fill ~102~19~3 ~103~19~5 minecraft:nether_brick_fence
fill ~139~18~3 ~140~18~3 minecraft:iron_bars
fill ~141~17~3 ~142~17~12 minecraft:wool 7
fill ~141~19~3 ~142~19~3 minecraft:nether_brick_fence
fill ~143~18~3 ~144~18~3 minecraft:iron_bars
fill ~175~19~3 ~176~19~5 minecraft:nether_brick_fence
fill ~101~18~4 ~104~18~4 minecraft:iron_bars
setblock ~139~18~4 minecraft:iron_bars
fill ~140~17~4 ~140~17~12 minecraft:wool 7
fill ~140~18~4 ~140~18~5 minecraft:obsidian
fill ~140~19~4 ~140~20~4 minecraft:wool 15
fill ~141~19~4 ~142~19~5 minecraft:obsidian
fill ~143~17~4 ~143~17~12 minecraft:wool 7
fill ~143~18~4 ~143~18~5 minecraft:obsidian
fill ~143~19~4 ~143~20~4 minecraft:wool 15
setblock ~144~18~4 minecraft:iron_bars
fill ~174~18~4 ~177~18~4 minecraft:iron_bars
fill ~72~19~5 ~73~19~7 minecraft:nether_brick_fence
fill ~100~18~5 ~101~18~5 minecraft:iron_bars
fill ~102~17~5 ~103~17~23 minecraft:wool 7
fill ~104~18~5 ~105~18~5 minecraft:iron_bars
fill ~137~17~5 ~139~18~5 minecraft:wool 7
fill ~144~17~5 ~157~18~5 minecraft:wool 7
fill ~173~18~5 ~174~18~5 minecraft:iron_bars
fill ~175~17~5 ~176~17~23 minecraft:wool 7
fill ~177~18~5 ~178~18~5 minecraft:iron_bars
fill ~71~18~6 ~74~18~6 minecraft:iron_bars
setblock ~100~18~6 minecraft:iron_bars
fill ~101~17~6 ~101~17~23 minecraft:wool 7
fill ~101~18~6 ~101~18~7 minecraft:obsidian
fill ~101~19~6 ~101~20~6 minecraft:wool 15
fill ~102~19~6 ~103~19~7 minecraft:obsidian
fill ~104~17~6 ~104~17~22 minecraft:wool 7
fill ~104~18~6 ~104~18~7 minecraft:obsidian
fill ~104~19~6 ~104~20~6 minecraft:wool 15
setblock ~105~18~6 minecraft:iron_bars
fill ~115~17~6 ~136~18~6 minecraft:wool 7
setblock ~137~17~6 minecraft:glowstone
fill ~138~17~6 ~139~17~12 minecraft:wool 7
fill ~142~18~6 ~142~19~6 minecraft:ladder 2
fill ~144~17~6 ~156~17~12 minecraft:wool 7
setblock ~157~17~6 minecraft:glowstone
fill ~158~17~6 ~169~18~6 minecraft:wool 7
setblock ~173~18~6 minecraft:iron_bars
fill ~174~17~6 ~174~17~23 minecraft:wool 7
fill ~174~18~6 ~174~18~7 minecraft:obsidian
fill ~174~19~6 ~174~20~6 minecraft:wool 15
fill ~175~19~6 ~176~19~7 minecraft:obsidian
fill ~177~17~6 ~177~17~23 minecraft:wool 7
fill ~177~18~6 ~177~18~7 minecraft:obsidian
fill ~177~19~6 ~177~20~6 minecraft:wool 15
setblock ~178~18~6 minecraft:iron_bars
fill ~70~18~7 ~71~18~7 minecraft:iron_bars
fill ~72~17~7 ~73~17~15 minecraft:wool 7
fill ~74~18~7 ~75~18~7 minecraft:iron_bars
fill ~97~17~7 ~100~18~7 minecraft:wool 7
fill ~105~17~7 ~114~17~22 minecraft:wool 7
fill ~105~18~7 ~114~18~7 minecraft:wool 7
setblock ~115~17~7 minecraft:glowstone
fill ~116~17~7 ~137~17~12 minecraft:wool 7
fill ~138~18~7 ~156~19~11 minecraft:wool 7
fill ~138~20~7 ~156~20~7 minecraft:wool 8
fill ~138~21~7 ~141~21~7 minecraft:iron_bars
fill ~143~21~7 ~156~21~7 minecraft:iron_bars
fill ~157~17~7 ~168~17~23 minecraft:wool 7
setblock ~169~17~7 minecraft:glowstone
fill ~170~17~7 ~173~17~23 minecraft:wool 7
fill ~170~18~7 ~173~18~7 minecraft:wool 7
fill ~178~17~7 ~181~18~7 minecraft:wool 7
setblock ~70~18~8 minecraft:iron_bars
fill ~71~17~8 ~71~17~15 minecraft:wool 7
fill ~71~18~8 ~71~18~9 minecraft:obsidian
fill ~71~19~8 ~71~20~8 minecraft:wool 15
fill ~72~19~8 ~73~19~9 minecraft:obsidian
fill ~74~17~8 ~74~17~15 minecraft:wool 7
fill ~74~18~8 ~74~18~9 minecraft:obsidian
fill ~74~19~8 ~74~20~8 minecraft:wool 15
setblock ~75~18~8 minecraft:iron_bars
fill ~81~17~8 ~91~18~8 minecraft:wool 7
fill ~92~18~8 ~96~18~8 minecraft:wool 7
fill ~94~17~8 ~94~17~9 minecraft:wool 7
fill ~96~17~8 ~96~17~15 minecraft:wool 7
setblock ~97~17~8 minecraft:glowstone
fill ~98~17~8 ~100~17~15 minecraft:wool 7
fill ~102~18~8 ~102~19~8 minecraft:ladder 2
fill ~115~17~8 ~115~17~23 minecraft:wool 7
fill ~116~18~8 ~137~19~12 minecraft:wool 7
fill ~116~20~8 ~137~20~8 minecraft:wool 8
fill ~116~21~8 ~138~21~8 minecraft:iron_bars
fill ~138~20~8 ~156~20~11 minecraft:wool 7
fill ~156~21~8 ~168~21~8 minecraft:iron_bars
fill ~157~18~8 ~168~19~22 minecraft:wool 7
fill ~157~20~8 ~168~20~8 minecraft:wool 8
fill ~169~17~8 ~169~17~23 minecraft:wool 7
fill ~178~17~8 ~180~17~23 minecraft:wool 7
setblock ~181~17~8 minecraft:glowstone
fill ~182~17~8 ~191~17~9 minecraft:wool 7
fill ~182~18~8 ~191~18~8 minecraft:wool 7
fill ~21~17~9 ~22~17~14 minecraft:iron_bars
fill ~30~17~9 ~31~17~14 minecraft:iron_bars
fill ~37~18~9 ~43~18~9 minecraft:iron_bars
fill ~38~12~9 ~206~12~9 minecraft:wool 7
fill ~38~13~9 ~38~17~10 minecraft:wool 7
fill ~39~13~9 ~42~13~9 minecraft:glass_pane
fill ~39~14~9 ~43~15~9 minecraft:wool 7
fill ~39~16~9 ~42~16~9 minecraft:glass_pane
fill ~39~17~9 ~43~17~23 minecraft:wool 7
fill ~43~13~9 ~43~13~10 minecraft:wool 7
fill ~43~16~9 ~43~16~10 minecraft:wool 7
fill ~65~17~9 ~70~18~9 minecraft:wool 7
fill ~75~17~9 ~80~17~15 minecraft:wool 7
fill ~75~18~9 ~80~18~9 minecraft:wool 7
setblock ~81~17~9 minecraft:glowstone
fill ~82~17~9 ~91~17~15 minecraft:wool 7
setblock ~95~17~9 minecraft:wool 7
fill ~97~17~9 ~97~17~15 minecraft:wool 7
fill ~98~18~9 ~115~18~22 minecraft:wool 7
fill ~98~19~9 ~115~19~14 minecraft:wool 7
fill ~98~20~9 ~115~20~9 minecraft:wool 8
fill ~98~21~9 ~101~21~9 minecraft:iron_bars
fill ~103~21~9 ~116~21~9 minecraft:iron_bars
fill ~116~20~9 ~137~20~11 minecraft:wool 7
fill ~157~20~9 ~168~20~14 minecraft:wool 7
fill ~168~21~9 ~180~21~9 minecraft:iron_bars
fill ~169~18~9 ~180~19~22 minecraft:wool 7
fill ~169~20~9 ~180~20~9 minecraft:wool 8
fill ~181~17~9 ~181~17~23 minecraft:wool 7
fill ~192~13~9 ~193~21~9 minecraft:iron_bars
fill ~8~18~10 ~9~18~15 minecraft:iron_bars
fill ~35~18~10 ~37~18~10 minecraft:iron_bars
fill ~37~12~10 ~38~12~10 minecraft:wool 7
fill ~37~13~10 ~37~13~11 minecraft:glass_pane
fill ~37~14~10 ~37~15~10 minecraft:wool 7
fill ~37~16~10 ~37~16~11 minecraft:glass_pane
fill ~37~17~10 ~37~17~23 minecraft:wool 7
fill ~38~11~10 ~206~11~10 minecraft:wool 7
setblock ~39~12~10 minecraft:double_stone_block_slab 0
fill ~40~12~10 ~41~12~10 minecraft:stone_block_slab 8
setblock ~42~12~10 minecraft:double_stone_block_slab 0
fill ~43~12~10 ~43~12~16 minecraft:wool 7
fill ~43~14~10 ~43~15~23 minecraft:wool 7
fill ~43~18~10 ~43~18~11 minecraft:iron_bars
fill ~49~17~10 ~64~18~10 minecraft:wool 7
setblock ~65~17~10 minecraft:glowstone
fill ~66~17~10 ~70~17~15 minecraft:wool 7
fill ~72~18~10 ~72~19~10 minecraft:ladder 2
fill ~81~17~10 ~81~17~15 minecraft:wool 7
fill ~82~18~10 ~97~18~22 minecraft:wool 7
fill ~82~19~10 ~97~19~14 minecraft:wool 7
fill ~82~20~10 ~97~20~10 minecraft:wool 8
fill ~82~21~10 ~98~21~10 minecraft:iron_bars
fill ~98~20~10 ~115~20~14 minecraft:wool 7
fill ~160~26~10 ~160~26~11 minecraft:wool 7
fill ~162~26~10 ~162~26~11 minecraft:wool 7
fill ~169~20~10 ~180~20~14 minecraft:wool 7
fill ~180~21~10 ~192~21~10 minecraft:iron_bars
fill ~181~18~10 ~190~19~19 minecraft:wool 7
fill ~181~20~10 ~192~20~10 minecraft:wool 8
fill ~182~17~10 ~190~17~19 minecraft:wool 7
setblock ~191~17~10 minecraft:glowstone
fill ~192~12~10 ~192~17~10 minecraft:wool 7
fill ~193~12~10 ~193~17~10 minecraft:ladder 5
fill ~206~12~10 ~206~12~12 minecraft:iron_bars
fill ~34~18~11 ~35~18~11 minecraft:iron_bars
fill ~35~12~11 ~36~12~11 minecraft:wool 7
fill ~35~13~11 ~35~13~12 minecraft:glass_pane
fill ~35~14~11 ~36~15~11 minecraft:wool 7
fill ~35~16~11 ~35~16~12 minecraft:glass_pane
fill ~35~17~11 ~36~17~23 minecraft:wool 7
setblock ~36~13~11 minecraft:wool 7
setblock ~36~16~11 minecraft:wool 7
fill ~37~11~11 ~95~11~17 minecraft:wool 7
setblock ~37~12~11 minecraft:double_stone_block_slab 0
fill ~38~17~11 ~38~17~23 minecraft:wool 7
fill ~43~13~11 ~43~13~15 minecraft:glass_pane
fill ~43~16~11 ~43~16~15 minecraft:glass_pane
fill ~44~17~11 ~48~17~15 minecraft:wool 7
fill ~44~18~11 ~48~18~11 minecraft:wool 7
setblock ~49~17~11 minecraft:glowstone
fill ~50~17~11 ~65~17~15 minecraft:wool 7
fill ~66~18~11 ~81~18~22 minecraft:wool 7
fill ~66~19~11 ~81~19~14 minecraft:wool 7
fill ~66~20~11 ~81~20~11 minecraft:wool 8
fill ~66~21~11 ~71~21~11 minecraft:iron_bars
fill ~73~21~11 ~82~21~11 minecraft:iron_bars
fill ~82~20~11 ~97~20~14 minecraft:wool 7
fill ~92~17~11 ~95~17~15 minecraft:wool 7
setblock ~96~11~11 minecraft:glowstone
fill ~97~11~11 ~111~11~23 minecraft:wool 7
fill ~98~16~11 ~204~16~11 minecraft:wool 7
setblock ~112~11~11 minecraft:glowstone
fill ~113~11~11 ~129~11~11 minecraft:wool 7
setblock ~130~11~11 minecraft:glowstone
fill ~131~11~11 ~149~11~11 minecraft:wool 7
setblock ~140~12~11 minecraft:stone_pressure_plate 0
setblock ~150~11~11 minecraft:glowstone
fill ~151~11~11 ~165~11~11 minecraft:wool 7
fill ~160~23~11 ~162~23~20 minecraft:wool 7
fill ~160~24~11 ~162~24~11 minecraft:stone_block_slab 0
fill ~160~25~11 ~160~25~13 minecraft:wool 7
fill ~162~25~11 ~162~25~13 minecraft:wool 7
setblock ~166~11~11 minecraft:glowstone
fill ~167~11~11 ~181~11~11 minecraft:wool 7
fill ~181~20~11 ~192~20~14 minecraft:wool 7
setblock ~182~11~11 minecraft:glowstone
fill ~183~11~11 ~197~11~11 minecraft:wool 7
fill ~191~17~11 ~204~19~19 minecraft:wool 7
fill ~192~21~11 ~204~21~11 minecraft:iron_bars
fill ~193~20~11 ~204~20~11 minecraft:wool 8
setblock ~198~11~11 minecraft:glowstone
fill ~199~11~11 ~206~11~11 minecraft:wool 7
fill ~34~12~12 ~34~12~23 minecraft:wool 7
fill ~34~13~12 ~34~17~12 minecraft:wool 7
setblock ~34~18~12 minecraft:iron_bars
fill ~35~11~12 ~36~11~23 minecraft:wool 7
setblock ~35~12~12 minecraft:double_stone_block_slab 0
fill ~40~18~12 ~40~19~12 minecraft:ladder 2
fill ~49~17~12 ~49~17~15 minecraft:wool 7
fill ~50~18~12 ~65~18~23 minecraft:wool 7
fill ~50~19~12 ~65~19~14 minecraft:wool 7
fill ~50~20~12 ~65~20~12 minecraft:wool 8
fill ~50~21~12 ~66~21~12 minecraft:iron_bars
fill ~66~20~12 ~81~20~14 minecraft:wool 7
fill ~95~16~12 ~98~16~12 minecraft:wool 7
fill ~96~11~12 ~96~11~23 minecraft:wool 7
fill ~98~12~12 ~137~15~12 minecraft:wool 7
fill ~101~16~12 ~137~16~12 minecraft:wool 7
fill ~112~11~12 ~123~11~23 minecraft:wool 7
fill ~116~20~12 ~130~20~14 minecraft:wool 7
fill ~131~20~12 ~148~20~12 minecraft:wool 8
fill ~138~12~12 ~138~13~12 minecraft:glowstone
setblock ~138~14~12 minecraft:wool 7
fill ~138~15~12 ~138~16~12 minecraft:glowstone
fill ~138~18~12 ~138~19~12 minecraft:glowstone
fill ~139~11~12 ~141~11~12 minecraft:wool 0
fill ~139~12~12 ~139~15~12 minecraft:wool 0
fill ~139~16~12 ~141~16~12 minecraft:wool 7
fill ~139~18~12 ~141~19~12 minecraft:wool 7
setblock ~140~12~12 minecraft:iron_door 1
fill ~140~14~12 ~141~15~12 minecraft:wool 0
fill ~141~12~12 ~141~13~12 minecraft:wool 0
fill ~142~12~12 ~142~13~12 minecraft:glowstone
fill ~142~14~12 ~203~14~12 minecraft:wool 7
fill ~142~15~12 ~142~16~12 minecraft:glowstone
fill ~142~18~12 ~142~19~12 minecraft:glowstone
fill ~143~12~12 ~203~13~12 minecraft:wool 7
fill ~143~15~12 ~203~16~12 minecraft:wool 7
fill ~143~18~12 ~156~19~12 minecraft:wool 7
fill ~149~20~12 ~156~20~14 minecraft:wool 7
fill ~160~24~12 ~160~24~15 minecraft:wool 7
setblock ~160~26~12 minecraft:stone_block_slab 0
fill ~161~22~12 ~161~22~22 minecraft:wool 7
fill ~161~24~12 ~161~24~17 minecraft:stone_block_slab 0
fill ~162~24~12 ~162~24~15 minecraft:wool 7
setblock ~162~26~12 minecraft:stone_block_slab 0
fill ~173~26~12 ~173~26~13 minecraft:wool 7
fill ~175~26~12 ~175~26~13 minecraft:wool 7
fill ~193~20~12 ~204~20~14 minecraft:wool 7
fill ~204~11~12 ~206~11~12 minecraft:wool 7
fill ~204~16~12 ~216~16~26 minecraft:wool 7
fill ~204~21~12 ~216~21~12 minecraft:iron_bars
setblock ~205~12~12 minecraft:stone_pressure_plate 0
fill ~205~17~12 ~216~17~23 minecraft:wool 7
fill ~205~18~12 ~216~19~22 minecraft:wool 7
fill ~205~20~12 ~216~20~12 minecraft:wool 8
fill ~34~13~13 ~34~13~17 minecraft:glass_pane
fill ~34~14~13 ~34~15~23 minecraft:wool 7
fill ~34~16~13 ~34~16~17 minecraft:glass_pane
fill ~34~17~13 ~34~19~23 minecraft:wool 7
fill ~34~20~13 ~49~20~13 minecraft:wool 8
fill ~34~21~13 ~39~21~13 minecraft:iron_bars
fill ~35~12~13 ~35~12~17 minecraft:stone_block_slab 8
fill ~35~18~13 ~49~18~23 minecraft:wool 7
fill ~35~19~13 ~49~19~19 minecraft:wool 7
fill ~41~21~13 ~50~21~13 minecraft:iron_bars
fill ~50~20~13 ~65~20~14 minecraft:wool 7
fill ~92~16~13 ~95~16~13 minecraft:wool 7
fill ~95~14~13 ~98~14~13 minecraft:wool 7
fill ~96~12~13 ~98~13~13 minecraft:wool 7
fill ~96~15~13 ~98~15~13 minecraft:wool 7
fill ~98~8~13 ~204~10~13 minecraft:wool 7
fill ~101~12~13 ~131~16~14 minecraft:wool 7
fill ~116~17~13 ~131~19~14 minecraft:wool 7
fill ~124~11~13 ~205~11~13 minecraft:wool 7
setblock ~131~20~13 minecraft:wool 8
setblock ~140~12~13 minecraft:stone_pressure_plate 0
fill ~148~12~13 ~203~16~14 minecraft:wool 7
fill ~148~17~13 ~156~19~14 minecraft:wool 7
setblock ~148~20~13 minecraft:wool 8
fill ~156~23~13 ~159~23~14 minecraft:wool 7
fill ~157~24~13 ~159~24~14 minecraft:stone_block_slab 0
fill ~160~22~13 ~160~22~19 minecraft:wool 7
fill ~162~22~13 ~162~22~19 minecraft:wool 7
fill ~163~23~13 ~166~23~14 minecraft:wool 7
fill ~163~24~13 ~165~24~14 minecraft:stone_block_slab 0
fill ~173~23~13 ~175~23~22 minecraft:wool 7
fill ~173~24~13 ~175~24~13 minecraft:stone_block_slab 0
fill ~173~25~13 ~173~25~15 minecraft:wool 7
fill ~175~25~13 ~175~25~15 minecraft:wool 7
fill ~204~12~13 ~204~14~13 minecraft:wool 0
fill ~204~15~13 ~216~15~20 minecraft:wool 7
setblock ~205~12~13 minecraft:iron_door 1
fill ~205~14~13 ~206~14~13 minecraft:wool 0
fill ~205~20~13 ~216~20~14 minecraft:wool 7
fill ~206~12~13 ~206~13~13 minecraft:wool 0
fill ~207~12~13 ~216~13~22 minecraft:wool 7
fill ~207~14~13 ~216~14~21 minecraft:wool 7
fill ~216~21~13 ~229~21~13 minecraft:iron_bars
fill ~217~16~13 ~228~19~14 minecraft:wool 7
fill ~217~20~13 ~229~20~13 minecraft:wool 8
fill ~18~19~14 ~33~19~19 minecraft:wool 7
fill ~18~20~14 ~33~20~14 minecraft:wool 8
fill ~18~21~14 ~34~21~14 minecraft:iron_bars
fill ~34~20~14 ~49~20~19 minecraft:wool 7
fill ~89~16~14 ~92~16~14 minecraft:wool 7
fill ~92~12~14 ~95~15~14 minecraft:wool 7
fill ~95~8~14 ~98~10~14 minecraft:wool 7
fill ~98~5~14 ~204~7~14 minecraft:wool 15
setblock ~100~9~14 minecraft:glowstone
fill ~101~8~14 ~216~8~25 minecraft:wool 7
fill ~101~9~14 ~216~9~24 minecraft:wool 7
fill ~101~10~14 ~216~10~16 minecraft:wool 7
fill ~124~11~14 ~131~11~14 minecraft:wool 7
fill ~130~21~14 ~131~22~14 minecraft:wool 7
setblock ~131~20~14 minecraft:wool 7
fill ~136~13~14 ~138~13~15 minecraft:wool 7
fill ~137~14~14 ~138~14~14 minecraft:stone_block_slab 0
fill ~140~13~14 ~142~13~15 minecraft:wool 7
fill ~140~14~14 ~141~14~14 minecraft:stone_block_slab 0
fill ~148~11~14 ~216~11~14 minecraft:wool 7
fill ~148~20~14 ~148~22~14 minecraft:wool 7
fill ~149~21~14 ~149~22~15 minecraft:wool 7
fill ~158~22~14 ~159~22~14 minecraft:wool 7
setblock ~160~25~14 minecraft:stone_block_slab 0
setblock ~162~25~14 minecraft:stone_block_slab 0
fill ~163~22~14 ~164~22~14 minecraft:wool 7
fill ~173~24~14 ~173~24~17 minecraft:wool 7
setblock ~173~26~14 minecraft:stone_block_slab 0
fill ~174~22~14 ~174~22~24 minecraft:wool 7
fill ~174~24~14 ~174~24~19 minecraft:stone_block_slab 0
fill ~175~24~14 ~175~24~17 minecraft:wool 7
setblock ~175~26~14 minecraft:stone_block_slab 0
fill ~204~12~14 ~204~12~22 minecraft:wool 7
fill ~204~13~14 ~204~14~14 minecraft:wool 7
setblock ~205~12~14 minecraft:stone_pressure_plate 0
fill ~205~14~14 ~206~14~21 minecraft:wool 7
fill ~206~12~14 ~206~12~22 minecraft:wool 7
setblock ~206~13~14 minecraft:wool 7
fill ~217~12~14 ~228~13~22 minecraft:wool 7
fill ~217~14~14 ~228~14~21 minecraft:wool 7
fill ~217~15~14 ~228~15~20 minecraft:wool 7
fill ~217~20~14 ~229~20~14 minecraft:wool 7
fill ~226~11~14 ~226~11~23 minecraft:wool 7
fill ~229~21~14 ~240~21~14 minecraft:iron_bars
fill ~230~20~14 ~240~20~14 minecraft:wool 8
fill ~2~19~15 ~17~19~19 minecraft:wool 7
fill ~2~20~15 ~17~20~15 minecraft:wool 8
fill ~2~21~15 ~18~21~15 minecraft:iron_bars
fill ~18~17~15 ~33~18~23 minecraft:wool 7
fill ~18~20~15 ~33~20~19 minecraft:wool 7
fill ~50~19~15 ~57~20~23 minecraft:wool 7
setblock ~58~19~15 minecraft:redstone_torch 5
setblock ~58~20~15 minecraft:lit_redstone_lamp
fill ~59~19~15 ~68~20~23 minecraft:wool 7
setblock ~69~19~15 minecraft:redstone_torch 5
setblock ~69~20~15 minecraft:lit_redstone_lamp
fill ~70~19~15 ~79~20~23 minecraft:wool 7
setblock ~80~19~15 minecraft:redstone_torch 5
setblock ~80~20~15 minecraft:lit_redstone_lamp
fill ~80~21~15 ~80~31~18 minecraft:iron_bars
fill ~80~32~15 ~82~47~15 minecraft:iron_bars
fill ~81~19~15 ~81~20~23 minecraft:wool 7
fill ~81~23~15 ~82~31~15 minecraft:iron_bars
setblock ~82~19~15 minecraft:redstone_torch 5
setblock ~82~20~15 minecraft:lit_redstone_lamp
fill ~82~21~15 ~82~22~18 minecraft:iron_bars
fill ~83~19~15 ~92~20~23 minecraft:wool 7
fill ~86~16~15 ~89~16~15 minecraft:wool 7
fill ~89~12~15 ~89~15~16 minecraft:wool 7
setblock ~90~12~15 minecraft:glowstone
fill ~90~13~15 ~92~15~15 minecraft:wool 7
fill ~91~12~15 ~92~12~15 minecraft:wool 7
fill ~92~8~15 ~95~10~15 minecraft:wool 7
setblock ~93~19~15 minecraft:redstone_torch 5
setblock ~93~20~15 minecraft:lit_redstone_lamp
fill ~94~19~15 ~103~19~23 minecraft:wool 7
fill ~94~20~15 ~103~20~20 minecraft:wool 7
fill ~95~5~15 ~98~7~15 minecraft:wool 15
setblock ~97~9~15 minecraft:glowstone
fill ~98~3~15 ~204~4~15 minecraft:wool 15
setblock ~100~7~15 minecraft:glowstone
fill ~101~5~15 ~216~6~26 minecraft:wool 15
fill ~101~7~15 ~216~7~25 minecraft:wool 15
fill ~101~12~15 ~130~16~18 minecraft:wool 7
setblock ~104~19~15 minecraft:redstone_torch 5
setblock ~104~20~15 minecraft:lit_redstone_lamp
fill ~105~19~15 ~114~20~22 minecraft:wool 7
setblock ~115~19~15 minecraft:redstone_torch 5
setblock ~115~20~15 minecraft:lit_redstone_lamp
fill ~116~17~15 ~130~17~23 minecraft:wool 7
fill ~116~18~15 ~130~18~18 minecraft:wool 7
fill ~116~19~15 ~125~19~23 minecraft:wool 7
fill ~116~20~15 ~125~20~18 minecraft:wool 7
fill ~124~11~15 ~130~11~23 minecraft:wool 7
setblock ~126~19~15 minecraft:redstone_torch 5
setblock ~126~20~15 minecraft:lit_redstone_lamp
fill ~127~19~15 ~130~19~18 minecraft:wool 7
fill ~127~20~15 ~130~20~15 minecraft:wool 7
fill ~130~21~15 ~130~22~15 minecraft:wool 7
fill ~131~11~15 ~131~21~15 minecraft:iron_bars
setblock ~131~22~15 minecraft:wool 7
fill ~137~14~15 ~137~14~16 minecraft:stone_block_slab 0
fill ~138~14~15 ~140~14~25 minecraft:wool 7
fill ~139~13~15 ~139~13~26 minecraft:wool 7
fill ~139~15~15 ~139~15~21 minecraft:stone_block_slab 0
fill ~141~14~15 ~141~14~16 minecraft:stone_block_slab 0
fill ~148~11~15 ~148~21~15 minecraft:iron_bars
setblock ~148~22~15 minecraft:wool 7
fill ~149~11~15 ~225~11~19 minecraft:wool 7
fill ~149~12~15 ~203~16~18 minecraft:wool 7
fill ~149~17~15 ~156~17~23 minecraft:wool 7
fill ~149~18~15 ~156~19~18 minecraft:wool 7
fill ~149~20~15 ~155~20~15 minecraft:wool 7
setblock ~156~20~15 minecraft:glowstone
fill ~157~20~15 ~166~20~18 minecraft:wool 7
fill ~157~23~15 ~159~23~15 minecraft:wool 7
fill ~158~24~15 ~159~24~15 minecraft:stone_block_slab 0
setblock ~159~22~15 minecraft:wool 7
fill ~163~22~15 ~163~23~15 minecraft:wool 7
fill ~163~24~15 ~164~24~15 minecraft:stone_block_slab 0
fill ~164~23~15 ~165~23~15 minecraft:wool 7
setblock ~167~20~15 minecraft:glowstone
fill ~168~20~15 ~177~20~34 minecraft:wool 7
fill ~169~23~15 ~172~23~16 minecraft:wool 7
fill ~170~24~15 ~172~24~16 minecraft:stone_block_slab 0
fill ~173~22~15 ~173~22~21 minecraft:wool 7
fill ~175~22~15 ~175~22~21 minecraft:wool 7
fill ~176~23~15 ~179~23~16 minecraft:wool 7
fill ~176~24~15 ~178~24~16 minecraft:stone_block_slab 0
setblock ~178~20~15 minecraft:glowstone
fill ~179~20~15 ~188~20~18 minecraft:wool 7
setblock ~189~20~15 minecraft:glowstone
fill ~190~20~15 ~199~20~18 minecraft:wool 7
setblock ~200~20~15 minecraft:glowstone
fill ~201~20~15 ~210~20~18 minecraft:wool 7
fill ~204~13~15 ~204~13~21 minecraft:glowstone
fill ~204~14~15 ~204~14~21 minecraft:wool 7
fill ~206~13~15 ~206~13~21 minecraft:glowstone
setblock ~211~20~15 minecraft:glowstone
fill ~212~20~15 ~221~20~34 minecraft:wool 7
fill ~217~8~15 ~228~8~25 minecraft:wool 7
fill ~217~9~15 ~228~10~24 minecraft:wool 7
fill ~217~16~15 ~227~16~26 minecraft:wool 7
fill ~217~17~15 ~227~17~23 minecraft:wool 7
fill ~217~18~15 ~227~19~22 minecraft:wool 7
setblock ~222~20~15 minecraft:glowstone
fill ~223~20~15 ~232~20~33 minecraft:wool 7
fill ~227~11~15 ~228~11~23 minecraft:wool 7
fill ~228~19~15 ~251~19~23 minecraft:wool 7
fill ~229~16~15 ~229~16~60 minecraft:wool 7
fill ~229~17~15 ~229~17~47 minecraft:wool 7
fill ~229~18~15 ~229~18~24 minecraft:wool 7
setblock ~233~20~15 minecraft:glowstone
fill ~234~20~15 ~240~20~33 minecraft:wool 7
fill ~240~21~15 ~251~21~15 minecraft:iron_bars
fill ~241~20~15 ~251~20~15 minecraft:wool 8
fill ~2~20~16 ~2~20~38 minecraft:wool 8
fill ~3~18~16 ~17~18~23 minecraft:wool 7
fill ~3~20~16 ~17~20~19 minecraft:wool 7
fill ~38~14~16 ~40~14~16 minecraft:glowstone
fill ~38~15~16 ~38~16~16 minecraft:iron_bars
fill ~40~15~16 ~40~16~16 minecraft:iron_bars
setblock ~43~13~16 minecraft:wool 7
fill ~43~16~16 ~43~16~38 minecraft:wool 7
setblock ~44~13~16 minecraft:wall_sign 5
fill ~58~19~16 ~58~20~19 minecraft:wool 7
fill ~69~19~16 ~69~20~23 minecraft:wool 7
setblock ~73~37~16 minecraft:torch 4
setblock ~79~37~16 minecraft:torch 4
fill ~80~19~16 ~80~20~23 minecraft:wool 7
fill ~80~32~16 ~80~47~16 minecraft:iron_bars
fill ~81~21~16 ~81~46~16 minecraft:ladder 2
fill ~82~19~16 ~82~20~23 minecraft:wool 7
fill ~82~23~16 ~82~31~18 minecraft:iron_bars
fill ~82~32~16 ~82~47~16 minecraft:iron_bars
fill ~83~16~16 ~86~17~16 minecraft:wool 7
setblock ~85~37~16 minecraft:torch 4
fill ~86~12~16 ~86~15~17 minecraft:wool 7
setblock ~87~12~16 minecraft:glowstone
fill ~87~13~16 ~88~15~16 minecraft:wool 7
setblock ~88~12~16 minecraft:wool 7
fill ~89~8~16 ~92~10~16 minecraft:wool 7
fill ~92~5~16 ~95~7~16 minecraft:wool 15
setblock ~92~37~16 minecraft:torch 4
fill ~93~19~16 ~93~20~23 minecraft:wool 7
setblock ~94~9~16 minecraft:glowstone
fill ~95~3~16 ~98~4~16 minecraft:wool 15
fill ~98~2~16 ~216~2~17 minecraft:wool 15
setblock ~98~37~16 minecraft:torch 4
fill ~99~54~16 ~101~56~16 minecraft:wool 0
fill ~101~3~16 ~216~4~27 minecraft:wool 15
fill ~104~19~16 ~104~19~22 minecraft:wool 7
fill ~104~20~16 ~104~20~20 minecraft:wool 7
setblock ~104~37~16 minecraft:torch 4
fill ~115~19~16 ~115~20~23 minecraft:wool 7
fill ~126~19~16 ~126~19~23 minecraft:wool 7
fill ~126~20~16 ~129~20~18 minecraft:wool 7
fill ~130~20~16 ~130~20~32 minecraft:wool 8
fill ~137~13~16 ~138~13~16 minecraft:wool 7
fill ~137~15~16 ~137~15~20 minecraft:wool 7
fill ~138~15~16 ~138~15~25 minecraft:stone_block_slab 0
fill ~140~13~16 ~141~13~16 minecraft:wool 7
fill ~140~15~16 ~140~15~25 minecraft:stone_block_slab 0
fill ~141~15~16 ~141~15~20 minecraft:wool 7
fill ~149~20~16 ~149~20~32 minecraft:wool 8
fill ~150~20~16 ~156~20~18 minecraft:wool 7
fill ~158~23~16 ~159~23~16 minecraft:wool 7
setblock ~159~22~16 minecraft:iron_block
fill ~159~24~16 ~160~24~18 minecraft:stone_block_slab 0
fill ~162~24~16 ~163~24~18 minecraft:stone_block_slab 0
setblock ~163~22~16 minecraft:iron_block
fill ~163~23~16 ~164~23~16 minecraft:wool 7
fill ~167~20~16 ~167~20~37 minecraft:wool 7
fill ~171~22~16 ~172~22~16 minecraft:wool 7
setblock ~173~25~16 minecraft:stone_block_slab 0
setblock ~175~25~16 minecraft:stone_block_slab 0
fill ~176~22~16 ~177~22~16 minecraft:wool 7
fill ~178~20~16 ~178~20~37 minecraft:wool 7
fill ~189~20~16 ~189~20~18 minecraft:wool 7
fill ~200~20~16 ~200~20~18 minecraft:wool 7
fill ~211~20~16 ~211~20~27 minecraft:wool 7
fill ~217~5~16 ~228~7~20 minecraft:wool 15
fill ~222~20~16 ~222~20~27 minecraft:wool 7
fill ~233~20~16 ~233~20~27 minecraft:wool 7
fill ~241~20~16 ~250~20~19 minecraft:wool 7
fill ~251~20~16 ~251~20~22 minecraft:wool 8
fill ~251~21~16 ~251~21~23 minecraft:iron_bars
fill ~3~17~17 ~17~17~17 minecraft:wool 7
fill ~6~23~17 ~12~23~18 minecraft:wool 8
fill ~6~24~17 ~6~25~18 minecraft:wool 8
fill ~7~24~17 ~7~24~18 minecraft:stone_block_slab 0
fill ~9~24~17 ~9~24~23 minecraft:stone_block_slab 0
fill ~11~24~17 ~11~24~18 minecraft:stone_block_slab 0
fill ~12~24~17 ~12~25~18 minecraft:wool 8
fill ~24~23~17 ~30~23~18 minecraft:wool 8
fill ~24~24~17 ~24~25~18 minecraft:wool 8
fill ~25~24~17 ~25~24~18 minecraft:stone_block_slab 0
fill ~27~24~17 ~27~24~23 minecraft:stone_block_slab 0
fill ~29~24~17 ~29~24~18 minecraft:stone_block_slab 0
fill ~30~24~17 ~30~25~18 minecraft:wool 8
setblock ~42~12~17 minecraft:stone_pressure_plate 0
fill ~42~23~17 ~48~23~18 minecraft:wool 8
fill ~42~24~17 ~42~25~18 minecraft:wool 8
setblock ~43~12~17 minecraft:iron_door 2
fill ~43~24~17 ~43~24~18 minecraft:stone_block_slab 0
setblock ~44~12~17 minecraft:stone_pressure_plate 0
fill ~44~17~17 ~100~17~23 minecraft:wool 7
fill ~45~24~17 ~45~24~23 minecraft:stone_block_slab 0
fill ~47~24~17 ~47~24~18 minecraft:stone_block_slab 0
fill ~48~24~17 ~48~25~18 minecraft:wool 8
fill ~72~32~17 ~108~32~19 minecraft:wool 8
fill ~72~33~17 ~108~33~17 minecraft:wool 8
fill ~72~34~17 ~106~34~17 minecraft:wool 8
fill ~72~35~17 ~73~35~17 minecraft:glass
fill ~72~36~17 ~106~39~17 minecraft:wool 8
fill ~72~40~17 ~73~40~17 minecraft:glass
fill ~72~41~17 ~106~42~17 minecraft:wool 8
fill ~72~43~17 ~73~43~17 minecraft:glass
fill ~72~44~17 ~106~45~30 minecraft:wool 8
fill ~72~46~17 ~106~46~22 minecraft:wool 8
fill ~72~47~17 ~80~47~17 minecraft:iron_bars
setblock ~74~35~17 minecraft:wool 8
setblock ~74~40~17 minecraft:wool 8
fill ~74~43~17 ~74~43~30 minecraft:wool 8
fill ~75~35~17 ~76~35~17 minecraft:glass
fill ~75~40~17 ~76~40~17 minecraft:glass
fill ~75~43~17 ~76~43~17 minecraft:glass
setblock ~77~35~17 minecraft:wool 8
setblock ~77~40~17 minecraft:wool 8
fill ~77~43~17 ~77~43~30 minecraft:wool 8
fill ~78~35~17 ~79~35~17 minecraft:glass
fill ~78~40~17 ~79~40~17 minecraft:glass
fill ~78~43~17 ~79~43~17 minecraft:glass
fill ~80~16~17 ~83~16~23 minecraft:wool 7
fill ~80~35~17 ~83~35~17 minecraft:wool 8
fill ~80~40~17 ~83~40~17 minecraft:wool 8
fill ~80~43~17 ~83~43~29 minecraft:wool 8
fill ~81~21~17 ~81~31~19 minecraft:wool 8
fill ~82~47~17 ~106~47~17 minecraft:iron_bars
fill ~83~12~17 ~83~15~18 minecraft:wool 7
setblock ~84~12~17 minecraft:glowstone
fill ~84~13~17 ~85~15~17 minecraft:wool 7
fill ~84~35~17 ~85~35~17 minecraft:glass
fill ~84~40~17 ~85~40~17 minecraft:glass
fill ~84~43~17 ~85~43~17 minecraft:glass
setblock ~85~12~17 minecraft:wool 7
fill ~86~8~17 ~89~10~17 minecraft:wool 7
setblock ~86~35~17 minecraft:wool 8
setblock ~86~40~17 minecraft:wool 8
fill ~86~43~17 ~86~43~30 minecraft:wool 8
fill ~87~35~17 ~88~35~17 minecraft:glass
fill ~87~40~17 ~88~40~17 minecraft:glass
fill ~87~43~17 ~88~43~17 minecraft:glass
fill ~89~5~17 ~92~7~17 minecraft:wool 15
setblock ~89~35~17 minecraft:wool 8
setblock ~89~40~17 minecraft:wool 8
fill ~89~43~17 ~89~43~30 minecraft:wool 8
fill ~90~35~17 ~91~35~17 minecraft:glass
fill ~90~40~17 ~91~40~17 minecraft:glass
fill ~90~43~17 ~91~43~17 minecraft:glass
setblock ~91~8~17 minecraft:glowstone
fill ~92~3~17 ~95~4~17 minecraft:wool 15
setblock ~92~35~17 minecraft:wool 8
setblock ~92~40~17 minecraft:wool 8
fill ~92~43~17 ~92~43~30 minecraft:wool 8
fill ~93~35~17 ~94~35~17 minecraft:glass
fill ~93~40~17 ~94~40~17 minecraft:glass
fill ~93~43~17 ~94~43~17 minecraft:glass
fill ~95~2~17 ~97~2~18 minecraft:wool 15
setblock ~95~35~17 minecraft:wool 8
setblock ~95~40~17 minecraft:wool 8
fill ~95~43~17 ~95~43~30 minecraft:wool 8
fill ~96~35~17 ~97~35~17 minecraft:glass
fill ~96~40~17 ~97~40~17 minecraft:glass
fill ~96~43~17 ~97~43~17 minecraft:glass
setblock ~98~35~17 minecraft:wool 8
setblock ~98~40~17 minecraft:wool 8
fill ~98~43~17 ~98~43~30 minecraft:wool 8
fill ~98~53~17 ~102~53~17 minecraft:wool 0
fill ~98~54~17 ~98~57~17 minecraft:wool 0
fill ~99~35~17 ~100~35~17 minecraft:glass
fill ~99~40~17 ~100~40~17 minecraft:glass
fill ~99~43~17 ~100~43~17 minecraft:glass
fill ~99~57~17 ~102~57~17 minecraft:wool 0
setblock ~100~7~17 minecraft:glowstone
fill ~101~1~17 ~216~1~27 minecraft:wool 15
fill ~101~10~17 ~133~10~29 minecraft:wool 7
fill ~101~35~17 ~106~35~17 minecraft:wool 8
fill ~101~40~17 ~106~40~17 minecraft:wool 8
fill ~101~43~17 ~106~43~30 minecraft:wool 8
fill ~102~54~17 ~102~56~17 minecraft:wool 0
fill ~107~38~17 ~108~38~31 minecraft:wool 8
fill ~107~39~17 ~108~39~17 minecraft:wool 8
setblock ~134~10~17 minecraft:glowstone
fill ~135~10~17 ~144~10~23 minecraft:wool 7
fill ~136~16~17 ~136~16~19 minecraft:wool 7
setblock ~138~13~17 minecraft:wool 7
setblock ~140~13~17 minecraft:wool 7
fill ~142~16~17 ~142~16~19 minecraft:wool 7
setblock ~145~10~17 minecraft:glowstone
fill ~146~10~17 ~216~10~22 minecraft:wool 7
setblock ~159~22~17 minecraft:dispenser 3
fill ~159~23~17 ~159~23~19 minecraft:wool 7
setblock ~163~22~17 minecraft:dispenser 3
fill ~163~23~17 ~163~23~19 minecraft:wool 7
fill ~170~23~17 ~172~23~17 minecraft:wool 7
fill ~171~24~17 ~172~24~17 minecraft:stone_block_slab 0
setblock ~172~22~17 minecraft:wool 7
fill ~176~22~17 ~176~23~17 minecraft:wool 7
fill ~176~24~17 ~177~24~17 minecraft:stone_block_slab 0
fill ~177~23~17 ~178~23~17 minecraft:wool 7
fill ~217~2~17 ~227~4~27 minecraft:wool 15
fill ~228~3~17 ~228~4~20 minecraft:wool 15
fill ~2~18~18 ~2~18~34 minecraft:wool 7
fill ~3~17~18 ~4~17~23 minecraft:wool 7
fill ~4~16~18 ~34~16~18 minecraft:wool 7
fill ~10~17~18 ~17~17~23 minecraft:wool 7
fill ~34~13~18 ~34~13~23 minecraft:wool 7
setblock ~35~12~18 minecraft:double_stone_block_slab 0
fill ~37~11~18 ~45~11~23 minecraft:wool 7
fill ~43~12~18 ~43~13~23 minecraft:wool 7
fill ~44~12~18 ~45~12~18 minecraft:iron_block
setblock ~44~13~18 minecraft:redstone_torch 5
fill ~44~16~18 ~79~16~23 minecraft:wool 7
setblock ~46~11~18 minecraft:glowstone
fill ~47~11~18 ~56~11~23 minecraft:wool 7
setblock ~57~11~18 minecraft:glowstone
fill ~58~11~18 ~67~11~23 minecraft:wool 7
setblock ~68~11~18 minecraft:glowstone
fill ~69~11~18 ~78~11~23 minecraft:wool 7
fill ~71~32~18 ~71~33~29 minecraft:wool 8
setblock ~71~34~18 minecraft:wool 8
setblock ~71~35~18 minecraft:glass
fill ~71~36~18 ~71~39~18 minecraft:wool 8
setblock ~71~40~18 minecraft:glass
fill ~71~41~18 ~71~42~18 minecraft:wool 8
setblock ~71~43~18 minecraft:glass
fill ~71~44~18 ~71~46~29 minecraft:wool 8
fill ~71~47~18 ~72~47~18 minecraft:iron_bars
fill ~72~33~18 ~79~33~18 minecraft:wool 8
fill ~72~37~18 ~80~37~30 minecraft:wool 8
fill ~72~38~18 ~80~38~22 minecraft:wool 8
fill ~72~42~18 ~106~42~24 minecraft:wool 8
fill ~72~43~18 ~73~43~29 minecraft:wool 8
fill ~73~34~18 ~73~36~20 minecraft:stone_block_slab 0
fill ~73~47~18 ~80~47~18 minecraft:wool 8
setblock ~73~48~18 minecraft:glass
setblock ~74~48~18 minecraft:wool 8
fill ~75~34~18 ~75~36~20 minecraft:stone_block_slab 0
fill ~75~43~18 ~76~43~29 minecraft:wool 8
fill ~75~48~18 ~76~48~18 minecraft:glass
fill ~76~34~18 ~77~36~18 minecraft:bookshelf
setblock ~77~48~18 minecraft:wool 8
fill ~78~34~18 ~78~36~21 minecraft:stone_block_slab 0
fill ~78~43~18 ~79~43~29 minecraft:wool 8
fill ~78~48~18 ~79~48~18 minecraft:glass
setblock ~79~11~18 minecraft:glowstone
fill ~80~11~18 ~95~11~23 minecraft:wool 7
fill ~80~12~18 ~80~15~19 minecraft:wool 7
fill ~80~33~18 ~81~33~21 minecraft:double_stone_block_slab 0
fill ~80~39~18 ~80~39~20 minecraft:fence 0
fill ~80~48~18 ~80~48~19 minecraft:wool 8
setblock ~81~12~18 minecraft:glowstone
fill ~81~13~18 ~82~15~18 minecraft:wool 7
setblock ~82~12~18 minecraft:wool 7
fill ~82~33~18 ~106~33~19 minecraft:wool 8
fill ~82~34~18 ~82~34~19 minecraft:stone_block_slab 0
fill ~83~8~18 ~86~10~18 minecraft:wool 7
fill ~83~34~18 ~85~34~19 minecraft:double_stone_block_slab 0
fill ~84~16~18 ~100~16~23 minecraft:wool 7
fill ~84~35~18 ~84~35~19 minecraft:stone_block_slab 0
fill ~84~43~18 ~85~43~29 minecraft:wool 8
fill ~85~35~18 ~86~35~19 minecraft:double_stone_block_slab 0
fill ~86~5~18 ~89~7~18 minecraft:wool 15
fill ~86~36~18 ~86~36~19 minecraft:stone_block_slab 0
fill ~87~36~18 ~87~36~19 minecraft:double_stone_block_slab 0
fill ~87~43~18 ~88~43~29 minecraft:wool 8
fill ~88~37~18 ~88~37~19 minecraft:stone_block_slab 0
fill ~89~3~18 ~92~4~18 minecraft:wool 15
fill ~89~37~18 ~89~37~19 minecraft:double_stone_block_slab 0
fill ~90~37~18 ~106~37~18 minecraft:wool 8
fill ~90~38~18 ~90~38~19 minecraft:stone_block_slab 0
fill ~90~43~18 ~91~43~29 minecraft:wool 8
fill ~91~38~18 ~92~38~19 minecraft:double_stone_block_slab 0
fill ~92~2~18 ~94~2~19 minecraft:wool 15
setblock ~92~5~18 minecraft:glowstone
fill ~93~38~18 ~106~38~22 minecraft:wool 8
fill ~93~43~18 ~94~43~29 minecraft:wool 8
fill ~94~34~18 ~94~36~20 minecraft:stone_block_slab 0
fill ~96~34~18 ~100~36~18 minecraft:stone_block_slab 0
fill ~96~43~18 ~97~43~29 minecraft:wool 8
setblock ~97~50~18 minecraft:torch 4
fill ~97~54~18 ~97~56~20 minecraft:wool 0
fill ~98~1~18 ~100~1~18 minecraft:wool 15
fill ~98~39~18 ~98~41~23 minecraft:planks 1
setblock ~98~53~18 minecraft:wool 0
fill ~98~57~18 ~98~57~21 minecraft:wool 0
fill ~99~39~18 ~99~41~18 minecraft:bookshelf
fill ~99~43~18 ~100~43~29 minecraft:wool 8
fill ~99~52~18 ~101~52~18 minecraft:wool 0
fill ~99~58~18 ~101~58~20 minecraft:wool 0
fill ~100~39~18 ~100~41~18 minecraft:fence 0
fill ~101~0~18 ~227~0~29 minecraft:wool 15
fill ~101~2~18 ~216~2~27 minecraft:wool 15
fill ~101~39~18 ~103~39~18 minecraft:bed 2
fill ~101~41~18 ~104~41~18 minecraft:fence 0
fill ~101~53~18 ~101~53~22 minecraft:wool 8
fill ~102~34~18 ~102~36~20 minecraft:stone_block_slab 0
setblock ~102~53~18 minecraft:wool 0
fill ~102~57~18 ~102~57~21 minecraft:wool 0
fill ~103~54~18 ~103~56~20 minecraft:wool 0
fill ~104~34~18 ~104~36~20 minecraft:stone_block_slab 0
fill ~104~39~18 ~104~40~18 minecraft:fence 0
fill ~105~39~18 ~105~41~18 minecraft:bookshelf
fill ~106~34~18 ~106~36~22 minecraft:wool 8
fill ~106~39~18 ~106~41~21 minecraft:wool 8
fill ~106~47~18 ~106~47~30 minecraft:iron_bars
fill ~108~33~18 ~108~33~29 minecraft:iron_bars
fill ~108~39~18 ~108~39~31 minecraft:wool 8
fill ~134~10~18 ~134~10~29 minecraft:wool 7
setblock ~135~17~18 minecraft:wool 7
setblock ~143~17~18 minecraft:wool 7
fill ~145~10~18 ~145~10~29 minecraft:wool 7
fill ~161~24~18 ~161~24~19 minecraft:wool 7
fill ~171~23~18 ~172~23~18 minecraft:wool 7
setblock ~172~22~18 minecraft:iron_block
fill ~172~24~18 ~173~24~20 minecraft:stone_block_slab 0
fill ~175~24~18 ~176~24~20 minecraft:stone_block_slab 0
setblock ~176~22~18 minecraft:iron_block
fill ~176~23~18 ~177~23~18 minecraft:wool 7
fill ~217~1~18 ~227~1~27 minecraft:wool 15
fill ~218~26~18 ~218~26~19 minecraft:wool 7
fill ~220~26~18 ~220~26~19 minecraft:wool 7
fill ~228~2~18 ~228~2~56 minecraft:wool 15
fill ~228~18~18 ~228~18~23 minecraft:wool 7
fill ~229~11~18 ~229~15~31 minecraft:wool 7
fill ~230~14~18 ~247~15~46 minecraft:wool 7
fill ~230~16~18 ~247~18~36 minecraft:wool 7
fill ~248~18~18 ~251~18~38 minecraft:wool 7
fill ~4~16~19 ~4~16~34 minecraft:wool 7
fill ~5~15~19 ~33~15~20 minecraft:wool 7
fill ~9~23~19 ~9~23~28 minecraft:wool 8
fill ~10~16~19 ~42~16~34 minecraft:wool 7
fill ~27~23~19 ~27~23~27 minecraft:wool 8
fill ~35~12~19 ~42~15~23 minecraft:wool 7
fill ~44~12~19 ~79~15~19 minecraft:wool 7
fill ~45~23~19 ~45~23~27 minecraft:wool 8
fill ~46~11~19 ~46~11~23 minecraft:wool 7
fill ~57~11~19 ~57~11~23 minecraft:wool 7
fill ~58~27~19 ~80~29~19 minecraft:wool 8
fill ~58~30~19 ~59~31~19 minecraft:wool 8
fill ~58~32~19 ~69~32~19 minecraft:iron_bars
fill ~59~21~19 ~80~24~19 minecraft:wool 8
fill ~59~25~19 ~59~26~19 minecraft:wool 8
fill ~60~25~19 ~61~25~19 minecraft:glass
fill ~60~26~19 ~80~26~19 minecraft:wool 8
fill ~60~30~19 ~61~30~19 minecraft:glass
fill ~60~31~19 ~80~31~19 minecraft:wool 8
fill ~62~25~19 ~63~25~19 minecraft:wool 8
fill ~62~30~19 ~63~30~24 minecraft:wool 8
fill ~64~25~19 ~65~25~19 minecraft:glass
fill ~64~30~19 ~65~30~19 minecraft:glass
fill ~66~25~19 ~67~25~19 minecraft:wool 8
fill ~66~30~19 ~67~30~24 minecraft:wool 8
fill ~68~11~19 ~68~11~23 minecraft:wool 7
fill ~68~25~19 ~69~25~19 minecraft:glass
fill ~68~30~19 ~69~30~19 minecraft:glass
fill ~70~25~19 ~71~25~19 minecraft:wool 8
fill ~70~30~19 ~71~30~24 minecraft:wool 8
fill ~70~32~19 ~70~34~28 minecraft:wool 8
fill ~70~35~19 ~70~35~21 minecraft:glass
fill ~70~36~19 ~70~39~28 minecraft:wool 8
fill ~70~40~19 ~70~40~21 minecraft:glass
fill ~70~41~19 ~70~42~28 minecraft:wool 8
fill ~70~43~19 ~70~43~21 minecraft:glass
fill ~70~44~19 ~70~46~28 minecraft:wool 8
fill ~70~47~19 ~71~47~19 minecraft:iron_bars
fill ~71~37~19 ~71~37~29 minecraft:wool 8
fill ~71~38~19 ~71~38~22 minecraft:wool 8
fill ~71~42~19 ~71~42~29 minecraft:wool 8
fill ~71~43~19 ~71~43~28 minecraft:wool 8
fill ~72~25~19 ~73~25~19 minecraft:glass
fill ~72~30~19 ~73~30~19 minecraft:glass
setblock ~72~33~19 minecraft:glowstone
setblock ~72~47~19 minecraft:wool 8
setblock ~72~48~19 minecraft:glass
fill ~73~33~19 ~79~33~24 minecraft:wool 8
setblock ~73~47~19 minecraft:stone_button 5
fill ~73~49~19 ~80~49~19 minecraft:wool 8
fill ~74~25~19 ~75~25~19 minecraft:wool 8
fill ~74~30~19 ~75~30~19 minecraft:wool 8
setblock ~74~48~19 minecraft:torch 3
fill ~76~25~19 ~77~25~19 minecraft:glass
fill ~76~30~19 ~77~30~19 minecraft:glass
fill ~78~25~19 ~80~25~19 minecraft:wool 8
fill ~78~30~19 ~80~30~19 minecraft:wool 8
fill ~79~11~19 ~79~11~23 minecraft:wool 7
fill ~80~8~19 ~83~10~19 minecraft:wool 7
setblock ~80~47~19 minecraft:wool 8
fill ~81~15~19 ~129~15~20 minecraft:wool 7
fill ~82~21~19 ~121~24~19 minecraft:wool 8
fill ~82~25~19 ~84~31~19 minecraft:wool 8
fill ~83~5~19 ~86~7~19 minecraft:wool 15
fill ~85~25~19 ~86~25~19 minecraft:glass
fill ~85~26~19 ~121~26~19 minecraft:wool 8
fill ~85~27~19 ~106~29~19 minecraft:wool 8
fill ~85~30~19 ~86~30~19 minecraft:glass
fill ~85~31~19 ~106~31~19 minecraft:wool 8
fill ~86~3~19 ~89~4~19 minecraft:wool 15
fill ~86~8~19 ~86~9~19 minecraft:glowstone
fill ~87~25~19 ~88~25~19 minecraft:wool 8
fill ~87~30~19 ~88~30~19 minecraft:wool 8
fill ~89~2~19 ~91~2~20 minecraft:wool 15
setblock ~89~5~19 minecraft:glowstone
fill ~89~25~19 ~90~25~19 minecraft:glass
fill ~89~30~19 ~90~30~19 minecraft:glass
fill ~90~37~19 ~96~37~30 minecraft:wool 8
fill ~91~25~19 ~92~25~19 minecraft:wool 8
fill ~91~30~19 ~92~30~19 minecraft:wool 8
fill ~93~25~19 ~94~25~19 minecraft:glass
fill ~93~30~19 ~94~30~19 minecraft:glass
fill ~93~34~19 ~93~34~22 minecraft:iron_bars
fill ~95~1~19 ~98~1~19 minecraft:wool 15
fill ~95~25~19 ~96~25~19 minecraft:wool 8
fill ~95~30~19 ~96~30~19 minecraft:wool 8
fill ~97~25~19 ~98~25~19 minecraft:glass
fill ~97~30~19 ~98~30~19 minecraft:glass
setblock ~97~37~19 minecraft:glowstone
fill ~97~47~19 ~103~52~19 minecraft:wool 8
fill ~97~53~19 ~100~53~22 minecraft:wool 8
fill ~98~0~19 ~100~0~41 minecraft:wool 15
fill ~98~37~19 ~100~37~30 minecraft:wool 8
fill ~99~25~19 ~99~25~28 minecraft:wool 8
fill ~99~30~19 ~99~30~28 minecraft:wool 8
fill ~99~41~19 ~99~41~23 minecraft:bookshelf
fill ~100~25~19 ~101~25~19 minecraft:glass
fill ~100~30~19 ~101~30~19 minecraft:glass
fill ~100~34~19 ~100~36~20 minecraft:stone_block_slab 0
fill ~100~41~19 ~100~41~20 minecraft:fence 0
fill ~100~54~19 ~100~54~20 minecraft:torch 5
fill ~101~12~19 ~129~13~22 minecraft:wool 7
fill ~101~14~19 ~130~14~21 minecraft:wool 7
fill ~101~16~19 ~129~16~23 minecraft:wool 7
setblock ~101~37~19 minecraft:glowstone
fill ~102~25~19 ~103~25~28 minecraft:wool 8
fill ~102~30~19 ~103~30~28 minecraft:wool 8
fill ~102~37~19 ~106~37~30 minecraft:wool 8
fill ~102~53~19 ~103~53~22 minecraft:wool 8
fill ~104~25~19 ~105~25~19 minecraft:glass
fill ~104~30~19 ~105~30~19 minecraft:glass
fill ~104~41~19 ~104~41~20 minecraft:fence 0
setblock ~104~49~19 minecraft:torch 1
fill ~106~25~19 ~121~25~19 minecraft:wool 8
fill ~106~30~19 ~106~30~28 minecraft:wool 8
fill ~107~29~19 ~122~29~19 minecraft:wool 8
setblock ~107~41~19 minecraft:torch 1
fill ~109~27~19 ~121~27~19 minecraft:iron_bars
fill ~116~18~19 ~129~18~22 minecraft:wool 7
fill ~116~20~19 ~122~20~41 minecraft:wool 7
fill ~122~28~19 ~123~28~19 minecraft:wool 8
setblock ~123~20~19 minecraft:glowstone
fill ~123~27~19 ~124~27~19 minecraft:wool 8
fill ~124~20~19 ~125~20~34 minecraft:wool 7
fill ~124~21~19 ~125~25~19 minecraft:wool 8
setblock ~124~26~19 minecraft:wool 8
setblock ~126~20~19 minecraft:glowstone
fill ~127~19~19 ~129~20~23 minecraft:wool 7
fill ~130~12~19 ~130~13~19 minecraft:glowstone
fill ~130~15~19 ~130~16~19 minecraft:glowstone
fill ~130~18~19 ~130~19~19 minecraft:glowstone
fill ~133~13~19 ~138~13~20 minecraft:wool 7
fill ~134~14~19 ~136~14~20 minecraft:stone_block_slab 0
fill ~137~14~19 ~137~14~25 minecraft:double_stone_block_slab 0
fill ~140~13~19 ~145~13~20 minecraft:wool 7
fill ~141~14~19 ~141~14~25 minecraft:double_stone_block_slab 0
fill ~142~14~19 ~144~14~20 minecraft:stone_block_slab 0
fill ~149~12~19 ~149~13~19 minecraft:glowstone
fill ~149~14~19 ~203~14~19 minecraft:wool 7
fill ~149~15~19 ~149~16~19 minecraft:glowstone
fill ~149~18~19 ~149~19~19 minecraft:glowstone
fill ~150~12~19 ~203~13~19 minecraft:wool 7
fill ~150~15~19 ~203~16~19 minecraft:wool 7
fill ~150~18~19 ~156~18~22 minecraft:wool 7
fill ~150~19~19 ~156~19~20 minecraft:wool 7
fill ~150~20~19 ~152~20~21 minecraft:wool 7
fill ~153~20~19 ~157~20~19 minecraft:wool 8
fill ~158~20~19 ~166~20~34 minecraft:wool 7
fill ~160~24~19 ~160~24~22 minecraft:stone_block_slab 0
fill ~162~24~19 ~162~24~22 minecraft:stone_block_slab 0
setblock ~172~22~19 minecraft:dispenser 3
fill ~172~23~19 ~172~23~21 minecraft:wool 7
setblock ~176~22~19 minecraft:dispenser 3
fill ~176~23~19 ~176~23~21 minecraft:wool 7
fill ~179~20~19 ~182~20~37 minecraft:wool 7
fill ~183~20~19 ~202~20~19 minecraft:wool 8
fill ~203~20~19 ~210~20~29 minecraft:wool 7
fill ~218~23~19 ~220~23~28 minecraft:wool 7
fill ~218~24~19 ~220~24~19 minecraft:stone_block_slab 0
fill ~218~25~19 ~218~25~21 minecraft:wool 7
fill ~220~25~19 ~220~25~21 minecraft:wool 7
fill ~228~1~19 ~228~1~56 minecraft:wool 15
fill ~229~8~19 ~229~9~58 minecraft:wool 7
fill ~229~10~19 ~229~10~31 minecraft:wool 7
fill ~235~23~19 ~237~23~20 minecraft:wool 7
fill ~236~24~19 ~237~24~19 minecraft:stone_block_slab 0
fill ~239~23~19 ~241~23~20 minecraft:wool 7
fill ~239~24~19 ~240~24~19 minecraft:stone_block_slab 0
fill ~2~19~20 ~5~19~23 minecraft:wool 7
fill ~3~16~20 ~3~16~32 minecraft:wool 7
fill ~3~20~20 ~5~20~37 minecraft:wool 7
setblock ~6~19~20 minecraft:redstone_torch 5
setblock ~6~20~20 minecraft:lit_redstone_lamp
fill ~7~19~20 ~18~20~23 minecraft:wool 7
fill ~7~23~20 ~8~23~22 minecraft:wool 8
fill ~7~24~20 ~7~24~22 minecraft:stone_block_slab 0
fill ~8~24~20 ~8~24~22 minecraft:wool 8
fill ~8~25~20 ~8~25~22 minecraft:stone_block_slab 0
fill ~9~16~20 ~9~16~34 minecraft:wool 7
fill ~10~23~20 ~11~23~22 minecraft:wool 8
fill ~10~24~20 ~10~24~22 minecraft:wool 8
fill ~10~25~20 ~10~25~22 minecraft:stone_block_slab 0
fill ~11~14~20 ~33~14~21 minecraft:wool 7
fill ~11~24~20 ~11~24~22 minecraft:stone_block_slab 0
setblock ~19~19~20 minecraft:redstone_torch 5
setblock ~19~20~20 minecraft:lit_redstone_lamp
fill ~20~19~20 ~31~20~23 minecraft:wool 7
fill ~25~23~20 ~26~23~22 minecraft:wool 8
fill ~25~24~20 ~25~24~22 minecraft:stone_block_slab 0
fill ~26~24~20 ~26~24~22 minecraft:wool 8
fill ~26~25~20 ~26~25~22 minecraft:stone_block_slab 0
fill ~28~23~20 ~29~23~22 minecraft:wool 8
fill ~28~24~20 ~28~24~22 minecraft:wool 8
fill ~28~25~20 ~28~25~22 minecraft:stone_block_slab 0
fill ~29~24~20 ~29~24~22 minecraft:stone_block_slab 0
setblock ~32~19~20 minecraft:redstone_torch 5
setblock ~32~20~20 minecraft:lit_redstone_lamp
fill ~33~19~20 ~33~20~23 minecraft:wool 7
fill ~34~20~20 ~44~20~40 minecraft:wool 7
fill ~35~19~20 ~44~19~23 minecraft:wool 7
fill ~43~23~20 ~44~23~22 minecraft:wool 8
fill ~43~24~20 ~43~24~22 minecraft:stone_block_slab 0
fill ~44~14~20 ~100~14~21 minecraft:wool 7
fill ~44~15~20 ~80~15~20 minecraft:wool 7
fill ~44~24~20 ~44~24~22 minecraft:wool 8
fill ~44~25~20 ~44~25~22 minecraft:stone_block_slab 0
setblock ~45~19~20 minecraft:redstone_torch 5
setblock ~45~20~20 minecraft:lit_redstone_lamp
fill ~46~19~20 ~49~20~23 minecraft:wool 7
fill ~46~23~20 ~47~23~22 minecraft:wool 8
fill ~46~24~20 ~46~24~22 minecraft:wool 8
fill ~46~25~20 ~46~25~22 minecraft:stone_block_slab 0
fill ~47~24~20 ~47~24~22 minecraft:stone_block_slab 0
setblock ~58~19~20 minecraft:redstone_torch 5
setblock ~58~20~20 minecraft:lit_redstone_lamp
fill ~58~27~20 ~72~29~25 minecraft:wool 8
fill ~58~30~20 ~58~30~21 minecraft:glass
fill ~58~31~20 ~59~31~25 minecraft:wool 8
fill ~58~32~20 ~58~32~22 minecraft:iron_bars
fill ~59~21~20 ~59~24~24 minecraft:wool 8
fill ~59~25~20 ~59~25~21 minecraft:glass
fill ~59~26~20 ~59~26~24 minecraft:wool 8
fill ~59~30~20 ~61~30~24 minecraft:wool 8
fill ~60~31~20 ~68~31~24 minecraft:wool 7
fill ~62~21~20 ~62~24~20 minecraft:double_stone_block_slab 0
setblock ~62~25~20 minecraft:glowstone
setblock ~62~26~20 minecraft:double_stone_block_slab 0
fill ~63~21~20 ~64~21~20 minecraft:chest 3
fill ~63~22~20 ~64~22~20 minecraft:stone_block_slab 8
fill ~63~23~20 ~64~23~20 minecraft:chest 3
fill ~63~24~20 ~64~24~20 minecraft:stone_block_slab 8
fill ~63~25~20 ~64~25~20 minecraft:chest 3
fill ~63~26~20 ~64~26~20 minecraft:stone_block_slab 8
fill ~64~30~20 ~65~30~24 minecraft:wool 8
fill ~65~21~20 ~65~24~20 minecraft:double_stone_block_slab 0
setblock ~65~25~20 minecraft:glowstone
setblock ~65~26~20 minecraft:double_stone_block_slab 0
fill ~66~21~20 ~67~21~20 minecraft:chest 3
fill ~66~22~20 ~67~22~20 minecraft:stone_block_slab 8
fill ~66~23~20 ~67~23~20 minecraft:chest 3
fill ~66~24~20 ~67~24~20 minecraft:stone_block_slab 8
fill ~66~25~20 ~67~25~20 minecraft:chest 3
fill ~66~26~20 ~67~26~20 minecraft:stone_block_slab 8
fill ~68~21~20 ~68~24~20 minecraft:double_stone_block_slab 0
setblock ~68~25~20 minecraft:glowstone
setblock ~68~26~20 minecraft:double_stone_block_slab 0
fill ~68~30~20 ~69~30~24 minecraft:wool 8
fill ~69~21~20 ~70~21~20 minecraft:chest 3
fill ~69~22~20 ~70~22~20 minecraft:stone_block_slab 8
fill ~69~23~20 ~70~23~20 minecraft:chest 3
fill ~69~24~20 ~70~24~20 minecraft:stone_block_slab 8
fill ~69~25~20 ~70~25~20 minecraft:chest 3
fill ~69~26~20 ~70~26~20 minecraft:stone_block_slab 8
fill ~69~31~20 ~72~31~25 minecraft:wool 8
fill ~70~47~20 ~70~47~28 minecraft:iron_bars
fill ~71~21~20 ~71~26~20 minecraft:double_stone_block_slab 0
fill ~71~34~20 ~71~36~20 minecraft:stone_block_slab 0
fill ~71~47~20 ~71~47~27 minecraft:wool 8
fill ~71~48~20 ~71~48~21 minecraft:glass
fill ~72~21~20 ~72~24~28 minecraft:wool 8
fill ~72~25~20 ~72~26~26 minecraft:wool 8
fill ~72~30~20 ~72~30~26 minecraft:wool 8
fill ~72~32~20 ~82~32~30 minecraft:wool 8
fill ~72~33~20 ~72~33~30 minecraft:wool 8
fill ~72~47~20 ~72~47~21 minecraft:stone_block_slab 8
fill ~72~48~20 ~72~48~21 minecraft:redstone_torch 5
fill ~72~49~20 ~72~49~27 minecraft:wool 8
fill ~73~47~20 ~73~47~21 minecraft:stone_brick_stairs 0
fill ~73~50~20 ~80~50~20 minecraft:wool 8
fill ~74~12~20 ~77~13~20 minecraft:wool 7
setblock ~74~22~20 minecraft:torch 3
fill ~77~8~20 ~80~10~20 minecraft:wool 7
fill ~78~51~20 ~80~53~22 minecraft:wool 8
setblock ~79~47~20 minecraft:stone_pressure_plate 0
fill ~80~5~20 ~83~7~20 minecraft:wool 15
setblock ~80~22~20 minecraft:torch 3
setblock ~80~47~20 minecraft:iron_door 2
fill ~80~49~20 ~80~49~22 minecraft:wool 8
setblock ~81~9~20 minecraft:glowstone
fill ~81~37~20 ~89~37~30 minecraft:wool 8
fill ~81~38~20 ~92~38~22 minecraft:wool 8
fill ~81~39~20 ~91~39~20 minecraft:fence 0
setblock ~81~47~20 minecraft:stone_pressure_plate 0
fill ~82~33~20 ~82~33~21 minecraft:stone_block_slab 0
fill ~83~3~20 ~86~4~20 minecraft:wool 15
fill ~83~32~20 ~83~32~21 minecraft:double_stone_block_slab 0
fill ~84~32~20 ~84~32~21 minecraft:stone_block_slab 0
setblock ~84~50~20 minecraft:torch 4
fill ~85~31~20 ~85~31~21 minecraft:glowstone
fill ~86~2~20 ~88~2~21 minecraft:wool 15
setblock ~86~5~20 minecraft:glowstone
setblock ~86~22~20 minecraft:torch 3
fill ~86~31~20 ~86~31~21 minecraft:stone_block_slab 0
fill ~87~30~20 ~87~30~21 minecraft:double_stone_block_slab 0
fill ~88~29~20 ~89~29~20 minecraft:double_stone_block_slab 0
fill ~88~30~20 ~88~30~21 minecraft:stone_block_slab 0
setblock ~89~49~20 minecraft:torch 4
fill ~90~29~20 ~90~29~21 minecraft:stone_block_slab 0
fill ~91~28~20 ~91~28~21 minecraft:glowstone
fill ~92~1~20 ~95~1~20 minecraft:wool 15
setblock ~92~22~20 minecraft:torch 3
fill ~92~28~20 ~92~28~21 minecraft:stone_block_slab 0
fill ~93~27~20 ~93~27~21 minecraft:double_stone_block_slab 0
fill ~93~32~20 ~108~32~30 minecraft:wool 8
fill ~93~33~20 ~106~33~22 minecraft:wool 8
fill ~94~27~20 ~94~27~21 minecraft:stone_block_slab 0
fill ~95~0~20 ~97~0~41 minecraft:wool 15
fill ~95~26~20 ~95~26~21 minecraft:double_stone_block_slab 0
fill ~96~21~20 ~106~24~24 minecraft:wool 8
fill ~96~25~20 ~98~26~24 minecraft:wool 8
fill ~96~29~20 ~106~29~20 minecraft:wool 8
fill ~96~30~20 ~98~31~27 minecraft:wool 8
fill ~96~34~20 ~99~36~20 minecraft:stone_block_slab 0
fill ~97~37~20 ~97~37~30 minecraft:wool 8
fill ~97~47~20 ~97~50~25 minecraft:wool 8
fill ~97~51~20 ~97~52~24 minecraft:wool 8
fill ~99~26~20 ~121~26~20 minecraft:wool 8
fill ~99~31~20 ~106~31~28 minecraft:wool 8
fill ~99~52~20 ~101~52~20 minecraft:wool 8
fill ~100~25~20 ~101~25~27 minecraft:wool 8
fill ~100~30~20 ~101~30~27 minecraft:wool 8
fill ~100~39~20 ~100~40~20 minecraft:fence 0
fill ~101~37~20 ~101~37~31 minecraft:wool 8
fill ~101~41~20 ~103~41~20 minecraft:fence 0
fill ~103~47~20 ~103~50~25 minecraft:wool 8
fill ~103~51~20 ~103~52~24 minecraft:wool 8
fill ~104~25~20 ~106~25~27 minecraft:wool 8
fill ~104~30~20 ~105~30~27 minecraft:wool 8
fill ~104~39~20 ~104~40~20 minecraft:fence 0
fill ~106~27~20 ~106~28~23 minecraft:wool 8
fill ~107~28~20 ~121~28~21 minecraft:wool 8
fill ~107~30~20 ~122~30~21 minecraft:wool 8
setblock ~107~37~20 minecraft:torch 1
setblock ~109~22~20 minecraft:torch 3
setblock ~113~22~20 minecraft:torch 3
setblock ~116~22~20 minecraft:torch 3
fill ~120~27~20 ~121~27~20 minecraft:iron_bars
fill ~121~21~20 ~121~25~20 minecraft:wool 8
fill ~122~27~20 ~122~27~21 minecraft:wool 8
fill ~123~20~20 ~123~20~21 minecraft:wool 7
fill ~123~21~20 ~123~26~21 minecraft:wool 8
fill ~123~29~20 ~123~29~21 minecraft:wool 8
fill ~124~28~20 ~124~28~21 minecraft:wool 8
fill ~125~26~20 ~126~26~21 minecraft:wool 8
fill ~125~27~20 ~125~27~21 minecraft:wool 8
fill ~126~20~20 ~126~20~21 minecraft:wool 7
fill ~126~21~20 ~126~25~21 minecraft:wool 8
fill ~130~12~20 ~130~13~23 minecraft:wool 7
fill ~130~15~20 ~130~16~23 minecraft:wool 7
fill ~130~18~20 ~130~19~23 minecraft:wool 7
fill ~136~12~20 ~136~12~21 minecraft:wool 7
fill ~142~12~20 ~142~12~21 minecraft:wool 7
fill ~149~11~20 ~184~16~20 minecraft:wool 7
fill ~149~18~20 ~149~19~23 minecraft:wool 7
fill ~153~20~20 ~153~20~35 minecraft:wool 8
fill ~154~20~20 ~156~20~20 minecraft:stone_block_slab 0
fill ~157~20~20 ~157~20~35 minecraft:wool 8
setblock ~161~24~20 minecraft:double_stone_block_slab 0
setblock ~161~25~20 minecraft:stone_block_slab 0
fill ~174~24~20 ~174~24~21 minecraft:wool 7
fill ~181~18~20 ~184~19~20 minecraft:wool 7
fill ~182~17~20 ~184~17~20 minecraft:wool 7
fill ~183~20~20 ~184~22~20 minecraft:wool 7
fill ~201~11~20 ~225~11~20 minecraft:wool 7
fill ~201~12~20 ~203~19~20 minecraft:wool 7
fill ~201~20~20 ~202~22~20 minecraft:wool 7
fill ~204~17~20 ~204~17~23 minecraft:wool 7
fill ~204~18~20 ~204~19~22 minecraft:wool 7
setblock ~207~23~20 minecraft:wool 15
fill ~207~26~20 ~207~26~22 minecraft:wool 7
fill ~207~27~20 ~207~27~21 minecraft:stone_block_slab 0
fill ~218~24~20 ~218~24~23 minecraft:wool 7
setblock ~218~26~20 minecraft:stone_block_slab 0
fill ~219~22~20 ~219~22~30 minecraft:wool 7
fill ~219~24~20 ~219~24~25 minecraft:stone_block_slab 0
fill ~220~24~20 ~220~24~23 minecraft:wool 7
setblock ~220~26~20 minecraft:stone_block_slab 0
fill ~228~0~20 ~228~0~55 minecraft:wool 15
fill ~228~16~20 ~228~16~30 minecraft:wool 7
fill ~229~5~20 ~229~7~57 minecraft:wool 15
fill ~236~24~20 ~236~24~21 minecraft:stone_block_slab 0
fill ~237~24~20 ~239~24~30 minecraft:wool 7
fill ~238~23~20 ~238~23~31 minecraft:wool 7
fill ~238~25~20 ~238~25~26 minecraft:stone_block_slab 0
fill ~240~24~20 ~240~24~21 minecraft:stone_block_slab 0
fill ~241~20~20 ~244~20~27 minecraft:wool 7
fill ~245~20~20 ~246~20~21 minecraft:glowstone
fill ~247~20~20 ~250~20~32 minecraft:wool 7
fill ~2~17~21 ~2~17~31 minecraft:wool 7
fill ~5~15~21 ~11~15~24 minecraft:wool 7
fill ~5~17~21 ~9~17~23 minecraft:wool 7
fill ~6~19~21 ~6~20~23 minecraft:wool 7
fill ~10~14~21 ~10~14~28 minecraft:wool 7
fill ~11~13~21 ~33~13~22 minecraft:wool 7
setblock ~12~15~21 minecraft:glowstone
fill ~19~19~21 ~19~20~23 minecraft:wool 7
fill ~32~19~21 ~32~20~23 minecraft:wool 7
setblock ~33~15~21 minecraft:glowstone
fill ~44~13~21 ~100~13~22 minecraft:wool 7
setblock ~44~15~21 minecraft:glowstone
fill ~45~19~21 ~45~20~23 minecraft:wool 7
fill ~58~19~21 ~58~20~23 minecraft:wool 7
fill ~71~12~21 ~74~12~23 minecraft:wool 7
fill ~71~21~21 ~71~21~22 minecraft:chest 4
fill ~71~22~21 ~71~22~22 minecraft:stone_block_slab 8
fill ~71~23~21 ~71~23~22 minecraft:chest 4
fill ~71~24~21 ~71~24~22 minecraft:stone_block_slab 8
fill ~71~25~21 ~71~25~22 minecraft:chest 4
fill ~71~26~21 ~71~26~22 minecraft:stone_block_slab 8
setblock ~73~22~21 minecraft:torch 1
fill ~73~50~21 ~75~50~27 minecraft:wool 8
fill ~74~8~21 ~77~10~21 minecraft:wool 7
fill ~76~49~21 ~79~49~21 minecraft:wool 8
fill ~77~5~21 ~80~7~21 minecraft:wool 15
fill ~77~34~21 ~77~36~21 minecraft:stone_block_slab 0
fill ~77~47~21 ~77~48~21 minecraft:double_stone_block_slab 0
fill ~78~47~21 ~79~48~21 minecraft:stone_block_slab 0
fill ~78~50~21 ~94~50~21 minecraft:wool 8
fill ~79~54~21 ~79~56~21 minecraft:wool 8
fill ~80~3~21 ~83~4~21 minecraft:wool 15
fill ~80~47~21 ~94~48~21 minecraft:wool 8
fill ~81~49~21 ~94~49~21 minecraft:wool 8
fill ~81~51~21 ~94~52~21 minecraft:wool 8
fill ~83~2~21 ~85~2~22 minecraft:wool 15
fill ~85~3~21 ~85~3~22 minecraft:glowstone
fill ~89~1~21 ~92~1~21 minecraft:wool 15
setblock ~89~29~21 minecraft:double_stone_block_slab 0
fill ~92~0~21 ~94~0~40 minecraft:wool 15
setblock ~92~2~21 minecraft:glowstone
setblock ~92~15~21 minecraft:glowstone
setblock ~94~1~21 minecraft:glowstone
fill ~94~20~21 ~101~20~24 minecraft:wool 7
setblock ~94~26~21 minecraft:double_stone_block_slab 0
setblock ~95~15~21 minecraft:glowstone
fill ~96~29~21 ~99~29~28 minecraft:wool 8
setblock ~96~50~21 minecraft:torch 2
fill ~97~15~21 ~98~15~21 minecraft:glowstone
fill ~98~54~21 ~98~56~21 minecraft:wool 0
fill ~99~26~21 ~120~26~21 minecraft:wool 8
fill ~99~57~21 ~101~57~21 minecraft:wool 0
setblock ~100~7~21 minecraft:glowstone
setblock ~100~9~21 minecraft:glowstone
setblock ~100~15~21 minecraft:glowstone
setblock ~100~29~21 minecraft:glowstone
fill ~101~29~21 ~103~29~28 minecraft:wool 8
setblock ~102~15~21 minecraft:wool 7
setblock ~102~20~21 minecraft:wool 8
fill ~102~54~21 ~102~56~21 minecraft:wool 0
fill ~103~20~21 ~103~20~43 minecraft:wool 7
setblock ~104~15~21 minecraft:wool 7
setblock ~104~20~21 minecraft:wool 8
setblock ~104~29~21 minecraft:glowstone
fill ~105~29~21 ~106~29~28 minecraft:wool 8
setblock ~106~15~21 minecraft:glowstone
setblock ~108~15~21 minecraft:glowstone
setblock ~110~15~21 minecraft:glowstone
setblock ~112~15~21 minecraft:glowstone
setblock ~114~15~21 minecraft:glowstone
setblock ~117~15~21 minecraft:glowstone
setblock ~119~15~21 minecraft:glowstone
fill ~119~27~21 ~120~27~21 minecraft:iron_bars
fill ~120~21~21 ~120~24~21 minecraft:wool 8
setblock ~120~25~21 minecraft:glass
setblock ~121~15~21 minecraft:glowstone
setblock ~123~15~21 minecraft:glowstone
setblock ~125~15~21 minecraft:glowstone
fill ~134~13~21 ~138~13~21 minecraft:wool 7
fill ~135~14~21 ~136~14~22 minecraft:stone_block_slab 0
fill ~140~13~21 ~144~13~21 minecraft:wool 7
fill ~142~14~21 ~143~14~22 minecraft:stone_block_slab 0
fill ~149~11~21 ~183~11~23 minecraft:wool 7
fill ~149~12~21 ~183~13~22 minecraft:wool 7
fill ~149~14~21 ~183~14~21 minecraft:wool 7
fill ~149~15~21 ~149~16~23 minecraft:wool 7
fill ~150~15~21 ~152~15~21 minecraft:glowstone
fill ~150~16~21 ~183~16~23 minecraft:wool 7
fill ~150~19~21 ~153~19~23 minecraft:wool 7
fill ~154~15~21 ~155~15~21 minecraft:glowstone
fill ~154~19~21 ~156~19~21 minecraft:iron_block
setblock ~157~15~21 minecraft:glowstone
setblock ~159~15~21 minecraft:glowstone
fill ~159~23~21 ~160~23~21 minecraft:wool 7
setblock ~159~24~21 minecraft:stone_block_slab 0
setblock ~161~15~21 minecraft:glowstone
fill ~161~25~21 ~161~25~22 minecraft:glass
fill ~162~23~21 ~163~23~21 minecraft:wool 7
setblock ~163~15~21 minecraft:glowstone
setblock ~163~24~21 minecraft:stone_block_slab 0
setblock ~165~15~21 minecraft:glowstone
setblock ~167~15~21 minecraft:glowstone
setblock ~169~15~21 minecraft:glowstone
setblock ~171~15~21 minecraft:glowstone
setblock ~173~15~21 minecraft:glowstone
fill ~173~24~21 ~173~24~24 minecraft:stone_block_slab 0
fill ~175~24~21 ~175~24~24 minecraft:stone_block_slab 0
setblock ~176~15~21 minecraft:glowstone
setblock ~178~15~21 minecraft:glowstone
setblock ~180~15~21 minecraft:glowstone
fill ~181~18~21 ~183~19~22 minecraft:wool 7
fill ~182~15~21 ~183~15~22 minecraft:wool 7
fill ~182~17~21 ~183~17~23 minecraft:wool 7
fill ~183~20~21 ~183~22~21 minecraft:wool 7
fill ~184~11~21 ~184~21~21 minecraft:iron_bars
setblock ~184~22~21 minecraft:wool 7
fill ~192~17~21 ~192~17~27 minecraft:stone_block_slab 3
fill ~201~11~21 ~201~21~21 minecraft:iron_bars
fill ~201~22~21 ~202~22~21 minecraft:wool 7
fill ~202~11~21 ~225~11~22 minecraft:wool 7
fill ~202~12~21 ~203~13~22 minecraft:wool 7
fill ~202~14~21 ~203~14~21 minecraft:wool 7
fill ~202~15~21 ~202~19~23 minecraft:wool 7
fill ~202~20~21 ~202~21~21 minecraft:wool 7
fill ~203~15~21 ~227~15~21 minecraft:glowstone
fill ~203~16~21 ~203~16~61 minecraft:wool 7
fill ~203~17~21 ~203~17~23 minecraft:wool 7
fill ~203~18~21 ~203~19~22 minecraft:wool 7
setblock ~205~12~21 minecraft:stone_pressure_plate 0
fill ~207~23~21 ~207~23~28 minecraft:wool 7
setblock ~207~24~21 minecraft:stone_block_slab 0
fill ~207~25~21 ~207~25~24 minecraft:wool 7
fill ~213~23~21 ~217~23~22 minecraft:wool 7
fill ~215~24~21 ~217~24~22 minecraft:stone_block_slab 0
fill ~217~5~21 ~227~6~26 minecraft:wool 15
fill ~217~7~21 ~227~7~25 minecraft:wool 15
fill ~218~22~21 ~218~22~27 minecraft:wool 7
fill ~220~22~21 ~220~22~27 minecraft:wool 7
fill ~221~23~21 ~225~23~22 minecraft:wool 7
fill ~221~24~21 ~223~24~22 minecraft:stone_block_slab 0
fill ~228~15~21 ~228~15~59 minecraft:wool 7
fill ~228~17~21 ~228~17~23 minecraft:wool 7
fill ~229~3~21 ~229~4~56 minecraft:wool 15
fill ~236~23~21 ~237~23~21 minecraft:wool 7
fill ~236~25~21 ~236~25~25 minecraft:wool 7
fill ~237~25~21 ~237~25~30 minecraft:stone_block_slab 0
fill ~239~23~21 ~240~23~21 minecraft:wool 7
fill ~239~25~21 ~239~25~30 minecraft:stone_block_slab 0
fill ~240~25~21 ~240~25~25 minecraft:wool 7
fill ~8~14~22 ~9~14~30 minecraft:wool 7
fill ~9~13~22 ~10~13~28 minecraft:wool 7
fill ~11~12~22 ~33~12~23 minecraft:wool 7
fill ~11~14~22 ~11~14~24 minecraft:wool 7
fill ~34~11~22 ~34~11~23 minecraft:wool 7
fill ~44~12~22 ~70~12~23 minecraft:wool 7
fill ~56~21~22 ~58~26~22 minecraft:iron_bars
fill ~56~27~22 ~57~32~22 minecraft:iron_bars
fill ~58~30~22 ~58~30~25 minecraft:wool 8
fill ~59~25~22 ~59~25~24 minecraft:wool 8
setblock ~63~33~22 minecraft:wool 0
fill ~64~32~22 ~64~32~24 minecraft:wool 0
setblock ~64~33~22 minecraft:lit_redstone_lamp
fill ~64~34~22 ~64~34~24 minecraft:wool 0
setblock ~65~33~22 minecraft:wool 0
setblock ~69~37~22 minecraft:torch 2
setblock ~70~35~22 minecraft:wool 8
setblock ~70~40~22 minecraft:wool 8
setblock ~70~43~22 minecraft:wool 8
fill ~71~8~22 ~74~10~22 minecraft:wool 7
fill ~71~34~22 ~74~36~23 minecraft:stone_block_slab 0
setblock ~71~48~22 minecraft:wool 8
setblock ~72~47~22 minecraft:double_stone_block_slab 0
setblock ~72~48~22 minecraft:lever 1
setblock ~73~47~22 minecraft:stone_button 5
fill ~74~5~22 ~77~7~22 minecraft:wool 15
setblock ~75~8~22 minecraft:glowstone
fill ~75~12~22 ~100~12~22 minecraft:wool 7
fill ~76~49~22 ~76~49~26 minecraft:wool 8
fill ~77~3~22 ~80~4~22 minecraft:wool 15
fill ~77~47~22 ~81~48~22 minecraft:wool 8
fill ~78~49~22 ~79~50~22 minecraft:wool 8
fill ~78~55~22 ~79~55~22 minecraft:wool 8
fill ~80~2~22 ~82~2~23 minecraft:wool 15
fill ~80~33~22 ~92~33~24 minecraft:wool 8
fill ~80~50~22 ~81~50~22 minecraft:wool 8
fill ~80~66~22 ~93~66~25 minecraft:wool 8
fill ~80~67~22 ~93~67~22 minecraft:wool 8
fill ~80~68~22 ~93~68~22 minecraft:iron_bars
fill ~81~34~22 ~92~34~22 minecraft:iron_bars
fill ~81~49~22 ~81~49~26 minecraft:wool 8
fill ~81~51~22 ~81~52~26 minecraft:wool 8
fill ~81~53~22 ~94~56~22 minecraft:wool 8
fill ~82~47~22 ~82~52~22 minecraft:stone_block_slab 0
fill ~83~32~22 ~92~32~30 minecraft:wool 8
fill ~83~47~22 ~83~51~22 minecraft:iron_block
setblock ~83~52~22 minecraft:glowstone
fill ~84~47~22 ~84~52~22 minecraft:stone_block_slab 0
fill ~85~24~22 ~89~26~22 minecraft:iron_block
fill ~85~27~22 ~86~31~22 minecraft:iron_block
fill ~85~47~22 ~85~51~22 minecraft:iron_block
setblock ~85~52~22 minecraft:glowstone
fill ~86~1~22 ~89~1~22 minecraft:wool 15
fill ~86~47~22 ~86~52~22 minecraft:stone_block_slab 0
fill ~87~27~22 ~88~27~22 minecraft:glowstone
fill ~87~28~22 ~95~31~22 minecraft:iron_block
fill ~87~47~22 ~87~51~22 minecraft:iron_block
setblock ~87~52~22 minecraft:glowstone
fill ~88~47~22 ~88~52~22 minecraft:stone_block_slab 0
fill ~89~0~22 ~91~0~40 minecraft:wool 15
fill ~89~27~22 ~95~27~22 minecraft:iron_block
fill ~89~47~22 ~89~51~22 minecraft:iron_block
setblock ~89~52~22 minecraft:glowstone
setblock ~90~1~22 minecraft:glowstone
fill ~90~25~22 ~90~26~22 minecraft:iron_block
fill ~90~47~22 ~90~52~22 minecraft:stone_block_slab 0
fill ~91~26~22 ~92~26~22 minecraft:iron_block
fill ~91~47~22 ~91~51~22 minecraft:iron_block
setblock ~91~52~22 minecraft:glowstone
fill ~92~47~22 ~92~52~22 minecraft:stone_block_slab 0
fill ~93~14~22 ~94~14~22 minecraft:glowstone
fill ~93~47~22 ~93~51~22 minecraft:iron_block
setblock ~93~52~22 minecraft:glowstone
fill ~94~47~22 ~94~52~26 minecraft:wool 8
setblock ~95~22~22 minecraft:torch 2
fill ~99~26~22 ~119~26~22 minecraft:wool 8
fill ~99~54~22 ~101~56~22 minecraft:wool 0
setblock ~100~5~22 minecraft:glowstone
fill ~100~29~22 ~100~29~28 minecraft:wool 8
setblock ~102~15~22 minecraft:glowstone
fill ~102~20~22 ~102~20~34 minecraft:wool 7
fill ~103~34~22 ~105~34~22 minecraft:iron_bars
setblock ~104~15~22 minecraft:glowstone
fill ~104~20~22 ~104~20~43 minecraft:wool 7
fill ~104~29~22 ~104~29~28 minecraft:wool 8
setblock ~105~28~22 minecraft:torch 2
setblock ~105~39~22 minecraft:stone_pressure_plate 0
setblock ~106~39~22 minecraft:iron_door 2
fill ~106~41~22 ~106~41~24 minecraft:wool 8
setblock ~107~22~22 minecraft:torch 1
fill ~107~29~22 ~122~29~22 minecraft:wool 8
setblock ~107~39~22 minecraft:stone_pressure_plate 0
fill ~118~27~22 ~119~27~22 minecraft:iron_bars
fill ~119~21~22 ~119~25~22 minecraft:wool 8
fill ~122~28~22 ~123~28~22 minecraft:wool 8
setblock ~123~20~22 minecraft:glowstone
fill ~123~27~22 ~124~27~22 minecraft:wool 8
fill ~124~21~22 ~125~25~22 minecraft:wool 8
setblock ~124~26~22 minecraft:wool 8
setblock ~126~20~22 minecraft:glowstone
fill ~130~14~22 ~130~14~23 minecraft:wool 7
fill ~135~13~22 ~138~13~23 minecraft:wool 7
fill ~139~15~22 ~139~15~25 minecraft:double_stone_block_slab 0
fill ~140~13~22 ~143~13~23 minecraft:wool 7
fill ~149~14~22 ~149~14~23 minecraft:wool 7
fill ~150~20~22 ~152~20~22 minecraft:glowstone
fill ~154~19~22 ~156~19~22 minecraft:stone_block_slab 0
setblock ~160~23~22 minecraft:wool 7
setblock ~162~23~22 minecraft:wool 7
setblock ~174~24~22 minecraft:double_stone_block_slab 0
setblock ~174~25~22 minecraft:stone_block_slab 0
fill ~179~14~22 ~181~14~23 minecraft:wool 0
fill ~182~14~22 ~183~14~22 minecraft:wool 7
fill ~183~20~22 ~183~20~33 minecraft:wool 8
fill ~202~14~22 ~202~14~23 minecraft:wool 7
fill ~202~20~22 ~202~20~33 minecraft:wool 8
fill ~203~23~22 ~206~23~23 minecraft:wool 7
setblock ~204~13~22 minecraft:wool 7
fill ~204~24~22 ~206~24~24 minecraft:stone_block_slab 0
setblock ~205~12~22 minecraft:iron_door 3
setblock ~206~13~22 minecraft:wool 7
fill ~207~22~22 ~207~22~30 minecraft:wool 7
fill ~207~24~22 ~207~24~29 minecraft:wool 7
fill ~208~23~22 ~211~23~23 minecraft:wool 7
fill ~208~24~22 ~210~24~24 minecraft:stone_block_slab 0
fill ~209~14~22 ~209~14~23 minecraft:wool 8
fill ~216~22~22 ~217~22~22 minecraft:wool 7
setblock ~218~25~22 minecraft:stone_block_slab 0
setblock ~220~25~22 minecraft:stone_block_slab 0
fill ~221~22~22 ~222~22~22 minecraft:wool 7
fill ~228~14~22 ~228~14~23 minecraft:wool 7
fill ~229~2~22 ~229~2~56 minecraft:wool 15
fill ~230~13~22 ~247~13~45 minecraft:wool 7
fill ~235~26~22 ~235~26~24 minecraft:wool 7
setblock ~237~23~22 minecraft:wool 7
setblock ~239~23~22 minecraft:wool 7
fill ~241~26~22 ~241~26~24 minecraft:wool 7
fill ~245~20~22 ~246~20~32 minecraft:wool 7
fill ~7~14~23 ~7~14~29 minecraft:wool 7
fill ~8~13~23 ~8~13~29 minecraft:wool 7
fill ~8~23~23 ~8~23~30 minecraft:wool 8
fill ~8~24~23 ~8~24~29 minecraft:stone_block_slab 0
fill ~10~12~23 ~10~12~28 minecraft:wool 7
fill ~10~23~23 ~10~23~30 minecraft:wool 8
fill ~10~24~23 ~10~24~29 minecraft:stone_block_slab 0
fill ~11~10~23 ~71~10~23 minecraft:wool 7
fill ~11~11~23 ~33~11~23 minecraft:wool 7
fill ~11~13~23 ~11~13~24 minecraft:wool 7
fill ~26~23~23 ~26~23~26 minecraft:wool 8
fill ~26~24~23 ~26~24~25 minecraft:stone_block_slab 0
fill ~28~23~23 ~28~23~30 minecraft:wool 8
fill ~28~24~23 ~28~24~25 minecraft:stone_block_slab 0
fill ~44~23~23 ~44~23~26 minecraft:wool 8
fill ~44~24~23 ~44~24~25 minecraft:stone_block_slab 0
fill ~46~23~23 ~46~23~30 minecraft:wool 8
fill ~46~24~23 ~46~24~25 minecraft:stone_block_slab 0
fill ~56~23~23 ~56~32~24 minecraft:iron_bars
fill ~57~21~23 ~57~31~23 minecraft:ladder 4
fill ~58~21~23 ~58~26~23 minecraft:wool 8
setblock ~61~21~23 minecraft:stone_pressure_plate 0
fill ~62~21~23 ~62~24~23 minecraft:double_stone_block_slab 0
setblock ~62~25~23 minecraft:glowstone
setblock ~62~26~23 minecraft:double_stone_block_slab 0
fill ~63~21~23 ~64~21~23 minecraft:chest 2
fill ~63~22~23 ~64~22~23 minecraft:stone_block_slab 8
fill ~63~23~23 ~64~23~23 minecraft:chest 2
fill ~63~24~23 ~64~24~23 minecraft:stone_block_slab 8
fill ~63~25~23 ~64~25~23 minecraft:chest 2
fill ~63~26~23 ~64~26~23 minecraft:stone_block_slab 8
setblock ~63~32~23 minecraft:wool 0
setblock ~63~33~23 minecraft:lit_redstone_lamp
setblock ~63~34~23 minecraft:wool 0
setblock ~64~33~23 minecraft:redstone_torch 5
fill ~65~21~23 ~65~24~23 minecraft:double_stone_block_slab 0
setblock ~65~25~23 minecraft:glowstone
setblock ~65~26~23 minecraft:double_stone_block_slab 0
setblock ~65~32~23 minecraft:wool 0
setblock ~65~33~23 minecraft:lit_redstone_lamp
setblock ~65~34~23 minecraft:wool 0
fill ~66~18~23 ~69~18~23 minecraft:wool 7
fill ~66~21~23 ~67~21~23 minecraft:chest 2
fill ~66~22~23 ~67~22~23 minecraft:stone_block_slab 8
fill ~66~23~23 ~67~23~23 minecraft:chest 2
fill ~66~24~23 ~67~24~23 minecraft:stone_block_slab 8
fill ~66~25~23 ~67~25~23 minecraft:chest 2
fill ~66~26~23 ~67~26~23 minecraft:stone_block_slab 8
fill ~68~8~23 ~71~8~25 minecraft:wool 7
fill ~68~9~23 ~71~9~24 minecraft:wool 7
fill ~68~21~23 ~68~24~23 minecraft:double_stone_block_slab 0
setblock ~68~25~23 minecraft:glowstone
setblock ~68~26~23 minecraft:double_stone_block_slab 0
fill ~69~21~23 ~70~21~23 minecraft:chest 2
fill ~69~22~23 ~70~22~23 minecraft:stone_block_slab 8
fill ~69~23~23 ~70~23~23 minecraft:chest 2
fill ~69~24~23 ~70~24~23 minecraft:stone_block_slab 8
fill ~69~25~23 ~70~25~23 minecraft:chest 2
fill ~69~26~23 ~70~26~23 minecraft:stone_block_slab 8
fill ~70~18~23 ~71~18~23 minecraft:glowstone
fill ~70~35~23 ~70~35~24 minecraft:glass
fill ~70~40~23 ~70~40~24 minecraft:glass
fill ~70~43~23 ~70~43~24 minecraft:glass
fill ~71~5~23 ~74~7~23 minecraft:wool 15
fill ~71~21~23 ~71~26~23 minecraft:double_stone_block_slab 0
fill ~71~38~23 ~74~38~25 minecraft:grass
fill ~71~48~23 ~71~48~24 minecraft:glass
fill ~72~18~23 ~74~18~23 minecraft:wool 7
fill ~72~46~23 ~84~46~30 minecraft:wool 8
fill ~72~47~23 ~72~47~24 minecraft:stone_block_slab 8
fill ~72~48~23 ~72~48~24 minecraft:redstone_torch 5
fill ~73~47~23 ~73~47~24 minecraft:stone_brick_stairs 0
fill ~74~3~23 ~77~4~23 minecraft:wool 15
fill ~75~12~23 ~90~12~23 minecraft:wool 7
fill ~75~18~23 ~76~18~23 minecraft:glowstone
setblock ~75~38~23 minecraft:wool 8
setblock ~76~38~23 minecraft:glowstone
fill ~77~2~23 ~79~2~24 minecraft:wool 15
fill ~77~18~23 ~79~18~23 minecraft:wool 8
fill ~77~38~23 ~77~38~25 minecraft:wool 8
fill ~78~38~23 ~78~38~24 minecraft:glowstone
fill ~79~38~23 ~79~38~30 minecraft:wool 8
fill ~80~18~23 ~81~18~23 minecraft:glowstone
fill ~80~38~23 ~80~38~24 minecraft:glowstone
setblock ~80~47~23 minecraft:stone_pressure_plate 0
setblock ~80~48~23 minecraft:torch 3
fill ~80~67~23 ~80~67~25 minecraft:wool 8
fill ~80~68~23 ~80~68~25 minecraft:iron_bars
fill ~81~38~23 ~81~38~30 minecraft:wool 8
setblock ~81~47~23 minecraft:iron_door 0
fill ~81~50~23 ~81~50~26 minecraft:wool 8
fill ~81~53~23 ~81~56~25 minecraft:wool 8
fill ~81~57~23 ~81~57~24 minecraft:torch 2
fill ~81~67~23 ~81~67~24 minecraft:glowstone
setblock ~82~10~23 minecraft:glowstone
fill ~82~18~23 ~84~18~23 minecraft:wool 8
fill ~82~38~23 ~82~38~24 minecraft:glowstone
fill ~82~55~23 ~93~55~24 minecraft:lit_redstone_lamp
fill ~82~56~23 ~94~56~25 minecraft:wool 8
fill ~82~57~23 ~92~58~24 minecraft:wool 8
fill ~82~59~23 ~82~65~24 minecraft:wool 8
fill ~82~67~23 ~91~67~25 minecraft:wool 8
fill ~83~1~23 ~86~1~23 minecraft:wool 15
fill ~83~38~23 ~83~38~30 minecraft:wool 8
setblock ~83~54~23 minecraft:redstone_torch 3
fill ~83~59~23 ~84~59~24 minecraft:glass
fill ~83~60~23 ~92~62~24 minecraft:wool 8
fill ~83~63~23 ~84~63~24 minecraft:glass
fill ~83~64~23 ~92~65~24 minecraft:wool 8
fill ~84~38~23 ~84~38~24 minecraft:glowstone
fill ~85~18~23 ~86~18~23 minecraft:glowstone
fill ~85~24~23 ~85~26~27 minecraft:iron_block
fill ~85~27~23 ~85~29~23 minecraft:iron_block
fill ~85~38~23 ~85~38~30 minecraft:wool 8
fill ~85~46~23 ~85~46~24 minecraft:glowstone
setblock ~85~54~23 minecraft:redstone_torch 3
fill ~85~59~23 ~86~59~24 minecraft:wool 8
fill ~85~63~23 ~86~63~24 minecraft:wool 8
fill ~86~0~23 ~88~0~39 minecraft:wool 15
fill ~86~24~23 ~88~24~23 minecraft:stone_block_slab 0
fill ~86~29~23 ~95~29~27 minecraft:iron_block
fill ~86~38~23 ~86~38~24 minecraft:glowstone
fill ~86~39~23 ~95~39~23 minecraft:iron_bars
fill ~86~46~23 ~91~46~30 minecraft:wool 8
fill ~87~18~23 ~89~18~23 minecraft:wool 8
fill ~87~38~23 ~87~38~30 minecraft:wool 8
setblock ~87~54~23 minecraft:redstone_torch 3
fill ~87~59~23 ~88~59~24 minecraft:glass
fill ~87~63~23 ~88~63~24 minecraft:glass
setblock ~88~1~23 minecraft:glowstone
fill ~88~38~23 ~88~38~24 minecraft:glowstone
fill ~89~24~23 ~90~24~24 minecraft:double_stone_block_slab 0
fill ~89~38~23 ~89~38~30 minecraft:wool 8
setblock ~89~54~23 minecraft:redstone_torch 3
fill ~89~59~23 ~90~59~24 minecraft:wool 8
fill ~89~63~23 ~90~63~24 minecraft:wool 8
fill ~90~18~23 ~91~18~23 minecraft:glowstone
fill ~90~25~23 ~90~25~24 minecraft:stone_block_slab 0
fill ~90~38~23 ~90~38~24 minecraft:glowstone
fill ~91~12~23 ~129~12~23 minecraft:wool 8
fill ~91~13~23 ~93~13~23 minecraft:glowstone
fill ~91~14~23 ~129~14~23 minecraft:wool 8
fill ~91~15~23 ~129~15~23 minecraft:wool 7
fill ~91~25~23 ~92~25~24 minecraft:double_stone_block_slab 0
fill ~91~38~23 ~91~38~30 minecraft:wool 8
setblock ~91~54~23 minecraft:redstone_torch 3
fill ~91~59~23 ~91~59~24 minecraft:glass
fill ~91~63~23 ~91~63~24 minecraft:glass
fill ~92~18~23 ~94~18~23 minecraft:wool 8
fill ~92~26~23 ~92~26~24 minecraft:stone_block_slab 0
fill ~92~38~23 ~92~38~24 minecraft:glowstone
fill ~92~46~23 ~92~46~24 minecraft:glowstone
fill ~92~59~23 ~92~59~24 minecraft:wool 8
fill ~92~63~23 ~92~63~24 minecraft:wool 8
fill ~92~67~23 ~92~67~24 minecraft:glowstone
fill ~93~26~23 ~93~26~24 minecraft:double_stone_block_slab 0
fill ~93~33~23 ~102~33~24 minecraft:wool 8
fill ~93~38~23 ~93~38~30 minecraft:wool 8
fill ~93~46~23 ~106~46~30 minecraft:wool 8
setblock ~93~54~23 minecraft:redstone_torch 3
fill ~93~57~23 ~93~57~24 minecraft:torch 5
fill ~93~67~23 ~93~67~25 minecraft:wool 8
fill ~93~68~23 ~93~68~25 minecraft:iron_bars
fill ~94~13~23 ~96~13~23 minecraft:wool 8
fill ~94~26~23 ~94~26~24 minecraft:glowstone
fill ~94~38~23 ~94~38~24 minecraft:glowstone
fill ~94~53~23 ~94~55~25 minecraft:wool 8
setblock ~95~1~23 minecraft:glowstone
fill ~95~18~23 ~96~18~23 minecraft:glowstone
fill ~95~26~23 ~95~26~24 minecraft:double_stone_block_slab 0
fill ~95~38~23 ~95~38~30 minecraft:wool 8
fill ~96~38~23 ~96~38~24 minecraft:glowstone
setblock ~97~1~23 minecraft:glowstone
fill ~97~7~23 ~97~7~24 minecraft:glowstone
fill ~97~13~23 ~99~13~23 minecraft:glowstone
fill ~97~18~23 ~99~18~23 minecraft:wool 8
fill ~97~38~23 ~97~38~30 minecraft:wool 8
fill ~98~38~23 ~98~38~24 minecraft:glowstone
fill ~98~52~23 ~102~52~24 minecraft:wool 8
setblock ~99~1~23 minecraft:glowstone
fill ~99~26~23 ~118~26~23 minecraft:wool 8
fill ~99~38~23 ~99~38~30 minecraft:wool 8
fill ~99~39~23 ~99~40~23 minecraft:bookshelf
fill ~100~13~23 ~102~13~23 minecraft:wool 8
fill ~100~18~23 ~101~18~23 minecraft:glowstone
fill ~100~38~23 ~100~38~24 minecraft:glowstone
fill ~101~38~23 ~101~38~31 minecraft:wool 8
setblock ~102~18~23 minecraft:wool 8
fill ~102~38~23 ~102~38~24 minecraft:glowstone
fill ~103~13~23 ~105~13~23 minecraft:glowstone
setblock ~103~18~23 minecraft:wool 7
fill ~103~33~23 ~103~33~24 minecraft:stone_block_slab 0
fill ~103~38~23 ~103~38~30 minecraft:wool 8
fill ~104~17~23 ~106~17~23 minecraft:iron_block
fill ~104~18~23 ~104~19~23 minecraft:iron_block
fill ~104~38~23 ~104~38~24 minecraft:glowstone
setblock ~104~49~23 minecraft:torch 1
setblock ~105~18~23 minecraft:wool 8
fill ~105~19~23 ~106~19~23 minecraft:iron_block
fill ~105~20~23 ~114~20~34 minecraft:wool 7
fill ~105~38~23 ~106~38~25 minecraft:wool 8
fill ~106~13~23 ~108~13~23 minecraft:wool 8
setblock ~106~18~23 minecraft:iron_block
setblock ~106~33~23 minecraft:stone_pressure_plate 0
fill ~106~35~23 ~106~36~31 minecraft:wool 8
fill ~106~39~23 ~106~40~28 minecraft:wool 8
fill ~107~17~23 ~114~19~23 minecraft:wool 7
setblock ~107~33~23 minecraft:iron_door 0
fill ~109~13~23 ~111~13~23 minecraft:glowstone
fill ~112~13~23 ~114~13~23 minecraft:wool 8
fill ~115~13~23 ~117~13~23 minecraft:glowstone
fill ~115~18~23 ~127~18~23 minecraft:wool 7
setblock ~117~22~23 minecraft:torch 4
fill ~117~27~23 ~118~27~23 minecraft:iron_bars
fill ~118~13~23 ~120~13~23 minecraft:wool 8
fill ~118~21~23 ~118~24~23 minecraft:wool 8
setblock ~118~25~23 minecraft:glass
fill ~121~13~23 ~123~13~23 minecraft:glowstone
fill ~123~20~23 ~123~20~41 minecraft:wool 7
fill ~124~13~23 ~126~13~23 minecraft:wool 8
fill ~126~20~23 ~126~20~41 minecraft:wool 7
fill ~127~13~23 ~129~13~23 minecraft:glowstone
fill ~128~18~23 ~129~18~23 minecraft:wool 8
fill ~136~14~23 ~136~14~25 minecraft:stone_block_slab 0
fill ~142~14~23 ~142~14~25 minecraft:stone_block_slab 0
fill ~146~10~23 ~185~10~23 minecraft:wool 7
fill ~149~12~23 ~149~13~23 minecraft:wool 7
fill ~150~12~23 ~182~12~23 minecraft:wool 0
fill ~150~13~23 ~150~14~23 minecraft:wool 0
fill ~150~15~23 ~182~15~23 minecraft:wool 8
fill ~150~18~23 ~153~18~23 minecraft:wool 8
fill ~150~20~23 ~152~20~26 minecraft:wool 7
fill ~151~13~23 ~152~13~23 minecraft:glowstone
fill ~151~14~23 ~178~14~23 minecraft:wool 0
setblock ~153~13~23 minecraft:wool 0
fill ~154~13~23 ~155~13~23 minecraft:glowstone
fill ~154~18~23 ~156~18~23 minecraft:iron_block
setblock ~156~13~23 minecraft:wool 0
fill ~157~13~23 ~158~13~23 minecraft:glowstone
fill ~157~18~23 ~158~18~23 minecraft:wool 8
fill ~157~19~23 ~183~19~23 minecraft:wool 7
setblock ~159~13~23 minecraft:wool 0
setblock ~159~18~23 minecraft:glowstone
fill ~160~13~23 ~161~13~23 minecraft:glowstone
setblock ~160~18~23 minecraft:wool 8
setblock ~161~18~23 minecraft:glowstone
setblock ~161~22~23 minecraft:iron_block
fill ~161~23~23 ~161~23~25 minecraft:wool 7
setblock ~161~24~23 minecraft:glass
setblock ~162~13~23 minecraft:wool 0
setblock ~162~18~23 minecraft:wool 8
fill ~163~13~23 ~164~13~23 minecraft:glowstone
setblock ~163~18~23 minecraft:glowstone
setblock ~164~18~23 minecraft:wool 8
setblock ~165~13~23 minecraft:wool 0
setblock ~165~18~23 minecraft:glowstone
fill ~166~13~23 ~167~13~23 minecraft:glowstone
setblock ~166~18~23 minecraft:wool 8
setblock ~167~18~23 minecraft:glowstone
setblock ~168~13~23 minecraft:wool 0
setblock ~168~18~23 minecraft:wool 8
fill ~169~13~23 ~170~13~23 minecraft:glowstone
setblock ~169~18~23 minecraft:glowstone
setblock ~170~18~23 minecraft:wool 8
setblock ~171~13~23 minecraft:wool 0
setblock ~171~18~23 minecraft:glowstone
fill ~172~13~23 ~173~13~23 minecraft:glowstone
setblock ~172~18~23 minecraft:wool 8
fill ~172~23~23 ~173~23~23 minecraft:wool 7
setblock ~172~24~23 minecraft:stone_block_slab 0
setblock ~173~18~23 minecraft:glowstone
setblock ~174~13~23 minecraft:wool 0
setblock ~174~18~23 minecraft:wool 8
fill ~174~25~23 ~174~25~24 minecraft:glass
fill ~175~13~23 ~176~13~23 minecraft:glowstone
setblock ~175~18~23 minecraft:glowstone
fill ~175~23~23 ~176~23~23 minecraft:wool 7
setblock ~176~18~23 minecraft:wool 8
setblock ~176~24~23 minecraft:stone_block_slab 0
setblock ~177~13~23 minecraft:wool 0
setblock ~177~18~23 minecraft:glowstone
fill ~178~13~23 ~179~13~23 minecraft:glowstone
setblock ~178~18~23 minecraft:wool 8
setblock ~179~18~23 minecraft:glowstone
setblock ~180~13~23 minecraft:wool 0
setblock ~180~18~23 minecraft:wool 8
fill ~181~13~23 ~182~13~23 minecraft:glowstone
setblock ~181~18~23 minecraft:glowstone
setblock ~182~14~23 minecraft:wool 0
setblock ~182~18~23 minecraft:wool 8
fill ~183~12~23 ~183~15~23 minecraft:wool 7
setblock ~183~18~23 minecraft:wool 7
setblock ~186~10~23 minecraft:glowstone
fill ~187~10~23 ~197~10~34 minecraft:wool 7
setblock ~198~10~23 minecraft:glowstone
fill ~199~10~23 ~216~10~23 minecraft:wool 7
fill ~202~11~23 ~205~11~23 minecraft:wool 7
fill ~202~12~23 ~202~13~23 minecraft:wool 7
fill ~203~12~23 ~203~14~23 minecraft:wool 8
fill ~203~15~23 ~227~15~23 minecraft:wool 7
fill ~203~18~23 ~204~18~23 minecraft:wool 8
fill ~203~19~23 ~227~19~23 minecraft:wool 7
fill ~204~12~23 ~204~14~23 minecraft:wool 0
setblock ~205~12~23 minecraft:stone_pressure_plate 0
fill ~205~14~23 ~206~14~23 minecraft:wool 0
fill ~205~18~23 ~206~18~23 minecraft:glowstone
fill ~206~11~23 ~206~11~24 minecraft:wool 0
fill ~206~12~23 ~206~13~23 minecraft:wool 0
fill ~207~11~23 ~225~11~23 minecraft:wool 7
fill ~207~12~23 ~227~12~23 minecraft:wool 8
fill ~207~13~23 ~208~13~23 minecraft:glowstone
fill ~207~14~23 ~208~14~23 minecraft:wool 8
fill ~207~18~23 ~208~18~23 minecraft:wool 8
setblock ~207~26~23 minecraft:stone_block_slab 0
fill ~209~13~23 ~210~13~23 minecraft:wool 8
fill ~209~18~23 ~210~18~23 minecraft:glowstone
fill ~210~14~23 ~227~14~23 minecraft:wool 8
fill ~211~13~23 ~212~13~23 minecraft:glowstone
fill ~211~18~23 ~212~18~23 minecraft:wool 8
fill ~213~13~23 ~214~13~23 minecraft:wool 8
fill ~213~18~23 ~214~18~23 minecraft:glowstone
fill ~215~13~23 ~216~13~23 minecraft:glowstone
fill ~215~18~23 ~216~18~23 minecraft:wool 8
fill ~215~23~23 ~217~23~23 minecraft:wool 7
fill ~216~24~23 ~217~24~23 minecraft:stone_block_slab 0
fill ~217~13~23 ~218~13~23 minecraft:wool 8
fill ~217~18~23 ~218~18~23 minecraft:glowstone
setblock ~217~22~23 minecraft:wool 7
fill ~219~13~23 ~220~13~23 minecraft:glowstone
fill ~219~18~23 ~220~18~23 minecraft:wool 8
fill ~221~13~23 ~222~13~23 minecraft:wool 8
fill ~221~18~23 ~222~18~23 minecraft:glowstone
fill ~221~22~23 ~221~23~23 minecraft:wool 7
fill ~221~24~23 ~222~24~23 minecraft:stone_block_slab 0
fill ~222~23~23 ~223~23~23 minecraft:wool 7
fill ~223~13~23 ~224~13~23 minecraft:glowstone
fill ~223~18~23 ~224~18~23 minecraft:wool 8
fill ~225~13~23 ~227~13~23 minecraft:wool 8
fill ~225~18~23 ~226~18~23 minecraft:glowstone
setblock ~227~18~23 minecraft:wool 8
fill ~228~12~23 ~228~13~23 minecraft:wool 7
fill ~229~1~23 ~229~1~31 minecraft:wool 15
setblock ~234~27~23 minecraft:wool 7
setblock ~242~27~23 minecraft:wool 7
fill ~251~20~23 ~251~20~31 minecraft:wool 7
fill ~252~20~23 ~252~20~28 minecraft:wool 8
fill ~252~21~23 ~252~21~29 minecraft:iron_bars
fill ~1~24~24 ~7~24~25 minecraft:stone_block_slab 0
fill ~2~16~24 ~2~16~28 minecraft:wool 7
fill ~2~19~24 ~3~19~38 minecraft:wool 7
fill ~2~23~24 ~7~23~25 minecraft:wool 8
fill ~3~17~24 ~3~18~35 minecraft:wool 7
setblock ~4~18~24 minecraft:torch 1
fill ~5~16~24 ~8~16~34 minecraft:wool 7
fill ~6~14~24 ~6~14~28 minecraft:wool 7
fill ~6~20~24 ~33~20~34 minecraft:wool 7
fill ~7~13~24 ~7~13~28 minecraft:wool 7
fill ~9~11~24 ~11~11~24 minecraft:wool 7
fill ~9~12~24 ~9~12~28 minecraft:wool 7
fill ~9~24~24 ~9~24~27 minecraft:double_stone_block_slab 0
fill ~10~10~24 ~59~10~28 minecraft:wool 7
fill ~11~8~24 ~67~8~25 minecraft:wool 7
fill ~11~9~24 ~67~9~24 minecraft:wool 7
setblock ~11~12~24 minecraft:wool 7
fill ~11~23~24 ~16~23~25 minecraft:wool 8
fill ~11~24~24 ~17~24~25 minecraft:stone_block_slab 0
fill ~19~24~24 ~25~24~25 minecraft:stone_block_slab 0
fill ~20~23~24 ~25~23~25 minecraft:wool 8
fill ~27~24~24 ~27~24~26 minecraft:double_stone_block_slab 0
fill ~29~23~24 ~34~23~25 minecraft:wool 8
fill ~29~24~24 ~35~24~25 minecraft:stone_block_slab 0
fill ~37~24~24 ~43~24~25 minecraft:stone_block_slab 0
fill ~38~23~24 ~43~23~25 minecraft:wool 8
fill ~44~16~24 ~74~16~25 minecraft:wool 7
fill ~45~20~24 ~93~20~34 minecraft:wool 7
fill ~45~24~24 ~45~24~26 minecraft:double_stone_block_slab 0
fill ~47~17~24 ~47~19~27 minecraft:wool 7
fill ~47~23~24 ~52~23~25 minecraft:wool 8
fill ~47~24~24 ~53~24~25 minecraft:stone_block_slab 0
fill ~56~21~24 ~58~22~24 minecraft:iron_bars
fill ~57~23~24 ~58~26~24 minecraft:iron_bars
fill ~57~27~24 ~57~32~24 minecraft:iron_bars
fill ~58~32~24 ~58~32~25 minecraft:iron_bars
fill ~60~10~24 ~90~10~24 minecraft:wool 0
fill ~60~21~24 ~60~23~24 minecraft:iron_block
fill ~60~24~24 ~71~24~24 minecraft:wool 8
fill ~60~25~24 ~61~25~24 minecraft:glass
fill ~60~26~24 ~71~26~24 minecraft:wool 8
setblock ~61~21~24 minecraft:iron_door 3
fill ~61~23~24 ~62~23~24 minecraft:iron_block
fill ~62~21~24 ~62~22~24 minecraft:iron_block
setblock ~62~25~24 minecraft:wool 8
fill ~63~21~24 ~71~23~24 minecraft:wool 8
fill ~63~25~24 ~64~25~24 minecraft:glass
setblock ~63~33~24 minecraft:wool 0
setblock ~64~33~24 minecraft:lit_redstone_lamp
setblock ~65~25~24 minecraft:wool 8
setblock ~65~33~24 minecraft:wool 0
fill ~66~25~24 ~67~25~24 minecraft:glass
fill ~67~17~24 ~67~19~36 minecraft:wool 8
fill ~68~5~24 ~71~7~24 minecraft:wool 15
setblock ~68~25~24 minecraft:wool 8
fill ~69~25~24 ~70~25~24 minecraft:glass
fill ~71~4~24 ~74~4~24 minecraft:wool 15
setblock ~71~25~24 minecraft:wool 8
fill ~71~34~24 ~71~36~26 minecraft:stone_block_slab 0
setblock ~71~39~24 minecraft:red_flower 0
fill ~72~8~24 ~100~8~25 minecraft:wool 7
fill ~72~9~24 ~100~9~24 minecraft:wool 7
fill ~73~40~24 ~73~40~25 minecraft:leaves 3
fill ~74~2~24 ~76~2~25 minecraft:wool 15
setblock ~74~3~24 minecraft:wool 15
fill ~74~17~24 ~74~19~36 minecraft:iron_block
fill ~74~34~24 ~74~36~26 minecraft:stone_block_slab 0
setblock ~74~39~24 minecraft:yellow_flower
fill ~75~16~24 ~102~16~24 minecraft:iron_block
fill ~75~38~24 ~76~38~27 minecraft:grass
setblock ~78~39~24 minecraft:trapdoor 3
setblock ~79~48~24 minecraft:torch 4
fill ~80~1~24 ~83~1~24 minecraft:wool 15
setblock ~80~47~24 minecraft:iron_door 2
setblock ~81~39~24 minecraft:trapdoor 3
setblock ~81~47~24 minecraft:stone_pressure_plate 0
fill ~83~0~24 ~85~0~38 minecraft:wool 15
setblock ~83~54~24 minecraft:redstone_torch 4
setblock ~84~39~24 minecraft:trapdoor 3
setblock ~85~7~24 minecraft:glowstone
fill ~85~27~24 ~85~27~25 minecraft:glowstone
fill ~85~28~24 ~85~29~27 minecraft:iron_block
setblock ~85~54~24 minecraft:redstone_torch 4
fill ~86~24~24 ~86~24~26 minecraft:stone_block_slab 0
fill ~86~39~24 ~86~39~29 minecraft:iron_bars
fill ~87~23~24 ~87~23~25 minecraft:glowstone
setblock ~87~54~24 minecraft:redstone_torch 4
fill ~88~24~24 ~88~24~26 minecraft:stone_block_slab 0
fill ~89~23~24 ~95~23~24 minecraft:double_stone_block_slab 0
setblock ~89~54~24 minecraft:redstone_torch 4
fill ~91~10~24 ~100~10~29 minecraft:wool 7
fill ~91~22~24 ~95~22~24 minecraft:double_stone_block_slab 0
fill ~91~24~24 ~95~24~24 minecraft:double_stone_block_slab 0
setblock ~91~54~24 minecraft:redstone_torch 4
setblock ~91~68~24 minecraft:iron_bars
setblock ~92~1~24 minecraft:glowstone
fill ~92~21~24 ~95~21~24 minecraft:double_stone_block_slab 0
fill ~93~25~24 ~95~25~24 minecraft:double_stone_block_slab 0
setblock ~93~54~24 minecraft:redstone_torch 4
fill ~98~51~24 ~102~51~24 minecraft:wool 8
fill ~99~26~24 ~117~26~24 minecraft:wool 8
fill ~99~39~24 ~100~41~24 minecraft:planks 1
setblock ~101~39~24 minecraft:wooden_door 3
fill ~101~41~24 ~105~41~24 minecraft:planks 1
fill ~102~39~24 ~102~40~24 minecraft:planks 1
fill ~103~16~24 ~129~16~24 minecraft:wool 7
fill ~103~17~24 ~103~17~29 minecraft:iron_block
fill ~103~18~24 ~103~19~24 minecraft:iron_block
setblock ~103~39~24 minecraft:wooden_door 3
fill ~104~39~24 ~105~40~24 minecraft:planks 1
setblock ~106~27~24 minecraft:stone_pressure_plate 0
setblock ~106~33~24 minecraft:iron_door 2
fill ~107~17~24 ~126~17~24 minecraft:iron_block
fill ~107~18~24 ~113~19~24 minecraft:iron_block
setblock ~107~27~24 minecraft:iron_door 0
setblock ~107~33~24 minecraft:stone_pressure_plate 0
setblock ~107~37~24 minecraft:torch 1
setblock ~107~41~24 minecraft:torch 1
fill ~114~18~24 ~124~18~24 minecraft:wool 8
fill ~114~19~24 ~126~19~24 minecraft:iron_block
fill ~115~20~24 ~115~20~42 minecraft:wool 7
fill ~116~27~24 ~117~27~24 minecraft:iron_bars
fill ~117~21~24 ~117~25~24 minecraft:wool 8
fill ~125~18~24 ~126~18~24 minecraft:iron_block
fill ~127~20~24 ~129~20~41 minecraft:wool 7
fill ~130~16~24 ~130~16~32 minecraft:wool 8
fill ~130~17~24 ~130~17~32 minecraft:iron_bars
fill ~135~10~24 ~138~10~37 minecraft:wool 7
fill ~136~13~24 ~138~13~25 minecraft:wool 7
fill ~139~10~24 ~139~10~25 minecraft:glowstone
fill ~140~10~24 ~144~10~37 minecraft:wool 7
fill ~140~13~24 ~142~13~25 minecraft:wool 7
fill ~146~10~24 ~182~10~25 minecraft:wool 7
fill ~149~16~24 ~149~16~32 minecraft:wool 8
fill ~149~17~24 ~149~17~32 minecraft:iron_bars
fill ~150~16~24 ~182~16~24 minecraft:wool 7
fill ~153~17~24 ~153~18~25 minecraft:iron_bars
setblock ~153~19~24 minecraft:iron_bars
fill ~154~17~24 ~156~17~25 minecraft:iron_block
fill ~154~18~24 ~156~18~24 minecraft:stone_block_slab 0
fill ~157~17~24 ~157~18~25 minecraft:iron_bars
setblock ~157~19~24 minecraft:iron_bars
setblock ~161~22~24 minecraft:dispenser 3
setblock ~161~24~24 minecraft:stone_block_slab 0
setblock ~163~12~24 minecraft:wall_sign 3
setblock ~173~23~24 minecraft:wool 7
setblock ~175~23~24 minecraft:wool 7
fill ~183~10~24 ~183~10~33 minecraft:wool 8
fill ~183~16~24 ~183~16~33 minecraft:wool 8
fill ~183~17~24 ~183~17~33 minecraft:iron_bars
fill ~184~10~24 ~186~10~30 minecraft:wool 7
fill ~198~10~24 ~201~10~30 minecraft:wool 7
fill ~202~10~24 ~202~10~33 minecraft:wool 8
fill ~202~16~24 ~202~16~26 minecraft:wool 8
fill ~202~17~24 ~202~17~33 minecraft:iron_bars
fill ~203~10~24 ~216~10~29 minecraft:wool 7
setblock ~204~11~24 minecraft:wool 0
fill ~204~23~24 ~206~23~25 minecraft:wool 7
setblock ~205~11~24 minecraft:stone_brick_stairs 3
fill ~208~23~24 ~210~23~25 minecraft:wool 7
fill ~216~23~24 ~217~23~24 minecraft:wool 7
setblock ~217~22~24 minecraft:iron_block
fill ~217~24~24 ~218~24~26 minecraft:stone_block_slab 0
fill ~220~24~24 ~221~24~26 minecraft:stone_block_slab 0
setblock ~221~22~24 minecraft:iron_block
fill ~221~23~24 ~222~23~24 minecraft:wool 7
fill ~228~11~24 ~228~11~45 minecraft:wool 7
fill ~228~12~24 ~228~12~45 minecraft:wool 8
fill ~228~13~24 ~228~14~24 minecraft:wool 8
fill ~229~0~24 ~229~0~31 minecraft:wool 15
fill ~229~19~24 ~251~19~38 minecraft:wool 7
fill ~232~23~24 ~237~23~25 minecraft:wool 7
fill ~233~24~24 ~235~24~25 minecraft:stone_block_slab 0
fill ~236~24~24 ~236~24~30 minecraft:double_stone_block_slab 0
fill ~239~23~24 ~244~23~25 minecraft:wool 7
fill ~240~24~24 ~240~24~30 minecraft:double_stone_block_slab 0
fill ~241~24~24 ~243~24~25 minecraft:stone_block_slab 0
fill ~4~15~25 ~10~15~27 minecraft:wool 7
fill ~5~14~25 ~5~14~27 minecraft:wool 7
fill ~6~13~25 ~6~13~27 minecraft:wool 7
fill ~8~12~25 ~8~12~27 minecraft:wool 7
fill ~9~10~25 ~9~11~27 minecraft:wool 7
fill ~10~8~25 ~10~9~27 minecraft:wool 7
fill ~10~11~25 ~10~11~28 minecraft:wool 7
fill ~11~7~25 ~100~7~25 minecraft:wool 15
fill ~11~9~25 ~11~9~28 minecraft:wool 7
fill ~12~6~25 ~100~6~26 minecraft:wool 15
fill ~22~22~25 ~22~22~26 minecraft:iron_block
fill ~32~22~25 ~32~22~26 minecraft:iron_block
fill ~40~22~25 ~40~22~26 minecraft:iron_block
fill ~50~22~25 ~50~22~26 minecraft:iron_block
setblock ~59~30~25 minecraft:wool 8
fill ~59~32~25 ~69~32~25 minecraft:iron_bars
fill ~60~10~25 ~60~10~36 minecraft:wool 0
fill ~60~30~25 ~61~30~25 minecraft:glass
fill ~60~31~25 ~68~31~25 minecraft:wool 8
fill ~61~10~25 ~89~10~29 minecraft:wool 7
setblock ~61~21~25 minecraft:stone_pressure_plate 0
setblock ~62~30~25 minecraft:wool 8
fill ~63~30~25 ~64~30~25 minecraft:glass
setblock ~64~22~25 minecraft:torch 3
fill ~65~5~25 ~68~5~26 minecraft:wool 15
setblock ~65~30~25 minecraft:wool 8
fill ~66~30~25 ~67~30~25 minecraft:glass
fill ~68~4~25 ~71~4~32 minecraft:wool 15
setblock ~68~30~25 minecraft:wool 8
fill ~69~30~25 ~70~30~25 minecraft:glass
setblock ~70~35~25 minecraft:wool 8
setblock ~70~40~25 minecraft:wool 8
setblock ~70~43~25 minecraft:wool 8
fill ~71~2~25 ~73~2~33 minecraft:wool 15
fill ~71~3~25 ~73~3~32 minecraft:wool 15
setblock ~71~30~25 minecraft:wool 8
setblock ~71~48~25 minecraft:wool 8
fill ~72~40~25 ~72~40~27 minecraft:leaves 3
fill ~72~42~25 ~103~42~30 minecraft:wool 8
setblock ~72~47~25 minecraft:double_stone_block_slab 0
setblock ~72~48~25 minecraft:lever 1
setblock ~73~33~25 minecraft:glowstone
setblock ~73~41~25 minecraft:leaves 3
setblock ~73~47~25 minecraft:stone_button 5
fill ~74~33~25 ~75~33~30 minecraft:wool 8
fill ~74~40~25 ~74~40~27 minecraft:leaves 3
setblock ~75~16~25 minecraft:iron_block
fill ~76~16~25 ~123~16~25 minecraft:wool 7
setblock ~76~33~25 minecraft:glowstone
fill ~77~1~25 ~80~1~25 minecraft:wool 15
setblock ~77~2~25 minecraft:wool 15
fill ~77~33~25 ~78~33~30 minecraft:wool 8
setblock ~77~39~25 minecraft:trapdoor 1
fill ~77~47~25 ~81~48~25 minecraft:wool 8
fill ~78~38~25 ~78~38~27 minecraft:wool 8
setblock ~78~39~25 minecraft:grass
setblock ~78~40~25 minecraft:yellow_flower
fill ~79~33~25 ~80~33~25 minecraft:glowstone
setblock ~79~39~25 minecraft:trapdoor 0
fill ~80~0~25 ~82~0~37 minecraft:wool 15
fill ~80~38~25 ~80~38~30 minecraft:wool 8
setblock ~80~39~25 minecraft:trapdoor 1
fill ~81~33~25 ~81~33~30 minecraft:wool 8
setblock ~81~39~25 minecraft:grass
setblock ~81~40~25 minecraft:red_flower 0
setblock ~81~67~25 minecraft:wool 8
fill ~81~68~25 ~90~68~25 minecraft:iron_bars
fill ~82~33~25 ~83~33~25 minecraft:glowstone
fill ~82~38~25 ~82~38~30 minecraft:wool 8
setblock ~82~39~25 minecraft:trapdoor 0
fill ~82~47~25 ~82~52~25 minecraft:stone_block_slab 0
fill ~82~53~25 ~93~55~25 minecraft:wool 8
setblock ~83~39~25 minecraft:trapdoor 1
fill ~83~47~25 ~83~51~25 minecraft:iron_block
setblock ~83~52~25 minecraft:glowstone
fill ~84~33~25 ~84~33~30 minecraft:wool 8
fill ~84~38~25 ~84~38~30 minecraft:wool 8
setblock ~84~39~25 minecraft:grass
setblock ~84~40~25 minecraft:yellow_flower
fill ~84~47~25 ~84~52~25 minecraft:stone_block_slab 0
setblock ~85~3~25 minecraft:glowstone
fill ~85~33~25 ~86~33~25 minecraft:glowstone
setblock ~85~39~25 minecraft:trapdoor 0
fill ~85~46~25 ~85~46~30 minecraft:wool 8
fill ~85~47~25 ~85~51~25 minecraft:iron_block
setblock ~85~52~25 minecraft:glowstone
fill ~86~38~25 ~86~38~30 minecraft:wool 8
fill ~86~47~25 ~86~52~25 minecraft:stone_block_slab 0
fill ~87~33~25 ~87~33~30 minecraft:wool 8
fill ~87~47~25 ~87~51~25 minecraft:iron_block
setblock ~87~52~25 minecraft:glowstone
setblock ~88~23~25 minecraft:stone_block_slab 0
fill ~88~33~25 ~89~33~25 minecraft:glowstone
fill ~88~38~25 ~88~38~30 minecraft:wool 8
fill ~88~47~25 ~88~52~25 minecraft:stone_block_slab 0
fill ~89~23~25 ~89~23~26 minecraft:double_stone_block_slab 0
setblock ~89~39~25 minecraft:oak_stairs 3
fill ~89~47~25 ~89~51~25 minecraft:iron_block
setblock ~89~52~25 minecraft:glowstone
setblock ~90~1~25 minecraft:glowstone
fill ~90~10~25 ~90~10~36 minecraft:wool 0
fill ~90~21~25 ~90~23~25 minecraft:stone_block_slab 0
fill ~90~33~25 ~90~33~30 minecraft:wool 8
fill ~90~38~25 ~90~38~30 minecraft:wool 8
fill ~90~47~25 ~90~52~25 minecraft:stone_block_slab 0
fill ~91~21~25 ~93~21~26 minecraft:double_stone_block_slab 0
fill ~91~22~25 ~91~22~26 minecraft:double_stone_block_slab 0
fill ~91~33~25 ~92~33~25 minecraft:glowstone
setblock ~91~39~25 minecraft:oak_stairs 3
fill ~91~47~25 ~91~51~25 minecraft:iron_block
setblock ~91~52~25 minecraft:glowstone
fill ~92~22~25 ~92~22~26 minecraft:stone_block_slab 0
fill ~92~38~25 ~92~38~30 minecraft:wool 8
fill ~92~46~25 ~92~46~30 minecraft:wool 8
fill ~92~47~25 ~92~52~25 minecraft:stone_block_slab 0
fill ~92~67~25 ~92~67~26 minecraft:wool 8
fill ~92~68~25 ~92~68~26 minecraft:iron_bars
fill ~93~33~25 ~93~33~30 minecraft:wool 8
setblock ~93~39~25 minecraft:oak_stairs 3
fill ~93~47~25 ~93~51~25 minecraft:iron_block
setblock ~93~52~25 minecraft:glowstone
fill ~94~20~25 ~94~20~44 minecraft:wool 7
fill ~94~21~25 ~94~21~26 minecraft:stone_block_slab 0
fill ~94~33~25 ~95~33~25 minecraft:glowstone
fill ~94~38~25 ~94~38~30 minecraft:wool 8
setblock ~95~1~25 minecraft:glowstone
fill ~95~20~25 ~95~20~26 minecraft:glowstone
fill ~95~30~25 ~95~31~25 minecraft:glowstone
fill ~96~20~25 ~96~20~43 minecraft:wool 7
fill ~96~23~25 ~96~28~26 minecraft:iron_block
fill ~96~33~25 ~96~33~30 minecraft:wool 8
fill ~96~38~25 ~96~38~30 minecraft:wool 8
fill ~97~20~25 ~97~20~26 minecraft:glowstone
fill ~97~23~25 ~106~24~27 minecraft:wool 8
fill ~97~25~25 ~98~26~27 minecraft:wool 8
fill ~97~27~25 ~97~27~27 minecraft:redstone_torch 5
fill ~97~28~25 ~97~28~27 minecraft:stone_block_slab 0
fill ~97~33~25 ~98~33~25 minecraft:glowstone
setblock ~98~3~25 minecraft:glowstone
fill ~98~20~25 ~98~20~43 minecraft:wool 7
fill ~98~38~25 ~98~38~30 minecraft:wool 8
fill ~98~47~25 ~102~50~25 minecraft:wool 8
fill ~99~20~25 ~100~20~26 minecraft:glowstone
fill ~99~26~25 ~116~26~25 minecraft:wool 8
fill ~99~33~25 ~106~33~30 minecraft:wool 8
setblock ~100~1~25 minecraft:glowstone
setblock ~100~4~25 minecraft:glowstone
fill ~100~38~25 ~100~38~30 minecraft:wool 8
fill ~101~20~25 ~101~20~43 minecraft:wool 7
fill ~101~21~25 ~106~22~27 minecraft:wool 8
fill ~102~38~25 ~102~38~32 minecraft:wool 8
setblock ~103~18~25 minecraft:wool 8
fill ~103~19~25 ~103~19~39 minecraft:iron_block
fill ~103~34~25 ~105~34~25 minecraft:iron_bars
setblock ~104~38~25 minecraft:wool 8
fill ~104~39~25 ~105~41~25 minecraft:stone_block_slab 0
fill ~104~42~25 ~105~42~25 minecraft:planks 1
setblock ~106~27~25 minecraft:iron_door 2
fill ~106~34~25 ~106~34~31 minecraft:wool 8
fill ~106~42~25 ~106~42~31 minecraft:wool 8
fill ~107~17~25 ~107~17~29 minecraft:iron_block
fill ~107~18~25 ~107~18~28 minecraft:wool 8
fill ~107~19~25 ~107~19~36 minecraft:iron_block
setblock ~107~27~25 minecraft:stone_pressure_plate 0
fill ~108~17~25 ~113~19~25 minecraft:furnace 3
fill ~111~9~25 ~111~9~45 minecraft:iron_block
fill ~112~9~25 ~113~9~26 minecraft:wool 7
fill ~114~17~25 ~117~17~25 minecraft:crafting_table
fill ~114~19~25 ~117~19~25 minecraft:crafting_table
fill ~115~27~25 ~116~27~25 minecraft:iron_bars
fill ~116~21~25 ~116~24~25 minecraft:wool 8
setblock ~116~25~25 minecraft:glass
fill ~118~17~25 ~121~17~25 minecraft:cauldron 6
fill ~118~19~25 ~121~19~25 minecraft:glowstone
fill ~120~9~25 ~120~9~26 minecraft:wool 7
fill ~122~17~25 ~123~17~25 minecraft:iron_block
fill ~124~16~25 ~125~16~25 minecraft:glowstone
fill ~126~16~25 ~129~16~26 minecraft:wool 7
fill ~126~17~25 ~126~17~36 minecraft:iron_block
fill ~126~18~25 ~126~19~25 minecraft:iron_block
fill ~128~9~25 ~128~9~31 minecraft:iron_block
fill ~134~9~25 ~134~9~26 minecraft:iron_block
fill ~148~9~25 ~148~9~31 minecraft:iron_block
fill ~150~16~25 ~156~16~25 minecraft:wool 7
fill ~156~11~25 ~161~12~25 minecraft:iron_bars
fill ~156~13~25 ~160~13~25 minecraft:iron_bars
fill ~156~14~25 ~159~14~25 minecraft:iron_bars
fill ~156~15~25 ~158~15~25 minecraft:iron_bars
fill ~157~16~25 ~170~16~25 minecraft:wool 8
fill ~164~11~25 ~170~11~25 minecraft:iron_bars
fill ~165~12~25 ~170~12~25 minecraft:iron_bars
fill ~166~13~25 ~170~13~25 minecraft:iron_bars
fill ~166~26~25 ~166~26~26 minecraft:wool 7
fill ~167~14~25 ~170~14~25 minecraft:iron_bars
fill ~168~15~25 ~170~15~25 minecraft:iron_bars
fill ~168~26~25 ~168~26~26 minecraft:wool 7
fill ~171~16~25 ~182~16~26 minecraft:wool 7
setblock ~174~22~25 minecraft:iron_block
fill ~174~23~25 ~174~23~27 minecraft:wool 7
setblock ~174~24~25 minecraft:glass
fill ~187~11~25 ~192~13~25 minecraft:vine 1
fill ~188~14~25 ~192~14~25 minecraft:vine 1
fill ~189~15~25 ~192~15~25 minecraft:vine 1
setblock ~205~22~25 minecraft:iron_block
fill ~205~24~25 ~206~24~26 minecraft:stone_block_slab 0
setblock ~207~25~25 minecraft:stone_block_slab 0
fill ~208~24~25 ~209~24~26 minecraft:stone_block_slab 0
setblock ~209~22~25 minecraft:iron_block
fill ~217~10~25 ~228~10~29 minecraft:wool 7
setblock ~217~22~25 minecraft:dispenser 3
fill ~217~23~25 ~217~23~27 minecraft:wool 7
setblock ~221~22~25 minecraft:dispenser 3
fill ~221~23~25 ~221~23~27 minecraft:wool 7
fill ~228~7~25 ~228~7~31 minecraft:wool 7
fill ~228~9~25 ~228~9~58 minecraft:wool 7
fill ~228~13~25 ~228~13~27 minecraft:glowstone
fill ~228~14~25 ~228~14~45 minecraft:wool 8
setblock ~229~18~25 minecraft:wool 8
fill ~235~22~25 ~235~22~26 minecraft:wool 7
fill ~241~22~25 ~241~22~26 minecraft:wool 7
fill ~2~24~26 ~7~24~26 minecraft:stone_block_slab 0
setblock ~3~15~26 minecraft:wool 7
fill ~3~23~26 ~7~23~26 minecraft:wool 8
setblock ~4~14~26 minecraft:wool 7
setblock ~5~13~26 minecraft:wool 7
fill ~6~12~26 ~7~12~26 minecraft:wool 7
fill ~7~11~26 ~8~11~26 minecraft:wool 7
setblock ~7~22~26 minecraft:wool 8
fill ~8~9~26 ~9~9~26 minecraft:wool 7
setblock ~8~10~26 minecraft:wool 7
fill ~9~6~26 ~11~7~26 minecraft:wool 15
setblock ~9~8~26 minecraft:wool 7
fill ~10~5~26 ~64~5~26 minecraft:wool 15
fill ~11~3~26 ~70~3~26 minecraft:wool 15
fill ~11~4~26 ~67~4~26 minecraft:wool 15
fill ~11~8~26 ~11~8~28 minecraft:wool 7
fill ~11~22~26 ~11~23~26 minecraft:wool 8
fill ~11~24~26 ~16~24~26 minecraft:stone_block_slab 0
fill ~12~7~26 ~12~7~27 minecraft:wool 15
fill ~12~23~26 ~15~23~26 minecraft:wool 8
fill ~14~7~26 ~15~7~27 minecraft:wool 15
fill ~14~8~26 ~14~9~28 minecraft:wool 7
fill ~17~7~26 ~18~7~27 minecraft:wool 15
fill ~17~8~26 ~17~9~28 minecraft:wool 7
fill ~20~7~26 ~21~7~27 minecraft:wool 15
fill ~20~8~26 ~20~9~28 minecraft:wool 7
fill ~20~24~26 ~25~24~26 minecraft:stone_block_slab 0
fill ~21~23~26 ~25~23~26 minecraft:wool 8
fill ~23~7~26 ~24~7~27 minecraft:wool 15
fill ~23~8~26 ~23~9~28 minecraft:wool 7
setblock ~25~22~26 minecraft:wool 8
fill ~26~7~26 ~27~7~27 minecraft:wool 15
fill ~26~8~26 ~26~9~28 minecraft:wool 7
fill ~26~24~26 ~26~24~28 minecraft:double_stone_block_slab 0
fill ~28~24~26 ~28~24~28 minecraft:double_stone_block_slab 0
fill ~29~7~26 ~30~7~27 minecraft:wool 15
fill ~29~8~26 ~29~9~28 minecraft:wool 7
fill ~29~22~26 ~29~23~26 minecraft:wool 8
fill ~29~24~26 ~34~24~26 minecraft:stone_block_slab 0
fill ~30~23~26 ~33~23~26 minecraft:wool 8
fill ~32~7~26 ~33~7~27 minecraft:wool 15
fill ~32~8~26 ~32~9~28 minecraft:wool 7
fill ~35~7~26 ~36~7~27 minecraft:wool 15
fill ~35~8~26 ~35~9~28 minecraft:wool 7
fill ~38~7~26 ~39~7~27 minecraft:wool 15
fill ~38~8~26 ~38~9~28 minecraft:wool 7
fill ~38~24~26 ~43~24~26 minecraft:stone_block_slab 0
fill ~39~23~26 ~43~23~26 minecraft:wool 8
fill ~41~7~26 ~42~7~28 minecraft:wool 15
fill ~41~8~26 ~41~9~29 minecraft:wool 7
setblock ~43~22~26 minecraft:wool 8
fill ~44~7~26 ~45~7~28 minecraft:wool 15
fill ~44~8~26 ~44~9~30 minecraft:wool 7
fill ~44~16~26 ~69~16~38 minecraft:wool 7
fill ~44~24~26 ~44~24~28 minecraft:double_stone_block_slab 0
setblock ~45~25~26 minecraft:stone_block_slab 0
fill ~46~24~26 ~46~24~28 minecraft:double_stone_block_slab 0
fill ~47~7~26 ~48~7~29 minecraft:wool 15
fill ~47~8~26 ~47~9~30 minecraft:wool 7
fill ~47~22~26 ~47~23~26 minecraft:wool 8
fill ~47~24~26 ~52~24~26 minecraft:stone_block_slab 0
fill ~48~23~26 ~51~23~26 minecraft:wool 8
fill ~50~7~26 ~51~7~30 minecraft:wool 15
fill ~50~8~26 ~50~9~31 minecraft:wool 7
fill ~53~7~26 ~54~7~31 minecraft:wool 15
