setblock ~10 ~6 ~9 trapped_chest
fill ~1 ~0 ~13 ~35 ~0 ~13 mossy_cobblestone 0  
fill ~1 ~0 ~14 ~35 ~0 ~14 mossy_cobblestone 0  
fill ~1 ~0 ~15 ~35 ~0 ~15 mossy_cobblestone 0  
fill ~1 ~0 ~16 ~28 ~0 ~16 mossy_cobblestone 0  
fill ~1 ~0 ~17 ~30 ~0 ~17 mossy_cobblestone 0  
fill ~1 ~0 ~18 ~30 ~0 ~18 mossy_cobblestone 0  
fill ~1 ~0 ~19 ~35 ~0 ~19 mossy_cobblestone 0  
fill ~1 ~0 ~20 ~28 ~0 ~20 mossy_cobblestone 0  
fill ~1 ~0 ~21 ~28 ~0 ~21 mossy_cobblestone 0  
fill ~2 ~0 ~10 ~34 ~0 ~10 mossy_cobblestone 0  
fill ~2 ~0 ~11 ~34 ~0 ~11 mossy_cobblestone 0  
fill ~2 ~0 ~12 ~34 ~0 ~12 mossy_cobblestone 0  
fill ~2 ~0 ~22 ~28 ~0 ~22 mossy_cobblestone 0  
fill ~2 ~0 ~23 ~34 ~0 ~23 mossy_cobblestone 0  
fill ~2 ~0 ~24 ~34 ~0 ~24 mossy_cobblestone 0  
fill ~3 ~0 ~8 ~33 ~0 ~8 mossy_cobblestone 0  
fill ~3 ~0 ~9 ~33 ~0 ~9 mossy_cobblestone 0  
fill ~3 ~0 ~25 ~33 ~0 ~25 mossy_cobblestone 0  
fill ~3 ~0 ~26 ~33 ~0 ~26 mossy_cobblestone 0  
fill ~4 ~0 ~7 ~32 ~0 ~7 mossy_cobblestone 0  
fill ~4 ~0 ~27 ~32 ~0 ~27 mossy_cobblestone 0  
fill ~5 ~0 ~6 ~31 ~0 ~6 mossy_cobblestone 0  
fill ~5 ~0 ~28 ~31 ~0 ~28 mossy_cobblestone 0  
fill ~6 ~0 ~5 ~30 ~0 ~5 mossy_cobblestone 0  
fill ~6 ~0 ~29 ~30 ~0 ~29 mossy_cobblestone 0  
fill ~7 ~0 ~4 ~29 ~0 ~4 mossy_cobblestone 0  
fill ~7 ~0 ~30 ~29 ~0 ~30 mossy_cobblestone 0  
fill ~8 ~0 ~3 ~28 ~0 ~3 mossy_cobblestone 0  
fill ~8 ~0 ~31 ~28 ~0 ~31 mossy_cobblestone 0  
fill ~9 ~0 ~2 ~27 ~0 ~2 mossy_cobblestone 0  
fill ~9 ~0 ~32 ~27 ~0 ~32 mossy_cobblestone 0  
fill ~11 ~0 ~1 ~25 ~0 ~1 mossy_cobblestone 0  
fill ~11 ~0 ~33 ~25 ~0 ~33 mossy_cobblestone 0  
fill ~14 ~0 ~0 ~22 ~0 ~0 mossy_cobblestone 0  
fill ~14 ~0 ~34 ~22 ~0 ~34 mossy_cobblestone 0  
fill ~29 ~0 ~16 ~33 ~0 ~16 stonebrick 1  
fill ~29 ~0 ~20 ~29 ~0 ~22 stonebrick 1  
fill ~30 ~0 ~20 ~32 ~0 ~20 mossy_cobblestone 0  
fill ~30 ~0 ~21 ~30 ~0 ~17 mossy_cobblestone 0  
fill ~30 ~0 ~22 ~33 ~0 ~22 stonebrick 1  
fill ~31 ~0 ~17 ~31 ~0 ~18 stonebrick 1 
setblock ~31 ~0 ~21 stonebrick 1 
setblock ~32 ~0 ~17 mossy_cobblestone 0  
fill ~32 ~0 ~18 ~33 ~0 ~18 stonebrick 1 
setblock ~32 ~0 ~21 mossy_cobblestone 0 
setblock ~33 ~0 ~17 stonebrick 1  
fill ~33 ~0 ~20 ~33 ~0 ~22 stonebrick 1  
fill ~34 ~0 ~16 ~35 ~0 ~16 mossy_cobblestone 0  
fill ~34 ~0 ~17 ~35 ~0 ~17 mossy_cobblestone 0  
fill ~34 ~0 ~18 ~35 ~0 ~18 mossy_cobblestone 0  
fill ~34 ~0 ~20 ~35 ~0 ~20 mossy_cobblestone 0  
fill ~34 ~0 ~21 ~35 ~0 ~21 mossy_cobblestone 0  
fill ~34 ~0 ~22 ~34 ~0 ~10 mossy_cobblestone 0  
fill ~6 ~1 ~4 ~30 ~1 ~4 mossy_cobblestone 0  
fill ~6 ~1 ~5 ~30 ~1 ~5 mossy_cobblestone 0  
fill ~6 ~1 ~6 ~11 ~1 ~6 mossy_cobblestone 0  
fill ~6 ~1 ~7 ~11 ~1 ~7 mossy_cobblestone 0  
fill ~6 ~1 ~8 ~11 ~1 ~8 mossy_cobblestone 0  
fill ~6 ~1 ~9 ~11 ~1 ~9 mossy_cobblestone 0  
fill ~6 ~1 ~10 ~11 ~1 ~10 mossy_cobblestone 0  
fill ~6 ~1 ~11 ~11 ~1 ~11 mossy_cobblestone 0  
fill ~6 ~1 ~12 ~11 ~1 ~12 mossy_cobblestone 0  
fill ~7 ~1 ~13 ~11 ~1 ~13 mossy_cobblestone 0  
fill ~7 ~1 ~14 ~11 ~1 ~14 mossy_cobblestone 0  
fill ~8 ~1 ~16 ~28 ~1 ~16 mossy_cobblestone 0  
fill ~9 ~1 ~17 ~27 ~1 ~17 mossy_cobblestone 0  
fill ~10 ~1 ~18 ~26 ~1 ~18 mossy_cobblestone 0 
setblock ~10 ~1 ~28 red_sandstone_stairs 1  
fill ~11 ~1 ~19 ~25 ~1 ~19 mossy_cobblestone 0 
setblock ~11 ~1 ~27 red_sandstone_stairs 3 
setblock ~11 ~1 ~28 double_stone_slab2 8  
fill ~12 ~1 ~6 ~12 ~1 ~14 stonebrick 1 
setblock ~12 ~1 ~30 red_sandstone_stairs 3 
setblock ~12 ~1 ~31 double_stone_slab2 0  
fill ~13 ~1 ~6 ~30 ~1 ~6 mossy_cobblestone 0  
fill ~13 ~1 ~7 ~30 ~1 ~7 mossy_cobblestone 0  
fill ~13 ~1 ~8 ~30 ~1 ~8 mossy_cobblestone 0  
fill ~13 ~1 ~9 ~30 ~1 ~9 mossy_cobblestone 0  
fill ~13 ~1 ~10 ~30 ~1 ~10 mossy_cobblestone 0  
fill ~13 ~1 ~11 ~30 ~1 ~11 mossy_cobblestone 0  
fill ~13 ~1 ~12 ~30 ~1 ~12 mossy_cobblestone 0  
fill ~13 ~1 ~13 ~15 ~1 ~13 mossy_cobblestone 0  
fill ~13 ~1 ~14 ~15 ~1 ~14 mossy_cobblestone 0  
fill ~13 ~1 ~20 ~23 ~1 ~20 mossy_cobblestone 0 
setblock ~13 ~1 ~29 red_sandstone_stairs 1 
setblock ~14 ~1 ~29 double_stone_slab2 0  
fill ~15 ~1 ~21 ~21 ~1 ~21 mossy_cobblestone 0  
fill ~16 ~1 ~3 ~16 ~35 ~3 ladder 2  
fill ~16 ~1 ~28 ~18 ~1 ~28 stone_stairs 3  
fill ~17 ~1 ~27 ~17 ~2 ~27 stone_stairs 3 
setblock ~18 ~1 ~26 vine 8  
fill ~19 ~1 ~25 ~19 ~15 ~25 vine 1 
setblock ~19 ~1 ~26 log 3  
fill ~19 ~1 ~27 ~19 ~24 ~27 vine 4  
fill ~20 ~1 ~13 ~29 ~1 ~13 mossy_cobblestone 0  
fill ~20 ~1 ~14 ~29 ~1 ~14 mossy_cobblestone 0  
fill ~20 ~1 ~26 ~20 ~15 ~26 vine 2 
setblock ~22 ~1 ~23 prismarine 2  
fill ~22 ~1 ~25 ~24 ~1 ~25 prismarine 2 
setblock ~22 ~1 ~27 prismarine 2 
setblock ~23 ~1 ~24 prismarine 2 
setblock ~23 ~1 ~26 prismarine 2 
setblock ~24 ~1 ~24 quartz_stairs 0 
setblock ~24 ~1 ~26 quartz_stairs 0 
setblock ~25 ~1 ~24 quartz_stairs 2 
setblock ~25 ~1 ~25 quartz_stairs 4 
setblock ~25 ~1 ~26 quartz_stairs 3  
fill ~26 ~1 ~15 ~28 ~1 ~15 mossy_cobblestone 0 
setblock ~26 ~1 ~24 quartz_stairs 6 
setblock ~26 ~1 ~25 quartz_stairs 5 
setblock ~26 ~1 ~26 quartz_stairs 7  
fill ~26 ~1 ~30 ~28 ~1 ~30 prismarine 2 
setblock ~26 ~1 ~32 prismarine 2 
setblock ~27 ~1 ~29 quartz_stairs 0  
fill ~27 ~1 ~31 ~28 ~1 ~31 prismarine 2 
setblock ~28 ~1 ~29 quartz_stairs 5 
setblock ~28 ~1 ~32 prismarine 2 
setblock ~29 ~1 ~30 quartz_stairs 6 
setblock ~29 ~1 ~31 quartz_stairs 3  
fill ~6 ~2 ~4 ~30 ~2 ~4 mossy_cobblestone 0  
fill ~6 ~2 ~5 ~30 ~2 ~5 mossy_cobblestone 0  
fill ~6 ~2 ~6 ~30 ~2 ~6 mossy_cobblestone 0  
fill ~6 ~2 ~7 ~11 ~2 ~7 mossy_cobblestone 0  
fill ~6 ~2 ~8 ~11 ~2 ~8 mossy_cobblestone 0  
fill ~6 ~2 ~9 ~11 ~2 ~9 mossy_cobblestone 0  
fill ~6 ~2 ~10 ~11 ~2 ~10 mossy_cobblestone 0  
fill ~6 ~2 ~11 ~11 ~2 ~11 mossy_cobblestone 0  
fill ~6 ~2 ~12 ~11 ~2 ~12 mossy_cobblestone 0  
fill ~7 ~2 ~13 ~11 ~2 ~13 mossy_cobblestone 0  
fill ~7 ~2 ~14 ~11 ~2 ~14 mossy_cobblestone 0  
fill ~8 ~2 ~15 ~11 ~2 ~15 mossy_cobblestone 0  
fill ~8 ~2 ~16 ~28 ~2 ~16 mossy_cobblestone 0  
fill ~9 ~2 ~17 ~27 ~2 ~17 mossy_cobblestone 0  
fill ~10 ~2 ~18 ~26 ~2 ~18 mossy_cobblestone 0  
fill ~11 ~2 ~19 ~25 ~2 ~19 mossy_cobblestone 0 
setblock ~11 ~2 ~29 red_sandstone_stairs 0  
fill ~12 ~2 ~7 ~12 ~2 ~14 stonebrick 1 
setblock ~12 ~2 ~28 red_sandstone_stairs 2 
setblock ~12 ~2 ~30 red_sandstone_stairs 7  
fill ~13 ~2 ~7 ~30 ~2 ~7 mossy_cobblestone 0  
fill ~13 ~2 ~8 ~30 ~2 ~8 mossy_cobblestone 0  
fill ~13 ~2 ~9 ~30 ~2 ~9 mossy_cobblestone 0  
fill ~13 ~2 ~10 ~30 ~2 ~10 mossy_cobblestone 0  
fill ~13 ~2 ~11 ~30 ~2 ~11 mossy_cobblestone 0  
fill ~13 ~2 ~12 ~30 ~2 ~12 mossy_cobblestone 0  
fill ~13 ~2 ~13 ~15 ~2 ~13 mossy_cobblestone 0  
fill ~13 ~2 ~14 ~15 ~2 ~14 mossy_cobblestone 0  
fill ~13 ~2 ~20 ~23 ~2 ~20 mossy_cobblestone 0 
setblock ~13 ~2 ~29 red_sandstone_stairs 5 
setblock ~13 ~2 ~30 sandstone_stairs 7  
fill ~15 ~2 ~21 ~21 ~2 ~21 mossy_cobblestone 0 
setblock ~16 ~2 ~27 stone_stairs 3  
fill ~17 ~2 ~26 ~17 ~3 ~26 stone_stairs 3 
setblock ~18 ~2 ~27 stone_stairs 3 
setblock ~19 ~2 ~26 sea_lantern 0  
fill ~20 ~2 ~13 ~29 ~2 ~13 mossy_cobblestone 0  
fill ~20 ~2 ~14 ~29 ~2 ~14 mossy_cobblestone 0 
setblock ~25 ~2 ~25 quartz_stairs 0  
fill ~26 ~2 ~15 ~28 ~2 ~15 mossy_cobblestone 0 
setblock ~26 ~2 ~24 quartz_stairs 2  
fill ~26 ~2 ~25 ~26 ~3 ~25 quartz_block 0 
setblock ~26 ~2 ~26 quartz_stairs 3 
setblock ~27 ~2 ~19 prismarine 2 
setblock ~27 ~2 ~20 quartz_stairs 6 
setblock ~27 ~2 ~21 quartz_block 0 
setblock ~27 ~2 ~22 quartz_stairs 7  
fill ~28 ~2 ~25 ~28 ~3 ~25 wool 9 
setblock ~28 ~2 ~29 quartz_stairs 0 
setblock ~29 ~2 ~29 quartz_stairs 6 
setblock ~29 ~2 ~30 quartz_stairs 3  
fill ~6 ~3 ~7 ~6 ~4 ~7 glass 0  
fill ~6 ~3 ~8 ~6 ~4 ~8 glass 0  
fill ~6 ~3 ~9 ~6 ~4 ~9 glass 0  
fill ~7 ~3 ~4 ~15 ~3 ~4 glass 0  
fill ~7 ~3 ~5 ~7 ~3 ~6 glass 0 
setblock ~7 ~3 ~7 sand 0  
fill ~7 ~3 ~8 ~11 ~3 ~8 gravel 0  
fill ~7 ~3 ~9 ~7 ~5 ~9 sandstone 1  
fill ~7 ~3 ~10 ~7 ~3 ~13 glass 0  
fill ~8 ~3 ~5 ~28 ~3 ~5 stained_hardened_clay 14  
fill ~8 ~3 ~6 ~28 ~3 ~6 stained_hardened_clay 14  
fill ~8 ~3 ~7 ~11 ~3 ~7 gravel 0  
fill ~8 ~3 ~9 ~11 ~3 ~9 gravel 0  
fill ~8 ~3 ~10 ~11 ~3 ~10 gravel 0  
fill ~8 ~3 ~11 ~11 ~3 ~11 gravel 0  
fill ~8 ~3 ~12 ~11 ~3 ~12 gravel 0  
fill ~8 ~3 ~13 ~8 ~4 ~13 sand 0 
setblock ~8 ~3 ~14 glass 0  
fill ~9 ~3 ~13 ~11 ~3 ~13 gravel 0  
fill ~9 ~3 ~14 ~11 ~3 ~14 gravel 0  
fill ~9 ~3 ~15 ~9 ~3 ~16 glass 0  
fill ~10 ~3 ~15 ~11 ~3 ~15 gravel 0  
fill ~10 ~3 ~17 ~11 ~3 ~17 glass 0  
fill ~11 ~3 ~16 ~25 ~3 ~16 gravel 0  
fill ~12 ~3 ~7 ~12 ~5 ~7 sandstone 0  
fill ~12 ~3 ~8 ~12 ~5 ~8 sandstone 0  
fill ~12 ~3 ~9 ~12 ~5 ~9 sandstone 0  
fill ~12 ~3 ~10 ~12 ~5 ~10 sandstone 0  
fill ~12 ~3 ~11 ~12 ~5 ~11 sandstone 0  
fill ~12 ~3 ~12 ~12 ~5 ~12 sandstone 0  
fill ~12 ~3 ~13 ~12 ~5 ~13 sandstone 0  
fill ~12 ~3 ~14 ~12 ~5 ~14 sandstone 0  
fill ~12 ~3 ~15 ~13 ~3 ~15 stonebrick 1  
fill ~12 ~3 ~17 ~24 ~3 ~17 gravel 0 
setblock ~12 ~3 ~18 glass 0 
setblock ~12 ~3 ~29 wool 0 
setblock ~12 ~3 ~30 red_sandstone_stairs 3 
setblock ~12 ~3 ~31 sandstone_stairs 1  
fill ~13 ~3 ~7 ~28 ~3 ~7 gravel 0  
fill ~13 ~3 ~8 ~29 ~3 ~8 gravel 0  
fill ~13 ~3 ~9 ~28 ~3 ~9 gravel 0  
fill ~13 ~3 ~10 ~28 ~3 ~10 gravel 0  
fill ~13 ~3 ~11 ~28 ~3 ~11 gravel 0  
fill ~13 ~3 ~12 ~28 ~3 ~12 gravel 0  
fill ~13 ~3 ~13 ~15 ~3 ~13 gravel 0  
fill ~13 ~3 ~14 ~15 ~3 ~14 gravel 0  
fill ~13 ~3 ~18 ~13 ~4 ~18 sand 0  
fill ~13 ~3 ~19 ~16 ~3 ~19 glass 0 
setblock ~13 ~3 ~28 sandstone_stairs 4 
setblock ~13 ~3 ~29 red_sandstone_stairs 1 
setblock ~13 ~3 ~30 sandstone_stairs 1 
setblock ~13 ~3 ~31 jungle_fence_gate 6  
fill ~14 ~3 ~15 ~23 ~3 ~15 sandstone 0  
fill ~14 ~3 ~18 ~22 ~3 ~18 gravel 0 
setblock ~14 ~3 ~28 sandstone_stairs 3 
setblock ~14 ~3 ~30 jungle_fence_gate 5  
fill ~16 ~3 ~4 ~16 ~35 ~4 log 3  
fill ~16 ~3 ~13 ~19 ~3 ~13 sandstone 0  
fill ~16 ~3 ~14 ~19 ~3 ~14 sandstone 0 
setblock ~16 ~3 ~26 stone_stairs 3  
fill ~17 ~3 ~4 ~27 ~3 ~4 glass 0  
fill ~17 ~3 ~19 ~18 ~3 ~19 gravel 0  
fill ~17 ~3 ~20 ~19 ~3 ~20 glass 0  
fill ~17 ~3 ~25 ~17 ~4 ~25 stone_stairs 3 
setblock ~18 ~3 ~26 stone_stairs 3  
fill ~19 ~3 ~19 ~23 ~3 ~19 glass 0 
setblock ~19 ~3 ~26 obsidian 0  
fill ~20 ~3 ~13 ~27 ~3 ~13 gravel 0  
fill ~20 ~3 ~14 ~27 ~3 ~14 gravel 0  
fill ~23 ~3 ~18 ~23 ~4 ~18 sand 0  
fill ~24 ~3 ~15 ~25 ~3 ~15 stonebrick 1 
setblock ~24 ~3 ~18 glass 0  
fill ~25 ~3 ~17 ~26 ~3 ~17 glass 0 
setblock ~26 ~3 ~15 gravel 0  
fill ~26 ~3 ~16 ~26 ~4 ~16 sand 0 
setblock ~26 ~3 ~30 wool 9  
fill ~27 ~3 ~15 ~27 ~3 ~16 glass 0 
setblock ~27 ~3 ~20 prismarine 2 
setblock ~27 ~3 ~21 quartz_stairs 3 
setblock ~27 ~3 ~22 quartz_stairs 0  
fill ~28 ~3 ~13 ~28 ~4 ~13 sand 0 
setblock ~28 ~3 ~14 glass 0 
setblock ~28 ~3 ~22 quartz_stairs 6  
fill ~29 ~3 ~4 ~29 ~3 ~6 glass 0  
fill ~29 ~3 ~10 ~29 ~3 ~13 glass 0 
setblock ~29 ~3 ~28 quartz_stairs 6 
setblock ~29 ~3 ~29 quartz_stairs 3  
fill ~30 ~3 ~7 ~30 ~4 ~7 glass 0  
fill ~30 ~3 ~8 ~30 ~4 ~8 glass 0  
fill ~30 ~3 ~9 ~30 ~4 ~9 glass 0  
fill ~6 ~4 ~4 ~15 ~4 ~4 glass 0  
fill ~6 ~4 ~5 ~6 ~5 ~5 glass 0  
fill ~6 ~4 ~6 ~6 ~5 ~6 glass 0  
fill ~6 ~4 ~10 ~6 ~5 ~10 glass 0  
fill ~6 ~4 ~11 ~6 ~5 ~11 glass 0  
fill ~6 ~4 ~12 ~6 ~6 ~12 glass 0  
fill ~7 ~4 ~5 ~29 ~4 ~5 hardened_clay 0  
fill ~7 ~4 ~6 ~29 ~4 ~6 hardened_clay 0  
fill ~7 ~4 ~8 ~7 ~5 ~8 sandstone 1  
fill ~7 ~4 ~10 ~7 ~5 ~10 sandstone 1  
fill ~7 ~4 ~11 ~11 ~4 ~11 sand 0  
fill ~7 ~4 ~12 ~11 ~4 ~12 sand 0  
fill ~7 ~4 ~13 ~7 ~4 ~14 glass 0  
fill ~8 ~4 ~7 ~8 ~4 ~9 redstone_wire 0 
setblock ~8 ~4 ~10 sticky_piston 1  
fill ~8 ~4 ~14 ~11 ~4 ~14 sand 0 
setblock ~8 ~4 ~15 glass 0 
setblock ~9 ~4 ~7 stonebrick 1  
fill ~9 ~4 ~8 ~9 ~5 ~8 sandstone 1  
fill ~9 ~4 ~9 ~11 ~4 ~9 sand 0  
fill ~9 ~4 ~10 ~11 ~4 ~10 sand 0  
fill ~9 ~4 ~13 ~11 ~4 ~13 sand 0  
fill ~9 ~4 ~15 ~11 ~4 ~15 sand 0 
setblock ~9 ~4 ~16 glass 0  
fill ~10 ~4 ~7 ~11 ~4 ~7 sand 0  
fill ~10 ~4 ~8 ~11 ~4 ~8 sand 0  
fill ~10 ~4 ~16 ~26 ~4 ~16 sand 0  
fill ~10 ~4 ~17 ~10 ~3 ~17 glass 0  
fill ~11 ~4 ~17 ~25 ~4 ~17 sand 0 
setblock ~11 ~4 ~18 glass 0 
setblock ~12 ~4 ~15 sandstone 0 
setblock ~12 ~4 ~18 sand 0  
fill ~12 ~4 ~19 ~13 ~4 ~19 glass 0  
fill ~12 ~4 ~29 ~12 ~4 ~30 red_sandstone_stairs 2 
setblock ~12 ~4 ~31 red_sandstone_stairs 5 
setblock ~12 ~4 ~32 sandstone_stairs 7  
fill ~13 ~4 ~7 ~29 ~4 ~7 sand 0  
fill ~13 ~4 ~8 ~29 ~4 ~8 sand 0  
fill ~13 ~4 ~9 ~29 ~4 ~9 sand 0  
fill ~13 ~4 ~10 ~29 ~4 ~10 sand 0  
fill ~13 ~4 ~11 ~29 ~4 ~11 sand 0  
fill ~13 ~4 ~12 ~29 ~4 ~12 sand 0  
fill ~13 ~4 ~13 ~15 ~4 ~13 sand 0  
fill ~13 ~4 ~14 ~15 ~4 ~14 sand 0  
fill ~13 ~4 ~15 ~14 ~4 ~15 redstone_wire 0 
setblock ~13 ~4 ~28 red_sandstone_stairs 3 
setblock ~13 ~4 ~29 red_sandstone_stairs 0 
setblock ~13 ~4 ~30 sandstone 0  
fill ~14 ~4 ~18 ~24 ~4 ~18 sand 0  
fill ~14 ~4 ~19 ~21 ~4 ~19 sand 0  
fill ~14 ~4 ~20 ~22 ~4 ~20 glass 0 
setblock ~14 ~4 ~28 red_sandstone_stairs 1 
setblock ~15 ~4 ~28 red_sandstone_stairs 5  
fill ~16 ~4 ~13 ~19 ~4 ~13 sandstone 0  
fill ~16 ~4 ~14 ~19 ~4 ~14 sandstone 0 
setblock ~16 ~4 ~25 stone_stairs 3  
fill ~17 ~4 ~4 ~27 ~4 ~4 glass 0  
fill ~17 ~4 ~24 ~17 ~5 ~24 stone_stairs 3  
fill ~17 ~4 ~26 ~17 ~24 ~26 vine 4 
setblock ~18 ~4 ~25 stone_stairs 3  
fill ~18 ~4 ~26 ~18 ~15 ~26 vine 8  
fill ~19 ~4 ~26 ~19 ~14 ~26 log 3  
fill ~20 ~4 ~13 ~28 ~4 ~13 sand 0  
fill ~20 ~4 ~14 ~28 ~4 ~14 sand 0  
fill ~22 ~4 ~19 ~24 ~4 ~19 glass 0 
setblock ~24 ~4 ~15 redstone_wire 0 
setblock ~25 ~4 ~15 sandstone 0 
setblock ~25 ~4 ~18 glass 0  
fill ~26 ~4 ~15 ~27 ~4 ~15 sand 0 
setblock ~26 ~4 ~17 glass 0  
fill ~26 ~4 ~24 ~27 ~4 ~24 quartz_stairs 6 
setblock ~26 ~4 ~25 quartz_stairs 4 
setblock ~27 ~4 ~16 glass 0 
setblock ~27 ~4 ~19 prismarine 2  
fill ~27 ~4 ~21 ~27 ~5 ~21 prismarine 2 
setblock ~27 ~4 ~25 quartz_stairs 5  
fill ~27 ~4 ~30 ~27 ~7 ~30 wool 9 
setblock ~28 ~4 ~15 glass 0 
setblock ~28 ~4 ~22 quartz_stairs 0  
fill ~28 ~4 ~24 ~28 ~5 ~24 wool 9  
fill ~29 ~4 ~13 ~29 ~4 ~14 glass 0 
setblock ~29 ~4 ~21 quartz_stairs 6 
setblock ~29 ~4 ~22 quartz_stairs 3  
fill ~29 ~4 ~28 ~29 ~10 ~28 quartz_block 0  
fill ~30 ~4 ~4 ~30 ~6 ~4 glass 0  
fill ~30 ~4 ~5 ~30 ~5 ~5 glass 0  
fill ~30 ~4 ~6 ~30 ~5 ~6 glass 0  
fill ~30 ~4 ~10 ~30 ~5 ~10 glass 0  
fill ~30 ~4 ~11 ~30 ~5 ~11 glass 0  
fill ~30 ~4 ~12 ~30 ~6 ~12 glass 0  
fill ~31 ~4 ~25 ~31 ~6 ~25 wool 9  
fill ~5 ~5 ~7 ~5 ~7 ~7 glass 0  
fill ~5 ~5 ~8 ~5 ~7 ~8 glass 0  
fill ~5 ~5 ~9 ~5 ~7 ~9 glass 0  
fill ~6 ~5 ~4 ~15 ~5 ~4 glass 0  
fill ~6 ~5 ~7 ~6 ~5 ~8 sand 0  
fill ~6 ~5 ~13 ~6 ~7 ~13 glass 0  
fill ~7 ~5 ~5 ~29 ~5 ~5 hardened_clay 0  
fill ~7 ~5 ~6 ~29 ~5 ~6 hardened_clay 0  
fill ~7 ~5 ~11 ~11 ~5 ~11 sand 0  
fill ~7 ~5 ~12 ~7 ~5 ~13 slime 0  
fill ~7 ~5 ~14 ~7 ~5 ~15 glass 0  
fill ~8 ~5 ~8 ~8 ~6 ~8 sandstone 1  
fill ~8 ~5 ~9 ~9 ~5 ~9 sandstone 1 
setblock ~8 ~5 ~10 slime 0  
fill ~8 ~5 ~12 ~11 ~5 ~12 sand 0  
fill ~8 ~5 ~13 ~8 ~5 ~15 slime 0  
fill ~8 ~5 ~16 ~8 ~6 ~16 glass 0 
setblock ~9 ~5 ~7 redstone_wire 0  
fill ~9 ~5 ~10 ~11 ~5 ~10 sand 0  
fill ~9 ~5 ~13 ~11 ~5 ~13 sand 0  
fill ~9 ~5 ~14 ~11 ~5 ~14 sand 0  
fill ~9 ~5 ~15 ~11 ~5 ~15 sand 0 
setblock ~9 ~5 ~16 slime 0 
setblock ~9 ~5 ~17 glass 0  
fill ~10 ~5 ~7 ~10 ~5 ~9 stonebrick 1  
fill ~10 ~5 ~16 ~25 ~5 ~16 sand 0 
setblock ~10 ~5 ~17 slime 0  
fill ~10 ~5 ~18 ~10 ~6 ~18 glass 0  
fill ~11 ~5 ~7 ~11 ~5 ~17 sand 0  
fill ~11 ~5 ~18 ~13 ~5 ~18 slime 0  
fill ~11 ~5 ~19 ~12 ~5 ~19 glass 0 
setblock ~12 ~5 ~15 redstone_lamp 0  
fill ~12 ~5 ~17 ~25 ~5 ~17 sand 0 
setblock ~12 ~5 ~29 wool 0 
setblock ~12 ~5 ~30 red_sandstone_stairs 7 
setblock ~12 ~5 ~32 red_sandstone_stairs 1  
fill ~13 ~5 ~7 ~22 ~5 ~7 sand 0  
fill ~13 ~5 ~8 ~22 ~5 ~8 sand 0  
fill ~13 ~5 ~9 ~29 ~5 ~9 sand 0  
fill ~13 ~5 ~10 ~29 ~5 ~10 sand 0  
fill ~13 ~5 ~11 ~29 ~5 ~11 sand 0  
fill ~13 ~5 ~12 ~28 ~5 ~12 sand 0  
fill ~13 ~5 ~13 ~15 ~5 ~13 sand 0  
fill ~13 ~5 ~14 ~15 ~5 ~14 sand 0  
fill ~13 ~5 ~15 ~24 ~5 ~15 sandstone 0  
fill ~13 ~5 ~19 ~14 ~5 ~19 slime 0  
fill ~13 ~5 ~20 ~16 ~5 ~20 glass 0 
setblock ~13 ~5 ~29 red_sandstone_stairs 5 
setblock ~13 ~5 ~30 double_stone_slab2 8  
fill ~14 ~5 ~18 ~22 ~5 ~18 sand 0  
fill ~15 ~5 ~19 ~21 ~5 ~19 sand 0  
fill ~16 ~5 ~13 ~19 ~5 ~13 sandstone 0  
fill ~16 ~5 ~14 ~19 ~5 ~14 sandstone 0 
setblock ~16 ~5 ~24 stone_stairs 3  
fill ~17 ~5 ~4 ~28 ~5 ~4 glass 0  
fill ~17 ~5 ~20 ~18 ~5 ~20 slime 0  
fill ~17 ~5 ~21 ~19 ~5 ~21 glass 0 
setblock ~18 ~5 ~24 stone_stairs 3  
fill ~19 ~5 ~20 ~23 ~5 ~20 glass 0  
fill ~20 ~5 ~13 ~27 ~5 ~13 sand 0  
fill ~20 ~5 ~14 ~27 ~5 ~14 sand 0 
setblock ~22 ~5 ~19 slime 0  
fill ~23 ~5 ~7 ~24 ~5 ~7 slime 0  
fill ~23 ~5 ~8 ~24 ~5 ~8 slime 0  
fill ~23 ~5 ~18 ~25 ~5 ~18 slime 0  
fill ~23 ~5 ~19 ~25 ~5 ~19 glass 0  
fill ~25 ~5 ~7 ~29 ~5 ~7 sand 0  
fill ~25 ~5 ~8 ~26 ~5 ~8 sand 0 
setblock ~25 ~5 ~15 redstone_lamp 0  
fill ~26 ~5 ~15 ~27 ~5 ~15 sand 0  
fill ~26 ~5 ~16 ~26 ~6 ~16 water 8 
setblock ~26 ~5 ~17 slime 0  
fill ~26 ~5 ~18 ~26 ~6 ~18 glass 0  
fill ~26 ~5 ~24 ~27 ~5 ~24 quartz_block 0  
fill ~26 ~5 ~25 ~27 ~5 ~25 quartz_block 0 
setblock ~26 ~5 ~26 quartz_stairs 7 
setblock ~27 ~5 ~8 log 3 
setblock ~27 ~5 ~16 slime 0 
setblock ~27 ~5 ~17 glass 0 
setblock ~27 ~5 ~26 quartz_stairs 5  
fill ~28 ~5 ~8 ~29 ~5 ~8 sand 0  
fill ~28 ~5 ~13 ~29 ~5 ~13 slime 0  
fill ~28 ~5 ~14 ~28 ~5 ~15 slime 0  
fill ~28 ~5 ~16 ~28 ~6 ~16 glass 0  
fill ~28 ~5 ~23 ~28 ~6 ~23 wool 9 
setblock ~29 ~5 ~12 slime 0  
fill ~29 ~5 ~14 ~29 ~5 ~15 glass 0 
setblock ~29 ~5 ~21 quartz_stairs 0 
setblock ~29 ~5 ~27 quartz_stairs 6  
fill ~30 ~5 ~7 ~30 ~5 ~9 slime 0  
fill ~30 ~5 ~13 ~30 ~7 ~13 glass 0 
setblock ~30 ~5 ~20 quartz_stairs 6 
setblock ~30 ~5 ~21 quartz_stairs 5  
fill ~30 ~5 ~27 ~30 ~5 ~28 quartz_stairs 5  
fill ~31 ~5 ~7 ~31 ~7 ~7 glass 0  
fill ~31 ~5 ~8 ~31 ~7 ~8 glass 0  
fill ~31 ~5 ~9 ~31 ~7 ~9 glass 0  
fill ~5 ~6 ~5 ~5 ~7 ~5 glass 0  
fill ~5 ~6 ~6 ~5 ~7 ~6 glass 0  
fill ~5 ~6 ~10 ~5 ~7 ~10 glass 0  
fill ~5 ~6 ~11 ~5 ~8 ~11 glass 0  
fill ~6 ~6 ~4 ~15 ~6 ~4 glass 0  
fill ~6 ~6 ~5 ~22 ~6 ~5 stonebrick 1  
fill ~6 ~6 ~6 ~22 ~6 ~6 stonebrick 1  
fill ~6 ~6 ~7 ~8 ~6 ~7 stonebrick 1  
fill ~6 ~6 ~8 ~7 ~6 ~8 stonebrick 1  
fill ~6 ~6 ~9 ~7 ~6 ~9 stonebrick 1  
fill ~6 ~6 ~10 ~6 ~6 ~11 slime 0  
fill ~6 ~6 ~14 ~6 ~8 ~14 glass 0  
fill ~7 ~6 ~10 ~10 ~6 ~10 water 8  
fill ~7 ~6 ~11 ~11 ~6 ~11 water 8  
fill ~7 ~6 ~12 ~13 ~6 ~12 water 8  
fill ~7 ~6 ~13 ~9 ~6 ~13 water 8 
setblock ~7 ~6 ~14 slime 0  
fill ~7 ~6 ~15 ~7 ~7 ~15 glass 0 
setblock ~8 ~6 ~9 water 8  
fill ~8 ~6 ~14 ~9 ~6 ~14 water 8  
fill ~8 ~6 ~15 ~9 ~6 ~15 water 8  
fill ~8 ~6 ~17 ~8 ~8 ~17 glass 0 
setblock ~9 ~6 ~9 stonebrick 1  
fill ~9 ~6 ~16 ~27 ~6 ~16 water 8 
setblock ~9 ~6 ~17 slime 0  
fill ~9 ~6 ~18 ~9 ~8 ~18 glass 0 
setblock ~10 ~6 ~7 redstone_wire 0 
setblock ~10 ~6 ~8 unpowered_repeater 0  
fill ~10 ~6 ~13 ~10 ~7 ~13 quartz_block 2  
fill ~10 ~6 ~14 ~10 ~7 ~14 quartz_block 2  
fill ~10 ~6 ~15 ~10 ~7 ~15 quartz_block 2  
fill ~10 ~6 ~17 ~27 ~6 ~17 water 8  
fill ~11 ~6 ~7 ~22 ~6 ~7 stonebrick 1  
fill ~11 ~6 ~8 ~22 ~6 ~8 stonebrick 1  
fill ~11 ~6 ~9 ~22 ~6 ~9 stonebrick 1  
fill ~11 ~6 ~10 ~21 ~6 ~10 stonebrick 1  
fill ~11 ~6 ~13 ~11 ~6 ~15 quartz_block 0  
fill ~11 ~6 ~18 ~25 ~6 ~18 water 8  
fill ~11 ~6 ~19 ~11 ~7 ~19 glass 0  
fill ~12 ~6 ~11 ~20 ~6 ~11 stonebrick 1  
fill ~12 ~6 ~13 ~13 ~6 ~13 water 8  
fill ~12 ~6 ~14 ~14 ~6 ~14 water 8  
fill ~12 ~6 ~15 ~16 ~6 ~15 water 8 
setblock ~12 ~6 ~19 slime 0  
fill ~12 ~6 ~20 ~14 ~6 ~20 glass 0 
setblock ~12 ~6 ~29 red_sandstone 2  
fill ~12 ~6 ~30 ~12 ~7 ~30 red_sandstone_stairs 3  
fill ~13 ~6 ~19 ~21 ~6 ~19 water 8 
setblock ~13 ~6 ~29 red_sandstone_stairs 1 
setblock ~13 ~6 ~30 glowstone 0  
fill ~14 ~6 ~12 ~15 ~6 ~12 stonebrick 1 
setblock ~14 ~6 ~13 stone_slab 0  
fill ~14 ~6 ~23 ~14 ~6 ~24 stone_slab 8  
fill ~15 ~6 ~13 ~17 ~6 ~13 stone_slab 8  
fill ~15 ~6 ~14 ~17 ~6 ~14 stone_slab 0  
fill ~15 ~6 ~20 ~18 ~6 ~20 water 8  
fill ~15 ~6 ~21 ~21 ~6 ~21 glass 0 
setblock ~15 ~6 ~22 stone_slab 8 
setblock ~15 ~6 ~23 double_stone_slab 0 
setblock ~15 ~6 ~24 stone_slab 0 
setblock ~16 ~6 ~12 mossy_cobblestone 0  
fill ~16 ~6 ~22 ~18 ~6 ~22 stone_slab 0  
fill ~16 ~6 ~23 ~18 ~6 ~23 stone_slab 0  
fill ~17 ~6 ~4 ~28 ~6 ~4 glass 0  
fill ~17 ~6 ~12 ~18 ~6 ~12 stonebrick 1  
fill ~17 ~6 ~15 ~18 ~6 ~15 sandstone 0 
setblock ~18 ~6 ~13 stone_slab 0 
setblock ~18 ~6 ~14 sandstone 0  
fill ~19 ~6 ~12 ~23 ~6 ~12 water 8  
fill ~19 ~6 ~13 ~22 ~6 ~13 water 8  
fill ~19 ~6 ~14 ~22 ~6 ~14 water 8  
fill ~19 ~6 ~15 ~22 ~6 ~15 water 8  
fill ~19 ~6 ~20 ~20 ~6 ~20 slime 0 
setblock ~19 ~6 ~22 stone_slab 8 
setblock ~19 ~6 ~23 double_stone_slab 0 
setblock ~19 ~6 ~24 stone_slab 0  
fill ~20 ~6 ~23 ~20 ~6 ~24 stone_slab 8  
fill ~21 ~6 ~11 ~23 ~6 ~11 water 8  
fill ~21 ~6 ~20 ~24 ~6 ~20 glass 0  
fill ~22 ~6 ~10 ~23 ~6 ~10 water 8  
fill ~22 ~6 ~19 ~22 ~19 ~19 water 9  
fill ~23 ~6 ~5 ~30 ~6 ~5 stained_hardened_clay 1  
fill ~23 ~6 ~6 ~30 ~6 ~6 stained_hardened_clay 1  
fill ~23 ~6 ~7 ~30 ~6 ~7 water 8  
fill ~23 ~6 ~8 ~24 ~6 ~8 water 8  
fill ~23 ~6 ~9 ~30 ~6 ~9 water 8  
fill ~23 ~6 ~13 ~24 ~6 ~13 water 0  
fill ~23 ~6 ~14 ~24 ~6 ~14 water 0  
fill ~23 ~6 ~15 ~24 ~6 ~15 water 0 
setblock ~23 ~6 ~19 slime 0  
fill ~24 ~6 ~10 ~25 ~6 ~10 water 1 
setblock ~24 ~6 ~11 fence 2  
fill ~24 ~6 ~19 ~25 ~6 ~19 glass 0  
fill ~25 ~6 ~8 ~26 ~6 ~8 leaves 11 
setblock ~25 ~6 ~11 red_sandstone 2  
fill ~25 ~6 ~13 ~29 ~6 ~13 water 8  
fill ~25 ~6 ~14 ~29 ~6 ~14 water 8  
fill ~25 ~6 ~15 ~28 ~6 ~15 water 8 
setblock ~25 ~6 ~25 quartz_stairs 4 
setblock ~26 ~6 ~10 birch_fence_gate 6 
setblock ~26 ~6 ~11 sandstone_stairs 0 
setblock ~26 ~6 ~12 birch_fence_gate 4 
setblock ~26 ~6 ~24 quartz_stairs 2  
fill ~26 ~6 ~25 ~27 ~6 ~25 quartz_block 0  
fill ~26 ~6 ~26 ~27 ~6 ~26 quartz_block 0  
fill ~26 ~6 ~30 ~26 ~10 ~30 wool 9  
fill ~27 ~6 ~8 ~27 ~8 ~8 leaves 15 
setblock ~27 ~6 ~10 birch_fence_gate 4 
setblock ~27 ~6 ~11 red_sandstone_stairs 0 
setblock ~27 ~6 ~12 birch_fence_gate 6  
fill ~27 ~6 ~18 ~27 ~8 ~18 glass 0  
fill ~27 ~6 ~23 ~27 ~8 ~23 wool 9 
setblock ~27 ~6 ~24 quartz_block 0 
setblock ~28 ~6 ~8 water 0 
setblock ~28 ~6 ~10 birch_fence_gate 6 
setblock ~28 ~6 ~11 sandstone_stairs 0 
setblock ~28 ~6 ~12 birch_fence_gate 4  
fill ~28 ~6 ~17 ~28 ~8 ~17 glass 0 
setblock ~29 ~6 ~8 water 1  
fill ~29 ~6 ~10 ~30 ~6 ~10 water 8  
fill ~29 ~6 ~11 ~30 ~6 ~11 water 8  
fill ~29 ~6 ~12 ~29 ~6 ~9 water 8  
fill ~29 ~6 ~15 ~29 ~7 ~15 glass 0  
fill ~29 ~6 ~27 ~30 ~6 ~27 quartz_block 0 
setblock ~30 ~6 ~8 water 8  
fill ~30 ~6 ~14 ~30 ~8 ~14 glass 0 
setblock ~30 ~6 ~20 quartz_block 0  
fill ~30 ~6 ~25 ~30 ~11 ~25 wool 9 
setblock ~30 ~6 ~28 quartz_block 0  
fill ~31 ~6 ~5 ~31 ~7 ~5 glass 0  
fill ~31 ~6 ~6 ~31 ~7 ~6 glass 0  
fill ~31 ~6 ~10 ~31 ~7 ~10 glass 0  
fill ~31 ~6 ~11 ~31 ~8 ~11 glass 0 
setblock ~31 ~6 ~20 quartz_stairs 5 
setblock ~31 ~6 ~21 quartz_stairs 7  
fill ~3 ~7 ~4 ~4 ~7 ~4 stone_slab 8  
fill ~3 ~7 ~5 ~4 ~7 ~5 stone_slab 8  
fill ~3 ~7 ~6 ~4 ~7 ~6 stone_slab 8  
fill ~3 ~7 ~7 ~4 ~7 ~7 stone_slab 8  
fill ~3 ~7 ~8 ~4 ~7 ~8 stone_slab 8  
fill ~3 ~7 ~9 ~4 ~7 ~9 stone_slab 8  
fill ~3 ~7 ~10 ~4 ~7 ~10 stone_slab 8  
fill ~3 ~7 ~11 ~4 ~7 ~11 stone_slab 8  
fill ~3 ~7 ~12 ~4 ~7 ~12 stone_slab 8  
fill ~3 ~7 ~13 ~5 ~7 ~13 stone_slab 8  
fill ~3 ~7 ~14 ~5 ~7 ~14 stone_slab 8  
fill ~3 ~7 ~15 ~6 ~7 ~15 stone_slab 8  
fill ~4 ~7 ~16 ~6 ~7 ~16 stone_slab 8  
fill ~4 ~7 ~17 ~7 ~7 ~17 stone_slab 8  
fill ~5 ~7 ~4 ~15 ~7 ~4 glass 0  
fill ~5 ~7 ~12 ~5 ~9 ~12 glass 0  
fill ~5 ~7 ~18 ~8 ~7 ~18 stone_slab 8  
fill ~5 ~7 ~19 ~9 ~7 ~19 stone_slab 8  
fill ~6 ~7 ~9 ~7 ~7 ~9 stonebrick 1  
fill ~6 ~7 ~10 ~10 ~7 ~10 water 0  
fill ~6 ~7 ~11 ~11 ~7 ~11 water 0  
fill ~6 ~7 ~12 ~8 ~7 ~12 water 0  
fill ~6 ~7 ~20 ~11 ~7 ~20 stone_slab 8  
fill ~7 ~7 ~13 ~8 ~7 ~13 water 0  
fill ~7 ~7 ~14 ~8 ~7 ~14 water 0  
fill ~7 ~7 ~16 ~7 ~8 ~16 glass 0  
fill ~7 ~7 ~21 ~13 ~7 ~21 stone_slab 8  
fill ~8 ~7 ~8 ~8 ~13 ~8 stonebrick 1  
fill ~8 ~7 ~9 ~10 ~7 ~9 water 0  
fill ~8 ~7 ~15 ~8 ~20 ~15 water 0  
fill ~8 ~7 ~16 ~8 ~20 ~16 water 0  
fill ~8 ~7 ~22 ~13 ~7 ~22 stone_slab 8  
fill ~9 ~7 ~7 ~10 ~7 ~7 mossy_cobblestone 0  
fill ~9 ~7 ~8 ~9 ~12 ~8 log 3 
setblock ~9 ~7 ~12 quartz_stairs 6  
fill ~9 ~7 ~13 ~9 ~7 ~15 quartz_block 10 
setblock ~9 ~7 ~16 quartz_stairs 7  
fill ~9 ~7 ~17 ~27 ~7 ~17 water 0  
fill ~9 ~7 ~23 ~12 ~7 ~23 stone_slab 8  
fill ~10 ~7 ~5 ~10 ~17 ~5 stonebrick 1  
fill ~10 ~7 ~8 ~10 ~13 ~8 stonebrick 1  
fill ~10 ~7 ~12 ~10 ~8 ~12 quartz_block 2  
fill ~10 ~7 ~16 ~10 ~8 ~16 quartz_block 2  
fill ~10 ~7 ~18 ~26 ~7 ~18 water 0  
fill ~10 ~7 ~19 ~10 ~8 ~19 glass 0  
fill ~11 ~7 ~9 ~11 ~13 ~9 stonebrick 1  
fill ~11 ~7 ~10 ~12 ~7 ~10 stonebrick 1  
fill ~11 ~7 ~12 ~13 ~7 ~12 water 0  
fill ~11 ~7 ~13 ~29 ~7 ~13 water 0  
fill ~11 ~7 ~14 ~29 ~7 ~14 water 0  
fill ~11 ~7 ~15 ~28 ~7 ~15 water 0  
fill ~11 ~7 ~16 ~28 ~7 ~16 water 0  
fill ~11 ~7 ~24 ~12 ~7 ~24 stone_slab 8  
fill ~12 ~7 ~5 ~12 ~7 ~8 stone_slab 0  
fill ~12 ~7 ~11 ~13 ~7 ~11 stonebrick 1  
fill ~12 ~7 ~19 ~20 ~7 ~19 water 0  
fill ~12 ~7 ~20 ~13 ~7 ~20 glass 0 
setblock ~12 ~7 ~29 red_sandstone_stairs 0 
setblock ~12 ~7 ~31 fence 2 
setblock ~13 ~7 ~9 stone_slab 0 
setblock ~13 ~7 ~23 double_stone_slab 0 
setblock ~13 ~7 ~24 stone_slab 0 
setblock ~13 ~7 ~29 red_sandstone_stairs 2 
setblock ~13 ~7 ~30 red_sandstone_stairs 1  
fill ~14 ~7 ~5 ~14 ~20 ~5 stonebrick 1  
fill ~14 ~7 ~7 ~14 ~20 ~7 stonebrick 1  
fill ~14 ~7 ~10 ~18 ~7 ~10 stone_slab 0  
fill ~14 ~7 ~12 ~15 ~7 ~12 stonebrick 1  
fill ~14 ~7 ~20 ~21 ~7 ~20 water 8  
fill ~14 ~7 ~21 ~22 ~7 ~21 glass 0  
fill ~14 ~7 ~22 ~14 ~7 ~23 stone_slab 0 
setblock ~14 ~7 ~29 fence 2  
fill ~15 ~7 ~8 ~15 ~20 ~8 stonebrick 1 
setblock ~16 ~7 ~6 stone_slab 0  
fill ~17 ~7 ~4 ~29 ~7 ~4 glass 0  
fill ~17 ~7 ~8 ~17 ~20 ~8 stonebrick 1  
fill ~17 ~7 ~12 ~18 ~7 ~12 stonebrick 1  
fill ~18 ~7 ~5 ~18 ~20 ~5 stonebrick 1  
fill ~18 ~7 ~7 ~18 ~20 ~7 stonebrick 1 
setblock ~19 ~7 ~9 stone_slab 0  
fill ~19 ~7 ~11 ~20 ~7 ~11 stonebrick 1  
fill ~19 ~7 ~12 ~23 ~7 ~12 water 0  
fill ~20 ~7 ~5 ~20 ~7 ~8 stone_slab 0  
fill ~20 ~7 ~10 ~21 ~7 ~10 stonebrick 1  
fill ~20 ~7 ~22 ~20 ~7 ~23 stone_slab 0 
setblock ~21 ~7 ~8 stone_button 2  
fill ~21 ~7 ~9 ~21 ~14 ~9 stonebrick 1  
fill ~21 ~7 ~11 ~23 ~7 ~11 water 0  
fill ~21 ~7 ~19 ~21 ~19 ~19 water 8  
fill ~21 ~7 ~22 ~27 ~7 ~22 stone_slab 8 
setblock ~21 ~7 ~23 double_stone_slab 0 
setblock ~21 ~7 ~24 stone_slab 0  
fill ~22 ~7 ~5 ~22 ~14 ~5 stonebrick 1  
fill ~22 ~7 ~7 ~22 ~14 ~7 stonebrick 1  
fill ~22 ~7 ~8 ~22 ~7 ~7 stonebrick 1 
setblock ~22 ~7 ~9 dispenser 3  
fill ~22 ~7 ~10 ~23 ~7 ~10 water 0  
fill ~22 ~7 ~20 ~24 ~7 ~20 glass 0  
fill ~22 ~7 ~23 ~24 ~7 ~23 stone_slab 8  
fill ~22 ~7 ~24 ~23 ~7 ~24 stone_slab 8  
fill ~23 ~7 ~5 ~30 ~7 ~5 hardened_clay 0 
setblock ~23 ~7 ~6 water 9  
fill ~23 ~7 ~7 ~30 ~7 ~7 water 0  
fill ~23 ~7 ~8 ~24 ~7 ~8 water 0  
fill ~23 ~7 ~9 ~27 ~7 ~9 water 0  
fill ~23 ~7 ~19 ~23 ~19 ~19 water 9  
fill ~23 ~7 ~21 ~28 ~7 ~21 stone_slab 8  
fill ~24 ~7 ~6 ~30 ~7 ~6 hardened_clay 0 
setblock ~24 ~7 ~11 stained_hardened_clay 9  
fill ~24 ~7 ~19 ~26 ~7 ~19 glass 0 
setblock ~24 ~7 ~25 quartz_stairs 4  
fill ~25 ~7 ~8 ~25 ~6 ~8 leaves 11  
fill ~25 ~7 ~20 ~29 ~7 ~20 stone_slab 8 
setblock ~25 ~7 ~24 quartz_stairs 4  
fill ~25 ~7 ~25 ~26 ~7 ~25 quartz_block 0  
fill ~25 ~7 ~30 ~25 ~9 ~30 wool 9  
fill ~26 ~7 ~8 ~26 ~20 ~8 water 0  
fill ~26 ~7 ~23 ~26 ~12 ~23 wool 9 
setblock ~26 ~7 ~24 quartz_stairs 6  
fill ~26 ~7 ~26 ~27 ~7 ~26 quartz_stairs 3  
fill ~27 ~7 ~19 ~30 ~7 ~19 stone_slab 8 
setblock ~27 ~7 ~24 quartz_stairs 2 
setblock ~27 ~7 ~25 quartz_stairs 1  
fill ~28 ~7 ~8 ~29 ~7 ~8 leaves 15 
setblock ~28 ~7 ~9 water 8 
setblock ~28 ~7 ~11 red_sandstone_stairs 5  
fill ~28 ~7 ~18 ~31 ~7 ~18 stone_slab 8  
fill ~28 ~7 ~28 ~28 ~7 ~29 quartz_stairs 4  
fill ~29 ~7 ~9 ~30 ~7 ~9 water 0  
fill ~29 ~7 ~10 ~30 ~7 ~10 water 0  
fill ~29 ~7 ~11 ~30 ~7 ~11 water 0  
fill ~29 ~7 ~12 ~30 ~7 ~12 water 0  
fill ~29 ~7 ~16 ~29 ~8 ~16 glass 0  
fill ~29 ~7 ~17 ~31 ~7 ~17 stone_slab 8  
fill ~29 ~7 ~25 ~29 ~9 ~25 wool 9  
fill ~29 ~7 ~27 ~30 ~7 ~27 quartz_stairs 2 
setblock ~29 ~7 ~29 quartz_stairs 7  
fill ~30 ~7 ~8 ~30 ~20 ~8 water 0  
fill ~30 ~7 ~15 ~32 ~7 ~15 stone_slab 8  
fill ~30 ~7 ~16 ~32 ~7 ~16 stone_slab 8 
setblock ~30 ~7 ~20 quartz_stairs 0 
setblock ~30 ~7 ~28 quartz_stairs 1  
fill ~31 ~7 ~4 ~31 ~9 ~4 glass 0  
fill ~31 ~7 ~12 ~31 ~9 ~12 glass 0  
fill ~31 ~7 ~13 ~33 ~7 ~13 stone_slab 8  
fill ~31 ~7 ~14 ~33 ~7 ~14 stone_slab 8 
setblock ~31 ~7 ~20 quartz_stairs 2  
fill ~31 ~7 ~21 ~31 ~8 ~21 quartz_block 0  
fill ~31 ~7 ~26 ~31 ~9 ~26 wool 9  
fill ~32 ~7 ~4 ~33 ~7 ~4 stone_slab 8  
fill ~32 ~7 ~5 ~33 ~7 ~5 stone_slab 8  
fill ~32 ~7 ~6 ~33 ~7 ~6 stone_slab 8  
fill ~32 ~7 ~7 ~33 ~7 ~7 stone_slab 8  
fill ~32 ~7 ~8 ~33 ~7 ~8 stone_slab 8  
fill ~32 ~7 ~9 ~33 ~7 ~9 stone_slab 8  
fill ~32 ~7 ~10 ~33 ~7 ~10 stone_slab 8  
fill ~32 ~7 ~11 ~33 ~7 ~11 stone_slab 8  
fill ~32 ~7 ~12 ~33 ~7 ~12 stone_slab 8  
fill ~4 ~8 ~4 ~15 ~8 ~4 glass 0  
fill ~4 ~8 ~5 ~4 ~13 ~5 glass 0  
fill ~4 ~8 ~7 ~4 ~11 ~7 glass 0  
fill ~4 ~8 ~8 ~4 ~11 ~8 glass 0  
fill ~4 ~8 ~9 ~4 ~11 ~9 glass 0  
fill ~4 ~8 ~10 ~4 ~12 ~10 glass 0  
fill ~5 ~8 ~9 ~5 ~13 ~9 stonebrick 1 
setblock ~5 ~8 ~10 water 8  
fill ~5 ~8 ~13 ~5 ~10 ~13 glass 0 
setblock ~6 ~8 ~9 glass_pane 0  
fill ~6 ~8 ~10 ~10 ~8 ~10 water 0  
fill ~6 ~8 ~11 ~8 ~8 ~11 water 0  
fill ~6 ~8 ~12 ~8 ~8 ~12 water 0  
fill ~6 ~8 ~13 ~8 ~8 ~13 water 0  
fill ~6 ~8 ~15 ~6 ~10 ~15 glass 0  
fill ~7 ~8 ~9 ~7 ~13 ~9 stonebrick 1  
fill ~7 ~8 ~14 ~8 ~8 ~14 water 0  
fill ~7 ~8 ~15 ~7 ~20 ~15 water 0  
fill ~8 ~8 ~9 ~10 ~8 ~9 water 0  
fill ~8 ~8 ~18 ~8 ~10 ~18 glass 0  
fill ~9 ~8 ~7 ~10 ~8 ~7 mossy_cobblestone 0 
setblock ~9 ~8 ~11 quartz_stairs 6 
setblock ~9 ~8 ~12 quartz_block 10  
fill ~9 ~8 ~13 ~9 ~13 ~13 quartz_block 0 
setblock ~9 ~8 ~14 quartz_block 10  
fill ~9 ~8 ~15 ~9 ~13 ~15 quartz_block 0 
setblock ~9 ~8 ~16 quartz_block 10 
setblock ~9 ~8 ~17 quartz_stairs 7 
setblock ~10 ~8 ~11 quartz_block 0  
fill ~10 ~8 ~13 ~30 ~8 ~13 water 0  
fill ~10 ~8 ~14 ~29 ~8 ~14 water 0  
fill ~10 ~8 ~15 ~29 ~8 ~15 water 0 
setblock ~10 ~8 ~17 quartz_block 0  
fill ~10 ~8 ~18 ~26 ~8 ~18 water 0  
fill ~11 ~8 ~10 ~12 ~8 ~10 stonebrick 1  
fill ~11 ~8 ~11 ~11 ~13 ~11 water 0  
fill ~11 ~8 ~12 ~13 ~8 ~12 water 0  
fill ~11 ~8 ~16 ~28 ~8 ~16 water 0  
fill ~11 ~8 ~17 ~27 ~8 ~17 water 0  
fill ~11 ~8 ~19 ~20 ~8 ~19 water 0  
fill ~11 ~8 ~20 ~12 ~8 ~20 glass 0  
fill ~12 ~8 ~11 ~13 ~8 ~11 stonebrick 1 
setblock ~12 ~8 ~31 sea_lantern 0  
fill ~13 ~8 ~20 ~13 ~12 ~20 water 9  
fill ~13 ~8 ~21 ~15 ~8 ~21 glass 0 
setblock ~13 ~8 ~30 fence 2  
fill ~14 ~8 ~12 ~15 ~8 ~12 stonebrick 1  
fill ~14 ~8 ~20 ~22 ~8 ~20 water 8 
setblock ~14 ~8 ~29 sea_lantern 0  
fill ~16 ~8 ~5 ~16 ~29 ~5 ladder 3  
fill ~16 ~8 ~21 ~19 ~8 ~21 water 8  
fill ~16 ~8 ~22 ~20 ~8 ~22 glass 0  
fill ~17 ~8 ~4 ~29 ~8 ~4 glass 0  
fill ~17 ~8 ~12 ~18 ~8 ~12 stonebrick 1  
fill ~19 ~8 ~11 ~20 ~8 ~11 stonebrick 1  
fill ~19 ~8 ~12 ~30 ~8 ~12 water 0  
fill ~20 ~8 ~10 ~21 ~8 ~10 stonebrick 1  
fill ~20 ~8 ~21 ~23 ~8 ~21 glass 0  
fill ~21 ~8 ~11 ~30 ~8 ~11 water 0 
setblock ~22 ~8 ~8 mossy_cobblestone 0  
fill ~22 ~8 ~9 ~30 ~8 ~9 water 0  
fill ~22 ~8 ~10 ~30 ~8 ~10 water 0  
fill ~23 ~8 ~5 ~31 ~8 ~5 hardened_clay 0 
setblock ~23 ~8 ~6 water 1  
fill ~23 ~8 ~7 ~30 ~8 ~7 water 0  
fill ~23 ~8 ~8 ~26 ~8 ~8 water 0  
fill ~23 ~8 ~20 ~25 ~8 ~20 glass 0 
setblock ~23 ~8 ~25 quartz_stairs 4  
fill ~24 ~8 ~6 ~31 ~8 ~6 hardened_clay 0  
fill ~24 ~8 ~19 ~24 ~19 ~19 water 9 
setblock ~24 ~8 ~24 quartz_stairs 4  
fill ~24 ~8 ~25 ~25 ~8 ~25 quartz_block 0  
fill ~25 ~8 ~19 ~26 ~8 ~19 glass 0  
fill ~25 ~8 ~23 ~25 ~11 ~23 wool 9 
setblock ~25 ~8 ~24 quartz_stairs 6 
setblock ~26 ~8 ~24 quartz_stairs 2 
setblock ~26 ~8 ~25 quartz_stairs 1  
fill ~28 ~8 ~8 ~28 ~20 ~8 water 0  
fill ~28 ~8 ~18 ~28 ~10 ~18 glass 0
fill ~28 ~8 ~28 ~28 ~9 ~28 quartz_block 0  
fill ~28 ~8 ~29 ~29 ~8 ~29 quartz_block 0 
setblock ~29 ~8 ~8 leaves 15  
fill ~30 ~8 ~15 ~30 ~10 ~15 glass 0  
fill ~31 ~8 ~7 ~31 ~19 ~7 water 8  
fill ~31 ~8 ~8 ~31 ~19 ~8 water 8  
fill ~31 ~8 ~9 ~31 ~19 ~9 water 8  
fill ~31 ~8 ~10 ~31 ~19 ~10 water 8  
fill ~31 ~8 ~13 ~31 ~10 ~13 glass 0 
setblock ~31 ~8 ~22 quartz_stairs 4  
fill ~31 ~8 ~27 ~31 ~13 ~27 wool 9  
fill ~32 ~8 ~6 ~32 ~26 ~6 glass 0  
fill ~32 ~8 ~7 ~32 ~26 ~7 glass 0  
fill ~32 ~8 ~8 ~32 ~26 ~8 glass 0  
fill ~32 ~8 ~9 ~32 ~26 ~9 glass 0  
fill ~32 ~8 ~10 ~32 ~26 ~10 glass 0  
fill ~4 ~9 ~4 ~15 ~9 ~4 glass 0  
fill ~4 ~9 ~11 ~4 ~13 ~11 glass 0  
fill ~5 ~9 ~10 ~10 ~9 ~10 water 0  
fill ~5 ~9 ~11 ~8 ~9 ~11 water 0  
fill ~5 ~9 ~14 ~5 ~12 ~14 glass 0  
fill ~6 ~9 ~9 ~6 ~10 ~9 stonebrick 1  
fill ~6 ~9 ~12 ~8 ~9 ~12 water 0  
fill ~6 ~9 ~13 ~8 ~9 ~13 water 0  
fill ~6 ~9 ~14 ~8 ~9 ~14 water 0  
fill ~6 ~9 ~16 ~6 ~13 ~16 glass 0  
fill ~7 ~9 ~16 ~7 ~20 ~16 water 0  
fill ~7 ~9 ~17 ~7 ~11 ~17 glass 0  
fill ~8 ~9 ~9 ~10 ~9 ~9 water 0  
fill ~8 ~9 ~17 ~8 ~20 ~17 water 0  
fill ~9 ~9 ~7 ~10 ~9 ~7 mossy_cobblestone 0  
fill ~9 ~9 ~11 ~9 ~11 ~11 quartz_block 0  
fill ~9 ~9 ~12 ~9 ~12 ~12 quartz_block 2  
fill ~9 ~9 ~14 ~9 ~13 ~14 quartz_block 2  
fill ~9 ~9 ~16 ~9 ~12 ~16 quartz_block 2  
fill ~9 ~9 ~17 ~9 ~12 ~17 quartz_block 0  
fill ~9 ~9 ~18 ~27 ~9 ~18 water 0  
fill ~9 ~9 ~19 ~9 ~11 ~19 glass 0 
setblock ~10 ~9 ~6 glowstone 0 
setblock ~10 ~9 ~11 quartz_stairs 2  
fill ~10 ~9 ~12 ~13 ~9 ~12 water 0  
fill ~10 ~9 ~13 ~30 ~9 ~13 water 0  
fill ~10 ~9 ~14 ~30 ~9 ~14 water 0  
fill ~10 ~9 ~15 ~29 ~9 ~15 water 0  
fill ~10 ~9 ~16 ~29 ~9 ~16 water 0 
setblock ~10 ~9 ~17 quartz_stairs 3  
fill ~10 ~9 ~19 ~20 ~9 ~19 water 0  
fill ~10 ~9 ~20 ~11 ~9 ~20 glass 0  
fill ~11 ~9 ~10 ~12 ~9 ~10 stonebrick 1  
fill ~11 ~9 ~17 ~28 ~9 ~17 water 0  
fill ~12 ~9 ~11 ~13 ~9 ~11 stonebrick 1  
fill ~12 ~9 ~20 ~12 ~19 ~20 water 8  
fill ~12 ~9 ~21 ~14 ~9 ~21 glass 0 
setblock ~13 ~9 ~30 sea_lantern 0 
setblock ~14 ~9 ~6 glowstone 0  
fill ~14 ~9 ~12 ~15 ~9 ~12 stonebrick 1  
fill ~14 ~9 ~20 ~22 ~9 ~20 water 8  
fill ~15 ~9 ~21 ~20 ~9 ~21 water 8  
fill ~15 ~9 ~22 ~21 ~9 ~22 glass 0 
setblock ~16 ~9 ~8 glowstone 0 
setblock ~16 ~9 ~12 glowstone 0  
fill ~17 ~9 ~4 ~31 ~9 ~4 glass 0  
fill ~17 ~9 ~12 ~18 ~9 ~12 stonebrick 1 
setblock ~18 ~9 ~6 glowstone 0  
fill ~19 ~9 ~11 ~20 ~9 ~11 stonebrick 1  
fill ~19 ~9 ~12 ~30 ~9 ~12 water 0  
fill ~20 ~9 ~10 ~21 ~9 ~10 stonebrick 1  
fill ~21 ~9 ~11 ~30 ~9 ~11 water 0  
fill ~21 ~9 ~21 ~24 ~9 ~21 glass 0 
setblock ~22 ~9 ~6 glowstone 0  
fill ~22 ~9 ~8 ~22 ~14 ~8 stonebrick 1  
fill ~22 ~9 ~9 ~30 ~9 ~9 water 0  
fill ~22 ~9 ~10 ~30 ~9 ~10 water 0  
fill ~23 ~9 ~5 ~31 ~9 ~5 stained_hardened_clay 0  
fill ~23 ~9 ~6 ~31 ~9 ~6 stained_hardened_clay 0  
fill ~23 ~9 ~7 ~30 ~9 ~7 water 0  
fill ~23 ~9 ~8 ~30 ~9 ~8 water 0  
fill ~23 ~9 ~20 ~23 ~19 ~20 water 9  
fill ~23 ~9 ~25 ~24 ~9 ~25 quartz_block 0  
fill ~24 ~9 ~20 ~26 ~9 ~20 glass 0 
setblock ~24 ~9 ~23 wool 9 
setblock ~24 ~9 ~24 quartz_stairs 0 
setblock ~24 ~9 ~26 quartz_stairs 7  
fill ~24 ~9 ~29 ~24 ~10 ~29 wool 9  
fill ~25 ~9 ~19 ~25 ~19 ~19 water 8 
setblock ~25 ~9 ~24 quartz_stairs 2 
setblock ~25 ~9 ~25 quartz_stairs 1  
fill ~26 ~9 ~19 ~27 ~9 ~19 glass 0  
fill ~28 ~9 ~29 ~29 ~9 ~29 quartz_block 0  
fill ~29 ~9 ~17 ~29 ~11 ~17 glass 0  
fill ~30 ~9 ~16 ~30 ~13 ~16 glass 0  
fill ~31 ~9 ~11 ~31 ~19 ~11 water 8  
fill ~31 ~9 ~14 ~31 ~12 ~14 glass 0 
setblock ~31 ~9 ~21 quartz_stairs 2 
setblock ~31 ~9 ~22 quartz_block 0 
setblock ~31 ~9 ~23 quartz_stairs 7  
fill ~31 ~9 ~28 ~31 ~13 ~28 wool 9  
fill ~32 ~9 ~5 ~32 ~25 ~5 glass 0  
fill ~32 ~9 ~11 ~32 ~25 ~11 glass 0  
fill ~4 ~10 ~4 ~15 ~10 ~4 glass 0  
fill ~4 ~10 ~6 ~4 ~12 ~6 glass 0  
fill ~4 ~10 ~12 ~4 ~24 ~12 glass 0  
fill ~5 ~10 ~10 ~8 ~10 ~10 water 0  
fill ~5 ~10 ~11 ~8 ~10 ~11 water 0  
fill ~5 ~10 ~12 ~8 ~10 ~12 water 0  
fill ~6 ~10 ~13 ~8 ~10 ~13 water 0  
fill ~6 ~10 ~14 ~8 ~10 ~14 water 0  
fill ~8 ~10 ~9 ~10 ~10 ~9 water 0  
fill ~9 ~10 ~7 ~10 ~10 ~7 stonebrick 1 
setblock ~9 ~10 ~10 quartz_stairs 6 
setblock ~9 ~10 ~18 quartz_stairs 7  
fill ~10 ~10 ~6 ~10 ~17 ~6 stonebrick 1 
setblock ~10 ~10 ~10 water 0 
setblock ~10 ~10 ~11 quartz_stairs 6  
fill ~10 ~10 ~12 ~13 ~10 ~12 water 0  
fill ~10 ~10 ~13 ~30 ~10 ~13 water 0  
fill ~10 ~10 ~14 ~30 ~10 ~14 water 0  
fill ~10 ~10 ~15 ~29 ~10 ~15 water 0  
fill ~10 ~10 ~16 ~29 ~10 ~16 water 0 
setblock ~10 ~10 ~17 quartz_stairs 7  
fill ~10 ~10 ~18 ~27 ~10 ~18 water 0  
fill ~10 ~10 ~19 ~20 ~10 ~19 water 0  
fill ~10 ~10 ~20 ~11 ~10 ~20 glass 0  
fill ~11 ~10 ~10 ~12 ~10 ~10 stonebrick 1  
fill ~11 ~10 ~17 ~28 ~10 ~17 water 0  
fill ~12 ~10 ~11 ~13 ~10 ~11 stonebrick 1  
fill ~12 ~10 ~21 ~13 ~10 ~21 glass 0  
fill ~14 ~10 ~6 ~14 ~19 ~6 stonebrick 1  
fill ~14 ~10 ~12 ~18 ~10 ~12 stonebrick 1  
fill ~14 ~10 ~20 ~22 ~10 ~20 water 8  
fill ~14 ~10 ~21 ~21 ~10 ~21 water 8  
fill ~14 ~10 ~22 ~22 ~10 ~22 glass 0  
fill ~16 ~10 ~8 ~16 ~13 ~8 stonebrick 1  
fill ~17 ~10 ~4 ~30 ~10 ~4 glass 0  
fill ~18 ~10 ~6 ~18 ~14 ~6 stonebrick 1  
fill ~19 ~10 ~11 ~20 ~10 ~11 stonebrick 1  
fill ~19 ~10 ~12 ~30 ~10 ~12 water 0  
fill ~20 ~10 ~10 ~21 ~10 ~10 stonebrick 1  
fill ~21 ~10 ~11 ~30 ~10 ~11 water 0  
fill ~22 ~10 ~6 ~22 ~14 ~6 stonebrick 1  
fill ~22 ~10 ~9 ~30 ~10 ~9 water 0  
fill ~22 ~10 ~10 ~30 ~10 ~10 water 0  
fill ~22 ~10 ~21 ~24 ~10 ~21 glass 0  
fill ~23 ~10 ~5 ~31 ~10 ~5 stained_hardened_clay 8  
fill ~23 ~10 ~6 ~31 ~10 ~6 stained_hardened_clay 8  
fill ~23 ~10 ~7 ~30 ~10 ~7 water 0  
fill ~23 ~10 ~8 ~30 ~10 ~8 water 0 
setblock ~23 ~10 ~25 quartz_stairs 0  
fill ~24 ~10 ~20 ~26 ~10 ~20 glass 0  
fill ~24 ~10 ~24 ~24 ~11 ~24 wool 9  
fill ~24 ~10 ~25 ~25 ~10 ~25 quartz_block 0 
setblock ~24 ~10 ~26 quartz_stairs 3  
fill ~25 ~10 ~24 ~26 ~10 ~24 quartz_stairs 6 
setblock ~25 ~10 ~26 quartz_stairs 7  
fill ~25 ~10 ~29 ~26 ~10 ~29 wool 9  
fill ~26 ~10 ~19 ~27 ~10 ~19 glass 0 
setblock ~26 ~10 ~25 quartz_stairs 5  
fill ~26 ~10 ~28 ~26 ~11 ~28 wool 9  
fill ~27 ~10 ~30 ~27 ~11 ~30 wool 9  
fill ~28 ~10 ~28 ~28 ~10 ~29 quartz_stairs 0  
fill ~29 ~10 ~23 ~29 ~13 ~23 wool 9 
setblock ~29 ~10 ~29 quartz_stairs 3 
setblock ~30 ~10 ~24 quartz_stairs 7  
fill ~30 ~10 ~26 ~30 ~11 ~26 wool 9  
fill ~31 ~10 ~12 ~31 ~19 ~12 water 8 
setblock ~31 ~10 ~22 quartz_stairs 2 
setblock ~31 ~10 ~23 quartz_block 0  
fill ~31 ~10 ~25 ~31 ~13 ~25 wool 9  
fill ~32 ~10 ~4 ~32 ~24 ~4 glass 0  
fill ~32 ~10 ~12 ~32 ~24 ~12 glass 0  
fill ~4 ~11 ~4 ~15 ~11 ~4 glass 0  
fill ~4 ~11 ~13 ~4 ~23 ~13 glass 0  
fill ~5 ~11 ~10 ~8 ~11 ~10 water 0  
fill ~5 ~11 ~11 ~8 ~11 ~11 water 0  
fill ~5 ~11 ~12 ~8 ~11 ~12 water 0  
fill ~5 ~11 ~13 ~8 ~11 ~13 water 0  
fill ~5 ~11 ~15 ~5 ~23 ~15 glass 0 
setblock ~6 ~11 ~9 glass_pane 0  
fill ~6 ~11 ~14 ~8 ~11 ~14 water 0  
fill ~6 ~11 ~15 ~6 ~20 ~15 water 0  
fill ~7 ~11 ~18 ~7 ~23 ~18 glass 0  
fill ~8 ~11 ~9 ~10 ~11 ~9 water 0  
fill ~8 ~11 ~18 ~8 ~20 ~18 water 0  
fill ~8 ~11 ~19 ~8 ~23 ~19 glass 0  
fill ~9 ~11 ~7 ~10 ~11 ~7 stonebrick 1 
setblock ~9 ~11 ~10 quartz_block 2 
setblock ~9 ~11 ~18 quartz_block 2 
setblock ~10 ~11 ~10 quartz_stairs 6 
setblock ~10 ~11 ~11 quartz_block 0  
fill ~10 ~11 ~12 ~13 ~11 ~12 water 0  
fill ~10 ~11 ~13 ~30 ~11 ~13 water 0  
fill ~10 ~11 ~14 ~30 ~11 ~14 water 0  
fill ~10 ~11 ~15 ~30 ~11 ~15 water 0  
fill ~10 ~11 ~16 ~29 ~11 ~16 water 0 
setblock ~10 ~11 ~17 quartz_block 0 
setblock ~10 ~11 ~18 quartz_stairs 7  
fill ~10 ~11 ~19 ~20 ~11 ~19 water 0  
fill ~10 ~11 ~20 ~10 ~13 ~20 glass 0  
fill ~11 ~11 ~10 ~12 ~11 ~10 stonebrick 1  
fill ~11 ~11 ~17 ~28 ~11 ~17 water 0  
fill ~11 ~11 ~18 ~28 ~11 ~18 water 0  
fill ~11 ~11 ~20 ~11 ~19 ~20 water 8  
fill ~11 ~11 ~21 ~12 ~11 ~21 glass 0  
fill ~12 ~11 ~11 ~13 ~11 ~11 stonebrick 1  
fill ~13 ~11 ~21 ~22 ~11 ~21 water 8  
fill ~13 ~11 ~22 ~23 ~11 ~22 glass 0  
fill ~14 ~11 ~12 ~18 ~11 ~12 stonebrick 1  
fill ~14 ~11 ~20 ~22 ~11 ~20 water 8  
fill ~17 ~11 ~4 ~30 ~11 ~4 glass 0  
fill ~19 ~11 ~11 ~20 ~11 ~11 stonebrick 1  
fill ~19 ~11 ~12 ~30 ~11 ~12 water 0  
fill ~20 ~11 ~10 ~21 ~11 ~10 stonebrick 1  
fill ~21 ~11 ~11 ~30 ~11 ~11 water 0  
fill ~22 ~11 ~9 ~30 ~11 ~9 water 0  
fill ~22 ~11 ~10 ~30 ~11 ~10 water 0  
fill ~23 ~11 ~5 ~31 ~11 ~5 hardened_clay 0  
fill ~23 ~11 ~6 ~31 ~11 ~6 hardened_clay 0  
fill ~23 ~11 ~7 ~30 ~11 ~7 water 0  
fill ~23 ~11 ~8 ~30 ~11 ~8 water 0  
fill ~23 ~11 ~21 ~25 ~11 ~21 glass 0  
fill ~24 ~11 ~20 ~24 ~18 ~20 water 8 
setblock ~24 ~11 ~25 quartz_stairs 0  
fill ~24 ~11 ~28 ~27 ~11 ~28 wool 9  
fill ~25 ~11 ~20 ~26 ~11 ~20 glass 0 
setblock ~25 ~11 ~24 quartz_stairs 0  
fill ~25 ~11 ~25 ~26 ~11 ~25 quartz_block 0 
setblock ~25 ~11 ~26 quartz_stairs 3  
fill ~25 ~11 ~29 ~27 ~11 ~29 wool 9  
fill ~26 ~11 ~19 ~28 ~11 ~19 glass 0  
fill ~26 ~11 ~24 ~26 ~13 ~24 quartz_block 0 
setblock ~26 ~11 ~26 quartz_stairs 5 
setblock ~26 ~11 ~27 wool 9 
setblock ~27 ~11 ~24 quartz_stairs 6 
setblock ~27 ~11 ~25 quartz_stairs 5 
setblock ~27 ~11 ~26 quartz_stairs 7  
fill ~28 ~11 ~23 ~28 ~13 ~23 wool 9  
fill ~28 ~11 ~28 ~29 ~11 ~28 quartz_stairs 4  
fill ~28 ~11 ~29 ~30 ~11 ~29 quartz_stairs 7  
fill ~28 ~11 ~30 ~30 ~11 ~30 wool 9  
fill ~29 ~11 ~18 ~29 ~23 ~18 glass 0  
fill ~29 ~11 ~27 ~30 ~11 ~27 quartz_stairs 6  
fill ~30 ~11 ~23 ~30 ~12 ~23 wool 9  
fill ~30 ~11 ~24 ~30 ~12 ~24 quartz_block 0 
setblock ~30 ~11 ~28 quartz_stairs 5  
fill ~31 ~11 ~13 ~31 ~19 ~13 water 8  
fill ~31 ~11 ~15 ~31 ~23 ~15 glass 0 
setblock ~31 ~11 ~23 quartz_stairs 1  
fill ~31 ~11 ~24 ~31 ~12 ~24 wool 9  
fill ~31 ~11 ~29 ~31 ~12 ~29 wool 9  
fill ~32 ~11 ~13 ~32 ~23 ~13 glass 0  
fill ~3 ~12 ~7 ~3 ~22 ~7 glass 0  
fill ~3 ~12 ~8 ~3 ~22 ~8 glass 0  
fill ~3 ~12 ~9 ~3 ~22 ~9 glass 0  
fill ~4 ~12 ~4 ~15 ~12 ~4 glass 0  
fill ~4 ~12 ~9 ~4 ~14 ~9 stonebrick 1  
fill ~5 ~12 ~10 ~8 ~12 ~10 water 0  
fill ~5 ~12 ~11 ~8 ~12 ~11 water 0  
fill ~5 ~12 ~12 ~8 ~12 ~12 water 0  
fill ~5 ~12 ~13 ~8 ~12 ~13 water 0  
fill ~6 ~12 ~9 ~6 ~13 ~9 stonebrick 1  
fill ~6 ~12 ~14 ~8 ~12 ~14 water 0  
fill ~6 ~12 ~17 ~6 ~22 ~17 glass 0  
fill ~7 ~12 ~17 ~7 ~20 ~17 water 0  
fill ~8 ~12 ~9 ~10 ~12 ~9 water 0  
fill ~9 ~12 ~7 ~10 ~12 ~7 stonebrick 1 
setblock ~9 ~12 ~10 quartz_stairs 3 
setblock ~9 ~12 ~11 quartz_stairs 2 
setblock ~9 ~12 ~18 quartz_stairs 2  
fill ~9 ~12 ~19 ~20 ~12 ~19 water 0  
fill ~9 ~12 ~20 ~9 ~22 ~20 glass 0 
setblock ~10 ~12 ~10 quartz_stairs 2 
setblock ~10 ~12 ~11 quartz_stairs 3  
fill ~10 ~12 ~12 ~13 ~12 ~12 water 0  
fill ~10 ~12 ~13 ~30 ~12 ~13 water 0  
fill ~10 ~12 ~14 ~30 ~12 ~14 water 0  
fill ~10 ~12 ~15 ~30 ~12 ~15 water 0  
fill ~10 ~12 ~16 ~29 ~12 ~16 water 0 
setblock ~10 ~12 ~17 quartz_stairs 2 
setblock ~10 ~12 ~18 quartz_stairs 3  
fill ~11 ~12 ~10 ~12 ~12 ~10 stonebrick 1  
fill ~11 ~12 ~17 ~29 ~12 ~17 water 0  
fill ~11 ~12 ~18 ~28 ~12 ~18 water 0  
fill ~11 ~12 ~21 ~12 ~12 ~21 glass 0  
fill ~12 ~12 ~11 ~13 ~12 ~11 stonebrick 1  
fill ~13 ~12 ~21 ~22 ~12 ~21 water 8  
fill ~13 ~12 ~22 ~16 ~12 ~22 glass 0  
fill ~14 ~12 ~12 ~18 ~12 ~12 stonebrick 1  
fill ~14 ~12 ~20 ~22 ~12 ~20 water 8  
fill ~17 ~12 ~4 ~30 ~12 ~4 glass 0  
fill ~17 ~12 ~22 ~18 ~12 ~22 water 8  
fill ~17 ~12 ~23 ~19 ~12 ~23 glass 0  
fill ~19 ~12 ~11 ~20 ~12 ~11 stonebrick 1  
fill ~19 ~12 ~12 ~30 ~12 ~12 water 0  
fill ~19 ~12 ~22 ~23 ~12 ~22 glass 0  
fill ~20 ~12 ~10 ~21 ~12 ~10 stonebrick 1  
fill ~21 ~12 ~11 ~30 ~12 ~11 water 0  
fill ~22 ~12 ~9 ~30 ~12 ~9 water 0  
fill ~22 ~12 ~10 ~30 ~12 ~10 water 0  
fill ~23 ~12 ~5 ~31 ~12 ~5 hardened_clay 0  
fill ~23 ~12 ~6 ~31 ~12 ~6 hardened_clay 0  
fill ~23 ~12 ~7 ~30 ~12 ~7 water 0  
fill ~23 ~12 ~8 ~30 ~12 ~8 water 0  
fill ~23 ~12 ~21 ~25 ~12 ~21 glass 0  
fill ~24 ~12 ~25 ~24 ~12 ~27 wool 9  
fill ~25 ~12 ~20 ~27 ~12 ~20 glass 0 
setblock ~25 ~12 ~24 wool 9 
setblock ~25 ~12 ~25 quartz_stairs 0  
fill ~25 ~12 ~26 ~25 ~13 ~26 wool 9  
fill ~25 ~12 ~27 ~25 ~13 ~27 wool 9  
fill ~25 ~12 ~28 ~25 ~12 ~26 wool 9  
fill ~26 ~12 ~19 ~26 ~18 ~19 water 8  
fill ~26 ~12 ~25 ~27 ~12 ~25 quartz_block 0  
fill ~26 ~12 ~26 ~27 ~12 ~26 quartz_block 0 
setblock ~26 ~12 ~27 quartz_stairs 4 
setblock ~26 ~12 ~28 red_sandstone_stairs 4  
fill ~26 ~12 ~29 ~27 ~12 ~29 wool 9  
fill ~27 ~12 ~19 ~28 ~12 ~19 glass 0  
fill ~27 ~12 ~23 ~27 ~13 ~23 wool 9  
fill ~27 ~12 ~24 ~27 ~13 ~24 quartz_block 0 
setblock ~27 ~12 ~28 quartz_stairs 7 
setblock ~28 ~12 ~24 quartz_stairs 6  
fill ~28 ~12 ~25 ~28 ~12 ~26 quartz_stairs 5  
fill ~28 ~12 ~27 ~30 ~12 ~27 quartz_block 0  
fill ~28 ~12 ~28 ~28 ~14 ~28 quartz_block 0  
fill ~28 ~12 ~29 ~30 ~12 ~29 quartz_block 0  
fill ~28 ~12 ~30 ~30 ~12 ~30 wool 9 
setblock ~29 ~12 ~25 quartz_stairs 7 
setblock ~29 ~12 ~26 quartz_stairs 6  
fill ~30 ~12 ~17 ~30 ~22 ~17 glass 0 
setblock ~30 ~12 ~26 quartz_stairs 5  
fill ~30 ~12 ~28 ~30 ~13 ~28 quartz_block 0  
fill ~31 ~12 ~26 ~31 ~13 ~26 wool 9  
fill ~3 ~13 ~6 ~3 ~21 ~6 glass 0  
fill ~3 ~13 ~10 ~3 ~21 ~10 glass 0  
fill ~4 ~13 ~4 ~15 ~13 ~4 glass 0 
setblock ~4 ~13 ~10 water 1  
fill ~4 ~13 ~14 ~4 ~21 ~14 glass 0  
fill ~5 ~13 ~6 ~9 ~13 ~6 stone_slab 8  
fill ~5 ~13 ~7 ~8 ~13 ~7 stone_slab 8  
fill ~5 ~13 ~8 ~7 ~13 ~8 stone_slab 8  
fill ~5 ~13 ~10 ~10 ~13 ~10 water 0  
fill ~5 ~13 ~11 ~11 ~13 ~11 water 0  
fill ~5 ~13 ~12 ~8 ~13 ~12 water 0  
fill ~5 ~13 ~13 ~8 ~13 ~13 water 0  
fill ~5 ~13 ~14 ~8 ~13 ~14 water 0  
fill ~8 ~13 ~9 ~9 ~13 ~9 stonebrick 1  
fill ~9 ~13 ~7 ~14 ~13 ~7 stonebrick 1  
fill ~9 ~13 ~8 ~9 ~13 ~7 stonebrick 1 
setblock ~9 ~13 ~12 quartz_stairs 3 
setblock ~9 ~13 ~16 quartz_stairs 2  
fill ~9 ~13 ~17 ~29 ~13 ~17 water 0  
fill ~9 ~13 ~18 ~28 ~13 ~18 water 0  
fill ~9 ~13 ~19 ~20 ~13 ~19 water 0 
setblock ~10 ~13 ~9 water 0  
fill ~10 ~13 ~12 ~13 ~13 ~12 water 0  
fill ~10 ~13 ~13 ~30 ~13 ~13 water 0  
fill ~10 ~13 ~14 ~30 ~13 ~14 water 0  
fill ~10 ~13 ~15 ~30 ~13 ~15 water 0  
fill ~10 ~13 ~16 ~29 ~13 ~16 water 0  
fill ~11 ~13 ~5 ~14 ~13 ~5 stonebrick 1  
fill ~11 ~13 ~6 ~14 ~13 ~6 stonebrick 1  
fill ~11 ~13 ~8 ~22 ~13 ~8 stonebrick 1  
fill ~11 ~13 ~10 ~21 ~13 ~10 stonebrick 1  
fill ~11 ~13 ~21 ~11 ~23 ~21 glass 0  
fill ~12 ~13 ~9 ~21 ~13 ~9 stonebrick 1  
fill ~12 ~13 ~11 ~20 ~13 ~11 stonebrick 1  
fill ~12 ~13 ~21 ~23 ~13 ~21 water 8  
fill ~12 ~13 ~22 ~15 ~13 ~22 glass 0 
setblock ~13 ~13 ~20 water 1  
fill ~14 ~13 ~12 ~18 ~13 ~12 stonebrick 1  
fill ~14 ~13 ~20 ~22 ~13 ~20 water 8  
fill ~15 ~13 ~5 ~15 ~13 ~7 stone_slab 0  
fill ~16 ~13 ~6 ~17 ~13 ~6 stone_slab 0  
fill ~16 ~13 ~7 ~17 ~13 ~7 stone_slab 0  
fill ~16 ~13 ~22 ~19 ~13 ~22 water 8  
fill ~16 ~13 ~23 ~20 ~13 ~23 glass 0  
fill ~17 ~13 ~4 ~32 ~13 ~4 glass 0 
setblock ~17 ~13 ~5 stone_slab 0  
fill ~19 ~13 ~5 ~22 ~13 ~5 stonebrick 1  
fill ~19 ~13 ~6 ~22 ~13 ~6 stonebrick 1  
fill ~19 ~13 ~7 ~22 ~13 ~7 stonebrick 1  
fill ~19 ~13 ~12 ~30 ~13 ~12 water 0  
fill ~20 ~13 ~22 ~24 ~13 ~22 glass 0  
fill ~21 ~13 ~11 ~30 ~13 ~11 water 0  
fill ~22 ~13 ~9 ~30 ~13 ~9 water 0  
fill ~22 ~13 ~10 ~30 ~13 ~10 water 0  
fill ~23 ~13 ~5 ~31 ~13 ~5 hardened_clay 0  
fill ~23 ~13 ~6 ~31 ~13 ~6 hardened_clay 0  
fill ~23 ~13 ~7 ~30 ~13 ~7 water 0  
fill ~23 ~13 ~8 ~30 ~13 ~8 water 0  
fill ~24 ~13 ~21 ~25 ~13 ~21 glass 0  
fill ~25 ~13 ~20 ~27 ~13 ~20 glass 0 
setblock ~25 ~13 ~25 wool 9  
fill ~26 ~13 ~25 ~29 ~13 ~25 quartz_block 0  
fill ~26 ~13 ~26 ~30 ~13 ~26 quartz_block 0  
fill ~26 ~13 ~27 ~26 ~14 ~27 quartz_block 0  
fill ~26 ~13 ~28 ~30 ~13 ~28 quartz_block 0  
fill ~27 ~13 ~19 ~28 ~13 ~19 glass 0 
setblock ~27 ~13 ~27 dispenser 0 
setblock ~28 ~13 ~24 quartz_block 0  
fill ~28 ~13 ~27 ~30 ~13 ~27 quartz_block 0  
fill ~28 ~13 ~29 ~30 ~13 ~29 quartz_block 0 
setblock ~29 ~13 ~24 quartz_stairs 6 
setblock ~30 ~13 ~24 quartz_stairs 1 
setblock ~30 ~13 ~25 quartz_stairs 5  
fill ~31 ~13 ~14 ~31 ~19 ~14 water 8  
fill ~32 ~13 ~14 ~32 ~21 ~14 glass 0  
fill ~3 ~14 ~5 ~3 ~20 ~5 glass 0  
fill ~3 ~14 ~11 ~3 ~20 ~11 glass 0  
fill ~4 ~14 ~4 ~15 ~14 ~4 glass 0  
fill ~4 ~14 ~5 ~10 ~14 ~5 stonebrick 1  
fill ~4 ~14 ~6 ~4 ~14 ~9 stonebrick 1 
setblock ~4 ~14 ~10 log 11  
fill ~4 ~14 ~11 ~4 ~19 ~11 water 8  
fill ~5 ~14 ~10 ~6 ~14 ~10 log 7  
fill ~5 ~14 ~11 ~10 ~14 ~11 water 0  
fill ~5 ~14 ~12 ~11 ~14 ~12 water 0  
fill ~5 ~14 ~13 ~8 ~14 ~13 water 0  
fill ~5 ~14 ~14 ~30 ~14 ~14 water 0  
fill ~5 ~14 ~16 ~5 ~20 ~16 glass 0  
fill ~6 ~14 ~16 ~6 ~20 ~16 water 0 
setblock ~7 ~14 ~9 stone_button 4 
setblock ~7 ~14 ~10 dispenser 3  
fill ~8 ~14 ~10 ~9 ~14 ~10 log 7 
setblock ~9 ~14 ~13 quartz_stairs 3 
setblock ~9 ~14 ~15 quartz_stairs 2  
fill ~9 ~14 ~16 ~30 ~14 ~16 water 0  
fill ~9 ~14 ~17 ~12 ~14 ~17 water 0  
fill ~9 ~14 ~18 ~11 ~14 ~18 water 0  
fill ~9 ~14 ~19 ~11 ~14 ~19 water 0  
fill ~10 ~14 ~7 ~10 ~17 ~7 stonebrick 1  
fill ~10 ~14 ~9 ~10 ~17 ~9 stonebrick 1 
setblock ~10 ~14 ~10 log 11  
fill ~10 ~14 ~13 ~13 ~14 ~13 water 0  
fill ~10 ~14 ~15 ~30 ~14 ~15 water 0  
fill ~10 ~14 ~20 ~10 ~19 ~20 water 8  
fill ~10 ~14 ~21 ~10 ~20 ~21 glass 0  
fill ~11 ~14 ~5 ~13 ~14 ~5 hardened_clay 0  
fill ~11 ~14 ~6 ~13 ~14 ~6 hardened_clay 0  
fill ~11 ~14 ~7 ~13 ~14 ~7 water 0  
fill ~11 ~14 ~8 ~14 ~14 ~8 water 0  
fill ~11 ~14 ~9 ~20 ~14 ~9 water 0  
fill ~11 ~14 ~10 ~12 ~14 ~10 stonebrick 1 
setblock ~11 ~14 ~11 log 3  
fill ~12 ~14 ~11 ~13 ~14 ~11 stonebrick 1  
fill ~12 ~14 ~12 ~13 ~14 ~12 log 7 
setblock ~12 ~14 ~18 birch_fence_gate 7  
fill ~12 ~14 ~21 ~23 ~14 ~21 water 8  
fill ~12 ~14 ~22 ~14 ~14 ~22 glass 0  
fill ~13 ~14 ~10 ~19 ~14 ~10 water 0 
setblock ~13 ~14 ~17 red_sandstone_stairs 2 
setblock ~13 ~14 ~18 sandstone_stairs 0 
setblock ~13 ~14 ~19 red_sandstone_stairs 7  
fill ~14 ~14 ~11 ~18 ~14 ~11 water 0  
fill ~14 ~14 ~12 ~18 ~14 ~12 stonebrick 1 
setblock ~14 ~14 ~13 log 11  
fill ~14 ~14 ~17 ~29 ~14 ~17 water 0 
setblock ~14 ~14 ~18 birch_fence_gate 5  
fill ~14 ~14 ~20 ~22 ~14 ~20 water 8  
fill ~15 ~14 ~13 ~17 ~14 ~13 log 7  
fill ~15 ~14 ~18 ~28 ~14 ~18 water 0  
fill ~15 ~14 ~19 ~20 ~14 ~19 water 0  
fill ~15 ~14 ~22 ~15 ~19 ~22 water 9  
fill ~15 ~14 ~23 ~21 ~14 ~23 glass 0  
fill ~16 ~14 ~22 ~20 ~14 ~22 water 8  
fill ~17 ~14 ~4 ~32 ~14 ~4 glass 0  
fill ~18 ~14 ~8 ~21 ~14 ~8 water 0 
setblock ~18 ~14 ~13 log 11  
fill ~19 ~14 ~5 ~21 ~14 ~5 hardened_clay 0  
fill ~19 ~14 ~6 ~21 ~14 ~6 hardened_clay 0  
fill ~19 ~14 ~7 ~21 ~14 ~7 water 0  
fill ~19 ~14 ~11 ~20 ~14 ~11 stonebrick 1  
fill ~19 ~14 ~12 ~20 ~14 ~12 log 7  
fill ~19 ~14 ~13 ~30 ~14 ~13 water 0  
fill ~20 ~14 ~10 ~21 ~14 ~10 stonebrick 1 
setblock ~21 ~14 ~11 log 3  
fill ~21 ~14 ~12 ~30 ~14 ~12 water 0  
fill ~21 ~14 ~22 ~24 ~14 ~22 glass 0  
fill ~22 ~14 ~9 ~22 ~14 ~10 log 11  
fill ~22 ~14 ~11 ~30 ~14 ~11 water 0  
fill ~23 ~14 ~5 ~31 ~14 ~5 hardened_clay 0  
fill ~23 ~14 ~6 ~31 ~14 ~6 hardened_clay 0  
fill ~23 ~14 ~7 ~23 ~14 ~8 log 11  
fill ~23 ~14 ~9 ~30 ~14 ~9 water 0  
fill ~23 ~14 ~10 ~30 ~14 ~10 water 0  
fill ~24 ~14 ~7 ~30 ~14 ~7 water 0  
fill ~24 ~14 ~8 ~30 ~14 ~8 water 0  
fill ~24 ~14 ~21 ~26 ~14 ~21 glass 0 
setblock ~24 ~14 ~31 quartz_stairs 4  
fill ~25 ~14 ~20 ~25 ~18 ~20 water 8 
setblock ~25 ~14 ~32 quartz_stairs 7  
fill ~26 ~14 ~20 ~27 ~14 ~20 glass 0  
fill ~26 ~14 ~24 ~26 ~14 ~25 quartz_stairs 0  
fill ~26 ~14 ~26 ~26 ~12 ~26 quartz_block 0 
setblock ~26 ~14 ~28 quartz_stairs 3 
setblock ~26 ~14 ~31 quartz_stairs 6  
fill ~27 ~14 ~19 ~28 ~14 ~19 glass 0  
fill ~27 ~14 ~24 ~28 ~14 ~24 quartz_stairs 2 
setblock ~27 ~14 ~25 quartz_block 0 
setblock ~27 ~14 ~26 wooden_button 5 
setblock ~27 ~14 ~27 stone_button 5 
setblock ~27 ~14 ~28 quartz_block 0 
setblock ~27 ~14 ~31 stone_brick_stairs 6 
setblock ~28 ~14 ~27 wooden_button 5 
setblock ~28 ~14 ~29 quartz_stairs 0 
setblock ~29 ~14 ~24 quartz_stairs 1 
setblock ~29 ~14 ~25 quartz_stairs 2  
fill ~29 ~14 ~27 ~29 ~14 ~28 quartz_block 0 
setblock ~29 ~14 ~29 quartz_stairs 3  
fill ~30 ~14 ~24 ~30 ~22 ~24 prismarine 2  
fill ~30 ~14 ~25 ~30 ~14 ~28 quartz_stairs 1  
fill ~31 ~14 ~16 ~31 ~20 ~16 glass 0  
fill ~4 ~15 ~4 ~15 ~15 ~4 glass 0  
fill ~4 ~15 ~10 ~5 ~15 ~10 stonebrick 1  
fill ~5 ~15 ~11 ~10 ~15 ~11 water 0  
fill ~5 ~15 ~12 ~30 ~15 ~12 water 0  
fill ~5 ~15 ~13 ~15 ~15 ~13 water 0  
fill ~5 ~15 ~14 ~30 ~15 ~14 water 0  
fill ~6 ~15 ~10 ~8 ~15 ~10 glass_pane 0  
fill ~9 ~15 ~10 ~10 ~15 ~10 stonebrick 1  
fill ~9 ~15 ~15 ~30 ~15 ~15 water 0  
fill ~9 ~15 ~16 ~30 ~15 ~16 water 0  
fill ~9 ~15 ~17 ~29 ~15 ~17 water 0  
fill ~9 ~15 ~18 ~28 ~15 ~18 water 0  
fill ~9 ~15 ~19 ~11 ~15 ~19 water 0  
fill ~11 ~15 ~5 ~13 ~15 ~5 stained_hardened_clay 1  
fill ~11 ~15 ~6 ~13 ~15 ~6 stained_hardened_clay 1  
fill ~11 ~15 ~7 ~13 ~15 ~7 water 0  
fill ~11 ~15 ~8 ~14 ~15 ~8 water 0  
fill ~11 ~15 ~9 ~30 ~15 ~9 water 0  
fill ~11 ~15 ~10 ~30 ~15 ~10 water 0 
setblock ~11 ~15 ~11 glowstone 0  
fill ~12 ~15 ~11 ~20 ~15 ~11 water 0 
setblock ~12 ~15 ~19 birch_fence_gate 7  
fill ~12 ~15 ~21 ~23 ~15 ~21 water 8  
fill ~12 ~15 ~22 ~14 ~15 ~22 glass 0 
setblock ~13 ~15 ~19 sandstone_stairs 6 
setblock ~13 ~15 ~20 red_sandstone_stairs 7 
setblock ~14 ~15 ~19 birch_fence_gate 5  
fill ~14 ~15 ~20 ~22 ~15 ~20 water 8  
fill ~15 ~15 ~19 ~20 ~15 ~19 water 0  
fill ~15 ~15 ~23 ~21 ~15 ~23 glass 0 
setblock ~16 ~15 ~13 glowstone 0  
fill ~16 ~15 ~22 ~20 ~15 ~22 water 8  
fill ~17 ~15 ~4 ~32 ~15 ~4 glass 0 
setblock ~17 ~15 ~6 stone_button 2  
fill ~17 ~15 ~13 ~30 ~15 ~13 water 0 
setblock ~18 ~15 ~6 mossy_cobblestone 0  
fill ~18 ~15 ~8 ~30 ~15 ~8 water 0  
fill ~19 ~15 ~5 ~31 ~15 ~5 stained_hardened_clay 1 
setblock ~19 ~15 ~6 dispenser 3  
fill ~19 ~15 ~7 ~30 ~15 ~7 water 0  
fill ~19 ~15 ~26 ~19 ~18 ~26 obsidian 0  
fill ~20 ~15 ~6 ~31 ~15 ~6 stained_hardened_clay 1 
setblock ~21 ~15 ~11 glowstone 0  
fill ~21 ~15 ~22 ~24 ~15 ~22 glass 0  
fill ~22 ~15 ~11 ~30 ~15 ~11 water 0  
fill ~24 ~15 ~21 ~26 ~15 ~21 glass 0  
fill ~24 ~15 ~31 ~24 ~15 ~32 quartz_stairs 0 
setblock ~25 ~15 ~31 quartz_stairs 4 
setblock ~25 ~15 ~32 quartz_stairs 3  
fill ~26 ~15 ~20 ~27 ~15 ~20 glass 0  
fill ~26 ~15 ~27 ~26 ~15 ~28 quartz_stairs 0 
setblock ~26 ~15 ~31 quartz_stairs 1  
fill ~27 ~15 ~19 ~28 ~15 ~19 glass 0  
fill ~27 ~15 ~25 ~28 ~15 ~25 quartz_stairs 2  
fill ~27 ~15 ~26 ~27 ~19 ~26 quartz_block 0  
fill ~27 ~15 ~28 ~29 ~15 ~28 quartz_stairs 3 
setblock ~27 ~15 ~31 stone_brick_stairs 2  
fill ~28 ~15 ~26 ~28 ~19 ~26 prismarine 2  
fill ~28 ~15 ~27 ~28 ~19 ~27 quartz_block 0  
fill ~29 ~15 ~26 ~29 ~15 ~27 quartz_stairs 1  
fill ~31 ~15 ~23 ~31 ~20 ~23 wool 3  
fill ~34 ~15 ~20 ~34 ~18 ~20 prismarine 2  
fill ~4 ~16 ~4 ~15 ~16 ~4 glass 0  
fill ~4 ~16 ~10 ~5 ~16 ~10 stonebrick 1  
fill ~5 ~16 ~11 ~30 ~16 ~11 water 0  
fill ~5 ~16 ~12 ~30 ~16 ~12 water 0  
fill ~5 ~16 ~13 ~30 ~16 ~13 water 0  
fill ~5 ~16 ~14 ~30 ~16 ~14 water 0  
fill ~6 ~16 ~10 ~8 ~16 ~10 glass_pane 0  
fill ~9 ~16 ~10 ~10 ~16 ~10 stonebrick 1  
fill ~9 ~16 ~15 ~30 ~16 ~15 water 0  
fill ~9 ~16 ~16 ~30 ~16 ~16 water 0  
fill ~9 ~16 ~17 ~12 ~16 ~17 water 0  
fill ~9 ~16 ~18 ~11 ~16 ~18 water 0  
fill ~9 ~16 ~19 ~11 ~16 ~19 water 0 
setblock ~10 ~16 ~8 glowstone 0  
fill ~11 ~16 ~5 ~13 ~16 ~5 hardened_clay 0  
fill ~11 ~16 ~6 ~13 ~16 ~6 hardened_clay 0  
fill ~11 ~16 ~7 ~13 ~16 ~7 water 0  
fill ~11 ~16 ~8 ~14 ~16 ~8 water 0  
fill ~11 ~16 ~9 ~30 ~16 ~9 water 0  
fill ~11 ~16 ~10 ~30 ~16 ~10 water 0 
setblock ~12 ~16 ~18 fence 2  
fill ~12 ~16 ~19 ~12 ~18 ~19 water 8  
fill ~12 ~16 ~21 ~23 ~16 ~21 water 8  
fill ~12 ~16 ~22 ~14 ~16 ~22 glass 0 
setblock ~13 ~16 ~17 fence 2 
setblock ~13 ~16 ~18 red_sandstone 2 
setblock ~13 ~16 ~19 red_sandstone_stairs 2 
setblock ~13 ~16 ~20 red_sandstone_stairs 3  
fill ~14 ~16 ~17 ~29 ~16 ~17 water 0  
fill ~14 ~16 ~18 ~28 ~16 ~18 water 0  
fill ~14 ~16 ~19 ~20 ~16 ~19 water 0  
fill ~14 ~16 ~20 ~22 ~16 ~20 water 8  
fill ~15 ~16 ~23 ~21 ~16 ~23 glass 0 
setblock ~16 ~16 ~8 glowstone 0  
fill ~16 ~16 ~22 ~20 ~16 ~22 water 8  
fill ~17 ~16 ~4 ~32 ~16 ~4 glass 0  
fill ~18 ~16 ~6 ~18 ~19 ~6 stonebrick 1  
fill ~18 ~16 ~8 ~30 ~16 ~8 water 0  
fill ~18 ~16 ~25 ~20 ~16 ~25 quartz_stairs 6 
setblock ~18 ~16 ~26 quartz_stairs 4  
fill ~19 ~16 ~5 ~31 ~16 ~5 hardened_clay 0  
fill ~19 ~16 ~6 ~31 ~16 ~6 hardened_clay 0  
fill ~19 ~16 ~7 ~30 ~16 ~7 water 0  
fill ~21 ~16 ~22 ~24 ~16 ~22 glass 0 
setblock ~21 ~16 ~24 stone_brick_stairs 6 
setblock ~21 ~16 ~25 stone_brick_stairs 7  
fill ~22 ~16 ~23 ~23 ~16 ~23 quartz_stairs 6 
setblock ~22 ~16 ~24 quartz_stairs 7  
fill ~24 ~16 ~21 ~26 ~16 ~21 glass 0  
fill ~26 ~16 ~20 ~27 ~16 ~20 glass 0 
setblock ~26 ~16 ~26 quartz_stairs 6  
fill ~26 ~16 ~27 ~26 ~17 ~27 quartz_stairs 4  
fill ~26 ~16 ~28 ~27 ~16 ~28 quartz_stairs 7  
fill ~27 ~16 ~19 ~28 ~16 ~19 glass 0 
setblock ~28 ~16 ~28 quartz_stairs 5 
setblock ~28 ~16 ~31 quartz_stairs 0  
fill ~29 ~16 ~25 ~29 ~20 ~25 wool 3 
setblock ~29 ~16 ~31 quartz_stairs 5  
fill ~32 ~16 ~22 ~32 ~21 ~22 prismarine 2  
fill ~33 ~16 ~21 ~33 ~18 ~21 wool 3  
fill ~4 ~17 ~4 ~15 ~17 ~4 glass 0  
fill ~4 ~17 ~10 ~10 ~17 ~10 stonebrick 1  
fill ~5 ~17 ~11 ~30 ~17 ~11 water 0  
fill ~5 ~17 ~12 ~30 ~17 ~12 water 0  
fill ~5 ~17 ~13 ~30 ~17 ~13 water 0  
fill ~5 ~17 ~14 ~30 ~17 ~14 water 0  
fill ~9 ~17 ~15 ~30 ~17 ~15 water 0  
fill ~9 ~17 ~16 ~30 ~17 ~16 water 0  
fill ~9 ~17 ~17 ~29 ~17 ~17 water 0  
fill ~9 ~17 ~18 ~12 ~17 ~18 water 0  
fill ~9 ~17 ~19 ~11 ~17 ~19 water 0 
setblock ~10 ~17 ~8 stonebrick 1  
fill ~11 ~17 ~5 ~12 ~17 ~5 water 0  
fill ~11 ~17 ~6 ~11 ~20 ~6 water 0  
fill ~11 ~17 ~7 ~13 ~17 ~7 water 0  
fill ~11 ~17 ~8 ~14 ~17 ~8 water 0  
fill ~11 ~17 ~9 ~30 ~17 ~9 water 0  
fill ~11 ~17 ~10 ~30 ~17 ~10 water 0  
fill ~12 ~17 ~6 ~13 ~17 ~6 hardened_clay 0  
fill ~12 ~17 ~21 ~23 ~17 ~21 water 8  
fill ~12 ~17 ~22 ~14 ~17 ~22 glass 0 
setblock ~13 ~17 ~5 hardened_clay 0 
setblock ~13 ~17 ~18 fence 2  
fill ~13 ~17 ~19 ~13 ~19 ~19 water 8  
fill ~13 ~17 ~20 ~22 ~17 ~20 water 8  
fill ~14 ~17 ~18 ~28 ~17 ~18 water 0  
fill ~14 ~17 ~19 ~20 ~17 ~19 water 0  
fill ~15 ~17 ~23 ~21 ~17 ~23 glass 0  
fill ~16 ~17 ~8 ~16 ~19 ~8 stonebrick 1  
fill ~16 ~17 ~22 ~20 ~17 ~22 water 8  
fill ~17 ~17 ~4 ~32 ~17 ~4 glass 0  
fill ~18 ~17 ~8 ~30 ~17 ~8 water 0  
fill ~18 ~17 ~25 ~18 ~17 ~26 quartz_stairs 0  
fill ~19 ~17 ~5 ~21 ~17 ~5 hardened_clay 0  
fill ~19 ~17 ~6 ~31 ~17 ~6 stained_hardened_clay 14  
fill ~19 ~17 ~7 ~30 ~17 ~7 water 0  
fill ~19 ~17 ~25 ~20 ~17 ~25 quartz_stairs 2 
setblock ~20 ~17 ~26 quartz_stairs 1 
setblock ~20 ~17 ~27 quartz_stairs 4  
fill ~21 ~17 ~22 ~24 ~17 ~22 glass 0 
setblock ~21 ~17 ~24 stone_brick_stairs 2 
setblock ~21 ~17 ~25 stone_brick_stairs 3  
fill ~22 ~17 ~5 ~31 ~17 ~5 stained_hardened_clay 14  
fill ~22 ~17 ~23 ~23 ~17 ~23 quartz_stairs 2 
setblock ~22 ~17 ~24 quartz_stairs 3  
fill ~23 ~17 ~24 ~23 ~18 ~24 quartz_stairs 0  
fill ~24 ~17 ~21 ~26 ~17 ~21 glass 0 
setblock ~24 ~17 ~24 quartz_stairs 5 
setblock ~24 ~17 ~25 quartz_stairs 7 
setblock ~25 ~17 ~24 stone_slab 14 
setblock ~25 ~17 ~27 quartz_stairs 4  
fill ~25 ~17 ~28 ~26 ~17 ~28 quartz_stairs 7  
fill ~26 ~17 ~20 ~27 ~17 ~20 glass 0  
fill ~26 ~17 ~26 ~26 ~18 ~26 quartz_block 0 
setblock ~26 ~17 ~29 quartz_stairs 4  
fill ~27 ~17 ~19 ~28 ~17 ~19 glass 0 
setblock ~27 ~17 ~27 quartz_stairs 5 
setblock ~27 ~17 ~29 quartz_stairs 7  
fill ~28 ~17 ~28 ~28 ~19 ~28 quartz_block 0 
setblock ~28 ~17 ~29 quartz_stairs 5 
setblock ~28 ~17 ~30 quartz_stairs 4  
fill ~28 ~17 ~31 ~29 ~17 ~31 quartz_block 0 
setblock ~29 ~17 ~30 quartz_stairs 6  
fill ~4 ~18 ~4 ~15 ~18 ~4 glass 0 
setblock ~4 ~18 ~5 glowstone 0  
fill ~4 ~18 ~6 ~4 ~18 ~9 log 11 
setblock ~4 ~18 ~10 glowstone 0  
fill ~5 ~18 ~5 ~9 ~18 ~5 log 7  
fill ~5 ~18 ~6 ~9 ~18 ~6 stone_slab 0  
fill ~5 ~18 ~7 ~9 ~18 ~7 stone_slab 0  
fill ~5 ~18 ~8 ~9 ~18 ~8 stone_slab 0  
fill ~5 ~18 ~9 ~9 ~18 ~9 stone_slab 0  
fill ~5 ~18 ~10 ~9 ~18 ~10 log 7  
fill ~5 ~18 ~11 ~30 ~18 ~11 water 0  
fill ~5 ~18 ~12 ~30 ~18 ~12 water 0  
fill ~5 ~18 ~13 ~30 ~18 ~13 water 0  
fill ~5 ~18 ~14 ~30 ~18 ~14 water 0  
fill ~9 ~18 ~15 ~30 ~18 ~15 water 0  
fill ~9 ~18 ~16 ~30 ~18 ~16 water 0  
fill ~9 ~18 ~17 ~29 ~18 ~17 water 0  
fill ~9 ~18 ~18 ~12 ~18 ~18 water 0  
fill ~9 ~18 ~19 ~11 ~18 ~19 water 0 
setblock ~10 ~18 ~5 glowstone 0  
fill ~10 ~18 ~6 ~10 ~18 ~9 log 11 
setblock ~10 ~18 ~10 glowstone 0  
fill ~11 ~18 ~5 ~13 ~18 ~5 water 0  
fill ~11 ~18 ~7 ~13 ~18 ~7 water 0  
fill ~11 ~18 ~8 ~14 ~18 ~8 water 0  
fill ~11 ~18 ~9 ~30 ~18 ~9 water 0  
fill ~11 ~18 ~10 ~30 ~18 ~10 water 0  
fill ~12 ~18 ~6 ~13 ~18 ~6 water 0  
fill ~12 ~18 ~21 ~20 ~18 ~21 water 8  
fill ~12 ~18 ~22 ~14 ~18 ~22 glass 0 
setblock ~13 ~18 ~18 sea_lantern 0  
fill ~13 ~18 ~20 ~22 ~18 ~20 water 8  
fill ~14 ~18 ~18 ~28 ~18 ~18 water 0  
fill ~14 ~18 ~19 ~20 ~18 ~19 water 0  
fill ~15 ~18 ~23 ~21 ~18 ~23 glass 0  
fill ~16 ~18 ~22 ~19 ~18 ~22 water 8  
fill ~17 ~18 ~4 ~32 ~18 ~4 glass 0  
fill ~18 ~18 ~8 ~30 ~18 ~8 water 0  
fill ~18 ~18 ~26 ~18 ~24 ~26 vine 8  
fill ~19 ~18 ~5 ~21 ~18 ~5 water 0  
fill ~19 ~18 ~6 ~31 ~18 ~6 hardened_clay 0  
fill ~19 ~18 ~7 ~30 ~18 ~7 water 0  
fill ~19 ~18 ~25 ~19 ~19 ~25 vine 1  
fill ~20 ~18 ~22 ~20 ~20 ~22 water 0  
fill ~20 ~18 ~26 ~20 ~19 ~26 vine 2  
fill ~21 ~18 ~21 ~21 ~20 ~21 water 0  
fill ~21 ~18 ~22 ~24 ~18 ~22 glass 0  
fill ~22 ~18 ~5 ~31 ~18 ~5 hardened_clay 0  
fill ~22 ~18 ~21 ~22 ~19 ~21 water 8  
fill ~23 ~18 ~21 ~23 ~20 ~21 water 0  
fill ~24 ~18 ~21 ~26 ~18 ~21 glass 0 
setblock ~24 ~18 ~24 quartz_stairs 2  
fill ~24 ~18 ~25 ~25 ~18 ~25 quartz_block 0 
setblock ~25 ~18 ~24 quartz_stairs 1 
setblock ~25 ~18 ~26 quartz_stairs 7 
setblock ~25 ~18 ~27 quartz_stairs 0 
setblock ~25 ~18 ~28 stone_stairs 0  
fill ~26 ~18 ~20 ~27 ~18 ~20 glass 0 
setblock ~26 ~18 ~25 quartz_stairs 5 
setblock ~26 ~18 ~28 quartz_stairs 3 
setblock ~26 ~18 ~29 stone_stairs 0  
fill ~27 ~18 ~19 ~28 ~18 ~19 glass 0 
setblock ~27 ~18 ~27 quartz_block 0 
setblock ~27 ~18 ~29 quartz_stairs 3  
fill ~28 ~18 ~29 ~28 ~18 ~30 quartz_block 0 
setblock ~28 ~18 ~31 quartz_stairs 0 
setblock ~29 ~18 ~29 quartz_stairs 5 
setblock ~29 ~18 ~30 quartz_block 0 
setblock ~29 ~18 ~31 quartz_stairs 3  
fill ~4 ~19 ~4 ~15 ~19 ~4 glass 0  
fill ~4 ~19 ~5 ~4 ~19 ~11 water 8  
fill ~5 ~19 ~5 ~13 ~19 ~5 water 0  
fill ~5 ~19 ~6 ~13 ~19 ~6 water 0  
fill ~5 ~19 ~7 ~13 ~19 ~7 water 0  
fill ~5 ~19 ~8 ~14 ~19 ~8 water 0  
fill ~5 ~19 ~9 ~30 ~19 ~9 water 0  
fill ~5 ~19 ~10 ~30 ~19 ~10 water 0  
fill ~5 ~19 ~11 ~30 ~19 ~11 water 0  
fill ~5 ~19 ~12 ~30 ~19 ~12 water 0  
fill ~5 ~19 ~13 ~30 ~19 ~13 water 0  
fill ~5 ~19 ~14 ~30 ~19 ~14 water 0  
fill ~9 ~19 ~15 ~30 ~19 ~15 water 0  
fill ~9 ~19 ~16 ~30 ~19 ~16 water 0  
fill ~9 ~19 ~17 ~29 ~19 ~17 water 0  
fill ~9 ~19 ~18 ~28 ~19 ~18 water 0  
fill ~9 ~19 ~19 ~12 ~19 ~19 water 0  
fill ~12 ~19 ~21 ~20 ~19 ~21 water 8  
fill ~12 ~19 ~22 ~14 ~19 ~22 glass 0  
fill ~13 ~19 ~20 ~22 ~19 ~20 water 8  
fill ~14 ~19 ~19 ~20 ~19 ~19 water 0  
fill ~15 ~19 ~23 ~21 ~19 ~23 glass 0  
fill ~16 ~19 ~22 ~17 ~19 ~22 water 8  
fill ~17 ~19 ~4 ~32 ~19 ~4 glass 0  
fill ~18 ~19 ~8 ~30 ~19 ~8 water 0  
fill ~18 ~19 ~22 ~20 ~19 ~22 water 0  
fill ~19 ~19 ~5 ~22 ~19 ~5 water 0  
fill ~19 ~19 ~6 ~20 ~19 ~6 water 0  
fill ~19 ~19 ~7 ~30 ~19 ~7 water 0  
fill ~19 ~19 ~26 ~19 ~21 ~26 mossy_cobblestone 0  
fill ~21 ~19 ~6 ~31 ~19 ~6 hardened_clay 0  
fill ~21 ~19 ~22 ~24 ~19 ~22 glass 0  
fill ~23 ~19 ~5 ~31 ~19 ~5 hardened_clay 0  
fill ~24 ~19 ~20 ~25 ~19 ~20 water 0  
fill ~24 ~19 ~21 ~26 ~19 ~21 glass 0 
setblock ~24 ~19 ~25 quartz_stairs 0 
setblock ~25 ~19 ~25 quartz_stairs 2 
setblock ~25 ~19 ~26 quartz_stairs 3  
fill ~26 ~19 ~19 ~26 ~20 ~19 water 0  
fill ~26 ~19 ~20 ~27 ~19 ~20 glass 0 
setblock ~26 ~19 ~25 quartz_stairs 1 
setblock ~26 ~19 ~26 quartz_stairs 0 
setblock ~26 ~19 ~27 quartz_stairs 3  
fill ~27 ~19 ~19 ~28 ~19 ~19 glass 0 
setblock ~27 ~19 ~27 quartz_stairs 0 
setblock ~27 ~19 ~28 quartz_stairs 3 
setblock ~28 ~19 ~29 quartz_stairs 0  
fill ~28 ~19 ~30 ~29 ~19 ~30 quartz_stairs 3
fill ~33 ~19 ~21 ~33 ~20 ~21 prismarine 2  
fill ~4 ~20 ~4 ~15 ~20 ~4 glass 0  
fill ~4 ~20 ~5 ~12 ~20 ~5 water 0  
fill ~4 ~20 ~6 ~12 ~20 ~6 water 0  
fill ~4 ~20 ~7 ~12 ~20 ~7 water 0  
fill ~4 ~20 ~8 ~13 ~20 ~8 water 0  
fill ~4 ~20 ~9 ~14 ~20 ~9 water 0  
fill ~4 ~20 ~10 ~31 ~20 ~10 water 0  
fill ~4 ~20 ~11 ~31 ~20 ~11 water 0  
fill ~5 ~20 ~12 ~31 ~20 ~12 water 0  
fill ~5 ~20 ~13 ~31 ~20 ~13 water 0  
fill ~5 ~20 ~14 ~31 ~20 ~14 water 0  
fill ~9 ~20 ~15 ~30 ~20 ~15 water 0  
fill ~9 ~20 ~16 ~30 ~20 ~16 water 0  
fill ~9 ~20 ~17 ~29 ~20 ~17 water 0  
fill ~9 ~20 ~18 ~28 ~20 ~18 water 0  
fill ~9 ~20 ~19 ~26 ~20 ~19 water 0  
fill ~10 ~20 ~20 ~24 ~20 ~20 water 0  
fill ~12 ~20 ~21 ~23 ~20 ~21 water 0  
fill ~12 ~20 ~22 ~14 ~20 ~22 glass 0  
fill ~13 ~20 ~5 ~13 ~21 ~5 stonebrick 1  
fill ~13 ~20 ~6 ~13 ~21 ~6 stonebrick 1  
fill ~13 ~20 ~7 ~13 ~21 ~7 stonebrick 1 
setblock ~14 ~20 ~6 glowstone 0  
fill ~14 ~20 ~8 ~14 ~21 ~8 stonebrick 1  
fill ~15 ~20 ~9 ~17 ~20 ~9 stonebrick 1 
setblock ~15 ~20 ~22 water 1  
fill ~15 ~20 ~23 ~21 ~20 ~23 glass 0 
setblock ~16 ~20 ~8 glowstone 0  
fill ~16 ~20 ~22 ~20 ~20 ~22 water 0  
fill ~17 ~20 ~4 ~32 ~20 ~4 glass 0 
setblock ~18 ~20 ~6 glowstone 0  
fill ~18 ~20 ~8 ~18 ~21 ~8 stonebrick 1  
fill ~18 ~20 ~9 ~31 ~20 ~9 water 0  
fill ~19 ~20 ~5 ~19 ~21 ~5 stonebrick 1  
fill ~19 ~20 ~6 ~19 ~21 ~6 stonebrick 1  
fill ~19 ~20 ~7 ~19 ~21 ~7 stonebrick 1  
fill ~19 ~20 ~8 ~31 ~20 ~8 water 0  
fill ~20 ~20 ~5 ~23 ~20 ~5 water 0  
fill ~20 ~20 ~6 ~22 ~20 ~6 water 0  
fill ~20 ~20 ~7 ~31 ~20 ~7 water 0  
fill ~21 ~20 ~22 ~24 ~20 ~22 glass 0  
fill ~23 ~20 ~6 ~31 ~20 ~6 hardened_clay 0  
fill ~24 ~20 ~5 ~31 ~20 ~5 hardened_clay 0  
fill ~24 ~20 ~21 ~26 ~20 ~21 glass 0 
setblock ~25 ~20 ~20 water 1  
fill ~26 ~20 ~20 ~27 ~20 ~20 glass 0 
setblock ~26 ~20 ~25 red_sandstone_stairs 4 
setblock ~26 ~20 ~26 red_sandstone_stairs 6 
setblock ~26 ~20 ~27 jungle_fence_gate 5  
fill ~27 ~20 ~19 ~28 ~20 ~19 glass 0 
setblock ~27 ~20 ~24 red_sandstone_stairs 6 
setblock ~27 ~20 ~25 red_sandstone_stairs 7 
setblock ~27 ~20 ~26 red_sandstone 0 
setblock ~27 ~20 ~27 log 3 
setblock ~27 ~20 ~28 jungle_fence_gate 6 
setblock ~28 ~20 ~25 red_sandstone_stairs 2  
fill ~28 ~20 ~26 ~28 ~20 ~29 red_sandstone_stairs 1 
setblock ~29 ~20 ~29 red_sandstone_stairs 5  
fill ~4 ~21 ~4 ~15 ~21 ~4 glass 0  
fill ~4 ~21 ~5 ~4 ~25 ~5 glass 0  
fill ~4 ~21 ~11 ~4 ~25 ~11 glass 0  
fill ~6 ~21 ~16 ~6 ~25 ~16 glass 0  
fill ~8 ~21 ~10 ~8 ~21 ~11 waterlily 0 
setblock ~9 ~21 ~12 waterlily 0 
setblock ~10 ~21 ~16 waterlily 0  
fill ~10 ~21 ~20 ~10 ~25 ~20 glass 0  
fill ~11 ~21 ~14 ~12 ~21 ~14 waterlily 0 
setblock ~11 ~21 ~17 waterlily 0  
fill ~12 ~21 ~5 ~12 ~22 ~5 vine 8  
fill ~12 ~21 ~6 ~12 ~21 ~7 vine 8 
setblock ~12 ~21 ~11 waterlily 0  
fill ~12 ~21 ~22 ~16 ~21 ~22 glass 0 
setblock ~13 ~21 ~8 vine 4 
setblock ~13 ~21 ~18 waterlily 0 
setblock ~13 ~21 ~20 waterlily 0  
fill ~14 ~21 ~5 ~15 ~21 ~5 stone_slab 0  
fill ~14 ~21 ~7 ~18 ~21 ~7 stone_slab 0 
setblock ~14 ~21 ~15 waterlily 0  
fill ~15 ~21 ~6 ~17 ~21 ~6 stone_slab 0 
setblock ~15 ~21 ~8 stone_slab 0  
fill ~15 ~21 ~9 ~17 ~21 ~9 stonebrick 1 
setblock ~15 ~21 ~14 waterlily 0  
fill ~15 ~21 ~16 ~15 ~21 ~17 waterlily 0 
setblock ~15 ~21 ~19 waterlily 0  
fill ~16 ~21 ~23 ~20 ~21 ~23 glass 0  
fill ~17 ~21 ~4 ~32 ~21 ~4 glass 0  
fill ~17 ~21 ~5 ~18 ~21 ~5 stone_slab 0 
setblock ~17 ~21 ~8 stone_slab 0 
setblock ~17 ~21 ~16 waterlily 0  
fill ~18 ~21 ~12 ~19 ~21 ~12 waterlily 0 
setblock ~18 ~21 ~14 waterlily 0 
setblock ~18 ~21 ~25 cobblestone_wall 1 
setblock ~19 ~21 ~8 vine 4 
setblock ~19 ~21 ~25 cobblestone_wall 0  
fill ~20 ~21 ~5 ~20 ~22 ~5 vine 2  
fill ~20 ~21 ~6 ~20 ~21 ~7 vine 2 
setblock ~20 ~21 ~11 waterlily 0 
setblock ~20 ~21 ~15 waterlily 0 
setblock ~20 ~21 ~18 waterlily 0  
fill ~20 ~21 ~22 ~24 ~21 ~22 glass 0 
setblock ~20 ~21 ~26 cobblestone_wall 0 
setblock ~20 ~21 ~27 cobblestone_wall 1  
fill ~21 ~21 ~20 ~22 ~21 ~20 waterlily 0 
setblock ~22 ~21 ~6 waterlily 0  
fill ~22 ~21 ~11 ~22 ~21 ~12 waterlily 0 
setblock ~22 ~21 ~18 waterlily 0 
setblock ~23 ~21 ~8 waterlily 0 
setblock ~23 ~21 ~10 waterlily 0 
setblock ~23 ~21 ~14 waterlily 0  
fill ~23 ~21 ~16 ~23 ~21 ~17 waterlily 0 
setblock ~24 ~21 ~7 waterlily 0  
fill ~24 ~21 ~12 ~24 ~21 ~13 waterlily 0 
setblock ~24 ~21 ~18 waterlily 0  
fill ~24 ~21 ~21 ~25 ~21 ~21 glass 0  
fill ~25 ~21 ~6 ~28 ~21 ~6 dirt 1 
setblock ~25 ~21 ~10 waterlily 0 
setblock ~25 ~21 ~15 waterlily 0  
fill ~25 ~21 ~20 ~27 ~21 ~20 glass 0 
setblock ~25 ~21 ~26 red_sandstone_stairs 4  
fill ~26 ~21 ~5 ~28 ~21 ~5 dirt 1  
fill ~26 ~21 ~14 ~27 ~21 ~14 waterlily 0 
setblock ~26 ~21 ~24 red_sandstone_stairs 2 
setblock ~26 ~21 ~25 red_sandstone_stairs 0  
fill ~26 ~21 ~26 ~27 ~21 ~26 red_sandstone_stairs 3 
setblock ~26 ~21 ~27 quartz_stairs 4  
fill ~26 ~21 ~28 ~27 ~21 ~28 quartz_stairs 7 
setblock ~27 ~21 ~12 waterlily 0  
fill ~27 ~21 ~19 ~28 ~21 ~19 glass 0 
setblock ~27 ~21 ~25 red_sandstone_stairs 1 
setblock ~27 ~21 ~27 quartz_stairs 2 
setblock ~28 ~21 ~25 red_sandstone_stairs 6 
setblock ~28 ~21 ~26 red_sandstone_stairs 7  
fill ~28 ~21 ~27 ~28 ~21 ~28 red_sandstone_stairs 5  
fill ~29 ~21 ~5 ~31 ~21 ~5 stained_hardened_clay 0  
fill ~29 ~21 ~6 ~31 ~21 ~6 stained_hardened_clay 0 
setblock ~29 ~21 ~25 prismarine 2 
setblock ~29 ~21 ~28 red_sandstone_stairs 4 
setblock ~29 ~21 ~29 red_sandstone_stairs 6  
fill ~30 ~21 ~16 ~30 ~25 ~16 glass 0  
fill ~31 ~21 ~23 ~31 ~22 ~23 prismarine 2  
fill ~4 ~22 ~4 ~15 ~22 ~4 glass 0  
fill ~4 ~22 ~6 ~4 ~26 ~6 glass 0  
fill ~4 ~22 ~10 ~4 ~26 ~10 glass 0  
fill ~5 ~22 ~14 ~5 ~25 ~14 glass 0  
fill ~12 ~22 ~21 ~12 ~25 ~21 glass 0 
setblock ~13 ~22 ~5 stonebrick 0 
setblock ~13 ~22 ~6 stone_slab 0 
setblock ~13 ~22 ~7 stonebrick 0  
fill ~13 ~22 ~22 ~23 ~22 ~22 glass 0 
setblock ~14 ~22 ~8 stone_slab 0 
setblock ~15 ~22 ~9 stonebrick 0 
setblock ~16 ~22 ~9 stone_slab 0  
fill ~17 ~22 ~4 ~32 ~22 ~4 glass 0 
setblock ~17 ~22 ~9 stonebrick 0  
fill ~17 ~22 ~23 ~19 ~22 ~23 glass 0  
fill ~17 ~22 ~25 ~17 ~23 ~25 cobblestone_wall 1 
setblock ~18 ~22 ~8 stone_slab 0 
setblock ~18 ~22 ~25 mossy_cobblestone 0 
setblock ~19 ~22 ~5 stonebrick 0 
setblock ~19 ~22 ~6 stone_slab 0 
setblock ~19 ~22 ~7 stonebrick 0 
setblock ~19 ~22 ~26 prismarine 2 
setblock ~20 ~22 ~27 mossy_cobblestone 0  
fill ~20 ~22 ~28 ~20 ~23 ~28 cobblestone_wall 1  
fill ~23 ~22 ~21 ~25 ~22 ~21 glass 0  
fill ~25 ~22 ~20 ~27 ~22 ~20 glass 0 
setblock ~25 ~22 ~26 red_sandstone_stairs 0 
setblock ~25 ~22 ~27 red_sandstone_stairs 6  
fill ~26 ~22 ~5 ~26 ~26 ~5 log 0  
fill ~26 ~22 ~26 ~26 ~23 ~26 prismarine 2 
setblock ~26 ~22 ~27 quartz_stairs 7 
setblock ~26 ~22 ~28 quartz_stairs 3  
fill ~27 ~22 ~19 ~28 ~22 ~19 glass 0 
setblock ~27 ~22 ~25 red_sandstone_stairs 0 
setblock ~27 ~22 ~26 red_sandstone_stairs 7 
setblock ~27 ~22 ~27 glowstone 0 
setblock ~27 ~22 ~28 quartz_stairs 4 
setblock ~28 ~22 ~25 red_sandstone_stairs 2 
setblock ~28 ~22 ~26 red_sandstone_stairs 1  
fill ~28 ~22 ~27 ~28 ~23 ~27 red_sandstone_stairs 0  
fill ~28 ~22 ~28 ~28 ~23 ~28 prismarine 2  
fill ~29 ~22 ~5 ~31 ~22 ~5 grass 0 
setblock ~29 ~22 ~6 dirt 1 
setblock ~29 ~22 ~27 red_sandstone_stairs 5 
setblock ~29 ~22 ~28 red_sandstone_stairs 0  
fill ~30 ~22 ~6 ~31 ~22 ~6 grass 0  
fill ~31 ~22 ~14 ~31 ~25 ~14 glass 0  
fill ~4 ~23 ~4 ~15 ~23 ~4 glass 0  
fill ~4 ~23 ~7 ~4 ~26 ~7 glass 0  
fill ~4 ~23 ~8 ~4 ~26 ~8 glass 0  
fill ~4 ~23 ~9 ~4 ~26 ~9 glass 0  
fill ~7 ~23 ~17 ~7 ~25 ~17 glass 0  
fill ~9 ~23 ~19 ~9 ~25 ~19 glass 0  
fill ~13 ~23 ~22 ~23 ~23 ~22 glass 0  
fill ~17 ~23 ~4 ~32 ~23 ~4 glass 0  
fill ~18 ~23 ~25 ~18 ~24 ~25 vine 2 
setblock ~19 ~23 ~26 sea_lantern 0  
fill ~23 ~23 ~21 ~25 ~23 ~21 glass 0  
fill ~25 ~23 ~20 ~26 ~23 ~20 glass 0 
setblock ~25 ~23 ~27 cobblestone_wall 1  
fill ~26 ~23 ~19 ~28 ~23 ~19 glass 0 
setblock ~26 ~23 ~27 red_sandstone_stairs 2 
setblock ~26 ~23 ~28 red_sandstone_stairs 1 
setblock ~27 ~23 ~26 red_sandstone_stairs 2 
setblock ~27 ~23 ~27 red_sandstone 0 
setblock ~27 ~23 ~28 red_sandstone_stairs 2 
setblock ~27 ~23 ~29 cobblestone_wall 1  
fill ~29 ~23 ~17 ~29 ~25 ~17 glass 0  
fill ~4 ~24 ~4 ~4 ~8 ~4 glass 0  
fill ~5 ~24 ~13 ~5 ~26 ~13 glass 0  
fill ~6 ~24 ~4 ~15 ~24 ~4 glass 0  
fill ~6 ~24 ~15 ~6 ~26 ~15 glass 0  
fill ~8 ~24 ~18 ~8 ~26 ~18 glass 0  
fill ~11 ~24 ~20 ~11 ~26 ~20 glass 0  
fill ~13 ~24 ~21 ~13 ~26 ~21 glass 0  
fill ~14 ~24 ~22 ~22 ~24 ~22 glass 0  
fill ~17 ~24 ~4 ~30 ~24 ~4 glass 0 
setblock ~17 ~24 ~25 mossy_cobblestone 0 
setblock ~19 ~24 ~26 prismarine 2 
setblock ~20 ~24 ~28 mossy_cobblestone 0  
fill ~22 ~24 ~21 ~24 ~24 ~21 glass 0  
fill ~24 ~24 ~5 ~25 ~24 ~5 leaves 0  
fill ~24 ~24 ~6 ~28 ~24 ~6 leaves 0  
fill ~24 ~24 ~20 ~26 ~24 ~20 glass 0 
setblock ~25 ~24 ~27 sea_lantern 0  
fill ~26 ~24 ~19 ~27 ~24 ~19 glass 0 
setblock ~26 ~24 ~28 cobblestone_wall 1  
fill ~27 ~24 ~5 ~28 ~24 ~5 leaves 0 
setblock ~27 ~24 ~29 sea_lantern 0  
fill ~28 ~24 ~18 ~28 ~26 ~18 glass 0  
fill ~30 ~24 ~15 ~30 ~26 ~15 glass 0  
fill ~31 ~24 ~13 ~31 ~26 ~13 glass 0  
fill ~5 ~25 ~4 ~15 ~25 ~4 glass 0  
fill ~5 ~25 ~12 ~5 ~26 ~12 glass 0  
fill ~14 ~25 ~21 ~14 ~27 ~21 glass 0  
fill ~15 ~25 ~22 ~21 ~25 ~22 glass 0  
fill ~17 ~25 ~4 ~31 ~25 ~4 glass 0 
setblock ~17 ~25 ~25 cobblestone_wall 1  
fill ~19 ~25 ~26 ~19 ~26 ~26 cobblestone_wall 1 
setblock ~20 ~25 ~28 cobblestone_wall 1  
fill ~21 ~25 ~21 ~24 ~25 ~21 glass 0  
fill ~24 ~25 ~5 ~25 ~25 ~5 leaves 0  
fill ~24 ~25 ~6 ~28 ~25 ~6 leaves 0  
fill ~24 ~25 ~20 ~26 ~25 ~20 glass 0  
fill ~26 ~25 ~19 ~27 ~25 ~19 glass 0 
setblock ~26 ~25 ~28 sea_lantern 0  
fill ~27 ~25 ~5 ~28 ~25 ~5 leaves 0  
fill ~31 ~25 ~12 ~31 ~26 ~12 glass 0  
fill ~5 ~26 ~4 ~15 ~26 ~4 glass 0  
fill ~5 ~26 ~5 ~5 ~26 ~13 glass 0  
fill ~6 ~26 ~14 ~6 ~27 ~14 glass 0  
fill ~7 ~26 ~16 ~7 ~27 ~16 glass 0  
fill ~8 ~26 ~17 ~8 ~27 ~17 glass 0  
fill ~9 ~26 ~18 ~9 ~27 ~18 glass 0  
fill ~10 ~26 ~19 ~10 ~27 ~19 glass 0  
fill ~12 ~26 ~20 ~12 ~27 ~20 glass 0  
fill ~15 ~26 ~21 ~15 ~27 ~21 glass 0  
fill ~16 ~26 ~22 ~20 ~26 ~22 glass 0  
fill ~17 ~26 ~4 ~31 ~26 ~4 glass 0  
fill ~20 ~26 ~21 ~23 ~26 ~21 glass 0  
fill ~23 ~26 ~20 ~25 ~26 ~20 glass 0  
fill ~25 ~26 ~5 ~25 ~27 ~5 leaves 0  
fill ~25 ~26 ~6 ~27 ~26 ~6 leaves 0  
fill ~25 ~26 ~19 ~26 ~26 ~19 glass 0  
fill ~27 ~26 ~5 ~27 ~27 ~5 leaves 0  
fill ~27 ~26 ~18 ~27 ~27 ~18 glass 0  
fill ~28 ~26 ~17 ~28 ~27 ~17 glass 0  
fill ~29 ~26 ~16 ~29 ~27 ~16 glass 0  
fill ~30 ~26 ~14 ~30 ~27 ~14 glass 0  
fill ~31 ~26 ~5 ~31 ~26 ~13 glass 0  
fill ~6 ~27 ~4 ~15 ~27 ~4 mossy_cobblestone 0  
fill ~6 ~27 ~5 ~6 ~27 ~12 mossy_cobblestone 0 
setblock ~6 ~27 ~13 glass 0  
fill ~7 ~27 ~13 ~7 ~27 ~14 mossy_cobblestone 0 
setblock ~7 ~27 ~15 glass 0 
setblock ~8 ~27 ~15 mossy_cobblestone 0 
setblock ~9 ~27 ~16 mossy_cobblestone 0 
setblock ~10 ~27 ~17 mossy_cobblestone 0 
setblock ~11 ~27 ~18 mossy_cobblestone 0 
setblock ~11 ~27 ~19 glass 0  
fill ~12 ~27 ~19 ~13 ~27 ~19 mossy_cobblestone 0 
setblock ~13 ~27 ~20 glass 0  
fill ~14 ~27 ~20 ~22 ~27 ~20 mossy_cobblestone 0 
setblock ~15 ~27 ~3 stone_slab 0  
fill ~15 ~27 ~5 ~15 ~27 ~6 stone_slab 0  
fill ~16 ~27 ~6 ~17 ~27 ~6 stone_slab 0  
fill ~16 ~27 ~21 ~22 ~27 ~21 glass 0 
setblock ~17 ~27 ~3 stone_slab 0  
fill ~17 ~27 ~4 ~30 ~27 ~4 mossy_cobblestone 0 
setblock ~17 ~27 ~5 stone_slab 0  
fill ~23 ~27 ~19 ~24 ~27 ~19 mossy_cobblestone 0  
fill ~23 ~27 ~20 ~24 ~27 ~20 glass 0 
setblock ~25 ~27 ~18 mossy_cobblestone 0  
fill ~25 ~27 ~19 ~26 ~27 ~19 glass 0  
fill ~26 ~27 ~5 ~26 ~27 ~6 leaves 0 
setblock ~26 ~27 ~17 mossy_cobblestone 0 
setblock ~27 ~27 ~16 mossy_cobblestone 0 
setblock ~28 ~27 ~15 mossy_cobblestone 0  
fill ~29 ~27 ~13 ~29 ~27 ~14 mossy_cobblestone 0 
setblock ~29 ~27 ~15 glass 0  
fill ~30 ~27 ~5 ~30 ~27 ~12 mossy_cobblestone 0 
setblock ~30 ~27 ~13 glass 0  
fill ~6 ~30 ~5 ~7 ~30 ~5 wool 15  
fill ~8 ~30 ~4 ~9 ~30 ~4 wool 15  
fill ~10 ~30 ~5 ~12 ~30 ~5 wool 15  
fill ~13 ~30 ~4 ~14 ~30 ~4 wool 15  
fill ~7 ~31 ~5 ~7 ~35 ~5 wool 15  
fill ~8 ~31 ~4 ~9 ~31 ~4 wool 15  
fill ~10 ~31 ~5 ~12 ~31 ~5 quartz_stairs 4  
fill ~13 ~31 ~4 ~15 ~31 ~4 wool 15 
setblock ~6 ~32 ~5 wool 15  
fill ~8 ~32 ~4 ~8 ~35 ~4 wool 15 
setblock ~9 ~32 ~4 quartz_stairs 4 
setblock ~10 ~32 ~5 quartz_stairs 6 
setblock ~11 ~32 ~5 wool 15 
setblock ~12 ~32 ~5 quartz_stairs 7 
setblock ~13 ~32 ~4 quartz_stairs 5  
fill ~14 ~32 ~4 ~14 ~35 ~4 wool 15 
setblock ~9 ~33 ~4 quartz_stairs 1 
setblock ~10 ~33 ~5 quartz_stairs 0  
fill ~11 ~33 ~5 ~12 ~33 ~5 quartz_stairs 1 
setblock ~13 ~33 ~4 quartz_stairs 0  
fill ~6 ~34 ~5 ~6 ~35 ~5 wool 15 
setblock ~9 ~34 ~4 quartz_stairs 5 
setblock ~10 ~34 ~5 quartz_stairs 4  
fill ~11 ~34 ~5 ~11 ~35 ~5 wool 15 
setblock ~12 ~34 ~5 quartz_stairs 5 
setblock ~13 ~34 ~4 quartz_stairs 4 
setblock ~5 ~35 ~5 wool 15 
setblock ~9 ~35 ~4 wool 15 
setblock ~10 ~35 ~5 wool 15 
setblock ~12 ~35 ~5 wool 15 
setblock ~13 ~35 ~4 wool 15 
setblock ~15 ~35 ~4 wool 15