setblock ~35~0~1 minecraft:stonebrick 0
fill ~35~1~1 ~35~2~1 minecraft:nether_brick_fence
setblock ~35~3~1 minecraft:stone_block_slab 3
fill ~36~0~1 ~40~0~1 minecraft:stone_brick_stairs 2
setblock ~41~0~1 minecraft:stonebrick 0
fill ~41~1~1 ~41~2~1 minecraft:nether_brick_fence
setblock ~41~3~1 minecraft:stone_block_slab 3
setblock ~35~0~2 minecraft:stone_block_slab 13
setblock ~35~1~2 minecraft:stonebrick 0
fill ~35~2~2 ~35~3~2 minecraft:nether_brick_fence
setblock ~35~4~2 minecraft:stone_block_slab 3
fill ~36~0~2 ~40~0~2 minecraft:stonebrick 0
fill ~36~1~2 ~40~1~2 minecraft:stone_brick_stairs 2
setblock ~41~0~2 minecraft:stone_block_slab 13
setblock ~41~1~2 minecraft:stonebrick 0
fill ~41~2~2 ~41~3~2 minecraft:nether_brick_fence
setblock ~41~4~2 minecraft:stone_block_slab 3
setblock ~35~1~3 minecraft:stone_block_slab 13
setblock ~35~2~3 minecraft:stonebrick 0
fill ~35~3~3 ~35~4~3 minecraft:nether_brick_fence
setblock ~35~5~3 minecraft:stone_block_slab 3
fill ~36~0~3 ~40~0~3 minecraft:stone_brick_stairs 7
fill ~36~1~3 ~40~1~3 minecraft:stonebrick 0
fill ~36~2~3 ~40~2~3 minecraft:stone_brick_stairs 2
setblock ~41~1~3 minecraft:stone_block_slab 13
setblock ~41~2~3 minecraft:stonebrick 0
fill ~41~3~3 ~41~4~3 minecraft:nether_brick_fence
setblock ~41~5~3 minecraft:stone_block_slab 3
setblock ~35~2~4 minecraft:stone_block_slab 13
setblock ~35~3~4 minecraft:stonebrick 0
fill ~35~4~4 ~35~5~4 minecraft:nether_brick_fence
setblock ~35~6~4 minecraft:stone_block_slab 3
fill ~36~1~4 ~40~1~4 minecraft:stone_brick_stairs 7
fill ~36~2~4 ~40~2~4 minecraft:stonebrick 0
fill ~36~3~4 ~40~3~4 minecraft:stone_brick_stairs 2
fill ~37~0~4 ~39~0~4 minecraft:stone_brick_stairs 2
setblock ~41~2~4 minecraft:stone_block_slab 13
setblock ~41~3~4 minecraft:stonebrick 0
fill ~41~4~4 ~41~5~4 minecraft:nether_brick_fence
setblock ~41~6~4 minecraft:stone_block_slab 3
setblock ~35~3~5 minecraft:stone_block_slab 13
setblock ~35~4~5 minecraft:stonebrick 0
fill ~35~5~5 ~35~6~5 minecraft:nether_brick_fence
fill ~35~7~5 ~35~7~6 minecraft:stone_block_slab 3
setblock ~36~0~5 minecraft:stone_brick_stairs 0
setblock ~36~2~5 minecraft:stone_brick_stairs 7
fill ~36~3~5 ~40~3~5 minecraft:stonebrick 0
fill ~36~4~5 ~40~4~5 minecraft:stone_brick_stairs 2
setblock ~37~0~5 minecraft:log 1
setblock ~37~1~5 minecraft:stonebrick 3
setblock ~37~2~5 minecraft:log 1
setblock ~38~0~5 minecraft:stonebrick 0
setblock ~38~2~5 minecraft:stone_brick_stairs 7
setblock ~39~0~5 minecraft:log 1
setblock ~39~1~5 minecraft:stonebrick 3
setblock ~39~2~5 minecraft:log 1
setblock ~40~0~5 minecraft:stone_brick_stairs 1
setblock ~40~2~5 minecraft:stone_brick_stairs 7
setblock ~41~3~5 minecraft:stone_block_slab 13
setblock ~41~4~5 minecraft:stonebrick 0
fill ~41~5~5 ~41~6~5 minecraft:nether_brick_fence
fill ~41~7~5 ~41~7~6 minecraft:stone_block_slab 3
setblock ~35~4~6 minecraft:stone_block_slab 13
fill ~35~5~6 ~35~5~7 minecraft:stonebrick 0
fill ~35~6~6 ~35~6~7 minecraft:nether_brick_fence
fill ~36~3~6 ~40~3~6 minecraft:stone_brick_stairs 7
fill ~36~4~6 ~40~4~6 minecraft:stonebrick 0
fill ~36~5~6 ~40~5~6 minecraft:stone_block_slab 5
fill ~37~0~6 ~39~0~6 minecraft:stone_brick_stairs 3
fill ~37~2~6 ~37~2~10 minecraft:log 1
fill ~39~2~6 ~39~2~10 minecraft:log 1
setblock ~41~4~6 minecraft:stone_block_slab 13
fill ~41~5~6 ~41~5~7 minecraft:stonebrick 0
fill ~41~6~6 ~41~6~7 minecraft:nether_brick_fence
fill ~35~7~7 ~35~7~9 minecraft:nether_brick_fence
fill ~35~8~7 ~35~8~8 minecraft:stone_block_slab 3
fill ~36~4~7 ~37~4~7 minecraft:stone_brick_stairs 7
fill ~36~5~7 ~40~5~7 minecraft:stonebrick 0
fill ~38~4~7 ~38~4~10 minecraft:log 1
fill ~39~4~7 ~40~4~7 minecraft:stone_brick_stairs 7
fill ~41~7~7 ~41~7~9 minecraft:nether_brick_fence
fill ~41~8~7 ~41~8~8 minecraft:stone_block_slab 3
setblock ~35~5~8 minecraft:stone_block_slab 13
fill ~35~6~8 ~35~6~9 minecraft:stonebrick 0
setblock ~36~2~8 minecraft:stone_button 4
setblock ~36~4~8 minecraft:stone_button 4
setblock ~36~5~8 minecraft:stone_brick_stairs 7
fill ~36~6~8 ~40~6~8 minecraft:stone_block_slab 5
fill ~37~3~8 ~37~5~8 minecraft:log 1
setblock ~38~5~8 minecraft:stone_brick_stairs 7
fill ~39~3~8 ~39~5~8 minecraft:log 1
setblock ~40~2~8 minecraft:stone_button 5
setblock ~40~4~8 minecraft:stone_button 5
setblock ~40~5~8 minecraft:stone_brick_stairs 7
setblock ~41~5~8 minecraft:stone_block_slab 13
fill ~41~6~8 ~41~6~9 minecraft:stonebrick 0
fill ~35~8~9 ~35~8~12 minecraft:nether_brick_fence
fill ~35~9~9 ~35~9~12 minecraft:stone_block_slab 3
fill ~36~5~9 ~40~5~9 minecraft:stone_block_slab 13
fill ~36~6~9 ~40~6~9 minecraft:stonebrick 0
fill ~41~8~9 ~41~8~12 minecraft:nether_brick_fence
fill ~41~9~9 ~41~9~12 minecraft:stone_block_slab 3
fill ~35~6~10 ~35~6~11 minecraft:stone_block_slab 13
fill ~35~7~10 ~35~7~12 minecraft:stonebrick 0
setblock ~36~6~10 minecraft:stone_brick_stairs 7
fill ~36~7~10 ~40~7~10 minecraft:stone_block_slab 5
fill ~37~0~10 ~39~0~10 minecraft:stone_brick_stairs 2
setblock ~37~6~10 minecraft:stonebrick 0
setblock ~38~6~10 minecraft:stone_brick_stairs 7
setblock ~39~6~10 minecraft:stonebrick 0
setblock ~40~6~10 minecraft:stone_brick_stairs 7
fill ~41~6~10 ~41~6~11 minecraft:stone_block_slab 13
fill ~41~7~10 ~41~7~12 minecraft:stonebrick 0
setblock ~36~0~11 minecraft:stone_brick_stairs 0
setblock ~36~2~11 minecraft:stone_button 4
setblock ~36~4~11 minecraft:stone_button 4
setblock ~36~6~11 minecraft:stone_brick_stairs 4
fill ~36~7~11 ~40~7~14 minecraft:stonebrick 0
setblock ~37~0~11 minecraft:log 1
setblock ~37~1~11 minecraft:stonebrick 3
fill ~37~2~11 ~37~6~11 minecraft:log 1
setblock ~38~0~11 minecraft:stonebrick 0
setblock ~38~2~11 minecraft:log 1
setblock ~38~4~11 minecraft:log 1
setblock ~38~6~11 minecraft:stone_block_slab 13
setblock ~39~0~11 minecraft:log 1
setblock ~39~1~11 minecraft:stonebrick 3
fill ~39~2~11 ~39~6~11 minecraft:log 1
setblock ~40~0~11 minecraft:stone_brick_stairs 1
setblock ~40~2~11 minecraft:stone_button 5
setblock ~40~4~11 minecraft:stone_button 5
setblock ~40~6~11 minecraft:stone_brick_stairs 5
fill ~37~0~12 ~39~0~12 minecraft:stone_brick_stairs 3
fill ~37~2~12 ~37~2~14 minecraft:log 1
setblock ~37~6~12 minecraft:stone_brick_stairs 7
fill ~38~4~12 ~38~4~14 minecraft:log 1
fill ~39~2~12 ~39~2~14 minecraft:log 1
setblock ~39~6~12 minecraft:stone_brick_stairs 7
setblock ~32~9~13 minecraft:stone_stairs 6
setblock ~32~10~13 minecraft:stonebrick 3
setblock ~32~11~13 minecraft:log 1
setblock ~32~12~13 minecraft:stone_block_slab 3
setblock ~35~7~13 minecraft:stone_block_slab 13
fill ~35~8~13 ~35~8~14 minecraft:stonebrick 0
setblock ~35~9~13 minecraft:stonebrick 3
fill ~35~10~13 ~35~11~13 minecraft:log 1
setblock ~35~12~13 minecraft:stone_block_slab 3
fill ~36~8~13 ~40~8~14 minecraft:stone_block_slab 5
setblock ~38~9~13 minecraft:wall_sign 2
setblock ~41~7~13 minecraft:stone_block_slab 13
fill ~41~8~13 ~41~8~14 minecraft:stonebrick 0
setblock ~41~9~13 minecraft:stonebrick 3
fill ~41~10~13 ~41~11~13 minecraft:log 1
setblock ~41~12~13 minecraft:stone_block_slab 3
setblock ~44~9~13 minecraft:stone_stairs 6
setblock ~44~10~13 minecraft:stonebrick 3
setblock ~44~11~13 minecraft:log 1
setblock ~44~12~13 minecraft:stone_block_slab 3
setblock ~29~8~14 minecraft:stone_stairs 6
setblock ~29~9~14 minecraft:stonebrick 3
fill ~29~10~14 ~29~11~14 minecraft:log 1
setblock ~29~12~14 minecraft:stone_block_slab 3
fill ~31~9~14 ~31~12~14 minecraft:iron_bars
setblock ~32~8~14 minecraft:stone_stairs 6
fill ~32~9~14 ~35~9~14 minecraft:stonebrick 0
fill ~32~10~14 ~32~12~14 minecraft:stonebrick 0
setblock ~33~8~14 minecraft:stone_stairs 4
fill ~33~10~14 ~34~11~14 minecraft:iron_bars
fill ~33~12~14 ~35~13~14 minecraft:stonebrick 0
setblock ~34~8~14 minecraft:stone_block_slab 3
setblock ~35~6~14 minecraft:stone_button 2
setblock ~35~7~14 minecraft:stone_stairs 6
fill ~35~10~14 ~35~11~14 minecraft:stonebrick 0
fill ~36~9~14 ~40~9~14 minecraft:fence 0
fill ~37~0~14 ~39~0~14 minecraft:stone_brick_stairs 2
setblock ~37~6~14 minecraft:stone_brick_stairs 6
setblock ~38~6~14 minecraft:stone_button 2
setblock ~39~6~14 minecraft:stone_brick_stairs 6
setblock ~41~6~14 minecraft:stone_button 2
setblock ~41~7~14 minecraft:stone_stairs 6
fill ~41~9~14 ~44~9~14 minecraft:stonebrick 0
fill ~41~10~14 ~41~13~14 minecraft:stonebrick 0
setblock ~42~8~14 minecraft:stone_block_slab 3
fill ~42~10~14 ~43~11~14 minecraft:iron_bars
fill ~42~12~14 ~44~12~14 minecraft:stonebrick 0
fill ~42~13~14 ~43~13~14 minecraft:stonebrick 0
setblock ~43~8~14 minecraft:stone_stairs 5
setblock ~44~8~14 minecraft:stone_stairs 6
fill ~44~10~14 ~44~11~14 minecraft:stonebrick 0
fill ~45~9~14 ~45~12~14 minecraft:iron_bars
setblock ~47~8~14 minecraft:stone_stairs 6
setblock ~47~9~14 minecraft:stonebrick 3
fill ~47~10~14 ~47~11~14 minecraft:log 1
setblock ~47~12~14 minecraft:stone_block_slab 3
setblock ~26~8~15 minecraft:stone_stairs 6
setblock ~26~9~15 minecraft:stonebrick 3
fill ~26~10~15 ~26~11~15 minecraft:log 1
setblock ~26~12~15 minecraft:stone_block_slab 3
fill ~28~8~15 ~29~9~15 minecraft:stonebrick 0
fill ~28~10~15 ~28~11~16 minecraft:iron_bars
fill ~28~12~15 ~31~12~15 minecraft:stonebrick 0
fill ~28~13~15 ~30~13~15 minecraft:stonebrick 0
setblock ~29~6~15 minecraft:stone_button 2
setblock ~29~7~15 minecraft:stone_stairs 6
fill ~29~10~15 ~29~11~15 minecraft:stonebrick 0
setblock ~30~8~15 minecraft:stone_stairs 4
fill ~30~9~15 ~31~9~15 minecraft:stonebrick 0
fill ~30~10~15 ~31~11~15 minecraft:iron_bars
setblock ~31~8~15 minecraft:stone_block_slab 3
setblock ~32~6~15 minecraft:stone_button 2
setblock ~32~7~15 minecraft:stone_stairs 6
fill ~32~8~15 ~44~8~15 minecraft:double_stone_block_slab 0
fill ~33~7~15 ~33~7~17 minecraft:stonebrick 0
setblock ~34~7~15 minecraft:stone_stairs 4
fill ~35~6~15 ~35~6~17 minecraft:log 1
fill ~35~7~15 ~36~7~17 minecraft:stonebrick 0
setblock ~36~0~15 minecraft:stone_brick_stairs 0
setblock ~36~2~15 minecraft:stone_button 4
setblock ~36~4~15 minecraft:stone_button 4
setblock ~36~6~15 minecraft:stone_brick_stairs 4
setblock ~37~0~15 minecraft:log 1
setblock ~37~1~15 minecraft:stonebrick 3
fill ~37~2~15 ~37~7~15 minecraft:log 1
setblock ~38~0~15 minecraft:stonebrick 0
setblock ~38~2~15 minecraft:log 1
setblock ~38~4~15 minecraft:log 1
fill ~38~6~15 ~38~6~17 minecraft:log 1
fill ~38~7~15 ~38~7~18 minecraft:stonebrick 0
setblock ~39~0~15 minecraft:log 1
setblock ~39~1~15 minecraft:stonebrick 3
fill ~39~2~15 ~39~7~15 minecraft:log 1
setblock ~40~0~15 minecraft:stone_brick_stairs 1
setblock ~40~2~15 minecraft:stone_button 5
setblock ~40~4~15 minecraft:stone_button 5
setblock ~40~6~15 minecraft:stone_brick_stairs 5
fill ~40~7~15 ~41~7~17 minecraft:stonebrick 0
fill ~41~6~15 ~41~6~17 minecraft:log 1
setblock ~42~7~15 minecraft:stone_stairs 5
fill ~43~7~15 ~43~7~17 minecraft:stonebrick 0
setblock ~44~6~15 minecraft:stone_button 2
setblock ~44~7~15 minecraft:stone_stairs 6
fill ~44~9~15 ~48~9~15 minecraft:stonebrick 0
setblock ~45~8~15 minecraft:stone_block_slab 3
fill ~45~10~15 ~46~11~15 minecraft:iron_bars
fill ~45~12~15 ~48~12~15 minecraft:stonebrick 0
setblock ~46~8~15 minecraft:stone_stairs 5
fill ~46~13~15 ~48~13~15 minecraft:stonebrick 0
setblock ~47~6~15 minecraft:stone_button 2
setblock ~47~7~15 minecraft:stone_stairs 6
fill ~47~8~15 ~48~8~15 minecraft:stonebrick 0
fill ~47~10~15 ~47~11~15 minecraft:stonebrick 0
fill ~48~10~15 ~48~11~16 minecraft:iron_bars
setblock ~50~8~15 minecraft:stone_stairs 6
setblock ~50~9~15 minecraft:stonebrick 3
fill ~50~10~15 ~50~11~15 minecraft:log 1
setblock ~50~12~15 minecraft:stone_block_slab 3
setblock ~23~8~16 minecraft:stone_stairs 6
setblock ~23~9~16 minecraft:stonebrick 3
fill ~23~10~16 ~23~11~16 minecraft:log 1
setblock ~23~12~16 minecraft:stone_block_slab 3
fill ~25~8~16 ~26~9~16 minecraft:stonebrick 0
fill ~25~10~16 ~25~11~17 minecraft:iron_bars
fill ~25~12~16 ~27~12~16 minecraft:stonebrick 0
setblock ~26~6~16 minecraft:stone_button 2
setblock ~26~7~16 minecraft:stone_stairs 6
fill ~26~10~16 ~26~11~16 minecraft:stonebrick 0
fill ~26~13~16 ~27~13~16 minecraft:stonebrick 0
setblock ~27~8~16 minecraft:stone_stairs 4
setblock ~27~9~16 minecraft:stonebrick 0
fill ~27~10~16 ~27~11~16 minecraft:iron_bars
setblock ~28~7~16 minecraft:stone_stairs 4
fill ~28~8~16 ~31~8~16 minecraft:double_stone_block_slab 0
setblock ~28~9~16 minecraft:iron_bars
setblock ~28~12~16 minecraft:iron_bars
fill ~29~6~16 ~29~6~18 minecraft:log 1
fill ~29~7~16 ~30~7~18 minecraft:stonebrick 0
setblock ~31~7~16 minecraft:stone_stairs 4
fill ~32~6~16 ~32~6~18 minecraft:log 1
fill ~32~7~16 ~32~7~18 minecraft:stonebrick 0
fill ~32~8~16 ~44~8~16 minecraft:stonebrick 0
setblock ~33~6~16 minecraft:stone_brick_stairs 5
setblock ~34~6~16 minecraft:stone_brick_stairs 4
fill ~34~7~16 ~34~7~17 minecraft:stonebrick 0
setblock ~36~6~16 minecraft:stone_brick_stairs 5
fill ~37~0~16 ~39~0~16 minecraft:stone_brick_stairs 3
fill ~37~2~16 ~37~2~19 minecraft:log 1
setblock ~37~6~16 minecraft:stone_brick_stairs 4
fill ~37~7~16 ~37~7~17 minecraft:stonebrick 0
fill ~38~4~16 ~38~4~19 minecraft:log 1
fill ~39~2~16 ~39~2~19 minecraft:log 1
setblock ~39~6~16 minecraft:stone_brick_stairs 5
fill ~39~7~16 ~39~7~17 minecraft:stonebrick 0
setblock ~40~6~16 minecraft:stone_brick_stairs 4
setblock ~42~6~16 minecraft:stone_brick_stairs 5
fill ~42~7~16 ~42~7~17 minecraft:stonebrick 0
setblock ~43~6~16 minecraft:stone_brick_stairs 4
fill ~44~6~16 ~44~6~18 minecraft:log 1
fill ~44~7~16 ~44~7~18 minecraft:stonebrick 0
setblock ~45~7~16 minecraft:stone_stairs 5
fill ~45~8~16 ~48~8~16 minecraft:double_stone_block_slab 0
fill ~46~7~16 ~47~7~18 minecraft:stonebrick 0
fill ~47~6~16 ~47~6~18 minecraft:log 1
setblock ~48~7~16 minecraft:stone_stairs 5
setblock ~48~9~16 minecraft:iron_bars
setblock ~48~12~16 minecraft:iron_bars
setblock ~49~8~16 minecraft:stone_stairs 5
fill ~49~9~16 ~51~9~16 minecraft:stonebrick 0
fill ~49~10~16 ~49~11~16 minecraft:iron_bars
fill ~49~12~16 ~51~12~16 minecraft:stonebrick 0
fill ~49~13~16 ~50~13~16 minecraft:stonebrick 0
setblock ~50~6~16 minecraft:stone_button 2
setblock ~50~7~16 minecraft:stone_stairs 6
fill ~50~8~16 ~51~8~16 minecraft:stonebrick 0
fill ~50~10~16 ~50~11~16 minecraft:stonebrick 0
fill ~51~10~16 ~51~11~17 minecraft:iron_bars
setblock ~53~8~16 minecraft:stone_stairs 6
setblock ~53~9~16 minecraft:stonebrick 3
fill ~53~10~16 ~53~11~16 minecraft:log 1
setblock ~53~12~16 minecraft:stone_block_slab 3
fill ~22~9~17 ~22~12~17 minecraft:iron_bars
setblock ~23~6~17 minecraft:stone_button 2
setblock ~23~7~17 minecraft:stone_stairs 6
fill ~23~8~17 ~23~13~17 minecraft:stonebrick 0
setblock ~24~8~17 minecraft:stone_stairs 4
setblock ~24~9~17 minecraft:stonebrick 0
fill ~24~10~17 ~24~11~17 minecraft:iron_bars
setblock ~24~12~17 minecraft:stonebrick 0
setblock ~25~7~17 minecraft:stone_stairs 4
fill ~25~8~17 ~27~8~17 minecraft:double_stone_block_slab 0
setblock ~25~9~17 minecraft:iron_bars
setblock ~25~12~17 minecraft:iron_bars
fill ~26~6~17 ~26~6~19 minecraft:log 1
fill ~26~7~17 ~28~7~17 minecraft:stonebrick 0
setblock ~27~6~17 minecraft:stone_brick_stairs 5
setblock ~28~6~17 minecraft:stone_brick_stairs 4
fill ~28~8~17 ~33~8~17 minecraft:stonebrick 0
setblock ~30~6~17 minecraft:stone_brick_stairs 5
setblock ~31~6~17 minecraft:stone_brick_stairs 4
fill ~31~7~17 ~31~7~18 minecraft:stonebrick 0
fill ~33~6~17 ~34~6~17 minecraft:nether_brick_fence
fill ~34~8~17 ~37~8~17 minecraft:stained_hardened_clay 4
fill ~36~6~17 ~37~6~17 minecraft:nether_brick_fence
setblock ~38~8~17 minecraft:stained_hardened_clay 1
fill ~39~6~17 ~40~6~17 minecraft:nether_brick_fence
fill ~39~8~17 ~42~8~17 minecraft:stained_hardened_clay 14
fill ~42~6~17 ~43~6~17 minecraft:nether_brick_fence
fill ~43~8~17 ~48~8~17 minecraft:stonebrick 0
setblock ~45~6~17 minecraft:stone_brick_stairs 5
fill ~45~7~17 ~45~7~18 minecraft:stonebrick 0
setblock ~46~6~17 minecraft:stone_brick_stairs 4
setblock ~48~6~17 minecraft:stone_brick_stairs 5
fill ~48~7~17 ~50~7~17 minecraft:stonebrick 0
setblock ~49~6~17 minecraft:stone_brick_stairs 4
fill ~49~8~17 ~51~8~17 minecraft:double_stone_block_slab 0
fill ~50~6~17 ~50~6~19 minecraft:log 1
setblock ~51~7~17 minecraft:stone_stairs 5
setblock ~51~9~17 minecraft:iron_bars
setblock ~51~12~17 minecraft:iron_bars
setblock ~52~8~17 minecraft:stone_stairs 5
fill ~52~9~17 ~53~9~17 minecraft:stonebrick 0
fill ~52~10~17 ~52~11~17 minecraft:iron_bars
fill ~52~12~17 ~53~12~17 minecraft:stonebrick 0
setblock ~53~6~17 minecraft:stone_button 2
setblock ~53~7~17 minecraft:stone_stairs 6
setblock ~53~8~17 minecraft:stonebrick 0
fill ~53~10~17 ~53~11~17 minecraft:stonebrick 0
setblock ~53~13~17 minecraft:stonebrick 0
fill ~54~9~17 ~54~12~17 minecraft:iron_bars
setblock ~20~8~18 minecraft:stone_stairs 6
setblock ~20~9~18 minecraft:stonebrick 3
fill ~20~10~18 ~20~11~18 minecraft:log 1
setblock ~20~12~18 minecraft:stone_block_slab 3
setblock ~21~8~18 minecraft:stone_stairs 4
fill ~21~9~18 ~22~9~18 minecraft:stonebrick 0
fill ~21~10~18 ~22~11~18 minecraft:iron_bars
fill ~21~12~18 ~22~13~18 minecraft:stonebrick 0
setblock ~22~7~18 minecraft:stone_stairs 4
setblock ~22~8~18 minecraft:stonebrick 0
fill ~23~6~18 ~23~6~21 minecraft:log 1
fill ~23~7~18 ~26~7~19 minecraft:stonebrick 0
fill ~23~8~18 ~24~8~18 minecraft:double_stone_block_slab 0
fill ~25~8~18 ~29~8~18 minecraft:stonebrick 0
fill ~27~6~18 ~28~6~18 minecraft:lit_redstone_lamp
fill ~27~7~18 ~28~7~18 minecraft:redstone_block
fill ~30~6~18 ~31~6~18 minecraft:nether_brick_fence
fill ~30~8~18 ~33~8~18 minecraft:stained_hardened_clay 4
fill ~33~6~18 ~34~6~18 minecraft:lit_redstone_lamp
fill ~33~7~18 ~34~7~18 minecraft:redstone_block
fill ~34~8~18 ~42~8~19 minecraft:stonebrick 0
setblock ~35~5~18 minecraft:stone_button 2
fill ~35~6~18 ~41~6~21 minecraft:stonebrick 0
fill ~37~9~18 ~37~11~18 minecraft:obsidian
setblock ~38~5~18 minecraft:stone_button 2
fill ~38~11~18 ~39~11~20 minecraft:obsidian
fill ~39~9~18 ~39~10~18 minecraft:obsidian
setblock ~41~5~18 minecraft:stone_button 2
fill ~42~6~18 ~43~6~18 minecraft:lit_redstone_lamp
fill ~42~7~18 ~43~7~18 minecraft:redstone_block
fill ~43~8~18 ~46~8~18 minecraft:stained_hardened_clay 14
fill ~45~6~18 ~46~6~18 minecraft:nether_brick_fence
fill ~47~8~18 ~51~8~18 minecraft:stonebrick 0
fill ~48~6~18 ~49~6~18 minecraft:lit_redstone_lamp
fill ~48~7~18 ~49~7~18 minecraft:redstone_block
fill ~50~7~18 ~53~7~20 minecraft:stonebrick 0
fill ~52~8~18 ~53~8~18 minecraft:double_stone_block_slab 0
fill ~53~6~18 ~53~6~21 minecraft:log 1
setblock ~54~7~18 minecraft:stone_stairs 5
fill ~54~8~18 ~54~9~18 minecraft:stonebrick 0
fill ~54~10~18 ~55~11~18 minecraft:iron_bars
fill ~54~12~18 ~55~13~18 minecraft:stonebrick 0
setblock ~55~8~18 minecraft:stone_stairs 5
setblock ~55~9~18 minecraft:stonebrick 0
setblock ~56~8~18 minecraft:stone_stairs 6
setblock ~56~9~18 minecraft:stonebrick 3
fill ~56~10~18 ~56~11~18 minecraft:log 1
setblock ~56~12~18 minecraft:stone_block_slab 3
setblock ~17~9~19 minecraft:cobblestone
setblock ~17~10~19 minecraft:stonebrick 3
setblock ~17~11~19 minecraft:log 1
setblock ~17~12~19 minecraft:stone_block_slab 3
fill ~19~8~19 ~20~9~19 minecraft:stonebrick 0
fill ~19~10~19 ~19~11~20 minecraft:iron_bars
fill ~19~12~19 ~20~13~19 minecraft:stonebrick 0
setblock ~20~6~19 minecraft:stone_button 2
setblock ~20~7~19 minecraft:stone_stairs 6
fill ~20~10~19 ~20~11~19 minecraft:stonebrick 0
fill ~21~7~19 ~22~7~20 minecraft:stonebrick 0
fill ~21~8~19 ~22~8~19 minecraft:double_stone_block_slab 0
fill ~23~8~19 ~26~8~19 minecraft:stonebrick 0
setblock ~24~6~19 minecraft:stone_brick_stairs 5
setblock ~25~6~19 minecraft:stone_brick_stairs 4
fill ~27~6~19 ~28~6~19 minecraft:nether_brick_fence
fill ~27~7~19 ~28~7~19 minecraft:stonebrick 0
fill ~27~8~19 ~29~8~19 minecraft:stained_hardened_clay 4
setblock ~29~5~19 minecraft:stone_button 2
fill ~29~6~19 ~34~6~20 minecraft:stonebrick 0
fill ~30~8~19 ~33~8~20 minecraft:stonebrick 0
setblock ~32~5~19 minecraft:stone_button 2
fill ~33~0~19 ~34~0~19 minecraft:stone_brick_stairs 2
fill ~33~1~19 ~34~1~19 minecraft:stone_stairs 6
fill ~33~2~19 ~34~2~19 minecraft:iron_bars
fill ~33~3~19 ~34~3~19 minecraft:stone_stairs 2
fill ~33~4~19 ~34~4~19 minecraft:stone_brick_stairs 6
fill ~33~5~19 ~34~5~19 minecraft:stonebrick 3
setblock ~35~0~19 minecraft:stone_stairs 6
fill ~35~1~19 ~35~3~19 minecraft:cobblestone_wall 0
setblock ~35~4~19 minecraft:stone_stairs 2
setblock ~35~5~19 minecraft:log 1
fill ~36~0~19 ~37~0~19 minecraft:stone_brick_stairs 2
fill ~36~1~19 ~37~1~19 minecraft:stone_stairs 6
setblock ~36~2~19 minecraft:iron_bars
fill ~36~3~19 ~37~3~19 minecraft:stone_stairs 2
fill ~36~4~19 ~37~4~19 minecraft:stone_brick_stairs 6
fill ~36~5~19 ~37~5~19 minecraft:stonebrick 3
fill ~36~9~19 ~36~11~19 minecraft:obsidian
fill ~37~11~19 ~37~11~20 minecraft:obsidian
setblock ~38~0~19 minecraft:stone_stairs 6
fill ~38~1~19 ~38~3~19 minecraft:cobblestone_wall 0
setblock ~38~5~19 minecraft:log 1
fill ~39~0~19 ~40~0~19 minecraft:stone_brick_stairs 2
fill ~39~1~19 ~40~1~19 minecraft:stone_stairs 6
fill ~39~3~19 ~40~3~19 minecraft:stone_stairs 2
fill ~39~4~19 ~40~4~19 minecraft:stone_brick_stairs 6
fill ~39~5~19 ~40~5~19 minecraft:stonebrick 3
setblock ~40~2~19 minecraft:iron_bars
fill ~40~9~19 ~40~11~19 minecraft:obsidian
setblock ~41~0~19 minecraft:stone_stairs 6
fill ~41~1~19 ~41~3~19 minecraft:cobblestone_wall 0
setblock ~41~4~19 minecraft:stone_stairs 2
setblock ~41~5~19 minecraft:log 1
fill ~42~0~19 ~43~0~19 minecraft:stone_brick_stairs 2
fill ~42~1~19 ~43~1~19 minecraft:stone_stairs 6
fill ~42~2~19 ~43~2~19 minecraft:iron_bars
fill ~42~3~19 ~43~3~19 minecraft:stone_stairs 2
fill ~42~4~19 ~43~4~19 minecraft:stone_brick_stairs 6
fill ~42~5~19 ~43~5~19 minecraft:stonebrick 3
fill ~42~6~19 ~47~6~20 minecraft:stonebrick 0
fill ~43~8~19 ~46~8~20 minecraft:stonebrick 0
setblock ~44~5~19 minecraft:stone_button 2
setblock ~47~5~19 minecraft:stone_button 2
fill ~47~7~19 ~49~7~19 minecraft:stonebrick 0
fill ~47~8~19 ~49~8~19 minecraft:stained_hardened_clay 14
fill ~48~6~19 ~49~6~19 minecraft:nether_brick_fence
fill ~50~8~19 ~53~8~19 minecraft:stonebrick 0
setblock ~51~6~19 minecraft:stone_brick_stairs 5
setblock ~52~6~19 minecraft:stone_brick_stairs 4
fill ~54~7~19 ~55~7~20 minecraft:stonebrick 0
fill ~54~8~19 ~55~8~19 minecraft:double_stone_block_slab 0
setblock ~56~6~19 minecraft:stone_button 2
setblock ~56~7~19 minecraft:stone_stairs 6
fill ~56~8~19 ~57~9~19 minecraft:stonebrick 0
fill ~56~10~19 ~56~13~19 minecraft:stonebrick 0
fill ~57~10~19 ~57~11~20 minecraft:iron_bars
fill ~57~12~19 ~57~13~19 minecraft:stonebrick 0
setblock ~59~9~19 minecraft:cobblestone
setblock ~59~10~19 minecraft:stonebrick 3
setblock ~59~11~19 minecraft:log 1
setblock ~59~12~19 minecraft:stone_block_slab 3
fill ~16~9~20 ~16~12~20 minecraft:iron_bars
setblock ~17~8~20 minecraft:stone_stairs 6
fill ~17~9~20 ~18~9~20 minecraft:stonebrick 0
fill ~17~10~20 ~17~12~20 minecraft:stonebrick 0
setblock ~18~8~20 minecraft:stone_stairs 4
fill ~18~10~20 ~18~11~20 minecraft:iron_bars
setblock ~18~12~20 minecraft:stonebrick 0
setblock ~19~7~20 minecraft:stone_stairs 4
fill ~19~8~20 ~20~8~20 minecraft:double_stone_block_slab 0
setblock ~19~9~20 minecraft:iron_bars
setblock ~19~12~20 minecraft:iron_bars
fill ~20~6~20 ~20~6~22 minecraft:log 1
fill ~20~7~20 ~20~7~22 minecraft:stonebrick 0
setblock ~21~6~20 minecraft:stone_brick_stairs 5
fill ~21~8~20 ~23~8~20 minecraft:stonebrick 0
setblock ~22~6~20 minecraft:stone_brick_stairs 4
fill ~23~7~20 ~25~7~20 minecraft:stonebrick 0
fill ~24~6~20 ~25~6~20 minecraft:nether_brick_fence
fill ~24~8~20 ~26~8~20 minecraft:stained_hardened_clay 4
setblock ~26~5~20 minecraft:stone_button 2
fill ~26~6~20 ~28~6~21 minecraft:stonebrick 0
fill ~27~8~20 ~29~8~21 minecraft:stonebrick 0
setblock ~29~0~20 minecraft:stone_stairs 6
fill ~29~1~20 ~29~3~20 minecraft:cobblestone_wall 0
setblock ~29~4~20 minecraft:stone_stairs 2
setblock ~29~5~20 minecraft:log 1
fill ~30~0~20 ~31~0~20 minecraft:stone_brick_stairs 2
fill ~30~1~20 ~31~1~20 minecraft:stone_stairs 6
fill ~30~2~20 ~31~2~20 minecraft:iron_bars
fill ~30~3~20 ~31~3~20 minecraft:stone_stairs 2
fill ~30~4~20 ~31~4~20 minecraft:stone_brick_stairs 6
fill ~30~5~20 ~31~5~20 minecraft:stonebrick 3
setblock ~32~0~20 minecraft:stone_stairs 6
fill ~32~1~20 ~32~3~20 minecraft:cobblestone_wall 0
setblock ~32~4~20 minecraft:stone_stairs 2
setblock ~32~5~20 minecraft:log 1
fill ~33~0~20 ~43~0~21 minecraft:stonebrick 0
fill ~33~1~20 ~34~1~21 minecraft:stonebrick 0
fill ~33~2~20 ~43~2~20 minecraft:brick_block
fill ~33~3~20 ~34~5~21 minecraft:stonebrick 0
fill ~34~8~20 ~35~8~21 minecraft:stonebrick 0
setblock ~35~1~20 minecraft:brick_block
setblock ~35~3~20 minecraft:brick_block
fill ~35~4~20 ~43~4~21 minecraft:stonebrick 0
fill ~35~5~20 ~43~5~20 minecraft:stonebrick 0
fill ~35~9~20 ~35~11~21 minecraft:obsidian
fill ~36~1~20 ~37~1~21 minecraft:stonebrick 0
fill ~36~3~20 ~37~3~20 minecraft:stonebrick 0
fill ~36~7~20 ~36~7~21 minecraft:stonebrick 0
setblock ~36~8~20 minecraft:glowstone
setblock ~36~11~20 minecraft:obsidian
fill ~37~8~20 ~39~8~20 minecraft:stonebrick 0
setblock ~38~1~20 minecraft:brick_block
setblock ~38~3~20 minecraft:brick_block
fill ~39~1~20 ~40~1~21 minecraft:stonebrick 0
fill ~39~3~20 ~40~3~21 minecraft:stonebrick 0
setblock ~40~8~20 minecraft:glowstone
fill ~40~11~20 ~41~11~20 minecraft:obsidian
setblock ~41~1~20 minecraft:brick_block
setblock ~41~3~20 minecraft:brick_block
fill ~41~8~20 ~42~8~21 minecraft:stonebrick 0
fill ~41~9~20 ~41~10~21 minecraft:obsidian
fill ~42~1~20 ~43~1~20 minecraft:stonebrick 0
fill ~42~3~20 ~43~3~20 minecraft:stonebrick 0
setblock ~44~0~20 minecraft:stone_stairs 6
fill ~44~1~20 ~44~3~20 minecraft:cobblestone_wall 0
setblock ~44~4~20 minecraft:stone_stairs 2
setblock ~44~5~20 minecraft:log 1
fill ~45~0~20 ~46~0~20 minecraft:stone_brick_stairs 2
fill ~45~1~20 ~46~1~20 minecraft:stone_stairs 6
fill ~45~2~20 ~46~2~20 minecraft:iron_bars
fill ~45~3~20 ~46~3~20 minecraft:stone_stairs 2
fill ~45~4~20 ~46~4~20 minecraft:stone_brick_stairs 6
fill ~45~5~20 ~46~5~20 minecraft:stonebrick 3
setblock ~47~0~20 minecraft:stone_stairs 6
fill ~47~1~20 ~47~3~20 minecraft:cobblestone_wall 0
setblock ~47~4~20 minecraft:stone_stairs 2
setblock ~47~5~20 minecraft:log 1
fill ~47~8~20 ~49~8~21 minecraft:stonebrick 0
fill ~48~6~20 ~50~6~21 minecraft:stonebrick 0
setblock ~50~5~20 minecraft:stone_button 2
fill ~50~8~20 ~52~8~20 minecraft:stained_hardened_clay 14
fill ~51~6~20 ~52~6~20 minecraft:nether_brick_fence
fill ~53~8~20 ~55~8~20 minecraft:stonebrick 0
setblock ~54~6~20 minecraft:stone_brick_stairs 5
setblock ~55~6~20 minecraft:stone_brick_stairs 4
fill ~56~6~20 ~56~6~22 minecraft:log 1
fill ~56~7~20 ~56~7~22 minecraft:stonebrick 0
fill ~56~8~20 ~57~8~20 minecraft:double_stone_block_slab 0
setblock ~57~7~20 minecraft:stone_stairs 5
setblock ~57~9~20 minecraft:iron_bars
setblock ~57~12~20 minecraft:iron_bars
setblock ~58~8~20 minecraft:stone_stairs 5
fill ~58~9~20 ~59~9~20 minecraft:stonebrick 0
fill ~58~10~20 ~58~11~20 minecraft:iron_bars
fill ~58~12~20 ~59~12~20 minecraft:stonebrick 0
setblock ~59~8~20 minecraft:stone_stairs 6
fill ~59~10~20 ~59~11~20 minecraft:stonebrick 0
fill ~60~9~20 ~60~12~20 minecraft:iron_bars
fill ~15~9~21 ~15~12~21 minecraft:iron_bars
fill ~16~8~21 ~17~8~21 minecraft:stonebrick 0
setblock ~16~9~21 minecraft:stonebrick 0
fill ~16~10~21 ~16~11~21 minecraft:iron_bars
fill ~16~12~21 ~16~13~21 minecraft:stonebrick 0
setblock ~17~6~21 minecraft:stone_button 2
setblock ~17~7~21 minecraft:stone_stairs 6
fill ~18~7~21 ~19~7~23 minecraft:stonebrick 0
setblock ~18~8~21 minecraft:double_stone_block_slab 0
fill ~19~8~21 ~21~8~21 minecraft:stonebrick 0
setblock ~21~6~21 minecraft:lit_redstone_lamp
setblock ~21~7~21 minecraft:redstone_block
setblock ~22~6~21 minecraft:nether_brick_fence
fill ~22~7~21 ~23~7~21 minecraft:stonebrick 0
fill ~22~8~21 ~23~8~21 minecraft:stained_hardened_clay 4
fill ~24~6~21 ~25~6~22 minecraft:stonebrick 0
fill ~24~8~21 ~26~8~22 minecraft:stonebrick 0
setblock ~26~0~21 minecraft:stone_stairs 6
fill ~26~1~21 ~26~3~21 minecraft:cobblestone_wall 0
setblock ~26~4~21 minecraft:stone_stairs 2
setblock ~26~5~21 minecraft:log 1
fill ~27~0~21 ~28~0~21 minecraft:stone_brick_stairs 2
fill ~27~1~21 ~28~1~21 minecraft:stone_stairs 6
fill ~27~2~21 ~28~2~21 minecraft:iron_bars
fill ~27~3~21 ~28~3~21 minecraft:stone_stairs 2
fill ~27~4~21 ~28~4~21 minecraft:stone_brick_stairs 6
fill ~27~5~21 ~28~5~21 minecraft:stonebrick 3
fill ~29~0~21 ~32~0~22 minecraft:stonebrick 0
fill ~29~1~21 ~29~3~21 minecraft:brick_block
fill ~29~4~21 ~32~4~22 minecraft:stonebrick 0
fill ~29~5~21 ~32~5~21 minecraft:stonebrick 0
fill ~30~1~21 ~31~1~21 minecraft:stonebrick 0
fill ~30~2~21 ~32~2~21 minecraft:brick_block
fill ~30~3~21 ~31~3~21 minecraft:stonebrick 0
fill ~30~8~21 ~31~8~21 minecraft:stonebrick 0
setblock ~32~1~21 minecraft:brick_block
setblock ~32~3~21 minecraft:brick_block
setblock ~32~8~21 minecraft:redstone_torch 5
setblock ~32~9~21 minecraft:log 1
setblock ~32~10~21 minecraft:lit_redstone_lamp
fill ~32~11~21 ~32~11~22 minecraft:stone_block_slab 3
setblock ~33~2~21 minecraft:stonebrick 1
setblock ~33~6~21 minecraft:stonebrick 1
fill ~33~7~21 ~35~7~21 minecraft:stonebrick 0
setblock ~33~8~21 minecraft:double_stone_block_slab 0
fill ~33~9~21 ~33~9~22 minecraft:stonebrick 0
fill ~34~2~21 ~35~2~21 minecraft:stonebrick 0
fill ~34~6~21 ~34~6~22 minecraft:stonebrick 0
setblock ~35~1~21 minecraft:stonebrick 0
setblock ~35~3~21 minecraft:stonebrick 0
fill ~35~5~21 ~36~5~21 minecraft:stonebrick 0
setblock ~36~2~21 minecraft:stonebrick 1
setblock ~36~3~21 minecraft:stonebrick 2
fill ~36~8~21 ~37~8~21 minecraft:double_stone_block_slab 0
fill ~36~11~21 ~40~11~21 minecraft:glass
fill ~37~2~21 ~39~2~21 minecraft:stonebrick 0
fill ~37~3~21 ~38~3~21 minecraft:stonebrick 0
fill ~37~5~21 ~37~5~22 minecraft:stonebrick 2
fill ~37~7~21 ~37~7~22 minecraft:stonebrick 0
fill ~37~9~21 ~39~10~21 minecraft:glass
setblock ~38~1~21 minecraft:stonebrick 0
fill ~38~5~21 ~42~5~21 minecraft:stonebrick 0
setblock ~38~8~21 minecraft:stonebrick 0
fill ~39~7~21 ~42~7~21 minecraft:stonebrick 0
fill ~39~8~21 ~40~8~21 minecraft:double_stone_block_slab 0
setblock ~40~2~21 minecraft:stonebrick 2
fill ~41~1~21 ~42~3~21 minecraft:stonebrick 0
setblock ~41~11~21 minecraft:obsidian
setblock ~42~6~21 minecraft:stonebrick 0
setblock ~43~1~21 minecraft:stonebrick 2
fill ~43~2~21 ~43~3~21 minecraft:stonebrick 1
setblock ~43~5~21 minecraft:stonebrick 2
setblock ~43~6~21 minecraft:stonebrick 1
setblock ~43~7~21 minecraft:stonebrick 2
setblock ~43~8~21 minecraft:double_stone_block_slab 0
fill ~43~9~21 ~43~9~22 minecraft:stonebrick 0
fill ~44~0~21 ~47~0~22 minecraft:stonebrick 0
fill ~44~1~21 ~44~3~21 minecraft:brick_block
fill ~44~4~21 ~47~4~22 minecraft:stonebrick 0
fill ~44~5~21 ~47~5~21 minecraft:stonebrick 0
setblock ~44~7~21 minecraft:stonebrick 0
setblock ~44~8~21 minecraft:redstone_torch 5
setblock ~44~9~21 minecraft:log 1
setblock ~44~10~21 minecraft:lit_redstone_lamp
fill ~44~11~21 ~44~11~22 minecraft:stone_block_slab 3
fill ~45~1~21 ~46~1~22 minecraft:stonebrick 0
fill ~45~2~21 ~47~2~21 minecraft:brick_block
fill ~45~3~21 ~46~3~21 minecraft:stonebrick 0
fill ~45~8~21 ~46~8~21 minecraft:stonebrick 0
setblock ~47~1~21 minecraft:brick_block
setblock ~47~3~21 minecraft:brick_block
fill ~48~0~21 ~49~0~21 minecraft:stone_brick_stairs 2
fill ~48~1~21 ~49~1~21 minecraft:stone_stairs 6
fill ~48~2~21 ~49~2~21 minecraft:iron_bars
fill ~48~3~21 ~49~3~21 minecraft:stone_stairs 2
fill ~48~4~21 ~49~4~21 minecraft:stone_brick_stairs 6
fill ~48~5~21 ~49~5~21 minecraft:stonebrick 3
setblock ~50~0~21 minecraft:stone_stairs 6
fill ~50~1~21 ~50~3~21 minecraft:cobblestone_wall 0
setblock ~50~4~21 minecraft:stone_stairs 2
setblock ~50~5~21 minecraft:log 1
fill ~50~8~21 ~52~8~22 minecraft:stonebrick 0
fill ~51~6~21 ~52~6~22 minecraft:stonebrick 0
fill ~53~7~21 ~54~7~21 minecraft:stonebrick 0
fill ~53~8~21 ~54~8~21 minecraft:stained_hardened_clay 14
setblock ~54~6~21 minecraft:nether_brick_fence
setblock ~55~6~21 minecraft:lit_redstone_lamp
setblock ~55~7~21 minecraft:redstone_block
fill ~55~8~21 ~57~8~21 minecraft:stonebrick 0
fill ~57~7~21 ~58~7~23 minecraft:stonebrick 0
setblock ~58~8~21 minecraft:double_stone_block_slab 0
setblock ~59~6~21 minecraft:stone_button 2
setblock ~59~7~21 minecraft:stone_stairs 6
fill ~59~8~21 ~60~8~21 minecraft:stonebrick 0
setblock ~60~9~21 minecraft:stonebrick 0
fill ~60~10~21 ~61~11~21 minecraft:iron_bars
fill ~60~12~21 ~60~13~21 minecraft:stonebrick 0
setblock ~61~9~21 minecraft:iron_bars
setblock ~61~12~21 minecraft:iron_bars
setblock ~14~9~22 minecraft:cobblestone
setblock ~14~10~22 minecraft:stonebrick 3
setblock ~14~11~22 minecraft:log 1
setblock ~14~12~22 minecraft:stone_block_slab 3
setblock ~15~8~22 minecraft:stone_stairs 4
fill ~15~9~22 ~15~13~22 minecraft:stonebrick 0
setblock ~16~7~22 minecraft:stone_stairs 4
fill ~16~8~22 ~17~8~22 minecraft:double_stone_block_slab 0
fill ~17~6~22 ~17~6~25 minecraft:log 1
fill ~17~7~22 ~17~7~25 minecraft:stonebrick 0
setblock ~18~6~22 minecraft:stone_brick_stairs 5
fill ~18~8~22 ~19~8~22 minecraft:stonebrick 0
setblock ~19~6~22 minecraft:stone_brick_stairs 4
fill ~20~8~22 ~21~8~22 minecraft:stained_hardened_clay 4
setblock ~21~6~22 minecraft:nether_brick_fence
setblock ~21~7~22 minecraft:stonebrick 0
fill ~22~6~22 ~23~6~23 minecraft:stonebrick 0
fill ~22~8~22 ~23~8~24 minecraft:stonebrick 0
setblock ~23~5~22 minecraft:stone_button 2
fill ~24~0~22 ~25~0~22 minecraft:stone_brick_stairs 2
fill ~24~1~22 ~25~1~22 minecraft:stone_stairs 6
fill ~24~2~22 ~25~2~22 minecraft:iron_bars
fill ~24~3~22 ~25~3~22 minecraft:stone_stairs 2
fill ~24~4~22 ~25~4~22 minecraft:stone_brick_stairs 6
fill ~24~5~22 ~25~5~22 minecraft:stonebrick 3
fill ~26~0~22 ~28~0~23 minecraft:stonebrick 0
fill ~26~1~22 ~26~3~22 minecraft:brick_block
fill ~26~4~22 ~28~4~23 minecraft:stonebrick 0
fill ~26~5~22 ~29~5~22 minecraft:stonebrick 0
fill ~27~1~22 ~29~1~22 minecraft:stonebrick 0
fill ~27~2~22 ~28~2~22 minecraft:brick_block
fill ~27~3~22 ~30~3~22 minecraft:stonebrick 0
fill ~27~8~22 ~28~8~22 minecraft:stonebrick 0
fill ~29~2~22 ~31~2~22 minecraft:stonebrick 0
fill ~29~6~22 ~31~6~22 minecraft:stonebrick 0
setblock ~29~7~22 minecraft:stonebrick 2
fill ~29~8~22 ~32~8~22 minecraft:double_stone_block_slab 0
fill ~29~9~22 ~32~9~22 minecraft:stonebrick 0
setblock ~30~1~22 minecraft:stonebrick 2
fill ~30~5~22 ~31~5~22 minecraft:stonebrick 2
fill ~30~7~22 ~32~7~22 minecraft:stonebrick 0
setblock ~30~10~22 minecraft:stonebrick 1
setblock ~30~11~22 minecraft:stone_block_slab 3
fill ~31~1~22 ~32~1~22 minecraft:stonebrick 0
setblock ~31~3~22 minecraft:stonebrick 2
setblock ~32~2~22 minecraft:stonebrick 2
setblock ~32~3~22 minecraft:stonebrick 0
setblock ~32~5~22 minecraft:stonebrick 1
setblock ~32~6~22 minecraft:stonebrick 2
setblock ~32~10~22 minecraft:stonebrick 0
fill ~33~0~22 ~34~0~25 minecraft:grass
fill ~33~1~22 ~33~6~22 minecraft:vine 14
setblock ~33~7~22 minecraft:vine 4
fill ~33~11~22 ~33~11~23 minecraft:stone_block_slab 11
setblock ~34~2~22 minecraft:stonebrick 0
setblock ~34~3~22 minecraft:stonebrick 1
fill ~34~4~22 ~35~4~22 minecraft:stonebrick 0
setblock ~34~5~22 minecraft:stonebrick 2
fill ~34~7~22 ~35~7~22 minecraft:stonebrick 0
fill ~34~8~22 ~35~8~22 minecraft:double_stone_block_slab 0
fill ~34~9~22 ~34~10~22 minecraft:stonebrick 0
setblock ~34~11~22 minecraft:stone_block_slab 3
setblock ~35~0~22 minecraft:dirt 0
setblock ~35~1~22 minecraft:stonebrick 2
setblock ~35~2~22 minecraft:stonebrick 1
setblock ~35~3~22 minecraft:stonebrick 2
setblock ~35~5~22 minecraft:stonebrick 0
setblock ~35~6~22 minecraft:stonebrick 2
fill ~36~0~22 ~36~0~26 minecraft:grass
setblock ~36~1~22 minecraft:vine 12
fill ~36~2~22 ~36~8~22 minecraft:vine 4
fill ~37~0~22 ~39~0~22 minecraft:dirt 0
setblock ~37~1~22 minecraft:stonebrick 1
setblock ~37~2~22 minecraft:stonebrick 0
setblock ~37~3~22 minecraft:stonebrick 1
setblock ~37~4~22 minecraft:stonebrick 0
fill ~37~6~22 ~39~6~22 minecraft:stonebrick 0
fill ~37~8~22 ~39~8~22 minecraft:double_stone_block_slab 0
fill ~38~1~22 ~38~2~22 minecraft:stonebrick 2
setblock ~38~3~22 minecraft:stonebrick 0
setblock ~38~4~22 minecraft:stonebrick 1
setblock ~38~5~22 minecraft:stonebrick 2
setblock ~38~7~22 minecraft:stonebrick 1
fill ~39~1~22 ~39~2~22 minecraft:stonebrick 0
setblock ~39~3~22 minecraft:stonebrick 2
fill ~39~4~22 ~39~5~22 minecraft:stonebrick 0
setblock ~39~7~22 minecraft:stonebrick 0
fill ~40~0~22 ~40~0~24 minecraft:grass
fill ~40~1~22 ~40~8~22 minecraft:vine 4
fill ~41~0~22 ~42~0~22 minecraft:dirt 0
setblock ~41~1~22 minecraft:stonebrick 0
fill ~41~2~22 ~41~3~22 minecraft:stonebrick 1
fill ~41~4~22 ~42~4~22 minecraft:stonebrick 0
setblock ~41~5~22 minecraft:stonebrick 2
fill ~41~6~22 ~41~7~22 minecraft:stonebrick 0
fill ~41~8~22 ~42~8~22 minecraft:double_stone_block_slab 0
setblock ~42~1~22 minecraft:stonebrick 2
fill ~42~2~22 ~42~3~22 minecraft:stonebrick 0
setblock ~42~5~22 minecraft:stonebrick 0
setblock ~42~6~22 minecraft:stonebrick 1
setblock ~42~7~22 minecraft:stonebrick 0
fill ~42~9~22 ~42~10~22 minecraft:stonebrick 0
setblock ~42~11~22 minecraft:stone_block_slab 3
fill ~43~0~22 ~43~0~24 minecraft:grass
fill ~43~1~22 ~43~6~22 minecraft:vine 14
setblock ~43~7~22 minecraft:vine 12
setblock ~43~8~22 minecraft:vine 4
fill ~43~11~22 ~43~11~23 minecraft:stone_block_slab 11
fill ~44~1~22 ~44~3~22 minecraft:stonebrick 0
fill ~44~5~22 ~44~6~22 minecraft:stonebrick 0
setblock ~44~7~22 minecraft:stonebrick 2
fill ~44~8~22 ~47~8~22 minecraft:double_stone_block_slab 0
fill ~44~9~22 ~47~9~22 minecraft:stonebrick 0
setblock ~44~10~22 minecraft:stonebrick 0
setblock ~45~2~22 minecraft:stonebrick 1
setblock ~45~3~22 minecraft:stonebrick 2
setblock ~45~5~22 minecraft:stonebrick 2
fill ~45~6~22 ~46~7~22 minecraft:stonebrick 0
fill ~46~2~22 ~47~2~22 minecraft:stonebrick 0
setblock ~46~3~22 minecraft:stonebrick 0
setblock ~46~5~22 minecraft:stonebrick 0
setblock ~46~10~22 minecraft:stonebrick 0
setblock ~46~11~22 minecraft:stone_block_slab 3
fill ~47~1~22 ~49~1~22 minecraft:stonebrick 0
setblock ~47~3~22 minecraft:stonebrick 1
setblock ~47~5~22 minecraft:stonebrick 1
setblock ~47~6~22 minecraft:stonebrick 2
setblock ~47~7~22 minecraft:stonebrick 0
fill ~48~0~22 ~50~0~23 minecraft:stonebrick 0
fill ~48~2~22 ~50~2~22 minecraft:brick_block
fill ~48~3~22 ~49~5~22 minecraft:stonebrick 0
fill ~48~8~22 ~49~8~22 minecraft:stonebrick 0
setblock ~50~1~22 minecraft:brick_block
setblock ~50~3~22 minecraft:brick_block
fill ~50~4~22 ~50~5~23 minecraft:stonebrick 0
fill ~51~0~22 ~52~0~22 minecraft:stone_brick_stairs 2
fill ~51~1~22 ~52~1~22 minecraft:stone_stairs 6
fill ~51~2~22 ~52~2~22 minecraft:iron_bars
fill ~51~3~22 ~52~3~22 minecraft:stone_stairs 2
fill ~51~4~22 ~52~4~22 minecraft:stone_brick_stairs 6
fill ~51~5~22 ~52~5~22 minecraft:stonebrick 3
setblock ~53~5~22 minecraft:stone_button 2
fill ~53~6~22 ~54~6~23 minecraft:stonebrick 0
fill ~53~8~22 ~54~8~24 minecraft:stonebrick 0
setblock ~55~6~22 minecraft:nether_brick_fence
setblock ~55~7~22 minecraft:stonebrick 0
fill ~55~8~22 ~56~8~22 minecraft:stained_hardened_clay 14
setblock ~57~6~22 minecraft:stone_brick_stairs 5
fill ~57~8~22 ~58~8~22 minecraft:stonebrick 0
setblock ~58~6~22 minecraft:stone_brick_stairs 4
fill ~59~6~22 ~59~6~25 minecraft:log 1
fill ~59~7~22 ~59~7~25 minecraft:stonebrick 0
fill ~59~8~22 ~60~8~22 minecraft:double_stone_block_slab 0
setblock ~60~7~22 minecraft:stone_stairs 5
setblock ~61~8~22 minecraft:stone_stairs 5
fill ~61~9~22 ~61~13~22 minecraft:stonebrick 0
setblock ~62~9~22 minecraft:cobblestone
setblock ~62~10~22 minecraft:stonebrick 3
setblock ~62~11~22 minecraft:log 1
setblock ~62~12~22 minecraft:stone_block_slab 3
fill ~13~9~23 ~13~12~23 minecraft:iron_bars
setblock ~14~8~23 minecraft:stone_stairs 6
setblock ~14~9~23 minecraft:stonebrick 0
fill ~14~10~23 ~14~11~23 minecraft:iron_bars
fill ~14~12~23 ~14~13~23 minecraft:stonebrick 0
setblock ~15~8~23 minecraft:double_stone_block_slab 0
fill ~16~7~23 ~16~7~28 minecraft:stonebrick 0
fill ~16~8~23 ~17~8~23 minecraft:stonebrick 0
fill ~18~8~23 ~19~8~23 minecraft:stained_hardened_clay 4
setblock ~19~6~23 minecraft:nether_brick_fence
fill ~20~6~23 ~21~6~24 minecraft:stonebrick 0
fill ~20~8~23 ~21~8~25 minecraft:stonebrick 0
fill ~21~2~23 ~22~2~23 minecraft:iron_bars
setblock ~22~0~23 minecraft:stone_brick_stairs 2
setblock ~22~1~23 minecraft:stone_stairs 6
setblock ~22~3~23 minecraft:stone_stairs 2
setblock ~22~4~23 minecraft:stone_brick_stairs 6
setblock ~22~5~23 minecraft:stonebrick 3
setblock ~23~0~23 minecraft:stone_stairs 6
fill ~23~1~23 ~23~3~23 minecraft:cobblestone_wall 0
setblock ~23~4~23 minecraft:stone_stairs 2
setblock ~23~5~23 minecraft:log 1
fill ~24~0~23 ~25~0~24 minecraft:stonebrick 0
fill ~24~1~23 ~27~1~23 minecraft:stonebrick 0
fill ~24~2~23 ~25~2~23 minecraft:brick_block
fill ~24~3~23 ~25~5~23 minecraft:stonebrick 0
setblock ~24~8~23 minecraft:stonebrick 0
setblock ~25~8~23 minecraft:redstone_torch 5
setblock ~25~9~23 minecraft:log 1
setblock ~25~10~23 minecraft:lit_redstone_lamp
fill ~25~11~23 ~26~11~23 minecraft:stone_block_slab 3
setblock ~26~2~23 minecraft:stonebrick 2
setblock ~26~3~23 minecraft:stonebrick 1
fill ~26~5~23 ~26~7~23 minecraft:stonebrick 0
fill ~26~8~23 ~28~8~23 minecraft:double_stone_block_slab 0
fill ~26~9~23 ~28~9~23 minecraft:stonebrick 0
setblock ~26~10~23 minecraft:stonebrick 0
setblock ~27~2~23 minecraft:stonebrick 0
setblock ~27~3~23 minecraft:stonebrick 2
fill ~27~5~23 ~28~5~23 minecraft:stonebrick 2
fill ~27~6~23 ~28~6~23 minecraft:stonebrick 0
setblock ~27~7~23 minecraft:stonebrick 2
setblock ~28~1~23 minecraft:stonebrick 1
setblock ~28~2~23 minecraft:stonebrick 2
setblock ~28~3~23 minecraft:stonebrick 1
setblock ~28~7~23 minecraft:stonebrick 0
setblock ~28~10~23 minecraft:stonebrick 0
setblock ~28~11~23 minecraft:stone_block_slab 3
fill ~29~0~23 ~32~0~24 minecraft:grass
fill ~29~1~23 ~29~3~23 minecraft:vine 2
fill ~29~11~23 ~32~11~23 minecraft:stone_block_slab 11
fill ~31~1~23 ~32~6~23 minecraft:vine 4
fill ~34~1~23 ~35~3~23 minecraft:vine 4
fill ~34~4~23 ~34~6~23 minecraft:vine 4
fill ~35~0~23 ~35~0~26 minecraft:grass
fill ~37~0~23 ~39~0~24 minecraft:grass
fill ~37~1~23 ~37~2~23 minecraft:vine 4
fill ~39~1~23 ~39~3~23 minecraft:vine 4
fill ~41~0~23 ~42~0~24 minecraft:grass
fill ~44~0~23 ~47~0~24 minecraft:grass
fill ~44~1~23 ~45~8~23 minecraft:vine 4
fill ~44~11~23 ~47~11~23 minecraft:stone_block_slab 11
setblock ~47~1~23 minecraft:vine 8
setblock ~48~1~23 minecraft:stonebrick 1
setblock ~48~2~23 minecraft:stonebrick 0
setblock ~48~3~23 minecraft:stonebrick 1
fill ~48~4~23 ~49~5~23 minecraft:stonebrick 0
fill ~48~6~23 ~48~7~23 minecraft:stonebrick 0
fill ~48~8~23 ~50~8~23 minecraft:double_stone_block_slab 0
fill ~48~9~23 ~50~9~23 minecraft:stonebrick 0
setblock ~48~10~23 minecraft:stonebrick 0
setblock ~48~11~23 minecraft:stone_block_slab 3
fill ~49~1~23 ~50~1~23 minecraft:stonebrick 2
setblock ~49~2~23 minecraft:stonebrick 1
setblock ~49~3~23 minecraft:stonebrick 0
setblock ~49~6~23 minecraft:stonebrick 2
setblock ~49~7~23 minecraft:stonebrick 0
setblock ~50~2~23 minecraft:stonebrick 2
setblock ~50~3~23 minecraft:stonebrick 1
setblock ~50~6~23 minecraft:stonebrick 0
setblock ~50~7~23 minecraft:stonebrick 1
setblock ~50~10~23 minecraft:stonebrick 0
fill ~50~11~23 ~51~11~23 minecraft:stone_block_slab 3
fill ~51~0~23 ~52~0~24 minecraft:stonebrick 0
fill ~51~1~23 ~52~1~23 minecraft:stonebrick 0
fill ~51~2~23 ~52~2~23 minecraft:brick_block
fill ~51~3~23 ~52~5~23 minecraft:stonebrick 0
fill ~51~7~23 ~51~7~24 minecraft:stonebrick 0
setblock ~51~8~23 minecraft:redstone_torch 5
setblock ~51~9~23 minecraft:log 1
setblock ~51~10~23 minecraft:lit_redstone_lamp
setblock ~52~8~23 minecraft:stonebrick 0
setblock ~53~0~23 minecraft:stone_stairs 6
fill ~53~1~23 ~53~3~23 minecraft:cobblestone_wall 0
setblock ~53~4~23 minecraft:stone_stairs 2
setblock ~53~5~23 minecraft:log 1
setblock ~54~0~23 minecraft:stone_brick_stairs 2
setblock ~54~1~23 minecraft:stone_stairs 6
fill ~54~2~23 ~55~2~23 minecraft:iron_bars
setblock ~54~3~23 minecraft:stone_stairs 2
setblock ~54~4~23 minecraft:stone_brick_stairs 6
setblock ~54~5~23 minecraft:stonebrick 3
fill ~55~6~23 ~56~6~24 minecraft:stonebrick 0
fill ~55~8~23 ~56~8~25 minecraft:stonebrick 0
setblock ~57~6~23 minecraft:nether_brick_fence
fill ~57~8~23 ~58~8~23 minecraft:stained_hardened_clay 14
fill ~59~8~23 ~60~8~23 minecraft:stonebrick 0
fill ~60~7~23 ~60~7~28 minecraft:stonebrick 0
setblock ~61~8~23 minecraft:double_stone_block_slab 0
setblock ~62~8~23 minecraft:stone_stairs 6
setblock ~62~9~23 minecraft:stonebrick 0
fill ~62~10~23 ~63~11~23 minecraft:iron_bars
fill ~62~12~23 ~62~13~23 minecraft:stonebrick 0
setblock ~63~9~23 minecraft:iron_bars
setblock ~63~12~23 minecraft:iron_bars
setblock ~0~19~24 minecraft:wool 4
setblock ~0~20~24 minecraft:wool 0
fill ~1~19~24 ~3~19~24 minecraft:wool 0
fill ~1~20~24 ~2~20~24 minecraft:wool 4
setblock ~2~18~24 minecraft:wool 4
setblock ~11~8~24 minecraft:double_stone_block_slab 3
setblock ~11~9~24 minecraft:stonebrick 3
fill ~11~10~24 ~11~11~24 minecraft:log 1
setblock ~11~12~24 minecraft:stone_block_slab 3
fill ~12~8~24 ~13~9~24 minecraft:stonebrick 0
fill ~12~10~24 ~12~13~24 minecraft:stonebrick 0
fill ~13~10~24 ~13~11~24 minecraft:iron_bars
fill ~13~12~24 ~13~13~24 minecraft:stonebrick 0
setblock ~14~6~24 minecraft:stone_button 2
setblock ~14~7~24 minecraft:stone_stairs 6
setblock ~14~8~24 minecraft:double_stone_block_slab 0
fill ~15~7~24 ~15~8~25 minecraft:stonebrick 0
setblock ~16~8~24 minecraft:stonebrick 0
setblock ~17~8~24 minecraft:stained_hardened_clay 4
setblock ~18~6~24 minecraft:nether_brick_fence
fill ~18~7~24 ~18~8~24 minecraft:stonebrick 0
fill ~19~6~24 ~19~6~25 minecraft:stonebrick 0
fill ~19~8~24 ~19~8~26 minecraft:stonebrick 0
setblock ~20~5~24 minecraft:stone_button 2
setblock ~21~0~24 minecraft:stone_brick_stairs 2
setblock ~21~1~24 minecraft:stone_stairs 6
setblock ~21~2~24 minecraft:iron_bars
setblock ~21~3~24 minecraft:stone_stairs 2
setblock ~21~4~24 minecraft:stone_brick_stairs 6
setblock ~21~5~24 minecraft:stonebrick 3
fill ~22~0~24 ~23~0~25 minecraft:stonebrick 0
fill ~22~1~24 ~22~1~26 minecraft:stonebrick 0
fill ~22~2~24 ~23~2~24 minecraft:brick_block
fill ~22~3~24 ~22~5~26 minecraft:stonebrick 0
setblock ~23~1~24 minecraft:brick_block
setblock ~23~3~24 minecraft:brick_block
fill ~23~4~24 ~25~4~24 minecraft:stonebrick 0
setblock ~23~5~24 minecraft:stonebrick 0
fill ~24~1~24 ~24~3~24 minecraft:stonebrick 0
fill ~24~5~24 ~24~6~24 minecraft:stonebrick 2
fill ~24~7~24 ~25~7~24 minecraft:stonebrick 0
fill ~24~8~24 ~25~8~24 minecraft:double_stone_block_slab 0
setblock ~24~9~24 minecraft:stonebrick 2
setblock ~24~10~24 minecraft:stonebrick 1
setblock ~24~11~24 minecraft:stone_block_slab 3
setblock ~25~1~24 minecraft:stonebrick 1
fill ~25~2~24 ~25~3~24 minecraft:stonebrick 2
setblock ~25~5~24 minecraft:stonebrick 0
setblock ~25~6~24 minecraft:stonebrick 1
setblock ~25~9~24 minecraft:stonebrick 0
fill ~26~0~24 ~28~0~25 minecraft:grass
fill ~26~11~24 ~29~11~24 minecraft:stone_block_slab 11
fill ~28~1~24 ~28~4~24 minecraft:vine 4
setblock ~36~1~24 minecraft:tallgrass 0
setblock ~37~1~24 minecraft:red_flower 3
setblock ~38~1~24 minecraft:red_flower 0
fill ~47~11~24 ~50~11~24 minecraft:stone_block_slab 11
setblock ~47~20~24 minecraft:wool 14
setblock ~47~21~24 minecraft:wool 0
setblock ~48~0~24 minecraft:grass
setblock ~48~1~24 minecraft:vine 12
fill ~48~2~24 ~48~4~24 minecraft:vine 4
setblock ~48~19~24 minecraft:wool 14
setblock ~48~20~24 minecraft:wool 0
fill ~49~0~24 ~50~0~35 minecraft:dirt 0
fill ~49~1~24 ~50~1~32 minecraft:grass
fill ~49~19~24 ~51~19~24 minecraft:wool 0
fill ~49~20~24 ~50~20~24 minecraft:wool 14
fill ~50~2~24 ~50~5~24 minecraft:vine 8
setblock ~50~18~24 minecraft:wool 14
setblock ~51~1~24 minecraft:stonebrick 0
fill ~51~2~24 ~52~2~24 minecraft:stonebrick 1
setblock ~51~3~24 minecraft:stonebrick 2
fill ~51~4~24 ~54~4~24 minecraft:stonebrick 0
fill ~51~5~24 ~51~6~24 minecraft:stonebrick 0
fill ~51~8~24 ~52~8~24 minecraft:double_stone_block_slab 0
setblock ~51~9~24 minecraft:stonebrick 0
setblock ~52~1~24 minecraft:stonebrick 1
setblock ~52~3~24 minecraft:stonebrick 0
setblock ~52~5~24 minecraft:stonebrick 2
fill ~52~6~24 ~52~7~24 minecraft:stonebrick 0
fill ~52~9~24 ~52~10~24 minecraft:stonebrick 2
setblock ~52~11~24 minecraft:stone_block_slab 3
fill ~53~0~24 ~54~0~25 minecraft:stonebrick 0
fill ~53~1~24 ~53~3~24 minecraft:brick_block
fill ~53~5~24 ~54~5~25 minecraft:stonebrick 0
fill ~54~1~24 ~54~1~26 minecraft:stonebrick 0
setblock ~54~2~24 minecraft:brick_block
fill ~54~3~24 ~54~3~26 minecraft:stonebrick 0
setblock ~55~0~24 minecraft:stone_brick_stairs 2
setblock ~55~1~24 minecraft:stone_stairs 6
setblock ~55~2~24 minecraft:iron_bars
setblock ~55~3~24 minecraft:stone_stairs 2
setblock ~55~4~24 minecraft:stone_brick_stairs 6
setblock ~55~5~24 minecraft:stonebrick 3
setblock ~56~5~24 minecraft:stone_button 2
fill ~57~6~24 ~57~6~25 minecraft:stonebrick 0
fill ~57~8~24 ~58~8~26 minecraft:stonebrick 0
setblock ~58~6~24 minecraft:nether_brick_fence
setblock ~58~7~24 minecraft:stonebrick 0
setblock ~59~8~24 minecraft:stained_hardened_clay 14
fill ~60~8~24 ~61~8~24 minecraft:stonebrick 0
fill ~61~7~24 ~61~7~25 minecraft:stonebrick 0
setblock ~62~6~24 minecraft:stone_button 2
setblock ~62~7~24 minecraft:stone_stairs 6
setblock ~62~8~24 minecraft:double_stone_block_slab 0
fill ~63~8~24 ~64~9~24 minecraft:stonebrick 0
fill ~63~10~24 ~63~11~24 minecraft:iron_bars
fill ~63~12~24 ~64~13~24 minecraft:stonebrick 0
fill ~64~10~24 ~64~11~24 minecraft:stonebrick 0
setblock ~65~8~24 minecraft:double_stone_block_slab 3
setblock ~65~9~24 minecraft:stonebrick 3
fill ~65~10~24 ~65~11~24 minecraft:log 1
setblock ~65~12~24 minecraft:stone_block_slab 3
setblock ~0~21~25 minecraft:wool 4
setblock ~1~18~25 minecraft:wool 4
fill ~3~18~25 ~4~18~25 minecraft:wool 4
fill ~3~20~25 ~5~20~25 minecraft:wool 4
fill ~4~19~25 ~5~19~25 minecraft:wool 0
fill ~7~18~25 ~8~18~25 minecraft:wool 4
setblock ~8~19~25 minecraft:wool 0
fill ~8~20~25 ~9~21~25 minecraft:wool 4
fill ~9~18~25 ~10~18~25 minecraft:wool 0
setblock ~9~19~25 minecraft:wool 4
fill ~11~8~25 ~12~8~25 minecraft:stonebrick 0
fill ~11~9~25 ~11~9~26 minecraft:stonebrick 0
fill ~11~10~25 ~11~13~25 minecraft:stonebrick 0
setblock ~12~7~25 minecraft:double_stone_block_slab 3
fill ~13~7~25 ~14~7~26 minecraft:stonebrick 0
setblock ~13~8~25 minecraft:double_stone_block_slab 0
fill ~14~6~25 ~14~6~26 minecraft:log 1
setblock ~14~8~25 minecraft:stonebrick 0
setblock ~15~6~25 minecraft:stone_brick_stairs 5
setblock ~16~6~25 minecraft:stone_brick_stairs 4
setblock ~16~8~25 minecraft:stained_hardened_clay 4
fill ~17~8~25 ~18~8~27 minecraft:stonebrick 0
fill ~18~2~25 ~19~2~25 minecraft:iron_bars
fill ~18~6~25 ~18~6~27 minecraft:stonebrick 0
setblock ~19~0~25 minecraft:stone_brick_stairs 2
setblock ~19~1~25 minecraft:stone_stairs 6
setblock ~19~3~25 minecraft:stone_stairs 2
setblock ~19~4~25 minecraft:stone_brick_stairs 6
setblock ~19~5~25 minecraft:stonebrick 3
fill ~19~7~25 ~22~7~25 minecraft:stonebrick 0
setblock ~20~0~25 minecraft:stone_stairs 6
fill ~20~1~25 ~20~3~25 minecraft:cobblestone_wall 0
setblock ~20~4~25 minecraft:stone_stairs 2
setblock ~20~5~25 minecraft:log 1
fill ~20~6~25 ~20~6~27 minecraft:stonebrick 0
fill ~21~0~25 ~21~0~26 minecraft:stonebrick 0
setblock ~21~1~25 minecraft:stonebrick 0
setblock ~21~2~25 minecraft:brick_block
fill ~21~3~25 ~21~4~26 minecraft:stonebrick 0
setblock ~21~5~25 minecraft:stonebrick 0
setblock ~22~2~25 minecraft:stonebrick 0
setblock ~22~8~25 minecraft:stonebrick 0
setblock ~23~1~25 minecraft:stonebrick 0
setblock ~23~2~25 minecraft:stonebrick 1
fill ~23~3~25 ~23~4~25 minecraft:stonebrick 0
setblock ~23~5~25 minecraft:stonebrick 2
setblock ~23~6~25 minecraft:stonebrick 0
setblock ~23~7~25 minecraft:stonebrick 2
setblock ~23~8~25 minecraft:double_stone_block_slab 0
setblock ~23~9~25 minecraft:stonebrick 0
fill ~24~0~25 ~25~0~28 minecraft:grass
fill ~24~1~25 ~25~2~25 minecraft:vine 4
fill ~24~11~25 ~26~11~25 minecraft:stone_block_slab 11
fill ~25~3~25 ~25~4~25 minecraft:vine 4
setblock ~29~0~25 minecraft:grass
fill ~30~0~25 ~32~0~28 minecraft:dirt 0
fill ~30~1~25 ~32~1~28 minecraft:grass
fill ~37~0~25 ~38~0~25 minecraft:grass
setblock ~37~1~25 minecraft:yellow_flower
fill ~39~0~25 ~43~0~30 minecraft:dirt 0
fill ~39~1~25 ~43~1~27 minecraft:grass
setblock ~39~2~25 minecraft:red_flower 0
setblock ~40~2~25 minecraft:tallgrass 0
fill ~44~0~25 ~46~0~25 minecraft:grass
fill ~47~0~25 ~48~0~33 minecraft:dirt 0
fill ~47~1~25 ~48~1~29 minecraft:grass
fill ~47~21~25 ~48~21~25 minecraft:wool 14
setblock ~47~22~25 minecraft:wool 14
fill ~49~2~25 ~50~2~31 minecraft:tallgrass 0
setblock ~49~18~25 minecraft:wool 14
fill ~50~11~25 ~52~11~25 minecraft:stone_block_slab 11
fill ~51~0~25 ~52~0~30 minecraft:dirt 0
fill ~51~1~25 ~52~1~33 minecraft:grass
fill ~51~2~25 ~51~4~25 minecraft:vine 4
fill ~51~18~25 ~52~18~25 minecraft:wool 14
fill ~51~20~25 ~53~20~25 minecraft:wool 14
fill ~52~2~25 ~52~2~26 minecraft:tallgrass 0
fill ~52~19~25 ~53~19~25 minecraft:wool 0
setblock ~53~1~25 minecraft:stonebrick 0
setblock ~53~2~25 minecraft:stonebrick 1
setblock ~53~3~25 minecraft:stonebrick 2
fill ~53~4~25 ~55~4~25 minecraft:stonebrick 0
fill ~53~6~25 ~53~7~25 minecraft:stonebrick 0
setblock ~53~8~25 minecraft:double_stone_block_slab 0
setblock ~53~9~25 minecraft:stonebrick 2
setblock ~54~2~25 minecraft:stonebrick 0
setblock ~54~8~25 minecraft:stonebrick 0
fill ~55~0~25 ~55~0~26 minecraft:stonebrick 0
setblock ~55~1~25 minecraft:stonebrick 0
setblock ~55~2~25 minecraft:brick_block
setblock ~55~3~25 minecraft:stonebrick 0
fill ~55~5~25 ~55~5~26 minecraft:stonebrick 0
fill ~55~18~25 ~56~18~25 minecraft:wool 14
setblock ~56~0~25 minecraft:stone_stairs 6
fill ~56~1~25 ~56~3~25 minecraft:cobblestone_wall 0
setblock ~56~4~25 minecraft:stone_stairs 2
setblock ~56~5~25 minecraft:log 1
setblock ~56~6~25 minecraft:stonebrick 0
setblock ~56~19~25 minecraft:wool 0
fill ~56~20~25 ~57~21~25 minecraft:wool 14
setblock ~57~0~25 minecraft:stone_brick_stairs 2
setblock ~57~1~25 minecraft:stone_stairs 6
fill ~57~2~25 ~58~2~25 minecraft:iron_bars
setblock ~57~3~25 minecraft:stone_stairs 2
setblock ~57~4~25 minecraft:stone_brick_stairs 6
setblock ~57~5~25 minecraft:stonebrick 3
fill ~57~18~25 ~58~18~25 minecraft:wool 0
setblock ~57~19~25 minecraft:wool 14
fill ~58~6~25 ~58~6~26 minecraft:stonebrick 0
fill ~59~8~25 ~59~8~28 minecraft:stonebrick 0
setblock ~60~6~25 minecraft:stone_brick_stairs 7
setblock ~60~8~25 minecraft:stained_hardened_clay 14
setblock ~61~6~25 minecraft:stone_brick_stairs 6
fill ~61~8~25 ~62~8~25 minecraft:stonebrick 0
fill ~62~6~25 ~62~6~26 minecraft:log 1
fill ~62~7~25 ~63~7~26 minecraft:stonebrick 0
setblock ~63~8~25 minecraft:double_stone_block_slab 0
setblock ~64~7~25 minecraft:double_stone_block_slab 3
fill ~64~8~25 ~65~8~25 minecraft:stonebrick 0
fill ~65~9~25 ~65~9~26 minecraft:stonebrick 0
fill ~65~10~25 ~65~13~25 minecraft:stonebrick 0
fill ~5~18~26 ~6~18~26 minecraft:wool 4
fill ~6~19~26 ~7~19~26 minecraft:wool 0
fill ~6~20~26 ~7~21~26 minecraft:wool 4
fill ~7~17~26 ~11~17~26 minecraft:wool 4
fill ~10~9~26 ~10~12~26 minecraft:iron_bars
fill ~10~19~26 ~10~20~26 minecraft:wool 4
setblock ~11~8~26 minecraft:stonebrick 0
fill ~11~10~26 ~11~11~26 minecraft:iron_bars
fill ~11~12~26 ~11~13~26 minecraft:stonebrick 0
setblock ~11~18~26 minecraft:wool 4
setblock ~11~19~26 minecraft:wool 0
setblock ~11~20~26 minecraft:wool 4
fill ~12~7~26 ~12~7~30 minecraft:stonebrick 0
setblock ~12~8~26 minecraft:double_stone_block_slab 0
fill ~13~0~26 ~13~2~26 minecraft:stonebrick 0
fill ~13~3~26 ~13~3~28 minecraft:stone_brick_stairs 0
setblock ~13~6~26 minecraft:stone_block_slab 11
fill ~13~8~26 ~15~8~28 minecraft:stained_hardened_clay 4
fill ~13~9~26 ~13~10~26 minecraft:stained_hardened_clay 4
fill ~13~11~26 ~14~11~26 minecraft:stonebrick 0
fill ~14~0~26 ~14~2~26 minecraft:log 1
fill ~14~3~26 ~15~3~26 minecraft:stone_brick_stairs 2
setblock ~14~4~26 minecraft:stone_brick_stairs 6
setblock ~14~5~26 minecraft:stonebrick 3
setblock ~14~9~26 minecraft:iron_door 3
setblock ~14~12~26 minecraft:stone_brick_stairs 2
setblock ~14~13~26 minecraft:stone_button 2
fill ~15~0~26 ~15~2~26 minecraft:stonebrick 0
setblock ~15~6~26 minecraft:lit_redstone_lamp
setblock ~15~7~26 minecraft:redstone_block
setblock ~16~6~26 minecraft:nether_brick_fence
fill ~16~8~26 ~16~8~29 minecraft:stonebrick 0
setblock ~17~5~26 minecraft:stone_button 2
fill ~17~6~26 ~17~6~29 minecraft:stonebrick 0
setblock ~18~0~26 minecraft:stone_brick_stairs 2
setblock ~18~1~26 minecraft:stone_stairs 6
setblock ~18~2~26 minecraft:iron_bars
setblock ~18~3~26 minecraft:stone_stairs 2
setblock ~18~4~26 minecraft:stone_brick_stairs 6
setblock ~18~5~26 minecraft:stonebrick 3
fill ~18~7~26 ~19~7~26 minecraft:stonebrick 0
fill ~19~0~26 ~20~0~27 minecraft:stonebrick 0
fill ~19~1~26 ~19~1~27 minecraft:stonebrick 0
fill ~19~2~26 ~20~2~26 minecraft:brick_block
fill ~19~3~26 ~19~5~27 minecraft:stonebrick 0
setblock ~20~1~26 minecraft:brick_block
setblock ~20~3~26 minecraft:brick_block
fill ~20~4~26 ~20~4~27 minecraft:stonebrick 0
setblock ~20~5~26 minecraft:stonebrick 0
setblock ~20~8~26 minecraft:stonebrick 0
setblock ~21~1~26 minecraft:stonebrick 2
setblock ~21~2~26 minecraft:stonebrick 0
setblock ~21~5~26 minecraft:stonebrick 2
fill ~21~6~26 ~22~6~26 minecraft:stonebrick 1
setblock ~21~7~26 minecraft:stonebrick 0
fill ~21~8~26 ~22~8~26 minecraft:double_stone_block_slab 0
fill ~21~9~26 ~22~9~26 minecraft:stonebrick 0
setblock ~22~0~26 minecraft:stonebrick 0
setblock ~22~2~26 minecraft:stonebrick 2
setblock ~22~7~26 minecraft:stonebrick 2
setblock ~22~10~26 minecraft:stonebrick 0
setblock ~22~11~26 minecraft:stone_block_slab 3
fill ~23~0~26 ~23~0~30 minecraft:grass
fill ~23~1~26 ~23~4~26 minecraft:vine 2
fill ~23~11~26 ~24~11~26 minecraft:stone_block_slab 11
fill ~26~0~26 ~27~0~26 minecraft:grass
fill ~28~0~26 ~29~0~29 minecraft:dirt 0
fill ~28~1~26 ~29~1~27 minecraft:grass
fill ~28~2~26 ~29~2~26 minecraft:tallgrass 0
fill ~32~2~26 ~33~2~26 minecraft:tallgrass 0
fill ~33~0~26 ~34~0~31 minecraft:dirt 0
fill ~33~1~26 ~34~1~28 minecraft:grass
fill ~37~0~26 ~38~0~27 minecraft:dirt 0
fill ~37~1~26 ~38~1~27 minecraft:grass
setblock ~38~2~26 minecraft:tallgrass 0
fill ~42~2~26 ~42~2~28 minecraft:tallgrass 0
fill ~44~0~26 ~46~0~30 minecraft:dirt 0
fill ~44~1~26 ~46~1~28 minecraft:grass
setblock ~44~2~26 minecraft:tallgrass 0
fill ~48~2~26 ~48~2~29 minecraft:tallgrass 0
fill ~51~2~26 ~51~2~27 minecraft:tallgrass 0
fill ~52~11~26 ~53~11~26 minecraft:stone_block_slab 11
fill ~53~0~26 ~53~0~36 minecraft:dirt 0
fill ~53~1~26 ~53~1~27 minecraft:water 0
fill ~53~2~26 ~53~5~26 minecraft:vine 12
fill ~53~18~26 ~54~18~26 minecraft:wool 14
setblock ~54~0~26 minecraft:stonebrick 0
setblock ~54~2~26 minecraft:stonebrick 1
fill ~54~4~26 ~57~4~26 minecraft:stonebrick 0
setblock ~54~5~26 minecraft:stonebrick 1
fill ~54~6~26 ~55~7~26 minecraft:stonebrick 0
fill ~54~8~26 ~55~8~26 minecraft:double_stone_block_slab 0
fill ~54~9~26 ~55~9~26 minecraft:stonebrick 0
setblock ~54~10~26 minecraft:stonebrick 0
setblock ~54~11~26 minecraft:stone_block_slab 3
fill ~54~19~26 ~55~19~26 minecraft:wool 0
fill ~54~20~26 ~55~21~26 minecraft:wool 14
setblock ~55~1~26 minecraft:stonebrick 1
setblock ~55~2~26 minecraft:stonebrick 2
setblock ~55~3~26 minecraft:stonebrick 1
fill ~55~17~26 ~59~17~26 minecraft:wool 14
fill ~56~0~26 ~57~0~27 minecraft:stonebrick 0
fill ~56~1~26 ~56~3~26 minecraft:brick_block
fill ~56~5~26 ~57~5~27 minecraft:stonebrick 0
setblock ~56~8~26 minecraft:stonebrick 0
fill ~57~1~26 ~57~1~27 minecraft:stonebrick 0
setblock ~57~2~26 minecraft:brick_block
fill ~57~3~26 ~57~3~27 minecraft:stonebrick 0
setblock ~58~0~26 minecraft:stone_brick_stairs 2
setblock ~58~1~26 minecraft:stone_stairs 6
setblock ~58~2~26 minecraft:iron_bars
setblock ~58~3~26 minecraft:stone_stairs 2
setblock ~58~4~26 minecraft:stone_brick_stairs 6
setblock ~58~5~26 minecraft:stonebrick 3
fill ~58~19~26 ~58~20~26 minecraft:wool 14
setblock ~59~5~26 minecraft:stone_button 2
fill ~59~6~26 ~59~6~29 minecraft:stonebrick 0
setblock ~59~18~26 minecraft:wool 14
setblock ~59~19~26 minecraft:wool 0
setblock ~59~20~26 minecraft:wool 14
setblock ~60~6~26 minecraft:nether_brick_fence
fill ~60~8~26 ~60~8~29 minecraft:stonebrick 0
fill ~61~0~26 ~61~2~26 minecraft:stonebrick 0
fill ~61~3~26 ~61~3~28 minecraft:stone_brick_stairs 0
setblock ~61~6~26 minecraft:lit_redstone_lamp
setblock ~61~7~26 minecraft:redstone_block
fill ~61~8~26 ~63~8~28 minecraft:stained_hardened_clay 14
fill ~62~0~26 ~62~2~26 minecraft:log 1
fill ~62~3~26 ~63~3~26 minecraft:stone_brick_stairs 2
setblock ~62~4~26 minecraft:stone_brick_stairs 6
setblock ~62~5~26 minecraft:stonebrick 3
setblock ~62~9~26 minecraft:iron_door 3
fill ~62~11~26 ~63~11~26 minecraft:stonebrick 0
setblock ~62~12~26 minecraft:stone_brick_stairs 2
setblock ~62~13~26 minecraft:stone_button 2
fill ~63~0~26 ~63~2~26 minecraft:stonebrick 0
setblock ~63~6~26 minecraft:stone_block_slab 11
fill ~63~9~26 ~63~10~26 minecraft:stained_hardened_clay 14
fill ~63~12~26 ~63~12~27 minecraft:stone_brick_stairs 1
fill ~64~7~26 ~64~7~30 minecraft:stonebrick 0
setblock ~64~8~26 minecraft:double_stone_block_slab 0
setblock ~65~8~26 minecraft:stonebrick 0
fill ~65~10~26 ~66~11~26 minecraft:iron_bars
fill ~65~12~26 ~65~13~26 minecraft:stonebrick 0
setblock ~66~9~26 minecraft:iron_bars
setblock ~66~12~26 minecraft:iron_bars
setblock ~9~9~27 minecraft:cobblestone
setblock ~9~10~27 minecraft:stonebrick 3
setblock ~9~11~27 minecraft:log 1
setblock ~9~12~27 minecraft:stone_block_slab 3
setblock ~10~8~27 minecraft:stone_stairs 4
setblock ~10~9~27 minecraft:stonebrick 0
fill ~10~10~27 ~10~11~27 minecraft:iron_bars
fill ~10~12~27 ~10~13~27 minecraft:stonebrick 0
setblock ~11~6~27 minecraft:stone_button 4
setblock ~11~7~27 minecraft:stone_stairs 4
setblock ~11~8~27 minecraft:double_stone_block_slab 0
fill ~11~21~27 ~13~21~27 minecraft:wool 4
fill ~12~6~27 ~13~6~27 minecraft:log 1
fill ~12~8~27 ~12~8~28 minecraft:stonebrick 0
fill ~12~17~27 ~13~18~27 minecraft:wool 4
fill ~12~19~27 ~13~19~27 minecraft:wool 0
fill ~12~20~27 ~13~20~27 minecraft:wool 4
fill ~13~0~27 ~13~2~27 minecraft:log 1
setblock ~13~4~27 minecraft:stone_brick_stairs 4
setblock ~13~5~27 minecraft:stonebrick 3
setblock ~13~7~27 minecraft:stonebrick 0
setblock ~13~9~27 minecraft:iron_door 2
setblock ~13~11~27 minecraft:stonebrick 0
setblock ~13~12~27 minecraft:stone_brick_stairs 0
setblock ~13~13~27 minecraft:stone_button 4
setblock ~14~11~27 minecraft:lit_redstone_lamp
setblock ~14~12~27 minecraft:redstone_block
fill ~14~13~27 ~14~14~27 minecraft:log 1
fill ~14~15~27 ~14~21~27 minecraft:fence 0
fill ~15~0~27 ~15~2~27 minecraft:log 1
fill ~15~3~27 ~15~3~28 minecraft:stone_brick_stairs 1
setblock ~15~4~27 minecraft:stone_brick_stairs 5
setblock ~15~5~27 minecraft:stonebrick 3
setblock ~15~6~27 minecraft:log 1
fill ~15~7~27 ~15~7~29 minecraft:stonebrick 0
setblock ~15~9~27 minecraft:iron_door 0
fill ~15~11~27 ~15~11~28 minecraft:stonebrick 0
setblock ~15~12~27 minecraft:stone_brick_stairs 1
setblock ~15~13~27 minecraft:stone_button 5
fill ~16~6~27 ~16~6~30 minecraft:stonebrick 0
setblock ~17~0~27 minecraft:stone_stairs 6
fill ~17~1~27 ~17~3~27 minecraft:cobblestone_wall 0
setblock ~17~4~27 minecraft:stone_stairs 2
setblock ~17~5~27 minecraft:log 1
setblock ~17~7~27 minecraft:stonebrick 0
fill ~18~0~27 ~18~1~28 minecraft:stonebrick 0
setblock ~18~2~27 minecraft:brick_block
fill ~18~3~27 ~18~5~28 minecraft:stonebrick 0
setblock ~19~2~27 minecraft:stonebrick 0
fill ~19~6~27 ~19~6~28 minecraft:stonebrick 0
setblock ~19~8~27 minecraft:redstone_torch 5
setblock ~19~9~27 minecraft:log 1
setblock ~19~10~27 minecraft:lit_redstone_lamp
fill ~19~11~27 ~20~11~27 minecraft:stone_block_slab 3
setblock ~20~1~27 minecraft:stonebrick 1
setblock ~20~2~27 minecraft:stonebrick 2
setblock ~20~3~27 minecraft:stonebrick 0
setblock ~20~5~27 minecraft:stonebrick 1
setblock ~20~7~27 minecraft:stonebrick 0
setblock ~20~8~27 minecraft:double_stone_block_slab 0
fill ~20~9~27 ~20~10~27 minecraft:stonebrick 0
fill ~21~0~27 ~22~0~28 minecraft:grass
fill ~21~11~27 ~23~11~27 minecraft:stone_block_slab 11
fill ~22~1~27 ~22~3~27 minecraft:vine 4
setblock ~26~0~27 minecraft:grass
setblock ~26~1~27 minecraft:tallgrass 0
fill ~27~0~27 ~27~0~29 minecraft:dirt 0
fill ~27~1~27 ~27~1~28 minecraft:grass
setblock ~27~2~27 minecraft:tallgrass 0
fill ~29~2~27 ~31~2~27 minecraft:tallgrass 0
fill ~35~0~27 ~36~0~30 minecraft:dirt 0
fill ~35~1~27 ~36~1~28 minecraft:grass
fill ~39~2~27 ~41~2~27 minecraft:tallgrass 0
fill ~45~2~27 ~46~2~28 minecraft:tallgrass 0
setblock ~52~2~27 minecraft:red_flower 3
fill ~53~11~27 ~55~11~27 minecraft:stone_block_slab 11
fill ~54~0~27 ~55~0~36 minecraft:dirt 0
fill ~54~1~27 ~55~1~29 minecraft:water 0
fill ~54~2~27 ~54~3~27 minecraft:water 9
setblock ~54~4~27 minecraft:water 1
setblock ~55~2~27 minecraft:water 0
setblock ~55~3~27 minecraft:water 8
setblock ~55~4~27 minecraft:water 0
fill ~56~1~27 ~56~4~27 minecraft:stonebrick 0
fill ~56~6~27 ~56~7~27 minecraft:stonebrick 0
setblock ~56~8~27 minecraft:double_stone_block_slab 0
fill ~56~9~27 ~56~10~27 minecraft:stonebrick 0
fill ~56~11~27 ~57~11~27 minecraft:stone_block_slab 3
fill ~57~2~27 ~57~2~28 minecraft:stonebrick 0
fill ~57~4~27 ~58~4~28 minecraft:stonebrick 0
fill ~57~7~27 ~59~7~27 minecraft:stonebrick 0
setblock ~57~8~27 minecraft:redstone_torch 5
setblock ~57~9~27 minecraft:log 1
setblock ~57~10~27 minecraft:lit_redstone_lamp
fill ~58~0~27 ~58~1~28 minecraft:stonebrick 0
setblock ~58~2~27 minecraft:brick_block
fill ~58~3~27 ~58~3~28 minecraft:stonebrick 0
fill ~58~5~27 ~58~5~28 minecraft:stonebrick 0
setblock ~58~8~27 minecraft:stonebrick 0
setblock ~59~0~27 minecraft:stone_stairs 6
fill ~59~1~27 ~59~3~27 minecraft:cobblestone_wall 0
setblock ~59~4~27 minecraft:stone_stairs 2
setblock ~59~5~27 minecraft:log 1
fill ~59~21~27 ~61~21~27 minecraft:wool 14
fill ~60~6~27 ~60~6~30 minecraft:stonebrick 0
fill ~60~17~27 ~61~18~27 minecraft:wool 14
fill ~60~19~27 ~61~19~27 minecraft:wool 0
fill ~60~20~27 ~61~20~27 minecraft:wool 14
fill ~61~0~27 ~61~2~27 minecraft:log 1
setblock ~61~4~27 minecraft:stone_brick_stairs 4
setblock ~61~5~27 minecraft:stonebrick 3
setblock ~61~6~27 minecraft:log 1
fill ~61~7~27 ~61~7~29 minecraft:stonebrick 0
setblock ~61~9~27 minecraft:iron_door 2
fill ~61~11~27 ~61~11~28 minecraft:stonebrick 0
fill ~61~12~27 ~61~12~28 minecraft:stone_brick_stairs 0
setblock ~61~13~27 minecraft:stone_button 4
setblock ~62~11~27 minecraft:lit_redstone_lamp
setblock ~62~12~27 minecraft:redstone_block
fill ~62~13~27 ~62~14~27 minecraft:log 1
fill ~62~15~27 ~62~21~27 minecraft:fence 0
fill ~63~0~27 ~63~2~27 minecraft:log 1
fill ~63~3~27 ~63~3~28 minecraft:stone_brick_stairs 1
setblock ~63~4~27 minecraft:stone_brick_stairs 5
setblock ~63~5~27 minecraft:stonebrick 3
fill ~63~6~27 ~64~6~27 minecraft:log 1
setblock ~63~7~27 minecraft:stonebrick 0
setblock ~63~9~27 minecraft:iron_door 0
setblock ~63~11~27 minecraft:stonebrick 0
setblock ~63~13~27 minecraft:stone_button 5
fill ~64~8~27 ~64~8~28 minecraft:stonebrick 0
setblock ~65~6~27 minecraft:stone_button 5
setblock ~65~7~27 minecraft:stone_stairs 5
setblock ~65~8~27 minecraft:double_stone_block_slab 0
setblock ~66~8~27 minecraft:stone_stairs 5
setblock ~66~9~27 minecraft:stonebrick 0
fill ~66~10~27 ~66~11~27 minecraft:iron_bars
fill ~66~12~27 ~66~13~27 minecraft:stonebrick 0
setblock ~67~9~27 minecraft:cobblestone
setblock ~67~10~27 minecraft:stonebrick 3
setblock ~67~11~27 minecraft:log 1
setblock ~67~12~27 minecraft:stone_block_slab 3
fill ~8~9~28 ~8~12~28 minecraft:iron_bars
setblock ~9~8~28 minecraft:stone_stairs 6
fill ~9~9~28 ~9~13~28 minecraft:stonebrick 0
setblock ~10~8~28 minecraft:double_stone_block_slab 0
fill ~11~7~28 ~11~7~31 minecraft:stonebrick 0
fill ~11~8~28 ~11~8~29 minecraft:stonebrick 0
setblock ~12~6~28 minecraft:stone_brick_stairs 7
fill ~13~0~28 ~13~2~28 minecraft:stonebrick 0
setblock ~13~6~28 minecraft:lit_redstone_lamp
setblock ~13~7~28 minecraft:redstone_block
fill ~14~0~28 ~14~2~28 minecraft:log 1
setblock ~14~3~28 minecraft:stone_brick_stairs 3
setblock ~14~4~28 minecraft:stone_brick_stairs 7
setblock ~14~5~28 minecraft:stonebrick 3
setblock ~14~6~28 minecraft:log 1
fill ~14~7~28 ~14~7~33 minecraft:stonebrick 0
setblock ~14~9~28 minecraft:iron_door 1
setblock ~14~11~28 minecraft:stonebrick 0
setblock ~14~12~28 minecraft:stone_brick_stairs 3
setblock ~14~13~28 minecraft:stone_button 3
fill ~15~0~28 ~15~2~28 minecraft:stonebrick 0
fill ~15~6~28 ~15~6~32 minecraft:stonebrick 0
fill ~15~9~28 ~15~10~28 minecraft:stained_hardened_clay 4
setblock ~16~0~28 minecraft:stone_brick_stairs 2
setblock ~16~1~28 minecraft:stone_stairs 6
setblock ~16~2~28 minecraft:iron_bars
setblock ~16~3~28 minecraft:stone_stairs 2
setblock ~16~4~28 minecraft:stone_brick_stairs 6
setblock ~16~5~28 minecraft:stonebrick 3
fill ~17~0~28 ~17~0~29 minecraft:stonebrick 0
fill ~17~1~28 ~17~3~28 minecraft:brick_block
fill ~17~4~28 ~17~5~29 minecraft:stonebrick 0
setblock ~17~8~28 minecraft:stonebrick 0
setblock ~18~2~28 minecraft:stonebrick 0
setblock ~18~6~28 minecraft:stonebrick 2
fill ~18~7~28 ~19~7~28 minecraft:stonebrick 0
fill ~18~8~28 ~19~8~28 minecraft:double_stone_block_slab 0
fill ~18~9~28 ~19~9~28 minecraft:stonebrick 0
setblock ~18~10~28 minecraft:stonebrick 0
setblock ~18~11~28 minecraft:stone_block_slab 3
setblock ~19~0~28 minecraft:stonebrick 0
fill ~19~1~28 ~19~3~28 minecraft:stonebrick 2
fill ~19~4~28 ~19~5~28 minecraft:stonebrick 0
fill ~20~0~28 ~20~0~29 minecraft:grass
fill ~20~1~28 ~20~3~28 minecraft:vine 2
fill ~20~5~28 ~26~5~28 minecraft:wooden_slab 9
fill ~20~11~28 ~21~11~28 minecraft:stone_block_slab 11
setblock ~24~1~28 minecraft:tallgrass 0
fill ~26~0~28 ~26~0~29 minecraft:dirt 0
fill ~26~1~28 ~26~1~30 minecraft:grass
setblock ~26~2~28 minecraft:red_flower 0
fill ~28~1~28 ~29~1~41 minecraft:dirt 0
fill ~28~2~28 ~29~2~29 minecraft:grass
setblock ~29~3~28 minecraft:tallgrass 0
setblock ~30~2~28 minecraft:tallgrass 0
setblock ~32~2~28 minecraft:tallgrass 0
setblock ~34~2~28 minecraft:tallgrass 0
fill ~37~0~28 ~38~0~28 minecraft:stone 0
fill ~37~1~28 ~39~1~34 minecraft:dirt 0
fill ~37~2~28 ~39~2~29 minecraft:grass
setblock ~38~3~28 minecraft:tallgrass 0
fill ~40~1~28 ~43~1~28 minecraft:grass
fill ~40~2~28 ~41~2~28 minecraft:tallgrass 0
fill ~43~2~28 ~44~2~28 minecraft:tallgrass 0
fill ~47~2~28 ~47~2~29 minecraft:tallgrass 0
fill ~52~2~28 ~53~2~28 minecraft:tallgrass 0
fill ~53~1~28 ~53~1~32 minecraft:grass
fill ~55~2~28 ~55~4~28 minecraft:water 9
setblock ~55~5~28 minecraft:water 1
fill ~55~11~28 ~56~11~28 minecraft:stone_block_slab 11
fill ~56~0~28 ~56~0~48 minecraft:dirt 0
fill ~56~1~28 ~56~1~31 minecraft:water 0
fill ~56~2~28 ~56~4~28 minecraft:water 8
setblock ~56~5~28 minecraft:water 0
setblock ~57~0~28 minecraft:stonebrick 0
setblock ~57~1~28 minecraft:stonebrick 1
setblock ~57~3~28 minecraft:stonebrick 1
setblock ~57~5~28 minecraft:stonebrick 2
fill ~57~6~28 ~58~7~28 minecraft:stonebrick 0
fill ~57~8~28 ~58~8~28 minecraft:double_stone_block_slab 0
fill ~57~9~28 ~58~9~28 minecraft:stonebrick 0
setblock ~58~2~28 minecraft:stonebrick 2
setblock ~58~10~28 minecraft:stonebrick 0
setblock ~58~11~28 minecraft:stone_block_slab 3
fill ~59~0~28 ~59~0~29 minecraft:stonebrick 0
fill ~59~1~28 ~59~3~28 minecraft:brick_block
fill ~59~4~28 ~59~5~29 minecraft:stonebrick 0
setblock ~60~0~28 minecraft:stone_brick_stairs 2
setblock ~60~1~28 minecraft:stone_stairs 6
setblock ~60~2~28 minecraft:iron_bars
setblock ~60~3~28 minecraft:stone_stairs 2
setblock ~60~4~28 minecraft:stone_brick_stairs 6
setblock ~60~5~28 minecraft:stonebrick 3
fill ~61~0~28 ~61~2~28 minecraft:stonebrick 0
fill ~61~6~28 ~61~6~32 minecraft:stonebrick 0
fill ~61~9~28 ~61~10~28 minecraft:stained_hardened_clay 14
fill ~62~0~28 ~62~2~28 minecraft:log 1
setblock ~62~3~28 minecraft:stone_brick_stairs 3
setblock ~62~4~28 minecraft:stone_brick_stairs 7
setblock ~62~5~28 minecraft:stonebrick 3
setblock ~62~6~28 minecraft:log 1
fill ~62~7~28 ~62~7~30 minecraft:stonebrick 0
setblock ~62~9~28 minecraft:iron_door 1
setblock ~62~11~28 minecraft:stonebrick 0
setblock ~62~12~28 minecraft:stone_brick_stairs 3
setblock ~62~13~28 minecraft:stone_button 3
fill ~63~0~28 ~63~2~28 minecraft:stonebrick 0
setblock ~63~6~28 minecraft:lit_redstone_lamp
setblock ~63~7~28 minecraft:redstone_block
setblock ~64~6~28 minecraft:stone_brick_stairs 7
fill ~65~7~28 ~65~7~31 minecraft:stonebrick 0
fill ~65~8~28 ~65~8~29 minecraft:stonebrick 0
setblock ~66~8~28 minecraft:double_stone_block_slab 0
setblock ~67~8~28 minecraft:stone_stairs 6
fill ~67~9~28 ~67~13~28 minecraft:stonebrick 0
fill ~68~9~28 ~68~12~28 minecraft:iron_bars
fill ~7~9~29 ~7~12~29 minecraft:iron_bars
fill ~8~8~29 ~8~8~30 minecraft:stonebrick 0
setblock ~8~9~29 minecraft:stonebrick 0
fill ~8~10~29 ~8~11~29 minecraft:iron_bars
fill ~8~12~29 ~8~13~29 minecraft:stonebrick 0
setblock ~9~7~29 minecraft:stone_stairs 6
fill ~9~8~29 ~9~8~30 minecraft:double_stone_block_slab 0
fill ~10~7~29 ~10~7~32 minecraft:stonebrick 0
fill ~10~8~29 ~10~8~30 minecraft:stonebrick 0
setblock ~12~6~29 minecraft:stone_brick_stairs 6
setblock ~12~8~29 minecraft:stained_hardened_clay 4
setblock ~13~6~29 minecraft:nether_brick_fence
fill ~13~7~29 ~13~8~29 minecraft:stonebrick 0
fill ~14~6~29 ~14~6~30 minecraft:stonebrick 0
fill ~14~8~29 ~15~8~30 minecraft:stonebrick 0
setblock ~15~0~29 minecraft:stone_brick_stairs 0
setblock ~15~1~29 minecraft:stone_stairs 4
setblock ~15~2~29 minecraft:iron_bars
setblock ~15~3~29 minecraft:stone_stairs 0
setblock ~15~4~29 minecraft:stone_brick_stairs 4
setblock ~15~5~29 minecraft:stonebrick 3
setblock ~16~0~29 minecraft:redstone_block
fill ~16~1~29 ~17~1~29 minecraft:stonebrick 0
setblock ~16~2~29 minecraft:brick_block
fill ~16~3~29 ~17~3~29 minecraft:stonebrick 0
fill ~16~4~29 ~16~4~30 minecraft:stonebrick 0
setblock ~16~5~29 minecraft:stonebrick 0
setblock ~17~2~29 minecraft:stonebrick 0
setblock ~17~7~29 minecraft:stonebrick 2
setblock ~17~8~29 minecraft:double_stone_block_slab 0
setblock ~17~9~29 minecraft:stonebrick 0
fill ~18~0~29 ~19~0~30 minecraft:grass
fill ~18~11~29 ~20~11~29 minecraft:stone_block_slab 11
fill ~19~1~29 ~19~2~29 minecraft:vine 4
fill ~20~5~29 ~20~5~34 minecraft:wooden_slab 9
fill ~21~0~29 ~21~0~35 minecraft:dirt 0
fill ~21~1~29 ~21~5~29 minecraft:log2 0
fill ~21~6~29 ~27~6~29 minecraft:wooden_slab 1
setblock ~22~0~29 minecraft:grass
fill ~22~4~29 ~22~5~29 minecraft:fence 0
fill ~23~5~29 ~26~5~29 minecraft:fence 0
setblock ~24~0~29 minecraft:grass
fill ~25~0~29 ~25~0~30 minecraft:dirt 0
fill ~25~1~29 ~25~1~31 minecraft:grass
fill ~25~2~29 ~26~2~29 minecraft:tallgrass 0
setblock ~26~4~29 minecraft:fence 0
fill ~27~1~29 ~27~1~42 minecraft:dirt 0
setblock ~27~2~29 minecraft:dirt 0
fill ~27~3~29 ~27~5~29 minecraft:log2 0
fill ~30~0~29 ~30~1~29 minecraft:dirt 0
setblock ~30~2~29 minecraft:grass
fill ~31~0~29 ~31~0~74 minecraft:stone 0
fill ~31~1~29 ~33~1~29 minecraft:grass
setblock ~31~2~29 minecraft:tallgrass 0
fill ~32~0~29 ~32~0~31 minecraft:dirt 0
fill ~34~1~29 ~36~1~31 minecraft:dirt 0
fill ~34~2~29 ~36~2~30 minecraft:grass
fill ~37~0~29 ~37~0~73 minecraft:stone 0
fill ~38~0~29 ~38~0~31 minecraft:dirt 0
fill ~40~1~29 ~44~1~31 minecraft:dirt 0
fill ~40~2~29 ~44~2~30 minecraft:grass
fill ~40~3~29 ~43~3~29 minecraft:tallgrass 0
setblock ~44~3~29 minecraft:red_flower 0
fill ~45~1~29 ~46~1~29 minecraft:grass
setblock ~45~2~29 minecraft:tallgrass 0
setblock ~52~2~29 minecraft:tallgrass 0
fill ~56~2~29 ~57~4~29 minecraft:water 9
setblock ~56~5~29 minecraft:water 1
fill ~56~11~29 ~58~11~29 minecraft:stone_block_slab 11
fill ~57~0~29 ~58~0~29 minecraft:stone 0
fill ~57~1~29 ~58~1~29 minecraft:water 0
setblock ~57~5~29 minecraft:water 9
fill ~57~6~29 ~57~6~31 minecraft:water 1
setblock ~58~4~29 minecraft:stone_block_slab 11
setblock ~58~5~29 minecraft:water 8
fill ~58~6~29 ~58~6~31 minecraft:water 0
fill ~59~1~29 ~60~1~29 minecraft:stonebrick 0
fill ~59~2~29 ~59~3~29 minecraft:stonebrick 0
setblock ~59~7~29 minecraft:stonebrick 0
setblock ~59~8~29 minecraft:double_stone_block_slab 0
setblock ~59~9~29 minecraft:stonebrick 0
setblock ~60~0~29 minecraft:redstone_block
setblock ~60~2~29 minecraft:brick_block
fill ~60~3~29 ~60~5~29 minecraft:stonebrick 0
setblock ~61~0~29 minecraft:stone_brick_stairs 1
setblock ~61~1~29 minecraft:stone_stairs 5
setblock ~61~2~29 minecraft:iron_bars
setblock ~61~3~29 minecraft:stone_stairs 1
setblock ~61~4~29 minecraft:stone_brick_stairs 5
setblock ~61~5~29 minecraft:stonebrick 3
fill ~61~8~29 ~63~8~30 minecraft:stonebrick 0
fill ~62~6~29 ~62~6~33 minecraft:stonebrick 0
setblock ~63~6~29 minecraft:nether_brick_fence
setblock ~63~7~29 minecraft:stonebrick 0
setblock ~64~6~29 minecraft:stone_brick_stairs 6
setblock ~64~8~29 minecraft:stained_hardened_clay 14
fill ~66~7~29 ~66~7~32 minecraft:stonebrick 0
fill ~66~8~29 ~66~8~30 minecraft:stonebrick 0
setblock ~67~7~29 minecraft:stone_stairs 6
fill ~67~8~29 ~67~8~30 minecraft:double_stone_block_slab 0
fill ~68~8~29 ~68~8~30 minecraft:stonebrick 0
setblock ~68~9~29 minecraft:stonebrick 0
fill ~68~10~29 ~69~11~29 minecraft:iron_bars
fill ~68~12~29 ~68~13~29 minecraft:stonebrick 0
setblock ~69~9~29 minecraft:iron_bars
setblock ~69~12~29 minecraft:iron_bars
setblock ~6~9~30 minecraft:cobblestone
setblock ~6~10~30 minecraft:stonebrick 3
setblock ~6~11~30 minecraft:log 1
setblock ~6~12~30 minecraft:stone_block_slab 3
setblock ~7~8~30 minecraft:stone_stairs 4
fill ~7~9~30 ~7~9~31 minecraft:stonebrick 0
fill ~7~10~30 ~7~12~30 minecraft:stonebrick 0
setblock ~8~6~30 minecraft:stone_button 4
setblock ~8~7~30 minecraft:stone_stairs 4
fill ~9~6~30 ~12~6~30 minecraft:log 1
fill ~9~7~30 ~9~7~34 minecraft:stonebrick 0
setblock ~11~8~30 minecraft:stained_hardened_clay 4
fill ~12~8~30 ~13~8~33 minecraft:stonebrick 0
setblock ~13~5~30 minecraft:stone_button 4
fill ~13~6~30 ~13~6~31 minecraft:stonebrick 0
setblock ~14~0~30 minecraft:stone_stairs 4
fill ~14~1~30 ~14~3~30 minecraft:cobblestone_wall 0
setblock ~14~4~30 minecraft:stone_stairs 0
setblock ~14~5~30 minecraft:log 1
fill ~15~0~30 ~16~0~30 minecraft:stonebrick 0
fill ~15~1~30 ~15~3~30 minecraft:brick_block
fill ~15~4~30 ~15~5~32 minecraft:stonebrick 0
fill ~16~1~30 ~16~3~30 minecraft:stonebrick 1
setblock ~16~5~30 minecraft:stonebrick 1
setblock ~16~7~30 minecraft:stonebrick 0
setblock ~16~8~30 minecraft:double_stone_block_slab 0
setblock ~16~9~30 minecraft:stonebrick 0
fill ~17~0~30 ~17~0~41 minecraft:grass
fill ~17~1~30 ~17~5~30 minecraft:vine 2
fill ~17~11~30 ~18~11~30 minecraft:stone_block_slab 11
fill ~20~0~30 ~20~0~36 minecraft:dirt 0
fill ~20~1~30 ~22~1~34 minecraft:grass
fill ~21~4~30 ~21~5~30 minecraft:fence 0
fill ~21~6~30 ~21~6~35 minecraft:wooden_slab 1
fill ~22~0~30 ~22~0~34 minecraft:dirt 0
setblock ~22~2~30 minecraft:tallgrass 0
setblock ~22~5~30 minecraft:web
fill ~22~6~30 ~28~6~30 minecraft:wooden_slab 9
fill ~24~0~30 ~24~0~31 minecraft:dirt 0
fill ~24~1~30 ~24~1~32 minecraft:grass
fill ~26~0~30 ~30~0~71 minecraft:stone 0
fill ~27~2~30 ~32~2~31 minecraft:cobblestone
fill ~30~1~30 ~33~1~33 minecraft:dirt 0
setblock ~33~2~30 minecraft:grass
fill ~34~3~30 ~35~3~30 minecraft:tallgrass 0
fill ~37~2~30 ~38~2~41 minecraft:dirt 0
fill ~37~3~30 ~38~3~32 minecraft:grass
setblock ~38~4~30 minecraft:tallgrass 0
setblock ~39~2~30 minecraft:grass
setblock ~40~3~30 minecraft:red_flower 0
setblock ~41~3~30 minecraft:tallgrass 0
fill ~43~3~30 ~44~3~31 minecraft:tallgrass 0
fill ~45~1~30 ~47~1~34 minecraft:dirt 0
fill ~45~2~30 ~47~2~31 minecraft:grass
fill ~46~3~30 ~47~3~30 minecraft:tallgrass 0
fill ~48~1~30 ~48~1~31 minecraft:grass
fill ~54~1~30 ~54~1~32 minecraft:grass
fill ~55~1~30 ~55~1~31 minecraft:water 0
fill ~56~2~30 ~56~5~30 minecraft:water 10
fill ~56~6~30 ~56~6~31 minecraft:water 2
fill ~57~0~30 ~58~0~62 minecraft:dirt 0
setblock ~57~1~30 minecraft:water 0
fill ~57~5~30 ~59~5~32 minecraft:double_stone_block_slab 3
fill ~58~1~30 ~59~1~31 minecraft:cobblestone
setblock ~58~7~30 minecraft:water 1
fill ~58~11~30 ~59~11~30 minecraft:stone_block_slab 11
setblock ~59~0~30 minecraft:stone 0
setblock ~59~4~30 minecraft:stone_block_slab 11
fill ~59~6~30 ~59~6~31 minecraft:water 0
setblock ~59~7~30 minecraft:water 0
fill ~60~0~30 ~61~0~30 minecraft:stonebrick 0
setblock ~60~1~30 minecraft:stonebrick 2
fill ~60~2~30 ~60~3~30 minecraft:stonebrick 1
fill ~60~4~30 ~61~4~30 minecraft:stonebrick 0
setblock ~60~5~30 minecraft:stonebrick 1
setblock ~60~7~30 minecraft:stonebrick 0
setblock ~60~8~30 minecraft:double_stone_block_slab 0
setblock ~60~9~30 minecraft:stonebrick 0
fill ~61~1~30 ~61~3~30 minecraft:brick_block
fill ~61~5~30 ~61~5~32 minecraft:stonebrick 0
setblock ~62~0~30 minecraft:stone_stairs 5
fill ~62~1~30 ~62~3~30 minecraft:cobblestone_wall 0
setblock ~62~4~30 minecraft:stone_stairs 1
setblock ~62~5~30 minecraft:log 1
setblock ~63~5~30 minecraft:stone_button 5
fill ~63~6~30 ~63~6~31 minecraft:stonebrick 0
fill ~64~6~30 ~67~6~30 minecraft:log 1
fill ~64~8~30 ~64~8~35 minecraft:stonebrick 0
setblock ~65~8~30 minecraft:stained_hardened_clay 14
fill ~67~7~30 ~67~7~34 minecraft:stonebrick 0
setblock ~68~6~30 minecraft:stone_button 5
setblock ~68~7~30 minecraft:stone_stairs 5
setblock ~69~8~30 minecraft:stone_stairs 5
fill ~69~9~30 ~69~9~31 minecraft:stonebrick 0
fill ~69~10~30 ~69~12~30 minecraft:stonebrick 0
setblock ~70~9~30 minecraft:cobblestone
setblock ~70~10~30 minecraft:stonebrick 3
setblock ~70~11~30 minecraft:log 1
setblock ~70~12~30 minecraft:stone_block_slab 3
setblock ~7~8~31 minecraft:stone_stairs 6
fill ~7~10~31 ~7~11~32 minecraft:iron_bars
setblock ~7~12~31 minecraft:stonebrick 0
fill ~8~7~31 ~8~7~33 minecraft:stonebrick 0
setblock ~8~8~31 minecraft:double_stone_block_slab 0
setblock ~9~6~31 minecraft:stone_brick_stairs 7
fill ~9~8~31 ~9~8~32 minecraft:stonebrick 0
fill ~10~8~31 ~10~8~32 minecraft:stained_hardened_clay 4
setblock ~11~6~31 minecraft:nether_brick_fence
fill ~11~8~31 ~11~8~36 minecraft:stonebrick 0
fill ~12~2~31 ~13~2~31 minecraft:iron_bars
fill ~12~6~31 ~12~6~33 minecraft:stonebrick 0
setblock ~13~0~31 minecraft:stone_brick_stairs 0
setblock ~13~1~31 minecraft:stone_stairs 4
setblock ~13~3~31 minecraft:stone_stairs 0
setblock ~13~4~31 minecraft:stone_brick_stairs 4
setblock ~13~5~31 minecraft:stonebrick 3
fill ~14~0~31 ~15~0~32 minecraft:stonebrick 0
fill ~14~1~31 ~14~1~32 minecraft:stonebrick 0
setblock ~14~2~31 minecraft:brick_block
fill ~14~3~31 ~15~3~32 minecraft:stonebrick 0
fill ~14~4~31 ~14~4~33 minecraft:stonebrick 0
fill ~14~5~31 ~14~5~32 minecraft:stonebrick 0
setblock ~14~8~31 minecraft:stonebrick 0
fill ~15~1~31 ~15~2~31 minecraft:stonebrick 2
setblock ~15~7~31 minecraft:stonebrick 0
fill ~15~8~31 ~15~8~32 minecraft:double_stone_block_slab 0
fill ~15~9~31 ~15~10~31 minecraft:stonebrick 0
setblock ~15~11~31 minecraft:stone_block_slab 3
fill ~16~0~31 ~16~0~44 minecraft:grass
fill ~16~1~31 ~16~5~31 minecraft:vine 6
fill ~16~11~31 ~17~11~31 minecraft:stone_block_slab 11
fill ~18~0~31 ~18~0~33 minecraft:grass
fill ~19~0~31 ~19~0~37 minecraft:dirt 0
fill ~19~1~31 ~19~1~41 minecraft:grass
fill ~20~2~31 ~20~2~32 minecraft:tallgrass 0
setblock ~21~2~31 minecraft:red_flower 3
fill ~21~5~31 ~21~5~34 minecraft:fence 0
fill ~22~6~31 ~22~6~36 minecraft:wooden_slab 9
fill ~23~0~31 ~23~0~32 minecraft:dirt 0
fill ~23~1~31 ~23~1~33 minecraft:grass
fill ~23~7~31 ~29~7~31 minecraft:wooden_slab 1
fill ~25~0~31 ~25~0~69 minecraft:stone 0
setblock ~25~6~31 minecraft:web
fill ~26~1~31 ~26~1~39 minecraft:dirt 0
fill ~26~2~31 ~26~2~32 minecraft:grass
setblock ~27~3~31 minecraft:stone_block_slab 3
fill ~29~13~31 ~29~13~33 minecraft:leaves 0
fill ~30~12~31 ~30~12~34 minecraft:leaves 0
setblock ~30~13~31 minecraft:leaves 0
fill ~31~3~31 ~33~3~31 minecraft:stone_block_slab 3
fill ~31~10~31 ~33~10~32 minecraft:leaves 0
setblock ~31~11~31 minecraft:leaves 0
setblock ~31~12~31 minecraft:leaves 0
fill ~31~13~31 ~31~13~32 minecraft:leaves 0
setblock ~32~11~31 minecraft:leaves 0
setblock ~32~12~31 minecraft:leaves 0
setblock ~33~2~31 minecraft:cobblestone
fill ~33~11~31 ~33~11~32 minecraft:leaves 0
setblock ~34~2~31 minecraft:grass
fill ~35~0~31 ~36~0~74 minecraft:stone 0
fill ~35~2~31 ~36~2~40 minecraft:dirt 0
fill ~35~3~31 ~36~3~32 minecraft:grass
fill ~39~0~31 ~40~0~31 minecraft:dirt 0
fill ~39~2~31 ~42~2~41 minecraft:dirt 0
fill ~39~3~31 ~42~3~32 minecraft:grass
fill ~39~4~31 ~41~4~32 minecraft:tallgrass 0
fill ~41~0~31 ~44~0~74 minecraft:stone 0
setblock ~42~4~31 minecraft:red_flower 8
fill ~43~2~31 ~44~2~31 minecraft:grass
fill ~45~0~31 ~46~0~31 minecraft:dirt 0
fill ~45~3~31 ~46~3~31 minecraft:tallgrass 0
setblock ~48~2~31 minecraft:tallgrass 0
fill ~51~0~31 ~51~0~35 minecraft:dirt 0
setblock ~51~2~31 minecraft:red_flower 3
setblock ~52~0~31 minecraft:stone 0
setblock ~52~2~31 minecraft:tallgrass 0
setblock ~54~2~31 minecraft:tallgrass 0
fill ~55~2~31 ~55~5~31 minecraft:water 11
setblock ~55~6~31 minecraft:water 3
setblock ~56~5~31 minecraft:double_stone_block_slab 3
fill ~57~1~31 ~57~1~33 minecraft:cobblestone
fill ~59~0~31 ~59~0~62 minecraft:dirt 0
setblock ~59~7~31 minecraft:water 1
fill ~59~11~31 ~60~11~31 minecraft:stone_block_slab 11
fill ~60~0~31 ~60~0~32 minecraft:stone 0
fill ~60~1~31 ~60~1~35 minecraft:water 0
setblock ~60~4~31 minecraft:stone_block_slab 11
setblock ~60~5~31 minecraft:water 9
setblock ~60~6~31 minecraft:water 1
fill ~61~0~31 ~62~0~32 minecraft:stonebrick 0
setblock ~61~1~31 minecraft:stonebrick 2
fill ~61~2~31 ~61~2~32 minecraft:stonebrick 1
setblock ~61~3~31 minecraft:stonebrick 1
fill ~61~4~31 ~62~4~32 minecraft:stonebrick 0
fill ~61~7~31 ~61~7~32 minecraft:stonebrick 0
fill ~61~8~31 ~61~8~32 minecraft:double_stone_block_slab 0
fill ~61~9~31 ~61~9~32 minecraft:stonebrick 0
setblock ~61~10~31 minecraft:stonebrick 0
setblock ~61~11~31 minecraft:stone_block_slab 3
fill ~62~1~31 ~62~1~32 minecraft:stonebrick 0
setblock ~62~2~31 minecraft:brick_block
fill ~62~3~31 ~62~3~33 minecraft:stonebrick 0
fill ~62~5~31 ~62~5~33 minecraft:stonebrick 0
fill ~62~8~31 ~63~8~31 minecraft:stonebrick 0
setblock ~63~0~31 minecraft:stone_brick_stairs 1
setblock ~63~1~31 minecraft:stone_stairs 5
fill ~63~2~31 ~64~2~31 minecraft:iron_bars
setblock ~63~3~31 minecraft:stone_stairs 1
setblock ~63~4~31 minecraft:stone_brick_stairs 5
setblock ~63~5~31 minecraft:stonebrick 3
fill ~63~7~31 ~63~7~32 minecraft:stonebrick 0
fill ~64~6~31 ~64~6~33 minecraft:stonebrick 0
setblock ~65~6~31 minecraft:nether_brick_fence
fill ~65~8~31 ~65~8~36 minecraft:stonebrick 0
fill ~66~8~31 ~66~8~32 minecraft:stained_hardened_clay 14
setblock ~67~6~31 minecraft:stone_brick_stairs 7
fill ~67~8~31 ~67~8~32 minecraft:stonebrick 0
fill ~68~7~31 ~68~7~33 minecraft:stonebrick 0
setblock ~68~8~31 minecraft:double_stone_block_slab 0
setblock ~69~8~31 minecraft:stone_stairs 6
fill ~69~10~31 ~69~11~32 minecraft:iron_bars
setblock ~69~12~31 minecraft:stonebrick 0
fill ~6~8~32 ~6~9~33 minecraft:stonebrick 0
fill ~6~10~32 ~6~11~32 minecraft:iron_bars
fill ~6~12~32 ~6~13~33 minecraft:stonebrick 0
setblock ~7~7~32 minecraft:stone_stairs 6
fill ~7~8~32 ~7~8~33 minecraft:double_stone_block_slab 0
setblock ~7~9~32 minecraft:iron_bars
setblock ~7~12~32 minecraft:iron_bars
fill ~8~8~32 ~8~8~34 minecraft:stonebrick 0
setblock ~9~6~32 minecraft:stone_brick_stairs 6
setblock ~10~6~32 minecraft:nether_brick_fence
fill ~11~6~32 ~11~6~34 minecraft:stonebrick 0
setblock ~12~0~32 minecraft:stone_brick_stairs 0
setblock ~12~1~32 minecraft:stone_stairs 4
setblock ~12~2~32 minecraft:iron_bars
setblock ~12~3~32 minecraft:stone_stairs 0
setblock ~12~4~32 minecraft:stone_brick_stairs 4
setblock ~12~5~32 minecraft:stonebrick 3
fill ~13~0~32 ~13~0~35 minecraft:stonebrick 0
setblock ~13~1~32 minecraft:stonebrick 0
fill ~13~2~32 ~13~2~33 minecraft:brick_block
fill ~13~3~32 ~13~5~32 minecraft:stonebrick 0
fill ~14~2~32 ~15~2~32 minecraft:stonebrick 0
setblock ~14~8~32 minecraft:redstone_torch 5
setblock ~14~9~32 minecraft:log 1
setblock ~14~10~32 minecraft:lit_redstone_lamp
fill ~14~11~32 ~14~11~33 minecraft:stone_block_slab 3
setblock ~15~1~32 minecraft:stonebrick 0
setblock ~15~7~32 minecraft:stonebrick 2
setblock ~15~9~32 minecraft:stonebrick 2
fill ~16~1~32 ~16~5~32 minecraft:vine 2
fill ~16~11~32 ~16~11~33 minecraft:stone_block_slab 11
fill ~19~2~32 ~19~2~33 minecraft:red_flower 0
fill ~21~2~32 ~23~2~32 minecraft:tallgrass 0
fill ~23~7~32 ~23~7~37 minecraft:wooden_slab 1
fill ~24~0~32 ~24~0~67 minecraft:stone 0
fill ~24~6~32 ~28~6~32 minecraft:wooden_slab 9
fill ~25~1~32 ~25~1~34 minecraft:stone 0
fill ~25~2~32 ~25~2~33 minecraft:grass
fill ~27~2~32 ~34~2~39 minecraft:dirt 0
setblock ~27~3~32 minecraft:cobblestone
fill ~28~3~32 ~31~3~33 minecraft:grass
setblock ~29~4~32 minecraft:tallgrass 0
fill ~29~12~32 ~29~12~35 minecraft:leaves 0
fill ~30~10~32 ~30~11~34 minecraft:leaves 0
fill ~30~13~32 ~30~14~32 minecraft:leaves 0
setblock ~31~4~32 minecraft:tallgrass 0
fill ~31~11~32 ~31~11~33 minecraft:log 0
fill ~31~12~32 ~31~12~35 minecraft:leaves 0
fill ~31~14~32 ~31~14~34 minecraft:leaves 0
fill ~32~0~32 ~34~0~74 minecraft:stone 0
fill ~32~3~32 ~34~3~32 minecraft:cobblestone
fill ~32~9~32 ~32~9~34 minecraft:leaves 0
fill ~32~11~32 ~32~11~35 minecraft:leaves 0
fill ~32~13~32 ~33~13~34 minecraft:leaves 0
fill ~33~4~32 ~34~4~32 minecraft:stone_block_slab 3
fill ~33~12~32 ~33~12~33 minecraft:leaves 0
fill ~34~1~32 ~35~1~34 minecraft:dirt 0
setblock ~34~10~32 minecraft:leaves 0
setblock ~34~11~32 minecraft:leaves 0
setblock ~36~1~32 minecraft:stone 0
setblock ~36~4~32 minecraft:tallgrass 0
fill ~38~0~32 ~40~0~73 minecraft:stone 0
setblock ~38~4~32 minecraft:tallgrass 0
fill ~40~1~32 ~40~1~37 minecraft:dirt 0
setblock ~41~1~32 minecraft:stone 0
fill ~42~1~32 ~44~1~34 minecraft:dirt 0
fill ~43~2~32 ~45~2~34 minecraft:dirt 0
setblock ~43~3~32 minecraft:grass
fill ~44~3~32 ~45~3~33 minecraft:cobblestone
fill ~45~0~32 ~45~0~73 minecraft:stone 0
setblock ~46~0~32 minecraft:dirt 0
fill ~46~2~32 ~47~2~32 minecraft:cobblestone
fill ~46~3~32 ~47~3~32 minecraft:stone_block_slab 3
fill ~48~1~32 ~48~1~34 minecraft:dirt 0
setblock ~48~2~32 minecraft:grass
setblock ~49~2~32 minecraft:tallgrass 0
setblock ~50~2~32 minecraft:yellow_flower
fill ~52~0~32 ~52~0~35 minecraft:dirt 0
fill ~55~1~32 ~56~1~33 minecraft:cobblestone
fill ~55~5~32 ~56~5~32 minecraft:stone_block_slab 3
setblock ~58~1~32 minecraft:cobblestone
fill ~58~6~32 ~59~6~32 minecraft:water 1
fill ~59~1~32 ~59~1~35 minecraft:water 0
fill ~60~2~32 ~60~5~32 minecraft:water 10
setblock ~60~6~32 minecraft:water 2
fill ~60~11~32 ~60~11~33 minecraft:stone_block_slab 11
setblock ~61~1~32 minecraft:stonebrick 1
setblock ~61~3~32 minecraft:stonebrick 2
setblock ~62~2~32 minecraft:stonebrick 0
setblock ~62~8~32 minecraft:redstone_torch 5
setblock ~62~9~32 minecraft:log 1
setblock ~62~10~32 minecraft:lit_redstone_lamp
fill ~62~11~32 ~62~11~33 minecraft:stone_block_slab 3
fill ~63~0~32 ~63~0~35 minecraft:stonebrick 0
setblock ~63~1~32 minecraft:stonebrick 0
fill ~63~2~32 ~63~2~33 minecraft:brick_block
fill ~63~3~32 ~63~5~32 minecraft:stonebrick 0
fill ~63~8~32 ~63~8~33 minecraft:stonebrick 0
setblock ~64~0~32 minecraft:stone_brick_stairs 1
setblock ~64~1~32 minecraft:stone_stairs 5
setblock ~64~2~32 minecraft:iron_bars
setblock ~64~3~32 minecraft:stone_stairs 1
setblock ~64~4~32 minecraft:stone_brick_stairs 5
setblock ~64~5~32 minecraft:stonebrick 3
fill ~64~7~32 ~64~7~36 minecraft:stonebrick 0
fill ~65~6~32 ~65~6~34 minecraft:stonebrick 0
setblock ~66~6~32 minecraft:nether_brick_fence
setblock ~67~6~32 minecraft:stone_brick_stairs 6
fill ~68~8~32 ~68~8~34 minecraft:stonebrick 0
setblock ~69~7~32 minecraft:stone_stairs 6
fill ~69~8~32 ~69~8~33 minecraft:double_stone_block_slab 0
setblock ~69~9~32 minecraft:iron_bars
setblock ~69~12~32 minecraft:iron_bars
fill ~70~8~32 ~70~9~33 minecraft:stonebrick 0
fill ~70~10~32 ~70~11~32 minecraft:iron_bars
fill ~70~12~32 ~70~13~33 minecraft:stonebrick 0
setblock ~5~8~33 minecraft:stone_stairs 4
setblock ~5~9~33 minecraft:stonebrick 3
fill ~5~10~33 ~5~11~33 minecraft:log 1
setblock ~5~12~33 minecraft:stone_block_slab 3
setblock ~6~6~33 minecraft:stone_button 4
setblock ~6~7~33 minecraft:stone_stairs 4
fill ~6~10~33 ~6~11~33 minecraft:stonebrick 0
fill ~7~6~33 ~9~6~33 minecraft:log 1
fill ~7~7~33 ~7~7~38 minecraft:stonebrick 0
fill ~9~8~33 ~9~8~34 minecraft:stained_hardened_clay 4
fill ~10~6~33 ~10~6~36 minecraft:stonebrick 0
fill ~10~8~33 ~10~8~37 minecraft:stonebrick 0
setblock ~11~5~33 minecraft:stone_button 4
setblock ~12~0~33 minecraft:stone_stairs 4
fill ~12~1~33 ~12~3~33 minecraft:cobblestone_wall 0
setblock ~12~4~33 minecraft:stone_stairs 0
setblock ~12~5~33 minecraft:log 1
setblock ~13~1~33 minecraft:brick_block
setblock ~13~3~33 minecraft:brick_block
fill ~13~4~33 ~13~5~35 minecraft:stonebrick 0
setblock ~14~0~33 minecraft:stonebrick 0
fill ~14~1~33 ~14~2~33 minecraft:stonebrick 1
setblock ~14~3~33 minecraft:stonebrick 2
setblock ~14~5~33 minecraft:stonebrick 1
setblock ~14~6~33 minecraft:stonebrick 2
setblock ~14~8~33 minecraft:double_stone_block_slab 0
fill ~14~9~33 ~14~10~33 minecraft:stonebrick 0
fill ~15~0~33 ~15~0~44 minecraft:grass
setblock ~15~1~33 minecraft:vine 2
fill ~15~11~33 ~15~11~34 minecraft:stone_block_slab 11
setblock ~18~1~33 minecraft:tallgrass 0
setblock ~21~2~33 minecraft:yellow_flower
setblock ~22~2~33 minecraft:tallgrass 0
fill ~23~0~33 ~23~0~40 minecraft:stone 0
setblock ~23~2~33 minecraft:yellow_flower
setblock ~24~1~33 minecraft:stone 0
fill ~24~2~33 ~24~2~34 minecraft:grass
fill ~24~6~33 ~24~6~36 minecraft:wooden_slab 9
fill ~25~5~33 ~26~5~33 minecraft:fence 0
fill ~25~6~33 ~27~6~33 minecraft:wooden_slab 1
fill ~26~2~33 ~26~2~42 minecraft:dirt 0
fill ~26~3~33 ~26~3~35 minecraft:grass
setblock ~26~4~33 minecraft:fence 0
fill ~26~11~33 ~28~11~37 minecraft:leaves 0
fill ~26~12~33 ~28~12~36 minecraft:leaves 0
setblock ~27~3~33 minecraft:dirt 0
fill ~27~4~33 ~27~5~33 minecraft:log2 0
fill ~28~13~33 ~28~13~34 minecraft:leaves 0
fill ~28~14~33 ~30~14~33 minecraft:leaves 0
setblock ~30~4~33 minecraft:tallgrass 0
setblock ~30~13~33 minecraft:leaves 0
fill ~30~15~33 ~31~15~33 minecraft:leaves 0
fill ~31~9~33 ~31~10~33 minecraft:leaves 0
setblock ~31~13~33 minecraft:log 0
setblock ~32~3~33 minecraft:grass
setblock ~32~4~33 minecraft:tallgrass 0
setblock ~32~10~33 minecraft:log 0
fill ~32~12~33 ~32~12~38 minecraft:leaves 0
fill ~32~14~33 ~32~15~33 minecraft:leaves 0
setblock ~33~3~33 minecraft:cobblestone
setblock ~33~4~33 minecraft:stone_block_slab 3
setblock ~33~10~33 minecraft:leaves 0
fill ~34~3~33 ~39~3~37 minecraft:dirt 0
fill ~34~4~33 ~35~4~34 minecraft:cobblestone
fill ~34~10~33 ~34~10~34 minecraft:leaves 0
setblock ~34~11~33 minecraft:leaves 0
setblock ~34~12~33 minecraft:leaves 0
fill ~36~1~33 ~36~1~55 minecraft:dirt 0
fill ~36~4~33 ~39~4~33 minecraft:grass
setblock ~36~5~33 minecraft:tallgrass 0
fill ~38~5~33 ~38~5~35 minecraft:tallgrass 0
fill ~40~3~33 ~41~3~33 minecraft:grass
setblock ~40~4~33 minecraft:tallgrass 0
fill ~41~1~33 ~41~1~74 minecraft:dirt 0
setblock ~41~4~33 minecraft:red_flower 3
fill ~42~3~33 ~43~3~34 minecraft:cobblestone
fill ~46~0~33 ~46~0~68 minecraft:stone 0
fill ~46~2~33 ~46~2~34 minecraft:dirt 0
setblock ~46~3~33 minecraft:cobblestone
fill ~47~2~33 ~48~2~33 minecraft:cobblestone
fill ~47~3~33 ~48~3~33 minecraft:stone_block_slab 3
fill ~49~1~33 ~49~1~40 minecraft:dirt 0
setblock ~49~2~33 minecraft:grass
setblock ~50~1~33 minecraft:grass
fill ~53~1~33 ~54~1~34 minecraft:cobblestone
setblock ~56~5~33 minecraft:stone_block_slab 11
fill ~57~5~33 ~57~5~34 minecraft:stone_block_slab 3
fill ~58~1~33 ~58~1~34 minecraft:water 0
setblock ~58~5~33 minecraft:double_stone_block_slab 3
fill ~58~6~33 ~59~6~33 minecraft:water 2
fill ~59~2~33 ~59~5~33 minecraft:water 10
fill ~60~0~33 ~60~0~67 minecraft:dirt 0
setblock ~61~0~33 minecraft:stone 0
fill ~61~1~33 ~61~1~36 minecraft:water 0
fill ~61~11~33 ~61~11~34 minecraft:stone_block_slab 11
setblock ~62~0~33 minecraft:stonebrick 0
fill ~62~1~33 ~62~2~33 minecraft:stonebrick 1
fill ~62~4~33 ~63~4~33 minecraft:stonebrick 0
setblock ~62~7~33 minecraft:stonebrick 0
setblock ~62~8~33 minecraft:double_stone_block_slab 0
fill ~62~9~33 ~62~10~33 minecraft:stonebrick 0
setblock ~63~1~33 minecraft:brick_block
setblock ~63~3~33 minecraft:brick_block
fill ~63~5~33 ~63~5~35 minecraft:stonebrick 0
fill ~63~6~33 ~63~6~34 minecraft:stonebrick 0
setblock ~64~0~33 minecraft:stone_stairs 5
fill ~64~1~33 ~64~3~33 minecraft:cobblestone_wall 0
setblock ~64~4~33 minecraft:stone_stairs 1
setblock ~64~5~33 minecraft:log 1
setblock ~65~5~33 minecraft:stone_button 5
fill ~66~6~33 ~66~6~36 minecraft:stonebrick 0
fill ~66~8~33 ~66~8~37 minecraft:stonebrick 0
fill ~67~6~33 ~69~6~33 minecraft:log 1
fill ~67~8~33 ~67~8~34 minecraft:stained_hardened_clay 14
fill ~69~7~33 ~69~7~38 minecraft:stonebrick 0
setblock ~70~6~33 minecraft:stone_button 5
setblock ~70~7~33 minecraft:stone_stairs 5
fill ~70~10~33 ~70~11~33 minecraft:stonebrick 0
setblock ~71~8~33 minecraft:stone_stairs 5
setblock ~71~9~33 minecraft:stonebrick 3
fill ~71~10~33 ~71~11~33 minecraft:log 1
setblock ~71~12~33 minecraft:stone_block_slab 3
setblock ~5~8~34 minecraft:stone_stairs 6
fill ~5~9~34 ~5~9~35 minecraft:stonebrick 0
fill ~5~10~34 ~5~11~35 minecraft:iron_bars
fill ~5~12~34 ~5~13~35 minecraft:stonebrick 0
fill ~6~7~34 ~6~7~41 minecraft:stonebrick 0
fill ~6~8~34 ~6~8~35 minecraft:double_stone_block_slab 0
setblock ~7~6~34 minecraft:stone_brick_stairs 7
fill ~7~8~34 ~7~8~36 minecraft:stonebrick 0
setblock ~8~6~34 minecraft:lit_redstone_lamp
setblock ~8~7~34 minecraft:redstone_block
setblock ~9~6~34 minecraft:nether_brick_fence
fill ~10~2~34 ~11~2~34 minecraft:iron_bars
setblock ~11~0~34 minecraft:stone_brick_stairs 0
setblock ~11~1~34 minecraft:stone_stairs 4
setblock ~11~3~34 minecraft:stone_stairs 0
setblock ~11~4~34 minecraft:stone_brick_stairs 4
setblock ~11~5~34 minecraft:stonebrick 3
fill ~12~0~34 ~12~0~36 minecraft:stonebrick 0
fill ~12~1~34 ~13~1~35 minecraft:stonebrick 0
setblock ~12~2~34 minecraft:brick_block
fill ~12~3~34 ~13~3~35 minecraft:stonebrick 0
fill ~12~4~34 ~12~5~36 minecraft:stonebrick 0
fill ~12~8~34 ~12~8~35 minecraft:stonebrick 0
fill ~13~2~34 ~13~2~35 minecraft:stonebrick 0
setblock ~13~6~34 minecraft:stonebrick 1
setblock ~13~7~34 minecraft:stonebrick 2
fill ~13~8~34 ~13~8~35 minecraft:double_stone_block_slab 0
setblock ~13~9~34 minecraft:stonebrick 2
fill ~14~0~34 ~14~0~45 minecraft:grass
fill ~14~1~34 ~14~3~34 minecraft:vine 4
fill ~14~11~34 ~14~11~36 minecraft:stone_block_slab 11
fill ~16~1~34 ~16~1~35 minecraft:tallgrass 0
setblock ~17~1~34 minecraft:red_flower 0
fill ~18~0~34 ~18~0~37 minecraft:dirt 0
fill ~18~1~34 ~18~1~37 minecraft:grass
fill ~18~2~34 ~19~2~34 minecraft:tallgrass 0
setblock ~21~2~34 minecraft:tallgrass 0
setblock ~21~4~34 minecraft:fence 0
fill ~23~1~34 ~24~1~38 minecraft:dirt 0
setblock ~23~2~34 minecraft:grass
setblock ~25~2~34 minecraft:stone 0
setblock ~25~3~34 minecraft:grass
fill ~25~4~34 ~25~5~34 minecraft:fence 0
fill ~25~6~34 ~25~6~35 minecraft:wooden_slab 1
fill ~25~11~34 ~25~12~36 minecraft:leaves 0
setblock ~26~4~34 minecraft:web
setblock ~26~5~34 minecraft:wooden_slab 9
fill ~27~3~34 ~30~3~34 minecraft:grass
setblock ~27~4~34 minecraft:fence 0
setblock ~27~10~34 minecraft:leaves 0
fill ~27~13~34 ~27~13~36 minecraft:leaves 0
fill ~27~14~34 ~28~14~34 minecraft:leaves 0
fill ~28~15~34 ~29~15~35 minecraft:leaves 0
fill ~29~11~34 ~29~11~36 minecraft:leaves 0
fill ~29~13~34 ~29~14~35 minecraft:leaves 0
fill ~29~16~34 ~29~16~38 minecraft:leaves 0
setblock ~30~1~34 minecraft:dirt 0
fill ~30~13~34 ~30~13~35 minecraft:log 0
fill ~30~14~34 ~30~14~35 minecraft:leaves 0
fill ~30~15~34 ~30~16~34 minecraft:leaves 0
fill ~31~1~34 ~32~1~34 minecraft:stone 0
fill ~31~3~34 ~33~3~37 minecraft:dirt 0
fill ~31~4~34 ~33~4~37 minecraft:grass
fill ~31~9~34 ~31~10~34 minecraft:log 0
fill ~31~11~34 ~31~11~35 minecraft:leaves 0
fill ~31~13~34 ~31~13~35 minecraft:leaves 0
