setblock ~6 ~29 ~35 chest 0  
setblock ~6 ~29 ~34 chest 0  
setblock ~6 ~29 ~97 chest 0  
setblock ~6 ~29 ~98 chest 0  
setblock ~26 ~29 ~34 chest 0  
setblock ~26 ~29 ~35 chest 0  
setblock ~27 ~29 ~97 iron_block 0  
setblock ~26 ~29 ~97 chest 0  
setblock ~27 ~29 ~98 iron_block 0  
setblock ~26 ~29 ~98 chest 0  
setblock ~56 ~0 ~0 chest 0  
setblock ~54 ~0 ~4 chest 0  
setblock ~57 ~0 ~4 chest 0  
setblock ~51 ~0 ~4 chest 0  
setblock ~54 ~0 ~14 chest 0  
setblock ~57 ~0 ~14 chest 0  
setblock ~56 ~0 ~18 chest 0  
setblock ~62 ~0 ~0 chest 0  
setblock ~59 ~0 ~0 chest 0  
setblock ~71 ~0 ~0 chest 0  
setblock ~68 ~0 ~0 chest 0  
setblock ~65 ~0 ~0 chest 0  
setblock ~63 ~0 ~4 chest 0  
setblock ~60 ~0 ~4 chest 0  
setblock ~63 ~0 ~14 chest 0  
setblock ~60 ~0 ~14 chest 0  
setblock ~72 ~0 ~4 chest 0  
setblock ~66 ~0 ~4 chest 0  
setblock ~69 ~0 ~4 chest 0  
setblock ~69 ~0 ~14 chest 0  
setblock ~66 ~0 ~14 chest 0  
setblock ~72 ~0 ~14 chest 0  
setblock ~59 ~0 ~18 chest 0  
setblock ~62 ~0 ~18 chest 0  
setblock ~65 ~0 ~18 chest 0  
setblock ~71 ~0 ~18 chest 0  
setblock ~68 ~0 ~18 chest 0  
setblock ~74 ~0 ~0 chest 0  
setblock ~77 ~0 ~0 chest 0  
setblock ~80 ~0 ~0 chest 0  
setblock ~89 ~0 ~0 chest 0  
setblock ~83 ~0 ~0 chest 0  
setblock ~86 ~0 ~0 chest 0  
setblock ~75 ~0 ~4 chest 0  
setblock ~78 ~0 ~4 chest 0  
setblock ~75 ~0 ~14 chest 0  
setblock ~84 ~0 ~4 chest 0  
setblock ~81 ~0 ~4 chest 0  
setblock ~87 ~0 ~4 chest 0  
setblock ~85 ~0 ~14 chest 0  
setblock ~82 ~0 ~14 chest 0  
setblock ~88 ~0 ~14 chest 0  
setblock ~74 ~0 ~18 chest 0  
setblock ~81 ~0 ~18 chest 0  
setblock ~87 ~0 ~18 chest 0  
setblock ~84 ~0 ~18 chest 0  
setblock ~95 ~0 ~0 chest 0  
setblock ~92 ~0 ~0 chest 0  
setblock ~98 ~0 ~0 chest 0  
setblock ~93 ~0 ~4 chest 0  
setblock ~90 ~0 ~4 chest 0  
setblock ~94 ~0 ~14 chest 0  
setblock ~91 ~0 ~14 chest 0  
setblock ~96 ~0 ~4 chest 0  
setblock ~99 ~0 ~4 chest 0  
setblock ~103 ~0 ~14 chest 0  
setblock ~100 ~0 ~14 chest 0  
setblock ~97 ~0 ~14 chest 0  
setblock ~90 ~0 ~18 chest 0  
setblock ~93 ~0 ~18 chest 0  
setblock ~96 ~0 ~18 chest 0  
setblock ~99 ~0 ~18 chest 0  
setblock ~128 ~29 ~35 chest 0  
setblock ~128 ~29 ~34 chest 0  
setblock ~128 ~29 ~97 chest 0  
setblock ~128 ~29 ~98 chest 0  
setblock ~148 ~29 ~34 chest 0  
setblock ~148 ~29 ~35 chest 0  
setblock ~148 ~29 ~97 chest 0  
setblock ~148 ~29 ~98 chest 0  
fill ~1 ~0 ~22 ~1 ~17 ~22 stone 
setblock ~1 ~0 ~23 glowstone 0  
fill ~1 ~0 ~24 ~1 ~2 ~24 stone 
setblock ~1 ~0 ~25 glowstone 0  
fill ~1 ~0 ~26 ~1 ~2 ~26 stone 
setblock ~1 ~0 ~27 glowstone 0  
fill ~1 ~0 ~28 ~1 ~2 ~28 stone 
setblock ~1 ~0 ~29 glowstone 0  
fill ~1 ~0 ~30 ~1 ~2 ~30 stone 
setblock ~1 ~0 ~31 glowstone 0  
fill ~1 ~0 ~32 ~1 ~17 ~32 stone 
setblock ~1 ~0 ~33 glowstone 0  
fill ~1 ~0 ~34 ~1 ~17 ~34 stone 
setblock ~1 ~0 ~35 glowstone 0  
fill ~1 ~0 ~36 ~1 ~2 ~36 stone 
setblock ~1 ~0 ~37 glowstone 0  
fill ~1 ~0 ~38 ~1 ~2 ~38 stone 
setblock ~1 ~0 ~39 glowstone 0  
fill ~1 ~0 ~40 ~1 ~2 ~40 stone 
setblock ~1 ~0 ~41 glowstone 0  
fill ~1 ~0 ~42 ~1 ~17 ~42 stone 
setblock ~1 ~0 ~43 glowstone 0  
fill ~1 ~0 ~44 ~1 ~17 ~44 stone 
setblock ~1 ~0 ~45 glowstone 0  
fill ~1 ~0 ~46 ~1 ~2 ~46 stone 
setblock ~1 ~0 ~47 glowstone 0  
fill ~1 ~0 ~48 ~1 ~2 ~48 stone 
setblock ~1 ~0 ~49 glowstone 0  
fill ~1 ~0 ~50 ~1 ~2 ~50 stone 
setblock ~1 ~0 ~51 glowstone 0  
fill ~1 ~0 ~52 ~1 ~2 ~52 stone 
setblock ~1 ~0 ~53 glowstone 0  
fill ~1 ~0 ~54 ~1 ~17 ~54 stone 
setblock ~1 ~0 ~55 glowstone 0  
fill ~1 ~0 ~56 ~1 ~17 ~56 stone 
setblock ~1 ~0 ~57 glowstone 0  
fill ~1 ~0 ~58 ~1 ~2 ~58 stone 
setblock ~1 ~0 ~59 glowstone 0  
fill ~1 ~0 ~60 ~1 ~2 ~60 stone 
setblock ~1 ~0 ~61 glowstone 0  
fill ~1 ~0 ~62 ~1 ~2 ~62 stone 
setblock ~1 ~0 ~63 glowstone 0  
fill ~1 ~0 ~64 ~1 ~17 ~64 stone 
setblock ~1 ~0 ~65 glowstone 0  
fill ~1 ~0 ~66 ~1 ~17 ~66 stone 
setblock ~1 ~0 ~67 glowstone 0  
fill ~1 ~0 ~68 ~1 ~17 ~68 stone 
setblock ~1 ~0 ~69 glowstone 0  
fill ~1 ~0 ~70 ~1 ~2 ~70 stone 
setblock ~1 ~0 ~71 glowstone 0  
fill ~1 ~0 ~72 ~1 ~2 ~72 stone 
setblock ~1 ~0 ~73 glowstone 0  
fill ~1 ~0 ~74 ~1 ~2 ~74 stone 
setblock ~1 ~0 ~75 glowstone 0  
fill ~1 ~0 ~76 ~1 ~17 ~76 stone 
setblock ~1 ~0 ~77 glowstone 0  
fill ~1 ~0 ~78 ~1 ~17 ~78 stone 
setblock ~1 ~0 ~79 glowstone 0  
fill ~1 ~0 ~80 ~1 ~2 ~80 stone 
setblock ~1 ~0 ~81 glowstone 0  
fill ~1 ~0 ~82 ~1 ~2 ~82 stone 
setblock ~1 ~0 ~83 glowstone 0  
fill ~1 ~0 ~84 ~1 ~2 ~84 stone 
setblock ~1 ~0 ~85 glowstone 0  
fill ~1 ~0 ~86 ~1 ~2 ~86 stone 
setblock ~1 ~0 ~87 glowstone 0  
fill ~1 ~0 ~88 ~1 ~17 ~88 stone 
setblock ~1 ~0 ~89 glowstone 0  
fill ~1 ~0 ~90 ~1 ~17 ~90 stone 
setblock ~1 ~0 ~91 glowstone 0  
fill ~1 ~0 ~92 ~1 ~2 ~92 stone 
setblock ~1 ~0 ~93 glowstone 0  
fill ~1 ~0 ~94 ~1 ~2 ~94 stone 
setblock ~1 ~0 ~95 glowstone 0  
fill ~1 ~0 ~96 ~1 ~2 ~96 stone 
setblock ~1 ~0 ~97 glowstone 0  
fill ~1 ~0 ~98 ~1 ~17 ~98 stone 
setblock ~1 ~0 ~99 glowstone 0  
fill ~1 ~0 ~100 ~1 ~17 ~100 stone 
setblock ~1 ~0 ~101 glowstone 0  
fill ~1 ~0 ~102 ~1 ~2 ~102 stone 
setblock ~1 ~0 ~103 glowstone 0  
fill ~1 ~0 ~104 ~1 ~2 ~104 stone 
setblock ~1 ~0 ~105 glowstone 0  
fill ~1 ~0 ~106 ~1 ~2 ~106 stone 
setblock ~1 ~0 ~107 glowstone 0  
fill ~1 ~0 ~108 ~1 ~2 ~108 stone 
setblock ~1 ~0 ~109 glowstone 0  
fill ~1 ~0 ~110 ~1 ~17 ~110 stone  
fill ~2 ~0 ~19 ~2 ~17 ~19 stone  
fill ~2 ~0 ~20 ~2 ~17 ~20 stone  
fill ~2 ~0 ~21 ~2 ~17 ~21 stone  
fill ~2 ~0 ~111 ~2 ~17 ~111 stone  
fill ~2 ~0 ~112 ~2 ~17 ~112 stone  
fill ~2 ~0 ~113 ~2 ~17 ~113 stone  
fill ~3 ~0 ~17 ~3 ~17 ~17 stone  
fill ~3 ~0 ~18 ~3 ~17 ~18 stone  
fill ~3 ~0 ~114 ~3 ~17 ~114 stone  
fill ~3 ~0 ~115 ~3 ~17 ~115 stone  
fill ~4 ~0 ~16 ~4 ~17 ~16 stone  
fill ~4 ~0 ~116 ~4 ~17 ~116 stone  
fill ~5 ~0 ~15 ~5 ~17 ~15 stone  
fill ~5 ~0 ~117 ~5 ~17 ~117 stone  
fill ~6 ~0 ~14 ~6 ~17 ~14 stone  
fill ~6 ~0 ~118 ~6 ~17 ~118 stone  
fill ~7 ~0 ~13 ~7 ~17 ~13 stone  
fill ~7 ~0 ~119 ~7 ~17 ~119 stone  
fill ~8 ~0 ~12 ~8 ~17 ~12 stone  
fill ~8 ~0 ~120 ~8 ~17 ~120 stone  
fill ~9 ~0 ~12 ~9 ~12 ~12 double_stone_slab  
fill ~9 ~0 ~120 ~9 ~12 ~120 double_stone_slab  
fill ~23 ~0 ~12 ~23 ~12 ~12 double_stone_slab  
fill ~23 ~0 ~120 ~23 ~12 ~120 double_stone_slab  
fill ~24 ~0 ~12 ~24 ~17 ~12 stone  
fill ~24 ~0 ~120 ~24 ~17 ~120 stone  
fill ~25 ~0 ~13 ~25 ~17 ~13 stone  
fill ~25 ~0 ~119 ~25 ~17 ~119 stone  
fill ~26 ~0 ~14 ~26 ~17 ~14 stone  
fill ~26 ~0 ~118 ~26 ~17 ~118 stone  
fill ~27 ~0 ~15 ~27 ~17 ~15 stone  
fill ~27 ~0 ~117 ~27 ~17 ~117 stone  
fill ~28 ~0 ~16 ~28 ~17 ~16 stone  
fill ~28 ~0 ~116 ~28 ~17 ~116 stone  
fill ~29 ~0 ~17 ~29 ~17 ~17 stone  
fill ~29 ~0 ~18 ~29 ~17 ~18 stone  
fill ~29 ~0 ~114 ~29 ~17 ~114 stone  
fill ~29 ~0 ~115 ~29 ~17 ~115 stone  
fill ~30 ~0 ~19 ~30 ~17 ~19 stone  
fill ~30 ~0 ~20 ~30 ~17 ~20 stone  
fill ~30 ~0 ~21 ~30 ~17 ~21 stone  
fill ~30 ~0 ~111 ~30 ~17 ~111 stone  
fill ~30 ~0 ~112 ~30 ~17 ~112 stone  
fill ~30 ~0 ~113 ~30 ~17 ~113 stone  
fill ~31 ~0 ~22 ~31 ~17 ~22 stone 
setblock ~31 ~0 ~23 glowstone 0  
fill ~31 ~0 ~24 ~31 ~17 ~24 stone 
setblock ~31 ~0 ~25 glowstone 0  
fill ~31 ~0 ~26 ~31 ~17 ~26 stone 
setblock ~31 ~0 ~27 glowstone 0  
fill ~31 ~0 ~28 ~31 ~17 ~28 stone 
setblock ~31 ~0 ~29 glowstone 0  
fill ~31 ~0 ~30 ~31 ~17 ~30 stone 
setblock ~31 ~0 ~31 glowstone 0  
fill ~31 ~0 ~32 ~31 ~17 ~32 stone 
setblock ~31 ~0 ~33 glowstone 0  
fill ~31 ~0 ~34 ~31 ~17 ~34 stone 
setblock ~31 ~0 ~35 glowstone 0  
fill ~31 ~0 ~36 ~31 ~17 ~36 stone 
setblock ~31 ~0 ~37 glowstone 0  
fill ~31 ~0 ~38 ~31 ~17 ~38 stone 
setblock ~31 ~0 ~39 glowstone 0  
fill ~31 ~0 ~40 ~31 ~17 ~40 stone 
setblock ~31 ~0 ~41 glowstone 0  
fill ~31 ~0 ~42 ~31 ~17 ~42 stone 
setblock ~31 ~0 ~43 glowstone 0  
fill ~31 ~0 ~44 ~31 ~17 ~44 stone 
setblock ~31 ~0 ~45 glowstone 0  
fill ~31 ~0 ~46 ~31 ~17 ~46 stone 
setblock ~31 ~0 ~47 glowstone 0  
fill ~31 ~0 ~48 ~31 ~17 ~48 stone 
setblock ~31 ~0 ~49 glowstone 0  
fill ~31 ~0 ~50 ~31 ~17 ~50 stone 
setblock ~31 ~0 ~51 glowstone 0  
fill ~31 ~0 ~52 ~31 ~17 ~52 stone 
setblock ~31 ~0 ~53 glowstone 0  
fill ~31 ~0 ~54 ~31 ~17 ~54 stone 
setblock ~31 ~0 ~55 glowstone 0  
fill ~31 ~0 ~56 ~32 ~0 ~56 stone 
setblock ~31 ~0 ~57 glowstone 0  
fill ~31 ~0 ~58 ~32 ~0 ~58 stone 
setblock ~31 ~0 ~59 glowstone 0  
fill ~31 ~0 ~60 ~32 ~0 ~60 stone 
setblock ~31 ~0 ~61 glowstone 0  
fill ~31 ~0 ~62 ~32 ~0 ~62 stone 
setblock ~31 ~0 ~63 glowstone 0 
setblock ~31 ~0 ~69 glowstone 0  
fill ~31 ~0 ~70 ~32 ~0 ~70 stone 
setblock ~31 ~0 ~71 glowstone 0  
fill ~31 ~0 ~72 ~32 ~0 ~72 stone 
setblock ~31 ~0 ~73 glowstone 0  
fill ~31 ~0 ~74 ~32 ~0 ~74 stone 
setblock ~31 ~0 ~75 glowstone 0  
fill ~31 ~0 ~76 ~32 ~0 ~76 stone 
setblock ~31 ~0 ~77 glowstone 0  
fill ~31 ~0 ~78 ~31 ~17 ~78 stone 
setblock ~31 ~0 ~79 glowstone 0  
fill ~31 ~0 ~80 ~31 ~17 ~80 stone 
setblock ~31 ~0 ~81 glowstone 0  
fill ~31 ~0 ~82 ~31 ~17 ~82 stone 
setblock ~31 ~0 ~83 glowstone 0  
fill ~31 ~0 ~84 ~31 ~17 ~84 stone 
setblock ~31 ~0 ~85 glowstone 0  
fill ~31 ~0 ~86 ~31 ~17 ~86 stone 
setblock ~31 ~0 ~87 glowstone 0  
fill ~31 ~0 ~88 ~31 ~17 ~88 stone 
setblock ~31 ~0 ~89 glowstone 0  
fill ~31 ~0 ~90 ~31 ~17 ~90 stone 
setblock ~31 ~0 ~91 glowstone 0  
fill ~31 ~0 ~92 ~31 ~17 ~92 stone 
setblock ~31 ~0 ~93 glowstone 0  
fill ~31 ~0 ~94 ~31 ~17 ~94 stone 
setblock ~31 ~0 ~95 glowstone 0  
fill ~31 ~0 ~96 ~31 ~17 ~96 stone 
setblock ~31 ~0 ~97 glowstone 0  
fill ~31 ~0 ~98 ~31 ~17 ~98 stone 
setblock ~31 ~0 ~99 glowstone 0  
fill ~31 ~0 ~100 ~31 ~17 ~100 stone 
setblock ~31 ~0 ~101 glowstone 0  
fill ~31 ~0 ~102 ~31 ~17 ~102 stone 
setblock ~31 ~0 ~103 glowstone 0  
fill ~31 ~0 ~104 ~31 ~17 ~104 stone 
setblock ~31 ~0 ~105 glowstone 0  
fill ~31 ~0 ~106 ~31 ~17 ~106 stone 
setblock ~31 ~0 ~107 glowstone 0  
fill ~31 ~0 ~108 ~31 ~17 ~108 stone 
setblock ~31 ~0 ~109 glowstone 0  
fill ~31 ~0 ~110 ~31 ~17 ~110 stone 
setblock ~32 ~0 ~55 stone 0 
setblock ~32 ~0 ~57 stone 0 
setblock ~32 ~0 ~59 stone 0 
setblock ~32 ~0 ~61 stone 0 
setblock ~32 ~0 ~63 stone 0 
setblock ~32 ~0 ~69 stone 0 
setblock ~32 ~0 ~71 stone 0 
setblock ~32 ~0 ~73 stone 0 
setblock ~32 ~0 ~75 stone 0 
setblock ~32 ~0 ~77 stone 0  
fill ~33 ~0 ~51 ~33 ~0 ~51 stone  
fill ~33 ~0 ~52 ~33 ~0 ~52 stone  
fill ~33 ~0 ~53 ~33 ~0 ~53 stone  
fill ~33 ~0 ~54 ~33 ~0 ~54 stone  
fill ~33 ~0 ~78 ~33 ~0 ~78 stone  
fill ~33 ~0 ~79 ~33 ~0 ~79 stone  
fill ~33 ~0 ~80 ~33 ~0 ~80 stone  
fill ~33 ~0 ~81 ~33 ~0 ~81 stone  
fill ~34 ~0 ~49 ~34 ~0 ~50 stone  
fill ~34 ~0 ~82 ~34 ~0 ~83 stone  
fill ~35 ~0 ~0 ~35 ~0 ~1 wool  
fill ~35 ~0 ~2 ~35 ~0 ~28 stone_slab 
setblock ~35 ~0 ~29 wool 11 
setblock ~35 ~0 ~30 stone_slab 0  
fill ~35 ~0 ~47 ~35 ~0 ~48 stone  
fill ~35 ~0 ~84 ~35 ~0 ~85 stone 
setblock ~35 ~0 ~102 stone_slab 0 
setblock ~35 ~0 ~103 wool 11  
fill ~35 ~0 ~104 ~35 ~0 ~130 stone_slab  
fill ~35 ~0 ~131 ~35 ~0 ~132 wool  
fill ~36 ~0 ~0 ~42 ~0 ~0 iron_block  
fill ~36 ~0 ~1 ~42 ~0 ~1 iron_block  
fill ~36 ~0 ~2 ~42 ~0 ~2 iron_block  
fill ~36 ~0 ~3 ~42 ~0 ~3 iron_block  
fill ~36 ~0 ~4 ~42 ~0 ~4 iron_block  
fill ~36 ~0 ~5 ~42 ~0 ~5 iron_block  
fill ~36 ~0 ~6 ~42 ~0 ~6 iron_block  
fill ~36 ~0 ~7 ~42 ~0 ~7 iron_block  
fill ~36 ~0 ~8 ~42 ~0 ~8 iron_block  
fill ~36 ~0 ~9 ~42 ~0 ~9 iron_block  
fill ~36 ~0 ~10 ~42 ~0 ~10 iron_block  
fill ~36 ~0 ~11 ~42 ~0 ~11 iron_block  
fill ~36 ~0 ~12 ~42 ~0 ~12 iron_block  
fill ~36 ~0 ~13 ~42 ~0 ~13 iron_block  
fill ~36 ~0 ~14 ~42 ~0 ~14 iron_block  
fill ~36 ~0 ~15 ~42 ~0 ~15 iron_block  
fill ~36 ~0 ~16 ~42 ~0 ~16 iron_block  
fill ~36 ~0 ~17 ~42 ~0 ~17 iron_block  
fill ~36 ~0 ~18 ~42 ~0 ~18 iron_block  
fill ~36 ~0 ~19 ~42 ~0 ~19 iron_block  
fill ~36 ~0 ~20 ~42 ~0 ~20 iron_block  
fill ~36 ~0 ~21 ~42 ~0 ~21 iron_block  
fill ~36 ~0 ~22 ~42 ~0 ~22 iron_block  
fill ~36 ~0 ~23 ~42 ~0 ~23 iron_block  
fill ~36 ~0 ~24 ~42 ~0 ~24 iron_block  
fill ~36 ~0 ~25 ~42 ~0 ~25 iron_block  
fill ~36 ~0 ~26 ~36 ~3 ~26 iron_block  
fill ~36 ~0 ~27 ~36 ~2 ~27 iron_block  
fill ~36 ~0 ~28 ~36 ~1 ~28 iron_block  
fill ~36 ~0 ~29 ~36 ~0 ~0 iron_block 
setblock ~36 ~0 ~30 wool 11  
fill ~36 ~0 ~45 ~36 ~0 ~46 stone  
fill ~36 ~0 ~86 ~36 ~0 ~87 stone 
setblock ~36 ~0 ~102 wool 11  
fill ~36 ~0 ~103 ~36 ~0 ~132 iron_block  
fill ~37 ~0 ~43 ~37 ~0 ~44 stone  
fill ~37 ~0 ~88 ~37 ~0 ~89 stone  
fill ~37 ~0 ~107 ~42 ~0 ~107 iron_block  
fill ~37 ~0 ~108 ~42 ~0 ~108 iron_block  
fill ~37 ~0 ~109 ~42 ~0 ~109 iron_block  
fill ~37 ~0 ~110 ~42 ~0 ~110 iron_block  
fill ~37 ~0 ~111 ~42 ~0 ~111 iron_block  
fill ~37 ~0 ~112 ~42 ~0 ~112 iron_block  
fill ~37 ~0 ~113 ~42 ~0 ~113 iron_block  
fill ~37 ~0 ~114 ~42 ~0 ~114 iron_block  
fill ~37 ~0 ~115 ~42 ~0 ~115 iron_block  
fill ~37 ~0 ~116 ~42 ~0 ~116 iron_block  
fill ~37 ~0 ~117 ~42 ~0 ~117 iron_block  
fill ~37 ~0 ~118 ~42 ~0 ~118 iron_block  
fill ~37 ~0 ~119 ~42 ~0 ~119 iron_block  
fill ~37 ~0 ~120 ~42 ~0 ~120 iron_block  
fill ~37 ~0 ~121 ~42 ~0 ~121 iron_block  
fill ~37 ~0 ~122 ~42 ~0 ~122 iron_block  
fill ~37 ~0 ~123 ~42 ~0 ~123 iron_block  
fill ~37 ~0 ~124 ~42 ~0 ~124 iron_block  
fill ~37 ~0 ~125 ~42 ~0 ~125 iron_block  
fill ~37 ~0 ~126 ~42 ~0 ~126 iron_block  
fill ~37 ~0 ~127 ~42 ~0 ~127 iron_block  
fill ~37 ~0 ~128 ~42 ~0 ~128 iron_block  
fill ~37 ~0 ~129 ~42 ~0 ~129 iron_block  
fill ~37 ~0 ~130 ~42 ~0 ~130 iron_block  
fill ~37 ~0 ~131 ~42 ~0 ~131 iron_block  
fill ~37 ~0 ~132 ~42 ~0 ~132 iron_block  
fill ~38 ~0 ~41 ~38 ~0 ~42 stone  
fill ~38 ~0 ~90 ~38 ~0 ~91 stone 
setblock ~39 ~0 ~40 stone 0 
setblock ~39 ~0 ~92 stone 0  
fill ~40 ~0 ~38 ~40 ~0 ~39 stone  
fill ~40 ~0 ~93 ~40 ~0 ~94 stone 
setblock ~41 ~0 ~37 stone 0 
setblock ~41 ~0 ~95 stone 0  
fill ~42 ~0 ~26 ~42 ~3 ~26 iron_block  
fill ~42 ~0 ~27 ~42 ~2 ~27 iron_block  
fill ~42 ~0 ~28 ~42 ~1 ~28 iron_block  
fill ~42 ~0 ~29 ~42 ~0 ~0 iron_block 
setblock ~42 ~0 ~30 wool 11  
fill ~42 ~0 ~36 ~42 ~0 ~36 stone  
fill ~42 ~0 ~96 ~42 ~0 ~96 stone 
setblock ~42 ~0 ~102 wool 11  
fill ~42 ~0 ~103 ~42 ~0 ~132 iron_block  
fill ~43 ~0 ~0 ~43 ~0 ~1 wool  
fill ~43 ~0 ~2 ~43 ~0 ~28 stone_slab 
setblock ~43 ~0 ~29 wool 11 
setblock ~43 ~0 ~30 stone_slab 0 
setblock ~43 ~0 ~35 stone 0 
setblock ~43 ~0 ~97 stone 0 
setblock ~43 ~0 ~102 stone_slab 0 
setblock ~43 ~0 ~103 wool 11  
fill ~43 ~0 ~104 ~43 ~0 ~130 stone_slab  
fill ~43 ~0 ~131 ~43 ~0 ~132 wool  
fill ~44 ~0 ~34 ~44 ~4 ~34 stone  
fill ~44 ~0 ~98 ~44 ~4 ~98 stone  
fill ~45 ~0 ~33 ~45 ~4 ~33 stone 
setblock ~45 ~0 ~34 glowstone 0  
fill ~45 ~0 ~56 ~45 ~0 ~57 oak_stairs  
fill ~45 ~0 ~75 ~45 ~0 ~76 oak_stairs 
setblock ~45 ~0 ~98 glowstone 0  
fill ~45 ~0 ~99 ~45 ~4 ~99 stone  
fill ~46 ~0 ~32 ~46 ~0 ~32 stone  
fill ~46 ~0 ~100 ~46 ~0 ~100 stone  
fill ~47 ~0 ~6 ~47 ~6 ~6 stone  
fill ~47 ~0 ~7 ~47 ~6 ~7 stone  
fill ~47 ~0 ~8 ~47 ~6 ~8 stone  
fill ~47 ~0 ~9 ~47 ~6 ~9 stone  
fill ~47 ~0 ~10 ~47 ~6 ~10 stone  
fill ~47 ~0 ~11 ~47 ~6 ~11 stone  
fill ~47 ~0 ~12 ~47 ~6 ~12 stone 
setblock ~47 ~0 ~31 stone 0  
fill ~47 ~0 ~54 ~48 ~0 ~54 oak_stairs  
fill ~47 ~0 ~56 ~48 ~0 ~56 stone_slab  
fill ~47 ~0 ~57 ~48 ~0 ~57 stone_slab  
fill ~47 ~0 ~59 ~48 ~0 ~59 oak_stairs  
fill ~47 ~0 ~73 ~48 ~0 ~73 oak_stairs  
fill ~47 ~0 ~75 ~48 ~0 ~75 stone_slab  
fill ~47 ~0 ~76 ~48 ~0 ~76 stone_slab  
fill ~47 ~0 ~78 ~48 ~0 ~78 oak_stairs 
setblock ~47 ~0 ~101 stone 0  
fill ~48 ~0 ~4 ~48 ~6 ~4 stone  
fill ~48 ~0 ~5 ~48 ~6 ~5 stone  
fill ~48 ~0 ~13 ~48 ~6 ~13 stone  
fill ~48 ~0 ~14 ~48 ~6 ~14 stone  
fill ~48 ~0 ~30 ~48 ~0 ~30 stone  
fill ~48 ~0 ~48 ~48 ~0 ~49 oak_stairs  
fill ~48 ~0 ~83 ~48 ~0 ~84 oak_stairs  
fill ~48 ~0 ~102 ~48 ~0 ~102 stone  
fill ~49 ~0 ~3 ~49 ~6 ~3 stone  
fill ~49 ~0 ~15 ~49 ~6 ~15 stone  
fill ~49 ~0 ~29 ~50 ~0 ~29 stone  
fill ~49 ~0 ~103 ~50 ~0 ~103 stone  
fill ~50 ~0 ~2 ~50 ~6 ~2 stone 
setblock ~50 ~0 ~4 bed 8 
setblock ~50 ~0 ~5 bed 0  
fill ~50 ~0 ~16 ~50 ~6 ~16 stone  
fill ~50 ~0 ~46 ~51 ~0 ~46 oak_stairs  
fill ~50 ~0 ~48 ~51 ~0 ~48 stone_slab  
fill ~50 ~0 ~49 ~51 ~0 ~49 stone_slab  
fill ~50 ~0 ~51 ~51 ~0 ~51 oak_stairs  
fill ~50 ~0 ~56 ~50 ~0 ~57 oak_stairs  
fill ~50 ~0 ~75 ~50 ~0 ~76 oak_stairs  
fill ~50 ~0 ~81 ~51 ~0 ~81 oak_stairs  
fill ~50 ~0 ~83 ~51 ~0 ~83 stone_slab  
fill ~50 ~0 ~84 ~51 ~0 ~84 stone_slab  
fill ~50 ~0 ~86 ~51 ~0 ~86 oak_stairs  
fill ~51 ~0 ~1 ~51 ~6 ~1 stone  
fill ~51 ~0 ~17 ~51 ~6 ~17 stone  
fill ~51 ~0 ~28 ~51 ~0 ~28 stone  
fill ~51 ~0 ~104 ~51 ~0 ~104 stone  
fill ~52 ~0 ~0 ~53 ~0 ~0 stone  
fill ~52 ~0 ~18 ~53 ~0 ~18 stone  
fill ~52 ~0 ~27 ~53 ~0 ~27 stone  
fill ~52 ~0 ~105 ~53 ~0 ~105 stone 
setblock ~53 ~0 ~4 bed 8 
setblock ~53 ~0 ~5 bed 0 
setblock ~53 ~0 ~13 bed 0 
setblock ~53 ~0 ~14 bed 8  
fill ~53 ~0 ~48 ~53 ~0 ~49 oak_stairs  
fill ~53 ~0 ~83 ~53 ~0 ~84 oak_stairs  
fill ~54 ~0 ~19 ~77 ~0 ~19 stone  
fill ~54 ~0 ~26 ~55 ~0 ~26 stone  
fill ~54 ~0 ~106 ~55 ~0 ~106 stone 
setblock ~55 ~0 ~0 bed 8 
setblock ~55 ~0 ~1 bed 0 
setblock ~55 ~0 ~17 bed 0 
setblock ~55 ~0 ~18 bed 8 
setblock ~56 ~0 ~4 bed 8 
setblock ~56 ~0 ~5 bed 0 
setblock ~56 ~0 ~13 bed 0 
setblock ~56 ~0 ~14 bed 8  
fill ~56 ~0 ~25 ~57 ~0 ~25 stone  
fill ~56 ~0 ~107 ~57 ~0 ~107 stone  
fill ~57 ~0 ~38 ~57 ~0 ~39 oak_stairs  
fill ~57 ~0 ~92 ~57 ~0 ~93 oak_stairs 
setblock ~58 ~0 ~0 bed 8 
setblock ~58 ~0 ~1 bed 0 
setblock ~58 ~0 ~17 bed 0 
setblock ~58 ~0 ~18 bed 8  
fill ~58 ~0 ~24 ~59 ~0 ~24 stone  
fill ~58 ~0 ~108 ~59 ~0 ~108 stone 
setblock ~59 ~0 ~4 bed 8 
setblock ~59 ~0 ~5 bed 0 
setblock ~59 ~0 ~13 bed 0 
setblock ~59 ~0 ~14 bed 8  
fill ~59 ~0 ~36 ~60 ~0 ~36 oak_stairs  
fill ~59 ~0 ~38 ~60 ~0 ~38 stone_slab  
fill ~59 ~0 ~39 ~60 ~0 ~39 stone_slab  
fill ~59 ~0 ~41 ~60 ~0 ~41 oak_stairs  
fill ~59 ~0 ~90 ~60 ~0 ~90 oak_stairs  
fill ~59 ~0 ~92 ~60 ~0 ~92 stone_slab  
fill ~59 ~0 ~93 ~60 ~0 ~93 stone_slab  
fill ~59 ~0 ~95 ~60 ~0 ~95 oak_stairs  
fill ~60 ~0 ~23 ~61 ~0 ~23 stone  
fill ~60 ~0 ~109 ~61 ~0 ~109 stone 
setblock ~61 ~0 ~0 bed 8 
setblock ~61 ~0 ~1 bed 0 
setblock ~61 ~0 ~17 bed 0 
setblock ~61 ~0 ~18 bed 8 
setblock ~62 ~0 ~4 bed 8 
setblock ~62 ~0 ~5 bed 0 
setblock ~62 ~0 ~13 bed 0 
setblock ~62 ~0 ~14 bed 8  
fill ~62 ~0 ~22 ~65 ~0 ~22 stone  
fill ~62 ~0 ~38 ~62 ~0 ~39 oak_stairs  
fill ~62 ~0 ~92 ~62 ~0 ~93 oak_stairs  
fill ~62 ~0 ~110 ~65 ~0 ~110 stone 
setblock ~64 ~0 ~0 bed 8 
setblock ~64 ~0 ~1 bed 0 
setblock ~64 ~0 ~17 bed 0 
setblock ~64 ~0 ~18 bed 8 
setblock ~65 ~0 ~4 bed 8 
setblock ~65 ~0 ~5 bed 0 
setblock ~65 ~0 ~13 bed 0 
setblock ~65 ~0 ~14 bed 8  
fill ~65 ~0 ~35 ~65 ~0 ~36 oak_stairs  
fill ~65 ~0 ~95 ~65 ~0 ~96 oak_stairs  
fill ~66 ~0 ~21 ~77 ~0 ~21 stone  
fill ~66 ~0 ~111 ~75 ~0 ~111 stone 
setblock ~67 ~0 ~0 bed 8 
setblock ~67 ~0 ~1 bed 0 
setblock ~67 ~0 ~17 bed 0 
setblock ~67 ~0 ~18 bed 8  
fill ~67 ~0 ~33 ~68 ~0 ~33 oak_stairs  
fill ~67 ~0 ~35 ~68 ~0 ~35 stone_slab  
fill ~67 ~0 ~36 ~68 ~0 ~36 stone_slab  
fill ~67 ~0 ~38 ~68 ~0 ~38 oak_stairs  
fill ~67 ~0 ~93 ~68 ~0 ~93 oak_stairs  
fill ~67 ~0 ~95 ~68 ~0 ~95 stone_slab  
fill ~67 ~0 ~96 ~68 ~0 ~96 stone_slab  
fill ~67 ~0 ~98 ~68 ~0 ~98 oak_stairs 
setblock ~68 ~0 ~4 bed 8 
setblock ~68 ~0 ~5 bed 0 
setblock ~68 ~0 ~13 bed 0 
setblock ~68 ~0 ~14 bed 8  
fill ~69 ~0 ~65 ~69 ~1 ~65 stone  
fill ~69 ~0 ~66 ~69 ~0 ~67 stone 
setblock ~70 ~0 ~0 bed 8 
setblock ~70 ~0 ~1 bed 0 
setblock ~70 ~0 ~17 bed 0 
setblock ~70 ~0 ~18 bed 8  
fill ~70 ~0 ~35 ~70 ~0 ~36 oak_stairs  
fill ~70 ~0 ~65 ~73 ~0 ~65 double_stone_slab  
fill ~70 ~0 ~66 ~73 ~0 ~66 stone_slab  
fill ~70 ~0 ~95 ~70 ~0 ~96 oak_stairs 
setblock ~71 ~0 ~4 bed 8 
setblock ~71 ~0 ~5 bed 0 
setblock ~71 ~0 ~13 bed 0 
setblock ~71 ~0 ~14 bed 8  
fill ~71 ~0 ~109 ~74 ~0 ~109 stone_slab  
fill ~71 ~0 ~110 ~71 ~0 ~109 stone_slab  
fill ~71 ~0 ~112 ~73 ~0 ~112 stone  
fill ~71 ~0 ~113 ~71 ~2 ~113 stone  
fill ~71 ~0 ~114 ~71 ~2 ~114 stone  
fill ~71 ~0 ~115 ~71 ~2 ~115 stone  
fill ~71 ~0 ~116 ~71 ~2 ~116 stone  
fill ~71 ~0 ~117 ~71 ~2 ~117 stone  
fill ~71 ~0 ~118 ~75 ~0 ~118 stone 
setblock ~72 ~0 ~113 redstone_wire 12 
setblock ~73 ~0 ~0 bed 8 
setblock ~73 ~0 ~1 bed 0 
setblock ~73 ~0 ~17 bed 0 
setblock ~73 ~0 ~18 bed 8 
setblock ~73 ~0 ~113 redstone_wire 13 
setblock ~74 ~0 ~4 bed 8 
setblock ~74 ~0 ~5 bed 0 
setblock ~74 ~0 ~13 bed 0 
setblock ~74 ~0 ~14 bed 8 
setblock ~74 ~0 ~20 redstone_wire 12 
setblock ~74 ~0 ~65 stone 0 
setblock ~74 ~0 ~66 glowstone 0  
fill ~74 ~0 ~112 ~75 ~0 ~112 wool  
fill ~74 ~0 ~115 ~75 ~0 ~115 stone  
fill ~74 ~0 ~119 ~75 ~0 ~119 stone 
setblock ~75 ~0 ~20 cobblestone 0  
fill ~75 ~0 ~110 ~75 ~1 ~110 stone  
fill ~75 ~0 ~113 ~75 ~2 ~113 stone  
fill ~75 ~0 ~114 ~75 ~2 ~114 stone  
fill ~75 ~0 ~116 ~75 ~2 ~116 stone  
fill ~75 ~0 ~117 ~75 ~2 ~117 stone  
fill ~75 ~0 ~120 ~75 ~2 ~120 stone  
fill ~75 ~0 ~121 ~75 ~2 ~121 stone  
fill ~75 ~0 ~122 ~75 ~2 ~122 stone 
setblock ~76 ~0 ~0 bed 8 
setblock ~76 ~0 ~1 bed 0  
fill ~76 ~0 ~20 ~77 ~0 ~20 wool  
fill ~76 ~0 ~112 ~78 ~0 ~112 double_stone_slab 
setblock ~77 ~0 ~4 bed 8 
setblock ~77 ~0 ~5 bed 0  
fill ~78 ~0 ~19 ~79 ~0 ~19 stone_pressure_plate  
fill ~78 ~0 ~20 ~79 ~0 ~20 double_stone_slab  
fill ~78 ~0 ~21 ~79 ~0 ~21 stone_pressure_plate 
setblock ~78 ~0 ~110 stone_button 2 
setblock ~78 ~0 ~115 stone_button 2 
setblock ~79 ~0 ~0 bed 8 
setblock ~79 ~0 ~1 bed 0  
fill ~79 ~0 ~110 ~79 ~1 ~110 stone  
fill ~79 ~0 ~111 ~88 ~0 ~111 stone  
fill ~79 ~0 ~112 ~80 ~0 ~112 wool  
fill ~79 ~0 ~113 ~79 ~1 ~113 stone  
fill ~79 ~0 ~114 ~79 ~1 ~114 stone  
fill ~79 ~0 ~115 ~79 ~1 ~115 stone  
fill ~79 ~0 ~116 ~79 ~1 ~116 stone  
fill ~79 ~0 ~117 ~79 ~1 ~117 stone  
fill ~79 ~0 ~118 ~83 ~0 ~118 stone  
fill ~79 ~0 ~119 ~80 ~0 ~119 stone  
fill ~79 ~0 ~120 ~79 ~2 ~120 stone  
fill ~79 ~0 ~121 ~79 ~2 ~121 stone  
fill ~79 ~0 ~122 ~79 ~2 ~122 stone 
setblock ~80 ~0 ~4 bed 8 
setblock ~80 ~0 ~5 bed 0 
setblock ~80 ~0 ~17 bed 0 
setblock ~80 ~0 ~18 bed 8  
fill ~80 ~0 ~19 ~100 ~0 ~19 stone  
fill ~80 ~0 ~20 ~81 ~0 ~20 wool  
fill ~80 ~0 ~21 ~88 ~0 ~21 stone  
fill ~80 ~0 ~109 ~83 ~0 ~109 stone_slab 
setblock ~80 ~0 ~110 redstone_wire 0 
setblock ~80 ~0 ~115 redstone_wire 0 
setblock ~81 ~0 ~13 bed 0 
setblock ~81 ~0 ~14 bed 8  
fill ~81 ~0 ~112 ~83 ~0 ~112 stone 
setblock ~81 ~0 ~113 redstone_wire 13 
setblock ~82 ~0 ~0 bed 8 
setblock ~82 ~0 ~1 bed 0 
setblock ~82 ~0 ~20 stone 0 
setblock ~82 ~0 ~113 redstone_wire 12 
setblock ~83 ~0 ~4 bed 8 
setblock ~83 ~0 ~5 bed 0 
setblock ~83 ~0 ~17 bed 0 
setblock ~83 ~0 ~18 bed 8 
setblock ~83 ~0 ~20 redstone_wire 13 
setblock ~83 ~0 ~110 stone_slab 0  
fill ~83 ~0 ~113 ~83 ~2 ~113 stone  
fill ~83 ~0 ~114 ~83 ~2 ~114 stone  
fill ~83 ~0 ~115 ~83 ~2 ~115 stone  
fill ~83 ~0 ~116 ~83 ~2 ~116 stone  
fill ~83 ~0 ~117 ~83 ~2 ~117 stone 
setblock ~84 ~0 ~13 bed 0 
setblock ~84 ~0 ~14 bed 8  
fill ~84 ~0 ~35 ~84 ~0 ~36 oak_stairs  
fill ~84 ~0 ~95 ~84 ~0 ~96 oak_stairs 
setblock ~85 ~0 ~0 bed 8 
setblock ~85 ~0 ~1 bed 0 
setblock ~86 ~0 ~4 bed 8 
setblock ~86 ~0 ~5 bed 0 
setblock ~86 ~0 ~17 bed 0 
setblock ~86 ~0 ~18 bed 8  
fill ~86 ~0 ~33 ~87 ~0 ~33 oak_stairs  
fill ~86 ~0 ~35 ~87 ~0 ~35 stone_slab  
fill ~86 ~0 ~36 ~87 ~0 ~36 stone_slab  
fill ~86 ~0 ~38 ~87 ~0 ~38 oak_stairs  
fill ~86 ~0 ~93 ~87 ~0 ~93 oak_stairs  
fill ~86 ~0 ~95 ~87 ~0 ~95 stone_slab  
fill ~86 ~0 ~96 ~87 ~0 ~96 stone_slab  
fill ~86 ~0 ~98 ~87 ~0 ~98 oak_stairs 
setblock ~87 ~0 ~13 bed 0 
setblock ~87 ~0 ~14 bed 8 
setblock ~88 ~0 ~0 bed 8 
setblock ~88 ~0 ~1 bed 0 
setblock ~89 ~0 ~4 bed 8 
setblock ~89 ~0 ~5 bed 0 
setblock ~89 ~0 ~17 bed 0 
setblock ~89 ~0 ~18 bed 8  
fill ~89 ~0 ~22 ~92 ~0 ~22 stone  
fill ~89 ~0 ~35 ~89 ~0 ~36 oak_stairs  
fill ~89 ~0 ~95 ~89 ~0 ~96 oak_stairs  
fill ~89 ~0 ~110 ~92 ~0 ~110 stone 
setblock ~90 ~0 ~13 bed 0 
setblock ~90 ~0 ~14 bed 8 
setblock ~91 ~0 ~0 bed 8 
setblock ~91 ~0 ~1 bed 0 
setblock ~92 ~0 ~4 bed 8 
setblock ~92 ~0 ~5 bed 0 
setblock ~92 ~0 ~17 bed 0 
setblock ~92 ~0 ~18 bed 8  
fill ~92 ~0 ~38 ~92 ~0 ~39 oak_stairs  
fill ~92 ~0 ~92 ~92 ~0 ~93 oak_stairs 
setblock ~93 ~0 ~13 bed 0 
setblock ~93 ~0 ~14 bed 8  
fill ~93 ~0 ~23 ~94 ~0 ~23 stone  
fill ~93 ~0 ~109 ~94 ~0 ~109 stone 
setblock ~94 ~0 ~0 bed 8 
setblock ~94 ~0 ~1 bed 0  
fill ~94 ~0 ~36 ~95 ~0 ~36 oak_stairs  
fill ~94 ~0 ~38 ~95 ~0 ~38 stone_slab  
fill ~94 ~0 ~39 ~95 ~0 ~39 stone_slab  
fill ~94 ~0 ~41 ~95 ~0 ~41 oak_stairs  
fill ~94 ~0 ~90 ~95 ~0 ~90 oak_stairs  
fill ~94 ~0 ~92 ~95 ~0 ~92 stone_slab  
fill ~94 ~0 ~93 ~95 ~0 ~93 stone_slab  
fill ~94 ~0 ~95 ~95 ~0 ~95 oak_stairs 
setblock ~95 ~0 ~4 bed 8 
setblock ~95 ~0 ~5 bed 0 
setblock ~95 ~0 ~17 bed 0 
setblock ~95 ~0 ~18 bed 8  
fill ~95 ~0 ~24 ~96 ~0 ~24 stone  
fill ~95 ~0 ~108 ~96 ~0 ~108 stone 
setblock ~96 ~0 ~13 bed 0 
setblock ~96 ~0 ~14 bed 8 
setblock ~97 ~0 ~0 bed 8 
setblock ~97 ~0 ~1 bed 0  
fill ~97 ~0 ~25 ~98 ~0 ~25 stone  
fill ~97 ~0 ~38 ~97 ~0 ~39 oak_stairs  
fill ~97 ~0 ~92 ~97 ~0 ~93 oak_stairs  
fill ~97 ~0 ~107 ~98 ~0 ~107 stone 
setblock ~98 ~0 ~4 bed 8 
setblock ~98 ~0 ~5 bed 0 
setblock ~98 ~0 ~17 bed 0 
setblock ~98 ~0 ~18 bed 8 
setblock ~99 ~0 ~13 bed 0 
setblock ~99 ~0 ~14 bed 8  
fill ~99 ~0 ~26 ~100 ~0 ~26 stone  
fill ~99 ~0 ~106 ~100 ~0 ~106 stone 
setblock ~101 ~0 ~0 glowstone 0 
setblock ~101 ~0 ~18 glowstone 0  
fill ~101 ~0 ~27 ~102 ~0 ~27 stone  
fill ~101 ~0 ~48 ~101 ~0 ~49 oak_stairs  
fill ~101 ~0 ~83 ~101 ~0 ~84 oak_stairs  
fill ~101 ~0 ~105 ~102 ~0 ~105 stone  
fill ~102 ~0 ~0 ~102 ~6 ~0 stone 
setblock ~102 ~0 ~13 bed 0 
setblock ~102 ~0 ~14 bed 8  
fill ~102 ~0 ~18 ~102 ~6 ~18 stone 
setblock ~103 ~0 ~1 glowstone 0 
setblock ~103 ~0 ~17 glowstone 0  
fill ~103 ~0 ~28 ~103 ~0 ~28 stone  
fill ~103 ~0 ~46 ~104 ~0 ~46 oak_stairs  
fill ~103 ~0 ~48 ~104 ~0 ~48 stone_slab  
fill ~103 ~0 ~49 ~104 ~0 ~49 stone_slab  
fill ~103 ~0 ~51 ~104 ~0 ~51 oak_stairs  
fill ~103 ~0 ~81 ~104 ~0 ~81 oak_stairs  
fill ~103 ~0 ~83 ~104 ~0 ~83 stone_slab  
fill ~103 ~0 ~84 ~104 ~0 ~84 stone_slab  
fill ~103 ~0 ~86 ~104 ~0 ~86 oak_stairs  
fill ~103 ~0 ~104 ~103 ~0 ~104 stone 
setblock ~104 ~0 ~2 glowstone 0 
setblock ~104 ~0 ~16 glowstone 0  
fill ~104 ~0 ~29 ~105 ~0 ~29 stone  
fill ~104 ~0 ~56 ~104 ~0 ~57 oak_stairs  
fill ~104 ~0 ~75 ~104 ~0 ~76 oak_stairs  
fill ~104 ~0 ~103 ~105 ~0 ~103 stone 
setblock ~105 ~0 ~3 glowstone 0 
setblock ~105 ~0 ~15 glowstone 0  
fill ~106 ~0 ~4 ~106 ~6 ~4 stone 
setblock ~106 ~0 ~5 glowstone 0 
setblock ~106 ~0 ~13 glowstone 0  
fill ~106 ~0 ~14 ~106 ~6 ~14 stone  
fill ~106 ~0 ~30 ~106 ~0 ~30 stone  
fill ~106 ~0 ~48 ~106 ~0 ~49 oak_stairs  
fill ~106 ~0 ~54 ~107 ~0 ~54 oak_stairs  
fill ~106 ~0 ~56 ~107 ~0 ~56 stone_slab  
fill ~106 ~0 ~57 ~107 ~0 ~57 stone_slab  
fill ~106 ~0 ~59 ~107 ~0 ~59 oak_stairs  
fill ~106 ~0 ~73 ~107 ~0 ~73 oak_stairs  
fill ~106 ~0 ~75 ~107 ~0 ~75 stone_slab  
fill ~106 ~0 ~76 ~107 ~0 ~76 stone_slab  
fill ~106 ~0 ~78 ~107 ~0 ~78 oak_stairs  
fill ~106 ~0 ~83 ~106 ~0 ~84 oak_stairs  
fill ~106 ~0 ~102 ~106 ~0 ~102 stone  
fill ~107 ~0 ~6 ~107 ~6 ~6 stone  
fill ~107 ~0 ~7 ~107 ~6 ~7 stone  
fill ~107 ~0 ~8 ~107 ~6 ~8 stone  
fill ~107 ~0 ~9 ~107 ~6 ~9 stone  
fill ~107 ~0 ~10 ~107 ~6 ~10 stone  
fill ~107 ~0 ~11 ~107 ~6 ~11 stone  
fill ~107 ~0 ~12 ~107 ~6 ~12 stone 
setblock ~107 ~0 ~31 stone 0 
setblock ~107 ~0 ~101 stone 0  
fill ~108 ~0 ~32 ~108 ~0 ~32 stone  
fill ~108 ~0 ~100 ~108 ~0 ~100 stone  
fill ~109 ~0 ~33 ~109 ~4 ~33 stone 
setblock ~109 ~0 ~34 glowstone 0  
fill ~109 ~0 ~56 ~109 ~0 ~57 oak_stairs  
fill ~109 ~0 ~75 ~109 ~0 ~76 oak_stairs 
setblock ~109 ~0 ~98 glowstone 0  
fill ~109 ~0 ~99 ~109 ~4 ~99 stone  
fill ~110 ~0 ~34 ~110 ~4 ~34 stone  
fill ~110 ~0 ~98 ~110 ~4 ~98 stone  
fill ~111 ~0 ~0 ~111 ~0 ~1 wool  
fill ~111 ~0 ~2 ~111 ~0 ~28 stone_slab 
setblock ~111 ~0 ~29 wool 11 
setblock ~111 ~0 ~30 stone_slab 0 
setblock ~111 ~0 ~35 stone 0 
setblock ~111 ~0 ~97 stone 0 
setblock ~111 ~0 ~102 stone_slab 0 
setblock ~111 ~0 ~103 wool 11  
fill ~111 ~0 ~104 ~111 ~0 ~130 stone_slab  
fill ~111 ~0 ~131 ~111 ~0 ~132 wool  
fill ~112 ~0 ~0 ~118 ~0 ~0 iron_block  
fill ~112 ~0 ~1 ~118 ~0 ~1 iron_block  
fill ~112 ~0 ~2 ~118 ~0 ~2 iron_block  
fill ~112 ~0 ~3 ~118 ~0 ~3 iron_block  
fill ~112 ~0 ~4 ~118 ~0 ~4 iron_block  
fill ~112 ~0 ~5 ~118 ~0 ~5 iron_block  
fill ~112 ~0 ~6 ~118 ~0 ~6 iron_block  
fill ~112 ~0 ~7 ~118 ~0 ~7 iron_block  
fill ~112 ~0 ~8 ~118 ~0 ~8 iron_block  
fill ~112 ~0 ~9 ~118 ~0 ~9 iron_block  
fill ~112 ~0 ~10 ~118 ~0 ~10 iron_block  
fill ~112 ~0 ~11 ~118 ~0 ~11 iron_block  
fill ~112 ~0 ~12 ~118 ~0 ~12 iron_block  
fill ~112 ~0 ~13 ~118 ~0 ~13 iron_block  
fill ~112 ~0 ~14 ~118 ~0 ~14 iron_block  
fill ~112 ~0 ~15 ~118 ~0 ~15 iron_block  
fill ~112 ~0 ~16 ~118 ~0 ~16 iron_block  
fill ~112 ~0 ~17 ~118 ~0 ~17 iron_block  
fill ~112 ~0 ~18 ~118 ~0 ~18 iron_block  
fill ~112 ~0 ~19 ~118 ~0 ~19 iron_block  
fill ~112 ~0 ~20 ~118 ~0 ~20 iron_block  
fill ~112 ~0 ~21 ~118 ~0 ~21 iron_block  
fill ~112 ~0 ~22 ~118 ~0 ~22 iron_block  
fill ~112 ~0 ~23 ~118 ~0 ~23 iron_block  
fill ~112 ~0 ~24 ~118 ~0 ~24 iron_block  
fill ~112 ~0 ~25 ~118 ~0 ~25 iron_block  
fill ~112 ~0 ~26 ~112 ~3 ~26 iron_block  
fill ~112 ~0 ~27 ~112 ~2 ~27 iron_block  
fill ~112 ~0 ~28 ~112 ~1 ~28 iron_block  
fill ~112 ~0 ~29 ~112 ~0 ~0 iron_block 
setblock ~112 ~0 ~30 wool 11  
fill ~112 ~0 ~36 ~112 ~0 ~36 stone  
fill ~112 ~0 ~96 ~112 ~0 ~96 stone 
setblock ~112 ~0 ~102 wool 11  
fill ~112 ~0 ~103 ~112 ~0 ~132 iron_block 
setblock ~113 ~0 ~37 stone 0 
setblock ~113 ~0 ~95 stone 0  
fill ~113 ~0 ~107 ~118 ~0 ~107 iron_block  
fill ~113 ~0 ~108 ~118 ~0 ~108 iron_block  
fill ~113 ~0 ~109 ~118 ~0 ~109 iron_block  
fill ~113 ~0 ~110 ~118 ~0 ~110 iron_block  
fill ~113 ~0 ~111 ~118 ~0 ~111 iron_block  
fill ~113 ~0 ~112 ~118 ~0 ~112 iron_block  
fill ~113 ~0 ~113 ~118 ~0 ~113 iron_block  
fill ~113 ~0 ~114 ~118 ~0 ~114 iron_block  
fill ~113 ~0 ~115 ~118 ~0 ~115 iron_block  
fill ~113 ~0 ~116 ~118 ~0 ~116 iron_block  
fill ~113 ~0 ~117 ~118 ~0 ~117 iron_block  
fill ~113 ~0 ~118 ~118 ~0 ~118 iron_block  
fill ~113 ~0 ~119 ~118 ~0 ~119 iron_block  
fill ~113 ~0 ~120 ~118 ~0 ~120 iron_block  
fill ~113 ~0 ~121 ~118 ~0 ~121 iron_block  
fill ~113 ~0 ~122 ~118 ~0 ~122 iron_block  
fill ~113 ~0 ~123 ~118 ~0 ~123 iron_block  
fill ~113 ~0 ~124 ~118 ~0 ~124 iron_block  
fill ~113 ~0 ~125 ~118 ~0 ~125 iron_block  
fill ~113 ~0 ~126 ~118 ~0 ~126 iron_block  
fill ~113 ~0 ~127 ~118 ~0 ~127 iron_block  
fill ~113 ~0 ~128 ~118 ~0 ~128 iron_block  
fill ~113 ~0 ~129 ~118 ~0 ~129 iron_block  
fill ~113 ~0 ~130 ~118 ~0 ~130 iron_block  
fill ~113 ~0 ~131 ~118 ~0 ~131 iron_block  
fill ~113 ~0 ~132 ~118 ~0 ~132 iron_block  
fill ~114 ~0 ~38 ~114 ~0 ~39 stone  
fill ~114 ~0 ~93 ~114 ~0 ~94 stone 
setblock ~115 ~0 ~40 stone 0 
setblock ~115 ~0 ~92 stone 0  
fill ~116 ~0 ~41 ~116 ~0 ~42 stone  
fill ~116 ~0 ~90 ~116 ~0 ~91 stone  
fill ~117 ~0 ~43 ~117 ~0 ~44 stone  
fill ~117 ~0 ~88 ~117 ~0 ~89 stone  
fill ~118 ~0 ~26 ~118 ~3 ~26 iron_block  
fill ~118 ~0 ~27 ~118 ~2 ~27 iron_block  
fill ~118 ~0 ~28 ~118 ~1 ~28 iron_block  
fill ~118 ~0 ~29 ~118 ~0 ~0 iron_block 
setblock ~118 ~0 ~30 wool 11  
fill ~118 ~0 ~45 ~118 ~0 ~46 stone  
fill ~118 ~0 ~86 ~118 ~0 ~87 stone 
setblock ~118 ~0 ~102 wool 11  
fill ~118 ~0 ~103 ~118 ~0 ~132 iron_block  
fill ~119 ~0 ~0 ~119 ~0 ~1 wool  
fill ~119 ~0 ~2 ~119 ~0 ~28 stone_slab 
setblock ~119 ~0 ~29 wool 11 
setblock ~119 ~0 ~30 stone_slab 0  
fill ~119 ~0 ~47 ~119 ~0 ~48 stone  
fill ~119 ~0 ~84 ~119 ~0 ~85 stone 
setblock ~119 ~0 ~102 stone_slab 0 
setblock ~119 ~0 ~103 wool 11  
fill ~119 ~0 ~104 ~119 ~0 ~130 stone_slab  
fill ~119 ~0 ~131 ~119 ~0 ~132 wool  
fill ~120 ~0 ~49 ~120 ~0 ~50 stone  
fill ~120 ~0 ~82 ~120 ~0 ~83 stone  
fill ~121 ~0 ~51 ~121 ~0 ~51 stone  
fill ~121 ~0 ~52 ~121 ~0 ~52 stone  
fill ~121 ~0 ~53 ~121 ~0 ~53 stone  
fill ~121 ~0 ~54 ~121 ~0 ~54 stone  
fill ~121 ~0 ~78 ~121 ~0 ~78 stone  
fill ~121 ~0 ~79 ~121 ~0 ~79 stone  
fill ~121 ~0 ~80 ~121 ~0 ~80 stone    
fill ~121 ~0 ~81 ~121 ~0 ~81 stone  
fill ~122 ~0 ~55 ~122 ~0 ~63 stone  
fill ~122 ~0 ~69 ~122 ~0 ~77 stone  
fill ~123 ~0 ~22 ~123 ~17 ~22 stone 
setblock ~123 ~0 ~23 glowstone 0  
fill ~123 ~0 ~24 ~123 ~17 ~24 stone 
setblock ~123 ~0 ~25 glowstone 0  
fill ~123 ~0 ~26 ~123 ~17 ~26 stone 
setblock ~123 ~0 ~27 glowstone 0  
fill ~123 ~0 ~28 ~123 ~17 ~28 stone 
setblock ~123 ~0 ~29 glowstone 0  
fill ~123 ~0 ~30 ~123 ~17 ~30 stone 
setblock ~123 ~0 ~31 glowstone 0  
fill ~123 ~0 ~32 ~123 ~17 ~32 stone 
setblock ~123 ~0 ~33 glowstone 0  
fill ~123 ~0 ~34 ~123 ~17 ~34 stone 
setblock ~123 ~0 ~35 glowstone 0  
fill ~123 ~0 ~36 ~123 ~17 ~36 stone 
setblock ~123 ~0 ~37 glowstone 0  
fill ~123 ~0 ~38 ~123 ~17 ~38 stone 
setblock ~123 ~0 ~39 glowstone 0  
fill ~123 ~0 ~40 ~123 ~17 ~40 stone 
setblock ~123 ~0 ~41 glowstone 0  
fill ~123 ~0 ~42 ~123 ~17 ~42 stone 
setblock ~123 ~0 ~43 glowstone 0  
fill ~123 ~0 ~44 ~123 ~17 ~44 stone 
setblock ~123 ~0 ~45 glowstone 0  
fill ~123 ~0 ~46 ~123 ~17 ~46 stone 
setblock ~123 ~0 ~47 glowstone 0  
fill ~123 ~0 ~48 ~123 ~17 ~48 stone 
setblock ~123 ~0 ~49 glowstone 0  
fill ~123 ~0 ~50 ~123 ~17 ~50 stone 
setblock ~123 ~0 ~51 glowstone 0  
fill ~123 ~0 ~52 ~123 ~17 ~52 stone 
setblock ~123 ~0 ~53 glowstone 0  
fill ~123 ~0 ~54 ~123 ~17 ~54 stone 
setblock ~123 ~0 ~55 glowstone 0  
fill ~123 ~0 ~56 ~123 ~17 ~56 stone 
setblock ~123 ~0 ~57 glowstone 0  
fill ~123 ~0 ~58 ~123 ~28 ~58 stone 
setblock ~123 ~0 ~59 glowstone 0  
fill ~123 ~0 ~60 ~123 ~28 ~60 stone 
setblock ~123 ~0 ~61 glowstone 0  
fill ~123 ~0 ~62 ~123 ~28 ~62 stone 
setblock ~123 ~0 ~63 glowstone 0 
setblock ~123 ~0 ~69 glowstone 0  
fill ~123 ~0 ~70 ~123 ~28 ~70 stone 
setblock ~123 ~0 ~71 glowstone 0  
fill ~123 ~0 ~72 ~123 ~28 ~72 stone 
setblock ~123 ~0 ~73 glowstone 0  
fill ~123 ~0 ~74 ~123 ~28 ~74 stone 
setblock ~123 ~0 ~75 glowstone 0  
fill ~123 ~0 ~76 ~123 ~17 ~76 stone 
setblock ~123 ~0 ~77 glowstone 0  
fill ~123 ~0 ~78 ~123 ~17 ~78 stone 
setblock ~123 ~0 ~79 glowstone 0  
fill ~123 ~0 ~80 ~123 ~17 ~80 stone 
setblock ~123 ~0 ~81 glowstone 0  
fill ~123 ~0 ~82 ~123 ~17 ~82 stone 
setblock ~123 ~0 ~83 glowstone 0  
fill ~123 ~0 ~84 ~123 ~17 ~84 stone 
setblock ~123 ~0 ~85 glowstone 0  
fill ~123 ~0 ~86 ~123 ~17 ~86 stone 
setblock ~123 ~0 ~87 glowstone 0  
fill ~123 ~0 ~88 ~123 ~17 ~88 stone 
setblock ~123 ~0 ~89 glowstone 0  
fill ~123 ~0 ~90 ~123 ~17 ~90 stone 
setblock ~123 ~0 ~91 glowstone 0  
fill ~123 ~0 ~92 ~123 ~17 ~92 stone 
setblock ~123 ~0 ~93 glowstone 0  
fill ~123 ~0 ~94 ~123 ~17 ~94 stone 
setblock ~123 ~0 ~95 glowstone 0  
fill ~123 ~0 ~96 ~123 ~17 ~96 stone 
setblock ~123 ~0 ~97 glowstone 0  
fill ~123 ~0 ~98 ~123 ~17 ~98 stone 
setblock ~123 ~0 ~99 glowstone 0  
fill ~123 ~0 ~100 ~123 ~17 ~100 stone 
setblock ~123 ~0 ~101 glowstone 0  
fill ~123 ~0 ~102 ~123 ~17 ~102 stone 
setblock ~123 ~0 ~103 glowstone 0  
fill ~123 ~0 ~104 ~123 ~17 ~104 stone 
setblock ~123 ~0 ~105 glowstone 0  
fill ~123 ~0 ~106 ~123 ~17 ~106 stone 
setblock ~123 ~0 ~107 glowstone 0  
fill ~123 ~0 ~108 ~123 ~17 ~108 stone 
setblock ~123 ~0 ~109 glowstone 0  
fill ~123 ~0 ~110 ~123 ~17 ~110 stone  
fill ~124 ~0 ~19 ~124 ~17 ~19 stone  
fill ~124 ~0 ~20 ~124 ~17 ~20 stone  
fill ~124 ~0 ~21 ~124 ~17 ~21 stone  
fill ~124 ~0 ~111 ~124 ~17 ~111 stone  
fill ~124 ~0 ~112 ~124 ~17 ~112 stone  
fill ~124 ~0 ~113 ~124 ~17 ~113 stone  
fill ~125 ~0 ~17 ~125 ~17 ~17 stone  
fill ~125 ~0 ~18 ~125 ~17 ~18 stone  
fill ~125 ~0 ~114 ~125 ~17 ~114 stone  
fill ~125 ~0 ~115 ~125 ~17 ~115 stone  
fill ~126 ~0 ~16 ~126 ~17 ~16 stone  
fill ~126 ~0 ~116 ~126 ~17 ~116 stone  
fill ~127 ~0 ~15 ~127 ~17 ~15 stone  
fill ~127 ~0 ~117 ~127 ~17 ~117 stone  
fill ~128 ~0 ~14 ~128 ~17 ~14 stone  
fill ~128 ~0 ~118 ~128 ~17 ~118 stone  
fill ~129 ~0 ~13 ~129 ~17 ~13 stone  
fill ~129 ~0 ~119 ~129 ~17 ~119 stone  
fill ~130 ~0 ~12 ~130 ~17 ~12 stone  
fill ~130 ~0 ~120 ~130 ~17 ~120 stone  
fill ~131 ~0 ~12 ~131 ~12 ~12 double_stone_slab  
fill ~131 ~0 ~120 ~131 ~12 ~120 double_stone_slab  
fill ~145 ~0 ~12 ~145 ~12 ~12 double_stone_slab  
fill ~145 ~0 ~120 ~145 ~12 ~120 double_stone_slab  
fill ~146 ~0 ~12 ~146 ~17 ~12 stone  
fill ~146 ~0 ~120 ~146 ~17 ~120 stone  
fill ~147 ~0 ~13 ~147 ~17 ~13 stone  
fill ~147 ~0 ~119 ~147 ~17 ~119 stone  
fill ~148 ~0 ~14 ~148 ~17 ~14 stone  
fill ~148 ~0 ~118 ~148 ~17 ~118 stone  
fill ~149 ~0 ~15 ~149 ~17 ~15 stone  
fill ~149 ~0 ~117 ~149 ~17 ~117 stone  
fill ~150 ~0 ~16 ~150 ~17 ~16 stone  
fill ~150 ~0 ~116 ~150 ~17 ~116 stone  
fill ~151 ~0 ~17 ~151 ~17 ~17 stone  
fill ~151 ~0 ~18 ~151 ~17 ~18 stone  
fill ~151 ~0 ~114 ~151 ~17 ~114 stone  
fill ~151 ~0 ~115 ~151 ~17 ~115 stone  
fill ~152 ~0 ~19 ~152 ~17 ~19 stone  
fill ~152 ~0 ~20 ~152 ~17 ~20 stone  
fill ~152 ~0 ~21 ~152 ~17 ~21 stone  
fill ~152 ~0 ~111 ~152 ~17 ~111 stone  
fill ~152 ~0 ~112 ~152 ~17 ~112 stone  
fill ~152 ~0 ~113 ~152 ~17 ~113 stone  
fill ~153 ~0 ~22 ~153 ~17 ~22 stone 
setblock ~153 ~0 ~23 glowstone 0  
fill ~153 ~0 ~24 ~153 ~2 ~24 stone 
setblock ~153 ~0 ~25 glowstone 0  
fill ~153 ~0 ~26 ~153 ~2 ~26 stone 
setblock ~153 ~0 ~27 glowstone 0  
fill ~153 ~0 ~28 ~153 ~2 ~28 stone 
setblock ~153 ~0 ~29 glowstone 0  
fill ~153 ~0 ~30 ~153 ~2 ~30 stone 
setblock ~153 ~0 ~31 glowstone 0  
fill ~153 ~0 ~32 ~153 ~17 ~32 stone 
setblock ~153 ~0 ~33 glowstone 0  
fill ~153 ~0 ~34 ~153 ~17 ~34 stone 
setblock ~153 ~0 ~35 glowstone 0  
fill ~153 ~0 ~36 ~153 ~2 ~36 stone 
setblock ~153 ~0 ~37 glowstone 0  
fill ~153 ~0 ~38 ~153 ~2 ~38 stone 
setblock ~153 ~0 ~39 glowstone 0  
fill ~153 ~0 ~40 ~153 ~2 ~40 stone 
setblock ~153 ~0 ~41 glowstone 0  
fill ~153 ~0 ~42 ~153 ~17 ~42 stone 
setblock ~153 ~0 ~43 glowstone 0  
fill ~153 ~0 ~44 ~153 ~17 ~44 stone 
setblock ~153 ~0 ~45 glowstone 0  
fill ~153 ~0 ~46 ~153 ~2 ~46 stone 
setblock ~153 ~0 ~47 glowstone 0  
fill ~153 ~0 ~48 ~153 ~2 ~48 stone 
setblock ~153 ~0 ~49 glowstone 0  
fill ~153 ~0 ~50 ~153 ~2 ~50 stone 
setblock ~153 ~0 ~51 glowstone 0  
fill ~153 ~0 ~52 ~153 ~2 ~52 stone 
setblock ~153 ~0 ~53 glowstone 0  
fill ~153 ~0 ~54 ~153 ~17 ~54 stone 
setblock ~153 ~0 ~55 glowstone 0  
fill ~153 ~0 ~56 ~153 ~17 ~56 stone 
setblock ~153 ~0 ~57 glowstone 0  
fill ~153 ~0 ~58 ~153 ~2 ~58 stone 
setblock ~153 ~0 ~59 glowstone 0  
fill ~153 ~0 ~60 ~153 ~2 ~60 stone 
setblock ~153 ~0 ~61 glowstone 0  
fill ~153 ~0 ~62 ~153 ~2 ~62 stone 
setblock ~153 ~0 ~63 glowstone 0  
fill ~153 ~0 ~64 ~153 ~17 ~64 stone 
setblock ~153 ~0 ~65 glowstone 0  
fill ~153 ~0 ~66 ~153 ~17 ~66 stone 
setblock ~153 ~0 ~67 glowstone 0  
fill ~153 ~0 ~68 ~153 ~17 ~68 stone 
setblock ~153 ~0 ~69 glowstone 0  
fill ~153 ~0 ~70 ~153 ~2 ~70 stone 
setblock ~153 ~0 ~71 glowstone 0  
fill ~153 ~0 ~72 ~153 ~2 ~72 stone 
setblock ~153 ~0 ~73 glowstone 0  
fill ~153 ~0 ~74 ~153 ~2 ~74 stone 
setblock ~153 ~0 ~75 glowstone 0  
fill ~153 ~0 ~76 ~153 ~17 ~76 stone 
setblock ~153 ~0 ~77 glowstone 0  
fill ~153 ~0 ~78 ~153 ~17 ~78 stone 
setblock ~153 ~0 ~79 glowstone 0  
fill ~153 ~0 ~80 ~153 ~2 ~80 stone 
setblock ~153 ~0 ~81 glowstone 0  
fill ~153 ~0 ~82 ~153 ~2 ~82 stone 
setblock ~153 ~0 ~83 glowstone 0  
fill ~153 ~0 ~84 ~153 ~2 ~84 stone 
setblock ~153 ~0 ~85 glowstone 0  
fill ~153 ~0 ~86 ~153 ~2 ~86 stone 
setblock ~153 ~0 ~87 glowstone 0  
fill ~153 ~0 ~88 ~153 ~17 ~88 stone 
setblock ~153 ~0 ~89 glowstone 0  
fill ~153 ~0 ~90 ~153 ~17 ~90 stone 
setblock ~153 ~0 ~91 glowstone 0  
fill ~153 ~0 ~92 ~153 ~2 ~92 stone 
setblock ~153 ~0 ~93 glowstone 0  
fill ~153 ~0 ~94 ~153 ~2 ~94 stone 
setblock ~153 ~0 ~95 glowstone 0  
fill ~153 ~0 ~96 ~153 ~2 ~96 stone 
setblock ~153 ~0 ~97 glowstone 0  
fill ~153 ~0 ~98 ~153 ~17 ~98 stone 
setblock ~153 ~0 ~99 glowstone 0  
fill ~153 ~0 ~100 ~153 ~17 ~100 stone 
setblock ~153 ~0 ~101 glowstone 0  
fill ~153 ~0 ~102 ~153 ~2 ~102 stone 
setblock ~153 ~0 ~103 glowstone 0  
fill ~153 ~0 ~104 ~153 ~2 ~104 stone 
setblock ~153 ~0 ~105 glowstone 0  
fill ~153 ~0 ~106 ~153 ~2 ~106 stone 
setblock ~153 ~0 ~107 glowstone 0  
fill ~153 ~0 ~108 ~153 ~2 ~108 stone 
setblock ~153 ~0 ~109 glowstone 0  
fill ~153 ~0 ~110 ~153 ~17 ~110 stone  
fill ~1 ~1 ~23 ~1 ~17 ~23 stone  
fill ~1 ~1 ~25 ~1 ~2 ~25 stone  
fill ~1 ~1 ~27 ~1 ~2 ~27 stone  
fill ~1 ~1 ~29 ~1 ~2 ~29 stone  
fill ~1 ~1 ~31 ~1 ~17 ~31 stone  
fill ~1 ~1 ~33 ~1 ~17 ~33 stone  
fill ~1 ~1 ~35 ~1 ~2 ~35 stone  
fill ~1 ~1 ~37 ~1 ~2 ~37 stone  
fill ~1 ~1 ~39 ~1 ~2 ~39 stone  
fill ~1 ~1 ~41 ~1 ~2 ~41 stone  
fill ~1 ~1 ~43 ~1 ~17 ~43 stone  
fill ~1 ~1 ~45 ~1 ~17 ~45 stone  
fill ~1 ~1 ~47 ~1 ~2 ~47 stone  
fill ~1 ~1 ~49 ~1 ~2 ~49 stone  
fill ~1 ~1 ~51 ~1 ~2 ~51 stone  
fill ~1 ~1 ~53 ~1 ~17 ~53 stone  
fill ~1 ~1 ~55 ~1 ~17 ~55 stone  
fill ~1 ~1 ~57 ~1 ~2 ~57 stone  
fill ~1 ~1 ~59 ~1 ~2 ~59 stone  
fill ~1 ~1 ~61 ~1 ~2 ~61 stone  
fill ~1 ~1 ~63 ~1 ~2 ~63 stone  
fill ~1 ~1 ~65 ~1 ~17 ~65 stone  
fill ~1 ~1 ~67 ~1 ~17 ~67 stone  
fill ~1 ~1 ~69 ~1 ~2 ~69 stone  
fill ~1 ~1 ~71 ~1 ~2 ~71 stone  
fill ~1 ~1 ~73 ~1 ~2 ~73 stone  
fill ~1 ~1 ~75 ~1 ~2 ~75 stone  
fill ~1 ~1 ~77 ~1 ~17 ~77 stone  
fill ~1 ~1 ~79 ~1 ~17 ~79 stone  
fill ~1 ~1 ~81 ~1 ~2 ~81 stone  
fill ~1 ~1 ~83 ~1 ~2 ~83 stone  
fill ~1 ~1 ~85 ~1 ~2 ~85 stone  
fill ~1 ~1 ~87 ~1 ~17 ~87 stone  
fill ~1 ~1 ~89 ~1 ~17 ~89 stone  
fill ~1 ~1 ~91 ~1 ~2 ~91 stone  
fill ~1 ~1 ~93 ~1 ~2 ~93 stone  
fill ~1 ~1 ~95 ~1 ~2 ~95 stone  
fill ~1 ~1 ~97 ~1 ~2 ~97 stone  
fill ~1 ~1 ~99 ~1 ~17 ~99 stone  
fill ~1 ~1 ~101 ~1 ~17 ~101 stone  
fill ~1 ~1 ~103 ~1 ~2 ~103 stone  
fill ~1 ~1 ~105 ~1 ~2 ~105 stone  
fill ~1 ~1 ~107 ~1 ~2 ~107 stone  
fill ~1 ~1 ~109 ~1 ~17 ~109 stone  
fill ~31 ~1 ~23 ~31 ~17 ~23 stone  
fill ~31 ~1 ~25 ~31 ~17 ~25 stone  
fill ~31 ~1 ~27 ~31 ~17 ~27 stone  
fill ~31 ~1 ~29 ~31 ~17 ~29 stone  
fill ~31 ~1 ~31 ~31 ~17 ~31 stone  
fill ~31 ~1 ~33 ~31 ~17 ~33 stone  
fill ~31 ~1 ~35 ~31 ~17 ~35 stone  
fill ~31 ~1 ~37 ~31 ~17 ~37 stone  
fill ~31 ~1 ~39 ~31 ~17 ~39 stone  
fill ~31 ~1 ~41 ~31 ~17 ~41 stone  
fill ~31 ~1 ~43 ~31 ~17 ~43 stone  
fill ~31 ~1 ~45 ~31 ~17 ~45 stone  
fill ~31 ~1 ~47 ~31 ~17 ~47 stone  
fill ~31 ~1 ~49 ~31 ~17 ~49 stone  
fill ~31 ~1 ~51 ~31 ~17 ~51 stone  
fill ~31 ~1 ~53 ~31 ~17 ~53 stone  
fill ~31 ~1 ~55 ~31 ~17 ~55 stone  
fill ~31 ~1 ~56 ~31 ~17 ~56 stone  
fill ~31 ~1 ~57 ~31 ~33 ~57 stone  
fill ~31 ~1 ~58 ~31 ~28 ~58 stone  
fill ~31 ~1 ~59 ~31 ~28 ~59 stone  
fill ~31 ~1 ~60 ~31 ~28 ~60 stone  
fill ~31 ~1 ~61 ~31 ~28 ~61 stone  
fill ~31 ~1 ~62 ~31 ~28 ~62 stone  
fill ~31 ~1 ~63 ~31 ~28 ~63 stone  
fill ~31 ~1 ~69 ~31 ~28 ~69 stone  
fill ~31 ~1 ~70 ~31 ~28 ~70 stone  
fill ~31 ~1 ~71 ~31 ~28 ~71 stone  
fill ~31 ~1 ~72 ~31 ~28 ~72 stone  
fill ~31 ~1 ~73 ~31 ~28 ~73 stone  
fill ~31 ~1 ~74 ~31 ~28 ~74 stone  
fill ~31 ~1 ~75 ~31 ~33 ~75 stone  
fill ~31 ~1 ~76 ~31 ~17 ~76 stone  
fill ~31 ~1 ~77 ~31 ~17 ~77 stone  
fill ~31 ~1 ~79 ~31 ~17 ~79 stone  
fill ~31 ~1 ~81 ~31 ~17 ~81 stone  
fill ~31 ~1 ~83 ~31 ~17 ~83 stone  
fill ~31 ~1 ~85 ~31 ~17 ~85 stone  
fill ~31 ~1 ~87 ~31 ~17 ~87 stone  
fill ~31 ~1 ~89 ~31 ~17 ~89 stone  
fill ~31 ~1 ~91 ~31 ~17 ~91 stone  
fill ~31 ~1 ~93 ~31 ~17 ~93 stone  
fill ~31 ~1 ~95 ~31 ~17 ~95 stone  
fill ~31 ~1 ~97 ~31 ~17 ~97 stone  
fill ~31 ~1 ~99 ~31 ~17 ~99 stone  
fill ~31 ~1 ~101 ~31 ~17 ~101 stone  
fill ~31 ~1 ~103 ~31 ~17 ~103 stone  
fill ~31 ~1 ~105 ~31 ~17 ~105 stone  
fill ~31 ~1 ~107 ~31 ~17 ~107 stone  
fill ~31 ~1 ~109 ~31 ~17 ~109 stone  
fill ~32 ~1 ~55 ~32 ~6 ~55 glass  
fill ~32 ~1 ~56 ~32 ~6 ~56 glass  
fill ~32 ~1 ~57 ~32 ~6 ~57 glass  
fill ~32 ~1 ~58 ~32 ~6 ~58 glass  
fill ~32 ~1 ~59 ~32 ~6 ~59 glass  
fill ~32 ~1 ~60 ~32 ~6 ~60 glass  
fill ~32 ~1 ~61 ~32 ~6 ~61 glass  
fill ~32 ~1 ~62 ~32 ~6 ~62 glass  
fill ~32 ~1 ~63 ~32 ~6 ~63 glass  
fill ~32 ~1 ~69 ~32 ~6 ~69 glass  
fill ~32 ~1 ~70 ~32 ~6 ~70 glass  
fill ~32 ~1 ~71 ~32 ~6 ~71 glass  
fill ~32 ~1 ~72 ~32 ~6 ~72 glass  
fill ~32 ~1 ~73 ~32 ~6 ~73 glass  
fill ~32 ~1 ~74 ~32 ~6 ~74 glass  
fill ~32 ~1 ~75 ~32 ~6 ~75 glass  
fill ~32 ~1 ~76 ~32 ~6 ~76 glass  
fill ~32 ~1 ~77 ~32 ~6 ~77 glass  
fill ~33 ~1 ~51 ~33 ~6 ~51 glass  
fill ~33 ~1 ~52 ~33 ~6 ~52 glass  
fill ~33 ~1 ~53 ~33 ~6 ~53 glass  
fill ~33 ~1 ~54 ~33 ~6 ~54 glass  
fill ~33 ~1 ~78 ~33 ~6 ~78 glass  
fill ~33 ~1 ~79 ~33 ~6 ~79 glass  
fill ~33 ~1 ~80 ~33 ~6 ~80 glass  
fill ~33 ~1 ~81 ~33 ~6 ~81 glass  
fill ~34 ~1 ~49 ~34 ~6 ~49 glass  
fill ~34 ~1 ~50 ~34 ~6 ~50 glass  
fill ~34 ~1 ~82 ~34 ~6 ~82 glass  
fill ~34 ~1 ~83 ~34 ~6 ~83 glass  
fill ~35 ~1 ~2 ~35 ~1 ~3 wool 
setblock ~35 ~1 ~28 wool 11  
fill ~35 ~1 ~47 ~35 ~6 ~47 glass  
fill ~35 ~1 ~48 ~35 ~6 ~48 glass  
fill ~35 ~1 ~84 ~35 ~6 ~84 glass  
fill ~35 ~1 ~85 ~35 ~6 ~85 glass 
setblock ~35 ~1 ~104 wool 11  
fill ~35 ~1 ~129 ~35 ~1 ~130 wool  
fill ~36 ~1 ~2 ~42 ~1 ~2 iron_block  
fill ~36 ~1 ~3 ~42 ~1 ~3 iron_block  
fill ~36 ~1 ~4 ~42 ~1 ~4 iron_block  
fill ~36 ~1 ~5 ~42 ~1 ~5 iron_block  
fill ~36 ~1 ~6 ~42 ~1 ~6 iron_block  
fill ~36 ~1 ~7 ~42 ~1 ~7 iron_block  
fill ~36 ~1 ~8 ~42 ~1 ~8 iron_block  
fill ~36 ~1 ~9 ~42 ~1 ~9 iron_block  
fill ~36 ~1 ~10 ~42 ~1 ~10 iron_block  
fill ~36 ~1 ~11 ~42 ~1 ~11 iron_block  
fill ~36 ~1 ~12 ~42 ~1 ~12 iron_block  
fill ~36 ~1 ~13 ~42 ~1 ~13 iron_block  
fill ~36 ~1 ~14 ~42 ~1 ~14 iron_block  
fill ~36 ~1 ~15 ~42 ~1 ~15 iron_block  
fill ~36 ~1 ~16 ~42 ~1 ~16 iron_block  
fill ~36 ~1 ~17 ~42 ~1 ~17 iron_block  
fill ~36 ~1 ~18 ~42 ~1 ~18 iron_block  
fill ~36 ~1 ~19 ~42 ~1 ~19 iron_block  
fill ~36 ~1 ~20 ~42 ~1 ~20 iron_block  
fill ~36 ~1 ~21 ~42 ~1 ~21 iron_block  
fill ~36 ~1 ~22 ~42 ~1 ~22 iron_block  
fill ~36 ~1 ~23 ~42 ~1 ~23 iron_block  
fill ~36 ~1 ~24 ~42 ~1 ~24 iron_block  
fill ~36 ~1 ~25 ~42 ~1 ~25 iron_block 
setblock ~36 ~1 ~29 wool 11  
fill ~36 ~1 ~45 ~36 ~6 ~45 glass  
fill ~36 ~1 ~46 ~36 ~6 ~46 glass  
fill ~36 ~1 ~86 ~36 ~6 ~86 glass  
fill ~36 ~1 ~87 ~36 ~6 ~87 glass 
setblock ~36 ~1 ~103 wool 11  
fill ~36 ~1 ~104 ~36 ~1 ~130 iron_block  
fill ~37 ~1 ~43 ~37 ~6 ~43 glass  
fill ~37 ~1 ~44 ~37 ~6 ~44 glass  
fill ~37 ~1 ~88 ~37 ~6 ~88 glass  
fill ~37 ~1 ~89 ~37 ~6 ~89 glass  
fill ~37 ~1 ~107 ~42 ~1 ~107 iron_block  
fill ~37 ~1 ~108 ~42 ~1 ~108 iron_block  
fill ~37 ~1 ~109 ~42 ~1 ~109 iron_block  
fill ~37 ~1 ~110 ~42 ~1 ~110 iron_block  
fill ~37 ~1 ~111 ~42 ~1 ~111 iron_block  
fill ~37 ~1 ~112 ~42 ~1 ~112 iron_block  
fill ~37 ~1 ~113 ~42 ~1 ~113 iron_block  
fill ~37 ~1 ~114 ~42 ~1 ~114 iron_block  
fill ~37 ~1 ~115 ~42 ~1 ~115 iron_block  
fill ~37 ~1 ~116 ~42 ~1 ~116 iron_block  
fill ~37 ~1 ~117 ~42 ~1 ~117 iron_block  
fill ~37 ~1 ~118 ~42 ~1 ~118 iron_block  
fill ~37 ~1 ~119 ~42 ~1 ~119 iron_block  
fill ~37 ~1 ~120 ~42 ~1 ~120 iron_block  
fill ~37 ~1 ~121 ~42 ~1 ~121 iron_block  
fill ~37 ~1 ~122 ~42 ~1 ~122 iron_block  
fill ~37 ~1 ~123 ~42 ~1 ~123 iron_block  
fill ~37 ~1 ~124 ~42 ~1 ~124 iron_block  
fill ~37 ~1 ~125 ~42 ~1 ~125 iron_block  
fill ~37 ~1 ~126 ~42 ~1 ~126 iron_block  
fill ~37 ~1 ~127 ~42 ~1 ~127 iron_block  
fill ~37 ~1 ~128 ~42 ~1 ~128 iron_block  
fill ~37 ~1 ~129 ~42 ~1 ~129 iron_block  
fill ~37 ~1 ~130 ~42 ~1 ~130 iron_block  
fill ~38 ~1 ~41 ~38 ~6 ~41 glass  
fill ~38 ~1 ~42 ~38 ~6 ~42 glass  
fill ~38 ~1 ~90 ~38 ~6 ~90 glass  
fill ~38 ~1 ~91 ~38 ~6 ~91 glass  
fill ~39 ~1 ~40 ~39 ~6 ~40 glass  
fill ~39 ~1 ~92 ~39 ~6 ~92 glass  
fill ~40 ~1 ~38 ~40 ~6 ~38 glass  
fill ~40 ~1 ~39 ~40 ~6 ~39 glass  
fill ~40 ~1 ~93 ~40 ~6 ~93 glass  
fill ~40 ~1 ~94 ~40 ~6 ~94 glass  
fill ~41 ~1 ~37 ~41 ~6 ~37 glass  
fill ~41 ~1 ~95 ~41 ~6 ~95 glass 
setblock ~42 ~1 ~29 wool 11  
fill ~42 ~1 ~36 ~42 ~6 ~36 glass  
fill ~42 ~1 ~96 ~42 ~6 ~96 glass 
setblock ~42 ~1 ~103 wool 11  
fill ~42 ~1 ~104 ~42 ~1 ~130 iron_block  
fill ~43 ~1 ~2 ~43 ~1 ~3 wool 
setblock ~43 ~1 ~28 wool 11  
fill ~43 ~1 ~35 ~43 ~6 ~35 glass  
fill ~43 ~1 ~97 ~43 ~6 ~97 glass 
setblock ~43 ~1 ~104 wool 11  
fill ~43 ~1 ~129 ~43 ~1 ~130 wool  
fill ~46 ~1 ~32 ~46 ~6 ~32 glass  
fill ~46 ~1 ~100 ~46 ~6 ~100 glass  
fill ~47 ~1 ~31 ~47 ~6 ~31 glass  
fill ~47 ~1 ~101 ~47 ~6 ~101 glass  
fill ~48 ~1 ~30 ~48 ~6 ~30 glass  
fill ~48 ~1 ~102 ~48 ~6 ~102 glass  
fill ~49 ~1 ~29 ~50 ~1 ~29 glass  
fill ~49 ~1 ~103 ~50 ~1 ~103 glass  
fill ~51 ~1 ~28 ~51 ~6 ~28 glass  
fill ~51 ~1 ~104 ~51 ~6 ~104 glass  
fill ~52 ~1 ~0 ~53 ~1 ~0 stone  
fill ~52 ~1 ~18 ~53 ~1 ~18 stone  
fill ~52 ~1 ~27 ~53 ~1 ~27 glass  
fill ~52 ~1 ~105 ~53 ~1 ~105 glass  
fill ~54 ~1 ~19 ~77 ~1 ~19 stone  
fill ~54 ~1 ~26 ~55 ~1 ~26 glass  
fill ~54 ~1 ~106 ~55 ~1 ~106 glass  
fill ~56 ~1 ~25 ~57 ~1 ~25 glass  
fill ~56 ~1 ~107 ~57 ~1 ~107 glass  
fill ~58 ~1 ~24 ~59 ~1 ~24 glass  
fill ~58 ~1 ~108 ~59 ~1 ~108 glass  
fill ~60 ~1 ~23 ~61 ~1 ~23 glass  
fill ~60 ~1 ~109 ~61 ~1 ~109 glass  
fill ~62 ~1 ~22 ~65 ~1 ~22 glass  
fill ~62 ~1 ~110 ~65 ~1 ~110 glass  
fill ~66 ~1 ~21 ~75 ~1 ~21 glass  
fill ~66 ~1 ~111 ~70 ~1 ~111 glass  
fill ~69 ~1 ~63 ~69 ~2 ~63 stone  
fill ~69 ~1 ~64 ~69 ~1 ~63 stone  
fill ~70 ~1 ~62 ~70 ~2 ~62 stone  
fill ~70 ~1 ~63 ~73 ~1 ~63 double_stone_slab  
fill ~70 ~1 ~64 ~73 ~1 ~64 stone_slab  
fill ~71 ~1 ~61 ~71 ~2 ~61 stone  
fill ~71 ~1 ~62 ~73 ~1 ~62 double_stone_slab  
fill ~71 ~1 ~111 ~75 ~1 ~111 stone  
fill ~71 ~1 ~112 ~71 ~2 ~112 stone  
fill ~71 ~1 ~118 ~75 ~1 ~118 stone  
fill ~72 ~1 ~60 ~72 ~2 ~60 stone  
fill ~72 ~1 ~61 ~73 ~1 ~61 double_stone_slab  
fill ~72 ~1 ~110 ~74 ~1 ~110 stone_slab 
setblock ~72 ~1 ~112 redstone_wire 11  
fill ~73 ~1 ~59 ~73 ~2 ~59 stone 
setblock ~73 ~1 ~60 double_stone_slab 0 
setblock ~73 ~1 ~112 powered_repeater 1 
setblock ~74 ~1 ~64 glowstone 0  
fill ~74 ~1 ~112 ~75 ~1 ~112 wool 
setblock ~74 ~1 ~115 unlit_redstone_torch 5  
fill ~74 ~1 ~119 ~75 ~1 ~119 stone 
setblock ~75 ~1 ~20 redstone_wire 11  
fill ~75 ~1 ~115 ~75 ~2 ~115 stone  
fill ~76 ~1 ~20 ~77 ~1 ~20 wool  
fill ~76 ~1 ~21 ~77 ~1 ~21 stone  
fill ~76 ~1 ~112 ~78 ~1 ~112 double_stone_slab  
fill ~76 ~1 ~113 ~76 ~1 ~118 redstone_torch  
fill ~78 ~1 ~20 ~79 ~1 ~20 double_stone_slab  
fill ~78 ~1 ~113 ~78 ~1 ~118 redstone_torch  
fill ~79 ~1 ~111 ~83 ~1 ~111 stone  
fill ~79 ~1 ~112 ~80 ~1 ~112 wool  
fill ~79 ~1 ~118 ~83 ~1 ~118 stone  
fill ~79 ~1 ~119 ~80 ~1 ~119 stone  
fill ~80 ~1 ~19 ~100 ~1 ~19 stone  
fill ~80 ~1 ~20 ~81 ~1 ~20 wool  
fill ~80 ~1 ~21 ~81 ~1 ~21 stone  
fill ~80 ~1 ~110 ~82 ~1 ~110 stone_slab 
setblock ~81 ~1 ~112 powered_repeater 3 
setblock ~82 ~1 ~20 redstone_wire 12  
fill ~82 ~1 ~21 ~88 ~1 ~21 glass 
setblock ~82 ~1 ~112 redstone_wire 11  
fill ~83 ~1 ~112 ~83 ~2 ~112 stone  
fill ~84 ~1 ~111 ~88 ~1 ~111 glass  
fill ~89 ~1 ~22 ~92 ~1 ~22 glass  
fill ~89 ~1 ~110 ~92 ~1 ~110 glass  
fill ~93 ~1 ~23 ~94 ~1 ~23 glass  
fill ~93 ~1 ~109 ~94 ~1 ~109 glass  
fill ~95 ~1 ~24 ~96 ~1 ~24 glass  
fill ~95 ~1 ~108 ~96 ~1 ~108 glass  
fill ~97 ~1 ~25 ~98 ~1 ~25 glass  
fill ~97 ~1 ~107 ~98 ~1 ~107 glass  
fill ~99 ~1 ~26 ~100 ~1 ~26 glass  
fill ~99 ~1 ~106 ~100 ~1 ~106 glass  
fill ~101 ~1 ~0 ~101 ~6 ~0 stone  
fill ~101 ~1 ~18 ~101 ~6 ~18 stone  
fill ~101 ~1 ~27 ~102 ~1 ~27 glass  
fill ~101 ~1 ~105 ~102 ~1 ~105 glass  
fill ~103 ~1 ~1 ~103 ~6 ~1 stone  
fill ~103 ~1 ~17 ~103 ~6 ~17 stone  
fill ~103 ~1 ~28 ~103 ~6 ~28 glass  
fill ~103 ~1 ~104 ~103 ~6 ~104 glass  
fill ~104 ~1 ~2 ~104 ~6 ~2 stone  
fill ~104 ~1 ~16 ~104 ~6 ~16 stone  
fill ~104 ~1 ~29 ~105 ~1 ~29 glass  
fill ~104 ~1 ~103 ~105 ~1 ~103 glass  
fill ~105 ~1 ~3 ~105 ~6 ~3 stone  
fill ~105 ~1 ~15 ~105 ~6 ~15 stone  
fill ~106 ~1 ~5 ~106 ~6 ~5 stone  
fill ~106 ~1 ~13 ~106 ~6 ~13 stone  
fill ~106 ~1 ~30 ~106 ~6 ~30 glass  
fill ~106 ~1 ~102 ~106 ~6 ~102 glass  
fill ~107 ~1 ~31 ~107 ~6 ~31 glass  
fill ~107 ~1 ~101 ~107 ~6 ~101 glass  
fill ~108 ~1 ~32 ~108 ~6 ~32 glass  
fill ~108 ~1 ~100 ~108 ~6 ~100 glass  
fill ~111 ~1 ~2 ~111 ~1 ~3 wool 
setblock ~111 ~1 ~28 wool 11  
fill ~111 ~1 ~35 ~111 ~6 ~35 glass  
fill ~111 ~1 ~97 ~111 ~6 ~97 glass 
setblock ~111 ~1 ~104 wool 11  
fill ~111 ~1 ~129 ~111 ~1 ~130 wool  
fill ~112 ~1 ~2 ~118 ~1 ~2 iron_block  
fill ~112 ~1 ~3 ~118 ~1 ~3 iron_block  
fill ~112 ~1 ~4 ~118 ~1 ~4 iron_block  
fill ~112 ~1 ~5 ~118 ~1 ~5 iron_block  
fill ~112 ~1 ~6 ~118 ~1 ~6 iron_block  
fill ~112 ~1 ~7 ~118 ~1 ~7 iron_block  
fill ~112 ~1 ~8 ~118 ~1 ~8 iron_block  
fill ~112 ~1 ~9 ~118 ~1 ~9 iron_block  
fill ~112 ~1 ~10 ~118 ~1 ~10 iron_block  
fill ~112 ~1 ~11 ~118 ~1 ~11 iron_block  
fill ~112 ~1 ~12 ~118 ~1 ~12 iron_block  
fill ~112 ~1 ~13 ~118 ~1 ~13 iron_block  
fill ~112 ~1 ~14 ~118 ~1 ~14 iron_block  
fill ~112 ~1 ~15 ~118 ~1 ~15 iron_block  
fill ~112 ~1 ~16 ~118 ~1 ~16 iron_block  
fill ~112 ~1 ~17 ~118 ~1 ~17 iron_block  
fill ~112 ~1 ~18 ~118 ~1 ~18 iron_block  
fill ~112 ~1 ~19 ~118 ~1 ~19 iron_block  
fill ~112 ~1 ~20 ~118 ~1 ~20 iron_block  
fill ~112 ~1 ~21 ~118 ~1 ~21 iron_block  
fill ~112 ~1 ~22 ~118 ~1 ~22 iron_block  
fill ~112 ~1 ~23 ~118 ~1 ~23 iron_block  
fill ~112 ~1 ~24 ~118 ~1 ~24 iron_block  
fill ~112 ~1 ~25 ~118 ~1 ~25 iron_block 
setblock ~112 ~1 ~29 wool 11  
fill ~112 ~1 ~36 ~112 ~6 ~36 glass  
fill ~112 ~1 ~96 ~112 ~6 ~96 glass 
setblock ~112 ~1 ~103 wool 11  
fill ~112 ~1 ~104 ~112 ~1 ~130 iron_block  
fill ~113 ~1 ~37 ~113 ~6 ~37 glass  
fill ~113 ~1 ~95 ~113 ~6 ~95 glass  
fill ~113 ~1 ~107 ~118 ~1 ~107 iron_block  
fill ~113 ~1 ~108 ~118 ~1 ~108 iron_block  
fill ~113 ~1 ~109 ~118 ~1 ~109 iron_block  
fill ~113 ~1 ~110 ~118 ~1 ~110 iron_block  
fill ~113 ~1 ~111 ~118 ~1 ~111 iron_block  
fill ~113 ~1 ~112 ~118 ~1 ~112 iron_block  
fill ~113 ~1 ~113 ~118 ~1 ~113 iron_block  
fill ~113 ~1 ~114 ~118 ~1 ~114 iron_block  
fill ~113 ~1 ~115 ~118 ~1 ~115 iron_block  
fill ~113 ~1 ~116 ~118 ~1 ~116 iron_block  
fill ~113 ~1 ~117 ~118 ~1 ~117 iron_block  
fill ~113 ~1 ~118 ~118 ~1 ~118 iron_block  
fill ~113 ~1 ~119 ~118 ~1 ~119 iron_block  
fill ~113 ~1 ~120 ~118 ~1 ~120 iron_block  
fill ~113 ~1 ~121 ~118 ~1 ~121 iron_block  
fill ~113 ~1 ~122 ~118 ~1 ~122 iron_block  
fill ~113 ~1 ~123 ~118 ~1 ~123 iron_block  
fill ~113 ~1 ~124 ~118 ~1 ~124 iron_block  
fill ~113 ~1 ~125 ~118 ~1 ~125 iron_block  
fill ~113 ~1 ~126 ~118 ~1 ~126 iron_block  
fill ~113 ~1 ~127 ~118 ~1 ~127 iron_block  
fill ~113 ~1 ~128 ~118 ~1 ~128 iron_block  
fill ~113 ~1 ~129 ~118 ~1 ~129 iron_block  
fill ~113 ~1 ~130 ~118 ~1 ~130 iron_block  
fill ~114 ~1 ~38 ~114 ~6 ~38 glass  
fill ~114 ~1 ~39 ~114 ~6 ~39 glass  
fill ~114 ~1 ~93 ~114 ~6 ~93 glass  
fill ~114 ~1 ~94 ~114 ~6 ~94 glass  
fill ~115 ~1 ~40 ~115 ~6 ~40 glass  
fill ~115 ~1 ~92 ~115 ~6 ~92 glass  
fill ~116 ~1 ~41 ~116 ~6 ~41 glass  
fill ~116 ~1 ~42 ~116 ~6 ~42 glass  
fill ~116 ~1 ~90 ~116 ~6 ~90 glass  
fill ~116 ~1 ~91 ~116 ~6 ~91 glass  
fill ~117 ~1 ~43 ~117 ~6 ~43 glass  
fill ~117 ~1 ~44 ~117 ~6 ~44 glass  
fill ~117 ~1 ~88 ~117 ~6 ~88 glass  
fill ~117 ~1 ~89 ~117 ~6 ~89 glass 
setblock ~118 ~1 ~29 wool 11  
fill ~118 ~1 ~45 ~118 ~6 ~45 glass  
fill ~118 ~1 ~46 ~118 ~6 ~46 glass  
fill ~118 ~1 ~86 ~118 ~6 ~86 glass  
fill ~118 ~1 ~87 ~118 ~6 ~87 glass 
setblock ~118 ~1 ~103 wool 11  
fill ~118 ~1 ~104 ~118 ~1 ~130 iron_block  
fill ~119 ~1 ~2 ~119 ~1 ~3 wool 
setblock ~119 ~1 ~28 wool 11  
fill ~119 ~1 ~47 ~119 ~6 ~47 glass  
fill ~119 ~1 ~48 ~119 ~6 ~48 glass  
fill ~119 ~1 ~84 ~119 ~6 ~84 glass  
fill ~119 ~1 ~85 ~119 ~6 ~85 glass 
setblock ~119 ~1 ~104 wool 11  
fill ~119 ~1 ~129 ~119 ~1 ~130 wool  
fill ~120 ~1 ~49 ~120 ~6 ~49 glass  
fill ~120 ~1 ~50 ~120 ~6 ~50 glass  
fill ~120 ~1 ~82 ~120 ~6 ~82 glass  
fill ~120 ~1 ~83 ~120 ~6 ~83 glass  
fill ~121 ~1 ~51 ~121 ~6 ~51 glass  
fill ~121 ~1 ~52 ~121 ~6 ~52 glass  
fill ~121 ~1 ~53 ~121 ~6 ~53 glass  
fill ~121 ~1 ~54 ~121 ~6 ~54 glass  
fill ~121 ~1 ~78 ~121 ~6 ~78 glass  
fill ~121 ~1 ~79 ~121 ~6 ~79 glass  
fill ~121 ~1 ~80 ~121 ~6 ~80 glass  
fill ~121 ~1 ~81 ~121 ~6 ~81 glass  
fill ~122 ~1 ~55 ~122 ~6 ~55 glass  
fill ~122 ~1 ~56 ~122 ~6 ~56 glass  
fill ~122 ~1 ~57 ~122 ~6 ~57 glass  
fill ~122 ~1 ~58 ~122 ~6 ~58 glass  
fill ~122 ~1 ~59 ~122 ~6 ~59 glass  
fill ~122 ~1 ~60 ~122 ~6 ~60 glass  
fill ~122 ~1 ~61 ~122 ~6 ~61 glass  
fill ~122 ~1 ~62 ~122 ~6 ~62 glass  
fill ~122 ~1 ~63 ~122 ~6 ~63 glass  
fill ~122 ~1 ~69 ~122 ~6 ~69 glass  
fill ~122 ~1 ~70 ~122 ~6 ~70 glass  
fill ~122 ~1 ~71 ~122 ~6 ~71 glass  
fill ~122 ~1 ~72 ~122 ~6 ~72 glass  
fill ~122 ~1 ~73 ~122 ~6 ~73 glass  
fill ~122 ~1 ~74 ~122 ~6 ~74 glass  
fill ~122 ~1 ~75 ~122 ~6 ~75 glass  
fill ~122 ~1 ~76 ~122 ~6 ~76 glass  
fill ~122 ~1 ~77 ~122 ~6 ~77 glass  
fill ~123 ~1 ~23 ~123 ~17 ~23 stone  
fill ~123 ~1 ~25 ~123 ~17 ~25 stone  
fill ~123 ~1 ~27 ~123 ~17 ~27 stone  
fill ~123 ~1 ~29 ~123 ~17 ~29 stone  
fill ~123 ~1 ~31 ~123 ~17 ~31 stone  
fill ~123 ~1 ~33 ~123 ~17 ~33 stone  
fill ~123 ~1 ~35 ~123 ~17 ~35 stone  
fill ~123 ~1 ~37 ~123 ~17 ~37 stone  
fill ~123 ~1 ~39 ~123 ~17 ~39 stone  
fill ~123 ~1 ~41 ~123 ~17 ~41 stone  
fill ~123 ~1 ~43 ~123 ~17 ~43 stone  
fill ~123 ~1 ~45 ~123 ~17 ~45 stone  
fill ~123 ~1 ~47 ~123 ~17 ~47 stone  
fill ~123 ~1 ~49 ~123 ~17 ~49 stone  
fill ~123 ~1 ~51 ~123 ~17 ~51 stone  
fill ~123 ~1 ~53 ~123 ~17 ~53 stone  
fill ~123 ~1 ~55 ~123 ~17 ~55 stone  
fill ~123 ~1 ~57 ~123 ~33 ~57 stone  
fill ~123 ~1 ~59 ~123 ~28 ~59 stone  
fill ~123 ~1 ~61 ~123 ~28 ~61 stone  
fill ~123 ~1 ~63 ~123 ~28 ~63 stone  
fill ~123 ~1 ~69 ~123 ~28 ~69 stone  
fill ~123 ~1 ~71 ~123 ~28 ~71 stone  
fill ~123 ~1 ~73 ~123 ~28 ~73 stone  
fill ~123 ~1 ~75 ~123 ~33 ~75 stone  
fill ~123 ~1 ~77 ~123 ~17 ~77 stone  
fill ~123 ~1 ~79 ~123 ~17 ~79 stone  
fill ~123 ~1 ~81 ~123 ~17 ~81 stone  
fill ~123 ~1 ~83 ~123 ~17 ~83 stone  
fill ~123 ~1 ~85 ~123 ~17 ~85 stone  
fill ~123 ~1 ~87 ~123 ~17 ~87 stone  
fill ~123 ~1 ~89 ~123 ~17 ~89 stone  
fill ~123 ~1 ~91 ~123 ~17 ~91 stone  
fill ~123 ~1 ~93 ~123 ~17 ~93 stone  
fill ~123 ~1 ~95 ~123 ~17 ~95 stone  
fill ~123 ~1 ~97 ~123 ~17 ~97 stone  
fill ~123 ~1 ~99 ~123 ~17 ~99 stone  
fill ~123 ~1 ~101 ~123 ~17 ~101 stone  
fill ~123 ~1 ~103 ~123 ~17 ~103 stone  
fill ~123 ~1 ~105 ~123 ~17 ~105 stone  
fill ~123 ~1 ~107 ~123 ~17 ~107 stone  
fill ~123 ~1 ~109 ~123 ~17 ~109 stone  
fill ~153 ~1 ~23 ~153 ~17 ~23 stone  
fill ~153 ~1 ~25 ~153 ~2 ~25 stone  
fill ~153 ~1 ~27 ~153 ~2 ~27 stone  
fill ~153 ~1 ~29 ~153 ~2 ~29 stone  
fill ~153 ~1 ~31 ~153 ~17 ~31 stone  
fill ~153 ~1 ~33 ~153 ~17 ~33 stone  
fill ~153 ~1 ~35 ~153 ~2 ~35 stone  
fill ~153 ~1 ~37 ~153 ~2 ~37 stone  
fill ~153 ~1 ~39 ~153 ~2 ~39 stone  
fill ~153 ~1 ~41 ~153 ~2 ~41 stone  
fill ~153 ~1 ~43 ~153 ~17 ~43 stone  
fill ~153 ~1 ~45 ~153 ~17 ~45 stone  
fill ~153 ~1 ~47 ~153 ~2 ~47 stone  
fill ~153 ~1 ~49 ~153 ~2 ~49 stone  
fill ~153 ~1 ~51 ~153 ~2 ~51 stone  
fill ~153 ~1 ~53 ~153 ~17 ~53 stone  
fill ~153 ~1 ~55 ~153 ~17 ~55 stone  
fill ~153 ~1 ~57 ~153 ~2 ~57 stone  
fill ~153 ~1 ~59 ~153 ~2 ~59 stone  
fill ~153 ~1 ~61 ~153 ~2 ~61 stone  
fill ~153 ~1 ~63 ~153 ~2 ~63 stone  
fill ~153 ~1 ~65 ~153 ~17 ~65 stone  
fill ~153 ~1 ~67 ~153 ~17 ~67 stone  
fill ~153 ~1 ~69 ~153 ~2 ~69 stone  
fill ~153 ~1 ~71 ~153 ~2 ~71 stone  
fill ~153 ~1 ~73 ~153 ~2 ~73 stone  
fill ~153 ~1 ~75 ~153 ~2 ~75 stone  
fill ~153 ~1 ~77 ~153 ~17 ~77 stone  
fill ~153 ~1 ~79 ~153 ~17 ~79 stone  
fill ~153 ~1 ~81 ~153 ~2 ~81 stone  
fill ~153 ~1 ~83 ~153 ~2 ~83 stone  
fill ~153 ~1 ~85 ~153 ~2 ~85 stone  
fill ~153 ~1 ~87 ~153 ~17 ~87 stone  
fill ~153 ~1 ~89 ~153 ~17 ~89 stone  
fill ~153 ~1 ~91 ~153 ~2 ~91 stone  
fill ~153 ~1 ~93 ~153 ~2 ~93 stone  
fill ~153 ~1 ~95 ~153 ~2 ~95 stone  
fill ~153 ~1 ~97 ~153 ~2 ~97 stone  
fill ~153 ~1 ~99 ~153 ~17 ~99 stone  
fill ~153 ~1 ~101 ~153 ~17 ~101 stone  
fill ~153 ~1 ~103 ~153 ~2 ~103 stone  
fill ~153 ~1 ~105 ~153 ~2 ~105 stone  
fill ~153 ~1 ~107 ~153 ~2 ~107 stone  
fill ~153 ~1 ~109 ~153 ~17 ~109 stone 
setblock ~12 ~2 ~80 stone_slab 0 
setblock ~12 ~2 ~83 stone_slab 0 
setblock ~12 ~2 ~86 stone_slab 0 
setblock ~12 ~2 ~89 stone_slab 0 
setblock ~12 ~2 ~104 stone_slab 0 
setblock ~12 ~2 ~107 stone_slab 0 
setblock ~12 ~2 ~110 stone_slab 0 
setblock ~12 ~2 ~113 stone_slab 0 
setblock ~13 ~2 ~19 stone_slab 0 
setblock ~13 ~2 ~22 stone_slab 0 
setblock ~13 ~2 ~25 stone_slab 0 
setblock ~13 ~2 ~28 stone_slab 0 
setblock ~13 ~2 ~43 stone_slab 0 
setblock ~13 ~2 ~46 stone_slab 0 
setblock ~13 ~2 ~49 stone_slab 0 
setblock ~13 ~2 ~52 stone_slab 0 
setblock ~13 ~2 ~79 stone_slab 0 
setblock ~13 ~2 ~80 glowstone 0  
fill ~13 ~2 ~81 ~13 ~2 ~82 stone_slab 
setblock ~13 ~2 ~83 glowstone 0  
fill ~13 ~2 ~84 ~13 ~2 ~85 stone_slab 
setblock ~13 ~2 ~86 glowstone 0  
fill ~13 ~2 ~87 ~13 ~2 ~88 stone_slab 
setblock ~13 ~2 ~89 glowstone 0 
setblock ~13 ~2 ~90 stone_slab 0 
setblock ~13 ~2 ~103 stone_slab 0 
setblock ~13 ~2 ~104 glowstone 0  
fill ~13 ~2 ~105 ~13 ~2 ~106 stone_slab 
setblock ~13 ~2 ~107 glowstone 0  
fill ~13 ~2 ~108 ~13 ~2 ~109 stone_slab 
setblock ~13 ~2 ~110 glowstone 0  
fill ~13 ~2 ~111 ~13 ~2 ~112 stone_slab 
setblock ~13 ~2 ~113 glowstone 0 
setblock ~13 ~2 ~114 stone_slab 0 
setblock ~14 ~2 ~18 stone_slab 0 
setblock ~14 ~2 ~19 glowstone 0  
fill ~14 ~2 ~20 ~14 ~2 ~21 stone_slab 
setblock ~14 ~2 ~22 glowstone 0  
fill ~14 ~2 ~23 ~14 ~2 ~24 stone_slab 
setblock ~14 ~2 ~25 glowstone 0  
fill ~14 ~2 ~26 ~14 ~2 ~27 stone_slab 
setblock ~14 ~2 ~28 glowstone 0 
setblock ~14 ~2 ~29 stone_slab 0 
setblock ~14 ~2 ~42 stone_slab 0 
setblock ~14 ~2 ~43 glowstone 0  
fill ~14 ~2 ~44 ~14 ~2 ~45 stone_slab 
setblock ~14 ~2 ~46 glowstone 0  
fill ~14 ~2 ~47 ~14 ~2 ~48 stone_slab 
setblock ~14 ~2 ~49 glowstone 0  
fill ~14 ~2 ~50 ~14 ~2 ~51 stone_slab 
setblock ~14 ~2 ~52 glowstone 0 
setblock ~14 ~2 ~53 stone_slab 0 
setblock ~14 ~2 ~80 stone_slab 0 
setblock ~14 ~2 ~83 stone_slab 0 
setblock ~14 ~2 ~86 stone_slab 0 
setblock ~14 ~2 ~89 stone_slab 0 
setblock ~14 ~2 ~104 stone_slab 0 
setblock ~14 ~2 ~107 stone_slab 0 
setblock ~14 ~2 ~110 stone_slab 0 
setblock ~14 ~2 ~113 stone_slab 0 
setblock ~15 ~2 ~19 stone_slab 0 
setblock ~15 ~2 ~22 stone_slab 0 
setblock ~15 ~2 ~25 stone_slab 0 
setblock ~15 ~2 ~28 stone_slab 0 
setblock ~15 ~2 ~43 stone_slab 0 
setblock ~15 ~2 ~46 stone_slab 0 
setblock ~15 ~2 ~49 stone_slab 0 
setblock ~15 ~2 ~52 stone_slab 0 
setblock ~16 ~2 ~80 stone_slab 0 
setblock ~16 ~2 ~83 stone_slab 0 
setblock ~16 ~2 ~86 stone_slab 0 
setblock ~16 ~2 ~89 stone_slab 0 
setblock ~16 ~2 ~104 stone_slab 0 
setblock ~16 ~2 ~107 stone_slab 0 
setblock ~16 ~2 ~110 stone_slab 0 
setblock ~16 ~2 ~113 stone_slab 0 
setblock ~17 ~2 ~19 stone_slab 0 
setblock ~17 ~2 ~22 stone_slab 0 
setblock ~17 ~2 ~25 stone_slab 0 
setblock ~17 ~2 ~28 stone_slab 0 
setblock ~17 ~2 ~43 stone_slab 0 
setblock ~17 ~2 ~46 stone_slab 0 
setblock ~17 ~2 ~49 stone_slab 0 
setblock ~17 ~2 ~52 stone_slab 0 
setblock ~17 ~2 ~79 stone_slab 0 
setblock ~17 ~2 ~80 glowstone 0  
fill ~17 ~2 ~81 ~17 ~2 ~82 stone_slab 
setblock ~17 ~2 ~83 glowstone 0  
fill ~17 ~2 ~84 ~17 ~2 ~85 stone_slab 
setblock ~17 ~2 ~86 glowstone 0  
fill ~17 ~2 ~87 ~17 ~2 ~88 stone_slab 
setblock ~17 ~2 ~89 glowstone 0 
setblock ~17 ~2 ~90 stone_slab 0 
setblock ~17 ~2 ~103 stone_slab 0 
setblock ~17 ~2 ~104 glowstone 0  
fill ~17 ~2 ~105 ~17 ~2 ~106 stone_slab 
setblock ~17 ~2 ~107 glowstone 0  
fill ~17 ~2 ~108 ~17 ~2 ~109 stone_slab 
setblock ~17 ~2 ~110 glowstone 0  
fill ~17 ~2 ~111 ~17 ~2 ~112 stone_slab 
setblock ~17 ~2 ~113 glowstone 0 
setblock ~17 ~2 ~114 stone_slab 0 
setblock ~18 ~2 ~18 stone_slab 0 
setblock ~18 ~2 ~19 glowstone 0  
fill ~18 ~2 ~20 ~18 ~2 ~21 stone_slab 
setblock ~18 ~2 ~22 glowstone 0  
fill ~18 ~2 ~23 ~18 ~2 ~24 stone_slab 
setblock ~18 ~2 ~25 glowstone 0  
fill ~18 ~2 ~26 ~18 ~2 ~27 stone_slab 
setblock ~18 ~2 ~28 glowstone 0 
setblock ~18 ~2 ~29 stone_slab 0 
setblock ~18 ~2 ~42 stone_slab 0 
setblock ~18 ~2 ~43 glowstone 0  
fill ~18 ~2 ~44 ~18 ~2 ~45 stone_slab 
setblock ~18 ~2 ~46 glowstone 0  
fill ~18 ~2 ~47 ~18 ~2 ~48 stone_slab 
setblock ~18 ~2 ~49 glowstone 0  
fill ~18 ~2 ~50 ~18 ~2 ~51 stone_slab   
setblock ~18 ~2 ~52 glowstone 0 
setblock ~18 ~2 ~53 stone_slab 0 
setblock ~18 ~2 ~80 stone_slab 0 
setblock ~18 ~2 ~83 stone_slab 0 
setblock ~18 ~2 ~86 stone_slab 0 
setblock ~18 ~2 ~89 stone_slab 0 
setblock ~18 ~2 ~104 stone_slab 0 
setblock ~18 ~2 ~107 stone_slab 0 
setblock ~18 ~2 ~110 stone_slab 0 
setblock ~18 ~2 ~113 stone_slab 0 
setblock ~19 ~2 ~19 stone_slab 0 
setblock ~19 ~2 ~22 stone_slab 0 
setblock ~19 ~2 ~25 stone_slab 0 
setblock ~19 ~2 ~28 stone_slab 0 
setblock ~19 ~2 ~43 stone_slab 0 
setblock ~19 ~2 ~46 stone_slab 0 
setblock ~19 ~2 ~49 stone_slab 0 
setblock ~19 ~2 ~52 stone_slab 0  
fill ~35 ~2 ~4 ~35 ~2 ~5 wool 
setblock ~35 ~2 ~27 wool 11 
setblock ~35 ~2 ~105 wool 11  
fill ~35 ~2 ~127 ~35 ~2 ~128 wool  
fill ~36 ~2 ~4 ~42 ~2 ~4 iron_block  
fill ~36 ~2 ~5 ~42 ~2 ~5 iron_block  
fill ~36 ~2 ~6 ~42 ~2 ~6 iron_block  
fill ~36 ~2 ~7 ~42 ~2 ~7 iron_block  
fill ~36 ~2 ~8 ~42 ~2 ~8 iron_block  
fill ~36 ~2 ~9 ~42 ~2 ~9 iron_block  
fill ~36 ~2 ~10 ~42 ~2 ~10 iron_block  
fill ~36 ~2 ~11 ~42 ~2 ~11 iron_block  
fill ~36 ~2 ~12 ~42 ~2 ~12 iron_block  
fill ~36 ~2 ~13 ~42 ~2 ~13 iron_block  
fill ~36 ~2 ~14 ~42 ~2 ~14 iron_block  
fill ~36 ~2 ~15 ~42 ~2 ~15 iron_block  
fill ~36 ~2 ~16 ~42 ~2 ~16 iron_block  
fill ~36 ~2 ~17 ~42 ~2 ~17 iron_block  
fill ~36 ~2 ~18 ~42 ~2 ~18 iron_block  
fill ~36 ~2 ~19 ~42 ~2 ~19 iron_block  
fill ~36 ~2 ~20 ~42 ~2 ~20 iron_block  
fill ~36 ~2 ~21 ~42 ~2 ~21 iron_block  
fill ~36 ~2 ~22 ~42 ~2 ~22 iron_block  
fill ~36 ~2 ~23 ~42 ~2 ~23 iron_block  
fill ~36 ~2 ~24 ~42 ~2 ~24 iron_block  
fill ~36 ~2 ~25 ~42 ~2 ~25 iron_block 
setblock ~36 ~2 ~28 wool 11 
setblock ~36 ~2 ~104 wool 11  
fill ~36 ~2 ~105 ~36 ~2 ~128 iron_block  
fill ~37 ~2 ~107 ~42 ~2 ~107 iron_block  
fill ~37 ~2 ~108 ~42 ~2 ~108 iron_block  
fill ~37 ~2 ~109 ~42 ~2 ~109 iron_block  
fill ~37 ~2 ~110 ~42 ~2 ~110 iron_block  
fill ~37 ~2 ~111 ~42 ~2 ~111 iron_block  
fill ~37 ~2 ~112 ~42 ~2 ~112 iron_block  
fill ~37 ~2 ~113 ~42 ~2 ~113 iron_block  
fill ~37 ~2 ~114 ~42 ~2 ~114 iron_block  
fill ~37 ~2 ~115 ~42 ~2 ~115 iron_block  
fill ~37 ~2 ~116 ~42 ~2 ~116 iron_block  
fill ~37 ~2 ~117 ~42 ~2 ~117 iron_block  
fill ~37 ~2 ~118 ~42 ~2 ~118 iron_block  
fill ~37 ~2 ~119 ~42 ~2 ~119 iron_block  
fill ~37 ~2 ~120 ~42 ~2 ~120 iron_block  
fill ~37 ~2 ~121 ~42 ~2 ~121 iron_block  
fill ~37 ~2 ~122 ~42 ~2 ~122 iron_block  
fill ~37 ~2 ~123 ~42 ~2 ~123 iron_block  
fill ~37 ~2 ~124 ~42 ~2 ~124 iron_block  
fill ~37 ~2 ~125 ~42 ~2 ~125 iron_block  
fill ~37 ~2 ~126 ~42 ~2 ~126 iron_block  
fill ~37 ~2 ~127 ~42 ~2 ~127 iron_block  
fill ~37 ~2 ~128 ~42 ~2 ~128 iron_block 
setblock ~42 ~2 ~28 wool 11 
setblock ~42 ~2 ~104 wool 11  
fill ~42 ~2 ~105 ~42 ~2 ~128 iron_block  
fill ~43 ~2 ~4 ~43 ~2 ~5 wool 
setblock ~43 ~2 ~27 wool 11 
setblock ~43 ~2 ~105 wool 11  
fill ~43 ~2 ~127 ~43 ~2 ~128 wool 
setblock ~45 ~2 ~34 glowstone 0 
setblock ~45 ~2 ~98 glowstone 0  
fill ~49 ~2 ~29 ~50 ~2 ~29 glass  
fill ~49 ~2 ~103 ~50 ~2 ~103 glass  
fill ~52 ~2 ~0 ~53 ~2 ~0 stone  
fill ~52 ~2 ~18 ~53 ~2 ~18 stone  
fill ~52 ~2 ~27 ~53 ~2 ~27 glass  
fill ~52 ~2 ~105 ~53 ~2 ~105 glass  
fill ~54 ~2 ~19 ~76 ~2 ~19 stone  
fill ~54 ~2 ~26 ~55 ~2 ~26 glass  
fill ~54 ~2 ~106 ~55 ~2 ~106 glass  
fill ~56 ~2 ~25 ~57 ~2 ~25 glass  
fill ~56 ~2 ~107 ~57 ~2 ~107 glass  
fill ~58 ~2 ~24 ~59 ~2 ~24 glass  
fill ~58 ~2 ~108 ~59 ~2 ~108 glass  
fill ~60 ~2 ~23 ~61 ~2 ~23 glass  
fill ~60 ~2 ~109 ~61 ~2 ~109 glass  
fill ~62 ~2 ~22 ~65 ~2 ~22 glass  
fill ~62 ~2 ~110 ~65 ~2 ~110 glass  
fill ~66 ~2 ~21 ~75 ~2 ~21 glass  
fill ~66 ~2 ~111 ~71 ~2 ~111 glass  
fill ~71 ~2 ~118 ~76 ~2 ~118 stone  
fill ~72 ~2 ~111 ~83 ~2 ~111 stone  
fill ~74 ~2 ~59 ~75 ~2 ~59 stone  
fill ~74 ~2 ~60 ~74 ~2 ~63 stone_slab  
fill ~74 ~2 ~112 ~76 ~2 ~112 stone  
fill ~74 ~2 ~113 ~74 ~2 ~115 stone  
fill ~74 ~2 ~119 ~76 ~2 ~119 stone  
fill ~75 ~2 ~60 ~75 ~2 ~63 double_stone_slab 
setblock ~75 ~2 ~64 stone 0 
setblock ~75 ~2 ~110 redstone_torch 4  
fill ~76 ~2 ~21 ~76 ~3 ~21 stone  
fill ~76 ~2 ~110 ~78 ~2 ~110 stone  
fill ~76 ~2 ~113 ~78 ~2 ~113 stone  
fill ~76 ~2 ~114 ~78 ~2 ~114 stone  
fill ~76 ~2 ~115 ~78 ~2 ~115 stone  
fill ~76 ~2 ~116 ~78 ~2 ~116 stone  
fill ~76 ~2 ~117 ~76 ~5 ~117 stone  
fill ~76 ~2 ~120 ~76 ~3 ~120 stone  
fill ~76 ~2 ~121 ~76 ~3 ~121 stone  
fill ~76 ~2 ~122 ~76 ~3 ~122 stone 
setblock ~77 ~2 ~19 glowstone 0 
setblock ~77 ~2 ~21 glowstone 0  
fill ~77 ~2 ~112 ~77 ~3 ~112 wool  
fill ~78 ~2 ~19 ~79 ~2 ~19 stone  
fill ~78 ~2 ~20 ~79 ~2 ~20 stone  
fill ~78 ~2 ~21 ~79 ~2 ~21 stone  
fill ~78 ~2 ~112 ~78 ~5 ~112 stone  
fill ~78 ~2 ~117 ~78 ~5 ~117 stone  
fill ~78 ~2 ~118 ~83 ~2 ~118 stone  
fill ~78 ~2 ~119 ~80 ~2 ~119 stone  
fill ~78 ~2 ~120 ~78 ~3 ~120 stone  
fill ~78 ~2 ~121 ~78 ~3 ~121 stone  
fill ~78 ~2 ~122 ~78 ~3 ~122 stone 
setblock ~79 ~2 ~110 redstone_torch 4 
setblock ~80 ~2 ~19 glowstone 0 
setblock ~80 ~2 ~21 glowstone 0  
fill ~81 ~2 ~19 ~100 ~2 ~19 stone  
fill ~81 ~2 ~21 ~81 ~3 ~21 stone  
fill ~82 ~2 ~21 ~88 ~2 ~21 glass  
fill ~84 ~2 ~111 ~88 ~2 ~111 glass  
fill ~89 ~2 ~22 ~92 ~2 ~22 glass  
fill ~89 ~2 ~110 ~92 ~2 ~110 glass  
fill ~93 ~2 ~23 ~94 ~2 ~23 glass  
fill ~93 ~2 ~109 ~94 ~2 ~109 glass  
fill ~95 ~2 ~24 ~96 ~2 ~24 glass  
fill ~95 ~2 ~108 ~96 ~2 ~108 glass  
fill ~97 ~2 ~25 ~98 ~2 ~25 glass  
fill ~97 ~2 ~107 ~98 ~2 ~107 glass  
fill ~99 ~2 ~26 ~100 ~2 ~26 glass  
fill ~99 ~2 ~106 ~100 ~2 ~106 glass  
fill ~101 ~2 ~27 ~102 ~2 ~27 glass  
fill ~101 ~2 ~105 ~102 ~2 ~105 glass  
fill ~104 ~2 ~29 ~105 ~2 ~29 glass  
fill ~104 ~2 ~103 ~105 ~2 ~103 glass 
setblock ~109 ~2 ~34 glowstone 0 
setblock ~109 ~2 ~98 glowstone 0  
fill ~111 ~2 ~4 ~111 ~2 ~5 wool 
setblock ~111 ~2 ~27 wool 11 
setblock ~111 ~2 ~105 wool 11  
fill ~111 ~2 ~127 ~111 ~2 ~128 wool  
fill ~112 ~2 ~4 ~118 ~2 ~4 iron_block  
fill ~112 ~2 ~5 ~118 ~2 ~5 iron_block  
fill ~112 ~2 ~6 ~118 ~2 ~6 iron_block  
fill ~112 ~2 ~7 ~118 ~2 ~7 iron_block  
fill ~112 ~2 ~8 ~118 ~2 ~8 iron_block  
fill ~112 ~2 ~9 ~118 ~2 ~9 iron_block  
fill ~112 ~2 ~10 ~118 ~2 ~10 iron_block  
fill ~112 ~2 ~11 ~118 ~2 ~11 iron_block  
fill ~112 ~2 ~12 ~118 ~2 ~12 iron_block  
fill ~112 ~2 ~13 ~118 ~2 ~13 iron_block  
fill ~112 ~2 ~14 ~118 ~2 ~14 iron_block  
fill ~112 ~2 ~15 ~118 ~2 ~15 iron_block  
fill ~112 ~2 ~16 ~118 ~2 ~16 iron_block  
fill ~112 ~2 ~17 ~118 ~2 ~17 iron_block  
fill ~112 ~2 ~18 ~118 ~2 ~18 iron_block  
fill ~112 ~2 ~19 ~118 ~2 ~19 iron_block  
fill ~112 ~2 ~20 ~118 ~2 ~20 iron_block  
fill ~112 ~2 ~21 ~118 ~2 ~21 iron_block  
fill ~112 ~2 ~22 ~118 ~2 ~22 iron_block  
fill ~112 ~2 ~23 ~118 ~2 ~23 iron_block  
fill ~112 ~2 ~24 ~118 ~2 ~24 iron_block  
fill ~112 ~2 ~25 ~118 ~2 ~25 iron_block 
setblock ~112 ~2 ~28 wool 11 
setblock ~112 ~2 ~104 wool 11  
fill ~112 ~2 ~105 ~112 ~2 ~128 iron_block  
fill ~113 ~2 ~107 ~118 ~2 ~107 iron_block  
fill ~113 ~2 ~108 ~118 ~2 ~108 iron_block  
fill ~113 ~2 ~109 ~118 ~2 ~109 iron_block  
fill ~113 ~2 ~110 ~118 ~2 ~110 iron_block  
fill ~113 ~2 ~111 ~118 ~2 ~111 iron_block  
fill ~113 ~2 ~112 ~118 ~2 ~112 iron_block  
fill ~113 ~2 ~113 ~118 ~2 ~113 iron_block  
fill ~113 ~2 ~114 ~118 ~2 ~114 iron_block  
fill ~113 ~2 ~115 ~118 ~2 ~115 iron_block  
fill ~113 ~2 ~116 ~118 ~2 ~116 iron_block  
fill ~113 ~2 ~117 ~118 ~2 ~117 iron_block  
fill ~113 ~2 ~118 ~118 ~2 ~118 iron_block  
fill ~113 ~2 ~119 ~118 ~2 ~119 iron_block  
fill ~113 ~2 ~120 ~118 ~2 ~120 iron_block  
fill ~113 ~2 ~121 ~118 ~2 ~121 iron_block  
fill ~113 ~2 ~122 ~118 ~2 ~122 iron_block  
fill ~113 ~2 ~123 ~118 ~2 ~123 iron_block  
fill ~113 ~2 ~124 ~118 ~2 ~124 iron_block  
fill ~113 ~2 ~125 ~118 ~2 ~125 iron_block  
fill ~113 ~2 ~126 ~118 ~2 ~126 iron_block  
fill ~113 ~2 ~127 ~118 ~2 ~127 iron_block  
fill ~113 ~2 ~128 ~118 ~2 ~128 iron_block 
setblock ~118 ~2 ~28 wool 11 
setblock ~118 ~2 ~104 wool 11  
fill ~118 ~2 ~105 ~118 ~2 ~128 iron_block  
fill ~119 ~2 ~4 ~119 ~2 ~5 wool 
setblock ~119 ~2 ~27 wool 11 
setblock ~119 ~2 ~105 wool 11  
fill ~119 ~2 ~127 ~119 ~2 ~128 wool 
setblock ~135 ~2 ~19 stone_slab 0 
setblock ~135 ~2 ~22 stone_slab 0 
setblock ~135 ~2 ~25 stone_slab 0 
setblock ~135 ~2 ~28 stone_slab 0 
setblock ~135 ~2 ~43 stone_slab 0 
setblock ~135 ~2 ~46 stone_slab 0 
setblock ~135 ~2 ~49 stone_slab 0 
setblock ~135 ~2 ~52 stone_slab 0 
setblock ~136 ~2 ~18 stone_slab 0 
setblock ~136 ~2 ~19 glowstone 0  
fill ~136 ~2 ~20 ~136 ~2 ~21 stone_slab 
setblock ~136 ~2 ~22 glowstone 0  
fill ~136 ~2 ~23 ~136 ~2 ~24 stone_slab 
setblock ~136 ~2 ~25 glowstone 0  
fill ~136 ~2 ~26 ~136 ~2 ~27 stone_slab 
setblock ~136 ~2 ~28 glowstone 0 
setblock ~136 ~2 ~29 stone_slab 0 
setblock ~136 ~2 ~42 stone_slab 0 
setblock ~136 ~2 ~43 glowstone 0  
fill ~136 ~2 ~44 ~136 ~2 ~45 stone_slab 
setblock ~136 ~2 ~46 glowstone 0  
fill ~136 ~2 ~47 ~136 ~2 ~48 stone_slab 
setblock ~136 ~2 ~49 glowstone 0  
fill ~136 ~2 ~50 ~136 ~2 ~51 stone_slab 
setblock ~136 ~2 ~52 glowstone 0 
setblock ~136 ~2 ~53 stone_slab 0 
setblock ~136 ~2 ~80 stone_slab 0 
setblock ~136 ~2 ~83 stone_slab 0 
setblock ~136 ~2 ~86 stone_slab 0 
setblock ~136 ~2 ~89 stone_slab 0 
setblock ~136 ~2 ~104 stone_slab 0 
setblock ~136 ~2 ~107 stone_slab 0 
setblock ~136 ~2 ~110 stone_slab 0 
setblock ~136 ~2 ~113 stone_slab 0 
setblock ~137 ~2 ~19 stone_slab 0 
setblock ~137 ~2 ~22 stone_slab 0 
setblock ~137 ~2 ~25 stone_slab 0 
setblock ~137 ~2 ~28 stone_slab 0 
setblock ~137 ~2 ~43 stone_slab 0 
setblock ~137 ~2 ~46 stone_slab 0 
setblock ~137 ~2 ~49 stone_slab 0 
setblock ~137 ~2 ~52 stone_slab 0 
setblock ~137 ~2 ~79 stone_slab 0 
setblock ~137 ~2 ~80 glowstone 0  
fill ~137 ~2 ~81 ~137 ~2 ~82 stone_slab 
setblock ~137 ~2 ~83 glowstone 0  
fill ~137 ~2 ~84 ~137 ~2 ~85 stone_slab 
setblock ~137 ~2 ~86 glowstone 0  
fill ~137 ~2 ~87 ~137 ~2 ~88 stone_slab 
setblock ~137 ~2 ~89 glowstone 0 
setblock ~137 ~2 ~90 stone_slab 0 
setblock ~137 ~2 ~103 stone_slab 0 
setblock ~137 ~2 ~104 glowstone 0  
fill ~137 ~2 ~105 ~137 ~2 ~106 stone_slab 
setblock ~137 ~2 ~107 glowstone 0  
fill ~137 ~2 ~108 ~137 ~2 ~109 stone_slab 
setblock ~137 ~2 ~110 glowstone 0  
fill ~137 ~2 ~111 ~137 ~2 ~112 stone_slab 
setblock ~137 ~2 ~113 glowstone 0 
setblock ~137 ~2 ~114 stone_slab 0 
setblock ~138 ~2 ~80 stone_slab 0 
setblock ~138 ~2 ~83 stone_slab 0 
setblock ~138 ~2 ~86 stone_slab 0 
setblock ~138 ~2 ~89 stone_slab 0 
setblock ~138 ~2 ~104 stone_slab 0 
setblock ~138 ~2 ~107 stone_slab 0 
setblock ~138 ~2 ~110 stone_slab 0 
setblock ~138 ~2 ~113 stone_slab 0 
setblock ~139 ~2 ~19 stone_slab 0 
setblock ~139 ~2 ~22 stone_slab 0 
setblock ~139 ~2 ~25 stone_slab 0 
setblock ~139 ~2 ~28 stone_slab 0 
setblock ~139 ~2 ~43 stone_slab 0 
setblock ~139 ~2 ~46 stone_slab 0 
setblock ~139 ~2 ~49 stone_slab 0 
setblock ~139 ~2 ~52 stone_slab 0 
setblock ~140 ~2 ~18 stone_slab 0 
setblock ~140 ~2 ~19 glowstone 0  
fill ~140 ~2 ~20 ~140 ~2 ~21 stone_slab 
setblock ~140 ~2 ~22 glowstone 0  
fill ~140 ~2 ~23 ~140 ~2 ~24 stone_slab 
setblock ~140 ~2 ~25 glowstone 0  
fill ~140 ~2 ~26 ~140 ~2 ~27 stone_slab 
setblock ~140 ~2 ~28 glowstone 0 
setblock ~140 ~2 ~29 stone_slab 0 
setblock ~140 ~2 ~42 stone_slab 0 
setblock ~140 ~2 ~43 glowstone 0  
fill ~140 ~2 ~44 ~140 ~2 ~45 stone_slab 
setblock ~140 ~2 ~46 glowstone 0  
fill ~140 ~2 ~47 ~140 ~2 ~48 stone_slab 
setblock ~140 ~2 ~49 glowstone 0  
fill ~140 ~2 ~50 ~140 ~2 ~51 stone_slab 
setblock ~140 ~2 ~52 glowstone 0 
setblock ~140 ~2 ~53 stone_slab 0 
setblock ~140 ~2 ~80 stone_slab 0 
setblock ~140 ~2 ~83 stone_slab 0 
setblock ~140 ~2 ~86 stone_slab 0 
setblock ~140 ~2 ~89 stone_slab 0 
setblock ~140 ~2 ~104 stone_slab 0 
setblock ~140 ~2 ~107 stone_slab 0 
setblock ~140 ~2 ~110 stone_slab 0 
setblock ~140 ~2 ~113 stone_slab 0 
setblock ~141 ~2 ~19 stone_slab 0 
setblock ~141 ~2 ~22 stone_slab 0 
setblock ~141 ~2 ~25 stone_slab 0 
setblock ~141 ~2 ~28 stone_slab 0 
setblock ~141 ~2 ~43 stone_slab 0 
setblock ~141 ~2 ~46 stone_slab 0 
setblock ~141 ~2 ~49 stone_slab 0 
setblock ~141 ~2 ~52 stone_slab 0 
setblock ~141 ~2 ~79 stone_slab 0 
setblock ~141 ~2 ~80 glowstone 0  
fill ~141 ~2 ~81 ~141 ~2 ~82 stone_slab 
setblock ~141 ~2 ~83 glowstone 0  
fill ~141 ~2 ~84 ~141 ~2 ~85 stone_slab 
setblock ~141 ~2 ~86 glowstone 0  
fill ~141 ~2 ~87 ~141 ~2 ~88 stone_slab 
setblock ~141 ~2 ~89 glowstone 0 
setblock ~141 ~2 ~90 stone_slab 0 
setblock ~141 ~2 ~103 stone_slab 0 
setblock ~141 ~2 ~104 glowstone 0  
fill ~141 ~2 ~105 ~141 ~2 ~106 stone_slab 
setblock ~141 ~2 ~107 glowstone 0  
fill ~141 ~2 ~108 ~141 ~2 ~109 stone_slab 
setblock ~141 ~2 ~110 glowstone 0  
fill ~141 ~2 ~111 ~141 ~2 ~112 stone_slab 
setblock ~141 ~2 ~113 glowstone 0 
setblock ~141 ~2 ~114 stone_slab 0 
setblock ~142 ~2 ~80 stone_slab 0 
setblock ~142 ~2 ~83 stone_slab 0 
setblock ~142 ~2 ~86 stone_slab 0 
setblock ~142 ~2 ~89 stone_slab 0 
setblock ~142 ~2 ~104 stone_slab 0 
setblock ~142 ~2 ~107 stone_slab 0 
setblock ~142 ~2 ~110 stone_slab 0 
setblock ~142 ~2 ~113 stone_slab 0  
fill ~1 ~3 ~24 ~1 ~4 ~24 glass  
fill ~1 ~3 ~25 ~1 ~4 ~25 glass  
fill ~1 ~3 ~26 ~1 ~4 ~26 glass  
fill ~1 ~3 ~27 ~1 ~4 ~27 glass  
fill ~1 ~3 ~28 ~1 ~4 ~28 glass  
fill ~1 ~3 ~29 ~1 ~4 ~29 glass  
fill ~1 ~3 ~30 ~1 ~4 ~30 glass  
fill ~1 ~3 ~35 ~1 ~4 ~35 glass  
fill ~1 ~3 ~36 ~1 ~4 ~36 glass  
fill ~1 ~3 ~37 ~1 ~4 ~37 glass  
fill ~1 ~3 ~38 ~1 ~4 ~38 glass  
fill ~1 ~3 ~39 ~1 ~4 ~39 glass  
fill ~1 ~3 ~40 ~1 ~4 ~40 glass  
fill ~1 ~3 ~41 ~1 ~4 ~41 glass  
fill ~1 ~3 ~46 ~1 ~4 ~46 glass  
fill ~1 ~3 ~47 ~1 ~4 ~47 glass  
fill ~1 ~3 ~48 ~1 ~4 ~48 glass  
fill ~1 ~3 ~49 ~1 ~4 ~49 glass  
fill ~1 ~3 ~50 ~1 ~4 ~50 glass  
fill ~1 ~3 ~51 ~1 ~4 ~51 glass  
fill ~1 ~3 ~52 ~1 ~4 ~52 glass  
fill ~1 ~3 ~57 ~1 ~4 ~57 glass  
fill ~1 ~3 ~58 ~1 ~4 ~58 glass  
fill ~1 ~3 ~59 ~1 ~4 ~59 glass  
fill ~1 ~3 ~60 ~1 ~4 ~60 glass  
fill ~1 ~3 ~61 ~1 ~4 ~61 glass  
fill ~1 ~3 ~62 ~1 ~4 ~62 glass  
fill ~1 ~3 ~63 ~1 ~4 ~63 glass  
fill ~1 ~3 ~69 ~1 ~4 ~69 glass  
fill ~1 ~3 ~70 ~1 ~4 ~70 glass  
fill ~1 ~3 ~71 ~1 ~4 ~71 glass  
fill ~1 ~3 ~72 ~1 ~4 ~72 glass  
fill ~1 ~3 ~73 ~1 ~4 ~73 glass  
fill ~1 ~3 ~74 ~1 ~4 ~74 glass  
fill ~1 ~3 ~75 ~1 ~4 ~75 glass  
fill ~1 ~3 ~80 ~1 ~4 ~80 glass  
fill ~1 ~3 ~81 ~1 ~4 ~81 glass  
fill ~1 ~3 ~82 ~1 ~4 ~82 glass  
fill ~1 ~3 ~83 ~1 ~4 ~83 glass  
fill ~1 ~3 ~84 ~1 ~4 ~84 glass  
fill ~1 ~3 ~85 ~1 ~4 ~85 glass  
fill ~1 ~3 ~86 ~1 ~4 ~86 glass  
fill ~1 ~3 ~91 ~1 ~4 ~91 glass  
fill ~1 ~3 ~92 ~1 ~4 ~92 glass  
fill ~1 ~3 ~93 ~1 ~4 ~93 glass  
fill ~1 ~3 ~94 ~1 ~4 ~94 glass  
fill ~1 ~3 ~95 ~1 ~4 ~95 glass  
fill ~1 ~3 ~96 ~1 ~4 ~96 glass  
fill ~1 ~3 ~97 ~1 ~4 ~97 glass  
fill ~1 ~3 ~102 ~1 ~4 ~102 glass  
fill ~1 ~3 ~103 ~1 ~4 ~103 glass  
fill ~1 ~3 ~104 ~1 ~4 ~104 glass  
fill ~1 ~3 ~105 ~1 ~4 ~105 glass  
fill ~1 ~3 ~106 ~1 ~4 ~106 glass  
fill ~1 ~3 ~107 ~1 ~4 ~107 glass  
fill ~1 ~3 ~108 ~1 ~4 ~108 glass  
fill ~10 ~3 ~82 ~10 ~3 ~88 wool  
fill ~10 ~3 ~106 ~10 ~3 ~112 wool  
fill ~11 ~3 ~20 ~11 ~3 ~26 wool  
fill ~11 ~3 ~44 ~11 ~3 ~50 wool  
fill ~11 ~3 ~78 ~18 ~3 ~78 wool  
fill ~11 ~3 ~79 ~11 ~3 ~81 wool  
fill ~11 ~3 ~82 ~19 ~3 ~82 iron_block  
fill ~11 ~3 ~83 ~19 ~3 ~83 iron_block  
fill ~11 ~3 ~84 ~19 ~3 ~84 iron_block  
fill ~11 ~3 ~85 ~19 ~3 ~85 iron_block  
fill ~11 ~3 ~86 ~19 ~3 ~86 iron_block  
fill ~11 ~3 ~87 ~19 ~3 ~87 iron_block  
fill ~11 ~3 ~88 ~19 ~3 ~88 iron_block 
setblock ~11 ~3 ~89 wool 15  
fill ~11 ~3 ~102 ~18 ~3 ~102 wool  
fill ~11 ~3 ~103 ~11 ~3 ~105 wool  
fill ~11 ~3 ~106 ~19 ~3 ~106 iron_block  
fill ~11 ~3 ~107 ~19 ~3 ~107 iron_block  
fill ~11 ~3 ~108 ~19 ~3 ~108 iron_block  
fill ~11 ~3 ~109 ~19 ~3 ~109 iron_block  
fill ~11 ~3 ~110 ~19 ~3 ~110 iron_block  
fill ~11 ~3 ~111 ~19 ~3 ~111 iron_block  
fill ~11 ~3 ~112 ~19 ~3 ~112 iron_block 
setblock ~11 ~3 ~113 wool 15 
setblock ~12 ~3 ~19 wool 15  
fill ~12 ~3 ~20 ~20 ~3 ~20 iron_block  
fill ~12 ~3 ~21 ~20 ~3 ~21 iron_block  
fill ~12 ~3 ~22 ~20 ~3 ~22 iron_block  
fill ~12 ~3 ~23 ~20 ~3 ~23 iron_block  
fill ~12 ~3 ~24 ~20 ~3 ~24 iron_block  
fill ~12 ~3 ~25 ~20 ~3 ~25 iron_block  
fill ~12 ~3 ~26 ~20 ~3 ~26 iron_block  
fill ~12 ~3 ~27 ~12 ~3 ~28 wool 
setblock ~12 ~3 ~43 wool 15  
fill ~12 ~3 ~44 ~20 ~3 ~44 iron_block  
fill ~12 ~3 ~45 ~20 ~3 ~45 iron_block  
fill ~12 ~3 ~46 ~20 ~3 ~46 iron_block  
fill ~12 ~3 ~47 ~20 ~3 ~47 iron_block  
fill ~12 ~3 ~48 ~20 ~3 ~48 iron_block  
fill ~12 ~3 ~49 ~20 ~3 ~49 iron_block  
fill ~12 ~3 ~50 ~20 ~3 ~50 iron_block  
fill ~12 ~3 ~51 ~12 ~3 ~52 wool  
fill ~12 ~3 ~79 ~17 ~3 ~79 iron_block  
fill ~12 ~3 ~80 ~18 ~3 ~80 iron_block  
fill ~12 ~3 ~81 ~18 ~3 ~81 iron_block  
fill ~12 ~3 ~89 ~18 ~3 ~89 iron_block  
fill ~12 ~3 ~90 ~12 ~3 ~91 wool  
fill ~12 ~3 ~103 ~17 ~3 ~103 iron_block  
fill ~12 ~3 ~104 ~18 ~3 ~104 iron_block  
fill ~12 ~3 ~105 ~18 ~3 ~105 iron_block  
fill ~12 ~3 ~113 ~18 ~3 ~113 iron_block  
fill ~12 ~3 ~114 ~12 ~3 ~115 wool  
fill ~13 ~3 ~17 ~13 ~3 ~18 wool  
fill ~13 ~3 ~19 ~19 ~3 ~19 iron_block  
fill ~13 ~3 ~27 ~19 ~3 ~27 iron_block  
fill ~13 ~3 ~28 ~19 ~3 ~28 iron_block  
fill ~13 ~3 ~29 ~13 ~3 ~30 wool  
fill ~13 ~3 ~41 ~13 ~3 ~42 wool  
fill ~13 ~3 ~43 ~19 ~3 ~43 iron_block  
fill ~13 ~3 ~51 ~19 ~3 ~51 iron_block  
fill ~13 ~3 ~52 ~19 ~3 ~52 iron_block  
fill ~13 ~3 ~53 ~13 ~3 ~54 wool  
fill ~13 ~3 ~77 ~17 ~3 ~77 double_stone_slab  
fill ~13 ~3 ~90 ~17 ~3 ~90 iron_block  
fill ~13 ~3 ~91 ~17 ~3 ~91 iron_block 
setblock ~13 ~3 ~92 wool 15  
fill ~13 ~3 ~101 ~17 ~3 ~101 double_stone_slab  
fill ~13 ~3 ~114 ~17 ~3 ~114 iron_block  
fill ~13 ~3 ~115 ~17 ~3 ~115 iron_block 
setblock ~13 ~3 ~116 wool 15 
setblock ~14 ~3 ~16 wool 15  
fill ~14 ~3 ~17 ~18 ~3 ~17 iron_block  
fill ~14 ~3 ~18 ~18 ~3 ~18 iron_block  
fill ~14 ~3 ~29 ~19 ~3 ~29 iron_block  
fill ~14 ~3 ~30 ~20 ~3 ~30 wool  
fill ~14 ~3 ~31 ~18 ~3 ~31 double_stone_slab 
setblock ~14 ~3 ~40 wool 15  
fill ~14 ~3 ~41 ~18 ~3 ~41 iron_block  
fill ~14 ~3 ~42 ~18 ~3 ~42 iron_block  
fill ~14 ~3 ~53 ~19 ~3 ~53 iron_block  
fill ~14 ~3 ~54 ~20 ~3 ~54 wool  
fill ~14 ~3 ~55 ~18 ~3 ~55 double_stone_slab 
setblock ~14 ~3 ~76 stone_slab 0  
fill ~14 ~3 ~92 ~16 ~3 ~92 iron_block  
fill ~14 ~3 ~93 ~16 ~3 ~93 wool 
setblock ~14 ~3 ~100 stone_slab 0  
fill ~14 ~3 ~116 ~16 ~3 ~116 iron_block  
fill ~14 ~3 ~117 ~16 ~3 ~117 wool  
fill ~15 ~3 ~15 ~17 ~3 ~15 wool  
fill ~15 ~3 ~16 ~17 ~3 ~16 iron_block 
setblock ~15 ~3 ~32 stone_slab 0  
fill ~15 ~3 ~39 ~17 ~3 ~39 wool  
fill ~15 ~3 ~40 ~17 ~3 ~40 iron_block 
setblock ~15 ~3 ~56 stone_slab 0 
setblock ~15 ~3 ~76 double_stone_slab 0 
setblock ~15 ~3 ~100 double_stone_slab 0 
setblock ~16 ~3 ~32 double_stone_slab 0 
setblock ~16 ~3 ~56 double_stone_slab 0 
setblock ~16 ~3 ~76 stone_slab 0 
setblock ~16 ~3 ~100 stone_slab 0 
setblock ~17 ~3 ~32 stone_slab 0 
setblock ~17 ~3 ~56 stone_slab 0 
setblock ~17 ~3 ~92 wool 15 
setblock ~17 ~3 ~116 wool 15 
setblock ~18 ~3 ~16 wool 15 
setblock ~18 ~3 ~40 wool 15 
setblock ~18 ~3 ~79 wool 15  
fill ~18 ~3 ~90 ~18 ~3 ~91 wool 
setblock ~18 ~3 ~103 wool 15  
fill ~18 ~3 ~114 ~18 ~3 ~115 wool  
fill ~19 ~3 ~17 ~19 ~3 ~18 wool  
fill ~19 ~3 ~41 ~19 ~3 ~42 wool  
fill ~19 ~3 ~80 ~19 ~3 ~81 wool 
setblock ~19 ~3 ~89 wool 15  
fill ~19 ~3 ~104 ~19 ~3 ~105 wool 
setblock ~19 ~3 ~113 wool 15 
setblock ~20 ~3 ~19 wool 15  
fill ~20 ~3 ~27 ~20 ~3 ~30 wool 
setblock ~20 ~3 ~43 wool 15  
fill ~20 ~3 ~51 ~20 ~3 ~54 wool  
fill ~20 ~3 ~82 ~20 ~3 ~88 wool  
fill ~20 ~3 ~106 ~20 ~3 ~112 wool  
fill ~21 ~3 ~20 ~21 ~3 ~26 wool  
fill ~21 ~3 ~44 ~21 ~3 ~50 wool  
fill ~35 ~3 ~6 ~35 ~3 ~7 wool 
setblock ~35 ~3 ~26 wool 11 
setblock ~35 ~3 ~106 wool 11  
fill ~35 ~3 ~125 ~35 ~3 ~126 wool  
fill ~36 ~3 ~6 ~42 ~3 ~6 iron_block  
fill ~36 ~3 ~7 ~42 ~3 ~7 iron_block  
fill ~36 ~3 ~8 ~42 ~3 ~8 iron_block  
fill ~36 ~3 ~9 ~42 ~3 ~9 iron_block  
fill ~36 ~3 ~10 ~42 ~3 ~10 iron_block  
fill ~36 ~3 ~11 ~42 ~3 ~11 iron_block  
fill ~36 ~3 ~12 ~42 ~3 ~12 iron_block  
fill ~36 ~3 ~13 ~42 ~3 ~13 iron_block  
fill ~36 ~3 ~14 ~42 ~3 ~14 iron_block  
fill ~36 ~3 ~15 ~42 ~3 ~15 iron_block  
fill ~36 ~3 ~16 ~42 ~3 ~16 iron_block  
fill ~36 ~3 ~17 ~42 ~3 ~17 iron_block  
fill ~36 ~3 ~18 ~42 ~3 ~18 iron_block  
fill ~36 ~3 ~19 ~42 ~3 ~19 iron_block  
fill ~36 ~3 ~20 ~42 ~3 ~20 iron_block  
fill ~36 ~3 ~21 ~42 ~3 ~21 iron_block  
fill ~36 ~3 ~22 ~42 ~3 ~22 iron_block  
fill ~36 ~3 ~23 ~42 ~3 ~23 iron_block  
fill ~36 ~3 ~24 ~42 ~3 ~24 iron_block  
fill ~36 ~3 ~25 ~42 ~3 ~25 iron_block 
setblock ~36 ~3 ~27 wool 11 
setblock ~36 ~3 ~105 wool 11  
fill ~36 ~3 ~106 ~36 ~3 ~126 iron_block  
fill ~37 ~3 ~107 ~42 ~3 ~107 iron_block  
fill ~37 ~3 ~108 ~42 ~3 ~108 iron_block  
fill ~37 ~3 ~109 ~42 ~3 ~109 iron_block  
fill ~37 ~3 ~110 ~42 ~3 ~110 iron_block  
fill ~37 ~3 ~111 ~42 ~3 ~111 iron_block  
fill ~37 ~3 ~112 ~42 ~3 ~112 iron_block  
fill ~37 ~3 ~113 ~42 ~3 ~113 iron_block  
fill ~37 ~3 ~114 ~42 ~3 ~114 iron_block  
fill ~37 ~3 ~115 ~42 ~3 ~115 iron_block  
fill ~37 ~3 ~116 ~42 ~3 ~116 iron_block  
fill ~37 ~3 ~117 ~42 ~3 ~117 iron_block  
fill ~37 ~3 ~118 ~42 ~3 ~118 iron_block  
fill ~37 ~3 ~119 ~42 ~3 ~119 iron_block  
fill ~37 ~3 ~120 ~42 ~3 ~120 iron_block  
fill ~37 ~3 ~121 ~42 ~3 ~121 iron_block  
fill ~37 ~3 ~122 ~42 ~3 ~122 iron_block  
fill ~37 ~3 ~123 ~42 ~3 ~123 iron_block  
fill ~37 ~3 ~124 ~42 ~3 ~124 iron_block  
fill ~37 ~3 ~125 ~42 ~3 ~125 iron_block  
fill ~37 ~3 ~126 ~42 ~3 ~126 iron_block 
setblock ~42 ~3 ~27 wool 11 
setblock ~42 ~3 ~105 wool 11 
setblock ~42 ~3 ~106 iron_block 0  
fill ~43 ~3 ~6 ~43 ~3 ~7 wool 
setblock ~43 ~3 ~26 wool 11 
setblock ~43 ~3 ~106 wool 11  
fill ~43 ~3 ~125 ~43 ~3 ~126 wool  
fill ~44 ~3 ~35 ~44 ~4 ~35 glass  
fill ~45 ~3 ~34 ~46 ~3 ~34 stone  
fill ~45 ~3 ~35 ~45 ~7 ~35 stone  
fill ~49 ~3 ~29 ~50 ~3 ~29 glass  
fill ~49 ~3 ~103 ~50 ~3 ~103 glass  
fill ~52 ~3 ~0 ~53 ~3 ~0 stone  
fill ~52 ~3 ~18 ~53 ~3 ~18 stone  
fill ~52 ~3 ~27 ~53 ~3 ~27 glass  
fill ~52 ~3 ~105 ~53 ~3 ~105 glass  
fill ~54 ~3 ~19 ~100 ~3 ~19 stone  
fill ~54 ~3 ~26 ~55 ~3 ~26 glass  
fill ~54 ~3 ~106 ~55 ~3 ~106 glass  
fill ~56 ~3 ~25 ~57 ~3 ~25 glass  
fill ~56 ~3 ~107 ~57 ~3 ~107 glass  
fill ~58 ~3 ~24 ~59 ~3 ~24 glass  
fill ~58 ~3 ~108 ~59 ~3 ~108 glass  
fill ~60 ~3 ~23 ~61 ~3 ~23 glass  
fill ~60 ~3 ~109 ~61 ~3 ~109 glass  
fill ~62 ~3 ~22 ~65 ~3 ~22 glass  
fill ~62 ~3 ~110 ~65 ~3 ~110 glass  
fill ~66 ~3 ~21 ~75 ~3 ~21 glass  
fill ~66 ~3 ~111 ~73 ~3 ~111 glass  
fill ~72 ~3 ~112 ~73 ~3 ~112 stone  
fill ~72 ~3 ~113 ~73 ~3 ~113 stone  
fill ~72 ~3 ~114 ~73 ~3 ~114 stone  
fill ~72 ~3 ~115 ~73 ~3 ~115 stone  
fill ~72 ~3 ~116 ~73 ~3 ~116 stone  
fill ~72 ~3 ~117 ~73 ~3 ~117 stone  
fill ~72 ~3 ~118 ~82 ~3 ~118 stone  
fill ~74 ~3 ~111 ~82 ~3 ~111 stone 
setblock ~74 ~3 ~112 redstone_wire 13 
setblock ~74 ~3 ~113 redstone_wire 14 
setblock ~74 ~3 ~114 redstone_wire 15 
setblock ~74 ~3 ~115 redstone_torch 5  
fill ~75 ~3 ~59 ~77 ~3 ~59 stone 
setblock ~75 ~3 ~112 redstone_wire 12  
fill ~75 ~3 ~119 ~79 ~3 ~119 stone  
fill ~76 ~3 ~20 ~79 ~3 ~20 stone  
fill ~76 ~3 ~60 ~76 ~3 ~63 stone_slab 
setblock ~76 ~3 ~64 glowstone 0 
setblock ~76 ~3 ~112 redstone_wire 11  
fill ~76 ~3 ~113 ~78 ~3 ~113 stone  
fill ~76 ~3 ~114 ~78 ~3 ~114 stone  
fill ~76 ~3 ~115 ~78 ~3 ~115 stone  
fill ~76 ~3 ~116 ~78 ~3 ~116 stone  
fill ~77 ~3 ~21 ~81 ~3 ~21 stone  
fill ~77 ~3 ~60 ~77 ~3 ~63 double_stone_slab 
setblock ~77 ~3 ~64 stone 0  
fill ~77 ~3 ~117 ~77 ~5 ~117 stone  
fill ~77 ~3 ~120 ~77 ~3 ~122 stone 
setblock ~80 ~3 ~20 double_stone_slab 0 
setblock ~81 ~3 ~20 stone 0  
fill ~81 ~3 ~112 ~82 ~3 ~112 stone  
fill ~81 ~3 ~113 ~82 ~3 ~113 stone  
fill ~81 ~3 ~114 ~82 ~3 ~114 stone  
fill ~81 ~3 ~115 ~82 ~3 ~115 stone  
fill ~81 ~3 ~116 ~82 ~3 ~116 stone  
fill ~81 ~3 ~117 ~82 ~3 ~117 stone  
fill ~82 ~3 ~21 ~88 ~3 ~21 glass  
fill ~83 ~3 ~111 ~88 ~3 ~111 glass  
fill ~89 ~3 ~22 ~92 ~3 ~22 glass  
fill ~89 ~3 ~110 ~92 ~3 ~110 glass  
fill ~93 ~3 ~23 ~94 ~3 ~23 glass  
fill ~93 ~3 ~109 ~94 ~3 ~109 glass  
fill ~95 ~3 ~24 ~96 ~3 ~24 glass  
fill ~95 ~3 ~108 ~96 ~3 ~108 glass  
fill ~97 ~3 ~25 ~98 ~3 ~25 glass  
fill ~97 ~3 ~107 ~98 ~3 ~107 glass  
fill ~99 ~3 ~26 ~100 ~3 ~26 glass  
fill ~99 ~3 ~106 ~100 ~3 ~106 glass  
fill ~101 ~3 ~27 ~102 ~3 ~27 glass  
fill ~101 ~3 ~105 ~102 ~3 ~105 glass  
fill ~104 ~3 ~29 ~105 ~3 ~29 glass  
fill ~104 ~3 ~103 ~105 ~3 ~103 glass  
fill ~108 ~3 ~34 ~110 ~3 ~34 stone  
fill ~109 ~3 ~35 ~109 ~7 ~35 stone  
fill ~110 ~3 ~35 ~110 ~4 ~35 glass  
fill ~111 ~3 ~6 ~111 ~3 ~7 wool 
setblock ~111 ~3 ~26 wool 11 
setblock ~111 ~3 ~106 wool 11  
fill ~111 ~3 ~125 ~111 ~3 ~126 wool  
fill ~112 ~3 ~6 ~118 ~3 ~6 iron_block  
fill ~112 ~3 ~7 ~118 ~3 ~7 iron_block  
fill ~112 ~3 ~8 ~118 ~3 ~8 iron_block  
fill ~112 ~3 ~9 ~118 ~3 ~9 iron_block  
fill ~112 ~3 ~10 ~118 ~3 ~10 iron_block  
fill ~112 ~3 ~11 ~118 ~3 ~11 iron_block  
fill ~112 ~3 ~12 ~118 ~3 ~12 iron_block  
fill ~112 ~3 ~13 ~118 ~3 ~13 iron_block  
fill ~112 ~3 ~14 ~118 ~3 ~14 iron_block  
fill ~112 ~3 ~15 ~118 ~3 ~15 iron_block  
fill ~112 ~3 ~16 ~118 ~3 ~16 iron_block  
fill ~112 ~3 ~17 ~118 ~3 ~17 iron_block  
fill ~112 ~3 ~18 ~118 ~3 ~18 iron_block  
fill ~112 ~3 ~19 ~118 ~3 ~19 iron_block  
fill ~112 ~3 ~20 ~118 ~3 ~20 iron_block  
fill ~112 ~3 ~21 ~118 ~3 ~21 iron_block  
fill ~112 ~3 ~22 ~118 ~3 ~22 iron_block  
fill ~112 ~3 ~23 ~118 ~3 ~23 iron_block  
fill ~112 ~3 ~24 ~118 ~3 ~24 iron_block  
fill ~112 ~3 ~25 ~118 ~3 ~25 iron_block 
setblock ~112 ~3 ~27 wool 11 
setblock ~112 ~3 ~105 wool 11  
fill ~112 ~3 ~106 ~112 ~3 ~126 iron_block  
fill ~113 ~3 ~107 ~118 ~3 ~107 iron_block  
fill ~113 ~3 ~108 ~118 ~3 ~108 iron_block  
fill ~113 ~3 ~109 ~118 ~3 ~109 iron_block  
fill ~113 ~3 ~110 ~118 ~3 ~110 iron_block  
fill ~113 ~3 ~111 ~118 ~3 ~111 iron_block  
fill ~113 ~3 ~112 ~118 ~3 ~112 iron_block  
fill ~113 ~3 ~113 ~118 ~3 ~113 iron_block  
fill ~113 ~3 ~114 ~118 ~3 ~114 iron_block  
fill ~113 ~3 ~115 ~118 ~3 ~115 iron_block  
fill ~113 ~3 ~116 ~118 ~3 ~116 iron_block  
fill ~113 ~3 ~117 ~118 ~3 ~117 iron_block  
fill ~113 ~3 ~118 ~118 ~3 ~118 iron_block  
fill ~113 ~3 ~119 ~118 ~3 ~119 iron_block  
fill ~113 ~3 ~120 ~118 ~3 ~120 iron_block  
fill ~113 ~3 ~121 ~118 ~3 ~121 iron_block  
fill ~113 ~3 ~122 ~118 ~3 ~122 iron_block  
fill ~113 ~3 ~123 ~118 ~3 ~123 iron_block  
fill ~113 ~3 ~124 ~118 ~3 ~124 iron_block  
fill ~113 ~3 ~125 ~118 ~3 ~125 iron_block  
fill ~113 ~3 ~126 ~118 ~3 ~126 iron_block 
setblock ~118 ~3 ~27 wool 11 
setblock ~118 ~3 ~105 wool 11 
setblock ~118 ~3 ~106 iron_block 0  
fill ~119 ~3 ~6 ~119 ~3 ~7 wool 
setblock ~119 ~3 ~26 wool 11 
setblock ~119 ~3 ~106 wool 11  
fill ~119 ~3 ~125 ~119 ~3 ~126 wool  
fill ~133 ~3 ~20 ~133 ~3 ~26 wool  
fill ~133 ~3 ~44 ~133 ~3 ~50 wool 
setblock ~134 ~3 ~19 wool 15  
fill ~134 ~3 ~20 ~142 ~3 ~20 iron_block  
fill ~134 ~3 ~21 ~142 ~3 ~21 iron_block  
fill ~134 ~3 ~22 ~142 ~3 ~22 iron_block  
fill ~134 ~3 ~23 ~142 ~3 ~23 iron_block  
fill ~134 ~3 ~24 ~142 ~3 ~24 iron_block  
fill ~134 ~3 ~25 ~142 ~3 ~25 iron_block  
fill ~134 ~3 ~26 ~142 ~3 ~26 iron_block  
fill ~134 ~3 ~27 ~134 ~3 ~30 wool 
setblock ~134 ~3 ~43 wool 15  
fill ~134 ~3 ~44 ~142 ~3 ~44 iron_block  
fill ~134 ~3 ~45 ~142 ~3 ~45 iron_block  
fill ~134 ~3 ~46 ~142 ~3 ~46 iron_block  
fill ~134 ~3 ~47 ~142 ~3 ~47 iron_block  
fill ~134 ~3 ~48 ~142 ~3 ~48 iron_block  
fill ~134 ~3 ~49 ~142 ~3 ~49 iron_block  
fill ~134 ~3 ~50 ~142 ~3 ~50 iron_block  
fill ~134 ~3 ~51 ~134 ~3 ~54 wool  
fill ~134 ~3 ~82 ~134 ~3 ~88 wool  
fill ~134 ~3 ~106 ~134 ~3 ~112 wool  
fill ~135 ~3 ~17 ~135 ~3 ~18 wool  
fill ~135 ~3 ~19 ~141 ~3 ~19 iron_block  
fill ~135 ~3 ~27 ~141 ~3 ~27 iron_block  
fill ~135 ~3 ~28 ~141 ~3 ~28 iron_block  
fill ~135 ~3 ~29 ~140 ~3 ~29 iron_block  
fill ~135 ~3 ~30 ~141 ~3 ~30 wool  
fill ~135 ~3 ~41 ~135 ~3 ~42 wool  
fill ~135 ~3 ~43 ~141 ~3 ~43 iron_block  
fill ~135 ~3 ~51 ~141 ~3 ~51 iron_block  
fill ~135 ~3 ~52 ~141 ~3 ~52 iron_block  
fill ~135 ~3 ~53 ~140 ~3 ~53 iron_block  
fill ~135 ~3 ~54 ~141 ~3 ~54 wool  
fill ~135 ~3 ~80 ~135 ~3 ~81 wool  
fill ~135 ~3 ~82 ~143 ~3 ~82 iron_block  
fill ~135 ~3 ~83 ~143 ~3 ~83 iron_block  
fill ~135 ~3 ~84 ~143 ~3 ~84 iron_block  
fill ~135 ~3 ~85 ~143 ~3 ~85 iron_block  
fill ~135 ~3 ~86 ~143 ~3 ~86 iron_block  
fill ~135 ~3 ~87 ~143 ~3 ~87 iron_block  
fill ~135 ~3 ~88 ~143 ~3 ~88 iron_block 
setblock ~135 ~3 ~89 wool 15  
fill ~135 ~3 ~104 ~135 ~3 ~105 wool  
fill ~135 ~3 ~106 ~143 ~3 ~106 iron_block  
fill ~135 ~3 ~107 ~143 ~3 ~107 iron_block  
fill ~135 ~3 ~108 ~143 ~3 ~108 iron_block  
fill ~135 ~3 ~109 ~143 ~3 ~109 iron_block  
fill ~135 ~3 ~110 ~143 ~3 ~110 iron_block  
fill ~135 ~3 ~111 ~143 ~3 ~111 iron_block  
fill ~135 ~3 ~112 ~143 ~3 ~112 iron_block 
setblock ~135 ~3 ~113 wool 15 
setblock ~136 ~3 ~16 wool 15  
fill ~136 ~3 ~17 ~140 ~3 ~17 iron_block  
fill ~136 ~3 ~18 ~140 ~3 ~18 iron_block  
fill ~136 ~3 ~31 ~140 ~3 ~31 double_stone_slab 
setblock ~136 ~3 ~40 wool 15  
fill ~136 ~3 ~41 ~140 ~3 ~41 iron_block  
fill ~136 ~3 ~42 ~140 ~3 ~42 iron_block  
fill ~136 ~3 ~55 ~140 ~3 ~55 double_stone_slab  
fill ~136 ~3 ~78 ~143 ~3 ~78 wool  
fill ~136 ~3 ~79 ~136 ~3 ~78 wool  
fill ~136 ~3 ~80 ~142 ~3 ~80 iron_block  
fill ~136 ~3 ~81 ~142 ~3 ~81 iron_block  
fill ~136 ~3 ~89 ~142 ~3 ~89 iron_block  
fill ~136 ~3 ~90 ~136 ~3 ~91 wool  
fill ~136 ~3 ~102 ~143 ~3 ~102 wool  
fill ~136 ~3 ~103 ~136 ~3 ~102 wool  
fill ~136 ~3 ~104 ~142 ~3 ~104 iron_block  
fill ~136 ~3 ~105 ~142 ~3 ~105 iron_block  
fill ~136 ~3 ~113 ~142 ~3 ~113 iron_block  
fill ~136 ~3 ~114 ~136 ~3 ~115 wool  
fill ~137 ~3 ~15 ~139 ~3 ~15 wool  
fill ~137 ~3 ~16 ~139 ~3 ~16 iron_block 
setblock ~137 ~3 ~32 stone_slab 0  
fill ~137 ~3 ~39 ~139 ~3 ~39 wool  
fill ~137 ~3 ~40 ~139 ~3 ~40 iron_block 
setblock ~137 ~3 ~56 stone_slab 0  
fill ~137 ~3 ~77 ~141 ~3 ~77 double_stone_slab  
fill ~137 ~3 ~79 ~142 ~3 ~79 iron_block  
fill ~137 ~3 ~90 ~141 ~3 ~90 iron_block  
fill ~137 ~3 ~91 ~141 ~3 ~91 iron_block 
setblock ~137 ~3 ~92 wool 15  
fill ~137 ~3 ~101 ~141 ~3 ~101 double_stone_slab  
fill ~137 ~3 ~103 ~142 ~3 ~103 iron_block  
fill ~137 ~3 ~114 ~141 ~3 ~114 iron_block  
fill ~137 ~3 ~115 ~141 ~3 ~115 iron_block 
setblock ~137 ~3 ~116 wool 15 
setblock ~138 ~3 ~32 double_stone_slab 0 
setblock ~138 ~3 ~56 double_stone_slab 0 
setblock ~138 ~3 ~76 stone_slab 0  
fill ~138 ~3 ~92 ~140 ~3 ~92 iron_block  
fill ~138 ~3 ~93 ~140 ~3 ~93 wool 
setblock ~138 ~3 ~100 stone_slab 0  
fill ~138 ~3 ~116 ~140 ~3 ~116 iron_block  
fill ~138 ~3 ~117 ~140 ~3 ~117 wool 
setblock ~139 ~3 ~32 stone_slab 0 
setblock ~139 ~3 ~56 stone_slab 0 
setblock ~139 ~3 ~76 double_stone_slab 0 
setblock ~139 ~3 ~100 double_stone_slab 0 
setblock ~140 ~3 ~16 wool 15 
setblock ~140 ~3 ~40 wool 15 
setblock ~140 ~3 ~76 stone_slab 0 
setblock ~140 ~3 ~100 stone_slab 0  
fill ~141 ~3 ~17 ~141 ~3 ~18 wool 
setblock ~141 ~3 ~29 wool 15  
fill ~141 ~3 ~41 ~141 ~3 ~42 wool 
setblock ~141 ~3 ~53 wool 15 
setblock ~141 ~3 ~92 wool 15 
setblock ~141 ~3 ~116 wool 15 
setblock ~142 ~3 ~19 wool 15  
fill ~142 ~3 ~27 ~142 ~3 ~28 wool 
setblock ~142 ~3 ~43 wool 15  
fill ~142 ~3 ~51 ~142 ~3 ~52 wool  
fill ~142 ~3 ~90 ~142 ~3 ~91 wool  
fill ~142 ~3 ~114 ~142 ~3 ~115 wool  
fill ~143 ~3 ~20 ~143 ~3 ~26 wool  
fill ~143 ~3 ~44 ~143 ~3 ~50 wool  
fill ~143 ~3 ~79 ~143 ~3 ~81 wool 
setblock ~143 ~3 ~89 wool 15  
fill ~143 ~3 ~103 ~143 ~3 ~105 wool 
setblock ~143 ~3 ~113 wool 15  
fill ~144 ~3 ~82 ~144 ~3 ~88 wool  
fill ~144 ~3 ~106 ~144 ~3 ~112 wool  
fill ~153 ~3 ~24 ~153 ~4 ~24 glass  
fill ~153 ~3 ~25 ~153 ~4 ~25 glass  
fill ~153 ~3 ~26 ~153 ~4 ~26 glass  
fill ~153 ~3 ~27 ~153 ~4 ~27 glass  
fill ~153 ~3 ~28 ~153 ~4 ~28 glass  
fill ~153 ~3 ~29 ~153 ~4 ~29 glass  
fill ~153 ~3 ~30 ~153 ~4 ~30 glass  
fill ~153 ~3 ~35 ~153 ~4 ~35 glass  
fill ~153 ~3 ~36 ~153 ~4 ~36 glass  
fill ~153 ~3 ~37 ~153 ~4 ~37 glass  
fill ~153 ~3 ~38 ~153 ~4 ~38 glass  
fill ~153 ~3 ~39 ~153 ~4 ~39 glass  
fill ~153 ~3 ~40 ~153 ~4 ~40 glass    
fill ~153 ~3 ~41 ~153 ~4 ~41 glass  
fill ~153 ~3 ~46 ~153 ~4 ~46 glass  
fill ~153 ~3 ~47 ~153 ~4 ~47 glass  
fill ~153 ~3 ~48 ~153 ~4 ~48 glass  
fill ~153 ~3 ~49 ~153 ~4 ~49 glass  
fill ~153 ~3 ~50 ~153 ~4 ~50 glass  
fill ~153 ~3 ~51 ~153 ~4 ~51 glass  
fill ~153 ~3 ~52 ~153 ~4 ~52 glass  
fill ~153 ~3 ~57 ~153 ~4 ~57 glass  
fill ~153 ~3 ~58 ~153 ~4 ~58 glass  
fill ~153 ~3 ~59 ~153 ~4 ~59 glass  
fill ~153 ~3 ~60 ~153 ~4 ~60 glass  
fill ~153 ~3 ~61 ~153 ~4 ~61 glass  
fill ~153 ~3 ~62 ~153 ~4 ~62 glass  
fill ~153 ~3 ~63 ~153 ~4 ~63 glass  
fill ~153 ~3 ~69 ~153 ~4 ~69 glass  
fill ~153 ~3 ~70 ~153 ~4 ~70 glass  
fill ~153 ~3 ~71 ~153 ~4 ~71 glass  
fill ~153 ~3 ~72 ~153 ~4 ~72 glass  
fill ~153 ~3 ~73 ~153 ~4 ~73 glass  
fill ~153 ~3 ~74 ~153 ~4 ~74 glass  
fill ~153 ~3 ~75 ~153 ~4 ~75 glass  
fill ~153 ~3 ~80 ~153 ~4 ~80 glass  
fill ~153 ~3 ~81 ~153 ~4 ~81 glass  
fill ~153 ~3 ~82 ~153 ~4 ~82 glass  
fill ~153 ~3 ~83 ~153 ~4 ~83 glass  
fill ~153 ~3 ~84 ~153 ~4 ~84 glass  
fill ~153 ~3 ~85 ~153 ~4 ~85 glass  
fill ~153 ~3 ~86 ~153 ~4 ~86 glass  
fill ~153 ~3 ~91 ~153 ~4 ~91 glass  
fill ~153 ~3 ~92 ~153 ~4 ~92 glass  
fill ~153 ~3 ~93 ~153 ~4 ~93 glass  
fill ~153 ~3 ~94 ~153 ~4 ~94 glass  
fill ~153 ~3 ~95 ~153 ~4 ~95 glass  
fill ~153 ~3 ~96 ~153 ~4 ~96 glass  
fill ~153 ~3 ~97 ~153 ~4 ~97 glass  
fill ~153 ~3 ~102 ~153 ~4 ~102 glass  
fill ~153 ~3 ~103 ~153 ~4 ~103 glass  
fill ~153 ~3 ~104 ~153 ~4 ~104 glass  
fill ~153 ~3 ~105 ~153 ~4 ~105 glass  
fill ~153 ~3 ~106 ~153 ~4 ~106 glass  
fill ~153 ~3 ~107 ~153 ~4 ~107 glass  
fill ~153 ~3 ~108 ~153 ~4 ~108 glass  
fill ~10 ~4 ~82 ~10 ~4 ~88 iron_block  
fill ~10 ~4 ~106 ~10 ~4 ~112 iron_block  
fill ~11 ~4 ~20 ~11 ~4 ~26 iron_block  
fill ~11 ~4 ~44 ~11 ~4 ~50 iron_block  
fill ~11 ~4 ~80 ~11 ~4 ~81 iron_block 
setblock ~11 ~4 ~82 glowstone 0 
setblock ~11 ~4 ~88 glowstone 0 
setblock ~11 ~4 ~89 iron_block 0  
fill ~11 ~4 ~104 ~11 ~4 ~105 iron_block 
setblock ~11 ~4 ~106 glowstone 0 
setblock ~11 ~4 ~112 glowstone 0 
setblock ~11 ~4 ~113 iron_block 0 
setblock ~12 ~4 ~19 iron_block 0 
setblock ~12 ~4 ~20 glowstone 0 
setblock ~12 ~4 ~26 glowstone 0  
fill ~12 ~4 ~27 ~12 ~4 ~28 iron_block 
setblock ~12 ~4 ~43 iron_block 0 
setblock ~12 ~4 ~44 glowstone 0 
setblock ~12 ~4 ~50 glowstone 0  
fill ~12 ~4 ~51 ~12 ~4 ~52 iron_block  
fill ~12 ~4 ~78 ~18 ~4 ~78 iron_block  
fill ~12 ~4 ~79 ~12 ~3 ~79 iron_block  
fill ~12 ~4 ~90 ~12 ~4 ~91 iron_block  
fill ~12 ~4 ~102 ~18 ~4 ~102 iron_block  
fill ~12 ~4 ~103 ~12 ~3 ~103 iron_block  
fill ~12 ~4 ~114 ~12 ~4 ~115 iron_block  
fill ~13 ~4 ~17 ~13 ~4 ~18 iron_block  
fill ~13 ~4 ~29 ~13 ~4 ~30 iron_block  
fill ~13 ~4 ~41 ~13 ~4 ~42 iron_block  
fill ~13 ~4 ~53 ~13 ~4 ~54 iron_block  
fill ~13 ~4 ~77 ~13 ~3 ~77 double_stone_slab 
setblock ~13 ~4 ~91 stone 0 
setblock ~13 ~4 ~92 iron_block 0  
fill ~13 ~4 ~101 ~13 ~3 ~101 double_stone_slab 
setblock ~13 ~4 ~115 stone 0 
setblock ~13 ~4 ~116 iron_block 0 
setblock ~14 ~4 ~16 iron_block 0 
setblock ~14 ~4 ~17 stone 0  
fill ~14 ~4 ~30 ~19 ~4 ~30 iron_block  
fill ~14 ~4 ~31 ~14 ~3 ~31 double_stone_slab 
setblock ~14 ~4 ~40 iron_block 0 
setblock ~14 ~4 ~41 stone 0  
fill ~14 ~4 ~54 ~19 ~4 ~54 iron_block  
fill ~14 ~4 ~55 ~14 ~3 ~55 double_stone_slab 
setblock ~14 ~4 ~76 double_stone_slab 0 
setblock ~14 ~4 ~91 lever 4  
fill ~14 ~4 ~92 ~16 ~4 ~92 stone  
fill ~14 ~4 ~93 ~16 ~4 ~93 iron_block 
setblock ~14 ~4 ~100 double_stone_slab 0 
setblock ~14 ~4 ~115 lever 4  
fill ~14 ~4 ~116 ~16 ~4 ~116 stone  
fill ~14 ~4 ~117 ~16 ~4 ~117 iron_block  
fill ~15 ~4 ~15 ~17 ~4 ~15 iron_block  
fill ~15 ~4 ~16 ~17 ~4 ~16 stone 
setblock ~15 ~4 ~17 lever 3 
setblock ~15 ~4 ~32 double_stone_slab 0  
fill ~15 ~4 ~39 ~17 ~4 ~39 iron_block  
fill ~15 ~4 ~40 ~17 ~4 ~40 stone 
setblock ~15 ~4 ~41 lever 3 
setblock ~15 ~4 ~56 double_stone_slab 0 
setblock ~15 ~4 ~77 redstone_ore 0  
fill ~15 ~4 ~81 ~15 ~5 ~81 ladder  
fill ~15 ~4 ~82 ~15 ~6 ~82 iron_block 
setblock ~15 ~4 ~89 double_stone_slab 2 
setblock ~15 ~4 ~90 stone_slab 2 
setblock ~15 ~4 ~101 redstone_ore 0  
fill ~15 ~4 ~105 ~15 ~5 ~105 ladder  
fill ~15 ~4 ~106 ~15 ~6 ~106 iron_block 
setblock ~15 ~4 ~113 double_stone_slab 2 
setblock ~15 ~4 ~114 stone_slab 2 
setblock ~16 ~4 ~18 stone_slab 2 
setblock ~16 ~4 ~19 double_stone_slab 2  
fill ~16 ~4 ~26 ~16 ~6 ~26 iron_block  
fill ~16 ~4 ~27 ~16 ~5 ~27 ladder 
setblock ~16 ~4 ~31 redstone_ore 0 
setblock ~16 ~4 ~42 stone_slab 2 
setblock ~16 ~4 ~43 double_stone_slab 2  
fill ~16 ~4 ~50 ~16 ~6 ~50 iron_block  
fill ~16 ~4 ~51 ~16 ~5 ~51 ladder 
setblock ~16 ~4 ~55 redstone_ore 0 
setblock ~16 ~4 ~76 double_stone_slab 0 
setblock ~16 ~4 ~91 lever 4 
