setblock ~8 ~97 ~38 furnace 5  
setblock ~8 ~98 ~38 furnace 5  
setblock ~8 ~99 ~38 furnace 5  
setblock ~8 ~97 ~39 furnace 5  
setblock ~8 ~97 ~40 furnace 5  
setblock ~8 ~98 ~39 furnace 5  
setblock ~8 ~98 ~40 furnace 5  
setblock ~8 ~99 ~39 furnace 5  
setblock ~8 ~99 ~40 furnace 5  
setblock ~6 ~122 ~55 furnace 3  
setblock ~6 ~122 ~56 furnace 3  
setblock ~6 ~122 ~57 furnace 3  
setblock ~7 ~122 ~58 furnace 5  
setblock ~29 ~103 ~62 furnace 5  
setblock ~29 ~103 ~63 furnace 5  
setblock ~29 ~103 ~64 furnace 5  
setblock ~29 ~103 ~65 furnace 5  
setblock ~29 ~103 ~66 furnace 5  
setblock ~29 ~103 ~67 furnace 5 
setblock ~1 ~0 ~18 double_stone_slab 14 
setblock ~1 ~0 ~19 leaves 12 
setblock ~1 ~0 ~20 double_stone_slab 14 
setblock ~1 ~0 ~21 leaves 12 
setblock ~1 ~0 ~22 double_stone_slab 14 
setblock ~1 ~0 ~23 leaves 12  
fill ~1 ~0 ~24 ~1 ~0 ~27 double_stone_slab 14  
fill ~1 ~0 ~28 ~36 ~0 ~28 cobblestone 0  
fill ~1 ~0 ~29 ~36 ~0 ~29 cobblestone 0  
fill ~1 ~0 ~30 ~36 ~0 ~30 cobblestone 0  
fill ~1 ~0 ~31 ~36 ~0 ~31 cobblestone 0  
fill ~1 ~0 ~32 ~4 ~0 ~32 cobblestone 0  
fill ~1 ~0 ~33 ~4 ~0 ~33 double_stone_slab 3  
fill ~1 ~0 ~34 ~4 ~0 ~34 double_stone_slab 3  
fill ~1 ~0 ~35 ~4 ~0 ~35 double_stone_slab 3  
fill ~1 ~0 ~36 ~4 ~0 ~36 double_stone_slab 3  
fill ~1 ~0 ~37 ~4 ~0 ~37 double_stone_slab 3  
fill ~1 ~0 ~38 ~4 ~0 ~38 double_stone_slab 3  
fill ~1 ~0 ~39 ~4 ~0 ~39 double_stone_slab 3  
fill ~1 ~0 ~40 ~4 ~0 ~40 double_stone_slab 3  
fill ~1 ~0 ~41 ~4 ~0 ~41 double_stone_slab 3  
fill ~1 ~0 ~42 ~4 ~0 ~42 double_stone_slab 3  
fill ~1 ~0 ~43 ~4 ~0 ~43 double_stone_slab 3  
fill ~1 ~0 ~44 ~4 ~0 ~44 double_stone_slab 3  
fill ~1 ~0 ~45 ~4 ~0 ~45 double_stone_slab 3  
fill ~1 ~0 ~46 ~4 ~0 ~46 double_stone_slab 3  
fill ~1 ~0 ~47 ~4 ~0 ~47 double_stone_slab 3  
fill ~1 ~0 ~48 ~3 ~0 ~48 double_stone_slab 3  
fill ~1 ~0 ~49 ~3 ~0 ~49 double_stone_slab 3  
fill ~1 ~0 ~50 ~3 ~0 ~50 double_stone_slab 3  
fill ~1 ~0 ~51 ~3 ~0 ~51 double_stone_slab 3  
fill ~1 ~0 ~52 ~2 ~0 ~52 double_stone_slab 3  
fill ~1 ~0 ~53 ~2 ~0 ~53 double_stone_slab 3  
fill ~1 ~0 ~54 ~2 ~0 ~54 double_stone_slab 3  
fill ~1 ~0 ~55 ~2 ~0 ~55 double_stone_slab 3  
fill ~1 ~0 ~56 ~2 ~0 ~56 double_stone_slab 3  
fill ~1 ~0 ~57 ~2 ~0 ~57 double_stone_slab 3  
fill ~1 ~0 ~58 ~3 ~0 ~58 double_stone_slab 3  
fill ~1 ~0 ~59 ~3 ~0 ~59 double_stone_slab 3  
fill ~1 ~0 ~60 ~3 ~0 ~60 double_stone_slab 3  
fill ~1 ~0 ~61 ~3 ~0 ~61 double_stone_slab 3  
fill ~1 ~0 ~62 ~4 ~0 ~62 double_stone_slab 3  
fill ~1 ~0 ~63 ~4 ~0 ~63 double_stone_slab 3  
fill ~1 ~0 ~64 ~4 ~0 ~64 double_stone_slab 3  
fill ~1 ~0 ~65 ~4 ~0 ~65 double_stone_slab 3  
fill ~1 ~0 ~66 ~5 ~0 ~66 double_stone_slab 3  
fill ~1 ~0 ~67 ~5 ~0 ~67 double_stone_slab 3  
fill ~1 ~0 ~68 ~5 ~0 ~68 double_stone_slab 3  
fill ~1 ~0 ~69 ~3 ~0 ~69 double_stone_slab 14  
fill ~1 ~0 ~70 ~8 ~0 ~70 double_stone_slab 14  
fill ~1 ~0 ~71 ~8 ~0 ~71 double_stone_slab 14  
fill ~1 ~0 ~72 ~8 ~0 ~72 double_stone_slab 14  
fill ~2 ~0 ~26 ~5 ~0 ~26 stone_slab 3  
fill ~2 ~0 ~27 ~5 ~0 ~27 stone_slab 11  
fill ~3 ~0 ~52 ~8 ~0 ~52 stone 0  
fill ~3 ~0 ~53 ~8 ~0 ~53 stone 0  
fill ~3 ~0 ~54 ~8 ~0 ~54 stone 0  
fill ~3 ~0 ~55 ~8 ~0 ~55 stone 0  
fill ~3 ~0 ~56 ~8 ~0 ~56 stone 0  
fill ~3 ~0 ~57 ~8 ~0 ~57 stone 0  
fill ~4 ~0 ~48 ~8 ~0 ~48 stone 0  
fill ~4 ~0 ~49 ~8 ~0 ~49 stone 0  
fill ~4 ~0 ~50 ~8 ~0 ~50 stone 0  
fill ~4 ~0 ~51 ~8 ~0 ~51 stone 0  
fill ~4 ~0 ~58 ~8 ~0 ~58 stone 0  
fill ~4 ~0 ~59 ~8 ~0 ~59 stone 0  
fill ~4 ~0 ~60 ~8 ~0 ~60 stone 0  
fill ~4 ~0 ~61 ~8 ~0 ~61 stone 0 
setblock ~4 ~0 ~69 double_stone_slab 0  
fill ~5 ~0 ~32 ~9 ~0 ~32 double_stone_slab 14  
fill ~5 ~0 ~33 ~8 ~0 ~33 stone 0  
fill ~5 ~0 ~34 ~8 ~0 ~34 stone 0  
fill ~5 ~0 ~35 ~8 ~0 ~35 stone 0  
fill ~5 ~0 ~36 ~8 ~0 ~36 stone 0  
fill ~5 ~0 ~37 ~8 ~0 ~37 stone 0  
fill ~5 ~0 ~38 ~8 ~0 ~38 stone 0  
fill ~5 ~0 ~39 ~8 ~0 ~39 stone 0  
fill ~5 ~0 ~40 ~8 ~0 ~40 stone 0  
fill ~5 ~0 ~41 ~8 ~0 ~41 stone 0  
fill ~5 ~0 ~42 ~8 ~0 ~42 stone 0  
fill ~5 ~0 ~43 ~8 ~0 ~43 stone 0  
fill ~5 ~0 ~44 ~8 ~0 ~44 stone 0  
fill ~5 ~0 ~45 ~8 ~0 ~45 stone 0  
fill ~5 ~0 ~46 ~8 ~0 ~46 stone 0  
fill ~5 ~0 ~47 ~8 ~0 ~47 stone 0  
fill ~5 ~0 ~62 ~8 ~0 ~62 stone 0  
fill ~5 ~0 ~63 ~8 ~0 ~63 stone 0  
fill ~5 ~0 ~64 ~8 ~0 ~64 stone 0  
fill ~5 ~0 ~65 ~8 ~0 ~65 stone 0  
fill ~5 ~0 ~69 ~8 ~0 ~69 double_stone_slab 14  
fill ~6 ~0 ~17 ~42 ~0 ~17 double_stone_slab 14  
fill ~6 ~0 ~18 ~6 ~0 ~17 double_stone_slab 14 
setblock ~6 ~0 ~19 leaves 12 
setblock ~6 ~0 ~20 double_stone_slab 14 
setblock ~6 ~0 ~21 leaves 12 
setblock ~6 ~0 ~22 double_stone_slab 14 
setblock ~6 ~0 ~23 leaves 12  
fill ~6 ~0 ~24 ~43 ~0 ~24 double_stone_slab 14  
fill ~6 ~0 ~25 ~32 ~0 ~25 double_stone_slab 14  
fill ~6 ~0 ~26 ~31 ~0 ~26 double_stone_slab 14  
fill ~6 ~0 ~27 ~31 ~0 ~27 double_stone_slab 14  
fill ~6 ~0 ~66 ~8 ~0 ~66 stone 0  
fill ~6 ~0 ~67 ~8 ~0 ~67 stone 0  
fill ~6 ~0 ~68 ~8 ~0 ~68 stone 0 
setblock ~7 ~0 ~18 leaves 12  
fill ~7 ~0 ~19 ~7 ~0 ~21 grass 0  
fill ~7 ~0 ~22 ~8 ~0 ~22 glowstone 0  
fill ~7 ~0 ~23 ~42 ~0 ~23 double_stone_slab 14  
fill ~8 ~0 ~16 ~42 ~0 ~16 double_stone_slab 14  
fill ~8 ~0 ~18 ~43 ~0 ~18 double_stone_slab 14 
setblock ~8 ~0 ~19 glowstone 0 
setblock ~8 ~0 ~20 sand 0 
setblock ~8 ~0 ~21 grass 0  
fill ~9 ~0 ~19 ~10 ~0 ~19 dirt 0  
fill ~9 ~0 ~21 ~9 ~0 ~22 dirt 0  
fill ~9 ~0 ~33 ~43 ~0 ~33 cobblestone 0  
fill ~9 ~0 ~34 ~43 ~0 ~34 cobblestone 0  
fill ~9 ~0 ~35 ~43 ~0 ~35 cobblestone 0  
fill ~9 ~0 ~36 ~43 ~0 ~36 cobblestone 0  
fill ~9 ~0 ~37 ~43 ~0 ~37 cobblestone 0  
fill ~9 ~0 ~38 ~43 ~0 ~38 cobblestone 0  
fill ~9 ~0 ~39 ~43 ~0 ~39 cobblestone 0  
fill ~9 ~0 ~40 ~43 ~0 ~40 cobblestone 0  
fill ~9 ~0 ~41 ~43 ~0 ~41 cobblestone 0  
fill ~9 ~0 ~42 ~43 ~0 ~42 cobblestone 0  
fill ~9 ~0 ~43 ~43 ~0 ~43 cobblestone 0  
fill ~9 ~0 ~44 ~43 ~0 ~44 cobblestone 0  
fill ~9 ~0 ~45 ~43 ~0 ~45 cobblestone 0  
fill ~9 ~0 ~46 ~43 ~0 ~46 cobblestone 0  
fill ~9 ~0 ~47 ~43 ~0 ~47 cobblestone 0  
fill ~9 ~0 ~48 ~43 ~0 ~48 cobblestone 0  
fill ~9 ~0 ~49 ~43 ~0 ~49 cobblestone 0  
fill ~9 ~0 ~50 ~43 ~0 ~50 cobblestone 0  
fill ~9 ~0 ~51 ~43 ~0 ~51 cobblestone 0  
fill ~9 ~0 ~52 ~43 ~0 ~52 cobblestone 0  
fill ~9 ~0 ~53 ~43 ~0 ~53 cobblestone 0  
fill ~9 ~0 ~54 ~43 ~0 ~54 cobblestone 0  
fill ~9 ~0 ~55 ~43 ~0 ~55 cobblestone 0  
fill ~9 ~0 ~56 ~43 ~0 ~56 cobblestone 0  
fill ~9 ~0 ~57 ~43 ~0 ~57 cobblestone 0  
fill ~9 ~0 ~58 ~43 ~0 ~58 cobblestone 0  
fill ~9 ~0 ~59 ~43 ~0 ~59 cobblestone 0  
fill ~9 ~0 ~60 ~43 ~0 ~60 cobblestone 0  
fill ~9 ~0 ~61 ~43 ~0 ~61 cobblestone 0  
fill ~9 ~0 ~62 ~43 ~0 ~62 cobblestone 0  
fill ~9 ~0 ~63 ~43 ~0 ~63 cobblestone 0  
fill ~9 ~0 ~64 ~43 ~0 ~64 cobblestone 0  
fill ~9 ~0 ~65 ~43 ~0 ~65 cobblestone 0  
fill ~9 ~0 ~66 ~43 ~0 ~66 cobblestone 0  
fill ~9 ~0 ~67 ~43 ~0 ~67 cobblestone 0  
fill ~9 ~0 ~68 ~43 ~0 ~68 cobblestone 0  
fill ~9 ~0 ~69 ~43 ~0 ~69 cobblestone 0  
fill ~9 ~0 ~70 ~43 ~0 ~70 cobblestone 0  
fill ~9 ~0 ~71 ~43 ~0 ~71 cobblestone 0  
fill ~9 ~0 ~72 ~43 ~0 ~72 cobblestone 0  
fill ~9 ~0 ~73 ~43 ~0 ~73 cobblestone 0  
fill ~9 ~0 ~74 ~9 ~0 ~33 cobblestone 0  
fill ~10 ~0 ~15 ~43 ~0 ~15 double_stone_slab 14 
setblock ~10 ~0 ~22 sand 0  
fill ~10 ~0 ~32 ~41 ~0 ~32 double_stone_slab 0  
fill ~10 ~0 ~74 ~43 ~0 ~74 double_stone_slab 14 
setblock ~11 ~0 ~19 sand 0  
fill ~11 ~0 ~22 ~12 ~0 ~22 dirt 0  
fill ~12 ~0 ~19 ~16 ~0 ~19 dirt 0  
fill ~12 ~0 ~20 ~13 ~0 ~20 dirt 0 
setblock ~12 ~0 ~21 sand 0  
fill ~13 ~0 ~21 ~15 ~0 ~21 dirt 0  
fill ~13 ~0 ~22 ~14 ~0 ~22 glowstone 0 
setblock ~14 ~0 ~20 sand 0 
setblock ~15 ~0 ~22 dirt 0  
fill ~16 ~0 ~14 ~42 ~0 ~14 double_stone_slab 14 
setblock ~16 ~0 ~22 sand 0  
fill ~17 ~0 ~19 ~42 ~0 ~19 double_stone_slab 14  
fill ~17 ~0 ~20 ~43 ~0 ~20 double_stone_slab 14  
fill ~17 ~0 ~21 ~42 ~0 ~21 double_stone_slab 14  
fill ~17 ~0 ~22 ~43 ~0 ~22 double_stone_slab 14  
fill ~21 ~0 ~13 ~36 ~0 ~13 double_stone_slab 14  
fill ~32 ~0 ~26 ~32 ~0 ~27 double_stone_slab 0 
setblock ~33 ~0 ~25 double_stone_slab 0  
fill ~33 ~0 ~26 ~43 ~0 ~26 double_stone_slab 14  
fill ~33 ~0 ~27 ~43 ~0 ~27 double_stone_slab 14  
fill ~34 ~0 ~25 ~43 ~0 ~25 double_stone_slab 14 
setblock ~37 ~0 ~13 leaves 8  
fill ~37 ~0 ~28 ~43 ~0 ~28 double_stone_slab 14  
fill ~37 ~0 ~29 ~43 ~0 ~29 double_stone_slab 14  
fill ~37 ~0 ~30 ~43 ~0 ~30 double_stone_slab 14  
fill ~37 ~0 ~31 ~43 ~0 ~31 double_stone_slab 14 
setblock ~38 ~0 ~13 double_stone_slab 14  
fill ~39 ~0 ~13 ~40 ~0 ~13 leaves 8 
setblock ~41 ~0 ~13 double_stone_slab 14 
setblock ~42 ~0 ~13 leaves 12  
fill ~42 ~0 ~32 ~43 ~0 ~32 double_stone_slab 14 
setblock ~43 ~0 ~13 double_stone_slab 14 
setblock ~43 ~0 ~14 leaves 8  
fill ~43 ~0 ~16 ~43 ~0 ~17 leaves 8 
setblock ~43 ~0 ~19 leaves 8 
setblock ~43 ~0 ~21 leaves 8 
setblock ~43 ~0 ~23 leaves 12  
fill ~1 ~1 ~18 ~1 ~1 ~27 stone_slab 0  
fill ~3 ~1 ~52 ~3 ~1 ~57 stone_slab 0  
fill ~4 ~1 ~48 ~4 ~1 ~51 stone_slab 0  
fill ~4 ~1 ~52 ~4 ~143 ~52 wool 8  
fill ~4 ~1 ~53 ~4 ~143 ~53 wool 8  
fill ~4 ~1 ~54 ~4 ~143 ~54 wool 7  
fill ~4 ~1 ~55 ~4 ~143 ~55 wool 7  
fill ~4 ~1 ~56 ~4 ~143 ~56 wool 8  
fill ~4 ~1 ~57 ~4 ~143 ~57 wool 8  
fill ~4 ~1 ~58 ~4 ~1 ~61 stone_slab 0  
fill ~5 ~1 ~30 ~5 ~1 ~47 stone_slab 0  
fill ~5 ~1 ~48 ~5 ~143 ~48 wool 8  
fill ~5 ~1 ~49 ~5 ~143 ~49 wool 8  
fill ~5 ~1 ~50 ~5 ~143 ~50 wool 7  
fill ~5 ~1 ~51 ~5 ~143 ~51 wool 7 
setblock ~5 ~1 ~52 glowstone 0  
fill ~5 ~1 ~53 ~10 ~1 ~53 planks 1  
fill ~5 ~1 ~54 ~38 ~1 ~54 planks 1  
fill ~5 ~1 ~55 ~37 ~1 ~55 planks 1  
fill ~5 ~1 ~56 ~37 ~1 ~56 planks 1  
fill ~5 ~1 ~57 ~37 ~1 ~57 planks 1  
fill ~5 ~1 ~58 ~5 ~143 ~58 wool 7  
fill ~5 ~1 ~59 ~5 ~143 ~59 wool 7  
fill ~5 ~1 ~60 ~5 ~143 ~60 wool 8  
fill ~5 ~1 ~61 ~5 ~143 ~61 wool 8  
fill ~5 ~1 ~62 ~5 ~1 ~65 stone_slab 0  
fill ~6 ~1 ~17 ~7 ~1 ~17 stone_slab 0  
fill ~6 ~1 ~18 ~6 ~1 ~29 stone_slab 0  
fill ~6 ~1 ~30 ~6 ~6 ~30 wool 7  
fill ~6 ~1 ~31 ~6 ~11 ~31 wool 7  
fill ~6 ~1 ~32 ~6 ~16 ~32 wool 8  
fill ~6 ~1 ~33 ~6 ~2 ~33 wool 8  
fill ~6 ~1 ~34 ~7 ~1 ~34 wool 7  
fill ~6 ~1 ~35 ~7 ~1 ~35 wool 7  
fill ~6 ~1 ~36 ~8 ~1 ~36 wool 8  
fill ~6 ~1 ~37 ~8 ~1 ~37 wool 8  
fill ~6 ~1 ~38 ~7 ~1 ~38 wool 7  
fill ~6 ~1 ~39 ~7 ~1 ~39 wool 7  
fill ~6 ~1 ~40 ~8 ~1 ~40 wool 8  
fill ~6 ~1 ~41 ~8 ~1 ~41 wool 8  
fill ~6 ~1 ~42 ~6 ~112 ~42 wool 7  
fill ~6 ~1 ~43 ~6 ~120 ~43 wool 7  
fill ~6 ~1 ~44 ~6 ~122 ~44 wool 8  
fill ~6 ~1 ~45 ~6 ~122 ~45 wool 8  
fill ~6 ~1 ~46 ~6 ~143 ~46 wool 7  
fill ~6 ~1 ~47 ~6 ~143 ~47 wool 7  
fill ~6 ~1 ~48 ~10 ~1 ~48 planks 1  
fill ~6 ~1 ~49 ~38 ~1 ~49 planks 1  
fill ~6 ~1 ~50 ~38 ~1 ~50 planks 1  
fill ~6 ~1 ~51 ~38 ~1 ~51 planks 1  
fill ~6 ~1 ~52 ~10 ~1 ~52 planks 1  
fill ~6 ~1 ~58 ~37 ~1 ~58 planks 1  
fill ~6 ~1 ~59 ~19 ~1 ~59 planks 1 
setblock ~6 ~1 ~60 glowstone 0  
fill ~6 ~1 ~62 ~6 ~143 ~62 wool 7  
fill ~6 ~1 ~63 ~6 ~143 ~63 wool 7  
fill ~6 ~1 ~64 ~6 ~143 ~64 wool 8  
fill ~6 ~1 ~65 ~6 ~143 ~65 wool 8  
fill ~6 ~1 ~66 ~6 ~1 ~67 stone_slab 0  
fill ~7 ~1 ~28 ~8 ~1 ~28 wool 8  
fill ~7 ~1 ~29 ~7 ~6 ~29 wool 7  
fill ~7 ~1 ~42 ~38 ~1 ~42 planks 1  
fill ~7 ~1 ~43 ~38 ~1 ~43 planks 1  
fill ~7 ~1 ~44 ~38 ~1 ~44 planks 1  
fill ~7 ~1 ~45 ~38 ~1 ~45 planks 1  
fill ~7 ~1 ~46 ~38 ~1 ~46 planks 1  
fill ~7 ~1 ~47 ~10 ~1 ~47 planks 1  
fill ~7 ~1 ~60 ~37 ~1 ~60 planks 1  
fill ~7 ~1 ~66 ~7 ~143 ~66 wool 7  
fill ~7 ~1 ~67 ~7 ~143 ~67 wool 7  
fill ~7 ~1 ~68 ~7 ~1 ~69 stone_slab 0  
fill ~8 ~1 ~16 ~9 ~1 ~16 stone_slab 0  
fill ~8 ~1 ~24 ~8 ~41 ~24 wool 8  
fill ~8 ~1 ~25 ~8 ~46 ~25 wool 8  
fill ~8 ~1 ~26 ~8 ~51 ~26 wool 7  
fill ~8 ~1 ~27 ~8 ~56 ~27 wool 7  
fill ~8 ~1 ~29 ~8 ~66 ~29 wool 8  
fill ~8 ~1 ~30 ~8 ~71 ~30 wool 7  
fill ~8 ~1 ~31 ~8 ~5 ~31 wool 7  
fill ~8 ~1 ~32 ~8 ~5 ~32 wool 8  
fill ~8 ~1 ~33 ~8 ~2 ~33 wool 8  
fill ~8 ~1 ~34 ~8 ~5 ~34 wool 8  
fill ~8 ~1 ~35 ~8 ~5 ~35 wool 8  
fill ~8 ~1 ~38 ~8 ~5 ~38 wool 8  
fill ~8 ~1 ~39 ~8 ~5 ~39 wool 8  
fill ~8 ~1 ~68 ~8 ~5 ~68 wool 8  
fill ~8 ~1 ~69 ~8 ~143 ~69 wool 8 
setblock ~8 ~1 ~70 stone_slab 0  
fill ~9 ~1 ~17 ~9 ~6 ~17 wool 8  
fill ~9 ~1 ~18 ~9 ~11 ~18 wool 7  
fill ~9 ~1 ~19 ~9 ~16 ~19 wool 7  
fill ~9 ~1 ~20 ~9 ~21 ~20 wool 8  
fill ~9 ~1 ~21 ~9 ~26 ~21 wool 8  
fill ~9 ~1 ~22 ~9 ~36 ~22 wool 7  
fill ~9 ~1 ~23 ~9 ~41 ~23 wool 7  
fill ~9 ~1 ~24 ~17 ~1 ~24 planks 1  
fill ~9 ~1 ~25 ~18 ~1 ~25 planks 1  
fill ~9 ~1 ~26 ~18 ~1 ~26 planks 1  
fill ~9 ~1 ~27 ~18 ~1 ~27 planks 1  
fill ~9 ~1 ~28 ~19 ~1 ~28 planks 1  
fill ~9 ~1 ~29 ~19 ~1 ~29 planks 1  
fill ~9 ~1 ~30 ~20 ~1 ~30 planks 1  
fill ~9 ~1 ~31 ~21 ~1 ~31 planks 1  
fill ~9 ~1 ~32 ~22 ~1 ~32 planks 1  
fill ~9 ~1 ~33 ~23 ~1 ~33 planks 1  
fill ~9 ~1 ~34 ~24 ~1 ~34 planks 1  
fill ~9 ~1 ~35 ~25 ~1 ~35 planks 1  
fill ~9 ~1 ~36 ~31 ~1 ~36 planks 1  
fill ~9 ~1 ~37 ~38 ~1 ~37 planks 1  
fill ~9 ~1 ~38 ~38 ~1 ~38 planks 1  
fill ~9 ~1 ~39 ~38 ~1 ~39 planks 1  
fill ~9 ~1 ~40 ~38 ~1 ~40 planks 1  
fill ~9 ~1 ~41 ~38 ~1 ~41 planks 1  
fill ~9 ~1 ~70 ~9 ~143 ~70 wool 7 
setblock ~9 ~1 ~71 stone_slab 0  
fill ~10 ~1 ~15 ~15 ~1 ~15 stone_slab 0  
fill ~10 ~1 ~16 ~13 ~1 ~16 planks 1  
fill ~10 ~1 ~17 ~10 ~6 ~17 planks 1  
fill ~10 ~1 ~18 ~16 ~1 ~18 planks 1  
fill ~10 ~1 ~19 ~16 ~1 ~19 planks 1  
fill ~10 ~1 ~20 ~16 ~1 ~20 planks 1  
fill ~10 ~1 ~21 ~16 ~1 ~21 planks 1  
fill ~10 ~1 ~22 ~16 ~1 ~22 planks 1  
fill ~10 ~1 ~23 ~17 ~1 ~23 planks 1  
fill ~10 ~1 ~71 ~10 ~143 ~71 wool 7 
setblock ~10 ~1 ~72 stone_slab 0  
fill ~11 ~1 ~17 ~12 ~1 ~17 glowstone 0  
fill ~11 ~1 ~47 ~11 ~1 ~48 glowstone 0  
fill ~11 ~1 ~52 ~11 ~1 ~53 glowstone 0  
fill ~11 ~1 ~72 ~12 ~1 ~72 wool 8  
fill ~11 ~1 ~73 ~12 ~1 ~73 stone_slab 0  
fill ~12 ~1 ~47 ~15 ~1 ~47 planks 1  
fill ~12 ~1 ~48 ~16 ~1 ~48 planks 1  
fill ~12 ~1 ~52 ~16 ~1 ~52 planks 1  
fill ~12 ~1 ~53 ~16 ~1 ~53 planks 1  
fill ~13 ~1 ~17 ~14 ~1 ~17 planks 1  
fill ~13 ~1 ~73 ~14 ~1 ~73 wool 7  
fill ~13 ~1 ~74 ~16 ~1 ~74 stone_slab 0  
fill ~15 ~1 ~73 ~16 ~1 ~73 wool 8  
fill ~16 ~1 ~14 ~20 ~1 ~14 stone_slab 0  
fill ~17 ~1 ~47 ~17 ~1 ~48 glowstone 0  
fill ~17 ~1 ~52 ~17 ~1 ~53 glowstone 0  
fill ~17 ~1 ~74 ~18 ~1 ~74 wool 7  
fill ~18 ~1 ~47 ~22 ~1 ~47 planks 1  
fill ~18 ~1 ~48 ~22 ~1 ~48 planks 1  
fill ~18 ~1 ~52 ~22 ~1 ~52 planks 1  
fill ~18 ~1 ~53 ~22 ~1 ~53 planks 1  
fill ~19 ~1 ~74 ~20 ~1 ~74 wool 8 
setblock ~20 ~1 ~59 glowstone 0  
fill ~21 ~1 ~13 ~43 ~1 ~13 stone_slab 0  
fill ~21 ~1 ~59 ~38 ~1 ~59 planks 1  
fill ~21 ~1 ~74 ~22 ~1 ~74 wool 7  
fill ~23 ~1 ~47 ~23 ~1 ~48 glowstone 0  
fill ~23 ~1 ~52 ~23 ~1 ~53 glowstone 0  
fill ~23 ~1 ~74 ~24 ~1 ~74 wool 8  
fill ~24 ~1 ~47 ~28 ~1 ~47 planks 1  
fill ~24 ~1 ~48 ~28 ~1 ~48 planks 1  
fill ~24 ~1 ~52 ~28 ~1 ~52 planks 1  
fill ~24 ~1 ~53 ~28 ~1 ~53 planks 1  
fill ~25 ~1 ~74 ~26 ~1 ~74 wool 7  
fill ~26 ~1 ~35 ~26 ~5 ~35 wool 7  
fill ~27 ~1 ~22 ~27 ~1 ~25 stone 0  
fill ~27 ~1 ~34 ~31 ~1 ~34 dropper 0  
fill ~27 ~1 ~35 ~31 ~1 ~35 planks 1  
fill ~27 ~1 ~74 ~28 ~1 ~74 wool 8  
fill ~28 ~1 ~21 ~29 ~1 ~21 stone 0  
fill ~28 ~1 ~23 ~28 ~3 ~23 stone 0  
fill ~28 ~1 ~25 ~28 ~1 ~26 stone 0  
fill ~29 ~1 ~22 ~30 ~1 ~22 stone 0  
fill ~29 ~1 ~23 ~29 ~3 ~23 glowstone 0  
fill ~29 ~1 ~24 ~29 ~3 ~24 glowstone 0  
fill ~29 ~1 ~25 ~29 ~3 ~25 glowstone 0  
fill ~29 ~1 ~26 ~30 ~1 ~26 stone 0  
fill ~29 ~1 ~27 ~30 ~1 ~27 stone 0  
fill ~29 ~1 ~47 ~29 ~1 ~48 glowstone 0  
fill ~29 ~1 ~52 ~29 ~1 ~53 glowstone 0  
fill ~29 ~1 ~73 ~30 ~1 ~73 wool 7  
fill ~30 ~1 ~23 ~31 ~1 ~23 stone 0  
fill ~30 ~1 ~24 ~31 ~1 ~24 stone 0  
fill ~30 ~1 ~25 ~31 ~1 ~25 stone 0  
fill ~30 ~1 ~47 ~34 ~1 ~47 planks 1  
fill ~30 ~1 ~48 ~34 ~1 ~48 planks 1  
fill ~30 ~1 ~52 ~34 ~1 ~52 planks 1  
fill ~30 ~1 ~53 ~34 ~1 ~53 planks 1  
fill ~31 ~1 ~73 ~32 ~1 ~73 wool 8  
fill ~31 ~1 ~74 ~43 ~1 ~74 stone_slab 0  
fill ~32 ~1 ~35 ~32 ~5 ~35 wool 7  
fill ~32 ~1 ~36 ~32 ~5 ~36 wool 8 
setblock ~33 ~1 ~36 planks 1  
fill ~33 ~1 ~72 ~33 ~143 ~72 wool 7  
fill ~34 ~1 ~71 ~34 ~143 ~71 wool 7  
fill ~35 ~1 ~47 ~35 ~1 ~48 glowstone 0  
fill ~35 ~1 ~52 ~35 ~1 ~53 glowstone 0  
fill ~35 ~1 ~70 ~35 ~143 ~70 wool 8  
fill ~36 ~1 ~47 ~38 ~1 ~47 planks 1  
fill ~36 ~1 ~48 ~38 ~1 ~48 planks 1  
fill ~36 ~1 ~52 ~38 ~1 ~52 planks 1  
fill ~36 ~1 ~53 ~38 ~1 ~53 planks 1  
fill ~36 ~1 ~68 ~36 ~143 ~68 wool 7  
fill ~36 ~1 ~69 ~36 ~143 ~69 wool 8  
fill ~36 ~1 ~71 ~36 ~3 ~71 leaves 12  
fill ~37 ~1 ~65 ~37 ~131 ~65 wool 8  
fill ~37 ~1 ~66 ~37 ~7 ~66 wool 8  
fill ~37 ~1 ~67 ~37 ~143 ~67 wool 7  
fill ~37 ~1 ~70 ~37 ~5 ~70 leaves 12  
fill ~38 ~1 ~36 ~38 ~6 ~36 planks 1  
fill ~38 ~1 ~55 ~38 ~2 ~55 wool 7  
fill ~38 ~1 ~56 ~38 ~2 ~56 wool 7  
fill ~38 ~1 ~57 ~38 ~2 ~57 wool 7  
fill ~38 ~1 ~58 ~38 ~2 ~58 wool 7 
setblock ~38 ~1 ~60 glowstone 0  
fill ~38 ~1 ~61 ~38 ~111 ~61 wool 8  
fill ~38 ~1 ~62 ~38 ~116 ~62 wool 8  
fill ~38 ~1 ~63 ~38 ~121 ~63 wool 7  
fill ~38 ~1 ~64 ~38 ~126 ~64 wool 7  
fill ~38 ~1 ~68 ~38 ~3 ~68 leaves 12  
fill ~38 ~1 ~69 ~38 ~4 ~69 leaves 12  
fill ~39 ~1 ~29 ~39 ~1 ~54 wool 7  
fill ~39 ~1 ~59 ~39 ~103 ~59 wool 7  
fill ~39 ~1 ~60 ~39 ~106 ~60 wool 7  
fill ~39 ~1 ~61 ~40 ~1 ~61 wool 7  
fill ~39 ~1 ~65 ~39 ~3 ~65 leaves 12  
fill ~39 ~1 ~66 ~39 ~4 ~66 leaves 12  
fill ~39 ~1 ~67 ~39 ~2 ~67 leaves 12  
fill ~40 ~1 ~62 ~40 ~2 ~62 leaves 12  
fill ~40 ~1 ~63 ~40 ~3 ~63 leaves 12  
fill ~40 ~1 ~64 ~40 ~3 ~64 leaves 12  
fill ~43 ~1 ~14 ~43 ~1 ~23 stone_slab 0  
fill ~5 ~2 ~52 ~5 ~4 ~52 leaves 15  
fill ~6 ~2 ~34 ~7 ~2 ~34 wool 7  
fill ~6 ~2 ~35 ~7 ~2 ~35 wool 7  
fill ~6 ~2 ~36 ~8 ~2 ~36 wool 8  
fill ~6 ~2 ~37 ~8 ~2 ~37 wool 8  
fill ~6 ~2 ~38 ~7 ~2 ~38 wool 7  
fill ~6 ~2 ~39 ~7 ~2 ~39 wool 7  
fill ~6 ~2 ~40 ~8 ~2 ~40 wool 8  
fill ~6 ~2 ~41 ~8 ~2 ~41 wool 8 
setblock ~6 ~2 ~57 spruce_stairs 1  
fill ~6 ~2 ~60 ~6 ~4 ~60 leaves 15  
fill ~7 ~2 ~28 ~8 ~2 ~28 wool 8 
setblock ~7 ~2 ~51 spruce_stairs 1 
setblock ~7 ~2 ~54 spruce_stairs 1  
fill ~7 ~2 ~56 ~7 ~2 ~58 wool 7  
fill ~8 ~2 ~50 ~8 ~2 ~55 wool 7  
fill ~10 ~2 ~16 ~10 ~6 ~16 planks 1  
fill ~10 ~2 ~18 ~10 ~5 ~18 planks 1  
fill ~11 ~2 ~17 ~12 ~2 ~17 glass 0  
fill ~11 ~2 ~47 ~11 ~2 ~48 leaves 15  
fill ~11 ~2 ~52 ~11 ~5 ~52 leaves 15  
fill ~11 ~2 ~53 ~11 ~4 ~53 leaves 15  
fill ~11 ~2 ~72 ~12 ~2 ~72 wool 8  
fill ~12 ~2 ~58 ~14 ~2 ~58 wool 7  
fill ~12 ~2 ~60 ~12 ~5 ~60 wool 8  
fill ~13 ~2 ~16 ~13 ~6 ~16 planks 1  
fill ~13 ~2 ~17 ~14 ~2 ~17 planks 1  
fill ~13 ~2 ~51 ~15 ~2 ~51 wool 7  
fill ~13 ~2 ~54 ~15 ~2 ~54 wool 7 
setblock ~13 ~2 ~59 spruce_stairs 2  
fill ~13 ~2 ~60 ~14 ~2 ~60 wool 7  
fill ~13 ~2 ~73 ~14 ~2 ~73 wool 7 
setblock ~14 ~2 ~52 spruce_stairs 2 
setblock ~14 ~2 ~53 spruce_stairs 3  
fill ~15 ~2 ~18 ~15 ~6 ~18 planks 1  
fill ~15 ~2 ~20 ~15 ~5 ~20 glass 0  
fill ~15 ~2 ~21 ~15 ~5 ~21 glass 0  
fill ~15 ~2 ~22 ~15 ~5 ~22 glass 0  
fill ~15 ~2 ~73 ~16 ~2 ~73 wool 8  
fill ~16 ~2 ~23 ~16 ~5 ~23 glass 0  
fill ~16 ~2 ~24 ~16 ~5 ~24 glass 0  
fill ~17 ~2 ~25 ~17 ~5 ~25 glass 0  
fill ~17 ~2 ~26 ~17 ~5 ~26 glass 0  
fill ~17 ~2 ~47 ~17 ~2 ~48 leaves 15  
fill ~17 ~2 ~52 ~17 ~5 ~52 leaves 15  
fill ~17 ~2 ~53 ~17 ~4 ~53 leaves 15  
fill ~17 ~2 ~74 ~18 ~2 ~74 wool 7  
fill ~18 ~2 ~27 ~18 ~5 ~27 glass 0  
fill ~18 ~2 ~28 ~18 ~5 ~28 glass 0  
fill ~19 ~2 ~29 ~19 ~5 ~29 glass 0  
fill ~19 ~2 ~30 ~19 ~5 ~30 glass 0  
fill ~19 ~2 ~51 ~21 ~2 ~51 wool 7  
fill ~19 ~2 ~54 ~21 ~2 ~54 wool 7  
fill ~19 ~2 ~74 ~20 ~2 ~74 wool 8  
fill ~20 ~2 ~31 ~20 ~5 ~31 glass 0 
setblock ~20 ~2 ~52 spruce_stairs 2 
setblock ~20 ~2 ~53 spruce_stairs 3  
fill ~20 ~2 ~59 ~20 ~4 ~59 leaves 15  
fill ~20 ~2 ~60 ~20 ~5 ~60 wool 8  
fill ~21 ~2 ~32 ~21 ~5 ~32 glass 0  
fill ~21 ~2 ~58 ~23 ~2 ~58 wool 7  
fill ~21 ~2 ~60 ~22 ~2 ~60 wool 7  
fill ~21 ~2 ~74 ~22 ~2 ~74 wool 7 
setblock ~22 ~2 ~59 spruce_stairs 2  
fill ~23 ~2 ~34 ~24 ~2 ~34 glass 0  
fill ~23 ~2 ~47 ~23 ~3 ~47 leaves 15  
fill ~23 ~2 ~48 ~23 ~5 ~48 leaves 15  
fill ~23 ~2 ~52 ~23 ~5 ~52 leaves 15  
fill ~23 ~2 ~53 ~23 ~4 ~53 leaves 15  
fill ~23 ~2 ~60 ~23 ~5 ~60 wool 8  
fill ~23 ~2 ~74 ~24 ~2 ~74 wool 8  
fill ~25 ~2 ~35 ~25 ~5 ~35 glass 0  
fill ~25 ~2 ~51 ~27 ~2 ~51 wool 7  
fill ~25 ~2 ~54 ~27 ~2 ~54 wool 7  
fill ~25 ~2 ~74 ~26 ~2 ~74 wool 7  
fill ~26 ~2 ~36 ~26 ~5 ~36 wool 8  
fill ~26 ~2 ~37 ~26 ~5 ~37 wool 8  
fill ~26 ~2 ~38 ~26 ~5 ~38 wool 7 
setblock ~26 ~2 ~52 spruce_stairs 2 
setblock ~26 ~2 ~53 spruce_stairs 3  
fill ~27 ~2 ~24 ~27 ~4 ~24 stone 0  
fill ~27 ~2 ~25 ~27 ~2 ~24 stone 0  
fill ~27 ~2 ~36 ~31 ~2 ~36 wooden_pressure_plate 0  
fill ~27 ~2 ~74 ~28 ~2 ~74 wool 8  
fill ~28 ~2 ~21 ~29 ~2 ~21 stone 0  
fill ~28 ~2 ~26 ~30 ~2 ~26 stone 0  
fill ~29 ~2 ~22 ~30 ~2 ~22 stone 0  
fill ~29 ~2 ~27 ~29 ~1 ~27 stone 0  
fill ~29 ~2 ~47 ~29 ~5 ~47 leaves 15 
setblock ~29 ~2 ~48 leaves 8  
fill ~29 ~2 ~52 ~29 ~5 ~52 leaves 15  
fill ~29 ~2 ~53 ~29 ~4 ~53 leaves 15  
fill ~29 ~2 ~58 ~31 ~2 ~58 wool 7  
fill ~29 ~2 ~60 ~30 ~2 ~60 wool 7  
fill ~29 ~2 ~73 ~30 ~2 ~73 wool 7  
fill ~30 ~2 ~23 ~30 ~1 ~23 stone 0  
fill ~30 ~2 ~24 ~31 ~2 ~24 stone 0  
fill ~30 ~2 ~25 ~31 ~2 ~25 stone 0 
setblock ~30 ~2 ~59 spruce_stairs 2  
fill ~31 ~2 ~51 ~33 ~2 ~51 wool 7  
fill ~31 ~2 ~54 ~33 ~2 ~54 wool 7  
fill ~31 ~2 ~60 ~31 ~5 ~60 wool 8  
fill ~31 ~2 ~73 ~32 ~2 ~73 wool 8  
fill ~32 ~2 ~37 ~32 ~5 ~37 wool 8  
fill ~32 ~2 ~38 ~32 ~5 ~38 wool 7 
setblock ~32 ~2 ~52 spruce_stairs 2 
setblock ~32 ~2 ~53 spruce_stairs 3  
fill ~33 ~2 ~37 ~33 ~5 ~37 glass 0  
fill ~34 ~2 ~38 ~37 ~2 ~38 glass 0  
fill ~35 ~2 ~47 ~35 ~4 ~47 leaves 15  
fill ~35 ~2 ~48 ~35 ~5 ~48 leaves 15  
fill ~35 ~2 ~52 ~35 ~5 ~52 leaves 15  
fill ~35 ~2 ~53 ~35 ~4 ~53 leaves 15  
fill ~37 ~2 ~51 ~39 ~2 ~51 wool 7  
fill ~37 ~2 ~54 ~39 ~2 ~54 wool 7  
fill ~37 ~2 ~57 ~37 ~2 ~58 wool 7  
fill ~38 ~2 ~37 ~38 ~11 ~37 planks 1 
setblock ~38 ~2 ~52 spruce_stairs 2 
setblock ~38 ~2 ~53 spruce_stairs 3  
fill ~38 ~2 ~60 ~38 ~4 ~60 leaves 15  
fill ~39 ~2 ~31 ~39 ~2 ~54 wool 7  
fill ~6 ~3 ~34 ~7 ~3 ~34 wool 7  
fill ~6 ~3 ~35 ~7 ~3 ~35 wool 7  
fill ~6 ~3 ~36 ~8 ~3 ~36 wool 8  
fill ~6 ~3 ~37 ~8 ~3 ~37 wool 8  
fill ~6 ~3 ~38 ~7 ~3 ~38 wool 7  
fill ~6 ~3 ~39 ~7 ~3 ~39 wool 7  
fill ~6 ~3 ~40 ~8 ~3 ~40 wool 8  
fill ~6 ~3 ~41 ~8 ~3 ~41 wool 8  
fill ~7 ~3 ~28 ~8 ~3 ~28 wool 8  
fill ~11 ~3 ~17 ~12 ~3 ~17 glass 0 
setblock ~11 ~3 ~47 leaves 11  
fill ~11 ~3 ~48 ~11 ~5 ~48 leaves 15  
fill ~11 ~3 ~72 ~12 ~3 ~72 wool 8  
fill ~13 ~3 ~17 ~14 ~3 ~17 planks 1  
fill ~13 ~3 ~60 ~14 ~3 ~60 wool 7  
fill ~13 ~3 ~73 ~14 ~3 ~73 wool 7  
fill ~15 ~3 ~73 ~16 ~3 ~73 wool 8 
setblock ~17 ~3 ~47 leaves 11  
fill ~17 ~3 ~48 ~17 ~5 ~48 leaves 15  
fill ~17 ~3 ~74 ~18 ~3 ~74 wool 7  
fill ~19 ~3 ~74 ~20 ~3 ~74 wool 8  
fill ~21 ~3 ~60 ~22 ~3 ~60 wool 7  
fill ~21 ~3 ~74 ~22 ~3 ~74 wool 7  
fill ~23 ~3 ~34 ~24 ~3 ~34 glass 0  
fill ~23 ~3 ~74 ~24 ~3 ~74 wool 8  
fill ~25 ~3 ~74 ~26 ~3 ~74 wool 7  
fill ~27 ~3 ~74 ~28 ~3 ~74 wool 8  
fill ~28 ~3 ~26 ~30 ~3 ~26 stone 0 
setblock ~29 ~3 ~21 stone 0  
fill ~29 ~3 ~48 ~29 ~4 ~48 leaves 15  
fill ~29 ~3 ~60 ~30 ~3 ~60 wool 7  
fill ~29 ~3 ~73 ~30 ~3 ~73 wool 7  
fill ~30 ~3 ~22 ~30 ~4 ~22 stone 0  
fill ~30 ~3 ~24 ~31 ~3 ~24 stone 0  
fill ~30 ~3 ~25 ~30 ~1 ~25 stone 0 
setblock ~31 ~3 ~23 stone 0  
fill ~31 ~3 ~73 ~32 ~3 ~73 wool 8  
fill ~34 ~3 ~38 ~37 ~3 ~38 glass 0  
fill ~38 ~3 ~55 ~38 ~4 ~55 wool 8  
fill ~38 ~3 ~56 ~38 ~4 ~56 wool 8  
fill ~38 ~3 ~57 ~38 ~4 ~57 wool 8  
fill ~38 ~3 ~58 ~38 ~4 ~58 wool 8  
fill ~39 ~3 ~33 ~39 ~3 ~54 wool 8  
fill ~6 ~4 ~34 ~7 ~4 ~34 wool 7  
fill ~6 ~4 ~35 ~7 ~4 ~35 wool 7  
fill ~6 ~4 ~36 ~8 ~4 ~36 wool 8  
fill ~6 ~4 ~37 ~8 ~4 ~37 wool 8  
fill ~6 ~4 ~38 ~7 ~4 ~38 wool 7  
fill ~6 ~4 ~39 ~7 ~4 ~39 wool 7  
fill ~6 ~4 ~40 ~8 ~4 ~40 wool 8  
fill ~6 ~4 ~41 ~8 ~4 ~41 wool 8  
fill ~7 ~4 ~28 ~8 ~4 ~28 wool 8  
fill ~11 ~4 ~17 ~12 ~4 ~17 glass 0  
fill ~11 ~4 ~47 ~11 ~5 ~47 leaves 15  
fill ~11 ~4 ~72 ~12 ~4 ~72 wool 8  
fill ~13 ~4 ~17 ~14 ~4 ~17 planks 1  
fill ~13 ~4 ~60 ~14 ~4 ~60 wool 7  
fill ~13 ~4 ~73 ~14 ~4 ~73 wool 7  
fill ~15 ~4 ~19 ~15 ~5 ~19 glass 0  
fill ~15 ~4 ~73 ~16 ~4 ~73 wool 8  
fill ~17 ~4 ~47 ~17 ~5 ~47 leaves 15  
fill ~17 ~4 ~74 ~18 ~4 ~74 wool 7  
fill ~19 ~4 ~74 ~20 ~4 ~74 wool 8  
fill ~21 ~4 ~60 ~22 ~4 ~60 wool 7  
fill ~21 ~4 ~74 ~22 ~4 ~74 wool 7  
fill ~22 ~4 ~33 ~22 ~5 ~33 glass 0  
fill ~23 ~4 ~34 ~24 ~4 ~34 glass 0 
setblock ~23 ~4 ~47 leaves 11  
fill ~23 ~4 ~74 ~24 ~4 ~74 wool 8  
fill ~25 ~4 ~74 ~26 ~4 ~74 wool 7  
fill ~27 ~4 ~74 ~28 ~4 ~74 wool 8  
fill ~28 ~4 ~23 ~28 ~4 ~24 diamond_block 0 
setblock ~28 ~4 ~26 diamond_block 0  
fill ~29 ~4 ~26 ~29 ~5 ~26 stone 0  
fill ~29 ~4 ~27 ~29 ~4 ~28 diamond_block 0  
fill ~29 ~4 ~60 ~30 ~4 ~60 wool 7  
fill ~29 ~4 ~73 ~30 ~4 ~73 wool 7  
fill ~30 ~4 ~23 ~30 ~4 ~26 diamond_block 0  
fill ~31 ~4 ~24 ~31 ~4 ~25 stone 0  
fill ~31 ~4 ~73 ~32 ~4 ~73 wool 8  
fill ~34 ~4 ~38 ~37 ~4 ~38 glass 0  
fill ~39 ~4 ~35 ~39 ~4 ~54 wool 8 
setblock ~40 ~4 ~64 leaves 8 
setblock ~5 ~5 ~52 leaves 11  
fill ~6 ~5 ~33 ~6 ~21 ~33 wool 8  
fill ~6 ~5 ~34 ~7 ~5 ~34 wool 7  
fill ~6 ~5 ~35 ~7 ~5 ~35 wool 7  
fill ~6 ~5 ~36 ~8 ~5 ~36 wool 8  
fill ~6 ~5 ~37 ~8 ~5 ~37 wool 8  
fill ~6 ~5 ~38 ~7 ~5 ~38 wool 7  
fill ~6 ~5 ~39 ~7 ~5 ~39 wool 7  
fill ~6 ~5 ~40 ~8 ~5 ~40 wool 8  
fill ~6 ~5 ~41 ~8 ~5 ~41 wool 8 
setblock ~6 ~5 ~60 leaves 11  
fill ~7 ~5 ~28 ~8 ~5 ~28 wool 8 
setblock ~8 ~5 ~33 wool 8  
fill ~11 ~5 ~17 ~12 ~5 ~17 glass 0 
setblock ~11 ~5 ~53 leaves 11  
fill ~11 ~5 ~72 ~12 ~5 ~72 wool 8  
fill ~13 ~5 ~17 ~14 ~5 ~17 planks 1  
fill ~13 ~5 ~60 ~14 ~5 ~60 wool 7  
fill ~13 ~5 ~73 ~14 ~5 ~73 wool 7  
fill ~15 ~5 ~73 ~16 ~5 ~73 wool 8 
setblock ~17 ~5 ~53 leaves 11  
fill ~17 ~5 ~74 ~18 ~5 ~74 wool 7  
fill ~19 ~5 ~74 ~20 ~5 ~74 wool 8  
fill ~20 ~5 ~33 ~20 ~5 ~35 wool 7 
setblock ~20 ~5 ~59 leaves 11  
fill ~21 ~5 ~36 ~21 ~5 ~38 wool 7  
fill ~21 ~5 ~60 ~22 ~5 ~60 wool 7  
fill ~21 ~5 ~74 ~22 ~5 ~74 wool 7  
fill ~22 ~5 ~39 ~22 ~5 ~40 wool 7  
fill ~23 ~5 ~34 ~24 ~5 ~34 glass 0 
setblock ~23 ~5 ~41 wool 7 
setblock ~23 ~5 ~47 leaves 15 
setblock ~23 ~5 ~53 leaves 11  
fill ~23 ~5 ~74 ~24 ~5 ~74 wool 8 
setblock ~24 ~5 ~42 wool 7  
fill ~25 ~5 ~43 ~26 ~5 ~43 wool 7  
fill ~25 ~5 ~74 ~26 ~5 ~74 wool 7  
fill ~27 ~5 ~35 ~32 ~5 ~35 wool 7  
fill ~27 ~5 ~36 ~32 ~5 ~36 wool 8  
fill ~27 ~5 ~37 ~32 ~5 ~37 wool 8  
fill ~27 ~5 ~38 ~32 ~5 ~38 wool 7  
fill ~27 ~5 ~44 ~29 ~5 ~44 wool 7  
fill ~27 ~5 ~74 ~28 ~5 ~74 wool 8 
setblock ~28 ~5 ~22 diamond_block 0 
setblock ~29 ~5 ~48 leaves 8 
setblock ~29 ~5 ~53 leaves 11  
fill ~29 ~5 ~60 ~30 ~5 ~60 wool 7  
fill ~29 ~5 ~73 ~30 ~5 ~73 wool 7 
setblock ~30 ~5 ~22 diamond_block 0  
fill ~30 ~5 ~45 ~33 ~5 ~45 wool 7  
fill ~31 ~5 ~73 ~32 ~5 ~73 wool 8  
fill ~34 ~5 ~38 ~37 ~5 ~38 glass 0  
fill ~34 ~5 ~46 ~39 ~5 ~46 wool 7 
setblock ~35 ~5 ~47 leaves 11 
setblock ~35 ~5 ~53 leaves 11  
fill ~38 ~5 ~38 ~38 ~16 ~38 planks 1  
fill ~38 ~5 ~39 ~38 ~6 ~39 planks 1  
fill ~38 ~5 ~55 ~38 ~6 ~55 wool 7  
fill ~38 ~5 ~56 ~38 ~6 ~56 wool 7  
fill ~38 ~5 ~57 ~38 ~6 ~57 wool 7  
fill ~38 ~5 ~58 ~38 ~6 ~58 wool 7  
fill ~39 ~5 ~36 ~39 ~6 ~36 wool 7  
fill ~39 ~5 ~37 ~39 ~6 ~37 wool 7  
fill ~39 ~5 ~38 ~39 ~6 ~38 wool 7  
fill ~39 ~5 ~39 ~39 ~6 ~39 wool 7  
fill ~39 ~5 ~40 ~39 ~6 ~40 wool 7  
fill ~39 ~5 ~41 ~39 ~6 ~41 wool 7  
fill ~39 ~5 ~42 ~39 ~6 ~42 wool 7  
fill ~39 ~5 ~43 ~39 ~6 ~43 wool 7  
fill ~39 ~5 ~44 ~39 ~6 ~44 wool 7  
fill ~39 ~5 ~45 ~39 ~6 ~45 wool 7  
fill ~39 ~5 ~47 ~39 ~6 ~47 wool 7  
fill ~39 ~5 ~48 ~39 ~6 ~48 wool 7  
fill ~39 ~5 ~49 ~39 ~6 ~49 wool 7  
fill ~39 ~5 ~50 ~39 ~6 ~50 wool 7  
fill ~39 ~5 ~51 ~39 ~6 ~51 wool 7  
fill ~39 ~5 ~52 ~39 ~6 ~52 wool 7  
fill ~39 ~5 ~53 ~39 ~6 ~53 wool 7  
fill ~39 ~5 ~54 ~39 ~6 ~54 wool 7 
setblock ~5 ~6 ~52 glowstone 0  
fill ~5 ~6 ~53 ~10 ~6 ~53 planks 1  
fill ~5 ~6 ~54 ~38 ~6 ~54 planks 1  
fill ~5 ~6 ~55 ~37 ~6 ~55 planks 1  
fill ~5 ~6 ~56 ~37 ~6 ~56 planks 1  
fill ~5 ~6 ~57 ~37 ~6 ~57 planks 1  
fill ~6 ~6 ~34 ~6 ~26 ~34 wool 7  
fill ~6 ~6 ~35 ~6 ~31 ~35 wool 7  
fill ~6 ~6 ~36 ~6 ~36 ~36 wool 8  
fill ~6 ~6 ~37 ~6 ~41 ~37 wool 8  
fill ~6 ~6 ~38 ~6 ~46 ~38 wool 7  
fill ~6 ~6 ~39 ~6 ~51 ~39 wool 7  
fill ~6 ~6 ~40 ~6 ~56 ~40 wool 8  
fill ~6 ~6 ~41 ~6 ~61 ~41 wool 8  
fill ~6 ~6 ~48 ~10 ~6 ~48 planks 1  
fill ~6 ~6 ~49 ~38 ~6 ~49 planks 1  
fill ~6 ~6 ~50 ~38 ~6 ~50 planks 1  
fill ~6 ~6 ~51 ~38 ~6 ~51 planks 1  
fill ~6 ~6 ~52 ~10 ~6 ~52 planks 1  
fill ~6 ~6 ~58 ~37 ~6 ~58 planks 1  
fill ~6 ~6 ~59 ~19 ~6 ~59 planks 1 
setblock ~6 ~6 ~60 glowstone 0  
fill ~6 ~6 ~61 ~6 ~115 ~61 wool 8  
fill ~7 ~6 ~28 ~8 ~6 ~28 wool 8  
fill ~7 ~6 ~31 ~20 ~6 ~31 planks 1  
fill ~7 ~6 ~32 ~21 ~6 ~32 planks 1  
fill ~7 ~6 ~33 ~19 ~6 ~33 planks 1  
fill ~7 ~6 ~34 ~19 ~6 ~34 planks 1  
fill ~7 ~6 ~35 ~19 ~6 ~35 planks 1  
fill ~7 ~6 ~36 ~20 ~6 ~36 planks 1  
fill ~7 ~6 ~37 ~20 ~6 ~37 planks 1  
fill ~7 ~6 ~38 ~20 ~6 ~38 planks 1  
fill ~7 ~6 ~39 ~21 ~6 ~39 planks 1  
fill ~7 ~6 ~40 ~21 ~6 ~40 planks 1  
fill ~7 ~6 ~41 ~22 ~6 ~41 planks 1  
fill ~7 ~6 ~42 ~23 ~6 ~42 planks 1  
fill ~7 ~6 ~43 ~24 ~6 ~43 planks 1  
fill ~7 ~6 ~44 ~26 ~6 ~44 planks 1  
fill ~7 ~6 ~45 ~29 ~6 ~45 planks 1  
fill ~7 ~6 ~46 ~33 ~6 ~46 planks 1  
fill ~7 ~6 ~47 ~10 ~6 ~47 planks 1  
fill ~7 ~6 ~60 ~37 ~6 ~60 planks 1  
fill ~7 ~6 ~61 ~37 ~6 ~61 planks 1  
fill ~7 ~6 ~62 ~37 ~6 ~62 planks 1  
fill ~7 ~6 ~63 ~15 ~6 ~63 planks 1  
fill ~7 ~6 ~64 ~15 ~6 ~64 planks 1  
fill ~7 ~6 ~65 ~36 ~6 ~65 planks 1  
fill ~8 ~6 ~66 ~36 ~6 ~66 planks 1  
fill ~8 ~6 ~67 ~36 ~6 ~67 planks 1 
setblock ~8 ~6 ~68 double_stone_slab 0  
fill ~9 ~6 ~24 ~17 ~6 ~24 planks 1  
fill ~9 ~6 ~25 ~17 ~6 ~25 planks 1  
fill ~9 ~6 ~26 ~18 ~6 ~26 planks 1  
fill ~9 ~6 ~27 ~18 ~6 ~27 planks 1  
fill ~9 ~6 ~28 ~19 ~6 ~28 planks 1  
fill ~9 ~6 ~29 ~19 ~6 ~29 planks 1  
fill ~9 ~6 ~30 ~19 ~6 ~30 planks 1  
fill ~9 ~6 ~68 ~11 ~6 ~68 planks 1  
fill ~9 ~6 ~69 ~35 ~6 ~69 planks 1 
setblock ~10 ~6 ~18 glowstone 0  
fill ~10 ~6 ~19 ~16 ~6 ~19 planks 1  
fill ~10 ~6 ~20 ~16 ~6 ~20 planks 1  
fill ~10 ~6 ~21 ~16 ~6 ~21 planks 1  
fill ~10 ~6 ~22 ~16 ~6 ~22 planks 1  
fill ~10 ~6 ~23 ~16 ~6 ~23 planks 1  
fill ~10 ~6 ~70 ~34 ~6 ~70 planks 1  
fill ~11 ~6 ~16 ~13 ~6 ~16 planks 1  
fill ~11 ~6 ~17 ~13 ~6 ~17 glowstone 0  
fill ~11 ~6 ~18 ~13 ~6 ~18 planks 1  
fill ~11 ~6 ~47 ~11 ~6 ~48 glowstone 0  
fill ~11 ~6 ~52 ~11 ~6 ~53 glowstone 0  
fill ~11 ~6 ~71 ~33 ~6 ~71 planks 1  
fill ~11 ~6 ~72 ~12 ~6 ~72 wool 8  
fill ~12 ~6 ~47 ~15 ~6 ~47 planks 1  
fill ~12 ~6 ~48 ~16 ~6 ~48 planks 1  
fill ~12 ~6 ~52 ~16 ~6 ~52 planks 1  
fill ~12 ~6 ~53 ~16 ~6 ~53 planks 1 
setblock ~12 ~6 ~68 glowstone 0  
fill ~13 ~6 ~68 ~19 ~6 ~68 planks 1  
fill ~13 ~6 ~72 ~13 ~110 ~72 wool 7  
fill ~13 ~6 ~73 ~14 ~6 ~73 wool 7 
setblock ~14 ~6 ~17 planks 1 
setblock ~14 ~6 ~18 glowstone 0 
setblock ~14 ~6 ~72 glowstone 0  
fill ~15 ~6 ~72 ~16 ~6 ~72 wool 8  
fill ~15 ~6 ~73 ~16 ~6 ~73 wool 8  
fill ~16 ~6 ~63 ~16 ~6 ~64 glowstone 0  
fill ~17 ~6 ~47 ~17 ~6 ~48 glowstone 0  
fill ~17 ~6 ~52 ~17 ~6 ~53 glowstone 0  
fill ~17 ~6 ~63 ~26 ~6 ~63 planks 1  
fill ~17 ~6 ~64 ~26 ~6 ~64 planks 1  
fill ~17 ~6 ~74 ~18 ~6 ~74 wool 7  
fill ~18 ~6 ~47 ~22 ~6 ~47 planks 1  
fill ~18 ~6 ~48 ~22 ~6 ~48 planks 1  
fill ~18 ~6 ~52 ~22 ~6 ~52 planks 1  
fill ~18 ~6 ~53 ~22 ~6 ~53 planks 1  
fill ~19 ~6 ~72 ~20 ~6 ~72 wool 8  
fill ~19 ~6 ~73 ~20 ~6 ~73 wool 8  
fill ~19 ~6 ~74 ~20 ~6 ~74 wool 8 
setblock ~20 ~6 ~59 glowstone 0 
setblock ~20 ~6 ~68 glowstone 0  
fill ~21 ~6 ~33 ~22 ~6 ~33 planks 1  
fill ~21 ~6 ~59 ~38 ~6 ~59 planks 1  
fill ~21 ~6 ~68 ~22 ~6 ~68 planks 1  
fill ~21 ~6 ~74 ~22 ~6 ~74 wool 7  
fill ~22 ~6 ~34 ~24 ~6 ~34 planks 1  
fill ~23 ~6 ~35 ~26 ~6 ~35 planks 1  
fill ~23 ~6 ~47 ~23 ~6 ~48 glowstone 0  
fill ~23 ~6 ~52 ~23 ~6 ~53 glowstone 0 
setblock ~23 ~6 ~68 glowstone 0  
fill ~23 ~6 ~72 ~24 ~6 ~72 wool 8  
fill ~23 ~6 ~73 ~24 ~6 ~73 wool 8  
fill ~23 ~6 ~74 ~24 ~6 ~74 wool 8  
fill ~24 ~6 ~47 ~28 ~6 ~47 planks 1  
fill ~24 ~6 ~48 ~28 ~6 ~48 planks 1  
fill ~24 ~6 ~52 ~28 ~6 ~52 planks 1  
fill ~24 ~6 ~53 ~28 ~6 ~53 planks 1  
fill ~24 ~6 ~68 ~30 ~6 ~68 planks 1 
fill ~25 ~6 ~36 ~29 ~6 ~36 planks 1  
fill ~25 ~6 ~74 ~26 ~6 ~74 wool 7  
fill ~27 ~6 ~37 ~33 ~6 ~37 planks 1  
fill ~27 ~6 ~63 ~27 ~6 ~64 glowstone 0  
fill ~27 ~6 ~72 ~28 ~6 ~72 wool 8  
fill ~27 ~6 ~73 ~28 ~6 ~73 wool 8  
fill ~27 ~6 ~74 ~28 ~6 ~74 wool 8  
fill ~28 ~6 ~21 ~30 ~6 ~21 diamond_block 0  
fill ~28 ~6 ~63 ~37 ~6 ~63 planks 1  
fill ~28 ~6 ~64 ~37 ~6 ~64 planks 1  
fill ~29 ~6 ~47 ~29 ~6 ~48 glowstone 0  
fill ~29 ~6 ~52 ~29 ~6 ~53 glowstone 0  
fill ~29 ~6 ~72 ~29 ~110 ~72 wool 7  
fill ~29 ~6 ~73 ~30 ~6 ~73 wool 7  
fill ~30 ~6 ~38 ~38 ~6 ~38 planks 1  
fill ~30 ~6 ~47 ~38 ~6 ~47 planks 1  
fill ~30 ~6 ~48 ~34 ~6 ~48 planks 1  
fill ~30 ~6 ~52 ~34 ~6 ~52 planks 1  
fill ~30 ~6 ~53 ~34 ~6 ~53 planks 1 
setblock ~30 ~6 ~72 glowstone 0 
setblock ~31 ~6 ~68 glowstone 0  
fill ~31 ~6 ~72 ~32 ~6 ~72 wool 8  
fill ~31 ~6 ~73 ~32 ~6 ~73 wool 8  
fill ~32 ~6 ~68 ~35 ~6 ~68 planks 1  
fill ~34 ~6 ~39 ~38 ~6 ~39 planks 1 
setblock ~35 ~6 ~48 glowstone 0  
fill ~35 ~6 ~52 ~35 ~6 ~53 glowstone 0  
fill ~36 ~6 ~48 ~38 ~6 ~48 planks 1  
fill ~36 ~6 ~52 ~38 ~6 ~52 planks 1  
fill ~36 ~6 ~53 ~38 ~6 ~53 planks 1 
setblock ~38 ~6 ~60 glowstone 0 
setblock ~39 ~6 ~46 wool 7  
fill ~5 ~7 ~52 ~5 ~9 ~52 leaves 15  
fill ~6 ~7 ~60 ~6 ~9 ~60 leaves 15  
fill ~7 ~7 ~29 ~7 ~11 ~29 wool 8  
fill ~7 ~7 ~30 ~7 ~16 ~30 wool 7 
setblock ~7 ~7 ~31 leaves 11  
fill ~7 ~7 ~61 ~8 ~7 ~61 spruce_stairs 3  
fill ~7 ~7 ~62 ~8 ~7 ~62 dropper 0  
fill ~7 ~7 ~63 ~8 ~7 ~63 dropper 0  
fill ~7 ~7 ~64 ~8 ~7 ~64 spruce_stairs 2  
fill ~8 ~7 ~28 ~8 ~61 ~28 wool 8 
setblock ~8 ~7 ~33 dark_oak_stairs 1 
setblock ~8 ~7 ~37 dark_oak_stairs 1 
setblock ~8 ~7 ~41 dark_oak_stairs 1  
fill ~8 ~7 ~68 ~8 ~143 ~68 wool 8 
setblock ~9 ~7 ~25 dark_oak_stairs 1 
setblock ~9 ~7 ~29 dark_oak_stairs 1 
setblock ~9 ~7 ~32 quartz_stairs 4 
setblock ~9 ~7 ~33 wool 15 
setblock ~9 ~7 ~34 quartz_stairs 4 
setblock ~9 ~7 ~36 quartz_stairs 4 
setblock ~9 ~7 ~37 wool 15 
setblock ~9 ~7 ~38 quartz_stairs 4 
setblock ~9 ~7 ~40 quartz_stairs 4 
setblock ~9 ~7 ~41 wool 15 
setblock ~9 ~7 ~42 quartz_stairs 4  
fill ~9 ~7 ~69 ~9 ~10 ~69 wool 8  
fill ~10 ~7 ~18 ~10 ~9 ~18 glass 0  
fill ~10 ~7 ~19 ~10 ~9 ~19 bookshelf 0  
fill ~10 ~7 ~20 ~10 ~7 ~22 dropper 2  
fill ~10 ~7 ~23 ~11 ~7 ~23 wool 8 
setblock ~10 ~7 ~24 quartz_stairs 4 
setblock ~10 ~7 ~25 wool 15 
setblock ~10 ~7 ~26 quartz_stairs 4 
setblock ~10 ~7 ~28 quartz_stairs 4 
setblock ~10 ~7 ~29 wool 15 
setblock ~10 ~7 ~30 quartz_stairs 4  
fill ~11 ~7 ~17 ~13 ~7 ~17 glass 0 
setblock ~11 ~7 ~20 quartz_stairs 6  
fill ~11 ~7 ~22 ~11 ~10 ~22 wool 8 
setblock ~11 ~7 ~37 quartz_stairs 5 
setblock ~11 ~7 ~38 wool 15 
setblock ~11 ~7 ~39 quartz_stairs 5  
fill ~11 ~7 ~47 ~11 ~7 ~48 leaves 15  
fill ~11 ~7 ~52 ~11 ~7 ~53 leaves 15  
fill ~11 ~7 ~72 ~12 ~7 ~72 wool 8 
setblock ~12 ~7 ~19 spruce_stairs 3 
setblock ~12 ~7 ~20 wool 15 
setblock ~12 ~7 ~38 spruce_stairs 0 
setblock ~12 ~7 ~58 quartz_stairs 7  
fill ~12 ~7 ~60 ~12 ~10 ~60 wool 8  
fill ~12 ~7 ~61 ~12 ~7 ~62 spruce_stairs 1  
fill ~12 ~7 ~65 ~12 ~7 ~66 spruce_stairs 1  
fill ~12 ~7 ~67 ~12 ~10 ~67 wool 8  
fill ~12 ~7 ~68 ~12 ~10 ~68 leaves 15 
setblock ~13 ~7 ~20 quartz_stairs 6  
fill ~13 ~7 ~23 ~14 ~7 ~23 wool 8 
setblock ~13 ~7 ~35 quartz_stairs 7  
fill ~13 ~7 ~37 ~13 ~11 ~37 planks 1  
fill ~13 ~7 ~38 ~13 ~9 ~38 leaves 15  
fill ~13 ~7 ~39 ~13 ~11 ~39 planks 1 
setblock ~13 ~7 ~41 quartz_stairs 6 
setblock ~13 ~7 ~51 quartz_stairs 7 
setblock ~13 ~7 ~54 quartz_stairs 6 
setblock ~13 ~7 ~58 wool 15 
setblock ~13 ~7 ~59 dark_oak_stairs 2  
fill ~13 ~7 ~60 ~14 ~7 ~60 wool 7  
fill ~13 ~7 ~61 ~13 ~7 ~62 dropper 0  
fill ~13 ~7 ~65 ~13 ~7 ~66 dropper 0  
fill ~13 ~7 ~67 ~14 ~7 ~67 wool 7  
fill ~13 ~7 ~68 ~14 ~7 ~68 dropper 0  
fill ~13 ~7 ~73 ~14 ~7 ~73 wool 7  
fill ~14 ~7 ~18 ~14 ~9 ~18 glass 0 
setblock ~14 ~7 ~22 leaves 12 
setblock ~14 ~7 ~35 wool 15 
setblock ~14 ~7 ~36 dark_oak_stairs 2  
fill ~14 ~7 ~37 ~14 ~9 ~37 leaves 11  
fill ~14 ~7 ~38 ~14 ~10 ~38 wool 15  
fill ~14 ~7 ~39 ~14 ~9 ~39 leaves 15 
setblock ~14 ~7 ~40 dark_oak_stairs 3 
setblock ~14 ~7 ~41 wool 15 
setblock ~14 ~7 ~51 wool 15 
setblock ~14 ~7 ~52 dark_oak_stairs 2 
setblock ~14 ~7 ~53 dark_oak_stairs 3 
setblock ~14 ~7 ~54 wool 15 
setblock ~14 ~7 ~58 quartz_stairs 7  
fill ~14 ~7 ~61 ~14 ~7 ~62 spruce_stairs 0  
fill ~14 ~7 ~65 ~14 ~7 ~66 spruce_stairs 0 
setblock ~14 ~7 ~72 wool 7  
fill ~15 ~7 ~19 ~15 ~11 ~19 planks 1  
fill ~15 ~7 ~20 ~15 ~9 ~20 glass 0  
fill ~15 ~7 ~21 ~15 ~10 ~21 glass 0  
fill ~15 ~7 ~22 ~15 ~10 ~22 glass 0  
fill ~15 ~7 ~24 ~16 ~7 ~24 glass 0 
setblock ~15 ~7 ~35 quartz_stairs 7  
fill ~15 ~7 ~37 ~15 ~11 ~37 planks 1  
fill ~15 ~7 ~38 ~15 ~9 ~38 leaves 15  
fill ~15 ~7 ~39 ~15 ~11 ~39 planks 1 
setblock ~15 ~7 ~41 quartz_stairs 6 
setblock ~15 ~7 ~51 quartz_stairs 7 
setblock ~15 ~7 ~54 quartz_stairs 6  
fill ~15 ~7 ~72 ~16 ~7 ~72 wool 8  
fill ~15 ~7 ~73 ~16 ~7 ~73 wool 8  
fill ~16 ~7 ~26 ~17 ~7 ~26 glass 0 
setblock ~16 ~7 ~38 spruce_stairs 1  
fill ~16 ~7 ~63 ~16 ~9 ~63 leaves 15  
fill ~16 ~7 ~64 ~16 ~10 ~64 leaves 15  
fill ~17 ~7 ~27 ~17 ~10 ~27 glass 0 
setblock ~17 ~7 ~37 quartz_stairs 4 
setblock ~17 ~7 ~38 wool 15 
setblock ~17 ~7 ~39 quartz_stairs 4  
fill ~17 ~7 ~47 ~17 ~7 ~48 leaves 15  
fill ~17 ~7 ~52 ~17 ~7 ~53 leaves 15  
fill ~17 ~7 ~74 ~18 ~7 ~74 wool 7  
fill ~18 ~7 ~28 ~18 ~10 ~28 glass 0  
fill ~18 ~7 ~29 ~18 ~10 ~29 glass 0  
fill ~18 ~7 ~30 ~18 ~10 ~30 glass 0  
fill ~19 ~7 ~31 ~20 ~7 ~31 glass 0 
setblock ~19 ~7 ~51 quartz_stairs 7 
setblock ~19 ~7 ~54 quartz_stairs 6  
fill ~19 ~7 ~72 ~20 ~7 ~72 wool 8  
fill ~19 ~7 ~73 ~20 ~7 ~73 wool 8  
fill ~19 ~7 ~74 ~20 ~7 ~74 wool 8  
fill ~20 ~7 ~32 ~20 ~10 ~32 glass 0  
fill ~20 ~7 ~33 ~20 ~7 ~35 wool 7 
setblock ~20 ~7 ~51 wool 15 
setblock ~20 ~7 ~52 dark_oak_stairs 2 
setblock ~20 ~7 ~53 dark_oak_stairs 7 
setblock ~20 ~7 ~54 wool 15  
fill ~20 ~7 ~59 ~20 ~8 ~59 leaves 11  
fill ~20 ~7 ~60 ~20 ~10 ~60 wool 8  
fill ~20 ~7 ~61 ~20 ~7 ~62 spruce_stairs 1  
fill ~20 ~7 ~65 ~20 ~7 ~66 spruce_stairs 1  
fill ~20 ~7 ~67 ~20 ~10 ~67 wool 8  
fill ~20 ~7 ~68 ~20 ~9 ~68 leaves 15  
fill ~21 ~7 ~33 ~21 ~10 ~33 glass 0  
fill ~21 ~7 ~36 ~21 ~7 ~38 wool 7 
setblock ~21 ~7 ~51 quartz_stairs 7 
setblock ~21 ~7 ~54 quartz_stairs 6 
setblock ~21 ~7 ~58 quartz_stairs 6  
fill ~21 ~7 ~60 ~22 ~7 ~60 wool 7  
fill ~21 ~7 ~61 ~22 ~7 ~61 dropper 0  
fill ~21 ~7 ~62 ~22 ~7 ~62 dropper 0  
fill ~21 ~7 ~65 ~22 ~7 ~65 dropper 0  
fill ~21 ~7 ~66 ~22 ~7 ~66 dropper 0  
fill ~21 ~7 ~67 ~22 ~7 ~67 wool 7  
fill ~21 ~7 ~68 ~22 ~7 ~68 dropper 0  
fill ~21 ~7 ~74 ~22 ~7 ~74 wool 7  
fill ~22 ~7 ~34 ~22 ~10 ~34 glass 0  
fill ~22 ~7 ~39 ~22 ~7 ~40 wool 7 
setblock ~22 ~7 ~58 wool 15 
setblock ~22 ~7 ~59 dark_oak_stairs 2  
fill ~23 ~7 ~35 ~24 ~7 ~35 glass 0 
setblock ~23 ~7 ~41 wool 7  
fill ~23 ~7 ~47 ~23 ~7 ~48 leaves 15  
fill ~23 ~7 ~52 ~23 ~7 ~53 leaves 15 
setblock ~23 ~7 ~58 quartz_stairs 6  
fill ~23 ~7 ~60 ~23 ~10 ~60 wool 8  
fill ~23 ~7 ~61 ~23 ~7 ~62 spruce_stairs 0  
fill ~23 ~7 ~65 ~23 ~7 ~66 spruce_stairs 0  
fill ~23 ~7 ~67 ~23 ~10 ~67 wool 8  
fill ~23 ~7 ~68 ~23 ~9 ~68 leaves 15  
fill ~23 ~7 ~72 ~24 ~7 ~72 wool 8  
fill ~23 ~7 ~73 ~24 ~7 ~73 wool 8  
fill ~23 ~7 ~74 ~24 ~7 ~74 wool 8 
setblock ~24 ~7 ~42 wool 7  
fill ~25 ~7 ~36 ~26 ~7 ~36 glass 0  
fill ~25 ~7 ~43 ~26 ~7 ~43 wool 7 
setblock ~25 ~7 ~51 quartz_stairs 7 
setblock ~25 ~7 ~54 quartz_stairs 6  
fill ~25 ~7 ~74 ~26 ~7 ~74 wool 7 
setblock ~26 ~7 ~51 wool 15 
setblock ~26 ~7 ~52 dark_oak_stairs 2 
setblock ~26 ~7 ~53 dark_oak_stairs 3 
setblock ~26 ~7 ~54 wool 15  
fill ~27 ~7 ~37 ~29 ~7 ~37 glass 0  
fill ~27 ~7 ~44 ~29 ~7 ~44 wool 7 
setblock ~27 ~7 ~51 quartz_stairs 7 
setblock ~27 ~7 ~54 quartz_stairs 6  
fill ~27 ~7 ~63 ~27 ~9 ~63 leaves 15  
fill ~27 ~7 ~64 ~27 ~10 ~64 leaves 15  
fill ~27 ~7 ~72 ~28 ~7 ~72 wool 8  
fill ~27 ~7 ~73 ~28 ~7 ~73 wool 8  
fill ~27 ~7 ~74 ~28 ~7 ~74 wool 8  
fill ~28 ~7 ~21 ~30 ~7 ~21 diamond_block 0  
fill ~29 ~7 ~47 ~29 ~7 ~48 leaves 15  
fill ~29 ~7 ~52 ~29 ~7 ~53 leaves 15 
setblock ~29 ~7 ~58 quartz_stairs 6  
fill ~29 ~7 ~60 ~30 ~7 ~60 wool 7  
fill ~29 ~7 ~61 ~29 ~7 ~62 spruce_stairs 1  
fill ~29 ~7 ~65 ~29 ~7 ~66 spruce_stairs 1  
fill ~29 ~7 ~67 ~30 ~7 ~67 wool 7  
fill ~29 ~7 ~68 ~30 ~7 ~68 dropper 0  
fill ~29 ~7 ~73 ~30 ~7 ~73 wool 7  
fill ~30 ~7 ~38 ~33 ~7 ~38 glass 0  
fill ~30 ~7 ~45 ~33 ~7 ~45 wool 7 
setblock ~30 ~7 ~58 wool 15  
fill ~30 ~7 ~61 ~30 ~7 ~62 dropper 0  
fill ~30 ~7 ~65 ~30 ~7 ~66 dropper 0 
setblock ~30 ~7 ~72 wool 7 
setblock ~31 ~7 ~51 quartz_stairs 6 
setblock ~31 ~7 ~54 quartz_stairs 6 
setblock ~31 ~7 ~58 quartz_stairs 6  
fill ~31 ~7 ~60 ~31 ~10 ~60 wool 8  
fill ~31 ~7 ~61 ~31 ~7 ~62 spruce_stairs 0  
fill ~31 ~7 ~65 ~31 ~7 ~66 spruce_stairs 0  
fill ~31 ~7 ~67 ~31 ~10 ~67 wool 8  
fill ~31 ~7 ~68 ~31 ~9 ~68 leaves 15  
fill ~31 ~7 ~72 ~32 ~7 ~72 wool 8  
fill ~31 ~7 ~73 ~32 ~7 ~73 wool 8 
setblock ~32 ~7 ~51 wool 15 
setblock ~32 ~7 ~52 dark_oak_stairs 2 
setblock ~32 ~7 ~53 dark_oak_stairs 3 
setblock ~32 ~7 ~54 wool 15 
setblock ~33 ~7 ~51 quartz_stairs 6 
setblock ~33 ~7 ~54 quartz_stairs 6  
fill ~34 ~7 ~39 ~38 ~7 ~39 glass 0  
fill ~34 ~7 ~46 ~38 ~7 ~46 wool 7  
fill ~34 ~7 ~70 ~34 ~10 ~70 wool 8  
fill ~35 ~7 ~47 ~35 ~7 ~48 leaves 15 
setblock ~35 ~7 ~52 leaves 15 
setblock ~35 ~7 ~53 leaves 11  
fill ~35 ~7 ~69 ~35 ~10 ~69 wool 8 
setblock ~36 ~7 ~50 quartz_stairs 7 
setblock ~36 ~7 ~54 quartz_stairs 6  
fill ~36 ~7 ~61 ~37 ~7 ~61 spruce_stairs 3  
fill ~36 ~7 ~62 ~37 ~7 ~62 dropper 0  
fill ~36 ~7 ~63 ~37 ~7 ~63 dropper 0  
fill ~36 ~7 ~64 ~37 ~7 ~64 spruce_stairs 2 
setblock ~37 ~7 ~50 wool 15 
setblock ~37 ~7 ~51 dark_oak_stairs 2 
setblock ~37 ~7 ~53 dark_oak_stairs 3 
setblock ~37 ~7 ~54 wool 15 
setblock ~38 ~7 ~50 quartz_stairs 7 
setblock ~38 ~7 ~54 quartz_stairs 6  
fill ~38 ~7 ~55 ~38 ~8 ~55 wool 8  
fill ~38 ~7 ~56 ~38 ~8 ~56 wool 8  
fill ~38 ~7 ~57 ~38 ~8 ~57 wool 8  
fill ~38 ~7 ~58 ~38 ~8 ~58 wool 8  
fill ~38 ~7 ~60 ~38 ~9 ~60 leaves 15  
fill ~39 ~7 ~37 ~39 ~8 ~37 wool 8  
fill ~39 ~7 ~38 ~39 ~8 ~38 wool 8  
fill ~39 ~7 ~39 ~39 ~8 ~39 wool 8  
fill ~39 ~7 ~40 ~39 ~8 ~40 wool 8  
fill ~39 ~7 ~41 ~39 ~8 ~41 wool 8  
fill ~39 ~7 ~42 ~39 ~8 ~42 wool 8  
fill ~39 ~7 ~43 ~39 ~8 ~43 wool 8  
fill ~39 ~7 ~44 ~39 ~8 ~44 wool 8  
fill ~39 ~7 ~45 ~39 ~8 ~45 wool 8  
fill ~39 ~7 ~46 ~39 ~8 ~46 wool 8  
fill ~39 ~7 ~47 ~39 ~8 ~47 wool 8  
fill ~39 ~7 ~48 ~39 ~8 ~48 wool 8  
fill ~39 ~7 ~49 ~39 ~8 ~49 wool 8  
fill ~39 ~7 ~50 ~39 ~8 ~50 wool 8  
fill ~39 ~7 ~51 ~39 ~8 ~51 wool 8  
fill ~39 ~7 ~52 ~39 ~8 ~52 wool 8  
fill ~39 ~7 ~53 ~39 ~8 ~53 wool 8  
fill ~39 ~7 ~54 ~39 ~8 ~54 wool 8  
fill ~7 ~8 ~31 ~7 ~10 ~31 leaves 15  
fill ~7 ~8 ~62 ~8 ~8 ~62 carpet 15  
fill ~7 ~8 ~63 ~8 ~8 ~63 carpet 15 
setblock ~9 ~8 ~32 flower_pot 0 
setblock ~9 ~8 ~33 heavy_weighted_pressure_plate 0 
setblock ~9 ~8 ~34 lever 13 
setblock ~9 ~8 ~36 flower_pot 0 
setblock ~9 ~8 ~37 heavy_weighted_pressure_plate 0 
setblock ~9 ~8 ~38 lever 13 
setblock ~9 ~8 ~40 flower_pot 0 
setblock ~9 ~8 ~41 heavy_weighted_pressure_plate 0 
setblock ~9 ~8 ~42 lever 13  
fill ~10 ~8 ~21 ~10 ~10 ~21 dropper 2  
fill ~10 ~8 ~22 ~10 ~10 ~22 dropper 2  
fill ~10 ~8 ~23 ~11 ~8 ~23 wool 8 
setblock ~10 ~8 ~24 flower_pot 0 
setblock ~10 ~8 ~25 heavy_weighted_pressure_plate 0 
setblock ~10 ~8 ~26 lever 13 
setblock ~10 ~8 ~28 flower_pot 0 
setblock ~10 ~8 ~29 heavy_weighted_pressure_plate 0 
setblock ~10 ~8 ~30 lever 13  
fill ~11 ~8 ~17 ~13 ~8 ~17 glass 0 
setblock ~11 ~8 ~20 lever 13 
setblock ~11 ~8 ~37 lever 6 
setblock ~11 ~8 ~38 heavy_weighted_pressure_plate 0 
setblock ~11 ~8 ~39 flower_pot 0  
fill ~11 ~8 ~47 ~11 ~9 ~47 leaves 11  
fill ~11 ~8 ~48 ~11 ~9 ~48 leaves 11  
fill ~11 ~8 ~52 ~11 ~8 ~53 dropper 2  
fill ~11 ~8 ~72 ~12 ~8 ~72 wool 8 
setblock ~12 ~8 ~20 heavy_weighted_pressure_plate 0 
setblock ~12 ~8 ~58 flower_pot 0 
setblock ~13 ~8 ~20 flower_pot 0  
fill ~13 ~8 ~23 ~14 ~8 ~23 wool 8 
setblock ~13 ~8 ~35 flower_pot 0 
setblock ~13 ~8 ~41 lever 13 
setblock ~13 ~8 ~51 flower_pot 0 
setblock ~13 ~8 ~54 lever 13 
setblock ~13 ~8 ~58 heavy_weighted_pressure_plate 0  
fill ~13 ~8 ~60 ~14 ~8 ~60 wool 7  
fill ~13 ~8 ~61 ~13 ~8 ~62 carpet 15  
fill ~13 ~8 ~65 ~13 ~8 ~66 carpet 15  
fill ~13 ~8 ~67 ~14 ~8 ~67 wool 7  
fill ~13 ~8 ~68 ~14 ~8 ~68 dropper 0  
fill ~13 ~8 ~73 ~13 ~143 ~73 wool 7  
fill ~14 ~8 ~22 ~14 ~10 ~22 leaves 8 
setblock ~14 ~8 ~35 heavy_weighted_pressure_plate 0 
setblock ~14 ~8 ~41 heavy_weighted_pressure_plate 0 
setblock ~14 ~8 ~51 heavy_weighted_pressure_plate 0 
setblock ~14 ~8 ~54 heavy_weighted_pressure_plate 0 
setblock ~14 ~8 ~58 lever 5  
fill ~14 ~8 ~72 ~14 ~10 ~72 glass 0  
fill ~14 ~8 ~73 ~14 ~10 ~73 glass 0  
fill ~15 ~8 ~23 ~15 ~10 ~23 glass 0  
fill ~15 ~8 ~24 ~16 ~8 ~24 glass 0 
setblock ~15 ~8 ~35 lever 5 
setblock ~15 ~8 ~41 flower_pot 0 
setblock ~15 ~8 ~51 lever 5 
setblock ~15 ~8 ~54 flower_pot 0  
fill ~15 ~8 ~72 ~16 ~8 ~72 wool 8  
fill ~15 ~8 ~73 ~16 ~8 ~73 wool 8  
fill ~16 ~8 ~25 ~16 ~10 ~25 glass 0  
fill ~16 ~8 ~26 ~17 ~8 ~26 glass 0 
setblock ~17 ~8 ~37 flower_pot 0 
setblock ~17 ~8 ~38 heavy_weighted_pressure_plate 0 
setblock ~17 ~8 ~39 lever 14  
fill ~17 ~8 ~47 ~17 ~9 ~47 leaves 11  
fill ~17 ~8 ~48 ~17 ~9 ~48 leaves 11  
fill ~17 ~8 ~52 ~17 ~8 ~53 dropper 2  
fill ~17 ~8 ~74 ~18 ~8 ~74 wool 7  
fill ~19 ~8 ~31 ~20 ~8 ~31 glass 0 
setblock ~19 ~8 ~51 flower_pot 0 
setblock ~19 ~8 ~54 lever 13  
fill ~19 ~8 ~72 ~20 ~8 ~72 wool 8  
fill ~19 ~8 ~73 ~20 ~8 ~73 wool 8  
fill ~19 ~8 ~74 ~20 ~8 ~74 wool 8  
fill ~20 ~8 ~33 ~20 ~8 ~35 carpet 15 
setblock ~20 ~8 ~51 heavy_weighted_pressure_plate 0 
setblock ~20 ~8 ~54 heavy_weighted_pressure_plate 0  
fill ~21 ~8 ~36 ~21 ~8 ~38 carpet 15 
setblock ~21 ~8 ~51 lever 5 
setblock ~21 ~8 ~54 flower_pot 0 
setblock ~21 ~8 ~58 flower_pot 0  
fill ~21 ~8 ~60 ~22 ~8 ~60 wool 7  
fill ~21 ~8 ~61 ~22 ~8 ~61 carpet 15  
fill ~21 ~8 ~62 ~22 ~8 ~62 carpet 15  
fill ~21 ~8 ~65 ~22 ~8 ~65 carpet 15  
fill ~21 ~8 ~66 ~22 ~8 ~66 carpet 15  
fill ~21 ~8 ~67 ~22 ~8 ~67 wool 7  
fill ~21 ~8 ~74 ~22 ~8 ~74 wool 7  
fill ~22 ~8 ~39 ~22 ~8 ~40 carpet 15 
setblock ~22 ~8 ~58 heavy_weighted_pressure_plate 0  
fill ~23 ~8 ~35 ~24 ~8 ~35 glass 0 
setblock ~23 ~8 ~41 carpet 15  
fill ~23 ~8 ~47 ~23 ~9 ~47 leaves 11  
fill ~23 ~8 ~48 ~23 ~9 ~48 leaves 11  
fill ~23 ~8 ~52 ~23 ~8 ~53 dropper 2 
setblock ~23 ~8 ~58 lever 13  
fill ~23 ~8 ~72 ~24 ~8 ~72 wool 8  
fill ~23 ~8 ~73 ~24 ~8 ~73 wool 8  
fill ~23 ~8 ~74 ~24 ~8 ~74 wool 8 
setblock ~24 ~8 ~42 carpet 15  
fill ~25 ~8 ~36 ~26 ~8 ~36 glass 0  
fill ~25 ~8 ~43 ~26 ~8 ~43 carpet 15 
setblock ~25 ~8 ~51 flower_pot 0 
setblock ~25 ~8 ~54 lever 13  
fill ~25 ~8 ~74 ~26 ~8 ~74 wool 7 
setblock ~26 ~8 ~51 heavy_weighted_pressure_plate 0 
setblock ~26 ~8 ~54 heavy_weighted_pressure_plate 0  
fill ~27 ~8 ~37 ~29 ~8 ~37 glass 0  
fill ~27 ~8 ~44 ~29 ~8 ~44 carpet 15 
setblock ~27 ~8 ~51 lever 5 
setblock ~27 ~8 ~54 flower_pot 0  
fill ~27 ~8 ~72 ~28 ~8 ~72 wool 8  
fill ~27 ~8 ~73 ~28 ~8 ~73 wool 8  
fill ~27 ~8 ~74 ~28 ~8 ~74 wool 8 
setblock ~28 ~8 ~22 diamond_block 0  
fill ~29 ~8 ~47 ~29 ~9 ~47 leaves 11  
fill ~29 ~8 ~48 ~29 ~9 ~48 leaves 11  
fill ~29 ~8 ~52 ~29 ~8 ~53 dropper 2 
setblock ~29 ~8 ~58 flower_pot 0  
fill ~29 ~8 ~60 ~30 ~8 ~60 wool 7  
fill ~29 ~8 ~67 ~30 ~8 ~67 wool 7  
fill ~29 ~8 ~68 ~30 ~8 ~68 dropper 0  
fill ~29 ~8 ~73 ~29 ~143 ~73 wool 7 
setblock ~30 ~8 ~22 diamond_block 0  
fill ~30 ~8 ~38 ~33 ~8 ~38 glass 0  
fill ~30 ~8 ~45 ~33 ~8 ~45 carpet 15 
setblock ~30 ~8 ~58 heavy_weighted_pressure_plate 0  
fill ~30 ~8 ~61 ~30 ~8 ~62 carpet 15  
fill ~30 ~8 ~65 ~30 ~8 ~66 carpet 15  
fill ~30 ~8 ~72 ~30 ~10 ~72 glass 0  
fill ~30 ~8 ~73 ~30 ~10 ~73 glass 0 
setblock ~31 ~8 ~51 flower_pot 0 
setblock ~31 ~8 ~54 lever 13 
setblock ~31 ~8 ~58 lever 13  
fill ~31 ~8 ~72 ~32 ~8 ~72 wool 8  
fill ~31 ~8 ~73 ~32 ~8 ~73 wool 8 
setblock ~32 ~8 ~51 heavy_weighted_pressure_plate 0 
setblock ~32 ~8 ~54 heavy_weighted_pressure_plate 0 
setblock ~33 ~8 ~51 lever 13 
setblock ~33 ~8 ~54 flower_pot 0  
fill ~34 ~8 ~39 ~38 ~8 ~39 glass 0  
fill ~34 ~8 ~46 ~38 ~8 ~46 carpet 15  
fill ~35 ~8 ~47 ~35 ~9 ~47 leaves 11  
fill ~35 ~8 ~48 ~35 ~9 ~48 leaves 11  
fill ~35 ~8 ~52 ~35 ~8 ~53 dropper 2 
setblock ~36 ~8 ~50 flower_pot 0 
setblock ~36 ~8 ~54 lever 13  
fill ~36 ~8 ~62 ~37 ~8 ~62 carpet 15  
fill ~36 ~8 ~63 ~37 ~8 ~63 carpet 15 
setblock ~37 ~8 ~50 heavy_weighted_pressure_plate 0 
setblock ~37 ~8 ~54 heavy_weighted_pressure_plate 0  
fill ~37 ~8 ~66 ~37 ~10 ~66 glass 0 
setblock ~38 ~8 ~50 lever 5 
setblock ~38 ~8 ~54 flower_pot 0 
setblock ~10 ~9 ~20 dropper 2  
fill ~10 ~9 ~23 ~11 ~9 ~23 wool 8  
fill ~11 ~9 ~17 ~13 ~9 ~17 glass 0  
fill ~11 ~9 ~52 ~11 ~9 ~53 dropper 0  
fill ~11 ~9 ~72 ~12 ~9 ~72 wool 8  
fill ~12 ~9 ~22 ~13 ~9 ~22 dropper 0 
setblock ~12 ~9 ~23 spruce_stairs 3  
fill ~13 ~9 ~23 ~14 ~9 ~23 wool 8  
fill ~13 ~9 ~60 ~14 ~9 ~60 wool 7  
fill ~13 ~9 ~67 ~14 ~9 ~67 wool 7  
fill ~13 ~9 ~68 ~14 ~9 ~68 dropper 0  
fill ~15 ~9 ~24 ~16 ~9 ~24 glass 0  
fill ~15 ~9 ~72 ~16 ~9 ~72 wool 8  
fill ~15 ~9 ~73 ~16 ~9 ~73 wool 8  
fill ~16 ~9 ~26 ~17 ~9 ~26 glass 0  
fill ~17 ~9 ~52 ~17 ~9 ~53 dropper 0  
fill ~17 ~9 ~74 ~18 ~9 ~74 wool 7  
fill ~19 ~9 ~31 ~20 ~9 ~31 glass 0  
fill ~19 ~9 ~72 ~20 ~9 ~72 wool 8  
fill ~19 ~9 ~73 ~20 ~9 ~73 wool 8  
fill ~19 ~9 ~74 ~20 ~9 ~74 wool 8 
setblock ~20 ~9 ~59 leaves 15  
fill ~21 ~9 ~60 ~22 ~9 ~60 wool 7  
fill ~21 ~9 ~67 ~22 ~9 ~67 wool 7  
fill ~21 ~9 ~68 ~22 ~9 ~68 dropper 0  
fill ~21 ~9 ~74 ~22 ~9 ~74 wool 7  
fill ~23 ~9 ~35 ~24 ~9 ~35 glass 0  
fill ~23 ~9 ~52 ~23 ~9 ~53 dropper 0  
fill ~23 ~9 ~72 ~24 ~9 ~72 wool 8  
fill ~23 ~9 ~73 ~24 ~9 ~73 wool 8  
fill ~23 ~9 ~74 ~24 ~9 ~74 wool 8  
fill ~25 ~9 ~36 ~26 ~9 ~36 glass 0  
fill ~25 ~9 ~74 ~26 ~9 ~74 wool 7  
fill ~27 ~9 ~37 ~29 ~9 ~37 glass 0  
fill ~27 ~9 ~72 ~28 ~9 ~72 wool 8  
fill ~27 ~9 ~73 ~28 ~9 ~73 wool 8  
fill ~27 ~9 ~74 ~28 ~9 ~74 wool 8 
setblock ~28 ~9 ~23 diamond_block 0  
fill ~29 ~9 ~52 ~29 ~9 ~53 dropper 0  
fill ~29 ~9 ~60 ~30 ~9 ~60 wool 7  
fill ~29 ~9 ~67 ~30 ~9 ~67 wool 7  
fill ~29 ~9 ~68 ~30 ~9 ~68 dropper 0 
setblock ~30 ~9 ~23 diamond_block 0  
fill ~30 ~9 ~38 ~33 ~9 ~38 glass 0  
fill ~31 ~9 ~72 ~32 ~9 ~72 wool 8  
fill ~31 ~9 ~73 ~32 ~9 ~73 wool 8  
fill ~34 ~9 ~39 ~38 ~9 ~39 glass 0  
fill ~35 ~9 ~52 ~35 ~9 ~53 dropper 0  
fill ~38 ~9 ~55 ~38 ~11 ~55 wool 7  
fill ~38 ~9 ~56 ~38 ~10 ~56 wool 7  
fill ~38 ~9 ~57 ~38 ~10 ~57 wool 7  
fill ~38 ~9 ~58 ~38 ~9 ~55 wool 7  
fill ~39 ~9 ~37 ~39 ~10 ~37 wool 7  
fill ~39 ~9 ~38 ~39 ~10 ~38 wool 7  
fill ~39 ~9 ~39 ~39 ~10 ~39 wool 7  
fill ~39 ~9 ~40 ~39 ~10 ~40 wool 7  
fill ~39 ~9 ~41 ~39 ~10 ~41 wool 7  
fill ~39 ~9 ~42 ~39 ~10 ~42 wool 7  
fill ~39 ~9 ~43 ~39 ~10 ~43 wool 7  
fill ~39 ~9 ~44 ~39 ~10 ~44 wool 7  
fill ~39 ~9 ~45 ~39 ~10 ~45 wool 7  
fill ~39 ~9 ~46 ~39 ~10 ~46 wool 7  
fill ~39 ~9 ~47 ~39 ~10 ~47 wool 7  
fill ~39 ~9 ~48 ~39 ~10 ~48 wool 7  
fill ~39 ~9 ~49 ~39 ~10 ~49 wool 7  
fill ~39 ~9 ~50 ~39 ~10 ~50 wool 7  
fill ~39 ~9 ~51 ~39 ~10 ~51 wool 7  
fill ~39 ~9 ~52 ~39 ~10 ~52 wool 7  
fill ~39 ~9 ~53 ~39 ~10 ~53 wool 7  
fill ~39 ~9 ~54 ~39 ~10 ~54 wool 7 
setblock ~5 ~10 ~52 leaves 11 
setblock ~6 ~10 ~60 leaves 11 
setblock ~10 ~10 ~19 glass 0  
fill ~10 ~10 ~23 ~14 ~10 ~23 wool 8  
fill ~11 ~10 ~18 ~13 ~10 ~18 glass 0  
fill ~11 ~10 ~47 ~11 ~10 ~48 leaves 15  
fill ~11 ~10 ~52 ~11 ~10 ~53 leaves 15  
fill ~11 ~10 ~72 ~12 ~10 ~72 wool 8  
fill ~12 ~10 ~22 ~13 ~10 ~22 dropper 0 
setblock ~12 ~10 ~38 spruce_stairs 4 
setblock ~13 ~10 ~38 glowstone 0  
fill ~13 ~10 ~60 ~14 ~10 ~60 wool 7  
fill ~13 ~10 ~67 ~14 ~10 ~67 wool 7  
fill ~13 ~10 ~68 ~14 ~10 ~68 dropper 0 
setblock ~14 ~10 ~19 glass 0 
setblock ~14 ~10 ~36 spruce_stairs 6 
setblock ~14 ~10 ~37 glowstone 0  
fill ~14 ~10 ~39 ~14 ~11 ~39 glowstone 0 
setblock ~14 ~10 ~40 spruce_stairs 7  
fill ~15 ~10 ~20 ~15 ~16 ~20 planks 1  
fill ~15 ~10 ~24 ~16 ~10 ~24 glass 0 
setblock ~15 ~10 ~38 glowstone 0  
fill ~15 ~10 ~71 ~28 ~10 ~71 wool 8  
fill ~15 ~10 ~72 ~16 ~10 ~72 wool 8  
fill ~15 ~10 ~73 ~16 ~10 ~73 wool 8  
fill ~16 ~10 ~26 ~17 ~10 ~26 glass 0 
setblock ~16 ~10 ~38 spruce_stairs 5 
setblock ~16 ~10 ~63 leaves 11  
fill ~17 ~10 ~47 ~17 ~10 ~48 leaves 15  
fill ~17 ~10 ~52 ~17 ~10 ~53 leaves 15  
fill ~17 ~10 ~74 ~18 ~10 ~74 wool 7  
fill ~19 ~10 ~31 ~20 ~10 ~31 glass 0  
fill ~19 ~10 ~72 ~20 ~10 ~72 wool 8  
fill ~19 ~10 ~73 ~20 ~10 ~73 wool 8  
fill ~19 ~10 ~74 ~20 ~10 ~74 wool 8 
setblock ~20 ~10 ~59 leaves 11 
setblock ~20 ~10 ~68 leaves 11  
fill ~21 ~10 ~60 ~22 ~10 ~60 wool 7  
fill ~21 ~10 ~67 ~22 ~10 ~67 wool 7  
fill ~21 ~10 ~68 ~22 ~10 ~68 dropper 0  
fill ~21 ~10 ~74 ~22 ~10 ~74 wool 7  
fill ~23 ~10 ~35 ~24 ~10 ~35 glass 0  
fill ~23 ~10 ~47 ~23 ~10 ~48 leaves 15  
fill ~23 ~10 ~52 ~23 ~10 ~53 leaves 15 
setblock ~23 ~10 ~68 leaves 11  
fill ~23 ~10 ~72 ~24 ~10 ~72 wool 8  
fill ~23 ~10 ~73 ~24 ~10 ~73 wool 8  
fill ~23 ~10 ~74 ~24 ~10 ~74 wool 8  
fill ~25 ~10 ~36 ~26 ~10 ~36 glass 0  
fill ~25 ~10 ~74 ~26 ~10 ~74 wool 7  
fill ~27 ~10 ~37 ~29 ~10 ~37 glass 0 
setblock ~27 ~10 ~63 leaves 11  
fill ~27 ~10 ~72 ~28 ~10 ~72 wool 8  
fill ~27 ~10 ~73 ~28 ~10 ~73 wool 8  
fill ~27 ~10 ~74 ~28 ~10 ~74 wool 8 
setblock ~28 ~10 ~24 diamond_block 0  
fill ~29 ~10 ~47 ~29 ~10 ~48 leaves 15  
fill ~29 ~10 ~52 ~29 ~10 ~53 leaves 15  
fill ~29 ~10 ~60 ~30 ~10 ~60 wool 7  
fill ~29 ~10 ~67 ~30 ~10 ~67 wool 7  
fill ~29 ~10 ~68 ~30 ~10 ~68 dropper 0 
setblock ~30 ~10 ~24 diamond_block 0  
fill ~30 ~10 ~38 ~33 ~10 ~38 glass 0 
setblock ~31 ~10 ~68 leaves 11  
fill ~31 ~10 ~72 ~32 ~10 ~72 wool 8  
fill ~31 ~10 ~73 ~32 ~10 ~73 wool 8  
fill ~34 ~10 ~39 ~38 ~10 ~39 glass 0  
fill ~35 ~10 ~47 ~35 ~10 ~48 leaves 15  
fill ~35 ~10 ~52 ~35 ~10 ~53 leaves 15 
setblock ~38 ~10 ~60 leaves 11  
fill ~39 ~10 ~58 ~39 ~103 ~58 wool 8 
setblock ~5 ~11 ~52 glowstone 0  
fill ~5 ~11 ~53 ~10 ~11 ~53 planks 1  
fill ~5 ~11 ~54 ~38 ~11 ~54 planks 1  
fill ~5 ~11 ~55 ~37 ~11 ~55 planks 1  
fill ~5 ~11 ~56 ~37 ~11 ~56 planks 1  
fill ~5 ~11 ~57 ~37 ~11 ~57 planks 1  
fill ~6 ~11 ~48 ~10 ~11 ~48 planks 1  
fill ~6 ~11 ~49 ~38 ~11 ~49 planks 1  
fill ~6 ~11 ~50 ~38 ~11 ~50 planks 1  
fill ~6 ~11 ~51 ~38 ~11 ~51 planks 1  
fill ~6 ~11 ~52 ~10 ~11 ~52 planks 1  
fill ~6 ~11 ~58 ~38 ~11 ~58 planks 1  
fill ~6 ~11 ~59 ~19 ~11 ~59 planks 1 
setblock ~6 ~11 ~60 glowstone 0 
setblock ~7 ~11 ~31 glowstone 0  
fill ~7 ~11 ~32 ~20 ~11 ~32 planks 1  
fill ~7 ~11 ~33 ~21 ~11 ~33 planks 1  
fill ~7 ~11 ~34 ~22 ~11 ~34 planks 1  
fill ~7 ~11 ~35 ~24 ~11 ~35 planks 1  
fill ~7 ~11 ~36 ~26 ~11 ~36 planks 1  
fill ~7 ~11 ~37 ~29 ~11 ~37 planks 1  
fill ~7 ~11 ~38 ~33 ~11 ~38 planks 1  
fill ~7 ~11 ~39 ~13 ~11 ~39 planks 1  
fill ~7 ~11 ~40 ~38 ~11 ~40 planks 1  
fill ~7 ~11 ~41 ~38 ~11 ~41 planks 1  
fill ~7 ~11 ~42 ~38 ~11 ~42 planks 1  
fill ~7 ~11 ~43 ~38 ~11 ~43 planks 1  
fill ~7 ~11 ~44 ~38 ~11 ~44 planks 1  
fill ~7 ~11 ~45 ~38 ~11 ~45 planks 1  
fill ~7 ~11 ~46 ~38 ~11 ~46 planks 1  
fill ~7 ~11 ~47 ~10 ~11 ~47 planks 1  
fill ~7 ~11 ~60 ~37 ~11 ~60 planks 1  
fill ~7 ~11 ~61 ~37 ~11 ~61 planks 1  
fill ~7 ~11 ~62 ~37 ~11 ~62 planks 1  
fill ~7 ~11 ~63 ~15 ~11 ~63 planks 1  
fill ~7 ~11 ~64 ~15 ~11 ~64 planks 1  
fill ~7 ~11 ~65 ~36 ~11 ~65 planks 1  
fill ~8 ~11 ~31 ~8 ~76 ~31 wool 7  
fill ~8 ~11 ~66 ~36 ~11 ~66 planks 1  
fill ~8 ~11 ~67 ~36 ~11 ~67 planks 1  
fill ~9 ~11 ~24 ~16 ~11 ~24 planks 1  
fill ~9 ~11 ~25 ~15 ~11 ~25 planks 1  
fill ~9 ~11 ~26 ~17 ~11 ~26 planks 1  
fill ~9 ~11 ~27 ~16 ~11 ~27 planks 1  
fill ~9 ~11 ~28 ~18 ~11 ~28 planks 1  
fill ~9 ~11 ~29 ~17 ~11 ~29 planks 1  
fill ~9 ~11 ~30 ~19 ~11 ~30 planks 1  
fill ~9 ~11 ~31 ~20 ~11 ~31 planks 1  
fill ~9 ~11 ~68 ~11 ~11 ~68 planks 1  
fill ~9 ~11 ~69 ~35 ~11 ~69 planks 1 
setblock ~10 ~11 ~18 planks 1 
setblock ~10 ~11 ~19 glowstone 0  
fill ~10 ~11 ~20 ~16 ~11 ~20 planks 1  
fill ~10 ~11 ~21 ~14 ~11 ~21 planks 1  
fill ~10 ~11 ~22 ~14 ~11 ~22 planks 1  
fill ~10 ~11 ~23 ~14 ~11 ~23 planks 1  
fill ~10 ~11 ~70 ~34 ~11 ~70 planks 1  
fill ~11 ~11 ~17 ~13 ~11 ~17 planks 1  
fill ~11 ~11 ~18 ~13 ~11 ~18 glowstone 0  
fill ~11 ~11 ~19 ~13 ~11 ~19 planks 1  
fill ~11 ~11 ~47 ~11 ~11 ~48 glowstone 0  
fill ~11 ~11 ~52 ~11 ~11 ~53 glowstone 0  
fill ~11 ~11 ~71 ~33 ~11 ~71 planks 1  
fill ~11 ~11 ~72 ~12 ~11 ~72 wool 8  
fill ~12 ~11 ~47 ~15 ~11 ~47 planks 1  
fill ~12 ~11 ~48 ~16 ~11 ~48 planks 1  
fill ~12 ~11 ~52 ~16 ~11 ~52 planks 1  
fill ~12 ~11 ~53 ~16 ~11 ~53 planks 1 
setblock ~12 ~11 ~68 glowstone 0  
fill ~13 ~11 ~68 ~19 ~11 ~68 planks 1 
setblock ~14 ~11 ~18 planks 1 
setblock ~14 ~11 ~19 glowstone 0 
setblock ~14 ~11 ~72 glowstone 0  
fill ~14 ~11 ~73 ~14 ~12 ~73 wool 7  
fill ~15 ~11 ~21 ~15 ~11 ~23 glowstone 0  
fill ~15 ~11 ~72 ~16 ~11 ~72 wool 8  
fill ~15 ~11 ~73 ~16 ~11 ~73 wool 8  
fill ~16 ~11 ~21 ~16 ~11 ~24 planks 1 
setblock ~16 ~11 ~25 glowstone 0  
fill ~16 ~11 ~39 ~38 ~11 ~39 planks 1  
fill ~16 ~11 ~63 ~16 ~11 ~64 glowstone 0 
setblock ~17 ~11 ~25 planks 1 
setblock ~17 ~11 ~27 glowstone 0  
fill ~17 ~11 ~47 ~17 ~11 ~48 glowstone 0  
fill ~17 ~11 ~52 ~17 ~11 ~53 glowstone 0  
fill ~17 ~11 ~63 ~26 ~11 ~63 planks 1  
fill ~17 ~11 ~64 ~26 ~11 ~64 planks 1  
fill ~17 ~11 ~74 ~18 ~11 ~74 wool 7 
setblock ~18 ~11 ~27 planks 1 
setblock ~18 ~11 ~29 glowstone 0  
fill ~18 ~11 ~47 ~22 ~11 ~47 planks 1  
fill ~18 ~11 ~48 ~22 ~11 ~48 planks 1  
fill ~18 ~11 ~52 ~22 ~11 ~52 planks 1  
fill ~18 ~11 ~53 ~22 ~11 ~53 planks 1 
setblock ~19 ~11 ~29 planks 1  
fill ~19 ~11 ~72 ~20 ~11 ~72 wool 8  
fill ~19 ~11 ~73 ~20 ~11 ~73 wool 8  
fill ~19 ~11 ~74 ~20 ~11 ~74 wool 8 
setblock ~20 ~11 ~59 glowstone 0 
setblock ~20 ~11 ~68 glowstone 0  
fill ~21 ~11 ~59 ~38 ~11 ~59 planks 1  
fill ~21 ~11 ~68 ~22 ~11 ~68 planks 1  
fill ~21 ~11 ~74 ~22 ~11 ~74 wool 7  
fill ~23 ~11 ~47 ~23 ~11 ~48 glowstone 0  
fill ~23 ~11 ~52 ~23 ~11 ~53 glowstone 0 
setblock ~23 ~11 ~68 glowstone 0  
fill ~23 ~11 ~72 ~24 ~11 ~72 wool 8  
fill ~23 ~11 ~73 ~24 ~11 ~73 wool 8  
fill ~23 ~11 ~74 ~24 ~11 ~74 wool 8  
fill ~24 ~11 ~47 ~28 ~11 ~47 planks 1  
fill ~24 ~11 ~48 ~28 ~11 ~48 planks 1  
fill ~24 ~11 ~52 ~28 ~11 ~52 planks 1  
fill ~24 ~11 ~53 ~28 ~11 ~53 planks 1  
fill ~24 ~11 ~68 ~30 ~11 ~68 planks 1  
fill ~25 ~11 ~74 ~26 ~11 ~74 wool 7  
fill ~27 ~11 ~63 ~27 ~11 ~64 glowstone 0  
fill ~27 ~11 ~72 ~28 ~11 ~72 wool 8  
fill ~27 ~11 ~73 ~28 ~11 ~73 wool 8  
fill ~27 ~11 ~74 ~28 ~11 ~74 wool 8 
setblock ~28 ~11 ~25 diamond_block 0  
fill ~28 ~11 ~63 ~37 ~11 ~63 planks 1  
fill ~28 ~11 ~64 ~37 ~11 ~64 planks 1  
fill ~29 ~11 ~47 ~29 ~11 ~48 glowstone 0  
fill ~29 ~11 ~52 ~29 ~11 ~53 glowstone 0 
setblock ~30 ~11 ~25 diamond_block 0  
fill ~30 ~11 ~47 ~34 ~11 ~47 planks 1  
fill ~30 ~11 ~48 ~34 ~11 ~48 planks 1  
fill ~30 ~11 ~52 ~34 ~11 ~52 planks 1  
fill ~30 ~11 ~53 ~34 ~11 ~53 planks 1 
setblock ~30 ~11 ~72 glowstone 0  
fill ~30 ~11 ~73 ~30 ~12 ~73 wool 7 
setblock ~31 ~11 ~68 glowstone 0  
fill ~31 ~11 ~72 ~32 ~11 ~72 wool 8  
fill ~31 ~11 ~73 ~32 ~11 ~73 wool 8  
fill ~32 ~11 ~68 ~35 ~11 ~68 planks 1  
fill ~35 ~11 ~47 ~35 ~11 ~48 glowstone 0  
fill ~35 ~11 ~52 ~35 ~11 ~53 glowstone 0  
fill ~36 ~11 ~47 ~38 ~11 ~47 planks 1  
fill ~36 ~11 ~48 ~38 ~11 ~48 planks 1  
fill ~36 ~11 ~52 ~38 ~11 ~52 planks 1  
fill ~36 ~11 ~53 ~38 ~11 ~53 planks 1  
fill ~37 ~11 ~66 ~37 ~12 ~66 wool 8  
fill ~38 ~11 ~56 ~38 ~12 ~56 wool 8  
fill ~38 ~11 ~57 ~38 ~12 ~57 wool 8 
setblock ~38 ~11 ~60 glowstone 0  
fill ~39 ~11 ~38 ~39 ~11 ~54 wool 8  
fill ~5 ~12 ~52 ~5 ~14 ~52 leaves 15 
setblock ~6 ~12 ~57 spruce_stairs 1  
fill ~6 ~12 ~60 ~6 ~14 ~60 leaves 15  
fill ~7 ~12 ~31 ~7 ~21 ~31 wool 7 
setblock ~7 ~12 ~32 leaves 11 
setblock ~7 ~12 ~51 spruce_stairs 1 
setblock ~7 ~12 ~54 spruce_stairs 1  
fill ~7 ~12 ~56 ~7 ~12 ~58 wool 7  
fill ~7 ~12 ~61 ~8 ~12 ~61 spruce_stairs 3  
fill ~7 ~12 ~62 ~8 ~12 ~62 sandstone 0  
fill ~7 ~12 ~63 ~8 ~12 ~63 sandstone 0  
fill ~7 ~12 ~64 ~8 ~12 ~64 spruce_stairs 2 
setblock ~8 ~12 ~34 spruce_stairs 1 
setblock ~8 ~12 ~38 spruce_stairs 1 
setblock ~8 ~12 ~42 spruce_stairs 1  
fill ~8 ~12 ~50 ~8 ~12 ~55 wool 7  
fill ~9 ~12 ~24 ~9 ~14 ~24 leaves 15 
setblock ~9 ~12 ~26 spruce_stairs 1 
setblock ~9 ~12 ~30 spruce_stairs 1  
fill ~9 ~12 ~33 ~9 ~12 ~35 wool 7  
fill ~9 ~12 ~37 ~9 ~12 ~39 wool 7  
fill ~9 ~12 ~41 ~9 ~12 ~43 wool 7  
fill ~9 ~12 ~69 ~9 ~15 ~69 wool 8  
fill ~10 ~12 ~19 ~10 ~14 ~19 glass 0  
fill ~10 ~12 ~23 ~10 ~15 ~23 stone_slab 1  
fill ~10 ~12 ~24 ~11 ~12 ~24 wool 8  
fill ~10 ~12 ~25 ~10 ~12 ~27 wool 7  
fill ~10 ~12 ~29 ~10 ~12 ~31 wool 7  
fill ~11 ~12 ~18 ~13 ~12 ~18 glass 0  
fill ~11 ~12 ~21 ~13 ~12 ~21 wool 7  
fill ~11 ~12 ~23 ~11 ~15 ~23 wool 8 
setblock ~11 ~12 ~38 quartz_stairs 5 
setblock ~11 ~12 ~39 wool 15 
setblock ~11 ~12 ~40 quartz_stairs 5  
fill ~11 ~12 ~47 ~11 ~12 ~48 leaves 15  
fill ~11 ~12 ~52 ~11 ~12 ~53 leaves 15  
fill ~11 ~12 ~72 ~12 ~12 ~72 wool 8 
setblock ~12 ~12 ~20 spruce_stairs 3 
setblock ~12 ~12 ~39 spruce_stairs 0 
setblock ~12 ~12 ~58 quartz_stairs 7  
fill ~12 ~12 ~60 ~12 ~15 ~60 wool 8  
fill ~12 ~12 ~61 ~12 ~12 ~62 spruce_stairs 1  
fill ~12 ~12 ~65 ~12 ~12 ~66 spruce_stairs 1  
fill ~12 ~12 ~67 ~12 ~15 ~67 wool 8  
fill ~12 ~12 ~68 ~12 ~13 ~68 leaves 15  
fill ~13 ~12 ~24 ~14 ~12 ~24 wool 8 
setblock ~13 ~12 ~36 quartz_stairs 7  
fill ~13 ~12 ~38 ~13 ~16 ~38 planks 1  
fill ~13 ~12 ~39 ~13 ~14 ~39 leaves 15  
fill ~13 ~12 ~40 ~13 ~16 ~40 planks 1 
setblock ~13 ~12 ~42 quartz_stairs 6 
setblock ~13 ~12 ~51 quartz_stairs 7 
setblock ~13 ~12 ~54 quartz_stairs 6 
setblock ~13 ~12 ~58 wool 15 
setblock ~13 ~12 ~59 dark_oak_stairs 2  
fill ~13 ~12 ~61 ~13 ~12 ~62 sandstone 0  
fill ~13 ~12 ~65 ~13 ~12 ~66 sandstone 0  
fill ~13 ~12 ~67 ~14 ~12 ~67 wool 7  
fill ~13 ~12 ~68 ~14 ~12 ~68 stone_slab 9  
fill ~14 ~12 ~19 ~14 ~14 ~19 glass 0  
fill ~14 ~12 ~25 ~14 ~12 ~27 wool 7 
setblock ~14 ~12 ~36 wool 15 
setblock ~14 ~12 ~37 dark_oak_stairs 2  
fill ~14 ~12 ~38 ~14 ~13 ~38 leaves 15  
fill ~14 ~12 ~39 ~14 ~15 ~39 wool 15  
fill ~14 ~12 ~40 ~14 ~14 ~40 leaves 15 
setblock ~14 ~12 ~41 dark_oak_stairs 3 
setblock ~14 ~12 ~42 wool 15 
setblock ~14 ~12 ~51 wool 15 
setblock ~14 ~12 ~52 dark_oak_stairs 2 
setblock ~14 ~12 ~53 dark_oak_stairs 3 
setblock ~14 ~12 ~54 wool 15 
setblock ~14 ~12 ~58 quartz_stairs 7  
fill ~14 ~12 ~60 ~14 ~15 ~60 wool 7  
fill ~14 ~12 ~61 ~14 ~12 ~62 spruce_stairs 0  
fill ~14 ~12 ~65 ~14 ~12 ~66 spruce_stairs 0 
setblock ~14 ~12 ~72 wool 7  
fill ~15 ~12 ~21 ~15 ~14 ~21 glass 0  
fill ~15 ~12 ~22 ~15 ~15 ~22 glass 0  
fill ~15 ~12 ~23 ~15 ~15 ~23 glass 0  
fill ~15 ~12 ~24 ~15 ~15 ~24 glass 0 
setblock ~15 ~12 ~26 spruce_stairs 0 
setblock ~15 ~12 ~36 quartz_stairs 7  
fill ~15 ~12 ~38 ~15 ~16 ~38 planks 1  
fill ~15 ~12 ~39 ~15 ~14 ~39 leaves 15  
fill ~15 ~12 ~40 ~15 ~16 ~40 planks 1 
setblock ~15 ~12 ~42 quartz_stairs 6 
setblock ~15 ~12 ~51 quartz_stairs 7 
setblock ~15 ~12 ~54 quartz_stairs 6  
fill ~15 ~12 ~72 ~16 ~12 ~72 wool 8  
fill ~15 ~12 ~73 ~16 ~12 ~73 wool 8  
fill ~16 ~12 ~25 ~16 ~15 ~25 glass 0  
fill ~16 ~12 ~26 ~16 ~15 ~26 glass 0  
fill ~16 ~12 ~28 ~16 ~12 ~30 wool 7 
setblock ~16 ~12 ~39 spruce_stairs 1  
fill ~16 ~12 ~63 ~16 ~14 ~63 leaves 15  
fill ~16 ~12 ~64 ~16 ~15 ~64 leaves 15  
fill ~17 ~12 ~27 ~17 ~15 ~27 glass 0  
fill ~17 ~12 ~28 ~17 ~15 ~28 glass 0 
setblock ~17 ~12 ~29 spruce_stairs 0 
setblock ~17 ~12 ~38 quartz_stairs 4 
setblock ~17 ~12 ~39 wool 15 
setblock ~17 ~12 ~40 quartz_stairs 4  
fill ~17 ~12 ~47 ~17 ~12 ~48 leaves 15  
fill ~17 ~12 ~52 ~17 ~12 ~53 leaves 15  
fill ~17 ~12 ~74 ~18 ~12 ~74 wool 7  
fill ~18 ~12 ~29 ~18 ~15 ~29 glass 0  
fill ~18 ~12 ~30 ~18 ~15 ~30 glass 0  
fill ~18 ~12 ~32 ~18 ~12 ~34 wool 7  
fill ~19 ~12 ~31 ~19 ~15 ~31 glass 0 
setblock ~19 ~12 ~33 spruce_stairs 0 
fill ~19 ~12 ~36 ~21 ~12 ~36 wool 7 
setblock ~19 ~12 ~51 quartz_stairs 7 
setblock ~19 ~12 ~54 quartz_stairs 6  
fill ~19 ~12 ~72 ~20 ~12 ~72 wool 8  
fill ~19 ~12 ~73 ~20 ~12 ~73 wool 8  
fill ~19 ~12 ~74 ~20 ~12 ~74 wool 8  
fill ~20 ~12 ~32 ~20 ~15 ~32 glass 0  
fill ~20 ~12 ~33 ~20 ~15 ~33 glass 0 
setblock ~20 ~12 ~35 spruce_stairs 3 
setblock ~20 ~12 ~51 wool 15 
setblock ~20 ~12 ~52 dark_oak_stairs 2 
setblock ~20 ~12 ~53 dark_oak_stairs 7 
setblock ~20 ~12 ~54 wool 15  
fill ~20 ~12 ~60 ~20 ~15 ~60 wool 8  
fill ~20 ~12 ~61 ~20 ~12 ~62 spruce_stairs 1  
fill ~20 ~12 ~65 ~20 ~12 ~66 spruce_stairs 1  
fill ~20 ~12 ~67 ~20 ~15 ~67 wool 8  
fill ~20 ~12 ~68 ~20 ~14 ~68 leaves 15  
fill ~21 ~12 ~34 ~21 ~15 ~34 glass 0 
setblock ~21 ~12 ~42 quartz_stairs 7 
setblock ~21 ~12 ~51 quartz_stairs 7 
setblock ~21 ~12 ~54 quartz_stairs 6 
setblock ~21 ~12 ~58 quartz_stairs 7  
fill ~21 ~12 ~60 ~21 ~15 ~60 wool 7  
fill ~21 ~12 ~61 ~22 ~12 ~61 sandstone 0  
fill ~21 ~12 ~62 ~22 ~12 ~62 sandstone 0  
fill ~21 ~12 ~65 ~22 ~12 ~65 sandstone 0  
fill ~21 ~12 ~66 ~22 ~12 ~66 sandstone 0  
fill ~21 ~12 ~67 ~22 ~12 ~67 wool 7  
fill ~21 ~12 ~68 ~22 ~12 ~68 stone_slab 9  
fill ~21 ~12 ~74 ~22 ~12 ~74 wool 7  
fill ~22 ~12 ~35 ~22 ~15 ~35 glass 0 
setblock ~22 ~12 ~42 wool 15 
setblock ~22 ~12 ~43 dark_oak_stairs 2 
setblock ~22 ~12 ~58 wool 15 
setblock ~22 ~12 ~59 dark_oak_stairs 2  
fill ~23 ~12 ~36 ~24 ~12 ~36 glass 0  
fill ~23 ~12 ~38 ~25 ~12 ~38 wool 7 
setblock ~23 ~12 ~42 quartz_stairs 7  
fill ~23 ~12 ~47 ~23 ~13 ~47 leaves 15  
fill ~23 ~12 ~48 ~23 ~15 ~48 leaves 15  
fill ~23 ~12 ~52 ~23 ~12 ~53 leaves 15 
setblock ~23 ~12 ~58 quartz_stairs 7  
fill ~23 ~12 ~60 ~23 ~15 ~60 wool 8  
fill ~23 ~12 ~61 ~23 ~12 ~62 spruce_stairs 0  
fill ~23 ~12 ~65 ~23 ~12 ~66 spruce_stairs 0  
fill ~23 ~12 ~67 ~23 ~15 ~67 wool 8  
fill ~23 ~12 ~68 ~23 ~14 ~68 leaves 15  
fill ~23 ~12 ~72 ~24 ~12 ~72 wool 8  
fill ~23 ~12 ~73 ~24 ~12 ~73 wool 8  
fill ~23 ~12 ~74 ~24 ~12 ~74 wool 8 
setblock ~24 ~12 ~37 spruce_stairs 3  
fill ~25 ~12 ~37 ~26 ~12 ~37 glass 0 
setblock ~25 ~12 ~51 quartz_stairs 7 
setblock ~25 ~12 ~54 quartz_stairs 6  
fill ~25 ~12 ~74 ~26 ~12 ~74 wool 7 
setblock ~26 ~12 ~51 wool 15 
setblock ~26 ~12 ~52 dark_oak_stairs 2 
setblock ~26 ~12 ~53 dark_oak_stairs 3 
setblock ~26 ~12 ~54 wool 15  
fill ~27 ~12 ~38 ~29 ~12 ~38 glass 0  
fill ~27 ~12 ~40 ~29 ~12 ~40 wool 7 
setblock ~27 ~12 ~51 quartz_stairs 7 
setblock ~27 ~12 ~54 quartz_stairs 6  
fill ~27 ~12 ~63 ~27 ~14 ~63 leaves 15  
fill ~27 ~12 ~64 ~27 ~15 ~64 leaves 15  
fill ~27 ~12 ~72 ~28 ~12 ~72 wool 8  
fill ~27 ~12 ~73 ~28 ~12 ~73 wool 8  
fill ~27 ~12 ~74 ~28 ~12 ~74 wool 8  
fill ~28 ~12 ~26 ~30 ~12 ~26 diamond_block 0 
setblock ~28 ~12 ~39 spruce_stairs 3  
fill ~29 ~12 ~47 ~29 ~13 ~47 leaves 15  
fill ~29 ~12 ~48 ~29 ~15 ~48 leaves 15  
fill ~29 ~12 ~52 ~29 ~12 ~53 leaves 15 
setblock ~29 ~12 ~58 quartz_stairs 7  
fill ~29 ~12 ~60 ~29 ~15 ~60 wool 7  
fill ~29 ~12 ~61 ~29 ~12 ~62 spruce_stairs 1  
fill ~29 ~12 ~65 ~29 ~12 ~66 spruce_stairs 1  
fill ~29 ~12 ~67 ~30 ~12 ~67 wool 7  
fill ~29 ~12 ~68 ~30 ~12 ~68 stone_slab 9  
fill ~30 ~12 ~39 ~33 ~12 ~39 glass 0 
setblock ~30 ~12 ~58 wool 15 
setblock ~30 ~12 ~59 dark_oak_stairs 2  
fill ~30 ~12 ~61 ~30 ~12 ~62 sandstone 0  
fill ~30 ~12 ~65 ~30 ~12 ~66 sandstone 0 
setblock ~30 ~12 ~72 wool 7  
fill ~31 ~12 ~41 ~33 ~12 ~41 wool 7 
setblock ~31 ~12 ~51 quartz_stairs 6 
setblock ~31 ~12 ~54 quartz_stairs 6 
setblock ~31 ~12 ~58 quartz_stairs 7  
fill ~31 ~12 ~60 ~31 ~15 ~60 wool 8  
fill ~31 ~12 ~61 ~31 ~12 ~62 spruce_stairs 0  
fill ~31 ~12 ~65 ~31 ~12 ~66 spruce_stairs 0  
fill ~31 ~12 ~67 ~31 ~15 ~67 wool 8  
fill ~31 ~12 ~68 ~31 ~14 ~68 leaves 15  
fill ~31 ~12 ~72 ~32 ~12 ~72 wool 8  
fill ~31 ~12 ~73 ~32 ~12 ~73 wool 8 
setblock ~32 ~12 ~40 spruce_stairs 3 
setblock ~32 ~12 ~51 wool 15 
setblock ~32 ~12 ~52 dark_oak_stairs 2 
setblock ~32 ~12 ~53 dark_oak_stairs 3 
setblock ~32 ~12 ~54 wool 15 
setblock ~33 ~12 ~51 quartz_stairs 6 
setblock ~33 ~12 ~54 quartz_stairs 6  
fill ~34 ~12 ~40 ~38 ~12 ~40 glass 0  
fill ~34 ~12 ~70 ~34 ~15 ~70 wool 8  
fill ~35 ~12 ~47 ~35 ~14 ~47 leaves 15  
fill ~35 ~12 ~48 ~35 ~15 ~48 leaves 15  
fill ~35 ~12 ~52 ~35 ~12 ~53 leaves 15  
fill ~35 ~12 ~69 ~35 ~15 ~69 wool 8  
fill ~36 ~12 ~42 ~38 ~12 ~42 wool 7 
setblock ~36 ~12 ~50 quartz_stairs 7 
setblock ~36 ~12 ~54 quartz_stairs 6  
fill ~36 ~12 ~61 ~37 ~12 ~61 spruce_stairs 3  
fill ~36 ~12 ~62 ~37 ~12 ~62 sandstone 0  
fill ~36 ~12 ~63 ~37 ~12 ~63 sandstone 0  
fill ~36 ~12 ~64 ~37 ~12 ~64 spruce_stairs 2 
setblock ~37 ~12 ~41 spruce_stairs 3 
setblock ~37 ~12 ~50 wool 15 
setblock ~37 ~12 ~51 dark_oak_stairs 2 
setblock ~37 ~12 ~53 dark_oak_stairs 3 
setblock ~37 ~12 ~54 wool 15  
fill ~37 ~12 ~57 ~37 ~12 ~59 wool 7  
fill ~38 ~12 ~39 ~38 ~21 ~39 planks 1 
setblock ~38 ~12 ~50 quartz_stairs 7 
setblock ~38 ~12 ~54 quartz_stairs 6  
fill ~38 ~12 ~55 ~38 ~13 ~55 wool 8 
setblock ~38 ~12 ~58 spruce_stairs 0  
fill ~38 ~12 ~60 ~38 ~14 ~60 leaves 15  
fill ~39 ~12 ~39 ~39 ~12 ~54 wool 8  
fill ~7 ~13 ~32 ~7 ~15 ~32 leaves 15  
fill ~10 ~13 ~24 ~11 ~13 ~24 wool 8  
fill ~11 ~13 ~18 ~13 ~13 ~18 glass 0 
setblock ~11 ~13 ~38 lever 6 
setblock ~11 ~13 ~39 heavy_weighted_pressure_plate 0 
setblock ~11 ~13 ~40 flower_pot 0 
setblock ~11 ~13 ~47 leaves 11  
fill ~11 ~13 ~48 ~11 ~15 ~48 leaves 15  
fill ~11 ~13 ~52 ~11 ~13 ~53 dropper 2  
fill ~11 ~13 ~72 ~12 ~13 ~72 wool 8 
setblock ~12 ~13 ~58 flower_pot 0  
fill ~13 ~13 ~24 ~14 ~13 ~24 wool 8 
setblock ~13 ~13 ~36 flower_pot 0 
setblock ~13 ~13 ~42 lever 13 
setblock ~13 ~13 ~51 flower_pot 0 
setblock ~13 ~13 ~54 lever 13 
setblock ~13 ~13 ~58 heavy_weighted_pressure_plate 0  
fill ~13 ~13 ~67 ~14 ~13 ~67 wool 7  
fill ~13 ~13 ~68 ~14 ~13 ~68 stone_slab 9 
setblock ~14 ~13 ~36 heavy_weighted_pressure_plate 0 
setblock ~14 ~13 ~42 heavy_weighted_pressure_plate 0 
setblock ~14 ~13 ~51 heavy_weighted_pressure_plate 0 
setblock ~14 ~13 ~54 heavy_weighted_pressure_plate 0 
setblock ~14 ~13 ~58 lever 5  
fill ~14 ~13 ~72 ~14 ~15 ~72 glass 0  
fill ~14 ~13 ~73 ~14 ~15 ~73 glass 0 
setblock ~15 ~13 ~36 lever 5 
setblock ~15 ~13 ~42 flower_pot 0 
setblock ~15 ~13 ~51 lever 5 
setblock ~15 ~13 ~54 flower_pot 0  
fill ~15 ~13 ~72 ~16 ~13 ~72 wool 8  
fill ~15 ~13 ~73 ~16 ~13 ~73 wool 8 
setblock ~17 ~13 ~38 flower_pot 0 
setblock ~17 ~13 ~39 heavy_weighted_pressure_plate 0 
setblock ~17 ~13 ~40 lever 14 
setblock ~17 ~13 ~47 leaves 11  
fill ~17 ~13 ~48 ~17 ~15 ~48 leaves 15  
fill ~17 ~13 ~52 ~17 ~13 ~53 dropper 2  
fill ~17 ~13 ~74 ~18 ~13 ~74 wool 7 
setblock ~19 ~13 ~51 flower_pot 0 
setblock ~19 ~13 ~54 lever 13  
fill ~19 ~13 ~72 ~20 ~13 ~72 wool 8  
fill ~19 ~13 ~73 ~20 ~13 ~73 wool 8  
fill ~19 ~13 ~74 ~20 ~13 ~74 wool 8 
setblock ~20 ~13 ~51 heavy_weighted_pressure_plate 0 
setblock ~20 ~13 ~54 heavy_weighted_pressure_plate 0 
setblock ~21 ~13 ~42 flower_pot 0 
setblock ~21 ~13 ~51 lever 5 
setblock ~21 ~13 ~54 flower_pot 0 
setblock ~21 ~13 ~58 flower_pot 0  
fill ~21 ~13 ~67 ~22 ~13 ~67 wool 7  
fill ~21 ~13 ~68 ~22 ~13 ~68 stone_slab 9  
fill ~21 ~13 ~74 ~22 ~13 ~74 wool 7 
setblock ~22 ~13 ~42 heavy_weighted_pressure_plate 0 
setblock ~22 ~13 ~58 heavy_weighted_pressure_plate 0  
fill ~23 ~13 ~36 ~24 ~13 ~36 glass 0 
setblock ~23 ~13 ~42 lever 5  
fill ~23 ~13 ~52 ~23 ~13 ~53 dropper 2 
setblock ~23 ~13 ~58 lever 5  
fill ~23 ~13 ~72 ~24 ~13 ~72 wool 8  
fill ~23 ~13 ~73 ~24 ~13 ~73 wool 8  
fill ~23 ~13 ~74 ~24 ~13 ~74 wool 8  
fill ~25 ~13 ~37 ~26 ~13 ~37 glass 0 
setblock ~25 ~13 ~51 flower_pot 0 
setblock ~25 ~13 ~54 lever 13  
fill ~25 ~13 ~74 ~26 ~13 ~74 wool 7 
setblock ~26 ~13 ~51 heavy_weighted_pressure_plate 0 
setblock ~26 ~13 ~54 heavy_weighted_pressure_plate 0  
fill ~27 ~13 ~38 ~29 ~13 ~38 glass 0 
setblock ~27 ~13 ~51 lever 5 
setblock ~27 ~13 ~54 flower_pot 0  
fill ~27 ~13 ~72 ~28 ~13 ~72 wool 8  
fill ~27 ~13 ~73 ~28 ~13 ~73 wool 8  
fill ~27 ~13 ~74 ~28 ~13 ~74 wool 8  
fill ~28 ~13 ~26 ~30 ~13 ~26 diamond_block 0  
fill ~29 ~13 ~52 ~29 ~13 ~53 dropper 2 
setblock ~29 ~13 ~58 flower_pot 0  
fill ~29 ~13 ~67 ~30 ~13 ~67 wool 7  
fill ~29 ~13 ~68 ~30 ~13 ~68 stone_slab 9  
fill ~30 ~13 ~39 ~33 ~13 ~39 glass 0 
setblock ~30 ~13 ~58 heavy_weighted_pressure_plate 0  
fill ~30 ~13 ~72 ~30 ~15 ~72 glass 0  
fill ~30 ~13 ~73 ~30 ~15 ~73 glass 0 
setblock ~31 ~13 ~51 flower_pot 0 
setblock ~31 ~13 ~54 lever 13 
setblock ~31 ~13 ~58 lever 5  
fill ~31 ~13 ~72 ~32 ~13 ~72 wool 8  
fill ~31 ~13 ~73 ~32 ~13 ~73 wool 8 
setblock ~32 ~13 ~51 heavy_weighted_pressure_plate 0 
setblock ~32 ~13 ~54 heavy_weighted_pressure_plate 0 
setblock ~33 ~13 ~51 lever 13 
setblock ~33 ~13 ~54 flower_pot 0  
fill ~34 ~13 ~40 ~38 ~13 ~40 glass 0  
fill ~35 ~13 ~52 ~35 ~13 ~53 dropper 2 
setblock ~36 ~13 ~50 flower_pot 0 
setblock ~36 ~13 ~54 lever 13 
setblock ~37 ~13 ~50 heavy_weighted_pressure_plate 0 
setblock ~37 ~13 ~54 heavy_weighted_pressure_plate 0  
fill ~37 ~13 ~66 ~37 ~15 ~66 glass 0 
setblock ~38 ~13 ~50 lever 5 
setblock ~38 ~13 ~54 flower_pot 0  
fill ~38 ~13 ~56 ~38 ~14 ~56 wool 7  
fill ~38 ~13 ~57 ~38 ~14 ~57 wool 7  
fill ~39 ~13 ~39 ~39 ~14 ~39 wool 7  
fill ~39 ~13 ~40 ~39 ~14 ~40 wool 7  
fill ~39 ~13 ~41 ~39 ~14 ~41 wool 7  
fill ~39 ~13 ~42 ~39 ~14 ~42 wool 7  
fill ~39 ~13 ~43 ~39 ~14 ~43 wool 7  
fill ~39 ~13 ~44 ~39 ~14 ~44 wool 7  
fill ~39 ~13 ~45 ~39 ~14 ~45 wool 7  
fill ~39 ~13 ~46 ~39 ~14 ~46 wool 7  
fill ~39 ~13 ~47 ~39 ~14 ~47 wool 7  
fill ~39 ~13 ~48 ~39 ~14 ~48 wool 7  
fill ~39 ~13 ~49 ~39 ~14 ~49 wool 7  
fill ~39 ~13 ~50 ~39 ~14 ~50 wool 7  
fill ~39 ~13 ~51 ~39 ~14 ~51 wool 7  
fill ~39 ~13 ~52 ~39 ~14 ~52 wool 7  
fill ~39 ~13 ~53 ~39 ~14 ~53 wool 7  
fill ~39 ~13 ~54 ~39 ~14 ~54 wool 7  
fill ~10 ~14 ~24 ~11 ~14 ~24 wool 8  
fill ~11 ~14 ~18 ~13 ~14 ~18 glass 0  
fill ~11 ~14 ~47 ~11 ~15 ~47 leaves 15  
fill ~11 ~14 ~52 ~11 ~14 ~53 dropper 0  
fill ~11 ~14 ~72 ~12 ~14 ~72 wool 8 
setblock ~12 ~14 ~24 spruce_stairs 3 
setblock ~12 ~14 ~68 leaves 11  
fill ~13 ~14 ~24 ~14 ~14 ~24 wool 8  
fill ~13 ~14 ~67 ~14 ~14 ~67 wool 7  
fill ~13 ~14 ~68 ~14 ~14 ~68 stone_slab 9 
setblock ~14 ~14 ~38 leaves 11  
fill ~15 ~14 ~72 ~16 ~14 ~72 wool 8  
fill ~15 ~14 ~73 ~16 ~14 ~73 wool 8  
fill ~17 ~14 ~47 ~17 ~15 ~47 leaves 15  
fill ~17 ~14 ~52 ~17 ~14 ~53 dropper 0  
fill ~17 ~14 ~74 ~18 ~14 ~74 wool 7  
fill ~19 ~14 ~72 ~20 ~14 ~72 wool 8  
fill ~19 ~14 ~73 ~20 ~14 ~73 wool 8  
fill ~19 ~14 ~74 ~20 ~14 ~74 wool 8 
setblock ~20 ~14 ~59 leaves 15  
fill ~21 ~14 ~67 ~22 ~14 ~67 wool 7  
fill ~21 ~14 ~68 ~22 ~14 ~68 stone_slab 9  
fill ~21 ~14 ~74 ~22 ~14 ~74 wool 7  
fill ~23 ~14 ~36 ~24 ~14 ~36 glass 0 
setblock ~23 ~14 ~47 leaves 11  
fill ~23 ~14 ~52 ~23 ~14 ~53 dropper 0  
fill ~23 ~14 ~72 ~24 ~14 ~72 wool 8  
fill ~23 ~14 ~73 ~24 ~14 ~73 wool 8  
fill ~23 ~14 ~74 ~24 ~14 ~74 wool 8  
fill ~25 ~14 ~37 ~26 ~14 ~37 glass 0  
fill ~25 ~14 ~74 ~26 ~14 ~74 wool 7 
setblock ~27 ~14 ~25 torch 2  
fill ~27 ~14 ~72 ~28 ~14 ~72 wool 8  
fill ~27 ~14 ~73 ~28 ~14 ~73 wool 8  
fill ~27 ~14 ~74 ~28 ~14 ~74 wool 8 
setblock ~28 ~14 ~25 diamond_block 0  
fill ~28 ~14 ~38 ~29 ~14 ~38 glass 0 
setblock ~29 ~14 ~47 leaves 11  
fill ~29 ~14 ~52 ~29 ~14 ~53 dropper 0  
fill ~29 ~14 ~67 ~30 ~14 ~67 wool 7  
fill ~29 ~14 ~68 ~30 ~14 ~68 stone_slab 9 
setblock ~30 ~14 ~25 diamond_block 0  
fill ~30 ~14 ~39 ~33 ~14 ~39 glass 0  
fill ~31 ~14 ~72 ~32 ~14 ~72 wool 8  
fill ~31 ~14 ~73 ~32 ~14 ~73 wool 8  
fill ~34 ~14 ~40 ~38 ~14 ~40 glass 0  
fill ~35 ~14 ~52 ~35 ~14 ~53 dropper 0  
fill ~38 ~14 ~55 ~38 ~16 ~55 wool 7 
setblock ~5 ~15 ~52 leaves 11 
setblock ~6 ~15 ~60 leaves 11 
setblock ~9 ~15 ~24 leaves 11 
setblock ~10 ~15 ~20 glass 0  
fill ~10 ~15 ~24 ~14 ~15 ~24 wool 8  
fill ~11 ~15 ~19 ~13 ~15 ~19 glass 0  
fill ~11 ~15 ~52 ~11 ~15 ~53 leaves 15  
fill ~11 ~15 ~72 ~12 ~15 ~72 wool 8 
setblock ~12 ~15 ~39 spruce_stairs 4 
setblock ~12 ~15 ~68 leaves 15 
setblock ~13 ~15 ~39 glowstone 0 
setblock ~13 ~15 ~60 wool 7  
fill ~13 ~15 ~67 ~14 ~15 ~67 wool 7  
fill ~13 ~15 ~68 ~14 ~15 ~68 stone_slab 9 
setblock ~14 ~15 ~20 glass 0 
setblock ~14 ~15 ~37 spruce_stairs 6 
setblock ~14 ~15 ~38 glowstone 0  
fill ~14 ~15 ~40 ~14 ~16 ~40 glowstone 0 
setblock ~14 ~15 ~41 spruce_stairs 7  
fill ~15 ~15 ~21 ~15 ~21 ~21 planks 1 
setblock ~15 ~15 ~39 glowstone 0  
fill ~15 ~15 ~71 ~28 ~15 ~71 wool 8  
fill ~15 ~15 ~72 ~16 ~15 ~72 wool 8  
fill ~15 ~15 ~73 ~16 ~15 ~73 wool 8 
setblock ~16 ~15 ~39 spruce_stairs 5 
setblock ~16 ~15 ~63 leaves 11  
fill ~17 ~15 ~52 ~17 ~15 ~53 leaves 15  
fill ~17 ~15 ~74 ~18 ~15 ~74 wool 7  
fill ~19 ~15 ~72 ~20 ~15 ~72 wool 8  
fill ~19 ~15 ~73 ~20 ~15 ~73 wool 8  
fill ~19 ~15 ~74 ~20 ~15 ~74 wool 8 
setblock ~20 ~15 ~59 leaves 11 
setblock ~20 ~15 ~68 leaves 11  
fill ~21 ~15 ~67 ~22 ~15 ~67 wool 7  
fill ~21 ~15 ~68 ~22 ~15 ~68 stone_slab 9  
fill ~21 ~15 ~74 ~22 ~15 ~74 wool 7 
setblock ~22 ~15 ~60 wool 7  
fill ~23 ~15 ~36 ~24 ~15 ~36 glass 0 
setblock ~23 ~15 ~47 leaves 15  
fill ~23 ~15 ~52 ~23 ~15 ~53 leaves 15 
setblock ~23 ~15 ~68 leaves 11  
fill ~23 ~15 ~72 ~24 ~15 ~72 wool 8  
fill ~23 ~15 ~73 ~24 ~15 ~73 wool 8  
fill ~23 ~15 ~74 ~24 ~15 ~74 wool 8  
fill ~25 ~15 ~37 ~26 ~15 ~37 glass 0  
fill ~25 ~15 ~74 ~26 ~15 ~74 wool 7 
setblock ~27 ~15 ~19 torch 2 
setblock ~27 ~15 ~63 leaves 11  
fill ~27 ~15 ~72 ~28 ~15 ~72 wool 8  
fill ~27 ~15 ~73 ~28 ~15 ~73 wool 8  
fill ~27 ~15 ~74 ~28 ~15 ~74 wool 8  
fill ~28 ~15 ~19 ~28 ~15 ~24 diamond_block 0  
fill ~28 ~15 ~38 ~29 ~15 ~38 glass 0  
fill ~29 ~15 ~20 ~29 ~15 ~21 diamond_block 0 
setblock ~29 ~15 ~47 leaves 15  
fill ~29 ~15 ~52 ~29 ~15 ~53 leaves 15  
fill ~29 ~15 ~67 ~30 ~15 ~67 wool 7  
fill ~29 ~15 ~68 ~30 ~15 ~68 stone_slab 9  
fill ~30 ~15 ~21 ~30 ~15 ~24 diamond_block 0  
fill ~30 ~15 ~39 ~33 ~15 ~39 glass 0 
setblock ~30 ~15 ~60 wool 7 
setblock ~31 ~15 ~68 leaves 11  
fill ~31 ~15 ~72 ~32 ~15 ~72 wool 8  
fill ~31 ~15 ~73 ~32 ~15 ~73 wool 8  
fill ~34 ~15 ~40 ~38 ~15 ~40 glass 0 
setblock ~35 ~15 ~47 leaves 11  
fill ~35 ~15 ~52 ~35 ~15 ~53 leaves 15  
fill ~38 ~15 ~56 ~38 ~16 ~56 wool 8 
setblock ~38 ~15 ~60 leaves 11  
fill ~39 ~15 ~39 ~39 ~16 ~39 wool 8  
fill ~39 ~15 ~40 ~39 ~16 ~40 wool 8  
fill ~39 ~15 ~41 ~39 ~16 ~41 wool 8  
fill ~39 ~15 ~42 ~39 ~16 ~42 wool 8  
fill ~39 ~15 ~43 ~39 ~16 ~43 wool 8  
fill ~39 ~15 ~44 ~39 ~16 ~44 wool 8  
fill ~39 ~15 ~45 ~39 ~16 ~45 wool 8  
fill ~39 ~15 ~46 ~39 ~16 ~46 wool 8  
fill ~39 ~15 ~47 ~39 ~16 ~47 wool 8  
fill ~39 ~15 ~48 ~39 ~16 ~48 wool 8  
fill ~39 ~15 ~49 ~39 ~16 ~49 wool 8  
fill ~39 ~15 ~50 ~39 ~16 ~50 wool 8  
fill ~39 ~15 ~51 ~39 ~16 ~51 wool 8  
fill ~39 ~15 ~52 ~39 ~16 ~52 wool 8  
fill ~39 ~15 ~53 ~39 ~16 ~53 wool 8  
fill ~39 ~15 ~54 ~39 ~16 ~54 wool 8  
fill ~39 ~15 ~57 ~39 ~102 ~57 wool 8 
setblock ~5 ~16 ~52 glowstone 0  
fill ~5 ~16 ~53 ~10 ~16 ~53 planks 1  
fill ~5 ~16 ~54 ~38 ~16 ~54 planks 1  
fill ~5 ~16 ~55 ~37 ~16 ~55 planks 1  
fill ~5 ~16 ~56 ~37 ~16 ~56 planks 1  
fill ~5 ~16 ~57 ~38 ~16 ~57 planks 1  
fill ~6 ~16 ~48 ~10 ~16 ~48 planks 1  
fill ~6 ~16 ~49 ~38 ~16 ~49 planks 1  
fill ~6 ~16 ~50 ~38 ~16 ~50 planks 1  
fill ~6 ~16 ~51 ~38 ~16 ~51 planks 1  
fill ~6 ~16 ~52 ~10 ~16 ~52 planks 1  
fill ~6 ~16 ~58 ~38 ~16 ~58 planks 1  
fill ~6 ~16 ~59 ~19 ~16 ~59 planks 1 
setblock ~6 ~16 ~60 glowstone 0 
setblock ~7 ~16 ~32 glowstone 0  
fill ~7 ~16 ~33 ~20 ~16 ~33 planks 1  
fill ~7 ~16 ~34 ~21 ~16 ~34 planks 1  
fill ~7 ~16 ~35 ~22 ~16 ~35 planks 1  
fill ~7 ~16 ~36 ~24 ~16 ~36 planks 1  
fill ~7 ~16 ~37 ~26 ~16 ~37 planks 1  
fill ~7 ~16 ~38 ~29 ~16 ~38 planks 1  
fill ~7 ~16 ~39 ~33 ~16 ~39 planks 1  
fill ~7 ~16 ~40 ~13 ~16 ~40 planks 1  
fill ~7 ~16 ~41 ~38 ~16 ~41 planks 1  
fill ~7 ~16 ~42 ~18 ~16 ~42 planks 1  
fill ~7 ~16 ~43 ~38 ~16 ~43 planks 1  
fill ~7 ~16 ~44 ~38 ~16 ~44 planks 1  
fill ~7 ~16 ~45 ~38 ~16 ~45 planks 1  
fill ~7 ~16 ~46 ~38 ~16 ~46 planks 1  
fill ~7 ~16 ~47 ~10 ~16 ~47 planks 1  
fill ~7 ~16 ~60 ~37 ~16 ~60 planks 1  
fill ~7 ~16 ~61 ~37 ~16 ~61 planks 1  
fill ~7 ~16 ~62 ~37 ~16 ~62 planks 1  
fill ~7 ~16 ~63 ~15 ~16 ~63 planks 1  
fill ~7 ~16 ~64 ~15 ~16 ~64 planks 1  
fill ~7 ~16 ~65 ~36 ~16 ~65 planks 1  
fill ~8 ~16 ~32 ~8 ~81 ~32 wool 8  
fill ~8 ~16 ~66 ~36 ~16 ~66 planks 1  
fill ~8 ~16 ~67 ~36 ~16 ~67 planks 1 
setblock ~9 ~16 ~24 glowstone 0  
fill ~9 ~16 ~25 ~16 ~16 ~25 planks 1  
fill ~9 ~16 ~26 ~15 ~16 ~26 planks 1  
fill ~9 ~16 ~27 ~17 ~16 ~27 planks 1  
fill ~9 ~16 ~28 ~16 ~16 ~28 planks 1  
fill ~9 ~16 ~29 ~18 ~16 ~29 planks 1  
fill ~9 ~16 ~30 ~17 ~16 ~30 planks 1  
fill ~9 ~16 ~31 ~19 ~16 ~31 planks 1  
fill ~9 ~16 ~32 ~20 ~16 ~32 planks 1  
fill ~9 ~16 ~68 ~11 ~16 ~68 planks 1  
fill ~9 ~16 ~69 ~35 ~16 ~69 planks 1 
setblock ~10 ~16 ~19 planks 1 
setblock ~10 ~16 ~20 glowstone 0  
fill ~10 ~16 ~21 ~16 ~16 ~21 planks 1  
fill ~10 ~16 ~22 ~14 ~16 ~22 planks 1  
fill ~10 ~16 ~23 ~14 ~16 ~23 planks 1  
fill ~10 ~16 ~24 ~14 ~16 ~24 planks 1  
fill ~10 ~16 ~70 ~34 ~16 ~70 planks 1  
fill ~11 ~16 ~18 ~13 ~16 ~18 planks 1  
fill ~11 ~16 ~19 ~13 ~16 ~19 glowstone 0  
fill ~11 ~16 ~20 ~13 ~16 ~20 planks 1  
fill ~11 ~16 ~47 ~11 ~16 ~48 glowstone 0  
fill ~11 ~16 ~52 ~11 ~16 ~53 glowstone 0  
fill ~11 ~16 ~71 ~33 ~16 ~71 planks 1  
fill ~11 ~16 ~72 ~12 ~16 ~72 wool 8  
fill ~12 ~16 ~47 ~15 ~16 ~47 planks 1  
fill ~12 ~16 ~48 ~16 ~16 ~48 planks 1  
fill ~12 ~16 ~52 ~16 ~16 ~52 planks 1  
fill ~12 ~16 ~53 ~16 ~16 ~53 planks 1 
setblock ~12 ~16 ~68 glowstone 0  
fill ~13 ~16 ~68 ~19 ~16 ~68 planks 1 
setblock ~14 ~16 ~19 planks 1 
setblock ~14 ~16 ~20 glowstone 0 
setblock ~14 ~16 ~72 glowstone 0  
fill ~14 ~16 ~73 ~14 ~17 ~73 wool 7  
fill ~15 ~16 ~22 ~15 ~16 ~24 glowstone 0  
fill ~15 ~16 ~72 ~16 ~16 ~72 wool 8  
fill ~15 ~16 ~73 ~16 ~16 ~73 wool 8  
fill ~16 ~16 ~22 ~16 ~16 ~25 planks 1 
setblock ~16 ~16 ~26 glowstone 0  
fill ~16 ~16 ~40 ~38 ~16 ~40 planks 1  
fill ~16 ~16 ~63 ~16 ~16 ~64 glowstone 0 
setblock ~17 ~16 ~26 planks 1 
setblock ~17 ~16 ~28 glowstone 0  
fill ~17 ~16 ~47 ~17 ~16 ~48 glowstone 0  
fill ~17 ~16 ~52 ~17 ~16 ~53 glowstone 0  
fill ~17 ~16 ~63 ~26 ~16 ~63 planks 1  
fill ~17 ~16 ~64 ~26 ~16 ~64 planks 1  
fill ~17 ~16 ~74 ~18 ~16 ~74 wool 7 
setblock ~18 ~16 ~28 planks 1 
setblock ~18 ~16 ~30 glowstone 0  
fill ~18 ~16 ~47 ~22 ~16 ~47 planks 1  
fill ~18 ~16 ~48 ~22 ~16 ~48 planks 1  
fill ~18 ~16 ~52 ~22 ~16 ~52 planks 1  
fill ~18 ~16 ~53 ~22 ~16 ~53 planks 1 
setblock ~19 ~16 ~30 planks 1  
fill ~19 ~16 ~72 ~20 ~16 ~72 wool 8  
fill ~19 ~16 ~73 ~20 ~16 ~73 wool 8  
fill ~19 ~16 ~74 ~20 ~16 ~74 wool 8  
fill ~20 ~16 ~42 ~38 ~16 ~42 planks 1 
setblock ~20 ~16 ~59 glowstone 0 
setblock ~20 ~16 ~68 glowstone 0  
fill ~21 ~16 ~59 ~38 ~16 ~59 planks 1  
fill ~21 ~16 ~68 ~22 ~16 ~68 planks 1  
fill ~21 ~16 ~74 ~22 ~16 ~74 wool 7  
fill ~23 ~16 ~47 ~23 ~16 ~48 glowstone 0  
fill ~23 ~16 ~52 ~23 ~16 ~53 glowstone 0 
setblock ~23 ~16 ~68 glowstone 0  
fill ~23 ~16 ~72 ~24 ~16 ~72 wool 8  
fill ~23 ~16 ~73 ~24 ~16 ~73 wool 8  
fill ~23 ~16 ~74 ~24 ~16 ~74 wool 8  
fill ~24 ~16 ~47 ~28 ~16 ~47 planks 1  
fill ~24 ~16 ~48 ~28 ~16 ~48 planks 1  
fill ~24 ~16 ~52 ~28 ~16 ~52 planks 1  
fill ~24 ~16 ~53 ~28 ~16 ~53 planks 1  
fill ~24 ~16 ~68 ~30 ~16 ~68 planks 1  
fill ~25 ~16 ~74 ~26 ~16 ~74 wool 7  
fill ~27 ~16 ~63 ~27 ~16 ~64 glowstone 0  
fill ~27 ~16 ~72 ~28 ~16 ~72 wool 8  
fill ~27 ~16 ~73 ~28 ~16 ~73 wool 8  
fill ~27 ~16 ~74 ~28 ~16 ~74 wool 8  
fill ~28 ~16 ~63 ~37 ~16 ~63 planks 1  
fill ~28 ~16 ~64 ~37 ~16 ~64 planks 1  
fill ~29 ~16 ~47 ~29 ~16 ~48 glowstone 0  
fill ~29 ~16 ~52 ~29 ~16 ~53 glowstone 0  
fill ~30 ~16 ~47 ~34 ~16 ~47 planks 1  
fill ~30 ~16 ~48 ~34 ~16 ~48 planks 1  
fill ~30 ~16 ~52 ~34 ~16 ~52 planks 1  
fill ~30 ~16 ~53 ~34 ~16 ~53 planks 1 
setblock ~30 ~16 ~72 glowstone 0  
fill ~30 ~16 ~73 ~30 ~17 ~73 wool 7 
setblock ~31 ~16 ~68 glowstone 0  
fill ~31 ~16 ~72 ~32 ~16 ~72 wool 8  
fill ~31 ~16 ~73 ~32 ~16 ~73 wool 8  
fill ~32 ~16 ~68 ~35 ~16 ~68 planks 1  
fill ~35 ~16 ~47 ~35 ~16 ~48 glowstone 0  
fill ~35 ~16 ~52 ~35 ~16 ~53 glowstone 0  
fill ~36 ~16 ~47 ~38 ~16 ~47 planks 1  
fill ~36 ~16 ~48 ~38 ~16 ~48 planks 1  
fill ~36 ~16 ~52 ~38 ~16 ~52 planks 1  
fill ~36 ~16 ~53 ~38 ~16 ~53 planks 1  
fill ~37 ~16 ~66 ~37 ~17 ~66 wool 8 
setblock ~38 ~16 ~60 glowstone 0  
fill ~5 ~17 ~52 ~5 ~19 ~52 leaves 15 
setblock ~6 ~17 ~57 spruce_stairs 1  
fill ~6 ~17 ~60 ~6 ~19 ~60 leaves 15  
fill ~7 ~17 ~32 ~7 ~26 ~32 wool 8  
fill ~7 ~17 ~33 ~7 ~20 ~33 leaves 15 
setblock ~7 ~17 ~51 spruce_stairs 1 
setblock ~7 ~17 ~54 spruce_stairs 1  
fill ~7 ~17 ~56 ~7 ~17 ~58 wool 7  
fill ~7 ~17 ~61 ~8 ~17 ~61 spruce_stairs 3  
fill ~7 ~17 ~62 ~8 ~17 ~62 sandstone 0  
fill ~7 ~17 ~63 ~8 ~17 ~63 sandstone 0  
fill ~7 ~17 ~64 ~8 ~17 ~64 spruce_stairs 2 
setblock ~8 ~17 ~35 spruce_stairs 1 
setblock ~8 ~17 ~39 spruce_stairs 1 
setblock ~8 ~17 ~43 spruce_stairs 1  
fill ~8 ~17 ~50 ~8 ~17 ~55 wool 7  
fill ~9 ~17 ~24 ~9 ~20 ~24 wool 7  
fill ~9 ~17 ~25 ~9 ~19 ~25 leaves 15 
setblock ~9 ~17 ~27 spruce_stairs 1 
setblock ~9 ~17 ~31 spruce_stairs 1  
fill ~9 ~17 ~34 ~9 ~17 ~36 wool 7  
fill ~9 ~17 ~38 ~9 ~17 ~40 wool 7  
fill ~9 ~17 ~42 ~9 ~17 ~44 wool 7  
fill ~9 ~17 ~69 ~9 ~20 ~69 wool 8  
fill ~10 ~17 ~20 ~10 ~19 ~20 glass 0  
fill ~10 ~17 ~24 ~10 ~20 ~24 stone_slab 1  
fill ~10 ~17 ~25 ~11 ~17 ~25 wool 8  
fill ~10 ~17 ~26 ~10 ~17 ~28 wool 7  
fill ~10 ~17 ~30 ~10 ~17 ~32 wool 7  
fill ~11 ~17 ~19 ~13 ~17 ~19 glass 0  
fill ~11 ~17 ~22 ~13 ~17 ~22 wool 7  
fill ~11 ~17 ~24 ~11 ~20 ~24 wool 8 
setblock ~11 ~17 ~39 quartz_stairs 5 
setblock ~11 ~17 ~40 wool 15 
setblock ~11 ~17 ~41 quartz_stairs 5  
fill ~11 ~17 ~47 ~11 ~17 ~48 leaves 15  
fill ~11 ~17 ~52 ~11 ~17 ~53 leaves 15  
fill ~11 ~17 ~72 ~12 ~17 ~72 wool 8 
setblock ~12 ~17 ~21 spruce_stairs 3 
setblock ~12 ~17 ~40 spruce_stairs 0  
fill ~12 ~17 ~58 ~14 ~17 ~58 wool 7  
fill ~12 ~17 ~60 ~12 ~20 ~60 wool 8  
fill ~12 ~17 ~61 ~12 ~17 ~62 spruce_stairs 1  
fill ~12 ~17 ~65 ~12 ~17 ~66 spruce_stairs 1  
fill ~12 ~17 ~67 ~12 ~20 ~67 wool 8  
fill ~12 ~17 ~68 ~12 ~18 ~68 leaves 15  
fill ~13 ~17 ~25 ~14 ~17 ~25 wool 8 
setblock ~13 ~17 ~37 quartz_stairs 7  
fill ~13 ~17 ~39 ~13 ~21 ~39 planks 1  
fill ~13 ~17 ~40 ~13 ~19 ~40 leaves 15  
fill ~13 ~17 ~41 ~13 ~21 ~41 planks 1 
setblock ~13 ~17 ~43 quartz_stairs 6 
setblock ~13 ~17 ~51 quartz_stairs 7 
setblock ~13 ~17 ~54 quartz_stairs 6 
setblock ~13 ~17 ~59 spruce_stairs 2  
fill ~13 ~17 ~60 ~14 ~17 ~60 wool 7  
fill ~13 ~17 ~61 ~13 ~17 ~62 sandstone 0  
fill ~13 ~17 ~65 ~13 ~17 ~66 sandstone 0  
fill ~13 ~17 ~67 ~14 ~17 ~67 wool 7  
fill ~13 ~17 ~68 ~14 ~17 ~68 stone_slab 9  
fill ~14 ~17 ~20 ~14 ~19 ~20 glass 0  
fill ~14 ~17 ~26 ~14 ~17 ~28 wool 7 
setblock ~14 ~17 ~37 wool 15 
setblock ~14 ~17 ~38 dark_oak_stairs 2  
fill ~14 ~17 ~39 ~14 ~18 ~39 leaves 15  
fill ~14 ~17 ~40 ~14 ~20 ~40 wool 15  
fill ~14 ~17 ~41 ~14 ~19 ~41 leaves 15 
setblock ~14 ~17 ~42 dark_oak_stairs 3 
setblock ~14 ~17 ~43 wool 15 
setblock ~14 ~17 ~51 wool 15 
setblock ~14 ~17 ~52 dark_oak_stairs 2 
setblock ~14 ~17 ~53 dark_oak_stairs 3 
setblock ~14 ~17 ~54 wool 15  
fill ~14 ~17 ~61 ~14 ~17 ~62 spruce_stairs 0  
fill ~14 ~17 ~65 ~14 ~17 ~66 spruce_stairs 0 
setblock ~14 ~17 ~72 wool 7  
fill ~15 ~17 ~22 ~15 ~19 ~22 glass 0  
fill ~15 ~17 ~23 ~15 ~20 ~23 glass 0  
fill ~15 ~17 ~24 ~15 ~20 ~24 glass 0  
fill ~15 ~17 ~25 ~15 ~20 ~25 glass 0 
setblock ~15 ~17 ~27 spruce_stairs 0 
setblock ~15 ~17 ~37 quartz_stairs 7  
fill ~15 ~17 ~39 ~15 ~21 ~39 planks 1  
fill ~15 ~17 ~40 ~15 ~19 ~40 leaves 15  
fill ~15 ~17 ~41 ~15 ~21 ~41 planks 1 
setblock ~15 ~17 ~43 quartz_stairs 6 
setblock ~15 ~17 ~51 quartz_stairs 7 
setblock ~15 ~17 ~54 quartz_stairs 6  
fill ~15 ~17 ~72 ~16 ~17 ~72 wool 8  
fill ~15 ~17 ~73 ~16 ~17 ~73 wool 8  
fill ~16 ~17 ~26 ~16 ~20 ~26 glass 0  
fill ~16 ~17 ~27 ~16 ~20 ~27 glass 0  
fill ~16 ~17 ~29 ~16 ~17 ~31 wool 7 
setblock ~16 ~17 ~40 spruce_stairs 1  
fill ~16 ~17 ~63 ~16 ~19 ~63 leaves 15  
fill ~16 ~17 ~64 ~16 ~20 ~64 leaves 15  
fill ~17 ~17 ~28 ~17 ~20 ~28 glass 0  
fill ~17 ~17 ~29 ~17 ~20 ~29 glass 0 
setblock ~17 ~17 ~30 spruce_stairs 0 
setblock ~17 ~17 ~39 quartz_stairs 4 
setblock ~17 ~17 ~40 wool 15 
setblock ~17 ~17 ~41 quartz_stairs 4  
fill ~17 ~17 ~47 ~17 ~17 ~48 leaves 15  
fill ~17 ~17 ~52 ~17 ~17 ~53 leaves 15  
fill ~17 ~17 ~74 ~18 ~17 ~74 wool 7  
fill ~18 ~17 ~30 ~18 ~20 ~30 glass 0  
fill ~18 ~17 ~31 ~18 ~20 ~31 glass 0  
fill ~18 ~17 ~33 ~18 ~17 ~35 wool 7  
fill ~19 ~17 ~32 ~19 ~20 ~32 glass 0 
setblock ~19 ~17 ~34 spruce_stairs 0  
fill ~19 ~17 ~37 ~21 ~17 ~37 wool 7 
setblock ~19 ~17 ~51 quartz_stairs 7 
setblock ~19 ~17 ~54 quartz_stairs 6  
fill ~19 ~17 ~72 ~20 ~17 ~72 wool 8  
fill ~19 ~17 ~73 ~20 ~17 ~73 wool 8  
fill ~19 ~17 ~74 ~20 ~17 ~74 wool 8  
fill ~20 ~17 ~33 ~20 ~20 ~33 glass 0  
fill ~20 ~17 ~34 ~20 ~20 ~34 glass 0 
setblock ~20 ~17 ~36 spruce_stairs 3 
setblock ~20 ~17 ~51 wool 15 
setblock ~20 ~17 ~52 dark_oak_stairs 2 
setblock ~20 ~17 ~53 dark_oak_stairs 7 
setblock ~20 ~17 ~54 wool 15  
fill ~20 ~17 ~59 ~20 ~19 ~59 leaves 15  
fill ~20 ~17 ~60 ~20 ~20 ~60 wool 8  
fill ~20 ~17 ~61 ~20 ~17 ~62 spruce_stairs 1  
fill ~20 ~17 ~65 ~20 ~17 ~66 spruce_stairs 1  
fill ~20 ~17 ~67 ~20 ~20 ~67 wool 8  
fill ~20 ~17 ~68 ~20 ~19 ~68 leaves 15  
fill ~21 ~17 ~35 ~21 ~20 ~35 glass 0  
fill ~21 ~17 ~43 ~23 ~17 ~43 wool 7 
setblock ~21 ~17 ~51 quartz_stairs 7 
setblock ~21 ~17 ~54 quartz_stairs 6  
fill ~21 ~17 ~58 ~23 ~17 ~58 wool 7  
fill ~21 ~17 ~60 ~22 ~17 ~60 wool 7  
fill ~21 ~17 ~61 ~22 ~17 ~61 sandstone 0  
fill ~21 ~17 ~62 ~22 ~17 ~62 sandstone 0  
fill ~21 ~17 ~65 ~22 ~17 ~65 sandstone 0  
fill ~21 ~17 ~66 ~22 ~17 ~66 sandstone 0  
fill ~21 ~17 ~67 ~22 ~17 ~67 wool 7  
fill ~21 ~17 ~68 ~22 ~17 ~68 stone_slab 9  
fill ~21 ~17 ~74 ~22 ~17 ~74 wool 7  
fill ~22 ~17 ~36 ~22 ~20 ~36 glass 0 
setblock ~22 ~17 ~44 spruce_stairs 2 
setblock ~22 ~17 ~59 spruce_stairs 2  
fill ~23 ~17 ~37 ~24 ~17 ~37 glass 0  
fill ~23 ~17 ~39 ~25 ~17 ~39 wool 7  
fill ~23 ~17 ~47 ~23 ~18 ~47 leaves 15  
fill ~23 ~17 ~48 ~23 ~20 ~48 leaves 15  
fill ~23 ~17 ~52 ~23 ~17 ~53 leaves 15  
fill ~23 ~17 ~60 ~23 ~20 ~60 wool 8  
fill ~23 ~17 ~61 ~23 ~17 ~62 spruce_stairs 0  
fill ~23 ~17 ~65 ~23 ~17 ~66 spruce_stairs 0  
fill ~23 ~17 ~67 ~23 ~20 ~67 wool 8  
fill ~23 ~17 ~68 ~23 ~19 ~68 leaves 15  
fill ~23 ~17 ~72 ~24 ~17 ~72 wool 8  
fill ~23 ~17 ~73 ~24 ~17 ~73 wool 8  
fill ~23 ~17 ~74 ~24 ~17 ~74 wool 8 
setblock ~24 ~17 ~38 spruce_stairs 3  
fill ~25 ~17 ~38 ~26 ~17 ~38 glass 0 
setblock ~25 ~17 ~51 quartz_stairs 7 
setblock ~25 ~17 ~54 quartz_stairs 6  
fill ~25 ~17 ~74 ~26 ~17 ~74 wool 7 
setblock ~26 ~17 ~51 wool 15 
setblock ~26 ~17 ~52 dark_oak_stairs 2 
setblock ~26 ~17 ~53 dark_oak_stairs 3 
setblock ~26 ~17 ~54 wool 15  
fill ~27 ~17 ~39 ~29 ~17 ~39 glass 0  
fill ~27 ~17 ~41 ~29 ~17 ~41 wool 7 
setblock ~27 ~17 ~51 quartz_stairs 7 
setblock ~27 ~17 ~54 quartz_stairs 6  
fill ~27 ~17 ~63 ~27 ~19 ~63 leaves 15  
fill ~27 ~17 ~64 ~27 ~20 ~64 leaves 15  
fill ~27 ~17 ~72 ~28 ~17 ~72 wool 8  
fill ~27 ~17 ~73 ~28 ~17 ~73 wool 8  
fill ~27 ~17 ~74 ~28 ~17 ~74 wool 8 
setblock ~28 ~17 ~40 spruce_stairs 3  
fill ~29 ~17 ~47 ~29 ~18 ~47 leaves 15  
fill ~29 ~17 ~48 ~29 ~20 ~48 leaves 15  
fill ~29 ~17 ~52 ~29 ~17 ~53 leaves 15  
fill ~29 ~17 ~58 ~31 ~17 ~58 wool 7  
fill ~29 ~17 ~60 ~30 ~17 ~60 wool 7  
fill ~29 ~17 ~61 ~29 ~17 ~62 spruce_stairs 1  
fill ~29 ~17 ~65 ~29 ~17 ~66 spruce_stairs 1  
fill ~29 ~17 ~67 ~30 ~17 ~67 wool 7  
fill ~29 ~17 ~68 ~30 ~17 ~68 stone_slab 9  
fill ~30 ~17 ~40 ~33 ~17 ~40 glass 0 
setblock ~30 ~17 ~59 spruce_stairs 2  
fill ~30 ~17 ~61 ~30 ~17 ~62 sandstone 0  
fill ~30 ~17 ~65 ~30 ~17 ~66 sandstone 0 
setblock ~30 ~17 ~72 wool 7  
fill ~31 ~17 ~42 ~33 ~17 ~42 wool 7 
setblock ~31 ~17 ~51 quartz_stairs 6 
setblock ~31 ~17 ~54 quartz_stairs 6  
fill ~31 ~17 ~60 ~31 ~20 ~60 wool 8  
fill ~31 ~17 ~61 ~31 ~17 ~62 spruce_stairs 0  
fill ~31 ~17 ~65 ~31 ~17 ~66 spruce_stairs 0  
fill ~31 ~17 ~67 ~31 ~20 ~67 wool 8  
fill ~31 ~17 ~68 ~31 ~19 ~68 leaves 15  
fill ~31 ~17 ~72 ~32 ~17 ~72 wool 8  
fill ~31 ~17 ~73 ~32 ~17 ~73 wool 8 
setblock ~32 ~17 ~41 spruce_stairs 3 
setblock ~32 ~17 ~51 wool 15 
setblock ~32 ~17 ~52 dark_oak_stairs 2 
setblock ~32 ~17 ~53 dark_oak_stairs 3 
setblock ~32 ~17 ~54 wool 15 
setblock ~33 ~17 ~51 quartz_stairs 6 
setblock ~33 ~17 ~54 quartz_stairs 6  
fill ~34 ~17 ~41 ~38 ~17 ~41 glass 0  
fill ~34 ~17 ~70 ~34 ~20 ~70 wool 8  
fill ~35 ~17 ~47 ~35 ~19 ~47 leaves 15  
fill ~35 ~17 ~48 ~35 ~20 ~48 leaves 15  
fill ~35 ~17 ~52 ~35 ~17 ~53 leaves 15  
fill ~35 ~17 ~69 ~35 ~20 ~69 wool 8  
fill ~36 ~17 ~43 ~39 ~17 ~43 wool 7 
setblock ~36 ~17 ~50 quartz_stairs 7 
setblock ~36 ~17 ~54 quartz_stairs 6  
fill ~36 ~17 ~61 ~37 ~17 ~61 spruce_stairs 3  
fill ~36 ~17 ~62 ~37 ~17 ~62 sandstone 0  
fill ~36 ~17 ~63 ~37 ~17 ~63 sandstone 0  
fill ~36 ~17 ~64 ~37 ~17 ~64 spruce_stairs 2 
setblock ~37 ~17 ~42 spruce_stairs 3 
setblock ~37 ~17 ~50 wool 15 
setblock ~37 ~17 ~51 dark_oak_stairs 2 
setblock ~37 ~17 ~53 dark_oak_stairs 3 
setblock ~37 ~17 ~54 wool 15  
fill ~37 ~17 ~58 ~37 ~17 ~59 wool 7  
fill ~38 ~17 ~40 ~38 ~26 ~40 planks 1 
setblock ~38 ~17 ~50 quartz_stairs 7 
setblock ~38 ~17 ~54 quartz_stairs 6  
fill ~38 ~17 ~55 ~38 ~18 ~55 wool 8  
fill ~38 ~17 ~56 ~38 ~18 ~56 wool 7 
setblock ~38 ~17 ~58 spruce_stairs 0  
fill ~38 ~17 ~60 ~38 ~19 ~60 leaves 15  
fill ~39 ~17 ~40 ~39 ~18 ~40 wool 7  
fill ~39 ~17 ~41 ~39 ~18 ~41 wool 7  
fill ~39 ~17 ~42 ~39 ~18 ~42 wool 7  
fill ~39 ~17 ~44 ~39 ~18 ~44 wool 7  
fill ~39 ~17 ~45 ~39 ~18 ~45 wool 7  
fill ~39 ~17 ~46 ~39 ~18 ~46 wool 7  
fill ~39 ~17 ~47 ~39 ~18 ~47 wool 7  
fill ~39 ~17 ~48 ~39 ~18 ~48 wool 7  
fill ~39 ~17 ~49 ~39 ~18 ~49 wool 7  
fill ~39 ~17 ~50 ~39 ~18 ~50 wool 7  
fill ~39 ~17 ~51 ~39 ~18 ~51 wool 7  
fill ~39 ~17 ~52 ~39 ~18 ~52 wool 7  
fill ~39 ~17 ~53 ~39 ~18 ~53 wool 7  
fill ~39 ~17 ~54 ~39 ~18 ~54 wool 7  
fill ~10 ~18 ~25 ~11 ~18 ~25 wool 8  
fill ~11 ~18 ~19 ~13 ~18 ~19 glass 0 
setblock ~11 ~18 ~39 lever 6 
setblock ~11 ~18 ~40 heavy_weighted_pressure_plate 0 
setblock ~11 ~18 ~41 flower_pot 0 
setblock ~11 ~18 ~47 leaves 11  
fill ~11 ~18 ~48 ~11 ~20 ~48 leaves 15  
fill ~11 ~18 ~52 ~11 ~18 ~53 dropper 2  
fill ~11 ~18 ~72 ~12 ~18 ~72 wool 8  
fill ~13 ~18 ~25 ~14 ~18 ~25 wool 8 
setblock ~13 ~18 ~37 flower_pot 0 
setblock ~13 ~18 ~43 lever 13 
setblock ~13 ~18 ~51 flower_pot 0 
setblock ~13 ~18 ~54 lever 13  
fill ~13 ~18 ~60 ~14 ~18 ~60 wool 7  
fill ~13 ~18 ~67 ~14 ~18 ~67 wool 7  
fill ~13 ~18 ~68 ~14 ~18 ~68 stone_slab 9 
setblock ~14 ~18 ~37 heavy_weighted_pressure_plate 0 
setblock ~14 ~18 ~43 heavy_weighted_pressure_plate 0 
setblock ~14 ~18 ~51 heavy_weighted_pressure_plate 0 
setblock ~14 ~18 ~54 heavy_weighted_pressure_plate 0  
fill ~14 ~18 ~72 ~14 ~20 ~72 glass 0  
fill ~14 ~18 ~73 ~14 ~20 ~73 glass 0 
setblock ~15 ~18 ~37 lever 5 
setblock ~15 ~18 ~43 flower_pot 0 
setblock ~15 ~18 ~51 lever 5 
setblock ~15 ~18 ~54 flower_pot 0  
fill ~15 ~18 ~72 ~16 ~18 ~72 wool 8  
fill ~15 ~18 ~73 ~16 ~18 ~73 wool 8 
setblock ~17 ~18 ~39 flower_pot 0 
setblock ~17 ~18 ~40 heavy_weighted_pressure_plate 0 
setblock ~17 ~18 ~41 lever 14 
setblock ~17 ~18 ~47 leaves 11  
fill ~17 ~18 ~48 ~17 ~20 ~48 leaves 15  
fill ~17 ~18 ~52 ~17 ~18 ~53 dropper 2  
fill ~17 ~18 ~74 ~18 ~18 ~74 wool 7 
setblock ~19 ~18 ~51 flower_pot 0 
setblock ~19 ~18 ~54 lever 13  
fill ~19 ~18 ~72 ~20 ~18 ~72 wool 8  
fill ~19 ~18 ~73 ~20 ~18 ~73 wool 8  
fill ~19 ~18 ~74 ~20 ~18 ~74 wool 8 
setblock ~20 ~18 ~51 heavy_weighted_pressure_plate 0 
setblock ~20 ~18 ~54 heavy_weighted_pressure_plate 0 
setblock ~21 ~18 ~51 lever 5 
setblock ~21 ~18 ~54 flower_pot 0  
fill ~21 ~18 ~60 ~22 ~18 ~60 wool 7  
fill ~21 ~18 ~67 ~22 ~18 ~67 wool 7  
fill ~21 ~18 ~68 ~22 ~18 ~68 stone_slab 9 
fill ~21 ~18 ~74 ~22 ~18 ~74 wool 7  
fill ~23 ~18 ~37 ~24 ~18 ~37 glass 0  
fill ~23 ~18 ~52 ~23 ~18 ~53 dropper 2  
fill ~23 ~18 ~72 ~24 ~18 ~72 wool 8  
fill ~23 ~18 ~73 ~24 ~18 ~73 wool 8  
fill ~23 ~18 ~74 ~24 ~18 ~74 wool 8  
fill ~25 ~18 ~38 ~26 ~18 ~38 glass 0 
setblock ~25 ~18 ~51 flower_pot 0 
setblock ~25 ~18 ~54 lever 13  
fill ~25 ~18 ~74 ~26 ~18 ~74 wool 7 
setblock ~26 ~18 ~51 heavy_weighted_pressure_plate 0 
setblock ~26 ~18 ~54 heavy_weighted_pressure_plate 0  
fill ~27 ~18 ~39 ~29 ~18 ~39 glass 0 
setblock ~27 ~18 ~51 lever 5 
setblock ~27 ~18 ~54 flower_pot 0  
fill ~27 ~18 ~72 ~28 ~18 ~72 wool 8  
fill ~27 ~18 ~73 ~28 ~18 ~73 wool 8  
fill ~27 ~18 ~74 ~28 ~18 ~74 wool 8  
fill ~29 ~18 ~52 ~29 ~18 ~53 dropper 2  
fill ~29 ~18 ~60 ~30 ~18 ~60 wool 7  
fill ~29 ~18 ~67 ~30 ~18 ~67 wool 7  
fill ~29 ~18 ~68 ~30 ~18 ~68 stone_slab 9  
fill ~30 ~18 ~40 ~33 ~18 ~40 glass 0  
fill ~30 ~18 ~72 ~30 ~20 ~72 glass 0  
fill ~30 ~18 ~73 ~30 ~20 ~73 glass 0 
setblock ~31 ~18 ~51 flower_pot 0 
setblock ~31 ~18 ~54 lever 13  
fill ~31 ~18 ~72 ~32 ~18 ~72 wool 8  
fill ~31 ~18 ~73 ~32 ~18 ~73 wool 8 
setblock ~32 ~18 ~51 heavy_weighted_pressure_plate 0 
setblock ~32 ~18 ~54 heavy_weighted_pressure_plate 0 
setblock ~33 ~18 ~51 lever 13 
setblock ~33 ~18 ~54 flower_pot 0  
fill ~34 ~18 ~41 ~38 ~18 ~41 glass 0  
fill ~35 ~18 ~52 ~35 ~18 ~53 dropper 2 
setblock ~36 ~18 ~50 flower_pot 0 
setblock ~36 ~18 ~54 lever 13 
setblock ~37 ~18 ~50 heavy_weighted_pressure_plate 0 
setblock ~37 ~18 ~54 heavy_weighted_pressure_plate 0  
fill ~37 ~18 ~66 ~37 ~20 ~66 glass 0 
setblock ~38 ~18 ~50 lever 5 
setblock ~38 ~18 ~54 flower_pot 0 
setblock ~39 ~18 ~43 wool 7  
fill ~10 ~19 ~25 ~11 ~19 ~25 wool 8  
fill ~11 ~19 ~19 ~13 ~19 ~19 glass 0  
fill ~11 ~19 ~47 ~11 ~20 ~47 leaves 15  
fill ~11 ~19 ~52 ~11 ~19 ~53 dropper 0  
fill ~11 ~19 ~72 ~12 ~19 ~72 wool 8 
setblock ~12 ~19 ~25 spruce_stairs 3 
setblock ~12 ~19 ~68 leaves 11  
fill ~13 ~19 ~25 ~14 ~19 ~25 wool 8  
fill ~13 ~19 ~60 ~14 ~19 ~60 wool 7  
fill ~13 ~19 ~67 ~14 ~19 ~67 wool 7  
fill ~13 ~19 ~68 ~14 ~19 ~68 stone_slab 9 
setblock ~14 ~19 ~39 leaves 11  
fill ~15 ~19 ~72 ~16 ~19 ~72 wool 8  
fill ~15 ~19 ~73 ~16 ~19 ~73 wool 8  
fill ~17 ~19 ~47 ~17 ~20 ~47 leaves 15  
fill ~17 ~19 ~52 ~17 ~19 ~53 dropper 0  
fill ~17 ~19 ~74 ~18 ~19 ~74 wool 7  
fill ~19 ~19 ~72 ~20 ~19 ~72 wool 8  
fill ~19 ~19 ~73 ~20 ~19 ~73 wool 8  
fill ~19 ~19 ~74 ~20 ~19 ~74 wool 8  
fill ~21 ~19 ~60 ~22 ~19 ~60 wool 7  
fill ~21 ~19 ~67 ~22 ~19 ~67 wool 7  
fill ~21 ~19 ~68 ~22 ~19 ~68 stone_slab 9  
fill ~21 ~19 ~74 ~22 ~19 ~74 wool 7  
fill ~23 ~19 ~37 ~24 ~19 ~37 glass 0 
setblock ~23 ~19 ~47 leaves 11  
fill ~23 ~19 ~52 ~23 ~19 ~53 dropper 0  
fill ~23 ~19 ~72 ~24 ~19 ~72 wool 8  
fill ~23 ~19 ~73 ~24 ~19 ~73 wool 8  
fill ~23 ~19 ~74 ~24 ~19 ~74 wool 8  
fill ~25 ~19 ~38 ~26 ~19 ~38 glass 0  
fill ~25 ~19 ~74 ~26 ~19 ~74 wool 7  
fill ~27 ~19 ~39 ~29 ~19 ~39 glass 0  
fill ~27 ~19 ~72 ~28 ~19 ~72 wool 8  
fill ~27 ~19 ~73 ~28 ~19 ~73 wool 8  
fill ~27 ~19 ~74 ~28 ~19 ~74 wool 8 
setblock ~29 ~19 ~47 leaves 11  
fill ~29 ~19 ~52 ~29 ~19 ~53 dropper 0  
fill ~29 ~19 ~60 ~30 ~19 ~60 wool 7  
fill ~29 ~19 ~67 ~30 ~19 ~67 wool 7  
fill ~29 ~19 ~68 ~30 ~19 ~68 stone_slab 9  
fill ~31 ~19 ~40 ~33 ~19 ~40 glass 0  
fill ~31 ~19 ~72 ~32 ~19 ~72 wool 8  
fill ~31 ~19 ~73 ~32 ~19 ~73 wool 8  
fill ~34 ~19 ~41 ~38 ~19 ~41 glass 0  
fill ~35 ~19 ~52 ~35 ~19 ~53 dropper 0  
fill ~38 ~19 ~55 ~38 ~21 ~55 wool 7 
setblock ~38 ~19 ~56 wool 8  
fill ~39 ~19 ~40 ~39 ~20 ~40 wool 8  
fill ~39 ~19 ~41 ~39 ~20 ~41 wool 8  
fill ~39 ~19 ~42 ~39 ~20 ~42 wool 8  
fill ~39 ~19 ~43 ~39 ~20 ~43 wool 8  
fill ~39 ~19 ~44 ~39 ~20 ~44 wool 8  
fill ~39 ~19 ~45 ~39 ~20 ~45 wool 8  
fill ~39 ~19 ~46 ~39 ~20 ~46 wool 8  
fill ~39 ~19 ~47 ~39 ~20 ~47 wool 8  
fill ~39 ~19 ~48 ~39 ~20 ~48 wool 8  
fill ~39 ~19 ~49 ~39 ~20 ~49 wool 8  
fill ~39 ~19 ~50 ~39 ~20 ~50 wool 8  
fill ~39 ~19 ~51 ~39 ~20 ~51 wool 8  
fill ~39 ~19 ~52 ~39 ~20 ~52 wool 8  
fill ~39 ~19 ~53 ~39 ~20 ~53 wool 8  
fill ~39 ~19 ~54 ~39 ~20 ~54 wool 8 
setblock ~5 ~20 ~52 leaves 11 
setblock ~6 ~20 ~60 leaves 11 
setblock ~9 ~20 ~25 leaves 11 
setblock ~10 ~20 ~21 glass 0  
fill ~10 ~20 ~25 ~14 ~20 ~25 wool 8  
fill ~11 ~20 ~20 ~13 ~20 ~20 glass 0  
fill ~11 ~20 ~52 ~11 ~20 ~53 leaves 15  
fill ~11 ~20 ~72 ~12 ~20 ~72 wool 8 
setblock ~12 ~20 ~40 spruce_stairs 4 
setblock ~12 ~20 ~68 leaves 15 
setblock ~13 ~20 ~40 glowstone 0  
fill ~13 ~20 ~60 ~14 ~20 ~60 wool 7  
fill ~13 ~20 ~67 ~14 ~20 ~67 wool 7  
fill ~13 ~20 ~68 ~14 ~20 ~68 stone_slab 9 
setblock ~14 ~20 ~21 glass 0 
setblock ~14 ~20 ~38 spruce_stairs 6 
setblock ~14 ~20 ~39 glowstone 0  
fill ~14 ~20 ~41 ~14 ~21 ~41 glowstone 0 
