fill ~-5 ~0 ~11 ~18 ~0 ~11 stained_hardened_clay 6  
fill ~-5 ~0 ~12 ~18 ~0 ~12 stained_hardened_clay 6  
fill ~17 ~0 ~-3 ~18 ~0 ~-3 stained_hardened_clay 6  
fill ~17 ~0 ~-2 ~18 ~0 ~-2 stained_hardened_clay 6  
fill ~17 ~0 ~23 ~18 ~0 ~23 stained_hardened_clay 6  
fill ~17 ~0 ~24 ~18 ~0 ~24 stained_hardened_clay 6  
fill ~19 ~0 ~-5 ~20 ~0 ~-5 stained_hardened_clay 6  
fill ~19 ~0 ~-4 ~20 ~0 ~-4 stained_hardened_clay 6  
fill ~19 ~0 ~-3 ~20 ~0 ~-3 concrete 6  
fill ~19 ~0 ~-2 ~20 ~0 ~-2 concrete 6  
fill ~19 ~0 ~-1 ~20 ~0 ~-1 concrete 6  
fill ~19 ~0 ~0 ~20 ~0 ~0 concrete 6  
fill ~19 ~0 ~3 ~20 ~0 ~3 concrete 6  
fill ~19 ~0 ~4 ~20 ~0 ~4 concrete 6  
fill ~19 ~0 ~5 ~20 ~0 ~5 concrete 6  
fill ~19 ~0 ~6 ~20 ~0 ~6 concrete 6  
fill ~19 ~0 ~7 ~20 ~0 ~7 concrete 6  
fill ~19 ~0 ~8 ~20 ~0 ~8 concrete 6  
fill ~19 ~0 ~9 ~20 ~0 ~9 concrete 6  
fill ~19 ~0 ~10 ~20 ~0 ~10 concrete 6  
fill ~19 ~0 ~11 ~46 ~0 ~11 wool 6  
fill ~19 ~0 ~12 ~46 ~0 ~12 wool 6  
fill ~19 ~0 ~13 ~20 ~0 ~13 concrete 6  
fill ~19 ~0 ~14 ~20 ~0 ~14 concrete 6  
fill ~19 ~0 ~15 ~20 ~0 ~15 concrete 6  
fill ~19 ~0 ~16 ~20 ~0 ~16 concrete 6  
fill ~19 ~0 ~17 ~20 ~0 ~17 concrete 6  
fill ~19 ~0 ~18 ~20 ~0 ~18 concrete 6  
fill ~19 ~0 ~21 ~20 ~0 ~21 concrete 6  
fill ~19 ~0 ~22 ~20 ~0 ~22 concrete 6  
fill ~19 ~0 ~23 ~20 ~0 ~23 concrete 6  
fill ~19 ~0 ~24 ~20 ~0 ~24 concrete 6  
fill ~19 ~0 ~25 ~20 ~0 ~25 stained_hardened_clay 6  
fill ~19 ~0 ~26 ~20 ~0 ~26 stained_hardened_clay 6  
fill ~21 ~0 ~-3 ~22 ~0 ~-3 stained_hardened_clay 6  
fill ~21 ~0 ~-2 ~22 ~0 ~-2 stained_hardened_clay 6  
fill ~21 ~0 ~1 ~22 ~0 ~1 concrete 6  
fill ~21 ~0 ~2 ~22 ~0 ~2 concrete 6  
fill ~21 ~0 ~3 ~22 ~0 ~3 wool 6  
fill ~21 ~0 ~4 ~22 ~0 ~4 wool 6  
fill ~21 ~0 ~5 ~44 ~0 ~5 wool 6  
fill ~21 ~0 ~6 ~44 ~0 ~6 wool 6  
fill ~21 ~0 ~7 ~46 ~0 ~7 wool 6  
fill ~21 ~0 ~8 ~46 ~0 ~8 wool 6  
fill ~21 ~0 ~9 ~46 ~0 ~9 wool 6  
fill ~21 ~0 ~10 ~46 ~0 ~10 wool 6  
fill ~21 ~0 ~13 ~46 ~0 ~13 wool 6  
fill ~21 ~0 ~14 ~46 ~0 ~14 wool 6  
fill ~21 ~0 ~15 ~44 ~0 ~15 wool 6  
fill ~21 ~0 ~16 ~44 ~0 ~16 wool 6  
fill ~21 ~0 ~17 ~22 ~0 ~17 wool 6  
fill ~21 ~0 ~18 ~22 ~0 ~18 wool 6  
fill ~21 ~0 ~19 ~22 ~0 ~19 concrete 6  
fill ~21 ~0 ~20 ~22 ~0 ~20 concrete 6  
fill ~21 ~0 ~23 ~22 ~0 ~23 stained_hardened_clay 6  
fill ~21 ~0 ~24 ~22 ~0 ~24 stained_hardened_clay 6  
fill ~23 ~0 ~3 ~26 ~0 ~3 concrete 6  
fill ~23 ~0 ~4 ~26 ~0 ~4 concrete 6  
fill ~23 ~0 ~17 ~24 ~0 ~17 stained_hardened_clay 2  
fill ~23 ~0 ~18 ~24 ~0 ~18 stained_hardened_clay 2  
fill ~25 ~0 ~17 ~26 ~0 ~17 concrete 6  
fill ~25 ~0 ~18 ~26 ~0 ~18 concrete 6  
fill ~27 ~0 ~3 ~28 ~0 ~3 stained_hardened_clay 2  
fill ~27 ~0 ~4 ~28 ~0 ~4 stained_hardened_clay 2  
fill ~27 ~0 ~17 ~28 ~0 ~17 stained_hardened_clay 2  
fill ~27 ~0 ~18 ~28 ~0 ~18 stained_hardened_clay 2  
fill ~29 ~0 ~-3 ~30 ~0 ~-3 stained_hardened_clay 6  
fill ~29 ~0 ~-2 ~30 ~0 ~-2 stained_hardened_clay 6  
fill ~29 ~0 ~3 ~30 ~0 ~3 concrete 6  
fill ~29 ~0 ~4 ~30 ~0 ~4 concrete 6  
fill ~29 ~0 ~17 ~30 ~0 ~17 concrete 6  
fill ~29 ~0 ~18 ~30 ~0 ~18 concrete 6  
fill ~29 ~0 ~23 ~30 ~0 ~23 stained_hardened_clay 6  
fill ~29 ~0 ~24 ~30 ~0 ~24 stained_hardened_clay 6  
fill ~31 ~0 ~-5 ~32 ~0 ~-5 stained_hardened_clay 6  
fill ~31 ~0 ~-4 ~32 ~0 ~-4 stained_hardened_clay 6  
fill ~31 ~0 ~-3 ~32 ~0 ~-3 concrete 6  
fill ~31 ~0 ~-2 ~32 ~0 ~-2 concrete 6  
fill ~31 ~0 ~-1 ~32 ~0 ~-1 concrete 6  
fill ~31 ~0 ~0 ~32 ~0 ~0 concrete 6  
fill ~31 ~0 ~3 ~32 ~0 ~3 stained_hardened_clay 2  
fill ~31 ~0 ~4 ~32 ~0 ~4 stained_hardened_clay 2  
fill ~31 ~0 ~17 ~32 ~0 ~17 stained_hardened_clay 2  
fill ~31 ~0 ~18 ~32 ~0 ~18 stained_hardened_clay 2  
fill ~31 ~0 ~21 ~32 ~0 ~21 concrete 6  
fill ~31 ~0 ~22 ~32 ~0 ~22 concrete 6  
fill ~31 ~0 ~23 ~32 ~0 ~23 concrete 6  
fill ~31 ~0 ~24 ~32 ~0 ~24 concrete 6  
fill ~31 ~0 ~25 ~32 ~0 ~25 stained_hardened_clay 6  
fill ~31 ~0 ~26 ~32 ~0 ~26 stained_hardened_clay 6  
fill ~33 ~0 ~-3 ~34 ~0 ~-3 stained_hardened_clay 6  
fill ~33 ~0 ~-2 ~34 ~0 ~-2 stained_hardened_clay 6  
fill ~33 ~0 ~1 ~34 ~0 ~1 concrete 6  
fill ~33 ~0 ~2 ~34 ~0 ~2 concrete 6  
fill ~33 ~0 ~3 ~34 ~0 ~3 wool 6  
fill ~33 ~0 ~4 ~34 ~0 ~4 wool 6  
fill ~33 ~0 ~17 ~34 ~0 ~17 wool 6  
fill ~33 ~0 ~18 ~34 ~0 ~18 wool 6  
fill ~33 ~0 ~19 ~34 ~0 ~19 concrete 6  
fill ~33 ~0 ~20 ~34 ~0 ~20 concrete 6  
fill ~33 ~0 ~23 ~34 ~0 ~23 stained_hardened_clay 6  
fill ~33 ~0 ~24 ~34 ~0 ~24 stained_hardened_clay 6  
fill ~35 ~0 ~3 ~36 ~0 ~3 stained_hardened_clay 2  
fill ~35 ~0 ~4 ~36 ~0 ~4 stained_hardened_clay 2  
fill ~35 ~0 ~17 ~36 ~0 ~17 stained_hardened_clay 2  
fill ~35 ~0 ~18 ~36 ~0 ~18 stained_hardened_clay 2  
fill ~37 ~0 ~-1 ~38 ~0 ~-1 concrete 6  
fill ~37 ~0 ~0 ~38 ~0 ~0 concrete 6  
fill ~37 ~0 ~1 ~38 ~0 ~1 stained_hardened_clay 2  
fill ~37 ~0 ~2 ~38 ~0 ~2 stained_hardened_clay 2  
fill ~37 ~0 ~3 ~38 ~0 ~3 wool 6  
fill ~37 ~0 ~4 ~38 ~0 ~4 wool 6  
fill ~37 ~0 ~17 ~38 ~0 ~17 wool 6  
fill ~37 ~0 ~18 ~38 ~0 ~18 wool 6  
fill ~37 ~0 ~19 ~38 ~0 ~19 stained_hardened_clay 2  
fill ~37 ~0 ~20 ~38 ~0 ~20 stained_hardened_clay 2  
fill ~37 ~0 ~21 ~38 ~0 ~21 concrete 6  
fill ~37 ~0 ~22 ~38 ~0 ~22 concrete 6  
fill ~39 ~0 ~3 ~46 ~0 ~3 stained_hardened_clay 2  
fill ~39 ~0 ~4 ~46 ~0 ~4 stained_hardened_clay 2  
fill ~39 ~0 ~17 ~46 ~0 ~17 stained_hardened_clay 2  
fill ~39 ~0 ~18 ~46 ~0 ~18 stained_hardened_clay 2  
fill ~45 ~0 ~5 ~46 ~0 ~5 concrete 6  
fill ~45 ~0 ~6 ~46 ~0 ~6 concrete 6  
fill ~45 ~0 ~15 ~46 ~0 ~15 concrete 6  
fill ~45 ~0 ~16 ~46 ~0 ~16 concrete 6  
fill ~-5 ~1 ~11 ~18 ~1 ~11 stained_hardened_clay 6  
fill ~-5 ~1 ~12 ~18 ~1 ~12 stained_hardened_clay 6  
fill ~17 ~1 ~-3 ~18 ~1 ~-3 stained_hardened_clay 6  
fill ~17 ~1 ~-2 ~18 ~1 ~-2 stained_hardened_clay 6  
fill ~17 ~1 ~23 ~18 ~1 ~23 stained_hardened_clay 6  
fill ~17 ~1 ~24 ~18 ~1 ~24 stained_hardened_clay 6  
fill ~19 ~1 ~-5 ~20 ~1 ~-5 stained_hardened_clay 6  
fill ~19 ~1 ~-4 ~20 ~1 ~-4 stained_hardened_clay 6  
fill ~19 ~1 ~-3 ~20 ~1 ~-3 concrete 6  
fill ~19 ~1 ~-2 ~20 ~1 ~-2 concrete 6  
fill ~19 ~1 ~-1 ~20 ~1 ~-1 concrete 6  
fill ~19 ~1 ~0 ~20 ~1 ~0 concrete 6  
fill ~19 ~1 ~3 ~20 ~1 ~3 concrete 6  
fill ~19 ~1 ~4 ~20 ~1 ~4 concrete 6  
fill ~19 ~1 ~5 ~20 ~1 ~5 concrete 6  
fill ~19 ~1 ~6 ~20 ~1 ~6 concrete 6  
fill ~19 ~1 ~7 ~20 ~1 ~7 concrete 6  
fill ~19 ~1 ~8 ~20 ~1 ~8 concrete 6  
fill ~19 ~1 ~9 ~20 ~1 ~9 concrete 6  
fill ~19 ~1 ~10 ~20 ~1 ~10 concrete 6  
fill ~19 ~1 ~11 ~46 ~1 ~11 wool 6  
fill ~19 ~1 ~12 ~46 ~1 ~12 wool 6  
fill ~19 ~1 ~13 ~20 ~1 ~13 concrete 6  
fill ~19 ~1 ~14 ~20 ~1 ~14 concrete 6  
fill ~19 ~1 ~15 ~20 ~1 ~15 concrete 6  
fill ~19 ~1 ~16 ~20 ~1 ~16 concrete 6  
fill ~19 ~1 ~17 ~20 ~1 ~17 concrete 6  
fill ~19 ~1 ~18 ~20 ~1 ~18 concrete 6  
fill ~19 ~1 ~21 ~20 ~1 ~21 concrete 6  
fill ~19 ~1 ~22 ~20 ~1 ~22 concrete 6  
fill ~19 ~1 ~23 ~20 ~1 ~23 concrete 6  
fill ~19 ~1 ~24 ~20 ~1 ~24 concrete 6  
fill ~19 ~1 ~25 ~20 ~1 ~25 stained_hardened_clay 6  
fill ~19 ~1 ~26 ~20 ~1 ~26 stained_hardened_clay 6  
fill ~21 ~1 ~-3 ~22 ~1 ~-3 stained_hardened_clay 6  
fill ~21 ~1 ~-2 ~22 ~1 ~-2 stained_hardened_clay 6  
fill ~21 ~1 ~1 ~22 ~1 ~1 concrete 6  
fill ~21 ~1 ~2 ~22 ~1 ~2 concrete 6  
fill ~21 ~1 ~3 ~22 ~1 ~3 wool 6  
fill ~21 ~1 ~4 ~22 ~1 ~4 wool 6  
fill ~21 ~1 ~5 ~44 ~1 ~5 wool 6  
fill ~21 ~1 ~6 ~44 ~1 ~6 wool 6  
fill ~21 ~1 ~7 ~46 ~1 ~7 wool 6  
fill ~21 ~1 ~8 ~46 ~1 ~8 wool 6  
fill ~21 ~1 ~9 ~46 ~1 ~9 wool 6  
fill ~21 ~1 ~10 ~46 ~1 ~10 wool 6  
fill ~21 ~1 ~13 ~46 ~1 ~13 wool 6  
fill ~21 ~1 ~14 ~46 ~1 ~14 wool 6  
fill ~21 ~1 ~15 ~44 ~1 ~15 wool 6  
fill ~21 ~1 ~16 ~44 ~1 ~16 wool 6  
fill ~21 ~1 ~17 ~22 ~1 ~17 wool 6  
fill ~21 ~1 ~18 ~22 ~1 ~18 wool 6  
fill ~21 ~1 ~19 ~22 ~1 ~19 concrete 6  
fill ~21 ~1 ~20 ~22 ~1 ~20 concrete 6  
fill ~21 ~1 ~23 ~22 ~1 ~23 stained_hardened_clay 6  
fill ~21 ~1 ~24 ~22 ~1 ~24 stained_hardened_clay 6  
fill ~23 ~1 ~3 ~26 ~1 ~3 concrete 6  
fill ~23 ~1 ~4 ~26 ~1 ~4 concrete 6  
fill ~23 ~1 ~17 ~24 ~1 ~17 stained_hardened_clay 2  
fill ~23 ~1 ~18 ~24 ~1 ~18 stained_hardened_clay 2  
fill ~25 ~1 ~17 ~26 ~1 ~17 concrete 6  
fill ~25 ~1 ~18 ~26 ~1 ~18 concrete 6  
fill ~27 ~1 ~3 ~28 ~1 ~3 stained_hardened_clay 2  
fill ~27 ~1 ~4 ~28 ~1 ~4 stained_hardened_clay 2  
fill ~27 ~1 ~17 ~28 ~1 ~17 stained_hardened_clay 2  
fill ~27 ~1 ~18 ~28 ~1 ~18 stained_hardened_clay 2  
fill ~29 ~1 ~-3 ~30 ~1 ~-3 stained_hardened_clay 6  
fill ~29 ~1 ~-2 ~30 ~1 ~-2 stained_hardened_clay 6  
fill ~29 ~1 ~3 ~30 ~1 ~3 concrete 6  
fill ~29 ~1 ~4 ~30 ~1 ~4 concrete 6  
fill ~29 ~1 ~17 ~30 ~1 ~17 concrete 6  
fill ~29 ~1 ~18 ~30 ~1 ~18 concrete 6  
fill ~29 ~1 ~23 ~30 ~1 ~23 stained_hardened_clay 6  
fill ~29 ~1 ~24 ~30 ~1 ~24 stained_hardened_clay 6  
fill ~31 ~1 ~-5 ~32 ~1 ~-5 stained_hardened_clay 6  
fill ~31 ~1 ~-4 ~32 ~1 ~-4 stained_hardened_clay 6  
fill ~31 ~1 ~-3 ~32 ~1 ~-3 concrete 6  
fill ~31 ~1 ~-2 ~32 ~1 ~-2 concrete 6  
fill ~31 ~1 ~-1 ~32 ~1 ~-1 concrete 6  
fill ~31 ~1 ~0 ~32 ~1 ~0 concrete 6  
fill ~31 ~1 ~3 ~32 ~1 ~3 stained_hardened_clay 2  
fill ~31 ~1 ~4 ~32 ~1 ~4 stained_hardened_clay 2  
fill ~31 ~1 ~17 ~32 ~1 ~17 stained_hardened_clay 2  
fill ~31 ~1 ~18 ~32 ~1 ~18 stained_hardened_clay 2  
fill ~31 ~1 ~21 ~32 ~1 ~21 concrete 6  
fill ~31 ~1 ~22 ~32 ~1 ~22 concrete 6  
fill ~31 ~1 ~23 ~32 ~1 ~23 concrete 6  
fill ~31 ~1 ~24 ~32 ~1 ~24 concrete 6  
fill ~31 ~1 ~25 ~32 ~1 ~25 stained_hardened_clay 6  
fill ~31 ~1 ~26 ~32 ~1 ~26 stained_hardened_clay 6  
fill ~33 ~1 ~-3 ~34 ~1 ~-3 stained_hardened_clay 6  
fill ~33 ~1 ~-2 ~34 ~1 ~-2 stained_hardened_clay 6  
fill ~33 ~1 ~1 ~34 ~1 ~1 concrete 6  
fill ~33 ~1 ~2 ~34 ~1 ~2 concrete 6  
fill ~33 ~1 ~3 ~34 ~1 ~3 wool 6  
fill ~33 ~1 ~4 ~34 ~1 ~4 wool 6  
fill ~33 ~1 ~17 ~34 ~1 ~17 wool 6  
fill ~33 ~1 ~18 ~34 ~1 ~18 wool 6  
fill ~33 ~1 ~19 ~34 ~1 ~19 concrete 6  
fill ~33 ~1 ~20 ~34 ~1 ~20 concrete 6  
fill ~33 ~1 ~23 ~34 ~1 ~23 stained_hardened_clay 6  
fill ~33 ~1 ~24 ~34 ~1 ~24 stained_hardened_clay 6  
fill ~35 ~1 ~3 ~36 ~1 ~3 stained_hardened_clay 2  
fill ~35 ~1 ~4 ~36 ~1 ~4 stained_hardened_clay 2  
fill ~35 ~1 ~17 ~36 ~1 ~17 stained_hardened_clay 2  
fill ~35 ~1 ~18 ~36 ~1 ~18 stained_hardened_clay 2  
fill ~37 ~1 ~-1 ~38 ~1 ~-1 concrete 6  
fill ~37 ~1 ~0 ~38 ~1 ~0 concrete 6  
fill ~37 ~1 ~1 ~38 ~1 ~1 stained_hardened_clay 2  
fill ~37 ~1 ~2 ~38 ~1 ~2 stained_hardened_clay 2  
fill ~37 ~1 ~3 ~38 ~1 ~3 wool 6  
fill ~37 ~1 ~4 ~38 ~1 ~4 wool 6  
fill ~37 ~1 ~17 ~38 ~1 ~17 wool 6  
fill ~37 ~1 ~18 ~38 ~1 ~18 wool 6  
fill ~37 ~1 ~19 ~38 ~1 ~19 stained_hardened_clay 2  
fill ~37 ~1 ~20 ~38 ~1 ~20 stained_hardened_clay 2  
fill ~37 ~1 ~21 ~38 ~1 ~21 concrete 6  
fill ~37 ~1 ~22 ~38 ~1 ~22 concrete 6  
fill ~39 ~1 ~3 ~46 ~1 ~3 stained_hardened_clay 2  
fill ~39 ~1 ~4 ~46 ~1 ~4 stained_hardened_clay 2  
fill ~39 ~1 ~17 ~46 ~1 ~17 stained_hardened_clay 2  
fill ~39 ~1 ~18 ~46 ~1 ~18 stained_hardened_clay 2  
fill ~45 ~1 ~5 ~46 ~1 ~5 concrete 6  
fill ~45 ~1 ~6 ~46 ~1 ~6 concrete 6  
fill ~45 ~1 ~15 ~46 ~1 ~15 concrete 6  
fill ~45 ~1 ~16 ~46 ~1 ~16 concrete 6  
fill ~-5 ~2 ~11 ~-4 ~2 ~11 stained_hardened_clay 6  
fill ~-5 ~2 ~12 ~-4 ~2 ~12 stained_hardened_clay 6  
fill ~-3 ~2 ~11 ~-2 ~2 ~11 concrete 6  
fill ~-3 ~2 ~12 ~-2 ~2 ~12 concrete 6  
fill ~-1 ~2 ~11 ~0 ~2 ~11 wool 6  
fill ~-1 ~2 ~12 ~0 ~2 ~12 wool 6  
fill ~1 ~2 ~11 ~2 ~2 ~11 concrete 6  
fill ~1 ~2 ~12 ~2 ~2 ~12 concrete 6  
fill ~3 ~2 ~11 ~4 ~2 ~11 concrete_powder 6  
fill ~3 ~2 ~12 ~4 ~2 ~12 concrete_powder 6  
fill ~5 ~2 ~11 ~6 ~2 ~11 stained_hardened_clay 2  
fill ~5 ~2 ~12 ~6 ~2 ~12 stained_hardened_clay 2  
fill ~7 ~2 ~11 ~8 ~2 ~11 concrete_powder 6  
fill ~7 ~2 ~12 ~8 ~2 ~12 concrete_powder 6  
fill ~9 ~2 ~11 ~10 ~2 ~11 stained_hardened_clay 2  
fill ~9 ~2 ~12 ~10 ~2 ~12 stained_hardened_clay 2  
fill ~11 ~2 ~11 ~12 ~2 ~11 concrete_powder 6  
fill ~11 ~2 ~12 ~12 ~2 ~12 concrete_powder 6  
fill ~13 ~2 ~11 ~14 ~2 ~11 stained_hardened_clay 2  
fill ~13 ~2 ~12 ~14 ~2 ~12 stained_hardened_clay 2  
fill ~15 ~2 ~11 ~16 ~2 ~11 concrete_powder 6  
fill ~15 ~2 ~12 ~16 ~2 ~12 concrete_powder 6  
fill ~17 ~2 ~11 ~18 ~2 ~11 stained_hardened_clay 2  
fill ~17 ~2 ~12 ~18 ~2 ~12 stained_hardened_clay 2  
fill ~19 ~2 ~3 ~20 ~2 ~3 wool 6  
fill ~19 ~2 ~4 ~19 ~7 ~4 wool 6  
fill ~19 ~2 ~5 ~19 ~7 ~5 wool 6  
fill ~19 ~2 ~6 ~19 ~7 ~6 wool 6  
fill ~19 ~2 ~7 ~19 ~7 ~7 wool 6  
fill ~19 ~2 ~8 ~19 ~7 ~8 wool 6  
fill ~19 ~2 ~9 ~19 ~7 ~9 wool 6  
fill ~19 ~2 ~10 ~19 ~7 ~10 wool 6  
fill ~19 ~2 ~11 ~19 ~7 ~11 wool 6  
fill ~19 ~2 ~12 ~19 ~7 ~12 wool 6  
fill ~19 ~2 ~13 ~19 ~7 ~13 wool 6  
fill ~19 ~2 ~14 ~19 ~7 ~14 wool 6  
fill ~19 ~2 ~15 ~19 ~7 ~15 wool 6  
fill ~19 ~2 ~16 ~19 ~7 ~16 wool 6  
fill ~19 ~2 ~17 ~19 ~7 ~17 wool 6  
fill ~19 ~2 ~18 ~20 ~2 ~18 wool 6  
fill ~21 ~2 ~3 ~22 ~2 ~3 concrete 6  
fill ~21 ~2 ~18 ~22 ~2 ~18 concrete 6  
fill ~23 ~2 ~3 ~24 ~2 ~3 wool 6  
fill ~23 ~2 ~18 ~26 ~2 ~18 wool 6  
fill ~25 ~2 ~3 ~26 ~2 ~3 wooden_door 1  
fill ~27 ~2 ~3 ~28 ~2 ~3 concrete 6  
fill ~27 ~2 ~18 ~28 ~2 ~18 concrete 6  
fill ~29 ~2 ~3 ~30 ~2 ~3 wool 6  
fill ~29 ~2 ~18 ~30 ~2 ~18 wool 6  
fill ~31 ~2 ~3 ~32 ~2 ~3 concrete 6  
fill ~31 ~2 ~18 ~32 ~2 ~18 concrete 6  
fill ~33 ~2 ~3 ~36 ~2 ~3 wool 6  
fill ~33 ~2 ~18 ~36 ~2 ~18 wool 6  
fill ~35 ~2 ~-3 ~36 ~2 ~-3 concrete 6  
fill ~35 ~2 ~-2 ~36 ~2 ~-2 concrete 6  
fill ~35 ~2 ~23 ~36 ~2 ~23 concrete 6  
fill ~35 ~2 ~24 ~36 ~2 ~24 concrete 6  
fill ~37 ~2 ~-1 ~38 ~2 ~-1 stained_hardened_clay 2  
fill ~37 ~2 ~0 ~38 ~2 ~0 stained_hardened_clay 2  
fill ~37 ~2 ~3 ~38 ~2 ~3 concrete 6  
fill ~37 ~2 ~18 ~38 ~2 ~18 concrete 6  
fill ~37 ~2 ~21 ~38 ~2 ~21 stained_hardened_clay 2  
fill ~37 ~2 ~22 ~38 ~2 ~22 stained_hardened_clay 2  
fill ~39 ~2 ~3 ~42 ~2 ~3 wool 6  
fill ~39 ~2 ~18 ~42 ~2 ~18 wool 6  
fill ~43 ~2 ~3 ~46 ~2 ~3 concrete 6  
fill ~43 ~2 ~18 ~46 ~2 ~18 concrete 6  
fill ~46 ~2 ~4 ~46 ~3 ~4 concrete 6  
fill ~46 ~2 ~5 ~46 ~9 ~5 wool 6  
fill ~46 ~2 ~6 ~46 ~9 ~6 wool 6  
fill ~46 ~2 ~7 ~46 ~9 ~7 wool 6  
fill ~46 ~2 ~8 ~46 ~9 ~8 wool 6  
fill ~46 ~2 ~9 ~46 ~3 ~9 wool 6  
fill ~46 ~2 ~10 ~46 ~3 ~10 wool 6  
fill ~46 ~2 ~11 ~46 ~3 ~11 wool 6  
fill ~46 ~2 ~12 ~46 ~3 ~12 wool 6  
fill ~46 ~2 ~13 ~46 ~9 ~13 wool 6  
fill ~46 ~2 ~14 ~46 ~9 ~14 wool 6  
fill ~46 ~2 ~15 ~46 ~9 ~15 wool 6  
fill ~46 ~2 ~16 ~46 ~9 ~16 wool 6  
fill ~46 ~2 ~17 ~46 ~3 ~17 concrete 6  
fill ~-5 ~3 ~11 ~-4 ~3 ~11 stained_hardened_clay 6  
fill ~-5 ~3 ~12 ~-4 ~3 ~12 stained_hardened_clay 6  
fill ~-3 ~3 ~11 ~-2 ~3 ~11 concrete 6  
fill ~-3 ~3 ~12 ~-2 ~3 ~12 concrete 6  
fill ~-1 ~3 ~11 ~0 ~3 ~11 wool 6  
fill ~-1 ~3 ~12 ~0 ~3 ~12 wool 6  
fill ~1 ~3 ~11 ~2 ~3 ~11 concrete 6  
fill ~1 ~3 ~12 ~2 ~3 ~12 concrete 6  
fill ~3 ~3 ~11 ~4 ~3 ~11 concrete_powder 6  
fill ~3 ~3 ~12 ~4 ~3 ~12 concrete_powder 6  
fill ~5 ~3 ~11 ~6 ~3 ~11 stained_hardened_clay 2  
fill ~5 ~3 ~12 ~6 ~3 ~12 stained_hardened_clay 2  
fill ~7 ~3 ~11 ~8 ~3 ~11 concrete_powder 6  
fill ~7 ~3 ~12 ~8 ~3 ~12 concrete_powder 6  
fill ~9 ~3 ~11 ~10 ~3 ~11 stained_hardened_clay 2  
fill ~9 ~3 ~12 ~10 ~3 ~12 stained_hardened_clay 2  
fill ~11 ~3 ~11 ~12 ~3 ~11 concrete_powder 6  
fill ~11 ~3 ~12 ~12 ~3 ~12 concrete_powder 6  
fill ~13 ~3 ~11 ~14 ~3 ~11 stained_hardened_clay 2  
fill ~13 ~3 ~12 ~14 ~3 ~12 stained_hardened_clay 2  
fill ~15 ~3 ~11 ~16 ~3 ~11 concrete_powder 6  
fill ~15 ~3 ~12 ~16 ~3 ~12 concrete_powder 6  
fill ~17 ~3 ~11 ~18 ~3 ~11 stained_hardened_clay 2  
fill ~17 ~3 ~12 ~18 ~3 ~12 stained_hardened_clay 2  
fill ~19 ~3 ~3 ~20 ~3 ~3 wool 6  
fill ~19 ~3 ~18 ~20 ~3 ~18 wool 6  
fill ~21 ~3 ~3 ~22 ~3 ~3 concrete 6  
fill ~21 ~3 ~18 ~22 ~3 ~18 concrete 6  
fill ~23 ~3 ~3 ~24 ~3 ~3 wool 6  
fill ~23 ~3 ~18 ~26 ~3 ~18 wool 6  
fill ~25 ~3 ~3 ~26 ~3 ~3 wooden_door 1  
fill ~27 ~3 ~3 ~28 ~3 ~3 concrete 6  
fill ~27 ~3 ~18 ~28 ~3 ~18 concrete 6  
fill ~29 ~3 ~3 ~30 ~3 ~3 wool 6  
fill ~29 ~3 ~18 ~30 ~3 ~18 wool 6  
fill ~31 ~3 ~3 ~32 ~3 ~3 concrete 6  
fill ~31 ~3 ~18 ~32 ~3 ~18 concrete 6  
fill ~33 ~3 ~3 ~36 ~3 ~3 wool 6  
fill ~33 ~3 ~18 ~36 ~3 ~18 wool 6  
fill ~35 ~3 ~-3 ~36 ~3 ~-3 concrete 6  
fill ~35 ~3 ~-2 ~36 ~3 ~-2 concrete 6  
fill ~35 ~3 ~23 ~36 ~3 ~23 concrete 6  
fill ~35 ~3 ~24 ~36 ~3 ~24 concrete 6  
fill ~37 ~3 ~-1 ~38 ~3 ~-1 stained_hardened_clay 2  
fill ~37 ~3 ~0 ~38 ~3 ~0 stained_hardened_clay 2  
fill ~37 ~3 ~3 ~38 ~3 ~3 concrete 6  
fill ~37 ~3 ~18 ~38 ~3 ~18 concrete 6  
fill ~37 ~3 ~21 ~38 ~3 ~21 stained_hardened_clay 2  
fill ~37 ~3 ~22 ~38 ~3 ~22 stained_hardened_clay 2  
fill ~39 ~3 ~3 ~42 ~3 ~3 wool 6  
fill ~39 ~3 ~18 ~42 ~3 ~18 wool 6  
fill ~43 ~3 ~3 ~46 ~3 ~3 concrete 6  
fill ~43 ~3 ~18 ~46 ~3 ~18 concrete 6  
fill ~-5 ~4 ~11 ~-4 ~4 ~11 concrete 6  
fill ~-5 ~4 ~12 ~-4 ~4 ~12 concrete 6  
fill ~-3 ~4 ~11 ~-2 ~4 ~11 stained_hardened_clay 6  
fill ~-3 ~4 ~12 ~-2 ~4 ~12 stained_hardened_clay 6  
fill ~-1 ~4 ~11 ~2 ~4 ~11 concrete 6  
fill ~-1 ~4 ~12 ~2 ~4 ~12 concrete 6  
fill ~3 ~4 ~11 ~4 ~4 ~11 wool 6  
fill ~3 ~4 ~12 ~4 ~4 ~12 wool 6  
fill ~5 ~4 ~11 ~6 ~4 ~11 concrete 6  
fill ~5 ~4 ~12 ~6 ~4 ~12 concrete 6  
fill ~7 ~4 ~11 ~8 ~4 ~11 wool 6  
fill ~7 ~4 ~12 ~8 ~4 ~12 wool 6  
fill ~9 ~4 ~11 ~10 ~4 ~11 concrete 6  
fill ~9 ~4 ~12 ~10 ~4 ~12 concrete 6  
fill ~11 ~4 ~11 ~12 ~4 ~11 wool 6  
fill ~11 ~4 ~12 ~12 ~4 ~12 wool 6  
fill ~13 ~4 ~11 ~14 ~4 ~11 concrete 6  
fill ~13 ~4 ~12 ~14 ~4 ~12 concrete 6  
fill ~15 ~4 ~11 ~16 ~4 ~11 wool 6  
fill ~15 ~4 ~12 ~16 ~4 ~12 wool 6  
fill ~17 ~4 ~11 ~18 ~4 ~11 concrete 6  
fill ~17 ~4 ~12 ~18 ~4 ~12 concrete 6  
fill ~19 ~4 ~3 ~38 ~4 ~3 wool 6  
fill ~19 ~4 ~18 ~38 ~4 ~18 wool 6  
fill ~35 ~4 ~-3 ~36 ~4 ~-3 concrete 6  
fill ~35 ~4 ~-2 ~36 ~4 ~-2 concrete 6  
fill ~35 ~4 ~23 ~36 ~4 ~23 concrete 6  
fill ~35 ~4 ~24 ~36 ~4 ~24 concrete 6  
fill ~39 ~4 ~3 ~40 ~4 ~3 concrete_powder 6  
fill ~39 ~4 ~18 ~40 ~4 ~18 concrete_powder 6  
fill ~41 ~4 ~3 ~42 ~4 ~3 concrete 6  
fill ~41 ~4 ~18 ~42 ~4 ~18 concrete 6  
fill ~43 ~4 ~3 ~44 ~4 ~3 wool 6  
fill ~43 ~4 ~18 ~44 ~4 ~18 wool 6  
fill ~45 ~4 ~3 ~46 ~4 ~3 stained_hardened_clay 11  
fill ~45 ~4 ~18 ~46 ~4 ~18 stained_hardened_clay 11  
fill ~46 ~4 ~4 ~46 ~5 ~4 stained_hardened_clay 11  
fill ~46 ~4 ~9 ~46 ~5 ~9 stained_hardened_clay 6  
fill ~46 ~4 ~10 ~46 ~5 ~10 stained_hardened_clay 6  
fill ~46 ~4 ~11 ~46 ~5 ~11 stained_hardened_clay 6  
fill ~46 ~4 ~12 ~46 ~5 ~12 stained_hardened_clay 6  
fill ~46 ~4 ~17 ~46 ~5 ~17 stained_hardened_clay 11  
fill ~-5 ~5 ~11 ~-4 ~5 ~11 concrete 6  
fill ~-5 ~5 ~12 ~-4 ~5 ~12 concrete 6  
fill ~-3 ~5 ~11 ~-2 ~5 ~11 stained_hardened_clay 6  
fill ~-3 ~5 ~12 ~-2 ~5 ~12 stained_hardened_clay 6  
fill ~-1 ~5 ~11 ~2 ~5 ~11 concrete 6  
fill ~-1 ~5 ~12 ~2 ~5 ~12 concrete 6  
fill ~3 ~5 ~11 ~4 ~5 ~11 wool 6  
fill ~3 ~5 ~12 ~4 ~5 ~12 wool 6  
fill ~5 ~5 ~11 ~6 ~5 ~11 concrete 6  
fill ~5 ~5 ~12 ~6 ~5 ~12 concrete 6  
fill ~7 ~5 ~11 ~8 ~5 ~11 wool 6  
fill ~7 ~5 ~12 ~8 ~5 ~12 wool 6  
fill ~9 ~5 ~11 ~10 ~5 ~11 concrete 6  
fill ~9 ~5 ~12 ~10 ~5 ~12 concrete 6  
fill ~11 ~5 ~11 ~12 ~5 ~11 wool 6  
fill ~11 ~5 ~12 ~12 ~5 ~12 wool 6  
fill ~13 ~5 ~11 ~14 ~5 ~11 concrete 6  
fill ~13 ~5 ~12 ~14 ~5 ~12 concrete 6  
fill ~15 ~5 ~11 ~16 ~5 ~11 wool 6  
fill ~15 ~5 ~12 ~16 ~5 ~12 wool 6  
fill ~17 ~5 ~11 ~18 ~5 ~11 concrete 6  
fill ~17 ~5 ~12 ~18 ~5 ~12 concrete 6  
fill ~19 ~5 ~3 ~38 ~5 ~3 wool 6  
fill ~19 ~5 ~18 ~38 ~5 ~18 wool 6  
fill ~35 ~5 ~-3 ~36 ~5 ~-3 concrete 6  
fill ~35 ~5 ~-2 ~36 ~5 ~-2 concrete 6  
fill ~35 ~5 ~23 ~36 ~5 ~23 concrete 6  
fill ~35 ~5 ~24 ~36 ~5 ~24 concrete 6  
fill ~39 ~5 ~3 ~40 ~5 ~3 concrete_powder 6  
fill ~39 ~5 ~18 ~40 ~5 ~18 concrete_powder 6  
fill ~41 ~5 ~3 ~42 ~5 ~3 concrete 6  
fill ~41 ~5 ~18 ~42 ~5 ~18 concrete 6  
fill ~43 ~5 ~3 ~44 ~5 ~3 wool 6  
fill ~43 ~5 ~18 ~44 ~5 ~18 wool 6  
fill ~45 ~5 ~3 ~46 ~5 ~3 stained_hardened_clay 11  
fill ~45 ~5 ~18 ~46 ~5 ~18 stained_hardened_clay 11  
fill ~1 ~6 ~11 ~2 ~6 ~11 concrete 6  
fill ~1 ~6 ~12 ~2 ~6 ~12 concrete 6  
fill ~3 ~6 ~11 ~4 ~6 ~11 stained_hardened_clay 6  
fill ~3 ~6 ~12 ~4 ~6 ~12 stained_hardened_clay 6  
fill ~5 ~6 ~11 ~12 ~6 ~11 concrete 6  
fill ~5 ~6 ~12 ~12 ~6 ~12 concrete 6  
fill ~13 ~6 ~11 ~14 ~6 ~11 wool 6  
fill ~13 ~6 ~12 ~14 ~6 ~12 wool 6  
fill ~15 ~6 ~11 ~16 ~6 ~11 concrete_powder 6  
fill ~15 ~6 ~12 ~16 ~6 ~12 concrete_powder 6  
fill ~17 ~6 ~11 ~19 ~6 ~11 wool 6  
fill ~17 ~6 ~12 ~19 ~6 ~12 wool 6  
fill ~19 ~6 ~3 ~38 ~6 ~3 wool 6  
fill ~19 ~6 ~18 ~38 ~6 ~18 wool 6  
fill ~37 ~6 ~1 ~38 ~6 ~1 stained_hardened_clay 2  
fill ~37 ~6 ~2 ~38 ~6 ~2 stained_hardened_clay 2  
fill ~37 ~6 ~19 ~38 ~6 ~19 stained_hardened_clay 2  
fill ~37 ~6 ~20 ~38 ~6 ~20 stained_hardened_clay 2  
fill ~39 ~6 ~3 ~40 ~6 ~3 concrete_powder 6  
fill ~39 ~6 ~18 ~40 ~6 ~18 concrete_powder 6  
fill ~41 ~6 ~3 ~46 ~6 ~3 wool 6  
fill ~41 ~6 ~18 ~46 ~6 ~18 wool 6  
fill ~46 ~6 ~4 ~46 ~9 ~4 wool 6  
fill ~46 ~6 ~9 ~46 ~9 ~9 wool 6  
fill ~46 ~6 ~10 ~46 ~9 ~10 wool 6  
fill ~46 ~6 ~11 ~46 ~9 ~11 wool 6  
fill ~46 ~6 ~12 ~46 ~9 ~12 wool 6  
fill ~46 ~6 ~17 ~46 ~9 ~17 wool 6  
fill ~1 ~7 ~11 ~2 ~7 ~11 concrete 6  
fill ~1 ~7 ~12 ~2 ~7 ~12 concrete 6  
fill ~3 ~7 ~11 ~4 ~7 ~11 stained_hardened_clay 6  
fill ~3 ~7 ~12 ~4 ~7 ~12 stained_hardened_clay 6  
fill ~5 ~7 ~11 ~12 ~7 ~11 concrete 6  
fill ~5 ~7 ~12 ~12 ~7 ~12 concrete 6  
fill ~13 ~7 ~11 ~14 ~7 ~11 wool 6  
fill ~13 ~7 ~12 ~14 ~7 ~12 wool 6  
fill ~15 ~7 ~11 ~16 ~7 ~11 concrete_powder 6  
fill ~15 ~7 ~12 ~16 ~7 ~12 concrete_powder 6  
fill ~17 ~7 ~11 ~34 ~7 ~11 wool 6  
fill ~17 ~7 ~12 ~34 ~7 ~12 wool 6  
fill ~19 ~7 ~3 ~38 ~7 ~3 wool 6  
fill ~19 ~7 ~18 ~38 ~7 ~18 wool 6  
fill ~20 ~7 ~4 ~38 ~7 ~4 wool 6  
fill ~20 ~7 ~5 ~46 ~7 ~5 wool 6  
fill ~20 ~7 ~6 ~46 ~7 ~6 wool 6  
fill ~20 ~7 ~7 ~46 ~7 ~7 wool 6  
fill ~20 ~7 ~8 ~46 ~7 ~8 wool 6  
fill ~20 ~7 ~9 ~20 ~7 ~18 wool 6  
fill ~21 ~7 ~9 ~22 ~7 ~9 concrete 6  
fill ~21 ~7 ~10 ~22 ~7 ~10 concrete 6  
fill ~21 ~7 ~13 ~46 ~7 ~13 wool 6  
fill ~21 ~7 ~14 ~46 ~7 ~14 wool 6  
fill ~21 ~7 ~15 ~46 ~7 ~15 wool 6  
fill ~21 ~7 ~16 ~46 ~7 ~16 wool 6  
fill ~21 ~7 ~17 ~38 ~7 ~17 wool 6  
fill ~23 ~7 ~9 ~26 ~7 ~9 concrete_powder 6  
fill ~23 ~7 ~10 ~26 ~7 ~10 concrete_powder 6  
fill ~27 ~7 ~9 ~28 ~7 ~9 concrete 6  
fill ~27 ~7 ~10 ~28 ~7 ~10 concrete 6  
fill ~29 ~7 ~9 ~30 ~7 ~9 wool 6  
fill ~29 ~7 ~10 ~30 ~7 ~10 wool 6  
fill ~31 ~7 ~9 ~32 ~7 ~9 concrete_powder 6  
fill ~31 ~7 ~10 ~32 ~7 ~10 concrete_powder 6  
fill ~33 ~7 ~9 ~36 ~7 ~9 concrete 6  
fill ~33 ~7 ~10 ~36 ~7 ~10 concrete 6  
fill ~35 ~7 ~11 ~36 ~7 ~11 concrete 6  
fill ~35 ~7 ~12 ~36 ~7 ~12 concrete 6  
fill ~37 ~7 ~1 ~38 ~7 ~1 stained_hardened_clay 2  
fill ~37 ~7 ~2 ~38 ~7 ~2 stained_hardened_clay 2  
fill ~37 ~7 ~9 ~46 ~7 ~9 wool 6  
fill ~37 ~7 ~10 ~46 ~7 ~10 wool 6  
fill ~37 ~7 ~11 ~46 ~7 ~11 wool 6  
fill ~37 ~7 ~12 ~46 ~7 ~12 wool 6  
fill ~37 ~7 ~19 ~38 ~7 ~19 stained_hardened_clay 2  
fill ~37 ~7 ~20 ~38 ~7 ~20 stained_hardened_clay 2  
fill ~39 ~7 ~3 ~40 ~7 ~3 concrete_powder 6  
fill ~39 ~7 ~4 ~40 ~7 ~4 concrete_powder 6  
fill ~39 ~7 ~17 ~40 ~7 ~17 concrete_powder 6  
fill ~39 ~7 ~18 ~40 ~7 ~18 concrete_powder 6  
fill ~41 ~7 ~3 ~46 ~7 ~3 wool 6  
fill ~41 ~7 ~4 ~46 ~7 ~4 wool 6  
fill ~41 ~7 ~17 ~46 ~7 ~17 wool 6  
fill ~41 ~7 ~18 ~46 ~7 ~18 wool 6  
fill ~7 ~8 ~11 ~10 ~8 ~11 concrete 6  
fill ~7 ~8 ~12 ~10 ~8 ~12 concrete 6  
fill ~11 ~8 ~11 ~24 ~8 ~11 stained_hardened_clay 6  
fill ~11 ~8 ~12 ~24 ~8 ~12 stained_hardened_clay 6  
fill ~25 ~8 ~11 ~28 ~8 ~11 concrete 6  
fill ~25 ~8 ~12 ~28 ~8 ~12 concrete 6  
fill ~29 ~8 ~11 ~34 ~8 ~11 stained_hardened_clay 6  
fill ~29 ~8 ~12 ~34 ~8 ~12 stained_hardened_clay 6  
fill ~37 ~8 ~-1 ~38 ~8 ~-1 concrete 6  
fill ~37 ~8 ~0 ~38 ~8 ~0 concrete 6  
fill ~37 ~8 ~1 ~38 ~8 ~1 stained_hardened_clay 2  
fill ~37 ~8 ~2 ~38 ~8 ~2 stained_hardened_clay 2  
fill ~37 ~8 ~3 ~42 ~8 ~3 concrete_powder 6  
fill ~37 ~8 ~4 ~42 ~8 ~4 concrete_powder 6  
fill ~37 ~8 ~5 ~40 ~8 ~5 concrete_powder 6  
fill ~37 ~8 ~6 ~40 ~8 ~6 concrete_powder 6  
fill ~37 ~8 ~7 ~38 ~8 ~7 concrete 6  
fill ~37 ~8 ~8 ~38 ~8 ~8 concrete 6  
fill ~37 ~8 ~9 ~38 ~8 ~9 concrete_powder 6  
fill ~37 ~8 ~10 ~38 ~8 ~10 concrete_powder 6  
fill ~37 ~8 ~11 ~38 ~8 ~11 concrete_powder 6  
fill ~37 ~8 ~12 ~38 ~8 ~12 concrete_powder 6  
fill ~37 ~8 ~13 ~38 ~8 ~13 concrete 6  
fill ~37 ~8 ~14 ~38 ~8 ~14 concrete 6  
fill ~37 ~8 ~15 ~40 ~8 ~15 concrete_powder 6  
fill ~37 ~8 ~16 ~40 ~8 ~16 concrete_powder 6  
fill ~37 ~8 ~17 ~42 ~8 ~17 concrete_powder 6  
fill ~37 ~8 ~18 ~42 ~8 ~18 concrete_powder 6  
fill ~37 ~8 ~19 ~38 ~8 ~19 stained_hardened_clay 2  
fill ~37 ~8 ~20 ~38 ~8 ~20 stained_hardened_clay 2  
fill ~37 ~8 ~21 ~38 ~8 ~21 concrete 6  
fill ~37 ~8 ~22 ~38 ~8 ~22 concrete 6  
fill ~39 ~8 ~7 ~46 ~8 ~7 wool 6  
fill ~39 ~8 ~8 ~46 ~8 ~8 wool 6  
fill ~39 ~8 ~9 ~46 ~8 ~9 wool 6  
fill ~39 ~8 ~10 ~46 ~8 ~10 wool 6  
fill ~39 ~8 ~11 ~46 ~8 ~11 wool 6  
fill ~39 ~8 ~12 ~46 ~8 ~12 wool 6  
fill ~39 ~8 ~13 ~46 ~8 ~13 wool 6  
fill ~39 ~8 ~14 ~46 ~8 ~14 wool 6  
fill ~41 ~8 ~5 ~46 ~8 ~5 wool 6  
fill ~41 ~8 ~6 ~46 ~8 ~6 wool 6  
fill ~41 ~8 ~15 ~46 ~8 ~15 wool 6  
fill ~41 ~8 ~16 ~46 ~8 ~16 wool 6  
fill ~43 ~8 ~3 ~46 ~8 ~3 wool 6  
fill ~43 ~8 ~4 ~46 ~8 ~4 wool 6  
fill ~43 ~8 ~17 ~46 ~8 ~17 wool 6  
fill ~43 ~8 ~18 ~46 ~8 ~18 wool 6  
fill ~7 ~9 ~11 ~10 ~9 ~11 concrete 6  
fill ~7 ~9 ~12 ~10 ~9 ~12 concrete 6  
fill ~11 ~9 ~11 ~24 ~9 ~11 stained_hardened_clay 6  
fill ~11 ~9 ~12 ~24 ~9 ~12 stained_hardened_clay 6  
fill ~25 ~9 ~11 ~28 ~9 ~11 concrete 6  
fill ~25 ~9 ~12 ~28 ~9 ~12 concrete 6  
fill ~29 ~9 ~11 ~34 ~9 ~11 stained_hardened_clay 6  
fill ~29 ~9 ~12 ~34 ~9 ~12 stained_hardened_clay 6  
fill ~37 ~9 ~-1 ~38 ~9 ~-1 concrete 6  
fill ~37 ~9 ~0 ~38 ~9 ~0 concrete 6  
fill ~37 ~9 ~1 ~38 ~9 ~1 stained_hardened_clay 2  
fill ~37 ~9 ~2 ~38 ~9 ~2 stained_hardened_clay 2  
fill ~37 ~9 ~3 ~42 ~9 ~3 concrete_powder 6  
fill ~37 ~9 ~4 ~42 ~9 ~4 concrete_powder 6  
fill ~37 ~9 ~5 ~40 ~9 ~5 concrete_powder 6  
fill ~37 ~9 ~6 ~40 ~9 ~6 concrete_powder 6  
fill ~37 ~9 ~7 ~38 ~9 ~7 concrete 6  
fill ~37 ~9 ~8 ~38 ~9 ~8 concrete 6  
fill ~37 ~9 ~9 ~38 ~9 ~9 concrete_powder 6  
fill ~37 ~9 ~10 ~38 ~9 ~10 concrete_powder 6  
fill ~37 ~9 ~11 ~38 ~9 ~11 concrete_powder 6  
fill ~37 ~9 ~12 ~38 ~9 ~12 concrete_powder 6  
fill ~37 ~9 ~13 ~38 ~9 ~13 concrete 6  
fill ~37 ~9 ~14 ~38 ~9 ~14 concrete 6  
fill ~37 ~9 ~15 ~40 ~9 ~15 concrete_powder 6  
fill ~37 ~9 ~16 ~40 ~9 ~16 concrete_powder 6  
fill ~37 ~9 ~17 ~42 ~9 ~17 concrete_powder 6  
fill ~37 ~9 ~18 ~42 ~9 ~18 concrete_powder 6  
fill ~37 ~9 ~19 ~38 ~9 ~19 stained_hardened_clay 2  
fill ~37 ~9 ~20 ~38 ~9 ~20 stained_hardened_clay 2  
fill ~37 ~9 ~21 ~38 ~9 ~21 concrete 6  
fill ~37 ~9 ~22 ~38 ~9 ~22 concrete 6  
fill ~39 ~9 ~7 ~46 ~9 ~7 wool 6  
fill ~39 ~9 ~8 ~46 ~9 ~8 wool 6  
fill ~39 ~9 ~9 ~46 ~9 ~9 wool 6  
fill ~39 ~9 ~10 ~46 ~9 ~10 wool 6  
fill ~39 ~9 ~11 ~46 ~9 ~11 wool 6  
fill ~39 ~9 ~12 ~46 ~9 ~12 wool 6  
fill ~39 ~9 ~13 ~46 ~9 ~13 wool 6  
fill ~39 ~9 ~14 ~46 ~9 ~14 wool 6  
fill ~41 ~9 ~5 ~46 ~9 ~5 wool 6  
fill ~41 ~9 ~6 ~46 ~9 ~6 wool 6  
fill ~41 ~9 ~15 ~46 ~9 ~15 wool 6  
fill ~41 ~9 ~16 ~46 ~9 ~16 wool 6  
fill ~43 ~9 ~3 ~46 ~9 ~3 wool 6  
fill ~43 ~9 ~4 ~46 ~9 ~4 wool 6  
fill ~43 ~9 ~17 ~46 ~9 ~17 wool 6  
fill ~43 ~9 ~18 ~46 ~9 ~18 wool 6  
fill ~35 ~10 ~-3 ~36 ~10 ~-3 concrete 6  
fill ~35 ~10 ~-2 ~36 ~10 ~-2 concrete 6  
fill ~35 ~10 ~-1 ~36 ~10 ~-1 stained_hardened_clay 2  
fill ~35 ~10 ~0 ~36 ~10 ~0 stained_hardened_clay 2  
fill ~35 ~10 ~21 ~36 ~10 ~21 stained_hardened_clay 2  
fill ~35 ~10 ~22 ~36 ~10 ~22 stained_hardened_clay 2  
fill ~35 ~10 ~23 ~36 ~10 ~23 concrete 6  
fill ~35 ~10 ~24 ~36 ~10 ~24 concrete 6  
fill ~37 ~10 ~5 ~38 ~10 ~5 concrete 6  
fill ~37 ~10 ~6 ~38 ~10 ~6 concrete 6  
fill ~37 ~10 ~7 ~38 ~10 ~7 stained_hardened_clay 2  
fill ~37 ~10 ~8 ~38 ~10 ~8 stained_hardened_clay 2  
fill ~37 ~10 ~13 ~38 ~10 ~13 stained_hardened_clay 2  
fill ~37 ~10 ~14 ~38 ~10 ~14 stained_hardened_clay 2  
fill ~37 ~10 ~15 ~38 ~10 ~15 concrete 6  
fill ~37 ~10 ~16 ~38 ~10 ~16 concrete 6  
fill ~35 ~11 ~-3 ~36 ~11 ~-3 concrete 6  
fill ~35 ~11 ~-2 ~36 ~11 ~-2 concrete 6  
fill ~35 ~11 ~-1 ~36 ~11 ~-1 stained_hardened_clay 2  
fill ~35 ~11 ~0 ~36 ~11 ~0 stained_hardened_clay 2  
fill ~35 ~11 ~21 ~36 ~11 ~21 stained_hardened_clay 2  
fill ~35 ~11 ~22 ~36 ~11 ~22 stained_hardened_clay 2  
fill ~35 ~11 ~23 ~36 ~11 ~23 concrete 6  
fill ~35 ~11 ~24 ~36 ~11 ~24 concrete 6  
fill ~37 ~11 ~5 ~38 ~11 ~5 concrete 6  
fill ~37 ~11 ~6 ~38 ~11 ~6 concrete 6  
fill ~37 ~11 ~7 ~38 ~11 ~7 stained_hardened_clay 2  
fill ~37 ~11 ~8 ~38 ~11 ~8 stained_hardened_clay 2  
fill ~37 ~11 ~13 ~38 ~11 ~13 stained_hardened_clay 2  
fill ~37 ~11 ~14 ~38 ~11 ~14 stained_hardened_clay 2  
fill ~37 ~11 ~15 ~38 ~11 ~15 concrete 6  
fill ~37 ~11 ~16 ~38 ~11 ~16 concrete 6  
fill ~35 ~12 ~-3 ~36 ~12 ~-3 concrete 6  
fill ~35 ~12 ~-2 ~36 ~12 ~-2 concrete 6  
fill ~35 ~12 ~3 ~36 ~12 ~3 concrete 6  
fill ~35 ~12 ~4 ~36 ~12 ~4 concrete 6  
fill ~35 ~12 ~17 ~36 ~12 ~17 concrete 6  
fill ~35 ~12 ~18 ~36 ~12 ~18 concrete 6  
fill ~35 ~12 ~23 ~36 ~12 ~23 concrete 6  
fill ~35 ~12 ~24 ~36 ~12 ~24 concrete 6  
fill ~37 ~12 ~5 ~38 ~12 ~5 stained_hardened_clay 2  
fill ~37 ~12 ~6 ~38 ~12 ~6 stained_hardened_clay 2  
fill ~37 ~12 ~15 ~38 ~12 ~15 stained_hardened_clay 2  
fill ~37 ~12 ~16 ~38 ~12 ~16 stained_hardened_clay 2  
fill ~35 ~13 ~-3 ~36 ~13 ~-3 concrete 6  
fill ~35 ~13 ~-2 ~36 ~13 ~-2 concrete 6  
fill ~35 ~13 ~3 ~36 ~13 ~3 concrete 6  
fill ~35 ~13 ~4 ~36 ~13 ~4 concrete 6  
fill ~35 ~13 ~17 ~36 ~13 ~17 concrete 6  
fill ~35 ~13 ~18 ~36 ~13 ~18 concrete 6  
fill ~35 ~13 ~23 ~36 ~13 ~23 concrete 6  
fill ~35 ~13 ~24 ~36 ~13 ~24 concrete 6  
fill ~37 ~13 ~5 ~38 ~13 ~5 stained_hardened_clay 2  
fill ~37 ~13 ~6 ~38 ~13 ~6 stained_hardened_clay 2  
fill ~37 ~13 ~15 ~38 ~13 ~15 stained_hardened_clay 2  
fill ~37 ~13 ~16 ~38 ~13 ~16 stained_hardened_clay 2  
fill ~35 ~14 ~3 ~36 ~14 ~3 concrete 6  
fill ~35 ~14 ~4 ~36 ~14 ~4 concrete 6  
fill ~35 ~14 ~17 ~36 ~14 ~17 concrete 6  
fill ~35 ~14 ~18 ~36 ~14 ~18 concrete 6  
fill ~35 ~15 ~3 ~36 ~15 ~3 concrete 6  
fill ~35 ~15 ~4 ~36 ~15 ~4 concrete 6  
fill ~35 ~15 ~17 ~36 ~15 ~17 concrete 6  
fill ~35 ~15 ~18 ~36 ~15 ~18 concrete 6    