setblock ~42 ~0 ~38 glass 0  
fill ~41 ~1 ~37 ~43 ~1 ~37 glass 0  
fill ~41 ~1 ~38 ~41 ~1 ~37 glass 0 
setblock ~41 ~1 ~39 dispenser 3 
setblock ~42 ~1 ~38 oak_stairs 3 
setblock ~42 ~1 ~39 wool 13 
setblock ~43 ~1 ~38 glass 0 
setblock ~43 ~1 ~39 dispenser 3  
fill ~40 ~2 ~37 ~40 ~2 ~39 glass 0  
fill ~41 ~2 ~13 ~43 ~2 ~13 wool 13  
fill ~41 ~2 ~14 ~43 ~2 ~14 wool 13  
fill ~41 ~2 ~15 ~43 ~2 ~15 wool 13  
fill ~41 ~2 ~16 ~43 ~2 ~16 wool 13  
fill ~41 ~2 ~17 ~43 ~2 ~17 wool 13  
fill ~41 ~2 ~18 ~43 ~2 ~18 wool 13  
fill ~41 ~2 ~19 ~43 ~2 ~19 wool 13  
fill ~41 ~2 ~20 ~43 ~2 ~20 wool 13  
fill ~41 ~2 ~21 ~43 ~2 ~21 wool 13  
fill ~41 ~2 ~22 ~43 ~2 ~22 wool 13  
fill ~41 ~2 ~23 ~43 ~2 ~23 wool 13  
fill ~41 ~2 ~24 ~43 ~2 ~24 wool 13  
fill ~41 ~2 ~25 ~43 ~2 ~25 wool 13  
fill ~41 ~2 ~31 ~43 ~2 ~31 wool 13  
fill ~41 ~2 ~32 ~43 ~2 ~32 wool 13  
fill ~41 ~2 ~33 ~43 ~2 ~33 wool 13  
fill ~41 ~2 ~36 ~43 ~2 ~36 glass 0  
fill ~41 ~2 ~40 ~43 ~2 ~40 glass 0  
fill ~41 ~2 ~44 ~43 ~2 ~44 wool 13  
fill ~41 ~2 ~45 ~43 ~2 ~45 wool 13  
fill ~41 ~2 ~46 ~43 ~2 ~46 wool 13  
fill ~41 ~2 ~47 ~43 ~2 ~47 wool 13  
fill ~41 ~2 ~48 ~43 ~2 ~48 wool 13  
fill ~41 ~2 ~49 ~43 ~2 ~49 wool 13  
fill ~41 ~2 ~50 ~43 ~2 ~50 wool 13  
fill ~41 ~2 ~51 ~43 ~2 ~51 wool 13  
fill ~41 ~2 ~52 ~43 ~2 ~52 wool 13  
fill ~41 ~2 ~53 ~43 ~2 ~53 wool 13  
fill ~41 ~2 ~54 ~43 ~2 ~54 wool 13  
fill ~41 ~2 ~55 ~43 ~2 ~55 wool 13  
fill ~41 ~2 ~56 ~43 ~2 ~56 wool 13  
fill ~41 ~2 ~57 ~43 ~2 ~57 wool 13  
fill ~41 ~2 ~58 ~43 ~2 ~58 wool 13  
fill ~41 ~2 ~59 ~43 ~2 ~59 wool 13  
fill ~42 ~2 ~12 ~42 ~3 ~12 wool 13  
fill ~42 ~2 ~26 ~42 ~3 ~26 wool 13  
fill ~42 ~2 ~27 ~42 ~3 ~27 wool 13  
fill ~42 ~2 ~28 ~42 ~3 ~28 wool 13  
fill ~42 ~2 ~29 ~42 ~3 ~29 wool 13  
fill ~42 ~2 ~30 ~42 ~3 ~30 wool 13  
fill ~42 ~2 ~34 ~42 ~3 ~34 wool 13 
setblock ~42 ~2 ~39 lever 5  
fill ~42 ~2 ~43 ~42 ~3 ~43 wool 13  
fill ~42 ~2 ~60 ~42 ~3 ~60 wool 13  
fill ~44 ~2 ~37 ~44 ~2 ~39 glass 0  
fill ~40 ~3 ~12 ~44 ~3 ~12 wool 13  
fill ~40 ~3 ~13 ~44 ~3 ~13 wool 13  
fill ~40 ~3 ~14 ~44 ~3 ~14 wool 13  
fill ~40 ~3 ~15 ~44 ~3 ~15 wool 13  
fill ~40 ~3 ~16 ~44 ~3 ~16 wool 13  
fill ~40 ~3 ~17 ~44 ~3 ~17 wool 13  
fill ~40 ~3 ~18 ~44 ~3 ~18 wool 13  
fill ~40 ~3 ~19 ~44 ~3 ~19 wool 13  
fill ~40 ~3 ~20 ~44 ~3 ~20 wool 13  
fill ~40 ~3 ~21 ~44 ~3 ~21 wool 13  
fill ~40 ~3 ~22 ~44 ~3 ~22 wool 13  
fill ~40 ~3 ~23 ~44 ~3 ~23 wool 13  
fill ~40 ~3 ~24 ~44 ~3 ~24 wool 13  
fill ~40 ~3 ~25 ~44 ~3 ~25 wool 13  
fill ~40 ~3 ~26 ~40 ~3 ~61 wool 13  
fill ~40 ~3 ~62 ~44 ~3 ~62 double_stone_slab 0  
fill ~41 ~3 ~11 ~43 ~3 ~11 wool 13  
fill ~41 ~3 ~31 ~44 ~3 ~31 wool 13  
fill ~41 ~3 ~32 ~44 ~3 ~32 wool 13  
fill ~41 ~3 ~33 ~44 ~3 ~33 wool 13  
fill ~41 ~3 ~34 ~41 ~3 ~36 wool 13  
fill ~41 ~3 ~40 ~44 ~3 ~40 wool 13  
fill ~41 ~3 ~41 ~44 ~3 ~41 wool 13  
fill ~41 ~3 ~42 ~44 ~3 ~42 wool 13  
fill ~41 ~3 ~43 ~41 ~3 ~61 wool 13  
fill ~42 ~3 ~10 ~42 ~4 ~10 wool 13  
fill ~42 ~3 ~35 ~44 ~3 ~35 wool 13  
fill ~42 ~3 ~36 ~44 ~3 ~36 wool 13  
fill ~42 ~3 ~37 ~42 ~6 ~37 ladder 3  
fill ~42 ~3 ~44 ~44 ~3 ~44 wool 13  
fill ~42 ~3 ~45 ~44 ~3 ~45 wool 13  
fill ~42 ~3 ~46 ~44 ~3 ~46 wool 13  
fill ~42 ~3 ~47 ~44 ~3 ~47 wool 13  
fill ~42 ~3 ~48 ~44 ~3 ~48 wool 13  
fill ~42 ~3 ~49 ~44 ~3 ~49 wool 13  
fill ~42 ~3 ~50 ~44 ~3 ~50 wool 13  
fill ~42 ~3 ~51 ~44 ~3 ~51 wool 13  
fill ~42 ~3 ~52 ~44 ~3 ~52 wool 13  
fill ~42 ~3 ~53 ~44 ~3 ~53 wool 13  
fill ~42 ~3 ~54 ~44 ~3 ~54 wool 13  
fill ~42 ~3 ~55 ~44 ~3 ~55 wool 13  
fill ~42 ~3 ~56 ~44 ~3 ~56 wool 13  
fill ~42 ~3 ~57 ~44 ~3 ~57 wool 13  
fill ~42 ~3 ~58 ~44 ~3 ~58 wool 13  
fill ~42 ~3 ~59 ~44 ~3 ~59 wool 13  
fill ~42 ~3 ~61 ~44 ~3 ~61 wool 13  
fill ~43 ~3 ~34 ~44 ~3 ~34 wool 13  
fill ~43 ~3 ~43 ~44 ~3 ~43 wool 13  
fill ~43 ~3 ~60 ~44 ~3 ~60 wool 13  
fill ~44 ~3 ~26 ~44 ~3 ~61 wool 13  
fill ~39 ~4 ~11 ~40 ~4 ~11 wool 13  
fill ~39 ~4 ~12 ~39 ~4 ~61 wool 13 
setblock ~39 ~4 ~62 double_stone_slab 0  
fill ~40 ~4 ~9 ~44 ~4 ~9 wool 13  
fill ~40 ~4 ~10 ~44 ~4 ~10 wool 13 
setblock ~40 ~4 ~25 wool 7  
fill ~40 ~4 ~26 ~40 ~5 ~26 obsidian 0  
fill ~40 ~4 ~27 ~40 ~5 ~27 obsidian 0  
fill ~40 ~4 ~28 ~40 ~5 ~28 obsidian 0  
fill ~40 ~4 ~29 ~40 ~5 ~29 obsidian 0  
fill ~40 ~4 ~30 ~40 ~5 ~30 obsidian 0  
fill ~40 ~4 ~31 ~44 ~4 ~31 obsidian 0  
fill ~40 ~4 ~37 ~40 ~6 ~37 wool 7 
setblock ~40 ~4 ~38 glowstone 0  
fill ~40 ~4 ~39 ~40 ~6 ~39 wool 7  
fill ~40 ~4 ~40 ~44 ~4 ~40 wool 7  
fill ~40 ~4 ~62 ~44 ~4 ~62 wool 13  
fill ~40 ~4 ~63 ~44 ~4 ~63 wool 13  
fill ~40 ~4 ~64 ~44 ~4 ~64 wool 13  
fill ~40 ~4 ~65 ~44 ~4 ~65 wool 13  
fill ~40 ~4 ~66 ~44 ~4 ~66 wool 13  
fill ~40 ~4 ~67 ~44 ~4 ~67 wool 13  
fill ~40 ~4 ~68 ~44 ~4 ~68 wool 13  
fill ~40 ~4 ~69 ~44 ~4 ~69 wool 13  
fill ~40 ~4 ~70 ~44 ~4 ~70 wool 13  
fill ~41 ~4 ~8 ~43 ~4 ~8 wool 13  
fill ~41 ~4 ~24 ~41 ~4 ~25 obsidian 0  
fill ~41 ~4 ~36 ~44 ~4 ~36 wool 7 
setblock ~41 ~4 ~38 trapdoor 7  
fill ~41 ~4 ~71 ~43 ~4 ~71 wool 13  
fill ~42 ~4 ~7 ~42 ~6 ~7 wool 13 
setblock ~42 ~4 ~25 wool 7  
fill ~42 ~4 ~26 ~42 ~5 ~26 obsidian 0  
fill ~42 ~4 ~27 ~42 ~5 ~27 obsidian 0  
fill ~42 ~4 ~28 ~42 ~5 ~28 obsidian 0  
fill ~42 ~4 ~29 ~42 ~5 ~29 obsidian 0  
fill ~42 ~4 ~30 ~42 ~5 ~30 obsidian 0  
fill ~42 ~4 ~72 ~42 ~5 ~72 wool 13  
fill ~43 ~4 ~11 ~45 ~4 ~11 wool 13  
fill ~43 ~4 ~25 ~43 ~6 ~25 obsidian 0 
setblock ~43 ~4 ~38 trapdoor 6  
fill ~43 ~4 ~41 ~43 ~6 ~41 wool 7 
setblock ~44 ~4 ~25 wool 7  
fill ~44 ~4 ~26 ~44 ~5 ~26 obsidian 0  
fill ~44 ~4 ~27 ~44 ~5 ~27 obsidian 0  
fill ~44 ~4 ~28 ~44 ~5 ~28 obsidian 0  
fill ~44 ~4 ~29 ~44 ~5 ~29 obsidian 0  
fill ~44 ~4 ~30 ~44 ~5 ~30 obsidian 0  
fill ~44 ~4 ~37 ~44 ~6 ~37 wool 7 
setblock ~44 ~4 ~38 glowstone 0  
fill ~44 ~4 ~39 ~44 ~6 ~39 wool 7  
fill ~45 ~4 ~12 ~45 ~4 ~61 wool 13 
setblock ~45 ~4 ~62 double_stone_slab 0 
setblock ~19 ~5 ~22 wool 15 
setblock ~25 ~5 ~22 wool 15 
setblock ~27 ~5 ~21 wool 15 
setblock ~33 ~5 ~21 wool 15  
fill ~38 ~5 ~11 ~38 ~7 ~11 wool 13  
fill ~38 ~5 ~12 ~38 ~7 ~12 wool 13  
fill ~38 ~5 ~13 ~38 ~7 ~13 wool 13  
fill ~38 ~5 ~14 ~38 ~6 ~14 wool 13  
fill ~38 ~5 ~15 ~38 ~6 ~15 wool 13  
fill ~38 ~5 ~16 ~38 ~6 ~16 wool 13  
fill ~38 ~5 ~17 ~38 ~5 ~61 wool 13 
setblock ~38 ~5 ~62 double_stone_slab 0  
fill ~39 ~5 ~9 ~45 ~5 ~9 wool 13  
fill ~39 ~5 ~10 ~39 ~5 ~9 wool 13  
fill ~39 ~5 ~11 ~45 ~5 ~11 wool 7  
fill ~39 ~5 ~12 ~45 ~5 ~12 wool 7  
fill ~39 ~5 ~13 ~45 ~5 ~13 wool 7  
fill ~39 ~5 ~14 ~45 ~5 ~14 wool 7  
fill ~39 ~5 ~15 ~45 ~5 ~15 wool 7  
fill ~39 ~5 ~16 ~45 ~5 ~16 wool 7  
fill ~39 ~5 ~17 ~45 ~5 ~17 wool 7  
fill ~39 ~5 ~18 ~45 ~5 ~18 wool 7  
fill ~39 ~5 ~19 ~45 ~5 ~19 wool 7  
fill ~39 ~5 ~20 ~45 ~5 ~20 wool 7  
fill ~39 ~5 ~21 ~45 ~5 ~21 wool 7  
fill ~39 ~5 ~22 ~45 ~5 ~22 wool 7  
fill ~39 ~5 ~23 ~45 ~5 ~23 wool 7  
fill ~39 ~5 ~24 ~45 ~5 ~24 wool 7  
fill ~39 ~5 ~25 ~44 ~5 ~25 obsidian 0  
fill ~39 ~5 ~26 ~39 ~5 ~30 obsidian 0  
fill ~39 ~5 ~31 ~39 ~7 ~31 wool 7  
fill ~39 ~5 ~32 ~45 ~5 ~32 wool 7  
fill ~39 ~5 ~33 ~45 ~5 ~33 wool 7  
fill ~39 ~5 ~34 ~45 ~5 ~34 wool 7  
fill ~39 ~5 ~35 ~45 ~5 ~35 wool 7  
fill ~39 ~5 ~36 ~45 ~5 ~36 wool 7  
fill ~39 ~5 ~37 ~39 ~6 ~37 wool 7  
fill ~39 ~5 ~38 ~45 ~5 ~38 wool 7  
fill ~39 ~5 ~39 ~39 ~6 ~39 wool 7  
fill ~39 ~5 ~40 ~45 ~5 ~40 wool 7  
fill ~39 ~5 ~41 ~45 ~5 ~41 wool 7  
fill ~39 ~5 ~42 ~45 ~5 ~42 wool 7  
fill ~39 ~5 ~43 ~45 ~5 ~43 wool 7  
fill ~39 ~5 ~44 ~45 ~5 ~44 wool 7  
fill ~39 ~5 ~45 ~45 ~5 ~45 wool 7  
fill ~39 ~5 ~46 ~45 ~5 ~46 wool 7  
fill ~39 ~5 ~47 ~45 ~5 ~47 wool 7  
fill ~39 ~5 ~48 ~45 ~5 ~48 wool 7  
fill ~39 ~5 ~49 ~45 ~5 ~49 wool 7  
fill ~39 ~5 ~50 ~45 ~5 ~50 wool 7  
fill ~39 ~5 ~51 ~45 ~5 ~51 wool 7  
fill ~39 ~5 ~52 ~45 ~5 ~52 wool 7  
fill ~39 ~5 ~53 ~45 ~5 ~53 wool 7  
fill ~39 ~5 ~54 ~45 ~5 ~54 wool 7  
fill ~39 ~5 ~55 ~45 ~5 ~55 wool 7  
fill ~39 ~5 ~56 ~45 ~5 ~56 wool 7  
fill ~39 ~5 ~57 ~45 ~5 ~57 wool 7  
fill ~39 ~5 ~58 ~45 ~5 ~58 wool 7  
fill ~39 ~5 ~59 ~45 ~5 ~59 wool 7  
fill ~39 ~5 ~60 ~45 ~5 ~60 wool 7  
fill ~39 ~5 ~61 ~45 ~5 ~61 wool 7  
fill ~39 ~5 ~62 ~39 ~5 ~70 wool 13  
fill ~40 ~5 ~7 ~44 ~5 ~7 wool 13  
fill ~40 ~5 ~8 ~44 ~5 ~8 wool 13  
fill ~40 ~5 ~10 ~44 ~5 ~10 wool 7  
fill ~40 ~5 ~31 ~41 ~5 ~31 obsidian 0  
fill ~40 ~5 ~62 ~44 ~5 ~62 wool 7  
fill ~40 ~5 ~63 ~44 ~5 ~63 wool 7  
fill ~40 ~5 ~64 ~44 ~5 ~64 wool 7  
fill ~40 ~5 ~65 ~44 ~5 ~65 wool 7  
fill ~40 ~5 ~66 ~44 ~5 ~66 wool 7  
fill ~40 ~5 ~67 ~44 ~5 ~67 wool 7  
fill ~40 ~5 ~68 ~44 ~5 ~68 wool 7  
fill ~40 ~5 ~69 ~44 ~5 ~69 wool 7  
fill ~40 ~5 ~70 ~44 ~5 ~70 wool 7  
fill ~40 ~5 ~71 ~44 ~5 ~71 wool 13  
fill ~41 ~5 ~37 ~41 ~6 ~37 wool 7  
fill ~41 ~5 ~39 ~45 ~5 ~39 wool 7  
fill ~41 ~5 ~72 ~41 ~5 ~73 wool 13  
fill ~42 ~5 ~6 ~42 ~7 ~6 wool 13 
setblock ~42 ~5 ~31 wool 7  
fill ~42 ~5 ~73 ~43 ~5 ~73 wool 13  
fill ~42 ~5 ~74 ~42 ~10 ~74 wool 13  
fill ~43 ~5 ~31 ~44 ~5 ~31 obsidian 0  
fill ~43 ~5 ~37 ~43 ~6 ~37 wool 7 
setblock ~43 ~5 ~72 wool 13 
setblock ~45 ~5 ~10 wool 13  
fill ~45 ~5 ~25 ~45 ~5 ~27 wool 7  
fill ~45 ~5 ~28 ~46 ~5 ~28 wool 13  
fill ~45 ~5 ~29 ~45 ~5 ~61 wool 7  
fill ~45 ~5 ~62 ~45 ~5 ~70 wool 13  
fill ~46 ~5 ~11 ~46 ~7 ~11 wool 13  
fill ~46 ~5 ~12 ~46 ~7 ~12 wool 13  
fill ~46 ~5 ~13 ~46 ~7 ~13 wool 13  
fill ~46 ~5 ~14 ~46 ~6 ~14 wool 13  
fill ~46 ~5 ~15 ~46 ~6 ~15 wool 13  
fill ~46 ~5 ~16 ~46 ~6 ~16 wool 13  
fill ~46 ~5 ~17 ~46 ~5 ~61 wool 13 
setblock ~46 ~5 ~62 double_stone_slab 0 
setblock ~51 ~5 ~21 wool 15 
setblock ~57 ~5 ~21 wool 15 
setblock ~59 ~5 ~22 wool 15 
setblock ~65 ~5 ~22 wool 15 
setblock ~20 ~6 ~22 wool 15  
fill ~21 ~6 ~23 ~23 ~6 ~23 wool 7  
fill ~21 ~6 ~24 ~23 ~6 ~24 wool 13  
fill ~21 ~6 ~25 ~23 ~6 ~25 wool 13  
fill ~21 ~6 ~26 ~23 ~6 ~26 wool 13  
fill ~21 ~6 ~27 ~23 ~6 ~27 wool 13  
fill ~21 ~6 ~28 ~23 ~6 ~28 wool 13  
fill ~22 ~6 ~29 ~22 ~9 ~29 wool 13 
setblock ~24 ~6 ~22 wool 15 
setblock ~28 ~6 ~21 wool 15  
fill ~29 ~6 ~22 ~31 ~6 ~22 wool 7  
fill ~29 ~6 ~23 ~31 ~6 ~23 wool 13  
fill ~29 ~6 ~24 ~31 ~6 ~24 wool 13  
fill ~29 ~6 ~25 ~31 ~6 ~25 wool 13  
fill ~29 ~6 ~26 ~31 ~6 ~26 wool 13  
fill ~30 ~6 ~27 ~30 ~10 ~27 wool 13 
setblock ~32 ~6 ~21 wool 15  
fill ~37 ~6 ~15 ~37 ~10 ~15 wool 13  
fill ~37 ~6 ~16 ~37 ~10 ~16 wool 13  
fill ~37 ~6 ~17 ~37 ~7 ~17 wool 13  
fill ~37 ~6 ~18 ~37 ~10 ~18 wool 13  
fill ~37 ~6 ~19 ~37 ~10 ~19 wool 13  
fill ~37 ~6 ~20 ~37 ~10 ~20 wool 13  
fill ~37 ~6 ~21 ~37 ~10 ~21 wool 13  
fill ~37 ~6 ~22 ~37 ~10 ~22 wool 13  
fill ~37 ~6 ~23 ~37 ~10 ~23 wool 13  
fill ~37 ~6 ~24 ~37 ~10 ~24 wool 13  
fill ~37 ~6 ~25 ~37 ~10 ~25 wool 13  
fill ~37 ~6 ~26 ~37 ~10 ~26 wool 13  
fill ~37 ~6 ~27 ~37 ~10 ~27 wool 13  
fill ~37 ~6 ~28 ~37 ~10 ~28 wool 13  
fill ~37 ~6 ~29 ~37 ~10 ~29 wool 13  
fill ~37 ~6 ~30 ~37 ~10 ~30 wool 13  
fill ~37 ~6 ~31 ~37 ~10 ~31 wool 13  
fill ~37 ~6 ~32 ~37 ~10 ~32 wool 13  
fill ~37 ~6 ~33 ~37 ~10 ~33 wool 13  
fill ~37 ~6 ~34 ~37 ~10 ~34 wool 13  
fill ~37 ~6 ~35 ~37 ~10 ~35 wool 13  
fill ~37 ~6 ~36 ~37 ~10 ~36 wool 13  
fill ~37 ~6 ~37 ~37 ~10 ~37 wool 13  
fill ~37 ~6 ~38 ~37 ~10 ~38 wool 13  
fill ~37 ~6 ~39 ~37 ~10 ~39 wool 13  
fill ~37 ~6 ~40 ~37 ~10 ~40 wool 13  
fill ~37 ~6 ~41 ~37 ~10 ~41 wool 13  
fill ~37 ~6 ~42 ~37 ~10 ~42 wool 13  
fill ~37 ~6 ~43 ~37 ~10 ~43 wool 13  
fill ~37 ~6 ~44 ~37 ~10 ~44 wool 13  
fill ~37 ~6 ~45 ~37 ~10 ~45 wool 13  
fill ~37 ~6 ~46 ~37 ~10 ~46 wool 15  
fill ~37 ~6 ~47 ~37 ~7 ~47 wool 13  
fill ~37 ~6 ~48 ~37 ~10 ~48 wool 15  
fill ~37 ~6 ~49 ~37 ~10 ~49 wool 13  
fill ~37 ~6 ~50 ~37 ~7 ~50 wool 13  
fill ~37 ~6 ~51 ~37 ~10 ~51 wool 13  
fill ~37 ~6 ~52 ~37 ~10 ~52 wool 15  
fill ~37 ~6 ~53 ~37 ~6 ~54 wool 15  
fill ~37 ~6 ~55 ~37 ~10 ~55 wool 13  
fill ~37 ~6 ~56 ~37 ~7 ~56 wool 13  
fill ~37 ~6 ~57 ~37 ~6 ~55 wool 13 
setblock ~37 ~6 ~58 wool 11  
fill ~37 ~6 ~59 ~37 ~6 ~61 wool 13  
fill ~37 ~6 ~62 ~37 ~10 ~62 double_stone_slab 0  
fill ~37 ~6 ~63 ~38 ~6 ~63 wool 13  
fill ~37 ~6 ~64 ~38 ~6 ~64 wool 13  
fill ~38 ~6 ~9 ~39 ~6 ~9 wool 13  
fill ~38 ~6 ~10 ~38 ~10 ~10 wool 13  
fill ~38 ~6 ~17 ~46 ~6 ~17 wool 7  
fill ~38 ~6 ~18 ~46 ~6 ~18 wool 7  
fill ~38 ~6 ~19 ~46 ~6 ~19 wool 7  
fill ~38 ~6 ~20 ~46 ~6 ~20 wool 7  
fill ~38 ~6 ~21 ~46 ~6 ~21 wool 7  
fill ~38 ~6 ~22 ~38 ~10 ~22 wool 7  
fill ~38 ~6 ~23 ~38 ~10 ~23 wool 7  
fill ~38 ~6 ~24 ~38 ~10 ~24 wool 7  
fill ~38 ~6 ~25 ~38 ~6 ~61 wool 7  
fill ~38 ~6 ~62 ~38 ~10 ~62 wool 13  
fill ~38 ~6 ~65 ~38 ~10 ~65 wool 13  
fill ~38 ~6 ~66 ~38 ~10 ~66 wool 13  
fill ~38 ~6 ~67 ~38 ~10 ~67 wool 13  
fill ~38 ~6 ~68 ~39 ~6 ~68 wool 13  
fill ~39 ~6 ~7 ~45 ~6 ~7 wool 13  
fill ~39 ~6 ~8 ~39 ~10 ~8 wool 13  
fill ~39 ~6 ~10 ~45 ~6 ~10 wool 7  
fill ~39 ~6 ~11 ~45 ~6 ~11 wool 7  
fill ~39 ~6 ~12 ~45 ~6 ~12 wool 7  
fill ~39 ~6 ~13 ~45 ~6 ~13 wool 7  
fill ~39 ~6 ~14 ~45 ~6 ~14 wool 7  
fill ~39 ~6 ~15 ~45 ~6 ~15 wool 7  
fill ~39 ~6 ~16 ~45 ~6 ~16 wool 7  
fill ~39 ~6 ~22 ~41 ~6 ~22 double_stone_slab 0  
fill ~39 ~6 ~23 ~45 ~6 ~23 double_stone_slab 0  
fill ~39 ~6 ~24 ~45 ~6 ~24 redstone_wire 0  
fill ~39 ~6 ~26 ~39 ~6 ~30 piston 4  
fill ~39 ~6 ~32 ~45 ~6 ~32 double_stone_slab 0  
fill ~39 ~6 ~33 ~46 ~6 ~33 wool 7  
fill ~39 ~6 ~34 ~46 ~6 ~34 wool 7  
fill ~39 ~6 ~35 ~46 ~6 ~35 wool 7  
fill ~39 ~6 ~36 ~46 ~6 ~36 wool 7  
fill ~39 ~6 ~38 ~46 ~6 ~38 wool 7  
fill ~39 ~6 ~40 ~46 ~6 ~40 wool 7  
fill ~39 ~6 ~41 ~46 ~6 ~41 wool 7  
fill ~39 ~6 ~42 ~46 ~6 ~42 wool 7  
fill ~39 ~6 ~43 ~46 ~6 ~43 wool 7  
fill ~39 ~6 ~44 ~46 ~6 ~44 wool 7  
fill ~39 ~6 ~45 ~46 ~6 ~45 wool 7  
fill ~39 ~6 ~46 ~46 ~6 ~46 wool 7  
fill ~39 ~6 ~47 ~46 ~6 ~47 wool 7  
fill ~39 ~6 ~48 ~46 ~6 ~48 wool 7  
fill ~39 ~6 ~49 ~46 ~6 ~49 wool 7  
fill ~39 ~6 ~50 ~46 ~6 ~50 wool 7  
fill ~39 ~6 ~51 ~46 ~6 ~51 wool 7  
fill ~39 ~6 ~52 ~46 ~6 ~52 wool 7  
fill ~39 ~6 ~53 ~46 ~6 ~53 wool 7  
fill ~39 ~6 ~54 ~46 ~6 ~54 wool 7  
fill ~39 ~6 ~55 ~46 ~6 ~55 wool 7  
fill ~39 ~6 ~56 ~46 ~6 ~56 wool 7  
fill ~39 ~6 ~57 ~46 ~6 ~57 wool 7  
fill ~39 ~6 ~58 ~46 ~6 ~58 wool 7  
fill ~39 ~6 ~59 ~46 ~6 ~59 wool 7  
fill ~39 ~6 ~60 ~46 ~6 ~60 wool 7  
fill ~39 ~6 ~61 ~46 ~6 ~61 wool 7  
fill ~39 ~6 ~62 ~45 ~6 ~62 wool 7  
fill ~39 ~6 ~63 ~45 ~6 ~63 wool 7  
fill ~39 ~6 ~64 ~45 ~6 ~64 wool 7  
fill ~39 ~6 ~65 ~45 ~6 ~65 wool 7  
fill ~39 ~6 ~66 ~45 ~6 ~66 wool 7  
fill ~39 ~6 ~67 ~45 ~6 ~67 wool 7  
fill ~39 ~6 ~69 ~39 ~6 ~71 wool 13  
fill ~40 ~6 ~6 ~44 ~6 ~6 wool 13  
fill ~40 ~6 ~8 ~44 ~6 ~8 wool 7  
fill ~40 ~6 ~9 ~44 ~6 ~9 wool 7  
fill ~40 ~6 ~25 ~41 ~6 ~25 obsidian 0  
fill ~40 ~6 ~26 ~40 ~6 ~30 tnt 0  
fill ~40 ~6 ~31 ~44 ~6 ~31 obsidian 0  
fill ~40 ~6 ~68 ~44 ~6 ~68 wool 7 
setblock ~40 ~6 ~72 wool 13  
fill ~41 ~6 ~5 ~43 ~6 ~5 wool 13  
fill ~41 ~6 ~39 ~46 ~6 ~39 wool 7  
fill ~41 ~6 ~73 ~43 ~6 ~73 wool 13  
fill ~41 ~6 ~74 ~41 ~7 ~74 wool 13 
setblock ~42 ~6 ~4 wool 13  
fill ~42 ~6 ~22 ~42 ~13 ~22 wool 7  
fill ~42 ~6 ~25 ~42 ~6 ~30 wool 7 
setblock ~42 ~6 ~70 glowstone 0  
fill ~42 ~6 ~75 ~42 ~10 ~75 wool 13  
fill ~43 ~6 ~22 ~45 ~6 ~22 double_stone_slab 0  
fill ~43 ~6 ~74 ~43 ~7 ~74 wool 13  
fill ~44 ~6 ~25 ~45 ~6 ~25 obsidian 0  
fill ~44 ~6 ~26 ~44 ~6 ~30 tnt 0 
setblock ~44 ~6 ~72 wool 13  
fill ~45 ~6 ~8 ~45 ~10 ~8 wool 13  
fill ~45 ~6 ~9 ~46 ~6 ~9 wool 13  
fill ~45 ~6 ~26 ~45 ~6 ~30 piston 5  
fill ~45 ~6 ~31 ~46 ~6 ~31 wool 7  
fill ~45 ~6 ~37 ~46 ~6 ~37 wool 7  
fill ~45 ~6 ~68 ~46 ~6 ~68 wool 13  
fill ~45 ~6 ~69 ~45 ~6 ~71 wool 13  
fill ~46 ~6 ~10 ~46 ~10 ~10 wool 13  
fill ~46 ~6 ~22 ~46 ~10 ~22 wool 7  
fill ~46 ~6 ~23 ~46 ~10 ~23 wool 7  
fill ~46 ~6 ~24 ~46 ~10 ~24 wool 7  
fill ~46 ~6 ~25 ~46 ~6 ~61 wool 7  
fill ~46 ~6 ~62 ~46 ~10 ~62 wool 13  
fill ~46 ~6 ~63 ~47 ~6 ~63 wool 13  
fill ~46 ~6 ~64 ~47 ~6 ~64 wool 13  
fill ~46 ~6 ~65 ~46 ~10 ~65 wool 13  
fill ~46 ~6 ~66 ~46 ~10 ~66 wool 13  
fill ~46 ~6 ~67 ~46 ~10 ~67 wool 13  
fill ~47 ~6 ~15 ~47 ~10 ~15 wool 13  
fill ~47 ~6 ~16 ~47 ~10 ~16 wool 13  
fill ~47 ~6 ~17 ~47 ~10 ~17 wool 13  
fill ~47 ~6 ~18 ~47 ~10 ~18 wool 13  
fill ~47 ~6 ~19 ~47 ~10 ~19 wool 13  
fill ~47 ~6 ~20 ~47 ~10 ~20 wool 13  
fill ~47 ~6 ~21 ~47 ~10 ~21 wool 13  
fill ~47 ~6 ~22 ~47 ~10 ~22 wool 13  
fill ~47 ~6 ~23 ~47 ~10 ~23 wool 13  
fill ~47 ~6 ~24 ~47 ~10 ~24 wool 13  
fill ~47 ~6 ~25 ~47 ~10 ~25 wool 13  
fill ~47 ~6 ~26 ~47 ~10 ~26 wool 13  
fill ~47 ~6 ~27 ~47 ~10 ~27 wool 13  
fill ~47 ~6 ~28 ~47 ~10 ~28 wool 13  
fill ~47 ~6 ~29 ~47 ~10 ~29 wool 13  
fill ~47 ~6 ~30 ~47 ~10 ~30 wool 13  
fill ~47 ~6 ~31 ~47 ~10 ~31 wool 13  
fill ~47 ~6 ~32 ~47 ~10 ~32 wool 13  
fill ~47 ~6 ~33 ~47 ~10 ~33 wool 13  
fill ~47 ~6 ~34 ~47 ~10 ~34 wool 13  
fill ~47 ~6 ~35 ~47 ~10 ~35 wool 13  
fill ~47 ~6 ~36 ~47 ~10 ~36 wool 13  
fill ~47 ~6 ~37 ~47 ~10 ~37 wool 13  
fill ~47 ~6 ~38 ~47 ~10 ~38 wool 13  
fill ~47 ~6 ~39 ~47 ~10 ~39 wool 13  
fill ~47 ~6 ~40 ~47 ~10 ~40 wool 13  
fill ~47 ~6 ~41 ~47 ~10 ~41 wool 13  
fill ~47 ~6 ~42 ~47 ~10 ~42 wool 13  
fill ~47 ~6 ~43 ~47 ~10 ~43 wool 13  
fill ~47 ~6 ~44 ~47 ~10 ~44 wool 13  
fill ~47 ~6 ~45 ~47 ~10 ~45 wool 13  
fill ~47 ~6 ~46 ~47 ~10 ~46 wool 15  
fill ~47 ~6 ~47 ~47 ~6 ~48 wool 15  
fill ~47 ~6 ~49 ~47 ~10 ~49 wool 13  
fill ~47 ~6 ~50 ~47 ~7 ~50 wool 13  
fill ~47 ~6 ~51 ~47 ~10 ~51 wool 13  
fill ~47 ~6 ~52 ~47 ~10 ~52 wool 15  
fill ~47 ~6 ~53 ~47 ~7 ~53 wool 13  
fill ~47 ~6 ~54 ~47 ~10 ~54 wool 15  
fill ~47 ~6 ~55 ~47 ~10 ~55 wool 13  
fill ~47 ~6 ~56 ~47 ~7 ~56 wool 13  
fill ~47 ~6 ~57 ~47 ~6 ~55 wool 13 
setblock ~47 ~6 ~58 wool 11  
fill ~47 ~6 ~59 ~47 ~6 ~61 wool 13  
fill ~47 ~6 ~62 ~47 ~10 ~62 double_stone_slab 0 
setblock ~52 ~6 ~21 wool 15  
fill ~53 ~6 ~22 ~55 ~6 ~22 wool 7  
fill ~53 ~6 ~23 ~55 ~6 ~23 wool 13  
fill ~53 ~6 ~24 ~55 ~6 ~24 wool 13  
fill ~53 ~6 ~25 ~55 ~6 ~25 wool 13  
fill ~53 ~6 ~26 ~55 ~6 ~26 wool 13  
fill ~54 ~6 ~27 ~54 ~10 ~27 wool 13 
setblock ~56 ~6 ~21 wool 15 
setblock ~60 ~6 ~22 wool 15  
fill ~61 ~6 ~23 ~63 ~6 ~23 wool 7  
fill ~61 ~6 ~24 ~63 ~6 ~24 wool 13  
fill ~61 ~6 ~25 ~63 ~6 ~25 wool 13  
fill ~61 ~6 ~26 ~63 ~6 ~26 wool 13  
fill ~61 ~6 ~27 ~63 ~6 ~27 wool 13  
fill ~61 ~6 ~28 ~63 ~6 ~28 wool 13  
fill ~62 ~6 ~29 ~62 ~9 ~29 wool 13 
setblock ~64 ~6 ~22 wool 15  
fill ~8 ~7 ~30 ~23 ~7 ~30 wool 13  
fill ~9 ~7 ~31 ~23 ~7 ~31 wool 13  
fill ~10 ~7 ~29 ~27 ~7 ~29 wool 13  
fill ~17 ~7 ~28 ~37 ~7 ~28 wool 13  
fill ~17 ~7 ~32 ~23 ~7 ~32 wool 13  
fill ~20 ~7 ~23 ~20 ~9 ~23 wool 7  
fill ~20 ~7 ~24 ~20 ~9 ~24 wool 13  
fill ~20 ~7 ~25 ~20 ~9 ~25 wool 13  
fill ~20 ~7 ~26 ~20 ~9 ~26 wool 13  
fill ~20 ~7 ~27 ~20 ~9 ~27 wool 13 
setblock ~21 ~7 ~22 wool 15  
fill ~21 ~7 ~24 ~23 ~7 ~24 wool 7  
fill ~21 ~7 ~33 ~27 ~7 ~33 wool 13 
setblock ~23 ~7 ~22 wool 15  
fill ~24 ~7 ~23 ~24 ~9 ~23 wool 7  
fill ~24 ~7 ~24 ~24 ~9 ~24 wool 13  
fill ~24 ~7 ~25 ~24 ~9 ~25 wool 13  
fill ~24 ~7 ~26 ~24 ~9 ~26 wool 13  
fill ~24 ~7 ~27 ~37 ~7 ~27 wool 13  
fill ~24 ~7 ~30 ~28 ~7 ~30 wool 11  
fill ~24 ~7 ~31 ~24 ~7 ~32 wool 11  
fill ~25 ~7 ~31 ~26 ~7 ~31 wool 0  
fill ~25 ~7 ~32 ~28 ~7 ~32 wool 11  
fill ~26 ~7 ~34 ~37 ~7 ~34 wool 13 
setblock ~27 ~7 ~31 wool 11  
fill ~28 ~7 ~22 ~28 ~9 ~22 wool 7  
fill ~28 ~7 ~23 ~28 ~9 ~23 wool 13  
fill ~28 ~7 ~24 ~28 ~9 ~24 wool 13  
fill ~28 ~7 ~25 ~28 ~9 ~25 wool 13  
fill ~28 ~7 ~26 ~32 ~7 ~26 wool 13  
fill ~28 ~7 ~29 ~30 ~7 ~29 wool 11  
fill ~28 ~7 ~31 ~30 ~7 ~31 wool 0  
fill ~28 ~7 ~33 ~30 ~7 ~33 wool 11 
setblock ~29 ~7 ~21 wool 15  
fill ~29 ~7 ~23 ~31 ~7 ~23 wool 7 
setblock ~29 ~7 ~30 wool 0 
setblock ~29 ~7 ~32 wool 0  
fill ~30 ~7 ~30 ~34 ~7 ~30 wool 11  
fill ~30 ~7 ~32 ~34 ~7 ~32 wool 11 
setblock ~31 ~7 ~21 wool 15  
fill ~31 ~7 ~29 ~37 ~7 ~29 wool 13 
setblock ~31 ~7 ~31 wool 11  
fill ~31 ~7 ~33 ~37 ~7 ~33 wool 13  
fill ~31 ~7 ~35 ~37 ~7 ~35 wool 13  
fill ~32 ~7 ~22 ~32 ~9 ~22 wool 7  
fill ~32 ~7 ~23 ~32 ~9 ~23 wool 13  
fill ~32 ~7 ~24 ~32 ~9 ~24 wool 13  
fill ~32 ~7 ~25 ~32 ~9 ~25 wool 13  
fill ~32 ~7 ~31 ~33 ~7 ~31 wool 0  
fill ~32 ~7 ~36 ~37 ~7 ~36 wool 13  
fill ~33 ~7 ~37 ~37 ~7 ~37 wool 13  
fill ~34 ~7 ~26 ~37 ~7 ~26 wool 13 
setblock ~34 ~7 ~31 wool 11  
fill ~34 ~7 ~38 ~37 ~7 ~38 wool 13  
fill ~35 ~7 ~25 ~37 ~7 ~25 wool 13  
fill ~35 ~7 ~30 ~37 ~7 ~30 wool 13  
fill ~35 ~7 ~31 ~37 ~7 ~31 wool 13  
fill ~35 ~7 ~32 ~37 ~7 ~32 wool 13  
fill ~35 ~7 ~39 ~37 ~7 ~39 wool 13  
fill ~36 ~7 ~24 ~36 ~9 ~24 wool 13  
fill ~36 ~7 ~40 ~36 ~9 ~40 wool 13  
fill ~37 ~7 ~13 ~37 ~9 ~13 wool 13  
fill ~37 ~7 ~14 ~37 ~9 ~14 wool 13 
setblock ~37 ~7 ~53 wool 13  
fill ~37 ~7 ~54 ~37 ~10 ~54 wool 15 
setblock ~37 ~7 ~57 wool 11  
fill ~37 ~7 ~58 ~37 ~9 ~58 wool 0 
setblock ~37 ~7 ~59 wool 11  
fill ~37 ~7 ~60 ~37 ~7 ~61 wool 13  
fill ~37 ~7 ~63 ~38 ~7 ~63 wool 13  
fill ~37 ~7 ~64 ~38 ~7 ~64 wool 13  
fill ~37 ~7 ~65 ~37 ~9 ~65 wool 13  
fill ~38 ~7 ~8 ~38 ~9 ~8 wool 13  
fill ~38 ~7 ~9 ~39 ~7 ~9 wool 13  
fill ~38 ~7 ~14 ~38 ~9 ~14 wool 7  
fill ~38 ~7 ~15 ~38 ~9 ~15 wool 7  
fill ~38 ~7 ~16 ~38 ~10 ~16 wool 7  
fill ~38 ~7 ~17 ~38 ~6 ~17 wool 7  
fill ~38 ~7 ~18 ~38 ~10 ~18 wool 7  
fill ~38 ~7 ~19 ~38 ~10 ~19 wool 7  
fill ~38 ~7 ~20 ~38 ~6 ~20 wool 7  
fill ~38 ~7 ~21 ~38 ~10 ~21 wool 7  
fill ~38 ~7 ~25 ~38 ~7 ~30 redstone_wire 0  
fill ~38 ~7 ~31 ~38 ~10 ~31 wool 7  
fill ~38 ~7 ~32 ~38 ~10 ~32 wool 7  
fill ~38 ~7 ~33 ~38 ~7 ~61 wool 7  
fill ~38 ~7 ~68 ~38 ~10 ~68 wool 13  
fill ~38 ~7 ~69 ~38 ~9 ~69 wool 13  
fill ~39 ~7 ~6 ~45 ~7 ~6 wool 13  
fill ~39 ~7 ~7 ~39 ~10 ~7 wool 13  
fill ~39 ~7 ~10 ~39 ~10 ~10 wool 7  
fill ~39 ~7 ~11 ~39 ~5 ~11 wool 7  
fill ~39 ~7 ~12 ~39 ~5 ~12 wool 7  
fill ~39 ~7 ~13 ~39 ~5 ~13 wool 7  
fill ~39 ~7 ~14 ~39 ~7 ~23 stone_slab 0 
setblock ~39 ~7 ~24 stone_button 4  
fill ~39 ~7 ~25 ~39 ~7 ~31 wool 7  
fill ~39 ~7 ~32 ~39 ~7 ~61 stone_slab 0  
fill ~39 ~7 ~62 ~39 ~10 ~62 wool 7  
fill ~39 ~7 ~63 ~39 ~10 ~63 wool 7  
fill ~39 ~7 ~64 ~39 ~6 ~64 wool 7  
fill ~39 ~7 ~65 ~39 ~10 ~65 wool 7  
fill ~39 ~7 ~66 ~39 ~10 ~66 wool 7  
fill ~39 ~7 ~67 ~45 ~7 ~67 wool 7  
fill ~39 ~7 ~68 ~45 ~7 ~68 wool 7  
fill ~39 ~7 ~69 ~39 ~9 ~69 wool 7  
fill ~39 ~7 ~70 ~39 ~7 ~72 wool 13  
fill ~40 ~7 ~5 ~44 ~7 ~5 wool 13  
fill ~40 ~7 ~7 ~44 ~7 ~7 wool 7  
fill ~40 ~7 ~8 ~40 ~10 ~8 wool 7  
fill ~40 ~7 ~9 ~40 ~10 ~9 wool 7  
fill ~40 ~7 ~10 ~40 ~7 ~13 stone_slab 0  
fill ~40 ~7 ~23 ~45 ~7 ~23 stone_slab 0  
fill ~40 ~7 ~24 ~41 ~7 ~24 stone_slab 0  
fill ~40 ~7 ~25 ~41 ~7 ~25 stone_slab 0  
fill ~40 ~7 ~26 ~40 ~7 ~30 trapdoor 7  
fill ~40 ~7 ~31 ~44 ~7 ~31 stone_slab 0  
fill ~40 ~7 ~62 ~40 ~7 ~66 stone_slab 0  
fill ~40 ~7 ~73 ~44 ~7 ~73 wool 13 
setblock ~41 ~7 ~4 glass 0  
fill ~41 ~7 ~8 ~43 ~7 ~8 stone_slab 0  
fill ~41 ~7 ~9 ~41 ~7 ~8 stone_slab 0  
fill ~41 ~7 ~26 ~41 ~7 ~31 stone_slab 0 
setblock ~41 ~7 ~37 stone_slab 0  
fill ~41 ~7 ~38 ~43 ~7 ~38 double_stone_slab 0  
fill ~41 ~7 ~66 ~44 ~7 ~66 stone_slab 0  
fill ~41 ~7 ~70 ~41 ~7 ~74 wool 13  
fill ~42 ~7 ~3 ~42 ~9 ~3 glass 0  
fill ~42 ~7 ~17 ~42 ~12 ~17 ladder 2  
fill ~42 ~7 ~18 ~42 ~12 ~18 wool 7  
fill ~42 ~7 ~19 ~42 ~12 ~19 wool 7  
fill ~42 ~7 ~20 ~42 ~12 ~20 wool 7  
fill ~42 ~7 ~21 ~42 ~12 ~21 wool 7  
fill ~42 ~7 ~25 ~42 ~7 ~30 redstone_wire 0 
setblock ~42 ~7 ~37 trapdoor 0 
setblock ~43 ~7 ~4 glass 0 
setblock ~43 ~7 ~9 stone_slab 0  
fill ~43 ~7 ~24 ~44 ~7 ~24 stone_slab 0  
fill ~43 ~7 ~25 ~44 ~7 ~25 stone_slab 0  
fill ~43 ~7 ~26 ~43 ~7 ~31 stone_slab 0 
setblock ~43 ~7 ~37 stone_slab 0  
fill ~43 ~7 ~70 ~43 ~7 ~74 wool 13  
fill ~44 ~7 ~8 ~44 ~10 ~8 wool 7  
fill ~44 ~7 ~9 ~44 ~10 ~9 wool 7  
fill ~44 ~7 ~10 ~44 ~7 ~13 stone_slab 0  
fill ~44 ~7 ~26 ~44 ~7 ~30 trapdoor 2  
fill ~44 ~7 ~62 ~44 ~7 ~66 stone_slab 0  
fill ~45 ~7 ~7 ~45 ~10 ~7 wool 13  
fill ~45 ~7 ~9 ~46 ~7 ~9 wool 13  
fill ~45 ~7 ~10 ~45 ~10 ~10 wool 7  
fill ~45 ~7 ~11 ~45 ~7 ~13 wool 7  
fill ~45 ~7 ~14 ~45 ~7 ~23 stone_slab 0 
setblock ~45 ~7 ~24 stone_button 4  
fill ~45 ~7 ~25 ~45 ~7 ~31 wool 7  
fill ~45 ~7 ~32 ~45 ~7 ~61 stone_slab 0  
fill ~45 ~7 ~62 ~45 ~10 ~62 wool 7  
fill ~45 ~7 ~63 ~45 ~10 ~63 wool 7  
fill ~45 ~7 ~64 ~45 ~7 ~69 wool 7  
fill ~45 ~7 ~70 ~45 ~7 ~72 wool 13  
fill ~46 ~7 ~8 ~46 ~9 ~8 wool 13  
fill ~46 ~7 ~14 ~46 ~9 ~14 wool 7  
fill ~46 ~7 ~15 ~46 ~9 ~15 wool 7  
fill ~46 ~7 ~16 ~46 ~10 ~16 wool 7  
fill ~46 ~7 ~17 ~46 ~10 ~17 wool 7  
fill ~46 ~7 ~18 ~46 ~10 ~18 wool 7  
fill ~46 ~7 ~19 ~46 ~10 ~19 wool 7  
fill ~46 ~7 ~20 ~46 ~7 ~24 wool 7  
fill ~46 ~7 ~25 ~46 ~7 ~30 redstone_wire 0  
fill ~46 ~7 ~31 ~46 ~10 ~31 wool 7  
fill ~46 ~7 ~32 ~46 ~10 ~32 wool 7  
fill ~46 ~7 ~33 ~46 ~7 ~61 wool 7  
fill ~46 ~7 ~63 ~47 ~7 ~63 wool 13  
fill ~46 ~7 ~64 ~47 ~7 ~64 wool 13  
fill ~46 ~7 ~68 ~46 ~10 ~68 wool 13  
fill ~46 ~7 ~69 ~46 ~9 ~69 wool 13  
fill ~47 ~7 ~13 ~47 ~9 ~13 wool 13  
fill ~47 ~7 ~14 ~47 ~9 ~14 wool 13 
setblock ~47 ~7 ~47 wool 13  
fill ~47 ~7 ~48 ~47 ~10 ~48 wool 15 
setblock ~47 ~7 ~57 wool 11  
fill ~47 ~7 ~58 ~47 ~9 ~58 wool 0 
setblock ~47 ~7 ~59 wool 11  
fill ~47 ~7 ~60 ~47 ~7 ~61 wool 13  
fill ~47 ~7 ~65 ~47 ~9 ~65 wool 13  
fill ~48 ~7 ~24 ~48 ~9 ~24 wool 13  
fill ~48 ~7 ~25 ~49 ~7 ~25 wool 13  
fill ~48 ~7 ~26 ~50 ~7 ~26 wool 13  
fill ~48 ~7 ~27 ~60 ~7 ~27 wool 13  
fill ~48 ~7 ~28 ~67 ~7 ~28 wool 13  
fill ~48 ~7 ~29 ~53 ~7 ~29 wool 13  
fill ~48 ~7 ~30 ~49 ~7 ~30 wool 13  
fill ~48 ~7 ~31 ~49 ~7 ~31 wool 13  
fill ~48 ~7 ~32 ~49 ~7 ~32 wool 13  
fill ~48 ~7 ~33 ~53 ~7 ~33 wool 13  
fill ~48 ~7 ~34 ~58 ~7 ~34 wool 13  
fill ~48 ~7 ~35 ~53 ~7 ~35 wool 13  
fill ~48 ~7 ~36 ~52 ~7 ~36 wool 13  
fill ~48 ~7 ~37 ~51 ~7 ~37 wool 13  
fill ~48 ~7 ~38 ~50 ~7 ~38 wool 13  
fill ~48 ~7 ~39 ~49 ~7 ~39 wool 13  
fill ~50 ~7 ~30 ~54 ~7 ~30 wool 11  
fill ~50 ~7 ~31 ~50 ~7 ~32 wool 11  
fill ~51 ~7 ~31 ~52 ~7 ~31 wool 0  
fill ~51 ~7 ~32 ~54 ~7 ~32 wool 11  
fill ~52 ~7 ~22 ~52 ~9 ~22 wool 7  
fill ~52 ~7 ~23 ~52 ~9 ~23 wool 13  
fill ~52 ~7 ~24 ~52 ~9 ~24 wool 13  
fill ~52 ~7 ~25 ~52 ~9 ~25 wool 13  
fill ~52 ~7 ~26 ~56 ~7 ~26 wool 13 
setblock ~53 ~7 ~21 wool 15  
fill ~53 ~7 ~23 ~55 ~7 ~23 wool 7 
setblock ~53 ~7 ~31 wool 11  
fill ~54 ~7 ~29 ~56 ~7 ~29 wool 11  
fill ~54 ~7 ~31 ~56 ~7 ~31 wool 0  
fill ~54 ~7 ~33 ~56 ~7 ~33 wool 11 
setblock ~55 ~7 ~21 wool 15 
setblock ~55 ~7 ~30 wool 0 
setblock ~55 ~7 ~32 wool 0  
fill ~56 ~7 ~22 ~56 ~9 ~22 wool 7  
fill ~56 ~7 ~23 ~56 ~9 ~23 wool 13  
fill ~56 ~7 ~24 ~56 ~9 ~24 wool 13  
fill ~56 ~7 ~25 ~56 ~9 ~25 wool 13  
fill ~56 ~7 ~30 ~60 ~7 ~30 wool 11  
fill ~56 ~7 ~32 ~60 ~7 ~32 wool 11  
fill ~57 ~7 ~29 ~74 ~7 ~29 wool 13 
setblock ~57 ~7 ~31 wool 11  
fill ~57 ~7 ~33 ~63 ~7 ~33 wool 13  
fill ~58 ~7 ~31 ~59 ~7 ~31 wool 0  
fill ~60 ~7 ~23 ~60 ~9 ~23 wool 7  
fill ~60 ~7 ~24 ~60 ~9 ~24 wool 13  
fill ~60 ~7 ~25 ~60 ~9 ~25 wool 13  
fill ~60 ~7 ~26 ~60 ~9 ~26 wool 13 
setblock ~60 ~7 ~31 wool 11 
setblock ~61 ~7 ~22 wool 15  
fill ~61 ~7 ~24 ~63 ~7 ~24 wool 7  
fill ~61 ~7 ~30 ~76 ~7 ~30 wool 13  
fill ~61 ~7 ~31 ~75 ~7 ~31 wool 13  
fill ~61 ~7 ~32 ~67 ~7 ~32 wool 13 
setblock ~63 ~7 ~22 wool 15  
fill ~64 ~7 ~23 ~64 ~9 ~23 wool 7  
fill ~64 ~7 ~24 ~64 ~9 ~24 wool 13  
fill ~64 ~7 ~25 ~64 ~9 ~25 wool 13  
fill ~64 ~7 ~26 ~64 ~9 ~26 wool 13  
fill ~64 ~7 ~27 ~64 ~9 ~27 wool 13  
fill ~1 ~8 ~30 ~5 ~8 ~30 wool 15  
fill ~1 ~8 ~31 ~5 ~8 ~31 wool 15  
fill ~2 ~8 ~29 ~5 ~8 ~29 wool 15  
fill ~3 ~8 ~32 ~6 ~8 ~32 wool 15  
fill ~4 ~8 ~28 ~9 ~8 ~28 wool 15  
fill ~5 ~8 ~33 ~7 ~8 ~33 wool 15  
fill ~6 ~8 ~29 ~37 ~8 ~29 wool 13  
fill ~6 ~8 ~30 ~37 ~8 ~30 wool 13  
fill ~6 ~8 ~31 ~37 ~8 ~31 wool 13  
fill ~7 ~8 ~32 ~37 ~8 ~32 wool 13  
fill ~8 ~8 ~33 ~37 ~8 ~33 wool 13  
fill ~9 ~8 ~27 ~14 ~8 ~27 wool 15  
fill ~10 ~8 ~28 ~37 ~8 ~28 wool 13  
fill ~15 ~8 ~26 ~20 ~8 ~26 wool 13  
fill ~15 ~8 ~27 ~20 ~8 ~27 wool 13  
fill ~15 ~8 ~34 ~37 ~8 ~34 wool 13 
setblock ~19 ~8 ~25 wool 13  
fill ~19 ~8 ~35 ~37 ~8 ~35 wool 13  
fill ~21 ~8 ~24 ~23 ~8 ~24 wool 7  
fill ~22 ~8 ~22 ~22 ~8 ~23 iron_block 0  
fill ~22 ~8 ~26 ~22 ~8 ~27 iron_block 0  
fill ~24 ~8 ~27 ~37 ~8 ~27 wool 13  
fill ~24 ~8 ~36 ~37 ~8 ~36 wool 13  
fill ~25 ~8 ~25 ~28 ~8 ~25 wool 13  
fill ~25 ~8 ~26 ~37 ~8 ~26 wool 13 
setblock ~27 ~8 ~24 wool 13  
fill ~29 ~8 ~23 ~29 ~9 ~23 wool 7  
fill ~29 ~8 ~37 ~37 ~8 ~37 wool 13  
fill ~30 ~8 ~21 ~30 ~8 ~25 iron_block 0  
fill ~31 ~8 ~23 ~31 ~9 ~23 wool 7  
fill ~31 ~8 ~38 ~37 ~8 ~38 wool 13  
fill ~32 ~8 ~39 ~37 ~8 ~39 wool 13  
fill ~33 ~8 ~25 ~37 ~8 ~25 wool 13  
fill ~33 ~8 ~40 ~37 ~8 ~40 wool 13  
fill ~34 ~8 ~24 ~37 ~8 ~24 wool 13  
fill ~34 ~8 ~41 ~37 ~8 ~41 wool 13  
fill ~35 ~8 ~23 ~37 ~8 ~23 wool 13  
fill ~35 ~8 ~42 ~37 ~8 ~42 wool 13 
setblock ~36 ~8 ~22 wool 13 
setblock ~36 ~8 ~43 wool 13  
fill ~37 ~8 ~11 ~37 ~8 ~16 wool 13 
setblock ~37 ~8 ~17 iron_door 0 
setblock ~37 ~8 ~47 wool 15 
setblock ~37 ~8 ~50 wool 15 
setblock ~37 ~8 ~53 wool 15 
setblock ~37 ~8 ~56 wool 11 
setblock ~37 ~8 ~57 wool 0 
setblock ~37 ~8 ~59 wool 0 
setblock ~37 ~8 ~60 wool 11  
fill ~37 ~8 ~61 ~37 ~10 ~61 wool 13  
fill ~37 ~8 ~63 ~38 ~8 ~63 wool 13  
fill ~37 ~8 ~64 ~38 ~8 ~64 wool 13 
setblock ~37 ~8 ~66 wool 13 
setblock ~38 ~8 ~7 wool 13  
fill ~38 ~8 ~9 ~39 ~8 ~9 wool 13  
fill ~38 ~8 ~11 ~38 ~8 ~16 wool 7 
setblock ~38 ~8 ~20 glowstone 0  
fill ~38 ~8 ~25 ~38 ~10 ~25 wool 7  
fill ~38 ~8 ~26 ~38 ~10 ~26 wool 7  
fill ~38 ~8 ~27 ~38 ~10 ~27 wool 7 
setblock ~38 ~8 ~28 glowstone 0  
fill ~38 ~8 ~29 ~38 ~10 ~29 wool 7  
fill ~38 ~8 ~30 ~38 ~10 ~30 wool 7 
setblock ~38 ~8 ~33 glowstone 0  
fill ~38 ~8 ~34 ~38 ~10 ~34 wool 7  
fill ~38 ~8 ~35 ~38 ~10 ~35 wool 7  
fill ~38 ~8 ~36 ~38 ~10 ~36 wool 7  
fill ~38 ~8 ~37 ~38 ~10 ~37 wool 7 
setblock ~38 ~8 ~38 glowstone 0  
fill ~38 ~8 ~39 ~38 ~10 ~39 wool 7  
fill ~38 ~8 ~40 ~38 ~10 ~40 wool 7  
fill ~38 ~8 ~41 ~38 ~10 ~41 wool 7  
fill ~38 ~8 ~42 ~38 ~10 ~42 wool 7  
fill ~38 ~8 ~43 ~38 ~10 ~43 wool 7 
setblock ~38 ~8 ~44 glowstone 0  
fill ~38 ~8 ~45 ~38 ~10 ~45 wool 7  
fill ~38 ~8 ~46 ~38 ~10 ~46 wool 7  
fill ~38 ~8 ~47 ~38 ~10 ~47 wool 7  
fill ~38 ~8 ~48 ~38 ~10 ~48 wool 7 
setblock ~38 ~8 ~49 glowstone 0  
fill ~38 ~8 ~50 ~38 ~10 ~50 wool 7  
fill ~38 ~8 ~51 ~38 ~10 ~51 wool 7  
fill ~38 ~8 ~52 ~38 ~10 ~52 wool 7  
fill ~38 ~8 ~53 ~38 ~10 ~53 wool 7  
fill ~38 ~8 ~54 ~38 ~10 ~54 wool 7 
setblock ~38 ~8 ~55 glowstone 0  
fill ~38 ~8 ~56 ~38 ~10 ~56 wool 7  
fill ~38 ~8 ~57 ~38 ~10 ~57 wool 7  
fill ~38 ~8 ~58 ~38 ~10 ~58 wool 7  
fill ~38 ~8 ~59 ~38 ~10 ~59 wool 7  
fill ~38 ~8 ~60 ~38 ~10 ~60 wool 7 
setblock ~38 ~8 ~61 glowstone 0 
setblock ~38 ~8 ~70 wool 13  
fill ~39 ~8 ~5 ~40 ~8 ~5 wool 13  
fill ~39 ~8 ~6 ~40 ~8 ~6 wool 13 
setblock ~39 ~8 ~20 trapdoor 7 
setblock ~39 ~8 ~28 trapdoor 7 
setblock ~39 ~8 ~33 trapdoor 7 
setblock ~39 ~8 ~38 trapdoor 7 
setblock ~39 ~8 ~44 trapdoor 7 
setblock ~39 ~8 ~49 trapdoor 7 
setblock ~39 ~8 ~55 trapdoor 7 
setblock ~39 ~8 ~61 trapdoor 7 
setblock ~39 ~8 ~64 glowstone 0  
fill ~39 ~8 ~67 ~45 ~8 ~67 wool 7  
fill ~39 ~8 ~68 ~45 ~8 ~68 wool 7 
setblock ~39 ~8 ~70 wool 7  
fill ~39 ~8 ~71 ~39 ~10 ~71 wool 13  
fill ~39 ~8 ~72 ~39 ~9 ~72 wool 13  
fill ~39 ~8 ~73 ~40 ~8 ~73 wool 13 
setblock ~40 ~8 ~4 wool 13  
fill ~40 ~8 ~7 ~40 ~9 ~7 wool 7 
setblock ~40 ~8 ~64 trapdoor 7 
setblock ~41 ~8 ~3 glass 0  
fill ~41 ~8 ~70 ~41 ~8 ~73 redstone_wire 0 
setblock ~41 ~8 ~74 dispenser 3 
setblock ~42 ~8 ~5 oak_stairs 2  
fill ~42 ~8 ~23 ~42 ~13 ~23 ladder 3  
fill ~42 ~8 ~66 ~42 ~9 ~66 ladder 2  
fill ~42 ~8 ~73 ~42 ~10 ~73 wool 13 
setblock ~43 ~8 ~3 glass 0 
setblock ~43 ~8 ~70 redstone_wire 15 
setblock ~43 ~8 ~71 redstone_wire 14 
setblock ~43 ~8 ~72 redstone_wire 13 
setblock ~43 ~8 ~73 redstone_wire 12 
setblock ~43 ~8 ~74 dispenser 3  
fill ~44 ~8 ~4 ~44 ~8 ~6 wool 13  
fill ~44 ~8 ~7 ~44 ~9 ~7 wool 7 
setblock ~44 ~8 ~64 trapdoor 6  
fill ~44 ~8 ~73 ~45 ~8 ~73 wool 13  
fill ~45 ~8 ~5 ~45 ~8 ~9 wool 13 
setblock ~45 ~8 ~20 trapdoor 6 
setblock ~45 ~8 ~28 trapdoor 6 
setblock ~45 ~8 ~33 trapdoor 6 
setblock ~45 ~8 ~38 trapdoor 6 
setblock ~45 ~8 ~44 trapdoor 6 
setblock ~45 ~8 ~49 trapdoor 6 
setblock ~45 ~8 ~55 trapdoor 6 
setblock ~45 ~8 ~61 trapdoor 6 
setblock ~45 ~8 ~64 glowstone 0  
fill ~45 ~8 ~65 ~45 ~10 ~65 wool 7 
fill ~45 ~8 ~66 ~45 ~10 ~66 wool 7  
fill ~45 ~8 ~69 ~45 ~9 ~69 wool 7  
fill ~45 ~8 ~70 ~45 ~8 ~65 wool 7  
fill ~45 ~8 ~71 ~45 ~10 ~71 wool 13  
fill ~45 ~8 ~72 ~45 ~9 ~72 wool 13 
setblock ~46 ~8 ~7 wool 13  
fill ~46 ~8 ~9 ~46 ~10 ~9 wool 13  
fill ~46 ~8 ~11 ~46 ~8 ~19 wool 7 
setblock ~46 ~8 ~20 glowstone 0  
fill ~46 ~8 ~21 ~46 ~10 ~21 wool 7  
fill ~46 ~8 ~25 ~46 ~10 ~25 wool 7  
fill ~46 ~8 ~26 ~46 ~10 ~26 wool 7  
fill ~46 ~8 ~27 ~46 ~10 ~27 wool 7 
setblock ~46 ~8 ~28 glowstone 0  
fill ~46 ~8 ~29 ~46 ~10 ~29 wool 7  
fill ~46 ~8 ~30 ~46 ~10 ~30 wool 7 
setblock ~46 ~8 ~33 glowstone 0  
fill ~46 ~8 ~34 ~46 ~10 ~34 wool 7  
fill ~46 ~8 ~35 ~46 ~10 ~35 wool 7  
fill ~46 ~8 ~36 ~46 ~10 ~36 wool 7  
fill ~46 ~8 ~37 ~46 ~10 ~37 wool 7 
setblock ~46 ~8 ~38 glowstone 0  
fill ~46 ~8 ~39 ~46 ~10 ~39 wool 7  
fill ~46 ~8 ~40 ~46 ~10 ~40 wool 7  
fill ~46 ~8 ~41 ~46 ~10 ~41 wool 7  
fill ~46 ~8 ~42 ~46 ~10 ~42 wool 7  
fill ~46 ~8 ~43 ~46 ~10 ~43 wool 7 
setblock ~46 ~8 ~44 glowstone 0  
fill ~46 ~8 ~45 ~46 ~10 ~45 wool 7  
fill ~46 ~8 ~46 ~46 ~10 ~46 wool 7  
fill ~46 ~8 ~47 ~46 ~10 ~47 wool 7  
fill ~46 ~8 ~48 ~46 ~10 ~48 wool 7 
setblock ~46 ~8 ~49 glowstone 0  
fill ~46 ~8 ~50 ~46 ~10 ~50 wool 7  
fill ~46 ~8 ~51 ~46 ~10 ~51 wool 7  
fill ~46 ~8 ~52 ~46 ~10 ~52 wool 7  
fill ~46 ~8 ~53 ~46 ~10 ~53 wool 7  
fill ~46 ~8 ~54 ~46 ~10 ~54 wool 7 
setblock ~46 ~8 ~55 glowstone 0  
fill ~46 ~8 ~56 ~46 ~10 ~56 wool 7  
fill ~46 ~8 ~57 ~46 ~10 ~57 wool 7  
fill ~46 ~8 ~58 ~46 ~10 ~58 wool 7  
fill ~46 ~8 ~59 ~46 ~10 ~59 wool 7  
fill ~46 ~8 ~60 ~46 ~10 ~60 wool 7 
setblock ~46 ~8 ~61 glowstone 0  
fill ~46 ~8 ~63 ~47 ~8 ~63 wool 13  
fill ~46 ~8 ~64 ~47 ~8 ~64 wool 13 
setblock ~46 ~8 ~70 wool 13  
fill ~47 ~8 ~11 ~47 ~8 ~45 wool 13 
setblock ~47 ~8 ~47 wool 15 
setblock ~47 ~8 ~50 wool 15 
setblock ~47 ~8 ~53 wool 15 
setblock ~47 ~8 ~56 wool 11 
setblock ~47 ~8 ~57 wool 0 
setblock ~47 ~8 ~59 wool 0 
setblock ~47 ~8 ~60 wool 11  
fill ~47 ~8 ~61 ~47 ~10 ~61 wool 13 
setblock ~47 ~8 ~66 wool 13  
fill ~48 ~8 ~22 ~48 ~8 ~43 wool 13  
fill ~49 ~8 ~23 ~49 ~8 ~42 wool 13  
fill ~50 ~8 ~24 ~50 ~8 ~41 wool 13  
fill ~51 ~8 ~25 ~51 ~8 ~40 wool 13  
fill ~52 ~8 ~26 ~60 ~8 ~26 wool 13  
fill ~52 ~8 ~27 ~60 ~8 ~27 wool 13  
fill ~52 ~8 ~28 ~74 ~8 ~28 wool 13  
fill ~52 ~8 ~29 ~78 ~8 ~29 wool 13  
fill ~52 ~8 ~30 ~78 ~8 ~30 wool 13  
fill ~52 ~8 ~31 ~78 ~8 ~31 wool 13  
fill ~52 ~8 ~32 ~77 ~8 ~32 wool 13  
fill ~52 ~8 ~33 ~76 ~8 ~33 wool 13  
fill ~52 ~8 ~34 ~69 ~8 ~34 wool 13  
fill ~52 ~8 ~35 ~65 ~8 ~35 wool 13  
fill ~52 ~8 ~36 ~60 ~8 ~36 wool 13  
fill ~52 ~8 ~37 ~55 ~8 ~37 wool 13  
fill ~52 ~8 ~38 ~53 ~8 ~38 wool 13  
fill ~52 ~8 ~39 ~52 ~8 ~23 wool 13  
fill ~53 ~8 ~23 ~53 ~9 ~23 wool 7  
fill ~54 ~8 ~21 ~54 ~8 ~25 iron_block 0  
fill ~55 ~8 ~23 ~55 ~9 ~23 wool 7  
fill ~57 ~8 ~24 ~57 ~8 ~36 wool 13  
fill ~58 ~8 ~25 ~60 ~8 ~25 wool 13  
fill ~61 ~8 ~24 ~63 ~8 ~24 wool 7  
fill ~62 ~8 ~22 ~62 ~8 ~23 iron_block 0  
fill ~62 ~8 ~25 ~62 ~8 ~27 iron_block 0  
fill ~65 ~8 ~25 ~65 ~8 ~35 wool 13  
fill ~66 ~8 ~26 ~69 ~8 ~26 wool 13  
fill ~66 ~8 ~27 ~69 ~8 ~27 wool 13  
fill ~70 ~8 ~27 ~75 ~8 ~27 wool 15  
fill ~75 ~8 ~28 ~80 ~8 ~28 wool 15  
fill ~77 ~8 ~33 ~79 ~8 ~33 wool 15  
fill ~78 ~8 ~32 ~81 ~8 ~32 wool 15  
fill ~79 ~8 ~29 ~82 ~8 ~29 wool 15  
fill ~79 ~8 ~30 ~83 ~8 ~30 wool 15  
fill ~79 ~8 ~31 ~83 ~8 ~31 wool 15  
fill ~8 ~9 ~30 ~23 ~9 ~30 wool 13  
fill ~9 ~9 ~31 ~23 ~9 ~31 wool 13  
fill ~10 ~9 ~29 ~27 ~9 ~29 wool 13  
fill ~17 ~9 ~28 ~37 ~9 ~28 wool 13  
fill ~17 ~9 ~32 ~23 ~9 ~32 wool 13 
setblock ~21 ~9 ~22 wool 15  
fill ~21 ~9 ~24 ~23 ~9 ~24 wool 7  
fill ~21 ~9 ~33 ~27 ~9 ~33 wool 13 
setblock ~23 ~9 ~22 wool 15  
fill ~24 ~9 ~27 ~37 ~9 ~27 wool 13  
fill ~24 ~9 ~30 ~28 ~9 ~30 wool 11  
fill ~24 ~9 ~31 ~24 ~9 ~32 wool 11  
fill ~25 ~9 ~31 ~26 ~9 ~31 wool 0  
fill ~25 ~9 ~32 ~28 ~9 ~32 wool 11  
fill ~26 ~9 ~34 ~37 ~9 ~34 wool 13 
setblock ~27 ~9 ~31 wool 11  
fill ~28 ~9 ~26 ~32 ~9 ~26 wool 13  
fill ~28 ~9 ~29 ~30 ~9 ~29 wool 11  
fill ~28 ~9 ~31 ~30 ~9 ~31 wool 0  
fill ~28 ~9 ~33 ~30 ~9 ~33 wool 11 
setblock ~29 ~9 ~21 wool 15 
setblock ~29 ~9 ~30 wool 0 
setblock ~29 ~9 ~32 wool 0 
setblock ~30 ~9 ~23 wool 7  
fill ~30 ~9 ~30 ~34 ~9 ~30 wool 11  
fill ~30 ~9 ~32 ~34 ~9 ~32 wool 11 
setblock ~31 ~9 ~21 wool 15  
fill ~31 ~9 ~29 ~37 ~9 ~29 wool 13 
setblock ~31 ~9 ~31 wool 11  
fill ~31 ~9 ~33 ~37 ~9 ~33 wool 13  
fill ~31 ~9 ~35 ~37 ~9 ~35 wool 13  
fill ~32 ~9 ~31 ~33 ~9 ~31 wool 0  
fill ~32 ~9 ~36 ~37 ~9 ~36 wool 13  
fill ~33 ~9 ~37 ~37 ~9 ~37 wool 13  
fill ~34 ~9 ~26 ~37 ~9 ~26 wool 13 
setblock ~34 ~9 ~31 wool 11  
fill ~34 ~9 ~38 ~37 ~9 ~38 wool 13  
fill ~35 ~9 ~25 ~37 ~9 ~25 wool 13  
fill ~35 ~9 ~30 ~37 ~9 ~30 wool 13  
fill ~35 ~9 ~31 ~37 ~9 ~31 wool 13  
fill ~35 ~9 ~32 ~37 ~9 ~32 wool 13  
fill ~35 ~9 ~39 ~37 ~9 ~39 wool 13  
fill ~35 ~9 ~40 ~35 ~9 ~25 wool 13 
setblock ~36 ~9 ~18 stone_button 2 
setblock ~37 ~9 ~17 iron_door 8 
setblock ~37 ~9 ~47 wool 13  
fill ~37 ~9 ~50 ~37 ~10 ~50 wool 13 
setblock ~37 ~9 ~53 wool 13  
fill ~37 ~9 ~56 ~37 ~10 ~56 wool 13 
setblock ~37 ~9 ~57 wool 11 
setblock ~37 ~9 ~59 wool 11  
fill ~37 ~9 ~60 ~37 ~10 ~60 wool 13  
fill ~37 ~9 ~63 ~38 ~9 ~63 wool 13  
fill ~37 ~9 ~64 ~38 ~9 ~64 wool 13  
fill ~38 ~9 ~9 ~39 ~9 ~9 wool 13  
fill ~38 ~9 ~11 ~38 ~11 ~11 wool 13  
fill ~38 ~9 ~12 ~38 ~11 ~12 wool 13  
fill ~38 ~9 ~13 ~38 ~11 ~13 wool 13 
setblock ~38 ~9 ~17 stone_button 4  
fill ~38 ~9 ~20 ~38 ~10 ~20 wool 7  
fill ~38 ~9 ~28 ~38 ~10 ~28 wool 7  
fill ~38 ~9 ~33 ~38 ~10 ~33 wool 7  
fill ~38 ~9 ~38 ~38 ~10 ~38 wool 7  
fill ~38 ~9 ~44 ~38 ~10 ~44 wool 7  
fill ~38 ~9 ~49 ~38 ~10 ~49 wool 7  
fill ~38 ~9 ~55 ~38 ~10 ~55 wool 7  
fill ~38 ~9 ~61 ~38 ~10 ~61 wool 7  
fill ~39 ~9 ~6 ~40 ~9 ~6 wool 13  
fill ~39 ~9 ~11 ~39 ~11 ~11 wool 7  
fill ~39 ~9 ~12 ~39 ~11 ~12 wool 7  
fill ~39 ~9 ~13 ~39 ~11 ~13 wool 7  
fill ~39 ~9 ~64 ~39 ~10 ~64 wool 7  
fill ~39 ~9 ~67 ~45 ~9 ~67 wool 7  
fill ~39 ~9 ~68 ~45 ~9 ~68 wool 7  
fill ~39 ~9 ~70 ~39 ~12 ~70 wool 13 
setblock ~40 ~9 ~5 wool 13  
fill ~40 ~9 ~69 ~45 ~9 ~69 wool 7  
fill ~40 ~9 ~70 ~44 ~9 ~70 wool 7  
fill ~40 ~9 ~72 ~45 ~9 ~72 wool 13  
fill ~40 ~9 ~73 ~44 ~9 ~73 wool 13 
setblock ~41 ~9 ~4 dispenser 2 
setblock ~41 ~9 ~5 stone_button 1  
fill ~41 ~9 ~71 ~43 ~9 ~71 wool 13 
setblock ~41 ~9 ~74 wool 13 
setblock ~43 ~9 ~4 dispenser 2 
setblock ~43 ~9 ~5 stone_button 2 
setblock ~43 ~9 ~74 wool 13  
fill ~44 ~9 ~5 ~44 ~9 ~6 wool 13 
setblock ~45 ~9 ~6 wool 13  
fill ~45 ~9 ~9 ~45 ~11 ~9 wool 13  
fill ~45 ~9 ~11 ~45 ~11 ~11 wool 7  
fill ~45 ~9 ~12 ~45 ~11 ~12 wool 7  
fill ~45 ~9 ~13 ~45 ~11 ~13 wool 7  
fill ~45 ~9 ~64 ~45 ~10 ~64 wool 7  
fill ~45 ~9 ~70 ~45 ~12 ~70 wool 13  
fill ~46 ~9 ~11 ~46 ~11 ~11 wool 13  
fill ~46 ~9 ~12 ~46 ~11 ~12 wool 13  
fill ~46 ~9 ~13 ~46 ~11 ~13 wool 13  
fill ~46 ~9 ~20 ~46 ~10 ~20 wool 7  
fill ~46 ~9 ~28 ~46 ~10 ~28 wool 7  
fill ~46 ~9 ~33 ~46 ~10 ~33 wool 7  
fill ~46 ~9 ~38 ~46 ~10 ~38 wool 7  
fill ~46 ~9 ~44 ~46 ~10 ~44 wool 7  
fill ~46 ~9 ~49 ~46 ~10 ~49 wool 7  
fill ~46 ~9 ~55 ~46 ~10 ~55 wool 7  
fill ~46 ~9 ~61 ~46 ~10 ~61 wool 7  
fill ~46 ~9 ~63 ~47 ~9 ~63 wool 13  
fill ~46 ~9 ~64 ~47 ~9 ~64 wool 13 
setblock ~47 ~9 ~47 wool 13  
fill ~47 ~9 ~50 ~47 ~10 ~50 wool 13 
setblock ~47 ~9 ~53 wool 13  
fill ~47 ~9 ~56 ~47 ~10 ~56 wool 13 
setblock ~47 ~9 ~57 wool 11 
setblock ~47 ~9 ~59 wool 11  
fill ~47 ~9 ~60 ~47 ~10 ~60 wool 13  
fill ~48 ~9 ~25 ~49 ~9 ~25 wool 13  
fill ~48 ~9 ~26 ~50 ~9 ~26 wool 13  
fill ~48 ~9 ~27 ~60 ~9 ~27 wool 13  
fill ~48 ~9 ~28 ~67 ~9 ~28 wool 13  
fill ~48 ~9 ~29 ~53 ~9 ~29 wool 13  
fill ~48 ~9 ~30 ~49 ~9 ~30 wool 13  
fill ~48 ~9 ~31 ~49 ~9 ~31 wool 13  
fill ~48 ~9 ~32 ~49 ~9 ~32 wool 13  
fill ~48 ~9 ~33 ~53 ~9 ~33 wool 13  
fill ~48 ~9 ~34 ~58 ~9 ~34 wool 13  
fill ~48 ~9 ~35 ~53 ~9 ~35 wool 13  
fill ~48 ~9 ~36 ~52 ~9 ~36 wool 13  
fill ~48 ~9 ~37 ~51 ~9 ~37 wool 13  
fill ~48 ~9 ~38 ~50 ~9 ~38 wool 13  
fill ~48 ~9 ~39 ~49 ~9 ~39 wool 13  
fill ~48 ~9 ~40 ~49 ~9 ~40 wool 13  
fill ~50 ~9 ~30 ~54 ~9 ~30 wool 11  
fill ~50 ~9 ~31 ~50 ~9 ~32 wool 11  
fill ~51 ~9 ~31 ~52 ~9 ~31 wool 0  
fill ~51 ~9 ~32 ~54 ~9 ~32 wool 11  
fill ~52 ~9 ~26 ~56 ~9 ~26 wool 13 
setblock ~53 ~9 ~21 wool 15 
setblock ~53 ~9 ~31 wool 11 
setblock ~54 ~9 ~23 wool 7  
fill ~54 ~9 ~29 ~56 ~9 ~29 wool 11  
fill ~54 ~9 ~31 ~56 ~9 ~31 wool 0  
fill ~54 ~9 ~33 ~56 ~9 ~33 wool 11 
setblock ~55 ~9 ~21 wool 15 
setblock ~55 ~9 ~30 wool 0 
setblock ~55 ~9 ~32 wool 0  
fill ~56 ~9 ~30 ~60 ~9 ~30 wool 11  
fill ~56 ~9 ~32 ~60 ~9 ~32 wool 11  
fill ~57 ~9 ~29 ~74 ~9 ~29 wool 13 
setblock ~57 ~9 ~31 wool 11  
fill ~57 ~9 ~33 ~63 ~9 ~33 wool 13  
fill ~58 ~9 ~31 ~59 ~9 ~31 wool 0 
setblock ~60 ~9 ~31 wool 11 
setblock ~61 ~9 ~22 wool 15  
fill ~61 ~9 ~24 ~63 ~9 ~24 wool 7  
fill ~61 ~9 ~30 ~76 ~9 ~30 wool 13  
fill ~61 ~9 ~31 ~75 ~9 ~31 wool 13  
fill ~61 ~9 ~32 ~67 ~9 ~32 wool 13 
setblock ~63 ~9 ~22 wool 15 
setblock ~20 ~10 ~22 wool 15  
fill ~21 ~10 ~23 ~23 ~10 ~23 wool 7  
fill ~21 ~10 ~24 ~23 ~10 ~24 wool 13  
fill ~21 ~10 ~25 ~23 ~10 ~25 wool 13  
fill ~21 ~10 ~26 ~23 ~10 ~26 wool 13  
fill ~21 ~10 ~27 ~23 ~10 ~27 wool 13 
setblock ~22 ~10 ~28 wool 13 
setblock ~24 ~10 ~22 wool 15 
setblock ~28 ~10 ~21 wool 15  
fill ~29 ~10 ~22 ~31 ~10 ~22 wool 7  
fill ~29 ~10 ~23 ~31 ~10 ~23 wool 13  
fill ~29 ~10 ~24 ~31 ~10 ~24 wool 13  
fill ~29 ~10 ~25 ~31 ~10 ~25 wool 13  
fill ~29 ~10 ~26 ~31 ~10 ~26 wool 13 
setblock ~32 ~10 ~21 wool 15 
setblock ~37 ~10 ~17 wool 13 
setblock ~37 ~10 ~47 wool 15 
setblock ~37 ~10 ~53 wool 15 
setblock ~37 ~10 ~57 wool 13 
setblock ~37 ~10 ~58 wool 11 
setblock ~37 ~10 ~59 wool 13  
fill ~37 ~10 ~63 ~38 ~10 ~63 wool 13  
fill ~37 ~10 ~64 ~38 ~10 ~64 wool 13  
fill ~38 ~10 ~9 ~39 ~10 ~9 wool 13  
fill ~38 ~10 ~14 ~38 ~11 ~14 wool 13  
fill ~38 ~10 ~15 ~38 ~11 ~15 wool 13 
setblock ~38 ~10 ~17 wool 7  
fill ~39 ~10 ~14 ~39 ~11 ~14 wool 7  
fill ~39 ~10 ~15 ~39 ~11 ~15 wool 7  
fill ~39 ~10 ~67 ~39 ~6 ~67 wool 7  
fill ~39 ~10 ~68 ~39 ~12 ~68 wool 13  
fill ~39 ~10 ~69 ~39 ~12 ~69 wool 13  
fill ~40 ~10 ~6 ~44 ~10 ~6 wool 13  
fill ~40 ~10 ~7 ~40 ~11 ~7 wool 13  
fill ~40 ~10 ~67 ~41 ~10 ~67 iron_bars 0  
fill ~40 ~10 ~71 ~45 ~10 ~71 wool 13  
fill ~40 ~10 ~72 ~44 ~10 ~72 wool 13  
fill ~41 ~10 ~5 ~43 ~10 ~5 wool 13  
fill ~41 ~10 ~7 ~43 ~10 ~7 wool 7  
fill ~41 ~10 ~8 ~44 ~10 ~8 wool 7  
fill ~41 ~10 ~9 ~44 ~10 ~9 wool 7 
setblock ~41 ~10 ~70 lever 5 
setblock ~41 ~10 ~73 wool 13 
setblock ~42 ~10 ~4 wool 13 
setblock ~42 ~10 ~69 oak_stairs 3  
fill ~43 ~10 ~67 ~44 ~10 ~67 iron_bars 0 
setblock ~43 ~10 ~70 lever 14 
setblock ~43 ~10 ~73 wool 13  
fill ~44 ~10 ~7 ~44 ~11 ~7 wool 13  
fill ~45 ~10 ~14 ~45 ~11 ~14 wool 7  
fill ~45 ~10 ~15 ~45 ~11 ~15 wool 7 
setblock ~45 ~10 ~67 wool 7  
fill ~45 ~10 ~68 ~45 ~12 ~68 wool 13  
fill ~45 ~10 ~69 ~45 ~12 ~69 wool 13  
fill ~46 ~10 ~14 ~46 ~11 ~14 wool 13  
fill ~46 ~10 ~15 ~46 ~11 ~15 wool 13  
fill ~46 ~10 ~63 ~47 ~10 ~63 wool 13  
fill ~46 ~10 ~64 ~47 ~10 ~64 wool 13 
setblock ~47 ~10 ~47 wool 15 
setblock ~47 ~10 ~53 wool 15 
setblock ~47 ~10 ~57 wool 13 
setblock ~47 ~10 ~58 wool 11 
setblock ~47 ~10 ~59 wool 13 
setblock ~52 ~10 ~21 wool 15  
fill ~53 ~10 ~22 ~55 ~10 ~22 wool 7  
fill ~53 ~10 ~23 ~55 ~10 ~23 wool 13  
fill ~53 ~10 ~24 ~55 ~10 ~24 wool 13  
fill ~53 ~10 ~25 ~55 ~10 ~25 wool 13  
fill ~53 ~10 ~26 ~55 ~10 ~26 wool 13 
setblock ~56 ~10 ~21 wool 15 
setblock ~60 ~10 ~22 wool 15  
fill ~61 ~10 ~23 ~63 ~10 ~23 wool 7  
fill ~61 ~10 ~24 ~63 ~10 ~24 wool 13  
fill ~61 ~10 ~25 ~63 ~10 ~25 wool 13  
fill ~61 ~10 ~26 ~63 ~10 ~26 wool 13  
fill ~61 ~10 ~27 ~63 ~10 ~27 wool 13 
setblock ~62 ~10 ~28 wool 13 
setblock ~64 ~10 ~22 wool 15 
setblock ~19 ~11 ~22 wool 15 
setblock ~25 ~11 ~22 wool 15 
setblock ~27 ~11 ~21 wool 15 
setblock ~33 ~11 ~21 wool 15  
fill ~38 ~11 ~16 ~38 ~11 ~61 wool 13 
setblock ~38 ~11 ~62 double_stone_slab 0  
fill ~38 ~11 ~63 ~38 ~11 ~65 stone_slab 0  
fill ~39 ~11 ~9 ~45 ~11 ~9 wool 13  
fill ~39 ~11 ~10 ~39 ~11 ~9 wool 13  
fill ~39 ~11 ~16 ~45 ~11 ~16 wool 7  
fill ~39 ~11 ~17 ~41 ~11 ~17 wool 7  
fill ~39 ~11 ~18 ~45 ~11 ~18 wool 7  
fill ~39 ~11 ~19 ~45 ~11 ~19 wool 7  
fill ~39 ~11 ~20 ~40 ~11 ~20 wool 7  
fill ~39 ~11 ~21 ~45 ~11 ~21 wool 7  
fill ~39 ~11 ~22 ~45 ~11 ~22 wool 7  
fill ~39 ~11 ~23 ~41 ~11 ~23 wool 7  
fill ~39 ~11 ~24 ~45 ~11 ~24 wool 7  
fill ~39 ~11 ~25 ~45 ~11 ~25 wool 7  
fill ~39 ~11 ~26 ~45 ~11 ~26 wool 7  
fill ~39 ~11 ~27 ~45 ~11 ~27 wool 7  
fill ~39 ~11 ~28 ~40 ~11 ~28 wool 7  
fill ~39 ~11 ~29 ~45 ~11 ~29 wool 7  
fill ~39 ~11 ~30 ~45 ~11 ~30 wool 7  
fill ~39 ~11 ~31 ~45 ~11 ~31 wool 7  
fill ~39 ~11 ~32 ~45 ~11 ~32 wool 7  
fill ~39 ~11 ~33 ~40 ~11 ~33 wool 7  
fill ~39 ~11 ~34 ~45 ~11 ~34 wool 7  
fill ~39 ~11 ~35 ~45 ~11 ~35 wool 7  
fill ~39 ~11 ~36 ~45 ~11 ~36 wool 7  
fill ~39 ~11 ~37 ~45 ~11 ~37 wool 7  
fill ~39 ~11 ~38 ~40 ~11 ~38 wool 7  
fill ~39 ~11 ~39 ~45 ~11 ~39 wool 7  
fill ~39 ~11 ~40 ~45 ~11 ~40 wool 7  
fill ~39 ~11 ~41 ~45 ~11 ~41 wool 7  
fill ~39 ~11 ~42 ~45 ~11 ~42 wool 7  
fill ~39 ~11 ~43 ~45 ~11 ~43 wool 7  
fill ~39 ~11 ~44 ~40 ~11 ~44 wool 7  
fill ~39 ~11 ~45 ~45 ~11 ~45 wool 7  
fill ~39 ~11 ~46 ~45 ~11 ~46 wool 7  
fill ~39 ~11 ~47 ~45 ~11 ~47 wool 7  
fill ~39 ~11 ~48 ~45 ~11 ~48 wool 7  
fill ~39 ~11 ~49 ~40 ~11 ~49 wool 7  
fill ~39 ~11 ~50 ~45 ~11 ~50 wool 7  
fill ~39 ~11 ~51 ~45 ~11 ~51 wool 7  
fill ~39 ~11 ~52 ~45 ~11 ~52 wool 7  
fill ~39 ~11 ~53 ~45 ~11 ~53 wool 7  
fill ~39 ~11 ~54 ~45 ~11 ~54 wool 7  
fill ~39 ~11 ~55 ~40 ~11 ~55 wool 7  
fill ~39 ~11 ~56 ~45 ~11 ~56 wool 7  
fill ~39 ~11 ~57 ~45 ~11 ~57 wool 7  
fill ~39 ~11 ~58 ~45 ~11 ~58 wool 7  
fill ~39 ~11 ~59 ~45 ~11 ~59 wool 7  
fill ~39 ~11 ~60 ~45 ~11 ~60 wool 7  
fill ~39 ~11 ~61 ~40 ~11 ~61 wool 7  
fill ~39 ~11 ~62 ~39 ~11 ~70 wool 13  
fill ~40 ~11 ~8 ~44 ~11 ~8 wool 13  
fill ~40 ~11 ~10 ~44 ~11 ~10 wool 7  
fill ~40 ~11 ~11 ~40 ~11 ~66 wool 7  
fill ~40 ~11 ~71 ~40 ~10 ~71 wool 13  
fill ~41 ~11 ~6 ~43 ~11 ~6 wool 13  
fill ~41 ~11 ~7 ~44 ~11 ~7 wool 13  
fill ~41 ~11 ~11 ~41 ~12 ~11 glowstone 0  
fill ~41 ~11 ~12 ~41 ~12 ~12 glowstone 0  
fill ~41 ~11 ~13 ~41 ~12 ~13 glowstone 0  
fill ~41 ~11 ~14 ~45 ~11 ~14 wool 7  
fill ~41 ~11 ~15 ~45 ~11 ~15 wool 7  
fill ~41 ~11 ~20 ~41 ~12 ~20 glowstone 0  
fill ~41 ~11 ~28 ~41 ~12 ~28 glowstone 0 
setblock ~41 ~11 ~33 glowstone 0  
fill ~41 ~11 ~38 ~41 ~12 ~38 glowstone 0  
fill ~41 ~11 ~44 ~41 ~12 ~44 glowstone 0  
fill ~41 ~11 ~49 ~41 ~12 ~49 glowstone 0  
fill ~41 ~11 ~55 ~41 ~12 ~55 glowstone 0  
fill ~41 ~11 ~61 ~41 ~12 ~61 glowstone 0  
fill ~41 ~11 ~62 ~44 ~11 ~62 wool 7  
fill ~41 ~11 ~63 ~44 ~11 ~63 wool 7  
fill ~41 ~11 ~64 ~44 ~11 ~64 wool 7  
fill ~41 ~11 ~65 ~44 ~11 ~65 wool 7  
fill ~41 ~11 ~66 ~41 ~11 ~62 wool 7  
fill ~41 ~11 ~71 ~43 ~11 ~71 glass 0 
setblock ~42 ~11 ~5 wool 13  
fill ~42 ~11 ~11 ~42 ~12 ~11 wool 7  
fill ~42 ~11 ~12 ~42 ~12 ~12 wool 7  
fill ~42 ~11 ~13 ~42 ~12 ~13 wool 7  
fill ~42 ~11 ~28 ~42 ~12 ~28 wool 7  
fill ~42 ~11 ~33 ~42 ~12 ~33 wool 7  
fill ~42 ~11 ~38 ~42 ~12 ~38 wool 7  
fill ~42 ~11 ~44 ~42 ~12 ~44 wool 7  
fill ~42 ~11 ~49 ~42 ~12 ~49 wool 7  
fill ~42 ~11 ~55 ~42 ~12 ~55 wool 7  
fill ~42 ~11 ~61 ~42 ~12 ~61 wool 7 
setblock ~42 ~11 ~72 wool 13 
setblock ~42 ~11 ~73 double_stone_slab 0  
fill ~42 ~11 ~74 ~42 ~11 ~75 stone_slab 0  
fill ~43 ~11 ~11 ~43 ~12 ~11 glowstone 0  
fill ~43 ~11 ~12 ~43 ~12 ~12 glowstone 0  
fill ~43 ~11 ~13 ~43 ~12 ~13 glowstone 0  
fill ~43 ~11 ~17 ~45 ~11 ~17 wool 7  
fill ~43 ~11 ~20 ~43 ~12 ~20 glowstone 0  
fill ~43 ~11 ~23 ~45 ~11 ~23 wool 7  
fill ~43 ~11 ~28 ~43 ~12 ~28 glowstone 0 
setblock ~43 ~11 ~33 glowstone 0  
fill ~43 ~11 ~38 ~43 ~12 ~38 glowstone 0  
fill ~43 ~11 ~44 ~43 ~12 ~44 glowstone 0  
fill ~43 ~11 ~49 ~43 ~12 ~49 glowstone 0  
fill ~43 ~11 ~55 ~43 ~12 ~55 glowstone 0  
fill ~43 ~11 ~61 ~43 ~12 ~61 glowstone 0  
fill ~43 ~11 ~66 ~44 ~11 ~66 wool 7  
fill ~44 ~11 ~11 ~44 ~11 ~66 wool 7 
setblock ~44 ~11 ~71 wool 13 
setblock ~45 ~11 ~10 wool 13 
setblock ~45 ~11 ~20 wool 7 
setblock ~45 ~11 ~28 wool 7 
setblock ~45 ~11 ~33 wool 7 
setblock ~45 ~11 ~38 wool 7 
setblock ~45 ~11 ~44 wool 7 
setblock ~45 ~11 ~49 wool 7 
setblock ~45 ~11 ~55 wool 7 
setblock ~45 ~11 ~61 wool 7  
fill ~45 ~11 ~62 ~45 ~11 ~70 wool 13  
fill ~46 ~11 ~16 ~46 ~11 ~61 wool 13 
setblock ~46 ~11 ~62 double_stone_slab 0  
fill ~46 ~11 ~63 ~46 ~11 ~65 stone_slab 0 
setblock ~51 ~11 ~21 wool 15 
setblock ~57 ~11 ~21 wool 15 
setblock ~59 ~11 ~22 wool 15 
setblock ~65 ~11 ~22 wool 15  
fill ~30 ~12 ~68 ~54 ~12 ~68 wool 13  
fill ~30 ~12 ~69 ~54 ~12 ~69 wool 13  
fill ~31 ~12 ~67 ~41 ~12 ~67 wool 13  
fill ~34 ~12 ~66 ~50 ~12 ~66 wool 13 
setblock ~34 ~12 ~70 wool 13  
fill ~35 ~12 ~70 ~38 ~12 ~70 wool 15  
fill ~39 ~12 ~11 ~40 ~12 ~11 wool 13  
fill ~39 ~12 ~12 ~39 ~12 ~61 wool 13 
setblock ~39 ~12 ~62 double_stone_slab 0  
fill ~39 ~12 ~63 ~39 ~12 ~65 stone_slab 0  
fill ~40 ~12 ~9 ~44 ~12 ~9 wool 13  
fill ~40 ~12 ~10 ~44 ~12 ~10 wool 13  
fill ~40 ~12 ~12 ~40 ~12 ~61 wool 7  
fill ~40 ~12 ~62 ~44 ~12 ~62 wool 13  
fill ~40 ~12 ~63 ~44 ~12 ~63 wool 13  
fill ~40 ~12 ~64 ~44 ~12 ~64 wool 13  
fill ~40 ~12 ~65 ~44 ~12 ~65 wool 13  
fill ~40 ~12 ~70 ~45 ~12 ~70 wool 13  
fill ~41 ~12 ~8 ~43 ~12 ~8 wool 13  
fill ~41 ~12 ~14 ~44 ~12 ~14 wool 7  
fill ~41 ~12 ~15 ~44 ~12 ~15 wool 7  
fill ~41 ~12 ~16 ~44 ~12 ~16 wool 7  
fill ~41 ~12 ~17 ~41 ~12 ~19 wool 7  
fill ~41 ~12 ~21 ~41 ~12 ~27 wool 7  
fill ~41 ~12 ~29 ~44 ~12 ~29 wool 7  
fill ~41 ~12 ~30 ~44 ~12 ~30 wool 7  
fill ~41 ~12 ~31 ~44 ~12 ~31 wool 7  
fill ~41 ~12 ~32 ~44 ~12 ~32 wool 7  
fill ~41 ~12 ~33 ~41 ~12 ~37 wool 7  
fill ~41 ~12 ~39 ~44 ~12 ~39 wool 7  
fill ~41 ~12 ~40 ~44 ~12 ~40 wool 7  
fill ~41 ~12 ~41 ~44 ~12 ~41 wool 7  
fill ~41 ~12 ~42 ~44 ~12 ~42 wool 7  
fill ~41 ~12 ~43 ~44 ~12 ~43 wool 7  
fill ~41 ~12 ~45 ~44 ~12 ~45 wool 7  
fill ~41 ~12 ~46 ~44 ~12 ~46 wool 7  
fill ~41 ~12 ~47 ~44 ~12 ~47 wool 7  
fill ~41 ~12 ~48 ~44 ~12 ~48 wool 7  
fill ~41 ~12 ~50 ~44 ~12 ~50 wool 7  
fill ~41 ~12 ~51 ~44 ~12 ~51 wool 7  
fill ~41 ~12 ~52 ~44 ~12 ~52 wool 7  
fill ~41 ~12 ~53 ~44 ~12 ~53 wool 7  
fill ~41 ~12 ~54 ~44 ~12 ~54 wool 7  
fill ~41 ~12 ~56 ~44 ~12 ~56 wool 7  
fill ~41 ~12 ~57 ~44 ~12 ~57 wool 7  
fill ~41 ~12 ~58 ~44 ~12 ~58 wool 7  
fill ~41 ~12 ~59 ~44 ~12 ~59 wool 7  
fill ~41 ~12 ~60 ~44 ~12 ~60 wool 7  
fill ~41 ~12 ~71 ~43 ~12 ~71 wool 13 
setblock ~42 ~12 ~7 wool 13  
fill ~42 ~12 ~24 ~44 ~12 ~24 wool 7  
fill ~42 ~12 ~25 ~44 ~12 ~25 wool 7  
fill ~42 ~12 ~26 ~44 ~12 ~26 wool 7  
fill ~42 ~12 ~27 ~44 ~12 ~27 wool 7  
fill ~42 ~12 ~34 ~44 ~12 ~34 wool 7  
fill ~42 ~12 ~35 ~44 ~12 ~35 wool 7  
fill ~42 ~12 ~36 ~44 ~12 ~36 wool 7  
fill ~42 ~12 ~37 ~44 ~12 ~37 wool 7 
setblock ~42 ~12 ~67 glowstone 0 
setblock ~42 ~12 ~72 stone_slab 0  
fill ~43 ~12 ~17 ~44 ~12 ~17 wool 7  
fill ~43 ~12 ~18 ~44 ~12 ~18 wool 7  
fill ~43 ~12 ~19 ~44 ~12 ~19 wool 7  
fill ~43 ~12 ~21 ~44 ~12 ~21 wool 7  
fill ~43 ~12 ~22 ~44 ~12 ~22 wool 7  
fill ~43 ~12 ~23 ~44 ~12 ~23 wool 7  
fill ~43 ~12 ~33 ~44 ~12 ~33 wool 7  
fill ~43 ~12 ~67 ~53 ~12 ~67 wool 13  
fill ~44 ~12 ~11 ~45 ~12 ~11 wool 13  
fill ~44 ~12 ~12 ~44 ~12 ~61 wool 7  
fill ~45 ~12 ~12 ~45 ~12 ~61 wool 13 
setblock ~45 ~12 ~62 double_stone_slab 0  
fill ~45 ~12 ~63 ~45 ~12 ~65 stone_slab 0  
fill ~46 ~12 ~70 ~49 ~12 ~70 wool 15 
setblock ~50 ~12 ~70 wool 13  
fill ~40 ~13 ~12 ~44 ~13 ~12 wool 13  
fill ~40 ~13 ~13 ~44 ~13 ~13 wool 13  
fill ~40 ~13 ~14 ~40 ~14 ~14 wool 13  
fill ~40 ~13 ~15 ~40 ~13 ~61 wool 13  
fill ~40 ~13 ~62 ~41 ~13 ~62 double_stone_slab 0  
fill ~40 ~13 ~63 ~41 ~13 ~63 stone_slab 0  
fill ~40 ~13 ~64 ~41 ~13 ~64 stone_slab 0  
fill ~40 ~13 ~65 ~41 ~13 ~65 stone_slab 0  
fill ~40 ~13 ~66 ~41 ~13 ~66 stone_slab 0  
fill ~40 ~13 ~67 ~40 ~13 ~70 stone_slab 0  
fill ~41 ~13 ~10 ~43 ~13 ~10 wool 13  
fill ~41 ~13 ~11 ~43 ~13 ~11 wool 13 
setblock ~41 ~13 ~14 lever 3 
setblock ~41 ~13 ~15 oak_stairs 2  
fill ~41 ~13 ~18 ~44 ~13 ~18 wool 13  
fill ~41 ~13 ~19 ~44 ~13 ~19 wool 13  
fill ~41 ~13 ~20 ~44 ~13 ~20 wool 13  
fill ~41 ~13 ~21 ~44 ~13 ~21 wool 13  
fill ~41 ~13 ~22 ~41 ~15 ~22 wool 13  
fill ~41 ~13 ~23 ~41 ~13 ~61 wool 13  
fill ~41 ~13 ~67 ~41 ~13 ~69 double_stone_slab 0  
fill ~41 ~13 ~70 ~41 ~13 ~71 stone_slab 0 
setblock ~42 ~13 ~9 wool 13 
setblock ~42 ~13 ~14 stone_button 3 
setblock ~42 ~13 ~17 trapdoor 0  
fill ~42 ~13 ~24 ~44 ~13 ~24 wool 13  
fill ~42 ~13 ~25 ~44 ~13 ~25 wool 13  
fill ~42 ~13 ~26 ~44 ~13 ~26 wool 13  
fill ~42 ~13 ~27 ~44 ~13 ~27 wool 13  
fill ~42 ~13 ~28 ~44 ~13 ~28 wool 13  
fill ~42 ~13 ~29 ~44 ~13 ~29 wool 13  
fill ~42 ~13 ~30 ~44 ~13 ~30 wool 13  
fill ~42 ~13 ~31 ~44 ~13 ~31 wool 13  
fill ~42 ~13 ~32 ~44 ~13 ~32 wool 13  
fill ~42 ~13 ~33 ~44 ~13 ~33 wool 13  
fill ~42 ~13 ~34 ~44 ~13 ~34 wool 13  
fill ~42 ~13 ~35 ~44 ~13 ~35 wool 13  
fill ~42 ~13 ~36 ~44 ~13 ~36 wool 13  
fill ~42 ~13 ~37 ~44 ~13 ~37 wool 13  
fill ~42 ~13 ~38 ~44 ~13 ~38 wool 13  
fill ~42 ~13 ~39 ~44 ~13 ~39 wool 13  
fill ~42 ~13 ~40 ~44 ~13 ~40 wool 13  
fill ~42 ~13 ~41 ~44 ~13 ~41 wool 13  
fill ~42 ~13 ~42 ~44 ~13 ~42 wool 13  
fill ~42 ~13 ~43 ~44 ~13 ~43 wool 13  
fill ~42 ~13 ~44 ~44 ~13 ~44 wool 13  
fill ~42 ~13 ~45 ~44 ~13 ~45 wool 13  
fill ~42 ~13 ~46 ~44 ~13 ~46 wool 13  
fill ~42 ~13 ~47 ~44 ~13 ~47 wool 13  
fill ~42 ~13 ~48 ~44 ~13 ~48 wool 13  
fill ~42 ~13 ~49 ~44 ~13 ~49 wool 13  
fill ~42 ~13 ~50 ~44 ~13 ~50 wool 13  
fill ~42 ~13 ~51 ~44 ~13 ~51 wool 13  
fill ~42 ~13 ~52 ~44 ~13 ~52 wool 13  
fill ~42 ~13 ~53 ~44 ~13 ~53 wool 13  
fill ~42 ~13 ~54 ~44 ~13 ~54 wool 13  
fill ~42 ~13 ~55 ~44 ~13 ~55 wool 13  
fill ~42 ~13 ~56 ~44 ~13 ~56 wool 13  
fill ~42 ~13 ~57 ~44 ~13 ~57 wool 13  
fill ~42 ~13 ~58 ~44 ~13 ~58 wool 13  
fill ~42 ~13 ~59 ~44 ~13 ~59 wool 13  
fill ~42 ~13 ~60 ~44 ~13 ~60 wool 13  
fill ~42 ~13 ~61 ~44 ~13 ~61 wool 13  
fill ~42 ~13 ~62 ~42 ~14 ~62 wool 13  
fill ~42 ~13 ~63 ~42 ~15 ~63 wool 13  
fill ~42 ~13 ~64 ~42 ~15 ~64 wool 13  
fill ~42 ~13 ~65 ~42 ~16 ~65 wool 13  
fill ~42 ~13 ~66 ~42 ~16 ~66 wool 13  
fill ~42 ~13 ~67 ~42 ~17 ~67 wool 13  
fill ~42 ~13 ~68 ~42 ~17 ~68 wool 13  
fill ~42 ~13 ~69 ~42 ~18 ~69 wool 13  
fill ~42 ~13 ~70 ~42 ~18 ~70 wool 13  
fill ~42 ~13 ~71 ~42 ~13 ~24 wool 13 
setblock ~43 ~13 ~14 lever 3 
setblock ~43 ~13 ~15 oak_stairs 2  
fill ~43 ~13 ~22 ~44 ~13 ~22 wool 13  
fill ~43 ~13 ~23 ~44 ~13 ~23 wool 13  
fill ~43 ~13 ~62 ~44 ~13 ~62 double_stone_slab 0  
fill ~43 ~13 ~63 ~44 ~13 ~63 stone_slab 0  
fill ~43 ~13 ~64 ~44 ~13 ~64 stone_slab 0  
fill ~43 ~13 ~65 ~44 ~13 ~65 stone_slab 0  
fill ~43 ~13 ~66 ~44 ~13 ~66 stone_slab 0  
fill ~43 ~13 ~67 ~43 ~13 ~69 double_stone_slab 0  
fill ~43 ~13 ~70 ~44 ~13 ~70 stone_slab 0  
fill ~43 ~13 ~71 ~43 ~13 ~70 stone_slab 0  
fill ~44 ~13 ~14 ~44 ~14 ~14 wool 13  
fill ~44 ~13 ~15 ~44 ~13 ~61 wool 13  
fill ~44 ~13 ~67 ~44 ~13 ~70 stone_slab 0  
fill ~40 ~14 ~15 ~40 ~14 ~17 glass 0  
fill ~40 ~14 ~18 ~41 ~14 ~18 wool 13  
fill ~40 ~14 ~19 ~40 ~14 ~29 wool 13  
fill ~41 ~14 ~13 ~43 ~14 ~13 glass 0 
setblock ~41 ~14 ~25 stone_button 4  
fill ~41 ~14 ~26 ~44 ~14 ~26 wool 13  
fill ~41 ~14 ~27 ~44 ~14 ~27 wool 13  
fill ~41 ~14 ~28 ~44 ~14 ~28 wool 13  
fill ~41 ~14 ~29 ~44 ~14 ~29 wool 13  
fill ~41 ~14 ~30 ~43 ~14 ~30 wool 13  
fill ~41 ~14 ~31 ~43 ~14 ~31 wool 13  
fill ~41 ~14 ~32 ~43 ~14 ~32 wool 13  
fill ~41 ~14 ~33 ~43 ~14 ~33 wool 13  
fill ~41 ~14 ~34 ~43 ~14 ~34 wool 13  
fill ~41 ~14 ~35 ~43 ~14 ~35 wool 13  
fill ~41 ~14 ~36 ~43 ~14 ~36 wool 13  
fill ~41 ~14 ~37 ~43 ~14 ~37 wool 13  
fill ~41 ~14 ~38 ~43 ~14 ~38 wool 13  
fill ~41 ~14 ~39 ~43 ~14 ~39 wool 13  
fill ~41 ~14 ~40 ~43 ~14 ~40 wool 13  
fill ~41 ~14 ~41 ~43 ~14 ~41 wool 13  
fill ~41 ~14 ~42 ~43 ~14 ~42 wool 13  
fill ~41 ~14 ~43 ~43 ~14 ~43 wool 13  
fill ~41 ~14 ~44 ~43 ~14 ~44 wool 13  
fill ~41 ~14 ~45 ~43 ~14 ~45 wool 13 
setblock ~42 ~14 ~17 trapdoor 4 
setblock ~42 ~14 ~18 glowstone 0 
setblock ~42 ~14 ~22 glowstone 0 
setblock ~42 ~14 ~23 trapdoor 1 
setblock ~42 ~14 ~25 oak_stairs 3  
fill ~42 ~14 ~46 ~42 ~14 ~48 wool 13  
fill ~42 ~14 ~49 ~42 ~14 ~54 stone_slab 0  
fill ~42 ~14 ~55 ~42 ~14 ~60 double_stone_slab 0 
setblock ~42 ~14 ~61 wool 13  
fill ~42 ~14 ~71 ~42 ~18 ~71 wool 15  
fill ~43 ~14 ~18 ~44 ~14 ~18 wool 13  
fill ~43 ~14 ~22 ~44 ~14 ~22 wool 13 
setblock ~43 ~14 ~25 stone_button 4  
fill ~44 ~14 ~15 ~44 ~14 ~17 glass 0  
fill ~44 ~14 ~19 ~44 ~14 ~29 wool 13 
setblock ~40 ~15 ~14 double_stone_slab 0  
fill ~40 ~15 ~15 ~40 ~15 ~17 stone_slab 0 
setblock ~40 ~15 ~18 double_stone_slab 0  
fill ~40 ~15 ~19 ~40 ~15 ~22 stone_slab 0  
fill ~40 ~15 ~23 ~40 ~15 ~25 glass 0 
setblock ~41 ~15 ~13 stone_slab 0  
fill ~41 ~15 ~14 ~43 ~15 ~14 wool 13  
fill ~41 ~15 ~15 ~41 ~15 ~17 glass 0  
fill ~41 ~15 ~18 ~43 ~15 ~18 wool 13  
fill ~41 ~15 ~19 ~43 ~15 ~19 wool 13  
fill ~41 ~15 ~20 ~43 ~15 ~20 wool 13  
fill ~41 ~15 ~21 ~43 ~15 ~21 wool 13 
setblock ~41 ~15 ~26 dispenser 3 
setblock ~42 ~15 ~13 wool 13  
fill ~42 ~15 ~15 ~42 ~15 ~22 wool 13  
fill ~42 ~15 ~26 ~42 ~16 ~26 glass 0  
fill ~42 ~15 ~27 ~42 ~15 ~26 glass 0 
setblock ~42 ~15 ~60 stone_slab 0  
fill ~42 ~15 ~61 ~42 ~15 ~62 wool 15 
setblock ~43 ~15 ~13 stone_slab 0  
fill ~43 ~15 ~15 ~43 ~15 ~17 glass 0  
fill ~43 ~15 ~22 ~43 ~13 ~22 wool 13 
setblock ~43 ~15 ~26 dispenser 3 
setblock ~44 ~15 ~14 double_stone_slab 0  
fill ~44 ~15 ~15 ~44 ~15 ~17 stone_slab 0 
setblock ~44 ~15 ~18 double_stone_slab 0  
fill ~44 ~15 ~19 ~44 ~15 ~22 stone_slab 0  
fill ~44 ~15 ~23 ~44 ~15 ~25 glass 0  
fill ~41 ~16 ~14 ~43 ~16 ~14 stone_slab 0  
fill ~41 ~16 ~18 ~43 ~16 ~18 stone_slab 0 
setblock ~41 ~16 ~22 stone_slab 0  
fill ~41 ~16 ~23 ~43 ~16 ~23 glass 0  
fill ~41 ~16 ~24 ~41 ~16 ~25 glass 0 
setblock ~42 ~16 ~13 stone_slab 0  
fill ~42 ~16 ~15 ~42 ~16 ~20 stone_slab 0 
setblock ~42 ~16 ~21 double_stone_slab 0 
setblock ~42 ~16 ~22 glass 0 
setblock ~42 ~16 ~62 stone_slab 0  
fill ~42 ~16 ~63 ~42 ~16 ~64 wool 15 
setblock ~43 ~16 ~22 stone_slab 0  
fill ~43 ~16 ~24 ~43 ~16 ~25 glass 0  
fill ~42 ~17 ~22 ~42 ~17 ~26 stone_slab 0 
setblock ~42 ~17 ~64 stone_slab 0  
fill ~42 ~17 ~65 ~42 ~17 ~66 wool 15 
setblock ~42 ~18 ~66 stone_slab 0  
fill ~42 ~18 ~67 ~42 ~18 ~68 wool 15 
setblock ~42 ~19 ~68 stone_slab 0  
fill ~42 ~19 ~69 ~42 ~19 ~70 wool 15 
setblock ~42 ~19 ~71 wool 13 
setblock ~42 ~20 ~70 stone_slab 0 
setblock ~42 ~20 ~71 wool 15 
setblock ~42 ~21 ~71 stone_slab 0  
setblock ~41 ~10 ~69 wall_sign 4  
setblock ~43 ~10 ~69 wall_sign 5    