setblock ~13 ~0 ~36 chest 3  
setblock ~14 ~0 ~36 chest 3  
setblock ~12 ~1 ~36 chest 3  
setblock ~13 ~1 ~36 chest 3  
setblock ~11 ~2 ~36 chest 3  
setblock ~12 ~2 ~36 chest 3  
fill ~1 ~-1 ~1 ~4 ~-1 ~1 grass 0  
fill ~1 ~-1 ~2 ~4 ~-1 ~2 grass 0  
fill ~1 ~-1 ~3 ~4 ~-1 ~3 grass 0  
fill ~1 ~-1 ~4 ~4 ~-1 ~4 grass 0  
fill ~1 ~-1 ~5 ~4 ~-1 ~5 grass 0  
fill ~1 ~-1 ~6 ~4 ~-1 ~6 grass 0  
fill ~1 ~-1 ~7 ~4 ~-1 ~7 grass 0  
fill ~1 ~-1 ~8 ~4 ~-1 ~8 grass 0  
fill ~1 ~-1 ~9 ~4 ~-1 ~9 grass 0  
fill ~1 ~-1 ~10 ~4 ~-1 ~10 grass 0  
fill ~1 ~-1 ~11 ~6 ~-1 ~11 stone 0  
fill ~1 ~-1 ~12 ~6 ~-1 ~12 stone 0  
fill ~1 ~-1 ~13 ~2 ~-1 ~13 stone 0  
fill ~1 ~-1 ~14 ~2 ~-1 ~14 stone 0  
fill ~1 ~-1 ~15 ~2 ~-1 ~15 stone 0  
fill ~1 ~-1 ~16 ~2 ~-1 ~16 stone 0  
fill ~1 ~-1 ~17 ~5 ~-1 ~17 stone 0  
fill ~1 ~-1 ~18 ~5 ~-1 ~18 stone 0  
fill ~1 ~-1 ~19 ~2 ~-1 ~19 stone 0  
fill ~1 ~-1 ~20 ~6 ~-1 ~20 stone 0  
fill ~1 ~-1 ~21 ~6 ~-1 ~21 stone 0  
fill ~1 ~-1 ~22 ~2 ~-1 ~22 stone 0  
fill ~1 ~-1 ~23 ~5 ~-1 ~23 stone 0  
fill ~1 ~-1 ~24 ~5 ~-1 ~24 stone 0  
fill ~1 ~-1 ~25 ~2 ~-1 ~25 stone 0  
fill ~1 ~-1 ~26 ~2 ~-1 ~26 stone 0  
fill ~1 ~-1 ~27 ~2 ~-1 ~27 stone 0  
fill ~1 ~-1 ~28 ~2 ~-1 ~28 stone 0  
fill ~1 ~-1 ~29 ~6 ~-1 ~29 stone 0  
fill ~1 ~-1 ~30 ~6 ~-1 ~30 stone 0  
fill ~1 ~-1 ~31 ~4 ~-1 ~31 grass 0  
fill ~1 ~-1 ~32 ~4 ~-1 ~32 grass 0  
fill ~1 ~-1 ~33 ~4 ~-1 ~33 grass 0  
fill ~1 ~-1 ~34 ~4 ~-1 ~34 grass 0  
fill ~1 ~-1 ~35 ~4 ~-1 ~35 grass 0  
fill ~1 ~-1 ~36 ~4 ~-1 ~36 grass 0  
fill ~1 ~-1 ~37 ~4 ~-1 ~37 grass 0  
fill ~1 ~-1 ~38 ~4 ~-1 ~38 grass 0  
fill ~1 ~-1 ~39 ~4 ~-1 ~39 grass 0  
fill ~1 ~-1 ~40 ~4 ~-1 ~40 grass 0  
fill ~3 ~-1 ~13 ~6 ~-1 ~13 dirt 0  
fill ~3 ~-1 ~14 ~3 ~-1 ~16 dirt 0 
setblock ~3 ~-1 ~19 dirt 0 
setblock ~3 ~-1 ~22 dirt 0  
fill ~3 ~-1 ~25 ~3 ~-1 ~28 dirt 0  
fill ~4 ~-1 ~14 ~5 ~-1 ~14 stone 0  
fill ~4 ~-1 ~15 ~5 ~-1 ~15 stone 0  
fill ~4 ~-1 ~16 ~5 ~-1 ~16 stone 0  
fill ~4 ~-1 ~19 ~5 ~-1 ~19 stone 0  
fill ~4 ~-1 ~22 ~5 ~-1 ~22 stone 0  
fill ~4 ~-1 ~25 ~5 ~-1 ~25 stone 0  
fill ~4 ~-1 ~26 ~5 ~-1 ~26 stone 0  
fill ~4 ~-1 ~27 ~5 ~-1 ~27 stone 0  
fill ~4 ~-1 ~28 ~6 ~-1 ~28 dirt 0  
fill ~5 ~-1 ~1 ~24 ~-1 ~1 stone 0  
fill ~5 ~-1 ~2 ~24 ~-1 ~2 stone 0  
fill ~5 ~-1 ~3 ~6 ~-1 ~3 stone 0  
fill ~5 ~-1 ~4 ~6 ~-1 ~4 stone 0  
fill ~5 ~-1 ~5 ~6 ~-1 ~5 stone 0  
fill ~5 ~-1 ~6 ~6 ~-1 ~6 stone 0  
fill ~5 ~-1 ~7 ~6 ~-1 ~7 stone 0  
fill ~5 ~-1 ~8 ~6 ~-1 ~8 stone 0  
fill ~5 ~-1 ~9 ~6 ~-1 ~9 stone 0  
fill ~5 ~-1 ~10 ~6 ~-1 ~10 stone 0  
fill ~5 ~-1 ~31 ~6 ~-1 ~31 stone 0  
fill ~5 ~-1 ~32 ~6 ~-1 ~32 stone 0  
fill ~5 ~-1 ~33 ~6 ~-1 ~33 stone 0  
fill ~5 ~-1 ~34 ~6 ~-1 ~34 stone 0  
fill ~5 ~-1 ~35 ~6 ~-1 ~35 stone 0  
fill ~5 ~-1 ~36 ~6 ~-1 ~36 stone 0  
fill ~5 ~-1 ~37 ~6 ~-1 ~37 stone 0  
fill ~5 ~-1 ~38 ~6 ~-1 ~38 stone 0  
fill ~5 ~-1 ~39 ~24 ~-1 ~39 stone 0  
fill ~5 ~-1 ~40 ~24 ~-1 ~40 stone 0  
fill ~6 ~-1 ~14 ~6 ~-1 ~19 dirt 0  
fill ~6 ~-1 ~22 ~6 ~-1 ~28 dirt 0  
fill ~7 ~-1 ~3 ~22 ~-1 ~3 dirt 0  
fill ~7 ~-1 ~4 ~22 ~-1 ~4 stained_hardened_clay 9  
fill ~7 ~-1 ~5 ~9 ~-1 ~5 stained_hardened_clay 9  
fill ~7 ~-1 ~6 ~9 ~-1 ~6 stained_hardened_clay 9  
fill ~7 ~-1 ~7 ~9 ~-1 ~7 stained_hardened_clay 9  
fill ~7 ~-1 ~8 ~9 ~-1 ~8 stained_hardened_clay 9  
fill ~7 ~-1 ~9 ~9 ~-1 ~9 stained_hardened_clay 9  
fill ~7 ~-1 ~10 ~9 ~-1 ~10 stained_hardened_clay 9  
fill ~7 ~-1 ~11 ~9 ~-1 ~11 stained_hardened_clay 9  
fill ~7 ~-1 ~12 ~9 ~-1 ~12 stained_hardened_clay 9  
fill ~7 ~-1 ~13 ~22 ~-1 ~13 stained_hardened_clay 9  
fill ~7 ~-1 ~14 ~22 ~-1 ~14 stained_hardened_clay 9  
fill ~7 ~-1 ~15 ~22 ~-1 ~15 stained_hardened_clay 9  
fill ~7 ~-1 ~16 ~22 ~-1 ~16 stained_hardened_clay 9  
fill ~7 ~-1 ~17 ~22 ~-1 ~17 stained_hardened_clay 9  
fill ~7 ~-1 ~18 ~22 ~-1 ~18 stained_hardened_clay 9  
fill ~7 ~-1 ~19 ~22 ~-1 ~19 stained_hardened_clay 9  
fill ~7 ~-1 ~20 ~22 ~-1 ~20 stained_hardened_clay 9  
fill ~7 ~-1 ~21 ~22 ~-1 ~21 stained_hardened_clay 9  
fill ~7 ~-1 ~22 ~22 ~-1 ~22 stained_hardened_clay 9  
fill ~7 ~-1 ~23 ~22 ~-1 ~23 stained_hardened_clay 9  
fill ~7 ~-1 ~24 ~22 ~-1 ~24 stained_hardened_clay 9  
fill ~7 ~-1 ~25 ~22 ~-1 ~25 stained_hardened_clay 9  
fill ~7 ~-1 ~26 ~22 ~-1 ~26 stained_hardened_clay 9  
fill ~7 ~-1 ~27 ~22 ~-1 ~27 stained_hardened_clay 9  
fill ~7 ~-1 ~28 ~22 ~-1 ~28 stained_hardened_clay 9  
fill ~7 ~-1 ~29 ~22 ~-1 ~29 stained_hardened_clay 9  
fill ~7 ~-1 ~30 ~22 ~-1 ~30 stained_hardened_clay 9  
fill ~7 ~-1 ~31 ~22 ~-1 ~31 stained_hardened_clay 9  
fill ~7 ~-1 ~32 ~22 ~-1 ~32 stained_hardened_clay 9  
fill ~7 ~-1 ~33 ~22 ~-1 ~33 stained_hardened_clay 9  
fill ~7 ~-1 ~34 ~22 ~-1 ~34 stained_hardened_clay 9  
fill ~7 ~-1 ~35 ~22 ~-1 ~35 stained_hardened_clay 9  
fill ~7 ~-1 ~36 ~22 ~-1 ~36 stained_hardened_clay 9  
fill ~7 ~-1 ~37 ~22 ~-1 ~37 stained_hardened_clay 9  
fill ~7 ~-1 ~38 ~22 ~-1 ~38 dirt 0  
fill ~10 ~-1 ~5 ~18 ~-1 ~5 wool 8  
fill ~10 ~-1 ~6 ~18 ~-1 ~6 wool 8  
fill ~10 ~-1 ~7 ~18 ~-1 ~7 wool 8  
fill ~10 ~-1 ~8 ~18 ~-1 ~8 wool 8  
fill ~10 ~-1 ~9 ~18 ~-1 ~9 wool 8  
fill ~10 ~-1 ~10 ~18 ~-1 ~10 wool 8  
fill ~10 ~-1 ~11 ~18 ~-1 ~11 wool 8  
fill ~10 ~-1 ~12 ~18 ~-1 ~12 wool 8  
fill ~19 ~-1 ~5 ~22 ~-1 ~5 stained_hardened_clay 9  
fill ~19 ~-1 ~6 ~22 ~-1 ~6 stained_hardened_clay 9  
fill ~19 ~-1 ~7 ~22 ~-1 ~7 stained_hardened_clay 9  
fill ~19 ~-1 ~8 ~22 ~-1 ~8 stained_hardened_clay 9  
fill ~19 ~-1 ~9 ~22 ~-1 ~9 stained_hardened_clay 9  
fill ~19 ~-1 ~10 ~22 ~-1 ~10 stained_hardened_clay 9  
fill ~19 ~-1 ~11 ~22 ~-1 ~11 stained_hardened_clay 9  
fill ~19 ~-1 ~12 ~22 ~-1 ~12 stained_hardened_clay 9  
fill ~23 ~-1 ~3 ~24 ~-1 ~3 stone 0  
fill ~23 ~-1 ~4 ~24 ~-1 ~4 stone 0  
fill ~23 ~-1 ~5 ~24 ~-1 ~5 stone 0  
fill ~23 ~-1 ~6 ~24 ~-1 ~6 stone 0  
fill ~23 ~-1 ~7 ~24 ~-1 ~7 stone 0  
fill ~23 ~-1 ~8 ~24 ~-1 ~8 stone 0  
fill ~23 ~-1 ~9 ~24 ~-1 ~9 stone 0  
fill ~23 ~-1 ~10 ~24 ~-1 ~10 stone 0  
fill ~23 ~-1 ~11 ~28 ~-1 ~11 stone 0  
fill ~23 ~-1 ~12 ~28 ~-1 ~12 stone 0  
fill ~23 ~-1 ~13 ~26 ~-1 ~13 dirt 0  
fill ~23 ~-1 ~14 ~23 ~-1 ~19 dirt 0  
fill ~23 ~-1 ~20 ~48 ~-1 ~20 stone 0  
fill ~23 ~-1 ~21 ~48 ~-1 ~21 stone 0  
fill ~23 ~-1 ~22 ~23 ~-1 ~28 dirt 0  
fill ~23 ~-1 ~29 ~28 ~-1 ~29 stone 0  
fill ~23 ~-1 ~30 ~28 ~-1 ~30 stone 0  
fill ~23 ~-1 ~31 ~24 ~-1 ~31 stone 0  
fill ~23 ~-1 ~32 ~24 ~-1 ~32 stone 0  
fill ~23 ~-1 ~33 ~24 ~-1 ~33 stone 0  
fill ~23 ~-1 ~34 ~24 ~-1 ~34 stone 0  
fill ~23 ~-1 ~35 ~24 ~-1 ~35 stone 0  
fill ~23 ~-1 ~36 ~24 ~-1 ~36 stone 0  
fill ~23 ~-1 ~37 ~24 ~-1 ~37 stone 0  
fill ~23 ~-1 ~38 ~24 ~-1 ~38 stone 0  
fill ~24 ~-1 ~14 ~25 ~-1 ~14 stone 0  
fill ~24 ~-1 ~15 ~25 ~-1 ~15 stone 0  
fill ~24 ~-1 ~16 ~25 ~-1 ~16 stone 0  
fill ~24 ~-1 ~17 ~28 ~-1 ~17 stone 0  
fill ~24 ~-1 ~18 ~28 ~-1 ~18 stone 0  
fill ~24 ~-1 ~19 ~25 ~-1 ~19 stone 0  
fill ~24 ~-1 ~22 ~25 ~-1 ~22 stone 0  
fill ~24 ~-1 ~23 ~28 ~-1 ~23 stone 0  
fill ~24 ~-1 ~24 ~28 ~-1 ~24 stone 0  
fill ~24 ~-1 ~25 ~25 ~-1 ~25 stone 0  
fill ~24 ~-1 ~26 ~25 ~-1 ~26 stone 0  
fill ~24 ~-1 ~27 ~25 ~-1 ~27 stone 0  
fill ~24 ~-1 ~28 ~26 ~-1 ~28 dirt 0  
fill ~25 ~-1 ~1 ~48 ~-1 ~1 grass 0  
fill ~25 ~-1 ~2 ~48 ~-1 ~2 grass 0  
fill ~25 ~-1 ~3 ~48 ~-1 ~3 grass 0  
fill ~25 ~-1 ~4 ~48 ~-1 ~4 grass 0  
fill ~25 ~-1 ~5 ~48 ~-1 ~5 grass 0  
fill ~25 ~-1 ~6 ~48 ~-1 ~6 grass 0  
fill ~25 ~-1 ~7 ~48 ~-1 ~7 grass 0  
fill ~25 ~-1 ~8 ~48 ~-1 ~8 grass 0  
fill ~25 ~-1 ~9 ~26 ~-1 ~9 grass 0  
fill ~25 ~-1 ~10 ~26 ~-1 ~10 grass 0  
fill ~25 ~-1 ~31 ~26 ~-1 ~31 grass 0  
fill ~25 ~-1 ~32 ~26 ~-1 ~32 grass 0  
fill ~25 ~-1 ~33 ~48 ~-1 ~33 grass 0  
fill ~25 ~-1 ~34 ~48 ~-1 ~34 grass 0  
fill ~25 ~-1 ~35 ~48 ~-1 ~35 grass 0  
fill ~25 ~-1 ~36 ~48 ~-1 ~36 grass 0  
fill ~25 ~-1 ~37 ~48 ~-1 ~37 grass 0  
fill ~25 ~-1 ~38 ~48 ~-1 ~38 grass 0  
fill ~25 ~-1 ~39 ~48 ~-1 ~39 grass 0  
fill ~25 ~-1 ~40 ~48 ~-1 ~40 grass 0  
fill ~26 ~-1 ~14 ~26 ~-1 ~16 dirt 0 
setblock ~26 ~-1 ~19 dirt 0 
setblock ~26 ~-1 ~22 dirt 0  
fill ~26 ~-1 ~25 ~26 ~-1 ~28 dirt 0  
fill ~27 ~-1 ~9 ~48 ~-1 ~9 stone 0  
fill ~27 ~-1 ~10 ~48 ~-1 ~10 stone 0  
fill ~27 ~-1 ~13 ~28 ~-1 ~13 stone 0  
fill ~27 ~-1 ~14 ~28 ~-1 ~14 stone 0  
fill ~27 ~-1 ~15 ~28 ~-1 ~15 stone 0  
fill ~27 ~-1 ~16 ~28 ~-1 ~16 stone 0  
fill ~27 ~-1 ~19 ~28 ~-1 ~19 stone 0  
fill ~27 ~-1 ~22 ~28 ~-1 ~22 stone 0  
fill ~27 ~-1 ~25 ~28 ~-1 ~25 stone 0  
fill ~27 ~-1 ~26 ~28 ~-1 ~26 stone 0  
fill ~27 ~-1 ~27 ~28 ~-1 ~27 stone 0  
fill ~27 ~-1 ~28 ~28 ~-1 ~28 stone 0  
fill ~27 ~-1 ~31 ~48 ~-1 ~31 stone 0  
fill ~27 ~-1 ~32 ~48 ~-1 ~32 stone 0  
fill ~29 ~-1 ~11 ~46 ~-1 ~11 grass 0  
fill ~29 ~-1 ~12 ~30 ~-1 ~12 grass 0  
fill ~29 ~-1 ~13 ~29 ~-1 ~19 grass 0  
fill ~29 ~-1 ~22 ~46 ~-1 ~22 grass 0  
fill ~29 ~-1 ~23 ~30 ~-1 ~23 grass 0  
fill ~29 ~-1 ~24 ~29 ~-1 ~30 grass 0  
fill ~30 ~-1 ~13 ~31 ~-1 ~13 dirt 1  
fill ~30 ~-1 ~14 ~30 ~-1 ~17 dirt 1  
fill ~30 ~-1 ~18 ~30 ~-1 ~19 grass 0  
fill ~30 ~-1 ~24 ~31 ~-1 ~24 dirt 1  
fill ~30 ~-1 ~25 ~30 ~-1 ~28 dirt 1  
fill ~30 ~-1 ~29 ~30 ~-1 ~30 grass 0  
fill ~31 ~-1 ~12 ~44 ~-1 ~12 dirt 1  
fill ~31 ~-1 ~14 ~44 ~-1 ~14 grass 0  
fill ~31 ~-1 ~15 ~33 ~-1 ~15 grass 0  
fill ~31 ~-1 ~16 ~44 ~-1 ~16 grass 0  
fill ~31 ~-1 ~17 ~31 ~-1 ~18 dirt 1  
fill ~31 ~-1 ~19 ~46 ~-1 ~19 grass 0  
fill ~31 ~-1 ~23 ~44 ~-1 ~23 dirt 1  
fill ~31 ~-1 ~25 ~44 ~-1 ~25 grass 0  
fill ~31 ~-1 ~26 ~33 ~-1 ~26 grass 0  
fill ~31 ~-1 ~27 ~44 ~-1 ~27 grass 0  
fill ~31 ~-1 ~28 ~31 ~-1 ~29 dirt 1  
fill ~31 ~-1 ~30 ~46 ~-1 ~30 grass 0  
fill ~32 ~-1 ~13 ~43 ~-1 ~13 grass 0  
fill ~32 ~-1 ~17 ~43 ~-1 ~17 grass 0  
fill ~32 ~-1 ~18 ~44 ~-1 ~18 dirt 1  
fill ~32 ~-1 ~24 ~43 ~-1 ~24 grass 0  
fill ~32 ~-1 ~28 ~43 ~-1 ~28 grass 0  
fill ~32 ~-1 ~29 ~44 ~-1 ~29 dirt 1  
fill ~34 ~-1 ~15 ~40 ~-1 ~15 dirt 0  
fill ~34 ~-1 ~26 ~40 ~-1 ~26 dirt 0  
fill ~41 ~-1 ~15 ~44 ~-1 ~15 grass 0  
fill ~41 ~-1 ~26 ~44 ~-1 ~26 grass 0  
fill ~44 ~-1 ~13 ~45 ~-1 ~13 dirt 1  
fill ~44 ~-1 ~17 ~45 ~-1 ~17 dirt 1  
fill ~44 ~-1 ~24 ~45 ~-1 ~24 dirt 1  
fill ~44 ~-1 ~28 ~45 ~-1 ~28 dirt 1  
fill ~45 ~-1 ~12 ~46 ~-1 ~12 grass 0  
fill ~45 ~-1 ~14 ~45 ~-1 ~17 dirt 1  
fill ~45 ~-1 ~18 ~46 ~-1 ~18 grass 0  
fill ~45 ~-1 ~23 ~46 ~-1 ~23 grass 0  
fill ~45 ~-1 ~25 ~45 ~-1 ~28 dirt 1  
fill ~45 ~-1 ~29 ~46 ~-1 ~29 grass 0  
fill ~46 ~-1 ~13 ~46 ~-1 ~19 grass 0  
fill ~46 ~-1 ~24 ~46 ~-1 ~30 grass 0  
fill ~47 ~-1 ~11 ~48 ~-1 ~11 stone 0  
fill ~47 ~-1 ~12 ~48 ~-1 ~12 stone 0  
fill ~47 ~-1 ~13 ~48 ~-1 ~13 stone 0  
fill ~47 ~-1 ~14 ~48 ~-1 ~14 stone 0  
fill ~47 ~-1 ~15 ~48 ~-1 ~15 stone 0  
fill ~47 ~-1 ~16 ~48 ~-1 ~16 stone 0  
fill ~47 ~-1 ~17 ~48 ~-1 ~17 stone 0  
fill ~47 ~-1 ~18 ~48 ~-1 ~18 stone 0  
fill ~47 ~-1 ~19 ~48 ~-1 ~19 stone 0  
fill ~47 ~-1 ~22 ~48 ~-1 ~22 stone 0  
fill ~47 ~-1 ~23 ~48 ~-1 ~23 stone 0  
fill ~47 ~-1 ~24 ~48 ~-1 ~24 stone 0  
fill ~47 ~-1 ~25 ~48 ~-1 ~25 stone 0  
fill ~47 ~-1 ~26 ~48 ~-1 ~26 stone 0  
fill ~47 ~-1 ~27 ~48 ~-1 ~27 stone 0  
fill ~47 ~-1 ~28 ~48 ~-1 ~28 stone 0  
fill ~47 ~-1 ~29 ~48 ~-1 ~29 stone 0  
fill ~47 ~-1 ~30 ~48 ~-1 ~30 stone 0  
fill ~3 ~0 ~13 ~6 ~0 ~13 stone 6  
fill ~3 ~0 ~14 ~3 ~0 ~16 stone 6 
setblock ~3 ~0 ~19 stone 6 
setblock ~3 ~0 ~22 stone 6  
fill ~3 ~0 ~25 ~3 ~0 ~28 stone 6  
fill ~4 ~0 ~28 ~6 ~0 ~28 stone 6  
fill ~6 ~0 ~14 ~6 ~0 ~19 stone 6 
setblock ~6 ~0 ~20 dark_oak_door 2 
setblock ~6 ~0 ~21 dark_oak_door 6  
fill ~6 ~0 ~22 ~6 ~0 ~28 stone 6  
fill ~7 ~0 ~3 ~22 ~0 ~3 stone 6  
fill ~7 ~0 ~4 ~7 ~0 ~12 stone 6  
fill ~7 ~0 ~16 ~8 ~0 ~16 carpet 15  
fill ~7 ~0 ~29 ~7 ~0 ~38 stone 6 
setblock ~8 ~0 ~15 carpet 7 
setblock ~8 ~0 ~17 carpet 7  
fill ~8 ~0 ~35 ~15 ~0 ~35 stained_hardened_clay 15  
fill ~8 ~0 ~38 ~22 ~0 ~38 stone 6  
fill ~9 ~0 ~14 ~11 ~0 ~14 carpet 15 
setblock ~9 ~0 ~15 carpet 14 
setblock ~9 ~0 ~16 carpet 7  
fill ~9 ~0 ~17 ~10 ~0 ~17 carpet 14  
fill ~9 ~0 ~18 ~9 ~0 ~17 carpet 14 
setblock ~10 ~0 ~13 carpet 14  
fill ~10 ~0 ~15 ~10 ~0 ~16 carpet 15  
fill ~10 ~0 ~18 ~11 ~0 ~18 carpet 7 
setblock ~11 ~0 ~15 carpet 7 
setblock ~11 ~0 ~16 carpet 15 
setblock ~11 ~0 ~17 carpet 7  
fill ~11 ~0 ~19 ~11 ~3 ~19 stonebrick 0  
fill ~11 ~0 ~22 ~11 ~3 ~22 stonebrick 0  
fill ~11 ~0 ~26 ~18 ~0 ~26 snow_layer 6  
fill ~11 ~0 ~27 ~18 ~0 ~27 snow_layer 6 
setblock ~11 ~0 ~28 stone_slab 6 
setblock ~11 ~0 ~29 wool 0 
setblock ~11 ~0 ~32 double_stone_slab 0  
fill ~11 ~0 ~33 ~11 ~0 ~34 stone_slab 8  
fill ~11 ~0 ~36 ~12 ~0 ~36 fence 2 
setblock ~12 ~0 ~7 snow_layer 2  
fill ~12 ~0 ~10 ~12 ~0 ~11 snow_layer 5  
fill ~12 ~0 ~14 ~12 ~0 ~15 carpet 14 
setblock ~12 ~0 ~16 carpet 7  
fill ~12 ~0 ~17 ~13 ~0 ~17 carpet 14  
fill ~12 ~0 ~18 ~12 ~0 ~17 carpet 14  
fill ~12 ~0 ~19 ~13 ~0 ~19 spruce_stairs 2  
fill ~12 ~0 ~20 ~15 ~0 ~20 planks 1  
fill ~12 ~0 ~21 ~15 ~0 ~21 planks 1  
fill ~12 ~0 ~22 ~13 ~0 ~22 spruce_stairs 3 
setblock ~12 ~0 ~24 wool 0 
setblock ~12 ~0 ~25 stone_slab 6  
fill ~12 ~0 ~32 ~15 ~0 ~32 stone_slab 8  
fill ~13 ~0 ~7 ~15 ~0 ~7 snow_layer 3  
fill ~13 ~0 ~10 ~15 ~0 ~10 snow_layer 2  
fill ~13 ~0 ~11 ~15 ~0 ~11 snow 0 
setblock ~13 ~0 ~13 carpet 15  
fill ~13 ~0 ~14 ~14 ~0 ~14 carpet 7  
fill ~13 ~0 ~15 ~13 ~0 ~16 carpet 15 
setblock ~13 ~0 ~28 stone_slab 6 
setblock ~13 ~0 ~29 wool 0 
setblock ~14 ~0 ~13 carpet 14  
fill ~14 ~0 ~15 ~14 ~0 ~17 stained_hardened_clay 10  
fill ~14 ~0 ~19 ~14 ~2 ~19 stonebrick 0  
fill ~14 ~0 ~22 ~14 ~2 ~22 stonebrick 0 
setblock ~14 ~0 ~24 wool 0 
setblock ~14 ~0 ~25 stone_slab 6 
setblock ~15 ~0 ~13 carpet 7 
setblock ~15 ~0 ~14 carpet 15 
setblock ~15 ~0 ~15 carpet 7 
setblock ~15 ~0 ~16 carpet 14 
setblock ~15 ~0 ~17 carpet 15 
setblock ~15 ~0 ~28 stone_slab 6 
setblock ~15 ~0 ~29 wool 0 
setblock ~15 ~0 ~31 double_stone_slab 0 
setblock ~16 ~0 ~7 snow_layer 2  
fill ~16 ~0 ~10 ~16 ~0 ~11 snow_layer 5  
fill ~16 ~0 ~15 ~17 ~0 ~15 carpet 14  
fill ~16 ~0 ~16 ~16 ~0 ~18 carpet 7 
setblock ~16 ~0 ~19 stone_brick_stairs 4  
fill ~16 ~0 ~20 ~16 ~0 ~21 spruce_stairs 1 
setblock ~16 ~0 ~22 stone_brick_stairs 4 
setblock ~16 ~0 ~24 wool 0 
setblock ~16 ~0 ~25 stone_slab 6  
fill ~16 ~0 ~31 ~17 ~0 ~31 stone_slab 8 
setblock ~16 ~0 ~35 dark_oak_door 3  
fill ~17 ~0 ~16 ~17 ~0 ~17 carpet 14  
fill ~17 ~0 ~18 ~18 ~0 ~18 carpet 15 
setblock ~17 ~0 ~19 stone_brick_stairs 1 
setblock ~17 ~0 ~22 stone_brick_stairs 1 
setblock ~17 ~0 ~28 stone_slab 6 
setblock ~17 ~0 ~29 wool 0  
fill ~17 ~0 ~35 ~21 ~0 ~35 stained_hardened_clay 15 
setblock ~18 ~0 ~7 snow_layer 1  
fill ~18 ~0 ~8 ~18 ~0 ~10 snow_layer 3 
setblock ~18 ~0 ~11 snow_layer 1  
fill ~18 ~0 ~16 ~18 ~0 ~18 carpet 15 
setblock ~18 ~0 ~24 wool 0 
setblock ~18 ~0 ~25 stone_slab 6  
fill ~18 ~0 ~31 ~18 ~1 ~31 stained_hardened_clay 8  
fill ~18 ~0 ~32 ~18 ~1 ~32 stained_hardened_clay 8  
fill ~18 ~0 ~33 ~18 ~1 ~33 stained_hardened_clay 8  
fill ~18 ~0 ~34 ~18 ~1 ~34 stained_hardened_clay 8 
setblock ~19 ~0 ~15 carpet 14  
fill ~19 ~0 ~16 ~19 ~0 ~17 carpet 7 
setblock ~19 ~0 ~18 carpet 14  
fill ~19 ~0 ~19 ~21 ~0 ~19 carpet 7 
setblock ~19 ~0 ~21 carpet 15 
setblock ~19 ~0 ~24 carpet 14 
setblock ~20 ~0 ~7 quartz_stairs 7  
fill ~20 ~0 ~8 ~20 ~0 ~10 stone_slab 6 
setblock ~20 ~0 ~11 quartz_stairs 6 
setblock ~20 ~0 ~15 carpet 7 
setblock ~20 ~0 ~16 carpet 15 
setblock ~20 ~0 ~17 carpet 14 
setblock ~20 ~0 ~18 carpet 15 
setblock ~20 ~0 ~20 carpet 15  
fill ~20 ~0 ~21 ~22 ~0 ~21 carpet 14 
setblock ~20 ~0 ~22 carpet 15 
setblock ~20 ~0 ~23 carpet 7 
setblock ~21 ~0 ~7 quartz_stairs 2  
fill ~21 ~0 ~8 ~21 ~0 ~10 quartz_block 10 
setblock ~21 ~0 ~11 quartz_stairs 3 
setblock ~21 ~0 ~14 carpet 7 
setblock ~21 ~0 ~15 carpet 15 
setblock ~21 ~0 ~16 carpet 14 
setblock ~21 ~0 ~17 carpet 7  
fill ~21 ~0 ~18 ~22 ~0 ~18 carpet 14 
setblock ~21 ~0 ~20 carpet 14  
fill ~21 ~0 ~22 ~22 ~0 ~22 carpet 7  
fill ~22 ~0 ~4 ~22 ~0 ~12 stone 6 
setblock ~22 ~0 ~16 carpet 7 
setblock ~22 ~0 ~17 carpet 15 
setblock ~22 ~0 ~19 carpet 14 
setblock ~22 ~0 ~20 carpet 15 
setblock ~22 ~0 ~23 carpet 14  
fill ~22 ~0 ~29 ~22 ~0 ~38 stone 6  
fill ~23 ~0 ~13 ~26 ~0 ~13 stone 6  
fill ~23 ~0 ~14 ~23 ~0 ~19 stone 6 
setblock ~23 ~0 ~20 dark_oak_door 4 
setblock ~23 ~0 ~21 dark_oak_door 0  
fill ~23 ~0 ~22 ~23 ~0 ~28 stone 6  
fill ~24 ~0 ~28 ~26 ~0 ~28 stone 6  
fill ~26 ~0 ~14 ~26 ~0 ~16 stone 6 
setblock ~26 ~0 ~19 stone 6 
setblock ~26 ~0 ~22 stone 6  
fill ~26 ~0 ~25 ~26 ~0 ~28 stone 6 
setblock ~29 ~0 ~11 tallgrass 0 
setblock ~29 ~0 ~12 red_flower 3 
setblock ~29 ~0 ~13 tallgrass 0 
setblock ~29 ~0 ~14 yellow_flower 0 
setblock ~29 ~0 ~15 tallgrass 0 
setblock ~29 ~0 ~16 yellow_flower 0  
fill ~29 ~0 ~17 ~29 ~0 ~18 tallgrass 0 
setblock ~29 ~0 ~22 yellow_flower 0  
fill ~29 ~0 ~23 ~30 ~0 ~23 tallgrass 0  
fill ~29 ~0 ~24 ~29 ~0 ~26 tallgrass 0  
fill ~29 ~0 ~28 ~29 ~0 ~29 tallgrass 0 
setblock ~29 ~0 ~30 red_flower 3 
setblock ~30 ~0 ~12 tallgrass 0  
fill ~30 ~0 ~15 ~31 ~0 ~15 leaves 8  
fill ~30 ~0 ~16 ~30 ~2 ~16 leaves 8 
setblock ~30 ~0 ~18 tallgrass 0  
fill ~30 ~0 ~25 ~31 ~0 ~25 leaves 8  
fill ~30 ~0 ~26 ~31 ~0 ~26 leaves 8  
fill ~30 ~0 ~27 ~30 ~0 ~25 leaves 8  
fill ~30 ~0 ~30 ~34 ~0 ~30 tallgrass 0 
setblock ~31 ~0 ~11 tallgrass 0 
setblock ~31 ~0 ~19 tallgrass 0  
fill ~32 ~0 ~27 ~32 ~0 ~28 tallgrass 0 
setblock ~33 ~0 ~11 red_flower 3 
setblock ~33 ~0 ~14 yellow_flower 0  
fill ~33 ~0 ~17 ~35 ~0 ~17 tallgrass 0  
fill ~33 ~0 ~22 ~46 ~0 ~22 tallgrass 0 
setblock ~33 ~0 ~24 tallgrass 0 
setblock ~33 ~0 ~25 yellow_flower 0  
fill ~34 ~0 ~11 ~35 ~0 ~11 tallgrass 0 
setblock ~34 ~0 ~14 stone_brick_stairs 0  
fill ~34 ~0 ~15 ~40 ~0 ~15 stonebrick 0 
setblock ~34 ~0 ~16 stone_brick_stairs 0  
fill ~34 ~0 ~19 ~35 ~0 ~19 tallgrass 0 
setblock ~34 ~0 ~25 stone_brick_stairs 0  
fill ~34 ~0 ~26 ~40 ~0 ~26 stonebrick 0 
setblock ~34 ~0 ~27 stone_brick_stairs 0 
setblock ~34 ~0 ~28 red_flower 0  
fill ~35 ~0 ~14 ~39 ~0 ~14 stone_brick_stairs 2  
fill ~35 ~0 ~16 ~39 ~0 ~16 stone_brick_stairs 3 
setblock ~35 ~0 ~24 tallgrass 0  
fill ~35 ~0 ~25 ~39 ~0 ~25 stone_brick_stairs 2  
fill ~35 ~0 ~27 ~39 ~0 ~27 stone_brick_stairs 3 
setblock ~36 ~0 ~13 tallgrass 0  
fill ~36 ~0 ~17 ~37 ~0 ~17 leaves 12 
setblock ~36 ~0 ~24 leaves 8  
fill ~36 ~0 ~29 ~36 ~1 ~29 leaves 8 
setblock ~36 ~0 ~30 red_flower 3 
setblock ~37 ~0 ~11 tallgrass 0  
fill ~37 ~0 ~13 ~38 ~0 ~13 leaves 8  
fill ~37 ~0 ~18 ~38 ~0 ~18 leaves 12  
fill ~37 ~0 ~19 ~37 ~2 ~19 leaves 8  
fill ~37 ~0 ~23 ~38 ~0 ~23 leaves 12  
fill ~37 ~0 ~24 ~38 ~0 ~24 leaves 12 
setblock ~37 ~0 ~28 leaves 8 
setblock ~37 ~0 ~29 leaves 12  
fill ~37 ~0 ~30 ~38 ~0 ~30 tallgrass 0 
setblock ~38 ~0 ~11 red_flower 0  
fill ~38 ~0 ~12 ~39 ~0 ~12 leaves 8  
fill ~38 ~0 ~17 ~42 ~0 ~17 tallgrass 0  
fill ~38 ~0 ~28 ~41 ~0 ~28 tallgrass 0 
setblock ~38 ~0 ~29 leaves 8  
fill ~39 ~0 ~11 ~40 ~0 ~11 tallgrass 0 
setblock ~39 ~0 ~24 tallgrass 0 
setblock ~40 ~0 ~14 stone_brick_stairs 1 
setblock ~40 ~0 ~16 stone_brick_stairs 1  
fill ~40 ~0 ~19 ~45 ~0 ~19 tallgrass 0 
setblock ~40 ~0 ~25 stone_brick_stairs 1 
setblock ~40 ~0 ~27 stone_brick_stairs 1  
fill ~40 ~0 ~30 ~41 ~0 ~30 tallgrass 0  
fill ~41 ~0 ~16 ~42 ~0 ~16 tallgrass 0  
fill ~41 ~0 ~24 ~43 ~0 ~24 tallgrass 0  
fill ~41 ~0 ~25 ~41 ~0 ~28 tallgrass 0  
fill ~42 ~0 ~11 ~46 ~0 ~11 tallgrass 0 
setblock ~42 ~0 ~25 yellow_flower 0 
setblock ~42 ~0 ~26 tallgrass 0 
setblock ~42 ~0 ~27 red_flower 0 
setblock ~42 ~0 ~30 red_flower 0 
setblock ~43 ~0 ~15 tallgrass 0  
fill ~43 ~0 ~25 ~44 ~0 ~25 tallgrass 0 
setblock ~43 ~0 ~27 tallgrass 0  
fill ~43 ~0 ~30 ~46 ~0 ~30 tallgrass 0  
fill ~44 ~0 ~15 ~45 ~0 ~15 leaves 8  
fill ~44 ~0 ~26 ~45 ~0 ~26 leaves 12 
setblock ~44 ~0 ~27 red_flower 3  
fill ~45 ~0 ~12 ~46 ~0 ~12 tallgrass 0 
setblock ~45 ~0 ~16 leaves 8  
fill ~45 ~0 ~18 ~46 ~0 ~18 tallgrass 0  
fill ~45 ~0 ~23 ~46 ~0 ~23 tallgrass 0  
fill ~45 ~0 ~27 ~45 ~1 ~27 leaves 8  
fill ~45 ~0 ~29 ~46 ~0 ~29 tallgrass 0 
setblock ~46 ~0 ~13 yellow_flower 0  
fill ~46 ~0 ~14 ~46 ~0 ~18 tallgrass 0 
setblock ~46 ~0 ~25 tallgrass 0 
setblock ~46 ~0 ~28 tallgrass 0  
fill ~3 ~1 ~13 ~3 ~4 ~13 sandstone 2  
fill ~3 ~1 ~14 ~3 ~1 ~15 dropper 2  
fill ~3 ~1 ~16 ~3 ~4 ~16 sandstone 2  
fill ~3 ~1 ~19 ~3 ~4 ~19 sandstone 2  
fill ~3 ~1 ~22 ~3 ~4 ~22 sandstone 2  
fill ~3 ~1 ~25 ~3 ~4 ~25 sandstone 2  
fill ~3 ~1 ~26 ~3 ~1 ~27 dropper 2  
fill ~3 ~1 ~28 ~3 ~4 ~28 sandstone 2  
fill ~4 ~1 ~13 ~5 ~1 ~13 dropper 2  
fill ~4 ~1 ~28 ~5 ~1 ~28 dropper 2  
fill ~6 ~1 ~13 ~6 ~4 ~13 sandstone 2  
fill ~6 ~1 ~14 ~6 ~3 ~14 stained_glass_pane 9  
fill ~6 ~1 ~15 ~6 ~3 ~15 stained_glass_pane 9  
fill ~6 ~1 ~16 ~6 ~4 ~16 sandstone 2  
fill ~6 ~1 ~17 ~6 ~3 ~17 stained_glass_pane 9  
fill ~6 ~1 ~18 ~6 ~3 ~18 stained_glass_pane 9  
fill ~6 ~1 ~19 ~6 ~4 ~19 sandstone 2 
setblock ~6 ~1 ~20 dark_oak_door 9 
setblock ~6 ~1 ~21 dark_oak_door 8  
fill ~6 ~1 ~22 ~6 ~4 ~22 sandstone 2  
fill ~6 ~1 ~23 ~6 ~3 ~23 stained_glass_pane 9  
fill ~6 ~1 ~24 ~6 ~3 ~24 stained_glass_pane 9  
fill ~6 ~1 ~25 ~6 ~4 ~25 sandstone 2  
fill ~6 ~1 ~26 ~6 ~3 ~26 stained_glass_pane 9  
fill ~6 ~1 ~27 ~6 ~3 ~27 stained_glass_pane 9  
fill ~6 ~1 ~28 ~6 ~4 ~28 sandstone 2  
fill ~7 ~1 ~3 ~7 ~10 ~3 sandstone 2  
fill ~7 ~1 ~4 ~7 ~3 ~4 stained_glass_pane 9  
fill ~7 ~1 ~5 ~7 ~3 ~5 stained_glass_pane 9  
fill ~7 ~1 ~6 ~7 ~10 ~6 sandstone 2  
fill ~7 ~1 ~7 ~7 ~3 ~7 stained_glass_pane 9  
fill ~7 ~1 ~8 ~7 ~3 ~8 stained_glass_pane 9  
fill ~7 ~1 ~9 ~7 ~10 ~9 sandstone 2  
fill ~7 ~1 ~10 ~7 ~3 ~10 stained_glass_pane 9  
fill ~7 ~1 ~11 ~7 ~3 ~11 stained_glass_pane 9  
fill ~7 ~1 ~12 ~7 ~10 ~12 sandstone 2  
fill ~7 ~1 ~29 ~7 ~10 ~29 sandstone 2  
fill ~7 ~1 ~30 ~7 ~3 ~30 stained_glass_pane 9  
fill ~7 ~1 ~31 ~7 ~3 ~31 stained_glass_pane 9  
fill ~7 ~1 ~32 ~7 ~10 ~32 sandstone 2  
fill ~7 ~1 ~33 ~7 ~3 ~33 stained_glass_pane 9  
fill ~7 ~1 ~34 ~7 ~3 ~34 stained_glass_pane 9  
fill ~7 ~1 ~35 ~7 ~10 ~35 sandstone 2  
fill ~7 ~1 ~36 ~7 ~3 ~36 stained_glass_pane 9  
fill ~7 ~1 ~37 ~7 ~3 ~37 stained_glass_pane 9  
fill ~7 ~1 ~38 ~7 ~10 ~38 sandstone 2  
fill ~8 ~1 ~3 ~9 ~1 ~3 stained_glass_pane 9  
fill ~8 ~1 ~35 ~15 ~1 ~35 stained_hardened_clay 15  
fill ~8 ~1 ~38 ~9 ~1 ~38 stained_glass_pane 9  
fill ~10 ~1 ~3 ~10 ~10 ~3 sandstone 2  
fill ~10 ~1 ~38 ~10 ~10 ~38 sandstone 2  
fill ~11 ~1 ~3 ~12 ~1 ~3 stained_glass_pane 9  
fill ~11 ~1 ~6 ~11 ~2 ~6 planks 0  
fill ~11 ~1 ~26 ~18 ~1 ~26 carpet 0  
fill ~11 ~1 ~27 ~18 ~1 ~27 carpet 0  
fill ~11 ~1 ~36 ~11 ~0 ~36 fence 2  
fill ~11 ~1 ~38 ~12 ~1 ~38 stained_glass_pane 9  
fill ~12 ~1 ~5 ~16 ~1 ~5 stained_hardened_clay 15  
fill ~12 ~1 ~6 ~16 ~1 ~6 dropper 0  
fill ~12 ~1 ~19 ~13 ~1 ~19 spruce_stairs 6  
fill ~12 ~1 ~20 ~14 ~1 ~20 planks 1  
fill ~12 ~1 ~21 ~14 ~1 ~21 planks 1  
fill ~12 ~1 ~22 ~13 ~1 ~22 spruce_stairs 7 
setblock ~12 ~1 ~32 quartz_stairs 3  
fill ~13 ~1 ~3 ~13 ~10 ~3 sandstone 2  
fill ~13 ~1 ~16 ~15 ~1 ~16 gold_block 0  
fill ~13 ~1 ~38 ~13 ~10 ~38 sandstone 2  
fill ~14 ~1 ~3 ~15 ~1 ~3 stained_glass_pane 9  
fill ~14 ~1 ~38 ~15 ~1 ~38 stained_glass_pane 9 
setblock ~15 ~1 ~19 stone_brick_stairs 4  
fill ~15 ~1 ~20 ~15 ~1 ~21 spruce_stairs 1 
setblock ~15 ~1 ~22 stone_brick_stairs 4 
setblock ~15 ~1 ~32 flower_pot 0  
fill ~16 ~1 ~3 ~16 ~10 ~3 sandstone 2 
setblock ~16 ~1 ~19 stone_brick_stairs 1 
setblock ~16 ~1 ~22 stone_brick_stairs 1 
setblock ~16 ~1 ~31 quartz_stairs 3 
setblock ~16 ~1 ~35 dark_oak_door 8  
fill ~16 ~1 ~38 ~16 ~10 ~38 sandstone 2  
fill ~17 ~1 ~3 ~18 ~1 ~3 stained_glass_pane 9  
fill ~17 ~1 ~6 ~17 ~2 ~6 planks 0  
fill ~17 ~1 ~35 ~21 ~1 ~35 stained_hardened_clay 15  
fill ~17 ~1 ~38 ~18 ~1 ~38 stained_glass_pane 9  
fill ~19 ~1 ~3 ~19 ~10 ~3 sandstone 2  
fill ~19 ~1 ~38 ~19 ~10 ~38 sandstone 2  
fill ~20 ~1 ~3 ~21 ~1 ~3 stained_glass_pane 9  
fill ~20 ~1 ~38 ~21 ~1 ~38 stained_glass_pane 9  
fill ~21 ~1 ~7 ~21 ~1 ~11 stone_slab 6  
fill ~22 ~1 ~3 ~22 ~10 ~3 sandstone 2  
fill ~22 ~1 ~4 ~22 ~3 ~4 stained_glass_pane 9  
fill ~22 ~1 ~5 ~22 ~3 ~5 stained_glass_pane 9  
fill ~22 ~1 ~6 ~22 ~10 ~6 sandstone 2  
fill ~22 ~1 ~7 ~22 ~3 ~7 stained_glass_pane 9  
fill ~22 ~1 ~8 ~22 ~3 ~8 stained_glass_pane 9  
fill ~22 ~1 ~9 ~22 ~10 ~9 sandstone 2  
fill ~22 ~1 ~10 ~22 ~3 ~10 stained_glass_pane 9  
fill ~22 ~1 ~11 ~22 ~3 ~11 stained_glass_pane 9  
fill ~22 ~1 ~12 ~22 ~10 ~12 sandstone 2  
fill ~22 ~1 ~29 ~22 ~10 ~29 sandstone 2  
fill ~22 ~1 ~30 ~22 ~3 ~30 stained_glass_pane 9  
fill ~22 ~1 ~31 ~22 ~3 ~31 stained_glass_pane 9  
fill ~22 ~1 ~32 ~22 ~10 ~32 sandstone 2  
fill ~22 ~1 ~33 ~22 ~3 ~33 stained_glass_pane 9  
fill ~22 ~1 ~34 ~22 ~3 ~34 stained_glass_pane 9  
fill ~22 ~1 ~35 ~22 ~10 ~35 sandstone 2  
fill ~22 ~1 ~36 ~22 ~3 ~36 stained_glass_pane 9  
fill ~22 ~1 ~37 ~22 ~3 ~37 stained_glass_pane 9  
fill ~22 ~1 ~38 ~22 ~10 ~38 sandstone 2  
fill ~23 ~1 ~13 ~23 ~4 ~13 sandstone 2  
fill ~23 ~1 ~14 ~23 ~3 ~14 stained_glass_pane 9  
fill ~23 ~1 ~15 ~23 ~3 ~15 stained_glass_pane 9  
fill ~23 ~1 ~16 ~23 ~4 ~16 sandstone 2  
fill ~23 ~1 ~17 ~23 ~3 ~17 stained_glass_pane 9  
fill ~23 ~1 ~18 ~23 ~3 ~18 stained_glass_pane 9  
fill ~23 ~1 ~19 ~23 ~4 ~19 sandstone 2 
setblock ~23 ~1 ~20 dark_oak_door 8 
setblock ~23 ~1 ~21 dark_oak_door 9  
fill ~23 ~1 ~22 ~23 ~4 ~22 sandstone 2  
fill ~23 ~1 ~23 ~23 ~3 ~23 stained_glass_pane 9  
fill ~23 ~1 ~24 ~23 ~3 ~24 stained_glass_pane 9  
fill ~23 ~1 ~25 ~23 ~4 ~25 sandstone 2  
fill ~23 ~1 ~26 ~23 ~3 ~26 stained_glass_pane 9  
fill ~23 ~1 ~27 ~23 ~3 ~27 stained_glass_pane 9  
fill ~23 ~1 ~28 ~23 ~4 ~28 sandstone 2  
fill ~24 ~1 ~13 ~25 ~1 ~13 dropper 2  
fill ~24 ~1 ~28 ~25 ~1 ~28 dropper 2  
fill ~26 ~1 ~13 ~26 ~4 ~13 sandstone 2  
fill ~26 ~1 ~14 ~26 ~1 ~15 dropper 2  
fill ~26 ~1 ~16 ~26 ~4 ~16 sandstone 2  
fill ~26 ~1 ~19 ~26 ~4 ~19 sandstone 2  
fill ~26 ~1 ~22 ~26 ~4 ~22 sandstone 2  
fill ~26 ~1 ~25 ~26 ~4 ~25 sandstone 2  
fill ~26 ~1 ~26 ~26 ~1 ~27 dropper 2  
fill ~26 ~1 ~28 ~26 ~4 ~28 sandstone 2  
fill ~30 ~1 ~25 ~30 ~1 ~26 leaves 8 
setblock ~34 ~1 ~14 stone_brick_stairs 4  
fill ~34 ~1 ~15 ~40 ~1 ~15 stonebrick 0 
setblock ~34 ~1 ~16 stone_brick_stairs 4 
setblock ~34 ~1 ~25 stone_brick_stairs 4  
fill ~34 ~1 ~26 ~40 ~1 ~26 stonebrick 0 
setblock ~34 ~1 ~27 stone_brick_stairs 4  
fill ~35 ~1 ~14 ~39 ~1 ~14 stone_brick_stairs 6  
fill ~35 ~1 ~16 ~39 ~1 ~16 stone_brick_stairs 7  
fill ~35 ~1 ~25 ~39 ~1 ~25 stone_brick_stairs 6  
fill ~35 ~1 ~27 ~39 ~1 ~27 stone_brick_stairs 7  
fill ~37 ~1 ~18 ~37 ~2 ~18 leaves 12 
setblock ~37 ~1 ~23 leaves 8  
fill ~37 ~1 ~29 ~37 ~2 ~29 leaves 8  
fill ~38 ~1 ~12 ~39 ~1 ~12 leaves 8 
setblock ~38 ~1 ~18 leaves 8  
fill ~38 ~1 ~23 ~38 ~2 ~23 leaves 12 
setblock ~40 ~1 ~14 stone_brick_stairs 5 
setblock ~40 ~1 ~16 stone_brick_stairs 5 
setblock ~40 ~1 ~25 stone_brick_stairs 5 
setblock ~40 ~1 ~27 stone_brick_stairs 5 
setblock ~45 ~1 ~15 leaves 8 
setblock ~45 ~1 ~26 leaves 12  
fill ~6 ~2 ~20 ~6 ~2 ~21 sandstone_stairs 4  
fill ~8 ~2 ~3 ~9 ~2 ~3 stained_glass_pane 9  
fill ~8 ~2 ~35 ~21 ~2 ~35 stained_hardened_clay 15  
fill ~8 ~2 ~38 ~9 ~2 ~38 stained_glass_pane 9  
fill ~11 ~2 ~3 ~12 ~2 ~3 stained_glass_pane 9  
fill ~11 ~2 ~20 ~11 ~2 ~22 stonebrick 0  
fill ~11 ~2 ~38 ~12 ~2 ~38 stained_glass_pane 9  
fill ~12 ~2 ~5 ~16 ~2 ~5 stained_hardened_clay 15  
fill ~12 ~2 ~18 ~13 ~2 ~18 spruce_stairs 6  
fill ~12 ~2 ~19 ~13 ~2 ~19 planks 1  
fill ~12 ~2 ~20 ~13 ~2 ~20 planks 1  
fill ~12 ~2 ~21 ~13 ~2 ~21 planks 1  
fill ~12 ~2 ~22 ~13 ~2 ~22 planks 1  
fill ~12 ~2 ~23 ~13 ~2 ~23 spruce_stairs 7  
fill ~14 ~2 ~3 ~15 ~2 ~3 stained_glass_pane 9  
fill ~14 ~2 ~15 ~14 ~2 ~17 stained_hardened_clay 1  
fill ~14 ~2 ~20 ~14 ~2 ~21 spruce_stairs 1  
fill ~14 ~2 ~38 ~15 ~2 ~38 stained_glass_pane 9 
setblock ~15 ~2 ~19 stone_brick_stairs 1 
setblock ~15 ~2 ~22 stone_brick_stairs 1  
fill ~17 ~2 ~3 ~18 ~2 ~3 stained_glass_pane 9  
fill ~17 ~2 ~38 ~18 ~2 ~38 stained_glass_pane 9  
fill ~20 ~2 ~3 ~21 ~2 ~3 stained_glass_pane 9  
fill ~20 ~2 ~38 ~21 ~2 ~38 stained_glass_pane 9  
fill ~23 ~2 ~20 ~23 ~2 ~21 sandstone_stairs 5  
fill ~30 ~2 ~26 ~30 ~3 ~26 leaves 8 
setblock ~33 ~2 ~14 stone_slab 3 
setblock ~33 ~2 ~25 stone_slab 3 
setblock ~34 ~2 ~15 quartz_stairs 0 
setblock ~34 ~2 ~26 quartz_stairs 0 
setblock ~35 ~2 ~14 quartz_block 0  
fill ~35 ~2 ~15 ~38 ~2 ~15 stone_slab 14 
setblock ~35 ~2 ~16 quartz_block 0 
setblock ~35 ~2 ~25 quartz_block 0  
fill ~35 ~2 ~26 ~38 ~2 ~26 stone_slab 14 
setblock ~35 ~2 ~27 quartz_block 0 
setblock ~36 ~2 ~14 quartz_stairs 1 
setblock ~36 ~2 ~16 quartz_stairs 1 
setblock ~36 ~2 ~25 quartz_stairs 1 
setblock ~36 ~2 ~27 quartz_stairs 1  
fill ~38 ~2 ~12 ~38 ~0 ~12 leaves 8 
setblock ~38 ~2 ~14 quartz_block 0 
setblock ~38 ~2 ~16 stone_slab 14 
setblock ~38 ~2 ~25 stone_slab 14 
setblock ~38 ~2 ~27 quartz_block 0 
setblock ~39 ~2 ~14 quartz_stairs 1 
setblock ~39 ~2 ~15 stone_slab 11 
setblock ~39 ~2 ~16 quartz_block 0 
setblock ~39 ~2 ~25 quartz_block 0 
setblock ~39 ~2 ~26 stone_slab 11 
setblock ~39 ~2 ~27 quartz_stairs 1 
setblock ~40 ~2 ~16 quartz_stairs 1 
setblock ~40 ~2 ~25 quartz_stairs 1 
setblock ~45 ~2 ~26 leaves 8 
setblock ~3 ~3 ~14 sandstone_stairs 7 
setblock ~3 ~3 ~15 sandstone_stairs 6 
setblock ~3 ~3 ~17 sandstone_stairs 7 
setblock ~3 ~3 ~18 sandstone_stairs 6 
setblock ~3 ~3 ~20 sandstone_stairs 7 
setblock ~3 ~3 ~21 sandstone_stairs 6 
setblock ~3 ~3 ~23 sandstone_stairs 7 
setblock ~3 ~3 ~24 sandstone_stairs 6 
setblock ~3 ~3 ~26 sandstone_stairs 7 
setblock ~3 ~3 ~27 sandstone_stairs 6 
setblock ~4 ~3 ~13 sandstone_stairs 5 
setblock ~4 ~3 ~28 sandstone_stairs 5 
setblock ~5 ~3 ~13 sandstone_stairs 4 
setblock ~5 ~3 ~28 sandstone_stairs 4  
fill ~6 ~3 ~20 ~6 ~4 ~20 sandstone 2  
fill ~6 ~3 ~21 ~6 ~4 ~21 sandstone 2  
fill ~8 ~3 ~3 ~9 ~3 ~3 stained_glass_pane 9  
fill ~8 ~3 ~35 ~21 ~3 ~35 stained_hardened_clay 15  
fill ~8 ~3 ~38 ~9 ~3 ~38 stained_glass_pane 9  
fill ~11 ~3 ~3 ~12 ~3 ~3 stained_glass_pane 9  
fill ~11 ~3 ~6 ~17 ~3 ~6 dropper 0 
setblock ~11 ~3 ~18 stone_brick_stairs 6  
fill ~11 ~3 ~20 ~11 ~3 ~21 stone_slab 13 
setblock ~11 ~3 ~23 stone_brick_stairs 7  
fill ~11 ~3 ~38 ~12 ~3 ~38 stained_glass_pane 9  
fill ~12 ~3 ~17 ~13 ~3 ~17 spruce_stairs 6  
fill ~12 ~3 ~18 ~13 ~3 ~18 spruce_stairs 3  
fill ~12 ~3 ~23 ~13 ~3 ~23 spruce_stairs 2  
fill ~12 ~3 ~24 ~13 ~3 ~24 spruce_stairs 7  
fill ~14 ~3 ~3 ~15 ~3 ~3 stained_glass_pane 9 
setblock ~14 ~3 ~5 stained_hardened_clay 9 
setblock ~14 ~3 ~18 stone_brick_stairs 6 
setblock ~14 ~3 ~19 stone_brick_stairs 3 
setblock ~14 ~3 ~22 stone_brick_stairs 2 
setblock ~14 ~3 ~23 stone_brick_stairs 7  
fill ~14 ~3 ~38 ~15 ~3 ~38 stained_glass_pane 9  
fill ~17 ~3 ~3 ~18 ~3 ~3 stained_glass_pane 9  
fill ~17 ~3 ~38 ~18 ~3 ~38 stained_glass_pane 9  
fill ~20 ~3 ~3 ~21 ~3 ~3 stained_glass_pane 9  
fill ~20 ~3 ~38 ~21 ~3 ~38 stained_glass_pane 9  
fill ~23 ~3 ~20 ~23 ~4 ~20 sandstone 2  
fill ~23 ~3 ~21 ~23 ~4 ~21 sandstone 2 
setblock ~24 ~3 ~13 sandstone_stairs 5 
setblock ~24 ~3 ~28 sandstone_stairs 5 
setblock ~25 ~3 ~13 sandstone_stairs 4 
setblock ~25 ~3 ~28 sandstone_stairs 4 
setblock ~26 ~3 ~14 sandstone_stairs 7 
setblock ~26 ~3 ~15 sandstone_stairs 6 
setblock ~26 ~3 ~17 sandstone_stairs 7 
setblock ~26 ~3 ~18 sandstone_stairs 6 
setblock ~26 ~3 ~20 sandstone_stairs 7 
setblock ~26 ~3 ~21 sandstone_stairs 6 
setblock ~26 ~3 ~23 sandstone_stairs 7 
setblock ~26 ~3 ~24 sandstone_stairs 6 
setblock ~26 ~3 ~26 sandstone_stairs 7 
setblock ~26 ~3 ~27 sandstone_stairs 6 
setblock ~35 ~3 ~14 quartz_stairs 2  
fill ~35 ~3 ~15 ~38 ~3 ~15 quartz_block 0 
setblock ~35 ~3 ~16 quartz_stairs 3 
setblock ~35 ~3 ~25 quartz_stairs 2  
fill ~35 ~3 ~26 ~38 ~3 ~26 quartz_block 0 
setblock ~35 ~3 ~27 quartz_stairs 3 
setblock ~37 ~3 ~18 leaves 8 
setblock ~38 ~3 ~14 quartz_stairs 2 
setblock ~38 ~3 ~16 quartz_stairs 3 
setblock ~38 ~3 ~25 quartz_stairs 2 
setblock ~38 ~3 ~27 quartz_stairs 3 
setblock ~39 ~3 ~14 stone_stairs 6  
fill ~39 ~3 ~15 ~39 ~4 ~15 double_stone_slab 3 
setblock ~39 ~3 ~16 stone_stairs 7 
setblock ~39 ~3 ~25 stone_stairs 6  
fill ~39 ~3 ~26 ~39 ~4 ~26 double_stone_slab 3 
setblock ~39 ~3 ~27 stone_stairs 7 
setblock ~40 ~3 ~15 stone_slab 14   

KittysCommands:  
setblock ~40 ~3 ~26 stone_slab 14 
setblock ~2 ~4 ~13 quartz_stairs 4  
fill ~2 ~4 ~14 ~2 ~4 ~15 stone_slab 14 
setblock ~2 ~4 ~16 quartz_stairs 4  
fill ~2 ~4 ~17 ~2 ~4 ~18 stone_slab 14 
setblock ~2 ~4 ~19 quartz_stairs 4  
fill ~2 ~4 ~20 ~2 ~4 ~21 stone_slab 14 
setblock ~2 ~4 ~22 quartz_stairs 4  
fill ~2 ~4 ~23 ~2 ~4 ~24 stone_slab 14 
setblock ~2 ~4 ~25 quartz_stairs 4  
fill ~2 ~4 ~26 ~2 ~4 ~27 stone_slab 14 
setblock ~2 ~4 ~28 quartz_stairs 4 
setblock ~3 ~4 ~12 quartz_stairs 6  
fill ~3 ~4 ~14 ~26 ~4 ~14 sandstone 2  
fill ~3 ~4 ~15 ~26 ~4 ~15 sandstone 2  
fill ~3 ~4 ~17 ~10 ~4 ~17 sandstone 2  
fill ~3 ~4 ~18 ~10 ~4 ~18 sandstone 2  
fill ~3 ~4 ~20 ~10 ~4 ~20 sandstone 2  
fill ~3 ~4 ~21 ~10 ~4 ~21 sandstone 2  
fill ~3 ~4 ~23 ~10 ~4 ~23 sandstone 2  
fill ~3 ~4 ~24 ~10 ~4 ~24 sandstone 2  
fill ~3 ~4 ~26 ~26 ~4 ~26 sandstone 2  
fill ~3 ~4 ~27 ~26 ~4 ~27 sandstone 2 
setblock ~3 ~4 ~29 quartz_stairs 7  
fill ~4 ~4 ~12 ~5 ~4 ~12 stone_slab 14  
fill ~4 ~4 ~13 ~26 ~4 ~13 sandstone 2  
fill ~4 ~4 ~16 ~10 ~4 ~16 sandstone 2  
fill ~4 ~4 ~19 ~10 ~4 ~19 sandstone 2  
fill ~4 ~4 ~22 ~10 ~4 ~22 sandstone 2  
fill ~4 ~4 ~25 ~10 ~4 ~25 sandstone 2  
fill ~4 ~4 ~28 ~26 ~4 ~28 sandstone 2  
fill ~4 ~4 ~29 ~5 ~4 ~29 stone_slab 14 
setblock ~6 ~4 ~4 quartz_stairs 2 
setblock ~6 ~4 ~5 quartz_stairs 3 
setblock ~6 ~4 ~7 quartz_stairs 2 
setblock ~6 ~4 ~8 quartz_stairs 3 
setblock ~6 ~4 ~10 quartz_stairs 2 
setblock ~6 ~4 ~11 quartz_stairs 3 
setblock ~6 ~4 ~12 quartz_stairs 6 
setblock ~6 ~4 ~29 quartz_stairs 7 
setblock ~6 ~4 ~30 quartz_stairs 2 
setblock ~6 ~4 ~31 quartz_stairs 3 
setblock ~6 ~4 ~33 quartz_stairs 2 
setblock ~6 ~4 ~34 quartz_stairs 3 
setblock ~6 ~4 ~36 quartz_stairs 2 
setblock ~6 ~4 ~37 quartz_stairs 3  
fill ~7 ~4 ~4 ~7 ~4 ~5 quartz_block 10  
fill ~7 ~4 ~7 ~7 ~4 ~8 quartz_block 10  
fill ~7 ~4 ~10 ~7 ~4 ~11 quartz_block 10  
fill ~7 ~4 ~30 ~7 ~4 ~31 quartz_block 10  
fill ~7 ~4 ~33 ~7 ~4 ~34 quartz_block 10  
fill ~7 ~4 ~36 ~7 ~4 ~37 quartz_block 10 
setblock ~8 ~4 ~2 quartz_stairs 0  
fill ~8 ~4 ~3 ~9 ~4 ~3 quartz_block 6  
fill ~8 ~4 ~4 ~21 ~4 ~4 sandstone 2  
fill ~8 ~4 ~5 ~21 ~4 ~5 sandstone 2  
fill ~8 ~4 ~6 ~22 ~4 ~6 sandstone 2  
fill ~8 ~4 ~7 ~21 ~4 ~7 sandstone 2  
fill ~8 ~4 ~8 ~21 ~4 ~8 sandstone 2  
fill ~8 ~4 ~9 ~22 ~4 ~9 sandstone 2  
fill ~8 ~4 ~10 ~21 ~4 ~10 sandstone 2  
fill ~8 ~4 ~11 ~21 ~4 ~11 sandstone 2  
fill ~8 ~4 ~12 ~22 ~4 ~12 sandstone 2  
fill ~8 ~4 ~29 ~22 ~4 ~29 sandstone 2  
fill ~8 ~4 ~30 ~21 ~4 ~30 sandstone 2  
fill ~8 ~4 ~31 ~21 ~4 ~31 sandstone 2  
fill ~8 ~4 ~32 ~22 ~4 ~32 sandstone 2  
fill ~8 ~4 ~33 ~21 ~4 ~33 sandstone 2  
fill ~8 ~4 ~34 ~21 ~4 ~34 sandstone 2  
fill ~8 ~4 ~35 ~22 ~4 ~35 sandstone 2  
fill ~8 ~4 ~36 ~21 ~4 ~36 sandstone 2  
fill ~8 ~4 ~37 ~21 ~4 ~37 sandstone 2  
fill ~8 ~4 ~38 ~9 ~4 ~38 quartz_block 6 
setblock ~8 ~4 ~39 quartz_stairs 0 
setblock ~9 ~4 ~2 quartz_stairs 1 
setblock ~9 ~4 ~39 quartz_stairs 1 
setblock ~11 ~4 ~2 quartz_stairs 0  
fill ~11 ~4 ~3 ~12 ~4 ~3 quartz_block 6 
setblock ~11 ~4 ~16 sandstone_stairs 7 
setblock ~11 ~4 ~17 stone_brick_stairs 6 
setblock ~11 ~4 ~18 stone_brick_stairs 3 
setblock ~11 ~4 ~23 stone_brick_stairs 2 
setblock ~11 ~4 ~24 stone_brick_stairs 7 
setblock ~11 ~4 ~25 sandstone_stairs 6  
fill ~11 ~4 ~38 ~12 ~4 ~38 quartz_block 6 
setblock ~11 ~4 ~39 quartz_stairs 0 
setblock ~12 ~4 ~2 quartz_stairs 1  
fill ~12 ~4 ~16 ~13 ~4 ~16 sandstone 2  
fill ~12 ~4 ~17 ~13 ~4 ~17 spruce_stairs 3  
fill ~12 ~4 ~24 ~13 ~4 ~24 spruce_stairs 2  
fill ~12 ~4 ~25 ~13 ~4 ~25 sandstone 2 
setblock ~12 ~4 ~39 quartz_stairs 1 
setblock ~14 ~4 ~2 quartz_stairs 0  
fill ~14 ~4 ~3 ~15 ~4 ~3 quartz_block 6 
setblock ~14 ~4 ~16 sandstone_stairs 7 
setblock ~14 ~4 ~17 stone_brick_stairs 6 
setblock ~14 ~4 ~18 stone_brick_stairs 3 
setblock ~14 ~4 ~23 stone_brick_stairs 2 
setblock ~14 ~4 ~24 stone_brick_stairs 7 
setblock ~14 ~4 ~25 sandstone_stairs 6  
fill ~14 ~4 ~38 ~15 ~4 ~38 quartz_block 6 
setblock ~14 ~4 ~39 quartz_stairs 0 
setblock ~15 ~4 ~2 quartz_stairs 1  
fill ~15 ~4 ~16 ~26 ~4 ~16 sandstone 2  
fill ~15 ~4 ~17 ~26 ~4 ~17 sandstone 2  
fill ~15 ~4 ~18 ~26 ~4 ~18 sandstone 2  
fill ~15 ~4 ~23 ~26 ~4 ~23 sandstone 2  
fill ~15 ~4 ~24 ~26 ~4 ~24 sandstone 2  
fill ~15 ~4 ~25 ~26 ~4 ~25 sandstone 2 
setblock ~15 ~4 ~39 quartz_stairs 1 
setblock ~17 ~4 ~2 quartz_stairs 0  
fill ~17 ~4 ~3 ~18 ~4 ~3 quartz_block 6  
fill ~17 ~4 ~19 ~26 ~4 ~19 sandstone 2  
fill ~17 ~4 ~20 ~26 ~4 ~20 sandstone 2  
fill ~17 ~4 ~21 ~26 ~4 ~21 sandstone 2  
fill ~17 ~4 ~22 ~26 ~4 ~22 sandstone 2  
fill ~17 ~4 ~38 ~18 ~4 ~38 quartz_block 6 
setblock ~17 ~4 ~39 quartz_stairs 0 
setblock ~18 ~4 ~2 quartz_stairs 1 
setblock ~18 ~4 ~39 quartz_stairs 1 
setblock ~20 ~4 ~2 quartz_stairs 0  
fill ~20 ~4 ~3 ~21 ~4 ~3 quartz_block 6  
fill ~20 ~4 ~38 ~21 ~4 ~38 quartz_block 6 
setblock ~20 ~4 ~39 quartz_stairs 0 
setblock ~21 ~4 ~2 quartz_stairs 1 
setblock ~21 ~4 ~39 quartz_stairs 1  
fill ~22 ~4 ~4 ~22 ~4 ~5 quartz_block 10  
fill ~22 ~4 ~7 ~22 ~4 ~8 quartz_block 10  
fill ~22 ~4 ~10 ~22 ~4 ~11 quartz_block 10  
fill ~22 ~4 ~30 ~22 ~4 ~31 quartz_block 10  
fill ~22 ~4 ~33 ~22 ~4 ~34 quartz_block 10  
fill ~22 ~4 ~36 ~22 ~4 ~37 quartz_block 10 
setblock ~23 ~4 ~4 quartz_stairs 2 
setblock ~23 ~4 ~5 quartz_stairs 3 
setblock ~23 ~4 ~7 quartz_stairs 2 
setblock ~23 ~4 ~8 quartz_stairs 3 
setblock ~23 ~4 ~10 quartz_stairs 2 
setblock ~23 ~4 ~11 quartz_stairs 3 
setblock ~23 ~4 ~12 quartz_stairs 6 
setblock ~23 ~4 ~29 quartz_stairs 7 
setblock ~23 ~4 ~30 quartz_stairs 2 
setblock ~23 ~4 ~31 quartz_stairs 3 
setblock ~23 ~4 ~33 quartz_stairs 2 
setblock ~23 ~4 ~34 quartz_stairs 3 
setblock ~23 ~4 ~36 quartz_stairs 2 
setblock ~23 ~4 ~37 quartz_stairs 3  
fill ~24 ~4 ~12 ~25 ~4 ~12 stone_slab 14  
fill ~24 ~4 ~29 ~25 ~4 ~29 stone_slab 14 
setblock ~26 ~4 ~12 quartz_stairs 6 
setblock ~26 ~4 ~29 quartz_stairs 7 
setblock ~27 ~4 ~13 quartz_stairs 5  
fill ~27 ~4 ~14 ~27 ~4 ~15 stone_slab 14 
setblock ~27 ~4 ~16 quartz_stairs 5  
fill ~27 ~4 ~17 ~27 ~4 ~18 stone_slab 14 
setblock ~27 ~4 ~19 quartz_stairs 5  
fill ~27 ~4 ~20 ~27 ~4 ~21 stone_slab 14 
setblock ~27 ~4 ~22 quartz_stairs 5  
fill ~27 ~4 ~23 ~27 ~4 ~24 stone_slab 14 
setblock ~27 ~4 ~25 quartz_stairs 5  
fill ~27 ~4 ~26 ~27 ~4 ~27 stone_slab 14 
setblock ~27 ~4 ~28 quartz_stairs 5 
setblock ~37 ~4 ~15 stone_slab 6 
setblock ~37 ~4 ~26 stone_slab 6 
setblock ~38 ~4 ~15 quartz_stairs 0 
setblock ~38 ~4 ~26 quartz_stairs 0 
setblock ~39 ~4 ~14 stone_stairs 2 
setblock ~39 ~4 ~16 stone_stairs 3 
setblock ~39 ~4 ~25 stone_stairs 2 
setblock ~39 ~4 ~27 stone_stairs 3 
setblock ~40 ~4 ~15 quartz_stairs 1 
setblock ~40 ~4 ~26 quartz_stairs 1 
setblock ~2 ~5 ~13 quartz_stairs 0 
setblock ~2 ~5 ~16 quartz_stairs 0 
setblock ~2 ~5 ~19 quartz_stairs 0 
setblock ~2 ~5 ~22 quartz_stairs 0 
setblock ~2 ~5 ~25 quartz_stairs 0 
setblock ~2 ~5 ~28 quartz_stairs 0 
setblock ~3 ~5 ~12 quartz_stairs 2  
fill ~3 ~5 ~13 ~3 ~11 ~13 quartz_block 2  
fill ~3 ~5 ~14 ~3 ~5 ~15 anvil 2  
fill ~3 ~5 ~16 ~3 ~11 ~16 quartz_block 2  
fill ~3 ~5 ~17 ~3 ~5 ~18 anvil 2  
fill ~3 ~5 ~19 ~3 ~11 ~19 quartz_block 2  
fill ~3 ~5 ~20 ~3 ~5 ~21 anvil 2  
fill ~3 ~5 ~22 ~3 ~11 ~22 quartz_block 2  
fill ~3 ~5 ~23 ~3 ~5 ~24 anvil 2  
fill ~3 ~5 ~25 ~3 ~11 ~25 quartz_block 2  
fill ~3 ~5 ~26 ~3 ~5 ~27 anvil 2  
fill ~3 ~5 ~28 ~3 ~11 ~28 quartz_block 2 
setblock ~3 ~5 ~29 quartz_stairs 3  
fill ~4 ~5 ~13 ~5 ~5 ~13 anvil 3  
fill ~4 ~5 ~28 ~5 ~5 ~28 anvil 1 
setblock ~6 ~5 ~12 quartz_stairs 2  
fill ~6 ~5 ~13 ~6 ~11 ~13 quartz_block 2  
fill ~6 ~5 ~28 ~6 ~11 ~28 quartz_block 2 
setblock ~6 ~5 ~29 quartz_stairs 3  
fill ~7 ~5 ~4 ~7 ~5 ~13 sandstone 2  
fill ~7 ~5 ~14 ~7 ~8 ~14 stained_glass_pane 9  
fill ~7 ~5 ~15 ~7 ~8 ~15 stained_glass_pane 9  
fill ~7 ~5 ~16 ~7 ~12 ~16 sandstone 2  
fill ~7 ~5 ~17 ~7 ~8 ~17 stained_glass_pane 9  
fill ~7 ~5 ~18 ~7 ~8 ~18 stained_glass_pane 9  
fill ~7 ~5 ~19 ~7 ~12 ~19 sandstone 2  
fill ~7 ~5 ~20 ~7 ~5 ~21 dark_oak_door 2  
fill ~7 ~5 ~22 ~7 ~12 ~22 sandstone 2  
fill ~7 ~5 ~23 ~7 ~8 ~23 stained_glass_pane 9  
fill ~7 ~5 ~24 ~7 ~8 ~24 stained_glass_pane 9  
fill ~7 ~5 ~25 ~7 ~12 ~25 sandstone 2  
fill ~7 ~5 ~26 ~7 ~8 ~26 stained_glass_pane 9  
fill ~7 ~5 ~27 ~7 ~8 ~27 stained_glass_pane 9  
fill ~7 ~5 ~28 ~7 ~12 ~28 sandstone 2  
fill ~7 ~5 ~30 ~7 ~5 ~38 sandstone 2  
fill ~8 ~5 ~3 ~22 ~5 ~3 sandstone 2  
fill ~8 ~5 ~5 ~8 ~7 ~5 quartz_block 0 
setblock ~8 ~5 ~7 trapdoor 10  
fill ~8 ~5 ~9 ~19 ~5 ~9 quartz_block 0 
setblock ~8 ~5 ~11 trapdoor 10  
fill ~8 ~5 ~13 ~8 ~7 ~13 quartz_block 0  
fill ~8 ~5 ~20 ~9 ~5 ~20 carpet 15 
setblock ~8 ~5 ~21 carpet 14  
fill ~8 ~5 ~22 ~9 ~5 ~22 carpet 15 
setblock ~8 ~5 ~23 carpet 7 
setblock ~8 ~5 ~24 carpet 14  
fill ~8 ~5 ~28 ~8 ~7 ~28 quartz_block 0 
setblock ~8 ~5 ~31 dark_oak_stairs 6  
fill ~8 ~5 ~32 ~19 ~5 ~32 quartz_block 0  
fill ~8 ~5 ~33 ~9 ~5 ~33 dropper 0  
fill ~8 ~5 ~34 ~8 ~5 ~33 dropper 0 
setblock ~8 ~5 ~35 dark_oak_stairs 6  
fill ~8 ~5 ~36 ~8 ~7 ~36 quartz_block 0  
fill ~8 ~5 ~38 ~22 ~5 ~38 sandstone 2 
setblock ~9 ~5 ~7 dropper 0 
setblock ~9 ~5 ~10 stone_brick_stairs 3 
setblock ~9 ~5 ~11 dropper 0 
setblock ~9 ~5 ~18 carpet 7 
setblock ~9 ~5 ~19 carpet 14 
setblock ~9 ~5 ~21 carpet 7  
fill ~9 ~5 ~23 ~10 ~5 ~23 carpet 15 
setblock ~9 ~5 ~25 carpet 7 
setblock ~9 ~5 ~34 stone_brick_stairs 2  
fill ~10 ~5 ~5 ~12 ~5 ~5 quartz_block 0 
setblock ~10 ~5 ~7 dark_oak_stairs 4 
setblock ~10 ~5 ~11 dark_oak_stairs 4  
fill ~10 ~5 ~13 ~12 ~5 ~13 quartz_block 0 
setblock ~10 ~5 ~17 carpet 14 
setblock ~10 ~5 ~19 carpet 15 
setblock ~10 ~5 ~20 carpet 7 
setblock ~10 ~5 ~21 carpet 14 
setblock ~10 ~5 ~22 carpet 7  
fill ~10 ~5 ~28 ~12 ~5 ~28 quartz_block 0 
setblock ~10 ~5 ~29 dark_oak_stairs 7  
fill ~10 ~5 ~30 ~10 ~5 ~31 dropper 0 
setblock ~10 ~5 ~33 dark_oak_stairs 4  
fill ~10 ~5 ~36 ~12 ~5 ~36 quartz_block 0  
fill ~11 ~5 ~6 ~11 ~7 ~6 quartz_block 0  
fill ~11 ~5 ~7 ~11 ~7 ~7 quartz_block 0  
fill ~11 ~5 ~8 ~11 ~7 ~8 quartz_block 0  
fill ~11 ~5 ~10 ~11 ~7 ~10 quartz_block 0  
fill ~11 ~5 ~11 ~11 ~7 ~11 quartz_block 0  
fill ~11 ~5 ~12 ~11 ~7 ~12 quartz_block 0 
setblock ~11 ~5 ~15 stone_brick_stairs 2 
setblock ~11 ~5 ~16 stonebrick 0 
setblock ~11 ~5 ~17 stone_brick_stairs 3 
setblock ~11 ~5 ~24 stone_brick_stairs 2 
setblock ~11 ~5 ~25 stonebrick 0 
setblock ~11 ~5 ~26 stone_brick_stairs 3  
fill ~11 ~5 ~29 ~11 ~7 ~29 quartz_block 0  
fill ~11 ~5 ~30 ~11 ~7 ~30 quartz_block 0  
fill ~11 ~5 ~31 ~11 ~7 ~31 quartz_block 0  
fill ~11 ~5 ~33 ~11 ~7 ~33 quartz_block 0  
fill ~11 ~5 ~34 ~11 ~7 ~34 quartz_block 0  
fill ~11 ~5 ~35 ~11 ~7 ~35 quartz_block 0 
setblock ~12 ~5 ~7 trapdoor 11 
setblock ~12 ~5 ~12 stone_brick_stairs 2  
fill ~12 ~5 ~29 ~12 ~5 ~30 dropper 0 
setblock ~12 ~5 ~31 dark_oak_stairs 6 
setblock ~12 ~5 ~33 dark_oak_stairs 5 
setblock ~13 ~5 ~7 dropper 0 
setblock ~13 ~5 ~8 stone_brick_stairs 2 
setblock ~13 ~5 ~10 stone_brick_stairs 3 
setblock ~13 ~5 ~11 dropper 0 
setblock ~13 ~5 ~30 stone_brick_stairs 0  
fill ~13 ~5 ~33 ~14 ~5 ~33 dropper 0 
setblock ~13 ~5 ~34 stone_brick_stairs 2  
fill ~14 ~5 ~5 ~16 ~5 ~5 quartz_block 0 
setblock ~14 ~5 ~7 dark_oak_stairs 4 
setblock ~14 ~5 ~11 dark_oak_stairs 4 
setblock ~14 ~5 ~12 stone_brick_stairs 2  
fill ~14 ~5 ~13 ~16 ~5 ~13 quartz_block 0 
setblock ~14 ~5 ~15 stone_brick_stairs 2 
setblock ~14 ~5 ~16 stonebrick 0 
setblock ~14 ~5 ~17 stone_brick_stairs 3 
setblock ~14 ~5 ~24 stone_brick_stairs 2 
setblock ~14 ~5 ~25 stonebrick 0 
setblock ~14 ~5 ~26 stone_brick_stairs 3  
fill ~14 ~5 ~28 ~15 ~5 ~28 quartz_block 0  
fill ~14 ~5 ~36 ~16 ~5 ~36 quartz_block 0  
fill ~15 ~5 ~6 ~15 ~7 ~6 quartz_block 0  
fill ~15 ~5 ~7 ~15 ~7 ~7 quartz_block 0  
fill ~15 ~5 ~8 ~15 ~7 ~8 quartz_block 0  
fill ~15 ~5 ~10 ~15 ~7 ~10 quartz_block 0  
fill ~15 ~5 ~11 ~15 ~7 ~11 quartz_block 0  
fill ~15 ~5 ~12 ~15 ~7 ~12 quartz_block 0  
fill ~15 ~5 ~17 ~16 ~5 ~17 carpet 14  
fill ~15 ~5 ~29 ~15 ~7 ~29 quartz_block 0  
fill ~15 ~5 ~30 ~15 ~7 ~30 quartz_block 0  
fill ~15 ~5 ~31 ~15 ~7 ~31 quartz_block 0  
fill ~15 ~5 ~33 ~15 ~7 ~33 quartz_block 0  
fill ~15 ~5 ~34 ~15 ~7 ~34 quartz_block 0  
fill ~15 ~5 ~35 ~15 ~7 ~35 quartz_block 0 
setblock ~16 ~5 ~7 dark_oak_stairs 5 
setblock ~16 ~5 ~11 dark_oak_stairs 5 
setblock ~16 ~5 ~12 stone_brick_stairs 2 
setblock ~16 ~5 ~15 carpet 14 
setblock ~16 ~5 ~16 carpet 7 
setblock ~16 ~5 ~18 carpet 7  
fill ~16 ~5 ~24 ~17 ~5 ~24 snow_layer 0  
fill ~16 ~5 ~25 ~17 ~5 ~25 snow_layer 0  
fill ~16 ~5 ~27 ~18 ~5 ~27 snow_layer 0  
fill ~16 ~5 ~28 ~17 ~5 ~28 snow_layer 0 
setblock ~17 ~5 ~7 dropper 0 
setblock ~17 ~5 ~8 stone_brick_stairs 2 
setblock ~17 ~5 ~10 stone_brick_stairs 3 
setblock ~17 ~5 ~11 dropper 0 
setblock ~17 ~5 ~15 carpet 7  
fill ~17 ~5 ~16 ~18 ~5 ~16 carpet 14 
setblock ~17 ~5 ~17 carpet 7  
fill ~17 ~5 ~18 ~21 ~5 ~18 carpet 14  
fill ~17 ~5 ~19 ~18 ~5 ~19 carpet 14 
setblock ~17 ~5 ~20 carpet 15  
fill ~17 ~5 ~23 ~19 ~5 ~23 snow_layer 0 
setblock ~17 ~5 ~26 snow_layer 0  
fill ~17 ~5 ~29 ~20 ~5 ~29 snow_layer 0 
setblock ~17 ~5 ~34 stone_brick_stairs 1  
fill ~18 ~5 ~5 ~19 ~5 ~5 quartz_block 0 
setblock ~18 ~5 ~7 trapdoor 11 
setblock ~18 ~5 ~12 stone_brick_stairs 2  
fill ~18 ~5 ~13 ~19 ~5 ~13 quartz_block 0 
setblock ~18 ~5 ~17 carpet 14 
setblock ~18 ~5 ~20 carpet 7 
setblock ~18 ~5 ~21 carpet 15  
fill ~18 ~5 ~24 ~18 ~5 ~26 stone_slab 6  
fill ~18 ~5 ~28 ~19 ~5 ~28 stone_slab 6 
setblock ~18 ~5 ~30 quartz_stairs 1  
fill ~18 ~5 ~33 ~18 ~5 ~34 dropper 0 
setblock ~18 ~5 ~35 dark_oak_stairs 6  
fill ~18 ~5 ~36 ~19 ~5 ~36 quartz_block 0  
fill ~19 ~5 ~6 ~19 ~7 ~6 quartz_block 0  
fill ~19 ~5 ~7 ~19 ~7 ~7 quartz_block 0  
fill ~19 ~5 ~8 ~19 ~7 ~8 quartz_block 0  
fill ~19 ~5 ~10 ~19 ~7 ~10 quartz_block 0  
fill ~19 ~5 ~11 ~19 ~7 ~11 quartz_block 0  
fill ~19 ~5 ~12 ~19 ~7 ~12 quartz_block 0  
fill ~19 ~5 ~16 ~19 ~5 ~17 carpet 15 
setblock ~19 ~5 ~19 carpet 7 
setblock ~19 ~5 ~20 carpet 14 
setblock ~19 ~5 ~22 quartz_stairs 3  
fill ~19 ~5 ~24 ~19 ~5 ~25 snow_layer 0  
fill ~19 ~5 ~26 ~19 ~5 ~28 stone_slab 6  
fill ~19 ~5 ~30 ~21 ~5 ~30 quartz_stairs 2  
fill ~19 ~5 ~33 ~19 ~7 ~33 quartz_block 0  
fill ~19 ~5 ~34 ~19 ~7 ~34 quartz_block 0  
fill ~19 ~5 ~35 ~19 ~7 ~35 quartz_block 0 
setblock ~20 ~5 ~15 carpet 7  
fill ~20 ~5 ~16 ~21 ~5 ~16 carpet 14  
fill ~20 ~5 ~17 ~20 ~5 ~16 carpet 14  
fill ~20 ~5 ~19 ~20 ~5 ~21 carpet 15  
fill ~20 ~5 ~22 ~20 ~5 ~23 quartz_stairs 0 
setblock ~20 ~5 ~24 quartz_stairs 3  
fill ~20 ~5 ~25 ~20 ~5 ~29 snow_layer 0 
setblock ~21 ~5 ~19 carpet 7  
fill ~21 ~5 ~24 ~21 ~5 ~29 quartz_stairs 0  
fill ~22 ~5 ~4 ~22 ~5 ~13 sandstone 2  
fill ~22 ~5 ~14 ~22 ~8 ~14 stained_glass_pane 9  
fill ~22 ~5 ~15 ~22 ~8 ~15 stained_glass_pane 9  
fill ~22 ~5 ~16 ~22 ~12 ~16 sandstone 2  
fill ~22 ~5 ~17 ~22 ~8 ~17 stained_glass_pane 9  
fill ~22 ~5 ~18 ~22 ~8 ~18 stained_glass_pane 9  
fill ~22 ~5 ~19 ~22 ~12 ~19 sandstone 2  
fill ~22 ~5 ~20 ~22 ~5 ~21 dark_oak_door 0  
fill ~22 ~5 ~22 ~22 ~12 ~22 sandstone 2  
fill ~22 ~5 ~23 ~22 ~8 ~23 stained_glass_pane 9  
fill ~22 ~5 ~24 ~22 ~8 ~24 stained_glass_pane 9  
fill ~22 ~5 ~25 ~22 ~12 ~25 sandstone 2  
fill ~22 ~5 ~26 ~22 ~8 ~26 stained_glass_pane 9  
fill ~22 ~5 ~27 ~22 ~8 ~27 stained_glass_pane 9  
fill ~22 ~5 ~28 ~22 ~12 ~28 sandstone 2  
fill ~22 ~5 ~30 ~22 ~5 ~38 sandstone 2 
setblock ~23 ~5 ~12 quartz_stairs 2  
fill ~23 ~5 ~13 ~23 ~11 ~13 quartz_block 2  
fill ~23 ~5 ~28 ~23 ~11 ~28 quartz_block 2 
setblock ~23 ~5 ~29 quartz_stairs 3  
fill ~24 ~5 ~13 ~25 ~5 ~13 anvil 1  
fill ~24 ~5 ~28 ~25 ~5 ~28 anvil 3 
setblock ~26 ~5 ~12 quartz_stairs 2  
fill ~26 ~5 ~13 ~26 ~11 ~13 quartz_block 2  
fill ~26 ~5 ~14 ~26 ~5 ~15 anvil 2  
fill ~26 ~5 ~16 ~26 ~11 ~16 quartz_block 2  
fill ~26 ~5 ~17 ~26 ~5 ~18 anvil 2  
fill ~26 ~5 ~19 ~26 ~11 ~19 quartz_block 2  
fill ~26 ~5 ~20 ~26 ~5 ~21 anvil 2  
fill ~26 ~5 ~22 ~26 ~11 ~22 quartz_block 2  
fill ~26 ~5 ~23 ~26 ~5 ~24 anvil 2  
fill ~26 ~5 ~25 ~26 ~11 ~25 quartz_block 2  
fill ~26 ~5 ~26 ~26 ~5 ~27 anvil 2  
fill ~26 ~5 ~28 ~26 ~11 ~28 quartz_block 2 
setblock ~26 ~5 ~29 quartz_stairs 3 
setblock ~27 ~5 ~13 quartz_stairs 1 
setblock ~27 ~5 ~16 quartz_stairs 1 
setblock ~27 ~5 ~19 quartz_stairs 1 
setblock ~27 ~5 ~22 quartz_stairs 1 
setblock ~27 ~5 ~25 quartz_stairs 1 
setblock ~27 ~5 ~28 quartz_stairs 1 
setblock ~39 ~5 ~15 stone_slab 3 
setblock ~39 ~5 ~26 stone_slab 3  
fill ~3 ~6 ~14 ~3 ~6 ~15 stone_slab 6  
fill ~3 ~6 ~17 ~3 ~6 ~18 stone_slab 6  
fill ~3 ~6 ~20 ~3 ~6 ~21 stone_slab 6  
fill ~3 ~6 ~23 ~3 ~6 ~24 stone_slab 6  
fill ~3 ~6 ~26 ~3 ~6 ~27 stone_slab 6  
fill ~4 ~6 ~13 ~5 ~6 ~13 stone_slab 6  
fill ~4 ~6 ~28 ~5 ~6 ~28 stone_slab 6  
fill ~7 ~6 ~4 ~7 ~8 ~4 stained_glass_pane 9  
fill ~7 ~6 ~5 ~7 ~8 ~5 stained_glass_pane 9  
fill ~7 ~6 ~7 ~7 ~8 ~7 stained_glass_pane 9  
fill ~7 ~6 ~8 ~7 ~8 ~8 stained_glass_pane 9  
fill ~7 ~6 ~10 ~7 ~8 ~10 stained_glass_pane 9  
fill ~7 ~6 ~11 ~7 ~8 ~11 stained_glass_pane 9  
fill ~7 ~6 ~13 ~7 ~12 ~13 sandstone 2 
setblock ~7 ~6 ~20 dark_oak_door 9 
setblock ~7 ~6 ~21 dark_oak_door 8  
fill ~7 ~6 ~30 ~7 ~8 ~30 stained_glass_pane 9  
fill ~7 ~6 ~31 ~7 ~8 ~31 stained_glass_pane 9  
fill ~7 ~6 ~33 ~7 ~8 ~33 stained_glass_pane 9  
fill ~7 ~6 ~34 ~7 ~8 ~34 stained_glass_pane 9  
fill ~7 ~6 ~36 ~7 ~8 ~36 stained_glass_pane 9  
fill ~7 ~6 ~37 ~7 ~8 ~37 stained_glass_pane 9  
fill ~8 ~6 ~3 ~9 ~6 ~3 stained_glass_pane 9  
fill ~8 ~6 ~9 ~19 ~6 ~9 quartz_block 0 
setblock ~8 ~6 ~31 flower_pot 0  
fill ~8 ~6 ~32 ~19 ~6 ~32 quartz_block 0 
setblock ~8 ~6 ~35 heavy_weighted_pressure_plate 0  
fill ~8 ~6 ~38 ~9 ~6 ~38 stained_glass_pane 9 
setblock ~9 ~6 ~7 light_weighted_pressure_plate 0 
setblock ~9 ~6 ~11 heavy_weighted_pressure_plate 0 
setblock ~9 ~6 ~33 light_weighted_pressure_plate 0  
fill ~10 ~6 ~5 ~12 ~6 ~5 quartz_block 0 
setblock ~10 ~6 ~7 flower_pot 0 
setblock ~10 ~6 ~11 flower_pot 0  
fill ~10 ~6 ~13 ~12 ~6 ~13 quartz_block 0  
fill ~10 ~6 ~28 ~12 ~6 ~28 quartz_block 0 
setblock ~10 ~6 ~30 light_weighted_pressure_plate 0 
setblock ~10 ~6 ~33 flower_pot 0  
fill ~10 ~6 ~36 ~12 ~6 ~36 quartz_block 0  
fill ~11 ~6 ~3 ~12 ~6 ~3 stained_glass_pane 9  
fill ~11 ~6 ~38 ~12 ~6 ~38 stained_glass_pane 9 
setblock ~12 ~6 ~30 light_weighted_pressure_plate 0 
setblock ~13 ~6 ~7 light_weighted_pressure_plate 0 
setblock ~13 ~6 ~11 heavy_weighted_pressure_plate 0 
setblock ~13 ~6 ~33 heavy_weighted_pressure_plate 0  
fill ~14 ~6 ~3 ~15 ~6 ~3 stained_glass_pane 9  
fill ~14 ~6 ~5 ~16 ~6 ~5 quartz_block 0 
setblock ~14 ~6 ~7 flower_pot 0 
setblock ~14 ~6 ~11 flower_pot 0  
fill ~14 ~6 ~13 ~16 ~6 ~13 quartz_block 0  
fill ~14 ~6 ~28 ~15 ~6 ~28 quartz_block 0  
fill ~14 ~6 ~36 ~16 ~6 ~36 quartz_block 0  
fill ~14 ~6 ~38 ~15 ~6 ~38 stained_glass_pane 9 
setblock ~16 ~6 ~7 flower_pot 0 
setblock ~16 ~6 ~11 flower_pot 0  
fill ~17 ~6 ~3 ~18 ~6 ~3 stained_glass_pane 9 
setblock ~17 ~6 ~7 heavy_weighted_pressure_plate 0 
setblock ~17 ~6 ~11 light_weighted_pressure_plate 0  
fill ~17 ~6 ~38 ~18 ~6 ~38 stained_glass_pane 9  
fill ~18 ~6 ~5 ~19 ~6 ~5 quartz_block 0  
fill ~18 ~6 ~13 ~19 ~6 ~13 quartz_block 0 
setblock ~18 ~6 ~33 flower_pot 0 
setblock ~18 ~6 ~34 heavy_weighted_pressure_plate 0  
fill ~18 ~6 ~36 ~19 ~6 ~36 quartz_block 0  
fill ~20 ~6 ~3 ~21 ~6 ~3 stained_glass_pane 9  
fill ~20 ~6 ~38 ~21 ~6 ~38 stained_glass_pane 9  
fill ~22 ~6 ~4 ~22 ~8 ~4 stained_glass_pane 9  
fill ~22 ~6 ~5 ~22 ~8 ~5 stained_glass_pane 9  
fill ~22 ~6 ~7 ~22 ~8 ~7 stained_glass_pane 9  
fill ~22 ~6 ~8 ~22 ~8 ~8 stained_glass_pane 9  
fill ~22 ~6 ~10 ~22 ~8 ~10 stained_glass_pane 9  
fill ~22 ~6 ~11 ~22 ~8 ~11 stained_glass_pane 9  
fill ~22 ~6 ~13 ~22 ~12 ~13 sandstone 2 
setblock ~22 ~6 ~20 dark_oak_door 8 
setblock ~22 ~6 ~21 dark_oak_door 9  
fill ~22 ~6 ~30 ~22 ~8 ~30 stained_glass_pane 9  
fill ~22 ~6 ~31 ~22 ~8 ~31 stained_glass_pane 9  
fill ~22 ~6 ~33 ~22 ~8 ~33 stained_glass_pane 9  
fill ~22 ~6 ~34 ~22 ~8 ~34 stained_glass_pane 9  
fill ~22 ~6 ~36 ~22 ~8 ~36 stained_glass_pane 9  
fill ~22 ~6 ~37 ~22 ~8 ~37 stained_glass_pane 9  
fill ~24 ~6 ~13 ~25 ~6 ~13 stone_slab 6  
fill ~24 ~6 ~28 ~25 ~6 ~28 stone_slab 6  
fill ~26 ~6 ~14 ~26 ~6 ~15 stone_slab 6  
fill ~26 ~6 ~17 ~26 ~6 ~18 stone_slab 6  
fill ~26 ~6 ~20 ~26 ~6 ~21 stone_slab 6  
fill ~26 ~6 ~23 ~26 ~6 ~24 stone_slab 6  
fill ~26 ~6 ~26 ~26 ~6 ~27 stone_slab 6  
fill ~7 ~7 ~20 ~7 ~7 ~21 sandstone_stairs 4  
fill ~8 ~7 ~3 ~9 ~7 ~3 stained_glass_pane 9  
fill ~8 ~7 ~9 ~19 ~7 ~9 quartz_block 0  
fill ~8 ~7 ~32 ~19 ~7 ~32 quartz_block 0  
fill ~8 ~7 ~38 ~9 ~7 ~38 stained_glass_pane 9 
setblock ~9 ~7 ~13 stone_slab 6 
setblock ~9 ~7 ~28 stone_slab 6 
setblock ~9 ~7 ~36 stone_slab 6  
fill ~10 ~7 ~5 ~12 ~7 ~5 quartz_block 0  
fill ~10 ~7 ~13 ~12 ~7 ~13 quartz_block 0  
fill ~10 ~7 ~28 ~12 ~7 ~28 quartz_block 0  
fill ~10 ~7 ~36 ~12 ~7 ~36 quartz_block 0  
fill ~11 ~7 ~3 ~12 ~7 ~3 stained_glass_pane 9  
fill ~11 ~7 ~38 ~12 ~7 ~38 stained_glass_pane 9 
setblock ~13 ~7 ~5 stone_slab 6 
setblock ~13 ~7 ~13 stone_slab 6 
setblock ~13 ~7 ~28 stone_slab 6 
setblock ~13 ~7 ~36 stone_slab 6  
fill ~14 ~7 ~3 ~15 ~7 ~3 stained_glass_pane 9  
fill ~14 ~7 ~5 ~16 ~7 ~5 quartz_block 0  
fill ~14 ~7 ~13 ~16 ~7 ~13 quartz_block 0  
fill ~14 ~7 ~28 ~15 ~7 ~28 quartz_block 0  
fill ~14 ~7 ~36 ~16 ~7 ~36 quartz_block 0  
fill ~14 ~7 ~38 ~15 ~7 ~38 stained_glass_pane 9  
fill ~17 ~7 ~3 ~18 ~7 ~3 stained_glass_pane 9 
setblock ~17 ~7 ~5 stone_slab 6 
setblock ~17 ~7 ~13 stone_slab 6 
setblock ~17 ~7 ~36 stone_slab 6  
fill ~17 ~7 ~38 ~18 ~7 ~38 stained_glass_pane 9  
fill ~18 ~7 ~5 ~19 ~7 ~5 quartz_block 0  
fill ~18 ~7 ~13 ~19 ~7 ~13 quartz_block 0  
fill ~18 ~7 ~36 ~19 ~7 ~36 quartz_block 0  
fill ~20 ~7 ~3 ~21 ~7 ~3 stained_glass_pane 9  
fill ~20 ~7 ~38 ~21 ~7 ~38 stained_glass_pane 9  
fill ~22 ~7 ~20 ~22 ~7 ~21 sandstone_stairs 5  
fill ~7 ~8 ~20 ~7 ~8 ~22 sandstone 2  
fill ~8 ~8 ~3 ~9 ~8 ~3 stained_glass_pane 9  
fill ~8 ~8 ~38 ~9 ~8 ~38 stained_glass_pane 9  
fill ~11 ~8 ~3 ~12 ~8 ~3 stained_glass_pane 9  
fill ~11 ~8 ~38 ~12 ~8 ~38 stained_glass_pane 9  
fill ~14 ~8 ~3 ~15 ~8 ~3 stained_glass_pane 9  
fill ~14 ~8 ~38 ~15 ~8 ~38 stained_glass_pane 9  
fill ~17 ~8 ~3 ~18 ~8 ~3 stained_glass_pane 9  
fill ~17 ~8 ~38 ~18 ~8 ~38 stained_glass_pane 9  
fill ~20 ~8 ~3 ~21 ~8 ~3 stained_glass_pane 9  
fill ~20 ~8 ~38 ~21 ~8 ~38 stained_glass_pane 9  
fill ~22 ~8 ~20 ~22 ~8 ~22 sandstone 2 
setblock ~6 ~9 ~4 quartz_stairs 2 
setblock ~6 ~9 ~5 quartz_stairs 3 
setblock ~6 ~9 ~7 quartz_stairs 2 
setblock ~6 ~9 ~8 quartz_stairs 3 
setblock ~6 ~9 ~10 quartz_stairs 2 
setblock ~6 ~9 ~11 quartz_stairs 3 
setblock ~6 ~9 ~14 quartz_stairs 2 
setblock ~6 ~9 ~15 quartz_stairs 3 
setblock ~6 ~9 ~17 quartz_stairs 2 
setblock ~6 ~9 ~18 quartz_stairs 3 
setblock ~6 ~9 ~20 quartz_stairs 2 
setblock ~6 ~9 ~21 quartz_stairs 3 
setblock ~6 ~9 ~23 quartz_stairs 2 
setblock ~6 ~9 ~24 quartz_stairs 3 
setblock ~6 ~9 ~26 quartz_stairs 2 
setblock ~6 ~9 ~27 quartz_stairs 3 
setblock ~6 ~9 ~30 quartz_stairs 2 
setblock ~6 ~9 ~31 quartz_stairs 3 
setblock ~6 ~9 ~33 quartz_stairs 2 
setblock ~6 ~9 ~34 quartz_stairs 3 
setblock ~6 ~9 ~36 quartz_stairs 2 
setblock ~6 ~9 ~37 quartz_stairs 3  
fill ~7 ~9 ~4 ~7 ~9 ~5 quartz_block 10  
fill ~7 ~9 ~7 ~7 ~9 ~8 quartz_block 10  
fill ~7 ~9 ~10 ~7 ~9 ~11 quartz_block 10  
fill ~7 ~9 ~14 ~7 ~9 ~15 quartz_block 10  
fill ~7 ~9 ~17 ~7 ~9 ~18 quartz_block 10  
fill ~7 ~9 ~20 ~7 ~9 ~21 quartz_block 10  
fill ~7 ~9 ~23 ~7 ~9 ~24 quartz_block 10  
fill ~7 ~9 ~26 ~7 ~9 ~27 quartz_block 10  
fill ~7 ~9 ~30 ~7 ~9 ~31 quartz_block 10  
fill ~7 ~9 ~33 ~7 ~9 ~34 quartz_block 10  
fill ~7 ~9 ~36 ~7 ~9 ~37 quartz_block 10 
setblock ~8 ~9 ~2 quartz_stairs 0  
fill ~8 ~9 ~3 ~9 ~9 ~3 quartz_block 6  
fill ~8 ~9 ~38 ~9 ~9 ~38 quartz_block 6 
setblock ~8 ~9 ~39 quartz_stairs 0 
setblock ~9 ~9 ~2 quartz_stairs 1 
setblock ~9 ~9 ~39 quartz_stairs 1 
setblock ~11 ~9 ~2 quartz_stairs 0  
fill ~11 ~9 ~3 ~12 ~9 ~3 quartz_block 6  
fill ~11 ~9 ~38 ~12 ~9 ~38 quartz_block 6 
setblock ~11 ~9 ~39 quartz_stairs 0 
setblock ~12 ~9 ~2 quartz_stairs 1 
setblock ~12 ~9 ~39 quartz_stairs 1 
setblock ~14 ~9 ~2 quartz_stairs 0  
fill ~14 ~9 ~3 ~15 ~9 ~3 quartz_block 6  
fill ~14 ~9 ~38 ~15 ~9 ~38 quartz_block 6 
setblock ~14 ~9 ~39 quartz_stairs 0 
setblock ~15 ~9 ~2 quartz_stairs 1 
setblock ~15 ~9 ~39 quartz_stairs 1 
setblock ~17 ~9 ~2 quartz_stairs 0  
fill ~17 ~9 ~3 ~18 ~9 ~3 quartz_block 6  
fill ~17 ~9 ~38 ~18 ~9 ~38 quartz_block 6 
setblock ~17 ~9 ~39 quartz_stairs 0 
setblock ~18 ~9 ~2 quartz_stairs 1 
setblock ~18 ~9 ~39 quartz_stairs 1 
setblock ~20 ~9 ~2 quartz_stairs 0  
fill ~20 ~9 ~3 ~21 ~9 ~3 quartz_block 6  
fill ~20 ~9 ~38 ~21 ~9 ~38 quartz_block 6 
setblock ~20 ~9 ~39 quartz_stairs 0 
setblock ~21 ~9 ~2 quartz_stairs 1 
setblock ~21 ~9 ~39 quartz_stairs 1  
fill ~22 ~9 ~4 ~22 ~9 ~5 quartz_block 10  
fill ~22 ~9 ~7 ~22 ~9 ~8 quartz_block 10  
fill ~22 ~9 ~10 ~22 ~9 ~11 quartz_block 10  
fill ~22 ~9 ~14 ~22 ~9 ~15 quartz_block 10  
fill ~22 ~9 ~17 ~22 ~9 ~18 quartz_block 10  
fill ~22 ~9 ~20 ~22 ~9 ~21 quartz_block 10  
fill ~22 ~9 ~23 ~22 ~9 ~24 quartz_block 10  
fill ~22 ~9 ~26 ~22 ~9 ~27 quartz_block 10  
fill ~22 ~9 ~30 ~22 ~9 ~31 quartz_block 10  
fill ~22 ~9 ~33 ~22 ~9 ~34 quartz_block 10  
fill ~22 ~9 ~36 ~22 ~9 ~37 quartz_block 10 
setblock ~23 ~9 ~4 quartz_stairs 2 
setblock ~23 ~9 ~5 quartz_stairs 3 
setblock ~23 ~9 ~7 quartz_stairs 2 
setblock ~23 ~9 ~8 quartz_stairs 3 
setblock ~23 ~9 ~10 quartz_stairs 2 
setblock ~23 ~9 ~11 quartz_stairs 3 
setblock ~23 ~9 ~14 quartz_stairs 2 
setblock ~23 ~9 ~15 quartz_stairs 3 
setblock ~23 ~9 ~17 quartz_stairs 2 
setblock ~23 ~9 ~18 quartz_stairs 3 
setblock ~23 ~9 ~20 quartz_stairs 2 
setblock ~23 ~9 ~21 quartz_stairs 3 
setblock ~23 ~9 ~23 quartz_stairs 2 
setblock ~23 ~9 ~24 quartz_stairs 3 
setblock ~23 ~9 ~26 quartz_stairs 2 
setblock ~23 ~9 ~27 quartz_stairs 3 
setblock ~23 ~9 ~30 quartz_stairs 2 
setblock ~23 ~9 ~31 quartz_stairs 3 
setblock ~23 ~9 ~33 quartz_stairs 2 
setblock ~23 ~9 ~34 quartz_stairs 3 
setblock ~23 ~9 ~36 quartz_stairs 2 
setblock ~23 ~9 ~37 quartz_stairs 3 
setblock ~6 ~10 ~3 quartz_stairs 4 
setblock ~6 ~10 ~6 quartz_stairs 4 
setblock ~6 ~10 ~9 quartz_stairs 4 
setblock ~6 ~10 ~16 stone_slab 14  
fill ~6 ~10 ~17 ~6 ~10 ~19 stone_slab 6  
fill ~6 ~10 ~20 ~6 ~10 ~21 stone_slab 14  
fill ~6 ~10 ~22 ~6 ~10 ~24 stone_slab 6 
setblock ~6 ~10 ~25 stone_slab 14 
setblock ~6 ~10 ~32 quartz_stairs 4 
setblock ~6 ~10 ~35 quartz_stairs 4 
setblock ~6 ~10 ~38 quartz_stairs 4 
setblock ~7 ~10 ~2 quartz_stairs 6  
fill ~7 ~10 ~4 ~7 ~10 ~38 sandstone 2 
setblock ~7 ~10 ~39 quartz_stairs 7  
fill ~8 ~10 ~3 ~22 ~10 ~3 sandstone 2  
fill ~8 ~10 ~38 ~22 ~10 ~38 sandstone 2 
setblock ~10 ~10 ~2 quartz_stairs 6 
setblock ~10 ~10 ~39 quartz_stairs 7 
setblock ~13 ~10 ~2 quartz_stairs 6 
setblock ~13 ~10 ~39 quartz_stairs 7 
setblock ~16 ~10 ~2 quartz_stairs 6 
setblock ~16 ~10 ~39 quartz_stairs 7 
setblock ~19 ~10 ~2 quartz_stairs 6 
setblock ~19 ~10 ~39 quartz_stairs 7 
setblock ~22 ~10 ~2 quartz_stairs 6  
fill ~22 ~10 ~4 ~22 ~10 ~38 sandstone 2 
setblock ~22 ~10 ~39 quartz_stairs 7 
setblock ~23 ~10 ~3 quartz_stairs 5 
setblock ~23 ~10 ~6 quartz_stairs 5 
setblock ~23 ~10 ~9 quartz_stairs 5 
setblock ~23 ~10 ~16 stone_slab 14  
fill ~23 ~10 ~17 ~23 ~10 ~19 stone_slab 6  
fill ~23 ~10 ~20 ~23 ~10 ~21 stone_slab 14  
fill ~23 ~10 ~22 ~23 ~10 ~24 stone_slab 6 
setblock ~23 ~10 ~25 stone_slab 14 
setblock ~23 ~10 ~32 quartz_stairs 5 
setblock ~23 ~10 ~35 quartz_stairs 5 
setblock ~23 ~10 ~38 quartz_stairs 5 
setblock ~2 ~11 ~13 quartz_stairs 4 
setblock ~2 ~11 ~16 quartz_stairs 4 
setblock ~2 ~11 ~19 quartz_stairs 4 
setblock ~2 ~11 ~22 quartz_stairs 4 
setblock ~2 ~11 ~25 quartz_stairs 4 
setblock ~2 ~11 ~28 quartz_stairs 4 
setblock ~3 ~11 ~12 quartz_stairs 6 
setblock ~3 ~11 ~29 quartz_stairs 7 
setblock ~6 ~11 ~3 quartz_stairs 0 
setblock ~6 ~11 ~6 quartz_stairs 0 
setblock ~6 ~11 ~9 quartz_stairs 0 
setblock ~6 ~11 ~12 quartz_stairs 6 
setblock ~6 ~11 ~14 stone_slab 14 
setblock ~6 ~11 ~15 stone_slab 6 
setblock ~6 ~11 ~18 stone_slab 6 
setblock ~6 ~11 ~19 stone_slab 14  
fill ~6 ~11 ~20 ~6 ~11 ~21 stone_slab 6 
setblock ~6 ~11 ~22 stone_slab 14 
setblock ~6 ~11 ~23 stone_slab 6 
setblock ~6 ~11 ~26 stone_slab 6 
setblock ~6 ~11 ~27 stone_slab 14 
setblock ~6 ~11 ~29 quartz_stairs 7 
setblock ~6 ~11 ~32 quartz_stairs 0 
setblock ~6 ~11 ~35 quartz_stairs 0 
setblock ~6 ~11 ~38 quartz_stairs 0 
setblock ~7 ~11 ~2 quartz_stairs 2  
fill ~7 ~11 ~3 ~22 ~11 ~3 quartz_block 0  
fill ~7 ~11 ~4 ~7 ~11 ~12 quartz_block 0  
fill ~7 ~11 ~14 ~7 ~12 ~14 sandstone 2  
fill ~7 ~11 ~15 ~7 ~12 ~15 sandstone 2  
fill ~7 ~11 ~17 ~7 ~12 ~17 sandstone 2  
fill ~7 ~11 ~18 ~7 ~12 ~18 sandstone 2  
fill ~7 ~11 ~20 ~7 ~12 ~20 sandstone 2  
fill ~7 ~11 ~21 ~7 ~12 ~21 sandstone 2  
fill ~7 ~11 ~23 ~7 ~12 ~23 sandstone 2  
fill ~7 ~11 ~24 ~7 ~12 ~24 sandstone 2  
fill ~7 ~11 ~26 ~7 ~12 ~26 sandstone 2  
fill ~7 ~11 ~27 ~7 ~12 ~27 sandstone 2  
fill ~7 ~11 ~29 ~7 ~11 ~38 quartz_block 0 
setblock ~7 ~11 ~39 quartz_stairs 3  
fill ~8 ~11 ~38 ~22 ~11 ~38 quartz_block 0 
setblock ~10 ~11 ~2 quartz_stairs 2 
setblock ~10 ~11 ~39 quartz_stairs 3 
setblock ~13 ~11 ~2 quartz_stairs 2 
setblock ~13 ~11 ~39 quartz_stairs 3 
setblock ~16 ~11 ~2 quartz_stairs 2 
setblock ~16 ~11 ~39 quartz_stairs 3 
setblock ~19 ~11 ~2 quartz_stairs 2 
setblock ~19 ~11 ~39 quartz_stairs 3 
setblock ~22 ~11 ~2 quartz_stairs 2  
fill ~22 ~11 ~4 ~22 ~11 ~12 quartz_block 0  
fill ~22 ~11 ~14 ~22 ~12 ~14 sandstone 2  
fill ~22 ~11 ~15 ~22 ~12 ~15 sandstone 2  
fill ~22 ~11 ~17 ~22 ~12 ~17 sandstone 2  
fill ~22 ~11 ~18 ~22 ~12 ~18 sandstone 2  
fill ~22 ~11 ~20 ~22 ~12 ~20 sandstone 2  
fill ~22 ~11 ~21 ~22 ~12 ~21 sandstone 2  
fill ~22 ~11 ~23 ~22 ~12 ~23 sandstone 2  
fill ~22 ~11 ~24 ~22 ~12 ~24 sandstone 2  
fill ~22 ~11 ~26 ~22 ~12 ~26 sandstone 2  
fill ~22 ~11 ~27 ~22 ~12 ~27 sandstone 2  
fill ~22 ~11 ~29 ~22 ~11 ~38 quartz_block 0 
setblock ~22 ~11 ~39 quartz_stairs 3 
setblock ~23 ~11 ~3 quartz_stairs 1 
setblock ~23 ~11 ~6 quartz_stairs 1 
setblock ~23 ~11 ~9 quartz_stairs 1 
setblock ~23 ~11 ~12 quartz_stairs 6 
setblock ~23 ~11 ~14 stone_slab 14 
setblock ~23 ~11 ~15 stone_slab 6 
setblock ~23 ~11 ~18 stone_slab 6 
setblock ~23 ~11 ~19 stone_slab 14  
fill ~23 ~11 ~20 ~23 ~11 ~21 stone_slab 6 
setblock ~23 ~11 ~22 stone_slab 14 
setblock ~23 ~11 ~23 stone_slab 6 
setblock ~23 ~11 ~26 stone_slab 6 
setblock ~23 ~11 ~27 stone_slab 14 
setblock ~23 ~11 ~29 quartz_stairs 7 
setblock ~23 ~11 ~32 quartz_stairs 1 
setblock ~23 ~11 ~35 quartz_stairs 1 
setblock ~23 ~11 ~38 quartz_stairs 1 
setblock ~26 ~11 ~12 quartz_stairs 6 
setblock ~26 ~11 ~29 quartz_stairs 7 
setblock ~27 ~11 ~13 quartz_stairs 5 
setblock ~27 ~11 ~16 quartz_stairs 5 
setblock ~27 ~11 ~19 quartz_stairs 5 
setblock ~27 ~11 ~22 quartz_stairs 5 
setblock ~27 ~11 ~25 quartz_stairs 5 
setblock ~27 ~11 ~28 quartz_stairs 5 
setblock ~2 ~12 ~13 quartz_stairs 0 
setblock ~2 ~12 ~16 quartz_stairs 0 
setblock ~2 ~12 ~19 quartz_stairs 0 
setblock ~2 ~12 ~22 quartz_stairs 0 
setblock ~2 ~12 ~25 quartz_stairs 0 
setblock ~2 ~12 ~28 quartz_stairs 0 
setblock ~3 ~12 ~12 quartz_stairs 2  
fill ~3 ~12 ~13 ~3 ~12 ~28 quartz_block 0 
setblock ~3 ~12 ~29 quartz_stairs 3  
fill ~4 ~12 ~13 ~6 ~12 ~13 double_stone_slab 6  
fill ~4 ~12 ~28 ~6 ~12 ~28 quartz_block 0 
setblock ~6 ~12 ~12 quartz_stairs 2 
setblock ~6 ~12 ~14 stone_slab 6  
fill ~6 ~12 ~15 ~6 ~12 ~16 stone_slab 14 
setblock ~6 ~12 ~17 stone_slab 6 
setblock ~6 ~12 ~24 stone_slab 6  
fill ~6 ~12 ~25 ~6 ~12 ~26 stone_slab 14 
setblock ~6 ~12 ~27 stone_slab 6 
setblock ~6 ~12 ~29 quartz_stairs 3 
setblock ~7 ~12 ~3 quartz_block 2  
fill ~7 ~12 ~4 ~22 ~12 ~4 sandstone 2  
fill ~7 ~12 ~5 ~22 ~12 ~5 sandstone 2 
setblock ~7 ~12 ~6 quartz_block 2   
fill ~7 ~12 ~7 ~22 ~12 ~7 sandstone 2  
fill ~7 ~12 ~8 ~22 ~12 ~8 sandstone 2 
setblock ~7 ~12 ~9 quartz_block 2  
fill ~7 ~12 ~10 ~22 ~12 ~10 sandstone 2  
fill ~7 ~12 ~11 ~22 ~12 ~11 sandstone 2 
setblock ~7 ~12 ~12 quartz_block 2 
setblock ~7 ~12 ~29 quartz_block 2  
fill ~7 ~12 ~30 ~22 ~12 ~30 sandstone 2  
fill ~7 ~12 ~31 ~22 ~12 ~31 sandstone 2 
setblock ~7 ~12 ~32 quartz_block 2  
fill ~7 ~12 ~33 ~22 ~12 ~33 sandstone 2  
fill ~7 ~12 ~34 ~22 ~12 ~34 sandstone 2 
setblock ~7 ~12 ~35 quartz_block 2  
fill ~7 ~12 ~36 ~22 ~12 ~36 sandstone 2  
fill ~7 ~12 ~37 ~22 ~12 ~37 sandstone 2 
setblock ~7 ~12 ~38 quartz_block 2  
fill ~8 ~12 ~3 ~9 ~12 ~3 sandstone 2  
fill ~8 ~12 ~6 ~21 ~12 ~6 sandstone 2  
fill ~8 ~12 ~9 ~21 ~12 ~9 sandstone 2  
fill ~8 ~12 ~12 ~21 ~12 ~12 sandstone 2  
fill ~8 ~12 ~13 ~22 ~12 ~13 sandstone 2  
fill ~8 ~12 ~14 ~22 ~12 ~14 sandstone 2  
fill ~8 ~12 ~15 ~22 ~12 ~15 sandstone 2  
fill ~8 ~12 ~16 ~22 ~12 ~16 sandstone 2  
fill ~8 ~12 ~17 ~22 ~12 ~17 sandstone 2  
fill ~8 ~12 ~18 ~22 ~12 ~18 sandstone 2  
fill ~8 ~12 ~19 ~22 ~12 ~19 sandstone 2  
fill ~8 ~12 ~20 ~22 ~12 ~20 sandstone 2  
fill ~8 ~12 ~21 ~22 ~12 ~21 sandstone 2  
fill ~8 ~12 ~22 ~22 ~12 ~22 sandstone 2  
fill ~8 ~12 ~23 ~22 ~12 ~23 sandstone 2  
fill ~8 ~12 ~24 ~22 ~12 ~24 sandstone 2  
fill ~8 ~12 ~25 ~22 ~12 ~25 sandstone 2  
fill ~8 ~12 ~26 ~22 ~12 ~26 sandstone 2  
fill ~8 ~12 ~27 ~22 ~12 ~27 sandstone 2  
fill ~8 ~12 ~28 ~22 ~12 ~28 sandstone 2  
fill ~8 ~12 ~29 ~21 ~12 ~29 sandstone 2  
fill ~8 ~12 ~32 ~21 ~12 ~32 sandstone 2  
fill ~8 ~12 ~35 ~21 ~12 ~35 sandstone 2  
fill ~8 ~12 ~38 ~9 ~12 ~38 sandstone 2 
setblock ~10 ~12 ~3 quartz_block 2 
setblock ~10 ~12 ~38 quartz_block 2  
fill ~11 ~12 ~3 ~12 ~12 ~3 sandstone 2  
fill ~11 ~12 ~38 ~12 ~12 ~38 sandstone 2 
setblock ~13 ~12 ~3 quartz_block 2 
setblock ~13 ~12 ~38 quartz_block 2  
fill ~14 ~12 ~3 ~15 ~12 ~3 sandstone 2  
fill ~14 ~12 ~38 ~15 ~12 ~38 sandstone 2 
setblock ~16 ~12 ~3 quartz_block 2 
setblock ~16 ~12 ~38 quartz_block 2  
fill ~17 ~12 ~3 ~18 ~12 ~3 sandstone 2  
fill ~17 ~12 ~38 ~18 ~12 ~38 sandstone 2 
setblock ~19 ~12 ~3 quartz_block 2 
setblock ~19 ~12 ~38 quartz_block 2  
fill ~20 ~12 ~3 ~21 ~12 ~3 sandstone 2  
fill ~20 ~12 ~38 ~21 ~12 ~38 sandstone 2 
setblock ~22 ~12 ~3 quartz_block 2 
setblock ~22 ~12 ~6 quartz_block 2 
setblock ~22 ~12 ~9 quartz_block 2 
setblock ~22 ~12 ~12 quartz_block 2 
setblock ~22 ~12 ~29 quartz_block 2 
setblock ~22 ~12 ~32 quartz_block 2 
setblock ~22 ~12 ~35 quartz_block 2 
setblock ~22 ~12 ~38 quartz_block 2 
setblock ~23 ~12 ~12 quartz_stairs 2  
fill ~23 ~12 ~13 ~26 ~12 ~13 quartz_block 0 
setblock ~23 ~12 ~14 stone_slab 6  
fill ~23 ~12 ~15 ~23 ~12 ~16 stone_slab 14 
setblock ~23 ~12 ~17 stone_slab 6 
setblock ~23 ~12 ~24 stone_slab 6  
fill ~23 ~12 ~25 ~23 ~12 ~26 stone_slab 14 
setblock ~23 ~12 ~27 stone_slab 6  
fill ~23 ~12 ~28 ~25 ~12 ~28 double_stone_slab 6 
setblock ~23 ~12 ~29 quartz_stairs 3 
setblock ~26 ~12 ~12 quartz_stairs 2  
fill ~26 ~12 ~14 ~26 ~12 ~28 quartz_block 0 
setblock ~26 ~12 ~29 quartz_stairs 3 
setblock ~27 ~12 ~13 quartz_stairs 1 
setblock ~27 ~12 ~16 quartz_stairs 1 
setblock ~27 ~12 ~19 quartz_stairs 1 
setblock ~27 ~12 ~22 quartz_stairs 1 
setblock ~27 ~12 ~25 quartz_stairs 1 
setblock ~27 ~12 ~28 quartz_stairs 1  
fill ~2 ~13 ~11 ~27 ~13 ~11 stone_slab 0  
fill ~2 ~13 ~12 ~27 ~13 ~12 double_stone_slab 0  
fill ~2 ~13 ~13 ~27 ~13 ~13 double_stone_slab 0  
fill ~2 ~13 ~14 ~2 ~13 ~27 stone_slab 0  
fill ~2 ~13 ~28 ~27 ~13 ~28 double_stone_slab 0  
fill ~2 ~13 ~29 ~27 ~13 ~29 double_stone_slab 0  
fill ~2 ~13 ~30 ~27 ~13 ~30 stone_slab 0  
fill ~3 ~13 ~14 ~3 ~13 ~27 sandstone 2  
fill ~4 ~13 ~14 ~25 ~13 ~14 stone_slab 0  
fill ~4 ~13 ~15 ~25 ~13 ~15 stone_slab 0  
fill ~4 ~13 ~16 ~25 ~13 ~16 stone_slab 0  
fill ~4 ~13 ~17 ~25 ~13 ~17 stone_slab 0  
fill ~4 ~13 ~18 ~25 ~13 ~18 stone_slab 0  
fill ~4 ~13 ~19 ~25 ~13 ~19 stone_slab 0  
fill ~4 ~13 ~20 ~25 ~13 ~20 stone_slab 0  
fill ~4 ~13 ~21 ~25 ~13 ~21 stone_slab 0  
fill ~4 ~13 ~22 ~25 ~13 ~22 stone_slab 0  
fill ~4 ~13 ~23 ~25 ~13 ~23 stone_slab 0  
fill ~4 ~13 ~24 ~25 ~13 ~24 stone_slab 0  
fill ~4 ~13 ~25 ~25 ~13 ~25 stone_slab 0  
fill ~4 ~13 ~26 ~25 ~13 ~26 stone_slab 0  
fill ~4 ~13 ~27 ~25 ~13 ~27 stone_slab 0  
fill ~7 ~13 ~3 ~22 ~13 ~3 stone_slab 6  
fill ~7 ~13 ~4 ~7 ~13 ~10 stone_slab 6  
fill ~7 ~13 ~31 ~7 ~13 ~38 stone_slab 6  
fill ~8 ~13 ~38 ~22 ~13 ~38 stone_slab 6  
fill ~22 ~13 ~4 ~22 ~13 ~10 stone_slab 6  
fill ~22 ~13 ~31 ~22 ~13 ~38 stone_slab 6  
fill ~26 ~13 ~14 ~26 ~13 ~27 sandstone 2  
fill ~27 ~13 ~14 ~27 ~13 ~27 stone_slab 0  
fill ~2 ~14 ~13 ~27 ~14 ~13 stone_slab 0  
fill ~2 ~14 ~14 ~27 ~14 ~14 double_stone_slab 0 
setblock ~2 ~14 ~15 stone_slab 8 
setblock ~2 ~14 ~26 stone_slab 8  
fill ~2 ~14 ~27 ~27 ~14 ~27 double_stone_slab 0  
fill ~2 ~14 ~28 ~27 ~14 ~28 stone_slab 0  
fill ~3 ~14 ~15 ~3 ~14 ~26 sandstone 2 
setblock ~4 ~14 ~15 stone_slab 8 
setblock ~4 ~14 ~26 stone_slab 8  
fill ~5 ~14 ~15 ~5 ~14 ~26 sandstone 2 
setblock ~6 ~14 ~15 stone_slab 8 
setblock ~6 ~14 ~26 stone_slab 8  
fill ~7 ~14 ~15 ~8 ~14 ~15 sandstone 2  
fill ~7 ~14 ~16 ~8 ~14 ~16 sandstone 2  
fill ~7 ~14 ~17 ~8 ~14 ~17 sandstone 2  
fill ~7 ~14 ~18 ~8 ~14 ~18 sandstone 2  
fill ~7 ~14 ~19 ~8 ~14 ~19 sandstone 2  
fill ~7 ~14 ~20 ~8 ~14 ~20 sandstone 2  
fill ~7 ~14 ~21 ~8 ~14 ~21 sandstone 2  
fill ~7 ~14 ~22 ~8 ~14 ~22 sandstone 2  
fill ~7 ~14 ~23 ~8 ~14 ~23 sandstone 2  
fill ~7 ~14 ~24 ~8 ~14 ~24 sandstone 2  
fill ~7 ~14 ~25 ~8 ~14 ~25 sandstone 2  
fill ~7 ~14 ~26 ~8 ~14 ~26 sandstone 2 
setblock ~9 ~14 ~15 stone_slab 8 
setblock ~9 ~14 ~26 stone_slab 8  
fill ~10 ~14 ~15 ~10 ~14 ~26 sandstone 2 
setblock ~11 ~14 ~15 stone_slab 8 
setblock ~11 ~14 ~26 stone_slab 8  
fill ~12 ~14 ~15 ~12 ~14 ~26 sandstone 2 
setblock ~13 ~14 ~15 stone_slab 8 
setblock ~13 ~14 ~26 stone_slab 8  
fill ~14 ~14 ~15 ~14 ~14 ~26 sandstone 2 
setblock ~15 ~14 ~15 stone_slab 8 
setblock ~15 ~14 ~26 stone_slab 8  
fill ~16 ~14 ~15 ~16 ~14 ~26 sandstone 2 
setblock ~17 ~14 ~15 stone_slab 8 
setblock ~17 ~14 ~26 stone_slab 8  
fill ~18 ~14 ~15 ~18 ~14 ~26 sandstone 2 
setblock ~19 ~14 ~15 stone_slab 8 
setblock ~19 ~14 ~26 stone_slab 8  
fill ~20 ~14 ~15 ~20 ~14 ~26 sandstone 2 
setblock ~21 ~14 ~15 stone_slab 8 
setblock ~21 ~14 ~26 stone_slab 8  
fill ~22 ~14 ~15 ~22 ~14 ~26 sandstone 2 
setblock ~23 ~14 ~15 stone_slab 8 
setblock ~23 ~14 ~26 stone_slab 8  
fill ~24 ~14 ~15 ~24 ~14 ~26 sandstone 2 
setblock ~25 ~14 ~15 stone_slab 8 
setblock ~25 ~14 ~26 stone_slab 8  
fill ~26 ~14 ~15 ~26 ~14 ~26 sandstone 2 
setblock ~27 ~14 ~15 stone_slab 8 
setblock ~27 ~14 ~26 stone_slab 8  
fill ~2 ~15 ~15 ~27 ~15 ~15 stone_slab 0  
fill ~2 ~15 ~16 ~27 ~15 ~16 double_stone_slab 0 
setblock ~2 ~15 ~17 stone_slab 8 
setblock ~2 ~15 ~24 stone_slab 8  
fill ~2 ~15 ~25 ~27 ~15 ~25 double_stone_slab 0  
fill ~2 ~15 ~26 ~27 ~15 ~26 stone_slab 0  
fill ~3 ~15 ~17 ~3 ~15 ~24 sandstone 2 
setblock ~4 ~15 ~17 stone_slab 8 
setblock ~4 ~15 ~24 stone_slab 8  
fill ~5 ~15 ~17 ~5 ~15 ~24 sandstone 2 
setblock ~6 ~15 ~17 stone_slab 8 
setblock ~6 ~15 ~24 stone_slab 8  
fill ~7 ~15 ~17 ~8 ~15 ~17 sandstone 2  
fill ~7 ~15 ~18 ~8 ~15 ~18 sandstone 2  
fill ~7 ~15 ~19 ~8 ~15 ~19 sandstone 2  
fill ~7 ~15 ~20 ~8 ~15 ~20 sandstone 2  
fill ~7 ~15 ~21 ~8 ~15 ~21 sandstone 2  
fill ~7 ~15 ~22 ~8 ~15 ~22 sandstone 2  
fill ~7 ~15 ~23 ~8 ~15 ~23 sandstone 2  
fill ~7 ~15 ~24 ~8 ~15 ~24 sandstone 2 
setblock ~9 ~15 ~17 stone_slab 8 
setblock ~9 ~15 ~24 stone_slab 8  
fill ~10 ~15 ~17 ~10 ~15 ~24 sandstone 2 
setblock ~11 ~15 ~17 stone_slab 8 
setblock ~11 ~15 ~24 stone_slab 8  
fill ~12 ~15 ~17 ~12 ~15 ~24 sandstone 2 
setblock ~13 ~15 ~17 stone_slab 8 
setblock ~13 ~15 ~24 stone_slab 8  
fill ~14 ~15 ~17 ~14 ~15 ~24 sandstone 2 
setblock ~15 ~15 ~17 stone_slab 8 
setblock ~15 ~15 ~24 stone_slab 8  
fill ~16 ~15 ~17 ~16 ~15 ~24 sandstone 2 
setblock ~17 ~15 ~17 stone_slab 8 
setblock ~17 ~15 ~24 stone_slab 8  
fill ~18 ~15 ~17 ~18 ~15 ~24 sandstone 2 
setblock ~19 ~15 ~17 stone_slab 8 
setblock ~19 ~15 ~24 stone_slab 8  
fill ~20 ~15 ~17 ~20 ~15 ~24 sandstone 2 
setblock ~21 ~15 ~17 stone_slab 8 
setblock ~21 ~15 ~24 stone_slab 8  
fill ~22 ~15 ~17 ~22 ~15 ~24 sandstone 2 
setblock ~23 ~15 ~17 stone_slab 8 
setblock ~23 ~15 ~24 stone_slab 8  
fill ~24 ~15 ~17 ~24 ~15 ~24 sandstone 2 
setblock ~25 ~15 ~17 stone_slab 8 
setblock ~25 ~15 ~24 stone_slab 8  
fill ~26 ~15 ~17 ~26 ~15 ~24 sandstone 2 
setblock ~27 ~15 ~17 stone_slab 8 
setblock ~27 ~15 ~24 stone_slab 8  
fill ~2 ~16 ~17 ~27 ~16 ~17 stone_slab 0  
fill ~2 ~16 ~18 ~27 ~16 ~18 double_stone_slab 0 
setblock ~2 ~16 ~19 stone_slab 8 
setblock ~2 ~16 ~22 stone_slab 8  
fill ~2 ~16 ~23 ~27 ~16 ~23 double_stone_slab 0  
fill ~2 ~16 ~24 ~27 ~16 ~24 stone_slab 0  
fill ~3 ~16 ~19 ~3 ~16 ~22 sandstone 2 
setblock ~4 ~16 ~19 stone_slab 8 
setblock ~4 ~16 ~22 stone_slab 8  
fill ~5 ~16 ~19 ~5 ~16 ~22 sandstone 2 
setblock ~6 ~16 ~19 stone_slab 8 
setblock ~6 ~16 ~22 stone_slab 8  
fill ~7 ~16 ~19 ~8 ~16 ~19 sandstone 2  
fill ~7 ~16 ~20 ~8 ~16 ~20 sandstone 2  
fill ~7 ~16 ~21 ~8 ~16 ~21 sandstone 2  
fill ~7 ~16 ~22 ~8 ~16 ~22 sandstone 2 
setblock ~9 ~16 ~19 stone_slab 8 
setblock ~9 ~16 ~22 stone_slab 8  
fill ~10 ~16 ~19 ~10 ~16 ~22 sandstone 2 
setblock ~11 ~16 ~19 stone_slab 8 
setblock ~11 ~16 ~22 stone_slab 8  
fill ~12 ~16 ~19 ~12 ~16 ~22 sandstone 2 
setblock ~13 ~16 ~19 stone_slab 8 
setblock ~13 ~16 ~22 stone_slab 8  
fill ~14 ~16 ~19 ~14 ~16 ~22 sandstone 2 
setblock ~15 ~16 ~19 stone_slab 8 
setblock ~15 ~16 ~22 stone_slab 8  
fill ~16 ~16 ~19 ~16 ~16 ~22 sandstone 2 
setblock ~17 ~16 ~19 stone_slab 8 
setblock ~17 ~16 ~22 stone_slab 8  
fill ~18 ~16 ~19 ~18 ~16 ~22 sandstone 2 
setblock ~19 ~16 ~19 stone_slab 8 
setblock ~19 ~16 ~22 stone_slab 8  
fill ~20 ~16 ~19 ~20 ~16 ~22 sandstone 2 
setblock ~21 ~16 ~19 stone_slab 8 
setblock ~21 ~16 ~22 stone_slab 8  
fill ~22 ~16 ~19 ~22 ~16 ~22 sandstone 2 
setblock ~23 ~16 ~19 stone_slab 8 
setblock ~23 ~16 ~22 stone_slab 8  
fill ~24 ~16 ~19 ~24 ~16 ~22 sandstone 2 
setblock ~25 ~16 ~16 quartz_block 0 
setblock ~25 ~16 ~19 stone_slab 8 
setblock ~25 ~16 ~22 stone_slab 8 
setblock ~25 ~16 ~25 quartz_block 0  
fill ~26 ~16 ~19 ~26 ~16 ~22 sandstone 2 
setblock ~27 ~16 ~19 stone_slab 8 
setblock ~27 ~16 ~22 stone_slab 8  
fill ~2 ~17 ~19 ~27 ~17 ~19 stone_slab 0  
fill ~2 ~17 ~20 ~27 ~17 ~20 double_stone_slab 0  
fill ~2 ~17 ~21 ~27 ~17 ~21 double_stone_slab 0  
fill ~2 ~17 ~22 ~27 ~17 ~22 stone_slab 0 
setblock ~25 ~17 ~16 quartz_stairs 1 
setblock ~25 ~17 ~25 quartz_stairs 1 
setblock ~25 ~18 ~16 quartz_stairs 5 
setblock ~25 ~18 ~25 quartz_stairs 5 
setblock ~25 ~19 ~16 quartz_stairs 3 
setblock ~25 ~19 ~25 quartz_stairs 2  
setblock ~9 ~6 ~6 wall_sign 2  
setblock ~13 ~6 ~6 wall_sign 2  
setblock ~9 ~6 ~12 wall_sign 3  
setblock ~13 ~6 ~12 wall_sign 3  
setblock ~17 ~6 ~6 wall_sign 2  
setblock ~17 ~6 ~12 wall_sign 3    