    
fill ~1 ~0 ~24 ~1 ~0 ~35 stone 0  
fill ~1 ~0 ~46 ~42 ~0 ~46 stone 0  
fill ~1 ~0 ~47 ~42 ~0 ~47 stone 0  
fill ~1 ~0 ~48 ~42 ~0 ~48 stone 0  
fill ~1 ~0 ~49 ~42 ~0 ~49 stone 0  
fill ~1 ~0 ~50 ~43 ~0 ~50 stone 0  
fill ~1 ~0 ~51 ~33 ~0 ~51 stone 0  
fill ~1 ~0 ~52 ~33 ~0 ~52 stone 0  
fill ~1 ~0 ~53 ~45 ~0 ~53 stone 0  
fill ~1 ~0 ~54 ~26 ~0 ~54 stone 0  
fill ~1 ~0 ~55 ~33 ~0 ~55 stone 0 
setblock ~2 ~0 ~23 stone 0  
fill ~2 ~0 ~35 ~2 ~2 ~35 stone 0  
fill ~2 ~0 ~36 ~3 ~0 ~36 stone 0  
fill ~2 ~0 ~44 ~25 ~0 ~44 stone 0  
fill ~2 ~0 ~45 ~40 ~0 ~45 stone 0  
fill ~2 ~0 ~56 ~46 ~0 ~56 stone 0 
setblock ~3 ~0 ~22 stone 0  
fill ~3 ~0 ~37 ~3 ~1 ~37 stone 0  
fill ~3 ~0 ~38 ~5 ~0 ~38 stone 0  
fill ~3 ~0 ~57 ~47 ~0 ~57 stone 0  
fill ~4 ~0 ~20 ~5 ~0 ~20 stone 0  
fill ~4 ~0 ~21 ~4 ~0 ~20 stone 0  
fill ~4 ~0 ~43 ~20 ~0 ~43 stone 0  
fill ~5 ~0 ~39 ~6 ~0 ~39 stone 0  
fill ~5 ~0 ~40 ~5 ~0 ~38 stone 0  
fill ~5 ~0 ~42 ~19 ~0 ~42 stone 0  
fill ~5 ~0 ~58 ~47 ~0 ~58 stone 0  
fill ~6 ~0 ~18 ~6 ~0 ~19 stone 0  
fill ~6 ~0 ~40 ~8 ~0 ~40 cobblestone 0  
fill ~6 ~0 ~41 ~18 ~0 ~41 stone 0 
setblock ~7 ~0 ~17 stone 0  
fill ~7 ~0 ~59 ~11 ~0 ~59 cobblestone 0  
fill ~8 ~0 ~12 ~8 ~0 ~16 stone 0  
fill ~8 ~0 ~39 ~14 ~0 ~39 cobblestone 0  
fill ~9 ~0 ~8 ~19 ~0 ~8 stone 0  
fill ~9 ~0 ~9 ~9 ~0 ~11 stone 0  
fill ~9 ~0 ~38 ~15 ~0 ~38 cobblestone 0  
fill ~9 ~0 ~40 ~17 ~0 ~40 stone 0  
fill ~9 ~0 ~60 ~12 ~0 ~60 cobblestone 0  
fill ~10 ~0 ~37 ~16 ~0 ~37 cobblestone 0  
fill ~10 ~0 ~61 ~12 ~0 ~61 cobblestone 0  
fill ~11 ~0 ~33 ~13 ~0 ~33 cobblestone 0  
fill ~11 ~0 ~34 ~14 ~0 ~34 cobblestone 0  
fill ~11 ~0 ~35 ~14 ~0 ~35 cobblestone 0  
fill ~11 ~0 ~36 ~15 ~0 ~36 cobblestone 0  
fill ~11 ~0 ~62 ~15 ~0 ~62 cobblestone 0  
fill ~12 ~0 ~32 ~14 ~0 ~32 cobblestone 0  
fill ~12 ~0 ~59 ~48 ~0 ~59 stone 0  
fill ~12 ~0 ~63 ~18 ~0 ~63 cobblestone 0  
fill ~13 ~0 ~28 ~13 ~46 ~28 stone 0  
fill ~13 ~0 ~29 ~14 ~0 ~29 cobblestone 0  
fill ~13 ~0 ~30 ~14 ~0 ~30 cobblestone 0  
fill ~13 ~0 ~31 ~14 ~0 ~31 cobblestone 0  
fill ~13 ~0 ~60 ~49 ~0 ~60 stone 0  
fill ~13 ~0 ~61 ~49 ~0 ~61 stone 0  
fill ~14 ~0 ~25 ~43 ~0 ~25 cobblestone 0  
fill ~14 ~0 ~26 ~41 ~0 ~26 cobblestone 0  
fill ~14 ~0 ~27 ~15 ~0 ~27 cobblestone 0  
fill ~14 ~0 ~28 ~14 ~0 ~25 cobblestone 0  
fill ~14 ~0 ~33 ~25 ~0 ~33 grass 0  
fill ~14 ~0 ~64 ~19 ~0 ~64 cobblestone 0  
fill ~15 ~0 ~24 ~44 ~0 ~24 cobblestone 0  
fill ~15 ~0 ~28 ~24 ~0 ~28 grass 0  
fill ~15 ~0 ~29 ~27 ~0 ~29 grass 0  
fill ~15 ~0 ~30 ~26 ~0 ~30 grass 0  
fill ~15 ~0 ~31 ~26 ~0 ~31 grass 0  
fill ~15 ~0 ~32 ~25 ~0 ~32 grass 0  
fill ~15 ~0 ~34 ~24 ~0 ~34 grass 0  
fill ~15 ~0 ~35 ~24 ~0 ~35 grass 0  
fill ~15 ~0 ~39 ~16 ~0 ~39 stone 0  
fill ~16 ~0 ~23 ~45 ~0 ~23 cobblestone 0  
fill ~16 ~0 ~27 ~20 ~0 ~27 grass 0  
fill ~16 ~0 ~36 ~23 ~0 ~36 grass 0  
fill ~16 ~0 ~38 ~23 ~0 ~38 dirt 0  
fill ~16 ~0 ~62 ~35 ~0 ~62 stone 0  
fill ~17 ~0 ~22 ~46 ~0 ~22 cobblestone 0  
fill ~17 ~0 ~37 ~24 ~0 ~37 dirt 0  
fill ~17 ~0 ~39 ~23 ~0 ~39 dirt 0  
fill ~17 ~0 ~65 ~20 ~0 ~65 cobblestone 0 
setblock ~18 ~0 ~40 grass 0  
fill ~19 ~0 ~9 ~20 ~0 ~9 stone 0  
fill ~19 ~0 ~21 ~46 ~0 ~21 cobblestone 0  
fill ~19 ~0 ~40 ~19 ~0 ~41 dirt 0  
fill ~19 ~0 ~63 ~50 ~0 ~63 stone 0  
fill ~19 ~0 ~66 ~21 ~0 ~66 cobblestone 0  
fill ~19 ~0 ~67 ~22 ~0 ~67 cobblestone 0  
fill ~20 ~0 ~10 ~26 ~0 ~10 stone 0  
fill ~20 ~0 ~20 ~47 ~0 ~20 cobblestone 0  
fill ~20 ~0 ~40 ~22 ~0 ~40 grass 0  
fill ~20 ~0 ~41 ~22 ~0 ~41 grass 0 
setblock ~20 ~0 ~42 dirt 0  
fill ~20 ~0 ~64 ~24 ~0 ~64 stone 0  
fill ~20 ~0 ~68 ~23 ~0 ~68 cobblestone 0  
fill ~21 ~0 ~19 ~48 ~0 ~19 cobblestone 0  
fill ~21 ~0 ~27 ~41 ~0 ~27 cobblestone 0  
fill ~21 ~0 ~42 ~22 ~0 ~42 grass 0 
setblock ~21 ~0 ~43 dirt 0  
fill ~21 ~0 ~65 ~24 ~0 ~65 stone 0  
fill ~21 ~0 ~69 ~24 ~0 ~69 cobblestone 0  
fill ~22 ~0 ~11 ~30 ~0 ~11 stone 0 
setblock ~22 ~0 ~43 grass 0  
fill ~22 ~0 ~66 ~38 ~0 ~66 stone 0  
fill ~23 ~0 ~12 ~23 ~2 ~12 stone 0  
fill ~23 ~0 ~18 ~48 ~0 ~18 cobblestone 0  
fill ~23 ~0 ~40 ~23 ~0 ~43 dirt 0  
fill ~23 ~0 ~67 ~37 ~0 ~67 stone 0  
fill ~23 ~0 ~70 ~26 ~0 ~70 cobblestone 0 
setblock ~24 ~0 ~36 dirt 0  
fill ~24 ~0 ~38 ~45 ~0 ~38 grass 0  
fill ~24 ~0 ~39 ~44 ~0 ~39 grass 0  
fill ~24 ~0 ~40 ~44 ~0 ~40 grass 0  
fill ~24 ~0 ~41 ~43 ~0 ~41 grass 0  
fill ~24 ~0 ~42 ~48 ~0 ~42 grass 0  
fill ~24 ~0 ~43 ~46 ~0 ~43 grass 0  
fill ~24 ~0 ~68 ~36 ~0 ~68 stone 0  
fill ~24 ~0 ~71 ~29 ~0 ~71 cobblestone 0  
fill ~25 ~0 ~17 ~49 ~0 ~17 cobblestone 0  
fill ~25 ~0 ~28 ~40 ~0 ~28 cobblestone 0  
fill ~25 ~0 ~34 ~25 ~0 ~35 dirt 0  
fill ~25 ~0 ~36 ~45 ~0 ~36 grass 0  
fill ~25 ~0 ~37 ~45 ~0 ~37 grass 0  
fill ~25 ~0 ~64 ~25 ~0 ~65 cobblestone 0  
fill ~25 ~0 ~69 ~36 ~0 ~69 stone 0  
fill ~26 ~0 ~32 ~26 ~0 ~33 dirt 0  
fill ~26 ~0 ~34 ~33 ~0 ~34 grass 0  
fill ~26 ~0 ~35 ~45 ~0 ~35 grass 0 
setblock ~26 ~0 ~44 dirt 0  
fill ~26 ~0 ~64 ~51 ~0 ~64 stone 0  
fill ~26 ~0 ~65 ~42 ~0 ~65 stone 0  
fill ~26 ~0 ~72 ~29 ~0 ~72 cobblestone 0  
fill ~27 ~0 ~30 ~27 ~0 ~31 dirt 0  
fill ~27 ~0 ~32 ~31 ~0 ~32 grass 0  
fill ~27 ~0 ~33 ~32 ~0 ~33 grass 0  
fill ~27 ~0 ~44 ~28 ~0 ~44 grass 0 
setblock ~27 ~0 ~54 stonebrick 2  
fill ~27 ~0 ~70 ~32 ~0 ~70 stone 0  
fill ~27 ~0 ~73 ~29 ~0 ~73 cobblestone 0  
fill ~28 ~0 ~15 ~49 ~0 ~15 cobblestone 0  
fill ~28 ~0 ~16 ~49 ~0 ~16 cobblestone 0 
setblock ~28 ~0 ~29 dirt 0  
fill ~28 ~0 ~30 ~30 ~0 ~30 grass 0  
fill ~28 ~0 ~31 ~31 ~0 ~31 grass 0  
fill ~28 ~0 ~54 ~45 ~0 ~54 stone 0  
fill ~28 ~0 ~74 ~30 ~0 ~74 cobblestone 0  
fill ~28 ~0 ~75 ~31 ~0 ~75 cobblestone 0  
fill ~28 ~0 ~76 ~32 ~0 ~76 cobblestone 0  
fill ~28 ~0 ~77 ~33 ~0 ~77 cobblestone 0  
fill ~29 ~0 ~14 ~50 ~0 ~14 cobblestone 0  
fill ~29 ~0 ~29 ~30 ~0 ~29 grass 0  
fill ~29 ~0 ~44 ~44 ~0 ~44 dirt 0  
fill ~29 ~0 ~78 ~34 ~0 ~78 cobblestone 0  
fill ~29 ~0 ~79 ~34 ~0 ~79 cobblestone 0  
fill ~29 ~0 ~80 ~34 ~0 ~80 cobblestone 0  
fill ~30 ~0 ~71 ~47 ~0 ~71 stone 0  
fill ~30 ~0 ~72 ~47 ~0 ~72 stone 0  
fill ~30 ~0 ~73 ~47 ~0 ~73 stone 0  
fill ~30 ~0 ~81 ~34 ~0 ~81 cobblestone 0  
fill ~30 ~0 ~82 ~33 ~0 ~82 cobblestone 0  
fill ~30 ~0 ~83 ~33 ~0 ~83 cobblestone 0  
fill ~31 ~0 ~10 ~33 ~0 ~10 stone 0  
fill ~31 ~0 ~13 ~50 ~0 ~13 cobblestone 0  
fill ~31 ~0 ~29 ~39 ~0 ~29 cobblestone 0  
fill ~31 ~0 ~30 ~39 ~0 ~30 cobblestone 0  
fill ~31 ~0 ~74 ~42 ~0 ~74 stone 0  
fill ~31 ~0 ~84 ~32 ~0 ~84 cobblestone 0  
fill ~31 ~0 ~85 ~32 ~0 ~85 cobblestone 0  
fill ~31 ~0 ~86 ~41 ~0 ~86 grass 0  
fill ~31 ~0 ~87 ~42 ~0 ~87 grass 0  
fill ~32 ~0 ~31 ~38 ~0 ~31 cobblestone 0  
fill ~32 ~0 ~32 ~38 ~0 ~32 cobblestone 0  
fill ~32 ~0 ~75 ~52 ~0 ~75 stone 0  
fill ~32 ~0 ~88 ~43 ~0 ~88 grass 0  
fill ~32 ~0 ~89 ~43 ~0 ~89 grass 0  
fill ~32 ~0 ~90 ~45 ~0 ~90 grass 0  
fill ~33 ~0 ~33 ~37 ~0 ~33 cobblestone 0 
setblock ~33 ~0 ~70 coal_ore 0  
fill ~33 ~0 ~76 ~52 ~0 ~76 stone 0  
fill ~33 ~0 ~84 ~40 ~0 ~84 grass 0  
fill ~33 ~0 ~85 ~41 ~0 ~85 grass 0  
fill ~34 ~0 ~9 ~35 ~0 ~9 stone 0  
fill ~34 ~0 ~12 ~50 ~0 ~12 cobblestone 0  
fill ~34 ~0 ~34 ~35 ~0 ~34 cobblestone 0  
fill ~34 ~0 ~51 ~35 ~0 ~51 cobblestone 0  
fill ~34 ~0 ~52 ~34 ~0 ~51 cobblestone 0 
setblock ~34 ~0 ~55 cobblestone 0  
fill ~34 ~0 ~70 ~47 ~0 ~70 stone 0  
fill ~34 ~0 ~77 ~52 ~0 ~77 stone 0  
fill ~34 ~0 ~82 ~38 ~0 ~82 grass 0  
fill ~34 ~0 ~83 ~39 ~0 ~83 grass 0  
fill ~35 ~0 ~11 ~50 ~0 ~11 cobblestone 0  
fill ~35 ~0 ~52 ~44 ~0 ~52 stone 0  
fill ~35 ~0 ~55 ~46 ~0 ~55 stone 0  
fill ~35 ~0 ~78 ~53 ~0 ~78 stone 0  
fill ~35 ~0 ~79 ~36 ~0 ~79 grass 0  
fill ~35 ~0 ~80 ~37 ~0 ~80 grass 0  
fill ~35 ~0 ~81 ~37 ~0 ~81 grass 0  
fill ~36 ~0 ~8 ~41 ~0 ~8 stone 0  
fill ~36 ~0 ~34 ~46 ~0 ~34 grass 0  
fill ~36 ~0 ~51 ~43 ~0 ~51 stone 0 
setblock ~36 ~0 ~62 stonebrick 0  
fill ~37 ~0 ~10 ~50 ~0 ~10 cobblestone 0  
fill ~37 ~0 ~62 ~50 ~0 ~62 stone 0  
fill ~37 ~0 ~68 ~40 ~0 ~68 coal_ore 0  
fill ~37 ~0 ~69 ~37 ~0 ~68 coal_ore 0  
fill ~37 ~0 ~79 ~60 ~0 ~79 stone 0  
fill ~38 ~0 ~33 ~47 ~0 ~33 grass 0  
fill ~38 ~0 ~67 ~40 ~0 ~67 coal_ore 0  
fill ~38 ~0 ~69 ~50 ~0 ~69 stone 0  
fill ~38 ~0 ~80 ~58 ~0 ~80 stone 0  
fill ~38 ~0 ~81 ~57 ~0 ~81 stone 0 
setblock ~39 ~0 ~9 stone 0  
fill ~39 ~0 ~31 ~52 ~0 ~31 grass 0  
fill ~39 ~0 ~32 ~50 ~0 ~32 grass 0  
fill ~39 ~0 ~66 ~40 ~0 ~66 coal_ore 0  
fill ~39 ~0 ~82 ~55 ~0 ~82 stone 0  
fill ~40 ~0 ~29 ~52 ~0 ~29 grass 0  
fill ~40 ~0 ~30 ~52 ~0 ~30 grass 0  
fill ~40 ~0 ~83 ~53 ~0 ~83 stone 0  
fill ~41 ~0 ~9 ~50 ~0 ~9 cobblestone 0  
fill ~41 ~0 ~28 ~52 ~0 ~28 grass 0  
fill ~41 ~0 ~45 ~42 ~0 ~45 grass 0  
fill ~41 ~0 ~66 ~52 ~0 ~66 stone 0  
fill ~41 ~0 ~67 ~53 ~0 ~67 stone 0  
fill ~41 ~0 ~68 ~41 ~0 ~46 stone 0  
fill ~41 ~0 ~84 ~52 ~0 ~84 stone 0  
fill ~42 ~0 ~8 ~50 ~0 ~8 cobblestone 0  
fill ~42 ~0 ~26 ~51 ~0 ~26 grass 0  
fill ~42 ~0 ~27 ~52 ~0 ~27 grass 0  
fill ~42 ~0 ~68 ~42 ~30 ~68 stonebrick 2  
fill ~42 ~0 ~85 ~51 ~0 ~85 stone 0  
fill ~42 ~0 ~86 ~50 ~0 ~86 stone 0  
fill ~43 ~0 ~45 ~51 ~0 ~45 cobblestone 0  
fill ~43 ~0 ~46 ~95 ~0 ~46 cobblestone 0  
fill ~43 ~0 ~47 ~96 ~0 ~47 cobblestone 0  
fill ~43 ~0 ~48 ~96 ~0 ~48 cobblestone 0  
fill ~43 ~0 ~49 ~96 ~0 ~49 cobblestone 0 
setblock ~43 ~0 ~65 stonebrick 2  
fill ~43 ~0 ~68 ~44 ~0 ~68 stone 0 
setblock ~43 ~0 ~74 stonebrick 0  
fill ~43 ~0 ~87 ~48 ~0 ~87 stone 0  
fill ~44 ~0 ~25 ~51 ~0 ~25 grass 0  
fill ~44 ~0 ~41 ~46 ~0 ~41 stone 0  
fill ~44 ~0 ~50 ~95 ~0 ~50 cobblestone 0  
fill ~44 ~0 ~51 ~95 ~0 ~51 cobblestone 0  
fill ~44 ~0 ~65 ~51 ~0 ~65 stone 0  
fill ~44 ~0 ~74 ~52 ~0 ~74 stone 0  
fill ~44 ~0 ~88 ~47 ~0 ~88 stone 0  
fill ~44 ~0 ~89 ~46 ~0 ~89 stone 0  
fill ~45 ~0 ~7 ~50 ~0 ~7 cobblestone 0  
fill ~45 ~0 ~24 ~50 ~0 ~24 grass 0  
fill ~45 ~0 ~39 ~46 ~0 ~39 stone 0  
fill ~45 ~0 ~40 ~46 ~0 ~40 stone 0  
fill ~45 ~0 ~44 ~53 ~0 ~44 cobblestone 0  
fill ~45 ~0 ~52 ~94 ~0 ~52 cobblestone 0  
fill ~46 ~0 ~6 ~50 ~0 ~6 cobblestone 0  
fill ~46 ~0 ~23 ~51 ~0 ~23 grass 0  
fill ~46 ~0 ~35 ~63 ~0 ~35 stone 0  
fill ~46 ~0 ~36 ~63 ~0 ~36 stone 0  
fill ~46 ~0 ~37 ~63 ~0 ~37 stone 0  
fill ~46 ~0 ~38 ~47 ~0 ~38 stone 0  
fill ~46 ~0 ~53 ~94 ~0 ~53 cobblestone 0  
fill ~46 ~0 ~54 ~47 ~0 ~54 cobblestone 0  
fill ~46 ~0 ~68 ~50 ~0 ~68 stone 0  
fill ~46 ~0 ~90 ~64 ~0 ~90 cobblestone 0  
fill ~47 ~0 ~5 ~50 ~0 ~5 cobblestone 0  
fill ~47 ~0 ~21 ~52 ~0 ~21 grass 0  
fill ~47 ~0 ~22 ~51 ~0 ~22 grass 0  
fill ~47 ~0 ~34 ~63 ~0 ~34 stone 0  
fill ~47 ~0 ~39 ~52 ~0 ~39 grass 0  
fill ~47 ~0 ~40 ~52 ~0 ~40 grass 0  
fill ~47 ~0 ~41 ~49 ~0 ~41 grass 0  
fill ~47 ~0 ~43 ~52 ~0 ~43 cobblestone 0  
fill ~47 ~0 ~55 ~92 ~0 ~55 cobblestone 0  
fill ~47 ~0 ~56 ~91 ~0 ~56 cobblestone 0  
fill ~47 ~0 ~89 ~64 ~0 ~89 cobblestone 0  
fill ~48 ~0 ~4 ~50 ~0 ~4 cobblestone 0  
fill ~48 ~0 ~20 ~52 ~0 ~20 grass 0  
fill ~48 ~0 ~33 ~61 ~0 ~33 stone 0  
fill ~48 ~0 ~38 ~52 ~0 ~38 grass 0 
setblock ~48 ~0 ~54 stonebrick 2  
fill ~48 ~0 ~57 ~90 ~0 ~57 cobblestone 0  
fill ~48 ~0 ~58 ~90 ~0 ~58 cobblestone 0  
fill ~48 ~0 ~70 ~49 ~0 ~70 grass 0  
fill ~48 ~0 ~71 ~49 ~0 ~71 dirt 0  
fill ~48 ~0 ~72 ~61 ~0 ~72 grass 0  
fill ~48 ~0 ~73 ~59 ~0 ~73 grass 0  
fill ~48 ~0 ~88 ~64 ~0 ~88 cobblestone 0  
fill ~49 ~0 ~18 ~52 ~0 ~18 grass 0  
fill ~49 ~0 ~19 ~52 ~0 ~19 grass 0  
fill ~49 ~0 ~42 ~51 ~0 ~42 cobblestone 0  
fill ~49 ~0 ~54 ~93 ~0 ~54 cobblestone 0  
fill ~49 ~0 ~59 ~90 ~0 ~59 cobblestone 0  
fill ~49 ~0 ~87 ~64 ~0 ~87 cobblestone 0  
fill ~50 ~0 ~3 ~51 ~0 ~3 cobblestone 0  
fill ~50 ~0 ~15 ~52 ~0 ~15 grass 0  
fill ~50 ~0 ~16 ~52 ~0 ~16 grass 0  
fill ~50 ~0 ~17 ~52 ~0 ~17 grass 0 
setblock ~50 ~0 ~41 cobblestone 0  
fill ~50 ~0 ~60 ~90 ~0 ~60 cobblestone 0  
fill ~50 ~0 ~61 ~90 ~0 ~61 cobblestone 0  
fill ~50 ~0 ~70 ~50 ~0 ~71 stone 0  
fill ~51 ~0 ~2 ~52 ~0 ~2 cobblestone 0  
fill ~51 ~0 ~4 ~53 ~0 ~4 dirt 0  
fill ~51 ~0 ~5 ~53 ~0 ~5 dirt 0  
fill ~51 ~0 ~6 ~53 ~0 ~6 grass 0  
fill ~51 ~0 ~7 ~53 ~0 ~7 grass 0  
fill ~51 ~0 ~8 ~51 ~0 ~13 grass 0  
fill ~51 ~0 ~14 ~58 ~0 ~14 dirt 0  
fill ~51 ~0 ~24 ~56 ~0 ~24 stone 0  
fill ~51 ~0 ~32 ~59 ~0 ~32 stone 0  
fill ~51 ~0 ~41 ~52 ~0 ~41 grass 0  
fill ~51 ~0 ~62 ~90 ~0 ~62 cobblestone 0  
fill ~51 ~0 ~63 ~90 ~0 ~63 cobblestone 0  
fill ~51 ~0 ~68 ~51 ~29 ~68 stonebrick 2  
fill ~51 ~0 ~69 ~52 ~0 ~69 grass 0  
fill ~51 ~0 ~70 ~58 ~0 ~70 grass 0  
fill ~51 ~0 ~71 ~51 ~0 ~69 grass 0  
fill ~51 ~0 ~86 ~64 ~0 ~86 cobblestone 0 
setblock ~52 ~0 ~1 cobblestone 0 
setblock ~52 ~0 ~3 grass 0 
setblock ~52 ~0 ~8 dirt 0 
setblock ~52 ~0 ~9 grass 0 
setblock ~52 ~0 ~10 dirt 0  
fill ~52 ~0 ~11 ~68 ~0 ~11 grass 0  
fill ~52 ~0 ~12 ~57 ~0 ~12 grass 0  
fill ~52 ~0 ~13 ~57 ~0 ~13 grass 0  
fill ~52 ~0 ~22 ~54 ~0 ~22 stone 0  
fill ~52 ~0 ~23 ~56 ~0 ~23 stone 0  
fill ~52 ~0 ~25 ~56 ~0 ~25 stone 0  
fill ~52 ~0 ~26 ~56 ~0 ~26 stone 0 
setblock ~52 ~0 ~42 grass 0 
setblock ~52 ~0 ~45 stonebrick 2  
fill ~52 ~0 ~64 ~91 ~0 ~64 cobblestone 0  
fill ~52 ~0 ~65 ~91 ~0 ~65 cobblestone 0  
fill ~52 ~0 ~68 ~53 ~0 ~68 stone 0  
fill ~52 ~0 ~71 ~58 ~0 ~71 dirt 0  
fill ~52 ~0 ~85 ~64 ~0 ~85 cobblestone 0 
setblock ~53 ~0 ~0 cobblestone 0  
fill ~53 ~0 ~1 ~54 ~0 ~1 grass 0  
fill ~53 ~0 ~2 ~54 ~0 ~2 grass 0 
setblock ~53 ~0 ~3 dirt 0 
setblock ~53 ~0 ~8 grass 0 
setblock ~53 ~0 ~9 dirt 0 
setblock ~53 ~0 ~10 grass 0  
fill ~53 ~0 ~15 ~53 ~0 ~21 dirt 0  
fill ~53 ~0 ~27 ~53 ~0 ~31 dirt 0  
fill ~53 ~0 ~38 ~53 ~0 ~43 dirt 0 
setblock ~53 ~0 ~45 cobblestone 0  
fill ~53 ~0 ~66 ~91 ~0 ~66 cobblestone 0 
setblock ~53 ~0 ~69 stone 0  
fill ~53 ~0 ~74 ~60 ~0 ~74 dirt 0  
fill ~53 ~0 ~75 ~54 ~0 ~75 dirt 0  
fill ~53 ~0 ~76 ~57 ~0 ~76 grass 0  
fill ~53 ~0 ~77 ~57 ~0 ~77 grass 0  
fill ~53 ~0 ~84 ~62 ~0 ~84 cobblestone 0  
fill ~54 ~0 ~0 ~57 ~0 ~0 grass 0  
fill ~54 ~0 ~3 ~63 ~0 ~3 stone 0  
fill ~54 ~0 ~4 ~63 ~0 ~4 stone 0  
fill ~54 ~0 ~5 ~64 ~0 ~5 stone 0  
fill ~54 ~0 ~6 ~64 ~0 ~6 stone 0  
fill ~54 ~0 ~7 ~55 ~0 ~7 stone 0  
fill ~54 ~0 ~8 ~54 ~1 ~8 stone 0  
fill ~54 ~0 ~9 ~54 ~0 ~3 stone 0 
setblock ~54 ~0 ~10 dirt 0  
fill ~54 ~0 ~15 ~54 ~0 ~21 grass 0  
fill ~54 ~0 ~27 ~55 ~0 ~27 stone 0  
fill ~54 ~0 ~28 ~67 ~0 ~28 grass 0  
fill ~54 ~0 ~29 ~67 ~0 ~29 grass 0  
fill ~54 ~0 ~30 ~69 ~0 ~30 grass 0  
fill ~54 ~0 ~31 ~69 ~0 ~31 grass 0  
fill ~54 ~0 ~38 ~59 ~0 ~38 stone 0  
fill ~54 ~0 ~39 ~56 ~0 ~39 grass 0  
fill ~54 ~0 ~40 ~76 ~0 ~40 grass 0  
fill ~54 ~0 ~41 ~65 ~0 ~41 grass 0  
fill ~54 ~0 ~42 ~62 ~0 ~42 grass 0  
fill ~54 ~0 ~43 ~59 ~0 ~43 grass 0  
fill ~54 ~0 ~44 ~58 ~0 ~44 dirt 0 
setblock ~54 ~0 ~45 grass 0 
setblock ~54 ~0 ~67 grass 0  
fill ~54 ~0 ~68 ~57 ~0 ~68 dirt 0  
fill ~54 ~0 ~69 ~60 ~0 ~69 grass 0  
fill ~54 ~0 ~78 ~55 ~0 ~78 grass 0  
fill ~54 ~0 ~83 ~62 ~0 ~83 cobblestone 0  
fill ~55 ~0 ~1 ~63 ~0 ~1 stone 0  
fill ~55 ~0 ~2 ~63 ~0 ~2 stone 0  
fill ~55 ~0 ~8 ~59 ~0 ~8 grass 0  
fill ~55 ~0 ~9 ~55 ~0 ~8 grass 0 
setblock ~55 ~0 ~10 stone 0 
setblock ~55 ~0 ~15 dirt 0  
fill ~55 ~0 ~16 ~55 ~0 ~22 grass 0  
fill ~55 ~0 ~45 ~95 ~0 ~45 cobblestone 0  
fill ~55 ~0 ~67 ~90 ~0 ~67 cobblestone 0  
fill ~55 ~0 ~75 ~57 ~0 ~75 grass 0 
setblock ~56 ~0 ~7 grass 0 
setblock ~56 ~0 ~9 stone 0 
setblock ~56 ~0 ~10 grass 0  
fill ~56 ~0 ~15 ~59 ~0 ~15 grass 0 
setblock ~56 ~0 ~16 dirt 0  
fill ~56 ~0 ~17 ~56 ~0 ~22 grass 0  
fill ~56 ~0 ~27 ~66 ~0 ~27 grass 0  
fill ~56 ~0 ~78 ~59 ~0 ~78 stone 0  
fill ~56 ~0 ~82 ~62 ~0 ~82 cobblestone 0  
fill ~57 ~0 ~7 ~64 ~0 ~7 stone 0  
fill ~57 ~0 ~9 ~63 ~0 ~9 grass 0 
setblock ~57 ~0 ~10 stone 0  
fill ~57 ~0 ~16 ~61 ~0 ~16 grass 0 
setblock ~57 ~0 ~17 dirt 0  
fill ~57 ~0 ~18 ~57 ~0 ~31 grass 0 
setblock ~57 ~0 ~39 stone 0  
fill ~58 ~0 ~0 ~60 ~0 ~0 stone 0  
fill ~58 ~0 ~10 ~67 ~0 ~10 grass 0  
fill ~58 ~0 ~12 ~58 ~0 ~14 dirt 0  
fill ~58 ~0 ~17 ~63 ~0 ~17 grass 0 
setblock ~58 ~0 ~18 dirt 0  
fill ~58 ~0 ~19 ~58 ~0 ~31 grass 0  
fill ~58 ~0 ~39 ~75 ~0 ~39 grass 0 
setblock ~58 ~0 ~68 grass 0  
fill ~58 ~0 ~75 ~60 ~0 ~75 dirt 0  
fill ~58 ~0 ~76 ~60 ~0 ~76 dirt 0 
setblock ~58 ~0 ~77 stone 0  
fill ~58 ~0 ~81 ~62 ~0 ~81 cobblestone 0 
setblock ~59 ~0 ~12 coal_ore 0  
fill ~59 ~0 ~13 ~64 ~0 ~13 grass 0 
setblock ~59 ~0 ~14 stone 0  
fill ~59 ~0 ~18 ~65 ~0 ~18 grass 0 
setblock ~59 ~0 ~19 dirt 0  
fill ~59 ~0 ~20 ~59 ~0 ~31 grass 0  
fill ~59 ~0 ~44 ~85 ~0 ~44 cobblestone 0 
setblock ~59 ~0 ~68 stone 0  
fill ~59 ~0 ~70 ~61 ~0 ~70 dirt 0  
fill ~59 ~0 ~71 ~62 ~0 ~71 grass 0  
fill ~59 ~0 ~77 ~60 ~0 ~77 dirt 0  
fill ~59 ~0 ~80 ~62 ~0 ~80 cobblestone 0  
fill ~60 ~0 ~8 ~66 ~0 ~8 stone 0  
fill ~60 ~0 ~12 ~68 ~0 ~12 grass 0  
fill ~60 ~0 ~14 ~69 ~0 ~14 grass 0  
fill ~60 ~0 ~15 ~61 ~0 ~15 dirt 0  
fill ~60 ~0 ~19 ~67 ~0 ~19 grass 0 
setblock ~60 ~0 ~20 dirt 0  
fill ~60 ~0 ~21 ~60 ~0 ~32 grass 0  
fill ~60 ~0 ~38 ~75 ~0 ~38 grass 0  
fill ~60 ~0 ~43 ~76 ~0 ~43 cobblestone 0  
fill ~60 ~0 ~68 ~90 ~0 ~68 cobblestone 0  
fill ~60 ~0 ~73 ~61 ~0 ~73 dirt 0 
setblock ~60 ~0 ~78 dirt 0  
fill ~61 ~0 ~0 ~67 ~0 ~0 grass 0  
fill ~61 ~0 ~20 ~69 ~0 ~20 grass 0 
setblock ~61 ~0 ~21 dirt 0  
fill ~61 ~0 ~22 ~61 ~0 ~31 grass 0  
fill ~61 ~0 ~32 ~63 ~0 ~32 stone 0  
fill ~61 ~0 ~69 ~90 ~0 ~69 cobblestone 0  
fill ~61 ~0 ~74 ~64 ~0 ~74 grass 0  
fill ~61 ~0 ~75 ~73 ~0 ~75 grass 0  
fill ~61 ~0 ~76 ~94 ~0 ~76 grass 0  
fill ~61 ~0 ~77 ~93 ~0 ~77 grass 0  
fill ~61 ~0 ~78 ~63 ~0 ~78 grass 0  
fill ~61 ~0 ~79 ~62 ~0 ~79 cobblestone 0  
fill ~62 ~0 ~15 ~68 ~0 ~15 grass 0  
fill ~62 ~0 ~16 ~63 ~0 ~16 dirt 0  
fill ~62 ~0 ~21 ~70 ~0 ~21 grass 0 
setblock ~62 ~0 ~22 dirt 0  
fill ~62 ~0 ~23 ~62 ~0 ~31 grass 0  
fill ~62 ~0 ~33 ~63 ~0 ~33 stonebrick 2  
fill ~62 ~0 ~70 ~89 ~0 ~70 cobblestone 0  
fill ~62 ~0 ~72 ~63 ~0 ~72 dirt 0  
fill ~62 ~0 ~73 ~64 ~0 ~73 grass 0  
fill ~63 ~0 ~22 ~67 ~0 ~22 grass 0 
setblock ~63 ~0 ~23 dirt 0  
fill ~63 ~0 ~24 ~63 ~0 ~31 grass 0  
fill ~63 ~0 ~42 ~74 ~0 ~42 cobblestone 0  
fill ~63 ~0 ~71 ~88 ~0 ~71 cobblestone 0  
fill ~64 ~0 ~1 ~67 ~0 ~1 grass 0  
fill ~64 ~0 ~2 ~67 ~0 ~2 grass 0  
fill ~64 ~0 ~3 ~64 ~0 ~4 dirt 0  
fill ~64 ~0 ~9 ~66 ~0 ~9 stone 0  
fill ~64 ~0 ~16 ~69 ~0 ~16 grass 0  
fill ~64 ~0 ~17 ~65 ~0 ~17 dirt 0  
fill ~64 ~0 ~23 ~68 ~0 ~23 grass 0 
setblock ~64 ~0 ~24 dirt 0  
fill ~64 ~0 ~25 ~64 ~0 ~32 grass 0 
setblock ~64 ~0 ~33 stone 0  
fill ~64 ~0 ~34 ~73 ~0 ~34 grass 0  
fill ~64 ~0 ~35 ~74 ~0 ~35 grass 0  
fill ~64 ~0 ~36 ~74 ~0 ~36 grass 0  
fill ~64 ~0 ~37 ~75 ~0 ~37 grass 0  
fill ~64 ~0 ~72 ~81 ~0 ~72 cobblestone 0  
fill ~64 ~0 ~78 ~67 ~0 ~78 cobblestone 0  
fill ~64 ~0 ~79 ~68 ~0 ~79 cobblestone 0  
fill ~64 ~0 ~80 ~68 ~0 ~80 cobblestone 0  
fill ~64 ~0 ~81 ~64 ~0 ~90 cobblestone 0  
fill ~65 ~0 ~3 ~70 ~0 ~3 grass 0  
fill ~65 ~0 ~4 ~66 ~0 ~4 dirt 0  
fill ~65 ~0 ~5 ~65 ~0 ~7 grass 0 
setblock ~65 ~0 ~13 dirt 0  
fill ~65 ~0 ~24 ~69 ~0 ~24 grass 0 
setblock ~65 ~0 ~25 dirt 0 
setblock ~65 ~0 ~26 grass 0  
fill ~65 ~0 ~32 ~69 ~0 ~32 grass 0  
fill ~65 ~0 ~33 ~72 ~0 ~33 grass 0  
fill ~65 ~0 ~73 ~78 ~0 ~73 cobblestone 0  
fill ~65 ~0 ~74 ~67 ~0 ~74 cobblestone 0  
fill ~66 ~0 ~5 ~68 ~0 ~5 dirt 0  
fill ~66 ~0 ~6 ~69 ~0 ~6 dirt 0 
setblock ~66 ~0 ~7 grass 0  
fill ~66 ~0 ~13 ~68 ~0 ~13 grass 0  
fill ~66 ~0 ~17 ~69 ~0 ~17 grass 0  
fill ~66 ~0 ~18 ~67 ~0 ~18 dirt 0  
fill ~66 ~0 ~25 ~67 ~0 ~25 grass 0 
setblock ~66 ~0 ~26 dirt 0  
fill ~66 ~0 ~41 ~69 ~0 ~41 cobblestone 0  
fill ~67 ~0 ~4 ~72 ~0 ~4 grass 0  
fill ~67 ~0 ~7 ~70 ~0 ~7 dirt 0  
fill ~67 ~0 ~8 ~70 ~0 ~8 dirt 0 
setblock ~67 ~0 ~9 grass 0 
setblock ~67 ~0 ~26 grass 0 
setblock ~67 ~0 ~27 dirt 0  
fill ~68 ~0 ~2 ~70 ~0 ~2 cobblestone 0  
fill ~68 ~0 ~9 ~71 ~0 ~9 dirt 0  
fill ~68 ~0 ~10 ~71 ~0 ~10 dirt 0  
fill ~68 ~0 ~18 ~69 ~0 ~18 grass 0  
fill ~68 ~0 ~19 ~71 ~0 ~19 dirt 0 
setblock ~68 ~0 ~22 dirt 0  
fill ~68 ~0 ~25 ~77 ~0 ~25 stone 0  
fill ~68 ~0 ~26 ~74 ~0 ~26 stone 0  
fill ~68 ~0 ~27 ~74 ~0 ~27 stone 0  
fill ~68 ~0 ~28 ~74 ~0 ~28 stone 0  
fill ~68 ~0 ~29 ~71 ~0 ~29 stone 0  
fill ~68 ~0 ~74 ~72 ~0 ~74 grass 0  
fill ~68 ~0 ~78 ~91 ~0 ~78 grass 0  
fill ~69 ~0 ~5 ~73 ~0 ~5 grass 0  
fill ~69 ~0 ~11 ~72 ~0 ~11 dirt 0  
fill ~69 ~0 ~12 ~72 ~0 ~12 dirt 0  
fill ~69 ~0 ~13 ~72 ~0 ~13 dirt 0  
fill ~69 ~0 ~15 ~73 ~0 ~15 dirt 0  
fill ~69 ~0 ~22 ~71 ~0 ~22 grass 0 
setblock ~69 ~0 ~23 dirt 0  
fill ~69 ~0 ~79 ~90 ~0 ~79 grass 0  
fill ~69 ~0 ~80 ~75 ~0 ~80 grass 0  
fill ~70 ~0 ~6 ~75 ~0 ~6 grass 0  
fill ~70 ~0 ~14 ~72 ~0 ~14 dirt 0  
fill ~70 ~0 ~16 ~73 ~0 ~16 dirt 0  
fill ~70 ~0 ~17 ~73 ~0 ~17 dirt 0  
fill ~70 ~0 ~18 ~74 ~0 ~18 dirt 0  
fill ~70 ~0 ~20 ~71 ~0 ~20 dirt 0  
fill ~70 ~0 ~23 ~72 ~0 ~23 grass 0 
setblock ~70 ~0 ~24 dirt 0  
fill ~70 ~0 ~30 ~70 ~0 ~32 stone 0  
fill ~70 ~0 ~41 ~76 ~0 ~41 grass 0  
fill ~71 ~0 ~3 ~72 ~0 ~3 cobblestone 0  
fill ~71 ~0 ~7 ~77 ~0 ~7 grass 0  
fill ~71 ~0 ~8 ~79 ~0 ~8 grass 0 
setblock ~71 ~0 ~21 dirt 0  
fill ~71 ~0 ~24 ~72 ~0 ~24 grass 0  
fill ~71 ~0 ~30 ~72 ~0 ~30 grass 0 
setblock ~71 ~0 ~31 dirt 0 
setblock ~71 ~0 ~32 grass 0  
fill ~72 ~0 ~9 ~80 ~0 ~9 grass 0  
fill ~72 ~0 ~10 ~81 ~0 ~10 grass 0  
fill ~72 ~0 ~19 ~72 ~0 ~21 grass 0 
setblock ~72 ~0 ~22 dirt 0 
setblock ~72 ~0 ~29 grass 0 
setblock ~72 ~0 ~31 grass 0 
setblock ~72 ~0 ~32 dirt 0 
setblock ~73 ~0 ~4 cobblestone 0  
fill ~73 ~0 ~11 ~83 ~0 ~11 grass 0  
fill ~73 ~0 ~12 ~84 ~0 ~12 grass 0  
fill ~73 ~0 ~13 ~85 ~0 ~13 grass 0  
fill ~73 ~0 ~14 ~86 ~0 ~14 grass 0  
fill ~73 ~0 ~19 ~75 ~0 ~19 dirt 0  
fill ~73 ~0 ~20 ~73 ~0 ~22 grass 0 
setblock ~73 ~0 ~23 dirt 0  
fill ~73 ~0 ~29 ~74 ~0 ~29 stone 0  
fill ~73 ~0 ~30 ~74 ~0 ~30 stone 0  
fill ~73 ~0 ~31 ~75 ~0 ~31 stone 0  
fill ~73 ~0 ~32 ~75 ~0 ~32 stone 0  
fill ~73 ~0 ~33 ~75 ~0 ~33 stone 0  
fill ~73 ~0 ~74 ~75 ~0 ~74 dirt 0  
fill ~74 ~0 ~5 ~75 ~0 ~5 cobblestone 0  
fill ~74 ~0 ~15 ~87 ~0 ~15 grass 0  
fill ~74 ~0 ~16 ~88 ~0 ~16 grass 0  
fill ~74 ~0 ~17 ~89 ~0 ~17 grass 0  
fill ~74 ~0 ~20 ~76 ~0 ~20 dirt 0  
fill ~74 ~0 ~21 ~74 ~0 ~23 grass 0 
setblock ~74 ~0 ~24 dirt 0 
setblock ~74 ~0 ~34 stone 0  
fill ~74 ~0 ~75 ~75 ~0 ~75 dirt 0  
fill ~75 ~0 ~18 ~87 ~0 ~18 grass 0  
fill ~75 ~0 ~21 ~77 ~0 ~21 dirt 0  
fill ~75 ~0 ~22 ~77 ~0 ~22 dirt 0  
fill ~75 ~0 ~23 ~77 ~0 ~23 dirt 0 
setblock ~75 ~0 ~24 grass 0  
fill ~75 ~0 ~27 ~76 ~0 ~27 grass 0  
fill ~75 ~0 ~28 ~77 ~0 ~28 grass 0 
setblock ~75 ~0 ~29 dirt 0 
setblock ~75 ~0 ~30 grass 0  
fill ~75 ~0 ~34 ~75 ~0 ~36 dirt 0  
fill ~75 ~0 ~42 ~76 ~0 ~42 grass 0  
fill ~76 ~0 ~6 ~77 ~0 ~6 cobblestone 0  
fill ~76 ~0 ~19 ~86 ~0 ~19 grass 0  
fill ~76 ~0 ~24 ~79 ~0 ~24 dirt 0  
fill ~76 ~0 ~26 ~81 ~0 ~26 dirt 0  
fill ~76 ~0 ~29 ~77 ~0 ~29 grass 0  
fill ~76 ~0 ~30 ~76 ~0 ~31 dirt 0  
fill ~76 ~0 ~32 ~76 ~0 ~36 grass 0  
fill ~76 ~0 ~37 ~76 ~0 ~39 dirt 0  
fill ~76 ~0 ~74 ~94 ~0 ~74 grass 0  
fill ~76 ~0 ~75 ~94 ~0 ~75 grass 0  
fill ~77 ~0 ~20 ~86 ~0 ~20 grass 0  
fill ~77 ~0 ~27 ~80 ~0 ~27 dirt 0  
fill ~77 ~0 ~30 ~78 ~0 ~30 grass 0  
fill ~77 ~0 ~31 ~78 ~0 ~31 grass 0  
fill ~77 ~0 ~32 ~77 ~0 ~33 dirt 0  
fill ~77 ~0 ~34 ~77 ~0 ~39 grass 0  
fill ~77 ~0 ~40 ~77 ~0 ~43 dirt 0  
fill ~78 ~0 ~7 ~79 ~0 ~7 cobblestone 0  
fill ~78 ~0 ~21 ~78 ~0 ~23 stone 0  
fill ~78 ~0 ~25 ~82 ~0 ~25 dirt 0  
fill ~78 ~0 ~28 ~79 ~0 ~28 dirt 0  
fill ~78 ~0 ~29 ~78 ~0 ~24 dirt 0  
fill ~78 ~0 ~32 ~79 ~0 ~32 grass 0  
fill ~78 ~0 ~33 ~79 ~0 ~33 grass 0  
fill ~78 ~0 ~34 ~78 ~0 ~35 dirt 0  
fill ~78 ~0 ~36 ~78 ~0 ~43 grass 0  
fill ~79 ~0 ~21 ~86 ~0 ~21 grass 0  
fill ~79 ~0 ~22 ~82 ~0 ~22 grass 0  
fill ~79 ~0 ~23 ~81 ~0 ~23 grass 0  
fill ~79 ~0 ~29 ~89 ~0 ~29 grass 0  
fill ~79 ~0 ~30 ~79 ~0 ~31 dirt 0  
fill ~79 ~0 ~34 ~80 ~0 ~34 grass 0  
fill ~79 ~0 ~35 ~80 ~0 ~35 grass 0  
fill ~79 ~0 ~36 ~79 ~0 ~38 dirt 0  
fill ~79 ~0 ~39 ~79 ~0 ~43 grass 0  
fill ~79 ~0 ~73 ~93 ~0 ~73 grass 0 
setblock ~80 ~0 ~8 cobblestone 0 
setblock ~80 ~0 ~24 grass 0  
fill ~80 ~0 ~28 ~87 ~0 ~28 grass 0  
fill ~80 ~0 ~30 ~89 ~0 ~30 grass 0  
fill ~80 ~0 ~31 ~90 ~0 ~31 grass 0  
fill ~80 ~0 ~32 ~80 ~0 ~33 dirt 0  
fill ~80 ~0 ~36 ~81 ~0 ~36 grass 0  
fill ~80 ~0 ~37 ~81 ~0 ~37 grass 0  
fill ~80 ~0 ~38 ~82 ~0 ~38 grass 0  
fill ~80 ~0 ~39 ~80 ~0 ~43 dirt 0 
setblock ~81 ~0 ~9 cobblestone 0  
fill ~81 ~0 ~24 ~83 ~0 ~24 dirt 0  
fill ~81 ~0 ~27 ~87 ~0 ~27 grass 0  
fill ~81 ~0 ~32 ~91 ~0 ~32 grass 0  
fill ~81 ~0 ~33 ~92 ~0 ~33 grass 0  
fill ~81 ~0 ~34 ~81 ~0 ~35 dirt 0  
fill ~81 ~0 ~39 ~82 ~0 ~39 grass 0  
fill ~81 ~0 ~40 ~82 ~0 ~40 grass 0  
fill ~81 ~0 ~41 ~82 ~0 ~41 grass 0  
fill ~81 ~0 ~42 ~82 ~0 ~42 grass 0  
fill ~81 ~0 ~43 ~82 ~0 ~43 grass 0  
fill ~82 ~0 ~10 ~83 ~0 ~10 cobblestone 0  
fill ~82 ~0 ~23 ~84 ~0 ~23 dirt 0  
fill ~82 ~0 ~26 ~86 ~0 ~26 grass 0  
fill ~82 ~0 ~34 ~93 ~0 ~34 grass 0  
fill ~82 ~0 ~35 ~94 ~0 ~35 grass 0  
fill ~82 ~0 ~36 ~82 ~0 ~37 dirt 0  
fill ~82 ~0 ~72 ~83 ~0 ~72 grass 0  
fill ~83 ~0 ~22 ~84 ~0 ~22 dirt 0  
fill ~83 ~0 ~25 ~86 ~0 ~25 grass 0  
fill ~83 ~0 ~36 ~94 ~0 ~36 grass 0  
fill ~83 ~0 ~37 ~89 ~0 ~37 dirt 0  
fill ~83 ~0 ~38 ~90 ~0 ~38 dirt 0  
fill ~83 ~0 ~39 ~84 ~0 ~39 dirt 0  
fill ~83 ~0 ~40 ~83 ~0 ~37 dirt 0  
fill ~83 ~0 ~41 ~84 ~0 ~41 stone 0  
fill ~83 ~0 ~42 ~83 ~0 ~41 stone 0 
setblock ~83 ~0 ~43 dirt 0 
setblock ~84 ~0 ~11 cobblestone 0  
fill ~84 ~0 ~24 ~86 ~0 ~24 grass 0 
setblock ~84 ~0 ~40 stone 0  
fill ~84 ~0 ~42 ~94 ~0 ~42 grass 0  
fill ~84 ~0 ~43 ~92 ~0 ~43 grass 0  
fill ~84 ~0 ~72 ~86 ~0 ~72 cobblestone 0 
setblock ~85 ~0 ~12 cobblestone 0  
fill ~85 ~0 ~22 ~86 ~0 ~22 grass 0  
fill ~85 ~0 ~23 ~86 ~0 ~23 grass 0 
setblock ~85 ~0 ~39 stone 0  
fill ~85 ~0 ~40 ~94 ~0 ~40 grass 0  
fill ~85 ~0 ~41 ~94 ~0 ~41 grass 0 
setblock ~86 ~0 ~13 cobblestone 0  
fill ~86 ~0 ~39 ~89 ~0 ~39 dirt 0 
setblock ~86 ~0 ~44 grass 0 
setblock ~87 ~0 ~14 cobblestone 0  
fill ~87 ~0 ~19 ~90 ~0 ~19 stone 0  
fill ~87 ~0 ~20 ~91 ~0 ~20 stone 0  
fill ~87 ~0 ~21 ~89 ~0 ~21 stone 0  
fill ~87 ~0 ~22 ~88 ~0 ~22 stone 0  
fill ~87 ~0 ~23 ~88 ~0 ~23 stone 0  
fill ~87 ~0 ~24 ~87 ~0 ~26 stone 0  
fill ~87 ~0 ~44 ~96 ~0 ~44 cobblestone 0  
fill ~87 ~0 ~72 ~93 ~0 ~72 grass 0 
setblock ~88 ~0 ~15 cobblestone 0  
fill ~88 ~0 ~18 ~90 ~0 ~18 stone 0  
fill ~88 ~0 ~24 ~90 ~0 ~24 grass 0  
fill ~88 ~0 ~25 ~88 ~0 ~28 stone 0 
setblock ~89 ~0 ~16 cobblestone 0  
fill ~89 ~0 ~22 ~91 ~0 ~22 grass 0  
fill ~89 ~0 ~23 ~91 ~0 ~23 grass 0 
setblock ~89 ~0 ~25 grass 0 
setblock ~89 ~0 ~26 stone 0  
fill ~89 ~0 ~27 ~89 ~0 ~36 grass 0  
fill ~89 ~0 ~71 ~95 ~0 ~71 grass 0 
setblock ~90 ~0 ~17 stone 0  
fill ~90 ~0 ~21 ~92 ~0 ~21 grass 0  
fill ~90 ~0 ~25 ~94 ~0 ~25 cobblestone 0  
fill ~90 ~0 ~26 ~94 ~0 ~26 cobblestone 0  
fill ~90 ~0 ~27 ~94 ~0 ~27 cobblestone 0  
fill ~90 ~0 ~28 ~94 ~0 ~28 cobblestone 0  
fill ~90 ~0 ~29 ~94 ~0 ~29 cobblestone 0  
fill ~90 ~0 ~30 ~94 ~0 ~30 cobblestone 0  
fill ~90 ~0 ~37 ~95 ~0 ~37 grass 0  
fill ~90 ~0 ~39 ~94 ~0 ~39 grass 0  
fill ~90 ~0 ~70 ~97 ~0 ~70 grass 0  
fill ~91 ~0 ~17 ~91 ~0 ~19 cobblestone 0  
fill ~91 ~0 ~24 ~94 ~0 ~24 cobblestone 0  
fill ~91 ~0 ~31 ~94 ~0 ~31 cobblestone 0  
fill ~91 ~0 ~38 ~94 ~0 ~38 grass 0  
fill ~91 ~0 ~57 ~99 ~0 ~57 grass 0  
fill ~91 ~0 ~58 ~99 ~0 ~58 grass 0  
fill ~91 ~0 ~59 ~99 ~0 ~59 grass 0  
fill ~91 ~0 ~60 ~99 ~0 ~60 grass 0  
fill ~91 ~0 ~61 ~99 ~0 ~61 grass 0  
fill ~91 ~0 ~62 ~99 ~0 ~62 grass 0  
fill ~91 ~0 ~63 ~99 ~0 ~63 grass 0  
fill ~91 ~0 ~67 ~99 ~0 ~67 grass 0  
fill ~91 ~0 ~68 ~99 ~0 ~68 grass 0  
fill ~91 ~0 ~69 ~98 ~0 ~69 grass 0  
fill ~92 ~0 ~18 ~92 ~0 ~20 cobblestone 0  
fill ~92 ~0 ~22 ~93 ~0 ~22 cobblestone 0  
fill ~92 ~0 ~23 ~93 ~0 ~23 cobblestone 0  
fill ~92 ~0 ~32 ~95 ~0 ~32 cobblestone 0  
fill ~92 ~0 ~56 ~99 ~0 ~56 grass 0  
fill ~92 ~0 ~64 ~99 ~0 ~64 grass 0  
fill ~92 ~0 ~65 ~99 ~0 ~65 grass 0  
fill ~92 ~0 ~66 ~99 ~0 ~66 grass 0  
fill ~93 ~0 ~20 ~93 ~0 ~33 cobblestone 0  
fill ~93 ~0 ~43 ~96 ~0 ~43 cobblestone 0  
fill ~93 ~0 ~55 ~99 ~0 ~55 grass 0  
fill ~94 ~0 ~33 ~95 ~0 ~33 cobblestone 0  
fill ~94 ~0 ~34 ~95 ~0 ~34 cobblestone 0  
fill ~94 ~0 ~54 ~99 ~0 ~54 grass 0  
fill ~95 ~0 ~35 ~96 ~0 ~35 cobblestone 0  
fill ~95 ~0 ~36 ~96 ~0 ~36 cobblestone 0  
fill ~95 ~0 ~38 ~96 ~0 ~38 cobblestone 0  
fill ~95 ~0 ~39 ~96 ~0 ~39 cobblestone 0  
fill ~95 ~0 ~40 ~96 ~0 ~40 cobblestone 0  
fill ~95 ~0 ~41 ~96 ~0 ~41 cobblestone 0  
fill ~95 ~0 ~42 ~96 ~0 ~42 cobblestone 0  
fill ~95 ~0 ~52 ~99 ~0 ~52 grass 0  
fill ~95 ~0 ~53 ~99 ~0 ~53 grass 0 
setblock ~96 ~0 ~37 cobblestone 0  
fill ~96 ~0 ~45 ~99 ~0 ~45 grass 0  
fill ~96 ~0 ~46 ~99 ~0 ~46 grass 0  
fill ~96 ~0 ~50 ~99 ~0 ~50 grass 0  
fill ~96 ~0 ~51 ~99 ~0 ~51 grass 0  
fill ~97 ~0 ~44 ~99 ~0 ~44 grass 0  
fill ~97 ~0 ~47 ~99 ~0 ~47 grass 0  
fill ~97 ~0 ~48 ~99 ~0 ~48 grass 0  
fill ~97 ~0 ~49 ~99 ~0 ~49 grass 0  
fill ~1 ~1 ~25 ~2 ~1 ~25 stone 0  
fill ~1 ~1 ~26 ~1 ~2 ~26 stone 0  
fill ~1 ~1 ~27 ~1 ~2 ~27 stone 0  
fill ~1 ~1 ~28 ~1 ~2 ~28 stone 0  
fill ~1 ~1 ~29 ~1 ~2 ~29 stone 0  
fill ~1 ~1 ~30 ~2 ~1 ~30 stone 0  
fill ~1 ~1 ~32 ~1 ~2 ~32 stone 0  
fill ~1 ~1 ~33 ~1 ~2 ~33 stone 0  
fill ~1 ~1 ~34 ~1 ~1 ~32 stone 0  
fill ~2 ~1 ~24 ~3 ~1 ~24 stone 0  
fill ~2 ~1 ~31 ~2 ~4 ~31 stone 0  
fill ~3 ~1 ~23 ~4 ~1 ~23 stone 0  
fill ~3 ~1 ~36 ~3 ~2 ~36 stone 0  
fill ~4 ~1 ~22 ~5 ~1 ~22 stone 0  
fill ~4 ~1 ~38 ~6 ~1 ~38 stone 0  
fill ~5 ~1 ~20 ~6 ~1 ~20 stone 0  
fill ~5 ~1 ~21 ~5 ~1 ~20 stone 0  
fill ~6 ~1 ~19 ~7 ~1 ~19 stone 0  
fill ~6 ~1 ~39 ~6 ~3 ~39 stone 0  
fill ~6 ~1 ~40 ~6 ~1 ~38 stone 0  
fill ~7 ~1 ~18 ~8 ~1 ~18 stone 0  
fill ~7 ~1 ~41 ~7 ~1 ~42 stone 0  
fill ~8 ~1 ~16 ~9 ~1 ~16 stone 0  
fill ~8 ~1 ~17 ~8 ~1 ~16 stone 0  
fill ~8 ~1 ~42 ~10 ~1 ~42 stone 0  
fill ~9 ~1 ~10 ~10 ~1 ~10 stone 0  
fill ~9 ~1 ~11 ~10 ~1 ~11 stone 0  
fill ~9 ~1 ~12 ~10 ~1 ~12 stone 0  
fill ~9 ~1 ~13 ~9 ~1 ~16 stone 0  
fill ~9 ~1 ~43 ~13 ~1 ~43 stone 0  
fill ~10 ~1 ~8 ~18 ~1 ~8 stone 0  
fill ~10 ~1 ~9 ~10 ~1 ~8 stone 0  
fill ~10 ~1 ~44 ~22 ~1 ~44 stone 0  
fill ~13 ~1 ~45 ~22 ~1 ~45 stone 0  
fill ~13 ~1 ~48 ~14 ~1 ~48 stone 0  
fill ~13 ~1 ~49 ~13 ~1 ~50 stone 0  
fill ~14 ~1 ~46 ~20 ~1 ~46 stone 0  
fill ~14 ~1 ~47 ~15 ~1 ~47 stone 0  
fill ~14 ~1 ~50 ~14 ~1 ~51 stone 0  
fill ~15 ~1 ~51 ~16 ~1 ~51 stone 0  
fill ~15 ~1 ~52 ~23 ~1 ~52 stone 0  
fill ~16 ~1 ~38 ~23 ~1 ~38 stonebrick 2  
fill ~16 ~1 ~43 ~21 ~1 ~43 stone 0  
fill ~16 ~1 ~50 ~23 ~1 ~50 stonebrick 2  
fill ~17 ~1 ~37 ~24 ~1 ~37 stonebrick 2  
fill ~17 ~1 ~39 ~22 ~1 ~39 stonebrick 2  
fill ~17 ~1 ~42 ~20 ~1 ~42 stone 0  
fill ~17 ~1 ~47 ~17 ~3 ~47 stone 0  
fill ~17 ~1 ~49 ~22 ~1 ~49 stonebrick 2  
fill ~17 ~1 ~51 ~24 ~1 ~51 stonebrick 2  
fill ~18 ~1 ~9 ~19 ~1 ~9 stone 0  
fill ~19 ~1 ~10 ~21 ~1 ~10 stone 0  
fill ~19 ~1 ~40 ~19 ~11 ~40 stone 0  
fill ~19 ~1 ~41 ~19 ~8 ~41 stone 0  
fill ~20 ~1 ~47 ~20 ~5 ~47 stone 0  
fill ~20 ~1 ~53 ~24 ~1 ~53 stone 0  
fill ~22 ~1 ~11 ~32 ~1 ~11 stone 0  
fill ~22 ~1 ~46 ~22 ~4 ~46 stone 0  
fill ~22 ~1 ~65 ~24 ~1 ~65 stonebrick 2  
fill ~22 ~1 ~66 ~23 ~1 ~66 stonebrick 2  
fill ~23 ~1 ~13 ~23 ~3 ~13 stone 0  
fill ~23 ~1 ~25 ~23 ~45 ~25 stonebrick 2  
fill ~23 ~1 ~39 ~23 ~1 ~49 stonebrick 0  
fill ~23 ~1 ~54 ~24 ~1 ~54 stone 0  
fill ~23 ~1 ~64 ~25 ~1 ~64 stonebrick 2  
fill ~24 ~1 ~12 ~24 ~2 ~12 stone 0  
fill ~24 ~1 ~36 ~24 ~15 ~36 stonebrick 2  
fill ~24 ~1 ~52 ~24 ~30 ~52 stonebrick 2  
fill ~24 ~1 ~55 ~25 ~1 ~55 stone 0  
fill ~24 ~1 ~63 ~26 ~1 ~63 stonebrick 2  
fill ~25 ~1 ~34 ~25 ~15 ~34 stonebrick 2  
fill ~25 ~1 ~35 ~25 ~15 ~35 stonebrick 2  
fill ~25 ~1 ~53 ~25 ~30 ~53 stonebrick 2  
fill ~25 ~1 ~54 ~25 ~30 ~54 stonebrick 2  
fill ~25 ~1 ~62 ~27 ~1 ~62 stonebrick 2  
fill ~26 ~1 ~26 ~26 ~1 ~27 stonebrick 2  
fill ~26 ~1 ~32 ~26 ~15 ~32 stonebrick 2  
fill ~26 ~1 ~33 ~26 ~15 ~33 stonebrick 2  
fill ~26 ~1 ~44 ~26 ~30 ~44 stonebrick 2  
fill ~26 ~1 ~45 ~26 ~30 ~45 stonebrick 2  
fill ~26 ~1 ~46 ~26 ~30 ~46 stonebrick 2  
fill ~26 ~1 ~47 ~26 ~30 ~47 stonebrick 2  
fill ~26 ~1 ~48 ~26 ~30 ~48 stonebrick 2  
fill ~26 ~1 ~49 ~26 ~30 ~49 stonebrick 2  
fill ~26 ~1 ~55 ~26 ~30 ~55 stonebrick 2  
fill ~26 ~1 ~56 ~26 ~30 ~56 stonebrick 2  
fill ~26 ~1 ~61 ~28 ~1 ~61 stonebrick 2  
fill ~27 ~1 ~27 ~27 ~1 ~28 stonebrick 2  
fill ~27 ~1 ~30 ~27 ~15 ~30 stonebrick 2  
fill ~27 ~1 ~31 ~27 ~15 ~31 stonebrick 2   

KittysCommands:   
fill ~27 ~1 ~50 ~27 ~30 ~50 stonebrick 2  
fill ~27 ~1 ~51 ~27 ~30 ~51 stonebrick 2  
fill ~27 ~1 ~52 ~27 ~30 ~52 stonebrick 2  
fill ~27 ~1 ~57 ~27 ~30 ~57 stonebrick 2  
fill ~27 ~1 ~58 ~27 ~30 ~58 stonebrick 2  
fill ~27 ~1 ~60 ~27 ~18 ~60 stonebrick 2 
setblock ~28 ~1 ~28 stonebrick 0  
fill ~28 ~1 ~29 ~28 ~15 ~29 stonebrick 2  
fill ~28 ~1 ~53 ~28 ~30 ~53 stonebrick 2  
fill ~28 ~1 ~54 ~28 ~30 ~54 stonebrick 2  
fill ~28 ~1 ~59 ~28 ~30 ~59 stonebrick 2 
setblock ~28 ~1 ~60 stonebrick 0 
setblock ~29 ~1 ~27 stonebrick 0 
setblock ~29 ~1 ~30 tallgrass 0 
setblock ~29 ~1 ~35 torch 5 
setblock ~29 ~1 ~41 torch 5  
fill ~29 ~1 ~44 ~77 ~1 ~44 stone 0  
fill ~29 ~1 ~45 ~29 ~29 ~45 stonebrick 2  
fill ~29 ~1 ~46 ~29 ~29 ~46 stonebrick 2  
fill ~29 ~1 ~47 ~29 ~29 ~47 stonebrick 2  
fill ~29 ~1 ~48 ~29 ~29 ~48 stonebrick 2  
fill ~29 ~1 ~55 ~29 ~30 ~55 stonebrick 2  
fill ~29 ~1 ~56 ~29 ~30 ~56 stonebrick 2 
setblock ~29 ~1 ~61 stonebrick 0 
setblock ~30 ~1 ~26 stonebrick 0 
setblock ~30 ~1 ~29 tallgrass 0  
fill ~30 ~1 ~31 ~31 ~1 ~31 tallgrass 0  
fill ~30 ~1 ~49 ~30 ~29 ~49 stonebrick 2  
fill ~30 ~1 ~50 ~30 ~29 ~50 stonebrick 2  
fill ~30 ~1 ~51 ~30 ~29 ~51 stonebrick 2  
fill ~30 ~1 ~57 ~30 ~30 ~57 stonebrick 2  
fill ~30 ~1 ~58 ~30 ~30 ~58 stonebrick 2 
setblock ~30 ~1 ~62 stonebrick 0 
setblock ~31 ~1 ~25 stonebrick 0  
fill ~31 ~1 ~33 ~31 ~1 ~34 tallgrass 0  
fill ~31 ~1 ~52 ~31 ~29 ~52 stonebrick 2  
fill ~31 ~1 ~53 ~31 ~29 ~53 stonebrick 2  
fill ~31 ~1 ~54 ~31 ~29 ~54 stonebrick 2  
fill ~31 ~1 ~59 ~31 ~30 ~59 stonebrick 2 
setblock ~31 ~1 ~63 stonebrick 0  
fill ~31 ~1 ~74 ~33 ~1 ~74 stonebrick 2  
fill ~31 ~1 ~75 ~32 ~1 ~75 stonebrick 2 
setblock ~32 ~1 ~24 stonebrick 0 
setblock ~32 ~1 ~47 torch 5  
fill ~32 ~1 ~52 ~32 ~1 ~53 purple_shulker_box 1  
fill ~32 ~1 ~55 ~32 ~29 ~55 stonebrick 2  
fill ~32 ~1 ~60 ~32 ~30 ~60 stonebrick 2 
setblock ~32 ~1 ~64 stonebrick 0  
fill ~32 ~1 ~73 ~34 ~1 ~73 stonebrick 2  
fill ~33 ~1 ~10 ~35 ~1 ~10 stone 0 
setblock ~33 ~1 ~23 stonebrick 0 
setblock ~33 ~1 ~30 torch 5  
fill ~33 ~1 ~56 ~33 ~29 ~56 stonebrick 2  
fill ~33 ~1 ~57 ~33 ~29 ~57 stonebrick 2 
setblock ~33 ~1 ~59 torch 5  
fill ~33 ~1 ~61 ~33 ~30 ~61 stonebrick 2 
setblock ~33 ~1 ~65 stonebrick 0  
fill ~33 ~1 ~72 ~35 ~1 ~72 stonebrick 2 
setblock ~34 ~1 ~22 stonebrick 0 
setblock ~34 ~1 ~57 crafting_table 0  
fill ~34 ~1 ~58 ~34 ~29 ~58 stonebrick 2  
fill ~34 ~1 ~62 ~34 ~30 ~62 stonebrick 2 
setblock ~34 ~1 ~66 stonebrick 0  
fill ~34 ~1 ~71 ~36 ~1 ~71 stonebrick 2  
fill ~35 ~1 ~9 ~38 ~1 ~9 stone 0  
fill ~35 ~1 ~17 ~36 ~1 ~17 stonebrick 2 
setblock ~35 ~1 ~21 stonebrick 0 
setblock ~35 ~1 ~42 torch 5  
fill ~35 ~1 ~58 ~35 ~3 ~58 furnace 5  
fill ~35 ~1 ~59 ~35 ~29 ~59 stonebrick 2  
fill ~35 ~1 ~63 ~35 ~30 ~63 stonebrick 2 
setblock ~35 ~1 ~67 stonebrick 0  
fill ~35 ~1 ~70 ~37 ~1 ~70 stonebrick 2  
fill ~36 ~1 ~18 ~37 ~1 ~18 stonebrick 2 
setblock ~36 ~1 ~20 stonebrick 0  
fill ~36 ~1 ~30 ~36 ~32 ~30 stone 0  
fill ~36 ~1 ~59 ~36 ~3 ~59 furnace 5  
fill ~36 ~1 ~60 ~36 ~29 ~60 stonebrick 2  
fill ~36 ~1 ~64 ~36 ~30 ~64 stonebrick 2 
setblock ~36 ~1 ~68 stonebrick 0  
fill ~36 ~1 ~69 ~36 ~18 ~69 stonebrick 2 
setblock ~37 ~1 ~19 stonebrick 0 
setblock ~37 ~1 ~34 tallgrass 0  
fill ~37 ~1 ~60 ~37 ~3 ~60 furnace 5  
fill ~37 ~1 ~61 ~37 ~29 ~61 stonebrick 2  
fill ~37 ~1 ~65 ~37 ~30 ~65 stonebrick 2 
setblock ~37 ~1 ~69 stonebrick 0  
fill ~38 ~1 ~19 ~38 ~15 ~19 stonebrick 2 
setblock ~38 ~1 ~26 torch 5  
fill ~38 ~1 ~61 ~38 ~1 ~62 hopper 5  
fill ~38 ~1 ~66 ~38 ~30 ~66 stonebrick 2  
fill ~38 ~1 ~69 ~38 ~30 ~69 stonebrick 2  
fill ~39 ~1 ~18 ~39 ~15 ~18 stonebrick 2 
setblock ~39 ~1 ~36 torch 5  
fill ~39 ~1 ~61 ~39 ~1 ~62 chest 5  
fill ~39 ~1 ~63 ~39 ~1 ~64 hopper 5  
fill ~39 ~1 ~67 ~40 ~1 ~67 stonebrick 2  
fill ~39 ~1 ~70 ~40 ~1 ~70 stonebrick 2  
fill ~40 ~1 ~8 ~48 ~1 ~8 stone 0  
fill ~40 ~1 ~9 ~41 ~1 ~9 stone 0 
setblock ~40 ~1 ~13 stone 0 
setblock ~40 ~1 ~15 stone 0  
fill ~40 ~1 ~63 ~40 ~1 ~64 chest 5 
setblock ~40 ~1 ~66 anvil 1 
setblock ~41 ~1 ~14 stone 0  
fill ~41 ~1 ~17 ~42 ~1 ~17 stonebrick 2 
setblock ~41 ~1 ~22 torch 5 
setblock ~41 ~1 ~50 torch 5 
setblock ~41 ~1 ~66 purple_shulker_box 1  
fill ~41 ~1 ~68 ~41 ~30 ~68 stonebrick 2 
setblock ~41 ~1 ~69 torch 5  
fill ~41 ~1 ~71 ~42 ~1 ~71 stonebrick 2 
setblock ~42 ~1 ~13 stone 0 
setblock ~42 ~1 ~15 stone 0 
setblock ~42 ~1 ~66 ender_chest 2  
fill ~42 ~1 ~67 ~45 ~1 ~67 stone 0  
fill ~43 ~1 ~16 ~44 ~1 ~16 stonebrick 2  
fill ~43 ~1 ~66 ~44 ~1 ~66 chest 2  
fill ~43 ~1 ~68 ~45 ~1 ~68 stone 0  
fill ~43 ~1 ~69 ~44 ~1 ~69 stonebrick 2  
fill ~43 ~1 ~72 ~44 ~1 ~72 stonebrick 2  
fill ~44 ~1 ~9 ~44 ~4 ~9 stone 0  
fill ~44 ~1 ~24 ~44 ~72 ~24 stone 0 
setblock ~44 ~1 ~57 torch 5  
fill ~45 ~1 ~15 ~46 ~1 ~15 stonebrick 2 
setblock ~45 ~1 ~30 torch 5 
setblock ~45 ~1 ~66 crafting_table 0  
fill ~45 ~1 ~70 ~47 ~1 ~70 stonebrick 2  
fill ~45 ~1 ~73 ~46 ~1 ~73 stonebrick 2  
fill ~46 ~1 ~7 ~48 ~1 ~7 stone 0 
setblock ~46 ~1 ~20 torch 5  
fill ~46 ~1 ~74 ~47 ~1 ~74 stonebrick 2  
fill ~46 ~1 ~75 ~48 ~1 ~75 stonebrick 2  
fill ~46 ~1 ~76 ~48 ~1 ~76 stonebrick 2  
fill ~46 ~1 ~77 ~48 ~1 ~77 stonebrick 2  
fill ~46 ~1 ~78 ~48 ~1 ~78 stonebrick 2  
fill ~46 ~1 ~79 ~48 ~1 ~79 stonebrick 2  
fill ~46 ~1 ~80 ~48 ~1 ~80 stonebrick 2  
fill ~46 ~1 ~86 ~48 ~1 ~86 stonebrick 2  
fill ~46 ~1 ~87 ~48 ~1 ~87 stonebrick 2  
fill ~46 ~1 ~88 ~48 ~1 ~88 stonebrick 2  
fill ~47 ~1 ~9 ~47 ~2 ~9 stone 0  
fill ~47 ~1 ~14 ~47 ~9 ~14 stonebrick 2  
fill ~47 ~1 ~67 ~48 ~1 ~67 stonebrick 0  
fill ~47 ~1 ~81 ~47 ~7 ~81 stonebrick 2  
fill ~48 ~1 ~6 ~50 ~1 ~6 stone 0  
fill ~48 ~1 ~12 ~48 ~1 ~13 stonebrick 2  
fill ~48 ~1 ~14 ~58 ~1 ~14 stonebrick 0  
fill ~48 ~1 ~71 ~49 ~1 ~71 stonebrick 2  
fill ~48 ~1 ~74 ~49 ~1 ~74 stonebrick 0  
fill ~49 ~1 ~5 ~53 ~1 ~5 stone 0 
setblock ~49 ~1 ~21 tallgrass 0 
setblock ~49 ~1 ~24 tallgrass 0 
setblock ~50 ~1 ~15 tallgrass 0 
setblock ~50 ~1 ~40 torch 5  
fill ~50 ~1 ~73 ~50 ~29 ~73 ladder 2  
fill ~50 ~1 ~74 ~50 ~30 ~74 stonebrick 2  
fill ~51 ~1 ~4 ~57 ~1 ~4 stone 0 
setblock ~51 ~1 ~19 torch 5 
setblock ~52 ~1 ~8 stone 0 
setblock ~52 ~1 ~10 stone 0 
setblock ~52 ~1 ~60 torch 5  
fill ~52 ~1 ~68 ~57 ~1 ~68 stonebrick 2  
fill ~52 ~1 ~71 ~58 ~1 ~71 stonebrick 2  
fill ~52 ~1 ~74 ~54 ~1 ~74 stonebrick 2  
fill ~52 ~1 ~75 ~54 ~1 ~75 stonebrick 2  
fill ~52 ~1 ~84 ~54 ~1 ~84 stonebrick 2  
fill ~53 ~1 ~3 ~64 ~1 ~3 stone 0 
setblock ~53 ~1 ~9 stone 0  
fill ~53 ~1 ~15 ~53 ~1 ~59 stone 0 
setblock ~54 ~1 ~10 stone 0 
setblock ~54 ~1 ~67 red_flower 0 
setblock ~54 ~1 ~69 tallgrass 0  
fill ~55 ~1 ~2 ~62 ~1 ~2 stone 0  
fill ~55 ~1 ~15 ~55 ~32 ~15 stonebrick 2  
fill ~55 ~1 ~74 ~58 ~1 ~74 stonebrick 0  
fill ~56 ~1 ~16 ~56 ~32 ~16 stonebrick 2  
fill ~57 ~1 ~1 ~60 ~1 ~1 stone 0  
fill ~57 ~1 ~17 ~57 ~32 ~17 stonebrick 2 
setblock ~57 ~1 ~18 torch 5 
setblock ~57 ~1 ~67 torch 5  
fill ~58 ~1 ~12 ~58 ~1 ~13 stonebrick 2  
fill ~58 ~1 ~18 ~58 ~40 ~18 stonebrick 2  
fill ~58 ~1 ~67 ~60 ~1 ~67 stonebrick 2  
fill ~58 ~1 ~75 ~60 ~1 ~75 stonebrick 2  
fill ~58 ~1 ~76 ~60 ~1 ~76 stonebrick 2  
fill ~58 ~1 ~77 ~60 ~1 ~77 stonebrick 2  
fill ~58 ~1 ~78 ~60 ~1 ~78 stonebrick 2  
fill ~58 ~1 ~79 ~60 ~1 ~79 stonebrick 2  
fill ~58 ~1 ~80 ~60 ~1 ~80 stonebrick 2  
fill ~58 ~1 ~86 ~60 ~1 ~86 stonebrick 2  
fill ~58 ~1 ~87 ~60 ~1 ~87 stonebrick 2  
fill ~58 ~1 ~88 ~60 ~1 ~88 stonebrick 2  
fill ~59 ~1 ~14 ~59 ~15 ~14 stonebrick 2  
fill ~59 ~1 ~19 ~59 ~40 ~19 stonebrick 2  
fill ~59 ~1 ~70 ~61 ~1 ~70 stonebrick 2  
fill ~59 ~1 ~74 ~60 ~1 ~74 stonebrick 2  
fill ~59 ~1 ~81 ~59 ~7 ~81 stonebrick 2  
fill ~60 ~1 ~15 ~61 ~1 ~15 stonebrick 2  
fill ~60 ~1 ~20 ~60 ~40 ~20 stonebrick 2 
setblock ~60 ~1 ~31 torch 5  
fill ~60 ~1 ~73 ~61 ~1 ~73 stonebrick 2  
fill ~61 ~1 ~21 ~61 ~40 ~21 stonebrick 2 
setblock ~61 ~1 ~56 torch 5  
fill ~61 ~1 ~66 ~63 ~1 ~66 stonebrick 2  
fill ~62 ~1 ~4 ~66 ~1 ~4 stone 0  
fill ~62 ~1 ~16 ~63 ~1 ~16 stonebrick 2 
setblock ~62 ~1 ~20 torch 5  
fill ~62 ~1 ~22 ~62 ~40 ~22 stonebrick 2  
fill ~62 ~1 ~69 ~63 ~1 ~69 stonebrick 2  
fill ~62 ~1 ~72 ~63 ~1 ~72 stonebrick 2  
fill ~63 ~1 ~23 ~63 ~40 ~23 stonebrick 2 
setblock ~63 ~1 ~65 torch 5  
fill ~64 ~1 ~17 ~65 ~1 ~17 stonebrick 2  
fill ~64 ~1 ~24 ~64 ~40 ~24 stonebrick 2  
fill ~64 ~1 ~65 ~64 ~29 ~65 stonebrick 2  
fill ~64 ~1 ~68 ~65 ~1 ~68 stonebrick 2  
fill ~64 ~1 ~71 ~65 ~1 ~71 stonebrick 2  
fill ~65 ~1 ~13 ~65 ~19 ~13 stonebrick 2  
fill ~65 ~1 ~25 ~65 ~40 ~25 stonebrick 2  
fill ~65 ~1 ~64 ~66 ~1 ~64 stonebrick 2  
fill ~66 ~1 ~5 ~68 ~1 ~5 stone 0  
fill ~66 ~1 ~6 ~69 ~1 ~6 stone 0  
fill ~66 ~1 ~18 ~67 ~1 ~18 stonebrick 2 
setblock ~66 ~1 ~23 torch 5  
fill ~66 ~1 ~26 ~66 ~40 ~26 stonebrick 2 
setblock ~66 ~1 ~49 torch 5  
fill ~66 ~1 ~67 ~67 ~1 ~67 stonebrick 2  
fill ~66 ~1 ~70 ~67 ~1 ~70 stonebrick 2  
fill ~67 ~1 ~7 ~70 ~1 ~7 stone 0  
fill ~67 ~1 ~8 ~70 ~1 ~8 stone 0  
fill ~67 ~1 ~27 ~67 ~40 ~27 stonebrick 2 
setblock ~67 ~1 ~36 torch 5  
fill ~67 ~1 ~63 ~67 ~29 ~63 stonebrick 2  
fill ~68 ~1 ~9 ~71 ~1 ~9 stone 0  
fill ~68 ~1 ~10 ~71 ~1 ~10 stone 0  
fill ~68 ~1 ~19 ~68 ~15 ~19 stonebrick 2  
fill ~68 ~1 ~22 ~68 ~30 ~22 stonebrick 2  
fill ~68 ~1 ~28 ~68 ~40 ~28 stonebrick 2  
fill ~68 ~1 ~62 ~68 ~29 ~62 stonebrick 2  
fill ~68 ~1 ~66 ~68 ~30 ~66 stonebrick 2  
fill ~68 ~1 ~69 ~68 ~30 ~69 stonebrick 2  
fill ~69 ~1 ~11 ~72 ~1 ~11 stone 0  
fill ~69 ~1 ~12 ~72 ~1 ~12 stone 0  
fill ~69 ~1 ~13 ~72 ~1 ~13 stone 0  
fill ~69 ~1 ~15 ~73 ~1 ~15 stone 0 
setblock ~69 ~1 ~19 stonebrick 0  
fill ~69 ~1 ~23 ~69 ~30 ~23 stonebrick 2  
fill ~69 ~1 ~29 ~69 ~40 ~29 stonebrick 2 
setblock ~69 ~1 ~59 torch 5  
fill ~69 ~1 ~61 ~69 ~29 ~61 stonebrick 2  
fill ~69 ~1 ~65 ~69 ~30 ~65 stonebrick 2 
setblock ~69 ~1 ~69 stonebrick 0  
fill ~69 ~1 ~70 ~71 ~1 ~70 stonebrick 2  
fill ~70 ~1 ~14 ~72 ~1 ~14 stone 0  
fill ~70 ~1 ~16 ~73 ~1 ~16 stone 0  
fill ~70 ~1 ~17 ~73 ~1 ~17 stone 0  
fill ~70 ~1 ~18 ~74 ~1 ~18 stone 0  
fill ~70 ~1 ~19 ~71 ~1 ~19 stone 0 
setblock ~70 ~1 ~20 stonebrick 0  
fill ~70 ~1 ~24 ~70 ~30 ~24 stonebrick 2  
fill ~70 ~1 ~30 ~70 ~40 ~30 stonebrick 2  
fill ~70 ~1 ~60 ~70 ~29 ~60 stonebrick 2  
fill ~70 ~1 ~64 ~70 ~30 ~64 stonebrick 2 
setblock ~70 ~1 ~68 stonebrick 0  
fill ~70 ~1 ~69 ~70 ~18 ~69 stonebrick 2  
fill ~70 ~1 ~71 ~72 ~1 ~71 stonebrick 2  
fill ~71 ~1 ~20 ~71 ~12 ~20 stone 0 
setblock ~71 ~1 ~21 stonebrick 0  
fill ~71 ~1 ~25 ~71 ~30 ~25 stonebrick 2 
setblock ~71 ~1 ~27 torch 5  
fill ~71 ~1 ~31 ~71 ~40 ~31 stonebrick 2  
fill ~71 ~1 ~59 ~71 ~29 ~59 stonebrick 2  
fill ~71 ~1 ~63 ~71 ~30 ~63 stonebrick 2 
setblock ~71 ~1 ~67 stonebrick 0  
fill ~71 ~1 ~72 ~73 ~1 ~72 stonebrick 2  
fill ~72 ~1 ~22 ~72 ~2 ~22 stone 0  
fill ~72 ~1 ~26 ~72 ~30 ~26 stonebrick 2  
fill ~72 ~1 ~32 ~74 ~1 ~32 stonebrick 2 
setblock ~72 ~1 ~54 torch 5  
fill ~72 ~1 ~58 ~72 ~29 ~58 stonebrick 2  
fill ~72 ~1 ~62 ~72 ~30 ~62 stonebrick 2 
setblock ~72 ~1 ~66 stonebrick 0  
fill ~72 ~1 ~73 ~74 ~1 ~73 stonebrick 2  
fill ~73 ~1 ~19 ~75 ~1 ~19 stone 0 
setblock ~73 ~1 ~23 stonebrick 0  
fill ~73 ~1 ~27 ~73 ~30 ~27 stonebrick 2  
fill ~73 ~1 ~56 ~73 ~29 ~56 stonebrick 2  
fill ~73 ~1 ~57 ~73 ~29 ~57 stonebrick 2  
fill ~73 ~1 ~61 ~73 ~30 ~61 stonebrick 2 
setblock ~73 ~1 ~65 stonebrick 0  
fill ~73 ~1 ~74 ~75 ~1 ~74 stonebrick 2  
fill ~74 ~1 ~20 ~76 ~1 ~20 stone 0 
setblock ~74 ~1 ~24 stonebrick 0  
fill ~74 ~1 ~28 ~74 ~30 ~28 stonebrick 2  
fill ~74 ~1 ~33 ~74 ~29 ~33 stonebrick 2  
fill ~74 ~1 ~55 ~74 ~29 ~55 stonebrick 2  
fill ~74 ~1 ~60 ~74 ~30 ~60 stonebrick 2 
setblock ~74 ~1 ~64 stonebrick 0  
fill ~74 ~1 ~75 ~75 ~1 ~75 stonebrick 2  
fill ~75 ~1 ~21 ~77 ~1 ~21 stone 0  
fill ~75 ~1 ~22 ~77 ~1 ~22 stone 0  
fill ~75 ~1 ~23 ~78 ~1 ~23 stone 0 
setblock ~75 ~1 ~25 stonebrick 0  
fill ~75 ~1 ~29 ~75 ~30 ~29 stonebrick 2  
fill ~75 ~1 ~34 ~75 ~29 ~34 stonebrick 2  
fill ~75 ~1 ~35 ~75 ~29 ~35 stonebrick 2  
fill ~75 ~1 ~36 ~75 ~29 ~36 stonebrick 2 
setblock ~75 ~1 ~38 torch 5  
fill ~75 ~1 ~52 ~75 ~29 ~52 stonebrick 2  
fill ~75 ~1 ~53 ~75 ~29 ~53 stonebrick 2  
fill ~75 ~1 ~54 ~75 ~29 ~54 stonebrick 2  
fill ~75 ~1 ~59 ~75 ~30 ~59 stonebrick 2 
setblock ~75 ~1 ~63 stonebrick 0  
fill ~76 ~1 ~24 ~79 ~1 ~24 stone 0  
fill ~76 ~1 ~25 ~79 ~1 ~25 stone 0 
setblock ~76 ~1 ~26 stonebrick 0  
fill ~76 ~1 ~30 ~76 ~30 ~30 stonebrick 2  
fill ~76 ~1 ~31 ~76 ~30 ~31 stonebrick 2  
fill ~76 ~1 ~37 ~76 ~29 ~37 stonebrick 2  
fill ~76 ~1 ~38 ~76 ~29 ~38 stonebrick 2  
fill ~76 ~1 ~39 ~76 ~29 ~39 stonebrick 2  
fill ~76 ~1 ~49 ~76 ~29 ~49 stonebrick 2  
fill ~76 ~1 ~50 ~76 ~29 ~50 stonebrick 2  
fill ~76 ~1 ~51 ~76 ~29 ~51 stonebrick 2  
fill ~76 ~1 ~57 ~76 ~30 ~57 stonebrick 2  
fill ~76 ~1 ~58 ~76 ~30 ~58 stonebrick 2 
setblock ~76 ~1 ~62 stonebrick 0  
fill ~77 ~1 ~26 ~78 ~1 ~26 stone 0 
setblock ~77 ~1 ~27 stonebrick 0  
fill ~77 ~1 ~32 ~77 ~30 ~32 stonebrick 2  
fill ~77 ~1 ~33 ~77 ~30 ~33 stonebrick 2  
fill ~77 ~1 ~40 ~77 ~29 ~40 stonebrick 2  
fill ~77 ~1 ~41 ~77 ~29 ~41 stonebrick 2  
fill ~77 ~1 ~42 ~77 ~29 ~42 stonebrick 2  
fill ~77 ~1 ~43 ~77 ~29 ~43 stonebrick 2  
fill ~77 ~1 ~45 ~77 ~29 ~45 stonebrick 2  
fill ~77 ~1 ~46 ~77 ~29 ~46 stonebrick 2  
fill ~77 ~1 ~47 ~77 ~29 ~47 stonebrick 2  
fill ~77 ~1 ~48 ~77 ~29 ~48 stonebrick 2  
fill ~77 ~1 ~55 ~77 ~30 ~55 stonebrick 2  
fill ~77 ~1 ~56 ~77 ~30 ~56 stonebrick 2 
setblock ~77 ~1 ~61 stonebrick 0  
fill ~78 ~1 ~27 ~80 ~1 ~27 stonebrick 2 
setblock ~78 ~1 ~28 stonebrick 0  
fill ~78 ~1 ~29 ~78 ~30 ~29 stonebrick 2  
fill ~78 ~1 ~34 ~78 ~30 ~34 stonebrick 2  
fill ~78 ~1 ~35 ~78 ~30 ~35 stonebrick 2 
setblock ~78 ~1 ~50 torch 5  
fill ~78 ~1 ~53 ~78 ~30 ~53 stonebrick 2  
fill ~78 ~1 ~54 ~78 ~30 ~54 stonebrick 2  
fill ~78 ~1 ~59 ~78 ~30 ~59 stonebrick 2 
setblock ~78 ~1 ~60 stonebrick 0  
fill ~78 ~1 ~61 ~80 ~1 ~61 stonebrick 2  
fill ~79 ~1 ~26 ~81 ~1 ~26 stonebrick 2  
fill ~79 ~1 ~28 ~79 ~18 ~28 stonebrick 2  
fill ~79 ~1 ~30 ~79 ~30 ~30 stonebrick 2  
fill ~79 ~1 ~31 ~79 ~30 ~31 stonebrick 2  
fill ~79 ~1 ~36 ~79 ~30 ~36 stonebrick 2  
fill ~79 ~1 ~37 ~79 ~30 ~37 stonebrick 2  
fill ~79 ~1 ~38 ~79 ~30 ~38 stonebrick 2  
fill ~79 ~1 ~50 ~79 ~30 ~50 stonebrick 2  
fill ~79 ~1 ~51 ~79 ~30 ~51 stonebrick 2  
fill ~79 ~1 ~52 ~79 ~30 ~52 stonebrick 2  
fill ~79 ~1 ~57 ~79 ~30 ~57 stonebrick 2  
fill ~79 ~1 ~58 ~79 ~30 ~58 stonebrick 2  
fill ~79 ~1 ~60 ~79 ~18 ~60 stonebrick 2  
fill ~79 ~1 ~62 ~81 ~1 ~62 stonebrick 2  
fill ~80 ~1 ~25 ~82 ~1 ~25 stonebrick 2  
fill ~80 ~1 ~32 ~80 ~30 ~32 stonebrick 2  
fill ~80 ~1 ~33 ~80 ~30 ~33 stonebrick 2  
fill ~80 ~1 ~39 ~80 ~30 ~39 stonebrick 2  
fill ~80 ~1 ~40 ~80 ~30 ~40 stonebrick 2  
fill ~80 ~1 ~41 ~80 ~30 ~41 stonebrick 2  
fill ~80 ~1 ~42 ~80 ~30 ~42 stonebrick 2  
fill ~80 ~1 ~43 ~80 ~30 ~43 stonebrick 2  
fill ~80 ~1 ~44 ~80 ~30 ~44 stonebrick 2  
fill ~80 ~1 ~45 ~80 ~30 ~45 stonebrick 2  
fill ~80 ~1 ~46 ~80 ~30 ~46 stonebrick 2  
fill ~80 ~1 ~47 ~80 ~30 ~47 stonebrick 2  
fill ~80 ~1 ~48 ~80 ~30 ~48 stonebrick 2  
fill ~80 ~1 ~49 ~80 ~30 ~49 stonebrick 2  
fill ~80 ~1 ~55 ~80 ~30 ~55 stonebrick 2  
fill ~80 ~1 ~56 ~80 ~30 ~56 stonebrick 2  
fill ~80 ~1 ~63 ~82 ~1 ~63 stonebrick 2  
fill ~81 ~1 ~24 ~83 ~1 ~24 stonebrick 2  
fill ~81 ~1 ~34 ~81 ~30 ~34 stonebrick 2  
fill ~81 ~1 ~35 ~81 ~30 ~35 stonebrick 2  
fill ~81 ~1 ~53 ~81 ~30 ~53 stonebrick 2  
fill ~81 ~1 ~54 ~81 ~30 ~54 stonebrick 2  
fill ~81 ~1 ~64 ~83 ~1 ~64 stonebrick 2  
fill ~82 ~1 ~23 ~84 ~1 ~23 stonebrick 2  
fill ~82 ~1 ~36 ~82 ~30 ~36 stonebrick 2  
fill ~82 ~1 ~37 ~89 ~1 ~37 stonebrick 2  
fill ~82 ~1 ~51 ~89 ~1 ~51 stonebrick 2  
fill ~82 ~1 ~52 ~82 ~30 ~52 stonebrick 2  
fill ~82 ~1 ~65 ~84 ~1 ~65 stonebrick 2  
fill ~83 ~1 ~22 ~84 ~1 ~22 stonebrick 2  
fill ~83 ~1 ~38 ~90 ~1 ~38 stonebrick 2  
fill ~83 ~1 ~39 ~83 ~1 ~49 stonebrick 0  
fill ~83 ~1 ~50 ~90 ~1 ~50 stonebrick 2  
fill ~83 ~1 ~66 ~84 ~1 ~66 stonebrick 2  
fill ~84 ~1 ~39 ~89 ~1 ~39 stonebrick 2  
fill ~84 ~1 ~49 ~89 ~1 ~49 stonebrick 2  
fill ~2 ~2 ~25 ~3 ~2 ~25 stone 0  
fill ~2 ~2 ~26 ~2 ~3 ~26 stone 0  
fill ~2 ~2 ~28 ~2 ~4 ~28 stone 0  
fill ~2 ~2 ~29 ~2 ~4 ~29 stone 0  
fill ~2 ~2 ~30 ~2 ~4 ~30 stone 0  
fill ~2 ~2 ~33 ~2 ~3 ~33 stone 0  
fill ~2 ~2 ~34 ~2 ~3 ~34 stone 0  
fill ~3 ~2 ~24 ~4 ~2 ~24 stone 0  
fill ~3 ~2 ~35 ~3 ~3 ~35 stone 0  
fill ~4 ~2 ~23 ~5 ~2 ~23 stone 0  
fill ~4 ~2 ~36 ~4 ~3 ~36 stone 0  
fill ~4 ~2 ~37 ~5 ~2 ~37 stone 0  
fill ~5 ~2 ~22 ~6 ~2 ~22 stone 0  
fill ~5 ~2 ~38 ~6 ~2 ~38 stone 0  
fill ~6 ~2 ~21 ~7 ~2 ~21 stone 0  
fill ~7 ~2 ~20 ~8 ~2 ~20 stone 0  
fill ~7 ~2 ~39 ~7 ~3 ~39 stone 0  
fill ~7 ~2 ~40 ~8 ~2 ~40 stone 0  
fill ~8 ~2 ~18 ~9 ~2 ~18 stone 0  
fill ~8 ~2 ~19 ~8 ~2 ~18 stone 0  
fill ~8 ~2 ~41 ~11 ~2 ~41 stone 0  
fill ~9 ~2 ~17 ~10 ~2 ~17 stone 0  
fill ~10 ~2 ~12 ~11 ~2 ~12 stone 0  
fill ~10 ~2 ~13 ~11 ~2 ~13 stone 0  
fill ~10 ~2 ~14 ~10 ~3 ~14 stone 0  
fill ~10 ~2 ~15 ~10 ~3 ~15 stone 0  
fill ~10 ~2 ~16 ~10 ~4 ~16 stone 0  
fill ~11 ~2 ~8 ~17 ~2 ~8 stone 0  
fill ~11 ~2 ~9 ~11 ~2 ~13 stone 0  
fill ~11 ~2 ~42 ~14 ~2 ~42 stone 0  
fill ~13 ~2 ~41 ~13 ~4 ~41 stone 0  
fill ~14 ~2 ~43 ~21 ~2 ~43 stone 0  
fill ~14 ~2 ~49 ~16 ~2 ~49 stone 0  
fill ~15 ~2 ~48 ~16 ~2 ~48 stone 0 
setblock ~15 ~2 ~50 stone 0  
fill ~16 ~2 ~42 ~16 ~4 ~42 stone 0 
setblock ~16 ~2 ~47 stone 0  
fill ~16 ~2 ~50 ~23 ~2 ~50 stonebrick 2  
fill ~17 ~2 ~9 ~18 ~2 ~9 stone 0  
fill ~17 ~2 ~46 ~22 ~2 ~46 stone 0  
fill ~17 ~2 ~49 ~23 ~2 ~49 stonebrick 2  
fill ~17 ~2 ~51 ~24 ~2 ~51 stonebrick 2  
fill ~18 ~2 ~10 ~20 ~2 ~10 stone 0  
fill ~18 ~2 ~38 ~20 ~2 ~38 stonebrick 2  
fill ~18 ~2 ~45 ~22 ~2 ~45 stone 0  
fill ~19 ~2 ~42 ~20 ~2 ~42 stone 0  
fill ~19 ~2 ~44 ~22 ~2 ~44 stone 0  
fill ~19 ~2 ~47 ~19 ~5 ~47 stone 0  
fill ~20 ~2 ~11 ~23 ~2 ~11 stone 0  
fill ~21 ~2 ~52 ~23 ~2 ~52 stone 0  
fill ~22 ~2 ~12 ~22 ~3 ~12 stone 0 
setblock ~22 ~2 ~42 stone 0  
fill ~22 ~2 ~65 ~22 ~8 ~65 stonebrick 2  
fill ~22 ~2 ~66 ~23 ~2 ~66 stonebrick 2  
fill ~23 ~2 ~38 ~23 ~36 ~38 stonebrick 2  
fill ~23 ~2 ~39 ~23 ~35 ~39 stonebrick 2  
fill ~23 ~2 ~40 ~23 ~35 ~40 stonebrick 2  
fill ~23 ~2 ~41 ~23 ~34 ~41 stonebrick 2  
fill ~23 ~2 ~42 ~23 ~34 ~42 stonebrick 2  
fill ~23 ~2 ~43 ~23 ~33 ~43 stonebrick 2  
fill ~23 ~2 ~44 ~23 ~33 ~44 stonebrick 2  
fill ~23 ~2 ~45 ~23 ~32 ~45 stonebrick 2  
fill ~23 ~2 ~46 ~23 ~32 ~46 stonebrick 2  
fill ~23 ~2 ~47 ~23 ~31 ~47 stonebrick 2  
fill ~23 ~2 ~48 ~23 ~31 ~48 stonebrick 2  
fill ~23 ~2 ~64 ~23 ~10 ~64 stonebrick 2  
fill ~23 ~2 ~65 ~23 ~6 ~65 dirt 0  
fill ~24 ~2 ~37 ~24 ~15 ~37 stonebrick 2  
fill ~24 ~2 ~63 ~24 ~12 ~63 stonebrick 2  
fill ~24 ~2 ~64 ~24 ~6 ~64 dirt 0  
fill ~24 ~2 ~65 ~24 ~10 ~65 stonebrick 2  
fill ~25 ~2 ~12 ~29 ~2 ~12 stone 0  
fill ~25 ~2 ~62 ~25 ~14 ~62 stonebrick 2  
fill ~25 ~2 ~63 ~25 ~8 ~63 dirt 0  
fill ~25 ~2 ~64 ~25 ~12 ~64 stonebrick 2  
fill ~26 ~2 ~61 ~26 ~16 ~61 stonebrick 2  
fill ~26 ~2 ~62 ~26 ~10 ~62 dirt 0  
fill ~26 ~2 ~63 ~26 ~14 ~63 stonebrick 2  
fill ~27 ~2 ~11 ~34 ~2 ~11 stone 0  
fill ~27 ~2 ~61 ~27 ~12 ~61 dirt 0  
fill ~27 ~2 ~62 ~27 ~16 ~62 stonebrick 2  
fill ~28 ~2 ~28 ~28 ~15 ~28 stonebrick 2  
fill ~28 ~2 ~60 ~28 ~30 ~60 stonebrick 2  
fill ~28 ~2 ~61 ~29 ~2 ~61 stonebrick 2  
fill ~29 ~2 ~27 ~29 ~15 ~27 stonebrick 2  
fill ~29 ~2 ~44 ~29 ~29 ~44 stonebrick 2  
fill ~30 ~2 ~26 ~30 ~15 ~26 stonebrick 2  
fill ~30 ~2 ~62 ~30 ~30 ~62 stonebrick 2  
fill ~31 ~2 ~25 ~31 ~15 ~25 stonebrick 2  
fill ~31 ~2 ~63 ~31 ~30 ~63 stonebrick 2  
fill ~31 ~2 ~74 ~31 ~8 ~74 stonebrick 2  
fill ~31 ~2 ~75 ~32 ~2 ~75 stonebrick 2  
fill ~32 ~2 ~24 ~32 ~15 ~24 stonebrick 2  
fill ~32 ~2 ~64 ~32 ~30 ~64 stonebrick 2  
fill ~32 ~2 ~73 ~32 ~10 ~73 stonebrick 2  
fill ~32 ~2 ~74 ~32 ~6 ~74 dirt 0  
fill ~33 ~2 ~23 ~33 ~15 ~23 stonebrick 2  
fill ~33 ~2 ~65 ~33 ~30 ~65 stonebrick 2  
fill ~33 ~2 ~72 ~33 ~12 ~72 stonebrick 2  
fill ~33 ~2 ~73 ~33 ~6 ~73 dirt 0  
fill ~33 ~2 ~74 ~33 ~10 ~74 stonebrick 2  
fill ~34 ~2 ~22 ~34 ~15 ~22 stonebrick 2  
fill ~34 ~2 ~66 ~34 ~30 ~66 stonebrick 2  
fill ~34 ~2 ~71 ~34 ~14 ~71 stonebrick 2  
fill ~34 ~2 ~72 ~34 ~8 ~72 dirt 0  
fill ~34 ~2 ~73 ~34 ~12 ~73 stonebrick 2  
fill ~35 ~2 ~10 ~37 ~2 ~10 stone 0  
fill ~35 ~2 ~21 ~35 ~15 ~21 stonebrick 2  
fill ~35 ~2 ~67 ~35 ~30 ~67 stonebrick 2  
fill ~35 ~2 ~70 ~35 ~16 ~70 stonebrick 2  
fill ~35 ~2 ~71 ~35 ~10 ~71 dirt 0  
fill ~35 ~2 ~72 ~35 ~14 ~72 stonebrick 2  
fill ~36 ~2 ~20 ~36 ~15 ~20 stonebrick 2  
fill ~36 ~2 ~68 ~36 ~30 ~68 stonebrick 2  
fill ~36 ~2 ~70 ~36 ~12 ~70 dirt 0  
fill ~36 ~2 ~71 ~36 ~16 ~71 stonebrick 2  
fill ~37 ~2 ~9 ~38 ~2 ~9 stone 0  
fill ~37 ~2 ~19 ~37 ~15 ~19 stonebrick 2  
fill ~37 ~2 ~69 ~37 ~30 ~69 stonebrick 2  
fill ~37 ~2 ~70 ~37 ~18 ~70 stonebrick 2  
fill ~38 ~2 ~61 ~38 ~2 ~62 furnace 5  
fill ~39 ~2 ~63 ~39 ~2 ~64 furnace 5  
fill ~39 ~2 ~67 ~40 ~2 ~67 stonebrick 2  
fill ~39 ~2 ~70 ~40 ~2 ~70 stonebrick 2  
fill ~40 ~2 ~9 ~48 ~2 ~9 stone 0  
fill ~41 ~2 ~17 ~42 ~2 ~17 stonebrick 2  
fill ~41 ~2 ~71 ~42 ~2 ~71 stonebrick 2 
setblock ~42 ~2 ~67 purple_shulker_box 2  
fill ~43 ~2 ~8 ~44 ~2 ~8 stone 0  
fill ~43 ~2 ~16 ~44 ~2 ~16 stonebrick 2 
setblock ~43 ~2 ~44 torch 5  
fill ~43 ~2 ~67 ~44 ~2 ~67 chest 2  
fill ~43 ~2 ~68 ~45 ~2 ~68 stone 0  
fill ~43 ~2 ~69 ~44 ~2 ~69 stonebrick 2  
fill ~43 ~2 ~72 ~44 ~2 ~72 stonebrick 2  
fill ~45 ~2 ~15 ~46 ~2 ~15 stonebrick 2 
setblock ~45 ~2 ~67 purple_shulker_box 2  
fill ~45 ~2 ~70 ~47 ~2 ~70 stonebrick 2  
fill ~45 ~2 ~73 ~46 ~2 ~73 stonebrick 2  
fill ~46 ~2 ~74 ~50 ~2 ~74 stonebrick 2  
fill ~46 ~2 ~75 ~46 ~18 ~75 stonebrick 2  
fill ~46 ~2 ~76 ~46 ~16 ~76 stonebrick 2  
fill ~46 ~2 ~77 ~46 ~14 ~77 stonebrick 2  
fill ~46 ~2 ~78 ~46 ~12 ~78 stonebrick 2  
fill ~46 ~2 ~79 ~46 ~10 ~79 stonebrick 2  
fill ~46 ~2 ~80 ~46 ~8 ~80 stonebrick 2  
fill ~46 ~2 ~86 ~46 ~12 ~86 cobblestone_wall 0  
fill ~46 ~2 ~87 ~46 ~35 ~87 stonebrick 2  
fill ~46 ~2 ~88 ~46 ~12 ~88 cobblestone_wall 0  
fill ~47 ~2 ~10 ~47 ~4 ~10 stone 0  
fill ~47 ~2 ~67 ~48 ~2 ~67 stonebrick 0  
fill ~47 ~2 ~75 ~47 ~13 ~75 dirt 0  
fill ~47 ~2 ~76 ~47 ~13 ~76 dirt 0  
fill ~47 ~2 ~77 ~47 ~13 ~77 dirt 0  
fill ~47 ~2 ~78 ~47 ~8 ~78 dirt 0  
fill ~47 ~2 ~79 ~47 ~7 ~79 dirt 0  
fill ~47 ~2 ~80 ~47 ~7 ~80 dirt 0  
fill ~47 ~2 ~86 ~47 ~35 ~86 stonebrick 2  
fill ~47 ~2 ~87 ~47 ~12 ~87 dirt 0  
fill ~47 ~2 ~88 ~47 ~35 ~88 stonebrick 2  
fill ~48 ~2 ~8 ~49 ~2 ~8 stone 0  
fill ~48 ~2 ~14 ~59 ~2 ~14 stonebrick 2  
fill ~48 ~2 ~71 ~49 ~2 ~71 stonebrick 2  
fill ~48 ~2 ~75 ~48 ~18 ~75 stonebrick 2  
fill ~48 ~2 ~76 ~48 ~16 ~76 stonebrick 2  
fill ~48 ~2 ~77 ~48 ~14 ~77 stonebrick 2  
fill ~48 ~2 ~78 ~48 ~12 ~78 stonebrick 2  
fill ~48 ~2 ~79 ~48 ~10 ~79 stonebrick 2  
fill ~48 ~2 ~80 ~48 ~8 ~80 stonebrick 2  
fill ~48 ~2 ~86 ~48 ~12 ~86 cobblestone_wall 0  
fill ~48 ~2 ~87 ~48 ~35 ~87 stonebrick 2  
fill ~48 ~2 ~88 ~48 ~12 ~88 cobblestone_wall 0  
fill ~49 ~2 ~7 ~50 ~2 ~7 stone 0  
fill ~50 ~2 ~6 ~53 ~2 ~6 stone 0  
fill ~52 ~2 ~5 ~54 ~2 ~5 stone 0  
fill ~52 ~2 ~68 ~57 ~2 ~68 stonebrick 2  
fill ~52 ~2 ~71 ~58 ~2 ~71 stonebrick 2  
fill ~52 ~2 ~74 ~60 ~2 ~74 stonebrick 2  
fill ~52 ~2 ~75 ~54 ~2 ~75 stonebrick 2  
fill ~52 ~2 ~84 ~54 ~2 ~84 stonebrick 2 
setblock ~53 ~2 ~26 torch 5 
setblock ~53 ~2 ~35 torch 5  
fill ~53 ~2 ~44 ~53 ~30 ~44 stone 0  
fill ~53 ~2 ~45 ~53 ~152 ~45 ladder 3 
setblock ~53 ~2 ~51 torch 5  
fill ~55 ~2 ~4 ~57 ~2 ~4 stone 0  
fill ~57 ~2 ~3 ~60 ~2 ~3 stone 0 
setblock ~58 ~2 ~2 stone 0  
fill ~58 ~2 ~67 ~60 ~2 ~67 stonebrick 2  
fill ~58 ~2 ~75 ~58 ~18 ~75 stonebrick 2  
fill ~58 ~2 ~76 ~58 ~16 ~76 stonebrick 2  
fill ~58 ~2 ~77 ~58 ~14 ~77 stonebrick 2  
fill ~58 ~2 ~78 ~58 ~12 ~78 stonebrick 2  
fill ~58 ~2 ~79 ~58 ~10 ~79 stonebrick 2  
fill ~58 ~2 ~80 ~60 ~2 ~80 stonebrick 2  
fill ~58 ~2 ~86 ~58 ~12 ~86 cobblestone_wall 0  
fill ~58 ~2 ~87 ~60 ~2 ~87 stonebrick 2  
fill ~58 ~2 ~88 ~58 ~12 ~88 cobblestone_wall 0  
fill ~59 ~2 ~70 ~61 ~2 ~70 stonebrick 2  
fill ~59 ~2 ~75 ~59 ~7 ~75 cobblestone 0  
fill ~59 ~2 ~76 ~59 ~7 ~76 cobblestone 0  
fill ~59 ~2 ~77 ~59 ~7 ~77 cobblestone 0  
fill ~59 ~2 ~78 ~59 ~7 ~78 cobblestone 0  
fill ~59 ~2 ~79 ~59 ~7 ~79 cobblestone 0  
fill ~59 ~2 ~86 ~59 ~35 ~86 stonebrick 2  
fill ~59 ~2 ~88 ~59 ~35 ~88 stonebrick 2  
fill ~60 ~2 ~4 ~62 ~2 ~4 stone 0  
fill ~60 ~2 ~15 ~61 ~2 ~15 stonebrick 2  
fill ~60 ~2 ~73 ~61 ~2 ~73 stonebrick 2  
fill ~60 ~2 ~75 ~60 ~18 ~75 stonebrick 2  
fill ~60 ~2 ~76 ~60 ~16 ~76 stonebrick 2  
fill ~60 ~2 ~77 ~60 ~14 ~77 stonebrick 2  
fill ~60 ~2 ~78 ~60 ~12 ~78 stonebrick 2  
fill ~60 ~2 ~79 ~60 ~10 ~79 stonebrick 2  
fill ~60 ~2 ~86 ~60 ~12 ~86 cobblestone_wall 0  
fill ~60 ~2 ~88 ~60 ~12 ~88 cobblestone_wall 0  
fill ~61 ~2 ~66 ~63 ~2 ~66 stonebrick 2  
fill ~62 ~2 ~16 ~63 ~2 ~16 stonebrick 2  
fill ~62 ~2 ~69 ~63 ~2 ~69 stonebrick 2  
fill ~62 ~2 ~72 ~63 ~2 ~72 stonebrick 2  
fill ~63 ~2 ~5 ~66 ~2 ~5 stone 0  
fill ~64 ~2 ~17 ~65 ~2 ~17 stonebrick 2  
fill ~64 ~2 ~68 ~65 ~2 ~68 stonebrick 2  
fill ~64 ~2 ~71 ~65 ~2 ~71 stonebrick 2  
fill ~65 ~2 ~64 ~66 ~2 ~64 stonebrick 2  
fill ~66 ~2 ~6 ~66 ~3 ~6 stone 0  
fill ~66 ~2 ~18 ~67 ~2 ~18 stonebrick 2  
fill ~66 ~2 ~67 ~67 ~2 ~67 stonebrick 2  
fill ~66 ~2 ~70 ~67 ~2 ~70 stonebrick 2  
fill ~67 ~2 ~7 ~67 ~1 ~7 stone 0  
fill ~67 ~2 ~8 ~68 ~2 ~8 stone 0  
fill ~68 ~2 ~9 ~69 ~2 ~9 stone 0  
fill ~68 ~2 ~10 ~69 ~2 ~10 stone 0  
fill ~69 ~2 ~11 ~70 ~2 ~11 stone 0  
fill ~69 ~2 ~12 ~70 ~2 ~12 stone 0  
fill ~69 ~2 ~13 ~71 ~2 ~13 stone 0  
fill ~69 ~2 ~15 ~71 ~2 ~15 stone 0  
fill ~69 ~2 ~19 ~69 ~15 ~19 stonebrick 2 
setblock ~69 ~2 ~44 torch 5  
fill ~69 ~2 ~69 ~69 ~19 ~69 stonebrick 2  
fill ~69 ~2 ~70 ~71 ~2 ~70 stonebrick 2  
fill ~70 ~2 ~14 ~71 ~2 ~14 stone 0  
fill ~70 ~2 ~16 ~70 ~4 ~16 stone 0  
fill ~70 ~2 ~17 ~71 ~2 ~17 stone 0  
fill ~70 ~2 ~18 ~72 ~2 ~18 stone 0  
fill ~70 ~2 ~20 ~70 ~15 ~20 stonebrick 2  
fill ~70 ~2 ~68 ~70 ~30 ~68 stonebrick 2  
fill ~70 ~2 ~71 ~72 ~2 ~71 stonebrick 2  
fill ~71 ~2 ~19 ~71 ~7 ~19 stone 0  
fill ~71 ~2 ~21 ~71 ~15 ~21 stonebrick 2  
fill ~71 ~2 ~67 ~71 ~30 ~67 stonebrick 2  
fill ~71 ~2 ~72 ~73 ~2 ~72 stonebrick 2  
fill ~72 ~2 ~32 ~74 ~2 ~32 stonebrick 2  
fill ~72 ~2 ~66 ~72 ~30 ~66 stonebrick 2  
fill ~72 ~2 ~73 ~74 ~2 ~73 stonebrick 2  
fill ~73 ~2 ~19 ~73 ~3 ~19 stone 0  
fill ~73 ~2 ~20 ~74 ~2 ~20 stone 0  
fill ~73 ~2 ~23 ~73 ~30 ~23 stonebrick 2  
fill ~73 ~2 ~65 ~73 ~30 ~65 stonebrick 2  
fill ~73 ~2 ~74 ~75 ~2 ~74 stonebrick 2  
fill ~74 ~2 ~24 ~74 ~30 ~24 stonebrick 2  
fill ~74 ~2 ~64 ~74 ~30 ~64 stonebrick 2  
fill ~74 ~2 ~75 ~75 ~2 ~75 stonebrick 2  
fill ~75 ~2 ~21 ~75 ~3 ~21 stone 0  
fill ~75 ~2 ~22 ~75 ~4 ~22 stone 0  
fill ~75 ~2 ~23 ~76 ~2 ~23 stone 0  
fill ~75 ~2 ~25 ~75 ~30 ~25 stonebrick 2  
fill ~75 ~2 ~63 ~75 ~30 ~63 stonebrick 2  
fill ~76 ~2 ~24 ~76 ~3 ~24 stone 0  
fill ~76 ~2 ~25 ~77 ~2 ~25 stone 0  
fill ~76 ~2 ~26 ~76 ~30 ~26 stonebrick 2  
fill ~76 ~2 ~62 ~76 ~30 ~62 stonebrick 2  
fill ~77 ~2 ~26 ~78 ~2 ~26 stone 0  
fill ~77 ~2 ~27 ~80 ~2 ~27 stonebrick 2  
fill ~77 ~2 ~44 ~77 ~29 ~44 stonebrick 2  
fill ~77 ~2 ~61 ~80 ~2 ~61 stonebrick 2  
fill ~78 ~2 ~28 ~78 ~30 ~28 stonebrick 2  
fill ~78 ~2 ~60 ~78 ~15 ~60 stonebrick 2  
fill ~79 ~2 ~26 ~81 ~2 ~26 stonebrick 2  
fill ~79 ~2 ~62 ~81 ~2 ~62 stonebrick 2  
fill ~80 ~2 ~25 ~82 ~2 ~25 stonebrick 2  
fill ~80 ~2 ~63 ~82 ~2 ~63 stonebrick 2  
fill ~81 ~2 ~24 ~83 ~2 ~24 stonebrick 2  
fill ~81 ~2 ~64 ~83 ~2 ~64 stonebrick 2  
fill ~82 ~2 ~23 ~84 ~2 ~23 stonebrick 2  
fill ~82 ~2 ~37 ~89 ~2 ~37 stonebrick 2  
fill ~82 ~2 ~51 ~89 ~2 ~51 stonebrick 2  
fill ~82 ~2 ~65 ~84 ~2 ~65 stonebrick 2  
fill ~83 ~2 ~22 ~84 ~2 ~22 stonebrick 2  
fill ~83 ~2 ~38 ~90 ~2 ~38 stonebrick 2  
fill ~83 ~2 ~39 ~89 ~2 ~39 stonebrick 2  
fill ~83 ~2 ~40 ~83 ~30 ~40 stonebrick 2  
fill ~83 ~2 ~41 ~83 ~30 ~41 stonebrick 2  
fill ~83 ~2 ~42 ~83 ~30 ~42 stonebrick 2  
fill ~83 ~2 ~43 ~83 ~30 ~43 stonebrick 2  
fill ~83 ~2 ~44 ~83 ~30 ~44 stonebrick 2  
fill ~83 ~2 ~45 ~83 ~30 ~45 stonebrick 2  
fill ~83 ~2 ~46 ~83 ~30 ~46 stonebrick 2  
fill ~83 ~2 ~47 ~83 ~30 ~47 stonebrick 2  
fill ~83 ~2 ~48 ~83 ~30 ~48 stonebrick 2  
fill ~83 ~2 ~49 ~89 ~2 ~49 stonebrick 2  
fill ~83 ~2 ~50 ~86 ~2 ~50 stonebrick 2  
fill ~83 ~2 ~66 ~84 ~2 ~66 stonebrick 2  
fill ~88 ~2 ~50 ~90 ~2 ~50 stonebrick 2 
setblock ~2 ~3 ~27 stone 0  
fill ~2 ~3 ~32 ~2 ~4 ~32 stone 0  
fill ~3 ~3 ~25 ~4 ~3 ~25 stone 0  
fill ~3 ~3 ~26 ~3 ~4 ~26 stone 0  
fill ~3 ~3 ~34 ~3 ~4 ~34 stone 0  
fill ~4 ~3 ~23 ~5 ~3 ~23 stone 0  
fill ~4 ~3 ~24 ~4 ~4 ~24 stone 0  
fill ~4 ~3 ~35 ~4 ~4 ~35 stone 0  
fill ~5 ~3 ~22 ~7 ~3 ~22 stone 0  
fill ~5 ~3 ~36 ~5 ~5 ~36 stone 0  
fill ~5 ~3 ~37 ~5 ~4 ~37 stone 0  
fill ~5 ~3 ~38 ~6 ~3 ~38 stone 0  
fill ~7 ~3 ~21 ~8 ~3 ~21 stone 0  
fill ~8 ~3 ~20 ~9 ~3 ~20 stone 0  
fill ~8 ~3 ~39 ~8 ~3 ~40 stone 0  
fill ~9 ~3 ~18 ~10 ~3 ~18 stone 0  
fill ~9 ~3 ~19 ~9 ~4 ~19 stone 0  
fill ~9 ~3 ~40 ~10 ~3 ~40 stone 0  
fill ~10 ~3 ~13 ~11 ~3 ~13 stone 0  
fill ~10 ~3 ~17 ~10 ~5 ~17 stone 0  
fill ~10 ~3 ~41 ~15 ~3 ~41 stone 0  
fill ~11 ~3 ~8 ~17 ~3 ~8 stone 0  
fill ~11 ~3 ~10 ~12 ~3 ~10 stone 0  
fill ~11 ~3 ~11 ~11 ~4 ~11 stone 0  
fill ~11 ~3 ~12 ~11 ~7 ~12 stone 0  
fill ~11 ~3 ~14 ~11 ~9 ~14 stone 0  
fill ~11 ~3 ~15 ~11 ~9 ~15 stone 0  
fill ~12 ~3 ~9 ~12 ~8 ~9 stone 0  
fill ~12 ~3 ~40 ~12 ~5 ~40 stone 0 
setblock ~15 ~3 ~42 stone 0 
setblock ~16 ~3 ~49 stone 0  
fill ~16 ~3 ~50 ~23 ~3 ~50 stonebrick 2  
fill ~17 ~3 ~9 ~18 ~3 ~9 stone 0  
fill ~17 ~3 ~42 ~20 ~3 ~42 stone 0  
fill ~17 ~3 ~48 ~17 ~4 ~48 stone 0  
fill ~17 ~3 ~49 ~23 ~3 ~49 stonebrick 2  
fill ~17 ~3 ~51 ~24 ~3 ~51 stonebrick 2  
fill ~18 ~3 ~38 ~20 ~3 ~38 stonebrick 2  
fill ~18 ~3 ~47 ~18 ~4 ~47 stone 0  
fill ~19 ~3 ~10 ~19 ~5 ~10 stone 0  
fill ~19 ~3 ~46 ~22 ~3 ~46 stone 0  
fill ~20 ~3 ~11 ~20 ~5 ~11 stone 0  
fill ~20 ~3 ~43 ~21 ~3 ~43 stone 0  
fill ~21 ~3 ~12 ~21 ~4 ~12 stone 0  
fill ~21 ~3 ~44 ~22 ~3 ~44 stone 0  
fill ~21 ~3 ~47 ~22 ~3 ~47 stone 0  
fill ~22 ~3 ~13 ~22 ~4 ~13 stone 0 
setblock ~22 ~3 ~45 stone 0  
fill ~22 ~3 ~66 ~23 ~3 ~66 stonebrick 2  
fill ~23 ~3 ~14 ~23 ~5 ~14 stone 0  
fill ~24 ~3 ~13 ~27 ~3 ~13 stone 0  
fill ~25 ~3 ~12 ~31 ~3 ~12 stone 0  
fill ~28 ~3 ~61 ~29 ~3 ~61 stonebrick 2  
fill ~31 ~3 ~11 ~36 ~3 ~11 stone 0  
fill ~31 ~3 ~75 ~32 ~3 ~75 stonebrick 2  
fill ~37 ~3 ~10 ~39 ~3 ~10 stone 0  
fill ~38 ~3 ~61 ~38 ~3 ~62 hopper 0  
fill ~39 ~3 ~11 ~39 ~6 ~11 stone 0  
fill ~39 ~3 ~63 ~39 ~3 ~64 hopper 0  
fill ~39 ~3 ~67 ~40 ~3 ~67 stonebrick 2  
fill ~39 ~3 ~70 ~40 ~3 ~70 stonebrick 2  
fill ~40 ~3 ~9 ~45 ~3 ~9 stone 0  
fill ~40 ~3 ~18 ~40 ~15 ~18 stonebrick 2  
fill ~41 ~3 ~10 ~41 ~5 ~10 stone 0  
fill ~41 ~3 ~17 ~42 ~3 ~17 stonebrick 2  
fill ~41 ~3 ~71 ~42 ~3 ~71 stonebrick 2  
fill ~43 ~3 ~16 ~44 ~3 ~16 stonebrick 2  
fill ~43 ~3 ~68 ~44 ~3 ~68 chest 2  
fill ~43 ~3 ~69 ~44 ~3 ~69 stonebrick 2  
fill ~43 ~3 ~72 ~44 ~3 ~72 stonebrick 2  
fill ~45 ~3 ~15 ~46 ~3 ~15 stonebrick 2 
setblock ~45 ~3 ~68 purple_shulker_box 5  
fill ~45 ~3 ~70 ~47 ~3 ~70 stonebrick 2  
fill ~45 ~3 ~73 ~46 ~3 ~73 stonebrick 2  
fill ~46 ~3 ~10 ~46 ~4 ~10 stone 0  
fill ~46 ~3 ~74 ~50 ~3 ~74 stonebrick 2  
fill ~47 ~3 ~11 ~47 ~5 ~11 stone 0  
fill ~47 ~3 ~67 ~48 ~3 ~67 stonebrick 0  
fill ~48 ~3 ~9 ~48 ~3 ~10 stone 0  
fill ~48 ~3 ~14 ~59 ~3 ~14 stonebrick 2  
fill ~48 ~3 ~71 ~49 ~3 ~71 stonebrick 2 
setblock ~49 ~3 ~8 stone 0  
fill ~50 ~3 ~7 ~53 ~3 ~7 stone 0  
fill ~52 ~3 ~68 ~57 ~3 ~68 stonebrick 2  
fill ~52 ~3 ~71 ~58 ~3 ~71 stonebrick 2  
fill ~52 ~3 ~74 ~60 ~3 ~74 stonebrick 2  
fill ~52 ~3 ~75 ~54 ~3 ~75 stonebrick 2  
fill ~52 ~3 ~84 ~54 ~3 ~84 stonebrick 2  
fill ~53 ~3 ~6 ~54 ~3 ~6 stone 0  
fill ~55 ~3 ~5 ~57 ~3 ~5 stone 0  
fill ~57 ~3 ~4 ~59 ~3 ~4 stone 0  
fill ~58 ~3 ~67 ~60 ~3 ~67 stonebrick 2  
fill ~58 ~3 ~80 ~60 ~3 ~80 stonebrick 2  
fill ~58 ~3 ~87 ~60 ~3 ~87 stonebrick 2  
fill ~59 ~3 ~5 ~63 ~3 ~5 stone 0 
setblock ~59 ~3 ~66 stone 0  
fill ~59 ~3 ~70 ~61 ~3 ~70 stonebrick 2   

KittysCommands:   
fill ~60 ~3 ~15 ~61 ~3 ~15 stonebrick 2 
setblock ~60 ~3 ~65 stone 0  
fill ~60 ~3 ~73 ~61 ~3 ~73 stonebrick 2  
fill ~61 ~3 ~66 ~63 ~3 ~66 stonebrick 2  
fill ~62 ~3 ~16 ~63 ~3 ~16 stonebrick 2  
fill ~62 ~3 ~69 ~63 ~3 ~69 stonebrick 2  
fill ~62 ~3 ~72 ~63 ~3 ~72 stonebrick 2  
fill ~64 ~3 ~6 ~66 ~3 ~6 stone 0  
fill ~64 ~3 ~17 ~65 ~3 ~17 stonebrick 2  
fill ~64 ~3 ~68 ~65 ~3 ~68 stonebrick 2  
fill ~64 ~3 ~71 ~65 ~3 ~71 stonebrick 2  
fill ~65 ~3 ~7 ~66 ~3 ~7 stone 0  
fill ~65 ~3 ~64 ~66 ~3 ~64 stonebrick 2  
fill ~66 ~3 ~18 ~67 ~3 ~18 stonebrick 2  
fill ~66 ~3 ~67 ~67 ~3 ~67 stonebrick 2  
fill ~66 ~3 ~70 ~67 ~3 ~70 stonebrick 2  
fill ~67 ~3 ~8 ~67 ~1 ~8 stone 0  
fill ~67 ~3 ~9 ~67 ~5 ~9 stone 0  
fill ~67 ~3 ~10 ~68 ~3 ~10 stone 0  
fill ~67 ~3 ~11 ~68 ~3 ~11 stone 0  
fill ~68 ~3 ~12 ~69 ~3 ~12 stone 0  
fill ~69 ~3 ~13 ~69 ~4 ~13 stone 0  
fill ~69 ~3 ~14 ~70 ~3 ~14 stone 0  
fill ~69 ~3 ~15 ~70 ~3 ~15 stone 0  
fill ~69 ~3 ~70 ~71 ~3 ~70 stonebrick 2  
fill ~70 ~3 ~17 ~70 ~6 ~17 stone 0  
fill ~70 ~3 ~18 ~71 ~3 ~18 stone 0  
fill ~70 ~3 ~19 ~70 ~9 ~19 stone 0  
fill ~70 ~3 ~71 ~72 ~3 ~71 stonebrick 2  
fill ~71 ~3 ~72 ~73 ~3 ~72 stonebrick 2  
fill ~72 ~3 ~19 ~72 ~5 ~19 stone 0  
fill ~72 ~3 ~22 ~72 ~15 ~22 stonebrick 2  
fill ~72 ~3 ~32 ~74 ~3 ~32 stonebrick 2  
fill ~72 ~3 ~73 ~74 ~3 ~73 stonebrick 2  
fill ~73 ~3 ~20 ~73 ~6 ~20 stone 0  
fill ~73 ~3 ~74 ~75 ~3 ~74 stonebrick 2  
fill ~74 ~3 ~21 ~74 ~7 ~21 stone 0  
fill ~74 ~3 ~75 ~75 ~3 ~75 stonebrick 2  
fill ~75 ~3 ~23 ~75 ~6 ~23 stone 0  
fill ~75 ~3 ~24 ~75 ~9 ~24 stone 0  
fill ~76 ~3 ~25 ~76 ~6 ~25 stone 0  
fill ~77 ~3 ~26 ~77 ~5 ~26 stone 0  
fill ~77 ~3 ~27 ~80 ~3 ~27 stonebrick 2  
fill ~77 ~3 ~61 ~80 ~3 ~61 stonebrick 2  
fill ~79 ~3 ~26 ~81 ~3 ~26 stonebrick 2  
fill ~79 ~3 ~62 ~81 ~3 ~62 stonebrick 2  
fill ~80 ~3 ~25 ~82 ~3 ~25 stonebrick 2  
fill ~80 ~3 ~63 ~82 ~3 ~63 stonebrick 2  
fill ~81 ~3 ~24 ~83 ~3 ~24 stonebrick 2  
fill ~81 ~3 ~64 ~83 ~3 ~64 stonebrick 2  
fill ~82 ~3 ~23 ~84 ~3 ~23 stonebrick 2  
fill ~82 ~3 ~37 ~89 ~3 ~37 stonebrick 2  
fill ~82 ~3 ~51 ~89 ~3 ~51 stonebrick 2  
fill ~82 ~3 ~65 ~84 ~3 ~65 stonebrick 2  
fill ~83 ~3 ~22 ~84 ~3 ~22 stonebrick 2  
fill ~83 ~3 ~38 ~90 ~3 ~38 stonebrick 2  
fill ~83 ~3 ~39 ~89 ~3 ~39 stonebrick 2  
fill ~83 ~3 ~49 ~89 ~3 ~49 stonebrick 2  
fill ~83 ~3 ~50 ~90 ~3 ~50 stonebrick 2  
fill ~83 ~3 ~66 ~84 ~3 ~66 stonebrick 2  
fill ~3 ~4 ~27 ~3 ~5 ~27 stone 0  
fill ~3 ~4 ~28 ~3 ~6 ~28 stone 0  
fill ~3 ~4 ~29 ~3 ~6 ~29 stone 0  
fill ~3 ~4 ~30 ~3 ~5 ~30 stone 0  
fill ~3 ~4 ~32 ~3 ~5 ~32 stone 0  
fill ~3 ~4 ~33 ~3 ~4 ~32 stone 0  
fill ~4 ~4 ~25 ~4 ~5 ~25 stone 0  
fill ~4 ~4 ~26 ~4 ~6 ~26 stone 0  
fill ~4 ~4 ~34 ~4 ~5 ~34 stone 0  
fill ~5 ~4 ~23 ~6 ~4 ~23 stone 0  
fill ~5 ~4 ~24 ~5 ~5 ~24 stone 0  
fill ~5 ~4 ~35 ~5 ~5 ~35 stone 0  
fill ~6 ~4 ~37 ~6 ~5 ~37 stone 0  
fill ~6 ~4 ~38 ~9 ~4 ~38 stone 0  
fill ~7 ~4 ~22 ~7 ~5 ~22 stone 0  
fill ~8 ~4 ~21 ~8 ~5 ~21 stone 0  
fill ~9 ~4 ~20 ~9 ~5 ~20 stone 0  
fill ~9 ~4 ~39 ~10 ~4 ~39 stone 0  
fill ~10 ~4 ~13 ~11 ~4 ~13 stone 0  
fill ~10 ~4 ~18 ~10 ~7 ~18 stone 0  
fill ~10 ~4 ~40 ~12 ~4 ~40 stone 0  
fill ~11 ~4 ~16 ~11 ~10 ~16 stone 0  
fill ~12 ~4 ~8 ~16 ~4 ~8 stone 0  
fill ~12 ~4 ~10 ~12 ~9 ~10 stone 0  
fill ~12 ~4 ~11 ~12 ~10 ~11 stone 0 
setblock ~12 ~4 ~41 stone 0  
fill ~14 ~4 ~41 ~19 ~4 ~41 stone 0  
fill ~16 ~4 ~50 ~17 ~4 ~50 stonebrick 2  
fill ~17 ~4 ~9 ~18 ~4 ~9 stone 0  
fill ~17 ~4 ~42 ~17 ~3 ~42 stone 0  
fill ~17 ~4 ~49 ~23 ~4 ~49 stonebrick 2  
fill ~17 ~4 ~51 ~17 ~5 ~51 stonebrick 0  
fill ~18 ~4 ~38 ~20 ~4 ~38 stonebrick 2  
fill ~18 ~4 ~48 ~18 ~5 ~48 stone 0  
fill ~18 ~4 ~50 ~18 ~5 ~50 stonebrick 0  
fill ~18 ~4 ~51 ~24 ~4 ~51 stonebrick 2  
fill ~19 ~4 ~46 ~19 ~0 ~46 stone 0  
fill ~19 ~4 ~50 ~23 ~4 ~50 stonebrick 2  
fill ~20 ~4 ~42 ~20 ~6 ~42 stone 0  
fill ~20 ~4 ~43 ~21 ~4 ~43 stone 0  
fill ~21 ~4 ~47 ~22 ~4 ~47 stone 0  
fill ~22 ~4 ~14 ~22 ~5 ~14 stone 0  
fill ~22 ~4 ~44 ~22 ~7 ~44 stone 0  
fill ~22 ~4 ~66 ~23 ~4 ~66 stonebrick 2  
fill ~24 ~4 ~14 ~26 ~4 ~14 stone 0  
fill ~25 ~4 ~13 ~28 ~4 ~13 stone 0  
fill ~28 ~4 ~12 ~31 ~4 ~12 stone 0  
fill ~28 ~4 ~61 ~29 ~4 ~61 stonebrick 2  
fill ~31 ~4 ~75 ~32 ~4 ~75 stonebrick 2  
fill ~32 ~4 ~11 ~40 ~4 ~11 stone 0  
fill ~38 ~4 ~61 ~38 ~4 ~62 chest 5  
fill ~39 ~4 ~10 ~49 ~4 ~10 stone 0  
fill ~39 ~4 ~63 ~39 ~4 ~64 chest 5  
fill ~39 ~4 ~67 ~40 ~4 ~67 stonebrick 2  
fill ~39 ~4 ~70 ~40 ~4 ~70 stonebrick 2  
fill ~41 ~4 ~17 ~42 ~4 ~17 stonebrick 2  
fill ~41 ~4 ~71 ~42 ~4 ~71 stonebrick 2 
setblock ~43 ~4 ~9 stone 0  
fill ~43 ~4 ~16 ~44 ~4 ~16 stonebrick 2  
fill ~43 ~4 ~69 ~44 ~4 ~69 stonebrick 2  
fill ~43 ~4 ~72 ~44 ~4 ~72 stonebrick 2  
fill ~45 ~4 ~15 ~46 ~4 ~15 stonebrick 2  
fill ~45 ~4 ~70 ~47 ~4 ~70 stonebrick 2  
fill ~45 ~4 ~73 ~46 ~4 ~73 stonebrick 2  
fill ~46 ~4 ~11 ~46 ~5 ~11 stone 0  
fill ~46 ~4 ~74 ~60 ~4 ~74 stonebrick 2  
fill ~47 ~4 ~67 ~48 ~4 ~67 stonebrick 0  
fill ~48 ~4 ~11 ~49 ~4 ~11 stone 0  
fill ~48 ~4 ~14 ~59 ~4 ~14 stonebrick 2  
fill ~48 ~4 ~71 ~58 ~4 ~71 stonebrick 2  
fill ~49 ~4 ~9 ~50 ~4 ~9 stone 0  
fill ~49 ~4 ~68 ~50 ~4 ~68 stonebrick 0  
fill ~50 ~4 ~8 ~53 ~4 ~8 stone 0  
fill ~52 ~4 ~7 ~54 ~4 ~7 stone 0  
fill ~52 ~4 ~68 ~57 ~4 ~68 stonebrick 2  
fill ~52 ~4 ~75 ~54 ~4 ~75 stonebrick 2  
fill ~52 ~4 ~84 ~54 ~4 ~84 stonebrick 2  
fill ~54 ~4 ~6 ~55 ~4 ~6 stone 0  
fill ~56 ~4 ~5 ~62 ~4 ~5 stone 0  
fill ~58 ~4 ~67 ~60 ~4 ~67 stonebrick 2  
fill ~58 ~4 ~80 ~60 ~4 ~80 stonebrick 2  
fill ~58 ~4 ~87 ~60 ~4 ~87 stonebrick 2  
fill ~59 ~4 ~70 ~61 ~4 ~70 stonebrick 2  
fill ~60 ~4 ~15 ~61 ~4 ~15 stonebrick 2  
fill ~60 ~4 ~73 ~61 ~4 ~73 stonebrick 2  
fill ~61 ~4 ~66 ~63 ~4 ~66 stonebrick 2  
fill ~62 ~4 ~16 ~63 ~4 ~16 stonebrick 2  
fill ~62 ~4 ~69 ~63 ~4 ~69 stonebrick 2  
fill ~62 ~4 ~72 ~63 ~4 ~72 stonebrick 2  
fill ~63 ~4 ~6 ~65 ~4 ~6 stone 0  
fill ~64 ~4 ~17 ~65 ~4 ~17 stonebrick 2  
fill ~64 ~4 ~68 ~65 ~4 ~68 stonebrick 2  
fill ~64 ~4 ~71 ~65 ~4 ~71 stonebrick 2  
fill ~65 ~4 ~7 ~66 ~4 ~7 stone 0  
fill ~65 ~4 ~64 ~66 ~4 ~64 stonebrick 2  
fill ~66 ~4 ~8 ~66 ~6 ~8 stone 0  
fill ~66 ~4 ~18 ~67 ~4 ~18 stonebrick 2  
fill ~66 ~4 ~67 ~67 ~4 ~67 stonebrick 2  
fill ~66 ~4 ~70 ~67 ~4 ~70 stonebrick 2  
fill ~67 ~4 ~10 ~67 ~7 ~10 stone 0  
fill ~67 ~4 ~11 ~68 ~4 ~11 stone 0  
fill ~68 ~4 ~12 ~68 ~6 ~12 stone 0  
fill ~69 ~4 ~14 ~69 ~3 ~14 stone 0  
fill ~69 ~4 ~15 ~69 ~6 ~15 stone 0  
fill ~69 ~4 ~70 ~71 ~4 ~70 stonebrick 2  
fill ~70 ~4 ~18 ~71 ~4 ~18 stone 0  
fill ~70 ~4 ~71 ~72 ~4 ~71 stonebrick 2  
fill ~71 ~4 ~72 ~73 ~4 ~72 stonebrick 2  
fill ~72 ~4 ~32 ~74 ~4 ~32 stonebrick 2  
fill ~72 ~4 ~73 ~74 ~4 ~73 stonebrick 2  
fill ~73 ~4 ~74 ~75 ~4 ~74 stonebrick 2  
fill ~74 ~4 ~75 ~75 ~4 ~75 stonebrick 2  
fill ~77 ~4 ~27 ~80 ~4 ~27 stonebrick 2  
fill ~77 ~4 ~61 ~80 ~4 ~61 stonebrick 2  
fill ~79 ~4 ~26 ~81 ~4 ~26 stonebrick 2  
fill ~79 ~4 ~62 ~81 ~4 ~62 stonebrick 2  
fill ~80 ~4 ~25 ~82 ~4 ~25 stonebrick 2  
fill ~80 ~4 ~63 ~82 ~4 ~63 stonebrick 2  
fill ~81 ~4 ~24 ~83 ~4 ~24 stonebrick 2  
fill ~81 ~4 ~64 ~83 ~4 ~64 stonebrick 2  
fill ~82 ~4 ~23 ~84 ~4 ~23 stonebrick 2  
fill ~82 ~4 ~37 ~89 ~4 ~37 stonebrick 2  
fill ~82 ~4 ~51 ~89 ~4 ~51 stonebrick 2  
fill ~82 ~4 ~65 ~84 ~4 ~65 stonebrick 2  
fill ~83 ~4 ~22 ~84 ~4 ~22 stonebrick 2  
fill ~83 ~4 ~38 ~90 ~4 ~38 stonebrick 2  
fill ~83 ~4 ~39 ~89 ~4 ~39 stonebrick 2  
fill ~83 ~4 ~49 ~89 ~4 ~49 stonebrick 2  
fill ~83 ~4 ~50 ~90 ~4 ~50 stonebrick 2  
fill ~83 ~4 ~66 ~84 ~4 ~66 stonebrick 2 
setblock ~3 ~5 ~31 stone 0  
fill ~4 ~5 ~27 ~4 ~6 ~27 stone 0 
setblock ~4 ~5 ~33 stone 0  
fill ~5 ~5 ~25 ~5 ~6 ~25 stone 0  
fill ~6 ~5 ~23 ~7 ~5 ~23 stone 0  
fill ~6 ~5 ~24 ~6 ~6 ~24 stone 0 
setblock ~6 ~5 ~36 stone 0  
fill ~7 ~5 ~38 ~9 ~5 ~38 stone 0  
fill ~8 ~5 ~22 ~8 ~6 ~22 stone 0  
fill ~9 ~5 ~21 ~9 ~6 ~21 stone 0  
fill ~10 ~5 ~19 ~11 ~5 ~19 stone 0  
fill ~10 ~5 ~20 ~10 ~12 ~20 stone 0 
setblock ~10 ~5 ~39 stone 0  
fill ~11 ~5 ~13 ~12 ~5 ~13 stone 0  
fill ~11 ~5 ~17 ~11 ~11 ~17 stone 0  
fill ~11 ~5 ~18 ~11 ~12 ~18 stone 0 
setblock ~11 ~5 ~40 stone 0  
fill ~12 ~5 ~8 ~16 ~5 ~8 stone 0  
fill ~12 ~5 ~12 ~12 ~11 ~12 stone 0  
fill ~12 ~5 ~39 ~12 ~6 ~39 stone 0  
fill ~13 ~5 ~40 ~14 ~5 ~40 stone 0  
fill ~14 ~5 ~41 ~20 ~5 ~41 stone 0  
fill ~16 ~5 ~50 ~17 ~5 ~50 stonebrick 2  
fill ~17 ~5 ~9 ~18 ~5 ~9 stone 0  
fill ~17 ~5 ~10 ~17 ~7 ~10 stone 0  
fill ~17 ~5 ~49 ~23 ~5 ~49 stonebrick 2  
fill ~18 ~5 ~38 ~20 ~5 ~38 stonebrick 2  
fill ~18 ~5 ~51 ~24 ~5 ~51 stonebrick 2  
fill ~19 ~5 ~50 ~23 ~5 ~50 stonebrick 2  
fill ~20 ~5 ~12 ~20 ~6 ~12 stone 0  
fill ~20 ~5 ~13 ~21 ~5 ~13 stone 0  
fill ~21 ~5 ~14 ~21 ~9 ~14 stone 0  
fill ~21 ~5 ~42 ~21 ~11 ~42 stone 0  
fill ~21 ~5 ~43 ~21 ~7 ~43 stone 0  
fill ~21 ~5 ~48 ~22 ~5 ~48 stone 0 
setblock ~22 ~5 ~47 stone 0  
fill ~22 ~5 ~66 ~23 ~5 ~66 stonebrick 2  
fill ~23 ~5 ~15 ~25 ~5 ~15 stone 0  
fill ~26 ~5 ~14 ~27 ~5 ~14 stone 0  
fill ~28 ~5 ~13 ~30 ~5 ~13 stone 0  
fill ~28 ~5 ~61 ~29 ~5 ~61 stonebrick 2  
fill ~31 ~5 ~12 ~38 ~5 ~12 stone 0  
fill ~31 ~5 ~75 ~32 ~5 ~75 stonebrick 2  
fill ~36 ~5 ~11 ~41 ~5 ~11 stone 0  
fill ~39 ~5 ~67 ~40 ~5 ~67 stonebrick 2  
fill ~39 ~5 ~70 ~40 ~5 ~70 stonebrick 2  
fill ~41 ~5 ~17 ~42 ~5 ~17 stonebrick 2  
fill ~41 ~5 ~71 ~42 ~5 ~71 stonebrick 2  
fill ~42 ~5 ~10 ~45 ~5 ~10 stone 0 
setblock ~42 ~5 ~65 stonebrick 0  
fill ~43 ~5 ~16 ~44 ~5 ~16 stonebrick 2  
fill ~43 ~5 ~66 ~45 ~5 ~66 stonebrick 0  
fill ~43 ~5 ~69 ~44 ~5 ~69 stonebrick 2  
fill ~43 ~5 ~72 ~44 ~5 ~72 stonebrick 2  
fill ~45 ~5 ~15 ~46 ~5 ~15 stonebrick 2  
fill ~45 ~5 ~70 ~47 ~5 ~70 stonebrick 2  
fill ~45 ~5 ~73 ~46 ~5 ~73 stonebrick 2  
fill ~46 ~5 ~67 ~48 ~5 ~67 stonebrick 0  
fill ~46 ~5 ~74 ~60 ~5 ~74 stonebrick 2  
fill ~47 ~5 ~12 ~47 ~9 ~12 stone 0  
fill ~48 ~5 ~11 ~49 ~5 ~11 stone 0  
fill ~48 ~5 ~14 ~59 ~5 ~14 stonebrick 2  
fill ~48 ~5 ~71 ~58 ~5 ~71 stonebrick 2  
fill ~49 ~5 ~10 ~50 ~5 ~10 stone 0  
fill ~49 ~5 ~68 ~50 ~5 ~68 stonebrick 0  
fill ~51 ~5 ~9 ~53 ~5 ~9 stone 0  
fill ~52 ~5 ~8 ~53 ~5 ~8 stone 0  
fill ~52 ~5 ~68 ~57 ~5 ~68 stonebrick 2  
fill ~52 ~5 ~75 ~54 ~5 ~75 stonebrick 2  
fill ~52 ~5 ~84 ~54 ~5 ~84 stonebrick 2  
fill ~54 ~5 ~7 ~57 ~5 ~7 stone 0  
fill ~56 ~5 ~6 ~57 ~5 ~6 stone 0  
fill ~57 ~5 ~5 ~60 ~5 ~5 stone 0  
fill ~58 ~5 ~67 ~60 ~5 ~67 stonebrick 2  
fill ~58 ~5 ~80 ~60 ~5 ~80 stonebrick 2  
fill ~58 ~5 ~87 ~60 ~5 ~87 stonebrick 2  
fill ~59 ~5 ~70 ~61 ~5 ~70 stonebrick 2  
fill ~60 ~5 ~15 ~61 ~5 ~15 stonebrick 2  
fill ~60 ~5 ~73 ~61 ~5 ~73 stonebrick 2  
fill ~61 ~5 ~6 ~63 ~5 ~6 stone 0  
fill ~61 ~5 ~66 ~63 ~5 ~66 stonebrick 2  
fill ~62 ~5 ~16 ~63 ~5 ~16 stonebrick 2  
fill ~62 ~5 ~69 ~63 ~5 ~69 stonebrick 2  
fill ~62 ~5 ~72 ~63 ~5 ~72 stonebrick 2  
fill ~64 ~5 ~7 ~65 ~5 ~7 stone 0  
fill ~64 ~5 ~17 ~65 ~5 ~17 stonebrick 2  
fill ~64 ~5 ~68 ~65 ~5 ~68 stonebrick 2  
fill ~64 ~5 ~71 ~65 ~5 ~71 stonebrick 2  
fill ~65 ~5 ~8 ~65 ~6 ~8 stone 0  
fill ~65 ~5 ~64 ~66 ~5 ~64 stonebrick 2  
fill ~66 ~5 ~9 ~66 ~7 ~9 stone 0  
fill ~66 ~5 ~18 ~67 ~5 ~18 stonebrick 2  
fill ~66 ~5 ~67 ~67 ~5 ~67 stonebrick 2  
fill ~66 ~5 ~70 ~67 ~5 ~70 stonebrick 2  
fill ~67 ~5 ~11 ~67 ~9 ~11 stone 0  
fill ~68 ~5 ~13 ~68 ~7 ~13 stone 0  
fill ~68 ~5 ~14 ~68 ~8 ~14 stone 0  
fill ~68 ~5 ~15 ~68 ~9 ~15 stone 0  
fill ~69 ~5 ~16 ~69 ~7 ~16 stone 0  
fill ~69 ~5 ~70 ~71 ~5 ~70 stonebrick 2  
fill ~70 ~5 ~18 ~70 ~6 ~18 stone 0  
fill ~70 ~5 ~71 ~72 ~5 ~71 stonebrick 2  
fill ~71 ~5 ~72 ~73 ~5 ~72 stonebrick 2  
fill ~72 ~5 ~20 ~72 ~8 ~20 stone 0  
fill ~72 ~5 ~32 ~74 ~5 ~32 stonebrick 2  
fill ~72 ~5 ~73 ~74 ~5 ~73 stonebrick 2  
fill ~73 ~5 ~74 ~75 ~5 ~74 stonebrick 2  
fill ~74 ~5 ~22 ~74 ~10 ~22 stone 0  
fill ~74 ~5 ~75 ~75 ~5 ~75 stonebrick 2  
fill ~77 ~5 ~27 ~80 ~5 ~27 stonebrick 2  
fill ~77 ~5 ~61 ~80 ~5 ~61 stonebrick 2  
fill ~79 ~5 ~26 ~81 ~5 ~26 stonebrick 2  
fill ~79 ~5 ~62 ~81 ~5 ~62 stonebrick 2  
fill ~80 ~5 ~25 ~82 ~5 ~25 stonebrick 2  
fill ~80 ~5 ~63 ~82 ~5 ~63 stonebrick 2  
fill ~81 ~5 ~24 ~83 ~5 ~24 stonebrick 2  
fill ~81 ~5 ~64 ~83 ~5 ~64 stonebrick 2  
fill ~82 ~5 ~23 ~84 ~5 ~23 stonebrick 2  
fill ~82 ~5 ~37 ~89 ~5 ~37 stonebrick 2  
fill ~82 ~5 ~51 ~89 ~5 ~51 stonebrick 2  
fill ~82 ~5 ~65 ~84 ~5 ~65 stonebrick 2  
fill ~83 ~5 ~22 ~84 ~5 ~22 stonebrick 2  
fill ~83 ~5 ~38 ~90 ~5 ~38 stonebrick 2  
fill ~83 ~5 ~39 ~89 ~5 ~39 stonebrick 2  
fill ~83 ~5 ~49 ~89 ~5 ~49 stonebrick 2  
fill ~83 ~5 ~50 ~90 ~5 ~50 stonebrick 2  
fill ~83 ~5 ~66 ~84 ~5 ~66 stonebrick 2  
fill ~4 ~6 ~28 ~4 ~9 ~28 stone 0  
fill ~4 ~6 ~29 ~4 ~7 ~29 stone 0  
fill ~4 ~6 ~30 ~4 ~7 ~30 stone 0  
fill ~4 ~6 ~31 ~4 ~6 ~32 stone 0  
fill ~5 ~6 ~26 ~5 ~7 ~26 stone 0  
fill ~5 ~6 ~32 ~5 ~7 ~32 stone 0  
fill ~5 ~6 ~33 ~5 ~6 ~34 stone 0  
fill ~6 ~6 ~25 ~6 ~12 ~25 stone 0  
fill ~6 ~6 ~34 ~6 ~7 ~34 stone 0  
fill ~6 ~6 ~35 ~7 ~6 ~35 stone 0  
fill ~7 ~6 ~23 ~8 ~6 ~23 stone 0  
fill ~7 ~6 ~24 ~7 ~8 ~24 stone 0  
fill ~7 ~6 ~36 ~7 ~6 ~37 stone 0  
fill ~8 ~6 ~37 ~10 ~6 ~37 stone 0  
fill ~9 ~6 ~22 ~9 ~9 ~22 stone 0  
fill ~10 ~6 ~19 ~10 ~9 ~19 stone 0  
fill ~10 ~6 ~38 ~11 ~6 ~38 stone 0  
fill ~11 ~6 ~13 ~12 ~6 ~13 stone 0 
setblock ~11 ~6 ~39 stone 0  
fill ~12 ~6 ~8 ~15 ~6 ~8 stone 0  
fill ~12 ~6 ~14 ~12 ~14 ~14 stone 0  
fill ~13 ~6 ~40 ~14 ~6 ~40 stone 0  
fill ~15 ~6 ~9 ~16 ~6 ~9 stone 0  
fill ~15 ~6 ~41 ~20 ~6 ~41 stone 0  
fill ~16 ~6 ~38 ~23 ~6 ~38 stonebrick 2  
fill ~16 ~6 ~50 ~23 ~6 ~50 stonebrick 2  
fill ~17 ~6 ~37 ~24 ~6 ~37 stonebrick 2  
fill ~17 ~6 ~39 ~23 ~6 ~39 stonebrick 2  
fill ~17 ~6 ~49 ~23 ~6 ~49 stonebrick 2  
fill ~17 ~6 ~51 ~24 ~6 ~51 stonebrick 2  
fill ~18 ~6 ~10 ~18 ~6 ~11 stone 0  
fill ~19 ~6 ~11 ~19 ~6 ~12 stone 0  
fill ~19 ~6 ~48 ~22 ~6 ~48 stone 0  
fill ~20 ~6 ~13 ~20 ~8 ~13 stone 0  
fill ~22 ~6 ~15 ~27 ~6 ~15 stone 0  
fill ~22 ~6 ~43 ~22 ~10 ~43 stone 0  
fill ~22 ~6 ~66 ~23 ~6 ~66 stonebrick 2  
fill ~27 ~6 ~14 ~30 ~6 ~14 stone 0  
fill ~28 ~6 ~61 ~29 ~6 ~61 stonebrick 2  
fill ~30 ~6 ~13 ~36 ~6 ~13 stone 0  
fill ~31 ~6 ~75 ~32 ~6 ~75 stonebrick 2  
fill ~37 ~6 ~12 ~38 ~6 ~12 stone 0  
fill ~38 ~6 ~62 ~38 ~29 ~62 stonebrick 2  
fill ~39 ~6 ~63 ~39 ~29 ~63 stonebrick 2  
fill ~39 ~6 ~67 ~40 ~6 ~67 stonebrick 2  
fill ~39 ~6 ~70 ~40 ~6 ~70 stonebrick 2  
fill ~40 ~6 ~11 ~41 ~6 ~11 stone 0  
fill ~40 ~6 ~64 ~41 ~6 ~64 stonebrick 2  
fill ~41 ~6 ~17 ~42 ~6 ~17 stonebrick 2  
fill ~41 ~6 ~71 ~42 ~6 ~71 stonebrick 2  
fill ~42 ~6 ~10 ~44 ~6 ~10 stone 0  
fill ~42 ~6 ~65 ~42 ~29 ~65 stonebrick 2  
fill ~43 ~6 ~16 ~44 ~6 ~16 stonebrick 2  
fill ~43 ~6 ~66 ~45 ~6 ~66 stonebrick 2  
fill ~43 ~6 ~69 ~44 ~6 ~69 stonebrick 2  
fill ~43 ~6 ~72 ~44 ~6 ~72 stonebrick 2  
fill ~45 ~6 ~11 ~45 ~6 ~12 stone 0  
fill ~45 ~6 ~15 ~46 ~6 ~15 stonebrick 2  
fill ~45 ~6 ~70 ~47 ~6 ~70 stonebrick 2  
fill ~45 ~6 ~73 ~46 ~6 ~73 stonebrick 2  
fill ~46 ~6 ~12 ~46 ~10 ~12 stone 0  
fill ~46 ~6 ~67 ~48 ~6 ~67 stonebrick 2  
fill ~46 ~6 ~74 ~60 ~6 ~74 stonebrick 2  
fill ~48 ~6 ~12 ~48 ~8 ~12 stone 0  
fill ~48 ~6 ~14 ~59 ~6 ~14 stonebrick 2  
fill ~48 ~6 ~71 ~58 ~6 ~71 stonebrick 2 
setblock ~49 ~6 ~11 stone 0  
fill ~49 ~6 ~68 ~57 ~6 ~68 stonebrick 2  
fill ~50 ~6 ~10 ~52 ~6 ~10 stone 0  
fill ~52 ~6 ~9 ~54 ~6 ~9 stone 0  
fill ~52 ~6 ~75 ~54 ~6 ~75 stonebrick 2  
fill ~52 ~6 ~84 ~54 ~6 ~84 stonebrick 2  
fill ~54 ~6 ~8 ~55 ~6 ~8 stone 0  
fill ~55 ~6 ~7 ~56 ~6 ~7 stone 0  
fill ~56 ~6 ~6 ~61 ~6 ~6 stone 0  
fill ~58 ~6 ~67 ~60 ~6 ~67 stonebrick 2  
fill ~58 ~6 ~80 ~60 ~6 ~80 stonebrick 2  
fill ~58 ~6 ~87 ~60 ~6 ~87 stonebrick 2  
fill ~59 ~6 ~70 ~61 ~6 ~70 stonebrick 2  
fill ~60 ~6 ~15 ~61 ~6 ~15 stonebrick 2  
fill ~60 ~6 ~73 ~61 ~6 ~73 stonebrick 2  
fill ~61 ~6 ~7 ~63 ~6 ~7 stone 0  
fill ~61 ~6 ~66 ~63 ~6 ~66 stonebrick 2  
fill ~62 ~6 ~16 ~63 ~6 ~16 stonebrick 2  
fill ~62 ~6 ~69 ~63 ~6 ~69 stonebrick 2  
fill ~62 ~6 ~72 ~63 ~6 ~72 stonebrick 2  
fill ~63 ~6 ~8 ~66 ~6 ~8 stone 0  
fill ~64 ~6 ~17 ~65 ~6 ~17 stonebrick 2  
fill ~64 ~6 ~68 ~65 ~6 ~68 stonebrick 2  
fill ~64 ~6 ~71 ~65 ~6 ~71 stonebrick 2  
fill ~65 ~6 ~64 ~66 ~6 ~64 stonebrick 2  
fill ~66 ~6 ~10 ~66 ~8 ~10 stone 0  
fill ~66 ~6 ~18 ~67 ~6 ~18 stonebrick 2  
fill ~66 ~6 ~67 ~67 ~6 ~67 stonebrick 2  
fill ~66 ~6 ~70 ~67 ~6 ~70 stonebrick 2  
fill ~69 ~6 ~70 ~71 ~6 ~70 stonebrick 2  
fill ~70 ~6 ~71 ~72 ~6 ~71 stonebrick 2  
fill ~71 ~6 ~72 ~73 ~6 ~72 stonebrick 2  
fill ~72 ~6 ~32 ~74 ~6 ~32 stonebrick 2  
fill ~72 ~6 ~73 ~74 ~6 ~73 stonebrick 2  
fill ~73 ~6 ~21 ~73 ~12 ~21 stone 0  
fill ~73 ~6 ~74 ~75 ~6 ~74 stonebrick 2  
fill ~74 ~6 ~23 ~74 ~12 ~23 stone 0  
fill ~74 ~6 ~75 ~75 ~6 ~75 stonebrick 2  
fill ~77 ~6 ~27 ~80 ~6 ~27 stonebrick 2  
fill ~77 ~6 ~61 ~80 ~6 ~61 stonebrick 2  
fill ~79 ~6 ~26 ~81 ~6 ~26 stonebrick 2  
fill ~79 ~6 ~62 ~81 ~6 ~62 stonebrick 2  
fill ~80 ~6 ~25 ~82 ~6 ~25 stonebrick 2  
fill ~80 ~6 ~63 ~82 ~6 ~63 stonebrick 2  
fill ~81 ~6 ~24 ~83 ~6 ~24 stonebrick 2  
fill ~81 ~6 ~64 ~83 ~6 ~64 stonebrick 2  
fill ~82 ~6 ~23 ~84 ~6 ~23 stonebrick 2  
fill ~82 ~6 ~37 ~89 ~6 ~37 stonebrick 2  
fill ~82 ~6 ~51 ~89 ~6 ~51 stonebrick 2  
fill ~82 ~6 ~65 ~84 ~6 ~65 stonebrick 2  
fill ~83 ~6 ~22 ~84 ~6 ~22 stonebrick 2  
fill ~83 ~6 ~38 ~90 ~6 ~38 stonebrick 2  
fill ~83 ~6 ~39 ~89 ~6 ~39 stonebrick 2  
fill ~83 ~6 ~49 ~89 ~6 ~49 stonebrick 2  
fill ~83 ~6 ~50 ~83 ~30 ~50 stonebrick 2  
fill ~83 ~6 ~66 ~84 ~6 ~66 stonebrick 2  
fill ~85 ~6 ~50 ~85 ~9 ~50 stonebrick 2  
fill ~87 ~6 ~50 ~90 ~6 ~50 stonebrick 2  
fill ~5 ~7 ~27 ~5 ~11 ~27 stone 0  
fill ~5 ~7 ~28 ~5 ~12 ~28 stone 0 
setblock ~5 ~7 ~31 stone 0  
fill ~6 ~7 ~26 ~6 ~14 ~26 stone 0  
fill ~6 ~7 ~32 ~6 ~8 ~32 stone 0  
fill ~6 ~7 ~33 ~6 ~7 ~32 stone 0  
fill ~7 ~7 ~25 ~7 ~14 ~25 stone 0  
fill ~7 ~7 ~34 ~8 ~7 ~34 stone 0  
fill ~7 ~7 ~35 ~8 ~7 ~35 stone 0  
fill ~8 ~7 ~23 ~9 ~7 ~23 stone 0  
fill ~8 ~7 ~24 ~8 ~15 ~24 stone 0  
fill ~8 ~7 ~36 ~10 ~7 ~36 stone 0  
fill ~10 ~7 ~21 ~11 ~7 ~21 stone 0  
fill ~10 ~7 ~22 ~10 ~18 ~22 stone 0  
fill ~10 ~7 ~37 ~12 ~7 ~37 stone 0  
fill ~11 ~7 ~13 ~12 ~7 ~13 stone 0  
fill ~11 ~7 ~19 ~11 ~15 ~19 stone 0  
fill ~11 ~7 ~20 ~11 ~20 ~20 stone 0  
fill ~12 ~7 ~8 ~14 ~7 ~8 stone 0  
fill ~12 ~7 ~15 ~12 ~15 ~15 stone 0  
fill ~12 ~7 ~16 ~12 ~17 ~16 stone 0  
fill ~12 ~7 ~38 ~13 ~7 ~38 stone 0  
fill ~13 ~7 ~39 ~15 ~7 ~39 stone 0  
fill ~14 ~7 ~40 ~16 ~7 ~40 stone 0  
fill ~15 ~7 ~9 ~16 ~7 ~9 stone 0  
fill ~16 ~7 ~10 ~16 ~8 ~10 stone 0  
fill ~16 ~7 ~38 ~23 ~7 ~38 stonebrick 2  
fill ~16 ~7 ~41 ~20 ~7 ~41 stone 0  
fill ~16 ~7 ~50 ~23 ~7 ~50 stonebrick 2  
fill ~17 ~7 ~11 ~18 ~7 ~11 stone 0  
fill ~17 ~7 ~37 ~24 ~7 ~37 stonebrick 2  
fill ~17 ~7 ~39 ~23 ~7 ~39 stonebrick 2  
fill ~17 ~7 ~49 ~23 ~7 ~49 stonebrick 2  
fill ~17 ~7 ~51 ~24 ~7 ~51 stonebrick 2  
fill ~18 ~7 ~12 ~19 ~7 ~12 stone 0  
fill ~18 ~7 ~40 ~18 ~14 ~40 stone 0  
fill ~19 ~7 ~13 ~19 ~9 ~13 stone 0  
fill ~22 ~7 ~15 ~23 ~7 ~15 stone 0 
setblock ~22 ~7 ~48 stone 0  
fill ~22 ~7 ~66 ~23 ~7 ~66 stonebrick 2  
fill ~23 ~7 ~65 ~23 ~9 ~65 stonebrick 2  
fill ~24 ~7 ~16 ~28 ~7 ~16 stone 0  
fill ~24 ~7 ~64 ~24 ~10 ~64 stonebrick 2  
fill ~26 ~7 ~15 ~28 ~7 ~15 stone 0  
fill ~28 ~7 ~61 ~29 ~7 ~61 stonebrick 2  
fill ~29 ~7 ~14 ~36 ~7 ~14 stone 0  
fill ~31 ~7 ~75 ~32 ~7 ~75 stonebrick 2  
fill ~32 ~7 ~74 ~32 ~9 ~74 stonebrick 2  
fill ~33 ~7 ~73 ~33 ~10 ~73 stonebrick 2  
fill ~34 ~7 ~13 ~39 ~7 ~13 stone 0  
fill ~39 ~7 ~12 ~41 ~7 ~12 stone 0  
fill ~39 ~7 ~67 ~40 ~7 ~67 stonebrick 2  
fill ~39 ~7 ~70 ~40 ~7 ~70 stonebrick 2  
fill ~40 ~7 ~64 ~41 ~7 ~64 stonebrick 2  
fill ~41 ~7 ~11 ~44 ~7 ~11 stone 0  
fill ~41 ~7 ~17 ~42 ~7 ~17 stonebrick 2  
fill ~41 ~7 ~71 ~42 ~7 ~71 stonebrick 2  
fill ~43 ~7 ~16 ~44 ~7 ~16 stonebrick 2  
fill ~43 ~7 ~66 ~45 ~7 ~66 stonebrick 2  
fill ~43 ~7 ~69 ~44 ~7 ~69 stonebrick 2  
fill ~43 ~7 ~72 ~44 ~7 ~72 stonebrick 2 
setblock ~44 ~7 ~10 stone 0  
fill ~45 ~7 ~12 ~45 ~11 ~12 stone 0  
fill ~45 ~7 ~15 ~46 ~7 ~15 stonebrick 2  
fill ~45 ~7 ~70 ~47 ~7 ~70 stonebrick 2  
fill ~45 ~7 ~73 ~46 ~7 ~73 stonebrick 2  
fill ~46 ~7 ~67 ~48 ~7 ~67 stonebrick 2  
fill ~46 ~7 ~74 ~60 ~7 ~74 stonebrick 2  
fill ~47 ~7 ~13 ~49 ~7 ~13 stone 0  
fill ~48 ~7 ~14 ~59 ~7 ~14 stonebrick 2  
fill ~48 ~7 ~71 ~58 ~7 ~71 stonebrick 2  
fill ~49 ~7 ~12 ~50 ~7 ~12 stone 0  
fill ~49 ~7 ~68 ~57 ~7 ~68 stonebrick 2  
fill ~50 ~7 ~11 ~52 ~7 ~11 stone 0  
fill ~52 ~7 ~10 ~53 ~7 ~10 stone 0  
fill ~52 ~7 ~75 ~54 ~7 ~75 stonebrick 2  
fill ~52 ~7 ~84 ~54 ~7 ~84 stonebrick 2  
fill ~53 ~7 ~9 ~54 ~7 ~9 stone 0  
fill ~55 ~7 ~8 ~55 ~8 ~8 stone 0  
fill ~56 ~7 ~7 ~57 ~7 ~7 stone 0  
fill ~57 ~7 ~6 ~59 ~7 ~6 stone 0  
fill ~58 ~7 ~67 ~60 ~7 ~67 stonebrick 2  
fill ~58 ~7 ~80 ~60 ~7 ~80 stonebrick 2  
fill ~58 ~7 ~87 ~60 ~7 ~87 stonebrick 2  
fill ~59 ~7 ~70 ~61 ~7 ~70 stonebrick 2  
fill ~60 ~7 ~7 ~62 ~7 ~7 stone 0  
fill ~60 ~7 ~15 ~61 ~7 ~15 stonebrick 2  
fill ~60 ~7 ~73 ~61 ~7 ~73 stonebrick 2  
fill ~61 ~7 ~66 ~63 ~7 ~66 stonebrick 2  
fill ~62 ~7 ~16 ~63 ~7 ~16 stonebrick 2  
fill ~62 ~7 ~69 ~63 ~7 ~69 stonebrick 2  
fill ~62 ~7 ~72 ~63 ~7 ~72 stonebrick 2  
fill ~63 ~7 ~8 ~63 ~6 ~8 stone 0  
fill ~64 ~7 ~9 ~66 ~7 ~9 stone 0  
fill ~64 ~7 ~17 ~65 ~7 ~17 stonebrick 2  
fill ~64 ~7 ~68 ~65 ~7 ~68 stonebrick 2  
fill ~64 ~7 ~71 ~65 ~7 ~71 stonebrick 2  
fill ~65 ~7 ~64 ~66 ~7 ~64 stonebrick 2  
fill ~66 ~7 ~18 ~67 ~7 ~18 stonebrick 2  
fill ~66 ~7 ~67 ~67 ~7 ~67 stonebrick 2  
fill ~66 ~7 ~70 ~67 ~7 ~70 stonebrick 2  
fill ~67 ~7 ~12 ~67 ~13 ~12 stone 0  
fill ~69 ~7 ~17 ~69 ~8 ~17 stone 0  
fill ~69 ~7 ~18 ~69 ~9 ~18 stone 0  
fill ~69 ~7 ~70 ~71 ~7 ~70 stonebrick 2  
fill ~70 ~7 ~71 ~72 ~7 ~71 stonebrick 2  
fill ~71 ~7 ~72 ~73 ~7 ~72 stonebrick 2  
fill ~72 ~7 ~21 ~72 ~10 ~21 stone 0  
fill ~72 ~7 ~32 ~74 ~7 ~32 stonebrick 2  
fill ~72 ~7 ~73 ~74 ~7 ~73 stonebrick 2  
fill ~73 ~7 ~74 ~75 ~7 ~74 stonebrick 2  
fill ~74 ~7 ~75 ~75 ~7 ~75 stonebrick 2  
fill ~77 ~7 ~27 ~80 ~7 ~27 stonebrick 2  
fill ~77 ~7 ~61 ~80 ~7 ~61 stonebrick 2  
fill ~79 ~7 ~26 ~81 ~7 ~26 stonebrick 2  
fill ~79 ~7 ~62 ~81 ~7 ~62 stonebrick 2  
fill ~80 ~7 ~25 ~82 ~7 ~25 stonebrick 2  
fill ~80 ~7 ~63 ~82 ~7 ~63 stonebrick 2  
fill ~81 ~7 ~24 ~83 ~7 ~24 stonebrick 2  
fill ~81 ~7 ~64 ~83 ~7 ~64 stonebrick 2  
fill ~82 ~7 ~23 ~84 ~7 ~23 stonebrick 2  
fill ~82 ~7 ~37 ~89 ~7 ~37 stonebrick 2  
fill ~82 ~7 ~51 ~89 ~7 ~51 stonebrick 2  
fill ~82 ~7 ~65 ~84 ~7 ~65 stonebrick 2  
fill ~83 ~7 ~22 ~84 ~7 ~22 stonebrick 2  
fill ~83 ~7 ~38 ~90 ~7 ~38 stonebrick 2  
fill ~83 ~7 ~39 ~89 ~7 ~39 stonebrick 2  
fill ~83 ~7 ~49 ~89 ~7 ~49 stonebrick 2  
fill ~83 ~7 ~66 ~84 ~7 ~66 stonebrick 2  
fill ~84 ~7 ~50 ~84 ~9 ~50 stonebrick 2  
fill ~86 ~7 ~50 ~90 ~7 ~50 stonebrick 2  
fill ~5 ~8 ~29 ~6 ~8 ~29 stone 0  
fill ~5 ~8 ~30 ~6 ~8 ~30 stone 0  
fill ~6 ~8 ~31 ~7 ~8 ~31 stone 0  
fill ~7 ~8 ~32 ~7 ~10 ~32 stone 0  
fill ~7 ~8 ~33 ~8 ~8 ~33 stone 0  
fill ~8 ~8 ~34 ~8 ~10 ~34 stone 0  
fill ~8 ~8 ~35 ~8 ~9 ~35 stone 0  
fill ~9 ~8 ~23 ~9 ~17 ~23 stone 0  
fill ~9 ~8 ~36 ~10 ~8 ~36 stone 0  
fill ~10 ~8 ~21 ~11 ~8 ~21 stone 0  
fill ~11 ~8 ~13 ~12 ~8 ~13 stone 0  
fill ~11 ~8 ~37 ~12 ~8 ~37 stone 0  
fill ~12 ~8 ~38 ~13 ~8 ~38 stone 0 
setblock ~13 ~8 ~9 stone 0  
fill ~13 ~8 ~39 ~14 ~8 ~39 stone 0 
setblock ~14 ~8 ~8 stone 0  
fill ~15 ~8 ~9 ~15 ~6 ~9 stone 0  
fill ~15 ~8 ~40 ~19 ~8 ~40 stone 0  
fill ~16 ~8 ~38 ~23 ~8 ~38 stonebrick 2  
fill ~16 ~8 ~41 ~17 ~8 ~41 stone 0  
fill ~17 ~8 ~11 ~17 ~7 ~11 stone 0  
fill ~17 ~8 ~37 ~24 ~8 ~37 stonebrick 2  
fill ~17 ~8 ~39 ~23 ~8 ~39 stonebrick 2  
fill ~17 ~8 ~49 ~23 ~8 ~49 stonebrick 2  
fill ~17 ~8 ~50 ~17 ~9 ~50 stonebrick 2  
fill ~17 ~8 ~51 ~24 ~8 ~51 stonebrick 2  
fill ~18 ~8 ~12 ~18 ~7 ~12 stone 0  
fill ~18 ~8 ~50 ~18 ~28 ~50 cobblestone_wall 0  
fill ~19 ~8 ~50 ~23 ~8 ~50 stonebrick 2  
fill ~20 ~8 ~41 ~21 ~8 ~41 stone 0  
fill ~22 ~8 ~15 ~23 ~8 ~15 stone 0  
fill ~23 ~8 ~16 ~28 ~8 ~16 stone 0 
setblock ~23 ~8 ~66 stonebrick 2  
fill ~28 ~8 ~15 ~34 ~8 ~15 stone 0  
fill ~28 ~8 ~61 ~29 ~8 ~61 stonebrick 2 
setblock ~32 ~8 ~75 stonebrick 2  
fill ~35 ~8 ~14 ~37 ~8 ~14 stone 0  
fill ~38 ~8 ~13 ~39 ~8 ~13 stone 0  
fill ~39 ~8 ~67 ~40 ~8 ~67 stonebrick 2  
fill ~39 ~8 ~70 ~40 ~8 ~70 stonebrick 2  
fill ~40 ~8 ~12 ~41 ~8 ~12 stone 0  
fill ~40 ~8 ~64 ~41 ~8 ~64 stonebrick 2  
fill ~41 ~8 ~17 ~42 ~8 ~17 stonebrick 2  
fill ~41 ~8 ~71 ~42 ~8 ~71 stonebrick 2  
fill ~42 ~8 ~11 ~44 ~8 ~11 stone 0  
fill ~43 ~8 ~16 ~44 ~8 ~16 stonebrick 2  
fill ~43 ~8 ~66 ~45 ~8 ~66 stonebrick 2  
fill ~43 ~8 ~69 ~44 ~8 ~69 stonebrick 2  
fill ~43 ~8 ~72 ~44 ~8 ~72 stonebrick 2  
fill ~45 ~8 ~15 ~46 ~8 ~15 stonebrick 2  
fill ~45 ~8 ~70 ~47 ~8 ~70 stonebrick 2  
fill ~45 ~8 ~73 ~46 ~8 ~73 stonebrick 2  
fill ~46 ~8 ~67 ~48 ~8 ~67 stonebrick 2  
fill ~46 ~8 ~74 ~60 ~8 ~74 stonebrick 2  
fill ~47 ~8 ~13 ~49 ~8 ~13 stone 0 
setblock ~47 ~8 ~79 grass 0  
fill ~47 ~8 ~80 ~47 ~9 ~80 stonebrick 2  
fill ~48 ~8 ~14 ~59 ~8 ~14 stonebrick 2  
fill ~48 ~8 ~71 ~58 ~8 ~71 stonebrick 2  
fill ~49 ~8 ~12 ~50 ~8 ~12 stone 0  
fill ~49 ~8 ~68 ~57 ~8 ~68 stonebrick 2  
fill ~51 ~8 ~11 ~52 ~8 ~11 stone 0  
fill ~52 ~8 ~10 ~53 ~8 ~10 stone 0  
fill ~52 ~8 ~75 ~54 ~8 ~75 stonebrick 2  
fill ~52 ~8 ~84 ~54 ~8 ~84 stonebrick 2  
fill ~54 ~8 ~9 ~55 ~8 ~9 stone 0  
fill ~56 ~8 ~8 ~57 ~8 ~8 stone 0  
fill ~57 ~8 ~7 ~59 ~8 ~7 stone 0  
fill ~58 ~8 ~67 ~60 ~8 ~67 stonebrick 2  
fill ~58 ~8 ~80 ~60 ~8 ~80 stonebrick 2  
fill ~58 ~8 ~87 ~60 ~8 ~87 stonebrick 2  
fill ~59 ~8 ~70 ~61 ~8 ~70 stonebrick 2  
fill ~59 ~8 ~75 ~59 ~16 ~75 stonebrick 2  
fill ~59 ~8 ~76 ~59 ~15 ~76 stonebrick 2  
fill ~59 ~8 ~77 ~59 ~12 ~77 stonebrick 2  
fill ~59 ~8 ~78 ~59 ~11 ~78 stonebrick 2  
fill ~59 ~8 ~79 ~59 ~28 ~79 cobblestone_wall 0  
fill ~60 ~8 ~8 ~62 ~8 ~8 stone 0  
fill ~60 ~8 ~15 ~61 ~8 ~15 stonebrick 2  
fill ~60 ~8 ~73 ~61 ~8 ~73 stonebrick 2  
fill ~61 ~8 ~66 ~63 ~8 ~66 stonebrick 2  
fill ~62 ~8 ~9 ~65 ~8 ~9 stone 0  
fill ~62 ~8 ~16 ~63 ~8 ~16 stonebrick 2  
fill ~62 ~8 ~69 ~63 ~8 ~69 stonebrick 2  
fill ~62 ~8 ~72 ~63 ~8 ~72 stonebrick 2  
fill ~64 ~8 ~10 ~66 ~8 ~10 stone 0  
fill ~64 ~8 ~17 ~65 ~8 ~17 stonebrick 2  
fill ~64 ~8 ~68 ~65 ~8 ~68 stonebrick 2  
fill ~64 ~8 ~71 ~65 ~8 ~71 stonebrick 2  
fill ~65 ~8 ~64 ~66 ~8 ~64 stonebrick 2  
fill ~66 ~8 ~11 ~66 ~11 ~11 stone 0  
fill ~66 ~8 ~18 ~67 ~8 ~18 stonebrick 2  
fill ~66 ~8 ~67 ~67 ~8 ~67 stonebrick 2  
fill ~66 ~8 ~70 ~67 ~8 ~70 stonebrick 2  
fill ~67 ~8 ~13 ~67 ~14 ~13 stone 0  
fill ~68 ~8 ~16 ~68 ~11 ~16 stone 0  
fill ~68 ~8 ~17 ~68 ~12 ~17 stone 0  
fill ~69 ~8 ~70 ~71 ~8 ~70 stonebrick 2  
fill ~70 ~8 ~71 ~72 ~8 ~71 stonebrick 2  
fill ~71 ~8 ~72 ~73 ~8 ~72 stonebrick 2  
fill ~72 ~8 ~32 ~74 ~8 ~32 stonebrick 2  
fill ~72 ~8 ~73 ~74 ~8 ~73 stonebrick 2  
fill ~73 ~8 ~74 ~75 ~8 ~74 stonebrick 2  
fill ~74 ~8 ~75 ~74 ~1 ~75 stonebrick 2  
fill ~77 ~8 ~27 ~80 ~8 ~27 stonebrick 2  
fill ~77 ~8 ~61 ~80 ~8 ~61 stonebrick 2  
fill ~79 ~8 ~26 ~81 ~8 ~26 stonebrick 2  
fill ~79 ~8 ~62 ~81 ~8 ~62 stonebrick 2  
fill ~80 ~8 ~25 ~82 ~8 ~25 stonebrick 2  
fill ~80 ~8 ~63 ~82 ~8 ~63 stonebrick 2  
fill ~81 ~8 ~24 ~83 ~8 ~24 stonebrick 2  
fill ~81 ~8 ~64 ~83 ~8 ~64 stonebrick 2  
fill ~82 ~8 ~23 ~84 ~8 ~23 stonebrick 2  
fill ~82 ~8 ~37 ~89 ~8 ~37 stonebrick 2  
fill ~82 ~8 ~51 ~89 ~8 ~51 stonebrick 2  
fill ~82 ~8 ~65 ~84 ~8 ~65 stonebrick 2  
fill ~83 ~8 ~22 ~83 ~1 ~22 stonebrick 2  
fill ~83 ~8 ~38 ~89 ~8 ~38 stonebrick 2  
fill ~83 ~8 ~39 ~89 ~8 ~39 stonebrick 2  
fill ~83 ~8 ~49 ~89 ~8 ~49 stonebrick 2  
fill ~83 ~8 ~66 ~83 ~1 ~66 stonebrick 2  
fill ~86 ~8 ~50 ~89 ~8 ~50 stonebrick 2  
fill ~5 ~9 ~29 ~5 ~10 ~29 stone 0  
fill ~6 ~9 ~30 ~6 ~10 ~30 stone 0  
fill ~6 ~9 ~31 ~7 ~9 ~31 stone 0  
fill ~8 ~9 ~33 ~8 ~11 ~33 stone 0  
fill ~9 ~9 ~36 ~11 ~9 ~36 stone 0  
fill ~10 ~9 ~21 ~11 ~9 ~21 stone 0  
fill ~11 ~9 ~37 ~12 ~9 ~37 stone 0  
fill ~12 ~9 ~13 ~12 ~13 ~13 stone 0  
fill ~12 ~9 ~17 ~12 ~20 ~17 stone 0  
fill ~13 ~9 ~10 ~15 ~9 ~10 stone 0  
fill ~13 ~9 ~38 ~13 ~13 ~38 stone 0 
setblock ~14 ~9 ~9 stone 0  
fill ~14 ~9 ~39 ~14 ~13 ~39 stone 0  
fill ~15 ~9 ~40 ~19 ~9 ~40 stone 0  
fill ~16 ~9 ~11 ~16 ~10 ~11 stone 0  
fill ~16 ~9 ~12 ~17 ~9 ~12 stone 0  
fill ~16 ~9 ~38 ~23 ~9 ~38 stonebrick 2  
fill ~16 ~9 ~41 ~16 ~4 ~41 stone 0  
fill ~17 ~9 ~13 ~19 ~9 ~13 stone 0  
fill ~17 ~9 ~37 ~24 ~9 ~37 stonebrick 2  
fill ~17 ~9 ~39 ~23 ~9 ~39 stonebrick 2  
fill ~18 ~9 ~14 ~21 ~9 ~14 stone 0  
fill ~18 ~9 ~49 ~23 ~9 ~49 stonebrick 2  
fill ~18 ~9 ~51 ~24 ~9 ~51 stonebrick 2  
fill ~19 ~9 ~50 ~23 ~9 ~50 stonebrick 2  
fill ~20 ~9 ~15 ~22 ~9 ~15 stone 0  
fill ~20 ~9 ~41 ~21 ~9 ~41 stone 0  
fill ~21 ~9 ~16 ~33 ~9 ~16 stone 0  
fill ~25 ~9 ~63 ~25 ~10 ~63 stonebrick 2  
fill ~28 ~9 ~61 ~29 ~9 ~61 stonebrick 2  
fill ~32 ~9 ~15 ~36 ~9 ~15 stone 0  
fill ~34 ~9 ~72 ~34 ~10 ~72 stonebrick 2  
fill ~37 ~9 ~14 ~38 ~9 ~14 stone 0  
fill ~39 ~9 ~13 ~40 ~9 ~13 stone 0  
fill ~39 ~9 ~67 ~40 ~9 ~67 stonebrick 2  
fill ~39 ~9 ~70 ~40 ~9 ~70 stonebrick 2  
fill ~40 ~9 ~64 ~41 ~9 ~64 stonebrick 2  
fill ~41 ~9 ~12 ~42 ~9 ~12 stone 0  
fill ~41 ~9 ~17 ~42 ~9 ~17 stonebrick 2  
fill ~41 ~9 ~71 ~42 ~9 ~71 stonebrick 2  
fill ~43 ~9 ~11 ~44 ~9 ~11 stone 0  
fill ~43 ~9 ~16 ~44 ~9 ~16 stonebrick 2  
fill ~43 ~9 ~66 ~45 ~9 ~66 stonebrick 2  
fill ~43 ~9 ~69 ~44 ~9 ~69 stonebrick 2  
fill ~43 ~9 ~72 ~44 ~9 ~72 stonebrick 2  
fill ~45 ~9 ~15 ~46 ~9 ~15 stonebrick 2  
fill ~45 ~9 ~70 ~47 ~9 ~70 stonebrick 2  
fill ~45 ~9 ~73 ~46 ~9 ~73 stonebrick 2  
fill ~46 ~9 ~67 ~48 ~9 ~67 stonebrick 2  
fill ~46 ~9 ~74 ~60 ~9 ~74 stonebrick 2  
fill ~47 ~9 ~13 ~50 ~9 ~13 stone 0  
fill ~47 ~9 ~78 ~47 ~12 ~78 stonebrick 2  
fill ~47 ~9 ~79 ~47 ~28 ~79 cobblestone_wall 0  
fill ~48 ~9 ~14 ~59 ~9 ~14 stonebrick 2  
fill ~48 ~9 ~71 ~58 ~9 ~71 stonebrick 2  
fill ~49 ~9 ~68 ~57 ~9 ~68 stonebrick 2  
fill ~50 ~9 ~12 ~52 ~9 ~12 stone 0  
fill ~52 ~9 ~11 ~53 ~9 ~11 stone 0  
fill ~52 ~9 ~75 ~54 ~9 ~75 stonebrick 2  
fill ~52 ~9 ~84 ~54 ~9 ~84 stonebrick 2  
fill ~53 ~9 ~10 ~54 ~9 ~10 stone 0  
fill ~55 ~9 ~9 ~56 ~9 ~9 stone 0  
fill ~56 ~9 ~8 ~61 ~9 ~8 stone 0  
fill ~58 ~9 ~67 ~60 ~9 ~67 stonebrick 2  
fill ~58 ~9 ~87 ~60 ~9 ~87 stonebrick 2  
fill ~59 ~9 ~70 ~61 ~9 ~70 stonebrick 2 
setblock ~59 ~9 ~80 stonebrick 2  
fill ~60 ~9 ~9 ~62 ~9 ~9 stone 0  
fill ~60 ~9 ~15 ~61 ~9 ~15 stonebrick 2  
fill ~60 ~9 ~73 ~61 ~9 ~73 stonebrick 2  
fill ~61 ~9 ~66 ~63 ~9 ~66 stonebrick 2  
fill ~62 ~9 ~16 ~63 ~9 ~16 stonebrick 2  
fill ~62 ~9 ~69 ~63 ~9 ~69 stonebrick 2  
fill ~62 ~9 ~72 ~63 ~9 ~72 stonebrick 2  
fill ~63 ~9 ~10 ~65 ~9 ~10 stone 0  
fill ~64 ~9 ~17 ~65 ~9 ~17 stonebrick 2  
fill ~64 ~9 ~68 ~65 ~9 ~68 stonebrick 2  
fill ~64 ~9 ~71 ~65 ~9 ~71 stonebrick 2  
fill ~65 ~9 ~64 ~66 ~9 ~64 stonebrick 2  
fill ~66 ~9 ~18 ~67 ~9 ~18 stonebrick 2  
fill ~66 ~9 ~67 ~67 ~9 ~67 stonebrick 2  
fill ~66 ~9 ~70 ~67 ~9 ~70 stonebrick 2  
fill ~67 ~9 ~14 ~67 ~11 ~14 stone 0  
fill ~67 ~9 ~15 ~67 ~12 ~15 stone 0  
fill ~68 ~9 ~18 ~68 ~13 ~18 stone 0  
fill ~69 ~9 ~70 ~71 ~9 ~70 stonebrick 2  
fill ~70 ~9 ~71 ~72 ~9 ~71 stonebrick 2  
fill ~71 ~9 ~72 ~73 ~9 ~72 stonebrick 2  
fill ~72 ~9 ~32 ~74 ~9 ~32 stonebrick 2  
fill ~72 ~9 ~73 ~74 ~9 ~73 stonebrick 2  
fill ~73 ~9 ~74 ~74 ~9 ~74 stonebrick 2  
fill ~77 ~9 ~27 ~80 ~9 ~27 stonebrick 2  
fill ~77 ~9 ~61 ~80 ~9 ~61 stonebrick 2  
fill ~79 ~9 ~26 ~81 ~9 ~26 stonebrick 2  
fill ~79 ~9 ~62 ~81 ~9 ~62 stonebrick 2  
fill ~80 ~9 ~25 ~82 ~9 ~25 stonebrick 2  
fill ~80 ~9 ~63 ~82 ~9 ~63 stonebrick 2  
fill ~81 ~9 ~24 ~83 ~9 ~24 stonebrick 2  
fill ~81 ~9 ~64 ~83 ~9 ~64 stonebrick 2  
fill ~82 ~9 ~23 ~83 ~9 ~23 stonebrick 2  
fill ~82 ~9 ~37 ~88 ~9 ~37 stonebrick 2  
fill ~82 ~9 ~51 ~88 ~9 ~51 stonebrick 2  
fill ~82 ~9 ~65 ~83 ~9 ~65 stonebrick 2  
fill ~83 ~9 ~38 ~87 ~9 ~38 stonebrick 2  
fill ~83 ~9 ~39 ~88 ~9 ~39 stonebrick 2  
fill ~83 ~9 ~49 ~88 ~9 ~49 stonebrick 2  
fill ~86 ~9 ~50 ~87 ~9 ~50 stonebrick 2  
fill ~88 ~9 ~38 ~88 ~28 ~38 cobblestone_wall 0   

KittysCommands:   
fill ~88 ~9 ~50 ~88 ~28 ~50 cobblestone_wall 0 
setblock ~89 ~9 ~38 stonebrick 2 
setblock ~89 ~9 ~50 stonebrick 2  
fill ~7 ~10 ~31 ~7 ~13 ~31 stone 0  
fill ~9 ~10 ~35 ~9 ~11 ~35 stone 0  
fill ~9 ~10 ~36 ~11 ~10 ~36 stone 0  
fill ~10 ~10 ~21 ~11 ~10 ~21 stone 0  
fill ~12 ~10 ~18 ~12 ~22 ~18 stone 0  
fill ~12 ~10 ~37 ~12 ~14 ~37 stone 0  
fill ~13 ~10 ~10 ~14 ~10 ~10 stone 0  
fill ~13 ~10 ~11 ~16 ~10 ~11 stone 0  
fill ~15 ~10 ~40 ~20 ~10 ~40 stone 0  
fill ~16 ~10 ~12 ~17 ~10 ~12 stone 0  
fill ~16 ~10 ~38 ~23 ~10 ~38 stonebrick 2  
fill ~17 ~10 ~37 ~24 ~10 ~37 stonebrick 2  
fill ~17 ~10 ~39 ~23 ~10 ~39 stonebrick 2  
fill ~18 ~10 ~13 ~18 ~11 ~13 stone 0  
fill ~18 ~10 ~49 ~23 ~10 ~49 stonebrick 2  
fill ~18 ~10 ~51 ~24 ~10 ~51 stonebrick 2  
fill ~19 ~10 ~14 ~20 ~10 ~14 stone 0  
fill ~19 ~10 ~50 ~22 ~10 ~50 cobblestone 0  
fill ~20 ~10 ~41 ~21 ~10 ~41 stone 0  
fill ~21 ~10 ~15 ~21 ~11 ~15 stone 0  
fill ~22 ~10 ~16 ~24 ~10 ~16 stone 0  
fill ~23 ~10 ~50 ~23 ~30 ~50 stonebrick 2  
fill ~25 ~10 ~17 ~29 ~10 ~17 stone 0  
fill ~28 ~10 ~16 ~34 ~10 ~16 stone 0  
fill ~28 ~10 ~61 ~29 ~10 ~61 stonebrick 2  
fill ~34 ~10 ~15 ~37 ~10 ~15 stone 0  
fill ~38 ~10 ~14 ~39 ~10 ~14 stone 0  
fill ~39 ~10 ~67 ~40 ~10 ~67 stonebrick 2  
fill ~39 ~10 ~70 ~40 ~10 ~70 stonebrick 2  
fill ~40 ~10 ~13 ~41 ~10 ~13 stone 0  
fill ~40 ~10 ~64 ~41 ~10 ~64 stonebrick 2  
fill ~41 ~10 ~17 ~42 ~10 ~17 stonebrick 2  
fill ~41 ~10 ~71 ~42 ~10 ~71 stonebrick 2 
setblock ~42 ~10 ~12 stone 0  
fill ~43 ~10 ~11 ~44 ~10 ~11 stone 0  
fill ~43 ~10 ~16 ~44 ~10 ~16 stonebrick 2  
fill ~43 ~10 ~66 ~45 ~10 ~66 stonebrick 2  
fill ~43 ~10 ~69 ~44 ~10 ~69 stonebrick 2  
fill ~43 ~10 ~72 ~44 ~10 ~72 stonebrick 2  
fill ~44 ~10 ~12 ~44 ~13 ~12 stone 0  
fill ~45 ~10 ~15 ~46 ~10 ~15 stonebrick 2  
fill ~45 ~10 ~70 ~47 ~10 ~70 stonebrick 2  
fill ~45 ~10 ~73 ~46 ~10 ~73 stonebrick 2  
fill ~46 ~10 ~13 ~50 ~10 ~13 stone 0  
fill ~46 ~10 ~67 ~48 ~10 ~67 stonebrick 2  
fill ~46 ~10 ~74 ~60 ~10 ~74 stonebrick 2  
fill ~47 ~10 ~14 ~47 ~11 ~14 stone 0  
fill ~47 ~10 ~15 ~47 ~12 ~15 stone 0  
fill ~47 ~10 ~16 ~47 ~13 ~16 stone 0  
fill ~48 ~10 ~14 ~59 ~10 ~14 stonebrick 2  
fill ~48 ~10 ~71 ~58 ~10 ~71 stonebrick 2  
fill ~49 ~10 ~68 ~57 ~10 ~68 stonebrick 2  
fill ~51 ~10 ~12 ~52 ~10 ~12 stone 0  
fill ~52 ~10 ~11 ~53 ~10 ~11 stone 0  
fill ~52 ~10 ~75 ~54 ~10 ~75 stonebrick 2  
fill ~52 ~10 ~84 ~54 ~10 ~84 stonebrick 2  
fill ~53 ~10 ~10 ~55 ~10 ~10 stone 0  
fill ~56 ~10 ~9 ~62 ~10 ~9 stone 0  
fill ~57 ~10 ~8 ~58 ~10 ~8 stone 0  
fill ~58 ~10 ~67 ~60 ~10 ~67 stonebrick 2  
fill ~58 ~10 ~87 ~60 ~10 ~87 stonebrick 2  
fill ~59 ~10 ~18 ~61 ~10 ~18 stonebrick 2  
fill ~59 ~10 ~70 ~61 ~10 ~70 stonebrick 2  
fill ~60 ~10 ~15 ~64 ~10 ~15 stonebrick 2  
fill ~60 ~10 ~17 ~62 ~10 ~17 stonebrick 2  
fill ~60 ~10 ~19 ~60 ~39 ~19 stonebrick 2  
fill ~60 ~10 ~73 ~61 ~10 ~73 stonebrick 2  
fill ~61 ~10 ~16 ~63 ~10 ~16 stonebrick 2  
fill ~61 ~10 ~66 ~63 ~10 ~66 stonebrick 2  
fill ~62 ~10 ~69 ~63 ~10 ~69 stonebrick 2  
fill ~62 ~10 ~72 ~63 ~10 ~72 stonebrick 2  
fill ~63 ~10 ~10 ~63 ~11 ~10 stone 0  
fill ~63 ~10 ~14 ~65 ~10 ~14 stonebrick 2  
fill ~64 ~10 ~11 ~66 ~10 ~11 stone 0  
fill ~64 ~10 ~13 ~64 ~20 ~13 stonebrick 2  
fill ~64 ~10 ~17 ~65 ~10 ~17 stonebrick 2  
fill ~64 ~10 ~68 ~65 ~10 ~68 stonebrick 2  
fill ~64 ~10 ~71 ~65 ~10 ~71 stonebrick 2  
fill ~65 ~10 ~12 ~66 ~10 ~12 stonebrick 2  
fill ~65 ~10 ~64 ~66 ~10 ~64 stonebrick 2  
fill ~66 ~10 ~13 ~66 ~18 ~13 stonebrick 2  
fill ~66 ~10 ~18 ~67 ~10 ~18 stonebrick 2  
fill ~66 ~10 ~67 ~67 ~10 ~67 stonebrick 2  
fill ~66 ~10 ~70 ~67 ~10 ~70 stonebrick 2  
fill ~69 ~10 ~70 ~71 ~10 ~70 stonebrick 2  
fill ~70 ~10 ~71 ~72 ~10 ~71 stonebrick 2  
fill ~71 ~10 ~72 ~73 ~10 ~72 stonebrick 2  
fill ~72 ~10 ~32 ~74 ~10 ~32 stonebrick 2  
fill ~72 ~10 ~73 ~74 ~10 ~73 stonebrick 2  
fill ~73 ~10 ~22 ~73 ~15 ~22 stone 0  
fill ~73 ~10 ~74 ~73 ~1 ~74 stonebrick 2  
fill ~77 ~10 ~27 ~80 ~10 ~27 stonebrick 2  
fill ~77 ~10 ~61 ~80 ~10 ~61 stonebrick 2  
fill ~79 ~10 ~26 ~81 ~10 ~26 stonebrick 2  
fill ~79 ~10 ~62 ~81 ~10 ~62 stonebrick 2  
fill ~80 ~10 ~25 ~82 ~10 ~25 stonebrick 2  
fill ~80 ~10 ~63 ~82 ~10 ~63 stonebrick 2  
fill ~81 ~10 ~24 ~83 ~10 ~24 stonebrick 2  
fill ~81 ~10 ~64 ~83 ~10 ~64 stonebrick 2  
fill ~82 ~10 ~23 ~82 ~1 ~23 stonebrick 2  
fill ~82 ~10 ~37 ~88 ~10 ~37 stonebrick 2  
fill ~82 ~10 ~51 ~88 ~10 ~51 stonebrick 2  
fill ~82 ~10 ~65 ~82 ~1 ~65 stonebrick 2  
fill ~83 ~10 ~38 ~83 ~30 ~38 stonebrick 2  
fill ~83 ~10 ~39 ~88 ~10 ~39 stonebrick 2  
fill ~83 ~10 ~49 ~88 ~10 ~49 stonebrick 2  
fill ~84 ~10 ~38 ~87 ~10 ~38 cobblestone 0  
