setblock ~11 ~0 ~33 chest 5  
setblock ~11 ~0 ~34 chest 5  
setblock ~8 ~0 ~67 lit_furnace 5  
setblock ~8 ~0 ~68 lit_furnace 5  
setblock ~8 ~0 ~69 lit_furnace 5  
setblock ~8 ~1 ~67 lit_furnace 5  
setblock ~8 ~0 ~70 lit_furnace 5  
setblock ~8 ~0 ~71 lit_furnace 5  
setblock ~8 ~1 ~69 lit_furnace 5  
setblock ~8 ~1 ~68 lit_furnace 5  
setblock ~8 ~1 ~71 lit_furnace 5  
setblock ~8 ~1 ~70 lit_furnace 5  
setblock ~8 ~1 ~80 lit_furnace 5  
setblock ~8 ~1 ~81 lit_furnace 5  
setblock ~8 ~1 ~82 lit_furnace 5  
setblock ~8 ~1 ~83 lit_furnace 5  
setblock ~8 ~1 ~79 lit_furnace 5  
setblock ~8 ~0 ~83 lit_furnace 5  
setblock ~8 ~0 ~79 lit_furnace 5  
setblock ~8 ~0 ~80 lit_furnace 5  
setblock ~8 ~0 ~81 lit_furnace 5  
setblock ~8 ~0 ~82 lit_furnace 5  
setblock ~8 ~1 ~92 lit_furnace 5  
setblock ~8 ~1 ~93 lit_furnace 5  
setblock ~8 ~1 ~94 lit_furnace 5  
setblock ~8 ~1 ~95 lit_furnace 5  
setblock ~8 ~0 ~94 lit_furnace 5  
setblock ~8 ~0 ~93 lit_furnace 5  
setblock ~8 ~0 ~92 lit_furnace 5  
setblock ~8 ~0 ~91 lit_furnace 5  
setblock ~8 ~1 ~91 lit_furnace 5  
setblock ~8 ~0 ~95 lit_furnace 5  
setblock ~8 ~0 ~103 lit_furnace 5  
setblock ~8 ~1 ~103 lit_furnace 5  
setblock ~8 ~1 ~104 lit_furnace 5  
setblock ~8 ~1 ~105 lit_furnace 5  
setblock ~8 ~1 ~106 lit_furnace 5  
setblock ~8 ~0 ~107 lit_furnace 5  
setblock ~8 ~1 ~107 lit_furnace 5  
setblock ~8 ~0 ~106 lit_furnace 5  
setblock ~8 ~0 ~105 lit_furnace 5  
setblock ~8 ~0 ~104 lit_furnace 5  
setblock ~9 ~0 ~138 chest 5  
setblock ~9 ~0 ~139 chest 5  
setblock ~13 ~0 ~23 chest 5  
setblock ~17 ~3 ~22 chest 4  
setblock ~17 ~3 ~21 chest 4  
setblock ~16 ~0 ~22 chest 4  
setblock ~14 ~0 ~22 chest 5  
setblock ~13 ~3 ~21 chest 5  
setblock ~16 ~0 ~21 chest 4  
setblock ~14 ~0 ~21 chest 5  
setblock ~17 ~0 ~23 chest 4  
setblock ~13 ~3 ~22 chest 5  
setblock ~16 ~0 ~29 chest 4  
setblock ~16 ~0 ~30 chest 4  
setblock ~14 ~0 ~29 chest 5  
setblock ~14 ~0 ~30 chest 5  
setblock ~13 ~3 ~25 chest 3  
setblock ~17 ~0 ~26 chest 4  
setblock ~17 ~0 ~27 chest 4  
setblock ~16 ~3 ~25 chest 3  
setblock ~13 ~0 ~24 chest 5  
setblock ~13 ~0 ~26 chest 5  
setblock ~13 ~0 ~27 chest 5  
setblock ~17 ~3 ~25 chest 3  
setblock ~17 ~0 ~24 chest 4  
setblock ~19 ~0 ~34 chest 4  
setblock ~14 ~3 ~25 chest 3  
setblock ~19 ~0 ~33 chest 4  
setblock ~17 ~1 ~67 lit_furnace 4  
setblock ~17 ~1 ~68 lit_furnace 4  
setblock ~17 ~1 ~69 lit_furnace 4  
setblock ~17 ~1 ~70 lit_furnace 4  
setblock ~17 ~1 ~71 lit_furnace 4  
setblock ~13 ~1 ~69 lit_furnace 5  
setblock ~13 ~1 ~68 lit_furnace 5  
setblock ~13 ~1 ~67 lit_furnace 5  
setblock ~13 ~1 ~71 lit_furnace 5  
setblock ~13 ~1 ~70 lit_furnace 5  
setblock ~18 ~0 ~70 lit_furnace 5  
setblock ~18 ~0 ~69 lit_furnace 5  
setblock ~17 ~0 ~67 lit_furnace 4  
setblock ~18 ~0 ~68 lit_furnace 5  
setblock ~17 ~0 ~68 lit_furnace 4  
setblock ~18 ~0 ~67 lit_furnace 5  
setblock ~12 ~1 ~71 lit_furnace 4  
setblock ~12 ~1 ~70 lit_furnace 4  
setblock ~12 ~1 ~69 lit_furnace 4  
setblock ~12 ~1 ~68 lit_furnace 4  
setblock ~18 ~0 ~71 lit_furnace 5  
setblock ~12 ~0 ~68 lit_furnace 4  
setblock ~12 ~1 ~67 lit_furnace 4  
setblock ~12 ~0 ~67 lit_furnace 4  
setblock ~12 ~0 ~70 lit_furnace 4  
setblock ~22 ~0 ~71 lit_furnace 4  
setblock ~12 ~0 ~69 lit_furnace 4  
setblock ~22 ~0 ~69 lit_furnace 4  
setblock ~22 ~0 ~70 lit_furnace 4  
setblock ~22 ~0 ~67 lit_furnace 4  
setblock ~22 ~0 ~68 lit_furnace 4  
setblock ~12 ~0 ~71 lit_furnace 4  
setblock ~17 ~0 ~70 lit_furnace 4  
setblock ~17 ~0 ~69 lit_furnace 4  
setblock ~17 ~0 ~71 lit_furnace 4  
setblock ~18 ~1 ~69 lit_furnace 5  
setblock ~18 ~1 ~68 lit_furnace 5  
setblock ~18 ~1 ~71 lit_furnace 5  
setblock ~18 ~1 ~70 lit_furnace 5  
setblock ~18 ~1 ~67 lit_furnace 5  
setblock ~13 ~0 ~68 lit_furnace 5  
setblock ~13 ~0 ~67 lit_furnace 5  
setblock ~13 ~0 ~71 lit_furnace 5  
setblock ~22 ~1 ~67 lit_furnace 4  
setblock ~13 ~0 ~70 lit_furnace 5  
setblock ~13 ~0 ~69 lit_furnace 5  
setblock ~22 ~1 ~70 lit_furnace 4  
setblock ~22 ~1 ~71 lit_furnace 4  
setblock ~22 ~1 ~68 lit_furnace 4  
setblock ~22 ~1 ~69 lit_furnace 4  
setblock ~17 ~1 ~79 lit_furnace 4  
setblock ~17 ~1 ~80 lit_furnace 4  
setblock ~17 ~1 ~81 lit_furnace 4  
setblock ~17 ~1 ~82 lit_furnace 4  
setblock ~17 ~1 ~83 lit_furnace 4  
setblock ~13 ~1 ~80 lit_furnace 5  
setblock ~13 ~1 ~81 lit_furnace 5  
setblock ~13 ~1 ~79 lit_furnace 5  
setblock ~13 ~1 ~83 lit_furnace 5  
setblock ~13 ~1 ~82 lit_furnace 5  
setblock ~17 ~0 ~81 lit_furnace 4  
setblock ~17 ~0 ~82 lit_furnace 4  
setblock ~17 ~0 ~83 lit_furnace 4  
setblock ~18 ~0 ~83 lit_furnace 5  
setblock ~17 ~0 ~79 lit_furnace 4  
setblock ~17 ~0 ~80 lit_furnace 4  
setblock ~12 ~1 ~83 lit_furnace 4  
setblock ~12 ~1 ~82 lit_furnace 4  
setblock ~12 ~0 ~83 lit_furnace 4  
setblock ~12 ~1 ~81 lit_furnace 4  
setblock ~12 ~1 ~80 lit_furnace 4  
setblock ~18 ~0 ~82 lit_furnace 5  
setblock ~12 ~1 ~79 lit_furnace 4  
setblock ~12 ~0 ~80 lit_furnace 4  
setblock ~18 ~0 ~81 lit_furnace 5  
setblock ~12 ~0 ~79 lit_furnace 4  
setblock ~22 ~0 ~83 lit_furnace 4  
setblock ~12 ~0 ~82 lit_furnace 4  
setblock ~18 ~0 ~80 lit_furnace 5  
setblock ~12 ~0 ~81 lit_furnace 4  
setblock ~18 ~0 ~79 lit_furnace 5  
setblock ~22 ~0 ~82 lit_furnace 4  
setblock ~22 ~0 ~81 lit_furnace 4  
setblock ~22 ~0 ~80 lit_furnace 4  
setblock ~22 ~0 ~79 lit_furnace 4  
setblock ~18 ~1 ~79 lit_furnace 5  
setblock ~18 ~1 ~81 lit_furnace 5  
setblock ~18 ~1 ~80 lit_furnace 5  
setblock ~18 ~1 ~83 lit_furnace 5  
setblock ~18 ~1 ~82 lit_furnace 5  
setblock ~13 ~0 ~80 lit_furnace 5  
setblock ~13 ~0 ~79 lit_furnace 5  
setblock ~13 ~0 ~83 lit_furnace 5  
setblock ~22 ~1 ~79 lit_furnace 4  
setblock ~13 ~0 ~82 lit_furnace 5  
setblock ~13 ~0 ~81 lit_furnace 5  
setblock ~22 ~1 ~82 lit_furnace 4  
setblock ~22 ~1 ~83 lit_furnace 4  
setblock ~22 ~1 ~80 lit_furnace 4  
setblock ~22 ~1 ~81 lit_furnace 4  
setblock ~17 ~1 ~91 lit_furnace 4  
setblock ~17 ~1 ~92 lit_furnace 4  
setblock ~17 ~1 ~93 lit_furnace 4  
setblock ~17 ~1 ~94 lit_furnace 4  
setblock ~17 ~1 ~95 lit_furnace 4  
setblock ~13 ~1 ~92 lit_furnace 5  
setblock ~13 ~1 ~93 lit_furnace 5  
setblock ~13 ~1 ~91 lit_furnace 5  
setblock ~17 ~1 ~103 lit_furnace 4  
setblock ~13 ~1 ~94 lit_furnace 5  
setblock ~13 ~1 ~95 lit_furnace 5  
setblock ~13 ~1 ~103 lit_furnace 5  
setblock ~12 ~0 ~92 lit_furnace 4  
setblock ~12 ~0 ~91 lit_furnace 4  
setblock ~12 ~0 ~94 lit_furnace 4  
setblock ~12 ~0 ~93 lit_furnace 4  
setblock ~17 ~0 ~93 lit_furnace 4  
setblock ~12 ~1 ~103 lit_furnace 4  
setblock ~17 ~0 ~94 lit_furnace 4  
setblock ~17 ~0 ~95 lit_furnace 4  
setblock ~18 ~0 ~103 lit_furnace 5  
setblock ~18 ~0 ~94 lit_furnace 5  
setblock ~18 ~0 ~93 lit_furnace 5  
setblock ~17 ~0 ~91 lit_furnace 4  
setblock ~18 ~0 ~92 lit_furnace 5  
setblock ~22 ~0 ~103 lit_furnace 4  
setblock ~17 ~0 ~92 lit_furnace 4  
setblock ~18 ~0 ~91 lit_furnace 5  
setblock ~12 ~1 ~95 lit_furnace 4  
setblock ~12 ~0 ~95 lit_furnace 4  
setblock ~12 ~1 ~94 lit_furnace 4  
setblock ~12 ~1 ~93 lit_furnace 4  
setblock ~12 ~1 ~92 lit_furnace 4  
setblock ~18 ~0 ~95 lit_furnace 5  
setblock ~12 ~1 ~91 lit_furnace 4  
setblock ~22 ~0 ~95 lit_furnace 4  
setblock ~12 ~0 ~103 lit_furnace 4  
setblock ~22 ~0 ~94 lit_furnace 4  
setblock ~22 ~0 ~93 lit_furnace 4  
setblock ~22 ~0 ~92 lit_furnace 4  
setblock ~22 ~0 ~91 lit_furnace 4  
setblock ~17 ~0 ~103 lit_furnace 4  
setblock ~18 ~1 ~92 lit_furnace 5  
setblock ~18 ~1 ~93 lit_furnace 5  
setblock ~18 ~1 ~94 lit_furnace 5  
setblock ~18 ~1 ~95 lit_furnace 5  
setblock ~18 ~1 ~91 lit_furnace 5  
setblock ~13 ~0 ~91 lit_furnace 5  
setblock ~13 ~0 ~92 lit_furnace 5  
setblock ~18 ~1 ~103 lit_furnace 5  
setblock ~22 ~1 ~91 lit_furnace 4  
setblock ~13 ~0 ~95 lit_furnace 5  
setblock ~13 ~0 ~94 lit_furnace 5  
setblock ~13 ~0 ~93 lit_furnace 5  
setblock ~22 ~1 ~94 lit_furnace 4  
setblock ~22 ~1 ~95 lit_furnace 4  
setblock ~22 ~1 ~92 lit_furnace 4  
setblock ~22 ~1 ~93 lit_furnace 4  
setblock ~13 ~0 ~103 lit_furnace 5  
setblock ~22 ~1 ~103 lit_furnace 4  
setblock ~17 ~1 ~106 lit_furnace 4  
setblock ~17 ~1 ~107 lit_furnace 4  
setblock ~18 ~1 ~104 lit_furnace 5  
setblock ~13 ~1 ~104 lit_furnace 5  
setblock ~18 ~1 ~105 lit_furnace 5  
setblock ~13 ~1 ~105 lit_furnace 5  
setblock ~18 ~1 ~106 lit_furnace 5  
setblock ~18 ~1 ~107 lit_furnace 5  
setblock ~13 ~1 ~106 lit_furnace 5  
setblock ~13 ~0 ~104 lit_furnace 5  
setblock ~13 ~1 ~107 lit_furnace 5  
setblock ~13 ~0 ~105 lit_furnace 5  
setblock ~13 ~0 ~106 lit_furnace 5  
setblock ~13 ~0 ~107 lit_furnace 5  
setblock ~18 ~0 ~104 lit_furnace 5  
setblock ~18 ~0 ~105 lit_furnace 5  
setblock ~18 ~0 ~106 lit_furnace 5  
setblock ~17 ~1 ~105 lit_furnace 4  
setblock ~17 ~1 ~104 lit_furnace 4  
setblock ~12 ~0 ~107 lit_furnace 4  
setblock ~12 ~0 ~104 lit_furnace 4  
setblock ~12 ~0 ~106 lit_furnace 4  
setblock ~12 ~0 ~105 lit_furnace 4  
setblock ~17 ~0 ~105 lit_furnace 4  
setblock ~17 ~0 ~106 lit_furnace 4  
setblock ~17 ~0 ~107 lit_furnace 4  
setblock ~18 ~0 ~107 lit_furnace 5  
setblock ~17 ~0 ~104 lit_furnace 4  
setblock ~22 ~1 ~106 lit_furnace 4  
setblock ~12 ~1 ~106 lit_furnace 4  
setblock ~22 ~1 ~107 lit_furnace 4  
setblock ~12 ~1 ~107 lit_furnace 4  
setblock ~22 ~1 ~104 lit_furnace 4  
setblock ~12 ~1 ~104 lit_furnace 4  
setblock ~22 ~1 ~105 lit_furnace 4  
setblock ~12 ~1 ~105 lit_furnace 4  
setblock ~22 ~0 ~107 lit_furnace 4  
setblock ~22 ~0 ~106 lit_furnace 4  
setblock ~22 ~0 ~105 lit_furnace 4  
setblock ~22 ~0 ~104 lit_furnace 4  
setblock ~21 ~0 ~138 chest 4  
setblock ~12 ~0 ~139 chest 2  
setblock ~18 ~0 ~137 chest 2  
setblock ~21 ~0 ~139 chest 4  
setblock ~12 ~0 ~137 chest 2  
setblock ~17 ~0 ~137 chest 2  
setblock ~17 ~0 ~139 chest 2  
setblock ~18 ~0 ~139 chest 2  
setblock ~13 ~0 ~137 chest 2  
setblock ~13 ~0 ~139 chest 2  
fill ~5 ~-2 ~61 ~25 ~-2 ~61 nether_brick 0  
fill ~5 ~-2 ~62 ~25 ~-2 ~62 nether_brick 0  
fill ~5 ~-2 ~63 ~25 ~-2 ~63 nether_brick 0  
fill ~5 ~-2 ~64 ~25 ~-2 ~64 nether_brick 0  
fill ~5 ~-2 ~65 ~25 ~-2 ~65 nether_brick 0  
fill ~5 ~-2 ~66 ~25 ~-2 ~66 nether_brick 0  
fill ~5 ~-2 ~67 ~25 ~-2 ~67 nether_brick 0  
fill ~5 ~-2 ~68 ~25 ~-2 ~68 nether_brick 0  
fill ~5 ~-2 ~69 ~25 ~-2 ~69 nether_brick 0  
fill ~5 ~-2 ~70 ~25 ~-2 ~70 nether_brick 0  
fill ~5 ~-2 ~71 ~25 ~-2 ~71 nether_brick 0  
fill ~5 ~-2 ~72 ~25 ~-2 ~72 nether_brick 0  
fill ~5 ~-2 ~73 ~25 ~-2 ~73 nether_brick 0  
fill ~5 ~-2 ~74 ~25 ~-2 ~74 nether_brick 0  
fill ~5 ~-2 ~75 ~25 ~-2 ~75 nether_brick 0  
fill ~5 ~-2 ~76 ~25 ~-2 ~76 nether_brick 0  
fill ~5 ~-2 ~77 ~25 ~-2 ~77 nether_brick 0  
fill ~5 ~-2 ~78 ~25 ~-2 ~78 nether_brick 0  
fill ~5 ~-2 ~79 ~25 ~-2 ~79 nether_brick 0  
fill ~5 ~-2 ~80 ~25 ~-2 ~80 nether_brick 0  
fill ~5 ~-2 ~81 ~25 ~-2 ~81 nether_brick 0  
fill ~5 ~-2 ~82 ~25 ~-2 ~82 nether_brick 0  
fill ~5 ~-2 ~83 ~25 ~-2 ~83 nether_brick 0  
fill ~5 ~-2 ~84 ~25 ~-2 ~84 nether_brick 0  
fill ~5 ~-2 ~85 ~25 ~-2 ~85 nether_brick 0  
fill ~5 ~-2 ~86 ~25 ~-2 ~86 nether_brick 0  
fill ~5 ~-2 ~87 ~25 ~-2 ~87 nether_brick 0  
fill ~5 ~-2 ~88 ~25 ~-2 ~88 nether_brick 0  
fill ~5 ~-2 ~89 ~25 ~-2 ~89 nether_brick 0  
fill ~5 ~-2 ~90 ~25 ~-2 ~90 nether_brick 0  
fill ~5 ~-2 ~91 ~25 ~-2 ~91 nether_brick 0  
fill ~5 ~-2 ~92 ~25 ~-2 ~92 nether_brick 0  
fill ~5 ~-2 ~93 ~25 ~-2 ~93 nether_brick 0  
fill ~5 ~-2 ~94 ~25 ~-2 ~94 nether_brick 0  
fill ~5 ~-2 ~95 ~25 ~-2 ~95 nether_brick 0  
fill ~5 ~-2 ~96 ~25 ~-2 ~96 nether_brick 0  
fill ~5 ~-2 ~97 ~25 ~-2 ~97 nether_brick 0  
fill ~5 ~-2 ~98 ~25 ~-2 ~98 nether_brick 0  
fill ~5 ~-2 ~99 ~25 ~-2 ~99 nether_brick 0  
fill ~5 ~-2 ~100 ~25 ~-2 ~100 nether_brick 0  
fill ~5 ~-2 ~101 ~25 ~-2 ~101 nether_brick 0  
fill ~5 ~-2 ~102 ~25 ~-2 ~102 nether_brick 0  
fill ~5 ~-2 ~103 ~25 ~-2 ~103 nether_brick 0  
fill ~5 ~-2 ~104 ~25 ~-2 ~104 nether_brick 0  
fill ~5 ~-2 ~105 ~25 ~-2 ~105 nether_brick 0  
fill ~5 ~-2 ~106 ~25 ~-2 ~106 nether_brick 0  
fill ~5 ~-2 ~107 ~25 ~-2 ~107 nether_brick 0  
fill ~5 ~-2 ~108 ~25 ~-2 ~108 nether_brick 0  
fill ~5 ~-2 ~109 ~25 ~-2 ~109 nether_brick 0  
fill ~5 ~-2 ~110 ~25 ~-2 ~110 nether_brick 0  
fill ~5 ~-2 ~111 ~25 ~-2 ~111 nether_brick 0  
fill ~5 ~-2 ~112 ~25 ~-2 ~112 nether_brick 0  
fill ~5 ~-2 ~113 ~25 ~-2 ~113 nether_brick 0  
fill ~5 ~-2 ~114 ~25 ~-2 ~114 nether_brick 0  
fill ~5 ~-2 ~115 ~25 ~-2 ~115 nether_brick 0  
fill ~5 ~-2 ~116 ~25 ~-2 ~116 nether_brick 0  
fill ~5 ~-2 ~117 ~25 ~-2 ~117 nether_brick 0  
fill ~5 ~-2 ~118 ~25 ~-2 ~118 nether_brick 0  
fill ~5 ~-2 ~119 ~25 ~-2 ~119 nether_brick 0  
fill ~5 ~-2 ~120 ~25 ~-2 ~120 nether_brick 0  
fill ~5 ~-2 ~121 ~25 ~-2 ~121 nether_brick 0  
fill ~6 ~-2 ~57 ~24 ~-2 ~57 nether_brick 0  
fill ~6 ~-2 ~58 ~24 ~-2 ~58 nether_brick 0  
fill ~6 ~-2 ~59 ~24 ~-2 ~59 nether_brick 0  
fill ~6 ~-2 ~60 ~24 ~-2 ~60 nether_brick 0  
fill ~6 ~-2 ~122 ~24 ~-2 ~122 nether_brick 0  
fill ~6 ~-2 ~123 ~24 ~-2 ~123 nether_brick 0  
fill ~6 ~-2 ~124 ~24 ~-2 ~124 nether_brick 0  
fill ~6 ~-2 ~125 ~24 ~-2 ~125 nether_brick 0  
fill ~6 ~-2 ~126 ~24 ~-2 ~126 nether_brick 0  
fill ~7 ~-2 ~54 ~23 ~-2 ~54 nether_brick 0  
fill ~7 ~-2 ~55 ~23 ~-2 ~55 nether_brick 0  
fill ~7 ~-2 ~56 ~23 ~-2 ~56 nether_brick 0  
fill ~7 ~-2 ~127 ~23 ~-2 ~127 nether_brick 0  
fill ~7 ~-2 ~128 ~23 ~-2 ~128 nether_brick 0  
fill ~7 ~-2 ~129 ~23 ~-2 ~129 nether_brick 0  
fill ~8 ~-2 ~49 ~22 ~-2 ~49 nether_brick 0  
fill ~8 ~-2 ~50 ~22 ~-2 ~50 nether_brick 0  
fill ~8 ~-2 ~51 ~22 ~-2 ~51 nether_brick 0  
fill ~8 ~-2 ~52 ~22 ~-2 ~52 nether_brick 0  
fill ~8 ~-2 ~53 ~22 ~-2 ~53 nether_brick 0  
fill ~8 ~-2 ~130 ~22 ~-2 ~130 nether_brick 0  
fill ~8 ~-2 ~131 ~22 ~-2 ~131 nether_brick 0  
fill ~8 ~-2 ~132 ~22 ~-2 ~132 nether_brick 0  
fill ~8 ~-2 ~133 ~22 ~-2 ~133 nether_brick 0  
fill ~9 ~-2 ~45 ~21 ~-2 ~45 nether_brick 0  
fill ~9 ~-2 ~46 ~21 ~-2 ~46 nether_brick 0  
fill ~9 ~-2 ~47 ~21 ~-2 ~47 nether_brick 0  
fill ~9 ~-2 ~48 ~21 ~-2 ~48 nether_brick 0  
fill ~9 ~-2 ~134 ~21 ~-2 ~134 nether_brick 0  
fill ~9 ~-2 ~135 ~21 ~-2 ~135 nether_brick 0  
fill ~9 ~-2 ~136 ~21 ~-2 ~136 nether_brick 0 
setblock ~9 ~-2 ~144 iron_bars 0  
fill ~10 ~-2 ~40 ~20 ~-2 ~40 nether_brick 0  
fill ~10 ~-2 ~41 ~20 ~-2 ~41 nether_brick 0  
fill ~10 ~-2 ~42 ~20 ~-2 ~42 nether_brick 0  
fill ~10 ~-2 ~43 ~20 ~-2 ~43 nether_brick 0  
fill ~10 ~-2 ~44 ~20 ~-2 ~44 nether_brick 0  
fill ~10 ~-2 ~137 ~20 ~-2 ~137 nether_brick 0  
fill ~10 ~-2 ~138 ~20 ~-2 ~138 nether_brick 0  
fill ~10 ~-2 ~139 ~20 ~-2 ~139 nether_brick 0  
fill ~11 ~-2 ~35 ~19 ~-2 ~35 nether_brick 0  
fill ~11 ~-2 ~36 ~19 ~-2 ~36 nether_brick 0  
fill ~11 ~-2 ~37 ~19 ~-2 ~37 nether_brick 0  
fill ~11 ~-2 ~38 ~19 ~-2 ~38 nether_brick 0  
fill ~11 ~-2 ~39 ~19 ~-2 ~39 nether_brick 0  
fill ~11 ~-2 ~140 ~19 ~-2 ~140 nether_brick 0  
fill ~11 ~-2 ~141 ~19 ~-2 ~141 nether_brick 0  
fill ~12 ~-2 ~29 ~18 ~-2 ~29 nether_brick 0  
fill ~12 ~-2 ~30 ~18 ~-2 ~30 nether_brick 0  
fill ~12 ~-2 ~31 ~18 ~-2 ~31 nether_brick 0  
fill ~12 ~-2 ~32 ~18 ~-2 ~32 nether_brick 0  
fill ~12 ~-2 ~33 ~18 ~-2 ~33 nether_brick 0  
fill ~12 ~-2 ~34 ~18 ~-2 ~34 nether_brick 0  
fill ~12 ~-2 ~142 ~18 ~-2 ~142 nether_brick 0  
fill ~12 ~-2 ~143 ~18 ~-2 ~143 nether_brick 0  
fill ~13 ~-2 ~25 ~17 ~-2 ~25 nether_brick 0  
fill ~13 ~-2 ~26 ~17 ~-2 ~26 nether_brick 0  
fill ~13 ~-2 ~27 ~17 ~-2 ~27 nether_brick 0  
fill ~13 ~-2 ~28 ~17 ~-2 ~28 nether_brick 0  
fill ~13 ~-2 ~144 ~17 ~-2 ~144 nether_brick 0  
fill ~13 ~-2 ~145 ~17 ~-2 ~145 nether_brick 0  
fill ~13 ~-2 ~146 ~13 ~0 ~146 nether_brick 0  
fill ~13 ~-2 ~147 ~13 ~0 ~147 nether_brick 0 
setblock ~13 ~-2 ~149 iron_bars 0 
setblock ~13 ~-2 ~153 nether_brick_stairs 6  
fill ~13 ~-2 ~154 ~13 ~1 ~154 nether_brick 0  
fill ~13 ~-2 ~155 ~13 ~1 ~155 nether_brick 0  
fill ~14 ~-2 ~14 ~16 ~-2 ~14 nether_brick 0  
fill ~14 ~-2 ~15 ~16 ~-2 ~15 nether_brick 0  
fill ~14 ~-2 ~16 ~16 ~-2 ~16 nether_brick 0  
fill ~14 ~-2 ~17 ~16 ~-2 ~17 nether_brick 0  
fill ~14 ~-2 ~18 ~16 ~-2 ~18 nether_brick 0  
fill ~14 ~-2 ~19 ~16 ~-2 ~19 nether_brick 0  
fill ~14 ~-2 ~20 ~16 ~-2 ~20 nether_brick 0  
fill ~14 ~-2 ~21 ~16 ~-2 ~21 nether_brick 0  
fill ~14 ~-2 ~22 ~16 ~-2 ~22 nether_brick 0  
fill ~14 ~-2 ~23 ~16 ~-2 ~23 nether_brick 0  
fill ~14 ~-2 ~24 ~16 ~-2 ~24 nether_brick 0  
fill ~15 ~-2 ~12 ~15 ~1 ~12 nether_brick 0  
fill ~15 ~-2 ~13 ~15 ~1 ~13 nether_brick 0  
fill ~17 ~-2 ~146 ~17 ~0 ~146 nether_brick 0  
fill ~17 ~-2 ~147 ~17 ~0 ~147 nether_brick 0 
setblock ~17 ~-2 ~149 iron_bars 0 
setblock ~17 ~-2 ~153 nether_brick_stairs 6  
fill ~17 ~-2 ~154 ~17 ~1 ~154 nether_brick 0  
fill ~17 ~-2 ~155 ~17 ~1 ~155 nether_brick 0 
setblock ~21 ~-2 ~145 iron_bars 0  
fill ~4 ~-1 ~60 ~5 ~-1 ~60 nether_brick 0  
fill ~4 ~-1 ~61 ~5 ~-1 ~61 nether_brick 0  
fill ~4 ~-1 ~62 ~5 ~-1 ~62 nether_brick 0  
fill ~4 ~-1 ~63 ~4 ~1 ~63 nether_brick 0  
fill ~4 ~-1 ~64 ~4 ~1 ~64 nether_brick 0  
fill ~4 ~-1 ~65 ~4 ~1 ~65 nether_brick 0  
fill ~4 ~-1 ~66 ~5 ~-1 ~66 nether_brick 0  
fill ~4 ~-1 ~67 ~4 ~1 ~67 nether_brick 0  
fill ~4 ~-1 ~68 ~6 ~-1 ~68 nether_brick 0  
fill ~4 ~-1 ~69 ~4 ~1 ~69 nether_brick 0  
fill ~4 ~-1 ~70 ~6 ~-1 ~70 nether_brick 0  
fill ~4 ~-1 ~71 ~6 ~-1 ~71 nether_brick 0  
fill ~4 ~-1 ~72 ~6 ~-1 ~72 nether_brick 0  
fill ~4 ~-1 ~73 ~4 ~1 ~73 nether_brick 0  
fill ~4 ~-1 ~74 ~6 ~-1 ~74 nether_brick 0  
fill ~4 ~-1 ~75 ~6 ~-1 ~75 nether_brick 0  
fill ~4 ~-1 ~76 ~4 ~1 ~76 nether_brick 0  
fill ~4 ~-1 ~77 ~6 ~-1 ~77 nether_brick 0  
fill ~4 ~-1 ~78 ~6 ~-1 ~78 nether_brick 0  
fill ~4 ~-1 ~79 ~6 ~-1 ~79 nether_brick 0  
fill ~4 ~-1 ~80 ~4 ~1 ~80 nether_brick 0  
fill ~4 ~-1 ~81 ~6 ~-1 ~81 nether_brick 0  
fill ~4 ~-1 ~82 ~6 ~-1 ~82 nether_brick 0  
fill ~4 ~-1 ~83 ~4 ~1 ~83 nether_brick 0  
fill ~4 ~-1 ~84 ~6 ~-1 ~84 nether_brick 0  
fill ~4 ~-1 ~85 ~6 ~-1 ~85 nether_brick 0  
fill ~4 ~-1 ~86 ~6 ~-1 ~86 nether_brick 0  
fill ~4 ~-1 ~87 ~6 ~-1 ~87 nether_brick 0  
fill ~4 ~-1 ~88 ~4 ~1 ~88 nether_brick 0  
fill ~4 ~-1 ~89 ~6 ~-1 ~89 nether_brick 0  
fill ~4 ~-1 ~90 ~6 ~-1 ~90 nether_brick 0  
fill ~4 ~-1 ~91 ~4 ~1 ~91 nether_brick 0  
fill ~4 ~-1 ~92 ~6 ~-1 ~92 nether_brick 0  
fill ~4 ~-1 ~93 ~6 ~-1 ~93 nether_brick 0  
fill ~4 ~-1 ~94 ~6 ~-1 ~94 nether_brick 0  
fill ~4 ~-1 ~95 ~6 ~-1 ~95 nether_brick 0  
fill ~4 ~-1 ~96 ~4 ~1 ~96 nether_brick 0  
fill ~4 ~-1 ~97 ~6 ~-1 ~97 nether_brick 0  
fill ~4 ~-1 ~98 ~6 ~-1 ~98 nether_brick 0  
fill ~4 ~-1 ~99 ~6 ~-1 ~99 nether_brick 0  
fill ~4 ~-1 ~100 ~6 ~-1 ~100 nether_brick 0  
fill ~4 ~-1 ~101 ~4 ~1 ~101 nether_brick 0  
fill ~4 ~-1 ~102 ~6 ~-1 ~102 nether_brick 0  
fill ~4 ~-1 ~103 ~6 ~-1 ~103 nether_brick 0  
fill ~4 ~-1 ~104 ~6 ~-1 ~104 nether_brick 0  
fill ~4 ~-1 ~105 ~6 ~-1 ~105 nether_brick 0  
fill ~4 ~-1 ~106 ~6 ~-1 ~106 nether_brick 0  
fill ~4 ~-1 ~107 ~6 ~-1 ~107 nether_brick 0  
fill ~4 ~-1 ~108 ~4 ~1 ~108 nether_brick 0  
fill ~4 ~-1 ~109 ~6 ~-1 ~109 nether_brick 0  
fill ~4 ~-1 ~110 ~6 ~-1 ~110 nether_brick 0  
fill ~4 ~-1 ~111 ~6 ~-1 ~111 nether_brick 0  
fill ~4 ~-1 ~112 ~6 ~-1 ~112 nether_brick 0  
fill ~4 ~-1 ~113 ~6 ~-1 ~113 nether_brick 0  
fill ~4 ~-1 ~114 ~6 ~-1 ~114 nether_brick 0  
fill ~4 ~-1 ~115 ~4 ~1 ~115 nether_brick 0  
fill ~4 ~-1 ~116 ~4 ~1 ~116 nether_brick 0  
fill ~4 ~-1 ~117 ~4 ~1 ~117 nether_brick 0  
fill ~4 ~-1 ~118 ~4 ~1 ~118 nether_brick 0  
fill ~4 ~-1 ~119 ~4 ~1 ~119 nether_brick 0  
fill ~4 ~-1 ~120 ~4 ~1 ~120 nether_brick 0  
fill ~4 ~-1 ~121 ~4 ~1 ~121 nether_brick 0  
fill ~4 ~-1 ~122 ~5 ~-1 ~122 nether_brick 0  
fill ~5 ~-1 ~56 ~6 ~-1 ~56 nether_brick 0  
fill ~5 ~-1 ~57 ~6 ~-1 ~57 nether_brick 0  
fill ~5 ~-1 ~58 ~5 ~1 ~58 nether_brick 0  
fill ~5 ~-1 ~59 ~5 ~1 ~59 nether_brick 0  
fill ~5 ~-1 ~63 ~25 ~-1 ~63 stone 0  
fill ~5 ~-1 ~64 ~25 ~-1 ~64 stone 0  
fill ~5 ~-1 ~65 ~8 ~-1 ~65 stone 0 
setblock ~5 ~-1 ~67 glowstone 0 
setblock ~5 ~-1 ~69 glowstone 0 
setblock ~5 ~-1 ~73 glowstone 0 
setblock ~5 ~-1 ~76 glowstone 0 
setblock ~5 ~-1 ~80 glowstone 0 
setblock ~5 ~-1 ~83 glowstone 0 
setblock ~5 ~-1 ~88 glowstone 0 
setblock ~5 ~-1 ~91 glowstone 0 
setblock ~5 ~-1 ~96 glowstone 0 
setblock ~5 ~-1 ~101 glowstone 0 
setblock ~5 ~-1 ~108 glowstone 0  
fill ~5 ~-1 ~115 ~8 ~-1 ~115 stone 0  
fill ~5 ~-1 ~116 ~5 ~-1 ~120 glowstone 0  
fill ~5 ~-1 ~121 ~24 ~-1 ~121 stone 0  
fill ~5 ~-1 ~123 ~5 ~-1 ~127 nether_brick 0  
fill ~6 ~-1 ~53 ~7 ~-1 ~53 nether_brick 0  
fill ~6 ~-1 ~54 ~6 ~1 ~54 nether_brick 0  
fill ~6 ~-1 ~55 ~6 ~1 ~55 nether_brick 0  
fill ~6 ~-1 ~58 ~9 ~-1 ~58 stone 0  
fill ~6 ~-1 ~59 ~24 ~-1 ~59 stone 0  
fill ~6 ~-1 ~60 ~8 ~-1 ~60 stone 0  
fill ~6 ~-1 ~61 ~24 ~-1 ~61 stone 0  
fill ~6 ~-1 ~62 ~8 ~-1 ~62 stone 0  
fill ~6 ~-1 ~66 ~24 ~-1 ~66 stone 0 
setblock ~6 ~-1 ~67 nether_brick 0 
setblock ~6 ~-1 ~69 nether_brick 0 
setblock ~6 ~-1 ~73 nether_brick 0 
setblock ~6 ~-1 ~76 nether_brick 0 
setblock ~6 ~-1 ~80 nether_brick 0 
setblock ~6 ~-1 ~83 nether_brick 0 
setblock ~6 ~-1 ~88 nether_brick 0 
setblock ~6 ~-1 ~91 nether_brick 0 
setblock ~6 ~-1 ~96 nether_brick 0 
setblock ~6 ~-1 ~101 nether_brick 0 
setblock ~6 ~-1 ~108 nether_brick 0  
fill ~6 ~-1 ~116 ~25 ~-1 ~116 stone 0  
fill ~6 ~-1 ~117 ~25 ~-1 ~117 stone 0  
fill ~6 ~-1 ~118 ~17 ~-1 ~118 stone 0  
fill ~6 ~-1 ~119 ~25 ~-1 ~119 stone 0  
fill ~6 ~-1 ~120 ~12 ~-1 ~120 stone 0  
fill ~6 ~-1 ~122 ~24 ~-1 ~122 stone 0  
fill ~6 ~-1 ~123 ~14 ~-1 ~123 stone 0  
fill ~6 ~-1 ~124 ~12 ~-1 ~124 stone 0  
fill ~6 ~-1 ~125 ~24 ~-1 ~125 stone 0  
fill ~6 ~-1 ~126 ~24 ~-1 ~126 stone 0  
fill ~6 ~-1 ~127 ~6 ~-1 ~131 nether_brick 0  
fill ~7 ~-1 ~48 ~8 ~-1 ~48 nether_brick 0  
fill ~7 ~-1 ~49 ~7 ~1 ~49 nether_brick 0  
fill ~7 ~-1 ~50 ~7 ~1 ~50 nether_brick 0  
fill ~7 ~-1 ~51 ~7 ~1 ~51 nether_brick 0  
fill ~7 ~-1 ~52 ~7 ~-1 ~48 nether_brick 0  
fill ~7 ~-1 ~54 ~9 ~-1 ~54 stone 0  
fill ~7 ~-1 ~55 ~23 ~-1 ~55 stone 0  
fill ~7 ~-1 ~56 ~9 ~-1 ~56 stone 0  
fill ~7 ~-1 ~57 ~12 ~-1 ~57 stone 0  
fill ~7 ~-1 ~67 ~24 ~-1 ~67 stone 0  
fill ~7 ~-1 ~68 ~22 ~-1 ~68 stone 0  
fill ~7 ~-1 ~69 ~22 ~-1 ~69 stone 0  
fill ~7 ~-1 ~70 ~22 ~-1 ~70 stone 0  
fill ~7 ~-1 ~71 ~22 ~-1 ~71 stone 0  
fill ~7 ~-1 ~72 ~23 ~-1 ~72 stone 0  
fill ~7 ~-1 ~73 ~23 ~-1 ~73 stone 0  
fill ~7 ~-1 ~74 ~23 ~-1 ~74 stone 0  
fill ~7 ~-1 ~75 ~23 ~-1 ~75 stone 0  
fill ~7 ~-1 ~76 ~23 ~-1 ~76 stone 0  
fill ~7 ~-1 ~77 ~23 ~-1 ~77 stone 0  
fill ~7 ~-1 ~78 ~23 ~-1 ~78 stone 0  
fill ~7 ~-1 ~79 ~23 ~-1 ~79 stone 0  
fill ~7 ~-1 ~80 ~23 ~-1 ~80 stone 0  
fill ~7 ~-1 ~81 ~23 ~-1 ~81 stone 0  
fill ~7 ~-1 ~82 ~23 ~-1 ~82 stone 0  
fill ~7 ~-1 ~83 ~23 ~-1 ~83 stone 0  
fill ~7 ~-1 ~84 ~23 ~-1 ~84 stone 0  
fill ~7 ~-1 ~85 ~23 ~-1 ~85 stone 0  
fill ~7 ~-1 ~86 ~23 ~-1 ~86 stone 0  
fill ~7 ~-1 ~87 ~23 ~-1 ~87 stone 0  
fill ~7 ~-1 ~88 ~23 ~-1 ~88 stone 0  
fill ~7 ~-1 ~89 ~23 ~-1 ~89 stone 0  
fill ~7 ~-1 ~90 ~23 ~-1 ~90 stone 0  
fill ~7 ~-1 ~91 ~23 ~-1 ~91 stone 0  
fill ~7 ~-1 ~92 ~23 ~-1 ~92 stone 0  
fill ~7 ~-1 ~93 ~23 ~-1 ~93 stone 0  
fill ~7 ~-1 ~94 ~23 ~-1 ~94 stone 0  
fill ~7 ~-1 ~95 ~23 ~-1 ~95 stone 0  
fill ~7 ~-1 ~96 ~23 ~-1 ~96 stone 0  
fill ~7 ~-1 ~97 ~23 ~-1 ~97 stone 0  
fill ~7 ~-1 ~98 ~23 ~-1 ~98 stone 0  
fill ~7 ~-1 ~99 ~23 ~-1 ~99 stone 0  
fill ~7 ~-1 ~100 ~23 ~-1 ~100 stone 0  
fill ~7 ~-1 ~101 ~23 ~-1 ~101 stone 0  
fill ~7 ~-1 ~102 ~23 ~-1 ~102 stone 0  
fill ~7 ~-1 ~103 ~23 ~-1 ~103 stone 0  
fill ~7 ~-1 ~104 ~23 ~-1 ~104 stone 0  
fill ~7 ~-1 ~105 ~23 ~-1 ~105 stone 0  
fill ~7 ~-1 ~106 ~23 ~-1 ~106 stone 0  
fill ~7 ~-1 ~107 ~23 ~-1 ~107 stone 0  
fill ~7 ~-1 ~108 ~23 ~-1 ~108 stone 0  
fill ~7 ~-1 ~109 ~23 ~-1 ~109 stone 0  
fill ~7 ~-1 ~110 ~23 ~-1 ~110 stone 0  
fill ~7 ~-1 ~111 ~23 ~-1 ~111 stone 0  
fill ~7 ~-1 ~112 ~23 ~-1 ~112 stone 0  
fill ~7 ~-1 ~113 ~23 ~-1 ~113 stone 0  
fill ~7 ~-1 ~114 ~22 ~-1 ~114 stone 0  
fill ~7 ~-1 ~127 ~23 ~-1 ~127 stone 0  
fill ~7 ~-1 ~128 ~8 ~-1 ~128 stone 0  
fill ~7 ~-1 ~129 ~12 ~-1 ~129 stone 0  
fill ~7 ~-1 ~130 ~7 ~-1 ~134 nether_brick 0  
fill ~8 ~-1 ~44 ~9 ~-1 ~44 nether_brick 0  
fill ~8 ~-1 ~45 ~8 ~1 ~45 nether_brick 0  
fill ~8 ~-1 ~46 ~8 ~1 ~46 nether_brick 0  
fill ~8 ~-1 ~47 ~8 ~-1 ~44 nether_brick 0  
fill ~8 ~-1 ~49 ~22 ~-1 ~49 stone 0  
fill ~8 ~-1 ~50 ~22 ~-1 ~50 stone 0  
fill ~8 ~-1 ~51 ~22 ~-1 ~51 stone 0  
fill ~8 ~-1 ~52 ~22 ~-1 ~52 stone 0  
fill ~8 ~-1 ~53 ~12 ~-1 ~53 stone 0  
fill ~8 ~-1 ~130 ~8 ~-1 ~133 stone 0  
fill ~8 ~-1 ~134 ~8 ~-1 ~137 nether_brick 0 
setblock ~8 ~-1 ~144 iron_bars 0  
fill ~9 ~-1 ~39 ~10 ~-1 ~39 nether_brick 0  
fill ~9 ~-1 ~40 ~9 ~1 ~40 nether_brick 0  
fill ~9 ~-1 ~41 ~9 ~1 ~41 nether_brick 0  
fill ~9 ~-1 ~42 ~9 ~1 ~42 nether_brick 0  
fill ~9 ~-1 ~43 ~9 ~-1 ~39 nether_brick 0  
fill ~9 ~-1 ~45 ~10 ~-1 ~45 stone 0  
fill ~9 ~-1 ~46 ~10 ~-1 ~46 stone 0  
fill ~9 ~-1 ~47 ~21 ~-1 ~47 stone 0  
fill ~9 ~-1 ~48 ~12 ~-1 ~48 stone 0 
setblock ~9 ~-1 ~60 glowstone 0 
setblock ~9 ~-1 ~62 glowstone 0 
setblock ~9 ~-1 ~65 glowstone 0 
setblock ~9 ~-1 ~115 glowstone 0 
setblock ~9 ~-1 ~128 glowstone 0 
setblock ~9 ~-1 ~130 glowstone 0  
fill ~9 ~-1 ~131 ~22 ~-1 ~131 stone 0 
setblock ~9 ~-1 ~132 glowstone 0  
fill ~9 ~-1 ~133 ~12 ~-1 ~133 stone 0  
fill ~9 ~-1 ~134 ~21 ~-1 ~134 stone 0  
fill ~9 ~-1 ~135 ~21 ~-1 ~135 stone 0 
setblock ~9 ~-1 ~136 glowstone 0  
fill ~9 ~-1 ~137 ~21 ~-1 ~137 stone 0  
fill ~9 ~-1 ~138 ~21 ~-1 ~138 stone 0  
fill ~9 ~-1 ~139 ~9 ~-1 ~143 stone 0 
setblock ~9 ~-1 ~144 obsidian 0  
fill ~10 ~-1 ~34 ~11 ~-1 ~34 nether_brick 0  
fill ~10 ~-1 ~35 ~10 ~1 ~35 nether_brick 0  
fill ~10 ~-1 ~36 ~10 ~1 ~36 nether_brick 0  
fill ~10 ~-1 ~37 ~10 ~1 ~37 nether_brick 0  
fill ~10 ~-1 ~38 ~10 ~-1 ~34 nether_brick 0  
fill ~10 ~-1 ~40 ~11 ~-1 ~40 stone 0  
fill ~10 ~-1 ~41 ~11 ~-1 ~41 stone 0  
fill ~10 ~-1 ~42 ~20 ~-1 ~42 stone 0  
fill ~10 ~-1 ~43 ~10 ~-1 ~53 stone 0 
setblock ~10 ~-1 ~54 glowstone 0 
setblock ~10 ~-1 ~56 glowstone 0 
setblock ~10 ~-1 ~58 glowstone 0  
fill ~10 ~-1 ~60 ~20 ~-1 ~60 stone 0  
fill ~10 ~-1 ~62 ~20 ~-1 ~62 stone 0  
fill ~10 ~-1 ~65 ~12 ~-1 ~65 stone 0  
fill ~10 ~-1 ~115 ~12 ~-1 ~115 stone 0  
fill ~10 ~-1 ~128 ~20 ~-1 ~128 stone 0  
fill ~10 ~-1 ~130 ~20 ~-1 ~130 stone 0  
fill ~10 ~-1 ~132 ~20 ~-1 ~132 stone 0  
fill ~10 ~-1 ~136 ~11 ~-1 ~136 stone 0  
fill ~10 ~-1 ~139 ~10 ~-2 ~139 nether_brick 0  
fill ~10 ~-1 ~140 ~10 ~-1 ~141 nether_brick 0 
setblock ~10 ~-1 ~144 iron_bars 0  
fill ~11 ~-1 ~28 ~12 ~-1 ~28 nether_brick 0  
fill ~11 ~-1 ~29 ~11 ~1 ~29 nether_brick 0  
fill ~11 ~-1 ~30 ~11 ~1 ~30 nether_brick 0  
fill ~11 ~-1 ~31 ~11 ~1 ~31 nether_brick 0  
fill ~11 ~-1 ~32 ~11 ~1 ~32 nether_brick 0  
fill ~11 ~-1 ~33 ~11 ~-1 ~28 nether_brick 0  
fill ~11 ~-1 ~35 ~12 ~-1 ~35 stone 0  
fill ~11 ~-1 ~36 ~19 ~-1 ~36 stone 0  
fill ~11 ~-1 ~37 ~19 ~-1 ~37 stone 0  
fill ~11 ~-1 ~38 ~19 ~-1 ~38 stone 0  
fill ~11 ~-1 ~39 ~11 ~-1 ~35 stone 0  
fill ~11 ~-1 ~43 ~11 ~-1 ~46 glowstone 0  
fill ~11 ~-1 ~54 ~19 ~-1 ~54 stone 0  
fill ~11 ~-1 ~56 ~14 ~-1 ~56 stone 0  
fill ~11 ~-1 ~58 ~19 ~-1 ~58 stone 0  
fill ~11 ~-1 ~139 ~19 ~-1 ~139 stone 0  
fill ~11 ~-1 ~140 ~19 ~-1 ~140 stone 0 
setblock ~11 ~-1 ~141 glowstone 0  
fill ~11 ~-1 ~142 ~11 ~-1 ~143 nether_brick 0  
fill ~12 ~-1 ~24 ~13 ~-1 ~24 nether_brick 0  
fill ~12 ~-1 ~25 ~12 ~1 ~25 nether_brick 0  
fill ~12 ~-1 ~26 ~12 ~1 ~26 nether_brick 0  
fill ~12 ~-1 ~27 ~12 ~1 ~27 nether_brick 0  
fill ~12 ~-1 ~29 ~17 ~-1 ~29 stone 0  
fill ~12 ~-1 ~30 ~18 ~-1 ~30 stone 0  
fill ~12 ~-1 ~31 ~18 ~-1 ~31 stone 0  
fill ~12 ~-1 ~32 ~12 ~-1 ~38 stone 0  
fill ~12 ~-1 ~39 ~12 ~-1 ~41 glowstone 0  
fill ~12 ~-1 ~43 ~18 ~-1 ~43 stone 0  
fill ~12 ~-1 ~44 ~18 ~-1 ~44 stone 0  
fill ~12 ~-1 ~45 ~18 ~-1 ~45 stone 0  
fill ~12 ~-1 ~46 ~14 ~-1 ~46 stone 0 
setblock ~12 ~-1 ~136 glowstone 0  
fill ~12 ~-1 ~141 ~14 ~-1 ~141 stone 0  
fill ~12 ~-1 ~142 ~18 ~-1 ~142 stone 0 
setblock ~12 ~-1 ~143 glowstone 0  
fill ~12 ~-1 ~144 ~12 ~0 ~144 nether_brick 0 
setblock ~12 ~-1 ~149 iron_bars 0  
fill ~13 ~-1 ~19 ~14 ~-1 ~19 nether_brick 0  
fill ~13 ~-1 ~20 ~13 ~1 ~20 nether_brick 0  
fill ~13 ~-1 ~21 ~13 ~1 ~21 nether_brick 0  
fill ~13 ~-1 ~22 ~13 ~1 ~22 nether_brick 0  
fill ~13 ~-1 ~23 ~13 ~-1 ~19 nether_brick 0  
fill ~13 ~-1 ~25 ~17 ~-1 ~25 stone 0  
fill ~13 ~-1 ~26 ~17 ~-1 ~26 stone 0  
fill ~13 ~-1 ~27 ~14 ~-1 ~27 stone 0  
fill ~13 ~-1 ~28 ~17 ~-1 ~28 stone 0  
fill ~13 ~-1 ~32 ~13 ~-1 ~35 glowstone 0  
fill ~13 ~-1 ~39 ~17 ~-1 ~39 stone 0  
fill ~13 ~-1 ~40 ~17 ~-1 ~40 stone 0  
fill ~13 ~-1 ~41 ~17 ~-1 ~41 stone 0 
setblock ~13 ~-1 ~48 glowstone 0 
setblock ~13 ~-1 ~53 glowstone 0 
setblock ~13 ~-1 ~57 glowstone 0 
setblock ~13 ~-1 ~65 glowstone 0 
setblock ~13 ~-1 ~115 glowstone 0 
setblock ~13 ~-1 ~120 glowstone 0 
setblock ~13 ~-1 ~124 glowstone 0 
setblock ~13 ~-1 ~129 glowstone 0 
setblock ~13 ~-1 ~133 glowstone 0  
fill ~13 ~-1 ~136 ~17 ~-1 ~136 stone 0  
fill ~13 ~-1 ~143 ~17 ~-1 ~143 stone 0  
fill ~13 ~-1 ~144 ~17 ~-1 ~144 stone 0  
fill ~13 ~-1 ~145 ~17 ~-1 ~145 nether_brick 0 
setblock ~13 ~-1 ~148 stone 0 
setblock ~13 ~-1 ~149 obsidian 0 
setblock ~13 ~-1 ~152 nether_brick_stairs 6  
fill ~13 ~-1 ~153 ~13 ~1 ~153 nether_brick 0  
fill ~14 ~-1 ~13 ~14 ~1 ~13 nether_brick 0  
fill ~14 ~-1 ~14 ~16 ~-1 ~14 nether_brick 0  
fill ~14 ~-1 ~15 ~16 ~-1 ~15 nether_brick 0  
fill ~14 ~-1 ~16 ~14 ~1 ~16 nether_brick 0  
fill ~14 ~-1 ~17 ~14 ~1 ~17 nether_brick 0  
fill ~14 ~-1 ~18 ~14 ~1 ~18 nether_brick 0  
fill ~14 ~-1 ~20 ~14 ~-1 ~144 stone 0  
fill ~14 ~-1 ~146 ~17 ~-1 ~146 nether_brick 0 
setblock ~14 ~-1 ~149 iron_bars 0  
fill ~15 ~-1 ~11 ~15 ~1 ~11 nether_brick 0  
fill ~15 ~-1 ~16 ~15 ~-1 ~19 stone 0  
fill ~15 ~-1 ~20 ~15 ~-1 ~21 glowstone 0  
fill ~15 ~-1 ~22 ~16 ~-1 ~22 stone 0  
fill ~15 ~-1 ~23 ~16 ~-1 ~23 stone 0  
fill ~15 ~-1 ~24 ~16 ~-1 ~24 stone 0 
setblock ~15 ~-1 ~27 glowstone 0  
fill ~15 ~-1 ~32 ~16 ~-1 ~32 stone 0  
fill ~15 ~-1 ~33 ~16 ~-1 ~33 stone 0  
fill ~15 ~-1 ~34 ~16 ~-1 ~34 stone 0  
fill ~15 ~-1 ~35 ~16 ~-1 ~35 stone 0 
setblock ~15 ~-1 ~46 piston 1  
fill ~15 ~-1 ~48 ~16 ~-1 ~48 stone 0  
fill ~15 ~-1 ~53 ~16 ~-1 ~53 stone 0 
setblock ~15 ~-1 ~56 piston 1  
fill ~15 ~-1 ~57 ~16 ~-1 ~57 stone 0  
fill ~15 ~-1 ~65 ~16 ~-1 ~65 stone 0  
fill ~15 ~-1 ~115 ~16 ~-1 ~115 stone 0  
fill ~15 ~-1 ~120 ~16 ~-1 ~120 stone 0 
setblock ~15 ~-1 ~123 piston 1  
fill ~15 ~-1 ~124 ~16 ~-1 ~124 stone 0  
fill ~15 ~-1 ~129 ~16 ~-1 ~129 stone 0  
fill ~15 ~-1 ~133 ~16 ~-1 ~133 stone 0 
setblock ~15 ~-1 ~141 glowstone 0  
fill ~16 ~-1 ~13 ~16 ~1 ~13 nether_brick 0  
fill ~16 ~-1 ~16 ~16 ~1 ~16 nether_brick 0  
fill ~16 ~-1 ~17 ~16 ~1 ~17 nether_brick 0  
fill ~16 ~-1 ~18 ~16 ~1 ~18 nether_brick 0  
fill ~16 ~-1 ~19 ~17 ~-1 ~19 nether_brick 0  
fill ~16 ~-1 ~20 ~16 ~-1 ~144 stone 0 
setblock ~16 ~-1 ~149 iron_bars 0  
fill ~17 ~-1 ~20 ~17 ~1 ~20 nether_brick 0  
fill ~17 ~-1 ~21 ~17 ~1 ~21 nether_brick 0  
fill ~17 ~-1 ~22 ~17 ~1 ~22 nether_brick 0  
fill ~17 ~-1 ~23 ~17 ~-1 ~24 nether_brick 0 
setblock ~17 ~-1 ~27 stone 0  
fill ~17 ~-1 ~32 ~17 ~-1 ~35 glowstone 0  
fill ~17 ~-1 ~46 ~18 ~-1 ~46 stone 0 
setblock ~17 ~-1 ~48 glowstone 0 
setblock ~17 ~-1 ~53 glowstone 0  
fill ~17 ~-1 ~56 ~19 ~-1 ~56 stone 0 
setblock ~17 ~-1 ~57 glowstone 0 
setblock ~17 ~-1 ~65 glowstone 0 
setblock ~17 ~-1 ~115 glowstone 0 
setblock ~17 ~-1 ~120 glowstone 0  
fill ~17 ~-1 ~123 ~24 ~-1 ~123 stone 0 
setblock ~17 ~-1 ~124 glowstone 0 
setblock ~17 ~-1 ~129 glowstone 0 
setblock ~17 ~-1 ~133 glowstone 0  
fill ~17 ~-1 ~141 ~18 ~-1 ~141 stone 0 
setblock ~17 ~-1 ~148 stone 0 
setblock ~17 ~-1 ~149 obsidian 0 
setblock ~17 ~-1 ~152 nether_brick_stairs 6  
fill ~17 ~-1 ~153 ~17 ~1 ~153 nether_brick 0  
fill ~18 ~-1 ~24 ~18 ~1 ~24 nether_brick 0  
fill ~18 ~-1 ~25 ~18 ~1 ~25 nether_brick 0  
fill ~18 ~-1 ~26 ~18 ~1 ~26 nether_brick 0  
fill ~18 ~-1 ~27 ~18 ~1 ~27 nether_brick 0  
fill ~18 ~-1 ~28 ~19 ~-1 ~28 nether_brick 0  
fill ~18 ~-1 ~29 ~19 ~-1 ~29 nether_brick 0  
fill ~18 ~-1 ~32 ~18 ~-1 ~38 stone 0   
fill ~18 ~-1 ~39 ~18 ~-1 ~41 glowstone 0  
fill ~18 ~-1 ~48 ~21 ~-1 ~48 stone 0  
fill ~18 ~-1 ~53 ~20 ~-1 ~53 stone 0  
fill ~18 ~-1 ~57 ~23 ~-1 ~57 stone 0  
fill ~18 ~-1 ~65 ~20 ~-1 ~65 stone 0  
fill ~18 ~-1 ~115 ~20 ~-1 ~115 stone 0  
fill ~18 ~-1 ~118 ~19 ~-1 ~118 glowstone 0  
fill ~18 ~-1 ~120 ~25 ~-1 ~120 stone 0  
fill ~18 ~-1 ~124 ~24 ~-1 ~124 stone 0  
fill ~18 ~-1 ~129 ~23 ~-1 ~129 stone 0  
fill ~18 ~-1 ~133 ~22 ~-1 ~133 stone 0 
setblock ~18 ~-1 ~136 glowstone 0 
setblock ~18 ~-1 ~143 glowstone 0  
fill ~18 ~-1 ~144 ~18 ~0 ~144 nether_brick 0 
setblock ~18 ~-1 ~149 iron_bars 0  
fill ~19 ~-1 ~30 ~19 ~1 ~30 nether_brick 0  
fill ~19 ~-1 ~31 ~19 ~1 ~31 nether_brick 0  
fill ~19 ~-1 ~32 ~19 ~1 ~32 nether_brick 0  
fill ~19 ~-1 ~33 ~19 ~-1 ~34 nether_brick 0 
setblock ~19 ~-1 ~35 stone 0  
fill ~19 ~-1 ~39 ~19 ~-1 ~42 stone 0  
fill ~19 ~-1 ~43 ~19 ~-1 ~46 glowstone 0  
fill ~19 ~-1 ~136 ~20 ~-1 ~136 stone 0 
setblock ~19 ~-1 ~141 glowstone 0  
fill ~19 ~-1 ~142 ~19 ~-1 ~143 nether_brick 0  
fill ~20 ~-1 ~34 ~20 ~1 ~34 nether_brick 0  
fill ~20 ~-1 ~35 ~20 ~1 ~35 nether_brick 0  
fill ~20 ~-1 ~36 ~20 ~1 ~36 nether_brick 0  
fill ~20 ~-1 ~37 ~20 ~1 ~37 nether_brick 0  
fill ~20 ~-1 ~38 ~20 ~-1 ~39 nether_brick 0  
fill ~20 ~-1 ~40 ~20 ~-1 ~53 stone 0 
setblock ~20 ~-1 ~54 glowstone 0 
setblock ~20 ~-1 ~56 glowstone 0 
setblock ~20 ~-1 ~58 glowstone 0  
fill ~20 ~-1 ~118 ~25 ~-1 ~118 stone 0  
fill ~20 ~-1 ~139 ~20 ~-1 ~141 nether_brick 0 
setblock ~20 ~-1 ~145 iron_bars 0  
fill ~21 ~-1 ~39 ~21 ~1 ~39 nether_brick 0  
fill ~21 ~-1 ~40 ~21 ~1 ~40 nether_brick 0  
fill ~21 ~-1 ~41 ~21 ~1 ~41 nether_brick 0  
fill ~21 ~-1 ~42 ~21 ~1 ~42 nether_brick 0  
fill ~21 ~-1 ~43 ~21 ~-1 ~44 nether_brick 0  
fill ~21 ~-1 ~45 ~21 ~-1 ~52 stone 0 
setblock ~21 ~-1 ~53 glowstone 0  
fill ~21 ~-1 ~54 ~23 ~-1 ~54 stone 0  
fill ~21 ~-1 ~56 ~23 ~-1 ~56 stone 0  
fill ~21 ~-1 ~58 ~24 ~-1 ~58 stone 0 
setblock ~21 ~-1 ~60 glowstone 0 
setblock ~21 ~-1 ~62 glowstone 0 
setblock ~21 ~-1 ~65 glowstone 0 
setblock ~21 ~-1 ~115 glowstone 0 
setblock ~21 ~-1 ~128 glowstone 0 
setblock ~21 ~-1 ~130 glowstone 0 
setblock ~21 ~-1 ~132 glowstone 0 
setblock ~21 ~-1 ~136 glowstone 0  
fill ~21 ~-1 ~139 ~21 ~-1 ~144 stone 0 
setblock ~21 ~-1 ~145 wool 15  
fill ~22 ~-1 ~44 ~22 ~1 ~44 nether_brick 0  
fill ~22 ~-1 ~45 ~22 ~1 ~45 nether_brick 0  
fill ~22 ~-1 ~46 ~22 ~1 ~46 nether_brick 0  
fill ~22 ~-1 ~47 ~22 ~-1 ~48 nether_brick 0 
setblock ~22 ~-1 ~53 stone 0  
fill ~22 ~-1 ~60 ~24 ~-1 ~60 stone 0  
fill ~22 ~-1 ~62 ~24 ~-1 ~62 stone 0  
fill ~22 ~-1 ~65 ~25 ~-1 ~65 stone 0  
fill ~22 ~-1 ~115 ~25 ~-1 ~115 stone 0  
fill ~22 ~-1 ~128 ~23 ~-1 ~128 stone 0 
setblock ~22 ~-1 ~130 stone 0 
setblock ~22 ~-1 ~132 stone 0  
fill ~22 ~-1 ~134 ~23 ~-1 ~134 nether_brick 0  
fill ~22 ~-1 ~135 ~22 ~-1 ~137 nether_brick 0 
setblock ~22 ~-1 ~145 iron_bars 0  
fill ~23 ~-1 ~48 ~23 ~1 ~48 nether_brick 0  
fill ~23 ~-1 ~49 ~23 ~1 ~49 nether_brick 0  
fill ~23 ~-1 ~50 ~23 ~1 ~50 nether_brick 0  
fill ~23 ~-1 ~51 ~23 ~1 ~51 nether_brick 0  
fill ~23 ~-1 ~52 ~23 ~-1 ~53 nether_brick 0  
fill ~23 ~-1 ~68 ~23 ~-1 ~71 glowstone 0  
fill ~23 ~-1 ~114 ~23 ~1 ~114 stonebrick 0  
fill ~23 ~-1 ~130 ~24 ~-1 ~130 nether_brick 0  
fill ~23 ~-1 ~131 ~23 ~-1 ~134 nether_brick 0  
fill ~24 ~-1 ~53 ~24 ~1 ~53 nether_brick 0  
fill ~24 ~-1 ~54 ~24 ~1 ~54 nether_brick 0  
fill ~24 ~-1 ~55 ~24 ~1 ~55 nether_brick 0  
fill ~24 ~-1 ~56 ~25 ~-1 ~56 nether_brick 0  
fill ~24 ~-1 ~57 ~25 ~-1 ~57 nether_brick 0  
fill ~24 ~-1 ~68 ~26 ~-1 ~68 nether_brick 0  
fill ~24 ~-1 ~69 ~26 ~-1 ~69 nether_brick 0  
fill ~24 ~-1 ~70 ~24 ~-1 ~114 nether_brick 0  
fill ~24 ~-1 ~127 ~24 ~-1 ~130 nether_brick 0  
fill ~25 ~-1 ~58 ~25 ~1 ~58 nether_brick 0  
fill ~25 ~-1 ~59 ~25 ~1 ~59 nether_brick 0  
fill ~25 ~-1 ~60 ~26 ~-1 ~60 nether_brick 0  
fill ~25 ~-1 ~61 ~26 ~-1 ~61 nether_brick 0  
fill ~25 ~-1 ~62 ~26 ~-1 ~62 nether_brick 0  
fill ~25 ~-1 ~66 ~26 ~-1 ~66 nether_brick 0 
setblock ~25 ~-1 ~67 glowstone 0 
setblock ~25 ~-1 ~70 glowstone 0  
fill ~25 ~-1 ~71 ~26 ~-1 ~71 nether_brick 0  
fill ~25 ~-1 ~72 ~26 ~-1 ~72 nether_brick 0  
fill ~25 ~-1 ~73 ~26 ~-1 ~73 nether_brick 0 
setblock ~25 ~-1 ~74 glowstone 0  
fill ~25 ~-1 ~75 ~26 ~-1 ~75 nether_brick 0  
fill ~25 ~-1 ~76 ~26 ~-1 ~76 nether_brick 0  
fill ~25 ~-1 ~77 ~26 ~-1 ~77 nether_brick 0  
fill ~25 ~-1 ~78 ~26 ~-1 ~78 nether_brick 0 
setblock ~25 ~-1 ~79 glowstone 0  
fill ~25 ~-1 ~80 ~26 ~-1 ~80 nether_brick 0  
fill ~25 ~-1 ~81 ~26 ~-1 ~81 nether_brick 0  
fill ~25 ~-1 ~82 ~26 ~-1 ~82 nether_brick 0  
fill ~25 ~-1 ~83 ~26 ~-1 ~83 nether_brick 0  
fill ~25 ~-1 ~84 ~26 ~-1 ~84 nether_brick 0  
fill ~25 ~-1 ~85 ~26 ~-1 ~85 nether_brick 0  
fill ~25 ~-1 ~86 ~26 ~-1 ~86 nether_brick 0 
setblock ~25 ~-1 ~87 glowstone 0  
fill ~25 ~-1 ~88 ~26 ~-1 ~88 nether_brick 0  
fill ~25 ~-1 ~89 ~26 ~-1 ~89 nether_brick 0  
fill ~25 ~-1 ~90 ~26 ~-1 ~90 nether_brick 0  
fill ~25 ~-1 ~91 ~26 ~-1 ~91 nether_brick 0  
fill ~25 ~-1 ~92 ~26 ~-1 ~92 nether_brick 0  
fill ~25 ~-1 ~93 ~26 ~-1 ~93 nether_brick 0  
fill ~25 ~-1 ~94 ~26 ~-1 ~94 nether_brick 0  
fill ~25 ~-1 ~95 ~26 ~-1 ~95 nether_brick 0 
setblock ~25 ~-1 ~96 glowstone 0  
fill ~25 ~-1 ~97 ~26 ~-1 ~97 nether_brick 0  
fill ~25 ~-1 ~98 ~26 ~-1 ~98 nether_brick 0  
fill ~25 ~-1 ~99 ~26 ~-1 ~99 nether_brick 0  
fill ~25 ~-1 ~100 ~26 ~-1 ~100 nether_brick 0  
fill ~25 ~-1 ~101 ~26 ~-1 ~101 nether_brick 0  
fill ~25 ~-1 ~102 ~26 ~-1 ~102 nether_brick 0  
fill ~25 ~-1 ~103 ~26 ~-1 ~103 nether_brick 0 
setblock ~25 ~-1 ~104 glowstone 0  
fill ~25 ~-1 ~105 ~26 ~-1 ~105 nether_brick 0  
fill ~25 ~-1 ~106 ~26 ~-1 ~106 nether_brick 0  
fill ~25 ~-1 ~107 ~26 ~-1 ~107 nether_brick 0  
fill ~25 ~-1 ~108 ~26 ~-1 ~108 nether_brick 0  
fill ~25 ~-1 ~109 ~26 ~-1 ~109 nether_brick 0 
setblock ~25 ~-1 ~110 glowstone 0  
fill ~25 ~-1 ~111 ~26 ~-1 ~111 nether_brick 0  
fill ~25 ~-1 ~112 ~26 ~-1 ~112 nether_brick 0  
fill ~25 ~-1 ~113 ~26 ~-1 ~113 nether_brick 0  
fill ~25 ~-1 ~114 ~26 ~-1 ~114 nether_brick 0 
setblock ~25 ~-1 ~121 glowstone 0  
fill ~25 ~-1 ~122 ~26 ~-1 ~122 nether_brick 0  
fill ~25 ~-1 ~123 ~25 ~-1 ~126 nether_brick 0  
fill ~26 ~-1 ~63 ~26 ~1 ~63 nether_brick 0  
fill ~26 ~-1 ~64 ~26 ~1 ~64 nether_brick 0  
fill ~26 ~-1 ~65 ~26 ~1 ~65 nether_brick 0  
fill ~26 ~-1 ~67 ~26 ~1 ~67 nether_brick 0  
fill ~26 ~-1 ~70 ~26 ~1 ~70 nether_brick 0  
fill ~26 ~-1 ~74 ~26 ~1 ~74 nether_brick 0  
fill ~26 ~-1 ~79 ~26 ~1 ~79 nether_brick 0  
fill ~26 ~-1 ~87 ~26 ~1 ~87 nether_brick 0  
fill ~26 ~-1 ~96 ~26 ~1 ~96 nether_brick 0  
fill ~26 ~-1 ~104 ~26 ~1 ~104 nether_brick 0  
fill ~26 ~-1 ~110 ~26 ~1 ~110 nether_brick 0  
fill ~26 ~-1 ~115 ~26 ~1 ~115 nether_brick 0  
fill ~26 ~-1 ~116 ~26 ~1 ~116 nether_brick 0  
fill ~26 ~-1 ~117 ~26 ~1 ~117 nether_brick 0  
fill ~26 ~-1 ~118 ~26 ~1 ~118 nether_brick 0  
fill ~26 ~-1 ~119 ~26 ~1 ~119 nether_brick 0  
fill ~26 ~-1 ~120 ~26 ~1 ~120 nether_brick 0  
fill ~26 ~-1 ~121 ~26 ~1 ~121 nether_brick 0  
fill ~4 ~0 ~60 ~5 ~0 ~60 nether_brick 0  
fill ~4 ~0 ~61 ~5 ~0 ~61 nether_brick 0  
fill ~4 ~0 ~62 ~4 ~1 ~62 nether_brick 0  
fill ~4 ~0 ~66 ~4 ~1 ~66 nether_brick 0  
fill ~4 ~0 ~68 ~4 ~1 ~68 nether_brick 0  
fill ~4 ~0 ~70 ~4 ~1 ~70 nether_brick 0  
fill ~4 ~0 ~71 ~4 ~1 ~71 nether_brick 0  
fill ~4 ~0 ~72 ~4 ~1 ~72 nether_brick 0  
fill ~4 ~0 ~74 ~4 ~1 ~74 nether_brick 0  
fill ~4 ~0 ~75 ~4 ~1 ~75 nether_brick 0  
fill ~4 ~0 ~77 ~4 ~1 ~77 nether_brick 0  
fill ~4 ~0 ~78 ~4 ~1 ~78 nether_brick 0  
fill ~4 ~0 ~79 ~4 ~1 ~79 nether_brick 0  
fill ~4 ~0 ~81 ~4 ~1 ~81 nether_brick 0  
fill ~4 ~0 ~82 ~4 ~1 ~82 nether_brick 0  
fill ~4 ~0 ~84 ~4 ~1 ~84 nether_brick 0  
fill ~4 ~0 ~85 ~4 ~1 ~85 nether_brick 0  
fill ~4 ~0 ~86 ~4 ~1 ~86 nether_brick 0  
fill ~4 ~0 ~87 ~4 ~1 ~87 nether_brick 0  
fill ~4 ~0 ~89 ~4 ~1 ~89 nether_brick 0  
fill ~4 ~0 ~90 ~4 ~1 ~90 nether_brick 0  
fill ~4 ~0 ~92 ~4 ~1 ~92 nether_brick 0  
fill ~4 ~0 ~93 ~4 ~1 ~93 nether_brick 0  
fill ~4 ~0 ~94 ~4 ~1 ~94 nether_brick 0  
fill ~4 ~0 ~95 ~4 ~1 ~95 nether_brick 0  
fill ~4 ~0 ~97 ~4 ~1 ~97 nether_brick 0  
fill ~4 ~0 ~98 ~4 ~1 ~98 nether_brick 0  
fill ~4 ~0 ~99 ~4 ~1 ~99 nether_brick 0  
fill ~4 ~0 ~100 ~4 ~1 ~100 nether_brick 0  
fill ~4 ~0 ~102 ~4 ~1 ~102 nether_brick 0  
fill ~4 ~0 ~103 ~4 ~1 ~103 nether_brick 0  
fill ~4 ~0 ~104 ~4 ~1 ~104 nether_brick 0  
fill ~4 ~0 ~105 ~4 ~1 ~105 nether_brick 0  
fill ~4 ~0 ~106 ~4 ~1 ~106 nether_brick 0  
fill ~4 ~0 ~107 ~4 ~1 ~107 nether_brick 0  
fill ~4 ~0 ~109 ~4 ~1 ~109 nether_brick 0  
fill ~4 ~0 ~110 ~4 ~1 ~110 nether_brick 0  
fill ~4 ~0 ~111 ~4 ~1 ~111 nether_brick 0  
fill ~4 ~0 ~112 ~4 ~1 ~112 nether_brick 0  
fill ~4 ~0 ~113 ~4 ~1 ~113 nether_brick 0  
fill ~4 ~0 ~114 ~4 ~1 ~114 nether_brick 0  
fill ~4 ~0 ~122 ~4 ~1 ~122 nether_brick 0  
fill ~4 ~0 ~123 ~4 ~1 ~123 nether_brick 0  
fill ~4 ~0 ~124 ~4 ~1 ~124 nether_brick 0  
fill ~4 ~0 ~125 ~4 ~1 ~125 nether_brick 0  
fill ~5 ~0 ~56 ~6 ~0 ~56 nether_brick 0  
fill ~5 ~0 ~57 ~5 ~1 ~57 nether_brick 0  
fill ~5 ~0 ~63 ~5 ~1 ~63 stonebrick 0  
fill ~5 ~0 ~64 ~5 ~1 ~64 stonebrick 0 
setblock ~5 ~0 ~65 stone_pressure_plate 0 
setblock ~5 ~0 ~113 stone_pressure_plate 0 
setblock ~5 ~0 ~114 iron_door 3 
setblock ~5 ~0 ~115 stone_pressure_plate 0  
fill ~5 ~0 ~122 ~5 ~1 ~122 stonebrick 0  
fill ~5 ~0 ~123 ~5 ~0 ~122 stonebrick 0 
setblock ~5 ~0 ~124 stone_brick_stairs 3  
fill ~5 ~0 ~126 ~5 ~1 ~126 nether_brick 0  
fill ~5 ~0 ~127 ~5 ~1 ~127 nether_brick 0  
fill ~5 ~0 ~128 ~5 ~1 ~128 nether_brick 0  
fill ~5 ~0 ~129 ~5 ~1 ~129 nether_brick 0  
fill ~5 ~0 ~130 ~5 ~1 ~130 nether_brick 0  
fill ~6 ~0 ~52 ~6 ~1 ~52 nether_brick 0  
fill ~6 ~0 ~53 ~6 ~1 ~53 nether_brick 0  
fill ~6 ~0 ~57 ~6 ~1 ~57 stonebrick 0  
fill ~6 ~0 ~58 ~6 ~1 ~58 stonebrick 0  
fill ~6 ~0 ~59 ~6 ~1 ~59 stonebrick 0  
fill ~6 ~0 ~60 ~6 ~1 ~60 stonebrick 0  
fill ~6 ~0 ~61 ~6 ~1 ~61 stonebrick 0  
fill ~6 ~0 ~62 ~6 ~1 ~62 stonebrick 0 
setblock ~6 ~0 ~65 iron_door 0  
fill ~6 ~0 ~66 ~10 ~0 ~66 stonebrick 0  
fill ~6 ~0 ~67 ~6 ~1 ~67 stonebrick 0  
fill ~6 ~0 ~68 ~6 ~1 ~68 stonebrick 0  
fill ~6 ~0 ~69 ~6 ~1 ~69 stonebrick 0  
fill ~6 ~0 ~70 ~6 ~1 ~70 stonebrick 0  
fill ~6 ~0 ~71 ~6 ~1 ~71 stonebrick 0  
fill ~6 ~0 ~72 ~10 ~0 ~72 stonebrick 0  
fill ~6 ~0 ~73 ~6 ~1 ~73 stonebrick 0  
fill ~6 ~0 ~74 ~6 ~1 ~74 stonebrick 0  
fill ~6 ~0 ~75 ~6 ~1 ~75 stonebrick 0  
fill ~6 ~0 ~76 ~6 ~1 ~76 stonebrick 0  
fill ~6 ~0 ~77 ~6 ~1 ~77 stonebrick 0  
fill ~6 ~0 ~78 ~10 ~0 ~78 stonebrick 0  
fill ~6 ~0 ~79 ~6 ~1 ~79 stonebrick 0  
fill ~6 ~0 ~80 ~6 ~1 ~80 stonebrick 0  
fill ~6 ~0 ~81 ~6 ~1 ~81 stonebrick 0  
fill ~6 ~0 ~82 ~6 ~1 ~82 stonebrick 0  
fill ~6 ~0 ~83 ~6 ~1 ~83 stonebrick 0  
fill ~6 ~0 ~84 ~10 ~0 ~84 stonebrick 0  
fill ~6 ~0 ~85 ~6 ~1 ~85 stonebrick 0  
fill ~6 ~0 ~86 ~6 ~1 ~86 stonebrick 0  
fill ~6 ~0 ~87 ~6 ~1 ~87 stonebrick 0  
fill ~6 ~0 ~88 ~6 ~1 ~88 stonebrick 0  
fill ~6 ~0 ~89 ~6 ~1 ~89 stonebrick 0  
fill ~6 ~0 ~90 ~10 ~0 ~90 stonebrick 0  
fill ~6 ~0 ~91 ~6 ~1 ~91 stonebrick 0  
fill ~6 ~0 ~92 ~6 ~1 ~92 stonebrick 0  
fill ~6 ~0 ~93 ~6 ~1 ~93 stonebrick 0  
fill ~6 ~0 ~94 ~6 ~1 ~94 stonebrick 0  
fill ~6 ~0 ~95 ~6 ~1 ~95 stonebrick 0  
fill ~6 ~0 ~96 ~10 ~0 ~96 stonebrick 0  
fill ~6 ~0 ~97 ~6 ~1 ~97 stonebrick 0  
fill ~6 ~0 ~98 ~6 ~1 ~98 stonebrick 0  
fill ~6 ~0 ~99 ~6 ~1 ~99 stonebrick 0  
fill ~6 ~0 ~100 ~6 ~1 ~100 stonebrick 0  
fill ~6 ~0 ~101 ~6 ~1 ~101 stonebrick 0  
fill ~6 ~0 ~102 ~10 ~0 ~102 stonebrick 0  
fill ~6 ~0 ~103 ~6 ~1 ~103 stonebrick 0  
fill ~6 ~0 ~104 ~6 ~1 ~104 stonebrick 0  
fill ~6 ~0 ~105 ~6 ~1 ~105 stonebrick 0  
fill ~6 ~0 ~106 ~6 ~1 ~106 stonebrick 0  
fill ~6 ~0 ~107 ~6 ~1 ~107 stonebrick 0  
fill ~6 ~0 ~108 ~10 ~0 ~108 stonebrick 0  
fill ~6 ~0 ~109 ~6 ~1 ~109 stonebrick 0  
fill ~6 ~0 ~110 ~6 ~1 ~110 stonebrick 0  
fill ~6 ~0 ~111 ~6 ~1 ~111 stonebrick 0  
fill ~6 ~0 ~112 ~6 ~1 ~112 stonebrick 0  
fill ~6 ~0 ~113 ~6 ~1 ~113 stonebrick 0  
fill ~6 ~0 ~114 ~10 ~0 ~114 stonebrick 0  
fill ~6 ~0 ~131 ~6 ~1 ~131 nether_brick 0  
fill ~6 ~0 ~132 ~6 ~1 ~132 nether_brick 0  
fill ~6 ~0 ~133 ~6 ~1 ~133 nether_brick 0  
fill ~7 ~0 ~47 ~7 ~1 ~47 nether_brick 0  
fill ~7 ~0 ~48 ~7 ~1 ~48 nether_brick 0  
fill ~7 ~0 ~52 ~7 ~1 ~52 stonebrick 0  
fill ~7 ~0 ~53 ~7 ~1 ~53 stonebrick 0  
fill ~7 ~0 ~61 ~8 ~0 ~61 stone_pressure_plate 0  
fill ~7 ~0 ~62 ~8 ~0 ~62 iron_door 1  
fill ~7 ~0 ~63 ~8 ~0 ~63 stone_pressure_plate 0 
setblock ~7 ~0 ~65 stone_pressure_plate 0  
fill ~7 ~0 ~134 ~7 ~1 ~134 nether_brick 0  
fill ~7 ~0 ~135 ~7 ~1 ~135 nether_brick 0  
fill ~7 ~0 ~136 ~7 ~1 ~136 nether_brick 0  
fill ~7 ~0 ~137 ~7 ~1 ~137 nether_brick 0  
fill ~8 ~0 ~43 ~8 ~1 ~43 nether_brick 0  
fill ~8 ~0 ~44 ~8 ~1 ~44 nether_brick 0  
fill ~8 ~0 ~74 ~10 ~0 ~74 coal_ore 0  
fill ~8 ~0 ~75 ~10 ~0 ~75 coal_ore 0  
fill ~8 ~0 ~76 ~10 ~0 ~76 coal_ore 0  
fill ~8 ~0 ~86 ~10 ~0 ~86 coal_ore 0  
fill ~8 ~0 ~87 ~10 ~0 ~87 coal_ore 0  
fill ~8 ~0 ~88 ~10 ~0 ~88 coal_ore 0  
fill ~8 ~0 ~98 ~10 ~0 ~98 coal_ore 0  
fill ~8 ~0 ~99 ~10 ~0 ~99 coal_ore 0  
fill ~8 ~0 ~100 ~10 ~0 ~100 coal_ore 0  
fill ~8 ~0 ~110 ~10 ~0 ~110 coal_ore 0  
fill ~8 ~0 ~111 ~10 ~0 ~111 coal_ore 0  
fill ~8 ~0 ~112 ~10 ~0 ~112 coal_ore 0  
fill ~8 ~0 ~133 ~9 ~0 ~133 stone_pressure_plate 0  
fill ~8 ~0 ~134 ~9 ~0 ~134 iron_door 1  
fill ~8 ~0 ~135 ~9 ~0 ~135 stone_pressure_plate 0  
fill ~8 ~0 ~138 ~8 ~0 ~140 nether_brick 0  
fill ~9 ~0 ~38 ~9 ~1 ~38 nether_brick 0  
fill ~9 ~0 ~39 ~9 ~1 ~39 nether_brick 0  
fill ~9 ~0 ~43 ~9 ~1 ~43 stonebrick 0  
fill ~9 ~0 ~44 ~9 ~0 ~43 stonebrick 0 
setblock ~9 ~0 ~45 stone_brick_stairs 3  
fill ~9 ~0 ~56 ~10 ~0 ~56 stonebrick 0  
fill ~9 ~0 ~57 ~9 ~1 ~57 stonebrick 0  
fill ~9 ~0 ~58 ~9 ~1 ~58 stonebrick 0  
fill ~9 ~0 ~59 ~9 ~1 ~59 stonebrick 0  
fill ~9 ~0 ~60 ~9 ~1 ~60 stonebrick 0  
fill ~9 ~0 ~61 ~9 ~1 ~61 stonebrick 0  
fill ~9 ~0 ~62 ~14 ~0 ~62 stonebrick 0 
setblock ~9 ~0 ~73 stone_slab 5 
setblock ~9 ~0 ~77 stone_slab 5 
setblock ~9 ~0 ~85 stone_slab 5 
setblock ~9 ~0 ~89 stone_slab 5 
setblock ~9 ~0 ~97 stone_slab 5 
setblock ~9 ~0 ~101 stone_slab 5 
setblock ~9 ~0 ~109 stone_slab 5 
setblock ~9 ~0 ~113 stone_slab 5  
fill ~9 ~0 ~119 ~9 ~1 ~119 stonebrick 0  
fill ~9 ~0 ~120 ~9 ~1 ~120 stonebrick 0  
fill ~9 ~0 ~121 ~9 ~1 ~121 stonebrick 0  
fill ~9 ~0 ~122 ~9 ~1 ~122 stonebrick 0  
fill ~9 ~0 ~123 ~9 ~1 ~123 stonebrick 0  
fill ~9 ~0 ~124 ~9 ~1 ~124 stonebrick 0  
fill ~9 ~0 ~125 ~9 ~1 ~125 stonebrick 0  
fill ~9 ~0 ~126 ~9 ~1 ~126 stonebrick 0  
fill ~9 ~0 ~127 ~11 ~0 ~127 stonebrick 0  
fill ~9 ~0 ~128 ~12 ~0 ~128 stonebrick 0  
fill ~9 ~0 ~129 ~12 ~0 ~129 stonebrick 0  
fill ~9 ~0 ~130 ~21 ~0 ~130 stonebrick 0  
fill ~9 ~0 ~140 ~9 ~0 ~142 nether_brick 0 
setblock ~9 ~0 ~144 iron_bars 0  
fill ~10 ~0 ~33 ~10 ~1 ~33 nether_brick 0  
fill ~10 ~0 ~34 ~10 ~1 ~34 nether_brick 0  
fill ~10 ~0 ~48 ~10 ~1 ~48 stonebrick 0  
fill ~10 ~0 ~49 ~11 ~0 ~49 stonebrick 0  
fill ~10 ~0 ~50 ~10 ~1 ~50 stonebrick 0  
fill ~10 ~0 ~51 ~10 ~1 ~51 stonebrick 0  
fill ~10 ~0 ~52 ~10 ~1 ~52 stonebrick 0  
fill ~10 ~0 ~53 ~10 ~1 ~53 stonebrick 0  
fill ~10 ~0 ~54 ~10 ~1 ~54 stonebrick 0  
fill ~10 ~0 ~55 ~11 ~0 ~55 stonebrick 0  
fill ~10 ~0 ~57 ~11 ~0 ~57 cauldron 0  
fill ~10 ~0 ~58 ~11 ~0 ~58 cauldron 0  
fill ~10 ~0 ~59 ~11 ~0 ~59 cauldron 0  
fill ~10 ~0 ~60 ~11 ~0 ~60 cauldron 0  
fill ~10 ~0 ~61 ~13 ~0 ~61 cauldron 0  
fill ~10 ~0 ~118 ~11 ~0 ~118 stonebrick 0  
fill ~10 ~0 ~119 ~11 ~0 ~119 wool 12  
fill ~10 ~0 ~120 ~11 ~0 ~120 wool 12  
fill ~10 ~0 ~121 ~11 ~0 ~121 wool 12  
fill ~10 ~0 ~122 ~11 ~0 ~122 wool 12  
fill ~10 ~0 ~123 ~11 ~0 ~123 wool 12  
fill ~10 ~0 ~124 ~11 ~0 ~124 wool 12  
fill ~10 ~0 ~125 ~11 ~0 ~125 wool 12  
fill ~10 ~0 ~126 ~11 ~0 ~126 wool 12  
fill ~10 ~0 ~134 ~20 ~0 ~134 stonebrick 0  
fill ~10 ~0 ~140 ~10 ~0 ~141 crafting_table 0  
fill ~10 ~0 ~142 ~10 ~0 ~143 nether_brick 0  
fill ~11 ~0 ~27 ~11 ~1 ~27 nether_brick 0  
fill ~11 ~0 ~28 ~11 ~1 ~28 nether_brick 0  
fill ~11 ~0 ~35 ~11 ~0 ~36 bookshelf 0  
fill ~11 ~0 ~37 ~11 ~1 ~37 stonebrick 0  
fill ~11 ~0 ~44 ~19 ~0 ~44 stonebrick 0  
fill ~11 ~0 ~45 ~11 ~1 ~45 stonebrick 0  
fill ~11 ~0 ~46 ~11 ~1 ~46 stonebrick 0  
fill ~11 ~0 ~47 ~11 ~1 ~47 stonebrick 0 
setblock ~11 ~0 ~48 cauldron 0  
fill ~11 ~0 ~50 ~11 ~1 ~50 wool 12  
fill ~11 ~0 ~51 ~11 ~1 ~51 wool 12  
fill ~11 ~0 ~52 ~11 ~1 ~52 wool 12  
fill ~11 ~0 ~53 ~11 ~1 ~53 wool 12  
fill ~11 ~0 ~54 ~11 ~1 ~54 wool 12 
setblock ~11 ~0 ~56 cauldron 0 
setblock ~11 ~0 ~65 stone_pressure_plate 0 
setblock ~11 ~0 ~66 iron_door 1 
setblock ~11 ~0 ~67 stone_pressure_plate 0 
setblock ~11 ~0 ~71 stone_pressure_plate 0 
setblock ~11 ~0 ~72 iron_door 1 
setblock ~11 ~0 ~73 stone_pressure_plate 0 
setblock ~11 ~0 ~77 stone_pressure_plate 0 
setblock ~11 ~0 ~78 iron_door 1 
setblock ~11 ~0 ~79 stone_pressure_plate 0 
setblock ~11 ~0 ~83 stone_pressure_plate 0 
setblock ~11 ~0 ~84 iron_door 1 
setblock ~11 ~0 ~85 stone_pressure_plate 0 
setblock ~11 ~0 ~89 stone_pressure_plate 0 
setblock ~11 ~0 ~90 iron_door 1 
setblock ~11 ~0 ~91 stone_pressure_plate 0 
setblock ~11 ~0 ~95 stone_pressure_plate 0 
setblock ~11 ~0 ~96 iron_door 1 
setblock ~11 ~0 ~97 stone_pressure_plate 0 
setblock ~11 ~0 ~101 stone_pressure_plate 0 
setblock ~11 ~0 ~102 iron_door 1 
setblock ~11 ~0 ~103 stone_pressure_plate 0 
setblock ~11 ~0 ~107 stone_pressure_plate 0 
setblock ~11 ~0 ~108 iron_door 1 
setblock ~11 ~0 ~109 stone_pressure_plate 0 
setblock ~11 ~0 ~113 stone_pressure_plate 0 
setblock ~11 ~0 ~114 iron_door 1 
setblock ~11 ~0 ~115 stone_pressure_plate 0  
fill ~11 ~0 ~117 ~14 ~0 ~117 stonebrick 0 
setblock ~11 ~0 ~142 crafting_table 0 
setblock ~11 ~0 ~143 nether_brick 0  
fill ~12 ~0 ~23 ~12 ~1 ~23 nether_brick 0  
fill ~12 ~0 ~24 ~12 ~1 ~24 nether_brick 0  
fill ~12 ~0 ~28 ~12 ~1 ~28 cobblestone 0  
fill ~12 ~0 ~29 ~12 ~1 ~29 stone_slab 3  
fill ~12 ~0 ~30 ~12 ~1 ~30 stone_slab 3  
fill ~12 ~0 ~31 ~12 ~1 ~31 stone_slab 3  
fill ~12 ~0 ~32 ~12 ~1 ~32 cobblestone 0  
fill ~12 ~0 ~36 ~13 ~0 ~36 stone_pressure_plate 0  
fill ~12 ~0 ~37 ~13 ~0 ~37 iron_door 3  
fill ~12 ~0 ~38 ~13 ~0 ~38 stone_pressure_plate 0  
fill ~12 ~0 ~45 ~12 ~0 ~47 cauldron 0  
fill ~12 ~0 ~66 ~14 ~0 ~66 stonebrick 0  
fill ~12 ~0 ~72 ~14 ~0 ~72 stonebrick 0  
fill ~12 ~0 ~74 ~14 ~0 ~74 coal_ore 0  
fill ~12 ~0 ~75 ~14 ~0 ~75 coal_ore 0  
fill ~12 ~0 ~76 ~14 ~0 ~76 coal_ore 0  
fill ~12 ~0 ~78 ~14 ~0 ~78 stonebrick 0  
fill ~12 ~0 ~84 ~14 ~0 ~84 stonebrick 0  
fill ~12 ~0 ~86 ~14 ~0 ~86 coal_ore 0  
fill ~12 ~0 ~87 ~14 ~0 ~87 coal_ore 0  
fill ~12 ~0 ~88 ~14 ~0 ~88 coal_ore 0  
fill ~12 ~0 ~90 ~14 ~0 ~90 stonebrick 0  
fill ~12 ~0 ~96 ~14 ~0 ~96 stonebrick 0  
fill ~12 ~0 ~98 ~14 ~0 ~98 coal_ore 0  
fill ~12 ~0 ~99 ~14 ~0 ~99 coal_ore 0  
fill ~12 ~0 ~100 ~14 ~0 ~100 coal_ore 0  
fill ~12 ~0 ~102 ~14 ~0 ~102 stonebrick 0  
fill ~12 ~0 ~108 ~14 ~0 ~108 stonebrick 0  
fill ~12 ~0 ~110 ~14 ~0 ~110 coal_ore 0  
fill ~12 ~0 ~111 ~14 ~0 ~111 coal_ore 0  
fill ~12 ~0 ~112 ~14 ~0 ~112 coal_ore 0  
fill ~12 ~0 ~114 ~14 ~0 ~114 stonebrick 0 
setblock ~12 ~0 ~145 nether_brick 0  
fill ~13 ~0 ~18 ~13 ~1 ~18 nether_brick 0  
fill ~13 ~0 ~19 ~13 ~1 ~19 nether_brick 0 
setblock ~13 ~0 ~25 bookshelf 0  
fill ~13 ~0 ~45 ~17 ~0 ~45 stonebrick 0  
fill ~13 ~0 ~46 ~14 ~0 ~46 stonebrick 0 
setblock ~13 ~0 ~47 cauldron 0  
fill ~13 ~0 ~51 ~13 ~0 ~56 stonebrick 0 
setblock ~13 ~0 ~73 stone_slab 5 
setblock ~13 ~0 ~77 stone_slab 5 
setblock ~13 ~0 ~85 stone_slab 5 
setblock ~13 ~0 ~89 stone_slab 5 
setblock ~13 ~0 ~97 stone_slab 5 
setblock ~13 ~0 ~101 stone_slab 5 
setblock ~13 ~0 ~109 stone_slab 5 
setblock ~13 ~0 ~113 stone_slab 5  
fill ~13 ~0 ~121 ~17 ~0 ~121 stonebrick 0  
fill ~13 ~0 ~122 ~17 ~0 ~122 stonebrick 0  
fill ~13 ~0 ~123 ~14 ~0 ~123 stonebrick 0  
fill ~13 ~0 ~128 ~17 ~0 ~128 cauldron 0  
fill ~13 ~0 ~129 ~17 ~0 ~129 cauldron 0 
setblock ~13 ~0 ~149 iron_bars 0  
fill ~13 ~0 ~152 ~13 ~1 ~152 nether_brick 0  
fill ~14 ~0 ~12 ~14 ~1 ~12 nether_brick 0  
fill ~14 ~0 ~14 ~16 ~0 ~14 nether_brick 0  
fill ~14 ~0 ~15 ~14 ~1 ~15 nether_brick 0  
fill ~14 ~0 ~19 ~14 ~1 ~19 stonebrick 0  
fill ~14 ~0 ~20 ~16 ~0 ~20 crafting_table 0 
setblock ~14 ~0 ~33 crafting_table 0  
fill ~14 ~0 ~37 ~16 ~0 ~37 stonebrick 0  
fill ~14 ~0 ~43 ~16 ~0 ~43 stonebrick 0  
fill ~14 ~0 ~47 ~14 ~1 ~47 stonebrick 0  
fill ~14 ~0 ~51 ~16 ~0 ~51 cauldron 0  
fill ~14 ~0 ~52 ~16 ~0 ~52 cauldron 0  
fill ~14 ~0 ~53 ~17 ~0 ~53 stonebrick 0  
fill ~14 ~0 ~54 ~17 ~0 ~54 stonebrick 0  
fill ~14 ~0 ~55 ~17 ~0 ~55 stonebrick 0  
fill ~14 ~0 ~56 ~14 ~7 ~56 stonebrick 0  
fill ~14 ~0 ~57 ~14 ~1 ~57 stonebrick 0  
fill ~14 ~0 ~61 ~14 ~1 ~61 stonebrick 0  
fill ~14 ~0 ~120 ~16 ~0 ~120 stonebrick 0  
fill ~14 ~0 ~124 ~14 ~6 ~124 stonebrick 0  
fill ~14 ~0 ~142 ~16 ~0 ~142 crafting_table 0  
fill ~14 ~0 ~144 ~16 ~0 ~144 crafting_table 0 
setblock ~14 ~0 ~146 glowstone 0  
fill ~14 ~0 ~147 ~17 ~0 ~147 nether_brick 0  
fill ~15 ~0 ~10 ~15 ~1 ~10 nether_brick 0  
fill ~15 ~0 ~16 ~15 ~1 ~16 glowstone 0  
fill ~15 ~0 ~17 ~15 ~1 ~17 glowstone 0  
fill ~15 ~0 ~18 ~15 ~1 ~18 glowstone 0  
fill ~15 ~0 ~19 ~15 ~1 ~19 glowstone 0  
fill ~15 ~0 ~46 ~15 ~5 ~46 ladder 3  
fill ~15 ~0 ~56 ~15 ~7 ~56 ladder 3 
setblock ~15 ~0 ~61 stone_pressure_plate 0 
setblock ~15 ~0 ~62 iron_door 3 
setblock ~15 ~0 ~63 stone_pressure_plate 0 
setblock ~15 ~0 ~65 stone_pressure_plate 0 
setblock ~15 ~0 ~66 iron_door 1 
setblock ~15 ~0 ~67 stone_pressure_plate 0 
setblock ~15 ~0 ~71 stone_pressure_plate 0 
setblock ~15 ~0 ~72 iron_door 1 
setblock ~15 ~0 ~73 stone_pressure_plate 0 
setblock ~15 ~0 ~77 stone_pressure_plate 0 
setblock ~15 ~0 ~78 iron_door 1 
setblock ~15 ~0 ~79 stone_pressure_plate 0 
setblock ~15 ~0 ~83 stone_pressure_plate 0 
setblock ~15 ~0 ~84 iron_door 1 
setblock ~15 ~0 ~85 stone_pressure_plate 0 
setblock ~15 ~0 ~89 stone_pressure_plate 0 
setblock ~15 ~0 ~90 iron_door 1 
setblock ~15 ~0 ~91 stone_pressure_plate 0 
setblock ~15 ~0 ~95 stone_pressure_plate 0 
setblock ~15 ~0 ~96 iron_door 1 
setblock ~15 ~0 ~97 stone_pressure_plate 0 
setblock ~15 ~0 ~101 stone_pressure_plate 0 
setblock ~15 ~0 ~102 iron_door 1 
setblock ~15 ~0 ~103 stone_pressure_plate 0 
setblock ~15 ~0 ~107 stone_pressure_plate 0 
setblock ~15 ~0 ~108 iron_door 1 
setblock ~15 ~0 ~109 stone_pressure_plate 0 
setblock ~15 ~0 ~113 stone_pressure_plate 0 
setblock ~15 ~0 ~114 iron_door 1  
fill ~15 ~0 ~115 ~15 ~0 ~116 stone_pressure_plate 0 
setblock ~15 ~0 ~117 iron_door 1 
setblock ~15 ~0 ~118 stone_pressure_plate 0  
fill ~15 ~0 ~123 ~15 ~5 ~123 ladder 3  
fill ~16 ~0 ~12 ~16 ~1 ~12 nether_brick 0  
fill ~16 ~0 ~15 ~16 ~1 ~15 nether_brick 0  
fill ~16 ~0 ~19 ~16 ~1 ~19 stonebrick 0 
setblock ~16 ~0 ~33 crafting_table 0  
fill ~16 ~0 ~46 ~17 ~0 ~46 stonebrick 0  
fill ~16 ~0 ~47 ~16 ~1 ~47 stonebrick 0  
fill ~16 ~0 ~56 ~17 ~0 ~56 stonebrick 0  
fill ~16 ~0 ~57 ~16 ~1 ~57 stonebrick 0  
fill ~16 ~0 ~61 ~16 ~1 ~61 stonebrick 0  
fill ~16 ~0 ~62 ~21 ~0 ~62 stonebrick 0  
fill ~16 ~0 ~66 ~18 ~0 ~66 stonebrick 0  
fill ~16 ~0 ~72 ~18 ~0 ~72 stonebrick 0  
fill ~16 ~0 ~74 ~18 ~0 ~74 coal_ore 0  
fill ~16 ~0 ~75 ~16 ~0 ~76 coal_ore 0  
fill ~16 ~0 ~78 ~18 ~0 ~78 stonebrick 0  
fill ~16 ~0 ~84 ~18 ~0 ~84 stonebrick 0  
fill ~16 ~0 ~86 ~18 ~0 ~86 coal_ore 0  
fill ~16 ~0 ~87 ~18 ~0 ~87 coal_ore 0  
fill ~16 ~0 ~88 ~18 ~0 ~88 coal_ore 0  
fill ~16 ~0 ~90 ~18 ~0 ~90 stonebrick 0  
fill ~16 ~0 ~96 ~18 ~0 ~96 stonebrick 0  
fill ~16 ~0 ~98 ~18 ~0 ~98 coal_ore 0  
fill ~16 ~0 ~99 ~18 ~0 ~99 coal_ore 0  
fill ~16 ~0 ~100 ~18 ~0 ~100 coal_ore 0  
fill ~16 ~0 ~102 ~18 ~0 ~102 stonebrick 0  
fill ~16 ~0 ~108 ~18 ~0 ~108 stonebrick 0  
fill ~16 ~0 ~110 ~18 ~0 ~110 coal_ore 0  
fill ~16 ~0 ~111 ~18 ~0 ~111 coal_ore 0  
fill ~16 ~0 ~112 ~18 ~0 ~112 coal_ore 0  
fill ~16 ~0 ~114 ~18 ~0 ~114 stonebrick 0  
fill ~16 ~0 ~117 ~19 ~0 ~117 stonebrick 0  
fill ~16 ~0 ~123 ~17 ~0 ~123 stonebrick 0  
fill ~16 ~0 ~124 ~16 ~6 ~124 stonebrick 0 
setblock ~16 ~0 ~146 glowstone 0  
fill ~17 ~0 ~18 ~17 ~1 ~18 nether_brick 0  
fill ~17 ~0 ~19 ~17 ~1 ~19 nether_brick 0 
setblock ~17 ~0 ~25 bookshelf 0  
fill ~17 ~0 ~36 ~18 ~0 ~36 stone_pressure_plate 0  
fill ~17 ~0 ~37 ~18 ~0 ~37 iron_door 3  
fill ~17 ~0 ~38 ~18 ~0 ~38 stone_pressure_plate 0  
fill ~17 ~0 ~47 ~18 ~0 ~47 cauldron 0  
fill ~17 ~0 ~51 ~17 ~0 ~56 stonebrick 0  
fill ~17 ~0 ~61 ~20 ~0 ~61 cauldron 0 
setblock ~17 ~0 ~73 stone_slab 5 
setblock ~17 ~0 ~75 nether_brick_fence 0  
fill ~17 ~0 ~76 ~18 ~0 ~76 coal_ore 0 
setblock ~17 ~0 ~77 stone_slab 5 
setblock ~17 ~0 ~85 stone_slab 5 
setblock ~17 ~0 ~89 stone_slab 5 
setblock ~17 ~0 ~97 stone_slab 5 
setblock ~17 ~0 ~101 stone_slab 5 
setblock ~17 ~0 ~109 stone_slab 5 
setblock ~17 ~0 ~113 stone_slab 5 
setblock ~17 ~0 ~149 iron_bars 0  
fill ~17 ~0 ~152 ~17 ~1 ~152 nether_brick 0  
fill ~18 ~0 ~23 ~18 ~1 ~23 nether_brick 0  
fill ~18 ~0 ~28 ~18 ~1 ~28 cobblestone 0  
fill ~18 ~0 ~29 ~18 ~1 ~29 stone_slab 3  
fill ~18 ~0 ~30 ~18 ~1 ~30 stone_slab 3  
fill ~18 ~0 ~31 ~18 ~1 ~31 stone_slab 3  
fill ~18 ~0 ~32 ~18 ~1 ~32 cobblestone 0  
fill ~18 ~0 ~45 ~18 ~0 ~47 cauldron 0 
setblock ~18 ~0 ~75 coal_ore 0  
fill ~18 ~0 ~128 ~21 ~0 ~128 stonebrick 0  
fill ~18 ~0 ~129 ~21 ~0 ~129 stonebrick 0 
setblock ~18 ~0 ~145 nether_brick 0  
fill ~19 ~0 ~27 ~19 ~1 ~27 nether_brick 0  
fill ~19 ~0 ~28 ~19 ~1 ~28 nether_brick 0  
fill ~19 ~0 ~29 ~19 ~1 ~29 nether_brick 0  
fill ~19 ~0 ~35 ~19 ~0 ~36 bookshelf 0  
fill ~19 ~0 ~37 ~19 ~1 ~37 stonebrick 0  
fill ~19 ~0 ~45 ~19 ~1 ~45 stonebrick 0  
fill ~19 ~0 ~46 ~19 ~1 ~46 stonebrick 0  
fill ~19 ~0 ~47 ~19 ~1 ~47 stonebrick 0 
setblock ~19 ~0 ~48 cauldron 0  
fill ~19 ~0 ~49 ~20 ~0 ~49 stonebrick 0  
fill ~19 ~0 ~50 ~19 ~1 ~50 wool 12  
fill ~19 ~0 ~51 ~19 ~1 ~51 wool 12  
fill ~19 ~0 ~52 ~19 ~1 ~52 wool 12  
fill ~19 ~0 ~53 ~19 ~1 ~53 wool 12  
fill ~19 ~0 ~54 ~19 ~1 ~54 wool 12  
fill ~19 ~0 ~55 ~20 ~0 ~55 stonebrick 0  
fill ~19 ~0 ~56 ~20 ~0 ~56 cauldron 0  
fill ~19 ~0 ~57 ~20 ~0 ~57 cauldron 0  
fill ~19 ~0 ~58 ~20 ~0 ~58 cauldron 0  
fill ~19 ~0 ~59 ~20 ~0 ~59 cauldron 0  
fill ~19 ~0 ~60 ~20 ~0 ~60 cauldron 0 
setblock ~19 ~0 ~65 stone_pressure_plate 0 
setblock ~19 ~0 ~66 iron_door 1 
setblock ~19 ~0 ~67 stone_pressure_plate 0 
setblock ~19 ~0 ~71 stone_pressure_plate 0 
setblock ~19 ~0 ~72 iron_door 1 
setblock ~19 ~0 ~73 stone_pressure_plate 0 
setblock ~19 ~0 ~77 stone_pressure_plate 0 
setblock ~19 ~0 ~78 iron_door 1 
setblock ~19 ~0 ~79 stone_pressure_plate 0 
setblock ~19 ~0 ~83 stone_pressure_plate 0 
setblock ~19 ~0 ~84 iron_door 1 
setblock ~19 ~0 ~85 stone_pressure_plate 0 
setblock ~19 ~0 ~89 stone_pressure_plate 0 
setblock ~19 ~0 ~90 iron_door 1 
setblock ~19 ~0 ~91 stone_pressure_plate 0 
setblock ~19 ~0 ~95 stone_pressure_plate 0 
setblock ~19 ~0 ~96 iron_door 1 
setblock ~19 ~0 ~97 stone_pressure_plate 0 
setblock ~19 ~0 ~101 stone_pressure_plate 0 
setblock ~19 ~0 ~102 iron_door 1 
setblock ~19 ~0 ~103 stone_pressure_plate 0 
setblock ~19 ~0 ~107 stone_pressure_plate 0 
setblock ~19 ~0 ~108 iron_door 1 
setblock ~19 ~0 ~109 stone_pressure_plate 0 
setblock ~19 ~0 ~113 stone_pressure_plate 0 
setblock ~19 ~0 ~114 iron_door 1 
setblock ~19 ~0 ~115 stone_pressure_plate 0  
fill ~19 ~0 ~118 ~20 ~0 ~118 stonebrick 0  
fill ~19 ~0 ~119 ~20 ~0 ~119 wool 12  
fill ~19 ~0 ~120 ~20 ~0 ~120 wool 12  
fill ~19 ~0 ~121 ~20 ~0 ~121 wool 12  
fill ~19 ~0 ~122 ~20 ~0 ~122 wool 12  
fill ~19 ~0 ~123 ~20 ~0 ~123 wool 12  
fill ~19 ~0 ~124 ~20 ~0 ~124 wool 12  
fill ~19 ~0 ~125 ~20 ~0 ~125 wool 12  
fill ~19 ~0 ~126 ~20 ~0 ~126 wool 12  
fill ~19 ~0 ~127 ~21 ~0 ~127 stonebrick 0 
setblock ~19 ~0 ~142 crafting_table 0  
fill ~19 ~0 ~143 ~20 ~0 ~143 nether_brick 0  
fill ~20 ~0 ~33 ~20 ~1 ~33 nether_brick 0  
fill ~20 ~0 ~48 ~20 ~1 ~48 stonebrick 0  
fill ~20 ~0 ~50 ~20 ~1 ~50 stonebrick 0  
fill ~20 ~0 ~51 ~20 ~1 ~51 stonebrick 0  
fill ~20 ~0 ~52 ~20 ~1 ~52 stonebrick 0  
fill ~20 ~0 ~53 ~20 ~1 ~53 stonebrick 0  
fill ~20 ~0 ~54 ~20 ~1 ~54 stonebrick 0  
fill ~20 ~0 ~66 ~24 ~0 ~66 stonebrick 0  
fill ~20 ~0 ~72 ~24 ~0 ~72 stonebrick 0  
fill ~20 ~0 ~74 ~22 ~0 ~74 coal_ore 0  
fill ~20 ~0 ~75 ~20 ~0 ~76 coal_ore 0  
fill ~20 ~0 ~78 ~24 ~0 ~78 stonebrick 0  
fill ~20 ~0 ~84 ~24 ~0 ~84 stonebrick 0  
fill ~20 ~0 ~86 ~22 ~0 ~86 coal_ore 0  
fill ~20 ~0 ~87 ~22 ~0 ~87 coal_ore 0  
fill ~20 ~0 ~88 ~22 ~0 ~88 coal_ore 0  
fill ~20 ~0 ~90 ~24 ~0 ~90 stonebrick 0  
fill ~20 ~0 ~96 ~24 ~0 ~96 stonebrick 0  
fill ~20 ~0 ~98 ~22 ~0 ~98 coal_ore 0  
fill ~20 ~0 ~99 ~22 ~0 ~99 coal_ore 0  
fill ~20 ~0 ~100 ~22 ~0 ~100 coal_ore 0  
fill ~20 ~0 ~102 ~24 ~0 ~102 stonebrick 0  
fill ~20 ~0 ~108 ~24 ~0 ~108 stonebrick 0  
fill ~20 ~0 ~110 ~22 ~0 ~110 coal_ore 0  
fill ~20 ~0 ~111 ~22 ~0 ~111 coal_ore 0  
fill ~20 ~0 ~112 ~22 ~0 ~112 coal_ore 0  
fill ~20 ~0 ~114 ~24 ~0 ~114 stonebrick 0  
fill ~20 ~0 ~140 ~20 ~0 ~141 crafting_table 0  
fill ~20 ~0 ~142 ~21 ~0 ~142 nether_brick 0  
fill ~21 ~0 ~38 ~21 ~1 ~38 nether_brick 0  
fill ~21 ~0 ~43 ~21 ~1 ~43 stonebrick 0  
fill ~21 ~0 ~44 ~21 ~0 ~43 stonebrick 0 
setblock ~21 ~0 ~45 stone_brick_stairs 3  
fill ~21 ~0 ~56 ~21 ~1 ~56 stonebrick 0  
fill ~21 ~0 ~57 ~21 ~1 ~57 stonebrick 0  
fill ~21 ~0 ~58 ~21 ~1 ~58 stonebrick 0  
fill ~21 ~0 ~59 ~21 ~1 ~59 stonebrick 0  
fill ~21 ~0 ~60 ~21 ~1 ~60 stonebrick 0  
fill ~21 ~0 ~61 ~21 ~1 ~61 stonebrick 0 
setblock ~21 ~0 ~73 stone_slab 5 
setblock ~21 ~0 ~75 nether_brick_fence 0  
fill ~21 ~0 ~76 ~22 ~0 ~76 coal_ore 0 
setblock ~21 ~0 ~77 stone_slab 5 
setblock ~21 ~0 ~85 stone_slab 5 
setblock ~21 ~0 ~89 stone_slab 5 
setblock ~21 ~0 ~97 stone_slab 5 
setblock ~21 ~0 ~101 stone_slab 5 
setblock ~21 ~0 ~109 stone_slab 5 
setblock ~21 ~0 ~113 stone_slab 5  
fill ~21 ~0 ~119 ~21 ~1 ~119 stonebrick 0  
fill ~21 ~0 ~120 ~21 ~1 ~120 stonebrick 0  
fill ~21 ~0 ~121 ~21 ~1 ~121 stonebrick 0  
fill ~21 ~0 ~122 ~21 ~1 ~122 stonebrick 0  
fill ~21 ~0 ~123 ~21 ~1 ~123 stonebrick 0  
fill ~21 ~0 ~124 ~21 ~1 ~124 stonebrick 0  
fill ~21 ~0 ~125 ~21 ~1 ~125 stonebrick 0  
fill ~21 ~0 ~126 ~21 ~1 ~126 stonebrick 0  
fill ~21 ~0 ~133 ~22 ~0 ~133 stone_pressure_plate 0  
fill ~21 ~0 ~134 ~22 ~0 ~134 iron_door 1  
fill ~21 ~0 ~135 ~22 ~0 ~135 stone_pressure_plate 0  
fill ~21 ~0 ~140 ~22 ~0 ~140 nether_brick 0  
fill ~21 ~0 ~141 ~21 ~0 ~140 nether_brick 0 
setblock ~21 ~0 ~145 iron_bars 0  
fill ~22 ~0 ~43 ~22 ~1 ~43 nether_brick 0  
fill ~22 ~0 ~61 ~23 ~0 ~61 stone_pressure_plate 0  
fill ~22 ~0 ~62 ~23 ~0 ~62 iron_door 1  
fill ~22 ~0 ~63 ~23 ~0 ~63 stone_pressure_plate 0 
setblock ~22 ~0 ~75 coal_ore 0  
fill ~22 ~0 ~137 ~22 ~0 ~140 nether_brick 0  
fill ~23 ~0 ~47 ~23 ~1 ~47 nether_brick 0  
fill ~23 ~0 ~52 ~23 ~1 ~52 stonebrick 0  
fill ~23 ~0 ~53 ~23 ~1 ~53 stonebrick 0 
setblock ~23 ~0 ~65 stone_pressure_plate 0  
fill ~23 ~0 ~134 ~23 ~1 ~134 nether_brick 0  
fill ~23 ~0 ~135 ~23 ~1 ~135 nether_brick 0  
fill ~23 ~0 ~136 ~23 ~1 ~136 nether_brick 0  
fill ~24 ~0 ~52 ~24 ~1 ~52 nether_brick 0  
fill ~24 ~0 ~56 ~25 ~0 ~56 nether_brick 0  
fill ~24 ~0 ~57 ~24 ~1 ~57 stonebrick 0  
fill ~24 ~0 ~58 ~24 ~1 ~58 stonebrick 0  
fill ~24 ~0 ~59 ~24 ~1 ~59 stonebrick 0  
fill ~24 ~0 ~60 ~24 ~1 ~60 stonebrick 0  
fill ~24 ~0 ~61 ~24 ~1 ~61 stonebrick 0  
fill ~24 ~0 ~62 ~25 ~0 ~62 stonebrick 0 
setblock ~24 ~0 ~65 iron_door 2  
fill ~24 ~0 ~67 ~24 ~1 ~67 stonebrick 0  
fill ~24 ~0 ~68 ~24 ~1 ~68 stonebrick 0  
fill ~24 ~0 ~69 ~24 ~1 ~69 stonebrick 0  
fill ~24 ~0 ~70 ~24 ~1 ~70 stonebrick 0  
fill ~24 ~0 ~71 ~24 ~1 ~71 stonebrick 0  
fill ~24 ~0 ~73 ~24 ~1 ~73 stonebrick 0  
fill ~24 ~0 ~74 ~24 ~1 ~74 stonebrick 0  
fill ~24 ~0 ~75 ~24 ~1 ~75 stonebrick 0  
fill ~24 ~0 ~76 ~24 ~1 ~76 stonebrick 0  
fill ~24 ~0 ~77 ~24 ~1 ~77 stonebrick 0  
fill ~24 ~0 ~79 ~24 ~1 ~79 stonebrick 0  
fill ~24 ~0 ~80 ~24 ~1 ~80 stonebrick 0  
fill ~24 ~0 ~81 ~24 ~1 ~81 stonebrick 0  
fill ~24 ~0 ~82 ~24 ~1 ~82 stonebrick 0   
fill ~24 ~0 ~83 ~24 ~1 ~83 stonebrick 0  
fill ~24 ~0 ~85 ~24 ~1 ~85 stonebrick 0  
fill ~24 ~0 ~86 ~24 ~1 ~86 stonebrick 0  
fill ~24 ~0 ~87 ~24 ~1 ~87 stonebrick 0  
fill ~24 ~0 ~88 ~24 ~1 ~88 stonebrick 0  
fill ~24 ~0 ~89 ~24 ~1 ~89 stonebrick 0  
fill ~24 ~0 ~91 ~24 ~1 ~91 stonebrick 0  
fill ~24 ~0 ~92 ~24 ~1 ~92 stonebrick 0  
fill ~24 ~0 ~93 ~24 ~1 ~93 stonebrick 0  
fill ~24 ~0 ~94 ~24 ~1 ~94 stonebrick 0  
fill ~24 ~0 ~95 ~24 ~1 ~95 stonebrick 0  
fill ~24 ~0 ~97 ~24 ~1 ~97 stonebrick 0  
fill ~24 ~0 ~98 ~24 ~1 ~98 stonebrick 0  
fill ~24 ~0 ~99 ~24 ~1 ~99 stonebrick 0  
fill ~24 ~0 ~100 ~24 ~1 ~100 stonebrick 0  
fill ~24 ~0 ~101 ~24 ~1 ~101 stonebrick 0  
fill ~24 ~0 ~103 ~24 ~1 ~103 stonebrick 0  
fill ~24 ~0 ~104 ~24 ~1 ~104 stonebrick 0  
fill ~24 ~0 ~105 ~24 ~1 ~105 stonebrick 0  
fill ~24 ~0 ~106 ~24 ~1 ~106 stonebrick 0  
fill ~24 ~0 ~107 ~24 ~1 ~107 stonebrick 0  
fill ~24 ~0 ~109 ~24 ~1 ~109 stonebrick 0  
fill ~24 ~0 ~110 ~24 ~1 ~110 stonebrick 0  
fill ~24 ~0 ~111 ~24 ~1 ~111 stonebrick 0  
fill ~24 ~0 ~112 ~24 ~1 ~112 stonebrick 0  
fill ~24 ~0 ~113 ~24 ~1 ~113 stonebrick 0  
fill ~24 ~0 ~131 ~24 ~1 ~131 nether_brick 0  
fill ~24 ~0 ~132 ~24 ~1 ~132 nether_brick 0  
fill ~24 ~0 ~133 ~24 ~1 ~133 nether_brick 0  
fill ~25 ~0 ~57 ~25 ~1 ~57 nether_brick 0  
fill ~25 ~0 ~60 ~26 ~0 ~60 nether_brick 0  
fill ~25 ~0 ~61 ~26 ~0 ~61 nether_brick 0  
fill ~25 ~0 ~63 ~25 ~1 ~63 stonebrick 0  
fill ~25 ~0 ~64 ~25 ~1 ~64 stonebrick 0 
setblock ~25 ~0 ~65 stone_pressure_plate 0 
setblock ~25 ~0 ~113 stone_pressure_plate 0 
setblock ~25 ~0 ~114 iron_door 3 
setblock ~25 ~0 ~115 stone_pressure_plate 0  
fill ~25 ~0 ~122 ~25 ~1 ~122 stonebrick 0  
fill ~25 ~0 ~123 ~25 ~0 ~122 stonebrick 0 
setblock ~25 ~0 ~124 stone_brick_stairs 3  
fill ~25 ~0 ~126 ~25 ~1 ~126 nether_brick 0  
fill ~25 ~0 ~127 ~25 ~1 ~127 nether_brick 0  
fill ~25 ~0 ~128 ~25 ~1 ~128 nether_brick 0  
fill ~25 ~0 ~129 ~25 ~1 ~129 nether_brick 0  
fill ~25 ~0 ~130 ~25 ~1 ~130 nether_brick 0  
fill ~26 ~0 ~62 ~26 ~1 ~62 nether_brick 0  
fill ~26 ~0 ~66 ~26 ~1 ~66 nether_brick 0  
fill ~26 ~0 ~68 ~26 ~1 ~68 nether_brick 0  
fill ~26 ~0 ~69 ~26 ~1 ~69 nether_brick 0  
fill ~26 ~0 ~71 ~26 ~1 ~71 nether_brick 0  
fill ~26 ~0 ~72 ~26 ~1 ~72 nether_brick 0  
fill ~26 ~0 ~73 ~26 ~1 ~73 nether_brick 0  
fill ~26 ~0 ~75 ~26 ~1 ~75 nether_brick 0  
fill ~26 ~0 ~76 ~26 ~1 ~76 nether_brick 0  
fill ~26 ~0 ~77 ~26 ~1 ~77 nether_brick 0  
fill ~26 ~0 ~78 ~26 ~1 ~78 nether_brick 0  
fill ~26 ~0 ~80 ~26 ~1 ~80 nether_brick 0  
fill ~26 ~0 ~81 ~26 ~1 ~81 nether_brick 0  
fill ~26 ~0 ~82 ~26 ~1 ~82 nether_brick 0  
fill ~26 ~0 ~83 ~26 ~1 ~83 nether_brick 0  
fill ~26 ~0 ~84 ~26 ~1 ~84 nether_brick 0  
fill ~26 ~0 ~85 ~26 ~1 ~85 nether_brick 0  
fill ~26 ~0 ~86 ~26 ~1 ~86 nether_brick 0  
fill ~26 ~0 ~88 ~26 ~1 ~88 nether_brick 0  
fill ~26 ~0 ~89 ~26 ~1 ~89 nether_brick 0  
fill ~26 ~0 ~90 ~26 ~1 ~90 nether_brick 0  
fill ~26 ~0 ~91 ~26 ~1 ~91 nether_brick 0  
fill ~26 ~0 ~92 ~26 ~1 ~92 nether_brick 0  
fill ~26 ~0 ~93 ~26 ~1 ~93 nether_brick 0  
fill ~26 ~0 ~94 ~26 ~1 ~94 nether_brick 0  
fill ~26 ~0 ~95 ~26 ~1 ~95 nether_brick 0  
fill ~26 ~0 ~97 ~26 ~1 ~97 nether_brick 0  
fill ~26 ~0 ~98 ~26 ~1 ~98 nether_brick 0  
fill ~26 ~0 ~99 ~26 ~1 ~99 nether_brick 0  
fill ~26 ~0 ~100 ~26 ~1 ~100 nether_brick 0  
fill ~26 ~0 ~101 ~26 ~1 ~101 nether_brick 0  
fill ~26 ~0 ~102 ~26 ~1 ~102 nether_brick 0  
fill ~26 ~0 ~103 ~26 ~1 ~103 nether_brick 0  
fill ~26 ~0 ~105 ~26 ~1 ~105 nether_brick 0  
fill ~26 ~0 ~106 ~26 ~1 ~106 nether_brick 0  
fill ~26 ~0 ~107 ~26 ~1 ~107 nether_brick 0  
fill ~26 ~0 ~108 ~26 ~1 ~108 nether_brick 0  
fill ~26 ~0 ~109 ~26 ~1 ~109 nether_brick 0  
fill ~26 ~0 ~111 ~26 ~1 ~111 nether_brick 0  
fill ~26 ~0 ~112 ~26 ~1 ~112 nether_brick 0  
fill ~26 ~0 ~113 ~26 ~1 ~113 nether_brick 0  
fill ~26 ~0 ~114 ~26 ~1 ~114 nether_brick 0  
fill ~26 ~0 ~122 ~26 ~1 ~122 nether_brick 0  
fill ~26 ~0 ~123 ~26 ~1 ~123 nether_brick 0  
fill ~26 ~0 ~124 ~26 ~1 ~124 nether_brick 0  
fill ~26 ~0 ~125 ~26 ~1 ~125 nether_brick 0  
fill ~4 ~1 ~60 ~5 ~1 ~60 nether_brick 0  
fill ~4 ~1 ~61 ~5 ~1 ~61 nether_brick 0  
fill ~4 ~1 ~126 ~4 ~1 ~128 nether_brick 0  
fill ~5 ~1 ~56 ~6 ~1 ~56 nether_brick 0 
setblock ~5 ~1 ~114 iron_door 8 
setblock ~5 ~1 ~123 stone_brick_stairs 3  
fill ~5 ~1 ~131 ~5 ~1 ~132 nether_brick 0 
setblock ~6 ~1 ~51 nether_brick 0 
setblock ~6 ~1 ~65 iron_door 9  
fill ~6 ~1 ~66 ~10 ~1 ~66 stonebrick 0  
fill ~6 ~1 ~72 ~10 ~1 ~72 stonebrick 0  
fill ~6 ~1 ~78 ~10 ~1 ~78 stonebrick 0  
fill ~6 ~1 ~84 ~10 ~1 ~84 stonebrick 0  
fill ~6 ~1 ~90 ~10 ~1 ~90 stonebrick 0  
fill ~6 ~1 ~96 ~10 ~1 ~96 stonebrick 0  
fill ~6 ~1 ~102 ~10 ~1 ~102 stonebrick 0  
fill ~6 ~1 ~108 ~10 ~1 ~108 stonebrick 0  
fill ~6 ~1 ~114 ~10 ~1 ~114 stonebrick 0  
fill ~6 ~1 ~134 ~6 ~1 ~135 nether_brick 0 
setblock ~7 ~1 ~46 nether_brick 0 
setblock ~7 ~1 ~62 iron_door 9  
fill ~7 ~1 ~138 ~7 ~1 ~144 nether_brick 0 
setblock ~8 ~1 ~42 nether_brick 0 
setblock ~8 ~1 ~62 iron_door 8 
setblock ~8 ~1 ~134 iron_door 9  
fill ~8 ~1 ~140 ~8 ~1 ~148 nether_brick 0 
setblock ~9 ~1 ~37 nether_brick 0 
setblock ~9 ~1 ~44 stone_brick_stairs 3  
fill ~9 ~1 ~56 ~10 ~1 ~56 stonebrick 0  
fill ~9 ~1 ~62 ~14 ~1 ~62 stonebrick 0  
fill ~9 ~1 ~74 ~9 ~1 ~76 coal_ore 0  
fill ~9 ~1 ~86 ~9 ~1 ~88 coal_ore 0  
fill ~9 ~1 ~98 ~9 ~1 ~100 coal_ore 0  
fill ~9 ~1 ~110 ~9 ~1 ~112 coal_ore 0  
fill ~9 ~1 ~127 ~11 ~1 ~127 stonebrick 0  
fill ~9 ~1 ~128 ~12 ~1 ~128 stonebrick 0  
fill ~9 ~1 ~129 ~12 ~1 ~129 stonebrick 0  
fill ~9 ~1 ~130 ~21 ~1 ~130 stonebrick 0 
setblock ~9 ~1 ~134 iron_door 8  
fill ~9 ~1 ~140 ~9 ~1 ~141 bookshelf 0  
fill ~9 ~1 ~142 ~9 ~1 ~151 nether_brick 0 
setblock ~10 ~1 ~32 nether_brick 0  
fill ~10 ~1 ~49 ~11 ~1 ~49 stonebrick 0  
fill ~10 ~1 ~55 ~11 ~1 ~55 stonebrick 0  
fill ~10 ~1 ~57 ~11 ~1 ~57 iron_block 0  
fill ~10 ~1 ~58 ~11 ~1 ~58 iron_block 0  
fill ~10 ~1 ~59 ~11 ~1 ~59 iron_block 0  
fill ~10 ~1 ~60 ~11 ~1 ~60 iron_block 0  
fill ~10 ~1 ~61 ~13 ~1 ~61 iron_block 0 
setblock ~10 ~1 ~67 torch 3 
setblock ~10 ~1 ~71 torch 4 
setblock ~10 ~1 ~73 torch 3 
setblock ~10 ~1 ~77 torch 4 
setblock ~10 ~1 ~79 torch 3 
setblock ~10 ~1 ~83 torch 4 
setblock ~10 ~1 ~85 torch 3 
setblock ~10 ~1 ~89 torch 4 
setblock ~10 ~1 ~91 torch 3 
setblock ~10 ~1 ~95 torch 4 
setblock ~10 ~1 ~97 torch 3 
setblock ~10 ~1 ~101 torch 4 
setblock ~10 ~1 ~103 torch 3 
setblock ~10 ~1 ~107 torch 4 
setblock ~10 ~1 ~109 torch 3  
fill ~10 ~1 ~118 ~11 ~1 ~118 stonebrick 0  
fill ~10 ~1 ~119 ~11 ~1 ~119 wool 12  
fill ~10 ~1 ~120 ~11 ~1 ~120 wool 12  
fill ~10 ~1 ~121 ~11 ~1 ~121 wool 12  
fill ~10 ~1 ~122 ~11 ~1 ~122 wool 12  
fill ~10 ~1 ~123 ~11 ~1 ~123 wool 12  
fill ~10 ~1 ~124 ~11 ~1 ~124 wool 12  
fill ~10 ~1 ~125 ~11 ~1 ~125 wool 12  
fill ~10 ~1 ~126 ~11 ~1 ~126 wool 12  
fill ~10 ~1 ~134 ~20 ~1 ~134 stonebrick 0 
setblock ~10 ~1 ~142 bookshelf 0  
fill ~10 ~1 ~143 ~10 ~1 ~153 nether_brick 0 
setblock ~11 ~1 ~26 nether_brick 0  
fill ~11 ~1 ~44 ~19 ~1 ~44 stonebrick 0 
setblock ~11 ~1 ~48 iron_block 0 
setblock ~11 ~1 ~56 iron_block 0 
setblock ~11 ~1 ~66 iron_door 8 
setblock ~11 ~1 ~72 iron_door 8 
setblock ~11 ~1 ~78 iron_door 8 
setblock ~11 ~1 ~84 iron_door 8 
setblock ~11 ~1 ~90 iron_door 8 
setblock ~11 ~1 ~96 iron_door 8 
setblock ~11 ~1 ~102 iron_door 8 
setblock ~11 ~1 ~108 iron_door 8 
setblock ~11 ~1 ~114 iron_door 8  
fill ~11 ~1 ~117 ~14 ~1 ~117 stonebrick 0 
setblock ~11 ~1 ~143 bookshelf 0  
fill ~11 ~1 ~144 ~11 ~1 ~155 nether_brick 0 
setblock ~12 ~1 ~22 nether_brick 0 
setblock ~12 ~1 ~37 iron_door 8  
fill ~12 ~1 ~45 ~12 ~1 ~47 iron_block 0  
fill ~12 ~1 ~66 ~14 ~1 ~66 stonebrick 0  
fill ~12 ~1 ~72 ~14 ~1 ~72 stonebrick 0 
setblock ~12 ~1 ~73 torch 3 
setblock ~12 ~1 ~77 torch 4  
fill ~12 ~1 ~78 ~14 ~1 ~78 stonebrick 0  
fill ~12 ~1 ~84 ~14 ~1 ~84 stonebrick 0 
setblock ~12 ~1 ~85 torch 3 
setblock ~12 ~1 ~89 torch 4  
fill ~12 ~1 ~90 ~14 ~1 ~90 stonebrick 0  
fill ~12 ~1 ~96 ~14 ~1 ~96 stonebrick 0 
setblock ~12 ~1 ~97 torch 3 
setblock ~12 ~1 ~101 torch 4  
fill ~12 ~1 ~102 ~14 ~1 ~102 stonebrick 0  
fill ~12 ~1 ~108 ~14 ~1 ~108 stonebrick 0 
setblock ~12 ~1 ~109 torch 3  
fill ~12 ~1 ~114 ~14 ~1 ~114 stonebrick 0  
fill ~12 ~1 ~144 ~12 ~1 ~145 bookshelf 0  
fill ~12 ~1 ~146 ~12 ~1 ~156 nether_brick 0 
setblock ~13 ~1 ~17 nether_brick 0 
setblock ~13 ~1 ~37 iron_door 9  
fill ~13 ~1 ~45 ~17 ~1 ~45 stonebrick 0  
fill ~13 ~1 ~46 ~14 ~1 ~46 stonebrick 0 
setblock ~13 ~1 ~47 iron_block 0  
fill ~13 ~1 ~54 ~17 ~1 ~54 stonebrick 0  
fill ~13 ~1 ~55 ~17 ~1 ~55 stonebrick 0  
fill ~13 ~1 ~56 ~13 ~5 ~56 stonebrick 0  
fill ~13 ~1 ~74 ~13 ~1 ~76 coal_ore 0  
fill ~13 ~1 ~86 ~13 ~1 ~88 coal_ore 0  
fill ~13 ~1 ~98 ~13 ~1 ~100 coal_ore 0  
fill ~13 ~1 ~110 ~13 ~1 ~112 coal_ore 0  
fill ~13 ~1 ~121 ~17 ~1 ~121 stonebrick 0  
fill ~13 ~1 ~122 ~17 ~1 ~122 stonebrick 0  
fill ~13 ~1 ~123 ~14 ~1 ~123 stonebrick 0  
fill ~13 ~1 ~128 ~17 ~1 ~128 iron_block 0  
fill ~13 ~1 ~129 ~17 ~1 ~129 iron_block 0 
setblock ~13 ~1 ~146 bookshelf 0  
fill ~13 ~1 ~148 ~22 ~1 ~148 nether_brick 0  
fill ~13 ~1 ~149 ~21 ~1 ~149 nether_brick 0  
fill ~13 ~1 ~150 ~21 ~1 ~150 nether_brick 0  
fill ~13 ~1 ~151 ~21 ~1 ~151 nether_brick 0  
fill ~13 ~1 ~156 ~18 ~1 ~156 nether_brick 0  
fill ~13 ~1 ~157 ~17 ~1 ~157 nether_brick 0 
setblock ~14 ~1 ~11 nether_brick 0  
fill ~14 ~1 ~14 ~14 ~-2 ~14 nether_brick 0  
fill ~14 ~1 ~20 ~16 ~1 ~20 crafting_table 0  
fill ~14 ~1 ~37 ~16 ~1 ~37 stonebrick 0  
fill ~14 ~1 ~43 ~16 ~1 ~43 stonebrick 0  
fill ~14 ~1 ~51 ~16 ~1 ~51 iron_block 0  
fill ~14 ~1 ~52 ~16 ~1 ~52 iron_block 0  
fill ~14 ~1 ~53 ~16 ~1 ~53 stonebrick 0 
setblock ~14 ~1 ~71 torch 4 
setblock ~14 ~1 ~73 torch 3 
setblock ~14 ~1 ~77 torch 4 
setblock ~14 ~1 ~79 torch 3 
setblock ~14 ~1 ~83 torch 4 
setblock ~14 ~1 ~85 torch 3 
setblock ~14 ~1 ~89 torch 4 
setblock ~14 ~1 ~91 torch 3 
setblock ~14 ~1 ~95 torch 4 
setblock ~14 ~1 ~97 torch 3 
setblock ~14 ~1 ~101 torch 4 
setblock ~14 ~1 ~103 torch 3 
setblock ~14 ~1 ~107 torch 4 
setblock ~14 ~1 ~109 torch 3  
fill ~14 ~1 ~120 ~16 ~1 ~120 stonebrick 0 
setblock ~14 ~1 ~147 bookshelf 0  
fill ~14 ~1 ~152 ~20 ~1 ~152 nether_brick 0  
fill ~14 ~1 ~153 ~20 ~1 ~153 nether_brick 0  
fill ~14 ~1 ~154 ~19 ~1 ~154 nether_brick 0  
fill ~14 ~1 ~155 ~19 ~1 ~155 nether_brick 0 
setblock ~15 ~1 ~9 nether_brick 0  
fill ~15 ~1 ~14 ~15 ~1 ~19 glowstone 0 
setblock ~15 ~1 ~62 iron_door 8 
setblock ~15 ~1 ~66 iron_door 8 
setblock ~15 ~1 ~72 iron_door 8 
setblock ~15 ~1 ~78 iron_door 8 
setblock ~15 ~1 ~84 iron_door 8 
setblock ~15 ~1 ~90 iron_door 8 
setblock ~15 ~1 ~96 iron_door 8 
setblock ~15 ~1 ~102 iron_door 8 
setblock ~15 ~1 ~108 iron_door 8 
setblock ~15 ~1 ~114 iron_door 8 
setblock ~15 ~1 ~117 iron_door 8 
setblock ~15 ~1 ~147 nether_brick 0 
setblock ~16 ~1 ~11 nether_brick 0 
setblock ~16 ~1 ~14 nether_brick 0  
fill ~16 ~1 ~46 ~17 ~1 ~46 stonebrick 0  
fill ~16 ~1 ~56 ~17 ~1 ~56 stonebrick 0  
fill ~16 ~1 ~62 ~21 ~1 ~62 stonebrick 0  
fill ~16 ~1 ~66 ~18 ~1 ~66 stonebrick 0 
setblock ~16 ~1 ~67 torch 3 
setblock ~16 ~1 ~71 torch 4  
fill ~16 ~1 ~72 ~18 ~1 ~72 stonebrick 0 
setblock ~16 ~1 ~73 torch 3 
setblock ~16 ~1 ~77 torch 4  
fill ~16 ~1 ~78 ~18 ~1 ~78 stonebrick 0 
setblock ~16 ~1 ~79 torch 3 
setblock ~16 ~1 ~83 torch 4  
fill ~16 ~1 ~84 ~18 ~1 ~84 stonebrick 0 
setblock ~16 ~1 ~85 torch 3 
setblock ~16 ~1 ~89 torch 4  
fill ~16 ~1 ~90 ~18 ~1 ~90 stonebrick 0 
setblock ~16 ~1 ~91 torch 3 
setblock ~16 ~1 ~95 torch 4  
fill ~16 ~1 ~96 ~18 ~1 ~96 stonebrick 0 
setblock ~16 ~1 ~97 torch 3 
setblock ~16 ~1 ~101 torch 4  
fill ~16 ~1 ~102 ~18 ~1 ~102 stonebrick 0 
setblock ~16 ~1 ~103 torch 3 
setblock ~16 ~1 ~107 torch 4  
fill ~16 ~1 ~108 ~18 ~1 ~108 stonebrick 0 
setblock ~16 ~1 ~109 torch 3  
fill ~16 ~1 ~114 ~18 ~1 ~114 stonebrick 0  
fill ~16 ~1 ~117 ~19 ~1 ~117 stonebrick 0  
fill ~16 ~1 ~123 ~17 ~1 ~123 stonebrick 0 
setblock ~16 ~1 ~147 bookshelf 0 
setblock ~17 ~1 ~17 nether_brick 0 
setblock ~17 ~1 ~37 iron_door 8  
fill ~17 ~1 ~47 ~18 ~1 ~47 iron_block 0  
fill ~17 ~1 ~61 ~20 ~1 ~61 iron_block 0  
fill ~17 ~1 ~74 ~17 ~1 ~76 coal_ore 0  
fill ~17 ~1 ~86 ~17 ~1 ~88 coal_ore 0  
fill ~17 ~1 ~98 ~17 ~1 ~100 coal_ore 0  
fill ~17 ~1 ~110 ~17 ~1 ~112 coal_ore 0 
setblock ~17 ~1 ~146 bookshelf 0 
setblock ~18 ~1 ~22 nether_brick 0 
setblock ~18 ~1 ~37 iron_door 9  
fill ~18 ~1 ~45 ~18 ~1 ~47 iron_block 0 
setblock ~18 ~1 ~73 torch 3 
setblock ~18 ~1 ~77 torch 4 
setblock ~18 ~1 ~85 torch 3 
setblock ~18 ~1 ~89 torch 4 
setblock ~18 ~1 ~97 torch 3 
setblock ~18 ~1 ~101 torch 4 
setblock ~18 ~1 ~109 torch 3  
fill ~18 ~1 ~128 ~21 ~1 ~128 stonebrick 0  
fill ~18 ~1 ~129 ~21 ~1 ~129 stonebrick 0  
fill ~18 ~1 ~144 ~18 ~1 ~145 bookshelf 0  
fill ~18 ~1 ~146 ~22 ~1 ~146 nether_brick 0  
fill ~18 ~1 ~147 ~22 ~1 ~147 nether_brick 0 
setblock ~19 ~1 ~26 nether_brick 0 
setblock ~19 ~1 ~48 iron_block 0  
fill ~19 ~1 ~49 ~20 ~1 ~49 stonebrick 0  
fill ~19 ~1 ~55 ~20 ~1 ~55 stonebrick 0  
fill ~19 ~1 ~56 ~20 ~1 ~56 iron_block 0  
fill ~19 ~1 ~57 ~20 ~1 ~57 iron_block 0  
fill ~19 ~1 ~58 ~20 ~1 ~58 iron_block 0  
fill ~19 ~1 ~59 ~20 ~1 ~59 iron_block 0  
fill ~19 ~1 ~60 ~20 ~1 ~60 iron_block 0 
setblock ~19 ~1 ~66 iron_door 8 
setblock ~19 ~1 ~72 iron_door 8 
setblock ~19 ~1 ~78 iron_door 8 
setblock ~19 ~1 ~84 iron_door 8 
setblock ~19 ~1 ~90 iron_door 8 
setblock ~19 ~1 ~96 iron_door 8 
setblock ~19 ~1 ~102 iron_door 8 
setblock ~19 ~1 ~108 iron_door 8 
setblock ~19 ~1 ~114 iron_door 8  
fill ~19 ~1 ~118 ~20 ~1 ~118 stonebrick 0  
fill ~19 ~1 ~119 ~20 ~1 ~119 wool 12  
fill ~19 ~1 ~120 ~20 ~1 ~120 wool 12  
fill ~19 ~1 ~121 ~20 ~1 ~121 wool 12  
fill ~19 ~1 ~122 ~20 ~1 ~122 wool 12  
fill ~19 ~1 ~123 ~20 ~1 ~123 wool 12  
fill ~19 ~1 ~124 ~20 ~1 ~124 wool 12  
fill ~19 ~1 ~125 ~20 ~1 ~125 wool 12  
fill ~19 ~1 ~126 ~20 ~1 ~126 wool 12  
fill ~19 ~1 ~127 ~21 ~1 ~127 stonebrick 0 
setblock ~19 ~1 ~143 bookshelf 0  
fill ~19 ~1 ~144 ~23 ~1 ~144 nether_brick 0  
fill ~19 ~1 ~145 ~22 ~1 ~145 nether_brick 0 
setblock ~20 ~1 ~32 nether_brick 0  
fill ~20 ~1 ~66 ~24 ~1 ~66 stonebrick 0 
setblock ~20 ~1 ~67 torch 3 
setblock ~20 ~1 ~71 torch 4  
fill ~20 ~1 ~72 ~24 ~1 ~72 stonebrick 0 
setblock ~20 ~1 ~73 torch 3 
setblock ~20 ~1 ~77 torch 4  
fill ~20 ~1 ~78 ~24 ~1 ~78 stonebrick 0 
setblock ~20 ~1 ~79 torch 3 
setblock ~20 ~1 ~83 torch 4  
fill ~20 ~1 ~84 ~24 ~1 ~84 stonebrick 0 
setblock ~20 ~1 ~85 torch 3 
setblock ~20 ~1 ~89 torch 4  
fill ~20 ~1 ~90 ~24 ~1 ~90 stonebrick 0 
setblock ~20 ~1 ~91 torch 3 
setblock ~20 ~1 ~95 torch 4  
fill ~20 ~1 ~96 ~24 ~1 ~96 stonebrick 0 
setblock ~20 ~1 ~97 torch 3 
setblock ~20 ~1 ~101 torch 4  
fill ~20 ~1 ~102 ~24 ~1 ~102 stonebrick 0 
setblock ~20 ~1 ~103 torch 3 
setblock ~20 ~1 ~107 torch 4  
fill ~20 ~1 ~108 ~24 ~1 ~108 stonebrick 0 
setblock ~20 ~1 ~109 torch 3  
fill ~20 ~1 ~114 ~24 ~1 ~114 stonebrick 0 
setblock ~20 ~1 ~142 bookshelf 0  
fill ~20 ~1 ~143 ~23 ~1 ~143 nether_brick 0 
setblock ~21 ~1 ~37 nether_brick 0 
setblock ~21 ~1 ~44 stone_brick_stairs 3  
fill ~21 ~1 ~75 ~21 ~1 ~76 coal_ore 0  
fill ~21 ~1 ~86 ~21 ~1 ~88 coal_ore 0  
fill ~21 ~1 ~98 ~21 ~1 ~100 coal_ore 0  
fill ~21 ~1 ~110 ~21 ~1 ~112 coal_ore 0 
setblock ~21 ~1 ~134 iron_door 9  
fill ~21 ~1 ~140 ~21 ~1 ~141 bookshelf 0  
fill ~21 ~1 ~142 ~23 ~1 ~142 nether_brick 0 
setblock ~22 ~1 ~42 nether_brick 0 
setblock ~22 ~1 ~62 iron_door 9 
setblock ~22 ~1 ~134 iron_door 8  
fill ~22 ~1 ~140 ~23 ~1 ~140 nether_brick 0  
fill ~22 ~1 ~141 ~23 ~1 ~141 nether_brick 0 
setblock ~23 ~1 ~46 nether_brick 0 
setblock ~23 ~1 ~62 iron_door 8  
fill ~23 ~1 ~137 ~23 ~1 ~144 nether_brick 0 
setblock ~24 ~1 ~51 nether_brick 0  
fill ~24 ~1 ~56 ~25 ~1 ~56 nether_brick 0  
fill ~24 ~1 ~62 ~25 ~1 ~62 stonebrick 0 
setblock ~24 ~1 ~65 iron_door 8  
fill ~24 ~1 ~134 ~24 ~1 ~135 nether_brick 0  
fill ~25 ~1 ~60 ~26 ~1 ~60 nether_brick 0  
fill ~25 ~1 ~61 ~26 ~1 ~61 nether_brick 0 
setblock ~25 ~1 ~114 iron_door 8 
setblock ~25 ~1 ~123 stone_brick_stairs 3  
fill ~25 ~1 ~131 ~25 ~1 ~132 nether_brick 0  
fill ~26 ~1 ~126 ~26 ~1 ~128 nether_brick 0 
setblock ~3 ~2 ~61 torch 2 
setblock ~3 ~2 ~67 torch 2 
setblock ~3 ~2 ~73 torch 2 
setblock ~3 ~2 ~79 torch 2 
setblock ~3 ~2 ~85 torch 2 
setblock ~3 ~2 ~91 torch 2 
setblock ~3 ~2 ~97 torch 2 
setblock ~3 ~2 ~103 torch 2 
setblock ~3 ~2 ~109 torch 2 
setblock ~3 ~2 ~115 torch 2 
setblock ~3 ~2 ~121 torch 2 
setblock ~3 ~2 ~127 torch 2  
fill ~4 ~2 ~60 ~6 ~2 ~60 wool 15  
fill ~4 ~2 ~61 ~5 ~2 ~61 wool 15  
fill ~4 ~2 ~62 ~4 ~2 ~130 wool 15 
setblock ~4 ~2 ~133 torch 2 
setblock ~5 ~2 ~55 torch 2  
fill ~5 ~2 ~56 ~6 ~2 ~56 wool 15  
fill ~5 ~2 ~57 ~6 ~2 ~57 wool 15  
fill ~5 ~2 ~58 ~6 ~2 ~58 wool 15  
fill ~5 ~2 ~59 ~6 ~2 ~59 wool 15  
fill ~5 ~2 ~62 ~7 ~2 ~62 stone 0  
fill ~5 ~2 ~63 ~7 ~2 ~63 stone 0  
fill ~5 ~2 ~64 ~7 ~2 ~64 stone 0  
fill ~5 ~2 ~65 ~7 ~2 ~65 stone 0  
fill ~5 ~2 ~66 ~7 ~2 ~66 stone 0  
fill ~5 ~2 ~67 ~6 ~2 ~67 stone 0  
fill ~5 ~2 ~68 ~6 ~2 ~68 stone 0  
fill ~5 ~2 ~69 ~6 ~2 ~69 stone 0  
fill ~5 ~2 ~70 ~6 ~2 ~70 stone 0  
fill ~5 ~2 ~71 ~6 ~2 ~71 stone 0  
fill ~5 ~2 ~72 ~6 ~2 ~72 stone 0  
fill ~5 ~2 ~73 ~6 ~2 ~73 stone 0  
fill ~5 ~2 ~74 ~6 ~2 ~74 stone 0  
fill ~5 ~2 ~75 ~6 ~2 ~75 stone 0  
fill ~5 ~2 ~76 ~6 ~2 ~76 stone 0  
fill ~5 ~2 ~77 ~6 ~2 ~77 stone 0  
fill ~5 ~2 ~78 ~6 ~2 ~78 stone 0  
fill ~5 ~2 ~79 ~6 ~2 ~79 stone 0  
fill ~5 ~2 ~80 ~6 ~2 ~80 stone 0  
fill ~5 ~2 ~81 ~6 ~2 ~81 stone 0  
fill ~5 ~2 ~82 ~6 ~2 ~82 stone 0  
fill ~5 ~2 ~83 ~6 ~2 ~83 stone 0  
fill ~5 ~2 ~84 ~6 ~2 ~84 stone 0  
fill ~5 ~2 ~85 ~6 ~2 ~85 stone 0  
fill ~5 ~2 ~86 ~6 ~2 ~86 stone 0  
fill ~5 ~2 ~87 ~6 ~2 ~87 stone 0  
fill ~5 ~2 ~88 ~6 ~2 ~88 stone 0  
fill ~5 ~2 ~89 ~6 ~2 ~89 stone 0  
fill ~5 ~2 ~90 ~6 ~2 ~90 stone 0  
fill ~5 ~2 ~91 ~6 ~2 ~91 stone 0  
fill ~5 ~2 ~92 ~6 ~2 ~92 stone 0  
fill ~5 ~2 ~93 ~6 ~2 ~93 stone 0  
fill ~5 ~2 ~94 ~6 ~2 ~94 stone 0  
fill ~5 ~2 ~95 ~6 ~2 ~95 stone 0  
fill ~5 ~2 ~96 ~6 ~2 ~96 stone 0  
fill ~5 ~2 ~97 ~6 ~2 ~97 stone 0  
fill ~5 ~2 ~98 ~6 ~2 ~98 stone 0  
fill ~5 ~2 ~99 ~6 ~2 ~99 stone 0  
fill ~5 ~2 ~100 ~6 ~2 ~100 stone 0  
fill ~5 ~2 ~101 ~6 ~2 ~101 stone 0  
fill ~5 ~2 ~102 ~6 ~2 ~102 stone 0  
fill ~5 ~2 ~103 ~6 ~2 ~103 stone 0  
fill ~5 ~2 ~104 ~6 ~2 ~104 stone 0  
fill ~5 ~2 ~105 ~6 ~2 ~105 stone 0  
fill ~5 ~2 ~106 ~6 ~2 ~106 stone 0  
fill ~5 ~2 ~107 ~6 ~2 ~107 stone 0  
fill ~5 ~2 ~108 ~6 ~2 ~108 stone 0  
fill ~5 ~2 ~109 ~6 ~2 ~109 stone 0  
fill ~5 ~2 ~110 ~6 ~2 ~110 stone 0  
fill ~5 ~2 ~111 ~6 ~2 ~111 stone 0  
fill ~5 ~2 ~112 ~6 ~2 ~112 stone 0  
fill ~5 ~2 ~113 ~6 ~2 ~113 stone 0  
fill ~5 ~2 ~114 ~6 ~2 ~114 stone 0  
fill ~5 ~2 ~115 ~6 ~2 ~115 stone 0  
fill ~5 ~2 ~116 ~6 ~2 ~116 stone 0  
fill ~5 ~2 ~117 ~6 ~2 ~117 stone 0  
fill ~5 ~2 ~118 ~6 ~2 ~118 stone 0  
fill ~5 ~2 ~119 ~6 ~2 ~119 stone 0  
fill ~5 ~2 ~120 ~6 ~2 ~120 stone 0  
fill ~5 ~2 ~121 ~6 ~2 ~121 stone 0  
fill ~5 ~2 ~126 ~5 ~2 ~135 wool 15 
setblock ~5 ~2 ~139 torch 2 
setblock ~6 ~2 ~49 torch 2  
fill ~6 ~2 ~51 ~7 ~2 ~51 wool 15  
fill ~6 ~2 ~52 ~7 ~2 ~52 wool 15  
fill ~6 ~2 ~53 ~6 ~2 ~60 wool 15  
fill ~6 ~2 ~61 ~7 ~2 ~61 stone 0 
setblock ~6 ~2 ~122 stone_brick_stairs 0  
fill ~6 ~2 ~123 ~12 ~2 ~123 stone 0  
fill ~6 ~2 ~124 ~8 ~2 ~124 glowstone 0  
fill ~6 ~2 ~125 ~9 ~2 ~125 stone 0  
fill ~6 ~2 ~126 ~11 ~2 ~126 glowstone 0  
fill ~6 ~2 ~127 ~14 ~2 ~127 planks 0  
fill ~6 ~2 ~128 ~24 ~2 ~128 planks 0  
fill ~6 ~2 ~129 ~24 ~2 ~129 glowstone 0  
fill ~6 ~2 ~130 ~24 ~2 ~130 planks 0  
fill ~6 ~2 ~131 ~6 ~2 ~133 stone 0  
fill ~6 ~2 ~134 ~6 ~2 ~141 wool 15 
setblock ~6 ~2 ~145 torch 2 
setblock ~7 ~2 ~43 torch 2  
fill ~7 ~2 ~46 ~7 ~2 ~52 wool 15  
fill ~7 ~2 ~53 ~8 ~2 ~53 stone 0  
fill ~7 ~2 ~54 ~8 ~2 ~54 stone 0  
fill ~7 ~2 ~55 ~8 ~2 ~55 stone 0  
fill ~7 ~2 ~56 ~8 ~2 ~56 stone 0  
fill ~7 ~2 ~57 ~8 ~2 ~57 stone 0  
fill ~7 ~2 ~58 ~8 ~2 ~58 stone 0  
fill ~7 ~2 ~59 ~8 ~2 ~59 stone 0  
fill ~7 ~2 ~60 ~7 ~2 ~53 stone 0  
fill ~7 ~2 ~67 ~7 ~2 ~121 glowstone 0  
fill ~7 ~2 ~122 ~12 ~2 ~122 stone 0  
fill ~7 ~2 ~131 ~14 ~2 ~131 planks 0  
fill ~7 ~2 ~132 ~8 ~2 ~132 glowstone 0  
fill ~7 ~2 ~133 ~14 ~2 ~133 planks 0  
fill ~7 ~2 ~134 ~23 ~2 ~134 planks 0  
fill ~7 ~2 ~135 ~8 ~2 ~135 glowstone 0  
fill ~7 ~2 ~136 ~7 ~2 ~141 stone 0  
fill ~7 ~2 ~142 ~7 ~2 ~146 wool 15 
setblock ~8 ~2 ~37 torch 2  
fill ~8 ~2 ~42 ~8 ~2 ~45 wool 15  
fill ~8 ~2 ~46 ~8 ~2 ~59 stone 0  
fill ~8 ~2 ~60 ~8 ~2 ~66 glowstone 0  
fill ~8 ~2 ~67 ~25 ~2 ~67 stone 0  
fill ~8 ~2 ~68 ~22 ~2 ~68 stone 0  
fill ~8 ~2 ~69 ~22 ~2 ~69 stone 0  
fill ~8 ~2 ~70 ~22 ~2 ~70 stone 0  
fill ~8 ~2 ~71 ~22 ~2 ~71 stone 0  
fill ~8 ~2 ~72 ~22 ~2 ~72 stone 0  
fill ~8 ~2 ~73 ~22 ~2 ~73 stone 0  
fill ~8 ~2 ~74 ~22 ~2 ~74 stone 0  
fill ~8 ~2 ~75 ~22 ~2 ~75 stone 0  
fill ~8 ~2 ~76 ~22 ~2 ~76 stone 0  
fill ~8 ~2 ~77 ~22 ~2 ~77 stone 0  
fill ~8 ~2 ~78 ~22 ~2 ~78 stone 0  
fill ~8 ~2 ~79 ~22 ~2 ~79 stone 0  
fill ~8 ~2 ~80 ~22 ~2 ~80 stone 0  
fill ~8 ~2 ~81 ~22 ~2 ~81 stone 0  
fill ~8 ~2 ~82 ~22 ~2 ~82 stone 0  
fill ~8 ~2 ~83 ~22 ~2 ~83 stone 0  
fill ~8 ~2 ~84 ~22 ~2 ~84 stone 0  
fill ~8 ~2 ~85 ~22 ~2 ~85 stone 0  
fill ~8 ~2 ~86 ~22 ~2 ~86 stone 0  
fill ~8 ~2 ~87 ~22 ~2 ~87 stone 0  
fill ~8 ~2 ~88 ~14 ~2 ~88 stone 0  
fill ~8 ~2 ~89 ~22 ~2 ~89 stone 0  
fill ~8 ~2 ~90 ~22 ~2 ~90 stone 0  
fill ~8 ~2 ~91 ~22 ~2 ~91 stone 0  
fill ~8 ~2 ~92 ~14 ~2 ~92 stone 0  
fill ~8 ~2 ~93 ~22 ~2 ~93 stone 0  
fill ~8 ~2 ~94 ~22 ~2 ~94 stone 0  
fill ~8 ~2 ~95 ~22 ~2 ~95 stone 0  
fill ~8 ~2 ~96 ~22 ~2 ~96 stone 0  
fill ~8 ~2 ~97 ~22 ~2 ~97 stone 0  
fill ~8 ~2 ~98 ~22 ~2 ~98 stone 0  
fill ~8 ~2 ~99 ~22 ~2 ~99 stone 0  
fill ~8 ~2 ~100 ~22 ~2 ~100 stone 0  
fill ~8 ~2 ~101 ~22 ~2 ~101 stone 0  
fill ~8 ~2 ~102 ~22 ~2 ~102 stone 0  
fill ~8 ~2 ~103 ~22 ~2 ~103 stone 0  
fill ~8 ~2 ~104 ~22 ~2 ~104 stone 0  
fill ~8 ~2 ~105 ~22 ~2 ~105 stone 0  
fill ~8 ~2 ~106 ~22 ~2 ~106 stone 0  
fill ~8 ~2 ~107 ~12 ~2 ~107 stone 0  
fill ~8 ~2 ~108 ~22 ~2 ~108 stone 0  
fill ~8 ~2 ~109 ~12 ~2 ~109 stone 0  
fill ~8 ~2 ~110 ~22 ~2 ~110 stone 0  
fill ~8 ~2 ~111 ~22 ~2 ~111 stone 0  
fill ~8 ~2 ~112 ~22 ~2 ~112 stone 0  
fill ~8 ~2 ~113 ~22 ~2 ~113 stone 0  
fill ~8 ~2 ~114 ~22 ~2 ~114 stone 0  
fill ~8 ~2 ~115 ~22 ~2 ~115 stone 0  
fill ~8 ~2 ~116 ~22 ~2 ~116 stone 0  
fill ~8 ~2 ~117 ~22 ~2 ~117 stone 0  
fill ~8 ~2 ~118 ~22 ~2 ~118 stone 0  
fill ~8 ~2 ~119 ~22 ~2 ~119 stone 0  
fill ~8 ~2 ~120 ~12 ~2 ~120 stone 0  
fill ~8 ~2 ~121 ~12 ~2 ~121 stone 0  
fill ~8 ~2 ~136 ~22 ~2 ~136 planks 0  
fill ~8 ~2 ~137 ~14 ~2 ~137 planks 0  
fill ~8 ~2 ~138 ~14 ~2 ~138 planks 0  
fill ~8 ~2 ~139 ~14 ~2 ~139 planks 0  
fill ~8 ~2 ~140 ~8 ~2 ~146 stone 0  
fill ~8 ~2 ~147 ~8 ~2 ~150 wool 15 
setblock ~8 ~2 ~151 torch 2  
fill ~9 ~2 ~37 ~10 ~2 ~37 wool 15  
fill ~9 ~2 ~38 ~9 ~2 ~41 wool 15  
fill ~9 ~2 ~42 ~10 ~2 ~42 stone 0 
setblock ~9 ~2 ~43 stone_brick_stairs 3  
fill ~9 ~2 ~47 ~9 ~2 ~52 stone 0  
fill ~9 ~2 ~53 ~10 ~2 ~53 glowstone 0  
fill ~9 ~2 ~54 ~9 ~2 ~59 glowstone 0  
fill ~9 ~2 ~60 ~13 ~2 ~60 stone 0  
fill ~9 ~2 ~61 ~21 ~2 ~61 stone 0  
fill ~9 ~2 ~62 ~21 ~2 ~62 stone 0  
fill ~9 ~2 ~63 ~21 ~2 ~63 stone 0  
fill ~9 ~2 ~64 ~21 ~2 ~64 stone 0  
fill ~9 ~2 ~65 ~21 ~2 ~65 stone 0  
fill ~9 ~2 ~66 ~21 ~2 ~66 stone 0  
fill ~9 ~2 ~124 ~13 ~2 ~124 stone 0  
fill ~9 ~2 ~132 ~14 ~2 ~132 planks 0  
fill ~9 ~2 ~135 ~14 ~2 ~135 planks 0  
fill ~9 ~2 ~140 ~21 ~2 ~140 planks 0  
fill ~9 ~2 ~141 ~14 ~2 ~141 planks 0  
fill ~9 ~2 ~142 ~21 ~2 ~142 planks 0  
fill ~9 ~2 ~143 ~14 ~2 ~143 planks 0  
fill ~9 ~2 ~144 ~14 ~2 ~144 planks 0  
fill ~9 ~2 ~145 ~14 ~2 ~145 planks 0  
fill ~9 ~2 ~146 ~9 ~2 ~150 stone 0  
fill ~9 ~2 ~151 ~9 ~2 ~153 wool 15 
setblock ~10 ~2 ~31 torch 2  
fill ~10 ~2 ~32 ~10 ~2 ~37 wool 15  
fill ~10 ~2 ~38 ~20 ~2 ~38 stone 0  
fill ~10 ~2 ~39 ~20 ~2 ~39 stone 0  
fill ~10 ~2 ~40 ~10 ~2 ~46 stone 0  
fill ~10 ~2 ~47 ~10 ~2 ~53 glowstone 0  
fill ~10 ~2 ~54 ~12 ~2 ~54 stone 0  
fill ~10 ~2 ~55 ~12 ~2 ~55 stone 0  
fill ~10 ~2 ~56 ~12 ~2 ~56 stone 0  
fill ~10 ~2 ~57 ~13 ~2 ~57 stone 0  
fill ~10 ~2 ~58 ~20 ~2 ~58 stone 0  
fill ~10 ~2 ~59 ~20 ~2 ~59 stone 0 
setblock ~10 ~2 ~125 planks 0  
fill ~10 ~2 ~146 ~20 ~2 ~146 planks 0  
fill ~10 ~2 ~147 ~10 ~2 ~153 stone 0  
fill ~10 ~2 ~154 ~10 ~2 ~155 wool 15 
setblock ~11 ~2 ~25 torch 2  
fill ~11 ~2 ~26 ~11 ~2 ~31 wool 15  
fill ~11 ~2 ~32 ~19 ~2 ~32 stone 0  
fill ~11 ~2 ~33 ~19 ~2 ~33 stone 0  
fill ~11 ~2 ~34 ~19 ~2 ~34 stone 0  
fill ~11 ~2 ~35 ~19 ~2 ~35 stone 0  
fill ~11 ~2 ~36 ~19 ~2 ~36 stone 0  
fill ~11 ~2 ~37 ~19 ~2 ~37 stone 0  
fill ~11 ~2 ~40 ~11 ~2 ~46 glowstone 0  
fill ~11 ~2 ~47 ~13 ~2 ~47 stone 0  
fill ~11 ~2 ~48 ~19 ~2 ~48 stone 0  
fill ~11 ~2 ~49 ~19 ~2 ~49 stone 0  
fill ~11 ~2 ~50 ~19 ~2 ~50 stone 0  
fill ~11 ~2 ~51 ~19 ~2 ~51 stone 0  
fill ~11 ~2 ~52 ~19 ~2 ~52 stone 0  
fill ~11 ~2 ~53 ~13 ~2 ~53 stone 0  
fill ~11 ~2 ~125 ~12 ~2 ~125 stone 0  
fill ~11 ~2 ~147 ~14 ~2 ~147 planks 0  
fill ~11 ~2 ~148 ~19 ~2 ~148 planks 0  
fill ~11 ~2 ~149 ~14 ~2 ~149 planks 0  
fill ~11 ~2 ~150 ~21 ~2 ~150 stone 0  
fill ~11 ~2 ~151 ~20 ~2 ~151 stone 0  
fill ~11 ~2 ~152 ~20 ~2 ~152 stone 0  
fill ~11 ~2 ~153 ~19 ~2 ~153 stone 0  
fill ~11 ~2 ~154 ~19 ~2 ~154 stone 0  
fill ~11 ~2 ~155 ~19 ~2 ~155 stone 0 
setblock ~11 ~2 ~156 wool 15 
setblock ~11 ~2 ~157 torch 2 
setblock ~12 ~2 ~19 torch 2  
fill ~12 ~2 ~21 ~12 ~2 ~25 wool 15  
fill ~12 ~2 ~26 ~18 ~2 ~26 stone 0  
fill ~12 ~2 ~27 ~18 ~2 ~27 stone 0  
fill ~12 ~2 ~28 ~18 ~2 ~28 stone 0  
fill ~12 ~2 ~29 ~18 ~2 ~29 stone 0  
fill ~12 ~2 ~30 ~18 ~2 ~30 stone 0  
fill ~12 ~2 ~31 ~18 ~2 ~31 stone 0  
fill ~12 ~2 ~40 ~18 ~2 ~40 stone 0  
fill ~12 ~2 ~41 ~18 ~2 ~41 stone 0  
fill ~12 ~2 ~42 ~18 ~2 ~42 stone 0  
fill ~12 ~2 ~43 ~14 ~2 ~43 stone 0  
fill ~12 ~2 ~44 ~13 ~2 ~44 stone 0  
fill ~12 ~2 ~45 ~12 ~2 ~125 stone 0  
fill ~12 ~2 ~126 ~14 ~2 ~126 planks 0  
fill ~12 ~2 ~156 ~18 ~2 ~156 stone 0  
fill ~12 ~2 ~157 ~12 ~2 ~158 wool 15 
setblock ~13 ~2 ~13 torch 2  
fill ~13 ~2 ~16 ~14 ~2 ~16 wool 15  
fill ~13 ~2 ~17 ~14 ~2 ~17 wool 15  
fill ~13 ~2 ~18 ~13 ~2 ~20 wool 15  
fill ~13 ~2 ~21 ~17 ~2 ~21 stone 0  
fill ~13 ~2 ~22 ~17 ~2 ~22 stone 0  
fill ~13 ~2 ~23 ~17 ~2 ~23 stone 0  
fill ~13 ~2 ~24 ~17 ~2 ~24 stone 0  
fill ~13 ~2 ~25 ~14 ~2 ~25 stone 0  
fill ~13 ~2 ~45 ~17 ~2 ~45 stonebrick 0  
fill ~13 ~2 ~46 ~14 ~2 ~46 stonebrick 0  
fill ~13 ~2 ~54 ~17 ~2 ~54 stonebrick 0  
fill ~13 ~2 ~55 ~17 ~2 ~55 stonebrick 0 
setblock ~13 ~2 ~107 glowstone 0 
setblock ~13 ~2 ~109 glowstone 0 
setblock ~13 ~2 ~120 glowstone 0  
fill ~13 ~2 ~121 ~17 ~2 ~121 stonebrick 0  
fill ~13 ~2 ~122 ~17 ~2 ~122 stonebrick 0  
fill ~13 ~2 ~123 ~14 ~2 ~123 stonebrick 0  
fill ~13 ~2 ~125 ~14 ~2 ~125 planks 0  
fill ~13 ~2 ~157 ~17 ~2 ~157 stone 0  
fill ~13 ~2 ~158 ~18 ~2 ~158 wool 15  
fill ~14 ~2 ~11 ~16 ~2 ~11 wool 15  
fill ~14 ~2 ~12 ~16 ~2 ~12 wool 15  
fill ~14 ~2 ~13 ~14 ~2 ~17 wool 15  
fill ~14 ~2 ~18 ~16 ~2 ~18 stone 0  
fill ~14 ~2 ~19 ~16 ~2 ~19 stone 0  
fill ~14 ~2 ~20 ~16 ~2 ~20 stone 0  
fill ~14 ~2 ~44 ~16 ~2 ~44 stonebrick 0 
setblock ~14 ~2 ~47 glowstone 0  
fill ~14 ~2 ~53 ~16 ~2 ~53 stonebrick 0 
setblock ~14 ~2 ~57 glowstone 0 
setblock ~14 ~2 ~60 glowstone 0  
fill ~14 ~2 ~107 ~16 ~2 ~107 stone 0  
fill ~14 ~2 ~109 ~16 ~2 ~109 stone 0  
fill ~14 ~2 ~120 ~16 ~2 ~120 stonebrick 0  
fill ~14 ~2 ~159 ~16 ~2 ~159 wool 15 
setblock ~15 ~2 ~7 torch 4  
fill ~15 ~2 ~8 ~15 ~2 ~12 wool 15 
setblock ~15 ~2 ~17 stonebrick 0 
setblock ~15 ~2 ~25 glowstone 0  
fill ~15 ~2 ~43 ~15 ~6 ~43 stonebrick 0  
fill ~15 ~2 ~47 ~15 ~6 ~47 stonebrick 0  
fill ~15 ~2 ~57 ~15 ~8 ~57 stonebrick 0 
setblock ~15 ~2 ~60 stone 0 
setblock ~15 ~2 ~88 glowstone 0 
setblock ~15 ~2 ~92 glowstone 0  
fill ~15 ~2 ~124 ~15 ~6 ~124 stonebrick 0  
fill ~15 ~2 ~125 ~15 ~2 ~127 wool 0  
fill ~15 ~2 ~131 ~15 ~2 ~133 wool 0 
setblock ~15 ~2 ~135 glowstone 0  
fill ~15 ~2 ~137 ~15 ~2 ~139 wool 0 
setblock ~15 ~2 ~141 glowstone 0  
fill ~15 ~2 ~143 ~15 ~2 ~145 wool 0 
setblock ~15 ~2 ~147 glowstone 0 
setblock ~15 ~2 ~149 wool 0 
setblock ~15 ~2 ~160 torch 3  
fill ~16 ~2 ~13 ~16 ~2 ~17 wool 15  
fill ~16 ~2 ~25 ~17 ~2 ~25 stone 0  
fill ~16 ~2 ~43 ~18 ~2 ~43 stone 0  
fill ~16 ~2 ~46 ~17 ~2 ~46 stonebrick 0 
setblock ~16 ~2 ~47 glowstone 0  
fill ~16 ~2 ~56 ~17 ~2 ~56 stonebrick 0 
setblock ~16 ~2 ~57 glowstone 0 
setblock ~16 ~2 ~60 glowstone 0  
fill ~16 ~2 ~88 ~22 ~2 ~88 stone 0  
fill ~16 ~2 ~92 ~22 ~2 ~92 stone 0  
fill ~16 ~2 ~123 ~17 ~2 ~123 stonebrick 0  
fill ~16 ~2 ~125 ~17 ~2 ~125 planks 0  
fill ~16 ~2 ~126 ~18 ~2 ~126 planks 0  
fill ~16 ~2 ~127 ~24 ~2 ~127 planks 0  
fill ~16 ~2 ~131 ~23 ~2 ~131 planks 0  
fill ~16 ~2 ~132 ~21 ~2 ~132 planks 0  
fill ~16 ~2 ~133 ~23 ~2 ~133 planks 0  
fill ~16 ~2 ~135 ~21 ~2 ~135 planks 0  
fill ~16 ~2 ~137 ~22 ~2 ~137 planks 0  
fill ~16 ~2 ~138 ~22 ~2 ~138 planks 0  
fill ~16 ~2 ~139 ~22 ~2 ~139 planks 0  
fill ~16 ~2 ~141 ~21 ~2 ~141 planks 0  
fill ~16 ~2 ~143 ~21 ~2 ~143 planks 0  
fill ~16 ~2 ~144 ~21 ~2 ~144 planks 0  
fill ~16 ~2 ~145 ~21 ~2 ~145 planks 0  
fill ~16 ~2 ~147 ~19 ~2 ~147 planks 0  
fill ~16 ~2 ~149 ~19 ~2 ~149 planks 0 
setblock ~17 ~2 ~13 torch 1  
fill ~17 ~2 ~16 ~17 ~2 ~20 wool 15  
fill ~17 ~2 ~44 ~18 ~2 ~44 stone 0  
fill ~17 ~2 ~47 ~19 ~2 ~47 stone 0  
fill ~17 ~2 ~53 ~20 ~2 ~53 stone 0  
fill ~17 ~2 ~57 ~20 ~2 ~57 stone 0  
fill ~17 ~2 ~60 ~21 ~2 ~60 stone 0 
setblock ~17 ~2 ~107 glowstone 0 
setblock ~17 ~2 ~109 glowstone 0 
setblock ~17 ~2 ~120 glowstone 0  
fill ~17 ~2 ~124 ~21 ~2 ~124 stone 0 
setblock ~18 ~2 ~19 torch 1  
fill ~18 ~2 ~21 ~18 ~2 ~25 wool 15  
fill ~18 ~2 ~45 ~18 ~2 ~125 stone 0 
setblock ~18 ~2 ~157 wool 15 
setblock ~19 ~2 ~25 torch 1  
fill ~19 ~2 ~26 ~19 ~2 ~31 wool 15  
fill ~19 ~2 ~40 ~19 ~2 ~46 glowstone 0  
fill ~19 ~2 ~54 ~20 ~2 ~54 stone 0  
fill ~19 ~2 ~55 ~20 ~2 ~55 stone 0  
fill ~19 ~2 ~56 ~20 ~2 ~56 stone 0  
fill ~19 ~2 ~107 ~22 ~2 ~107 stone 0  
fill ~19 ~2 ~109 ~22 ~2 ~109 stone 0  
fill ~19 ~2 ~120 ~22 ~2 ~120 stone 0  
fill ~19 ~2 ~121 ~22 ~2 ~121 stone 0  
fill ~19 ~2 ~122 ~23 ~2 ~122 stone 0  
fill ~19 ~2 ~123 ~24 ~2 ~123 stone 0 
setblock ~19 ~2 ~125 stone 0  
fill ~19 ~2 ~126 ~24 ~2 ~126 glowstone 0 
setblock ~19 ~2 ~156 wool 15 
setblock ~19 ~2 ~157 torch 1 
setblock ~20 ~2 ~31 torch 1  
fill ~20 ~2 ~32 ~20 ~2 ~37 wool 15  
fill ~20 ~2 ~40 ~20 ~2 ~46 stone 0  
fill ~20 ~2 ~47 ~20 ~2 ~52 glowstone 0 
setblock ~20 ~2 ~125 planks 0  
fill ~20 ~2 ~147 ~21 ~2 ~147 stone 0  
fill ~20 ~2 ~148 ~21 ~2 ~148 stone 0  
fill ~20 ~2 ~149 ~21 ~2 ~149 stone 0  
fill ~20 ~2 ~153 ~21 ~2 ~153 wool 15  
fill ~20 ~2 ~154 ~20 ~2 ~155 wool 15  
fill ~21 ~2 ~37 ~21 ~2 ~41 wool 15 
setblock ~21 ~2 ~42 stone 0 
setblock ~21 ~2 ~43 stone_brick_stairs 3  
fill ~21 ~2 ~47 ~22 ~2 ~47 stone 0  
fill ~21 ~2 ~48 ~22 ~2 ~48 stone 0  
fill ~21 ~2 ~49 ~22 ~2 ~49 stone 0  
fill ~21 ~2 ~50 ~22 ~2 ~50 stone 0  
fill ~21 ~2 ~51 ~23 ~2 ~51 stone 0  
fill ~21 ~2 ~52 ~23 ~2 ~52 stone 0  
fill ~21 ~2 ~53 ~21 ~2 ~59 glowstone 0  
fill ~21 ~2 ~125 ~24 ~2 ~125 stone 0  
fill ~21 ~2 ~146 ~22 ~2 ~146 stone 0  
fill ~21 ~2 ~151 ~21 ~2 ~153 wool 15 
setblock ~22 ~2 ~37 torch 1  
fill ~22 ~2 ~42 ~22 ~2 ~45 wool 15 
setblock ~22 ~2 ~46 stone 0  
fill ~22 ~2 ~53 ~23 ~2 ~53 stone 0  
fill ~22 ~2 ~54 ~23 ~2 ~54 stone 0  
fill ~22 ~2 ~55 ~23 ~2 ~55 stone 0  
fill ~22 ~2 ~56 ~23 ~2 ~56 stone 0  
fill ~22 ~2 ~57 ~23 ~2 ~57 stone 0  
fill ~22 ~2 ~58 ~23 ~2 ~58 stone 0  
fill ~22 ~2 ~59 ~23 ~2 ~59 stone 0  
fill ~22 ~2 ~60 ~22 ~2 ~66 glowstone 0 
setblock ~22 ~2 ~124 glowstone 0  
fill ~22 ~2 ~132 ~23 ~2 ~132 glowstone 0  
fill ~22 ~2 ~135 ~23 ~2 ~135 glowstone 0  
fill ~22 ~2 ~140 ~22 ~2 ~146 stone 0  
fill ~22 ~2 ~147 ~22 ~2 ~150 wool 15 
setblock ~22 ~2 ~151 torch 1 
setblock ~23 ~2 ~43 torch 1  
fill ~23 ~2 ~46 ~23 ~2 ~50 wool 15  
fill ~23 ~2 ~60 ~23 ~2 ~67 stone 0   
fill ~23 ~2 ~68 ~23 ~2 ~121 glowstone 0  
fill ~23 ~2 ~124 ~24 ~2 ~124 stone 0  
fill ~23 ~2 ~136 ~23 ~2 ~139 stone 0  
fill ~23 ~2 ~140 ~24 ~2 ~140 wool 15  
fill ~23 ~2 ~141 ~24 ~2 ~141 wool 15  
fill ~23 ~2 ~142 ~23 ~2 ~146 wool 15 
setblock ~24 ~2 ~49 torch 1  
fill ~24 ~2 ~51 ~24 ~2 ~60 wool 15 
setblock ~24 ~2 ~61 stone 0 
setblock ~24 ~2 ~62 glowstone 0  
fill ~24 ~2 ~63 ~25 ~2 ~63 stone 0  
fill ~24 ~2 ~64 ~25 ~2 ~64 stone 0  
fill ~24 ~2 ~65 ~25 ~2 ~65 stone 0  
fill ~24 ~2 ~66 ~25 ~2 ~66 stone 0  
fill ~24 ~2 ~68 ~25 ~2 ~68 stone 0  
fill ~24 ~2 ~69 ~25 ~2 ~69 stone 0  
fill ~24 ~2 ~70 ~25 ~2 ~70 stone 0  
fill ~24 ~2 ~71 ~25 ~2 ~71 stone 0  
fill ~24 ~2 ~72 ~25 ~2 ~72 stone 0  
fill ~24 ~2 ~73 ~25 ~2 ~73 stone 0  
fill ~24 ~2 ~74 ~25 ~2 ~74 stone 0  
fill ~24 ~2 ~75 ~25 ~2 ~75 stone 0  
fill ~24 ~2 ~76 ~25 ~2 ~76 stone 0  
fill ~24 ~2 ~77 ~25 ~2 ~77 stone 0  
fill ~24 ~2 ~78 ~25 ~2 ~78 stone 0  
fill ~24 ~2 ~79 ~25 ~2 ~79 stone 0  
fill ~24 ~2 ~80 ~25 ~2 ~80 stone 0  
fill ~24 ~2 ~81 ~25 ~2 ~81 stone 0  
fill ~24 ~2 ~82 ~25 ~2 ~82 stone 0  
fill ~24 ~2 ~83 ~25 ~2 ~83 stone 0  
fill ~24 ~2 ~84 ~25 ~2 ~84 stone 0  
fill ~24 ~2 ~85 ~25 ~2 ~85 stone 0  
fill ~24 ~2 ~86 ~25 ~2 ~86 stone 0  
fill ~24 ~2 ~87 ~25 ~2 ~87 stone 0  
fill ~24 ~2 ~88 ~25 ~2 ~88 stone 0  
fill ~24 ~2 ~89 ~25 ~2 ~89 stone 0  
fill ~24 ~2 ~90 ~25 ~2 ~90 stone 0  
fill ~24 ~2 ~91 ~25 ~2 ~91 stone 0  
fill ~24 ~2 ~92 ~25 ~2 ~92 stone 0  
fill ~24 ~2 ~93 ~25 ~2 ~93 stone 0  
fill ~24 ~2 ~94 ~25 ~2 ~94 stone 0  
fill ~24 ~2 ~95 ~25 ~2 ~95 stone 0  
fill ~24 ~2 ~96 ~25 ~2 ~96 stone 0  
fill ~24 ~2 ~97 ~25 ~2 ~97 stone 0  
fill ~24 ~2 ~98 ~25 ~2 ~98 stone 0  
fill ~24 ~2 ~99 ~25 ~2 ~99 stone 0  
fill ~24 ~2 ~100 ~25 ~2 ~100 stone 0  
fill ~24 ~2 ~101 ~25 ~2 ~101 stone 0  
fill ~24 ~2 ~102 ~25 ~2 ~102 stone 0  
fill ~24 ~2 ~103 ~25 ~2 ~103 stone 0  
fill ~24 ~2 ~104 ~25 ~2 ~104 stone 0  
fill ~24 ~2 ~105 ~25 ~2 ~105 stone 0  
fill ~24 ~2 ~106 ~25 ~2 ~106 stone 0  
fill ~24 ~2 ~107 ~25 ~2 ~107 stone 0  
fill ~24 ~2 ~108 ~25 ~2 ~108 stone 0  
fill ~24 ~2 ~109 ~25 ~2 ~109 stone 0  
fill ~24 ~2 ~110 ~25 ~2 ~110 stone 0  
fill ~24 ~2 ~111 ~25 ~2 ~111 stone 0  
fill ~24 ~2 ~112 ~25 ~2 ~112 stone 0  
fill ~24 ~2 ~113 ~25 ~2 ~113 stone 0  
fill ~24 ~2 ~114 ~25 ~2 ~114 stone 0  
fill ~24 ~2 ~115 ~25 ~2 ~115 stone 0  
fill ~24 ~2 ~116 ~25 ~2 ~116 stone 0  
fill ~24 ~2 ~117 ~25 ~2 ~117 stone 0  
fill ~24 ~2 ~118 ~25 ~2 ~118 stone 0  
fill ~24 ~2 ~119 ~25 ~2 ~119 stone 0  
fill ~24 ~2 ~120 ~25 ~2 ~120 stone 0  
fill ~24 ~2 ~121 ~25 ~2 ~121 stone 0 
setblock ~24 ~2 ~122 stone_brick_stairs 1  
fill ~24 ~2 ~131 ~24 ~2 ~133 stone 0  
fill ~24 ~2 ~134 ~25 ~2 ~134 wool 15  
fill ~24 ~2 ~135 ~25 ~2 ~135 wool 15  
fill ~24 ~2 ~136 ~24 ~2 ~141 wool 15 
setblock ~24 ~2 ~145 torch 1 
setblock ~25 ~2 ~55 torch 1  
fill ~25 ~2 ~56 ~25 ~2 ~61 wool 15 
setblock ~25 ~2 ~62 stone 0  
fill ~25 ~2 ~126 ~25 ~2 ~130 stone 0  
fill ~25 ~2 ~131 ~25 ~2 ~135 wool 15 
setblock ~25 ~2 ~139 torch 1  
fill ~26 ~2 ~60 ~26 ~2 ~130 wool 15 
setblock ~26 ~2 ~133 torch 1 
setblock ~27 ~2 ~61 torch 1 
setblock ~27 ~2 ~67 torch 1 
setblock ~27 ~2 ~73 torch 1 
setblock ~27 ~2 ~79 torch 1 
setblock ~27 ~2 ~85 torch 1 
setblock ~27 ~2 ~91 torch 1 
setblock ~27 ~2 ~97 torch 1 
setblock ~27 ~2 ~103 torch 1 
setblock ~27 ~2 ~109 torch 1 
setblock ~27 ~2 ~115 torch 1 
setblock ~27 ~2 ~121 torch 1 
setblock ~27 ~2 ~127 torch 1 
setblock ~2 ~3 ~88 stonebrick 0 
setblock ~2 ~3 ~91 stonebrick 0 
setblock ~3 ~3 ~88 lit_pumpkin 1 
setblock ~3 ~3 ~91 lit_pumpkin 1  
fill ~4 ~3 ~60 ~6 ~3 ~60 stonebrick 0  
fill ~4 ~3 ~61 ~11 ~3 ~61 stonebrick 0  
fill ~4 ~3 ~62 ~4 ~6 ~62 stonebrick 0  
fill ~4 ~3 ~63 ~4 ~6 ~63 stonebrick 0  
fill ~4 ~3 ~64 ~4 ~6 ~64 stonebrick 0  
fill ~4 ~3 ~65 ~4 ~6 ~65 stonebrick 0  
fill ~4 ~3 ~66 ~4 ~6 ~66 stonebrick 0  
fill ~4 ~3 ~67 ~4 ~6 ~67 stonebrick 0  
fill ~4 ~3 ~68 ~4 ~6 ~68 stonebrick 0  
fill ~4 ~3 ~69 ~4 ~6 ~69 stonebrick 0  
fill ~4 ~3 ~70 ~4 ~6 ~70 stonebrick 0  
fill ~4 ~3 ~71 ~4 ~6 ~71 stonebrick 0  
fill ~4 ~3 ~72 ~4 ~6 ~72 stonebrick 0  
fill ~4 ~3 ~73 ~5 ~3 ~73 stonebrick 0  
fill ~4 ~3 ~74 ~4 ~6 ~74 stonebrick 0  
fill ~4 ~3 ~75 ~4 ~6 ~75 stonebrick 0  
fill ~4 ~3 ~76 ~4 ~6 ~76 stonebrick 0  
fill ~4 ~3 ~77 ~4 ~6 ~77 stonebrick 0  
fill ~4 ~3 ~78 ~4 ~6 ~78 stonebrick 0  
fill ~4 ~3 ~79 ~4 ~6 ~79 stonebrick 0  
fill ~4 ~3 ~80 ~4 ~6 ~80 stonebrick 0  
fill ~4 ~3 ~81 ~4 ~6 ~81 stonebrick 0  
fill ~4 ~3 ~82 ~4 ~6 ~82 stonebrick 0  
fill ~4 ~3 ~83 ~4 ~6 ~83 stonebrick 0  
fill ~4 ~3 ~84 ~4 ~6 ~84 stonebrick 0  
fill ~4 ~3 ~85 ~5 ~3 ~85 stonebrick 0  
fill ~4 ~3 ~86 ~4 ~6 ~86 stonebrick 0  
fill ~4 ~3 ~87 ~4 ~6 ~87 stonebrick 0  
fill ~4 ~3 ~88 ~4 ~6 ~88 stonebrick 0  
