fill ~65~34~7 ~66~34~13 minecraft:stained_hardened_clay 7
fill ~65~35~7 ~66~35~12 minecraft:stained_hardened_clay 7
fill ~65~36~7 ~70~37~7 minecraft:stained_hardened_clay 7
fill ~65~38~7 ~66~39~11 minecraft:stained_hardened_clay 7
setblock ~65~40~7 minecraft:wool 12
fill ~66~33~7 ~67~33~13 minecraft:stained_hardened_clay 7
fill ~66~40~7 ~68~40~8 minecraft:stained_hardened_clay 7
setblock ~66~41~7 minecraft:wool 12
fill ~67~34~7 ~67~35~7 minecraft:stained_hardened_clay 12
setblock ~67~38~7 minecraft:stained_hardened_clay 12
fill ~67~39~7 ~67~39~12 minecraft:stained_hardened_clay 7
fill ~67~41~7 ~67~42~7 minecraft:stained_hardened_clay 12
setblock ~67~43~7 minecraft:wool 12
fill ~68~34~7 ~69~35~9 minecraft:stained_hardened_clay 7
fill ~68~38~7 ~68~38~11 minecraft:stained_hardened_clay 7
fill ~68~39~7 ~70~39~7 minecraft:stained_hardened_clay 12
fill ~68~41~7 ~71~41~9 minecraft:stained_hardened_clay 7
fill ~68~42~7 ~68~43~12 minecraft:stained_hardened_clay 7
setblock ~68~44~7 minecraft:wool 12
setblock ~69~38~7 minecraft:stained_hardened_clay 12
setblock ~69~40~7 minecraft:stained_hardened_clay 12
setblock ~69~42~7 minecraft:stained_hardened_clay 12
fill ~69~43~7 ~72~44~9 minecraft:stained_hardened_clay 7
fill ~69~45~7 ~70~45~7 minecraft:wool 12
setblock ~70~35~7 minecraft:stained_hardened_clay 7
fill ~70~38~7 ~71~38~7 minecraft:stained_hardened_clay 7
fill ~70~40~7 ~71~40~10 minecraft:stained_hardened_clay 7
fill ~70~42~7 ~74~42~7 minecraft:stained_hardened_clay 7
fill ~71~37~7 ~71~37~9 minecraft:stained_hardened_clay 7
fill ~71~39~7 ~72~39~7 minecraft:stained_hardened_clay 7
fill ~71~45~7 ~73~45~7 minecraft:stained_hardened_clay 7
setblock ~71~46~7 minecraft:wool 12
setblock ~72~38~7 minecraft:stained_hardened_clay 12
fill ~72~40~7 ~72~41~8 minecraft:stained_hardened_clay 12
setblock ~72~46~7 minecraft:wool 7
fill ~73~40~7 ~73~41~7 minecraft:stained_hardened_clay 7
setblock ~73~43~7 minecraft:stained_hardened_clay 12
fill ~73~44~7 ~74~44~7 minecraft:stained_hardened_clay 7
setblock ~73~46~7 minecraft:wool 12
fill ~74~41~7 ~74~41~11 minecraft:stained_hardened_clay 7
setblock ~74~43~7 minecraft:stained_hardened_clay 7
setblock ~74~45~7 minecraft:wool 8
fill ~63~34~8 ~64~35~13 minecraft:stained_hardened_clay 7
fill ~63~36~8 ~63~36~14 minecraft:stained_hardened_clay 7
fill ~63~37~8 ~64~40~12 minecraft:stained_hardened_clay 7
setblock ~63~41~8 minecraft:wool 12
fill ~64~32~8 ~69~32~13 minecraft:stained_hardened_clay 7
fill ~64~33~8 ~65~33~10 minecraft:stained_hardened_clay 7
setblock ~64~36~8 minecraft:stained_hardened_clay 12
setblock ~64~41~8 minecraft:stained_hardened_clay 12
setblock ~64~42~8 minecraft:wool 12
fill ~65~36~8 ~67~36~11 minecraft:stained_hardened_clay 7
setblock ~65~37~8 minecraft:stained_hardened_clay 12
fill ~65~40~8 ~65~42~13 minecraft:stained_hardened_clay 7
setblock ~65~43~8 minecraft:wool 12
fill ~66~37~8 ~68~37~10 minecraft:stained_hardened_clay 7
fill ~66~41~8 ~67~41~13 minecraft:stained_hardened_clay 7
setblock ~66~42~8 minecraft:stained_hardened_clay 12
fill ~66~43~8 ~67~43~11 minecraft:stained_hardened_clay 7
setblock ~66~44~8 minecraft:wool 8
setblock ~67~31~8 minecraft:stained_hardened_clay 12
fill ~67~34~8 ~67~34~13 minecraft:stained_hardened_clay 7
setblock ~67~35~8 minecraft:stained_hardened_clay 12
fill ~67~38~8 ~67~38~11 minecraft:stained_hardened_clay 7
fill ~67~42~8 ~67~42~9 minecraft:stained_hardened_clay 7
fill ~67~44~8 ~68~44~11 minecraft:stained_hardened_clay 7
setblock ~67~45~8 minecraft:wool 12
fill ~68~31~8 ~68~31~12 minecraft:stained_hardened_clay 7
fill ~68~33~8 ~70~33~11 minecraft:stained_hardened_clay 7
setblock ~68~36~8 minecraft:stained_hardened_clay 12
setblock ~68~39~8 minecraft:stained_hardened_clay 12
fill ~68~45~8 ~68~45~14 minecraft:stained_hardened_clay 7
setblock ~68~46~8 minecraft:wool 12
fill ~69~36~8 ~72~36~9 minecraft:stained_hardened_clay 7
fill ~69~37~8 ~70~37~8 minecraft:stained_hardened_clay 12
fill ~69~38~8 ~70~38~12 minecraft:stained_hardened_clay 7
fill ~69~39~8 ~70~39~10 minecraft:stained_hardened_clay 7
fill ~69~40~8 ~69~40~11 minecraft:stained_hardened_clay 7
fill ~69~42~8 ~72~42~9 minecraft:stained_hardened_clay 7
setblock ~69~45~8 minecraft:stained_hardened_clay 12
setblock ~69~46~8 minecraft:wool 7
fill ~70~34~8 ~71~34~11 minecraft:stained_hardened_clay 7
fill ~70~35~8 ~70~35~9 minecraft:stained_hardened_clay 12
fill ~70~45~8 ~71~46~14 minecraft:stained_hardened_clay 7
fill ~70~47~8 ~71~47~8 minecraft:wool 12
fill ~71~35~8 ~71~35~12 minecraft:stained_hardened_clay 7
fill ~71~38~8 ~71~39~8 minecraft:stained_hardened_clay 12
fill ~72~37~8 ~72~37~10 minecraft:stained_hardened_clay 7
fill ~72~38~8 ~73~39~8 minecraft:stained_hardened_clay 7
setblock ~72~45~8 minecraft:stained_hardened_clay 12
fill ~72~46~8 ~72~47~11 minecraft:stained_hardened_clay 7
setblock ~72~48~8 minecraft:wool 12
setblock ~73~37~8 minecraft:stained_hardened_clay 12
fill ~73~40~8 ~75~40~8 minecraft:stained_hardened_clay 12
fill ~73~41~8 ~73~41~12 minecraft:stained_hardened_clay 7
setblock ~73~42~8 minecraft:stained_hardened_clay 12
setblock ~73~43~8 minecraft:stained_hardened_clay 7
fill ~73~44~8 ~73~44~9 minecraft:stained_hardened_clay 12
fill ~73~45~8 ~76~45~8 minecraft:stained_hardened_clay 7
fill ~73~46~8 ~74~46~8 minecraft:stained_hardened_clay 12
fill ~73~47~8 ~74~47~9 minecraft:stained_hardened_clay 7
setblock ~73~48~8 minecraft:wool 7
fill ~74~39~8 ~74~39~17 minecraft:stained_hardened_clay 12
fill ~74~42~8 ~74~42~11 minecraft:stained_hardened_clay 7
setblock ~74~43~8 minecraft:stained_hardened_clay 12
fill ~74~44~8 ~75~44~13 minecraft:stained_hardened_clay 7
setblock ~74~48~8 minecraft:wool 12
fill ~75~41~8 ~75~41~18 minecraft:stained_hardened_clay 12
fill ~75~42~8 ~75~42~9 minecraft:stained_hardened_clay 12
fill ~75~43~8 ~76~43~10 minecraft:stained_hardened_clay 7
fill ~75~46~8 ~75~46~10 minecraft:stained_hardened_clay 7
setblock ~75~47~8 minecraft:wool 7
fill ~76~42~8 ~76~42~11 minecraft:stained_hardened_clay 7
fill ~76~44~8 ~76~44~9 minecraft:stained_hardened_clay 12
setblock ~76~46~8 minecraft:wool 8
fill ~61~35~9 ~61~37~15 minecraft:stained_hardened_clay 7
fill ~61~38~9 ~62~39~11 minecraft:stained_hardened_clay 7
setblock ~61~40~9 minecraft:wool 8
setblock ~62~32~9 minecraft:stained_hardened_clay 12
fill ~62~33~9 ~63~33~10 minecraft:stained_hardened_clay 7
fill ~62~34~9 ~62~34~14 minecraft:stained_hardened_clay 7
setblock ~62~35~9 minecraft:stained_hardened_clay 12
fill ~62~36~9 ~62~37~15 minecraft:stained_hardened_clay 7
fill ~62~40~9 ~62~41~16 minecraft:stained_hardened_clay 7
setblock ~62~42~9 minecraft:wool 7
setblock ~63~31~9 minecraft:stained_hardened_clay 12
fill ~63~32~9 ~63~32~12 minecraft:stained_hardened_clay 7
fill ~63~41~9 ~64~41~13 minecraft:stained_hardened_clay 7
fill ~63~42~9 ~63~42~14 minecraft:stained_hardened_clay 7
setblock ~63~43~9 minecraft:stained_hardened_clay 12
setblock ~63~44~9 minecraft:wool 7
fill ~64~31~9 ~67~31~11 minecraft:stained_hardened_clay 7
fill ~64~36~9 ~64~36~14 minecraft:stained_hardened_clay 7
setblock ~64~42~9 minecraft:stained_hardened_clay 12
fill ~64~43~9 ~64~43~14 minecraft:stained_hardened_clay 7
fill ~64~44~9 ~66~44~13 minecraft:stained_hardened_clay 7
setblock ~64~45~9 minecraft:wool 7
fill ~65~37~9 ~65~37~10 minecraft:stained_hardened_clay 7
fill ~65~43~9 ~65~43~10 minecraft:stained_hardened_clay 12
fill ~65~45~9 ~67~45~10 minecraft:stained_hardened_clay 7
setblock ~65~46~9 minecraft:wool 7
fill ~66~30~9 ~69~30~11 minecraft:stained_hardened_clay 7
fill ~66~40~9 ~66~40~14 minecraft:stained_hardened_clay 7
fill ~66~42~9 ~66~42~13 minecraft:stained_hardened_clay 7
fill ~66~46~9 ~69~46~11 minecraft:stained_hardened_clay 7
setblock ~66~47~9 minecraft:wool 7
fill ~67~35~9 ~67~35~13 minecraft:stained_hardened_clay 7
setblock ~67~40~9 minecraft:stained_hardened_clay 12
fill ~67~47~9 ~67~47~15 minecraft:stained_hardened_clay 7
setblock ~67~48~9 minecraft:wool 12
fill ~68~36~9 ~68~36~11 minecraft:stained_hardened_clay 7
fill ~68~39~9 ~68~40~9 minecraft:stained_hardened_clay 7
setblock ~68~47~9 minecraft:stained_hardened_clay 12
setblock ~68~48~9 minecraft:wool 7
fill ~69~31~9 ~70~31~11 minecraft:stained_hardened_clay 7
fill ~69~37~9 ~70~37~12 minecraft:stained_hardened_clay 7
fill ~69~45~9 ~69~45~12 minecraft:stained_hardened_clay 7
fill ~69~47~9 ~71~47~10 minecraft:stained_hardened_clay 7
fill ~69~48~9 ~69~48~13 minecraft:stained_hardened_clay 7
fill ~69~49~9 ~70~49~9 minecraft:wool 12
fill ~70~32~9 ~70~32~12 minecraft:stained_hardened_clay 7
setblock ~70~48~9 minecraft:stained_hardened_clay 12
setblock ~71~32~9 minecraft:stained_hardened_clay 12
fill ~71~33~9 ~72~33~9 minecraft:stained_hardened_clay 7
fill ~71~38~9 ~71~39~9 minecraft:stained_hardened_clay 7
fill ~71~48~9 ~71~49~10 minecraft:stained_hardened_clay 7
setblock ~71~50~9 minecraft:wool 7
fill ~72~34~9 ~72~34~17 minecraft:stained_hardened_clay 7
fill ~72~35~9 ~73~35~10 minecraft:stained_hardened_clay 7
setblock ~72~38~9 minecraft:stained_hardened_clay 12
fill ~72~39~9 ~73~40~9 minecraft:stained_hardened_clay 7
setblock ~72~41~9 minecraft:stained_hardened_clay 7
fill ~72~45~9 ~72~45~14 minecraft:stained_hardened_clay 7
setblock ~72~48~9 minecraft:stained_hardened_clay 12
fill ~72~49~9 ~73~49~12 minecraft:stained_hardened_clay 7
fill ~72~50~9 ~73~50~9 minecraft:wool 8
fill ~73~36~9 ~74~38~9 minecraft:stained_hardened_clay 7
fill ~73~42~9 ~73~42~13 minecraft:stained_hardened_clay 7
setblock ~73~43~9 minecraft:stained_hardened_clay 12
setblock ~73~45~9 minecraft:stained_hardened_clay 12
fill ~73~46~9 ~74~46~10 minecraft:stained_hardened_clay 7
fill ~73~48~9 ~73~48~14 minecraft:stained_hardened_clay 7
setblock ~74~40~9 minecraft:stained_hardened_clay 7
setblock ~74~43~9 minecraft:stained_hardened_clay 7
fill ~74~45~9 ~78~45~10 minecraft:stained_hardened_clay 7
fill ~74~48~9 ~74~49~9 minecraft:stained_hardened_clay 12
fill ~74~50~9 ~75~50~9 minecraft:wool 7
fill ~75~38~9 ~75~40~9 minecraft:stained_hardened_clay 12
fill ~75~47~9 ~77~48~9 minecraft:stained_hardened_clay 7
fill ~75~49~9 ~75~49~10 minecraft:stained_hardened_clay 12
fill ~76~39~9 ~76~40~17 minecraft:stained_hardened_clay 12
setblock ~76~41~9 minecraft:stained_hardened_clay 7
setblock ~76~46~9 minecraft:stained_hardened_clay 7
setblock ~76~49~9 minecraft:wool 8
fill ~77~41~9 ~77~42~9 minecraft:stained_hardened_clay 12
fill ~77~43~9 ~78~44~10 minecraft:stained_hardened_clay 7
setblock ~77~46~9 minecraft:stained_hardened_clay 12
setblock ~77~49~9 minecraft:wool 7
fill ~78~42~9 ~78~42~13 minecraft:stained_hardened_clay 7
fill ~78~46~9 ~78~46~12 minecraft:stained_hardened_clay 7
setblock ~78~47~9 minecraft:wool 7
fill ~52~52~10 ~52~52~11 minecraft:wool 12
setblock ~52~53~10 minecraft:wool 12
fill ~53~48~10 ~53~51~10 minecraft:wool 12
fill ~54~49~10 ~54~51~10 minecraft:wool 12
fill ~55~50~10 ~57~50~10 minecraft:wool 12
fill ~55~53~10 ~55~53~11 minecraft:wool 12
setblock ~55~54~10 minecraft:wool 12
fill ~56~48~10 ~56~49~10 minecraft:wool 12
setblock ~56~51~10 minecraft:wool 12
setblock ~57~49~10 minecraft:wool 12
fill ~59~35~10 ~60~38~14 minecraft:stained_hardened_clay 7
fill ~59~39~10 ~60~40~13 minecraft:stained_hardened_clay 7
setblock ~59~41~10 minecraft:wool 8
fill ~60~32~10 ~62~32~11 minecraft:stained_hardened_clay 7
fill ~60~33~10 ~61~34~12 minecraft:stained_hardened_clay 7
fill ~60~41~10 ~61~42~11 minecraft:stained_hardened_clay 7
setblock ~60~43~10 minecraft:wool 8
fill ~61~31~10 ~61~31~11 minecraft:stained_hardened_clay 12
fill ~61~40~10 ~61~40~16 minecraft:stained_hardened_clay 7
fill ~61~43~10 ~63~43~14 minecraft:stained_hardened_clay 7
fill ~61~44~10 ~63~44~13 minecraft:stained_hardened_clay 7
setblock ~61~45~10 minecraft:wool 8
fill ~62~29~10 ~71~29~10 minecraft:stained_hardened_clay 7
fill ~62~30~10 ~65~30~12 minecraft:stained_hardened_clay 7
fill ~62~31~10 ~63~31~11 minecraft:stained_hardened_clay 7
fill ~62~35~10 ~62~35~15 minecraft:stained_hardened_clay 7
fill ~62~42~10 ~62~42~16 minecraft:stained_hardened_clay 7
fill ~62~45~10 ~64~45~11 minecraft:stained_hardened_clay 7
setblock ~62~46~10 minecraft:wool 12
fill ~63~28~10 ~70~28~11 minecraft:stained_hardened_clay 7
fill ~63~46~10 ~65~46~11 minecraft:stained_hardened_clay 7
fill ~63~47~10 ~66~47~10 minecraft:stained_hardened_clay 7
setblock ~63~48~10 minecraft:wool 7
fill ~64~42~10 ~64~42~15 minecraft:stained_hardened_clay 7
setblock ~64~48~10 minecraft:stained_hardened_clay 12
setblock ~64~49~10 minecraft:wool 7
fill ~65~27~10 ~67~27~10 minecraft:stained_hardened_clay 7
fill ~65~48~10 ~68~48~10 minecraft:stained_hardened_clay 7
setblock ~65~49~10 minecraft:wool 8
fill ~66~49~10 ~70~49~12 minecraft:stained_hardened_clay 7
setblock ~66~50~10 minecraft:wool 7
fill ~67~40~10 ~68~40~11 minecraft:stained_hardened_clay 7
setblock ~67~42~10 minecraft:stained_hardened_clay 12
setblock ~67~50~10 minecraft:stained_hardened_clay 12
setblock ~67~51~10 minecraft:wool 7
fill ~68~27~10 ~68~27~15 minecraft:stained_hardened_clay 12
fill ~68~34~10 ~68~35~12 minecraft:stained_hardened_clay 7
fill ~68~39~10 ~68~39~17 minecraft:stained_hardened_clay 12
fill ~68~41~10 ~70~41~10 minecraft:stained_hardened_clay 7
fill ~68~47~10 ~68~47~13 minecraft:stained_hardened_clay 7
fill ~68~50~10 ~76~50~10 minecraft:stained_hardened_clay 7
setblock ~68~51~10 minecraft:wool 8
setblock ~69~34~10 minecraft:stained_hardened_clay 12
fill ~69~35~10 ~70~35~10 minecraft:stained_hardened_clay 7
setblock ~69~36~10 minecraft:stained_hardened_clay 12
fill ~69~42~10 ~69~44~10 minecraft:stained_hardened_clay 7
setblock ~69~51~10 minecraft:wool 7
fill ~70~30~10 ~70~30~12 minecraft:stained_hardened_clay 7
fill ~70~36~10 ~70~36~11 minecraft:stained_hardened_clay 7
fill ~70~42~10 ~70~42~11 minecraft:stained_hardened_clay 12
fill ~70~43~10 ~71~44~13 minecraft:stained_hardened_clay 7
fill ~70~48~10 ~70~48~13 minecraft:stained_hardened_clay 7
fill ~70~51~10 ~71~51~10 minecraft:wool 8
setblock ~71~30~10 minecraft:stained_hardened_clay 12
fill ~71~31~10 ~72~31~17 minecraft:stained_hardened_clay 7
fill ~71~32~10 ~71~33~12 minecraft:stained_hardened_clay 7
fill ~71~36~10 ~73~36~10 minecraft:stained_hardened_clay 12
fill ~71~37~10 ~71~38~10 minecraft:stained_hardened_clay 12
fill ~71~39~10 ~72~39~10 minecraft:stained_hardened_clay 7
fill ~71~41~10 ~72~41~10 minecraft:stained_hardened_clay 12
fill ~71~42~10 ~71~42~13 minecraft:stained_hardened_clay 7
fill ~72~32~10 ~72~33~10 minecraft:stained_hardened_clay 12
fill ~72~38~10 ~72~38~11 minecraft:stained_hardened_clay 7
fill ~72~40~10 ~73~40~10 minecraft:stained_hardened_clay 7
fill ~72~42~10 ~72~43~10 minecraft:stained_hardened_clay 12
fill ~72~44~10 ~73~44~11 minecraft:stained_hardened_clay 7
setblock ~72~48~10 minecraft:stained_hardened_clay 7
fill ~72~51~10 ~73~51~11 minecraft:stained_hardened_clay 7
setblock ~72~52~10 minecraft:wool 12
fill ~73~33~10 ~73~34~11 minecraft:stained_hardened_clay 7
setblock ~73~37~10 minecraft:stained_hardened_clay 7
fill ~73~38~10 ~74~38~10 minecraft:stained_hardened_clay 12
fill ~73~39~10 ~73~39~17 minecraft:stained_hardened_clay 12
fill ~73~43~10 ~73~43~11 minecraft:stained_hardened_clay 7
fill ~73~45~10 ~73~45~14 minecraft:stained_hardened_clay 7
fill ~73~47~10 ~73~47~11 minecraft:stained_hardened_clay 7
setblock ~73~52~10 minecraft:wool 7
fill ~74~35~10 ~74~35~14 minecraft:stained_hardened_clay 7
fill ~74~36~10 ~75~36~13 minecraft:stained_hardened_clay 7
setblock ~74~37~10 minecraft:stained_hardened_clay 12
fill ~74~40~10 ~75~40~18 minecraft:stained_hardened_clay 12
setblock ~74~43~10 minecraft:stained_hardened_clay 12
fill ~74~47~10 ~74~47~11 minecraft:stained_hardened_clay 12
fill ~74~48~10 ~77~48~10 minecraft:stained_hardened_clay 7
setblock ~74~49~10 minecraft:stained_hardened_clay 7
setblock ~74~51~10 minecraft:stained_hardened_clay 12
fill ~74~52~10 ~76~52~10 minecraft:wool 8
fill ~75~37~10 ~75~37~11 minecraft:stained_hardened_clay 7
setblock ~75~38~10 minecraft:stained_hardened_clay 7
fill ~75~39~10 ~75~39~17 minecraft:stained_hardened_clay 12
fill ~75~42~10 ~75~42~12 minecraft:stained_hardened_clay 7
setblock ~75~47~10 minecraft:stained_hardened_clay 7
setblock ~75~51~10 minecraft:stained_hardened_clay 7
fill ~76~37~10 ~76~37~18 minecraft:stained_hardened_clay 12
fill ~76~38~10 ~76~38~17 minecraft:stained_hardened_clay 12
fill ~76~41~10 ~76~41~18 minecraft:stained_hardened_clay 12
fill ~76~44~10 ~76~44~11 minecraft:stained_hardened_clay 7
fill ~76~46~10 ~76~46~12 minecraft:stained_hardened_clay 12
fill ~76~47~10 ~76~47~11 minecraft:stained_hardened_clay 12
fill ~76~49~10 ~77~49~10 minecraft:stained_hardened_clay 7
fill ~76~51~10 ~77~51~23 minecraft:stained_hardened_clay 12
fill ~77~38~10 ~77~39~13 minecraft:stained_hardened_clay 7
fill ~77~40~10 ~80~41~10 minecraft:stained_hardened_clay 7
fill ~77~42~10 ~77~42~19 minecraft:stained_hardened_clay 12
fill ~77~46~10 ~77~47~11 minecraft:stained_hardened_clay 7
fill ~77~50~10 ~78~50~10 minecraft:stained_hardened_clay 12
setblock ~77~52~10 minecraft:wool 7
fill ~78~39~10 ~78~39~15 minecraft:stained_hardened_clay 7
fill ~78~47~10 ~83~47~12 minecraft:stained_hardened_clay 7
fill ~78~48~10 ~78~48~21 minecraft:stained_hardened_clay 12
fill ~78~49~10 ~78~49~11 minecraft:stained_hardened_clay 12
setblock ~78~51~10 minecraft:wool 8
fill ~79~42~10 ~83~46~13 minecraft:stained_hardened_clay 7
fill ~79~48~10 ~80~48~15 minecraft:stained_hardened_clay 7
fill ~79~49~10 ~79~49~17 minecraft:stained_hardened_clay 7
setblock ~79~50~10 minecraft:wool 8
setblock ~80~49~10 minecraft:wool 7
fill ~81~41~10 ~82~41~16 minecraft:stained_hardened_clay 7
fill ~81~48~10 ~83~48~10 minecraft:wool 8
fill ~84~43~10 ~84~46~16 minecraft:stained_hardened_clay 7
setblock ~84~47~10 minecraft:wool 8
fill ~100~54~10 ~101~54~10 minecraft:wool 7
setblock ~100~55~10 minecraft:wool 7
fill ~21~39~11 ~26~39~11 minecraft:stained_hardened_clay 7
fill ~21~40~11 ~22~41~12 minecraft:stained_hardened_clay 7
fill ~22~38~11 ~22~38~13 minecraft:stained_hardened_clay 7
fill ~22~42~11 ~29~43~11 minecraft:stained_hardened_clay 7
fill ~23~37~11 ~23~38~11 minecraft:stained_hardened_clay 12
setblock ~23~40~11 minecraft:stained_hardened_clay 12
fill ~23~41~11 ~28~41~14 minecraft:stained_hardened_clay 7
fill ~23~44~11 ~27~44~15 minecraft:stained_hardened_clay 7
fill ~23~45~11 ~23~46~11 minecraft:stained_hardened_clay 12
fill ~24~37~11 ~24~38~11 minecraft:stained_hardened_clay 7
fill ~24~40~11 ~27~40~13 minecraft:stained_hardened_clay 7
fill ~24~45~11 ~31~45~12 minecraft:stained_hardened_clay 7
fill ~24~46~11 ~32~48~11 minecraft:stained_hardened_clay 7
fill ~24~49~11 ~27~49~11 minecraft:stained_hardened_clay 7
fill ~25~38~11 ~25~38~14 minecraft:stained_hardened_clay 7
fill ~26~50~11 ~33~50~11 minecraft:stained_hardened_clay 7
fill ~27~51~11 ~33~51~12 minecraft:stained_hardened_clay 7
fill ~28~44~11 ~28~44~13 minecraft:stained_hardened_clay 12
setblock ~28~49~11 minecraft:stained_hardened_clay 12
fill ~29~44~11 ~31~44~17 minecraft:stained_hardened_clay 7
fill ~29~49~11 ~33~49~11 minecraft:stained_hardened_clay 7
fill ~29~52~11 ~32~52~15 minecraft:stained_hardened_clay 7
fill ~30~43~11 ~30~43~15 minecraft:stained_hardened_clay 7
fill ~30~53~11 ~31~53~17 minecraft:stained_hardened_clay 7
fill ~33~48~11 ~33~48~18 minecraft:stained_hardened_clay 7
setblock ~33~52~11 minecraft:wool 12
fill ~40~44~11 ~40~44~12 minecraft:stained_hardened_clay 12
fill ~40~45~11 ~41~46~11 minecraft:stained_hardened_clay 7
fill ~40~47~11 ~41~47~11 minecraft:stained_hardened_clay 12
setblock ~40~48~11 minecraft:wool 12
setblock ~41~43~11 minecraft:stained_hardened_clay 12
setblock ~41~44~11 minecraft:stained_hardened_clay 7
fill ~41~48~11 ~42~48~11 minecraft:stained_hardened_clay 12
setblock ~41~49~11 minecraft:wool 12
fill ~42~42~11 ~43~42~21 minecraft:stained_hardened_clay 12
setblock ~42~43~11 minecraft:stained_hardened_clay 7
fill ~42~44~11 ~43~44~20 minecraft:stained_hardened_clay 12
fill ~42~45~11 ~42~45~21 minecraft:stained_hardened_clay 12
fill ~42~46~11 ~48~46~11 minecraft:stained_hardened_clay 7
fill ~42~47~11 ~45~47~11 minecraft:stained_hardened_clay 7
setblock ~42~49~11 minecraft:stained_hardened_clay 12
fill ~42~50~11 ~43~50~11 minecraft:wool 7
fill ~43~43~11 ~43~43~20 minecraft:stained_hardened_clay 12
setblock ~43~45~11 minecraft:stained_hardened_clay 7
fill ~43~48~11 ~43~49~11 minecraft:stained_hardened_clay 7
fill ~44~42~11 ~46~42~11 minecraft:stained_hardened_clay 7
fill ~44~43~11 ~44~44~11 minecraft:stained_hardened_clay 7
fill ~44~45~11 ~44~45~21 minecraft:stained_hardened_clay 12
setblock ~44~48~11 minecraft:wool 12
fill ~44~49~11 ~52~49~11 minecraft:stained_hardened_clay 7
setblock ~44~50~11 minecraft:wool 12
fill ~45~41~11 ~46~41~12 minecraft:stained_hardened_clay 7
fill ~45~43~11 ~45~43~20 minecraft:stained_hardened_clay 12
fill ~45~44~11 ~53~44~11 minecraft:stained_hardened_clay 7
setblock ~45~45~11 minecraft:stained_hardened_clay 7
setblock ~45~48~11 minecraft:stained_hardened_clay 12
setblock ~45~50~11 minecraft:wool 7
fill ~46~43~11 ~50~43~11 minecraft:stained_hardened_clay 7
fill ~46~45~11 ~46~45~21 minecraft:stained_hardened_clay 12
setblock ~46~47~11 minecraft:stained_hardened_clay 12
fill ~46~48~11 ~48~48~12 minecraft:stained_hardened_clay 7
fill ~46~50~11 ~59~50~11 minecraft:stained_hardened_clay 7
setblock ~46~51~11 minecraft:wool 8
fill ~47~41~11 ~47~42~11 minecraft:stained_hardened_clay 12
fill ~47~45~11 ~48~45~12 minecraft:stained_hardened_clay 7
fill ~47~47~11 ~47~47~12 minecraft:stained_hardened_clay 7
setblock ~47~51~11 minecraft:wool 7
fill ~48~41~11 ~51~42~11 minecraft:stained_hardened_clay 7
setblock ~48~47~11 minecraft:wool 12
setblock ~48~51~11 minecraft:wool 12
fill ~49~45~11 ~50~45~11 minecraft:wool 12
setblock ~49~46~11 minecraft:stained_hardened_clay 12
fill ~49~47~11 ~57~47~12 minecraft:stained_hardened_clay 7
fill ~49~48~11 ~52~48~11 minecraft:stained_hardened_clay 12
setblock ~49~51~11 minecraft:wool 7
fill ~50~46~11 ~52~46~13 minecraft:stained_hardened_clay 7
setblock ~50~51~11 minecraft:wool 8
fill ~51~40~11 ~51~40~12 minecraft:stained_hardened_clay 12
fill ~51~43~11 ~51~43~12 minecraft:stained_hardened_clay 12
fill ~51~45~11 ~61~45~12 minecraft:stained_hardened_clay 7
setblock ~51~51~11 minecraft:wool 7
fill ~52~40~11 ~53~40~15 minecraft:stained_hardened_clay 7
setblock ~52~41~11 minecraft:wool 12
fill ~52~42~11 ~52~42~15 minecraft:stained_hardened_clay 7
setblock ~52~43~11 minecraft:stained_hardened_clay 7
setblock ~52~51~11 minecraft:wool 12
fill ~52~55~11 ~52~55~12 minecraft:wool 12
fill ~53~39~11 ~58~39~13 minecraft:stained_hardened_clay 7
fill ~53~41~11 ~58~41~11 minecraft:stained_hardened_clay 7
fill ~53~42~11 ~53~43~11 minecraft:wool 12
setblock ~53~46~11 minecraft:stained_hardened_clay 12
fill ~53~48~11 ~54~48~16 minecraft:stained_hardened_clay 7
setblock ~53~49~11 minecraft:stained_hardened_clay 12
setblock ~53~51~11 minecraft:wool 7
setblock ~53~52~11 minecraft:wool 12
setblock ~54~40~11 minecraft:wool 12
fill ~54~42~11 ~54~42~14 minecraft:stained_hardened_clay 7
fill ~54~43~11 ~54~44~11 minecraft:wool 12
fill ~54~46~11 ~62~46~14 minecraft:stained_hardened_clay 7
fill ~54~49~11 ~59~49~12 minecraft:stained_hardened_clay 7
setblock ~54~51~11 minecraft:wool 12
fill ~55~40~11 ~58~40~11 minecraft:stained_hardened_clay 7
setblock ~55~42~11 minecraft:stained_hardened_clay 12
fill ~55~43~11 ~60~44~13 minecraft:stained_hardened_clay 7
setblock ~55~48~11 minecraft:stained_hardened_clay 12
setblock ~55~51~11 minecraft:wool 7
fill ~56~38~11 ~58~38~12 minecraft:stained_hardened_clay 7
setblock ~56~42~11 minecraft:wool 12
fill ~56~48~11 ~58~48~11 minecraft:stained_hardened_clay 7
setblock ~56~51~11 minecraft:wool 8
setblock ~56~52~11 minecraft:wool 12
fill ~57~34~11 ~59~34~15 minecraft:stained_hardened_clay 7
fill ~57~35~11 ~57~36~11 minecraft:stained_hardened_clay 7
setblock ~57~37~11 minecraft:stained_hardened_clay 12
fill ~57~42~11 ~59~42~15 minecraft:stained_hardened_clay 7
fill ~57~51~11 ~59~51~11 minecraft:wool 12
fill ~58~32~11 ~59~32~13 minecraft:stained_hardened_clay 7
setblock ~58~33~11 minecraft:stained_hardened_clay 12
fill ~58~35~11 ~58~36~11 minecraft:stained_hardened_clay 12
fill ~58~37~11 ~58~37~17 minecraft:stained_hardened_clay 7
setblock ~58~47~11 minecraft:stained_hardened_clay 12
fill ~59~31~11 ~60~31~14 minecraft:stained_hardened_clay 7
fill ~59~33~11 ~59~33~15 minecraft:stained_hardened_clay 7
setblock ~59~41~11 minecraft:stained_hardened_clay 12
fill ~59~47~11 ~64~47~12 minecraft:stained_hardened_clay 7
setblock ~59~48~11 minecraft:stained_hardened_clay 12
fill ~60~30~11 ~61~30~11 minecraft:stained_hardened_clay 7
fill ~60~48~11 ~60~48~14 minecraft:stained_hardened_clay 7
fill ~60~49~11 ~60~50~11 minecraft:stained_hardened_clay 12
fill ~60~51~11 ~63~51~11 minecraft:stained_hardened_clay 7
setblock ~60~52~11 minecraft:wool 8
fill ~61~28~11 ~62~29~12 minecraft:stained_hardened_clay 7
setblock ~61~48~11 minecraft:stained_hardened_clay 12
fill ~61~49~11 ~63~49~13 minecraft:stained_hardened_clay 7
fill ~61~50~11 ~64~50~11 minecraft:stained_hardened_clay 7
setblock ~61~52~11 minecraft:wool 7
fill ~62~27~11 ~65~27~12 minecraft:stained_hardened_clay 7
fill ~62~33~11 ~62~33~14 minecraft:stained_hardened_clay 7
fill ~62~48~11 ~65~48~14 minecraft:stained_hardened_clay 7
fill ~62~52~11 ~63~52~11 minecraft:wool 8
fill ~63~25~11 ~67~25~11 minecraft:stained_hardened_clay 7
fill ~63~26~11 ~66~26~11 minecraft:stained_hardened_clay 7
fill ~63~29~11 ~63~29~14 minecraft:stained_hardened_clay 7
fill ~63~33~11 ~64~33~11 minecraft:stained_hardened_clay 12
fill ~64~24~11 ~68~24~12 minecraft:stained_hardened_clay 7
setblock ~64~29~11 minecraft:stained_hardened_clay 12
setblock ~64~49~11 minecraft:stained_hardened_clay 12
fill ~64~51~11 ~64~51~22 minecraft:stained_hardened_clay 12
fill ~64~52~11 ~65~52~11 minecraft:wool 7
fill ~65~23~11 ~66~23~16 minecraft:stained_hardened_clay 7
fill ~65~29~11 ~65~29~12 minecraft:stained_hardened_clay 7
fill ~65~33~11 ~65~33~14 minecraft:stained_hardened_clay 7
setblock ~65~37~11 minecraft:stained_hardened_clay 12
fill ~65~43~11 ~65~43~12 minecraft:stained_hardened_clay 7
fill ~65~45~11 ~65~45~15 minecraft:stained_hardened_clay 7
fill ~65~47~11 ~66~47~11 minecraft:stained_hardened_clay 12
setblock ~65~49~11 minecraft:stained_hardened_clay 7
setblock ~65~50~11 minecraft:stained_hardened_clay 12
fill ~65~51~11 ~67~51~11 minecraft:stained_hardened_clay 7
fill ~66~27~11 ~67~27~11 minecraft:stained_hardened_clay 12
fill ~66~29~11 ~66~29~12 minecraft:stained_hardened_clay 12
fill ~66~37~11 ~66~37~12 minecraft:stained_hardened_clay 7
setblock ~66~45~11 minecraft:stained_hardened_clay 12
fill ~66~48~11 ~66~48~12 minecraft:stained_hardened_clay 12
fill ~66~50~11 ~72~50~11 minecraft:stained_hardened_clay 7
setblock ~66~52~11 minecraft:wool 8
fill ~67~26~11 ~69~26~14 minecraft:stained_hardened_clay 12
fill ~67~29~11 ~72~29~11 minecraft:stained_hardened_clay 7
fill ~67~37~11 ~67~37~17 minecraft:stained_hardened_clay 12
fill ~67~42~11 ~67~42~14 minecraft:stained_hardened_clay 7
fill ~67~45~11 ~67~45~13 minecraft:stained_hardened_clay 7
fill ~67~48~11 ~68~48~11 minecraft:stained_hardened_clay 7
setblock ~67~52~11 minecraft:wool 7
fill ~68~25~11 ~69~25~11 minecraft:stained_hardened_clay 12
setblock ~68~37~11 minecraft:stained_hardened_clay 7
fill ~68~41~11 ~69~41~11 minecraft:stained_hardened_clay 12
fill ~68~51~11 ~69~51~23 minecraft:stained_hardened_clay 12
setblock ~68~52~11 minecraft:wool 8
fill ~69~27~11 ~69~27~14 minecraft:stained_hardened_clay 12
fill ~69~34~11 ~69~34~14 minecraft:stained_hardened_clay 7
setblock ~69~35~11 minecraft:stained_hardened_clay 12
fill ~69~36~11 ~69~36~13 minecraft:stained_hardened_clay 7
fill ~69~39~11 ~69~39~17 minecraft:stained_hardened_clay 12
fill ~69~42~11 ~69~43~11 minecraft:stained_hardened_clay 12
fill ~69~44~11 ~69~44~12 minecraft:stained_hardened_clay 7
fill ~69~47~11 ~70~47~14 minecraft:stained_hardened_clay 7
setblock ~69~52~11 minecraft:wool 7
setblock ~70~27~11 minecraft:stained_hardened_clay 7
setblock ~70~35~11 minecraft:stained_hardened_clay 7
setblock ~70~39~11 minecraft:stained_hardened_clay 7
fill ~70~40~11 ~73~40~17 minecraft:stained_hardened_clay 12
setblock ~70~41~11 minecraft:stained_hardened_clay 7
setblock ~70~51~11 minecraft:stained_hardened_clay 7
fill ~70~52~11 ~72~52~11 minecraft:wool 8
fill ~71~28~11 ~71~28~19 minecraft:stained_hardened_clay 7
setblock ~71~30~11 minecraft:stained_hardened_clay 7
fill ~71~36~11 ~73~36~11 minecraft:stained_hardened_clay 7
fill ~71~37~11 ~71~37~14 minecraft:stained_hardened_clay 7
setblock ~71~38~11 minecraft:stained_hardened_clay 7
fill ~71~39~11 ~71~39~16 minecraft:stained_hardened_clay 12
setblock ~71~41~11 minecraft:stained_hardened_clay 12
fill ~71~47~11 ~71~48~11 minecraft:stained_hardened_clay 12
fill ~71~49~11 ~71~49~13 minecraft:stained_hardened_clay 7
fill ~71~51~11 ~71~51~24 minecraft:stained_hardened_clay 12
setblock ~72~30~11 minecraft:stained_hardened_clay 12
fill ~72~32~11 ~74~32~11 minecraft:stained_hardened_clay 7
fill ~72~33~11 ~72~33~18 minecraft:stained_hardened_clay 7
setblock ~72~35~11 minecraft:stained_hardened_clay 12
fill ~72~37~11 ~73~37~11 minecraft:stained_hardened_clay 12
setblock ~72~39~11 minecraft:stained_hardened_clay 7
fill ~72~41~11 ~72~43~12 minecraft:stained_hardened_clay 7
setblock ~72~48~11 minecraft:stained_hardened_clay 12
setblock ~73~31~11 minecraft:stained_hardened_clay 7
fill ~73~35~11 ~73~35~14 minecraft:stained_hardened_clay 7
setblock ~73~38~11 minecraft:stained_hardened_clay 12
fill ~73~46~11 ~73~46~14 minecraft:stained_hardened_clay 7
setblock ~73~50~11 minecraft:stained_hardened_clay 12
fill ~73~52~11 ~77~52~14 minecraft:stained_hardened_clay 12
fill ~73~53~11 ~74~53~11 minecraft:wool 7
fill ~74~33~11 ~74~34~11 minecraft:stained_hardened_clay 7
fill ~74~37~11 ~74~37~13 minecraft:stained_hardened_clay 7
setblock ~74~38~11 minecraft:stained_hardened_clay 7
fill ~74~43~11 ~74~43~13 minecraft:stained_hardened_clay 7
fill ~74~45~11 ~75~45~12 minecraft:stained_hardened_clay 7
fill ~74~46~11 ~75~46~11 minecraft:stained_hardened_clay 12
fill ~74~48~11 ~74~49~11 minecraft:stained_hardened_clay 12
fill ~74~50~11 ~75~50~11 minecraft:stained_hardened_clay 7
setblock ~74~51~11 minecraft:stained_hardened_clay 7
fill ~75~35~11 ~75~35~12 minecraft:stained_hardened_clay 7
fill ~75~38~11 ~75~38~17 minecraft:stained_hardened_clay 12
setblock ~75~43~11 minecraft:stained_hardened_clay 12
setblock ~75~47~11 minecraft:stained_hardened_clay 12
fill ~75~48~11 ~77~48~11 minecraft:stained_hardened_clay 7
fill ~75~49~11 ~76~49~12 minecraft:stained_hardened_clay 7
fill ~75~51~11 ~75~51~23 minecraft:stained_hardened_clay 12
fill ~75~53~11 ~77~53~11 minecraft:wool 8
setblock ~76~36~11 minecraft:stained_hardened_clay 7
fill ~76~43~11 ~76~43~12 minecraft:stained_hardened_clay 7
fill ~76~45~11 ~77~45~11 minecraft:stained_hardened_clay 12
fill ~76~50~11 ~77~50~21 minecraft:stained_hardened_clay 12
fill ~77~37~11 ~81~37~14 minecraft:stained_hardened_clay 7
setblock ~77~40~11 minecraft:stained_hardened_clay 12
fill ~77~41~11 ~80~41~12 minecraft:stained_hardened_clay 7
fill ~77~43~11 ~77~44~19 minecraft:stained_hardened_clay 12
fill ~77~49~11 ~77~49~21 minecraft:stained_hardened_clay 12
fill ~78~38~11 ~82~38~15 minecraft:stained_hardened_clay 7
fill ~78~40~11 ~85~40~15 minecraft:stained_hardened_clay 7
fill ~78~43~11 ~78~45~12 minecraft:stained_hardened_clay 7
fill ~78~50~11 ~81~50~17 minecraft:stained_hardened_clay 7
fill ~78~51~11 ~78~51~16 minecraft:stained_hardened_clay 7
setblock ~78~52~11 minecraft:wool 8
fill ~79~39~11 ~84~39~16 minecraft:stained_hardened_clay 7
fill ~79~51~11 ~81~51~11 minecraft:wool 7
fill ~80~49~11 ~86~49~18 minecraft:stained_hardened_clay 7
fill ~81~48~11 ~87~48~17 minecraft:stained_hardened_clay 7
setblock ~82~50~11 minecraft:wool 7
fill ~83~41~11 ~87~41~15 minecraft:stained_hardened_clay 7
fill ~83~50~11 ~84~50~11 minecraft:wool 8
fill ~84~42~11 ~89~42~14 minecraft:stained_hardened_clay 7
fill ~84~47~11 ~89~47~16 minecraft:stained_hardened_clay 7
fill ~85~43~11 ~90~46~12 minecraft:stained_hardened_clay 7
setblock ~85~50~11 minecraft:wool 7
setblock ~99~55~11 minecraft:wool 7
fill ~100~53~11 ~101~53~11 minecraft:wool 7
fill ~100~54~11 ~101~55~12 minecraft:stained_hardened_clay 7
setblock ~101~56~11 minecraft:wool 7
setblock ~19~33~12 minecraft:stained_hardened_clay 7
fill ~19~34~12 ~20~34~12 minecraft:stained_hardened_clay 12
fill ~19~35~12 ~19~35~33 minecraft:stained_hardened_clay 12
fill ~19~36~12 ~19~38~12 minecraft:stained_hardened_clay 7
fill ~20~32~12 ~21~32~12 minecraft:stained_hardened_clay 7
fill ~20~33~12 ~20~33~13 minecraft:stained_hardened_clay 12
fill ~20~35~12 ~22~35~12 minecraft:stained_hardened_clay 7
fill ~20~36~12 ~20~36~13 minecraft:stained_hardened_clay 12
fill ~20~37~12 ~20~38~12 minecraft:stained_hardened_clay 12
fill ~20~39~12 ~21~39~13 minecraft:stained_hardened_clay 7
fill ~20~40~12 ~20~40~15 minecraft:stained_hardened_clay 7
fill ~20~41~12 ~20~41~14 minecraft:stained_hardened_clay 7
fill ~20~42~12 ~25~43~12 minecraft:stained_hardened_clay 7
fill ~20~44~12 ~20~44~14 minecraft:stained_hardened_clay 7
fill ~21~33~12 ~23~34~13 minecraft:stained_hardened_clay 7
fill ~21~36~12 ~21~38~12 minecraft:stained_hardened_clay 7
fill ~21~44~12 ~22~44~12 minecraft:stained_hardened_clay 12
setblock ~21~45~12 minecraft:stained_hardened_clay 12
fill ~21~46~12 ~23~46~13 minecraft:stained_hardened_clay 7
fill ~21~47~12 ~21~47~13 minecraft:stained_hardened_clay 7
setblock ~22~32~12 minecraft:stained_hardened_clay 12
setblock ~22~36~12 minecraft:stained_hardened_clay 12
fill ~22~37~12 ~23~37~14 minecraft:stained_hardened_clay 7
fill ~22~39~12 ~22~39~13 minecraft:stained_hardened_clay 12
fill ~22~45~12 ~23~45~12 minecraft:stained_hardened_clay 7
fill ~22~47~12 ~23~47~13 minecraft:stained_hardened_clay 12
fill ~22~48~12 ~23~48~15 minecraft:stained_hardened_clay 7
fill ~22~49~12 ~23~49~13 minecraft:stained_hardened_clay 7
fill ~22~50~12 ~22~50~13 minecraft:stained_hardened_clay 12
fill ~22~51~12 ~26~51~14 minecraft:stained_hardened_clay 7
setblock ~23~35~12 minecraft:stained_hardened_clay 12
fill ~23~36~12 ~26~36~12 minecraft:stained_hardened_clay 7
fill ~23~38~12 ~23~38~13 minecraft:stained_hardened_clay 7
fill ~23~39~12 ~23~40~12 minecraft:stained_hardened_clay 7
fill ~23~50~12 ~26~50~13 minecraft:stained_hardened_clay 7
fill ~24~34~12 ~24~34~19 minecraft:stained_hardened_clay 7
fill ~24~35~12 ~24~35~13 minecraft:stained_hardened_clay 7
fill ~24~37~12 ~24~39~12 minecraft:stained_hardened_clay 12
fill ~24~46~12 ~25~46~12 minecraft:stained_hardened_clay 12
fill ~24~47~12 ~31~47~14 minecraft:stained_hardened_clay 7
fill ~24~48~12 ~24~49~12 minecraft:stained_hardened_clay 12
fill ~24~52~12 ~27~52~12 minecraft:stained_hardened_clay 7
fill ~25~35~12 ~25~35~13 minecraft:stained_hardened_clay 12
fill ~25~37~12 ~25~37~14 minecraft:stained_hardened_clay 7
fill ~25~39~12 ~28~39~14 minecraft:stained_hardened_clay 7
fill ~25~48~12 ~28~49~12 minecraft:stained_hardened_clay 7
fill ~25~53~12 ~29~53~12 minecraft:stained_hardened_clay 7
fill ~26~37~12 ~26~37~14 minecraft:stained_hardened_clay 12
fill ~26~38~12 ~26~38~13 minecraft:stained_hardened_clay 7
setblock ~26~42~12 minecraft:stained_hardened_clay 12
fill ~26~43~12 ~29~43~15 minecraft:stained_hardened_clay 7
fill ~26~46~12 ~26~46~15 minecraft:stained_hardened_clay 7
fill ~27~38~12 ~27~38~13 minecraft:stained_hardened_clay 12
fill ~27~42~12 ~28~42~15 minecraft:stained_hardened_clay 7
setblock ~27~46~12 minecraft:stained_hardened_clay 12
setblock ~27~50~12 minecraft:stained_hardened_clay 12
fill ~27~54~12 ~34~54~14 minecraft:stained_hardened_clay 7
fill ~28~40~12 ~29~40~15 minecraft:stained_hardened_clay 7
fill ~28~46~12 ~34~46~13 minecraft:stained_hardened_clay 7
fill ~28~50~12 ~35~50~13 minecraft:stained_hardened_clay 7
setblock ~28~52~12 minecraft:stained_hardened_clay 12
fill ~28~55~12 ~33~55~13 minecraft:stained_hardened_clay 7
fill ~29~41~12 ~30~41~17 minecraft:stained_hardened_clay 7
setblock ~29~42~12 minecraft:stained_hardened_clay 12
fill ~29~48~12 ~29~49~13 minecraft:wool 0
fill ~30~42~12 ~31~42~13 minecraft:stained_hardened_clay 7
fill ~30~48~12 ~32~48~16 minecraft:stained_hardened_clay 7
fill ~30~49~12 ~35~49~15 minecraft:stained_hardened_clay 7
fill ~31~43~12 ~32~43~14 minecraft:stained_hardened_clay 7
setblock ~31~56~12 minecraft:wool 8
fill ~32~44~12 ~33~44~16 minecraft:stained_hardened_clay 7
fill ~32~45~12 ~33~45~15 minecraft:stained_hardened_clay 7
setblock ~32~47~12 minecraft:stained_hardened_clay 12
fill ~32~53~12 ~35~53~16 minecraft:stained_hardened_clay 7
setblock ~32~56~12 minecraft:wool 12
fill ~33~47~12 ~35~47~17 minecraft:stained_hardened_clay 7
fill ~33~52~12 ~35~52~17 minecraft:stained_hardened_clay 7
setblock ~33~56~12 minecraft:wool 7
fill ~34~48~12 ~35~48~18 minecraft:stained_hardened_clay 7
fill ~34~51~12 ~35~51~15 minecraft:stained_hardened_clay 7
setblock ~34~55~12 minecraft:wool 12
setblock ~35~54~12 minecraft:wool 12
fill ~38~42~12 ~40~43~13 minecraft:stained_hardened_clay 7
fill ~38~44~12 ~39~44~18 minecraft:stained_hardened_clay 7
fill ~38~45~12 ~40~45~13 minecraft:stained_hardened_clay 7
fill ~38~46~12 ~40~47~12 minecraft:stained_hardened_clay 7
fill ~38~48~12 ~38~48~17 minecraft:stained_hardened_clay 7
setblock ~38~49~12 minecraft:wool 8
fill ~39~41~12 ~43~41~12 minecraft:stained_hardened_clay 7
setblock ~39~48~12 minecraft:stained_hardened_clay 12
fill ~39~49~12 ~50~49~12 minecraft:stained_hardened_clay 7
setblock ~39~50~12 minecraft:wool 7
fill ~40~40~12 ~45~40~14 minecraft:stained_hardened_clay 7
fill ~40~48~12 ~42~48~13 minecraft:stained_hardened_clay 7
fill ~40~50~12 ~40~50~15 minecraft:stained_hardened_clay 7
setblock ~40~51~12 minecraft:wool 7
fill ~41~39~12 ~46~39~12 minecraft:stained_hardened_clay 7
setblock ~41~42~12 minecraft:stained_hardened_clay 12
fill ~41~43~12 ~41~43~15 minecraft:stained_hardened_clay 7
fill ~41~44~12 ~41~47~12 minecraft:stained_hardened_clay 12
setblock ~41~50~12 minecraft:stained_hardened_clay 12
fill ~41~51~12 ~45~51~13 minecraft:stained_hardened_clay 7
setblock ~41~52~12 minecraft:wool 12
fill ~42~38~12 ~43~38~12 minecraft:stained_hardened_clay 7
fill ~42~43~12 ~42~43~21 minecraft:stained_hardened_clay 12
fill ~42~46~12 ~42~47~21 minecraft:stained_hardened_clay 12
setblock ~42~50~12 minecraft:stained_hardened_clay 7
fill ~42~52~12 ~43~52~15 minecraft:stained_hardened_clay 7
fill ~42~53~12 ~48~53~12 minecraft:wool 7
fill ~43~45~12 ~43~45~21 minecraft:stained_hardened_clay 12
setblock ~43~46~12 minecraft:stained_hardened_clay 7
fill ~43~47~12 ~43~48~12 minecraft:stained_hardened_clay 12
fill ~43~50~12 ~43~50~14 minecraft:stained_hardened_clay 12
fill ~44~38~12 ~45~38~12 minecraft:stained_hardened_clay 12
setblock ~44~41~12 minecraft:stained_hardened_clay 12
fill ~44~42~12 ~44~42~14 minecraft:stained_hardened_clay 7
fill ~44~43~12 ~44~44~20 minecraft:stained_hardened_clay 12
fill ~44~46~12 ~46~46~21 minecraft:stained_hardened_clay 12
fill ~44~47~12 ~46~47~14 minecraft:stained_hardened_clay 7
fill ~44~48~12 ~45~48~12 minecraft:stained_hardened_clay 7
fill ~44~50~12 ~45~50~12 minecraft:stained_hardened_clay 7
setblock ~44~52~12 minecraft:stained_hardened_clay 12
setblock ~45~42~12 minecraft:stained_hardened_clay 12
fill ~45~44~12 ~46~44~19 minecraft:stained_hardened_clay 12
fill ~45~45~12 ~45~45~21 minecraft:stained_hardened_clay 12
fill ~45~52~12 ~49~52~13 minecraft:stained_hardened_clay 7
fill ~46~38~12 ~50~38~12 minecraft:stained_hardened_clay 7
setblock ~46~40~12 minecraft:stained_hardened_clay 12
fill ~46~42~12 ~51~42~12 minecraft:stained_hardened_clay 7
fill ~46~43~12 ~46~43~20 minecraft:stained_hardened_clay 12
fill ~46~50~12 ~46~50~13 minecraft:stained_hardened_clay 12
setblock ~46~51~12 minecraft:stained_hardened_clay 12
setblock ~47~37~12 minecraft:stained_hardened_clay 12
setblock ~47~39~12 minecraft:stained_hardened_clay 12
fill ~47~40~12 ~50~40~13 minecraft:stained_hardened_clay 7
fill ~47~41~12 ~50~41~12 minecraft:stained_hardened_clay 7
fill ~47~43~12 ~50~43~12 minecraft:stained_hardened_clay 7
fill ~47~44~12 ~48~44~12 minecraft:stained_hardened_clay 7
fill ~47~46~12 ~49~46~13 minecraft:stained_hardened_clay 7
fill ~47~50~12 ~47~51~12 minecraft:stained_hardened_clay 7
fill ~48~37~12 ~49~37~15 minecraft:stained_hardened_clay 7
fill ~48~39~12 ~49~39~12 minecraft:stained_hardened_clay 7
fill ~48~47~12 ~48~47~13 minecraft:stained_hardened_clay 7
setblock ~48~50~12 minecraft:stained_hardened_clay 12
fill ~48~51~12 ~49~51~14 minecraft:stained_hardened_clay 7
setblock ~49~44~12 minecraft:stained_hardened_clay 12
fill ~49~45~12 ~50~45~15 minecraft:stained_hardened_clay 7
fill ~49~48~12 ~49~48~15 minecraft:stained_hardened_clay 7
fill ~49~50~12 ~51~50~14 minecraft:stained_hardened_clay 7
setblock ~49~53~12 minecraft:wool 8
fill ~50~37~12 ~51~37~12 minecraft:stained_hardened_clay 12
setblock ~50~39~12 minecraft:stained_hardened_clay 12
fill ~50~44~12 ~54~44~13 minecraft:stained_hardened_clay 7
setblock ~50~48~12 minecraft:stained_hardened_clay 12
fill ~50~51~12 ~50~52~12 minecraft:stained_hardened_clay 12
setblock ~50~53~12 minecraft:wool 12
fill ~51~36~12 ~58~36~12 minecraft:stained_hardened_clay 7
fill ~51~38~12 ~52~38~12 minecraft:stained_hardened_clay 12
fill ~51~39~12 ~52~39~12 minecraft:stained_hardened_clay 7
setblock ~51~41~12 minecraft:stained_hardened_clay 12
fill ~51~48~12 ~52~48~13 minecraft:stained_hardened_clay 7
setblock ~51~49~12 minecraft:stained_hardened_clay 12
fill ~51~51~12 ~62~51~12 minecraft:stained_hardened_clay 7
fill ~51~52~12 ~51~52~13 minecraft:stained_hardened_clay 7
fill ~51~53~12 ~54~53~12 minecraft:wool 7
fill ~52~37~12 ~57~37~12 minecraft:stained_hardened_clay 7
fill ~52~41~12 ~52~41~14 minecraft:stained_hardened_clay 7
fill ~52~43~12 ~53~43~12 minecraft:stained_hardened_clay 12
fill ~52~49~12 ~53~49~14 minecraft:stained_hardened_clay 7
setblock ~52~50~12 minecraft:stained_hardened_clay 12
fill ~52~52~12 ~52~52~23 minecraft:stained_hardened_clay 12
fill ~52~54~12 ~53~54~12 minecraft:wool 12
fill ~53~38~12 ~55~38~13 minecraft:stained_hardened_clay 7
setblock ~53~41~12 minecraft:stained_hardened_clay 12
fill ~53~42~12 ~53~42~16 minecraft:stained_hardened_clay 7
fill ~53~46~12 ~53~46~17 minecraft:stained_hardened_clay 7
fill ~53~50~12 ~55~50~13 minecraft:stained_hardened_clay 7
setblock ~53~52~12 minecraft:stained_hardened_clay 7
fill ~54~35~12 ~56~35~16 minecraft:stained_hardened_clay 7
fill ~54~40~12 ~56~41~15 minecraft:stained_hardened_clay 7
fill ~54~43~12 ~54~43~16 minecraft:stained_hardened_clay 7
fill ~54~52~12 ~54~52~22 minecraft:stained_hardened_clay 12
fill ~54~57~12 ~55~57~12 minecraft:wool 8
fill ~55~34~12 ~56~34~14 minecraft:stained_hardened_clay 7
fill ~55~42~12 ~56~42~13 minecraft:stained_hardened_clay 7
fill ~55~48~12 ~57~48~16 minecraft:stained_hardened_clay 7
fill ~55~52~12 ~56~52~12 minecraft:stained_hardened_clay 7
setblock ~55~53~12 minecraft:wool 8
fill ~55~56~12 ~55~56~13 minecraft:wool 8
fill ~56~33~12 ~58~33~16 minecraft:stained_hardened_clay 7
setblock ~56~50~12 minecraft:stained_hardened_clay 12
setblock ~56~53~12 minecraft:wool 7
fill ~57~31~12 ~58~31~12 minecraft:stained_hardened_clay 7
fill ~57~32~12 ~57~32~17 minecraft:stained_hardened_clay 7
setblock ~57~35~12 minecraft:stained_hardened_clay 12
setblock ~57~40~12 minecraft:wool 7
fill ~57~41~12 ~60~41~15 minecraft:stained_hardened_clay 7
fill ~57~50~12 ~62~50~12 minecraft:stained_hardened_clay 7
setblock ~57~52~12 minecraft:stained_hardened_clay 12
fill ~57~53~12 ~58~53~12 minecraft:wool 12
fill ~57~58~12 ~58~58~12 minecraft:wool 7
fill ~58~30~12 ~59~30~16 minecraft:stained_hardened_clay 7
fill ~58~35~12 ~58~35~14 minecraft:stained_hardened_clay 7
fill ~58~40~12 ~58~40~17 minecraft:stained_hardened_clay 7
fill ~58~47~12 ~58~47~14 minecraft:stained_hardened_clay 7
setblock ~58~48~12 minecraft:stained_hardened_clay 12
fill ~58~52~12 ~60~52~14 minecraft:stained_hardened_clay 7
fill ~58~57~12 ~58~57~14 minecraft:wool 7
fill ~59~29~12 ~60~29~14 minecraft:stained_hardened_clay 7
fill ~59~48~12 ~59~48~14 minecraft:stained_hardened_clay 7
setblock ~59~53~12 minecraft:wool 7
fill ~60~27~12 ~61~27~13 minecraft:stained_hardened_clay 7
fill ~60~28~12 ~60~28~14 minecraft:stained_hardened_clay 7
setblock ~60~30~12 minecraft:stained_hardened_clay 12
fill ~60~32~12 ~61~32~12 minecraft:stained_hardened_clay 7
fill ~60~42~12 ~61~42~16 minecraft:stained_hardened_clay 7
setblock ~60~49~12 minecraft:stained_hardened_clay 7
setblock ~60~53~12 minecraft:wool 8
fill ~60~56~12 ~61~56~12 minecraft:wool 8
setblock ~60~57~12 minecraft:wool 8
fill ~61~25~12 ~61~26~16 minecraft:stained_hardened_clay 7
fill ~61~30~12 ~61~31~14 minecraft:stained_hardened_clay 7
fill ~61~38~12 ~61~39~14 minecraft:stained_hardened_clay 7
setblock ~61~41~12 minecraft:stained_hardened_clay 12
setblock ~61~48~12 minecraft:stained_hardened_clay 7
setblock ~61~52~12 minecraft:stained_hardened_clay 12
setblock ~61~53~12 minecraft:wool 7
setblock ~62~23~12 minecraft:stained_hardened_clay 12
fill ~62~24~12 ~63~24~16 minecraft:stained_hardened_clay 7
fill ~62~25~12 ~63~25~12 minecraft:stained_hardened_clay 12
fill ~62~26~12 ~64~26~13 minecraft:stained_hardened_clay 7
fill ~62~31~12 ~62~31~14 minecraft:stained_hardened_clay 7
setblock ~62~32~12 minecraft:stained_hardened_clay 12
setblock ~62~38~12 minecraft:stained_hardened_clay 12
fill ~62~39~12 ~62~39~16 minecraft:stained_hardened_clay 7
fill ~62~45~12 ~63~45~14 minecraft:stained_hardened_clay 7
fill ~62~52~12 ~63~52~12 minecraft:stained_hardened_clay 7
fill ~62~53~12 ~65~53~12 minecraft:wool 8
fill ~63~22~12 ~65~22~13 minecraft:stained_hardened_clay 7
fill ~63~23~12 ~64~23~14 minecraft:stained_hardened_clay 7
fill ~63~28~12 ~65~28~13 minecraft:stained_hardened_clay 7
fill ~63~31~12 ~65~31~12 minecraft:stained_hardened_clay 12
fill ~63~33~12 ~64~33~12 minecraft:stained_hardened_clay 7
fill ~63~46~12 ~64~46~14 minecraft:stained_hardened_clay 7
fill ~63~50~12 ~63~51~12 minecraft:stained_hardened_clay 12
fill ~64~25~12 ~66~25~12 minecraft:stained_hardened_clay 7
fill ~64~29~12 ~64~29~14 minecraft:stained_hardened_clay 7
setblock ~64~45~12 minecraft:stained_hardened_clay 12
fill ~64~49~12 ~64~49~13 minecraft:stained_hardened_clay 7
fill ~64~50~12 ~67~50~12 minecraft:stained_hardened_clay 7
fill ~64~52~12 ~72~52~21 minecraft:stained_hardened_clay 12
setblock ~64~54~12 minecraft:wool 8
fill ~65~21~12 ~67~21~12 minecraft:stained_hardened_clay 7
setblock ~65~26~12 minecraft:stained_hardened_clay 12
fill ~65~36~12 ~65~36~13 minecraft:stained_hardened_clay 7
setblock ~65~37~12 minecraft:stained_hardened_clay 7
fill ~65~38~12 ~65~39~12 minecraft:stained_hardened_clay 12
fill ~65~46~12 ~65~47~12 minecraft:stained_hardened_clay 12
setblock ~65~49~12 minecraft:stained_hardened_clay 12
fill ~65~51~12 ~67~51~21 minecraft:stained_hardened_clay 12
setblock ~66~22~12 minecraft:stained_hardened_clay 12
fill ~66~26~12 ~66~26~16 minecraft:stained_hardened_clay 7
fill ~66~27~12 ~66~27~14 minecraft:stained_hardened_clay 7
fill ~66~28~12 ~66~28~16 minecraft:stained_hardened_clay 12
fill ~66~30~12 ~68~30~13 minecraft:stained_hardened_clay 7
fill ~66~31~12 ~67~31~13 minecraft:stained_hardened_clay 7
fill ~66~36~12 ~66~36~17 minecraft:stained_hardened_clay 12
fill ~66~38~12 ~66~39~12 minecraft:stained_hardened_clay 7
fill ~66~43~12 ~66~43~15 minecraft:stained_hardened_clay 7
fill ~66~45~12 ~66~46~13 minecraft:stained_hardened_clay 7
setblock ~66~47~12 minecraft:stained_hardened_clay 7
fill ~66~53~12 ~69~53~12 minecraft:wool 7
fill ~67~22~12 ~67~23~14 minecraft:stained_hardened_clay 7
fill ~67~25~12 ~67~25~14 minecraft:stained_hardened_clay 12
fill ~67~27~12 ~67~27~16 minecraft:stained_hardened_clay 12
fill ~67~28~12 ~67~29~12 minecraft:stained_hardened_clay 7
fill ~67~36~12 ~67~36~13 minecraft:stained_hardened_clay 7
fill ~67~38~12 ~68~38~16 minecraft:stained_hardened_clay 12
fill ~67~40~12 ~67~40~13 minecraft:stained_hardened_clay 7
fill ~67~43~12 ~67~44~12 minecraft:stained_hardened_clay 12
setblock ~67~46~12 minecraft:stained_hardened_clay 12
fill ~67~48~12 ~67~48~13 minecraft:stained_hardened_clay 12
fill ~68~22~12 ~69~22~12 minecraft:stained_hardened_clay 12
fill ~68~23~12 ~70~23~12 minecraft:stained_hardened_clay 7
fill ~68~25~12 ~68~25~13 minecraft:stained_hardened_clay 7
fill ~68~28~12 ~68~28~15 minecraft:stained_hardened_clay 12
fill ~68~29~12 ~68~29~13 minecraft:stained_hardened_clay 7
setblock ~68~33~12 minecraft:stained_hardened_clay 12
fill ~68~36~12 ~68~37~16 minecraft:stained_hardened_clay 12
fill ~68~40~12 ~69~40~17 minecraft:stained_hardened_clay 12
setblock ~68~41~12 minecraft:stained_hardened_clay 12
setblock ~68~44~12 minecraft:stained_hardened_clay 7
fill ~68~46~12 ~69~46~14 minecraft:stained_hardened_clay 7
fill ~68~48~12 ~68~48~14 minecraft:stained_hardened_clay 7
fill ~68~50~12 ~68~50~22 minecraft:stained_hardened_clay 12
fill ~69~24~12 ~69~24~23 minecraft:stained_hardened_clay 7
fill ~69~25~12 ~71~25~13 minecraft:stained_hardened_clay 12
fill ~69~28~12 ~70~28~12 minecraft:stained_hardened_clay 7
fill ~69~29~12 ~69~30~12 minecraft:stained_hardened_clay 12
fill ~69~31~12 ~69~31~14 minecraft:stained_hardened_clay 7
fill ~69~33~12 ~70~33~14 minecraft:stained_hardened_clay 7
setblock ~69~35~12 minecraft:stained_hardened_clay 7
fill ~69~41~12 ~69~43~13 minecraft:stained_hardened_clay 7
fill ~69~50~12 ~70~50~12 minecraft:stained_hardened_clay 7
setblock ~70~24~12 minecraft:stained_hardened_clay 12
fill ~70~26~12 ~71~27~13 minecraft:stained_hardened_clay 12
fill ~70~29~12 ~73~29~13 minecraft:stained_hardened_clay 7
setblock ~70~31~12 minecraft:stained_hardened_clay 12
fill ~70~34~12 ~70~35~12 minecraft:stained_hardened_clay 12
fill ~70~36~12 ~71~36~12 minecraft:wool 7
fill ~70~39~12 ~70~39~16 minecraft:stained_hardened_clay 12
fill ~70~41~12 ~70~41~17 minecraft:stained_hardened_clay 12
setblock ~70~42~12 minecraft:stained_hardened_clay 7
fill ~70~51~12 ~70~51~24 minecraft:stained_hardened_clay 12
setblock ~70~53~12 minecraft:wool 8
setblock ~71~30~12 minecraft:stained_hardened_clay 12
fill ~71~34~12 ~71~34~15 minecraft:stained_hardened_clay 7
fill ~71~38~12 ~72~38~12 minecraft:stained_hardened_clay 12
setblock ~71~41~12 minecraft:stained_hardened_clay 7
fill ~71~47~12 ~72~47~14 minecraft:stained_hardened_clay 7
fill ~71~48~12 ~71~48~13 minecraft:stained_hardened_clay 12
setblock ~71~50~12 minecraft:stained_hardened_clay 12
fill ~71~53~12 ~73~53~12 minecraft:wool 7
fill ~72~28~12 ~72~28~15 minecraft:stained_hardened_clay 7
fill ~72~30~12 ~73~30~15 minecraft:stained_hardened_clay 7
fill ~72~32~12 ~74~32~12 minecraft:stained_hardened_clay 12
fill ~72~35~12 ~72~35~14 minecraft:stained_hardened_clay 7
fill ~72~36~12 ~73~37~12 minecraft:stained_hardened_clay 7
fill ~72~39~12 ~72~39~17 minecraft:stained_hardened_clay 12
setblock ~72~44~12 minecraft:stained_hardened_clay 12
setblock ~72~46~12 minecraft:stained_hardened_clay 12
fill ~72~48~12 ~72~48~14 minecraft:stained_hardened_clay 7
fill ~72~50~12 ~73~50~13 minecraft:stained_hardened_clay 7
fill ~72~51~12 ~72~51~23 minecraft:stained_hardened_clay 12
fill ~73~31~12 ~74~31~12 minecraft:stained_hardened_clay 12
fill ~73~33~12 ~75~33~12 minecraft:stained_hardened_clay 12
fill ~73~34~12 ~75~34~12 minecraft:stained_hardened_clay 7
setblock ~73~38~12 minecraft:stained_hardened_clay 7
fill ~73~43~12 ~73~43~17 minecraft:stained_hardened_clay 12
fill ~73~44~12 ~73~44~14 minecraft:stained_hardened_clay 7
setblock ~73~47~12 minecraft:stained_hardened_clay 12
setblock ~73~51~12 minecraft:stained_hardened_clay 7
fill ~74~38~12 ~74~38~17 minecraft:stained_hardened_clay 12
fill ~74~41~12 ~74~42~18 minecraft:stained_hardened_clay 12
fill ~74~46~12 ~75~47~13 minecraft:stained_hardened_clay 7
fill ~74~48~12 ~74~48~13 minecraft:stained_hardened_clay 7
setblock ~74~49~12 minecraft:stained_hardened_clay 7
fill ~74~50~12 ~74~51~23 minecraft:stained_hardened_clay 12
setblock ~74~53~12 minecraft:wool 8
fill ~75~37~12 ~75~37~17 minecraft:stained_hardened_clay 12
setblock ~75~43~12 minecraft:stained_hardened_clay 7
fill ~75~48~12 ~77~48~12 minecraft:stained_hardened_clay 12
setblock ~75~50~12 minecraft:stained_hardened_clay 7
fill ~75~53~12 ~78~53~12 minecraft:wool 7
fill ~76~35~12 ~77~35~12 minecraft:stained_hardened_clay 7
fill ~76~36~12 ~76~36~19 minecraft:stained_hardened_clay 12
fill ~76~42~12 ~76~42~18 minecraft:stained_hardened_clay 12
fill ~76~44~12 ~76~44~18 minecraft:stained_hardened_clay 12
fill ~76~45~12 ~77~45~12 minecraft:stained_hardened_clay 7
fill ~76~47~12 ~77~47~12 minecraft:stained_hardened_clay 7
fill ~77~36~12 ~83~36~17 minecraft:stained_hardened_clay 7
fill ~77~40~12 ~77~40~13 minecraft:stained_hardened_clay 7
fill ~77~46~12 ~77~46~20 minecraft:stained_hardened_clay 12
setblock ~78~49~12 minecraft:stained_hardened_clay 7
fill ~78~52~12 ~79~52~19 minecraft:stained_hardened_clay 7
fill ~79~51~12 ~81~51~20 minecraft:stained_hardened_clay 7
setblock ~79~53~12 minecraft:wool 8
fill ~80~52~12 ~81~52~12 minecraft:wool 8
fill ~82~37~12 ~85~37~14 minecraft:stained_hardened_clay 7
fill ~82~50~12 ~88~50~19 minecraft:stained_hardened_clay 7
setblock ~82~51~12 minecraft:wool 8
fill ~83~38~12 ~86~38~15 minecraft:stained_hardened_clay 7
setblock ~83~51~12 minecraft:wool 7
setblock ~84~51~12 minecraft:wool 8
fill ~85~39~12 ~90~39~13 minecraft:stained_hardened_clay 7
fill ~86~40~12 ~92~40~12 minecraft:stained_hardened_clay 7
fill ~87~49~12 ~91~49~14 minecraft:stained_hardened_clay 7
fill ~88~41~12 ~90~41~13 minecraft:stained_hardened_clay 7
fill ~88~48~12 ~91~48~13 minecraft:stained_hardened_clay 7
fill ~90~42~12 ~93~42~12 minecraft:stained_hardened_clay 7
fill ~90~47~12 ~92~47~12 minecraft:stained_hardened_clay 7
fill ~91~41~12 ~91~41~17 minecraft:stained_hardened_clay 12
setblock ~91~43~12 minecraft:stained_hardened_clay 7
fill ~91~44~12 ~91~44~17 minecraft:stained_hardened_clay 12
setblock ~91~45~12 minecraft:stained_hardened_clay 7
fill ~91~46~12 ~91~46~17 minecraft:stained_hardened_clay 12
setblock ~92~41~12 minecraft:stained_hardened_clay 7
fill ~92~43~12 ~93~43~17 minecraft:stained_hardened_clay 12
setblock ~92~44~12 minecraft:stained_hardened_clay 7
fill ~92~45~12 ~97~45~17 minecraft:stained_hardened_clay 12
fill ~92~46~12 ~93~46~12 minecraft:stained_hardened_clay 7
fill ~92~48~12 ~95~48~16 minecraft:stained_hardened_clay 12
fill ~92~49~12 ~93~49~17 minecraft:stained_hardened_clay 12
fill ~93~41~12 ~94~41~17 minecraft:stained_hardened_clay 12
fill ~93~44~12 ~93~44~17 minecraft:stained_hardened_clay 12
fill ~93~47~12 ~96~47~17 minecraft:stained_hardened_clay 12
fill ~94~42~12 ~96~42~17 minecraft:stained_hardened_clay 12
fill ~94~43~12 ~94~44~12 minecraft:stained_hardened_clay 7
fill ~94~46~12 ~97~46~17 minecraft:stained_hardened_clay 12
setblock ~95~41~12 minecraft:stained_hardened_clay 7
fill ~95~43~12 ~96~44~17 minecraft:stained_hardened_clay 12
fill ~97~44~12 ~97~44~17 minecraft:stained_hardened_clay 12
fill ~98~57~12 ~98~57~13 minecraft:wool 7
setblock ~99~53~12 minecraft:wool 7
fill ~99~54~12 ~99~57~12 minecraft:stained_hardened_clay 7
fill ~99~58~12 ~99~58~13 minecraft:wool 7
setblock ~100~52~12 minecraft:wool 7
fill ~100~53~12 ~101~53~13 minecraft:stained_hardened_clay 7
fill ~100~56~12 ~101~56~13 minecraft:stained_hardened_clay 7
fill ~100~57~12 ~100~57~13 minecraft:wool 7
fill ~17~31~13 ~23~31~13 minecraft:stained_hardened_clay 7
fill ~17~32~13 ~18~32~13 minecraft:stained_hardened_clay 7
setblock ~17~33~13 minecraft:stained_hardened_clay 12
fill ~17~34~13 ~18~34~13 minecraft:stained_hardened_clay 7
fill ~17~35~13 ~17~35~20 minecraft:stained_hardened_clay 7
fill ~17~36~13 ~17~36~18 minecraft:stained_hardened_clay 7
setblock ~17~37~13 minecraft:stained_hardened_clay 12
fill ~18~30~13 ~20~30~15 minecraft:stained_hardened_clay 7
fill ~18~33~13 ~18~33~18 minecraft:stained_hardened_clay 7
fill ~18~35~13 ~18~36~13 minecraft:stained_hardened_clay 12
fill ~18~37~13 ~21~38~13 minecraft:stained_hardened_clay 7
fill ~18~39~13 ~19~43~13 minecraft:stained_hardened_clay 7
fill ~19~32~13 ~19~34~13 minecraft:stained_hardened_clay 12
fill ~19~36~13 ~19~36~24 minecraft:stained_hardened_clay 12
fill ~19~44~13 ~19~44~15 minecraft:stained_hardened_clay 7
fill ~19~45~13 ~19~46~13 minecraft:stained_hardened_clay 12
fill ~19~47~13 ~20~48~13 minecraft:stained_hardened_clay 7
fill ~20~32~13 ~20~32~15 minecraft:stained_hardened_clay 7
fill ~20~34~13 ~20~35~13 minecraft:stained_hardened_clay 7
setblock ~20~42~13 minecraft:stained_hardened_clay 12
fill ~20~43~13 ~25~43~13 minecraft:stained_hardened_clay 7
fill ~20~45~13 ~21~45~13 minecraft:stained_hardened_clay 7
fill ~20~46~13 ~20~46~14 minecraft:stained_hardened_clay 7
setblock ~20~49~13 minecraft:stained_hardened_clay 7
fill ~20~50~13 ~20~50~15 minecraft:stained_hardened_clay 12
setblock ~21~30~13 minecraft:stained_hardened_clay 12
setblock ~21~32~13 minecraft:stained_hardened_clay 12
fill ~21~35~13 ~21~35~16 minecraft:stained_hardened_clay 7
setblock ~21~36~13 minecraft:stained_hardened_clay 12
fill ~21~40~13 ~21~42~15 minecraft:stained_hardened_clay 7
setblock ~21~44~13 minecraft:stained_hardened_clay 12
fill ~21~48~13 ~21~48~17 minecraft:stained_hardened_clay 7
setblock ~21~49~13 minecraft:stained_hardened_clay 12
fill ~21~50~13 ~21~50~17 minecraft:stained_hardened_clay 7
fill ~21~51~13 ~21~53~15 minecraft:stained_hardened_clay 7
fill ~22~32~13 ~24~32~14 minecraft:stained_hardened_clay 7
setblock ~22~35~13 minecraft:stained_hardened_clay 12
fill ~22~36~13 ~22~36~14 minecraft:stained_hardened_clay 7
fill ~22~40~13 ~22~40~14 minecraft:stained_hardened_clay 12
fill ~22~41~13 ~22~41~15 minecraft:stained_hardened_clay 7
fill ~22~42~13 ~26~42~13 minecraft:stained_hardened_clay 7
fill ~22~44~13 ~22~44~17 minecraft:stained_hardened_clay 7
setblock ~22~45~13 minecraft:stained_hardened_clay 12
fill ~22~52~13 ~24~52~13 minecraft:stained_hardened_clay 7
fill ~22~53~13 ~23~53~13 minecraft:stained_hardened_clay 7
fill ~22~54~13 ~22~54~19 minecraft:stained_hardened_clay 7
fill ~23~35~13 ~23~35~14 minecraft:stained_hardened_clay 7
fill ~23~36~13 ~23~36~24 minecraft:stained_hardened_clay 12
fill ~23~39~13 ~24~39~14 minecraft:stained_hardened_clay 12
fill ~23~40~13 ~23~40~14 minecraft:stained_hardened_clay 7
fill ~23~45~13 ~24~45~13 minecraft:stained_hardened_clay 7
fill ~23~54~13 ~24~54~13 minecraft:stained_hardened_clay 12
fill ~24~33~13 ~25~33~16 minecraft:stained_hardened_clay 7
fill ~24~36~13 ~24~36~17 minecraft:stained_hardened_clay 7
fill ~24~37~13 ~24~37~16 minecraft:stained_hardened_clay 7
setblock ~24~38~13 minecraft:stained_hardened_clay 12
fill ~24~46~13 ~25~46~15 minecraft:stained_hardened_clay 7
fill ~24~48~13 ~24~49~14 minecraft:stained_hardened_clay 7
fill ~24~53~13 ~25~53~13 minecraft:stained_hardened_clay 12
fill ~24~55~13 ~27~55~14 minecraft:stained_hardened_clay 7
fill ~25~34~13 ~26~34~13 minecraft:stained_hardened_clay 7
setblock ~25~36~13 minecraft:stained_hardened_clay 12
setblock ~25~45~13 minecraft:stained_hardened_clay 12
fill ~25~48~13 ~26~48~13 minecraft:stained_hardened_clay 12
fill ~25~49~13 ~28~49~13 minecraft:stained_hardened_clay 7
setblock ~25~52~13 minecraft:stained_hardened_clay 12
fill ~25~54~13 ~26~54~14 minecraft:stained_hardened_clay 7
fill ~26~35~13 ~26~35~16 minecraft:stained_hardened_clay 7
fill ~26~36~13 ~27~36~13 minecraft:stained_hardened_clay 7
fill ~26~45~13 ~31~45~15 minecraft:stained_hardened_clay 7
fill ~26~52~13 ~26~53~13 minecraft:stained_hardened_clay 7
fill ~26~56~13 ~35~56~16 minecraft:stained_hardened_clay 7
fill ~27~37~13 ~28~37~13 minecraft:stained_hardened_clay 7
fill ~27~46~13 ~27~46~16 minecraft:stained_hardened_clay 7
fill ~27~48~13 ~28~48~14 minecraft:stained_hardened_clay 7
fill ~27~50~13 ~27~51~15 minecraft:stained_hardened_clay 7
setblock ~27~52~13 minecraft:stained_hardened_clay 12
fill ~27~53~13 ~29~53~14 minecraft:stained_hardened_clay 7
fill ~28~38~13 ~29~38~16 minecraft:stained_hardened_clay 7
fill ~28~51~13 ~29~51~15 minecraft:stained_hardened_clay 7
fill ~28~52~13 ~28~52~18 minecraft:stained_hardened_clay 7
fill ~28~57~13 ~34~57~13 minecraft:stained_hardened_clay 7
fill ~29~39~13 ~30~39~13 minecraft:stained_hardened_clay 7
fill ~29~42~13 ~29~42~17 minecraft:stained_hardened_clay 7
fill ~30~40~13 ~31~40~16 minecraft:stained_hardened_clay 7
setblock ~30~51~13 minecraft:stained_hardened_clay 12
fill ~31~41~13 ~32~41~16 minecraft:stained_hardened_clay 7
fill ~31~51~13 ~31~51~17 minecraft:stained_hardened_clay 7
fill ~31~58~13 ~32~58~13 minecraft:wool 7
fill ~32~42~13 ~33~42~17 minecraft:stained_hardened_clay 7
fill ~32~47~13 ~32~47~14 minecraft:stained_hardened_clay 7
setblock ~32~51~13 minecraft:stained_hardened_clay 12
fill ~33~43~13 ~37~43~14 minecraft:stained_hardened_clay 7
fill ~33~51~13 ~33~51~17 minecraft:stained_hardened_clay 7
fill ~33~58~13 ~34~58~13 minecraft:wool 12
fill ~34~44~13 ~37~45~17 minecraft:stained_hardened_clay 7
fill ~34~55~13 ~36~55~15 minecraft:stained_hardened_clay 7
fill ~35~46~13 ~37~46~14 minecraft:stained_hardened_clay 7
fill ~35~54~13 ~37~54~19 minecraft:stained_hardened_clay 7
setblock ~35~57~13 minecraft:wool 7
fill ~36~42~13 ~36~42~15 minecraft:stained_hardened_clay 7
fill ~36~47~13 ~41~47~13 minecraft:stained_hardened_clay 7
fill ~36~48~13 ~36~49~13 minecraft:stained_hardened_clay 12
fill ~36~50~13 ~39~52~15 minecraft:stained_hardened_clay 7
fill ~36~53~13 ~43~53~13 minecraft:stained_hardened_clay 7
setblock ~36~56~13 minecraft:wool 8
fill ~37~40~13 ~39~41~15 minecraft:stained_hardened_clay 7
setblock ~37~42~13 minecraft:stained_hardened_clay 12
fill ~37~48~13 ~37~48~18 minecraft:stained_hardened_clay 7
fill ~37~49~13 ~40~49~14 minecraft:stained_hardened_clay 7
setblock ~37~55~13 minecraft:wool 7
fill ~38~39~13 ~42~39~14 minecraft:stained_hardened_clay 7
setblock ~38~46~13 minecraft:stained_hardened_clay 12
fill ~38~54~13 ~39~54~13 minecraft:wool 12
fill ~39~38~13 ~42~38~17 minecraft:stained_hardened_clay 7
fill ~39~46~13 ~41~46~15 minecraft:stained_hardened_clay 7
fill ~39~48~13 ~39~48~14 minecraft:stained_hardened_clay 7
fill ~40~37~13 ~45~37~13 minecraft:stained_hardened_clay 7
fill ~40~41~13 ~42~41~15 minecraft:stained_hardened_clay 7
fill ~40~44~13 ~41~44~15 minecraft:stained_hardened_clay 7
setblock ~40~51~13 minecraft:stained_hardened_clay 12
fill ~40~52~13 ~41~52~18 minecraft:stained_hardened_clay 7
setblock ~40~54~13 minecraft:wool 7
fill ~41~36~13 ~45~36~14 minecraft:stained_hardened_clay 7
fill ~41~42~13 ~41~42~16 minecraft:stained_hardened_clay 7
fill ~41~45~13 ~41~45~14 minecraft:stained_hardened_clay 7
fill ~41~49~13 ~41~49~20 minecraft:stained_hardened_clay 12
fill ~41~50~13 ~41~50~17 minecraft:stained_hardened_clay 7
fill ~41~54~13 ~41~54~19 minecraft:stained_hardened_clay 7
setblock ~41~55~13 minecraft:wool 7
setblock ~42~49~13 minecraft:stained_hardened_clay 7
fill ~42~50~13 ~42~50~14 minecraft:stained_hardened_clay 12
setblock ~42~54~13 minecraft:stained_hardened_clay 12
fill ~42~55~13 ~43~55~13 minecraft:wool 12
fill ~43~38~13 ~43~39~13 minecraft:stained_hardened_clay 12
setblock ~43~41~13 minecraft:stained_hardened_clay 12
fill ~43~46~13 ~43~46~21 minecraft:stained_hardened_clay 12
fill ~43~47~13 ~43~47~14 minecraft:stained_hardened_clay 7
fill ~43~48~13 ~43~49~13 minecraft:stained_hardened_clay 12
fill ~43~54~13 ~44~54~18 minecraft:stained_hardened_clay 7
fill ~44~35~13 ~53~35~13 minecraft:stained_hardened_clay 7
fill ~44~38~13 ~45~38~13 minecraft:stained_hardened_clay 7
fill ~44~39~13 ~44~39~16 minecraft:stained_hardened_clay 12
fill ~44~41~13 ~45~41~16 minecraft:stained_hardened_clay 7
fill ~44~48~13 ~44~49~14 minecraft:stained_hardened_clay 7
fill ~44~50~13 ~45~50~13 minecraft:stained_hardened_clay 12
fill ~44~52~13 ~44~52~19 minecraft:stained_hardened_clay 7
fill ~44~53~13 ~45~53~13 minecraft:stained_hardened_clay 12
setblock ~44~55~13 minecraft:wool 8
fill ~45~39~13 ~45~39~14 minecraft:stained_hardened_clay 7
fill ~45~42~13 ~47~42~13 minecraft:stained_hardened_clay 7
setblock ~45~48~13 minecraft:stained_hardened_clay 12
fill ~45~49~13 ~51~49~13 minecraft:stained_hardened_clay 7
setblock ~45~54~13 minecraft:stained_hardened_clay 12
fill ~45~55~13 ~51~55~13 minecraft:stained_hardened_clay 7
setblock ~45~56~13 minecraft:wool 7
fill ~46~36~13 ~46~39~13 minecraft:stained_hardened_clay 12
fill ~46~40~13 ~46~40~16 minecraft:stained_hardened_clay 7
setblock ~46~41~13 minecraft:stained_hardened_clay 12
fill ~46~48~13 ~46~48~17 minecraft:stained_hardened_clay 7
fill ~46~51~13 ~47~51~13 minecraft:stained_hardened_clay 7
fill ~46~53~13 ~48~53~13 minecraft:stained_hardened_clay 7
fill ~46~54~13 ~46~54~17 minecraft:stained_hardened_clay 7
setblock ~46~56~13 minecraft:wool 12
fill ~47~36~13 ~57~36~13 minecraft:stained_hardened_clay 7
fill ~47~37~13 ~47~39~13 minecraft:stained_hardened_clay 7
fill ~47~41~13 ~49~41~13 minecraft:stained_hardened_clay 7
fill ~47~43~13 ~47~43~20 minecraft:stained_hardened_clay 12
fill ~47~44~13 ~48~44~14 minecraft:stained_hardened_clay 12
fill ~47~45~13 ~47~45~18 minecraft:stained_hardened_clay 12
fill ~47~47~13 ~47~48~13 minecraft:stained_hardened_clay 12
fill ~47~50~13 ~47~50~14 minecraft:stained_hardened_clay 12
setblock ~47~54~13 minecraft:stained_hardened_clay 12
fill ~47~56~13 ~48~56~13 minecraft:wool 7
fill ~48~38~13 ~48~39~13 minecraft:stained_hardened_clay 7
fill ~48~42~13 ~48~42~19 minecraft:stained_hardened_clay 12
fill ~48~43~13 ~48~43~14 minecraft:stained_hardened_clay 7
fill ~48~45~13 ~48~45~14 minecraft:stained_hardened_clay 7
setblock ~48~48~13 minecraft:stained_hardened_clay 7
fill ~48~50~13 ~48~50~17 minecraft:stained_hardened_clay 7
fill ~48~54~13 ~51~54~15 minecraft:stained_hardened_clay 7
fill ~49~38~13 ~49~38~14 minecraft:stained_hardened_clay 12
setblock ~49~39~13 minecraft:stained_hardened_clay 12
fill ~49~42~13 ~51~42~13 minecraft:stained_hardened_clay 7
fill ~49~43~13 ~50~43~13 minecraft:stained_hardened_clay 12
fill ~49~44~13 ~49~44~16 minecraft:stained_hardened_clay 7
fill ~49~47~13 ~51~47~13 minecraft:stained_hardened_clay 12
fill ~49~53~13 ~50~53~13 minecraft:stained_hardened_clay 12
setblock ~49~56~13 minecraft:wool 12
fill ~50~34~13 ~51~34~14 minecraft:stained_hardened_clay 7
fill ~50~37~13 ~53~37~13 minecraft:stained_hardened_clay 7
fill ~50~38~13 ~52~38~13 minecraft:stained_hardened_clay 7
fill ~50~39~13 ~50~39~15 minecraft:stained_hardened_clay 7
fill ~50~41~13 ~50~41~14 minecraft:stained_hardened_clay 12
fill ~50~48~13 ~50~48~15 minecraft:stained_hardened_clay 7
fill ~50~51~13 ~54~51~13 minecraft:stained_hardened_clay 7
setblock ~50~52~13 minecraft:stained_hardened_clay 12
fill ~50~56~13 ~52~56~13 minecraft:wool 7
fill ~51~39~13 ~51~39~20 minecraft:stained_hardened_clay 12
fill ~51~40~13 ~51~41~13 minecraft:stained_hardened_clay 7
fill ~51~43~13 ~52~43~15 minecraft:stained_hardened_clay 7
fill ~51~45~13 ~55~45~13 minecraft:stained_hardened_clay 7
setblock ~51~53~13 minecraft:stained_hardened_clay 7
setblock ~52~34~13 minecraft:stained_hardened_clay 12
setblock ~52~39~13 minecraft:stained_hardened_clay 7
fill ~52~47~13 ~57~47~15 minecraft:stained_hardened_clay 7
fill ~52~50~13 ~52~50~15 minecraft:stained_hardened_clay 7
fill ~52~53~13 ~54~55~22 minecraft:stained_hardened_clay 12
fill ~53~34~13 ~54~34~14 minecraft:stained_hardened_clay 7
fill ~53~41~13 ~53~41~14 minecraft:stained_hardened_clay 7
fill ~53~43~13 ~53~43~14 minecraft:stained_hardened_clay 12
fill ~53~52~13 ~53~52~23 minecraft:stained_hardened_clay 12
fill ~53~56~13 ~54~56~13 minecraft:wool 8
setblock ~54~33~13 minecraft:stained_hardened_clay 12
setblock ~54~37~13 minecraft:stained_hardened_clay 12
fill ~54~49~13 ~57~49~16 minecraft:stained_hardened_clay 7
fill ~55~32~13 ~56~32~13 minecraft:stained_hardened_clay 7
setblock ~55~33~13 minecraft:stained_hardened_clay 7
fill ~55~37~13 ~55~37~15 minecraft:stained_hardened_clay 7
fill ~55~51~13 ~55~51~14 minecraft:stained_hardened_clay 12
setblock ~55~52~13 minecraft:stained_hardened_clay 12
fill ~55~53~13 ~56~53~13 minecraft:stained_hardened_clay 7
fill ~55~54~13 ~56~54~23 minecraft:stained_hardened_clay 12
fill ~55~55~13 ~55~55~23 minecraft:stained_hardened_clay 12
setblock ~56~37~13 minecraft:stained_hardened_clay 12
fill ~56~38~13 ~56~38~16 minecraft:stained_hardened_clay 7
setblock ~56~45~13 minecraft:stained_hardened_clay 12
fill ~56~50~13 ~56~50~15 minecraft:stained_hardened_clay 7
fill ~56~51~13 ~57~52~13 minecraft:stained_hardened_clay 7
fill ~56~55~13 ~57~55~13 minecraft:wool 7
fill ~57~30~13 ~57~30~15 minecraft:stained_hardened_clay 7
setblock ~57~31~13 minecraft:stained_hardened_clay 12
fill ~57~35~13 ~57~35~17 minecraft:stained_hardened_clay 7
fill ~57~37~13 ~57~37~14 minecraft:stained_hardened_clay 7
setblock ~57~38~13 minecraft:stained_hardened_clay 12
fill ~57~40~13 ~57~40~16 minecraft:stained_hardened_clay 7
fill ~57~45~13 ~61~45~15 minecraft:stained_hardened_clay 7
setblock ~57~50~13 minecraft:stained_hardened_clay 12
setblock ~57~53~13 minecraft:stained_hardened_clay 12
fill ~57~54~13 ~58~54~13 minecraft:stained_hardened_clay 7
fill ~58~28~13 ~59~28~15 minecraft:stained_hardened_clay 7
fill ~58~29~13 ~58~29~17 minecraft:stained_hardened_clay 7
fill ~58~31~13 ~58~31~14 minecraft:stained_hardened_clay 7
fill ~58~36~13 ~58~36~14 minecraft:stained_hardened_clay 12
fill ~58~38~13 ~58~38~16 minecraft:stained_hardened_clay 7
fill ~58~48~13 ~58~48~14 minecraft:stained_hardened_clay 7
fill ~58~49~13 ~58~49~16 minecraft:stained_hardened_clay 12
fill ~58~50~13 ~63~50~13 minecraft:stained_hardened_clay 7
fill ~58~51~13 ~58~51~14 minecraft:stained_hardened_clay 12
fill ~58~53~13 ~60~53~14 minecraft:stained_hardened_clay 7
setblock ~58~55~13 minecraft:wool 8
fill ~59~26~13 ~59~27~14 minecraft:stained_hardened_clay 7
fill ~59~47~13 ~59~47~14 minecraft:stained_hardened_clay 7
fill ~59~49~13 ~59~49~16 minecraft:stained_hardened_clay 7
fill ~59~51~13 ~62~51~13 minecraft:stained_hardened_clay 7
fill ~59~54~13 ~77~54~13 minecraft:stained_hardened_clay 12
fill ~59~55~13 ~60~55~13 minecraft:wool 7
setblock ~60~23~13 minecraft:stained_hardened_clay 12
fill ~60~24~13 ~61~24~14 minecraft:stained_hardened_clay 7
fill ~60~25~13 ~60~25~14 minecraft:stained_hardened_clay 7
fill ~60~26~13 ~60~26~14 minecraft:stained_hardened_clay 12
fill ~60~30~13 ~60~30~16 minecraft:stained_hardened_clay 7
fill ~60~32~13 ~60~34~13 minecraft:stained_hardened_clay 7
fill ~60~47~13 ~61~47~13 minecraft:stained_hardened_clay 12
setblock ~60~49~13 minecraft:stained_hardened_clay 12
setblock ~61~22~13 minecraft:stained_hardened_clay 12
fill ~61~23~13 ~62~23~13 minecraft:stained_hardened_clay 7
fill ~61~28~13 ~61~28~14 minecraft:stained_hardened_clay 7
fill ~61~29~13 ~62~29~13 minecraft:stained_hardened_clay 7
fill ~61~32~13 ~61~33~20 minecraft:stained_hardened_clay 12
setblock ~61~34~13 minecraft:stained_hardened_clay 7
fill ~61~41~13 ~61~41~16 minecraft:stained_hardened_clay 7
setblock ~61~48~13 minecraft:stained_hardened_clay 12
fill ~61~52~13 ~62~52~14 minecraft:stained_hardened_clay 7
fill ~61~53~13 ~77~53~14 minecraft:stained_hardened_clay 12
fill ~61~55~13 ~65~55~13 minecraft:wool 8
fill ~61~56~13 ~61~56~14 minecraft:wool 8
fill ~62~21~13 ~65~21~14 minecraft:stained_hardened_clay 7
fill ~62~22~13 ~62~22~17 minecraft:stained_hardened_clay 7
fill ~62~25~13 ~62~25~16 minecraft:stained_hardened_clay 7
fill ~62~27~13 ~62~28~13 minecraft:stained_hardened_clay 12
fill ~62~30~13 ~62~30~14 minecraft:stained_hardened_clay 12
fill ~62~32~13 ~62~32~14 minecraft:stained_hardened_clay 7
fill ~62~38~13 ~65~38~14 minecraft:stained_hardened_clay 7
fill ~62~47~13 ~64~47~14 minecraft:stained_hardened_clay 7
fill ~63~19~13 ~63~19~15 minecraft:stained_hardened_clay 7
setblock ~63~20~13 minecraft:stained_hardened_clay 7
setblock ~63~25~13 minecraft:stained_hardened_clay 12
fill ~63~27~13 ~63~27~15 minecraft:stained_hardened_clay 7
fill ~63~30~13 ~65~30~14 minecraft:stained_hardened_clay 7
fill ~63~31~13 ~64~31~13 minecraft:stained_hardened_clay 7
fill ~63~32~13 ~63~33~13 minecraft:stained_hardened_clay 12
fill ~63~37~13 ~66~37~13 minecraft:stained_hardened_clay 12
fill ~63~39~13 ~65~39~13 minecraft:stained_hardened_clay 7
fill ~63~40~13 ~63~40~16 minecraft:stained_hardened_clay 7
fill ~63~51~13 ~63~52~22 minecraft:stained_hardened_clay 12
fill ~63~58~13 ~63~58~14 minecraft:stained_hardened_clay 12
fill ~64~18~13 ~67~18~14 minecraft:stained_hardened_clay 7
fill ~64~19~13 ~65~19~13 minecraft:stained_hardened_clay 12
setblock ~64~20~13 minecraft:stained_hardened_clay 12
fill ~64~24~13 ~66~24~16 minecraft:stained_hardened_clay 7
fill ~64~25~13 ~64~25~14 minecraft:stained_hardened_clay 7
fill ~64~27~13 ~65~27~13 minecraft:stained_hardened_clay 12
setblock ~64~33~13 minecraft:stained_hardened_clay 7
setblock ~64~40~13 minecraft:stained_hardened_clay 12
fill ~64~45~13 ~64~45~14 minecraft:stained_hardened_clay 7
fill ~64~50~13 ~64~50~21 minecraft:stained_hardened_clay 12
fill ~65~20~13 ~69~20~18 minecraft:stained_hardened_clay 7
setblock ~65~25~13 minecraft:stained_hardened_clay 12
fill ~65~26~13 ~65~26~16 minecraft:stained_hardened_clay 7
fill ~65~29~13 ~65~29~16 minecraft:stained_hardened_clay 12
setblock ~65~31~13 minecraft:stained_hardened_clay 12
setblock ~65~35~13 minecraft:stained_hardened_clay 7
setblock ~65~43~13 minecraft:stained_hardened_clay 12
fill ~65~46~13 ~65~46~15 minecraft:stained_hardened_clay 7
fill ~65~47~13 ~66~47~13 minecraft:stained_hardened_clay 12
fill ~65~49~13 ~66~50~13 minecraft:stained_hardened_clay 7
fill ~66~19~13 ~68~19~13 minecraft:stained_hardened_clay 7
setblock ~66~21~13 minecraft:stained_hardened_clay 12
fill ~66~22~13 ~66~22~20 minecraft:stained_hardened_clay 7
fill ~66~25~13 ~66~25~16 minecraft:stained_hardened_clay 7
setblock ~66~29~13 minecraft:stained_hardened_clay 7
fill ~66~35~13 ~66~35~17 minecraft:stained_hardened_clay 12
fill ~66~38~13 ~66~38~16 minecraft:stained_hardened_clay 12
fill ~66~39~13 ~67~39~13 minecraft:stained_hardened_clay 12
setblock ~66~48~13 minecraft:stained_hardened_clay 7
setblock ~66~55~13 minecraft:wool 7
fill ~67~21~13 ~70~21~14 minecraft:stained_hardened_clay 7
setblock ~67~24~13 minecraft:stained_hardened_clay 12
fill ~67~28~13 ~67~29~16 minecraft:stained_hardened_clay 12
fill ~67~43~13 ~68~43~13 minecraft:stained_hardened_clay 7
fill ~67~44~13 ~67~44~14 minecraft:stained_hardened_clay 7
setblock ~67~46~13 minecraft:stained_hardened_clay 7
fill ~67~49~13 ~67~49~20 minecraft:stained_hardened_clay 12
setblock ~67~50~13 minecraft:stained_hardened_clay 7
setblock ~67~55~13 minecraft:wool 8
fill ~68~22~13 ~70~22~13 minecraft:stained_hardened_clay 7
setblock ~68~23~13 minecraft:stained_hardened_clay 12
fill ~68~24~13 ~68~24~15 minecraft:stained_hardened_clay 7
setblock ~68~31~13 minecraft:stained_hardened_clay 12
fill ~68~33~13 ~68~33~14 minecraft:stained_hardened_clay 7
setblock ~68~34~13 minecraft:stained_hardened_clay 12
fill ~68~35~13 ~68~35~14 minecraft:stained_hardened_clay 7
setblock ~68~41~13 minecraft:stained_hardened_clay 7
setblock ~68~42~13 minecraft:stained_hardened_clay 12
fill ~68~44~13 ~69~44~13 minecraft:stained_hardened_clay 12
fill ~68~49~13 ~70~49~13 minecraft:stained_hardened_clay 7
fill ~68~55~13 ~70~55~13 minecraft:wool 7
fill ~69~23~13 ~71~23~15 minecraft:stained_hardened_clay 7
fill ~69~28~13 ~70~28~13 minecraft:stained_hardened_clay 12
fill ~69~29~13 ~69~30~16 minecraft:stained_hardened_clay 7
fill ~69~35~13 ~69~35~15 minecraft:stained_hardened_clay 12
fill ~69~37~13 ~70~37~13 minecraft:stained_hardened_clay 12
fill ~69~38~13 ~69~38~16 minecraft:stained_hardened_clay 12
setblock ~69~45~13 minecraft:stained_hardened_clay 12
fill ~69~50~13 ~70~50~23 minecraft:stained_hardened_clay 12
fill ~70~24~13 ~70~24~14 minecraft:stained_hardened_clay 7
setblock ~70~30~13 minecraft:stained_hardened_clay 12
fill ~70~31~13 ~70~31~21 minecraft:stained_hardened_clay 7
fill ~70~32~13 ~71~32~13 minecraft:stained_hardened_clay 12
fill ~70~34~13 ~70~36~13 minecraft:stained_hardened_clay 7
fill ~70~38~13 ~72~38~13 minecraft:stained_hardened_clay 7
fill ~70~42~13 ~70~42~17 minecraft:stained_hardened_clay 12
fill ~71~0~13 ~72~0~14 minecraft:coal_block
setblock ~71~24~13 minecraft:stained_hardened_clay 12
fill ~71~30~13 ~71~30~21 minecraft:stained_hardened_clay 7
setblock ~71~33~13 minecraft:stained_hardened_clay 7
setblock ~71~35~13 minecraft:stained_hardened_clay 12
fill ~71~36~13 ~71~36~14 minecraft:stained_hardened_clay 7
fill ~71~41~13 ~73~41~17 minecraft:stained_hardened_clay 12
setblock ~71~50~13 minecraft:stained_hardened_clay 7
fill ~71~55~13 ~72~55~13 minecraft:wool 8
setblock ~72~27~13 minecraft:stained_hardened_clay 12
fill ~72~32~13 ~75~32~14 minecraft:stained_hardened_clay 7
setblock ~72~36~13 minecraft:stained_hardened_clay 12
fill ~72~37~13 ~72~37~14 minecraft:stained_hardened_clay 7
fill ~72~42~13 ~72~44~13 minecraft:stained_hardened_clay 7
setblock ~72~46~13 minecraft:stained_hardened_clay 7
fill ~72~49~13 ~72~49~21 minecraft:stained_hardened_clay 12
fill ~73~31~13 ~74~31~14 minecraft:stained_hardened_clay 7
fill ~73~33~13 ~75~33~14 minecraft:stained_hardened_clay 7
setblock ~73~34~13 minecraft:stained_hardened_clay 7
fill ~73~36~13 ~73~36~14 minecraft:stained_hardened_clay 7
fill ~73~37~13 ~73~38~16 minecraft:stained_hardened_clay 12
fill ~73~47~13 ~73~47~14 minecraft:stained_hardened_clay 7
setblock ~73~49~13 minecraft:stained_hardened_clay 7
fill ~73~51~13 ~73~51~23 minecraft:stained_hardened_clay 12
setblock ~73~55~13 minecraft:wool 7
fill ~74~30~13 ~74~30~14 minecraft:stained_hardened_clay 7
fill ~74~34~13 ~75~34~13 minecraft:stained_hardened_clay 12
fill ~74~45~13 ~74~45~14 minecraft:stained_hardened_clay 7
fill ~74~49~13 ~76~49~20 minecraft:stained_hardened_clay 12
fill ~74~55~13 ~75~55~13 minecraft:wool 8
fill ~75~35~13 ~76~35~16 minecraft:stained_hardened_clay 12
fill ~75~42~13 ~75~43~18 minecraft:stained_hardened_clay 12
fill ~75~45~13 ~75~45~18 minecraft:stained_hardened_clay 12
setblock ~75~48~13 minecraft:stained_hardened_clay 7
fill ~75~50~13 ~75~50~22 minecraft:stained_hardened_clay 12
setblock ~76~34~13 minecraft:stained_hardened_clay 7
fill ~76~43~13 ~76~43~19 minecraft:stained_hardened_clay 12
fill ~76~45~13 ~76~46~13 minecraft:stained_hardened_clay 7
fill ~76~47~13 ~78~47~19 minecraft:stained_hardened_clay 12
fill ~76~48~13 ~77~48~20 minecraft:stained_hardened_clay 12
fill ~76~55~13 ~77~55~13 minecraft:wool 7
fill ~77~35~13 ~83~35~18 minecraft:stained_hardened_clay 7
fill ~77~41~13 ~77~41~18 minecraft:stained_hardened_clay 12
fill ~77~45~13 ~78~45~19 minecraft:stained_hardened_clay 12
fill ~78~41~13 ~80~41~14 minecraft:stained_hardened_clay 7
fill ~78~43~13 ~78~44~19 minecraft:stained_hardened_clay 12
fill ~78~46~13 ~78~46~20 minecraft:stained_hardened_clay 12
fill ~78~49~13 ~78~49~23 minecraft:stained_hardened_clay 12
fill ~78~53~13 ~79~53~14 minecraft:stained_hardened_clay 7
fill ~78~54~13 ~79~54~13 minecraft:wool 8
fill ~79~47~13 ~83~47~14 minecraft:stained_hardened_clay 7
fill ~80~52~13 ~81~52~19 minecraft:stained_hardened_clay 7
setblock ~80~53~13 minecraft:wool 7
setblock ~81~53~13 minecraft:wool 8
fill ~82~51~13 ~88~51~19 minecraft:stained_hardened_clay 7
setblock ~82~52~13 minecraft:wool 7
setblock ~83~52~13 minecraft:wool 8
fill ~84~36~13 ~85~36~22 minecraft:stained_hardened_clay 7
setblock ~84~52~13 minecraft:wool 7
fill ~85~43~13 ~89~46~14 minecraft:stained_hardened_clay 7
fill ~86~37~13 ~87~37~22 minecraft:stained_hardened_clay 7
fill ~86~40~13 ~90~40~13 minecraft:stained_hardened_clay 7
fill ~87~38~13 ~90~38~14 minecraft:stained_hardened_clay 7
fill ~89~50~13 ~90~50~16 minecraft:stained_hardened_clay 7
fill ~90~42~13 ~93~42~17 minecraft:stained_hardened_clay 12
fill ~90~43~13 ~91~43~17 minecraft:stained_hardened_clay 12
fill ~90~44~13 ~90~44~17 minecraft:stained_hardened_clay 12
fill ~90~45~13 ~90~47~13 minecraft:stained_hardened_clay 7
fill ~91~38~13 ~92~38~20 minecraft:stained_hardened_clay 12
fill ~91~39~13 ~92~39~13 minecraft:stained_hardened_clay 7
fill ~91~40~13 ~98~40~17 minecraft:stained_hardened_clay 12
fill ~91~45~13 ~91~45~17 minecraft:stained_hardened_clay 12
fill ~91~47~13 ~92~47~17 minecraft:stained_hardened_clay 12
fill ~91~50~13 ~95~50~13 minecraft:stained_hardened_clay 12
fill ~92~41~13 ~92~41~17 minecraft:stained_hardened_clay 12
fill ~92~44~13 ~92~44~17 minecraft:stained_hardened_clay 12
fill ~92~46~13 ~93~46~17 minecraft:stained_hardened_clay 12
setblock ~93~38~13 minecraft:stained_hardened_clay 7
fill ~93~39~13 ~93~39~19 minecraft:stained_hardened_clay 12
fill ~94~38~13 ~94~38~28 minecraft:stained_hardened_clay 12
setblock ~94~39~13 minecraft:stained_hardened_clay 7
fill ~94~43~13 ~94~44~17 minecraft:stained_hardened_clay 12
fill ~94~49~13 ~97~49~17 minecraft:stained_hardened_clay 12
fill ~95~39~13 ~97~39~29 minecraft:stained_hardened_clay 12
fill ~95~41~13 ~99~41~18 minecraft:stained_hardened_clay 12
fill ~96~48~13 ~98~48~18 minecraft:stained_hardened_clay 12
fill ~97~42~13 ~100~42~17 minecraft:stained_hardened_clay 12
fill ~97~43~13 ~100~43~16 minecraft:stained_hardened_clay 12
fill ~97~47~13 ~99~47~18 minecraft:stained_hardened_clay 12
fill ~98~44~13 ~100~46~17 minecraft:stained_hardened_clay 12
fill ~98~54~13 ~98~55~14 minecraft:stained_hardened_clay 7
setblock ~99~53~13 minecraft:stained_hardened_clay 7
fill ~99~56~13 ~99~56~15 minecraft:stained_hardened_clay 7
setblock ~99~57~13 minecraft:stained_hardened_clay 7
fill ~100~51~13 ~100~52~14 minecraft:stained_hardened_clay 7
setblock ~101~49~13 minecraft:wool 7
setblock ~101~51~13 minecraft:wool 7
fill ~15~28~14 ~19~29~19 minecraft:stained_hardened_clay 7
fill ~15~30~14 ~16~31~15 minecraft:stained_hardened_clay 7
fill ~15~32~14 ~16~32~14 minecraft:stained_hardened_clay 7
fill ~15~33~14 ~15~34~23 minecraft:stained_hardened_clay 7
fill ~15~35~14 ~16~35~21 minecraft:stained_hardened_clay 7
fill ~16~27~14 ~18~27~18 minecraft:stained_hardened_clay 7
setblock ~16~33~14 minecraft:stained_hardened_clay 12
fill ~16~34~14 ~16~34~22 minecraft:stained_hardened_clay 7
fill ~16~36~14 ~16~36~21 minecraft:stained_hardened_clay 7
setblock ~17~30~14 minecraft:stained_hardened_clay 12
fill ~17~31~14 ~18~31~16 minecraft:stained_hardened_clay 7
fill ~17~32~14 ~17~32~15 minecraft:stained_hardened_clay 12
setblock ~17~33~14 minecraft:stained_hardened_clay 7
setblock ~17~34~14 minecraft:stained_hardened_clay 12
fill ~17~37~14 ~18~37~19 minecraft:stained_hardened_clay 7
fill ~17~38~14 ~18~39~14 minecraft:stained_hardened_clay 12
fill ~17~40~14 ~19~41~14 minecraft:stained_hardened_clay 7
setblock ~17~42~14 minecraft:stained_hardened_clay 12
fill ~17~43~14 ~19~43~14 minecraft:stained_hardened_clay 7
fill ~17~44~14 ~18~46~16 minecraft:stained_hardened_clay 7
fill ~17~47~14 ~18~48~15 minecraft:stained_hardened_clay 7
fill ~17~49~14 ~18~49~14 minecraft:stained_hardened_clay 7
fill ~18~32~14 ~19~32~19 minecraft:stained_hardened_clay 7
fill ~18~34~14 ~19~34~15 minecraft:stained_hardened_clay 7
fill ~18~35~14 ~18~35~18 minecraft:stained_hardened_clay 7
setblock ~18~36~14 minecraft:stained_hardened_clay 12
fill ~18~42~14 ~20~42~16 minecraft:stained_hardened_clay 7
fill ~18~50~14 ~19~50~16 minecraft:stained_hardened_clay 7
setblock ~19~31~14 minecraft:stained_hardened_clay 12
fill ~19~33~14 ~21~33~14 minecraft:stained_hardened_clay 7
fill ~19~37~14 ~20~37~14 minecraft:stained_hardened_clay 12
fill ~19~38~14 ~19~39~14 minecraft:stained_hardened_clay 7
fill ~19~45~14 ~20~45~14 minecraft:stained_hardened_clay 7
fill ~19~46~14 ~19~47~14 minecraft:stained_hardened_clay 12
fill ~19~48~14 ~20~48~14 minecraft:stained_hardened_clay 7
fill ~19~49~14 ~20~49~14 minecraft:stained_hardened_clay 12
fill ~19~51~14 ~20~51~14 minecraft:stained_hardened_clay 12
fill ~19~52~14 ~19~52~16 minecraft:stained_hardened_clay 7
setblock ~20~28~14 minecraft:stained_hardened_clay 12
fill ~20~29~14 ~22~29~15 minecraft:stained_hardened_clay 7
setblock ~20~31~14 minecraft:stained_hardened_clay 7
fill ~20~34~14 ~20~35~14 minecraft:stained_hardened_clay 12
fill ~20~36~14 ~21~36~14 minecraft:stained_hardened_clay 7
fill ~20~38~14 ~23~38~15 minecraft:stained_hardened_clay 12
fill ~20~39~14 ~21~39~14 minecraft:stained_hardened_clay 12
fill ~20~43~14 ~21~43~14 minecraft:stained_hardened_clay 12
fill ~20~47~14 ~20~47~18 minecraft:stained_hardened_clay 7
setblock ~20~52~14 minecraft:stained_hardened_clay 12
fill ~20~53~14 ~20~54~16 minecraft:stained_hardened_clay 7
fill ~21~30~14 ~23~30~14 minecraft:stained_hardened_clay 7
fill ~21~31~14 ~21~31~15 minecraft:stained_hardened_clay 12
fill ~21~32~14 ~21~32~15 minecraft:stained_hardened_clay 7
fill ~21~34~14 ~23~34~16 minecraft:stained_hardened_clay 7
fill ~21~37~14 ~21~37~16 minecraft:stained_hardened_clay 7
fill ~21~44~14 ~21~44~15 minecraft:stained_hardened_clay 7
fill ~21~45~14 ~21~47~14 minecraft:stained_hardened_clay 12
fill ~21~49~14 ~21~49~18 minecraft:stained_hardened_clay 7
setblock ~21~54~14 minecraft:stained_hardened_clay 7
setblock ~21~55~14 minecraft:stained_hardened_clay 12
fill ~21~56~14 ~25~56~15 minecraft:stained_hardened_clay 7
fill ~22~31~14 ~23~31~14 minecraft:stained_hardened_clay 7
fill ~22~33~14 ~22~33~15 minecraft:stained_hardened_clay 12
fill ~22~35~14 ~22~35~17 minecraft:stained_hardened_clay 7
setblock ~22~39~14 minecraft:stained_hardened_clay 7
fill ~22~42~14 ~23~42~14 minecraft:stained_hardened_clay 12
fill ~22~43~14 ~25~43~15 minecraft:stained_hardened_clay 7
fill ~22~45~14 ~23~45~17 minecraft:stained_hardened_clay 7
fill ~22~46~14 ~23~46~16 minecraft:stained_hardened_clay 7
fill ~22~47~14 ~23~47~14 minecraft:stained_hardened_clay 7
setblock ~22~49~14 minecraft:stained_hardened_clay 12
fill ~22~50~14 ~22~50~16 minecraft:stained_hardened_clay 7
fill ~22~52~14 ~22~52~18 minecraft:stained_hardened_clay 7
fill ~22~53~14 ~22~53~17 minecraft:stained_hardened_clay 7
fill ~22~55~14 ~23~55~16 minecraft:stained_hardened_clay 7
fill ~23~33~14 ~23~33~15 minecraft:stained_hardened_clay 7
fill ~23~49~14 ~23~49~15 minecraft:stained_hardened_clay 7
setblock ~23~50~14 minecraft:stained_hardened_clay 12
fill ~23~52~14 ~23~53~14 minecraft:stained_hardened_clay 12
fill ~23~54~14 ~24~54~17 minecraft:stained_hardened_clay 7
setblock ~24~31~14 minecraft:stained_hardened_clay 12
setblock ~24~35~14 minecraft:stained_hardened_clay 12
setblock ~24~38~14 minecraft:stained_hardened_clay 7
setblock ~24~40~14 minecraft:stained_hardened_clay 12
fill ~24~42~14 ~26~42~15 minecraft:stained_hardened_clay 7
setblock ~24~45~14 minecraft:stained_hardened_clay 12
fill ~24~50~14 ~26~50~16 minecraft:stained_hardened_clay 7
fill ~24~52~14 ~25~52~19 minecraft:stained_hardened_clay 7
setblock ~24~53~14 minecraft:stained_hardened_clay 12
fill ~25~32~14 ~25~32~16 minecraft:stained_hardened_clay 7
setblock ~25~34~14 minecraft:stained_hardened_clay 12
fill ~25~35~14 ~25~35~16 minecraft:stained_hardened_clay 7
fill ~25~36~14 ~25~36~15 minecraft:stained_hardened_clay 7
fill ~25~40~14 ~27~40~15 minecraft:stained_hardened_clay 7
fill ~25~45~14 ~25~45~16 minecraft:stained_hardened_clay 7
fill ~25~48~14 ~26~48~16 minecraft:stained_hardened_clay 7
fill ~25~49~14 ~25~49~16 minecraft:stained_hardened_clay 7
fill ~25~53~14 ~26~53~14 minecraft:stained_hardened_clay 7
fill ~25~57~14 ~32~57~14 minecraft:stained_hardened_clay 7
fill ~26~33~14 ~26~33~17 minecraft:stained_hardened_clay 7
fill ~26~34~14 ~27~34~16 minecraft:stained_hardened_clay 7
setblock ~26~36~14 minecraft:stained_hardened_clay 12
setblock ~26~38~14 minecraft:stained_hardened_clay 12
fill ~26~49~14 ~28~49~14 minecraft:stained_hardened_clay 12
setblock ~26~52~14 minecraft:stained_hardened_clay 12
fill ~27~35~14 ~27~36~14 minecraft:stained_hardened_clay 7
fill ~27~37~14 ~28~37~14 minecraft:stained_hardened_clay 12
setblock ~27~38~14 minecraft:stained_hardened_clay 7
fill ~27~52~14 ~27~52~18 minecraft:stained_hardened_clay 7
fill ~27~58~14 ~36~58~15 minecraft:stained_hardened_clay 7
setblock ~28~35~14 minecraft:stained_hardened_clay 12
fill ~28~36~14 ~28~36~16 minecraft:stained_hardened_clay 7
fill ~28~44~14 ~28~44~17 minecraft:stained_hardened_clay 7
setblock ~28~46~14 minecraft:stained_hardened_clay 12
setblock ~28~50~14 minecraft:stained_hardened_clay 12
fill ~28~55~14 ~29~55~19 minecraft:stained_hardened_clay 7
fill ~29~37~14 ~29~37~15 minecraft:stained_hardened_clay 7
fill ~29~39~14 ~29~39~15 minecraft:stained_hardened_clay 12
fill ~29~46~14 ~34~46~15 minecraft:stained_hardened_clay 7
fill ~29~48~14 ~29~48~15 minecraft:stained_hardened_clay 7
setblock ~29~49~14 minecraft:wool 0
fill ~29~50~14 ~35~50~16 minecraft:stained_hardened_clay 7
fill ~29~59~14 ~31~59~16 minecraft:stained_hardened_clay 7
fill ~30~38~14 ~30~39~16 minecraft:stained_hardened_clay 7
setblock ~30~42~14 minecraft:stained_hardened_clay 12
fill ~30~51~14 ~30~51~15 minecraft:stained_hardened_clay 7
setblock ~30~55~14 minecraft:stained_hardened_clay 12
fill ~31~39~14 ~31~39~18 minecraft:stained_hardened_clay 7
fill ~31~42~14 ~31~42~17 minecraft:stained_hardened_clay 7
fill ~31~55~14 ~33~55~16 minecraft:stained_hardened_clay 7
setblock ~31~60~14 minecraft:wool 7
fill ~32~40~14 ~32~40~16 minecraft:stained_hardened_clay 7
setblock ~32~51~14 minecraft:stained_hardened_clay 7
setblock ~32~59~14 minecraft:wool 12
fill ~33~41~14 ~36~41~14 minecraft:stained_hardened_clay 7
setblock ~33~57~14 minecraft:stained_hardened_clay 12
fill ~33~59~14 ~34~59~14 minecraft:wool 8
fill ~34~42~14 ~35~42~14 minecraft:stained_hardened_clay 7
fill ~34~57~14 ~35~57~17 minecraft:stained_hardened_clay 7
fill ~35~40~14 ~36~40~15 minecraft:stained_hardened_clay 7
setblock ~35~59~14 minecraft:wool 12
fill ~36~39~14 ~37~39~16 minecraft:stained_hardened_clay 7
fill ~36~47~14 ~38~47~14 minecraft:stained_hardened_clay 7
fill ~36~48~14 ~36~48~17 minecraft:stained_hardened_clay 7
fill ~36~49~14 ~36~49~16 minecraft:stained_hardened_clay 7
fill ~36~53~14 ~37~53~16 minecraft:stained_hardened_clay 7
fill ~36~56~14 ~44~56~15 minecraft:stained_hardened_clay 7
setblock ~36~57~14 minecraft:stained_hardened_clay 12
setblock ~36~59~14 minecraft:wool 7
fill ~37~38~14 ~38~38~14 minecraft:stained_hardened_clay 7
fill ~37~42~14 ~39~42~18 minecraft:stained_hardened_clay 7
fill ~37~55~14 ~48~55~14 minecraft:stained_hardened_clay 7
fill ~37~57~14 ~40~57~14 minecraft:stained_hardened_clay 7
setblock ~37~58~14 minecraft:wool 7
fill ~38~37~14 ~43~37~14 minecraft:stained_hardened_clay 7
fill ~38~43~14 ~40~43~17 minecraft:stained_hardened_clay 7
fill ~38~45~14 ~38~45~15 minecraft:stained_hardened_clay 7
setblock ~38~46~14 minecraft:stained_hardened_clay 7
setblock ~38~53~14 minecraft:stained_hardened_clay 12
fill ~38~54~14 ~40~54~15 minecraft:stained_hardened_clay 7
fill ~38~58~14 ~39~58~14 minecraft:wool 12
fill ~39~36~14 ~40~36~18 minecraft:stained_hardened_clay 7
setblock ~39~45~14 minecraft:stained_hardened_clay 12
setblock ~39~47~14 minecraft:stained_hardened_clay 12
fill ~39~53~14 ~46~53~15 minecraft:stained_hardened_clay 7
setblock ~40~42~14 minecraft:stained_hardened_clay 12
setblock ~40~45~14 minecraft:stained_hardened_clay 7
fill ~40~47~14 ~41~47~14 minecraft:stained_hardened_clay 7
fill ~40~48~14 ~40~48~19 minecraft:stained_hardened_clay 12
fill ~40~51~14 ~43~51~15 minecraft:stained_hardened_clay 7
setblock ~40~58~14 minecraft:wool 7
fill ~41~35~14 ~41~35~18 minecraft:stained_hardened_clay 7
fill ~41~48~14 ~43~48~14 minecraft:stained_hardened_clay 7
fill ~41~57~14 ~42~57~14 minecraft:wool 7
fill ~42~34~14 ~42~34~18 minecraft:stained_hardened_clay 7
setblock ~42~35~14 minecraft:stained_hardened_clay 12
setblock ~42~49~14 minecraft:stained_hardened_clay 12
fill ~42~54~14 ~42~54~18 minecraft:stained_hardened_clay 7
fill ~43~34~14 ~43~34~15 minecraft:stained_hardened_clay 12
fill ~43~35~14 ~45~35~15 minecraft:stained_hardened_clay 7
fill ~43~38~14 ~44~38~17 minecraft:stained_hardened_clay 7
fill ~43~39~14 ~43~39~18 minecraft:stained_hardened_clay 7
fill ~43~41~14 ~43~41~16 minecraft:stained_hardened_clay 7
fill ~43~49~14 ~43~49~16 minecraft:stained_hardened_clay 7
fill ~43~57~14 ~47~57~14 minecraft:wool 8
fill ~44~34~14 ~45~34~15 minecraft:stained_hardened_clay 7
fill ~44~37~14 ~44~37~15 minecraft:stained_hardened_clay 12
fill ~44~50~14 ~46~50~14 minecraft:stained_hardened_clay 7
fill ~44~51~14 ~45~51~14 minecraft:stained_hardened_clay 12
fill ~45~37~14 ~45~37~19 minecraft:stained_hardened_clay 7
setblock ~45~38~14 minecraft:stained_hardened_clay 12
fill ~45~42~14 ~46~42~15 minecraft:stained_hardened_clay 7
fill ~45~48~14 ~45~49~14 minecraft:stained_hardened_clay 7
fill ~45~52~14 ~47~52~14 minecraft:stained_hardened_clay 7
setblock ~45~54~14 minecraft:stained_hardened_clay 7
setblock ~45~56~14 minecraft:stained_hardened_clay 12
fill ~46~34~14 ~46~35~14 minecraft:stained_hardened_clay 12
fill ~46~36~14 ~47~36~16 minecraft:stained_hardened_clay 7
fill ~46~37~14 ~47~37~14 minecraft:stained_hardened_clay 12
fill ~46~38~14 ~47~39~14 minecraft:stained_hardened_clay 7
fill ~46~41~14 ~47~41~16 minecraft:stained_hardened_clay 7
setblock ~46~49~14 minecraft:stained_hardened_clay 7
setblock ~46~51~14 minecraft:stained_hardened_clay 7
fill ~46~56~14 ~48~56~16 minecraft:stained_hardened_clay 7
fill ~47~34~14 ~49~35~14 minecraft:stained_hardened_clay 7
fill ~47~40~14 ~48~40~15 minecraft:stained_hardened_clay 7
fill ~47~42~14 ~47~42~20 minecraft:stained_hardened_clay 12
fill ~47~46~14 ~47~46~21 minecraft:stained_hardened_clay 12
setblock ~47~47~14 minecraft:stained_hardened_clay 7
fill ~47~48~14 ~48~48~14 minecraft:stained_hardened_clay 12
fill ~47~49~14 ~47~49~15 minecraft:stained_hardened_clay 12
setblock ~47~51~14 minecraft:stained_hardened_clay 12
setblock ~47~53~14 minecraft:stained_hardened_clay 12
fill ~47~54~14 ~47~54~16 minecraft:stained_hardened_clay 7
fill ~48~33~14 ~54~33~14 minecraft:stained_hardened_clay 7
setblock ~48~36~14 minecraft:stained_hardened_clay 12
setblock ~48~38~14 minecraft:stained_hardened_clay 12
fill ~48~39~14 ~49~39~16 minecraft:stained_hardened_clay 7
setblock ~48~41~14 minecraft:stained_hardened_clay 12
fill ~48~46~14 ~50~46~14 minecraft:stained_hardened_clay 7
fill ~48~47~14 ~48~47~18 minecraft:stained_hardened_clay 12
fill ~48~49~14 ~50~49~14 minecraft:stained_hardened_clay 7
setblock ~48~52~14 minecraft:stained_hardened_clay 12
fill ~48~53~14 ~50~53~16 minecraft:stained_hardened_clay 7
fill ~48~57~14 ~50~57~14 minecraft:wool 7
fill ~49~36~14 ~51~36~15 minecraft:stained_hardened_clay 7
setblock ~49~40~14 minecraft:stained_hardened_clay 12
setblock ~49~41~14 minecraft:stained_hardened_clay 7
fill ~49~42~14 ~49~43~14 minecraft:stained_hardened_clay 12
setblock ~49~47~14 minecraft:stained_hardened_clay 7
fill ~49~52~14 ~50~52~14 minecraft:stained_hardened_clay 7
fill ~49~55~14 ~50~55~14 minecraft:stained_hardened_clay 12
setblock ~49~56~14 minecraft:stained_hardened_clay 12
fill ~50~35~14 ~51~35~17 minecraft:stained_hardened_clay 7
fill ~50~37~14 ~50~37~17 minecraft:stained_hardened_clay 7
setblock ~50~38~14 minecraft:stained_hardened_clay 12
setblock ~50~40~14 minecraft:stained_hardened_clay 7
fill ~50~42~14 ~51~42~14 minecraft:stained_hardened_clay 7
fill ~50~43~14 ~50~43~16 minecraft:stained_hardened_clay 7
fill ~50~44~14 ~51~44~15 minecraft:stained_hardened_clay 7
fill ~50~47~14 ~51~47~14 minecraft:stained_hardened_clay 12
fill ~50~51~14 ~51~51~14 minecraft:stained_hardened_clay 7
fill ~50~56~14 ~50~56~15 minecraft:stained_hardened_clay 7
fill ~51~32~14 ~53~32~14 minecraft:stained_hardened_clay 7
fill ~51~37~14 ~52~37~14 minecraft:stained_hardened_clay 12
setblock ~51~38~14 minecraft:stained_hardened_clay 7
fill ~51~40~14 ~51~40~19 minecraft:stained_hardened_clay 12
fill ~51~41~14 ~51~41~17 minecraft:stained_hardened_clay 12
fill ~51~45~14 ~51~45~16 minecraft:stained_hardened_clay 7
setblock ~51~46~14 minecraft:stained_hardened_clay 12
fill ~51~48~14 ~51~48~16 minecraft:stained_hardened_clay 12
setblock ~51~49~14 minecraft:stained_hardened_clay 12
fill ~51~52~14 ~51~53~14 minecraft:stained_hardened_clay 12
setblock ~51~55~14 minecraft:stained_hardened_clay 7
fill ~51~56~14 ~56~56~23 minecraft:stained_hardened_clay 12
fill ~51~57~14 ~54~57~25 minecraft:stained_hardened_clay 12
setblock ~51~58~14 minecraft:wool 8
setblock ~52~34~14 minecraft:stained_hardened_clay 7
fill ~52~35~14 ~52~36~14 minecraft:stained_hardened_clay 12
fill ~52~38~14 ~52~39~22 minecraft:stained_hardened_clay 12
fill ~52~44~14 ~52~45~14 minecraft:stained_hardened_clay 12
setblock ~52~46~14 minecraft:stained_hardened_clay 7
fill ~52~48~14 ~52~48~16 minecraft:stained_hardened_clay 7
fill ~52~51~14 ~53~51~23 minecraft:stained_hardened_clay 12
setblock ~52~58~14 minecraft:wool 12
fill ~53~31~14 ~54~31~14 minecraft:stained_hardened_clay 12
fill ~53~35~14 ~53~36~17 minecraft:stained_hardened_clay 7
fill ~53~37~14 ~54~37~16 minecraft:stained_hardened_clay 7
fill ~53~38~14 ~54~38~15 minecraft:stained_hardened_clay 7
fill ~53~39~14 ~54~39~14 minecraft:stained_hardened_clay 7
fill ~53~44~14 ~61~44~14 minecraft:stained_hardened_clay 7
fill ~53~45~14 ~56~45~14 minecraft:stained_hardened_clay 7
setblock ~53~50~14 minecraft:stained_hardened_clay 12
setblock ~53~58~14 minecraft:wool 8
fill ~54~32~14 ~55~32~14 minecraft:stained_hardened_clay 12
fill ~54~36~14 ~57~36~16 minecraft:stained_hardened_clay 7
fill ~54~50~14 ~54~50~15 minecraft:stained_hardened_clay 7
setblock ~54~51~14 minecraft:stained_hardened_clay 7
setblock ~54~58~14 minecraft:wool 7
setblock ~55~31~14 minecraft:stained_hardened_clay 7
fill ~55~33~14 ~55~33~15 minecraft:stained_hardened_clay 12
fill ~55~38~14 ~55~39~14 minecraft:stained_hardened_clay 12
fill ~55~42~14 ~55~43~14 minecraft:stained_hardened_clay 12
setblock ~55~50~14 minecraft:stained_hardened_clay 12
fill ~55~52~14 ~57~52~15 minecraft:stained_hardened_clay 7
fill ~55~53~14 ~56~53~22 minecraft:stained_hardened_clay 12
setblock ~55~57~14 minecraft:wool 7
fill ~56~30~14 ~56~30~15 minecraft:stained_hardened_clay 7
fill ~56~31~14 ~56~31~15 minecraft:stained_hardened_clay 12
setblock ~56~32~14 minecraft:stained_hardened_clay 7
setblock ~56~37~14 minecraft:stained_hardened_clay 7
fill ~56~39~14 ~58~39~15 minecraft:stained_hardened_clay 7
fill ~56~42~14 ~56~43~15 minecraft:stained_hardened_clay 7
setblock ~56~51~14 minecraft:stained_hardened_clay 12
fill ~56~55~14 ~76~55~23 minecraft:stained_hardened_clay 12
setblock ~56~57~14 minecraft:wool 8
fill ~57~28~14 ~57~29~18 minecraft:stained_hardened_clay 7
setblock ~57~31~14 minecraft:stained_hardened_clay 7
setblock ~57~38~14 minecraft:stained_hardened_clay 7
fill ~57~43~14 ~60~43~14 minecraft:stained_hardened_clay 7
fill ~57~50~14 ~62~50~14 minecraft:stained_hardened_clay 7
fill ~57~51~14 ~57~51~16 minecraft:stained_hardened_clay 7
fill ~57~53~14 ~57~53~15 minecraft:stained_hardened_clay 7
fill ~57~54~14 ~76~54~21 minecraft:stained_hardened_clay 12
fill ~57~56~14 ~59~56~14 minecraft:wool 8
setblock ~58~26~14 minecraft:stained_hardened_clay 12
fill ~58~27~14 ~58~27~15 minecraft:stained_hardened_clay 7
setblock ~58~32~14 minecraft:stained_hardened_clay 12
fill ~59~22~14 ~61~22~15 minecraft:stained_hardened_clay 7
fill ~59~23~14 ~60~23~19 minecraft:stained_hardened_clay 7
fill ~59~24~14 ~59~25~14 minecraft:stained_hardened_clay 7
setblock ~59~32~14 minecraft:stained_hardened_clay 7
setblock ~59~39~14 minecraft:stained_hardened_clay 12
fill ~59~40~14 ~60~40~14 minecraft:stained_hardened_clay 7
fill ~59~51~14 ~60~51~16 minecraft:stained_hardened_clay 7
fill ~60~20~14 ~62~20~17 minecraft:stained_hardened_clay 7
fill ~60~21~14 ~61~21~14 minecraft:stained_hardened_clay 7
fill ~60~27~14 ~60~27~15 minecraft:stained_hardened_clay 12
fill ~60~32~14 ~60~32~20 minecraft:stained_hardened_clay 12
fill ~60~33~14 ~60~34~14 minecraft:stained_hardened_clay 7
fill ~60~39~14 ~60~39~17 minecraft:stained_hardened_clay 7
setblock ~60~47~14 minecraft:stained_hardened_clay 7
fill ~60~49~14 ~60~49~17 minecraft:stained_hardened_clay 7
setblock ~60~56~14 minecraft:wool 7
fill ~61~19~14 ~62~19~15 minecraft:stained_hardened_clay 7
setblock ~61~23~14 minecraft:stained_hardened_clay 12
fill ~61~27~14 ~62~27~17 minecraft:stained_hardened_clay 7
fill ~61~29~14 ~62~29~14 minecraft:stained_hardened_clay 12
fill ~61~34~14 ~61~34~20 minecraft:stained_hardened_clay 12
fill ~61~47~14 ~61~47~15 minecraft:stained_hardened_clay 12
setblock ~61~48~14 minecraft:stained_hardened_clay 7
setblock ~61~49~14 minecraft:stained_hardened_clay 12
setblock ~61~51~14 minecraft:stained_hardened_clay 12
