fill ~1~92~1 ~1~94~1 minecraft:fence
fill ~2~71~1 ~24~71~1 minecraft:sandstone
fill ~2~72~1 ~2~91~1 minecraft:sandstone
fill ~2~92~1 ~5~92~1 minecraft:stone_block_slab4
fill ~3~74~1 ~4~74~1 minecraft:stone_block_slab4
fill ~3~75~1 ~6~75~1 minecraft:sandstone
fill ~3~78~1 ~4~78~1 minecraft:stone_block_slab4
fill ~3~81~1 ~4~81~1 minecraft:stone_block_slab4
fill ~3~84~1 ~4~84~1 minecraft:stone_block_slab4
fill ~3~87~1 ~4~87~1 minecraft:stone_block_slab4
fill ~3~89~1 ~5~89~1 minecraft:sandstone
fill ~3~90~1 ~4~90~1 minecraft:stone_block_slab4
fill ~4~72~1 ~4~73~1 minecraft:fence
fill ~4~76~1 ~4~77~1 minecraft:fence
fill ~4~79~1 ~4~80~1 minecraft:fence
fill ~4~82~1 ~4~83~1 minecraft:fence
fill ~4~85~1 ~4~86~1 minecraft:fence
setblock ~4~88~1 minecraft:fence
setblock ~4~91~1 minecraft:fence
setblock ~5~0~1 minecraft:quartz_block
fill ~5~72~1 ~5~74~1 minecraft:sandstone
fill ~5~76~1 ~5~88~1 minecraft:sandstone
fill ~5~90~1 ~5~91~1 minecraft:sandstone
fill ~6~76~1 ~20~76~1 minecraft:stone_block_slab2
fill ~6~77~1 ~20~77~1 minecraft:stone_block_slab2
fill ~6~89~1 ~20~89~1 minecraft:stone_block_slab4
fill ~6~90~1 ~6~91~1 minecraft:fence
setblock ~6~92~1 minecraft:sandstone
setblock ~7~72~1 minecraft:sandstone
setblock ~7~73~1 minecraft:sandstone
setblock ~7~74~1 minecraft:sandstone
setblock ~7~75~1 minecraft:stone_block_slab4
fill ~7~82~1 ~7~84~1 minecraft:trapdoor
fill ~7~90~1 ~7~91~1 minecraft:sandstone
setblock ~7~92~1 minecraft:stone_block_slab4
setblock ~8~75~1 minecraft:sandstone
fill ~8~80~1 ~8~81~1 minecraft:trapdoor
fill ~8~85~1 ~8~86~1 minecraft:trapdoor
fill ~8~90~1 ~8~91~1 minecraft:fence
setblock ~8~92~1 minecraft:sandstone
setblock ~9~72~1 minecraft:sandstone
setblock ~9~73~1 minecraft:sandstone
setblock ~9~74~1 minecraft:sandstone
setblock ~9~75~1 minecraft:stone_block_slab4
setblock ~9~79~1 minecraft:trapdoor
setblock ~9~87~1 minecraft:trapdoor
fill ~9~90~1 ~9~91~1 minecraft:sandstone
setblock ~9~92~1 minecraft:stone_block_slab4
setblock ~10~75~1 minecraft:sandstone
fill ~10~78~1 ~11~78~1 minecraft:trapdoor
fill ~10~88~1 ~11~88~1 minecraft:trapdoor
fill ~10~90~1 ~10~91~1 minecraft:fence
setblock ~10~92~1 minecraft:sandstone
setblock ~11~72~1 minecraft:sandstone
setblock ~11~73~1 minecraft:sandstone
setblock ~11~74~1 minecraft:sandstone
setblock ~11~75~1 minecraft:stone_block_slab4
fill ~11~90~1 ~11~91~1 minecraft:sandstone
setblock ~11~92~1 minecraft:stone_block_slab4
setblock ~12~75~1 minecraft:sandstone
fill ~12~90~1 ~12~91~1 minecraft:fence
setblock ~12~92~1 minecraft:sandstone
setblock ~13~72~1 minecraft:sandstone
setblock ~13~73~1 minecraft:sandstone
setblock ~13~74~1 minecraft:sandstone
setblock ~13~75~1 minecraft:stone_block_slab4
fill ~13~90~1 ~13~91~1 minecraft:sandstone
setblock ~13~92~1 minecraft:stone_block_slab4
setblock ~14~75~1 minecraft:sandstone
fill ~14~90~1 ~14~91~1 minecraft:fence
setblock ~14~92~1 minecraft:sandstone
setblock ~15~0~1 minecraft:quartz_block
setblock ~15~72~1 minecraft:sandstone
setblock ~15~73~1 minecraft:sandstone
setblock ~15~74~1 minecraft:sandstone
setblock ~15~75~1 minecraft:stone_block_slab4
fill ~15~78~1 ~16~78~1 minecraft:trapdoor
fill ~15~88~1 ~16~88~1 minecraft:trapdoor
fill ~15~90~1 ~15~91~1 minecraft:sandstone
setblock ~15~92~1 minecraft:stone_block_slab4
setblock ~16~75~1 minecraft:sandstone
fill ~16~90~1 ~16~91~1 minecraft:fence
setblock ~16~92~1 minecraft:sandstone
setblock ~17~72~1 minecraft:sandstone
setblock ~17~73~1 minecraft:sandstone
setblock ~17~74~1 minecraft:sandstone
setblock ~17~75~1 minecraft:stone_block_slab4
setblock ~17~79~1 minecraft:trapdoor
setblock ~17~87~1 minecraft:trapdoor
fill ~17~90~1 ~17~91~1 minecraft:sandstone
setblock ~17~92~1 minecraft:stone_block_slab4
setblock ~18~75~1 minecraft:sandstone
fill ~18~80~1 ~18~81~1 minecraft:trapdoor
fill ~18~85~1 ~18~86~1 minecraft:trapdoor
fill ~18~90~1 ~18~91~1 minecraft:fence
setblock ~18~92~1 minecraft:sandstone
setblock ~19~72~1 minecraft:sandstone
setblock ~19~73~1 minecraft:sandstone
setblock ~19~74~1 minecraft:sandstone
setblock ~19~75~1 minecraft:stone_block_slab4
fill ~19~82~1 ~19~84~1 minecraft:trapdoor
fill ~19~90~1 ~19~91~1 minecraft:sandstone
setblock ~19~92~1 minecraft:stone_block_slab4
fill ~20~75~1 ~24~75~1 minecraft:sandstone
fill ~20~90~1 ~20~91~1 minecraft:fence
setblock ~20~92~1 minecraft:sandstone
setblock ~21~72~1 minecraft:sandstone
setblock ~21~73~1 minecraft:sandstone
setblock ~21~74~1 minecraft:sandstone
setblock ~21~76~1 minecraft:sandstone
setblock ~21~77~1 minecraft:sandstone
fill ~21~78~1 ~21~79~1 minecraft:sandstone
setblock ~21~80~1 minecraft:sandstone
fill ~21~81~1 ~21~82~1 minecraft:sandstone
setblock ~21~83~1 minecraft:sandstone
fill ~21~84~1 ~21~85~1 minecraft:sandstone
setblock ~21~86~1 minecraft:sandstone
fill ~21~87~1 ~21~91~1 minecraft:sandstone
fill ~21~92~1 ~24~92~1 minecraft:stone_block_slab4
fill ~22~72~1 ~22~73~1 minecraft:fence
fill ~22~74~1 ~23~74~1 minecraft:stone_block_slab4
fill ~22~76~1 ~22~77~1 minecraft:fence
fill ~22~78~1 ~23~78~1 minecraft:stone_block_slab4
fill ~22~79~1 ~22~80~1 minecraft:fence
fill ~22~81~1 ~23~81~1 minecraft:stone_block_slab4
fill ~22~82~1 ~22~83~1 minecraft:fence
fill ~22~84~1 ~23~84~1 minecraft:stone_block_slab4
fill ~22~85~1 ~22~86~1 minecraft:fence
fill ~22~87~1 ~23~87~1 minecraft:stone_block_slab4
setblock ~22~88~1 minecraft:fence
fill ~22~89~1 ~24~89~1 minecraft:sandstone
fill ~22~90~1 ~23~90~1 minecraft:stone_block_slab4
setblock ~22~91~1 minecraft:fence
fill ~24~72~1 ~24~74~1 minecraft:sandstone
fill ~24~76~1 ~24~88~1 minecraft:sandstone
fill ~24~90~1 ~24~91~1 minecraft:sandstone
setblock ~25~91~1 minecraft:cobblestone_wall
fill ~25~92~1 ~25~94~1 minecraft:fence
fill ~1~71~2 ~2~71~2 minecraft:sandstone
fill ~1~72~2 ~1~91~2 minecraft:sandstone
fill ~1~92~2 ~1~92~5 minecraft:stone_block_slab4
fill ~2~0~2 ~24~0~3 minecraft:stonebrick
setblock ~2~91~2 minecraft:sandstone
fill ~3~71~2 ~4~71~2 minecraft:sandstone
fill ~3~72~2 ~4~91~2 minecraft:stripped_oak_log
fill ~3~96~2 ~23~96~2 minecraft:polished_basalt
fill ~5~71~2 ~6~71~2 minecraft:sandstone
fill ~5~91~2 ~5~91~3 minecraft:sandstone
fill ~6~72~2 ~6~76~2 minecraft:stripped_oak_log
fill ~6~77~2 ~11~77~2 minecraft:planks
fill ~6~78~2 ~9~78~2 minecraft:planks
fill ~6~79~2 ~8~79~2 minecraft:planks
fill ~6~80~2 ~7~81~2 minecraft:planks
fill ~6~82~2 ~6~89~2 minecraft:planks
fill ~6~90~2 ~6~91~2 minecraft:stripped_oak_log
setblock ~7~70~2 minecraft:trapdoor
setblock ~7~71~2 minecraft:glowstone
fill ~7~75~2 ~20~76~2 minecraft:stripped_oak_log
fill ~7~82~2 ~7~84~2 minecraft:glowstone
fill ~7~85~2 ~7~89~2 minecraft:planks
fill ~7~91~2 ~7~91~3 minecraft:sandstone
fill ~8~71~2 ~8~71~3 minecraft:sandstone
fill ~8~72~2 ~8~74~2 minecraft:stripped_oak_log
fill ~8~80~2 ~8~81~2 minecraft:glowstone
fill ~8~82~2 ~8~84~2 minecraft:stone
fill ~8~85~2 ~8~86~2 minecraft:glowstone
fill ~8~87~2 ~8~89~2 minecraft:planks
fill ~8~90~2 ~8~91~2 minecraft:stripped_oak_log
setblock ~9~70~2 minecraft:trapdoor
setblock ~9~71~2 minecraft:glowstone
setblock ~9~79~2 minecraft:glowstone
fill ~9~80~2 ~9~81~2 minecraft:stone
setblock ~9~82~2 minecraft:gravel
fill ~9~83~2 ~12~83~2 minecraft:quartz_block
setblock ~9~84~2 minecraft:gravel
fill ~9~85~2 ~9~86~2 minecraft:stone
setblock ~9~87~2 minecraft:glowstone
fill ~9~88~2 ~9~89~2 minecraft:planks
fill ~9~91~2 ~9~91~3 minecraft:sandstone
fill ~10~71~2 ~10~71~3 minecraft:sandstone
fill ~10~72~2 ~10~74~2 minecraft:stripped_oak_log
fill ~10~78~2 ~11~78~2 minecraft:glowstone
fill ~10~79~2 ~11~79~2 minecraft:stone
setblock ~10~80~2 minecraft:gravel
fill ~10~81~2 ~16~81~2 minecraft:quartz_block
fill ~10~82~2 ~11~82~2 minecraft:quartz_block
fill ~10~84~2 ~11~84~2 minecraft:quartz_block
setblock ~10~85~2 minecraft:quartz_block
setblock ~10~86~2 minecraft:gravel
fill ~10~87~2 ~11~87~2 minecraft:stone
fill ~10~88~2 ~11~88~2 minecraft:glowstone
fill ~10~89~2 ~11~89~2 minecraft:planks
fill ~10~90~2 ~10~91~2 minecraft:stripped_oak_log
setblock ~11~70~2 minecraft:trapdoor
setblock ~11~71~2 minecraft:glowstone
fill ~11~80~2 ~15~80~2 minecraft:quartz_block
setblock ~11~85~2 minecraft:coal_block
fill ~11~86~2 ~15~86~2 minecraft:quartz_block
fill ~11~91~2 ~11~91~3 minecraft:sandstone
fill ~12~71~2 ~12~71~3 minecraft:sandstone
fill ~12~72~2 ~12~74~2 minecraft:stripped_oak_log
fill ~12~77~2 ~14~77~2 minecraft:glowstone
fill ~12~78~2 ~14~78~2 minecraft:stone
setblock ~12~79~2 minecraft:gravel
setblock ~12~82~2 minecraft:coal_block
setblock ~12~84~2 minecraft:coal_block
fill ~12~85~2 ~14~85~2 minecraft:quartz_block
setblock ~12~87~2 minecraft:gravel
fill ~12~88~2 ~14~88~2 minecraft:stone
fill ~12~89~2 ~14~89~2 minecraft:glowstone
fill ~12~90~2 ~12~91~2 minecraft:stripped_oak_log
setblock ~13~70~2 minecraft:trapdoor
setblock ~13~71~2 minecraft:glowstone
setblock ~13~79~2 minecraft:quartz_block
fill ~13~82~2 ~16~82~2 minecraft:quartz_block
setblock ~13~83~2 minecraft:coal_block
setblock ~13~84~2 minecraft:quartz_block
setblock ~13~87~2 minecraft:quartz_block
fill ~13~91~2 ~13~91~3 minecraft:sandstone
fill ~14~71~2 ~14~71~3 minecraft:sandstone
fill ~14~72~2 ~14~74~2 minecraft:stripped_oak_log
setblock ~14~79~2 minecraft:gravel
fill ~14~83~2 ~17~83~2 minecraft:quartz_block
setblock ~14~84~2 minecraft:coal_block
setblock ~14~87~2 minecraft:gravel
fill ~14~90~2 ~14~91~2 minecraft:stripped_oak_log
setblock ~15~70~2 minecraft:trapdoor
setblock ~15~71~2 minecraft:glowstone
fill ~15~77~2 ~20~77~2 minecraft:planks
fill ~15~78~2 ~16~78~2 minecraft:glowstone
fill ~15~79~2 ~16~79~2 minecraft:stone
fill ~15~84~2 ~16~84~2 minecraft:quartz_block
setblock ~15~85~2 minecraft:coal_block
fill ~15~87~2 ~16~87~2 minecraft:stone
fill ~15~88~2 ~16~88~2 minecraft:glowstone
fill ~15~89~2 ~20~89~2 minecraft:planks
fill ~15~91~2 ~15~91~3 minecraft:sandstone
fill ~16~71~2 ~16~71~3 minecraft:sandstone
fill ~16~72~2 ~16~74~2 minecraft:stripped_oak_log
setblock ~16~80~2 minecraft:gravel
setblock ~16~85~2 minecraft:quartz_block
setblock ~16~86~2 minecraft:coal_block
fill ~16~90~2 ~16~91~2 minecraft:stripped_oak_log
setblock ~17~70~2 minecraft:trapdoor
setblock ~17~71~2 minecraft:glowstone
fill ~17~78~2 ~20~78~2 minecraft:planks
setblock ~17~79~2 minecraft:glowstone
fill ~17~80~2 ~17~81~2 minecraft:stone
setblock ~17~82~2 minecraft:gravel
setblock ~17~84~2 minecraft:gravel
fill ~17~85~2 ~17~86~2 minecraft:stone
setblock ~17~87~2 minecraft:glowstone
fill ~17~88~2 ~20~88~2 minecraft:planks
fill ~17~91~2 ~17~91~3 minecraft:sandstone
fill ~18~71~2 ~18~71~3 minecraft:sandstone
fill ~18~72~2 ~18~74~2 minecraft:stripped_oak_log
fill ~18~79~2 ~20~79~2 minecraft:planks
fill ~18~80~2 ~18~81~2 minecraft:glowstone
fill ~18~82~2 ~18~84~2 minecraft:stone
fill ~18~85~2 ~18~86~2 minecraft:glowstone
fill ~18~87~2 ~20~87~2 minecraft:planks
fill ~18~90~2 ~18~91~2 minecraft:stripped_oak_log
setblock ~19~70~2 minecraft:trapdoor
setblock ~19~71~2 minecraft:glowstone
fill ~19~80~2 ~20~81~2 minecraft:planks
fill ~19~82~2 ~19~84~2 minecraft:glowstone
fill ~19~85~2 ~20~86~2 minecraft:planks
fill ~19~91~2 ~19~91~3 minecraft:sandstone
fill ~20~71~2 ~21~71~2 minecraft:sandstone
fill ~20~72~2 ~20~74~2 minecraft:stripped_oak_log
fill ~20~82~2 ~20~84~2 minecraft:planks
fill ~20~90~2 ~20~91~2 minecraft:stripped_oak_log
fill ~21~91~2 ~21~91~3 minecraft:sandstone
fill ~22~71~2 ~23~71~2 minecraft:sandstone
fill ~22~72~2 ~23~91~2 minecraft:stripped_oak_log
fill ~24~71~2 ~25~71~2 minecraft:sandstone
fill ~24~91~2 ~25~91~2 minecraft:sandstone
fill ~25~72~2 ~25~90~2 minecraft:sandstone
fill ~25~92~2 ~25~92~5 minecraft:stone_block_slab4
fill ~1~71~3 ~1~71~24 minecraft:sandstone
fill ~1~74~3 ~1~74~4 minecraft:stone_block_slab4
fill ~1~75~3 ~1~75~6 minecraft:sandstone
fill ~1~78~3 ~1~78~4 minecraft:stone_block_slab4
fill ~1~81~3 ~1~81~4 minecraft:stone_block_slab4
fill ~1~84~3 ~1~84~4 minecraft:stone_block_slab4
fill ~1~87~3 ~1~87~4 minecraft:stone_block_slab4
fill ~1~89~3 ~1~89~5 minecraft:sandstone
fill ~1~90~3 ~1~90~4 minecraft:stone_block_slab4
fill ~2~71~3 ~2~71~4 minecraft:sandstone
fill ~2~72~3 ~2~91~4 minecraft:stripped_oak_log
fill ~2~96~3 ~2~96~23 minecraft:polished_basalt
fill ~3~71~3 ~4~71~3 minecraft:sandstone
fill ~3~91~3 ~4~91~3 minecraft:sandstone
fill ~3~92~3 ~3~95~3 minecraft:sandstone
fill ~3~96~3 ~23~98~3 minecraft:polished_basalt
fill ~3~99~3 ~6~99~3 minecraft:polished_basalt
setblock ~3~100~3 minecraft:torch
setblock ~4~1~3 minecraft:sandstone
fill ~4~92~3 ~4~95~3 minecraft:stone_block_slab4
fill ~5~1~3 ~6~2~3 minecraft:sandstone
fill ~5~3~3 ~6~13~3 minecraft:sandstone
fill ~5~14~3 ~6~14~3 minecraft:sandstone
setblock ~5~15~3 minecraft:cobblestone_wall
fill ~5~16~3 ~6~16~3 minecraft:sandstone
fill ~5~17~3 ~6~27~3 minecraft:sandstone
fill ~5~28~3 ~6~28~3 minecraft:sandstone
setblock ~5~29~3 minecraft:cobblestone_wall
fill ~5~30~3 ~6~30~3 minecraft:sandstone
fill ~5~31~3 ~6~41~3 minecraft:sandstone
fill ~5~42~3 ~6~42~3 minecraft:sandstone
setblock ~5~43~3 minecraft:cobblestone_wall
fill ~5~44~3 ~6~44~3 minecraft:sandstone
fill ~5~45~3 ~6~56~3 minecraft:sandstone
fill ~5~57~3 ~6~57~3 minecraft:sandstone
setblock ~5~58~3 minecraft:cobblestone_wall
fill ~5~59~3 ~6~59~3 minecraft:sandstone
fill ~5~60~3 ~6~70~3 minecraft:sandstone
fill ~5~92~3 ~5~95~3 minecraft:sandstone
setblock ~6~15~3 minecraft:cobblestone_wall
setblock ~6~29~3 minecraft:cobblestone_wall
setblock ~6~43~3 minecraft:cobblestone_wall
setblock ~6~58~3 minecraft:cobblestone_wall
setblock ~6~91~3 minecraft:sandstone
setblock ~6~95~3 minecraft:stone_block_slab4
setblock ~7~1~3 minecraft:sandstone
setblock ~7~70~3 minecraft:sandstone
setblock ~7~71~3 minecraft:sandstone
setblock ~7~72~3 minecraft:torch
fill ~7~92~3 ~7~94~3 minecraft:sandstone
setblock ~7~95~3 minecraft:sandstone
setblock ~7~99~3 minecraft:sandstone
setblock ~7~100~3 minecraft:sandstone
setblock ~7~101~3 minecraft:cobblestone_wall
setblock ~8~91~3 minecraft:sandstone
setblock ~8~95~3 minecraft:stone_block_slab4
fill ~8~99~3 ~10~99~3 minecraft:polished_basalt
setblock ~9~70~3 minecraft:sandstone
setblock ~9~71~3 minecraft:sandstone
fill ~9~92~3 ~9~94~3 minecraft:sandstone
setblock ~9~95~3 minecraft:sandstone
setblock ~10~91~3 minecraft:sandstone
setblock ~10~95~3 minecraft:stone_block_slab4
setblock ~11~70~3 minecraft:sandstone
setblock ~11~71~3 minecraft:sandstone
setblock ~11~72~3 minecraft:torch
fill ~11~92~3 ~11~94~3 minecraft:sandstone
setblock ~11~95~3 minecraft:sandstone
setblock ~11~99~3 minecraft:sandstone
setblock ~11~100~3 minecraft:sandstone
setblock ~11~101~3 minecraft:cobblestone_wall
setblock ~12~91~3 minecraft:sandstone
setblock ~12~95~3 minecraft:stone_block_slab4
fill ~12~99~3 ~14~99~3 minecraft:polished_basalt
setblock ~13~70~3 minecraft:sandstone
setblock ~13~71~3 minecraft:sandstone
fill ~13~92~3 ~13~94~3 minecraft:sandstone
setblock ~13~95~3 minecraft:sandstone
setblock ~14~91~3 minecraft:sandstone
setblock ~14~95~3 minecraft:stone_block_slab4
setblock ~15~70~3 minecraft:sandstone
setblock ~15~71~3 minecraft:sandstone
setblock ~15~72~3 minecraft:torch
fill ~15~92~3 ~15~94~3 minecraft:sandstone
setblock ~15~95~3 minecraft:sandstone
setblock ~15~99~3 minecraft:sandstone
setblock ~15~100~3 minecraft:sandstone
setblock ~15~101~3 minecraft:cobblestone_wall
setblock ~16~91~3 minecraft:sandstone
setblock ~16~95~3 minecraft:stone_block_slab4
fill ~16~99~3 ~18~99~3 minecraft:polished_basalt
setblock ~17~70~3 minecraft:sandstone
setblock ~17~71~3 minecraft:sandstone
fill ~17~92~3 ~17~94~3 minecraft:sandstone
setblock ~17~95~3 minecraft:sandstone
setblock ~18~91~3 minecraft:sandstone
setblock ~18~95~3 minecraft:stone_block_slab4
setblock ~19~1~3 minecraft:sandstone
setblock ~19~70~3 minecraft:sandstone
setblock ~19~71~3 minecraft:sandstone
setblock ~19~72~3 minecraft:torch
fill ~19~92~3 ~19~94~3 minecraft:sandstone
setblock ~19~95~3 minecraft:sandstone
setblock ~19~99~3 minecraft:sandstone
setblock ~19~100~3 minecraft:sandstone
setblock ~19~101~3 minecraft:cobblestone_wall
fill ~20~1~3 ~21~2~3 minecraft:sandstone
fill ~20~3~3 ~21~13~3 minecraft:sandstone
fill ~20~14~3 ~21~14~3 minecraft:sandstone
setblock ~20~15~3 minecraft:cobblestone_wall
fill ~20~16~3 ~21~16~3 minecraft:sandstone
fill ~20~17~3 ~21~27~3 minecraft:sandstone
fill ~20~28~3 ~21~28~3 minecraft:sandstone
setblock ~20~29~3 minecraft:cobblestone_wall
fill ~20~30~3 ~21~30~3 minecraft:sandstone
fill ~20~31~3 ~21~41~3 minecraft:sandstone
fill ~20~42~3 ~21~42~3 minecraft:sandstone
setblock ~20~43~3 minecraft:cobblestone_wall
fill ~20~44~3 ~21~44~3 minecraft:sandstone
fill ~20~45~3 ~21~56~3 minecraft:sandstone
fill ~20~57~3 ~21~57~3 minecraft:sandstone
setblock ~20~58~3 minecraft:cobblestone_wall
fill ~20~59~3 ~21~59~3 minecraft:sandstone
fill ~20~60~3 ~21~70~3 minecraft:sandstone
setblock ~20~91~3 minecraft:sandstone
setblock ~20~95~3 minecraft:stone_block_slab4
fill ~20~99~3 ~23~99~3 minecraft:polished_basalt
setblock ~21~15~3 minecraft:cobblestone_wall
setblock ~21~29~3 minecraft:cobblestone_wall
setblock ~21~43~3 minecraft:cobblestone_wall
setblock ~21~58~3 minecraft:cobblestone_wall
fill ~21~92~3 ~21~95~3 minecraft:sandstone
setblock ~22~1~3 minecraft:sandstone
fill ~22~71~3 ~23~71~3 minecraft:sandstone
fill ~22~91~3 ~23~91~3 minecraft:sandstone
fill ~22~92~3 ~22~95~3 minecraft:stone_block_slab4
fill ~23~92~3 ~23~95~3 minecraft:sandstone
setblock ~23~100~3 minecraft:torch
fill ~24~71~3 ~24~71~4 minecraft:sandstone
fill ~24~72~3 ~24~91~4 minecraft:stripped_oak_log
fill ~24~96~3 ~24~96~23 minecraft:polished_basalt
fill ~25~71~3 ~25~71~24 minecraft:sandstone
fill ~25~74~3 ~25~74~4 minecraft:stone_block_slab4
fill ~25~75~3 ~25~75~6 minecraft:sandstone
fill ~25~78~3 ~25~78~4 minecraft:stone_block_slab4
fill ~25~81~3 ~25~81~4 minecraft:stone_block_slab4
fill ~25~84~3 ~25~84~4 minecraft:stone_block_slab4
fill ~25~87~3 ~25~87~4 minecraft:stone_block_slab4
fill ~25~89~3 ~25~89~5 minecraft:sandstone
fill ~25~90~3 ~25~90~4 minecraft:stone_block_slab4
fill ~1~72~4 ~1~73~4 minecraft:fence
fill ~1~76~4 ~1~77~4 minecraft:fence
fill ~1~79~4 ~1~80~4 minecraft:fence
fill ~1~82~4 ~1~83~4 minecraft:fence
fill ~1~85~4 ~1~86~4 minecraft:fence
setblock ~1~88~4 minecraft:fence
setblock ~1~91~4 minecraft:fence
fill ~2~0~4 ~4~0~4 minecraft:stonebrick
setblock ~3~1~4 minecraft:sandstone
setblock ~3~71~4 minecraft:sandstone
fill ~3~91~4 ~3~91~23 minecraft:sandstone
fill ~3~92~4 ~3~95~4 minecraft:stone_block_slab4
fill ~3~96~4 ~3~98~23 minecraft:polished_basalt
fill ~3~99~4 ~3~99~6 minecraft:polished_basalt
fill ~4~1~4 ~4~2~4 minecraft:sandstone
fill ~4~3~4 ~4~13~4 minecraft:sandstone
setblock ~4~14~4 minecraft:sandstone
setblock ~4~15~4 minecraft:cobblestone_wall
fill ~4~16~4 ~5~16~4 minecraft:sandstone
fill ~4~17~4 ~4~27~4 minecraft:sandstone
setblock ~4~28~4 minecraft:sandstone
setblock ~4~29~4 minecraft:cobblestone_wall
setblock ~4~30~4 minecraft:sandstone
fill ~4~31~4 ~4~41~4 minecraft:sandstone
setblock ~4~42~4 minecraft:sandstone
setblock ~4~43~4 minecraft:cobblestone_wall
setblock ~4~44~4 minecraft:sandstone
fill ~4~45~4 ~4~56~4 minecraft:sandstone
setblock ~4~57~4 minecraft:sandstone
setblock ~4~58~4 minecraft:cobblestone_wall
setblock ~4~59~4 minecraft:sandstone
fill ~4~60~4 ~4~70~4 minecraft:sandstone
fill ~4~92~4 ~4~95~4 minecraft:stripped_oak_log
fill ~4~99~4 ~22~99~4 minecraft:dirt
fill ~4~100~4 ~22~101~4 minecraft:polished_basalt
fill ~4~102~4 ~8~102~4 minecraft:polished_basalt
setblock ~4~103~4 minecraft:torch
setblock ~4~106~4 minecraft:cobblestone_wall
fill ~4~107~4 ~4~109~4 minecraft:fence
setblock ~5~14~4 minecraft:sandstone
fill ~5~15~4 ~6~15~4 minecraft:sandstone
fill ~5~29~4 ~6~29~4 minecraft:sandstone
fill ~5~43~4 ~6~43~4 minecraft:sandstone
fill ~5~58~4 ~6~58~4 minecraft:sandstone
fill ~5~106~4 ~21~106~4 minecraft:polished_basalt
fill ~6~91~4 ~20~91~7 minecraft:planks
fill ~6~94~4 ~6~95~4 minecraft:stripped_oak_log
fill ~7~1~4 ~19~1~4 minecraft:sandstone
setblock ~7~2~4 minecraft:sandstone
fill ~7~3~4 ~7~13~4 minecraft:sandstone
setblock ~7~14~4 minecraft:sandstone
setblock ~7~15~4 minecraft:cobblestone_wall
setblock ~7~16~4 minecraft:sandstone
fill ~7~17~4 ~7~27~4 minecraft:sandstone
setblock ~7~28~4 minecraft:sandstone
setblock ~7~29~4 minecraft:cobblestone_wall
setblock ~7~30~4 minecraft:sandstone
fill ~7~31~4 ~7~41~4 minecraft:sandstone
setblock ~7~42~4 minecraft:sandstone
setblock ~7~43~4 minecraft:cobblestone_wall
setblock ~7~44~4 minecraft:sandstone
fill ~7~45~4 ~7~56~4 minecraft:sandstone
setblock ~7~57~4 minecraft:sandstone
setblock ~7~58~4 minecraft:cobblestone_wall
setblock ~7~59~4 minecraft:sandstone
fill ~7~60~4 ~7~70~4 minecraft:sandstone
setblock ~7~95~4 minecraft:torch
setblock ~8~2~4 minecraft:sandstone
setblock ~8~14~4 minecraft:stone_block_slab4
setblock ~8~15~4 minecraft:sandstone
setblock ~8~28~4 minecraft:stone_block_slab4
setblock ~8~29~4 minecraft:sandstone
setblock ~8~42~4 minecraft:stone_block_slab4
setblock ~8~43~4 minecraft:sandstone
setblock ~8~57~4 minecraft:stone_block_slab4
setblock ~8~58~4 minecraft:sandstone
setblock ~8~70~4 minecraft:sandstone
fill ~8~94~4 ~8~95~4 minecraft:stripped_oak_log
setblock ~9~2~4 minecraft:sandstone
fill ~9~3~4 ~9~13~4 minecraft:sandstone
setblock ~9~14~4 minecraft:sandstone
setblock ~9~15~4 minecraft:cobblestone_wall
setblock ~9~16~4 minecraft:sandstone
fill ~9~17~4 ~9~27~4 minecraft:sandstone
setblock ~9~28~4 minecraft:sandstone
setblock ~9~29~4 minecraft:cobblestone_wall
setblock ~9~30~4 minecraft:sandstone
fill ~9~31~4 ~9~41~4 minecraft:sandstone
setblock ~9~42~4 minecraft:sandstone
setblock ~9~43~4 minecraft:cobblestone_wall
setblock ~9~44~4 minecraft:sandstone
fill ~9~45~4 ~9~56~4 minecraft:sandstone
setblock ~9~57~4 minecraft:sandstone
setblock ~9~58~4 minecraft:cobblestone_wall
setblock ~9~59~4 minecraft:sandstone
fill ~9~60~4 ~9~70~4 minecraft:sandstone
setblock ~9~95~4 minecraft:torch
setblock ~9~102~4 minecraft:sandstone
setblock ~9~103~4 minecraft:sandstone
setblock ~9~104~4 minecraft:cobblestone_wall
setblock ~10~2~4 minecraft:sandstone
setblock ~10~14~4 minecraft:stone_block_slab4
setblock ~10~15~4 minecraft:sandstone
setblock ~10~28~4 minecraft:stone_block_slab4
setblock ~10~29~4 minecraft:sandstone
setblock ~10~42~4 minecraft:stone_block_slab4
setblock ~10~43~4 minecraft:sandstone
setblock ~10~57~4 minecraft:stone_block_slab4
setblock ~10~58~4 minecraft:sandstone
setblock ~10~70~4 minecraft:sandstone
fill ~10~94~4 ~10~95~4 minecraft:stripped_oak_log
fill ~10~102~4 ~12~102~4 minecraft:polished_basalt
setblock ~11~2~4 minecraft:sandstone
fill ~11~3~4 ~11~13~4 minecraft:sandstone
setblock ~11~14~4 minecraft:sandstone
setblock ~11~15~4 minecraft:cobblestone_wall
setblock ~11~16~4 minecraft:sandstone
fill ~11~17~4 ~11~27~4 minecraft:sandstone
setblock ~11~28~4 minecraft:sandstone
setblock ~11~29~4 minecraft:cobblestone_wall
setblock ~11~30~4 minecraft:sandstone
fill ~11~31~4 ~11~41~4 minecraft:sandstone
setblock ~11~42~4 minecraft:sandstone
setblock ~11~43~4 minecraft:cobblestone_wall
setblock ~11~44~4 minecraft:sandstone
fill ~11~45~4 ~11~56~4 minecraft:sandstone
setblock ~11~57~4 minecraft:sandstone
setblock ~11~58~4 minecraft:cobblestone_wall
setblock ~11~59~4 minecraft:sandstone
fill ~11~60~4 ~11~70~4 minecraft:sandstone
setblock ~11~95~4 minecraft:torch
setblock ~12~2~4 minecraft:sandstone
setblock ~12~14~4 minecraft:stone_block_slab4
setblock ~12~15~4 minecraft:sandstone
setblock ~12~28~4 minecraft:stone_block_slab4
setblock ~12~29~4 minecraft:sandstone
setblock ~12~42~4 minecraft:stone_block_slab4
setblock ~12~43~4 minecraft:sandstone
setblock ~12~57~4 minecraft:stone_block_slab4
setblock ~12~58~4 minecraft:sandstone
setblock ~12~70~4 minecraft:sandstone
fill ~12~94~4 ~12~95~4 minecraft:stripped_oak_log
setblock ~13~2~4 minecraft:sandstone
fill ~13~3~4 ~13~13~4 minecraft:sandstone
setblock ~13~14~4 minecraft:sandstone
setblock ~13~15~4 minecraft:cobblestone_wall
setblock ~13~16~4 minecraft:sandstone
fill ~13~17~4 ~13~27~4 minecraft:sandstone
setblock ~13~28~4 minecraft:sandstone
setblock ~13~29~4 minecraft:cobblestone_wall
setblock ~13~30~4 minecraft:sandstone
fill ~13~31~4 ~13~41~4 minecraft:sandstone
setblock ~13~42~4 minecraft:sandstone
setblock ~13~43~4 minecraft:cobblestone_wall
setblock ~13~44~4 minecraft:sandstone
fill ~13~45~4 ~13~56~4 minecraft:sandstone
setblock ~13~57~4 minecraft:sandstone
setblock ~13~58~4 minecraft:cobblestone_wall
setblock ~13~59~4 minecraft:sandstone
fill ~13~60~4 ~13~70~4 minecraft:sandstone
setblock ~13~95~4 minecraft:torch
setblock ~13~102~4 minecraft:sandstone
setblock ~13~103~4 minecraft:sandstone
setblock ~13~104~4 minecraft:cobblestone_wall
setblock ~14~2~4 minecraft:sandstone
setblock ~14~14~4 minecraft:stone_block_slab4
setblock ~14~15~4 minecraft:sandstone
setblock ~14~28~4 minecraft:stone_block_slab4
setblock ~14~29~4 minecraft:sandstone
setblock ~14~42~4 minecraft:stone_block_slab4
setblock ~14~43~4 minecraft:sandstone
setblock ~14~57~4 minecraft:stone_block_slab4
setblock ~14~58~4 minecraft:sandstone
setblock ~14~70~4 minecraft:sandstone
fill ~14~94~4 ~14~95~4 minecraft:stripped_oak_log
fill ~14~102~4 ~16~102~4 minecraft:polished_basalt
setblock ~15~2~4 minecraft:sandstone
fill ~15~3~4 ~15~13~4 minecraft:sandstone
setblock ~15~14~4 minecraft:sandstone
setblock ~15~15~4 minecraft:cobblestone_wall
setblock ~15~16~4 minecraft:sandstone
fill ~15~17~4 ~15~27~4 minecraft:sandstone
setblock ~15~28~4 minecraft:sandstone
setblock ~15~29~4 minecraft:cobblestone_wall
setblock ~15~30~4 minecraft:sandstone
fill ~15~31~4 ~15~41~4 minecraft:sandstone
setblock ~15~42~4 minecraft:sandstone
setblock ~15~43~4 minecraft:cobblestone_wall
setblock ~15~44~4 minecraft:sandstone
fill ~15~45~4 ~15~56~4 minecraft:sandstone
setblock ~15~57~4 minecraft:sandstone
setblock ~15~58~4 minecraft:cobblestone_wall
setblock ~15~59~4 minecraft:sandstone
fill ~15~60~4 ~15~70~4 minecraft:sandstone
setblock ~15~95~4 minecraft:torch
setblock ~16~2~4 minecraft:sandstone
setblock ~16~14~4 minecraft:stone_block_slab4
setblock ~16~15~4 minecraft:sandstone
setblock ~16~28~4 minecraft:stone_block_slab4
setblock ~16~29~4 minecraft:sandstone
setblock ~16~42~4 minecraft:stone_block_slab4
setblock ~16~43~4 minecraft:sandstone
setblock ~16~57~4 minecraft:stone_block_slab4
setblock ~16~58~4 minecraft:sandstone
setblock ~16~70~4 minecraft:sandstone
fill ~16~94~4 ~16~95~4 minecraft:stripped_oak_log
setblock ~17~2~4 minecraft:sandstone
fill ~17~3~4 ~17~13~4 minecraft:sandstone
setblock ~17~14~4 minecraft:sandstone
setblock ~17~15~4 minecraft:cobblestone_wall
setblock ~17~16~4 minecraft:sandstone
fill ~17~17~4 ~17~27~4 minecraft:sandstone
setblock ~17~28~4 minecraft:sandstone
setblock ~17~29~4 minecraft:cobblestone_wall
setblock ~17~30~4 minecraft:sandstone
fill ~17~31~4 ~17~41~4 minecraft:sandstone
setblock ~17~42~4 minecraft:sandstone
setblock ~17~43~4 minecraft:cobblestone_wall
setblock ~17~44~4 minecraft:sandstone
fill ~17~45~4 ~17~56~4 minecraft:sandstone
setblock ~17~57~4 minecraft:sandstone
setblock ~17~58~4 minecraft:cobblestone_wall
setblock ~17~59~4 minecraft:sandstone
fill ~17~60~4 ~17~70~4 minecraft:sandstone
setblock ~17~95~4 minecraft:torch
setblock ~17~102~4 minecraft:sandstone
setblock ~17~103~4 minecraft:sandstone
setblock ~17~104~4 minecraft:cobblestone_wall
setblock ~18~2~4 minecraft:sandstone
setblock ~18~14~4 minecraft:stone_block_slab4
setblock ~18~15~4 minecraft:sandstone
setblock ~18~28~4 minecraft:stone_block_slab4
setblock ~18~29~4 minecraft:sandstone
setblock ~18~42~4 minecraft:stone_block_slab4
setblock ~18~43~4 minecraft:sandstone
setblock ~18~57~4 minecraft:stone_block_slab4
setblock ~18~58~4 minecraft:sandstone
setblock ~18~70~4 minecraft:sandstone
fill ~18~94~4 ~18~95~4 minecraft:stripped_oak_log
fill ~18~102~4 ~22~102~4 minecraft:polished_basalt
setblock ~19~2~4 minecraft:sandstone
fill ~19~3~4 ~19~13~4 minecraft:sandstone
setblock ~19~14~4 minecraft:sandstone
setblock ~19~15~4 minecraft:cobblestone_wall
fill ~19~16~4 ~20~16~4 minecraft:sandstone
fill ~19~17~4 ~19~27~4 minecraft:sandstone
setblock ~19~28~4 minecraft:sandstone
setblock ~19~29~4 minecraft:cobblestone_wall
setblock ~19~30~4 minecraft:sandstone
fill ~19~31~4 ~19~41~4 minecraft:sandstone
setblock ~19~42~4 minecraft:sandstone
setblock ~19~43~4 minecraft:cobblestone_wall
setblock ~19~44~4 minecraft:sandstone
fill ~19~45~4 ~19~56~4 minecraft:sandstone
setblock ~19~57~4 minecraft:sandstone
setblock ~19~58~4 minecraft:cobblestone_wall
setblock ~19~59~4 minecraft:sandstone
fill ~19~60~4 ~19~70~4 minecraft:sandstone
setblock ~19~95~4 minecraft:torch
setblock ~20~14~4 minecraft:sandstone
fill ~20~15~4 ~21~15~4 minecraft:sandstone
fill ~20~29~4 ~21~29~4 minecraft:sandstone
fill ~20~43~4 ~21~43~4 minecraft:sandstone
fill ~20~58~4 ~21~58~4 minecraft:sandstone
fill ~20~94~4 ~20~95~4 minecraft:stripped_oak_log
fill ~22~0~4 ~24~0~4 minecraft:stonebrick
fill ~22~1~4 ~22~2~4 minecraft:sandstone
fill ~22~3~4 ~22~13~4 minecraft:sandstone
setblock ~22~14~4 minecraft:sandstone
setblock ~22~15~4 minecraft:cobblestone_wall
setblock ~22~16~4 minecraft:sandstone
fill ~22~17~4 ~22~27~4 minecraft:sandstone
setblock ~22~28~4 minecraft:sandstone
setblock ~22~29~4 minecraft:cobblestone_wall
setblock ~22~30~4 minecraft:sandstone
fill ~22~31~4 ~22~41~4 minecraft:sandstone
setblock ~22~42~4 minecraft:sandstone
setblock ~22~43~4 minecraft:cobblestone_wall
setblock ~22~44~4 minecraft:sandstone
fill ~22~45~4 ~22~56~4 minecraft:sandstone
setblock ~22~57~4 minecraft:sandstone
setblock ~22~58~4 minecraft:cobblestone_wall
setblock ~22~59~4 minecraft:sandstone
fill ~22~60~4 ~22~70~4 minecraft:sandstone
fill ~22~92~4 ~22~95~4 minecraft:stripped_oak_log
setblock ~22~103~4 minecraft:torch
setblock ~22~106~4 minecraft:cobblestone_wall
fill ~22~107~4 ~22~109~4 minecraft:fence
setblock ~23~1~4 minecraft:sandstone
setblock ~23~71~4 minecraft:sandstone
fill ~23~91~4 ~23~91~23 minecraft:sandstone
fill ~23~92~4 ~23~95~4 minecraft:stone_block_slab4
fill ~23~96~4 ~23~98~23 minecraft:polished_basalt
fill ~23~99~4 ~23~99~6 minecraft:polished_basalt
fill ~25~72~4 ~25~73~4 minecraft:fence
fill ~25~76~4 ~25~77~4 minecraft:fence
fill ~25~79~4 ~25~80~4 minecraft:fence
fill ~25~82~4 ~25~83~4 minecraft:fence
fill ~25~85~4 ~25~86~4 minecraft:fence
setblock ~25~88~4 minecraft:fence
setblock ~25~91~4 minecraft:fence
setblock ~1~72~5 minecraft:sandstone
setblock ~1~73~5 minecraft:sandstone
setblock ~1~74~5 minecraft:sandstone
setblock ~1~76~5 minecraft:sandstone
setblock ~1~77~5 minecraft:sandstone
fill ~1~78~5 ~1~79~5 minecraft:sandstone
setblock ~1~80~5 minecraft:sandstone
fill ~1~81~5 ~1~82~5 minecraft:sandstone
setblock ~1~83~5 minecraft:sandstone
fill ~1~84~5 ~1~85~5 minecraft:sandstone
setblock ~1~86~5 minecraft:sandstone
fill ~1~87~5 ~1~88~5 minecraft:sandstone
fill ~1~90~5 ~1~91~5 minecraft:sandstone
fill ~2~0~5 ~3~0~24 minecraft:stonebrick
fill ~2~71~5 ~2~71~6 minecraft:sandstone
setblock ~2~91~5 minecraft:sandstone
fill ~3~1~5 ~3~2~6 minecraft:sandstone
fill ~3~3~5 ~3~13~6 minecraft:sandstone
fill ~3~14~5 ~3~14~6 minecraft:sandstone
setblock ~3~15~5 minecraft:cobblestone_wall
fill ~3~16~5 ~4~16~6 minecraft:sandstone
fill ~3~17~5 ~3~27~6 minecraft:sandstone
fill ~3~28~5 ~3~28~6 minecraft:sandstone
setblock ~3~29~5 minecraft:cobblestone_wall
fill ~3~30~5 ~3~30~6 minecraft:sandstone
fill ~3~31~5 ~3~41~6 minecraft:sandstone
fill ~3~42~5 ~3~42~6 minecraft:sandstone
setblock ~3~43~5 minecraft:cobblestone_wall
fill ~3~44~5 ~3~44~6 minecraft:sandstone
fill ~3~45~5 ~3~56~6 minecraft:sandstone
fill ~3~57~5 ~3~57~6 minecraft:sandstone
setblock ~3~58~5 minecraft:cobblestone_wall
fill ~3~59~5 ~3~59~6 minecraft:sandstone
fill ~3~60~5 ~3~70~6 minecraft:sandstone
fill ~3~92~5 ~3~95~5 minecraft:sandstone
fill ~4~14~5 ~4~14~6 minecraft:sandstone
fill ~4~15~5 ~4~15~6 minecraft:sandstone
fill ~4~29~5 ~4~29~6 minecraft:sandstone
fill ~4~43~5 ~4~43~6 minecraft:sandstone
fill ~4~58~5 ~4~58~6 minecraft:sandstone
fill ~4~99~5 ~4~99~22 minecraft:dirt
fill ~4~100~5 ~4~101~22 minecraft:polished_basalt
fill ~4~102~5 ~4~102~8 minecraft:polished_basalt
fill ~4~106~5 ~4~106~21 minecraft:polished_basalt
fill ~5~102~5 ~21~102~5 minecraft:dirt
fill ~5~103~5 ~21~105~5 minecraft:polished_basalt
fill ~5~106~5 ~21~106~7 minecraft:sandstone
fill ~8~2~5 ~8~14~5 minecraft:stripped_oak_log
setblock ~8~15~5 minecraft:glowstone
fill ~8~16~5 ~8~28~5 minecraft:stripped_oak_log
setblock ~8~29~5 minecraft:glowstone
fill ~8~30~5 ~8~42~5 minecraft:stripped_oak_log
setblock ~8~43~5 minecraft:glowstone
fill ~8~44~5 ~8~57~5 minecraft:stripped_oak_log
setblock ~8~58~5 minecraft:glowstone
fill ~8~59~5 ~8~69~5 minecraft:stripped_oak_log
fill ~10~2~5 ~10~14~5 minecraft:stripped_oak_log
setblock ~10~15~5 minecraft:glowstone
fill ~10~16~5 ~10~28~5 minecraft:stripped_oak_log
setblock ~10~29~5 minecraft:glowstone
fill ~10~30~5 ~10~42~5 minecraft:stripped_oak_log
setblock ~10~43~5 minecraft:glowstone
fill ~10~44~5 ~10~57~5 minecraft:stripped_oak_log
setblock ~10~58~5 minecraft:glowstone
fill ~10~59~5 ~10~69~5 minecraft:stripped_oak_log
fill ~12~2~5 ~12~14~5 minecraft:stripped_oak_log
setblock ~12~15~5 minecraft:glowstone
fill ~12~16~5 ~12~28~5 minecraft:stripped_oak_log
setblock ~12~29~5 minecraft:glowstone
fill ~12~30~5 ~12~42~5 minecraft:stripped_oak_log
setblock ~12~43~5 minecraft:glowstone
fill ~12~44~5 ~12~57~5 minecraft:stripped_oak_log
setblock ~12~58~5 minecraft:glowstone
fill ~12~59~5 ~12~69~5 minecraft:stripped_oak_log
fill ~14~2~5 ~14~14~5 minecraft:stripped_oak_log
setblock ~14~15~5 minecraft:glowstone
fill ~14~16~5 ~14~28~5 minecraft:stripped_oak_log
setblock ~14~29~5 minecraft:glowstone
fill ~14~30~5 ~14~42~5 minecraft:stripped_oak_log
setblock ~14~43~5 minecraft:glowstone
fill ~14~44~5 ~14~57~5 minecraft:stripped_oak_log
setblock ~14~58~5 minecraft:glowstone
fill ~14~59~5 ~14~69~5 minecraft:stripped_oak_log
fill ~16~2~5 ~16~14~5 minecraft:stripped_oak_log
setblock ~16~15~5 minecraft:glowstone
fill ~16~16~5 ~16~28~5 minecraft:stripped_oak_log
setblock ~16~29~5 minecraft:glowstone
fill ~16~30~5 ~16~42~5 minecraft:stripped_oak_log
setblock ~16~43~5 minecraft:glowstone
fill ~16~44~5 ~16~57~5 minecraft:stripped_oak_log
setblock ~16~58~5 minecraft:glowstone
fill ~16~59~5 ~16~69~5 minecraft:stripped_oak_log
fill ~18~2~5 ~18~14~5 minecraft:stripped_oak_log
setblock ~18~15~5 minecraft:glowstone
fill ~18~16~5 ~18~28~5 minecraft:stripped_oak_log
setblock ~18~29~5 minecraft:glowstone
fill ~18~30~5 ~18~42~5 minecraft:stripped_oak_log
setblock ~18~43~5 minecraft:glowstone
fill ~18~44~5 ~18~57~5 minecraft:stripped_oak_log
setblock ~18~58~5 minecraft:glowstone
fill ~18~59~5 ~18~69~5 minecraft:stripped_oak_log
fill ~22~15~5 ~22~15~6 minecraft:sandstone
fill ~22~29~5 ~22~29~6 minecraft:sandstone
fill ~22~43~5 ~22~43~6 minecraft:sandstone
fill ~22~58~5 ~22~58~6 minecraft:sandstone
fill ~22~99~5 ~22~99~22 minecraft:dirt
fill ~22~100~5 ~22~101~22 minecraft:polished_basalt
fill ~22~102~5 ~22~102~8 minecraft:polished_basalt
fill ~22~106~5 ~22~106~21 minecraft:polished_basalt
fill ~23~0~5 ~24~0~5 minecraft:stonebrick
fill ~23~1~5 ~23~2~6 minecraft:sandstone
fill ~23~3~5 ~23~13~6 minecraft:sandstone
fill ~23~14~5 ~23~14~6 minecraft:sandstone
setblock ~23~15~5 minecraft:cobblestone_wall
fill ~23~16~5 ~23~16~6 minecraft:sandstone
fill ~23~17~5 ~23~27~6 minecraft:sandstone
fill ~23~28~5 ~23~28~6 minecraft:sandstone
setblock ~23~29~5 minecraft:cobblestone_wall
fill ~23~30~5 ~23~30~6 minecraft:sandstone
fill ~23~31~5 ~23~41~6 minecraft:sandstone
fill ~23~42~5 ~23~42~6 minecraft:sandstone
setblock ~23~43~5 minecraft:cobblestone_wall
fill ~23~44~5 ~23~44~6 minecraft:sandstone
fill ~23~45~5 ~23~56~6 minecraft:sandstone
fill ~23~57~5 ~23~57~6 minecraft:sandstone
setblock ~23~58~5 minecraft:cobblestone_wall
fill ~23~59~5 ~23~59~6 minecraft:sandstone
fill ~23~60~5 ~23~70~6 minecraft:sandstone
fill ~23~92~5 ~23~95~5 minecraft:sandstone
fill ~24~71~5 ~24~71~6 minecraft:sandstone
fill ~24~91~5 ~25~91~5 minecraft:sandstone
setblock ~25~72~5 minecraft:sandstone
setblock ~25~73~5 minecraft:sandstone
setblock ~25~74~5 minecraft:sandstone
setblock ~25~76~5 minecraft:sandstone
setblock ~25~77~5 minecraft:sandstone
fill ~25~78~5 ~25~79~5 minecraft:sandstone
setblock ~25~80~5 minecraft:sandstone
fill ~25~81~5 ~25~82~5 minecraft:sandstone
setblock ~25~83~5 minecraft:sandstone
fill ~25~84~5 ~25~85~5 minecraft:sandstone
setblock ~25~86~5 minecraft:sandstone
fill ~25~87~5 ~25~88~5 minecraft:sandstone
setblock ~25~90~5 minecraft:sandstone
fill ~1~76~6 ~1~76~20 minecraft:stone_block_slab2
fill ~1~77~6 ~1~77~20 minecraft:stone_block_slab2
fill ~1~89~6 ~1~89~20 minecraft:stone_block_slab4
fill ~1~90~6 ~1~91~6 minecraft:fence
setblock ~1~92~6 minecraft:sandstone
fill ~2~72~6 ~2~76~6 minecraft:stripped_oak_log
fill ~2~77~6 ~2~77~11 minecraft:planks
fill ~2~78~6 ~2~78~9 minecraft:planks
fill ~2~79~6 ~2~79~8 minecraft:planks
fill ~2~80~6 ~2~81~7 minecraft:planks
fill ~2~82~6 ~2~89~6 minecraft:planks
fill ~2~90~6 ~2~91~6 minecraft:stripped_oak_log
setblock ~3~15~6 minecraft:cobblestone_wall
setblock ~3~29~6 minecraft:cobblestone_wall
setblock ~3~43~6 minecraft:cobblestone_wall
setblock ~3~58~6 minecraft:cobblestone_wall
setblock ~3~95~6 minecraft:stone_block_slab4
fill ~4~91~6 ~5~91~20 minecraft:planks
fill ~4~94~6 ~4~95~6 minecraft:stripped_oak_log
fill ~5~102~6 ~5~102~21 minecraft:dirt
fill ~5~103~6 ~5~105~21 minecraft:polished_basalt
fill ~7~113~6 ~19~113~6 minecraft:polished_basalt
fill ~21~91~6 ~22~91~20 minecraft:planks
fill ~21~102~6 ~21~102~21 minecraft:dirt
fill ~21~103~6 ~21~105~21 minecraft:polished_basalt
fill ~22~94~6 ~22~95~6 minecraft:stripped_oak_log
setblock ~23~15~6 minecraft:cobblestone_wall
setblock ~23~29~6 minecraft:cobblestone_wall
setblock ~23~43~6 minecraft:cobblestone_wall
setblock ~23~58~6 minecraft:cobblestone_wall
setblock ~23~95~6 minecraft:stone_block_slab4
fill ~24~0~6 ~24~0~24 minecraft:stonebrick
fill ~24~72~6 ~24~76~6 minecraft:stripped_oak_log
fill ~24~77~6 ~24~77~11 minecraft:planks
fill ~24~78~6 ~24~78~9 minecraft:planks
fill ~24~79~6 ~24~79~8 minecraft:planks
fill ~24~80~6 ~24~81~7 minecraft:planks
fill ~24~82~6 ~24~89~6 minecraft:planks
fill ~24~90~6 ~24~91~6 minecraft:stripped_oak_log
fill ~25~76~6 ~25~76~20 minecraft:stone_block_slab2
fill ~25~77~6 ~25~77~20 minecraft:stone_block_slab2
fill ~25~89~6 ~25~89~20 minecraft:stone_block_slab4
fill ~25~90~6 ~25~91~6 minecraft:fence
setblock ~25~92~6 minecraft:sandstone
setblock ~1~72~7 minecraft:sandstone
setblock ~1~73~7 minecraft:sandstone
setblock ~1~74~7 minecraft:sandstone
setblock ~1~75~7 minecraft:stone_block_slab4
fill ~1~82~7 ~1~84~7 minecraft:trapdoor
fill ~1~90~7 ~1~91~7 minecraft:sandstone
setblock ~1~92~7 minecraft:stone_block_slab4
setblock ~2~70~7 minecraft:trapdoor
setblock ~2~71~7 minecraft:glowstone
fill ~2~75~7 ~2~76~20 minecraft:stripped_oak_log
fill ~2~82~7 ~2~84~7 minecraft:glowstone
fill ~2~85~7 ~2~89~7 minecraft:planks
setblock ~2~91~7 minecraft:sandstone
setblock ~3~1~7 minecraft:sandstone
setblock ~3~70~7 minecraft:sandstone
fill ~3~71~7 ~3~71~19 minecraft:sandstone
setblock ~3~72~7 minecraft:torch
fill ~3~92~7 ~3~94~7 minecraft:sandstone
setblock ~3~95~7 minecraft:sandstone
setblock ~3~99~7 minecraft:sandstone
setblock ~3~100~7 minecraft:sandstone
setblock ~3~101~7 minecraft:cobblestone_wall
fill ~4~1~7 ~4~1~19 minecraft:sandstone
setblock ~4~2~7 minecraft:sandstone
fill ~4~3~7 ~4~13~7 minecraft:sandstone
setblock ~4~14~7 minecraft:sandstone
setblock ~4~15~7 minecraft:cobblestone_wall
setblock ~4~16~7 minecraft:sandstone
fill ~4~17~7 ~4~27~7 minecraft:sandstone
setblock ~4~28~7 minecraft:sandstone
setblock ~4~29~7 minecraft:cobblestone_wall
setblock ~4~30~7 minecraft:sandstone
fill ~4~31~7 ~4~41~7 minecraft:sandstone
setblock ~4~42~7 minecraft:sandstone
setblock ~4~43~7 minecraft:cobblestone_wall
setblock ~4~44~7 minecraft:sandstone
fill ~4~45~7 ~4~56~7 minecraft:sandstone
setblock ~4~57~7 minecraft:sandstone
setblock ~4~58~7 minecraft:cobblestone_wall
setblock ~4~59~7 minecraft:sandstone
fill ~4~60~7 ~4~70~7 minecraft:sandstone
setblock ~4~95~7 minecraft:torch
fill ~6~113~7 ~6~113~19 minecraft:polished_basalt
setblock ~7~107~7 minecraft:sandstone
fill ~7~108~7 ~7~109~7 minecraft:sandstone
setblock ~7~110~7 minecraft:sandstone
fill ~7~111~7 ~7~112~7 minecraft:sandstone
fill ~7~113~7 ~19~113~7 minecraft:sandstone
fill ~7~114~7 ~19~116~7 minecraft:polished_basalt
setblock ~7~117~7 minecraft:torch
setblock ~8~110~7 minecraft:sandstone
setblock ~8~111~7 minecraft:sandstone
setblock ~8~112~7 minecraft:sandstone
setblock ~9~110~7 minecraft:sandstone
setblock ~9~111~7 minecraft:sandstone
setblock ~9~112~7 minecraft:sandstone
setblock ~10~107~7 minecraft:sandstone
fill ~10~108~7 ~10~109~7 minecraft:sandstone
setblock ~10~110~7 minecraft:sandstone
fill ~10~111~7 ~10~112~7 minecraft:sandstone
setblock ~11~110~7 minecraft:sandstone
setblock ~11~111~7 minecraft:sandstone
setblock ~11~112~7 minecraft:sandstone
setblock ~12~110~7 minecraft:sandstone
setblock ~12~111~7 minecraft:sandstone
setblock ~12~112~7 minecraft:sandstone
setblock ~13~107~7 minecraft:sandstone
fill ~13~108~7 ~13~109~7 minecraft:sandstone
setblock ~13~110~7 minecraft:sandstone
fill ~13~111~7 ~13~112~7 minecraft:sandstone
setblock ~14~110~7 minecraft:sandstone
setblock ~14~111~7 minecraft:sandstone
setblock ~14~112~7 minecraft:sandstone
setblock ~15~110~7 minecraft:sandstone
setblock ~15~111~7 minecraft:sandstone
setblock ~15~112~7 minecraft:sandstone
setblock ~16~107~7 minecraft:sandstone
fill ~16~108~7 ~16~109~7 minecraft:sandstone
setblock ~16~110~7 minecraft:sandstone
fill ~16~111~7 ~16~112~7 minecraft:sandstone
setblock ~17~110~7 minecraft:sandstone
setblock ~17~111~7 minecraft:sandstone
setblock ~17~112~7 minecraft:sandstone
setblock ~18~110~7 minecraft:sandstone
setblock ~18~111~7 minecraft:sandstone
setblock ~18~112~7 minecraft:sandstone
setblock ~19~107~7 minecraft:sandstone
fill ~19~108~7 ~19~109~7 minecraft:sandstone
setblock ~19~110~7 minecraft:sandstone
fill ~19~111~7 ~19~112~7 minecraft:sandstone
setblock ~19~117~7 minecraft:torch
fill ~20~113~7 ~20~113~19 minecraft:polished_basalt
fill ~22~1~7 ~22~1~19 minecraft:sandstone
setblock ~22~2~7 minecraft:sandstone
fill ~22~3~7 ~22~13~7 minecraft:sandstone
setblock ~22~14~7 minecraft:sandstone
setblock ~22~15~7 minecraft:cobblestone_wall
setblock ~22~16~7 minecraft:sandstone
fill ~22~17~7 ~22~27~7 minecraft:sandstone
setblock ~22~28~7 minecraft:sandstone
setblock ~22~29~7 minecraft:cobblestone_wall
setblock ~22~30~7 minecraft:sandstone
fill ~22~31~7 ~22~41~7 minecraft:sandstone
setblock ~22~42~7 minecraft:sandstone
setblock ~22~43~7 minecraft:cobblestone_wall
setblock ~22~44~7 minecraft:sandstone
fill ~22~45~7 ~22~56~7 minecraft:sandstone
setblock ~22~57~7 minecraft:sandstone
setblock ~22~58~7 minecraft:cobblestone_wall
setblock ~22~59~7 minecraft:sandstone
fill ~22~60~7 ~22~70~7 minecraft:sandstone
setblock ~22~95~7 minecraft:torch
fill ~23~0~7 ~23~0~24 minecraft:stonebrick
setblock ~23~1~7 minecraft:sandstone
setblock ~23~70~7 minecraft:sandstone
fill ~23~71~7 ~23~71~19 minecraft:sandstone
setblock ~23~72~7 minecraft:torch
fill ~23~92~7 ~23~94~7 minecraft:sandstone
setblock ~23~95~7 minecraft:sandstone
setblock ~23~99~7 minecraft:sandstone
setblock ~23~100~7 minecraft:sandstone
setblock ~23~101~7 minecraft:cobblestone_wall
setblock ~24~70~7 minecraft:trapdoor
setblock ~24~71~7 minecraft:glowstone
fill ~24~75~7 ~24~76~20 minecraft:stripped_oak_log
fill ~24~82~7 ~24~84~7 minecraft:glowstone
fill ~24~85~7 ~24~89~7 minecraft:planks
fill ~24~91~7 ~25~91~7 minecraft:sandstone
setblock ~25~72~7 minecraft:sandstone
setblock ~25~73~7 minecraft:sandstone
setblock ~25~74~7 minecraft:sandstone
setblock ~25~75~7 minecraft:stone_block_slab4
fill ~25~82~7 ~25~84~7 minecraft:trapdoor
setblock ~25~90~7 minecraft:sandstone
setblock ~25~92~7 minecraft:stone_block_slab4
setblock ~1~75~8 minecraft:sandstone
fill ~1~80~8 ~1~81~8 minecraft:trapdoor
fill ~1~85~8 ~1~86~8 minecraft:trapdoor
fill ~1~90~8 ~1~91~8 minecraft:fence
setblock ~1~92~8 minecraft:sandstone
setblock ~2~71~8 minecraft:sandstone
fill ~2~72~8 ~2~74~8 minecraft:stripped_oak_log
fill ~2~80~8 ~2~81~8 minecraft:glowstone
fill ~2~82~8 ~2~84~8 minecraft:stone
fill ~2~85~8 ~2~86~8 minecraft:glowstone
fill ~2~87~8 ~2~89~8 minecraft:planks
fill ~2~90~8 ~2~91~8 minecraft:stripped_oak_log
setblock ~3~95~8 minecraft:stone_block_slab4
fill ~3~99~8 ~3~99~10 minecraft:polished_basalt
setblock ~4~2~8 minecraft:sandstone
setblock ~4~14~8 minecraft:stone_block_slab4
setblock ~4~15~8 minecraft:sandstone
setblock ~4~28~8 minecraft:stone_block_slab4
setblock ~4~29~8 minecraft:sandstone
setblock ~4~42~8 minecraft:stone_block_slab4
setblock ~4~43~8 minecraft:sandstone
setblock ~4~57~8 minecraft:stone_block_slab4
setblock ~4~58~8 minecraft:sandstone
setblock ~4~70~8 minecraft:sandstone
fill ~4~94~8 ~4~95~8 minecraft:stripped_oak_log
fill ~5~2~8 ~5~14~8 minecraft:stripped_oak_log
setblock ~5~15~8 minecraft:glowstone
fill ~5~16~8 ~5~28~8 minecraft:stripped_oak_log
setblock ~5~29~8 minecraft:glowstone
fill ~5~30~8 ~5~42~8 minecraft:stripped_oak_log
setblock ~5~43~8 minecraft:glowstone
fill ~5~44~8 ~5~57~8 minecraft:stripped_oak_log
setblock ~5~58~8 minecraft:glowstone
fill ~5~59~8 ~5~69~8 minecraft:stripped_oak_log
fill ~5~106~8 ~7~106~21 minecraft:sandstone
setblock ~7~110~8 minecraft:sandstone
setblock ~7~111~8 minecraft:sandstone
setblock ~7~112~8 minecraft:sandstone
fill ~7~113~8 ~7~113~19 minecraft:sandstone
fill ~7~114~8 ~7~116~19 minecraft:polished_basalt
fill ~8~106~8 ~18~106~12 minecraft:planks
fill ~8~111~8 ~9~112~8 minecraft:stripped_oak_log
fill ~8~116~8 ~18~116~8 minecraft:dirt
fill ~8~117~8 ~18~119~8 minecraft:polished_basalt
setblock ~8~120~8 minecraft:torch
setblock ~10~110~8 minecraft:torch
fill ~11~111~8 ~15~111~8 minecraft:stripped_oak_log
fill ~11~112~8 ~12~112~8 minecraft:stripped_oak_log
setblock ~13~110~8 minecraft:torch
fill ~14~112~8 ~15~112~8 minecraft:stripped_oak_log
setblock ~16~110~8 minecraft:torch
fill ~17~111~8 ~18~112~8 minecraft:stripped_oak_log
setblock ~18~120~8 minecraft:torch
fill ~19~106~8 ~21~106~21 minecraft:sandstone
setblock ~19~110~8 minecraft:sandstone
setblock ~19~111~8 minecraft:sandstone
setblock ~19~112~8 minecraft:sandstone
fill ~19~113~8 ~19~113~19 minecraft:sandstone
fill ~19~114~8 ~19~116~19 minecraft:polished_basalt
fill ~21~2~8 ~21~14~8 minecraft:stripped_oak_log
setblock ~21~15~8 minecraft:glowstone
fill ~21~16~8 ~21~28~8 minecraft:stripped_oak_log
setblock ~21~29~8 minecraft:glowstone
fill ~21~30~8 ~21~42~8 minecraft:stripped_oak_log
setblock ~21~43~8 minecraft:glowstone
fill ~21~44~8 ~21~57~8 minecraft:stripped_oak_log
setblock ~21~58~8 minecraft:glowstone
fill ~21~59~8 ~21~69~8 minecraft:stripped_oak_log
setblock ~22~2~8 minecraft:sandstone
setblock ~22~14~8 minecraft:stone_block_slab4
setblock ~22~15~8 minecraft:sandstone
setblock ~22~28~8 minecraft:stone_block_slab4
setblock ~22~29~8 minecraft:sandstone
setblock ~22~42~8 minecraft:stone_block_slab4
setblock ~22~43~8 minecraft:sandstone
setblock ~22~57~8 minecraft:stone_block_slab4
setblock ~22~58~8 minecraft:sandstone
setblock ~22~70~8 minecraft:sandstone
fill ~22~94~8 ~22~95~8 minecraft:stripped_oak_log
setblock ~23~95~8 minecraft:stone_block_slab4
fill ~23~99~8 ~23~99~10 minecraft:polished_basalt
setblock ~24~71~8 minecraft:sandstone
fill ~24~72~8 ~24~74~8 minecraft:stripped_oak_log
fill ~24~80~8 ~24~81~8 minecraft:glowstone
fill ~24~82~8 ~24~84~8 minecraft:stone
fill ~24~85~8 ~24~86~8 minecraft:glowstone
fill ~24~87~8 ~24~89~8 minecraft:planks
fill ~24~90~8 ~24~91~8 minecraft:stripped_oak_log
setblock ~25~75~8 minecraft:sandstone
fill ~25~80~8 ~25~81~8 minecraft:trapdoor
fill ~25~85~8 ~25~86~8 minecraft:trapdoor
fill ~25~90~8 ~25~91~8 minecraft:fence
setblock ~25~92~8 minecraft:sandstone
setblock ~1~72~9 minecraft:sandstone
setblock ~1~73~9 minecraft:sandstone
setblock ~1~74~9 minecraft:sandstone
setblock ~1~75~9 minecraft:stone_block_slab4
setblock ~1~79~9 minecraft:trapdoor
setblock ~1~87~9 minecraft:trapdoor
fill ~1~90~9 ~1~91~9 minecraft:sandstone
setblock ~1~92~9 minecraft:stone_block_slab4
setblock ~2~70~9 minecraft:trapdoor
setblock ~2~71~9 minecraft:glowstone
setblock ~2~79~9 minecraft:glowstone
fill ~2~80~9 ~2~81~9 minecraft:stone
setblock ~2~82~9 minecraft:gravel
fill ~2~83~9 ~2~83~12 minecraft:quartz_block
setblock ~2~84~9 minecraft:gravel
fill ~2~85~9 ~2~86~9 minecraft:stone
setblock ~2~87~9 minecraft:glowstone
fill ~2~88~9 ~2~89~9 minecraft:planks
setblock ~2~91~9 minecraft:sandstone
setblock ~3~70~9 minecraft:sandstone
fill ~3~92~9 ~3~94~9 minecraft:sandstone
setblock ~3~95~9 minecraft:sandstone
setblock ~4~2~9 minecraft:sandstone
fill ~4~3~9 ~4~13~9 minecraft:sandstone
setblock ~4~14~9 minecraft:sandstone
setblock ~4~15~9 minecraft:cobblestone_wall
setblock ~4~16~9 minecraft:sandstone
fill ~4~17~9 ~4~27~9 minecraft:sandstone
setblock ~4~28~9 minecraft:sandstone
setblock ~4~29~9 minecraft:cobblestone_wall
setblock ~4~30~9 minecraft:sandstone
fill ~4~31~9 ~4~41~9 minecraft:sandstone
setblock ~4~42~9 minecraft:sandstone
setblock ~4~43~9 minecraft:cobblestone_wall
setblock ~4~44~9 minecraft:sandstone
fill ~4~45~9 ~4~56~9 minecraft:sandstone
setblock ~4~57~9 minecraft:sandstone
setblock ~4~58~9 minecraft:cobblestone_wall
setblock ~4~59~9 minecraft:sandstone
fill ~4~60~9 ~4~70~9 minecraft:sandstone
setblock ~4~95~9 minecraft:torch
setblock ~4~102~9 minecraft:sandstone
setblock ~4~103~9 minecraft:sandstone
setblock ~4~104~9 minecraft:cobblestone_wall
setblock ~7~110~9 minecraft:sandstone
setblock ~7~111~9 minecraft:sandstone
setblock ~7~112~9 minecraft:sandstone
fill ~8~111~9 ~8~112~9 minecraft:stripped_oak_log
fill ~8~116~9 ~8~116~18 minecraft:dirt
fill ~8~117~9 ~8~119~18 minecraft:polished_basalt
fill ~9~119~9 ~17~119~9 minecraft:dirt
fill ~9~120~9 ~17~122~9 minecraft:polished_basalt
setblock ~9~123~9 minecraft:torch
fill ~13~111~9 ~13~111~18 minecraft:stripped_oak_log
setblock ~17~123~9 minecraft:torch
fill ~18~111~9 ~18~112~9 minecraft:stripped_oak_log
fill ~18~116~9 ~18~116~18 minecraft:dirt
fill ~18~117~9 ~18~119~18 minecraft:polished_basalt
setblock ~19~110~9 minecraft:sandstone
setblock ~19~111~9 minecraft:sandstone
setblock ~19~112~9 minecraft:sandstone
setblock ~22~2~9 minecraft:sandstone
fill ~22~3~9 ~22~13~9 minecraft:sandstone
setblock ~22~14~9 minecraft:sandstone
setblock ~22~15~9 minecraft:cobblestone_wall
setblock ~22~16~9 minecraft:sandstone
fill ~22~17~9 ~22~27~9 minecraft:sandstone
setblock ~22~28~9 minecraft:sandstone
setblock ~22~29~9 minecraft:cobblestone_wall
setblock ~22~30~9 minecraft:sandstone
fill ~22~31~9 ~22~41~9 minecraft:sandstone
setblock ~22~42~9 minecraft:sandstone
setblock ~22~43~9 minecraft:cobblestone_wall
setblock ~22~44~9 minecraft:sandstone
fill ~22~45~9 ~22~56~9 minecraft:sandstone
setblock ~22~57~9 minecraft:sandstone
setblock ~22~58~9 minecraft:cobblestone_wall
setblock ~22~59~9 minecraft:sandstone
fill ~22~60~9 ~22~70~9 minecraft:sandstone
setblock ~22~95~9 minecraft:torch
setblock ~22~102~9 minecraft:sandstone
setblock ~22~103~9 minecraft:sandstone
setblock ~22~104~9 minecraft:cobblestone_wall
setblock ~23~70~9 minecraft:sandstone
fill ~23~92~9 ~23~94~9 minecraft:sandstone
setblock ~23~95~9 minecraft:sandstone
setblock ~24~70~9 minecraft:trapdoor
setblock ~24~71~9 minecraft:glowstone
setblock ~24~79~9 minecraft:glowstone
fill ~24~80~9 ~24~81~9 minecraft:stone
setblock ~24~82~9 minecraft:gravel
fill ~24~83~9 ~24~83~12 minecraft:quartz_block
setblock ~24~84~9 minecraft:gravel
fill ~24~85~9 ~24~86~9 minecraft:stone
setblock ~24~87~9 minecraft:glowstone
fill ~24~88~9 ~24~89~9 minecraft:planks
fill ~24~91~9 ~25~91~9 minecraft:sandstone
setblock ~25~72~9 minecraft:sandstone
setblock ~25~73~9 minecraft:sandstone
setblock ~25~74~9 minecraft:sandstone
setblock ~25~75~9 minecraft:stone_block_slab4
setblock ~25~79~9 minecraft:trapdoor
setblock ~25~87~9 minecraft:trapdoor
setblock ~25~90~9 minecraft:sandstone
setblock ~25~92~9 minecraft:stone_block_slab4
setblock ~1~75~10 minecraft:sandstone
fill ~1~78~10 ~1~78~11 minecraft:trapdoor
fill ~1~88~10 ~1~88~11 minecraft:trapdoor
fill ~1~90~10 ~1~91~10 minecraft:fence
setblock ~1~92~10 minecraft:sandstone
setblock ~2~71~10 minecraft:sandstone
fill ~2~72~10 ~2~74~10 minecraft:stripped_oak_log
fill ~2~78~10 ~2~78~11 minecraft:glowstone
fill ~2~79~10 ~2~79~11 minecraft:stone
setblock ~2~80~10 minecraft:gravel
fill ~2~81~10 ~2~81~16 minecraft:quartz_block
fill ~2~82~10 ~2~82~13 minecraft:quartz_block
fill ~2~84~10 ~2~84~11 minecraft:quartz_block
setblock ~2~85~10 minecraft:quartz_block
setblock ~2~86~10 minecraft:coal_block
fill ~2~87~10 ~2~87~11 minecraft:stone
fill ~2~88~10 ~2~88~11 minecraft:glowstone
fill ~2~89~10 ~2~89~11 minecraft:planks
fill ~2~90~10 ~2~91~10 minecraft:stripped_oak_log
setblock ~3~95~10 minecraft:stone_block_slab4
setblock ~4~2~10 minecraft:sandstone
setblock ~4~14~10 minecraft:stone_block_slab4
setblock ~4~15~10 minecraft:sandstone
setblock ~4~28~10 minecraft:stone_block_slab4
setblock ~4~29~10 minecraft:sandstone
setblock ~4~42~10 minecraft:stone_block_slab4
setblock ~4~43~10 minecraft:sandstone
setblock ~4~57~10 minecraft:stone_block_slab4
setblock ~4~58~10 minecraft:sandstone
setblock ~4~70~10 minecraft:sandstone
fill ~4~94~10 ~4~95~10 minecraft:stripped_oak_log
fill ~4~102~10 ~4~102~12 minecraft:polished_basalt
fill ~5~2~10 ~5~14~10 minecraft:stripped_oak_log
setblock ~5~15~10 minecraft:glowstone
fill ~5~16~10 ~5~28~10 minecraft:stripped_oak_log
setblock ~5~29~10 minecraft:glowstone
fill ~5~30~10 ~5~42~10 minecraft:stripped_oak_log
setblock ~5~43~10 minecraft:glowstone
fill ~5~44~10 ~5~57~10 minecraft:stripped_oak_log
setblock ~5~58~10 minecraft:glowstone
fill ~5~59~10 ~5~69~10 minecraft:stripped_oak_log
setblock ~7~107~10 minecraft:sandstone
fill ~7~108~10 ~7~109~10 minecraft:sandstone
setblock ~7~110~10 minecraft:sandstone
fill ~7~111~10 ~7~112~10 minecraft:sandstone
setblock ~8~110~10 minecraft:torch
fill ~9~119~10 ~9~119~17 minecraft:dirt
fill ~9~120~10 ~9~122~17 minecraft:polished_basalt
fill ~10~122~10 ~16~122~10 minecraft:dirt
fill ~10~123~10 ~16~125~10 minecraft:polished_basalt
setblock ~10~126~10 minecraft:torch
setblock ~16~126~10 minecraft:torch
fill ~17~119~10 ~17~119~17 minecraft:dirt
fill ~17~120~10 ~17~122~17 minecraft:polished_basalt
setblock ~18~110~10 minecraft:torch
setblock ~19~107~10 minecraft:sandstone
fill ~19~108~10 ~19~109~10 minecraft:sandstone
setblock ~19~110~10 minecraft:sandstone
fill ~19~111~10 ~19~112~10 minecraft:sandstone
fill ~21~2~10 ~21~14~10 minecraft:stripped_oak_log
setblock ~21~15~10 minecraft:glowstone
fill ~21~16~10 ~21~28~10 minecraft:stripped_oak_log
setblock ~21~29~10 minecraft:glowstone
fill ~21~30~10 ~21~42~10 minecraft:stripped_oak_log
setblock ~21~43~10 minecraft:glowstone
fill ~21~44~10 ~21~57~10 minecraft:stripped_oak_log
setblock ~21~58~10 minecraft:glowstone
fill ~21~59~10 ~21~69~10 minecraft:stripped_oak_log
setblock ~22~2~10 minecraft:sandstone
setblock ~22~14~10 minecraft:stone_block_slab4
setblock ~22~15~10 minecraft:sandstone
setblock ~22~28~10 minecraft:stone_block_slab4
setblock ~22~29~10 minecraft:sandstone
setblock ~22~42~10 minecraft:stone_block_slab4
setblock ~22~43~10 minecraft:sandstone
setblock ~22~57~10 minecraft:stone_block_slab4
setblock ~22~58~10 minecraft:sandstone
setblock ~22~70~10 minecraft:sandstone
fill ~22~94~10 ~22~95~10 minecraft:stripped_oak_log
fill ~22~102~10 ~22~102~12 minecraft:polished_basalt
setblock ~23~95~10 minecraft:stone_block_slab4
setblock ~24~71~10 minecraft:sandstone
fill ~24~72~10 ~24~74~10 minecraft:stripped_oak_log
fill ~24~78~10 ~24~78~11 minecraft:glowstone
fill ~24~79~10 ~24~79~11 minecraft:stone
setblock ~24~80~10 minecraft:gravel
fill ~24~81~10 ~24~81~16 minecraft:quartz_block
fill ~24~82~10 ~24~82~11 minecraft:quartz_block
fill ~24~84~10 ~24~84~11 minecraft:quartz_block
setblock ~24~85~10 minecraft:quartz_block
setblock ~24~86~10 minecraft:gravel
fill ~24~87~10 ~24~87~11 minecraft:stone
fill ~24~88~10 ~24~88~11 minecraft:glowstone
fill ~24~89~10 ~24~89~11 minecraft:planks
fill ~24~90~10 ~24~91~10 minecraft:stripped_oak_log
setblock ~25~75~10 minecraft:sandstone
fill ~25~78~10 ~25~78~11 minecraft:trapdoor
fill ~25~88~10 ~25~88~11 minecraft:trapdoor
fill ~25~90~10 ~25~91~10 minecraft:fence
setblock ~25~92~10 minecraft:sandstone
setblock ~1~72~11 minecraft:sandstone
setblock ~1~73~11 minecraft:sandstone
setblock ~1~74~11 minecraft:sandstone
setblock ~1~75~11 minecraft:stone_block_slab4
fill ~1~90~11 ~1~91~11 minecraft:sandstone
setblock ~1~92~11 minecraft:stone_block_slab4
setblock ~2~70~11 minecraft:trapdoor
setblock ~2~71~11 minecraft:glowstone
fill ~2~80~11 ~2~80~15 minecraft:quartz_block
setblock ~2~85~11 minecraft:coal_block
fill ~2~86~11 ~2~86~15 minecraft:quartz_block
setblock ~2~91~11 minecraft:sandstone
setblock ~3~70~11 minecraft:sandstone
setblock ~3~72~11 minecraft:torch
fill ~3~92~11 ~3~94~11 minecraft:sandstone
setblock ~3~95~11 minecraft:sandstone
setblock ~3~99~11 minecraft:sandstone
setblock ~3~100~11 minecraft:sandstone
setblock ~3~101~11 minecraft:cobblestone_wall
setblock ~4~2~11 minecraft:sandstone
fill ~4~3~11 ~4~13~11 minecraft:sandstone
setblock ~4~14~11 minecraft:sandstone
setblock ~4~15~11 minecraft:cobblestone_wall
setblock ~4~16~11 minecraft:sandstone
fill ~4~17~11 ~4~27~11 minecraft:sandstone
setblock ~4~28~11 minecraft:sandstone
setblock ~4~29~11 minecraft:cobblestone_wall
setblock ~4~30~11 minecraft:sandstone
fill ~4~31~11 ~4~41~11 minecraft:sandstone
setblock ~4~42~11 minecraft:sandstone
setblock ~4~43~11 minecraft:cobblestone_wall
setblock ~4~44~11 minecraft:sandstone
fill ~4~45~11 ~4~56~11 minecraft:sandstone
setblock ~4~57~11 minecraft:sandstone
setblock ~4~58~11 minecraft:cobblestone_wall
setblock ~4~59~11 minecraft:sandstone
fill ~4~60~11 ~4~70~11 minecraft:sandstone
setblock ~4~95~11 minecraft:torch
setblock ~7~110~11 minecraft:sandstone
setblock ~7~111~11 minecraft:sandstone
setblock ~7~112~11 minecraft:sandstone
fill ~8~111~11 ~8~111~15 minecraft:stripped_oak_log
fill ~8~112~11 ~8~112~12 minecraft:stripped_oak_log
fill ~10~122~11 ~10~122~16 minecraft:dirt
fill ~10~123~11 ~10~125~16 minecraft:polished_basalt
fill ~11~125~11 ~15~125~11 minecraft:dirt
fill ~11~126~11 ~15~128~11 minecraft:polished_basalt
setblock ~11~129~11 minecraft:torch
setblock ~15~129~11 minecraft:torch
fill ~16~122~11 ~16~122~16 minecraft:dirt
fill ~16~123~11 ~16~125~16 minecraft:polished_basalt
fill ~18~111~11 ~18~111~15 minecraft:stripped_oak_log
fill ~18~112~11 ~18~112~12 minecraft:stripped_oak_log
setblock ~19~110~11 minecraft:sandstone
setblock ~19~111~11 minecraft:sandstone
setblock ~19~112~11 minecraft:sandstone
setblock ~22~2~11 minecraft:sandstone
fill ~22~3~11 ~22~13~11 minecraft:sandstone
setblock ~22~14~11 minecraft:sandstone
setblock ~22~15~11 minecraft:cobblestone_wall
setblock ~22~16~11 minecraft:sandstone
fill ~22~17~11 ~22~27~11 minecraft:sandstone
setblock ~22~28~11 minecraft:sandstone
setblock ~22~29~11 minecraft:cobblestone_wall
setblock ~22~30~11 minecraft:sandstone
fill ~22~31~11 ~22~41~11 minecraft:sandstone
setblock ~22~42~11 minecraft:sandstone
setblock ~22~43~11 minecraft:cobblestone_wall
setblock ~22~44~11 minecraft:sandstone
fill ~22~45~11 ~22~56~11 minecraft:sandstone
setblock ~22~57~11 minecraft:sandstone
setblock ~22~58~11 minecraft:cobblestone_wall
setblock ~22~59~11 minecraft:sandstone
fill ~22~60~11 ~22~70~11 minecraft:sandstone
setblock ~22~95~11 minecraft:torch
setblock ~23~70~11 minecraft:sandstone
setblock ~23~72~11 minecraft:torch
fill ~23~92~11 ~23~94~11 minecraft:sandstone
setblock ~23~95~11 minecraft:sandstone
setblock ~23~99~11 minecraft:sandstone
setblock ~23~100~11 minecraft:sandstone
setblock ~23~101~11 minecraft:cobblestone_wall
setblock ~24~70~11 minecraft:trapdoor
setblock ~24~71~11 minecraft:glowstone
fill ~24~80~11 ~24~80~15 minecraft:quartz_block
setblock ~24~85~11 minecraft:coal_block
fill ~24~86~11 ~24~86~15 minecraft:quartz_block
fill ~24~91~11 ~25~91~11 minecraft:sandstone
setblock ~25~72~11 minecraft:sandstone
setblock ~25~73~11 minecraft:sandstone
setblock ~25~74~11 minecraft:sandstone
setblock ~25~75~11 minecraft:stone_block_slab4
setblock ~25~90~11 minecraft:sandstone
setblock ~25~92~11 minecraft:stone_block_slab4
setblock ~1~75~12 minecraft:sandstone
fill ~1~90~12 ~1~91~12 minecraft:fence
setblock ~1~92~12 minecraft:sandstone
setblock ~2~71~12 minecraft:sandstone
fill ~2~72~12 ~2~74~12 minecraft:stripped_oak_log
fill ~2~77~12 ~2~77~14 minecraft:glowstone
fill ~2~78~12 ~2~78~14 minecraft:stone
setblock ~2~79~12 minecraft:gravel
setblock ~2~84~12 minecraft:coal_block
fill ~2~85~12 ~2~85~14 minecraft:quartz_block
setblock ~2~87~12 minecraft:gravel
fill ~2~88~12 ~2~88~14 minecraft:stone
fill ~2~89~12 ~2~89~14 minecraft:glowstone
fill ~2~90~12 ~2~91~12 minecraft:stripped_oak_log
setblock ~3~95~12 minecraft:stone_block_slab4
fill ~3~99~12 ~3~99~14 minecraft:polished_basalt
setblock ~4~2~12 minecraft:sandstone
setblock ~4~14~12 minecraft:stone_block_slab4
setblock ~4~15~12 minecraft:sandstone
setblock ~4~28~12 minecraft:stone_block_slab4
setblock ~4~29~12 minecraft:sandstone
setblock ~4~42~12 minecraft:stone_block_slab4
setblock ~4~43~12 minecraft:sandstone
setblock ~4~57~12 minecraft:stone_block_slab4
setblock ~4~58~12 minecraft:sandstone
setblock ~4~70~12 minecraft:sandstone
fill ~4~94~12 ~4~95~12 minecraft:stripped_oak_log
fill ~5~2~12 ~5~14~12 minecraft:stripped_oak_log
setblock ~5~15~12 minecraft:glowstone
fill ~5~16~12 ~5~28~12 minecraft:stripped_oak_log
setblock ~5~29~12 minecraft:glowstone
fill ~5~30~12 ~5~42~12 minecraft:stripped_oak_log
setblock ~5~43~12 minecraft:glowstone
fill ~5~44~12 ~5~57~12 minecraft:stripped_oak_log
setblock ~5~58~12 minecraft:glowstone
fill ~5~59~12 ~5~69~12 minecraft:stripped_oak_log
setblock ~7~110~12 minecraft:sandstone
setblock ~7~111~12 minecraft:sandstone
setblock ~7~112~12 minecraft:sandstone
fill ~11~125~12 ~11~125~15 minecraft:dirt
fill ~11~126~12 ~11~128~15 minecraft:polished_basalt
fill ~12~128~12 ~14~128~12 minecraft:dirt
fill ~12~129~12 ~14~131~12 minecraft:polished_basalt
setblock ~13~110~12 minecraft:torch
setblock ~13~134~12 minecraft:sandstone
setblock ~13~135~12 minecraft:stone_block_slab4
fill ~15~125~12 ~15~125~15 minecraft:dirt
fill ~15~126~12 ~15~128~15 minecraft:polished_basalt
setblock ~19~110~12 minecraft:sandstone
setblock ~19~111~12 minecraft:sandstone
setblock ~19~112~12 minecraft:sandstone
fill ~21~2~12 ~21~14~12 minecraft:stripped_oak_log
setblock ~21~15~12 minecraft:glowstone
fill ~21~16~12 ~21~28~12 minecraft:stripped_oak_log
setblock ~21~29~12 minecraft:glowstone
fill ~21~30~12 ~21~42~12 minecraft:stripped_oak_log
setblock ~21~43~12 minecraft:glowstone
fill ~21~44~12 ~21~57~12 minecraft:stripped_oak_log
setblock ~21~58~12 minecraft:glowstone
fill ~21~59~12 ~21~69~12 minecraft:stripped_oak_log
setblock ~22~2~12 minecraft:sandstone
setblock ~22~14~12 minecraft:stone_block_slab4
setblock ~22~15~12 minecraft:sandstone
setblock ~22~28~12 minecraft:stone_block_slab4
setblock ~22~29~12 minecraft:sandstone
setblock ~22~42~12 minecraft:stone_block_slab4
setblock ~22~43~12 minecraft:sandstone
setblock ~22~57~12 minecraft:stone_block_slab4
setblock ~22~58~12 minecraft:sandstone
setblock ~22~70~12 minecraft:sandstone
fill ~22~94~12 ~22~95~12 minecraft:stripped_oak_log
setblock ~23~95~12 minecraft:stone_block_slab4
fill ~23~99~12 ~23~99~14 minecraft:polished_basalt
setblock ~24~71~12 minecraft:sandstone
fill ~24~72~12 ~24~74~12 minecraft:stripped_oak_log
fill ~24~77~12 ~24~77~14 minecraft:glowstone
fill ~24~78~12 ~24~78~14 minecraft:stone
setblock ~24~79~12 minecraft:gravel
setblock ~24~82~12 minecraft:coal_block
setblock ~24~84~12 minecraft:coal_block
fill ~24~85~12 ~24~85~14 minecraft:quartz_block
setblock ~24~87~12 minecraft:gravel
fill ~24~88~12 ~24~88~14 minecraft:stone
fill ~24~89~12 ~24~89~14 minecraft:glowstone
fill ~24~90~12 ~24~91~12 minecraft:stripped_oak_log
setblock ~25~75~12 minecraft:sandstone
fill ~25~90~12 ~25~91~12 minecraft:fence
setblock ~25~92~12 minecraft:sandstone
setblock ~1~72~13 minecraft:sandstone
setblock ~1~73~13 minecraft:sandstone
setblock ~1~74~13 minecraft:sandstone
setblock ~1~75~13 minecraft:stone_block_slab4
fill ~1~90~13 ~1~91~13 minecraft:sandstone
setblock ~1~92~13 minecraft:stone_block_slab4
setblock ~2~70~13 minecraft:trapdoor
setblock ~2~71~13 minecraft:glowstone
setblock ~2~79~13 minecraft:quartz_block
setblock ~2~83~13 minecraft:coal_block
setblock ~2~84~13 minecraft:quartz_block
setblock ~2~87~13 minecraft:quartz_block
setblock ~2~91~13 minecraft:sandstone
setblock ~3~70~13 minecraft:sandstone
fill ~3~92~13 ~3~94~13 minecraft:sandstone
setblock ~3~95~13 minecraft:sandstone
setblock ~4~2~13 minecraft:sandstone
fill ~4~3~13 ~4~13~13 minecraft:sandstone
setblock ~4~14~13 minecraft:sandstone
setblock ~4~15~13 minecraft:cobblestone_wall
setblock ~4~16~13 minecraft:sandstone
fill ~4~17~13 ~4~27~13 minecraft:sandstone
setblock ~4~28~13 minecraft:sandstone
setblock ~4~29~13 minecraft:cobblestone_wall
setblock ~4~30~13 minecraft:sandstone
fill ~4~31~13 ~4~41~13 minecraft:sandstone
setblock ~4~42~13 minecraft:sandstone
setblock ~4~43~13 minecraft:cobblestone_wall
setblock ~4~44~13 minecraft:sandstone
fill ~4~45~13 ~4~56~13 minecraft:sandstone
setblock ~4~57~13 minecraft:sandstone
setblock ~4~58~13 minecraft:cobblestone_wall
setblock ~4~59~13 minecraft:sandstone
fill ~4~60~13 ~4~70~13 minecraft:sandstone
setblock ~4~95~13 minecraft:torch
setblock ~4~102~13 minecraft:sandstone
setblock ~4~103~13 minecraft:sandstone
setblock ~4~104~13 minecraft:cobblestone_wall
setblock ~7~107~13 minecraft:sandstone
fill ~7~108~13 ~7~109~13 minecraft:sandstone
setblock ~7~110~13 minecraft:sandstone
fill ~7~111~13 ~7~112~13 minecraft:sandstone
fill ~8~106~13 ~12~106~18 minecraft:planks
fill ~9~111~13 ~12~111~13 minecraft:stripped_oak_log
setblock ~12~110~13 minecraft:torch
fill ~12~128~13 ~12~128~14 minecraft:dirt
fill ~12~129~13 ~12~131~14 minecraft:polished_basalt
setblock ~12~134~13 minecraft:sandstone
setblock ~12~135~13 minecraft:stone_block_slab4
setblock ~13~110~13 minecraft:stripped_oak_log
setblock ~13~130~13 minecraft:dirt
fill ~13~131~13 ~14~131~14 minecraft:polished_basalt
fill ~13~132~13 ~13~133~13 minecraft:cobblestone_wall
fill ~13~134~13 ~13~135~13 minecraft:sandstone
setblock ~13~136~13 minecraft:cobblestone_wall
fill ~13~137~13 ~13~139~13 minecraft:fence
setblock ~13~140~13 minecraft:stone_block_slab4
fill ~14~106~13 ~18~106~18 minecraft:planks
setblock ~14~110~13 minecraft:torch
fill ~14~111~13 ~17~111~13 minecraft:stripped_oak_log
fill ~14~128~13 ~14~128~14 minecraft:dirt
fill ~14~129~13 ~14~130~14 minecraft:polished_basalt
setblock ~14~134~13 minecraft:sandstone
setblock ~14~135~13 minecraft:stone_block_slab4
setblock ~18~110~13 minecraft:torch
setblock ~19~107~13 minecraft:sandstone
fill ~19~108~13 ~19~109~13 minecraft:sandstone
setblock ~19~110~13 minecraft:sandstone
fill ~19~111~13 ~19~112~13 minecraft:sandstone
setblock ~22~2~13 minecraft:sandstone
fill ~22~3~13 ~22~13~13 minecraft:sandstone
setblock ~22~14~13 minecraft:sandstone
setblock ~22~15~13 minecraft:cobblestone_wall
setblock ~22~16~13 minecraft:sandstone
fill ~22~17~13 ~22~27~13 minecraft:sandstone
setblock ~22~28~13 minecraft:sandstone
setblock ~22~29~13 minecraft:cobblestone_wall
setblock ~22~30~13 minecraft:sandstone
fill ~22~31~13 ~22~41~13 minecraft:sandstone
setblock ~22~42~13 minecraft:sandstone
setblock ~22~43~13 minecraft:cobblestone_wall
setblock ~22~44~13 minecraft:sandstone
fill ~22~45~13 ~22~56~13 minecraft:sandstone
setblock ~22~57~13 minecraft:sandstone
setblock ~22~58~13 minecraft:cobblestone_wall
setblock ~22~59~13 minecraft:sandstone
fill ~22~60~13 ~22~70~13 minecraft:sandstone
setblock ~22~95~13 minecraft:torch
setblock ~22~102~13 minecraft:sandstone
setblock ~22~103~13 minecraft:sandstone
setblock ~22~104~13 minecraft:cobblestone_wall
setblock ~23~70~13 minecraft:sandstone
fill ~23~92~13 ~23~94~13 minecraft:sandstone
setblock ~23~95~13 minecraft:sandstone
setblock ~24~70~13 minecraft:trapdoor
setblock ~24~71~13 minecraft:glowstone
setblock ~24~79~13 minecraft:quartz_block
fill ~24~82~13 ~24~82~16 minecraft:quartz_block
setblock ~24~83~13 minecraft:coal_block
setblock ~24~84~13 minecraft:quartz_block
setblock ~24~87~13 minecraft:quartz_block
fill ~24~91~13 ~25~91~13 minecraft:sandstone
setblock ~25~72~13 minecraft:sandstone
setblock ~25~73~13 minecraft:sandstone
setblock ~25~74~13 minecraft:sandstone
setblock ~25~75~13 minecraft:stone_block_slab4
setblock ~25~90~13 minecraft:sandstone
setblock ~25~92~13 minecraft:stone_block_slab4
setblock ~1~75~14 minecraft:sandstone
fill ~1~90~14 ~1~91~14 minecraft:fence
setblock ~1~92~14 minecraft:sandstone
setblock ~2~71~14 minecraft:sandstone
fill ~2~72~14 ~2~74~14 minecraft:stripped_oak_log
setblock ~2~79~14 minecraft:gravel
setblock ~2~82~14 minecraft:coal_block
fill ~2~83~14 ~2~83~17 minecraft:quartz_block
setblock ~2~84~14 minecraft:coal_block
setblock ~2~87~14 minecraft:gravel
fill ~2~90~14 ~2~91~14 minecraft:stripped_oak_log
setblock ~3~95~14 minecraft:stone_block_slab4
setblock ~4~2~14 minecraft:sandstone
setblock ~4~14~14 minecraft:stone_block_slab4
setblock ~4~15~14 minecraft:sandstone
setblock ~4~28~14 minecraft:stone_block_slab4
setblock ~4~29~14 minecraft:sandstone
setblock ~4~42~14 minecraft:stone_block_slab4
setblock ~4~43~14 minecraft:sandstone
setblock ~4~57~14 minecraft:stone_block_slab4
setblock ~4~58~14 minecraft:sandstone
setblock ~4~70~14 minecraft:sandstone
fill ~4~94~14 ~4~95~14 minecraft:stripped_oak_log
fill ~4~102~14 ~4~102~16 minecraft:polished_basalt
fill ~5~2~14 ~5~14~14 minecraft:stripped_oak_log
setblock ~5~15~14 minecraft:glowstone
fill ~5~16~14 ~5~28~14 minecraft:stripped_oak_log
setblock ~5~29~14 minecraft:glowstone
fill ~5~30~14 ~5~42~14 minecraft:stripped_oak_log
setblock ~5~43~14 minecraft:glowstone
fill ~5~44~14 ~5~57~14 minecraft:stripped_oak_log
setblock ~5~58~14 minecraft:glowstone
fill ~5~59~14 ~5~69~14 minecraft:stripped_oak_log
setblock ~7~110~14 minecraft:sandstone
setblock ~7~111~14 minecraft:sandstone
setblock ~7~112~14 minecraft:sandstone
fill ~8~112~14 ~8~112~15 minecraft:stripped_oak_log
fill ~13~106~14 ~13~106~18 minecraft:planks
setblock ~13~110~14 minecraft:torch
setblock ~13~128~14 minecraft:dirt
fill ~13~129~14 ~13~130~14 minecraft:polished_basalt
setblock ~13~134~14 minecraft:sandstone
setblock ~13~135~14 minecraft:stone_block_slab4
fill ~18~112~14 ~18~112~15 minecraft:stripped_oak_log
setblock ~19~110~14 minecraft:sandstone
setblock ~19~111~14 minecraft:sandstone
setblock ~19~112~14 minecraft:sandstone
fill ~21~2~14 ~21~14~14 minecraft:stripped_oak_log
setblock ~21~15~14 minecraft:glowstone
fill ~21~16~14 ~21~28~14 minecraft:stripped_oak_log
setblock ~21~29~14 minecraft:glowstone
fill ~21~30~14 ~21~42~14 minecraft:stripped_oak_log
setblock ~21~43~14 minecraft:glowstone
fill ~21~44~14 ~21~57~14 minecraft:stripped_oak_log
setblock ~21~58~14 minecraft:glowstone
fill ~21~59~14 ~21~69~14 minecraft:stripped_oak_log
setblock ~22~2~14 minecraft:sandstone
setblock ~22~14~14 minecraft:stone_block_slab4
setblock ~22~15~14 minecraft:sandstone
setblock ~22~28~14 minecraft:stone_block_slab4
setblock ~22~29~14 minecraft:sandstone
setblock ~22~42~14 minecraft:stone_block_slab4
setblock ~22~43~14 minecraft:sandstone
setblock ~22~57~14 minecraft:stone_block_slab4
setblock ~22~58~14 minecraft:sandstone
setblock ~22~70~14 minecraft:sandstone
fill ~22~94~14 ~22~95~14 minecraft:stripped_oak_log
fill ~22~102~14 ~22~102~16 minecraft:polished_basalt
setblock ~23~95~14 minecraft:stone_block_slab4
setblock ~24~71~14 minecraft:sandstone
fill ~24~72~14 ~24~74~14 minecraft:stripped_oak_log
setblock ~24~79~14 minecraft:gravel
fill ~24~83~14 ~24~83~17 minecraft:quartz_block
setblock ~24~84~14 minecraft:coal_block
setblock ~24~87~14 minecraft:gravel
fill ~24~90~14 ~24~91~14 minecraft:stripped_oak_log
setblock ~25~75~14 minecraft:sandstone
fill ~25~90~14 ~25~91~14 minecraft:fence
setblock ~25~92~14 minecraft:sandstone
setblock ~1~72~15 minecraft:sandstone
setblock ~1~73~15 minecraft:sandstone
setblock ~1~74~15 minecraft:sandstone
setblock ~1~75~15 minecraft:stone_block_slab4
fill ~1~78~15 ~1~78~16 minecraft:trapdoor
fill ~1~88~15 ~1~88~16 minecraft:trapdoor
fill ~1~90~15 ~1~91~15 minecraft:sandstone
setblock ~1~92~15 minecraft:stone_block_slab4
setblock ~2~70~15 minecraft:trapdoor
setblock ~2~71~15 minecraft:glowstone
fill ~2~77~15 ~2~77~20 minecraft:planks
fill ~2~78~15 ~2~78~16 minecraft:glowstone
fill ~2~79~15 ~2~79~16 minecraft:stone
fill ~2~82~15 ~2~82~16 minecraft:quartz_block
fill ~2~84~15 ~2~84~16 minecraft:quartz_block
setblock ~2~85~15 minecraft:coal_block
fill ~2~87~15 ~2~87~16 minecraft:stone
fill ~2~88~15 ~2~88~16 minecraft:glowstone
fill ~2~89~15 ~2~89~20 minecraft:planks
setblock ~2~91~15 minecraft:sandstone
setblock ~3~70~15 minecraft:sandstone
setblock ~3~72~15 minecraft:torch
fill ~3~92~15 ~3~94~15 minecraft:sandstone
setblock ~3~95~15 minecraft:sandstone
setblock ~3~99~15 minecraft:sandstone
setblock ~3~100~15 minecraft:sandstone
setblock ~3~101~15 minecraft:cobblestone_wall
setblock ~4~2~15 minecraft:sandstone
fill ~4~3~15 ~4~13~15 minecraft:sandstone
setblock ~4~14~15 minecraft:sandstone
setblock ~4~15~15 minecraft:cobblestone_wall
setblock ~4~16~15 minecraft:sandstone
fill ~4~17~15 ~4~27~15 minecraft:sandstone
setblock ~4~28~15 minecraft:sandstone
setblock ~4~29~15 minecraft:cobblestone_wall
setblock ~4~30~15 minecraft:sandstone
fill ~4~31~15 ~4~41~15 minecraft:sandstone
setblock ~4~42~15 minecraft:sandstone
setblock ~4~43~15 minecraft:cobblestone_wall
setblock ~4~44~15 minecraft:sandstone
fill ~4~45~15 ~4~56~15 minecraft:sandstone
setblock ~4~57~15 minecraft:sandstone
setblock ~4~58~15 minecraft:cobblestone_wall
setblock ~4~59~15 minecraft:sandstone
fill ~4~60~15 ~4~70~15 minecraft:sandstone
setblock ~4~95~15 minecraft:torch
setblock ~7~110~15 minecraft:sandstone
setblock ~7~111~15 minecraft:sandstone
setblock ~7~112~15 minecraft:sandstone
setblock ~11~129~15 minecraft:torch
fill ~12~125~15 ~14~125~15 minecraft:dirt
fill ~12~126~15 ~14~128~15 minecraft:polished_basalt
setblock ~15~129~15 minecraft:torch
setblock ~19~110~15 minecraft:sandstone
setblock ~19~111~15 minecraft:sandstone
setblock ~19~112~15 minecraft:sandstone
setblock ~22~2~15 minecraft:sandstone
fill ~22~3~15 ~22~13~15 minecraft:sandstone
setblock ~22~14~15 minecraft:sandstone
setblock ~22~15~15 minecraft:cobblestone_wall
setblock ~22~16~15 minecraft:sandstone
fill ~22~17~15 ~22~27~15 minecraft:sandstone
setblock ~22~28~15 minecraft:sandstone
setblock ~22~29~15 minecraft:cobblestone_wall
setblock ~22~30~15 minecraft:sandstone
fill ~22~31~15 ~22~41~15 minecraft:sandstone
setblock ~22~42~15 minecraft:sandstone
setblock ~22~43~15 minecraft:cobblestone_wall
setblock ~22~44~15 minecraft:sandstone
fill ~22~45~15 ~22~56~15 minecraft:sandstone
setblock ~22~57~15 minecraft:sandstone
setblock ~22~58~15 minecraft:cobblestone_wall
setblock ~22~59~15 minecraft:sandstone
fill ~22~60~15 ~22~70~15 minecraft:sandstone
setblock ~22~95~15 minecraft:torch
setblock ~23~70~15 minecraft:sandstone
setblock ~23~72~15 minecraft:torch
fill ~23~92~15 ~23~94~15 minecraft:sandstone
setblock ~23~95~15 minecraft:sandstone
setblock ~23~99~15 minecraft:sandstone
setblock ~23~100~15 minecraft:sandstone
setblock ~23~101~15 minecraft:cobblestone_wall
setblock ~24~70~15 minecraft:trapdoor
setblock ~24~71~15 minecraft:glowstone
fill ~24~77~15 ~24~77~20 minecraft:planks
fill ~24~78~15 ~24~78~16 minecraft:glowstone
fill ~24~79~15 ~24~79~16 minecraft:stone
fill ~24~84~15 ~24~84~16 minecraft:quartz_block
setblock ~24~85~15 minecraft:coal_block
fill ~24~87~15 ~24~87~16 minecraft:stone
fill ~24~88~15 ~24~88~16 minecraft:glowstone
fill ~24~89~15 ~24~89~20 minecraft:planks
fill ~24~91~15 ~25~91~15 minecraft:sandstone
setblock ~25~72~15 minecraft:sandstone
setblock ~25~73~15 minecraft:sandstone
setblock ~25~74~15 minecraft:sandstone
setblock ~25~75~15 minecraft:stone_block_slab4
fill ~25~78~15 ~25~78~16 minecraft:trapdoor
fill ~25~88~15 ~25~88~16 minecraft:trapdoor
setblock ~25~90~15 minecraft:sandstone
setblock ~25~92~15 minecraft:stone_block_slab4
setblock ~1~75~16 minecraft:sandstone
fill ~1~90~16 ~1~91~16 minecraft:fence
setblock ~1~92~16 minecraft:sandstone
setblock ~2~71~16 minecraft:sandstone
fill ~2~72~16 ~2~74~16 minecraft:stripped_oak_log
setblock ~2~80~16 minecraft:gravel
setblock ~2~85~16 minecraft:quartz_block
setblock ~2~86~16 minecraft:gravel
fill ~2~90~16 ~2~91~16 minecraft:stripped_oak_log
setblock ~3~95~16 minecraft:stone_block_slab4
fill ~3~99~16 ~3~99~18 minecraft:polished_basalt
setblock ~4~2~16 minecraft:sandstone
setblock ~4~14~16 minecraft:stone_block_slab4
setblock ~4~15~16 minecraft:sandstone
setblock ~4~28~16 minecraft:stone_block_slab4
setblock ~4~29~16 minecraft:sandstone
setblock ~4~42~16 minecraft:stone_block_slab4
setblock ~4~43~16 minecraft:sandstone
setblock ~4~57~16 minecraft:stone_block_slab4
setblock ~4~58~16 minecraft:sandstone
setblock ~4~70~16 minecraft:sandstone
fill ~4~94~16 ~4~95~16 minecraft:stripped_oak_log
fill ~5~2~16 ~5~14~16 minecraft:stripped_oak_log
setblock ~5~15~16 minecraft:glowstone
fill ~5~16~16 ~5~28~16 minecraft:stripped_oak_log
setblock ~5~29~16 minecraft:glowstone
fill ~5~30~16 ~5~42~16 minecraft:stripped_oak_log
setblock ~5~43~16 minecraft:glowstone
fill ~5~44~16 ~5~57~16 minecraft:stripped_oak_log
setblock ~5~58~16 minecraft:glowstone
fill ~5~59~16 ~5~69~16 minecraft:stripped_oak_log
setblock ~7~107~16 minecraft:sandstone
fill ~7~108~16 ~7~109~16 minecraft:sandstone
setblock ~7~110~16 minecraft:sandstone
fill ~7~111~16 ~7~112~16 minecraft:sandstone
setblock ~8~110~16 minecraft:torch
setblock ~10~126~16 minecraft:torch
fill ~11~122~16 ~15~122~16 minecraft:dirt
fill ~11~123~16 ~15~125~16 minecraft:polished_basalt
setblock ~16~126~16 minecraft:torch
setblock ~18~110~16 minecraft:torch
setblock ~19~107~16 minecraft:sandstone
fill ~19~108~16 ~19~109~16 minecraft:sandstone
setblock ~19~110~16 minecraft:sandstone
fill ~19~111~16 ~19~112~16 minecraft:sandstone
fill ~21~2~16 ~21~14~16 minecraft:stripped_oak_log
setblock ~21~15~16 minecraft:glowstone
fill ~21~16~16 ~21~28~16 minecraft:stripped_oak_log
setblock ~21~29~16 minecraft:glowstone
fill ~21~30~16 ~21~42~16 minecraft:stripped_oak_log
setblock ~21~43~16 minecraft:glowstone
fill ~21~44~16 ~21~57~16 minecraft:stripped_oak_log
setblock ~21~58~16 minecraft:glowstone
fill ~21~59~16 ~21~69~16 minecraft:stripped_oak_log
setblock ~22~2~16 minecraft:sandstone
setblock ~22~14~16 minecraft:stone_block_slab4
setblock ~22~15~16 minecraft:sandstone
setblock ~22~28~16 minecraft:stone_block_slab4
setblock ~22~29~16 minecraft:sandstone
setblock ~22~42~16 minecraft:stone_block_slab4
setblock ~22~43~16 minecraft:sandstone
setblock ~22~57~16 minecraft:stone_block_slab4
setblock ~22~58~16 minecraft:sandstone
setblock ~22~70~16 minecraft:sandstone
fill ~22~94~16 ~22~95~16 minecraft:stripped_oak_log
setblock ~23~95~16 minecraft:stone_block_slab4
fill ~23~99~16 ~23~99~18 minecraft:polished_basalt
setblock ~24~71~16 minecraft:sandstone
fill ~24~72~16 ~24~74~16 minecraft:stripped_oak_log
setblock ~24~80~16 minecraft:gravel
setblock ~24~85~16 minecraft:quartz_block
setblock ~24~86~16 minecraft:coal_block
fill ~24~90~16 ~24~91~16 minecraft:stripped_oak_log
setblock ~25~75~16 minecraft:sandstone
fill ~25~90~16 ~25~91~16 minecraft:fence
setblock ~25~92~16 minecraft:sandstone
setblock ~1~72~17 minecraft:sandstone
setblock ~1~73~17 minecraft:sandstone
setblock ~1~74~17 minecraft:sandstone
setblock ~1~75~17 minecraft:stone_block_slab4
setblock ~1~79~17 minecraft:trapdoor
setblock ~1~87~17 minecraft:trapdoor
fill ~1~90~17 ~1~91~17 minecraft:sandstone
setblock ~1~92~17 minecraft:stone_block_slab4
setblock ~2~70~17 minecraft:trapdoor
setblock ~2~71~17 minecraft:glowstone
fill ~2~78~17 ~2~78~20 minecraft:planks
setblock ~2~79~17 minecraft:glowstone
fill ~2~80~17 ~2~81~17 minecraft:stone
setblock ~2~82~17 minecraft:gravel
setblock ~2~84~17 minecraft:gravel
fill ~2~85~17 ~2~86~17 minecraft:stone
setblock ~2~87~17 minecraft:glowstone
fill ~2~88~17 ~2~88~20 minecraft:planks
setblock ~2~91~17 minecraft:sandstone
setblock ~3~70~17 minecraft:sandstone
fill ~3~92~17 ~3~94~17 minecraft:sandstone
setblock ~3~95~17 minecraft:sandstone
setblock ~4~2~17 minecraft:sandstone
fill ~4~3~17 ~4~13~17 minecraft:sandstone
setblock ~4~14~17 minecraft:sandstone
setblock ~4~15~17 minecraft:cobblestone_wall
setblock ~4~16~17 minecraft:sandstone
fill ~4~17~17 ~4~27~17 minecraft:sandstone
setblock ~4~28~17 minecraft:sandstone
setblock ~4~29~17 minecraft:cobblestone_wall
setblock ~4~30~17 minecraft:sandstone
fill ~4~31~17 ~4~41~17 minecraft:sandstone
setblock ~4~42~17 minecraft:sandstone
setblock ~4~43~17 minecraft:cobblestone_wall
setblock ~4~44~17 minecraft:sandstone
fill ~4~45~17 ~4~56~17 minecraft:sandstone
setblock ~4~57~17 minecraft:sandstone
setblock ~4~58~17 minecraft:cobblestone_wall
setblock ~4~59~17 minecraft:sandstone
fill ~4~60~17 ~4~70~17 minecraft:sandstone
setblock ~4~95~17 minecraft:torch
setblock ~4~102~17 minecraft:sandstone
setblock ~4~103~17 minecraft:sandstone
setblock ~4~104~17 minecraft:cobblestone_wall
setblock ~7~110~17 minecraft:sandstone
setblock ~7~111~17 minecraft:sandstone
setblock ~7~112~17 minecraft:sandstone
fill ~8~111~17 ~8~112~18 minecraft:stripped_oak_log
setblock ~9~123~17 minecraft:torch
fill ~10~119~17 ~16~119~17 minecraft:dirt
fill ~10~120~17 ~16~122~17 minecraft:polished_basalt
setblock ~17~123~17 minecraft:torch
fill ~18~111~17 ~18~112~18 minecraft:stripped_oak_log
setblock ~19~110~17 minecraft:sandstone
setblock ~19~111~17 minecraft:sandstone
setblock ~19~112~17 minecraft:sandstone
setblock ~22~2~17 minecraft:sandstone
fill ~22~3~17 ~22~13~17 minecraft:sandstone
setblock ~22~14~17 minecraft:sandstone
setblock ~22~15~17 minecraft:cobblestone_wall
setblock ~22~16~17 minecraft:sandstone
fill ~22~17~17 ~22~27~17 minecraft:sandstone
setblock ~22~28~17 minecraft:sandstone
setblock ~22~29~17 minecraft:cobblestone_wall
setblock ~22~30~17 minecraft:sandstone
fill ~22~31~17 ~22~41~17 minecraft:sandstone
setblock ~22~42~17 minecraft:sandstone
setblock ~22~43~17 minecraft:cobblestone_wall
setblock ~22~44~17 minecraft:sandstone
fill ~22~45~17 ~22~56~17 minecraft:sandstone
setblock ~22~57~17 minecraft:sandstone
setblock ~22~58~17 minecraft:cobblestone_wall
setblock ~22~59~17 minecraft:sandstone
fill ~22~60~17 ~22~70~17 minecraft:sandstone
setblock ~22~95~17 minecraft:torch
setblock ~22~102~17 minecraft:sandstone
setblock ~22~103~17 minecraft:sandstone
setblock ~22~104~17 minecraft:cobblestone_wall
setblock ~23~70~17 minecraft:sandstone
fill ~23~92~17 ~23~94~17 minecraft:sandstone
setblock ~23~95~17 minecraft:sandstone
setblock ~24~70~17 minecraft:trapdoor
setblock ~24~71~17 minecraft:glowstone
fill ~24~78~17 ~24~78~20 minecraft:planks
setblock ~24~79~17 minecraft:glowstone
fill ~24~80~17 ~24~81~17 minecraft:stone
setblock ~24~82~17 minecraft:gravel
setblock ~24~84~17 minecraft:gravel
fill ~24~85~17 ~24~86~17 minecraft:stone
setblock ~24~87~17 minecraft:glowstone
fill ~24~88~17 ~24~88~20 minecraft:planks
fill ~24~91~17 ~25~91~17 minecraft:sandstone
setblock ~25~72~17 minecraft:sandstone
setblock ~25~73~17 minecraft:sandstone
setblock ~25~74~17 minecraft:sandstone
setblock ~25~75~17 minecraft:stone_block_slab4
setblock ~25~79~17 minecraft:trapdoor
setblock ~25~87~17 minecraft:trapdoor
setblock ~25~90~17 minecraft:sandstone
setblock ~25~92~17 minecraft:stone_block_slab4
setblock ~1~75~18 minecraft:sandstone
fill ~1~80~18 ~1~81~18 minecraft:trapdoor
fill ~1~85~18 ~1~86~18 minecraft:trapdoor
fill ~1~90~18 ~1~91~18 minecraft:fence
setblock ~1~92~18 minecraft:sandstone
setblock ~2~71~18 minecraft:sandstone
fill ~2~72~18 ~2~74~18 minecraft:stripped_oak_log
fill ~2~79~18 ~2~79~20 minecraft:planks
fill ~2~80~18 ~2~81~18 minecraft:glowstone
fill ~2~82~18 ~2~84~18 minecraft:stone
fill ~2~85~18 ~2~86~18 minecraft:glowstone
fill ~2~87~18 ~2~87~20 minecraft:planks
fill ~2~90~18 ~2~91~18 minecraft:stripped_oak_log
setblock ~3~95~18 minecraft:stone_block_slab4
setblock ~4~2~18 minecraft:sandstone
setblock ~4~14~18 minecraft:stone_block_slab4
setblock ~4~15~18 minecraft:sandstone
setblock ~4~28~18 minecraft:stone_block_slab4
setblock ~4~29~18 minecraft:sandstone
setblock ~4~42~18 minecraft:stone_block_slab4
setblock ~4~43~18 minecraft:sandstone
setblock ~4~57~18 minecraft:stone_block_slab4
setblock ~4~58~18 minecraft:sandstone
setblock ~4~70~18 minecraft:sandstone
fill ~4~94~18 ~4~95~18 minecraft:stripped_oak_log
fill ~4~102~18 ~4~102~22 minecraft:polished_basalt
fill ~5~2~18 ~5~14~18 minecraft:stripped_oak_log
setblock ~5~15~18 minecraft:glowstone
fill ~5~16~18 ~5~28~18 minecraft:stripped_oak_log
setblock ~5~29~18 minecraft:glowstone
fill ~5~30~18 ~5~42~18 minecraft:stripped_oak_log
setblock ~5~43~18 minecraft:glowstone
fill ~5~44~18 ~5~57~18 minecraft:stripped_oak_log
setblock ~5~58~18 minecraft:glowstone
fill ~5~59~18 ~5~69~18 minecraft:stripped_oak_log
setblock ~7~110~18 minecraft:sandstone
setblock ~7~111~18 minecraft:sandstone
setblock ~7~112~18 minecraft:sandstone
setblock ~8~120~18 minecraft:torch
fill ~9~111~18 ~9~112~18 minecraft:stripped_oak_log
fill ~9~116~18 ~17~116~18 minecraft:dirt
fill ~9~117~18 ~17~119~18 minecraft:polished_basalt
setblock ~10~110~18 minecraft:torch
fill ~11~111~18 ~12~112~18 minecraft:stripped_oak_log
setblock ~13~110~18 minecraft:torch
fill ~14~111~18 ~15~112~18 minecraft:stripped_oak_log
setblock ~16~110~18 minecraft:torch
fill ~17~111~18 ~17~112~18 minecraft:stripped_oak_log
setblock ~18~120~18 minecraft:torch
setblock ~19~110~18 minecraft:sandstone
setblock ~19~111~18 minecraft:sandstone
setblock ~19~112~18 minecraft:sandstone
fill ~21~2~18 ~21~14~18 minecraft:stripped_oak_log
setblock ~21~15~18 minecraft:glowstone
fill ~21~16~18 ~21~28~18 minecraft:stripped_oak_log
setblock ~21~29~18 minecraft:glowstone
fill ~21~30~18 ~21~42~18 minecraft:stripped_oak_log
setblock ~21~43~18 minecraft:glowstone
fill ~21~44~18 ~21~57~18 minecraft:stripped_oak_log
setblock ~21~58~18 minecraft:glowstone
fill ~21~59~18 ~21~69~18 minecraft:stripped_oak_log
setblock ~22~2~18 minecraft:sandstone
setblock ~22~14~18 minecraft:stone_block_slab4
setblock ~22~15~18 minecraft:sandstone
setblock ~22~28~18 minecraft:stone_block_slab4
setblock ~22~29~18 minecraft:sandstone
setblock ~22~42~18 minecraft:stone_block_slab4
setblock ~22~43~18 minecraft:sandstone
setblock ~22~57~18 minecraft:stone_block_slab4
setblock ~22~58~18 minecraft:sandstone
setblock ~22~70~18 minecraft:sandstone
fill ~22~94~18 ~22~95~18 minecraft:stripped_oak_log
fill ~22~102~18 ~22~102~22 minecraft:polished_basalt
setblock ~23~95~18 minecraft:stone_block_slab4
setblock ~24~71~18 minecraft:sandstone
fill ~24~72~18 ~24~74~18 minecraft:stripped_oak_log
fill ~24~79~18 ~24~79~20 minecraft:planks
fill ~24~80~18 ~24~81~18 minecraft:glowstone
fill ~24~82~18 ~24~84~18 minecraft:stone
fill ~24~85~18 ~24~86~18 minecraft:glowstone
fill ~24~87~18 ~24~87~20 minecraft:planks
fill ~24~90~18 ~24~91~18 minecraft:stripped_oak_log
setblock ~25~75~18 minecraft:sandstone
fill ~25~80~18 ~25~81~18 minecraft:trapdoor
fill ~25~85~18 ~25~86~18 minecraft:trapdoor
fill ~25~90~18 ~25~91~18 minecraft:fence
setblock ~25~92~18 minecraft:sandstone
setblock ~1~72~19 minecraft:sandstone
setblock ~1~73~19 minecraft:sandstone
setblock ~1~74~19 minecraft:sandstone
setblock ~1~75~19 minecraft:stone_block_slab4
fill ~1~82~19 ~1~84~19 minecraft:trapdoor
fill ~1~90~19 ~1~91~19 minecraft:sandstone
setblock ~1~92~19 minecraft:stone_block_slab4
setblock ~2~70~19 minecraft:trapdoor
setblock ~2~71~19 minecraft:glowstone
fill ~2~80~19 ~2~81~20 minecraft:planks
fill ~2~82~19 ~2~84~19 minecraft:glowstone
fill ~2~85~19 ~2~86~20 minecraft:planks
setblock ~2~91~19 minecraft:sandstone
setblock ~3~1~19 minecraft:sandstone
setblock ~3~70~19 minecraft:sandstone
setblock ~3~72~19 minecraft:torch
fill ~3~92~19 ~3~94~19 minecraft:sandstone
setblock ~3~95~19 minecraft:sandstone
setblock ~3~99~19 minecraft:sandstone
setblock ~3~100~19 minecraft:sandstone
setblock ~3~101~19 minecraft:cobblestone_wall
setblock ~4~2~19 minecraft:sandstone
fill ~4~3~19 ~4~13~19 minecraft:sandstone
setblock ~4~14~19 minecraft:sandstone
setblock ~4~15~19 minecraft:cobblestone_wall
setblock ~4~16~19 minecraft:sandstone
fill ~4~17~19 ~4~27~19 minecraft:sandstone
setblock ~4~28~19 minecraft:sandstone
setblock ~4~29~19 minecraft:cobblestone_wall
setblock ~4~30~19 minecraft:sandstone
fill ~4~31~19 ~4~41~19 minecraft:sandstone
setblock ~4~42~19 minecraft:sandstone
setblock ~4~43~19 minecraft:cobblestone_wall
setblock ~4~44~19 minecraft:sandstone
fill ~4~45~19 ~4~56~19 minecraft:sandstone
setblock ~4~57~19 minecraft:sandstone
setblock ~4~58~19 minecraft:cobblestone_wall
setblock ~4~59~19 minecraft:sandstone
fill ~4~60~19 ~4~70~19 minecraft:sandstone
setblock ~4~95~19 minecraft:torch
setblock ~7~107~19 minecraft:sandstone
fill ~7~108~19 ~7~109~19 minecraft:sandstone
setblock ~7~110~19 minecraft:sandstone
fill ~7~111~19 ~7~112~19 minecraft:sandstone
setblock ~7~117~19 minecraft:torch
fill ~8~106~19 ~18~106~21 minecraft:sandstone
setblock ~8~110~19 minecraft:sandstone
setblock ~8~111~19 minecraft:sandstone
setblock ~8~112~19 minecraft:sandstone
fill ~8~113~19 ~18~113~19 minecraft:sandstone
fill ~8~114~19 ~18~116~19 minecraft:polished_basalt
setblock ~9~110~19 minecraft:sandstone
setblock ~9~111~19 minecraft:sandstone
setblock ~9~112~19 minecraft:sandstone
setblock ~10~107~19 minecraft:sandstone
fill ~10~108~19 ~10~109~19 minecraft:sandstone
setblock ~10~110~19 minecraft:sandstone
fill ~10~111~19 ~10~112~19 minecraft:sandstone
setblock ~11~110~19 minecraft:sandstone
setblock ~11~111~19 minecraft:sandstone
setblock ~11~112~19 minecraft:sandstone
setblock ~12~110~19 minecraft:sandstone
setblock ~12~111~19 minecraft:sandstone
setblock ~12~112~19 minecraft:sandstone
setblock ~13~107~19 minecraft:sandstone
fill ~13~108~19 ~13~109~19 minecraft:sandstone
setblock ~13~110~19 minecraft:sandstone
fill ~13~111~19 ~13~112~19 minecraft:sandstone
setblock ~14~110~19 minecraft:sandstone
setblock ~14~111~19 minecraft:sandstone
setblock ~14~112~19 minecraft:sandstone
setblock ~15~110~19 minecraft:sandstone
setblock ~15~111~19 minecraft:sandstone
setblock ~15~112~19 minecraft:sandstone
setblock ~16~107~19 minecraft:sandstone
fill ~16~108~19 ~16~109~19 minecraft:sandstone
setblock ~16~110~19 minecraft:sandstone
fill ~16~111~19 ~16~112~19 minecraft:sandstone
setblock ~17~110~19 minecraft:sandstone
setblock ~17~111~19 minecraft:sandstone
setblock ~17~112~19 minecraft:sandstone
setblock ~18~110~19 minecraft:sandstone
setblock ~18~111~19 minecraft:sandstone
setblock ~18~112~19 minecraft:sandstone
setblock ~19~107~19 minecraft:sandstone
fill ~19~108~19 ~19~109~19 minecraft:sandstone
setblock ~19~110~19 minecraft:sandstone
fill ~19~111~19 ~19~112~19 minecraft:sandstone
setblock ~19~117~19 minecraft:torch
setblock ~22~2~19 minecraft:sandstone
fill ~22~3~19 ~22~13~19 minecraft:sandstone
setblock ~22~14~19 minecraft:sandstone
setblock ~22~15~19 minecraft:cobblestone_wall
fill ~22~16~19 ~22~16~20 minecraft:sandstone
fill ~22~17~19 ~22~27~19 minecraft:sandstone
setblock ~22~28~19 minecraft:sandstone
setblock ~22~29~19 minecraft:cobblestone_wall
setblock ~22~30~19 minecraft:sandstone
fill ~22~31~19 ~22~41~19 minecraft:sandstone
setblock ~22~42~19 minecraft:sandstone
setblock ~22~43~19 minecraft:cobblestone_wall
setblock ~22~44~19 minecraft:sandstone
fill ~22~45~19 ~22~56~19 minecraft:sandstone
setblock ~22~57~19 minecraft:sandstone
setblock ~22~58~19 minecraft:cobblestone_wall
setblock ~22~59~19 minecraft:sandstone
fill ~22~60~19 ~22~70~19 minecraft:sandstone
setblock ~22~95~19 minecraft:torch
setblock ~23~1~19 minecraft:sandstone
setblock ~23~70~19 minecraft:sandstone
setblock ~23~72~19 minecraft:torch
fill ~23~92~19 ~23~94~19 minecraft:sandstone
setblock ~23~95~19 minecraft:sandstone
setblock ~23~99~19 minecraft:sandstone
setblock ~23~100~19 minecraft:sandstone
setblock ~23~101~19 minecraft:cobblestone_wall
setblock ~24~70~19 minecraft:trapdoor
setblock ~24~71~19 minecraft:glowstone
fill ~24~80~19 ~24~81~20 minecraft:planks
fill ~24~82~19 ~24~84~19 minecraft:glowstone
fill ~24~85~19 ~24~86~20 minecraft:planks
fill ~24~91~19 ~25~91~19 minecraft:sandstone
setblock ~25~72~19 minecraft:sandstone
setblock ~25~73~19 minecraft:sandstone
setblock ~25~74~19 minecraft:sandstone
setblock ~25~75~19 minecraft:stone_block_slab4
fill ~25~82~19 ~25~84~19 minecraft:trapdoor
setblock ~25~90~19 minecraft:sandstone
setblock ~25~92~19 minecraft:stone_block_slab4
fill ~1~75~20 ~1~75~24 minecraft:sandstone
fill ~1~90~20 ~1~91~20 minecraft:fence
setblock ~1~92~20 minecraft:sandstone
fill ~2~71~20 ~2~71~21 minecraft:sandstone
fill ~2~72~20 ~2~74~20 minecraft:stripped_oak_log
fill ~2~82~20 ~2~84~20 minecraft:planks
fill ~2~90~20 ~2~91~20 minecraft:stripped_oak_log
fill ~3~1~20 ~3~2~21 minecraft:sandstone
fill ~3~3~20 ~3~13~21 minecraft:sandstone
fill ~3~14~20 ~3~14~21 minecraft:sandstone
setblock ~3~15~20 minecraft:cobblestone_wall
fill ~3~16~20 ~3~16~21 minecraft:sandstone
fill ~3~17~20 ~3~27~21 minecraft:sandstone
fill ~3~28~20 ~3~28~21 minecraft:sandstone
setblock ~3~29~20 minecraft:cobblestone_wall
fill ~3~30~20 ~3~30~21 minecraft:sandstone
fill ~3~31~20 ~3~41~21 minecraft:sandstone
fill ~3~42~20 ~3~42~21 minecraft:sandstone
setblock ~3~43~20 minecraft:cobblestone_wall
fill ~3~44~20 ~3~44~21 minecraft:sandstone
fill ~3~45~20 ~3~56~21 minecraft:sandstone
fill ~3~57~20 ~3~57~21 minecraft:sandstone
setblock ~3~58~20 minecraft:cobblestone_wall
fill ~3~59~20 ~3~59~21 minecraft:sandstone
fill ~3~60~20 ~3~70~21 minecraft:sandstone
setblock ~3~95~20 minecraft:stone_block_slab4
fill ~3~99~20 ~3~99~23 minecraft:polished_basalt
fill ~4~15~20 ~4~15~21 minecraft:sandstone
fill ~4~29~20 ~4~29~21 minecraft:sandstone
fill ~4~43~20 ~4~43~21 minecraft:sandstone
fill ~4~58~20 ~4~58~21 minecraft:sandstone
fill ~4~94~20 ~4~95~20 minecraft:stripped_oak_log
fill ~7~113~20 ~19~113~20 minecraft:polished_basalt
setblock ~22~14~20 minecraft:sandstone
fill ~22~15~20 ~22~15~21 minecraft:sandstone
fill ~22~29~20 ~22~29~21 minecraft:sandstone
fill ~22~43~20 ~22~43~21 minecraft:sandstone
fill ~22~58~20 ~22~58~21 minecraft:sandstone
fill ~22~94~20 ~22~95~20 minecraft:stripped_oak_log
fill ~23~1~20 ~23~2~21 minecraft:sandstone
fill ~23~3~20 ~23~13~21 minecraft:sandstone
fill ~23~14~20 ~23~14~21 minecraft:sandstone
setblock ~23~15~20 minecraft:cobblestone_wall
fill ~23~16~20 ~23~16~21 minecraft:sandstone
fill ~23~17~20 ~23~27~21 minecraft:sandstone
fill ~23~28~20 ~23~28~21 minecraft:sandstone
setblock ~23~29~20 minecraft:cobblestone_wall
fill ~23~30~20 ~23~30~21 minecraft:sandstone
fill ~23~31~20 ~23~41~21 minecraft:sandstone
fill ~23~42~20 ~23~42~21 minecraft:sandstone
setblock ~23~43~20 minecraft:cobblestone_wall
fill ~23~44~20 ~23~44~21 minecraft:sandstone
fill ~23~45~20 ~23~56~21 minecraft:sandstone
fill ~23~57~20 ~23~57~21 minecraft:sandstone
setblock ~23~58~20 minecraft:cobblestone_wall
fill ~23~59~20 ~23~59~21 minecraft:sandstone
fill ~23~60~20 ~23~70~21 minecraft:sandstone
setblock ~23~95~20 minecraft:stone_block_slab4
fill ~23~99~20 ~23~99~23 minecraft:polished_basalt
fill ~24~71~20 ~24~71~21 minecraft:sandstone
fill ~24~72~20 ~24~74~20 minecraft:stripped_oak_log
fill ~24~82~20 ~24~84~20 minecraft:planks
fill ~24~90~20 ~24~91~20 minecraft:stripped_oak_log
fill ~25~75~20 ~25~75~24 minecraft:sandstone
fill ~25~90~20 ~25~91~20 minecraft:fence
setblock ~25~92~20 minecraft:sandstone
setblock ~1~72~21 minecraft:sandstone
setblock ~1~73~21 minecraft:sandstone
setblock ~1~74~21 minecraft:sandstone
setblock ~1~76~21 minecraft:sandstone
setblock ~1~77~21 minecraft:sandstone
fill ~1~78~21 ~1~79~21 minecraft:sandstone
setblock ~1~80~21 minecraft:sandstone
fill ~1~81~21 ~1~82~21 minecraft:sandstone
setblock ~1~83~21 minecraft:sandstone
fill ~1~84~21 ~1~85~21 minecraft:sandstone
setblock ~1~86~21 minecraft:sandstone
fill ~1~87~21 ~1~91~21 minecraft:sandstone
fill ~1~92~21 ~1~92~24 minecraft:stone_block_slab4
setblock ~2~91~21 minecraft:sandstone
setblock ~3~15~21 minecraft:cobblestone_wall
setblock ~3~29~21 minecraft:cobblestone_wall
setblock ~3~43~21 minecraft:cobblestone_wall
setblock ~3~58~21 minecraft:cobblestone_wall
fill ~3~92~21 ~3~95~21 minecraft:sandstone
fill ~6~91~21 ~20~91~22 minecraft:planks
fill ~6~102~21 ~20~102~21 minecraft:dirt
fill ~6~103~21 ~20~105~21 minecraft:polished_basalt
fill ~8~2~21 ~8~14~21 minecraft:stripped_oak_log
setblock ~8~15~21 minecraft:glowstone
fill ~8~16~21 ~8~28~21 minecraft:stripped_oak_log
setblock ~8~29~21 minecraft:glowstone
fill ~8~30~21 ~8~42~21 minecraft:stripped_oak_log
setblock ~8~43~21 minecraft:glowstone
fill ~8~44~21 ~8~57~21 minecraft:stripped_oak_log
setblock ~8~58~21 minecraft:glowstone
fill ~8~59~21 ~8~69~21 minecraft:stripped_oak_log
fill ~10~2~21 ~10~14~21 minecraft:stripped_oak_log
setblock ~10~15~21 minecraft:glowstone
fill ~10~16~21 ~10~28~21 minecraft:stripped_oak_log
setblock ~10~29~21 minecraft:glowstone
fill ~10~30~21 ~10~42~21 minecraft:stripped_oak_log
setblock ~10~43~21 minecraft:glowstone
fill ~10~44~21 ~10~57~21 minecraft:stripped_oak_log
setblock ~10~58~21 minecraft:glowstone
fill ~10~59~21 ~10~69~21 minecraft:stripped_oak_log
fill ~12~2~21 ~12~14~21 minecraft:stripped_oak_log
setblock ~12~15~21 minecraft:glowstone
fill ~12~16~21 ~12~28~21 minecraft:stripped_oak_log
setblock ~12~29~21 minecraft:glowstone
fill ~12~30~21 ~12~42~21 minecraft:stripped_oak_log
setblock ~12~43~21 minecraft:glowstone
fill ~12~44~21 ~12~57~21 minecraft:stripped_oak_log
setblock ~12~58~21 minecraft:glowstone
fill ~12~59~21 ~12~69~21 minecraft:stripped_oak_log
fill ~14~2~21 ~14~14~21 minecraft:stripped_oak_log
setblock ~14~15~21 minecraft:glowstone
fill ~14~16~21 ~14~28~21 minecraft:stripped_oak_log
setblock ~14~29~21 minecraft:glowstone
fill ~14~30~21 ~14~42~21 minecraft:stripped_oak_log
setblock ~14~43~21 minecraft:glowstone
fill ~14~44~21 ~14~57~21 minecraft:stripped_oak_log
setblock ~14~58~21 minecraft:glowstone
fill ~14~59~21 ~14~69~21 minecraft:stripped_oak_log
fill ~16~2~21 ~16~14~21 minecraft:stripped_oak_log
setblock ~16~15~21 minecraft:glowstone
fill ~16~16~21 ~16~28~21 minecraft:stripped_oak_log
setblock ~16~29~21 minecraft:glowstone
fill ~16~30~21 ~16~42~21 minecraft:stripped_oak_log
setblock ~16~43~21 minecraft:glowstone
fill ~16~44~21 ~16~57~21 minecraft:stripped_oak_log
setblock ~16~58~21 minecraft:glowstone
fill ~16~59~21 ~16~69~21 minecraft:stripped_oak_log
fill ~18~2~21 ~18~14~21 minecraft:stripped_oak_log
setblock ~18~15~21 minecraft:glowstone
fill ~18~16~21 ~18~28~21 minecraft:stripped_oak_log
setblock ~18~29~21 minecraft:glowstone
fill ~18~30~21 ~18~42~21 minecraft:stripped_oak_log
setblock ~18~43~21 minecraft:glowstone
fill ~18~44~21 ~18~57~21 minecraft:stripped_oak_log
setblock ~18~58~21 minecraft:glowstone
fill ~18~59~21 ~18~69~21 minecraft:stripped_oak_log
setblock ~23~15~21 minecraft:cobblestone_wall
setblock ~23~29~21 minecraft:cobblestone_wall
setblock ~23~43~21 minecraft:cobblestone_wall
setblock ~23~58~21 minecraft:cobblestone_wall
fill ~23~92~21 ~23~95~21 minecraft:sandstone
fill ~24~91~21 ~25~91~21 minecraft:sandstone
setblock ~25~72~21 minecraft:sandstone
setblock ~25~73~21 minecraft:sandstone
setblock ~25~74~21 minecraft:sandstone
setblock ~25~76~21 minecraft:sandstone
setblock ~25~77~21 minecraft:sandstone
fill ~25~78~21 ~25~79~21 minecraft:sandstone
setblock ~25~80~21 minecraft:sandstone
fill ~25~81~21 ~25~82~21 minecraft:sandstone
setblock ~25~83~21 minecraft:sandstone
fill ~25~84~21 ~25~85~21 minecraft:sandstone
setblock ~25~86~21 minecraft:sandstone
fill ~25~87~21 ~25~90~21 minecraft:sandstone
fill ~25~92~21 ~25~92~24 minecraft:stone_block_slab4
fill ~1~72~22 ~1~73~22 minecraft:fence
fill ~1~74~22 ~1~74~23 minecraft:stone_block_slab4
fill ~1~76~22 ~1~77~22 minecraft:fence
fill ~1~78~22 ~1~78~23 minecraft:stone_block_slab4
fill ~1~79~22 ~1~80~22 minecraft:fence
fill ~1~81~22 ~1~81~23 minecraft:stone_block_slab4
fill ~1~82~22 ~1~83~22 minecraft:fence
fill ~1~84~22 ~1~84~23 minecraft:stone_block_slab4
fill ~1~85~22 ~1~86~22 minecraft:fence
