fill ~42~15~3 ~43~15~3 minecraft:fence 0
setblock ~42~16~3 minecraft:fence 0
setblock ~43~14~3 minecraft:fence 0
setblock ~43~17~3 minecraft:stone_button 2
setblock ~45~13~3 minecraft:stone_button 2
setblock ~45~15~3 minecraft:dispenser 2
setblock ~45~16~3 minecraft:trapdoor 3
setblock ~45~17~3 minecraft:stone_button 2
setblock ~47~13~3 minecraft:stone_button 2
fill ~47~14~3 ~47~15~3 minecraft:fence 0
setblock ~47~17~3 minecraft:stone_button 2
setblock ~49~13~3 minecraft:stone_button 2
setblock ~49~15~3 minecraft:dispenser 2
setblock ~49~16~3 minecraft:trapdoor 3
setblock ~49~17~3 minecraft:stone_button 2
setblock ~51~13~3 minecraft:stone_button 2
fill ~51~14~3 ~51~15~3 minecraft:fence 0
setblock ~51~17~3 minecraft:stone_button 2
setblock ~53~13~3 minecraft:stone_button 2
setblock ~53~15~3 minecraft:dispenser 2
setblock ~53~16~3 minecraft:trapdoor 3
setblock ~53~17~3 minecraft:stone_button 2
setblock ~55~13~3 minecraft:stone_button 2
fill ~55~14~3 ~55~15~3 minecraft:fence 0
setblock ~55~17~3 minecraft:stone_button 2
setblock ~57~13~3 minecraft:stone_button 2
setblock ~57~15~3 minecraft:dispenser 2
setblock ~57~16~3 minecraft:trapdoor 3
setblock ~57~17~3 minecraft:stone_button 2
fill ~57~20~3 ~65~20~3 minecraft:stone_button 2
setblock ~59~13~3 minecraft:stone_button 2
fill ~59~14~3 ~59~15~3 minecraft:fence 0
setblock ~59~17~3 minecraft:stone_button 2
setblock ~61~13~3 minecraft:stone_button 2
setblock ~61~15~3 minecraft:dispenser 2
setblock ~61~16~3 minecraft:trapdoor 3
setblock ~61~17~3 minecraft:stone_button 2
setblock ~63~13~3 minecraft:stone_button 2
fill ~63~14~3 ~63~15~3 minecraft:fence 0
setblock ~63~17~3 minecraft:stone_button 2
setblock ~65~13~3 minecraft:stone_button 2
setblock ~65~15~3 minecraft:dispenser 2
setblock ~65~16~3 minecraft:trapdoor 3
setblock ~65~17~3 minecraft:stone_button 2
setblock ~67~13~3 minecraft:stone_button 2
fill ~67~14~3 ~67~15~3 minecraft:fence 0
setblock ~67~17~3 minecraft:stone_button 2
setblock ~69~13~3 minecraft:stone_button 2
setblock ~69~15~3 minecraft:dispenser 2
setblock ~69~16~3 minecraft:trapdoor 3
setblock ~69~17~3 minecraft:stone_button 2
setblock ~71~13~3 minecraft:stone_button 2
fill ~71~14~3 ~71~15~3 minecraft:fence 0
setblock ~71~17~3 minecraft:stone_button 2
fill ~72~10~3 ~72~17~3 minecraft:ladder 2
setblock ~73~13~3 minecraft:stone_button 2
setblock ~73~15~3 minecraft:dispenser 2
setblock ~73~16~3 minecraft:trapdoor 3
setblock ~73~17~3 minecraft:stone_button 2
setblock ~75~14~3 minecraft:stone_button 2
fill ~75~15~3 ~77~16~3 minecraft:fence 0
fill ~75~17~3 ~76~17~3 minecraft:fence 0
setblock ~75~18~3 minecraft:stone_button 2
setblock ~77~14~3 minecraft:stone_button 2
setblock ~77~18~3 minecraft:stone_button 2
setblock ~79~14~3 minecraft:stone_button 2
setblock ~79~16~3 minecraft:dispenser 2
setblock ~79~17~3 minecraft:trapdoor 3
setblock ~79~18~3 minecraft:stone_button 2
setblock ~81~14~3 minecraft:stone_button 2
fill ~81~15~3 ~81~16~3 minecraft:fence 0
setblock ~81~18~3 minecraft:stone_button 2
setblock ~83~14~3 minecraft:stone_button 2
setblock ~83~16~3 minecraft:dispenser 2
setblock ~83~17~3 minecraft:trapdoor 3
setblock ~83~18~3 minecraft:stone_button 2
setblock ~27~18~4 minecraft:stone_button 2
setblock ~28~14~4 minecraft:stone_button 2
setblock ~28~16~4 minecraft:dispenser 2
setblock ~28~17~4 minecraft:trapdoor 3
setblock ~29~18~4 minecraft:stone_button 2
setblock ~30~14~4 minecraft:stone_button 2
fill ~30~15~4 ~30~16~4 minecraft:fence 0
setblock ~31~18~4 minecraft:stone_button 2
setblock ~32~14~4 minecraft:stone_button 2
setblock ~32~16~4 minecraft:dispenser 2
setblock ~32~17~4 minecraft:trapdoor 3
setblock ~33~18~4 minecraft:stone_button 2
setblock ~34~14~4 minecraft:stone_button 2
fill ~34~15~4 ~34~16~4 minecraft:fence 0
setblock ~35~18~4 minecraft:stone_button 2
setblock ~36~14~4 minecraft:stone_button 2
setblock ~36~16~4 minecraft:dispenser 2
setblock ~36~17~4 minecraft:trapdoor 3
setblock ~37~18~4 minecraft:stone_button 2
setblock ~38~14~4 minecraft:stone_button 2
fill ~38~15~4 ~38~16~4 minecraft:fence 0
setblock ~39~18~4 minecraft:stone_button 2
setblock ~40~14~4 minecraft:stone_button 2
setblock ~40~16~4 minecraft:dispenser 2
setblock ~40~17~4 minecraft:trapdoor 3
setblock ~41~18~4 minecraft:stone_button 2
setblock ~42~12~4 minecraft:fence 0
setblock ~42~13~4 minecraft:stone_button 2
setblock ~42~14~4 minecraft:oak_stairs 6
fill ~42~15~4 ~43~15~4 minecraft:planks 0
fill ~42~16~4 ~42~16~5 minecraft:planks 0
fill ~42~17~4 ~74~17~4 minecraft:log 0
fill ~42~18~4 ~74~18~4 minecraft:oak_stairs 2
fill ~42~21~4 ~44~21~4 minecraft:wall_sign 2
setblock ~43~12~4 minecraft:trapdoor 3
fill ~43~13~4 ~74~13~4 minecraft:log 0
fill ~43~14~4 ~43~14~25 minecraft:planks 0
setblock ~43~16~4 minecraft:glass
setblock ~44~12~4 minecraft:fence 0
fill ~44~14~4 ~46~14~4 minecraft:log 1
fill ~44~15~4 ~44~16~4 minecraft:log 1
setblock ~45~12~4 minecraft:oak_stairs 6
setblock ~45~15~4 minecraft:lever 5
fill ~45~16~4 ~46~16~4 minecraft:log 1
setblock ~46~12~4 minecraft:fence 0
setblock ~46~15~4 minecraft:log 1
setblock ~46~20~4 minecraft:stone_block_slab 0
setblock ~47~11~4 minecraft:dispenser 2
setblock ~47~12~4 minecraft:trapdoor 3
fill ~47~14~4 ~47~14~25 minecraft:planks 0
setblock ~47~15~4 minecraft:planks 0
setblock ~47~16~4 minecraft:glass
setblock ~48~12~4 minecraft:fence 0
fill ~48~14~4 ~50~14~4 minecraft:log 1
fill ~48~15~4 ~48~16~4 minecraft:log 1
setblock ~49~12~4 minecraft:oak_stairs 6
setblock ~49~15~4 minecraft:lever 6
fill ~49~16~4 ~50~16~4 minecraft:log 1
setblock ~50~12~4 minecraft:fence 0
setblock ~50~15~4 minecraft:log 1
setblock ~50~20~4 minecraft:stone_block_slab 0
setblock ~51~11~4 minecraft:dispenser 2
setblock ~51~12~4 minecraft:trapdoor 3
setblock ~51~14~4 minecraft:double_stone_block_slab 0
setblock ~51~15~4 minecraft:planks 0
setblock ~51~16~4 minecraft:glass
setblock ~52~12~4 minecraft:fence 0
fill ~52~14~4 ~54~14~4 minecraft:log 1
fill ~52~15~4 ~52~16~4 minecraft:log 1
setblock ~53~12~4 minecraft:oak_stairs 6
setblock ~53~15~4 minecraft:lever 5
fill ~53~16~4 ~54~16~4 minecraft:log 1
setblock ~54~12~4 minecraft:fence 0
setblock ~54~15~4 minecraft:log 1
setblock ~54~20~4 minecraft:stone_block_slab 0
setblock ~55~11~4 minecraft:dispenser 2
setblock ~55~12~4 minecraft:trapdoor 3
fill ~55~14~4 ~55~14~25 minecraft:planks 0
setblock ~55~15~4 minecraft:planks 0
setblock ~55~16~4 minecraft:glass
setblock ~56~12~4 minecraft:fence 0
fill ~56~14~4 ~58~14~4 minecraft:log 1
fill ~56~15~4 ~56~16~4 minecraft:log 1
setblock ~56~20~4 minecraft:stone_button 4
setblock ~57~12~4 minecraft:oak_stairs 6
setblock ~57~15~4 minecraft:lever 6
fill ~57~16~4 ~58~16~4 minecraft:log 1
setblock ~57~19~4 minecraft:lever 4
fill ~57~20~4 ~65~20~4 minecraft:log 1
fill ~57~21~4 ~65~21~5 minecraft:fence 0
fill ~57~22~4 ~65~24~4 minecraft:fence 0
setblock ~58~12~4 minecraft:fence 0
setblock ~58~15~4 minecraft:log 1
setblock ~59~11~4 minecraft:dispenser 2
setblock ~59~12~4 minecraft:trapdoor 3
fill ~59~14~4 ~59~14~25 minecraft:planks 0
setblock ~59~15~4 minecraft:planks 0
setblock ~59~16~4 minecraft:glass
fill ~59~19~4 ~61~19~4 minecraft:lever 4
setblock ~60~12~4 minecraft:fence 0
fill ~60~14~4 ~62~14~4 minecraft:log 1
fill ~60~15~4 ~60~16~4 minecraft:log 1
setblock ~61~12~4 minecraft:oak_stairs 6
setblock ~61~15~4 minecraft:lever 6
fill ~61~16~4 ~62~16~4 minecraft:log 1
setblock ~62~12~4 minecraft:fence 0
setblock ~62~15~4 minecraft:log 1
setblock ~63~11~4 minecraft:dispenser 2
setblock ~63~12~4 minecraft:trapdoor 3
fill ~63~14~4 ~63~14~25 minecraft:planks 0
setblock ~63~15~4 minecraft:planks 0
setblock ~63~16~4 minecraft:glass
fill ~63~19~4 ~65~19~4 minecraft:lever 4
setblock ~64~12~4 minecraft:fence 0
fill ~64~14~4 ~66~14~4 minecraft:log 1
fill ~64~15~4 ~64~16~4 minecraft:log 1
setblock ~65~12~4 minecraft:oak_stairs 6
setblock ~65~15~4 minecraft:lever 5
fill ~65~16~4 ~66~16~4 minecraft:log 1
setblock ~66~12~4 minecraft:fence 0
setblock ~66~15~4 minecraft:log 1
setblock ~66~20~4 minecraft:stone_button 5
setblock ~67~11~4 minecraft:dispenser 2
setblock ~67~12~4 minecraft:trapdoor 3
fill ~67~14~4 ~67~14~25 minecraft:planks 0
setblock ~67~15~4 minecraft:planks 0
setblock ~67~16~4 minecraft:glass
setblock ~68~12~4 minecraft:fence 0
fill ~68~14~4 ~70~14~4 minecraft:log 1
fill ~68~15~4 ~68~16~4 minecraft:log 1
setblock ~69~12~4 minecraft:oak_stairs 6
setblock ~69~15~4 minecraft:lever 6
fill ~69~16~4 ~70~16~4 minecraft:log 1
setblock ~70~12~4 minecraft:fence 0
setblock ~70~15~4 minecraft:log 1
setblock ~70~20~4 minecraft:stone_block_slab 0
setblock ~71~11~4 minecraft:dispenser 2
setblock ~71~12~4 minecraft:trapdoor 3
fill ~71~14~4 ~71~14~25 minecraft:planks 0
setblock ~71~15~4 minecraft:planks 0
setblock ~71~16~4 minecraft:glass
fill ~72~9~4 ~72~12~4 minecraft:log 1
fill ~72~14~4 ~74~14~4 minecraft:log 1
fill ~72~15~4 ~72~16~4 minecraft:log 1
setblock ~72~19~4 minecraft:ladder 2
setblock ~73~12~4 minecraft:oak_stairs 6
setblock ~73~15~4 minecraft:lever 6
fill ~73~16~4 ~74~16~4 minecraft:log 1
fill ~73~21~4 ~74~21~4 minecraft:wall_sign 2
setblock ~74~15~4 minecraft:log 1
setblock ~74~20~4 minecraft:stone_block_slab 0
setblock ~75~11~4 minecraft:dispenser 2
setblock ~75~12~4 minecraft:trapdoor 3
fill ~75~13~4 ~77~13~4 minecraft:oak_stairs 6
fill ~75~14~4 ~84~14~4 minecraft:log 0
fill ~75~15~4 ~77~15~17 minecraft:planks 0
fill ~75~16~4 ~77~16~4 minecraft:planks 0
fill ~75~17~4 ~76~17~4 minecraft:planks 0
fill ~75~18~4 ~84~18~4 minecraft:log 0
fill ~75~19~4 ~84~19~4 minecraft:oak_stairs 2
fill ~75~22~4 ~85~22~4 minecraft:wall_sign 2
setblock ~77~11~4 minecraft:fence 0
setblock ~77~17~4 minecraft:glass
setblock ~78~13~4 minecraft:fence 0
fill ~78~15~4 ~80~15~4 minecraft:log 1
fill ~78~16~4 ~78~17~4 minecraft:log 1
setblock ~78~21~4 minecraft:stone_block_slab 0
setblock ~79~12~4 minecraft:dispenser 2
setblock ~79~13~4 minecraft:trapdoor 3
setblock ~79~16~4 minecraft:lever 5
fill ~79~17~4 ~80~17~4 minecraft:log 1
setblock ~80~13~4 minecraft:fence 0
setblock ~80~16~4 minecraft:log 1
setblock ~81~11~4 minecraft:fence 0
setblock ~81~13~4 minecraft:oak_stairs 6
fill ~81~15~4 ~81~15~8 minecraft:planks 0
setblock ~81~16~4 minecraft:planks 0
setblock ~81~17~4 minecraft:glass
setblock ~82~13~4 minecraft:fence 0
fill ~82~15~4 ~84~15~4 minecraft:log 1
fill ~82~16~4 ~82~17~4 minecraft:log 1
setblock ~82~21~4 minecraft:stone_block_slab 0
fill ~82~23~4 ~87~23~4 minecraft:stone_button 2
setblock ~83~12~4 minecraft:dispenser 2
setblock ~83~13~4 minecraft:trapdoor 3
setblock ~83~16~4 minecraft:lever 6
fill ~83~17~4 ~84~17~4 minecraft:log 1
fill ~84~13~4 ~85~13~4 minecraft:fence 0
setblock ~84~16~4 minecraft:log 1
setblock ~85~14~4 minecraft:stone_button 2
fill ~85~15~4 ~85~17~4 minecraft:fence 0
setblock ~85~18~4 minecraft:stone_button 2
setblock ~86~16~4 minecraft:fence 0
setblock ~86~18~4 minecraft:fence 0
setblock ~87~15~4 minecraft:stone_button 2
setblock ~87~19~4 minecraft:stone_button 2
setblock ~88~17~4 minecraft:dispenser 2
setblock ~88~18~4 minecraft:trapdoor 3
setblock ~89~15~4 minecraft:stone_button 2
setblock ~89~19~4 minecraft:stone_button 2
fill ~90~16~4 ~90~18~4 minecraft:fence 0
setblock ~91~19~4 minecraft:stone_button 2
setblock ~20~45~5 minecraft:oak_stairs 6
fill ~20~46~5 ~20~48~5 minecraft:planks 0
setblock ~20~49~5 minecraft:oak_stairs 2
fill ~21~23~5 ~28~23~5 minecraft:stone_button 2
fill ~21~45~5 ~24~46~5 minecraft:fence 0
fill ~21~47~5 ~55~47~5 minecraft:planks 0
fill ~21~48~5 ~24~49~5 minecraft:fence 0
setblock ~23~19~5 minecraft:stone_button 2
fill ~25~16~5 ~26~17~5 minecraft:fence 0
setblock ~25~18~5 minecraft:fence 0
setblock ~25~19~5 minecraft:stone_button 2
setblock ~25~45~5 minecraft:oak_stairs 6
setblock ~25~46~5 minecraft:planks 0
setblock ~25~48~5 minecraft:planks 0
setblock ~25~49~5 minecraft:oak_stairs 2
setblock ~26~15~5 minecraft:stone_button 2
fill ~27~13~5 ~28~13~5 minecraft:oak_stairs 6
fill ~27~14~5 ~41~14~5 minecraft:log 0
fill ~27~15~5 ~29~15~5 minecraft:log 1
fill ~27~16~5 ~27~17~5 minecraft:log 1
fill ~27~18~5 ~41~18~5 minecraft:log 0
fill ~27~19~5 ~41~19~5 minecraft:oak_stairs 2
fill ~27~22~5 ~40~22~5 minecraft:wall_sign 2
setblock ~28~16~5 minecraft:lever 6
fill ~28~17~5 ~29~17~5 minecraft:log 1
setblock ~29~13~5 minecraft:fence 0
setblock ~29~16~5 minecraft:log 1
setblock ~30~12~5 minecraft:dispenser 2
setblock ~30~13~5 minecraft:trapdoor 3
fill ~30~15~5 ~30~15~25 minecraft:planks 0
setblock ~30~16~5 minecraft:planks 0
setblock ~30~17~5 minecraft:glass
setblock ~30~21~5 minecraft:stone_block_slab 0
setblock ~31~13~5 minecraft:fence 0
fill ~31~15~5 ~33~15~5 minecraft:log 1
fill ~31~16~5 ~31~17~5 minecraft:log 1
setblock ~32~11~5 minecraft:fence 0
setblock ~32~13~5 minecraft:oak_stairs 6
setblock ~32~16~5 minecraft:lever 6
fill ~32~17~5 ~33~17~5 minecraft:log 1
setblock ~33~13~5 minecraft:fence 0
setblock ~33~16~5 minecraft:log 1
setblock ~34~12~5 minecraft:dispenser 2
setblock ~34~13~5 minecraft:trapdoor 3
fill ~34~15~5 ~34~15~25 minecraft:planks 0
setblock ~34~16~5 minecraft:planks 0
setblock ~34~17~5 minecraft:glass
setblock ~34~21~5 minecraft:stone_block_slab 0
setblock ~35~13~5 minecraft:fence 0
fill ~35~15~5 ~37~15~5 minecraft:log 1
fill ~35~16~5 ~35~17~5 minecraft:log 1
setblock ~36~11~5 minecraft:fence 0
setblock ~36~13~5 minecraft:oak_stairs 6
setblock ~36~16~5 minecraft:lever 5
fill ~36~17~5 ~37~17~5 minecraft:log 1
setblock ~37~13~5 minecraft:fence 0
setblock ~37~16~5 minecraft:log 1
setblock ~38~12~5 minecraft:dispenser 2
setblock ~38~13~5 minecraft:trapdoor 3
fill ~38~15~5 ~38~15~25 minecraft:planks 0
setblock ~38~16~5 minecraft:planks 0
setblock ~38~17~5 minecraft:glass
setblock ~38~21~5 minecraft:stone_block_slab 0
setblock ~39~13~5 minecraft:fence 0
fill ~39~15~5 ~41~15~5 minecraft:log 1
fill ~39~16~5 ~39~17~5 minecraft:log 1
fill ~40~11~5 ~40~12~5 minecraft:fence 0
fill ~40~13~5 ~41~13~5 minecraft:oak_stairs 6
setblock ~40~16~5 minecraft:lever 5
fill ~40~17~5 ~41~17~5 minecraft:log 1
setblock ~41~12~5 minecraft:fence 0
setblock ~41~16~5 minecraft:log 1
setblock ~41~21~5 minecraft:wall_sign 4
fill ~42~12~5 ~44~12~5 minecraft:log 1
setblock ~42~13~5 minecraft:log 0
fill ~42~14~5 ~42~15~5 minecraft:planks 0
fill ~42~18~5 ~74~18~5 minecraft:planks 0
setblock ~42~19~5 minecraft:glass_pane
fill ~42~20~5 ~71~20~5 minecraft:wool 3
fill ~42~21~5 ~44~21~5 minecraft:log 0
fill ~42~22~5 ~73~22~5 minecraft:stone_block_slab 0
setblock ~43~11~5 minecraft:dispenser 2
setblock ~43~13~5 minecraft:planks 0
fill ~43~15~5 ~43~15~25 minecraft:stone_block_slab 0
fill ~43~19~5 ~45~19~5 minecraft:wool 3
setblock ~44~11~5 minecraft:log 1
fill ~44~14~5 ~46~14~25 minecraft:planks 0
setblock ~44~15~5 minecraft:chest 3
setblock ~45~10~5 minecraft:oak_stairs 6
setblock ~45~11~5 minecraft:glass
setblock ~45~12~5 minecraft:planks 0
fill ~45~21~5 ~56~21~5 minecraft:fence 0
fill ~46~11~5 ~46~12~5 minecraft:log 1
setblock ~46~19~5 minecraft:glass_pane
setblock ~47~10~5 minecraft:stone_block_slab 5
setblock ~47~11~5 minecraft:redstone_wire 0
fill ~47~12~5 ~48~12~5 minecraft:log 1
fill ~47~15~5 ~48~15~5 minecraft:chest 3
fill ~47~19~5 ~49~19~5 minecraft:wool 3
setblock ~48~11~5 minecraft:log 1
fill ~48~14~5 ~54~14~25 minecraft:planks 0
setblock ~49~10~5 minecraft:oak_stairs 6
setblock ~49~11~5 minecraft:glass
setblock ~49~12~5 minecraft:planks 0
fill ~50~11~5 ~50~12~5 minecraft:log 1
setblock ~50~19~5 minecraft:glass_pane
setblock ~51~10~5 minecraft:stone_block_slab 5
setblock ~51~11~5 minecraft:redstone_wire 0
fill ~51~12~5 ~52~12~5 minecraft:log 1
fill ~51~15~5 ~52~15~5 minecraft:chest 3
fill ~51~19~5 ~53~19~5 minecraft:wool 3
setblock ~52~11~5 minecraft:log 1
setblock ~53~10~5 minecraft:oak_stairs 6
setblock ~53~11~5 minecraft:glass
setblock ~53~12~5 minecraft:planks 0
fill ~54~11~5 ~54~12~5 minecraft:log 1
setblock ~54~19~5 minecraft:glass_pane
setblock ~55~10~5 minecraft:stone_block_slab 5
setblock ~55~11~5 minecraft:redstone_wire 0
fill ~55~12~5 ~56~12~5 minecraft:log 1
fill ~55~15~5 ~56~15~5 minecraft:chest 3
fill ~55~19~5 ~57~19~5 minecraft:wool 3
setblock ~56~11~5 minecraft:log 1
fill ~56~14~5 ~58~14~14 minecraft:planks 0
setblock ~56~44~5 minecraft:oak_stairs 6
fill ~56~45~5 ~56~49~5 minecraft:double_wooden_slab 0
setblock ~56~50~5 minecraft:oak_stairs 2
setblock ~57~10~5 minecraft:oak_stairs 6
setblock ~57~11~5 minecraft:glass
setblock ~57~12~5 minecraft:planks 0
fill ~57~24~5 ~64~27~5 minecraft:fence 0
fill ~57~45~5 ~60~49~5 minecraft:fence 0
fill ~58~11~5 ~58~12~5 minecraft:log 1
setblock ~58~19~5 minecraft:glass_pane
setblock ~59~10~5 minecraft:stone_block_slab 5
setblock ~59~11~5 minecraft:redstone_wire 0
fill ~59~12~5 ~60~12~5 minecraft:log 1
fill ~59~15~5 ~60~15~5 minecraft:chest 3
fill ~59~19~5 ~61~19~5 minecraft:wool 3
setblock ~60~11~5 minecraft:log 1
fill ~60~14~5 ~62~14~25 minecraft:planks 0
setblock ~61~10~5 minecraft:oak_stairs 6
setblock ~61~11~5 minecraft:glass
setblock ~61~12~5 minecraft:planks 0
setblock ~61~44~5 minecraft:oak_stairs 6
fill ~61~45~5 ~61~49~5 minecraft:double_wooden_slab 0
setblock ~61~50~5 minecraft:oak_stairs 2
fill ~62~11~5 ~62~12~5 minecraft:log 1
setblock ~62~19~5 minecraft:glass_pane
fill ~62~47~5 ~82~47~5 minecraft:planks 0
setblock ~63~10~5 minecraft:stone_block_slab 5
setblock ~63~11~5 minecraft:redstone_wire 0
fill ~63~12~5 ~64~12~5 minecraft:log 1
fill ~63~15~5 ~64~15~5 minecraft:chest 3
fill ~63~19~5 ~65~19~5 minecraft:wool 3
setblock ~64~11~5 minecraft:log 1
fill ~64~14~5 ~66~14~25 minecraft:planks 0
setblock ~65~10~5 minecraft:oak_stairs 6
setblock ~65~11~5 minecraft:glass
setblock ~65~12~5 minecraft:planks 0
fill ~66~11~5 ~66~12~5 minecraft:log 1
setblock ~66~19~5 minecraft:glass_pane
fill ~66~21~5 ~71~21~5 minecraft:fence 0
setblock ~67~10~5 minecraft:stone_block_slab 5
setblock ~67~11~5 minecraft:redstone_wire 0
fill ~67~12~5 ~68~12~5 minecraft:log 1
fill ~67~15~5 ~68~15~5 minecraft:chest 3
fill ~67~19~5 ~69~19~5 minecraft:wool 3
setblock ~68~11~5 minecraft:log 1
fill ~68~14~5 ~70~14~25 minecraft:planks 0
setblock ~69~10~5 minecraft:oak_stairs 6
setblock ~69~11~5 minecraft:glass
setblock ~69~12~5 minecraft:planks 0
fill ~70~11~5 ~70~12~5 minecraft:log 1
setblock ~70~19~5 minecraft:glass_pane
setblock ~71~10~5 minecraft:stone_block_slab 5
setblock ~71~11~5 minecraft:redstone_wire 0
fill ~71~12~5 ~72~12~5 minecraft:log 1
fill ~71~15~5 ~72~15~5 minecraft:chest 3
fill ~71~19~5 ~73~19~5 minecraft:wool 3
setblock ~72~11~5 minecraft:log 1
fill ~72~14~5 ~74~14~25 minecraft:planks 0
setblock ~72~20~5 minecraft:trapdoor 1
setblock ~73~10~5 minecraft:oak_stairs 6
setblock ~73~11~5 minecraft:glass
setblock ~73~12~5 minecraft:planks 0
fill ~73~20~5 ~77~20~5 minecraft:wool 3
fill ~73~21~5 ~74~21~5 minecraft:log 0
fill ~74~11~5 ~74~12~5 minecraft:log 1
fill ~74~15~5 ~74~15~25 minecraft:stone_block_slab 0
setblock ~74~19~5 minecraft:glass_pane
setblock ~74~22~5 minecraft:double_stone_block_slab 0
setblock ~75~10~5 minecraft:stone_block_slab 5
setblock ~75~11~5 minecraft:redstone_wire 0
fill ~75~12~5 ~76~12~5 minecraft:log 1
fill ~75~13~5 ~77~13~5 minecraft:planks 0
setblock ~75~14~5 minecraft:oak_stairs 5
fill ~75~19~5 ~85~19~12 minecraft:planks 0
fill ~75~21~5 ~85~21~5 minecraft:wool 3
fill ~75~22~5 ~85~22~5 minecraft:log 0
setblock ~75~23~5 minecraft:stone_block_slab 0
setblock ~76~11~5 minecraft:log 1
setblock ~76~18~5 minecraft:oak_stairs 7
setblock ~76~23~5 minecraft:double_stone_block_slab 0
setblock ~77~10~5 minecraft:oak_stairs 6
setblock ~77~11~5 minecraft:planks 0
setblock ~77~12~5 minecraft:glass
fill ~78~11~5 ~80~11~5 minecraft:log 1
fill ~78~12~5 ~78~13~5 minecraft:log 1
fill ~78~15~5 ~80~15~8 minecraft:planks 0
setblock ~78~18~5 minecraft:oak_stairs 7
setblock ~78~20~5 minecraft:glass_pane
setblock ~79~12~5 minecraft:lever 6
fill ~79~13~5 ~80~13~5 minecraft:log 1
fill ~79~20~5 ~81~20~5 minecraft:wool 3
setblock ~80~12~5 minecraft:log 1
setblock ~80~18~5 minecraft:oak_stairs 7
fill ~81~10~5 ~84~10~5 minecraft:oak_stairs 6
setblock ~81~11~5 minecraft:planks 0
setblock ~81~12~5 minecraft:glass
setblock ~81~13~5 minecraft:planks 0
fill ~82~11~5 ~84~11~5 minecraft:log 1
fill ~82~12~5 ~82~13~5 minecraft:log 1
fill ~82~15~5 ~85~15~8 minecraft:planks 0
setblock ~82~18~5 minecraft:oak_stairs 7
setblock ~82~20~5 minecraft:glass_pane
fill ~82~23~5 ~87~23~5 minecraft:log 1
fill ~82~24~5 ~87~26~5 minecraft:fence 0
setblock ~82~45~5 minecraft:oak_stairs 6
setblock ~82~46~5 minecraft:planks 0
setblock ~82~48~5 minecraft:double_wooden_slab 0
setblock ~82~49~5 minecraft:oak_stairs 2
setblock ~83~12~5 minecraft:lever 6
fill ~83~13~5 ~84~13~5 minecraft:log 1
fill ~83~20~5 ~85~20~5 minecraft:wool 3
fill ~83~45~5 ~85~49~5 minecraft:fence 0
setblock ~84~12~5 minecraft:log 1
setblock ~84~18~5 minecraft:oak_stairs 4
setblock ~85~11~5 minecraft:oak_stairs 6
setblock ~85~12~5 minecraft:glass
setblock ~85~13~5 minecraft:planks 0
setblock ~85~14~5 minecraft:log 0
fill ~85~16~5 ~86~16~5 minecraft:planks 0
fill ~85~17~5 ~85~17~6 minecraft:planks 0
setblock ~85~18~5 minecraft:log 0
fill ~86~14~5 ~90~14~5 minecraft:oak_stairs 6
fill ~86~15~5 ~90~15~5 minecraft:log 0
setblock ~86~17~5 minecraft:glass
setblock ~86~18~5 minecraft:planks 0
fill ~86~19~5 ~91~19~5 minecraft:log 0
fill ~86~20~5 ~91~20~5 minecraft:oak_stairs 2
fill ~86~22~5 ~87~22~5 minecraft:lever 4
setblock ~86~45~5 minecraft:oak_stairs 6
fill ~86~46~5 ~86~47~5 minecraft:planks 0
setblock ~86~48~5 minecraft:double_wooden_slab 0
setblock ~86~49~5 minecraft:oak_stairs 2
setblock ~87~12~5 minecraft:dispenser 2
setblock ~87~13~5 minecraft:trapdoor 3
fill ~87~16~5 ~89~16~5 minecraft:log 1
fill ~87~17~5 ~87~18~5 minecraft:log 1
setblock ~88~17~5 minecraft:lever 6
fill ~88~18~5 ~89~18~5 minecraft:log 1
setblock ~88~23~5 minecraft:stone_button 5
fill ~89~12~5 ~89~13~5 minecraft:fence 0
setblock ~89~17~5 minecraft:log 1
fill ~89~23~5 ~92~23~5 minecraft:wall_sign 2
fill ~90~16~5 ~90~18~5 minecraft:planks 0
setblock ~90~22~5 minecraft:stone_block_slab 0
fill ~91~15~5 ~96~15~5 minecraft:gold_block
setblock ~91~16~5 minecraft:gold_block
fill ~91~17~5 ~91~18~5 minecraft:planks 0
fill ~92~16~5 ~95~16~5 minecraft:fence 0
fill ~92~17~5 ~92~19~5 minecraft:gold_block
fill ~93~17~5 ~95~17~5 minecraft:stone_block_slab 0
fill ~93~19~5 ~97~19~5 minecraft:gold_block
fill ~96~16~5 ~96~18~5 minecraft:gold_block
setblock ~18~22~6 minecraft:stone_block_slab 0
fill ~18~47~6 ~19~47~6 minecraft:planks 0
setblock ~19~19~6 minecraft:stone_button 2
setblock ~20~23~6 minecraft:stone_button 4
setblock ~20~43~6 minecraft:oak_stairs 6
setblock ~20~44~6 minecraft:planks 0
fill ~20~45~6 ~86~49~6 minecraft:wool 0
setblock ~20~50~6 minecraft:planks 0
setblock ~20~51~6 minecraft:oak_stairs 2
setblock ~21~19~6 minecraft:stone_button 2
fill ~21~22~6 ~26~22~6 minecraft:lever 4
fill ~21~23~6 ~28~23~6 minecraft:log 1
fill ~21~24~6 ~28~26~6 minecraft:fence 0
fill ~21~43~6 ~24~44~6 minecraft:fence 0
fill ~21~50~6 ~24~51~6 minecraft:fence 0
setblock ~23~18~6 minecraft:oak_stairs 4
fill ~23~19~6 ~26~19~6 minecraft:log 0
fill ~23~20~6 ~26~20~6 minecraft:oak_stairs 2
setblock ~24~15~6 minecraft:stone_button 2
setblock ~24~16~6 minecraft:oak_stairs 4
fill ~24~17~6 ~26~17~6 minecraft:planks 0
fill ~24~18~6 ~25~18~6 minecraft:planks 0
setblock ~25~14~6 minecraft:oak_stairs 4
fill ~25~15~6 ~26~15~6 minecraft:log 0
fill ~25~16~6 ~26~16~8 minecraft:planks 0
setblock ~25~43~6 minecraft:oak_stairs 6
setblock ~25~44~6 minecraft:planks 0
setblock ~25~50~6 minecraft:planks 0
setblock ~25~51~6 minecraft:oak_stairs 2
setblock ~26~13~6 minecraft:oak_stairs 4
setblock ~26~14~6 minecraft:planks 0
setblock ~26~18~6 minecraft:glass
setblock ~27~12~6 minecraft:oak_stairs 6
fill ~27~13~6 ~28~13~6 minecraft:planks 0
setblock ~27~14~6 minecraft:log 0
fill ~27~15~6 ~29~15~23 minecraft:planks 0
fill ~27~19~6 ~74~19~6 minecraft:planks 0
fill ~27~20~6 ~29~21~6 minecraft:wool 3
fill ~27~22~6 ~40~22~6 minecraft:log 0
setblock ~28~11~6 minecraft:oak_stairs 6
setblock ~28~12~6 minecraft:glass
fill ~29~10~6 ~41~10~6 minecraft:oak_stairs 6
fill ~29~11~6 ~31~11~6 minecraft:log 1
fill ~29~12~6 ~29~13~6 minecraft:log 1
setblock ~29~18~6 minecraft:oak_stairs 7
setblock ~29~23~6 minecraft:double_stone_block_slab 0
setblock ~30~12~6 minecraft:lever 6
fill ~30~13~6 ~31~13~6 minecraft:log 1
setblock ~30~20~6 minecraft:glass_pane
fill ~30~21~6 ~41~21~6 minecraft:wool 3
fill ~30~23~6 ~40~23~6 minecraft:stone_block_slab 0
setblock ~31~12~6 minecraft:log 1
fill ~31~15~6 ~33~15~24 minecraft:planks 0
setblock ~31~18~6 minecraft:oak_stairs 7
fill ~31~20~6 ~33~20~6 minecraft:wool 3
setblock ~32~11~6 minecraft:planks 0
setblock ~32~12~6 minecraft:glass
setblock ~32~13~6 minecraft:planks 0
fill ~33~11~6 ~35~11~6 minecraft:log 1
fill ~33~12~6 ~33~13~6 minecraft:log 1
setblock ~33~18~6 minecraft:oak_stairs 7
setblock ~34~12~6 minecraft:lever 5
fill ~34~13~6 ~35~13~6 minecraft:log 1
setblock ~34~20~6 minecraft:glass_pane
setblock ~35~12~6 minecraft:log 1
fill ~35~15~6 ~37~15~24 minecraft:planks 0
setblock ~35~18~6 minecraft:oak_stairs 7
fill ~35~20~6 ~37~20~6 minecraft:wool 3
setblock ~36~11~6 minecraft:planks 0
setblock ~36~12~6 minecraft:glass
setblock ~36~13~6 minecraft:planks 0
fill ~37~11~6 ~39~11~6 minecraft:log 1
fill ~37~12~6 ~37~13~6 minecraft:log 1
setblock ~37~18~6 minecraft:oak_stairs 7
setblock ~38~12~6 minecraft:lever 6
fill ~38~13~6 ~39~13~6 minecraft:log 1
setblock ~38~20~6 minecraft:glass_pane
setblock ~39~12~6 minecraft:log 1
fill ~39~15~6 ~42~15~24 minecraft:planks 0
setblock ~39~18~6 minecraft:oak_stairs 7
fill ~39~20~6 ~41~20~6 minecraft:wool 3
fill ~40~11~6 ~40~13~6 minecraft:planks 0
setblock ~41~11~6 minecraft:glass
fill ~41~12~6 ~41~13~6 minecraft:planks 0
setblock ~41~18~6 minecraft:oak_stairs 7
setblock ~41~22~6 minecraft:double_stone_block_slab 0
fill ~42~10~6 ~44~10~6 minecraft:log 1
fill ~42~11~6 ~42~12~6 minecraft:log 1
setblock ~42~14~6 minecraft:oak_stairs 4
fill ~42~21~6 ~44~21~6 minecraft:trapdoor 2
setblock ~43~11~6 minecraft:lever 5
setblock ~43~18~6 minecraft:oak_stairs 7
setblock ~45~10~6 minecraft:planks 0
setblock ~45~18~6 minecraft:oak_stairs 7
fill ~46~10~6 ~48~10~6 minecraft:log 1
setblock ~47~11~6 minecraft:lever 6
setblock ~47~18~6 minecraft:oak_stairs 7
setblock ~49~10~6 minecraft:planks 0
setblock ~49~18~6 minecraft:oak_stairs 7
fill ~50~10~6 ~52~10~6 minecraft:log 1
setblock ~51~11~6 minecraft:lever 6
setblock ~51~18~6 minecraft:oak_stairs 7
setblock ~53~10~6 minecraft:planks 0
setblock ~53~18~6 minecraft:oak_stairs 7
fill ~54~10~6 ~56~10~6 minecraft:log 1
setblock ~55~11~6 minecraft:lever 5
setblock ~55~18~6 minecraft:oak_stairs 7
setblock ~56~43~6 minecraft:oak_stairs 6
setblock ~56~44~6 minecraft:double_wooden_slab 0
setblock ~56~50~6 minecraft:double_wooden_slab 0
setblock ~56~51~6 minecraft:oak_stairs 2
setblock ~57~10~6 minecraft:planks 0
setblock ~57~18~6 minecraft:oak_stairs 7
fill ~57~27~6 ~63~30~6 minecraft:fence 0
fill ~57~43~6 ~60~44~6 minecraft:fence 0
fill ~57~50~6 ~60~51~6 minecraft:fence 0
fill ~58~10~6 ~60~10~6 minecraft:log 1
setblock ~59~11~6 minecraft:lever 5
setblock ~59~18~6 minecraft:oak_stairs 7
setblock ~61~10~6 minecraft:planks 0
setblock ~61~18~6 minecraft:oak_stairs 7
setblock ~61~43~6 minecraft:oak_stairs 6
setblock ~61~44~6 minecraft:double_wooden_slab 0
setblock ~61~50~6 minecraft:double_wooden_slab 0
setblock ~61~51~6 minecraft:oak_stairs 2
fill ~62~10~6 ~64~10~6 minecraft:log 1
setblock ~63~11~6 minecraft:lever 5
setblock ~63~18~6 minecraft:oak_stairs 7
setblock ~65~10~6 minecraft:planks 0
setblock ~65~18~6 minecraft:oak_stairs 7
fill ~66~10~6 ~68~10~6 minecraft:log 1
setblock ~67~11~6 minecraft:lever 5
setblock ~67~18~6 minecraft:oak_stairs 7
setblock ~69~10~6 minecraft:planks 0
setblock ~69~18~6 minecraft:oak_stairs 7
fill ~70~10~6 ~72~10~6 minecraft:log 1
setblock ~71~11~6 minecraft:lever 6
setblock ~71~18~6 minecraft:oak_stairs 7
setblock ~73~10~6 minecraft:planks 0
setblock ~73~18~6 minecraft:oak_stairs 7
fill ~73~21~6 ~74~21~6 minecraft:stone_button 3
fill ~74~10~6 ~76~10~6 minecraft:log 1
setblock ~75~11~6 minecraft:lever 5
fill ~75~22~6 ~79~22~6 minecraft:trapdoor 2
setblock ~77~10~6 minecraft:planks 0
fill ~77~23~6 ~85~23~6 minecraft:wool 3
fill ~77~24~6 ~97~24~6 minecraft:stone_block_slab 0
fill ~78~10~6 ~80~10~6 minecraft:log 1
fill ~80~20~6 ~80~22~10 minecraft:planks 0
fill ~81~10~6 ~85~10~6 minecraft:planks 0
fill ~81~21~6 ~81~22~6 minecraft:stone_block_slab 0
fill ~82~26~6 ~87~29~6 minecraft:fence 0
setblock ~82~43~6 minecraft:oak_stairs 6
setblock ~82~44~6 minecraft:planks 0
setblock ~82~50~6 minecraft:double_wooden_slab 0
setblock ~82~51~6 minecraft:oak_stairs 2
fill ~83~20~6 ~84~20~6 minecraft:bookshelf
setblock ~83~22~6 minecraft:fence 0
fill ~83~43~6 ~85~44~6 minecraft:fence 0
fill ~83~50~6 ~85~51~6 minecraft:fence 0
setblock ~84~16~6 minecraft:oak_stairs 0
fill ~84~21~6 ~84~22~6 minecraft:bookshelf
setblock ~85~11~6 minecraft:planks 0
setblock ~85~14~6 minecraft:oak_stairs 7
setblock ~85~16~6 minecraft:planks 0
fill ~85~18~6 ~85~18~8 minecraft:planks 0
fill ~85~20~6 ~92~20~6 minecraft:planks 0
fill ~85~21~6 ~85~22~12 minecraft:planks 0
fill ~86~10~6 ~91~10~6 minecraft:fence 0
fill ~86~12~6 ~86~13~6 minecraft:log 1
fill ~86~14~6 ~90~15~6 minecraft:planks 0
fill ~86~18~6 ~92~18~6 minecraft:oak_stairs 7
fill ~86~19~6 ~96~19~7 minecraft:planks 0
setblock ~86~21~6 minecraft:glass
fill ~86~22~6 ~92~22~6 minecraft:wool 3
fill ~86~23~6 ~92~23~6 minecraft:log 0
setblock ~86~43~6 minecraft:oak_stairs 6
setblock ~86~44~6 minecraft:planks 0
setblock ~86~50~6 minecraft:double_wooden_slab 0
setblock ~86~51~6 minecraft:oak_stairs 2
setblock ~87~11~6 minecraft:stone_block_slab 5
setblock ~87~12~6 minecraft:lever 5
fill ~87~13~6 ~88~13~6 minecraft:log 1
fill ~87~21~6 ~89~21~6 minecraft:wool 3
fill ~87~47~6 ~88~47~6 minecraft:planks 0
setblock ~88~12~6 minecraft:log 1
fill ~89~11~6 ~90~11~6 minecraft:oak_stairs 6
fill ~89~12~6 ~90~13~6 minecraft:planks 0
setblock ~89~26~6 minecraft:stone_block_slab 0
setblock ~90~21~6 minecraft:glass_pane
fill ~91~12~6 ~91~14~6 minecraft:gold_block
fill ~91~15~6 ~96~15~23 minecraft:planks 0
fill ~91~21~6 ~92~21~6 minecraft:wool 3
fill ~92~14~6 ~94~14~6 minecraft:wool 3
setblock ~92~26~6 minecraft:stone_block_slab 0
fill ~93~20~6 ~93~23~6 minecraft:gold_block
fill ~94~20~6 ~95~20~6 minecraft:fence 0
fill ~94~21~6 ~95~21~6 minecraft:stone_block_slab 0
fill ~94~23~6 ~97~23~6 minecraft:gold_block
setblock ~95~14~6 minecraft:gold_block
setblock ~96~14~6 minecraft:wool 3
fill ~96~20~6 ~96~22~6 minecraft:gold_block
fill ~97~15~6 ~99~15~6 minecraft:gold_block
fill ~97~16~6 ~99~16~6 minecraft:fence 0
fill ~97~17~6 ~99~17~6 minecraft:stone_block_slab 0
fill ~97~19~6 ~100~19~6 minecraft:gold_block
fill ~97~20~6 ~100~20~6 minecraft:fence 0
fill ~97~21~6 ~100~21~6 minecraft:stone_block_slab 0
fill ~16~22~7 ~26~22~7 minecraft:wool 3
fill ~16~23~7 ~17~23~7 minecraft:stone_block_slab 0
setblock ~17~19~7 minecraft:stone_button 2
setblock ~17~20~7 minecraft:oak_stairs 4
setblock ~17~21~7 minecraft:wool 3
setblock ~17~47~7 minecraft:planks 0
fill ~18~20~7 ~36~20~7 minecraft:planks 0
setblock ~18~21~7 minecraft:glass_pane
fill ~18~23~7 ~27~23~7 minecraft:log 0
fill ~18~24~7 ~21~24~7 minecraft:fence 0
setblock ~18~25~7 minecraft:torch 5
fill ~18~45~7 ~19~49~7 minecraft:wool 0
setblock ~19~18~7 minecraft:oak_stairs 4
fill ~19~19~7 ~23~19~7 minecraft:log 0
fill ~19~21~7 ~21~21~7 minecraft:wool 3
setblock ~20~17~7 minecraft:oak_stairs 4
fill ~20~18~7 ~20~18~8 minecraft:planks 0
setblock ~20~42~7 minecraft:oak_stairs 6
fill ~20~43~7 ~86~44~7 minecraft:wool 0
fill ~20~50~7 ~86~51~7 minecraft:wool 0
setblock ~20~52~7 minecraft:oak_stairs 2
setblock ~21~16~7 minecraft:oak_stairs 4
fill ~21~17~7 ~21~17~8 minecraft:planks 0
setblock ~21~18~7 minecraft:log 0
fill ~21~26~7 ~27~29~7 minecraft:fence 0
fill ~21~42~7 ~24~42~7 minecraft:fence 0
fill ~21~52~7 ~24~52~7 minecraft:fence 0
setblock ~22~15~7 minecraft:oak_stairs 4
fill ~22~16~7 ~22~16~14 minecraft:planks 0
setblock ~22~17~7 minecraft:log 0
fill ~22~18~7 ~23~18~7 minecraft:planks 0
setblock ~22~21~7 minecraft:glass_pane
setblock ~23~14~7 minecraft:oak_stairs 4
fill ~23~15~7 ~23~15~8 minecraft:planks 0
setblock ~23~16~7 minecraft:log 0
setblock ~23~17~7 minecraft:planks 0
fill ~23~21~7 ~25~21~7 minecraft:wool 3
setblock ~24~13~7 minecraft:oak_stairs 4
fill ~24~14~7 ~25~14~7 minecraft:planks 0
setblock ~24~15~7 minecraft:log 0
fill ~24~16~7 ~24~16~24 minecraft:planks 0
fill ~24~19~7 ~25~19~22 minecraft:planks 0
setblock ~25~12~7 minecraft:oak_stairs 4
fill ~25~13~7 ~26~13~7 minecraft:planks 0
setblock ~25~42~7 minecraft:oak_stairs 6
setblock ~25~52~7 minecraft:oak_stairs 2
setblock ~26~11~7 minecraft:oak_stairs 4
fill ~26~12~7 ~27~12~7 minecraft:planks 0
setblock ~26~15~7 minecraft:oak_stairs 4
fill ~26~21~7 ~27~21~7 minecraft:glass_pane
setblock ~27~10~7 minecraft:oak_stairs 4
fill ~27~11~7 ~29~11~7 minecraft:planks 0
setblock ~27~16~7 minecraft:oak_stairs 1
fill ~28~10~7 ~41~10~7 minecraft:planks 0
setblock ~28~22~7 minecraft:log 0
setblock ~28~23~7 minecraft:fence 0
setblock ~29~18~7 minecraft:oak_stairs 6
setblock ~29~21~7 minecraft:log 0
fill ~29~22~7 ~38~22~7 minecraft:wall_sign 3
setblock ~30~17~7 minecraft:lever 4
setblock ~30~21~7 minecraft:trapdoor 0
setblock ~31~18~7 minecraft:oak_stairs 6
setblock ~33~18~7 minecraft:oak_stairs 6
setblock ~35~18~7 minecraft:oak_stairs 6
setblock ~37~18~7 minecraft:oak_stairs 6
setblock ~37~20~7 minecraft:planks 1
fill ~38~20~7 ~40~20~7 minecraft:planks 0
setblock ~39~18~7 minecraft:oak_stairs 6
setblock ~40~22~7 minecraft:wall_sign 3
setblock ~41~18~7 minecraft:oak_stairs 6
fill ~41~20~7 ~41~20~8 minecraft:oak_stairs 1
fill ~42~7~7 ~85~7~7 minecraft:planks 0
fill ~42~8~7 ~85~8~7 minecraft:log 0
fill ~42~9~7 ~85~9~7 minecraft:log 1
fill ~42~19~7 ~74~19~7 minecraft:planks 0
setblock ~46~45~7 minecraft:glowstone
setblock ~50~15~7 minecraft:trapdoor 3
setblock ~54~15~7 minecraft:trapdoor 3
setblock ~56~42~7 minecraft:oak_stairs 6
setblock ~56~52~7 minecraft:oak_stairs 2
setblock ~57~27~7 minecraft:trapdoor 3
fill ~57~30~7 ~62~33~7 minecraft:fence 0
fill ~57~42~7 ~60~42~7 minecraft:fence 0
fill ~57~52~7 ~60~52~7 minecraft:fence 0
setblock ~60~15~7 minecraft:trapdoor 3
setblock ~61~42~7 minecraft:oak_stairs 6
setblock ~61~52~7 minecraft:oak_stairs 2
setblock ~64~15~7 minecraft:trapdoor 3
setblock ~70~15~7 minecraft:trapdoor 3
setblock ~74~45~7 minecraft:glowstone
setblock ~75~14~7 minecraft:oak_stairs 5
setblock ~76~20~7 minecraft:trapdoor 1
setblock ~77~20~7 minecraft:log 0
setblock ~77~21~7 minecraft:fence 0
setblock ~78~21~7 minecraft:log 0
fill ~78~22~7 ~78~23~7 minecraft:fence 0
fill ~79~22~7 ~79~23~7 minecraft:log 0
setblock ~79~24~7 minecraft:fence 0
setblock ~79~25~7 minecraft:torch 5
fill ~80~23~7 ~96~23~7 minecraft:planks 0
setblock ~80~24~7 minecraft:double_stone_block_slab 0
fill ~81~24~7 ~93~24~7 minecraft:wool 3
fill ~81~25~7 ~82~25~7 minecraft:stone_block_slab 0
fill ~82~29~7 ~86~32~7 minecraft:fence 0
setblock ~82~42~7 minecraft:oak_stairs 6
setblock ~82~52~7 minecraft:oak_stairs 2
setblock ~83~25~7 minecraft:oak_stairs 0
fill ~83~42~7 ~85~42~7 minecraft:fence 0
fill ~83~52~7 ~85~52~7 minecraft:fence 0
setblock ~84~18~7 minecraft:oak_stairs 4
fill ~84~22~7 ~84~22~13 minecraft:fence 0
fill ~84~25~7 ~88~25~7 minecraft:wool 3
fill ~84~26~7 ~85~26~7 minecraft:stone_block_slab 0
fill ~85~10~7 ~91~10~7 minecraft:planks 0
setblock ~85~16~7 minecraft:wooden_door 2
fill ~85~20~7 ~85~20~12 minecraft:planks 0
fill ~86~11~7 ~88~11~7 minecraft:log 1
setblock ~86~14~7 minecraft:oak_stairs 7
fill ~86~15~7 ~90~15~24 minecraft:planks 0
fill ~86~18~7 ~92~18~7 minecraft:oak_stairs 6
fill ~86~20~7 ~87~20~7 minecraft:wool 0
fill ~86~22~7 ~86~22~9 minecraft:bookshelf
setblock ~86~26~7 minecraft:oak_stairs 0
setblock ~86~42~7 minecraft:oak_stairs 6
setblock ~86~52~7 minecraft:oak_stairs 2
fill ~87~26~7 ~94~26~7 minecraft:wool 3
fill ~87~27~7 ~88~27~7 minecraft:stone_block_slab 0
fill ~87~45~7 ~88~49~7 minecraft:wool 0
setblock ~88~14~7 minecraft:oak_stairs 7
fill ~88~20~7 ~88~20~9 minecraft:wall_sign 5
fill ~89~11~7 ~90~11~7 minecraft:planks 0
setblock ~89~25~7 minecraft:glass_pane
setblock ~89~27~7 minecraft:oak_stairs 0
setblock ~89~47~7 minecraft:planks 0
setblock ~90~12~7 minecraft:planks 0
setblock ~90~14~7 minecraft:oak_stairs 4
fill ~90~25~7 ~91~25~7 minecraft:wool 3
fill ~90~27~7 ~94~27~7 minecraft:wool 3
setblock ~90~28~7 minecraft:stone_block_slab 0
setblock ~91~11~7 minecraft:gold_block
fill ~91~12~7 ~93~12~7 minecraft:wool 3
fill ~91~13~7 ~91~14~23 minecraft:planks 0
fill ~91~28~7 ~95~28~7 minecraft:double_stone_block_slab 0
fill ~92~13~7 ~93~13~7 minecraft:wool 3
fill ~92~14~7 ~92~14~9 minecraft:web
fill ~92~20~7 ~92~22~7 minecraft:planks 0
setblock ~92~25~7 minecraft:glass_pane
setblock ~93~25~7 minecraft:wool 3
fill ~94~12~7 ~94~13~7 minecraft:gold_block
setblock ~94~14~7 minecraft:torch 3
fill ~94~18~7 ~95~18~7 minecraft:oak_stairs 6
fill ~94~24~7 ~94~25~7 minecraft:gold_block
fill ~95~12~7 ~96~13~7 minecraft:wool 3
fill ~95~24~7 ~97~24~7 minecraft:wool 3
fill ~95~25~7 ~96~25~7 minecraft:wool 3
fill ~95~26~7 ~95~27~7 minecraft:gold_block
setblock ~96~14~7 minecraft:torch 3
fill ~96~26~7 ~97~26~7 minecraft:wool 3
fill ~96~27~7 ~98~27~7 minecraft:gold_block
setblock ~96~28~7 minecraft:gold_block
setblock ~96~29~7 minecraft:stone_block_slab 0
setblock ~97~12~7 minecraft:gold_block
fill ~97~13~7 ~97~14~7 minecraft:wool 3
fill ~97~15~7 ~99~15~14 minecraft:planks 0
fill ~97~19~7 ~99~19~8 minecraft:planks 0
fill ~97~23~7 ~100~23~7 minecraft:gold_block
setblock ~97~25~7 minecraft:glass
setblock ~97~28~7 minecraft:wool 3
setblock ~97~29~7 minecraft:gold_block
fill ~97~32~7 ~99~32~7 minecraft:glass_pane
setblock ~98~12~7 minecraft:wool 3
setblock ~98~13~7 minecraft:gold_block
fill ~98~14~7 ~100~14~7 minecraft:wool 3
fill ~98~24~7 ~102~24~7 minecraft:stone_block_slab 0
setblock ~98~28~7 minecraft:stone_block_slab 0
setblock ~98~31~7 minecraft:stone_block_slab 8
setblock ~98~33~7 minecraft:stone_block_slab 0
setblock ~99~13~7 minecraft:wool 3
fill ~99~16~7 ~100~16~7 minecraft:fence 0
fill ~99~17~7 ~100~17~7 minecraft:stone_block_slab 0
fill ~100~15~7 ~101~15~7 minecraft:gold_block
fill ~100~19~7 ~102~19~7 minecraft:gold_block
fill ~100~20~7 ~101~20~7 minecraft:fence 0
setblock ~100~21~7 minecraft:stone_block_slab 0
fill ~101~16~7 ~101~18~7 minecraft:gold_block
setblock ~13~20~8 minecraft:stone_button 2
fill ~13~22~8 ~15~22~8 minecraft:wool 3
fill ~13~23~8 ~15~23~8 minecraft:stone_block_slab 0
fill ~14~21~8 ~16~21~8 minecraft:wool 3
setblock ~15~19~8 minecraft:stone_button 2
setblock ~15~20~8 minecraft:oak_stairs 4
setblock ~16~18~8 minecraft:oak_stairs 4
fill ~16~19~8 ~19~19~8 minecraft:log 0
fill ~16~20~8 ~18~20~8 minecraft:planks 0
fill ~16~22~8 ~16~23~8 minecraft:log 0
fill ~16~24~8 ~18~24~8 minecraft:fence 0
setblock ~16~47~8 minecraft:planks 0
setblock ~17~17~8 minecraft:oak_stairs 4
fill ~17~18~8 ~19~18~8 minecraft:planks 0
setblock ~17~23~8 minecraft:log 0
fill ~17~45~8 ~17~49~8 minecraft:wool 0
setblock ~18~16~8 minecraft:oak_stairs 4
fill ~18~17~8 ~20~17~8 minecraft:planks 0
fill ~18~23~8 ~19~23~8 minecraft:planks 0
fill ~18~43~8 ~20~44~8 minecraft:wool 0
fill ~18~50~8 ~20~50~8 minecraft:wool 0
fill ~18~51~8 ~19~51~8 minecraft:wool 0
setblock ~19~15~8 minecraft:oak_stairs 4
fill ~19~16~8 ~21~16~14 minecraft:planks 0
setblock ~19~20~8 minecraft:bed 1
setblock ~20~14~8 minecraft:oak_stairs 4
fill ~20~15~8 ~22~15~8 minecraft:planks 0
fill ~20~19~8 ~23~19~14 minecraft:planks 0
setblock ~20~23~8 minecraft:planks 1
setblock ~20~41~8 minecraft:oak_stairs 6
fill ~20~42~8 ~86~42~8 minecraft:wool 0
fill ~20~52~8 ~86~52~8 minecraft:wool 0
setblock ~20~53~8 minecraft:oak_stairs 2
setblock ~21~13~8 minecraft:oak_stairs 4
fill ~21~14~8 ~23~14~8 minecraft:planks 0
setblock ~21~18~8 minecraft:torch 3
setblock ~21~20~8 minecraft:wooden_door 0
fill ~21~23~8 ~24~23~8 minecraft:planks 0
fill ~21~29~8 ~26~32~8 minecraft:fence 0
fill ~21~41~8 ~24~41~8 minecraft:fence 0
fill ~21~53~8 ~24~53~8 minecraft:fence 0
setblock ~22~12~8 minecraft:oak_stairs 4
fill ~22~13~8 ~24~13~8 minecraft:planks 0
fill ~22~17~8 ~23~17~8 minecraft:chest 3
setblock ~22~20~8 minecraft:wooden_door 2
setblock ~23~11~8 minecraft:oak_stairs 4
fill ~23~12~8 ~25~12~8 minecraft:planks 0
fill ~23~16~8 ~23~16~22 minecraft:planks 0
setblock ~24~10~8 minecraft:oak_stairs 4
fill ~24~11~8 ~26~11~8 minecraft:planks 0
setblock ~24~20~8 minecraft:bed 3
fill ~25~10~8 ~27~10~8 minecraft:planks 0
setblock ~25~18~8 minecraft:lever 2
setblock ~25~20~8 minecraft:wooden_door 0
setblock ~25~23~8 minecraft:planks 1
setblock ~25~41~8 minecraft:oak_stairs 6
setblock ~25~53~8 minecraft:oak_stairs 2
fill ~26~17~8 ~30~19~8 minecraft:planks 0
fill ~26~23~8 ~26~23~12 minecraft:planks 0
fill ~27~16~8 ~30~16~8 minecraft:planks 0
fill ~27~20~8 ~35~20~8 minecraft:planks 0
fill ~27~22~8 ~27~22~9 minecraft:oak_stairs 4
fill ~27~23~8 ~27~23~9 minecraft:oak_stairs 1
fill ~28~8~8 ~41~8~8 minecraft:log 0
fill ~28~9~8 ~41~9~8 minecraft:log 1
fill ~28~21~8 ~28~21~9 minecraft:oak_stairs 4
fill ~28~22~8 ~28~22~9 minecraft:oak_stairs 1
fill ~29~7~8 ~41~7~8 minecraft:planks 0
fill ~29~21~8 ~29~21~9 minecraft:oak_stairs 1
setblock ~29~43~8 minecraft:glowstone
setblock ~31~16~8 minecraft:iron_door 1
fill ~31~18~8 ~41~19~8 minecraft:planks 0
fill ~32~16~8 ~41~17~8 minecraft:planks 0
setblock ~36~20~8 minecraft:planks 1
setblock ~37~20~8 minecraft:planks 0
setblock ~38~20~8 minecraft:planks 1
fill ~39~20~8 ~40~20~8 minecraft:planks 0
fill ~42~5~8 ~85~6~8 minecraft:planks 0
setblock ~42~8~8 minecraft:torch 3
fill ~42~9~8 ~84~9~8 minecraft:planks 0
setblock ~42~14~8 minecraft:oak_stairs 4
setblock ~42~17~8 minecraft:torch 1
setblock ~42~18~8 minecraft:stone_block_slab 5
fill ~42~19~8 ~43~19~24 minecraft:planks 0
fill ~44~19~8 ~54~19~8 minecraft:log 0
fill ~44~20~8 ~49~20~8 minecraft:fence 0
setblock ~46~8~8 minecraft:torch 3
setblock ~50~8~8 minecraft:torch 3
setblock ~50~15~8 minecraft:stonebrick 3
fill ~50~20~8 ~50~20~22 minecraft:stone_block_slab 0
fill ~51~20~8 ~53~20~8 minecraft:fence 0
setblock ~54~8~8 minecraft:torch 3
setblock ~54~15~8 minecraft:stonebrick 3
fill ~54~20~8 ~54~20~22 minecraft:stone_block_slab 0
setblock ~55~19~8 minecraft:log 1
fill ~56~19~8 ~74~19~8 minecraft:log 0
setblock ~56~41~8 minecraft:oak_stairs 6
setblock ~56~53~8 minecraft:oak_stairs 2
fill ~57~23~8 ~57~26~8 minecraft:fence 0
fill ~57~27~8 ~57~27~14 minecraft:log 1
setblock ~57~28~8 minecraft:wooden_slab 0
fill ~57~33~8 ~61~36~8 minecraft:fence 0
fill ~57~41~8 ~60~41~8 minecraft:fence 0
fill ~57~53~8 ~60~53~8 minecraft:fence 0
setblock ~58~8~8 minecraft:torch 3
fill ~59~20~8 ~59~20~22 minecraft:stone_block_slab 0
setblock ~60~15~8 minecraft:stonebrick 3
fill ~60~20~8 ~63~20~8 minecraft:fence 0
setblock ~61~41~8 minecraft:oak_stairs 6
setblock ~61~53~8 minecraft:oak_stairs 2
setblock ~62~8~8 minecraft:torch 3
setblock ~64~15~8 minecraft:stonebrick 3
fill ~64~20~8 ~64~20~22 minecraft:stone_block_slab 0
fill ~65~20~8 ~67~20~8 minecraft:fence 0
setblock ~66~8~8 minecraft:torch 3
setblock ~68~8~8 minecraft:torch 3
fill ~68~20~8 ~68~20~22 minecraft:stone_block_slab 0
fill ~69~20~8 ~74~20~8 minecraft:fence 0
setblock ~70~15~8 minecraft:stonebrick 3
setblock ~73~8~8 minecraft:torch 3
setblock ~74~21~8 minecraft:torch 5
setblock ~76~8~8 minecraft:torch 3
fill ~77~20~8 ~77~20~9 minecraft:oak_stairs 0
fill ~78~21~8 ~78~21~9 minecraft:oak_stairs 0
setblock ~79~8~8 minecraft:torch 3
fill ~79~22~8 ~79~22~9 minecraft:oak_stairs 0
fill ~80~23~8 ~80~23~9 minecraft:oak_stairs 0
fill ~81~23~8 ~82~23~8 minecraft:planks 0
setblock ~82~8~8 minecraft:torch 3
fill ~82~20~8 ~83~20~8 minecraft:oak_stairs 3
fill ~82~32~8 ~85~35~8 minecraft:fence 0
setblock ~82~41~8 minecraft:oak_stairs 6
setblock ~82~53~8 minecraft:oak_stairs 2
setblock ~83~23~8 minecraft:log 0
fill ~83~41~8 ~85~41~8 minecraft:fence 0
fill ~83~53~8 ~85~53~8 minecraft:fence 0
setblock ~84~16~8 minecraft:oak_stairs 0
fill ~84~23~8 ~99~23~10 minecraft:planks 0
fill ~85~7~8 ~97~7~8 minecraft:planks 0
fill ~85~8~8 ~97~8~8 minecraft:log 0
fill ~85~9~8 ~92~9~8 minecraft:log 1
fill ~85~16~8 ~85~17~8 minecraft:planks 0
fill ~85~43~8 ~88~43~8 minecraft:wool 0
fill ~86~16~8 ~92~16~8 minecraft:log 0
fill ~86~17~8 ~86~19~8 minecraft:log 0
fill ~86~20~8 ~87~20~9 minecraft:wool 11
setblock ~86~41~8 minecraft:oak_stairs 6
fill ~86~44~8 ~88~44~8 minecraft:wool 0
setblock ~86~53~8 minecraft:oak_stairs 2
fill ~87~17~8 ~89~18~8 minecraft:planks 0
fill ~87~19~8 ~95~19~8 minecraft:log 0
fill ~87~24~8 ~87~24~9 minecraft:oak_stairs 0
fill ~87~50~8 ~88~51~8 minecraft:wool 0
fill ~88~25~8 ~88~25~9 minecraft:oak_stairs 0
setblock ~89~20~8 minecraft:stone_button 2
fill ~89~26~8 ~89~26~9 minecraft:oak_stairs 0
fill ~89~45~8 ~89~49~8 minecraft:wool 0
setblock ~90~17~8 minecraft:glass
fill ~90~18~8 ~92~18~8 minecraft:planks 0
fill ~90~24~8 ~90~26~10 minecraft:planks 0
fill ~90~27~8 ~90~27~9 minecraft:oak_stairs 0
setblock ~90~47~8 minecraft:planks 0
fill ~91~10~8 ~91~10~14 minecraft:planks 0
fill ~91~11~8 ~91~12~12 minecraft:planks 0
setblock ~91~17~8 minecraft:planks 0
fill ~91~24~8 ~92~24~8 minecraft:chest 3
setblock ~91~27~8 minecraft:planks 0
setblock ~92~10~8 minecraft:gold_block
fill ~92~11~8 ~94~11~8 minecraft:wool 3
fill ~92~12~8 ~98~12~8 minecraft:dispenser 3
setblock ~92~17~8 minecraft:log 0
setblock ~92~20~8 minecraft:wooden_door 2
fill ~92~22~8 ~92~22~23 minecraft:planks 0
setblock ~92~27~8 minecraft:log 0
fill ~93~9~8 ~97~9~8 minecraft:gold_block
fill ~93~10~8 ~97~10~8 minecraft:wool 3
setblock ~93~16~8 minecraft:wooden_door 1
setblock ~93~18~8 minecraft:log 0
fill ~93~22~8 ~94~22~8 minecraft:oak_stairs 6
fill ~93~27~8 ~97~27~8 minecraft:planks 0
fill ~94~16~8 ~95~16~8 minecraft:log 0
setblock ~94~17~8 minecraft:log 0
fill ~94~18~8 ~95~18~8 minecraft:planks 0
fill ~94~24~8 ~95~24~8 minecraft:chest 3
fill ~95~11~8 ~96~11~8 minecraft:gold_block
setblock ~95~17~8 minecraft:planks 0
fill ~95~28~8 ~97~28~8 minecraft:stone_block_slab 0
fill ~96~18~8 ~97~18~8 minecraft:stone_block_slab 5
setblock ~96~19~8 minecraft:planks 0
fill ~96~22~8 ~98~22~8 minecraft:oak_stairs 6
setblock ~97~11~8 minecraft:wool 3
setblock ~97~24~8 minecraft:chest 3
setblock ~97~31~8 minecraft:stone_block_slab 8
fill ~97~32~8 ~97~32~9 minecraft:glass_pane
setblock ~97~33~8 minecraft:stone_block_slab 0
fill ~98~10~8 ~98~11~8 minecraft:gold_block
fill ~98~24~8 ~98~26~8 minecraft:wool 3
fill ~98~27~8 ~99~27~8 minecraft:gold_block
fill ~98~28~8 ~98~29~8 minecraft:wool 3
setblock ~98~30~8 minecraft:gold_block
setblock ~98~31~8 minecraft:fence 0
setblock ~98~32~8 minecraft:glowstone
setblock ~98~33~8 minecraft:double_stone_block_slab 0
setblock ~99~12~8 minecraft:gold_block
setblock ~99~14~8 minecraft:torch 3
fill ~99~24~8 ~99~26~8 minecraft:gold_block
setblock ~99~28~8 minecraft:stone_block_slab 0
setblock ~99~31~8 minecraft:stone_block_slab 8
fill ~99~32~8 ~99~32~9 minecraft:glass_pane
setblock ~99~33~8 minecraft:stone_block_slab 0
setblock ~100~13~8 minecraft:gold_block
setblock ~100~14~8 minecraft:web
fill ~100~15~8 ~101~15~21 minecraft:planks 0
fill ~100~19~8 ~101~19~9 minecraft:planks 0
fill ~100~23~8 ~102~23~8 minecraft:gold_block
fill ~100~24~8 ~102~24~8 minecraft:wool 3
fill ~100~25~8 ~102~25~8 minecraft:stone_block_slab 0
fill ~101~14~8 ~102~14~8 minecraft:gold_block
fill ~101~20~8 ~101~22~8 minecraft:gold_block
fill ~102~15~8 ~103~15~8 minecraft:gold_block
fill ~102~16~8 ~103~16~8 minecraft:fence 0
fill ~102~17~8 ~103~17~8 minecraft:stone_block_slab 0
fill ~102~19~8 ~104~19~8 minecraft:gold_block
fill ~102~20~8 ~104~20~8 minecraft:fence 0
fill ~102~21~8 ~104~21~8 minecraft:stone_block_slab 0
fill ~103~24~8 ~104~24~8 minecraft:stone_block_slab 0
setblock ~12~22~9 minecraft:wool 3
setblock ~12~23~9 minecraft:stone_block_slab 0
setblock ~13~19~9 minecraft:oak_stairs 4
fill ~13~20~9 ~15~20~9 minecraft:log 0
setblock ~13~21~9 minecraft:wool 3
setblock ~14~18~9 minecraft:oak_stairs 4
fill ~14~19~9 ~14~19~21 minecraft:planks 0
setblock ~15~17~9 minecraft:oak_stairs 4
fill ~15~18~9 ~17~18~9 minecraft:planks 0
setblock ~15~19~9 minecraft:log 0
fill ~15~21~9 ~15~23~9 minecraft:log 0
fill ~15~24~9 ~16~24~9 minecraft:fence 0
setblock ~15~47~9 minecraft:planks 0
setblock ~16~16~9 minecraft:oak_stairs 4
fill ~16~17~9 ~18~17~9 minecraft:planks 0
fill ~16~19~9 ~19~19~20 minecraft:planks 0
fill ~16~20~9 ~16~21~9 minecraft:bed 2
setblock ~16~22~9 minecraft:torch 1
fill ~16~23~9 ~18~23~9 minecraft:planks 0
fill ~16~45~9 ~16~49~9 minecraft:wool 0
setblock ~17~15~9 minecraft:oak_stairs 4
fill ~17~16~9 ~18~16~14 minecraft:planks 0
fill ~17~43~9 ~17~44~9 minecraft:wool 0
fill ~17~50~9 ~18~50~9 minecraft:wool 0
setblock ~17~51~9 minecraft:wool 0
setblock ~18~14~9 minecraft:oak_stairs 4
fill ~18~15~9 ~19~15~9 minecraft:planks 0
setblock ~18~18~9 minecraft:chest 3
fill ~18~42~9 ~20~42~9 minecraft:wool 0
setblock ~18~44~9 minecraft:wool 0
fill ~18~52~9 ~20~52~9 minecraft:wool 0
setblock ~19~13~9 minecraft:oak_stairs 4
fill ~19~14~9 ~20~14~9 minecraft:planks 0
setblock ~19~23~9 minecraft:planks 1
setblock ~20~12~9 minecraft:oak_stairs 4
fill ~20~13~9 ~21~13~9 minecraft:planks 0
fill ~20~17~9 ~21~17~9 minecraft:chest 3
fill ~20~23~9 ~23~23~9 minecraft:planks 0
setblock ~20~40~9 minecraft:oak_stairs 6
fill ~20~41~9 ~86~41~9 minecraft:wool 0
fill ~20~53~9 ~86~53~9 minecraft:wool 0
setblock ~20~54~9 minecraft:oak_stairs 2
setblock ~21~11~9 minecraft:oak_stairs 4
fill ~21~12~9 ~22~12~9 minecraft:planks 0
fill ~21~32~9 ~25~35~9 minecraft:fence 0
fill ~21~40~9 ~24~40~9 minecraft:fence 0
fill ~21~54~9 ~24~54~9 minecraft:fence 0
setblock ~22~10~9 minecraft:oak_stairs 4
fill ~22~11~9 ~23~11~9 minecraft:planks 0
fill ~23~10~9 ~24~10~9 minecraft:planks 0
fill ~24~7~9 ~28~7~9 minecraft:planks 0
fill ~24~8~9 ~27~8~9 minecraft:log 0
fill ~24~9~9 ~27~9~9 minecraft:log 1
setblock ~24~23~9 minecraft:planks 1
fill ~25~16~9 ~25~16~23 minecraft:planks 0
fill ~25~17~9 ~25~17~10 minecraft:iron_door 2
fill ~25~23~9 ~25~23~11 minecraft:planks 0
setblock ~25~40~9 minecraft:oak_stairs 6
setblock ~25~54~9 minecraft:oak_stairs 2
setblock ~26~15~9 minecraft:oak_stairs 4
fill ~26~16~9 ~26~16~10 minecraft:oak_stairs 1
fill ~26~19~9 ~26~19~22 minecraft:planks 0
fill ~27~16~9 ~29~16~13 minecraft:stone_block_slab 0
setblock ~27~19~9 minecraft:torch 3
fill ~27~20~9 ~34~20~21 minecraft:planks 0
fill ~28~6~9 ~41~6~9 minecraft:planks 0
setblock ~28~8~9 minecraft:torch 1
fill ~28~9~9 ~42~9~9 minecraft:planks 0
fill ~29~5~9 ~54~5~9 minecraft:planks 0
setblock ~30~8~9 minecraft:torch 3
fill ~30~16~9 ~30~18~9 minecraft:bookshelf
setblock ~30~19~9 minecraft:torch 3
fill ~31~18~9 ~40~18~9 minecraft:bookshelf
fill ~32~16~9 ~40~16~9 minecraft:cauldron 6
setblock ~33~8~9 minecraft:torch 3
setblock ~33~19~9 minecraft:torch 3
setblock ~35~20~9 minecraft:planks 1
setblock ~36~8~9 minecraft:torch 3
setblock ~36~19~9 minecraft:torch 3
setblock ~36~20~9 minecraft:planks 0
setblock ~37~20~9 minecraft:log 0
setblock ~38~20~9 minecraft:planks 0
setblock ~39~19~9 minecraft:torch 3
setblock ~39~20~9 minecraft:planks 1
setblock ~40~8~9 minecraft:torch 3
fill ~40~20~9 ~40~20~11 minecraft:planks 0
fill ~41~16~9 ~41~19~13 minecraft:planks 0
fill ~41~20~9 ~41~20~21 minecraft:log 0
fill ~41~21~9 ~41~21~21 minecraft:fence 0
setblock ~41~22~9 minecraft:torch 5
fill ~42~4~9 ~85~4~9 minecraft:planks 0
setblock ~42~20~9 minecraft:fence 0
setblock ~42~21~9 minecraft:oak_stairs 1
fill ~43~9~9 ~76~9~9 minecraft:log 0
fill ~43~10~9 ~76~10~9 minecraft:fence 0
setblock ~44~6~9 minecraft:torch 3
fill ~44~19~9 ~44~19~13 minecraft:log 0
fill ~44~20~9 ~44~20~13 minecraft:fence 0
fill ~45~19~9 ~53~19~9 minecraft:wall_sign 3
setblock ~46~6~9 minecraft:torch 3
setblock ~48~6~9 minecraft:torch 3
fill ~48~16~9 ~50~16~9 minecraft:dispenser 4
fill ~49~15~9 ~50~15~9 minecraft:log 0
setblock ~50~6~9 minecraft:torch 3
setblock ~51~15~9 minecraft:lever 1
fill ~52~16~9 ~54~16~9 minecraft:dispenser 4
setblock ~53~6~9 minecraft:torch 3
fill ~53~15~9 ~54~15~9 minecraft:log 0
setblock ~54~19~9 minecraft:oak_stairs 7
setblock ~55~6~9 minecraft:torch 3
setblock ~55~15~9 minecraft:lever 1
fill ~55~19~9 ~58~19~9 minecraft:wooden_slab 8
setblock ~56~40~9 minecraft:oak_stairs 6
setblock ~56~54~9 minecraft:oak_stairs 2
setblock ~57~6~9 minecraft:torch 3
fill ~57~36~9 ~60~40~9 minecraft:fence 0
setblock ~57~42~9 minecraft:glowstone
fill ~57~54~9 ~60~54~9 minecraft:fence 0
fill ~58~16~9 ~60~16~9 minecraft:dispenser 4
setblock ~59~6~9 minecraft:torch 3
fill ~59~15~9 ~60~15~9 minecraft:log 0
setblock ~59~19~9 minecraft:oak_stairs 7
fill ~60~19~9 ~73~19~9 minecraft:wall_sign 3
setblock ~61~15~9 minecraft:lever 1
setblock ~61~40~9 minecraft:oak_stairs 6
setblock ~61~54~9 minecraft:oak_stairs 2
setblock ~62~6~9 minecraft:torch 3
fill ~62~16~9 ~64~16~9 minecraft:dispenser 4
fill ~63~15~9 ~64~15~9 minecraft:log 0
setblock ~64~6~9 minecraft:torch 3
setblock ~65~15~9 minecraft:lever 1
setblock ~66~6~9 minecraft:torch 3
setblock ~68~6~9 minecraft:torch 3
fill ~68~16~9 ~70~16~9 minecraft:dispenser 4
fill ~69~15~9 ~70~15~9 minecraft:log 0
fill ~71~5~9 ~99~5~9 minecraft:planks 0
setblock ~71~6~9 minecraft:torch 3
setblock ~71~15~9 minecraft:lever 1
setblock ~73~6~9 minecraft:torch 3
fill ~74~19~9 ~74~19~13 minecraft:log 0
fill ~74~20~9 ~74~20~13 minecraft:fence 0
setblock ~75~6~9 minecraft:torch 3
setblock ~75~14~9 minecraft:oak_stairs 5
setblock ~77~6~9 minecraft:torch 3
fill ~77~9~9 ~97~9~14 minecraft:planks 0
fill ~78~15~9 ~78~15~17 minecraft:planks 0
setblock ~79~6~9 minecraft:torch 3
fill ~79~15~9 ~83~15~9 minecraft:log 0
setblock ~80~14~9 minecraft:log 0
fill ~80~16~9 ~83~16~9 minecraft:fence 0
setblock ~80~17~9 minecraft:torch 5
setblock ~81~6~9 minecraft:torch 3
setblock ~81~13~9 minecraft:log 0
setblock ~81~14~9 minecraft:fence 0
setblock ~81~23~9 minecraft:planks 0
setblock ~82~12~9 minecraft:log 0
setblock ~82~13~9 minecraft:fence 0
setblock ~82~23~9 minecraft:log 0
fill ~82~35~9 ~85~35~9 minecraft:fence 0
setblock ~82~40~9 minecraft:oak_stairs 6
setblock ~82~54~9 minecraft:oak_stairs 2
setblock ~83~6~9 minecraft:torch 3
setblock ~83~11~9 minecraft:log 0
setblock ~83~12~9 minecraft:fence 0
fill ~83~23~9 ~83~23~13 minecraft:planks 0
fill ~83~36~9 ~85~40~9 minecraft:fence 0
fill ~83~54~9 ~85~54~9 minecraft:fence 0
setblock ~84~6~9 minecraft:gold_block
setblock ~84~10~9 minecraft:log 0
setblock ~84~11~9 minecraft:fence 0
fill ~84~15~9 ~85~15~25 minecraft:planks 0
setblock ~84~18~9 minecraft:oak_stairs 4
setblock ~85~6~9 minecraft:torch 2
setblock ~85~8~9 minecraft:torch 3
fill ~85~16~9 ~85~16~15 minecraft:log 0
fill ~85~17~9 ~85~18~9 minecraft:log 0
fill ~86~6~9 ~99~6~9 minecraft:planks 0
fill ~86~16~9 ~86~18~9 minecraft:bookshelf
fill ~86~19~9 ~95~19~19 minecraft:planks 0
setblock ~86~40~9 minecraft:oak_stairs 6
fill ~86~42~9 ~88~42~9 minecraft:wool 0
setblock ~86~54~9 minecraft:oak_stairs 2
setblock ~87~8~9 minecraft:torch 3
fill ~87~18~9 ~95~18~9 minecraft:bookshelf
fill ~87~43~9 ~89~43~9 minecraft:wool 0
fill ~87~52~9 ~88~52~9 minecraft:wool 0
setblock ~88~17~9 minecraft:torch 3
fill ~88~44~9 ~89~44~9 minecraft:wool 0
fill ~89~20~9 ~89~20~11 minecraft:log 0
fill ~89~21~9 ~89~22~11 minecraft:fence 0
fill ~89~50~9 ~89~51~9 minecraft:wool 0
setblock ~90~8~9 minecraft:torch 3
setblock ~90~14~9 minecraft:oak_stairs 4
fill ~90~20~9 ~90~20~11 minecraft:stone_button 5
fill ~90~45~9 ~90~49~9 minecraft:wool 0
setblock ~91~27~9 minecraft:log 0
setblock ~91~47~9 minecraft:planks 0
setblock ~92~8~9 minecraft:torch 3
fill ~92~10~9 ~98~11~9 minecraft:dispenser 3
fill ~92~20~9 ~93~21~9 minecraft:planks 0
fill ~92~27~9 ~96~27~9 minecraft:planks 0
fill ~93~22~9 ~94~22~9 minecraft:planks 0
fill ~94~13~9 ~94~14~9 minecraft:web
fill ~94~20~9 ~94~21~9 minecraft:log 0
setblock ~95~8~9 minecraft:torch 3
setblock ~95~17~9 minecraft:torch 3
setblock ~95~20~9 minecraft:wooden_door 1
setblock ~95~22~9 minecraft:log 0
fill ~96~16~9 ~97~16~9 minecraft:log 0
setblock ~96~17~9 minecraft:glass
fill ~96~18~9 ~97~18~9 minecraft:planks 0
fill ~96~19~9 ~97~19~9 minecraft:log 0
fill ~96~20~9 ~96~21~9 minecraft:log 0
fill ~96~22~9 ~98~22~9 minecraft:planks 0
setblock ~97~8~9 minecraft:torch 3
setblock ~97~17~9 minecraft:planks 0
fill ~97~20~9 ~98~20~9 minecraft:planks 0
setblock ~97~21~9 minecraft:planks 0
setblock ~97~27~9 minecraft:log 0
fill ~98~7~9 ~99~7~9 minecraft:planks 0
fill ~98~8~9 ~99~8~9 minecraft:log 0
fill ~98~9~9 ~99~9~9 minecraft:double_stone_block_slab 0
fill ~98~18~9 ~100~18~9 minecraft:stone_block_slab 5
fill ~98~19~9 ~99~19~9 minecraft:planks 0
setblock ~98~21~9 minecraft:glass
fill ~98~27~9 ~98~27~13 minecraft:planks 0
fill ~98~28~9 ~98~28~10 minecraft:stone_block_slab 0
setblock ~98~31~9 minecraft:stone_block_slab 8
setblock ~98~32~9 minecraft:glass_pane
setblock ~98~33~9 minecraft:stone_block_slab 0
fill ~99~10~9 ~99~11~9 minecraft:wool 3
setblock ~99~22~9 minecraft:stone_block_slab 5
fill ~99~24~9 ~99~28~9 minecraft:wool 3
setblock ~99~29~9 minecraft:gold_block
fill ~100~11~9 ~100~11~10 minecraft:wool 3
fill ~100~12~9 ~101~12~9 minecraft:wool 3
fill ~100~23~9 ~101~23~21 minecraft:planks 0
setblock ~100~26~9 minecraft:stone_block_slab 3
fill ~101~13~9 ~102~13~9 minecraft:wool 3
fill ~102~14~9 ~103~14~9 minecraft:wool 3
fill ~102~15~9 ~103~15~20 minecraft:planks 0
fill ~102~19~9 ~103~19~11 minecraft:planks 0
fill ~102~23~9 ~104~23~9 minecraft:gold_block
fill ~103~16~9 ~104~16~9 minecraft:fence 0
fill ~103~17~9 ~104~17~9 minecraft:stone_block_slab 0
fill ~103~24~9 ~104~24~9 minecraft:wool 3
fill ~103~25~9 ~104~25~9 minecraft:stone_block_slab 0
fill ~104~15~9 ~104~15~10 minecraft:gold_block
fill ~104~19~9 ~105~19~9 minecraft:gold_block
fill ~104~20~9 ~105~20~9 minecraft:fence 0
fill ~104~21~9 ~105~21~9 minecraft:stone_block_slab 0
setblock ~105~24~9 minecraft:stone_block_slab 0
setblock ~9~13~10 minecraft:stone_stairs 4
setblock ~9~14~10 minecraft:stone_stairs 1
setblock ~9~20~10 minecraft:stone_button 2
fill ~10~13~10 ~12~13~10 minecraft:obsidian
setblock ~10~16~10 minecraft:stone_block_slab 3
setblock ~10~17~10 minecraft:obsidian
setblock ~11~12~10 minecraft:stone_block_slab 11
fill ~11~14~10 ~11~16~10 minecraft:obsidian
setblock ~11~18~10 minecraft:obsidian
fill ~11~19~10 ~11~21~10 minecraft:iron_bars
setblock ~11~22~10 minecraft:log 0
setblock ~11~23~10 minecraft:stone_block_slab 0
setblock ~12~16~10 minecraft:stone_block_slab 3
setblock ~12~17~10 minecraft:obsidian
setblock ~12~18~10 minecraft:oak_stairs 4
fill ~12~19~10 ~13~19~14 minecraft:planks 0
fill ~12~20~10 ~14~20~10 minecraft:log 0
setblock ~12~21~10 minecraft:wool 3
setblock ~13~13~10 minecraft:stone_stairs 5
setblock ~13~14~10 minecraft:stone_stairs 0
setblock ~13~17~10 minecraft:oak_stairs 4
fill ~13~18~10 ~15~18~10 minecraft:planks 0
setblock ~14~16~10 minecraft:oak_stairs 4
fill ~14~17~10 ~16~17~10 minecraft:planks 0
fill ~14~21~10 ~14~23~10 minecraft:log 0
fill ~14~24~10 ~15~24~10 minecraft:fence 0
setblock ~14~47~10 minecraft:planks 0
setblock ~15~15~10 minecraft:oak_stairs 4
fill ~15~16~10 ~16~16~20 minecraft:planks 0
fill ~15~19~10 ~15~19~20 minecraft:planks 0
fill ~15~23~10 ~17~23~10 minecraft:planks 0
fill ~15~45~10 ~15~49~10 minecraft:wool 0
setblock ~16~14~10 minecraft:oak_stairs 4
fill ~16~15~10 ~17~15~10 minecraft:planks 0
setblock ~16~18~10 minecraft:chest 3
fill ~16~43~10 ~16~43~12 minecraft:wool 0
fill ~16~44~10 ~17~44~10 minecraft:wool 0
fill ~16~50~10 ~17~50~10 minecraft:wool 0
setblock ~16~51~10 minecraft:wool 0
setblock ~17~13~10 minecraft:oak_stairs 4
fill ~17~14~10 ~18~14~10 minecraft:planks 0
fill ~17~17~10 ~18~17~10 minecraft:chest 3
fill ~17~42~10 ~18~42~10 minecraft:wool 0
fill ~17~52~10 ~18~52~10 minecraft:wool 0
setblock ~18~12~10 minecraft:oak_stairs 4
fill ~18~13~10 ~19~13~10 minecraft:planks 0
setblock ~18~15~10 minecraft:torch 1
setblock ~18~20~10 minecraft:wooden_door 2
setblock ~18~23~10 minecraft:planks 1
fill ~18~24~10 ~22~24~10 minecraft:wall_sign 2
fill ~18~41~10 ~20~41~10 minecraft:wool 0
setblock ~19~11~10 minecraft:oak_stairs 4
fill ~19~12~10 ~20~12~10 minecraft:planks 0
setblock ~19~15~10 minecraft:torch 3
fill ~19~23~10 ~22~23~14 minecraft:planks 0
fill ~19~53~10 ~20~53~10 minecraft:wool 0
setblock ~20~10~10 minecraft:oak_stairs 4
fill ~20~11~10 ~21~11~10 minecraft:planks 0
setblock ~20~20~10 minecraft:bed 3
setblock ~20~39~10 minecraft:oak_stairs 6
fill ~20~40~10 ~86~40~10 minecraft:wool 0
fill ~20~54~10 ~86~54~10 minecraft:wool 0
setblock ~20~55~10 minecraft:oak_stairs 2
fill ~21~10~10 ~22~10~10 minecraft:planks 0
setblock ~21~20~10 minecraft:wooden_door 0
fill ~21~35~10 ~24~39~10 minecraft:fence 0
fill ~21~55~10 ~24~55~10 minecraft:fence 0
fill ~22~7~10 ~24~7~10 minecraft:planks 0
fill ~22~8~10 ~24~8~10 minecraft:log 0
fill ~22~9~10 ~23~9~10 minecraft:log 1
setblock ~22~20~10 minecraft:wooden_door 2
setblock ~23~20~10 minecraft:bed 1
setblock ~23~23~10 minecraft:planks 1
fill ~24~6~10 ~27~6~10 minecraft:planks 0
fill ~24~9~10 ~28~9~10 minecraft:planks 0
setblock ~24~23~10 minecraft:planks 0
setblock ~25~20~10 minecraft:wooden_door 0
setblock ~25~39~10 minecraft:oak_stairs 6
setblock ~25~55~10 minecraft:oak_stairs 2
setblock ~26~21~10 minecraft:torch 2
fill ~27~5~10 ~28~5~10 minecraft:planks 0
fill ~27~21~10 ~27~22~10 minecraft:planks 0
fill ~27~23~10 ~27~23~20 minecraft:log 0
fill ~27~24~10 ~27~24~20 minecraft:fence 0
fill ~27~25~10 ~27~25~20 minecraft:stone_block_slab 0
fill ~28~4~10 ~54~4~10 minecraft:planks 0
setblock ~28~22~10 minecraft:log 0
setblock ~28~23~10 minecraft:fence 0
setblock ~28~24~10 minecraft:oak_stairs 1
fill ~29~9~10 ~43~9~10 minecraft:log 0
fill ~29~10~10 ~43~10~10 minecraft:fence 0
setblock ~29~21~10 minecraft:log 0
setblock ~29~22~10 minecraft:fence 0
setblock ~29~23~10 minecraft:oak_stairs 1
fill ~30~5~10 ~30~6~10 minecraft:torch 3
fill ~30~16~10 ~30~16~21 minecraft:stone_block_slab 0
setblock ~30~21~10 minecraft:fence 0
setblock ~30~22~10 minecraft:oak_stairs 1
fill ~32~6~10 ~33~6~10 minecraft:torch 3
fill ~32~16~10 ~39~16~11 minecraft:stone_block_slab 0
setblock ~34~5~10 minecraft:torch 3
setblock ~35~6~10 minecraft:torch 3
fill ~35~20~10 ~35~20~20 minecraft:planks 0
fill ~35~22~10 ~35~22~11 minecraft:log 0
setblock ~36~20~10 minecraft:planks 1
fill ~37~5~10 ~37~6~10 minecraft:torch 3
setblock ~37~20~10 minecraft:planks 0
setblock ~38~20~10 minecraft:planks 1
setblock ~39~6~10 minecraft:torch 3
fill ~39~20~10 ~39~20~12 minecraft:planks 0
setblock ~40~5~10 minecraft:torch 3
fill ~40~16~10 ~40~16~13 minecraft:cauldron 6
fill ~40~18~10 ~40~18~13 minecraft:bookshelf
setblock ~40~19~10 minecraft:torch 2
setblock ~41~6~10 minecraft:torch 3
fill ~42~3~10 ~85~3~10 minecraft:planks 0
setblock ~42~14~10 minecraft:oak_stairs 4
setblock ~42~18~10 minecraft:stone_block_slab 5
fill ~42~20~10 ~42~20~20 minecraft:wall_sign 5
setblock ~44~5~10 minecraft:torch 3
fill ~45~19~10 ~45~19~12 minecraft:stone_button 5
setblock ~47~5~10 minecraft:torch 3
setblock ~50~15~10 minecraft:stonebrick 3
setblock ~50~16~10 minecraft:torch 5
setblock ~51~5~10 minecraft:torch 3
setblock ~54~5~10 minecraft:torch 3
setblock ~54~15~10 minecraft:stonebrick 3
setblock ~54~16~10 minecraft:torch 5
setblock ~56~39~10 minecraft:oak_stairs 6
setblock ~56~55~10 minecraft:oak_stairs 2
setblock ~57~4~10 minecraft:torch 3
fill ~57~39~10 ~60~39~10 minecraft:wooden_slab 8
setblock ~57~41~10 minecraft:oak_stairs 3
fill ~57~55~10 ~60~55~10 minecraft:fence 0
setblock ~60~15~10 minecraft:stonebrick 3
setblock ~60~16~10 minecraft:torch 5
setblock ~61~39~10 minecraft:oak_stairs 6
setblock ~61~55~10 minecraft:oak_stairs 2
setblock ~62~4~10 minecraft:torch 3
setblock ~64~15~10 minecraft:stonebrick 3
setblock ~64~16~10 minecraft:torch 5
setblock ~66~4~10 minecraft:torch 3
setblock ~70~4~10 minecraft:torch 3
setblock ~70~15~10 minecraft:stonebrick 3
setblock ~70~16~10 minecraft:torch 5
fill ~71~4~10 ~100~4~10 minecraft:planks 0
setblock ~73~5~10 minecraft:torch 3
fill ~73~19~10 ~73~19~12 minecraft:stone_button 4
setblock ~76~5~10 minecraft:torch 3
fill ~76~9~10 ~76~9~21 minecraft:log 0
fill ~76~10~10 ~76~10~21 minecraft:fence 0
setblock ~76~20~10 minecraft:fence 0
setblock ~76~21~10 minecraft:oak_stairs 0
setblock ~77~20~10 minecraft:log 0
setblock ~77~21~10 minecraft:fence 0
setblock ~77~22~10 minecraft:oak_stairs 0
setblock ~78~21~10 minecraft:log 0
fill ~78~22~10 ~78~23~10 minecraft:fence 0
setblock ~78~24~10 minecraft:oak_stairs 0
setblock ~79~5~10 minecraft:torch 3
fill ~79~15~10 ~79~15~12 minecraft:oak_stairs 1
fill ~79~22~10 ~79~23~10 minecraft:log 0
fill ~79~24~10 ~79~24~20 minecraft:fence 0
fill ~79~25~10 ~79~25~20 minecraft:stone_block_slab 0
fill ~80~14~10 ~80~14~12 minecraft:oak_stairs 1
setblock ~80~23~10 minecraft:planks 0
fill ~81~13~10 ~81~13~12 minecraft:oak_stairs 1
setblock ~81~20~10 minecraft:oak_stairs 1
setblock ~81~23~10 minecraft:log 0
setblock ~82~5~10 minecraft:torch 3
fill ~82~12~10 ~82~12~12 minecraft:oak_stairs 1
fill ~82~20~10 ~83~20~10 minecraft:fence 0
fill ~82~21~10 ~83~21~10 minecraft:wooden_pressure_plate 0
fill ~82~23~10 ~82~23~14 minecraft:planks 0
setblock ~82~39~10 minecraft:oak_stairs 6
setblock ~82~55~10 minecraft:oak_stairs 2
fill ~83~11~10 ~83~11~12 minecraft:oak_stairs 1
fill ~83~15~10 ~83~15~13 minecraft:log 0
fill ~83~16~10 ~83~16~13 minecraft:fence 0
fill ~83~39~10 ~85~39~10 minecraft:wooden_slab 8
fill ~83~55~10 ~85~55~10 minecraft:fence 0
setblock ~84~5~10 minecraft:gold_block
fill ~84~10~10 ~84~10~12 minecraft:oak_stairs 1
setblock ~84~20~10 minecraft:oak_stairs 0
setblock ~85~5~10 minecraft:torch 3
setblock ~85~17~10 minecraft:fence 0
fill ~85~18~10 ~85~18~20 minecraft:planks 0
setblock ~86~5~10 minecraft:gold_block
fill ~86~18~10 ~86~18~19 minecraft:bookshelf
fill ~86~20~10 ~87~20~10 minecraft:trapdoor 2
setblock ~86~21~10 minecraft:lever 1
setblock ~86~22~10 minecraft:redstone_lamp
setblock ~86~24~10 minecraft:fence 0
setblock ~86~25~10 minecraft:oak_stairs 0
setblock ~86~39~10 minecraft:oak_stairs 6
fill ~86~53~10 ~88~53~10 minecraft:wool 0
setblock ~86~55~10 minecraft:oak_stairs 2
setblock ~87~6~10 minecraft:torch 3
fill ~87~18~10 ~87~18~19 minecraft:wall_sign 5
setblock ~87~24~10 minecraft:log 0
setblock ~87~25~10 minecraft:fence 0
setblock ~87~26~10 minecraft:oak_stairs 0
fill ~87~41~10 ~88~41~10 minecraft:wool 0
setblock ~88~5~10 minecraft:torch 3
setblock ~88~16~10 minecraft:wall_sign 4
fill ~88~18~10 ~95~18~10 minecraft:wall_sign 3
fill ~88~20~10 ~88~20~11 minecraft:stone_button 4
setblock ~88~25~10 minecraft:log 0
setblock ~88~26~10 minecraft:fence 0
setblock ~88~27~10 minecraft:oak_stairs 0
fill ~88~42~10 ~89~42~10 minecraft:wool 0
setblock ~89~6~10 minecraft:torch 3
setblock ~89~16~10 minecraft:stone_brick_stairs 3
setblock ~89~26~10 minecraft:log 0
setblock ~89~27~10 minecraft:fence 0
setblock ~89~28~10 minecraft:oak_stairs 0
fill ~89~43~10 ~90~43~10 minecraft:wool 0
setblock ~89~51~10 minecraft:glowstone
setblock ~89~52~10 minecraft:wool 0
setblock ~90~16~10 minecraft:fence_gate 2
fill ~90~27~10 ~90~27~20 minecraft:log 0
fill ~90~28~10 ~90~28~20 minecraft:fence 0
fill ~90~29~10 ~90~29~20 minecraft:stone_block_slab 0
setblock ~90~44~10 minecraft:wool 0
fill ~90~50~10 ~90~51~10 minecraft:wool 0
fill ~91~5~10 ~91~6~10 minecraft:torch 3
setblock ~91~16~10 minecraft:stone_brick_stairs 3
fill ~91~27~10 ~95~27~10 minecraft:planks 0
fill ~91~45~10 ~91~49~10 minecraft:wool 0
fill ~92~5~10 ~93~5~10 minecraft:diamond_block
setblock ~92~16~10 minecraft:fence_gate 2
fill ~92~20~10 ~92~20~15 minecraft:planks 0
setblock ~92~21~10 minecraft:planks 0
setblock ~92~47~10 minecraft:planks 0
setblock ~93~16~10 minecraft:stone_brick_stairs 3
fill ~93~20~10 ~94~21~10 minecraft:bookshelf
fill ~93~22~10 ~98~22~14 minecraft:fence 0
setblock ~94~5~10 minecraft:torch 3
setblock ~94~16~10 minecraft:wall_sign 5
fill ~95~5~10 ~96~5~10 minecraft:diamond_block
fill ~96~16~10 ~97~18~10 minecraft:bookshelf
fill ~96~19~10 ~97~19~14 minecraft:planks 0
fill ~96~20~10 ~98~20~10 minecraft:bookshelf
fill ~96~21~10 ~97~21~10 minecraft:bookshelf
setblock ~96~27~10 minecraft:log 0
setblock ~97~5~10 minecraft:torch 3
fill ~97~27~10 ~97~27~14 minecraft:planks 0
fill ~98~9~10 ~99~9~20 minecraft:planks 0
fill ~98~16~10 ~100~16~10 minecraft:log 0
fill ~98~17~10 ~98~18~10 minecraft:planks 0
fill ~98~19~10 ~100~19~10 minecraft:log 0
setblock ~99~5~10 minecraft:torch 3
setblock ~99~17~10 minecraft:glass
fill ~99~18~10 ~100~18~10 minecraft:planks 0
fill ~99~20~10 ~99~22~10 minecraft:planks 0
setblock ~99~24~10 minecraft:wooden_door 2
fill ~99~26~10 ~99~26~11 minecraft:wool 3
setblock ~99~27~10 minecraft:wool 3
setblock ~99~28~10 minecraft:gold_block
fill ~100~5~10 ~100~5~11 minecraft:planks 0
fill ~100~6~10 ~102~8~10 minecraft:iron_block
fill ~100~9~10 ~100~9~11 minecraft:double_stone_block_slab 0
fill ~100~10~10 ~100~10~11 minecraft:wool 3
setblock ~100~17~10 minecraft:planks 0
fill ~100~22~10 ~101~22~10 minecraft:stone_block_slab 5
setblock ~100~26~10 minecraft:double_stone_block_slab 0
setblock ~101~12~10 minecraft:wool 3
setblock ~101~18~10 minecraft:stone_block_slab 5
setblock ~101~19~10 minecraft:planks 0
setblock ~101~26~10 minecraft:stone_block_slab 3
fill ~102~13~10 ~102~13~14 minecraft:wool 3
setblock ~102~14~10 minecraft:torch 2
fill ~102~23~10 ~103~23~20 minecraft:planks 0
fill ~103~14~10 ~103~14~14 minecraft:wool 3
setblock ~104~16~10 minecraft:fence 0
setblock ~104~17~10 minecraft:stone_block_slab 0
fill ~104~19~10 ~104~19~20 minecraft:planks 0
fill ~104~23~10 ~105~23~10 minecraft:gold_block
fill ~105~18~10 ~105~19~11 minecraft:gold_block
setblock ~105~20~10 minecraft:fence 0
setblock ~105~21~10 minecraft:stone_block_slab 0
fill ~105~24~10 ~105~24~20 minecraft:wool 3
fill ~105~25~10 ~105~25~20 minecraft:stone_block_slab 0
setblock ~9~19~11 minecraft:oak_stairs 4
fill ~9~20~11 ~12~20~11 minecraft:log 0
fill ~9~21~11 ~9~21~12 minecraft:fence 0
fill ~9~22~11 ~9~22~12 minecraft:stone_block_slab 0
setblock ~10~18~11 minecraft:oak_stairs 4
fill ~10~19~11 ~11~19~19 minecraft:planks 0
setblock ~10~21~11 minecraft:log 0
setblock ~10~22~11 minecraft:double_stone_block_slab 0
setblock ~11~17~11 minecraft:oak_stairs 4
fill ~11~18~11 ~13~18~11 minecraft:planks 0
fill ~11~21~11 ~11~21~12 minecraft:iron_bars
setblock ~12~16~11 minecraft:oak_stairs 4
fill ~12~17~11 ~14~17~11 minecraft:planks 0
setblock ~13~15~11 minecraft:oak_stairs 4
fill ~13~16~11 ~14~16~19 minecraft:planks 0
fill ~13~20~11 ~13~20~12 minecraft:double_stone_block_slab 0
fill ~13~21~11 ~13~21~12 minecraft:log 0
fill ~13~22~11 ~13~22~12 minecraft:planks 0
fill ~13~23~11 ~13~23~12 minecraft:log 0
fill ~13~24~11 ~14~24~11 minecraft:fence 0
fill ~13~47~11 ~13~47~12 minecraft:planks 0
setblock ~14~14~11 minecraft:oak_stairs 4
fill ~14~15~11 ~15~15~11 minecraft:planks 0
setblock ~14~18~11 minecraft:chest 3
fill ~14~20~11 ~14~20~12 minecraft:stone_block_slab 0
fill ~14~23~11 ~16~23~11 minecraft:planks 0
fill ~14~45~11 ~14~49~12 minecraft:wool 0
setblock ~15~13~11 minecraft:oak_stairs 4
fill ~15~14~11 ~16~14~11 minecraft:planks 0
fill ~15~17~11 ~16~17~11 minecraft:chest 3
fill ~15~43~11 ~15~44~12 minecraft:wool 0
setblock ~15~46~11 minecraft:glowstone
fill ~15~50~11 ~16~50~11 minecraft:wool 0
fill ~15~51~11 ~15~51~12 minecraft:wool 0
setblock ~16~12~11 minecraft:oak_stairs 4
fill ~16~13~11 ~17~13~11 minecraft:planks 0
setblock ~16~20~11 minecraft:wooden_door 1
fill ~16~42~11 ~16~42~12 minecraft:wool 0
fill ~16~52~11 ~17~52~11 minecraft:wool 0
setblock ~17~11~11 minecraft:oak_stairs 4
fill ~17~12~11 ~18~12~11 minecraft:planks 0
setblock ~17~23~11 minecraft:planks 1
fill ~17~41~11 ~17~41~12 minecraft:wool 0
setblock ~18~10~11 minecraft:oak_stairs 4
fill ~18~11~11 ~19~11~11 minecraft:planks 0
fill ~18~23~11 ~18~23~19 minecraft:planks 0
fill ~18~24~11 ~22~24~11 minecraft:log 0
fill ~18~25~11 ~21~25~11 minecraft:fence 0
fill ~18~26~11 ~21~26~11 minecraft:stone_block_slab 0
fill ~18~40~11 ~19~40~12 minecraft:wool 0
fill ~18~53~11 ~19~53~11 minecraft:wool 0
fill ~19~10~11 ~20~10~11 minecraft:planks 0
fill ~20~7~11 ~22~7~11 minecraft:planks 0
fill ~20~8~11 ~22~8~11 minecraft:log 0
fill ~20~9~11 ~21~9~11 minecraft:log 1
setblock ~20~38~11 minecraft:wooden_slab 8
fill ~20~39~11 ~86~39~12 minecraft:wool 0
fill ~20~54~11 ~20~55~12 minecraft:wool 0
fill ~20~56~11 ~25~56~11 minecraft:wooden_slab 0
fill ~21~55~11 ~86~55~12 minecraft:wool 0
fill ~22~9~11 ~24~9~19 minecraft:planks 0
setblock ~22~25~11 minecraft:oak_stairs 1
fill ~23~6~11 ~24~6~11 minecraft:planks 0
fill ~23~23~11 ~23~23~19 minecraft:planks 0
setblock ~23~24~11 minecraft:trapdoor 0
fill ~24~5~11 ~27~5~11 minecraft:planks 0
setblock ~24~23~11 minecraft:planks 1
fill ~25~9~11 ~29~9~11 minecraft:log 0
fill ~25~10~11 ~29~10~11 minecraft:fence 0
setblock ~25~18~11 minecraft:lever 2
setblock ~25~38~11 minecraft:wooden_slab 8
setblock ~26~15~11 minecraft:oak_stairs 4
fill ~26~16~11 ~26~16~23 minecraft:planks 0
fill ~26~17~11 ~26~18~21 minecraft:planks 0
fill ~27~4~11 ~27~4~12 minecraft:planks 0
setblock ~27~17~11 minecraft:wall_sign 5
setblock ~27~19~11 minecraft:torch 1
setblock ~27~21~11 minecraft:oak_stairs 1
fill ~27~22~11 ~27~22~14 minecraft:planks 0
fill ~28~3~11 ~54~3~11 minecraft:planks 0
setblock ~28~5~11 minecraft:torch 3
setblock ~28~22~11 minecraft:stone_button 3
fill ~28~23~11 ~28~23~19 minecraft:stone_button 5
setblock ~29~21~11 minecraft:stone_button 3
fill ~31~16~11 ~31~16~19 minecraft:stone_block_slab 0
setblock ~31~21~11 minecraft:stone_button 2
fill ~32~25~11 ~34~25~11 minecraft:wall_sign 2
fill ~33~22~11 ~33~22~18 minecraft:stone_button 4
fill ~34~19~11 ~37~19~11 minecraft:stone_button 2
fill ~34~22~11 ~34~22~18 minecraft:planks 0
fill ~35~21~11 ~35~21~18 minecraft:log 0
setblock ~35~54~11 minecraft:glowstone
fill ~36~20~11 ~36~20~19 minecraft:planks 0
fill ~36~22~11 ~36~22~18 minecraft:planks 0
setblock ~37~20~11 minecraft:planks 1
fill ~37~22~11 ~37~22~18 minecraft:stone_button 5
fill ~38~20~11 ~38~20~13 minecraft:planks 0
fill ~42~2~11 ~85~2~11 minecraft:planks 0
fill ~46~4~11 ~55~4~11 minecraft:fence 0
setblock ~50~15~11 minecraft:trapdoor 2
setblock ~54~15~11 minecraft:trapdoor 2
fill ~55~3~11 ~70~3~12 minecraft:grass
setblock ~56~4~11 minecraft:fence_gate 0
fill ~56~6~11 ~63~6~12 minecraft:leaves 0
fill ~56~38~11 ~61~38~11 minecraft:wooden_slab 8
fill ~56~56~11 ~61~56~11 minecraft:wooden_slab 0
fill ~57~4~11 ~57~4~14 minecraft:fence 0
fill ~57~7~11 ~59~7~12 minecraft:leaves 0
setblock ~57~40~11 minecraft:oak_stairs 3
setblock ~60~15~11 minecraft:trapdoor 2
fill ~61~5~11 ~63~5~12 minecraft:leaves 0
setblock ~62~54~11 minecraft:glowstone
setblock ~64~15~11 minecraft:trapdoor 2
fill ~65~5~11 ~67~6~12 minecraft:leaves 0
fill ~68~6~11 ~68~8~14 minecraft:leaves 0
fill ~69~7~11 ~71~8~12 minecraft:leaves 0
setblock ~70~15~11 minecraft:trapdoor 2
fill ~71~3~11 ~100~3~11 minecraft:planks 0
fill ~72~6~11 ~75~6~12 minecraft:leaves 0
fill ~73~5~11 ~76~5~12 minecraft:leaves 0
setblock ~75~14~11 minecraft:oak_stairs 5
setblock ~77~20~11 minecraft:stone_button 3
setblock ~78~21~11 minecraft:stone_button 3
fill ~78~23~11 ~78~23~19 minecraft:stone_button 4
fill ~79~22~11 ~79~22~19 minecraft:fence_gate 1
fill ~79~23~11 ~80~23~11 minecraft:log 0
fill ~80~20~11 ~80~22~11 minecraft:log 1
fill ~81~23~11 ~81~23~19 minecraft:planks 0
fill ~82~38~11 ~86~38~11 minecraft:wooden_slab 8
fill ~82~56~11 ~86~56~11 minecraft:wooden_slab 0
fill ~84~4~11 ~87~4~11 minecraft:gold_block
setblock ~84~18~11 minecraft:oak_stairs 4
fill ~84~23~11 ~85~23~11 minecraft:planks 0
setblock ~85~17~11 minecraft:planks 0
fill ~85~54~11 ~87~54~11 minecraft:wool 0
setblock ~86~17~11 minecraft:torch 1
setblock ~86~23~11 minecraft:log 1
setblock ~87~16~11 minecraft:wall_sign 2
fill ~87~23~11 ~99~23~11 minecraft:planks 0
setblock ~87~24~11 minecraft:stone_button 3
fill ~87~40~11 ~88~40~12 minecraft:wool 0
setblock ~88~25~11 minecraft:stone_button 3
setblock ~88~41~11 minecraft:glowstone
fill ~88~53~11 ~89~53~11 minecraft:wool 0
fill ~89~24~11 ~89~25~11 minecraft:fence 0
fill ~89~26~11 ~89~26~14 minecraft:stone_block_slab 0
fill ~89~27~11 ~89~27~13 minecraft:stone_button 4
fill ~89~41~11 ~89~41~12 minecraft:wool 0
setblock ~90~14~11 minecraft:oak_stairs 4
fill ~90~24~11 ~90~26~11 minecraft:planks 1
fill ~90~42~11 ~90~42~12 minecraft:wool 0
fill ~90~52~11 ~90~52~12 minecraft:wool 0
fill ~91~4~11 ~97~4~11 minecraft:diamond_block
fill ~91~24~11 ~91~27~11 minecraft:planks 0
fill ~91~43~11 ~91~44~12 minecraft:wool 0
fill ~91~50~11 ~91~51~12 minecraft:wool 0
fill ~92~10~11 ~93~10~11 minecraft:crafting_table
setblock ~92~14~11 minecraft:web
setblock ~92~21~11 minecraft:fence 0
setblock ~92~24~11 minecraft:fence_gate 0
fill ~92~26~11 ~98~26~11 minecraft:planks 0
fill ~92~27~11 ~94~27~11 minecraft:planks 0
fill ~92~45~11 ~92~49~12 minecraft:wool 0
fill ~93~20~11 ~93~20~15 minecraft:bookshelf
fill ~93~24~11 ~95~25~11 minecraft:planks 0
fill ~93~47~11 ~93~47~12 minecraft:planks 0
setblock ~95~16~11 minecraft:wall_sign 2
setblock ~95~27~11 minecraft:log 0
fill ~96~18~11 ~97~18~11 minecraft:wall_sign 3
setblock ~96~24~11 minecraft:fence_gate 2
fill ~96~27~11 ~96~27~19 minecraft:planks 0
setblock ~97~16~11 minecraft:torch 3
fill ~97~24~11 ~98~25~11 minecraft:planks 0
fill ~98~16~11 ~100~16~11 minecraft:bookshelf
fill ~98~17~11 ~98~18~11 minecraft:bookshelf
fill ~98~19~11 ~100~19~14 minecraft:planks 0
fill ~99~18~11 ~100~18~11 minecraft:bookshelf
fill ~99~20~11 ~99~21~11 minecraft:bookshelf
fill ~99~22~11 ~99~22~19 minecraft:fence 0
fill ~99~24~11 ~101~25~11 minecraft:wool 3
setblock ~99~27~11 minecraft:gold_block
setblock ~99~28~11 minecraft:stone_block_slab 0
setblock ~100~4~11 minecraft:planks 0
fill ~100~6~11 ~100~7~11 minecraft:planks 0
setblock ~100~8~11 minecraft:log 0
setblock ~100~17~11 minecraft:bookshelf
fill ~100~20~11 ~101~20~11 minecraft:planks 0
fill ~100~21~11 ~100~22~11 minecraft:planks 0
fill ~100~26~11 ~101~27~11 minecraft:wool 3
setblock ~100~28~11 minecraft:wool 3
fill ~100~29~11 ~101~29~11 minecraft:gold_block
fill ~101~5~11 ~102~5~11 minecraft:iron_block
fill ~101~6~11 ~102~8~11 minecraft:glowstone
fill ~101~9~11 ~102~9~11 minecraft:iron_block
fill ~101~11~11 ~101~11~14 minecraft:wool 3
setblock ~101~16~11 minecraft:log 0
fill ~101~17~11 ~101~18~11 minecraft:planks 0
setblock ~101~19~11 minecraft:log 0
setblock ~101~21~11 minecraft:glass
setblock ~101~22~11 minecraft:planks 0
setblock ~101~28~11 minecraft:gold_block
setblock ~102~11~11 minecraft:stone_block_slab 11
setblock ~102~12~11 minecraft:dispenser 5
setblock ~102~18~11 minecraft:stone_block_slab 5
setblock ~102~22~11 minecraft:stone_block_slab 5
fill ~102~24~11 ~102~27~11 minecraft:gold_block
setblock ~102~28~11 minecraft:stone_block_slab 0
setblock ~103~13~11 minecraft:stone_block_slab 0
fill ~104~14~11 ~104~14~13 minecraft:wool 3
fill ~104~15~11 ~104~15~18 minecraft:planks 0
fill ~104~23~11 ~104~23~20 minecraft:planks 0
fill ~105~15~11 ~105~15~19 minecraft:gold_block
fill ~105~16~11 ~105~17~11 minecraft:gold_block
fill ~105~20~11 ~105~23~11 minecraft:gold_block
fill ~106~18~11 ~106~19~11 minecraft:gold_block
fill ~106~20~11 ~106~20~19 minecraft:fence 0
fill ~106~21~11 ~106~21~19 minecraft:stone_block_slab 0
fill ~106~23~11 ~106~23~19 minecraft:gold_block
fill ~2~27~12 ~2~27~14 minecraft:iron_block
setblock ~7~20~12 minecraft:stone_button 2
setblock ~8~19~12 minecraft:oak_stairs 4
fill ~8~20~12 ~10~20~12 minecraft:log 0
fill ~8~21~12 ~8~21~13 minecraft:fence 0
fill ~8~22~12 ~8~22~13 minecraft:stone_block_slab 0
setblock ~9~18~12 minecraft:oak_stairs 4
fill ~9~19~12 ~9~19~18 minecraft:planks 0
setblock ~10~17~12 minecraft:oak_stairs 4
fill ~10~18~12 ~12~18~12 minecraft:planks 0
fill ~10~21~12 ~10~21~13 minecraft:iron_bars
setblock ~10~22~12 minecraft:stone_block_slab 0
setblock ~11~16~12 minecraft:oak_stairs 4
fill ~11~17~12 ~12~17~12 minecraft:planks 0
fill ~11~20~12 ~12~20~13 minecraft:planks 0
setblock ~12~15~12 minecraft:oak_stairs 4
fill ~12~16~12 ~12~16~18 minecraft:planks 0
setblock ~13~14~12 minecraft:oak_stairs 4
fill ~13~15~12 ~14~15~12 minecraft:planks 0
fill ~13~17~12 ~14~17~12 minecraft:chest 3
setblock ~13~18~12 minecraft:torch 3
fill ~13~24~12 ~13~24~13 minecraft:fence 0
setblock ~14~13~12 minecraft:oak_stairs 4
fill ~14~14~12 ~15~14~12 minecraft:planks 0
fill ~14~23~12 ~15~23~12 minecraft:planks 0
setblock ~15~12~12 minecraft:oak_stairs 4
fill ~15~13~12 ~16~13~12 minecraft:planks 0
setblock ~15~15~12 minecraft:torch 1
setblock ~15~50~12 minecraft:wool 0
setblock ~16~11~12 minecraft:oak_stairs 4
fill ~16~12~12 ~17~12~12 minecraft:planks 0
setblock ~16~23~12 minecraft:planks 1
setblock ~16~52~12 minecraft:wool 0
setblock ~17~10~12 minecraft:oak_stairs 4
fill ~17~11~12 ~18~11~12 minecraft:planks 0
fill ~17~23~12 ~17~23~18 minecraft:planks 0
fill ~17~24~12 ~21~24~14 minecraft:log 0
fill ~17~25~12 ~18~25~12 minecraft:fence 0
fill ~17~26~12 ~18~26~12 minecraft:stone_block_slab 0
setblock ~17~42~12 minecraft:wool 0
fill ~17~53~12 ~18~53~12 minecraft:wool 0
fill ~18~10~12 ~19~10~12 minecraft:planks 0
setblock ~18~20~12 minecraft:wooden_door 2
setblock ~18~41~12 minecraft:wool 0
fill ~18~54~12 ~19~54~12 minecraft:wool 0
fill ~19~7~12 ~20~7~12 minecraft:planks 0
fill ~19~8~12 ~20~8~12 minecraft:log 0
setblock ~19~9~12 minecraft:log 1
fill ~20~6~12 ~22~6~12 minecraft:planks 0
fill ~20~9~12 ~21~9~14 minecraft:planks 0
fill ~20~17~12 ~21~17~12 minecraft:chest 2
setblock ~20~20~12 minecraft:bed 3
setblock ~20~38~12 minecraft:oak_stairs 6
setblock ~20~40~12 minecraft:wool 0
setblock ~20~56~12 minecraft:oak_stairs 2
setblock ~21~20~12 minecraft:wooden_door 0
fill ~21~56~12 ~24~56~12 minecraft:fence 0
fill ~22~5~12 ~24~5~12 minecraft:planks 0
setblock ~22~20~12 minecraft:wooden_door 2
fill ~22~24~12 ~22~24~13 minecraft:oak_stairs 1
setblock ~23~20~12 minecraft:bed 1
fill ~24~4~12 ~26~4~12 minecraft:planks 0
fill ~24~23~12 ~24~23~14 minecraft:planks 0
fill ~25~9~12 ~25~9~19 minecraft:log 0
fill ~25~10~12 ~25~10~19 minecraft:fence 0
setblock ~25~20~12 minecraft:wooden_door 0
setblock ~25~23~12 minecraft:planks 1
setblock ~25~38~12 minecraft:oak_stairs 6
setblock ~25~56~12 minecraft:oak_stairs 2
setblock ~27~3~12 minecraft:planks 0
fill ~27~19~12 ~31~19~12 minecraft:glass
setblock ~27~21~12 minecraft:planks 0
fill ~28~2~12 ~54~2~12 minecraft:planks 0
fill ~29~3~12 ~29~3~17 minecraft:log 1
fill ~30~3~12 ~30~3~13 minecraft:grass
setblock ~30~21~12 minecraft:oak_stairs 0
fill ~31~3~12 ~38~3~12 minecraft:farmland 7
fill ~31~21~12 ~31~24~12 minecraft:planks 1
setblock ~31~25~12 minecraft:oak_stairs 0
fill ~32~16~12 ~33~16~21 minecraft:stone_block_slab 0
setblock ~32~21~12 minecraft:oak_stairs 1
setblock ~32~23~12 minecraft:oak_stairs 5
fill ~32~24~12 ~32~25~12 minecraft:planks 1
fill ~33~19~12 ~33~19~14 minecraft:stone_button 4
setblock ~33~24~12 minecraft:oak_stairs 5
fill ~33~25~12 ~34~25~12 minecraft:planks 1
fill ~34~16~12 ~37~16~12 minecraft:brick_block
fill ~34~17~12 ~37~17~12 minecraft:brewing_stand 0
fill ~34~18~12 ~37~18~12 minecraft:fence 0
fill ~34~19~12 ~37~19~12 minecraft:brick_block
fill ~34~23~12 ~34~24~12 minecraft:fence 0
setblock ~34~26~12 minecraft:torch 5
setblock ~35~25~12 minecraft:wall_sign 5
fill ~37~20~12 ~37~20~14 minecraft:planks 0
fill ~38~16~12 ~39~16~21 minecraft:stone_block_slab 0
fill ~38~19~12 ~38~19~14 minecraft:stone_button 5
fill ~39~3~12 ~39~3~15 minecraft:water 0
fill ~40~3~12 ~41~3~14 minecraft:dirt 0
fill ~40~4~12 ~41~6~14 minecraft:reeds 0
setblock ~40~20~12 minecraft:log 0
fill ~42~1~12 ~85~1~13 minecraft:planks 0
fill ~42~3~12 ~42~3~15 minecraft:water 0
setblock ~42~14~12 minecraft:oak_stairs 4
setblock ~42~18~12 minecraft:stone_block_slab 5
fill ~43~3~12 ~54~3~18 minecraft:grass
fill ~43~4~12 ~43~6~15 minecraft:reeds 0
setblock ~46~4~12 minecraft:fence_gate 3
setblock ~46~17~12 minecraft:stone_button 2
setblock ~48~15~12 minecraft:stone_button 2
fill ~52~4~12 ~52~4~18 minecraft:fence 0
fill ~56~7~12 ~56~7~18 minecraft:leaves 0
setblock ~56~38~12 minecraft:oak_stairs 6
setblock ~56~56~12 minecraft:oak_stairs 2
fill ~57~8~12 ~58~8~12 minecraft:leaves 0
setblock ~57~40~12 minecraft:wooden_slab 0
fill ~57~56~12 ~60~56~12 minecraft:fence 0
fill ~58~9~12 ~58~9~14 minecraft:leaves 0
setblock ~59~2~12 minecraft:torch 5
fill ~60~5~12 ~60~5~19 minecraft:leaves 0
fill ~60~7~12 ~60~7~19 minecraft:leaves 0
setblock ~61~38~12 minecraft:oak_stairs 6
setblock ~61~56~12 minecraft:oak_stairs 2
fill ~62~7~12 ~62~8~12 minecraft:leaves 0
setblock ~64~2~12 minecraft:torch 5
fill ~64~5~12 ~64~6~19 minecraft:leaves 0
fill ~65~7~12 ~66~7~12 minecraft:leaves 0
fill ~66~8~12 ~66~8~16 minecraft:leaves 0
fill ~68~5~12 ~68~5~18 minecraft:leaves 0
fill ~70~9~12 ~71~9~12 minecraft:leaves 0
fill ~70~10~12 ~70~10~14 minecraft:leaves 0
fill ~71~2~12 ~100~2~12 minecraft:planks 0
fill ~71~3~12 ~75~3~12 minecraft:grass
fill ~72~5~12 ~72~5~19 minecraft:leaves 0
fill ~72~7~12 ~74~7~12 minecraft:leaves 0
fill ~72~8~12 ~72~8~14 minecraft:leaves 0
fill ~74~8~12 ~74~8~14 minecraft:leaves 0
fill ~76~3~12 ~76~3~18 minecraft:log 1
fill ~76~6~12 ~76~6~19 minecraft:leaves 0
fill ~77~3~12 ~77~3~13 minecraft:oak_stairs 1
fill ~79~23~12 ~79~23~20 minecraft:log 0
fill ~80~20~12 ~80~20~13 minecraft:wooden_door 0
fill ~80~22~12 ~80~22~19 minecraft:log 1
fill ~80~23~12 ~80~23~18 minecraft:planks 0
setblock ~82~38~12 minecraft:oak_stairs 6
setblock ~82~56~12 minecraft:oak_stairs 2
fill ~83~56~12 ~85~56~12 minecraft:fence 0
fill ~84~3~12 ~90~3~12 minecraft:gold_block
setblock ~84~23~12 minecraft:planks 0
setblock ~85~17~12 minecraft:fence 0
setblock ~85~23~12 minecraft:log 1
fill ~86~4~12 ~86~4~13 minecraft:gold_block
fill ~86~23~12 ~86~23~13 minecraft:planks 0
setblock ~86~38~12 minecraft:oak_stairs 6
setblock ~86~56~12 minecraft:oak_stairs 2
setblock ~87~16~12 minecraft:stone_brick_stairs 1
setblock ~87~23~12 minecraft:log 1
fill ~87~54~12 ~88~54~12 minecraft:wool 0
fill ~88~23~12 ~99~23~12 minecraft:planks 0
fill ~89~16~12 ~93~16~12 minecraft:bookshelf
fill ~89~17~12 ~93~17~12 minecraft:stone_pressure_plate 0
setblock ~89~20~12 minecraft:stone_button 3
setblock ~89~53~12 minecraft:wool 0
setblock ~90~24~12 minecraft:wooden_door 0
fill ~90~26~12 ~90~26~19 minecraft:planks 1
fill ~91~26~12 ~96~26~12 minecraft:bookshelf
fill ~91~27~12 ~93~27~12 minecraft:planks 0
fill ~92~3~12 ~96~3~12 minecraft:diamond_block
setblock ~92~21~12 minecraft:planks 0
fill ~93~21~12 ~93~21~15 minecraft:bookshelf
setblock ~93~24~12 minecraft:stone_brick_stairs 1
setblock ~94~24~12 minecraft:fence 0
setblock ~94~25~12 minecraft:stone_pressure_plate 0
setblock ~94~27~12 minecraft:log 0
setblock ~95~16~12 minecraft:stone_brick_stairs 0
fill ~95~27~12 ~95~27~18 minecraft:planks 0
fill ~97~24~12 ~97~26~12 minecraft:planks 0
fill ~98~18~12 ~100~18~12 minecraft:wall_sign 3
fill ~98~24~12 ~99~24~12 minecraft:chest 3
fill ~98~26~12 ~101~26~12 minecraft:bookshelf
fill ~99~27~12 ~101~27~12 minecraft:planks 0
fill ~100~3~12 ~100~3~13 minecraft:planks 0
fill ~100~9~12 ~100~9~18 minecraft:planks 0
fill ~100~10~12 ~100~10~13 minecraft:chest 4
setblock ~100~17~12 minecraft:torch 2
fill ~100~20~12 ~101~20~12 minecraft:bookshelf
setblock ~100~21~12 minecraft:bookshelf
fill ~100~22~12 ~101~22~18 minecraft:fence 0
fill ~100~28~12 ~101~28~12 minecraft:stone_block_slab 0
fill ~101~4~12 ~101~7~13 minecraft:planks 0
fill ~101~8~12 ~101~8~14 minecraft:log 0
fill ~101~9~12 ~101~9~13 minecraft:double_stone_block_slab 0
fill ~101~10~12 ~101~10~14 minecraft:wool 3
fill ~101~16~12 ~101~16~14 minecraft:bookshelf
fill ~101~17~12 ~101~18~12 minecraft:bookshelf
fill ~101~19~12 ~101~19~18 minecraft:planks 0
fill ~101~24~12 ~101~25~12 minecraft:bookshelf
fill ~102~5~12 ~102~5~13 minecraft:iron_block
fill ~102~6~12 ~102~8~13 minecraft:glowstone
fill ~102~9~12 ~102~9~13 minecraft:iron_block
setblock ~102~12~12 minecraft:wool 3
fill ~102~16~12 ~102~16~14 minecraft:log 0
fill ~102~17~12 ~102~18~12 minecraft:planks 0
fill ~102~19~12 ~102~19~18 minecraft:log 0
fill ~102~20~12 ~102~22~12 minecraft:planks 0
fill ~102~24~12 ~102~27~12 minecraft:wool 3
fill ~102~28~12 ~102~29~12 minecraft:gold_block
fill ~103~18~12 ~103~18~14 minecraft:oak_stairs 5
fill ~103~19~12 ~103~19~21 minecraft:planks 0
setblock ~103~22~12 minecraft:stone_block_slab 5
fill ~105~16~12 ~105~16~18 minecraft:fence 0
fill ~105~17~12 ~105~17~18 minecraft:stone_block_slab 0
fill ~105~19~12 ~105~19~18 minecraft:planks 0
fill ~105~23~12 ~105~23~18 minecraft:planks 0
fill ~106~19~12 ~106~19~19 minecraft:gold_block
setblock ~7~19~13 minecraft:oak_stairs 4
fill ~7~20~13 ~8~20~13 minecraft:log 0
fill ~7~21~13 ~7~21~14 minecraft:fence 0
fill ~7~22~13 ~7~22~14 minecraft:stone_block_slab 0
setblock ~8~18~13 minecraft:oak_stairs 4
fill ~8~19~13 ~8~19~17 minecraft:planks 0
setblock ~9~17~13 minecraft:oak_stairs 4
fill ~9~18~13 ~10~18~13 minecraft:planks 0
fill ~9~20~13 ~10~20~14 minecraft:planks 0
setblock ~10~16~13 minecraft:oak_stairs 4
fill ~10~17~13 ~11~17~13 minecraft:planks 0
setblock ~10~22~13 minecraft:planks 1
setblock ~11~15~13 minecraft:oak_stairs 4
fill ~11~16~13 ~11~16~17 minecraft:planks 0
setblock ~11~18~13 minecraft:chest 3
setblock ~12~14~13 minecraft:oak_stairs 4
fill ~12~15~13 ~13~15~13 minecraft:planks 0
setblock ~12~17~13 minecraft:chest 3
setblock ~12~21~13 minecraft:wooden_door 2
fill ~12~23~13 ~12~23~17 minecraft:log 0
fill ~12~24~13 ~12~24~17 minecraft:fence 0
setblock ~12~25~13 minecraft:torch 5
fill ~12~47~13 ~12~47~14 minecraft:planks 0
setblock ~13~13~13 minecraft:oak_stairs 4
fill ~13~14~13 ~14~14~13 minecraft:planks 0
setblock ~13~20~13 minecraft:planks 0
fill ~13~23~13 ~14~23~13 minecraft:planks 0
fill ~13~45~13 ~13~49~17 minecraft:wool 0
setblock ~14~12~13 minecraft:oak_stairs 4
fill ~14~13~13 ~15~13~13 minecraft:planks 0
setblock ~14~20~13 minecraft:oak_stairs 1
fill ~14~43~13 ~14~44~17 minecraft:wool 0
fill ~14~50~13 ~14~51~17 minecraft:wool 0
setblock ~15~11~13 minecraft:oak_stairs 4
fill ~15~12~13 ~16~12~13 minecraft:planks 0
setblock ~15~23~13 minecraft:planks 1
fill ~15~24~13 ~15~24~17 minecraft:wall_sign 4
fill ~15~42~13 ~15~42~17 minecraft:wool 0
fill ~15~52~13 ~15~52~17 minecraft:wool 0
setblock ~16~10~13 minecraft:oak_stairs 4
fill ~16~11~13 ~17~11~13 minecraft:planks 0
fill ~16~23~13 ~16~23~17 minecraft:planks 0
fill ~16~24~13 ~16~24~17 minecraft:log 0
fill ~16~25~13 ~17~25~13 minecraft:fence 0
fill ~16~26~13 ~17~26~13 minecraft:stone_block_slab 0
fill ~16~41~13 ~16~41~17 minecraft:wool 0
fill ~16~53~13 ~16~53~17 minecraft:wool 0
fill ~17~10~13 ~18~10~13 minecraft:planks 0
fill ~17~40~13 ~17~40~17 minecraft:wool 0
fill ~17~54~13 ~17~54~17 minecraft:wool 0
fill ~18~7~13 ~19~7~13 minecraft:planks 0
fill ~18~8~13 ~19~8~13 minecraft:log 0
setblock ~18~9~13 minecraft:log 1
fill ~18~39~13 ~19~39~17 minecraft:wool 0
fill ~18~55~13 ~19~55~17 minecraft:wool 0
setblock ~19~6~13 minecraft:planks 0
fill ~19~9~13 ~19~9~17 minecraft:planks 0
fill ~20~5~13 ~22~5~13 minecraft:planks 0
fill ~20~37~13 ~25~37~13 minecraft:wooden_slab 8
fill ~20~38~13 ~86~38~14 minecraft:wool 0
fill ~20~56~13 ~86~56~17 minecraft:wool 0
fill ~20~57~13 ~21~57~13 minecraft:wooden_slab 0
fill ~22~4~13 ~24~4~13 minecraft:planks 0
setblock ~22~57~13 minecraft:oak_stairs 2
fill ~22~58~13 ~22~59~13 minecraft:trapdoor 3
fill ~23~57~13 ~83~57~13 minecraft:wooden_slab 0
fill ~23~60~13 ~83~60~13 minecraft:trapdoor 3
fill ~24~3~13 ~26~3~13 minecraft:planks 0
setblock ~25~23~13 minecraft:planks 0
setblock ~26~15~13 minecraft:oak_stairs 4
setblock ~26~23~13 minecraft:planks 1
setblock ~27~2~13 minecraft:planks 0
fill ~27~18~13 ~30~18~13 minecraft:glass
fill ~27~19~13 ~30~19~13 minecraft:water 0
setblock ~27~21~13 minecraft:oak_stairs 1
fill ~28~1~13 ~41~1~13 minecraft:planks 0
setblock ~28~2~13 minecraft:torch 3
fill ~29~2~13 ~29~2~16 minecraft:planks 1
setblock ~31~2~13 minecraft:torch 3
fill ~31~3~13 ~31~3~14 minecraft:farmland 7
fill ~31~19~13 ~31~19~20 minecraft:glass
setblock ~31~21~13 minecraft:stone_button 3
fill ~32~3~13 ~38~3~13 minecraft:dirt 0
fill ~32~4~13 ~34~4~13 minecraft:melon_block
fill ~32~25~13 ~34~25~13 minecraft:wall_sign 3
fill ~33~2~13 ~34~2~13 minecraft:torch 3
fill ~34~16~13 ~34~16~14 minecraft:brick_block
fill ~34~17~13 ~34~17~14 minecraft:brewing_stand 0
fill ~34~18~13 ~34~18~14 minecraft:fence 0
fill ~34~19~13 ~34~19~14 minecraft:brick_block
setblock ~34~23~13 minecraft:lever 6
fill ~35~4~13 ~38~4~13 minecraft:carved_pumpkin 2
fill ~35~16~13 ~36~16~13 minecraft:water 0
fill ~35~19~13 ~36~19~13 minecraft:fence 0
setblock ~35~22~13 minecraft:oak_stairs 2
setblock ~36~23~13 minecraft:lever 6
setblock ~37~2~13 minecraft:torch 3
fill ~37~16~13 ~37~16~14 minecraft:brick_block
fill ~37~17~13 ~37~17~14 minecraft:brewing_stand 0
fill ~37~18~13 ~37~18~14 minecraft:fence 0
fill ~37~19~13 ~37~19~14 minecraft:brick_block
fill ~39~2~13 ~39~2~15 minecraft:water 8
setblock ~39~20~13 minecraft:log 0
setblock ~40~17~13 minecraft:lever 2
setblock ~40~19~13 minecraft:torch 2
fill ~40~20~13 ~40~20~14 minecraft:planks 0
fill ~42~2~13 ~42~2~15 minecraft:water 8
setblock ~42~17~13 minecraft:lever 1
setblock ~44~2~13 minecraft:torch 3
setblock ~44~21~13 minecraft:stone_block_slab 0
setblock ~45~18~13 minecraft:log 0
setblock ~45~19~13 minecraft:fence 0
fill ~46~4~13 ~46~4~18 minecraft:fence 0
setblock ~46~17~13 minecraft:log 0
setblock ~46~18~13 minecraft:fence 0
setblock ~47~2~13 minecraft:torch 3
setblock ~47~16~13 minecraft:log 0
setblock ~47~17~13 minecraft:fence 0
setblock ~48~15~13 minecraft:log 0
setblock ~48~16~13 minecraft:fence 0
setblock ~49~2~13 minecraft:torch 3
setblock ~49~15~13 minecraft:fence 0
setblock ~52~2~13 minecraft:torch 3
setblock ~53~15~13 minecraft:trapdoor 3
setblock ~54~2~13 minecraft:torch 3
fill ~55~3~13 ~57~3~14 minecraft:grass
fill ~56~6~13 ~57~6~14 minecraft:leaves 0
fill ~56~37~13 ~61~37~13 minecraft:wooden_slab 8
fill ~57~7~13 ~57~7~14 minecraft:leaves 0
fill ~57~8~13 ~57~9~13 minecraft:leaves 0
setblock ~57~26~13 minecraft:wooden_slab 8
setblock ~57~28~13 minecraft:wooden_slab 0
fill ~57~39~13 ~57~39~17 minecraft:planks 0
setblock ~58~3~13 minecraft:dirt 0
fill ~58~4~13 ~58~8~13 minecraft:log 0
fill ~59~3~13 ~61~3~18 minecraft:grass
fill ~59~6~13 ~61~6~19 minecraft:leaves 0
fill ~59~7~13 ~59~7~19 minecraft:leaves 0
fill ~59~8~13 ~59~8~14 minecraft:leaves 0
setblock ~59~9~13 minecraft:leaves 0
fill ~61~5~13 ~61~5~19 minecraft:leaves 0
fill ~61~7~13 ~61~7~14 minecraft:leaves 0
fill ~61~8~13 ~63~8~13 minecraft:leaves 0
setblock ~62~3~13 minecraft:dirt 0
fill ~62~4~13 ~62~7~13 minecraft:log 0
fill ~63~3~13 ~65~3~18 minecraft:grass
fill ~63~5~13 ~63~6~19 minecraft:leaves 0
setblock ~63~7~13 minecraft:leaves 0
setblock ~64~15~13 minecraft:trapdoor 3
fill ~65~5~13 ~65~7~15 minecraft:leaves 0
setblock ~65~8~13 minecraft:leaves 0
setblock ~66~3~13 minecraft:dirt 0
fill ~66~4~13 ~66~7~13 minecraft:log 0
fill ~67~3~13 ~69~3~18 minecraft:grass
fill ~67~5~13 ~67~7~15 minecraft:leaves 0
setblock ~67~8~13 minecraft:leaves 0
fill ~69~7~13 ~69~7~17 minecraft:leaves 0
fill ~69~8~13 ~69~8~15 minecraft:leaves 0
fill ~69~9~13 ~69~9~14 minecraft:leaves 0
setblock ~69~10~13 minecraft:leaves 0
setblock ~69~15~13 minecraft:fence 0
setblock ~70~3~13 minecraft:dirt 0
fill ~70~4~13 ~70~9~13 minecraft:log 0
setblock ~70~15~13 minecraft:log 0
setblock ~70~16~13 minecraft:fence 0
fill ~71~3~13 ~73~3~18 minecraft:grass
fill ~71~7~13 ~73~7~13 minecraft:leaves 0
fill ~71~8~13 ~71~8~15 minecraft:leaves 0
fill ~71~9~13 ~71~9~14 minecraft:leaves 0
setblock ~71~10~13 minecraft:leaves 0
setblock ~71~16~13 minecraft:log 0
setblock ~71~17~13 minecraft:fence 0
fill ~72~6~13 ~73~6~14 minecraft:leaves 0
setblock ~72~17~13 minecraft:log 0
setblock ~72~18~13 minecraft:fence 0
setblock ~73~2~13 minecraft:torch 3
fill ~73~5~13 ~73~5~19 minecraft:leaves 0
setblock ~73~8~13 minecraft:leaves 0
setblock ~73~18~13 minecraft:log 0
setblock ~73~19~13 minecraft:fence 0
setblock ~74~3~13 minecraft:dirt 0
fill ~74~4~13 ~74~7~13 minecraft:log 0
setblock ~74~21~13 minecraft:stone_block_slab 0
setblock ~75~2~13 minecraft:torch 3
fill ~75~3~13 ~75~3~18 minecraft:grass
fill ~75~5~13 ~76~5~18 minecraft:leaves 0
fill ~75~6~13 ~75~6~19 minecraft:leaves 0
fill ~75~7~13 ~75~7~14 minecraft:leaves 0
setblock ~75~8~13 minecraft:leaves 0
setblock ~75~14~13 minecraft:oak_stairs 5
fill ~75~19~13 ~76~19~13 minecraft:planks 0
fill ~76~2~13 ~76~2~17 minecraft:planks 1
setblock ~77~2~13 minecraft:oak_stairs 4
setblock ~77~19~13 minecraft:log 0
setblock ~78~2~13 minecraft:oak_stairs 1
fill ~78~19~13 ~85~19~13 minecraft:planks 0
fill ~79~15~13 ~82~15~13 minecraft:log 0
setblock ~80~2~13 minecraft:torch 3
setblock ~80~14~13 minecraft:log 0
fill ~80~16~13 ~82~16~13 minecraft:fence 0
setblock ~80~17~13 minecraft:torch 5
setblock ~81~13~13 minecraft:log 0
setblock ~81~14~13 minecraft:fence 0
setblock ~82~12~13 minecraft:log 0
setblock ~82~13~13 minecraft:fence 0
fill ~82~37~13 ~86~37~13 minecraft:wooden_slab 8
setblock ~83~2~13 minecraft:torch 3
setblock ~83~11~13 minecraft:log 0
setblock ~83~12~13 minecraft:fence 0
fill ~84~2~13 ~90~2~13 minecraft:gold_block
setblock ~84~10~13 minecraft:log 0
setblock ~84~11~13 minecraft:fence 0
setblock ~84~18~13 minecraft:oak_stairs 4
setblock ~84~23~13 minecraft:log 1
setblock ~84~57~13 minecraft:oak_stairs 2
fill ~84~58~13 ~84~59~13 minecraft:trapdoor 3
fill ~85~3~13 ~87~3~13 minecraft:gold_block
setblock ~85~17~13 minecraft:planks 0
setblock ~85~21~13 minecraft:trapdoor 2
fill ~85~22~13 ~85~23~14 minecraft:planks 0
fill ~85~57~13 ~86~57~13 minecraft:wooden_slab 0
fill ~86~1~13 ~99~1~13 minecraft:planks 0
setblock ~86~17~13 minecraft:torch 1
setblock ~87~16~13 minecraft:wall_sign 3
fill ~87~23~13 ~87~23~14 minecraft:planks 0
fill ~87~39~13 ~88~39~17 minecraft:wool 0
fill ~87~55~13 ~88~55~17 minecraft:wool 0
setblock ~88~23~13 minecraft:log 1
fill ~89~16~13 ~89~16~17 minecraft:bookshelf
fill ~89~17~13 ~89~17~17 minecraft:stone_pressure_plate 0
fill ~89~23~13 ~99~23~13 minecraft:planks 0
fill ~89~40~13 ~89~40~17 minecraft:wool 0
fill ~89~54~13 ~89~54~17 minecraft:wool 0
setblock ~90~14~13 minecraft:oak_stairs 4
fill ~90~16~13 ~92~16~16 minecraft:crafting_table
fill ~90~21~13 ~91~22~13 minecraft:glass_pane
setblock ~90~24~13 minecraft:wooden_door 0
fill ~90~41~13 ~90~41~17 minecraft:wool 0
fill ~90~53~13 ~90~53~17 minecraft:wool 0
setblock ~91~2~13 minecraft:torch 3
setblock ~91~11~13 minecraft:iron_bars
fill ~91~12~13 ~91~12~22 minecraft:planks 0
setblock ~91~20~13 minecraft:stone_block_slab 0
fill ~91~27~13 ~92~27~13 minecraft:planks 0
fill ~91~42~13 ~91~42~17 minecraft:wool 0
fill ~91~52~13 ~91~52~17 minecraft:wool 0
setblock ~92~2~13 minecraft:diamond_block
fill ~92~10~13 ~93~10~13 minecraft:crafting_table
setblock ~92~21~13 minecraft:double_stone_block_slab 0
fill ~92~43~13 ~92~44~17 minecraft:wool 0
fill ~92~50~13 ~92~51~17 minecraft:wool 0
setblock ~93~2~13 minecraft:torch 3
fill ~93~16~13 ~93~16~17 minecraft:bookshelf
fill ~93~17~13 ~93~17~17 minecraft:stone_pressure_plate 0
setblock ~93~24~13 minecraft:wall_sign 3
setblock ~93~27~13 minecraft:log 0
fill ~93~45~13 ~93~49~17 minecraft:wool 0
fill ~93~63~13 ~93~64~13 minecraft:wool 0
fill ~94~2~13 ~95~2~13 minecraft:diamond_block
fill ~94~27~13 ~94~27~17 minecraft:planks 0
fill ~94~47~13 ~94~47~14 minecraft:planks 0
setblock ~95~16~13 minecraft:fence_gate 3
setblock ~96~2~13 minecraft:torch 3
fill ~96~14~13 ~96~14~15 minecraft:web
fill ~96~63~13 ~97~63~13 minecraft:wool 0
fill ~96~64~13 ~97~64~13 minecraft:wool 11
setblock ~97~2~13 minecraft:gold_block
setblock ~97~20~13 minecraft:enchanting_table
setblock ~97~24~13 minecraft:fence_gate 1
fill ~97~26~13 ~97~26~14 minecraft:planks 0
setblock ~98~2~13 minecraft:torch 3
setblock ~99~27~13 minecraft:log 0
setblock ~100~2~13 minecraft:planks 0
setblock ~100~5~13 minecraft:torch 2
setblock ~100~8~13 minecraft:torch 2
fill ~100~18~13 ~100~18~17 minecraft:wall_sign 4
fill ~100~27~13 ~101~27~18 minecraft:planks 0
setblock ~101~3~13 minecraft:planks 0
fill ~101~18~13 ~101~18~18 minecraft:bookshelf
fill ~101~26~13 ~101~26~18 minecraft:bookshelf
fill ~101~28~13 ~101~28~18 minecraft:stone_block_slab 0
setblock ~102~11~13 minecraft:stone_block_slab 11
setblock ~102~12~13 minecraft:dispenser 5
setblock ~102~14~13 minecraft:torch 2
setblock ~102~17~13 minecraft:glass
