fill ~2 ~0 ~17 ~12 ~0 ~17 stone 6  
fill ~2 ~0 ~18 ~12 ~0 ~18 stone 6  
fill ~2 ~0 ~19 ~11 ~0 ~19 stone 6  
fill ~2 ~0 ~20 ~10 ~0 ~20 stone 6  
fill ~2 ~0 ~21 ~5 ~0 ~21 stone 6  
fill ~2 ~0 ~22 ~5 ~0 ~22 stone 6  
fill ~2 ~0 ~23 ~5 ~0 ~23 stone 6  
fill ~2 ~0 ~24 ~5 ~0 ~24 stone 6  
fill ~2 ~0 ~25 ~5 ~0 ~25 stone 6  
fill ~2 ~0 ~26 ~5 ~0 ~26 stone 6  
fill ~2 ~0 ~27 ~5 ~0 ~27 stone 6  
fill ~2 ~0 ~28 ~5 ~0 ~28 stone 6  
fill ~2 ~0 ~29 ~5 ~0 ~29 stone 6  
fill ~2 ~0 ~30 ~5 ~0 ~30 stone 6  
fill ~2 ~0 ~31 ~5 ~0 ~31 stone 6  
fill ~2 ~0 ~32 ~5 ~0 ~32 stone 6  
fill ~2 ~0 ~33 ~5 ~0 ~33 stone 6  
fill ~2 ~0 ~34 ~5 ~0 ~34 stone 6  
fill ~2 ~0 ~35 ~5 ~0 ~35 stone 6  
fill ~2 ~0 ~36 ~4 ~0 ~36 stone 6  
fill ~2 ~0 ~37 ~3 ~0 ~37 stone 6  
fill ~2 ~0 ~38 ~5 ~0 ~38 stone 6  
fill ~2 ~0 ~39 ~7 ~0 ~39 stone 6  
fill ~3 ~0 ~40 ~18 ~0 ~40 stone 6  
fill ~3 ~0 ~41 ~18 ~0 ~41 stone 6  
fill ~5 ~0 ~42 ~12 ~0 ~42 stone 6 
setblock ~7 ~0 ~31 torch 5 
setblock ~7 ~0 ~35 torch 5  
fill ~7 ~0 ~43 ~10 ~0 ~43 stone 6 
setblock ~8 ~0 ~24 torch 5  
fill ~8 ~0 ~36 ~18 ~0 ~36 stone 6  
fill ~8 ~0 ~37 ~18 ~0 ~37 stone 6  
fill ~8 ~0 ~38 ~18 ~0 ~38 stone 6  
fill ~9 ~0 ~34 ~18 ~0 ~34 stone 6  
fill ~9 ~0 ~35 ~18 ~0 ~35 stone 6  
fill ~9 ~0 ~39 ~18 ~0 ~39 stone 6 
setblock ~10 ~0 ~26 torch 5 
setblock ~10 ~0 ~29 torch 5  
fill ~10 ~0 ~33 ~18 ~0 ~33 stone 6  
fill ~11 ~0 ~8 ~16 ~0 ~8 stone 6  
fill ~11 ~0 ~9 ~16 ~0 ~9 stone 6  
fill ~11 ~0 ~10 ~16 ~0 ~10 stone 6  
fill ~11 ~0 ~11 ~16 ~0 ~11 stone 6  
fill ~11 ~0 ~12 ~16 ~0 ~12 stone 6  
fill ~11 ~0 ~13 ~17 ~0 ~13 stone 6  
fill ~11 ~0 ~14 ~12 ~0 ~14 stone 6 
setblock ~11 ~0 ~22 torch 5  
fill ~11 ~0 ~32 ~12 ~0 ~32 stone 6  
fill ~12 ~0 ~4 ~18 ~0 ~4 stone 6  
fill ~12 ~0 ~5 ~18 ~0 ~5 stone 6  
fill ~12 ~0 ~6 ~17 ~0 ~6 stone 6  
fill ~12 ~0 ~7 ~17 ~0 ~7 stone 6  
fill ~12 ~0 ~15 ~12 ~5 ~15 stone 6  
fill ~12 ~0 ~16 ~12 ~5 ~16 stone 6 
setblock ~12 ~0 ~26 torch 5  
fill ~13 ~0 ~2 ~13 ~0 ~13 stone 6  
fill ~13 ~0 ~64 ~18 ~0 ~64 stone 6  
fill ~13 ~0 ~65 ~18 ~0 ~65 stone 6  
fill ~13 ~0 ~66 ~18 ~0 ~66 stone 6  
fill ~13 ~0 ~67 ~18 ~0 ~67 stone 6  
fill ~13 ~0 ~68 ~18 ~0 ~68 stone 6  
fill ~13 ~0 ~69 ~18 ~0 ~69 stone 6 
setblock ~14 ~0 ~0 stone_brick_stairs 2 
setblock ~14 ~0 ~1 stone 6  
fill ~14 ~0 ~2 ~18 ~0 ~2 stonebrick 0  
fill ~14 ~0 ~3 ~19 ~0 ~3 stonebrick 0  
fill ~14 ~0 ~14 ~18 ~0 ~14 stone 6 
setblock ~14 ~0 ~20 torch 5 
setblock ~14 ~0 ~24 torch 5 
setblock ~14 ~0 ~30 torch 5  
fill ~14 ~0 ~42 ~17 ~0 ~42 stone 6  
fill ~14 ~0 ~43 ~17 ~0 ~43 stone 6  
fill ~14 ~0 ~44 ~17 ~0 ~44 stone 6  
fill ~14 ~0 ~45 ~17 ~0 ~45 stone 6  
fill ~14 ~0 ~46 ~17 ~0 ~46 stone 6  
fill ~14 ~0 ~47 ~17 ~0 ~47 stone 6  
fill ~14 ~0 ~48 ~17 ~0 ~48 stone 6  
fill ~14 ~0 ~49 ~17 ~0 ~49 stone 6  
fill ~14 ~0 ~50 ~17 ~0 ~50 stone 6  
fill ~14 ~0 ~51 ~17 ~0 ~51 stone 6  
fill ~14 ~0 ~52 ~17 ~0 ~52 stone 6  
fill ~14 ~0 ~53 ~17 ~0 ~53 stone 6  
fill ~14 ~0 ~54 ~17 ~0 ~54 stone 6  
fill ~14 ~0 ~55 ~17 ~0 ~55 stone 6  
fill ~14 ~0 ~56 ~17 ~0 ~56 stone 6  
fill ~14 ~0 ~57 ~17 ~0 ~57 stone 6  
fill ~14 ~0 ~58 ~17 ~0 ~58 stone 6  
fill ~14 ~0 ~59 ~17 ~0 ~59 stone 6  
fill ~14 ~0 ~60 ~17 ~0 ~60 stone 6  
fill ~14 ~0 ~61 ~17 ~0 ~61 stone 6  
fill ~14 ~0 ~62 ~18 ~0 ~62 stone 6  
fill ~14 ~0 ~63 ~18 ~0 ~63 stone 6  
fill ~14 ~0 ~70 ~18 ~0 ~70 stone 6  
fill ~15 ~0 ~1 ~19 ~0 ~1 stone_slab 5  
fill ~15 ~0 ~15 ~19 ~0 ~15 stone 6 
setblock ~15 ~0 ~17 torch 5  
fill ~15 ~0 ~71 ~37 ~0 ~71 stone 6  
fill ~16 ~0 ~16 ~21 ~0 ~16 stone 6 
setblock ~16 ~0 ~28 torch 5  
fill ~16 ~0 ~32 ~18 ~0 ~32 stone 6  
fill ~17 ~0 ~8 ~19 ~0 ~8 dirt 1  
fill ~17 ~0 ~9 ~20 ~0 ~9 dirt 1  
fill ~17 ~0 ~10 ~20 ~0 ~10 dirt 1  
fill ~17 ~0 ~11 ~21 ~0 ~11 dirt 1  
fill ~17 ~0 ~12 ~22 ~0 ~12 dirt 1  
fill ~17 ~0 ~17 ~24 ~0 ~17 stone 6 
setblock ~17 ~0 ~23 torch 5  
fill ~17 ~0 ~31 ~61 ~0 ~31 stone 6  
fill ~18 ~0 ~6 ~19 ~0 ~6 dirt 1  
fill ~18 ~0 ~7 ~19 ~0 ~7 dirt 1  
fill ~18 ~0 ~13 ~23 ~0 ~13 dirt 1  
fill ~18 ~0 ~21 ~18 ~0 ~22 torch 5  
fill ~18 ~0 ~30 ~61 ~0 ~30 stone 6  
fill ~18 ~0 ~42 ~59 ~0 ~42 stonebrick 0  
fill ~18 ~0 ~43 ~59 ~0 ~43 stonebrick 0  
fill ~18 ~0 ~44 ~59 ~0 ~44 stonebrick 0  
fill ~18 ~0 ~45 ~59 ~0 ~45 stonebrick 0  
fill ~18 ~0 ~46 ~59 ~0 ~46 stonebrick 0  
fill ~18 ~0 ~47 ~59 ~0 ~47 stonebrick 0  
fill ~18 ~0 ~48 ~59 ~0 ~48 stonebrick 0  
fill ~18 ~0 ~49 ~59 ~0 ~49 stonebrick 0  
fill ~18 ~0 ~50 ~59 ~0 ~50 stonebrick 0  
fill ~18 ~0 ~51 ~59 ~0 ~51 stonebrick 0  
fill ~18 ~0 ~52 ~59 ~0 ~52 stonebrick 0  
fill ~18 ~0 ~53 ~59 ~0 ~53 stonebrick 0  
fill ~18 ~0 ~54 ~59 ~0 ~54 stonebrick 0  
fill ~18 ~0 ~55 ~59 ~0 ~55 stonebrick 0  
fill ~18 ~0 ~56 ~59 ~0 ~56 stonebrick 0  
fill ~18 ~0 ~57 ~59 ~0 ~57 stonebrick 0  
fill ~18 ~0 ~58 ~59 ~0 ~58 stonebrick 0  
fill ~18 ~0 ~59 ~59 ~0 ~59 stonebrick 0  
fill ~18 ~0 ~60 ~59 ~0 ~60 stonebrick 0  
fill ~18 ~0 ~61 ~59 ~0 ~61 stonebrick 0  
fill ~19 ~0 ~2 ~20 ~0 ~2 stone_slab 5  
fill ~19 ~0 ~4 ~19 ~0 ~5 stonebrick 0  
fill ~19 ~0 ~14 ~25 ~0 ~14 dirt 1  
fill ~19 ~0 ~18 ~28 ~0 ~18 stone 6  
fill ~19 ~0 ~32 ~58 ~0 ~32 stonebrick 0  
fill ~19 ~0 ~33 ~58 ~0 ~33 stonebrick 0  
fill ~19 ~0 ~34 ~58 ~0 ~34 stonebrick 0  
fill ~19 ~0 ~35 ~58 ~0 ~35 stonebrick 0  
fill ~19 ~0 ~36 ~58 ~0 ~36 stonebrick 0  
fill ~19 ~0 ~37 ~58 ~0 ~37 stonebrick 0  
fill ~19 ~0 ~38 ~58 ~0 ~38 stonebrick 0  
fill ~19 ~0 ~39 ~58 ~0 ~39 stonebrick 0  
fill ~19 ~0 ~40 ~58 ~0 ~40 stonebrick 0  
fill ~19 ~0 ~41 ~58 ~0 ~41 stonebrick 0  
fill ~19 ~0 ~62 ~58 ~0 ~62 stonebrick 0  
fill ~19 ~0 ~63 ~58 ~0 ~63 stonebrick 0  
fill ~19 ~0 ~64 ~58 ~0 ~64 stonebrick 0  
fill ~19 ~0 ~65 ~58 ~0 ~65 stonebrick 0  
fill ~19 ~0 ~66 ~58 ~0 ~66 stonebrick 0  
fill ~19 ~0 ~67 ~58 ~0 ~67 stonebrick 0  
fill ~19 ~0 ~68 ~58 ~0 ~68 stonebrick 0  
fill ~19 ~0 ~69 ~58 ~0 ~69 stonebrick 0  
fill ~19 ~0 ~70 ~58 ~0 ~70 stonebrick 0  
fill ~19 ~0 ~98 ~51 ~0 ~98 stone 6  
fill ~19 ~0 ~104 ~51 ~0 ~104 stone 6  
fill ~20 ~0 ~3 ~20 ~0 ~4 stone_slab 5  
fill ~20 ~0 ~5 ~20 ~0 ~8 stone 6  
fill ~20 ~0 ~15 ~31 ~0 ~15 dirt 1  
fill ~20 ~0 ~19 ~32 ~0 ~19 stone 6  
fill ~20 ~0 ~93 ~31 ~0 ~93 stone 6  
fill ~20 ~0 ~94 ~31 ~0 ~94 stone 6  
fill ~20 ~0 ~95 ~23 ~0 ~95 stone 6  
fill ~20 ~0 ~96 ~23 ~0 ~96 stone 6  
fill ~20 ~0 ~97 ~23 ~0 ~97 stone 6  
fill ~20 ~0 ~99 ~46 ~0 ~99 stone 6  
fill ~20 ~0 ~100 ~34 ~0 ~100 stone 6  
fill ~20 ~0 ~101 ~34 ~0 ~101 stone 6  
fill ~20 ~0 ~102 ~39 ~0 ~102 stone 6  
fill ~20 ~0 ~103 ~51 ~0 ~103 stone 6  
fill ~20 ~0 ~105 ~56 ~0 ~105 stone 6  
fill ~20 ~0 ~106 ~23 ~0 ~106 stone 6  
fill ~20 ~0 ~107 ~23 ~0 ~107 stone 6  
fill ~20 ~0 ~108 ~24 ~0 ~108 stone 6  
fill ~20 ~0 ~109 ~41 ~0 ~109 stone 6 
setblock ~21 ~0 ~5 stone_brick_stairs 1  
fill ~21 ~0 ~9 ~21 ~0 ~10 stone 6 
setblock ~21 ~0 ~22 torch 5 
setblock ~21 ~0 ~26 torch 5  
fill ~21 ~0 ~29 ~23 ~0 ~29 stone 6  
fill ~21 ~0 ~92 ~33 ~0 ~92 stone 6  
fill ~21 ~0 ~110 ~41 ~0 ~110 stone 6 
setblock ~22 ~0 ~11 stone 6  
fill ~22 ~0 ~16 ~31 ~0 ~16 dirt 1  
fill ~22 ~0 ~91 ~54 ~0 ~91 stone 6  
fill ~22 ~0 ~111 ~41 ~0 ~111 stone 6 
setblock ~23 ~0 ~12 stone 6  
fill ~23 ~0 ~20 ~55 ~0 ~20 stone 6  
fill ~24 ~0 ~13 ~25 ~0 ~13 stone 6 
setblock ~24 ~0 ~23 torch 5 
setblock ~24 ~0 ~27 torch 5  
fill ~24 ~0 ~72 ~37 ~0 ~72 stone 6  
fill ~24 ~0 ~90 ~52 ~0 ~90 stone 6  
fill ~24 ~0 ~112 ~52 ~0 ~112 stone 6  
fill ~25 ~0 ~17 ~31 ~0 ~17 dirt 1 
setblock ~25 ~0 ~25 torch 5  
fill ~25 ~0 ~73 ~37 ~0 ~73 stone 6  
fill ~25 ~0 ~74 ~28 ~0 ~74 stone 6  
fill ~25 ~0 ~95 ~29 ~0 ~95 stone 6  
fill ~25 ~0 ~97 ~28 ~0 ~97 stone 6  
fill ~25 ~0 ~106 ~34 ~0 ~106 stone 6  
fill ~25 ~0 ~107 ~33 ~0 ~107 stone 6  
fill ~26 ~0 ~14 ~29 ~0 ~14 stone 6  
fill ~26 ~0 ~75 ~29 ~0 ~75 stone 6  
fill ~26 ~0 ~76 ~30 ~0 ~76 stone 6  
fill ~26 ~0 ~108 ~37 ~0 ~108 stone 6  
fill ~27 ~0 ~21 ~37 ~0 ~21 stone 6 
setblock ~27 ~0 ~24 torch 5  
fill ~27 ~0 ~77 ~31 ~0 ~77 stone 6  
fill ~27 ~0 ~87 ~31 ~0 ~87 stone 6  
fill ~27 ~0 ~88 ~30 ~0 ~88 stone 6  
fill ~27 ~0 ~89 ~49 ~0 ~89 stone 6  
fill ~27 ~0 ~113 ~49 ~0 ~113 stone 6  
fill ~27 ~0 ~114 ~49 ~0 ~114 stone 6  
fill ~27 ~0 ~115 ~35 ~0 ~115 stone 6 
setblock ~28 ~0 ~27 torch 5  
fill ~28 ~0 ~78 ~32 ~0 ~78 stone 6  
fill ~28 ~0 ~86 ~31 ~0 ~86 stone 6  
fill ~28 ~0 ~116 ~48 ~0 ~116 stone 6  
fill ~28 ~0 ~117 ~48 ~0 ~117 stone 6  
fill ~29 ~0 ~18 ~31 ~0 ~18 dirt 1  
fill ~29 ~0 ~22 ~35 ~0 ~22 stone 6  
fill ~29 ~0 ~79 ~32 ~0 ~79 stone 6  
fill ~29 ~0 ~85 ~31 ~0 ~85 stone 6  
fill ~29 ~0 ~118 ~47 ~0 ~118 stone 6 
setblock ~30 ~0 ~13 stone_brick_stairs 2  
fill ~30 ~0 ~14 ~32 ~0 ~14 stonebrick 0 
setblock ~30 ~0 ~26 torch 5 
setblock ~30 ~0 ~74 torch 3  
fill ~30 ~0 ~80 ~37 ~0 ~80 stone 6  
fill ~30 ~0 ~84 ~37 ~0 ~84 stone 6  
fill ~30 ~0 ~119 ~46 ~0 ~119 stone 6 
setblock ~31 ~0 ~12 stone_brick_stairs 2  
fill ~31 ~0 ~13 ~32 ~0 ~13 stonebrick 0  
fill ~31 ~0 ~23 ~32 ~0 ~23 stone 6 
setblock ~31 ~0 ~28 torch 5  
fill ~31 ~0 ~97 ~51 ~0 ~97 stone 6 
setblock ~32 ~0 ~11 stone_brick_stairs 2  
fill ~32 ~0 ~12 ~32 ~16 ~12 stonebrick 0  
fill ~32 ~0 ~15 ~32 ~0 ~23 stone 6 
setblock ~32 ~0 ~25 torch 5  
fill ~32 ~0 ~81 ~37 ~0 ~81 stone 6  
fill ~32 ~0 ~83 ~37 ~0 ~83 stone 6  
fill ~32 ~0 ~88 ~49 ~0 ~88 stone 6  
fill ~33 ~0 ~12 ~33 ~0 ~14 stone_brick_stairs 1 
setblock ~33 ~0 ~74 torch 5  
fill ~33 ~0 ~82 ~37 ~0 ~82 stone 6  
fill ~33 ~0 ~85 ~37 ~0 ~85 stone 6  
fill ~33 ~0 ~87 ~44 ~0 ~87 stone 6  
fill ~33 ~0 ~96 ~41 ~0 ~96 stone 6 
setblock ~34 ~0 ~27 torch 5  
fill ~34 ~0 ~74 ~37 ~0 ~74 stone 6  
fill ~34 ~0 ~75 ~37 ~0 ~75 stone 6  
fill ~34 ~0 ~76 ~37 ~0 ~76 stone 6  
fill ~34 ~0 ~77 ~37 ~0 ~77 stone 6  
fill ~34 ~0 ~78 ~37 ~0 ~78 stone 6  
fill ~34 ~0 ~79 ~37 ~0 ~79 stone 6  
fill ~34 ~0 ~86 ~49 ~0 ~86 stone 6 
setblock ~35 ~0 ~25 torch 5  
fill ~35 ~0 ~92 ~55 ~0 ~92 stone 6  
fill ~35 ~0 ~120 ~35 ~7 ~120 stone 6 
setblock ~36 ~0 ~24 torch 5  
fill ~36 ~0 ~100 ~39 ~0 ~100 stone 6  
fill ~36 ~0 ~101 ~37 ~0 ~101 stone 6  
fill ~36 ~0 ~106 ~51 ~0 ~106 stone 6 
setblock ~38 ~0 ~23 torch 5 
setblock ~38 ~0 ~26 torch 5  
fill ~38 ~0 ~71 ~39 ~0 ~71 stonebrick 0  
fill ~38 ~0 ~72 ~40 ~0 ~72 stonebrick 0  
fill ~38 ~0 ~73 ~39 ~0 ~73 stonebrick 0  
fill ~38 ~0 ~74 ~39 ~0 ~74 stonebrick 0  
fill ~38 ~0 ~75 ~39 ~0 ~75 stonebrick 0  
fill ~38 ~0 ~76 ~39 ~0 ~76 stonebrick 0  
fill ~38 ~0 ~77 ~39 ~0 ~77 stonebrick 0  
fill ~38 ~0 ~78 ~39 ~0 ~78 stonebrick 0  
fill ~38 ~0 ~79 ~39 ~0 ~79 stonebrick 0  
fill ~38 ~0 ~80 ~39 ~0 ~80 stonebrick 0  
fill ~38 ~0 ~81 ~39 ~0 ~81 stonebrick 0  
fill ~38 ~0 ~82 ~40 ~0 ~82 stonebrick 0  
fill ~38 ~0 ~83 ~39 ~0 ~83 stonebrick 0  
fill ~38 ~0 ~84 ~39 ~0 ~84 stonebrick 0  
fill ~38 ~0 ~85 ~39 ~0 ~85 stonebrick 0  
fill ~38 ~0 ~93 ~56 ~0 ~93 stone 6  
fill ~38 ~0 ~95 ~42 ~0 ~95 stone 6  
fill ~38 ~0 ~101 ~38 ~4 ~101 planks 1  
fill ~39 ~0 ~21 ~50 ~0 ~21 stone 6 
setblock ~39 ~0 ~28 torch 5  
fill ~39 ~0 ~94 ~43 ~0 ~94 stone 6  
fill ~39 ~0 ~107 ~40 ~0 ~107 stone 6  
fill ~40 ~0 ~71 ~61 ~0 ~71 stone 6  
fill ~40 ~0 ~73 ~45 ~0 ~73 stone 6  
fill ~40 ~0 ~74 ~44 ~0 ~74 stone 6  
fill ~40 ~0 ~75 ~44 ~0 ~75 stone 6  
fill ~40 ~0 ~76 ~50 ~0 ~76 stone 6  
fill ~40 ~0 ~77 ~49 ~0 ~77 stone 6  
fill ~40 ~0 ~78 ~48 ~0 ~78 stone 6  
fill ~40 ~0 ~79 ~47 ~0 ~79 stone 6  
fill ~40 ~0 ~80 ~46 ~0 ~80 stone 6  
fill ~40 ~0 ~81 ~44 ~0 ~81 stone 6  
fill ~40 ~0 ~83 ~44 ~0 ~83 stone 6  
fill ~40 ~0 ~84 ~46 ~0 ~84 stone 6  
fill ~40 ~0 ~85 ~47 ~0 ~85 stone 6  
fill ~41 ~0 ~22 ~44 ~0 ~22 stone 6  
fill ~41 ~0 ~72 ~52 ~0 ~72 stone 6  
fill ~41 ~0 ~82 ~43 ~0 ~82 stone 6  
fill ~41 ~0 ~100 ~46 ~0 ~100 stone 6  
fill ~41 ~0 ~101 ~46 ~0 ~101 stone 6  
fill ~41 ~0 ~102 ~51 ~0 ~102 stone 6  
fill ~41 ~0 ~120 ~41 ~7 ~120 stone 6 
setblock ~42 ~0 ~26 torch 5 
setblock ~42 ~0 ~28 torch 5  
fill ~43 ~0 ~12 ~43 ~0 ~14 stone_brick_stairs 0 
setblock ~43 ~0 ~25 torch 5  
fill ~43 ~0 ~96 ~51 ~0 ~96 stone 6 
setblock ~44 ~0 ~11 stone_brick_stairs 2  
fill ~44 ~0 ~12 ~44 ~16 ~12 stonebrick 0  
fill ~44 ~0 ~13 ~45 ~0 ~13 stonebrick 0  
fill ~44 ~0 ~14 ~46 ~0 ~14 stonebrick 0  
fill ~44 ~0 ~15 ~44 ~0 ~22 stone 6 
setblock ~44 ~0 ~24 torch 5  
fill ~44 ~0 ~107 ~51 ~0 ~107 stone 6  
fill ~44 ~0 ~108 ~51 ~0 ~108 stone 6 
setblock ~45 ~0 ~12 stone_brick_stairs 2  
fill ~45 ~0 ~15 ~56 ~0 ~15 dirt 1  
fill ~45 ~0 ~16 ~54 ~0 ~16 dirt 1  
fill ~45 ~0 ~17 ~51 ~0 ~17 dirt 1  
fill ~45 ~0 ~18 ~47 ~0 ~18 dirt 1  
fill ~45 ~0 ~19 ~56 ~0 ~19 stone 6  
fill ~45 ~0 ~94 ~48 ~0 ~94 stone 6  
fill ~45 ~0 ~109 ~51 ~0 ~109 stone 6  
fill ~45 ~0 ~110 ~55 ~0 ~110 stone 6  
fill ~45 ~0 ~111 ~54 ~0 ~111 stone 6 
setblock ~46 ~0 ~13 stone_brick_stairs 2 
setblock ~46 ~0 ~25 torch 5  
fill ~46 ~0 ~87 ~49 ~0 ~87 stone 6  
fill ~46 ~0 ~95 ~50 ~0 ~95 stone 6  
fill ~46 ~0 ~115 ~49 ~0 ~115 stone 6  
fill ~47 ~0 ~14 ~50 ~0 ~14 stone 6 
setblock ~47 ~0 ~27 torch 5  
fill ~47 ~0 ~75 ~50 ~0 ~75 stone 6  
fill ~48 ~0 ~18 ~58 ~0 ~18 stone 6  
fill ~48 ~0 ~73 ~51 ~0 ~73 stone 6  
fill ~48 ~0 ~74 ~51 ~0 ~74 stone 6  
fill ~48 ~0 ~99 ~51 ~0 ~99 stone 6  
fill ~48 ~0 ~100 ~51 ~0 ~100 stone 6  
fill ~48 ~0 ~101 ~51 ~0 ~101 stone 6 
setblock ~49 ~0 ~26 torch 5  
fill ~51 ~0 ~13 ~52 ~0 ~13 stone 6  
fill ~51 ~0 ~14 ~57 ~0 ~14 dirt 1 
setblock ~51 ~0 ~26 torch 5  
fill ~51 ~0 ~80 ~52 ~0 ~80 stone 6  
fill ~51 ~0 ~81 ~52 ~0 ~81 stone 6  
fill ~51 ~0 ~82 ~52 ~0 ~82 stone 6  
fill ~51 ~0 ~83 ~52 ~0 ~83 stone 6  
fill ~51 ~0 ~84 ~52 ~0 ~84 stone 6  
fill ~52 ~0 ~17 ~59 ~0 ~17 stone 6  
fill ~52 ~0 ~78 ~53 ~0 ~78 stone 6  
fill ~52 ~0 ~79 ~53 ~0 ~79 stone 6  
fill ~52 ~0 ~85 ~53 ~0 ~85 stone 6  
fill ~52 ~0 ~86 ~53 ~0 ~86 stone 6  
fill ~52 ~0 ~94 ~56 ~0 ~94 stone 6  
fill ~52 ~0 ~108 ~52 ~1 ~108 dirt 0  
fill ~52 ~0 ~109 ~52 ~1 ~109 dirt 0 
setblock ~53 ~0 ~12 stone 6  
fill ~53 ~0 ~13 ~58 ~0 ~13 dirt 1 
setblock ~53 ~0 ~22 torch 5 
setblock ~53 ~0 ~25 torch 5  
fill ~53 ~0 ~77 ~54 ~0 ~77 stone 6  
fill ~53 ~0 ~87 ~54 ~0 ~87 stone 6  
fill ~53 ~0 ~95 ~56 ~0 ~95 stone 6  
fill ~53 ~0 ~96 ~56 ~0 ~96 stone 6  
fill ~53 ~0 ~97 ~56 ~0 ~97 stone 6  
fill ~53 ~0 ~98 ~57 ~0 ~98 stone 6  
fill ~53 ~0 ~99 ~56 ~0 ~99 stone 6  
fill ~53 ~0 ~100 ~56 ~0 ~100 stone 6  
fill ~53 ~0 ~101 ~56 ~0 ~101 stone 6  
fill ~53 ~0 ~102 ~56 ~0 ~102 stone 6  
fill ~53 ~0 ~103 ~56 ~0 ~103 stone 6  
fill ~53 ~0 ~104 ~57 ~0 ~104 stone 6  
fill ~53 ~0 ~106 ~56 ~0 ~106 stone 6  
fill ~53 ~0 ~107 ~56 ~0 ~107 stone 6  
fill ~53 ~0 ~108 ~56 ~0 ~108 stone 6  
fill ~53 ~0 ~109 ~56 ~0 ~109 stone 6 
setblock ~54 ~0 ~11 stone 6  
fill ~54 ~0 ~12 ~59 ~0 ~12 dirt 1  
fill ~54 ~0 ~76 ~56 ~0 ~76 stone 6  
fill ~54 ~0 ~88 ~56 ~0 ~88 stone 6 
setblock ~55 ~0 ~5 stone_brick_stairs 0  
fill ~55 ~0 ~9 ~55 ~0 ~10 stone 6  
fill ~55 ~0 ~11 ~59 ~0 ~11 dirt 1  
fill ~55 ~0 ~16 ~60 ~0 ~16 stone 6 
setblock ~55 ~0 ~23 torch 5  
fill ~55 ~0 ~29 ~59 ~0 ~29 stone 6  
fill ~55 ~0 ~75 ~63 ~0 ~75 stone 6  
fill ~55 ~0 ~89 ~66 ~0 ~89 stone 6  
fill ~56 ~0 ~2 ~57 ~0 ~2 stone_slab 5  
fill ~56 ~0 ~3 ~56 ~0 ~4 stone_slab 5  
fill ~56 ~0 ~5 ~56 ~0 ~8 stone 6  
fill ~56 ~0 ~9 ~59 ~0 ~9 dirt 1  
fill ~56 ~0 ~10 ~59 ~0 ~10 dirt 1  
fill ~57 ~0 ~1 ~61 ~0 ~1 stone_slab 5  
fill ~57 ~0 ~3 ~62 ~0 ~3 stonebrick 0  
fill ~57 ~0 ~4 ~57 ~0 ~5 stonebrick 0  
fill ~57 ~0 ~6 ~58 ~0 ~6 dirt 1  
fill ~57 ~0 ~7 ~58 ~0 ~7 dirt 1  
fill ~57 ~0 ~8 ~59 ~0 ~8 dirt 1  
fill ~57 ~0 ~15 ~61 ~0 ~15 stone 6  
fill ~57 ~0 ~74 ~61 ~0 ~74 stone 6  
fill ~57 ~0 ~90 ~65 ~0 ~90 stone 6  
fill ~58 ~0 ~2 ~62 ~0 ~2 stonebrick 0  
fill ~58 ~0 ~4 ~64 ~0 ~4 stone 6  
fill ~58 ~0 ~5 ~64 ~0 ~5 stone 6  
fill ~58 ~0 ~14 ~62 ~0 ~14 stone 6 
setblock ~58 ~0 ~23 torch 5  
fill ~59 ~0 ~6 ~64 ~0 ~6 stone 6  
fill ~59 ~0 ~7 ~64 ~0 ~7 stone 6  
fill ~59 ~0 ~13 ~65 ~0 ~13 stone 6 
setblock ~59 ~0 ~25 torch 5  
fill ~59 ~0 ~32 ~61 ~0 ~32 stone 6  
fill ~59 ~0 ~33 ~61 ~0 ~33 stone 6  
fill ~59 ~0 ~34 ~61 ~0 ~34 stone 6  
fill ~59 ~0 ~35 ~61 ~0 ~35 stone 6  
fill ~59 ~0 ~36 ~61 ~0 ~36 stone 6  
fill ~59 ~0 ~37 ~61 ~0 ~37 stone 6  
fill ~59 ~0 ~38 ~67 ~0 ~38 stone 6  
fill ~59 ~0 ~39 ~73 ~0 ~39 stone 6  
fill ~59 ~0 ~40 ~73 ~0 ~40 stone 6  
fill ~59 ~0 ~41 ~72 ~0 ~41 stone 6  
fill ~59 ~0 ~62 ~62 ~0 ~62 stone 6  
fill ~59 ~0 ~63 ~62 ~0 ~63 stone 6  
fill ~59 ~0 ~64 ~63 ~0 ~64 stone 6  
fill ~59 ~0 ~65 ~63 ~0 ~65 stone 6  
fill ~59 ~0 ~66 ~63 ~0 ~66 stone 6  
fill ~59 ~0 ~67 ~63 ~0 ~67 stone 6  
fill ~59 ~0 ~68 ~63 ~0 ~68 stone 6  
fill ~59 ~0 ~69 ~63 ~0 ~69 stone 6  
fill ~59 ~0 ~70 ~62 ~0 ~70 stone 6  
fill ~60 ~0 ~8 ~65 ~0 ~8 stone 6  
fill ~60 ~0 ~9 ~65 ~0 ~9 stone 6  
fill ~60 ~0 ~10 ~65 ~0 ~10 stone 6  
fill ~60 ~0 ~11 ~65 ~0 ~11 stone 6  
fill ~60 ~0 ~12 ~65 ~0 ~12 stone 6  
fill ~60 ~0 ~42 ~62 ~0 ~42 stone 6  
fill ~60 ~0 ~43 ~62 ~0 ~43 stone 6  
fill ~60 ~0 ~44 ~62 ~0 ~44 stone 6  
fill ~60 ~0 ~45 ~62 ~0 ~45 stone 6  
fill ~60 ~0 ~46 ~62 ~0 ~46 stone 6  
fill ~60 ~0 ~47 ~62 ~0 ~47 stone 6  
fill ~60 ~0 ~48 ~62 ~0 ~48 stone 6  
fill ~60 ~0 ~49 ~62 ~0 ~49 stone 6  
fill ~60 ~0 ~50 ~62 ~0 ~50 stone 6  
fill ~60 ~0 ~51 ~62 ~0 ~51 stone 6  
fill ~60 ~0 ~52 ~62 ~0 ~52 stone 6  
fill ~60 ~0 ~53 ~62 ~0 ~53 stone 6  
fill ~60 ~0 ~54 ~62 ~0 ~54 stone 6  
fill ~60 ~0 ~55 ~62 ~0 ~55 stone 6  
fill ~60 ~0 ~56 ~62 ~0 ~56 stone 6  
fill ~60 ~0 ~57 ~62 ~0 ~57 stone 6  
fill ~60 ~0 ~58 ~62 ~0 ~58 stone 6  
fill ~60 ~0 ~59 ~62 ~0 ~59 stone 6  
fill ~60 ~0 ~60 ~62 ~0 ~60 stone 6  
fill ~60 ~0 ~61 ~62 ~0 ~61 stone 6 
setblock ~61 ~0 ~18 torch 5 
setblock ~61 ~0 ~22 torch 5 
setblock ~61 ~0 ~27 torch 5 
setblock ~62 ~0 ~0 stone_brick_stairs 2 
setblock ~62 ~0 ~1 stone 6  
fill ~62 ~0 ~76 ~64 ~0 ~76 stone 6  
fill ~62 ~0 ~88 ~67 ~0 ~88 stone 6  
fill ~62 ~0 ~91 ~64 ~0 ~91 stone 6  
fill ~63 ~0 ~2 ~63 ~0 ~13 stone 6 
setblock ~63 ~0 ~16 torch 5  
fill ~63 ~0 ~32 ~66 ~0 ~32 stone 6  
fill ~63 ~0 ~33 ~67 ~0 ~33 stone 6  
fill ~63 ~0 ~34 ~68 ~0 ~34 stone 6  
fill ~63 ~0 ~35 ~68 ~0 ~35 stone 6  
fill ~63 ~0 ~36 ~68 ~0 ~36 stone 6  
fill ~63 ~0 ~37 ~68 ~0 ~37 stone 6  
fill ~64 ~0 ~14 ~65 ~0 ~14 stone 6  
fill ~64 ~0 ~15 ~64 ~5 ~15 stone 6  
fill ~64 ~0 ~16 ~64 ~5 ~16 stone 6  
fill ~64 ~0 ~17 ~74 ~0 ~17 stone 6  
fill ~64 ~0 ~18 ~74 ~0 ~18 stone 6 
setblock ~64 ~0 ~21 torch 5 
setblock ~64 ~0 ~28 torch 5  
fill ~64 ~0 ~42 ~71 ~0 ~42 stone 6  
fill ~64 ~0 ~77 ~65 ~0 ~77 stone 6  
fill ~64 ~0 ~87 ~67 ~0 ~87 stone 6  
fill ~65 ~0 ~19 ~74 ~0 ~19 stone 6 
setblock ~65 ~0 ~27 torch 5  
fill ~65 ~0 ~78 ~66 ~0 ~78 stone 6  
fill ~65 ~0 ~79 ~66 ~0 ~79 stone 6  
fill ~65 ~0 ~85 ~67 ~0 ~85 stone 6  
fill ~65 ~0 ~86 ~67 ~0 ~86 stone 6  
fill ~66 ~0 ~20 ~74 ~0 ~20 stone 6 
setblock ~66 ~0 ~24 torch 5  
fill ~66 ~0 ~43 ~69 ~0 ~43 stone 6  
fill ~66 ~0 ~80 ~67 ~0 ~80 stone 6  
fill ~66 ~0 ~81 ~67 ~0 ~81 stone 6  
fill ~66 ~0 ~82 ~67 ~0 ~82 stone 6  
fill ~66 ~0 ~83 ~67 ~0 ~83 stone 6  
fill ~66 ~0 ~84 ~67 ~0 ~84 stone 6 
setblock ~67 ~0 ~22 torch 5  
fill ~70 ~0 ~37 ~74 ~0 ~37 stone 6  
fill ~70 ~0 ~38 ~74 ~0 ~38 stone 6  
fill ~71 ~0 ~21 ~72 ~0 ~21 stone 6  
fill ~71 ~0 ~22 ~74 ~0 ~22 stone 6  
fill ~71 ~0 ~23 ~74 ~0 ~23 stone 6  
fill ~71 ~0 ~24 ~74 ~0 ~24 stone 6  
fill ~71 ~0 ~25 ~74 ~0 ~25 stone 6  
fill ~71 ~0 ~26 ~74 ~0 ~26 stone 6  
fill ~71 ~0 ~27 ~74 ~0 ~27 stone 6  
fill ~71 ~0 ~28 ~74 ~0 ~28 stone 6  
fill ~71 ~0 ~29 ~74 ~0 ~29 stone 6  
fill ~71 ~0 ~30 ~74 ~0 ~30 stone 6  
fill ~71 ~0 ~31 ~74 ~0 ~31 stone 6  
fill ~71 ~0 ~32 ~74 ~0 ~32 stone 6  
fill ~71 ~0 ~33 ~74 ~0 ~33 stone 6  
fill ~71 ~0 ~34 ~74 ~0 ~34 stone 6  
fill ~71 ~0 ~35 ~74 ~0 ~35 stone 6  
fill ~71 ~0 ~36 ~74 ~0 ~36 stone 6  
fill ~73 ~0 ~21 ~73 ~1 ~21 log 2  
fill ~74 ~0 ~21 ~74 ~9 ~21 stone 6 
setblock ~78 ~0 ~0 wool 14  
fill ~2 ~1 ~17 ~12 ~1 ~17 stone 6  
fill ~2 ~1 ~18 ~12 ~1 ~18 stone 6  
fill ~2 ~1 ~19 ~11 ~1 ~19 stone 6  
fill ~2 ~1 ~20 ~10 ~1 ~20 stone 6  
fill ~2 ~1 ~21 ~5 ~1 ~21 stone 6  
fill ~2 ~1 ~22 ~5 ~1 ~22 stone 6  
fill ~2 ~1 ~23 ~5 ~1 ~23 stone 6  
fill ~2 ~1 ~24 ~5 ~1 ~24 stone 6  
fill ~2 ~1 ~25 ~5 ~1 ~25 stone 6  
fill ~2 ~1 ~26 ~5 ~1 ~26 stone 6  
fill ~2 ~1 ~27 ~5 ~1 ~27 stone 6  
fill ~2 ~1 ~28 ~5 ~1 ~28 stone 6  
fill ~2 ~1 ~29 ~5 ~1 ~29 stone 6  
fill ~2 ~1 ~30 ~5 ~1 ~30 stone 6  
fill ~2 ~1 ~31 ~5 ~1 ~31 stone 6  
fill ~2 ~1 ~32 ~5 ~1 ~32 stone 6  
fill ~2 ~1 ~33 ~5 ~1 ~33 stone 6  
fill ~2 ~1 ~34 ~5 ~1 ~34 stone 6  
fill ~2 ~1 ~35 ~5 ~1 ~35 stone 6  
fill ~2 ~1 ~36 ~4 ~1 ~36 stone 6  
fill ~2 ~1 ~37 ~3 ~1 ~37 stone 6  
fill ~2 ~1 ~38 ~5 ~1 ~38 stone 6  
fill ~2 ~1 ~39 ~7 ~1 ~39 stone 6  
fill ~3 ~1 ~40 ~18 ~1 ~40 stone 6  
fill ~3 ~1 ~41 ~17 ~1 ~41 stone 6  
fill ~5 ~1 ~42 ~12 ~1 ~42 stone 6  
fill ~7 ~1 ~43 ~10 ~1 ~43 stone 6  
fill ~8 ~1 ~36 ~17 ~1 ~36 stone 6  
fill ~8 ~1 ~37 ~17 ~1 ~37 stone 6  
fill ~8 ~1 ~38 ~18 ~1 ~38 stone 6  
fill ~9 ~1 ~34 ~18 ~1 ~34 stone 6  
fill ~9 ~1 ~35 ~17 ~1 ~35 stone 6  
fill ~9 ~1 ~39 ~18 ~1 ~39 stone 6  
fill ~10 ~1 ~33 ~18 ~1 ~33 stone 6  
fill ~11 ~1 ~8 ~16 ~1 ~8 stone 6  
fill ~11 ~1 ~9 ~16 ~1 ~9 stone 6  
fill ~11 ~1 ~10 ~16 ~1 ~10 stone 6  
fill ~11 ~1 ~11 ~16 ~1 ~11 stone 6  
fill ~11 ~1 ~12 ~16 ~1 ~12 stone 6  
fill ~11 ~1 ~13 ~17 ~1 ~13 stone 6  
fill ~11 ~1 ~14 ~12 ~1 ~14 stone 6  
fill ~11 ~1 ~32 ~12 ~1 ~32 stone 6  
fill ~12 ~1 ~4 ~12 ~1 ~5 stonebrick 0  
fill ~12 ~1 ~6 ~17 ~1 ~6 stone 6  
fill ~12 ~1 ~7 ~17 ~1 ~7 stone 6  
fill ~13 ~1 ~2 ~13 ~1 ~3 stonebrick 0  
fill ~13 ~1 ~4 ~18 ~1 ~4 stone_slab 5  
fill ~13 ~1 ~5 ~20 ~1 ~5 stonebrick 0  
fill ~13 ~1 ~64 ~18 ~1 ~64 stone 6  
fill ~13 ~1 ~65 ~18 ~1 ~65 stone 6  
fill ~13 ~1 ~66 ~18 ~1 ~66 stone 6  
fill ~13 ~1 ~67 ~18 ~1 ~67 stone 6  
fill ~13 ~1 ~68 ~18 ~1 ~68 stone 6  
fill ~13 ~1 ~69 ~18 ~1 ~69 stone 6 
setblock ~14 ~1 ~1 stonebrick 0  
fill ~14 ~1 ~14 ~18 ~1 ~14 stone 6  
fill ~14 ~1 ~42 ~17 ~1 ~42 stone 6  
fill ~14 ~1 ~43 ~17 ~1 ~43 stone 6  
fill ~14 ~1 ~44 ~17 ~1 ~44 stone 6  
fill ~14 ~1 ~45 ~17 ~1 ~45 stone 6  
fill ~14 ~1 ~46 ~17 ~1 ~46 stone 6  
fill ~14 ~1 ~47 ~17 ~1 ~47 stone 6  
fill ~14 ~1 ~48 ~17 ~1 ~48 stone 6  
fill ~14 ~1 ~49 ~17 ~1 ~49 stone 6  
fill ~14 ~1 ~50 ~17 ~1 ~50 stone 6  
fill ~14 ~1 ~51 ~17 ~1 ~51 stone 6  
fill ~14 ~1 ~52 ~17 ~1 ~52 stone 6  
fill ~14 ~1 ~53 ~17 ~1 ~53 stone 6  
fill ~14 ~1 ~54 ~17 ~1 ~54 stone 6  
fill ~14 ~1 ~55 ~17 ~1 ~55 stone 6  
fill ~14 ~1 ~56 ~17 ~1 ~56 stone 6  
fill ~14 ~1 ~57 ~17 ~1 ~57 stone 6  
fill ~14 ~1 ~58 ~17 ~1 ~58 stone 6  
fill ~14 ~1 ~59 ~17 ~1 ~59 stone 6  
fill ~14 ~1 ~60 ~17 ~1 ~60 stone 6  
fill ~14 ~1 ~61 ~17 ~1 ~61 stone 6  
fill ~14 ~1 ~62 ~17 ~1 ~62 stone 6  
fill ~14 ~1 ~63 ~17 ~1 ~63 stone 6  
fill ~14 ~1 ~70 ~18 ~1 ~70 stone 6  
fill ~15 ~1 ~15 ~19 ~1 ~15 stone 6  
fill ~15 ~1 ~71 ~37 ~1 ~71 stone 6  
fill ~16 ~1 ~16 ~21 ~1 ~16 stone 6  
fill ~16 ~1 ~32 ~18 ~1 ~32 stone 6  
fill ~17 ~1 ~17 ~24 ~1 ~17 stone 6  
fill ~17 ~1 ~31 ~61 ~1 ~31 stone 6  
fill ~18 ~1 ~30 ~61 ~1 ~30 stone 6  
fill ~18 ~1 ~35 ~18 ~1 ~37 stone_brick_stairs 1  
fill ~18 ~1 ~41 ~18 ~4 ~41 stonebrick 0  
fill ~18 ~1 ~42 ~18 ~4 ~42 stonebrick 0  
fill ~18 ~1 ~43 ~18 ~1 ~44 iron_trapdoor 11  
fill ~18 ~1 ~46 ~18 ~1 ~47 iron_trapdoor 11  
fill ~18 ~1 ~48 ~18 ~4 ~48 stonebrick 0  
fill ~18 ~1 ~49 ~18 ~4 ~49 stonebrick 0  
fill ~18 ~1 ~50 ~18 ~1 ~51 iron_trapdoor 11  
fill ~18 ~1 ~53 ~18 ~1 ~54 iron_trapdoor 11  
fill ~18 ~1 ~55 ~18 ~4 ~55 stonebrick 0  
fill ~18 ~1 ~56 ~18 ~4 ~56 stonebrick 0  
fill ~18 ~1 ~57 ~18 ~1 ~58 iron_trapdoor 11  
fill ~18 ~1 ~60 ~18 ~1 ~61 iron_trapdoor 11  
fill ~18 ~1 ~62 ~18 ~4 ~62 stonebrick 0  
fill ~18 ~1 ~63 ~18 ~4 ~63 stonebrick 0  
fill ~19 ~1 ~18 ~28 ~1 ~18 stone 6  
fill ~19 ~1 ~32 ~20 ~1 ~32 iron_trapdoor 9  
fill ~19 ~1 ~70 ~20 ~1 ~70 iron_trapdoor 8  
fill ~19 ~1 ~98 ~51 ~1 ~98 stone 6  
fill ~19 ~1 ~104 ~51 ~1 ~104 stone 6 
setblock ~20 ~1 ~6 stone_brick_stairs 3  
fill ~20 ~1 ~19 ~32 ~1 ~19 stone 6  
fill ~20 ~1 ~93 ~31 ~1 ~93 stone 6  
fill ~20 ~1 ~94 ~31 ~1 ~94 stone 6  
fill ~20 ~1 ~95 ~23 ~1 ~95 stone 6  
fill ~20 ~1 ~96 ~23 ~1 ~96 stone 6  
fill ~20 ~1 ~97 ~23 ~1 ~97 stone 6  
fill ~20 ~1 ~99 ~46 ~1 ~99 stone 6  
fill ~20 ~1 ~100 ~34 ~1 ~100 stone 6  
fill ~20 ~1 ~101 ~34 ~1 ~101 stone 6  
fill ~20 ~1 ~102 ~39 ~1 ~102 stone 6  
fill ~20 ~1 ~103 ~51 ~1 ~103 stone 6  
fill ~20 ~1 ~105 ~56 ~1 ~105 stone 6  
fill ~20 ~1 ~106 ~23 ~1 ~106 stone 6  
fill ~20 ~1 ~107 ~23 ~1 ~107 stone 6  
fill ~20 ~1 ~108 ~24 ~1 ~108 stone 6  
fill ~20 ~1 ~109 ~41 ~1 ~109 stone 6  
fill ~21 ~1 ~29 ~23 ~1 ~29 stone 6  
fill ~21 ~1 ~92 ~33 ~1 ~92 stone 6  
fill ~21 ~1 ~110 ~41 ~1 ~110 stone 6  
fill ~22 ~1 ~32 ~23 ~1 ~32 iron_trapdoor 9  
fill ~22 ~1 ~70 ~23 ~1 ~70 iron_trapdoor 8  
fill ~22 ~1 ~91 ~54 ~1 ~91 stone 6  
fill ~22 ~1 ~111 ~41 ~1 ~111 stone 6  
fill ~23 ~1 ~20 ~55 ~1 ~20 stone 6  
fill ~24 ~1 ~32 ~25 ~1 ~32 stonebrick 0  
fill ~24 ~1 ~40 ~25 ~1 ~40 stone 6  
fill ~24 ~1 ~41 ~25 ~1 ~41 stone 6  
fill ~24 ~1 ~47 ~25 ~1 ~47 stone 6  
fill ~24 ~1 ~48 ~25 ~1 ~48 stone 6  
fill ~24 ~1 ~54 ~25 ~1 ~54 stone 6  
fill ~24 ~1 ~55 ~25 ~1 ~55 stone 6  
fill ~24 ~1 ~61 ~25 ~1 ~61 stone 6  
fill ~24 ~1 ~62 ~25 ~1 ~62 stone 6  
fill ~24 ~1 ~70 ~25 ~1 ~70 stonebrick 0  
fill ~24 ~1 ~72 ~37 ~1 ~72 stone 6  
fill ~24 ~1 ~90 ~52 ~1 ~90 stone 6  
fill ~24 ~1 ~112 ~52 ~1 ~112 stone 6  
fill ~25 ~1 ~73 ~37 ~1 ~73 stone 6  
fill ~25 ~1 ~74 ~28 ~1 ~74 stone 6  
fill ~25 ~1 ~95 ~29 ~1 ~95 stone 6  
fill ~25 ~1 ~97 ~28 ~1 ~97 stone 6  
fill ~25 ~1 ~106 ~34 ~1 ~106 stone 6  
fill ~25 ~1 ~107 ~33 ~1 ~107 stone 6  
fill ~26 ~1 ~32 ~27 ~1 ~32 iron_trapdoor 9  
fill ~26 ~1 ~70 ~27 ~1 ~70 iron_trapdoor 8  
fill ~26 ~1 ~75 ~29 ~1 ~75 stone 6  
fill ~26 ~1 ~76 ~30 ~1 ~76 stone 6  
fill ~26 ~1 ~108 ~37 ~1 ~108 stone 6  
fill ~27 ~1 ~21 ~37 ~1 ~21 stone 6  
fill ~27 ~1 ~77 ~31 ~1 ~77 stone 6  
fill ~27 ~1 ~87 ~31 ~1 ~87 stone 6  
fill ~27 ~1 ~88 ~30 ~1 ~88 stone 6  
fill ~27 ~1 ~89 ~49 ~1 ~89 stone 6  
fill ~27 ~1 ~113 ~49 ~1 ~113 stone 6  
fill ~27 ~1 ~114 ~49 ~1 ~114 stone 6  
fill ~27 ~1 ~115 ~35 ~1 ~115 stone 6  
fill ~28 ~1 ~78 ~32 ~1 ~78 stone 6  
fill ~28 ~1 ~86 ~31 ~1 ~86 stone 6  
fill ~28 ~1 ~116 ~48 ~1 ~116 stone 6  
fill ~28 ~1 ~117 ~48 ~1 ~117 stone 6 
setblock ~29 ~1 ~14 stone_brick_stairs 0  
fill ~29 ~1 ~22 ~35 ~1 ~22 stone 6  
fill ~29 ~1 ~32 ~30 ~1 ~32 iron_trapdoor 9  
fill ~29 ~1 ~70 ~30 ~1 ~70 iron_trapdoor 8 
setblock ~29 ~1 ~74 torch 1  
fill ~29 ~1 ~79 ~32 ~1 ~79 stone 6  
fill ~29 ~1 ~85 ~31 ~1 ~85 stone 6  
fill ~29 ~1 ~118 ~47 ~1 ~118 stone 6  
fill ~30 ~1 ~14 ~32 ~1 ~14 stonebrick 0  
fill ~30 ~1 ~80 ~37 ~1 ~80 stone 6  
fill ~30 ~1 ~84 ~37 ~1 ~84 stone 6  
fill ~30 ~1 ~119 ~46 ~1 ~119 stone 6  
fill ~31 ~1 ~12 ~31 ~19 ~12 fence 1  
fill ~31 ~1 ~13 ~32 ~1 ~13 stonebrick 0  
fill ~31 ~1 ~23 ~32 ~1 ~23 stone 6  
fill ~31 ~1 ~32 ~32 ~1 ~32 stonebrick 0  
fill ~31 ~1 ~40 ~32 ~1 ~40 stone 6  
fill ~31 ~1 ~41 ~32 ~1 ~41 stone 6  
fill ~31 ~1 ~47 ~32 ~1 ~47 stone 6  
fill ~31 ~1 ~48 ~32 ~1 ~48 stone 6  
fill ~31 ~1 ~54 ~32 ~1 ~54 stone 6  
fill ~31 ~1 ~55 ~32 ~1 ~55 stone 6  
fill ~31 ~1 ~61 ~32 ~1 ~61 stone 6  
fill ~31 ~1 ~62 ~32 ~1 ~62 stone 6  
fill ~31 ~1 ~70 ~32 ~1 ~70 stonebrick 0  
fill ~31 ~1 ~97 ~51 ~1 ~97 stone 6 
setblock ~32 ~1 ~15 stone_brick_stairs 3 
setblock ~32 ~1 ~74 torch 3 
setblock ~32 ~1 ~77 torch 4  
fill ~32 ~1 ~81 ~37 ~1 ~81 stone 6  
fill ~32 ~1 ~83 ~37 ~1 ~83 stone 6  
fill ~32 ~1 ~88 ~49 ~1 ~88 stone 6  
fill ~33 ~1 ~12 ~33 ~19 ~12 fence 1  
fill ~33 ~1 ~32 ~34 ~1 ~32 iron_trapdoor 9  
fill ~33 ~1 ~70 ~34 ~1 ~70 iron_trapdoor 8 
setblock ~33 ~1 ~79 torch 4  
fill ~33 ~1 ~82 ~37 ~1 ~82 stone 6  
fill ~33 ~1 ~85 ~37 ~1 ~85 stone 6  
fill ~33 ~1 ~87 ~44 ~1 ~87 stone 6  
fill ~33 ~1 ~96 ~41 ~1 ~96 stone 6  
fill ~34 ~1 ~74 ~37 ~1 ~74 stone 6  
fill ~34 ~1 ~75 ~37 ~1 ~75 stone 6  
fill ~34 ~1 ~76 ~37 ~1 ~76 stone 6  
fill ~34 ~1 ~77 ~37 ~1 ~77 stone 6  
fill ~34 ~1 ~78 ~37 ~1 ~78 stone 6  
fill ~34 ~1 ~79 ~37 ~1 ~79 stone 6  
fill ~34 ~1 ~86 ~49 ~1 ~86 stone 6  
fill ~35 ~1 ~92 ~55 ~1 ~92 stone 6  
fill ~36 ~1 ~32 ~37 ~1 ~32 iron_trapdoor 9 
setblock ~36 ~1 ~70 iron_trapdoor 8  
fill ~36 ~1 ~100 ~39 ~1 ~100 stone 6  
fill ~36 ~1 ~101 ~37 ~1 ~101 stone 6  
fill ~36 ~1 ~106 ~51 ~1 ~106 stone 6  
fill ~37 ~1 ~70 ~37 ~6 ~70 stonebrick 0  
fill ~38 ~1 ~32 ~39 ~1 ~32 stonebrick 0  
fill ~38 ~1 ~40 ~39 ~1 ~40 stone 6  
fill ~38 ~1 ~41 ~39 ~1 ~41 stone 6  
fill ~38 ~1 ~47 ~39 ~1 ~47 stone 6  
fill ~38 ~1 ~48 ~39 ~1 ~48 stone 6  
fill ~38 ~1 ~54 ~39 ~1 ~54 stone 6  
fill ~38 ~1 ~55 ~39 ~1 ~55 stone 6  
fill ~38 ~1 ~61 ~39 ~1 ~61 stone 6  
fill ~38 ~1 ~62 ~39 ~1 ~62 stone 6  
fill ~38 ~1 ~85 ~39 ~1 ~85 stone_brick_stairs 2  
fill ~38 ~1 ~93 ~56 ~1 ~93 stone 6  
fill ~38 ~1 ~95 ~42 ~1 ~95 stone 6  
fill ~39 ~1 ~21 ~50 ~1 ~21 stone 6  
fill ~39 ~1 ~94 ~43 ~1 ~94 stone 6  
fill ~39 ~1 ~107 ~40 ~1 ~107 stone 6  
fill ~40 ~1 ~32 ~41 ~1 ~32 iron_trapdoor 9  
fill ~40 ~1 ~70 ~40 ~6 ~70 stonebrick 0  
fill ~40 ~1 ~71 ~61 ~1 ~71 stone 6 
setblock ~40 ~1 ~72 stone_brick_stairs 0  
fill ~40 ~1 ~73 ~45 ~1 ~73 stone 6  
fill ~40 ~1 ~74 ~44 ~1 ~74 stone 6  
fill ~40 ~1 ~75 ~44 ~1 ~75 stone 6  
fill ~40 ~1 ~76 ~50 ~1 ~76 stone 6 
setblock ~40 ~1 ~77 stone_brick_stairs 0  
fill ~40 ~1 ~78 ~48 ~1 ~78 stone 6  
fill ~40 ~1 ~79 ~47 ~1 ~79 stone 6  
fill ~40 ~1 ~80 ~46 ~1 ~80 stone 6  
fill ~40 ~1 ~81 ~44 ~1 ~81 stone 6 
setblock ~40 ~1 ~82 stone_brick_stairs 0  
fill ~40 ~1 ~83 ~44 ~1 ~83 stone 6  
fill ~40 ~1 ~84 ~46 ~1 ~84 stone 6  
fill ~40 ~1 ~85 ~47 ~1 ~85 stone 6  
fill ~41 ~1 ~22 ~44 ~1 ~22 stone 6 
setblock ~41 ~1 ~70 iron_trapdoor 8  
fill ~41 ~1 ~72 ~52 ~1 ~72 stone 6  
fill ~41 ~1 ~77 ~49 ~1 ~77 stone 6  
fill ~41 ~1 ~82 ~43 ~1 ~82 stone 6  
fill ~41 ~1 ~100 ~46 ~1 ~100 stone 6  
fill ~41 ~1 ~101 ~46 ~1 ~101 stone 6  
fill ~41 ~1 ~102 ~51 ~1 ~102 stone 6  
fill ~43 ~1 ~12 ~43 ~19 ~12 fence 1  
fill ~43 ~1 ~32 ~44 ~1 ~32 iron_trapdoor 9  
fill ~43 ~1 ~70 ~44 ~1 ~70 iron_trapdoor 8  
fill ~43 ~1 ~96 ~51 ~1 ~96 stone 6  
fill ~44 ~1 ~13 ~45 ~1 ~13 stonebrick 0  
fill ~44 ~1 ~14 ~46 ~1 ~14 stonebrick 0 
setblock ~44 ~1 ~15 stone_brick_stairs 3  
fill ~44 ~1 ~19 ~56 ~1 ~19 stone 6  
fill ~44 ~1 ~107 ~51 ~1 ~107 stone 6  
fill ~44 ~1 ~108 ~51 ~1 ~108 stone 6  
fill ~45 ~1 ~12 ~45 ~19 ~12 fence 1  
fill ~45 ~1 ~32 ~46 ~1 ~32 stonebrick 0  
fill ~45 ~1 ~40 ~46 ~1 ~40 stone 6  
fill ~45 ~1 ~41 ~46 ~1 ~41 stone 6  
fill ~45 ~1 ~47 ~46 ~1 ~47 stone 6  
fill ~45 ~1 ~48 ~46 ~1 ~48 stone 6  
fill ~45 ~1 ~54 ~46 ~1 ~54 stone 6  
fill ~45 ~1 ~55 ~46 ~1 ~55 stone 6  
fill ~45 ~1 ~61 ~46 ~1 ~61 stone 6  
fill ~45 ~1 ~62 ~46 ~1 ~62 stone 6  
fill ~45 ~1 ~70 ~46 ~1 ~70 stonebrick 0  
fill ~45 ~1 ~94 ~48 ~1 ~94 stone 6  
fill ~45 ~1 ~109 ~51 ~1 ~109 stone 6  
fill ~45 ~1 ~110 ~55 ~1 ~110 stone 6  
fill ~45 ~1 ~111 ~54 ~1 ~111 stone 6  
fill ~46 ~1 ~87 ~49 ~1 ~87 stone 6  
fill ~46 ~1 ~95 ~50 ~1 ~95 stone 6  
fill ~46 ~1 ~115 ~49 ~1 ~115 stone 6 
setblock ~47 ~1 ~14 stone_brick_stairs 1  
fill ~47 ~1 ~32 ~48 ~1 ~32 iron_trapdoor 9  
fill ~47 ~1 ~70 ~48 ~1 ~70 iron_trapdoor 8  
fill ~47 ~1 ~75 ~50 ~1 ~75 stone 6  
fill ~48 ~1 ~18 ~58 ~1 ~18 stone 6  
fill ~48 ~1 ~73 ~51 ~1 ~73 stone 6  
fill ~48 ~1 ~74 ~51 ~1 ~74 stone 6  
fill ~48 ~1 ~99 ~51 ~1 ~99 stone 6  
fill ~48 ~1 ~100 ~51 ~1 ~100 stone 6  
fill ~48 ~1 ~101 ~51 ~1 ~101 stone 6  
fill ~50 ~1 ~32 ~51 ~1 ~32 iron_trapdoor 9  
fill ~50 ~1 ~70 ~51 ~1 ~70 iron_trapdoor 8  
fill ~51 ~1 ~80 ~52 ~1 ~80 stone 6  
fill ~51 ~1 ~81 ~52 ~1 ~81 stone 6  
fill ~51 ~1 ~82 ~52 ~1 ~82 stone 6  
fill ~51 ~1 ~83 ~52 ~1 ~83 stone 6  
fill ~51 ~1 ~84 ~52 ~1 ~84 stone 6  
fill ~52 ~1 ~17 ~59 ~1 ~17 stone 6  
fill ~52 ~1 ~32 ~53 ~1 ~32 stonebrick 0  
fill ~52 ~1 ~40 ~53 ~1 ~40 stone 6  
fill ~52 ~1 ~41 ~53 ~1 ~41 stone 6  
fill ~52 ~1 ~47 ~53 ~1 ~47 stone 6  
fill ~52 ~1 ~48 ~53 ~1 ~48 stone 6  
fill ~52 ~1 ~54 ~53 ~1 ~54 stone 6  
fill ~52 ~1 ~55 ~53 ~1 ~55 stone 6  
fill ~52 ~1 ~61 ~53 ~1 ~61 stone 6  
fill ~52 ~1 ~62 ~53 ~1 ~62 stone 6  
fill ~52 ~1 ~70 ~53 ~1 ~70 stonebrick 0  
fill ~52 ~1 ~78 ~53 ~1 ~78 stone 6  
fill ~52 ~1 ~79 ~53 ~1 ~79 stone 6  
fill ~52 ~1 ~85 ~53 ~1 ~85 stone 6  
fill ~52 ~1 ~86 ~53 ~1 ~86 stone 6  
fill ~52 ~1 ~94 ~56 ~1 ~94 stone 6  
fill ~53 ~1 ~77 ~54 ~1 ~77 stone 6  
fill ~53 ~1 ~87 ~54 ~1 ~87 stone 6  
fill ~53 ~1 ~95 ~56 ~1 ~95 stone 6  
fill ~53 ~1 ~96 ~56 ~1 ~96 stone 6  
fill ~53 ~1 ~97 ~56 ~1 ~97 stone 6  
fill ~53 ~1 ~98 ~57 ~1 ~98 stone 6  
fill ~53 ~1 ~99 ~56 ~1 ~99 stone 6  
fill ~53 ~1 ~100 ~56 ~1 ~100 stone 6  
fill ~53 ~1 ~101 ~56 ~1 ~101 stone 6  
fill ~53 ~1 ~102 ~56 ~1 ~102 stone 6  
fill ~53 ~1 ~103 ~56 ~1 ~103 stone 6  
fill ~53 ~1 ~104 ~57 ~1 ~104 stone 6  
fill ~53 ~1 ~106 ~56 ~1 ~106 stone 6  
fill ~53 ~1 ~107 ~56 ~1 ~107 stone 6  
fill ~53 ~1 ~108 ~56 ~1 ~108 stone 6  
fill ~53 ~1 ~109 ~56 ~1 ~109 stone 6  
fill ~54 ~1 ~32 ~55 ~1 ~32 iron_trapdoor 9  
fill ~54 ~1 ~70 ~55 ~1 ~70 iron_trapdoor 8  
fill ~54 ~1 ~76 ~56 ~1 ~76 stone 6  
fill ~54 ~1 ~88 ~56 ~1 ~88 stone 6  
fill ~55 ~1 ~16 ~60 ~1 ~16 stone 6  
fill ~55 ~1 ~29 ~59 ~1 ~29 stone 6  
fill ~55 ~1 ~75 ~63 ~1 ~75 stone 6  
fill ~55 ~1 ~89 ~66 ~1 ~89 stone 6  
fill ~56 ~1 ~5 ~64 ~1 ~5 stonebrick 0 
setblock ~56 ~1 ~6 stone_brick_stairs 3  
fill ~57 ~1 ~15 ~61 ~1 ~15 stone 6  
fill ~57 ~1 ~32 ~58 ~1 ~32 iron_trapdoor 9  
fill ~57 ~1 ~70 ~58 ~1 ~70 iron_trapdoor 8  
fill ~57 ~1 ~74 ~61 ~1 ~74 stone 6  
fill ~57 ~1 ~90 ~65 ~1 ~90 stone 6  
fill ~58 ~1 ~4 ~63 ~1 ~4 stone_slab 5  
fill ~58 ~1 ~14 ~62 ~1 ~14 stone 6  
fill ~59 ~1 ~6 ~64 ~1 ~6 stone 6  
fill ~59 ~1 ~7 ~64 ~1 ~7 stone 6  
fill ~59 ~1 ~13 ~65 ~1 ~13 stone 6  
fill ~59 ~1 ~32 ~61 ~1 ~32 stone 6  
fill ~59 ~1 ~33 ~61 ~1 ~33 stone 6  
fill ~59 ~1 ~34 ~61 ~1 ~34 stone 6  
fill ~59 ~1 ~35 ~59 ~1 ~37 stone_brick_stairs 0  
fill ~59 ~1 ~38 ~67 ~1 ~38 stone 6  
fill ~59 ~1 ~39 ~73 ~1 ~39 stone 6  
fill ~59 ~1 ~40 ~59 ~4 ~40 stonebrick 0  
fill ~59 ~1 ~41 ~59 ~4 ~41 stonebrick 0  
fill ~59 ~1 ~42 ~59 ~1 ~43 iron_trapdoor 10  
fill ~59 ~1 ~45 ~59 ~1 ~46 iron_trapdoor 10  
fill ~59 ~1 ~47 ~59 ~4 ~47 stonebrick 0  
fill ~59 ~1 ~48 ~59 ~4 ~48 stonebrick 0  
fill ~59 ~1 ~49 ~59 ~1 ~50 iron_trapdoor 10  
fill ~59 ~1 ~52 ~59 ~1 ~53 iron_trapdoor 10  
fill ~59 ~1 ~54 ~59 ~4 ~54 stonebrick 0  
fill ~59 ~1 ~55 ~59 ~4 ~55 stonebrick 0  
fill ~59 ~1 ~56 ~59 ~1 ~57 iron_trapdoor 10  
fill ~59 ~1 ~59 ~59 ~1 ~60 iron_trapdoor 10  
fill ~59 ~1 ~61 ~59 ~4 ~61 stonebrick 0  
fill ~59 ~1 ~62 ~59 ~4 ~62 stonebrick 0  
fill ~59 ~1 ~63 ~62 ~1 ~63 stone 6  
fill ~59 ~1 ~64 ~63 ~1 ~64 stone 6  
fill ~59 ~1 ~65 ~63 ~1 ~65 stone 6  
fill ~59 ~1 ~66 ~63 ~1 ~66 stone 6  
fill ~59 ~1 ~67 ~63 ~1 ~67 stone 6  
fill ~59 ~1 ~68 ~63 ~1 ~68 stone 6  
fill ~59 ~1 ~69 ~63 ~1 ~69 stone 6  
fill ~59 ~1 ~70 ~62 ~1 ~70 stone 6  
fill ~60 ~1 ~8 ~65 ~1 ~8 stone 6  
fill ~60 ~1 ~9 ~65 ~1 ~9 stone 6  
fill ~60 ~1 ~10 ~65 ~1 ~10 stone 6  
fill ~60 ~1 ~11 ~65 ~1 ~11 stone 6  
fill ~60 ~1 ~12 ~65 ~1 ~12 stone 6  
fill ~60 ~1 ~35 ~61 ~1 ~35 stone 6  
fill ~60 ~1 ~36 ~61 ~1 ~36 stone 6  
fill ~60 ~1 ~37 ~61 ~1 ~37 stone 6  
fill ~60 ~1 ~40 ~73 ~1 ~40 stone 6  
fill ~60 ~1 ~41 ~72 ~1 ~41 stone 6  
fill ~60 ~1 ~42 ~62 ~1 ~42 stone 6  
fill ~60 ~1 ~43 ~62 ~1 ~43 stone 6  
fill ~60 ~1 ~44 ~62 ~1 ~44 stone 6  
fill ~60 ~1 ~45 ~62 ~1 ~45 stone 6  
fill ~60 ~1 ~46 ~62 ~1 ~46 stone 6  
fill ~60 ~1 ~47 ~62 ~1 ~47 stone 6  
fill ~60 ~1 ~48 ~62 ~1 ~48 stone 6  
fill ~60 ~1 ~49 ~62 ~1 ~49 stone 6  
fill ~60 ~1 ~50 ~62 ~1 ~50 stone 6  
fill ~60 ~1 ~51 ~62 ~1 ~51 stone 6  
fill ~60 ~1 ~52 ~62 ~1 ~52 stone 6  
fill ~60 ~1 ~53 ~62 ~1 ~53 stone 6  
fill ~60 ~1 ~54 ~62 ~1 ~54 stone 6  
fill ~60 ~1 ~55 ~62 ~1 ~55 stone 6  
fill ~60 ~1 ~56 ~62 ~1 ~56 stone 6  
fill ~60 ~1 ~57 ~62 ~1 ~57 stone 6  
fill ~60 ~1 ~58 ~62 ~1 ~58 stone 6  
fill ~60 ~1 ~59 ~62 ~1 ~59 stone 6  
fill ~60 ~1 ~60 ~62 ~1 ~60 stone 6  
fill ~60 ~1 ~61 ~62 ~1 ~61 stone 6  
fill ~60 ~1 ~62 ~62 ~1 ~62 stone 6 
setblock ~62 ~1 ~1 stonebrick 0  
fill ~62 ~1 ~76 ~64 ~1 ~76 stone 6  
fill ~62 ~1 ~88 ~67 ~1 ~88 stone 6  
fill ~62 ~1 ~91 ~64 ~1 ~91 stone 6  
fill ~63 ~1 ~2 ~63 ~1 ~3 stonebrick 0  
fill ~63 ~1 ~32 ~66 ~1 ~32 stone 6  
fill ~63 ~1 ~33 ~67 ~1 ~33 stone 6  
fill ~63 ~1 ~34 ~68 ~1 ~34 stone 6  
fill ~63 ~1 ~35 ~68 ~1 ~35 stone 6  
fill ~63 ~1 ~36 ~68 ~1 ~36 stone 6  
fill ~63 ~1 ~37 ~68 ~1 ~37 stone 6 
setblock ~64 ~1 ~4 stonebrick 0  
fill ~64 ~1 ~14 ~65 ~1 ~14 stone 6  
fill ~64 ~1 ~17 ~74 ~1 ~17 stone 6  
fill ~64 ~1 ~18 ~74 ~1 ~18 stone 6  
fill ~64 ~1 ~42 ~71 ~1 ~42 stone 6  
fill ~64 ~1 ~77 ~65 ~1 ~77 stone 6  
fill ~64 ~1 ~87 ~67 ~1 ~87 stone 6  
fill ~65 ~1 ~19 ~74 ~1 ~19 stone 6  
fill ~65 ~1 ~78 ~66 ~1 ~78 stone 6  
fill ~65 ~1 ~79 ~66 ~1 ~79 stone 6  
fill ~65 ~1 ~85 ~67 ~1 ~85 stone 6  
fill ~65 ~1 ~86 ~67 ~1 ~86 stone 6  
fill ~66 ~1 ~20 ~74 ~1 ~20 stone 6  
fill ~66 ~1 ~43 ~69 ~1 ~43 stone 6  
fill ~66 ~1 ~80 ~67 ~1 ~80 stone 6  
fill ~66 ~1 ~81 ~67 ~1 ~81 stone 6  
fill ~66 ~1 ~82 ~67 ~1 ~82 stone 6  
fill ~66 ~1 ~83 ~67 ~1 ~83 stone 6  
fill ~66 ~1 ~84 ~67 ~1 ~84 stone 6  
fill ~70 ~1 ~37 ~74 ~1 ~37 stone 6  
fill ~70 ~1 ~38 ~74 ~1 ~38 stone 6  
fill ~71 ~1 ~21 ~72 ~1 ~21 stone 6  
fill ~71 ~1 ~22 ~74 ~1 ~22 stone 6  
fill ~71 ~1 ~23 ~74 ~1 ~23 stone 6  
fill ~71 ~1 ~24 ~74 ~1 ~24 stone 6  
fill ~71 ~1 ~25 ~74 ~1 ~25 stone 6  
fill ~71 ~1 ~26 ~74 ~1 ~26 stone 6  
fill ~71 ~1 ~27 ~74 ~1 ~27 stone 6  
fill ~71 ~1 ~28 ~74 ~1 ~28 stone 6  
fill ~71 ~1 ~29 ~74 ~1 ~29 stone 6  
fill ~71 ~1 ~30 ~74 ~1 ~30 stone 6  
fill ~71 ~1 ~31 ~74 ~1 ~31 stone 6  
fill ~71 ~1 ~32 ~74 ~1 ~32 stone 6  
fill ~71 ~1 ~33 ~74 ~1 ~33 stone 6  
fill ~71 ~1 ~34 ~74 ~1 ~34 stone 6  
fill ~71 ~1 ~35 ~74 ~1 ~35 stone 6  
fill ~71 ~1 ~36 ~74 ~1 ~36 stone 6  
fill ~2 ~2 ~17 ~13 ~2 ~17 stone 6  
fill ~2 ~2 ~18 ~12 ~2 ~18 stone 6  
fill ~2 ~2 ~19 ~11 ~2 ~19 stone 6  
fill ~2 ~2 ~20 ~10 ~2 ~20 stone 6  
fill ~2 ~2 ~21 ~6 ~2 ~21 stone 6  
fill ~2 ~2 ~22 ~6 ~2 ~22 stone 6  
fill ~2 ~2 ~23 ~6 ~2 ~23 stone 6  
fill ~2 ~2 ~24 ~6 ~2 ~24 stone 6  
fill ~2 ~2 ~25 ~6 ~2 ~25 stone 6  
fill ~2 ~2 ~26 ~6 ~2 ~26 stone 6  
fill ~2 ~2 ~27 ~6 ~2 ~27 stone 6  
fill ~2 ~2 ~28 ~6 ~2 ~28 stone 6  
fill ~2 ~2 ~29 ~6 ~2 ~29 stone 6  
fill ~2 ~2 ~30 ~6 ~2 ~30 stone 6  
fill ~2 ~2 ~31 ~6 ~2 ~31 stone 6  
fill ~2 ~2 ~32 ~6 ~2 ~32 stone 6  
fill ~2 ~2 ~33 ~5 ~2 ~33 stone 6  
fill ~2 ~2 ~34 ~5 ~2 ~34 stone 6  
fill ~2 ~2 ~35 ~5 ~2 ~35 stone 6  
fill ~2 ~2 ~36 ~4 ~2 ~36 stone 6  
fill ~2 ~2 ~37 ~4 ~2 ~37 stone 6  
fill ~2 ~2 ~38 ~5 ~2 ~38 stone 6  
fill ~2 ~2 ~39 ~18 ~2 ~39 stone 6  
fill ~3 ~2 ~40 ~18 ~2 ~40 stone 6  
fill ~3 ~2 ~41 ~17 ~2 ~41 stone 6  
fill ~5 ~2 ~42 ~12 ~2 ~42 stone 6  
fill ~7 ~2 ~36 ~16 ~2 ~36 stone 6  
fill ~7 ~2 ~37 ~16 ~2 ~37 stone 6  
fill ~7 ~2 ~38 ~18 ~2 ~38 stone 6  
fill ~7 ~2 ~43 ~10 ~2 ~43 stone 6  
fill ~8 ~2 ~34 ~18 ~2 ~34 stone 6  
fill ~8 ~2 ~35 ~16 ~2 ~35 stone 6  
fill ~9 ~2 ~32 ~18 ~2 ~32 stone 6  
fill ~9 ~2 ~33 ~18 ~2 ~33 stone 6  
fill ~10 ~2 ~31 ~13 ~2 ~31 stone 6  
fill ~11 ~2 ~8 ~16 ~2 ~8 stone 6  
fill ~11 ~2 ~9 ~16 ~2 ~9 stone 6  
fill ~11 ~2 ~10 ~16 ~2 ~10 stone 6  
fill ~11 ~2 ~11 ~16 ~2 ~11 stone 6  
fill ~11 ~2 ~12 ~16 ~2 ~12 stone 6  
fill ~11 ~2 ~13 ~17 ~2 ~13 stone 6  
fill ~11 ~2 ~14 ~18 ~2 ~14 stone 6 
setblock ~12 ~2 ~4 cobblestone_wall 0  
fill ~12 ~2 ~5 ~12 ~2 ~7 stonebrick 0  
fill ~13 ~2 ~2 ~13 ~2 ~3 cobblestone_wall 0  
fill ~13 ~2 ~6 ~16 ~2 ~6 stone_slab 5  
fill ~13 ~2 ~7 ~17 ~2 ~7 stonebrick 0  
fill ~13 ~2 ~15 ~19 ~2 ~15 stone 6  
fill ~13 ~2 ~16 ~13 ~5 ~16 stone 6  
fill ~13 ~2 ~64 ~18 ~2 ~64 stone 6  
fill ~13 ~2 ~65 ~18 ~2 ~65 stone 6  
fill ~13 ~2 ~66 ~18 ~2 ~66 stone 6  
fill ~13 ~2 ~67 ~18 ~2 ~67 stone 6  
fill ~13 ~2 ~68 ~18 ~2 ~68 stone 6  
fill ~13 ~2 ~69 ~18 ~2 ~69 stone 6 
setblock ~14 ~2 ~1 cobblestone_wall 0  
fill ~14 ~2 ~42 ~17 ~2 ~42 stone 6  
fill ~14 ~2 ~43 ~17 ~2 ~43 stone 6  
fill ~14 ~2 ~44 ~17 ~2 ~44 stone 6  
fill ~14 ~2 ~45 ~17 ~2 ~45 stone 6  
fill ~14 ~2 ~46 ~17 ~2 ~46 stone 6  
fill ~14 ~2 ~47 ~17 ~2 ~47 stone 6  
fill ~14 ~2 ~48 ~17 ~2 ~48 stone 6  
fill ~14 ~2 ~49 ~17 ~2 ~49 stone 6  
fill ~14 ~2 ~50 ~17 ~2 ~50 stone 6  
fill ~14 ~2 ~51 ~17 ~2 ~51 stone 6  
fill ~14 ~2 ~52 ~17 ~2 ~52 stone 6  
fill ~14 ~2 ~53 ~17 ~2 ~53 stone 6  
fill ~14 ~2 ~54 ~17 ~2 ~54 stone 6  
fill ~14 ~2 ~55 ~17 ~2 ~55 stone 6  
fill ~14 ~2 ~56 ~17 ~2 ~56 stone 6  
fill ~14 ~2 ~57 ~17 ~2 ~57 stone 6  
fill ~14 ~2 ~58 ~17 ~2 ~58 stone 6  
fill ~14 ~2 ~59 ~17 ~2 ~59 stone 6  
fill ~14 ~2 ~60 ~17 ~2 ~60 stone 6  
fill ~14 ~2 ~61 ~17 ~2 ~61 stone 6  
fill ~14 ~2 ~62 ~17 ~2 ~62 stone 6  
fill ~14 ~2 ~63 ~17 ~2 ~63 stone 6  
fill ~14 ~2 ~70 ~18 ~2 ~70 stone 6  
fill ~15 ~2 ~16 ~21 ~2 ~16 stone 6  
fill ~15 ~2 ~71 ~37 ~2 ~71 stone 6  
fill ~16 ~2 ~17 ~24 ~2 ~17 stone 6  
fill ~17 ~2 ~5 ~20 ~2 ~5 cobblestone_wall 0 
setblock ~17 ~2 ~6 stonebrick 0  
fill ~17 ~2 ~31 ~66 ~2 ~31 stone 6  
fill ~17 ~2 ~35 ~17 ~2 ~37 stone_brick_stairs 1  
fill ~18 ~2 ~30 ~61 ~2 ~30 stone 6  
fill ~18 ~2 ~43 ~18 ~2 ~44 chest 5  
fill ~18 ~2 ~46 ~18 ~2 ~47 chest 5  
fill ~18 ~2 ~50 ~18 ~2 ~51 chest 5  
fill ~18 ~2 ~53 ~18 ~2 ~54 chest 5  
fill ~18 ~2 ~57 ~18 ~2 ~58 chest 5  
fill ~18 ~2 ~60 ~18 ~2 ~61 chest 5  
fill ~19 ~2 ~18 ~28 ~2 ~18 stone 6  
fill ~19 ~2 ~32 ~20 ~2 ~32 chest 3  
fill ~19 ~2 ~70 ~20 ~2 ~70 chest 2  
fill ~19 ~2 ~98 ~57 ~2 ~98 stone 6  
fill ~19 ~2 ~104 ~57 ~2 ~104 stone 6  
fill ~20 ~2 ~19 ~32 ~2 ~19 stone 6  
fill ~20 ~2 ~93 ~56 ~2 ~93 stone 6  
fill ~20 ~2 ~94 ~56 ~2 ~94 stone 6  
fill ~20 ~2 ~95 ~56 ~2 ~95 stone 6  
fill ~20 ~2 ~96 ~56 ~2 ~96 stone 6  
fill ~20 ~2 ~97 ~56 ~2 ~97 stone 6  
fill ~20 ~2 ~99 ~56 ~2 ~99 stone 6  
fill ~20 ~2 ~100 ~56 ~2 ~100 stone 6  
fill ~20 ~2 ~101 ~37 ~2 ~101 stone 6  
fill ~20 ~2 ~102 ~56 ~2 ~102 stone 6  
fill ~20 ~2 ~103 ~56 ~2 ~103 stone 6  
fill ~20 ~2 ~105 ~56 ~2 ~105 stone 6  
fill ~20 ~2 ~106 ~56 ~2 ~106 stone 6  
fill ~20 ~2 ~107 ~56 ~2 ~107 stone 6  
fill ~20 ~2 ~108 ~56 ~2 ~108 stone 6  
fill ~20 ~2 ~109 ~56 ~2 ~109 stone 6  
fill ~21 ~2 ~29 ~23 ~2 ~29 stone 6  
fill ~21 ~2 ~92 ~55 ~2 ~92 stone 6  
fill ~21 ~2 ~110 ~55 ~2 ~110 stone 6  
fill ~22 ~2 ~32 ~23 ~2 ~32 chest 3  
fill ~22 ~2 ~70 ~23 ~2 ~70 chest 2  
fill ~22 ~2 ~91 ~54 ~2 ~91 stone 6  
fill ~22 ~2 ~111 ~54 ~2 ~111 stone 6  
fill ~23 ~2 ~20 ~55 ~2 ~20 stone 6  
fill ~24 ~2 ~32 ~25 ~2 ~32 stonebrick 0  
fill ~24 ~2 ~40 ~25 ~2 ~40 stone 6  
fill ~24 ~2 ~41 ~25 ~2 ~41 stone 6  
fill ~24 ~2 ~47 ~25 ~2 ~47 stone 6  
fill ~24 ~2 ~48 ~25 ~2 ~48 stone 6  
fill ~24 ~2 ~54 ~25 ~2 ~54 stone 6  
fill ~24 ~2 ~55 ~25 ~2 ~55 stone 6  
fill ~24 ~2 ~61 ~25 ~2 ~61 stone 6  
fill ~24 ~2 ~62 ~25 ~2 ~62 stone 6  
fill ~24 ~2 ~70 ~25 ~2 ~70 stonebrick 0  
fill ~24 ~2 ~72 ~37 ~2 ~72 stone 6  
fill ~24 ~2 ~90 ~52 ~2 ~90 stone 6  
fill ~24 ~2 ~112 ~52 ~2 ~112 stone 6  
fill ~25 ~2 ~73 ~37 ~2 ~73 stone 6  
fill ~25 ~2 ~74 ~29 ~2 ~74 stone 6  
fill ~26 ~2 ~21 ~51 ~2 ~21 stone 6  
fill ~26 ~2 ~32 ~27 ~2 ~32 chest 3  
fill ~26 ~2 ~70 ~27 ~2 ~70 chest 2  
fill ~26 ~2 ~75 ~29 ~2 ~75 stone 6  
fill ~26 ~2 ~76 ~30 ~2 ~76 stone 6  
fill ~27 ~2 ~22 ~35 ~2 ~22 stone 6  
fill ~27 ~2 ~77 ~31 ~2 ~77 stone 6  
fill ~27 ~2 ~87 ~49 ~2 ~87 stone 6  
fill ~27 ~2 ~88 ~49 ~2 ~88 stone 6  
fill ~27 ~2 ~89 ~49 ~2 ~89 stone 6  
fill ~27 ~2 ~113 ~49 ~2 ~113 stone 6  
fill ~27 ~2 ~114 ~49 ~2 ~114 stone 6  
fill ~27 ~2 ~115 ~49 ~2 ~115 stone 6  
fill ~28 ~2 ~78 ~32 ~2 ~78 stone 6  
fill ~28 ~2 ~86 ~37 ~2 ~86 stone 6  
fill ~28 ~2 ~116 ~48 ~2 ~116 stone 6  
fill ~28 ~2 ~117 ~48 ~2 ~117 stone 6  
fill ~29 ~2 ~32 ~30 ~2 ~32 chest 3  
fill ~29 ~2 ~70 ~30 ~2 ~70 chest 2  
fill ~29 ~2 ~79 ~32 ~2 ~79 stone 6  
fill ~29 ~2 ~85 ~31 ~2 ~85 stone 6  
fill ~29 ~2 ~118 ~47 ~2 ~118 stone 6  
fill ~30 ~2 ~14 ~32 ~2 ~14 stonebrick 0  
fill ~30 ~2 ~80 ~37 ~2 ~80 stone 6  
fill ~30 ~2 ~84 ~37 ~2 ~84 stone 6  
fill ~30 ~2 ~119 ~46 ~2 ~119 stone 6  
fill ~31 ~2 ~13 ~32 ~2 ~13 stonebrick 0  
fill ~31 ~2 ~32 ~32 ~2 ~32 stonebrick 0  
fill ~31 ~2 ~40 ~32 ~2 ~40 stone 6  
fill ~31 ~2 ~41 ~32 ~2 ~41 stone 6  
fill ~31 ~2 ~47 ~32 ~2 ~47 stone 6  
fill ~31 ~2 ~48 ~32 ~2 ~48 stone 6  
fill ~31 ~2 ~54 ~32 ~2 ~54 stone 6  
fill ~31 ~2 ~55 ~32 ~2 ~55 stone 6  
fill ~31 ~2 ~61 ~32 ~2 ~61 stone 6  
fill ~31 ~2 ~62 ~32 ~2 ~62 stone 6  
fill ~31 ~2 ~70 ~32 ~2 ~70 stonebrick 0 
setblock ~32 ~2 ~15 torch 3 
setblock ~32 ~2 ~23 stone 6  
fill ~32 ~2 ~81 ~37 ~2 ~81 stone 6  
fill ~32 ~2 ~83 ~37 ~2 ~83 stone 6  
fill ~33 ~2 ~13 ~33 ~2 ~14 stone_brick_stairs 5 
setblock ~33 ~2 ~19 torch 4  
fill ~33 ~2 ~32 ~34 ~2 ~32 chest 3  
fill ~33 ~2 ~70 ~34 ~2 ~70 chest 2  
fill ~33 ~2 ~82 ~37 ~2 ~82 stone 6  
fill ~33 ~2 ~85 ~37 ~2 ~85 stone 6  
fill ~34 ~2 ~74 ~37 ~2 ~74 stone 6  
fill ~34 ~2 ~75 ~37 ~2 ~75 stone 6  
fill ~34 ~2 ~76 ~37 ~2 ~76 stone 6  
fill ~34 ~2 ~77 ~37 ~2 ~77 stone 6  
fill ~34 ~2 ~78 ~37 ~2 ~78 stone 6  
fill ~34 ~2 ~79 ~37 ~2 ~79 stone 6  
fill ~36 ~2 ~32 ~37 ~2 ~32 chest 3 
setblock ~36 ~2 ~70 chest 2 
setblock ~38 ~2 ~19 torch 4  
fill ~38 ~2 ~32 ~39 ~2 ~32 stonebrick 0  
fill ~38 ~2 ~40 ~39 ~2 ~40 stone 6  
fill ~38 ~2 ~41 ~39 ~2 ~41 stone 6  
fill ~38 ~2 ~47 ~39 ~2 ~47 stone 6  
fill ~38 ~2 ~48 ~39 ~2 ~48 stone 6  
fill ~38 ~2 ~54 ~39 ~2 ~54 stone 6  
fill ~38 ~2 ~55 ~39 ~2 ~55 stone 6  
fill ~38 ~2 ~61 ~39 ~2 ~61 stone 6  
fill ~38 ~2 ~62 ~39 ~2 ~62 stone 6  
fill ~38 ~2 ~86 ~39 ~2 ~86 stone_brick_stairs 2  
fill ~39 ~2 ~101 ~56 ~2 ~101 stone 6  
fill ~40 ~2 ~32 ~41 ~2 ~32 chest 3  
fill ~40 ~2 ~71 ~61 ~2 ~71 stone 6 
setblock ~40 ~2 ~72 torch 2  
fill ~40 ~2 ~73 ~45 ~2 ~73 stone 6  
fill ~40 ~2 ~74 ~44 ~2 ~74 stone 6  
fill ~40 ~2 ~75 ~44 ~2 ~75 stone 6  
fill ~40 ~2 ~76 ~50 ~2 ~76 stone 6 
setblock ~40 ~2 ~77 torch 2  
fill ~40 ~2 ~78 ~48 ~2 ~78 stone 6  
fill ~40 ~2 ~79 ~47 ~2 ~79 stone 6  
fill ~40 ~2 ~80 ~46 ~2 ~80 stone 6  
fill ~40 ~2 ~81 ~44 ~2 ~81 stone 6 
setblock ~40 ~2 ~82 torch 2  
fill ~40 ~2 ~83 ~44 ~2 ~83 stone 6  
fill ~40 ~2 ~84 ~46 ~2 ~84 stone 6  
fill ~40 ~2 ~85 ~47 ~2 ~85 stone 6  
fill ~40 ~2 ~86 ~49 ~2 ~86 stone 6  
fill ~41 ~2 ~22 ~44 ~2 ~22 stone 6 
setblock ~41 ~2 ~70 chest 2  
fill ~41 ~2 ~72 ~52 ~2 ~72 stone 6  
fill ~41 ~2 ~77 ~49 ~2 ~77 stone 6  
fill ~41 ~2 ~82 ~43 ~2 ~82 stone 6  
fill ~43 ~2 ~13 ~43 ~2 ~14 stone_brick_stairs 4 
setblock ~43 ~2 ~19 torch 4  
fill ~43 ~2 ~32 ~44 ~2 ~32 chest 3  
fill ~43 ~2 ~70 ~44 ~2 ~70 chest 2  
fill ~44 ~2 ~13 ~45 ~2 ~13 stonebrick 0  
fill ~44 ~2 ~14 ~46 ~2 ~14 stonebrick 0 
setblock ~44 ~2 ~15 torch 3  
fill ~44 ~2 ~19 ~57 ~2 ~19 stone 6  
fill ~45 ~2 ~32 ~46 ~2 ~32 stonebrick 0  
fill ~45 ~2 ~40 ~46 ~2 ~40 stone 6  
fill ~45 ~2 ~41 ~46 ~2 ~41 stone 6  
fill ~45 ~2 ~47 ~46 ~2 ~47 stone 6  
fill ~45 ~2 ~48 ~46 ~2 ~48 stone 6  
fill ~45 ~2 ~54 ~46 ~2 ~54 stone 6  
fill ~45 ~2 ~55 ~46 ~2 ~55 stone 6  
fill ~45 ~2 ~61 ~46 ~2 ~61 stone 6  
fill ~45 ~2 ~62 ~46 ~2 ~62 stone 6  
fill ~45 ~2 ~70 ~46 ~2 ~70 stonebrick 0  
fill ~46 ~2 ~75 ~50 ~2 ~75 stone 6  
fill ~47 ~2 ~32 ~48 ~2 ~32 chest 3  
fill ~47 ~2 ~70 ~48 ~2 ~70 chest 2  
fill ~48 ~2 ~18 ~58 ~2 ~18 stone 6  
fill ~48 ~2 ~73 ~51 ~2 ~73 stone 6  
fill ~48 ~2 ~74 ~51 ~2 ~74 stone 6  
fill ~50 ~2 ~32 ~51 ~2 ~32 chest 3  
fill ~50 ~2 ~70 ~51 ~2 ~70 chest 2  
fill ~51 ~2 ~80 ~52 ~2 ~80 stone 6  
fill ~51 ~2 ~81 ~52 ~2 ~81 stone 6  
fill ~51 ~2 ~82 ~52 ~2 ~82 stone 6  
fill ~51 ~2 ~83 ~52 ~2 ~83 stone 6  
fill ~51 ~2 ~84 ~52 ~2 ~84 stone 6  
fill ~52 ~2 ~17 ~60 ~2 ~17 stone 6  
fill ~52 ~2 ~32 ~53 ~2 ~32 stonebrick 0  
fill ~52 ~2 ~40 ~53 ~2 ~40 stone 6  
fill ~52 ~2 ~41 ~53 ~2 ~41 stone 6  
fill ~52 ~2 ~47 ~53 ~2 ~47 stone 6  
fill ~52 ~2 ~48 ~53 ~2 ~48 stone 6  
fill ~52 ~2 ~54 ~53 ~2 ~54 stone 6  
fill ~52 ~2 ~55 ~53 ~2 ~55 stone 6  
fill ~52 ~2 ~61 ~53 ~2 ~61 stone 6  
fill ~52 ~2 ~62 ~53 ~2 ~62 stone 6  
fill ~52 ~2 ~70 ~53 ~2 ~70 stonebrick 0  
fill ~52 ~2 ~78 ~53 ~2 ~78 stone 6  
fill ~52 ~2 ~79 ~53 ~2 ~79 stone 6  
fill ~52 ~2 ~85 ~53 ~2 ~85 stone 6  
fill ~52 ~2 ~86 ~53 ~2 ~86 stone 6  
fill ~53 ~2 ~77 ~54 ~2 ~77 stone 6  
fill ~53 ~2 ~87 ~54 ~2 ~87 stone 6  
fill ~54 ~2 ~29 ~59 ~2 ~29 stone 6  
fill ~54 ~2 ~32 ~55 ~2 ~32 chest 3  
fill ~54 ~2 ~70 ~55 ~2 ~70 chest 2  
fill ~54 ~2 ~76 ~56 ~2 ~76 stone 6  
fill ~54 ~2 ~88 ~56 ~2 ~88 stone 6  
fill ~55 ~2 ~16 ~61 ~2 ~16 stone 6  
fill ~55 ~2 ~75 ~63 ~2 ~75 stone 6  
fill ~55 ~2 ~89 ~66 ~2 ~89 stone 6  
fill ~56 ~2 ~5 ~59 ~2 ~5 cobblestone_wall 0  
fill ~57 ~2 ~15 ~64 ~2 ~15 stone 6  
fill ~57 ~2 ~32 ~58 ~2 ~32 chest 3  
fill ~57 ~2 ~70 ~58 ~2 ~70 chest 2  
fill ~57 ~2 ~74 ~61 ~2 ~74 stone 6  
fill ~57 ~2 ~90 ~65 ~2 ~90 stone 6  
fill ~58 ~2 ~14 ~65 ~2 ~14 stone 6  
fill ~59 ~2 ~6 ~59 ~2 ~7 stonebrick 0  
fill ~59 ~2 ~13 ~65 ~2 ~13 stone 6  
fill ~59 ~2 ~32 ~67 ~2 ~32 stone 6  
fill ~59 ~2 ~33 ~68 ~2 ~33 stone 6  
fill ~59 ~2 ~34 ~68 ~2 ~34 stone 6  
fill ~59 ~2 ~38 ~68 ~2 ~38 stone 6  
fill ~59 ~2 ~39 ~73 ~2 ~39 stone 6  
fill ~59 ~2 ~42 ~59 ~2 ~43 chest 4  
fill ~59 ~2 ~45 ~59 ~2 ~46 chest 4  
fill ~59 ~2 ~49 ~59 ~2 ~50 chest 4  
fill ~59 ~2 ~52 ~59 ~2 ~53 chest 4  
fill ~59 ~2 ~56 ~59 ~2 ~57 chest 4  
fill ~59 ~2 ~59 ~59 ~2 ~60 chest 4  
fill ~59 ~2 ~63 ~62 ~2 ~63 stone 6  
fill ~59 ~2 ~64 ~63 ~2 ~64 stone 6  
fill ~59 ~2 ~65 ~63 ~2 ~65 stone 6  
fill ~59 ~2 ~66 ~63 ~2 ~66 stone 6  
fill ~59 ~2 ~67 ~63 ~2 ~67 stone 6  
fill ~59 ~2 ~68 ~63 ~2 ~68 stone 6  
fill ~59 ~2 ~69 ~63 ~2 ~69 stone 6  
fill ~59 ~2 ~70 ~62 ~2 ~70 stone 6  
fill ~60 ~2 ~6 ~63 ~2 ~6 stone_slab 5  
fill ~60 ~2 ~7 ~64 ~2 ~7 stonebrick 0  
fill ~60 ~2 ~8 ~65 ~2 ~8 stone 6  
fill ~60 ~2 ~9 ~65 ~2 ~9 stone 6  
fill ~60 ~2 ~10 ~65 ~2 ~10 stone 6  
fill ~60 ~2 ~11 ~65 ~2 ~11 stone 6  
fill ~60 ~2 ~12 ~65 ~2 ~12 stone 6  
fill ~60 ~2 ~35 ~60 ~2 ~37 stone_brick_stairs 0  
fill ~60 ~2 ~40 ~73 ~2 ~40 stone 6  
fill ~60 ~2 ~41 ~72 ~2 ~41 stone 6  
fill ~60 ~2 ~42 ~62 ~2 ~42 stone 6  
fill ~60 ~2 ~43 ~62 ~2 ~43 stone 6  
fill ~60 ~2 ~44 ~62 ~2 ~44 stone 6  
fill ~60 ~2 ~45 ~62 ~2 ~45 stone 6  
fill ~60 ~2 ~46 ~62 ~2 ~46 stone 6  
fill ~60 ~2 ~47 ~62 ~2 ~47 stone 6  
fill ~60 ~2 ~48 ~62 ~2 ~48 stone 6  
fill ~60 ~2 ~49 ~62 ~2 ~49 stone 6  
fill ~60 ~2 ~50 ~62 ~2 ~50 stone 6  
fill ~60 ~2 ~51 ~62 ~2 ~51 stone 6  
fill ~60 ~2 ~52 ~62 ~2 ~52 stone 6  
fill ~60 ~2 ~53 ~62 ~2 ~53 stone 6  
fill ~60 ~2 ~54 ~62 ~2 ~54 stone 6  
fill ~60 ~2 ~55 ~62 ~2 ~55 stone 6  
fill ~60 ~2 ~56 ~62 ~2 ~56 stone 6  
fill ~60 ~2 ~57 ~62 ~2 ~57 stone 6  
fill ~60 ~2 ~58 ~62 ~2 ~58 stone 6  
fill ~60 ~2 ~59 ~62 ~2 ~59 stone 6  
fill ~60 ~2 ~60 ~62 ~2 ~60 stone 6  
fill ~60 ~2 ~61 ~62 ~2 ~61 stone 6  
fill ~60 ~2 ~62 ~62 ~2 ~62 stone 6  
fill ~61 ~2 ~35 ~74 ~2 ~35 stone 6  
fill ~61 ~2 ~36 ~68 ~2 ~36 stone 6  
fill ~61 ~2 ~37 ~68 ~2 ~37 stone 6 
setblock ~62 ~2 ~1 cobblestone_wall 0  
fill ~62 ~2 ~76 ~64 ~2 ~76 stone 6  
fill ~62 ~2 ~88 ~67 ~2 ~88 stone 6  
fill ~62 ~2 ~91 ~64 ~2 ~91 stone 6  
fill ~63 ~2 ~2 ~63 ~2 ~3 cobblestone_wall 0  
fill ~63 ~2 ~16 ~63 ~5 ~16 stone 6  
fill ~63 ~2 ~17 ~74 ~2 ~17 stone 6 
setblock ~64 ~2 ~4 cobblestone_wall 0  
fill ~64 ~2 ~5 ~64 ~2 ~7 stonebrick 0  
fill ~64 ~2 ~18 ~74 ~2 ~18 stone 6  
fill ~64 ~2 ~19 ~74 ~2 ~19 stone 6  
fill ~64 ~2 ~42 ~71 ~2 ~42 stone 6  
fill ~64 ~2 ~77 ~65 ~2 ~77 stone 6  
fill ~64 ~2 ~87 ~67 ~2 ~87 stone 6  
fill ~65 ~2 ~20 ~74 ~2 ~20 stone 6  
fill ~65 ~2 ~78 ~66 ~2 ~78 stone 6  
fill ~65 ~2 ~79 ~66 ~2 ~79 stone 6  
fill ~65 ~2 ~85 ~67 ~2 ~85 stone 6  
fill ~65 ~2 ~86 ~67 ~2 ~86 stone 6  
fill ~66 ~2 ~43 ~69 ~2 ~43 stone 6  
fill ~66 ~2 ~80 ~67 ~2 ~80 stone 6  
fill ~66 ~2 ~81 ~67 ~2 ~81 stone 6  
fill ~66 ~2 ~82 ~67 ~2 ~82 stone 6  
fill ~66 ~2 ~83 ~67 ~2 ~83 stone 6  
fill ~66 ~2 ~84 ~67 ~2 ~84 stone 6  
fill ~67 ~2 ~21 ~74 ~2 ~21 stone 6  
fill ~70 ~2 ~22 ~74 ~2 ~22 stone 6  
fill ~70 ~2 ~23 ~74 ~2 ~23 stone 6  
fill ~70 ~2 ~24 ~74 ~2 ~24 stone 6  
fill ~70 ~2 ~25 ~74 ~2 ~25 stone 6  
fill ~70 ~2 ~26 ~74 ~2 ~26 stone 6  
fill ~70 ~2 ~27 ~74 ~2 ~27 stone 6  
fill ~70 ~2 ~28 ~74 ~2 ~28 stone 6  
fill ~70 ~2 ~29 ~74 ~2 ~29 stone 6  
fill ~70 ~2 ~30 ~74 ~2 ~30 stone 6  
fill ~70 ~2 ~31 ~74 ~2 ~31 stone 6  
fill ~70 ~2 ~32 ~74 ~2 ~32 stone 6  
fill ~70 ~2 ~33 ~74 ~2 ~33 stone 6  
fill ~70 ~2 ~34 ~74 ~2 ~34 stone 6  
fill ~70 ~2 ~36 ~74 ~2 ~36 stone 6  
fill ~70 ~2 ~37 ~74 ~2 ~37 stone 6  
fill ~70 ~2 ~38 ~74 ~2 ~38 stone 6  
fill ~2 ~3 ~17 ~13 ~3 ~17 stone 6  
fill ~2 ~3 ~18 ~15 ~3 ~18 stone 6  
fill ~2 ~3 ~19 ~16 ~3 ~19 stone 6  
fill ~2 ~3 ~20 ~9 ~3 ~20 stone 6  
fill ~2 ~3 ~21 ~7 ~3 ~21 stone 6  
fill ~2 ~3 ~22 ~9 ~3 ~22 stone 6  
fill ~2 ~3 ~23 ~9 ~3 ~23 stone 6  
fill ~2 ~3 ~24 ~12 ~3 ~24 stone 6  
fill ~2 ~3 ~25 ~13 ~3 ~25 stone 6  
fill ~2 ~3 ~26 ~18 ~3 ~26 stone 6  
fill ~2 ~3 ~27 ~8 ~3 ~27 stone 6  
fill ~2 ~3 ~28 ~7 ~3 ~28 stone 6  
fill ~2 ~3 ~29 ~7 ~3 ~29 stone 6  
fill ~2 ~3 ~30 ~7 ~3 ~30 stone 6  
fill ~2 ~3 ~31 ~7 ~3 ~31 stone 6  
fill ~2 ~3 ~32 ~18 ~3 ~32 stone 6  
fill ~2 ~3 ~33 ~18 ~3 ~33 stone 6  
fill ~2 ~3 ~34 ~18 ~3 ~34 stone 6  
fill ~2 ~3 ~35 ~15 ~3 ~35 stone 6  
fill ~2 ~3 ~36 ~15 ~3 ~36 stone 6  
fill ~2 ~3 ~37 ~15 ~3 ~37 stone 6  
fill ~2 ~3 ~38 ~18 ~3 ~38 stone 6  
fill ~2 ~3 ~39 ~18 ~3 ~39 stone 6  
fill ~3 ~3 ~40 ~18 ~3 ~40 stone 6  
fill ~3 ~3 ~41 ~17 ~3 ~41 stone 6  
fill ~5 ~3 ~42 ~12 ~3 ~42 stone 6  
fill ~7 ~3 ~43 ~10 ~3 ~43 stone 6  
fill ~9 ~3 ~31 ~15 ~3 ~31 stone 6  
fill ~10 ~3 ~27 ~19 ~3 ~27 stone 6  
fill ~10 ~3 ~30 ~13 ~3 ~30 stone 6  
fill ~11 ~3 ~8 ~11 ~3 ~9 stonebrick 0  
fill ~11 ~3 ~10 ~16 ~3 ~10 stone 6  
fill ~11 ~3 ~11 ~16 ~3 ~11 stone 6  
fill ~11 ~3 ~12 ~16 ~3 ~12 stone 6  
fill ~11 ~3 ~13 ~17 ~3 ~13 stone 6  
fill ~11 ~3 ~14 ~18 ~3 ~14 stone 6  
fill ~12 ~3 ~5 ~12 ~3 ~7 cobblestone_wall 0  
fill ~12 ~3 ~8 ~15 ~3 ~8 stone_slab 5  
fill ~12 ~3 ~9 ~16 ~3 ~9 stonebrick 0  
fill ~12 ~3 ~28 ~19 ~3 ~28 stone 6  
fill ~13 ~3 ~15 ~19 ~3 ~15 stone 6  
fill ~13 ~3 ~20 ~16 ~3 ~20 stone 6  
fill ~13 ~3 ~21 ~15 ~3 ~21 stone 6  
fill ~13 ~3 ~29 ~19 ~3 ~29 stone 6  
fill ~13 ~3 ~64 ~18 ~3 ~64 stone 6  
fill ~13 ~3 ~65 ~18 ~3 ~65 stone 6  
fill ~13 ~3 ~66 ~18 ~3 ~66 stone 6  
fill ~13 ~3 ~67 ~18 ~3 ~67 stone 6  
fill ~13 ~3 ~68 ~18 ~3 ~68 stone 6  
fill ~13 ~3 ~69 ~18 ~3 ~69 stone 6  
fill ~14 ~3 ~16 ~21 ~3 ~16 stone 6  
fill ~14 ~3 ~42 ~17 ~3 ~42 stone 6  
fill ~14 ~3 ~43 ~17 ~3 ~43 stone 6  
fill ~14 ~3 ~44 ~17 ~3 ~44 stone 6  
fill ~14 ~3 ~45 ~17 ~3 ~45 stone 6  
fill ~14 ~3 ~46 ~17 ~3 ~46 stone 6  
fill ~14 ~3 ~47 ~17 ~3 ~47 stone 6  
fill ~14 ~3 ~48 ~17 ~3 ~48 stone 6  
fill ~14 ~3 ~49 ~17 ~3 ~49 stone 6  
fill ~14 ~3 ~50 ~17 ~3 ~50 stone 6  
fill ~14 ~3 ~51 ~17 ~3 ~51 stone 6  
fill ~14 ~3 ~52 ~17 ~3 ~52 stone 6  
fill ~14 ~3 ~53 ~17 ~3 ~53 stone 6  
fill ~14 ~3 ~54 ~17 ~3 ~54 stone 6  
fill ~14 ~3 ~55 ~17 ~3 ~55 stone 6  
fill ~14 ~3 ~56 ~17 ~3 ~56 stone 6  
fill ~14 ~3 ~57 ~17 ~3 ~57 stone 6  
fill ~14 ~3 ~58 ~17 ~3 ~58 stone 6  
fill ~14 ~3 ~59 ~17 ~3 ~59 stone 6  
fill ~14 ~3 ~60 ~17 ~3 ~60 stone 6  
fill ~14 ~3 ~61 ~17 ~3 ~61 stone 6  
fill ~14 ~3 ~62 ~17 ~3 ~62 stone 6  
fill ~14 ~3 ~63 ~17 ~3 ~63 stone 6  
fill ~14 ~3 ~70 ~18 ~3 ~70 stone 6  
fill ~15 ~3 ~71 ~37 ~3 ~71 stone 6  
fill ~16 ~3 ~7 ~17 ~3 ~7 cobblestone_wall 0 
setblock ~16 ~3 ~8 stonebrick 0  
fill ~16 ~3 ~17 ~24 ~3 ~17 stone 6  
fill ~16 ~3 ~35 ~16 ~3 ~37 stone_brick_stairs 1 
setblock ~17 ~3 ~6 cobblestone_wall 0  
fill ~17 ~3 ~31 ~74 ~3 ~31 stone 6  
fill ~18 ~3 ~18 ~28 ~3 ~18 stone 6  
fill ~18 ~3 ~43 ~18 ~3 ~44 iron_trapdoor 11 
setblock ~18 ~3 ~45 torch 1  
fill ~18 ~3 ~46 ~18 ~3 ~47 iron_trapdoor 11  
fill ~18 ~3 ~50 ~18 ~3 ~51 iron_trapdoor 11 
setblock ~18 ~3 ~52 torch 1  
fill ~18 ~3 ~53 ~18 ~3 ~54 iron_trapdoor 11  
fill ~18 ~3 ~57 ~18 ~3 ~58 iron_trapdoor 11 
setblock ~18 ~3 ~59 torch 1  
fill ~18 ~3 ~60 ~18 ~3 ~61 iron_trapdoor 11  
fill ~19 ~3 ~19 ~32 ~3 ~19 stone 6  
fill ~19 ~3 ~30 ~74 ~3 ~30 stone 6  
fill ~19 ~3 ~32 ~20 ~3 ~32 iron_trapdoor 9 
setblock ~19 ~3 ~38 torch 1  
fill ~19 ~3 ~70 ~20 ~3 ~70 iron_trapdoor 8  
fill ~19 ~3 ~98 ~57 ~3 ~98 stone 6  
fill ~19 ~3 ~104 ~57 ~3 ~104 stone 6  
fill ~20 ~3 ~93 ~56 ~3 ~93 stone 6  
fill ~20 ~3 ~94 ~56 ~3 ~94 stone 6  
fill ~20 ~3 ~95 ~56 ~3 ~95 stone 6  
fill ~20 ~3 ~96 ~56 ~3 ~96 stone 6  
fill ~20 ~3 ~97 ~56 ~3 ~97 stone 6  
fill ~20 ~3 ~99 ~56 ~3 ~99 stone 6  
fill ~20 ~3 ~100 ~56 ~3 ~100 stone 6  
fill ~20 ~3 ~101 ~37 ~3 ~101 stone 6  
fill ~20 ~3 ~102 ~56 ~3 ~102 stone 6  
fill ~20 ~3 ~103 ~56 ~3 ~103 stone 6  
fill ~20 ~3 ~105 ~56 ~3 ~105 stone 6  
fill ~20 ~3 ~106 ~56 ~3 ~106 stone 6  
fill ~20 ~3 ~107 ~56 ~3 ~107 stone 6  
fill ~20 ~3 ~108 ~56 ~3 ~108 stone 6  
fill ~20 ~3 ~109 ~56 ~3 ~109 stone 6  
fill ~21 ~3 ~29 ~23 ~3 ~29 stone 6 
setblock ~21 ~3 ~32 torch 3 
setblock ~21 ~3 ~70 torch 4  
fill ~21 ~3 ~92 ~55 ~3 ~92 stone 6  
fill ~21 ~3 ~110 ~55 ~3 ~110 stone 6  
fill ~22 ~3 ~32 ~23 ~3 ~32 iron_trapdoor 9  
fill ~22 ~3 ~70 ~23 ~3 ~70 iron_trapdoor 8  
fill ~22 ~3 ~91 ~54 ~3 ~91 stone 6  
fill ~22 ~3 ~111 ~54 ~3 ~111 stone 6  
fill ~24 ~3 ~20 ~55 ~3 ~20 stone 6  
fill ~24 ~3 ~32 ~25 ~3 ~32 stonebrick 0  
fill ~24 ~3 ~40 ~25 ~3 ~40 stone 6  
fill ~24 ~3 ~41 ~25 ~3 ~41 stone 6  
fill ~24 ~3 ~47 ~25 ~3 ~47 stone 6  
fill ~24 ~3 ~48 ~25 ~3 ~48 stone 6  
fill ~24 ~3 ~54 ~25 ~3 ~54 stone 6  
fill ~24 ~3 ~55 ~25 ~3 ~55 stone 6  
fill ~24 ~3 ~61 ~25 ~3 ~61 stone 6  
fill ~24 ~3 ~62 ~25 ~3 ~62 stone 6  
fill ~24 ~3 ~70 ~25 ~3 ~70 stonebrick 0  
fill ~24 ~3 ~72 ~37 ~3 ~72 stone 6  
fill ~24 ~3 ~90 ~52 ~3 ~90 stone 6  
fill ~24 ~3 ~112 ~52 ~3 ~112 stone 6  
fill ~25 ~3 ~21 ~53 ~3 ~21 stone 6  
fill ~25 ~3 ~73 ~37 ~3 ~73 stone 6  
fill ~25 ~3 ~74 ~29 ~3 ~74 stone 6  
fill ~26 ~3 ~22 ~35 ~3 ~22 stone 6  
fill ~26 ~3 ~29 ~32 ~3 ~29 stone 6  
fill ~26 ~3 ~32 ~27 ~3 ~32 iron_trapdoor 9  
fill ~26 ~3 ~70 ~27 ~3 ~70 iron_trapdoor 8  
fill ~26 ~3 ~75 ~29 ~3 ~75 stone 6  
fill ~26 ~3 ~76 ~30 ~3 ~76 stone 6  
fill ~27 ~3 ~27 ~29 ~3 ~27 stone 6  
fill ~27 ~3 ~28 ~32 ~3 ~28 stone 6  
fill ~27 ~3 ~77 ~31 ~3 ~77 stone 6  
fill ~27 ~3 ~87 ~37 ~3 ~87 stone 6  
fill ~27 ~3 ~88 ~49 ~3 ~88 stone 6  
fill ~27 ~3 ~89 ~49 ~3 ~89 stone 6  
fill ~27 ~3 ~113 ~49 ~3 ~113 stone 6  
fill ~27 ~3 ~114 ~49 ~3 ~114 stone 6  
fill ~27 ~3 ~115 ~49 ~3 ~115 stone 6 
setblock ~28 ~3 ~32 torch 3 
setblock ~28 ~3 ~70 torch 4  
fill ~28 ~3 ~78 ~32 ~3 ~78 stone 6  
fill ~28 ~3 ~86 ~37 ~3 ~86 stone 6  
fill ~28 ~3 ~116 ~48 ~3 ~116 stone 6  
fill ~28 ~3 ~117 ~48 ~3 ~117 stone 6  
fill ~29 ~3 ~32 ~30 ~3 ~32 iron_trapdoor 9  
fill ~29 ~3 ~70 ~30 ~3 ~70 iron_trapdoor 8  
fill ~29 ~3 ~79 ~32 ~3 ~79 stone 6  
fill ~29 ~3 ~85 ~37 ~3 ~85 stone 6  
fill ~29 ~3 ~118 ~47 ~3 ~118 stone 6  
fill ~30 ~3 ~14 ~33 ~3 ~14 stonebrick 0  
fill ~30 ~3 ~15 ~31 ~3 ~15 stone_brick_stairs 7  
fill ~30 ~3 ~18 ~31 ~3 ~18 stone_brick_stairs 6  
fill ~30 ~3 ~80 ~32 ~3 ~80 stone 6  
fill ~30 ~3 ~84 ~37 ~3 ~84 stone 6  
fill ~30 ~3 ~119 ~46 ~3 ~119 stone 6  
fill ~31 ~3 ~13 ~33 ~3 ~13 stonebrick 0  
fill ~31 ~3 ~32 ~32 ~3 ~32 stonebrick 0  
fill ~31 ~3 ~40 ~32 ~3 ~40 stone 6  
fill ~31 ~3 ~41 ~32 ~3 ~41 stone 6  
fill ~31 ~3 ~47 ~32 ~3 ~47 stone 6  
fill ~31 ~3 ~48 ~32 ~3 ~48 stone 6  
fill ~31 ~3 ~54 ~32 ~3 ~54 stone 6  
fill ~31 ~3 ~55 ~32 ~3 ~55 stone 6  
fill ~31 ~3 ~61 ~32 ~3 ~61 stone 6  
fill ~31 ~3 ~62 ~32 ~3 ~62 stone 6  
fill ~31 ~3 ~70 ~32 ~3 ~70 stonebrick 0  
fill ~32 ~3 ~81 ~37 ~3 ~81 stone 6  
fill ~32 ~3 ~83 ~32 ~7 ~83 stone 6  
fill ~33 ~3 ~32 ~34 ~3 ~32 iron_trapdoor 9  
fill ~33 ~3 ~70 ~34 ~3 ~70 iron_trapdoor 8  
fill ~33 ~3 ~82 ~37 ~3 ~82 stone 6  
fill ~34 ~3 ~74 ~37 ~3 ~74 stone 6  
fill ~34 ~3 ~75 ~37 ~3 ~75 stone 6  
fill ~34 ~3 ~76 ~37 ~3 ~76 stone 6  
fill ~34 ~3 ~77 ~37 ~3 ~77 stone 6  
fill ~34 ~3 ~78 ~37 ~3 ~78 stone 6  
fill ~34 ~3 ~79 ~37 ~3 ~79 stone 6  
fill ~34 ~3 ~80 ~37 ~3 ~80 stone 6  
fill ~34 ~3 ~83 ~37 ~3 ~83 stone 6 
setblock ~35 ~3 ~32 torch 3 
setblock ~35 ~3 ~70 torch 4  
fill ~36 ~3 ~32 ~37 ~3 ~32 iron_trapdoor 9 
setblock ~36 ~3 ~70 iron_trapdoor 8  
fill ~38 ~3 ~32 ~39 ~3 ~32 stonebrick 0  
fill ~38 ~3 ~40 ~39 ~3 ~40 stone 6  
fill ~38 ~3 ~41 ~39 ~3 ~41 stone 6  
fill ~38 ~3 ~47 ~39 ~3 ~47 stone 6  
fill ~38 ~3 ~48 ~39 ~3 ~48 stone 6  
fill ~38 ~3 ~54 ~39 ~3 ~54 stone 6  
fill ~38 ~3 ~55 ~39 ~3 ~55 stone 6  
fill ~38 ~3 ~61 ~39 ~3 ~61 stone 6  
fill ~38 ~3 ~62 ~39 ~3 ~62 stone 6  
fill ~38 ~3 ~87 ~39 ~3 ~87 stone_brick_stairs 2  
fill ~39 ~3 ~101 ~56 ~3 ~101 stone 6  
fill ~40 ~3 ~32 ~41 ~3 ~32 iron_trapdoor 9  
fill ~40 ~3 ~71 ~61 ~3 ~71 stone 6 
setblock ~40 ~3 ~72 stone_brick_stairs 4  
fill ~40 ~3 ~73 ~45 ~3 ~73 stone 6  
fill ~40 ~3 ~74 ~43 ~3 ~74 stone 6  
fill ~40 ~3 ~75 ~43 ~3 ~75 stone 6  
fill ~40 ~3 ~76 ~43 ~3 ~76 stone 6 
setblock ~40 ~3 ~77 stone_brick_stairs 4  
fill ~40 ~3 ~78 ~48 ~3 ~78 stone 6  
fill ~40 ~3 ~79 ~47 ~3 ~79 stone 6  
fill ~40 ~3 ~80 ~46 ~3 ~80 stone 6  
fill ~40 ~3 ~81 ~44 ~3 ~81 stone 6 
setblock ~40 ~3 ~82 stone_brick_stairs 4  
fill ~40 ~3 ~83 ~44 ~3 ~83 stone 6  
fill ~40 ~3 ~84 ~46 ~3 ~84 stone 6  
fill ~40 ~3 ~85 ~47 ~3 ~85 stone 6  
fill ~40 ~3 ~86 ~49 ~3 ~86 stone 6  
fill ~40 ~3 ~87 ~49 ~3 ~87 stone 6 
setblock ~41 ~3 ~70 iron_trapdoor 8  
fill ~41 ~3 ~72 ~52 ~3 ~72 stone 6  
fill ~41 ~3 ~77 ~49 ~3 ~77 stone 6  
fill ~41 ~3 ~82 ~43 ~3 ~82 stone 6  
fill ~42 ~3 ~22 ~43 ~3 ~22 stone 6 
setblock ~42 ~3 ~32 torch 3 
setblock ~42 ~3 ~70 torch 4  
fill ~43 ~3 ~13 ~45 ~3 ~13 stonebrick 0  
fill ~43 ~3 ~14 ~46 ~3 ~14 stonebrick 0  
fill ~43 ~3 ~29 ~74 ~3 ~29 stone 6  
fill ~43 ~3 ~32 ~44 ~3 ~32 iron_trapdoor 9  
fill ~43 ~3 ~70 ~44 ~3 ~70 iron_trapdoor 8  
fill ~44 ~3 ~19 ~57 ~3 ~19 stone 6  
fill ~44 ~3 ~27 ~74 ~3 ~27 stone 6  
fill ~44 ~3 ~28 ~74 ~3 ~28 stone 6  
fill ~45 ~3 ~15 ~46 ~3 ~15 stone_brick_stairs 7  
fill ~45 ~3 ~18 ~46 ~3 ~18 stone_brick_stairs 6  
fill ~45 ~3 ~32 ~46 ~3 ~32 stonebrick 0  
fill ~45 ~3 ~40 ~46 ~3 ~40 stone 6  
fill ~45 ~3 ~41 ~46 ~3 ~41 stone 6  
fill ~45 ~3 ~47 ~46 ~3 ~47 stone 6  
fill ~45 ~3 ~48 ~46 ~3 ~48 stone 6  
fill ~45 ~3 ~54 ~46 ~3 ~54 stone 6  
fill ~45 ~3 ~55 ~46 ~3 ~55 stone 6  
fill ~45 ~3 ~61 ~46 ~3 ~61 stone 6  
fill ~45 ~3 ~62 ~46 ~3 ~62 stone 6  
fill ~45 ~3 ~70 ~46 ~3 ~70 stonebrick 0  
fill ~45 ~3 ~76 ~50 ~3 ~76 stone 6  
fill ~46 ~3 ~22 ~48 ~3 ~22 stone 6  
fill ~46 ~3 ~75 ~50 ~3 ~75 stone 6  
fill ~47 ~3 ~32 ~48 ~3 ~32 iron_trapdoor 9  
fill ~47 ~3 ~70 ~48 ~3 ~70 iron_trapdoor 8  
fill ~48 ~3 ~18 ~58 ~3 ~18 stone 6  
fill ~48 ~3 ~74 ~51 ~3 ~74 stone 6 
setblock ~49 ~3 ~32 torch 3 
setblock ~49 ~3 ~70 torch 4  
fill ~49 ~3 ~73 ~51 ~3 ~73 stone 6  
fill ~50 ~3 ~32 ~51 ~3 ~32 iron_trapdoor 9  
fill ~50 ~3 ~70 ~51 ~3 ~70 iron_trapdoor 8  
fill ~51 ~3 ~80 ~52 ~3 ~80 stone 6  
fill ~51 ~3 ~81 ~52 ~3 ~81 stone 6  
fill ~51 ~3 ~82 ~52 ~3 ~82 stone 6  
fill ~51 ~3 ~83 ~52 ~3 ~83 stone 6  
fill ~51 ~3 ~84 ~52 ~3 ~84 stone 6  
fill ~52 ~3 ~17 ~60 ~3 ~17 stone 6  
fill ~52 ~3 ~32 ~53 ~3 ~32 stonebrick 0  
fill ~52 ~3 ~40 ~53 ~3 ~40 stone 6  
fill ~52 ~3 ~41 ~53 ~3 ~41 stone 6  
fill ~52 ~3 ~47 ~53 ~3 ~47 stone 6  
fill ~52 ~3 ~48 ~53 ~3 ~48 stone 6  
fill ~52 ~3 ~54 ~53 ~3 ~54 stone 6  
fill ~52 ~3 ~55 ~53 ~3 ~55 stone 6  
fill ~52 ~3 ~61 ~53 ~3 ~61 stone 6  
fill ~52 ~3 ~62 ~53 ~3 ~62 stone 6  
fill ~52 ~3 ~70 ~53 ~3 ~70 stonebrick 0  
fill ~52 ~3 ~78 ~53 ~3 ~78 stone 6  
fill ~52 ~3 ~79 ~53 ~3 ~79 stone 6  
fill ~52 ~3 ~85 ~53 ~3 ~85 stone 6  
fill ~52 ~3 ~86 ~53 ~3 ~86 stone 6  
fill ~53 ~3 ~77 ~54 ~3 ~77 stone 6  
fill ~53 ~3 ~87 ~54 ~3 ~87 stone 6  
fill ~54 ~3 ~32 ~55 ~3 ~32 iron_trapdoor 9  
fill ~54 ~3 ~70 ~55 ~3 ~70 iron_trapdoor 8  
fill ~54 ~3 ~76 ~56 ~3 ~76 stone 6  
fill ~54 ~3 ~88 ~56 ~3 ~88 stone 6  
fill ~55 ~3 ~16 ~64 ~3 ~16 stone 6  
fill ~55 ~3 ~75 ~63 ~3 ~75 stone 6  
fill ~55 ~3 ~89 ~66 ~3 ~89 stone 6 
setblock ~56 ~3 ~32 torch 3 
setblock ~56 ~3 ~70 torch 4  
fill ~57 ~3 ~15 ~64 ~3 ~15 stone 6  
fill ~57 ~3 ~26 ~74 ~3 ~26 stone 6  
fill ~57 ~3 ~32 ~58 ~3 ~32 iron_trapdoor 9  
fill ~57 ~3 ~70 ~58 ~3 ~70 iron_trapdoor 8  
fill ~57 ~3 ~74 ~61 ~3 ~74 stone 6  
fill ~57 ~3 ~90 ~65 ~3 ~90 stone 6  
fill ~58 ~3 ~14 ~65 ~3 ~14 stone 6 
setblock ~58 ~3 ~38 torch 2  
fill ~59 ~3 ~6 ~59 ~3 ~7 cobblestone_wall 0  
fill ~59 ~3 ~13 ~65 ~3 ~13 stone 6  
fill ~59 ~3 ~32 ~74 ~3 ~32 stone 6  
fill ~59 ~3 ~33 ~74 ~3 ~33 stone 6  
fill ~59 ~3 ~34 ~74 ~3 ~34 stone 6  
fill ~59 ~3 ~38 ~74 ~3 ~38 stone 6  
fill ~59 ~3 ~39 ~73 ~3 ~39 stone 6  
fill ~59 ~3 ~42 ~59 ~3 ~43 iron_trapdoor 10 
setblock ~59 ~3 ~44 torch 2  
fill ~59 ~3 ~45 ~59 ~3 ~46 iron_trapdoor 10  
fill ~59 ~3 ~49 ~59 ~3 ~50 iron_trapdoor 10 
setblock ~59 ~3 ~51 torch 2  
fill ~59 ~3 ~52 ~59 ~3 ~53 iron_trapdoor 10  
fill ~59 ~3 ~56 ~59 ~3 ~57 iron_trapdoor 10 
setblock ~59 ~3 ~58 torch 2  
fill ~59 ~3 ~59 ~59 ~3 ~60 iron_trapdoor 10  
fill ~59 ~3 ~63 ~62 ~3 ~63 stone 6  
fill ~59 ~3 ~64 ~63 ~3 ~64 stone 6  
fill ~59 ~3 ~65 ~63 ~3 ~65 stone 6  
fill ~59 ~3 ~66 ~63 ~3 ~66 stone 6  
fill ~59 ~3 ~67 ~63 ~3 ~67 stone 6  
fill ~59 ~3 ~68 ~63 ~3 ~68 stone 6  
fill ~59 ~3 ~69 ~63 ~3 ~69 stone 6  
fill ~59 ~3 ~70 ~62 ~3 ~70 stone 6 
setblock ~60 ~3 ~7 cobblestone_wall 0  
fill ~60 ~3 ~8 ~60 ~3 ~9 stonebrick 0  
fill ~60 ~3 ~10 ~65 ~3 ~10 stone 6  
fill ~60 ~3 ~11 ~65 ~3 ~11 stone 6  
fill ~60 ~3 ~12 ~65 ~3 ~12 stone 6  
fill ~60 ~3 ~40 ~73 ~3 ~40 stone 6  
fill ~60 ~3 ~41 ~72 ~3 ~41 stone 6  
fill ~60 ~3 ~42 ~62 ~3 ~42 stone 6  
fill ~60 ~3 ~43 ~62 ~3 ~43 stone 6  
fill ~60 ~3 ~44 ~62 ~3 ~44 stone 6  
fill ~60 ~3 ~45 ~62 ~3 ~45 stone 6  
fill ~60 ~3 ~46 ~62 ~3 ~46 stone 6  
fill ~60 ~3 ~47 ~62 ~3 ~47 stone 6  
fill ~60 ~3 ~48 ~62 ~3 ~48 stone 6  
fill ~60 ~3 ~49 ~62 ~3 ~49 stone 6  
fill ~60 ~3 ~50 ~62 ~3 ~50 stone 6  
fill ~60 ~3 ~51 ~62 ~3 ~51 stone 6  
fill ~60 ~3 ~52 ~62 ~3 ~52 stone 6  
fill ~60 ~3 ~53 ~62 ~3 ~53 stone 6  
fill ~60 ~3 ~54 ~62 ~3 ~54 stone 6  
fill ~60 ~3 ~55 ~62 ~3 ~55 stone 6  
fill ~60 ~3 ~56 ~62 ~3 ~56 stone 6  
fill ~60 ~3 ~57 ~62 ~3 ~57 stone 6  
fill ~60 ~3 ~58 ~62 ~3 ~58 stone 6  
fill ~60 ~3 ~59 ~62 ~3 ~59 stone 6  
fill ~60 ~3 ~60 ~62 ~3 ~60 stone 6  
fill ~60 ~3 ~61 ~62 ~3 ~61 stone 6  
fill ~60 ~3 ~62 ~62 ~3 ~62 stone 6  
fill ~61 ~3 ~8 ~64 ~3 ~8 stone_slab 5  
fill ~61 ~3 ~9 ~65 ~3 ~9 stonebrick 0  
fill ~61 ~3 ~35 ~61 ~3 ~37 stone_brick_stairs 0  
fill ~62 ~3 ~24 ~74 ~3 ~24 stone 6  
fill ~62 ~3 ~25 ~74 ~3 ~25 stone 6  
fill ~62 ~3 ~35 ~74 ~3 ~35 stone 6  
fill ~62 ~3 ~36 ~74 ~3 ~36 stone 6  
fill ~62 ~3 ~37 ~74 ~3 ~37 stone 6  
fill ~62 ~3 ~76 ~64 ~3 ~76 stone 6  
fill ~62 ~3 ~88 ~67 ~3 ~88 stone 6  
fill ~62 ~3 ~91 ~64 ~3 ~91 stone 6  
fill ~63 ~3 ~17 ~74 ~3 ~17 stone 6  
fill ~63 ~3 ~23 ~74 ~3 ~23 stone 6  
fill ~64 ~3 ~5 ~64 ~3 ~7 cobblestone_wall 0  
fill ~64 ~3 ~18 ~74 ~3 ~18 stone 6  
fill ~64 ~3 ~19 ~74 ~3 ~19 stone 6  
fill ~64 ~3 ~42 ~71 ~3 ~42 stone 6  
fill ~64 ~3 ~77 ~65 ~3 ~77 stone 6  
fill ~64 ~3 ~87 ~67 ~3 ~87 stone 6 
setblock ~65 ~3 ~8 stonebrick 0  
fill ~65 ~3 ~20 ~74 ~3 ~20 stone 6  
fill ~65 ~3 ~78 ~66 ~3 ~78 stone 6  
fill ~65 ~3 ~79 ~66 ~3 ~79 stone 6  
fill ~65 ~3 ~85 ~67 ~3 ~85 stone 6  
fill ~65 ~3 ~86 ~67 ~3 ~86 stone 6  
fill ~66 ~3 ~22 ~74 ~3 ~22 stone 6  
fill ~66 ~3 ~43 ~69 ~3 ~43 stone 6  
fill ~66 ~3 ~80 ~67 ~3 ~80 stone 6  
fill ~66 ~3 ~81 ~67 ~3 ~81 stone 6  
fill ~66 ~3 ~82 ~67 ~3 ~82 stone 6  
fill ~66 ~3 ~83 ~67 ~3 ~83 stone 6  
fill ~66 ~3 ~84 ~67 ~3 ~84 stone 6  
fill ~67 ~3 ~21 ~74 ~3 ~21 stone 6  
fill ~2 ~4 ~17 ~24 ~4 ~17 stone 6  
fill ~2 ~4 ~18 ~28 ~4 ~18 stone 6  
fill ~2 ~4 ~19 ~32 ~4 ~19 stone 6  
fill ~2 ~4 ~20 ~21 ~4 ~20 stone 6  
fill ~2 ~4 ~21 ~19 ~4 ~21 stone 6  
fill ~2 ~4 ~22 ~17 ~4 ~22 stone 6  
fill ~2 ~4 ~23 ~13 ~4 ~23 stone 6  
fill ~2 ~4 ~24 ~15 ~4 ~24 stone 6  
fill ~2 ~4 ~25 ~19 ~4 ~25 stone 6  
fill ~2 ~4 ~26 ~21 ~4 ~26 stone 6  
fill ~2 ~4 ~27 ~21 ~4 ~27 stone 6  
fill ~2 ~4 ~28 ~21 ~4 ~28 stone 6  
fill ~2 ~4 ~29 ~22 ~4 ~29 stone 6  
fill ~2 ~4 ~30 ~38 ~4 ~30 stone 6  
fill ~2 ~4 ~31 ~74 ~4 ~31 stone 6  
fill ~2 ~4 ~32 ~18 ~4 ~32 stone 6  
fill ~2 ~4 ~33 ~18 ~4 ~33 stone 6  
fill ~2 ~4 ~34 ~18 ~4 ~34 stone 6  
fill ~2 ~4 ~35 ~10 ~4 ~35 stone 6  
fill ~2 ~4 ~36 ~10 ~4 ~36 stone 6  
fill ~2 ~4 ~37 ~10 ~4 ~37 stone 6  
fill ~2 ~4 ~38 ~18 ~4 ~38 stone 6  
fill ~2 ~4 ~39 ~18 ~4 ~39 stone 6  
fill ~3 ~4 ~40 ~18 ~4 ~40 stone 6  
fill ~3 ~4 ~41 ~17 ~4 ~41 stone 6  
fill ~5 ~4 ~42 ~12 ~4 ~42 stone 6  
fill ~7 ~4 ~43 ~10 ~4 ~43 stone 6 
setblock ~11 ~4 ~8 cobblestone_wall 0  
fill ~11 ~4 ~9 ~11 ~4 ~10 stonebrick 0  
fill ~11 ~4 ~11 ~11 ~0 ~11 stone 6  
fill ~11 ~4 ~12 ~11 ~0 ~12 stone 6  
fill ~11 ~4 ~13 ~17 ~4 ~13 stone 6  
fill ~11 ~4 ~14 ~18 ~4 ~14 stone 6  
fill ~11 ~4 ~35 ~14 ~4 ~35 stonebrick 0  
fill ~11 ~4 ~36 ~14 ~4 ~36 stonebrick 0  
fill ~11 ~4 ~37 ~14 ~4 ~37 stonebrick 0  
fill ~12 ~4 ~10 ~15 ~4 ~10 stone_slab 5  
fill ~12 ~4 ~11 ~15 ~4 ~11 stonebrick 0  
fill ~12 ~4 ~12 ~14 ~4 ~12 stonebrick 0  
fill ~13 ~4 ~15 ~19 ~4 ~15 stone 6  
fill ~13 ~4 ~64 ~18 ~4 ~64 stone 6  
fill ~13 ~4 ~65 ~18 ~4 ~65 stone 6  
fill ~13 ~4 ~66 ~18 ~4 ~66 stone 6  
fill ~13 ~4 ~67 ~18 ~4 ~67 stone 6  
fill ~13 ~4 ~68 ~18 ~4 ~68 stone 6  
fill ~13 ~4 ~69 ~18 ~4 ~69 stone 6  
fill ~14 ~4 ~16 ~21 ~4 ~16 stone 6  
fill ~14 ~4 ~42 ~17 ~4 ~42 stone 6  
fill ~14 ~4 ~43 ~17 ~4 ~43 stone 6  
fill ~14 ~4 ~44 ~17 ~4 ~44 stone 6  
fill ~14 ~4 ~45 ~17 ~4 ~45 stone 6  
fill ~14 ~4 ~46 ~17 ~4 ~46 stone 6  
fill ~14 ~4 ~47 ~17 ~4 ~47 stone 6  
fill ~14 ~4 ~48 ~17 ~4 ~48 stone 6  
fill ~14 ~4 ~49 ~17 ~4 ~49 stone 6  
fill ~14 ~4 ~50 ~17 ~4 ~50 stone 6  
fill ~14 ~4 ~51 ~17 ~4 ~51 stone 6  
fill ~14 ~4 ~52 ~17 ~4 ~52 stone 6  
fill ~14 ~4 ~53 ~17 ~4 ~53 stone 6  
fill ~14 ~4 ~54 ~17 ~4 ~54 stone 6  
fill ~14 ~4 ~55 ~17 ~4 ~55 stone 6  
fill ~14 ~4 ~56 ~17 ~4 ~56 stone 6  
fill ~14 ~4 ~57 ~17 ~4 ~57 stone 6  
fill ~14 ~4 ~58 ~17 ~4 ~58 stone 6  
fill ~14 ~4 ~59 ~17 ~4 ~59 stone 6  
fill ~14 ~4 ~60 ~17 ~4 ~60 stone 6  
fill ~14 ~4 ~61 ~17 ~4 ~61 stone 6  
fill ~14 ~4 ~62 ~17 ~4 ~62 stone 6  
fill ~14 ~4 ~63 ~17 ~4 ~63 stone 6  
fill ~14 ~4 ~70 ~18 ~4 ~70 stone 6  
fill ~15 ~4 ~12 ~16 ~4 ~12 stone 6  
fill ~15 ~4 ~35 ~15 ~4 ~37 stone_brick_stairs 1  
fill ~15 ~4 ~71 ~37 ~4 ~71 stone 6 
setblock ~16 ~4 ~8 cobblestone_wall 0  
fill ~16 ~4 ~9 ~16 ~4 ~10 stonebrick 0 
setblock ~16 ~4 ~11 stone 6  
fill ~18 ~4 ~43 ~18 ~4 ~44 chest 5  
fill ~18 ~4 ~46 ~18 ~4 ~47 chest 5  
fill ~18 ~4 ~50 ~18 ~4 ~51 chest 5  
fill ~18 ~4 ~53 ~18 ~4 ~54 chest 5  
fill ~18 ~4 ~57 ~18 ~4 ~58 chest 5  
fill ~18 ~4 ~60 ~18 ~4 ~61 chest 5  
fill ~19 ~4 ~32 ~20 ~4 ~32 chest 3  
fill ~19 ~4 ~70 ~20 ~4 ~70 chest 2  
fill ~19 ~4 ~98 ~57 ~4 ~98 stone 6  
fill ~19 ~4 ~104 ~57 ~4 ~104 stone 6  
fill ~20 ~4 ~93 ~56 ~4 ~93 stone 6  
fill ~20 ~4 ~94 ~56 ~4 ~94 stone 6  
fill ~20 ~4 ~95 ~56 ~4 ~95 stone 6  
fill ~20 ~4 ~96 ~56 ~4 ~96 stone 6  
fill ~20 ~4 ~97 ~56 ~4 ~97 stone 6  
fill ~20 ~4 ~99 ~56 ~4 ~99 stone 6  
fill ~20 ~4 ~100 ~56 ~4 ~100 stone 6  
fill ~20 ~4 ~101 ~37 ~4 ~101 stone 6  
fill ~20 ~4 ~102 ~56 ~4 ~102 stone 6  
fill ~20 ~4 ~103 ~56 ~4 ~103 stone 6  
fill ~20 ~4 ~105 ~56 ~4 ~105 stone 6  
fill ~20 ~4 ~106 ~56 ~4 ~106 stone 6  
fill ~20 ~4 ~107 ~56 ~4 ~107 stone 6  
fill ~20 ~4 ~108 ~56 ~4 ~108 stone 6  
fill ~20 ~4 ~109 ~56 ~4 ~109 stone 6  
fill ~21 ~4 ~92 ~55 ~4 ~92 stone 6  
fill ~21 ~4 ~110 ~55 ~4 ~110 stone 6  
fill ~22 ~4 ~32 ~23 ~4 ~32 chest 3  
fill ~22 ~4 ~70 ~23 ~4 ~70 chest 2  
fill ~22 ~4 ~91 ~54 ~4 ~91 stone 6  
fill ~22 ~4 ~111 ~54 ~4 ~111 stone 6  
fill ~24 ~4 ~32 ~25 ~4 ~32 stonebrick 0  
fill ~24 ~4 ~40 ~25 ~4 ~40 stone 6  
fill ~24 ~4 ~41 ~25 ~4 ~41 stone 6  
fill ~24 ~4 ~47 ~25 ~4 ~47 stone 6  
fill ~24 ~4 ~48 ~25 ~4 ~48 stone 6  
fill ~24 ~4 ~54 ~25 ~4 ~54 stone 6  
fill ~24 ~4 ~55 ~25 ~4 ~55 stone 6  
fill ~24 ~4 ~61 ~25 ~4 ~61 stone 6  
fill ~24 ~4 ~62 ~25 ~4 ~62 stone 6  
fill ~24 ~4 ~70 ~25 ~4 ~70 stonebrick 0  
fill ~24 ~4 ~72 ~37 ~4 ~72 stone 6  
fill ~24 ~4 ~90 ~52 ~4 ~90 stone 6  
fill ~24 ~4 ~112 ~52 ~4 ~112 stone 6  
fill ~25 ~4 ~20 ~55 ~4 ~20 stone 6  
fill ~25 ~4 ~21 ~52 ~4 ~21 stone 6  
fill ~25 ~4 ~27 ~33 ~4 ~27 stone 6  
fill ~25 ~4 ~28 ~34 ~4 ~28 stone 6  
fill ~25 ~4 ~29 ~34 ~4 ~29 stone 6  
fill ~25 ~4 ~73 ~37 ~4 ~73 stone 6  
fill ~25 ~4 ~74 ~27 ~4 ~74 stone 6  
fill ~26 ~4 ~22 ~35 ~4 ~22 stone 6  
fill ~26 ~4 ~26 ~30 ~4 ~26 stone 6  
fill ~26 ~4 ~32 ~27 ~4 ~32 chest 3  
fill ~26 ~4 ~70 ~27 ~4 ~70 chest 2  
fill ~26 ~4 ~75 ~28 ~4 ~75 stone 6  
fill ~26 ~4 ~76 ~30 ~4 ~76 stone 6 
setblock ~27 ~4 ~44 torch 2 
setblock ~27 ~4 ~51 torch 2 
setblock ~27 ~4 ~58 torch 2  
fill ~27 ~4 ~77 ~31 ~4 ~77 stone 6  
fill ~27 ~4 ~87 ~37 ~4 ~87 stone 6  
fill ~27 ~4 ~88 ~37 ~4 ~88 stone 6  
fill ~27 ~4 ~89 ~49 ~4 ~89 stone 6  
fill ~27 ~4 ~113 ~49 ~4 ~113 stone 6  
fill ~27 ~4 ~114 ~49 ~4 ~114 stone 6  
fill ~27 ~4 ~115 ~49 ~4 ~115 stone 6  
fill ~28 ~4 ~23 ~30 ~4 ~23 stone 6 
setblock ~28 ~4 ~43 torch 4 
setblock ~28 ~4 ~44 stone 6 
setblock ~28 ~4 ~45 torch 3 
setblock ~28 ~4 ~50 torch 4 
setblock ~28 ~4 ~51 stone 6 
setblock ~28 ~4 ~52 torch 3 
setblock ~28 ~4 ~58 stone 6 
setblock ~28 ~4 ~59 torch 3  
fill ~28 ~4 ~78 ~31 ~4 ~78 stone 6  
fill ~28 ~4 ~86 ~37 ~4 ~86 stone 6  
fill ~28 ~4 ~116 ~48 ~4 ~116 stone 6  
fill ~28 ~4 ~117 ~48 ~4 ~117 stone 6  
fill ~29 ~4 ~32 ~30 ~4 ~32 chest 3 
setblock ~29 ~4 ~44 torch 1 
setblock ~29 ~4 ~51 torch 1 
setblock ~29 ~4 ~58 torch 1  
fill ~29 ~4 ~70 ~30 ~4 ~70 chest 2  
fill ~29 ~4 ~79 ~32 ~4 ~79 stone 6  
fill ~29 ~4 ~85 ~37 ~4 ~85 stone 6  
fill ~29 ~4 ~118 ~47 ~4 ~118 stone 6  
fill ~30 ~4 ~14 ~33 ~4 ~14 stonebrick 0  
fill ~30 ~4 ~15 ~31 ~4 ~15 stonebrick 0  
fill ~30 ~4 ~16 ~31 ~4 ~16 stone_brick_stairs 7  
fill ~30 ~4 ~17 ~31 ~4 ~17 stone_brick_stairs 6  
fill ~30 ~4 ~18 ~31 ~4 ~18 stonebrick 0  
fill ~30 ~4 ~80 ~37 ~4 ~80 stone 6  
fill ~30 ~4 ~84 ~37 ~4 ~84 stone 6  
fill ~30 ~4 ~119 ~46 ~4 ~119 stone 6  
fill ~31 ~4 ~13 ~33 ~4 ~13 stonebrick 0  
fill ~31 ~4 ~32 ~32 ~4 ~32 stonebrick 0  
fill ~31 ~4 ~40 ~32 ~4 ~40 stone 6  
fill ~31 ~4 ~41 ~32 ~4 ~41 stone 6  
fill ~31 ~4 ~47 ~32 ~4 ~47 stone 6  
fill ~31 ~4 ~48 ~32 ~4 ~48 stone 6  
fill ~31 ~4 ~54 ~32 ~4 ~54 stone 6  
fill ~31 ~4 ~55 ~32 ~4 ~55 stone 6  
fill ~31 ~4 ~61 ~32 ~4 ~61 stone 6  
fill ~31 ~4 ~62 ~32 ~4 ~62 stone 6  
fill ~31 ~4 ~70 ~32 ~4 ~70 stonebrick 0 
setblock ~32 ~4 ~15 stone_brick_stairs 7 
setblock ~32 ~4 ~18 stone_brick_stairs 6  
fill ~32 ~4 ~81 ~37 ~4 ~81 stone 6 
setblock ~33 ~4 ~19 stone_brick_stairs 5  
fill ~33 ~4 ~32 ~34 ~4 ~32 chest 3  
fill ~33 ~4 ~70 ~34 ~4 ~70 chest 2  
fill ~33 ~4 ~82 ~37 ~4 ~82 stone 6  
fill ~33 ~4 ~83 ~37 ~4 ~83 stone 6  
fill ~34 ~4 ~13 ~34 ~4 ~14 stone_brick_stairs 5 
setblock ~34 ~4 ~44 torch 2 
setblock ~34 ~4 ~51 torch 2 
setblock ~34 ~4 ~58 torch 2  
fill ~34 ~4 ~78 ~37 ~4 ~78 stone 6  
fill ~34 ~4 ~79 ~37 ~4 ~79 stone 6 
setblock ~35 ~4 ~43 torch 4 
setblock ~35 ~4 ~44 stone 6 
setblock ~35 ~4 ~45 torch 3 
setblock ~35 ~4 ~50 torch 4 
setblock ~35 ~4 ~51 stone 6 
setblock ~35 ~4 ~52 torch 3 
setblock ~35 ~4 ~58 stone 6 
setblock ~35 ~4 ~59 torch 3  
fill ~35 ~4 ~74 ~37 ~4 ~74 stone 6  
fill ~35 ~4 ~75 ~37 ~4 ~75 stone 6  
fill ~35 ~4 ~76 ~37 ~4 ~76 stone 6  
fill ~35 ~4 ~77 ~37 ~4 ~77 stone 6  
fill ~36 ~4 ~32 ~37 ~4 ~32 chest 3 
setblock ~36 ~4 ~44 torch 1 
setblock ~36 ~4 ~51 torch 1 
setblock ~36 ~4 ~58 torch 1 
setblock ~36 ~4 ~70 chest 2  
fill ~38 ~4 ~32 ~39 ~4 ~32 stonebrick 0  
fill ~38 ~4 ~40 ~39 ~4 ~40 stone 6  
fill ~38 ~4 ~41 ~39 ~4 ~41 stone 6  
fill ~38 ~4 ~47 ~39 ~4 ~47 stone 6  
fill ~38 ~4 ~48 ~39 ~4 ~48 stone 6  
fill ~38 ~4 ~54 ~39 ~4 ~54 stone 6  
fill ~38 ~4 ~55 ~39 ~4 ~55 stone 6  
fill ~38 ~4 ~61 ~39 ~4 ~61 stone 6  
fill ~38 ~4 ~62 ~39 ~4 ~62 stone 6  
fill ~38 ~4 ~70 ~38 ~4 ~83 stone_brick_stairs 5  
fill ~38 ~4 ~88 ~39 ~4 ~88 stone_brick_stairs 2  
fill ~39 ~4 ~70 ~39 ~4 ~83 stone_brick_stairs 4  
fill ~39 ~4 ~101 ~41 ~4 ~101 stone 6  
fill ~40 ~4 ~32 ~41 ~4 ~32 chest 3  
fill ~40 ~4 ~71 ~61 ~4 ~71 stone 6  
fill ~40 ~4 ~72 ~52 ~4 ~72 stone 6  
fill ~40 ~4 ~73 ~51 ~4 ~73 stone 6  
fill ~40 ~4 ~74 ~43 ~4 ~74 stone 6  
fill ~40 ~4 ~75 ~43 ~4 ~75 stone 6  
fill ~40 ~4 ~76 ~43 ~4 ~76 stone 6  
fill ~40 ~4 ~77 ~49 ~4 ~77 stone 6  
fill ~40 ~4 ~78 ~48 ~4 ~78 stone 6  
fill ~40 ~4 ~79 ~47 ~4 ~79 stone 6  
fill ~40 ~4 ~80 ~46 ~4 ~80 stone 6  
fill ~40 ~4 ~81 ~44 ~4 ~81 stone 6  
fill ~40 ~4 ~82 ~43 ~4 ~82 stone 6  
fill ~40 ~4 ~83 ~44 ~4 ~83 stone 6  
fill ~40 ~4 ~84 ~46 ~4 ~84 stone 6  
fill ~40 ~4 ~85 ~47 ~4 ~85 stone 6  
fill ~40 ~4 ~86 ~49 ~4 ~86 stone 6  
fill ~40 ~4 ~87 ~49 ~4 ~87 stone 6  
fill ~40 ~4 ~88 ~49 ~4 ~88 stone 6 
setblock ~41 ~4 ~44 torch 2 
setblock ~41 ~4 ~51 torch 2 
setblock ~41 ~4 ~58 torch 2 
setblock ~41 ~4 ~70 chest 2  
fill ~42 ~4 ~13 ~42 ~4 ~14 stone_brick_stairs 4  
fill ~42 ~4 ~22 ~42 ~0 ~22 stone 6  
fill ~42 ~4 ~27 ~74 ~4 ~27 stone 6  
fill ~42 ~4 ~28 ~74 ~4 ~28 stone 6  
fill ~42 ~4 ~29 ~74 ~4 ~29 stone 6  
fill ~42 ~4 ~30 ~74 ~4 ~30 stone 6 
setblock ~42 ~4 ~43 torch 4 
setblock ~42 ~4 ~44 stone 6 
setblock ~42 ~4 ~45 torch 3 
setblock ~42 ~4 ~50 torch 4 
setblock ~42 ~4 ~51 stone 6 
setblock ~42 ~4 ~52 torch 3 
setblock ~42 ~4 ~58 stone 6 
setblock ~42 ~4 ~59 torch 3 
setblock ~42 ~4 ~101 hopper 0  
fill ~43 ~4 ~13 ~45 ~4 ~13 stonebrick 0  
fill ~43 ~4 ~14 ~46 ~4 ~14 stonebrick 0 
setblock ~43 ~4 ~19 stone_brick_stairs 4  
fill ~43 ~4 ~26 ~74 ~4 ~26 stone 6  
fill ~43 ~4 ~32 ~44 ~4 ~32 chest 3 
setblock ~43 ~4 ~44 torch 1 
setblock ~43 ~4 ~51 torch 1 
setblock ~43 ~4 ~58 torch 1  
fill ~43 ~4 ~70 ~44 ~4 ~70 chest 2  
fill ~43 ~4 ~101 ~56 ~4 ~101 stone 6 
setblock ~44 ~4 ~15 stone_brick_stairs 4 
setblock ~44 ~4 ~18 stone_brick_stairs 6  
fill ~44 ~4 ~19 ~57 ~4 ~19 stone 6  
fill ~45 ~4 ~15 ~46 ~4 ~15 stonebrick 0  
fill ~45 ~4 ~16 ~46 ~4 ~16 stone_brick_stairs 7  
fill ~45 ~4 ~17 ~46 ~4 ~17 stone_brick_stairs 6  
fill ~45 ~4 ~18 ~46 ~4 ~18 stonebrick 0  
fill ~45 ~4 ~25 ~48 ~4 ~25 stone 6  
fill ~45 ~4 ~32 ~46 ~4 ~32 stonebrick 0  
fill ~45 ~4 ~40 ~46 ~4 ~40 stone 6  
fill ~45 ~4 ~41 ~46 ~4 ~41 stone 6  
fill ~45 ~4 ~47 ~46 ~4 ~47 stone 6  
fill ~45 ~4 ~48 ~46 ~4 ~48 stone 6  
fill ~45 ~4 ~54 ~46 ~4 ~54 stone 6  
fill ~45 ~4 ~55 ~46 ~4 ~55 stone 6  
fill ~45 ~4 ~61 ~46 ~4 ~61 stone 6  
fill ~45 ~4 ~62 ~46 ~4 ~62 stone 6  
fill ~45 ~4 ~70 ~46 ~4 ~70 stonebrick 0  
fill ~45 ~4 ~76 ~50 ~4 ~76 stone 6  
fill ~46 ~4 ~22 ~48 ~4 ~22 stone 6  
fill ~46 ~4 ~75 ~50 ~4 ~75 stone 6  
fill ~47 ~4 ~32 ~48 ~4 ~32 chest 3  
fill ~47 ~4 ~70 ~48 ~4 ~70 chest 2  
fill ~48 ~4 ~18 ~62 ~4 ~18 stone 6 
setblock ~48 ~4 ~44 torch 2 
setblock ~48 ~4 ~51 torch 2 
setblock ~48 ~4 ~58 torch 2  
fill ~48 ~4 ~74 ~51 ~4 ~74 stone 6 
setblock ~49 ~4 ~43 torch 4 
setblock ~49 ~4 ~44 stone 6 
setblock ~49 ~4 ~45 torch 3 
setblock ~49 ~4 ~50 torch 4 
setblock ~49 ~4 ~51 stone 6 
setblock ~49 ~4 ~52 torch 3 
setblock ~49 ~4 ~58 stone 6 
setblock ~49 ~4 ~59 torch 3  
fill ~50 ~4 ~32 ~51 ~4 ~32 chest 3 
setblock ~50 ~4 ~44 torch 1 
setblock ~50 ~4 ~51 torch 1 
setblock ~50 ~4 ~58 torch 1  
fill ~50 ~4 ~70 ~51 ~4 ~70 chest 2  
fill ~51 ~4 ~80 ~52 ~4 ~80 stone 6  
fill ~51 ~4 ~81 ~52 ~4 ~81 stone 6  
fill ~51 ~4 ~82 ~52 ~4 ~82 stone 6  
fill ~51 ~4 ~83 ~52 ~4 ~83 stone 6  
fill ~51 ~4 ~84 ~52 ~4 ~84 stone 6  
fill ~52 ~4 ~17 ~74 ~4 ~17 stone 6  
fill ~52 ~4 ~32 ~53 ~4 ~32 stonebrick 0  
fill ~52 ~4 ~40 ~53 ~4 ~40 stone 6  
fill ~52 ~4 ~41 ~53 ~4 ~41 stone 6  
fill ~52 ~4 ~47 ~53 ~4 ~47 stone 6  
fill ~52 ~4 ~48 ~53 ~4 ~48 stone 6  
fill ~52 ~4 ~54 ~53 ~4 ~54 stone 6  
fill ~52 ~4 ~55 ~53 ~4 ~55 stone 6  
fill ~52 ~4 ~61 ~53 ~4 ~61 stone 6  
fill ~52 ~4 ~62 ~53 ~4 ~62 stone 6  
fill ~52 ~4 ~70 ~53 ~4 ~70 stonebrick 0  
fill ~52 ~4 ~78 ~53 ~4 ~78 stone 6  
fill ~52 ~4 ~79 ~53 ~4 ~79 stone 6  
fill ~52 ~4 ~85 ~53 ~4 ~85 stone 6  
fill ~52 ~4 ~86 ~53 ~4 ~86 stone 6  
fill ~53 ~4 ~77 ~54 ~4 ~77 stone 6  
fill ~53 ~4 ~87 ~54 ~4 ~87 stone 6  
fill ~54 ~4 ~25 ~74 ~4 ~25 stone 6  
fill ~54 ~4 ~32 ~55 ~4 ~32 chest 3  
fill ~54 ~4 ~70 ~55 ~4 ~70 chest 2  
fill ~54 ~4 ~76 ~56 ~4 ~76 stone 6  
fill ~54 ~4 ~88 ~56 ~4 ~88 stone 6  
fill ~55 ~4 ~16 ~64 ~4 ~16 stone 6  
fill ~55 ~4 ~75 ~63 ~4 ~75 stone 6  
fill ~55 ~4 ~89 ~66 ~4 ~89 stone 6  
fill ~57 ~4 ~15 ~64 ~4 ~15 stone 6  
fill ~57 ~4 ~32 ~58 ~4 ~32 chest 3  
fill ~57 ~4 ~70 ~58 ~4 ~70 chest 2  
fill ~57 ~4 ~74 ~61 ~4 ~74 stone 6  
fill ~57 ~4 ~90 ~65 ~4 ~90 stone 6  
fill ~58 ~4 ~14 ~65 ~4 ~14 stone 6  
fill ~59 ~4 ~13 ~65 ~4 ~13 stone 6  
fill ~59 ~4 ~32 ~74 ~4 ~32 stone 6  
fill ~59 ~4 ~33 ~74 ~4 ~33 stone 6  
fill ~59 ~4 ~34 ~74 ~4 ~34 stone 6  
fill ~59 ~4 ~38 ~74 ~4 ~38 stone 6  
fill ~59 ~4 ~39 ~73 ~4 ~39 stone 6  
fill ~59 ~4 ~42 ~59 ~4 ~43 chest 4  
fill ~59 ~4 ~45 ~59 ~4 ~46 chest 4  
fill ~59 ~4 ~49 ~59 ~4 ~50 chest 4  
fill ~59 ~4 ~52 ~59 ~4 ~53 chest 4  
fill ~59 ~4 ~56 ~59 ~4 ~57 chest 4  
fill ~59 ~4 ~59 ~59 ~4 ~60 chest 4  
fill ~59 ~4 ~63 ~62 ~4 ~63 stone 6  
fill ~59 ~4 ~64 ~63 ~4 ~64 stone 6  
fill ~59 ~4 ~65 ~63 ~4 ~65 stone 6  
fill ~59 ~4 ~66 ~63 ~4 ~66 stone 6  
fill ~59 ~4 ~67 ~63 ~4 ~67 stone 6  
fill ~59 ~4 ~68 ~63 ~4 ~68 stone 6  
fill ~59 ~4 ~69 ~63 ~4 ~69 stone 6  
fill ~59 ~4 ~70 ~62 ~4 ~70 stone 6 
setblock ~60 ~4 ~8 cobblestone_wall 0  
fill ~60 ~4 ~9 ~60 ~4 ~10 stonebrick 0  
fill ~60 ~4 ~11 ~60 ~0 ~11 stone 6  
fill ~60 ~4 ~12 ~61 ~4 ~12 stone 6  
fill ~60 ~4 ~24 ~74 ~4 ~24 stone 6  
fill ~60 ~4 ~40 ~73 ~4 ~40 stone 6  
fill ~60 ~4 ~41 ~72 ~4 ~41 stone 6  
fill ~60 ~4 ~42 ~62 ~4 ~42 stone 6  
fill ~60 ~4 ~43 ~62 ~4 ~43 stone 6  
fill ~60 ~4 ~44 ~62 ~4 ~44 stone 6  
fill ~60 ~4 ~45 ~62 ~4 ~45 stone 6  
fill ~60 ~4 ~46 ~62 ~4 ~46 stone 6  
fill ~60 ~4 ~47 ~62 ~4 ~47 stone 6  
fill ~60 ~4 ~48 ~62 ~4 ~48 stone 6  
fill ~60 ~4 ~49 ~62 ~4 ~49 stone 6  
fill ~60 ~4 ~50 ~62 ~4 ~50 stone 6  
fill ~60 ~4 ~51 ~62 ~4 ~51 stone 6  
fill ~60 ~4 ~52 ~62 ~4 ~52 stone 6  
fill ~60 ~4 ~53 ~62 ~4 ~53 stone 6  
fill ~60 ~4 ~54 ~62 ~4 ~54 stone 6  
fill ~60 ~4 ~55 ~62 ~4 ~55 stone 6  
fill ~60 ~4 ~56 ~62 ~4 ~56 stone 6  
fill ~60 ~4 ~57 ~62 ~4 ~57 stone 6  
fill ~60 ~4 ~58 ~62 ~4 ~58 stone 6  
fill ~60 ~4 ~59 ~62 ~4 ~59 stone 6  
fill ~60 ~4 ~60 ~62 ~4 ~60 stone 6  
fill ~60 ~4 ~61 ~62 ~4 ~61 stone 6  
fill ~60 ~4 ~62 ~62 ~4 ~62 stone 6  
fill ~61 ~4 ~10 ~64 ~4 ~10 stone_slab 5  
fill ~61 ~4 ~11 ~64 ~4 ~11 stonebrick 0  
fill ~61 ~4 ~23 ~74 ~4 ~23 stone 6  
fill ~62 ~4 ~12 ~64 ~4 ~12 stonebrick 0  
fill ~62 ~4 ~22 ~74 ~4 ~22 stone 6  
fill ~62 ~4 ~35 ~62 ~4 ~37 stone_brick_stairs 0  
fill ~62 ~4 ~76 ~64 ~4 ~76 stone 6  
fill ~62 ~4 ~88 ~67 ~4 ~88 stone 6  
fill ~62 ~4 ~91 ~64 ~4 ~91 stone 6  
fill ~63 ~4 ~35 ~66 ~4 ~35 stonebrick 0  
fill ~63 ~4 ~36 ~66 ~4 ~36 stonebrick 0  
fill ~63 ~4 ~37 ~66 ~4 ~37 stonebrick 0  
fill ~64 ~4 ~18 ~74 ~4 ~18 stone 6  
fill ~64 ~4 ~19 ~74 ~4 ~19 stone 6  
fill ~64 ~4 ~42 ~71 ~4 ~42 stone 6  
fill ~64 ~4 ~77 ~65 ~4 ~77 stone 6  
fill ~64 ~4 ~87 ~67 ~4 ~87 stone 6 
setblock ~65 ~4 ~8 cobblestone_wall 0  
fill ~65 ~4 ~9 ~65 ~4 ~10 stonebrick 0  
fill ~65 ~4 ~11 ~65 ~4 ~14 stone 6  
fill ~65 ~4 ~20 ~74 ~4 ~20 stone 6  
fill ~65 ~4 ~21 ~74 ~4 ~21 stone 6  
fill ~65 ~4 ~78 ~66 ~4 ~78 stone 6  
fill ~65 ~4 ~79 ~66 ~4 ~79 stone 6  
fill ~65 ~4 ~85 ~67 ~4 ~85 stone 6  
fill ~65 ~4 ~86 ~67 ~4 ~86 stone 6  
fill ~66 ~4 ~43 ~69 ~4 ~43 stone 6  
fill ~66 ~4 ~80 ~67 ~4 ~80 stone 6  
fill ~66 ~4 ~81 ~67 ~4 ~81 stone 6  
fill ~66 ~4 ~82 ~67 ~4 ~82 stone 6  
fill ~66 ~4 ~83 ~67 ~4 ~83 stone 6  
fill ~66 ~4 ~84 ~67 ~4 ~84 stone 6  
fill ~67 ~4 ~35 ~74 ~4 ~35 stone 6  
fill ~67 ~4 ~36 ~74 ~4 ~36 stone 6  
fill ~67 ~4 ~37 ~74 ~4 ~37 stone 6  
fill ~2 ~5 ~17 ~24 ~5 ~17 stone 6  
fill ~2 ~5 ~18 ~28 ~5 ~18 stone 6  
fill ~2 ~5 ~19 ~33 ~5 ~19 stone 6  
fill ~2 ~5 ~20 ~74 ~5 ~20 stone 6  
fill ~2 ~5 ~21 ~57 ~5 ~21 stone 6  
fill ~2 ~5 ~22 ~24 ~5 ~22 stone 6  
fill ~2 ~5 ~23 ~17 ~5 ~23 stone 6  
fill ~2 ~5 ~24 ~19 ~5 ~24 stone 6  
fill ~2 ~5 ~25 ~21 ~5 ~25 stone 6  
fill ~2 ~5 ~26 ~33 ~5 ~26 stone 6  
fill ~2 ~5 ~27 ~34 ~5 ~27 stone 6  
fill ~2 ~5 ~28 ~35 ~5 ~28 stone 6  
fill ~2 ~5 ~29 ~35 ~5 ~29 stone 6  
fill ~2 ~5 ~30 ~37 ~5 ~30 stone 6  
fill ~2 ~5 ~31 ~74 ~5 ~31 stone 6  
fill ~2 ~5 ~32 ~18 ~5 ~32 stone 6  
fill ~2 ~5 ~33 ~18 ~5 ~33 stone 6  
fill ~2 ~5 ~34 ~10 ~5 ~34 stone 6  
fill ~2 ~5 ~35 ~10 ~5 ~35 stone 6  
fill ~2 ~5 ~36 ~10 ~5 ~36 stone 6  
fill ~2 ~5 ~37 ~10 ~5 ~37 stone 6  
fill ~2 ~5 ~38 ~18 ~5 ~38 stone 6  
fill ~2 ~5 ~39 ~18 ~5 ~39 stone 6  
fill ~3 ~5 ~40 ~18 ~5 ~40 stone 6  
fill ~3 ~5 ~41 ~18 ~5 ~41 stone 6  
fill ~5 ~5 ~42 ~12 ~5 ~42 stone 6  
fill ~7 ~5 ~43 ~10 ~5 ~43 stone 6  
fill ~11 ~5 ~9 ~11 ~5 ~10 cobblestone_wall 0  
fill ~11 ~5 ~11 ~11 ~5 ~13 stonebrick 0  
fill ~11 ~5 ~14 ~11 ~0 ~14 stone 6  
fill ~11 ~5 ~34 ~13 ~5 ~34 stone_brick_stairs 3  
fill ~12 ~5 ~13 ~14 ~5 ~13 stone_slab 5  
fill ~12 ~5 ~14 ~14 ~5 ~14 stonebrick 0  
fill ~13 ~5 ~15 ~19 ~5 ~15 stone 6  
fill ~13 ~5 ~64 ~18 ~5 ~64 stone 6  
fill ~13 ~5 ~65 ~18 ~5 ~65 stone 6  
fill ~13 ~5 ~66 ~18 ~5 ~66 stone 6  
fill ~13 ~5 ~67 ~18 ~5 ~67 stone 6  
fill ~13 ~5 ~68 ~18 ~5 ~68 stone 6  
fill ~13 ~5 ~69 ~18 ~5 ~69 stone 6  
fill ~14 ~5 ~16 ~21 ~5 ~16 stone 6  
fill ~14 ~5 ~34 ~18 ~5 ~34 stone 6  
fill ~14 ~5 ~42 ~18 ~5 ~42 stone 6  
fill ~14 ~5 ~43 ~17 ~5 ~43 stone 6  
fill ~14 ~5 ~44 ~17 ~5 ~44 stone 6  
fill ~14 ~5 ~45 ~17 ~5 ~45 stone 6  
fill ~14 ~5 ~46 ~17 ~5 ~46 stone 6  
fill ~14 ~5 ~47 ~17 ~5 ~47 stone 6  
fill ~14 ~5 ~48 ~18 ~5 ~48 stone 6  
fill ~14 ~5 ~49 ~18 ~5 ~49 stone 6  
fill ~14 ~5 ~50 ~17 ~5 ~50 stone 6  
fill ~14 ~5 ~51 ~17 ~5 ~51 stone 6  
fill ~14 ~5 ~52 ~17 ~5 ~52 stone 6  
fill ~14 ~5 ~53 ~17 ~5 ~53 stone 6  
fill ~14 ~5 ~54 ~17 ~5 ~54 stone 6  
fill ~14 ~5 ~55 ~18 ~5 ~55 stone 6  
fill ~14 ~5 ~56 ~18 ~5 ~56 stone 6  
fill ~14 ~5 ~57 ~17 ~5 ~57 stone 6  
fill ~14 ~5 ~58 ~17 ~5 ~58 stone 6  
fill ~14 ~5 ~59 ~17 ~5 ~59 stone 6  
fill ~14 ~5 ~60 ~17 ~5 ~60 stone 6  
fill ~14 ~5 ~61 ~17 ~5 ~61 stone 6  
fill ~14 ~5 ~62 ~18 ~5 ~62 stone 6  
fill ~14 ~5 ~63 ~18 ~5 ~63 stone 6  
fill ~14 ~5 ~70 ~18 ~5 ~70 stone 6 
setblock ~15 ~5 ~12 stone_slab 5 
setblock ~15 ~5 ~13 stonebrick 0  
fill ~15 ~5 ~14 ~18 ~5 ~14 stone 6  
fill ~15 ~5 ~71 ~61 ~5 ~71 stone 6  
fill ~16 ~5 ~9 ~16 ~5 ~10 cobblestone_wall 0  
fill ~16 ~5 ~11 ~16 ~5 ~12 stonebrick 0  
fill ~16 ~5 ~13 ~17 ~5 ~13 stone 6 
setblock ~18 ~5 ~43 stone_brick_stairs 7 
setblock ~18 ~5 ~47 stone_brick_stairs 6  
fill ~18 ~5 ~50 ~19 ~5 ~50 stone_brick_stairs 7 
setblock ~18 ~5 ~54 stone_brick_stairs 6  
fill ~18 ~5 ~57 ~19 ~5 ~57 stone_brick_stairs 7 
setblock ~18 ~5 ~61 stone_brick_stairs 6 
setblock ~19 ~5 ~32 stone_brick_stairs 5  
fill ~19 ~5 ~40 ~19 ~5 ~43 stone_brick_stairs 5  
fill ~19 ~5 ~47 ~19 ~5 ~49 stone_brick_stairs 5  
fill ~19 ~5 ~54 ~19 ~5 ~56 stone_brick_stairs 5  
fill ~19 ~5 ~61 ~19 ~5 ~63 stone_brick_stairs 5 
setblock ~19 ~5 ~70 stone_brick_stairs 5  
fill ~19 ~5 ~98 ~44 ~5 ~98 stone 6  
fill ~19 ~5 ~104 ~44 ~5 ~104 stone 6  
fill ~20 ~5 ~93 ~56 ~5 ~93 stone 6  
fill ~20 ~5 ~94 ~56 ~5 ~94 stone 6  
fill ~20 ~5 ~95 ~56 ~5 ~95 stone 6  
fill ~20 ~5 ~96 ~56 ~5 ~96 stone 6  
fill ~20 ~5 ~97 ~44 ~5 ~97 stone 6  
fill ~20 ~5 ~99 ~44 ~5 ~99 stone 6  
fill ~20 ~5 ~100 ~44 ~5 ~100 stone 6  
fill ~20 ~5 ~101 ~41 ~5 ~101 stone 6  
fill ~20 ~5 ~102 ~44 ~5 ~102 stone 6  
fill ~20 ~5 ~103 ~44 ~5 ~103 stone 6  
fill ~20 ~5 ~105 ~44 ~5 ~105 stone 6  
fill ~20 ~5 ~106 ~56 ~5 ~106 stone 6  
fill ~20 ~5 ~107 ~56 ~5 ~107 stone 6  
fill ~20 ~5 ~108 ~56 ~5 ~108 stone 6  
fill ~20 ~5 ~109 ~56 ~5 ~109 stone 6  
fill ~21 ~5 ~92 ~55 ~5 ~92 stone 6  
fill ~21 ~5 ~110 ~55 ~5 ~110 stone 6  
fill ~22 ~5 ~91 ~54 ~5 ~91 stone 6  
fill ~22 ~5 ~111 ~54 ~5 ~111 stone 6 
setblock ~23 ~5 ~32 stone_brick_stairs 4  
fill ~23 ~5 ~40 ~23 ~5 ~42 stone_brick_stairs 4  
fill ~23 ~5 ~46 ~25 ~5 ~46 stone_brick_stairs 6  
fill ~23 ~5 ~47 ~23 ~5 ~49 stone_brick_stairs 4  
fill ~23 ~5 ~53 ~25 ~5 ~53 stone_brick_stairs 6  
fill ~23 ~5 ~54 ~23 ~5 ~56 stone_brick_stairs 4  
fill ~23 ~5 ~60 ~25 ~5 ~60 stone_brick_stairs 6  
fill ~23 ~5 ~61 ~23 ~5 ~62 stone_brick_stairs 4 
setblock ~23 ~5 ~70 stone_brick_stairs 4  
fill ~24 ~5 ~32 ~25 ~5 ~32 stonebrick 0  
fill ~24 ~5 ~33 ~25 ~5 ~33 stone_brick_stairs 7 
setblock ~24 ~5 ~36 torch 2  
fill ~24 ~5 ~39 ~25 ~5 ~39 stone_brick_stairs 6  
fill ~24 ~5 ~40 ~25 ~5 ~40 stonebrick 0  
fill ~24 ~5 ~41 ~25 ~5 ~41 stonebrick 0  
fill ~24 ~5 ~42 ~25 ~5 ~42 stone_brick_stairs 7  
fill ~24 ~5 ~47 ~25 ~5 ~47 stonebrick 0  
fill ~24 ~5 ~48 ~25 ~5 ~48 stonebrick 0  
fill ~24 ~5 ~49 ~26 ~5 ~49 stone_brick_stairs 7  
fill ~24 ~5 ~54 ~25 ~5 ~54 stonebrick 0  
fill ~24 ~5 ~55 ~25 ~5 ~55 stonebrick 0  
fill ~24 ~5 ~56 ~26 ~5 ~56 stone_brick_stairs 7  
fill ~24 ~5 ~61 ~25 ~5 ~61 stonebrick 0  
fill ~24 ~5 ~62 ~25 ~5 ~62 stonebrick 0  
fill ~24 ~5 ~63 ~25 ~5 ~63 stone_brick_stairs 7 
setblock ~24 ~5 ~66 torch 2  
fill ~24 ~5 ~69 ~25 ~5 ~69 stone_brick_stairs 6  
fill ~24 ~5 ~70 ~25 ~5 ~70 stonebrick 0  
fill ~24 ~5 ~72 ~52 ~5 ~72 stone 6  
fill ~24 ~5 ~90 ~52 ~5 ~90 stone 6  
fill ~24 ~5 ~112 ~52 ~5 ~112 stone 6 
setblock ~25 ~5 ~35 torch 4 
setblock ~25 ~5 ~36 stone 6 
setblock ~25 ~5 ~37 torch 3 
setblock ~25 ~5 ~65 torch 4 
setblock ~25 ~5 ~66 stone 6 
setblock ~25 ~5 ~67 torch 3  
fill ~25 ~5 ~73 ~25 ~7 ~73 stone 6  
fill ~25 ~5 ~74 ~27 ~5 ~74 stone 6  
fill ~26 ~5 ~22 ~32 ~5 ~22 stone 6  
fill ~26 ~5 ~25 ~30 ~5 ~25 stone 6 
setblock ~26 ~5 ~32 stone_brick_stairs 5 
setblock ~26 ~5 ~36 torch 1  
fill ~26 ~5 ~40 ~26 ~5 ~42 stone_brick_stairs 5  
fill ~26 ~5 ~46 ~26 ~5 ~48 stone_brick_stairs 5  
fill ~26 ~5 ~53 ~26 ~5 ~55 stone_brick_stairs 5  
fill ~26 ~5 ~60 ~26 ~5 ~62 stone_brick_stairs 5 
setblock ~26 ~5 ~66 torch 1 
setblock ~26 ~5 ~70 stone_brick_stairs 5  
fill ~26 ~5 ~75 ~28 ~5 ~75 stone 6  
fill ~26 ~5 ~76 ~30 ~5 ~76 stone 6  
fill ~27 ~5 ~73 ~31 ~5 ~73 stone 6  
fill ~27 ~5 ~77 ~31 ~5 ~77 stone 6  
fill ~27 ~5 ~87 ~37 ~5 ~87 stone 6  
fill ~27 ~5 ~88 ~37 ~5 ~88 stone 6  
fill ~27 ~5 ~89 ~37 ~5 ~89 stone 6  
fill ~27 ~5 ~113 ~49 ~5 ~113 stone 6  
fill ~27 ~5 ~114 ~35 ~5 ~114 stone 6  
fill ~27 ~5 ~115 ~49 ~5 ~115 stone 6  
fill ~28 ~5 ~23 ~29 ~5 ~23 stone 6  
fill ~28 ~5 ~44 ~28 ~6 ~44 fence 0  
fill ~28 ~5 ~51 ~28 ~6 ~51 fence 0  
fill ~28 ~5 ~58 ~28 ~6 ~58 fence 0  
fill ~28 ~5 ~78 ~32 ~5 ~78 stone 6  
fill ~28 ~5 ~86 ~37 ~5 ~86 stone 6  
fill ~28 ~5 ~116 ~48 ~5 ~116 stone 6  
fill ~28 ~5 ~117 ~48 ~5 ~117 stone 6  
fill ~29 ~5 ~79 ~33 ~5 ~79 stone 6  
fill ~29 ~5 ~85 ~37 ~5 ~85 stone 6  
fill ~29 ~5 ~118 ~47 ~5 ~118 stone 6  
fill ~30 ~5 ~14 ~34 ~5 ~14 stonebrick 0  
fill ~30 ~5 ~15 ~32 ~5 ~15 stonebrick 0  
fill ~30 ~5 ~16 ~31 ~5 ~16 stonebrick 0  
fill ~30 ~5 ~17 ~31 ~5 ~17 stonebrick 0  
fill ~30 ~5 ~18 ~32 ~5 ~18 stonebrick 0 
setblock ~30 ~5 ~32 stone_brick_stairs 4 
setblock ~30 ~5 ~36 torch 2  
fill ~30 ~5 ~40 ~30 ~5 ~42 stone_brick_stairs 4  
fill ~30 ~5 ~46 ~32 ~5 ~46 stone_brick_stairs 6  
fill ~30 ~5 ~47 ~30 ~5 ~49 stone_brick_stairs 4  
fill ~30 ~5 ~53 ~32 ~5 ~53 stone_brick_stairs 6  
fill ~30 ~5 ~54 ~30 ~5 ~56 stone_brick_stairs 4  
fill ~30 ~5 ~60 ~32 ~5 ~60 stone_brick_stairs 6  
fill ~30 ~5 ~61 ~30 ~5 ~62 stone_brick_stairs 4 
setblock ~30 ~5 ~66 torch 2 
setblock ~30 ~5 ~70 stone_brick_stairs 4  
fill ~30 ~5 ~80 ~33 ~5 ~80 stone 6  
fill ~30 ~5 ~84 ~37 ~5 ~84 stone 6  
fill ~30 ~5 ~119 ~46 ~5 ~119 stone 6  
fill ~31 ~5 ~13 ~34 ~5 ~13 stonebrick 0  
fill ~31 ~5 ~32 ~32 ~5 ~32 stonebrick 0  
fill ~31 ~5 ~33 ~32 ~5 ~33 stone_brick_stairs 7 
setblock ~31 ~5 ~35 torch 4 
setblock ~31 ~5 ~36 stone 6 
setblock ~31 ~5 ~37 torch 3  
fill ~31 ~5 ~39 ~32 ~5 ~39 stone_brick_stairs 6  
fill ~31 ~5 ~40 ~32 ~5 ~40 stonebrick 0  
fill ~31 ~5 ~41 ~32 ~5 ~41 stonebrick 0  
fill ~31 ~5 ~42 ~32 ~5 ~42 stone_brick_stairs 7  
fill ~31 ~5 ~47 ~32 ~5 ~47 stonebrick 0  
fill ~31 ~5 ~48 ~32 ~5 ~48 stonebrick 0  
fill ~31 ~5 ~49 ~33 ~5 ~49 stone_brick_stairs 7  
fill ~31 ~5 ~54 ~32 ~5 ~54 stonebrick 0  
fill ~31 ~5 ~55 ~32 ~5 ~55 stonebrick 0  
fill ~31 ~5 ~56 ~33 ~5 ~56 stone_brick_stairs 7  
fill ~31 ~5 ~61 ~32 ~5 ~61 stonebrick 0  
fill ~31 ~5 ~62 ~32 ~5 ~62 stonebrick 0  
fill ~31 ~5 ~63 ~32 ~5 ~63 stone_brick_stairs 7 
setblock ~31 ~5 ~65 torch 4 
setblock ~31 ~5 ~66 stone 6 
setblock ~31 ~5 ~67 torch 3  
fill ~31 ~5 ~69 ~32 ~5 ~69 stone_brick_stairs 6  
fill ~31 ~5 ~70 ~32 ~5 ~70 stonebrick 0 
setblock ~32 ~5 ~16 stone_brick_stairs 7 
setblock ~32 ~5 ~17 stone_brick_stairs 6 
setblock ~32 ~5 ~36 torch 1 
setblock ~32 ~5 ~66 torch 1  
fill ~32 ~5 ~81 ~44 ~5 ~81 stone 6 
setblock ~33 ~5 ~15 stone_brick_stairs 5 
setblock ~33 ~5 ~32 stone_brick_stairs 5  
fill ~33 ~5 ~40 ~33 ~5 ~42 stone_brick_stairs 5  
fill ~33 ~5 ~46 ~33 ~5 ~48 stone_brick_stairs 5  
fill ~33 ~5 ~53 ~33 ~5 ~55 stone_brick_stairs 5  
fill ~33 ~5 ~60 ~33 ~5 ~62 stone_brick_stairs 5 
setblock ~33 ~5 ~70 stone_brick_stairs 5  
fill ~33 ~5 ~82 ~43 ~5 ~82 stone 6  
fill ~33 ~5 ~83 ~44 ~5 ~83 stone 6 
setblock ~34 ~5 ~19 stone_brick_stairs 5  
fill ~35 ~5 ~13 ~35 ~5 ~14 stone_brick_stairs 5  
fill ~35 ~5 ~44 ~35 ~6 ~44 fence 0  
fill ~35 ~5 ~51 ~35 ~6 ~51 fence 0  
fill ~35 ~5 ~58 ~35 ~6 ~58 fence 0  
fill ~35 ~5 ~77 ~42 ~5 ~77 stone 6  
fill ~35 ~5 ~78 ~48 ~5 ~78 stone 6  
fill ~35 ~5 ~79 ~47 ~5 ~79 stone 6  
fill ~35 ~5 ~80 ~46 ~5 ~80 stone 6  
fill ~36 ~5 ~73 ~44 ~5 ~73 stone 6  
fill ~36 ~5 ~74 ~42 ~5 ~74 stone 6  
fill ~36 ~5 ~75 ~42 ~5 ~75 stone 6  
fill ~36 ~5 ~76 ~42 ~5 ~76 stone 6  
fill ~36 ~5 ~114 ~41 ~5 ~114 crafting_table 0 
setblock ~37 ~5 ~32 stone_brick_stairs 4  
fill ~37 ~5 ~40 ~37 ~5 ~42 stone_brick_stairs 4  
fill ~37 ~5 ~46 ~39 ~5 ~46 stone_brick_stairs 6  
fill ~37 ~5 ~47 ~37 ~5 ~49 stone_brick_stairs 4  
fill ~37 ~5 ~53 ~39 ~5 ~53 stone_brick_stairs 6  
fill ~37 ~5 ~54 ~37 ~5 ~56 stone_brick_stairs 4  
fill ~37 ~5 ~60 ~39 ~5 ~60 stone_brick_stairs 6  
fill ~37 ~5 ~61 ~37 ~5 ~62 stone_brick_stairs 4  
fill ~38 ~5 ~32 ~39 ~5 ~32 stonebrick 0  
fill ~38 ~5 ~33 ~39 ~5 ~33 stone_brick_stairs 7 
setblock ~38 ~5 ~36 torch 2  
fill ~38 ~5 ~39 ~39 ~5 ~39 stone_brick_stairs 6  
fill ~38 ~5 ~40 ~39 ~5 ~40 stonebrick 0  
fill ~38 ~5 ~41 ~39 ~5 ~41 stonebrick 0  
fill ~38 ~5 ~42 ~39 ~5 ~42 stone_brick_stairs 7  
fill ~38 ~5 ~47 ~39 ~5 ~47 stonebrick 0  
fill ~38 ~5 ~48 ~39 ~5 ~48 stonebrick 0  
fill ~38 ~5 ~49 ~40 ~5 ~49 stone_brick_stairs 7  
fill ~38 ~5 ~54 ~39 ~5 ~54 stonebrick 0  
fill ~38 ~5 ~55 ~39 ~5 ~55 stonebrick 0  
fill ~38 ~5 ~56 ~40 ~5 ~56 stone_brick_stairs 7  
fill ~38 ~5 ~61 ~39 ~5 ~61 stonebrick 0  
fill ~38 ~5 ~62 ~39 ~5 ~62 stonebrick 0  
fill ~38 ~5 ~63 ~39 ~5 ~63 stone_brick_stairs 7 
setblock ~38 ~5 ~66 torch 2  
fill ~38 ~5 ~69 ~39 ~5 ~69 stone_brick_stairs 6  
fill ~38 ~5 ~70 ~40 ~5 ~70 stonebrick 0 
setblock ~38 ~5 ~84 stone_brick_stairs 5  
fill ~38 ~5 ~89 ~39 ~5 ~89 stone_brick_stairs 2 
setblock ~39 ~5 ~35 torch 4 
setblock ~39 ~5 ~36 stone 6 
setblock ~39 ~5 ~37 torch 3 
setblock ~39 ~5 ~65 torch 4 
setblock ~39 ~5 ~66 stone 6 
setblock ~39 ~5 ~67 torch 3 
setblock ~39 ~5 ~84 stone_brick_stairs 4 
setblock ~40 ~5 ~32 stone_brick_stairs 5 
setblock ~40 ~5 ~36 torch 1  
fill ~40 ~5 ~40 ~40 ~5 ~42 stone_brick_stairs 5  
fill ~40 ~5 ~46 ~40 ~5 ~48 stone_brick_stairs 5  
fill ~40 ~5 ~53 ~40 ~5 ~55 stone_brick_stairs 5  
fill ~40 ~5 ~60 ~40 ~5 ~62 stone_brick_stairs 5 
setblock ~40 ~5 ~66 torch 1  
fill ~40 ~5 ~84 ~46 ~5 ~84 stone 6  
fill ~40 ~5 ~85 ~47 ~5 ~85 stone 6  
fill ~40 ~5 ~86 ~49 ~5 ~86 stone 6  
fill ~40 ~5 ~87 ~49 ~5 ~87 stone 6  
fill ~40 ~5 ~88 ~49 ~5 ~88 stone 6  
fill ~40 ~5 ~89 ~49 ~5 ~89 stone 6  
fill ~41 ~5 ~13 ~41 ~5 ~14 stone_brick_stairs 4  
fill ~41 ~5 ~27 ~74 ~5 ~27 stone 6  
fill ~41 ~5 ~28 ~74 ~5 ~28 stone 6  
fill ~41 ~5 ~29 ~74 ~5 ~29 stone 6  
fill ~41 ~5 ~30 ~74 ~5 ~30 stone 6  
fill ~42 ~5 ~13 ~45 ~5 ~13 stonebrick 0  
fill ~42 ~5 ~14 ~46 ~5 ~14 stonebrick 0 
setblock ~42 ~5 ~19 stone_brick_stairs 4  
fill ~42 ~5 ~25 ~74 ~5 ~25 stone 6  
fill ~42 ~5 ~26 ~74 ~5 ~26 stone 6  
fill ~42 ~5 ~44 ~42 ~6 ~44 fence 0  
fill ~42 ~5 ~51 ~42 ~6 ~51 fence 0  
fill ~42 ~5 ~58 ~42 ~6 ~58 fence 0 
setblock ~42 ~5 ~101 iron_trapdoor 8  
fill ~42 ~5 ~114 ~49 ~5 ~114 stone 6 
setblock ~43 ~5 ~15 stone_brick_stairs 4  
fill ~43 ~5 ~19 ~74 ~5 ~19 stone 6  
fill ~43 ~5 ~101 ~45 ~5 ~101 stone_brick_stairs 2  
fill ~44 ~5 ~15 ~46 ~5 ~15 stonebrick 0 
setblock ~44 ~5 ~16 stone_brick_stairs 7 
setblock ~44 ~5 ~17 stone_brick_stairs 6  
fill ~44 ~5 ~18 ~46 ~5 ~18 stonebrick 0 
setblock ~44 ~5 ~32 stone_brick_stairs 4 
setblock ~44 ~5 ~36 torch 2  
fill ~44 ~5 ~40 ~44 ~5 ~42 stone_brick_stairs 4  
fill ~44 ~5 ~46 ~46 ~5 ~46 stone_brick_stairs 6  
fill ~44 ~5 ~47 ~44 ~5 ~49 stone_brick_stairs 4  
fill ~44 ~5 ~53 ~46 ~5 ~53 stone_brick_stairs 6  
fill ~44 ~5 ~54 ~44 ~5 ~56 stone_brick_stairs 4  
fill ~44 ~5 ~60 ~46 ~5 ~60 stone_brick_stairs 6  
fill ~44 ~5 ~61 ~44 ~5 ~62 stone_brick_stairs 4 
setblock ~44 ~5 ~66 torch 2 
setblock ~44 ~5 ~70 stone_brick_stairs 4  
fill ~44 ~5 ~77 ~49 ~5 ~77 stone 6  
fill ~45 ~5 ~16 ~46 ~5 ~16 stonebrick 0  
fill ~45 ~5 ~17 ~46 ~5 ~17 stonebrick 0  
fill ~45 ~5 ~32 ~46 ~5 ~32 stonebrick 0  
fill ~45 ~5 ~33 ~46 ~5 ~33 stone_brick_stairs 7 
setblock ~45 ~5 ~35 torch 4 
setblock ~45 ~5 ~36 stone 6 
setblock ~45 ~5 ~37 torch 3  
fill ~45 ~5 ~39 ~46 ~5 ~39 stone_brick_stairs 6  
fill ~45 ~5 ~40 ~46 ~5 ~40 stonebrick 0  
fill ~45 ~5 ~41 ~46 ~5 ~41 stonebrick 0  
fill ~45 ~5 ~42 ~46 ~5 ~42 stone_brick_stairs 7  
fill ~45 ~5 ~47 ~46 ~5 ~47 stonebrick 0  
fill ~45 ~5 ~48 ~46 ~5 ~48 stonebrick 0  
fill ~45 ~5 ~49 ~47 ~5 ~49 stone_brick_stairs 7  
fill ~45 ~5 ~54 ~46 ~5 ~54 stonebrick 0  
fill ~45 ~5 ~55 ~46 ~5 ~55 stonebrick 0  
fill ~45 ~5 ~56 ~47 ~5 ~56 stone_brick_stairs 7  
fill ~45 ~5 ~61 ~46 ~5 ~61 stonebrick 0  
fill ~45 ~5 ~62 ~46 ~5 ~62 stonebrick 0  
fill ~45 ~5 ~63 ~46 ~5 ~63 stone_brick_stairs 7 
setblock ~45 ~5 ~65 torch 4 
setblock ~45 ~5 ~66 stone 6 
setblock ~45 ~5 ~67 torch 3  
fill ~45 ~5 ~69 ~46 ~5 ~69 stone_brick_stairs 6  
fill ~45 ~5 ~70 ~46 ~5 ~70 stonebrick 0  
fill ~45 ~5 ~76 ~50 ~5 ~76 stone 6  
fill ~45 ~5 ~97 ~47 ~5 ~97 stone_brick_stairs 3  
fill ~45 ~5 ~98 ~45 ~5 ~100 stone_brick_stairs 1  
fill ~45 ~5 ~102 ~45 ~5 ~104 stone_brick_stairs 1  
fill ~45 ~5 ~105 ~47 ~5 ~105 stone_brick_stairs 2  
fill ~46 ~5 ~22 ~49 ~5 ~22 stone 6 
setblock ~46 ~5 ~36 torch 1 
setblock ~46 ~5 ~66 torch 1  
fill ~46 ~5 ~75 ~50 ~5 ~75 stone 6  
fill ~46 ~5 ~98 ~51 ~5 ~98 stone 6  
fill ~46 ~5 ~99 ~47 ~5 ~99 stone_brick_stairs 2  
fill ~46 ~5 ~100 ~47 ~5 ~100 stone_brick_stairs 3  
fill ~46 ~5 ~101 ~51 ~5 ~101 stone 6  
fill ~46 ~5 ~102 ~47 ~5 ~102 stone_brick_stairs 2  
fill ~46 ~5 ~103 ~47 ~5 ~103 stone_brick_stairs 3  
fill ~46 ~5 ~104 ~57 ~5 ~104 stone 6 
setblock ~47 ~5 ~32 stone_brick_stairs 5  
fill ~47 ~5 ~40 ~47 ~5 ~42 stone_brick_stairs 5  
fill ~47 ~5 ~46 ~47 ~5 ~48 stone_brick_stairs 5  
fill ~47 ~5 ~53 ~47 ~5 ~55 stone_brick_stairs 5  
fill ~47 ~5 ~60 ~47 ~5 ~62 stone_brick_stairs 5 
setblock ~47 ~5 ~70 stone_brick_stairs 5  
fill ~48 ~5 ~18 ~74 ~5 ~18 stone 6  
fill ~48 ~5 ~74 ~51 ~5 ~74 stone 6  
fill ~48 ~5 ~97 ~56 ~5 ~97 stone 6  
fill ~48 ~5 ~99 ~51 ~5 ~99 stone 6  
fill ~48 ~5 ~100 ~51 ~5 ~100 stone 6  
fill ~48 ~5 ~102 ~51 ~5 ~102 stone 6  
fill ~48 ~5 ~103 ~51 ~5 ~103 stone 6  
fill ~48 ~5 ~105 ~56 ~5 ~105 stone 6  
fill ~49 ~5 ~44 ~49 ~6 ~44 fence 0  
fill ~49 ~5 ~51 ~49 ~6 ~51 fence 0  
fill ~49 ~5 ~58 ~49 ~6 ~58 fence 0  
fill ~49 ~5 ~73 ~51 ~5 ~73 stone 6 
setblock ~51 ~5 ~32 stone_brick_stairs 4  
fill ~51 ~5 ~40 ~51 ~5 ~42 stone_brick_stairs 4  
fill ~51 ~5 ~46 ~53 ~5 ~46 stone_brick_stairs 6  
fill ~51 ~5 ~47 ~51 ~5 ~49 stone_brick_stairs 4  
fill ~51 ~5 ~53 ~53 ~5 ~53 stone_brick_stairs 6  
fill ~51 ~5 ~54 ~51 ~5 ~56 stone_brick_stairs 4  
fill ~51 ~5 ~60 ~53 ~5 ~60 stone_brick_stairs 6  
fill ~51 ~5 ~61 ~51 ~5 ~62 stone_brick_stairs 4 
setblock ~51 ~5 ~70 stone_brick_stairs 4  
fill ~51 ~5 ~80 ~52 ~5 ~80 stone 6  
fill ~51 ~5 ~81 ~52 ~5 ~81 stone 6  
fill ~51 ~5 ~82 ~52 ~5 ~82 stone 6  
fill ~51 ~5 ~83 ~52 ~5 ~83 stone 6  
fill ~51 ~5 ~84 ~52 ~5 ~84 stone 6  
fill ~52 ~5 ~17 ~74 ~5 ~17 stone 6  
fill ~52 ~5 ~22 ~57 ~5 ~22 stone 6  
fill ~52 ~5 ~32 ~53 ~5 ~32 stonebrick 0  
fill ~52 ~5 ~33 ~53 ~5 ~33 stone_brick_stairs 7 
setblock ~52 ~5 ~36 torch 2  
fill ~52 ~5 ~39 ~53 ~5 ~39 stone_brick_stairs 6  
fill ~52 ~5 ~40 ~53 ~5 ~40 stonebrick 0  
fill ~52 ~5 ~41 ~53 ~5 ~41 stonebrick 0  
fill ~52 ~5 ~42 ~53 ~5 ~42 stone_brick_stairs 7  
fill ~52 ~5 ~47 ~53 ~5 ~47 stonebrick 0  
fill ~52 ~5 ~48 ~53 ~5 ~48 stonebrick 0  
fill ~52 ~5 ~49 ~54 ~5 ~49 stone_brick_stairs 7  
fill ~52 ~5 ~54 ~53 ~5 ~54 stonebrick 0  
fill ~52 ~5 ~55 ~53 ~5 ~55 stonebrick 0  
fill ~52 ~5 ~56 ~54 ~5 ~56 stone_brick_stairs 7  
fill ~52 ~5 ~61 ~53 ~5 ~61 stonebrick 0  
fill ~52 ~5 ~62 ~53 ~5 ~62 stonebrick 0  
fill ~52 ~5 ~63 ~53 ~5 ~63 stone_brick_stairs 7 
setblock ~52 ~5 ~66 torch 2  
fill ~52 ~5 ~69 ~53 ~5 ~69 stone_brick_stairs 6  
fill ~52 ~5 ~70 ~53 ~5 ~70 stonebrick 0  
fill ~52 ~5 ~78 ~53 ~5 ~78 stone 6  
fill ~52 ~5 ~79 ~53 ~5 ~79 stone 6  
fill ~52 ~5 ~85 ~53 ~5 ~85 stone 6  
fill ~52 ~5 ~86 ~53 ~5 ~86 stone 6  
fill ~52 ~5 ~98 ~52 ~5 ~103 netherrack 0 
setblock ~53 ~5 ~35 torch 4 
setblock ~53 ~5 ~36 stone 6 
setblock ~53 ~5 ~37 torch 3 
setblock ~53 ~5 ~65 torch 4 
setblock ~53 ~5 ~66 stone 6 
setblock ~53 ~5 ~67 torch 3  
fill ~53 ~5 ~77 ~54 ~5 ~77 stone 6  
fill ~53 ~5 ~87 ~54 ~5 ~87 stone 6  
fill ~53 ~5 ~98 ~57 ~5 ~98 stone 6  
