fill ~16~0~4 ~17~0~4 minecraft:podzol
setblock ~25~0~4 minecraft:leaves 3
setblock ~24~0~5 minecraft:log 3
setblock ~25~0~5 minecraft:log 3
fill ~25~1~5 ~25~1~7 minecraft:leaves 3
setblock ~26~0~5 minecraft:leaves 3
fill ~23~0~6 ~23~0~8 minecraft:podzol
setblock ~24~0~6 minecraft:log 3
fill ~24~1~6 ~24~1~7 minecraft:leaves 3
fill ~25~0~6 ~26~0~6 minecraft:log 3
setblock ~25~2~6 minecraft:leaves 3
fill ~27~0~6 ~33~0~6 minecraft:log 3
fill ~21~0~7 ~22~0~8 minecraft:podzol
setblock ~21~1~7 minecraft:red_flower 7
setblock ~22~1~7 minecraft:red_flower 8
setblock ~23~1~7 minecraft:red_flower 2
setblock ~24~0~7 minecraft:log 3
setblock ~25~0~7 minecraft:log 3
setblock ~26~0~7 minecraft:log 3
setblock ~32~1~7 minecraft:waterlily
fill ~12~11~8 ~14~11~8 minecraft:wooden_slab 13
fill ~15~27~8 ~20~27~8 minecraft:wool 12
setblock ~18~0~8 minecraft:leaves 3
setblock ~19~0~8 minecraft:log 3
setblock ~20~0~8 minecraft:log 3
setblock ~21~1~8 minecraft:red_flower 4
setblock ~22~1~8 minecraft:carpet 6
setblock ~23~1~8 minecraft:red_flower 7
setblock ~24~0~8 minecraft:podzol
setblock ~24~1~8 minecraft:red_flower 4
setblock ~25~0~8 minecraft:log 3
setblock ~25~1~8 minecraft:leaves 3
setblock ~35~1~8 minecraft:waterlily
fill ~10~11~9 ~11~11~9 minecraft:wooden_slab 13
setblock ~10~12~9 minecraft:flower_pot 0
fill ~12~11~9 ~14~11~12 minecraft:double_wooden_slab 5
fill ~12~12~9 ~14~12~9 minecraft:wooden_slab 2
fill ~12~14~9 ~14~14~9 minecraft:stone_block_slab 1
setblock ~14~1~9 minecraft:waterlily
setblock ~14~27~9 minecraft:wool 12
fill ~15~11~9 ~16~11~9 minecraft:wooden_slab 13
fill ~15~26~9 ~20~26~9 minecraft:wool 12
fill ~15~27~9 ~20~27~9 minecraft:stained_hardened_clay 0
fill ~15~28~9 ~16~29~9 minecraft:stained_hardened_clay 0
fill ~16~30~9 ~19~30~9 minecraft:stained_hardened_clay 0
setblock ~17~0~9 minecraft:leaves 3
fill ~17~28~9 ~18~29~9 minecraft:stained_glass_pane 0
fill ~17~31~9 ~18~31~9 minecraft:stained_hardened_clay 0
fill ~18~0~9 ~19~0~9 minecraft:log 3
fill ~18~1~9 ~19~1~9 minecraft:leaves 3
fill ~19~28~9 ~20~29~9 minecraft:stained_hardened_clay 0
fill ~20~0~9 ~21~0~9 minecraft:podzol
setblock ~20~1~9 minecraft:red_flower 7
setblock ~21~1~9 minecraft:red_flower 3
setblock ~21~27~9 minecraft:wool 12
fill ~22~0~9 ~22~0~11 minecraft:dirt 1
setblock ~23~0~9 minecraft:log 3
setblock ~24~0~9 minecraft:dirt 1
setblock ~24~1~9 minecraft:red_flower 1
setblock ~25~25~9 minecraft:stained_glass_pane 0
fill ~25~26~9 ~25~27~9 minecraft:sea_lantern
setblock ~25~28~9 minecraft:trapdoor 3
fill ~26~31~9 ~26~31~10 minecraft:trapdoor 3
setblock ~31~1~9 minecraft:waterlily
setblock ~6~23~10 minecraft:wooden_slab 3
fill ~7~23~10 ~7~23~12 minecraft:wooden_slab 11
fill ~8~24~10 ~9~24~10 minecraft:wooden_slab 3
setblock ~9~11~10 minecraft:wooden_slab 13
fill ~10~11~10 ~11~11~13 minecraft:double_wooden_slab 5
setblock ~10~12~10 minecraft:wooden_slab 2
fill ~10~14~10 ~11~14~10 minecraft:stone_block_slab 1
setblock ~11~15~10 minecraft:trip_wire 0
fill ~11~18~10 ~11~23~10 minecraft:vine 1
fill ~12~14~10 ~13~14~10 minecraft:wool 2
setblock ~13~12~10 minecraft:anvil 1
setblock ~13~13~10 minecraft:fence 2
setblock ~13~19~10 minecraft:trip_wire 0
fill ~13~20~10 ~13~23~10 minecraft:vine 1
fill ~13~27~10 ~13~27~15 minecraft:wool 12
fill ~14~12~10 ~14~12~11 minecraft:bookshelf
setblock ~14~14~10 minecraft:wool 10
setblock ~14~21~10 minecraft:trip_wire 0
fill ~14~22~10 ~14~24~10 minecraft:vine 9
setblock ~14~25~10 minecraft:vine 8
fill ~14~26~10 ~14~26~15 minecraft:wool 12
fill ~14~27~10 ~15~27~10 minecraft:stained_hardened_clay 0
fill ~14~28~10 ~14~29~15 minecraft:stained_hardened_clay 0
fill ~15~11~10 ~16~11~14 minecraft:double_wooden_slab 5
fill ~15~14~10 ~16~14~10 minecraft:stone_block_slab 1
fill ~15~25~10 ~16~25~11 minecraft:wool 12
fill ~15~26~10 ~20~26~10 minecraft:stained_hardened_clay 0
setblock ~15~30~10 minecraft:stained_hardened_clay 0
fill ~16~0~10 ~16~0~11 minecraft:leaves 3
setblock ~16~12~10 minecraft:wooden_slab 2
setblock ~16~15~10 minecraft:trip_wire 0
fill ~16~31~10 ~16~32~10 minecraft:stained_hardened_clay 0
setblock ~17~0~10 minecraft:log 3
fill ~17~1~10 ~18~1~10 minecraft:leaves 3
setblock ~17~11~10 minecraft:wooden_slab 13
fill ~17~25~10 ~18~25~10 minecraft:log 3
setblock ~17~27~10 minecraft:birch_stairs 3
fill ~17~32~10 ~19~32~10 minecraft:stained_hardened_clay 0
fill ~17~33~10 ~18~33~10 minecraft:stained_hardened_clay 0
setblock ~18~0~10 minecraft:log 3
setblock ~18~2~10 minecraft:leaves 3
setblock ~18~27~10 minecraft:jungle_stairs 3
setblock ~18~39~10 minecraft:trip_wire 0
fill ~18~40~10 ~18~45~10 minecraft:vine 1
setblock ~19~0~10 minecraft:log 3
setblock ~19~1~10 minecraft:leaves 3
fill ~19~25~10 ~20~25~10 minecraft:wool 12
setblock ~19~31~10 minecraft:stained_hardened_clay 0
fill ~19~43~10 ~19~45~10 minecraft:leaves2 1
setblock ~20~0~10 minecraft:podzol
fill ~20~27~10 ~21~27~10 minecraft:stained_hardened_clay 0
setblock ~20~30~10 minecraft:stained_hardened_clay 0
setblock ~21~0~10 minecraft:dirt 1
fill ~21~26~10 ~21~26~15 minecraft:wool 12
fill ~21~28~10 ~21~29~12 minecraft:stained_hardened_clay 0
fill ~22~27~10 ~22~27~12 minecraft:wool 12
fill ~23~0~10 ~23~0~11 minecraft:dirt 1
setblock ~24~0~10 minecraft:log 3
setblock ~25~0~10 minecraft:log 3
setblock ~25~31~10 minecraft:trapdoor 1
setblock ~26~27~10 minecraft:fence 1
setblock ~26~28~10 minecraft:sea_lantern
setblock ~26~29~10 minecraft:fence 1
setblock ~26~30~10 minecraft:spruce_stairs 6
setblock ~27~31~10 minecraft:trapdoor 1
fill ~5~23~11 ~5~23~12 minecraft:wooden_slab 3
setblock ~6~23~11 minecraft:double_wooden_slab 3
fill ~7~24~11 ~8~24~11 minecraft:wooden_slab 3
fill ~8~11~11 ~8~11~12 minecraft:wooden_slab 13
fill ~9~11~11 ~9~11~17 minecraft:double_wooden_slab 5
setblock ~9~12~11 minecraft:wooden_slab 2
fill ~9~14~11 ~9~14~12 minecraft:stone_block_slab 1
fill ~9~24~11 ~10~24~11 minecraft:wooden_slab 11
setblock ~10~12~11 minecraft:anvil 2
setblock ~10~13~11 minecraft:fence 2
fill ~10~14~11 ~10~14~12 minecraft:wool 10
fill ~10~15~11 ~10~19~11 minecraft:vine 1
fill ~10~20~11 ~10~23~11 minecraft:vine 9
setblock ~11~14~11 minecraft:wool 6
setblock ~11~23~11 minecraft:leaves 3
setblock ~12~12~11 minecraft:carpet 2
setblock ~12~15~11 minecraft:wool 10
fill ~12~22~11 ~12~22~12 minecraft:leaves 3
fill ~12~27~11 ~12~27~14 minecraft:wool 12
fill ~13~10~11 ~13~10~12 minecraft:log 3
setblock ~13~12~11 minecraft:bookshelf
setblock ~13~15~11 minecraft:wool 2
setblock ~13~23~11 minecraft:leaves 3
fill ~13~24~11 ~13~25~11 minecraft:vine 9
fill ~13~26~11 ~13~26~14 minecraft:wool 12
fill ~13~28~11 ~13~28~14 minecraft:stained_hardened_clay 0
setblock ~14~13~11 minecraft:bookshelf
setblock ~14~15~11 minecraft:wool 9
setblock ~14~23~11 minecraft:log 3
fill ~14~24~11 ~14~24~12 minecraft:leaves 3
fill ~14~25~11 ~14~25~14 minecraft:wool 12
fill ~14~27~11 ~14~27~15 minecraft:stained_hardened_clay 0
fill ~14~30~11 ~14~30~14 minecraft:stained_hardened_clay 0
setblock ~15~14~11 minecraft:wool 6
fill ~15~26~11 ~16~26~11 minecraft:stained_hardened_clay 0
setblock ~15~27~11 minecraft:birch_stairs 7
setblock ~15~28~11 minecraft:carpet 0
fill ~15~31~11 ~15~32~11 minecraft:stained_hardened_clay 0
setblock ~16~12~11 minecraft:anvil 3
setblock ~16~13~11 minecraft:fence 2
setblock ~16~14~11 minecraft:wool 10
setblock ~16~24~11 minecraft:log 3
setblock ~16~33~11 minecraft:stained_hardened_clay 0
setblock ~17~0~11 minecraft:leaves 3
fill ~17~11~11 ~17~11~17 minecraft:double_wooden_slab 5
setblock ~17~12~11 minecraft:wooden_slab 2
fill ~17~14~11 ~17~14~12 minecraft:stone_block_slab 1
fill ~17~24~11 ~17~24~17 minecraft:log 3
setblock ~17~25~11 minecraft:log 3
fill ~17~26~11 ~18~26~11 minecraft:quartz_block 0
fill ~17~33~11 ~18~33~11 minecraft:trapdoor 3
fill ~17~34~11 ~18~34~14 minecraft:stained_hardened_clay 0
setblock ~17~40~11 minecraft:trip_wire 0
fill ~17~41~11 ~17~45~11 minecraft:vine 8
setblock ~18~0~11 minecraft:log 3
setblock ~18~1~11 minecraft:leaves 3
fill ~18~11~11 ~18~11~12 minecraft:wooden_slab 13
setblock ~18~25~11 minecraft:log 3
setblock ~18~43~11 minecraft:leaves2 1
fill ~18~44~11 ~19~45~11 minecraft:leaves 3
fill ~18~48~11 ~18~48~19 minecraft:leaves 3
setblock ~19~0~11 minecraft:log 3
fill ~19~25~11 ~19~25~12 minecraft:podzol
fill ~19~26~11 ~20~26~11 minecraft:stained_hardened_clay 0
setblock ~19~33~11 minecraft:stained_hardened_clay 0
fill ~19~42~11 ~20~42~11 minecraft:leaves2 1
fill ~19~43~11 ~19~43~12 minecraft:leaves 3
fill ~19~46~11 ~20~46~11 minecraft:leaves 3
setblock ~19~47~11 minecraft:leaves2 1
fill ~20~25~11 ~21~25~14 minecraft:wool 12
setblock ~20~27~11 minecraft:birch_stairs 7
setblock ~20~28~11 minecraft:flower_pot 0
fill ~20~31~11 ~20~32~11 minecraft:stained_hardened_clay 0
fill ~20~43~11 ~20~43~12 minecraft:leaves2 1
setblock ~20~45~11 minecraft:leaves 3
setblock ~21~0~11 minecraft:podzol
fill ~21~27~11 ~21~27~12 minecraft:stained_hardened_clay 0
fill ~21~30~11 ~21~30~14 minecraft:stained_hardened_clay 0
fill ~22~26~11 ~22~26~14 minecraft:wool 12
fill ~22~28~11 ~22~28~14 minecraft:stained_hardened_clay 0
setblock ~23~1~11 minecraft:leaves 3
setblock ~24~0~11 minecraft:dirt 1
setblock ~26~31~11 minecraft:trapdoor 3
setblock ~26~32~11 minecraft:wooden_slab 1
setblock ~34~1~11 minecraft:waterlily
fill ~4~22~12 ~5~22~12 minecraft:wooden_slab 11
setblock ~6~0~12 minecraft:log 3
setblock ~6~17~12 minecraft:trip_wire 0
fill ~6~18~12 ~6~21~12 minecraft:vine 1
setblock ~6~23~12 minecraft:wooden_slab 3
setblock ~7~24~12 minecraft:wooden_slab 3
setblock ~8~12~12 minecraft:flower_pot 0
fill ~8~24~12 ~9~24~12 minecraft:wooden_slab 11
fill ~9~23~12 ~9~23~14 minecraft:leaves 3
fill ~9~25~12 ~11~25~12 minecraft:wooden_slab 3
fill ~10~12~12 ~10~12~13 minecraft:bookshelf
fill ~10~22~12 ~11~22~12 minecraft:leaves 3
fill ~10~23~12 ~15~23~12 minecraft:log 3
setblock ~10~24~12 minecraft:log 3
fill ~11~10~12 ~11~10~13 minecraft:wooden_slab 13
setblock ~11~12~12 minecraft:carpet 10
setblock ~11~15~12 minecraft:wool 9
setblock ~11~24~12 minecraft:wooden_slab 11
setblock ~12~10~12 minecraft:log 3
fill ~12~12~12 ~12~12~13 minecraft:carpet 9
setblock ~12~15~12 minecraft:wool 2
setblock ~12~16~12 minecraft:stone_block_slab 1
setblock ~12~24~12 minecraft:log 3
setblock ~12~25~12 minecraft:vine 8
setblock ~13~9~12 minecraft:log 3
setblock ~13~12~12 minecraft:carpet 2
setblock ~13~16~12 minecraft:wool 6
setblock ~13~22~12 minecraft:leaves 3
setblock ~13~24~12 minecraft:log 3
setblock ~13~25~12 minecraft:leaves 3
fill ~13~29~12 ~13~29~13 minecraft:stained_hardened_clay 0
fill ~14~10~12 ~14~10~14 minecraft:log 3
setblock ~14~13~12 minecraft:redstone_torch 3
setblock ~14~15~12 minecraft:wool 6
fill ~14~31~12 ~14~31~13 minecraft:stained_hardened_clay 0
fill ~15~10~12 ~15~10~13 minecraft:wooden_slab 13
setblock ~15~15~12 minecraft:wool 2
fill ~15~24~12 ~15~24~15 minecraft:leaves 3
setblock ~15~25~12 minecraft:log 3
fill ~15~26~12 ~15~26~15 minecraft:stained_hardened_clay 0
setblock ~15~27~12 minecraft:wooden_slab 10
fill ~15~28~12 ~15~28~13 minecraft:carpet 6
fill ~15~29~12 ~15~29~13 minecraft:wooden_slab 10
fill ~15~32~12 ~15~32~14 minecraft:stained_hardened_clay 0
fill ~15~33~12 ~15~33~13 minecraft:stained_hardened_clay 0
setblock ~16~12~12 minecraft:flower_pot 0
setblock ~16~14~12 minecraft:wool 2
fill ~16~23~12 ~16~24~12 minecraft:log 3
setblock ~16~25~12 minecraft:log 3
fill ~16~26~12 ~16~26~13 minecraft:quartz_block 0
fill ~16~33~12 ~16~33~13 minecraft:trapdoor 1
fill ~16~34~12 ~16~34~13 minecraft:stained_hardened_clay 0
setblock ~17~23~12 minecraft:leaves 3
setblock ~17~25~12 minecraft:log 3
setblock ~17~26~12 minecraft:stained_hardened_clay 0
fill ~17~33~12 ~18~33~13 minecraft:glowstone
fill ~17~35~12 ~18~35~13 minecraft:stained_hardened_clay 0
fill ~17~48~12 ~17~48~14 minecraft:leaves 3
setblock ~18~25~12 minecraft:podzol
fill ~18~26~12 ~19~26~12 minecraft:quartz_block 0
setblock ~18~44~12 minecraft:leaves2 1
fill ~18~45~12 ~19~45~13 minecraft:leaves 3
fill ~18~46~12 ~20~46~12 minecraft:leaves2 1
fill ~18~47~12 ~18~47~13 minecraft:leaves2 1
fill ~18~49~12 ~18~49~13 minecraft:leaves 3
fill ~19~33~12 ~19~33~13 minecraft:trapdoor 1
fill ~19~34~12 ~19~34~13 minecraft:stained_hardened_clay 0
fill ~19~44~12 ~20~44~12 minecraft:leaves 3
fill ~19~47~12 ~20~48~12 minecraft:leaves 3
fill ~20~26~12 ~20~26~15 minecraft:stained_hardened_clay 0
setblock ~20~27~12 minecraft:wooden_slab 11
fill ~20~32~12 ~20~32~14 minecraft:stained_hardened_clay 0
fill ~20~33~12 ~20~33~13 minecraft:stained_hardened_clay 0
fill ~20~45~12 ~20~45~13 minecraft:leaves2 1
fill ~21~0~12 ~23~0~12 minecraft:log 3
fill ~21~31~12 ~21~31~13 minecraft:stained_hardened_clay 0
setblock ~21~48~12 minecraft:leaves2 1
setblock ~22~1~12 minecraft:log 3
fill ~22~29~12 ~22~29~13 minecraft:stained_hardened_clay 0
setblock ~23~1~12 minecraft:dirt 1
fill ~23~2~12 ~23~2~13 minecraft:leaves 3
fill ~23~27~12 ~23~27~14 minecraft:wool 12
fill ~24~0~12 ~24~0~13 minecraft:log 3
setblock ~24~1~12 minecraft:leaves 3
setblock ~25~0~12 minecraft:log 3
setblock ~25~31~12 minecraft:spruce_stairs 6
setblock ~26~0~12 minecraft:dirt 1
setblock ~26~31~12 minecraft:fence 1
setblock ~26~32~12 minecraft:trapdoor 3
setblock ~27~0~12 minecraft:log 3
setblock ~27~31~12 minecraft:spruce_stairs 6
setblock ~29~0~12 minecraft:log 3
setblock ~4~22~13 minecraft:wooden_slab 3
setblock ~5~10~13 minecraft:trip_wire 0
setblock ~5~22~13 minecraft:double_wooden_slab 3
fill ~6~21~13 ~7~21~13 minecraft:leaves 3
setblock ~6~22~13 minecraft:wooden_slab 11
fill ~7~11~13 ~7~11~15 minecraft:wooden_slab 13
fill ~7~22~13 ~7~23~13 minecraft:leaves 3
fill ~8~9~13 ~8~10~13 minecraft:trip_wire 0
fill ~8~11~13 ~8~11~15 minecraft:double_wooden_slab 5
fill ~8~12~13 ~8~12~15 minecraft:wooden_slab 2
fill ~8~14~13 ~8~14~15 minecraft:stone_block_slab 1
setblock ~8~18~13 minecraft:trip_wire 0
fill ~8~19~13 ~8~21~13 minecraft:vine 3
setblock ~8~22~13 minecraft:vine 2
fill ~8~23~13 ~8~23~14 minecraft:leaves 3
fill ~8~24~13 ~12~24~13 minecraft:leaves 3
fill ~8~25~13 ~9~25~13 minecraft:wooden_slab 3
setblock ~9~14~13 minecraft:wool 9
setblock ~9~21~13 minecraft:leaves 3
setblock ~10~10~13 minecraft:wooden_slab 13
setblock ~10~13~13 minecraft:bookshelf
setblock ~10~15~13 minecraft:wool 2
fill ~10~22~13 ~10~23~13 minecraft:leaves 3
fill ~10~25~13 ~12~25~13 minecraft:wooden_slab 11
setblock ~11~15~13 minecraft:wool 10
fill ~11~23~13 ~11~23~14 minecraft:log 3
setblock ~12~0~13 minecraft:log 3
setblock ~12~9~13 minecraft:log 3
setblock ~12~10~13 minecraft:log 3
setblock ~12~11~13 minecraft:double_wooden_slab 5
setblock ~12~16~13 minecraft:wool 10
setblock ~12~17~13 minecraft:wool 9
setblock ~13~0~13 minecraft:log 3
fill ~13~9~13 ~13~11~13 minecraft:log 3
setblock ~13~12~13 minecraft:carpet 10
setblock ~13~17~13 minecraft:wool 10
setblock ~13~18~13 minecraft:wool 6
fill ~13~47~13 ~13~48~15 minecraft:leaves 3
setblock ~14~9~13 minecraft:log 3
setblock ~14~11~13 minecraft:double_wooden_slab 5
setblock ~14~12~13 minecraft:carpet 9
fill ~14~16~13 ~14~17~13 minecraft:wool 2
setblock ~14~18~13 minecraft:stone_block_slab 1
setblock ~14~24~13 minecraft:shulker_box 14
fill ~14~48~13 ~14~48~19 minecraft:leaves 3
setblock ~15~12~13 minecraft:birch_stairs 0
setblock ~15~15~13 minecraft:wool 9
setblock ~15~16~13 minecraft:stone_block_slab 1
setblock ~15~23~13 minecraft:leaves 3
setblock ~15~25~13 minecraft:wool 12
setblock ~15~27~13 minecraft:birch_stairs 6
setblock ~16~0~13 minecraft:log 3
fill ~16~15~13 ~16~15~14 minecraft:wool 10
fill ~16~23~13 ~17~23~13 minecraft:log 3
fill ~16~24~13 ~16~24~17 minecraft:log 3
fill ~16~25~13 ~16~25~14 minecraft:podzol
fill ~16~48~13 ~16~48~14 minecraft:leaves 3
fill ~17~14~13 ~17~14~14 minecraft:wool 10
fill ~17~22~13 ~17~22~17 minecraft:leaves 3
fill ~17~25~13 ~17~25~16 minecraft:log 3
fill ~17~26~13 ~17~26~14 minecraft:quartz_block 0
setblock ~17~46~13 minecraft:leaves2 1
setblock ~17~47~13 minecraft:leaves 3
fill ~17~49~13 ~17~49~14 minecraft:leaves2 1
fill ~18~11~13 ~18~11~15 minecraft:double_wooden_slab 5
fill ~18~12~13 ~18~12~15 minecraft:wooden_slab 2
fill ~18~14~13 ~18~14~15 minecraft:stone_block_slab 1
fill ~18~23~13 ~18~23~14 minecraft:leaves 3
fill ~18~24~13 ~18~25~13 minecraft:vine 5
setblock ~18~26~13 minecraft:stained_hardened_clay 0
fill ~18~46~13 ~20~46~13 minecraft:leaves 3
fill ~19~11~13 ~19~11~15 minecraft:wooden_slab 13
setblock ~19~12~13 minecraft:flower_pot 0
setblock ~19~19~13 minecraft:trip_wire 0
fill ~19~20~13 ~19~23~13 minecraft:vine 14
fill ~19~24~13 ~19~25~13 minecraft:vine 12
setblock ~19~26~13 minecraft:quartz_block 0
fill ~19~27~13 ~19~27~14 minecraft:trapdoor 1
fill ~19~39~13 ~19~44~13 minecraft:vine 4
fill ~19~47~13 ~21~47~13 minecraft:leaves2 1
fill ~19~48~13 ~22~48~14 minecraft:leaves 3
fill ~19~49~13 ~19~49~15 minecraft:leaves 3
fill ~19~50~13 ~19~50~14 minecraft:leaves2 1
fill ~20~0~13 ~20~0~14 minecraft:dirt 1
setblock ~20~1~13 minecraft:red_flower 1
fill ~20~27~13 ~20~27~14 minecraft:bookshelf
fill ~20~28~13 ~20~28~14 minecraft:stained_glass 9
fill ~20~29~13 ~20~29~14 minecraft:trapdoor 1
setblock ~20~40~13 minecraft:trip_wire 0
fill ~20~41~13 ~20~44~13 minecraft:vine 4
setblock ~20~49~13 minecraft:leaves2 1
fill ~20~50~13 ~24~50~13 minecraft:leaves 3
fill ~21~0~13 ~21~0~14 minecraft:log 3
fill ~21~29~13 ~21~29~15 minecraft:stained_hardened_clay 0
fill ~21~49~13 ~21~49~16 minecraft:leaves 3
setblock ~22~0~13 minecraft:log 3
setblock ~22~1~13 minecraft:leaves 3
fill ~22~27~13 ~22~27~14 minecraft:stained_hardened_clay 0
setblock ~22~49~13 minecraft:leaves2 1
setblock ~22~51~13 minecraft:leaves 3
setblock ~23~0~13 minecraft:log 3
fill ~23~1~13 ~23~1~14 minecraft:log 3
setblock ~23~28~13 minecraft:spruce_stairs 6
setblock ~23~29~13 minecraft:spruce_stairs 1
fill ~23~49~13 ~23~49~16 minecraft:leaves 3
setblock ~24~1~13 minecraft:log 3
setblock ~24~2~13 minecraft:leaves 3
setblock ~24~28~13 minecraft:spruce_stairs 5
setblock ~24~29~13 minecraft:planks 1
setblock ~24~30~13 minecraft:spruce_stairs 0
setblock ~24~31~13 minecraft:spruce_stairs 4
setblock ~25~0~13 minecraft:dirt 1
setblock ~25~30~13 minecraft:spruce_stairs 5
setblock ~25~31~13 minecraft:planks 1
setblock ~25~32~13 minecraft:spruce_stairs 1
fill ~26~0~13 ~26~0~14 minecraft:log 3
setblock ~26~31~13 minecraft:wooden_slab 9
setblock ~26~32~13 minecraft:double_wooden_slab 1
setblock ~27~0~13 minecraft:log 3
setblock ~27~30~13 minecraft:spruce_stairs 4
fill ~27~31~13 ~27~31~14 minecraft:planks 1
setblock ~27~32~13 minecraft:spruce_stairs 0
setblock ~28~28~13 minecraft:spruce_stairs 4
setblock ~28~29~13 minecraft:planks 1
setblock ~28~30~13 minecraft:spruce_stairs 1
setblock ~28~31~13 minecraft:spruce_stairs 5
setblock ~29~28~13 minecraft:spruce_stairs 5
setblock ~29~29~13 minecraft:spruce_stairs 0
setblock ~4~21~14 minecraft:wooden_slab 11
setblock ~5~21~14 minecraft:leaves 3
fill ~5~22~14 ~7~22~14 minecraft:wooden_slab 3
setblock ~6~21~14 minecraft:log 3
setblock ~6~38~14 minecraft:leaves2 1
fill ~7~0~14 ~8~0~14 minecraft:log 3
fill ~7~21~14 ~8~21~14 minecraft:log 3
fill ~7~39~14 ~8~39~14 minecraft:leaves2 1
setblock ~8~22~14 minecraft:leaves 3
fill ~8~40~14 ~12~40~14 minecraft:leaves 3
fill ~8~42~14 ~8~42~15 minecraft:leaves 3
fill ~8~44~14 ~8~44~16 minecraft:leaves 3
setblock ~9~12~14 minecraft:anvil 2
setblock ~9~13~14 minecraft:fence 2
setblock ~9~14~14 minecraft:wool 6
setblock ~9~21~14 minecraft:log 3
setblock ~9~22~14 minecraft:log 3
fill ~9~24~14 ~10~24~14 minecraft:leaves 3
fill ~9~25~14 ~10~25~14 minecraft:wooden_slab 11
setblock ~9~41~14 minecraft:leaves2 1
fill ~9~43~14 ~9~43~15 minecraft:leaves 3
setblock ~10~10~14 minecraft:log 3
setblock ~10~11~14 minecraft:log 3
setblock ~10~12~14 minecraft:redstone_torch 3
fill ~10~15~14 ~10~15~15 minecraft:wool 10
setblock ~10~22~14 minecraft:log 3
setblock ~10~23~14 minecraft:glowstone
fill ~10~37~14 ~10~39~14 minecraft:leaves 3
fill ~10~41~14 ~12~41~14 minecraft:leaves 3
fill ~10~42~14 ~10~44~14 minecraft:leaves2 1
setblock ~11~10~14 minecraft:log 3
fill ~11~11~14 ~11~11~15 minecraft:double_wooden_slab 5
setblock ~11~12~14 minecraft:carpet 10
setblock ~11~16~14 minecraft:wool 2
fill ~11~26~14 ~12~26~14 minecraft:wooden_slab 3
fill ~11~38~14 ~11~38~15 minecraft:leaves 3
setblock ~11~39~14 minecraft:leaves 3
setblock ~11~42~14 minecraft:leaves 3
fill ~11~46~14 ~14~46~16 minecraft:leaves 3
fill ~11~47~14 ~12~47~15 minecraft:leaves 3
fill ~11~48~14 ~12~48~14 minecraft:leaves 3
setblock ~12~0~14 minecraft:log 3
fill ~12~8~14 ~12~10~14 minecraft:log 3
fill ~12~11~14 ~13~11~14 minecraft:log 3
setblock ~12~12~14 minecraft:carpet 2
setblock ~12~16~14 minecraft:planks 0
fill ~12~17~14 ~12~18~14 minecraft:wool 10
setblock ~12~19~14 minecraft:stone_block_slab 1
setblock ~12~25~14 minecraft:wooden_slab 11
setblock ~12~45~14 minecraft:leaves2 1
setblock ~13~8~14 minecraft:log 3
fill ~13~9~14 ~14~9~15 minecraft:log 3
setblock ~13~10~14 minecraft:log 3
setblock ~13~12~14 minecraft:carpet 6
setblock ~13~17~14 minecraft:redstone_torch 1
fill ~13~19~14 ~13~21~14 minecraft:wool 2
setblock ~13~22~14 minecraft:cobblestone_wall 0
setblock ~13~23~14 minecraft:nether_brick_fence
setblock ~13~24~14 minecraft:cobblestone_wall 0
setblock ~13~25~14 minecraft:nether_brick_fence
fill ~13~49~14 ~16~49~16 minecraft:leaves 3
setblock ~14~11~14 minecraft:log 3
fill ~14~12~14 ~14~12~15 minecraft:carpet 2
setblock ~14~17~14 minecraft:wool 2
setblock ~14~18~14 minecraft:wool 10
setblock ~14~24~14 minecraft:shulker_box 5
fill ~14~47~14 ~14~47~15 minecraft:leaves 3
setblock ~15~10~14 minecraft:log 3
setblock ~15~16~14 minecraft:wool 2
setblock ~15~25~14 minecraft:podzol
fill ~15~27~14 ~16~27~14 minecraft:wall_sign 2
setblock ~15~31~14 minecraft:stained_hardened_clay 0
fill ~15~48~14 ~15~48~15 minecraft:leaves 3
setblock ~16~0~14 minecraft:log 3
setblock ~16~23~14 minecraft:leaves 3
fill ~16~26~14 ~16~26~15 minecraft:stained_hardened_clay 0
setblock ~16~33~14 minecraft:stained_hardened_clay 0
fill ~16~47~14 ~17~47~14 minecraft:leaves2 1
fill ~16~50~14 ~17~50~14 minecraft:leaves2 1
setblock ~17~0~14 minecraft:log 3
setblock ~17~12~14 minecraft:anvil 0
setblock ~17~13~14 minecraft:fence 2
fill ~17~23~14 ~17~23~16 minecraft:log 3
fill ~17~33~14 ~18~33~14 minecraft:trapdoor 2
fill ~18~24~14 ~18~24~17 minecraft:log 3
fill ~18~25~14 ~19~25~14 minecraft:log 3
setblock ~18~26~14 minecraft:quartz_block 0
fill ~18~45~14 ~18~47~14 minecraft:leaves 3
setblock ~18~49~14 minecraft:leaves2 1
fill ~18~51~14 ~21~51~16 minecraft:leaves 3
setblock ~19~0~14 minecraft:dirt 1
setblock ~19~16~14 minecraft:trip_wire 0
fill ~19~17~14 ~19~24~14 minecraft:vine 2
fill ~19~26~14 ~19~26~15 minecraft:stained_hardened_clay 0
setblock ~19~33~14 minecraft:stained_hardened_clay 0
setblock ~19~46~14 minecraft:leaves2 1
fill ~19~47~14 ~23~47~15 minecraft:leaves 3
setblock ~20~31~14 minecraft:stained_hardened_clay 0
fill ~20~46~14 ~21~46~14 minecraft:leaves 3
fill ~20~49~14 ~20~50~14 minecraft:leaves 3
fill ~21~1~14 ~22~1~14 minecraft:log 3
fill ~22~0~14 ~23~0~14 minecraft:log 3
setblock ~22~2~14 minecraft:leaves 3
setblock ~22~46~14 minecraft:leaves2 1
setblock ~22~49~14 minecraft:leaves 3
fill ~22~51~14 ~23~51~15 minecraft:leaves2 1
fill ~23~2~14 ~23~2~15 minecraft:log 3
setblock ~23~3~14 minecraft:leaves 3
fill ~23~48~14 ~23~48~15 minecraft:leaves2 1
fill ~23~50~14 ~23~50~16 minecraft:leaves 3
setblock ~24~0~14 minecraft:log 3
fill ~24~1~14 ~24~1~15 minecraft:log 3
setblock ~24~2~14 minecraft:log 3
fill ~24~25~14 ~24~28~14 minecraft:log 0
setblock ~24~29~14 minecraft:leaves 3
fill ~24~48~14 ~24~49~14 minecraft:leaves 3
setblock ~24~50~14 minecraft:leaves2 1
fill ~24~51~14 ~24~51~16 minecraft:leaves 3
setblock ~25~0~14 minecraft:log 3
setblock ~25~1~14 minecraft:log 3
fill ~25~26~14 ~25~26~16 minecraft:wooden_slab 9
fill ~25~29~14 ~25~30~14 minecraft:log 0
setblock ~25~31~14 minecraft:leaves 3
fill ~25~47~14 ~26~47~14 minecraft:leaves2 1
fill ~25~48~14 ~25~49~14 minecraft:leaves2 1
setblock ~26~26~14 minecraft:oak_stairs 6
fill ~26~27~14 ~26~27~15 minecraft:wooden_slab 1
setblock ~26~31~14 minecraft:log 0
fill ~26~32~14 ~27~32~16 minecraft:planks 1
fill ~27~26~14 ~27~26~16 minecraft:wooden_slab 9
fill ~27~29~14 ~27~30~14 minecraft:log 0
fill ~28~25~14 ~28~28~14 minecraft:log 0
setblock ~30~27~14 minecraft:fence 1
setblock ~30~28~14 minecraft:spruce_stairs 6
setblock ~33~27~14 minecraft:fence 1
setblock ~33~28~14 minecraft:spruce_stairs 6
setblock ~3~0~15 minecraft:log 3
setblock ~5~0~15 minecraft:log 3
fill ~5~21~15 ~7~21~15 minecraft:wooden_slab 11
fill ~5~38~15 ~5~39~15 minecraft:leaves2 1
fill ~5~40~15 ~9~41~15 minecraft:leaves 3
fill ~5~42~15 ~7~42~15 minecraft:leaves 3
setblock ~6~0~15 minecraft:dirt 1
setblock ~6~1~15 minecraft:red_flower 1
fill ~6~37~15 ~9~37~15 minecraft:leaves 3
fill ~6~38~15 ~7~38~15 minecraft:leaves 3
setblock ~6~39~15 minecraft:leaves2 1
fill ~6~44~15 ~7~44~15 minecraft:leaves 3
setblock ~7~0~15 minecraft:log 3
setblock ~7~39~15 minecraft:leaves 3
fill ~7~43~15 ~8~43~16 minecraft:leaves 3
fill ~8~0~15 ~9~0~15 minecraft:log 3
setblock ~8~21~15 minecraft:leaves 3
fill ~8~38~15 ~9~38~15 minecraft:leaves2 1
setblock ~8~39~15 minecraft:leaves2 1
fill ~8~45~15 ~8~45~16 minecraft:leaves 3
setblock ~9~14~15 minecraft:wool 10
setblock ~9~22~15 minecraft:leaves 3
setblock ~9~39~15 minecraft:leaves 3
fill ~9~42~15 ~10~42~15 minecraft:leaves 3
fill ~9~44~15 ~9~44~16 minecraft:leaves2 1
setblock ~9~45~15 minecraft:leaves2 1
fill ~9~49~15 ~10~49~22 minecraft:leaves 3
setblock ~10~0~15 minecraft:dirt 1
setblock ~10~10~15 minecraft:log 3
fill ~10~11~15 ~10~11~18 minecraft:double_wooden_slab 5
fill ~10~22~15 ~10~22~16 minecraft:log 3
setblock ~10~23~15 minecraft:leaves 3
fill ~10~26~15 ~11~26~15 minecraft:wooden_slab 3
setblock ~10~32~15 minecraft:leaves2 1
fill ~10~33~15 ~10~34~15 minecraft:leaves 3
fill ~10~35~15 ~10~37~15 minecraft:leaves2 1
setblock ~10~38~15 minecraft:leaves 3
setblock ~10~41~15 minecraft:leaves2 1
fill ~10~43~15 ~10~45~15 minecraft:leaves 3
fill ~10~46~15 ~10~46~16 minecraft:leaves2 1
fill ~10~47~15 ~10~47~17 minecraft:leaves 3
fill ~11~10~15 ~12~10~15 minecraft:log 3
setblock ~11~12~15 minecraft:carpet 2
setblock ~11~15~15 minecraft:wool 2
fill ~11~39~15 ~11~40~15 minecraft:leaves2 1
fill ~11~41~15 ~13~41~15 minecraft:leaves 3
fill ~11~42~15 ~11~43~15 minecraft:leaves2 1
fill ~11~44~15 ~12~44~15 minecraft:leaves 3
fill ~11~45~15 ~11~45~18 minecraft:leaves2 1
fill ~11~48~15 ~11~48~16 minecraft:leaves2 1
fill ~11~49~15 ~12~49~15 minecraft:leaves2 1
setblock ~12~9~15 minecraft:log 3
fill ~12~11~15 ~12~11~17 minecraft:log 3
setblock ~12~12~15 minecraft:carpet 6
setblock ~12~16~15 minecraft:wool 10
setblock ~12~17~15 minecraft:wool 6
setblock ~12~26~15 minecraft:wooden_slab 11
fill ~12~39~15 ~13~40~15 minecraft:leaves 3
fill ~12~42~15 ~13~42~15 minecraft:leaves 3
fill ~12~43~15 ~12~43~16 minecraft:leaves2 1
fill ~12~45~15 ~13~45~15 minecraft:leaves 3
setblock ~12~48~15 minecraft:leaves 3
setblock ~13~8~15 minecraft:log 3
setblock ~13~10~15 minecraft:log 3
fill ~13~11~15 ~14~11~15 minecraft:log 3
setblock ~13~12~15 minecraft:carpet 9
setblock ~13~17~15 minecraft:wool 10
setblock ~13~18~15 minecraft:wool 9
fill ~13~43~15 ~13~43~16 minecraft:leaves 3
fill ~13~44~15 ~13~44~16 minecraft:leaves2 1
fill ~14~10~15 ~14~10~16 minecraft:log 3
setblock ~14~15~15 minecraft:redstone_torch 2
setblock ~14~16~15 minecraft:wool 10
setblock ~14~17~15 minecraft:wool 6
setblock ~14~24~15 minecraft:shulker_box 14
fill ~14~45~15 ~14~45~16 minecraft:leaves2 1
fill ~14~50~15 ~22~50~16 minecraft:leaves 3
fill ~15~10~15 ~15~10~16 minecraft:log 3
fill ~15~11~15 ~15~11~16 minecraft:log 3
setblock ~15~15~15 minecraft:wool 2
setblock ~15~25~15 minecraft:log 3
fill ~15~27~15 ~16~27~15 minecraft:chest 2
fill ~15~28~15 ~16~28~15 minecraft:carpet 0
setblock ~15~30~15 minecraft:stained_hardened_clay 0
setblock ~15~44~15 minecraft:leaves2 1
fill ~15~45~15 ~15~45~16 minecraft:leaves 3
fill ~15~46~15 ~15~47~15 minecraft:leaves 3
fill ~15~51~15 ~17~51~16 minecraft:leaves 3
setblock ~16~0~15 minecraft:dirt 1
setblock ~16~1~15 minecraft:red_flower 1
fill ~16~10~15 ~16~10~16 minecraft:log 3
fill ~16~11~15 ~16~11~16 minecraft:double_wooden_slab 5
setblock ~16~15~15 minecraft:wool 9
setblock ~16~22~15 minecraft:leaves 3
fill ~16~23~15 ~16~23~18 minecraft:log 3
setblock ~16~25~15 minecraft:log 3
fill ~16~31~15 ~16~32~15 minecraft:stained_hardened_clay 0
setblock ~16~46~15 minecraft:leaves2 1
fill ~16~47~15 ~18~47~15 minecraft:leaves 3
fill ~16~48~15 ~17~48~15 minecraft:leaves2 1
setblock ~17~0~15 minecraft:log 3
setblock ~17~14~15 minecraft:wool 6
setblock ~17~18~15 minecraft:trip_wire 0
fill ~17~26~15 ~18~26~15 minecraft:stained_hardened_clay 0
fill ~17~32~15 ~19~32~15 minecraft:stained_hardened_clay 0
fill ~17~33~15 ~18~33~15 minecraft:stained_hardened_clay 0
fill ~17~46~15 ~18~46~15 minecraft:leaves 3
fill ~17~49~15 ~18~49~15 minecraft:leaves 3
fill ~17~52~15 ~20~52~16 minecraft:leaves 3
setblock ~18~0~15 minecraft:log 3
setblock ~18~17~15 minecraft:trip_wire 0
fill ~18~18~15 ~18~23~15 minecraft:vine 1
setblock ~18~25~15 minecraft:log 3
setblock ~19~0~15 minecraft:log 3
setblock ~19~25~15 minecraft:log 3
setblock ~19~31~15 minecraft:stained_hardened_clay 0
fill ~19~48~15 ~19~48~19 minecraft:leaves 3
fill ~20~0~15 ~21~1~15 minecraft:log 3
setblock ~20~25~15 minecraft:wool 12
fill ~20~27~15 ~21~27~15 minecraft:stained_hardened_clay 0
setblock ~20~30~15 minecraft:stained_hardened_clay 0
fill ~20~48~15 ~20~49~16 minecraft:leaves2 1
setblock ~21~28~15 minecraft:stained_hardened_clay 0
fill ~21~48~15 ~22~48~15 minecraft:leaves 3
fill ~21~52~15 ~21~52~16 minecraft:leaves2 1
fill ~21~53~15 ~22~53~16 minecraft:leaves 3
fill ~22~0~15 ~22~1~15 minecraft:log 3
setblock ~22~2~15 minecraft:log 3
setblock ~22~27~15 minecraft:wool 12
fill ~22~28~15 ~22~28~16 minecraft:leaves 3
fill ~22~29~15 ~22~30~15 minecraft:leaves 3
fill ~22~52~15 ~23~52~15 minecraft:leaves 3
fill ~23~0~15 ~23~1~15 minecraft:log 3
setblock ~23~27~15 minecraft:wooden_slab 1
fill ~23~46~15 ~24~46~15 minecraft:leaves 3
fill ~24~0~15 ~24~0~16 minecraft:log 3
setblock ~24~25~15 minecraft:oak_stairs 2
setblock ~24~26~15 minecraft:oak_stairs 7
fill ~24~47~15 ~24~47~17 minecraft:leaves 3
setblock ~24~48~15 minecraft:leaves2 1
fill ~24~49~15 ~25~50~15 minecraft:leaves 3
fill ~25~0~15 ~26~0~15 minecraft:log 3
setblock ~25~22~15 minecraft:spruce_stairs 6
setblock ~25~23~15 minecraft:spruce_stairs 4
fill ~25~27~15 ~25~29~15 minecraft:end_stone
setblock ~25~32~15 minecraft:leaves 3
setblock ~25~47~15 minecraft:leaves2 1
fill ~25~48~15 ~25~48~17 minecraft:leaves 3
fill ~25~51~15 ~25~51~17 minecraft:leaves 3
setblock ~26~23~15 minecraft:spruce_stairs 5
setblock ~26~24~15 minecraft:spruce_stairs 1
setblock ~26~30~15 minecraft:end_stone
setblock ~26~31~15 minecraft:leaves 3
fill ~26~47~15 ~26~47~16 minecraft:leaves 3
fill ~26~48~15 ~26~48~16 minecraft:leaves2 1
setblock ~27~0~15 minecraft:dirt 1
setblock ~27~1~15 minecraft:red_flower 1
setblock ~27~23~15 minecraft:double_wooden_slab 1
fill ~27~27~15 ~27~29~15 minecraft:end_stone
setblock ~27~31~15 minecraft:end_stone
setblock ~28~23~15 minecraft:spruce_stairs 4
setblock ~28~24~15 minecraft:spruce_stairs 0
setblock ~28~26~15 minecraft:oak_stairs 6
setblock ~28~27~15 minecraft:double_wooden_slab 1
fill ~28~29~15 ~28~31~15 minecraft:log 0
setblock ~29~22~15 minecraft:spruce_stairs 6
setblock ~29~23~15 minecraft:spruce_stairs 5
fill ~29~27~15 ~29~27~16 minecraft:wooden_slab 1
setblock ~30~25~15 minecraft:spruce_stairs 6
fill ~30~26~15 ~30~28~15 minecraft:log 0
setblock ~30~29~15 minecraft:spruce_stairs 0
setblock ~30~30~15 minecraft:wooden_slab 1
fill ~31~29~15 ~31~29~16 minecraft:spruce_stairs 5
fill ~32~29~15 ~32~29~16 minecraft:spruce_stairs 4
setblock ~33~25~15 minecraft:spruce_stairs 6
fill ~33~26~15 ~33~28~15 minecraft:log 0
setblock ~33~29~15 minecraft:spruce_stairs 1
setblock ~33~30~15 minecraft:wooden_slab 1
setblock ~34~28~15 minecraft:spruce_stairs 5
setblock ~3~0~16 minecraft:log 3
setblock ~4~0~16 minecraft:log 3
fill ~4~38~16 ~4~38~22 minecraft:leaves 3
fill ~4~39~16 ~4~41~16 minecraft:leaves2 1
fill ~4~42~16 ~4~42~20 minecraft:leaves 3
setblock ~5~0~16 minecraft:log 3
fill ~5~21~16 ~8~21~16 minecraft:wooden_slab 3
fill ~5~37~16 ~8~37~16 minecraft:leaves 3
fill ~5~38~16 ~9~38~16 minecraft:log 0
fill ~5~39~16 ~5~41~16 minecraft:sea_lantern
fill ~5~42~16 ~10~42~16 minecraft:glass
fill ~5~43~16 ~6~43~16 minecraft:leaves 3
fill ~5~44~16 ~5~46~20 minecraft:leaves 3
fill ~5~47~16 ~7~47~16 minecraft:leaves 3
setblock ~6~0~16 minecraft:log 3
fill ~6~36~16 ~7~36~17 minecraft:leaves 3
fill ~6~39~16 ~10~41~16 minecraft:glass
fill ~6~45~16 ~7~46~16 minecraft:leaves 3
setblock ~7~0~16 minecraft:log 3
fill ~7~44~16 ~7~44~19 minecraft:leaves2 1
fill ~8~0~16 ~9~0~16 minecraft:log 3
setblock ~8~1~16 minecraft:log 3
fill ~8~11~16 ~8~11~17 minecraft:wooden_slab 13
fill ~8~46~16 ~9~46~16 minecraft:leaves 3
fill ~8~48~16 ~8~49~23 minecraft:leaves 3
setblock ~9~1~16 minecraft:log 3
fill ~9~14~16 ~9~14~17 minecraft:stone_block_slab 1
fill ~9~21~16 ~9~21~18 minecraft:leaves 3
fill ~9~43~16 ~11~43~16 minecraft:leaves2 1
fill ~9~45~16 ~10~45~16 minecraft:leaves 3
fill ~10~0~16 ~10~0~17 minecraft:log 3
fill ~10~14~16 ~10~14~17 minecraft:wool 2
setblock ~10~21~16 minecraft:log 3
setblock ~10~33~16 minecraft:leaves2 1
fill ~10~34~16 ~10~37~16 minecraft:leaves 3
setblock ~10~38~16 minecraft:leaves2 1
fill ~10~44~16 ~11~44~16 minecraft:leaves 3
fill ~10~48~16 ~10~48~17 minecraft:leaves2 1
fill ~11~0~16 ~12~0~16 minecraft:dirt 1
fill ~11~10~16 ~12~10~16 minecraft:log 3
setblock ~11~11~16 minecraft:log 3
setblock ~11~15~16 minecraft:wool 6
setblock ~11~26~16 minecraft:wooden_slab 3
setblock ~11~34~16 minecraft:leaves2 1
fill ~11~35~16 ~11~37~16 minecraft:leaves 3
fill ~11~38~16 ~14~38~19 minecraft:log 0
fill ~11~39~16 ~11~42~16 minecraft:log 0
setblock ~11~47~16 minecraft:glowstone
fill ~11~49~16 ~12~49~18 minecraft:leaves 3
setblock ~12~1~16 minecraft:red_flower 1
setblock ~12~12~16 minecraft:carpet 2
fill ~12~15~16 ~12~15~17 minecraft:wool 2
setblock ~12~16~16 minecraft:stone_block_slab 1
setblock ~12~26~16 minecraft:double_wooden_slab 3
fill ~12~39~16 ~13~41~16 minecraft:log 0
fill ~12~42~16 ~13~42~16 minecraft:log 0
fill ~12~44~16 ~12~45~18 minecraft:leaves2 1
setblock ~12~47~16 minecraft:leaves 3
setblock ~12~48~16 minecraft:leaves2 1
setblock ~12~50~16 minecraft:leaves2 1
fill ~13~9~16 ~13~9~17 minecraft:log 3
fill ~13~10~16 ~13~10~17 minecraft:log 3
setblock ~13~11~16 minecraft:log 3
setblock ~13~16~16 minecraft:wool 9
fill ~13~27~16 ~13~27~18 minecraft:wooden_slab 3
fill ~13~45~16 ~13~45~17 minecraft:leaves 3
fill ~13~48~16 ~13~48~18 minecraft:leaves 3
fill ~13~50~16 ~13~52~18 minecraft:leaves 3
setblock ~14~9~16 minecraft:log 3
setblock ~14~11~16 minecraft:log 3
setblock ~14~15~16 minecraft:wool 2
setblock ~14~27~16 minecraft:wool 12
fill ~14~39~16 ~14~42~16 minecraft:log 0
fill ~14~43~16 ~14~44~17 minecraft:leaves 3
fill ~14~51~16 ~14~53~16 minecraft:leaves 3
setblock ~15~15~16 minecraft:wool 6
fill ~15~25~16 ~15~25~20 minecraft:leaves 3
setblock ~15~26~16 minecraft:wool 12
fill ~15~27~16 ~16~29~16 minecraft:stained_hardened_clay 0
fill ~15~44~16 ~16~44~16 minecraft:leaves 3
fill ~15~47~16 ~17~47~16 minecraft:leaves 3
fill ~15~52~16 ~16~53~16 minecraft:leaves 3
fill ~16~14~16 ~16~14~17 minecraft:wool 10
fill ~16~25~16 ~16~26~16 minecraft:log 3
fill ~16~30~16 ~19~30~16 minecraft:stained_hardened_clay 0
fill ~16~45~16 ~16~45~19 minecraft:leaves 3
fill ~16~54~16 ~17~54~19 minecraft:leaves 3
fill ~17~0~16 ~17~0~17 minecraft:dirt 1
setblock ~17~10~16 minecraft:log 3
fill ~17~14~16 ~17~14~17 minecraft:stone_block_slab 1
fill ~17~21~16 ~18~21~16 minecraft:leaves 3
fill ~17~26~16 ~18~26~16 minecraft:log 3
fill ~17~29~16 ~20~29~16 minecraft:stained_hardened_clay 0
fill ~17~31~16 ~18~31~16 minecraft:stained_hardened_clay 0
fill ~17~48~16 ~17~48~19 minecraft:leaves 3
setblock ~17~49~16 minecraft:leaves 3
fill ~17~53~16 ~20~53~16 minecraft:leaves 3
fill ~18~0~16 ~18~0~20 minecraft:log 3
fill ~18~11~16 ~18~11~17 minecraft:wooden_slab 13
fill ~18~22~16 ~18~22~17 minecraft:leaves 3
fill ~18~23~16 ~18~23~18 minecraft:log 3
setblock ~18~25~16 minecraft:log 3
fill ~18~49~16 ~19~49~16 minecraft:leaves2 1
fill ~19~0~16 ~19~0~17 minecraft:log 3
fill ~19~1~16 ~20~1~16 minecraft:log 3
setblock ~19~24~16 minecraft:log 3
fill ~19~25~16 ~19~25~17 minecraft:log 3
setblock ~19~26~16 minecraft:log 3
fill ~19~27~16 ~20~28~16 minecraft:stained_hardened_clay 0
setblock ~20~0~16 minecraft:log 3
setblock ~20~26~16 minecraft:wool 12
fill ~21~0~16 ~21~1~17 minecraft:log 3
fill ~21~2~16 ~21~2~17 minecraft:log 3
setblock ~21~27~16 minecraft:wool 12
fill ~21~28~16 ~21~29~16 minecraft:leaves 3
setblock ~22~0~16 minecraft:log 3
setblock ~22~1~16 minecraft:log 3
setblock ~22~2~16 minecraft:log 3
fill ~22~26~16 ~23~26~16 minecraft:wooden_slab 11
setblock ~22~27~16 minecraft:leaves 3
setblock ~22~49~16 minecraft:leaves 3
fill ~22~51~16 ~23~51~16 minecraft:leaves 3
setblock ~22~52~16 minecraft:leaves2 1
setblock ~23~0~16 minecraft:log 3
fill ~23~1~16 ~23~2~16 minecraft:log 3
fill ~23~28~16 ~23~29~16 minecraft:leaves 3
fill ~23~52~16 ~25~52~16 minecraft:leaves 3
setblock ~23~53~16 minecraft:leaves 3
setblock ~24~25~16 minecraft:oak_stairs 6
setblock ~24~26~16 minecraft:double_wooden_slab 1
fill ~24~27~16 ~24~28~16 minecraft:log 0
setblock ~24~30~16 minecraft:leaves 3
setblock ~24~46~16 minecraft:leaves2 1
fill ~24~50~16 ~25~50~16 minecraft:leaves 3
setblock ~24~53~16 minecraft:leaves2 1
fill ~25~0~16 ~26~0~16 minecraft:dirt 1
setblock ~25~27~16 minecraft:wooden_slab 1
setblock ~25~28~16 minecraft:log 0
fill ~25~29~16 ~25~30~17 minecraft:log 0
setblock ~25~31~16 minecraft:leaves 3
fill ~25~42~16 ~26~45~16 minecraft:vine 1
fill ~25~46~16 ~27~46~17 minecraft:leaves 3
fill ~25~47~16 ~25~47~19 minecraft:leaves 3
fill ~25~49~16 ~25~49~24 minecraft:leaves 3
setblock ~26~20~16 minecraft:oak_stairs 6
fill ~26~21~16 ~26~23~16 minecraft:log 0
setblock ~26~26~16 minecraft:wooden_slab 9
setblock ~26~30~16 minecraft:log 0
setblock ~26~31~16 minecraft:log 0
fill ~26~49~16 ~26~50~16 minecraft:leaves2 1
fill ~27~23~16 ~27~23~18 minecraft:planks 0
fill ~27~44~16 ~27~45~16 minecraft:vine 1
setblock ~27~47~16 minecraft:leaves 3
fill ~28~20~16 ~28~21~16 minecraft:spruce_stairs 6
fill ~28~22~16 ~28~23~17 minecraft:log 0
fill ~28~27~16 ~28~28~16 minecraft:end_stone
fill ~28~29~16 ~28~31~16 minecraft:vine 6
setblock ~28~32~16 minecraft:vine 3
fill ~28~33~16 ~30~33~16 minecraft:vine 1
setblock ~28~40~16 minecraft:leaves 3
fill ~28~41~16 ~28~43~16 minecraft:vine 1
fill ~28~44~16 ~28~44~19 minecraft:leaves2 1
setblock ~28~45~16 minecraft:leaves 3
setblock ~29~8~16 minecraft:trip_wire 0
fill ~29~9~16 ~29~21~16 minecraft:vine 1
fill ~29~22~16 ~29~23~16 minecraft:planks 0
setblock ~29~24~16 minecraft:spruce_stairs 6
setblock ~29~25~16 minecraft:spruce_stairs 0
setblock ~29~26~16 minecraft:spruce_stairs 2
setblock ~29~28~16 minecraft:vine 9
fill ~29~29~16 ~29~32~16 minecraft:vine 1
fill ~29~34~16 ~30~38~16 minecraft:vine 1
setblock ~29~39~16 minecraft:leaves 3
fill ~29~41~16 ~29~44~16 minecraft:leaves 3
setblock ~30~19~16 minecraft:log 3
setblock ~30~20~16 minecraft:log 3
fill ~30~21~16 ~30~22~17 minecraft:log 0
setblock ~30~23~16 minecraft:spruce_stairs 6
fill ~30~24~16 ~30~25~16 minecraft:spruce_stairs 2
fill ~30~26~16 ~31~26~16 minecraft:spruce_stairs 1
fill ~30~27~16 ~30~29~16 minecraft:end_stone
fill ~30~39~16 ~30~41~16 minecraft:vine 1
setblock ~30~42~16 minecraft:leaves 3
fill ~30~43~16 ~30~44~16 minecraft:vine 1
setblock ~31~12~16 minecraft:trip_wire 0
fill ~31~13~16 ~31~20~16 minecraft:vine 1
setblock ~31~21~16 minecraft:spruce_stairs 6
setblock ~31~22~16 minecraft:vine 2
setblock ~31~25~16 minecraft:spruce_stairs 5
setblock ~31~30~16 minecraft:spruce_stairs 0
setblock ~32~21~16 minecraft:wooden_slab 9
setblock ~32~22~16 minecraft:wooden_slab 1
setblock ~32~25~16 minecraft:spruce_stairs 4
fill ~32~26~16 ~33~26~16 minecraft:spruce_stairs 0
setblock ~32~30~16 minecraft:spruce_stairs 1
setblock ~33~18~16 minecraft:fence 1
setblock ~33~21~16 minecraft:spruce_stairs 6
setblock ~33~23~16 minecraft:spruce_stairs 6
fill ~33~24~16 ~33~25~16 minecraft:spruce_stairs 2
fill ~33~27~16 ~33~29~16 minecraft:end_stone
setblock ~34~24~16 minecraft:spruce_stairs 6
setblock ~34~25~16 minecraft:spruce_stairs 1
setblock ~34~26~16 minecraft:spruce_stairs 2
fill ~3~38~17 ~3~38~19 minecraft:leaves 3
setblock ~3~39~17 minecraft:leaves2 1
setblock ~4~0~17 minecraft:dirt 1
fill ~4~22~17 ~4~22~18 minecraft:leaves 3
fill ~4~36~17 ~5~37~17 minecraft:leaves 3
fill ~4~39~17 ~4~39~22 minecraft:leaves 3
fill ~4~40~17 ~4~41~19 minecraft:leaves 3
setblock ~4~45~17 minecraft:leaves 3
fill ~5~20~17 ~8~20~18 minecraft:wooden_slab 11
setblock ~5~24~17 minecraft:leaves 3
fill ~5~38~17 ~6~38~17 minecraft:log 0
fill ~5~39~17 ~5~41~17 minecraft:log 0
fill ~5~42~17 ~5~42~22 minecraft:glass
fill ~5~43~17 ~5~43~22 minecraft:leaves 3
fill ~5~47~17 ~6~47~17 minecraft:leaves 3
fill ~6~0~17 ~6~0~18 minecraft:log 3
fill ~6~37~17 ~7~37~18 minecraft:leaves 3
fill ~6~44~17 ~6~44~19 minecraft:leaves2 1
setblock ~6~45~17 minecraft:leaves2 1
fill ~7~0~17 ~7~1~17 minecraft:log 3
fill ~7~38~17 ~7~38~19 minecraft:log 3
setblock ~7~47~17 minecraft:log 3
fill ~7~48~17 ~7~49~17 minecraft:leaves 3
setblock ~8~38~17 minecraft:log 3
fill ~8~44~17 ~8~45~17 minecraft:leaves2 1
fill ~8~47~17 ~9~47~20 minecraft:leaves 3
setblock ~9~0~17 minecraft:log 3
fill ~9~1~17 ~10~1~17 minecraft:log 3
setblock ~9~12~17 minecraft:wooden_slab 2
setblock ~9~20~17 minecraft:leaves 3
fill ~9~37~17 ~10~38~17 minecraft:leaves 3
fill ~9~45~17 ~10~45~18 minecraft:leaves2 1
fill ~9~48~17 ~9~48~18 minecraft:leaves 3
setblock ~10~12~17 minecraft:anvil 1
setblock ~10~13~17 minecraft:fence 2
setblock ~10~21~17 minecraft:log 3
setblock ~10~22~17 minecraft:leaves 3
setblock ~10~36~17 minecraft:leaves 3
fill ~10~50~17 ~12~50~19 minecraft:leaves 3
setblock ~11~0~17 minecraft:log 3
setblock ~11~10~17 minecraft:log 3
fill ~11~11~17 ~11~11~18 minecraft:double_wooden_slab 5
setblock ~11~14~17 minecraft:wool 10
setblock ~11~44~17 minecraft:leaves2 1
fill ~11~47~17 ~11~48~17 minecraft:leaves 3
fill ~11~51~17 ~12~51~21 minecraft:leaves 3
fill ~12~0~17 ~12~1~17 minecraft:log 3
fill ~12~10~17 ~12~10~18 minecraft:log 3
setblock ~12~26~17 minecraft:wooden_slab 11
setblock ~12~48~17 minecraft:leaves 3
setblock ~13~0~17 minecraft:dirt 1
setblock ~13~11~17 minecraft:leaves 3
setblock ~13~15~17 minecraft:wool 2
setblock ~13~44~17 minecraft:leaves 3
fill ~13~49~17 ~13~49~24 minecraft:leaves 3
fill ~13~53~17 ~13~53~30 minecraft:leaves 3
fill ~14~8~17 ~14~9~17 minecraft:log 3
setblock ~14~10~17 minecraft:log 3
setblock ~14~11~17 minecraft:log 3
setblock ~14~12~17 minecraft:shulker_box 3
setblock ~14~15~17 minecraft:wool 10
setblock ~14~25~17 minecraft:leaves 3
fill ~14~27~17 ~14~27~18 minecraft:wooden_slab 3
fill ~14~39~17 ~14~40~18 minecraft:glass
fill ~14~41~17 ~14~41~18 minecraft:log 0
fill ~14~42~17 ~14~42~19 minecraft:glass
fill ~14~45~17 ~14~46~19 minecraft:leaves 3
fill ~14~47~17 ~15~47~18 minecraft:leaves 3
fill ~14~49~17 ~19~49~17 minecraft:stone_block_slab 13
fill ~14~50~17 ~14~53~17 minecraft:log 3
fill ~14~54~17 ~15~54~24 minecraft:leaves 3
setblock ~15~9~17 minecraft:log 3
setblock ~15~10~17 minecraft:log 3
fill ~15~11~17 ~16~11~17 minecraft:log 3
fill ~15~12~17 ~15~12~18 minecraft:bookshelf
setblock ~15~14~17 minecraft:wool 9
setblock ~15~24~17 minecraft:leaves 3
setblock ~15~26~17 minecraft:wooden_slab 11
fill ~15~44~17 ~15~44~19 minecraft:leaves 3
fill ~15~45~17 ~15~45~18 minecraft:leaves2 1
fill ~15~46~17 ~19~46~18 minecraft:leaves 3
fill ~15~48~17 ~16~48~19 minecraft:leaves 3
setblock ~15~52~17 minecraft:wooden_slab 9
setblock ~15~53~17 minecraft:log 3
setblock ~16~0~17 minecraft:log 3
setblock ~16~9~17 minecraft:log 3
setblock ~16~10~17 minecraft:log 3
setblock ~16~12~17 minecraft:anvil 1
setblock ~16~13~17 minecraft:fence 2
fill ~16~22~17 ~16~22~18 minecraft:leaves 3
fill ~16~25~17 ~17~25~17 minecraft:log 3
fill ~16~26~17 ~19~26~17 minecraft:log 3
fill ~16~35~17 ~16~35~18 minecraft:leaves 3
setblock ~17~1~17 minecraft:red_flower 1
setblock ~17~10~17 minecraft:log 3
setblock ~17~12~17 minecraft:wooden_slab 2
setblock ~17~23~17 minecraft:log 3
setblock ~17~34~17 minecraft:leaves 3
fill ~17~47~17 ~18~47~19 minecraft:leaves 3
fill ~18~21~17 ~18~21~18 minecraft:leaves 3
setblock ~18~25~17 minecraft:log 3
setblock ~18~44~17 minecraft:leaves2 1
fill ~18~54~17 ~23~54~17 minecraft:leaves 3
fill ~19~14~17 ~19~15~17 minecraft:leaves 3
setblock ~19~22~17 minecraft:leaves 3
setblock ~19~24~17 minecraft:log 3
setblock ~19~34~17 minecraft:leaves 3
fill ~19~50~17 ~19~53~17 minecraft:log 3
setblock ~20~0~17 minecraft:log 3
fill ~20~1~17 ~20~2~17 minecraft:log 3
fill ~20~4~17 ~20~11~17 minecraft:vine 1
fill ~20~12~17 ~20~15~17 minecraft:vine 3
setblock ~20~27~17 minecraft:wool 12
setblock ~20~28~17 minecraft:leaves 3
fill ~20~32~17 ~21~36~17 minecraft:vine 1
setblock ~20~37~17 minecraft:vine 1
setblock ~20~44~17 minecraft:leaves2 1
fill ~20~45~17 ~20~45~19 minecraft:leaves 3
fill ~20~48~17 ~23~48~18 minecraft:leaves 3
setblock ~20~49~17 minecraft:double_stone_block_slab 5
setblock ~20~50~17 minecraft:spruce_stairs 4
setblock ~21~27~17 minecraft:wooden_slab 11
setblock ~21~31~17 minecraft:vine 1
setblock ~21~45~17 minecraft:leaves2 1
fill ~21~49~17 ~24~49~19 minecraft:stone_block_slab 13
fill ~21~50~17 ~22~50~17 minecraft:wool 13
setblock ~21~51~17 minecraft:spruce_stairs 0
setblock ~22~0~17 minecraft:log 3
setblock ~22~1~17 minecraft:log 3
setblock ~22~27~17 minecraft:wooden_slab 3
setblock ~22~51~17 minecraft:spruce_stairs 1
setblock ~22~53~17 minecraft:spruce_stairs 4
setblock ~23~0~17 minecraft:log 3
fill ~23~22~17 ~23~24~17 minecraft:fence 1
fill ~23~25~17 ~25~25~17 minecraft:log 0
setblock ~23~26~17 minecraft:double_wooden_slab 3
setblock ~23~27~17 minecraft:spruce_stairs 0
setblock ~23~28~17 minecraft:spruce_stairs 4
setblock ~23~29~17 minecraft:spruce_stairs 1
setblock ~23~50~17 minecraft:spruce_stairs 5
setblock ~23~52~17 minecraft:wooden_slab 9
setblock ~23~53~17 minecraft:log 3
setblock ~24~0~17 minecraft:log 3
setblock ~24~23~17 minecraft:spruce_stairs 2
fill ~24~24~17 ~24~24~19 minecraft:log 0
fill ~24~26~17 ~24~26~18 minecraft:wooden_slab 11
fill ~24~27~17 ~24~29~17 minecraft:planks 1
fill ~24~30~17 ~24~30~18 minecraft:spruce_stairs 0
setblock ~24~31~17 minecraft:spruce_stairs 4
fill ~24~50~17 ~24~53~17 minecraft:log 3
setblock ~24~54~17 minecraft:leaves2 1
setblock ~25~0~17 minecraft:dirt 1
setblock ~25~26~17 minecraft:wooden_slab 1
fill ~25~27~17 ~26~28~17 minecraft:log 0
setblock ~25~31~17 minecraft:planks 1
setblock ~25~32~17 minecraft:spruce_stairs 1
fill ~25~45~17 ~25~45~18 minecraft:leaves 3
fill ~25~50~17 ~25~50~23 minecraft:leaves 3
fill ~25~52~17 ~25~52~32 minecraft:leaves 3
setblock ~25~53~17 minecraft:leaves2 1
setblock ~26~19~17 minecraft:oak_stairs 2
setblock ~26~20~17 minecraft:oak_stairs 3
setblock ~26~22~17 minecraft:log 0
fill ~26~23~17 ~26~26~17 minecraft:log 0
setblock ~26~32~17 minecraft:double_wooden_slab 1
fill ~26~44~17 ~26~44~18 minecraft:leaves 3
fill ~26~45~17 ~28~45~17 minecraft:leaves2 1
fill ~26~47~17 ~27~47~17 minecraft:leaves2 1
fill ~26~48~17 ~27~48~20 minecraft:leaves 3
fill ~26~49~17 ~26~49~33 minecraft:leaves 3
setblock ~26~50~17 minecraft:leaves2 1
setblock ~27~13~17 minecraft:trip_wire 0
fill ~27~14~17 ~27~21~17 minecraft:vine 1
setblock ~27~22~17 minecraft:end_stone
fill ~27~24~17 ~27~25~17 minecraft:stained_glass_pane 0
setblock ~27~26~17 minecraft:end_stone
setblock ~27~32~17 minecraft:spruce_stairs 0
fill ~27~38~17 ~28~38~17 minecraft:leaves 3
fill ~27~42~17 ~27~42~19 minecraft:leaves2 1
fill ~27~43~17 ~27~44~18 minecraft:leaves2 1
setblock ~28~18~17 minecraft:log 3
fill ~28~19~17 ~28~21~17 minecraft:log 0
fill ~28~24~17 ~28~29~17 minecraft:log 0
setblock ~28~33~17 minecraft:leaves2 1
fill ~28~35~17 ~29~37~17 minecraft:leaves 3
fill ~28~39~17 ~30~39~17 minecraft:leaves2 1
setblock ~28~40~17 minecraft:leaves2 1
fill ~28~41~17 ~28~43~17 minecraft:leaves 3
fill ~28~46~17 ~28~46~20 minecraft:leaves 3
setblock ~28~47~17 minecraft:leaves 3
setblock ~29~0~17 minecraft:log 3
fill ~29~19~17 ~31~19~17 minecraft:log 3
fill ~29~20~17 ~29~21~17 minecraft:end_stone
fill ~29~31~17 ~29~32~17 minecraft:leaves 3
fill ~29~33~17 ~29~34~17 minecraft:leaves 3
fill ~29~38~17 ~30~38~17 minecraft:leaves2 1
fill ~29~40~17 ~30~40~17 minecraft:leaves 3
setblock ~29~41~17 minecraft:glowstone
fill ~29~42~17 ~29~42~18 minecraft:leaves 3
fill ~29~43~17 ~30~43~17 minecraft:leaves 3
setblock ~29~44~17 minecraft:leaves2 1
setblock ~29~45~17 minecraft:leaves 3
setblock ~30~0~17 minecraft:log 3
setblock ~30~18~17 minecraft:log 0
fill ~30~20~17 ~30~20~18 minecraft:log 3
fill ~30~23~17 ~30~29~17 minecraft:log 0
fill ~30~30~17 ~30~36~17 minecraft:vine 2
fill ~30~37~17 ~30~37~18 minecraft:leaves 3
setblock ~30~41~17 minecraft:leaves 3
fill ~30~42~17 ~30~42~18 minecraft:leaves2 1
setblock ~30~44~17 minecraft:leaves 3
setblock ~31~18~17 minecraft:leaves2 1
fill ~31~20~17 ~31~20~18 minecraft:log 3
fill ~31~21~17 ~32~21~17 minecraft:log 0
fill ~31~22~17 ~31~24~17 minecraft:vine 3
setblock ~31~25~17 minecraft:vine 2
fill ~31~26~17 ~32~26~17 minecraft:end_stone
fill ~31~27~17 ~31~29~17 minecraft:vine 2
setblock ~31~33~17 minecraft:trip_wire 0
fill ~31~34~17 ~31~43~18 minecraft:vine 2
setblock ~31~44~17 minecraft:vine 2
setblock ~32~14~17 minecraft:trip_wire 0
fill ~32~15~17 ~32~17~17 minecraft:vine 10
setblock ~32~18~17 minecraft:vine 2
fill ~32~19~17 ~32~20~17 minecraft:leaves 3
fill ~32~22~17 ~32~25~17 minecraft:vine 9
setblock ~33~16~17 minecraft:oak_stairs 6
fill ~33~17~17 ~33~29~17 minecraft:log 0
setblock ~3~0~18 minecraft:dirt 1
setblock ~3~14~18 minecraft:trip_wire 0
fill ~3~15~18 ~3~19~18 minecraft:vine 1
fill ~4~0~18 ~5~0~18 minecraft:log 3
fill ~4~17~18 ~4~19~18 minecraft:vine 1
setblock ~4~20~18 minecraft:wooden_slab 11
setblock ~4~21~18 minecraft:web
setblock ~4~23~18 minecraft:leaves 3
fill ~4~44~18 ~4~44~20 minecraft:leaves 3
fill ~5~25~18 ~6~25~18 minecraft:leaves 3
fill ~5~36~18 ~6~36~18 minecraft:leaves 3
fill ~5~37~18 ~5~37~22 minecraft:leaves 3
fill ~5~38~18 ~5~38~20 minecraft:log 0
fill ~5~39~18 ~5~40~18 minecraft:glass
setblock ~5~41~18 minecraft:log 0
fill ~5~49~18 ~7~49~18 minecraft:leaves 3
fill ~6~1~18 ~7~1~19 minecraft:log 3
setblock ~6~17~18 minecraft:leaves 3
setblock ~6~18~18 minecraft:fence 5
fill ~6~19~18 ~7~19~18 minecraft:leaves 3
fill ~6~21~18 ~8~21~18 minecraft:carpet 7
setblock ~6~38~18 minecraft:log 3
fill ~6~39~18 ~13~39~19 minecraft:carpet 12
fill ~7~0~18 ~8~0~18 minecraft:log 3
fill ~7~2~18 ~7~2~19 minecraft:log 3
setblock ~7~16~18 minecraft:leaves 3
fill ~7~17~18 ~7~18~18 minecraft:log 3
fill ~7~47~18 ~7~47~19 minecraft:leaves 3
fill ~8~1~18 ~8~2~18 minecraft:log 3
setblock ~8~25~18 minecraft:leaves 3
fill ~8~36~18 ~9~36~20 minecraft:leaves 3
fill ~8~37~18 ~8~37~20 minecraft:log 3
fill ~8~38~18 ~9~38~18 minecraft:log 3
fill ~8~45~18 ~8~46~18 minecraft:leaves2 1
fill ~9~0~18 ~9~0~19 minecraft:log 3
fill ~9~1~18 ~10~1~18 minecraft:log 3
setblock ~9~3~18 minecraft:log 3
setblock ~9~11~18 minecraft:wooden_slab 13
setblock ~9~20~18 minecraft:wooden_slab 11
setblock ~9~22~18 minecraft:leaves 3
setblock ~9~37~18 minecraft:log 3
setblock ~9~50~18 minecraft:leaves2 1
setblock ~10~0~18 minecraft:log 3
setblock ~10~2~18 minecraft:log 3
setblock ~10~12~18 minecraft:wooden_slab 2
fill ~10~14~18 ~11~14~18 minecraft:stone_block_slab 1
setblock ~10~19~18 minecraft:log 3
fill ~10~20~18 ~10~21~18 minecraft:log 3
fill ~10~37~18 ~11~37~18 minecraft:log 3
setblock ~10~38~18 minecraft:log 3
fill ~10~44~18 ~10~44~19 minecraft:leaves2 1
setblock ~10~48~18 minecraft:leaves 3
setblock ~11~0~18 minecraft:log 3
setblock ~11~1~18 minecraft:log 3
fill ~11~3~18 ~12~3~18 minecraft:leaves 3
fill ~11~48~18 ~12~48~18 minecraft:log 3
fill ~12~0~18 ~12~0~19 minecraft:log 3
setblock ~12~1~18 minecraft:log 3
setblock ~12~2~18 minecraft:leaves 3
fill ~12~11~18 ~13~11~19 minecraft:double_wooden_slab 5
setblock ~12~14~18 minecraft:wool 10
fill ~12~47~18 ~13~47~18 minecraft:leaves 3
fill ~12~52~18 ~12~52~25 minecraft:leaves 3
fill ~13~0~18 ~13~1~18 minecraft:log 3
setblock ~13~12~18 minecraft:anvil 1
setblock ~13~13~18 minecraft:fence 2
fill ~13~14~18 ~14~14~18 minecraft:wool 6
setblock ~13~26~18 minecraft:leaves2 1
fill ~13~44~18 ~14~44~18 minecraft:leaves2 1
setblock ~13~45~18 minecraft:leaves2 1
fill ~14~0~18 ~15~0~18 minecraft:dirt 1
setblock ~14~2~18 minecraft:leaves 3
fill ~14~9~18 ~15~9~18 minecraft:log 3
setblock ~14~10~18 minecraft:leaves 3
setblock ~14~11~18 minecraft:leaves 3
setblock ~14~12~18 minecraft:bookshelf
fill ~14~18~18 ~14~18~19 minecraft:leaves 3
fill ~14~26~18 ~15~26~18 minecraft:leaves 3
fill ~14~43~18 ~15~43~18 minecraft:leaves2 1
fill ~14~49~18 ~15~49~18 minecraft:stone_block_slab 13
fill ~14~50~18 ~14~52~18 minecraft:jungle_stairs 7
setblock ~14~53~18 minecraft:leaves 3
fill ~15~10~18 ~17~10~18 minecraft:log 3
fill ~15~11~18 ~16~11~18 minecraft:log 3
setblock ~15~13~18 minecraft:shulker_box 9
fill ~15~14~18 ~16~14~18 minecraft:stone_block_slab 1
setblock ~15~24~18 minecraft:log 3
setblock ~15~27~18 minecraft:wooden_slab 3
setblock ~15~33~18 minecraft:leaves2 1
setblock ~15~35~18 minecraft:leaves2 1
setblock ~15~50~18 minecraft:trapdoor 1
fill ~16~0~18 ~17~0~18 minecraft:log 3
fill ~16~1~18 ~17~1~18 minecraft:leaves 3
fill ~16~9~18 ~16~9~20 minecraft:log 3
setblock ~16~12~18 minecraft:wooden_slab 2
fill ~16~24~18 ~18~24~18 minecraft:log 3
fill ~16~25~18 ~16~25~19 minecraft:leaves 3
fill ~16~26~18 ~18~26~19 minecraft:log 3
fill ~16~33~18 ~18~33~18 minecraft:leaves 3
setblock ~16~34~18 minecraft:leaves 3
fill ~16~43~18 ~18~44~18 minecraft:leaves 3
fill ~16~47~18 ~16~47~19 minecraft:leaves 3
fill ~16~49~18 ~17~49~20 minecraft:double_stone_block_slab 5
fill ~17~2~18 ~17~4~18 minecraft:leaves 3
setblock ~17~11~18 minecraft:wooden_slab 13
fill ~17~22~18 ~17~22~20 minecraft:log 3
setblock ~17~23~18 minecraft:log 3
fill ~17~25~18 ~18~25~18 minecraft:leaves 3
fill ~17~34~18 ~17~34~20 minecraft:log 3
setblock ~17~35~18 minecraft:log 3
fill ~17~37~18 ~17~38~18 minecraft:leaves 3
fill ~17~45~18 ~19~45~19 minecraft:leaves 3
fill ~18~1~18 ~18~3~20 minecraft:log 3
fill ~18~14~18 ~18~15~18 minecraft:leaves 3
fill ~18~19~18 ~18~19~19 minecraft:leaves 3
setblock ~18~20~18 minecraft:leaves 3
setblock ~18~22~18 minecraft:leaves 3
setblock ~18~27~18 minecraft:wooden_slab 3
fill ~18~34~18 ~18~35~18 minecraft:log 3
fill ~18~37~18 ~18~37~19 minecraft:log 3
fill ~18~42~18 ~19~42~18 minecraft:leaves 3
fill ~18~49~18 ~20~49~19 minecraft:stone_block_slab 13
fill ~18~54~18 ~19~54~18 minecraft:leaves2 1
setblock ~19~0~18 minecraft:log 3
setblock ~19~1~18 minecraft:log 3
setblock ~19~2~18 minecraft:log 3
setblock ~19~4~18 minecraft:leaves 3
fill ~19~5~18 ~19~6~18 minecraft:vine 1
fill ~19~7~18 ~19~13~18 minecraft:vine 9
fill ~19~14~18 ~19~15~19 minecraft:log 3
setblock ~19~16~18 minecraft:leaves 3
fill ~19~21~18 ~19~21~19 minecraft:leaves 3
setblock ~19~25~18 minecraft:wall_sign 5
setblock ~19~26~18 minecraft:leaves 3
setblock ~19~27~18 minecraft:double_wooden_slab 3
fill ~19~34~18 ~19~35~18 minecraft:log 3
setblock ~19~37~18 minecraft:log 3
fill ~19~44~18 ~24~44~18 minecraft:leaves 3
fill ~20~0~18 ~20~0~20 minecraft:log 3
fill ~20~1~18 ~21~1~18 minecraft:log 3
fill ~20~2~18 ~20~2~19 minecraft:log 3
setblock ~20~3~18 minecraft:leaves 3
fill ~20~13~18 ~20~13~19 minecraft:leaves 3
setblock ~20~15~18 minecraft:leaves 3
setblock ~20~27~18 minecraft:leaves 3
fill ~20~28~18 ~21~28~18 minecraft:wooden_slab 3
setblock ~20~35~18 minecraft:log 3
fill ~20~36~18 ~20~36~21 minecraft:log 3
fill ~20~37~18 ~20~37~19 minecraft:leaves 3
fill ~20~46~18 ~23~47~19 minecraft:leaves 3
fill ~20~54~18 ~24~54~20 minecraft:leaves 3
fill ~20~55~18 ~20~55~31 minecraft:leaves 3
fill ~21~0~18 ~23~0~18 minecraft:log 3
setblock ~21~2~18 minecraft:log 3
setblock ~21~3~18 minecraft:leaves2 1
fill ~21~6~18 ~21~13~18 minecraft:vine 2
setblock ~21~27~18 minecraft:leaves2 1
fill ~21~36~18 ~21~36~19 minecraft:leaves 3
fill ~21~45~18 ~21~45~19 minecraft:leaves 3
setblock ~21~50~18 minecraft:spruce_stairs 1
setblock ~21~55~18 minecraft:leaves2 1
setblock ~22~1~18 minecraft:log 3
setblock ~22~27~18 minecraft:double_wooden_slab 3
fill ~22~28~18 ~23~29~18 minecraft:vine 1
fill ~22~30~18 ~22~36~18 minecraft:vine 2
setblock ~23~1~18 minecraft:log 3
fill ~23~27~18 ~23~27~19 minecraft:wooden_slab 3
setblock ~23~30~18 minecraft:vine 1
setblock ~23~53~18 minecraft:leaves 3
setblock ~24~0~18 minecraft:dirt 1
setblock ~24~1~18 minecraft:red_flower 1
fill ~24~9~18 ~24~18~18 minecraft:vine 1
setblock ~24~22~18 minecraft:spruce_stairs 6
fill ~24~23~18 ~24~23~19 minecraft:log 0
setblock ~24~31~18 minecraft:spruce_stairs 2
setblock ~24~48~18 minecraft:leaves 3
setblock ~24~50~18 minecraft:wooden_slab 9
setblock ~24~53~18 minecraft:log 3
fill ~25~22~18 ~25~22~19 minecraft:planks 0
fill ~25~23~18 ~25~24~18 minecraft:planks 0
setblock ~25~26~18 minecraft:wooden_slab 11
fill ~25~27~18 ~25~28~18 minecraft:leaves 3
setblock ~25~29~18 minecraft:spruce_stairs 4
setblock ~25~30~18 minecraft:log 0
fill ~25~46~18 ~26~46~18 minecraft:leaves 3
fill ~25~51~18 ~26~51~19 minecraft:leaves2 1
fill ~25~53~18 ~25~53~29 minecraft:leaves 3
setblock ~26~18~18 minecraft:log 3
fill ~26~19~18 ~26~22~18 minecraft:log 0
fill ~26~26~18 ~26~28~18 minecraft:end_stone
setblock ~26~29~18 minecraft:log 0
fill ~26~43~18 ~26~43~19 minecraft:leaves2 1
fill ~26~45~18 ~28~45~19 minecraft:leaves 3
fill ~26~47~18 ~26~47~20 minecraft:leaves 3
fill ~26~50~18 ~27~50~18 minecraft:leaves 3
fill ~27~0~18 ~27~0~19 minecraft:log 3
setblock ~27~17~18 minecraft:leaves2 1
fill ~27~18~18 ~29~18~18 minecraft:log 3
setblock ~27~19~18 minecraft:log 3
fill ~27~20~18 ~27~21~18 minecraft:end_stone
setblock ~27~22~18 minecraft:planks 0
fill ~27~46~18 ~27~47~18 minecraft:leaves2 1
fill ~27~49~18 ~27~49~22 minecraft:leaves 3
fill ~28~0~18 ~29~0~22 minecraft:log 3
setblock ~28~17~18 minecraft:leaves 3
setblock ~28~19~18 minecraft:log 3
fill ~28~20~18 ~29~20~18 minecraft:log 3
fill ~28~37~18 ~28~38~18 minecraft:leaves2 1
fill ~28~39~18 ~28~40~18 minecraft:leaves 3
fill ~28~41~18 ~28~43~18 minecraft:leaves2 1
setblock ~29~1~18 minecraft:log 3
fill ~29~16~18 ~30~16~18 minecraft:leaves2 1
fill ~29~17~18 ~31~17~18 minecraft:leaves 3
fill ~29~19~18 ~29~19~19 minecraft:log 3
fill ~29~25~18 ~30~28~18 minecraft:vine 4
fill ~29~29~18 ~29~33~18 minecraft:vine 4
fill ~29~34~18 ~29~35~18 minecraft:leaves2 1
fill ~29~36~18 ~29~38~18 minecraft:leaves 3
setblock ~29~39~18 minecraft:leaves2 1
fill ~29~40~18 ~29~41~18 minecraft:leaves 3
fill ~29~43~18 ~30~43~18 minecraft:leaves2 1
setblock ~29~44~18 minecraft:leaves 3
fill ~29~45~18 ~30~45~18 minecraft:leaves2 1
setblock ~29~46~18 minecraft:leaves 3
fill ~30~18~18 ~31~18~18 minecraft:log 3
fill ~30~19~18 ~30~19~19 minecraft:log 3
fill ~30~23~18 ~30~24~18 minecraft:vine 4
setblock ~30~36~18 minecraft:leaves2 1
fill ~30~38~18 ~30~39~18 minecraft:leaves 3
setblock ~30~41~18 minecraft:leaves2 1
fill ~31~19~18 ~31~19~19 minecraft:log 3
fill ~31~21~18 ~32~25~18 minecraft:planks 0
fill ~31~30~18 ~31~33~18 minecraft:vine 2
setblock ~32~18~18 minecraft:leaves 3
fill ~32~19~18 ~32~20~18 minecraft:log 3
fill ~33~19~18 ~33~20~18 minecraft:leaves 3
fill ~1~16~19 ~1~19~19 minecraft:vine 8
fill ~2~19~19 ~3~19~19 minecraft:leaves 3
fill ~2~20~19 ~2~22~19 minecraft:vine 1
fill ~2~23~19 ~3~23~19 minecraft:leaves2 1
setblock ~2~25~19 minecraft:leaves2 1
fill ~3~0~19 ~4~0~19 minecraft:log 3
setblock ~3~20~19 minecraft:wooden_slab 11
setblock ~3~24~19 minecraft:leaves2 1
fill ~3~25~19 ~3~25~20 minecraft:dark_oak_stairs 0
fill ~3~26~19 ~3~26~20 minecraft:leaves2 1
fill ~3~44~19 ~3~45~19 minecraft:leaves 3
setblock ~4~16~19 minecraft:leaves 3
setblock ~4~18~19 minecraft:fence 5
fill ~4~19~19 ~8~20~19 minecraft:log 3
fill ~4~21~19 ~4~24~19 minecraft:planks 0
fill ~4~25~19 ~10~25~19 minecraft:dark_oak_stairs 2
setblock ~4~37~19 minecraft:leaves 3
fill ~4~43~19 ~4~43~22 minecraft:leaves 3
fill ~4~45~19 ~4~46~21 minecraft:leaves 3
setblock ~5~0~19 minecraft:log 3
fill ~5~1~19 ~5~1~20 minecraft:log 3
setblock ~5~2~19 minecraft:log 3
setblock ~5~16~19 minecraft:fence 5
fill ~5~18~19 ~8~18~19 minecraft:leaves 3
fill ~5~21~19 ~5~23~19 minecraft:log 3
setblock ~5~24~19 minecraft:planks 0
fill ~5~39~19 ~5~41~19 minecraft:log 0
fill ~5~47~19 ~6~47~19 minecraft:leaves 3
setblock ~6~0~19 minecraft:log 3
setblock ~6~2~19 minecraft:log 3
fill ~6~15~19 ~7~15~19 minecraft:fence 5
setblock ~6~16~19 minecraft:leaves 3
fill ~6~21~19 ~7~21~19 minecraft:birch_door 1
fill ~6~23~19 ~7~23~19 minecraft:stained_glass 12
fill ~6~24~19 ~7~24~19 minecraft:log 3
fill ~6~36~19 ~7~36~19 minecraft:leaves 3
fill ~6~37~19 ~6~37~23 minecraft:leaves 3
fill ~6~38~19 ~6~38~20 minecraft:log 0
setblock ~6~43~19 minecraft:log 3
fill ~6~49~19 ~7~49~22 minecraft:leaves 3
setblock ~7~0~19 minecraft:log 3
setblock ~7~16~19 minecraft:log 3
setblock ~7~35~19 minecraft:leaves 3
setblock ~7~37~19 minecraft:log 3
fill ~7~43~19 ~7~43~22 minecraft:leaves 3
fill ~8~0~19 ~8~1~19 minecraft:log 3
setblock ~8~2~19 minecraft:log 3
fill ~8~3~19 ~10~3~19 minecraft:log 3
fill ~8~15~19 ~9~15~19 minecraft:leaves 3
fill ~8~17~19 ~9~17~19 minecraft:leaves 3
fill ~8~21~19 ~8~23~19 minecraft:log 3
fill ~8~24~19 ~9~24~19 minecraft:planks 0
fill ~8~38~19 ~9~38~19 minecraft:log 3
setblock ~8~43~19 minecraft:log 3
fill ~8~44~19 ~9~44~19 minecraft:leaves2 1
setblock ~8~46~19 minecraft:leaves2 1
fill ~8~50~19 ~8~50~20 minecraft:leaves2 1
setblock ~9~1~19 minecraft:log 3
setblock ~9~23~19 minecraft:planks 0
setblock ~9~26~19 minecraft:leaves 3
fill ~9~37~19 ~9~37~20 minecraft:log 3
fill ~9~43~19 ~11~43~19 minecraft:leaves 3
fill ~9~48~19 ~12~48~19 minecraft:log 3
fill ~9~50~19 ~9~50~23 minecraft:leaves 3
setblock ~9~51~19 minecraft:leaves2 1
fill ~10~0~19 ~10~0~20 minecraft:log 3
setblock ~10~1~19 minecraft:log 3
fill ~10~2~19 ~11~2~19 minecraft:log 3
fill ~10~11~19 ~11~11~19 minecraft:wooden_slab 13
fill ~10~16~19 ~11~16~19 minecraft:leaves 3
setblock ~10~19~19 minecraft:leaves 3
setblock ~10~20~19 minecraft:wooden_slab 11
fill ~10~23~19 ~10~24~19 minecraft:leaves2 1
setblock ~10~26~19 minecraft:fence 5
setblock ~10~37~19 minecraft:log 3
fill ~10~38~19 ~10~38~20 minecraft:log 3
fill ~10~51~19 ~10~51~20 minecraft:leaves 3
fill ~11~0~19 ~11~1~19 minecraft:log 3
fill ~11~3~19 ~11~3~20 minecraft:log 3
fill ~11~4~19 ~13~4~19 minecraft:leaves 3
setblock ~11~37~19 minecraft:log 3
setblock ~11~44~19 minecraft:leaves2 1
fill ~11~49~19 ~11~49~20 minecraft:log 3
fill ~12~1~19 ~14~1~19 minecraft:log 3
setblock ~12~2~19 minecraft:log 3
fill ~12~3~19 ~13~3~19 minecraft:leaves 3
setblock ~12~5~19 minecraft:leaves2 1
fill ~12~12~19 ~13~12~19 minecraft:wooden_slab 2
fill ~12~14~19 ~14~14~19 minecraft:stone_block_slab 1
setblock ~12~15~19 minecraft:leaves 3
setblock ~12~37~19 minecraft:log 3
fill ~12~44~19 ~14~44~19 minecraft:leaves 3
fill ~12~46~19 ~13~46~19 minecraft:leaves 3
fill ~12~47~19 ~12~47~20 minecraft:log 3
fill ~12~49~19 ~12~49~26 minecraft:leaves 3
fill ~13~0~19 ~14~0~19 minecraft:log 3
setblock ~13~2~19 minecraft:leaves 3
setblock ~13~15~19 minecraft:leaves 3
setblock ~13~18~19 minecraft:leaves 3
fill ~13~19~19 ~14~19~19 minecraft:leaves2 1
fill ~13~31~19 ~14~31~19 minecraft:leaves 3
setblock ~13~33~19 minecraft:leaves 3
setblock ~13~40~19 minecraft:wooden_button 4
fill ~13~45~19 ~13~45~20 minecraft:leaves 3
setblock ~13~47~19 minecraft:leaves 3
setblock ~13~48~19 minecraft:log 3
fill ~13~50~19 ~13~50~22 minecraft:leaves2 1
fill ~13~51~19 ~13~52~25 minecraft:leaves 3
fill ~14~2~19 ~14~2~27 minecraft:log 3
setblock ~14~11~19 minecraft:leaves2 1
setblock ~14~12~19 minecraft:shulker_box 11
fill ~14~28~19 ~14~28~20 minecraft:leaves 3
setblock ~14~30~19 minecraft:log 3
setblock ~14~32~19 minecraft:leaves 3
setblock ~14~33~19 minecraft:leaves2 1
setblock ~14~36~19 minecraft:leaves2 1
fill ~14~37~19 ~16~37~19 minecraft:log 3
fill ~14~39~19 ~14~41~19 minecraft:log 0
setblock ~14~47~19 minecraft:log 3
fill ~14~49~19 ~14~49~27 minecraft:double_stone_block_slab 5
fill ~14~50~19 ~14~53~22 minecraft:carpet 12
setblock ~15~0~19 minecraft:log 3
fill ~15~1~19 ~15~3~19 minecraft:leaves 3
setblock ~15~9~19 minecraft:log 3
fill ~15~11~19 ~16~11~19 minecraft:leaves 3
setblock ~15~12~19 minecraft:leaves 3
setblock ~15~13~19 minecraft:log 3
fill ~15~19~19 ~16~19~19 minecraft:leaves 3
setblock ~15~20~19 minecraft:leaves2 1
fill ~15~23~19 ~15~24~20 minecraft:leaves 3
fill ~15~26~19 ~15~26~20 minecraft:leaves 3
setblock ~15~27~19 minecraft:leaves 3
fill ~15~28~19 ~16~28~20 minecraft:log 3
setblock ~15~29~19 minecraft:log 3
fill ~15~30~19 ~17~30~20 minecraft:log 3
setblock ~15~31~19 minecraft:log 3
fill ~15~32~19 ~15~32~21 minecraft:log 3
fill ~15~33~19 ~16~33~19 minecraft:leaves 3
fill ~15~34~19 ~15~34~20 minecraft:leaves 3
setblock ~15~35~19 minecraft:leaves 3
fill ~15~42~19 ~16~42~19 minecraft:leaves 3
setblock ~15~43~19 minecraft:leaves 3
setblock ~15~45~19 minecraft:leaves 3
fill ~15~46~19 ~15~47~21 minecraft:log 3
setblock ~15~49~19 minecraft:stone_block_slab 13
setblock ~16~0~19 minecraft:log 3
fill ~16~1~19 ~16~1~20 minecraft:log 3
fill ~16~2~19 ~16~5~19 minecraft:leaves 3
setblock ~16~8~19 minecraft:log 3
setblock ~16~10~19 minecraft:log 3
fill ~16~12~19 ~16~13~20 minecraft:log 3
setblock ~16~14~19 minecraft:log 3
fill ~16~20~19 ~17~20~19 minecraft:leaves 3
setblock ~16~21~19 minecraft:leaves 3
setblock ~16~22~19 minecraft:log 3
fill ~16~23~19 ~18~23~20 minecraft:log 3
setblock ~16~24~19 minecraft:leaves 3
setblock ~16~27~19 minecraft:log 3
fill ~16~29~19 ~17~29~20 minecraft:log 3
setblock ~16~34~19 minecraft:log 3
fill ~16~35~19 ~16~35~20 minecraft:log 3
fill ~16~36~19 ~18~36~19 minecraft:log 3
fill ~16~38~19 ~19~38~20 minecraft:log 3
fill ~16~39~19 ~17~40~20 minecraft:log 3
setblock ~16~43~19 minecraft:glowstone
fill ~16~44~19 ~22~44~19 minecraft:leaves 3
fill ~16~46~19 ~19~46~19 minecraft:leaves 3
setblock ~17~0~19 minecraft:log 3
setblock ~17~1~19 minecraft:log 3
fill ~17~2~19 ~17~6~20 minecraft:log 3
setblock ~17~9~19 minecraft:log 3
fill ~17~10~19 ~17~11~20 minecraft:log 3
setblock ~17~13~19 minecraft:log 3
fill ~17~14~19 ~17~15~20 minecraft:log 3
fill ~17~21~19 ~17~21~20 minecraft:log 3
fill ~17~24~19 ~18~24~19 minecraft:leaves 3
setblock ~17~25~19 minecraft:leaves 3
setblock ~17~27~19 minecraft:log 3
setblock ~17~28~19 minecraft:log 3
fill ~17~32~19 ~18~32~19 minecraft:leaves 3
fill ~17~33~19 ~17~33~20 minecraft:log 3
fill ~17~35~19 ~18~35~19 minecraft:log 3
setblock ~17~37~19 minecraft:log 3
fill ~17~41~19 ~17~43~20 minecraft:log 3
fill ~18~4~19 ~19~4~20 minecraft:log 3
fill ~18~5~19 ~18~7~20 minecraft:log 3
fill ~18~8~19 ~18~9~19 minecraft:leaves 3
setblock ~18~10~19 minecraft:log 3
fill ~18~13~19 ~19~13~19 minecraft:leaves 3
setblock ~18~14~19 minecraft:log 3
fill ~18~15~19 ~18~17~20 minecraft:log 3
setblock ~18~20~19 minecraft:glowstone
setblock ~18~21~19 minecraft:log 3
fill ~18~22~19 ~18~22~20 minecraft:log 3
fill ~18~25~19 ~19~25~19 minecraft:leaves2 1
setblock ~18~27~19 minecraft:glowstone
fill ~18~28~19 ~18~28~20 minecraft:log 3
fill ~18~29~19 ~19~29~19 minecraft:leaves 3
setblock ~18~30~19 minecraft:leaves 3
setblock ~18~33~19 minecraft:leaves 3
fill ~18~34~19 ~18~34~20 minecraft:log 3
setblock ~18~39~19 minecraft:log 3
fill ~18~40~19 ~18~40~20 minecraft:log 3
fill ~18~41~19 ~20~41~19 minecraft:leaves 3
setblock ~18~42~19 minecraft:leaves 3
setblock ~18~43~19 minecraft:log 3
setblock ~18~54~19 minecraft:leaves2 1
setblock ~19~0~19 minecraft:log 3
fill ~19~1~19 ~19~1~20 minecraft:log 3
setblock ~19~2~19 minecraft:log 3
fill ~19~3~19 ~19~3~20 minecraft:log 3
fill ~19~5~19 ~21~5~19 minecraft:leaves 3
fill ~19~6~19 ~19~7~19 minecraft:leaves 3
fill ~19~12~19 ~20~12~19 minecraft:leaves 3
fill ~19~16~19 ~19~16~20 minecraft:log 3
fill ~19~19~19 ~19~20~19 minecraft:leaves 3
setblock ~19~22~19 minecraft:leaves 3
setblock ~19~26~19 minecraft:log 3
setblock ~19~27~19 minecraft:log 3
setblock ~19~28~19 minecraft:log 3
setblock ~19~35~19 minecraft:log 3
fill ~19~36~19 ~19~36~20 minecraft:log 3
setblock ~19~37~19 minecraft:log 3
fill ~19~39~19 ~19~39~20 minecraft:log 3
setblock ~19~42~19 minecraft:log 3
fill ~19~43~19 ~21~43~19 minecraft:leaves 3
setblock ~19~47~19 minecraft:leaves 3
fill ~19~54~19 ~19~55~19 minecraft:leaves 3
setblock ~20~1~19 minecraft:log 3
setblock ~20~3~19 minecraft:log 3
fill ~20~4~19 ~21~4~19 minecraft:leaves 3
setblock ~20~6~19 minecraft:leaves2 1
setblock ~20~14~19 minecraft:leaves 3
setblock ~20~15~19 minecraft:log 3
fill ~20~20~19 ~20~21~20 minecraft:leaves 3
fill ~20~22~19 ~21~22~19 minecraft:vine 1
fill ~20~23~19 ~20~25~19 minecraft:vine 1
setblock ~20~26~19 minecraft:leaves2 1
setblock ~20~27~19 minecraft:wooden_slab 9
fill ~20~28~19 ~21~28~19 minecraft:wooden_slab 11
fill ~20~34~19 ~20~35~19 minecraft:log 3
fill ~20~38~19 ~20~40~19 minecraft:leaves 3
setblock ~20~42~19 minecraft:leaves 3
fill ~20~48~19 ~21~48~19 minecraft:leaves 3
fill ~21~0~19 ~21~1~19 minecraft:log 3
fill ~21~2~19 ~22~2~19 minecraft:leaves 3
setblock ~21~3~19 minecraft:leaves 3
fill ~21~9~19 ~21~12~19 minecraft:vine 2
fill ~21~13~19 ~21~15~19 minecraft:vine 3
setblock ~21~16~19 minecraft:vine 2
fill ~21~17~19 ~21~18~20 minecraft:vine 3
fill ~21~19~19 ~21~21~19 minecraft:vine 3
fill ~21~27~19 ~22~27~19 minecraft:leaves 3
fill ~21~34~19 ~21~35~19 minecraft:log 3
setblock ~21~39~19 minecraft:leaves 3
fill ~21~55~19 ~21~55~24 minecraft:leaves 3
fill ~22~0~19 ~22~0~21 minecraft:log 3
setblock ~22~3~19 minecraft:leaves2 1
fill ~22~28~19 ~22~29~19 minecraft:leaves 3
fill ~22~32~19 ~22~34~19 minecraft:vine 2
setblock ~22~36~19 minecraft:wooden_slab 1
fill ~22~45~19 ~23~45~20 minecraft:leaves 3
setblock ~23~0~19 minecraft:dirt 1
fill ~23~1~19 ~23~3~19 minecraft:vine 2
fill ~23~26~19 ~23~26~20 minecraft:wooden_slab 11
fill ~23~29~19 ~23~30~19 minecraft:leaves 3
fill ~23~48~19 ~23~48~29 minecraft:leaves 3
fill ~24~0~19 ~24~0~20 minecraft:log 3
setblock ~24~17~19 minecraft:leaves 3
setblock ~24~18~19 minecraft:barrier
setblock ~24~19~19 minecraft:spruce_stairs 6
fill ~24~20~19 ~24~22~19 minecraft:log 0
setblock ~24~26~19 minecraft:double_wooden_slab 3
setblock ~24~31~19 minecraft:wooden_slab 9
setblock ~24~32~19 minecraft:wooden_slab 1
fill ~24~46~19 ~24~47~27 minecraft:leaves 3
setblock ~24~48~19 minecraft:leaves2 1
setblock ~24~50~19 minecraft:spruce_stairs 6
setblock ~24~53~19 minecraft:spruce_stairs 7
fill ~25~0~19 ~25~0~20 minecraft:log 3
fill ~25~17~19 ~25~17~21 minecraft:log 3
setblock ~25~18~19 minecraft:log 3
setblock ~25~19~19 minecraft:planks 0
fill ~25~20~19 ~25~21~19 minecraft:stained_glass_pane 0
fill ~25~26~19 ~25~26~20 minecraft:wooden_slab 3
setblock ~25~29~19 minecraft:leaves 3
setblock ~25~30~19 minecraft:wooden_slab 9
setblock ~25~31~19 minecraft:log 0
fill ~25~46~19 ~26~46~19 minecraft:leaves2 1
fill ~26~0~19 ~26~0~24 minecraft:log 3
fill ~26~16~19 ~26~16~20 minecraft:leaves2 1
setblock ~26~17~19 minecraft:log 3
fill ~26~18~19 ~26~18~21 minecraft:log 3
setblock ~26~19~19 minecraft:log 3
fill ~26~20~19 ~26~20~21 minecraft:log 0
setblock ~26~21~19 minecraft:log 0
setblock ~26~26~19 minecraft:wooden_slab 9
setblock ~26~27~19 minecraft:dark_oak_door 2
setblock ~26~29~19 minecraft:end_stone
setblock ~26~30~19 minecraft:log 0
setblock ~26~44~19 minecraft:leaves2 1
fill ~26~50~19 ~26~50~23 minecraft:leaves 3
setblock ~27~1~19 minecraft:log 3
fill ~27~16~19 ~28~16~19 minecraft:leaves 3
setblock ~27~17~19 minecraft:leaves 3
setblock ~27~18~19 minecraft:log 3
fill ~27~19~19 ~27~20~19 minecraft:log 3
setblock ~27~46~19 minecraft:leaves 3
fill ~27~47~19 ~28~47~19 minecraft:leaves2 1
setblock ~28~1~19 minecraft:log 3
setblock ~28~17~19 minecraft:log 3
fill ~28~18~19 ~28~18~21 minecraft:log 3
setblock ~28~19~19 minecraft:log 3
setblock ~28~20~19 minecraft:log 3
fill ~29~17~19 ~30~17~19 minecraft:leaves 3
fill ~29~18~19 ~29~18~20 minecraft:log 3
setblock ~29~20~19 minecraft:log 3
setblock ~29~43~19 minecraft:leaves 3
fill ~29~44~19 ~29~45~19 minecraft:leaves2 1
setblock ~30~0~19 minecraft:dirt 1
setblock ~30~1~19 minecraft:red_flower 1
setblock ~30~18~19 minecraft:log 3
fill ~30~20~19 ~31~20~19 minecraft:log 3
setblock ~31~18~19 minecraft:leaves 3
setblock ~32~18~19 minecraft:leaves2 1
fill ~32~19~19 ~32~20~19 minecraft:leaves 3
setblock ~33~13~19 minecraft:trip_wire 0
fill ~33~14~19 ~33~20~19 minecraft:vine 2
setblock ~1~16~20 minecraft:trip_wire 0
fill ~1~17~20 ~1~21~20 minecraft:vine 9
fill ~1~22~20 ~1~24~20 minecraft:vine 1
setblock ~1~25~20 minecraft:leaves2 1
setblock ~2~0~20 minecraft:log 3
setblock ~2~19~20 minecraft:leaves 3
setblock ~2~20~20 minecraft:wooden_slab 11
fill ~2~21~20 ~2~22~20 minecraft:leaves 3
setblock ~2~23~20 minecraft:leaves 3
setblock ~2~25~20 minecraft:dark_oak_stairs 2
setblock ~2~26~20 minecraft:leaves2 1
setblock ~3~17~20 minecraft:leaves 3
fill ~3~18~20 ~3~20~20 minecraft:log 3
fill ~3~21~20 ~3~21~21 minecraft:planks 0
fill ~3~22~20 ~3~24~20 minecraft:planks 0
setblock ~3~45~20 minecraft:leaves 3
fill ~4~0~20 ~5~0~20 minecraft:log 3
setblock ~4~1~20 minecraft:log 3
setblock ~4~16~20 minecraft:log 3
fill ~4~17~20 ~4~18~20 minecraft:log 3
fill ~4~20~20 ~8~20~20 minecraft:planks 0
setblock ~4~22~20 minecraft:wooden_slab 9
setblock ~4~24~20 minecraft:ladder 3
fill ~4~25~20 ~9~25~22 minecraft:wooden_slab 13
setblock ~4~26~20 minecraft:leaves2 1
fill ~4~47~20 ~5~47~20 minecraft:leaves 3
fill ~5~16~20 ~7~16~20 minecraft:log 3
fill ~5~17~20 ~7~17~20 minecraft:leaves 3
setblock ~5~22~20 minecraft:spruce_stairs 7
setblock ~5~24~20 minecraft:wooden_button 3
fill ~5~39~20 ~5~40~20 minecraft:stonebrick 0
fill ~5~41~20 ~5~41~21 minecraft:log 0
setblock ~5~49~20 minecraft:leaves 3
fill ~6~0~20 ~7~0~20 minecraft:log 3
setblock ~6~1~20 minecraft:log 3
setblock ~6~15~20 minecraft:log 3
setblock ~6~19~20 minecraft:leaves2 1
fill ~6~24~20 ~7~24~20 minecraft:trapdoor 2
fill ~6~39~20 ~6~40~21 minecraft:furnace 5
fill ~6~43~20 ~6~44~20 minecraft:leaves 3
setblock ~7~14~20 minecraft:leaves 3
fill ~7~15~20 ~11~15~20 minecraft:log 3
setblock ~7~26~20 minecraft:fence 5
fill ~7~36~20 ~7~37~20 minecraft:leaves 3
setblock ~7~38~20 minecraft:log 3
fill ~7~39~20 ~13~39~20 minecraft:carpet 12
fill ~7~48~20 ~7~48~23 minecraft:leaves 3
setblock ~7~50~20 minecraft:leaves2 1
setblock ~8~0~20 minecraft:log 3
setblock ~8~1~20 minecraft:log 3
setblock ~8~16~20 minecraft:leaves 3
fill ~8~19~20 ~8~19~23 minecraft:leaves 3
setblock ~8~22~20 minecraft:spruce_stairs 7
setblock ~8~23~20 minecraft:heavy_weighted_pressure_plate 0
setblock ~8~24~20 minecraft:wooden_button 3
fill ~8~38~20 ~9~38~20 minecraft:log 3
fill ~8~43~20 ~9~43~20 minecraft:leaves 3
setblock ~9~0~20 minecraft:log 3
setblock ~9~1~20 minecraft:log 3
fill ~9~16~20 ~11~16~20 minecraft:log 3
setblock ~9~17~20 minecraft:log 3
setblock ~9~18~20 minecraft:leaves 3
setblock ~9~19~20 minecraft:planks 0
setblock ~9~20~20 minecraft:wooden_slab 11
setblock ~9~21~20 minecraft:cauldron 0
setblock ~9~22~20 minecraft:wooden_slab 9
setblock ~9~24~20 minecraft:ladder 3
setblock ~9~26~20 minecraft:leaves2 1
fill ~9~48~20 ~9~48~21 minecraft:leaves 3
fill ~10~1~20 ~10~3~20 minecraft:log 3
setblock ~10~17~20 minecraft:leaves 3
fill ~10~19~20 ~10~20~20 minecraft:log 3
fill ~10~21~20 ~10~24~20 minecraft:planks 0
setblock ~10~25~20 minecraft:dark_oak_stairs 1
fill ~10~26~20 ~10~26~21 minecraft:leaves 3
setblock ~10~27~20 minecraft:fence 5
fill ~10~37~20 ~10~37~21 minecraft:log 3
setblock ~10~43~20 minecraft:log 3
fill ~10~48~20 ~14~48~20 minecraft:log 3
fill ~10~50~20 ~11~50~25 minecraft:leaves 3
fill ~10~52~20 ~11~52~20 minecraft:leaves2 1
fill ~11~0~20 ~11~2~20 minecraft:log 3
fill ~11~4~20 ~11~4~21 minecraft:leaves 3
setblock ~11~20~20 minecraft:wooden_slab 11
setblock ~11~24~20 minecraft:web
setblock ~11~25~20 minecraft:dark_oak_stairs 2
setblock ~11~31~20 minecraft:leaves2 1
fill ~11~37~20 ~11~37~21 minecraft:log 3
fill ~11~38~20 ~13~38~20 minecraft:log 0
setblock ~11~43~20 minecraft:leaves 3
fill ~12~1~20 ~13~1~20 minecraft:log 3
fill ~12~2~20 ~12~2~21 minecraft:log 3
setblock ~12~3~20 minecraft:leaves 3
fill ~12~4~20 ~13~4~20 minecraft:leaves2 1
fill ~12~11~20 ~13~11~20 minecraft:wooden_slab 13
fill ~12~14~20 ~12~15~20 minecraft:log 3
setblock ~12~17~20 minecraft:leaves2 1
fill ~12~30~20 ~13~30~20 minecraft:leaves 3
fill ~12~31~20 ~12~31~21 minecraft:leaves 3
fill ~12~32~20 ~13~32~20 minecraft:leaves 3
setblock ~12~37~20 minecraft:log 3
fill ~12~45~20 ~12~45~29 minecraft:leaves 3
setblock ~12~46~20 minecraft:leaves 3
setblock ~12~50~20 minecraft:leaves2 1
setblock ~13~0~20 minecraft:log 3
setblock ~13~2~20 minecraft:log 3
setblock ~13~3~20 minecraft:log 3
setblock ~13~5~20 minecraft:leaves2 1
setblock ~13~13~20 minecraft:log 3
setblock ~13~14~20 minecraft:log 3
setblock ~13~15~20 minecraft:log 3
fill ~13~16~20 ~13~18~21 minecraft:leaves 3
fill ~13~19~20 ~13~21~20 minecraft:leaves 3
fill ~13~24~20 ~13~25~20 minecraft:leaves2 1
fill ~13~28~20 ~13~29~20 minecraft:leaves 3
fill ~13~31~20 ~14~31~20 minecraft:log 3
setblock ~13~33~20 minecraft:log 3
fill ~13~37~20 ~14~37~20 minecraft:log 3
fill ~13~44~20 ~14~44~20 minecraft:leaves 3
fill ~13~46~20 ~13~46~22 minecraft:log 3
setblock ~13~47~20 minecraft:log 3
fill ~14~0~20 ~14~0~21 minecraft:log 3
fill ~14~1~20 ~15~1~20 minecraft:log 3
setblock ~14~3~20 minecraft:log 3
fill ~14~4~20 ~16~4~20 minecraft:log 3
fill ~14~6~20 ~14~7~20 minecraft:leaves 3
fill ~14~10~20 ~14~11~20 minecraft:leaves 3
setblock ~14~12~20 minecraft:leaves2 1
fill ~14~13~20 ~15~13~20 minecraft:log 3
setblock ~14~15~20 minecraft:leaves 3
setblock ~14~17~20 minecraft:log 3
fill ~14~18~20 ~14~18~26 minecraft:log 3
fill ~14~19~20 ~14~19~21 minecraft:log 3
fill ~14~20~20 ~14~20~26 minecraft:log 3
fill ~14~21~20 ~15~22~20 minecraft:leaves 3
fill ~14~24~20 ~14~27~20 minecraft:leaves 3
setblock ~14~29~20 minecraft:log 3
setblock ~14~30~20 minecraft:log 3
setblock ~14~32~20 minecraft:log 3
fill ~14~33~20 ~14~36~20 minecraft:leaves 3
setblock ~14~38~20 minecraft:log 3
setblock ~14~39~20 minecraft:stone_brick_stairs 4
setblock ~14~40~20 minecraft:dispenser 4
fill ~14~41~20 ~14~43~20 minecraft:leaves 3
fill ~14~45~20 ~14~46~20 minecraft:log 3
setblock ~15~0~20 minecraft:log 3
fill ~15~2~20 ~16~3~20 minecraft:log 3
fill ~15~5~20 ~16~8~20 minecraft:log 3
fill ~15~9~20 ~15~12~20 minecraft:log 3
fill ~15~14~20 ~16~14~20 minecraft:log 3
setblock ~15~15~20 minecraft:log 3
fill ~15~17~20 ~15~18~20 minecraft:log 3
setblock ~15~19~20 minecraft:leaves 3
fill ~15~27~20 ~19~27~20 minecraft:log 3
fill ~15~29~20 ~15~29~21 minecraft:log 3
fill ~15~31~20 ~19~31~20 minecraft:log 3
fill ~15~33~20 ~16~33~20 minecraft:log 3
setblock ~15~36~20 minecraft:log 3
fill ~15~37~20 ~20~37~20 minecraft:log 3
fill ~15~38~20 ~15~45~21 minecraft:log 3
fill ~15~48~20 ~21~48~20 minecraft:log 3
fill ~15~49~20 ~15~49~21 minecraft:double_stone_block_slab 5
fill ~16~0~20 ~17~0~20 minecraft:log 3
fill ~16~10~20 ~16~11~20 minecraft:log 3
fill ~16~15~20 ~16~22~20 minecraft:log 3
fill ~16~24~20 ~16~26~20 minecraft:log 3
fill ~16~32~20 ~19~32~20 minecraft:log 3
setblock ~16~34~20 minecraft:log 3
fill ~16~36~20 ~18~36~20 minecraft:log 3
fill ~16~41~20 ~16~47~20 minecraft:log 3
fill ~16~50~20 ~16~50~21 minecraft:bookshelf
fill ~16~51~20 ~16~51~22 minecraft:carpet 0
fill ~16~54~20 ~16~54~32 minecraft:leaves 3
setblock ~17~1~20 minecraft:log 3
fill ~17~7~20 ~17~9~20 minecraft:log 3
fill ~17~12~20 ~20~13~20 minecraft:log 3
fill ~17~16~20 ~17~17~20 minecraft:log 3
fill ~17~18~20 ~18~18~20 minecraft:log 3
fill ~17~19~20 ~17~20~20 minecraft:log 3
fill ~17~24~20 ~18~24~20 minecraft:log 3
fill ~17~25~20 ~19~26~20 minecraft:log 3
setblock ~17~28~20 minecraft:log 3
fill ~17~35~20 ~21~35~20 minecraft:log 3
fill ~17~44~20 ~17~45~20 minecraft:log 3
fill ~17~46~20 ~17~47~20 minecraft:log 3
fill ~17~50~20 ~17~50~22 minecraft:trapdoor 1
fill ~17~54~20 ~19~54~20 minecraft:leaves 3
fill ~18~8~20 ~20~11~20 minecraft:log 3
fill ~18~14~20 ~20~14~20 minecraft:log 3
fill ~18~19~20 ~19~19~20 minecraft:log 3
fill ~18~20~20 ~18~21~20 minecraft:log 3
fill ~18~29~20 ~19~30~20 minecraft:log 3
fill ~18~33~20 ~19~33~20 minecraft:log 3
setblock ~18~39~20 minecraft:log 3
fill ~18~41~20 ~20~41~20 minecraft:log 3
fill ~18~42~20 ~18~45~20 minecraft:log 3
fill ~18~46~20 ~19~46~20 minecraft:log 3
fill ~18~47~20 ~21~47~20 minecraft:log 3
fill ~18~49~20 ~19~49~20 minecraft:double_stone_block_slab 5
fill ~18~55~20 ~19~55~20 minecraft:leaves 3
setblock ~19~0~20 minecraft:log 3
fill ~19~2~20 ~22~2~20 minecraft:log 3
fill ~19~5~20 ~20~5~20 minecraft:log 3
fill ~19~6~20 ~19~7~20 minecraft:log 3
fill ~19~15~20 ~20~15~20 minecraft:log 3
fill ~19~17~20 ~19~18~20 minecraft:log 3
setblock ~19~20~20 minecraft:log 3
fill ~19~21~20 ~19~24~20 minecraft:log 3
setblock ~19~28~20 minecraft:log 3
setblock ~19~34~20 minecraft:log 3
setblock ~19~40~20 minecraft:log 3
setblock ~19~42~20 minecraft:log 3
fill ~19~43~20 ~21~44~20 minecraft:log 3
fill ~19~45~20 ~20~45~20 minecraft:log 3
fill ~19~50~20 ~19~50~22 minecraft:wall_sign 4
fill ~19~56~20 ~19~56~21 minecraft:leaves 3
fill ~20~1~20 ~21~1~21 minecraft:log 3
fill ~20~3~20 ~21~3~21 minecraft:log 3
fill ~20~4~20 ~20~4~21 minecraft:log 3
setblock ~20~6~20 minecraft:leaves 3
setblock ~20~7~20 minecraft:log 3
fill ~20~16~20 ~20~16~21 minecraft:log 3
setblock ~20~17~20 minecraft:log 3
fill ~20~18~20 ~20~18~21 minecraft:log 3
setblock ~20~19~20 minecraft:leaves 3
setblock ~20~25~20 minecraft:leaves 3
setblock ~20~26~20 minecraft:log 3
setblock ~20~27~20 minecraft:log 3
setblock ~20~28~20 minecraft:log 3
fill ~20~29~20 ~21~29~20 minecraft:wooden_slab 3
fill ~20~32~20 ~20~33~20 minecraft:leaves 3
setblock ~20~34~20 minecraft:log 3
fill ~20~38~20 ~20~39~21 minecraft:log 3
setblock ~20~40~20 minecraft:log 3
fill ~20~42~20 ~21~42~21 minecraft:log 3
fill ~20~46~20 ~21~46~21 minecraft:log 3
fill ~20~49~20 ~22~49~20 minecraft:stone_block_slab 13
fill ~20~50~20 ~21~50~20 minecraft:sandstone_stairs 7
setblock ~20~51~20 minecraft:carpet 13
fill ~20~56~20 ~20~56~25 minecraft:leaves 3
setblock ~21~0~20 minecraft:log 3
fill ~21~4~20 ~22~4~20 minecraft:leaves 3
setblock ~21~5~20 minecraft:leaves 3
setblock ~21~6~20 minecraft:leaves2 1
setblock ~21~7~20 minecraft:leaves 3
fill ~21~8~20 ~21~10~20 minecraft:vine 1
fill ~21~15~20 ~21~15~21 minecraft:leaves 3
setblock ~21~16~20 minecraft:vine 3
fill ~21~19~20 ~21~21~20 minecraft:vine 2
fill ~21~22~20 ~21~22~21 minecraft:leaves 3
fill ~21~23~20 ~21~25~20 minecraft:vine 2
fill ~21~26~20 ~21~28~20 minecraft:leaves 3
setblock ~21~33~20 minecraft:leaves 3
fill ~21~34~20 ~21~34~26 minecraft:log 3
setblock ~21~36~20 minecraft:log 3
setblock ~21~37~20 minecraft:log 3
setblock ~21~38~20 minecraft:log 3
fill ~21~39~20 ~21~39~27 minecraft:log 3
setblock ~21~45~20 minecraft:log 3
setblock ~21~51~20 minecraft:carpet 8
setblock ~22~1~20 minecraft:log 3
setblock ~22~3~20 minecraft:leaves 3
fill ~22~5~20 ~22~7~20 minecraft:vine 2
setblock ~22~9~20 minecraft:vine 2
fill ~22~10~20 ~22~15~20 minecraft:vine 3
fill ~22~16~20 ~23~16~20 minecraft:vine 1
fill ~22~17~20 ~22~19~20 minecraft:vine 1
fill ~22~27~20 ~22~28~20 minecraft:leaves2 1
fill ~22~29~20 ~22~29~21 minecraft:double_wooden_slab 3
setblock ~22~33~20 minecraft:trip_wire 0
fill ~22~34~20 ~22~35~20 minecraft:vine 2
setblock ~22~36~20 minecraft:double_wooden_slab 1
setblock ~22~37~20 minecraft:log 3
fill ~22~38~20 ~22~39~22 minecraft:leaves 3
fill ~22~42~20 ~22~44~20 minecraft:leaves 3
fill ~22~46~20 ~23~47~22 minecraft:leaves 3
fill ~22~50~20 ~22~50~22 minecraft:wall_sign 5
setblock ~22~55~20 minecraft:leaves2 1
setblock ~23~0~20 minecraft:log 3
setblock ~23~1~20 minecraft:log 3
fill ~23~2~20 ~23~3~20 minecraft:vine 3
setblock ~23~4~20 minecraft:vine 2
fill ~23~9~20 ~23~11~21 minecraft:vine 1
fill ~23~12~20 ~23~15~20 minecraft:vine 1
fill ~23~17~20 ~23~17~21 minecraft:leaves 3
setblock ~23~27~20 minecraft:leaves 3
setblock ~23~28~20 minecraft:leaves2 1
setblock ~23~29~20 minecraft:wooden_slab 11
fill ~23~30~20 ~24~30~20 minecraft:leaves 3
setblock ~23~36~20 minecraft:wooden_slab 1
setblock ~23~43~20 minecraft:leaves2 1
setblock ~23~44~20 minecraft:leaves 3
setblock ~23~49~20 minecraft:double_stone_block_slab 5
setblock ~23~50~20 minecraft:spruce_stairs 3
setblock ~24~1~20 minecraft:vine 3
setblock ~24~2~20 minecraft:vine 1
fill ~24~16~20 ~25~16~21 minecraft:leaves 3
fill ~24~17~20 ~24~18~20 minecraft:log 3
setblock ~24~26~20 minecraft:wooden_slab 3
setblock ~24~29~20 minecraft:leaves2 1
setblock ~24~31~20 minecraft:spruce_stairs 3
fill ~24~36~20 ~24~40~20 minecraft:vine 1
fill ~24~41~20 ~24~44~20 minecraft:vine 3
fill ~24~45~20 ~24~45~26 minecraft:leaves 3
fill ~24~48~20 ~24~48~21 minecraft:leaves 3
fill ~24~49~20 ~24~49~31 minecraft:stone_block_slab 13
fill ~24~50~20 ~24~50~22 minecraft:wool 13
setblock ~24~51~20 minecraft:wooden_slab 1
setblock ~25~1~20 minecraft:vine 1
fill ~25~18~20 ~25~18~22 minecraft:log 3
fill ~25~19~20 ~25~19~21 minecraft:log 3
setblock ~25~28~20 minecraft:leaves 3
fill ~25~29~20 ~25~31~20 minecraft:vine 5
setblock ~25~32~20 minecraft:vine 1
setblock ~25~46~20 minecraft:leaves 3
fill ~25~51~20 ~26~51~21 minecraft:leaves 3
setblock ~26~1~20 minecraft:log 3
fill ~26~17~20 ~27~17~20 minecraft:log 3
fill ~26~19~20 ~26~19~21 minecraft:log 3
fill ~26~26~20 ~26~28~20 minecraft:end_stone
setblock ~26~29~20 minecraft:log 0
setblock ~26~30~20 minecraft:log 0
setblock ~26~45~20 minecraft:leaves 3
fill ~26~46~20 ~27~46~20 minecraft:leaves2 1
fill ~27~0~20 ~27~0~23 minecraft:log 3
fill ~27~1~20 ~28~1~21 minecraft:log 3
fill ~27~18~20 ~27~18~21 minecraft:log 3
fill ~27~19~20 ~28~19~20 minecraft:log 3
setblock ~27~20~20 minecraft:log 3
setblock ~27~47~20 minecraft:leaves2 1
fill ~27~50~20 ~27~50~27 minecraft:leaves 3
setblock ~28~20~20 minecraft:log 3
fill ~28~48~20 ~28~49~20 minecraft:leaves 3
setblock ~28~50~20 minecraft:leaves2 1
setblock ~29~19~20 minecraft:log 3
fill ~30~0~20 ~31~0~20 minecraft:log 3
setblock ~30~1~20 minecraft:log 3
setblock ~30~18~20 minecraft:leaves 3
setblock ~30~19~20 minecraft:log 3
setblock ~30~20~20 minecraft:log 3
setblock ~31~19~20 minecraft:leaves 3
fill ~31~20~20 ~32~20~20 minecraft:vine 4
setblock ~32~14~20 minecraft:trip_wire 0
fill ~32~15~20 ~32~19~20 minecraft:vine 4
setblock ~34~0~20 minecraft:dirt 1
setblock ~0~9~21 minecraft:trip_wire 0
fill ~0~10~21 ~0~24~21 minecraft:vine 8
setblock ~1~16~21 minecraft:leaves2 1
fill ~1~18~21 ~1~19~21 minecraft:leaves2 1
fill ~1~20~21 ~1~20~27 minecraft:wooden_slab 11
setblock ~1~22~21 minecraft:leaves 3
fill ~1~23~21 ~1~24~21 minecraft:leaves2 1
fill ~2~0~21 ~4~0~21 minecraft:log 3
setblock ~2~18~21 minecraft:leaves 3
fill ~2~19~21 ~2~20~23 minecraft:log 3
fill ~2~21~21 ~2~21~23 minecraft:planks 0
setblock ~2~22~21 minecraft:planks 0
setblock ~2~23~21 minecraft:log 3
setblock ~2~24~21 minecraft:planks 0
fill ~2~25~21 ~2~25~28 minecraft:dark_oak_stairs 0
fill ~3~20~21 ~3~20~24 minecraft:planks 0
setblock ~3~22~21 minecraft:daylight_detector 11
setblock ~3~24~21 minecraft:ladder 5
fill ~3~25~21 ~3~25~27 minecraft:wooden_slab 13
setblock ~4~20~21 minecraft:wooden_slab 11
setblock ~4~21~21 minecraft:trapdoor 0
fill ~5~0~21 ~6~0~21 minecraft:log 3
setblock ~5~1~21 minecraft:log 3
setblock ~5~9~21 minecraft:leaves2 1
fill ~5~10~21 ~5~10~22 minecraft:fence 0
setblock ~5~13~21 minecraft:leaves2 1
fill ~5~14~21 ~6~14~21 minecraft:fence 0
setblock ~5~15~21 minecraft:fence 5
setblock ~5~19~21 minecraft:leaves2 1
fill ~5~20~21 ~5~20~24 minecraft:planks 0
fill ~5~26~21 ~5~27~21 minecraft:leaves2 1
fill ~5~38~21 ~6~38~22 minecraft:log 0
setblock ~5~40~21 minecraft:glass
setblock ~5~45~21 minecraft:leaves 3
setblock ~5~47~21 minecraft:leaves 3
setblock ~6~16~21 minecraft:leaves 3
fill ~6~19~21 ~6~19~22 minecraft:redstone_block
fill ~6~20~21 ~6~20~22 minecraft:piston 1
fill ~6~21~21 ~6~21~22 minecraft:piston_arm_collision 1
setblock ~6~43~21 minecraft:log 3
setblock ~6~44~21 minecraft:leaves 3
fill ~6~47~21 ~7~47~24 minecraft:leaves2 1
fill ~6~48~21 ~6~48~23 minecraft:leaves 3
setblock ~7~0~21 minecraft:dirt 1
setblock ~7~1~21 minecraft:red_flower 1
fill ~7~17~21 ~7~18~21 minecraft:log 3
setblock ~7~19~21 minecraft:leaves2 1
fill ~7~20~21 ~10~20~22 minecraft:planks 0
fill ~7~37~21 ~9~37~22 minecraft:leaves 3
setblock ~7~38~21 minecraft:leaves 3
fill ~7~39~21 ~9~39~21 minecraft:carpet 12
setblock ~7~46~21 minecraft:leaves2 1
fill ~7~50~21 ~8~50~22 minecraft:leaves 3
setblock ~8~0~21 minecraft:log 3
fill ~8~15~21 ~9~15~21 minecraft:log 3
setblock ~8~38~21 minecraft:log 3
setblock ~8~43~21 minecraft:log 3
fill ~8~51~21 ~8~51~27 minecraft:leaves 3
setblock ~9~0~21 minecraft:log 3
setblock ~9~1~21 minecraft:log 3
fill ~9~2~21 ~10~2~21 minecraft:leaves 3
setblock ~9~16~21 minecraft:leaves 3
setblock ~9~26~21 minecraft:leaves 3
setblock ~9~38~21 minecraft:log 3
setblock ~9~40~21 minecraft:torch 4
fill ~9~43~21 ~10~43~22 minecraft:leaves 3
setblock ~10~0~21 minecraft:log 3
setblock ~10~1~21 minecraft:log 3
setblock ~10~4~21 minecraft:leaves 3
fill ~10~15~21 ~11~15~21 minecraft:log 3
setblock ~10~23~21 minecraft:tripwire_hook 1
fill ~10~25~21 ~10~25~28 minecraft:wooden_slab 13
fill ~10~36~21 ~12~36~24 minecraft:leaves 3
setblock ~10~38~21 minecraft:log 3
fill ~10~39~21 ~11~39~21 minecraft:spruce_door 3
setblock ~11~0~21 minecraft:log 3
fill ~11~1~21 ~12~1~21 minecraft:log 3
setblock ~11~2~21 minecraft:log 3
fill ~11~3~21 ~12~3~21 minecraft:log 3
fill ~11~14~21 ~12~14~21 minecraft:log 3
fill ~11~19~21 ~11~20~21 minecraft:log 3
fill ~11~21~21 ~11~21~27 minecraft:planks 0
fill ~11~22~21 ~11~24~22 minecraft:planks 0
fill ~11~25~21 ~11~25~29 minecraft:dark_oak_stairs 1
setblock ~11~32~21 minecraft:leaves 3
fill ~11~38~21 ~13~38~21 minecraft:log 3
setblock ~11~43~21 minecraft:log 3
fill ~11~45~21 ~11~47~23 minecraft:leaves 3
fill ~11~49~21 ~11~49~22 minecraft:leaves 3
setblock ~11~52~21 minecraft:leaves2 1
setblock ~12~0~21 minecraft:log 3
setblock ~12~4~21 minecraft:leaves 3
fill ~12~5~21 ~12~5~22 minecraft:leaves2 1
setblock ~12~15~21 minecraft:log 3
fill ~12~16~21 ~12~17~21 minecraft:leaves 3
setblock ~12~20~21 minecraft:wooden_slab 11
fill ~12~28~21 ~12~30~21 minecraft:leaves 3
fill ~12~32~21 ~12~33~21 minecraft:log 3
setblock ~12~34~21 minecraft:leaves 3
fill ~12~37~21 ~12~37~22 minecraft:log 3
fill ~12~39~21 ~13~39~21 minecraft:carpet 12
setblock ~12~40~21 minecraft:torch 4
fill ~12~44~21 ~13~44~21 minecraft:leaves 3
setblock ~12~46~21 minecraft:log 3
fill ~12~47~21 ~13~48~21 minecraft:log 3
setblock ~12~50~21 minecraft:leaves 3
fill ~12~53~21 ~12~53~32 minecraft:leaves 3
fill ~13~0~21 ~13~1~21 minecraft:log 3
fill ~13~2~21 ~13~3~21 minecraft:log 3
setblock ~13~4~21 minecraft:log 3
fill ~13~5~21 ~15~5~21 minecraft:log 3
setblock ~13~6~21 minecraft:leaves2 1
setblock ~13~7~21 minecraft:leaves 3
fill ~13~9~21 ~13~9~25 minecraft:leaves 3
setblock ~13~14~21 minecraft:log 3
setblock ~13~15~21 minecraft:log 3
setblock ~13~19~21 minecraft:log 3
fill ~13~20~21 ~13~21~21 minecraft:leaves 3
setblock ~13~27~21 minecraft:leaves 3
setblock ~13~28~21 minecraft:log 3
setblock ~13~29~21 minecraft:log 3
setblock ~13~30~21 minecraft:glowstone
setblock ~13~31~21 minecraft:log 3
fill ~13~32~21 ~13~36~21 minecraft:log 3
setblock ~13~37~21 minecraft:log 3
fill ~13~42~21 ~13~43~21 minecraft:leaves 3
setblock ~13~45~21 minecraft:log 3
setblock ~14~1~21 minecraft:log 3
fill ~14~3~21 ~15~4~21 minecraft:log 3
fill ~14~6~21 ~14~12~24 minecraft:log 3
setblock ~14~13~21 minecraft:log 3
fill ~14~14~21 ~15~17~21 minecraft:log 3
fill ~14~21~21 ~15~21~21 minecraft:log 3
fill ~14~34~21 ~15~35~21 minecraft:log 3
setblock ~14~36~21 minecraft:log 0
fill ~14~37~21 ~15~37~21 minecraft:log 3
fill ~14~38~21 ~14~38~27 minecraft:log 3
fill ~14~42~21 ~14~46~22 minecraft:log 3
fill ~14~47~21 ~14~48~21 minecraft:log 3
fill ~15~0~21 ~15~2~21 minecraft:log 3
setblock ~15~6~21 minecraft:double_stone_block_slab 5
setblock ~15~7~21 minecraft:crafting_table
setblock ~15~12~21 minecraft:stone_block_slab 13
setblock ~15~13~21 minecraft:log 3
fill ~15~18~21 ~15~20~21 minecraft:log 3
fill ~15~22~21 ~15~28~21 minecraft:log 3
fill ~15~30~21 ~15~31~21 minecraft:log 3
setblock ~15~33~21 minecraft:log 3
setblock ~15~36~21 minecraft:log 3
setblock ~15~48~21 minecraft:log 3
fill ~16~0~21 ~19~0~23 minecraft:stone_block_slab 13
fill ~16~6~21 ~19~6~23 minecraft:stone_block_slab 13
fill ~16~7~21 ~17~7~21 minecraft:jungle_stairs 7
setblock ~16~8~21 minecraft:flower_pot 0
fill ~16~13~21 ~19~13~23 minecraft:stone_block_slab 13
fill ~16~19~21 ~19~19~23 minecraft:stone_block_slab 13
fill ~16~25~21 ~19~25~23 minecraft:stone_block_slab 13
fill ~16~31~21 ~19~31~23 minecraft:stone_block_slab 13
fill ~16~37~21 ~19~37~23 minecraft:stone_block_slab 13
fill ~16~43~21 ~19~43~23 minecraft:stone_block_slab 13
fill ~16~49~21 ~19~49~23 minecraft:stone_block_slab 13
fill ~16~55~21 ~16~55~22 minecraft:leaves2 1
fill ~17~32~21 ~17~36~21 minecraft:wall_sign 3
fill ~17~54~21 ~17~54~22 minecraft:leaves 3
setblock ~17~55~21 minecraft:leaves2 1
setblock ~18~36~21 minecraft:wall_sign 3
fill ~18~54~21 ~18~56~21 minecraft:leaves 3
fill ~19~7~21 ~19~8~21 minecraft:fence 3
fill ~19~9~21 ~20~9~21 minecraft:leaves 3
fill ~19~32~21 ~19~35~21 minecraft:wall_sign 3
fill ~19~54~21 ~19~55~22 minecraft:leaves 3
fill ~19~57~21 ~19~57~22 minecraft:leaves 3
fill ~20~0~21 ~21~0~21 minecraft:log 3
fill ~20~2~21 ~21~2~21 minecraft:log 3
fill ~20~5~21 ~21~5~21 minecraft:log 3
setblock ~20~6~21 minecraft:double_stone_block_slab 5
setblock ~20~7~21 minecraft:bookshelf
setblock ~20~8~21 minecraft:flower_pot 0
setblock ~20~12~21 minecraft:stone_block_slab 13
setblock ~20~13~21 minecraft:log 3
setblock ~20~14~21 minecraft:log 3
setblock ~20~15~21 minecraft:log 3
setblock ~20~17~21 minecraft:log 3
fill ~20~19~21 ~20~23~21 minecraft:log 3
setblock ~20~24~21 minecraft:log 3
fill ~20~25~21 ~20~35~21 minecraft:log 3
fill ~20~37~21 ~22~37~21 minecraft:log 3
fill ~20~40~21 ~21~41~21 minecraft:log 3
fill ~20~43~21 ~22~44~21 minecraft:log 3
fill ~20~45~21 ~21~45~21 minecraft:log 3
fill ~20~47~21 ~21~48~21 minecraft:log 3
fill ~20~49~21 ~21~49~21 minecraft:double_stone_block_slab 5
fill ~20~50~21 ~21~50~21 minecraft:stone_block_slab 9
setblock ~20~51~21 minecraft:carpet 8
fill ~20~54~21 ~22~54~21 minecraft:leaves 3
fill ~20~57~21 ~20~57~22 minecraft:leaves 3
fill ~21~4~21 ~22~4~24 minecraft:log 3
fill ~21~6~21 ~21~12~26 minecraft:log 3
fill ~21~13~21 ~21~14~21 minecraft:leaves 3
fill ~21~16~21 ~21~21~21 minecraft:leaves 3
fill ~21~23~21 ~21~25~21 minecraft:vine 1
setblock ~21~26~21 minecraft:log 3
fill ~21~27~21 ~21~28~21 minecraft:log 3
setblock ~21~29~21 minecraft:double_wooden_slab 3
setblock ~21~32~21 minecraft:log 3
fill ~21~33~21 ~21~33~26 minecraft:log 3
fill ~21~35~21 ~21~36~26 minecraft:log 3
fill ~21~38~21 ~21~38~27 minecraft:log 3
setblock ~21~51~21 minecraft:carpet 13
fill ~21~56~21 ~21~56~24 minecraft:leaves 3
fill ~22~1~21 ~22~1~22 minecraft:log 3
fill ~22~2~21 ~23~2~21 minecraft:log 3
setblock ~22~3~21 minecraft:log 3
setblock ~22~5~21 minecraft:leaves2 1
fill ~22~6~21 ~22~9~21 minecraft:vine 3
fill ~22~10~21 ~22~11~21 minecraft:vine 1
fill ~22~13~21 ~22~15~21 minecraft:trip_wire 0
fill ~22~17~21 ~22~19~21 minecraft:leaves 3
setblock ~22~27~21 minecraft:leaves 3
setblock ~22~28~21 minecraft:log 3
fill ~22~36~21 ~22~36~22 minecraft:log 3
fill ~22~41~21 ~22~42~21 minecraft:log 3
setblock ~22~45~21 minecraft:log 3
fill ~22~49~21 ~23~49~24 minecraft:stone_block_slab 13
fill ~22~55~21 ~23~55~22 minecraft:leaves 3
setblock ~22~56~21 minecraft:leaves2 1
setblock ~23~0~21 minecraft:log 3
fill ~23~1~21 ~24~1~21 minecraft:log 3
setblock ~23~3~21 minecraft:log 3
fill ~23~4~21 ~23~5~21 minecraft:vine 3
fill ~23~6~21 ~23~8~21 minecraft:vine 1
setblock ~23~16~21 minecraft:leaves 3
setblock ~23~18~21 minecraft:log 3
setblock ~23~19~21 minecraft:vine 6
fill ~23~20~21 ~23~27~21 minecraft:vine 4
fill ~23~28~21 ~23~28~22 minecraft:leaves 3
setblock ~23~29~21 minecraft:leaves2 1
setblock ~23~30~21 minecraft:wooden_slab 3
setblock ~23~36~21 minecraft:double_wooden_slab 1
fill ~23~41~21 ~24~41~21 minecraft:leaves2 1
setblock ~23~42~21 minecraft:leaves2 1
setblock ~23~43~21 minecraft:log 3
fill ~23~44~21 ~23~45~21 minecraft:log 3
setblock ~23~50~21 minecraft:wooden_slab 1
fill ~24~0~21 ~25~0~21 minecraft:log 3
setblock ~24~2~21 minecraft:log 3
setblock ~24~3~21 minecraft:vine 3
setblock ~24~17~21 minecraft:log 3
fill ~24~18~21 ~24~18~23 minecraft:log 3
setblock ~24~19~21 minecraft:log 3
fill ~24~25~21 ~24~28~21 minecraft:log 0
fill ~24~29~21 ~25~29~24 minecraft:leaves 3
fill ~24~30~21 ~24~30~22 minecraft:wooden_slab 11
fill ~24~42~21 ~24~43~21 minecraft:vine 3
setblock ~24~44~21 minecraft:leaves 3
setblock ~24~51~21 minecraft:spruce_stairs 4
fill ~24~54~21 ~24~54~29 minecraft:leaves 3
setblock ~25~1~21 minecraft:log 3
fill ~25~25~21 ~25~28~21 minecraft:planks 1
fill ~25~30~21 ~25~32~21 minecraft:leaves2 1
fill ~25~38~21 ~25~41~23 minecraft:vine 2
fill ~25~46~21 ~26~46~21 minecraft:leaves2 1
fill ~25~47~21 ~25~48~23 minecraft:leaves 3
fill ~26~1~21 ~26~1~22 minecraft:log 3
setblock ~26~2~21 minecraft:log 3
setblock ~26~16~21 minecraft:leaves 3
setblock ~26~17~21 minecraft:log 3
fill ~26~21~21 ~26~29~21 minecraft:log 0
fill ~26~30~21 ~26~32~21 minecraft:vine 3
fill ~26~52~21 ~26~52~25 minecraft:leaves 3
setblock ~27~19~21 minecraft:log 3
fill ~27~47~21 ~27~47~23 minecraft:leaves 3
setblock ~27~48~21 minecraft:leaves 3
fill ~27~51~21 ~28~51~21 minecraft:leaves 3
fill ~28~49~21 ~28~50~21 minecraft:leaves 3
setblock ~29~1~21 minecraft:log 3
fill ~29~7~21 ~29~7~22 minecraft:leaves 3
setblock ~29~8~21 minecraft:leaves 3
fill ~29~48~21 ~29~48~23 minecraft:leaves2 1
fill ~29~49~21 ~29~49~22 minecraft:leaves2 1
fill ~30~0~21 ~30~0~22 minecraft:log 3
fill ~30~6~21 ~31~6~21 minecraft:leaves 3
setblock ~30~7~21 minecraft:leaves2 1
setblock ~31~5~21 minecraft:leaves2 1
setblock ~31~7~21 minecraft:log 3
setblock ~32~6~21 minecraft:log 3
setblock ~33~0~21 minecraft:dirt 1
setblock ~33~1~21 minecraft:red_flower 1
setblock ~34~0~21 minecraft:log 3
fill ~35~0~21 ~36~0~21 minecraft:log 3
setblock ~1~17~22 minecraft:leaves2 1
fill ~1~21~22 ~1~24~22 minecraft:vine 4
setblock ~2~18~22 minecraft:leaves2 1
setblock ~2~22~22 minecraft:log 3
setblock ~2~23~22 minecraft:stained_glass_pane 12
setblock ~2~24~22 minecraft:log 3
setblock ~3~10~22 minecraft:leaves2 1
fill ~3~19~22 ~4~19~22 minecraft:leaves2 1
setblock ~3~21~22 minecraft:trapdoor 2
setblock ~3~29~22 minecraft:leaves 3
setblock ~3~41~22 minecraft:vine 8
fill ~4~10~22 ~4~11~22 minecraft:leaves 3
fill ~4~12~22 ~4~12~23 minecraft:fence 0
fill ~4~15~22 ~4~16~22 minecraft:leaves2 1
fill ~4~20~22 ~4~20~23 minecraft:planks 0
setblock ~4~26~22 minecraft:leaves2 1
fill ~4~29~22 ~4~29~24 minecraft:log 3
setblock ~4~30~22 minecraft:leaves 3
fill ~4~41~22 ~4~42~22 minecraft:leaves 3
setblock ~5~7~22 minecraft:leaves 3
setblock ~5~9~22 minecraft:leaves 3
fill ~5~12~22 ~5~18~22 minecraft:leaves 3
fill ~5~19~22 ~5~19~23 minecraft:fence 0
fill ~5~39~22 ~5~41~22 minecraft:log 0
fill ~5~46~22 ~7~46~22 minecraft:leaves 3
fill ~5~47~22 ~5~47~23 minecraft:leaves2 1
setblock ~5~48~22 minecraft:leaves 3
setblock ~6~13~22 minecraft:leaves2 1
setblock ~6~14~22 minecraft:fence 0
setblock ~6~17~22 minecraft:leaves 3
fill ~6~18~22 ~8~18~22 minecraft:fence 0
fill ~6~39~22 ~6~40~22 minecraft:stonebrick 0
fill ~6~41~22 ~8~41~22 minecraft:log 0
fill ~6~42~22 ~13~42~22 minecraft:glass
setblock ~6~43~22 minecraft:leaves 3
fill ~6~44~22 ~6~44~23 minecraft:leaves2 1
fill ~6~45~22 ~9~45~23 minecraft:leaves 3
setblock ~6~50~22 minecraft:leaves 3
fill ~7~19~22 ~7~19~23 minecraft:fence 0
setblock ~7~38~22 minecraft:log 0
fill ~7~39~22 ~7~40~22 minecraft:glass
fill ~7~51~22 ~7~51~24 minecraft:leaves 3
setblock ~8~26~22 minecraft:stone_block_slab 3
setblock ~8~36~22 minecraft:leaves 3
fill ~8~38~22 ~9~38~24 minecraft:leaves 3
fill ~8~39~22 ~8~40~22 minecraft:stonebrick 0
setblock ~8~43~22 minecraft:leaves 3
fill ~8~47~22 ~8~47~24 minecraft:leaves2 1
fill ~9~39~22 ~9~41~22 minecraft:log 0
