fill ~1 ~0 ~10 ~73 ~0 ~10 netherrack 0  
fill ~1 ~0 ~11 ~73 ~0 ~11 netherrack 0  
fill ~1 ~0 ~12 ~73 ~0 ~12 netherrack 0  
fill ~1 ~0 ~13 ~73 ~0 ~13 netherrack 0  
fill ~1 ~0 ~14 ~73 ~0 ~14 netherrack 0  
fill ~1 ~0 ~15 ~73 ~0 ~15 netherrack 0  
fill ~1 ~0 ~16 ~73 ~0 ~16 netherrack 0  
fill ~1 ~0 ~17 ~73 ~0 ~17 netherrack 0  
fill ~1 ~0 ~18 ~73 ~0 ~18 netherrack 0  
fill ~1 ~0 ~19 ~72 ~0 ~19 netherrack 0  
fill ~2 ~0 ~7 ~72 ~0 ~7 netherrack 0  
fill ~2 ~0 ~8 ~73 ~0 ~8 netherrack 0  
fill ~2 ~0 ~9 ~73 ~0 ~9 netherrack 0  
fill ~2 ~0 ~20 ~71 ~0 ~20 netherrack 0  
fill ~2 ~0 ~21 ~71 ~0 ~21 netherrack 0  
fill ~3 ~0 ~4 ~70 ~0 ~4 netherrack 0  
fill ~3 ~0 ~5 ~71 ~0 ~5 netherrack 0  
fill ~3 ~0 ~6 ~72 ~0 ~6 netherrack 0  
fill ~3 ~0 ~22 ~69 ~0 ~22 netherrack 0  
fill ~4 ~0 ~3 ~69 ~0 ~3 netherrack 0  
fill ~4 ~0 ~23 ~69 ~0 ~23 netherrack 0  
fill ~5 ~0 ~2 ~68 ~0 ~2 netherrack 0  
fill ~6 ~0 ~24 ~67 ~0 ~24 netherrack 0  
fill ~7 ~0 ~1 ~66 ~0 ~1 netherrack 0  
fill ~5 ~1 ~7 ~7 ~1 ~7 obsidian 0  
fill ~5 ~1 ~8 ~7 ~1 ~8 obsidian 0  
fill ~5 ~1 ~15 ~7 ~1 ~15 obsidian 0  
fill ~5 ~1 ~16 ~7 ~1 ~16 obsidian 0  
fill ~6 ~1 ~6 ~7 ~1 ~6 obsidian 0  
fill ~6 ~1 ~10 ~6 ~4 ~10 obsidian 0  
fill ~6 ~1 ~13 ~6 ~4 ~13 obsidian 0  
fill ~6 ~1 ~17 ~7 ~1 ~17 obsidian 0  
fill ~7 ~1 ~9 ~7 ~3 ~9 coal_block 0  
fill ~7 ~1 ~10 ~7 ~3 ~10 coal_block 0  
fill ~7 ~1 ~11 ~7 ~3 ~11 coal_block 0  
fill ~7 ~1 ~12 ~7 ~3 ~12 coal_block 0  
fill ~7 ~1 ~13 ~7 ~3 ~13 coal_block 0  
fill ~7 ~1 ~14 ~7 ~3 ~14 coal_block 0  
fill ~8 ~1 ~8 ~13 ~1 ~8 coal_block 0  
fill ~8 ~1 ~15 ~13 ~1 ~15 coal_block 0  
fill ~9 ~1 ~7 ~9 ~4 ~7 obsidian 0  
fill ~9 ~1 ~16 ~9 ~4 ~16 obsidian 0 
setblock ~10 ~1 ~11 coal_block 0  
fill ~12 ~1 ~7 ~12 ~4 ~7 obsidian 0  
fill ~12 ~1 ~16 ~12 ~4 ~16 obsidian 0  
fill ~14 ~1 ~6 ~15 ~1 ~6 obsidian 0  
fill ~14 ~1 ~7 ~16 ~1 ~7 obsidian 0  
fill ~14 ~1 ~8 ~16 ~1 ~8 obsidian 0  
fill ~14 ~1 ~9 ~14 ~3 ~9 coal_block 0  
fill ~14 ~1 ~10 ~14 ~3 ~10 coal_block 0  
fill ~14 ~1 ~11 ~14 ~3 ~11 coal_block 0  
fill ~14 ~1 ~12 ~14 ~3 ~12 coal_block 0  
fill ~14 ~1 ~13 ~14 ~3 ~13 coal_block 0  
fill ~14 ~1 ~14 ~14 ~3 ~14 coal_block 0  
fill ~14 ~1 ~15 ~16 ~1 ~15 obsidian 0  
fill ~14 ~1 ~16 ~16 ~1 ~16 obsidian 0  
fill ~14 ~1 ~17 ~15 ~1 ~17 obsidian 0  
fill ~15 ~1 ~10 ~15 ~4 ~10 obsidian 0  
fill ~15 ~1 ~13 ~15 ~4 ~13 obsidian 0  
fill ~17 ~1 ~6 ~42 ~1 ~6 netherrack 0  
fill ~17 ~1 ~7 ~51 ~1 ~7 netherrack 0  
fill ~17 ~1 ~9 ~26 ~1 ~9 netherrack 0  
fill ~17 ~1 ~10 ~26 ~1 ~10 netherrack 0  
fill ~17 ~1 ~11 ~26 ~1 ~11 netherrack 0  
fill ~17 ~1 ~12 ~26 ~1 ~12 netherrack 0  
fill ~18 ~1 ~5 ~31 ~1 ~5 netherrack 0  
fill ~18 ~1 ~8 ~51 ~1 ~8 netherrack 0  
fill ~18 ~1 ~13 ~26 ~1 ~13 netherrack 0  
fill ~19 ~1 ~4 ~31 ~1 ~4 netherrack 0  
fill ~19 ~1 ~14 ~26 ~1 ~14 netherrack 0  
fill ~19 ~1 ~15 ~37 ~1 ~15 netherrack 0  
fill ~21 ~1 ~16 ~36 ~1 ~16 netherrack 0  
fill ~27 ~1 ~17 ~36 ~1 ~17 netherrack 0  
fill ~27 ~1 ~18 ~36 ~1 ~18 netherrack 0  
fill ~27 ~1 ~19 ~39 ~1 ~19 netherrack 0  
fill ~28 ~1 ~9 ~29 ~1 ~9 coal_block 0  
fill ~28 ~1 ~10 ~29 ~1 ~10 coal_block 0  
fill ~28 ~1 ~11 ~29 ~1 ~11 coal_block 0  
fill ~28 ~1 ~12 ~29 ~1 ~12 coal_block 0  
fill ~28 ~1 ~13 ~29 ~1 ~13 coal_block 0  
fill ~28 ~1 ~14 ~29 ~1 ~14 coal_block 0  
fill ~30 ~1 ~9 ~44 ~1 ~9 netherrack 0  
fill ~30 ~1 ~10 ~44 ~1 ~10 netherrack 0  
fill ~30 ~1 ~11 ~44 ~1 ~11 netherrack 0  
fill ~30 ~1 ~12 ~43 ~1 ~12 netherrack 0  
fill ~30 ~1 ~13 ~43 ~1 ~13 netherrack 0  
fill ~30 ~1 ~14 ~43 ~1 ~14 netherrack 0  
fill ~34 ~1 ~5 ~39 ~1 ~5 netherrack 0  
fill ~35 ~1 ~4 ~37 ~1 ~4 netherrack 0  
fill ~39 ~1 ~18 ~42 ~1 ~18 netherrack 0  
fill ~42 ~1 ~17 ~46 ~1 ~17 netherrack 0  
fill ~44 ~1 ~12 ~45 ~1 ~12 coal_block 0  
fill ~44 ~1 ~13 ~45 ~1 ~13 coal_block 0  
fill ~44 ~1 ~14 ~45 ~1 ~14 coal_block 0  
fill ~45 ~1 ~9 ~45 ~1 ~14 coal_block 0  
fill ~46 ~1 ~6 ~49 ~1 ~6 netherrack 0  
fill ~46 ~1 ~9 ~52 ~1 ~9 netherrack 0  
fill ~46 ~1 ~10 ~52 ~1 ~10 netherrack 0  
fill ~46 ~1 ~11 ~52 ~1 ~11 netherrack 0  
fill ~46 ~1 ~12 ~52 ~1 ~12 netherrack 0  
fill ~46 ~1 ~13 ~52 ~1 ~13 netherrack 0  
fill ~46 ~1 ~14 ~52 ~1 ~14 netherrack 0  
fill ~46 ~1 ~16 ~49 ~1 ~16 netherrack 0  
fill ~49 ~1 ~15 ~50 ~1 ~15 netherrack 0 
setblock ~51 ~1 ~15 nether_brick 0  
fill ~57 ~1 ~7 ~59 ~1 ~7 obsidian 0  
fill ~57 ~1 ~8 ~59 ~1 ~8 obsidian 0  
fill ~57 ~1 ~15 ~59 ~1 ~15 obsidian 0  
fill ~57 ~1 ~16 ~59 ~1 ~16 obsidian 0  
fill ~58 ~1 ~6 ~59 ~1 ~6 obsidian 0  
fill ~58 ~1 ~10 ~58 ~4 ~10 obsidian 0  
fill ~58 ~1 ~13 ~58 ~4 ~13 obsidian 0  
fill ~58 ~1 ~17 ~59 ~1 ~17 obsidian 0  
fill ~59 ~1 ~9 ~59 ~3 ~9 coal_block 0  
fill ~59 ~1 ~10 ~59 ~3 ~10 coal_block 0  
fill ~59 ~1 ~11 ~59 ~3 ~11 coal_block 0  
fill ~59 ~1 ~12 ~59 ~3 ~12 coal_block 0  
fill ~59 ~1 ~13 ~59 ~3 ~13 coal_block 0  
fill ~59 ~1 ~14 ~59 ~3 ~14 coal_block 0  
fill ~60 ~1 ~8 ~65 ~1 ~8 coal_block 0  
fill ~60 ~1 ~15 ~65 ~1 ~15 coal_block 0  
fill ~61 ~1 ~7 ~61 ~4 ~7 obsidian 0  
fill ~61 ~1 ~16 ~61 ~4 ~16 obsidian 0  
fill ~64 ~1 ~7 ~64 ~4 ~7 obsidian 0  
fill ~64 ~1 ~16 ~64 ~4 ~16 obsidian 0  
fill ~66 ~1 ~6 ~67 ~1 ~6 obsidian 0  
fill ~66 ~1 ~7 ~68 ~1 ~7 obsidian 0  
fill ~66 ~1 ~8 ~68 ~1 ~8 obsidian 0  
fill ~66 ~1 ~9 ~66 ~3 ~9 coal_block 0  
fill ~66 ~1 ~10 ~66 ~3 ~10 coal_block 0  
fill ~66 ~1 ~11 ~66 ~3 ~11 coal_block 0  
fill ~66 ~1 ~12 ~66 ~3 ~12 coal_block 0  
fill ~66 ~1 ~13 ~66 ~3 ~13 coal_block 0  
fill ~66 ~1 ~14 ~66 ~3 ~14 coal_block 0  
fill ~66 ~1 ~15 ~68 ~1 ~15 obsidian 0  
fill ~66 ~1 ~16 ~68 ~1 ~16 obsidian 0  
fill ~66 ~1 ~17 ~67 ~1 ~17 obsidian 0  
fill ~67 ~1 ~10 ~67 ~4 ~10 obsidian 0  
fill ~67 ~1 ~13 ~67 ~4 ~13 obsidian 0 
setblock ~68 ~1 ~6 nether_brick 0  
fill ~5 ~2 ~7 ~7 ~2 ~7 obsidian 0  
fill ~5 ~2 ~8 ~7 ~2 ~8 obsidian 0 
setblock ~5 ~2 ~10 nether_brick_fence 0 
setblock ~5 ~2 ~13 nether_brick_fence 0  
fill ~5 ~2 ~15 ~7 ~2 ~15 obsidian 0  
fill ~5 ~2 ~16 ~7 ~2 ~16 obsidian 0  
fill ~6 ~2 ~6 ~7 ~2 ~6 obsidian 0  
fill ~6 ~2 ~17 ~7 ~2 ~17 obsidian 0  
fill ~8 ~2 ~8 ~13 ~2 ~8 coal_block 0  
fill ~8 ~2 ~15 ~13 ~2 ~15 coal_block 0 
setblock ~9 ~2 ~6 nether_brick_fence 0 
setblock ~9 ~2 ~17 nether_brick_fence 0 
setblock ~12 ~2 ~6 nether_brick_fence 0 
setblock ~12 ~2 ~17 nether_brick_fence 0  
fill ~14 ~2 ~6 ~15 ~2 ~6 obsidian 0  
fill ~14 ~2 ~7 ~16 ~2 ~7 obsidian 0  
fill ~14 ~2 ~8 ~16 ~2 ~8 obsidian 0  
fill ~14 ~2 ~15 ~16 ~2 ~15 obsidian 0  
fill ~14 ~2 ~16 ~16 ~2 ~16 obsidian 0  
fill ~14 ~2 ~17 ~15 ~2 ~17 obsidian 0 
setblock ~16 ~2 ~10 nether_brick_fence 0 
setblock ~16 ~2 ~13 nether_brick_fence 0  
fill ~22 ~2 ~9 ~25 ~2 ~9 coal_block 0  
fill ~22 ~2 ~10 ~22 ~2 ~14 coal_block 0  
fill ~23 ~2 ~4 ~35 ~2 ~4 netherrack 0 
setblock ~23 ~2 ~10 lava 10  
fill ~23 ~2 ~11 ~23 ~4 ~11 lava 12  
fill ~23 ~2 ~12 ~23 ~4 ~12 lava 10  
fill ~23 ~2 ~13 ~23 ~3 ~13 lava 8  
fill ~23 ~2 ~14 ~25 ~2 ~14 coal_block 0  
fill ~24 ~2 ~10 ~24 ~2 ~13 lava 2  
fill ~25 ~2 ~5 ~36 ~2 ~5 netherrack 0  
fill ~25 ~2 ~10 ~25 ~2 ~13 lava 4  
fill ~26 ~2 ~6 ~36 ~2 ~6 netherrack 0  
fill ~26 ~2 ~9 ~26 ~2 ~15 netherrack 0  
fill ~27 ~2 ~7 ~37 ~2 ~7 netherrack 0  
fill ~27 ~2 ~8 ~47 ~2 ~8 netherrack 0  
fill ~27 ~2 ~9 ~27 ~2 ~14 coal_block 0  
fill ~27 ~2 ~15 ~47 ~2 ~15 netherrack 0  
fill ~28 ~2 ~9 ~45 ~2 ~9 netherrack 0  
fill ~28 ~2 ~10 ~45 ~2 ~10 netherrack 0  
fill ~28 ~2 ~11 ~45 ~2 ~11 netherrack 0  
fill ~28 ~2 ~12 ~46 ~2 ~12 coal_block 0  
fill ~28 ~2 ~13 ~45 ~2 ~13 netherrack 0  
fill ~28 ~2 ~14 ~45 ~2 ~14 netherrack 0  
fill ~28 ~2 ~16 ~45 ~2 ~16 netherrack 0  
fill ~29 ~2 ~17 ~41 ~2 ~17 netherrack 0  
fill ~29 ~2 ~18 ~38 ~2 ~18 netherrack 0  
fill ~30 ~2 ~19 ~36 ~2 ~19 netherrack 0  
fill ~46 ~2 ~9 ~46 ~2 ~14 coal_block 0  
fill ~47 ~2 ~7 ~48 ~2 ~7 netherrack 0  
fill ~47 ~2 ~9 ~47 ~2 ~15 netherrack 0  
fill ~48 ~2 ~9 ~51 ~2 ~9 coal_block 0  
fill ~48 ~2 ~10 ~48 ~2 ~13 lava 4  
fill ~48 ~2 ~14 ~51 ~2 ~14 coal_block 0  
fill ~49 ~2 ~10 ~49 ~2 ~13 lava 2  
fill ~50 ~2 ~10 ~50 ~3 ~10 lava 8  
fill ~50 ~2 ~11 ~50 ~4 ~11 lava 10  
fill ~50 ~2 ~12 ~50 ~4 ~12 lava 12 
setblock ~50 ~2 ~13 lava 10  
fill ~51 ~2 ~10 ~51 ~2 ~14 coal_block 0  
fill ~57 ~2 ~7 ~59 ~2 ~7 obsidian 0  
fill ~57 ~2 ~8 ~59 ~2 ~8 obsidian 0 
setblock ~57 ~2 ~10 nether_brick_fence 0 
setblock ~57 ~2 ~13 nether_brick_fence 0  
fill ~57 ~2 ~15 ~59 ~2 ~15 obsidian 0  
fill ~57 ~2 ~16 ~59 ~2 ~16 obsidian 0  
fill ~58 ~2 ~6 ~59 ~2 ~6 obsidian 0  
fill ~58 ~2 ~17 ~59 ~2 ~17 obsidian 0  
fill ~60 ~2 ~8 ~65 ~2 ~8 coal_block 0  
fill ~60 ~2 ~15 ~65 ~2 ~15 coal_block 0 
setblock ~61 ~2 ~6 nether_brick_fence 0 
setblock ~61 ~2 ~17 nether_brick_fence 0 
setblock ~64 ~2 ~6 nether_brick_fence 0 
setblock ~64 ~2 ~17 nether_brick_fence 0  
fill ~66 ~2 ~6 ~67 ~2 ~6 obsidian 0  
fill ~66 ~2 ~7 ~68 ~2 ~7 obsidian 0  
fill ~66 ~2 ~8 ~68 ~2 ~8 obsidian 0  
fill ~66 ~2 ~15 ~68 ~2 ~15 obsidian 0  
fill ~66 ~2 ~16 ~68 ~2 ~16 obsidian 0  
fill ~66 ~2 ~17 ~67 ~2 ~17 obsidian 0 
setblock ~68 ~2 ~10 nether_brick_fence 0 
setblock ~68 ~2 ~13 nether_brick_fence 0  
fill ~5 ~3 ~7 ~7 ~3 ~7 obsidian 0  
fill ~5 ~3 ~8 ~7 ~3 ~8 obsidian 0  
fill ~5 ~3 ~15 ~7 ~3 ~15 obsidian 0  
fill ~5 ~3 ~16 ~7 ~3 ~16 obsidian 0  
fill ~6 ~3 ~6 ~7 ~3 ~6 obsidian 0  
fill ~6 ~3 ~17 ~7 ~3 ~17 obsidian 0  
fill ~8 ~3 ~8 ~13 ~3 ~8 coal_block 0  
fill ~8 ~3 ~9 ~14 ~3 ~9 coal_block 0  
fill ~8 ~3 ~10 ~8 ~3 ~15 coal_block 0  
fill ~9 ~3 ~14 ~14 ~3 ~14 coal_block 0  
fill ~9 ~3 ~15 ~13 ~3 ~15 coal_block 0  
fill ~13 ~3 ~10 ~13 ~3 ~15 coal_block 0  
fill ~14 ~3 ~6 ~15 ~3 ~6 obsidian 0  
fill ~14 ~3 ~7 ~16 ~3 ~7 obsidian 0  
fill ~14 ~3 ~8 ~16 ~3 ~8 obsidian 0  
fill ~14 ~3 ~15 ~16 ~3 ~15 obsidian 0  
fill ~14 ~3 ~16 ~16 ~3 ~16 obsidian 0  
fill ~14 ~3 ~17 ~15 ~3 ~17 obsidian 0 
setblock ~20 ~3 ~8 nether_brick_stairs 6  
fill ~20 ~3 ~9 ~20 ~4 ~9 nether_brick_stairs 4  
fill ~20 ~3 ~10 ~20 ~4 ~10 nether_brick_stairs 4  
fill ~20 ~3 ~11 ~20 ~4 ~11 nether_brick_stairs 4  
fill ~20 ~3 ~12 ~20 ~4 ~12 nether_brick_stairs 4  
fill ~20 ~3 ~13 ~20 ~4 ~13 nether_brick_stairs 4  
fill ~20 ~3 ~14 ~20 ~4 ~14 nether_brick_stairs 4 
setblock ~20 ~3 ~15 nether_brick_stairs 7  
fill ~21 ~3 ~8 ~22 ~3 ~8 nether_brick 0  
fill ~21 ~3 ~9 ~21 ~3 ~15 nether_brick 0  
fill ~22 ~3 ~9 ~22 ~3 ~10 lava 0  
fill ~22 ~3 ~11 ~22 ~8 ~11 coal_block 0  
fill ~22 ~3 ~12 ~22 ~5 ~12 lava 12  
fill ~22 ~3 ~13 ~22 ~5 ~13 lava 10 
setblock ~22 ~3 ~14 lava 0 
setblock ~22 ~3 ~15 nether_brick 0 
setblock ~23 ~3 ~8 nether_brick_stairs 6  
fill ~23 ~3 ~9 ~26 ~3 ~9 coal_block 0 
setblock ~23 ~3 ~10 lava 2  
fill ~23 ~3 ~14 ~26 ~3 ~14 coal_block 0 
setblock ~23 ~3 ~15 nether_brick_stairs 7  
fill ~24 ~3 ~13 ~26 ~3 ~13 coal_block 0  
fill ~25 ~3 ~10 ~26 ~3 ~10 coal_block 0  
fill ~25 ~3 ~11 ~26 ~3 ~11 coal_block 0  
fill ~25 ~3 ~12 ~26 ~3 ~12 coal_block 0  
fill ~26 ~3 ~4 ~34 ~3 ~4 netherrack 0  
fill ~27 ~3 ~5 ~34 ~3 ~5 netherrack 0  
fill ~27 ~3 ~12 ~46 ~3 ~12 portal 1  
fill ~28 ~3 ~6 ~33 ~3 ~6 netherrack 0  
fill ~29 ~3 ~7 ~33 ~3 ~7 netherrack 0  
fill ~29 ~3 ~8 ~32 ~3 ~8 netherrack 0  
fill ~47 ~3 ~9 ~50 ~3 ~9 coal_block 0  
fill ~47 ~3 ~10 ~49 ~3 ~10 coal_block 0  
fill ~47 ~3 ~11 ~48 ~3 ~11 coal_block 0  
fill ~47 ~3 ~12 ~48 ~3 ~12 coal_block 0  
fill ~47 ~3 ~13 ~48 ~3 ~13 coal_block 0  
fill ~47 ~3 ~14 ~50 ~3 ~14 coal_block 0 
setblock ~50 ~3 ~8 nether_brick_stairs 6 
setblock ~50 ~3 ~13 lava 2 
setblock ~50 ~3 ~15 nether_brick_stairs 7  
fill ~51 ~3 ~8 ~52 ~3 ~8 nether_brick 0 
setblock ~51 ~3 ~9 lava 0  
fill ~51 ~3 ~10 ~51 ~5 ~10 lava 10  
fill ~51 ~3 ~11 ~51 ~5 ~11 lava 12  
fill ~51 ~3 ~12 ~51 ~8 ~12 coal_block 0  
fill ~51 ~3 ~13 ~51 ~3 ~14 lava 0  
fill ~51 ~3 ~15 ~52 ~3 ~15 nether_brick 0  
fill ~52 ~3 ~9 ~52 ~3 ~15 nether_brick 0 
setblock ~53 ~3 ~8 nether_brick_stairs 6  
fill ~53 ~3 ~9 ~53 ~4 ~9 nether_brick_stairs 5  
fill ~53 ~3 ~10 ~53 ~4 ~10 nether_brick_stairs 5  
fill ~53 ~3 ~11 ~53 ~4 ~11 nether_brick_stairs 5  
fill ~53 ~3 ~12 ~53 ~4 ~12 nether_brick_stairs 5  
fill ~53 ~3 ~13 ~53 ~4 ~13 nether_brick_stairs 5  
fill ~53 ~3 ~14 ~53 ~4 ~14 nether_brick_stairs 5 
setblock ~53 ~3 ~15 nether_brick_stairs 7  
fill ~57 ~3 ~7 ~59 ~3 ~7 obsidian 0  
fill ~57 ~3 ~8 ~59 ~3 ~8 obsidian 0  
fill ~57 ~3 ~15 ~59 ~3 ~15 obsidian 0  
fill ~57 ~3 ~16 ~59 ~3 ~16 obsidian 0  
fill ~58 ~3 ~6 ~59 ~3 ~6 obsidian 0  
fill ~58 ~3 ~17 ~59 ~3 ~17 obsidian 0  
fill ~60 ~3 ~8 ~65 ~3 ~8 coal_block 0  
fill ~60 ~3 ~9 ~66 ~3 ~9 coal_block 0  
fill ~60 ~3 ~10 ~60 ~3 ~15 coal_block 0  
fill ~61 ~3 ~14 ~66 ~3 ~14 coal_block 0  
fill ~61 ~3 ~15 ~65 ~3 ~15 coal_block 0  
fill ~65 ~3 ~10 ~65 ~3 ~15 coal_block 0  
fill ~66 ~3 ~6 ~67 ~3 ~6 obsidian 0  
fill ~66 ~3 ~7 ~68 ~3 ~7 obsidian 0  
fill ~66 ~3 ~8 ~68 ~3 ~8 obsidian 0  
fill ~66 ~3 ~15 ~68 ~3 ~15 obsidian 0  
fill ~66 ~3 ~16 ~68 ~3 ~16 obsidian 0  
fill ~66 ~3 ~17 ~67 ~3 ~17 obsidian 0  
fill ~5 ~4 ~7 ~16 ~4 ~7 obsidian 0  
fill ~5 ~4 ~8 ~7 ~4 ~8 obsidian 0 
setblock ~5 ~4 ~9 nether_brick_fence 0  
fill ~5 ~4 ~11 ~5 ~4 ~12 nether_brick_fence 0 
setblock ~5 ~4 ~14 nether_brick_fence 0  
fill ~5 ~4 ~15 ~7 ~4 ~15 obsidian 0  
fill ~5 ~4 ~16 ~16 ~4 ~16 obsidian 0  
fill ~6 ~4 ~6 ~7 ~4 ~6 obsidian 0 
setblock ~6 ~4 ~9 obsidian 0  
fill ~6 ~4 ~11 ~6 ~4 ~17 obsidian 0  
fill ~7 ~4 ~9 ~7 ~4 ~14 lava 0  
fill ~7 ~4 ~17 ~7 ~6 ~17 obsidian 0 
setblock ~8 ~4 ~6 nether_brick_fence 0  
fill ~8 ~4 ~8 ~13 ~4 ~8 lava 0  
fill ~8 ~4 ~9 ~13 ~4 ~9 lava 10  
fill ~8 ~4 ~10 ~8 ~5 ~10 lava 10  
fill ~8 ~4 ~11 ~8 ~5 ~11 lava 10  
fill ~8 ~4 ~12 ~8 ~5 ~12 lava 10  
fill ~8 ~4 ~13 ~8 ~5 ~13 lava 10  
fill ~8 ~4 ~14 ~11 ~4 ~14 lava 10  
fill ~8 ~4 ~15 ~13 ~4 ~15 lava 0 
setblock ~8 ~4 ~17 nether_brick_fence 0  
fill ~9 ~4 ~10 ~12 ~4 ~10 coal_block 0  
fill ~9 ~4 ~11 ~9 ~6 ~11 coal_block 0  
fill ~9 ~4 ~12 ~9 ~6 ~12 coal_block 0  
fill ~9 ~4 ~13 ~12 ~4 ~13 coal_block 0  
fill ~10 ~4 ~6 ~11 ~4 ~6 nether_brick_fence 0  
fill ~10 ~4 ~17 ~11 ~4 ~17 nether_brick_fence 0  
fill ~12 ~4 ~11 ~12 ~6 ~11 coal_block 0  
fill ~12 ~4 ~12 ~12 ~6 ~12 coal_block 0 
setblock ~12 ~4 ~14 lava 8 
setblock ~13 ~4 ~6 nether_brick_fence 0  
fill ~13 ~4 ~10 ~13 ~5 ~10 lava 10  
fill ~13 ~4 ~11 ~13 ~5 ~11 lava 10  
fill ~13 ~4 ~12 ~13 ~5 ~12 lava 10  
fill ~13 ~4 ~13 ~13 ~5 ~13 lava 10  
fill ~13 ~4 ~14 ~13 ~5 ~14 lava 10 
setblock ~13 ~4 ~17 nether_brick_fence 0  
fill ~14 ~4 ~6 ~15 ~4 ~6 obsidian 0  
fill ~14 ~4 ~8 ~16 ~4 ~8 obsidian 0  
fill ~14 ~4 ~9 ~14 ~4 ~14 lava 0  
fill ~14 ~4 ~15 ~16 ~4 ~15 obsidian 0  
fill ~14 ~4 ~17 ~15 ~4 ~17 obsidian 0 
setblock ~15 ~4 ~9 obsidian 0  
fill ~15 ~4 ~11 ~15 ~4 ~17 obsidian 0 
setblock ~16 ~4 ~9 nether_brick_fence 0  
fill ~16 ~4 ~11 ~16 ~4 ~12 nether_brick_fence 0 
setblock ~16 ~4 ~14 nether_brick_fence 0 
setblock ~19 ~4 ~8 nether_brick_stairs 6  
fill ~19 ~4 ~9 ~19 ~4 ~14 nether_brick_stairs 4 
setblock ~19 ~4 ~15 nether_brick_stairs 7 
setblock ~20 ~4 ~8 nether_brick_stairs 7 
setblock ~20 ~4 ~15 nether_brick_stairs 6  
fill ~21 ~4 ~8 ~21 ~3 ~8 nether_brick 0 
setblock ~21 ~4 ~9 lava 0 
setblock ~21 ~4 ~10 nether_brick 0  
fill ~21 ~4 ~11 ~21 ~9 ~11 coal_block 0  
fill ~21 ~4 ~12 ~21 ~4 ~13 coal_block 0 
setblock ~21 ~4 ~14 lava 0 
setblock ~21 ~4 ~15 nether_brick 0  
fill ~22 ~4 ~8 ~22 ~5 ~8 stained_glass_pane 15  
fill ~22 ~4 ~9 ~22 ~5 ~9 nether_brick_fence 0 
setblock ~22 ~4 ~10 lava 10  
fill ~22 ~4 ~14 ~22 ~5 ~14 nether_brick_fence 0  
fill ~22 ~4 ~15 ~22 ~5 ~15 stained_glass_pane 15  
fill ~23 ~4 ~8 ~24 ~4 ~8 nether_brick 0 
setblock ~23 ~4 ~9 nether_brick_stairs 0  
fill ~23 ~4 ~10 ~24 ~4 ~10 coal_block 0  
fill ~23 ~4 ~13 ~23 ~5 ~13 lava 0  
fill ~23 ~4 ~14 ~23 ~5 ~14 lava 0  
fill ~23 ~4 ~15 ~24 ~4 ~15 nether_brick 0 
setblock ~24 ~4 ~9 coal_block 0  
fill ~24 ~4 ~11 ~24 ~4 ~14 coal_block 0  
fill ~25 ~4 ~12 ~48 ~4 ~12 portal 1  
fill ~28 ~4 ~4 ~33 ~4 ~4 netherrack 0  
fill ~29 ~4 ~5 ~32 ~4 ~5 netherrack 0  
fill ~49 ~4 ~8 ~50 ~4 ~8 nether_brick 0  
fill ~49 ~4 ~9 ~49 ~4 ~14 coal_block 0  
fill ~49 ~4 ~15 ~50 ~4 ~15 nether_brick 0  
fill ~50 ~4 ~9 ~50 ~5 ~9 lava 0  
fill ~50 ~4 ~10 ~50 ~5 ~10 lava 0  
fill ~50 ~4 ~13 ~50 ~5 ~13 coal_block 0 
setblock ~50 ~4 ~14 nether_brick_stairs 1  
fill ~51 ~4 ~8 ~51 ~5 ~8 stained_glass_pane 15  
fill ~51 ~4 ~9 ~51 ~5 ~9 nether_brick_fence 0 
setblock ~51 ~4 ~13 lava 10  
fill ~51 ~4 ~14 ~51 ~5 ~14 nether_brick_fence 0  
fill ~51 ~4 ~15 ~51 ~5 ~15 stained_glass_pane 15 
setblock ~52 ~4 ~8 nether_brick 0 
setblock ~52 ~4 ~9 lava 0  
fill ~52 ~4 ~10 ~52 ~4 ~12 coal_block 0 
setblock ~52 ~4 ~13 nether_brick 0 
setblock ~52 ~4 ~14 lava 0 
setblock ~52 ~4 ~15 nether_brick 0 
setblock ~53 ~4 ~8 nether_brick_stairs 7 
setblock ~53 ~4 ~15 nether_brick_stairs 6 
setblock ~54 ~4 ~8 nether_brick_stairs 6  
fill ~54 ~4 ~9 ~54 ~4 ~14 nether_brick_stairs 5 
setblock ~54 ~4 ~15 nether_brick_stairs 7  
fill ~57 ~4 ~7 ~68 ~4 ~7 obsidian 0  
fill ~57 ~4 ~8 ~59 ~4 ~8 obsidian 0 
setblock ~57 ~4 ~9 nether_brick_fence 0  
fill ~57 ~4 ~11 ~57 ~4 ~12 nether_brick_fence 0 
setblock ~57 ~4 ~14 nether_brick_fence 0  
fill ~57 ~4 ~15 ~59 ~4 ~15 obsidian 0  
fill ~57 ~4 ~16 ~68 ~4 ~16 obsidian 0  
fill ~58 ~4 ~6 ~59 ~4 ~6 obsidian 0 
setblock ~58 ~4 ~9 obsidian 0  
fill ~58 ~4 ~11 ~58 ~4 ~17 obsidian 0  
fill ~59 ~4 ~9 ~59 ~4 ~14 lava 0  
fill ~59 ~4 ~17 ~59 ~6 ~17 obsidian 0 
setblock ~60 ~4 ~6 nether_brick_fence 0  
fill ~60 ~4 ~8 ~65 ~4 ~8 lava 0  
fill ~60 ~4 ~9 ~65 ~4 ~9 lava 10  
fill ~60 ~4 ~10 ~60 ~5 ~10 lava 10  
fill ~60 ~4 ~11 ~60 ~5 ~11 lava 10  
fill ~60 ~4 ~12 ~60 ~5 ~12 lava 10  
fill ~60 ~4 ~13 ~60 ~5 ~13 lava 10  
fill ~60 ~4 ~14 ~63 ~4 ~14 lava 10  
fill ~60 ~4 ~15 ~65 ~4 ~15 lava 0 
setblock ~60 ~4 ~17 nether_brick_fence 0  
fill ~61 ~4 ~10 ~64 ~4 ~10 coal_block 0  
fill ~61 ~4 ~11 ~61 ~6 ~11 coal_block 0  
fill ~61 ~4 ~12 ~61 ~6 ~12 coal_block 0  
fill ~61 ~4 ~13 ~64 ~4 ~13 coal_block 0  
fill ~62 ~4 ~6 ~63 ~4 ~6 nether_brick_fence 0  
fill ~62 ~4 ~17 ~63 ~4 ~17 nether_brick_fence 0  
fill ~64 ~4 ~11 ~64 ~6 ~11 coal_block 0  
fill ~64 ~4 ~12 ~64 ~6 ~12 coal_block 0 
setblock ~64 ~4 ~14 lava 8 
setblock ~65 ~4 ~6 nether_brick_fence 0  
fill ~65 ~4 ~10 ~65 ~5 ~10 lava 10  
fill ~65 ~4 ~11 ~65 ~5 ~11 lava 10  
fill ~65 ~4 ~12 ~65 ~5 ~12 lava 10  
fill ~65 ~4 ~13 ~65 ~5 ~13 lava 10  
fill ~65 ~4 ~14 ~65 ~5 ~14 lava 10 
setblock ~65 ~4 ~17 nether_brick_fence 0  
fill ~66 ~4 ~6 ~67 ~4 ~6 obsidian 0  
fill ~66 ~4 ~8 ~68 ~4 ~8 obsidian 0  
fill ~66 ~4 ~9 ~66 ~4 ~14 lava 0  
fill ~66 ~4 ~15 ~68 ~4 ~15 obsidian 0  
fill ~66 ~4 ~17 ~67 ~4 ~17 obsidian 0 
setblock ~67 ~4 ~9 obsidian 0  
fill ~67 ~4 ~11 ~67 ~4 ~17 obsidian 0 
setblock ~68 ~4 ~9 nether_brick_fence 0  
fill ~68 ~4 ~11 ~68 ~4 ~12 nether_brick_fence 0 
setblock ~68 ~4 ~14 nether_brick_fence 0  
fill ~5 ~5 ~7 ~7 ~5 ~7 obsidian 0  
fill ~5 ~5 ~8 ~6 ~5 ~8 obsidian 0  
fill ~5 ~5 ~15 ~6 ~5 ~15 obsidian 0  
fill ~5 ~5 ~16 ~7 ~5 ~16 obsidian 0  
fill ~6 ~5 ~6 ~7 ~5 ~6 obsidian 0  
fill ~6 ~5 ~9 ~6 ~5 ~14 stained_glass_pane 15 
setblock ~6 ~5 ~17 obsidian 0 
setblock ~7 ~5 ~8 lava 0  
fill ~7 ~5 ~9 ~7 ~5 ~14 nether_brick_fence 0 
setblock ~7 ~5 ~15 lava 0  
fill ~8 ~5 ~7 ~13 ~5 ~7 stained_glass_pane 15  
fill ~8 ~5 ~8 ~13 ~5 ~8 nether_brick_fence 0  
fill ~8 ~5 ~9 ~13 ~5 ~9 lava 10  
fill ~8 ~5 ~14 ~11 ~5 ~14 lava 10  
fill ~8 ~5 ~15 ~13 ~5 ~15 nether_brick_fence 0  
fill ~8 ~5 ~16 ~13 ~5 ~16 stained_glass_pane 15  
fill ~9 ~5 ~10 ~12 ~5 ~10 coal_block 0  
fill ~9 ~5 ~13 ~12 ~5 ~13 coal_block 0 
setblock ~12 ~5 ~14 lava 0  
fill ~14 ~5 ~6 ~15 ~5 ~6 obsidian 0  
fill ~14 ~5 ~7 ~16 ~5 ~7 obsidian 0 
setblock ~14 ~5 ~8 lava 0  
fill ~14 ~5 ~9 ~14 ~5 ~14 nether_brick_fence 0 
setblock ~14 ~5 ~15 lava 0  
fill ~14 ~5 ~16 ~16 ~5 ~16 obsidian 0  
fill ~14 ~5 ~17 ~15 ~5 ~17 obsidian 0  
fill ~15 ~5 ~8 ~16 ~5 ~8 obsidian 0  
fill ~15 ~5 ~9 ~15 ~5 ~14 stained_glass_pane 15  
fill ~15 ~5 ~15 ~16 ~5 ~15 obsidian 0 
setblock ~19 ~5 ~8 nether_brick_stairs 2  
fill ~19 ~5 ~9 ~19 ~5 ~14 nether_brick_stairs 0 
setblock ~19 ~5 ~15 nether_brick_stairs 3 
setblock ~20 ~5 ~8 nether_brick 0 
setblock ~20 ~5 ~9 lava 0  
fill ~20 ~5 ~10 ~20 ~5 ~12 nether_brick 0  
fill ~20 ~5 ~13 ~20 ~5 ~14 lava 0 
setblock ~20 ~5 ~15 nether_brick 0 
setblock ~21 ~5 ~8 stained_glass_pane 15 
setblock ~21 ~5 ~9 nether_brick_fence 0 
setblock ~21 ~5 ~10 lava 0 
setblock ~21 ~5 ~12 lava 12 
setblock ~21 ~5 ~13 lava 10 
setblock ~21 ~5 ~14 nether_brick_fence 0 
setblock ~21 ~5 ~15 stained_glass_pane 15 
setblock ~22 ~5 ~10 lava 2  
fill ~23 ~5 ~8 ~23 ~4 ~8 nether_brick 0 
setblock ~23 ~5 ~9 nether_brick_stairs 4  
fill ~23 ~5 ~10 ~23 ~4 ~10 coal_block 0 
setblock ~23 ~5 ~11 lava 4 
setblock ~23 ~5 ~12 lava 2  
fill ~23 ~5 ~15 ~23 ~4 ~15 nether_brick 0 
setblock ~24 ~5 ~8 nether_brick_stairs 2  
fill ~24 ~5 ~9 ~24 ~6 ~9 nether_brick 0  
fill ~24 ~5 ~10 ~24 ~5 ~13 nether_brick_stairs 1  
fill ~24 ~5 ~14 ~24 ~6 ~14 nether_brick 0 
setblock ~24 ~5 ~15 nether_brick_stairs 3  
fill ~25 ~5 ~12 ~48 ~5 ~12 portal 1 
setblock ~49 ~5 ~8 nether_brick_stairs 2  
fill ~49 ~5 ~9 ~49 ~6 ~9 nether_brick 0  
fill ~49 ~5 ~10 ~49 ~5 ~13 nether_brick_stairs 0  
fill ~49 ~5 ~14 ~49 ~6 ~14 nether_brick 0 
setblock ~49 ~5 ~15 nether_brick_stairs 3 
setblock ~50 ~5 ~8 nether_brick 0 
setblock ~50 ~5 ~11 lava 2 
setblock ~50 ~5 ~12 lava 4 
setblock ~50 ~5 ~14 nether_brick_stairs 5 
setblock ~50 ~5 ~15 nether_brick 0 
setblock ~51 ~5 ~13 lava 2 
setblock ~52 ~5 ~8 stained_glass_pane 15 
setblock ~52 ~5 ~9 nether_brick_fence 0 
setblock ~52 ~5 ~10 lava 10 
setblock ~52 ~5 ~11 lava 12  
fill ~52 ~5 ~12 ~52 ~9 ~12 coal_block 0 
setblock ~52 ~5 ~13 lava 0 
setblock ~52 ~5 ~14 nether_brick_fence 0 
setblock ~52 ~5 ~15 stained_glass_pane 15 
setblock ~53 ~5 ~8 nether_brick 0  
fill ~53 ~5 ~9 ~53 ~5 ~10 lava 0  
fill ~53 ~5 ~11 ~53 ~5 ~13 nether_brick 0 
setblock ~53 ~5 ~14 lava 0 
setblock ~53 ~5 ~15 nether_brick 0 
setblock ~54 ~5 ~8 nether_brick_stairs 2  
fill ~54 ~5 ~9 ~54 ~5 ~14 nether_brick_stairs 1 
setblock ~54 ~5 ~15 nether_brick_stairs 3  
fill ~57 ~5 ~7 ~59 ~5 ~7 obsidian 0  
fill ~57 ~5 ~8 ~58 ~5 ~8 obsidian 0  
fill ~57 ~5 ~15 ~58 ~5 ~15 obsidian 0  
fill ~57 ~5 ~16 ~59 ~5 ~16 obsidian 0  
fill ~58 ~5 ~6 ~59 ~5 ~6 obsidian 0  
fill ~58 ~5 ~9 ~58 ~5 ~14 stained_glass_pane 15 
setblock ~58 ~5 ~17 obsidian 0 
setblock ~59 ~5 ~8 lava 0  
fill ~59 ~5 ~9 ~59 ~5 ~14 nether_brick_fence 0 
setblock ~59 ~5 ~15 lava 0  
fill ~60 ~5 ~7 ~65 ~5 ~7 stained_glass_pane 15  
fill ~60 ~5 ~8 ~65 ~5 ~8 nether_brick_fence 0  
fill ~60 ~5 ~9 ~65 ~5 ~9 lava 10  
fill ~60 ~5 ~14 ~63 ~5 ~14 lava 10  
fill ~60 ~5 ~15 ~65 ~5 ~15 nether_brick_fence 0  
fill ~60 ~5 ~16 ~65 ~5 ~16 stained_glass_pane 15  
fill ~61 ~5 ~10 ~64 ~5 ~10 coal_block 0  
fill ~61 ~5 ~13 ~64 ~5 ~13 coal_block 0 
setblock ~64 ~5 ~14 lava 0  
fill ~66 ~5 ~6 ~67 ~5 ~6 obsidian 0  
fill ~66 ~5 ~7 ~68 ~5 ~7 obsidian 0 
setblock ~66 ~5 ~8 lava 0  
fill ~66 ~5 ~9 ~66 ~5 ~14 nether_brick_fence 0 
setblock ~66 ~5 ~15 lava 0  
fill ~66 ~5 ~16 ~68 ~5 ~16 obsidian 0  
fill ~66 ~5 ~17 ~67 ~5 ~17 obsidian 0  
fill ~67 ~5 ~8 ~68 ~5 ~8 obsidian 0  
fill ~67 ~5 ~9 ~67 ~5 ~14 stained_glass_pane 15  
fill ~67 ~5 ~15 ~68 ~5 ~15 obsidian 0 
setblock ~5 ~6 ~7 nether_brick_fence 0  
fill ~5 ~6 ~8 ~7 ~6 ~8 obsidian 0 
setblock ~5 ~6 ~10 nether_brick_fence 0 
setblock ~5 ~6 ~12 nether_brick_fence 0 
setblock ~5 ~6 ~14 nether_brick_fence 0  
fill ~5 ~6 ~15 ~7 ~6 ~15 obsidian 0 
setblock ~5 ~6 ~16 nether_brick_fence 0 
setblock ~6 ~6 ~6 nether_brick_fence 0  
fill ~6 ~6 ~7 ~15 ~6 ~7 obsidian 0  
fill ~6 ~6 ~9 ~6 ~6 ~16 obsidian 0 
setblock ~6 ~6 ~17 nether_brick_fence 0 
setblock ~7 ~6 ~6 obsidian 0  
fill ~7 ~6 ~9 ~7 ~6 ~14 lava 0  
fill ~7 ~6 ~16 ~15 ~6 ~16 obsidian 0 
setblock ~8 ~6 ~6 nether_brick_fence 0  
fill ~8 ~6 ~8 ~13 ~6 ~8 lava 0  
fill ~8 ~6 ~9 ~13 ~6 ~9 lava 2  
fill ~8 ~6 ~10 ~8 ~6 ~14 lava 2  
fill ~8 ~6 ~15 ~11 ~6 ~15 lava 0  
fill ~9 ~6 ~10 ~12 ~6 ~10 coal_block 0  
fill ~9 ~6 ~13 ~12 ~6 ~13 coal_block 0  
fill ~9 ~6 ~14 ~11 ~6 ~14 lava 2 
setblock ~9 ~6 ~17 nether_brick_fence 0 
setblock ~10 ~6 ~6 nether_brick_fence 0 
setblock ~11 ~6 ~17 nether_brick_fence 0 
setblock ~12 ~6 ~6 nether_brick_fence 0  
fill ~13 ~6 ~10 ~13 ~6 ~14 lava 2 
setblock ~13 ~6 ~15 lava 0 
setblock ~13 ~6 ~17 nether_brick_fence 0  
fill ~14 ~6 ~6 ~14 ~1 ~6 obsidian 0  
fill ~14 ~6 ~8 ~16 ~6 ~8 obsidian 0  
fill ~14 ~6 ~9 ~14 ~6 ~14 lava 0  
fill ~14 ~6 ~15 ~16 ~6 ~15 obsidian 0  
fill ~14 ~6 ~17 ~14 ~1 ~17 obsidian 0 
setblock ~15 ~6 ~6 nether_brick_fence 0  
fill ~15 ~6 ~9 ~15 ~6 ~16 obsidian 0 
setblock ~15 ~6 ~17 nether_brick_fence 0 
setblock ~16 ~6 ~7 nether_brick_fence 0 
setblock ~16 ~6 ~9 nether_brick_fence 0 
setblock ~16 ~6 ~11 nether_brick_fence 0 
setblock ~16 ~6 ~13 nether_brick_fence 0 
setblock ~16 ~6 ~16 nether_brick_fence 0  
fill ~19 ~6 ~9 ~20 ~6 ~9 coal_block 0  
fill ~19 ~6 ~10 ~20 ~6 ~10 coal_block 0  
fill ~19 ~6 ~11 ~22 ~6 ~11 coal_block 0  
fill ~19 ~6 ~12 ~19 ~7 ~12 coal_block 0  
fill ~19 ~6 ~13 ~19 ~7 ~13 coal_block 0  
fill ~19 ~6 ~14 ~20 ~6 ~14 coal_block 0 
setblock ~20 ~6 ~8 nether_brick_stairs 0 
setblock ~20 ~6 ~12 lava 6 
setblock ~20 ~6 ~13 lava 4 
setblock ~20 ~6 ~15 nether_brick_stairs 0  
fill ~21 ~6 ~8 ~22 ~6 ~8 nether_brick 0  
fill ~21 ~6 ~12 ~22 ~6 ~12 lava 4  
fill ~21 ~6 ~13 ~22 ~6 ~13 lava 2  
fill ~21 ~6 ~14 ~22 ~6 ~14 lava 0  
fill ~21 ~6 ~15 ~22 ~6 ~15 nether_brick 0 
setblock ~23 ~6 ~8 nether_brick_stairs 2 
setblock ~23 ~6 ~9 nether_brick 0  
fill ~23 ~6 ~10 ~23 ~6 ~13 nether_brick_stairs 1 
setblock ~23 ~6 ~14 nether_brick 0 
setblock ~23 ~6 ~15 nether_brick_stairs 3  
fill ~24 ~6 ~12 ~49 ~6 ~12 portal 1 
setblock ~25 ~6 ~9 nether_brick_stairs 5 
setblock ~25 ~6 ~14 nether_brick_stairs 5 
setblock ~48 ~6 ~9 nether_brick_stairs 4 
setblock ~48 ~6 ~14 nether_brick_stairs 4 
setblock ~50 ~6 ~8 nether_brick_stairs 2 
setblock ~50 ~6 ~9 nether_brick 0  
fill ~50 ~6 ~10 ~50 ~6 ~13 nether_brick_stairs 0 
setblock ~50 ~6 ~14 nether_brick 0 
setblock ~50 ~6 ~15 nether_brick_stairs 3  
fill ~51 ~6 ~8 ~52 ~6 ~8 nether_brick 0  
fill ~51 ~6 ~9 ~52 ~6 ~9 lava 0  
fill ~51 ~6 ~10 ~52 ~6 ~10 lava 2  
fill ~51 ~6 ~11 ~52 ~6 ~11 lava 4  
fill ~51 ~6 ~15 ~52 ~6 ~15 nether_brick 0 
setblock ~53 ~6 ~8 nether_brick_stairs 1  
fill ~53 ~6 ~9 ~54 ~6 ~9 coal_block 0 
setblock ~53 ~6 ~10 lava 4 
setblock ~53 ~6 ~11 lava 6  
fill ~53 ~6 ~12 ~54 ~6 ~12 coal_block 0  
fill ~53 ~6 ~13 ~54 ~6 ~13 coal_block 0  
fill ~53 ~6 ~14 ~54 ~6 ~14 coal_block 0 
setblock ~53 ~6 ~15 nether_brick_stairs 1  
fill ~54 ~6 ~10 ~54 ~7 ~10 coal_block 0  
fill ~54 ~6 ~11 ~54 ~7 ~11 coal_block 0 
setblock ~57 ~6 ~7 nether_brick_fence 0  
fill ~57 ~6 ~8 ~59 ~6 ~8 obsidian 0 
setblock ~57 ~6 ~10 nether_brick_fence 0 
setblock ~57 ~6 ~12 nether_brick_fence 0 
setblock ~57 ~6 ~14 nether_brick_fence 0  
fill ~57 ~6 ~15 ~59 ~6 ~15 obsidian 0 
setblock ~57 ~6 ~16 nether_brick_fence 0 
setblock ~58 ~6 ~6 nether_brick_fence 0  
fill ~58 ~6 ~7 ~67 ~6 ~7 obsidian 0  
fill ~58 ~6 ~9 ~58 ~6 ~16 obsidian 0 
setblock ~58 ~6 ~17 nether_brick_fence 0 
setblock ~59 ~6 ~6 obsidian 0  
fill ~59 ~6 ~9 ~59 ~6 ~14 lava 0  
fill ~59 ~6 ~16 ~67 ~6 ~16 obsidian 0 
setblock ~60 ~6 ~6 nether_brick_fence 0  
fill ~60 ~6 ~8 ~65 ~6 ~8 lava 0  
fill ~60 ~6 ~9 ~65 ~6 ~9 lava 2  
fill ~60 ~6 ~10 ~60 ~6 ~14 lava 2  
fill ~60 ~6 ~15 ~63 ~6 ~15 lava 0  
fill ~61 ~6 ~10 ~64 ~6 ~10 coal_block 0  
fill ~61 ~6 ~13 ~64 ~6 ~13 coal_block 0  
fill ~61 ~6 ~14 ~63 ~6 ~14 lava 2 
setblock ~61 ~6 ~17 nether_brick_fence 0 
setblock ~62 ~6 ~6 nether_brick_fence 0 
setblock ~63 ~6 ~17 nether_brick_fence 0 
setblock ~64 ~6 ~6 nether_brick_fence 0  
fill ~65 ~6 ~10 ~65 ~6 ~14 lava 2 
setblock ~65 ~6 ~15 lava 0 
setblock ~65 ~6 ~17 nether_brick_fence 0  
fill ~66 ~6 ~6 ~66 ~1 ~6 obsidian 0  
fill ~66 ~6 ~8 ~68 ~6 ~8 obsidian 0  
fill ~66 ~6 ~9 ~66 ~6 ~14 lava 0  
fill ~66 ~6 ~15 ~68 ~6 ~15 obsidian 0  
fill ~66 ~6 ~17 ~66 ~1 ~17 obsidian 0 
setblock ~67 ~6 ~6 nether_brick_fence 0  
fill ~67 ~6 ~9 ~67 ~6 ~16 obsidian 0 
setblock ~67 ~6 ~17 nether_brick_fence 0 
setblock ~68 ~6 ~7 nether_brick_fence 0 
setblock ~68 ~6 ~9 nether_brick_fence 0 
setblock ~68 ~6 ~11 nether_brick_fence 0 
setblock ~68 ~6 ~13 nether_brick_fence 0 
setblock ~68 ~6 ~16 nether_brick_fence 0  
fill ~6 ~7 ~8 ~7 ~7 ~8 obsidian 0 
setblock ~6 ~7 ~9 nether_brick_fence 0  
fill ~6 ~7 ~11 ~6 ~11 ~11 coal_block 0  
fill ~6 ~7 ~12 ~6 ~11 ~12 coal_block 0 
setblock ~6 ~7 ~14 nether_brick_fence 0  
fill ~6 ~7 ~15 ~7 ~7 ~15 obsidian 0 
setblock ~7 ~7 ~7 obsidian 0  
fill ~7 ~7 ~9 ~8 ~7 ~9 coal_block 0  
fill ~7 ~7 ~10 ~7 ~7 ~9 coal_block 0  
fill ~7 ~7 ~11 ~8 ~7 ~11 obsidian 0  
fill ~7 ~7 ~12 ~8 ~7 ~12 obsidian 0  
fill ~7 ~7 ~13 ~7 ~7 ~14 coal_block 0  
fill ~7 ~7 ~16 ~7 ~1 ~16 obsidian 0 
setblock ~8 ~7 ~7 nether_brick_fence 0  
fill ~8 ~7 ~8 ~9 ~7 ~8 coal_block 0  
fill ~8 ~7 ~10 ~8 ~8 ~10 obsidian 0  
fill ~8 ~7 ~13 ~8 ~8 ~13 obsidian 0  
fill ~8 ~7 ~14 ~8 ~7 ~15 coal_block 0 
setblock ~8 ~7 ~16 nether_brick_fence 0  
fill ~9 ~7 ~9 ~12 ~7 ~9 obsidian 0  
fill ~9 ~7 ~14 ~12 ~7 ~14 obsidian 0 
setblock ~9 ~7 ~15 coal_block 0  
fill ~10 ~7 ~7 ~11 ~7 ~7 coal_block 0  
fill ~10 ~7 ~8 ~11 ~7 ~8 obsidian 0  
fill ~10 ~7 ~15 ~11 ~7 ~15 obsidian 0  
fill ~10 ~7 ~16 ~11 ~7 ~16 coal_block 0  
fill ~12 ~7 ~8 ~13 ~7 ~8 coal_block 0  
fill ~12 ~7 ~15 ~13 ~7 ~15 coal_block 0 
setblock ~13 ~7 ~7 nether_brick_fence 0  
fill ~13 ~7 ~9 ~14 ~7 ~9 coal_block 0  
fill ~13 ~7 ~10 ~13 ~8 ~10 obsidian 0  
fill ~13 ~7 ~11 ~14 ~7 ~11 obsidian 0  
fill ~13 ~7 ~12 ~14 ~7 ~12 obsidian 0  
fill ~13 ~7 ~13 ~13 ~8 ~13 obsidian 0  
fill ~13 ~7 ~14 ~14 ~7 ~14 coal_block 0 
setblock ~13 ~7 ~16 nether_brick_fence 0  
fill ~14 ~7 ~7 ~14 ~7 ~8 obsidian 0 
setblock ~14 ~7 ~10 coal_block 0 
setblock ~14 ~7 ~13 coal_block 0  
fill ~14 ~7 ~15 ~15 ~7 ~15 obsidian 0  
fill ~14 ~7 ~16 ~14 ~7 ~15 obsidian 0 
setblock ~15 ~7 ~8 obsidian 0 
setblock ~15 ~7 ~9 nether_brick_fence 0  
fill ~15 ~7 ~11 ~15 ~11 ~11 coal_block 0  
fill ~15 ~7 ~12 ~15 ~11 ~12 coal_block 0 
setblock ~15 ~7 ~14 nether_brick_fence 0  
fill ~18 ~7 ~9 ~22 ~7 ~9 coal_block 0  
fill ~18 ~7 ~10 ~22 ~7 ~10 coal_block 0  
fill ~18 ~7 ~11 ~19 ~7 ~11 coal_block 0  
fill ~18 ~7 ~12 ~18 ~8 ~12 coal_block 0  
fill ~18 ~7 ~13 ~18 ~8 ~13 coal_block 0  
fill ~18 ~7 ~14 ~22 ~7 ~14 coal_block 0  
fill ~22 ~7 ~12 ~22 ~8 ~12 coal_block 0  
fill ~22 ~7 ~13 ~22 ~8 ~13 coal_block 0  
fill ~23 ~7 ~12 ~50 ~7 ~12 portal 1 
setblock ~24 ~7 ~9 nether_brick_stairs 0 
setblock ~24 ~7 ~14 nether_brick_stairs 0 
setblock ~25 ~7 ~8 wool 0 
setblock ~25 ~7 ~9 stone_slab 7 
setblock ~25 ~7 ~14 stone_slab 7 
setblock ~25 ~7 ~15 wool 0 
setblock ~48 ~7 ~9 stone_slab 7 
setblock ~48 ~7 ~14 stone_slab 7 
setblock ~48 ~7 ~15 wool 0 
setblock ~49 ~7 ~9 nether_brick_stairs 1 
setblock ~49 ~7 ~14 nether_brick_stairs 1  
fill ~51 ~7 ~9 ~55 ~7 ~9 coal_block 0  
fill ~51 ~7 ~10 ~51 ~8 ~10 coal_block 0  
fill ~51 ~7 ~11 ~51 ~8 ~11 coal_block 0  
fill ~51 ~7 ~13 ~55 ~7 ~13 coal_block 0  
fill ~51 ~7 ~14 ~55 ~7 ~14 coal_block 0  
fill ~54 ~7 ~12 ~55 ~7 ~12 coal_block 0  
fill ~55 ~7 ~10 ~55 ~8 ~10 coal_block 0  
fill ~55 ~7 ~11 ~55 ~8 ~11 coal_block 0  
fill ~58 ~7 ~8 ~59 ~7 ~8 obsidian 0 
setblock ~58 ~7 ~9 nether_brick_fence 0  
fill ~58 ~7 ~11 ~58 ~11 ~11 coal_block 0  
fill ~58 ~7 ~12 ~58 ~11 ~12 coal_block 0 
setblock ~58 ~7 ~14 nether_brick_fence 0  
fill ~58 ~7 ~15 ~59 ~7 ~15 obsidian 0 
setblock ~59 ~7 ~7 obsidian 0  
fill ~59 ~7 ~9 ~60 ~7 ~9 coal_block 0  
fill ~59 ~7 ~10 ~59 ~7 ~9 coal_block 0  
fill ~59 ~7 ~11 ~60 ~7 ~11 obsidian 0  
fill ~59 ~7 ~12 ~60 ~7 ~12 obsidian 0  
fill ~59 ~7 ~13 ~59 ~7 ~14 coal_block 0  
fill ~59 ~7 ~16 ~59 ~1 ~16 obsidian 0 
setblock ~60 ~7 ~7 nether_brick_fence 0  
fill ~60 ~7 ~8 ~61 ~7 ~8 coal_block 0  
fill ~60 ~7 ~10 ~60 ~8 ~10 obsidian 0  
fill ~60 ~7 ~13 ~60 ~8 ~13 obsidian 0  
fill ~60 ~7 ~14 ~60 ~7 ~15 coal_block 0 
setblock ~60 ~7 ~16 nether_brick_fence 0  
fill ~61 ~7 ~9 ~64 ~7 ~9 obsidian 0  
fill ~61 ~7 ~14 ~64 ~7 ~14 obsidian 0 
setblock ~61 ~7 ~15 coal_block 0  
fill ~62 ~7 ~7 ~63 ~7 ~7 coal_block 0  
fill ~62 ~7 ~8 ~63 ~7 ~8 obsidian 0   
fill ~62 ~7 ~15 ~63 ~7 ~15 obsidian 0  
fill ~62 ~7 ~16 ~63 ~7 ~16 coal_block 0  
fill ~64 ~7 ~8 ~65 ~7 ~8 coal_block 0  
fill ~64 ~7 ~15 ~65 ~7 ~15 coal_block 0 
setblock ~65 ~7 ~7 nether_brick_fence 0  
fill ~65 ~7 ~9 ~66 ~7 ~9 coal_block 0  
fill ~65 ~7 ~10 ~65 ~8 ~10 obsidian 0  
fill ~65 ~7 ~11 ~66 ~7 ~11 obsidian 0  
fill ~65 ~7 ~12 ~66 ~7 ~12 obsidian 0  
fill ~65 ~7 ~13 ~65 ~8 ~13 obsidian 0  
fill ~65 ~7 ~14 ~66 ~7 ~14 coal_block 0 
setblock ~65 ~7 ~16 nether_brick_fence 0  
fill ~66 ~7 ~7 ~66 ~7 ~8 obsidian 0 
setblock ~66 ~7 ~10 coal_block 0 
setblock ~66 ~7 ~13 coal_block 0  
fill ~66 ~7 ~15 ~67 ~7 ~15 obsidian 0  
fill ~66 ~7 ~16 ~66 ~7 ~15 obsidian 0 
setblock ~67 ~7 ~8 obsidian 0 
setblock ~67 ~7 ~9 nether_brick_fence 0  
fill ~67 ~7 ~11 ~67 ~11 ~11 coal_block 0  
fill ~67 ~7 ~12 ~67 ~11 ~12 coal_block 0 
setblock ~67 ~7 ~14 nether_brick_fence 0 
setblock ~7 ~8 ~8 nether_brick_fence 0  
fill ~7 ~8 ~11 ~8 ~8 ~11 obsidian 0  
fill ~7 ~8 ~12 ~8 ~8 ~12 obsidian 0 
setblock ~7 ~8 ~15 nether_brick_fence 0  
fill ~9 ~8 ~9 ~12 ~8 ~9 obsidian 0  
fill ~9 ~8 ~10 ~9 ~12 ~10 coal_block 0  
fill ~9 ~8 ~13 ~9 ~12 ~13 coal_block 0  
fill ~9 ~8 ~14 ~12 ~8 ~14 obsidian 0  
fill ~10 ~8 ~7 ~11 ~8 ~7 coal_block 0  
fill ~10 ~8 ~8 ~11 ~8 ~8 obsidian 0  
fill ~10 ~8 ~15 ~11 ~8 ~15 obsidian 0  
fill ~10 ~8 ~16 ~11 ~8 ~16 coal_block 0  
fill ~12 ~8 ~10 ~12 ~12 ~10 coal_block 0  
fill ~12 ~8 ~13 ~12 ~12 ~13 coal_block 0  
fill ~13 ~8 ~11 ~14 ~8 ~11 obsidian 0  
fill ~13 ~8 ~12 ~14 ~8 ~12 obsidian 0 
setblock ~14 ~8 ~8 nether_brick_fence 0 
setblock ~14 ~8 ~15 nether_brick_fence 0  
fill ~18 ~8 ~9 ~22 ~8 ~9 coal_block 0  
fill ~18 ~8 ~10 ~18 ~7 ~10 coal_block 0  
fill ~18 ~8 ~11 ~18 ~7 ~11 coal_block 0  
fill ~18 ~8 ~14 ~22 ~8 ~14 coal_block 0  
fill ~21 ~8 ~10 ~22 ~8 ~10 coal_block 0  
fill ~23 ~8 ~12 ~50 ~8 ~12 portal 1  
fill ~51 ~8 ~9 ~55 ~8 ~9 coal_block 0  
fill ~51 ~8 ~13 ~52 ~8 ~13 coal_block 0  
fill ~51 ~8 ~14 ~55 ~8 ~14 coal_block 0  
fill ~55 ~8 ~12 ~55 ~8 ~14 coal_block 0 
setblock ~59 ~8 ~8 nether_brick_fence 0  
fill ~59 ~8 ~11 ~60 ~8 ~11 obsidian 0  
fill ~59 ~8 ~12 ~60 ~8 ~12 obsidian 0 
setblock ~59 ~8 ~15 nether_brick_fence 0  
fill ~61 ~8 ~9 ~64 ~8 ~9 obsidian 0  
fill ~61 ~8 ~10 ~61 ~12 ~10 coal_block 0  
fill ~61 ~8 ~13 ~61 ~12 ~13 coal_block 0  
fill ~61 ~8 ~14 ~64 ~8 ~14 obsidian 0  
fill ~62 ~8 ~7 ~63 ~8 ~7 coal_block 0  
fill ~62 ~8 ~8 ~63 ~8 ~8 obsidian 0  
fill ~62 ~8 ~15 ~63 ~8 ~15 obsidian 0  
fill ~62 ~8 ~16 ~63 ~8 ~16 coal_block 0  
fill ~64 ~8 ~10 ~64 ~12 ~10 coal_block 0  
fill ~64 ~8 ~13 ~64 ~12 ~13 coal_block 0  
fill ~65 ~8 ~11 ~66 ~8 ~11 obsidian 0  
fill ~65 ~8 ~12 ~66 ~8 ~12 obsidian 0 
setblock ~66 ~8 ~8 nether_brick_fence 0 
setblock ~66 ~8 ~15 nether_brick_fence 0  
fill ~7 ~9 ~11 ~8 ~9 ~11 coal_block 0  
fill ~7 ~9 ~12 ~8 ~9 ~12 coal_block 0  
fill ~8 ~9 ~10 ~8 ~12 ~10 coal_block 0  
fill ~8 ~9 ~13 ~8 ~12 ~13 coal_block 0  
fill ~9 ~9 ~9 ~12 ~9 ~9 coal_block 0  
fill ~9 ~9 ~14 ~12 ~9 ~14 coal_block 0  
fill ~10 ~9 ~7 ~11 ~9 ~7 coal_block 0  
fill ~10 ~9 ~8 ~11 ~9 ~8 coal_block 0  
fill ~10 ~9 ~15 ~11 ~9 ~15 coal_block 0  
fill ~10 ~9 ~16 ~11 ~9 ~16 coal_block 0  
fill ~13 ~9 ~10 ~13 ~12 ~10 coal_block 0  
fill ~13 ~9 ~11 ~15 ~9 ~11 coal_block 0  
fill ~13 ~9 ~12 ~15 ~9 ~12 coal_block 0  
fill ~13 ~9 ~13 ~13 ~12 ~13 coal_block 0  
fill ~17 ~9 ~9 ~21 ~9 ~9 coal_block 0  
fill ~17 ~9 ~10 ~17 ~12 ~10 coal_block 0  
fill ~17 ~9 ~11 ~17 ~12 ~11 coal_block 0  
fill ~17 ~9 ~12 ~17 ~12 ~12 coal_block 0  
fill ~17 ~9 ~13 ~17 ~12 ~13 coal_block 0  
fill ~17 ~9 ~14 ~21 ~9 ~14 coal_block 0  
fill ~21 ~9 ~10 ~21 ~7 ~10 coal_block 0  
fill ~21 ~9 ~12 ~21 ~9 ~14 coal_block 0  
fill ~22 ~9 ~12 ~51 ~9 ~12 portal 1  
fill ~52 ~9 ~9 ~56 ~9 ~9 coal_block 0  
fill ~52 ~9 ~10 ~52 ~9 ~14 coal_block 0  
fill ~53 ~9 ~14 ~56 ~9 ~14 coal_block 0  
fill ~56 ~9 ~10 ~56 ~14 ~10 coal_block 0  
fill ~56 ~9 ~11 ~56 ~14 ~11 coal_block 0  
fill ~56 ~9 ~12 ~56 ~12 ~12 coal_block 0  
fill ~56 ~9 ~13 ~56 ~12 ~13 coal_block 0  
fill ~59 ~9 ~11 ~60 ~9 ~11 coal_block 0  
fill ~59 ~9 ~12 ~60 ~9 ~12 coal_block 0  
fill ~60 ~9 ~10 ~60 ~12 ~10 coal_block 0  
fill ~60 ~9 ~13 ~60 ~12 ~13 coal_block 0  
fill ~61 ~9 ~9 ~64 ~9 ~9 coal_block 0  
fill ~61 ~9 ~14 ~64 ~9 ~14 coal_block 0  
fill ~62 ~9 ~7 ~63 ~9 ~7 coal_block 0  
fill ~62 ~9 ~8 ~63 ~9 ~8 coal_block 0  
fill ~62 ~9 ~15 ~63 ~9 ~15 coal_block 0  
fill ~62 ~9 ~16 ~63 ~9 ~16 coal_block 0  
fill ~65 ~9 ~10 ~65 ~12 ~10 coal_block 0  
fill ~65 ~9 ~11 ~67 ~9 ~11 coal_block 0  
fill ~65 ~9 ~12 ~67 ~9 ~12 coal_block 0  
fill ~65 ~9 ~13 ~65 ~12 ~13 coal_block 0  
fill ~7 ~10 ~11 ~8 ~10 ~11 coal_block 0  
fill ~7 ~10 ~12 ~8 ~10 ~12 coal_block 0  
fill ~9 ~10 ~9 ~12 ~10 ~9 coal_block 0  
fill ~9 ~10 ~14 ~12 ~10 ~14 coal_block 0  
fill ~10 ~10 ~7 ~11 ~10 ~7 coal_block 0  
fill ~10 ~10 ~8 ~11 ~10 ~8 coal_block 0  
fill ~10 ~10 ~15 ~11 ~10 ~15 coal_block 0  
fill ~10 ~10 ~16 ~11 ~10 ~16 coal_block 0  
fill ~13 ~10 ~11 ~15 ~10 ~11 coal_block 0  
fill ~13 ~10 ~12 ~15 ~10 ~12 coal_block 0  
fill ~17 ~10 ~9 ~20 ~10 ~9 coal_block 0  
fill ~17 ~10 ~14 ~20 ~10 ~14 coal_block 0  
fill ~20 ~10 ~10 ~20 ~12 ~10 coal_block 0  
fill ~20 ~10 ~11 ~20 ~12 ~11 coal_block 0  
fill ~20 ~10 ~12 ~20 ~12 ~12 coal_block 0  
fill ~20 ~10 ~13 ~20 ~12 ~13 coal_block 0  
fill ~21 ~10 ~12 ~52 ~10 ~12 portal 1  
fill ~53 ~10 ~9 ~56 ~10 ~9 coal_block 0  
fill ~53 ~10 ~10 ~53 ~12 ~10 coal_block 0  
fill ~53 ~10 ~11 ~53 ~12 ~11 coal_block 0  
fill ~53 ~10 ~12 ~53 ~12 ~12 coal_block 0  
fill ~53 ~10 ~13 ~53 ~12 ~13 coal_block 0  
fill ~53 ~10 ~14 ~56 ~10 ~14 coal_block 0  
fill ~59 ~10 ~11 ~60 ~10 ~11 coal_block 0  
fill ~59 ~10 ~12 ~60 ~10 ~12 coal_block 0  
fill ~61 ~10 ~9 ~64 ~10 ~9 coal_block 0  
fill ~61 ~10 ~14 ~64 ~10 ~14 coal_block 0  
fill ~62 ~10 ~7 ~63 ~10 ~7 coal_block 0  
fill ~62 ~10 ~8 ~63 ~10 ~8 coal_block 0  
fill ~62 ~10 ~15 ~63 ~10 ~15 coal_block 0  
fill ~62 ~10 ~16 ~63 ~10 ~16 coal_block 0  
fill ~65 ~10 ~11 ~67 ~10 ~11 coal_block 0  
fill ~65 ~10 ~12 ~67 ~10 ~12 coal_block 0  
fill ~7 ~11 ~11 ~8 ~11 ~11 coal_block 0  
fill ~7 ~11 ~12 ~8 ~11 ~12 coal_block 0  
fill ~9 ~11 ~9 ~12 ~11 ~9 coal_block 0  
fill ~9 ~11 ~14 ~12 ~11 ~14 coal_block 0  
fill ~10 ~11 ~7 ~11 ~11 ~7 coal_block 0  
fill ~10 ~11 ~8 ~11 ~11 ~8 coal_block 0  
fill ~10 ~11 ~15 ~11 ~11 ~15 coal_block 0  
fill ~10 ~11 ~16 ~11 ~11 ~16 coal_block 0  
fill ~13 ~11 ~11 ~15 ~11 ~11 coal_block 0  
fill ~13 ~11 ~12 ~15 ~11 ~12 coal_block 0  
fill ~17 ~11 ~9 ~20 ~11 ~9 coal_block 0  
fill ~17 ~11 ~14 ~20 ~11 ~14 coal_block 0  
fill ~21 ~11 ~12 ~52 ~11 ~12 portal 1  
fill ~53 ~11 ~9 ~56 ~11 ~9 coal_block 0  
fill ~53 ~11 ~14 ~56 ~11 ~14 coal_block 0  
fill ~59 ~11 ~11 ~60 ~11 ~11 coal_block 0  
fill ~59 ~11 ~12 ~60 ~11 ~12 coal_block 0  
fill ~61 ~11 ~9 ~64 ~11 ~9 coal_block 0  
fill ~61 ~11 ~14 ~64 ~11 ~14 coal_block 0  
fill ~62 ~11 ~7 ~63 ~11 ~7 coal_block 0  
fill ~62 ~11 ~8 ~63 ~11 ~8 coal_block 0  
fill ~62 ~11 ~15 ~63 ~11 ~15 coal_block 0  
fill ~62 ~11 ~16 ~63 ~11 ~16 coal_block 0  
fill ~65 ~11 ~11 ~67 ~11 ~11 coal_block 0  
fill ~65 ~11 ~12 ~67 ~11 ~12 coal_block 0 
setblock ~6 ~12 ~11 nether_brick_fence 0  
fill ~7 ~12 ~11 ~8 ~12 ~11 coal_block 0  
fill ~7 ~12 ~12 ~8 ~12 ~12 coal_block 0  
fill ~9 ~12 ~9 ~12 ~12 ~9 coal_block 0  
fill ~9 ~12 ~14 ~12 ~12 ~14 coal_block 0  
fill ~10 ~12 ~8 ~11 ~12 ~8 coal_block 0  
fill ~10 ~12 ~15 ~11 ~12 ~15 coal_block 0 
setblock ~11 ~12 ~16 nether_brick_fence 0  
fill ~12 ~12 ~12 ~14 ~12 ~12 coal_block 0  
fill ~13 ~12 ~11 ~14 ~12 ~11 coal_block 0 
setblock ~15 ~12 ~12 nether_brick_fence 0 
setblock ~16 ~12 ~17 nether_brick 0  
fill ~17 ~12 ~9 ~20 ~12 ~9 coal_block 0  
fill ~17 ~12 ~14 ~20 ~12 ~14 coal_block 0  
fill ~21 ~12 ~12 ~52 ~12 ~12 portal 1  
fill ~53 ~12 ~9 ~56 ~12 ~9 coal_block 0  
fill ~53 ~12 ~14 ~56 ~12 ~14 coal_block 0 
setblock ~58 ~12 ~11 nether_brick_fence 0  
fill ~59 ~12 ~11 ~60 ~12 ~11 coal_block 0  
fill ~59 ~12 ~12 ~60 ~12 ~12 coal_block 0  
fill ~61 ~12 ~9 ~64 ~12 ~9 coal_block 0  
fill ~61 ~12 ~14 ~64 ~12 ~14 coal_block 0  
fill ~62 ~12 ~8 ~63 ~12 ~8 coal_block 0  
fill ~62 ~12 ~15 ~63 ~12 ~15 coal_block 0 
setblock ~63 ~12 ~16 nether_brick_fence 0  
fill ~65 ~12 ~11 ~66 ~12 ~11 coal_block 0  
fill ~65 ~12 ~12 ~66 ~12 ~12 coal_block 0 
setblock ~67 ~12 ~12 nether_brick_fence 0  
fill ~8 ~13 ~10 ~9 ~13 ~10 obsidian 0  
fill ~8 ~13 ~11 ~8 ~13 ~13 obsidian 0  
fill ~9 ~13 ~9 ~12 ~13 ~9 obsidian 0  
fill ~9 ~13 ~11 ~9 ~15 ~11 coal_block 0  
fill ~9 ~13 ~12 ~9 ~15 ~12 coal_block 0  
fill ~9 ~13 ~13 ~9 ~13 ~14 obsidian 0  
fill ~10 ~13 ~14 ~12 ~13 ~14 obsidian 0  
fill ~12 ~13 ~10 ~13 ~13 ~10 obsidian 0  
fill ~12 ~13 ~12 ~12 ~15 ~12 coal_block 0  
fill ~12 ~13 ~13 ~13 ~13 ~13 obsidian 0  
fill ~13 ~13 ~11 ~13 ~13 ~13 obsidian 0  
fill ~16 ~13 ~9 ~19 ~13 ~9 coal_block 0  
fill ~16 ~13 ~10 ~16 ~15 ~10 coal_block 0  
fill ~16 ~13 ~11 ~16 ~20 ~11 coal_block 0  
fill ~16 ~13 ~12 ~16 ~20 ~12 coal_block 0  
fill ~16 ~13 ~13 ~16 ~15 ~13 coal_block 0  
fill ~16 ~13 ~14 ~19 ~13 ~14 coal_block 0  
fill ~19 ~13 ~10 ~19 ~16 ~10 coal_block 0  
fill ~19 ~13 ~11 ~19 ~16 ~11 coal_block 0  
fill ~19 ~13 ~12 ~19 ~16 ~12 coal_block 0  
fill ~19 ~13 ~13 ~19 ~15 ~13 coal_block 0  
fill ~20 ~13 ~12 ~53 ~13 ~12 portal 1  
fill ~54 ~13 ~9 ~57 ~13 ~9 coal_block 0  
fill ~54 ~13 ~10 ~57 ~13 ~10 coal_block 0  
fill ~54 ~13 ~11 ~57 ~13 ~11 coal_block 0  
fill ~54 ~13 ~12 ~54 ~17 ~12 coal_block 0  
fill ~54 ~13 ~13 ~54 ~17 ~13 coal_block 0  
fill ~54 ~13 ~14 ~57 ~13 ~14 coal_block 0  
fill ~57 ~13 ~12 ~57 ~20 ~12 coal_block 0  
fill ~57 ~13 ~13 ~57 ~16 ~13 coal_block 0 
setblock ~59 ~13 ~10 nether_brick_fence 0 
setblock ~59 ~13 ~12 nether_brick_fence 0  
fill ~60 ~13 ~10 ~61 ~13 ~10 obsidian 0  
fill ~60 ~13 ~11 ~60 ~13 ~13 obsidian 0 
setblock ~60 ~13 ~14 nether_brick_fence 0 
setblock ~61 ~13 ~8 nether_brick_fence 0  
fill ~61 ~13 ~9 ~64 ~13 ~9 obsidian 0  
fill ~61 ~13 ~13 ~61 ~13 ~14 obsidian 0  
fill ~62 ~13 ~14 ~64 ~13 ~14 obsidian 0 
setblock ~62 ~13 ~15 nether_brick_fence 0 
setblock ~63 ~13 ~8 nether_brick_fence 0  
fill ~64 ~13 ~10 ~65 ~13 ~10 obsidian 0  
fill ~64 ~13 ~13 ~65 ~13 ~13 obsidian 0 
setblock ~64 ~13 ~15 nether_brick_fence 0 
setblock ~65 ~13 ~9 nether_brick_fence 0  
fill ~65 ~13 ~11 ~65 ~13 ~13 obsidian 0 
setblock ~66 ~13 ~11 nether_brick_fence 0 
setblock ~66 ~13 ~13 nether_brick_fence 0  
fill ~10 ~14 ~10 ~11 ~14 ~10 coal_block 0  
fill ~10 ~14 ~13 ~11 ~14 ~13 coal_block 0  
fill ~12 ~14 ~11 ~12 ~15 ~11 coal_block 0  
fill ~14 ~14 ~11 ~15 ~14 ~11 obsidian 0  
fill ~14 ~14 ~12 ~15 ~14 ~12 obsidian 0  
fill ~16 ~14 ~9 ~19 ~14 ~9 coal_block 0  
fill ~16 ~14 ~14 ~19 ~14 ~14 coal_block 0  
fill ~20 ~14 ~12 ~53 ~14 ~12 portal 1  
fill ~54 ~14 ~9 ~57 ~14 ~9 coal_block 0  
fill ~54 ~14 ~10 ~57 ~14 ~10 coal_block 0  
fill ~54 ~14 ~11 ~54 ~17 ~11 coal_block 0  
fill ~54 ~14 ~14 ~57 ~14 ~14 coal_block 0  
fill ~57 ~14 ~11 ~57 ~20 ~11 coal_block 0 
setblock ~60 ~14 ~11 nether_brick_fence 0  
fill ~61 ~14 ~11 ~61 ~16 ~11 coal_block 0  
fill ~61 ~14 ~12 ~61 ~16 ~12 coal_block 0 
setblock ~61 ~14 ~13 nether_brick_fence 0 
setblock ~62 ~14 ~9 nether_brick_fence 0  
fill ~62 ~14 ~10 ~63 ~14 ~10 coal_block 0  
fill ~62 ~14 ~13 ~63 ~14 ~13 coal_block 0 
setblock ~63 ~14 ~14 nether_brick_fence 0 
setblock ~64 ~14 ~10 nether_brick_fence 0  
fill ~64 ~14 ~11 ~64 ~16 ~11 coal_block 0  
fill ~64 ~14 ~12 ~64 ~16 ~12 coal_block 0 
setblock ~65 ~14 ~12 nether_brick_fence 0  
fill ~10 ~15 ~10 ~11 ~15 ~10 coal_block 0  
fill ~10 ~15 ~11 ~12 ~15 ~11 coal_block 0  
fill ~10 ~15 ~12 ~12 ~15 ~12 coal_block 0  
fill ~10 ~15 ~13 ~11 ~15 ~13 coal_block 0  
fill ~13 ~15 ~10 ~14 ~15 ~10 obsidian 0  
fill ~13 ~15 ~11 ~14 ~15 ~11 obsidian 0  
fill ~13 ~15 ~12 ~14 ~15 ~12 obsidian 0  
fill ~13 ~15 ~13 ~14 ~15 ~13 obsidian 0 
setblock ~15 ~15 ~8 nether_brick_stairs 6  
fill ~15 ~15 ~9 ~15 ~15 ~14 nether_brick_stairs 4 
setblock ~15 ~15 ~15 nether_brick_stairs 7  
fill ~16 ~15 ~8 ~20 ~15 ~8 nether_brick 0  
fill ~16 ~15 ~9 ~18 ~15 ~9 lava 0  
fill ~16 ~15 ~14 ~18 ~15 ~14 lava 0  
fill ~16 ~15 ~15 ~20 ~15 ~15 nether_brick 0  
fill ~17 ~15 ~10 ~19 ~15 ~10 coal_block 0  
fill ~17 ~15 ~13 ~19 ~15 ~13 coal_block 0 
setblock ~19 ~15 ~9 lava 8  
fill ~19 ~15 ~14 ~20 ~15 ~14 nether_brick 0  
fill ~20 ~15 ~9 ~20 ~15 ~15 nether_brick 0 
setblock ~21 ~15 ~9 nether_brick_stairs 6  
fill ~21 ~15 ~12 ~53 ~15 ~12 portal 1 
setblock ~21 ~15 ~14 nether_brick_stairs 7  
fill ~54 ~15 ~9 ~57 ~15 ~9 coal_block 0  
fill ~54 ~15 ~10 ~54 ~16 ~10 coal_block 0  
fill ~54 ~15 ~14 ~57 ~15 ~14 coal_block 0  
fill ~57 ~15 ~10 ~57 ~16 ~10 coal_block 0  
fill ~58 ~15 ~11 ~59 ~15 ~11 obsidian 0  
fill ~58 ~15 ~12 ~59 ~15 ~12 obsidian 0  
fill ~62 ~15 ~10 ~63 ~15 ~10 coal_block 0  
fill ~62 ~15 ~13 ~63 ~15 ~13 coal_block 0  
fill ~8 ~16 ~10 ~9 ~16 ~10 obsidian 0  
fill ~8 ~16 ~11 ~8 ~16 ~13 obsidian 0  
fill ~9 ~16 ~9 ~12 ~16 ~9 obsidian 0  
fill ~9 ~16 ~11 ~9 ~16 ~12 lava 0  
fill ~9 ~16 ~13 ~9 ~16 ~14 obsidian 0  
fill ~10 ~16 ~10 ~11 ~16 ~10 lava 0  
fill ~10 ~16 ~11 ~11 ~16 ~11 lava 10  
fill ~10 ~16 ~12 ~11 ~16 ~12 lava 10  
fill ~10 ~16 ~13 ~11 ~16 ~13 lava 0  
fill ~10 ~16 ~14 ~12 ~16 ~14 obsidian 0  
fill ~12 ~16 ~10 ~13 ~16 ~10 obsidian 0  
fill ~12 ~16 ~11 ~12 ~16 ~12 lava 0  
fill ~12 ~16 ~13 ~13 ~16 ~13 obsidian 0  
fill ~13 ~16 ~11 ~13 ~18 ~11 obsidian 0  
fill ~13 ~16 ~12 ~13 ~18 ~12 obsidian 0 
setblock ~14 ~16 ~8 nether_brick_stairs 6  
fill ~14 ~16 ~9 ~14 ~16 ~14 nether_brick_stairs 4 
setblock ~14 ~16 ~15 nether_brick_stairs 7  
fill ~15 ~16 ~8 ~15 ~17 ~8 nether_brick 0 
setblock ~15 ~16 ~9 lava 0  
fill ~15 ~16 ~10 ~15 ~16 ~12 coal_block 0 
setblock ~15 ~16 ~13 lava 0 
setblock ~15 ~16 ~14 lava 2  
fill ~15 ~16 ~15 ~15 ~17 ~15 nether_brick 0  
fill ~16 ~16 ~8 ~18 ~16 ~8 stained_glass_pane 15  
fill ~16 ~16 ~9 ~18 ~16 ~9 nether_brick_fence 0  
fill ~16 ~16 ~10 ~18 ~16 ~10 lava 0 
setblock ~16 ~16 ~13 lava 2  
fill ~16 ~16 ~14 ~18 ~16 ~14 nether_brick_fence 0  
fill ~16 ~16 ~15 ~18 ~16 ~15 stained_glass_pane 15  
fill ~17 ~16 ~11 ~19 ~16 ~11 coal_block 0  
fill ~17 ~16 ~12 ~19 ~16 ~12 coal_block 0  
fill ~17 ~16 ~13 ~18 ~16 ~13 lava 4 
setblock ~19 ~16 ~8 nether_brick 0 
setblock ~19 ~16 ~9 lava 0 
setblock ~19 ~16 ~13 lava 2 
setblock ~19 ~16 ~14 lava 0 
setblock ~19 ~16 ~15 nether_brick 0 
setblock ~20 ~16 ~8 nether_brick_stairs 2 
setblock ~20 ~16 ~9 nether_brick_stairs 5  
fill ~20 ~16 ~10 ~20 ~16 ~13 nether_brick_stairs 1 
setblock ~20 ~16 ~14 nether_brick_stairs 5 
setblock ~20 ~16 ~15 nether_brick_stairs 3 
setblock ~21 ~16 ~9 nether_brick_stairs 1  
fill ~21 ~16 ~12 ~52 ~16 ~12 portal 1 
setblock ~21 ~16 ~14 nether_brick_stairs 1 
setblock ~22 ~16 ~8 wool 0 
setblock ~22 ~16 ~9 nether_brick_stairs 6 
setblock ~22 ~16 ~14 nether_brick_stairs 7 
setblock ~22 ~16 ~15 wool 0 
setblock ~52 ~16 ~9 nether_brick_stairs 6 
setblock ~52 ~16 ~14 nether_brick_stairs 7  
fill ~53 ~16 ~8 ~57 ~16 ~8 nether_brick 0  
fill ~53 ~16 ~9 ~54 ~16 ~9 nether_brick 0  
fill ~53 ~16 ~10 ~53 ~16 ~15 nether_brick 0 
setblock ~54 ~16 ~14 lava 8  
fill ~54 ~16 ~15 ~57 ~16 ~15 nether_brick 0  
fill ~55 ~16 ~9 ~57 ~16 ~9 lava 0  
fill ~55 ~16 ~10 ~57 ~16 ~10 coal_block 0  
fill ~55 ~16 ~13 ~57 ~16 ~13 coal_block 0  
fill ~55 ~16 ~14 ~57 ~16 ~14 lava 0 
setblock ~58 ~16 ~8 nether_brick_stairs 6  
fill ~58 ~16 ~9 ~58 ~16 ~14 nether_brick_stairs 5 
setblock ~58 ~16 ~15 nether_brick_stairs 7  
fill ~59 ~16 ~10 ~60 ~16 ~10 obsidian 0  
fill ~59 ~16 ~11 ~60 ~16 ~11 obsidian 0  
fill ~59 ~16 ~12 ~60 ~16 ~12 obsidian 0  
fill ~59 ~16 ~13 ~60 ~16 ~13 obsidian 0 
setblock ~61 ~16 ~10 nether_brick_fence 0  
fill ~62 ~16 ~10 ~63 ~16 ~10 coal_block 0  
fill ~62 ~16 ~13 ~63 ~16 ~13 coal_block 0 
setblock ~62 ~16 ~14 nether_brick_fence 0 
setblock ~63 ~16 ~9 nether_brick_fence 0 
setblock ~64 ~16 ~13 nether_brick_fence 0 
setblock ~65 ~16 ~11 nether_brick_fence 0  
fill ~8 ~17 ~9 ~9 ~17 ~9 obsidian 0  
fill ~8 ~17 ~10 ~8 ~18 ~10 obsidian 0  
fill ~8 ~17 ~11 ~8 ~17 ~12 stained_glass_pane 15  
fill ~8 ~17 ~13 ~8 ~18 ~13 obsidian 0  
fill ~8 ~17 ~14 ~9 ~17 ~14 obsidian 0 
setblock ~9 ~17 ~10 lava 0  
fill ~9 ~17 ~11 ~9 ~17 ~12 nether_brick_fence 0 
setblock ~9 ~17 ~13 lava 0  
fill ~10 ~17 ~9 ~11 ~17 ~9 stained_glass_pane 15  
fill ~10 ~17 ~10 ~11 ~17 ~10 nether_brick_fence 0  
fill ~10 ~17 ~11 ~11 ~17 ~11 lava 10  
fill ~10 ~17 ~12 ~11 ~17 ~12 lava 10  
fill ~10 ~17 ~13 ~11 ~17 ~13 nether_brick_fence 0  
fill ~10 ~17 ~14 ~11 ~17 ~14 stained_glass_pane 15  
fill ~12 ~17 ~9 ~13 ~17 ~9 obsidian 0 
setblock ~12 ~17 ~10 lava 0  
fill ~12 ~17 ~11 ~12 ~17 ~12 nether_brick_fence 0 
setblock ~12 ~17 ~13 lava 0  
fill ~12 ~17 ~14 ~13 ~17 ~14 obsidian 0  
fill ~13 ~17 ~10 ~13 ~18 ~10 obsidian 0  
fill ~13 ~17 ~13 ~13 ~18 ~13 obsidian 0  
fill ~14 ~17 ~8 ~14 ~17 ~15 nether_brick 0 
setblock ~15 ~17 ~9 nether_brick_stairs 6  
fill ~15 ~17 ~10 ~15 ~17 ~15 nether_brick 0  
fill ~16 ~17 ~8 ~18 ~17 ~8 nether_brick 0  
fill ~16 ~17 ~9 ~18 ~17 ~9 lava 0  
fill ~16 ~17 ~10 ~18 ~17 ~10 coal_block 0  
fill ~16 ~17 ~13 ~18 ~17 ~13 coal_block 0 
setblock ~16 ~17 ~14 lava 0  
fill ~16 ~17 ~15 ~18 ~17 ~15 nether_brick 0 
setblock ~17 ~17 ~11 lava 10 
setblock ~17 ~17 ~12 lava 2 
setblock ~17 ~17 ~14 lava 2  
fill ~18 ~17 ~11 ~18 ~17 ~13 coal_block 0 
setblock ~18 ~17 ~14 lava 4 
setblock ~19 ~17 ~8 nether_brick_stairs 2 
setblock ~19 ~17 ~9 nether_brick_stairs 1  
fill ~19 ~17 ~10 ~19 ~17 ~14 nether_brick 0 
setblock ~19 ~17 ~15 nether_brick_stairs 3 
setblock ~20 ~17 ~9 nether_brick 0  
fill ~20 ~17 ~12 ~52 ~17 ~12 portal 1 
setblock ~20 ~17 ~14 nether_brick 0 
setblock ~21 ~17 ~9 nether_brick_stairs 2 
setblock ~21 ~17 ~14 nether_brick_stairs 3 
setblock ~22 ~17 ~9 nether_brick_stairs 1 
setblock ~22 ~17 ~14 nether_brick_stairs 1 
setblock ~51 ~17 ~8 wool 0 
setblock ~51 ~17 ~9 nether_brick_stairs 6 
setblock ~51 ~17 ~14 nether_brick_stairs 7 
setblock ~51 ~17 ~15 wool 0 
setblock ~52 ~17 ~9 nether_brick_stairs 0 
setblock ~52 ~17 ~14 nether_brick_stairs 0 
setblock ~53 ~17 ~8 nether_brick_stairs 2 
setblock ~53 ~17 ~9 nether_brick_stairs 4  
fill ~53 ~17 ~10 ~53 ~17 ~13 nether_brick_stairs 0 
setblock ~53 ~17 ~14 nether_brick_stairs 4 
setblock ~53 ~17 ~15 nether_brick_stairs 3 
setblock ~54 ~17 ~8 nether_brick 0 
setblock ~54 ~17 ~9 lava 0 
setblock ~54 ~17 ~10 lava 2 
setblock ~54 ~17 ~14 lava 0  
fill ~54 ~17 ~15 ~54 ~16 ~15 nether_brick 0  
fill ~55 ~17 ~8 ~57 ~17 ~8 stained_glass_pane 15  
fill ~55 ~17 ~9 ~57 ~17 ~9 nether_brick_fence 0  
fill ~55 ~17 ~10 ~56 ~17 ~10 lava 4  
fill ~55 ~17 ~11 ~58 ~17 ~11 coal_block 0  
fill ~55 ~17 ~12 ~58 ~17 ~12 coal_block 0  
fill ~55 ~17 ~13 ~57 ~17 ~13 lava 0  
fill ~55 ~17 ~14 ~57 ~17 ~14 nether_brick_fence 0  
fill ~55 ~17 ~15 ~57 ~17 ~15 stained_glass_pane 15 
setblock ~57 ~17 ~10 lava 2  
fill ~58 ~17 ~8 ~58 ~18 ~8 nether_brick 0 
setblock ~58 ~17 ~9 lava 2 
setblock ~58 ~17 ~10 lava 0 
setblock ~58 ~17 ~13 coal_block 0 
setblock ~58 ~17 ~14 lava 0  
fill ~58 ~17 ~15 ~58 ~18 ~15 nether_brick 0 
setblock ~59 ~17 ~8 nether_brick_stairs 6  
fill ~59 ~17 ~9 ~59 ~17 ~14 nether_brick_stairs 5 
setblock ~59 ~17 ~15 nether_brick_stairs 7  
fill ~60 ~17 ~10 ~61 ~17 ~10 obsidian 0  
fill ~60 ~17 ~11 ~63 ~17 ~11 obsidian 0  
fill ~60 ~17 ~12 ~63 ~17 ~12 obsidian 0  
fill ~60 ~17 ~13 ~61 ~17 ~13 obsidian 0  
fill ~61 ~17 ~9 ~64 ~17 ~9 obsidian 0  
fill ~61 ~17 ~14 ~64 ~17 ~14 obsidian 0 
setblock ~62 ~17 ~8 nether_brick_fence 0  
fill ~62 ~17 ~10 ~63 ~17 ~10 lava 0  
fill ~62 ~17 ~13 ~63 ~17 ~13 lava 0 
setblock ~63 ~17 ~15 nether_brick_fence 0 
setblock ~64 ~17 ~8 nether_brick_fence 0  
fill ~64 ~17 ~10 ~65 ~17 ~10 obsidian 0  
fill ~64 ~17 ~11 ~64 ~17 ~12 lava 0  
fill ~64 ~17 ~13 ~65 ~17 ~13 obsidian 0  
fill ~65 ~17 ~11 ~65 ~17 ~13 obsidian 0 
setblock ~66 ~17 ~11 nether_brick_fence 0  
fill ~8 ~18 ~11 ~8 ~18 ~13 obsidian 0  
fill ~9 ~18 ~9 ~14 ~18 ~9 obsidian 0  
fill ~9 ~18 ~10 ~9 ~18 ~9 obsidian 0  
fill ~9 ~18 ~11 ~9 ~18 ~12 lava 0  
fill ~9 ~18 ~13 ~9 ~18 ~14 obsidian 0  
fill ~10 ~18 ~10 ~11 ~18 ~10 lava 0  
fill ~10 ~18 ~11 ~11 ~18 ~11 lava 2  
fill ~10 ~18 ~12 ~11 ~18 ~12 lava 2  
fill ~10 ~18 ~13 ~11 ~18 ~13 lava 0  
fill ~10 ~18 ~14 ~14 ~18 ~14 obsidian 0 
setblock ~12 ~18 ~10 obsidian 0  
fill ~12 ~18 ~11 ~12 ~18 ~12 lava 0 
setblock ~12 ~18 ~13 obsidian 0  
fill ~14 ~18 ~10 ~15 ~18 ~10 obsidian 0  
fill ~14 ~18 ~11 ~15 ~18 ~11 obsidian 0  
fill ~14 ~18 ~12 ~15 ~18 ~12 obsidian 0  
fill ~14 ~18 ~13 ~15 ~18 ~13 obsidian 0  
fill ~16 ~18 ~9 ~19 ~18 ~9 coal_block 0  
fill ~16 ~18 ~10 ~16 ~20 ~10 coal_block 0  
fill ~16 ~18 ~13 ~16 ~20 ~13 coal_block 0  
fill ~16 ~18 ~14 ~19 ~18 ~14 coal_block 0  
fill ~17 ~18 ~10 ~17 ~18 ~11 lava 2  
fill ~18 ~18 ~10 ~18 ~20 ~10 lava 10  
fill ~18 ~18 ~11 ~18 ~20 ~11 lava 10  
fill ~19 ~18 ~10 ~19 ~20 ~10 coal_block 0  
fill ~19 ~18 ~11 ~19 ~20 ~11 coal_block 0  
fill ~19 ~18 ~12 ~19 ~20 ~12 coal_block 0  
fill ~19 ~18 ~13 ~19 ~20 ~13 coal_block 0  
fill ~20 ~18 ~12 ~53 ~18 ~12 portal 1 
setblock ~51 ~18 ~9 nether_brick_stairs 0 
setblock ~51 ~18 ~14 nether_brick_stairs 0 
setblock ~52 ~18 ~9 nether_brick_stairs 2 
setblock ~52 ~18 ~14 nether_brick_stairs 3  
fill ~53 ~18 ~9 ~54 ~18 ~9 nether_brick 0 
setblock ~53 ~18 ~14 nether_brick 0 
setblock ~54 ~18 ~8 nether_brick_stairs 2  
fill ~54 ~18 ~10 ~54 ~18 ~13 nether_brick 0 
setblock ~54 ~18 ~14 nether_brick_stairs 0 
setblock ~54 ~18 ~15 nether_brick_stairs 3  
fill ~55 ~18 ~8 ~59 ~18 ~8 nether_brick 0 
setblock ~55 ~18 ~9 lava 4  
fill ~55 ~18 ~10 ~57 ~18 ~10 coal_block 0  
fill ~55 ~18 ~11 ~55 ~17 ~11 coal_block 0  
fill ~55 ~18 ~12 ~55 ~17 ~12 coal_block 0  
fill ~55 ~18 ~13 ~57 ~18 ~13 coal_block 0  
fill ~55 ~18 ~14 ~57 ~18 ~14 lava 0  
fill ~55 ~18 ~15 ~59 ~18 ~15 nether_brick 0 
setblock ~56 ~18 ~9 lava 2  
fill ~56 ~18 ~11 ~56 ~18 ~12 lava 10 
setblock ~57 ~18 ~9 lava 0  
fill ~58 ~18 ~9 ~59 ~18 ~9 nether_brick 0  
fill ~58 ~18 ~10 ~59 ~18 ~10 nether_brick 0  
fill ~58 ~18 ~11 ~59 ~18 ~11 nether_brick 0  
fill ~58 ~18 ~12 ~59 ~18 ~12 nether_brick 0  
fill ~58 ~18 ~13 ~59 ~18 ~13 nether_brick 0 
setblock ~58 ~18 ~14 nether_brick_stairs 7 
setblock ~59 ~18 ~14 nether_brick 0 
setblock ~60 ~18 ~8 nether_brick_fence 0  
fill ~60 ~18 ~9 ~61 ~18 ~9 obsidian 0  
fill ~60 ~18 ~10 ~60 ~19 ~10 obsidian 0  
fill ~60 ~18 ~11 ~60 ~19 ~11 obsidian 0  
fill ~60 ~18 ~12 ~60 ~19 ~12 obsidian 0  
fill ~60 ~18 ~13 ~60 ~19 ~13 obsidian 0  
fill ~60 ~18 ~14 ~61 ~18 ~14 obsidian 0 
setblock ~61 ~18 ~10 lava 0  
fill ~61 ~18 ~11 ~61 ~18 ~12 coal_block 0 
setblock ~61 ~18 ~13 lava 0 
setblock ~61 ~18 ~15 nether_brick_fence 0  
fill ~62 ~18 ~9 ~63 ~18 ~9 stained_glass_pane 15  
fill ~62 ~18 ~10 ~63 ~18 ~10 nether_brick_fence 0  
fill ~62 ~18 ~11 ~63 ~18 ~11 lava 0  
fill ~62 ~18 ~12 ~63 ~18 ~12 lava 0  
fill ~62 ~18 ~13 ~63 ~18 ~13 nether_brick_fence 0  
fill ~62 ~18 ~14 ~63 ~18 ~14 stained_glass_pane 15  
fill ~64 ~18 ~9 ~65 ~18 ~9 obsidian 0 
setblock ~64 ~18 ~10 lava 0  
fill ~64 ~18 ~11 ~64 ~18 ~12 nether_brick_fence 0 
setblock ~64 ~18 ~13 lava 0  
fill ~64 ~18 ~14 ~65 ~18 ~14 obsidian 0 
setblock ~64 ~18 ~15 nether_brick_fence 0 
setblock ~65 ~18 ~8 nether_brick_fence 0  
fill ~65 ~18 ~10 ~65 ~19 ~10 obsidian 0  
fill ~65 ~18 ~11 ~65 ~18 ~12 stained_glass_pane 15  
fill ~65 ~18 ~13 ~65 ~19 ~13 obsidian 0 
setblock ~66 ~18 ~10 nether_brick_fence 0 
setblock ~66 ~18 ~13 nether_brick_fence 0  
fill ~9 ~19 ~11 ~12 ~19 ~11 coal_block 0  
fill ~9 ~19 ~12 ~12 ~19 ~12 coal_block 0  
fill ~10 ~19 ~10 ~11 ~19 ~10 coal_block 0  
fill ~10 ~19 ~13 ~11 ~19 ~13 coal_block 0  
fill ~14 ~19 ~11 ~14 ~21 ~11 coal_block 0  
fill ~14 ~19 ~12 ~14 ~21 ~12 coal_block 0  
fill ~16 ~19 ~9 ~19 ~19 ~9 coal_block 0  
fill ~16 ~19 ~14 ~19 ~19 ~14 coal_block 0  
fill ~20 ~19 ~12 ~53 ~19 ~12 portal 1  
fill ~54 ~19 ~9 ~57 ~19 ~9 coal_block 0  
fill ~54 ~19 ~10 ~54 ~20 ~10 coal_block 0  
fill ~54 ~19 ~11 ~54 ~20 ~11 coal_block 0  
fill ~54 ~19 ~12 ~54 ~20 ~12 coal_block 0  
fill ~54 ~19 ~13 ~54 ~20 ~13 coal_block 0  
fill ~54 ~19 ~14 ~57 ~19 ~14 coal_block 0  
fill ~55 ~19 ~11 ~55 ~20 ~11 lava 12  
fill ~55 ~19 ~12 ~55 ~20 ~12 lava 10  
fill ~55 ~19 ~13 ~55 ~20 ~13 lava 10  
fill ~56 ~19 ~11 ~56 ~19 ~13 lava 2  
fill ~57 ~19 ~10 ~57 ~20 ~10 coal_block 0  
fill ~57 ~19 ~13 ~57 ~20 ~13 coal_block 0  
fill ~58 ~19 ~10 ~61 ~19 ~10 obsidian 0  
fill ~58 ~19 ~11 ~63 ~19 ~11 obsidian 0  
fill ~58 ~19 ~12 ~63 ~19 ~12 obsidian 0  
fill ~58 ~19 ~13 ~61 ~19 ~13 obsidian 0 
setblock ~59 ~19 ~8 nether_brick_fence 0  
fill ~59 ~19 ~9 ~64 ~19 ~9 obsidian 0  
fill ~59 ~19 ~14 ~64 ~19 ~14 obsidian 0 
setblock ~61 ~19 ~8 nether_brick_fence 0  
fill ~62 ~19 ~10 ~63 ~19 ~10 lava 0  
fill ~62 ~19 ~13 ~63 ~19 ~13 lava 0 
setblock ~62 ~19 ~15 nether_brick_fence 0 
setblock ~63 ~19 ~8 nether_brick_fence 0 
setblock ~64 ~19 ~10 obsidian 0  
fill ~64 ~19 ~11 ~64 ~19 ~12 lava 0 
setblock ~64 ~19 ~13 obsidian 0  
fill ~65 ~19 ~11 ~65 ~19 ~13 obsidian 0 
setblock ~66 ~19 ~12 nether_brick_fence 0  
fill ~10 ~20 ~11 ~11 ~20 ~11 coal_block 0  
fill ~10 ~20 ~12 ~11 ~20 ~12 coal_block 0  
fill ~16 ~20 ~9 ~19 ~20 ~9 coal_block 0  
fill ~16 ~20 ~14 ~19 ~20 ~14 coal_block 0  
fill ~20 ~20 ~12 ~53 ~20 ~12 portal 1  
fill ~54 ~20 ~9 ~57 ~20 ~9 coal_block 0  
fill ~54 ~20 ~14 ~57 ~20 ~14 coal_block 0  
fill ~55 ~20 ~10 ~57 ~20 ~10 coal_block 0 
setblock ~58 ~20 ~12 nether_brick_fence 0  
fill ~59 ~20 ~11 ~59 ~22 ~11 coal_block 0  
fill ~59 ~20 ~12 ~59 ~22 ~12 coal_block 0 
setblock ~60 ~20 ~13 nether_brick_fence 0 
setblock ~61 ~20 ~10 nether_brick_fence 0  
fill ~61 ~20 ~11 ~64 ~20 ~11 coal_block 0  
fill ~61 ~20 ~12 ~64 ~20 ~12 coal_block 0 
setblock ~62 ~20 ~9 nether_brick_fence 0  
fill ~62 ~20 ~10 ~63 ~20 ~10 coal_block 0  
fill ~62 ~20 ~13 ~63 ~20 ~13 coal_block 0 
setblock ~64 ~20 ~13 nether_brick_fence 0 
setblock ~65 ~20 ~11 nether_brick_fence 0  
fill ~10 ~21 ~11 ~11 ~21 ~11 coal_block 0  
fill ~10 ~21 ~12 ~11 ~21 ~12 coal_block 0  
fill ~13 ~21 ~11 ~13 ~23 ~11 coal_block 0  
fill ~13 ~21 ~12 ~13 ~23 ~12 coal_block 0  
fill ~17 ~21 ~9 ~20 ~21 ~9 coal_block 0  
fill ~17 ~21 ~10 ~17 ~24 ~10 coal_block 0  
fill ~17 ~21 ~11 ~17 ~24 ~11 coal_block 0  
fill ~17 ~21 ~12 ~17 ~24 ~12 coal_block 0  
fill ~17 ~21 ~13 ~17 ~24 ~13 coal_block 0  
fill ~17 ~21 ~14 ~20 ~21 ~14 coal_block 0  
fill ~18 ~21 ~10 ~18 ~21 ~11 lava 2  
fill ~19 ~21 ~10 ~19 ~26 ~10 lava 8  
fill ~19 ~21 ~11 ~19 ~23 ~11 lava 10  
fill ~20 ~21 ~10 ~20 ~23 ~10 coal_block 0  
fill ~20 ~21 ~11 ~20 ~23 ~11 coal_block 0  
fill ~20 ~21 ~12 ~20 ~28 ~12 coal_block 0  
fill ~20 ~21 ~13 ~20 ~25 ~13 coal_block 0  
fill ~21 ~21 ~12 ~52 ~21 ~12 portal 1  
fill ~53 ~21 ~9 ~56 ~21 ~9 coal_block 0  
fill ~53 ~21 ~10 ~53 ~25 ~10 coal_block 0  
fill ~53 ~21 ~11 ~53 ~28 ~11 coal_block 0  
fill ~53 ~21 ~12 ~53 ~23 ~12 coal_block 0  
fill ~53 ~21 ~13 ~53 ~23 ~13 coal_block 0  
fill ~53 ~21 ~14 ~56 ~21 ~14 coal_block 0 
setblock ~54 ~21 ~10 lava 4 
setblock ~54 ~21 ~11 lava 2  
fill ~54 ~21 ~12 ~54 ~23 ~12 lava 10  
fill ~54 ~21 ~13 ~54 ~26 ~13 lava 8 
setblock ~55 ~21 ~10 lava 6 
setblock ~55 ~21 ~11 lava 4  
fill ~55 ~21 ~12 ~55 ~21 ~13 lava 2  
fill ~56 ~21 ~10 ~56 ~24 ~10 coal_block 0  
fill ~56 ~21 ~11 ~56 ~24 ~11 coal_block 0  
fill ~56 ~21 ~12 ~56 ~24 ~12 coal_block 0  
fill ~56 ~21 ~13 ~56 ~24 ~13 coal_block 0  
fill ~62 ~21 ~11 ~63 ~21 ~11 coal_block 0  
fill ~62 ~21 ~12 ~63 ~21 ~12 coal_block 0  
fill ~10 ~22 ~11 ~11 ~22 ~11 coal_block 0  
fill ~10 ~22 ~12 ~11 ~22 ~12 coal_block 0  
fill ~17 ~22 ~9 ~20 ~22 ~9 coal_block 0  
fill ~17 ~22 ~14 ~20 ~22 ~14 coal_block 0  
fill ~21 ~22 ~12 ~52 ~22 ~12 portal 1  
fill ~53 ~22 ~9 ~56 ~22 ~9 coal_block 0  
fill ~53 ~22 ~14 ~56 ~22 ~14 coal_block 0  
fill ~60 ~22 ~11 ~60 ~24 ~11 coal_block 0  
fill ~60 ~22 ~12 ~60 ~24 ~12 coal_block 0  
fill ~62 ~22 ~11 ~63 ~22 ~11 coal_block 0  
fill ~62 ~22 ~12 ~63 ~22 ~12 coal_block 0  
fill ~10 ~23 ~11 ~13 ~23 ~11 coal_block 0  
fill ~10 ~23 ~12 ~13 ~23 ~12 coal_block 0  
fill ~14 ~23 ~12 ~14 ~26 ~12 obsidian 0  
fill ~17 ~23 ~9 ~20 ~23 ~9 coal_block 0  
fill ~17 ~23 ~14 ~20 ~23 ~14 coal_block 0  
fill ~21 ~23 ~12 ~52 ~23 ~12 portal 1  
fill ~53 ~23 ~9 ~56 ~23 ~9 coal_block 0  
fill ~53 ~23 ~14 ~56 ~23 ~14 coal_block 0  
fill ~62 ~23 ~11 ~63 ~23 ~11 coal_block 0  
fill ~62 ~23 ~12 ~63 ~23 ~12 coal_block 0  
fill ~11 ~24 ~11 ~12 ~24 ~11 coal_block 0  
fill ~11 ~24 ~12 ~12 ~24 ~12 coal_block 0  
fill ~17 ~24 ~9 ~21 ~24 ~9 coal_block 0  
fill ~17 ~24 ~14 ~21 ~24 ~14 coal_block 0 
setblock ~19 ~24 ~11 lava 2  
fill ~20 ~24 ~10 ~20 ~26 ~10 lava 10  
fill ~20 ~24 ~11 ~20 ~25 ~11 lava 10  
fill ~21 ~24 ~10 ~21 ~25 ~10 coal_block 0  
fill ~21 ~24 ~11 ~21 ~25 ~11 coal_block 0  
fill ~21 ~24 ~12 ~21 ~30 ~12 coal_block 0  
fill ~21 ~24 ~13 ~21 ~25 ~13 coal_block 0  
fill ~22 ~24 ~12 ~51 ~24 ~12 portal 1  
fill ~52 ~24 ~9 ~56 ~24 ~9 coal_block 0  
fill ~52 ~24 ~10 ~52 ~25 ~10 coal_block 0  
fill ~52 ~24 ~11 ~52 ~30 ~11 coal_block 0  
fill ~52 ~24 ~12 ~52 ~25 ~12 coal_block 0  
fill ~52 ~24 ~13 ~52 ~25 ~13 coal_block 0  
fill ~52 ~24 ~14 ~56 ~24 ~14 coal_block 0  
fill ~53 ~24 ~12 ~53 ~25 ~12 lava 10  
fill ~53 ~24 ~13 ~53 ~26 ~13 lava 10 
setblock ~54 ~24 ~12 lava 2  
fill ~59 ~24 ~11 ~59 ~26 ~11 obsidian 0  
fill ~61 ~24 ~11 ~63 ~24 ~11 coal_block 0  
fill ~61 ~24 ~12 ~63 ~24 ~12 coal_block 0  
fill ~11 ~25 ~11 ~11 ~26 ~11 coal_block 0  
fill ~11 ~25 ~12 ~11 ~26 ~12 coal_block 0  
fill ~18 ~25 ~9 ~21 ~25 ~9 coal_block 0  
fill ~18 ~25 ~10 ~18 ~26 ~10 coal_block 0  
fill ~18 ~25 ~11 ~18 ~26 ~11 coal_block 0  
fill ~18 ~25 ~12 ~18 ~26 ~12 coal_block 0  
fill ~18 ~25 ~13 ~21 ~25 ~13 coal_block 0  
fill ~18 ~25 ~14 ~21 ~25 ~14 coal_block 0  
fill ~22 ~25 ~12 ~51 ~25 ~12 portal 1 
setblock ~23 ~25 ~9 nether_brick_stairs 4 
setblock ~23 ~25 ~14 nether_brick_stairs 4 
setblock ~24 ~25 ~8 wool 0 
setblock ~24 ~25 ~9 stone_slab 15 
setblock ~24 ~25 ~14 stone_slab 15 
setblock ~24 ~25 ~15 wool 0 
setblock ~49 ~25 ~8 wool 0 
setblock ~49 ~25 ~9 stone_slab 15 
setblock ~49 ~25 ~14 stone_slab 15 
setblock ~49 ~25 ~15 wool 0 
setblock ~50 ~25 ~9 nether_brick_stairs 5 
setblock ~50 ~25 ~14 nether_brick_stairs 5  
fill ~52 ~25 ~9 ~55 ~25 ~9 coal_block 0  
fill ~52 ~25 ~14 ~55 ~25 ~14 coal_block 0  
fill ~54 ~25 ~10 ~55 ~25 ~10 coal_block 0  
fill ~55 ~25 ~11 ~55 ~26 ~11 coal_block 0  
fill ~55 ~25 ~12 ~55 ~26 ~12 coal_block 0  
fill ~55 ~25 ~13 ~55 ~26 ~13 coal_block 0  
fill ~61 ~25 ~11 ~62 ~25 ~11 coal_block 0  
fill ~61 ~25 ~12 ~62 ~25 ~12 coal_block 0  
fill ~12 ~26 ~11 ~12 ~28 ~11 coal_block 0  
fill ~12 ~26 ~12 ~12 ~28 ~12 coal_block 0  
fill ~15 ~26 ~12 ~15 ~28 ~12 obsidian 0  
fill ~18 ~26 ~9 ~19 ~26 ~9 coal_block 0  
fill ~18 ~26 ~13 ~19 ~26 ~13 coal_block 0  
fill ~18 ~26 ~14 ~19 ~26 ~14 coal_block 0 
setblock ~19 ~26 ~8 nether_brick_stairs 4 
setblock ~19 ~26 ~12 coal_block 0 
setblock ~19 ~26 ~15 nether_brick_stairs 4  
fill ~20 ~26 ~8 ~21 ~26 ~8 nether_brick 0  
fill ~20 ~26 ~9 ~21 ~26 ~9 lava 0 
setblock ~20 ~26 ~11 lava 2  
fill ~20 ~26 ~13 ~21 ~26 ~13 lava 8  
fill ~20 ~26 ~14 ~21 ~26 ~14 lava 2  
fill ~20 ~26 ~15 ~21 ~26 ~15 nether_brick 0  
fill ~21 ~26 ~10 ~21 ~28 ~10 lava 10  
fill ~21 ~26 ~11 ~21 ~26 ~10 lava 10 
setblock ~22 ~26 ~8 nether_brick_stairs 6  
fill ~22 ~26 ~9 ~23 ~26 ~9 nether_brick 0  
fill ~22 ~26 ~10 ~22 ~26 ~13 nether_brick_stairs 5  
fill ~22 ~26 ~14 ~23 ~26 ~14 nether_brick 0 
setblock ~22 ~26 ~15 nether_brick_stairs 7  
fill ~23 ~26 ~12 ~50 ~26 ~12 portal 1 
setblock ~24 ~26 ~9 nether_brick_stairs 1 
setblock ~24 ~26 ~14 nether_brick_stairs 1 
setblock ~49 ~26 ~9 nether_brick_stairs 0 
setblock ~49 ~26 ~14 nether_brick_stairs 0  
fill ~50 ~26 ~9 ~51 ~26 ~9 nether_brick 0  
fill ~50 ~26 ~14 ~51 ~26 ~14 nether_brick 0 
setblock ~51 ~26 ~8 nether_brick_stairs 6  
fill ~51 ~26 ~10 ~51 ~26 ~13 nether_brick_stairs 4 
setblock ~51 ~26 ~15 nether_brick_stairs 7  
fill ~52 ~26 ~8 ~53 ~26 ~8 nether_brick 0  
fill ~52 ~26 ~9 ~53 ~26 ~9 lava 2   
fill ~52 ~26 ~10 ~53 ~26 ~10 lava 8  
fill ~52 ~26 ~12 ~52 ~26 ~13 lava 10  
fill ~52 ~26 ~14 ~53 ~26 ~14 lava 0  
fill ~52 ~26 ~15 ~53 ~26 ~15 nether_brick 0 
setblock ~53 ~26 ~12 lava 2 
setblock ~54 ~26 ~8 nether_brick_stairs 5  
fill ~54 ~26 ~9 ~55 ~26 ~9 coal_block 0  
fill ~54 ~26 ~10 ~55 ~26 ~10 coal_block 0  
fill ~54 ~26 ~11 ~54 ~26 ~9 coal_block 0  
fill ~54 ~26 ~14 ~55 ~26 ~14 coal_block 0 
setblock ~54 ~26 ~15 nether_brick_stairs 5  
fill ~58 ~26 ~11 ~58 ~29 ~11 obsidian 0  
fill ~62 ~26 ~11 ~62 ~27 ~11 coal_block 0  
fill ~62 ~26 ~12 ~62 ~27 ~12 coal_block 0 
setblock ~18 ~27 ~8 nether_brick_stairs 6  
fill ~18 ~27 ~9 ~18 ~27 ~14 nether_brick_stairs 4 
setblock ~18 ~27 ~15 nether_brick_stairs 7 
setblock ~19 ~27 ~7 coal_block 0 
setblock ~19 ~27 ~8 nether_brick 0  
fill ~19 ~27 ~9 ~19 ~27 ~10 lava 0  
fill ~19 ~27 ~11 ~19 ~27 ~13 nether_brick 0 
setblock ~19 ~27 ~14 lava 0 
setblock ~19 ~27 ~15 nether_brick 0  
fill ~20 ~27 ~8 ~21 ~27 ~8 stained_glass_pane 15  
fill ~20 ~27 ~9 ~21 ~27 ~9 nether_brick_fence 0 
setblock ~20 ~27 ~10 lava 2 
setblock ~20 ~27 ~13 lava 0  
fill ~20 ~27 ~14 ~21 ~27 ~14 nether_brick_fence 0  
fill ~20 ~27 ~15 ~21 ~27 ~15 stained_glass_pane 15 
setblock ~21 ~27 ~11 lava 2  
fill ~21 ~27 ~13 ~21 ~28 ~13 lava 8  
fill ~22 ~27 ~8 ~22 ~28 ~8 nether_brick 0  
fill ~22 ~27 ~9 ~22 ~28 ~9 lava 0  
fill ~22 ~27 ~10 ~22 ~28 ~10 lava 0 
setblock ~22 ~27 ~11 lava 10  
fill ~22 ~27 ~12 ~22 ~28 ~12 lava 12  
fill ~22 ~27 ~13 ~22 ~28 ~13 coal_block 0 
setblock ~22 ~27 ~14 nether_brick_stairs 0  
fill ~22 ~27 ~15 ~22 ~28 ~15 nether_brick 0 
setblock ~23 ~27 ~8 nether_brick_stairs 6 
setblock ~23 ~27 ~9 nether_brick 0  
fill ~23 ~27 ~10 ~23 ~27 ~13 nether_brick_stairs 5 
setblock ~23 ~27 ~14 nether_brick 0 
setblock ~23 ~27 ~15 nether_brick_stairs 7  
fill ~24 ~27 ~12 ~49 ~27 ~12 portal 1 
setblock ~50 ~27 ~8 nether_brick_stairs 6  
fill ~50 ~27 ~9 ~50 ~26 ~9 nether_brick 0  
fill ~50 ~27 ~10 ~50 ~27 ~13 nether_brick_stairs 4  
fill ~50 ~27 ~14 ~50 ~26 ~14 nether_brick 0 
setblock ~50 ~27 ~15 nether_brick_stairs 7  
fill ~51 ~27 ~8 ~51 ~28 ~8 nether_brick 0 
setblock ~51 ~27 ~9 nether_brick_stairs 1  
fill ~51 ~27 ~10 ~51 ~28 ~10 coal_block 0  
fill ~51 ~27 ~11 ~51 ~28 ~11 lava 12 
setblock ~51 ~27 ~12 lava 10  
fill ~51 ~27 ~13 ~51 ~28 ~13 lava 0  
fill ~51 ~27 ~14 ~51 ~28 ~14 lava 0  
fill ~51 ~27 ~15 ~51 ~28 ~15 nether_brick 0  
fill ~52 ~27 ~8 ~53 ~27 ~8 stained_glass_pane 15  
fill ~52 ~27 ~9 ~53 ~27 ~9 nether_brick_fence 0  
fill ~52 ~27 ~10 ~52 ~28 ~10 lava 8 
setblock ~52 ~27 ~12 lava 2  
fill ~52 ~27 ~13 ~52 ~28 ~13 lava 10  
fill ~52 ~27 ~14 ~53 ~27 ~14 nether_brick_fence 0  
fill ~52 ~27 ~15 ~53 ~27 ~15 stained_glass_pane 15 
setblock ~53 ~27 ~10 lava 0 
setblock ~53 ~27 ~13 lava 2 
setblock ~54 ~27 ~8 nether_brick 0 
setblock ~54 ~27 ~9 lava 0  
fill ~54 ~27 ~10 ~54 ~27 ~12 nether_brick 0  
fill ~54 ~27 ~13 ~54 ~27 ~14 lava 0 
setblock ~54 ~27 ~15 nether_brick 0 
setblock ~55 ~27 ~8 nether_brick_stairs 6  
fill ~55 ~27 ~9 ~55 ~27 ~14 nether_brick_stairs 5 
setblock ~55 ~27 ~15 nether_brick_stairs 7  
fill ~61 ~27 ~11 ~61 ~29 ~11 coal_block 0  
fill ~61 ~27 ~12 ~61 ~29 ~12 coal_block 0  
fill ~13 ~28 ~11 ~13 ~30 ~11 coal_block 0  
fill ~13 ~28 ~12 ~13 ~30 ~12 coal_block 0  
fill ~16 ~28 ~12 ~16 ~30 ~12 obsidian 0 
setblock ~18 ~28 ~8 nether_brick_stairs 2  
fill ~18 ~28 ~9 ~19 ~28 ~9 nether_brick_stairs 0  
fill ~18 ~28 ~10 ~19 ~28 ~10 nether_brick_stairs 0  
fill ~18 ~28 ~11 ~19 ~28 ~11 nether_brick_stairs 0  
fill ~18 ~28 ~12 ~19 ~28 ~12 nether_brick_stairs 0  
fill ~18 ~28 ~13 ~19 ~28 ~13 nether_brick_stairs 0  
fill ~18 ~28 ~14 ~19 ~28 ~14 nether_brick_stairs 0 
setblock ~18 ~28 ~15 nether_brick_stairs 3 
setblock ~19 ~28 ~8 nether_brick_stairs 3 
setblock ~19 ~28 ~15 nether_brick_stairs 2 
setblock ~20 ~28 ~7 coal_block 0  
fill ~20 ~28 ~8 ~20 ~29 ~8 nether_brick 0 
setblock ~20 ~28 ~9 lava 0  
fill ~20 ~28 ~10 ~20 ~28 ~12 coal_block 0  
fill ~20 ~28 ~13 ~20 ~29 ~13 nether_brick 0 
setblock ~20 ~28 ~14 lava 0  
fill ~20 ~28 ~15 ~20 ~29 ~15 nether_brick 0 
setblock ~21 ~28 ~8 stained_glass_pane 15 
setblock ~21 ~28 ~9 nether_brick_fence 0 
setblock ~21 ~28 ~14 nether_brick_fence 0 
setblock ~21 ~28 ~15 stained_glass_pane 15 
setblock ~22 ~28 ~11 lava 2 
setblock ~22 ~28 ~14 nether_brick_stairs 4 
setblock ~23 ~28 ~8 nether_brick 0  
fill ~23 ~28 ~9 ~23 ~32 ~9 coal_block 0  
fill ~23 ~28 ~10 ~23 ~29 ~10 coal_block 0  
fill ~23 ~28 ~11 ~23 ~28 ~14 coal_block 0 
setblock ~23 ~28 ~15 nether_brick 0  
fill ~24 ~28 ~12 ~49 ~28 ~12 portal 1 
setblock ~50 ~28 ~8 nether_brick 0  
fill ~50 ~28 ~9 ~50 ~32 ~9 coal_block 0  
fill ~50 ~28 ~10 ~50 ~28 ~14 coal_block 0 
setblock ~50 ~28 ~15 nether_brick 0 
setblock ~51 ~28 ~9 nether_brick_stairs 5 
setblock ~51 ~28 ~12 lava 2  
fill ~52 ~28 ~8 ~52 ~27 ~8 stained_glass_pane 15  
fill ~52 ~28 ~9 ~52 ~27 ~9 nether_brick_fence 0  
fill ~52 ~28 ~14 ~52 ~27 ~14 nether_brick_fence 0  
fill ~52 ~28 ~15 ~52 ~27 ~15 stained_glass_pane 15  
fill ~53 ~28 ~8 ~53 ~29 ~8 nether_brick 0 
setblock ~53 ~28 ~9 lava 0  
fill ~53 ~28 ~10 ~53 ~29 ~10 nether_brick 0  
fill ~53 ~28 ~12 ~53 ~28 ~13 coal_block 0 
setblock ~53 ~28 ~14 lava 0  
fill ~53 ~28 ~15 ~53 ~29 ~15 nether_brick 0 
setblock ~54 ~28 ~8 nether_brick_stairs 3  
fill ~54 ~28 ~9 ~55 ~28 ~9 nether_brick_stairs 1  
fill ~54 ~28 ~10 ~55 ~28 ~10 nether_brick_stairs 1  
fill ~54 ~28 ~11 ~55 ~28 ~11 nether_brick_stairs 1  
fill ~54 ~28 ~12 ~55 ~28 ~12 nether_brick_stairs 1  
fill ~54 ~28 ~13 ~55 ~28 ~13 nether_brick_stairs 1  
fill ~54 ~28 ~14 ~55 ~28 ~14 nether_brick_stairs 1 
setblock ~54 ~28 ~15 nether_brick_stairs 2 
setblock ~55 ~28 ~8 nether_brick_stairs 2 
setblock ~55 ~28 ~15 nether_brick_stairs 3 
setblock ~19 ~29 ~8 nether_brick_stairs 2  
fill ~19 ~29 ~9 ~19 ~29 ~14 nether_brick_stairs 0 
setblock ~19 ~29 ~15 nether_brick_stairs 3  
fill ~20 ~29 ~9 ~20 ~29 ~15 nether_brick 0 
setblock ~21 ~29 ~7 coal_block 0 
setblock ~21 ~29 ~8 nether_brick 0 
setblock ~21 ~29 ~9 lava 0 
setblock ~21 ~29 ~10 lava 2  
fill ~21 ~29 ~13 ~21 ~29 ~14 lava 0 
setblock ~21 ~29 ~15 nether_brick 0 
setblock ~22 ~29 ~8 nether_brick_stairs 2  
fill ~22 ~29 ~9 ~22 ~31 ~9 coal_block 0 
setblock ~22 ~29 ~12 lava 4 
setblock ~22 ~29 ~13 lava 2  
fill ~22 ~29 ~14 ~24 ~29 ~14 coal_block 0 
setblock ~22 ~29 ~15 nether_brick_stairs 3  
fill ~24 ~29 ~9 ~24 ~33 ~9 coal_block 0  
fill ~24 ~29 ~10 ~24 ~29 ~14 coal_block 0  
fill ~25 ~29 ~12 ~48 ~29 ~12 portal 1  
fill ~49 ~29 ~9 ~49 ~33 ~9 coal_block 0  
fill ~49 ~29 ~10 ~49 ~29 ~14 coal_block 0  
fill ~50 ~29 ~13 ~50 ~29 ~14 coal_block 0 
setblock ~51 ~29 ~8 nether_brick_stairs 2  
fill ~51 ~29 ~9 ~51 ~31 ~9 coal_block 0 
setblock ~51 ~29 ~10 lava 2 
setblock ~51 ~29 ~11 lava 4  
fill ~51 ~29 ~14 ~51 ~31 ~14 coal_block 0 
setblock ~51 ~29 ~15 nether_brick_stairs 3 
setblock ~52 ~29 ~8 nether_brick 0  
fill ~52 ~29 ~9 ~52 ~29 ~10 lava 0 
setblock ~52 ~29 ~13 lava 2 
setblock ~52 ~29 ~14 lava 0 
setblock ~52 ~29 ~15 nether_brick 0 
setblock ~53 ~29 ~9 nether_brick 0  
fill ~53 ~29 ~11 ~53 ~29 ~15 nether_brick 0 
setblock ~54 ~29 ~8 nether_brick_stairs 2  
fill ~54 ~29 ~9 ~54 ~28 ~9 nether_brick_stairs 1  
fill ~54 ~29 ~10 ~54 ~28 ~10 nether_brick_stairs 1  
fill ~54 ~29 ~11 ~54 ~28 ~11 nether_brick_stairs 1  
fill ~54 ~29 ~12 ~54 ~28 ~12 nether_brick_stairs 1  
fill ~54 ~29 ~13 ~54 ~28 ~13 nether_brick_stairs 1  
fill ~54 ~29 ~14 ~54 ~28 ~14 nether_brick_stairs 1 
setblock ~54 ~29 ~15 nether_brick_stairs 3  
fill ~57 ~29 ~11 ~57 ~31 ~11 obsidian 0  
fill ~60 ~29 ~11 ~60 ~32 ~11 coal_block 0  
fill ~60 ~29 ~12 ~60 ~32 ~12 coal_block 0  
fill ~14 ~30 ~11 ~14 ~32 ~11 coal_block 0  
fill ~14 ~30 ~12 ~14 ~32 ~12 coal_block 0  
fill ~17 ~30 ~12 ~17 ~32 ~12 obsidian 0  
fill ~21 ~30 ~9 ~21 ~30 ~14 coal_block 0  
fill ~22 ~30 ~14 ~26 ~30 ~14 coal_block 0  
fill ~25 ~30 ~9 ~26 ~30 ~9 coal_block 0  
fill ~25 ~30 ~10 ~26 ~30 ~10 coal_block 0  
fill ~25 ~30 ~11 ~26 ~30 ~11 coal_block 0  
fill ~25 ~30 ~12 ~26 ~30 ~12 coal_block 0  
fill ~25 ~30 ~13 ~26 ~30 ~13 coal_block 0  
fill ~27 ~30 ~12 ~46 ~30 ~12 portal 1 
setblock ~30 ~30 ~9 nether_brick_stairs 4 
setblock ~30 ~30 ~14 nether_brick_stairs 4 
setblock ~31 ~30 ~8 wool 0 
setblock ~31 ~30 ~9 stone_slab 15 
setblock ~31 ~30 ~14 stone_slab 15 
setblock ~31 ~30 ~15 wool 0 
setblock ~42 ~30 ~8 wool 0 
setblock ~42 ~30 ~9 stone_slab 15 
setblock ~42 ~30 ~14 stone_slab 15 
setblock ~42 ~30 ~15 wool 0 
setblock ~43 ~30 ~9 nether_brick_stairs 5 
setblock ~43 ~30 ~14 nether_brick_stairs 5  
fill ~47 ~30 ~9 ~52 ~30 ~9 coal_block 0  
fill ~47 ~30 ~10 ~48 ~30 ~10 coal_block 0  
fill ~47 ~30 ~11 ~48 ~30 ~11 coal_block 0  
fill ~47 ~30 ~12 ~48 ~30 ~12 coal_block 0  
fill ~47 ~30 ~13 ~48 ~30 ~13 coal_block 0  
fill ~47 ~30 ~14 ~52 ~30 ~14 coal_block 0 
setblock ~52 ~30 ~10 coal_block 0  
fill ~52 ~30 ~12 ~52 ~30 ~14 coal_block 0  
fill ~18 ~31 ~12 ~20 ~31 ~12 nether_brick_fence 0  
fill ~20 ~31 ~11 ~20 ~32 ~11 nether_brick_fence 0  
fill ~22 ~31 ~10 ~22 ~31 ~14 coal_block 0  
fill ~23 ~31 ~14 ~27 ~31 ~14 coal_block 0  
fill ~25 ~31 ~9 ~27 ~31 ~9 coal_block 0  
fill ~27 ~31 ~10 ~27 ~31 ~14 coal_block 0  
fill ~28 ~31 ~8 ~28 ~35 ~8 nether_brick 0  
fill ~28 ~31 ~9 ~28 ~32 ~9 nether_brick 0  
fill ~28 ~31 ~10 ~28 ~31 ~15 nether_brick 0 
setblock ~29 ~31 ~8 nether_brick_stairs 6 
setblock ~29 ~31 ~9 nether_brick_stairs 4  
fill ~29 ~31 ~10 ~29 ~31 ~13 nether_brick_stairs 5 
setblock ~29 ~31 ~14 nether_brick_stairs 4 
setblock ~29 ~31 ~15 nether_brick_stairs 7 
setblock ~30 ~31 ~9 nether_brick 0  
fill ~30 ~31 ~12 ~43 ~31 ~12 portal 1 
setblock ~30 ~31 ~14 nether_brick 0 
setblock ~31 ~31 ~9 nether_brick_stairs 1 
setblock ~31 ~31 ~14 nether_brick_stairs 1 
setblock ~42 ~31 ~9 nether_brick_stairs 0 
setblock ~42 ~31 ~14 nether_brick_stairs 0  
fill ~43 ~31 ~9 ~43 ~32 ~9 nether_brick 0 
setblock ~43 ~31 ~14 nether_brick 0 
setblock ~44 ~31 ~8 nether_brick_stairs 6 
setblock ~44 ~31 ~9 nether_brick_stairs 5  
fill ~44 ~31 ~10 ~44 ~31 ~13 nether_brick_stairs 4 
setblock ~44 ~31 ~14 nether_brick_stairs 5 
setblock ~44 ~31 ~15 nether_brick_stairs 7  
fill ~45 ~31 ~8 ~45 ~35 ~8 nether_brick 0  
fill ~45 ~31 ~9 ~45 ~32 ~9 nether_brick 0  
fill ~45 ~31 ~10 ~45 ~31 ~15 nether_brick 0  
fill ~46 ~31 ~9 ~51 ~31 ~9 coal_block 0  
fill ~46 ~31 ~10 ~46 ~31 ~14 coal_block 0  
fill ~47 ~31 ~14 ~51 ~31 ~14 coal_block 0  
fill ~51 ~31 ~10 ~51 ~31 ~14 coal_block 0  
fill ~53 ~31 ~11 ~55 ~31 ~11 nether_brick_fence 0  
fill ~53 ~31 ~12 ~53 ~32 ~12 nether_brick_fence 0  
fill ~56 ~31 ~11 ~56 ~32 ~11 obsidian 0  
fill ~15 ~32 ~11 ~15 ~34 ~11 coal_block 0  
fill ~15 ~32 ~12 ~15 ~34 ~12 coal_block 0  
fill ~21 ~32 ~11 ~21 ~33 ~11 nether_brick_fence 0  
fill ~23 ~32 ~10 ~23 ~32 ~14 coal_block 0  
fill ~24 ~32 ~14 ~27 ~32 ~14 coal_block 0  
fill ~25 ~32 ~9 ~27 ~32 ~9 coal_block 0  
fill ~28 ~32 ~10 ~28 ~35 ~10 coal_block 0  
fill ~28 ~32 ~11 ~29 ~32 ~11 coal_block 0  
fill ~28 ~32 ~12 ~29 ~32 ~12 coal_block 0  
fill ~28 ~32 ~13 ~28 ~35 ~13 coal_block 0 
setblock ~28 ~32 ~14 nether_brick_stairs 3  
fill ~28 ~32 ~15 ~29 ~32 ~15 nether_brick 0 
setblock ~29 ~32 ~8 nether_brick 0 
setblock ~29 ~32 ~9 lava 2  
fill ~29 ~32 ~10 ~29 ~35 ~10 lava 8  
fill ~29 ~32 ~13 ~29 ~35 ~13 lava 8 
setblock ~29 ~32 ~14 lava 2 
setblock ~30 ~32 ~8 nether_brick_stairs 6  
fill ~30 ~32 ~9 ~30 ~32 ~14 nether_brick_stairs 5 
setblock ~30 ~32 ~15 nether_brick_stairs 7  
fill ~31 ~32 ~12 ~42 ~32 ~12 portal 1 
setblock ~43 ~32 ~8 nether_brick_stairs 6  
fill ~43 ~32 ~10 ~43 ~32 ~14 nether_brick_stairs 4 
setblock ~43 ~32 ~15 nether_brick_stairs 7 
setblock ~44 ~32 ~8 nether_brick 0 
setblock ~44 ~32 ~9 lava 2  
fill ~44 ~32 ~10 ~44 ~35 ~10 lava 8  
fill ~44 ~32 ~11 ~45 ~32 ~11 coal_block 0  
fill ~44 ~32 ~12 ~45 ~32 ~12 coal_block 0  
fill ~44 ~32 ~13 ~44 ~35 ~13 lava 8  
fill ~44 ~32 ~14 ~50 ~32 ~14 coal_block 0  
fill ~44 ~32 ~15 ~45 ~32 ~15 nether_brick 0  
fill ~45 ~32 ~10 ~45 ~35 ~10 coal_block 0  
fill ~45 ~32 ~13 ~45 ~35 ~13 coal_block 0  
fill ~46 ~32 ~9 ~50 ~32 ~9 coal_block 0  
fill ~50 ~32 ~10 ~50 ~32 ~14 coal_block 0  
fill ~52 ~32 ~12 ~52 ~33 ~12 nether_brick_fence 0  
fill ~59 ~32 ~11 ~59 ~34 ~11 coal_block 0  
fill ~59 ~32 ~12 ~59 ~34 ~12 coal_block 0 
setblock ~16 ~33 ~10 double_stone_slab 7  
fill ~16 ~33 ~11 ~19 ~33 ~11 coal_block 0  
fill ~16 ~33 ~12 ~19 ~33 ~12 coal_block 0 
setblock ~16 ~33 ~13 double_stone_slab 7  
fill ~17 ~33 ~10 ~18 ~33 ~10 stone_slab 15  
fill ~17 ~33 ~13 ~18 ~33 ~13 stone_slab 15 
setblock ~19 ~33 ~10 double_stone_slab 7 
setblock ~19 ~33 ~13 double_stone_slab 7  
fill ~22 ~33 ~11 ~22 ~34 ~11 nether_brick_fence 0  
fill ~24 ~33 ~10 ~25 ~33 ~10 coal_block 0  
fill ~24 ~33 ~11 ~25 ~33 ~11 coal_block 0  
fill ~24 ~33 ~12 ~25 ~33 ~12 coal_block 0  
fill ~24 ~33 ~13 ~25 ~33 ~13 coal_block 0  
fill ~24 ~33 ~14 ~27 ~33 ~14 coal_block 0  
fill ~25 ~33 ~9 ~27 ~33 ~9 coal_block 0  
fill ~28 ~33 ~9 ~28 ~34 ~9 lava 8  
fill ~28 ~33 ~14 ~28 ~34 ~14 lava 8  
fill ~28 ~33 ~15 ~28 ~35 ~15 nether_brick 0  
fill ~29 ~33 ~8 ~29 ~35 ~8 stained_glass_pane 15  
fill ~29 ~33 ~9 ~29 ~35 ~9 nether_brick_fence 0  
fill ~29 ~33 ~11 ~31 ~33 ~11 coal_block 0  
fill ~29 ~33 ~12 ~31 ~33 ~12 coal_block 0  
fill ~29 ~33 ~14 ~29 ~35 ~14 nether_brick_fence 0  
fill ~29 ~33 ~15 ~29 ~35 ~15 stained_glass_pane 15  
fill ~30 ~33 ~8 ~30 ~37 ~8 nether_brick 0  
fill ~30 ~33 ~9 ~30 ~34 ~9 lava 8  
fill ~30 ~33 ~10 ~31 ~33 ~10 coal_block 0  
fill ~30 ~33 ~13 ~31 ~33 ~13 coal_block 0  
fill ~30 ~33 ~14 ~30 ~34 ~14 lava 8  
fill ~30 ~33 ~15 ~30 ~37 ~15 nether_brick 0  
fill ~31 ~33 ~9 ~31 ~35 ~9 coal_block 0  
fill ~31 ~33 ~14 ~31 ~35 ~14 coal_block 0  
fill ~32 ~33 ~12 ~41 ~33 ~12 portal 1  
fill ~42 ~33 ~9 ~42 ~35 ~9 coal_block 0  
fill ~42 ~33 ~10 ~43 ~33 ~10 coal_block 0  
fill ~42 ~33 ~11 ~44 ~33 ~11 coal_block 0  
fill ~42 ~33 ~12 ~45 ~33 ~12 coal_block 0  
fill ~42 ~33 ~13 ~43 ~33 ~13 coal_block 0  
fill ~42 ~33 ~14 ~43 ~33 ~14 coal_block 0  
fill ~43 ~33 ~8 ~43 ~37 ~8 nether_brick 0  
fill ~43 ~33 ~9 ~43 ~34 ~9 lava 8  
fill ~43 ~33 ~15 ~43 ~37 ~15 nether_brick 0  
fill ~44 ~33 ~8 ~44 ~35 ~8 stained_glass_pane 15  
fill ~44 ~33 ~9 ~44 ~35 ~9 nether_brick_fence 0  
fill ~44 ~33 ~15 ~44 ~35 ~15 stained_glass_pane 15  
fill ~45 ~33 ~9 ~45 ~34 ~9 lava 8  
fill ~45 ~33 ~14 ~49 ~33 ~14 coal_block 0  
fill ~45 ~33 ~15 ~45 ~35 ~15 nether_brick 0  
fill ~46 ~33 ~9 ~49 ~33 ~9 coal_block 0  
fill ~48 ~33 ~10 ~49 ~33 ~10 coal_block 0  
fill ~48 ~33 ~11 ~49 ~33 ~11 coal_block 0  
fill ~48 ~33 ~12 ~49 ~33 ~12 coal_block 0  
fill ~48 ~33 ~13 ~49 ~33 ~13 coal_block 0  
fill ~51 ~33 ~12 ~51 ~34 ~12 nether_brick_fence 0 
setblock ~54 ~33 ~10 double_stone_slab 7  
fill ~54 ~33 ~11 ~57 ~33 ~11 coal_block 0  
fill ~54 ~33 ~12 ~57 ~33 ~12 coal_block 0 
setblock ~54 ~33 ~13 double_stone_slab 7  
fill ~55 ~33 ~10 ~56 ~33 ~10 stone_slab 15  
fill ~55 ~33 ~13 ~56 ~33 ~13 stone_slab 15 
setblock ~57 ~33 ~10 double_stone_slab 7 
setblock ~57 ~33 ~13 double_stone_slab 7  
fill ~16 ~34 ~11 ~16 ~33 ~11 coal_block 0  
fill ~16 ~34 ~12 ~16 ~33 ~12 coal_block 0 
setblock ~16 ~34 ~13 stone_slab 15 
setblock ~17 ~34 ~10 nether_brick_stairs 4  
fill ~17 ~34 ~11 ~18 ~34 ~11 nether_brick 0  
fill ~17 ~34 ~12 ~18 ~34 ~12 nether_brick 0 
setblock ~17 ~34 ~13 nether_brick_stairs 4 
setblock ~18 ~34 ~10 nether_brick_stairs 5 
setblock ~18 ~34 ~13 nether_brick_stairs 5  
fill ~19 ~34 ~11 ~20 ~34 ~11 coal_block 0  
fill ~19 ~34 ~12 ~20 ~34 ~12 coal_block 0 
setblock ~19 ~34 ~13 stone_slab 15  
fill ~23 ~34 ~11 ~23 ~35 ~11 nether_brick_fence 0  
fill ~26 ~34 ~9 ~27 ~34 ~9 coal_block 0  
fill ~26 ~34 ~10 ~26 ~34 ~14 coal_block 0  
fill ~27 ~34 ~14 ~27 ~35 ~14 coal_block 0  
fill ~29 ~34 ~11 ~29 ~36 ~11 coal_block 0  
fill ~29 ~34 ~12 ~29 ~36 ~12 coal_block 0  
fill ~30 ~34 ~10 ~32 ~34 ~10 coal_block 0  
fill ~30 ~34 ~13 ~33 ~34 ~13 coal_block 0  
fill ~31 ~34 ~11 ~33 ~34 ~11 coal_block 0  
fill ~31 ~34 ~12 ~33 ~34 ~12 coal_block 0  
fill ~34 ~34 ~12 ~39 ~34 ~12 portal 1  
fill ~40 ~34 ~11 ~41 ~34 ~11 coal_block 0  
fill ~40 ~34 ~12 ~41 ~34 ~12 coal_block 0  
fill ~40 ~34 ~13 ~43 ~34 ~13 coal_block 0  
fill ~41 ~34 ~10 ~43 ~34 ~10 coal_block 0  
fill ~42 ~34 ~14 ~43 ~34 ~14 coal_block 0  
fill ~44 ~34 ~11 ~44 ~36 ~11 coal_block 0  
fill ~44 ~34 ~12 ~44 ~36 ~12 coal_block 0  
fill ~45 ~34 ~14 ~47 ~34 ~14 coal_block 0  
fill ~46 ~34 ~9 ~47 ~34 ~9 coal_block 0  
fill ~47 ~34 ~10 ~47 ~34 ~14 coal_block 0  
fill ~50 ~34 ~12 ~50 ~35 ~12 nether_brick_fence 0  
fill ~53 ~34 ~11 ~54 ~34 ~11 coal_block 0  
fill ~53 ~34 ~12 ~54 ~34 ~12 coal_block 0 
setblock ~54 ~34 ~10 stone_slab 15 
setblock ~55 ~34 ~10 nether_brick_stairs 4  
fill ~55 ~34 ~11 ~56 ~34 ~11 nether_brick 0  
fill ~55 ~34 ~12 ~56 ~34 ~12 nether_brick 0 
setblock ~55 ~34 ~13 nether_brick_stairs 4 
setblock ~56 ~34 ~10 nether_brick_stairs 5 
setblock ~56 ~34 ~13 nether_brick_stairs 5 
setblock ~57 ~34 ~10 stone_slab 15  
fill ~57 ~34 ~11 ~59 ~34 ~11 coal_block 0  
fill ~57 ~34 ~12 ~59 ~34 ~12 coal_block 0 
setblock ~15 ~35 ~10 nether_brick_stairs 5 
setblock ~15 ~35 ~13 nether_brick_stairs 5  
fill ~16 ~35 ~10 ~16 ~35 ~13 nether_brick_stairs 4  
fill ~17 ~35 ~10 ~18 ~35 ~10 glass 0  
fill ~17 ~35 ~11 ~17 ~35 ~12 lava 8  
fill ~17 ~35 ~13 ~18 ~35 ~13 glass 0  
fill ~18 ~35 ~11 ~18 ~36 ~11 lava 0  
fill ~18 ~35 ~12 ~18 ~36 ~12 lava 0  
fill ~19 ~35 ~10 ~19 ~35 ~13 nether_brick_stairs 5 
setblock ~20 ~35 ~10 nether_brick_stairs 4  
fill ~20 ~35 ~11 ~20 ~37 ~11 coal_block 0  
fill ~20 ~35 ~12 ~20 ~37 ~12 coal_block 0 
setblock ~20 ~35 ~13 nether_brick_stairs 4  
fill ~24 ~35 ~11 ~24 ~36 ~11 nether_brick_fence 0  
fill ~26 ~35 ~11 ~26 ~37 ~11 obsidian 0  
fill ~27 ~35 ~9 ~27 ~35 ~14 coal_block 0 
setblock ~28 ~35 ~9 lava 0  
fill ~28 ~35 ~11 ~28 ~35 ~13 coal_block 0 
setblock ~28 ~35 ~14 lava 0 
setblock ~30 ~35 ~9 lava 0  
fill ~30 ~35 ~10 ~32 ~35 ~10 coal_block 0  
fill ~30 ~35 ~13 ~30 ~36 ~13 coal_block 0 
setblock ~30 ~35 ~14 lava 0  
fill ~32 ~35 ~11 ~34 ~35 ~11 coal_block 0  
fill ~32 ~35 ~12 ~34 ~35 ~12 coal_block 0  
fill ~32 ~35 ~13 ~34 ~35 ~13 coal_block 0  
fill ~35 ~35 ~12 ~38 ~35 ~12 portal 1  
fill ~39 ~35 ~11 ~41 ~35 ~11 coal_block 0  
fill ~39 ~35 ~12 ~41 ~35 ~12 coal_block 0  
fill ~39 ~35 ~13 ~43 ~35 ~13 coal_block 0  
fill ~41 ~35 ~10 ~43 ~35 ~10 coal_block 0  
fill ~42 ~35 ~14 ~43 ~35 ~14 coal_block 0 
setblock ~43 ~35 ~9 lava 0 
setblock ~45 ~35 ~9 lava 0  
fill ~45 ~35 ~11 ~46 ~35 ~11 coal_block 0  
fill ~45 ~35 ~12 ~46 ~35 ~12 coal_block 0  
fill ~45 ~35 ~14 ~46 ~35 ~14 coal_block 0  
fill ~46 ~35 ~9 ~46 ~31 ~9 coal_block 0  
fill ~46 ~35 ~10 ~46 ~35 ~9 coal_block 0 
setblock ~46 ~35 ~13 coal_block 0  
fill ~47 ~35 ~12 ~47 ~37 ~12 obsidian 0  
fill ~49 ~35 ~12 ~49 ~36 ~12 nether_brick_fence 0 
setblock ~53 ~35 ~10 nether_brick_stairs 5  
fill ~53 ~35 ~11 ~53 ~37 ~11 coal_block 0  
fill ~53 ~35 ~12 ~53 ~37 ~12 coal_block 0 
setblock ~53 ~35 ~13 nether_brick_stairs 5  
fill ~54 ~35 ~10 ~54 ~35 ~13 nether_brick_stairs 4  
fill ~55 ~35 ~10 ~56 ~35 ~10 glass 0  
fill ~55 ~35 ~11 ~55 ~36 ~11 lava 0  
fill ~55 ~35 ~12 ~55 ~36 ~12 lava 0  
fill ~55 ~35 ~13 ~56 ~35 ~13 glass 0  
fill ~56 ~35 ~11 ~56 ~35 ~12 lava 8  
fill ~57 ~35 ~10 ~57 ~35 ~13 nether_brick_stairs 5 
setblock ~58 ~35 ~10 nether_brick_stairs 4 
setblock ~58 ~35 ~13 nether_brick_stairs 4 
setblock ~15 ~36 ~10 nether_brick_stairs 1 
setblock ~15 ~36 ~13 nether_brick_stairs 1  
fill ~16 ~36 ~10 ~16 ~36 ~13 nether_brick_stairs 0  
fill ~17 ~36 ~10 ~18 ~36 ~10 glass 0  
fill ~17 ~36 ~11 ~17 ~36 ~12 lava 0  
fill ~17 ~36 ~13 ~18 ~36 ~13 glass 0  
fill ~19 ~36 ~10 ~19 ~36 ~13 nether_brick_stairs 1 
setblock ~20 ~36 ~10 nether_brick_stairs 0 
setblock ~20 ~36 ~13 nether_brick_stairs 0 
setblock ~25 ~36 ~11 nether_brick_fence 0 
setblock ~28 ~36 ~8 nether_brick_stairs 2  
fill ~28 ~36 ~9 ~28 ~36 ~14 nether_brick_stairs 0 
setblock ~28 ~36 ~15 nether_brick_stairs 3 
setblock ~29 ~36 ~8 nether_brick 0 
setblock ~29 ~36 ~9 lava 2 
setblock ~29 ~36 ~10 lava 0 
setblock ~29 ~36 ~13 lava 0 
setblock ~29 ~36 ~14 lava 2 
setblock ~29 ~36 ~15 nether_brick 0  
fill ~30 ~36 ~9 ~30 ~36 ~14 coal_block 0  
fill ~31 ~36 ~10 ~31 ~36 ~13 coal_block 0  
fill ~32 ~36 ~11 ~32 ~34 ~11 coal_block 0  
fill ~32 ~36 ~12 ~35 ~36 ~12 coal_block 0  
fill ~34 ~36 ~11 ~35 ~36 ~11 coal_block 0  
fill ~34 ~36 ~13 ~35 ~36 ~13 coal_block 0  
fill ~36 ~36 ~12 ~37 ~36 ~12 portal 1  
fill ~38 ~36 ~11 ~39 ~36 ~11 coal_block 0  
fill ~38 ~36 ~12 ~44 ~36 ~12 coal_block 0  
fill ~38 ~36 ~13 ~39 ~36 ~13 coal_block 0  
fill ~41 ~36 ~11 ~44 ~36 ~11 coal_block 0  
fill ~42 ~36 ~10 ~43 ~36 ~10 coal_block 0  
fill ~42 ~36 ~13 ~43 ~36 ~13 coal_block 0  
fill ~43 ~36 ~9 ~43 ~37 ~9 nether_brick 0  
fill ~43 ~36 ~14 ~44 ~36 ~14 coal_block 0 
setblock ~44 ~36 ~8 nether_brick 0 
setblock ~44 ~36 ~9 lava 2 
setblock ~44 ~36 ~10 lava 0 
setblock ~44 ~36 ~13 lava 0 
setblock ~44 ~36 ~15 nether_brick 0 
setblock ~45 ~36 ~8 nether_brick_stairs 2  
fill ~45 ~36 ~9 ~45 ~36 ~14 nether_brick_stairs 1 
setblock ~45 ~36 ~15 nether_brick_stairs 3 
setblock ~48 ~36 ~12 nether_brick_fence 0 
setblock ~53 ~36 ~10 nether_brick_stairs 1 
setblock ~53 ~36 ~13 nether_brick_stairs 1  
fill ~54 ~36 ~10 ~54 ~36 ~13 nether_brick_stairs 0  
fill ~55 ~36 ~10 ~56 ~36 ~10 glass 0  
fill ~55 ~36 ~13 ~56 ~36 ~13 glass 0  
fill ~56 ~36 ~11 ~56 ~36 ~12 lava 0  
fill ~57 ~36 ~10 ~57 ~36 ~13 nether_brick_stairs 1 
setblock ~58 ~36 ~10 nether_brick_stairs 0 
setblock ~58 ~36 ~13 nether_brick_stairs 0 
setblock ~16 ~37 ~10 stone_slab 7 
setblock ~16 ~37 ~13 stone_slab 7 
setblock ~17 ~37 ~10 nether_brick_stairs 0  
fill ~17 ~37 ~11 ~18 ~37 ~11 nether_brick 0  
fill ~17 ~37 ~12 ~18 ~37 ~12 nether_brick 0 
setblock ~17 ~37 ~13 nether_brick_stairs 0 
setblock ~18 ~37 ~10 nether_brick_stairs 1 
setblock ~18 ~37 ~13 nether_brick_stairs 1 
setblock ~19 ~37 ~10 stone_slab 7 
setblock ~19 ~37 ~13 stone_slab 7  
fill ~21 ~37 ~11 ~21 ~39 ~11 coal_block 0  
fill ~21 ~37 ~12 ~21 ~39 ~12 coal_block 0  
fill ~25 ~37 ~11 ~25 ~38 ~11 obsidian 0  
fill ~27 ~37 ~11 ~27 ~38 ~11 nether_brick_fence 0 
setblock ~29 ~37 ~8 nether_brick_stairs 2  
fill ~29 ~37 ~9 ~29 ~37 ~14 nether_brick_stairs 0 
setblock ~29 ~37 ~15 nether_brick_stairs 3  
fill ~30 ~37 ~9 ~30 ~37 ~15 nether_brick 0  
fill ~31 ~37 ~12 ~31 ~40 ~12 obsidian 0  
fill ~33 ~37 ~12 ~40 ~37 ~12 coal_block 0  
fill ~35 ~37 ~11 ~38 ~37 ~11 coal_block 0  
fill ~35 ~37 ~13 ~38 ~37 ~13 coal_block 0  
fill ~42 ~37 ~11 ~42 ~40 ~11 obsidian 0  
fill ~43 ~37 ~10 ~43 ~37 ~15 nether_brick 0 
setblock ~44 ~37 ~8 nether_brick_stairs 2  
fill ~44 ~37 ~9 ~44 ~37 ~14 nether_brick_stairs 1 
setblock ~44 ~37 ~15 nether_brick_stairs 3  
fill ~46 ~37 ~12 ~46 ~38 ~12 nether_brick_fence 0  
fill ~48 ~37 ~12 ~48 ~38 ~12 obsidian 0  
fill ~52 ~37 ~11 ~52 ~39 ~11 coal_block 0  
fill ~52 ~37 ~12 ~52 ~39 ~12 coal_block 0 
setblock ~54 ~37 ~10 stone_slab 7 
setblock ~54 ~37 ~13 stone_slab 7 
setblock ~55 ~37 ~10 nether_brick_stairs 0  
fill ~55 ~37 ~11 ~56 ~37 ~11 nether_brick 0  
fill ~55 ~37 ~12 ~56 ~37 ~12 nether_brick 0 
setblock ~55 ~37 ~13 nether_brick_stairs 0 
setblock ~56 ~37 ~10 nether_brick_stairs 1 
setblock ~56 ~37 ~13 nether_brick_stairs 1 
setblock ~57 ~37 ~10 stone_slab 7 
setblock ~57 ~37 ~13 stone_slab 7 
setblock ~16 ~38 ~10 double_stone_slab 7 
setblock ~16 ~38 ~13 double_stone_slab 7  
fill ~17 ~38 ~10 ~18 ~38 ~10 stone_slab 7  
fill ~17 ~38 ~12 ~17 ~41 ~12 obsidian 0  
fill ~17 ~38 ~13 ~18 ~38 ~13 stone_slab 7 
setblock ~19 ~38 ~10 double_stone_slab 7 
setblock ~19 ~38 ~13 double_stone_slab 7  
fill ~28 ~38 ~11 ~28 ~39 ~11 nether_brick_fence 0  
fill ~34 ~38 ~12 ~39 ~38 ~12 coal_block 0  
fill ~36 ~38 ~11 ~37 ~38 ~11 coal_block 0  
fill ~36 ~38 ~13 ~37 ~38 ~13 coal_block 0  
fill ~45 ~38 ~12 ~45 ~39 ~12 nether_brick_fence 0 
setblock ~54 ~38 ~10 double_stone_slab 7 
setblock ~54 ~38 ~13 double_stone_slab 7  
fill ~55 ~38 ~10 ~56 ~38 ~10 stone_slab 7  
fill ~55 ~38 ~13 ~56 ~38 ~13 stone_slab 7  
fill ~56 ~38 ~11 ~56 ~41 ~11 obsidian 0 
setblock ~57 ~38 ~10 double_stone_slab 7 
setblock ~57 ~38 ~13 double_stone_slab 7  
fill ~22 ~39 ~11 ~26 ~39 ~11 coal_block 0  
fill ~22 ~39 ~12 ~26 ~39 ~12 coal_block 0 
setblock ~23 ~39 ~10 double_stone_slab 7 
setblock ~23 ~39 ~13 double_stone_slab 7  
fill ~24 ~39 ~10 ~25 ~39 ~10 stone_slab 15  
fill ~24 ~39 ~13 ~25 ~39 ~13 stone_slab 15 
setblock ~26 ~39 ~10 double_stone_slab 7 
setblock ~26 ~39 ~13 double_stone_slab 7  
fill ~29 ~39 ~11 ~29 ~40 ~11 nether_brick_fence 0  
fill ~35 ~39 ~12 ~38 ~39 ~12 coal_block 0  
fill ~44 ~39 ~12 ~44 ~40 ~12 nether_brick_fence 0 
setblock ~47 ~39 ~10 double_stone_slab 7  
fill ~47 ~39 ~11 ~52 ~39 ~11 coal_block 0  
fill ~47 ~39 ~12 ~52 ~39 ~12 coal_block 0 
setblock ~47 ~39 ~13 double_stone_slab 7  
fill ~48 ~39 ~10 ~49 ~39 ~10 stone_slab 15  
fill ~48 ~39 ~13 ~49 ~39 ~13 stone_slab 15 
setblock ~50 ~39 ~10 double_stone_slab 7 
setblock ~50 ~39 ~13 double_stone_slab 7  
fill ~22 ~40 ~11 ~23 ~40 ~11 coal_block 0  
fill ~22 ~40 ~12 ~23 ~40 ~12 coal_block 0 
setblock ~23 ~40 ~10 stone_slab 15 
setblock ~23 ~40 ~13 stone_slab 15 
setblock ~24 ~40 ~10 nether_brick_stairs 4  
fill ~24 ~40 ~11 ~25 ~40 ~11 nether_brick 0  
fill ~24 ~40 ~12 ~25 ~40 ~12 nether_brick 0 
setblock ~24 ~40 ~13 nether_brick_stairs 4 
setblock ~25 ~40 ~10 nether_brick_stairs 5 
setblock ~25 ~40 ~13 nether_brick_stairs 5 
setblock ~26 ~40 ~10 stone_slab 15  
fill ~26 ~40 ~11 ~27 ~40 ~11 coal_block 0  
fill ~26 ~40 ~12 ~27 ~40 ~12 coal_block 0 
setblock ~26 ~40 ~13 stone_slab 15  
fill ~29 ~40 ~12 ~30 ~40 ~12 nether_brick_fence 0  
fill ~32 ~40 ~12 ~32 ~43 ~12 obsidian 0  
fill ~41 ~40 ~11 ~41 ~43 ~11 obsidian 0  
fill ~43 ~40 ~11 ~43 ~40 ~12 nether_brick_fence 0  
fill ~46 ~40 ~11 ~47 ~40 ~11 coal_block 0  
fill ~46 ~40 ~12 ~47 ~40 ~12 coal_block 0 
setblock ~47 ~40 ~10 stone_slab 15 
setblock ~47 ~40 ~13 stone_slab 15 
setblock ~48 ~40 ~10 nether_brick_stairs 4  
fill ~48 ~40 ~11 ~49 ~40 ~11 nether_brick 0  
fill ~48 ~40 ~12 ~49 ~40 ~12 nether_brick 0 
setblock ~48 ~40 ~13 nether_brick_stairs 4 
setblock ~49 ~40 ~10 nether_brick_stairs 5 
setblock ~49 ~40 ~13 nether_brick_stairs 5 
setblock ~50 ~40 ~10 stone_slab 15  
fill ~50 ~40 ~11 ~51 ~40 ~11 coal_block 0  
fill ~50 ~40 ~12 ~51 ~40 ~12 coal_block 0 
setblock ~50 ~40 ~13 stone_slab 15  
fill ~18 ~41 ~12 ~18 ~43 ~12 obsidian 0 
setblock ~22 ~41 ~10 nether_brick_stairs 5 
setblock ~22 ~41 ~13 nether_brick_stairs 5  
fill ~23 ~41 ~10 ~23 ~41 ~13 nether_brick_stairs 4  
fill ~24 ~41 ~10 ~25 ~41 ~10 glass 0  
fill ~24 ~41 ~11 ~25 ~41 ~11 lava 0  
fill ~24 ~41 ~12 ~24 ~42 ~12 lava 0  
fill ~24 ~41 ~13 ~25 ~41 ~13 glass 0 
setblock ~25 ~41 ~12 lava 8  
fill ~26 ~41 ~10 ~26 ~41 ~13 nether_brick_stairs 5 
setblock ~27 ~41 ~10 nether_brick_stairs 4  
fill ~27 ~41 ~11 ~28 ~41 ~11 coal_block 0  
fill ~27 ~41 ~12 ~28 ~41 ~12 coal_block 0 
setblock ~27 ~41 ~13 nether_brick_stairs 4  
fill ~35 ~41 ~12 ~36 ~41 ~12 nether_brick_fence 0  
fill ~36 ~41 ~11 ~38 ~41 ~11 nether_brick_fence 0  
fill ~45 ~41 ~11 ~46 ~41 ~11 coal_block 0  
fill ~45 ~41 ~12 ~46 ~41 ~12 coal_block 0 
setblock ~46 ~41 ~10 nether_brick_stairs 5 
setblock ~46 ~41 ~13 nether_brick_stairs 5  
fill ~47 ~41 ~10 ~47 ~41 ~13 nether_brick_stairs 4  
fill ~48 ~41 ~10 ~49 ~41 ~10 glass 0 
setblock ~48 ~41 ~11 lava 8  
fill ~48 ~41 ~12 ~49 ~41 ~12 lava 0  
fill ~48 ~41 ~13 ~49 ~41 ~13 glass 0  
fill ~49 ~41 ~11 ~49 ~42 ~11 lava 0  
fill ~50 ~41 ~10 ~50 ~41 ~13 nether_brick_stairs 5 
setblock ~51 ~41 ~10 nether_brick_stairs 4 
setblock ~51 ~41 ~13 nether_brick_stairs 4  
fill ~55 ~41 ~11 ~55 ~43 ~11 obsidian 0 
setblock ~22 ~42 ~10 nether_brick_stairs 1 
setblock ~22 ~42 ~13 nether_brick_stairs 1  
fill ~23 ~42 ~10 ~23 ~42 ~13 nether_brick_stairs 0  
fill ~24 ~42 ~10 ~25 ~42 ~10 glass 0  
fill ~24 ~42 ~11 ~25 ~42 ~11 lava 0  
fill ~24 ~42 ~13 ~25 ~42 ~13 glass 0 
setblock ~25 ~42 ~12 lava 0  
fill ~26 ~42 ~10 ~26 ~42 ~13 nether_brick_stairs 1 
setblock ~27 ~42 ~10 nether_brick_stairs 0 
setblock ~27 ~42 ~13 nether_brick_stairs 0  
fill ~28 ~42 ~11 ~29 ~42 ~11 coal_block 0  
fill ~28 ~42 ~12 ~29 ~42 ~12 coal_block 0  
fill ~33 ~42 ~12 ~35 ~42 ~12 nether_brick_fence 0  
fill ~38 ~42 ~11 ~40 ~42 ~11 nether_brick_fence 0  
fill ~44 ~42 ~11 ~45 ~42 ~11 coal_block 0  
fill ~44 ~42 ~12 ~45 ~42 ~12 coal_block 0 
setblock ~46 ~42 ~10 nether_brick_stairs 1 
setblock ~46 ~42 ~13 nether_brick_stairs 1  
fill ~47 ~42 ~10 ~47 ~42 ~13 nether_brick_stairs 0  
fill ~48 ~42 ~10 ~49 ~42 ~10 glass 0  
fill ~48 ~42 ~11 ~48 ~42 ~12 lava 0  
fill ~48 ~42 ~13 ~49 ~42 ~13 glass 0 
setblock ~49 ~42 ~12 lava 0  
fill ~50 ~42 ~10 ~50 ~42 ~13 nether_brick_stairs 1 
setblock ~51 ~42 ~10 nether_brick_stairs 0 
setblock ~51 ~42 ~13 nether_brick_stairs 0  
fill ~19 ~43 ~12 ~19 ~46 ~12 obsidian 0 
setblock ~23 ~43 ~10 stone_slab 7 
setblock ~23 ~43 ~13 stone_slab 7 
setblock ~24 ~43 ~10 nether_brick_stairs 0  
fill ~24 ~43 ~11 ~25 ~43 ~11 nether_brick 0  
fill ~24 ~43 ~12 ~25 ~43 ~12 nether_brick 0 
setblock ~24 ~43 ~13 nether_brick_stairs 0 
setblock ~25 ~43 ~10 nether_brick_stairs 1 
setblock ~25 ~43 ~13 nether_brick_stairs 1 
setblock ~26 ~43 ~10 stone_slab 7 
setblock ~26 ~43 ~13 stone_slab 7  
fill ~29 ~43 ~11 ~30 ~43 ~11 coal_block 0  
fill ~29 ~43 ~12 ~30 ~43 ~12 coal_block 0  
fill ~33 ~43 ~12 ~33 ~44 ~12 obsidian 0  
fill ~40 ~43 ~11 ~40 ~44 ~11 obsidian 0  
fill ~43 ~43 ~11 ~44 ~43 ~11 coal_block 0  
fill ~43 ~43 ~12 ~44 ~43 ~12 coal_block 0 
setblock ~47 ~43 ~10 stone_slab 7 
setblock ~47 ~43 ~13 stone_slab 7 
setblock ~48 ~43 ~10 nether_brick_stairs 0  
fill ~48 ~43 ~11 ~49 ~43 ~11 nether_brick 0  
fill ~48 ~43 ~12 ~49 ~43 ~12 nether_brick 0 
setblock ~48 ~43 ~13 nether_brick_stairs 0 
setblock ~49 ~43 ~10 nether_brick_stairs 1 
setblock ~49 ~43 ~13 nether_brick_stairs 1 
setblock ~50 ~43 ~10 stone_slab 7 
setblock ~50 ~43 ~13 stone_slab 7  
fill ~54 ~43 ~11 ~54 ~46 ~11 obsidian 0 
setblock ~23 ~44 ~10 double_stone_slab 7 
setblock ~23 ~44 ~11 nether_brick_fence 0 
setblock ~23 ~44 ~13 double_stone_slab 7  
fill ~24 ~44 ~10 ~25 ~44 ~10 stone_slab 7  
fill ~24 ~44 ~11 ~24 ~46 ~11 obsidian 0  
fill ~24 ~44 ~13 ~25 ~44 ~13 stone_slab 7 
setblock ~25 ~44 ~11 nether_brick_fence 0 
setblock ~26 ~44 ~10 double_stone_slab 7 
setblock ~26 ~44 ~13 double_stone_slab 7  
fill ~30 ~44 ~11 ~32 ~44 ~11 coal_block 0  
fill ~30 ~44 ~12 ~32 ~44 ~12 coal_block 0  
fill ~41 ~44 ~11 ~43 ~44 ~11 coal_block 0  
fill ~41 ~44 ~12 ~43 ~44 ~12 coal_block 0 
setblock ~47 ~44 ~10 double_stone_slab 7 
setblock ~47 ~44 ~13 double_stone_slab 7  
fill ~48 ~44 ~10 ~49 ~44 ~10 stone_slab 7 
setblock ~48 ~44 ~12 nether_brick_fence 0  
fill ~48 ~44 ~13 ~49 ~44 ~13 stone_slab 7  
fill ~49 ~44 ~12 ~49 ~46 ~12 obsidian 0 
setblock ~50 ~44 ~10 double_stone_slab 7 
setblock ~50 ~44 ~12 nether_brick_fence 0 
setblock ~50 ~44 ~13 double_stone_slab 7 
setblock ~24 ~45 ~10 nether_brick_fence 0 
setblock ~24 ~45 ~12 nether_brick_fence 0  
fill ~32 ~45 ~11 ~33 ~45 ~11 coal_block 0  
fill ~32 ~45 ~12 ~33 ~45 ~12 coal_block 0 
setblock ~35 ~45 ~10 double_stone_slab 7  
fill ~35 ~45 ~11 ~38 ~45 ~11 coal_block 0  
fill ~35 ~45 ~12 ~38 ~45 ~12 coal_block 0 
setblock ~35 ~45 ~13 double_stone_slab 7  
fill ~36 ~45 ~10 ~37 ~45 ~10 stone_slab 15  
fill ~36 ~45 ~13 ~37 ~45 ~13 stone_slab 15 
setblock ~38 ~45 ~10 double_stone_slab 7 
setblock ~38 ~45 ~13 double_stone_slab 7  
fill ~40 ~45 ~11 ~41 ~45 ~11 coal_block 0  
fill ~40 ~45 ~12 ~41 ~45 ~12 coal_block 0 
setblock ~49 ~45 ~11 nether_brick_fence 0 
setblock ~49 ~45 ~13 nether_brick_fence 0  
fill ~20 ~46 ~12 ~20 ~48 ~12 obsidian 0 
setblock ~22 ~46 ~11 nether_brick_fence 0  
fill ~23 ~46 ~11 ~23 ~49 ~11 obsidian 0 
setblock ~25 ~46 ~11 nether_brick_fence 0  
fill ~33 ~46 ~11 ~35 ~46 ~11 coal_block 0  
fill ~33 ~46 ~12 ~35 ~46 ~12 coal_block 0 
setblock ~35 ~46 ~10 stone_slab 15 
setblock ~35 ~46 ~13 stone_slab 15   

KittysCommands:  
setblock ~36 ~46 ~10 nether_brick_stairs 4  
fill ~36 ~46 ~11 ~37 ~46 ~11 nether_brick 0  
fill ~36 ~46 ~12 ~37 ~46 ~12 nether_brick 0 
setblock ~36 ~46 ~13 nether_brick_stairs 4 
setblock ~37 ~46 ~10 nether_brick_stairs 5 
setblock ~37 ~46 ~13 nether_brick_stairs 5 
setblock ~38 ~46 ~10 stone_slab 15  
fill ~38 ~46 ~11 ~40 ~46 ~11 coal_block 0  
fill ~38 ~46 ~12 ~40 ~46 ~12 coal_block 0 
setblock ~38 ~46 ~13 stone_slab 15 
setblock ~48 ~46 ~12 nether_brick_fence 0  
fill ~50 ~46 ~12 ~50 ~49 ~12 obsidian 0 
setblock ~51 ~46 ~12 nether_brick_fence 0  
fill ~53 ~46 ~11 ~53 ~48 ~11 obsidian 0 
setblock ~23 ~47 ~10 nether_brick_fence 0 
setblock ~23 ~47 ~12 nether_brick_fence 0  
fill ~33 ~47 ~12 ~33 ~49 ~12 obsidian 0 
setblock ~34 ~47 ~10 nether_brick_stairs 5 
setblock ~34 ~47 ~13 nether_brick_stairs 5  
fill ~35 ~47 ~10 ~35 ~47 ~13 nether_brick_stairs 4  
fill ~36 ~47 ~10 ~37 ~47 ~10 glass 0  
fill ~36 ~47 ~11 ~37 ~47 ~11 lava 8  
fill ~36 ~47 ~12 ~37 ~47 ~12 lava 0  
fill ~36 ~47 ~13 ~37 ~47 ~13 glass 0  
fill ~38 ~47 ~10 ~38 ~47 ~13 nether_brick_stairs 5 
setblock ~39 ~47 ~10 nether_brick_stairs 4 
setblock ~39 ~47 ~13 nether_brick_stairs 4  
fill ~40 ~47 ~11 ~40 ~49 ~11 obsidian 0 
setblock ~50 ~47 ~11 nether_brick_fence 0 
setblock ~50 ~47 ~13 nether_brick_fence 0 
setblock ~22 ~48 ~11 nether_brick_fence 0 
setblock ~24 ~48 ~11 nether_brick_fence 0 
setblock ~34 ~48 ~10 nether_brick_stairs 1 
setblock ~34 ~48 ~13 nether_brick_stairs 1  
fill ~35 ~48 ~10 ~35 ~48 ~13 nether_brick_stairs 0  
fill ~36 ~48 ~10 ~37 ~48 ~10 glass 0  
fill ~36 ~48 ~11 ~37 ~48 ~11 lava 0  
fill ~36 ~48 ~12 ~37 ~48 ~12 lava 0  
fill ~36 ~48 ~13 ~37 ~48 ~13 glass 0  
fill ~38 ~48 ~10 ~38 ~48 ~13 nether_brick_stairs 1 
setblock ~39 ~48 ~10 nether_brick_stairs 0 
setblock ~39 ~48 ~13 nether_brick_stairs 0 
setblock ~49 ~48 ~12 nether_brick_fence 0 
setblock ~51 ~48 ~12 nether_brick_fence 0 
setblock ~22 ~49 ~10 nether_brick_fence 0  
fill ~22 ~49 ~11 ~22 ~51 ~11 obsidian 0 
setblock ~22 ~49 ~12 nether_brick_fence 0  
fill ~34 ~49 ~12 ~34 ~52 ~12 obsidian 0 
setblock ~35 ~49 ~10 stone_slab 7 
setblock ~35 ~49 ~13 stone_slab 7 
setblock ~36 ~49 ~10 nether_brick_stairs 0  
fill ~36 ~49 ~11 ~37 ~49 ~11 nether_brick 0  
fill ~36 ~49 ~12 ~37 ~49 ~12 nether_brick 0 
setblock ~36 ~49 ~13 nether_brick_stairs 0 
setblock ~37 ~49 ~10 nether_brick_stairs 1 
setblock ~37 ~49 ~13 nether_brick_stairs 1 
setblock ~38 ~49 ~10 stone_slab 7 
setblock ~38 ~49 ~13 stone_slab 7  
fill ~39 ~49 ~11 ~39 ~52 ~11 obsidian 0 
setblock ~51 ~49 ~11 nether_brick_fence 0  
fill ~51 ~49 ~12 ~51 ~51 ~12 obsidian 0 
setblock ~51 ~49 ~13 nether_brick_fence 0 
setblock ~21 ~50 ~11 nether_brick_fence 0 
setblock ~23 ~50 ~11 nether_brick_fence 0 
setblock ~35 ~50 ~10 double_stone_slab 7 
setblock ~35 ~50 ~13 double_stone_slab 7  
fill ~36 ~50 ~10 ~37 ~50 ~10 stone_slab 7  
fill ~36 ~50 ~13 ~37 ~50 ~13 stone_slab 7 
setblock ~38 ~50 ~10 double_stone_slab 7 
setblock ~38 ~50 ~13 double_stone_slab 7 
setblock ~50 ~50 ~12 nether_brick_fence 0 
setblock ~52 ~50 ~12 nether_brick_fence 0 
setblock ~22 ~51 ~10 nether_brick_fence 0 
setblock ~22 ~51 ~12 nether_brick_fence 0 
setblock ~51 ~51 ~11 nether_brick_fence 0 
setblock ~51 ~51 ~13 nether_brick_fence 0  
fill ~35 ~52 ~12 ~35 ~54 ~12 obsidian 0  
fill ~38 ~52 ~11 ~38 ~54 ~11 obsidian 0  
fill ~37 ~54 ~11 ~37 ~56 ~11 obsidian 0    