fill ~22~0~0 ~32~5~2 minecraft:planks 5
fill ~19~0~1 ~21~5~3 minecraft:planks 5
fill ~33~0~1 ~35~5~3 minecraft:planks 5
fill ~16~0~2 ~18~5~4 minecraft:planks 5
fill ~36~0~2 ~38~5~4 minecraft:planks 5
fill ~14~0~3 ~15~5~4 minecraft:planks 5
fill ~22~1~3 ~32~3~51 minecraft:planks 1
fill ~22~4~3 ~32~4~3 minecraft:spruce_stairs 3
fill ~39~0~3 ~40~5~4 minecraft:planks 5
fill ~12~0~4 ~13~5~4 minecraft:planks 5
fill ~19~1~4 ~21~3~50 minecraft:planks 1
fill ~19~4~4 ~35~4~4 minecraft:planks 1
fill ~33~1~4 ~35~3~50 minecraft:planks 1
fill ~41~0~4 ~42~5~4 minecraft:planks 5
fill ~11~0~5 ~11~5~6 minecraft:planks 5
fill ~12~5~5 ~15~5~5 minecraft:planks 5
fill ~13~0~5 ~13~4~6 minecraft:planks 5
fill ~15~0~5 ~15~4~5 minecraft:planks 5
fill ~16~1~5 ~18~3~49 minecraft:planks 1
fill ~16~4~5 ~38~4~5 minecraft:spruce_stairs 3
fill ~36~1~5 ~38~3~49 minecraft:planks 1
fill ~39~0~5 ~39~5~5 minecraft:planks 5
fill ~40~1~5 ~40~4~5 minecraft:planks 1
fill ~40~5~5 ~43~5~6 minecraft:planks 5
fill ~41~0~5 ~41~4~6 minecraft:planks 5
fill ~43~0~5 ~43~4~6 minecraft:planks 5
fill ~10~0~6 ~10~5~8 minecraft:planks 5
fill ~12~0~6 ~12~5~7 minecraft:planks 5
fill ~13~5~6 ~14~5~6 minecraft:planks 5
fill ~14~0~6 ~14~4~6 minecraft:planks 5
fill ~15~1~6 ~15~3~48 minecraft:planks 1
fill ~15~4~6 ~39~4~6 minecraft:planks 1
fill ~39~1~6 ~39~3~48 minecraft:planks 1
fill ~40~0~6 ~40~4~6 minecraft:planks 5
fill ~42~0~6 ~42~4~7 minecraft:planks 5
fill ~44~0~6 ~44~5~8 minecraft:planks 5
fill ~9~0~7 ~9~5~9 minecraft:planks 5
fill ~11~5~7 ~11~5~8 minecraft:planks 5
fill ~13~1~7 ~14~3~47 minecraft:planks 1
fill ~13~4~7 ~41~4~7 minecraft:spruce_stairs 3
fill ~40~1~7 ~41~3~47 minecraft:planks 1
fill ~42~5~7 ~43~5~7 minecraft:planks 5
fill ~43~1~7 ~43~3~7 minecraft:planks 1
setblock ~43~4~7 minecraft:spruce_stairs 3
fill ~45~0~7 ~45~5~9 minecraft:planks 5
fill ~8~0~8 ~8~5~11 minecraft:planks 5
fill ~11~0~8 ~11~4~8 minecraft:planks 5
fill ~12~1~8 ~12~3~46 minecraft:planks 1
fill ~12~4~8 ~42~4~8 minecraft:planks 1
fill ~42~1~8 ~42~3~46 minecraft:planks 1
fill ~43~0~8 ~43~5~8 minecraft:planks 5
fill ~46~0~8 ~46~5~11 minecraft:planks 5
fill ~7~0~9 ~7~5~10 minecraft:planks 5
fill ~10~1~9 ~11~3~45 minecraft:planks 1
fill ~10~4~9 ~44~4~9 minecraft:spruce_stairs 3
fill ~43~1~9 ~44~3~45 minecraft:planks 1
fill ~47~0~9 ~47~5~10 minecraft:planks 5
fill ~6~0~10 ~6~5~14 minecraft:planks 5
fill ~9~1~10 ~9~3~44 minecraft:planks 1
fill ~9~4~10 ~45~4~10 minecraft:planks 1
fill ~45~1~10 ~45~3~44 minecraft:planks 1
fill ~48~0~10 ~48~5~14 minecraft:planks 5
fill ~5~0~11 ~5~5~11 minecraft:planks 5
fill ~7~5~11 ~7~5~12 minecraft:planks 5
fill ~9~4~11 ~45~4~11 minecraft:spruce_stairs 3
fill ~24~21~11 ~30~21~11 minecraft:stone 6
fill ~47~1~11 ~47~4~11 minecraft:planks 1
fill ~47~5~11 ~47~5~12 minecraft:planks 5
fill ~49~0~11 ~49~5~11 minecraft:planks 5
fill ~4~0~12 ~4~5~18 minecraft:planks 5
fill ~5~5~12 ~5~5~15 minecraft:planks 5
fill ~7~0~12 ~7~4~12 minecraft:planks 5
fill ~8~1~12 ~8~3~42 minecraft:planks 1
fill ~8~4~12 ~46~4~12 minecraft:planks 1
fill ~21~21~12 ~24~21~12 minecraft:stone 6
fill ~24~20~12 ~30~20~26 minecraft:stone 6
fill ~30~21~12 ~33~21~12 minecraft:stone 6
fill ~46~1~12 ~46~3~42 minecraft:planks 1
fill ~47~0~12 ~47~4~12 minecraft:planks 5
fill ~49~5~12 ~50~5~15 minecraft:planks 5
fill ~50~0~12 ~50~4~18 minecraft:planks 5
fill ~5~0~13 ~5~4~13 minecraft:planks 5
fill ~7~1~13 ~7~3~41 minecraft:planks 1
fill ~7~4~13 ~47~4~13 minecraft:spruce_stairs 3
fill ~19~21~13 ~21~21~13 minecraft:stone 6
fill ~21~20~13 ~23~20~41 minecraft:stone 6
fill ~31~20~13 ~33~20~41 minecraft:stone 6
fill ~33~21~13 ~35~21~13 minecraft:stone 6
fill ~47~1~13 ~47~3~41 minecraft:planks 1
fill ~49~0~13 ~49~4~13 minecraft:planks 5
fill ~3~0~14 ~3~5~21 minecraft:planks 5
fill ~7~4~14 ~47~4~14 minecraft:planks 1
fill ~18~21~14 ~19~21~14 minecraft:stone 6
fill ~19~20~14 ~20~20~40 minecraft:stone 6
fill ~24~26~14 ~30~27~14 minecraft:snow
setblock ~24~28~14 minecraft:snow_layer 1
fill ~25~25~14 ~26~25~14 minecraft:snow
fill ~25~28~14 ~27~28~19 minecraft:snow
fill ~28~28~14 ~29~28~14 minecraft:snow_layer 3
setblock ~29~25~14 minecraft:snow
fill ~34~20~14 ~35~20~40 minecraft:stone 6
fill ~35~21~14 ~36~21~14 minecraft:stone 6
fill ~49~1~14 ~49~4~14 minecraft:planks 1
fill ~51~0~14 ~51~5~21 minecraft:planks 5
fill ~5~0~15 ~5~4~15 minecraft:planks 5
fill ~6~1~15 ~6~3~39 minecraft:planks 1
fill ~6~4~15 ~48~4~15 minecraft:spruce_stairs 3
fill ~17~21~15 ~18~21~15 minecraft:stone 6
fill ~18~20~15 ~18~20~39 minecraft:stone 6
fill ~22~25~15 ~22~27~15 minecraft:snow
setblock ~22~28~15 minecraft:snow_layer 2
fill ~23~26~15 ~23~27~15 minecraft:snow
setblock ~23~28~15 minecraft:snow_layer 1
fill ~24~21~15 ~30~26~39 minecraft:stained_hardened_clay 14
fill ~24~27~15 ~30~27~38 minecraft:stained_hardened_clay 14
setblock ~24~28~15 minecraft:snow_layer 2
fill ~28~28~15 ~31~28~19 minecraft:snow
fill ~31~25~15 ~31~27~15 minecraft:snow
fill ~32~26~15 ~32~27~15 minecraft:snow
setblock ~32~28~15 minecraft:snow_layer 3
fill ~36~20~15 ~36~20~39 minecraft:stone 6
fill ~36~21~15 ~37~21~15 minecraft:stone 6
fill ~48~1~15 ~48~3~39 minecraft:planks 1
fill ~49~0~15 ~49~4~15 minecraft:planks 5
fill ~2~0~16 ~2~5~38 minecraft:planks 5
fill ~5~1~16 ~5~3~38 minecraft:planks 1
fill ~5~4~16 ~49~4~16 minecraft:planks 1
fill ~16~21~16 ~17~21~16 minecraft:stone 6
fill ~17~20~16 ~17~20~38 minecraft:stone 6
fill ~20~27~16 ~21~27~16 minecraft:snow
setblock ~20~28~16 minecraft:snow_layer 2
setblock ~21~26~16 minecraft:snow
setblock ~21~28~16 minecraft:snow_layer 1
fill ~22~21~16 ~23~27~38 minecraft:stained_hardened_clay 14
fill ~22~28~16 ~24~28~20 minecraft:snow
fill ~31~21~16 ~32~26~38 minecraft:stained_hardened_clay 14
fill ~31~27~16 ~32~27~37 minecraft:stained_hardened_clay 14
fill ~32~28~16 ~33~28~21 minecraft:snow
fill ~33~24~16 ~33~27~16 minecraft:snow
fill ~34~26~16 ~34~27~16 minecraft:snow
setblock ~34~28~16 minecraft:snow_layer 3
fill ~37~20~16 ~37~20~38 minecraft:stone 6
fill ~37~21~16 ~38~21~16 minecraft:stone 6
fill ~49~1~16 ~49~3~38 minecraft:planks 1
fill ~50~5~16 ~50~5~18 minecraft:planks 5
fill ~52~0~16 ~52~5~38 minecraft:planks 5
fill ~5~4~17 ~49~4~17 minecraft:spruce_stairs 3
fill ~15~21~17 ~16~21~17 minecraft:stone 6
fill ~16~20~17 ~16~20~37 minecraft:stone 6
fill ~19~25~17 ~19~27~17 minecraft:snow
setblock ~19~28~17 minecraft:snow_layer 0
fill ~20~21~17 ~21~27~37 minecraft:stained_hardened_clay 14
fill ~20~28~17 ~21~28~22 minecraft:snow
fill ~25~29~17 ~27~29~19 minecraft:snow
setblock ~28~29~17 minecraft:snow_layer 2
setblock ~29~29~17 minecraft:snow_layer 0
fill ~33~21~17 ~34~27~37 minecraft:stained_hardened_clay 14
fill ~34~28~17 ~34~28~24 minecraft:snow
fill ~35~25~17 ~35~27~17 minecraft:snow
setblock ~35~28~17 minecraft:snow_layer 2
fill ~38~20~17 ~38~20~37 minecraft:stone 6
fill ~38~21~17 ~39~21~17 minecraft:stone 6
fill ~5~4~18 ~49~4~18 minecraft:planks 1
fill ~14~21~18 ~15~21~18 minecraft:stone 6
fill ~15~20~18 ~15~20~36 minecraft:stone 6
fill ~18~26~18 ~18~28~18 minecraft:snow
fill ~19~21~18 ~19~27~36 minecraft:stained_hardened_clay 14
fill ~19~28~18 ~19~28~36 minecraft:snow
fill ~23~29~18 ~24~29~20 minecraft:snow
setblock ~25~30~18 minecraft:snow_layer 2
fill ~26~30~18 ~27~30~19 minecraft:snow
fill ~27~5~18 ~27~5~26 minecraft:stone 6
fill ~28~29~18 ~30~29~19 minecraft:snow
setblock ~28~30~18 minecraft:snow_layer 4
setblock ~29~30~18 minecraft:snow_layer 0
setblock ~31~29~18 minecraft:snow_layer 0
fill ~35~21~18 ~35~26~36 minecraft:stained_hardened_clay 14
fill ~35~27~18 ~35~28~18 minecraft:snow
setblock ~36~26~18 minecraft:snow
setblock ~36~27~18 minecraft:snow_layer 5
fill ~39~20~18 ~39~20~36 minecraft:stone 6
fill ~39~21~18 ~40~21~18 minecraft:stone 6
fill ~1~0~19 ~1~5~35 minecraft:planks 5
fill ~4~1~19 ~4~3~35 minecraft:planks 1
fill ~4~4~19 ~24~4~19 minecraft:spruce_stairs 3
fill ~13~21~19 ~14~21~19 minecraft:stone 6
fill ~14~20~19 ~14~20~35 minecraft:stone 6
fill ~17~25~19 ~17~27~19 minecraft:snow
setblock ~17~28~19 minecraft:snow_layer 3
fill ~18~21~19 ~18~27~35 minecraft:stained_hardened_clay 14
fill ~18~28~19 ~18~28~35 minecraft:snow
fill ~22~29~19 ~22~29~21 minecraft:snow
setblock ~22~30~19 minecraft:snow_layer 0
setblock ~23~30~19 minecraft:snow_layer 2
fill ~24~30~19 ~25~30~19 minecraft:snow
fill ~25~4~19 ~25~4~20 minecraft:planks 1
fill ~25~5~19 ~26~5~35 minecraft:stone 6
setblock ~25~31~19 minecraft:snow
fill ~25~34~19 ~29~34~19 minecraft:snow
setblock ~25~35~19 minecraft:snow_layer 1
setblock ~26~4~19 minecraft:stone 6
fill ~26~33~19 ~28~33~19 minecraft:snow
setblock ~26~35~19 minecraft:snow_layer 3
fill ~27~4~19 ~28~4~19 minecraft:spruce_stairs 3
setblock ~27~32~19 minecraft:snow
fill ~27~35~19 ~27~35~35 minecraft:snow
fill ~28~5~19 ~29~5~35 minecraft:stone 6
fill ~28~30~19 ~29~30~19 minecraft:snow
fill ~28~31~19 ~29~31~19 minecraft:snow_layer 1
setblock ~28~35~19 minecraft:snow_layer 1
setblock ~29~4~19 minecraft:planks 1
fill ~30~4~19 ~50~4~19 minecraft:spruce_stairs 3
setblock ~30~30~19 minecraft:snow_layer 0
fill ~31~29~19 ~31~29~20 minecraft:snow
setblock ~32~29~19 minecraft:snow_layer 2
fill ~35~27~19 ~35~27~35 minecraft:stained_hardened_clay 14
fill ~35~28~19 ~36~28~35 minecraft:snow
fill ~36~21~19 ~36~26~35 minecraft:stained_hardened_clay 14
setblock ~36~27~19 minecraft:snow
fill ~37~25~19 ~37~26~19 minecraft:snow
setblock ~37~27~19 minecraft:snow_layer 7
fill ~40~20~19 ~40~20~35 minecraft:stone 6
fill ~40~21~19 ~41~21~19 minecraft:stone 6
fill ~50~1~19 ~50~3~35 minecraft:planks 1
fill ~53~0~19 ~53~5~35 minecraft:planks 5
fill ~4~4~20 ~24~4~20 minecraft:planks 1
fill ~13~21~20 ~13~21~21 minecraft:stone 6
fill ~16~27~20 ~16~27~21 minecraft:snow
setblock ~16~28~20 minecraft:snow_layer 1
fill ~17~21~20 ~17~27~34 minecraft:stained_hardened_clay 14
fill ~17~28~20 ~17~28~35 minecraft:snow
fill ~21~29~20 ~21~29~22 minecraft:snow
fill ~21~30~20 ~21~30~21 minecraft:snow_layer 0
setblock ~22~30~20 minecraft:snow_layer 1
fill ~23~5~20 ~24~5~34 minecraft:stone 6
fill ~23~30~20 ~24~30~20 minecraft:snow
setblock ~23~31~20 minecraft:snow
fill ~23~34~20 ~24~34~20 minecraft:snow
setblock ~23~35~20 minecraft:snow_layer 2
setblock ~24~31~20 minecraft:snow_layer 2
setblock ~24~33~20 minecraft:snow
fill ~24~35~20 ~26~35~34 minecraft:snow
fill ~25~28~20 ~29~34~20 minecraft:stained_hardened_clay 14
fill ~25~40~20 ~26~40~20 minecraft:stained_glass_pane 4
fill ~26~4~20 ~28~4~20 minecraft:planks 1
fill ~26~39~20 ~26~39~21 minecraft:stained_glass_pane 4
fill ~27~19~20 ~27~19~26 minecraft:stone 6
fill ~28~35~20 ~29~35~34 minecraft:snow
setblock ~29~4~20 minecraft:stone 6
fill ~30~4~20 ~50~4~20 minecraft:planks 1
fill ~30~5~20 ~31~5~34 minecraft:stone 6
fill ~30~28~20 ~31~28~20 minecraft:snow
setblock ~30~29~20 minecraft:snow
setblock ~30~30~20 minecraft:snow_layer 5
fill ~30~32~20 ~30~34~20 minecraft:snow
setblock ~31~30~20 minecraft:snow
setblock ~31~33~20 minecraft:snow
setblock ~31~34~20 minecraft:snow_layer 0
fill ~32~29~20 ~32~29~21 minecraft:snow
setblock ~33~29~20 minecraft:snow_layer 2
fill ~36~27~20 ~36~27~34 minecraft:stained_hardened_clay 14
fill ~37~21~20 ~37~26~34 minecraft:stained_hardened_clay 14
fill ~37~27~20 ~38~27~20 minecraft:snow
fill ~37~28~20 ~37~28~34 minecraft:snow
fill ~38~26~20 ~38~26~21 minecraft:snow
setblock ~38~28~20 minecraft:snow_layer 0
fill ~41~21~20 ~41~21~21 minecraft:stone 6
fill ~4~4~21 ~20~4~21 minecraft:spruce_stairs 3
fill ~12~21~21 ~12~21~24 minecraft:stone 6
fill ~13~20~21 ~13~20~33 minecraft:stone 6
setblock ~16~26~21 minecraft:snow
fill ~16~28~21 ~16~28~32 minecraft:snow
fill ~20~29~21 ~20~29~24 minecraft:snow
fill ~21~4~21 ~21~4~22 minecraft:planks 1
fill ~21~5~21 ~22~5~33 minecraft:stone 6
setblock ~22~4~21 minecraft:stone 6
setblock ~22~28~21 minecraft:snow
setblock ~22~30~21 minecraft:snow
fill ~22~32~21 ~22~34~21 minecraft:snow
setblock ~22~35~21 minecraft:snow_layer 0
fill ~23~4~21 ~32~4~21 minecraft:spruce_stairs 3
fill ~23~28~21 ~24~34~21 minecraft:stained_hardened_clay 14
fill ~23~35~21 ~23~35~33 minecraft:snow
setblock ~24~40~21 minecraft:stained_glass_pane 4
setblock ~24~42~21 minecraft:stained_glass_pane 1
fill ~25~19~21 ~26~19~33 minecraft:stone 6
fill ~25~34~21 ~30~34~33 minecraft:stained_hardened_clay 14
fill ~25~36~21 ~25~38~21 minecraft:brown_mushroom_block 15
setblock ~25~39~21 minecraft:fence 1
setblock ~25~40~21 minecraft:stained_glass_pane 1
fill ~25~41~21 ~25~42~21 minecraft:stained_glass_pane 4
setblock ~26~40~21 minecraft:stained_glass_pane 4
fill ~28~19~21 ~29~19~33 minecraft:stone 6
fill ~29~40~21 ~31~40~21 minecraft:stained_glass_pane 4
fill ~30~28~21 ~31~33~21 minecraft:stained_hardened_clay 14
fill ~30~35~21 ~31~35~32 minecraft:snow
fill ~31~34~21 ~32~34~21 minecraft:snow
fill ~31~39~21 ~31~39~22 minecraft:stained_glass_pane 4
fill ~32~5~21 ~33~5~33 minecraft:stone 6
fill ~32~30~21 ~32~31~21 minecraft:snow
setblock ~32~35~21 minecraft:snow_layer 3
fill ~33~4~21 ~33~4~22 minecraft:planks 1
fill ~33~29~21 ~33~29~22 minecraft:snow
fill ~34~4~21 ~50~4~21 minecraft:spruce_stairs 3
setblock ~34~29~21 minecraft:snow_layer 1
fill ~37~27~21 ~37~27~33 minecraft:stained_hardened_clay 14
setblock ~38~25~21 minecraft:snow
setblock ~38~27~21 minecraft:snow
setblock ~38~28~21 minecraft:snow_layer 3
fill ~41~20~21 ~41~20~33 minecraft:stone 6
fill ~42~21~21 ~42~21~24 minecraft:stone 6
fill ~0~0~22 ~0~5~32 minecraft:planks 5
fill ~3~1~22 ~3~3~32 minecraft:planks 1
fill ~3~4~22 ~20~4~22 minecraft:planks 1
fill ~15~27~22 ~15~27~23 minecraft:snow
setblock ~15~28~22 minecraft:snow_layer 4
fill ~16~21~22 ~16~27~32 minecraft:stained_hardened_clay 14
setblock ~19~29~22 minecraft:snow_layer 1
setblock ~21~30~22 minecraft:snow_layer 3
fill ~21~33~22 ~22~33~22 minecraft:snow
setblock ~21~34~22 minecraft:snow
setblock ~21~35~22 minecraft:snow_layer 3
fill ~22~4~22 ~32~4~22 minecraft:planks 1
fill ~22~28~22 ~22~32~22 minecraft:stained_hardened_clay 14
fill ~22~34~22 ~24~34~32 minecraft:stained_hardened_clay 14
fill ~22~35~22 ~22~35~32 minecraft:snow
fill ~23~19~22 ~24~19~32 minecraft:stone 6
setblock ~25~40~22 minecraft:stained_glass_pane 4
setblock ~25~41~22 minecraft:stained_glass_pane 1
fill ~27~6~22 ~27~6~32 minecraft:stone 6
fill ~27~18~22 ~27~18~26 minecraft:stone 6
setblock ~29~40~22 minecraft:stained_glass_pane 4
setblock ~29~42~22 minecraft:stained_glass_pane 1
fill ~30~19~22 ~31~19~32 minecraft:stone 6
fill ~30~36~22 ~30~38~22 minecraft:brown_mushroom_block 15
setblock ~30~39~22 minecraft:fence 1
setblock ~30~40~22 minecraft:stained_glass_pane 1
fill ~30~41~22 ~30~42~22 minecraft:stained_glass_pane 4
fill ~31~34~22 ~32~34~32 minecraft:stained_hardened_clay 14
setblock ~31~40~22 minecraft:stained_glass_pane 4
fill ~32~28~22 ~32~33~22 minecraft:stained_hardened_clay 14
fill ~32~35~22 ~32~35~32 minecraft:snow
setblock ~33~28~22 minecraft:snow
setblock ~33~30~22 minecraft:snow
fill ~33~33~22 ~33~34~22 minecraft:snow
fill ~34~4~22 ~51~4~22 minecraft:planks 1
fill ~34~29~22 ~34~29~24 minecraft:snow
setblock ~35~29~22 minecraft:snow_layer 1
setblock ~36~29~22 minecraft:snow_layer 0
fill ~38~21~22 ~38~26~32 minecraft:stained_hardened_clay 14
fill ~38~27~22 ~38~27~31 minecraft:stained_hardened_clay 14
fill ~38~28~22 ~38~28~32 minecraft:snow
fill ~39~26~22 ~39~27~23 minecraft:snow
setblock ~39~28~22 minecraft:snow_layer 1
fill ~51~1~22 ~51~3~32 minecraft:planks 1
fill ~54~0~22 ~54~5~32 minecraft:planks 5
fill ~3~4~23 ~19~4~23 minecraft:spruce_stairs 3
setblock ~15~26~23 minecraft:snow
fill ~15~28~23 ~15~28~30 minecraft:snow
fill ~19~29~23 ~19~29~30 minecraft:snow
fill ~19~30~23 ~19~30~24 minecraft:snow_layer 1
fill ~20~4~23 ~20~4~24 minecraft:planks 1
fill ~20~5~23 ~20~5~31 minecraft:stone 6
fill ~20~28~23 ~20~28~24 minecraft:snow
fill ~20~30~23 ~20~30~24 minecraft:snow
fill ~20~34~23 ~20~34~24 minecraft:snow
setblock ~20~35~23 minecraft:snow_layer 2
setblock ~21~4~23 minecraft:stone 6
fill ~21~28~23 ~21~34~24 minecraft:stained_hardened_clay 14
fill ~21~35~23 ~21~35~31 minecraft:snow
fill ~22~4~23 ~33~4~23 minecraft:spruce_stairs 3
fill ~22~19~23 ~22~19~31 minecraft:stone 6
fill ~25~6~23 ~26~6~31 minecraft:stone 6
fill ~25~18~23 ~26~18~31 minecraft:stone 6
fill ~28~6~23 ~29~6~31 minecraft:stone 6
fill ~28~18~23 ~29~18~31 minecraft:stone 6
setblock ~30~40~23 minecraft:stained_glass_pane 4
setblock ~30~41~23 minecraft:stained_glass_pane 1
fill ~32~19~23 ~32~19~31 minecraft:stone 6
fill ~33~28~23 ~33~33~24 minecraft:stained_hardened_clay 14
fill ~33~34~23 ~33~35~23 minecraft:snow
fill ~34~4~23 ~34~4~24 minecraft:planks 1
fill ~34~5~23 ~34~5~31 minecraft:stone 6
setblock ~34~30~23 minecraft:snow_layer 1
fill ~34~32~23 ~34~33~23 minecraft:snow
setblock ~34~34~23 minecraft:snow_layer 1
fill ~35~4~23 ~51~4~23 minecraft:spruce_stairs 3
fill ~35~29~23 ~35~29~30 minecraft:snow
setblock ~36~29~23 minecraft:snow_layer 1
setblock ~39~25~23 minecraft:snow
setblock ~39~28~23 minecraft:snow_layer 3
fill ~3~4~24 ~19~4~24 minecraft:planks 1
fill ~11~21~24 ~11~21~30 minecraft:stone 6
fill ~12~20~24 ~12~20~30 minecraft:stone 6
fill ~14~25~24 ~14~27~24 minecraft:snow
setblock ~14~28~24 minecraft:snow_layer 1
fill ~15~21~24 ~15~27~30 minecraft:stained_hardened_clay 14
setblock ~18~29~24 minecraft:snow_layer 1
setblock ~20~31~24 minecraft:snow_layer 0
fill ~20~32~24 ~20~33~24 minecraft:snow
fill ~20~35~24 ~20~35~30 minecraft:snow
fill ~21~4~24 ~33~4~24 minecraft:planks 1
fill ~24~6~24 ~24~6~30 minecraft:stone 6
fill ~24~18~24 ~24~18~30 minecraft:stone 6
fill ~27~7~24 ~27~7~30 minecraft:stone 6
fill ~30~6~24 ~30~6~30 minecraft:stone 6
fill ~30~18~24 ~30~18~30 minecraft:stone 6
fill ~33~34~24 ~33~34~30 minecraft:stained_hardened_clay 14
fill ~33~35~24 ~33~35~30 minecraft:snow
setblock ~34~30~24 minecraft:snow
fill ~34~33~24 ~34~34~24 minecraft:snow
setblock ~34~35~24 minecraft:snow_layer 1
fill ~35~4~24 ~51~4~24 minecraft:planks 1
setblock ~35~30~24 minecraft:snow_layer 2
fill ~36~29~24 ~36~29~27 minecraft:snow
setblock ~37~29~24 minecraft:snow_layer 3
fill ~39~21~24 ~39~25~30 minecraft:stained_hardened_clay 14
fill ~39~26~24 ~39~27~29 minecraft:stained_hardened_clay 14
fill ~39~28~24 ~39~28~30 minecraft:snow
fill ~40~27~24 ~40~27~30 minecraft:snow
setblock ~40~28~24 minecraft:snow_layer 0
fill ~42~20~24 ~42~20~30 minecraft:stone 6
fill ~43~21~24 ~43~21~30 minecraft:stone 6
fill ~3~4~25 ~18~4~25 minecraft:spruce_stairs 3
fill ~14~26~25 ~14~27~29 minecraft:snow
setblock ~14~28~25 minecraft:snow_layer 4
setblock ~17~29~25 minecraft:snow_layer 0
fill ~18~29~25 ~18~29~29 minecraft:snow
fill ~18~30~25 ~18~30~26 minecraft:snow_layer 0
fill ~19~4~25 ~19~4~26 minecraft:planks 1
fill ~19~5~25 ~19~5~29 minecraft:stone 6
fill ~19~30~25 ~19~30~28 minecraft:snow
setblock ~19~31~25 minecraft:snow_layer 0
fill ~19~33~25 ~19~34~25 minecraft:snow
setblock ~19~35~25 minecraft:snow_layer 4
setblock ~20~4~25 minecraft:stone 6
fill ~20~28~25 ~20~34~29 minecraft:stained_hardened_clay 14
fill ~21~4~25 ~34~4~25 minecraft:spruce_stairs 3
fill ~21~19~25 ~21~19~29 minecraft:stone 6
fill ~21~34~25 ~21~34~31 minecraft:stained_hardened_clay 14
fill ~21~40~25 ~22~40~25 minecraft:stained_glass_pane 4
fill ~22~39~25 ~22~39~26 minecraft:stained_glass_pane 4
fill ~23~6~25 ~23~6~29 minecraft:stone 6
fill ~23~18~25 ~23~18~29 minecraft:stone 6
fill ~26~7~25 ~26~8~29 minecraft:stone 6
fill ~26~17~25 ~28~17~29 minecraft:stone 6
fill ~27~8~25 ~28~8~29 minecraft:stone 6
fill ~27~9~25 ~27~10~29 minecraft:stone 6
fill ~27~15~25 ~27~16~29 minecraft:stone 6
fill ~28~7~25 ~28~7~29 minecraft:stone 6
fill ~31~6~25 ~31~6~29 minecraft:stone 6
fill ~31~18~25 ~31~18~29 minecraft:stone 6
fill ~33~19~25 ~33~19~29 minecraft:stone 6
fill ~34~28~25 ~34~33~29 minecraft:stained_hardened_clay 14
fill ~34~34~25 ~34~35~25 minecraft:snow
fill ~35~4~25 ~35~4~26 minecraft:planks 1
fill ~35~5~25 ~35~5~29 minecraft:stone 6
fill ~35~30~25 ~35~30~27 minecraft:snow
fill ~35~33~25 ~35~33~29 minecraft:snow
setblock ~35~34~25 minecraft:snow_layer 2
fill ~36~4~25 ~51~4~25 minecraft:spruce_stairs 3
setblock ~36~30~25 minecraft:snow_layer 0
setblock ~37~29~25 minecraft:snow_layer 4
fill ~40~26~25 ~40~26~29 minecraft:snow
setblock ~40~28~25 minecraft:snow_layer 2
fill ~3~4~26 ~18~4~26 minecraft:planks 1
fill ~14~25~26 ~14~25~28 minecraft:snow
fill ~14~28~26 ~14~28~27 minecraft:snow
setblock ~17~29~26 minecraft:snow_layer 2
setblock ~19~31~26 minecraft:snow
fill ~19~34~26 ~19~34~29 minecraft:snow
fill ~19~35~26 ~19~35~27 minecraft:snow
fill ~20~4~26 ~34~4~26 minecraft:planks 1
setblock ~20~40~26 minecraft:stained_glass_pane 4
setblock ~20~42~26 minecraft:stained_glass_pane 1
fill ~21~36~26 ~21~38~26 minecraft:brown_mushroom_block 15
setblock ~21~39~26 minecraft:fence 1
setblock ~21~40~26 minecraft:stained_glass_pane 1
fill ~21~41~26 ~21~42~26 minecraft:stained_glass_pane 4
setblock ~22~40~26 minecraft:stained_glass_pane 4
setblock ~24~36~26 minecraft:dark_oak_stairs 4
setblock ~24~37~26 minecraft:double_wooden_slab 5
setblock ~24~38~26 minecraft:wooden_slab 13
setblock ~24~39~26 minecraft:dark_oak_stairs 0
fill ~24~41~26 ~25~41~26 minecraft:stained_glass_pane 4
fill ~25~7~26 ~25~8~28 minecraft:stone 6
fill ~25~17~26 ~25~17~28 minecraft:stone 6
setblock ~25~36~26 minecraft:planks 5
setblock ~25~38~26 minecraft:wooden_slab 5
setblock ~25~39~26 minecraft:planks 5
setblock ~25~40~26 minecraft:fence 1
fill ~25~42~26 ~25~43~26 minecraft:stained_glass_pane 4
fill ~26~9~26 ~26~16~28 minecraft:stone 6
setblock ~26~36~26 minecraft:dark_oak_stairs 5
setblock ~26~37~26 minecraft:double_wooden_slab 5
setblock ~26~38~26 minecraft:wooden_slab 13
setblock ~26~39~26 minecraft:dark_oak_stairs 1
fill ~27~11~26 ~28~14~28 minecraft:stone 6
fill ~28~9~26 ~28~10~28 minecraft:stone 6
fill ~28~15~26 ~28~16~28 minecraft:stone 6
fill ~28~36~26 ~30~36~26 minecraft:planks 5
fill ~28~41~26 ~29~41~26 minecraft:stained_glass_pane 4
setblock ~28~42~26 minecraft:stained_glass_pane 4
fill ~29~7~26 ~29~8~28 minecraft:stone 6
fill ~29~17~26 ~29~17~28 minecraft:stone 6
fill ~29~37~26 ~29~39~26 minecraft:planks 5
setblock ~29~40~26 minecraft:fence 1
setblock ~29~42~26 minecraft:stained_glass_pane 1
setblock ~29~43~26 minecraft:stained_glass_pane 4
setblock ~30~39~26 minecraft:dark_oak_stairs 1
fill ~34~34~26 ~34~34~29 minecraft:stained_hardened_clay 14
fill ~34~35~26 ~34~35~28 minecraft:snow
fill ~35~32~26 ~35~32~27 minecraft:snow
fill ~35~34~26 ~35~34~29 minecraft:snow
setblock ~35~35~26 minecraft:snow_layer 1
fill ~36~4~26 ~51~4~26 minecraft:planks 1
setblock ~36~30~26 minecraft:snow_layer 2
setblock ~37~29~26 minecraft:snow_layer 1
fill ~40~25~26 ~40~25~28 minecraft:snow
fill ~40~28~26 ~40~28~28 minecraft:snow
fill ~3~4~27 ~17~4~27 minecraft:spruce_stairs 3
fill ~17~29~27 ~17~29~28 minecraft:snow
fill ~18~4~27 ~18~4~28 minecraft:planks 1
setblock ~18~5~27 minecraft:stone 6
setblock ~18~30~27 minecraft:snow
fill ~18~31~27 ~19~31~27 minecraft:snow_layer 0
setblock ~19~4~27 minecraft:stone 6
fill ~19~33~27 ~19~33~28 minecraft:snow
fill ~20~4~27 ~51~4~27 minecraft:spruce_stairs 3
setblock ~20~19~27 minecraft:stone 6
setblock ~21~40~27 minecraft:stained_glass_pane 4
setblock ~21~41~27 minecraft:stained_glass_pane 1
setblock ~22~6~27 minecraft:stone 6
setblock ~22~18~27 minecraft:stone 6
setblock ~24~7~27 minecraft:stone 6
fill ~24~20~27 ~26~20~42 minecraft:stone 6
fill ~24~41~27 ~24~42~27 minecraft:stained_glass_pane 4
fill ~25~9~27 ~25~10~27 minecraft:stone 6
fill ~25~15~27 ~25~16~27 minecraft:stone 6
fill ~25~41~27 ~25~42~27 minecraft:stained_glass_pane 1
setblock ~27~28~27 minecraft:stone_block_slab 12
setblock ~27~33~27 minecraft:stained_hardened_clay 14
fill ~28~20~27 ~30~20~42 minecraft:stone 6
setblock ~28~41~27 minecraft:stained_glass_pane 4
fill ~29~9~27 ~29~10~27 minecraft:stone 6
fill ~29~15~27 ~29~16~27 minecraft:stone 6
setblock ~29~41~27 minecraft:stained_glass_pane 1
setblock ~29~42~27 minecraft:stained_glass_pane 4
setblock ~30~7~27 minecraft:stone 6
setblock ~32~6~27 minecraft:stone 6
setblock ~32~18~27 minecraft:stone 6
setblock ~34~19~27 minecraft:stone 6
setblock ~35~35~27 minecraft:snow_layer 2
setblock ~36~5~27 minecraft:stone 6
setblock ~36~30~27 minecraft:snow_layer 1
setblock ~37~29~27 minecraft:snow_layer 2
fill ~3~4~28 ~17~4~28 minecraft:planks 1
fill ~9~47~28 ~45~47~28 minecraft:stained_hardened_clay 14
fill ~9~48~28 ~9~54~28 minecraft:stained_hardened_clay 14
fill ~10~54~28 ~16~54~28 minecraft:stained_hardened_clay 14
setblock ~11~49~28 minecraft:planks 5
setblock ~11~50~28 minecraft:wooden_slab 13
fill ~11~51~28 ~11~52~28 minecraft:planks 5
setblock ~13~50~28 minecraft:wooden_slab 13
fill ~13~51~28 ~13~52~28 minecraft:double_wooden_slab 5
setblock ~14~28~28 minecraft:snow_layer 4
fill ~14~49~28 ~14~50~28 minecraft:planks 5
setblock ~14~51~28 minecraft:wooden_slab 5
setblock ~15~50~28 minecraft:wooden_slab 13
fill ~15~51~28 ~15~52~28 minecraft:double_wooden_slab 5
setblock ~16~55~28 minecraft:stained_hardened_clay 14
fill ~16~56~28 ~16~59~28 minecraft:stained_hardened_clay 1
fill ~17~49~28 ~17~51~28 minecraft:planks 5
setblock ~17~52~28 minecraft:dark_oak_stairs 0
fill ~17~59~28 ~38~59~28 minecraft:stained_hardened_clay 1
setblock ~18~30~28 minecraft:snow_layer 2
fill ~18~50~28 ~19~50~28 minecraft:planks 5
setblock ~18~52~28 minecraft:planks 5
setblock ~18~55~28 minecraft:wooden_slab 13
setblock ~18~56~28 minecraft:double_wooden_slab 5
setblock ~18~57~28 minecraft:planks 5
fill ~19~4~28 ~51~4~28 minecraft:planks 1
setblock ~19~31~28 minecraft:snow_layer 0
setblock ~19~32~28 minecraft:snow
setblock ~19~35~28 minecraft:snow_layer 4
setblock ~19~49~28 minecraft:planks 5
setblock ~19~51~28 minecraft:planks 5
setblock ~19~52~28 minecraft:dark_oak_stairs 1
fill ~19~54~28 ~19~55~28 minecraft:planks 5
setblock ~19~56~28 minecraft:wooden_slab 5
setblock ~20~55~28 minecraft:wooden_slab 13
setblock ~20~56~28 minecraft:double_wooden_slab 5
setblock ~20~57~28 minecraft:planks 5
setblock ~21~49~28 minecraft:dark_oak_stairs 4
fill ~21~50~28 ~21~51~28 minecraft:planks 5
setblock ~21~52~28 minecraft:dark_oak_stairs 0
fill ~22~49~28 ~23~49~28 minecraft:planks 5
fill ~22~52~28 ~23~52~28 minecraft:planks 5
setblock ~22~55~28 minecraft:dark_oak_stairs 4
setblock ~22~56~28 minecraft:planks 5
setblock ~22~57~28 minecraft:dark_oak_stairs 0
fill ~23~50~28 ~23~51~28 minecraft:planks 5
fill ~23~55~28 ~24~55~28 minecraft:planks 5
fill ~23~57~28 ~24~57~28 minecraft:planks 5
setblock ~24~54~28 minecraft:planks 5
setblock ~24~56~28 minecraft:planks 5
fill ~25~49~28 ~25~52~28 minecraft:planks 5
setblock ~26~50~28 minecraft:wooden_slab 13
setblock ~26~51~28 minecraft:wooden_slab 5
setblock ~26~55~28 minecraft:dark_oak_stairs 4
setblock ~26~56~28 minecraft:planks 5
setblock ~26~57~28 minecraft:dark_oak_stairs 0
fill ~27~5~28 ~27~5~36 minecraft:stone 6
fill ~27~18~28 ~27~20~32 minecraft:stone 6
fill ~27~49~28 ~27~52~28 minecraft:planks 5
fill ~27~55~28 ~28~55~28 minecraft:planks 5
fill ~27~57~28 ~28~57~28 minecraft:planks 5
setblock ~28~54~28 minecraft:planks 5
setblock ~28~56~28 minecraft:planks 5
fill ~29~52~28 ~31~52~28 minecraft:planks 5
fill ~30~49~28 ~30~51~28 minecraft:planks 5
fill ~30~54~28 ~30~56~28 minecraft:planks 5
setblock ~30~57~28 minecraft:dark_oak_stairs 0
fill ~31~55~28 ~32~55~28 minecraft:planks 5
setblock ~31~57~28 minecraft:planks 5
fill ~32~40~28 ~33~40~28 minecraft:stained_glass_pane 4
setblock ~32~54~28 minecraft:planks 5
setblock ~32~56~28 minecraft:planks 5
setblock ~32~57~28 minecraft:dark_oak_stairs 1
fill ~33~39~28 ~33~39~29 minecraft:stained_glass_pane 4
setblock ~33~49~28 minecraft:planks 5
setblock ~33~50~28 minecraft:wooden_slab 5
setblock ~33~51~28 minecraft:planks 5
setblock ~33~52~28 minecraft:dark_oak_stairs 0
fill ~34~50~28 ~35~50~28 minecraft:planks 5
fill ~34~52~28 ~35~52~28 minecraft:planks 5
fill ~34~54~28 ~34~57~28 minecraft:planks 5
setblock ~35~30~28 minecraft:snow_layer 5
setblock ~35~35~28 minecraft:snow_layer 1
setblock ~35~49~28 minecraft:planks 5
setblock ~35~51~28 minecraft:planks 5
setblock ~35~55~28 minecraft:wooden_slab 13
setblock ~35~56~28 minecraft:wooden_slab 5
setblock ~36~29~28 minecraft:snow_layer 4
fill ~36~54~28 ~36~57~28 minecraft:planks 5
setblock ~37~29~28 minecraft:snow_layer 0
fill ~37~49~28 ~39~49~28 minecraft:planks 5
fill ~37~52~28 ~39~52~28 minecraft:planks 5
fill ~38~50~28 ~38~51~28 minecraft:planks 5
fill ~38~54~28 ~45~54~28 minecraft:stained_hardened_clay 14
setblock ~38~55~28 minecraft:stained_hardened_clay 14
fill ~38~56~28 ~38~58~28 minecraft:stained_hardened_clay 1
setblock ~41~49~28 minecraft:dark_oak_stairs 4
setblock ~41~50~28 minecraft:planks 5
setblock ~41~51~28 minecraft:wooden_slab 13
setblock ~41~52~28 minecraft:dark_oak_stairs 0
fill ~42~49~28 ~43~49~28 minecraft:planks 5
setblock ~42~51~28 minecraft:wooden_slab 5
fill ~42~52~28 ~43~52~28 minecraft:planks 5
fill ~43~50~28 ~43~51~28 minecraft:planks 5
fill ~45~48~28 ~45~53~28 minecraft:stained_hardened_clay 14
fill ~3~4~29 ~18~4~29 minecraft:spruce_stairs 3
fill ~9~47~29 ~9~47~31 minecraft:stained_hardened_clay 14
fill ~9~54~29 ~9~54~31 minecraft:stained_hardened_clay 14
fill ~10~48~29 ~44~53~30 minecraft:snow
setblock ~14~28~29 minecraft:snow_layer 3
fill ~16~54~29 ~16~54~31 minecraft:stained_hardened_clay 14
fill ~16~59~29 ~16~59~31 minecraft:stained_hardened_clay 1
setblock ~17~29~29 minecraft:snow_layer 1
fill ~17~54~29 ~37~58~30 minecraft:snow
fill ~19~4~29 ~19~4~30 minecraft:planks 1
setblock ~19~30~29 minecraft:snow_layer 2
setblock ~19~35~29 minecraft:snow_layer 1
setblock ~20~4~29 minecraft:stone 6
fill ~21~4~29 ~34~4~29 minecraft:spruce_stairs 3
fill ~27~59~29 ~27~59~31 minecraft:stained_hardened_clay 1
setblock ~31~40~29 minecraft:stained_glass_pane 4
setblock ~31~42~29 minecraft:stained_glass_pane 1
fill ~32~36~29 ~32~38~29 minecraft:brown_mushroom_block 15
setblock ~32~39~29 minecraft:fence 1
setblock ~32~40~29 minecraft:stained_glass_pane 1
fill ~32~41~29 ~32~42~29 minecraft:stained_glass_pane 4
setblock ~33~40~29 minecraft:stained_glass_pane 4
setblock ~34~35~29 minecraft:snow_layer 5
fill ~35~4~29 ~35~4~30 minecraft:planks 1
setblock ~35~30~29 minecraft:snow_layer 1
fill ~36~4~29 ~51~4~29 minecraft:spruce_stairs 3
setblock ~36~29~29 minecraft:snow_layer 1
fill ~38~54~29 ~38~54~31 minecraft:stained_hardened_clay 14
fill ~38~59~29 ~38~59~31 minecraft:stained_hardened_clay 1
setblock ~40~28~29 minecraft:snow_layer 3
fill ~45~47~29 ~45~47~31 minecraft:stained_hardened_clay 14
fill ~45~54~29 ~45~54~31 minecraft:stained_hardened_clay 14
fill ~3~4~30 ~18~4~30 minecraft:planks 1
fill ~12~21~30 ~12~21~33 minecraft:stone 6
setblock ~14~27~30 minecraft:snow
setblock ~14~28~30 minecraft:snow_layer 2
setblock ~18~29~30 minecraft:snow_layer 0
setblock ~19~30~30 minecraft:snow_layer 0
fill ~20~4~30 ~34~4~30 minecraft:planks 1
fill ~20~28~30 ~20~28~37 minecraft:snow
fill ~20~29~30 ~20~29~32 minecraft:snow
setblock ~20~30~30 minecraft:snow
setblock ~20~31~30 minecraft:snow_layer 0
fill ~20~32~30 ~20~34~30 minecraft:snow
fill ~21~28~30 ~21~33~31 minecraft:stained_hardened_clay 14
setblock ~32~40~30 minecraft:stained_glass_pane 4
setblock ~32~41~30 minecraft:stained_glass_pane 1
fill ~33~28~30 ~33~33~31 minecraft:stained_hardened_clay 14
fill ~34~28~30 ~34~28~37 minecraft:snow
fill ~34~29~30 ~34~29~32 minecraft:snow
fill ~34~30~30 ~34~30~31 minecraft:snow
fill ~34~32~30 ~34~34~30 minecraft:snow
setblock ~35~30~30 minecraft:snow_layer 0
fill ~36~4~30 ~51~4~30 minecraft:planks 1
setblock ~36~29~30 minecraft:snow_layer 0
fill ~39~26~30 ~39~26~32 minecraft:snow
setblock ~39~27~30 minecraft:stained_hardened_clay 14
setblock ~40~28~30 minecraft:snow_layer 0
fill ~42~21~30 ~42~21~33 minecraft:stone 6
fill ~3~4~31 ~19~4~31 minecraft:spruce_stairs 3
fill ~9~48~31 ~9~53~31 minecraft:stained_hardened_clay 14
fill ~10~47~31 ~44~47~31 minecraft:stained_hardened_clay 14
fill ~10~54~31 ~15~54~31 minecraft:stained_hardened_clay 14
fill ~11~49~31 ~12~49~31 minecraft:planks 5
fill ~11~50~31 ~11~52~31 minecraft:planks 5
setblock ~12~51~31 minecraft:wooden_slab 5
setblock ~12~52~31 minecraft:planks 5
setblock ~13~49~31 minecraft:dark_oak_stairs 5
setblock ~13~50~31 minecraft:planks 5
setblock ~13~51~31 minecraft:wooden_slab 13
setblock ~13~52~31 minecraft:dark_oak_stairs 1
fill ~15~27~31 ~15~27~32 minecraft:snow
setblock ~15~28~31 minecraft:snow_layer 5
fill ~15~49~31 ~17~49~31 minecraft:planks 5
fill ~15~52~31 ~17~52~31 minecraft:planks 5
fill ~16~50~31 ~16~51~31 minecraft:planks 5
setblock ~16~55~31 minecraft:stained_hardened_clay 14
fill ~16~56~31 ~16~58~31 minecraft:stained_hardened_clay 1
fill ~17~59~31 ~26~59~31 minecraft:stained_hardened_clay 1
fill ~18~54~31 ~18~57~31 minecraft:planks 5
setblock ~19~29~31 minecraft:snow_layer 1
fill ~19~49~31 ~19~52~31 minecraft:planks 5
setblock ~19~55~31 minecraft:wooden_slab 13
setblock ~19~56~31 minecraft:wooden_slab 5
fill ~20~4~31 ~20~4~32 minecraft:planks 1
setblock ~20~30~31 minecraft:snow_layer 1
fill ~20~33~31 ~20~34~31 minecraft:snow
setblock ~20~35~31 minecraft:snow_layer 0
setblock ~20~50~31 minecraft:planks 5
setblock ~20~52~31 minecraft:planks 5
fill ~20~54~31 ~20~57~31 minecraft:planks 5
setblock ~21~4~31 minecraft:stone 6
setblock ~21~49~31 minecraft:planks 5
setblock ~21~50~31 minecraft:wooden_slab 5
setblock ~21~51~31 minecraft:planks 5
setblock ~21~52~31 minecraft:dark_oak_stairs 1
fill ~22~4~31 ~33~4~31 minecraft:spruce_stairs 3
fill ~22~54~31 ~22~56~31 minecraft:planks 5
setblock ~22~57~31 minecraft:dark_oak_stairs 0
fill ~23~52~31 ~25~52~31 minecraft:planks 5
fill ~23~55~31 ~24~55~31 minecraft:planks 5
setblock ~23~57~31 minecraft:planks 5
fill ~24~49~31 ~24~51~31 minecraft:planks 5
setblock ~24~54~31 minecraft:planks 5
setblock ~24~56~31 minecraft:planks 5
setblock ~24~57~31 minecraft:dark_oak_stairs 1
fill ~26~40~31 ~27~40~31 minecraft:stained_glass_pane 4
fill ~26~54~31 ~26~57~31 minecraft:planks 5
fill ~27~39~31 ~27~39~32 minecraft:stained_glass_pane 4
fill ~27~49~31 ~27~52~31 minecraft:planks 5
setblock ~27~55~31 minecraft:planks 5
setblock ~27~57~31 minecraft:planks 5
setblock ~28~50~31 minecraft:wooden_slab 13
setblock ~28~51~31 minecraft:wooden_slab 5
setblock ~28~55~31 minecraft:dark_oak_stairs 5
setblock ~28~56~31 minecraft:planks 5
setblock ~28~57~31 minecraft:dark_oak_stairs 1
fill ~28~59~31 ~37~59~31 minecraft:stained_hardened_clay 1
fill ~29~49~31 ~29~52~31 minecraft:planks 5
fill ~30~54~31 ~30~57~31 minecraft:planks 5
fill ~31~49~31 ~32~49~31 minecraft:planks 5
fill ~31~50~31 ~31~52~31 minecraft:planks 5
setblock ~31~55~31 minecraft:planks 5
setblock ~31~57~31 minecraft:planks 5
setblock ~32~52~31 minecraft:planks 5
setblock ~32~55~31 minecraft:dark_oak_stairs 5
setblock ~32~56~31 minecraft:planks 5
setblock ~32~57~31 minecraft:dark_oak_stairs 1
fill ~33~34~31 ~33~34~32 minecraft:snow
setblock ~33~35~31 minecraft:snow_layer 5
setblock ~33~49~31 minecraft:dark_oak_stairs 5
fill ~33~50~31 ~33~51~31 minecraft:planks 5
setblock ~33~52~31 minecraft:dark_oak_stairs 1
fill ~34~4~31 ~34~4~32 minecraft:planks 1
setblock ~34~33~31 minecraft:snow
setblock ~34~55~31 minecraft:wooden_slab 13
setblock ~34~56~31 minecraft:double_wooden_slab 5
setblock ~34~57~31 minecraft:planks 5
fill ~35~4~31 ~51~4~31 minecraft:spruce_stairs 3
setblock ~35~29~31 minecraft:snow_layer 2
fill ~35~49~31 ~35~51~31 minecraft:planks 5
setblock ~35~52~31 minecraft:dark_oak_stairs 0
fill ~35~54~31 ~35~55~31 minecraft:planks 5
setblock ~35~56~31 minecraft:wooden_slab 5
fill ~36~50~31 ~37~50~31 minecraft:planks 5
setblock ~36~52~31 minecraft:planks 5
setblock ~36~55~31 minecraft:wooden_slab 13
setblock ~36~56~31 minecraft:double_wooden_slab 5
setblock ~36~57~31 minecraft:planks 5
setblock ~37~49~31 minecraft:planks 5
setblock ~37~51~31 minecraft:planks 5
setblock ~37~52~31 minecraft:dark_oak_stairs 1
setblock ~38~55~31 minecraft:stained_hardened_clay 14
fill ~38~56~31 ~38~58~31 minecraft:stained_hardened_clay 1
setblock ~39~25~31 minecraft:snow
setblock ~39~27~31 minecraft:snow
setblock ~39~28~31 minecraft:snow_layer 0
setblock ~39~50~31 minecraft:wooden_slab 13
fill ~39~51~31 ~39~52~31 minecraft:double_wooden_slab 5
fill ~39~54~31 ~44~54~31 minecraft:stained_hardened_clay 14
fill ~40~49~31 ~40~50~31 minecraft:planks 5
setblock ~40~51~31 minecraft:wooden_slab 5
setblock ~41~50~31 minecraft:wooden_slab 13
fill ~41~51~31 ~41~52~31 minecraft:double_wooden_slab 5
setblock ~43~49~31 minecraft:planks 5
setblock ~43~50~31 minecraft:wooden_slab 13
fill ~43~51~31 ~43~52~31 minecraft:planks 5
fill ~45~48~31 ~45~53~31 minecraft:stained_hardened_clay 14
fill ~3~4~32 ~19~4~32 minecraft:planks 1
fill ~15~25~32 ~15~26~32 minecraft:snow
setblock ~15~28~32 minecraft:snow_layer 2
setblock ~19~29~32 minecraft:snow_layer 2
fill ~21~4~32 ~33~4~32 minecraft:planks 1
fill ~21~28~32 ~21~28~38 minecraft:snow
fill ~21~29~32 ~21~29~33 minecraft:snow
setblock ~21~30~32 minecraft:snow
setblock ~21~31~32 minecraft:snow_layer 2
setblock ~21~34~32 minecraft:snow
setblock ~21~35~32 minecraft:snow_layer 5
fill ~22~28~32 ~22~33~32 minecraft:stained_hardened_clay 14
setblock ~25~40~32 minecraft:stained_glass_pane 4
setblock ~25~42~32 minecraft:stained_glass_pane 1
fill ~26~36~32 ~26~38~32 minecraft:brown_mushroom_block 15
setblock ~26~39~32 minecraft:fence 1
setblock ~26~40~32 minecraft:stained_glass_pane 1
fill ~26~41~32 ~26~42~32 minecraft:stained_glass_pane 4
setblock ~27~40~32 minecraft:stained_glass_pane 4
fill ~32~28~32 ~32~33~32 minecraft:stained_hardened_clay 14
fill ~33~28~32 ~33~28~37 minecraft:snow
fill ~33~29~32 ~33~29~34 minecraft:snow
setblock ~33~30~32 minecraft:snow
setblock ~33~31~32 minecraft:snow_layer 4
setblock ~33~33~32 minecraft:snow
fill ~35~4~32 ~51~4~32 minecraft:planks 1
setblock ~35~29~32 minecraft:snow_layer 1
fill ~38~27~32 ~38~27~33 minecraft:snow
setblock ~39~27~32 minecraft:snow_layer 1
fill ~3~0~33 ~3~5~40 minecraft:planks 5
fill ~4~4~33 ~20~4~33 minecraft:spruce_stairs 3
fill ~13~21~33 ~13~21~35 minecraft:stone 6
fill ~16~26~33 ~16~27~33 minecraft:snow
setblock ~16~28~33 minecraft:snow_layer 4
setblock ~20~29~33 minecraft:snow_layer 1
fill ~21~4~33 ~21~4~34 minecraft:planks 1
setblock ~21~30~33 minecraft:snow_layer 3
setblock ~22~4~33 minecraft:stone 6
fill ~22~28~33 ~22~28~38 minecraft:snow
fill ~22~29~33 ~22~29~34 minecraft:snow
setblock ~22~30~33 minecraft:snow
setblock ~22~31~33 minecraft:snow_layer 5
fill ~22~33~33 ~22~34~33 minecraft:snow
setblock ~22~35~33 minecraft:snow_layer 2
fill ~23~4~33 ~32~4~33 minecraft:spruce_stairs 3
fill ~23~28~33 ~24~34~33 minecraft:stained_hardened_clay 14
setblock ~26~40~33 minecraft:stained_glass_pane 4
setblock ~26~41~33 minecraft:stained_glass_pane 1
fill ~27~19~33 ~27~20~34 minecraft:stone 6
fill ~30~28~33 ~31~33~33 minecraft:stained_hardened_clay 14
setblock ~30~35~33 minecraft:snow
fill ~31~34~33 ~32~34~33 minecraft:snow
setblock ~31~35~33 minecraft:snow_layer 4
fill ~32~28~33 ~32~28~38 minecraft:snow
fill ~32~29~33 ~32~29~35 minecraft:snow
setblock ~32~30~33 minecraft:snow
fill ~32~32~33 ~32~33~33 minecraft:snow
fill ~33~4~33 ~33~4~34 minecraft:planks 1
setblock ~33~30~33 minecraft:snow_layer 0
fill ~34~4~33 ~50~4~33 minecraft:spruce_stairs 3
setblock ~34~29~33 minecraft:snow_layer 1
fill ~38~25~33 ~38~26~33 minecraft:snow
setblock ~38~28~33 minecraft:snow_layer 0
fill ~41~21~33 ~41~21~35 minecraft:stone 6
fill ~51~0~33 ~51~5~40 minecraft:planks 5
fill ~4~4~34 ~20~4~34 minecraft:planks 1
setblock ~16~27~34 minecraft:snow
setblock ~16~28~34 minecraft:snow_layer 2
setblock ~21~29~34 minecraft:snow_layer 0
fill ~22~4~34 ~32~4~34 minecraft:planks 1
fill ~23~28~34 ~24~28~39 minecraft:snow
fill ~23~29~34 ~24~29~34 minecraft:snow
setblock ~23~30~34 minecraft:snow_layer 3
fill ~23~34~34 ~24~34~34 minecraft:snow
setblock ~23~35~34 minecraft:snow_layer 1
setblock ~24~30~34 minecraft:snow
setblock ~24~31~34 minecraft:snow_layer 0
setblock ~24~33~34 minecraft:snow
fill ~25~28~34 ~29~34~34 minecraft:stained_hardened_clay 14
fill ~30~28~34 ~31~28~38 minecraft:snow
fill ~30~29~34 ~31~29~35 minecraft:snow
fill ~30~30~34 ~31~30~34 minecraft:snow
setblock ~30~31~34 minecraft:snow_layer 1
fill ~30~33~34 ~30~34~34 minecraft:snow
setblock ~30~35~34 minecraft:snow_layer 1
setblock ~32~30~34 minecraft:snow_layer 1
fill ~34~4~34 ~50~4~34 minecraft:planks 1
fill ~37~27~34 ~37~27~35 minecraft:snow
fill ~4~4~35 ~24~4~35 minecraft:spruce_stairs 3
fill ~14~21~35 ~14~21~36 minecraft:stone 6
fill ~17~26~35 ~17~27~35 minecraft:snow
setblock ~22~29~35 minecraft:snow_layer 0
setblock ~23~29~35 minecraft:snow_layer 3
fill ~24~29~35 ~29~29~35 minecraft:snow
setblock ~24~30~35 minecraft:snow_layer 1
fill ~25~4~35 ~25~4~36 minecraft:planks 1
fill ~25~28~35 ~29~28~39 minecraft:snow
fill ~25~30~35 ~28~30~35 minecraft:snow
setblock ~25~31~35 minecraft:snow_layer 1
fill ~25~34~35 ~29~34~35 minecraft:snow
setblock ~25~35~35 minecraft:snow_layer 2
setblock ~26~4~35 minecraft:stone 6
fill ~26~31~35 ~27~31~35 minecraft:snow
fill ~26~33~35 ~28~33~35 minecraft:snow
setblock ~26~35~35 minecraft:snow
fill ~27~4~35 ~28~4~35 minecraft:spruce_stairs 3
fill ~27~20~35 ~27~20~42 minecraft:stone 6
setblock ~28~35~35 minecraft:snow
fill ~29~4~35 ~29~4~36 minecraft:planks 1
setblock ~29~30~35 minecraft:snow_layer 2
setblock ~29~35~35 minecraft:snow_layer 1
fill ~30~4~35 ~50~4~35 minecraft:spruce_stairs 3
setblock ~30~30~35 minecraft:snow_layer 0
setblock ~36~27~35 minecraft:snow
setblock ~37~26~35 minecraft:snow
setblock ~37~28~35 minecraft:snow_layer 1
fill ~40~21~35 ~40~21~36 minecraft:stone 6
fill ~4~0~36 ~4~5~42 minecraft:planks 5
fill ~5~4~36 ~24~4~36 minecraft:planks 1
fill ~15~21~36 ~15~21~37 minecraft:stone 6
fill ~18~25~36 ~18~27~36 minecraft:snow
setblock ~18~28~36 minecraft:snow_layer 3
setblock ~24~29~36 minecraft:snow_layer 0
setblock ~25~29~36 minecraft:snow_layer 2
fill ~26~4~36 ~28~4~36 minecraft:planks 1
setblock ~26~29~36 minecraft:snow_layer 4
fill ~27~29~36 ~30~29~36 minecraft:snow
setblock ~27~30~36 minecraft:snow_layer 0
setblock ~29~30~36 minecraft:snow_layer 0
fill ~30~4~36 ~49~4~36 minecraft:planks 1
fill ~35~27~36 ~35~27~37 minecraft:snow
setblock ~35~28~36 minecraft:snow
setblock ~36~26~36 minecraft:snow
setblock ~36~27~36 minecraft:snow_layer 3
fill ~39~21~36 ~39~21~37 minecraft:stone 6
fill ~50~0~36 ~50~5~42 minecraft:planks 5
fill ~5~4~37 ~49~4~37 minecraft:spruce_stairs 3
fill ~16~21~37 ~16~21~38 minecraft:stone 6
fill ~19~26~37 ~19~27~37 minecraft:snow
setblock ~19~28~37 minecraft:snow_layer 2
setblock ~26~29~37 minecraft:snow_layer 0
fill ~27~29~37 ~29~29~37 minecraft:snow_layer 2
fill ~35~25~37 ~35~26~37 minecraft:snow
setblock ~35~28~37 minecraft:snow_layer 2
fill ~38~21~37 ~38~21~38 minecraft:stone 6
fill ~5~4~38 ~49~4~38 minecraft:planks 1
fill ~17~21~38 ~17~21~39 minecraft:stone 6
fill ~20~27~38 ~21~27~38 minecraft:snow
setblock ~21~26~38 minecraft:snow
setblock ~31~27~38 minecraft:stained_hardened_clay 14
fill ~32~27~38 ~34~27~38 minecraft:snow
fill ~33~25~38 ~33~26~38 minecraft:snow
setblock ~33~28~38 minecraft:snow_layer 4
setblock ~34~26~38 minecraft:snow
setblock ~34~28~38 minecraft:snow_layer 2
fill ~37~21~38 ~37~21~39 minecraft:stone 6
fill ~5~0~39 ~5~5~39 minecraft:planks 5
fill ~6~4~39 ~48~4~39 minecraft:spruce_stairs 3
fill ~18~21~39 ~18~21~40 minecraft:stone 6
fill ~22~27~39 ~23~27~39 minecraft:snow
setblock ~22~28~39 minecraft:snow_layer 3
fill ~24~27~39 ~28~27~39 minecraft:stained_hardened_clay 14
fill ~29~27~39 ~31~27~39 minecraft:snow
setblock ~30~28~39 minecraft:snow
fill ~31~25~39 ~31~26~39 minecraft:snow
setblock ~31~28~39 minecraft:snow_layer 2
setblock ~32~26~39 minecraft:snow
setblock ~32~27~39 minecraft:snow_layer 0
fill ~36~21~39 ~36~21~40 minecraft:stone 6
fill ~49~0~39 ~49~5~39 minecraft:planks 5
fill ~5~4~40 ~6~5~41 minecraft:planks 5
fill ~6~0~40 ~6~3~44 minecraft:planks 5
fill ~7~4~40 ~47~4~40 minecraft:planks 1
fill ~19~21~40 ~19~21~41 minecraft:stone 6
fill ~24~27~40 ~28~27~40 minecraft:snow
setblock ~24~28~40 minecraft:snow_layer 0
fill ~25~26~40 ~29~26~40 minecraft:snow
setblock ~25~28~40 minecraft:snow_layer 3
fill ~26~25~40 ~28~25~40 minecraft:snow
fill ~26~28~40 ~27~28~40 minecraft:snow
setblock ~28~28~40 minecraft:snow_layer 2
setblock ~29~27~40 minecraft:snow_layer 5
fill ~35~21~40 ~35~21~41 minecraft:stone 6
fill ~48~0~40 ~48~5~44 minecraft:planks 5
fill ~49~1~40 ~49~4~40 minecraft:planks 1
fill ~49~5~40 ~49~5~43 minecraft:planks 5
fill ~5~0~41 ~5~3~41 minecraft:planks 5
fill ~7~4~41 ~47~4~41 minecraft:spruce_stairs 3
fill ~20~21~41 ~21~21~41 minecraft:stone 6
fill ~34~21~41 ~34~21~42 minecraft:stone 6
fill ~49~0~41 ~49~4~41 minecraft:planks 5
fill ~5~5~42 ~7~5~43 minecraft:planks 5
fill ~6~4~42 ~7~4~42 minecraft:planks 5
fill ~7~0~42 ~7~3~42 minecraft:planks 5
fill ~8~4~42 ~46~4~42 minecraft:planks 1
fill ~21~21~42 ~24~21~42 minecraft:stone 6
fill ~30~21~42 ~33~21~42 minecraft:stone 6
fill ~47~0~42 ~47~5~42 minecraft:planks 5
fill ~5~0~43 ~5~4~43 minecraft:planks 5
fill ~6~4~43 ~6~4~44 minecraft:planks 5
fill ~8~0~43 ~8~5~46 minecraft:planks 5
fill ~9~4~43 ~45~4~43 minecraft:spruce_stairs 3
fill ~24~21~43 ~30~21~43 minecraft:stone 6
fill ~46~0~43 ~46~5~46 minecraft:planks 5
fill ~47~1~43 ~47~4~43 minecraft:planks 1
fill ~47~5~43 ~47~5~45 minecraft:planks 5
fill ~49~0~43 ~49~4~43 minecraft:planks 5
fill ~6~5~44 ~7~5~44 minecraft:planks 5
fill ~7~0~44 ~7~4~45 minecraft:planks 5
fill ~9~4~44 ~45~4~44 minecraft:planks 1
fill ~47~0~44 ~47~4~45 minecraft:planks 5
setblock ~7~5~45 minecraft:planks 5
fill ~9~0~45 ~9~5~47 minecraft:planks 5
fill ~10~4~45 ~44~4~45 minecraft:spruce_stairs 3
fill ~45~0~45 ~45~5~47 minecraft:planks 5
fill ~10~0~46 ~11~5~46 minecraft:planks 5
fill ~12~4~46 ~42~4~46 minecraft:planks 1
fill ~43~0~46 ~44~5~46 minecraft:planks 5
fill ~10~0~47 ~10~5~48 minecraft:planks 5
fill ~11~5~47 ~12~5~49 minecraft:planks 5
fill ~12~0~47 ~12~4~48 minecraft:planks 5
fill ~13~4~47 ~41~4~47 minecraft:spruce_stairs 3
fill ~42~0~47 ~42~5~48 minecraft:planks 5
fill ~43~1~47 ~43~4~47 minecraft:planks 1
fill ~43~5~47 ~44~5~48 minecraft:planks 5
fill ~44~0~47 ~44~4~48 minecraft:planks 5
fill ~11~0~48 ~11~4~49 minecraft:planks 5
fill ~13~0~48 ~14~5~48 minecraft:planks 5
fill ~15~4~48 ~39~4~48 minecraft:planks 1
fill ~40~0~48 ~41~5~48 minecraft:planks 5
fill ~43~0~48 ~43~4~49 minecraft:planks 5
fill ~13~0~49 ~13~5~50 minecraft:planks 5
fill ~14~5~49 ~15~5~51 minecraft:planks 5
fill ~15~0~49 ~15~4~51 minecraft:planks 5
fill ~16~4~49 ~38~4~49 minecraft:spruce_stairs 3
fill ~39~0~49 ~39~5~51 minecraft:planks 5
fill ~40~1~49 ~40~4~49 minecraft:planks 1
fill ~40~5~49 ~43~5~49 minecraft:planks 5
fill ~41~0~49 ~41~4~50 minecraft:planks 5
fill ~12~0~50 ~12~5~50 minecraft:planks 5
fill ~14~0~50 ~14~4~51 minecraft:planks 5
fill ~16~0~50 ~18~5~52 minecraft:planks 5
fill ~19~4~50 ~35~4~50 minecraft:planks 1
fill ~36~0~50 ~38~5~52 minecraft:planks 5
fill ~40~0~50 ~40~5~51 minecraft:planks 5
fill ~41~5~50 ~42~5~50 minecraft:planks 5
fill ~42~0~50 ~42~4~50 minecraft:planks 5
fill ~19~0~51 ~21~5~53 minecraft:planks 5
fill ~22~4~51 ~32~4~51 minecraft:spruce_stairs 3
fill ~33~0~51 ~35~5~53 minecraft:planks 5
fill ~22~0~52 ~32~5~54 minecraft:planks 5