fill ~19 ~-4 ~8 ~19 ~2 ~8 stained_hardened_clay 15  
fill ~19 ~-4 ~9 ~19 ~-1 ~9 stained_hardened_clay 15  
fill ~19 ~-4 ~10 ~19 ~-1 ~10 fence 5  
fill ~19 ~-4 ~11 ~19 ~5 ~11 stained_hardened_clay 15  
fill ~19 ~-4 ~12 ~19 ~4 ~12 stained_hardened_clay 15  
fill ~19 ~-4 ~13 ~19 ~3 ~13 stained_hardened_clay 15  
fill ~19 ~-4 ~14 ~19 ~0 ~14 stained_hardened_clay 15  
fill ~19 ~-4 ~15 ~19 ~-1 ~15 stained_hardened_clay 15  
fill ~19 ~-4 ~16 ~19 ~1 ~16 stained_hardened_clay 15  
fill ~19 ~-4 ~17 ~19 ~-1 ~17 stained_hardened_clay 15  
fill ~19 ~-4 ~18 ~19 ~-2 ~18 stained_hardened_clay 15  
fill ~19 ~-4 ~19 ~19 ~-2 ~19 stained_hardened_clay 15  
fill ~19 ~-4 ~20 ~19 ~-2 ~20 stained_hardened_clay 15  
fill ~19 ~-4 ~21 ~19 ~-3 ~21 stained_hardened_clay 15  
fill ~19 ~-4 ~22 ~19 ~-3 ~22 stained_hardened_clay 15  
fill ~19 ~-4 ~23 ~19 ~-3 ~23 stained_hardened_clay 15  
fill ~19 ~-4 ~24 ~19 ~-3 ~24 stained_hardened_clay 15  
fill ~19 ~-4 ~25 ~19 ~-3 ~25 stained_hardened_clay 15  
fill ~19 ~-4 ~26 ~19 ~-3 ~26 stained_hardened_clay 15  
fill ~19 ~-4 ~27 ~19 ~-3 ~27 stained_hardened_clay 15  
fill ~19 ~-4 ~28 ~19 ~-3 ~28 stained_hardened_clay 15  
fill ~19 ~-4 ~29 ~19 ~-3 ~29 stained_hardened_clay 15  
fill ~19 ~-4 ~30 ~19 ~-3 ~30 stained_hardened_clay 15  
fill ~19 ~-4 ~31 ~19 ~-3 ~31 stained_hardened_clay 15  
fill ~19 ~-4 ~32 ~19 ~-3 ~32 stained_hardened_clay 15  
fill ~19 ~-4 ~33 ~19 ~1 ~33 stained_hardened_clay 15  
fill ~19 ~-4 ~34 ~19 ~-3 ~34 stained_hardened_clay 15  
fill ~19 ~-4 ~35 ~19 ~-3 ~35 stained_hardened_clay 15  
fill ~19 ~-4 ~36 ~19 ~-3 ~36 stained_hardened_clay 15  
fill ~19 ~-4 ~37 ~19 ~-3 ~37 stained_hardened_clay 15  
fill ~19 ~-4 ~38 ~19 ~-3 ~38 stained_hardened_clay 15  
fill ~19 ~-4 ~39 ~19 ~-3 ~39 stained_hardened_clay 15  
fill ~19 ~-4 ~40 ~19 ~-3 ~40 stained_hardened_clay 15  
fill ~19 ~-4 ~41 ~19 ~-3 ~41 stained_hardened_clay 15  
fill ~19 ~-4 ~42 ~19 ~-3 ~42 stained_hardened_clay 15  
fill ~19 ~-4 ~43 ~19 ~-3 ~43 stained_hardened_clay 15  
fill ~19 ~-4 ~44 ~19 ~-3 ~44 stained_hardened_clay 15  
fill ~19 ~-4 ~45 ~19 ~-3 ~45 stained_hardened_clay 15  
fill ~19 ~-4 ~46 ~19 ~-3 ~46 stained_hardened_clay 15  
fill ~19 ~-4 ~47 ~19 ~-3 ~47 stained_hardened_clay 15  
fill ~19 ~-4 ~48 ~19 ~-3 ~48 stained_hardened_clay 15  
fill ~19 ~-4 ~49 ~19 ~-3 ~49 stained_hardened_clay 15  
fill ~19 ~-4 ~50 ~19 ~-3 ~50 stained_hardened_clay 15  
fill ~19 ~-4 ~51 ~19 ~-3 ~51 stained_hardened_clay 15  
fill ~19 ~-4 ~52 ~19 ~-3 ~52 stained_hardened_clay 15  
fill ~19 ~-4 ~53 ~19 ~-3 ~53 stained_hardened_clay 15  
fill ~19 ~-4 ~54 ~19 ~-3 ~54 stained_hardened_clay 15  
fill ~19 ~-4 ~55 ~19 ~-3 ~55 stained_hardened_clay 15  
fill ~19 ~-4 ~56 ~19 ~-3 ~56 stained_hardened_clay 15  
fill ~19 ~-4 ~57 ~19 ~-3 ~57 stained_hardened_clay 15  
fill ~19 ~-4 ~58 ~19 ~-3 ~58 stained_hardened_clay 15  
fill ~19 ~-4 ~59 ~19 ~0 ~59 stained_hardened_clay 15  
fill ~19 ~-4 ~60 ~19 ~-3 ~60 stained_hardened_clay 15  
fill ~19 ~-4 ~61 ~19 ~-3 ~61 stained_hardened_clay 15  
fill ~19 ~-4 ~62 ~19 ~-3 ~62 stained_hardened_clay 15  
fill ~19 ~-4 ~63 ~19 ~-3 ~63 stained_hardened_clay 15  
fill ~19 ~-4 ~64 ~19 ~-3 ~64 stained_hardened_clay 15  
fill ~19 ~-4 ~65 ~19 ~-3 ~65 stained_hardened_clay 15  
fill ~14 ~-3 ~26 ~24 ~-3 ~26 stained_hardened_clay 15  
fill ~14 ~-3 ~27 ~24 ~-3 ~27 stained_hardened_clay 15  
fill ~14 ~-3 ~28 ~24 ~-3 ~28 stained_hardened_clay 15  
fill ~14 ~-3 ~29 ~24 ~-3 ~29 stained_hardened_clay 15  
fill ~14 ~-3 ~30 ~24 ~-3 ~30 stained_hardened_clay 15  
fill ~14 ~-3 ~31 ~24 ~-3 ~31 stained_hardened_clay 15  
fill ~14 ~-3 ~32 ~24 ~-3 ~32 stained_hardened_clay 15  
fill ~14 ~-3 ~33 ~24 ~-3 ~33 stained_hardened_clay 15  
fill ~14 ~-3 ~34 ~24 ~-3 ~34 stained_hardened_clay 15  
fill ~14 ~-3 ~35 ~24 ~-3 ~35 stained_hardened_clay 15  
fill ~14 ~-3 ~36 ~24 ~-3 ~36 stained_hardened_clay 15  
fill ~14 ~-3 ~37 ~24 ~-3 ~37 stained_hardened_clay 15  
fill ~14 ~-3 ~38 ~24 ~-3 ~38 stained_hardened_clay 15  
fill ~14 ~-3 ~39 ~24 ~-3 ~39 stained_hardened_clay 15  
fill ~14 ~-3 ~40 ~24 ~-3 ~40 stained_hardened_clay 15  
fill ~14 ~-3 ~41 ~24 ~-3 ~41 stained_hardened_clay 15  
fill ~14 ~-3 ~42 ~24 ~-3 ~42 stained_hardened_clay 15  
fill ~14 ~-3 ~43 ~24 ~-3 ~43 stained_hardened_clay 15  
fill ~14 ~-3 ~44 ~24 ~-3 ~44 stained_hardened_clay 15  
fill ~14 ~-3 ~45 ~24 ~-3 ~45 stained_hardened_clay 15  
fill ~14 ~-3 ~46 ~24 ~-3 ~46 stained_hardened_clay 15  
fill ~14 ~-3 ~47 ~24 ~-3 ~47 stained_hardened_clay 15  
fill ~14 ~-3 ~48 ~24 ~-3 ~48 stained_hardened_clay 15  
fill ~14 ~-3 ~49 ~24 ~-3 ~49 stained_hardened_clay 15  
fill ~14 ~-3 ~50 ~24 ~-3 ~50 stained_hardened_clay 15  
fill ~15 ~-3 ~23 ~23 ~-3 ~23 stained_hardened_clay 15  
fill ~15 ~-3 ~24 ~23 ~-3 ~24 stained_hardened_clay 15  
fill ~15 ~-3 ~25 ~23 ~-3 ~25 stained_hardened_clay 15  
fill ~15 ~-3 ~51 ~23 ~-3 ~51 stained_hardened_clay 15  
fill ~15 ~-3 ~52 ~23 ~-3 ~52 stained_hardened_clay 15  
fill ~15 ~-3 ~53 ~23 ~-3 ~53 stained_hardened_clay 15  
fill ~15 ~-3 ~54 ~23 ~-3 ~54 stained_hardened_clay 15  
fill ~15 ~-3 ~55 ~23 ~-3 ~55 stained_hardened_clay 15  
fill ~16 ~-3 ~22 ~22 ~-3 ~22 stained_hardened_clay 15  
fill ~16 ~-3 ~56 ~22 ~-3 ~56 stained_hardened_clay 15  
fill ~16 ~-3 ~57 ~22 ~-3 ~57 stained_hardened_clay 15  
fill ~16 ~-3 ~58 ~22 ~-3 ~58 stained_hardened_clay 15  
fill ~16 ~-3 ~59 ~22 ~-3 ~59 stained_hardened_clay 15  
fill ~16 ~-3 ~60 ~22 ~-3 ~60 stained_hardened_clay 15  
fill ~16 ~-3 ~61 ~22 ~-3 ~61 stained_hardened_clay 15  
fill ~17 ~-3 ~21 ~21 ~-3 ~21 stained_hardened_clay 15  
fill ~17 ~-3 ~62 ~21 ~-3 ~62 stained_hardened_clay 15  
fill ~17 ~-3 ~63 ~21 ~-3 ~63 stained_hardened_clay 15  
fill ~18 ~-3 ~64 ~18 ~-3 ~65 stained_hardened_clay 15 
setblock ~19 ~-3 ~66 stained_hardened_clay 15  
fill ~20 ~-3 ~64 ~20 ~-3 ~65 stained_hardened_clay 15  
fill ~12 ~-2 ~26 ~13 ~-2 ~26 stained_hardened_clay 15  
fill ~12 ~-2 ~27 ~13 ~-2 ~27 stained_hardened_clay 15  
fill ~12 ~-2 ~28 ~13 ~-2 ~28 stained_hardened_clay 15  
fill ~12 ~-2 ~29 ~13 ~-2 ~29 stained_hardened_clay 15  
fill ~12 ~-2 ~30 ~13 ~-2 ~30 stained_hardened_clay 15  
fill ~12 ~-2 ~31 ~13 ~-2 ~31 stained_hardened_clay 15  
fill ~12 ~-2 ~32 ~13 ~-2 ~32 stained_hardened_clay 15  
fill ~12 ~-2 ~33 ~13 ~-2 ~33 stained_hardened_clay 15  
fill ~12 ~-2 ~34 ~13 ~-2 ~34 stained_hardened_clay 15  
fill ~12 ~-2 ~35 ~13 ~-2 ~35 stained_hardened_clay 15  
fill ~12 ~-2 ~36 ~13 ~-2 ~36 stained_hardened_clay 15  
fill ~12 ~-2 ~37 ~13 ~-2 ~37 stained_hardened_clay 15  
fill ~12 ~-2 ~38 ~13 ~-2 ~38 stained_hardened_clay 15  
fill ~12 ~-2 ~39 ~13 ~-2 ~39 stained_hardened_clay 15  
fill ~12 ~-2 ~40 ~13 ~-2 ~40 stained_hardened_clay 15  
fill ~12 ~-2 ~41 ~13 ~-2 ~41 stained_hardened_clay 15  
fill ~12 ~-2 ~42 ~13 ~-2 ~42 stained_hardened_clay 15  
fill ~12 ~-2 ~43 ~13 ~-2 ~43 stained_hardened_clay 15  
fill ~12 ~-2 ~44 ~13 ~-2 ~44 stained_hardened_clay 15  
fill ~12 ~-2 ~45 ~13 ~-2 ~45 stained_hardened_clay 15  
fill ~12 ~-2 ~46 ~13 ~-2 ~46 stained_hardened_clay 15  
fill ~12 ~-2 ~47 ~13 ~-2 ~47 stained_hardened_clay 15  
fill ~12 ~-2 ~48 ~13 ~-2 ~48 stained_hardened_clay 15  
fill ~12 ~-2 ~49 ~13 ~-2 ~49 stained_hardened_clay 15  
fill ~12 ~-2 ~50 ~13 ~-2 ~50 stained_hardened_clay 15  
fill ~12 ~-2 ~51 ~14 ~-2 ~51 stained_hardened_clay 15  
fill ~12 ~-2 ~52 ~14 ~-2 ~52 stained_hardened_clay 15  
fill ~12 ~-2 ~53 ~14 ~-2 ~53 stained_hardened_clay 15  
fill ~12 ~-2 ~54 ~14 ~-2 ~54 stained_hardened_clay 15  
fill ~13 ~-2 ~22 ~15 ~-2 ~22 stained_hardened_clay 15  
fill ~13 ~-2 ~23 ~14 ~-2 ~23 stained_hardened_clay 15  
fill ~13 ~-2 ~24 ~14 ~-2 ~24 stained_hardened_clay 15  
fill ~13 ~-2 ~25 ~14 ~-2 ~25 stained_hardened_clay 15  
fill ~13 ~-2 ~55 ~14 ~-2 ~55 stained_hardened_clay 15  
fill ~13 ~-2 ~56 ~15 ~-2 ~56 stained_hardened_clay 15  
fill ~13 ~-2 ~57 ~15 ~-2 ~57 stained_hardened_clay 15  
fill ~13 ~-2 ~58 ~15 ~-2 ~58 stained_hardened_clay 15  
fill ~14 ~-2 ~20 ~24 ~-2 ~20 stained_hardened_clay 15  
fill ~14 ~-2 ~21 ~16 ~-2 ~21 stained_hardened_clay 15  
fill ~14 ~-2 ~59 ~15 ~-2 ~59 stained_hardened_clay 15  
fill ~14 ~-2 ~60 ~15 ~-2 ~60 stained_hardened_clay 15  
fill ~14 ~-2 ~61 ~15 ~-2 ~61 stained_hardened_clay 15  
fill ~15 ~-2 ~19 ~23 ~-2 ~19 stained_hardened_clay 15  
fill ~15 ~-2 ~62 ~16 ~-2 ~62 stained_hardened_clay 15  
fill ~15 ~-2 ~63 ~16 ~-2 ~63 stained_hardened_clay 15  
fill ~16 ~-2 ~64 ~17 ~-2 ~64 stained_hardened_clay 15  
fill ~17 ~-2 ~18 ~21 ~-2 ~18 stained_hardened_clay 15 
setblock ~17 ~-2 ~65 stained_hardened_clay 15 
setblock ~18 ~-2 ~66 stained_hardened_clay 15 
setblock ~19 ~-2 ~67 stained_hardened_clay 15 
setblock ~20 ~-2 ~66 stained_hardened_clay 15  
fill ~21 ~-2 ~64 ~22 ~-2 ~64 stained_hardened_clay 15  
fill ~21 ~-2 ~65 ~21 ~-2 ~64 stained_hardened_clay 15  
fill ~22 ~-2 ~21 ~24 ~-2 ~21 stained_hardened_clay 15  
fill ~22 ~-2 ~62 ~23 ~-2 ~62 stained_hardened_clay 15  
fill ~22 ~-2 ~63 ~23 ~-2 ~63 stained_hardened_clay 15  
fill ~23 ~-2 ~22 ~25 ~-2 ~22 stained_hardened_clay 15  
fill ~23 ~-2 ~56 ~25 ~-2 ~56 stained_hardened_clay 15  
fill ~23 ~-2 ~57 ~25 ~-2 ~57 stained_hardened_clay 15  
fill ~23 ~-2 ~58 ~25 ~-2 ~58 stained_hardened_clay 15  
fill ~23 ~-2 ~59 ~24 ~-2 ~59 stained_hardened_clay 15  
fill ~23 ~-2 ~60 ~24 ~-2 ~60 stained_hardened_clay 15  
fill ~23 ~-2 ~61 ~24 ~-2 ~61 stained_hardened_clay 15  
fill ~24 ~-2 ~23 ~25 ~-2 ~23 stained_hardened_clay 15  
fill ~24 ~-2 ~24 ~25 ~-2 ~24 stained_hardened_clay 15  
fill ~24 ~-2 ~25 ~25 ~-2 ~25 stained_hardened_clay 15  
fill ~24 ~-2 ~51 ~26 ~-2 ~51 stained_hardened_clay 15  
fill ~24 ~-2 ~52 ~26 ~-2 ~52 stained_hardened_clay 15  
fill ~24 ~-2 ~53 ~26 ~-2 ~53 stained_hardened_clay 15  
fill ~24 ~-2 ~54 ~26 ~-2 ~54 stained_hardened_clay 15  
fill ~24 ~-2 ~55 ~25 ~-2 ~55 stained_hardened_clay 15  
fill ~25 ~-2 ~26 ~26 ~-2 ~26 stained_hardened_clay 15  
fill ~25 ~-2 ~27 ~26 ~-2 ~27 stained_hardened_clay 15  
fill ~25 ~-2 ~28 ~26 ~-2 ~28 stained_hardened_clay 15  
fill ~25 ~-2 ~29 ~26 ~-2 ~29 stained_hardened_clay 15  
fill ~25 ~-2 ~30 ~26 ~-2 ~30 stained_hardened_clay 15  
fill ~25 ~-2 ~31 ~26 ~-2 ~31 stained_hardened_clay 15  
fill ~25 ~-2 ~32 ~26 ~-2 ~32 stained_hardened_clay 15  
fill ~25 ~-2 ~33 ~26 ~-2 ~33 stained_hardened_clay 15  
fill ~25 ~-2 ~34 ~26 ~-2 ~34 stained_hardened_clay 15  
fill ~25 ~-2 ~35 ~26 ~-2 ~35 stained_hardened_clay 15  
fill ~25 ~-2 ~36 ~26 ~-2 ~36 stained_hardened_clay 15  
fill ~25 ~-2 ~37 ~26 ~-2 ~37 stained_hardened_clay 15  
fill ~25 ~-2 ~38 ~26 ~-2 ~38 stained_hardened_clay 15  
fill ~25 ~-2 ~39 ~26 ~-2 ~39 stained_hardened_clay 15  
fill ~25 ~-2 ~40 ~26 ~-2 ~40 stained_hardened_clay 15  
fill ~25 ~-2 ~41 ~26 ~-2 ~41 stained_hardened_clay 15  
fill ~25 ~-2 ~42 ~26 ~-2 ~42 stained_hardened_clay 15  
fill ~25 ~-2 ~43 ~26 ~-2 ~43 stained_hardened_clay 15  
fill ~25 ~-2 ~44 ~26 ~-2 ~44 stained_hardened_clay 15  
fill ~25 ~-2 ~45 ~26 ~-2 ~45 stained_hardened_clay 15  
fill ~25 ~-2 ~46 ~26 ~-2 ~46 stained_hardened_clay 15  
fill ~25 ~-2 ~47 ~26 ~-2 ~47 stained_hardened_clay 15  
fill ~25 ~-2 ~48 ~26 ~-2 ~48 stained_hardened_clay 15  
fill ~25 ~-2 ~49 ~26 ~-2 ~49 stained_hardened_clay 15  
fill ~25 ~-2 ~50 ~26 ~-2 ~50 stained_hardened_clay 15  
fill ~11 ~-1 ~21 ~13 ~-1 ~21 stained_hardened_clay 15  
fill ~11 ~-1 ~22 ~12 ~-1 ~22 stained_hardened_clay 15  
fill ~11 ~-1 ~23 ~12 ~-1 ~23 stained_hardened_clay 15  
fill ~11 ~-1 ~24 ~12 ~-1 ~24 stained_hardened_clay 15  
fill ~11 ~-1 ~25 ~12 ~-1 ~25 stained_hardened_clay 15  
fill ~11 ~-1 ~26 ~11 ~-1 ~57 stained_hardened_clay 15  
fill ~12 ~-1 ~17 ~26 ~-1 ~17 stained_hardened_clay 15  
fill ~12 ~-1 ~18 ~16 ~-1 ~18 stained_hardened_clay 15  
fill ~12 ~-1 ~19 ~14 ~-1 ~19 stained_hardened_clay 15  
fill ~12 ~-1 ~20 ~13 ~-1 ~20 stained_hardened_clay 15  
fill ~12 ~-1 ~55 ~12 ~-1 ~61 stained_hardened_clay 15  
fill ~13 ~-1 ~16 ~25 ~-1 ~16 stained_hardened_clay 15  
fill ~13 ~-1 ~59 ~13 ~-1 ~62 stained_hardened_clay 15  
fill ~14 ~-1 ~62 ~14 ~-1 ~63 stained_hardened_clay 15  
fill ~15 ~-1 ~15 ~23 ~-1 ~15 stained_hardened_clay 15 
setblock ~15 ~-1 ~64 stained_hardened_clay 15 
setblock ~16 ~-1 ~65 stained_hardened_clay 15 
setblock ~17 ~-1 ~66 stained_hardened_clay 15 
setblock ~18 ~-1 ~67 stained_hardened_clay 15 
setblock ~19 ~-1 ~68 stained_hardened_clay 15 
setblock ~20 ~-1 ~67 stained_hardened_clay 15 
setblock ~21 ~-1 ~66 stained_hardened_clay 15  
fill ~22 ~-1 ~18 ~26 ~-1 ~18 stained_hardened_clay 15 
setblock ~22 ~-1 ~65 stained_hardened_clay 15 
setblock ~23 ~-1 ~64 stained_hardened_clay 15  
fill ~24 ~-1 ~19 ~26 ~-1 ~19 stained_hardened_clay 15  
fill ~24 ~-1 ~62 ~25 ~-1 ~62 stained_hardened_clay 15  
fill ~24 ~-1 ~63 ~24 ~-1 ~62 stained_hardened_clay 15  
fill ~25 ~-1 ~20 ~26 ~-1 ~20 stained_hardened_clay 15  
fill ~25 ~-1 ~21 ~26 ~-1 ~21 stained_hardened_clay 15  
fill ~25 ~-1 ~59 ~26 ~-1 ~59 stained_hardened_clay 15  
fill ~25 ~-1 ~60 ~26 ~-1 ~60 stained_hardened_clay 15  
fill ~25 ~-1 ~61 ~26 ~-1 ~61 stained_hardened_clay 15  
fill ~26 ~-1 ~22 ~26 ~-1 ~25 stained_hardened_clay 15  
fill ~26 ~-1 ~55 ~27 ~-1 ~55 stained_hardened_clay 15  
fill ~26 ~-1 ~56 ~27 ~-1 ~56 stained_hardened_clay 15  
fill ~26 ~-1 ~57 ~27 ~-1 ~57 stained_hardened_clay 15  
fill ~26 ~-1 ~58 ~26 ~-1 ~55 stained_hardened_clay 15  
fill ~27 ~-1 ~25 ~27 ~0 ~25 stained_hardened_clay 15  
fill ~27 ~-1 ~26 ~27 ~-1 ~57 stained_hardened_clay 15  
fill ~10 ~0 ~26 ~10 ~2 ~26 stained_hardened_clay 15  
fill ~10 ~0 ~27 ~10 ~1 ~27 stained_hardened_clay 15  
fill ~10 ~0 ~28 ~10 ~4 ~28 stained_hardened_clay 15  
fill ~10 ~0 ~29 ~10 ~0 ~55 stained_hardened_clay 15  
fill ~11 ~0 ~18 ~12 ~0 ~18 stained_hardened_clay 15  
fill ~11 ~0 ~19 ~11 ~3 ~19 stained_hardened_clay 15  
fill ~11 ~0 ~20 ~11 ~2 ~20 stained_hardened_clay 15  
fill ~11 ~0 ~21 ~11 ~1 ~21 stained_hardened_clay 15  
fill ~11 ~0 ~22 ~11 ~9 ~22 stained_hardened_clay 15  
fill ~11 ~0 ~23 ~11 ~-1 ~23 stained_hardened_clay 15  
fill ~11 ~0 ~24 ~11 ~-1 ~24 stained_hardened_clay 15  
fill ~11 ~0 ~25 ~11 ~-1 ~25 stained_hardened_clay 15  
fill ~11 ~0 ~56 ~11 ~0 ~60 stained_hardened_clay 15  
fill ~12 ~0 ~15 ~14 ~0 ~15 stained_hardened_clay 15  
fill ~12 ~0 ~16 ~12 ~0 ~18 stained_hardened_clay 15  
fill ~12 ~0 ~61 ~12 ~0 ~62 stained_hardened_clay 15  
fill ~13 ~0 ~14 ~25 ~0 ~14 stained_hardened_clay 15 
setblock ~13 ~0 ~63 stained_hardened_clay 15 
setblock ~14 ~0 ~64 stained_hardened_clay 15  
fill ~15 ~0 ~13 ~23 ~0 ~13 stained_hardened_clay 15 
setblock ~15 ~0 ~65 stained_hardened_clay 15 
setblock ~16 ~0 ~66 stained_hardened_clay 15 
setblock ~17 ~0 ~67 stained_hardened_clay 15 
setblock ~18 ~0 ~68 stained_hardened_clay 15  
fill ~19 ~0 ~9 ~19 ~5 ~9 fence 5  
fill ~19 ~0 ~10 ~19 ~5 ~10 stained_hardened_clay 15 
setblock ~19 ~0 ~69 stained_hardened_clay 15 
setblock ~20 ~0 ~68 stained_hardened_clay 15 
setblock ~21 ~0 ~67 stained_hardened_clay 15 
setblock ~22 ~0 ~66 stained_hardened_clay 15 
setblock ~23 ~0 ~65 stained_hardened_clay 15  
fill ~24 ~0 ~15 ~26 ~0 ~15 stained_hardened_clay 15 
setblock ~24 ~0 ~64 stained_hardened_clay 15 
setblock ~25 ~0 ~63 stained_hardened_clay 15  
fill ~26 ~0 ~16 ~26 ~0 ~18 stained_hardened_clay 15  
fill ~26 ~0 ~61 ~26 ~0 ~62 stained_hardened_clay 15  
fill ~27 ~0 ~19 ~27 ~3 ~19 stained_hardened_clay 15  
fill ~27 ~0 ~20 ~27 ~2 ~20 stained_hardened_clay 15  
fill ~27 ~0 ~21 ~27 ~1 ~21 stained_hardened_clay 15  
fill ~27 ~0 ~22 ~27 ~9 ~22 stained_hardened_clay 15  
fill ~27 ~0 ~23 ~27 ~0 ~25 stained_hardened_clay 15  
fill ~27 ~0 ~56 ~27 ~0 ~60 stained_hardened_clay 15  
fill ~28 ~0 ~26 ~28 ~2 ~26 stained_hardened_clay 15  
fill ~28 ~0 ~27 ~28 ~1 ~27 stained_hardened_clay 15  
fill ~28 ~0 ~28 ~28 ~4 ~28 stained_hardened_clay 15  
fill ~28 ~0 ~29 ~28 ~0 ~55 stained_hardened_clay 15  
fill ~9 ~1 ~29 ~9 ~3 ~29 stained_hardened_clay 15  
fill ~9 ~1 ~30 ~9 ~2 ~30 stained_hardened_clay 15  
fill ~9 ~1 ~31 ~9 ~2 ~31 stained_hardened_clay 15  
fill ~9 ~1 ~32 ~9 ~1 ~52 stained_hardened_clay 15  
fill ~10 ~1 ~23 ~10 ~5 ~23 stained_hardened_clay 15  
fill ~10 ~1 ~24 ~10 ~4 ~24 stained_hardened_clay 15  
fill ~10 ~1 ~25 ~10 ~3 ~25 stained_hardened_clay 15  
fill ~10 ~1 ~29 ~28 ~1 ~29 planks 5  
fill ~10 ~1 ~30 ~28 ~1 ~30 planks 5  
fill ~10 ~1 ~31 ~28 ~1 ~31 planks 5  
fill ~10 ~1 ~32 ~28 ~1 ~32 planks 5  
fill ~10 ~1 ~33 ~18 ~1 ~33 planks 5  
fill ~10 ~1 ~34 ~28 ~1 ~34 planks 5  
fill ~10 ~1 ~35 ~28 ~1 ~35 planks 5  
fill ~10 ~1 ~36 ~28 ~1 ~36 planks 5  
fill ~10 ~1 ~37 ~28 ~1 ~37 planks 5  
fill ~10 ~1 ~38 ~28 ~1 ~38 planks 5  
fill ~10 ~1 ~39 ~28 ~1 ~39 planks 5  
fill ~10 ~1 ~40 ~28 ~1 ~40 planks 5  
fill ~10 ~1 ~41 ~28 ~1 ~41 planks 5  
fill ~10 ~1 ~42 ~28 ~1 ~42 planks 5  
fill ~10 ~1 ~43 ~28 ~1 ~43 planks 5  
fill ~10 ~1 ~44 ~28 ~1 ~44 planks 5  
fill ~10 ~1 ~45 ~28 ~1 ~45 planks 5  
fill ~10 ~1 ~46 ~28 ~1 ~46 planks 5  
fill ~10 ~1 ~47 ~28 ~1 ~47 planks 5  
fill ~10 ~1 ~48 ~28 ~1 ~48 planks 5  
fill ~10 ~1 ~49 ~28 ~1 ~49 planks 5  
fill ~10 ~1 ~50 ~28 ~1 ~50 planks 5  
fill ~10 ~1 ~51 ~28 ~1 ~51 planks 5  
fill ~10 ~1 ~52 ~28 ~1 ~52 planks 5  
fill ~10 ~1 ~53 ~10 ~1 ~57 stained_hardened_clay 15  
fill ~11 ~1 ~16 ~11 ~5 ~16 stained_hardened_clay 15  
fill ~11 ~1 ~17 ~11 ~5 ~17 stained_hardened_clay 15  
fill ~11 ~1 ~18 ~11 ~5 ~18 stained_hardened_clay 15  
fill ~11 ~1 ~23 ~27 ~1 ~23 planks 5  
fill ~11 ~1 ~24 ~27 ~1 ~24 planks 5  
fill ~11 ~1 ~25 ~27 ~1 ~25 planks 5  
fill ~11 ~1 ~26 ~27 ~1 ~26 planks 5  
fill ~11 ~1 ~27 ~27 ~1 ~27 planks 5  
fill ~11 ~1 ~28 ~27 ~1 ~28 planks 5  
fill ~11 ~1 ~53 ~27 ~1 ~53 planks 5  
fill ~11 ~1 ~54 ~27 ~1 ~54 planks 5  
fill ~11 ~1 ~55 ~27 ~1 ~55 planks 5  
fill ~11 ~1 ~56 ~27 ~1 ~56 planks 5  
fill ~11 ~1 ~57 ~27 ~1 ~57 planks 5  
fill ~11 ~1 ~58 ~11 ~8 ~58 stained_hardened_clay 15  
fill ~11 ~1 ~59 ~11 ~2 ~59 stained_hardened_clay 15  
fill ~11 ~1 ~60 ~11 ~4 ~60 stained_hardened_clay 15  
fill ~11 ~1 ~61 ~11 ~4 ~61 stained_hardened_clay 15  
fill ~12 ~1 ~14 ~15 ~1 ~14 stained_hardened_clay 15  
fill ~12 ~1 ~15 ~12 ~0 ~15 stained_hardened_clay 15  
fill ~12 ~1 ~16 ~18 ~1 ~16 planks 5  
fill ~12 ~1 ~17 ~26 ~1 ~17 planks 5  
fill ~12 ~1 ~18 ~26 ~1 ~18 planks 5  
fill ~12 ~1 ~19 ~26 ~1 ~19 planks 5  
fill ~12 ~1 ~20 ~26 ~1 ~20 planks 5  
fill ~12 ~1 ~21 ~26 ~1 ~21 planks 5  
fill ~12 ~1 ~22 ~26 ~1 ~22 planks 5  
fill ~12 ~1 ~58 ~26 ~1 ~58 planks 5  
fill ~12 ~1 ~59 ~18 ~1 ~59 planks 5  
fill ~12 ~1 ~60 ~26 ~1 ~60 planks 5  
fill ~12 ~1 ~61 ~26 ~1 ~61 planks 5  
fill ~12 ~1 ~62 ~12 ~2 ~62 stained_hardened_clay 15  
fill ~12 ~1 ~63 ~12 ~4 ~63 stained_hardened_clay 15  
fill ~13 ~1 ~13 ~25 ~1 ~13 stained_hardened_clay 15  
fill ~13 ~1 ~15 ~25 ~1 ~15 planks 5  
fill ~13 ~1 ~62 ~25 ~1 ~62 planks 5  
fill ~13 ~1 ~63 ~25 ~1 ~63 planks 5  
fill ~13 ~1 ~64 ~13 ~2 ~64 stained_hardened_clay 15  
fill ~14 ~1 ~64 ~24 ~1 ~64 planks 5  
fill ~14 ~1 ~65 ~14 ~2 ~65 stained_hardened_clay 15  
fill ~15 ~1 ~65 ~23 ~1 ~65 planks 5  
fill ~15 ~1 ~66 ~15 ~7 ~66 stained_hardened_clay 15  
fill ~16 ~1 ~14 ~23 ~1 ~14 planks 5  
fill ~16 ~1 ~66 ~22 ~1 ~66 planks 5 
setblock ~16 ~1 ~67 stained_hardened_clay 15  
fill ~17 ~1 ~67 ~21 ~1 ~67 planks 5 
setblock ~17 ~1 ~68 stained_hardened_clay 15  
fill ~18 ~1 ~68 ~20 ~1 ~68 planks 5 
setblock ~18 ~1 ~69 stained_hardened_clay 15 
setblock ~19 ~1 ~59 log2 1 
setblock ~19 ~1 ~69 planks 5  
fill ~19 ~1 ~70 ~19 ~2 ~70 stained_hardened_clay 15  
fill ~19 ~1 ~71 ~19 ~4 ~71 stained_hardened_clay 15  
fill ~20 ~1 ~16 ~26 ~1 ~16 planks 5  
fill ~20 ~1 ~33 ~28 ~1 ~33 planks 5  
fill ~20 ~1 ~59 ~26 ~1 ~59 planks 5 
setblock ~20 ~1 ~69 stained_hardened_clay 15 
setblock ~21 ~1 ~68 stained_hardened_clay 15 
setblock ~22 ~1 ~67 stained_hardened_clay 15  
fill ~23 ~1 ~66 ~23 ~7 ~66 stained_hardened_clay 15  
fill ~24 ~1 ~14 ~26 ~1 ~14 stained_hardened_clay 15  
fill ~24 ~1 ~65 ~24 ~2 ~65 stained_hardened_clay 15  
fill ~25 ~1 ~64 ~25 ~2 ~64 stained_hardened_clay 15 
setblock ~26 ~1 ~15 stained_hardened_clay 15  
fill ~26 ~1 ~62 ~26 ~2 ~62 stained_hardened_clay 15  
fill ~26 ~1 ~63 ~26 ~4 ~63 stained_hardened_clay 15  
fill ~27 ~1 ~16 ~27 ~5 ~16 stained_hardened_clay 15  
fill ~27 ~1 ~17 ~27 ~5 ~17 stained_hardened_clay 15  
fill ~27 ~1 ~18 ~27 ~5 ~18 stained_hardened_clay 15  
fill ~27 ~1 ~58 ~27 ~8 ~58 stained_hardened_clay 15  
fill ~27 ~1 ~59 ~27 ~2 ~59 stained_hardened_clay 15  
fill ~27 ~1 ~60 ~27 ~4 ~60 stained_hardened_clay 15  
fill ~27 ~1 ~61 ~27 ~4 ~61 stained_hardened_clay 15  
fill ~28 ~1 ~23 ~28 ~5 ~23 stained_hardened_clay 15  
fill ~28 ~1 ~24 ~28 ~4 ~24 stained_hardened_clay 15  
fill ~28 ~1 ~25 ~28 ~3 ~25 stained_hardened_clay 15  
fill ~28 ~1 ~53 ~28 ~1 ~57 stained_hardened_clay 15  
fill ~29 ~1 ~29 ~29 ~3 ~29 stained_hardened_clay 15  
fill ~29 ~1 ~30 ~29 ~2 ~30 stained_hardened_clay 15  
fill ~29 ~1 ~31 ~29 ~2 ~31 stained_hardened_clay 15  
fill ~29 ~1 ~32 ~29 ~1 ~52 stained_hardened_clay 15  
fill ~8 ~2 ~32 ~8 ~4 ~32 stained_hardened_clay 15  
fill ~8 ~2 ~33 ~8 ~4 ~33 stained_hardened_clay 15  
fill ~8 ~2 ~34 ~9 ~2 ~34 stained_hardened_clay 15  
fill ~8 ~2 ~35 ~8 ~4 ~35 stained_hardened_clay 15  
fill ~8 ~2 ~36 ~8 ~4 ~36 stained_hardened_clay 15  
fill ~8 ~2 ~37 ~8 ~4 ~37 stained_hardened_clay 15  
fill ~8 ~2 ~38 ~8 ~4 ~38 stained_hardened_clay 15  
fill ~8 ~2 ~39 ~8 ~4 ~39 stained_hardened_clay 15  
fill ~8 ~2 ~40 ~9 ~2 ~40 stained_hardened_clay 15  
fill ~8 ~2 ~41 ~8 ~4 ~41 stained_hardened_clay 15  
fill ~8 ~2 ~42 ~8 ~4 ~42 stained_hardened_clay 15  
fill ~8 ~2 ~43 ~8 ~4 ~43 stained_hardened_clay 15  
fill ~8 ~2 ~44 ~8 ~4 ~44 stained_hardened_clay 15  
fill ~8 ~2 ~45 ~8 ~4 ~45 stained_hardened_clay 15  
fill ~8 ~2 ~46 ~9 ~2 ~46 stained_hardened_clay 15  
fill ~8 ~2 ~47 ~8 ~4 ~47 stained_hardened_clay 15  
fill ~8 ~2 ~48 ~8 ~4 ~48 stained_hardened_clay 15  
fill ~9 ~2 ~27 ~9 ~4 ~27 stained_hardened_clay 15  
fill ~9 ~2 ~28 ~9 ~4 ~28 stained_hardened_clay 15  
fill ~9 ~2 ~32 ~10 ~2 ~32 gray_shulker_box 5  
fill ~9 ~2 ~33 ~10 ~2 ~33 gray_shulker_box 5  
fill ~9 ~2 ~35 ~15 ~2 ~35 iron_bars 0  
fill ~9 ~2 ~39 ~15 ~2 ~39 iron_bars 0  
fill ~9 ~2 ~41 ~10 ~2 ~41 planks 0  
fill ~9 ~2 ~42 ~9 ~2 ~41 planks 0 
setblock ~9 ~2 ~45 skull 1  
fill ~9 ~2 ~47 ~15 ~2 ~47 iron_bars 0  
fill ~9 ~2 ~49 ~9 ~2 ~54 stained_hardened_clay 15  
fill ~10 ~2 ~21 ~10 ~5 ~21 stained_hardened_clay 15  
fill ~10 ~2 ~22 ~10 ~5 ~22 stained_hardened_clay 15  
fill ~10 ~2 ~29 ~10 ~4 ~29 gray_shulker_box 5  
fill ~10 ~2 ~30 ~10 ~4 ~30 gray_shulker_box 5  
fill ~10 ~2 ~31 ~10 ~4 ~31 gray_shulker_box 5 
setblock ~10 ~2 ~40 planks 0  
fill ~10 ~2 ~51 ~15 ~2 ~51 iron_bars 0  
fill ~10 ~2 ~52 ~10 ~4 ~52 stained_hardened_clay 15  
fill ~10 ~2 ~53 ~14 ~2 ~53 iron_bars 0  
fill ~10 ~2 ~55 ~10 ~2 ~58 stained_hardened_clay 15  
fill ~11 ~2 ~15 ~11 ~5 ~15 stained_hardened_clay 15  
fill ~11 ~2 ~23 ~17 ~2 ~23 stained_hardened_clay 15 
setblock ~11 ~2 ~30 brown_shulker_box 1 
setblock ~11 ~2 ~32 flower_pot 0  
fill ~11 ~2 ~57 ~15 ~2 ~57 iron_bars 0  
fill ~12 ~2 ~13 ~26 ~2 ~13 stained_hardened_clay 15  
fill ~12 ~2 ~14 ~12 ~1 ~14 stained_hardened_clay 15  
fill ~12 ~2 ~16 ~12 ~5 ~16 stained_hardened_clay 15  
fill ~15 ~2 ~34 ~15 ~4 ~34 stained_hardened_clay 15  
fill ~15 ~2 ~36 ~15 ~4 ~36 iron_bars 0  
fill ~15 ~2 ~37 ~15 ~4 ~37 iron_bars 0  
fill ~15 ~2 ~38 ~15 ~4 ~38 iron_bars 0  
fill ~15 ~2 ~40 ~15 ~4 ~40 stained_hardened_clay 15  
fill ~15 ~2 ~46 ~15 ~4 ~46 stained_hardened_clay 15  
fill ~15 ~2 ~48 ~15 ~4 ~48 iron_bars 0  
fill ~15 ~2 ~49 ~15 ~4 ~49 iron_bars 0  
fill ~15 ~2 ~50 ~15 ~4 ~50 iron_bars 0  
fill ~15 ~2 ~52 ~15 ~4 ~52 stained_hardened_clay 15  
fill ~15 ~2 ~53 ~15 ~4 ~53 stained_hardened_clay 15  
fill ~15 ~2 ~54 ~15 ~4 ~54 iron_bars 0  
fill ~15 ~2 ~55 ~15 ~4 ~55 iron_bars 0  
fill ~15 ~2 ~56 ~15 ~4 ~56 iron_bars 0  
fill ~15 ~2 ~58 ~15 ~10 ~58 stained_hardened_clay 15 
setblock ~15 ~2 ~59 flower_pot 0  
fill ~15 ~2 ~67 ~15 ~3 ~67 stained_hardened_clay 15  
fill ~16 ~2 ~28 ~16 ~5 ~28 planks 5  
fill ~16 ~2 ~63 ~16 ~6 ~63 planks 5  
fill ~16 ~2 ~66 ~17 ~2 ~66 stained_hardened_clay 15 
setblock ~16 ~2 ~67 planks 0 
setblock ~16 ~2 ~68 stained_hardened_clay 15  
fill ~17 ~2 ~52 ~17 ~2 ~53 dark_oak_stairs 0 
setblock ~17 ~2 ~68 planks 0 
setblock ~17 ~2 ~69 stained_hardened_clay 15 
setblock ~18 ~2 ~16 dark_oak_stairs 4 
setblock ~18 ~2 ~23 wooden_door 3 
setblock ~18 ~2 ~33 dark_oak_stairs 4  
fill ~18 ~2 ~52 ~18 ~2 ~53 dark_oak_stairs 5 
setblock ~18 ~2 ~59 dark_oak_stairs 4 
setblock ~18 ~2 ~60 brown_shulker_box 1  
fill ~18 ~2 ~66 ~18 ~4 ~66 activator_rail 5  
fill ~18 ~2 ~70 ~18 ~3 ~70 stained_hardened_clay 15 
setblock ~19 ~2 ~15 dark_oak_stairs 6 
setblock ~19 ~2 ~16 log2 1 
setblock ~19 ~2 ~17 dark_oak_stairs 7  
fill ~19 ~2 ~23 ~19 ~5 ~23 stained_hardened_clay 15 
setblock ~19 ~2 ~32 dark_oak_stairs 6 
setblock ~19 ~2 ~33 log2 1 
setblock ~19 ~2 ~34 dark_oak_stairs 7  
fill ~19 ~2 ~41 ~19 ~2 ~42 dark_oak_stairs 4 
setblock ~19 ~2 ~58 dark_oak_stairs 6  
fill ~19 ~2 ~59 ~19 ~5 ~59 stained_hardened_clay 15 
setblock ~19 ~2 ~60 dark_oak_stairs 7 
setblock ~19 ~2 ~66 wooden_door 1  
fill ~19 ~2 ~72 ~19 ~4 ~72 stained_hardened_clay 15 
setblock ~20 ~2 ~16 dark_oak_stairs 5 
setblock ~20 ~2 ~23 wooden_door 3 
setblock ~20 ~2 ~33 dark_oak_stairs 5  
fill ~20 ~2 ~41 ~20 ~2 ~42 dark_oak_stairs 1 
setblock ~20 ~2 ~58 flower_pot 0 
setblock ~20 ~2 ~59 dark_oak_stairs 5  
fill ~20 ~2 ~66 ~20 ~4 ~66 activator_rail 5 
setblock ~20 ~2 ~69 brown_shulker_box 1  
fill ~20 ~2 ~70 ~20 ~3 ~70 stained_hardened_clay 15  
fill ~21 ~2 ~23 ~28 ~2 ~23 stained_hardened_clay 15  
fill ~21 ~2 ~42 ~21 ~3 ~42 fence 5  
fill ~21 ~2 ~66 ~23 ~2 ~66 stained_hardened_clay 15 
setblock ~21 ~2 ~68 brown_shulker_box 1 
setblock ~21 ~2 ~69 stained_hardened_clay 15  
fill ~22 ~2 ~28 ~22 ~5 ~28 planks 5  
fill ~22 ~2 ~63 ~22 ~6 ~63 planks 5  
fill ~22 ~2 ~65 ~23 ~2 ~65 dark_oak_stairs 2 
setblock ~22 ~2 ~67 brown_shulker_box 1 
setblock ~22 ~2 ~68 stained_hardened_clay 15  
fill ~23 ~2 ~34 ~23 ~4 ~34 stained_hardened_clay 15  
fill ~23 ~2 ~35 ~29 ~2 ~35 iron_bars 0  
fill ~23 ~2 ~36 ~23 ~4 ~36 iron_bars 0  
fill ~23 ~2 ~37 ~23 ~4 ~37 iron_bars 0  
fill ~23 ~2 ~38 ~23 ~4 ~38 iron_bars 0  
fill ~23 ~2 ~39 ~29 ~2 ~39 iron_bars 0  
fill ~23 ~2 ~40 ~23 ~4 ~40 stained_hardened_clay 15  
fill ~23 ~2 ~46 ~23 ~4 ~46 stained_hardened_clay 15  
fill ~23 ~2 ~47 ~29 ~2 ~47 iron_bars 0  
fill ~23 ~2 ~48 ~23 ~4 ~48 iron_bars 0  
fill ~23 ~2 ~49 ~23 ~4 ~49 iron_bars 0  
fill ~23 ~2 ~50 ~23 ~4 ~50 iron_bars 0  
fill ~23 ~2 ~51 ~23 ~4 ~51 iron_bars 0  
fill ~23 ~2 ~52 ~23 ~4 ~52 stained_hardened_clay 15  
fill ~23 ~2 ~53 ~23 ~4 ~53 stained_hardened_clay 15  
fill ~23 ~2 ~54 ~28 ~2 ~54 iron_bars 0  
fill ~23 ~2 ~55 ~23 ~4 ~55 iron_bars 0  
fill ~23 ~2 ~56 ~23 ~4 ~56 iron_bars 0  
fill ~23 ~2 ~57 ~23 ~4 ~57 iron_bars 0  
fill ~23 ~2 ~58 ~26 ~2 ~58 iron_bars 0  
fill ~23 ~2 ~59 ~23 ~5 ~59 stained_hardened_clay 15  
fill ~23 ~2 ~67 ~23 ~3 ~67 stained_hardened_clay 15  
fill ~24 ~2 ~52 ~27 ~2 ~52 iron_bars 0 
setblock ~25 ~2 ~41 flower_pot 0 
setblock ~25 ~2 ~57 skull 1 
setblock ~25 ~2 ~62 flower_pot 0 
setblock ~25 ~2 ~63 brown_shulker_box 1 
setblock ~26 ~2 ~14 stained_hardened_clay 15  
fill ~26 ~2 ~16 ~26 ~5 ~16 stained_hardened_clay 15  
fill ~26 ~2 ~32 ~27 ~2 ~32 brown_shulker_box 1 
setblock ~26 ~2 ~33 flower_pot 0  
fill ~26 ~2 ~41 ~29 ~2 ~41 bone_block 4 
setblock ~26 ~2 ~45 flower_pot 0  
fill ~26 ~2 ~51 ~27 ~2 ~51 brown_shulker_box 1  
fill ~27 ~2 ~15 ~27 ~5 ~15 stained_hardened_clay 15  
fill ~27 ~2 ~29 ~28 ~2 ~29 planks 0 
setblock ~27 ~2 ~30 flower_pot 0 
setblock ~27 ~2 ~31 brown_shulker_box 1 
setblock ~27 ~2 ~33 brown_shulker_box 1 
setblock ~27 ~2 ~43 carpet 12 
setblock ~27 ~2 ~44 brown_shulker_box 2  
fill ~27 ~2 ~45 ~28 ~2 ~45 brown_shulker_box 1 
setblock ~27 ~2 ~50 planks 0 
setblock ~27 ~2 ~55 brown_shulker_box 1  
fill ~28 ~2 ~21 ~28 ~5 ~21 stained_hardened_clay 15  
fill ~28 ~2 ~22 ~28 ~5 ~22 stained_hardened_clay 15 
setblock ~28 ~2 ~30 planks 0  
fill ~28 ~2 ~43 ~28 ~3 ~43 brown_shulker_box 1  
fill ~28 ~2 ~44 ~28 ~3 ~44 brown_shulker_box 1  
fill ~28 ~2 ~52 ~29 ~2 ~52 stained_hardened_clay 15  
fill ~28 ~2 ~55 ~28 ~2 ~58 stained_hardened_clay 15  
fill ~29 ~2 ~27 ~29 ~4 ~27 stained_hardened_clay 15  
fill ~29 ~2 ~28 ~29 ~4 ~28 stained_hardened_clay 15  
fill ~29 ~2 ~34 ~30 ~2 ~34 stained_hardened_clay 15  
fill ~29 ~2 ~40 ~30 ~2 ~40 stained_hardened_clay 15  
fill ~29 ~2 ~46 ~30 ~2 ~46 stained_hardened_clay 15  
fill ~29 ~2 ~49 ~29 ~2 ~54 stained_hardened_clay 15  
fill ~30 ~2 ~32 ~30 ~4 ~32 stained_hardened_clay 15  
fill ~30 ~2 ~33 ~30 ~4 ~33 stained_hardened_clay 15  
fill ~30 ~2 ~35 ~30 ~4 ~35 stained_hardened_clay 15  
fill ~30 ~2 ~36 ~30 ~4 ~36 stained_hardened_clay 15  
fill ~30 ~2 ~37 ~30 ~4 ~37 stained_hardened_clay 15  
fill ~30 ~2 ~38 ~30 ~4 ~38 stained_hardened_clay 15  
fill ~30 ~2 ~39 ~30 ~4 ~39 stained_hardened_clay 15  
fill ~30 ~2 ~41 ~30 ~4 ~41 stained_hardened_clay 15  
fill ~30 ~2 ~42 ~30 ~4 ~42 stained_hardened_clay 15  
fill ~30 ~2 ~43 ~30 ~4 ~43 stained_hardened_clay 15  
fill ~30 ~2 ~44 ~30 ~4 ~44 stained_hardened_clay 15  
fill ~30 ~2 ~45 ~30 ~4 ~45 stained_hardened_clay 15  
fill ~30 ~2 ~47 ~30 ~4 ~47 stained_hardened_clay 15  
fill ~30 ~2 ~48 ~30 ~4 ~48 stained_hardened_clay 15  
fill ~8 ~3 ~30 ~8 ~4 ~30 stained_hardened_clay 15  
fill ~8 ~3 ~31 ~8 ~4 ~31 stained_hardened_clay 15  
fill ~8 ~3 ~34 ~9 ~3 ~34 stained_hardened_clay 15  
fill ~8 ~3 ~40 ~9 ~3 ~40 stained_hardened_clay 15  
fill ~8 ~3 ~46 ~9 ~3 ~46 stained_hardened_clay 15  
fill ~8 ~3 ~49 ~8 ~4 ~49 stained_hardened_clay 15  
fill ~8 ~3 ~50 ~8 ~4 ~50 stained_hardened_clay 15  
fill ~9 ~3 ~26 ~9 ~4 ~26 stained_hardened_clay 15  
fill ~9 ~3 ~30 ~9 ~4 ~30 gray_shulker_box 5  
fill ~9 ~3 ~31 ~9 ~4 ~31 gray_shulker_box 5  
fill ~9 ~3 ~32 ~10 ~3 ~32 gray_shulker_box 5  
fill ~9 ~3 ~33 ~10 ~3 ~33 gray_shulker_box 5  
fill ~9 ~3 ~35 ~15 ~3 ~35 iron_bars 0  
fill ~9 ~3 ~39 ~15 ~3 ~39 iron_bars 0 
setblock ~9 ~3 ~41 planks 0  
fill ~9 ~3 ~47 ~15 ~3 ~47 iron_bars 0  
fill ~9 ~3 ~51 ~9 ~3 ~55 stained_hardened_clay 15  
fill ~10 ~3 ~20 ~10 ~5 ~20 stained_hardened_clay 15  
fill ~10 ~3 ~51 ~15 ~3 ~51 iron_bars 0  
fill ~10 ~3 ~53 ~14 ~3 ~53 iron_bars 0  
fill ~10 ~3 ~56 ~10 ~3 ~59 stained_hardened_clay 15  
fill ~11 ~3 ~14 ~11 ~5 ~14 stained_hardened_clay 15  
fill ~11 ~3 ~23 ~17 ~3 ~23 stained_hardened_clay 15 
setblock ~11 ~3 ~30 carpet 12  
fill ~11 ~3 ~57 ~15 ~3 ~57 iron_bars 0  
fill ~11 ~3 ~62 ~11 ~4 ~62 stained_hardened_clay 15  
fill ~12 ~3 ~13 ~26 ~3 ~13 stained_hardened_clay 15  
fill ~12 ~3 ~64 ~12 ~4 ~64 stained_hardened_clay 15  
fill ~13 ~3 ~65 ~13 ~4 ~65 stained_hardened_clay 15  
fill ~14 ~3 ~66 ~14 ~4 ~66 stained_hardened_clay 15  
fill ~15 ~3 ~68 ~15 ~4 ~68 stained_hardened_clay 15  
fill ~16 ~3 ~66 ~17 ~3 ~66 stained_hardened_clay 15 
setblock ~16 ~3 ~68 planks 0  
fill ~16 ~3 ~69 ~16 ~4 ~69 stained_hardened_clay 15  
fill ~17 ~3 ~52 ~17 ~4 ~52 fence 5 
setblock ~17 ~3 ~69 planks 0  
fill ~17 ~3 ~70 ~17 ~4 ~70 stained_hardened_clay 15 
setblock ~18 ~3 ~23 wooden_door 8  
fill ~18 ~3 ~41 ~18 ~3 ~42 dark_oak_stairs 4  
fill ~18 ~3 ~52 ~18 ~3 ~53 dark_oak_stairs 0 
setblock ~18 ~3 ~60 carpet 12  
fill ~19 ~3 ~16 ~19 ~6 ~16 stained_hardened_clay 15  
fill ~19 ~3 ~33 ~19 ~6 ~33 stained_hardened_clay 15  
fill ~19 ~3 ~41 ~19 ~3 ~42 dark_oak_stairs 1  
fill ~19 ~3 ~52 ~19 ~3 ~53 dark_oak_stairs 5 
setblock ~19 ~3 ~66 wooden_door 9  
fill ~19 ~3 ~73 ~19 ~7 ~73 stained_hardened_clay 15 
setblock ~20 ~3 ~23 wooden_door 9  
fill ~20 ~3 ~42 ~20 ~4 ~42 fence 5 
setblock ~20 ~3 ~69 carpet 12  
fill ~21 ~3 ~23 ~28 ~3 ~23 stained_hardened_clay 15  
fill ~21 ~3 ~66 ~24 ~3 ~66 stained_hardened_clay 15 
setblock ~21 ~3 ~68 carpet 12 
setblock ~21 ~3 ~69 skull 1  
fill ~21 ~3 ~70 ~21 ~4 ~70 stained_hardened_clay 15  
fill ~22 ~3 ~65 ~23 ~3 ~65 dark_oak_stairs 2 
setblock ~22 ~3 ~67 carpet 12 
setblock ~22 ~3 ~68 brown_shulker_box 1  
fill ~22 ~3 ~69 ~22 ~4 ~69 stained_hardened_clay 15   
fill ~23 ~3 ~35 ~29 ~3 ~35 iron_bars 0  
fill ~23 ~3 ~39 ~29 ~3 ~39 iron_bars 0  
fill ~23 ~3 ~47 ~29 ~3 ~47 iron_bars 0  
fill ~23 ~3 ~54 ~28 ~3 ~54 iron_bars 0  
fill ~23 ~3 ~58 ~26 ~3 ~58 iron_bars 0  
fill ~23 ~3 ~68 ~23 ~4 ~68 stained_hardened_clay 15  
fill ~24 ~3 ~52 ~27 ~3 ~52 iron_bars 0 
setblock ~25 ~3 ~63 carpet 12  
fill ~25 ~3 ~65 ~25 ~4 ~65 stained_hardened_clay 15  
fill ~26 ~3 ~41 ~29 ~3 ~41 bone_block 4  
fill ~26 ~3 ~51 ~27 ~3 ~51 carpet 12  
fill ~26 ~3 ~64 ~26 ~4 ~64 stained_hardened_clay 15  
fill ~27 ~3 ~14 ~27 ~5 ~14 stained_hardened_clay 15 
setblock ~27 ~3 ~31 carpet 12  
fill ~27 ~3 ~45 ~28 ~3 ~45 brown_shulker_box 1 
setblock ~27 ~3 ~55 carpet 12  
fill ~27 ~3 ~62 ~27 ~4 ~62 stained_hardened_clay 15  
fill ~28 ~3 ~20 ~28 ~5 ~20 stained_hardened_clay 15 
setblock ~28 ~3 ~29 planks 0  
fill ~28 ~3 ~52 ~29 ~3 ~52 stained_hardened_clay 15  
fill ~28 ~3 ~56 ~28 ~3 ~59 stained_hardened_clay 15  
fill ~29 ~3 ~26 ~29 ~4 ~26 stained_hardened_clay 15  
fill ~29 ~3 ~34 ~30 ~3 ~34 stained_hardened_clay 15  
fill ~29 ~3 ~40 ~30 ~3 ~40 stained_hardened_clay 15  
fill ~29 ~3 ~46 ~30 ~3 ~46 stained_hardened_clay 15 
setblock ~29 ~3 ~51 stained_hardened_clay 15  
fill ~29 ~3 ~53 ~29 ~4 ~53 stained_hardened_clay 15  
fill ~29 ~3 ~54 ~29 ~4 ~54 stained_hardened_clay 15  
fill ~29 ~3 ~55 ~29 ~4 ~55 stained_hardened_clay 15  
fill ~30 ~3 ~30 ~30 ~4 ~30 stained_hardened_clay 15  
fill ~30 ~3 ~31 ~30 ~4 ~31 stained_hardened_clay 15  
fill ~30 ~3 ~49 ~30 ~4 ~49 stained_hardened_clay 15  
fill ~30 ~3 ~50 ~30 ~4 ~50 stained_hardened_clay 15  
fill ~7 ~4 ~41 ~7 ~8 ~41 dropper 0 
setblock ~8 ~4 ~29 stained_hardened_clay 15  
fill ~8 ~4 ~34 ~9 ~4 ~34 stained_hardened_clay 15  
fill ~8 ~4 ~40 ~9 ~4 ~40 stained_hardened_clay 15  
fill ~8 ~4 ~46 ~9 ~4 ~46 stained_hardened_clay 15 
setblock ~8 ~4 ~51 stained_hardened_clay 15 
setblock ~9 ~4 ~25 stained_hardened_clay 15 
setblock ~9 ~4 ~29 gray_shulker_box 5  
fill ~9 ~4 ~32 ~10 ~4 ~32 gray_shulker_box 5  
fill ~9 ~4 ~33 ~10 ~4 ~33 gray_shulker_box 5  
fill ~9 ~4 ~35 ~15 ~4 ~35 iron_bars 0 
setblock ~9 ~4 ~37 torch 1  
fill ~9 ~4 ~39 ~15 ~4 ~39 iron_bars 0  
fill ~9 ~4 ~47 ~15 ~4 ~47 iron_bars 0 
setblock ~9 ~4 ~49 torch 1  
fill ~9 ~4 ~51 ~15 ~4 ~51 iron_bars 0  
fill ~9 ~4 ~52 ~9 ~4 ~56 stained_hardened_clay 15  
fill ~10 ~4 ~19 ~10 ~5 ~19 stained_hardened_clay 15  
fill ~10 ~4 ~34 ~14 ~4 ~34 dropper 0  
fill ~10 ~4 ~40 ~14 ~4 ~40 dropper 0  
fill ~10 ~4 ~46 ~14 ~4 ~46 dropper 0  
fill ~10 ~4 ~53 ~14 ~4 ~53 iron_bars 0 
setblock ~10 ~4 ~55 torch 1  
fill ~10 ~4 ~57 ~10 ~4 ~59 stained_hardened_clay 15  
fill ~11 ~4 ~23 ~28 ~4 ~23 stained_hardened_clay 15  
fill ~11 ~4 ~28 ~15 ~4 ~28 dropper 0  
fill ~11 ~4 ~52 ~14 ~4 ~52 dropper 0  
fill ~11 ~4 ~57 ~15 ~4 ~57 iron_bars 0  
fill ~12 ~4 ~13 ~12 ~5 ~13 stained_hardened_clay 15  
fill ~13 ~4 ~12 ~25 ~4 ~12 stained_hardened_clay 15 
setblock ~14 ~4 ~67 stained_hardened_clay 15 
setblock ~16 ~4 ~24 torch 3  
fill ~16 ~4 ~34 ~22 ~4 ~34 dropper 0  
fill ~16 ~4 ~40 ~18 ~4 ~40 dropper 0 
setblock ~16 ~4 ~46 dropper 0 
setblock ~16 ~4 ~52 dropper 0  
fill ~16 ~4 ~66 ~17 ~4 ~66 stained_hardened_clay 15  
fill ~17 ~4 ~28 ~18 ~4 ~28 dropper 0  
fill ~17 ~4 ~41 ~17 ~4 ~42 dark_oak_stairs 4 
setblock ~18 ~4 ~16 torch 2 
setblock ~18 ~4 ~33 torch 2  
fill ~18 ~4 ~41 ~18 ~4 ~42 dark_oak_stairs 1  
fill ~18 ~4 ~52 ~18 ~5 ~52 fence 5 
setblock ~18 ~4 ~59 torch 2 
setblock ~18 ~4 ~71 stained_hardened_clay 15 
setblock ~19 ~4 ~28 glowstone 0 
setblock ~19 ~4 ~40 glowstone 0  
fill ~19 ~4 ~42 ~19 ~5 ~42 fence 5  
fill ~19 ~4 ~52 ~19 ~4 ~53 dark_oak_stairs 0 
setblock ~19 ~4 ~66 activator_rail 5  
fill ~19 ~4 ~74 ~19 ~7 ~74 stained_hardened_clay 15 
setblock ~20 ~4 ~16 torch 1  
fill ~20 ~4 ~28 ~21 ~4 ~28 dropper 0 
setblock ~20 ~4 ~33 torch 1  
fill ~20 ~4 ~40 ~22 ~4 ~40 dropper 0  
fill ~20 ~4 ~52 ~20 ~4 ~53 dark_oak_stairs 5 
setblock ~20 ~4 ~59 torch 1 
setblock ~20 ~4 ~71 stained_hardened_clay 15  
fill ~21 ~4 ~52 ~22 ~4 ~52 dropper 0  
fill ~21 ~4 ~66 ~24 ~4 ~66 stained_hardened_clay 15 
setblock ~22 ~4 ~24 torch 3 
setblock ~22 ~4 ~46 dropper 0  
fill ~22 ~4 ~65 ~23 ~4 ~65 dropper 5 
setblock ~22 ~4 ~68 carpet 12  
fill ~23 ~4 ~28 ~27 ~4 ~28 dropper 0  
fill ~23 ~4 ~35 ~29 ~4 ~35 iron_bars 0  
fill ~23 ~4 ~39 ~29 ~4 ~39 iron_bars 0  
fill ~23 ~4 ~47 ~29 ~4 ~47 iron_bars 0  
fill ~23 ~4 ~54 ~28 ~4 ~54 iron_bars 0  
fill ~23 ~4 ~58 ~26 ~4 ~58 iron_bars 0  
fill ~24 ~4 ~34 ~28 ~4 ~34 dropper 0  
fill ~24 ~4 ~40 ~28 ~4 ~40 dropper 0  
fill ~24 ~4 ~46 ~28 ~4 ~46 dropper 0  
fill ~24 ~4 ~52 ~27 ~4 ~52 dropper 0 
setblock ~24 ~4 ~67 stained_hardened_clay 15  
fill ~26 ~4 ~13 ~26 ~5 ~13 stained_hardened_clay 15  
fill ~28 ~4 ~19 ~28 ~5 ~19 stained_hardened_clay 15 
setblock ~28 ~4 ~43 carpet 12 
setblock ~28 ~4 ~45 carpet 12  
fill ~28 ~4 ~52 ~29 ~4 ~52 stained_hardened_clay 15 
setblock ~28 ~4 ~56 torch 2  
fill ~28 ~4 ~57 ~28 ~4 ~59 stained_hardened_clay 15 
setblock ~29 ~4 ~25 stained_hardened_clay 15  
fill ~29 ~4 ~34 ~30 ~4 ~34 stained_hardened_clay 15 
setblock ~29 ~4 ~37 torch 2  
fill ~29 ~4 ~40 ~30 ~4 ~40 stained_hardened_clay 15  
fill ~29 ~4 ~46 ~30 ~4 ~46 stained_hardened_clay 15 
setblock ~29 ~4 ~49 torch 2 
setblock ~29 ~4 ~56 stained_hardened_clay 15 
setblock ~30 ~4 ~29 stained_hardened_clay 15 
setblock ~30 ~4 ~51 stained_hardened_clay 15  
fill ~31 ~4 ~41 ~31 ~8 ~41 dropper 0  
fill ~8 ~5 ~29 ~8 ~5 ~51 coal_block 0  
fill ~9 ~5 ~25 ~9 ~5 ~28 coal_block 0  
fill ~9 ~5 ~29 ~29 ~5 ~29 planks 5  
fill ~9 ~5 ~30 ~29 ~5 ~30 planks 5  
fill ~9 ~5 ~31 ~29 ~5 ~31 planks 5  
fill ~9 ~5 ~32 ~29 ~5 ~32 planks 5  
fill ~9 ~5 ~33 ~18 ~5 ~33 planks 5  
fill ~9 ~5 ~34 ~29 ~5 ~34 planks 5  
fill ~9 ~5 ~35 ~29 ~5 ~35 planks 5  
fill ~9 ~5 ~36 ~29 ~5 ~36 planks 5  
fill ~9 ~5 ~37 ~29 ~5 ~37 planks 5  
fill ~9 ~5 ~38 ~29 ~5 ~38 planks 5  
fill ~9 ~5 ~39 ~29 ~5 ~39 planks 5  
fill ~9 ~5 ~40 ~29 ~5 ~40 planks 5  
fill ~9 ~5 ~41 ~16 ~5 ~41 planks 5  
fill ~9 ~5 ~42 ~16 ~5 ~42 planks 5  
fill ~9 ~5 ~43 ~29 ~5 ~43 planks 5  
fill ~9 ~5 ~44 ~16 ~5 ~44 planks 5  
fill ~9 ~5 ~45 ~16 ~5 ~45 planks 5  
fill ~9 ~5 ~46 ~16 ~5 ~46 planks 5  
fill ~9 ~5 ~47 ~16 ~5 ~47 planks 5  
fill ~9 ~5 ~48 ~16 ~5 ~48 planks 5  
fill ~9 ~5 ~49 ~16 ~5 ~49 planks 5  
fill ~9 ~5 ~50 ~16 ~5 ~50 planks 5  
fill ~9 ~5 ~51 ~29 ~5 ~51 planks 5  
fill ~9 ~5 ~52 ~9 ~5 ~56 coal_block 0 
setblock ~10 ~5 ~24 coal_block 0  
fill ~10 ~5 ~25 ~28 ~5 ~25 planks 5  
fill ~10 ~5 ~26 ~28 ~5 ~26 planks 5  
fill ~10 ~5 ~27 ~28 ~5 ~27 planks 5  
fill ~10 ~5 ~28 ~28 ~5 ~28 planks 5  
fill ~10 ~5 ~52 ~16 ~5 ~52 planks 5  
fill ~10 ~5 ~53 ~16 ~5 ~53 planks 5  
fill ~10 ~5 ~54 ~28 ~5 ~54 planks 5  
fill ~10 ~5 ~55 ~28 ~5 ~55 planks 5  
fill ~10 ~5 ~56 ~28 ~5 ~56 planks 5  
fill ~10 ~5 ~57 ~10 ~5 ~59 coal_block 0  
fill ~11 ~5 ~23 ~28 ~5 ~23 stained_hardened_clay 15  
fill ~11 ~5 ~24 ~27 ~5 ~24 planks 5  
fill ~11 ~5 ~57 ~27 ~5 ~57 planks 5  
fill ~11 ~5 ~60 ~11 ~5 ~62 coal_block 0 
setblock ~12 ~5 ~12 stained_hardened_clay 15  
fill ~12 ~5 ~22 ~26 ~5 ~22 dropper 0  
fill ~12 ~5 ~58 ~14 ~5 ~58 dropper 0  
fill ~12 ~5 ~63 ~12 ~5 ~64 coal_block 0  
fill ~13 ~5 ~10 ~25 ~5 ~10 stained_hardened_clay 15  
fill ~13 ~5 ~11 ~25 ~5 ~11 stained_hardened_clay 15  
fill ~13 ~5 ~16 ~18 ~5 ~16 dropper 0  
fill ~13 ~5 ~63 ~15 ~5 ~63 dropper 0 
setblock ~13 ~5 ~65 coal_block 0  
fill ~14 ~5 ~66 ~14 ~5 ~67 coal_block 0  
fill ~14 ~5 ~68 ~14 ~5 ~69 stone_slab 3  
fill ~15 ~5 ~68 ~15 ~5 ~69 coal_block 0 
setblock ~15 ~5 ~70 stone_slab 11  
fill ~16 ~5 ~58 ~26 ~5 ~58 dropper 0  
fill ~16 ~5 ~66 ~23 ~5 ~66 stained_hardened_clay 15 
setblock ~16 ~5 ~70 coal_block 0 
setblock ~16 ~5 ~71 stone_slab 11  
fill ~17 ~5 ~41 ~17 ~5 ~42 dark_oak_stairs 1 
setblock ~17 ~5 ~59 dropper 0  
fill ~17 ~5 ~63 ~18 ~5 ~63 dropper 0 
setblock ~17 ~5 ~71 coal_block 0  
fill ~18 ~5 ~42 ~18 ~6 ~42 fence 5  
fill ~18 ~5 ~72 ~20 ~5 ~72 coal_block 0  
fill ~19 ~5 ~52 ~19 ~6 ~52 fence 5 
setblock ~19 ~5 ~63 glowstone 0  
fill ~19 ~5 ~75 ~19 ~8 ~75 stained_hardened_clay 15  
fill ~20 ~5 ~16 ~25 ~5 ~16 dropper 0  
fill ~20 ~5 ~33 ~29 ~5 ~33 planks 5  
fill ~20 ~5 ~52 ~20 ~5 ~53 dark_oak_stairs 0  
fill ~20 ~5 ~63 ~21 ~5 ~63 dropper 0  
fill ~21 ~5 ~52 ~28 ~5 ~52 planks 5  
fill ~21 ~5 ~53 ~28 ~5 ~53 planks 5 
setblock ~21 ~5 ~71 coal_block 0  
fill ~22 ~5 ~41 ~29 ~5 ~41 planks 5  
fill ~22 ~5 ~42 ~29 ~5 ~42 planks 5  
fill ~22 ~5 ~44 ~29 ~5 ~44 planks 5  
fill ~22 ~5 ~45 ~29 ~5 ~45 planks 5  
fill ~22 ~5 ~46 ~29 ~5 ~46 planks 5  
fill ~22 ~5 ~47 ~29 ~5 ~47 planks 5  
fill ~22 ~5 ~48 ~29 ~5 ~48 planks 5  
fill ~22 ~5 ~49 ~29 ~5 ~49 planks 5  
fill ~22 ~5 ~50 ~29 ~5 ~50 planks 5 
setblock ~22 ~5 ~70 coal_block 0 
setblock ~22 ~5 ~71 stone_slab 11  
fill ~23 ~5 ~63 ~25 ~5 ~63 dropper 0  
fill ~23 ~5 ~68 ~23 ~5 ~69 coal_block 0 
setblock ~23 ~5 ~70 stone_slab 11  
fill ~24 ~5 ~66 ~24 ~5 ~67 coal_block 0  
fill ~24 ~5 ~68 ~24 ~5 ~69 stone_slab 3 
setblock ~25 ~5 ~65 coal_block 0 
setblock ~26 ~5 ~12 stained_hardened_clay 15  
fill ~26 ~5 ~63 ~26 ~5 ~64 coal_block 0  
fill ~27 ~5 ~60 ~27 ~5 ~62 coal_block 0 
setblock ~28 ~5 ~24 coal_block 0  
fill ~28 ~5 ~57 ~28 ~5 ~59 coal_block 0  
fill ~29 ~5 ~25 ~29 ~5 ~28 coal_block 0  
fill ~29 ~5 ~52 ~29 ~5 ~56 coal_block 0  
fill ~30 ~5 ~29 ~30 ~5 ~51 coal_block 0  
fill ~7 ~6 ~39 ~7 ~8 ~39 dark_oak_fence_gate 7  
fill ~8 ~6 ~30 ~8 ~6 ~50 stained_hardened_clay 15  
fill ~9 ~6 ~25 ~9 ~6 ~29 stained_hardened_clay 15  
fill ~9 ~6 ~34 ~9 ~8 ~34 stained_hardened_clay 15  
fill ~9 ~6 ~37 ~10 ~6 ~37 stone 6  
fill ~9 ~6 ~40 ~9 ~8 ~40 stained_hardened_clay 15  
fill ~9 ~6 ~43 ~10 ~6 ~43 stone 6  
fill ~9 ~6 ~46 ~9 ~8 ~46 stained_hardened_clay 15  
fill ~9 ~6 ~51 ~9 ~8 ~51 stained_hardened_clay 15  
fill ~9 ~6 ~52 ~10 ~6 ~52 stained_hardened_clay 15  
fill ~9 ~6 ~53 ~9 ~7 ~53 stained_hardened_clay 15  
fill ~9 ~6 ~54 ~9 ~7 ~54 stained_hardened_clay 15  
fill ~9 ~6 ~55 ~9 ~6 ~51 stained_hardened_clay 15  
fill ~10 ~6 ~19 ~10 ~6 ~23 coal_block 0  
fill ~10 ~6 ~24 ~10 ~8 ~24 stained_hardened_clay 15  
fill ~10 ~6 ~28 ~10 ~8 ~28 stained_hardened_clay 15  
fill ~10 ~6 ~31 ~11 ~6 ~31 stone 6  
fill ~10 ~6 ~49 ~11 ~6 ~49 stone 6  
fill ~10 ~6 ~56 ~10 ~8 ~56 stained_hardened_clay 15  
fill ~10 ~6 ~57 ~10 ~7 ~57 stained_hardened_clay 15  
fill ~10 ~6 ~58 ~10 ~7 ~58 stained_hardened_clay 15  
fill ~10 ~6 ~59 ~10 ~6 ~56 stained_hardened_clay 15  
fill ~11 ~6 ~14 ~11 ~6 ~18 coal_block 0  
fill ~11 ~6 ~19 ~27 ~6 ~19 planks 5  
fill ~11 ~6 ~20 ~27 ~6 ~20 dropper 5  
fill ~11 ~6 ~21 ~27 ~6 ~21 dropper 5  
fill ~11 ~6 ~23 ~27 ~6 ~23 dropper 5  
fill ~11 ~6 ~25 ~12 ~6 ~25 stone 6 
setblock ~11 ~6 ~37 dark_oak_stairs 1 
setblock ~11 ~6 ~43 dark_oak_stairs 1  
fill ~11 ~6 ~55 ~12 ~6 ~55 stone 6  
fill ~11 ~6 ~59 ~17 ~6 ~59 dropper 5  
fill ~11 ~6 ~60 ~11 ~8 ~60 stained_hardened_clay 15  
fill ~11 ~6 ~61 ~11 ~7 ~61 stained_hardened_clay 15  
fill ~11 ~6 ~62 ~11 ~6 ~60 stained_hardened_clay 15  
fill ~12 ~6 ~11 ~12 ~6 ~13 coal_block 0  
fill ~12 ~6 ~14 ~26 ~6 ~14 planks 5  
fill ~12 ~6 ~15 ~26 ~6 ~15 planks 5  
fill ~12 ~6 ~16 ~18 ~6 ~16 planks 5  
fill ~12 ~6 ~17 ~26 ~6 ~17 planks 5  
fill ~12 ~6 ~18 ~26 ~6 ~18 planks 5  
fill ~12 ~6 ~22 ~13 ~6 ~22 dropper 5 
setblock ~12 ~6 ~31 dark_oak_stairs 1 
setblock ~12 ~6 ~49 dark_oak_stairs 1  
fill ~12 ~6 ~58 ~16 ~6 ~58 stained_hardened_clay 15  
fill ~12 ~6 ~60 ~18 ~6 ~60 dropper 5  
fill ~12 ~6 ~61 ~26 ~6 ~61 planks 5  
fill ~12 ~6 ~62 ~26 ~6 ~62 planks 5  
fill ~12 ~6 ~63 ~12 ~8 ~63 stained_hardened_clay 15  
fill ~12 ~6 ~64 ~12 ~6 ~63 stained_hardened_clay 15  
fill ~13 ~6 ~9 ~25 ~6 ~9 coal_block 0  
fill ~13 ~6 ~10 ~13 ~6 ~9 coal_block 0  
fill ~13 ~6 ~11 ~25 ~6 ~11 planks 5  
fill ~13 ~6 ~12 ~25 ~6 ~12 planks 5  
fill ~13 ~6 ~13 ~25 ~6 ~13 planks 5 
setblock ~13 ~6 ~25 dark_oak_stairs 1 
setblock ~13 ~6 ~34 brown_shulker_box 1 
setblock ~13 ~6 ~55 dark_oak_stairs 1  
fill ~13 ~6 ~63 ~25 ~6 ~63 planks 5  
fill ~13 ~6 ~64 ~25 ~6 ~64 planks 5 
setblock ~13 ~6 ~65 stained_hardened_clay 15  
fill ~14 ~6 ~10 ~24 ~6 ~10 planks 5 
setblock ~14 ~6 ~22 activator_rail 5 
setblock ~14 ~6 ~27 planks 0  
fill ~14 ~6 ~28 ~14 ~9 ~28 planks 5  
fill ~14 ~6 ~34 ~14 ~9 ~34 planks 5 
setblock ~14 ~6 ~35 planks 1  
fill ~14 ~6 ~40 ~14 ~9 ~40 planks 5  
fill ~14 ~6 ~46 ~14 ~9 ~46 planks 5  
fill ~14 ~6 ~52 ~14 ~9 ~52 planks 5  
fill ~14 ~6 ~65 ~24 ~6 ~65 planks 5  
fill ~14 ~6 ~66 ~14 ~9 ~66 stained_hardened_clay 15  
fill ~14 ~6 ~67 ~14 ~8 ~67 stained_hardened_clay 15  
fill ~15 ~6 ~22 ~23 ~6 ~22 dropper 5 
setblock ~15 ~6 ~28 planks 1 
setblock ~15 ~6 ~33 brown_shulker_box 1  
fill ~15 ~6 ~68 ~15 ~7 ~68 stained_hardened_clay 15  
fill ~15 ~6 ~69 ~15 ~7 ~69 stained_hardened_clay 15  
fill ~16 ~6 ~39 ~16 ~7 ~39 fence 5  
fill ~16 ~6 ~42 ~18 ~6 ~42 fence 5  
fill ~16 ~6 ~43 ~22 ~6 ~43 dropper 5  
fill ~16 ~6 ~44 ~16 ~6 ~51 dropper 5 
setblock ~16 ~6 ~53 brown_shulker_box 1  
fill ~16 ~6 ~66 ~24 ~6 ~66 stained_hardened_clay 15  
fill ~16 ~6 ~70 ~16 ~7 ~70 stained_hardened_clay 15  
fill ~17 ~6 ~39 ~17 ~6 ~40 dark_oak_stairs 0  
fill ~17 ~6 ~44 ~17 ~6 ~49 trapdoor 3  
fill ~17 ~6 ~50 ~19 ~6 ~50 trapdoor 0  
fill ~17 ~6 ~51 ~22 ~6 ~51 dropper 5 
setblock ~17 ~6 ~54 brown_shulker_box 1 
setblock ~17 ~6 ~55 carpet 12 
setblock ~17 ~6 ~56 brown_shulker_box 1 
setblock ~17 ~6 ~58 wooden_door 1  
fill ~17 ~6 ~71 ~17 ~7 ~71 stained_hardened_clay 15 
setblock ~17 ~6 ~72 stone_slab 3 
setblock ~18 ~6 ~33 dark_oak_stairs 4  
fill ~18 ~6 ~39 ~18 ~6 ~40 dark_oak_stairs 5  
fill ~18 ~6 ~44 ~20 ~6 ~44 trapdoor 1  
fill ~18 ~6 ~45 ~19 ~6 ~45 trapdoor 1  
fill ~18 ~6 ~46 ~19 ~6 ~46 trapdoor 3  
fill ~18 ~6 ~47 ~19 ~6 ~47 trapdoor 3  
fill ~18 ~6 ~48 ~19 ~6 ~48 trapdoor 3  
fill ~18 ~6 ~49 ~18 ~6 ~46 trapdoor 3  
fill ~18 ~6 ~58 ~20 ~6 ~58 stained_hardened_clay 15 
setblock ~18 ~6 ~59 activator_rail 5  
fill ~18 ~6 ~72 ~18 ~7 ~72 stained_hardened_clay 15 
setblock ~18 ~6 ~73 stone_slab 3 
setblock ~19 ~6 ~32 dark_oak_stairs 6 
setblock ~19 ~6 ~34 dark_oak_stairs 7 
setblock ~19 ~6 ~49 trapdoor 0  
fill ~19 ~6 ~54 ~19 ~6 ~55 dark_oak_stairs 4 
setblock ~19 ~6 ~59 log2 1 
setblock ~19 ~6 ~60 activator_rail 5  
fill ~19 ~6 ~76 ~19 ~11 ~76 stained_hardened_clay 15  
fill ~20 ~6 ~16 ~26 ~6 ~16 planks 5 
setblock ~20 ~6 ~33 dark_oak_stairs 5  
fill ~20 ~6 ~45 ~20 ~6 ~50 trapdoor 2  
fill ~20 ~6 ~52 ~21 ~6 ~52 fence 5  
fill ~20 ~6 ~54 ~20 ~6 ~55 dark_oak_stairs 1 
setblock ~20 ~6 ~59 activator_rail 5  
fill ~20 ~6 ~60 ~26 ~6 ~60 dropper 5  
fill ~20 ~6 ~72 ~20 ~7 ~72 stained_hardened_clay 15 
setblock ~20 ~6 ~73 stone_slab 3  
fill ~21 ~6 ~44 ~21 ~6 ~50 trapdoor 3  
fill ~21 ~6 ~55 ~22 ~6 ~55 fence 5 
setblock ~21 ~6 ~58 wooden_door 1  
fill ~21 ~6 ~59 ~27 ~6 ~59 dropper 5  
fill ~21 ~6 ~71 ~21 ~7 ~71 stained_hardened_clay 15 
setblock ~21 ~6 ~72 stone_slab 3  
fill ~22 ~6 ~44 ~22 ~6 ~51 dropper 5  
fill ~22 ~6 ~58 ~28 ~6 ~58 stained_hardened_clay 15  
fill ~22 ~6 ~70 ~22 ~7 ~70 stained_hardened_clay 15 
setblock ~23 ~6 ~52 flower_pot 0  
fill ~23 ~6 ~68 ~23 ~7 ~68 stained_hardened_clay 15  
fill ~23 ~6 ~69 ~23 ~7 ~69 stained_hardened_clay 15 
setblock ~24 ~6 ~22 activator_rail 5  
fill ~24 ~6 ~28 ~24 ~9 ~28 planks 5  
fill ~24 ~6 ~34 ~24 ~9 ~34 planks 5  
fill ~24 ~6 ~40 ~24 ~9 ~40 planks 5 
setblock ~24 ~6 ~45 brown_shulker_box 1  
fill ~24 ~6 ~46 ~24 ~9 ~46 planks 5 
setblock ~24 ~6 ~51 brown_shulker_box 1  
fill ~24 ~6 ~52 ~24 ~9 ~52 planks 5  
fill ~24 ~6 ~67 ~24 ~8 ~67 stained_hardened_clay 15 
setblock ~25 ~6 ~10 coal_block 0  
fill ~25 ~6 ~22 ~26 ~6 ~22 dropper 5 
setblock ~25 ~6 ~25 dark_oak_stairs 0 
setblock ~25 ~6 ~45 flower_pot 0 
setblock ~25 ~6 ~46 planks 1 
setblock ~25 ~6 ~55 dark_oak_stairs 0 
setblock ~25 ~6 ~65 stained_hardened_clay 15  
fill ~26 ~6 ~11 ~26 ~6 ~13 coal_block 0  
fill ~26 ~6 ~25 ~27 ~6 ~25 stone 6 
setblock ~26 ~6 ~31 dark_oak_stairs 0 
setblock ~26 ~6 ~49 dark_oak_stairs 0  
fill ~26 ~6 ~55 ~27 ~6 ~55 stone 6  
fill ~26 ~6 ~63 ~26 ~8 ~63 stained_hardened_clay 15  
fill ~26 ~6 ~64 ~26 ~6 ~63 stained_hardened_clay 15  
fill ~27 ~6 ~14 ~27 ~6 ~18 coal_block 0  
fill ~27 ~6 ~31 ~28 ~6 ~31 stone 6 
setblock ~27 ~6 ~37 dark_oak_stairs 0 
setblock ~27 ~6 ~43 dark_oak_stairs 0  
fill ~27 ~6 ~49 ~28 ~6 ~49 stone 6  
fill ~27 ~6 ~60 ~27 ~8 ~60 stained_hardened_clay 15  
fill ~27 ~6 ~61 ~27 ~7 ~61 stained_hardened_clay 15  
fill ~27 ~6 ~62 ~27 ~6 ~60 stained_hardened_clay 15  
fill ~28 ~6 ~19 ~28 ~6 ~23 coal_block 0  
fill ~28 ~6 ~24 ~28 ~8 ~24 stained_hardened_clay 15  
fill ~28 ~6 ~28 ~29 ~6 ~28 stained_hardened_clay 15 
setblock ~28 ~6 ~34 brown_shulker_box 1  
fill ~28 ~6 ~37 ~29 ~6 ~37 stone 6  
fill ~28 ~6 ~43 ~29 ~6 ~43 stone 6  
fill ~28 ~6 ~52 ~29 ~6 ~52 stained_hardened_clay 15  
fill ~28 ~6 ~56 ~29 ~6 ~56 stained_hardened_clay 15  
fill ~28 ~6 ~57 ~28 ~7 ~57 stained_hardened_clay 15 
setblock ~28 ~6 ~59 stained_hardened_clay 15  
fill ~29 ~6 ~25 ~29 ~6 ~29 stained_hardened_clay 15  
fill ~29 ~6 ~34 ~30 ~6 ~34 stained_hardened_clay 15  
fill ~29 ~6 ~40 ~30 ~6 ~40 stained_hardened_clay 15  
fill ~29 ~6 ~46 ~30 ~6 ~46 stained_hardened_clay 15  
fill ~29 ~6 ~51 ~29 ~8 ~51 stained_hardened_clay 15  
fill ~29 ~6 ~53 ~29 ~7 ~53 stained_hardened_clay 15  
fill ~29 ~6 ~54 ~29 ~7 ~54 stained_hardened_clay 15  
fill ~29 ~6 ~55 ~29 ~6 ~51 stained_hardened_clay 15  
fill ~30 ~6 ~30 ~30 ~6 ~50 stained_hardened_clay 15  
fill ~31 ~6 ~39 ~31 ~8 ~39 dark_oak_fence_gate 5  
fill ~8 ~7 ~32 ~8 ~7 ~36 stained_hardened_clay 15 
setblock ~8 ~7 ~37 wool 15  
fill ~8 ~7 ~38 ~8 ~8 ~38 stained_hardened_clay 15  
fill ~8 ~7 ~39 ~8 ~8 ~39 stained_hardened_clay 15  
fill ~8 ~7 ~40 ~8 ~8 ~40 stained_hardened_clay 15  
fill ~8 ~7 ~41 ~8 ~8 ~41 stained_hardened_clay 15  
fill ~8 ~7 ~42 ~8 ~8 ~42 stained_hardened_clay 15 
setblock ~8 ~7 ~43 wool 15  
fill ~8 ~7 ~44 ~8 ~8 ~44 stained_hardened_clay 15  
fill ~8 ~7 ~45 ~8 ~8 ~45 stained_hardened_clay 15  
fill ~8 ~7 ~46 ~8 ~7 ~48 stained_hardened_clay 15  
fill ~9 ~7 ~26 ~9 ~7 ~30 stained_hardened_clay 15 
setblock ~9 ~7 ~31 wool 15 
setblock ~9 ~7 ~49 wool 15  
fill ~9 ~7 ~50 ~9 ~8 ~50 stained_hardened_clay 15  
fill ~9 ~7 ~52 ~10 ~7 ~52 stained_hardened_clay 15  
fill ~10 ~7 ~20 ~10 ~7 ~24 stained_hardened_clay 15 
setblock ~10 ~7 ~25 wool 15 
setblock ~10 ~7 ~55 wool 15  
fill ~11 ~7 ~14 ~11 ~7 ~19 stained_hardened_clay 15  
fill ~11 ~7 ~59 ~11 ~8 ~59 stained_hardened_clay 15  
fill ~12 ~7 ~11 ~12 ~9 ~11 stained_hardened_clay 15  
fill ~12 ~7 ~12 ~12 ~9 ~12 stained_hardened_clay 15  
fill ~12 ~7 ~13 ~12 ~7 ~11 stained_hardened_clay 15  
fill ~12 ~7 ~16 ~12 ~9 ~16 stained_hardened_clay 15  
fill ~12 ~7 ~19 ~13 ~7 ~19 stone 6  
fill ~12 ~7 ~58 ~16 ~7 ~58 stained_hardened_clay 15  
fill ~12 ~7 ~62 ~12 ~9 ~62 stained_hardened_clay 15  
fill ~13 ~7 ~8 ~25 ~7 ~8 stained_hardened_clay 15  
fill ~13 ~7 ~9 ~13 ~9 ~9 stained_hardened_clay 15  
fill ~13 ~7 ~10 ~25 ~7 ~10 stained_hardened_clay 15  
fill ~13 ~7 ~13 ~14 ~7 ~13 stone 6 
setblock ~13 ~7 ~34 carpet 12  
fill ~13 ~7 ~61 ~14 ~7 ~61 stone 6  
fill ~13 ~7 ~64 ~13 ~7 ~65 dark_oak_stairs 2  
fill ~13 ~7 ~66 ~13 ~7 ~67 stone_slab 3  
fill ~14 ~7 ~6 ~24 ~7 ~6 stained_hardened_clay 15  
fill ~14 ~7 ~7 ~24 ~7 ~7 stained_hardened_clay 15  
fill ~14 ~7 ~16 ~14 ~10 ~16 planks 5 
setblock ~14 ~7 ~19 dark_oak_stairs 1  
fill ~14 ~7 ~22 ~14 ~9 ~22 planks 5 
setblock ~14 ~7 ~41 stone_slab 14  
fill ~14 ~7 ~42 ~14 ~7 ~44 stone_slab 6 
setblock ~14 ~7 ~45 stone_slab 14 
setblock ~14 ~7 ~47 stone_slab 14  
fill ~14 ~7 ~48 ~14 ~7 ~50 stone_slab 6 
setblock ~14 ~7 ~51 stone_slab 14  
fill ~14 ~7 ~68 ~14 ~9 ~68 double_stone_slab 3 
setblock ~14 ~7 ~69 stone_slab 3 
setblock ~15 ~7 ~9 stained_hardened_clay 15 
setblock ~15 ~7 ~13 dark_oak_stairs 1 
setblock ~15 ~7 ~33 carpet 12 
setblock ~15 ~7 ~61 dark_oak_stairs 1  
fill ~15 ~7 ~65 ~17 ~7 ~65 dark_oak_stairs 2  
fill ~15 ~7 ~67 ~23 ~7 ~67 planks 5  
fill ~15 ~7 ~70 ~15 ~9 ~70 double_stone_slab 3 
setblock ~16 ~7 ~53 carpet 12  
fill ~16 ~7 ~66 ~24 ~7 ~66 stained_hardened_clay 15  
fill ~16 ~7 ~68 ~22 ~7 ~68 planks 5  
fill ~16 ~7 ~69 ~22 ~7 ~69 planks 5 
setblock ~16 ~7 ~71 stone_slab 3 
setblock ~16 ~7 ~72 stone_slab 11 
setblock ~17 ~7 ~9 stained_hardened_clay 15  
fill ~17 ~7 ~39 ~17 ~8 ~39 fence 5 
setblock ~17 ~7 ~54 carpet 12 
setblock ~17 ~7 ~56 carpet 12 
setblock ~17 ~7 ~58 wooden_door 8  
fill ~17 ~7 ~70 ~21 ~7 ~70 planks 5  
fill ~17 ~7 ~73 ~17 ~7 ~74 stone_slab 11 
setblock ~18 ~7 ~16 dark_oak_stairs 4  
fill ~18 ~7 ~39 ~18 ~7 ~40 dark_oak_stairs 0  
fill ~18 ~7 ~54 ~18 ~7 ~55 dark_oak_stairs 4  
fill ~18 ~7 ~58 ~20 ~7 ~58 stained_hardened_clay 15 
setblock ~18 ~7 ~59 dark_oak_stairs 4  
fill ~18 ~7 ~71 ~20 ~7 ~71 planks 5 
setblock ~19 ~7 ~9 stained_hardened_clay 15 
setblock ~19 ~7 ~15 dark_oak_stairs 6 
setblock ~19 ~7 ~16 log2 1 
setblock ~19 ~7 ~17 dark_oak_stairs 7 
setblock ~19 ~7 ~33 log2 1  
fill ~19 ~7 ~39 ~19 ~7 ~40 dark_oak_stairs 5  
fill ~19 ~7 ~54 ~19 ~7 ~55 dark_oak_stairs 1  
fill ~19 ~7 ~59 ~19 ~10 ~59 stained_hardened_clay 15 
setblock ~19 ~7 ~60 dark_oak_stairs 7  
fill ~19 ~7 ~72 ~19 ~8 ~72 activator_rail 5  
fill ~19 ~7 ~77 ~19 ~10 ~77 stained_hardened_clay 15 
setblock ~19 ~7 ~78 stone_stairs 7 
setblock ~20 ~7 ~16 dark_oak_stairs 5  
fill ~20 ~7 ~55 ~21 ~7 ~55 fence 5 
setblock ~20 ~7 ~59 dark_oak_stairs 5 
setblock ~21 ~7 ~9 stained_hardened_clay 15 
setblock ~21 ~7 ~58 wooden_door 9  
fill ~21 ~7 ~65 ~23 ~7 ~65 dark_oak_stairs 2  
fill ~21 ~7 ~73 ~21 ~7 ~74 stone_slab 11  
fill ~22 ~7 ~58 ~28 ~7 ~58 stained_hardened_clay 15 
setblock ~22 ~7 ~71 stone_slab 3 
setblock ~22 ~7 ~72 stone_slab 11 
setblock ~23 ~7 ~9 stained_hardened_clay 15 
setblock ~23 ~7 ~13 dark_oak_stairs 0 
setblock ~23 ~7 ~17 planks 0 
setblock ~23 ~7 ~61 dark_oak_stairs 0  
fill ~23 ~7 ~70 ~23 ~9 ~70 double_stone_slab 3  
fill ~24 ~7 ~13 ~25 ~7 ~13 stone 6 
setblock ~24 ~7 ~15 brown_shulker_box 1  
fill ~24 ~7 ~16 ~24 ~10 ~16 planks 5 
setblock ~24 ~7 ~19 dark_oak_stairs 0  
fill ~24 ~7 ~22 ~24 ~9 ~22 planks 5 
setblock ~24 ~7 ~23 stone_slab 14  
fill ~24 ~7 ~24 ~24 ~7 ~26 stone_slab 6 
setblock ~24 ~7 ~27 stone_slab 14 
setblock ~24 ~7 ~29 stone_slab 14  
fill ~24 ~7 ~30 ~24 ~7 ~32 stone_slab 6 
setblock ~24 ~7 ~33 stone_slab 14 
setblock ~24 ~7 ~45 carpet 12 
setblock ~24 ~7 ~51 carpet 12  
fill ~24 ~7 ~61 ~25 ~7 ~61 stone 6  
fill ~24 ~7 ~68 ~24 ~9 ~68 double_stone_slab 3 
setblock ~24 ~7 ~69 stone_slab 3  
fill ~25 ~7 ~9 ~25 ~9 ~9 stained_hardened_clay 15  
fill ~25 ~7 ~19 ~26 ~7 ~19 stone 6  
fill ~25 ~7 ~64 ~25 ~7 ~65 dark_oak_stairs 2  
fill ~25 ~7 ~66 ~25 ~7 ~67 stone_slab 3  
fill ~26 ~7 ~11 ~26 ~9 ~11 stained_hardened_clay 15  
fill ~26 ~7 ~12 ~26 ~9 ~12 stained_hardened_clay 15  
fill ~26 ~7 ~13 ~26 ~7 ~11 stained_hardened_clay 15  
fill ~26 ~7 ~16 ~27 ~7 ~16 stained_hardened_clay 15  
fill ~26 ~7 ~62 ~26 ~9 ~62 stained_hardened_clay 15  
fill ~27 ~7 ~14 ~27 ~7 ~19 stained_hardened_clay 15  
fill ~27 ~7 ~59 ~27 ~8 ~59 stained_hardened_clay 15  
fill ~28 ~7 ~20 ~28 ~7 ~24 stained_hardened_clay 15 
setblock ~28 ~7 ~25 wool 15  
fill ~28 ~7 ~28 ~29 ~7 ~28 stained_hardened_clay 15 
setblock ~28 ~7 ~34 carpet 12  
fill ~28 ~7 ~52 ~29 ~7 ~52 stained_hardened_clay 15 
setblock ~28 ~7 ~55 wool 15  
fill ~28 ~7 ~56 ~28 ~8 ~56 stained_hardened_clay 15  
fill ~29 ~7 ~26 ~29 ~7 ~30 stained_hardened_clay 15 
setblock ~29 ~7 ~31 wool 15  
fill ~29 ~7 ~34 ~30 ~7 ~34 stained_hardened_clay 15  
fill ~29 ~7 ~40 ~30 ~7 ~40 stained_hardened_clay 15  
fill ~29 ~7 ~46 ~30 ~7 ~46 stained_hardened_clay 15 
setblock ~29 ~7 ~49 wool 15  
fill ~29 ~7 ~50 ~29 ~8 ~50 stained_hardened_clay 15  
fill ~30 ~7 ~32 ~30 ~7 ~36 stained_hardened_clay 15 
setblock ~30 ~7 ~37 wool 15  
fill ~30 ~7 ~38 ~30 ~8 ~38 stained_hardened_clay 15  
fill ~30 ~7 ~39 ~30 ~8 ~39 stained_hardened_clay 15  
fill ~30 ~7 ~41 ~30 ~8 ~41 stained_hardened_clay 15  
fill ~30 ~7 ~42 ~30 ~8 ~42 stained_hardened_clay 15 
setblock ~30 ~7 ~43 wool 15  
fill ~30 ~7 ~44 ~30 ~8 ~44 stained_hardened_clay 15  
fill ~30 ~7 ~45 ~30 ~8 ~45 stained_hardened_clay 15  
fill ~30 ~7 ~47 ~30 ~7 ~48 stained_hardened_clay 15 
setblock ~8 ~8 ~29 lever 2 
setblock ~8 ~8 ~31 lever 2  
fill ~8 ~8 ~35 ~8 ~8 ~45 stained_hardened_clay 15 
setblock ~8 ~8 ~47 lever 2 
setblock ~8 ~8 ~49 lever 2 
setblock ~8 ~8 ~51 lever 2 
setblock ~9 ~8 ~23 lever 2 
setblock ~9 ~8 ~25 lever 2 
setblock ~9 ~8 ~27 lever 2  
fill ~9 ~8 ~28 ~9 ~8 ~34 stained_hardened_clay 15  
fill ~9 ~8 ~47 ~9 ~8 ~52 stained_hardened_clay 15 
setblock ~9 ~8 ~53 lever 2 
setblock ~9 ~8 ~55 lever 2  
fill ~10 ~8 ~22 ~10 ~8 ~28 stained_hardened_clay 15  
fill ~10 ~8 ~52 ~10 ~8 ~56 stained_hardened_clay 15 
setblock ~10 ~8 ~57 lever 2  
fill ~11 ~8 ~15 ~11 ~8 ~18 stained_hardened_clay 15 
setblock ~11 ~8 ~19 wool 15  
fill ~11 ~8 ~20 ~11 ~9 ~20 stained_hardened_clay 15  
fill ~11 ~8 ~21 ~11 ~9 ~21 stained_hardened_clay 15 
setblock ~11 ~8 ~57 stained_hardened_clay 15 
setblock ~12 ~8 ~13 wool 15  
fill ~12 ~8 ~14 ~12 ~9 ~14 stained_hardened_clay 15  
fill ~12 ~8 ~58 ~16 ~8 ~58 stained_hardened_clay 15 
setblock ~12 ~8 ~61 wool 15  
fill ~13 ~8 ~7 ~13 ~10 ~7 stained_hardened_clay 15  
fill ~13 ~8 ~8 ~13 ~9 ~8 stained_hardened_clay 15  
fill ~13 ~8 ~10 ~25 ~8 ~10 stained_hardened_clay 15 
setblock ~13 ~8 ~22 torch 2 
setblock ~13 ~8 ~28 torch 2 
setblock ~13 ~8 ~34 torch 2 
setblock ~13 ~8 ~40 torch 2 
setblock ~13 ~8 ~46 torch 2 
setblock ~13 ~8 ~52 torch 2  
fill ~13 ~8 ~64 ~13 ~9 ~64 stained_hardened_clay 15  
fill ~13 ~8 ~65 ~13 ~8 ~64 stained_hardened_clay 15  
fill ~13 ~8 ~66 ~13 ~8 ~67 stone_slab 11  
fill ~14 ~8 ~6 ~15 ~8 ~6 stained_hardened_clay 15  
fill ~15 ~8 ~5 ~23 ~8 ~5 stained_hardened_clay 15  
fill ~15 ~8 ~7 ~15 ~8 ~8 stained_hardened_clay 15  
fill ~15 ~8 ~66 ~15 ~10 ~66 planks 5 
setblock ~15 ~8 ~69 stone_slab 3 
setblock ~16 ~8 ~66 spruce_door 3 
setblock ~16 ~8 ~71 stone_slab 11  
fill ~16 ~8 ~72 ~16 ~9 ~72 double_stone_slab 3  
fill ~17 ~8 ~6 ~17 ~8 ~8 stained_hardened_clay 15  
fill ~17 ~8 ~54 ~17 ~8 ~55 dark_oak_stairs 4 
setblock ~17 ~8 ~58 dropper 0  
fill ~17 ~8 ~66 ~17 ~10 ~66 planks 5  
fill ~17 ~8 ~74 ~17 ~10 ~74 double_stone_slab 3 
setblock ~18 ~8 ~33 torch 2  
fill ~18 ~8 ~39 ~18 ~9 ~39 fence 5  
fill ~18 ~8 ~54 ~18 ~8 ~55 dark_oak_stairs 1  
fill ~18 ~8 ~58 ~20 ~8 ~58 stained_hardened_clay 15 
setblock ~18 ~8 ~66 planks 1 
setblock ~18 ~8 ~75 stone_slab 3 
setblock ~18 ~8 ~76 stone_stairs 7  
fill ~18 ~8 ~77 ~18 ~8 ~78 cobblestone_wall 0  
fill ~19 ~8 ~6 ~19 ~8 ~8 stained_hardened_clay 15  
fill ~19 ~8 ~16 ~19 ~11 ~16 stained_hardened_clay 15  
fill ~19 ~8 ~33 ~19 ~11 ~33 stained_hardened_clay 15  
fill ~19 ~8 ~39 ~19 ~8 ~40 dark_oak_stairs 0  
fill ~19 ~8 ~55 ~20 ~8 ~55 fence 5 
setblock ~19 ~8 ~57 torch 4  
fill ~19 ~8 ~66 ~19 ~10 ~66 planks 5 
setblock ~19 ~8 ~71 dropper 5 
setblock ~19 ~8 ~74 dropper 5 
setblock ~19 ~8 ~78 double_stone_slab 3 
setblock ~19 ~8 ~79 stone_stairs 7 
setblock ~20 ~8 ~33 torch 1  
fill ~20 ~8 ~39 ~20 ~8 ~40 dark_oak_stairs 5 
setblock ~20 ~8 ~66 planks 1 
setblock ~20 ~8 ~75 stone_slab 3 
setblock ~20 ~8 ~76 stone_stairs 7  
fill ~20 ~8 ~77 ~20 ~8 ~78 cobblestone_wall 0  
fill ~21 ~8 ~6 ~21 ~8 ~8 stained_hardened_clay 15 
setblock ~21 ~8 ~58 dropper 0  
fill ~21 ~8 ~66 ~21 ~10 ~66 planks 5  
fill ~21 ~8 ~74 ~21 ~10 ~74 double_stone_slab 3  
fill ~22 ~8 ~58 ~27 ~8 ~58 stained_hardened_clay 15 
setblock ~22 ~8 ~66 spruce_door 3 
setblock ~22 ~8 ~71 stone_slab 11  
fill ~22 ~8 ~72 ~22 ~9 ~72 double_stone_slab 3  
fill ~23 ~8 ~6 ~24 ~8 ~6 stained_hardened_clay 15  
fill ~23 ~8 ~7 ~23 ~8 ~8 stained_hardened_clay 15 
setblock ~23 ~8 ~17 flower_pot 0 
setblock ~23 ~8 ~22 torch 2  
fill ~23 ~8 ~66 ~23 ~10 ~66 planks 5 
setblock ~23 ~8 ~69 stone_slab 3 
setblock ~24 ~8 ~15 carpet 12  
fill ~24 ~8 ~66 ~24 ~9 ~66 stained_hardened_clay 15  
fill ~25 ~8 ~7 ~25 ~10 ~7 stained_hardened_clay 15  
fill ~25 ~8 ~8 ~25 ~9 ~8 stained_hardened_clay 15 
setblock ~25 ~8 ~28 torch 1 
setblock ~25 ~8 ~34 torch 1 
setblock ~25 ~8 ~40 torch 1 
setblock ~25 ~8 ~46 torch 1 
setblock ~25 ~8 ~52 torch 1  
fill ~25 ~8 ~64 ~25 ~9 ~64 stained_hardened_clay 15  
fill ~25 ~8 ~65 ~25 ~8 ~64 stained_hardened_clay 15  
fill ~25 ~8 ~66 ~25 ~8 ~67 stone_slab 11 
setblock ~26 ~8 ~13 wool 15  
fill ~26 ~8 ~14 ~26 ~9 ~14 stained_hardened_clay 15  
fill ~26 ~8 ~16 ~27 ~8 ~16 stained_hardened_clay 15 
setblock ~26 ~8 ~61 wool 15 
setblock ~27 ~8 ~15 stained_hardened_clay 15  
fill ~27 ~8 ~17 ~27 ~9 ~17 stained_hardened_clay 15  
fill ~27 ~8 ~18 ~27 ~9 ~18 stained_hardened_clay 15 
setblock ~27 ~8 ~19 wool 15  
fill ~27 ~8 ~20 ~27 ~9 ~20 stained_hardened_clay 15  
fill ~27 ~8 ~21 ~27 ~9 ~21 stained_hardened_clay 15 
setblock ~27 ~8 ~57 stained_hardened_clay 15  
fill ~28 ~8 ~22 ~28 ~8 ~28 stained_hardened_clay 15  
fill ~28 ~8 ~52 ~29 ~8 ~52 stained_hardened_clay 15  
fill ~28 ~8 ~53 ~28 ~8 ~56 stained_hardened_clay 15 
setblock ~28 ~8 ~57 lever 1 
setblock ~29 ~8 ~23 lever 1 
setblock ~29 ~8 ~25 lever 1 
setblock ~29 ~8 ~27 lever 1  
fill ~29 ~8 ~28 ~29 ~8 ~34 stained_hardened_clay 15  
fill ~29 ~8 ~40 ~30 ~8 ~40 stained_hardened_clay 15  
fill ~29 ~8 ~46 ~29 ~6 ~46 stained_hardened_clay 15  
fill ~29 ~8 ~47 ~29 ~8 ~52 stained_hardened_clay 15 
setblock ~29 ~8 ~53 lever 1 
setblock ~29 ~8 ~55 lever 1 
setblock ~30 ~8 ~29 lever 1 
setblock ~30 ~8 ~31 lever 1  
fill ~30 ~8 ~35 ~30 ~8 ~45 stained_hardened_clay 15 
setblock ~30 ~8 ~47 lever 1 
setblock ~30 ~8 ~49 lever 1 
setblock ~30 ~8 ~51 lever 1  
fill ~7 ~9 ~27 ~9 ~9 ~27 dropper 5  
fill ~7 ~9 ~28 ~7 ~9 ~32 dropper 5  
fill ~7 ~9 ~47 ~8 ~9 ~47 dropper 5  
fill ~7 ~9 ~48 ~7 ~9 ~50 dropper 5  
fill ~8 ~9 ~23 ~10 ~9 ~23 dropper 0  
fill ~8 ~9 ~24 ~9 ~9 ~24 dropper 0  
fill ~8 ~9 ~25 ~9 ~9 ~25 dropper 0  
fill ~8 ~9 ~26 ~9 ~9 ~26 dropper 0  
fill ~8 ~9 ~28 ~9 ~9 ~28 activator_rail 5  
fill ~8 ~9 ~29 ~9 ~9 ~29 dropper 5  
fill ~8 ~9 ~30 ~9 ~9 ~30 activator_rail 5  
fill ~8 ~9 ~31 ~8 ~9 ~32 dropper 5  
fill ~8 ~9 ~39 ~8 ~10 ~39 dark_oak_fence_gate 7  
fill ~8 ~9 ~41 ~8 ~10 ~41 dropper 0 
setblock ~8 ~9 ~48 activator_rail 5 
setblock ~8 ~9 ~49 dropper 5  
fill ~8 ~9 ~50 ~9 ~9 ~50 activator_rail 5  
fill ~8 ~9 ~51 ~9 ~9 ~51 dropper 5  
fill ~8 ~9 ~52 ~8 ~9 ~51 dropper 5  
fill ~8 ~9 ~53 ~9 ~9 ~53 dropper 0  
fill ~8 ~9 ~54 ~9 ~9 ~54 dropper 0  
fill ~9 ~9 ~31 ~9 ~9 ~49 coal_block 0 
setblock ~9 ~9 ~52 dropper 0  
fill ~9 ~9 ~55 ~10 ~9 ~55 dropper 0  
fill ~9 ~9 ~56 ~10 ~9 ~56 dropper 0  
fill ~9 ~9 ~57 ~10 ~9 ~57 dropper 0  
fill ~9 ~9 ~58 ~10 ~9 ~58 dropper 0  
fill ~10 ~9 ~24 ~10 ~9 ~30 coal_block 0  
fill ~10 ~9 ~31 ~28 ~9 ~31 planks 5  
fill ~10 ~9 ~32 ~28 ~9 ~32 planks 5  
fill ~10 ~9 ~33 ~18 ~9 ~33 planks 5  
fill ~10 ~9 ~34 ~27 ~9 ~34 planks 5  
fill ~10 ~9 ~35 ~28 ~9 ~35 planks 5  
fill ~10 ~9 ~36 ~28 ~9 ~36 planks 5  
fill ~10 ~9 ~37 ~28 ~9 ~37 planks 5  
fill ~10 ~9 ~38 ~28 ~9 ~38 planks 5  
fill ~10 ~9 ~39 ~16 ~9 ~39 planks 5  
fill ~10 ~9 ~40 ~16 ~9 ~40 planks 5  
fill ~10 ~9 ~41 ~28 ~9 ~41 planks 5  
fill ~10 ~9 ~42 ~28 ~9 ~42 planks 5  
fill ~10 ~9 ~43 ~28 ~9 ~43 planks 5  
fill ~10 ~9 ~44 ~16 ~9 ~44 planks 5  
fill ~10 ~9 ~45 ~16 ~9 ~45 planks 5  
fill ~10 ~9 ~46 ~16 ~9 ~46 planks 5  
fill ~10 ~9 ~47 ~16 ~9 ~47 planks 5  
fill ~10 ~9 ~48 ~16 ~9 ~48 planks 5  
fill ~10 ~9 ~49 ~16 ~9 ~49 planks 5  
fill ~10 ~9 ~50 ~10 ~9 ~54 coal_block 0  
fill ~11 ~9 ~16 ~11 ~9 ~23 stained_hardened_clay 15  
fill ~11 ~9 ~24 ~27 ~9 ~24 planks 5  
fill ~11 ~9 ~25 ~27 ~9 ~25 planks 5  
fill ~11 ~9 ~26 ~27 ~9 ~26 planks 5  
fill ~11 ~9 ~27 ~27 ~9 ~27 planks 5  
fill ~11 ~9 ~28 ~26 ~9 ~28 planks 5  
fill ~11 ~9 ~29 ~27 ~9 ~29 planks 5  
fill ~11 ~9 ~30 ~19 ~9 ~30 planks 5  
fill ~11 ~9 ~50 ~16 ~9 ~50 planks 5  
fill ~11 ~9 ~51 ~27 ~9 ~51 planks 5  
fill ~11 ~9 ~52 ~27 ~9 ~52 planks 5  
fill ~11 ~9 ~53 ~27 ~9 ~53 planks 5  
fill ~11 ~9 ~54 ~16 ~9 ~54 planks 5  
fill ~11 ~9 ~55 ~11 ~9 ~58 coal_block 0  
fill ~12 ~9 ~7 ~12 ~10 ~7 cobblestone_wall 0  
fill ~12 ~9 ~9 ~12 ~10 ~9 cobblestone_wall 0   

KittysCommands:  
setblock ~12 ~9 ~13 stained_hardened_clay 15 
setblock ~12 ~9 ~15 stained_hardened_clay 15  
fill ~12 ~9 ~20 ~26 ~9 ~20 planks 5  
fill ~12 ~9 ~21 ~26 ~9 ~21 planks 5  
fill ~12 ~9 ~22 ~26 ~9 ~22 planks 5  
fill ~12 ~9 ~23 ~26 ~9 ~23 planks 5  
fill ~12 ~9 ~55 ~16 ~9 ~55 planks 5  
fill ~12 ~9 ~56 ~26 ~9 ~56 planks 5  
fill ~12 ~9 ~57 ~26 ~9 ~57 planks 5  
fill ~12 ~9 ~58 ~26 ~9 ~58 stained_hardened_clay 15  
fill ~12 ~9 ~59 ~12 ~9 ~62 stained_hardened_clay 15  
fill ~13 ~9 ~5 ~13 ~10 ~5 cobblestone_wall 0  
fill ~13 ~9 ~10 ~25 ~9 ~10 stained_hardened_clay 15 
setblock ~13 ~9 ~16 torch 2 
setblock ~13 ~9 ~63 stained_hardened_clay 15  
fill ~13 ~9 ~65 ~13 ~10 ~65 cobblestone_wall 0 
setblock ~13 ~9 ~66 stone_slab 3 
setblock ~14 ~9 ~4 cobblestone_wall 0  
fill ~14 ~9 ~5 ~24 ~9 ~5 stained_hardened_clay 15  
fill ~14 ~9 ~6 ~14 ~10 ~6 stained_hardened_clay 15 
setblock ~14 ~9 ~65 stained_hardened_clay 15  
fill ~15 ~9 ~7 ~23 ~9 ~7 dropper 0  
fill ~15 ~9 ~8 ~23 ~9 ~8 dropper 0  
fill ~15 ~9 ~9 ~23 ~9 ~9 dropper 0  
fill ~15 ~9 ~11 ~23 ~9 ~11 dropper 0  
fill ~15 ~9 ~12 ~23 ~9 ~12 dropper 0  
fill ~15 ~9 ~13 ~23 ~9 ~13 dropper 0  
fill ~15 ~9 ~14 ~23 ~9 ~14 dropper 0 
setblock ~15 ~9 ~69 stone_slab 11 
setblock ~16 ~9 ~4 cobblestone_wall 0 
setblock ~16 ~9 ~66 spruce_door 8  
fill ~17 ~9 ~54 ~17 ~9 ~55 dark_oak_stairs 1 
setblock ~17 ~9 ~73 stone_slab 3 
setblock ~18 ~9 ~4 cobblestone_wall 0 
setblock ~18 ~9 ~16 torch 2  
fill ~18 ~9 ~55 ~19 ~9 ~55 fence 5 
setblock ~18 ~9 ~59 torch 2 
setblock ~18 ~9 ~66 planks 5 
setblock ~18 ~9 ~75 stone_slab 11  
fill ~18 ~9 ~76 ~18 ~10 ~76 double_stone_slab 3  
fill ~18 ~9 ~78 ~18 ~9 ~79 cobblestone_wall 0  
fill ~19 ~9 ~39 ~19 ~10 ~39 fence 5  
fill ~19 ~9 ~67 ~19 ~9 ~68 stained_hardened_clay 15 
setblock ~19 ~9 ~73 dropper 5 
setblock ~19 ~9 ~74 dropper 0 
setblock ~19 ~9 ~78 stone_stairs 2  
fill ~19 ~9 ~79 ~19 ~11 ~79 double_stone_slab 3 
setblock ~20 ~9 ~4 cobblestone_wall 0 
setblock ~20 ~9 ~16 torch 1 
setblock ~20 ~9 ~30 activator_rail 5  
fill ~20 ~9 ~33 ~28 ~9 ~33 planks 5  
fill ~20 ~9 ~39 ~20 ~9 ~40 dark_oak_stairs 0 
setblock ~20 ~9 ~59 torch 1 
setblock ~20 ~9 ~66 planks 5 
setblock ~20 ~9 ~75 stone_slab 11  
fill ~20 ~9 ~76 ~20 ~10 ~76 double_stone_slab 3  
fill ~20 ~9 ~78 ~20 ~9 ~79 cobblestone_wall 0  
fill ~21 ~9 ~30 ~27 ~9 ~30 planks 5  
fill ~21 ~9 ~39 ~28 ~9 ~39 planks 5  
fill ~21 ~9 ~40 ~28 ~9 ~40 planks 5  
fill ~21 ~9 ~54 ~27 ~9 ~54 planks 5  
fill ~21 ~9 ~55 ~26 ~9 ~55 planks 5 
setblock ~21 ~9 ~73 stone_slab 3 
setblock ~22 ~9 ~4 cobblestone_wall 0  
fill ~22 ~9 ~44 ~28 ~9 ~44 planks 5  
fill ~22 ~9 ~45 ~28 ~9 ~45 planks 5  
fill ~22 ~9 ~46 ~28 ~9 ~46 planks 5  
fill ~22 ~9 ~47 ~28 ~9 ~47 planks 5  
fill ~22 ~9 ~48 ~28 ~9 ~48 planks 5  
fill ~22 ~9 ~49 ~28 ~9 ~49 planks 5  
fill ~22 ~9 ~50 ~27 ~9 ~50 planks 5 
setblock ~22 ~9 ~66 spruce_door 9 
setblock ~23 ~9 ~69 stone_slab 11 
setblock ~24 ~9 ~4 cobblestone_wall 0  
fill ~24 ~9 ~6 ~24 ~10 ~6 stained_hardened_clay 15 
setblock ~24 ~9 ~65 stained_hardened_clay 15  
fill ~25 ~9 ~5 ~25 ~10 ~5 cobblestone_wall 0 
setblock ~25 ~9 ~16 torch 1 
setblock ~25 ~9 ~63 stained_hardened_clay 15  
fill ~25 ~9 ~65 ~25 ~10 ~65 cobblestone_wall 0 
setblock ~25 ~9 ~66 stone_slab 3  
fill ~26 ~9 ~7 ~26 ~10 ~7 cobblestone_wall 0  
fill ~26 ~9 ~9 ~26 ~10 ~9 cobblestone_wall 0 
setblock ~26 ~9 ~13 stained_hardened_clay 15  
fill ~26 ~9 ~15 ~26 ~9 ~16 stained_hardened_clay 15  
fill ~26 ~9 ~59 ~26 ~9 ~62 stained_hardened_clay 15 
setblock ~27 ~9 ~16 stained_hardened_clay 15 
setblock ~27 ~9 ~19 stained_hardened_clay 15 
setblock ~27 ~9 ~23 stained_hardened_clay 15 
setblock ~27 ~9 ~28 activator_rail 5  
fill ~27 ~9 ~55 ~27 ~9 ~58 coal_block 0  
fill ~28 ~9 ~23 ~30 ~9 ~23 dropper 0  
fill ~28 ~9 ~24 ~28 ~9 ~30 coal_block 0 
setblock ~28 ~9 ~34 activator_rail 5  
fill ~28 ~9 ~50 ~28 ~9 ~54 coal_block 0  
fill ~28 ~9 ~55 ~29 ~9 ~55 dropper 0  
fill ~28 ~9 ~56 ~29 ~9 ~56 dropper 0  
fill ~28 ~9 ~57 ~29 ~9 ~57 dropper 0  
fill ~28 ~9 ~58 ~29 ~9 ~58 dropper 0  
fill ~29 ~9 ~24 ~30 ~9 ~24 dropper 0  
fill ~29 ~9 ~25 ~30 ~9 ~25 dropper 0  
fill ~29 ~9 ~26 ~30 ~9 ~26 dropper 0  
fill ~29 ~9 ~27 ~31 ~9 ~27 dropper 5  
fill ~29 ~9 ~28 ~30 ~9 ~28 activator_rail 5  
fill ~29 ~9 ~29 ~31 ~9 ~29 dropper 5  
fill ~29 ~9 ~30 ~30 ~9 ~30 activator_rail 5  
fill ~29 ~9 ~31 ~29 ~9 ~49 coal_block 0  
fill ~29 ~9 ~50 ~30 ~9 ~50 activator_rail 5  
fill ~29 ~9 ~51 ~30 ~9 ~51 dropper 5  
fill ~29 ~9 ~52 ~29 ~9 ~58 dropper 0  
fill ~30 ~9 ~31 ~31 ~9 ~31 dropper 5  
fill ~30 ~9 ~32 ~31 ~9 ~32 dropper 5  
fill ~30 ~9 ~39 ~30 ~10 ~39 dark_oak_fence_gate 5  
fill ~30 ~9 ~41 ~30 ~10 ~41 dropper 0  
fill ~30 ~9 ~47 ~31 ~9 ~47 dropper 5 
setblock ~30 ~9 ~48 activator_rail 5  
fill ~30 ~9 ~49 ~31 ~9 ~49 dropper 5 
setblock ~30 ~9 ~52 dropper 5  
fill ~30 ~9 ~53 ~30 ~9 ~54 dropper 0 
setblock ~31 ~9 ~28 dropper 5 
setblock ~31 ~9 ~30 dropper 5 
setblock ~31 ~9 ~48 dropper 5 
setblock ~31 ~9 ~50 dropper 5  
fill ~7 ~10 ~47 ~7 ~11 ~47 glass 0  
fill ~7 ~10 ~49 ~7 ~11 ~49 glass 0  
fill ~7 ~10 ~53 ~7 ~10 ~54 glass 0  
fill ~8 ~10 ~23 ~8 ~10 ~24 glass 0  
fill ~8 ~10 ~25 ~8 ~13 ~25 fence 1  
fill ~8 ~10 ~26 ~8 ~13 ~26 fence 1  
fill ~8 ~10 ~27 ~8 ~13 ~27 fence 1  
fill ~8 ~10 ~29 ~8 ~13 ~29 fence 1  
fill ~8 ~10 ~30 ~8 ~13 ~30 fence 1  
fill ~8 ~10 ~31 ~8 ~13 ~31 fence 1  
fill ~8 ~10 ~32 ~8 ~13 ~32 fence 1  
fill ~8 ~10 ~51 ~8 ~12 ~51 fence 1  
fill ~8 ~10 ~52 ~8 ~12 ~52 fence 1  
fill ~9 ~10 ~25 ~10 ~10 ~25 dropper 5  
fill ~9 ~10 ~35 ~9 ~10 ~39 stained_hardened_clay 15  
fill ~9 ~10 ~41 ~9 ~10 ~45 stained_hardened_clay 15  
fill ~9 ~10 ~53 ~10 ~10 ~53 dropper 5 
setblock ~10 ~10 ~27 stained_hardened_clay 15 
setblock ~10 ~10 ~28 dropper 5  
fill ~10 ~10 ~29 ~10 ~10 ~33 stained_hardened_clay 15  
fill ~10 ~10 ~40 ~11 ~10 ~40 stone 6  
fill ~10 ~10 ~47 ~10 ~10 ~51 stained_hardened_clay 15 
setblock ~10 ~10 ~55 dropper 5  
fill ~10 ~10 ~57 ~11 ~10 ~57 dropper 5  
fill ~11 ~10 ~18 ~11 ~10 ~23 coal_block 0  
fill ~11 ~10 ~24 ~11 ~12 ~24 stained_hardened_clay 15  
fill ~11 ~10 ~25 ~11 ~11 ~25 stained_hardened_clay 15  
fill ~11 ~10 ~26 ~11 ~10 ~24 stained_hardened_clay 15  
fill ~11 ~10 ~27 ~15 ~10 ~27 dropper 5  
fill ~11 ~10 ~28 ~12 ~10 ~28 stone 6  
fill ~11 ~10 ~34 ~12 ~10 ~34 stone 6  
fill ~11 ~10 ~46 ~12 ~10 ~46 stone 6 
setblock ~11 ~10 ~52 dropper 5  
fill ~11 ~10 ~53 ~11 ~10 ~56 stained_hardened_clay 15  
fill ~12 ~10 ~12 ~12 ~10 ~17 coal_block 0  
fill ~12 ~10 ~18 ~12 ~10 ~19 planks 5  
fill ~12 ~10 ~22 ~13 ~10 ~22 cobblestone_wall 0  
fill ~12 ~10 ~23 ~17 ~10 ~23 stained_hardened_clay 15 
setblock ~12 ~10 ~40 dark_oak_stairs 1  
fill ~12 ~10 ~52 ~13 ~10 ~52 stone 6  
fill ~12 ~10 ~57 ~26 ~10 ~57 stained_hardened_clay 15  
fill ~12 ~10 ~58 ~26 ~10 ~58 stained_hardened_clay 15  
fill ~12 ~10 ~59 ~12 ~10 ~61 coal_block 0  
fill ~13 ~10 ~8 ~13 ~10 ~11 coal_block 0  
fill ~13 ~10 ~12 ~14 ~10 ~12 planks 5  
fill ~13 ~10 ~13 ~14 ~10 ~13 planks 5  
fill ~13 ~10 ~14 ~14 ~10 ~14 planks 5  
fill ~13 ~10 ~15 ~25 ~10 ~15 planks 5  
fill ~13 ~10 ~16 ~13 ~10 ~17 planks 5  
fill ~13 ~10 ~18 ~25 ~10 ~18 dropper 5  
fill ~13 ~10 ~19 ~25 ~10 ~19 dropper 5 
setblock ~13 ~10 ~28 dark_oak_stairs 1 
setblock ~13 ~10 ~34 dark_oak_stairs 1 
setblock ~13 ~10 ~46 dark_oak_stairs 1  
fill ~13 ~10 ~55 ~14 ~10 ~55 dark_oak_stairs 2  
fill ~13 ~10 ~56 ~14 ~10 ~56 dark_oak_stairs 7  
fill ~13 ~10 ~62 ~13 ~10 ~64 coal_block 0 
setblock ~13 ~10 ~66 stone_stairs 6 
setblock ~13 ~10 ~67 stone_slab 3 
setblock ~14 ~10 ~3 cobblestone_wall 0  
fill ~14 ~10 ~5 ~14 ~9 ~5 stained_hardened_clay 15  
fill ~14 ~10 ~7 ~14 ~10 ~17 planks 5 
setblock ~14 ~10 ~22 dark_oak_stairs 1 
setblock ~14 ~10 ~52 dark_oak_stairs 1 
setblock ~14 ~10 ~65 coal_block 0 
setblock ~14 ~10 ~66 cobblestone_wall 0  
fill ~15 ~10 ~4 ~23 ~10 ~4 stained_hardened_clay 15  
fill ~15 ~10 ~5 ~23 ~10 ~5 planks 5  
fill ~15 ~10 ~6 ~23 ~10 ~6 planks 5  
fill ~15 ~10 ~7 ~23 ~10 ~7 light_gray_glazed_terracotta 0  
fill ~15 ~10 ~8 ~16 ~10 ~8 light_gray_glazed_terracotta 0  
fill ~15 ~10 ~9 ~15 ~10 ~14 light_gray_glazed_terracotta 0  
fill ~15 ~10 ~16 ~18 ~10 ~16 planks 5  
fill ~15 ~10 ~17 ~25 ~10 ~17 planks 5 
setblock ~16 ~10 ~3 cobblestone_wall 0  
fill ~16 ~10 ~9 ~16 ~10 ~12 stained_hardened_clay 14  
fill ~16 ~10 ~13 ~16 ~10 ~14 light_gray_glazed_terracotta 0 
setblock ~16 ~10 ~22 brown_shulker_box 1 
setblock ~16 ~10 ~26 brown_shulker_box 1 
setblock ~16 ~10 ~27 stained_hardened_clay 15 
setblock ~16 ~10 ~38 activator_rail 5  
fill ~16 ~10 ~39 ~16 ~10 ~40 dropper 0 
setblock ~16 ~10 ~41 activator_rail 5  
fill ~16 ~10 ~43 ~22 ~10 ~43 dropper 5  
fill ~16 ~10 ~44 ~16 ~10 ~51 dropper 5 
setblock ~16 ~10 ~53 activator_rail 5 
setblock ~16 ~10 ~56 activator_rail 5 
setblock ~16 ~10 ~66 planks 1  
fill ~16 ~10 ~71 ~16 ~10 ~72 stone_slab 3  
fill ~17 ~10 ~8 ~21 ~10 ~8 stained_hardened_clay 14 
setblock ~17 ~10 ~9 light_gray_glazed_terracotta 0  
fill ~17 ~10 ~10 ~17 ~10 ~11 stained_hardened_clay 14 
setblock ~17 ~10 ~12 light_gray_glazed_terracotta 0  
fill ~17 ~10 ~13 ~21 ~10 ~13 stained_hardened_clay 14  
fill ~17 ~10 ~14 ~23 ~10 ~14 light_gray_glazed_terracotta 0  
fill ~17 ~10 ~24 ~17 ~12 ~24 anvil 3  
fill ~17 ~10 ~38 ~20 ~10 ~38 dropper 0  
fill ~17 ~10 ~41 ~20 ~10 ~41 dropper 0  
fill ~17 ~10 ~44 ~21 ~10 ~44 trapdoor 3  
fill ~17 ~10 ~45 ~19 ~10 ~45 trapdoor 3  
fill ~17 ~10 ~46 ~21 ~10 ~46 trapdoor 3  
fill ~17 ~10 ~47 ~21 ~10 ~47 trapdoor 3  
fill ~17 ~10 ~48 ~21 ~10 ~48 trapdoor 3  
fill ~17 ~10 ~49 ~21 ~10 ~49 trapdoor 3  
fill ~17 ~10 ~50 ~20 ~10 ~50 trapdoor 0  
fill ~17 ~10 ~51 ~22 ~10 ~51 dropper 5  
fill ~17 ~10 ~53 ~20 ~10 ~53 dropper 0  
fill ~17 ~10 ~55 ~18 ~10 ~55 fence 5  
fill ~17 ~10 ~56 ~20 ~10 ~56 dropper 0 
setblock ~17 ~10 ~73 stone_slab 11 
setblock ~18 ~10 ~3 cobblestone_wall 0 
setblock ~18 ~10 ~9 stained_hardened_clay 14  
fill ~18 ~10 ~10 ~20 ~10 ~10 light_gray_glazed_terracotta 0  
fill ~18 ~10 ~11 ~20 ~10 ~11 light_gray_glazed_terracotta 0 
setblock ~18 ~10 ~12 stained_hardened_clay 14 
setblock ~18 ~10 ~24 dark_oak_door 1  
fill ~18 ~10 ~33 ~18 ~11 ~33 stained_hardened_clay 15 
setblock ~18 ~10 ~66 planks 1  
fill ~18 ~10 ~79 ~18 ~11 ~79 cobblestone_wall 0  
fill ~18 ~10 ~80 ~19 ~10 ~80 cobblestone_wall 0 
setblock ~19 ~10 ~9 light_gray_glazed_terracotta 0 
setblock ~19 ~10 ~12 light_gray_glazed_terracotta 0  
fill ~19 ~10 ~23 ~19 ~13 ~23 planks 5  
fill ~19 ~10 ~32 ~19 ~11 ~32 stained_hardened_clay 15  
fill ~19 ~10 ~34 ~19 ~11 ~34 stained_hardened_clay 15 
setblock ~19 ~10 ~68 glass 0  
fill ~19 ~10 ~69 ~19 ~10 ~70 stained_hardened_clay 15 
setblock ~19 ~10 ~75 dropper 5 
setblock ~20 ~10 ~3 cobblestone_wall 0 
setblock ~20 ~10 ~9 stained_hardened_clay 14 
setblock ~20 ~10 ~12 stained_hardened_clay 14  
fill ~20 ~10 ~16 ~25 ~10 ~16 planks 5 
setblock ~20 ~10 ~24 dark_oak_door 1  
fill ~20 ~10 ~33 ~20 ~11 ~33 stained_hardened_clay 15 
setblock ~20 ~10 ~39 fence 5 
setblock ~20 ~10 ~45 trapdoor 2 
setblock ~20 ~10 ~66 planks 1 
setblock ~21 ~10 ~9 light_gray_glazed_terracotta 0  
fill ~21 ~10 ~10 ~22 ~10 ~10 stained_hardened_clay 14  
fill ~21 ~10 ~11 ~22 ~10 ~11 stained_hardened_clay 14 
setblock ~21 ~10 ~12 light_gray_glazed_terracotta 0  
fill ~21 ~10 ~23 ~26 ~10 ~23 stained_hardened_clay 15  
fill ~21 ~10 ~24 ~21 ~12 ~24 anvil 3 
setblock ~21 ~10 ~38 activator_rail 5 
setblock ~21 ~10 ~41 activator_rail 5 
setblock ~21 ~10 ~45 trapdoor 3 
setblock ~21 ~10 ~50 trapdoor 3 
setblock ~21 ~10 ~53 activator_rail 5  
fill ~21 ~10 ~54 ~21 ~10 ~55 dropper 0 
setblock ~21 ~10 ~56 activator_rail 5 
setblock ~21 ~10 ~73 stone_slab 11 
setblock ~22 ~10 ~3 cobblestone_wall 0  
fill ~22 ~10 ~8 ~23 ~10 ~8 light_gray_glazed_terracotta 0 
setblock ~22 ~10 ~9 stained_hardened_clay 14 
setblock ~22 ~10 ~12 stained_hardened_clay 14  
fill ~22 ~10 ~13 ~23 ~10 ~13 light_gray_glazed_terracotta 0 
setblock ~22 ~10 ~27 stained_hardened_clay 15  
fill ~22 ~10 ~44 ~22 ~10 ~51 dropper 5 
setblock ~22 ~10 ~66 planks 1  
fill ~22 ~10 ~71 ~22 ~10 ~72 stone_slab 3  
fill ~23 ~10 ~9 ~23 ~10 ~14 light_gray_glazed_terracotta 0  
fill ~23 ~10 ~27 ~27 ~10 ~27 dropper 5 
setblock ~24 ~10 ~3 cobblestone_wall 0 
setblock ~24 ~10 ~5 stained_hardened_clay 15  
fill ~24 ~10 ~7 ~24 ~10 ~17 planks 5 
setblock ~24 ~10 ~22 dark_oak_stairs 0 
setblock ~24 ~10 ~52 dark_oak_stairs 0  
fill ~24 ~10 ~55 ~25 ~10 ~55 dark_oak_stairs 2  
fill ~24 ~10 ~56 ~25 ~10 ~56 dark_oak_stairs 7 
setblock ~24 ~10 ~65 coal_block 0 
setblock ~24 ~10 ~66 cobblestone_wall 0  
fill ~25 ~10 ~8 ~25 ~10 ~11 coal_block 0  
fill ~25 ~10 ~12 ~25 ~10 ~17 planks 5  
fill ~25 ~10 ~22 ~26 ~10 ~22 cobblestone_wall 0 
setblock ~25 ~10 ~28 dark_oak_stairs 0 
setblock ~25 ~10 ~34 dark_oak_stairs 0 
setblock ~25 ~10 ~46 dark_oak_stairs 0  
fill ~25 ~10 ~52 ~26 ~10 ~52 stone 6  
fill ~25 ~10 ~62 ~25 ~10 ~64 coal_block 0 
setblock ~25 ~10 ~66 stone_stairs 6 
setblock ~25 ~10 ~67 stone_slab 3  
fill ~26 ~10 ~12 ~26 ~10 ~17 coal_block 0  
fill ~26 ~10 ~18 ~26 ~10 ~19 planks 5  
fill ~26 ~10 ~28 ~27 ~10 ~28 stone 6  
fill ~26 ~10 ~34 ~27 ~10 ~34 stone 6 
setblock ~26 ~10 ~40 dark_oak_stairs 0  
fill ~26 ~10 ~46 ~27 ~10 ~46 stone 6  
fill ~26 ~10 ~59 ~26 ~10 ~61 coal_block 0  
fill ~27 ~10 ~18 ~27 ~10 ~23 coal_block 0  
fill ~27 ~10 ~24 ~27 ~12 ~24 stained_hardened_clay 15  
fill ~27 ~10 ~25 ~27 ~11 ~25 stained_hardened_clay 15  
fill ~27 ~10 ~26 ~27 ~10 ~24 stained_hardened_clay 15  
fill ~27 ~10 ~40 ~28 ~10 ~40 stone 6 
setblock ~27 ~10 ~52 dropper 5  
fill ~27 ~10 ~53 ~27 ~10 ~56 stained_hardened_clay 15  
fill ~27 ~10 ~57 ~28 ~10 ~57 dropper 5  
fill ~28 ~10 ~25 ~29 ~10 ~25 dropper 5 
setblock ~28 ~10 ~27 stained_hardened_clay 15 
setblock ~28 ~10 ~28 dropper 5  
fill ~28 ~10 ~29 ~28 ~10 ~33 stained_hardened_clay 15  
fill ~28 ~10 ~47 ~28 ~10 ~51 stained_hardened_clay 15 
setblock ~28 ~10 ~53 dropper 5  
fill ~28 ~10 ~54 ~29 ~10 ~54 fence 1 
setblock ~28 ~10 ~55 dropper 5  
fill ~29 ~10 ~35 ~29 ~10 ~39 stained_hardened_clay 15  
fill ~29 ~10 ~41 ~29 ~10 ~45 stained_hardened_clay 15  
fill ~29 ~10 ~52 ~30 ~10 ~52 fence 1  
fill ~29 ~10 ~53 ~29 ~14 ~53 fence 1  
fill ~30 ~10 ~25 ~30 ~13 ~25 fence 1  
fill ~30 ~10 ~26 ~30 ~13 ~26 fence 1  
fill ~30 ~10 ~27 ~30 ~13 ~27 fence 1  
fill ~30 ~10 ~29 ~30 ~13 ~29 fence 1  
fill ~30 ~10 ~30 ~30 ~13 ~30 fence 1  
fill ~30 ~10 ~31 ~30 ~13 ~31 fence 1  
fill ~30 ~10 ~32 ~30 ~13 ~32 fence 1  
fill ~30 ~10 ~51 ~30 ~12 ~51 fence 1  
fill ~30 ~10 ~57 ~30 ~10 ~58 glass 0  
fill ~31 ~10 ~47 ~31 ~11 ~47 glass 0  
fill ~31 ~10 ~49 ~31 ~11 ~49 glass 0  
fill ~31 ~10 ~59 ~31 ~10 ~60 glass 0 
setblock ~6 ~11 ~55 glass 0  
fill ~7 ~11 ~25 ~7 ~11 ~26 glass 0  
fill ~9 ~11 ~35 ~9 ~11 ~36 dropper 0 
setblock ~9 ~11 ~37 anvil 0  
fill ~9 ~11 ~38 ~9 ~11 ~39 dropper 0 
setblock ~9 ~11 ~40 stained_hardened_clay 15  
fill ~9 ~11 ~41 ~9 ~11 ~42 dropper 0 
setblock ~9 ~11 ~43 anvil 0  
fill ~9 ~11 ~44 ~9 ~11 ~45 dropper 0  
fill ~9 ~11 ~52 ~9 ~14 ~52 fence 1  
fill ~9 ~11 ~53 ~9 ~14 ~53 fence 1  
fill ~9 ~11 ~54 ~10 ~11 ~54 fence 1 
setblock ~10 ~11 ~21 lever 2  
fill ~10 ~11 ~27 ~10 ~12 ~27 dropper 5 
setblock ~10 ~11 ~28 dropper 0  
fill ~10 ~11 ~29 ~10 ~12 ~29 dropper 5  
fill ~10 ~11 ~30 ~10 ~12 ~30 dropper 5 
setblock ~10 ~11 ~31 anvil 0  
fill ~10 ~11 ~32 ~10 ~12 ~32 dropper 5  
fill ~10 ~11 ~33 ~10 ~12 ~33 dropper 5 
setblock ~10 ~11 ~34 stained_hardened_clay 15 
setblock ~10 ~11 ~46 stained_hardened_clay 15  
fill ~10 ~11 ~47 ~10 ~11 ~48 dropper 0 
setblock ~10 ~11 ~49 anvil 0  
fill ~10 ~11 ~50 ~10 ~12 ~50 dropper 5  
fill ~10 ~11 ~51 ~10 ~12 ~51 dropper 5  
fill ~10 ~11 ~55 ~10 ~14 ~55 fence 1  
fill ~10 ~11 ~56 ~10 ~14 ~56 fence 1  
fill ~10 ~11 ~57 ~10 ~14 ~57 fence 1 
setblock ~11 ~11 ~19 lever 2  
fill ~11 ~11 ~20 ~11 ~11 ~21 stained_hardened_clay 15 
setblock ~11 ~11 ~22 wool 15  
fill ~11 ~11 ~23 ~12 ~11 ~23 stained_hardened_clay 15 
setblock ~11 ~11 ~26 anvil 0 
setblock ~11 ~11 ~52 dropper 0  
fill ~11 ~11 ~53 ~11 ~12 ~53 dropper 5  
fill ~11 ~11 ~54 ~11 ~12 ~54 dropper 5 
setblock ~11 ~11 ~55 anvil 0  
fill ~11 ~11 ~56 ~11 ~12 ~56 dropper 5 
setblock ~12 ~11 ~7 planks 5 
setblock ~12 ~11 ~8 dark_oak_stairs 4  
fill ~12 ~11 ~9 ~13 ~11 ~9 planks 5 
setblock ~12 ~11 ~10 dark_oak_stairs 4 
setblock ~12 ~11 ~11 dark_oak_stairs 7  
fill ~12 ~11 ~13 ~12 ~11 ~15 stained_hardened_clay 15 
setblock ~12 ~11 ~16 wool 15  
fill ~12 ~11 ~17 ~12 ~13 ~17 stained_hardened_clay 15  
fill ~12 ~11 ~18 ~12 ~13 ~18 stained_hardened_clay 15  
fill ~12 ~11 ~19 ~12 ~13 ~19 stained_hardened_clay 15  
fill ~12 ~11 ~26 ~14 ~11 ~26 dropper 5  
fill ~12 ~11 ~57 ~12 ~12 ~57 stained_hardened_clay 15  
fill ~12 ~11 ~58 ~12 ~6 ~58 stained_hardened_clay 15  
fill ~12 ~11 ~59 ~12 ~11 ~60 stained_hardened_clay 15 
setblock ~13 ~11 ~5 planks 5 
setblock ~13 ~11 ~6 dark_oak_stairs 4 
setblock ~13 ~11 ~7 activator_rail 5 
setblock ~13 ~11 ~8 planks 5  
fill ~13 ~11 ~10 ~13 ~14 ~10 stained_hardened_clay 15  
fill ~13 ~11 ~11 ~13 ~14 ~11 stained_hardened_clay 15  
fill ~13 ~11 ~12 ~13 ~14 ~12 stained_hardened_clay 15  
fill ~13 ~11 ~16 ~14 ~11 ~16 cobblestone_wall 0 
setblock ~13 ~11 ~23 stained_glass_pane 0  
fill ~13 ~11 ~56 ~14 ~11 ~56 dark_oak_stairs 2  
fill ~13 ~11 ~57 ~14 ~11 ~57 planks 5  
fill ~13 ~11 ~58 ~25 ~11 ~58 planks 5  
fill ~13 ~11 ~59 ~18 ~11 ~59 planks 5  
fill ~13 ~11 ~60 ~25 ~11 ~60 planks 5  
fill ~13 ~11 ~61 ~13 ~11 ~63 stained_hardened_clay 15 
setblock ~13 ~11 ~66 cobblestone_wall 0 
setblock ~14 ~11 ~2 dark_oak_stairs 4 
setblock ~14 ~11 ~3 planks 5 
setblock ~14 ~11 ~4 dark_oak_stairs 4 
setblock ~14 ~11 ~5 coal_block 0 
setblock ~14 ~11 ~6 activator_rail 5  
fill ~14 ~11 ~23 ~14 ~12 ~23 stained_hardened_clay 15  
fill ~14 ~11 ~64 ~14 ~11 ~65 stained_hardened_clay 15 
setblock ~15 ~11 ~2 dark_oak_stairs 6  
fill ~15 ~11 ~3 ~23 ~11 ~3 stained_hardened_clay 15  
fill ~15 ~11 ~4 ~23 ~11 ~4 activator_rail 5  
fill ~15 ~11 ~5 ~15 ~11 ~4 activator_rail 5 
setblock ~15 ~11 ~6 chest 5 
setblock ~15 ~11 ~16 dark_oak_stairs 1 
setblock ~15 ~11 ~23 stained_glass_pane 0 
setblock ~15 ~11 ~26 stained_hardened_clay 15  
fill ~15 ~11 ~57 ~23 ~11 ~57 stained_hardened_clay 15  
fill ~15 ~11 ~66 ~23 ~11 ~66 stained_hardened_clay 15 
setblock ~16 ~11 ~2 planks 5  
fill ~16 ~11 ~23 ~17 ~11 ~23 stained_hardened_clay 15 
setblock ~16 ~11 ~26 carpet 12 
setblock ~16 ~11 ~27 fence 5  
fill ~16 ~11 ~33 ~17 ~11 ~33 dropper 5 
setblock ~17 ~11 ~2 dark_oak_stairs 6  
fill ~17 ~11 ~9 ~21 ~11 ~9 dropper 0  
fill ~17 ~11 ~10 ~21 ~11 ~10 dropper 0 
setblock ~17 ~11 ~31 dropper 5 
setblock ~17 ~11 ~35 dropper 5 
setblock ~18 ~11 ~2 planks 5 
setblock ~18 ~11 ~7 trapdoor 6 
setblock ~18 ~11 ~8 activator_rail 5 
setblock ~18 ~11 ~11 activator_rail 5 
setblock ~18 ~11 ~16 dark_oak_stairs 4 
setblock ~18 ~11 ~24 dark_oak_door 9 
setblock ~18 ~11 ~32 dropper 5 
setblock ~18 ~11 ~34 dropper 5  
fill ~18 ~11 ~75 ~18 ~11 ~76 stone_slab 3 
setblock ~18 ~11 ~77 stone_slab 11  
fill ~18 ~11 ~78 ~20 ~11 ~78 cobblestone_wall 0 
setblock ~19 ~11 ~2 dark_oak_stairs 6 
setblock ~19 ~11 ~6 spruce_door 3 
setblock ~19 ~11 ~7 spruce_stairs 3 
setblock ~19 ~11 ~8 dropper 0 
setblock ~19 ~11 ~11 dropper 0 
setblock ~19 ~11 ~15 dark_oak_stairs 6 
setblock ~19 ~11 ~17 dark_oak_stairs 7  
fill ~19 ~11 ~30 ~19 ~11 ~31 dropper 5  
fill ~19 ~11 ~35 ~19 ~11 ~36 dropper 5 
setblock ~19 ~11 ~59 log2 1 
setblock ~19 ~11 ~67 glass 0  
fill ~19 ~11 ~69 ~19 ~11 ~70 glass 0 
setblock ~19 ~11 ~71 log2 9 
setblock ~19 ~11 ~72 stained_hardened_clay 15 
setblock ~19 ~11 ~77 dropper 5 
setblock ~20 ~11 ~2 planks 5 
setblock ~20 ~11 ~7 trapdoor 7 
setblock ~20 ~11 ~8 activator_rail 5 
setblock ~20 ~11 ~11 activator_rail 5 
setblock ~20 ~11 ~12 trapdoor 6 
setblock ~20 ~11 ~16 dark_oak_stairs 5 
setblock ~20 ~11 ~24 dark_oak_door 8 
setblock ~20 ~11 ~32 dropper 5 
setblock ~20 ~11 ~34 dropper 5  
fill ~20 ~11 ~59 ~25 ~11 ~59 planks 5  
fill ~20 ~11 ~75 ~20 ~11 ~76 stone_slab 3 
setblock ~20 ~11 ~77 stone_slab 11  
fill ~20 ~11 ~79 ~20 ~11 ~80 cobblestone_wall 0 
setblock ~21 ~11 ~2 dark_oak_stairs 6 
setblock ~21 ~11 ~12 spruce_stairs 2 
setblock ~21 ~11 ~13 spruce_door 1  
fill ~21 ~11 ~23 ~22 ~11 ~23 stained_hardened_clay 15 
setblock ~21 ~11 ~31 dropper 5  
fill ~21 ~11 ~33 ~22 ~11 ~33 dropper 5 
setblock ~21 ~11 ~35 dropper 5 
setblock ~22 ~11 ~2 planks 5 
setblock ~22 ~11 ~12 trapdoor 7 
setblock ~22 ~11 ~27 fence 5 
setblock ~23 ~11 ~2 dark_oak_stairs 6 
setblock ~23 ~11 ~5 activator_rail 5  
fill ~23 ~11 ~14 ~23 ~11 ~15 dark_oak_door 2 
setblock ~23 ~11 ~16 dark_oak_stairs 0 
setblock ~23 ~11 ~23 stained_glass_pane 0 
setblock ~23 ~11 ~26 stained_hardened_clay 15 
setblock ~24 ~11 ~2 dark_oak_stairs 5 
setblock ~24 ~11 ~3 planks 5 
setblock ~24 ~11 ~4 dark_oak_stairs 5 
setblock ~24 ~11 ~5 coal_block 0 
setblock ~24 ~11 ~6 activator_rail 5 
setblock ~24 ~11 ~10 dark_oak_stairs 4  
fill ~24 ~11 ~14 ~24 ~12 ~14 planks 1  
fill ~24 ~11 ~15 ~24 ~12 ~15 planks 1  
fill ~24 ~11 ~16 ~25 ~11 ~16 cobblestone_wall 0  
fill ~24 ~11 ~23 ~24 ~12 ~23 stained_hardened_clay 15  
fill ~24 ~11 ~26 ~26 ~11 ~26 dropper 5  
fill ~24 ~11 ~56 ~25 ~11 ~56 dark_oak_stairs 2  
fill ~24 ~11 ~57 ~25 ~11 ~57 planks 5  
fill ~24 ~11 ~64 ~24 ~11 ~65 stained_hardened_clay 15 
setblock ~25 ~11 ~5 planks 5 
setblock ~25 ~11 ~6 dark_oak_stairs 5 
setblock ~25 ~11 ~7 activator_rail 5  
fill ~25 ~11 ~8 ~25 ~11 ~9 planks 5  
fill ~25 ~11 ~10 ~25 ~13 ~10 stained_hardened_clay 15  
fill ~25 ~11 ~11 ~25 ~14 ~11 stained_hardened_clay 15  
fill ~25 ~11 ~12 ~25 ~14 ~12 stained_hardened_clay 15 
setblock ~25 ~11 ~23 stained_glass_pane 0  
fill ~25 ~11 ~61 ~25 ~11 ~63 stained_hardened_clay 15 
setblock ~25 ~11 ~66 cobblestone_wall 0 
setblock ~26 ~11 ~7 planks 5 
setblock ~26 ~11 ~8 dark_oak_stairs 5 
setblock ~26 ~11 ~9 planks 5 
setblock ~26 ~11 ~10 dark_oak_stairs 5 
setblock ~26 ~11 ~11 dark_oak_stairs 7  
fill ~26 ~11 ~13 ~26 ~11 ~15 stained_hardened_clay 15 
setblock ~26 ~11 ~16 wool 15  
fill ~26 ~11 ~17 ~26 ~13 ~17 stained_hardened_clay 15  
fill ~26 ~11 ~18 ~26 ~13 ~18 stained_hardened_clay 15  
fill ~26 ~11 ~19 ~26 ~13 ~19 stained_hardened_clay 15  
fill ~26 ~11 ~23 ~27 ~11 ~23 stained_hardened_clay 15  
fill ~26 ~11 ~57 ~26 ~12 ~57 stained_hardened_clay 15  
fill ~26 ~11 ~58 ~26 ~11 ~60 stained_hardened_clay 15 
setblock ~27 ~11 ~19 lever 1  
fill ~27 ~11 ~20 ~27 ~11 ~21 stained_hardened_clay 15 
setblock ~27 ~11 ~22 wool 15 
setblock ~27 ~11 ~26 anvil 2 
setblock ~27 ~11 ~52 dropper 0  
fill ~27 ~11 ~53 ~27 ~12 ~53 dropper 5  
fill ~27 ~11 ~54 ~27 ~12 ~54 dropper 5 
setblock ~27 ~11 ~55 anvil 2  
fill ~27 ~11 ~56 ~27 ~12 ~56 dropper 5 
setblock ~28 ~11 ~21 lever 1  
fill ~28 ~11 ~27 ~28 ~12 ~27 dropper 5 
setblock ~28 ~11 ~28 dropper 0  
fill ~28 ~11 ~29 ~28 ~12 ~29 dropper 5  
fill ~28 ~11 ~30 ~28 ~12 ~30 dropper 5 
setblock ~28 ~11 ~31 anvil 2  
fill ~28 ~11 ~32 ~28 ~12 ~32 dropper 5  
fill ~28 ~11 ~33 ~28 ~12 ~33 dropper 5 
setblock ~28 ~11 ~34 stained_hardened_clay 15 
setblock ~28 ~11 ~46 stained_hardened_clay 15  
fill ~28 ~11 ~47 ~28 ~11 ~48 dropper 0 
setblock ~28 ~11 ~49 anvil 2  
fill ~28 ~11 ~50 ~28 ~12 ~50 dropper 5  
fill ~28 ~11 ~51 ~28 ~12 ~51 dropper 5  
fill ~28 ~11 ~54 ~29 ~11 ~54 fence 1  
fill ~28 ~11 ~55 ~28 ~14 ~55 fence 1  
fill ~28 ~11 ~56 ~28 ~14 ~56 fence 1  
fill ~28 ~11 ~57 ~28 ~14 ~57 fence 1  
fill ~29 ~11 ~35 ~29 ~11 ~36 dropper 0 
setblock ~29 ~11 ~37 anvil 2  
fill ~29 ~11 ~38 ~29 ~11 ~39 dropper 0 
setblock ~29 ~11 ~40 stained_hardened_clay 15  
fill ~29 ~11 ~41 ~29 ~11 ~42 dropper 0 
setblock ~29 ~11 ~43 anvil 2  
fill ~29 ~11 ~44 ~29 ~11 ~45 dropper 0  
fill ~29 ~11 ~52 ~30 ~11 ~52 fence 1  
fill ~31 ~11 ~26 ~31 ~11 ~28 glass 0 
setblock ~32 ~11 ~61 glass 0 
setblock ~5 ~12 ~56 glass 0  
fill ~6 ~12 ~27 ~6 ~12 ~28 glass 0  
fill ~8 ~12 ~28 ~8 ~13 ~28 fence 1  
fill ~8 ~12 ~48 ~8 ~14 ~48 glass 0  
fill ~8 ~12 ~50 ~8 ~14 ~50 glass 0 
setblock ~9 ~12 ~35 carpet 15 
setblock ~9 ~12 ~36 fence 5  
fill ~9 ~12 ~37 ~9 ~12 ~45 carpet 15  
fill ~9 ~12 ~54 ~10 ~12 ~54 fence 1  
fill ~10 ~12 ~19 ~10 ~12 ~21 dropper 5 
setblock ~10 ~12 ~28 dropper 5 
setblock ~10 ~12 ~31 dropper 5 
setblock ~10 ~12 ~34 carpet 15 
setblock ~10 ~12 ~46 carpet 15 
setblock ~10 ~12 ~47 fence 5  
fill ~10 ~12 ~48 ~10 ~12 ~49 carpet 15 
setblock ~11 ~12 ~15 lever 2 
setblock ~11 ~12 ~19 activator_rail 5 
setblock ~11 ~12 ~20 dropper 5 
setblock ~11 ~12 ~21 activator_rail 5  
fill ~11 ~12 ~22 ~11 ~12 ~24 stained_hardened_clay 15 
setblock ~11 ~12 ~25 anvil 0 
setblock ~11 ~12 ~26 dropper 5 
setblock ~11 ~12 ~52 dropper 5 
setblock ~11 ~12 ~55 dropper 5 
setblock ~11 ~12 ~66 dropper 5  
fill ~12 ~12 ~7 ~12 ~13 ~7 stained_hardened_clay 15  
fill ~12 ~12 ~8 ~12 ~13 ~8 glass 0  
fill ~12 ~12 ~9 ~12 ~13 ~9 stained_hardened_clay 15  
fill ~12 ~12 ~10 ~12 ~13 ~10 stained_hardened_clay 15  
fill ~12 ~12 ~11 ~12 ~13 ~11 stained_hardened_clay 15 
setblock ~12 ~12 ~12 lever 2  
fill ~12 ~12 ~15 ~12 ~12 ~21 stained_hardened_clay 15  
fill ~12 ~12 ~23 ~17 ~12 ~23 stained_hardened_clay 15  
fill ~12 ~12 ~25 ~14 ~12 ~25 dropper 5 
setblock ~12 ~12 ~58 dropper 0 
setblock ~12 ~12 ~59 anvil 2 
setblock ~12 ~12 ~60 dropper 0 
setblock ~12 ~12 ~65 dropper 5  
fill ~13 ~12 ~5 ~13 ~13 ~5 stained_hardened_clay 15  
fill ~13 ~12 ~6 ~13 ~13 ~6 glass 0 
setblock ~13 ~12 ~7 flower_pot 0 
setblock ~13 ~12 ~8 redstone_torch 5  
fill ~13 ~12 ~13 ~13 ~15 ~13 stained_hardened_clay 15  
fill ~13 ~12 ~14 ~13 ~15 ~14 stained_hardened_clay 15  
fill ~13 ~12 ~61 ~16 ~12 ~61 dropper 5 
setblock ~13 ~12 ~62 anvil 2  
fill ~13 ~12 ~63 ~16 ~12 ~63 dropper 5  
fill ~13 ~12 ~64 ~16 ~12 ~64 dropper 5  
fill ~14 ~12 ~2 ~14 ~13 ~2 stained_hardened_clay 15  
fill ~14 ~12 ~3 ~14 ~13 ~3 stained_hardened_clay 15  
fill ~14 ~12 ~4 ~14 ~13 ~4 glass 0 
setblock ~14 ~12 ~11 torch 1 
setblock ~14 ~12 ~13 spruce_fence_gate 5 
setblock ~14 ~12 ~60 brown_shulker_box 1  
fill ~14 ~12 ~62 ~16 ~12 ~62 dropper 5 
setblock ~14 ~12 ~65 anvil 2 
setblock ~15 ~12 ~2 redstone_lamp 0 
setblock ~15 ~12 ~5 flower_pot 0 
setblock ~15 ~12 ~10 stone_slab 8 
setblock ~15 ~12 ~25 stained_hardened_clay 15 
setblock ~15 ~12 ~26 fence 5 
setblock ~15 ~12 ~57 anvil 1  
fill ~15 ~12 ~65 ~16 ~12 ~65 dropper 5  
fill ~15 ~12 ~66 ~16 ~12 ~66 dropper 5 
setblock ~16 ~12 ~2 stained_hardened_clay 15 
setblock ~16 ~12 ~4 redstone_torch 5 
setblock ~16 ~12 ~24 torch 3 
setblock ~16 ~12 ~27 dropper 5 
setblock ~16 ~12 ~57 dropper 0 
setblock ~17 ~12 ~2 glass 0 
setblock ~17 ~12 ~57 anvil 1  
fill ~17 ~12 ~61 ~21 ~12 ~61 dark_oak_stairs 2  
fill ~17 ~12 ~62 ~17 ~12 ~64 dark_oak_stairs 0  
fill ~17 ~12 ~65 ~21 ~12 ~65 dark_oak_stairs 3 
setblock ~17 ~12 ~66 anvil 3 
setblock ~18 ~12 ~2 stained_hardened_clay 15 
setblock ~18 ~12 ~10 redstone_torch 5 
setblock ~18 ~12 ~11 chest 5  
fill ~18 ~12 ~23 ~18 ~13 ~23 planks 5 
setblock ~18 ~12 ~33 dropper 5 
setblock ~18 ~12 ~57 dropper 0 
setblock ~18 ~12 ~60 fence 5  
fill ~18 ~12 ~62 ~19 ~12 ~62 trapdoor 9  
fill ~18 ~12 ~63 ~19 ~12 ~63 trapdoor 11  
fill ~18 ~12 ~64 ~20 ~12 ~64 trapdoor 8  
fill ~18 ~12 ~66 ~20 ~12 ~66 dropper 5 
setblock ~18 ~12 ~76 stone_slab 3  
fill ~18 ~12 ~77 ~18 ~12 ~78 cobblestone_wall 0 
setblock ~19 ~12 ~2 glass 0 
setblock ~19 ~12 ~6 spruce_door 8 
setblock ~19 ~12 ~8 carpet 0 
setblock ~19 ~12 ~11 carpet 0 
setblock ~19 ~12 ~16 log2 1 
setblock ~19 ~12 ~32 dropper 5 
setblock ~19 ~12 ~33 log2 1 
setblock ~19 ~12 ~34 dropper 5 
setblock ~19 ~12 ~57 anvil 1  
fill ~19 ~12 ~59 ~19 ~13 ~59 stained_hardened_clay 15  
fill ~19 ~12 ~71 ~19 ~12 ~72 glass 0  
fill ~19 ~12 ~73 ~19 ~12 ~74 stained_hardened_clay 15 
setblock ~19 ~12 ~79 dispenser 3 
setblock ~20 ~12 ~2 stained_hardened_clay 15 
setblock ~20 ~12 ~9 carpet 0 
setblock ~20 ~12 ~10 flower_pot 0  
fill ~20 ~12 ~23 ~20 ~13 ~23 planks 5 
setblock ~20 ~12 ~33 dropper 5 
setblock ~20 ~12 ~57 dropper 0 
setblock ~20 ~12 ~60 fence 5  
fill ~20 ~12 ~62 ~20 ~12 ~63 trapdoor 10 
setblock ~20 ~12 ~76 stone_slab 3  
fill ~20 ~12 ~77 ~20 ~12 ~78 cobblestone_wall 0  
fill ~20 ~12 ~80 ~20 ~12 ~81 cobblestone_wall 0 
setblock ~21 ~12 ~2 glass 0 
setblock ~21 ~12 ~4 trapped_chest 3 
setblock ~21 ~12 ~13 spruce_door 8  
fill ~21 ~12 ~23 ~27 ~12 ~23 stained_hardened_clay 15 
setblock ~21 ~12 ~57 anvil 1  
fill ~21 ~12 ~62 ~21 ~12 ~64 dark_oak_stairs 1 
setblock ~21 ~12 ~66 anvil 3 
setblock ~22 ~12 ~2 stained_hardened_clay 15 
setblock ~22 ~12 ~24 torch 3 
setblock ~22 ~12 ~27 dropper 5 
setblock ~22 ~12 ~57 dropper 0  
fill ~22 ~12 ~61 ~25 ~12 ~61 dropper 5  
fill ~22 ~12 ~62 ~24 ~12 ~62 dropper 5  
fill ~22 ~12 ~63 ~25 ~12 ~63 dropper 5  
fill ~22 ~12 ~64 ~25 ~12 ~64 dropper 5  
fill ~22 ~12 ~65 ~23 ~12 ~65 dropper 5  
fill ~22 ~12 ~66 ~23 ~12 ~66 dropper 5 
setblock ~23 ~12 ~2 redstone_lamp 0 
setblock ~23 ~12 ~5 flower_pot 0 
setblock ~23 ~12 ~14 dark_oak_door 9 
setblock ~23 ~12 ~15 dark_oak_door 8 
setblock ~23 ~12 ~25 stained_hardened_clay 15 
setblock ~23 ~12 ~26 fence 5 
setblock ~23 ~12 ~57 anvil 1  
fill ~24 ~12 ~2 ~24 ~13 ~2 stained_hardened_clay 15  
fill ~24 ~12 ~3 ~24 ~13 ~3 stained_hardened_clay 15  
fill ~24 ~12 ~4 ~24 ~13 ~4 glass 0 
setblock ~24 ~12 ~11 torch 2 
setblock ~24 ~12 ~13 spruce_fence_gate 7  
fill ~24 ~12 ~25 ~26 ~12 ~25 dropper 5 
setblock ~24 ~12 ~65 anvil 0  
fill ~25 ~12 ~5 ~25 ~13 ~5 stained_hardened_clay 15  
fill ~25 ~12 ~6 ~25 ~13 ~6 glass 0 
setblock ~25 ~12 ~7 redstone_torch 5 
setblock ~25 ~12 ~9 flower_pot 0  
fill ~25 ~12 ~13 ~25 ~15 ~13 stained_hardened_clay 15  
fill ~25 ~12 ~14 ~25 ~15 ~14 stained_hardened_clay 15 
setblock ~25 ~12 ~62 anvil 0  
fill ~26 ~12 ~7 ~26 ~13 ~7 stained_hardened_clay 15  
fill ~26 ~12 ~8 ~26 ~13 ~8 glass 0  
fill ~26 ~12 ~9 ~26 ~13 ~9 stained_hardened_clay 15  
fill ~26 ~12 ~10 ~26 ~13 ~10 stained_hardened_clay 15  
fill ~26 ~12 ~11 ~26 ~13 ~11 stained_hardened_clay 15 
setblock ~26 ~12 ~12 lever 1  
fill ~26 ~12 ~15 ~26 ~12 ~21 stained_hardened_clay 15 
setblock ~26 ~12 ~58 dropper 0 
setblock ~26 ~12 ~59 anvil 0 
setblock ~26 ~12 ~60 dropper 0 
setblock ~26 ~12 ~65 dropper 5 
setblock ~27 ~12 ~15 lever 1 
setblock ~27 ~12 ~19 activator_rail 5  
fill ~27 ~12 ~20 ~28 ~12 ~20 dropper 5 
setblock ~27 ~12 ~21 activator_rail 5 
setblock ~27 ~12 ~22 stained_hardened_clay 15 
setblock ~27 ~12 ~25 anvil 0 
setblock ~27 ~12 ~26 dropper 5 
setblock ~27 ~12 ~52 dropper 5 
setblock ~27 ~12 ~55 dropper 5 
setblock ~27 ~12 ~66 dropper 5 
setblock ~28 ~12 ~19 dropper 5 
setblock ~28 ~12 ~21 dropper 5 
setblock ~28 ~12 ~28 dropper 5 
setblock ~28 ~12 ~31 dropper 5 
setblock ~28 ~12 ~34 carpet 15 
setblock ~28 ~12 ~46 carpet 15 
setblock ~28 ~12 ~47 fence 5  
fill ~28 ~12 ~48 ~28 ~12 ~49 carpet 15  
fill ~28 ~12 ~54 ~29 ~12 ~54 fence 1 
setblock ~29 ~12 ~35 carpet 15 
setblock ~29 ~12 ~36 fence 5  
fill ~29 ~12 ~37 ~29 ~12 ~45 carpet 15  
fill ~29 ~12 ~52 ~30 ~12 ~52 fence 1  
fill ~30 ~12 ~28 ~30 ~13 ~28 fence 1  
fill ~30 ~12 ~48 ~30 ~14 ~48 glass 0  
fill ~30 ~12 ~50 ~30 ~14 ~50 glass 0  
fill ~32 ~12 ~29 ~32 ~12 ~31 glass 0 
setblock ~33 ~12 ~62 glass 0 
setblock ~5 ~13 ~29 glass 0 
setblock ~5 ~13 ~57 wool 15  
fill ~9 ~13 ~26 ~9 ~16 ~26 fence 1  
fill ~9 ~13 ~27 ~9 ~16 ~27 fence 1  
fill ~9 ~13 ~28 ~9 ~16 ~28 fence 1  
fill ~9 ~13 ~29 ~9 ~16 ~29 fence 1  
fill ~9 ~13 ~30 ~9 ~16 ~30 fence 1  
fill ~9 ~13 ~31 ~9 ~16 ~31 fence 1  
fill ~9 ~13 ~32 ~9 ~16 ~32 fence 1 
setblock ~9 ~13 ~36 torch 5  
fill ~9 ~13 ~54 ~10 ~13 ~54 fence 1  
fill ~10 ~13 ~19 ~10 ~15 ~19 glass 0  
fill ~10 ~13 ~21 ~10 ~15 ~21 glass 0 
setblock ~10 ~13 ~47 torch 5  
fill ~11 ~13 ~12 ~12 ~13 ~12 dropper 0  
fill ~11 ~13 ~13 ~12 ~13 ~13 dropper 0  
fill ~11 ~13 ~14 ~12 ~13 ~14 dropper 0  
fill ~11 ~13 ~15 ~12 ~13 ~15 dropper 0 
setblock ~11 ~13 ~25 dropper 5  
fill ~12 ~13 ~20 ~12 ~13 ~23 stained_hardened_clay 15 
setblock ~12 ~13 ~24 dark_oak_stairs 7 
setblock ~12 ~13 ~57 fence 5 
setblock ~12 ~13 ~58 carpet 15 
setblock ~12 ~13 ~59 dropper 5   

KittysCommands:  
setblock ~12 ~13 ~60 carpet 15  
fill ~13 ~13 ~15 ~13 ~13 ~16 stained_hardened_clay 15  
fill ~13 ~13 ~20 ~25 ~13 ~20 planks 5  
fill ~13 ~13 ~21 ~25 ~13 ~21 planks 5  
fill ~13 ~13 ~22 ~25 ~13 ~22 planks 5  
fill ~13 ~13 ~23 ~25 ~13 ~23 planks 5  
fill ~13 ~13 ~24 ~14 ~13 ~24 dropper 5  
fill ~13 ~13 ~61 ~13 ~12 ~61 dropper 5 
setblock ~13 ~13 ~62 stained_hardened_clay 15  
fill ~13 ~13 ~63 ~13 ~12 ~63 dropper 5 
setblock ~14 ~13 ~1 stained_hardened_clay 15 
setblock ~14 ~13 ~13 spruce_fence_gate 1 
setblock ~14 ~13 ~60 carpet 12 
setblock ~14 ~13 ~64 dropper 5 
setblock ~14 ~13 ~65 stained_hardened_clay 15 
setblock ~15 ~13 ~1 redstone_lamp 0 
setblock ~15 ~13 ~10 iron_bars 0  
fill ~15 ~13 ~24 ~17 ~13 ~24 stained_hardened_clay 15 
setblock ~15 ~13 ~25 fence 5 
setblock ~15 ~13 ~26 dropper 5 
setblock ~15 ~13 ~57 dropper 5  
fill ~15 ~13 ~66 ~16 ~13 ~66 dropper 5 
setblock ~16 ~13 ~1 stained_hardened_clay 15 
setblock ~16 ~13 ~57 carpet 15 
setblock ~17 ~13 ~1 glass 0 
setblock ~17 ~13 ~57 dropper 5 
setblock ~17 ~13 ~66 stained_hardened_clay 15 
setblock ~18 ~13 ~1 stained_hardened_clay 15  
fill ~18 ~13 ~24 ~20 ~13 ~24 planks 5  
fill ~18 ~13 ~25 ~20 ~13 ~25 stained_hardened_clay 15  
fill ~18 ~13 ~34 ~18 ~13 ~35 glass 0 
setblock ~18 ~13 ~57 carpet 15  
fill ~18 ~13 ~60 ~20 ~13 ~60 dropper 5  
fill ~18 ~13 ~66 ~20 ~13 ~66 dropper 5 
setblock ~19 ~13 ~1 glass 0  
fill ~19 ~13 ~16 ~19 ~16 ~16 stained_hardened_clay 15  
fill ~19 ~13 ~33 ~19 ~15 ~33 stained_hardened_clay 15 
setblock ~19 ~13 ~57 dropper 5  
fill ~19 ~13 ~73 ~19 ~13 ~74 glass 0 
setblock ~19 ~13 ~75 stained_hardened_clay 15 
setblock ~19 ~13 ~76 log2 9 
setblock ~20 ~13 ~1 stained_hardened_clay 15 
setblock ~20 ~13 ~57 carpet 15 
setblock ~20 ~13 ~81 stone_stairs 3 
setblock ~21 ~13 ~1 glass 0  
fill ~21 ~13 ~24 ~23 ~13 ~24 stained_hardened_clay 15 
setblock ~21 ~13 ~57 dropper 5 
setblock ~21 ~13 ~66 stained_hardened_clay 15 
setblock ~22 ~13 ~1 stained_hardened_clay 15 
setblock ~22 ~13 ~57 carpet 15  
fill ~22 ~13 ~66 ~23 ~13 ~66 dropper 5 
setblock ~23 ~13 ~1 redstone_lamp 0 
setblock ~23 ~13 ~25 fence 5 
setblock ~23 ~13 ~26 dropper 5 
setblock ~23 ~13 ~57 dropper 5 
setblock ~24 ~13 ~1 stained_hardened_clay 15 
setblock ~24 ~13 ~13 spruce_fence_gate 3 
setblock ~24 ~13 ~14 spruce_stairs 2 
setblock ~24 ~13 ~15 spruce_stairs 3  
fill ~24 ~13 ~24 ~25 ~13 ~24 dropper 5 
setblock ~24 ~13 ~64 dropper 5 
setblock ~24 ~13 ~65 stained_hardened_clay 15  
fill ~25 ~13 ~15 ~25 ~13 ~16 stained_hardened_clay 15 
setblock ~25 ~13 ~61 dropper 5 
setblock ~25 ~13 ~62 stained_hardened_clay 15 
setblock ~25 ~13 ~63 dropper 5  
fill ~26 ~13 ~12 ~27 ~13 ~12 dropper 0  
fill ~26 ~13 ~13 ~27 ~13 ~13 dropper 0  
fill ~26 ~13 ~14 ~27 ~13 ~14 dropper 0  
fill ~26 ~13 ~15 ~27 ~13 ~15 dropper 0  
fill ~26 ~13 ~20 ~26 ~13 ~23 stained_hardened_clay 15 
setblock ~26 ~13 ~24 dark_oak_stairs 7 
setblock ~26 ~13 ~57 fence 5 
setblock ~26 ~13 ~58 carpet 15 
setblock ~26 ~13 ~59 dropper 5 
setblock ~26 ~13 ~60 carpet 15 
setblock ~27 ~13 ~25 dropper 5  
fill ~28 ~13 ~19 ~28 ~15 ~19 glass 0  
fill ~28 ~13 ~21 ~28 ~15 ~21 glass 0 
setblock ~28 ~13 ~47 torch 5  
fill ~28 ~13 ~54 ~29 ~13 ~54 fence 1  
fill ~29 ~13 ~26 ~29 ~16 ~26 fence 1  
fill ~29 ~13 ~27 ~29 ~16 ~27 fence 1  
fill ~29 ~13 ~28 ~29 ~16 ~28 fence 1  
fill ~29 ~13 ~29 ~29 ~16 ~29 fence 1  
fill ~29 ~13 ~30 ~29 ~16 ~30 fence 1  
fill ~29 ~13 ~31 ~29 ~16 ~31 fence 1  
fill ~29 ~13 ~32 ~29 ~16 ~32 fence 1 
setblock ~29 ~13 ~36 torch 5  
fill ~29 ~13 ~52 ~29 ~14 ~52 fence 1  
fill ~33 ~13 ~32 ~33 ~13 ~33 glass 0 
setblock ~33 ~13 ~63 wool 15 
setblock ~4 ~14 ~30 glass 0  
fill ~5 ~14 ~58 ~6 ~14 ~58 wool 15  
fill ~7 ~14 ~59 ~7 ~15 ~59 wool 15  
fill ~9 ~14 ~54 ~11 ~14 ~54 fence 1  
fill ~10 ~14 ~52 ~10 ~14 ~57 fence 1  
fill ~11 ~14 ~12 ~11 ~16 ~12 fence 1  
fill ~11 ~14 ~13 ~11 ~17 ~13 fence 1  
fill ~11 ~14 ~14 ~11 ~17 ~14 fence 1  
fill ~11 ~14 ~15 ~11 ~17 ~15 fence 1  
fill ~11 ~14 ~55 ~11 ~18 ~55 fence 1  
fill ~11 ~14 ~56 ~11 ~18 ~56 fence 1  
fill ~11 ~14 ~57 ~11 ~18 ~57 fence 1  
fill ~12 ~14 ~8 ~12 ~14 ~10 coal_block 0 
setblock ~12 ~14 ~12 dropper 5  
fill ~12 ~14 ~15 ~26 ~14 ~15 dropper 5 
setblock ~12 ~14 ~17 anvil 0  
fill ~12 ~14 ~18 ~26 ~14 ~18 dropper 5  
fill ~12 ~14 ~19 ~26 ~14 ~19 dropper 5 
setblock ~12 ~14 ~20 anvil 0  
fill ~12 ~14 ~21 ~12 ~14 ~22 dropper 0 
setblock ~12 ~14 ~23 anvil 0 
setblock ~12 ~14 ~24 dropper 0 
setblock ~12 ~14 ~25 stained_hardened_clay 15 
setblock ~12 ~14 ~57 torch 5  
fill ~13 ~14 ~5 ~13 ~14 ~7 coal_block 0  
fill ~13 ~14 ~8 ~14 ~14 ~8 stained_hardened_clay 15  
fill ~13 ~14 ~9 ~14 ~14 ~9 stained_hardened_clay 15  
fill ~13 ~14 ~16 ~18 ~14 ~16 dropper 5  
