fill ~20~49~0 ~25~51~0 minecraft:wool 0
fill ~21~48~0 ~27~48~0 minecraft:wool 0
fill ~21~52~0 ~27~52~0 minecraft:wool 0
fill ~22~47~0 ~32~47~0 minecraft:wool 0
fill ~22~53~0 ~32~53~0 minecraft:wool 0
setblock ~23~42~0 minecraft:trapdoor 1
fill ~23~45~0 ~23~46~0 minecraft:fence 0
fill ~23~54~0 ~23~55~0 minecraft:fence 0
setblock ~24~42~0 minecraft:glowstone
fill ~24~43~0 ~24~44~0 minecraft:fence 0
setblock ~24~45~0 minecraft:log 0
setblock ~24~46~0 minecraft:log 1
setblock ~24~54~0 minecraft:glowstone
setblock ~24~55~0 minecraft:log 0
setblock ~24~56~0 minecraft:oak_stairs 2
setblock ~25~42~0 minecraft:trapdoor 0
fill ~25~44~0 ~26~44~0 minecraft:fence 0
setblock ~25~45~0 minecraft:fence 0
fill ~25~46~0 ~43~46~0 minecraft:wool 0
fill ~25~54~0 ~43~54~0 minecraft:wool 0
setblock ~25~55~0 minecraft:fence 0
fill ~26~43~0 ~28~43~0 minecraft:fence 0
setblock ~27~40~0 minecraft:trapdoor 1
setblock ~28~40~0 minecraft:glowstone
fill ~28~41~0 ~28~42~0 minecraft:fence 0
setblock ~28~48~0 minecraft:glowstone
setblock ~29~40~0 minecraft:trapdoor 0
fill ~29~42~0 ~31~42~0 minecraft:fence 0
setblock ~31~39~0 minecraft:trapdoor 1
fill ~31~41~0 ~37~41~0 minecraft:fence 0
fill ~31~45~0 ~37~45~0 minecraft:wool 0
fill ~31~55~0 ~37~55~0 minecraft:wool 0
setblock ~32~39~0 minecraft:glowstone
setblock ~32~40~0 minecraft:fence 0
setblock ~33~39~0 minecraft:trapdoor 0
setblock ~35~39~0 minecraft:trapdoor 1
setblock ~36~39~0 minecraft:glowstone
setblock ~36~40~0 minecraft:fence 0
fill ~36~47~0 ~46~47~0 minecraft:wool 0
fill ~36~53~0 ~46~53~0 minecraft:wool 0
setblock ~37~39~0 minecraft:trapdoor 0
fill ~37~42~0 ~40~42~0 minecraft:fence 0
setblock ~39~40~0 minecraft:trapdoor 1
setblock ~40~40~0 minecraft:glowstone
setblock ~40~41~0 minecraft:fence 0
fill ~40~43~0 ~42~43~0 minecraft:fence 0
setblock ~40~48~0 minecraft:glowstone
setblock ~41~40~0 minecraft:trapdoor 0
fill ~41~48~0 ~47~48~0 minecraft:wool 0
fill ~41~52~0 ~47~52~0 minecraft:wool 0
fill ~42~44~0 ~44~44~0 minecraft:fence 0
setblock ~43~42~0 minecraft:trapdoor 1
setblock ~43~45~0 minecraft:fence 0
fill ~43~49~0 ~48~51~0 minecraft:wool 0
setblock ~43~55~0 minecraft:fence 0
setblock ~44~42~0 minecraft:glowstone
setblock ~44~43~0 minecraft:fence 0
setblock ~44~45~0 minecraft:log 0
setblock ~44~46~0 minecraft:log 1
setblock ~44~54~0 minecraft:glowstone
setblock ~44~55~0 minecraft:log 0
setblock ~44~56~0 minecraft:oak_stairs 2
setblock ~45~42~0 minecraft:trapdoor 0
fill ~45~45~0 ~45~46~0 minecraft:fence 0
fill ~45~54~0 ~45~55~0 minecraft:fence 0
fill ~16~49~1 ~19~51~1 minecraft:wool 0
fill ~17~48~1 ~20~48~1 minecraft:wool 0
fill ~17~52~1 ~20~52~1 minecraft:wool 0
fill ~18~47~1 ~21~47~1 minecraft:wool 0
fill ~18~53~1 ~21~53~1 minecraft:wool 0
fill ~20~46~1 ~24~46~1 minecraft:wool 0
setblock ~20~49~1 minecraft:glowstone
fill ~20~54~1 ~24~54~1 minecraft:wool 0
setblock ~23~44~1 minecraft:fence 0
fill ~23~45~1 ~30~45~1 minecraft:wool 0
fill ~23~55~1 ~30~55~1 minecraft:wool 0
setblock ~23~56~1 minecraft:fence 0
setblock ~24~42~1 minecraft:trapdoor 2
setblock ~24~43~1 minecraft:trapdoor 3
setblock ~24~44~1 minecraft:log 1
setblock ~24~56~1 minecraft:glowstone
setblock ~24~57~1 minecraft:oak_stairs 2
setblock ~25~44~1 minecraft:fence 0
setblock ~25~56~1 minecraft:fence 0
setblock ~28~40~1 minecraft:trapdoor 2
fill ~28~44~1 ~40~44~1 minecraft:wool 0
fill ~28~56~1 ~40~56~1 minecraft:wool 0
setblock ~31~45~1 minecraft:glowstone
setblock ~32~39~1 minecraft:trapdoor 2
setblock ~36~39~1 minecraft:trapdoor 2
setblock ~37~45~1 minecraft:glowstone
fill ~38~45~1 ~45~45~1 minecraft:wool 0
fill ~38~55~1 ~45~55~1 minecraft:wool 0
setblock ~40~40~1 minecraft:trapdoor 2
setblock ~43~44~1 minecraft:fence 0
setblock ~43~56~1 minecraft:fence 0
setblock ~44~42~1 minecraft:trapdoor 2
setblock ~44~43~1 minecraft:trapdoor 3
setblock ~44~44~1 minecraft:log 1
fill ~44~46~1 ~48~46~1 minecraft:wool 0
fill ~44~54~1 ~48~54~1 minecraft:wool 0
setblock ~44~56~1 minecraft:glowstone
setblock ~44~57~1 minecraft:oak_stairs 2
setblock ~45~44~1 minecraft:fence 0
setblock ~45~56~1 minecraft:fence 0
fill ~47~47~1 ~50~47~1 minecraft:wool 0
fill ~47~53~1 ~50~53~1 minecraft:wool 0
fill ~48~48~1 ~51~48~1 minecraft:wool 0
setblock ~48~49~1 minecraft:glowstone
fill ~48~52~1 ~51~52~1 minecraft:wool 0
fill ~49~49~1 ~52~51~1 minecraft:wool 0
fill ~13~49~2 ~15~51~2 minecraft:wool 0
fill ~14~48~2 ~16~48~2 minecraft:wool 0
fill ~14~52~2 ~16~52~2 minecraft:wool 0
fill ~15~47~2 ~17~47~2 minecraft:wool 0
fill ~15~53~2 ~17~53~2 minecraft:wool 0
fill ~17~46~2 ~19~46~2 minecraft:wool 0
fill ~17~54~2 ~19~54~2 minecraft:wool 0
fill ~19~45~2 ~22~45~2 minecraft:wool 0
fill ~19~55~2 ~22~55~2 minecraft:wool 0
fill ~22~44~2 ~27~44~2 minecraft:wool 0
fill ~22~56~2 ~27~56~2 minecraft:wool 0
setblock ~23~43~2 minecraft:fence 0
setblock ~23~57~2 minecraft:fence 0
setblock ~24~42~2 minecraft:trapdoor 3
setblock ~24~43~2 minecraft:log 0
setblock ~24~57~2 minecraft:log 0
setblock ~24~58~2 minecraft:oak_stairs 2
setblock ~25~43~2 minecraft:fence 0
setblock ~25~57~2 minecraft:fence 0
fill ~28~43~2 ~40~43~2 minecraft:wool 0
fill ~28~57~2 ~40~57~2 minecraft:wool 0
fill ~41~44~2 ~46~44~2 minecraft:wool 0
fill ~41~56~2 ~46~56~2 minecraft:wool 0
setblock ~43~43~2 minecraft:fence 0
setblock ~43~57~2 minecraft:fence 0
setblock ~44~42~2 minecraft:trapdoor 3
setblock ~44~43~2 minecraft:log 0
setblock ~44~57~2 minecraft:log 0
setblock ~44~58~2 minecraft:oak_stairs 2
setblock ~45~43~2 minecraft:fence 0
setblock ~45~57~2 minecraft:fence 0
fill ~46~45~2 ~49~45~2 minecraft:wool 0
fill ~46~55~2 ~49~55~2 minecraft:wool 0
fill ~49~46~2 ~51~46~2 minecraft:wool 0
fill ~49~54~2 ~51~54~2 minecraft:wool 0
fill ~51~47~2 ~53~47~2 minecraft:wool 0
fill ~51~53~2 ~53~53~2 minecraft:wool 0
fill ~52~48~2 ~54~48~2 minecraft:wool 0
fill ~52~52~2 ~54~52~2 minecraft:wool 0
fill ~53~49~2 ~55~51~2 minecraft:wool 0
fill ~11~49~3 ~12~51~3 minecraft:wool 0
fill ~12~48~3 ~13~48~3 minecraft:wool 0
fill ~12~52~3 ~13~52~3 minecraft:wool 0
fill ~13~47~3 ~14~47~3 minecraft:wool 0
fill ~13~53~3 ~14~53~3 minecraft:wool 0
fill ~14~46~3 ~16~46~3 minecraft:wool 0
fill ~14~54~3 ~16~54~3 minecraft:wool 0
fill ~16~45~3 ~18~45~3 minecraft:wool 0
fill ~16~55~3 ~18~55~3 minecraft:wool 0
fill ~19~44~3 ~22~44~3 minecraft:wool 0
fill ~19~56~3 ~22~56~3 minecraft:wool 0
fill ~23~42~3 ~23~42~4 minecraft:fence 0
fill ~23~43~3 ~30~43~3 minecraft:wool 0
fill ~23~57~3 ~30~57~3 minecraft:wool 0
fill ~23~58~3 ~23~58~4 minecraft:fence 0
setblock ~24~42~3 minecraft:log 1
setblock ~24~58~3 minecraft:glowstone
setblock ~25~42~3 minecraft:fence 0
setblock ~25~58~3 minecraft:fence 0
fill ~31~42~3 ~37~42~4 minecraft:wool 0
fill ~31~58~3 ~37~58~4 minecraft:wool 0
fill ~38~43~3 ~45~43~3 minecraft:wool 0
fill ~38~57~3 ~45~57~3 minecraft:wool 0
setblock ~43~42~3 minecraft:fence 0
setblock ~43~58~3 minecraft:fence 0
setblock ~44~42~3 minecraft:log 1
setblock ~44~58~3 minecraft:glowstone
fill ~45~42~3 ~45~42~4 minecraft:fence 0
fill ~45~58~3 ~45~58~4 minecraft:fence 0
fill ~46~44~3 ~49~44~3 minecraft:wool 0
fill ~46~56~3 ~49~56~3 minecraft:wool 0
fill ~50~45~3 ~52~45~3 minecraft:wool 0
fill ~50~55~3 ~52~55~3 minecraft:wool 0
fill ~52~46~3 ~54~46~3 minecraft:wool 0
fill ~52~54~3 ~54~54~3 minecraft:wool 0
fill ~54~47~3 ~55~47~3 minecraft:wool 0
fill ~54~53~3 ~55~53~3 minecraft:wool 0
fill ~55~48~3 ~56~48~3 minecraft:wool 0
fill ~55~52~3 ~56~52~3 minecraft:wool 0
fill ~56~49~3 ~57~51~3 minecraft:wool 0
fill ~10~48~4 ~11~48~4 minecraft:wool 0
fill ~10~49~4 ~10~52~4 minecraft:wool 0
fill ~11~47~4 ~12~47~4 minecraft:wool 0
fill ~11~52~4 ~11~53~4 minecraft:wool 0
fill ~12~46~4 ~13~46~4 minecraft:wool 0
fill ~12~53~4 ~12~54~4 minecraft:wool 0
setblock ~13~54~4 minecraft:wool 0
fill ~14~45~4 ~16~45~4 minecraft:wool 0
setblock ~14~46~4 minecraft:glowstone
fill ~14~55~4 ~16~55~4 minecraft:wool 0
fill ~17~44~4 ~19~44~4 minecraft:wool 0
fill ~17~56~4 ~19~56~4 minecraft:wool 0
fill ~20~43~4 ~24~43~4 minecraft:wool 0
fill ~20~57~4 ~24~57~4 minecraft:wool 0
setblock ~24~41~4 minecraft:trapdoor 3
setblock ~24~42~4 minecraft:log 0
setblock ~24~58~4 minecraft:log 0
setblock ~24~59~4 minecraft:oak_stairs 2
fill ~25~41~4 ~25~41~12 minecraft:fence 0
fill ~25~42~4 ~30~42~5 minecraft:wool 0
fill ~25~58~4 ~30~58~5 minecraft:wool 0
fill ~25~59~4 ~25~59~12 minecraft:fence 0
fill ~38~42~4 ~43~42~5 minecraft:wool 0
fill ~38~58~4 ~43~58~5 minecraft:wool 0
fill ~43~41~4 ~43~41~12 minecraft:fence 0
fill ~43~59~4 ~43~59~12 minecraft:fence 0
setblock ~44~41~4 minecraft:trapdoor 3
setblock ~44~42~4 minecraft:log 0
fill ~44~43~4 ~48~43~4 minecraft:wool 0
fill ~44~57~4 ~48~57~4 minecraft:wool 0
setblock ~44~58~4 minecraft:log 0
setblock ~44~59~4 minecraft:oak_stairs 2
fill ~49~44~4 ~51~44~4 minecraft:wool 0
fill ~49~56~4 ~51~56~4 minecraft:wool 0
fill ~52~45~4 ~54~45~4 minecraft:wool 0
fill ~52~55~4 ~54~55~4 minecraft:wool 0
setblock ~54~46~4 minecraft:glowstone
fill ~55~46~4 ~56~46~4 minecraft:wool 0
fill ~55~54~4 ~56~54~4 minecraft:wool 0
fill ~56~47~4 ~57~47~4 minecraft:wool 0
fill ~56~53~4 ~57~53~4 minecraft:wool 0
fill ~57~48~4 ~58~48~4 minecraft:wool 0
fill ~57~52~4 ~58~52~4 minecraft:wool 0
fill ~58~49~4 ~58~51~4 minecraft:wool 0
fill ~8~50~5 ~9~50~5 minecraft:wool 0
setblock ~8~51~5 minecraft:glowstone
fill ~9~48~5 ~9~49~5 minecraft:wool 0
fill ~9~51~5 ~9~52~5 minecraft:wool 0
setblock ~10~47~5 minecraft:wool 0
setblock ~10~53~5 minecraft:wool 0
fill ~11~46~5 ~12~46~5 minecraft:wool 0
fill ~11~54~5 ~12~54~5 minecraft:wool 0
fill ~13~45~5 ~14~45~5 minecraft:wool 0
fill ~13~55~5 ~14~55~5 minecraft:wool 0
fill ~15~44~5 ~17~44~5 minecraft:wool 0
fill ~15~56~5 ~17~56~5 minecraft:wool 0
fill ~18~43~5 ~21~43~5 minecraft:wool 0
setblock ~18~44~5 minecraft:glowstone
fill ~18~57~5 ~21~57~5 minecraft:wool 0
fill ~22~42~5 ~24~42~11 minecraft:wool 0
setblock ~22~43~5 minecraft:glowstone
fill ~22~58~5 ~24~58~11 minecraft:wool 0
fill ~23~41~5 ~23~41~7 minecraft:fence 0
fill ~23~59~5 ~23~59~11 minecraft:fence 0
setblock ~24~41~5 minecraft:log 1
setblock ~24~59~5 minecraft:glowstone
fill ~31~42~5 ~32~42~5 minecraft:wool 0
fill ~31~58~5 ~32~58~5 minecraft:wool 0
fill ~33~41~5 ~35~41~11 minecraft:wool 0
setblock ~33~42~5 minecraft:glowstone
fill ~33~59~5 ~35~59~11 minecraft:wool 0
setblock ~35~42~5 minecraft:glowstone
fill ~36~42~5 ~37~42~5 minecraft:wool 0
fill ~36~58~5 ~37~58~5 minecraft:wool 0
setblock ~44~41~5 minecraft:log 1
fill ~44~42~5 ~46~42~11 minecraft:wool 0
fill ~44~58~5 ~46~58~11 minecraft:wool 0
setblock ~44~59~5 minecraft:glowstone
fill ~45~41~5 ~45~41~7 minecraft:fence 0
fill ~45~59~5 ~45~59~11 minecraft:fence 0
setblock ~46~43~5 minecraft:glowstone
fill ~47~43~5 ~50~43~5 minecraft:wool 0
fill ~47~57~5 ~50~57~5 minecraft:wool 0
setblock ~50~44~5 minecraft:glowstone
fill ~51~44~5 ~53~44~5 minecraft:wool 0
fill ~51~56~5 ~53~56~5 minecraft:wool 0
fill ~54~45~5 ~55~45~5 minecraft:wool 0
fill ~54~55~5 ~55~55~5 minecraft:wool 0
fill ~56~46~5 ~57~46~5 minecraft:wool 0
fill ~56~54~5 ~57~54~5 minecraft:wool 0
setblock ~56~55~5 minecraft:glowstone
setblock ~58~47~5 minecraft:wool 0
setblock ~58~53~5 minecraft:wool 0
fill ~59~48~5 ~59~52~5 minecraft:wool 0
setblock ~60~49~5 minecraft:glowstone
fill ~60~50~5 ~60~50~6 minecraft:wool 0
fill ~8~48~6 ~8~48~10 minecraft:wool 0
fill ~8~49~6 ~8~52~6 minecraft:wool 0
fill ~9~47~6 ~9~47~10 minecraft:wool 0
setblock ~9~48~6 minecraft:glowstone
fill ~9~53~6 ~9~53~10 minecraft:wool 0
fill ~10~46~6 ~11~46~6 minecraft:wool 0
fill ~10~54~6 ~11~54~6 minecraft:wool 0
fill ~12~45~6 ~13~45~6 minecraft:wool 0
fill ~12~55~6 ~13~55~6 minecraft:wool 0
setblock ~13~56~6 minecraft:glowstone
fill ~14~44~6 ~16~44~6 minecraft:wool 0
fill ~14~56~6 ~16~56~6 minecraft:wool 0
fill ~17~43~6 ~20~43~6 minecraft:wool 0
fill ~17~57~6 ~20~57~6 minecraft:wool 0
fill ~21~42~6 ~21~42~10 minecraft:wool 0
fill ~21~58~6 ~21~58~10 minecraft:wool 0
setblock ~24~41~6 minecraft:log 0
setblock ~24~59~6 minecraft:log 0
fill ~25~42~6 ~27~42~6 minecraft:wool 0
fill ~25~58~6 ~27~58~6 minecraft:wool 0
fill ~28~41~6 ~32~41~10 minecraft:wool 0
fill ~28~59~6 ~32~59~10 minecraft:wool 0
fill ~36~41~6 ~40~41~10 minecraft:wool 0
fill ~36~59~6 ~40~59~10 minecraft:wool 0
fill ~41~42~6 ~43~42~6 minecraft:wool 0
fill ~41~58~6 ~43~58~6 minecraft:wool 0
setblock ~44~41~6 minecraft:log 0
setblock ~44~59~6 minecraft:log 0
fill ~47~42~6 ~47~42~10 minecraft:wool 0
fill ~47~58~6 ~47~58~10 minecraft:wool 0
fill ~48~43~6 ~51~43~6 minecraft:wool 0
fill ~48~57~6 ~51~57~6 minecraft:wool 0
fill ~52~44~6 ~54~44~6 minecraft:wool 0
fill ~52~56~6 ~54~56~6 minecraft:wool 0
fill ~55~45~6 ~56~45~6 minecraft:wool 0
fill ~55~55~6 ~56~55~6 minecraft:wool 0
fill ~57~46~6 ~58~46~6 minecraft:wool 0
fill ~57~54~6 ~58~54~6 minecraft:wool 0
fill ~59~47~6 ~59~47~10 minecraft:wool 0
setblock ~59~48~6 minecraft:glowstone
fill ~59~53~6 ~59~53~10 minecraft:wool 0
fill ~60~48~6 ~60~48~10 minecraft:wool 0
setblock ~60~49~6 minecraft:wool 0
fill ~60~51~6 ~60~52~6 minecraft:wool 0
fill ~7~49~7 ~7~51~9 minecraft:wool 0
fill ~8~52~7 ~8~52~10 minecraft:wool 0
fill ~10~46~7 ~10~46~10 minecraft:wool 0
fill ~10~54~7 ~10~54~10 minecraft:wool 0
fill ~11~45~7 ~12~45~9 minecraft:wool 0
fill ~11~55~7 ~12~55~9 minecraft:wool 0
fill ~13~44~7 ~15~44~9 minecraft:wool 0
fill ~13~56~7 ~15~56~9 minecraft:wool 0
fill ~16~43~7 ~19~43~9 minecraft:wool 0
fill ~16~57~7 ~19~57~9 minecraft:wool 0
fill ~20~42~7 ~20~42~9 minecraft:wool 0
fill ~20~58~7 ~20~58~9 minecraft:wool 0
setblock ~24~38~7 minecraft:stone_brick_stairs 6
setblock ~24~39~7 minecraft:stone_brick_stairs 2
setblock ~24~41~7 minecraft:log 1
setblock ~24~59~7 minecraft:log 1
fill ~25~42~7 ~25~42~12 minecraft:wool 0
fill ~25~58~7 ~25~58~12 minecraft:wool 0
fill ~26~41~7 ~27~41~7 minecraft:wool 0
fill ~26~42~7 ~27~42~7 minecraft:glowstone
fill ~26~59~7 ~27~59~9 minecraft:wool 0
fill ~41~41~7 ~42~41~7 minecraft:wool 0
fill ~41~42~7 ~42~42~7 minecraft:glowstone
fill ~41~59~7 ~42~59~9 minecraft:wool 0
fill ~43~42~7 ~43~42~12 minecraft:wool 0
fill ~43~58~7 ~43~58~12 minecraft:wool 0
setblock ~44~38~7 minecraft:stone_brick_stairs 6
setblock ~44~39~7 minecraft:stone_brick_stairs 2
setblock ~44~41~7 minecraft:log 1
setblock ~44~59~7 minecraft:log 1
fill ~48~42~7 ~48~42~9 minecraft:wool 0
fill ~48~58~7 ~48~58~9 minecraft:wool 0
fill ~49~43~7 ~52~43~9 minecraft:wool 0
fill ~49~57~7 ~52~57~9 minecraft:wool 0
fill ~53~44~7 ~55~44~9 minecraft:wool 0
fill ~53~56~7 ~55~56~9 minecraft:wool 0
fill ~56~45~7 ~57~45~9 minecraft:wool 0
fill ~56~55~7 ~57~55~9 minecraft:wool 0
fill ~58~46~7 ~58~46~10 minecraft:wool 0
fill ~58~54~7 ~58~54~10 minecraft:wool 0
fill ~60~52~7 ~60~52~10 minecraft:wool 0
fill ~61~49~7 ~61~51~9 minecraft:wool 0
setblock ~8~47~8 minecraft:wool 0
setblock ~8~53~8 minecraft:wool 0
setblock ~23~34~8 minecraft:stone_brick_stairs 6
setblock ~23~35~8 minecraft:stone_brick_stairs 2
setblock ~23~40~8 minecraft:stone_brick_stairs 4
setblock ~23~41~8 minecraft:stonebrick 0
setblock ~24~37~8 minecraft:stone_brick_stairs 3
setblock ~24~39~8 minecraft:stone_brick_stairs 1
fill ~24~40~8 ~24~40~9 minecraft:stone_block_slab 5
setblock ~24~41~8 minecraft:log 0
setblock ~24~59~8 minecraft:log 0
setblock ~25~39~8 minecraft:stone_brick_stairs 0
setblock ~26~40~8 minecraft:stone_brick_stairs 5
fill ~26~41~8 ~26~41~9 minecraft:wool 0
fill ~26~42~8 ~26~42~9 minecraft:glowstone
setblock ~42~40~8 minecraft:stone_brick_stairs 4
fill ~42~41~8 ~42~41~9 minecraft:wool 0
fill ~42~42~8 ~42~42~9 minecraft:glowstone
setblock ~43~39~8 minecraft:stone_brick_stairs 1
setblock ~44~37~8 minecraft:stone_brick_stairs 3
setblock ~44~39~8 minecraft:stone_brick_stairs 0
fill ~44~40~8 ~44~40~9 minecraft:stone_block_slab 5
setblock ~44~41~8 minecraft:log 0
setblock ~44~59~8 minecraft:log 0
setblock ~45~34~8 minecraft:stone_brick_stairs 6
setblock ~45~35~8 minecraft:stone_brick_stairs 2
setblock ~45~40~8 minecraft:stone_brick_stairs 5
setblock ~45~41~8 minecraft:stonebrick 0
setblock ~60~47~8 minecraft:wool 0
setblock ~60~53~8 minecraft:wool 0
setblock ~22~36~9 minecraft:stone_brick_stairs 4
setblock ~22~37~9 minecraft:stone_brick_stairs 0
setblock ~23~33~9 minecraft:stone_brick_stairs 3
setblock ~23~35~9 minecraft:stone_brick_stairs 1
fill ~23~36~9 ~23~36~10 minecraft:stone_block_slab 5
fill ~23~38~9 ~24~38~9 minecraft:stone_block_slab 5
fill ~23~41~9 ~23~41~11 minecraft:fence 0
setblock ~24~35~9 minecraft:stone_brick_stairs 0
setblock ~24~37~9 minecraft:stone_brick_stairs 2
setblock ~24~41~9 minecraft:log 1
setblock ~24~59~9 minecraft:log 1
setblock ~25~36~9 minecraft:stone_brick_stairs 5
setblock ~25~37~9 minecraft:stone_brick_stairs 1
setblock ~27~41~9 minecraft:wool 0
setblock ~27~42~9 minecraft:glowstone
setblock ~41~41~9 minecraft:wool 0
setblock ~41~42~9 minecraft:glowstone
setblock ~43~36~9 minecraft:stone_brick_stairs 4
setblock ~43~37~9 minecraft:stone_brick_stairs 0
setblock ~44~35~9 minecraft:stone_brick_stairs 1
setblock ~44~37~9 minecraft:stone_brick_stairs 2
fill ~44~38~9 ~45~38~9 minecraft:stone_block_slab 5
setblock ~44~41~9 minecraft:log 1
setblock ~44~59~9 minecraft:log 1
setblock ~45~33~9 minecraft:stone_brick_stairs 3
setblock ~45~35~9 minecraft:stone_brick_stairs 0
fill ~45~36~9 ~45~36~10 minecraft:stone_block_slab 5
fill ~45~41~9 ~45~41~11 minecraft:fence 0
setblock ~46~36~9 minecraft:stone_brick_stairs 5
setblock ~46~37~9 minecraft:stone_brick_stairs 1
fill ~8~49~10 ~8~51~10 minecraft:wool 0
setblock ~9~48~10 minecraft:glowstone
fill ~11~46~10 ~11~46~11 minecraft:wool 0
fill ~11~54~10 ~11~54~11 minecraft:wool 0
fill ~12~45~10 ~13~45~10 minecraft:wool 0
fill ~12~55~10 ~13~55~10 minecraft:wool 0
setblock ~13~56~10 minecraft:glowstone
fill ~14~44~10 ~16~44~10 minecraft:wool 0
fill ~14~56~10 ~16~56~10 minecraft:wool 0
fill ~17~43~10 ~20~43~10 minecraft:wool 0
fill ~17~57~10 ~20~57~10 minecraft:wool 0
fill ~22~34~10 ~23~34~10 minecraft:stone_brick_stairs 3
setblock ~23~33~10 minecraft:stone_brick_stairs 2
setblock ~24~38~10 minecraft:stone_brick_stairs 7
setblock ~24~39~10 minecraft:stone_brick_stairs 3
setblock ~24~41~10 minecraft:log 0
setblock ~24~59~10 minecraft:log 0
fill ~26~42~10 ~27~42~12 minecraft:wool 0
fill ~26~58~10 ~27~58~12 minecraft:wool 0
fill ~41~42~10 ~42~42~12 minecraft:wool 0
fill ~41~58~10 ~42~58~12 minecraft:wool 0
setblock ~44~38~10 minecraft:stone_brick_stairs 7
setblock ~44~39~10 minecraft:stone_brick_stairs 3
setblock ~44~41~10 minecraft:log 0
setblock ~44~59~10 minecraft:log 0
setblock ~45~33~10 minecraft:stone_brick_stairs 2
fill ~45~34~10 ~46~34~10 minecraft:stone_brick_stairs 3
fill ~48~43~10 ~51~43~10 minecraft:wool 0
fill ~48~57~10 ~51~57~10 minecraft:wool 0
fill ~52~44~10 ~54~44~10 minecraft:wool 0
fill ~52~56~10 ~54~56~10 minecraft:wool 0
fill ~55~45~10 ~56~45~10 minecraft:wool 0
fill ~55~55~10 ~56~55~10 minecraft:wool 0
fill ~57~46~10 ~57~46~11 minecraft:wool 0
fill ~57~54~10 ~57~54~11 minecraft:wool 0
setblock ~59~48~10 minecraft:glowstone
fill ~60~49~10 ~60~51~10 minecraft:wool 0
fill ~8~50~11 ~9~50~11 minecraft:wool 0
setblock ~8~51~11 minecraft:glowstone
fill ~9~48~11 ~9~49~11 minecraft:wool 0
fill ~9~51~11 ~9~52~11 minecraft:wool 0
setblock ~10~47~11 minecraft:wool 0
setblock ~10~53~11 minecraft:wool 0
fill ~12~46~11 ~12~46~12 minecraft:wool 0
fill ~12~54~11 ~12~54~12 minecraft:wool 0
fill ~13~45~11 ~14~45~11 minecraft:wool 0
fill ~13~55~11 ~14~55~11 minecraft:wool 0
fill ~15~44~11 ~17~44~11 minecraft:wool 0
fill ~15~56~11 ~17~56~11 minecraft:wool 0
fill ~18~43~11 ~21~43~11 minecraft:wool 0
setblock ~18~44~11 minecraft:glowstone
fill ~18~57~11 ~21~57~11 minecraft:wool 0
setblock ~21~33~11 minecraft:stone_brick_stairs 3
setblock ~22~31~11 minecraft:stone_brick_stairs 6
setblock ~22~32~11 minecraft:stone_brick_stairs 2
setblock ~22~43~11 minecraft:glowstone
setblock ~23~34~11 minecraft:stone_brick_stairs 7
setblock ~23~35~11 minecraft:stone_brick_stairs 3
setblock ~24~33~11 minecraft:stone_brick_stairs 3
setblock ~24~41~11 minecraft:log 1
setblock ~24~59~11 minecraft:glowstone
fill ~28~42~11 ~32~42~12 minecraft:wool 0
fill ~28~58~11 ~32~58~12 minecraft:wool 0
setblock ~33~42~11 minecraft:glowstone
setblock ~35~42~11 minecraft:glowstone
fill ~36~42~11 ~40~42~12 minecraft:wool 0
fill ~36~58~11 ~40~58~12 minecraft:wool 0
setblock ~44~33~11 minecraft:stone_brick_stairs 3
setblock ~44~41~11 minecraft:log 1
setblock ~44~59~11 minecraft:glowstone
setblock ~45~34~11 minecraft:stone_brick_stairs 7
setblock ~45~35~11 minecraft:stone_brick_stairs 3
setblock ~46~31~11 minecraft:stone_brick_stairs 6
setblock ~46~32~11 minecraft:stone_brick_stairs 2
setblock ~46~43~11 minecraft:glowstone
setblock ~47~33~11 minecraft:stone_brick_stairs 3
fill ~47~43~11 ~50~43~11 minecraft:wool 0
fill ~47~57~11 ~50~57~11 minecraft:wool 0
setblock ~50~44~11 minecraft:glowstone
fill ~51~44~11 ~53~44~11 minecraft:wool 0
fill ~51~56~11 ~53~56~11 minecraft:wool 0
fill ~54~45~11 ~55~45~11 minecraft:wool 0
fill ~54~55~11 ~55~55~11 minecraft:wool 0
fill ~56~46~11 ~56~46~12 minecraft:wool 0
fill ~56~54~11 ~56~54~12 minecraft:wool 0
setblock ~56~55~11 minecraft:glowstone
setblock ~58~47~11 minecraft:wool 0
setblock ~58~53~11 minecraft:wool 0
fill ~59~48~11 ~59~52~11 minecraft:wool 0
setblock ~60~49~11 minecraft:glowstone
setblock ~60~50~11 minecraft:wool 0
fill ~10~48~12 ~11~48~12 minecraft:wool 0
fill ~10~49~12 ~10~52~12 minecraft:wool 0
fill ~11~47~12 ~12~47~12 minecraft:wool 0
fill ~11~52~12 ~11~53~12 minecraft:wool 0
setblock ~12~53~12 minecraft:wool 0
setblock ~13~46~12 minecraft:wool 0
setblock ~13~54~12 minecraft:wool 0
fill ~14~45~12 ~16~45~12 minecraft:wool 0
setblock ~14~46~12 minecraft:glowstone
fill ~14~55~12 ~16~55~12 minecraft:wool 0
fill ~17~44~12 ~19~44~12 minecraft:wool 0
fill ~17~56~12 ~19~56~12 minecraft:wool 0
fill ~20~43~12 ~24~43~12 minecraft:wool 0
fill ~20~57~12 ~24~57~12 minecraft:wool 0
setblock ~22~30~12 minecraft:stone_brick_stairs 3
fill ~22~32~12 ~23~32~12 minecraft:stone_brick_stairs 3
fill ~22~33~12 ~22~33~13 minecraft:stone_block_slab 5
fill ~23~42~12 ~23~42~13 minecraft:fence 0
fill ~23~58~12 ~23~58~13 minecraft:fence 0
setblock ~24~41~12 minecraft:trapdoor 2
setblock ~24~42~12 minecraft:log 0
setblock ~24~58~12 minecraft:log 0
setblock ~24~59~12 minecraft:oak_stairs 3
setblock ~28~37~12 minecraft:trapdoor 3
setblock ~32~36~12 minecraft:trapdoor 3
fill ~33~42~12 ~35~42~13 minecraft:wool 0
fill ~33~58~12 ~35~58~13 minecraft:wool 0
setblock ~36~37~12 minecraft:trapdoor 3
setblock ~40~38~12 minecraft:trapdoor 3
setblock ~44~41~12 minecraft:trapdoor 2
setblock ~44~42~12 minecraft:log 0
fill ~44~43~12 ~48~43~12 minecraft:wool 0
fill ~44~57~12 ~48~57~12 minecraft:wool 0
setblock ~44~58~12 minecraft:log 0
setblock ~44~59~12 minecraft:oak_stairs 3
fill ~45~32~12 ~46~32~12 minecraft:stone_brick_stairs 3
fill ~45~42~12 ~45~42~13 minecraft:fence 0
fill ~45~58~12 ~45~58~13 minecraft:fence 0
setblock ~46~30~12 minecraft:stone_brick_stairs 3
fill ~46~33~12 ~46~33~13 minecraft:stone_block_slab 5
fill ~49~44~12 ~51~44~12 minecraft:wool 0
fill ~49~56~12 ~51~56~12 minecraft:wool 0
fill ~52~45~12 ~54~45~12 minecraft:wool 0
fill ~52~55~12 ~54~55~12 minecraft:wool 0
setblock ~54~46~12 minecraft:glowstone
setblock ~55~46~12 minecraft:wool 0
setblock ~55~54~12 minecraft:wool 0
fill ~56~47~12 ~57~47~12 minecraft:wool 0
fill ~56~53~12 ~57~53~12 minecraft:wool 0
fill ~57~48~12 ~58~48~12 minecraft:wool 0
fill ~57~52~12 ~58~52~12 minecraft:wool 0
fill ~58~49~12 ~58~51~12 minecraft:wool 0
fill ~11~49~13 ~12~51~13 minecraft:wool 0
fill ~12~48~13 ~13~48~13 minecraft:wool 0
fill ~12~52~13 ~13~52~13 minecraft:wool 0
fill ~13~47~13 ~14~47~13 minecraft:wool 0
fill ~13~53~13 ~14~53~13 minecraft:wool 0
fill ~14~46~13 ~16~46~13 minecraft:wool 0
fill ~14~54~13 ~16~54~13 minecraft:wool 0
fill ~16~45~13 ~18~45~13 minecraft:wool 0
fill ~16~55~13 ~18~55~13 minecraft:wool 0
fill ~19~44~13 ~22~44~13 minecraft:wool 0
fill ~19~56~13 ~22~56~13 minecraft:wool 0
fill ~21~31~13 ~23~31~13 minecraft:stone_brick_stairs 2
setblock ~22~30~13 minecraft:stone_brick_stairs 2
fill ~23~43~13 ~30~43~13 minecraft:wool 0
fill ~23~57~13 ~30~57~13 minecraft:wool 0
setblock ~24~42~13 minecraft:log 1
setblock ~24~58~13 minecraft:glowstone
fill ~25~42~13 ~26~42~13 minecraft:fence 0
setblock ~25~58~13 minecraft:fence 0
fill ~26~41~13 ~28~41~13 minecraft:fence 0
setblock ~27~37~13 minecraft:trapdoor 1
setblock ~28~37~13 minecraft:glowstone
fill ~28~38~13 ~28~40~13 minecraft:fence 0
setblock ~29~37~13 minecraft:trapdoor 0
fill ~29~40~13 ~31~40~13 minecraft:fence 0
setblock ~31~36~13 minecraft:trapdoor 1
fill ~31~39~13 ~37~39~13 minecraft:fence 0
fill ~31~42~13 ~32~42~13 minecraft:wool 0
fill ~31~58~13 ~32~58~13 minecraft:wool 0
setblock ~32~36~13 minecraft:glowstone
fill ~32~37~13 ~32~38~13 minecraft:fence 0
setblock ~33~36~13 minecraft:trapdoor 0
setblock ~35~37~13 minecraft:trapdoor 1
setblock ~36~37~13 minecraft:glowstone
setblock ~36~38~13 minecraft:fence 0
fill ~36~42~13 ~37~42~13 minecraft:wool 0
fill ~36~58~13 ~37~58~13 minecraft:wool 0
setblock ~37~37~13 minecraft:trapdoor 0
fill ~37~40~13 ~40~40~13 minecraft:fence 0
fill ~38~43~13 ~45~43~13 minecraft:wool 0
fill ~38~57~13 ~45~57~13 minecraft:wool 0
setblock ~39~38~13 minecraft:trapdoor 1
setblock ~40~38~13 minecraft:glowstone
setblock ~40~39~13 minecraft:fence 0
fill ~40~41~13 ~42~41~13 minecraft:fence 0
setblock ~41~38~13 minecraft:trapdoor 0
fill ~42~42~13 ~43~42~13 minecraft:fence 0
setblock ~43~58~13 minecraft:fence 0
setblock ~44~42~13 minecraft:log 1
setblock ~44~58~13 minecraft:glowstone
fill ~45~31~13 ~47~31~13 minecraft:stone_brick_stairs 2
setblock ~46~30~13 minecraft:stone_brick_stairs 2
fill ~46~44~13 ~49~44~13 minecraft:wool 0
fill ~46~56~13 ~49~56~13 minecraft:wool 0
fill ~50~45~13 ~52~45~13 minecraft:wool 0
fill ~50~55~13 ~52~55~13 minecraft:wool 0
fill ~52~46~13 ~54~46~13 minecraft:wool 0
fill ~52~54~13 ~54~54~13 minecraft:wool 0
fill ~54~47~13 ~55~47~13 minecraft:wool 0
fill ~54~53~13 ~55~53~13 minecraft:wool 0
fill ~55~48~13 ~56~48~13 minecraft:wool 0
fill ~55~52~13 ~56~52~13 minecraft:wool 0
fill ~56~49~13 ~57~51~13 minecraft:wool 0
fill ~13~49~14 ~15~51~14 minecraft:wool 0
fill ~14~48~14 ~16~48~14 minecraft:wool 0
fill ~14~52~14 ~16~52~14 minecraft:wool 0
fill ~15~47~14 ~17~47~14 minecraft:wool 0
fill ~15~53~14 ~17~53~14 minecraft:wool 0
fill ~17~46~14 ~19~46~14 minecraft:wool 0
fill ~17~54~14 ~19~54~14 minecraft:wool 0
fill ~17~56~14 ~19~56~14 minecraft:iron_bars
fill ~19~45~14 ~22~45~14 minecraft:wool 0
fill ~19~55~14 ~22~55~14 minecraft:wool 0
fill ~19~57~14 ~21~57~14 minecraft:iron_bars
setblock ~20~31~14 minecraft:stone_brick_stairs 0
setblock ~22~31~14 minecraft:stone_brick_stairs 7
setblock ~22~32~14 minecraft:stone_brick_stairs 3
fill ~22~44~14 ~27~44~14 minecraft:wool 0
fill ~22~56~14 ~27~56~14 minecraft:wool 0
setblock ~23~43~14 minecraft:fence 0
setblock ~23~57~14 minecraft:fence 0
setblock ~24~31~14 minecraft:stone_brick_stairs 1
setblock ~24~42~14 minecraft:trapdoor 2
setblock ~24~43~14 minecraft:log 0
setblock ~24~57~14 minecraft:log 0
setblock ~24~58~14 minecraft:oak_stairs 3
setblock ~25~43~14 minecraft:fence 0
setblock ~25~57~14 minecraft:fence 0
setblock ~28~37~14 minecraft:trapdoor 2
fill ~28~43~14 ~40~43~14 minecraft:wool 0
fill ~28~57~14 ~40~57~14 minecraft:wool 0
setblock ~32~36~14 minecraft:trapdoor 2
setblock ~36~37~14 minecraft:trapdoor 2
fill ~36~38~14 ~38~38~14 minecraft:iron_bars
fill ~38~39~14 ~39~39~14 minecraft:iron_bars
setblock ~40~38~14 minecraft:trapdoor 2
setblock ~40~39~14 minecraft:wool 0
setblock ~41~40~14 minecraft:wool 0
fill ~41~44~14 ~46~44~14 minecraft:wool 0
fill ~41~56~14 ~46~56~14 minecraft:wool 0
setblock ~43~43~14 minecraft:fence 0
setblock ~43~57~14 minecraft:fence 0
setblock ~44~31~14 minecraft:stone_brick_stairs 0
setblock ~44~42~14 minecraft:trapdoor 2
setblock ~44~43~14 minecraft:log 0
setblock ~44~57~14 minecraft:log 0
setblock ~44~58~14 minecraft:oak_stairs 3
setblock ~45~43~14 minecraft:fence 0
setblock ~45~57~14 minecraft:fence 0
setblock ~46~31~14 minecraft:stone_brick_stairs 7
setblock ~46~32~14 minecraft:stone_brick_stairs 3
fill ~46~45~14 ~49~45~14 minecraft:wool 0
fill ~46~55~14 ~49~55~14 minecraft:wool 0
setblock ~48~31~14 minecraft:stone_brick_stairs 1
fill ~49~46~14 ~51~46~14 minecraft:wool 0
fill ~49~54~14 ~51~54~14 minecraft:wool 0
fill ~51~47~14 ~53~47~14 minecraft:wool 0
fill ~51~53~14 ~53~53~14 minecraft:wool 0
fill ~52~48~14 ~54~48~14 minecraft:wool 0
fill ~52~52~14 ~54~52~14 minecraft:wool 0
fill ~53~49~14 ~55~51~14 minecraft:wool 0
fill ~13~35~15 ~15~35~15 minecraft:iron_bars
setblock ~14~34~15 minecraft:stone_block_slab 0
setblock ~15~33~15 minecraft:trapdoor 3
fill ~15~36~15 ~17~36~15 minecraft:iron_bars
setblock ~16~32~15 minecraft:stone_block_slab 3
setblock ~16~34~15 minecraft:stone_block_slab 0
fill ~16~49~15 ~19~51~15 minecraft:wool 0
setblock ~17~31~15 minecraft:fence 0
setblock ~17~32~15 minecraft:stone_stairs 2
setblock ~17~33~15 minecraft:trapdoor 3
fill ~17~37~15 ~19~37~15 minecraft:iron_bars
fill ~17~48~15 ~20~48~15 minecraft:wool 0
fill ~17~52~15 ~20~52~15 minecraft:wool 0
setblock ~18~32~15 minecraft:stone_block_slab 3
setblock ~18~34~15 minecraft:stone_block_slab 0
fill ~18~47~15 ~21~47~15 minecraft:wool 0
fill ~18~53~15 ~21~53~15 minecraft:wool 0
setblock ~19~30~15 minecraft:stone_block_slab 0
setblock ~19~31~15 minecraft:fence 0
setblock ~19~32~15 minecraft:stone_stairs 2
setblock ~19~33~15 minecraft:trapdoor 3
fill ~19~38~15 ~21~38~15 minecraft:iron_bars
setblock ~20~31~15 minecraft:stonebrick 0
setblock ~20~32~15 minecraft:stone_block_slab 3
setblock ~20~34~15 minecraft:stone_block_slab 0
fill ~20~46~15 ~24~46~15 minecraft:wool 0
setblock ~20~49~15 minecraft:glowstone
fill ~20~54~15 ~24~54~15 minecraft:wool 0
setblock ~21~30~15 minecraft:stone_block_slab 0
setblock ~21~31~15 minecraft:fence 0
setblock ~21~32~15 minecraft:stone_stairs 2
setblock ~21~33~15 minecraft:trapdoor 3
setblock ~21~37~15 minecraft:torch 4
fill ~21~39~15 ~23~39~15 minecraft:iron_bars
fill ~21~58~15 ~23~58~15 minecraft:iron_bars
setblock ~22~32~15 minecraft:stone_block_slab 3
setblock ~22~34~15 minecraft:stone_block_slab 0
setblock ~23~30~15 minecraft:stone_block_slab 0
setblock ~23~31~15 minecraft:stonebrick 0
setblock ~23~32~15 minecraft:stone_stairs 2
setblock ~23~33~15 minecraft:trapdoor 3
fill ~23~40~15 ~24~40~15 minecraft:iron_bars
setblock ~23~44~15 minecraft:fence 0
fill ~23~45~15 ~30~45~15 minecraft:wool 0
fill ~23~55~15 ~30~55~15 minecraft:wool 0
setblock ~23~56~15 minecraft:fence 0
setblock ~24~32~15 minecraft:stone_block_slab 3
setblock ~24~34~15 minecraft:stone_block_slab 0
setblock ~24~43~15 minecraft:trapdoor 2
setblock ~24~44~15 minecraft:log 1
setblock ~24~56~15 minecraft:glowstone
setblock ~24~57~15 minecraft:oak_stairs 3
setblock ~25~30~15 minecraft:stone_block_slab 0
setblock ~25~31~15 minecraft:fence 0
setblock ~25~32~15 minecraft:stone_stairs 2
setblock ~25~33~15 minecraft:trapdoor 3
setblock ~25~40~15 minecraft:wool 0
setblock ~25~44~15 minecraft:fence 0
setblock ~25~56~15 minecraft:fence 0
setblock ~26~32~15 minecraft:stone_block_slab 3
setblock ~27~30~15 minecraft:stone_block_slab 0
setblock ~27~31~15 minecraft:stone_stairs 1
setblock ~28~31~15 minecraft:stone_block_slab 3
fill ~28~44~15 ~40~44~15 minecraft:wool 0
fill ~28~56~15 ~40~56~15 minecraft:wool 0
setblock ~29~30~15 minecraft:stone_block_slab 0
setblock ~29~31~15 minecraft:stone_stairs 2
setblock ~30~31~15 minecraft:stone_block_slab 3
setblock ~31~30~15 minecraft:stone_block_slab 0
setblock ~31~31~15 minecraft:stone_stairs 2
setblock ~31~45~15 minecraft:glowstone
setblock ~32~31~15 minecraft:stone_block_slab 3
fill ~32~36~15 ~34~36~15 minecraft:iron_bars
fill ~32~57~15 ~34~57~15 minecraft:iron_bars
setblock ~33~31~15 minecraft:stone_stairs 2
fill ~34~26~15 ~35~26~15 minecraft:ladder 2
fill ~34~28~15 ~35~28~15 minecraft:ladder 2
fill ~34~30~15 ~35~30~15 minecraft:ladder 2
fill ~34~37~15 ~36~37~15 minecraft:iron_bars
fill ~34~58~15 ~36~58~15 minecraft:iron_bars
setblock ~36~31~15 minecraft:stone_stairs 2
setblock ~37~31~15 minecraft:stone_block_slab 3
setblock ~37~45~15 minecraft:glowstone
setblock ~38~30~15 minecraft:stone_block_slab 0
setblock ~38~31~15 minecraft:stone_stairs 2
fill ~38~45~15 ~45~45~15 minecraft:wool 0
fill ~38~55~15 ~45~55~15 minecraft:wool 0
setblock ~39~31~15 minecraft:stone_block_slab 3
setblock ~40~30~15 minecraft:stone_block_slab 0
setblock ~40~31~15 minecraft:stone_stairs 2
setblock ~41~31~15 minecraft:stone_block_slab 3
setblock ~41~39~15 minecraft:wool 0
setblock ~42~30~15 minecraft:stone_block_slab 0
setblock ~42~31~15 minecraft:stone_stairs 2
fill ~42~40~15 ~42~40~16 minecraft:wool 0
setblock ~42~41~15 minecraft:wool 0
setblock ~43~31~15 minecraft:stone_block_slab 3
setblock ~43~44~15 minecraft:fence 0
setblock ~43~56~15 minecraft:fence 0
setblock ~44~30~15 minecraft:stone_block_slab 0
setblock ~44~31~15 minecraft:stonebrick 0
setblock ~44~43~15 minecraft:trapdoor 2
setblock ~44~44~15 minecraft:log 1
fill ~44~46~15 ~48~46~15 minecraft:wool 0
fill ~44~54~15 ~48~54~15 minecraft:wool 0
setblock ~44~56~15 minecraft:glowstone
setblock ~44~57~15 minecraft:oak_stairs 3
fill ~45~31~15 ~46~31~15 minecraft:stone_block_slab 3
setblock ~45~32~15 minecraft:stone_stairs 0
setblock ~45~44~15 minecraft:fence 0
setblock ~45~56~15 minecraft:fence 0
setblock ~46~30~15 minecraft:stone_block_slab 0
setblock ~46~32~15 minecraft:fence 0
setblock ~46~33~15 minecraft:stone_stairs 2
setblock ~47~33~15 minecraft:stone_block_slab 3
setblock ~47~35~15 minecraft:stone_block_slab 0
fill ~47~47~15 ~50~47~15 minecraft:wool 0
fill ~47~53~15 ~50~53~15 minecraft:wool 0
setblock ~48~31~15 minecraft:stonebrick 0
setblock ~48~32~15 minecraft:fence 0
setblock ~48~33~15 minecraft:stone_stairs 2
setblock ~48~34~15 minecraft:trapdoor 3
fill ~48~48~15 ~51~48~15 minecraft:wool 0
setblock ~48~49~15 minecraft:glowstone
fill ~48~52~15 ~51~52~15 minecraft:wool 0
fill ~49~31~15 ~50~31~15 minecraft:stone_block_slab 3
setblock ~49~33~15 minecraft:stone_block_slab 3
setblock ~49~35~15 minecraft:stone_block_slab 0
fill ~49~49~15 ~52~51~15 minecraft:wool 0
setblock ~50~32~15 minecraft:fence 0
setblock ~50~33~15 minecraft:stone_stairs 2
setblock ~50~34~15 minecraft:trapdoor 3
setblock ~51~33~15 minecraft:stone_block_slab 3
setblock ~51~35~15 minecraft:stone_block_slab 0
fill ~51~37~15 ~52~37~15 minecraft:iron_bars
setblock ~52~33~15 minecraft:stone_stairs 2
setblock ~52~34~15 minecraft:trapdoor 3
fill ~11~35~16 ~11~36~16 minecraft:stone_block_slab 3
setblock ~11~37~16 minecraft:trapdoor 3
setblock ~12~32~16 minecraft:stone_block_slab 3
setblock ~12~33~16 minecraft:trapdoor 3
fill ~12~34~16 ~13~34~16 minecraft:stone_block_slab 0
fill ~12~35~16 ~12~36~16 minecraft:stone_stairs 2
setblock ~13~32~16 minecraft:stone_stairs 2
fill ~13~35~16 ~13~36~16 minecraft:stone_block_slab 3
setblock ~13~37~16 minecraft:trapdoor 3
setblock ~14~32~16 minecraft:stone_block_slab 3
setblock ~14~33~16 minecraft:double_stone_block_slab 0
fill ~14~34~16 ~25~34~16 minecraft:log 0
fill ~14~35~16 ~14~36~16 minecraft:stone_stairs 2
setblock ~15~31~16 minecraft:fence 0
setblock ~15~32~16 minecraft:cobblestone
fill ~15~33~16 ~15~33~17 minecraft:planks 0
fill ~15~35~16 ~15~36~16 minecraft:stone_block_slab 3
setblock ~15~37~16 minecraft:trapdoor 3
setblock ~16~30~16 minecraft:oak_stairs 4
setblock ~16~31~16 minecraft:oak_stairs 2
setblock ~16~32~16 minecraft:log 1
setblock ~16~33~16 minecraft:glass_pane
fill ~16~35~16 ~16~36~16 minecraft:stone_stairs 2
setblock ~17~30~16 minecraft:stone_block_slab 0
fill ~17~31~16 ~17~31~30 minecraft:planks 0
fill ~17~32~16 ~17~33~16 minecraft:planks 0
fill ~17~35~16 ~17~36~16 minecraft:stone_block_slab 3
setblock ~17~37~16 minecraft:trapdoor 3
setblock ~18~28~16 minecraft:nether_brick_fence
fill ~18~29~16 ~18~29~17 minecraft:planks 0
fill ~18~30~16 ~32~30~16 minecraft:planks 0
setblock ~18~31~16 minecraft:oak_stairs 2
setblock ~18~32~16 minecraft:log 1
setblock ~18~33~16 minecraft:glass_pane
fill ~18~35~16 ~18~36~16 minecraft:stone_stairs 2
setblock ~19~28~16 minecraft:dispenser 2
setblock ~19~29~16 minecraft:glass_pane
fill ~19~31~16 ~19~31~30 minecraft:planks 0
setblock ~19~32~16 minecraft:planks 0
setblock ~19~33~16 minecraft:double_stone_block_slab 0
fill ~19~35~16 ~19~36~16 minecraft:stone_block_slab 3
setblock ~19~37~16 minecraft:trapdoor 3
setblock ~20~28~16 minecraft:nether_brick_fence
setblock ~20~29~16 minecraft:planks 0
setblock ~20~31~16 minecraft:oak_stairs 2
setblock ~20~32~16 minecraft:log 1
setblock ~20~33~16 minecraft:glass_pane
fill ~20~35~16 ~20~36~16 minecraft:stone_stairs 2
setblock ~20~38~16 minecraft:trapdoor 1
setblock ~20~39~16 minecraft:nether_brick_fence
fill ~20~49~16 ~25~51~16 minecraft:wool 0
setblock ~21~28~16 minecraft:dispenser 2
setblock ~21~29~16 minecraft:glass_pane
fill ~21~31~16 ~21~31~20 minecraft:planks 0
fill ~21~32~16 ~21~33~16 minecraft:planks 0
fill ~21~35~16 ~21~38~16 minecraft:log 0
setblock ~21~39~16 minecraft:log 1
fill ~21~40~16 ~21~40~17 minecraft:stone_block_slab 3
fill ~21~48~16 ~27~48~16 minecraft:wool 0
fill ~21~52~16 ~27~52~16 minecraft:wool 0
setblock ~22~28~16 minecraft:nether_brick_fence
setblock ~22~29~16 minecraft:planks 0
setblock ~22~31~16 minecraft:oak_stairs 2
setblock ~22~32~16 minecraft:log 1
setblock ~22~33~16 minecraft:glass_pane
fill ~22~35~16 ~22~36~16 minecraft:stone_stairs 2
setblock ~22~38~16 minecraft:trapdoor 0
setblock ~22~39~16 minecraft:nether_brick_fence
setblock ~22~40~16 minecraft:torch 5
fill ~22~47~16 ~32~47~16 minecraft:wool 0
fill ~22~53~16 ~32~53~16 minecraft:wool 0
setblock ~23~28~16 minecraft:dispenser 2
setblock ~23~29~16 minecraft:glass_pane
fill ~23~31~16 ~23~31~21 minecraft:planks 0
fill ~23~32~16 ~23~33~16 minecraft:planks 0
fill ~23~35~16 ~23~36~16 minecraft:stone_block_slab 3
fill ~23~45~16 ~23~46~16 minecraft:fence 0
fill ~23~54~16 ~23~55~16 minecraft:fence 0
fill ~23~59~16 ~25~59~16 minecraft:iron_bars
setblock ~24~28~16 minecraft:nether_brick_fence
setblock ~24~29~16 minecraft:planks 0
setblock ~24~31~16 minecraft:oak_stairs 2
setblock ~24~32~16 minecraft:log 1
setblock ~24~33~16 minecraft:glass_pane
setblock ~24~35~16 minecraft:stone_stairs 2
setblock ~24~36~16 minecraft:stone_block_slab 3
setblock ~24~44~16 minecraft:trapdoor 2
setblock ~24~45~16 minecraft:log 0
setblock ~24~46~16 minecraft:log 1
setblock ~24~54~16 minecraft:glowstone
setblock ~24~55~16 minecraft:log 0
setblock ~24~56~16 minecraft:oak_stairs 3
setblock ~25~28~16 minecraft:dispenser 2
setblock ~25~29~16 minecraft:glass_pane
fill ~25~31~16 ~25~31~19 minecraft:planks 0
fill ~25~32~16 ~25~33~18 minecraft:planks 0
setblock ~25~35~16 minecraft:stone_stairs 1
setblock ~25~45~16 minecraft:fence 0
fill ~25~46~16 ~43~46~16 minecraft:wool 0
fill ~25~54~16 ~43~54~16 minecraft:wool 0
setblock ~25~55~16 minecraft:fence 0
setblock ~25~58~16 minecraft:wool 0
setblock ~26~28~16 minecraft:nether_brick_fence
setblock ~26~29~16 minecraft:planks 0
setblock ~26~31~16 minecraft:oak_stairs 2
fill ~26~32~16 ~27~32~16 minecraft:log 0
setblock ~26~33~16 minecraft:log 0
setblock ~26~34~16 minecraft:stone_stairs 1
fill ~26~41~16 ~26~42~17 minecraft:wool 0
fill ~26~43~16 ~26~44~16 minecraft:wool 0
fill ~26~56~16 ~26~57~16 minecraft:wool 0
setblock ~27~28~16 minecraft:dispenser 2
setblock ~27~29~16 minecraft:glass_pane
fill ~27~31~16 ~32~31~16 minecraft:log 0
setblock ~27~33~16 minecraft:stone_stairs 1
setblock ~27~44~16 minecraft:wool 0
setblock ~28~28~16 minecraft:nether_brick_fence
setblock ~28~29~16 minecraft:planks 0
fill ~28~32~16 ~32~32~16 minecraft:fence 0
fill ~28~33~16 ~32~33~16 minecraft:stone_block_slab 3
fill ~28~34~16 ~30~34~16 minecraft:iron_bars
setblock ~28~48~16 minecraft:glowstone
setblock ~29~28~16 minecraft:dispenser 2
setblock ~29~29~16 minecraft:glass_pane
setblock ~30~28~16 minecraft:nether_brick_fence
setblock ~30~29~16 minecraft:planks 0
fill ~30~35~16 ~32~35~16 minecraft:iron_bars
setblock ~31~28~16 minecraft:dispenser 2
setblock ~31~29~16 minecraft:glass_pane
fill ~31~45~16 ~37~45~16 minecraft:wool 0
fill ~31~55~16 ~37~55~16 minecraft:wool 0
setblock ~32~28~16 minecraft:nether_brick_fence
setblock ~32~29~16 minecraft:planks 0
fill ~33~30~16 ~33~30~17 minecraft:log 0
setblock ~33~31~16 minecraft:log 1
setblock ~33~32~16 minecraft:stone_stairs 1
setblock ~33~33~16 minecraft:stonebrick 3
fill ~34~25~16 ~35~25~16 minecraft:fence 0
fill ~34~26~16 ~35~26~16 minecraft:planks 0
fill ~34~27~16 ~35~27~16 minecraft:fence 0
fill ~34~28~16 ~35~28~17 minecraft:planks 0
fill ~34~29~16 ~35~29~16 minecraft:fence 0
fill ~34~30~16 ~35~30~17 minecraft:planks 0
fill ~34~31~16 ~35~31~16 minecraft:oak_stairs 2
fill ~34~32~16 ~35~32~16 minecraft:fence_gate 2
fill ~36~29~16 ~36~30~17 minecraft:log 0
setblock ~36~31~16 minecraft:log 1
setblock ~36~32~16 minecraft:stone_stairs 0
setblock ~36~33~16 minecraft:stonebrick 3
fill ~36~47~16 ~46~47~16 minecraft:wool 0
fill ~36~53~16 ~46~53~16 minecraft:wool 0
fill ~36~59~16 ~37~59~16 minecraft:iron_bars
setblock ~37~28~16 minecraft:nether_brick_fence
fill ~37~29~16 ~37~29~17 minecraft:planks 0
fill ~37~30~16 ~48~30~16 minecraft:planks 0
fill ~37~31~16 ~38~31~16 minecraft:log 0
fill ~37~32~16 ~43~32~16 minecraft:fence 0
fill ~37~33~16 ~42~33~16 minecraft:stone_block_slab 3
setblock ~38~28~16 minecraft:dispenser 2
setblock ~38~29~16 minecraft:glass_pane
setblock ~38~59~16 minecraft:wool 0
setblock ~39~28~16 minecraft:nether_brick_fence
setblock ~39~29~16 minecraft:planks 0
setblock ~39~31~16 minecraft:log 1
setblock ~40~28~16 minecraft:dispenser 2
setblock ~40~29~16 minecraft:glass_pane
fill ~40~31~16 ~44~31~16 minecraft:log 0
setblock ~40~48~16 minecraft:glowstone
setblock ~41~28~16 minecraft:nether_brick_fence
setblock ~41~29~16 minecraft:planks 0
fill ~41~48~16 ~47~48~16 minecraft:wool 0
fill ~41~52~16 ~47~52~16 minecraft:wool 0
setblock ~42~28~16 minecraft:dispenser 2
setblock ~42~29~16 minecraft:glass_pane
fill ~42~39~16 ~42~39~17 minecraft:wool 0
setblock ~42~41~16 minecraft:torch 3
setblock ~43~28~16 minecraft:nether_brick_fence
setblock ~43~29~16 minecraft:planks 0
setblock ~43~33~16 minecraft:stone_stairs 0
fill ~43~41~16 ~43~42~17 minecraft:wool 0
fill ~43~43~16 ~43~45~16 minecraft:wool 0
fill ~43~49~16 ~48~51~16 minecraft:wool 0
setblock ~43~55~16 minecraft:fence 0
setblock ~44~28~16 minecraft:dispenser 2
setblock ~44~29~16 minecraft:glass_pane
fill ~44~32~16 ~45~32~16 minecraft:log 0
fill ~44~33~16 ~46~33~16 minecraft:fence 0
fill ~44~34~16 ~46~34~16 minecraft:stone_block_slab 3
setblock ~44~44~16 minecraft:trapdoor 2
setblock ~44~45~16 minecraft:log 0
setblock ~44~46~16 minecraft:log 1
setblock ~44~54~16 minecraft:glowstone
setblock ~44~55~16 minecraft:log 0
setblock ~44~56~16 minecraft:oak_stairs 3
setblock ~45~28~16 minecraft:nether_brick_fence
setblock ~45~29~16 minecraft:planks 0
fill ~45~31~16 ~50~31~30 minecraft:planks 0
fill ~45~45~16 ~45~46~16 minecraft:fence 0
fill ~45~54~16 ~45~55~16 minecraft:fence 0
setblock ~46~28~16 minecraft:dispenser 2
setblock ~46~29~16 minecraft:glass_pane
fill ~46~32~16 ~47~32~16 minecraft:planks 0
setblock ~47~28~16 minecraft:stone_block_slab 5
setblock ~47~29~16 minecraft:planks 0
fill ~47~33~16 ~52~33~16 minecraft:log 1
fill ~47~34~16 ~47~35~16 minecraft:log 0
fill ~47~36~16 ~47~36~21 minecraft:fence 0
fill ~47~37~16 ~53~37~16 minecraft:stone_block_slab 3
setblock ~48~29~16 minecraft:oak_stairs 5
setblock ~48~32~16 minecraft:double_stone_block_slab 0
fill ~48~34~16 ~48~35~16 minecraft:planks 0
setblock ~48~36~16 minecraft:log 1
setblock ~49~30~16 minecraft:oak_stairs 5
fill ~49~32~16 ~50~32~30 minecraft:planks 0
setblock ~49~34~16 minecraft:glass_pane
fill ~49~35~16 ~52~35~29 minecraft:planks 0
setblock ~49~36~16 minecraft:fence 0
setblock ~50~34~16 minecraft:planks 0
setblock ~50~36~16 minecraft:log 1
fill ~51~31~16 ~52~31~16 minecraft:stone_block_slab 3
setblock ~51~32~16 minecraft:oak_stairs 5
setblock ~51~34~16 minecraft:glass_pane
setblock ~51~36~16 minecraft:fence 0
setblock ~52~32~16 minecraft:fence 0
setblock ~52~34~16 minecraft:planks 0
setblock ~52~36~16 minecraft:log 1
setblock ~53~33~16 minecraft:stone_block_slab 3
setblock ~53~35~16 minecraft:stone_block_slab 0
setblock ~54~33~16 minecraft:stone_stairs 2
setblock ~54~34~16 minecraft:trapdoor 3
setblock ~10~35~17 minecraft:stone_block_slab 3
setblock ~10~36~17 minecraft:stone_stairs 2
setblock ~10~37~17 minecraft:trapdoor 1
setblock ~11~32~17 minecraft:stone_stairs 2
setblock ~11~34~17 minecraft:stone_block_slab 0
fill ~11~35~17 ~20~36~17 minecraft:planks 0
fill ~11~37~17 ~11~38~17 minecraft:planks 0
setblock ~11~39~17 minecraft:fence 0
fill ~11~40~17 ~20~40~17 minecraft:stone_block_slab 3
setblock ~12~31~17 minecraft:stone_block_slab 5
fill ~12~32~17 ~14~32~17 minecraft:log 1
setblock ~12~33~17 minecraft:planks 0
fill ~12~34~17 ~13~34~17 minecraft:log 0
setblock ~12~37~17 minecraft:glass_pane
setblock ~12~38~17 minecraft:oak_stairs 2
setblock ~12~39~17 minecraft:log 1
setblock ~13~31~17 minecraft:double_stone_block_slab 0
setblock ~13~33~17 minecraft:glass
fill ~13~37~17 ~13~38~17 minecraft:planks 0
setblock ~13~39~17 minecraft:fence 0
setblock ~14~30~17 minecraft:oak_stairs 4
fill ~14~31~17 ~14~31~29 minecraft:planks 0
fill ~14~33~17 ~14~34~17 minecraft:planks 0
setblock ~14~37~17 minecraft:glass_pane
setblock ~14~38~17 minecraft:oak_stairs 2
setblock ~14~39~17 minecraft:log 1
setblock ~15~29~17 minecraft:stone_block_slab 5
fill ~15~30~17 ~17~30~17 minecraft:planks 0
setblock ~15~31~17 minecraft:double_stone_block_slab 0
setblock ~15~32~17 minecraft:planks 0
fill ~15~34~17 ~21~34~29 minecraft:planks 0
fill ~15~37~17 ~15~38~17 minecraft:planks 0
setblock ~15~39~17 minecraft:fence 0
setblock ~16~28~17 minecraft:nether_brick_fence
setblock ~16~29~17 minecraft:planks 0
fill ~16~31~17 ~16~31~21 minecraft:planks 0
setblock ~16~32~17 minecraft:torch 1
setblock ~16~37~17 minecraft:glass_pane
setblock ~16~38~17 minecraft:oak_stairs 2
setblock ~16~39~17 minecraft:log 1
setblock ~17~28~17 minecraft:dispenser 2
setblock ~17~29~17 minecraft:glass_pane
fill ~17~37~17 ~17~38~17 minecraft:planks 0
setblock ~17~39~17 minecraft:fence 0
setblock ~18~27~17 minecraft:stone_block_slab 5
setblock ~18~28~17 minecraft:planks 0
setblock ~18~30~17 minecraft:torch 1
fill ~18~31~17 ~18~31~29 minecraft:planks 0
setblock ~18~32~17 minecraft:torch 3
setblock ~18~37~17 minecraft:glass_pane
setblock ~18~38~17 minecraft:oak_stairs 2
setblock ~18~39~17 minecraft:log 1
fill ~19~27~17 ~33~27~17 minecraft:oak_stairs 6
setblock ~19~28~17 minecraft:obsidian
setblock ~19~29~17 minecraft:golden_rail 0
fill ~19~37~17 ~20~37~17 minecraft:planks 0
fill ~19~38~17 ~19~38~19 minecraft:planks 0
setblock ~19~39~17 minecraft:fence 0
setblock ~20~28~17 minecraft:planks 0
setblock ~20~30~17 minecraft:torch 3
fill ~20~31~17 ~20~31~21 minecraft:planks 0
setblock ~20~32~17 minecraft:torch 3
setblock ~20~38~17 minecraft:oak_stairs 2
setblock ~20~39~17 minecraft:log 1
setblock ~21~28~17 minecraft:obsidian
setblock ~21~29~17 minecraft:golden_rail 0
fill ~21~35~17 ~21~35~18 minecraft:log 1
fill ~21~36~17 ~21~37~17 minecraft:oak_stairs 1
fill ~21~38~17 ~21~38~21 minecraft:log 0
fill ~21~39~17 ~21~39~21 minecraft:fence 0
setblock ~22~28~17 minecraft:planks 0
setblock ~22~30~17 minecraft:torch 3
fill ~22~31~17 ~22~31~21 minecraft:planks 0
setblock ~22~32~17 minecraft:torch 3
fill ~22~34~17 ~23~34~17 minecraft:planks 1
setblock ~22~35~17 minecraft:torch 1
setblock ~22~37~17 minecraft:fence 0
fill ~22~38~17 ~22~38~20 minecraft:stone_stairs 1
setblock ~23~28~17 minecraft:obsidian
setblock ~23~29~17 minecraft:golden_rail 0
fill ~23~47~17 ~23~53~17 minecraft:fence 0
setblock ~24~28~17 minecraft:planks 0
setblock ~24~30~17 minecraft:torch 3
fill ~24~31~17 ~24~31~19 minecraft:planks 0
setblock ~24~32~17 minecraft:torch 2
fill ~24~34~17 ~24~34~29 minecraft:planks 0
fill ~24~45~17 ~24~46~17 minecraft:trapdoor 2
setblock ~24~47~17 minecraft:log 0
setblock ~24~48~17 minecraft:log 1
setblock ~24~49~17 minecraft:log 0
setblock ~24~50~17 minecraft:log 1
setblock ~24~51~17 minecraft:log 0
setblock ~24~52~17 minecraft:log 1
setblock ~24~53~17 minecraft:log 0
setblock ~24~54~17 minecraft:oak_stairs 3
setblock ~24~55~17 minecraft:trapdoor 2
setblock ~25~28~17 minecraft:obsidian
setblock ~25~29~17 minecraft:golden_rail 0
fill ~25~34~17 ~25~34~18 minecraft:oak_stairs 1
fill ~25~46~17 ~25~54~17 minecraft:fence 0
setblock ~25~59~17 minecraft:wool 0
setblock ~26~28~17 minecraft:planks 0
setblock ~26~30~17 minecraft:torch 3
fill ~26~31~17 ~29~31~18 minecraft:planks 0
fill ~26~32~17 ~26~32~19 minecraft:planks 0
fill ~26~33~17 ~26~33~18 minecraft:oak_stairs 1
fill ~26~49~17 ~42~51~17 minecraft:wool 0
fill ~26~54~17 ~26~55~17 minecraft:wool 0
setblock ~26~58~17 minecraft:wool 0
setblock ~27~28~17 minecraft:obsidian
setblock ~27~29~17 minecraft:golden_rail 0
fill ~27~32~17 ~27~32~18 minecraft:oak_stairs 1
fill ~27~42~17 ~27~42~19 minecraft:wool 0
setblock ~27~43~17 minecraft:wool 0
fill ~27~55~17 ~27~57~17 minecraft:wool 0
setblock ~28~28~17 minecraft:planks 0
fill ~28~29~17 ~28~30~17 minecraft:iron_bars
fill ~28~32~17 ~29~32~18 minecraft:stone_block_slab 0
fill ~28~44~17 ~28~45~17 minecraft:wool 0
fill ~28~48~17 ~41~48~17 minecraft:wool 0
fill ~28~52~17 ~40~52~17 minecraft:wool 0
setblock ~29~28~17 minecraft:obsidian
setblock ~29~29~17 minecraft:golden_rail 0
setblock ~30~28~17 minecraft:planks 0
setblock ~30~30~17 minecraft:torch 3
setblock ~30~31~17 minecraft:log 0
setblock ~31~28~17 minecraft:obsidian
setblock ~31~31~17 minecraft:planks 0
setblock ~32~28~17 minecraft:planks 0
setblock ~32~30~17 minecraft:torch 2
fill ~32~31~17 ~33~31~17 minecraft:planks 1
setblock ~32~53~17 minecraft:glowstone
fill ~33~28~17 ~33~29~17 minecraft:log 0
setblock ~33~32~17 minecraft:stone_block_slab 3
setblock ~33~33~17 minecraft:torch 3
fill ~33~47~17 ~35~47~17 minecraft:wool 0
fill ~33~53~17 ~35~53~17 minecraft:wool 0
fill ~34~27~17 ~35~27~19 minecraft:planks 0
fill ~34~29~17 ~35~29~17 minecraft:planks 0
setblock ~34~31~17 minecraft:planks 0
fill ~34~54~17 ~36~54~17 minecraft:iron_bars
fill ~35~31~17 ~36~31~17 minecraft:planks 1
fill ~36~27~17 ~44~27~17 minecraft:oak_stairs 6
setblock ~36~28~17 minecraft:log 0
setblock ~36~32~17 minecraft:stone_block_slab 3
setblock ~36~33~17 minecraft:torch 3
setblock ~36~53~17 minecraft:glowstone
fill ~36~55~17 ~38~55~17 minecraft:iron_bars
setblock ~37~28~17 minecraft:planks 0
setblock ~37~31~17 minecraft:planks 0
setblock ~38~28~17 minecraft:obsidian
setblock ~38~29~17 minecraft:golden_rail 0
setblock ~38~31~17 minecraft:planks 1
setblock ~39~28~17 minecraft:planks 0
setblock ~39~30~17 minecraft:torch 3
setblock ~39~31~17 minecraft:log 0
setblock ~39~55~17 minecraft:wool 0
setblock ~39~59~17 minecraft:wool 0
setblock ~40~28~17 minecraft:obsidian
setblock ~40~29~17 minecraft:golden_rail 0
setblock ~40~31~17 minecraft:planks 0
setblock ~40~58~17 minecraft:wool 0
setblock ~41~28~17 minecraft:planks 0
setblock ~41~30~17 minecraft:torch 3
setblock ~41~31~17 minecraft:planks 1
fill ~41~47~17 ~41~47~19 minecraft:stone_block_slab 0
setblock ~42~28~17 minecraft:obsidian
setblock ~42~29~17 minecraft:golden_rail 0
setblock ~42~31~17 minecraft:log 0
fill ~42~46~17 ~43~46~17 minecraft:wool 0
fill ~42~47~17 ~42~47~18 minecraft:wool 0
setblock ~43~28~17 minecraft:planks 0
setblock ~43~30~17 minecraft:torch 3
fill ~43~31~17 ~44~31~17 minecraft:planks 0
setblock ~43~32~17 minecraft:torch 2
fill ~43~40~17 ~43~40~18 minecraft:wool 0
setblock ~43~45~17 minecraft:wool 0
fill ~43~47~17 ~43~54~17 minecraft:fence 0
setblock ~44~28~17 minecraft:obsidian
setblock ~44~29~17 minecraft:golden_rail 0
fill ~44~32~17 ~44~32~18 minecraft:log 0
fill ~44~33~17 ~44~33~18 minecraft:fence 0
fill ~44~43~17 ~44~44~18 minecraft:wool 0
fill ~44~45~17 ~44~46~17 minecraft:trapdoor 2
setblock ~44~47~17 minecraft:log 0
setblock ~44~48~17 minecraft:log 1
setblock ~44~49~17 minecraft:log 0
setblock ~44~50~17 minecraft:log 1
setblock ~44~51~17 minecraft:log 0
setblock ~44~52~17 minecraft:log 1
setblock ~44~53~17 minecraft:log 0
setblock ~44~54~17 minecraft:oak_stairs 3
setblock ~44~55~17 minecraft:trapdoor 2
fill ~45~27~17 ~46~27~17 minecraft:stone_block_slab 5
setblock ~45~28~17 minecraft:planks 0
setblock ~45~30~17 minecraft:torch 3
fill ~45~32~17 ~46~32~20 minecraft:planks 1
fill ~45~47~17 ~45~53~17 minecraft:fence 0
setblock ~46~28~17 minecraft:obsidian
setblock ~46~29~17 minecraft:golden_rail 0
setblock ~46~35~17 minecraft:oak_stairs 0
setblock ~47~28~17 minecraft:planks 0
setblock ~47~30~17 minecraft:torch 2
fill ~47~32~17 ~48~32~18 minecraft:planks 0
fill ~47~33~17 ~47~33~18 minecraft:log 0
setblock ~47~34~17 minecraft:glass_pane
fill ~47~35~17 ~48~35~17 minecraft:planks 0
fill ~47~37~17 ~47~37~21 minecraft:stone_block_slab 3
setblock ~48~28~17 minecraft:double_stone_block_slab 0
fill ~48~29~17 ~49~30~17 minecraft:planks 0
setblock ~48~36~17 minecraft:torch 3
setblock ~49~28~17 minecraft:stone_block_slab 5
setblock ~49~33~17 minecraft:torch 3
setblock ~50~29~17 minecraft:oak_stairs 5
setblock ~50~30~17 minecraft:planks 0
setblock ~50~36~17 minecraft:torch 3
setblock ~51~30~17 minecraft:oak_stairs 5
fill ~51~31~17 ~51~32~29 minecraft:planks 0
setblock ~51~33~17 minecraft:torch 3
setblock ~52~31~17 minecraft:double_stone_block_slab 0
fill ~52~32~17 ~52~32~29 minecraft:planks 0
fill ~52~36~17 ~53~36~17 minecraft:fence 0
fill ~52~38~17 ~53~38~17 minecraft:iron_bars
fill ~53~31~17 ~54~31~17 minecraft:stone_block_slab 3
setblock ~53~32~17 minecraft:oak_stairs 5
fill ~53~33~17 ~54~33~17 minecraft:log 1
setblock ~53~34~17 minecraft:glass
fill ~53~35~17 ~54~35~28 minecraft:planks 0
setblock ~54~32~17 minecraft:fence 0
setblock ~54~34~17 minecraft:planks 0
setblock ~54~36~17 minecraft:log 1
fill ~54~37~17 ~55~37~17 minecraft:stone_block_slab 3
setblock ~55~33~17 minecraft:stone_block_slab 3
setblock ~55~35~17 minecraft:stone_block_slab 0
setblock ~56~33~17 minecraft:stone_stairs 2
setblock ~56~34~17 minecraft:trapdoor 3
setblock ~9~35~18 minecraft:stone_block_slab 3
setblock ~9~36~18 minecraft:stone_stairs 0
setblock ~9~37~18 minecraft:trapdoor 3
fill ~9~43~18 ~12~43~18 minecraft:wool 0
setblock ~10~32~18 minecraft:stone_stairs 0
setblock ~10~33~18 minecraft:trapdoor 3
setblock ~10~34~18 minecraft:stone_block_slab 0
setblock ~10~35~18 minecraft:cobblestone
setblock ~10~36~18 minecraft:planks 0
setblock ~10~37~18 minecraft:glass
setblock ~10~38~18 minecraft:stone_block_slab 0
setblock ~10~39~18 minecraft:log 1
setblock ~10~40~18 minecraft:stone_block_slab 3
fill ~10~42~18 ~11~42~19 minecraft:wool 0
fill ~10~44~18 ~13~44~18 minecraft:wool 0
setblock ~11~31~18 minecraft:stone_block_slab 5
setblock ~11~32~18 minecraft:log 1
setblock ~11~33~18 minecraft:glass
setblock ~11~34~18 minecraft:log 0
setblock ~11~35~18 minecraft:double_stone_block_slab 0
fill ~11~38~18 ~18~38~19 minecraft:planks 0
setblock ~11~39~18 minecraft:torch 1
fill ~11~45~18 ~13~45~18 minecraft:wool 0
setblock ~12~31~18 minecraft:double_stone_block_slab 0
setblock ~12~32~18 minecraft:planks 0
setblock ~12~33~18 minecraft:torch 3
fill ~12~35~18 ~12~35~28 minecraft:stone_block_slab 0
setblock ~12~39~18 minecraft:torch 3
setblock ~12~46~18 minecraft:wool 0
fill ~13~30~18 ~14~30~18 minecraft:planks 0
fill ~13~31~18 ~13~31~28 minecraft:planks 0
fill ~13~34~18 ~14~34~20 minecraft:planks 0
setblock ~13~36~18 minecraft:torch 3
fill ~14~29~18 ~15~29~18 minecraft:planks 0
setblock ~14~39~18 minecraft:torch 3
fill ~15~28~18 ~16~28~18 minecraft:planks 0
setblock ~15~30~18 minecraft:oak_stairs 1
fill ~15~31~18 ~15~31~22 minecraft:planks 0
setblock ~16~27~18 minecraft:stone_block_slab 5
setblock ~16~39~18 minecraft:torch 3
setblock ~17~27~18 minecraft:double_stone_block_slab 0
setblock ~17~28~18 minecraft:obsidian
setblock ~17~29~18 minecraft:golden_rail 0
setblock ~17~35~18 minecraft:double_stone_block_slab 0
setblock ~17~36~18 minecraft:wool 8
setblock ~17~37~18 minecraft:stone_block_slab 0
fill ~18~26~18 ~19~26~18 minecraft:stone_block_slab 5
fill ~18~27~18 ~33~27~18 minecraft:planks 0
setblock ~18~39~18 minecraft:torch 3
setblock ~19~28~18 minecraft:stone_button 3
setblock ~19~36~18 minecraft:torch 3
fill ~20~26~18 ~43~26~18 minecraft:oak_stairs 6
fill ~20~38~18 ~20~38~20 minecraft:planks 0
setblock ~20~39~18 minecraft:torch 3
setblock ~21~28~18 minecraft:stone_button 3
setblock ~21~36~18 minecraft:glass
fill ~21~37~18 ~21~37~19 minecraft:oak_stairs 5
setblock ~22~34~18 minecraft:planks 1
setblock ~23~28~18 minecraft:stone_button 3
fill ~23~34~18 ~23~34~20 minecraft:planks 0
fill ~24~47~18 ~24~53~18 minecraft:trapdoor 2
setblock ~25~28~18 minecraft:stone_button 3
fill ~25~49~18 ~25~49~21 minecraft:stone_block_slab 0
setblock ~25~51~18 minecraft:wool 0
fill ~25~59~18 ~25~59~21 minecraft:stone_block_slab 0
setblock ~26~49~18 minecraft:wool 0
fill ~26~52~18 ~26~52~19 minecraft:wool 0
setblock ~26~53~18 minecraft:wool 0
setblock ~26~59~18 minecraft:wool 0
setblock ~27~28~18 minecraft:stone_button 3
setblock ~27~34~18 minecraft:torch 4
fill ~27~41~18 ~27~41~19 minecraft:wool 0
setblock ~27~54~18 minecraft:wool 0
setblock ~27~58~18 minecraft:wool 0
setblock ~28~28~18 minecraft:fence_gate 3
fill ~28~30~18 ~28~30~21 minecraft:iron_bars
setblock ~28~43~18 minecraft:wool 0
fill ~28~46~18 ~29~46~18 minecraft:wool 0
setblock ~28~47~18 minecraft:wool 0
fill ~28~55~18 ~28~55~19 minecraft:wool 0
fill ~28~56~18 ~28~57~18 minecraft:wool 0
setblock ~29~28~18 minecraft:stone_button 3
fill ~29~44~18 ~29~44~19 minecraft:wool 0
setblock ~29~45~18 minecraft:wool 0
setblock ~30~31~18 minecraft:planks 1
setblock ~31~31~18 minecraft:log 0
setblock ~32~31~18 minecraft:planks 0
setblock ~33~29~18 minecraft:torch 3
setblock ~33~31~18 minecraft:planks 1
setblock ~34~31~18 minecraft:log 0
setblock ~35~31~18 minecraft:planks 0
fill ~35~48~18 ~36~48~18 minecraft:iron_bars
fill ~36~27~18 ~47~27~18 minecraft:planks 0
setblock ~36~29~18 minecraft:torch 3
setblock ~36~31~18 minecraft:planks 1
fill ~36~49~18 ~38~49~18 minecraft:iron_bars
setblock ~37~31~18 minecraft:log 0
setblock ~38~31~18 minecraft:planks 0
setblock ~39~31~18 minecraft:planks 1
setblock ~39~49~18 minecraft:wool 0
setblock ~40~28~18 minecraft:stone_button 3
setblock ~40~31~18 minecraft:log 0
setblock ~40~50~18 minecraft:wool 0
setblock ~40~54~18 minecraft:wool 0
setblock ~40~56~18 minecraft:wool 0
fill ~40~59~18 ~41~59~18 minecraft:wool 0
setblock ~41~31~18 minecraft:planks 0
fill ~41~51~18 ~41~53~18 minecraft:wool 0
fill ~41~57~18 ~41~58~18 minecraft:wool 0
setblock ~42~28~18 minecraft:stone_button 3
setblock ~42~31~18 minecraft:planks 1
fill ~42~48~18 ~42~48~19 minecraft:wool 0
fill ~42~52~18 ~42~52~19 minecraft:wool 0
setblock ~43~31~18 minecraft:log 0
fill ~43~39~18 ~43~39~19 minecraft:wool 0
setblock ~43~46~18 minecraft:wool 0
fill ~44~26~18 ~45~26~18 minecraft:stone_block_slab 5
setblock ~44~28~18 minecraft:stone_button 3
fill ~44~31~18 ~44~31~29 minecraft:planks 0
fill ~44~41~18 ~44~42~19 minecraft:wool 0
fill ~44~45~18 ~44~45~19 minecraft:wool 0
fill ~44~47~18 ~44~53~18 minecraft:trapdoor 2
setblock ~46~28~18 minecraft:stone_button 3
setblock ~46~34~18 minecraft:torch 2
setblock ~47~28~18 minecraft:stone_block_slab 0
setblock ~47~34~18 minecraft:log 0
setblock ~47~35~18 minecraft:oak_stairs 4
fill ~48~27~18 ~49~27~18 minecraft:stone_block_slab 5
fill ~48~28~18 ~50~28~18 minecraft:planks 0
fill ~48~35~18 ~48~35~24 minecraft:planks 0
fill ~49~29~18 ~50~29~18 minecraft:planks 0
setblock ~51~28~18 minecraft:stone_block_slab 5
setblock ~51~29~18 minecraft:double_stone_block_slab 0
fill ~51~30~18 ~53~30~18 minecraft:planks 0
setblock ~52~29~18 minecraft:oak_stairs 5
fill ~52~31~18 ~54~31~28 minecraft:planks 0
fill ~53~32~18 ~54~32~28 minecraft:planks 0
fill ~53~39~18 ~54~39~18 minecraft:iron_bars
setblock ~54~30~18 minecraft:stone_block_slab 5
fill ~54~36~18 ~55~36~18 minecraft:fence 0
setblock ~55~31~18 minecraft:stone_stairs 0
setblock ~55~32~18 minecraft:oak_stairs 5
fill ~55~33~18 ~56~33~18 minecraft:log 1
setblock ~55~34~18 minecraft:glass
fill ~55~35~18 ~56~35~27 minecraft:planks 0
setblock ~56~32~18 minecraft:stone_block_slab 3
setblock ~56~34~18 minecraft:planks 0
setblock ~56~36~18 minecraft:log 1
fill ~56~37~18 ~57~37~18 minecraft:stone_block_slab 3
setblock ~57~32~18 minecraft:stone_stairs 0
setblock ~57~33~18 minecraft:stone_block_slab 3
setblock ~57~35~18 minecraft:stone_block_slab 0
setblock ~58~33~18 minecraft:stone_stairs 2
setblock ~58~34~18 minecraft:trapdoor 3
fill ~6~36~19 ~7~39~19 minecraft:iron_bars
fill ~7~42~19 ~9~42~19 minecraft:wool 0
fill ~8~35~19 ~8~35~20 minecraft:stone_block_slab 3
setblock ~8~36~19 minecraft:stone_block_slab 3
setblock ~8~37~19 minecraft:trapdoor 1
setblock ~8~43~19 minecraft:wool 0
setblock ~8~44~19 minecraft:glowstone
setblock ~9~32~19 minecraft:stone_block_slab 3
setblock ~9~33~19 minecraft:trapdoor 1
fill ~9~34~19 ~9~34~20 minecraft:stone_block_slab 0
fill ~9~35~19 ~9~38~19 minecraft:planks 0
setblock ~9~39~19 minecraft:fence 0
fill ~9~40~19 ~9~40~20 minecraft:stone_block_slab 3
setblock ~9~43~19 minecraft:torch 1
fill ~9~44~19 ~9~45~19 minecraft:wool 0
setblock ~10~31~19 minecraft:stone_block_slab 5
setblock ~10~32~19 minecraft:log 1
setblock ~10~33~19 minecraft:planks 0
fill ~10~34~19 ~10~34~20 minecraft:log 0
fill ~10~35~19 ~10~35~20 minecraft:double_stone_block_slab 0
fill ~10~38~19 ~10~38~27 minecraft:planks 0
fill ~10~45~19 ~10~46~19 minecraft:wool 0
fill ~11~31~19 ~12~31~22 minecraft:planks 0
fill ~11~32~19 ~11~32~20 minecraft:stone_block_slab 3
fill ~11~35~19 ~11~35~27 minecraft:stone_block_slab 0
fill ~11~46~19 ~11~47~19 minecraft:wool 0
setblock ~12~30~19 minecraft:planks 0
fill ~12~42~19 ~13~42~19 minecraft:wool 0
fill ~12~47~19 ~14~47~19 minecraft:wool 0
fill ~12~48~19 ~13~48~19 minecraft:wool 0
setblock ~13~29~19 minecraft:planks 0
setblock ~13~30~19 minecraft:oak_stairs 1
fill ~13~43~19 ~14~43~19 minecraft:wool 0
fill ~13~46~19 ~14~46~19 minecraft:wool 0
setblock ~14~28~19 minecraft:planks 0
fill ~14~44~19 ~15~45~19 minecraft:wool 0
fill ~15~27~19 ~19~27~19 minecraft:planks 0
setblock ~15~29~19 minecraft:torch 3
setblock ~16~26~19 minecraft:stone_block_slab 5
fill ~17~26~19 ~20~26~19 minecraft:planks 0
setblock ~17~28~19 minecraft:stone_button 3
setblock ~17~37~19 minecraft:double_stone_block_slab 0
setblock ~18~25~19 minecraft:stone_block_slab 5
fill ~19~25~19 ~42~25~19 minecraft:oak_stairs 6
fill ~20~27~19 ~27~27~20 minecraft:log 0
setblock ~21~26~19 minecraft:oak_stairs 2
setblock ~21~35~19 minecraft:wooden_door 0
fill ~22~26~19 ~24~26~19 minecraft:oak_stairs 1
setblock ~22~34~19 minecraft:planks 0
fill ~24~32~19 ~24~33~19 minecraft:planks 0
setblock ~25~26~19 minecraft:oak_stairs 2
fill ~25~32~19 ~25~33~19 minecraft:log 0
fill ~25~34~19 ~26~34~19 minecraft:planks 0
fill ~25~35~19 ~27~35~19 minecraft:fence 0
setblock ~25~36~19 minecraft:torch 5
fill ~26~26~19 ~26~26~20 minecraft:oak_stairs 6
fill ~26~31~19 ~28~31~21 minecraft:planks 0
setblock ~26~33~19 minecraft:planks 0
fill ~26~51~19 ~26~51~20 minecraft:wool 0
fill ~27~26~19 ~32~26~19 minecraft:oak_stairs 2
fill ~27~32~19 ~27~34~19 minecraft:log 1
setblock ~27~49~19 minecraft:wool 0
setblock ~27~53~19 minecraft:wool 0
setblock ~27~59~19 minecraft:wool 0
fill ~28~27~19 ~32~27~19 minecraft:planks 0
fill ~28~28~19 ~28~28~21 minecraft:fence 0
fill ~28~29~19 ~28~29~21 minecraft:iron_bars
setblock ~28~32~19 minecraft:stone_block_slab 0
setblock ~28~34~19 minecraft:fence 0
setblock ~28~35~19 minecraft:log 1
setblock ~28~36~19 minecraft:stone_block_slab 3
fill ~28~42~19 ~28~42~20 minecraft:wool 0
setblock ~28~48~19 minecraft:wool 0
fill ~28~54~19 ~28~54~20 minecraft:wool 0
fill ~28~57~19 ~28~58~19 minecraft:wool 0
setblock ~29~31~19 minecraft:log 0
fill ~29~43~19 ~29~43~20 minecraft:wool 0
fill ~29~46~19 ~29~47~19 minecraft:wool 0
fill ~29~56~19 ~29~56~20 minecraft:wool 0
setblock ~30~31~19 minecraft:planks 0
fill ~30~45~19 ~30~45~21 minecraft:wool 0
setblock ~31~31~19 minecraft:planks 1
setblock ~32~31~19 minecraft:log 0
fill ~33~26~19 ~34~26~26 minecraft:planks 0
setblock ~33~27~19 minecraft:glowstone
setblock ~33~31~19 minecraft:planks 0
setblock ~34~31~19 minecraft:planks 1
fill ~35~26~19 ~39~26~19 minecraft:oak_stairs 2
setblock ~35~31~19 minecraft:log 0
setblock ~36~27~19 minecraft:glowstone
setblock ~36~31~19 minecraft:planks 0
fill ~37~27~19 ~39~27~19 minecraft:planks 0
setblock ~37~31~19 minecraft:planks 1
setblock ~38~31~19 minecraft:log 0
setblock ~39~31~19 minecraft:planks 0
fill ~40~26~19 ~40~27~19 minecraft:double_stone_block_slab 0
setblock ~40~31~19 minecraft:planks 1
setblock ~40~49~19 minecraft:wool 0
fill ~41~26~19 ~42~26~19 minecraft:oak_stairs 2
setblock ~41~27~19 minecraft:glowstone
setblock ~41~31~19 minecraft:log 0
setblock ~41~50~19 minecraft:wool 0
setblock ~41~54~19 minecraft:wool 0
setblock ~41~56~19 minecraft:wool 0
setblock ~41~59~19 minecraft:glowstone
fill ~42~27~19 ~49~27~19 minecraft:planks 0
setblock ~42~31~19 minecraft:planks 0
setblock ~42~51~19 minecraft:wool 0
setblock ~42~53~19 minecraft:wool 0
fill ~42~57~19 ~42~59~19 minecraft:wool 0
setblock ~43~25~19 minecraft:stone_block_slab 5
fill ~43~26~19 ~45~26~21 minecraft:planks 0
setblock ~43~31~19 minecraft:planks 1
fill ~43~47~19 ~43~47~20 minecraft:wool 0
fill ~43~52~19 ~43~52~20 minecraft:wool 0
fill ~44~32~19 ~44~32~20 minecraft:oak_stairs 0
fill ~44~40~19 ~44~40~20 minecraft:wool 0
fill ~44~46~19 ~44~46~20 minecraft:wool 0
fill ~45~43~19 ~45~44~20 minecraft:wool 0
fill ~46~26~19 ~47~26~19 minecraft:stone_block_slab 5
setblock ~47~32~19 minecraft:planks 1
setblock ~47~33~19 minecraft:wooden_door 2
setblock ~47~35~19 minecraft:log 0
fill ~48~32~19 ~48~32~30 minecraft:planks 0
setblock ~49~29~19 minecraft:torch 3
setblock ~50~27~19 minecraft:stone_block_slab 5
fill ~50~28~19 ~51~28~19 minecraft:planks 0
setblock ~52~28~19 minecraft:stone_block_slab 5
fill ~52~29~19 ~53~29~19 minecraft:planks 0
setblock ~54~29~19 minecraft:stone_block_slab 5
setblock ~54~30~19 minecraft:planks 0
fill ~54~40~19 ~56~40~19 minecraft:iron_bars
setblock ~55~30~19 minecraft:oak_stairs 5
fill ~55~31~19 ~55~31~27 minecraft:planks 0
fill ~55~32~19 ~57~32~25 minecraft:planks 0
setblock ~56~31~19 minecraft:oak_stairs 5
setblock ~56~33~19 minecraft:torch 2
fill ~56~36~19 ~57~36~19 minecraft:fence 0
fill ~57~33~19 ~58~33~19 minecraft:log 1
setblock ~57~34~19 minecraft:glass
fill ~57~35~19 ~58~35~26 minecraft:planks 0
fill ~57~40~19 ~61~40~19 minecraft:wool 0
setblock ~58~34~19 minecraft:planks 0
setblock ~58~36~19 minecraft:log 1
fill ~58~37~19 ~59~37~19 minecraft:stone_block_slab 3
fill ~58~41~19 ~60~41~19 minecraft:wool 0
setblock ~59~33~19 minecraft:cobblestone
setblock ~59~34~19 minecraft:log 1
setblock ~59~35~19 minecraft:oak_stairs 2
fill ~59~36~19 ~60~36~19 minecraft:fence 0
setblock ~59~42~19 minecraft:wool 0
setblock ~60~34~19 minecraft:stone_stairs 2
setblock ~60~35~19 minecraft:log 1
setblock ~61~35~19 minecraft:stone_stairs 2
setblock ~71~23~19 minecraft:wooden_button 2
fill ~6~40~20 ~7~41~20 minecraft:iron_bars
fill ~6~42~20 ~6~43~20 minecraft:iron_bars
setblock ~7~42~20 minecraft:oak_stairs 0
fill ~7~43~20 ~7~46~20 minecraft:iron_bars
setblock ~8~29~20 minecraft:stone_stairs 6
setblock ~8~30~20 minecraft:stone_stairs 1
setblock ~8~31~20 minecraft:stone_stairs 2
setblock ~8~36~20 minecraft:stone_stairs 0
setblock ~8~37~20 minecraft:trapdoor 3
setblock ~8~42~20 minecraft:stone_block_slab 0
fill ~8~44~20 ~8~46~20 minecraft:iron_bars
setblock ~9~30~20 minecraft:fence 0
setblock ~9~32~20 minecraft:stone_stairs 0
fill ~9~33~20 ~10~33~20 minecraft:glass_pane
setblock ~9~35~20 minecraft:cobblestone
setblock ~9~36~20 minecraft:planks 0
setblock ~9~37~20 minecraft:glass
setblock ~9~38~20 minecraft:oak_stairs 0
setblock ~9~39~20 minecraft:log 1
setblock ~9~46~20 minecraft:wool 0
fill ~10~31~20 ~10~32~20 minecraft:double_stone_block_slab 0
setblock ~10~36~20 minecraft:torch 1
setblock ~10~39~20 minecraft:torch 1
setblock ~10~47~20 minecraft:wool 0
fill ~11~30~20 ~11~30~21 minecraft:planks 0
fill ~11~38~20 ~16~38~28 minecraft:planks 0
fill ~11~48~20 ~11~49~20 minecraft:wool 0
setblock ~12~29~20 minecraft:planks 0
setblock ~12~30~20 minecraft:oak_stairs 3
fill ~12~49~20 ~14~49~20 minecraft:wool 0
fill ~12~50~20 ~13~50~20 minecraft:wool 0
setblock ~13~28~20 minecraft:planks 0
setblock ~13~30~20 minecraft:web
fill ~13~42~20 ~15~42~20 minecraft:wool 0
fill ~14~27~20 ~17~27~20 minecraft:planks 0
fill ~14~43~20 ~16~43~20 minecraft:wool 0
setblock ~14~48~20 minecraft:wool 0
fill ~15~26~20 ~16~26~20 minecraft:planks 0
setblock ~15~28~20 minecraft:crafting_table
fill ~15~44~20 ~16~45~20 minecraft:wool 0
fill ~15~46~20 ~15~47~20 minecraft:wool 0
setblock ~16~25~20 minecraft:stone_block_slab 5
fill ~17~25~20 ~19~25~20 minecraft:planks 0
setblock ~17~35~20 minecraft:double_stone_block_slab 0
setblock ~17~36~20 minecraft:wool 8
setblock ~17~37~20 minecraft:stone_block_slab 0
fill ~17~38~20 ~17~38~21 minecraft:log 0
setblock ~18~24~20 minecraft:stone_block_slab 5
fill ~18~27~20 ~19~27~20 minecraft:log 0
fill ~18~38~20 ~19~38~20 minecraft:stone_brick_stairs 3
fill ~19~24~20 ~42~24~20 minecraft:oak_stairs 6
setblock ~19~36~20 minecraft:torch 4
setblock ~20~25~20 minecraft:oak_stairs 2
fill ~21~25~20 ~37~25~20 minecraft:planks 0
setblock ~21~26~20 minecraft:oak_stairs 6
fill ~21~35~20 ~21~35~21 minecraft:log 1
fill ~21~36~20 ~21~37~20 minecraft:oak_stairs 1
setblock ~22~34~20 minecraft:planks 1
setblock ~22~36~20 minecraft:torch 4
setblock ~22~37~20 minecraft:fence 0
setblock ~23~32~20 minecraft:wooden_door 2
fill ~24~31~20 ~25~31~20 minecraft:planks 2
setblock ~25~26~20 minecraft:oak_stairs 6
setblock ~25~33~20 minecraft:torch 3
fill ~25~34~20 ~25~34~27 minecraft:planks 0
setblock ~26~32~20 minecraft:stone_stairs 3
fill ~26~34~20 ~27~34~20 minecraft:planks 1
fill ~27~26~20 ~32~26~26 minecraft:planks 0
setblock ~27~32~20 minecraft:cobblestone
setblock ~27~33~20 minecraft:fence 0
fill ~27~52~20 ~27~52~21 minecraft:wool 0
setblock ~28~27~20 minecraft:planks 0
fill ~28~32~20 ~28~34~20 minecraft:log 1
fill ~28~35~20 ~28~35~26 minecraft:fence 0
setblock ~28~36~20 minecraft:torch 5
setblock ~28~41~20 minecraft:wool 0
fill ~28~49~20 ~28~49~21 minecraft:wool 0
fill ~28~53~20 ~28~53~26 minecraft:wool 0
fill ~28~58~20 ~28~59~20 minecraft:wool 0
fill ~29~31~20 ~29~31~21 minecraft:planks 1
setblock ~29~33~20 minecraft:fence 0
setblock ~29~34~20 minecraft:torch 1
fill ~29~42~20 ~29~42~22 minecraft:wool 0
fill ~29~47~20 ~29~48~20 minecraft:wool 0
fill ~29~55~20 ~29~55~21 minecraft:wool 0
fill ~29~57~20 ~29~57~21 minecraft:wool 0
setblock ~30~31~20 minecraft:log 0
fill ~30~44~20 ~30~44~26 minecraft:wool 0
fill ~30~46~20 ~30~46~22 minecraft:wool 0
setblock ~31~31~20 minecraft:planks 0
setblock ~32~31~20 minecraft:planks 1
setblock ~33~31~20 minecraft:log 0
setblock ~34~31~20 minecraft:planks 0
fill ~35~26~20 ~42~26~26 minecraft:planks 0
setblock ~35~31~20 minecraft:planks 1
setblock ~36~31~20 minecraft:log 0
setblock ~37~31~20 minecraft:planks 0
fill ~38~25~20 ~42~25~20 minecraft:oak_stairs 2
setblock ~38~31~20 minecraft:planks 1
setblock ~39~31~20 minecraft:log 0
setblock ~40~31~20 minecraft:planks 0
setblock ~40~47~20 minecraft:torch 2
setblock ~41~31~20 minecraft:planks 1
fill ~41~47~20 ~41~47~26 minecraft:double_stone_block_slab 0
setblock ~41~49~20 minecraft:wool 0
setblock ~42~31~20 minecraft:log 0
setblock ~42~47~20 minecraft:torch 1
setblock ~42~50~20 minecraft:wool 0
setblock ~42~54~20 minecraft:wool 0
setblock ~42~56~20 minecraft:wool 0
setblock ~43~24~20 minecraft:stone_block_slab 5
fill ~43~25~20 ~44~25~20 minecraft:planks 0
setblock ~43~29~20 minecraft:stone_button 2
setblock ~43~30~20 minecraft:nether_brick_stairs 3
setblock ~43~31~20 minecraft:planks 0
setblock ~43~48~20 minecraft:wool 0
fill ~43~51~20 ~43~51~21 minecraft:wool 0
fill ~43~53~20 ~43~53~21 minecraft:wool 0
fill ~43~57~20 ~43~57~21 minecraft:wool 0
fill ~43~58~20 ~43~59~20 minecraft:wool 0
fill ~44~39~20 ~44~39~25 minecraft:wool 0
setblock ~45~25~20 minecraft:double_stone_block_slab 0
fill ~45~41~20 ~45~41~26 minecraft:wool 0
fill ~45~42~20 ~45~42~21 minecraft:wool 0
fill ~45~45~20 ~45~45~26 minecraft:wool 0
fill ~46~25~20 ~47~25~20 minecraft:stone_block_slab 5
fill ~46~26~20 ~48~26~20 minecraft:planks 0
setblock ~46~34~20 minecraft:torch 2
fill ~47~32~20 ~47~32~26 minecraft:planks 0
fill ~47~33~20 ~47~34~20 minecraft:log 0
setblock ~47~35~20 minecraft:oak_stairs 4
setblock ~49~26~20 minecraft:double_stone_block_slab 0
fill ~49~27~20 ~50~27~20 minecraft:planks 0
setblock ~50~26~20 minecraft:stone_block_slab 5
setblock ~51~27~20 minecraft:double_stone_block_slab 0
setblock ~52~27~20 minecraft:stone_block_slab 5
fill ~52~28~20 ~53~28~20 minecraft:planks 0
setblock ~54~28~20 minecraft:stone_block_slab 5
setblock ~54~29~20 minecraft:planks 0
setblock ~54~30~20 minecraft:torch 3
setblock ~55~29~20 minecraft:oak_stairs 5
setblock ~55~30~20 minecraft:planks 0
fill ~55~40~20 ~56~40~20 minecraft:wool 0
setblock ~56~30~20 minecraft:oak_stairs 5
fill ~56~31~20 ~56~31~26 minecraft:planks 0
setblock ~57~31~20 minecraft:oak_stairs 5
fill ~57~41~20 ~57~42~20 minecraft:wool 0
fill ~57~46~20 ~57~46~21 minecraft:wool 0
fill ~58~32~20 ~58~32~25 minecraft:planks 0
setblock ~58~33~20 minecraft:stone_block_slab 0
setblock ~58~36~20 minecraft:torch 3
fill ~58~42~20 ~58~45~20 minecraft:wool 0
setblock ~59~32~20 minecraft:stone_block_slab 5
setblock ~59~33~20 minecraft:oak_stairs 0
fill ~59~35~20 ~61~35~26 minecraft:planks 0
fill ~59~43~20 ~60~43~20 minecraft:wool 0
setblock ~59~44~20 minecraft:wool 0
setblock ~60~33~20 minecraft:oak_stairs 5
setblock ~60~34~20 minecraft:planks 0
setblock ~60~36~20 minecraft:fence 0
setblock ~60~37~20 minecraft:stone_stairs 0
fill ~60~42~20 ~61~42~20 minecraft:wool 0
setblock ~61~34~20 minecraft:oak_stairs 5
setblock ~61~36~20 minecraft:log 1
setblock ~61~37~20 minecraft:double_stone_block_slab 3
fill ~61~41~20 ~62~41~20 minecraft:wool 0
setblock ~62~35~20 minecraft:oak_stairs 5
setblock ~62~36~20 minecraft:stone_stairs 2
fill ~62~40~20 ~63~40~20 minecraft:wool 0
setblock ~70~23~20 minecraft:wooden_button 4
setblock ~71~22~20 minecraft:wooden_button 0
fill ~71~23~20 ~71~23~24 minecraft:log 0
setblock ~71~24~20 minecraft:wooden_button 1
setblock ~72~23~20 minecraft:wooden_button 5
fill ~7~35~21 ~7~36~21 minecraft:stone_block_slab 3
setblock ~7~37~21 minecraft:trapdoor 1
setblock ~8~28~21 minecraft:double_stone_block_slab 3
fill ~8~29~21 ~8~30~21 minecraft:iron_bars
setblock ~8~32~21 minecraft:double_stone_block_slab 3
fill ~8~34~21 ~8~34~25 minecraft:stone_block_slab 0
fill ~8~35~21 ~9~35~22 minecraft:planks 0
fill ~8~36~21 ~8~38~21 minecraft:planks 0
setblock ~8~39~21 minecraft:fence 0
setblock ~8~40~21 minecraft:stone_block_slab 3
fill ~8~47~21 ~9~49~21 minecraft:iron_bars
fill ~9~28~21 ~9~28~22 minecraft:fence 0
setblock ~9~29~21 minecraft:fence 0
setblock ~9~30~21 minecraft:planks 0
setblock ~9~31~21 minecraft:fence 0
setblock ~9~32~21 minecraft:log 1
setblock ~9~33~21 minecraft:planks 0
fill ~9~34~21 ~9~34~25 minecraft:log 0
fill ~9~38~21 ~9~38~25 minecraft:planks 0
fill ~9~42~21 ~11~42~21 minecraft:stone_block_slab 0
fill ~9~50~21 ~10~51~21 minecraft:iron_bars
setblock ~10~30~21 minecraft:fence 0
setblock ~10~32~21 minecraft:stone_block_slab 3
setblock ~10~33~21 minecraft:torch 1
fill ~10~35~21 ~10~35~25 minecraft:stone_block_slab 0
setblock ~10~48~21 minecraft:wool 0
setblock ~10~49~21 minecraft:glowstone
fill ~10~52~21 ~11~53~21 minecraft:iron_bars
setblock ~11~29~21 minecraft:planks 0
fill ~11~50~21 ~11~51~21 minecraft:wool 0
setblock ~12~28~21 minecraft:planks 0
setblock ~12~30~21 minecraft:crafting_table
fill ~12~51~21 ~14~51~21 minecraft:wool 0
fill ~12~52~21 ~13~53~21 minecraft:wool 0
fill ~13~27~21 ~16~27~21 minecraft:planks 0
fill ~13~28~21 ~13~28~22 minecraft:crafting_table
fill ~13~35~21 ~13~35~26 minecraft:stone_block_slab 0
setblock ~13~54~21 minecraft:wool 0
setblock ~13~55~21 minecraft:glowstone
fill ~14~26~21 ~15~26~21 minecraft:planks 0
fill ~14~34~21 ~14~34~29 minecraft:planks 0
setblock ~14~50~21 minecraft:wool 0
fill ~14~55~21 ~14~56~21 minecraft:wool 0
setblock ~15~25~21 minecraft:oak_stairs 4
fill ~15~42~21 ~16~42~21 minecraft:wool 0
fill ~15~48~21 ~15~49~21 minecraft:wool 0
setblock ~16~24~21 minecraft:stone_block_slab 5
fill ~16~25~21 ~17~25~21 minecraft:planks 0
setblock ~16~36~21 minecraft:torch 2
fill ~16~46~21 ~16~47~21 minecraft:wool 0
setblock ~17~24~21 minecraft:double_stone_block_slab 0
fill ~17~27~21 ~18~27~25 minecraft:log 0
fill ~17~35~21 ~20~36~21 minecraft:planks 0
setblock ~17~37~21 minecraft:log 1
fill ~17~39~21 ~17~39~25 minecraft:fence 0
fill ~17~43~21 ~17~45~21 minecraft:wool 0
fill ~18~24~21 ~45~24~21 minecraft:planks 0
fill ~18~37~21 ~19~37~21 minecraft:stone_brick_stairs 3
setblock ~18~38~21 minecraft:torch 1
setblock ~19~27~21 minecraft:cobblestone
fill ~19~28~21 ~19~30~21 minecraft:fence 0
fill ~20~27~21 ~21~27~25 minecraft:planks 0
fill ~20~28~21 ~21~28~21 minecraft:oak_stairs 2
fill ~20~32~21 ~20~33~21 minecraft:fence 0
setblock ~20~37~21 minecraft:oak_stairs 7
setblock ~20~38~21 minecraft:log 0
setblock ~20~39~21 minecraft:fence 0
setblock ~21~31~21 minecraft:oak_stairs 7
fill ~21~32~21 ~21~33~21 minecraft:log 0
fill ~21~36~21 ~21~37~21 minecraft:planks 1
setblock ~22~27~21 minecraft:cobblestone
fill ~22~28~21 ~22~30~21 minecraft:fence 0
fill ~22~32~21 ~22~33~21 minecraft:fence 0
fill ~22~35~21 ~22~37~21 minecraft:log 0
setblock ~22~38~21 minecraft:oak_stairs 1
fill ~23~27~21 ~26~27~21 minecraft:log 0
setblock ~23~28~21 minecraft:torch 5
fill ~23~32~21 ~23~33~21 minecraft:log 0
setblock ~23~34~21 minecraft:planks 1
setblock ~24~31~21 minecraft:planks 2
setblock ~24~32~21 minecraft:fence 0
fill ~25~26~21 ~26~26~25 minecraft:planks 0
setblock ~25~31~21 minecraft:planks 0
fill ~26~34~21 ~26~34~25 minecraft:planks 0
setblock ~27~27~21 minecraft:glowstone
fill ~27~28~21 ~27~28~22 minecraft:fence 0
fill ~27~29~21 ~27~30~22 minecraft:iron_bars
setblock ~27~32~21 minecraft:stone_stairs 0
setblock ~27~34~21 minecraft:planks 1
fill ~28~32~21 ~28~32~22 minecraft:log 0
setblock ~28~33~21 minecraft:glass_pane
fill ~28~34~21 ~28~34~25 minecraft:oak_stairs 1
fill ~28~59~21 ~28~59~22 minecraft:wool 0
fill ~29~48~21 ~29~48~22 minecraft:wool 0
setblock ~29~49~21 minecraft:glowstone
fill ~29~54~21 ~29~54~25 minecraft:wool 0
setblock ~29~56~21 minecraft:torch 3
fill ~29~58~21 ~29~58~25 minecraft:wool 0
setblock ~30~31~21 minecraft:planks 1
fill ~30~43~21 ~30~43~25 minecraft:wool 0
fill ~30~47~21 ~30~47~25 minecraft:wool 0
fill ~30~56~21 ~30~56~25 minecraft:wool 0
setblock ~31~31~21 minecraft:log 0
fill ~31~45~21 ~31~45~25 minecraft:wool 0
setblock ~32~31~21 minecraft:planks 0
setblock ~33~31~21 minecraft:planks 1
setblock ~34~31~21 minecraft:log 0
fill ~35~29~21 ~35~29~22 minecraft:wool 6
setblock ~35~31~21 minecraft:planks 0
setblock ~36~31~21 minecraft:planks 1
setblock ~37~31~21 minecraft:log 0
setblock ~38~31~21 minecraft:planks 0
setblock ~39~31~21 minecraft:planks 1
setblock ~40~31~21 minecraft:log 0
setblock ~41~31~21 minecraft:planks 0
fill ~42~29~21 ~43~29~21 minecraft:wool 12
setblock ~42~31~21 minecraft:planks 1
setblock ~42~55~21 minecraft:glowstone
fill ~43~27~21 ~43~28~21 minecraft:wool 12
setblock ~43~31~21 minecraft:log 0
setblock ~43~48~21 minecraft:glowstone
fill ~43~50~21 ~43~50~25 minecraft:wool 0
setblock ~43~52~21 minecraft:torch 3
fill ~43~54~21 ~43~54~25 minecraft:wool 0
setblock ~43~59~21 minecraft:wool 0
fill ~44~25~21 ~48~25~21 minecraft:planks 0
fill ~44~28~21 ~45~28~21 minecraft:wool 12
setblock ~44~32~21 minecraft:log 0
fill ~44~33~21 ~44~34~21 minecraft:fence 0
setblock ~44~35~21 minecraft:torch 5
fill ~44~47~21 ~44~47~25 minecraft:wool 0
fill ~44~52~21 ~44~52~25 minecraft:wool 0
fill ~44~58~21 ~44~58~25 minecraft:wool 0
setblock ~45~27~21 minecraft:wool 12
fill ~45~32~21 ~46~32~24 minecraft:planks 0
fill ~45~33~21 ~46~33~21 minecraft:log 0
setblock ~45~34~21 minecraft:log 0
setblock ~45~35~21 minecraft:fence 0
setblock ~45~36~21 minecraft:stone_stairs 0
fill ~45~40~21 ~45~40~25 minecraft:wool 0
setblock ~45~43~21 minecraft:torch 3
setblock ~45~44~21 minecraft:wool 0
fill ~45~46~21 ~45~46~25 minecraft:wool 0
fill ~46~24~21 ~47~24~21 minecraft:stone_block_slab 5
setblock ~46~28~21 minecraft:nether_brick_fence
setblock ~46~34~21 minecraft:double_stone_block_slab 0
setblock ~46~35~21 minecraft:oak_stairs 0
setblock ~46~36~21 minecraft:fence 0
setblock ~46~37~21 minecraft:stone_block_slab 3
fill ~46~43~21 ~46~43~25 minecraft:wool 0
fill ~47~33~21 ~47~34~23 minecraft:planks 0
setblock ~47~35~21 minecraft:planks 0
fill ~48~26~21 ~51~26~21 minecraft:planks 0
setblock ~49~25~21 minecraft:double_stone_block_slab 0
setblock ~50~25~21 minecraft:stone_block_slab 5
fill ~50~27~21 ~52~27~22 minecraft:planks 0
setblock ~52~26~21 minecraft:stone_block_slab 5
setblock ~53~27~21 minecraft:double_stone_block_slab 0
setblock ~53~28~21 minecraft:glowstone
setblock ~54~27~21 minecraft:stone_block_slab 5
setblock ~54~28~21 minecraft:planks 0
setblock ~54~40~21 minecraft:wool 0
setblock ~55~28~21 minecraft:oak_stairs 5
setblock ~55~29~21 minecraft:planks 0
fill ~55~41~21 ~56~41~21 minecraft:wool 0
setblock ~55~49~21 minecraft:wool 0
setblock ~56~29~21 minecraft:oak_stairs 5
setblock ~56~30~21 minecraft:planks 0
fill ~56~42~21 ~56~43~22 minecraft:wool 0
fill ~56~47~21 ~57~47~21 minecraft:wool 0
setblock ~56~48~21 minecraft:wool 0
setblock ~57~30~21 minecraft:double_stone_block_slab 0
fill ~57~31~21 ~58~31~25 minecraft:planks 0
fill ~57~43~21 ~57~45~21 minecraft:wool 0
setblock ~58~30~21 minecraft:stone_block_slab 5
setblock ~58~46~21 minecraft:wool 0
setblock ~59~31~21 minecraft:oak_stairs 5
fill ~59~32~21 ~59~32~25 minecraft:planks 0
fill ~59~33~21 ~59~33~22 minecraft:stone_block_slab 0
setblock ~59~45~21 minecraft:wool 0
setblock ~60~32~21 minecraft:oak_stairs 5
setblock ~60~33~21 minecraft:double_stone_block_slab 0
fill ~60~36~21 ~61~36~21 minecraft:stone_block_slab 0
setblock ~60~44~21 minecraft:wool 0
setblock ~61~33~21 minecraft:oak_stairs 5
setblock ~61~34~21 minecraft:planks 0
setblock ~61~37~21 minecraft:torch 3
setblock ~61~43~21 minecraft:wool 0
setblock ~62~34~21 minecraft:oak_stairs 5
fill ~62~35~21 ~62~35~25 minecraft:planks 0
setblock ~62~36~21 minecraft:double_stone_block_slab 0
setblock ~62~37~21 minecraft:double_stone_block_slab 3
setblock ~62~42~21 minecraft:wool 0
setblock ~63~35~21 minecraft:oak_stairs 5
setblock ~63~36~21 minecraft:planks 0
setblock ~63~37~21 minecraft:stone_stairs 1
setblock ~63~38~21 minecraft:stone_block_slab 3
fill ~63~40~21 ~64~40~21 minecraft:wool 0
setblock ~63~41~21 minecraft:wool 0
setblock ~64~36~21 minecraft:stone_block_slab 0
fill ~65~20~21 ~68~20~21 minecraft:wool 8
fill ~67~21~21 ~68~21~21 minecraft:wool 0
fill ~67~22~21 ~69~22~21 minecraft:fence 5
fill ~68~26~21 ~68~29~21 minecraft:wool 8
fill ~69~21~21 ~70~21~21 minecraft:wool 8
fill ~69~23~21 ~70~23~21 minecraft:fence 5
fill ~69~24~21 ~69~25~21 minecraft:wool 8
fill ~69~26~21 ~69~27~21 minecraft:wool 0
setblock ~70~22~21 minecraft:wool 0
setblock ~70~24~21 minecraft:wool 0
fill ~70~25~21 ~71~25~21 minecraft:fence 5
fill ~70~26~21 ~70~27~21 minecraft:fence 5
fill ~71~21~21 ~72~21~21 minecraft:fence 5
setblock ~71~22~21 minecraft:fence 5
setblock ~71~24~21 minecraft:fence 5
fill ~72~19~21 ~72~20~21 minecraft:fence 5
setblock ~72~22~21 minecraft:wool 0
fill ~72~23~21 ~73~23~21 minecraft:fence 5
setblock ~72~24~21 minecraft:wool 0
fill ~72~25~21 ~73~25~21 minecraft:wool 8
fill ~73~19~21 ~73~20~21 minecraft:wool 0
fill ~73~21~21 ~73~22~21 minecraft:wool 8
fill ~73~24~21 ~75~24~21 minecraft:fence 5
fill ~74~17~21 ~74~20~21 minecraft:wool 8
fill ~74~25~21 ~75~25~21 minecraft:wool 0
fill ~74~26~21 ~77~26~21 minecraft:wool 8
setblock ~6~37~22 minecraft:trapdoor 1
fill ~7~35~22 ~7~36~22 minecraft:stone_stairs 0
fill ~7~37~22 ~7~38~22 minecraft:planks 0
setblock ~7~39~22 minecraft:log 1
fill ~7~40~22 ~7~40~24 minecraft:stone_block_slab 3
setblock ~8~27~22 minecraft:stone_stairs 6
setblock ~8~30~22 minecraft:iron_bars
fill ~8~32~22 ~8~32~23 minecraft:iron_bars
setblock ~8~33~22 minecraft:stone_stairs 2
fill ~8~36~22 ~8~36~24 minecraft:oak_stairs 1
setblock ~8~37~22 minecraft:torch 1
fill ~8~38~22 ~8~38~25 minecraft:planks 0
setblock ~8~39~22 minecraft:torch 1
setblock ~9~32~22 minecraft:fence 0
setblock ~9~33~22 minecraft:log 1
setblock ~10~32~22 minecraft:stone_stairs 2
setblock ~11~28~22 minecraft:stone_block_slab 5
setblock ~11~29~22 minecraft:double_stone_block_slab 0
setblock ~11~30~22 minecraft:nether_brick_fence
setblock ~11~32~22 minecraft:stone_block_slab 5
fill ~11~54~22 ~12~55~22 minecraft:iron_bars
setblock ~12~27~22 minecraft:stone_block_slab 5
setblock ~12~28~22 minecraft:oak_stairs 0
setblock ~12~29~22 minecraft:torch 1
setblock ~12~32~22 minecraft:oak_stairs 2
fill ~12~42~22 ~14~42~22 minecraft:stone_block_slab 0
fill ~12~56~22 ~12~57~22 minecraft:iron_bars
setblock ~13~26~22 minecraft:stone_block_slab 5
fill ~13~27~22 ~15~27~23 minecraft:planks 0
fill ~13~32~22 ~14~32~22 minecraft:stone_block_slab 5
fill ~13~57~22 ~13~58~22 minecraft:iron_bars
setblock ~14~25~22 minecraft:stone_block_slab 5
fill ~14~26~22 ~14~26~25 minecraft:planks 0
fill ~14~52~22 ~14~54~22 minecraft:wool 0
fill ~14~56~22 ~15~56~22 minecraft:wool 0
setblock ~14~58~22 minecraft:iron_bars
setblock ~15~24~22 minecraft:stone_block_slab 5
setblock ~15~25~22 minecraft:planks 0
setblock ~15~30~22 minecraft:stone_brick_stairs 2
setblock ~15~39~22 minecraft:stone_stairs 2
fill ~15~40~22 ~15~41~22 minecraft:trapdoor 3
fill ~15~50~22 ~15~51~22 minecraft:wool 0
setblock ~15~55~22 minecraft:wool 0
fill ~15~57~22 ~15~58~22 minecraft:wool 0
setblock ~15~59~22 minecraft:trapdoor 3
fill ~16~24~22 ~17~24~22 minecraft:planks 0
fill ~16~27~22 ~16~27~24 minecraft:log 0
fill ~16~31~22 ~16~31~24 minecraft:oak_stairs 4
fill ~16~35~22 ~16~36~24 minecraft:planks 0
fill ~16~37~22 ~16~37~24 minecraft:log 1
fill ~16~47~22 ~17~47~22 minecraft:wool 0
fill ~16~48~22 ~16~48~23 minecraft:wool 0
setblock ~16~49~22 minecraft:wool 0
fill ~17~36~22 ~17~36~24 minecraft:glowstone
setblock ~17~37~22 minecraft:fence 0
fill ~17~38~22 ~17~38~24 minecraft:oak_stairs 5
setblock ~17~42~22 minecraft:wool 0
fill ~17~46~22 ~17~46~23 minecraft:wool 0
fill ~18~23~22 ~44~23~22 minecraft:oak_stairs 6
fill ~18~36~22 ~19~36~25 minecraft:planks 0
fill ~18~43~22 ~18~45~22 minecraft:wool 0
setblock ~19~27~22 minecraft:log 0
fill ~19~29~22 ~19~29~25 minecraft:fence 0
setblock ~19~33~22 minecraft:torch 2
fill ~19~35~22 ~20~35~22 minecraft:planks 0
fill ~20~28~22 ~21~28~24 minecraft:planks 0
fill ~20~31~22 ~20~31~24 minecraft:oak_stairs 5
fill ~20~32~22 ~20~33~22 minecraft:log 0
fill ~20~36~22 ~20~36~24 minecraft:stone_brick_stairs 1
setblock ~21~32~22 minecraft:torch 1
setblock ~21~33~22 minecraft:log 0
fill ~21~35~22 ~21~35~24 minecraft:stone_brick_stairs 1
setblock ~21~38~22 minecraft:torch 3
fill ~22~27~22 ~23~27~23 minecraft:planks 0
fill ~22~28~22 ~22~28~24 minecraft:oak_stairs 1
fill ~22~29~22 ~22~29~24 minecraft:oak_stairs 0
setblock ~22~31~22 minecraft:torch 3
setblock ~22~34~22 minecraft:planks 1
fill ~23~28~22 ~23~29~22 minecraft:tnt 0
fill ~23~30~22 ~23~30~24 minecraft:oak_stairs 0
fill ~23~34~22 ~23~34~24 minecraft:planks 0
fill ~24~27~22 ~25~27~22 minecraft:log 0
fill ~24~31~22 ~24~31~24 minecraft:oak_stairs 0
setblock ~25~31~22 minecraft:planks 2
fill ~25~49~22 ~25~49~24 minecraft:oak_stairs 0
setblock ~25~59~22 minecraft:oak_stairs 0
fill ~26~27~22 ~26~27~24 minecraft:planks 0
fill ~26~28~22 ~26~28~24 minecraft:fence 0
fill ~26~29~22 ~26~30~24 minecraft:iron_bars
setblock ~26~31~22 minecraft:planks 0
setblock ~26~35~22 minecraft:stone_stairs 2
fill ~26~36~22 ~26~37~22 minecraft:trapdoor 3
setblock ~26~59~22 minecraft:torch 4
setblock ~27~31~22 minecraft:planks 2
setblock ~27~33~22 minecraft:torch 2
fill ~27~34~22 ~27~34~24 minecraft:planks 0
fill ~28~31~22 ~28~31~29 minecraft:planks 0
setblock ~28~33~22 minecraft:planks 0
fill ~28~52~22 ~28~52~24 minecraft:wool 0
setblock ~29~31~22 minecraft:log 0
setblock ~29~33~22 minecraft:torch 1
fill ~29~49~22 ~29~49~24 minecraft:wool 0
setblock ~29~59~22 minecraft:glowstone
setblock ~30~27~22 minecraft:fence 0
setblock ~30~31~22 minecraft:planks 0
fill ~30~55~22 ~30~55~24 minecraft:wool 0
fill ~30~57~22 ~30~57~24 minecraft:wool 0
fill ~31~27~22 ~31~28~22 minecraft:wool 15
setblock ~31~29~22 minecraft:stone_button 2
setblock ~31~31~22 minecraft:planks 1
fill ~31~44~22 ~31~44~24 minecraft:wool 0
fill ~31~46~22 ~31~46~24 minecraft:wool 0
setblock ~32~31~22 minecraft:log 0
setblock ~33~31~22 minecraft:planks 0
setblock ~34~29~22 minecraft:stone_button 4
setblock ~34~31~22 minecraft:planks 1
fill ~35~27~22 ~35~28~22 minecraft:wool 6
setblock ~35~30~22 minecraft:fence 0
setblock ~35~31~22 minecraft:log 0
setblock ~36~29~22 minecraft:stone_button 5
setblock ~36~31~22 minecraft:planks 0
setblock ~37~31~22 minecraft:planks 1
setblock ~38~31~22 minecraft:log 0
setblock ~39~31~22 minecraft:planks 0
fill ~40~31~22 ~40~31~23 minecraft:wool 10
setblock ~40~32~22 minecraft:stone_stairs 2
fill ~40~33~22 ~40~34~22 minecraft:trapdoor 3
setblock ~40~35~22 minecraft:torch 4
setblock ~40~47~22 minecraft:trapdoor 1
setblock ~41~31~22 minecraft:log 0
setblock ~41~44~22 minecraft:torch 4
setblock ~41~46~22 minecraft:nether_brick_fence
setblock ~42~31~22 minecraft:planks 0
fill ~42~55~22 ~42~55~24 minecraft:wool 0
fill ~43~26~22 ~43~26~26 minecraft:planks 0
setblock ~43~29~22 minecraft:stone_button 3
setblock ~43~30~22 minecraft:nether_brick_stairs 2
setblock ~43~31~22 minecraft:planks 1
fill ~44~24~22 ~47~24~22 minecraft:planks 0
fill ~44~25~22 ~44~25~25 minecraft:planks 0
fill ~44~32~22 ~44~32~24 minecraft:oak_stairs 0
fill ~44~51~22 ~44~51~24 minecraft:wool 0
fill ~44~53~22 ~44~53~24 minecraft:wool 0
fill ~44~57~22 ~44~57~24 minecraft:wool 0
fill ~44~59~22 ~44~59~24 minecraft:wool 0
fill ~45~23~22 ~46~23~22 minecraft:stone_block_slab 5
fill ~45~33~22 ~45~33~24 minecraft:stone_stairs 0
setblock ~46~26~22 minecraft:fence 0
fill ~46~33~22 ~46~33~24 minecraft:planks 0
fill ~46~34~22 ~46~34~24 minecraft:stone_stairs 0
fill ~46~42~22 ~46~42~24 minecraft:wool 0
fill ~46~44~22 ~46~44~24 minecraft:wool 0
fill ~47~35~22 ~47~35~24 minecraft:stone_stairs 0
fill ~48~24~22 ~49~24~22 minecraft:double_stone_block_slab 0
fill ~48~25~22 ~48~25~25 minecraft:planks 0
setblock ~49~25~22 minecraft:oak_stairs 2
fill ~49~26~22 ~49~26~26 minecraft:planks 0
fill ~50~24~22 ~51~24~22 minecraft:stone_block_slab 5
fill ~50~25~22 ~51~25~22 minecraft:planks 0
setblock ~50~26~22 minecraft:oak_stairs 2
fill ~51~26~22 ~54~26~23 minecraft:planks 0
fill ~51~30~22 ~51~30~23 minecraft:wool 12
setblock ~52~25~22 minecraft:double_stone_block_slab 0
setblock ~53~25~22 minecraft:stone_block_slab 5
fill ~53~27~22 ~55~27~24 minecraft:planks 0
setblock ~53~36~22 minecraft:stone_stairs 2
fill ~53~37~22 ~53~38~22 minecraft:trapdoor 3
setblock ~53~40~22 minecraft:wool 0
setblock ~53~52~22 minecraft:wool 0
setblock ~53~53~22 minecraft:trapdoor 3
setblock ~54~41~22 minecraft:wool 0
fill ~54~49~22 ~54~51~22 minecraft:wool 0
setblock ~55~26~22 minecraft:stone_block_slab 5
fill ~55~28~22 ~56~28~22 minecraft:planks 0
fill ~55~42~22 ~55~43~22 minecraft:wool 0
fill ~55~47~22 ~55~48~22 minecraft:wool 0
setblock ~55~50~22 minecraft:wool 0
setblock ~56~27~22 minecraft:oak_stairs 5
setblock ~56~29~22 minecraft:planks 0
fill ~56~44~22 ~56~46~22 minecraft:wool 0
setblock ~56~49~22 minecraft:glowstone
setblock ~57~28~22 minecraft:oak_stairs 5
setblock ~57~29~22 minecraft:double_stone_block_slab 0
fill ~57~30~22 ~58~30~22 minecraft:planks 0
setblock ~57~48~22 minecraft:wool 0
setblock ~58~29~22 minecraft:oak_stairs 5
setblock ~58~47~22 minecraft:wool 0
setblock ~59~30~22 minecraft:oak_stairs 5
fill ~59~31~22 ~59~31~24 minecraft:planks 0
setblock ~59~46~22 minecraft:wool 0
setblock ~60~31~22 minecraft:oak_stairs 5
fill ~60~32~22 ~60~32~24 minecraft:planks 0
setblock ~60~45~22 minecraft:glowstone
setblock ~61~32~22 minecraft:oak_stairs 5
setblock ~61~33~22 minecraft:oak_stairs 3
fill ~61~36~22 ~62~36~22 minecraft:stone_block_slab 0
setblock ~61~44~22 minecraft:wool 0
setblock ~62~33~22 minecraft:planks 0
setblock ~62~34~22 minecraft:double_stone_block_slab 0
setblock ~62~43~22 minecraft:wool 0
fill ~63~33~22 ~63~33~24 minecraft:stone_block_slab 0
fill ~63~34~22 ~63~35~24 minecraft:planks 0
setblock ~63~36~22 minecraft:double_stone_block_slab 0
setblock ~63~42~22 minecraft:wool 0
fill ~64~34~22 ~64~34~24 minecraft:stone_block_slab 0
fill ~64~35~22 ~65~35~22 minecraft:stone_block_slab 0
setblock ~64~36~22 minecraft:planks 0
fill ~64~37~22 ~64~38~22 minecraft:stone_block_slab 3
setblock ~64~41~22 minecraft:glowstone
fill ~65~36~22 ~66~36~24 minecraft:stone_block_slab 0
setblock ~65~40~22 minecraft:wool 0
fill ~7~35~23 ~7~36~23 minecraft:stone_block_slab 3
setblock ~7~37~23 minecraft:glass_pane
setblock ~7~38~23 minecraft:oak_stairs 0
setblock ~7~39~23 minecraft:fence 0
setblock ~8~27~23 minecraft:stone_block_slab 3
fill ~8~28~23 ~8~28~24 minecraft:iron_bars
setblock ~8~29~23 minecraft:iron_bars
setblock ~8~30~23 minecraft:stonebrick 3
setblock ~8~31~23 minecraft:iron_bars
setblock ~8~33~23 minecraft:stone_block_slab 11
setblock ~8~35~23 minecraft:double_stone_block_slab 0
setblock ~9~27~23 minecraft:fence 0
setblock ~9~28~23 minecraft:planks 0
fill ~9~30~23 ~10~30~23 minecraft:nether_brick_fence
setblock ~9~32~23 minecraft:planks 0
setblock ~9~33~23 minecraft:fence 0
fill ~9~35~23 ~9~35~25 minecraft:planks 0
setblock ~10~28~23 minecraft:fence 0
fill ~10~32~23 ~12~32~23 minecraft:nether_brick_fence
setblock ~10~33~23 minecraft:stone_block_slab 3
setblock ~11~28~23 minecraft:double_stone_block_slab 0
setblock ~11~29~23 minecraft:nether_brick_fence
setblock ~11~30~23 minecraft:stonebrick 3
setblock ~11~31~23 minecraft:nether_brick_fence
setblock ~12~27~23 minecraft:oak_stairs 4
setblock ~12~28~23 minecraft:oak_stairs 2
fill ~12~30~23 ~14~30~23 minecraft:nether_brick_fence
fill ~12~31~23 ~12~31~27 minecraft:planks 0
setblock ~12~33~23 minecraft:stone_block_slab 3
setblock ~13~26~23 minecraft:oak_stairs 4
setblock ~13~32~23 minecraft:double_stone_block_slab 3
setblock ~14~25~23 minecraft:oak_stairs 4
setblock ~14~29~23 minecraft:stone_stairs 2
setblock ~14~32~23 minecraft:double_stone_block_slab 5
setblock ~14~33~23 minecraft:beacon
setblock ~14~39~23 minecraft:stone_stairs 0
fill ~14~40~23 ~14~41~23 minecraft:trapdoor 1
setblock ~14~43~23 minecraft:torch 2
setblock ~14~58~23 minecraft:torch 2
setblock ~14~59~23 minecraft:trapdoor 1
setblock ~15~24~23 minecraft:oak_stairs 4
setblock ~15~25~23 minecraft:stone_block_slab 0
fill ~15~28~23 ~15~28~27 minecraft:iron_bars
setblock ~15~29~23 minecraft:stone_brick_stairs 6
setblock ~15~30~23 minecraft:stonebrick 3
setblock ~15~31~23 minecraft:stone_brick_stairs 3
setblock ~15~32~23 minecraft:stone_stairs 1
setblock ~15~39~23 minecraft:glowstone
fill ~15~40~23 ~15~59~23 minecraft:log 1
setblock ~16~23~23 minecraft:stone_block_slab 5
fill ~16~24~23 ~16~24~24 minecraft:planks 0
setblock ~16~30~23 minecraft:iron_bars
setblock ~16~32~23 minecraft:stone_block_slab 5
setblock ~16~39~23 minecraft:stone_stairs 1
fill ~16~40~23 ~16~41~23 minecraft:trapdoor 0
fill ~16~42~23 ~17~42~23 minecraft:stone_block_slab 0
setblock ~16~43~23 minecraft:torch 1
fill ~16~46~23 ~16~47~23 minecraft:wool 0
setblock ~16~58~23 minecraft:torch 1
fill ~16~59~23 ~18~59~23 minecraft:iron_bars
fill ~17~23~23 ~48~23~23 minecraft:planks 0
setblock ~17~37~23 minecraft:oak_stairs 1
setblock ~18~42~23 minecraft:wool 0
setblock ~18~45~23 minecraft:wool 0
fill ~18~58~23 ~21~58~23 minecraft:iron_bars
setblock ~19~27~23 minecraft:cobblestone
setblock ~19~28~23 minecraft:fence 0
setblock ~19~30~23 minecraft:fence 0
fill ~19~43~23 ~19~43~24 minecraft:wool 0
setblock ~19~44~23 minecraft:wool 0
setblock ~20~24~23 minecraft:torch 4
fill ~20~32~23 ~20~33~23 minecraft:fence 0
fill ~20~35~23 ~20~35~25 minecraft:planks 0
setblock ~21~33~23 minecraft:fence 0
fill ~21~59~23 ~24~59~23 minecraft:iron_bars
setblock ~22~34~23 minecraft:planks 0
fill ~23~28~23 ~23~29~23 minecraft:oak_stairs 1
setblock ~24~27~23 minecraft:planks 0
setblock ~24~28~23 minecraft:tnt 0
fill ~25~27~23 ~25~27~27 minecraft:log 0
setblock ~25~31~23 minecraft:planks 0
setblock ~25~35~23 minecraft:stone_stairs 0
fill ~25~36~23 ~25~37~23 minecraft:trapdoor 1
setblock ~25~38~23 minecraft:torch 2
setblock ~25~45~23 minecraft:torch 2
setblock ~25~50~23 minecraft:torch 2
setblock ~25~59~23 minecraft:double_stone_block_slab 0
setblock ~26~31~23 minecraft:planks 2
setblock ~26~35~23 minecraft:glowstone
fill ~26~36~23 ~26~59~23 minecraft:log 1
setblock ~27~31~23 minecraft:planks 0
setblock ~27~35~23 minecraft:stone_stairs 1
fill ~27~36~23 ~27~37~23 minecraft:trapdoor 0
setblock ~27~38~23 minecraft:torch 1
setblock ~27~45~23 minecraft:torch 1
setblock ~27~50~23 minecraft:torch 1
setblock ~28~32~23 minecraft:wooden_door 2
setblock ~29~31~23 minecraft:planks 1
setblock ~29~34~23 minecraft:wall_sign 5
setblock ~29~53~23 minecraft:wool 0
setblock ~29~59~23 minecraft:wool 0
setblock ~30~29~23 minecraft:stone_block_slab 4
setblock ~30~31~23 minecraft:log 0
setblock ~30~42~23 minecraft:wool 0
setblock ~30~48~23 minecraft:wool 0
fill ~31~27~23 ~31~28~23 minecraft:wool 0
setblock ~31~29~23 minecraft:wool 15
setblock ~31~31~23 minecraft:planks 0
fill ~32~27~23 ~32~28~23 minecraft:wool 15
setblock ~32~31~23 minecraft:planks 1
setblock ~33~31~23 minecraft:log 0
setblock ~34~24~23 minecraft:torch 4
setblock ~34~31~23 minecraft:planks 0
fill ~35~28~23 ~35~28~24 minecraft:wool 6
setblock ~35~31~23 minecraft:planks 1
setblock ~36~24~23 minecraft:torch 4
setblock ~36~31~23 minecraft:log 0
setblock ~37~31~23 minecraft:planks 0
setblock ~38~31~23 minecraft:planks 1
setblock ~39~31~23 minecraft:wool 1
setblock ~39~32~23 minecraft:stone_stairs 0
fill ~39~33~23 ~39~46~23 minecraft:ladder 4
setblock ~40~24~23 minecraft:torch 4
setblock ~40~32~23 minecraft:glowstone
setblock ~40~33~23 minecraft:cobblestone
fill ~40~34~23 ~40~46~23 minecraft:log 1
setblock ~40~47~23 minecraft:oak_stairs 0
setblock ~41~31~23 minecraft:wool 1
setblock ~41~32~23 minecraft:stone_stairs 1
fill ~41~33~23 ~41~34~23 minecraft:trapdoor 0
setblock ~41~43~23 minecraft:nether_brick_fence
setblock ~41~44~23 minecraft:log 0
setblock ~41~45~23 minecraft:nether_brick_fence
setblock ~41~46~23 minecraft:log 1
setblock ~42~31~23 minecraft:log 0
setblock ~43~24~23 minecraft:torch 5
setblock ~43~31~23 minecraft:planks 0
setblock ~44~24~23 minecraft:oak_stairs 6
fill ~45~24~23 ~47~24~24 minecraft:planks 0
fill ~46~25~23 ~46~26~23 minecraft:glowstone
setblock ~48~24~23 minecraft:double_stone_block_slab 0
setblock ~48~34~23 minecraft:torch 1
fill ~49~23~23 ~50~23~23 minecraft:stone_block_slab 5
setblock ~49~24~23 minecraft:stone_block_slab 0
fill ~50~24~23 ~51~24~23 minecraft:planks 0
fill ~50~25~23 ~50~26~24 minecraft:planks 0
setblock ~50~30~23 minecraft:stone_button 4
setblock ~51~25~23 minecraft:oak_stairs 1
fill ~51~27~23 ~52~27~25 minecraft:planks 0
fill ~51~28~23 ~51~29~23 minecraft:wool 12
fill ~51~53~23 ~52~53~23 minecraft:wool 0
setblock ~52~24~23 minecraft:double_stone_block_slab 0
fill ~52~25~23 ~53~25~23 minecraft:planks 0
setblock ~52~30~23 minecraft:stone_button 5
setblock ~52~36~23 minecraft:stone_stairs 0
fill ~52~37~23 ~52~38~23 minecraft:trapdoor 1
setblock ~52~40~23 minecraft:wool 0
setblock ~52~52~23 minecraft:torch 2
setblock ~53~24~23 minecraft:stone_block_slab 5
setblock ~53~36~23 minecraft:glowstone
setblock ~53~37~23 minecraft:double_stone_block_slab 3
fill ~53~38~23 ~53~53~23 minecraft:log 1
setblock ~53~54~23 minecraft:stone_block_slab 3
setblock ~54~25~23 minecraft:double_stone_block_slab 0
setblock ~54~36~23 minecraft:stone_stairs 1
fill ~54~37~23 ~54~38~23 minecraft:trapdoor 0
fill ~54~43~23 ~56~43~23 minecraft:iron_bars
setblock ~54~44~23 minecraft:iron_bars
setblock ~54~50~23 minecraft:wool 0
fill ~54~51~23 ~55~51~23 minecraft:iron_bars
setblock ~54~52~23 minecraft:iron_bars
setblock ~54~53~23 minecraft:trapdoor 0
setblock ~55~25~23 minecraft:stone_block_slab 5
setblock ~55~26~23 minecraft:planks 0
fill ~55~50~23 ~56~50~23 minecraft:iron_bars
setblock ~56~26~23 minecraft:oak_stairs 5
