setblock ~39 ~23 ~49 furnace 5  
setblock ~49 ~23 ~45 furnace 4  
fill ~1 ~0 ~1 ~130 ~0 ~1 stained_hardened_clay 14  
fill ~1 ~0 ~2 ~1 ~16 ~2 stained_hardened_clay 14  
fill ~1 ~0 ~3 ~1 ~16 ~3 stained_hardened_clay 14  
fill ~1 ~0 ~4 ~1 ~16 ~4 stained_hardened_clay 14  
fill ~1 ~0 ~5 ~1 ~16 ~5 stained_hardened_clay 14  
fill ~1 ~0 ~6 ~1 ~16 ~6 stained_hardened_clay 14  
fill ~1 ~0 ~7 ~1 ~16 ~7 stained_hardened_clay 14  
fill ~1 ~0 ~8 ~1 ~16 ~8 stained_hardened_clay 14  
fill ~1 ~0 ~9 ~1 ~16 ~9 stained_hardened_clay 14  
fill ~1 ~0 ~10 ~1 ~16 ~10 stained_hardened_clay 14  
fill ~1 ~0 ~11 ~1 ~16 ~11 stained_hardened_clay 14  
fill ~1 ~0 ~12 ~1 ~16 ~12 stained_hardened_clay 14  
fill ~1 ~0 ~13 ~1 ~16 ~13 stained_hardened_clay 14  
fill ~1 ~0 ~14 ~1 ~16 ~14 stained_hardened_clay 14  
fill ~1 ~0 ~15 ~1 ~16 ~15 stained_hardened_clay 14  
fill ~1 ~0 ~16 ~1 ~16 ~16 stained_hardened_clay 14  
fill ~1 ~0 ~17 ~1 ~16 ~17 stained_hardened_clay 14  
fill ~1 ~0 ~18 ~1 ~16 ~18 stained_hardened_clay 14  
fill ~1 ~0 ~19 ~1 ~16 ~19 stained_hardened_clay 14  
fill ~1 ~0 ~20 ~1 ~16 ~20 stained_hardened_clay 14  
fill ~1 ~0 ~21 ~1 ~16 ~21 stained_hardened_clay 14  
fill ~1 ~0 ~22 ~1 ~16 ~22 stained_hardened_clay 14  
fill ~1 ~0 ~23 ~1 ~16 ~23 stained_hardened_clay 14  
fill ~1 ~0 ~24 ~1 ~16 ~24 stained_hardened_clay 14  
fill ~1 ~0 ~25 ~1 ~16 ~25 stained_hardened_clay 14  
fill ~1 ~0 ~26 ~1 ~16 ~26 stained_hardened_clay 14  
fill ~1 ~0 ~27 ~1 ~16 ~27 stained_hardened_clay 14  
fill ~1 ~0 ~28 ~1 ~16 ~28 stained_hardened_clay 14  
fill ~1 ~0 ~29 ~1 ~16 ~29 stained_hardened_clay 14  
fill ~1 ~0 ~30 ~1 ~16 ~30 stained_hardened_clay 14  
fill ~1 ~0 ~31 ~1 ~16 ~31 stained_hardened_clay 14  
fill ~1 ~0 ~32 ~1 ~16 ~32 stained_hardened_clay 14  
fill ~1 ~0 ~33 ~1 ~16 ~33 stained_hardened_clay 14  
fill ~1 ~0 ~34 ~1 ~16 ~34 stained_hardened_clay 14  
fill ~1 ~0 ~35 ~1 ~16 ~35 stained_hardened_clay 14  
fill ~1 ~0 ~36 ~1 ~16 ~36 stained_hardened_clay 14  
fill ~1 ~0 ~37 ~1 ~16 ~37 stained_hardened_clay 14  
fill ~1 ~0 ~38 ~1 ~16 ~38 stained_hardened_clay 14  
fill ~1 ~0 ~39 ~1 ~16 ~39 stained_hardened_clay 14  
fill ~1 ~0 ~40 ~1 ~16 ~40 stained_hardened_clay 14  
fill ~1 ~0 ~41 ~1 ~16 ~41 stained_hardened_clay 14  
fill ~1 ~0 ~42 ~1 ~16 ~42 stained_hardened_clay 14  
fill ~1 ~0 ~43 ~1 ~16 ~43 stained_hardened_clay 14  
fill ~1 ~0 ~44 ~1 ~16 ~44 stained_hardened_clay 14  
fill ~1 ~0 ~45 ~1 ~16 ~45 stained_hardened_clay 14  
fill ~1 ~0 ~46 ~1 ~16 ~46 stained_hardened_clay 14  
fill ~1 ~0 ~47 ~1 ~16 ~47 stained_hardened_clay 14  
fill ~1 ~0 ~48 ~1 ~16 ~48 stained_hardened_clay 14  
fill ~1 ~0 ~49 ~1 ~16 ~49 stained_hardened_clay 14  
fill ~1 ~0 ~50 ~1 ~16 ~50 stained_hardened_clay 14  
fill ~1 ~0 ~51 ~1 ~16 ~51 stained_hardened_clay 14  
fill ~1 ~0 ~52 ~1 ~16 ~52 stained_hardened_clay 14  
fill ~1 ~0 ~53 ~1 ~16 ~53 stained_hardened_clay 14  
fill ~1 ~0 ~54 ~1 ~16 ~54 stained_hardened_clay 14  
fill ~1 ~0 ~55 ~1 ~16 ~55 stained_hardened_clay 14  
fill ~1 ~0 ~56 ~1 ~16 ~56 stained_hardened_clay 14  
fill ~1 ~0 ~57 ~1 ~16 ~57 stained_hardened_clay 14  
fill ~1 ~0 ~58 ~1 ~16 ~58 stained_hardened_clay 14  
fill ~1 ~0 ~59 ~1 ~16 ~59 stained_hardened_clay 14  
fill ~1 ~0 ~60 ~1 ~16 ~60 stained_hardened_clay 14  
fill ~1 ~0 ~61 ~1 ~16 ~61 stained_hardened_clay 14  
fill ~1 ~0 ~62 ~1 ~16 ~62 stained_hardened_clay 14  
fill ~1 ~0 ~63 ~1 ~16 ~63 stained_hardened_clay 14  
fill ~1 ~0 ~64 ~1 ~16 ~64 stained_hardened_clay 14  
fill ~1 ~0 ~65 ~1 ~16 ~65 stained_hardened_clay 14  
fill ~1 ~0 ~66 ~1 ~16 ~66 stained_hardened_clay 14  
fill ~1 ~0 ~67 ~1 ~16 ~67 stained_hardened_clay 14  
fill ~1 ~0 ~68 ~1 ~16 ~68 stained_hardened_clay 14  
fill ~1 ~0 ~69 ~1 ~16 ~69 stained_hardened_clay 14  
fill ~1 ~0 ~70 ~1 ~16 ~70 stained_hardened_clay 14  
fill ~1 ~0 ~71 ~1 ~16 ~71 stained_hardened_clay 14  
fill ~1 ~0 ~72 ~1 ~16 ~72 stained_hardened_clay 14  
fill ~1 ~0 ~73 ~1 ~16 ~73 stained_hardened_clay 14  
fill ~1 ~0 ~74 ~1 ~16 ~74 stained_hardened_clay 14  
fill ~1 ~0 ~75 ~1 ~16 ~75 stained_hardened_clay 14  
fill ~1 ~0 ~76 ~1 ~16 ~76 stained_hardened_clay 14  
fill ~1 ~0 ~77 ~1 ~16 ~77 stained_hardened_clay 14  
fill ~1 ~0 ~78 ~1 ~16 ~78 stained_hardened_clay 14  
fill ~1 ~0 ~79 ~1 ~16 ~79 stained_hardened_clay 14  
fill ~1 ~0 ~80 ~1 ~16 ~80 stained_hardened_clay 14  
fill ~1 ~0 ~81 ~1 ~16 ~81 stained_hardened_clay 14  
fill ~1 ~0 ~82 ~1 ~16 ~82 stained_hardened_clay 14  
fill ~1 ~0 ~83 ~1 ~16 ~83 stained_hardened_clay 14  
fill ~1 ~0 ~84 ~1 ~16 ~84 stained_hardened_clay 14  
fill ~1 ~0 ~85 ~1 ~16 ~85 stained_hardened_clay 14  
fill ~1 ~0 ~86 ~1 ~16 ~86 stained_hardened_clay 14  
fill ~1 ~0 ~87 ~1 ~16 ~87 stained_hardened_clay 14  
fill ~1 ~0 ~88 ~1 ~16 ~88 stained_hardened_clay 14  
fill ~1 ~0 ~89 ~1 ~16 ~89 stained_hardened_clay 14  
fill ~1 ~0 ~90 ~1 ~16 ~90 stained_hardened_clay 14  
fill ~1 ~0 ~91 ~1 ~16 ~91 stained_hardened_clay 14  
fill ~1 ~0 ~92 ~1 ~16 ~92 stained_hardened_clay 14  
fill ~1 ~0 ~93 ~1 ~16 ~93 stained_hardened_clay 14  
fill ~1 ~0 ~94 ~1 ~16 ~94 stained_hardened_clay 14  
fill ~1 ~0 ~95 ~1 ~16 ~95 stained_hardened_clay 14  
fill ~1 ~0 ~96 ~1 ~16 ~96 stained_hardened_clay 14  
fill ~1 ~0 ~97 ~1 ~16 ~97 stained_hardened_clay 14  
fill ~1 ~0 ~98 ~1 ~16 ~98 stained_hardened_clay 14  
fill ~1 ~0 ~99 ~1 ~16 ~99 stained_hardened_clay 14  
fill ~1 ~0 ~100 ~1 ~16 ~100 stained_hardened_clay 14  
fill ~1 ~0 ~101 ~1 ~16 ~101 stained_hardened_clay 14  
fill ~1 ~0 ~102 ~1 ~16 ~102 stained_hardened_clay 14  
fill ~1 ~0 ~103 ~1 ~16 ~103 stained_hardened_clay 14  
fill ~1 ~0 ~104 ~1 ~16 ~104 stained_hardened_clay 14  
fill ~1 ~0 ~105 ~1 ~16 ~105 stained_hardened_clay 14  
fill ~1 ~0 ~106 ~1 ~16 ~106 stained_hardened_clay 14  
fill ~1 ~0 ~107 ~1 ~16 ~107 stained_hardened_clay 14  
fill ~1 ~0 ~108 ~1 ~16 ~108 stained_hardened_clay 14  
fill ~1 ~0 ~109 ~1 ~16 ~109 stained_hardened_clay 14  
fill ~1 ~0 ~110 ~1 ~16 ~110 stained_hardened_clay 14  
fill ~1 ~0 ~111 ~1 ~16 ~111 stained_hardened_clay 14  
fill ~1 ~0 ~112 ~1 ~16 ~112 stained_hardened_clay 14  
fill ~1 ~0 ~113 ~1 ~16 ~113 stained_hardened_clay 14  
fill ~1 ~0 ~114 ~1 ~16 ~114 stained_hardened_clay 14  
fill ~1 ~0 ~115 ~1 ~16 ~115 stained_hardened_clay 14  
fill ~1 ~0 ~116 ~1 ~16 ~116 stained_hardened_clay 14  
fill ~1 ~0 ~117 ~1 ~16 ~117 stained_hardened_clay 14  
fill ~1 ~0 ~118 ~1 ~16 ~118 stained_hardened_clay 14  
fill ~1 ~0 ~119 ~1 ~16 ~119 stained_hardened_clay 14  
fill ~1 ~0 ~120 ~1 ~16 ~120 stained_hardened_clay 14  
fill ~1 ~0 ~121 ~1 ~16 ~121 stained_hardened_clay 14  
fill ~1 ~0 ~122 ~1 ~16 ~122 stained_hardened_clay 14  
fill ~1 ~0 ~123 ~1 ~16 ~123 stained_hardened_clay 14  
fill ~1 ~0 ~124 ~1 ~16 ~124 stained_hardened_clay 14  
fill ~1 ~0 ~125 ~1 ~16 ~125 stained_hardened_clay 14  
fill ~1 ~0 ~126 ~1 ~16 ~126 stained_hardened_clay 14  
fill ~1 ~0 ~127 ~1 ~16 ~127 stained_hardened_clay 14  
fill ~1 ~0 ~128 ~1 ~16 ~128 stained_hardened_clay 14  
fill ~1 ~0 ~129 ~1 ~16 ~129 stained_hardened_clay 14  
fill ~1 ~0 ~130 ~130 ~0 ~130 stained_hardened_clay 14  
fill ~2 ~0 ~2 ~129 ~0 ~2 stone 0  
fill ~2 ~0 ~3 ~129 ~0 ~3 stone 0  
fill ~2 ~0 ~4 ~129 ~0 ~4 stone 0  
fill ~2 ~0 ~5 ~129 ~0 ~5 stone 0  
fill ~2 ~0 ~6 ~129 ~0 ~6 stone 0  
fill ~2 ~0 ~7 ~129 ~0 ~7 stone 0  
fill ~2 ~0 ~8 ~129 ~0 ~8 stone 0  
fill ~2 ~0 ~9 ~129 ~0 ~9 stone 0  
fill ~2 ~0 ~10 ~129 ~0 ~10 stone 0  
fill ~2 ~0 ~11 ~129 ~0 ~11 stone 0  
fill ~2 ~0 ~12 ~129 ~0 ~12 stone 0  
fill ~2 ~0 ~13 ~129 ~0 ~13 stone 0  
fill ~2 ~0 ~14 ~129 ~0 ~14 stone 0  
fill ~2 ~0 ~15 ~129 ~0 ~15 stone 0  
fill ~2 ~0 ~16 ~129 ~0 ~16 stone 0  
fill ~2 ~0 ~17 ~129 ~0 ~17 stone 0  
fill ~2 ~0 ~18 ~129 ~0 ~18 stone 0  
fill ~2 ~0 ~19 ~129 ~0 ~19 stone 0  
fill ~2 ~0 ~20 ~129 ~0 ~20 stone 0  
fill ~2 ~0 ~21 ~129 ~0 ~21 stone 0  
fill ~2 ~0 ~22 ~129 ~0 ~22 stone 0  
fill ~2 ~0 ~23 ~129 ~0 ~23 stone 0  
fill ~2 ~0 ~24 ~129 ~0 ~24 stone 0  
fill ~2 ~0 ~25 ~129 ~0 ~25 stone 0  
fill ~2 ~0 ~26 ~129 ~0 ~26 stone 0  
fill ~2 ~0 ~27 ~129 ~0 ~27 stone 0  
fill ~2 ~0 ~28 ~129 ~0 ~28 stone 0  
fill ~2 ~0 ~29 ~129 ~0 ~29 stone 0  
fill ~2 ~0 ~30 ~129 ~0 ~30 stone 0  
fill ~2 ~0 ~31 ~129 ~0 ~31 stone 0  
fill ~2 ~0 ~32 ~129 ~0 ~32 stone 0  
fill ~2 ~0 ~33 ~129 ~0 ~33 stone 0  
fill ~2 ~0 ~34 ~129 ~0 ~34 stone 0  
fill ~2 ~0 ~35 ~129 ~0 ~35 stone 0  
fill ~2 ~0 ~36 ~129 ~0 ~36 stone 0  
fill ~2 ~0 ~37 ~129 ~0 ~37 stone 0  
fill ~2 ~0 ~38 ~129 ~0 ~38 stone 0  
fill ~2 ~0 ~39 ~129 ~0 ~39 stone 0  
fill ~2 ~0 ~40 ~129 ~0 ~40 stone 0  
fill ~2 ~0 ~41 ~129 ~0 ~41 stone 0  
fill ~2 ~0 ~42 ~129 ~0 ~42 stone 0  
fill ~2 ~0 ~43 ~129 ~0 ~43 stone 0  
fill ~2 ~0 ~44 ~129 ~0 ~44 stone 0  
fill ~2 ~0 ~45 ~129 ~0 ~45 stone 0  
fill ~2 ~0 ~46 ~129 ~0 ~46 stone 0  
fill ~2 ~0 ~47 ~129 ~0 ~47 stone 0  
fill ~2 ~0 ~48 ~129 ~0 ~48 stone 0  
fill ~2 ~0 ~49 ~129 ~0 ~49 stone 0  
fill ~2 ~0 ~50 ~129 ~0 ~50 stone 0  
fill ~2 ~0 ~51 ~129 ~0 ~51 stone 0  
fill ~2 ~0 ~52 ~129 ~0 ~52 stone 0  
fill ~2 ~0 ~53 ~129 ~0 ~53 stone 0  
fill ~2 ~0 ~54 ~129 ~0 ~54 stone 0  
fill ~2 ~0 ~55 ~129 ~0 ~55 stone 0  
fill ~2 ~0 ~56 ~129 ~0 ~56 stone 0  
fill ~2 ~0 ~57 ~129 ~0 ~57 stone 0  
fill ~2 ~0 ~58 ~129 ~0 ~58 stone 0  
fill ~2 ~0 ~59 ~129 ~0 ~59 stone 0  
fill ~2 ~0 ~60 ~129 ~0 ~60 stone 0  
fill ~2 ~0 ~61 ~129 ~0 ~61 stone 0  
fill ~2 ~0 ~62 ~129 ~0 ~62 stone 0  
fill ~2 ~0 ~63 ~129 ~0 ~63 stone 0  
fill ~2 ~0 ~64 ~129 ~0 ~64 stone 0  
fill ~2 ~0 ~65 ~129 ~0 ~65 stone 0  
fill ~2 ~0 ~66 ~129 ~0 ~66 stone 0  
fill ~2 ~0 ~67 ~129 ~0 ~67 stone 0  
fill ~2 ~0 ~68 ~129 ~0 ~68 stone 0  
fill ~2 ~0 ~69 ~129 ~0 ~69 stone 0  
fill ~2 ~0 ~70 ~129 ~0 ~70 stone 0  
fill ~2 ~0 ~71 ~129 ~0 ~71 stone 0  
fill ~2 ~0 ~72 ~129 ~0 ~72 stone 0  
fill ~2 ~0 ~73 ~129 ~0 ~73 stone 0  
fill ~2 ~0 ~74 ~129 ~0 ~74 stone 0  
fill ~2 ~0 ~75 ~129 ~0 ~75 stone 0  
fill ~2 ~0 ~76 ~129 ~0 ~76 stone 0  
fill ~2 ~0 ~77 ~129 ~0 ~77 stone 0  
fill ~2 ~0 ~78 ~129 ~0 ~78 stone 0  
fill ~2 ~0 ~79 ~129 ~0 ~79 stone 0  
fill ~2 ~0 ~80 ~129 ~0 ~80 stone 0  
fill ~2 ~0 ~81 ~129 ~0 ~81 stone 0  
fill ~2 ~0 ~82 ~129 ~0 ~82 stone 0  
fill ~2 ~0 ~83 ~129 ~0 ~83 stone 0  
fill ~2 ~0 ~84 ~129 ~0 ~84 stone 0  
fill ~2 ~0 ~85 ~129 ~0 ~85 stone 0  
fill ~2 ~0 ~86 ~129 ~0 ~86 stone 0  
fill ~2 ~0 ~87 ~129 ~0 ~87 stone 0  
fill ~2 ~0 ~88 ~129 ~0 ~88 stone 0  
fill ~2 ~0 ~89 ~129 ~0 ~89 stone 0  
fill ~2 ~0 ~90 ~129 ~0 ~90 stone 0  
fill ~2 ~0 ~91 ~129 ~0 ~91 stone 0  
fill ~2 ~0 ~92 ~129 ~0 ~92 stone 0  
fill ~2 ~0 ~93 ~129 ~0 ~93 stone 0  
fill ~2 ~0 ~94 ~129 ~0 ~94 stone 0  
fill ~2 ~0 ~95 ~129 ~0 ~95 stone 0  
fill ~2 ~0 ~96 ~129 ~0 ~96 stone 0  
fill ~2 ~0 ~97 ~129 ~0 ~97 stone 0  
fill ~2 ~0 ~98 ~129 ~0 ~98 stone 0  
fill ~2 ~0 ~99 ~129 ~0 ~99 stone 0  
fill ~2 ~0 ~100 ~129 ~0 ~100 stone 0  
fill ~2 ~0 ~101 ~129 ~0 ~101 stone 0  
fill ~2 ~0 ~102 ~129 ~0 ~102 stone 0  
fill ~2 ~0 ~103 ~129 ~0 ~103 stone 0  
fill ~2 ~0 ~104 ~129 ~0 ~104 stone 0  
fill ~2 ~0 ~105 ~129 ~0 ~105 stone 0  
fill ~2 ~0 ~106 ~129 ~0 ~106 stone 0  
fill ~2 ~0 ~107 ~129 ~0 ~107 stone 0  
fill ~2 ~0 ~108 ~129 ~0 ~108 stone 0  
fill ~2 ~0 ~109 ~129 ~0 ~109 stone 0  
fill ~2 ~0 ~110 ~129 ~0 ~110 stone 0  
fill ~2 ~0 ~111 ~129 ~0 ~111 stone 0  
fill ~2 ~0 ~112 ~129 ~0 ~112 stone 0  
fill ~2 ~0 ~113 ~129 ~0 ~113 stone 0  
fill ~2 ~0 ~114 ~129 ~0 ~114 stone 0  
fill ~2 ~0 ~115 ~129 ~0 ~115 stone 0  
fill ~2 ~0 ~116 ~129 ~0 ~116 stone 0  
fill ~2 ~0 ~117 ~129 ~0 ~117 stone 0  
fill ~2 ~0 ~118 ~129 ~0 ~118 stone 0  
fill ~2 ~0 ~119 ~129 ~0 ~119 stone 0  
fill ~2 ~0 ~120 ~129 ~0 ~120 stone 0  
fill ~2 ~0 ~121 ~129 ~0 ~121 stone 0  
fill ~2 ~0 ~122 ~129 ~0 ~122 stone 0  
fill ~2 ~0 ~123 ~129 ~0 ~123 stone 0  
fill ~2 ~0 ~124 ~129 ~0 ~124 stone 0  
fill ~2 ~0 ~125 ~129 ~0 ~125 stone 0  
fill ~2 ~0 ~126 ~129 ~0 ~126 stone 0  
fill ~2 ~0 ~127 ~129 ~0 ~127 stone 0  
fill ~2 ~0 ~128 ~129 ~0 ~128 stone 0  
fill ~2 ~0 ~129 ~129 ~0 ~129 stone 0  
fill ~130 ~0 ~2 ~130 ~16 ~2 stained_hardened_clay 14  
fill ~130 ~0 ~3 ~130 ~16 ~3 stained_hardened_clay 14  
fill ~130 ~0 ~4 ~130 ~16 ~4 stained_hardened_clay 14  
fill ~130 ~0 ~5 ~130 ~16 ~5 stained_hardened_clay 14  
fill ~130 ~0 ~6 ~130 ~16 ~6 stained_hardened_clay 14  
fill ~130 ~0 ~7 ~130 ~16 ~7 stained_hardened_clay 14  
fill ~130 ~0 ~8 ~130 ~16 ~8 stained_hardened_clay 14  
fill ~130 ~0 ~9 ~130 ~16 ~9 stained_hardened_clay 14  
fill ~130 ~0 ~10 ~130 ~16 ~10 stained_hardened_clay 14  
fill ~130 ~0 ~11 ~130 ~16 ~11 stained_hardened_clay 14  
fill ~130 ~0 ~12 ~130 ~16 ~12 stained_hardened_clay 14  
fill ~130 ~0 ~13 ~130 ~16 ~13 stained_hardened_clay 14  
fill ~130 ~0 ~14 ~130 ~16 ~14 stained_hardened_clay 14  
fill ~130 ~0 ~15 ~130 ~16 ~15 stained_hardened_clay 14  
fill ~130 ~0 ~16 ~130 ~16 ~16 stained_hardened_clay 14  
fill ~130 ~0 ~17 ~130 ~16 ~17 stained_hardened_clay 14  
fill ~130 ~0 ~18 ~130 ~16 ~18 stained_hardened_clay 14  
fill ~130 ~0 ~19 ~130 ~16 ~19 stained_hardened_clay 14  
fill ~130 ~0 ~20 ~130 ~16 ~20 stained_hardened_clay 14  
fill ~130 ~0 ~21 ~130 ~16 ~21 stained_hardened_clay 14  
fill ~130 ~0 ~22 ~130 ~16 ~22 stained_hardened_clay 14  
fill ~130 ~0 ~23 ~130 ~16 ~23 stained_hardened_clay 14  
fill ~130 ~0 ~24 ~130 ~16 ~24 stained_hardened_clay 14  
fill ~130 ~0 ~25 ~130 ~16 ~25 stained_hardened_clay 14  
fill ~130 ~0 ~26 ~130 ~16 ~26 stained_hardened_clay 14  
fill ~130 ~0 ~27 ~130 ~16 ~27 stained_hardened_clay 14  
fill ~130 ~0 ~28 ~130 ~16 ~28 stained_hardened_clay 14  
fill ~130 ~0 ~29 ~130 ~16 ~29 stained_hardened_clay 14  
fill ~130 ~0 ~30 ~130 ~16 ~30 stained_hardened_clay 14  
fill ~130 ~0 ~31 ~130 ~16 ~31 stained_hardened_clay 14  
fill ~130 ~0 ~32 ~130 ~16 ~32 stained_hardened_clay 14  
fill ~130 ~0 ~33 ~130 ~16 ~33 stained_hardened_clay 14  
fill ~130 ~0 ~34 ~130 ~16 ~34 stained_hardened_clay 14  
fill ~130 ~0 ~35 ~130 ~16 ~35 stained_hardened_clay 14  
fill ~130 ~0 ~36 ~130 ~16 ~36 stained_hardened_clay 14  
fill ~130 ~0 ~37 ~130 ~16 ~37 stained_hardened_clay 14  
fill ~130 ~0 ~38 ~130 ~16 ~38 stained_hardened_clay 14  
fill ~130 ~0 ~39 ~130 ~16 ~39 stained_hardened_clay 14  
fill ~130 ~0 ~40 ~130 ~16 ~40 stained_hardened_clay 14  
fill ~130 ~0 ~41 ~130 ~16 ~41 stained_hardened_clay 14  
fill ~130 ~0 ~42 ~130 ~16 ~42 stained_hardened_clay 14  
fill ~130 ~0 ~43 ~130 ~16 ~43 stained_hardened_clay 14  
fill ~130 ~0 ~44 ~130 ~16 ~44 stained_hardened_clay 14  
fill ~130 ~0 ~45 ~130 ~16 ~45 stained_hardened_clay 14  
fill ~130 ~0 ~46 ~130 ~16 ~46 stained_hardened_clay 14  
fill ~130 ~0 ~47 ~130 ~16 ~47 stained_hardened_clay 14  
fill ~130 ~0 ~48 ~130 ~16 ~48 stained_hardened_clay 14  
fill ~130 ~0 ~49 ~130 ~16 ~49 stained_hardened_clay 14  
fill ~130 ~0 ~50 ~130 ~16 ~50 stained_hardened_clay 14  
fill ~130 ~0 ~51 ~130 ~16 ~51 stained_hardened_clay 14  
fill ~130 ~0 ~52 ~130 ~16 ~52 stained_hardened_clay 14  
fill ~130 ~0 ~53 ~130 ~16 ~53 stained_hardened_clay 14  
fill ~130 ~0 ~54 ~130 ~16 ~54 stained_hardened_clay 14  
fill ~130 ~0 ~55 ~130 ~16 ~55 stained_hardened_clay 14  
fill ~130 ~0 ~56 ~130 ~16 ~56 stained_hardened_clay 14  
fill ~130 ~0 ~57 ~130 ~16 ~57 stained_hardened_clay 14  
fill ~130 ~0 ~58 ~130 ~16 ~58 stained_hardened_clay 14  
fill ~130 ~0 ~59 ~130 ~16 ~59 stained_hardened_clay 14  
fill ~130 ~0 ~60 ~130 ~16 ~60 stained_hardened_clay 14  
fill ~130 ~0 ~61 ~130 ~16 ~61 stained_hardened_clay 14  
fill ~130 ~0 ~62 ~130 ~16 ~62 stained_hardened_clay 14  
fill ~130 ~0 ~63 ~130 ~16 ~63 stained_hardened_clay 14  
fill ~130 ~0 ~64 ~130 ~16 ~64 stained_hardened_clay 14  
fill ~130 ~0 ~65 ~130 ~16 ~65 stained_hardened_clay 14  
fill ~130 ~0 ~66 ~130 ~16 ~66 stained_hardened_clay 14  
fill ~130 ~0 ~67 ~130 ~16 ~67 stained_hardened_clay 14  
fill ~130 ~0 ~68 ~130 ~16 ~68 stained_hardened_clay 14  
fill ~130 ~0 ~69 ~130 ~16 ~69 stained_hardened_clay 14  
fill ~130 ~0 ~70 ~130 ~16 ~70 stained_hardened_clay 14  
fill ~130 ~0 ~71 ~130 ~16 ~71 stained_hardened_clay 14  
fill ~130 ~0 ~72 ~130 ~16 ~72 stained_hardened_clay 14  
fill ~130 ~0 ~73 ~130 ~16 ~73 stained_hardened_clay 14  
fill ~130 ~0 ~74 ~130 ~16 ~74 stained_hardened_clay 14  
fill ~130 ~0 ~75 ~130 ~16 ~75 stained_hardened_clay 14  
fill ~130 ~0 ~76 ~130 ~16 ~76 stained_hardened_clay 14  
fill ~130 ~0 ~77 ~130 ~16 ~77 stained_hardened_clay 14  
fill ~130 ~0 ~78 ~130 ~16 ~78 stained_hardened_clay 14  
fill ~130 ~0 ~79 ~130 ~16 ~79 stained_hardened_clay 14  
fill ~130 ~0 ~80 ~130 ~16 ~80 stained_hardened_clay 14  
fill ~130 ~0 ~81 ~130 ~16 ~81 stained_hardened_clay 14  
fill ~130 ~0 ~82 ~130 ~16 ~82 stained_hardened_clay 14  
fill ~130 ~0 ~83 ~130 ~16 ~83 stained_hardened_clay 14  
fill ~130 ~0 ~84 ~130 ~16 ~84 stained_hardened_clay 14  
fill ~130 ~0 ~85 ~130 ~16 ~85 stained_hardened_clay 14  
fill ~130 ~0 ~86 ~130 ~16 ~86 stained_hardened_clay 14  
fill ~130 ~0 ~87 ~130 ~16 ~87 stained_hardened_clay 14  
fill ~130 ~0 ~88 ~130 ~16 ~88 stained_hardened_clay 14  
fill ~130 ~0 ~89 ~130 ~16 ~89 stained_hardened_clay 14  
fill ~130 ~0 ~90 ~130 ~16 ~90 stained_hardened_clay 14  
fill ~130 ~0 ~91 ~130 ~16 ~91 stained_hardened_clay 14  
fill ~130 ~0 ~92 ~130 ~16 ~92 stained_hardened_clay 14  
fill ~130 ~0 ~93 ~130 ~16 ~93 stained_hardened_clay 14  
fill ~130 ~0 ~94 ~130 ~16 ~94 stained_hardened_clay 14  
fill ~130 ~0 ~95 ~130 ~16 ~95 stained_hardened_clay 14  
fill ~130 ~0 ~96 ~130 ~16 ~96 stained_hardened_clay 14  
fill ~130 ~0 ~97 ~130 ~16 ~97 stained_hardened_clay 14  
fill ~130 ~0 ~98 ~130 ~16 ~98 stained_hardened_clay 14  
fill ~130 ~0 ~99 ~130 ~16 ~99 stained_hardened_clay 14  
fill ~130 ~0 ~100 ~130 ~16 ~100 stained_hardened_clay 14  
fill ~130 ~0 ~101 ~130 ~16 ~101 stained_hardened_clay 14  
fill ~130 ~0 ~102 ~130 ~16 ~102 stained_hardened_clay 14  
fill ~130 ~0 ~103 ~130 ~16 ~103 stained_hardened_clay 14  
fill ~130 ~0 ~104 ~130 ~16 ~104 stained_hardened_clay 14  
fill ~130 ~0 ~105 ~130 ~16 ~105 stained_hardened_clay 14  
fill ~130 ~0 ~106 ~130 ~16 ~106 stained_hardened_clay 14  
fill ~130 ~0 ~107 ~130 ~16 ~107 stained_hardened_clay 14  
fill ~130 ~0 ~108 ~130 ~16 ~108 stained_hardened_clay 14  
fill ~130 ~0 ~109 ~130 ~16 ~109 stained_hardened_clay 14  
fill ~130 ~0 ~110 ~130 ~16 ~110 stained_hardened_clay 14  
fill ~130 ~0 ~111 ~130 ~16 ~111 stained_hardened_clay 14  
fill ~130 ~0 ~112 ~130 ~16 ~112 stained_hardened_clay 14  
fill ~130 ~0 ~113 ~130 ~16 ~113 stained_hardened_clay 14  
fill ~130 ~0 ~114 ~130 ~16 ~114 stained_hardened_clay 14  
fill ~130 ~0 ~115 ~130 ~16 ~115 stained_hardened_clay 14  
fill ~130 ~0 ~116 ~130 ~16 ~116 stained_hardened_clay 14  
fill ~130 ~0 ~117 ~130 ~16 ~117 stained_hardened_clay 14  
fill ~130 ~0 ~118 ~130 ~16 ~118 stained_hardened_clay 14  
fill ~130 ~0 ~119 ~130 ~16 ~119 stained_hardened_clay 14  
fill ~130 ~0 ~120 ~130 ~16 ~120 stained_hardened_clay 14  
fill ~130 ~0 ~121 ~130 ~16 ~121 stained_hardened_clay 14  
fill ~130 ~0 ~122 ~130 ~16 ~122 stained_hardened_clay 14  
fill ~130 ~0 ~123 ~130 ~16 ~123 stained_hardened_clay 14  
fill ~130 ~0 ~124 ~130 ~16 ~124 stained_hardened_clay 14  
fill ~130 ~0 ~125 ~130 ~16 ~125 stained_hardened_clay 14  
fill ~130 ~0 ~126 ~130 ~16 ~126 stained_hardened_clay 14  
fill ~130 ~0 ~127 ~130 ~16 ~127 stained_hardened_clay 14  
fill ~130 ~0 ~128 ~130 ~16 ~128 stained_hardened_clay 14  
fill ~130 ~0 ~129 ~130 ~16 ~129 stained_hardened_clay 14  
fill ~1 ~1 ~1 ~130 ~1 ~1 stained_hardened_clay 14  
fill ~1 ~1 ~130 ~130 ~1 ~130 stained_hardened_clay 14  
fill ~2 ~1 ~2 ~129 ~1 ~2 stone 0  
fill ~2 ~1 ~3 ~129 ~1 ~3 stone 0  
fill ~2 ~1 ~4 ~129 ~1 ~4 stone 0  
fill ~2 ~1 ~5 ~129 ~1 ~5 stone 0  
fill ~2 ~1 ~6 ~129 ~1 ~6 stone 0  
fill ~2 ~1 ~7 ~129 ~1 ~7 stone 0  
fill ~2 ~1 ~8 ~129 ~1 ~8 stone 0  
fill ~2 ~1 ~9 ~129 ~1 ~9 stone 0  
fill ~2 ~1 ~10 ~129 ~1 ~10 stone 0  
fill ~2 ~1 ~11 ~129 ~1 ~11 stone 0  
fill ~2 ~1 ~12 ~129 ~1 ~12 stone 0  
fill ~2 ~1 ~13 ~129 ~1 ~13 stone 0  
fill ~2 ~1 ~14 ~129 ~1 ~14 stone 0  
fill ~2 ~1 ~15 ~129 ~1 ~15 stone 0  
fill ~2 ~1 ~16 ~129 ~1 ~16 stone 0  
fill ~2 ~1 ~17 ~129 ~1 ~17 stone 0  
fill ~2 ~1 ~18 ~129 ~1 ~18 stone 0  
fill ~2 ~1 ~19 ~129 ~1 ~19 stone 0  
fill ~2 ~1 ~20 ~129 ~1 ~20 stone 0  
fill ~2 ~1 ~21 ~129 ~1 ~21 stone 0  
fill ~2 ~1 ~22 ~129 ~1 ~22 stone 0  
fill ~2 ~1 ~23 ~129 ~1 ~23 stone 0  
fill ~2 ~1 ~24 ~129 ~1 ~24 stone 0  
fill ~2 ~1 ~25 ~129 ~1 ~25 stone 0  
fill ~2 ~1 ~26 ~129 ~1 ~26 stone 0  
fill ~2 ~1 ~27 ~129 ~1 ~27 stone 0  
fill ~2 ~1 ~28 ~129 ~1 ~28 stone 0  
fill ~2 ~1 ~29 ~129 ~1 ~29 stone 0  
fill ~2 ~1 ~30 ~129 ~1 ~30 stone 0  
fill ~2 ~1 ~31 ~129 ~1 ~31 stone 0  
fill ~2 ~1 ~32 ~129 ~1 ~32 stone 0  
fill ~2 ~1 ~33 ~129 ~1 ~33 stone 0  
fill ~2 ~1 ~34 ~129 ~1 ~34 stone 0  
fill ~2 ~1 ~35 ~129 ~1 ~35 stone 0  
fill ~2 ~1 ~36 ~129 ~1 ~36 stone 0  
fill ~2 ~1 ~37 ~129 ~1 ~37 stone 0  
fill ~2 ~1 ~38 ~129 ~1 ~38 stone 0  
fill ~2 ~1 ~39 ~129 ~1 ~39 stone 0  
fill ~2 ~1 ~40 ~129 ~1 ~40 stone 0  
fill ~2 ~1 ~41 ~129 ~1 ~41 stone 0  
fill ~2 ~1 ~42 ~129 ~1 ~42 stone 0  
fill ~2 ~1 ~43 ~129 ~1 ~43 stone 0  
fill ~2 ~1 ~44 ~129 ~1 ~44 stone 0  
fill ~2 ~1 ~45 ~129 ~1 ~45 stone 0  
fill ~2 ~1 ~46 ~129 ~1 ~46 stone 0  
fill ~2 ~1 ~47 ~129 ~1 ~47 stone 0  
fill ~2 ~1 ~48 ~129 ~1 ~48 stone 0  
fill ~2 ~1 ~49 ~129 ~1 ~49 stone 0  
fill ~2 ~1 ~50 ~129 ~1 ~50 stone 0  
fill ~2 ~1 ~51 ~129 ~1 ~51 stone 0  
fill ~2 ~1 ~52 ~129 ~1 ~52 stone 0  
fill ~2 ~1 ~53 ~129 ~1 ~53 stone 0  
fill ~2 ~1 ~54 ~129 ~1 ~54 stone 0  
fill ~2 ~1 ~55 ~129 ~1 ~55 stone 0  
fill ~2 ~1 ~56 ~129 ~1 ~56 stone 0  
fill ~2 ~1 ~57 ~129 ~1 ~57 stone 0  
fill ~2 ~1 ~58 ~129 ~1 ~58 stone 0  
fill ~2 ~1 ~59 ~129 ~1 ~59 stone 0  
fill ~2 ~1 ~60 ~129 ~1 ~60 stone 0  
fill ~2 ~1 ~61 ~129 ~1 ~61 stone 0  
fill ~2 ~1 ~62 ~129 ~1 ~62 stone 0  
fill ~2 ~1 ~63 ~129 ~1 ~63 stone 0  
fill ~2 ~1 ~64 ~129 ~1 ~64 stone 0  
fill ~2 ~1 ~65 ~129 ~1 ~65 stone 0  
fill ~2 ~1 ~66 ~129 ~1 ~66 stone 0  
fill ~2 ~1 ~67 ~129 ~1 ~67 stone 0  
fill ~2 ~1 ~68 ~129 ~1 ~68 stone 0  
fill ~2 ~1 ~69 ~129 ~1 ~69 stone 0  
fill ~2 ~1 ~70 ~129 ~1 ~70 stone 0  
fill ~2 ~1 ~71 ~129 ~1 ~71 stone 0  
fill ~2 ~1 ~72 ~129 ~1 ~72 stone 0  
fill ~2 ~1 ~73 ~129 ~1 ~73 stone 0  
fill ~2 ~1 ~74 ~129 ~1 ~74 stone 0  
fill ~2 ~1 ~75 ~129 ~1 ~75 stone 0  
fill ~2 ~1 ~76 ~129 ~1 ~76 stone 0  
fill ~2 ~1 ~77 ~129 ~1 ~77 stone 0  
fill ~2 ~1 ~78 ~129 ~1 ~78 stone 0  
fill ~2 ~1 ~79 ~129 ~1 ~79 stone 0  
fill ~2 ~1 ~80 ~129 ~1 ~80 stone 0  
fill ~2 ~1 ~81 ~129 ~1 ~81 stone 0  
fill ~2 ~1 ~82 ~129 ~1 ~82 stone 0  
fill ~2 ~1 ~83 ~129 ~1 ~83 stone 0  
fill ~2 ~1 ~84 ~129 ~1 ~84 stone 0  
fill ~2 ~1 ~85 ~129 ~1 ~85 stone 0  
fill ~2 ~1 ~86 ~129 ~1 ~86 stone 0  
fill ~2 ~1 ~87 ~129 ~1 ~87 stone 0  
fill ~2 ~1 ~88 ~129 ~1 ~88 stone 0  
fill ~2 ~1 ~89 ~129 ~1 ~89 stone 0  
fill ~2 ~1 ~90 ~129 ~1 ~90 stone 0  
fill ~2 ~1 ~91 ~129 ~1 ~91 stone 0  
fill ~2 ~1 ~92 ~129 ~1 ~92 stone 0  
fill ~2 ~1 ~93 ~129 ~1 ~93 stone 0  
fill ~2 ~1 ~94 ~129 ~1 ~94 stone 0  
fill ~2 ~1 ~95 ~129 ~1 ~95 stone 0  
fill ~2 ~1 ~96 ~129 ~1 ~96 stone 0  
fill ~2 ~1 ~97 ~129 ~1 ~97 stone 0  
fill ~2 ~1 ~98 ~129 ~1 ~98 stone 0  
fill ~2 ~1 ~99 ~129 ~1 ~99 stone 0  
fill ~2 ~1 ~100 ~129 ~1 ~100 stone 0  
fill ~2 ~1 ~101 ~129 ~1 ~101 stone 0  
fill ~2 ~1 ~102 ~129 ~1 ~102 stone 0  
fill ~2 ~1 ~103 ~129 ~1 ~103 stone 0  
fill ~2 ~1 ~104 ~129 ~1 ~104 stone 0  
fill ~2 ~1 ~105 ~129 ~1 ~105 stone 0  
fill ~2 ~1 ~106 ~129 ~1 ~106 stone 0  
fill ~2 ~1 ~107 ~129 ~1 ~107 stone 0  
fill ~2 ~1 ~108 ~129 ~1 ~108 stone 0  
fill ~2 ~1 ~109 ~129 ~1 ~109 stone 0  
fill ~2 ~1 ~110 ~129 ~1 ~110 stone 0  
fill ~2 ~1 ~111 ~129 ~1 ~111 stone 0  
fill ~2 ~1 ~112 ~129 ~1 ~112 stone 0  
fill ~2 ~1 ~113 ~129 ~1 ~113 stone 0  
fill ~2 ~1 ~114 ~129 ~1 ~114 stone 0  
fill ~2 ~1 ~115 ~129 ~1 ~115 stone 0  
fill ~2 ~1 ~116 ~129 ~1 ~116 stone 0  
fill ~2 ~1 ~117 ~129 ~1 ~117 stone 0  
fill ~2 ~1 ~118 ~129 ~1 ~118 stone 0  
fill ~2 ~1 ~119 ~129 ~1 ~119 stone 0  
fill ~2 ~1 ~120 ~129 ~1 ~120 stone 0  
fill ~2 ~1 ~121 ~129 ~1 ~121 stone 0  
fill ~2 ~1 ~122 ~129 ~1 ~122 stone 0  
fill ~2 ~1 ~123 ~129 ~1 ~123 stone 0  
fill ~2 ~1 ~124 ~129 ~1 ~124 stone 0  
fill ~2 ~1 ~125 ~129 ~1 ~125 stone 0  
fill ~2 ~1 ~126 ~129 ~1 ~126 stone 0  
fill ~2 ~1 ~127 ~129 ~1 ~127 stone 0  
fill ~2 ~1 ~128 ~129 ~1 ~128 stone 0  
fill ~2 ~1 ~129 ~129 ~1 ~129 stone 0  
fill ~1 ~2 ~1 ~130 ~2 ~1 stained_hardened_clay 14  
fill ~1 ~2 ~130 ~130 ~2 ~130 stained_hardened_clay 14  
fill ~2 ~2 ~2 ~129 ~2 ~2 stone 0  
fill ~2 ~2 ~3 ~129 ~2 ~3 stone 0  
fill ~2 ~2 ~4 ~129 ~2 ~4 stone 0  
fill ~2 ~2 ~5 ~129 ~2 ~5 stone 0  
fill ~2 ~2 ~6 ~129 ~2 ~6 stone 0  
fill ~2 ~2 ~7 ~129 ~2 ~7 stone 0  
fill ~2 ~2 ~8 ~129 ~2 ~8 stone 0  
fill ~2 ~2 ~9 ~129 ~2 ~9 stone 0  
fill ~2 ~2 ~10 ~129 ~2 ~10 stone 0  
fill ~2 ~2 ~11 ~129 ~2 ~11 stone 0  
fill ~2 ~2 ~12 ~129 ~2 ~12 stone 0  
fill ~2 ~2 ~13 ~129 ~2 ~13 stone 0  
fill ~2 ~2 ~14 ~129 ~2 ~14 stone 0  
fill ~2 ~2 ~15 ~129 ~2 ~15 stone 0  
fill ~2 ~2 ~16 ~129 ~2 ~16 stone 0  
fill ~2 ~2 ~17 ~129 ~2 ~17 stone 0  
fill ~2 ~2 ~18 ~129 ~2 ~18 stone 0  
fill ~2 ~2 ~19 ~129 ~2 ~19 stone 0  
fill ~2 ~2 ~20 ~129 ~2 ~20 stone 0  
fill ~2 ~2 ~21 ~129 ~2 ~21 stone 0  
fill ~2 ~2 ~22 ~129 ~2 ~22 stone 0  
fill ~2 ~2 ~23 ~129 ~2 ~23 stone 0  
fill ~2 ~2 ~24 ~129 ~2 ~24 stone 0  
fill ~2 ~2 ~25 ~129 ~2 ~25 stone 0  
fill ~2 ~2 ~26 ~129 ~2 ~26 stone 0  
fill ~2 ~2 ~27 ~129 ~2 ~27 stone 0  
fill ~2 ~2 ~28 ~129 ~2 ~28 stone 0  
fill ~2 ~2 ~29 ~129 ~2 ~29 stone 0  
fill ~2 ~2 ~30 ~129 ~2 ~30 stone 0  
fill ~2 ~2 ~31 ~129 ~2 ~31 stone 0  
fill ~2 ~2 ~32 ~129 ~2 ~32 stone 0  
fill ~2 ~2 ~33 ~129 ~2 ~33 stone 0  
fill ~2 ~2 ~34 ~129 ~2 ~34 stone 0  
fill ~2 ~2 ~35 ~129 ~2 ~35 stone 0  
fill ~2 ~2 ~36 ~129 ~2 ~36 stone 0  
fill ~2 ~2 ~37 ~129 ~2 ~37 stone 0  
fill ~2 ~2 ~38 ~129 ~2 ~38 stone 0  
fill ~2 ~2 ~39 ~129 ~2 ~39 stone 0  
fill ~2 ~2 ~40 ~129 ~2 ~40 stone 0  
fill ~2 ~2 ~41 ~129 ~2 ~41 stone 0  
fill ~2 ~2 ~42 ~129 ~2 ~42 stone 0  
fill ~2 ~2 ~43 ~129 ~2 ~43 stone 0  
fill ~2 ~2 ~44 ~129 ~2 ~44 stone 0  
fill ~2 ~2 ~45 ~129 ~2 ~45 stone 0  
fill ~2 ~2 ~46 ~129 ~2 ~46 stone 0  
fill ~2 ~2 ~47 ~129 ~2 ~47 stone 0  
fill ~2 ~2 ~48 ~129 ~2 ~48 stone 0  
fill ~2 ~2 ~49 ~129 ~2 ~49 stone 0  
fill ~2 ~2 ~50 ~129 ~2 ~50 stone 0  
fill ~2 ~2 ~51 ~129 ~2 ~51 stone 0  
fill ~2 ~2 ~52 ~129 ~2 ~52 stone 0  
fill ~2 ~2 ~53 ~129 ~2 ~53 stone 0  
fill ~2 ~2 ~54 ~129 ~2 ~54 stone 0  
fill ~2 ~2 ~55 ~129 ~2 ~55 stone 0  
fill ~2 ~2 ~56 ~129 ~2 ~56 stone 0  
fill ~2 ~2 ~57 ~129 ~2 ~57 stone 0  
fill ~2 ~2 ~58 ~129 ~2 ~58 stone 0  
fill ~2 ~2 ~59 ~129 ~2 ~59 stone 0  
fill ~2 ~2 ~60 ~129 ~2 ~60 stone 0  
fill ~2 ~2 ~61 ~129 ~2 ~61 stone 0  
fill ~2 ~2 ~62 ~129 ~2 ~62 stone 0  
fill ~2 ~2 ~63 ~129 ~2 ~63 stone 0  
fill ~2 ~2 ~64 ~129 ~2 ~64 stone 0  
fill ~2 ~2 ~65 ~129 ~2 ~65 stone 0  
fill ~2 ~2 ~66 ~129 ~2 ~66 stone 0  
fill ~2 ~2 ~67 ~129 ~2 ~67 stone 0  
fill ~2 ~2 ~68 ~129 ~2 ~68 stone 0  
fill ~2 ~2 ~69 ~129 ~2 ~69 stone 0  
fill ~2 ~2 ~70 ~129 ~2 ~70 stone 0  
fill ~2 ~2 ~71 ~129 ~2 ~71 stone 0  
fill ~2 ~2 ~72 ~129 ~2 ~72 stone 0  
fill ~2 ~2 ~73 ~129 ~2 ~73 stone 0  
fill ~2 ~2 ~74 ~129 ~2 ~74 stone 0  
fill ~2 ~2 ~75 ~129 ~2 ~75 stone 0  
fill ~2 ~2 ~76 ~129 ~2 ~76 stone 0  
fill ~2 ~2 ~77 ~129 ~2 ~77 stone 0  
fill ~2 ~2 ~78 ~129 ~2 ~78 stone 0  
fill ~2 ~2 ~79 ~129 ~2 ~79 stone 0  
fill ~2 ~2 ~80 ~129 ~2 ~80 stone 0  
fill ~2 ~2 ~81 ~129 ~2 ~81 stone 0  
fill ~2 ~2 ~82 ~129 ~2 ~82 stone 0  
fill ~2 ~2 ~83 ~129 ~2 ~83 stone 0  
fill ~2 ~2 ~84 ~129 ~2 ~84 stone 0  
fill ~2 ~2 ~85 ~129 ~2 ~85 stone 0  
fill ~2 ~2 ~86 ~129 ~2 ~86 stone 0  
fill ~2 ~2 ~87 ~129 ~2 ~87 stone 0  
fill ~2 ~2 ~88 ~129 ~2 ~88 stone 0  
fill ~2 ~2 ~89 ~129 ~2 ~89 stone 0  
fill ~2 ~2 ~90 ~129 ~2 ~90 stone 0  
fill ~2 ~2 ~91 ~129 ~2 ~91 stone 0  
fill ~2 ~2 ~92 ~129 ~2 ~92 stone 0  
fill ~2 ~2 ~93 ~129 ~2 ~93 stone 0  
fill ~2 ~2 ~94 ~129 ~2 ~94 stone 0  
fill ~2 ~2 ~95 ~129 ~2 ~95 stone 0  
fill ~2 ~2 ~96 ~129 ~2 ~96 stone 0  
fill ~2 ~2 ~97 ~129 ~2 ~97 stone 0  
fill ~2 ~2 ~98 ~129 ~2 ~98 stone 0  
fill ~2 ~2 ~99 ~129 ~2 ~99 stone 0  
fill ~2 ~2 ~100 ~129 ~2 ~100 stone 0  
fill ~2 ~2 ~101 ~129 ~2 ~101 stone 0  
fill ~2 ~2 ~102 ~129 ~2 ~102 stone 0  
fill ~2 ~2 ~103 ~129 ~2 ~103 stone 0  
fill ~2 ~2 ~104 ~129 ~2 ~104 stone 0  
fill ~2 ~2 ~105 ~129 ~2 ~105 stone 0  
fill ~2 ~2 ~106 ~129 ~2 ~106 stone 0  
fill ~2 ~2 ~107 ~129 ~2 ~107 stone 0  
fill ~2 ~2 ~108 ~129 ~2 ~108 stone 0  
fill ~2 ~2 ~109 ~129 ~2 ~109 stone 0  
fill ~2 ~2 ~110 ~129 ~2 ~110 stone 0  
fill ~2 ~2 ~111 ~129 ~2 ~111 stone 0  
fill ~2 ~2 ~112 ~129 ~2 ~112 stone 0  
fill ~2 ~2 ~113 ~129 ~2 ~113 stone 0  
fill ~2 ~2 ~114 ~129 ~2 ~114 stone 0  
fill ~2 ~2 ~115 ~129 ~2 ~115 stone 0  
fill ~2 ~2 ~116 ~129 ~2 ~116 stone 0  
fill ~2 ~2 ~117 ~129 ~2 ~117 stone 0  
fill ~2 ~2 ~118 ~129 ~2 ~118 stone 0  
fill ~2 ~2 ~119 ~129 ~2 ~119 stone 0  
fill ~2 ~2 ~120 ~129 ~2 ~120 stone 0  
fill ~2 ~2 ~121 ~129 ~2 ~121 stone 0  
fill ~2 ~2 ~122 ~129 ~2 ~122 stone 0  
fill ~2 ~2 ~123 ~129 ~2 ~123 stone 0  
fill ~2 ~2 ~124 ~129 ~2 ~124 stone 0  
fill ~2 ~2 ~125 ~129 ~2 ~125 stone 0  
fill ~2 ~2 ~126 ~129 ~2 ~126 stone 0  
fill ~2 ~2 ~127 ~129 ~2 ~127 stone 0  
fill ~2 ~2 ~128 ~129 ~2 ~128 stone 0  
fill ~2 ~2 ~129 ~129 ~2 ~129 stone 0  
fill ~1 ~3 ~1 ~130 ~3 ~1 stained_hardened_clay 14  
fill ~1 ~3 ~130 ~130 ~3 ~130 stained_hardened_clay 14  
fill ~2 ~3 ~2 ~129 ~3 ~2 stone 0  
fill ~2 ~3 ~3 ~129 ~3 ~3 stone 0  
fill ~2 ~3 ~4 ~129 ~3 ~4 stone 0  
fill ~2 ~3 ~5 ~129 ~3 ~5 stone 0  
fill ~2 ~3 ~6 ~129 ~3 ~6 stone 0  
fill ~2 ~3 ~7 ~129 ~3 ~7 stone 0  
fill ~2 ~3 ~8 ~129 ~3 ~8 stone 0  
fill ~2 ~3 ~9 ~129 ~3 ~9 stone 0  
fill ~2 ~3 ~10 ~129 ~3 ~10 stone 0  
fill ~2 ~3 ~11 ~129 ~3 ~11 stone 0  
fill ~2 ~3 ~12 ~129 ~3 ~12 stone 0  
fill ~2 ~3 ~13 ~129 ~3 ~13 stone 0  
fill ~2 ~3 ~14 ~129 ~3 ~14 stone 0  
fill ~2 ~3 ~15 ~129 ~3 ~15 stone 0  
fill ~2 ~3 ~16 ~129 ~3 ~16 stone 0  
fill ~2 ~3 ~17 ~129 ~3 ~17 stone 0  
fill ~2 ~3 ~18 ~129 ~3 ~18 stone 0  
fill ~2 ~3 ~19 ~129 ~3 ~19 stone 0  
fill ~2 ~3 ~20 ~129 ~3 ~20 stone 0  
fill ~2 ~3 ~21 ~129 ~3 ~21 stone 0  
fill ~2 ~3 ~22 ~129 ~3 ~22 stone 0  
fill ~2 ~3 ~23 ~129 ~3 ~23 stone 0  
fill ~2 ~3 ~24 ~129 ~3 ~24 stone 0  
fill ~2 ~3 ~25 ~129 ~3 ~25 stone 0  
fill ~2 ~3 ~26 ~129 ~3 ~26 stone 0  
fill ~2 ~3 ~27 ~129 ~3 ~27 stone 0  
fill ~2 ~3 ~28 ~129 ~3 ~28 stone 0  
fill ~2 ~3 ~29 ~129 ~3 ~29 stone 0  
fill ~2 ~3 ~30 ~129 ~3 ~30 stone 0  
fill ~2 ~3 ~31 ~129 ~3 ~31 stone 0  
fill ~2 ~3 ~32 ~129 ~3 ~32 stone 0  
fill ~2 ~3 ~33 ~129 ~3 ~33 stone 0  
fill ~2 ~3 ~34 ~129 ~3 ~34 stone 0  
fill ~2 ~3 ~35 ~129 ~3 ~35 stone 0  
fill ~2 ~3 ~36 ~129 ~3 ~36 stone 0  
fill ~2 ~3 ~37 ~129 ~3 ~37 stone 0  
fill ~2 ~3 ~38 ~129 ~3 ~38 stone 0  
fill ~2 ~3 ~39 ~129 ~3 ~39 stone 0  
fill ~2 ~3 ~40 ~129 ~3 ~40 stone 0  
fill ~2 ~3 ~41 ~129 ~3 ~41 stone 0  
fill ~2 ~3 ~42 ~129 ~3 ~42 stone 0  
fill ~2 ~3 ~43 ~129 ~3 ~43 stone 0  
fill ~2 ~3 ~44 ~129 ~3 ~44 stone 0  
fill ~2 ~3 ~45 ~129 ~3 ~45 stone 0  
fill ~2 ~3 ~46 ~129 ~3 ~46 stone 0  
fill ~2 ~3 ~47 ~129 ~3 ~47 stone 0  
fill ~2 ~3 ~48 ~129 ~3 ~48 stone 0  
fill ~2 ~3 ~49 ~129 ~3 ~49 stone 0  
fill ~2 ~3 ~50 ~129 ~3 ~50 stone 0  
fill ~2 ~3 ~51 ~129 ~3 ~51 stone 0  
fill ~2 ~3 ~52 ~129 ~3 ~52 stone 0  
fill ~2 ~3 ~53 ~129 ~3 ~53 stone 0  
fill ~2 ~3 ~54 ~129 ~3 ~54 stone 0  
fill ~2 ~3 ~55 ~129 ~3 ~55 stone 0  
fill ~2 ~3 ~56 ~129 ~3 ~56 stone 0  
fill ~2 ~3 ~57 ~129 ~3 ~57 stone 0  
fill ~2 ~3 ~58 ~129 ~3 ~58 stone 0  
fill ~2 ~3 ~59 ~129 ~3 ~59 stone 0  
fill ~2 ~3 ~60 ~129 ~3 ~60 stone 0  
fill ~2 ~3 ~61 ~129 ~3 ~61 stone 0  
fill ~2 ~3 ~62 ~129 ~3 ~62 stone 0  
fill ~2 ~3 ~63 ~129 ~3 ~63 stone 0  
fill ~2 ~3 ~64 ~129 ~3 ~64 stone 0  
fill ~2 ~3 ~65 ~129 ~3 ~65 stone 0  
fill ~2 ~3 ~66 ~129 ~3 ~66 stone 0  
fill ~2 ~3 ~67 ~129 ~3 ~67 stone 0  
fill ~2 ~3 ~68 ~129 ~3 ~68 stone 0  
fill ~2 ~3 ~69 ~129 ~3 ~69 stone 0  
fill ~2 ~3 ~70 ~129 ~3 ~70 stone 0  
fill ~2 ~3 ~71 ~129 ~3 ~71 stone 0  
fill ~2 ~3 ~72 ~129 ~3 ~72 stone 0  
fill ~2 ~3 ~73 ~129 ~3 ~73 stone 0  
fill ~2 ~3 ~74 ~129 ~3 ~74 stone 0  
fill ~2 ~3 ~75 ~129 ~3 ~75 stone 0  
fill ~2 ~3 ~76 ~129 ~3 ~76 stone 0   
fill ~2 ~3 ~77 ~129 ~3 ~77 stone 0  
fill ~2 ~3 ~78 ~129 ~3 ~78 stone 0  
fill ~2 ~3 ~79 ~129 ~3 ~79 stone 0  
fill ~2 ~3 ~80 ~129 ~3 ~80 stone 0  
fill ~2 ~3 ~81 ~129 ~3 ~81 stone 0  
fill ~2 ~3 ~82 ~129 ~3 ~82 stone 0  
fill ~2 ~3 ~83 ~129 ~3 ~83 stone 0  
fill ~2 ~3 ~84 ~129 ~3 ~84 stone 0  
fill ~2 ~3 ~85 ~129 ~3 ~85 stone 0  
fill ~2 ~3 ~86 ~129 ~3 ~86 stone 0  
fill ~2 ~3 ~87 ~129 ~3 ~87 stone 0  
fill ~2 ~3 ~88 ~129 ~3 ~88 stone 0  
fill ~2 ~3 ~89 ~129 ~3 ~89 stone 0  
fill ~2 ~3 ~90 ~129 ~3 ~90 stone 0  
fill ~2 ~3 ~91 ~129 ~3 ~91 stone 0  
fill ~2 ~3 ~92 ~129 ~3 ~92 stone 0  
fill ~2 ~3 ~93 ~129 ~3 ~93 stone 0  
fill ~2 ~3 ~94 ~129 ~3 ~94 stone 0  
fill ~2 ~3 ~95 ~129 ~3 ~95 stone 0  
fill ~2 ~3 ~96 ~129 ~3 ~96 stone 0  
fill ~2 ~3 ~97 ~129 ~3 ~97 stone 0  
fill ~2 ~3 ~98 ~129 ~3 ~98 stone 0  
fill ~2 ~3 ~99 ~129 ~3 ~99 stone 0  
fill ~2 ~3 ~100 ~129 ~3 ~100 stone 0  
fill ~2 ~3 ~101 ~129 ~3 ~101 stone 0  
fill ~2 ~3 ~102 ~129 ~3 ~102 stone 0  
fill ~2 ~3 ~103 ~129 ~3 ~103 stone 0  
fill ~2 ~3 ~104 ~129 ~3 ~104 stone 0  
fill ~2 ~3 ~105 ~129 ~3 ~105 stone 0  
fill ~2 ~3 ~106 ~129 ~3 ~106 stone 0  
fill ~2 ~3 ~107 ~129 ~3 ~107 stone 0  
fill ~2 ~3 ~108 ~129 ~3 ~108 stone 0  
fill ~2 ~3 ~109 ~129 ~3 ~109 stone 0  
fill ~2 ~3 ~110 ~129 ~3 ~110 stone 0  
fill ~2 ~3 ~111 ~129 ~3 ~111 stone 0  
fill ~2 ~3 ~112 ~129 ~3 ~112 stone 0  
fill ~2 ~3 ~113 ~129 ~3 ~113 stone 0  
fill ~2 ~3 ~114 ~129 ~3 ~114 stone 0  
fill ~2 ~3 ~115 ~129 ~3 ~115 stone 0  
fill ~2 ~3 ~116 ~129 ~3 ~116 stone 0  
fill ~2 ~3 ~117 ~129 ~3 ~117 stone 0  
fill ~2 ~3 ~118 ~129 ~3 ~118 stone 0  
fill ~2 ~3 ~119 ~129 ~3 ~119 stone 0  
fill ~2 ~3 ~120 ~129 ~3 ~120 stone 0  
fill ~2 ~3 ~121 ~129 ~3 ~121 stone 0  
fill ~2 ~3 ~122 ~129 ~3 ~122 stone 0  
fill ~2 ~3 ~123 ~129 ~3 ~123 stone 0  
fill ~2 ~3 ~124 ~129 ~3 ~124 stone 0  
fill ~2 ~3 ~125 ~129 ~3 ~125 stone 0  
fill ~2 ~3 ~126 ~129 ~3 ~126 stone 0  
fill ~2 ~3 ~127 ~129 ~3 ~127 stone 0  
fill ~2 ~3 ~128 ~129 ~3 ~128 stone 0  
fill ~2 ~3 ~129 ~129 ~3 ~129 stone 0  
fill ~1 ~4 ~1 ~130 ~4 ~1 stained_hardened_clay 14  
fill ~1 ~4 ~130 ~130 ~4 ~130 stained_hardened_clay 14  
fill ~2 ~4 ~2 ~129 ~4 ~2 stone 0  
fill ~2 ~4 ~3 ~129 ~4 ~3 stone 0  
fill ~2 ~4 ~4 ~129 ~4 ~4 stone 0  
fill ~2 ~4 ~5 ~129 ~4 ~5 stone 0  
fill ~2 ~4 ~6 ~129 ~4 ~6 stone 0  
fill ~2 ~4 ~7 ~129 ~4 ~7 stone 0  
fill ~2 ~4 ~8 ~129 ~4 ~8 stone 0  
fill ~2 ~4 ~9 ~129 ~4 ~9 stone 0  
fill ~2 ~4 ~10 ~129 ~4 ~10 stone 0  
fill ~2 ~4 ~11 ~129 ~4 ~11 stone 0  
fill ~2 ~4 ~12 ~129 ~4 ~12 stone 0  
fill ~2 ~4 ~13 ~129 ~4 ~13 stone 0  
fill ~2 ~4 ~14 ~129 ~4 ~14 stone 0  
fill ~2 ~4 ~15 ~129 ~4 ~15 stone 0  
fill ~2 ~4 ~16 ~129 ~4 ~16 stone 0  
fill ~2 ~4 ~17 ~129 ~4 ~17 stone 0  
fill ~2 ~4 ~18 ~129 ~4 ~18 stone 0  
fill ~2 ~4 ~19 ~129 ~4 ~19 stone 0  
fill ~2 ~4 ~20 ~129 ~4 ~20 stone 0  
fill ~2 ~4 ~21 ~129 ~4 ~21 stone 0  
fill ~2 ~4 ~22 ~129 ~4 ~22 stone 0  
fill ~2 ~4 ~23 ~129 ~4 ~23 stone 0  
fill ~2 ~4 ~24 ~129 ~4 ~24 stone 0  
fill ~2 ~4 ~25 ~129 ~4 ~25 stone 0  
fill ~2 ~4 ~26 ~129 ~4 ~26 stone 0  
fill ~2 ~4 ~27 ~129 ~4 ~27 stone 0  
fill ~2 ~4 ~28 ~129 ~4 ~28 stone 0  
fill ~2 ~4 ~29 ~129 ~4 ~29 stone 0  
fill ~2 ~4 ~30 ~129 ~4 ~30 stone 0  
fill ~2 ~4 ~31 ~129 ~4 ~31 stone 0  
fill ~2 ~4 ~32 ~129 ~4 ~32 stone 0  
fill ~2 ~4 ~33 ~129 ~4 ~33 stone 0  
fill ~2 ~4 ~34 ~129 ~4 ~34 stone 0  
fill ~2 ~4 ~35 ~129 ~4 ~35 stone 0  
fill ~2 ~4 ~36 ~129 ~4 ~36 stone 0  
fill ~2 ~4 ~37 ~129 ~4 ~37 stone 0  
fill ~2 ~4 ~38 ~129 ~4 ~38 stone 0  
fill ~2 ~4 ~39 ~129 ~4 ~39 stone 0  
fill ~2 ~4 ~40 ~129 ~4 ~40 stone 0  
fill ~2 ~4 ~41 ~129 ~4 ~41 stone 0  
fill ~2 ~4 ~42 ~129 ~4 ~42 stone 0  
fill ~2 ~4 ~43 ~129 ~4 ~43 stone 0  
fill ~2 ~4 ~44 ~129 ~4 ~44 stone 0  
fill ~2 ~4 ~45 ~129 ~4 ~45 stone 0  
fill ~2 ~4 ~46 ~129 ~4 ~46 stone 0  
fill ~2 ~4 ~47 ~129 ~4 ~47 stone 0  
fill ~2 ~4 ~48 ~129 ~4 ~48 stone 0  
fill ~2 ~4 ~49 ~129 ~4 ~49 stone 0  
fill ~2 ~4 ~50 ~129 ~4 ~50 stone 0  
fill ~2 ~4 ~51 ~129 ~4 ~51 stone 0  
fill ~2 ~4 ~52 ~129 ~4 ~52 stone 0  
fill ~2 ~4 ~53 ~129 ~4 ~53 stone 0  
fill ~2 ~4 ~54 ~129 ~4 ~54 stone 0  
fill ~2 ~4 ~55 ~129 ~4 ~55 stone 0  
fill ~2 ~4 ~56 ~129 ~4 ~56 stone 0  
fill ~2 ~4 ~57 ~129 ~4 ~57 stone 0  
fill ~2 ~4 ~58 ~129 ~4 ~58 stone 0  
fill ~2 ~4 ~59 ~129 ~4 ~59 stone 0  
fill ~2 ~4 ~60 ~129 ~4 ~60 stone 0  
fill ~2 ~4 ~61 ~129 ~4 ~61 stone 0  
fill ~2 ~4 ~62 ~129 ~4 ~62 stone 0  
fill ~2 ~4 ~63 ~129 ~4 ~63 stone 0  
fill ~2 ~4 ~64 ~129 ~4 ~64 stone 0  
fill ~2 ~4 ~65 ~129 ~4 ~65 stone 0  
fill ~2 ~4 ~66 ~129 ~4 ~66 stone 0  
fill ~2 ~4 ~67 ~129 ~4 ~67 stone 0  
fill ~2 ~4 ~68 ~129 ~4 ~68 stone 0  
fill ~2 ~4 ~69 ~129 ~4 ~69 stone 0  
fill ~2 ~4 ~70 ~129 ~4 ~70 stone 0  
fill ~2 ~4 ~71 ~129 ~4 ~71 stone 0  
fill ~2 ~4 ~72 ~129 ~4 ~72 stone 0  
fill ~2 ~4 ~73 ~129 ~4 ~73 stone 0  
fill ~2 ~4 ~74 ~129 ~4 ~74 stone 0  
fill ~2 ~4 ~75 ~129 ~4 ~75 stone 0  
fill ~2 ~4 ~76 ~129 ~4 ~76 stone 0  
fill ~2 ~4 ~77 ~129 ~4 ~77 stone 0  
fill ~2 ~4 ~78 ~129 ~4 ~78 stone 0  
fill ~2 ~4 ~79 ~129 ~4 ~79 stone 0  
fill ~2 ~4 ~80 ~129 ~4 ~80 stone 0  
fill ~2 ~4 ~81 ~129 ~4 ~81 stone 0  
fill ~2 ~4 ~82 ~129 ~4 ~82 stone 0  
fill ~2 ~4 ~83 ~129 ~4 ~83 stone 0  
fill ~2 ~4 ~84 ~129 ~4 ~84 stone 0  
fill ~2 ~4 ~85 ~129 ~4 ~85 stone 0  
fill ~2 ~4 ~86 ~129 ~4 ~86 stone 0  
fill ~2 ~4 ~87 ~129 ~4 ~87 stone 0  
fill ~2 ~4 ~88 ~129 ~4 ~88 stone 0  
fill ~2 ~4 ~89 ~129 ~4 ~89 stone 0  
fill ~2 ~4 ~90 ~129 ~4 ~90 stone 0  
fill ~2 ~4 ~91 ~129 ~4 ~91 stone 0  
fill ~2 ~4 ~92 ~129 ~4 ~92 stone 0  
fill ~2 ~4 ~93 ~129 ~4 ~93 stone 0  
fill ~2 ~4 ~94 ~129 ~4 ~94 stone 0  
fill ~2 ~4 ~95 ~129 ~4 ~95 stone 0  
fill ~2 ~4 ~96 ~129 ~4 ~96 stone 0  
fill ~2 ~4 ~97 ~129 ~4 ~97 stone 0  
fill ~2 ~4 ~98 ~129 ~4 ~98 stone 0  
fill ~2 ~4 ~99 ~129 ~4 ~99 stone 0  
fill ~2 ~4 ~100 ~129 ~4 ~100 stone 0  
fill ~2 ~4 ~101 ~129 ~4 ~101 stone 0  
fill ~2 ~4 ~102 ~129 ~4 ~102 stone 0  
fill ~2 ~4 ~103 ~129 ~4 ~103 stone 0  
fill ~2 ~4 ~104 ~129 ~4 ~104 stone 0  
fill ~2 ~4 ~105 ~129 ~4 ~105 stone 0  
fill ~2 ~4 ~106 ~129 ~4 ~106 stone 0  
fill ~2 ~4 ~107 ~129 ~4 ~107 stone 0  
fill ~2 ~4 ~108 ~129 ~4 ~108 stone 0  
fill ~2 ~4 ~109 ~129 ~4 ~109 stone 0  
fill ~2 ~4 ~110 ~129 ~4 ~110 stone 0  
fill ~2 ~4 ~111 ~129 ~4 ~111 stone 0  
fill ~2 ~4 ~112 ~129 ~4 ~112 stone 0  
fill ~2 ~4 ~113 ~129 ~4 ~113 stone 0  
fill ~2 ~4 ~114 ~129 ~4 ~114 stone 0  
fill ~2 ~4 ~115 ~129 ~4 ~115 stone 0  
fill ~2 ~4 ~116 ~129 ~4 ~116 stone 0  
fill ~2 ~4 ~117 ~129 ~4 ~117 stone 0  
fill ~2 ~4 ~118 ~129 ~4 ~118 stone 0  
fill ~2 ~4 ~119 ~129 ~4 ~119 stone 0  
fill ~2 ~4 ~120 ~129 ~4 ~120 stone 0  
fill ~2 ~4 ~121 ~129 ~4 ~121 stone 0  
fill ~2 ~4 ~122 ~129 ~4 ~122 stone 0  
fill ~2 ~4 ~123 ~129 ~4 ~123 stone 0  
fill ~2 ~4 ~124 ~129 ~4 ~124 stone 0  
fill ~2 ~4 ~125 ~129 ~4 ~125 stone 0  
fill ~2 ~4 ~126 ~129 ~4 ~126 stone 0  
fill ~2 ~4 ~127 ~129 ~4 ~127 stone 0  
fill ~2 ~4 ~128 ~129 ~4 ~128 stone 0  
fill ~2 ~4 ~129 ~129 ~4 ~129 stone 0  
fill ~1 ~5 ~1 ~130 ~5 ~1 stained_hardened_clay 14  
fill ~1 ~5 ~130 ~130 ~5 ~130 stained_hardened_clay 14  
fill ~2 ~5 ~2 ~129 ~5 ~2 stone 0  
fill ~2 ~5 ~3 ~129 ~5 ~3 stone 0  
fill ~2 ~5 ~4 ~129 ~5 ~4 stone 0  
fill ~2 ~5 ~5 ~129 ~5 ~5 stone 0  
fill ~2 ~5 ~6 ~129 ~5 ~6 stone 0  
fill ~2 ~5 ~7 ~129 ~5 ~7 stone 0  
fill ~2 ~5 ~8 ~129 ~5 ~8 stone 0  
fill ~2 ~5 ~9 ~129 ~5 ~9 stone 0  
fill ~2 ~5 ~10 ~129 ~5 ~10 stone 0  
fill ~2 ~5 ~11 ~129 ~5 ~11 stone 0  
fill ~2 ~5 ~12 ~129 ~5 ~12 stone 0  
fill ~2 ~5 ~13 ~129 ~5 ~13 stone 0  
fill ~2 ~5 ~14 ~129 ~5 ~14 stone 0  
fill ~2 ~5 ~15 ~129 ~5 ~15 stone 0  
fill ~2 ~5 ~16 ~129 ~5 ~16 stone 0  
fill ~2 ~5 ~17 ~129 ~5 ~17 stone 0  
fill ~2 ~5 ~18 ~129 ~5 ~18 stone 0  
fill ~2 ~5 ~19 ~129 ~5 ~19 stone 0  
fill ~2 ~5 ~20 ~129 ~5 ~20 stone 0  
fill ~2 ~5 ~21 ~129 ~5 ~21 stone 0  
fill ~2 ~5 ~22 ~129 ~5 ~22 stone 0  
fill ~2 ~5 ~23 ~129 ~5 ~23 stone 0  
fill ~2 ~5 ~24 ~129 ~5 ~24 stone 0  
fill ~2 ~5 ~25 ~129 ~5 ~25 stone 0  
fill ~2 ~5 ~26 ~129 ~5 ~26 stone 0  
fill ~2 ~5 ~27 ~129 ~5 ~27 stone 0  
fill ~2 ~5 ~28 ~129 ~5 ~28 stone 0  
fill ~2 ~5 ~29 ~129 ~5 ~29 stone 0  
fill ~2 ~5 ~30 ~129 ~5 ~30 stone 0  
fill ~2 ~5 ~31 ~80 ~5 ~31 stone 0  
fill ~2 ~5 ~32 ~79 ~5 ~32 stone 0  
fill ~2 ~5 ~33 ~129 ~5 ~33 stone 0  
fill ~2 ~5 ~34 ~129 ~5 ~34 stone 0  
fill ~2 ~5 ~35 ~78 ~5 ~35 stone 0  
fill ~2 ~5 ~36 ~129 ~5 ~36 stone 0  
fill ~2 ~5 ~37 ~79 ~5 ~37 stone 0  
fill ~2 ~5 ~38 ~129 ~5 ~38 stone 0  
fill ~2 ~5 ~39 ~84 ~5 ~39 stone 0  
fill ~2 ~5 ~40 ~129 ~5 ~40 stone 0  
fill ~2 ~5 ~41 ~129 ~5 ~41 stone 0  
fill ~2 ~5 ~42 ~129 ~5 ~42 stone 0  
fill ~2 ~5 ~43 ~129 ~5 ~43 stone 0  
fill ~2 ~5 ~44 ~129 ~5 ~44 stone 0  
fill ~2 ~5 ~45 ~74 ~5 ~45 stone 0  
fill ~2 ~5 ~46 ~129 ~5 ~46 stone 0  
fill ~2 ~5 ~47 ~129 ~5 ~47 stone 0  
fill ~2 ~5 ~48 ~129 ~5 ~48 stone 0  
fill ~2 ~5 ~49 ~129 ~5 ~49 stone 0  
fill ~2 ~5 ~50 ~129 ~5 ~50 stone 0  
fill ~2 ~5 ~51 ~129 ~5 ~51 stone 0  
fill ~2 ~5 ~52 ~129 ~5 ~52 stone 0  
fill ~2 ~5 ~53 ~129 ~5 ~53 stone 0  
fill ~2 ~5 ~54 ~129 ~5 ~54 stone 0  
fill ~2 ~5 ~55 ~129 ~5 ~55 stone 0  
fill ~2 ~5 ~56 ~129 ~5 ~56 stone 0  
fill ~2 ~5 ~57 ~70 ~5 ~57 stone 0  
fill ~2 ~5 ~58 ~72 ~5 ~58 stone 0  
fill ~2 ~5 ~59 ~67 ~5 ~59 stone 0  
fill ~2 ~5 ~60 ~68 ~5 ~60 stone 0  
fill ~2 ~5 ~61 ~66 ~5 ~61 stone 0  
fill ~2 ~5 ~62 ~70 ~5 ~62 stone 0  
fill ~2 ~5 ~63 ~59 ~5 ~63 stone 0  
fill ~2 ~5 ~64 ~129 ~5 ~64 stone 0  
fill ~2 ~5 ~65 ~71 ~5 ~65 stone 0  
fill ~2 ~5 ~66 ~66 ~5 ~66 stone 0  
fill ~2 ~5 ~67 ~71 ~5 ~67 stone 0  
fill ~2 ~5 ~68 ~129 ~5 ~68 stone 0  
fill ~2 ~5 ~69 ~65 ~5 ~69 stone 0  
fill ~2 ~5 ~70 ~129 ~5 ~70 stone 0  
fill ~2 ~5 ~71 ~62 ~5 ~71 stone 0  
fill ~2 ~5 ~72 ~68 ~5 ~72 stone 0  
fill ~2 ~5 ~73 ~67 ~5 ~73 stone 0  
fill ~2 ~5 ~74 ~129 ~5 ~74 stone 0  
fill ~2 ~5 ~75 ~129 ~5 ~75 stone 0  
fill ~2 ~5 ~76 ~129 ~5 ~76 stone 0  
fill ~2 ~5 ~77 ~129 ~5 ~77 stone 0  
fill ~2 ~5 ~78 ~129 ~5 ~78 stone 0  
fill ~2 ~5 ~79 ~129 ~5 ~79 stone 0  
fill ~2 ~5 ~80 ~129 ~5 ~80 stone 0  
fill ~2 ~5 ~81 ~129 ~5 ~81 stone 0  
fill ~2 ~5 ~82 ~129 ~5 ~82 stone 0  
fill ~2 ~5 ~83 ~129 ~5 ~83 stone 0  
fill ~2 ~5 ~84 ~129 ~5 ~84 stone 0  
fill ~2 ~5 ~85 ~129 ~5 ~85 stone 0  
fill ~2 ~5 ~86 ~129 ~5 ~86 stone 0  
fill ~2 ~5 ~87 ~129 ~5 ~87 stone 0  
fill ~2 ~5 ~88 ~129 ~5 ~88 stone 0  
fill ~2 ~5 ~89 ~129 ~5 ~89 stone 0  
fill ~2 ~5 ~90 ~129 ~5 ~90 stone 0  
fill ~2 ~5 ~91 ~129 ~5 ~91 stone 0  
fill ~2 ~5 ~92 ~129 ~5 ~92 stone 0  
fill ~2 ~5 ~93 ~129 ~5 ~93 stone 0  
fill ~2 ~5 ~94 ~129 ~5 ~94 stone 0  
fill ~2 ~5 ~95 ~129 ~5 ~95 stone 0  
fill ~2 ~5 ~96 ~129 ~5 ~96 stone 0  
fill ~2 ~5 ~97 ~129 ~5 ~97 stone 0  
fill ~2 ~5 ~98 ~129 ~5 ~98 stone 0  
fill ~2 ~5 ~99 ~129 ~5 ~99 stone 0  
fill ~2 ~5 ~100 ~129 ~5 ~100 stone 0  
fill ~2 ~5 ~101 ~129 ~5 ~101 stone 0  
fill ~2 ~5 ~102 ~129 ~5 ~102 stone 0  
fill ~2 ~5 ~103 ~129 ~5 ~103 stone 0  
fill ~2 ~5 ~104 ~129 ~5 ~104 stone 0  
fill ~2 ~5 ~105 ~129 ~5 ~105 stone 0  
fill ~2 ~5 ~106 ~129 ~5 ~106 stone 0  
fill ~2 ~5 ~107 ~129 ~5 ~107 stone 0  
fill ~2 ~5 ~108 ~129 ~5 ~108 stone 0  
fill ~2 ~5 ~109 ~129 ~5 ~109 stone 0  
fill ~2 ~5 ~110 ~129 ~5 ~110 stone 0  
fill ~2 ~5 ~111 ~129 ~5 ~111 stone 0  
fill ~2 ~5 ~112 ~129 ~5 ~112 stone 0  
fill ~2 ~5 ~113 ~129 ~5 ~113 stone 0  
fill ~2 ~5 ~114 ~129 ~5 ~114 stone 0  
fill ~2 ~5 ~115 ~129 ~5 ~115 stone 0  
fill ~2 ~5 ~116 ~129 ~5 ~116 stone 0  
fill ~2 ~5 ~117 ~129 ~5 ~117 stone 0  
fill ~2 ~5 ~118 ~129 ~5 ~118 stone 0  
fill ~2 ~5 ~119 ~129 ~5 ~119 stone 0  
fill ~2 ~5 ~120 ~129 ~5 ~120 stone 0  
fill ~2 ~5 ~121 ~129 ~5 ~121 stone 0  
fill ~2 ~5 ~122 ~129 ~5 ~122 stone 0  
fill ~2 ~5 ~123 ~129 ~5 ~123 stone 0  
fill ~2 ~5 ~124 ~129 ~5 ~124 stone 0  
fill ~2 ~5 ~125 ~129 ~5 ~125 stone 0  
fill ~2 ~5 ~126 ~129 ~5 ~126 stone 0  
fill ~2 ~5 ~127 ~129 ~5 ~127 stone 0  
fill ~2 ~5 ~128 ~129 ~5 ~128 stone 0  
fill ~2 ~5 ~129 ~129 ~5 ~129 stone 0 
setblock ~60 ~5 ~63 stained_hardened_clay 5 
setblock ~61 ~5 ~63 stone 0  
fill ~62 ~5 ~63 ~62 ~6 ~63 dirt 0  
fill ~63 ~5 ~63 ~68 ~5 ~63 stone 0  
fill ~63 ~5 ~71 ~64 ~5 ~71 dirt 0  
fill ~65 ~5 ~71 ~129 ~5 ~71 stone 0  
fill ~66 ~5 ~69 ~66 ~8 ~69 stained_hardened_clay 5 
setblock ~67 ~5 ~61 stained_hardened_clay 5 
setblock ~67 ~5 ~66 stained_hardened_clay 5 
setblock ~67 ~5 ~69 stone 0 
setblock ~68 ~5 ~59 stained_hardened_clay 5  
fill ~68 ~5 ~61 ~129 ~5 ~61 stone 0  
fill ~68 ~5 ~66 ~69 ~5 ~66 stone 0  
fill ~68 ~5 ~69 ~68 ~11 ~69 stained_hardened_clay 5  
fill ~68 ~5 ~73 ~68 ~6 ~73 stained_hardened_clay 5  
fill ~69 ~5 ~59 ~129 ~5 ~59 stone 0 
setblock ~69 ~5 ~60 stained_hardened_clay 5 
setblock ~69 ~5 ~63 stained_hardened_clay 5  
fill ~69 ~5 ~69 ~129 ~5 ~69 stone 0 
setblock ~69 ~5 ~72 dirt 0  
fill ~69 ~5 ~73 ~129 ~5 ~73 stone 0  
fill ~70 ~5 ~60 ~129 ~5 ~60 stone 0  
fill ~70 ~5 ~63 ~71 ~5 ~63 stone 0 
setblock ~70 ~5 ~66 stained_hardened_clay 5  
fill ~70 ~5 ~72 ~129 ~5 ~72 stone 0 
setblock ~71 ~5 ~57 stained_hardened_clay 5 
setblock ~71 ~5 ~62 dirt 0  
fill ~71 ~5 ~66 ~129 ~5 ~66 stone 0  
fill ~72 ~5 ~57 ~129 ~5 ~57 stone 0  
fill ~72 ~5 ~62 ~129 ~5 ~62 stone 0 
setblock ~72 ~5 ~63 dirt 0 
setblock ~72 ~5 ~65 dirt 0  
fill ~72 ~5 ~67 ~72 ~6 ~67 dirt 0 
setblock ~73 ~5 ~58 dirt 0  
fill ~73 ~5 ~63 ~129 ~5 ~63 stone 0  
fill ~73 ~5 ~65 ~129 ~5 ~65 stone 0  
fill ~73 ~5 ~67 ~129 ~5 ~67 stone 0  
fill ~74 ~5 ~58 ~129 ~5 ~58 stone 0 
setblock ~75 ~5 ~45 stone 2  
fill ~76 ~5 ~45 ~129 ~5 ~45 stone 0 
setblock ~79 ~5 ~35 planks 3 
setblock ~80 ~5 ~32 stone 2  
fill ~80 ~5 ~35 ~82 ~5 ~35 stone 0  
fill ~80 ~5 ~37 ~80 ~7 ~37 stone 2 
setblock ~81 ~5 ~31 planks 3  
fill ~81 ~5 ~32 ~129 ~5 ~32 stone 0 
setblock ~81 ~5 ~37 stone 0  
fill ~82 ~5 ~31 ~129 ~5 ~31 stone 0  
fill ~82 ~5 ~37 ~82 ~8 ~37 stone 2 
setblock ~83 ~5 ~35 stone 2  
fill ~83 ~5 ~37 ~129 ~5 ~37 stone 0  
fill ~84 ~5 ~35 ~129 ~5 ~35 stone 0 
setblock ~85 ~5 ~39 stained_hardened_clay 5  
fill ~86 ~5 ~39 ~129 ~5 ~39 stone 0  
fill ~1 ~6 ~1 ~130 ~6 ~1 stained_hardened_clay 14  
fill ~1 ~6 ~130 ~130 ~6 ~130 stained_hardened_clay 14  
fill ~2 ~6 ~2 ~129 ~6 ~2 stone 0  
fill ~2 ~6 ~3 ~129 ~6 ~3 stone 0  
fill ~2 ~6 ~4 ~129 ~6 ~4 stone 0  
fill ~2 ~6 ~5 ~129 ~6 ~5 stone 0  
fill ~2 ~6 ~6 ~129 ~6 ~6 stone 0  
fill ~2 ~6 ~7 ~129 ~6 ~7 stone 0  
fill ~2 ~6 ~8 ~129 ~6 ~8 stone 0  
fill ~2 ~6 ~9 ~129 ~6 ~9 stone 0  
fill ~2 ~6 ~10 ~129 ~6 ~10 stone 0  
fill ~2 ~6 ~11 ~129 ~6 ~11 stone 0  
fill ~2 ~6 ~12 ~129 ~6 ~12 stone 0  
fill ~2 ~6 ~13 ~129 ~6 ~13 stone 0  
fill ~2 ~6 ~14 ~129 ~6 ~14 stone 0  
fill ~2 ~6 ~15 ~129 ~6 ~15 stone 0  
fill ~2 ~6 ~16 ~129 ~6 ~16 stone 0  
fill ~2 ~6 ~17 ~129 ~6 ~17 stone 0  
fill ~2 ~6 ~18 ~129 ~6 ~18 stone 0  
fill ~2 ~6 ~19 ~129 ~6 ~19 stone 0  
fill ~2 ~6 ~20 ~129 ~6 ~20 stone 0  
fill ~2 ~6 ~21 ~129 ~6 ~21 stone 0  
fill ~2 ~6 ~22 ~129 ~6 ~22 stone 0  
fill ~2 ~6 ~23 ~129 ~6 ~23 stone 0  
fill ~2 ~6 ~24 ~129 ~6 ~24 stone 0  
fill ~2 ~6 ~25 ~129 ~6 ~25 stone 0  
fill ~2 ~6 ~26 ~129 ~6 ~26 stone 0  
fill ~2 ~6 ~27 ~129 ~6 ~27 stone 0  
fill ~2 ~6 ~28 ~129 ~6 ~28 stone 0  
fill ~2 ~6 ~29 ~81 ~6 ~29 stone 0  
fill ~2 ~6 ~30 ~80 ~6 ~30 stone 0  
fill ~2 ~6 ~31 ~78 ~6 ~31 stone 0  
fill ~2 ~6 ~32 ~129 ~6 ~32 stone 0  
fill ~2 ~6 ~33 ~80 ~6 ~33 stone 0  
fill ~2 ~6 ~34 ~75 ~6 ~34 stone 0  
fill ~2 ~6 ~35 ~76 ~6 ~35 stone 0  
fill ~2 ~6 ~36 ~77 ~6 ~36 stone 0  
fill ~2 ~6 ~37 ~79 ~6 ~37 stone 0  
fill ~2 ~6 ~38 ~79 ~6 ~38 stone 0  
fill ~2 ~6 ~39 ~74 ~6 ~39 stone 0  
fill ~2 ~6 ~40 ~82 ~6 ~40 stone 0  
fill ~2 ~6 ~41 ~74 ~6 ~41 stone 0  
fill ~2 ~6 ~42 ~72 ~6 ~42 stone 0  
fill ~2 ~6 ~43 ~71 ~6 ~43 stone 0  
fill ~2 ~6 ~44 ~72 ~6 ~44 stone 0  
fill ~2 ~6 ~45 ~73 ~6 ~45 stone 0  
fill ~2 ~6 ~46 ~71 ~6 ~46 stone 0  
fill ~2 ~6 ~47 ~70 ~6 ~47 stone 0  
fill ~2 ~6 ~48 ~129 ~6 ~48 stone 0  
fill ~2 ~6 ~49 ~66 ~6 ~49 stone 0  
fill ~2 ~6 ~50 ~67 ~6 ~50 stone 0  
fill ~2 ~6 ~51 ~65 ~6 ~51 stone 0  
fill ~2 ~6 ~52 ~129 ~6 ~52 stone 0  
fill ~2 ~6 ~53 ~129 ~6 ~53 stone 0  
fill ~2 ~6 ~54 ~72 ~6 ~54 stone 0  
fill ~2 ~6 ~55 ~129 ~6 ~55 stone 0  
fill ~2 ~6 ~56 ~70 ~6 ~56 stone 0  
fill ~2 ~6 ~57 ~72 ~6 ~57 stone 0  
fill ~2 ~6 ~58 ~60 ~6 ~58 stone 0  
fill ~2 ~6 ~59 ~58 ~6 ~59 stone 0  
fill ~2 ~6 ~60 ~57 ~6 ~60 stone 0  
fill ~2 ~6 ~61 ~60 ~6 ~61 stone 0  
fill ~2 ~6 ~62 ~60 ~6 ~62 stone 0  
fill ~2 ~6 ~63 ~60 ~6 ~63 stone 0  
fill ~2 ~6 ~64 ~59 ~6 ~64 stone 0  
fill ~2 ~6 ~65 ~59 ~6 ~65 stone 0  
fill ~2 ~6 ~66 ~65 ~6 ~66 stone 0  
fill ~2 ~6 ~67 ~65 ~6 ~67 stone 0  
fill ~2 ~6 ~68 ~59 ~6 ~68 stone 0  
fill ~2 ~6 ~69 ~58 ~6 ~69 stone 0  
fill ~2 ~6 ~70 ~63 ~6 ~70 stone 0  
fill ~2 ~6 ~71 ~63 ~6 ~71 stone 0  
fill ~2 ~6 ~72 ~64 ~6 ~72 stone 0  
fill ~2 ~6 ~73 ~66 ~6 ~73 stone 0  
fill ~2 ~6 ~74 ~64 ~6 ~74 stone 0  
fill ~2 ~6 ~75 ~129 ~6 ~75 stone 0  
fill ~2 ~6 ~76 ~64 ~6 ~76 stone 0  
fill ~2 ~6 ~77 ~64 ~6 ~77 stone 0  
fill ~2 ~6 ~78 ~61 ~6 ~78 stone 0  
fill ~2 ~6 ~79 ~60 ~6 ~79 stone 0  
fill ~2 ~6 ~80 ~72 ~6 ~80 stone 0  
fill ~2 ~6 ~81 ~70 ~6 ~81 stone 0  
fill ~2 ~6 ~82 ~129 ~6 ~82 stone 0  
fill ~2 ~6 ~83 ~68 ~6 ~83 stone 0  
fill ~2 ~6 ~84 ~129 ~6 ~84 stone 0  
fill ~2 ~6 ~85 ~129 ~6 ~85 stone 0  
fill ~2 ~6 ~86 ~129 ~6 ~86 stone 0  
fill ~2 ~6 ~87 ~62 ~6 ~87 stone 0  
fill ~2 ~6 ~88 ~66 ~6 ~88 stone 0  
fill ~2 ~6 ~89 ~63 ~6 ~89 stone 0  
fill ~2 ~6 ~90 ~63 ~6 ~90 stone 0  
fill ~2 ~6 ~91 ~129 ~6 ~91 stone 0  
fill ~2 ~6 ~92 ~129 ~6 ~92 stone 0  
fill ~2 ~6 ~93 ~129 ~6 ~93 stone 0  
fill ~2 ~6 ~94 ~129 ~6 ~94 stone 0  
fill ~2 ~6 ~95 ~129 ~6 ~95 stone 0  
fill ~2 ~6 ~96 ~129 ~6 ~96 stone 0  
fill ~2 ~6 ~97 ~129 ~6 ~97 stone 0  
fill ~2 ~6 ~98 ~129 ~6 ~98 stone 0  
fill ~2 ~6 ~99 ~129 ~6 ~99 stone 0  
fill ~2 ~6 ~100 ~129 ~6 ~100 stone 0  
fill ~2 ~6 ~101 ~129 ~6 ~101 stone 0  
fill ~2 ~6 ~102 ~129 ~6 ~102 stone 0  
fill ~2 ~6 ~103 ~129 ~6 ~103 stone 0  
fill ~2 ~6 ~104 ~129 ~6 ~104 stone 0  
fill ~2 ~6 ~105 ~129 ~6 ~105 stone 0  
fill ~2 ~6 ~106 ~129 ~6 ~106 stone 0  
fill ~2 ~6 ~107 ~129 ~6 ~107 stone 0  
fill ~2 ~6 ~108 ~129 ~6 ~108 stone 0  
fill ~2 ~6 ~109 ~129 ~6 ~109 stone 0  
fill ~2 ~6 ~110 ~129 ~6 ~110 stone 0  
fill ~2 ~6 ~111 ~129 ~6 ~111 stone 0  
fill ~2 ~6 ~112 ~129 ~6 ~112 stone 0  
fill ~2 ~6 ~113 ~129 ~6 ~113 stone 0  
fill ~2 ~6 ~114 ~129 ~6 ~114 stone 0  
fill ~2 ~6 ~115 ~129 ~6 ~115 stone 0  
fill ~2 ~6 ~116 ~129 ~6 ~116 stone 0  
fill ~2 ~6 ~117 ~129 ~6 ~117 stone 0  
fill ~2 ~6 ~118 ~129 ~6 ~118 stone 0  
fill ~2 ~6 ~119 ~129 ~6 ~119 stone 0  
fill ~2 ~6 ~120 ~129 ~6 ~120 stone 0  
fill ~2 ~6 ~121 ~129 ~6 ~121 stone 0  
fill ~2 ~6 ~122 ~129 ~6 ~122 stone 0  
fill ~2 ~6 ~123 ~129 ~6 ~123 stone 0  
fill ~2 ~6 ~124 ~129 ~6 ~124 stone 0  
fill ~2 ~6 ~125 ~129 ~6 ~125 stone 0  
fill ~2 ~6 ~126 ~129 ~6 ~126 stone 0  
fill ~2 ~6 ~127 ~129 ~6 ~127 stone 0  
fill ~2 ~6 ~128 ~129 ~6 ~128 stone 0  
fill ~2 ~6 ~129 ~129 ~6 ~129 stone 0  
fill ~58 ~6 ~60 ~59 ~6 ~60 stained_hardened_clay 5  
fill ~59 ~6 ~59 ~59 ~8 ~59 stained_hardened_clay 5 
setblock ~59 ~6 ~69 stained_hardened_clay 5  
fill ~60 ~6 ~59 ~61 ~6 ~59 stone 0  
fill ~60 ~6 ~60 ~60 ~6 ~2 stone 0  
fill ~60 ~6 ~64 ~60 ~6 ~65 dirt 0 
setblock ~60 ~6 ~68 stained_hardened_clay 5  
fill ~60 ~6 ~69 ~65 ~6 ~69 stone 0 
setblock ~61 ~6 ~58 stained_hardened_clay 5  
fill ~61 ~6 ~60 ~61 ~7 ~60 dirt 0  
fill ~61 ~6 ~61 ~61 ~6 ~60 dirt 0  
fill ~61 ~6 ~62 ~61 ~6 ~63 stained_hardened_clay 5  
fill ~61 ~6 ~64 ~62 ~6 ~64 stone 0  
fill ~61 ~6 ~65 ~61 ~9 ~65 stained_hardened_clay 5  
fill ~61 ~6 ~68 ~65 ~6 ~68 stone 0  
fill ~61 ~6 ~79 ~61 ~7 ~79 stained_hardened_clay 5  
fill ~62 ~6 ~58 ~65 ~6 ~58 stone 0  
fill ~62 ~6 ~59 ~63 ~6 ~59 dirt 0  
fill ~62 ~6 ~60 ~64 ~6 ~60 stone 0  
fill ~62 ~6 ~61 ~62 ~6 ~60 stone 0 
setblock ~62 ~6 ~62 dirt 0  
fill ~62 ~6 ~65 ~68 ~6 ~65 stone 0 
setblock ~62 ~6 ~78 dirt 0  
fill ~62 ~6 ~79 ~129 ~6 ~79 stone 0 
setblock ~63 ~6 ~61 stained_hardened_clay 5 
setblock ~63 ~6 ~62 stone 0  
fill ~63 ~6 ~63 ~63 ~6 ~64 dirt 0 
setblock ~63 ~6 ~78 stone 0  
fill ~63 ~6 ~87 ~63 ~8 ~87 stone 2 
setblock ~64 ~6 ~59 stone 0 
setblock ~64 ~6 ~61 dirt 0  
fill ~64 ~6 ~62 ~65 ~6 ~62 stained_hardened_clay 5  
fill ~64 ~6 ~63 ~66 ~6 ~63 stained_hardened_clay 5  
fill ~64 ~6 ~64 ~66 ~6 ~64 dirt 0 
setblock ~64 ~6 ~70 dirt 0  
fill ~64 ~6 ~71 ~64 ~7 ~71 stained_hardened_clay 5 
setblock ~64 ~6 ~78 dirt 0  
fill ~64 ~6 ~87 ~129 ~6 ~87 stone 0 
setblock ~64 ~6 ~89 planks 3  
fill ~64 ~6 ~90 ~65 ~6 ~90 stone 2  
fill ~65 ~6 ~59 ~65 ~10 ~59 dirt 0  
fill ~65 ~6 ~60 ~65 ~6 ~63 stained_hardened_clay 5 
setblock ~65 ~6 ~70 stained_hardened_clay 5  
fill ~65 ~6 ~71 ~65 ~0 ~71 stone 0 
setblock ~65 ~6 ~72 dirt 0  
fill ~65 ~6 ~74 ~66 ~6 ~74 stained_hardened_clay 5 
setblock ~65 ~6 ~76 dirt 0  
fill ~65 ~6 ~77 ~65 ~9 ~77 stained_hardened_clay 5  
fill ~65 ~6 ~78 ~73 ~6 ~78 stone 0  
fill ~65 ~6 ~89 ~66 ~6 ~89 stone 0 
setblock ~66 ~6 ~51 stone 2 
setblock ~66 ~6 ~58 stained_hardened_clay 5 
setblock ~66 ~6 ~59 stone 0  
fill ~66 ~6 ~60 ~66 ~6 ~61 dirt 0  
fill ~66 ~6 ~62 ~67 ~6 ~62 stone 0 
setblock ~66 ~6 ~66 stained_hardened_clay 5  
fill ~66 ~6 ~67 ~66 ~6 ~68 dirt 0  
fill ~66 ~6 ~70 ~68 ~6 ~70 dirt 0  
fill ~66 ~6 ~71 ~66 ~9 ~71 dirt 0  
fill ~66 ~6 ~72 ~67 ~6 ~72 stone 0  
fill ~66 ~6 ~76 ~129 ~6 ~76 stone 0  
fill ~66 ~6 ~77 ~129 ~6 ~77 stone 0  
fill ~66 ~6 ~90 ~129 ~6 ~90 stone 0 
setblock ~67 ~6 ~49 planks 3  
fill ~67 ~6 ~51 ~129 ~6 ~51 stone 0 
setblock ~67 ~6 ~58 stone 0 
setblock ~67 ~6 ~59 stained_hardened_clay 5  
fill ~67 ~6 ~60 ~70 ~6 ~60 stone 0  
fill ~67 ~6 ~61 ~68 ~6 ~61 stone 0 
setblock ~67 ~6 ~63 dirt 0  
fill ~67 ~6 ~64 ~70 ~6 ~64 stone 0 
setblock ~67 ~6 ~66 dirt 0 
setblock ~67 ~6 ~67 stained_hardened_clay 5  
fill ~67 ~6 ~68 ~67 ~7 ~68 dirt 0  
fill ~67 ~6 ~69 ~67 ~8 ~69 stained_hardened_clay 5 
setblock ~67 ~6 ~71 stained_hardened_clay 5 
setblock ~67 ~6 ~73 dirt 0  
fill ~67 ~6 ~74 ~68 ~6 ~74 stone 0 
setblock ~67 ~6 ~88 stone 2 
setblock ~67 ~6 ~89 planks 3  
fill ~68 ~6 ~49 ~71 ~6 ~49 stone 0 
setblock ~68 ~6 ~50 stone 2  
fill ~68 ~6 ~58 ~68 ~6 ~59 dirt 0  
fill ~68 ~6 ~62 ~70 ~6 ~62 dirt 0  
fill ~68 ~6 ~63 ~69 ~6 ~63 stone 0 
setblock ~68 ~6 ~66 stained_hardened_clay 5  
fill ~68 ~6 ~67 ~69 ~6 ~67 stone 0  
fill ~68 ~6 ~68 ~68 ~7 ~68 stained_hardened_clay 5  
fill ~68 ~6 ~71 ~68 ~7 ~71 dirt 0  
fill ~68 ~6 ~72 ~68 ~8 ~72 stained_hardened_clay 5  
fill ~68 ~6 ~88 ~129 ~6 ~88 stone 0  
fill ~68 ~6 ~89 ~129 ~6 ~89 stone 0  
fill ~69 ~6 ~50 ~129 ~6 ~50 stone 0  
fill ~69 ~6 ~58 ~69 ~7 ~58 stone 0 
setblock ~69 ~6 ~59 dirt 0 
setblock ~69 ~6 ~61 stained_hardened_clay 5  
fill ~69 ~6 ~65 ~71 ~6 ~65 dirt 0  
fill ~69 ~6 ~66 ~69 ~9 ~66 dirt 0  
fill ~69 ~6 ~68 ~70 ~6 ~68 dirt 0  
fill ~69 ~6 ~69 ~69 ~6 ~68 dirt 0  
fill ~69 ~6 ~70 ~69 ~6 ~72 stone 0 
setblock ~69 ~6 ~73 stained_hardened_clay 5  
fill ~69 ~6 ~74 ~71 ~6 ~74 dirt 0 
setblock ~69 ~6 ~83 planks 3  
fill ~70 ~6 ~58 ~70 ~6 ~59 stained_hardened_clay 5  
fill ~70 ~6 ~61 ~129 ~6 ~61 stone 0  
fill ~70 ~6 ~63 ~70 ~7 ~63 stained_hardened_clay 5 
setblock ~70 ~6 ~66 stone 0 
setblock ~70 ~6 ~67 stained_hardened_clay 5  
fill ~70 ~6 ~69 ~72 ~6 ~69 stained_hardened_clay 5  
fill ~70 ~6 ~70 ~72 ~6 ~70 dirt 0  
fill ~70 ~6 ~71 ~70 ~8 ~71 dirt 0  
fill ~70 ~6 ~72 ~129 ~6 ~72 stone 0  
fill ~70 ~6 ~73 ~70 ~7 ~73 dirt 0  
fill ~70 ~6 ~83 ~70 ~7 ~83 stone 0  
fill ~71 ~6 ~47 ~74 ~6 ~47 stone 2  
fill ~71 ~6 ~56 ~71 ~11 ~56 dirt 0  
fill ~71 ~6 ~58 ~72 ~6 ~58 dirt 0  
fill ~71 ~6 ~59 ~129 ~6 ~59 stone 0 
setblock ~71 ~6 ~60 dirt 0  
fill ~71 ~6 ~62 ~71 ~9 ~62 stained_hardened_clay 5  
fill ~71 ~6 ~63 ~71 ~7 ~63 dirt 0  
fill ~71 ~6 ~64 ~71 ~6 ~63 dirt 0  
fill ~71 ~6 ~66 ~71 ~7 ~66 stained_hardened_clay 5  
fill ~71 ~6 ~67 ~71 ~11 ~67 dirt 0 
setblock ~71 ~6 ~68 stained_hardened_clay 5  
fill ~71 ~6 ~71 ~129 ~6 ~71 stone 0  
fill ~71 ~6 ~73 ~129 ~6 ~73 stone 0  
fill ~71 ~6 ~81 ~71 ~8 ~81 stone 2  
fill ~71 ~6 ~83 ~71 ~8 ~83 stone 2 
setblock ~72 ~6 ~43 stone 2  
fill ~72 ~6 ~46 ~73 ~6 ~46 stone 2 
setblock ~72 ~6 ~49 planks 3  
fill ~72 ~6 ~56 ~72 ~7 ~56 stone 0  
fill ~72 ~6 ~60 ~72 ~7 ~60 stained_hardened_clay 5  
fill ~72 ~6 ~62 ~129 ~6 ~62 stone 0  
fill ~72 ~6 ~63 ~129 ~6 ~63 stone 0  
fill ~72 ~6 ~64 ~72 ~11 ~64 stained_hardened_clay 5  
fill ~72 ~6 ~65 ~129 ~6 ~65 stone 0  
fill ~72 ~6 ~66 ~72 ~7 ~66 dirt 0 
setblock ~72 ~6 ~68 dirt 0  
fill ~72 ~6 ~74 ~129 ~6 ~74 stone 0  
fill ~72 ~6 ~81 ~129 ~6 ~81 stone 0  
fill ~72 ~6 ~83 ~129 ~6 ~83 stone 0  
fill ~73 ~6 ~42 ~73 ~8 ~42 planks 3  
fill ~73 ~6 ~43 ~74 ~6 ~43 stone 0 
setblock ~73 ~6 ~44 stone 2  
fill ~73 ~6 ~49 ~77 ~6 ~49 stone 0 
setblock ~73 ~6 ~54 stained_hardened_clay 5  
fill ~73 ~6 ~56 ~73 ~6 ~57 dirt 0  
fill ~73 ~6 ~58 ~129 ~6 ~58 stone 0  
fill ~73 ~6 ~60 ~129 ~6 ~60 stone 0  
fill ~73 ~6 ~64 ~129 ~6 ~64 stone 0  
fill ~73 ~6 ~66 ~73 ~6 ~79 stone 0 
setblock ~73 ~6 ~80 planks 3  
fill ~74 ~6 ~42 ~129 ~6 ~42 stone 0  
fill ~74 ~6 ~44 ~74 ~7 ~44 planks 3  
fill ~74 ~6 ~45 ~74 ~7 ~45 stone 2 
setblock ~74 ~6 ~46 stone 0  
fill ~74 ~6 ~54 ~129 ~6 ~54 stone 0  
fill ~74 ~6 ~56 ~74 ~6 ~57 stained_hardened_clay 5 
setblock ~74 ~6 ~66 dirt 0  
fill ~74 ~6 ~67 ~129 ~6 ~67 stone 0  
fill ~74 ~6 ~68 ~129 ~6 ~68 stone 0  
fill ~74 ~6 ~69 ~129 ~6 ~69 stone 0  
fill ~74 ~6 ~70 ~129 ~6 ~70 stone 0  
fill ~74 ~6 ~78 ~74 ~7 ~78 planks 3  
fill ~74 ~6 ~80 ~129 ~6 ~80 stone 0 
setblock ~75 ~6 ~39 planks 3  
fill ~75 ~6 ~41 ~75 ~7 ~41 planks 3 
setblock ~75 ~6 ~43 planks 3 
setblock ~75 ~6 ~44 stone 0  
fill ~75 ~6 ~45 ~76 ~6 ~45 planks 3  
fill ~75 ~6 ~46 ~76 ~6 ~46 planks 3  
fill ~75 ~6 ~47 ~75 ~6 ~45 planks 3 
setblock ~75 ~6 ~56 dirt 0  
fill ~75 ~6 ~57 ~129 ~6 ~57 stone 0  
fill ~75 ~6 ~66 ~129 ~6 ~66 stone 0  
fill ~75 ~6 ~78 ~129 ~6 ~78 stone 0 
setblock ~76 ~6 ~34 stone 2  
fill ~76 ~6 ~39 ~83 ~6 ~39 stone 0  
fill ~76 ~6 ~41 ~86 ~6 ~41 stone 0  
fill ~76 ~6 ~43 ~76 ~6 ~44 stone 2  
fill ~76 ~6 ~47 ~129 ~6 ~47 stone 0  
fill ~76 ~6 ~56 ~129 ~6 ~56 stone 0  
fill ~77 ~6 ~34 ~77 ~10 ~34 planks 3  
fill ~77 ~6 ~35 ~77 ~7 ~35 stone 2  
fill ~77 ~6 ~43 ~129 ~6 ~43 stone 0  
fill ~77 ~6 ~44 ~77 ~6 ~36 stone 0  
fill ~77 ~6 ~45 ~77 ~11 ~45 stone 2  
fill ~77 ~6 ~46 ~80 ~6 ~46 stone 0  
fill ~78 ~6 ~34 ~78 ~6 ~35 stone 0  
fill ~78 ~6 ~36 ~78 ~10 ~36 stone 2  
fill ~78 ~6 ~44 ~78 ~7 ~44 planks 3  
fill ~78 ~6 ~45 ~129 ~6 ~45 stone 0 
setblock ~78 ~6 ~49 stained_hardened_clay 5  
fill ~79 ~6 ~31 ~80 ~6 ~31 stone 2  
fill ~79 ~6 ~34 ~79 ~7 ~34 stone 2  
fill ~79 ~6 ~35 ~79 ~10 ~35 stone 2  
fill ~79 ~6 ~36 ~79 ~9 ~36 planks 3  
fill ~79 ~6 ~44 ~83 ~6 ~44 stone 0  
fill ~79 ~6 ~49 ~79 ~7 ~49 stone 0 
setblock ~80 ~6 ~34 stone 0  
fill ~80 ~6 ~35 ~82 ~6 ~35 planks 3 
setblock ~80 ~6 ~36 stone 0 
setblock ~80 ~6 ~38 stone 2 
setblock ~80 ~6 ~49 dirt 0 
setblock ~81 ~6 ~30 planks 3  
fill ~81 ~6 ~31 ~82 ~6 ~31 stone 0  
fill ~81 ~6 ~33 ~81 ~6 ~34 stone 2 
setblock ~81 ~6 ~36 stone 2  
fill ~81 ~6 ~37 ~81 ~9 ~37 planks 3  
fill ~81 ~6 ~38 ~83 ~6 ~38 stone 0 
setblock ~81 ~6 ~46 stained_hardened_clay 5  
fill ~81 ~6 ~49 ~129 ~6 ~49 stone 0  
fill ~82 ~6 ~29 ~82 ~11 ~29 planks 3  
fill ~82 ~6 ~30 ~129 ~6 ~30 stone 0 
setblock ~82 ~6 ~33 stone 0  
fill ~82 ~6 ~34 ~83 ~6 ~34 stone 2  
fill ~82 ~6 ~36 ~85 ~6 ~36 stone 0  
fill ~82 ~6 ~46 ~129 ~6 ~46 stone 0  
fill ~83 ~6 ~29 ~129 ~6 ~29 stone 0  
fill ~83 ~6 ~31 ~83 ~7 ~31 stone 2 
setblock ~83 ~6 ~33 stone 2  
fill ~83 ~6 ~35 ~84 ~6 ~35 stone 0  
fill ~83 ~6 ~37 ~83 ~8 ~37 stone 2  
fill ~83 ~6 ~40 ~83 ~8 ~40 stained_hardened_clay 5 
setblock ~84 ~6 ~31 planks 3 
setblock ~84 ~6 ~33 planks 3  
fill ~84 ~6 ~34 ~129 ~6 ~34 stone 0 
setblock ~84 ~6 ~37 stone 0 
setblock ~84 ~6 ~38 stone 2 
setblock ~84 ~6 ~39 stained_hardened_clay 5  
fill ~84 ~6 ~40 ~85 ~6 ~40 stone 0 
setblock ~84 ~6 ~44 stained_hardened_clay 5  
fill ~85 ~6 ~31 ~129 ~6 ~31 stone 0  
fill ~85 ~6 ~33 ~87 ~6 ~33 stone 0 
setblock ~85 ~6 ~35 stone 2 
setblock ~85 ~6 ~37 stone 2  
fill ~85 ~6 ~38 ~129 ~6 ~38 stone 0 
setblock ~85 ~6 ~39 dirt 0  
fill ~85 ~6 ~44 ~129 ~6 ~44 stone 0  
fill ~86 ~6 ~35 ~129 ~6 ~35 stone 0 
setblock ~86 ~6 ~36 dirt 0  
fill ~86 ~6 ~37 ~88 ~6 ~37 stone 0  
fill ~86 ~6 ~39 ~86 ~7 ~39 stone 0 
setblock ~86 ~6 ~40 dirt 0  
fill ~87 ~6 ~36 ~129 ~6 ~36 stone 0 
setblock ~87 ~6 ~39 stained_hardened_clay 5  
fill ~87 ~6 ~40 ~88 ~6 ~40 stone 0 
setblock ~87 ~6 ~41 dirt 0 
setblock ~88 ~6 ~33 dirt 1  
fill ~88 ~6 ~39 ~129 ~6 ~39 stone 0  
fill ~88 ~6 ~41 ~129 ~6 ~41 stone 0  
fill ~89 ~6 ~33 ~129 ~6 ~33 stone 0 
setblock ~89 ~6 ~37 planks 1 
setblock ~89 ~6 ~40 stained_hardened_clay 5  
fill ~90 ~6 ~37 ~90 ~7 ~37 stone 0  
fill ~90 ~6 ~40 ~129 ~6 ~40 stone 0 
setblock ~91 ~6 ~37 planks 1  
fill ~92 ~6 ~37 ~129 ~6 ~37 stone 0  
fill ~1 ~7 ~1 ~130 ~7 ~1 stained_hardened_clay 14  
fill ~1 ~7 ~130 ~130 ~7 ~130 stained_hardened_clay 14  
fill ~2 ~7 ~2 ~129 ~7 ~2 stone 0  
fill ~2 ~7 ~3 ~129 ~7 ~3 stone 0  
fill ~2 ~7 ~4 ~129 ~7 ~4 stone 0  
fill ~2 ~7 ~5 ~129 ~7 ~5 stone 0  
fill ~2 ~7 ~6 ~129 ~7 ~6 stone 0  
fill ~2 ~7 ~7 ~129 ~7 ~7 stone 0  
fill ~2 ~7 ~8 ~129 ~7 ~8 stone 0  
fill ~2 ~7 ~9 ~129 ~7 ~9 stone 0  
fill ~2 ~7 ~10 ~129 ~7 ~10 stone 0  
fill ~2 ~7 ~11 ~129 ~7 ~11 stone 0  
fill ~2 ~7 ~12 ~129 ~7 ~12 stone 0  
fill ~2 ~7 ~13 ~129 ~7 ~13 stone 0  
fill ~2 ~7 ~14 ~129 ~7 ~14 stone 0  
fill ~2 ~7 ~15 ~129 ~7 ~15 stone 0  
fill ~2 ~7 ~16 ~129 ~7 ~16 stone 0  
fill ~2 ~7 ~17 ~129 ~7 ~17 stone 0  
fill ~2 ~7 ~18 ~129 ~7 ~18 stone 0  
fill ~2 ~7 ~19 ~129 ~7 ~19 stone 0  
fill ~2 ~7 ~20 ~129 ~7 ~20 stone 0  
fill ~2 ~7 ~21 ~129 ~7 ~21 stone 0  
fill ~2 ~7 ~22 ~129 ~7 ~22 stone 0  
fill ~2 ~7 ~23 ~129 ~7 ~23 stone 0  
fill ~2 ~7 ~24 ~88 ~7 ~24 stone 0  
fill ~2 ~7 ~25 ~79 ~7 ~25 stone 0  
fill ~2 ~7 ~26 ~129 ~7 ~26 stone 0  
fill ~2 ~7 ~27 ~129 ~7 ~27 stone 0  
fill ~2 ~7 ~28 ~79 ~7 ~28 stone 0  
fill ~2 ~7 ~29 ~79 ~7 ~29 stone 0  
fill ~2 ~7 ~30 ~78 ~7 ~30 stone 0  
fill ~2 ~7 ~31 ~77 ~7 ~31 stone 0  
fill ~2 ~7 ~32 ~76 ~7 ~32 stone 0  
fill ~2 ~7 ~33 ~75 ~7 ~33 stone 0  
fill ~2 ~7 ~34 ~76 ~7 ~34 stone 0  
fill ~2 ~7 ~35 ~75 ~7 ~35 stone 0  
fill ~2 ~7 ~36 ~73 ~7 ~36 stone 0  
fill ~2 ~7 ~37 ~74 ~7 ~37 stone 0  
fill ~2 ~7 ~38 ~74 ~7 ~38 stone 0  
fill ~2 ~7 ~39 ~72 ~7 ~39 stone 0  
fill ~2 ~7 ~40 ~73 ~7 ~40 stone 0  
fill ~2 ~7 ~41 ~71 ~7 ~41 stone 0  
fill ~2 ~7 ~42 ~72 ~7 ~42 stone 0  
fill ~2 ~7 ~43 ~70 ~7 ~43 stone 0  
fill ~2 ~7 ~44 ~71 ~7 ~44 stone 0  
fill ~2 ~7 ~45 ~70 ~7 ~45 stone 0  
fill ~2 ~7 ~46 ~68 ~7 ~46 stone 0  
fill ~2 ~7 ~47 ~68 ~7 ~47 stone 0  
fill ~2 ~7 ~48 ~67 ~7 ~48 stone 0  
fill ~2 ~7 ~49 ~67 ~7 ~49 stone 0  
fill ~2 ~7 ~50 ~59 ~7 ~50 stone 0  
fill ~2 ~7 ~51 ~59 ~7 ~51 stone 0  
fill ~2 ~7 ~52 ~56 ~7 ~52 stone 0  
fill ~2 ~7 ~53 ~60 ~7 ~53 stone 0  
fill ~2 ~7 ~54 ~52 ~7 ~54 stone 0  
fill ~2 ~7 ~55 ~50 ~7 ~55 stone 0  
fill ~2 ~7 ~56 ~56 ~7 ~56 stone 0  
fill ~2 ~7 ~57 ~51 ~7 ~57 stone 0  
fill ~2 ~7 ~58 ~49 ~7 ~58 stone 0  
fill ~2 ~7 ~59 ~58 ~7 ~59 stone 0  
fill ~2 ~7 ~60 ~42 ~7 ~60 stone 0  
fill ~2 ~7 ~61 ~58 ~7 ~61 stone 0  
fill ~2 ~7 ~62 ~58 ~7 ~62 stone 0  
fill ~2 ~7 ~63 ~58 ~7 ~63 stone 0  
fill ~2 ~7 ~64 ~57 ~7 ~64 stone 0  
fill ~2 ~7 ~65 ~55 ~7 ~65 stone 0  
fill ~2 ~7 ~66 ~55 ~7 ~66 stone 0  
fill ~2 ~7 ~67 ~62 ~7 ~67 stone 0  
fill ~2 ~7 ~68 ~56 ~7 ~68 stone 0  
fill ~2 ~7 ~69 ~60 ~7 ~69 stone 0  
fill ~2 ~7 ~70 ~57 ~7 ~70 stone 0  
fill ~2 ~7 ~71 ~60 ~7 ~71 stone 0  
fill ~2 ~7 ~72 ~61 ~7 ~72 stone 0  
fill ~2 ~7 ~73 ~61 ~7 ~73 stone 0  
fill ~2 ~7 ~74 ~62 ~7 ~74 stone 0  
fill ~2 ~7 ~75 ~61 ~7 ~75 stone 0  
fill ~2 ~7 ~76 ~62 ~7 ~76 stone 0  
fill ~2 ~7 ~77 ~60 ~7 ~77 stone 0  
fill ~2 ~7 ~78 ~59 ~7 ~78 stone 0  
fill ~2 ~7 ~79 ~60 ~7 ~79 stone 0  
fill ~2 ~7 ~80 ~59 ~7 ~80 stone 0  
fill ~2 ~7 ~81 ~56 ~7 ~81 stone 0  
fill ~2 ~7 ~82 ~60 ~7 ~82 stone 0  
fill ~2 ~7 ~83 ~57 ~7 ~83 stone 0  
fill ~2 ~7 ~84 ~66 ~7 ~84 stone 0  
fill ~2 ~7 ~85 ~65 ~7 ~85 stone 0  
fill ~2 ~7 ~86 ~64 ~7 ~86 stone 0  
fill ~2 ~7 ~87 ~61 ~7 ~87 stone 0  
fill ~2 ~7 ~88 ~61 ~7 ~88 stone 0  
fill ~2 ~7 ~89 ~60 ~7 ~89 stone 0  
fill ~2 ~7 ~90 ~60 ~7 ~90 stone 0  
fill ~2 ~7 ~91 ~61 ~7 ~91 stone 0   
fill ~2 ~7 ~92 ~62 ~7 ~92 stone 0  
fill ~2 ~7 ~93 ~64 ~7 ~93 stone 0  
fill ~2 ~7 ~94 ~129 ~7 ~94 stone 0  
fill ~2 ~7 ~95 ~129 ~7 ~95 stone 0  
fill ~2 ~7 ~96 ~129 ~7 ~96 stone 0  
fill ~2 ~7 ~97 ~129 ~7 ~97 stone 0  
fill ~2 ~7 ~98 ~129 ~7 ~98 stone 0  
fill ~2 ~7 ~99 ~129 ~7 ~99 stone 0  
fill ~2 ~7 ~100 ~129 ~7 ~100 stone 0  
fill ~2 ~7 ~101 ~129 ~7 ~101 stone 0  
fill ~2 ~7 ~102 ~129 ~7 ~102 stone 0  
fill ~2 ~7 ~103 ~129 ~7 ~103 stone 0  
fill ~2 ~7 ~104 ~129 ~7 ~104 stone 0  
fill ~2 ~7 ~105 ~129 ~7 ~105 stone 0  
fill ~2 ~7 ~106 ~129 ~7 ~106 stone 0  
fill ~2 ~7 ~107 ~129 ~7 ~107 stone 0  
fill ~2 ~7 ~108 ~129 ~7 ~108 stone 0  
fill ~2 ~7 ~109 ~129 ~7 ~109 stone 0  
fill ~2 ~7 ~110 ~129 ~7 ~110 stone 0  
fill ~2 ~7 ~111 ~129 ~7 ~111 stone 0  
fill ~2 ~7 ~112 ~129 ~7 ~112 stone 0  
fill ~2 ~7 ~113 ~129 ~7 ~113 stone 0  
fill ~2 ~7 ~114 ~129 ~7 ~114 stone 0  
fill ~2 ~7 ~115 ~129 ~7 ~115 stone 0  
fill ~2 ~7 ~116 ~129 ~7 ~116 stone 0  
fill ~2 ~7 ~117 ~129 ~7 ~117 stone 0  
fill ~2 ~7 ~118 ~129 ~7 ~118 stone 0  
fill ~2 ~7 ~119 ~129 ~7 ~119 stone 0  
fill ~2 ~7 ~120 ~129 ~7 ~120 stone 0  
fill ~2 ~7 ~121 ~129 ~7 ~121 stone 0  
fill ~2 ~7 ~122 ~129 ~7 ~122 stone 0  
fill ~2 ~7 ~123 ~129 ~7 ~123 stone 0  
fill ~2 ~7 ~124 ~129 ~7 ~124 stone 0  
fill ~2 ~7 ~125 ~129 ~7 ~125 stone 0  
fill ~2 ~7 ~126 ~129 ~7 ~126 stone 0  
fill ~2 ~7 ~127 ~129 ~7 ~127 stone 0  
fill ~2 ~7 ~128 ~129 ~7 ~128 stone 0  
fill ~2 ~7 ~129 ~129 ~7 ~129 stone 0 
setblock ~43 ~7 ~60 stained_hardened_clay 5  
fill ~44 ~7 ~60 ~57 ~7 ~60 stone 0 
setblock ~50 ~7 ~58 dirt 1 
setblock ~51 ~7 ~55 dirt 1  
fill ~51 ~7 ~58 ~52 ~7 ~58 stone 0  
fill ~52 ~7 ~55 ~54 ~7 ~55 stone 0  
fill ~52 ~7 ~57 ~52 ~9 ~57 planks 1  
fill ~53 ~7 ~54 ~53 ~10 ~54 dirt 1 
setblock ~53 ~7 ~57 stone 0 
setblock ~53 ~7 ~58 planks 1  
fill ~54 ~7 ~54 ~58 ~7 ~54 stone 0 
setblock ~54 ~7 ~57 planks 1  
fill ~54 ~7 ~58 ~54 ~8 ~58 dirt 1 
setblock ~55 ~7 ~55 stone 2  
fill ~55 ~7 ~57 ~58 ~7 ~57 stone 0  
fill ~55 ~7 ~58 ~57 ~7 ~58 stone 0 
setblock ~56 ~7 ~55 stone 0  
fill ~56 ~7 ~65 ~56 ~7 ~66 stained_hardened_clay 5 
setblock ~57 ~7 ~52 planks 3  
fill ~57 ~7 ~55 ~57 ~7 ~56 stone 2  
fill ~57 ~7 ~65 ~57 ~7 ~67 stone 0  
fill ~57 ~7 ~68 ~58 ~7 ~68 dirt 0 
setblock ~57 ~7 ~81 stained_hardened_clay 5 
setblock ~58 ~7 ~52 stone 0  
fill ~58 ~7 ~55 ~58 ~8 ~55 stone 0  
fill ~58 ~7 ~56 ~58 ~8 ~56 stone 2  
fill ~58 ~7 ~58 ~59 ~7 ~58 stone 2  
fill ~58 ~7 ~60 ~59 ~7 ~60 stained_hardened_clay 5  
fill ~58 ~7 ~64 ~61 ~7 ~64 stained_hardened_clay 5  
fill ~58 ~7 ~65 ~58 ~8 ~65 dirt 0  
fill ~58 ~7 ~66 ~59 ~7 ~66 stone 0 
setblock ~58 ~7 ~70 dirt 0  
fill ~58 ~7 ~81 ~62 ~7 ~81 stone 0 
setblock ~58 ~7 ~83 stained_hardened_clay 5 
setblock ~59 ~7 ~52 planks 3  
fill ~59 ~7 ~54 ~59 ~7 ~55 stone 2  
fill ~59 ~7 ~56 ~59 ~11 ~56 planks 3  
fill ~59 ~7 ~57 ~59 ~7 ~56 planks 3  
fill ~59 ~7 ~61 ~59 ~9 ~61 dirt 0  
fill ~59 ~7 ~62 ~61 ~7 ~62 dirt 0  
fill ~59 ~7 ~63 ~59 ~9 ~63 dirt 0  
fill ~59 ~7 ~65 ~61 ~7 ~65 stained_hardened_clay 5  
fill ~59 ~7 ~68 ~62 ~7 ~68 stone 0 
setblock ~59 ~7 ~70 stone 0  
fill ~59 ~7 ~83 ~67 ~7 ~83 stone 0  
fill ~60 ~7 ~50 ~60 ~7 ~51 planks 3 
setblock ~60 ~7 ~52 stone 0  
fill ~60 ~7 ~54 ~60 ~7 ~59 stone 0  
fill ~60 ~7 ~60 ~60 ~8 ~60 dirt 0 
setblock ~60 ~7 ~61 stone 0  
fill ~60 ~7 ~63 ~63 ~7 ~63 stained_hardened_clay 5  
fill ~60 ~7 ~66 ~60 ~8 ~66 stained_hardened_clay 5 
setblock ~60 ~7 ~70 stained_hardened_clay 5 
setblock ~60 ~7 ~78 stained_hardened_clay 5 
setblock ~60 ~7 ~80 dirt 0  
fill ~61 ~7 ~50 ~61 ~7 ~51 stone 0  
fill ~61 ~7 ~52 ~61 ~10 ~52 planks 3  
fill ~61 ~7 ~53 ~61 ~7 ~52 planks 3  
fill ~61 ~7 ~54 ~62 ~7 ~54 stone 2  
fill ~61 ~7 ~55 ~61 ~7 ~57 stone 0  
fill ~61 ~7 ~58 ~62 ~7 ~58 planks 3 
setblock ~61 ~7 ~59 dirt 0  
fill ~61 ~7 ~61 ~62 ~7 ~61 stained_hardened_clay 5  
fill ~61 ~7 ~66 ~61 ~8 ~66 stone 0  
fill ~61 ~7 ~69 ~61 ~10 ~69 dirt 0  
fill ~61 ~7 ~70 ~63 ~7 ~70 stone 0 
setblock ~61 ~7 ~71 stained_hardened_clay 5  
fill ~61 ~7 ~77 ~61 ~10 ~77 dirt 0 
setblock ~61 ~7 ~78 stone 0  
fill ~61 ~7 ~80 ~61 ~8 ~80 stone 0 
setblock ~61 ~7 ~82 stained_hardened_clay 5  
fill ~61 ~7 ~89 ~61 ~7 ~90 stone 2  
fill ~62 ~7 ~50 ~62 ~8 ~50 planks 3 
setblock ~62 ~7 ~51 stone 2  
fill ~62 ~7 ~52 ~62 ~7 ~53 stone 0  
fill ~62 ~7 ~55 ~62 ~8 ~55 planks 3  
fill ~62 ~7 ~56 ~62 ~7 ~55 planks 3  
fill ~62 ~7 ~57 ~64 ~7 ~57 stone 0 
setblock ~62 ~7 ~59 stone 0  
fill ~62 ~7 ~60 ~63 ~7 ~60 dirt 0 
setblock ~62 ~7 ~62 stained_hardened_clay 5 
setblock ~62 ~7 ~64 dirt 0  
fill ~62 ~7 ~65 ~63 ~7 ~65 stone 0  
fill ~62 ~7 ~66 ~62 ~9 ~66 stained_hardened_clay 5 
setblock ~62 ~7 ~69 stained_hardened_clay 5 
setblock ~62 ~7 ~71 stone 0  
fill ~62 ~7 ~72 ~62 ~7 ~73 dirt 0 
setblock ~62 ~7 ~75 dirt 0  
fill ~62 ~7 ~77 ~63 ~7 ~77 stained_hardened_clay 5  
fill ~62 ~7 ~78 ~62 ~8 ~78 stained_hardened_clay 5  
fill ~62 ~7 ~79 ~63 ~7 ~79 stone 0  
fill ~62 ~7 ~80 ~63 ~7 ~80 dirt 0  
fill ~62 ~7 ~82 ~64 ~7 ~82 stone 0 
setblock ~62 ~7 ~87 stone 2 
setblock ~62 ~7 ~88 planks 3  
fill ~62 ~7 ~89 ~62 ~7 ~90 stone 0  
fill ~62 ~7 ~91 ~62 ~8 ~91 planks 3 
setblock ~63 ~7 ~50 stone 0 
setblock ~63 ~7 ~51 planks 3  
fill ~63 ~7 ~52 ~64 ~7 ~52 stone 2  
fill ~63 ~7 ~53 ~65 ~7 ~53 planks 3 
setblock ~63 ~7 ~54 stone 0 
setblock ~63 ~7 ~55 stone 2  
fill ~63 ~7 ~56 ~66 ~7 ~56 stone 0 
setblock ~63 ~7 ~58 stone 0  
fill ~63 ~7 ~59 ~63 ~8 ~59 dirt 0 
setblock ~63 ~7 ~61 stone 0  
fill ~63 ~7 ~62 ~64 ~7 ~62 dirt 0  
fill ~63 ~7 ~64 ~64 ~7 ~64 stained_hardened_clay 5  
fill ~63 ~7 ~66 ~64 ~7 ~66 stone 0 
setblock ~63 ~7 ~67 dirt 0 
setblock ~63 ~7 ~68 stained_hardened_clay 5  
fill ~63 ~7 ~69 ~65 ~7 ~69 dirt 0 
setblock ~63 ~7 ~71 stained_hardened_clay 5  
fill ~63 ~7 ~72 ~63 ~7 ~73 stone 0  
fill ~63 ~7 ~74 ~63 ~7 ~77 stained_hardened_clay 5 
setblock ~63 ~7 ~78 dirt 0 
setblock ~63 ~7 ~81 dirt 0  
fill ~63 ~7 ~88 ~64 ~7 ~88 stone 0  
fill ~63 ~7 ~89 ~63 ~8 ~89 stone 2  
fill ~63 ~7 ~90 ~64 ~7 ~90 planks 3  
fill ~63 ~7 ~91 ~63 ~7 ~92 stone 2  
fill ~64 ~7 ~50 ~64 ~11 ~50 planks 3 
setblock ~64 ~7 ~51 stone 0 
setblock ~64 ~7 ~54 planks 3  
fill ~64 ~7 ~55 ~69 ~7 ~55 stone 0 
setblock ~64 ~7 ~58 dirt 0  
fill ~64 ~7 ~59 ~64 ~9 ~59 stained_hardened_clay 5 
setblock ~64 ~7 ~60 stone 0  
fill ~64 ~7 ~61 ~65 ~7 ~61 stained_hardened_clay 5  
fill ~64 ~7 ~63 ~64 ~8 ~63 dirt 0  
fill ~64 ~7 ~65 ~64 ~8 ~65 dirt 0 
setblock ~64 ~7 ~67 stone 0  
fill ~64 ~7 ~68 ~64 ~8 ~68 dirt 0 
setblock ~64 ~7 ~70 stained_hardened_clay 5  
fill ~64 ~7 ~72 ~65 ~7 ~72 stained_hardened_clay 5  
fill ~64 ~7 ~73 ~64 ~7 ~74 stone 0  
fill ~64 ~7 ~75 ~64 ~7 ~76 stained_hardened_clay 5  
fill ~64 ~7 ~77 ~64 ~9 ~77 dirt 0  
fill ~64 ~7 ~78 ~64 ~7 ~80 stained_hardened_clay 5  
fill ~64 ~7 ~81 ~70 ~7 ~81 stone 0  
fill ~64 ~7 ~87 ~67 ~7 ~87 stone 2  
fill ~64 ~7 ~89 ~65 ~7 ~89 stone 0  
fill ~64 ~7 ~91 ~64 ~7 ~129 stone 0  
fill ~65 ~7 ~50 ~65 ~9 ~50 stone 2  
fill ~65 ~7 ~51 ~66 ~7 ~51 planks 3  
fill ~65 ~7 ~52 ~65 ~7 ~51 planks 3 
setblock ~65 ~7 ~54 stone 2 
setblock ~65 ~7 ~57 dirt 0  
fill ~65 ~7 ~58 ~65 ~8 ~58 stone 0  
fill ~65 ~7 ~60 ~65 ~9 ~60 dirt 0  
fill ~65 ~7 ~62 ~66 ~7 ~62 stained_hardened_clay 5  
fill ~65 ~7 ~63 ~67 ~7 ~63 stained_hardened_clay 5  
fill ~65 ~7 ~64 ~66 ~7 ~64 dirt 0  
fill ~65 ~7 ~65 ~66 ~7 ~65 stone 0  
fill ~65 ~7 ~66 ~65 ~9 ~66 stained_hardened_clay 5 
setblock ~65 ~7 ~67 dirt 0  
fill ~65 ~7 ~68 ~66 ~7 ~68 stained_hardened_clay 5  
fill ~65 ~7 ~70 ~69 ~7 ~70 dirt 0  
fill ~65 ~7 ~71 ~65 ~8 ~71 dirt 0  
fill ~65 ~7 ~73 ~65 ~7 ~75 dirt 0  
fill ~65 ~7 ~76 ~66 ~7 ~76 stained_hardened_clay 5  
fill ~65 ~7 ~78 ~66 ~7 ~78 dirt 0  
fill ~65 ~7 ~79 ~65 ~7 ~81 stone 0  
fill ~65 ~7 ~82 ~65 ~8 ~82 stained_hardened_clay 5  
fill ~65 ~7 ~86 ~66 ~7 ~86 planks 3  
fill ~65 ~7 ~88 ~66 ~7 ~88 stone 2  
fill ~65 ~7 ~90 ~65 ~8 ~90 stone 2  
fill ~65 ~7 ~91 ~65 ~8 ~91 stone 2 
setblock ~65 ~7 ~92 stone 0  
fill ~65 ~7 ~93 ~65 ~8 ~93 stone 2 
setblock ~66 ~7 ~50 stone 0  
fill ~66 ~7 ~52 ~68 ~7 ~52 stone 0 
setblock ~66 ~7 ~53 stone 2  
fill ~66 ~7 ~54 ~66 ~9 ~54 planks 3  
fill ~66 ~7 ~57 ~67 ~7 ~57 stained_hardened_clay 5  
fill ~66 ~7 ~58 ~67 ~7 ~58 dirt 0  
fill ~66 ~7 ~59 ~66 ~7 ~60 stained_hardened_clay 5  
fill ~66 ~7 ~61 ~66 ~10 ~61 dirt 0 
setblock ~66 ~7 ~66 stone 0  
fill ~66 ~7 ~67 ~66 ~8 ~67 stained_hardened_clay 5  
fill ~66 ~7 ~72 ~67 ~7 ~72 dirt 0  
fill ~66 ~7 ~73 ~67 ~7 ~73 stained_hardened_clay 5  
fill ~66 ~7 ~74 ~68 ~7 ~74 stained_hardened_clay 5  
fill ~66 ~7 ~75 ~67 ~7 ~75 dirt 0  
fill ~66 ~7 ~77 ~66 ~8 ~77 dirt 0  
fill ~66 ~7 ~79 ~67 ~7 ~79 dirt 0  
fill ~66 ~7 ~80 ~70 ~7 ~80 stone 0  
fill ~66 ~7 ~82 ~66 ~8 ~82 stone 0  
fill ~66 ~7 ~85 ~68 ~7 ~85 stone 2  
fill ~66 ~7 ~89 ~67 ~7 ~89 stone 2  
fill ~66 ~7 ~90 ~66 ~8 ~90 planks 3  
fill ~66 ~7 ~91 ~67 ~7 ~91 stone 0  
fill ~66 ~7 ~92 ~66 ~9 ~92 planks 3  
fill ~66 ~7 ~93 ~66 ~7 ~92 planks 3 
setblock ~67 ~7 ~50 planks 3  
fill ~67 ~7 ~51 ~68 ~7 ~51 stone 0  
fill ~67 ~7 ~53 ~67 ~8 ~53 planks 3  
fill ~67 ~7 ~54 ~68 ~7 ~54 stone 0 
setblock ~67 ~7 ~56 stained_hardened_clay 5  
fill ~67 ~7 ~59 ~68 ~7 ~59 dirt 0  
fill ~67 ~7 ~60 ~67 ~0 ~60 stone 0  
fill ~67 ~7 ~61 ~68 ~7 ~61 stone 0  
fill ~67 ~7 ~62 ~67 ~8 ~62 stone 0  
fill ~67 ~7 ~64 ~67 ~7 ~66 stained_hardened_clay 5  
fill ~67 ~7 ~67 ~71 ~7 ~67 dirt 0  
fill ~67 ~7 ~71 ~67 ~8 ~71 dirt 0 
setblock ~67 ~7 ~76 stone 0  
fill ~67 ~7 ~77 ~67 ~8 ~77 stained_hardened_clay 5  
fill ~67 ~7 ~78 ~70 ~7 ~78 stone 0 
setblock ~67 ~7 ~82 planks 3  
fill ~67 ~7 ~84 ~70 ~7 ~84 planks 3 
setblock ~67 ~7 ~86 stone 2 
setblock ~67 ~7 ~88 planks 3  
fill ~67 ~7 ~90 ~69 ~7 ~90 stone 2  
fill ~67 ~7 ~92 ~67 ~8 ~92 stone 2  
fill ~67 ~7 ~93 ~67 ~8 ~93 stone 0  
fill ~68 ~7 ~48 ~69 ~7 ~48 planks 3  
fill ~68 ~7 ~49 ~68 ~7 ~48 planks 3  
fill ~68 ~7 ~50 ~70 ~7 ~50 stone 0  
fill ~68 ~7 ~53 ~72 ~7 ~53 stone 0  
fill ~68 ~7 ~56 ~68 ~7 ~57 dirt 0 
setblock ~68 ~7 ~58 stained_hardened_clay 5  
fill ~68 ~7 ~60 ~68 ~9 ~60 stained_hardened_clay 5 
setblock ~68 ~7 ~62 stained_hardened_clay 5  
fill ~68 ~7 ~63 ~68 ~0 ~63 stone 0  
fill ~68 ~7 ~64 ~69 ~7 ~64 dirt 0  
fill ~68 ~7 ~65 ~69 ~7 ~65 stained_hardened_clay 5 
setblock ~68 ~7 ~66 dirt 0  
fill ~68 ~7 ~73 ~70 ~7 ~73 dirt 0  
fill ~68 ~7 ~75 ~68 ~8 ~75 stained_hardened_clay 5  
fill ~68 ~7 ~76 ~69 ~7 ~76 stained_hardened_clay 5 
setblock ~68 ~7 ~77 dirt 0  
fill ~68 ~7 ~79 ~70 ~7 ~79 stone 0  
fill ~68 ~7 ~82 ~129 ~7 ~82 stone 0 
setblock ~68 ~7 ~83 stone 2  
fill ~68 ~7 ~86 ~69 ~7 ~86 planks 3 
setblock ~68 ~7 ~87 stone 0  
fill ~68 ~7 ~88 ~68 ~11 ~88 stone 2  
fill ~68 ~7 ~89 ~68 ~9 ~89 planks 3 
setblock ~68 ~7 ~91 planks 3  
fill ~68 ~7 ~92 ~129 ~7 ~92 stone 0 
setblock ~68 ~7 ~93 planks 3  
fill ~69 ~7 ~46 ~69 ~8 ~46 stone 2  
fill ~69 ~7 ~47 ~69 ~7 ~46 stone 2  
fill ~69 ~7 ~49 ~73 ~7 ~49 stone 0 
setblock ~69 ~7 ~51 planks 3  
fill ~69 ~7 ~52 ~70 ~7 ~52 stone 2 
setblock ~69 ~7 ~54 stone 2 
setblock ~69 ~7 ~56 stone 0  
fill ~69 ~7 ~57 ~70 ~7 ~57 dirt 0  
fill ~69 ~7 ~59 ~71 ~7 ~59 stained_hardened_clay 5 
setblock ~69 ~7 ~60 stone 0  
fill ~69 ~7 ~61 ~72 ~7 ~61 dirt 0 
setblock ~69 ~7 ~62 stone 0 
setblock ~69 ~7 ~63 dirt 0  
fill ~69 ~7 ~68 ~69 ~8 ~68 stained_hardened_clay 5  
fill ~69 ~7 ~69 ~69 ~7 ~68 stained_hardened_clay 5  
fill ~69 ~7 ~71 ~69 ~10 ~71 stained_hardened_clay 5  
fill ~69 ~7 ~72 ~71 ~7 ~72 stained_hardened_clay 5  
fill ~69 ~7 ~74 ~70 ~7 ~74 dirt 0 
setblock ~69 ~7 ~75 stone 0  
fill ~69 ~7 ~77 ~70 ~7 ~77 stone 0 
setblock ~69 ~7 ~83 stone 0 
setblock ~69 ~7 ~85 planks 3  
fill ~69 ~7 ~87 ~69 ~9 ~87 planks 3  
fill ~69 ~7 ~88 ~129 ~7 ~88 stone 0  
fill ~69 ~7 ~89 ~69 ~8 ~89 stone 2  
fill ~69 ~7 ~91 ~129 ~7 ~91 stone 0  
fill ~69 ~7 ~93 ~129 ~7 ~93 stone 0 
setblock ~70 ~7 ~46 stone 0 
setblock ~70 ~7 ~47 planks 3 
setblock ~70 ~7 ~48 stone 2  
fill ~70 ~7 ~51 ~70 ~9 ~51 stone 2 
setblock ~70 ~7 ~54 dirt 0  
fill ~70 ~7 ~55 ~70 ~7 ~56 stained_hardened_clay 5 
setblock ~70 ~7 ~58 dirt 0  
fill ~70 ~7 ~60 ~70 ~8 ~60 dirt 0 
setblock ~70 ~7 ~62 stained_hardened_clay 5  
fill ~70 ~7 ~64 ~72 ~7 ~64 stained_hardened_clay 5  
fill ~70 ~7 ~65 ~70 ~8 ~65 dirt 0  
fill ~70 ~7 ~66 ~70 ~7 ~65 dirt 0  
fill ~70 ~7 ~68 ~71 ~7 ~68 dirt 0  
fill ~70 ~7 ~69 ~70 ~7 ~65 dirt 0  
fill ~70 ~7 ~70 ~71 ~7 ~70 stained_hardened_clay 5 
setblock ~70 ~7 ~75 dirt 0 
setblock ~70 ~7 ~76 planks 3 
setblock ~70 ~7 ~85 stone 0  
fill ~70 ~7 ~86 ~70 ~7 ~87 stone 2  
fill ~70 ~7 ~89 ~129 ~7 ~89 stone 0  
fill ~70 ~7 ~90 ~129 ~7 ~90 stone 0 
setblock ~71 ~7 ~43 stone 2  
fill ~71 ~7 ~45 ~72 ~7 ~45 stone 2  
fill ~71 ~7 ~46 ~71 ~8 ~46 planks 3  
fill ~71 ~7 ~47 ~71 ~8 ~47 stone 2 
setblock ~71 ~7 ~48 stone 0 
setblock ~71 ~7 ~50 stone 2  
fill ~71 ~7 ~51 ~74 ~7 ~51 stone 0  
fill ~71 ~7 ~52 ~71 ~7 ~51 stone 0 
setblock ~71 ~7 ~54 stone 0  
fill ~71 ~7 ~55 ~72 ~7 ~55 dirt 0  
fill ~71 ~7 ~57 ~71 ~8 ~57 stained_hardened_clay 5 
setblock ~71 ~7 ~58 stone 0  
fill ~71 ~7 ~60 ~71 ~8 ~60 stained_hardened_clay 5  
fill ~71 ~7 ~65 ~71 ~11 ~65 stained_hardened_clay 5 
setblock ~71 ~7 ~69 stained_hardened_clay 5  
fill ~71 ~7 ~71 ~72 ~7 ~71 dirt 0 
setblock ~71 ~7 ~73 stained_hardened_clay 5  
fill ~71 ~7 ~74 ~129 ~7 ~74 stone 0  
fill ~71 ~7 ~75 ~129 ~7 ~75 stone 0  
fill ~71 ~7 ~76 ~71 ~7 ~74 stone 0  
fill ~71 ~7 ~77 ~71 ~7 ~79 stone 2  
fill ~71 ~7 ~80 ~71 ~8 ~80 planks 3  
fill ~71 ~7 ~84 ~129 ~7 ~84 stone 0 
setblock ~71 ~7 ~85 planks 3  
fill ~71 ~7 ~86 ~129 ~7 ~86 stone 0  
fill ~71 ~7 ~87 ~129 ~7 ~87 stone 0 
setblock ~72 ~7 ~41 stone 2 
setblock ~72 ~7 ~43 stone 0 
setblock ~72 ~7 ~44 stone 2  
fill ~72 ~7 ~46 ~73 ~7 ~46 stone 2  
fill ~72 ~7 ~47 ~73 ~7 ~47 planks 3  
fill ~72 ~7 ~48 ~72 ~7 ~47 planks 3 
setblock ~72 ~7 ~50 stone 0 
setblock ~72 ~7 ~52 dirt 0 
setblock ~72 ~7 ~54 stained_hardened_clay 5  
fill ~72 ~7 ~57 ~72 ~10 ~57 dirt 0  
fill ~72 ~7 ~58 ~72 ~11 ~58 dirt 0  
fill ~72 ~7 ~59 ~129 ~7 ~59 stone 0  
fill ~72 ~7 ~62 ~72 ~0 ~62 stone 0 
setblock ~72 ~7 ~63 dirt 0 
setblock ~72 ~7 ~65 dirt 0  
fill ~72 ~7 ~67 ~72 ~8 ~67 stained_hardened_clay 5  
fill ~72 ~7 ~68 ~74 ~7 ~68 stained_hardened_clay 5  
fill ~72 ~7 ~69 ~73 ~7 ~69 dirt 0  
fill ~72 ~7 ~70 ~72 ~9 ~70 dirt 0  
fill ~72 ~7 ~72 ~72 ~10 ~72 dirt 0  
fill ~72 ~7 ~73 ~77 ~7 ~73 stone 0  
fill ~72 ~7 ~76 ~74 ~7 ~76 planks 3 
setblock ~72 ~7 ~77 stone 0  
fill ~72 ~7 ~78 ~76 ~7 ~78 planks 3  
fill ~72 ~7 ~79 ~72 ~8 ~79 stone 2  
fill ~72 ~7 ~80 ~72 ~7 ~82 stone 0 
setblock ~72 ~7 ~83 planks 3  
fill ~72 ~7 ~85 ~129 ~7 ~85 stone 0  
fill ~73 ~7 ~39 ~73 ~8 ~39 planks 3 
setblock ~73 ~7 ~41 planks 3 
setblock ~73 ~7 ~43 stone 2 
setblock ~73 ~7 ~44 stone 0  
fill ~73 ~7 ~45 ~73 ~9 ~45 planks 3  
fill ~73 ~7 ~48 ~74 ~7 ~48 stone 2 
setblock ~73 ~7 ~50 stone 2  
fill ~73 ~7 ~52 ~74 ~7 ~52 stone 0  
fill ~73 ~7 ~53 ~73 ~7 ~54 dirt 0  
fill ~73 ~7 ~55 ~73 ~8 ~55 stained_hardened_clay 5  
fill ~73 ~7 ~56 ~73 ~12 ~56 stained_hardened_clay 5  
fill ~73 ~7 ~57 ~73 ~7 ~59 stone 0  
fill ~73 ~7 ~60 ~73 ~12 ~60 stained_hardened_clay 5  
fill ~73 ~7 ~61 ~74 ~7 ~61 stone 0  
fill ~73 ~7 ~62 ~73 ~8 ~62 stained_hardened_clay 5  
fill ~73 ~7 ~63 ~73 ~9 ~63 stained_hardened_clay 5  
fill ~73 ~7 ~64 ~73 ~0 ~64 stone 0  
fill ~73 ~7 ~65 ~73 ~10 ~65 stained_hardened_clay 5  
fill ~73 ~7 ~66 ~74 ~7 ~66 stained_hardened_clay 5 
setblock ~73 ~7 ~67 dirt 0  
fill ~73 ~7 ~70 ~76 ~7 ~70 stone 0  
fill ~73 ~7 ~71 ~76 ~7 ~71 stone 0  
fill ~73 ~7 ~72 ~129 ~7 ~72 stone 0 
setblock ~73 ~7 ~77 planks 3 
setblock ~73 ~7 ~79 stone 0  
fill ~73 ~7 ~80 ~74 ~7 ~80 stone 2  
fill ~73 ~7 ~81 ~75 ~7 ~81 stone 0  
fill ~73 ~7 ~83 ~129 ~7 ~83 stone 0 
setblock ~74 ~7 ~36 planks 3 
setblock ~74 ~7 ~39 stone 0 
setblock ~74 ~7 ~40 planks 3  
fill ~74 ~7 ~41 ~74 ~9 ~41 stone 2  
fill ~74 ~7 ~42 ~74 ~0 ~42 stone 0 
setblock ~74 ~7 ~43 planks 3  
fill ~74 ~7 ~46 ~74 ~10 ~46 planks 3  
fill ~74 ~7 ~47 ~75 ~7 ~47 stone 2 
setblock ~74 ~7 ~49 planks 3  
fill ~74 ~7 ~50 ~77 ~7 ~50 stone 0  
fill ~74 ~7 ~53 ~74 ~7 ~54 stone 0  
fill ~74 ~7 ~55 ~74 ~8 ~55 dirt 0 
setblock ~74 ~7 ~56 stone 0  
fill ~74 ~7 ~57 ~74 ~10 ~57 stained_hardened_clay 5 
setblock ~74 ~7 ~58 dirt 0  
fill ~74 ~7 ~60 ~129 ~7 ~60 stone 0  
fill ~74 ~7 ~62 ~75 ~7 ~62 stone 0  
fill ~74 ~7 ~63 ~75 ~7 ~63 stone 0 
setblock ~74 ~7 ~64 stained_hardened_clay 5  
fill ~74 ~7 ~65 ~75 ~7 ~65 dirt 0  
fill ~74 ~7 ~67 ~74 ~0 ~67 stone 0  
fill ~74 ~7 ~69 ~129 ~7 ~69 stone 0  
fill ~74 ~7 ~77 ~74 ~8 ~77 stone 0  
fill ~74 ~7 ~79 ~75 ~7 ~79 stone 2 
setblock ~75 ~7 ~36 stone 0  
fill ~75 ~7 ~37 ~75 ~8 ~37 stone 2  
fill ~75 ~7 ~38 ~76 ~7 ~38 stone 2  
fill ~75 ~7 ~39 ~75 ~7 ~37 stone 2 
setblock ~75 ~7 ~40 stone 0  
fill ~75 ~7 ~42 ~76 ~7 ~42 planks 3  
fill ~75 ~7 ~43 ~75 ~8 ~43 stone 2  
fill ~75 ~7 ~44 ~76 ~7 ~44 stone 2  
fill ~75 ~7 ~45 ~76 ~7 ~45 planks 3  
fill ~75 ~7 ~46 ~76 ~7 ~46 stone 2  
fill ~75 ~7 ~48 ~75 ~7 ~50 stone 0  
fill ~75 ~7 ~51 ~75 ~9 ~51 stained_hardened_clay 5  
fill ~75 ~7 ~52 ~75 ~7 ~53 dirt 0  
fill ~75 ~7 ~54 ~76 ~7 ~54 stained_hardened_clay 5  
fill ~75 ~7 ~55 ~75 ~7 ~56 stained_hardened_clay 5  
fill ~75 ~7 ~57 ~129 ~7 ~57 stone 0  
fill ~75 ~7 ~58 ~129 ~7 ~58 stone 0 
setblock ~75 ~7 ~61 dirt 0 
setblock ~75 ~7 ~64 stone 0  
fill ~75 ~7 ~66 ~129 ~7 ~66 stone 0 
setblock ~75 ~7 ~67 stained_hardened_clay 5  
fill ~75 ~7 ~68 ~76 ~7 ~68 stone 0  
fill ~75 ~7 ~76 ~129 ~7 ~76 stone 0 
setblock ~75 ~7 ~77 stone 2  
fill ~75 ~7 ~80 ~75 ~8 ~80 planks 3  
fill ~76 ~7 ~33 ~77 ~7 ~33 stone 2  
fill ~76 ~7 ~35 ~76 ~7 ~37 planks 3  
fill ~76 ~7 ~39 ~76 ~8 ~39 stone 0  
fill ~76 ~7 ~40 ~77 ~7 ~40 stone 2  
fill ~76 ~7 ~41 ~77 ~7 ~41 stone 2 
setblock ~76 ~7 ~43 planks 3  
fill ~76 ~7 ~47 ~76 ~11 ~47 planks 3  
fill ~76 ~7 ~48 ~76 ~9 ~48 stone 2  
fill ~76 ~7 ~49 ~80 ~7 ~49 stone 0  
fill ~76 ~7 ~51 ~76 ~7 ~52 stone 0 
setblock ~76 ~7 ~53 stained_hardened_clay 5  
fill ~76 ~7 ~55 ~129 ~7 ~55 stone 0  
fill ~76 ~7 ~56 ~129 ~7 ~56 stone 0  
fill ~76 ~7 ~61 ~129 ~7 ~61 stone 0 
setblock ~76 ~7 ~62 dirt 0 
setblock ~76 ~7 ~63 stained_hardened_clay 5 
setblock ~76 ~7 ~64 dirt 0 
setblock ~76 ~7 ~65 stained_hardened_clay 5  
fill ~76 ~7 ~67 ~129 ~7 ~67 stone 0  
fill ~76 ~7 ~77 ~129 ~7 ~77 stone 0  
fill ~76 ~7 ~79 ~129 ~7 ~79 stone 0  
fill ~76 ~7 ~80 ~129 ~7 ~80 stone 0 
setblock ~76 ~7 ~81 planks 3 
setblock ~77 ~7 ~32 stone 2 
setblock ~77 ~7 ~36 stone 2  
fill ~77 ~7 ~37 ~77 ~7 ~38 stone 0  
fill ~77 ~7 ~39 ~78 ~7 ~39 planks 3  
fill ~77 ~7 ~42 ~80 ~7 ~42 stone 0  
fill ~77 ~7 ~43 ~79 ~7 ~43 stone 2 
setblock ~77 ~7 ~44 planks 3  
fill ~77 ~7 ~46 ~78 ~7 ~46 planks 3  
fill ~77 ~7 ~47 ~77 ~10 ~47 stone 2  
fill ~77 ~7 ~48 ~79 ~7 ~48 stone 0  
fill ~77 ~7 ~51 ~81 ~7 ~51 stained_hardened_clay 5  
fill ~77 ~7 ~52 ~77 ~8 ~52 stone 0  
fill ~77 ~7 ~53 ~82 ~7 ~53 stone 0  
fill ~77 ~7 ~54 ~77 ~10 ~54 dirt 0  
fill ~77 ~7 ~62 ~129 ~7 ~62 stone 0  
fill ~77 ~7 ~63 ~129 ~7 ~63 stone 0  
fill ~77 ~7 ~64 ~129 ~7 ~64 stone 0  
fill ~77 ~7 ~65 ~129 ~7 ~65 stone 0  
fill ~77 ~7 ~68 ~77 ~9 ~68 stained_hardened_clay 5  
fill ~77 ~7 ~70 ~77 ~8 ~70 stained_hardened_clay 5  
fill ~77 ~7 ~71 ~77 ~7 ~70 stained_hardened_clay 5  
fill ~77 ~7 ~78 ~129 ~7 ~78 stone 0  
fill ~77 ~7 ~81 ~129 ~7 ~81 stone 0  
fill ~78 ~7 ~31 ~78 ~7 ~32 planks 3 
setblock ~78 ~7 ~33 stone 0 
setblock ~78 ~7 ~34 stone 2 
setblock ~78 ~7 ~35 planks 3  
fill ~78 ~7 ~37 ~78 ~10 ~37 stone 2  
fill ~78 ~7 ~38 ~78 ~8 ~38 stone 2  
fill ~78 ~7 ~40 ~80 ~7 ~40 stone 0 
setblock ~78 ~7 ~41 planks 3  
fill ~78 ~7 ~45 ~78 ~9 ~45 stone 2 
setblock ~78 ~7 ~47 planks 3 
setblock ~78 ~7 ~50 dirt 0  
fill ~78 ~7 ~52 ~78 ~11 ~52 dirt 0  
fill ~78 ~7 ~54 ~78 ~8 ~54 stained_hardened_clay 5  
fill ~78 ~7 ~68 ~129 ~7 ~68 stone 0  
fill ~78 ~7 ~70 ~129 ~7 ~70 stone 0  
fill ~78 ~7 ~71 ~129 ~7 ~71 stone 0 
setblock ~78 ~7 ~73 dirt 0  
fill ~79 ~7 ~30 ~80 ~7 ~30 planks 3 
setblock ~79 ~7 ~31 stone 0  
fill ~79 ~7 ~32 ~83 ~7 ~32 planks 3  
fill ~79 ~7 ~33 ~79 ~7 ~32 planks 3  
fill ~79 ~7 ~37 ~79 ~7 ~38 planks 3  
fill ~79 ~7 ~39 ~81 ~7 ~39 stone 0 
setblock ~79 ~7 ~41 stone 2  
fill ~79 ~7 ~44 ~80 ~7 ~44 planks 3  
fill ~79 ~7 ~45 ~80 ~7 ~45 stone 0  
fill ~79 ~7 ~46 ~80 ~7 ~46 stone 0  
fill ~79 ~7 ~47 ~80 ~7 ~47 stone 0  
fill ~79 ~7 ~50 ~129 ~7 ~50 stone 0 
setblock ~79 ~7 ~52 stained_hardened_clay 5 
setblock ~79 ~7 ~54 stone 0  
fill ~79 ~7 ~73 ~129 ~7 ~73 stone 0  
fill ~80 ~7 ~25 ~80 ~8 ~25 planks 3  
fill ~80 ~7 ~28 ~80 ~8 ~28 planks 3  
fill ~80 ~7 ~29 ~80 ~7 ~28 planks 3  
fill ~80 ~7 ~31 ~80 ~8 ~31 stone 2  
fill ~80 ~7 ~33 ~80 ~8 ~33 stone 2  
fill ~80 ~7 ~34 ~80 ~7 ~35 stone 2  
fill ~80 ~7 ~36 ~81 ~7 ~36 planks 3  
fill ~80 ~7 ~38 ~80 ~8 ~38 planks 3  
fill ~80 ~7 ~41 ~84 ~7 ~41 stone 0 
setblock ~80 ~7 ~43 stone 0  
fill ~80 ~7 ~48 ~80 ~9 ~48 dirt 0  
fill ~80 ~7 ~52 ~129 ~7 ~52 stone 0 
setblock ~80 ~7 ~54 stained_hardened_clay 5 
setblock ~81 ~7 ~25 stone 0  
fill ~81 ~7 ~28 ~81 ~7 ~29 stone 0  
fill ~81 ~7 ~30 ~81 ~9 ~30 stone 2 
setblock ~81 ~7 ~31 planks 3  
fill ~81 ~7 ~33 ~83 ~7 ~33 planks 3  
fill ~81 ~7 ~34 ~82 ~7 ~34 planks 3 
setblock ~81 ~7 ~35 stone 2 
setblock ~81 ~7 ~38 stone 2 
setblock ~81 ~7 ~40 stone 2  
fill ~81 ~7 ~42 ~81 ~7 ~43 dirt 0  
fill ~81 ~7 ~44 ~83 ~7 ~44 stained_hardened_clay 5  
fill ~81 ~7 ~45 ~81 ~9 ~45 stained_hardened_clay 5 
setblock ~81 ~7 ~46 dirt 0  
fill ~81 ~7 ~47 ~82 ~7 ~47 stained_hardened_clay 5  
fill ~81 ~7 ~48 ~129 ~7 ~48 stone 0 
setblock ~81 ~7 ~49 dirt 0  
fill ~81 ~7 ~54 ~129 ~7 ~54 stone 0 
setblock ~82 ~7 ~25 planks 3  
fill ~82 ~7 ~28 ~82 ~8 ~28 stone 2 
setblock ~82 ~7 ~30 planks 3 
setblock ~82 ~7 ~31 stone 0 
setblock ~82 ~7 ~35 planks 3 
setblock ~82 ~7 ~36 stone 2  
fill ~82 ~7 ~38 ~82 ~10 ~38 planks 3  
fill ~82 ~7 ~39 ~82 ~9 ~39 stone 2 
setblock ~82 ~7 ~40 stained_hardened_clay 5  
fill ~82 ~7 ~42 ~82 ~7 ~43 stone 0 
setblock ~82 ~7 ~45 stone 0 
setblock ~82 ~7 ~46 stained_hardened_clay 5  
fill ~82 ~7 ~49 ~129 ~7 ~49 stone 0  
fill ~82 ~7 ~51 ~83 ~7 ~51 dirt 0  
fill ~83 ~7 ~25 ~88 ~7 ~25 stone 0  
fill ~83 ~7 ~28 ~129 ~7 ~28 stone 0 
setblock ~83 ~7 ~29 planks 3 
setblock ~83 ~7 ~30 stone 0  
fill ~83 ~7 ~34 ~83 ~7 ~35 stone 2  
fill ~83 ~7 ~36 ~83 ~9 ~36 planks 3  
fill ~83 ~7 ~38 ~83 ~8 ~38 stone 2 
setblock ~83 ~7 ~39 stone 0 
setblock ~83 ~7 ~42 stained_hardened_clay 5 
setblock ~83 ~7 ~43 dirt 0 
setblock ~83 ~7 ~45 stained_hardened_clay 5  
fill ~83 ~7 ~46 ~83 ~8 ~46 stone 0  
fill ~83 ~7 ~47 ~129 ~7 ~47 stone 0 
setblock ~83 ~7 ~53 stained_hardened_clay 5  
fill ~84 ~7 ~29 ~84 ~8 ~29 stone 2  
fill ~84 ~7 ~30 ~84 ~8 ~30 stone 2  
fill ~84 ~7 ~31 ~84 ~7 ~33 stone 0  
fill ~84 ~7 ~34 ~85 ~7 ~34 planks 3  
fill ~84 ~7 ~35 ~84 ~7 ~36 stone 0  
fill ~84 ~7 ~37 ~85 ~7 ~37 planks 3 
setblock ~84 ~7 ~38 dirt 0  
fill ~84 ~7 ~39 ~85 ~7 ~39 planks 3 
setblock ~84 ~7 ~40 dirt 0  
fill ~84 ~7 ~42 ~87 ~7 ~42 stone 0  
fill ~84 ~7 ~43 ~84 ~8 ~43 stained_hardened_clay 5  
fill ~84 ~7 ~44 ~129 ~7 ~44 stone 0  
fill ~84 ~7 ~45 ~90 ~7 ~45 stone 0 
setblock ~84 ~7 ~46 dirt 0  
fill ~84 ~7 ~51 ~129 ~7 ~51 stone 0  
fill ~84 ~7 ~53 ~129 ~7 ~53 stone 0  
fill ~85 ~7 ~29 ~86 ~7 ~29 stone 0  
fill ~85 ~7 ~30 ~129 ~7 ~30 stone 0  
fill ~85 ~7 ~31 ~86 ~7 ~31 dirt 1  
fill ~85 ~7 ~32 ~86 ~7 ~32 stone 0 
setblock ~85 ~7 ~33 planks 3 
setblock ~85 ~7 ~35 planks 3 
setblock ~85 ~7 ~36 stained_hardened_clay 5 
setblock ~85 ~7 ~38 planks 3 
setblock ~85 ~7 ~40 planks 3  
fill ~85 ~7 ~41 ~85 ~8 ~41 dirt 0 
setblock ~85 ~7 ~43 stone 0  
fill ~85 ~7 ~46 ~129 ~7 ~46 stone 0 
setblock ~86 ~7 ~33 dirt 1  
fill ~86 ~7 ~34 ~87 ~7 ~34 stone 0  
fill ~86 ~7 ~35 ~86 ~0 ~35 stone 0  
fill ~86 ~7 ~36 ~86 ~7 ~34 stone 0  
fill ~86 ~7 ~37 ~87 ~7 ~37 dirt 0  
fill ~86 ~7 ~38 ~86 ~7 ~37 dirt 0 
setblock ~86 ~7 ~40 stained_hardened_clay 5  
fill ~86 ~7 ~41 ~129 ~7 ~41 stone 0 
setblock ~86 ~7 ~43 stained_hardened_clay 5 
setblock ~87 ~7 ~29 planks 1  
fill ~87 ~7 ~31 ~89 ~7 ~31 stone 0 
setblock ~87 ~7 ~32 planks 1  
fill ~87 ~7 ~33 ~88 ~7 ~33 stone 0 
setblock ~87 ~7 ~35 planks 1  
fill ~87 ~7 ~36 ~87 ~8 ~36 dirt 1  
fill ~87 ~7 ~38 ~87 ~8 ~38 stone 0  
fill ~87 ~7 ~39 ~87 ~7 ~38 stone 0  
fill ~87 ~7 ~40 ~88 ~7 ~40 dirt 0  
fill ~87 ~7 ~43 ~89 ~7 ~43 stone 0  
fill ~88 ~7 ~29 ~129 ~7 ~29 stone 0  
fill ~88 ~7 ~32 ~89 ~7 ~32 stone 0 
setblock ~88 ~7 ~34 dirt 1  
fill ~88 ~7 ~35 ~90 ~7 ~35 stone 0 
setblock ~88 ~7 ~36 planks 1  
fill ~88 ~7 ~37 ~91 ~7 ~37 stone 0  
fill ~88 ~7 ~38 ~88 ~8 ~38 stained_hardened_clay 5  
fill ~88 ~7 ~39 ~88 ~7 ~38 stained_hardened_clay 5 
setblock ~88 ~7 ~42 stained_hardened_clay 5  
fill ~89 ~7 ~24 ~89 ~7 ~25 planks 1 
setblock ~89 ~7 ~33 planks 1 
setblock ~89 ~7 ~34 stone 0 
setblock ~89 ~7 ~36 stone 0  
fill ~89 ~7 ~38 ~89 ~7 ~129 stone 0  
fill ~90 ~7 ~24 ~129 ~7 ~24 stone 0  
fill ~90 ~7 ~25 ~90 ~7 ~2 stone 0 
setblock ~90 ~7 ~31 planks 1 
setblock ~90 ~7 ~32 dirt 1  
fill ~90 ~7 ~33 ~129 ~7 ~33 stone 0  
fill ~90 ~7 ~34 ~91 ~7 ~34 dirt 1  
fill ~90 ~7 ~36 ~90 ~8 ~36 dirt 1  
fill ~90 ~7 ~38 ~90 ~9 ~38 dirt 1  
fill ~90 ~7 ~39 ~90 ~7 ~38 dirt 1  
fill ~90 ~7 ~40 ~129 ~7 ~40 stone 0  
fill ~90 ~7 ~42 ~90 ~7 ~43 dirt 1  
fill ~91 ~7 ~25 ~92 ~7 ~25 dirt 1  
fill ~91 ~7 ~31 ~129 ~7 ~31 stone 0  
fill ~91 ~7 ~32 ~92 ~7 ~32 planks 1  
fill ~91 ~7 ~35 ~91 ~8 ~35 planks 1 
setblock ~91 ~7 ~36 stone 0  
fill ~91 ~7 ~38 ~91 ~9 ~38 planks 1  
fill ~91 ~7 ~39 ~129 ~7 ~39 stone 0  
fill ~91 ~7 ~42 ~91 ~7 ~43 planks 1  
fill ~91 ~7 ~45 ~91 ~9 ~45 planks 1  
fill ~92 ~7 ~34 ~129 ~7 ~34 stone 0  
fill ~92 ~7 ~35 ~129 ~7 ~35 stone 0  
fill ~92 ~7 ~36 ~93 ~7 ~36 dirt 1  
fill ~92 ~7 ~37 ~92 ~8 ~37 planks 1  
fill ~92 ~7 ~38 ~129 ~7 ~38 stone 0 
setblock ~92 ~7 ~42 dirt 1  
fill ~92 ~7 ~43 ~129 ~7 ~43 stone 0  
fill ~92 ~7 ~45 ~129 ~7 ~45 stone 0  
fill ~93 ~7 ~25 ~129 ~7 ~25 stone 0  
fill ~93 ~7 ~32 ~129 ~7 ~32 stone 0  
fill ~93 ~7 ~37 ~129 ~7 ~37 stone 0  
fill ~93 ~7 ~42 ~129 ~7 ~42 stone 0  
fill ~94 ~7 ~36 ~129 ~7 ~36 stone 0  
fill ~1 ~8 ~1 ~130 ~8 ~1 stained_hardened_clay 14  
fill ~1 ~8 ~130 ~130 ~8 ~130 stained_hardened_clay 14  
fill ~2 ~8 ~2 ~129 ~8 ~2 stone 0  
fill ~2 ~8 ~3 ~129 ~8 ~3 stone 0  
fill ~2 ~8 ~4 ~129 ~8 ~4 stone 0  
fill ~2 ~8 ~5 ~129 ~8 ~5 stone 0  
fill ~2 ~8 ~6 ~129 ~8 ~6 stone 0  
fill ~2 ~8 ~7 ~129 ~8 ~7 stone 0  
fill ~2 ~8 ~8 ~129 ~8 ~8 stone 0  
fill ~2 ~8 ~9 ~129 ~8 ~9 stone 0  
fill ~2 ~8 ~10 ~129 ~8 ~10 stone 0  
fill ~2 ~8 ~11 ~129 ~8 ~11 stone 0  
fill ~2 ~8 ~12 ~129 ~8 ~12 stone 0  
fill ~2 ~8 ~13 ~129 ~8 ~13 stone 0  
fill ~2 ~8 ~14 ~129 ~8 ~14 stone 0  
fill ~2 ~8 ~15 ~129 ~8 ~15 stone 0  
fill ~2 ~8 ~16 ~129 ~8 ~16 stone 0  
fill ~2 ~8 ~17 ~129 ~8 ~17 stone 0  
fill ~2 ~8 ~18 ~129 ~8 ~18 stone 0  
fill ~2 ~8 ~19 ~129 ~8 ~19 stone 0  
fill ~2 ~8 ~20 ~129 ~8 ~20 stone 0  
fill ~2 ~8 ~21 ~89 ~8 ~21 stone 0  
fill ~2 ~8 ~22 ~78 ~8 ~22 stone 0  
fill ~2 ~8 ~23 ~78 ~8 ~23 stone 0  
fill ~2 ~8 ~24 ~78 ~8 ~24 stone 0  
fill ~2 ~8 ~25 ~78 ~8 ~25 stone 0  
fill ~2 ~8 ~26 ~78 ~8 ~26 stone 0  
fill ~2 ~8 ~27 ~76 ~8 ~27 stone 0  
fill ~2 ~8 ~28 ~75 ~8 ~28 stone 0  
fill ~2 ~8 ~29 ~74 ~8 ~29 stone 0  
fill ~2 ~8 ~30 ~75 ~8 ~30 stone 0  
fill ~2 ~8 ~31 ~75 ~8 ~31 stone 0  
fill ~2 ~8 ~32 ~74 ~8 ~32 stone 0  
fill ~2 ~8 ~33 ~74 ~8 ~33 stone 0  
fill ~2 ~8 ~34 ~73 ~8 ~34 stone 0  
fill ~2 ~8 ~35 ~72 ~8 ~35 stone 0  
fill ~2 ~8 ~36 ~73 ~8 ~36 stone 0  
fill ~2 ~8 ~37 ~73 ~8 ~37 stone 0  
fill ~2 ~8 ~38 ~73 ~8 ~38 stone 0  
fill ~2 ~8 ~39 ~72 ~8 ~39 stone 0  
fill ~2 ~8 ~40 ~72 ~8 ~40 stone 0  
fill ~2 ~8 ~41 ~71 ~8 ~41 stone 0  
fill ~2 ~8 ~42 ~71 ~8 ~42 stone 0  
fill ~2 ~8 ~43 ~71 ~8 ~43 stone 0  
fill ~2 ~8 ~44 ~62 ~8 ~44 stone 0  
fill ~2 ~8 ~45 ~67 ~8 ~45 stone 0  
fill ~2 ~8 ~46 ~66 ~8 ~46 stone 0  
fill ~2 ~8 ~47 ~66 ~8 ~47 stone 0  
fill ~2 ~8 ~48 ~63 ~8 ~48 stone 0  
fill ~2 ~8 ~49 ~60 ~8 ~49 stone 0  
fill ~2 ~8 ~50 ~59 ~8 ~50 stone 0  
fill ~2 ~8 ~51 ~49 ~8 ~51 stone 0  
fill ~2 ~8 ~52 ~50 ~8 ~52 stone 0  
fill ~2 ~8 ~53 ~52 ~8 ~53 stone 0  
fill ~2 ~8 ~54 ~51 ~8 ~54 stone 0  
fill ~2 ~8 ~55 ~43 ~8 ~55 stone 0  
fill ~2 ~8 ~56 ~47 ~8 ~56 stone 0  
fill ~2 ~8 ~57 ~42 ~8 ~57 stone 0  
fill ~2 ~8 ~58 ~42 ~8 ~58 stone 0  
fill ~2 ~8 ~59 ~43 ~8 ~59 stone 0  
fill ~2 ~8 ~60 ~42 ~8 ~60 stone 0  
fill ~2 ~8 ~61 ~42 ~8 ~61 stone 0  
fill ~2 ~8 ~62 ~41 ~8 ~62 stone 0  
fill ~2 ~8 ~63 ~51 ~8 ~63 stone 0  
fill ~2 ~8 ~64 ~57 ~8 ~64 stone 0  
fill ~2 ~8 ~65 ~43 ~8 ~65 stone 0  
fill ~2 ~8 ~66 ~57 ~8 ~66 stone 0  
fill ~2 ~8 ~67 ~50 ~8 ~67 stone 0  
fill ~2 ~8 ~68 ~51 ~8 ~68 stone 0  
fill ~2 ~8 ~69 ~55 ~8 ~69 stone 0  
fill ~2 ~8 ~70 ~55 ~8 ~70 stone 0  
fill ~2 ~8 ~71 ~55 ~8 ~71 stone 0  
fill ~2 ~8 ~72 ~54 ~8 ~72 stone 0  
fill ~2 ~8 ~73 ~56 ~8 ~73 stone 0  
fill ~2 ~8 ~74 ~53 ~8 ~74 stone 0  
fill ~2 ~8 ~75 ~55 ~8 ~75 stone 0  
fill ~2 ~8 ~76 ~60 ~8 ~76 stone 0  
fill ~2 ~8 ~77 ~56 ~8 ~77 stone 0  
fill ~2 ~8 ~78 ~58 ~8 ~78 stone 0  
fill ~2 ~8 ~79 ~53 ~8 ~79 stone 0  
fill ~2 ~8 ~80 ~53 ~8 ~80 stone 0  
fill ~2 ~8 ~81 ~55 ~8 ~81 stone 0  
fill ~2 ~8 ~82 ~56 ~8 ~82 stone 0  
fill ~2 ~8 ~83 ~54 ~8 ~83 stone 0  
fill ~2 ~8 ~84 ~56 ~8 ~84 stone 0  
fill ~2 ~8 ~85 ~62 ~8 ~85 stone 0  
fill ~2 ~8 ~86 ~51 ~8 ~86 stone 0  
fill ~2 ~8 ~87 ~54 ~8 ~87 stone 0  
fill ~2 ~8 ~88 ~54 ~8 ~88 stone 0  
fill ~2 ~8 ~89 ~60 ~8 ~89 stone 0  
fill ~2 ~8 ~90 ~58 ~8 ~90 stone 0  
fill ~2 ~8 ~91 ~52 ~8 ~91 stone 0  
fill ~2 ~8 ~92 ~51 ~8 ~92 stone 0  
fill ~2 ~8 ~93 ~63 ~8 ~93 stone 0  
fill ~2 ~8 ~94 ~54 ~8 ~94 stone 0  
fill ~2 ~8 ~95 ~68 ~8 ~95 stone 0  
fill ~2 ~8 ~96 ~60 ~8 ~96 stone 0  
fill ~2 ~8 ~97 ~129 ~8 ~97 stone 0  
fill ~2 ~8 ~98 ~129 ~8 ~98 stone 0  
fill ~2 ~8 ~99 ~129 ~8 ~99 stone 0  
fill ~2 ~8 ~100 ~129 ~8 ~100 stone 0  
fill ~2 ~8 ~101 ~129 ~8 ~101 stone 0  
fill ~2 ~8 ~102 ~129 ~8 ~102 stone 0  
fill ~2 ~8 ~103 ~129 ~8 ~103 stone 0  
fill ~2 ~8 ~104 ~129 ~8 ~104 stone 0  
fill ~2 ~8 ~105 ~129 ~8 ~105 stone 0  
fill ~2 ~8 ~106 ~129 ~8 ~106 stone 0  
fill ~2 ~8 ~107 ~129 ~8 ~107 stone 0  
fill ~2 ~8 ~108 ~129 ~8 ~108 stone 0  
fill ~2 ~8 ~109 ~129 ~8 ~109 stone 0  
fill ~2 ~8 ~110 ~129 ~8 ~110 stone 0  
fill ~2 ~8 ~111 ~129 ~8 ~111 stone 0  
fill ~2 ~8 ~112 ~129 ~8 ~112 stone 0  
fill ~2 ~8 ~113 ~129 ~8 ~113 stone 0  
fill ~2 ~8 ~114 ~129 ~8 ~114 stone 0  
fill ~2 ~8 ~115 ~129 ~8 ~115 stone 0  
fill ~2 ~8 ~116 ~129 ~8 ~116 stone 0  
fill ~2 ~8 ~117 ~129 ~8 ~117 stone 0  
fill ~2 ~8 ~118 ~129 ~8 ~118 stone 0  
fill ~2 ~8 ~119 ~129 ~8 ~119 stone 0  
fill ~2 ~8 ~120 ~129 ~8 ~120 stone 0  
fill ~2 ~8 ~121 ~129 ~8 ~121 stone 0  
fill ~2 ~8 ~122 ~129 ~8 ~122 stone 0  
fill ~2 ~8 ~123 ~129 ~8 ~123 stone 0  
fill ~2 ~8 ~124 ~129 ~8 ~124 stone 0  
fill ~2 ~8 ~125 ~129 ~8 ~125 stone 0  
fill ~2 ~8 ~126 ~129 ~8 ~126 stone 0  
fill ~2 ~8 ~127 ~129 ~8 ~127 stone 0  
fill ~2 ~8 ~128 ~129 ~8 ~128 stone 0  
fill ~2 ~8 ~129 ~129 ~8 ~129 stone 0 
setblock ~42 ~8 ~62 stained_hardened_clay 5 
setblock ~43 ~8 ~57 stained_hardened_clay 5 
setblock ~43 ~8 ~58 dirt 0 
setblock ~43 ~8 ~60 dirt 0 
setblock ~43 ~8 ~61 stained_hardened_clay 5  
fill ~43 ~8 ~62 ~44 ~8 ~62 stone 0 
setblock ~44 ~8 ~55 stained_hardened_clay 5  
fill ~44 ~8 ~57 ~45 ~8 ~57 stone 0  
fill ~44 ~8 ~58 ~44 ~9 ~58 stained_hardened_clay 5 
setblock ~44 ~8 ~59 dirt 0 
setblock ~44 ~8 ~60 stained_hardened_clay 5  
fill ~44 ~8 ~61 ~46 ~8 ~61 stone 0 
setblock ~44 ~8 ~65 stained_hardened_clay 5  
fill ~45 ~8 ~55 ~46 ~8 ~55 dirt 0 
setblock ~45 ~8 ~58 dirt 0  
fill ~45 ~8 ~59 ~45 ~8 ~61 stone 0 
setblock ~45 ~8 ~62 dirt 0  
fill ~45 ~8 ~65 ~48 ~8 ~65 stone 0  
fill ~46 ~8 ~57 ~46 ~9 ~57 dirt 0 
setblock ~46 ~8 ~58 stone 0  
fill ~46 ~8 ~59 ~46 ~9 ~59 stained_hardened_clay 5  
fill ~46 ~8 ~60 ~51 ~8 ~60 stone 0  
fill ~46 ~8 ~62 ~49 ~8 ~62 stone 0  
fill ~47 ~8 ~55 ~49 ~8 ~55 stone 0 
setblock ~47 ~8 ~57 stone 0 
setblock ~47 ~8 ~58 dirt 0  
fill ~47 ~8 ~59 ~48 ~8 ~59 stone 0  
fill ~47 ~8 ~61 ~47 ~9 ~61 dirt 0  
fill ~48 ~8 ~56 ~48 ~8 ~57 stained_hardened_clay 5  
fill ~48 ~8 ~58 ~51 ~8 ~58 stone 0  
fill ~48 ~8 ~61 ~50 ~8 ~61 stone 0   
fill ~49 ~8 ~56 ~50 ~8 ~56 dirt 1  
fill ~49 ~8 ~57 ~50 ~8 ~57 stone 0 
setblock ~49 ~8 ~59 dirt 0 
setblock ~49 ~8 ~65 planks 1 
setblock ~50 ~8 ~51 dirt 1  
fill ~50 ~8 ~55 ~53 ~8 ~55 planks 1  
fill ~50 ~8 ~59 ~53 ~8 ~59 dirt 1  
fill ~50 ~8 ~62 ~50 ~9 ~62 dirt 1  
fill ~50 ~8 ~65 ~56 ~8 ~65 stone 0  
fill ~51 ~8 ~51 ~52 ~8 ~51 stone 0  
fill ~51 ~8 ~52 ~51 ~10 ~52 planks 1  
fill ~51 ~8 ~56 ~52 ~8 ~56 planks 1  
fill ~51 ~8 ~57 ~51 ~9 ~57 dirt 1  
fill ~51 ~8 ~61 ~51 ~8 ~62 planks 1 
setblock ~51 ~8 ~67 dirt 1 
setblock ~52 ~8 ~52 stone 0 
setblock ~52 ~8 ~54 planks 1  
fill ~52 ~8 ~58 ~52 ~9 ~58 dirt 1  
fill ~52 ~8 ~60 ~52 ~9 ~60 planks 1  
fill ~52 ~8 ~61 ~53 ~8 ~61 stone 0  
fill ~52 ~8 ~62 ~52 ~8 ~61 stone 0  
fill ~52 ~8 ~63 ~52 ~9 ~63 dirt 1  
fill ~52 ~8 ~67 ~54 ~8 ~67 stone 0 
setblock ~52 ~8 ~68 dirt 1 
setblock ~52 ~8 ~86 planks 3  
fill ~52 ~8 ~92 ~52 ~10 ~92 stone 2  
fill ~53 ~8 ~51 ~53 ~12 ~51 planks 1  
fill ~53 ~8 ~52 ~53 ~8 ~54 dirt 1 
setblock ~53 ~8 ~56 dirt 1  
fill ~53 ~8 ~57 ~53 ~12 ~57 planks 1 
setblock ~53 ~8 ~58 stone 0 
setblock ~53 ~8 ~60 dirt 1 
setblock ~53 ~8 ~62 planks 1 
setblock ~53 ~8 ~63 stone 0  
fill ~53 ~8 ~68 ~57 ~8 ~68 stone 0  
fill ~53 ~8 ~86 ~63 ~8 ~86 stone 0  
fill ~53 ~8 ~91 ~53 ~9 ~91 planks 3 
setblock ~53 ~8 ~92 stone 0  
fill ~54 ~8 ~51 ~56 ~8 ~51 stone 0  
fill ~54 ~8 ~52 ~55 ~8 ~52 stone 0  
fill ~54 ~8 ~53 ~54 ~9 ~53 planks 1  
fill ~54 ~8 ~54 ~54 ~0 ~54 stone 0 
setblock ~54 ~8 ~55 dirt 1  
fill ~54 ~8 ~56 ~54 ~9 ~56 planks 1 
setblock ~54 ~8 ~57 stone 0  
fill ~54 ~8 ~59 ~57 ~8 ~59 stone 0  
fill ~54 ~8 ~60 ~54 ~10 ~60 planks 1  
fill ~54 ~8 ~61 ~55 ~8 ~61 planks 1  
fill ~54 ~8 ~62 ~55 ~8 ~62 stone 0 
setblock ~54 ~8 ~63 dirt 1  
fill ~54 ~8 ~74 ~55 ~8 ~74 stained_hardened_clay 5 
setblock ~54 ~8 ~79 stained_hardened_clay 5  
fill ~54 ~8 ~80 ~54 ~9 ~80 dirt 0 
setblock ~54 ~8 ~91 stone 0 
setblock ~54 ~8 ~92 planks 3  
fill ~55 ~8 ~53 ~57 ~8 ~53 stone 0 
setblock ~55 ~8 ~54 stone 2 
setblock ~55 ~8 ~55 planks 1 
setblock ~55 ~8 ~56 stone 0 
setblock ~55 ~8 ~57 planks 1  
fill ~55 ~8 ~58 ~55 ~11 ~58 dirt 1 
setblock ~55 ~8 ~60 dirt 1 
setblock ~55 ~8 ~63 planks 1  
fill ~55 ~8 ~67 ~55 ~9 ~67 stained_hardened_clay 5 
setblock ~55 ~8 ~72 dirt 0  
fill ~55 ~8 ~79 ~55 ~8 ~82 stone 0 
setblock ~55 ~8 ~83 stained_hardened_clay 5  
fill ~55 ~8 ~87 ~55 ~8 ~88 planks 3 
setblock ~55 ~8 ~91 planks 3  
fill ~55 ~8 ~92 ~61 ~8 ~92 stone 0 
setblock ~55 ~8 ~94 stone 2 
setblock ~56 ~8 ~52 stone 2 
setblock ~56 ~8 ~54 planks 1  
fill ~56 ~8 ~55 ~56 ~10 ~55 stone 2  
fill ~56 ~8 ~56 ~58 ~8 ~56 stone 2  
fill ~56 ~8 ~57 ~58 ~8 ~57 stone 2  
fill ~56 ~8 ~58 ~57 ~8 ~58 planks 3 
setblock ~56 ~8 ~60 stone 0 
setblock ~56 ~8 ~61 dirt 0 
setblock ~56 ~8 ~62 stained_hardened_clay 5  
fill ~56 ~8 ~63 ~57 ~8 ~63 stone 0  
fill ~56 ~8 ~67 ~56 ~9 ~67 stone 0 
setblock ~56 ~8 ~69 stained_hardened_clay 5 
setblock ~56 ~8 ~70 dirt 0 
setblock ~56 ~8 ~71 stained_hardened_clay 5 
setblock ~56 ~8 ~72 stone 0  
fill ~56 ~8 ~74 ~60 ~8 ~74 stone 0 
setblock ~56 ~8 ~75 stained_hardened_clay 5  
fill ~56 ~8 ~79 ~56 ~10 ~79 stained_hardened_clay 5 
setblock ~56 ~8 ~80 stone 0 
setblock ~56 ~8 ~81 dirt 0  
fill ~56 ~8 ~83 ~58 ~8 ~83 stone 0  
fill ~56 ~8 ~87 ~57 ~8 ~87 stone 0  
fill ~56 ~8 ~88 ~58 ~8 ~88 stone 0  
fill ~56 ~8 ~91 ~61 ~8 ~91 stone 0  
fill ~56 ~8 ~94 ~66 ~8 ~94 stone 0 
setblock ~57 ~8 ~51 stone 2 
setblock ~57 ~8 ~52 stone 0  
fill ~57 ~8 ~54 ~58 ~8 ~54 stone 0 
setblock ~57 ~8 ~55 planks 3  
fill ~57 ~8 ~60 ~58 ~8 ~60 stained_hardened_clay 5  
fill ~57 ~8 ~61 ~57 ~8 ~60 stained_hardened_clay 5  
fill ~57 ~8 ~62 ~58 ~8 ~62 stone 0 
setblock ~57 ~8 ~65 dirt 0  
fill ~57 ~8 ~67 ~57 ~10 ~67 dirt 0  
fill ~57 ~8 ~69 ~57 ~9 ~69 stone 0  
fill ~57 ~8 ~70 ~59 ~8 ~70 stained_hardened_clay 5  
fill ~57 ~8 ~71 ~58 ~8 ~71 dirt 0  
fill ~57 ~8 ~72 ~57 ~12 ~72 stained_hardened_clay 5  
fill ~57 ~8 ~73 ~57 ~12 ~73 dirt 0  
fill ~57 ~8 ~75 ~57 ~10 ~75 dirt 0  
fill ~57 ~8 ~77 ~57 ~9 ~77 stained_hardened_clay 5 
setblock ~57 ~8 ~79 stone 0  
fill ~57 ~8 ~80 ~59 ~8 ~80 dirt 0  
fill ~57 ~8 ~81 ~58 ~8 ~81 stone 0 
setblock ~57 ~8 ~82 stained_hardened_clay 5  
fill ~57 ~8 ~84 ~57 ~9 ~84 stained_hardened_clay 5 
setblock ~58 ~8 ~51 stone 0 
setblock ~58 ~8 ~52 stone 2  
fill ~58 ~8 ~53 ~60 ~8 ~53 planks 3  
fill ~58 ~8 ~58 ~58 ~7 ~58 stone 2 
setblock ~58 ~8 ~59 planks 3  
fill ~58 ~8 ~61 ~58 ~9 ~61 dirt 0 
setblock ~58 ~8 ~63 stained_hardened_clay 5  
fill ~58 ~8 ~64 ~58 ~10 ~64 dirt 0  
fill ~58 ~8 ~66 ~58 ~8 ~67 stained_hardened_clay 5  
fill ~58 ~8 ~68 ~58 ~8 ~69 dirt 0 
setblock ~58 ~8 ~72 dirt 0 
setblock ~58 ~8 ~73 stone 0  
fill ~58 ~8 ~75 ~58 ~11 ~75 stained_hardened_clay 5 
