fill ~2~0~1 ~14~0~0 minecraft:grass
fill ~15~0~1 ~17~0~0 minecraft:dirt 0
fill ~15~1~1 ~17~3~0 minecraft:stonebrick 0
fill ~18~0~1 ~31~0~0 minecraft:grass
fill ~2~0~1 ~13~0~1 minecraft:grass
setblock ~11~2~1 minecraft:glowstone
fill ~11~3~1 ~14~3~1 minecraft:stonebrick 0
setblock ~11~4~1 minecraft:glowstone
setblock ~12~2~1 minecraft:stonebrick 0
setblock ~12~4~1 minecraft:stonebrick 0
setblock ~13~2~1 minecraft:glowstone
setblock ~13~4~1 minecraft:glowstone
fill ~14~0~1 ~14~0~2 minecraft:dirt 0
fill ~14~1~1 ~14~2~2 minecraft:stonebrick 0
fill ~14~4~1 ~18~4~2 minecraft:stonebrick 0
fill ~15~0~1 ~17~0~6 minecraft:double_stone_block_slab 0
fill ~15~5~1 ~17~5~2 minecraft:stonebrick 0
fill ~18~0~1 ~18~0~2 minecraft:dirt 0
fill ~18~1~1 ~18~3~2 minecraft:stonebrick 0
fill ~19~0~1 ~31~0~1 minecraft:grass
setblock ~19~2~1 minecraft:glowstone
fill ~19~3~1 ~21~3~1 minecraft:stonebrick 0
setblock ~19~4~1 minecraft:glowstone
setblock ~20~2~1 minecraft:stonebrick 0
setblock ~20~4~1 minecraft:stonebrick 0
setblock ~21~2~1 minecraft:glowstone
setblock ~21~4~1 minecraft:glowstone
fill ~1~0~2 ~9~0~2 minecraft:grass
fill ~10~0~2 ~13~0~2 minecraft:dirt 0
fill ~10~1~2 ~13~1~2 minecraft:stonebrick 0
fill ~10~2~2 ~10~6~2 minecraft:stonebrick 0
setblock ~10~7~2 minecraft:leaves 0
setblock ~11~2~2 minecraft:stone_brick_stairs 1
setblock ~11~4~2 minecraft:stone_brick_stairs 5
fill ~11~5~2 ~14~5~2 minecraft:stonebrick 0
fill ~11~6~2 ~12~6~2 minecraft:leaves 0
setblock ~13~2~2 minecraft:stone_brick_stairs 0
setblock ~13~4~2 minecraft:stone_brick_stairs 4
fill ~13~6~2 ~14~6~2 minecraft:stonebrick 0
fill ~13~7~2 ~14~7~2 minecraft:leaves 0
setblock ~14~3~2 minecraft:stonebrick 0
setblock ~15~3~2 minecraft:stone_brick_stairs 5
fill ~15~6~2 ~16~6~2 minecraft:leaves 0
setblock ~17~3~2 minecraft:stone_brick_stairs 4
setblock ~17~6~2 minecraft:leaves 0
fill ~18~5~2 ~22~5~2 minecraft:stonebrick 0
fill ~18~6~2 ~19~6~2 minecraft:stonebrick 0
fill ~18~7~2 ~19~7~2 minecraft:leaves 0
fill ~19~0~2 ~22~0~2 minecraft:dirt 0
fill ~19~1~2 ~22~1~2 minecraft:stonebrick 0
setblock ~19~2~2 minecraft:stone_brick_stairs 1
setblock ~19~4~2 minecraft:stone_brick_stairs 5
fill ~20~6~2 ~21~6~2 minecraft:leaves 0
setblock ~21~2~2 minecraft:stone_brick_stairs 0
setblock ~21~4~2 minecraft:stone_brick_stairs 4
fill ~22~2~2 ~22~4~2 minecraft:stonebrick 0
setblock ~22~6~2 minecraft:stonebrick 0
setblock ~22~7~2 minecraft:leaves 0
fill ~23~0~2 ~31~0~2 minecraft:grass
fill ~1~0~3 ~8~0~3 minecraft:grass
fill ~8~2~3 ~9~4~3 minecraft:stonebrick 0
setblock ~9~0~3 minecraft:dirt 0
setblock ~9~1~3 minecraft:stonebrick 0
setblock ~9~5~3 minecraft:stonebrick 0
setblock ~9~6~3 minecraft:leaves 0
fill ~10~0~3 ~14~0~5 minecraft:double_stone_block_slab 0
fill ~10~1~3 ~10~5~3 minecraft:log 0
setblock ~10~6~3 minecraft:log 0
fill ~18~0~3 ~22~0~5 minecraft:double_stone_block_slab 0
fill ~22~1~3 ~22~5~3 minecraft:log 0
setblock ~22~6~3 minecraft:log 0
setblock ~23~0~3 minecraft:dirt 0
fill ~23~1~3 ~23~5~3 minecraft:stonebrick 0
setblock ~23~6~3 minecraft:leaves 0
fill ~24~0~3 ~31~0~3 minecraft:grass
fill ~24~2~3 ~24~4~3 minecraft:stonebrick 0
fill ~1~0~4 ~7~0~4 minecraft:grass
setblock ~7~2~4 minecraft:stonebrick 0
setblock ~7~3~4 minecraft:glowstone
setblock ~7~4~4 minecraft:stonebrick 0
setblock ~8~0~4 minecraft:dirt 0
setblock ~8~1~4 minecraft:stonebrick 0
setblock ~8~2~4 minecraft:stone_block_slab 13
setblock ~8~4~4 minecraft:stone_block_slab 5
fill ~8~5~4 ~8~6~4 minecraft:stonebrick 0
setblock ~8~7~4 minecraft:leaves 0
fill ~9~0~4 ~9~0~7 minecraft:double_stone_block_slab 0
fill ~23~0~4 ~23~0~7 minecraft:double_stone_block_slab 0
setblock ~24~0~4 minecraft:dirt 0
setblock ~24~1~4 minecraft:stonebrick 0
setblock ~24~2~4 minecraft:stone_block_slab 13
setblock ~24~4~4 minecraft:stone_block_slab 5
fill ~24~5~4 ~24~6~4 minecraft:stonebrick 0
setblock ~24~7~4 minecraft:leaves 0
fill ~25~0~4 ~31~0~4 minecraft:grass
setblock ~25~2~4 minecraft:stonebrick 0
setblock ~25~3~4 minecraft:glowstone
setblock ~25~4~4 minecraft:stonebrick 0
fill ~1~0~5 ~6~0~5 minecraft:grass
setblock ~6~2~5 minecraft:stonebrick 0
setblock ~6~3~5 minecraft:glowstone
setblock ~6~4~5 minecraft:stonebrick 0
setblock ~7~0~5 minecraft:dirt 0
setblock ~7~1~5 minecraft:stonebrick 0
setblock ~7~2~5 minecraft:stone_block_slab 13
setblock ~7~4~5 minecraft:stone_block_slab 5
setblock ~7~5~5 minecraft:stonebrick 0
setblock ~7~6~5 minecraft:leaves 0
fill ~8~0~5 ~8~0~8 minecraft:double_stone_block_slab 0
setblock ~14~4~5 minecraft:trapdoor 3
setblock ~18~4~5 minecraft:trapdoor 3
fill ~24~0~5 ~24~0~8 minecraft:double_stone_block_slab 0
setblock ~25~0~5 minecraft:dirt 0
setblock ~25~1~5 minecraft:stonebrick 0
setblock ~25~2~5 minecraft:stone_block_slab 13
setblock ~25~4~5 minecraft:stone_block_slab 5
setblock ~25~5~5 minecraft:stonebrick 0
setblock ~25~6~5 minecraft:leaves 0
fill ~26~0~5 ~31~0~5 minecraft:grass
setblock ~26~2~5 minecraft:stonebrick 0
setblock ~26~3~5 minecraft:glowstone
setblock ~26~4~5 minecraft:stonebrick 0
fill ~1~0~6 ~5~0~6 minecraft:grass
setblock ~5~2~6 minecraft:stonebrick 0
setblock ~5~3~6 minecraft:glowstone
setblock ~5~4~6 minecraft:stonebrick 0
setblock ~6~0~6 minecraft:dirt 0
setblock ~6~1~6 minecraft:stonebrick 0
setblock ~6~2~6 minecraft:stone_block_slab 13
setblock ~6~4~6 minecraft:stone_block_slab 5
setblock ~6~5~6 minecraft:stonebrick 0
setblock ~6~6~6 minecraft:leaves 0
fill ~7~0~6 ~7~0~10 minecraft:double_stone_block_slab 0
fill ~10~0~6 ~11~0~6 minecraft:double_stone_block_slab 0
fill ~12~0~6 ~14~0~7 minecraft:dirt 0
fill ~12~1~6 ~14~1~6 minecraft:stonebrick 0
setblock ~13~4~6 minecraft:trapdoor 1
fill ~14~2~6 ~14~3~6 minecraft:nether_brick_fence
setblock ~14~4~6 minecraft:glowstone
setblock ~14~5~6 minecraft:stone_block_slab 0
setblock ~15~4~6 minecraft:trapdoor 0
setblock ~17~4~6 minecraft:trapdoor 1
fill ~18~0~6 ~20~0~8 minecraft:dirt 0
fill ~18~1~6 ~20~1~6 minecraft:stonebrick 0
fill ~18~2~6 ~18~3~6 minecraft:nether_brick_fence
setblock ~18~4~6 minecraft:glowstone
setblock ~18~5~6 minecraft:stone_block_slab 0
setblock ~19~4~6 minecraft:trapdoor 0
fill ~21~0~6 ~22~0~6 minecraft:double_stone_block_slab 0
fill ~25~0~6 ~25~0~10 minecraft:double_stone_block_slab 0
setblock ~26~0~6 minecraft:dirt 0
setblock ~26~1~6 minecraft:stonebrick 0
setblock ~26~2~6 minecraft:stone_block_slab 13
setblock ~26~4~6 minecraft:stone_block_slab 5
setblock ~26~5~6 minecraft:stonebrick 0
setblock ~26~6~6 minecraft:leaves 0
fill ~27~0~6 ~31~0~6 minecraft:grass
setblock ~27~2~6 minecraft:stonebrick 0
setblock ~27~3~6 minecraft:glowstone
setblock ~27~4~6 minecraft:stonebrick 0
fill ~1~0~7 ~4~0~7 minecraft:grass
fill ~4~2~7 ~4~4~8 minecraft:stonebrick 0
setblock ~5~0~7 minecraft:dirt 0
setblock ~5~1~7 minecraft:stonebrick 0
setblock ~5~2~7 minecraft:stone_block_slab 13
setblock ~5~4~7 minecraft:stone_block_slab 5
fill ~5~5~7 ~5~6~7 minecraft:stonebrick 0
setblock ~5~7~7 minecraft:leaves 0
fill ~6~0~7 ~6~0~23 minecraft:double_stone_block_slab 0
fill ~10~0~7 ~11~0~7 minecraft:dirt 0
fill ~10~1~7 ~11~1~7 minecraft:stonebrick 0
fill ~12~1~7 ~13~1~7 minecraft:grass
setblock ~12~2~7 minecraft:red_flower 8
fill ~13~2~7 ~13~2~8 minecraft:red_flower 3
fill ~14~1~7 ~14~1~11 minecraft:stonebrick 0
setblock ~14~4~7 minecraft:trapdoor 2
fill ~15~0~7 ~15~0~13 minecraft:double_stone_block_slab 0
fill ~16~0~7 ~16~0~8 minecraft:redstone_lamp
fill ~17~0~7 ~17~0~13 minecraft:double_stone_block_slab 0
fill ~18~1~7 ~18~1~11 minecraft:stonebrick 0
setblock ~18~4~7 minecraft:trapdoor 2
fill ~19~1~7 ~20~1~7 minecraft:grass
setblock ~19~2~7 minecraft:red_flower 8
setblock ~20~2~7 minecraft:red_flower 3
fill ~21~0~7 ~22~0~7 minecraft:dirt 0
fill ~21~1~7 ~22~1~7 minecraft:stonebrick 0
fill ~26~0~7 ~26~0~23 minecraft:double_stone_block_slab 0
setblock ~27~0~7 minecraft:dirt 0
setblock ~27~1~7 minecraft:stonebrick 0
setblock ~27~2~7 minecraft:stone_block_slab 13
setblock ~27~4~7 minecraft:stone_block_slab 5
fill ~27~5~7 ~27~6~7 minecraft:stonebrick 0
setblock ~27~7~7 minecraft:leaves 0
fill ~28~0~7 ~31~0~7 minecraft:grass
fill ~28~2~7 ~28~4~8 minecraft:stonebrick 0
fill ~1~0~8 ~3~0~8 minecraft:grass
setblock ~4~0~8 minecraft:dirt 0
setblock ~4~1~8 minecraft:stonebrick 0
setblock ~4~5~8 minecraft:stonebrick 0
setblock ~4~6~8 minecraft:leaves 0
fill ~5~0~8 ~5~0~22 minecraft:double_stone_block_slab 0
setblock ~9~0~8 minecraft:dirt 0
setblock ~9~1~8 minecraft:stonebrick 0
fill ~10~0~8 ~12~0~10 minecraft:grass
fill ~10~1~8 ~12~1~10 minecraft:ice
fill ~13~0~8 ~14~0~11 minecraft:dirt 0
fill ~13~1~8 ~13~1~11 minecraft:grass
fill ~19~1~8 ~19~1~11 minecraft:grass
setblock ~19~2~8 minecraft:red_flower 3
fill ~20~1~8 ~22~1~10 minecraft:ice
fill ~21~0~8 ~22~0~11 minecraft:grass
setblock ~23~0~8 minecraft:dirt 0
setblock ~23~1~8 minecraft:stonebrick 0
fill ~27~0~8 ~27~0~22 minecraft:double_stone_block_slab 0
setblock ~28~0~8 minecraft:dirt 0
setblock ~28~1~8 minecraft:stonebrick 0
setblock ~28~5~8 minecraft:stonebrick 0
setblock ~28~6~8 minecraft:leaves 0
fill ~29~0~8 ~31~0~8 minecraft:grass
fill ~1~0~9 ~2~0~12 minecraft:grass
fill ~3~0~9 ~3~0~13 minecraft:dirt 0
fill ~3~1~9 ~3~1~13 minecraft:stonebrick 0
fill ~3~2~9 ~3~6~9 minecraft:stonebrick 0
setblock ~3~7~9 minecraft:leaves 0
fill ~4~0~9 ~4~0~21 minecraft:double_stone_block_slab 0
fill ~4~1~9 ~4~5~9 minecraft:log 0
setblock ~4~6~9 minecraft:log 0
fill ~8~0~9 ~8~0~13 minecraft:dirt 0
fill ~8~1~9 ~8~1~10 minecraft:stonebrick 0
fill ~9~0~9 ~9~0~11 minecraft:grass
fill ~9~1~9 ~9~1~11 minecraft:ice
setblock ~13~2~9 minecraft:leaves 0
fill ~14~2~9 ~14~2~11 minecraft:stonebrick 0
setblock ~16~0~9 minecraft:double_stone_block_slab 0
fill ~18~0~9 ~19~0~11 minecraft:dirt 0
fill ~18~2~9 ~18~2~11 minecraft:stonebrick 0
fill ~19~2~9 ~19~2~10 minecraft:leaves 0
fill ~20~0~9 ~20~0~10 minecraft:grass
fill ~23~0~9 ~23~0~11 minecraft:grass
fill ~23~1~9 ~23~1~11 minecraft:ice
fill ~24~0~9 ~24~0~13 minecraft:dirt 0
fill ~24~1~9 ~24~1~10 minecraft:stonebrick 0
fill ~28~0~9 ~28~0~21 minecraft:double_stone_block_slab 0
fill ~28~1~9 ~28~5~9 minecraft:log 0
setblock ~28~6~9 minecraft:log 0
fill ~29~0~9 ~29~0~13 minecraft:dirt 0
fill ~29~1~9 ~29~1~13 minecraft:stonebrick 0
fill ~29~2~9 ~29~6~9 minecraft:stonebrick 0
setblock ~29~7~9 minecraft:leaves 0
fill ~30~0~9 ~31~0~12 minecraft:grass
setblock ~2~2~10 minecraft:glowstone
fill ~2~3~10 ~2~3~13 minecraft:stonebrick 0
setblock ~2~4~10 minecraft:glowstone
setblock ~3~2~10 minecraft:stone_brick_stairs 3
setblock ~3~4~10 minecraft:stone_brick_stairs 7
fill ~3~5~10 ~3~5~21 minecraft:stonebrick 0
fill ~3~6~10 ~3~6~11 minecraft:leaves 0
fill ~13~2~10 ~13~2~11 minecraft:leaves 0
setblock ~14~4~10 minecraft:trapdoor 3
fill ~16~0~10 ~16~0~11 minecraft:redstone_lamp
setblock ~18~4~10 minecraft:trapdoor 3
setblock ~29~2~10 minecraft:stone_brick_stairs 3
setblock ~29~4~10 minecraft:stone_brick_stairs 7
fill ~29~5~10 ~29~5~21 minecraft:stonebrick 0
fill ~29~6~10 ~29~6~11 minecraft:leaves 0
setblock ~30~2~10 minecraft:glowstone
fill ~30~3~10 ~30~3~13 minecraft:stonebrick 0
setblock ~30~4~10 minecraft:glowstone
setblock ~2~2~11 minecraft:stonebrick 0
setblock ~2~4~11 minecraft:stonebrick 0
fill ~7~0~11 ~7~0~13 minecraft:dirt 0
fill ~7~1~11 ~7~1~13 minecraft:stonebrick 0
fill ~8~1~11 ~8~1~12 minecraft:grass
fill ~8~2~11 ~8~2~12 minecraft:red_flower 3
fill ~10~0~11 ~11~0~11 minecraft:grass
fill ~10~1~11 ~11~1~11 minecraft:ice
fill ~12~0~11 ~12~0~13 minecraft:dirt 0
fill ~12~1~11 ~12~1~12 minecraft:grass
fill ~12~2~11 ~12~2~12 minecraft:leaves 0
setblock ~13~3~11 minecraft:leaves 0
setblock ~13~4~11 minecraft:trapdoor 1
setblock ~14~3~11 minecraft:nether_brick_fence
setblock ~14~4~11 minecraft:glowstone
setblock ~14~5~11 minecraft:stone_block_slab 0
setblock ~15~4~11 minecraft:trapdoor 0
setblock ~17~4~11 minecraft:trapdoor 1
setblock ~18~3~11 minecraft:nether_brick_fence
setblock ~18~4~11 minecraft:glowstone
setblock ~18~5~11 minecraft:stone_block_slab 0
fill ~19~2~11 ~20~2~11 minecraft:leaves 0
setblock ~19~3~11 minecraft:leaves 0
setblock ~19~4~11 minecraft:trapdoor 0
fill ~20~0~11 ~20~0~13 minecraft:dirt 0
fill ~20~1~11 ~20~1~12 minecraft:grass
fill ~21~1~11 ~22~1~11 minecraft:ice
fill ~24~1~11 ~24~1~12 minecraft:grass
setblock ~24~2~11 minecraft:red_flower 8
fill ~25~0~11 ~25~0~13 minecraft:dirt 0
fill ~25~1~11 ~25~1~13 minecraft:stonebrick 0
setblock ~30~2~11 minecraft:stonebrick 0
setblock ~30~4~11 minecraft:stonebrick 0
setblock ~2~2~12 minecraft:glowstone
setblock ~2~4~12 minecraft:glowstone
setblock ~3~2~12 minecraft:stone_brick_stairs 2
setblock ~3~4~12 minecraft:stone_brick_stairs 6
fill ~3~6~12 ~3~6~13 minecraft:stonebrick 0
fill ~3~7~12 ~3~7~13 minecraft:leaves 0
setblock ~7~4~12 minecraft:trapdoor 3
fill ~9~0~12 ~11~0~13 minecraft:dirt 0
fill ~9~1~12 ~11~1~12 minecraft:grass
setblock ~9~2~12 minecraft:red_flower 8
fill ~10~2~12 ~11~2~12 minecraft:leaves 0
setblock ~12~3~12 minecraft:leaves 0
setblock ~12~4~12 minecraft:trapdoor 3
setblock ~13~0~12 minecraft:dirt 0
fill ~13~1~12 ~13~3~12 minecraft:stonebrick 0
fill ~14~0~12 ~14~0~18 minecraft:double_stone_block_slab 0
setblock ~14~1~12 minecraft:stone_block_slab 0
setblock ~14~3~12 minecraft:stonebrick 0
setblock ~14~4~12 minecraft:trapdoor 2
fill ~16~0~12 ~16~0~13 minecraft:double_stone_block_slab 0
fill ~18~0~12 ~18~0~18 minecraft:double_stone_block_slab 0
setblock ~18~1~12 minecraft:stone_block_slab 0
fill ~18~3~12 ~19~3~12 minecraft:stonebrick 0
setblock ~18~4~12 minecraft:trapdoor 2
setblock ~19~0~12 minecraft:dirt 0
fill ~19~1~12 ~19~2~12 minecraft:stonebrick 0
fill ~20~2~12 ~21~2~12 minecraft:leaves 0
setblock ~20~3~12 minecraft:leaves 0
setblock ~20~4~12 minecraft:trapdoor 3
fill ~21~0~12 ~23~0~13 minecraft:dirt 0
fill ~21~1~12 ~23~1~12 minecraft:grass
setblock ~22~2~12 minecraft:leaves 0
fill ~23~2~12 ~24~2~12 minecraft:red_flower 3
setblock ~25~4~12 minecraft:trapdoor 3
setblock ~29~2~12 minecraft:stone_brick_stairs 2
setblock ~29~4~12 minecraft:stone_brick_stairs 6
fill ~29~6~12 ~29~6~13 minecraft:stonebrick 0
fill ~29~7~12 ~29~7~13 minecraft:leaves 0
setblock ~30~2~12 minecraft:glowstone
setblock ~30~4~12 minecraft:glowstone
setblock ~1~0~13 minecraft:grass
setblock ~2~0~13 minecraft:dirt 0
fill ~2~1~13 ~2~2~13 minecraft:stonebrick 0
fill ~2~4~13 ~3~4~13 minecraft:stonebrick 0
fill ~3~2~13 ~3~3~13 minecraft:stonebrick 0
setblock ~6~4~13 minecraft:trapdoor 1
fill ~7~2~13 ~7~3~13 minecraft:nether_brick_fence
setblock ~7~4~13 minecraft:glowstone
setblock ~7~5~13 minecraft:stone_block_slab 0
fill ~8~1~13 ~12~1~13 minecraft:stonebrick 0
setblock ~8~4~13 minecraft:trapdoor 0
fill ~10~2~13 ~12~2~13 minecraft:stonebrick 0
setblock ~11~4~13 minecraft:trapdoor 1
setblock ~12~3~13 minecraft:nether_brick_fence
setblock ~12~4~13 minecraft:glowstone
setblock ~12~5~13 minecraft:stone_block_slab 0
fill ~13~0~13 ~13~0~17 minecraft:double_stone_block_slab 0
setblock ~13~1~13 minecraft:stone_block_slab 0
setblock ~13~3~13 minecraft:stonebrick 0
setblock ~13~4~13 minecraft:trapdoor 0
fill ~14~4~13 ~15~4~13 minecraft:stonebrick 0
fill ~14~5~13 ~15~5~13 minecraft:leaves 0
fill ~17~4~13 ~18~4~13 minecraft:stonebrick 0
fill ~17~5~13 ~18~5~13 minecraft:leaves 0
fill ~19~0~13 ~19~0~17 minecraft:double_stone_block_slab 0
setblock ~19~1~13 minecraft:stone_block_slab 0
setblock ~19~3~13 minecraft:stonebrick 0
setblock ~19~4~13 minecraft:trapdoor 1
fill ~20~1~13 ~24~1~13 minecraft:stonebrick 0
fill ~20~2~13 ~22~2~13 minecraft:stonebrick 0
setblock ~20~3~13 minecraft:nether_brick_fence
setblock ~20~4~13 minecraft:glowstone
setblock ~20~5~13 minecraft:stone_block_slab 0
setblock ~21~4~13 minecraft:trapdoor 0
setblock ~24~4~13 minecraft:trapdoor 1
fill ~25~2~13 ~25~3~13 minecraft:nether_brick_fence
setblock ~25~4~13 minecraft:glowstone
setblock ~25~5~13 minecraft:stone_block_slab 0
setblock ~26~4~13 minecraft:trapdoor 0
fill ~29~2~13 ~30~2~13 minecraft:stonebrick 0
fill ~29~3~13 ~29~4~13 minecraft:stonebrick 0
setblock ~30~0~13 minecraft:dirt 0
setblock ~30~1~13 minecraft:stonebrick 0
fill ~30~4~13 ~30~4~17 minecraft:stonebrick 0
setblock ~31~0~13 minecraft:grass
fill ~1~0~14 ~1~0~16 minecraft:dirt 0
fill ~1~1~14 ~1~4~16 minecraft:stonebrick 0
fill ~2~0~14 ~3~0~16 minecraft:double_stone_block_slab 0
fill ~2~5~14 ~2~5~16 minecraft:stonebrick 0
fill ~3~6~14 ~3~6~16 minecraft:leaves 0
fill ~7~0~14 ~11~0~14 minecraft:stone_block_slab 8
setblock ~7~4~14 minecraft:trapdoor 2
setblock ~12~0~14 minecraft:double_stone_block_slab 0
setblock ~12~4~14 minecraft:trapdoor 2
setblock ~14~4~14 minecraft:stonebrick 0
setblock ~14~5~14 minecraft:leaves 0
fill ~15~0~14 ~17~0~14 minecraft:stained_glass 14
fill ~15~5~14 ~17~5~14 minecraft:stonebrick 0
setblock ~15~6~14 minecraft:leaves 0
fill ~16~6~14 ~16~6~16 minecraft:stonebrick 0
fill ~16~7~14 ~16~7~16 minecraft:leaves 0
setblock ~17~6~14 minecraft:leaves 0
setblock ~18~4~14 minecraft:stonebrick 0
setblock ~18~5~14 minecraft:leaves 0
fill ~20~0~14 ~25~0~14 minecraft:double_stone_block_slab 0
setblock ~20~4~14 minecraft:trapdoor 2
setblock ~25~4~14 minecraft:trapdoor 2
fill ~29~0~14 ~30~0~16 minecraft:double_stone_block_slab 0
setblock ~29~3~14 minecraft:stone_brick_stairs 7
fill ~29~4~14 ~29~4~17 minecraft:stonebrick 0
fill ~29~6~14 ~29~6~16 minecraft:leaves 0
fill ~30~5~14 ~30~5~16 minecraft:stonebrick 0
fill ~31~0~14 ~31~0~16 minecraft:dirt 0
fill ~31~1~14 ~31~4~16 minecraft:stonebrick 0
fill ~7~0~15 ~7~0~16 minecraft:stone_block_slab 8
fill ~8~0~15 ~9~0~15 minecraft:redstone_lamp
fill ~10~0~15 ~10~0~16 minecraft:stone_block_slab 8
fill ~11~0~15 ~12~0~15 minecraft:redstone_lamp
fill ~15~0~15 ~15~0~16 minecraft:stained_glass 14
fill ~15~5~15 ~15~5~16 minecraft:stonebrick 0
setblock ~15~6~15 minecraft:stonebrick 0
setblock ~15~7~15 minecraft:leaves 0
setblock ~16~0~15 minecraft:redstone_lamp
setblock ~16~5~15 minecraft:beacon
fill ~17~0~15 ~17~0~16 minecraft:stained_glass 14
fill ~17~5~15 ~17~5~16 minecraft:stonebrick 0
setblock ~17~6~15 minecraft:stonebrick 0
setblock ~17~7~15 minecraft:leaves 0
fill ~20~0~15 ~21~0~15 minecraft:redstone_lamp
fill ~22~0~15 ~22~0~16 minecraft:double_stone_block_slab 0
fill ~23~0~15 ~24~0~15 minecraft:redstone_lamp
fill ~25~0~15 ~25~0~16 minecraft:double_stone_block_slab 0
setblock ~7~4~16 minecraft:trapdoor 3
fill ~8~0~16 ~9~0~16 minecraft:stone_block_slab 8
fill ~11~0~16 ~12~0~16 minecraft:stone_block_slab 8
setblock ~12~4~16 minecraft:trapdoor 3
fill ~14~4~16 ~14~4~17 minecraft:stonebrick 0
fill ~14~5~16 ~14~5~17 minecraft:leaves 0
setblock ~15~6~16 minecraft:leaves 0
setblock ~16~0~16 minecraft:stained_glass 14
setblock ~16~5~16 minecraft:stonebrick 0
setblock ~17~6~16 minecraft:leaves 0
fill ~18~4~16 ~18~4~17 minecraft:stonebrick 0
fill ~18~5~16 ~18~5~17 minecraft:leaves 0
fill ~20~0~16 ~21~0~16 minecraft:double_stone_block_slab 0
setblock ~20~4~16 minecraft:trapdoor 3
fill ~23~0~16 ~24~0~16 minecraft:double_stone_block_slab 0
setblock ~25~4~16 minecraft:trapdoor 3
setblock ~29~3~16 minecraft:stone_brick_stairs 6
fill ~1~0~17 ~1~0~30 minecraft:grass
fill ~2~0~17 ~3~0~17 minecraft:dirt 0
fill ~2~1~17 ~3~4~17 minecraft:stonebrick 0
fill ~3~6~17 ~3~6~18 minecraft:stonebrick 0
fill ~3~7~17 ~3~7~18 minecraft:leaves 0
setblock ~6~4~17 minecraft:trapdoor 1
fill ~7~0~17 ~12~0~18 minecraft:dirt 0
fill ~7~1~17 ~12~1~17 minecraft:stonebrick 0
fill ~7~2~17 ~7~3~17 minecraft:nether_brick_fence
setblock ~7~4~17 minecraft:glowstone
setblock ~7~5~17 minecraft:stone_block_slab 0
setblock ~8~4~17 minecraft:trapdoor 0
fill ~10~2~17 ~12~2~17 minecraft:stonebrick 0
setblock ~11~4~17 minecraft:trapdoor 1
setblock ~12~3~17 minecraft:nether_brick_fence
setblock ~12~4~17 minecraft:glowstone
setblock ~12~5~17 minecraft:stone_block_slab 0
setblock ~13~1~17 minecraft:stone_block_slab 0
fill ~13~3~17 ~13~3~18 minecraft:stonebrick 0
setblock ~13~4~17 minecraft:trapdoor 0
fill ~15~0~17 ~17~0~18 minecraft:double_stone_block_slab 0
setblock ~15~4~17 minecraft:stonebrick 0
setblock ~15~5~17 minecraft:leaves 0
setblock ~17~4~17 minecraft:stonebrick 0
setblock ~17~5~17 minecraft:leaves 0
setblock ~19~1~17 minecraft:stone_block_slab 0
fill ~19~3~17 ~19~3~18 minecraft:stonebrick 0
setblock ~19~4~17 minecraft:trapdoor 1
fill ~20~0~17 ~25~0~18 minecraft:dirt 0
fill ~20~1~17 ~25~1~17 minecraft:stonebrick 0
fill ~20~2~17 ~22~2~17 minecraft:stonebrick 0
setblock ~20~3~17 minecraft:nether_brick_fence
setblock ~20~4~17 minecraft:glowstone
setblock ~20~5~17 minecraft:stone_block_slab 0
setblock ~21~4~17 minecraft:trapdoor 0
setblock ~24~4~17 minecraft:trapdoor 1
fill ~25~2~17 ~25~3~17 minecraft:nether_brick_fence
setblock ~25~4~17 minecraft:glowstone
setblock ~25~5~17 minecraft:stone_block_slab 0
setblock ~26~4~17 minecraft:trapdoor 0
fill ~29~0~17 ~30~0~17 minecraft:dirt 0
fill ~29~1~17 ~30~3~17 minecraft:stonebrick 0
fill ~29~6~17 ~29~6~18 minecraft:stonebrick 0
fill ~29~7~17 ~29~7~18 minecraft:leaves 0
fill ~31~0~17 ~31~0~30 minecraft:grass
fill ~2~0~18 ~2~0~30 minecraft:grass
setblock ~2~2~18 minecraft:glowstone
fill ~2~3~18 ~2~3~20 minecraft:stonebrick 0
setblock ~2~4~18 minecraft:glowstone
fill ~3~0~18 ~3~0~21 minecraft:dirt 0
fill ~3~1~18 ~3~1~21 minecraft:stonebrick 0
setblock ~3~2~18 minecraft:stone_brick_stairs 3
setblock ~3~4~18 minecraft:stone_brick_stairs 7
fill ~7~1~18 ~7~1~19 minecraft:stonebrick 0
setblock ~7~4~18 minecraft:trapdoor 2
fill ~8~1~18 ~12~1~18 minecraft:grass
fill ~8~2~18 ~9~2~18 minecraft:red_flower 3
fill ~10~2~18 ~12~2~18 minecraft:leaves 0
setblock ~12~3~18 minecraft:leaves 0
setblock ~12~4~18 minecraft:trapdoor 2
fill ~13~0~18 ~13~0~24 minecraft:dirt 0
fill ~13~1~18 ~13~2~18 minecraft:stonebrick 0
setblock ~14~1~18 minecraft:stone_block_slab 0
setblock ~14~3~18 minecraft:stonebrick 0
setblock ~14~4~18 minecraft:trapdoor 3
setblock ~18~1~18 minecraft:stone_block_slab 0
setblock ~18~3~18 minecraft:stonebrick 0
setblock ~18~4~18 minecraft:trapdoor 3
fill ~19~0~18 ~19~0~24 minecraft:dirt 0
fill ~19~1~18 ~19~2~18 minecraft:stonebrick 0
fill ~20~1~18 ~24~1~18 minecraft:grass
fill ~20~2~18 ~22~2~18 minecraft:leaves 0
setblock ~20~3~18 minecraft:leaves 0
setblock ~20~4~18 minecraft:trapdoor 2
setblock ~23~2~18 minecraft:red_flower 8
fill ~24~2~18 ~24~2~19 minecraft:red_flower 3
fill ~25~1~18 ~25~1~19 minecraft:stonebrick 0
setblock ~25~4~18 minecraft:trapdoor 2
fill ~29~0~18 ~29~0~21 minecraft:dirt 0
fill ~29~1~18 ~29~1~21 minecraft:stonebrick 0
setblock ~29~2~18 minecraft:stone_brick_stairs 3
setblock ~29~4~18 minecraft:stone_brick_stairs 7
fill ~30~0~18 ~30~0~30 minecraft:grass
setblock ~30~2~18 minecraft:glowstone
fill ~30~3~18 ~30~3~20 minecraft:stonebrick 0
setblock ~30~4~18 minecraft:glowstone
setblock ~2~2~19 minecraft:stonebrick 0
setblock ~2~4~19 minecraft:stonebrick 0
fill ~3~6~19 ~3~6~20 minecraft:leaves 0
fill ~7~0~19 ~8~0~19 minecraft:dirt 0
setblock ~8~1~19 minecraft:grass
setblock ~8~2~19 minecraft:red_flower 8
fill ~9~0~19 ~11~0~19 minecraft:grass
fill ~9~1~19 ~11~1~21 minecraft:ice
setblock ~12~0~19 minecraft:dirt 0
fill ~12~1~19 ~13~1~19 minecraft:grass
fill ~12~2~19 ~13~2~19 minecraft:leaves 0
setblock ~13~3~19 minecraft:leaves 0
setblock ~13~4~19 minecraft:trapdoor 1
fill ~14~0~19 ~14~0~24 minecraft:dirt 0
fill ~14~1~19 ~14~1~24 minecraft:stonebrick 0
fill ~14~2~19 ~14~2~21 minecraft:stonebrick 0
setblock ~14~3~19 minecraft:nether_brick_fence
setblock ~14~4~19 minecraft:glowstone
setblock ~14~5~19 minecraft:stone_block_slab 0
fill ~15~0~19 ~15~0~29 minecraft:double_stone_block_slab 0
setblock ~15~4~19 minecraft:trapdoor 0
fill ~16~0~19 ~16~0~20 minecraft:redstone_lamp
fill ~17~0~19 ~17~0~29 minecraft:double_stone_block_slab 0
setblock ~17~4~19 minecraft:trapdoor 1
fill ~18~0~19 ~18~0~24 minecraft:dirt 0
fill ~18~1~19 ~18~1~24 minecraft:stonebrick 0
fill ~18~2~19 ~18~2~21 minecraft:stonebrick 0
setblock ~18~3~19 minecraft:nether_brick_fence
setblock ~18~4~19 minecraft:glowstone
setblock ~18~5~19 minecraft:stone_block_slab 0
fill ~19~1~19 ~20~1~19 minecraft:grass
fill ~19~2~19 ~19~2~21 minecraft:leaves 0
setblock ~19~3~19 minecraft:leaves 0
setblock ~19~4~19 minecraft:trapdoor 0
setblock ~20~0~19 minecraft:dirt 0
setblock ~20~2~19 minecraft:leaves 0
fill ~21~0~19 ~23~0~21 minecraft:grass
fill ~21~1~19 ~23~1~21 minecraft:ice
fill ~24~0~19 ~25~0~19 minecraft:dirt 0
setblock ~24~1~19 minecraft:grass
fill ~29~6~19 ~29~6~20 minecraft:leaves 0
setblock ~30~2~19 minecraft:stonebrick 0
setblock ~30~4~19 minecraft:stonebrick 0
setblock ~2~2~20 minecraft:glowstone
setblock ~2~4~20 minecraft:glowstone
setblock ~3~2~20 minecraft:stone_brick_stairs 2
setblock ~3~4~20 minecraft:stone_brick_stairs 6
fill ~7~0~20 ~7~0~24 minecraft:double_stone_block_slab 0
fill ~8~0~20 ~8~0~21 minecraft:dirt 0
fill ~8~1~20 ~8~1~21 minecraft:stonebrick 0
setblock ~9~0~20 minecraft:grass
fill ~10~0~20 ~11~0~20 minecraft:dirt 0
fill ~12~0~20 ~12~0~21 minecraft:grass
fill ~12~1~20 ~12~1~22 minecraft:ice
fill ~13~1~20 ~13~1~23 minecraft:grass
fill ~13~2~20 ~13~2~21 minecraft:leaves 0
setblock ~14~4~20 minecraft:trapdoor 2
setblock ~18~4~20 minecraft:trapdoor 2
fill ~19~1~20 ~19~1~23 minecraft:grass
fill ~20~0~20 ~20~0~22 minecraft:grass
fill ~20~1~20 ~20~1~22 minecraft:ice
fill ~24~0~20 ~24~0~21 minecraft:dirt 0
fill ~24~1~20 ~24~1~21 minecraft:stonebrick 0
fill ~25~0~20 ~25~0~24 minecraft:double_stone_block_slab 0
setblock ~29~2~20 minecraft:stone_brick_stairs 2
setblock ~29~4~20 minecraft:stone_brick_stairs 6
setblock ~30~2~20 minecraft:glowstone
setblock ~30~4~20 minecraft:glowstone
fill ~3~2~21 ~3~4~21 minecraft:stonebrick 0
setblock ~3~6~21 minecraft:stonebrick 0
setblock ~3~7~21 minecraft:leaves 0
fill ~4~1~21 ~4~5~21 minecraft:log 0
setblock ~4~6~21 minecraft:log 0
fill ~9~0~21 ~10~0~21 minecraft:dirt 0
fill ~11~0~21 ~11~0~22 minecraft:grass
setblock ~16~0~21 minecraft:double_stone_block_slab 0
fill ~28~1~21 ~28~5~21 minecraft:log 0
setblock ~28~6~21 minecraft:log 0
fill ~29~2~21 ~29~4~21 minecraft:stonebrick 0
setblock ~29~6~21 minecraft:stonebrick 0
setblock ~29~7~21 minecraft:leaves 0
fill ~3~0~22 ~3~0~30 minecraft:grass
setblock ~4~0~22 minecraft:dirt 0
fill ~4~1~22 ~4~5~22 minecraft:stonebrick 0
setblock ~4~6~22 minecraft:leaves 0
fill ~8~0~22 ~8~0~25 minecraft:double_stone_block_slab 0
setblock ~9~0~22 minecraft:dirt 0
setblock ~9~1~22 minecraft:stonebrick 0
setblock ~10~0~22 minecraft:grass
fill ~10~1~22 ~11~1~22 minecraft:ice
fill ~12~0~22 ~12~0~24 minecraft:dirt 0
setblock ~13~2~22 minecraft:red_flower 3
fill ~16~0~22 ~16~0~23 minecraft:redstone_lamp
setblock ~19~2~22 minecraft:red_flower 3
fill ~21~0~22 ~22~0~22 minecraft:grass
fill ~21~1~22 ~22~1~22 minecraft:ice
setblock ~23~0~22 minecraft:dirt 0
setblock ~23~1~22 minecraft:stonebrick 0
fill ~24~0~22 ~24~0~25 minecraft:double_stone_block_slab 0
setblock ~28~0~22 minecraft:dirt 0
fill ~28~1~22 ~28~5~22 minecraft:stonebrick 0
setblock ~28~6~22 minecraft:leaves 0
fill ~29~0~22 ~29~0~30 minecraft:grass
fill ~4~0~23 ~4~0~30 minecraft:grass
fill ~4~2~23 ~4~4~23 minecraft:stonebrick 0
setblock ~5~0~23 minecraft:dirt 0
setblock ~5~1~23 minecraft:stonebrick 0
setblock ~5~2~23 minecraft:stone_block_slab 13
setblock ~5~4~23 minecraft:stone_block_slab 5
fill ~5~5~23 ~5~6~23 minecraft:stonebrick 0
setblock ~5~7~23 minecraft:leaves 0
fill ~9~0~23 ~9~0~26 minecraft:double_stone_block_slab 0
fill ~10~0~23 ~11~0~23 minecraft:dirt 0
fill ~10~1~23 ~11~1~23 minecraft:stonebrick 0
setblock ~12~1~23 minecraft:grass
setblock ~12~2~23 minecraft:red_flower 3
setblock ~13~2~23 minecraft:red_flower 8
setblock ~14~4~23 minecraft:trapdoor 3
setblock ~18~4~23 minecraft:trapdoor 3
setblock ~19~2~23 minecraft:red_flower 8
fill ~20~0~23 ~22~0~23 minecraft:dirt 0
setblock ~20~1~23 minecraft:grass
setblock ~20~2~23 minecraft:red_flower 3
fill ~21~1~23 ~22~1~23 minecraft:stonebrick 0
fill ~23~0~23 ~23~0~26 minecraft:double_stone_block_slab 0
setblock ~27~0~23 minecraft:dirt 0
setblock ~27~1~23 minecraft:stonebrick 0
setblock ~27~2~23 minecraft:stone_block_slab 13
setblock ~27~4~23 minecraft:stone_block_slab 5
fill ~27~5~23 ~27~6~23 minecraft:stonebrick 0
setblock ~27~7~23 minecraft:leaves 0
fill ~28~0~23 ~28~0~30 minecraft:grass
fill ~28~2~23 ~28~4~23 minecraft:stonebrick 0
fill ~5~0~24 ~5~0~30 minecraft:grass
setblock ~5~2~24 minecraft:stonebrick 0
setblock ~5~3~24 minecraft:glowstone
setblock ~5~4~24 minecraft:stonebrick 0
setblock ~6~0~24 minecraft:dirt 0
setblock ~6~1~24 minecraft:stonebrick 0
setblock ~6~2~24 minecraft:stone_block_slab 13
setblock ~6~4~24 minecraft:stone_block_slab 5
setblock ~6~5~24 minecraft:stonebrick 0
setblock ~6~6~24 minecraft:leaves 0
fill ~10~0~24 ~11~0~27 minecraft:double_stone_block_slab 0
fill ~12~1~24 ~13~1~24 minecraft:stonebrick 0
setblock ~13~4~24 minecraft:trapdoor 1
fill ~14~2~24 ~14~3~24 minecraft:nether_brick_fence
setblock ~14~4~24 minecraft:glowstone
setblock ~14~5~24 minecraft:stone_block_slab 0
setblock ~15~4~24 minecraft:trapdoor 0
fill ~16~0~24 ~16~0~29 minecraft:double_stone_block_slab 0
setblock ~17~4~24 minecraft:trapdoor 1
fill ~18~2~24 ~18~3~24 minecraft:nether_brick_fence
setblock ~18~4~24 minecraft:glowstone
setblock ~18~5~24 minecraft:stone_block_slab 0
fill ~19~1~24 ~20~1~24 minecraft:stonebrick 0
setblock ~19~4~24 minecraft:trapdoor 0
setblock ~20~0~24 minecraft:dirt 0
fill ~21~0~24 ~22~0~27 minecraft:double_stone_block_slab 0
setblock ~26~0~24 minecraft:dirt 0
setblock ~26~1~24 minecraft:stonebrick 0
setblock ~26~2~24 minecraft:stone_block_slab 13
setblock ~26~4~24 minecraft:stone_block_slab 5
setblock ~26~5~24 minecraft:stonebrick 0
setblock ~26~6~24 minecraft:leaves 0
fill ~27~0~24 ~27~0~30 minecraft:grass
setblock ~27~2~24 minecraft:stonebrick 0
setblock ~27~3~24 minecraft:glowstone
setblock ~27~4~24 minecraft:stonebrick 0
fill ~6~0~25 ~6~0~30 minecraft:grass
setblock ~6~2~25 minecraft:stonebrick 0
setblock ~6~3~25 minecraft:glowstone
setblock ~6~4~25 minecraft:stonebrick 0
setblock ~7~0~25 minecraft:dirt 0
setblock ~7~1~25 minecraft:stonebrick 0
setblock ~7~2~25 minecraft:stone_block_slab 13
setblock ~7~4~25 minecraft:stone_block_slab 5
setblock ~7~5~25 minecraft:stonebrick 0
setblock ~7~6~25 minecraft:leaves 0
fill ~12~0~25 ~14~0~27 minecraft:double_stone_block_slab 0
setblock ~14~4~25 minecraft:trapdoor 2
fill ~18~0~25 ~20~0~27 minecraft:double_stone_block_slab 0
setblock ~18~4~25 minecraft:trapdoor 2
setblock ~25~0~25 minecraft:dirt 0
setblock ~25~1~25 minecraft:stonebrick 0
setblock ~25~2~25 minecraft:stone_block_slab 13
setblock ~25~4~25 minecraft:stone_block_slab 5
setblock ~25~5~25 minecraft:stonebrick 0
setblock ~25~6~25 minecraft:leaves 0
fill ~26~0~25 ~26~0~30 minecraft:grass
setblock ~26~2~25 minecraft:stonebrick 0
setblock ~26~3~25 minecraft:glowstone
setblock ~26~4~25 minecraft:stonebrick 0
fill ~7~0~26 ~7~0~30 minecraft:grass
setblock ~7~2~26 minecraft:stonebrick 0
setblock ~7~3~26 minecraft:glowstone
setblock ~7~4~26 minecraft:stonebrick 0
setblock ~8~0~26 minecraft:dirt 0
setblock ~8~1~26 minecraft:stonebrick 0
setblock ~8~2~26 minecraft:stone_block_slab 13
setblock ~8~4~26 minecraft:stone_block_slab 5
fill ~8~5~26 ~8~6~26 minecraft:stonebrick 0
setblock ~8~7~26 minecraft:leaves 0
setblock ~24~0~26 minecraft:dirt 0
setblock ~24~1~26 minecraft:stonebrick 0
setblock ~24~2~26 minecraft:stone_block_slab 13
setblock ~24~4~26 minecraft:stone_block_slab 5
fill ~24~5~26 ~24~6~26 minecraft:stonebrick 0
setblock ~24~7~26 minecraft:leaves 0
fill ~25~0~26 ~25~0~30 minecraft:grass
setblock ~25~2~26 minecraft:stonebrick 0
setblock ~25~3~26 minecraft:glowstone
setblock ~25~4~26 minecraft:stonebrick 0
fill ~8~0~27 ~8~0~30 minecraft:grass
fill ~8~2~27 ~9~4~27 minecraft:stonebrick 0
setblock ~9~0~27 minecraft:dirt 0
setblock ~9~1~27 minecraft:stonebrick 0
setblock ~9~5~27 minecraft:stonebrick 0
setblock ~9~6~27 minecraft:leaves 0
fill ~10~1~27 ~10~5~27 minecraft:log 0
setblock ~10~6~27 minecraft:log 0
fill ~22~1~27 ~22~5~27 minecraft:log 0
setblock ~22~6~27 minecraft:log 0
setblock ~23~0~27 minecraft:dirt 0
fill ~23~1~27 ~23~5~27 minecraft:stonebrick 0
setblock ~23~6~27 minecraft:leaves 0
fill ~24~0~27 ~24~0~30 minecraft:grass
fill ~24~2~27 ~24~4~27 minecraft:stonebrick 0
fill ~9~0~28 ~9~0~30 minecraft:grass
fill ~10~0~28 ~14~0~28 minecraft:dirt 0
fill ~10~1~28 ~14~1~28 minecraft:stonebrick 0
fill ~10~2~28 ~10~6~28 minecraft:stonebrick 0
setblock ~10~7~28 minecraft:leaves 0
setblock ~11~2~28 minecraft:stone_brick_stairs 1
setblock ~11~4~28 minecraft:stone_brick_stairs 5
fill ~11~5~28 ~22~5~28 minecraft:stonebrick 0
fill ~11~6~28 ~12~6~28 minecraft:leaves 0
setblock ~13~2~28 minecraft:stone_brick_stairs 0
setblock ~13~4~28 minecraft:stone_brick_stairs 4
fill ~13~6~28 ~14~6~28 minecraft:stonebrick 0
fill ~13~7~28 ~14~7~28 minecraft:leaves 0
fill ~14~2~28 ~14~4~30 minecraft:stonebrick 0
setblock ~15~3~28 minecraft:stone_brick_stairs 5
fill ~15~4~28 ~18~4~30 minecraft:stonebrick 0
fill ~15~6~28 ~17~6~28 minecraft:leaves 0
setblock ~17~3~28 minecraft:stone_brick_stairs 4
fill ~18~0~28 ~22~0~28 minecraft:dirt 0
fill ~18~1~28 ~22~1~28 minecraft:stonebrick 0
fill ~18~2~28 ~18~3~30 minecraft:stonebrick 0
fill ~18~6~28 ~19~6~28 minecraft:stonebrick 0
fill ~18~7~28 ~19~7~28 minecraft:leaves 0
setblock ~19~2~28 minecraft:stone_brick_stairs 1
setblock ~19~4~28 minecraft:stone_brick_stairs 5
fill ~20~6~28 ~21~6~28 minecraft:leaves 0
setblock ~21~2~28 minecraft:stone_brick_stairs 0
setblock ~21~4~28 minecraft:stone_brick_stairs 4
fill ~22~2~28 ~22~4~28 minecraft:stonebrick 0
setblock ~22~6~28 minecraft:stonebrick 0
setblock ~22~7~28 minecraft:leaves 0
fill ~23~0~28 ~23~0~30 minecraft:grass
fill ~10~0~29 ~13~0~30 minecraft:grass
setblock ~11~2~29 minecraft:glowstone
fill ~11~3~29 ~13~3~29 minecraft:stonebrick 0
setblock ~11~4~29 minecraft:glowstone
setblock ~12~2~29 minecraft:stonebrick 0
setblock ~12~4~29 minecraft:stonebrick 0
setblock ~13~2~29 minecraft:glowstone
setblock ~13~4~29 minecraft:glowstone
fill ~14~0~29 ~14~0~30 minecraft:dirt 0
fill ~14~1~29 ~14~1~30 minecraft:stonebrick 0
fill ~15~5~29 ~17~5~29 minecraft:stonebrick 0
fill ~18~0~29 ~18~0~30 minecraft:dirt 0
fill ~18~1~29 ~18~1~30 minecraft:stonebrick 0
fill ~19~0~29 ~22~0~30 minecraft:grass
setblock ~19~2~29 minecraft:glowstone
fill ~19~3~29 ~21~3~29 minecraft:stonebrick 0
setblock ~19~4~29 minecraft:glowstone
setblock ~20~2~29 minecraft:stonebrick 0
setblock ~20~4~29 minecraft:stonebrick 0
setblock ~21~2~29 minecraft:glowstone
setblock ~21~4~29 minecraft:glowstone
fill ~15~0~30 ~17~0~30 minecraft:dirt 0
fill ~15~1~30 ~17~3~30 minecraft:stonebrick 0