fill ~152~12~3 ~156~14~5 minecraft:light_block 15
fill ~153~11~3 ~155~11~5 minecraft:light_block 15
fill ~153~15~3 ~155~15~7 minecraft:light_block 15
fill ~47~12~4 ~51~14~5 minecraft:light_block 15
fill ~48~11~4 ~50~11~5 minecraft:light_block 15
fill ~48~15~4 ~50~15~8 minecraft:light_block 15
fill ~151~11~4 ~152~11~6 minecraft:light_block 15
fill ~151~12~4 ~151~15~8 minecraft:light_block 15
fill ~152~10~4 ~156~10~5 minecraft:light_block 15
fill ~152~15~4 ~152~16~10 minecraft:light_block 15
fill ~153~16~4 ~160~16~5 minecraft:light_block 15
fill ~155~17~4 ~160~17~5 minecraft:light_block 15
fill ~156~11~4 ~157~11~12 minecraft:light_block 15
fill ~156~15~4 ~159~15~5 minecraft:light_block 15
fill ~156~18~4 ~160~18~6 minecraft:light_block 15
fill ~157~12~4 ~157~12~13 minecraft:light_block 15
fill ~157~13~4 ~157~14~5 minecraft:light_block 15
fill ~157~19~4 ~159~19~8 minecraft:light_block 15
fill ~158~14~4 ~158~14~5 minecraft:light_block 15
fill ~46~11~5 ~47~11~13 minecraft:light_block 15
fill ~46~12~5 ~46~15~5 minecraft:light_block 15
fill ~47~10~5 ~51~10~5 minecraft:light_block 15
fill ~47~15~5 ~47~16~7 minecraft:light_block 15
fill ~48~16~5 ~51~16~9 minecraft:light_block 15
fill ~51~11~5 ~52~11~7 minecraft:light_block 15
fill ~51~15~5 ~52~15~11 minecraft:light_block 15
fill ~52~12~5 ~52~14~8 minecraft:light_block 15
fill ~144~7~5 ~148~9~5 minecraft:light_block 15
fill ~145~6~5 ~147~6~5 minecraft:light_block 15
fill ~145~10~5 ~151~10~5 minecraft:light_block 15
fill ~148~11~5 ~150~12~7 minecraft:light_block 15
fill ~149~9~5 ~156~9~5 minecraft:light_block 15
fill ~149~13~5 ~150~13~9 minecraft:light_block 15
fill ~150~14~5 ~150~15~10 minecraft:light_block 15
fill ~151~16~5 ~151~16~11 minecraft:light_block 15
fill ~152~17~5 ~154~17~10 minecraft:light_block 15
fill ~154~18~5 ~155~18~10 minecraft:light_block 15
fill ~155~19~5 ~156~19~10 minecraft:light_block 15
fill ~156~20~5 ~162~20~7 minecraft:light_block 15
fill ~157~10~5 ~157~10~11 minecraft:light_block 15
fill ~158~11~5 ~158~13~12 minecraft:light_block 15
fill ~158~21~5 ~162~21~7 minecraft:light_block 15
fill ~159~13~5 ~159~14~13 minecraft:light_block 15
fill ~159~22~5 ~161~22~9 minecraft:light_block 15
fill ~160~14~5 ~160~15~13 minecraft:light_block 15
fill ~160~19~5 ~162~19~6 minecraft:light_block 15
fill ~161~15~5 ~161~16~13 minecraft:light_block 15
fill ~161~17~5 ~161~18~6 minecraft:light_block 15
fill ~42~16~6 ~43~16~6 minecraft:wool 15
setblock ~42~17~6 minecraft:concrete 15
fill ~43~15~6 ~44~15~6 minecraft:wool 15
fill ~44~14~6 ~46~14~6 minecraft:wool 15
fill ~45~11~6 ~45~12~12 minecraft:light_block 15
fill ~45~13~6 ~46~13~6 minecraft:wool 15
fill ~45~15~6 ~46~15~6 minecraft:light_block 15
fill ~46~10~6 ~48~10~12 minecraft:light_block 15
setblock ~46~12~6 minecraft:wool 15
fill ~46~16~6 ~46~16~8 minecraft:light_block 15
fill ~47~9~6 ~49~9~12 minecraft:light_block 15
fill ~47~12~6 ~48~12~6 minecraft:concrete 15
setblock ~47~13~6 minecraft:concrete 15
fill ~47~14~6 ~51~14~6 minecraft:light_block 15
fill ~47~17~6 ~51~17~9 minecraft:light_block 15
setblock ~48~11~6 minecraft:wool 15
fill ~48~13~6 ~51~13~6 minecraft:light_block 15
fill ~49~10~6 ~51~10~6 minecraft:wool 15
fill ~49~11~6 ~49~11~7 minecraft:concrete 15
fill ~49~12~6 ~51~12~6 minecraft:light_block 15
fill ~50~9~6 ~51~9~6 minecraft:wool 15
setblock ~50~11~6 minecraft:light_block 15
fill ~52~8~6 ~52~8~7 minecraft:wool 15
setblock ~52~9~6 minecraft:concrete 15
setblock ~52~10~6 minecraft:light_block 15
fill ~52~16~6 ~52~16~12 minecraft:light_block 15
setblock ~53~7~6 minecraft:wool 15
fill ~53~8~6 ~53~8~7 minecraft:concrete 15
fill ~53~11~6 ~53~15~8 minecraft:light_block 15
fill ~54~6~6 ~54~7~6 minecraft:concrete 15
setblock ~55~5~6 minecraft:concrete 15
setblock ~55~6~6 minecraft:wool 15
setblock ~56~5~6 minecraft:wool 15
setblock ~57~4~6 minecraft:wool 15
fill ~143~6~6 ~146~10~6 minecraft:light_block 15
fill ~144~5~6 ~145~5~6 minecraft:light_block 15
fill ~144~11~6 ~147~11~10 minecraft:light_block 15
fill ~145~4~6 ~145~4~7 minecraft:wool 15
fill ~146~5~6 ~147~5~6 minecraft:concrete 15
fill ~146~12~6 ~147~12~11 minecraft:light_block 15
fill ~147~6~6 ~148~6~6 minecraft:concrete 15
fill ~147~7~6 ~147~10~6 minecraft:light_block 15
fill ~147~13~6 ~148~13~11 minecraft:light_block 15
fill ~148~5~6 ~148~5~14 minecraft:light_block 15
setblock ~148~7~6 minecraft:wool 15
fill ~148~8~6 ~148~10~6 minecraft:light_block 15
fill ~148~14~6 ~149~14~11 minecraft:light_block 15
fill ~149~6~6 ~149~6~14 minecraft:light_block 15
fill ~149~7~6 ~149~8~6 minecraft:concrete 15
fill ~149~9~6 ~149~10~6 minecraft:light_block 15
fill ~150~8~6 ~150~8~7 minecraft:concrete 15
setblock ~150~9~6 minecraft:concrete 15
setblock ~150~10~6 minecraft:light_block 15
fill ~150~16~6 ~150~16~12 minecraft:light_block 15
fill ~151~8~6 ~155~8~10 minecraft:light_block 15
fill ~151~9~6 ~152~9~6 minecraft:wool 15
setblock ~151~10~6 minecraft:wool 15
fill ~151~17~6 ~151~17~12 minecraft:light_block 15
fill ~152~10~6 ~152~10~7 minecraft:concrete 15
fill ~152~12~6 ~153~14~6 minecraft:light_block 15
fill ~153~9~6 ~157~9~10 minecraft:light_block 15
fill ~153~10~6 ~153~11~6 minecraft:wool 15
fill ~153~16~6 ~158~16~6 minecraft:light_block 15
fill ~153~18~6 ~153~18~12 minecraft:light_block 15
fill ~154~10~6 ~156~10~12 minecraft:light_block 15
setblock ~154~11~6 minecraft:wool 15
setblock ~154~12~6 minecraft:concrete 15
fill ~154~13~6 ~154~14~6 minecraft:light_block 15
fill ~154~19~6 ~154~19~12 minecraft:light_block 15
fill ~155~11~6 ~155~11~13 minecraft:light_block 15
fill ~155~12~6 ~155~13~6 minecraft:wool 15
setblock ~155~14~6 minecraft:light_block 15
fill ~155~17~6 ~159~17~6 minecraft:light_block 15
fill ~155~20~6 ~155~20~12 minecraft:light_block 15
fill ~156~12~6 ~156~14~6 minecraft:concrete 15
fill ~156~15~6 ~157~15~6 minecraft:light_block 15
fill ~156~21~6 ~157~21~12 minecraft:light_block 15
setblock ~157~13~6 minecraft:wool 15
setblock ~157~14~6 minecraft:concrete 15
fill ~157~22~6 ~158~22~12 minecraft:light_block 15
fill ~158~10~6 ~158~10~10 minecraft:light_block 15
fill ~158~14~6 ~158~15~6 minecraft:wool 15
fill ~158~23~6 ~162~23~9 minecraft:light_block 15
fill ~159~12~6 ~159~12~12 minecraft:light_block 15
setblock ~159~15~6 minecraft:wool 15
fill ~159~16~6 ~160~16~6 minecraft:concrete 15
fill ~160~13~6 ~160~13~12 minecraft:light_block 15
fill ~160~17~6 ~160~17~7 minecraft:concrete 15
fill ~161~14~6 ~161~14~12 minecraft:light_block 15
fill ~162~15~6 ~162~17~12 minecraft:light_block 15
fill ~162~18~6 ~163~18~6 minecraft:light_block 15
fill ~162~22~6 ~163~22~8 minecraft:light_block 15
fill ~163~19~6 ~163~21~6 minecraft:light_block 15
fill ~37~21~7 ~38~21~7 minecraft:wool 15
fill ~37~22~7 ~37~22~8 minecraft:concrete 15
setblock ~38~20~7 minecraft:concrete 15
fill ~39~19~7 ~39~20~7 minecraft:wool 15
fill ~40~18~7 ~40~19~7 minecraft:concrete 15
fill ~41~17~7 ~42~17~7 minecraft:wool 15
fill ~41~18~7 ~41~19~7 minecraft:wool 15
fill ~42~16~7 ~44~16~7 minecraft:concrete 15
fill ~42~18~7 ~42~18~8 minecraft:sea_lantern
fill ~43~17~7 ~43~17~8 minecraft:sea_lantern
fill ~44~12~7 ~44~14~11 minecraft:light_block 15
setblock ~44~15~7 minecraft:concrete 15
fill ~45~10~7 ~45~10~11 minecraft:light_block 15
fill ~45~13~7 ~45~13~12 minecraft:light_block 15
fill ~45~14~7 ~45~15~7 minecraft:wool 15
setblock ~45~16~7 minecraft:light_block 15
fill ~46~9~7 ~46~9~11 minecraft:light_block 15
fill ~46~12~7 ~47~12~13 minecraft:light_block 15
setblock ~46~13~7 minecraft:concrete 15
setblock ~46~14~7 minecraft:light_block 15
setblock ~46~15~7 minecraft:concrete 15
fill ~46~17~7 ~46~17~8 minecraft:light_block 15
fill ~47~13~7 ~47~14~7 minecraft:wool 15
fill ~48~8~7 ~50~8~11 minecraft:light_block 15
fill ~48~11~7 ~48~11~15 minecraft:light_block 15
fill ~48~12~7 ~48~13~7 minecraft:concrete 15
fill ~48~14~7 ~51~14~7 minecraft:light_block 15
fill ~48~18~7 ~50~18~11 minecraft:light_block 15
fill ~49~10~7 ~49~10~15 minecraft:light_block 15
fill ~49~12~7 ~49~12~8 minecraft:sea_lantern
fill ~49~13~7 ~51~13~7 minecraft:light_block 15
fill ~50~9~7 ~50~9~14 minecraft:light_block 15
fill ~50~10~7 ~51~10~7 minecraft:wool 15
fill ~50~11~7 ~50~11~8 minecraft:sea_lantern
fill ~50~12~7 ~51~12~7 minecraft:light_block 15
setblock ~51~9~7 minecraft:concrete 15
setblock ~52~9~7 minecraft:light_block 15
fill ~52~10~7 ~52~10~8 minecraft:concrete 15
fill ~52~17~7 ~52~17~13 minecraft:light_block 15
fill ~53~9~7 ~53~9~8 minecraft:wool 15
setblock ~53~10~7 minecraft:light_block 15
fill ~53~16~7 ~53~16~13 minecraft:light_block 15
fill ~54~7~7 ~55~7~7 minecraft:concrete 15
fill ~54~8~7 ~54~8~8 minecraft:wool 15
fill ~54~12~7 ~54~14~10 minecraft:light_block 15
fill ~55~6~7 ~56~6~7 minecraft:concrete 15
fill ~56~5~7 ~58~5~7 minecraft:concrete 15
fill ~57~4~7 ~58~4~7 minecraft:concrete 15
fill ~59~3~7 ~60~3~7 minecraft:wool 15
fill ~59~4~7 ~59~4~8 minecraft:wool 15
fill ~139~5~7 ~143~7~7 minecraft:light_block 15
fill ~140~4~7 ~142~4~7 minecraft:light_block 15
fill ~140~8~7 ~147~8~7 minecraft:light_block 15
fill ~142~3~7 ~143~3~7 minecraft:concrete 15
fill ~142~9~7 ~148~10~7 minecraft:light_block 15
fill ~143~4~7 ~144~4~7 minecraft:concrete 15
fill ~143~11~7 ~143~11~13 minecraft:light_block 15
fill ~144~5~7 ~145~5~7 minecraft:wool 15
fill ~144~6~7 ~145~7~7 minecraft:light_block 15
fill ~144~12~7 ~145~12~12 minecraft:light_block 15
fill ~145~13~7 ~146~13~12 minecraft:light_block 15
fill ~146~4~7 ~148~4~13 minecraft:light_block 15
setblock ~146~5~7 minecraft:concrete 15
fill ~146~6~7 ~146~6~8 minecraft:wool 15
setblock ~146~7~7 minecraft:light_block 15
fill ~146~14~7 ~147~14~13 minecraft:light_block 15
fill ~147~5~7 ~147~5~14 minecraft:light_block 15
setblock ~147~6~7 minecraft:concrete 15
fill ~147~7~7 ~147~7~8 minecraft:wool 15
fill ~148~6~7 ~148~6~14 minecraft:light_block 15
fill ~148~7~7 ~148~8~7 minecraft:concrete 15
fill ~148~15~7 ~149~15~12 minecraft:light_block 15
fill ~149~5~7 ~149~5~13 minecraft:light_block 15
fill ~149~7~7 ~152~7~13 minecraft:light_block 15
setblock ~149~8~7 minecraft:concrete 15
setblock ~149~9~7 minecraft:wool 15
setblock ~149~10~7 minecraft:light_block 15
fill ~150~6~7 ~150~6~13 minecraft:light_block 15
setblock ~150~9~7 minecraft:light_block 15
setblock ~150~10~7 minecraft:wool 15
setblock ~151~9~7 minecraft:wool 15
setblock ~151~10~7 minecraft:concrete 15
setblock ~151~11~7 minecraft:light_block 15
fill ~152~9~7 ~152~9~14 minecraft:light_block 15
fill ~152~11~7 ~152~11~8 minecraft:sea_lantern
fill ~152~12~7 ~152~14~7 minecraft:light_block 15
fill ~152~18~7 ~152~18~13 minecraft:light_block 15
fill ~153~10~7 ~153~10~14 minecraft:light_block 15
setblock ~153~11~7 minecraft:concrete 15
fill ~153~12~7 ~153~12~8 minecraft:sea_lantern
fill ~153~13~7 ~153~14~7 minecraft:light_block 15
fill ~153~16~7 ~157~16~7 minecraft:light_block 15
fill ~153~19~7 ~153~19~13 minecraft:light_block 15
fill ~154~11~7 ~154~11~13 minecraft:light_block 15
setblock ~154~12~7 minecraft:wool 15
fill ~154~13~7 ~155~13~7 minecraft:concrete 15
setblock ~154~14~7 minecraft:light_block 15
fill ~154~20~7 ~154~20~13 minecraft:light_block 15
fill ~155~12~7 ~156~12~13 minecraft:light_block 15
setblock ~155~14~7 minecraft:concrete 15
fill ~155~17~7 ~158~17~7 minecraft:light_block 15
fill ~155~21~7 ~155~21~13 minecraft:light_block 15
fill ~156~8~7 ~156~8~9 minecraft:light_block 15
setblock ~156~13~7 minecraft:wool 15
setblock ~156~14~7 minecraft:light_block 15
fill ~156~15~7 ~156~15~9 minecraft:concrete 15
fill ~156~18~7 ~159~18~7 minecraft:light_block 15
fill ~156~22~7 ~156~22~13 minecraft:light_block 15
fill ~157~13~7 ~157~13~14 minecraft:light_block 15
fill ~157~14~7 ~157~15~7 minecraft:wool 15
fill ~157~23~7 ~157~23~14 minecraft:light_block 15
fill ~158~14~7 ~158~14~14 minecraft:light_block 15
setblock ~158~15~7 minecraft:concrete 15
fill ~158~16~7 ~158~16~8 minecraft:wool 15
fill ~158~24~7 ~162~24~11 minecraft:light_block 15
fill ~159~11~7 ~159~11~11 minecraft:light_block 15
fill ~159~15~7 ~159~15~15 minecraft:light_block 15
setblock ~159~16~7 minecraft:concrete 15
fill ~159~17~7 ~159~17~8 minecraft:sea_lantern
fill ~160~12~7 ~160~12~11 minecraft:light_block 15
setblock ~160~16~7 minecraft:wool 15
fill ~160~18~7 ~160~18~8 minecraft:sea_lantern
setblock ~160~19~7 minecraft:light_block 15
fill ~161~13~7 ~161~13~11 minecraft:light_block 15
setblock ~161~17~7 minecraft:concrete 15
fill ~161~18~7 ~161~19~7 minecraft:wool 15
fill ~162~14~7 ~162~14~11 minecraft:light_block 15
setblock ~162~18~7 minecraft:concrete 15
fill ~162~19~7 ~162~19~8 minecraft:wool 15
fill ~163~16~7 ~163~18~12 minecraft:light_block 15
fill ~163~19~7 ~163~20~7 minecraft:concrete 15
setblock ~163~21~7 minecraft:light_block 15
fill ~163~23~7 ~163~23~9 minecraft:light_block 15
fill ~163~25~7 ~167~27~7 minecraft:light_block 15
fill ~164~18~7 ~164~19~13 minecraft:light_block 15
fill ~164~20~7 ~164~21~7 minecraft:wool 15
setblock ~164~22~7 minecraft:light_block 15
fill ~164~24~7 ~166~24~7 minecraft:light_block 15
fill ~164~28~7 ~166~28~11 minecraft:light_block 15
fill ~165~21~7 ~165~22~7 minecraft:concrete 15
setblock ~34~25~8 minecraft:concrete 15
fill ~35~24~8 ~36~24~8 minecraft:concrete 15
setblock ~35~25~8 minecraft:wool 15
fill ~36~22~8 ~36~23~8 minecraft:wool 15
fill ~37~23~8 ~37~23~9 minecraft:wool 15
fill ~38~21~8 ~39~21~8 minecraft:concrete 15
fill ~38~22~8 ~38~22~9 minecraft:concrete 15
fill ~39~20~8 ~41~20~8 minecraft:concrete 15
setblock ~40~19~8 minecraft:wool 15
fill ~40~21~8 ~40~21~9 minecraft:wool 15
fill ~41~19~8 ~41~19~9 minecraft:concrete 15
setblock ~42~19~8 minecraft:sea_lantern
fill ~42~20~8 ~46~22~8 minecraft:light_block 15
fill ~43~18~8 ~43~18~9 minecraft:sea_lantern
fill ~43~19~8 ~45~19~8 minecraft:light_block 15
fill ~43~23~8 ~45~23~12 minecraft:light_block 15
fill ~44~11~8 ~44~11~10 minecraft:light_block 15
fill ~44~15~8 ~44~15~10 minecraft:light_block 15
fill ~44~16~8 ~45~16~8 minecraft:concrete 15
setblock ~44~17~8 minecraft:sea_lantern
fill ~45~14~8 ~45~14~12 minecraft:light_block 15
setblock ~45~15~8 minecraft:concrete 15
fill ~46~13~8 ~47~13~14 minecraft:light_block 15
fill ~46~14~8 ~47~14~8 minecraft:wool 15
setblock ~46~15~8 minecraft:wool 15
fill ~47~8~8 ~47~8~10 minecraft:light_block 15
setblock ~47~15~8 minecraft:concrete 15
setblock ~47~16~8 minecraft:light_block 15
fill ~47~18~8 ~47~18~10 minecraft:light_block 15
fill ~48~12~8 ~48~12~16 minecraft:light_block 15
setblock ~48~13~8 minecraft:wool 15
fill ~48~14~8 ~48~14~9 minecraft:concrete 15
fill ~49~11~8 ~49~11~16 minecraft:light_block 15
setblock ~49~13~8 minecraft:sea_lantern
fill ~49~14~8 ~51~14~8 minecraft:light_block 15
fill ~50~10~8 ~50~10~16 minecraft:light_block 15
fill ~50~12~8 ~50~12~9 minecraft:sea_lantern
fill ~50~13~8 ~51~13~8 minecraft:light_block 15
fill ~51~8~8 ~51~9~10 minecraft:light_block 15
setblock ~51~10~8 minecraft:wool 15
setblock ~51~11~8 minecraft:sea_lantern
setblock ~51~12~8 minecraft:light_block 15
fill ~51~18~8 ~51~18~14 minecraft:light_block 15
setblock ~52~9~8 minecraft:wool 15
setblock ~52~11~8 minecraft:wool 15
setblock ~53~10~8 minecraft:concrete 15
fill ~54~9~8 ~54~9~9 minecraft:concrete 15
fill ~54~10~8 ~56~11~8 minecraft:light_block 15
fill ~54~15~8 ~54~15~13 minecraft:light_block 15
fill ~55~7~8 ~56~7~8 minecraft:wool 15
fill ~55~8~8 ~55~8~9 minecraft:concrete 15
fill ~55~12~8 ~57~13~11 minecraft:light_block 15
fill ~55~14~8 ~56~14~13 minecraft:light_block 15
fill ~56~6~8 ~57~6~8 minecraft:wool 15
setblock ~57~5~8 minecraft:wool 15
setblock ~57~7~8 minecraft:sea_lantern
fill ~57~11~8 ~57~11~11 minecraft:light_block 15
fill ~58~5~8 ~59~5~8 minecraft:concrete 15
setblock ~58~6~8 minecraft:sea_lantern
setblock ~60~3~8 minecraft:wool 15
fill ~60~4~8 ~60~4~9 minecraft:concrete 15
fill ~61~2~8 ~61~3~8 minecraft:concrete 15
setblock ~62~2~8 minecraft:wool 15
fill ~63~1~8 ~63~1~9 minecraft:concrete 15
setblock ~63~2~8 minecraft:concrete 15
fill ~138~4~8 ~141~8~8 minecraft:light_block 15
fill ~139~1~8 ~139~2~8 minecraft:wool 15
fill ~139~3~8 ~140~3~8 minecraft:light_block 15
fill ~139~9~8 ~147~9~8 minecraft:light_block 15
setblock ~140~2~8 minecraft:wool 15
setblock ~141~2~8 minecraft:concrete 15
fill ~141~3~8 ~141~3~9 minecraft:wool 15
setblock ~142~3~8 minecraft:concrete 15
fill ~142~4~8 ~142~4~9 minecraft:wool 15
fill ~142~5~8 ~142~8~8 minecraft:light_block 15
fill ~142~10~8 ~148~10~8 minecraft:light_block 15
fill ~142~11~8 ~142~11~14 minecraft:light_block 15
fill ~143~3~8 ~143~3~16 minecraft:light_block 15
fill ~143~4~8 ~143~5~8 minecraft:concrete 15
fill ~143~6~8 ~143~8~8 minecraft:light_block 15
fill ~143~12~8 ~143~12~14 minecraft:light_block 15
fill ~144~4~8 ~145~4~15 minecraft:light_block 15
fill ~144~5~8 ~144~5~9 minecraft:concrete 15
setblock ~144~6~8 minecraft:sea_lantern
fill ~144~7~8 ~144~8~8 minecraft:light_block 15
fill ~144~13~8 ~144~13~14 minecraft:light_block 15
fill ~145~3~8 ~147~3~12 minecraft:light_block 15
fill ~145~5~8 ~145~6~8 minecraft:wool 15
setblock ~145~7~8 minecraft:sea_lantern
fill ~145~8~8 ~146~8~8 minecraft:light_block 15
fill ~145~14~8 ~145~14~15 minecraft:light_block 15
fill ~146~5~8 ~146~5~14 minecraft:light_block 15
fill ~146~7~8 ~146~7~9 minecraft:wool 15
fill ~146~15~8 ~147~15~14 minecraft:light_block 15
fill ~147~6~8 ~147~6~15 minecraft:light_block 15
fill ~147~8~8 ~148~8~8 minecraft:concrete 15
fill ~148~7~8 ~148~7~15 minecraft:light_block 15
setblock ~148~9~8 minecraft:wool 15
fill ~148~11~8 ~149~12~8 minecraft:light_block 15
fill ~149~4~8 ~149~4~12 minecraft:light_block 15
fill ~149~8~8 ~150~8~15 minecraft:light_block 15
fill ~149~9~8 ~149~10~8 minecraft:concrete 15
fill ~149~16~8 ~149~16~13 minecraft:light_block 15
fill ~150~5~8 ~150~5~12 minecraft:light_block 15
setblock ~150~9~8 minecraft:wool 15
fill ~150~10~8 ~150~11~8 minecraft:concrete 15
setblock ~150~12~8 minecraft:light_block 15
fill ~151~6~8 ~151~6~12 minecraft:light_block 15
fill ~151~9~8 ~151~9~15 minecraft:light_block 15
setblock ~151~10~8 minecraft:wool 15
setblock ~151~11~8 minecraft:sea_lantern
fill ~152~10~8 ~152~10~15 minecraft:light_block 15
fill ~152~12~8 ~152~12~9 minecraft:sea_lantern
fill ~152~13~8 ~152~14~8 minecraft:light_block 15
fill ~153~7~8 ~153~7~12 minecraft:light_block 15
fill ~153~11~8 ~153~11~14 minecraft:light_block 15
setblock ~153~13~8 minecraft:sea_lantern
fill ~153~14~8 ~153~16~8 minecraft:light_block 15
fill ~153~20~8 ~153~20~14 minecraft:light_block 15
fill ~154~12~8 ~154~12~13 minecraft:light_block 15
setblock ~154~13~8 minecraft:wool 15
fill ~154~14~8 ~154~14~9 minecraft:concrete 15
fill ~154~15~8 ~154~16~8 minecraft:light_block 15
fill ~154~21~8 ~154~21~14 minecraft:light_block 15
fill ~155~13~8 ~156~13~14 minecraft:light_block 15
setblock ~155~14~8 minecraft:wool 15
fill ~155~15~8 ~155~15~9 minecraft:concrete 15
fill ~155~16~8 ~156~17~8 minecraft:light_block 15
fill ~155~22~8 ~155~22~14 minecraft:light_block 15
setblock ~156~14~8 minecraft:concrete 15
fill ~156~18~8 ~158~18~8 minecraft:light_block 15
fill ~156~20~8 ~160~20~8 minecraft:light_block 15
fill ~156~23~8 ~156~23~15 minecraft:light_block 15
fill ~157~14~8 ~157~14~14 minecraft:light_block 15
setblock ~157~15~8 minecraft:wool 15
fill ~157~16~8 ~157~16~9 minecraft:concrete 15
setblock ~157~17~8 minecraft:light_block 15
fill ~157~24~8 ~157~24~15 minecraft:light_block 15
fill ~158~15~8 ~158~15~15 minecraft:light_block 15
setblock ~158~17~8 minecraft:sea_lantern
fill ~158~21~8 ~161~21~8 minecraft:light_block 15
fill ~159~16~8 ~160~16~15 minecraft:light_block 15
fill ~159~18~8 ~159~18~9 minecraft:sea_lantern
fill ~159~25~8 ~166~25~8 minecraft:light_block 15
fill ~160~17~8 ~161~17~15 minecraft:light_block 15
setblock ~160~19~8 minecraft:sea_lantern
fill ~161~18~8 ~162~18~15 minecraft:light_block 15
fill ~161~19~8 ~161~19~9 minecraft:concrete 15
fill ~161~20~8 ~162~20~8 minecraft:wool 15
fill ~162~21~8 ~162~21~9 minecraft:wool 15
fill ~162~26~8 ~168~27~8 minecraft:light_block 15
fill ~162~28~8 ~163~28~14 minecraft:light_block 15
fill ~163~15~8 ~163~15~10 minecraft:light_block 15
fill ~163~19~8 ~163~19~14 minecraft:light_block 15
fill ~163~20~8 ~163~21~8 minecraft:concrete 15
fill ~163~24~8 ~165~24~8 minecraft:light_block 15
fill ~163~29~8 ~167~29~11 minecraft:light_block 15
fill ~164~17~8 ~164~17~12 minecraft:light_block 15
fill ~164~20~8 ~165~20~12 minecraft:light_block 15
setblock ~164~21~8 minecraft:concrete 15
fill ~164~22~8 ~166~22~8 minecraft:wool 15
setblock ~164~23~8 minecraft:light_block 15
fill ~165~19~8 ~165~19~12 minecraft:light_block 15
fill ~165~21~8 ~165~21~16 minecraft:light_block 15
fill ~165~23~8 ~166~23~8 minecraft:concrete 15
setblock ~166~24~8 minecraft:concrete 15
fill ~167~23~8 ~167~23~16 minecraft:light_block 15
setblock ~167~24~8 minecraft:wool 15
fill ~167~25~8 ~168~25~8 minecraft:concrete 15
fill ~167~28~8 ~168~28~10 minecraft:light_block 15
fill ~168~24~8 ~168~24~16 minecraft:light_block 15
fill ~32~28~9 ~32~28~10 minecraft:sea_lantern
setblock ~33~26~9 minecraft:wool 15
fill ~33~27~9 ~33~27~10 minecraft:sea_lantern
setblock ~34~25~9 minecraft:wool 15
fill ~34~26~9 ~35~26~9 minecraft:concrete 15
setblock ~35~24~9 minecraft:concrete 15
setblock ~36~24~9 minecraft:wool 15
fill ~36~25~9 ~36~25~10 minecraft:concrete 15
fill ~37~24~9 ~37~24~10 minecraft:concrete 15
fill ~38~23~9 ~38~23~10 minecraft:concrete 15
setblock ~39~21~9 minecraft:wool 15
setblock ~39~22~9 minecraft:concrete 15
setblock ~40~20~9 minecraft:wool 15
setblock ~41~20~9 minecraft:light_block 15
setblock ~41~21~9 minecraft:concrete 15
fill ~41~22~9 ~47~22~9 minecraft:light_block 15
fill ~41~23~9 ~42~23~10 minecraft:light_block 15
fill ~42~18~9 ~42~18~17 minecraft:light_block 15
setblock ~42~19~9 minecraft:wool 15
fill ~42~20~9 ~42~20~10 minecraft:concrete 15
fill ~42~21~9 ~48~21~9 minecraft:light_block 15
fill ~42~24~9 ~46~24~12 minecraft:light_block 15
setblock ~43~19~9 minecraft:sea_lantern
fill ~43~20~9 ~50~20~9 minecraft:light_block 15
fill ~44~17~9 ~46~17~9 minecraft:wool 15
setblock ~44~18~9 minecraft:sea_lantern
fill ~44~19~9 ~53~19~9 minecraft:light_block 15
fill ~45~15~9 ~45~15~16 minecraft:light_block 15
fill ~45~16~9 ~47~16~9 minecraft:concrete 15
fill ~45~18~9 ~45~18~11 minecraft:concrete 15
fill ~46~14~9 ~47~14~16 minecraft:light_block 15
setblock ~46~15~9 minecraft:concrete 15
setblock ~46~18~9 minecraft:light_block 15
fill ~46~23~9 ~47~23~15 minecraft:light_block 15
setblock ~47~15~9 minecraft:wool 15
fill ~48~13~9 ~48~13~17 minecraft:light_block 15
fill ~48~15~9 ~48~15~10 minecraft:concrete 15
fill ~49~12~9 ~49~12~17 minecraft:light_block 15
setblock ~49~13~9 minecraft:wool 15
fill ~49~14~9 ~49~14~10 minecraft:concrete 15
fill ~49~15~9 ~50~15~9 minecraft:light_block 15
fill ~50~11~9 ~50~11~17 minecraft:light_block 15
setblock ~50~13~9 minecraft:sea_lantern
fill ~50~14~9 ~53~14~9 minecraft:light_block 15
fill ~51~10~9 ~52~10~16 minecraft:light_block 15
setblock ~51~11~9 minecraft:wool 15
setblock ~51~12~9 minecraft:sea_lantern
fill ~51~13~9 ~53~13~9 minecraft:light_block 15
fill ~52~9~9 ~53~9~16 minecraft:light_block 15
fill ~52~11~9 ~53~11~10 minecraft:concrete 15
fill ~52~12~9 ~52~12~10 minecraft:concrete 15
fill ~52~18~9 ~54~18~14 minecraft:light_block 15
fill ~53~10~9 ~54~10~9 minecraft:wool 15
setblock ~53~12~9 minecraft:light_block 15
fill ~53~15~9 ~53~15~12 minecraft:light_block 15
fill ~53~17~9 ~54~17~14 minecraft:light_block 15
fill ~54~11~9 ~56~11~9 minecraft:light_block 15
fill ~54~16~9 ~55~16~14 minecraft:light_block 15
setblock ~55~9~9 minecraft:wool 15
fill ~55~10~9 ~58~10~9 minecraft:light_block 15
fill ~55~15~9 ~57~15~14 minecraft:light_block 15
setblock ~56~7~9 minecraft:wool 15
setblock ~56~8~9 minecraft:concrete 15
fill ~56~9~9 ~57~9~9 minecraft:light_block 15
setblock ~57~6~9 minecraft:sea_lantern
setblock ~57~8~9 minecraft:sea_lantern
fill ~57~14~9 ~58~14~15 minecraft:light_block 15
setblock ~58~5~9 minecraft:concrete 15
setblock ~58~7~9 minecraft:sea_lantern
fill ~58~11~9 ~58~13~12 minecraft:light_block 15
fill ~59~5~9 ~60~5~9 minecraft:wool 15
setblock ~59~6~9 minecraft:sea_lantern
fill ~61~3~9 ~62~3~9 minecraft:wool 15
setblock ~61~4~9 minecraft:wool 15
setblock ~62~2~9 minecraft:concrete 15
fill ~62~5~9 ~66~7~9 minecraft:light_block 15
setblock ~63~3~9 minecraft:concrete 15
fill ~63~4~9 ~65~4~9 minecraft:light_block 15
fill ~63~8~9 ~65~8~13 minecraft:light_block 15
setblock ~64~1~9 minecraft:concrete 15
setblock ~64~2~9 minecraft:wool 15
setblock ~65~0~9 minecraft:concrete 15
setblock ~65~1~9 minecraft:wool 15
fill ~66~0~9 ~66~0~10 minecraft:wool 15
fill ~136~0~9 ~137~0~9 minecraft:concrete 15
setblock ~137~1~9 minecraft:wool 15
fill ~137~4~9 ~140~8~9 minecraft:light_block 15
fill ~138~1~9 ~139~1~9 minecraft:concrete 15
setblock ~138~2~9 minecraft:wool 15
setblock ~138~3~9 minecraft:light_block 15
fill ~138~9~9 ~146~9~9 minecraft:light_block 15
setblock ~139~2~9 minecraft:light_block 15
setblock ~139~3~9 minecraft:concrete 15
fill ~139~10~9 ~147~10~9 minecraft:light_block 15
setblock ~140~2~9 minecraft:concrete 15
fill ~140~3~9 ~140~3~10 minecraft:wool 15
fill ~141~2~9 ~143~2~15 minecraft:light_block 15
setblock ~141~4~9 minecraft:wool 15
fill ~141~5~9 ~141~8~9 minecraft:light_block 15
fill ~142~3~9 ~142~3~16 minecraft:light_block 15
fill ~142~5~9 ~143~5~9 minecraft:wool 15
fill ~142~6~9 ~142~8~9 minecraft:light_block 15
fill ~143~4~9 ~143~4~16 minecraft:light_block 15
setblock ~143~6~9 minecraft:sea_lantern
fill ~143~7~9 ~143~8~9 minecraft:light_block 15
fill ~143~13~9 ~143~13~15 minecraft:light_block 15
fill ~144~3~9 ~144~3~15 minecraft:light_block 15
setblock ~144~6~9 minecraft:light_block 15
setblock ~144~7~9 minecraft:sea_lantern
setblock ~144~8~9 minecraft:light_block 15
fill ~144~14~9 ~144~14~15 minecraft:light_block 15
fill ~145~5~9 ~145~5~15 minecraft:light_block 15
setblock ~145~6~9 minecraft:sea_lantern
setblock ~145~7~9 minecraft:light_block 15
setblock ~145~8~9 minecraft:sea_lantern
fill ~145~15~9 ~145~15~15 minecraft:light_block 15
fill ~146~6~9 ~146~6~15 minecraft:light_block 15
setblock ~146~8~9 minecraft:concrete 15
fill ~147~7~9 ~147~7~15 minecraft:light_block 15
setblock ~147~8~9 minecraft:wool 15
fill ~147~9~9 ~148~9~9 minecraft:concrete 15
fill ~147~16~9 ~148~16~14 minecraft:light_block 15
fill ~148~3~9 ~148~3~11 minecraft:light_block 15
fill ~148~8~9 ~148~8~16 minecraft:light_block 15
fill ~148~10~9 ~149~10~9 minecraft:wool 15
fill ~148~11~9 ~148~12~9 minecraft:light_block 15
fill ~149~9~9 ~150~9~16 minecraft:light_block 15
fill ~149~11~9 ~149~11~10 minecraft:concrete 15
setblock ~149~12~9 minecraft:light_block 15
fill ~150~10~9 ~151~10~16 minecraft:light_block 15
setblock ~150~11~9 minecraft:wool 15
setblock ~150~12~9 minecraft:concrete 15
setblock ~151~11~9 minecraft:concrete 15
setblock ~151~12~9 minecraft:sea_lantern
fill ~151~13~9 ~151~15~9 minecraft:light_block 15
fill ~152~6~9 ~152~6~11 minecraft:light_block 15
fill ~152~11~9 ~152~11~16 minecraft:light_block 15
setblock ~152~13~9 minecraft:sea_lantern
setblock ~152~14~9 minecraft:light_block 15
fill ~152~19~9 ~152~19~14 minecraft:light_block 15
fill ~153~12~9 ~153~12~17 minecraft:light_block 15
setblock ~153~13~9 minecraft:concrete 15
setblock ~153~14~9 minecraft:wool 15
fill ~153~15~9 ~153~16~9 minecraft:light_block 15
fill ~153~21~9 ~153~21~15 minecraft:light_block 15
fill ~154~13~9 ~154~13~17 minecraft:light_block 15
fill ~154~15~9 ~154~15~10 minecraft:concrete 15
setblock ~154~16~9 minecraft:light_block 15
fill ~154~22~9 ~154~22~15 minecraft:light_block 15
fill ~155~14~9 ~156~14~14 minecraft:light_block 15
fill ~155~16~9 ~156~16~9 minecraft:wool 15
setblock ~155~17~9 minecraft:light_block 15
fill ~155~23~9 ~155~23~15 minecraft:light_block 15
fill ~156~17~9 ~157~17~9 minecraft:wool 15
setblock ~156~18~9 minecraft:light_block 15
fill ~156~20~9 ~159~20~9 minecraft:light_block 15
fill ~156~24~9 ~156~24~15 minecraft:light_block 15
fill ~157~15~9 ~157~15~16 minecraft:light_block 15
fill ~157~18~9 ~157~18~10 minecraft:wool 15
fill ~157~19~9 ~158~19~9 minecraft:light_block 15
fill ~158~16~9 ~158~16~17 minecraft:light_block 15
setblock ~158~17~9 minecraft:concrete 15
setblock ~158~18~9 minecraft:sea_lantern
fill ~158~21~9 ~160~21~9 minecraft:light_block 15
fill ~158~25~9 ~165~25~9 minecraft:light_block 15
fill ~159~17~9 ~159~17~17 minecraft:light_block 15
setblock ~159~19~9 minecraft:sea_lantern
fill ~159~26~9 ~166~26~9 minecraft:light_block 15
fill ~160~18~9 ~160~18~17 minecraft:light_block 15
setblock ~160~19~9 minecraft:wool 15
fill ~160~20~9 ~160~20~10 minecraft:concrete 15
setblock ~161~20~9 minecraft:light_block 15
setblock ~161~21~9 minecraft:wool 15
fill ~161~27~9 ~168~27~9 minecraft:light_block 15
fill ~161~28~9 ~161~28~15 minecraft:light_block 15
fill ~162~19~9 ~162~19~15 minecraft:light_block 15
setblock ~162~20~9 minecraft:wool 15
setblock ~162~22~9 minecraft:light_block 15
fill ~162~29~9 ~162~29~16 minecraft:light_block 15
fill ~163~20~9 ~163~20~16 minecraft:light_block 15
fill ~163~21~9 ~163~22~9 minecraft:concrete 15
fill ~163~24~9 ~164~24~9 minecraft:light_block 15
fill ~163~30~9 ~167~30~12 minecraft:light_block 15
fill ~164~21~9 ~164~21~17 minecraft:light_block 15
fill ~164~22~9 ~164~23~9 minecraft:concrete 15
fill ~165~18~9 ~165~18~11 minecraft:light_block 15
fill ~165~22~9 ~167~22~15 minecraft:light_block 15
fill ~165~23~9 ~165~24~9 minecraft:wool 15
fill ~166~23~9 ~166~23~17 minecraft:light_block 15
fill ~166~24~9 ~166~24~10 minecraft:wool 15
setblock ~166~25~9 minecraft:concrete 15
setblock ~167~24~9 minecraft:concrete 15
setblock ~167~25~9 minecraft:light_block 15
setblock ~167~26~9 minecraft:concrete 15
fill ~168~23~9 ~168~23~15 minecraft:light_block 15
setblock ~168~25~9 minecraft:concrete 15
fill ~168~26~9 ~169~26~9 minecraft:wool 15
fill ~168~29~9 ~168~29~11 minecraft:light_block 15
fill ~169~24~9 ~169~25~15 minecraft:light_block 15
fill ~169~27~9 ~169~27~10 minecraft:sea_lantern
setblock ~169~28~9 minecraft:light_block 15
fill ~170~28~9 ~170~28~10 minecraft:sea_lantern
setblock ~32~29~10 minecraft:sea_lantern
fill ~33~28~10 ~33~28~11 minecraft:sea_lantern
setblock ~34~26~10 minecraft:wool 15
setblock ~34~27~10 minecraft:sea_lantern
setblock ~35~25~10 minecraft:wool 15
setblock ~35~27~10 minecraft:wool 15
setblock ~36~24~10 minecraft:concrete 15
fill ~36~26~10 ~36~26~11 minecraft:wool 15
fill ~36~27~10 ~40~29~10 minecraft:light_block 15
fill ~37~25~10 ~37~25~11 minecraft:wool 15
fill ~37~26~10 ~39~26~10 minecraft:light_block 15
fill ~37~30~10 ~39~30~14 minecraft:light_block 15
fill ~38~24~10 ~38~24~11 minecraft:sea_lantern
fill ~39~22~10 ~41~22~10 minecraft:wool 15
fill ~39~23~10 ~39~23~11 minecraft:sea_lantern
fill ~40~19~10 ~42~19~16 minecraft:light_block 15
fill ~40~20~10 ~40~20~16 minecraft:light_block 15
setblock ~40~21~10 minecraft:concrete 15
setblock ~40~23~10 minecraft:wool 15
fill ~41~18~10 ~41~18~16 minecraft:light_block 15
setblock ~41~20~10 minecraft:wool 15
setblock ~41~21~10 minecraft:light_block 15
fill ~41~24~10 ~41~24~11 minecraft:light_block 15
fill ~42~17~10 ~44~17~16 minecraft:light_block 15
setblock ~42~21~10 minecraft:concrete 15
fill ~42~22~10 ~49~22~10 minecraft:light_block 15
fill ~42~25~10 ~46~25~13 minecraft:light_block 15
fill ~43~18~10 ~43~18~18 minecraft:light_block 15
setblock ~43~19~10 minecraft:concrete 15
setblock ~43~20~10 minecraft:wool 15
fill ~43~21~10 ~51~21~10 minecraft:light_block 15
setblock ~44~18~10 minecraft:concrete 15
setblock ~44~19~10 minecraft:wool 15
fill ~44~20~10 ~54~20~10 minecraft:light_block 15
fill ~45~16~10 ~45~16~17 minecraft:light_block 15
setblock ~45~17~10 minecraft:concrete 15
fill ~45~19~10 ~55~19~10 minecraft:light_block 15
fill ~46~15~10 ~47~15~17 minecraft:light_block 15
setblock ~46~16~10 minecraft:wool 15
setblock ~46~17~10 minecraft:light_block 15
setblock ~46~18~10 minecraft:concrete 15
setblock ~47~16~10 minecraft:concrete 15
setblock ~47~17~10 minecraft:wool 15
fill ~47~24~10 ~47~24~16 minecraft:light_block 15
fill ~48~14~10 ~48~14~17 minecraft:light_block 15
setblock ~48~16~10 minecraft:wool 15
fill ~48~17~10 ~51~17~10 minecraft:light_block 15
fill ~48~23~10 ~48~23~16 minecraft:light_block 15
fill ~49~13~10 ~49~13~17 minecraft:light_block 15
setblock ~49~15~10 minecraft:wool 15
fill ~49~16~10 ~51~16~10 minecraft:light_block 15
fill ~50~12~10 ~50~12~17 minecraft:light_block 15
fill ~50~13~10 ~52~13~10 minecraft:wool 15
setblock ~50~14~10 minecraft:wool 15
setblock ~50~15~10 minecraft:light_block 15
fill ~51~11~10 ~51~11~17 minecraft:light_block 15
setblock ~51~12~10 minecraft:wool 15
fill ~51~14~10 ~53~14~10 minecraft:light_block 15
fill ~53~8~10 ~55~8~16 minecraft:light_block 15
fill ~53~10~10 ~53~10~18 minecraft:light_block 15
setblock ~53~12~10 minecraft:concrete 15
setblock ~53~13~10 minecraft:light_block 15
fill ~54~9~10 ~54~9~18 minecraft:light_block 15
fill ~54~10~10 ~54~11~10 minecraft:wool 15
fill ~55~9~10 ~55~10~10 minecraft:concrete 15
fill ~55~11~10 ~56~11~10 minecraft:light_block 15
fill ~55~17~10 ~55~18~16 minecraft:light_block 15
fill ~56~8~10 ~56~9~10 minecraft:wool 15
fill ~56~10~10 ~59~10~10 minecraft:light_block 15
fill ~56~16~10 ~57~16~16 minecraft:light_block 15
setblock ~57~7~10 minecraft:sea_lantern
setblock ~57~8~10 minecraft:light_block 15
setblock ~57~9~10 minecraft:concrete 15
setblock ~58~6~10 minecraft:sea_lantern
setblock ~58~8~10 minecraft:sea_lantern
setblock ~58~9~10 minecraft:light_block 15
fill ~58~15~10 ~58~15~16 minecraft:light_block 15
setblock ~59~6~10 minecraft:concrete 15
setblock ~59~7~10 minecraft:sea_lantern
fill ~59~11~10 ~59~14~13 minecraft:light_block 15
fill ~60~5~10 ~61~5~10 minecraft:wool 15
fill ~60~6~10 ~60~6~11 minecraft:wool 15
fill ~60~7~10 ~67~7~10 minecraft:light_block 15
fill ~60~8~10 ~62~9~11 minecraft:light_block 15
fill ~61~4~10 ~62~4~10 minecraft:concrete 15
fill ~61~6~10 ~68~6~10 minecraft:light_block 15
fill ~61~10~10 ~63~10~14 minecraft:light_block 15
setblock ~62~3~10 minecraft:concrete 15
setblock ~62~5~10 minecraft:concrete 15
setblock ~63~2~10 minecraft:wool 15
setblock ~63~3~10 minecraft:light_block 15
setblock ~63~4~10 minecraft:wool 15
fill ~63~5~10 ~69~5~10 minecraft:light_block 15
fill ~63~9~10 ~66~9~14 minecraft:light_block 15
setblock ~64~2~10 minecraft:concrete 15
setblock ~64~3~10 minecraft:wool 15
fill ~64~4~10 ~69~4~10 minecraft:light_block 15
fill ~65~1~10 ~66~1~10 minecraft:concrete 15
setblock ~65~2~10 minecraft:wool 15
fill ~65~3~10 ~69~3~10 minecraft:light_block 15
fill ~66~2~10 ~68~2~10 minecraft:light_block 15
fill ~66~8~10 ~67~8~16 minecraft:light_block 15
fill ~67~0~10 ~67~0~11 minecraft:concrete 15
fill ~68~0~10 ~68~0~11 minecraft:wool 15
setblock ~134~0~10 minecraft:wool 15
fill ~135~0~10 ~136~0~10 minecraft:concrete 15
setblock ~136~1~10 minecraft:wool 15
fill ~136~5~10 ~139~8~10 minecraft:light_block 15
fill ~137~1~10 ~137~2~10 minecraft:concrete 15
fill ~137~3~10 ~137~4~10 minecraft:light_block 15
fill ~137~9~10 ~144~9~10 minecraft:light_block 15
fill ~138~2~10 ~139~2~10 minecraft:concrete 15
setblock ~138~3~10 minecraft:wool 15
setblock ~138~4~10 minecraft:light_block 15
fill ~138~10~10 ~146~10~10 minecraft:light_block 15
setblock ~139~3~10 minecraft:light_block 15
fill ~139~4~10 ~141~4~10 minecraft:concrete 15
fill ~140~1~10 ~142~1~14 minecraft:light_block 15
fill ~140~2~10 ~140~2~16 minecraft:light_block 15
setblock ~140~5~10 minecraft:concrete 15
fill ~140~6~10 ~141~8~10 minecraft:light_block 15
fill ~140~11~10 ~141~11~15 minecraft:light_block 15
fill ~141~3~10 ~141~3~17 minecraft:light_block 15
setblock ~141~5~10 minecraft:wool 15
fill ~142~4~10 ~142~4~17 minecraft:light_block 15
fill ~142~5~10 ~142~6~10 minecraft:concrete 15
fill ~142~7~10 ~142~8~10 minecraft:light_block 15
fill ~142~12~10 ~142~12~15 minecraft:light_block 15
fill ~143~5~10 ~144~5~16 minecraft:light_block 15
setblock ~143~6~10 minecraft:concrete 15
setblock ~143~7~10 minecraft:sea_lantern
setblock ~143~8~10 minecraft:light_block 15
fill ~143~14~10 ~143~14~16 minecraft:light_block 15
fill ~144~2~10 ~144~2~14 minecraft:light_block 15
setblock ~144~6~10 minecraft:sea_lantern
setblock ~144~7~10 minecraft:light_block 15
setblock ~144~8~10 minecraft:sea_lantern
fill ~144~15~10 ~144~15~16 minecraft:light_block 15
fill ~145~6~10 ~145~6~15 minecraft:light_block 15
setblock ~145~7~10 minecraft:sea_lantern
setblock ~145~8~10 minecraft:light_block 15
fill ~145~9~10 ~147~9~10 minecraft:wool 15
fill ~145~16~10 ~146~16~16 minecraft:light_block 15
fill ~146~7~10 ~146~7~15 minecraft:light_block 15
setblock ~146~8~10 minecraft:wool 15
fill ~147~8~10 ~147~8~16 minecraft:light_block 15
fill ~147~10~10 ~148~10~10 minecraft:wool 15
fill ~148~9~10 ~148~9~17 minecraft:light_block 15
setblock ~148~11~10 minecraft:wool 15
setblock ~148~12~10 minecraft:light_block 15
fill ~148~17~10 ~150~17~13 minecraft:light_block 15
fill ~149~10~10 ~149~10~18 minecraft:light_block 15
setblock ~149~12~10 minecraft:concrete 15
setblock ~149~13~10 minecraft:light_block 15
fill ~149~18~10 ~151~18~14 minecraft:light_block 15
setblock ~150~11~10 minecraft:concrete 15
fill ~150~12~10 ~151~12~10 minecraft:wool 15
fill ~150~13~10 ~150~13~11 minecraft:concrete 15
fill ~151~11~10 ~151~11~17 minecraft:light_block 15
fill ~151~13~10 ~152~13~10 minecraft:wool 15
fill ~151~14~10 ~151~15~10 minecraft:light_block 15
fill ~152~12~10 ~152~12~18 minecraft:light_block 15
setblock ~152~14~10 minecraft:wool 15
fill ~152~20~10 ~152~20~14 minecraft:light_block 15
fill ~153~13~10 ~153~13~18 minecraft:light_block 15
fill ~153~14~10 ~153~15~10 minecraft:concrete 15
setblock ~153~16~10 minecraft:light_block 15
fill ~153~22~10 ~153~22~16 minecraft:light_block 15
fill ~154~14~10 ~154~14~18 minecraft:light_block 15
setblock ~154~16~10 minecraft:wool 15
fill ~154~23~10 ~154~23~16 minecraft:light_block 15
fill ~155~15~10 ~156~15~16 minecraft:light_block 15
fill ~155~16~10 ~155~17~11 minecraft:concrete 15
fill ~155~24~10 ~155~24~16 minecraft:light_block 15
setblock ~156~16~10 minecraft:wool 15
setblock ~156~17~10 minecraft:light_block 15
setblock ~156~18~10 minecraft:concrete 15
fill ~156~20~10 ~158~20~10 minecraft:light_block 15
fill ~157~16~10 ~157~16~17 minecraft:light_block 15
setblock ~157~17~10 minecraft:concrete 15
setblock ~157~19~10 minecraft:light_block 15
fill ~157~25~10 ~164~26~10 minecraft:light_block 15
fill ~158~17~10 ~158~17~18 minecraft:light_block 15
setblock ~158~18~10 minecraft:wool 15
fill ~158~19~10 ~159~19~10 minecraft:concrete 15
fill ~158~21~10 ~159~21~10 minecraft:light_block 15
fill ~158~23~10 ~161~23~10 minecraft:light_block 15
fill ~158~27~10 ~166~27~10 minecraft:light_block 15
fill ~159~18~10 ~159~18~18 minecraft:light_block 15
setblock ~159~20~10 minecraft:wool 15
fill ~159~22~10 ~160~22~10 minecraft:light_block 15
fill ~160~19~10 ~161~19~16 minecraft:light_block 15
setblock ~160~21~10 minecraft:concrete 15
fill ~160~28~10 ~160~28~16 minecraft:light_block 15
setblock ~161~20~10 minecraft:wool 15
setblock ~161~21~10 minecraft:light_block 15
setblock ~161~22~10 minecraft:concrete 15
fill ~161~29~10 ~161~29~16 minecraft:light_block 15
fill ~162~20~10 ~162~20~17 minecraft:light_block 15
setblock ~162~21~10 minecraft:concrete 15
fill ~162~22~10 ~163~22~10 minecraft:wool 15
setblock ~162~23~10 minecraft:wool 15
fill ~162~30~10 ~162~30~16 minecraft:light_block 15
fill ~163~21~10 ~163~21~17 minecraft:light_block 15
fill ~163~23~10 ~163~23~11 minecraft:sea_lantern
setblock ~163~24~10 minecraft:light_block 15
fill ~164~22~10 ~164~22~18 minecraft:light_block 15
setblock ~164~23~10 minecraft:concrete 15
fill ~164~24~10 ~164~24~11 minecraft:sea_lantern
fill ~164~31~10 ~170~31~11 minecraft:light_block 15
fill ~165~23~10 ~165~23~18 minecraft:light_block 15
setblock ~165~24~10 minecraft:concrete 15
fill ~165~25~10 ~167~25~10 minecraft:wool 15
setblock ~165~26~10 minecraft:light_block 15
fill ~166~21~10 ~166~21~14 minecraft:light_block 15
setblock ~166~26~10 minecraft:concrete 15
fill ~166~32~10 ~170~32~12 minecraft:light_block 15
fill ~167~24~10 ~167~24~16 minecraft:light_block 15
setblock ~167~26~10 minecraft:light_block 15
setblock ~167~27~10 minecraft:wool 15
fill ~167~33~10 ~169~33~14 minecraft:light_block 15
fill ~168~22~10 ~168~22~14 minecraft:light_block 15
fill ~168~25~10 ~168~25~16 minecraft:light_block 15
setblock ~168~26~10 minecraft:wool 15
setblock ~168~27~10 minecraft:sea_lantern
fill ~168~30~10 ~170~30~10 minecraft:light_block 15
fill ~169~23~10 ~169~23~14 minecraft:light_block 15
fill ~169~26~10 ~170~26~16 minecraft:light_block 15
fill ~169~28~10 ~169~28~11 minecraft:sea_lantern
setblock ~169~29~10 minecraft:light_block 15
fill ~170~25~10 ~170~25~14 minecraft:light_block 15
fill ~170~27~10 ~170~27~18 minecraft:light_block 15
setblock ~170~29~10 minecraft:sea_lantern
fill ~31~29~11 ~32~30~11 minecraft:concrete 15
setblock ~33~29~11 minecraft:sea_lantern
setblock ~34~27~11 minecraft:wool 15
setblock ~34~28~11 minecraft:sea_lantern
setblock ~35~26~11 minecraft:wool 15
setblock ~35~27~11 minecraft:light_block 15
setblock ~35~28~11 minecraft:wool 15
fill ~35~29~11 ~41~29~11 minecraft:light_block 15
fill ~35~30~11 ~36~30~12 minecraft:light_block 15
fill ~36~25~11 ~36~25~19 minecraft:light_block 15
setblock ~36~27~11 minecraft:wool 15
fill ~36~28~11 ~42~28~11 minecraft:light_block 15
fill ~36~31~11 ~40~31~14 minecraft:light_block 15
fill ~37~26~11 ~37~26~12 minecraft:concrete 15
fill ~37~27~11 ~43~27~11 minecraft:light_block 15
setblock ~38~25~11 minecraft:sea_lantern
fill ~38~26~11 ~45~26~11 minecraft:light_block 15
fill ~39~20~11 ~39~22~15 minecraft:light_block 15
fill ~39~24~11 ~39~24~12 minecraft:sea_lantern
fill ~39~25~11 ~41~25~11 minecraft:light_block 15
fill ~40~18~11 ~40~18~15 minecraft:light_block 15
fill ~40~21~11 ~40~21~18 minecraft:light_block 15
setblock ~40~22~11 minecraft:wool 15
setblock ~40~23~11 minecraft:sea_lantern
setblock ~40~24~11 minecraft:light_block 15
fill ~40~30~11 ~41~30~16 minecraft:light_block 15
fill ~41~17~11 ~41~17~15 minecraft:light_block 15
fill ~41~20~11 ~42~20~17 minecraft:light_block 15
fill ~41~21~11 ~42~21~11 minecraft:wool 15
setblock ~41~22~11 minecraft:light_block 15
setblock ~41~23~11 minecraft:wool 15
fill ~42~22~11 ~42~22~12 minecraft:concrete 15
setblock ~42~23~11 minecraft:light_block 15
fill ~43~16~11 ~44~16~16 minecraft:light_block 15
fill ~43~19~11 ~43~19~18 minecraft:light_block 15
fill ~43~20~11 ~45~20~11 minecraft:concrete 15
setblock ~43~21~11 minecraft:concrete 15
fill ~43~22~11 ~51~22~11 minecraft:light_block 15
fill ~44~18~11 ~44~18~18 minecraft:light_block 15
fill ~44~19~11 ~46~19~11 minecraft:concrete 15
fill ~44~21~11 ~54~21~11 minecraft:light_block 15
fill ~45~17~11 ~45~17~18 minecraft:light_block 15
fill ~46~16~11 ~46~16~18 minecraft:light_block 15
setblock ~46~17~11 minecraft:wool 15
setblock ~46~18~11 minecraft:light_block 15
fill ~46~20~11 ~55~20~11 minecraft:light_block 15
setblock ~47~16~11 minecraft:wool 15
setblock ~47~17~11 minecraft:concrete 15
fill ~47~18~11 ~47~18~12 minecraft:wool 15
fill ~47~19~11 ~56~19~11 minecraft:light_block 15
fill ~47~25~11 ~47~25~17 minecraft:light_block 15
fill ~48~15~11 ~48~15~19 minecraft:light_block 15
setblock ~48~16~11 minecraft:concrete 15
fill ~48~17~11 ~48~17~12 minecraft:wool 15
fill ~48~24~11 ~48~24~17 minecraft:light_block 15
fill ~49~14~11 ~49~14~18 minecraft:light_block 15
setblock ~49~15~11 minecraft:concrete 15
fill ~49~16~11 ~49~16~12 minecraft:wool 15
fill ~49~17~11 ~51~17~11 minecraft:light_block 15
fill ~49~23~11 ~49~23~17 minecraft:light_block 15
fill ~50~13~11 ~50~13~18 minecraft:light_block 15
setblock ~50~14~11 minecraft:concrete 15
fill ~50~15~11 ~50~15~12 minecraft:wool 15
fill ~50~16~11 ~51~16~11 minecraft:light_block 15
fill ~51~9~11 ~51~9~15 minecraft:light_block 15
fill ~51~12~11 ~52~12~18 minecraft:light_block 15
fill ~51~13~11 ~51~14~11 minecraft:wool 15
fill ~52~8~11 ~52~8~15 minecraft:light_block 15
fill ~52~11~11 ~53~11~18 minecraft:light_block 15
fill ~52~13~11 ~53~13~11 minecraft:concrete 15
setblock ~52~14~11 minecraft:wool 15
setblock ~53~12~11 minecraft:wool 15
fill ~53~14~11 ~54~14~11 minecraft:light_block 15
fill ~54~7~11 ~56~7~15 minecraft:light_block 15
fill ~54~10~11 ~54~10~19 minecraft:light_block 15
fill ~54~11~11 ~55~11~11 minecraft:wool 15
fill ~54~12~11 ~54~12~12 minecraft:concrete 15
setblock ~54~13~11 minecraft:light_block 15
fill ~55~9~11 ~55~9~19 minecraft:light_block 15
fill ~55~10~11 ~57~10~11 minecraft:wool 15
fill ~56~8~11 ~56~8~19 minecraft:light_block 15
setblock ~56~9~11 minecraft:wool 15
setblock ~56~11~11 minecraft:light_block 15
fill ~56~17~11 ~56~18~16 minecraft:light_block 15
fill ~57~8~11 ~58~8~11 minecraft:concrete 15
setblock ~57~9~11 minecraft:light_block 15
fill ~58~7~11 ~59~7~11 minecraft:concrete 15
fill ~58~9~11 ~58~9~12 minecraft:concrete 15
fill ~58~10~11 ~60~10~11 minecraft:light_block 15
fill ~58~16~11 ~58~16~17 minecraft:light_block 15
fill ~59~6~11 ~59~6~19 minecraft:light_block 15
fill ~59~8~11 ~59~8~12 minecraft:sea_lantern
setblock ~59~9~11 minecraft:light_block 15
fill ~59~15~11 ~59~15~17 minecraft:light_block 15
fill ~60~4~11 ~61~4~18 minecraft:light_block 15
fill ~60~5~11 ~60~5~19 minecraft:light_block 15
fill ~60~7~11 ~60~7~12 minecraft:sea_lantern
fill ~60~11~11 ~64~11~14 minecraft:light_block 15
fill ~60~12~11 ~61~13~15 minecraft:light_block 15
fill ~60~14~11 ~60~14~17 minecraft:light_block 15
fill ~61~3~11 ~62~3~17 minecraft:light_block 15
fill ~61~5~11 ~61~6~11 minecraft:wool 15
fill ~61~7~11 ~69~7~11 minecraft:light_block 15
fill ~62~2~11 ~64~2~17 minecraft:light_block 15
setblock ~62~4~11 minecraft:concrete 15
setblock ~62~5~11 minecraft:light_block 15
setblock ~62~6~11 minecraft:concrete 15
fill ~63~3~11 ~64~3~11 minecraft:concrete 15
setblock ~63~4~11 minecraft:light_block 15
setblock ~63~5~11 minecraft:wool 15
fill ~63~6~11 ~70~6~11 minecraft:light_block 15
fill ~64~4~11 ~64~4~12 minecraft:concrete 15
fill ~64~5~11 ~70~5~11 minecraft:light_block 15
fill ~64~10~11 ~66~10~16 minecraft:light_block 15
fill ~65~1~11 ~65~1~19 minecraft:light_block 15
fill ~65~2~11 ~66~2~11 minecraft:concrete 15
setblock ~65~3~11 minecraft:wool 15
fill ~65~4~11 ~70~4~11 minecraft:light_block 15
fill ~66~1~11 ~67~1~11 minecraft:wool 15
fill ~66~3~11 ~70~3~11 minecraft:light_block 15
fill ~67~2~11 ~70~2~11 minecraft:light_block 15
fill ~67~9~11 ~67~9~18 minecraft:light_block 15
setblock ~68~1~11 minecraft:concrete 15
fill ~68~8~11 ~68~8~18 minecraft:light_block 15
setblock ~69~1~11 minecraft:light_block 15
fill ~132~3~11 ~136~5~11 minecraft:light_block 15
fill ~133~2~11 ~135~2~11 minecraft:light_block 15
fill ~133~6~11 ~139~6~11 minecraft:light_block 15
fill ~134~0~11 ~134~0~12 minecraft:concrete 15
setblock ~134~1~11 minecraft:wool 15
fill ~134~7~11 ~141~7~11 minecraft:light_block 15
setblock ~135~0~11 minecraft:wool 15
fill ~135~1~11 ~136~1~11 minecraft:concrete 15
fill ~135~8~11 ~142~9~11 minecraft:light_block 15
fill ~136~2~11 ~136~2~12 minecraft:concrete 15
fill ~136~10~11 ~144~10~11 minecraft:light_block 15
fill ~137~2~11 ~137~3~11 minecraft:wool 15
fill ~137~4~11 ~137~5~11 minecraft:light_block 15
fill ~138~2~11 ~139~2~18 minecraft:light_block 15
fill ~138~3~11 ~138~4~11 minecraft:concrete 15
setblock ~138~5~11 minecraft:light_block 15
fill ~139~1~11 ~139~1~13 minecraft:light_block 15
setblock ~139~3~11 minecraft:wool 15
setblock ~139~4~11 minecraft:light_block 15
setblock ~139~5~11 minecraft:concrete 15
fill ~139~11~11 ~139~11~16 minecraft:light_block 15
fill ~140~3~11 ~140~3~18 minecraft:light_block 15
setblock ~140~4~11 minecraft:wool 15
setblock ~140~5~11 minecraft:light_block 15
fill ~140~6~11 ~142~6~11 minecraft:concrete 15
fill ~141~4~11 ~141~4~18 minecraft:light_block 15
setblock ~141~5~11 minecraft:concrete 15
fill ~142~5~11 ~142~5~18 minecraft:light_block 15
fill ~142~7~11 ~142~7~12 minecraft:sea_lantern
fill ~142~13~11 ~142~13~16 minecraft:light_block 15
fill ~143~1~11 ~143~1~13 minecraft:light_block 15
fill ~143~6~11 ~144~6~16 minecraft:light_block 15
setblock ~143~7~11 minecraft:wool 15
fill ~143~8~11 ~143~8~12 minecraft:sea_lantern
setblock ~143~9~11 minecraft:light_block 15
fill ~143~15~11 ~143~15~17 minecraft:light_block 15
fill ~144~7~11 ~144~9~11 minecraft:concrete 15
fill ~144~11~11 ~146~11~11 minecraft:light_block 15
fill ~144~16~11 ~144~16~17 minecraft:light_block 15
fill ~145~7~11 ~145~7~15 minecraft:light_block 15
setblock ~145~8~11 minecraft:wool 15
setblock ~145~9~11 minecraft:light_block 15
setblock ~145~10~11 minecraft:wool 15
fill ~145~17~11 ~147~17~16 minecraft:light_block 15
fill ~146~8~11 ~146~8~16 minecraft:light_block 15
setblock ~146~9~11 minecraft:wool 15
fill ~146~10~11 ~147~10~11 minecraft:concrete 15
fill ~147~9~11 ~147~9~17 minecraft:light_block 15
fill ~147~11~11 ~148~11~11 minecraft:concrete 15
fill ~147~18~11 ~148~18~16 minecraft:light_block 15
fill ~148~10~11 ~148~10~18 minecraft:light_block 15
fill ~148~12~11 ~148~12~12 minecraft:concrete 15
fill ~148~19~11 ~151~19~15 minecraft:light_block 15
fill ~149~11~11 ~150~11~18 minecraft:light_block 15
setblock ~149~12~11 minecraft:wool 15
fill ~149~13~11 ~149~13~12 minecraft:concrete 15
fill ~150~12~11 ~151~12~18 minecraft:light_block 15
setblock ~150~14~11 minecraft:wool 15
fill ~150~15~11 ~151~15~11 minecraft:light_block 15
fill ~150~20~11 ~151~20~16 minecraft:light_block 15
fill ~151~8~11 ~154~8~12 minecraft:light_block 15
fill ~151~13~11 ~151~14~11 minecraft:concrete 15
fill ~152~13~11 ~152~13~19 minecraft:light_block 15
fill ~152~14~11 ~152~15~11 minecraft:concrete 15
fill ~152~16~11 ~152~17~11 minecraft:light_block 15
fill ~152~21~11 ~152~22~16 minecraft:light_block 15
fill ~153~9~11 ~156~9~11 minecraft:light_block 15
fill ~153~14~11 ~153~14~19 minecraft:light_block 15
fill ~153~15~11 ~153~16~11 minecraft:wool 15
setblock ~153~17~11 minecraft:light_block 15
fill ~153~23~11 ~153~23~17 minecraft:light_block 15
fill ~154~15~11 ~154~15~19 minecraft:light_block 15
fill ~154~16~11 ~154~17~11 minecraft:concrete 15
setblock ~154~18~11 minecraft:light_block 15
fill ~154~24~11 ~154~24~17 minecraft:light_block 15
fill ~155~18~11 ~155~18~13 minecraft:wool 15
setblock ~155~19~11 minecraft:light_block 15
fill ~156~16~11 ~156~16~18 minecraft:light_block 15
setblock ~156~17~11 minecraft:concrete 15
setblock ~156~18~11 minecraft:light_block 15
setblock ~156~19~11 minecraft:wool 15
setblock ~156~20~11 minecraft:light_block 15
fill ~156~25~11 ~163~26~11 minecraft:light_block 15
fill ~157~17~11 ~157~17~19 minecraft:light_block 15
fill ~157~18~11 ~157~20~11 minecraft:concrete 15
fill ~157~27~11 ~165~27~11 minecraft:light_block 15
fill ~158~18~11 ~158~18~19 minecraft:light_block 15
fill ~158~19~11 ~158~20~11 minecraft:concrete 15
setblock ~158~21~11 minecraft:light_block 15
fill ~158~23~11 ~160~23~11 minecraft:light_block 15
fill ~158~28~11 ~159~28~17 minecraft:light_block 15
fill ~159~19~11 ~159~19~19 minecraft:light_block 15
setblock ~159~20~11 minecraft:concrete 15
fill ~159~21~11 ~160~21~11 minecraft:wool 15
setblock ~159~22~11 minecraft:light_block 15
fill ~160~20~11 ~161~20~17 minecraft:light_block 15
setblock ~160~22~11 minecraft:concrete 15
fill ~160~29~11 ~160~29~17 minecraft:light_block 15
setblock ~161~21~11 minecraft:concrete 15
setblock ~161~22~11 minecraft:light_block 15
setblock ~161~23~11 minecraft:wool 15
fill ~162~21~11 ~162~21~18 minecraft:light_block 15
setblock ~162~22~11 minecraft:concrete 15
setblock ~162~23~11 minecraft:sea_lantern
fill ~163~22~11 ~163~22~18 minecraft:light_block 15
fill ~163~24~11 ~163~24~12 minecraft:sea_lantern
fill ~163~31~11 ~163~31~17 minecraft:light_block 15
fill ~164~23~11 ~164~23~19 minecraft:light_block 15
setblock ~164~25~11 minecraft:sea_lantern
setblock ~164~26~11 minecraft:light_block 15
fill ~165~24~11 ~166~24~17 minecraft:light_block 15
fill ~165~25~11 ~165~26~11 minecraft:concrete 15
fill ~165~32~11 ~165~33~16 minecraft:light_block 15
fill ~166~25~11 ~167~25~17 minecraft:light_block 15
fill ~166~26~11 ~166~27~11 minecraft:wool 15
fill ~166~33~11 ~166~34~16 minecraft:light_block 15
fill ~167~21~11 ~167~21~13 minecraft:light_block 15
setblock ~167~26~11 minecraft:concrete 15
setblock ~167~27~11 minecraft:light_block 15
setblock ~167~28~11 minecraft:concrete 15
fill ~167~34~11 ~170~34~14 minecraft:light_block 15
fill ~168~26~11 ~168~26~17 minecraft:light_block 15
setblock ~168~27~11 minecraft:concrete 15
setblock ~168~28~11 minecraft:sea_lantern
fill ~168~30~11 ~169~30~11 minecraft:light_block 15
fill ~169~27~11 ~169~27~18 minecraft:light_block 15
setblock ~169~29~11 minecraft:sea_lantern
fill ~170~24~11 ~170~24~13 minecraft:light_block 15
fill ~170~28~11 ~170~28~19 minecraft:light_block 15
fill ~170~29~11 ~171~29~11 minecraft:wool 15
fill ~170~30~11 ~170~30~12 minecraft:wool 15
fill ~170~33~11 ~171~33~12 minecraft:light_block 15
setblock ~171~30~11 minecraft:concrete 15
fill ~171~31~11 ~171~32~11 minecraft:light_block 15
fill ~30~32~12 ~31~32~12 minecraft:concrete 15
fill ~31~30~12 ~32~30~12 minecraft:concrete 15
setblock ~31~31~12 minecraft:wool 15
fill ~32~31~12 ~32~31~13 minecraft:concrete 15
fill ~32~32~12 ~40~32~12 minecraft:light_block 15
fill ~32~33~12 ~37~33~13 minecraft:light_block 15
fill ~32~34~12 ~36~34~14 minecraft:light_block 15
fill ~33~29~12 ~34~29~12 minecraft:concrete 15
setblock ~33~30~12 minecraft:wool 15
fill ~33~31~12 ~35~31~12 minecraft:light_block 15
fill ~33~35~12 ~35~35~16 minecraft:light_block 15
fill ~34~26~12 ~36~26~18 minecraft:light_block 15
fill ~34~27~12 ~34~27~19 minecraft:light_block 15
setblock ~34~28~12 minecraft:wool 15
setblock ~34~30~12 minecraft:light_block 15
fill ~35~25~12 ~35~25~18 minecraft:light_block 15
fill ~35~27~12 ~37~27~12 minecraft:concrete 15
setblock ~35~28~12 minecraft:light_block 15
setblock ~35~29~12 minecraft:wool 15
fill ~36~24~12 ~38~24~18 minecraft:light_block 15
fill ~36~28~12 ~36~28~13 minecraft:concrete 15
fill ~36~29~12 ~43~29~12 minecraft:light_block 15
fill ~37~25~12 ~37~25~20 minecraft:light_block 15
fill ~37~28~12 ~44~28~12 minecraft:light_block 15
setblock ~38~25~12 minecraft:concrete 15
setblock ~38~26~12 minecraft:wool 15
fill ~38~27~12 ~44~27~12 minecraft:light_block 15
fill ~39~19~12 ~39~19~14 minecraft:light_block 15
fill ~39~23~12 ~39~23~20 minecraft:light_block 15
setblock ~39~25~12 minecraft:sea_lantern
fill ~39~26~12 ~46~26~12 minecraft:light_block 15
fill ~40~22~12 ~40~22~19 minecraft:light_block 15
setblock ~40~23~12 minecraft:concrete 15
setblock ~40~24~12 minecraft:sea_lantern
setblock ~40~25~12 minecraft:wool 15
fill ~41~21~12 ~42~21~18 minecraft:light_block 15
setblock ~41~22~12 minecraft:wool 15
setblock ~41~23~12 minecraft:light_block 15
fill ~41~24~12 ~41~24~13 minecraft:concrete 15
setblock ~41~25~12 minecraft:light_block 15
fill ~41~31~12 ~41~31~18 minecraft:light_block 15
fill ~42~16~12 ~42~16~14 minecraft:light_block 15
setblock ~42~23~12 minecraft:wool 15
fill ~42~30~12 ~42~30~18 minecraft:light_block 15
fill ~43~20~12 ~43~20~18 minecraft:light_block 15
fill ~43~21~12 ~43~22~12 minecraft:wool 15
fill ~44~19~12 ~44~19~19 minecraft:light_block 15
fill ~44~20~12 ~46~20~12 minecraft:concrete 15
setblock ~44~21~12 minecraft:concrete 15
fill ~44~22~12 ~53~22~12 minecraft:light_block 15
fill ~45~18~12 ~45~18~19 minecraft:light_block 15
setblock ~45~19~12 minecraft:wool 15
fill ~45~21~12 ~55~21~12 minecraft:light_block 15
fill ~46~17~12 ~47~17~19 minecraft:light_block 15
setblock ~46~18~12 minecraft:wool 15
setblock ~46~19~12 minecraft:light_block 15
fill ~47~16~12 ~48~16~19 minecraft:light_block 15
setblock ~47~19~12 minecraft:concrete 15
fill ~47~20~12 ~56~20~12 minecraft:light_block 15
fill ~48~18~12 ~48~18~13 minecraft:concrete 15
fill ~48~19~12 ~56~19~12 minecraft:light_block 15
fill ~49~15~12 ~49~15~19 minecraft:light_block 15
fill ~49~17~12 ~49~17~13 minecraft:wool 15
fill ~49~18~12 ~50~18~12 minecraft:light_block 15
fill ~49~24~12 ~49~24~18 minecraft:light_block 15
fill ~50~14~12 ~50~14~18 minecraft:light_block 15
setblock ~50~16~12 minecraft:concrete 15
fill ~50~17~12 ~51~17~12 minecraft:light_block 15
fill ~50~23~12 ~51~23~18 minecraft:light_block 15
fill ~51~13~12 ~51~13~19 minecraft:light_block 15
fill ~51~14~12 ~51~15~12 minecraft:concrete 15
setblock ~51~16~12 minecraft:wool 15
fill ~52~13~12 ~54~13~12 minecraft:wool 15
setblock ~52~14~12 minecraft:light_block 15
setblock ~52~15~12 minecraft:sea_lantern
fill ~53~7~12 ~53~7~14 minecraft:light_block 15
fill ~53~12~12 ~53~12~20 minecraft:light_block 15
fill ~53~14~12 ~53~14~13 minecraft:sea_lantern
fill ~54~11~12 ~54~11~19 minecraft:light_block 15
setblock ~54~14~12 minecraft:light_block 15
fill ~55~10~12 ~55~10~20 minecraft:light_block 15
fill ~55~11~12 ~56~11~12 minecraft:concrete 15
setblock ~55~12~12 minecraft:concrete 15
fill ~55~13~12 ~57~13~12 minecraft:light_block 15
fill ~56~9~12 ~56~9~20 minecraft:light_block 15
setblock ~56~10~12 minecraft:wool 15
fill ~56~12~12 ~57~12~12 minecraft:light_block 15
fill ~57~7~12 ~59~7~18 minecraft:light_block 15
fill ~57~8~12 ~58~8~19 minecraft:light_block 15
setblock ~57~9~12 minecraft:concrete 15
setblock ~57~10~12 minecraft:light_block 15
setblock ~57~11~12 minecraft:wool 15
fill ~57~17~12 ~58~17~17 minecraft:light_block 15
fill ~57~18~12 ~57~18~18 minecraft:light_block 15
fill ~58~6~12 ~58~6~18 minecraft:light_block 15
setblock ~58~10~12 minecraft:wool 15
fill ~59~5~12 ~59~5~18 minecraft:light_block 15
setblock ~59~9~12 minecraft:sea_lantern
fill ~59~10~12 ~60~10~12 minecraft:light_block 15
fill ~59~16~12 ~59~16~18 minecraft:light_block 15
fill ~60~3~12 ~60~3~16 minecraft:light_block 15
fill ~60~6~12 ~60~6~19 minecraft:light_block 15
fill ~60~8~12 ~60~8~13 minecraft:sea_lantern
fill ~60~9~12 ~62~9~12 minecraft:light_block 15
fill ~60~15~12 ~61~15~18 minecraft:light_block 15
fill ~61~2~12 ~61~2~16 minecraft:light_block 15
fill ~61~5~12 ~61~5~19 minecraft:light_block 15
setblock ~61~6~12 minecraft:wool 15
setblock ~61~7~12 minecraft:sea_lantern
fill ~61~8~12 ~62~8~12 minecraft:light_block 15
fill ~61~14~12 ~62~14~18 minecraft:light_block 15
fill ~62~4~12 ~62~4~19 minecraft:light_block 15
fill ~62~5~12 ~64~5~12 minecraft:concrete 15
setblock ~62~6~12 minecraft:light_block 15
fill ~62~7~12 ~62~7~13 minecraft:concrete 15
fill ~62~12~12 ~64~12~16 minecraft:light_block 15
fill ~62~13~12 ~62~13~17 minecraft:light_block 15
fill ~63~1~12 ~64~1~17 minecraft:light_block 15
fill ~63~3~12 ~64~3~19 minecraft:light_block 15
setblock ~63~4~12 minecraft:concrete 15
setblock ~63~6~12 minecraft:concrete 15
fill ~63~7~12 ~70~7~12 minecraft:light_block 15
fill ~64~6~12 ~71~6~12 minecraft:light_block 15
fill ~65~0~12 ~67~0~18 minecraft:light_block 15
fill ~65~2~12 ~65~2~20 minecraft:light_block 15
setblock ~65~3~12 minecraft:concrete 15
setblock ~65~4~12 minecraft:wool 15
fill ~65~5~12 ~71~5~12 minecraft:light_block 15
fill ~65~11~12 ~65~11~18 minecraft:light_block 15
fill ~66~1~12 ~66~1~19 minecraft:light_block 15
fill ~66~2~12 ~66~3~12 minecraft:wool 15
fill ~66~4~12 ~71~4~12 minecraft:light_block 15
setblock ~67~1~12 minecraft:wool 15
setblock ~67~2~12 minecraft:concrete 15
fill ~67~3~12 ~71~3~12 minecraft:light_block 15
fill ~67~10~12 ~67~10~19 minecraft:light_block 15
fill ~68~0~12 ~69~0~12 minecraft:concrete 15
setblock ~68~1~12 minecraft:light_block 15
setblock ~68~2~12 minecraft:sea_lantern
fill ~68~9~12 ~68~9~19 minecraft:light_block 15
setblock ~69~1~12 minecraft:concrete 15
fill ~69~2~12 ~71~2~12 minecraft:light_block 15
fill ~69~8~12 ~69~8~18 minecraft:light_block 15
setblock ~70~1~12 minecraft:light_block 15
fill ~130~3~12 ~135~5~12 minecraft:light_block 15
fill ~131~2~12 ~133~2~12 minecraft:light_block 15
fill ~131~6~12 ~138~6~12 minecraft:light_block 15
setblock ~132~1~12 minecraft:light_block 15
fill ~132~7~12 ~139~7~12 minecraft:light_block 15
fill ~133~0~12 ~133~1~12 minecraft:wool 15
fill ~133~8~12 ~141~8~12 minecraft:light_block 15
setblock ~134~1~12 minecraft:light_block 15
setblock ~134~2~12 minecraft:sea_lantern
fill ~134~9~12 ~142~9~12 minecraft:light_block 15
setblock ~135~1~12 minecraft:concrete 15
setblock ~135~2~12 minecraft:wool 15
fill ~135~10~12 ~143~10~12 minecraft:light_block 15
fill ~136~1~12 ~136~1~20 minecraft:light_block 15
setblock ~136~3~12 minecraft:concrete 15
fill ~136~4~12 ~136~5~12 minecraft:light_block 15
fill ~136~11~12 ~138~11~17 minecraft:light_block 15
fill ~137~2~12 ~137~2~20 minecraft:light_block 15
fill ~137~3~12 ~137~4~12 minecraft:wool 15
setblock ~137~5~12 minecraft:light_block 15
fill ~138~3~12 ~139~3~19 minecraft:light_block 15
setblock ~138~4~12 minecraft:wool 15
setblock ~138~5~12 minecraft:concrete 15
setblock ~139~4~12 minecraft:concrete 15
fill ~139~5~12 ~140~5~12 minecraft:wool 15
fill ~139~6~12 ~139~6~13 minecraft:concrete 15
fill ~139~12~12 ~141~12~16 minecraft:light_block 15
fill ~140~4~12 ~140~4~19 minecraft:light_block 15
setblock ~140~6~12 minecraft:light_block 15
setblock ~140~7~12 minecraft:wool 15
fill ~141~5~12 ~141~5~19 minecraft:light_block 15
setblock ~141~6~12 minecraft:wool 15
setblock ~141~7~12 minecraft:sea_lantern
fill ~141~13~12 ~141~14~17 minecraft:light_block 15
fill ~142~6~12 ~142~6~20 minecraft:light_block 15
fill ~142~8~12 ~142~8~13 minecraft:sea_lantern
fill ~142~14~12 ~142~15~17 minecraft:light_block 15
fill ~143~7~12 ~144~7~19 minecraft:light_block 15
setblock ~143~9~12 minecraft:sea_lantern
fill ~143~16~12 ~143~16~18 minecraft:light_block 15
fill ~144~8~12 ~145~8~18 minecraft:light_block 15
fill ~144~9~12 ~144~10~12 minecraft:wool 15
setblock ~144~11~12 minecraft:light_block 15
fill ~144~17~12 ~144~17~18 minecraft:light_block 15
setblock ~145~9~12 minecraft:concrete 15
setblock ~145~10~12 minecraft:light_block 15
fill ~145~11~12 ~147~11~12 minecraft:wool 15
fill ~145~18~12 ~146~18~17 minecraft:light_block 15
fill ~146~9~12 ~146~9~19 minecraft:light_block 15
setblock ~146~10~12 minecraft:concrete 15
setblock ~146~12~12 minecraft:light_block 15
fill ~146~19~12 ~147~19~18 minecraft:light_block 15
fill ~147~10~12 ~147~10~19 minecraft:light_block 15
setblock ~147~12~12 minecraft:wool 15
setblock ~147~13~12 minecraft:light_block 15
fill ~148~11~12 ~148~11~19 minecraft:light_block 15
setblock ~148~13~12 minecraft:concrete 15
setblock ~148~14~12 minecraft:light_block 15
fill ~148~20~12 ~149~20~17 minecraft:light_block 15
fill ~149~12~12 ~149~12~19 minecraft:light_block 15
fill ~149~14~12 ~149~14~13 minecraft:sea_lantern
fill ~149~21~12 ~151~21~16 minecraft:light_block 15
setblock ~150~13~12 minecraft:wool 15
setblock ~150~14~12 minecraft:light_block 15
setblock ~150~15~12 minecraft:sea_lantern
fill ~151~13~12 ~151~13~19 minecraft:light_block 15
setblock ~151~14~12 minecraft:concrete 15
fill ~151~15~12 ~152~15~12 minecraft:wool 15
fill ~151~16~12 ~152~16~12 minecraft:concrete 15
fill ~152~14~12 ~152~14~19 minecraft:light_block 15
setblock ~152~17~12 minecraft:light_block 15
fill ~152~23~12 ~152~23~18 minecraft:light_block 15
fill ~153~9~12 ~154~9~13 minecraft:light_block 15
fill ~153~15~12 ~153~15~20 minecraft:light_block 15
setblock ~153~16~12 minecraft:wool 15
setblock ~153~17~12 minecraft:concrete 15
fill ~153~24~12 ~153~24~18 minecraft:light_block 15
fill ~154~16~12 ~155~16~19 minecraft:light_block 15
fill ~154~17~12 ~154~18~12 minecraft:wool 15
fill ~155~17~12 ~156~17~19 minecraft:light_block 15
setblock ~155~19~12 minecraft:concrete 15
fill ~155~25~12 ~161~25~12 minecraft:light_block 15
setblock ~156~18~12 minecraft:wool 15
setblock ~156~19~12 minecraft:light_block 15
setblock ~156~20~12 minecraft:wool 15
fill ~156~26~12 ~163~27~12 minecraft:light_block 15
fill ~157~18~12 ~157~18~20 minecraft:light_block 15
fill ~157~19~12 ~157~20~12 minecraft:concrete 15
fill ~157~28~12 ~157~28~19 minecraft:light_block 15
fill ~158~19~12 ~158~19~20 minecraft:light_block 15
setblock ~158~20~12 minecraft:concrete 15
fill ~158~21~12 ~159~21~12 minecraft:wool 15
fill ~158~23~12 ~159~24~12 minecraft:light_block 15
fill ~159~20~12 ~159~20~20 minecraft:light_block 15
fill ~159~22~12 ~161~22~12 minecraft:wool 15
fill ~159~29~12 ~159~29~18 minecraft:light_block 15
fill ~160~21~12 ~161~21~19 minecraft:light_block 15
fill ~160~23~12 ~160~23~13 minecraft:wool 15
setblock ~160~24~12 minecraft:light_block 15
setblock ~161~23~12 minecraft:light_block 15
setblock ~161~24~12 minecraft:wool 15
fill ~161~30~12 ~161~30~18 minecraft:light_block 15
fill ~162~22~12 ~162~22~19 minecraft:light_block 15
setblock ~162~23~12 minecraft:concrete 15
setblock ~162~24~12 minecraft:sea_lantern
setblock ~162~25~12 minecraft:concrete 15
fill ~163~23~12 ~163~23~20 minecraft:light_block 15
setblock ~163~25~12 minecraft:sea_lantern
fill ~163~29~12 ~166~29~12 minecraft:light_block 15
fill ~164~24~12 ~164~24~20 minecraft:light_block 15
setblock ~164~25~12 minecraft:concrete 15
setblock ~164~26~12 minecraft:wool 15
fill ~164~27~12 ~164~28~12 minecraft:light_block 15
fill ~164~31~12 ~169~31~12 minecraft:light_block 15
fill ~164~32~12 ~164~33~17 minecraft:light_block 15
fill ~165~25~12 ~165~25~20 minecraft:light_block 15
fill ~165~26~12 ~165~27~12 minecraft:concrete 15
setblock ~165~28~12 minecraft:light_block 15
fill ~165~34~12 ~165~34~18 minecraft:light_block 15
fill ~166~26~12 ~167~26~17 minecraft:light_block 15
fill ~166~27~12 ~167~27~12 minecraft:wool 15
fill ~166~28~12 ~166~28~14 minecraft:wool 15
fill ~166~35~12 ~170~35~15 minecraft:light_block 15
setblock ~167~28~12 minecraft:light_block 15
fill ~167~29~12 ~168~29~12 minecraft:concrete 15
fill ~168~27~12 ~168~27~19 minecraft:light_block 15
setblock ~168~28~12 minecraft:wool 15
setblock ~168~30~12 minecraft:light_block 15
fill ~169~28~12 ~169~28~20 minecraft:light_block 15
setblock ~169~29~12 minecraft:wool 15
fill ~169~30~12 ~169~30~13 minecraft:concrete 15
fill ~170~29~12 ~172~29~18 minecraft:light_block 15
fill ~170~31~12 ~170~31~13 minecraft:concrete 15
fill ~171~28~12 ~171~28~18 minecraft:light_block 15
fill ~171~30~12 ~171~31~12 minecraft:wool 15
fill ~171~32~12 ~172~32~12 minecraft:concrete 15
fill ~171~34~12 ~171~34~13 minecraft:light_block 15
fill ~172~30~12 ~172~31~18 minecraft:light_block 15
setblock ~172~33~12 minecraft:light_block 15
setblock ~30~32~13 minecraft:wool 15
fill ~30~33~13 ~31~33~13 minecraft:concrete 15
fill ~30~34~13 ~30~34~15 minecraft:wool 15
fill ~31~31~13 ~31~31~21 minecraft:light_block 15
fill ~31~32~13 ~32~32~13 minecraft:concrete 15
fill ~31~34~13 ~31~35~13 minecraft:light_block 15
fill ~32~30~13 ~32~30~21 minecraft:light_block 15
fill ~32~35~13 ~32~36~15 minecraft:light_block 15
fill ~33~27~13 ~33~29~18 minecraft:light_block 15
fill ~33~30~13 ~35~30~13 minecraft:concrete 15
setblock ~33~31~13 minecraft:wool 15
fill ~33~32~13 ~41~32~13 minecraft:light_block 15
fill ~33~36~13 ~36~36~17 minecraft:light_block 15
fill ~34~25~13 ~34~25~17 minecraft:light_block 15
fill ~34~28~13 ~34~28~20 minecraft:light_block 15
setblock ~34~29~13 minecraft:concrete 15
fill ~34~31~13 ~35~31~13 minecraft:light_block 15
fill ~35~24~13 ~35~24~17 minecraft:light_block 15
fill ~35~27~13 ~36~27~20 minecraft:light_block 15
setblock ~35~28~13 minecraft:concrete 15
setblock ~35~29~13 minecraft:light_block 15
setblock ~36~29~13 minecraft:wool 15
setblock ~36~30~13 minecraft:light_block 15
fill ~36~35~13 ~37~35~18 minecraft:light_block 15
fill ~37~23~13 ~38~23~18 minecraft:light_block 15
fill ~37~26~13 ~37~26~21 minecraft:light_block 15
setblock ~37~27~13 minecraft:wool 15
setblock ~37~28~13 minecraft:concrete 15
fill ~37~29~13 ~44~29~13 minecraft:light_block 15
fill ~37~34~13 ~38~34~18 minecraft:light_block 15
fill ~38~25~13 ~38~25~20 minecraft:light_block 15
fill ~38~26~13 ~39~26~13 minecraft:concrete 15
fill ~38~27~13 ~38~27~14 minecraft:concrete 15
fill ~38~28~13 ~45~28~13 minecraft:light_block 15
fill ~38~33~13 ~39~33~18 minecraft:light_block 15
fill ~39~24~13 ~39~24~20 minecraft:light_block 15
setblock ~39~25~13 minecraft:concrete 15
fill ~39~27~13 ~45~27~13 minecraft:light_block 15
fill ~40~23~13 ~40~23~20 minecraft:light_block 15
setblock ~40~24~13 minecraft:concrete 15
setblock ~40~25~13 minecraft:light_block 15
setblock ~40~26~13 minecraft:wool 15
fill ~41~22~13 ~42~22~19 minecraft:light_block 15
fill ~41~23~13 ~42~23~13 minecraft:concrete 15
fill ~41~25~13 ~41~25~15 minecraft:wool 15
fill ~41~26~13 ~46~26~13 minecraft:light_block 15
fill ~42~24~13 ~42~24~14 minecraft:concrete 15
fill ~42~31~13 ~42~31~19 minecraft:light_block 15
fill ~43~21~13 ~43~21~18 minecraft:light_block 15
setblock ~43~22~13 minecraft:concrete 15
setblock ~43~23~13 minecraft:wool 15
fill ~43~24~13 ~46~24~13 minecraft:light_block 15
fill ~43~30~13 ~43~30~19 minecraft:light_block 15
fill ~44~15~13 ~44~15~15 minecraft:light_block 15
fill ~44~20~13 ~44~20~19 minecraft:light_block 15
fill ~44~21~13 ~44~22~13 minecraft:wool 15
fill ~44~23~13 ~45~23~13 minecraft:light_block 15
fill ~45~19~13 ~45~19~19 minecraft:light_block 15
setblock ~45~20~13 minecraft:concrete 15
fill ~45~21~13 ~45~21~14 minecraft:sea_lantern
fill ~45~22~13 ~54~22~13 minecraft:light_block 15
fill ~46~18~13 ~46~18~20 minecraft:light_block 15
setblock ~46~19~13 minecraft:concrete 15
fill ~46~20~13 ~46~20~14 minecraft:sea_lantern
fill ~46~21~13 ~55~21~13 minecraft:light_block 15
fill ~47~10~13 ~48~10~13 minecraft:light_block 15
setblock ~47~18~13 minecraft:concrete 15
setblock ~47~19~13 minecraft:light_block 15
setblock ~47~20~13 minecraft:wool 15
fill ~48~17~13 ~48~17~21 minecraft:light_block 15
setblock ~48~19~13 minecraft:concrete 15
fill ~48~20~13 ~56~20~13 minecraft:light_block 15
fill ~48~25~13 ~48~25~18 minecraft:light_block 15
fill ~49~16~13 ~49~16~20 minecraft:light_block 15
fill ~49~18~13 ~49~18~14 minecraft:wool 15
fill ~49~19~13 ~57~19~13 minecraft:light_block 15
fill ~50~15~13 ~50~15~19 minecraft:light_block 15
fill ~50~16~13 ~50~17~13 minecraft:wool 15
setblock ~50~18~13 minecraft:light_block 15
fill ~50~24~13 ~50~24~19 minecraft:light_block 15
fill ~51~14~13 ~51~14~20 minecraft:light_block 15
setblock ~51~15~13 minecraft:concrete 15
setblock ~51~16~13 minecraft:light_block 15
setblock ~51~17~13 minecraft:wool 15
fill ~52~13~13 ~53~13~20 minecraft:light_block 15
setblock ~52~14~13 minecraft:sea_lantern
setblock ~52~15~13 minecraft:light_block 15
setblock ~52~16~13 minecraft:sea_lantern
fill ~52~23~13 ~52~23~19 minecraft:light_block 15
fill ~53~15~13 ~53~15~14 minecraft:sea_lantern
fill ~54~12~13 ~54~12~20 minecraft:light_block 15
setblock ~54~13~13 minecraft:wool 15
setblock ~54~14~13 minecraft:sea_lantern
fill ~55~11~13 ~55~11~20 minecraft:light_block 15
setblock ~55~12~13 minecraft:wool 15
fill ~55~13~13 ~56~13~14 minecraft:concrete 15
fill ~56~10~13 ~56~10~20 minecraft:light_block 15
setblock ~56~11~13 minecraft:wool 15
fill ~56~12~13 ~57~12~13 minecraft:concrete 15
fill ~57~9~13 ~58~9~20 minecraft:light_block 15
fill ~57~10~13 ~59~10~13 minecraft:concrete 15
setblock ~57~11~13 minecraft:light_block 15
fill ~57~13~13 ~58~13~14 minecraft:light_block 15
fill ~58~5~13 ~58~5~17 minecraft:light_block 15
setblock ~58~11~13 minecraft:concrete 15
setblock ~58~12~13 minecraft:light_block 15
fill ~58~18~13 ~58~18~19 minecraft:light_block 15
fill ~59~4~13 ~59~4~17 minecraft:light_block 15
fill ~59~8~13 ~59~8~19 minecraft:light_block 15
setblock ~59~9~13 minecraft:concrete 15
fill ~59~17~13 ~59~17~19 minecraft:light_block 15
fill ~60~7~13 ~60~7~20 minecraft:light_block 15
setblock ~60~9~13 minecraft:sea_lantern
setblock ~60~10~13 minecraft:light_block 15
fill ~60~16~13 ~61~16~19 minecraft:light_block 15
fill ~61~6~13 ~61~6~20 minecraft:light_block 15
setblock ~61~7~13 minecraft:wool 15
setblock ~61~8~13 minecraft:sea_lantern
fill ~61~9~13 ~62~9~13 minecraft:light_block 15
fill ~62~1~13 ~62~1~15 minecraft:light_block 15
fill ~62~5~13 ~63~5~19 minecraft:light_block 15
setblock ~62~6~13 minecraft:concrete 15
setblock ~62~8~13 minecraft:light_block 15
fill ~62~15~13 ~62~15~19 minecraft:light_block 15
fill ~63~4~13 ~64~4~19 minecraft:light_block 15
fill ~63~6~13 ~63~7~13 minecraft:wool 15
fill ~63~13~13 ~63~14~18 minecraft:light_block 15
fill ~64~0~13 ~64~0~17 minecraft:light_block 15
fill ~64~5~13 ~64~6~13 minecraft:concrete 15
fill ~64~7~13 ~71~7~13 minecraft:light_block 15
fill ~65~3~13 ~65~3~21 minecraft:light_block 15
setblock ~65~4~13 minecraft:concrete 15
setblock ~65~5~13 minecraft:wool 15
fill ~65~6~13 ~71~6~13 minecraft:light_block 15
fill ~65~12~13 ~65~12~19 minecraft:light_block 15
fill ~66~2~13 ~66~2~21 minecraft:light_block 15
setblock ~66~3~13 minecraft:concrete 15
fill ~66~4~13 ~66~4~14 minecraft:wool 15
fill ~66~5~13 ~72~5~13 minecraft:light_block 15
fill ~66~11~13 ~66~11~19 minecraft:light_block 15
fill ~67~1~13 ~67~1~20 minecraft:light_block 15
fill ~67~2~13 ~67~3~13 minecraft:sea_lantern
fill ~67~4~13 ~72~4~13 minecraft:light_block 15
fill ~68~0~13 ~68~0~18 minecraft:light_block 15
setblock ~68~1~13 minecraft:concrete 15
setblock ~68~2~13 minecraft:light_block 15
setblock ~68~3~13 minecraft:sea_lantern
fill ~68~10~13 ~68~10~19 minecraft:light_block 15
setblock ~69~0~13 minecraft:concrete 15
setblock ~69~1~13 minecraft:light_block 15
setblock ~69~2~13 minecraft:sea_lantern
fill ~69~3~13 ~72~3~13 minecraft:light_block 15
fill ~69~9~13 ~69~9~19 minecraft:light_block 15
fill ~70~0~13 ~70~0~17 minecraft:light_block 15
fill ~70~1~13 ~70~1~14 minecraft:wool 15
fill ~70~2~13 ~71~2~13 minecraft:light_block 15
fill ~70~8~13 ~70~8~19 minecraft:light_block 15
setblock ~71~1~13 minecraft:light_block 15
fill ~129~2~13 ~132~6~13 minecraft:light_block 15
fill ~130~1~13 ~131~1~13 minecraft:light_block 15
fill ~130~7~13 ~138~7~13 minecraft:light_block 15
fill ~132~0~13 ~132~0~20 minecraft:light_block 15
fill ~132~1~13 ~132~1~14 minecraft:wool 15
fill ~132~8~13 ~140~8~13 minecraft:light_block 15
setblock ~133~0~13 minecraft:concrete 15
setblock ~133~1~13 minecraft:light_block 15
setblock ~133~2~13 minecraft:sea_lantern
fill ~133~3~13 ~133~6~13 minecraft:light_block 15
fill ~133~9~13 ~141~9~13 minecraft:light_block 15
fill ~134~0~13 ~136~0~19 minecraft:light_block 15
setblock ~134~1~13 minecraft:wool 15
setblock ~134~2~13 minecraft:light_block 15
fill ~134~3~13 ~135~3~13 minecraft:sea_lantern
fill ~134~4~13 ~135~6~13 minecraft:light_block 15
fill ~134~10~13 ~142~10~13 minecraft:light_block 15
fill ~135~1~13 ~135~1~20 minecraft:light_block 15
setblock ~135~2~13 minecraft:sea_lantern
fill ~135~11~13 ~135~11~20 minecraft:light_block 15
fill ~136~2~13 ~136~2~20 minecraft:light_block 15
fill ~136~3~13 ~136~4~13 minecraft:wool 15
fill ~136~5~13 ~136~6~13 minecraft:light_block 15
fill ~137~1~13 ~137~1~19 minecraft:light_block 15
fill ~137~3~13 ~137~3~20 minecraft:light_block 15
fill ~137~4~13 ~137~5~13 minecraft:wool 15
setblock ~137~6~13 minecraft:light_block 15
fill ~137~12~13 ~138~12~18 minecraft:light_block 15
fill ~138~4~13 ~139~4~20 minecraft:light_block 15
setblock ~138~5~13 minecraft:wool 15
setblock ~138~6~13 minecraft:concrete 15
fill ~138~13~13 ~140~13~17 minecraft:light_block 15
fill ~139~5~13 ~140~5~20 minecraft:light_block 15
fill ~139~7~13 ~140~7~13 minecraft:concrete 15
setblock ~140~6~13 minecraft:concrete 15
fill ~140~14~13 ~140~15~19 minecraft:light_block 15
fill ~141~6~13 ~141~6~20 minecraft:light_block 15
setblock ~141~7~13 minecraft:wool 15
setblock ~141~8~13 minecraft:sea_lantern
fill ~141~15~13 ~141~16~19 minecraft:light_block 15
fill ~142~7~13 ~142~7~21 minecraft:light_block 15
setblock ~142~9~13 minecraft:sea_lantern
fill ~142~16~13 ~142~16~19 minecraft:light_block 15
fill ~143~8~13 ~143~8~21 minecraft:light_block 15
setblock ~143~9~13 minecraft:concrete 15
fill ~143~10~13 ~144~10~13 minecraft:wool 15
fill ~144~9~13 ~145~9~20 minecraft:light_block 15
setblock ~144~11~13 minecraft:concrete 15
setblock ~144~12~13 minecraft:light_block 15
fill ~144~18~13 ~144~18~19 minecraft:light_block 15
fill ~145~3~13 ~145~3~14 minecraft:light_block 15
setblock ~145~10~13 minecraft:concrete 15
setblock ~145~11~13 minecraft:light_block 15
fill ~145~12~13 ~146~12~13 minecraft:wool 15
fill ~145~13~13 ~145~13~14 minecraft:light_block 15
fill ~145~19~13 ~145~19~19 minecraft:light_block 15
fill ~146~10~13 ~146~10~20 minecraft:light_block 15
setblock ~146~11~13 minecraft:wool 15
fill ~146~13~13 ~147~13~13 minecraft:concrete 15
fill ~146~20~13 ~147~20~19 minecraft:light_block 15
fill ~147~11~13 ~147~11~21 minecraft:light_block 15
setblock ~147~12~13 minecraft:concrete 15
fill ~148~12~13 ~148~12~21 minecraft:light_block 15
setblock ~148~13~13 minecraft:wool 15
setblock ~148~14~13 minecraft:sea_lantern
setblock ~148~15~13 minecraft:light_block 15
fill ~148~21~13 ~148~21~19 minecraft:light_block 15
fill ~149~13~13 ~150~13~20 minecraft:light_block 15
fill ~149~15~13 ~149~15~14 minecraft:sea_lantern
fill ~149~22~13 ~151~22~17 minecraft:light_block 15
setblock ~150~14~13 minecraft:sea_lantern
setblock ~150~15~13 minecraft:light_block 15
setblock ~150~16~13 minecraft:sea_lantern
fill ~151~8~13 ~153~8~13 minecraft:light_block 15
fill ~151~14~13 ~151~14~20 minecraft:light_block 15
setblock ~151~15~13 minecraft:wool 15
setblock ~151~16~13 minecraft:light_block 15
fill ~151~17~13 ~152~17~14 minecraft:concrete 15
fill ~151~23~13 ~151~23~19 minecraft:light_block 15
fill ~152~15~13 ~152~15~20 minecraft:light_block 15
setblock ~152~16~13 minecraft:wool 15
fill ~152~24~13 ~152~24~19 minecraft:light_block 15
fill ~153~16~13 ~153~16~20 minecraft:light_block 15
fill ~153~17~13 ~153~18~13 minecraft:wool 15
fill ~153~25~13 ~160~25~13 minecraft:light_block 15
setblock ~154~10~13 minecraft:light_block 15
fill ~154~17~13 ~154~17~20 minecraft:light_block 15
setblock ~154~18~13 minecraft:wool 15
fill ~154~19~13 ~154~19~14 minecraft:concrete 15
fill ~154~26~13 ~161~26~13 minecraft:light_block 15
setblock ~155~19~13 minecraft:light_block 15
setblock ~155~20~13 minecraft:wool 15
fill ~155~27~13 ~163~27~13 minecraft:light_block 15
fill ~156~18~13 ~156~18~20 minecraft:light_block 15
setblock ~156~19~13 minecraft:wool 15
fill ~156~20~13 ~156~20~14 minecraft:sea_lantern
setblock ~156~21~13 minecraft:light_block 15
fill ~157~19~13 ~157~19~20 minecraft:light_block 15
setblock ~157~20~13 minecraft:concrete 15
fill ~157~21~13 ~157~21~14 minecraft:sea_lantern
setblock ~157~22~13 minecraft:light_block 15
fill ~158~12~13 ~158~13~13 minecraft:light_block 15
fill ~158~20~13 ~158~20~20 minecraft:light_block 15
fill ~158~21~13 ~158~22~13 minecraft:wool 15
fill ~158~23~13 ~158~24~13 minecraft:light_block 15
fill ~158~29~13 ~158~29~19 minecraft:light_block 15
fill ~159~21~13 ~159~21~21 minecraft:light_block 15
setblock ~159~22~13 minecraft:wool 15
fill ~159~23~13 ~159~23~14 minecraft:concrete 15
setblock ~159~24~13 minecraft:light_block 15
fill ~159~30~13 ~160~30~18 minecraft:light_block 15
fill ~160~22~13 ~161~22~20 minecraft:light_block 15
setblock ~160~24~13 minecraft:wool 15
setblock ~161~23~13 minecraft:wool 15
fill ~161~24~13 ~161~25~13 minecraft:concrete 15
fill ~162~16~13 ~162~17~13 minecraft:light_block 15
fill ~162~23~13 ~162~23~20 minecraft:light_block 15
setblock ~162~24~13 minecraft:wool 15
setblock ~162~25~13 minecraft:light_block 15
fill ~162~26~13 ~163~26~13 minecraft:wool 15
fill ~163~17~13 ~163~18~13 minecraft:light_block 15
fill ~163~24~13 ~163~24~21 minecraft:light_block 15
setblock ~163~25~13 minecraft:wool 15
fill ~163~29~13 ~165~30~13 minecraft:light_block 15
fill ~163~32~13 ~163~32~18 minecraft:light_block 15
fill ~164~20~13 ~164~20~15 minecraft:light_block 15
fill ~164~25~13 ~164~25~21 minecraft:light_block 15
fill ~164~26~13 ~164~27~13 minecraft:concrete 15
setblock ~164~28~13 minecraft:light_block 15
fill ~164~31~13 ~168~31~13 minecraft:light_block 15
fill ~164~34~13 ~164~34~19 minecraft:light_block 15
fill ~165~26~13 ~165~26~21 minecraft:light_block 15
fill ~165~27~13 ~165~28~13 minecraft:concrete 15
fill ~165~35~13 ~165~35~19 minecraft:light_block 15
fill ~166~27~13 ~167~27~19 minecraft:light_block 15
setblock ~166~29~13 minecraft:concrete 15
setblock ~166~30~13 minecraft:light_block 15
fill ~166~32~13 ~169~32~13 minecraft:light_block 15
setblock ~167~28~13 minecraft:concrete 15
setblock ~167~29~13 minecraft:light_block 15
fill ~167~30~13 ~168~30~13 minecraft:wool 15
fill ~167~36~13 ~169~36~17 minecraft:light_block 15
fill ~168~28~13 ~168~28~20 minecraft:light_block 15
setblock ~168~29~13 minecraft:wool 15
fill ~169~29~13 ~169~29~21 minecraft:light_block 15
setblock ~169~31~13 minecraft:wool 15
fill ~170~30~13 ~171~30~20 minecraft:light_block 15
fill ~170~32~13 ~171~32~13 minecraft:concrete 15
setblock ~170~33~13 minecraft:light_block 15
fill ~171~27~13 ~171~27~17 minecraft:light_block 15
fill ~171~31~13 ~171~31~20 minecraft:light_block 15
fill ~171~33~13 ~172~33~13 minecraft:concrete 15
fill ~171~35~13 ~171~35~14 minecraft:light_block 15
fill ~172~28~13 ~172~28~17 minecraft:light_block 15
setblock ~172~32~13 minecraft:wool 15
setblock ~172~34~13 minecraft:wool 15
fill ~173~30~13 ~173~32~17 minecraft:light_block 15
fill ~29~35~14 ~30~35~14 minecraft:wool 15
fill ~30~31~14 ~30~32~20 minecraft:light_block 15
fill ~30~33~14 ~31~33~14 minecraft:wool 15
fill ~31~30~14 ~31~30~20 minecraft:light_block 15
fill ~31~32~14 ~31~32~22 minecraft:light_block 15
fill ~31~34~14 ~31~34~15 minecraft:wool 15
fill ~31~35~14 ~31~37~14 minecraft:light_block 15
fill ~32~29~14 ~32~29~20 minecraft:light_block 15
fill ~32~31~14 ~32~31~22 minecraft:light_block 15
fill ~32~32~14 ~33~32~14 minecraft:concrete 15
setblock ~32~33~14 minecraft:concrete 15
fill ~32~37~14 ~36~37~17 minecraft:light_block 15
fill ~32~38~14 ~34~38~18 minecraft:light_block 15
fill ~33~26~14 ~33~26~16 minecraft:light_block 15
fill ~33~30~14 ~33~30~21 minecraft:light_block 15
setblock ~33~31~14 minecraft:concrete 15
fill ~33~33~14 ~37~33~14 minecraft:light_block 15
fill ~34~29~14 ~34~29~21 minecraft:light_block 15
setblock ~34~30~14 minecraft:concrete 15
setblock ~34~31~14 minecraft:wool 15
fill ~34~32~14 ~42~32~14 minecraft:light_block 15
fill ~35~28~14 ~35~28~20 minecraft:light_block 15
setblock ~35~29~14 minecraft:concrete 15
setblock ~35~30~14 minecraft:light_block 15
setblock ~35~31~14 minecraft:sea_lantern
fill ~36~23~14 ~36~23~16 minecraft:light_block 15
fill ~36~28~14 ~37~28~14 minecraft:wool 15
setblock ~36~29~14 minecraft:light_block 15
setblock ~36~30~14 minecraft:sea_lantern
fill ~37~27~14 ~37~27~21 minecraft:light_block 15
setblock ~37~29~14 minecraft:concrete 15
fill ~37~36~14 ~37~36~20 minecraft:light_block 15
fill ~38~22~14 ~38~22~18 minecraft:light_block 15
fill ~38~26~14 ~38~26~21 minecraft:light_block 15
setblock ~38~28~14 minecraft:concrete 15
fill ~38~29~14 ~45~29~14 minecraft:light_block 15
fill ~38~35~14 ~38~35~20 minecraft:light_block 15
fill ~39~25~14 ~39~25~21 minecraft:light_block 15
setblock ~39~26~14 minecraft:wool 15
fill ~39~27~14 ~39~27~15 minecraft:concrete 15
fill ~39~28~14 ~45~28~14 minecraft:light_block 15
fill ~39~34~14 ~39~34~20 minecraft:light_block 15
fill ~40~24~14 ~41~24~21 minecraft:light_block 15
setblock ~40~25~14 minecraft:wool 15
setblock ~40~26~14 minecraft:concrete 15
fill ~40~27~14 ~46~27~14 minecraft:light_block 15
fill ~40~33~14 ~41~33~19 minecraft:light_block 15
fill ~41~23~14 ~41~23~20 minecraft:light_block 15
setblock ~41~26~14 minecraft:wool 15
fill ~42~23~14 ~44~23~14 minecraft:concrete 15
fill ~42~25~14 ~42~25~16 minecraft:wool 15
fill ~42~26~14 ~46~26~14 minecraft:light_block 15
fill ~43~22~14 ~43~22~19 minecraft:light_block 15
setblock ~43~24~14 minecraft:concrete 15
fill ~43~25~14 ~46~25~14 minecraft:light_block 15
fill ~43~31~14 ~43~31~20 minecraft:light_block 15
fill ~44~21~14 ~44~21~19 minecraft:light_block 15
setblock ~44~22~14 minecraft:wool 15
fill ~44~24~14 ~46~24~14 minecraft:light_block 15
fill ~44~30~14 ~44~30~20 minecraft:light_block 15
fill ~45~20~14 ~45~20~20 minecraft:light_block 15
fill ~45~22~14 ~46~22~14 minecraft:sea_lantern
setblock ~45~23~14 minecraft:light_block 15
fill ~46~19~14 ~46~19~21 minecraft:light_block 15
fill ~46~21~14 ~47~21~14 minecraft:sea_lantern
fill ~47~12~14 ~47~12~15 minecraft:light_block 15
fill ~47~18~14 ~48~18~21 minecraft:light_block 15
fill ~47~19~14 ~48~19~14 minecraft:wool 15
setblock ~47~20~14 minecraft:light_block 15
fill ~47~22~14 ~54~22~14 minecraft:light_block 15
setblock ~48~20~14 minecraft:concrete 15
fill ~48~21~14 ~55~21~14 minecraft:light_block 15
fill ~49~17~14 ~49~17~22 minecraft:light_block 15
fill ~49~19~14 ~49~19~15 minecraft:concrete 15
fill ~49~20~14 ~57~20~14 minecraft:light_block 15
fill ~50~16~14 ~50~16~21 minecraft:light_block 15
fill ~50~17~14 ~50~18~14 minecraft:wool 15
fill ~50~19~14 ~58~19~14 minecraft:light_block 15
fill ~51~15~14 ~51~15~21 minecraft:light_block 15
setblock ~51~16~14 minecraft:wool 15
fill ~51~17~14 ~52~17~14 minecraft:concrete 15
fill ~51~24~14 ~52~24~20 minecraft:light_block 15
fill ~52~14~14 ~53~14~21 minecraft:light_block 15
setblock ~52~15~14 minecraft:sea_lantern
setblock ~52~16~14 minecraft:light_block 15
setblock ~53~16~14 minecraft:sea_lantern
fill ~53~23~14 ~53~23~20 minecraft:light_block 15
fill ~54~13~14 ~54~13~21 minecraft:light_block 15
setblock ~54~14~14 minecraft:concrete 15
setblock ~54~15~14 minecraft:sea_lantern
fill ~55~12~14 ~55~12~20 minecraft:light_block 15
setblock ~55~14~14 minecraft:wool 15
fill ~56~11~14 ~56~11~21 minecraft:light_block 15
fill ~56~12~14 ~57~12~14 minecraft:wool 15
fill ~56~14~14 ~56~14~15 minecraft:concrete 15
fill ~57~6~14 ~57~6~16 minecraft:light_block 15
fill ~57~10~14 ~58~10~21 minecraft:light_block 15
fill ~57~11~14 ~59~11~14 minecraft:wool 15
fill ~58~12~14 ~58~12~15 minecraft:concrete 15
fill ~59~9~14 ~59~9~20 minecraft:light_block 15
fill ~59~10~14 ~60~10~14 minecraft:wool 15
fill ~59~12~14 ~59~14~14 minecraft:light_block 15
fill ~59~18~14 ~59~18~20 minecraft:light_block 15
fill ~60~8~14 ~60~8~20 minecraft:light_block 15
fill ~60~9~14 ~61~9~14 minecraft:concrete 15
fill ~60~17~14 ~60~17~20 minecraft:light_block 15
fill ~61~7~14 ~61~7~20 minecraft:light_block 15
fill ~61~8~14 ~62~8~14 minecraft:wool 15
fill ~62~6~14 ~63~6~20 minecraft:light_block 15
fill ~62~7~14 ~63~7~14 minecraft:wool 15
setblock ~62~9~14 minecraft:light_block 15
fill ~62~16~14 ~62~16~20 minecraft:light_block 15
fill ~63~8~14 ~63~8~16 minecraft:sea_lantern
fill ~63~15~14 ~63~15~20 minecraft:light_block 15
fill ~64~5~14 ~64~5~21 minecraft:light_block 15
fill ~64~6~14 ~65~6~14 minecraft:wool 15
fill ~64~7~14 ~64~7~15 minecraft:sea_lantern
fill ~64~8~14 ~65~8~14 minecraft:light_block 15
fill ~64~13~14 ~64~13~19 minecraft:light_block 15
fill ~65~4~14 ~65~4~22 minecraft:light_block 15
setblock ~65~5~14 minecraft:concrete 15
fill ~65~7~14 ~71~7~14 minecraft:light_block 15
fill ~66~3~14 ~66~3~22 minecraft:light_block 15
setblock ~66~5~14 minecraft:wool 15
fill ~66~6~14 ~72~6~14 minecraft:light_block 15
fill ~67~2~14 ~67~2~21 minecraft:light_block 15
setblock ~67~3~14 minecraft:sea_lantern
fill ~67~4~14 ~67~4~15 minecraft:concrete 15
fill ~67~5~14 ~72~5~14 minecraft:light_block 15
fill ~67~11~14 ~67~11~20 minecraft:light_block 15
fill ~68~1~14 ~68~1~20 minecraft:light_block 15
setblock ~68~2~14 minecraft:sea_lantern
setblock ~68~3~14 minecraft:light_block 15
setblock ~68~4~14 minecraft:sea_lantern
fill ~69~0~14 ~69~0~18 minecraft:light_block 15
setblock ~69~1~14 minecraft:wool 15
setblock ~69~2~14 minecraft:light_block 15
setblock ~69~3~14 minecraft:sea_lantern
fill ~69~4~14 ~72~4~14 minecraft:light_block 15
fill ~70~2~14 ~70~2~15 minecraft:concrete 15
fill ~70~3~14 ~72~3~14 minecraft:light_block 15
fill ~70~9~14 ~70~9~20 minecraft:light_block 15
setblock ~71~1~14 minecraft:wool 15
fill ~71~2~14 ~72~2~14 minecraft:light_block 15
fill ~71~8~14 ~71~8~20 minecraft:light_block 15
fill ~128~2~14 ~131~6~14 minecraft:light_block 15
fill ~129~1~14 ~130~1~14 minecraft:light_block 15
fill ~129~7~14 ~137~7~14 minecraft:light_block 15
fill ~130~0~14 ~131~0~20 minecraft:light_block 15
fill ~130~8~14 ~138~8~14 minecraft:light_block 15
setblock ~131~1~14 minecraft:concrete 15
setblock ~132~2~14 minecraft:wool 15
fill ~132~3~14 ~132~6~14 minecraft:light_block 15
fill ~132~9~14 ~140~9~14 minecraft:light_block 15
fill ~133~0~14 ~133~0~20 minecraft:light_block 15
setblock ~133~1~14 minecraft:concrete 15
setblock ~133~2~14 minecraft:light_block 15
setblock ~133~3~14 minecraft:sea_lantern
fill ~133~4~14 ~133~6~14 minecraft:light_block 15
fill ~133~10~14 ~141~10~14 minecraft:light_block 15
fill ~134~1~14 ~134~1~21 minecraft:light_block 15
setblock ~134~2~14 minecraft:sea_lantern
setblock ~134~3~14 minecraft:light_block 15
setblock ~134~4~14 minecraft:sea_lantern
fill ~134~5~14 ~135~6~14 minecraft:light_block 15
fill ~134~11~14 ~134~11~20 minecraft:light_block 15
fill ~135~2~14 ~135~2~21 minecraft:light_block 15
setblock ~135~3~14 minecraft:sea_lantern
fill ~135~4~14 ~136~4~14 minecraft:wool 15
fill ~136~3~14 ~136~3~21 minecraft:light_block 15
setblock ~136~5~14 minecraft:wool 15
setblock ~136~6~14 minecraft:light_block 15
fill ~136~12~14 ~136~12~20 minecraft:light_block 15
fill ~137~0~14 ~137~0~18 minecraft:light_block 15
fill ~137~4~14 ~137~4~21 minecraft:light_block 15
setblock ~137~5~14 minecraft:concrete 15
fill ~137~6~14 ~138~6~14 minecraft:wool 15
fill ~137~13~14 ~137~13~20 minecraft:light_block 15
fill ~138~1~14 ~138~1~18 minecraft:light_block 15
fill ~138~5~14 ~138~5~21 minecraft:light_block 15
fill ~138~7~14 ~138~7~15 minecraft:sea_lantern
fill ~138~14~14 ~139~14~19 minecraft:light_block 15
fill ~139~6~14 ~140~6~21 minecraft:light_block 15
fill ~139~7~14 ~140~7~14 minecraft:wool 15
fill ~139~8~14 ~139~8~16 minecraft:sea_lantern
fill ~139~15~14 ~139~15~20 minecraft:light_block 15
fill ~140~8~14 ~140~8~15 minecraft:concrete 15
fill ~140~16~14 ~140~16~20 minecraft:light_block 15
fill ~141~7~14 ~141~7~22 minecraft:light_block 15
fill ~141~8~14 ~141~9~14 minecraft:wool 15
fill ~141~17~14 ~143~17~19 minecraft:light_block 15
fill ~142~8~14 ~142~8~22 minecraft:light_block 15
fill ~142~9~14 ~142~10~14 minecraft:concrete 15
fill ~143~9~14 ~143~9~22 minecraft:light_block 15
fill ~143~10~14 ~143~11~14 minecraft:concrete 15
fill ~144~10~14 ~145~10~21 minecraft:light_block 15
fill ~144~11~14 ~145~12~14 minecraft:wool 15
fill ~144~19~14 ~144~19~20 minecraft:light_block 15
fill ~145~20~14 ~145~20~20 minecraft:light_block 15
fill ~146~11~14 ~146~11~22 minecraft:light_block 15
setblock ~146~12~14 minecraft:concrete 15
fill ~146~13~14 ~147~13~14 minecraft:wool 15
setblock ~146~14~14 minecraft:concrete 15
fill ~147~12~14 ~147~12~22 minecraft:light_block 15
fill ~147~14~14 ~148~14~14 minecraft:wool 15
fill ~147~21~14 ~147~21~20 minecraft:light_block 15
fill ~148~13~14 ~148~13~22 minecraft:light_block 15
setblock ~148~15~14 minecraft:sea_lantern
fill ~148~17~14 ~149~17~14 minecraft:light_block 15
fill ~148~22~14 ~148~22~20 minecraft:light_block 15
fill ~149~7~14 ~150~7~14 minecraft:light_block 15
fill ~149~14~14 ~150~14~20 minecraft:light_block 15
setblock ~149~16~14 minecraft:sea_lantern
setblock ~150~15~14 minecraft:sea_lantern
setblock ~150~16~14 minecraft:light_block 15
setblock ~150~17~14 minecraft:concrete 15
fill ~150~23~14 ~150~23~19 minecraft:light_block 15
fill ~151~8~14 ~152~8~14 minecraft:light_block 15
fill ~151~15~14 ~151~15~20 minecraft:light_block 15
setblock ~151~16~14 minecraft:wool 15
fill ~151~24~14 ~151~24~20 minecraft:light_block 15
fill ~152~16~14 ~152~16~21 minecraft:light_block 15
fill ~152~18~14 ~152~18~15 minecraft:wool 15
fill ~152~25~14 ~159~25~14 minecraft:light_block 15
setblock ~153~9~14 minecraft:light_block 15
fill ~153~17~14 ~153~17~21 minecraft:light_block 15
setblock ~153~18~14 minecraft:concrete 15
fill ~153~19~14 ~153~19~15 minecraft:wool 15
fill ~153~26~14 ~160~26~14 minecraft:light_block 15
fill ~154~18~14 ~155~18~20 minecraft:light_block 15
setblock ~154~20~14 minecraft:wool 15
fill ~154~27~14 ~162~27~14 minecraft:light_block 15
setblock ~155~19~14 minecraft:wool 15
setblock ~155~20~14 minecraft:light_block 15
fill ~155~21~14 ~156~21~14 minecraft:sea_lantern
fill ~155~28~14 ~156~28~19 minecraft:light_block 15
fill ~156~19~14 ~156~19~21 minecraft:light_block 15
fill ~156~22~14 ~157~22~14 minecraft:sea_lantern
fill ~157~20~14 ~157~20~21 minecraft:light_block 15
fill ~157~29~14 ~157~29~19 minecraft:light_block 15
fill ~158~21~14 ~158~21~21 minecraft:light_block 15
setblock ~158~22~14 minecraft:wool 15
fill ~158~23~14 ~158~23~15 minecraft:concrete 15
setblock ~158~24~14 minecraft:light_block 15
fill ~158~30~14 ~158~30~20 minecraft:light_block 15
setblock ~159~14~14 minecraft:light_block 15
fill ~159~22~14 ~159~22~21 minecraft:light_block 15
fill ~159~24~14 ~159~24~15 minecraft:wool 15
fill ~159~31~14 ~162~31~18 minecraft:light_block 15
setblock ~160~15~14 minecraft:light_block 15
fill ~160~23~14 ~160~25~14 minecraft:concrete 15
setblock ~161~16~14 minecraft:light_block 15
fill ~161~23~14 ~161~24~20 minecraft:light_block 15
fill ~161~25~14 ~161~25~15 minecraft:wool 15
fill ~161~26~14 ~162~26~14 minecraft:concrete 15
fill ~161~32~14 ~162~32~18 minecraft:light_block 15
setblock ~162~17~14 minecraft:light_block 15
fill ~162~24~14 ~162~24~21 minecraft:light_block 15
setblock ~162~25~14 minecraft:concrete 15
fill ~162~33~14 ~163~33~19 minecraft:light_block 15
setblock ~163~18~14 minecraft:light_block 15
fill ~163~25~14 ~163~25~21 minecraft:light_block 15
setblock ~163~26~14 minecraft:wool 15
fill ~163~27~14 ~164~27~14 minecraft:concrete 15
fill ~163~29~14 ~164~30~14 minecraft:light_block 15
fill ~163~34~14 ~163~34~20 minecraft:light_block 15
fill ~164~26~14 ~164~26~22 minecraft:light_block 15
fill ~164~28~14 ~164~28~15 minecraft:concrete 15
fill ~164~31~14 ~166~31~14 minecraft:light_block 15
fill ~164~35~14 ~164~36~20 minecraft:light_block 15
fill ~165~27~14 ~165~27~22 minecraft:light_block 15
setblock ~165~28~14 minecraft:wool 15
fill ~165~29~14 ~165~29~15 minecraft:concrete 15
setblock ~165~30~14 minecraft:light_block 15
fill ~165~36~14 ~166~37~19 minecraft:light_block 15
setblock ~166~29~14 minecraft:light_block 15
setblock ~166~30~14 minecraft:sea_lantern
fill ~166~32~14 ~168~32~14 minecraft:light_block 15
fill ~167~28~14 ~167~28~21 minecraft:light_block 15
setblock ~167~29~14 minecraft:wool 15
setblock ~167~30~14 minecraft:light_block 15
setblock ~167~31~14 minecraft:sea_lantern
fill ~167~37~14 ~167~37~20 minecraft:light_block 15
fill ~168~29~14 ~168~29~21 minecraft:light_block 15
fill ~168~30~14 ~168~31~14 minecraft:wool 15
fill ~169~30~14 ~169~30~21 minecraft:light_block 15
setblock ~169~31~14 minecraft:concrete 15
setblock ~169~32~14 minecraft:wool 15
fill ~170~31~14 ~170~31~21 minecraft:light_block 15
setblock ~170~32~14 minecraft:concrete 15
setblock ~170~33~14 minecraft:wool 15
fill ~170~36~14 ~170~36~16 minecraft:light_block 15
fill ~171~32~14 ~172~32~19 minecraft:light_block 15
setblock ~171~33~14 minecraft:concrete 15
fill ~171~34~14 ~171~34~15 minecraft:wool 15
setblock ~172~33~14 minecraft:wool 15
fill ~172~34~14 ~172~34~15 minecraft:concrete 15
setblock ~172~35~14 minecraft:concrete 15
fill ~173~29~14 ~173~29~16 minecraft:light_block 15
fill ~173~33~14 ~173~33~16 minecraft:light_block 15
setblock ~173~35~14 minecraft:wool 15
fill ~29~32~15 ~29~34~19 minecraft:light_block 15
fill ~29~35~15 ~29~36~15 minecraft:concrete 15
fill ~30~30~15 ~30~30~19 minecraft:light_block 15
fill ~30~33~15 ~31~33~22 minecraft:light_block 15
setblock ~30~35~15 minecraft:light_block 15
setblock ~30~36~15 minecraft:concrete 15
fill ~30~37~15 ~31~38~15 minecraft:light_block 15
fill ~31~29~15 ~31~29~19 minecraft:light_block 15
fill ~31~35~15 ~31~35~17 minecraft:concrete 15
setblock ~31~36~15 minecraft:light_block 15
fill ~31~39~15 ~35~39~18 minecraft:light_block 15
fill ~32~28~15 ~32~28~19 minecraft:light_block 15
fill ~32~32~15 ~32~32~22 minecraft:light_block 15
fill ~32~33~15 ~32~34~15 minecraft:wool 15
fill ~33~31~15 ~33~31~22 minecraft:light_block 15
fill ~33~32~15 ~34~33~15 minecraft:concrete 15
fill ~33~34~15 ~36~34~15 minecraft:light_block 15
fill ~34~30~15 ~34~30~22 minecraft:light_block 15
setblock ~34~31~15 minecraft:concrete 15
fill ~35~29~15 ~35~29~21 minecraft:light_block 15
setblock ~35~30~15 minecraft:sea_lantern
setblock ~35~31~15 minecraft:light_block 15
setblock ~35~32~15 minecraft:sea_lantern
fill ~35~33~15 ~37~33~15 minecraft:light_block 15
fill ~35~38~15 ~36~38~20 minecraft:light_block 15
fill ~36~28~15 ~37~28~21 minecraft:light_block 15
fill ~36~29~15 ~38~29~15 minecraft:wool 15
setblock ~36~30~15 minecraft:light_block 15
setblock ~36~31~15 minecraft:sea_lantern
fill ~36~32~15 ~43~32~15 minecraft:light_block 15
setblock ~37~30~15 minecraft:sea_lantern
fill ~37~31~15 ~40~31~15 minecraft:light_block 15
fill ~37~37~15 ~37~37~21 minecraft:light_block 15
fill ~38~27~15 ~38~27~22 minecraft:light_block 15
fill ~38~28~15 ~39~28~15 minecraft:wool 15
fill ~38~30~15 ~39~30~15 minecraft:light_block 15
fill ~38~36~15 ~38~36~21 minecraft:light_block 15
fill ~39~26~15 ~39~26~21 minecraft:light_block 15
fill ~39~29~15 ~45~29~15 minecraft:light_block 15
fill ~39~35~15 ~39~35~21 minecraft:light_block 15
fill ~40~25~15 ~40~25~21 minecraft:light_block 15
setblock ~40~26~15 minecraft:wool 15
setblock ~40~27~15 minecraft:concrete 15
fill ~40~28~15 ~40~28~17 minecraft:sea_lantern
fill ~40~34~15 ~40~34~20 minecraft:light_block 15
setblock ~41~26~15 minecraft:light_block 15
setblock ~41~27~15 minecraft:sea_lantern
fill ~41~28~15 ~46~28~15 minecraft:light_block 15
fill ~42~23~15 ~43~23~20 minecraft:light_block 15
fill ~42~24~15 ~42~24~21 minecraft:light_block 15
fill ~42~26~15 ~42~26~16 minecraft:concrete 15
fill ~42~27~15 ~46~27~15 minecraft:light_block 15
fill ~42~33~15 ~42~33~21 minecraft:light_block 15
fill ~43~24~15 ~43~25~15 minecraft:wool 15
fill ~43~26~15 ~46~26~15 minecraft:light_block 15
fill ~44~22~15 ~44~22~18 minecraft:light_block 15
fill ~44~23~15 ~45~23~15 minecraft:wool 15
fill ~44~24~15 ~44~24~16 minecraft:concrete 15
fill ~44~25~15 ~46~25~15 minecraft:light_block 15
fill ~45~21~15 ~45~21~20 minecraft:light_block 15
setblock ~45~22~15 minecraft:wool 15
fill ~45~24~15 ~46~24~15 minecraft:light_block 15
fill ~46~20~15 ~46~20~21 minecraft:light_block 15
fill ~46~21~15 ~46~22~15 minecraft:sea_lantern
fill ~47~13~15 ~47~13~16 minecraft:light_block 15
fill ~47~19~15 ~48~19~22 minecraft:light_block 15
setblock ~47~20~15 minecraft:concrete 15
setblock ~47~21~15 minecraft:light_block 15
setblock ~47~22~15 minecraft:wool 15
fill ~48~20~15 ~48~21~15 minecraft:wool 15
fill ~48~22~15 ~54~22~15 minecraft:light_block 15
fill ~49~18~15 ~49~18~23 minecraft:light_block 15
fill ~49~20~15 ~50~20~15 minecraft:concrete 15
fill ~49~21~15 ~57~21~15 minecraft:light_block 15
fill ~49~25~15 ~52~25~19 minecraft:light_block 15
fill ~50~17~15 ~50~17~23 minecraft:light_block 15
setblock ~50~18~15 minecraft:wool 15
setblock ~50~19~15 minecraft:concrete 15
fill ~51~16~15 ~51~16~22 minecraft:light_block 15
setblock ~51~17~15 minecraft:wool 15
fill ~51~18~15 ~52~18~15 minecraft:concrete 15
fill ~51~19~15 ~59~19~15 minecraft:light_block 15
fill ~51~20~15 ~58~20~16 minecraft:light_block 15
fill ~52~15~15 ~52~15~22 minecraft:light_block 15
setblock ~52~16~15 minecraft:wool 15
setblock ~52~17~15 minecraft:light_block 15
fill ~53~15~15 ~53~17~15 minecraft:concrete 15
fill ~53~18~15 ~54~18~15 minecraft:light_block 15
fill ~53~24~15 ~53~24~21 minecraft:light_block 15
fill ~54~14~15 ~54~14~22 minecraft:light_block 15
setblock ~54~15~15 minecraft:wool 15
setblock ~54~16~15 minecraft:concrete 15
setblock ~54~17~15 minecraft:light_block 15
fill ~54~23~15 ~54~23~21 minecraft:light_block 15
fill ~55~13~15 ~55~13~22 minecraft:light_block 15
fill ~55~14~15 ~55~15~15 minecraft:concrete 15
setblock ~55~16~15 minecraft:light_block 15
fill ~56~12~15 ~56~12~22 minecraft:light_block 15
fill ~56~13~15 ~58~13~15 minecraft:concrete 15
fill ~56~15~15 ~57~15~15 minecraft:light_block 15
fill ~57~11~15 ~58~11~21 minecraft:light_block 15
setblock ~57~12~15 minecraft:wool 15
fill ~59~10~15 ~59~10~21 minecraft:light_block 15
fill ~59~11~15 ~60~11~15 minecraft:wool 15
setblock ~59~12~15 minecraft:wool 15
fill ~59~13~15 ~59~14~15 minecraft:light_block 15
fill ~60~9~15 ~60~9~20 minecraft:light_block 15
setblock ~60~10~15 minecraft:concrete 15
fill ~60~18~15 ~60~18~21 minecraft:light_block 15
fill ~61~8~15 ~61~8~20 minecraft:light_block 15
fill ~61~9~15 ~61~10~15 minecraft:wool 15
fill ~61~11~15 ~64~11~15 minecraft:light_block 15
fill ~61~17~15 ~61~17~21 minecraft:light_block 15
fill ~62~7~15 ~63~7~20 minecraft:light_block 15
setblock ~62~8~15 minecraft:wool 15
fill ~62~9~15 ~62~9~16 minecraft:concrete 15
fill ~62~10~15 ~63~10~15 minecraft:light_block 15
