fill ~19~2~2 ~23~2~3 minecraft:wool 11
fill ~24~2~2 ~27~2~3 minecraft:wool 8
fill ~28~2~2 ~32~2~3 minecraft:wool 11
fill ~15~2~3 ~18~2~3 minecraft:wool 8
fill ~33~2~3 ~36~2~3 minecraft:wool 8
fill ~12~2~4 ~16~2~4 minecraft:wool 8
fill ~16~12~4 ~18~12~5 minecraft:wool 8
fill ~16~13~4 ~18~13~4 minecraft:wool 8
fill ~17~3~4 ~18~3~6 minecraft:wool 8
fill ~17~14~4 ~18~14~9 minecraft:wool 8
fill ~19~3~4 ~23~3~5 minecraft:wool 11
fill ~19~12~4 ~23~12~6 minecraft:wool 11
fill ~19~13~4 ~23~14~4 minecraft:wool 11
fill ~24~3~4 ~27~3~5 minecraft:wool 8
fill ~24~12~4 ~27~12~9 minecraft:wool 8
fill ~24~13~4 ~27~14~4 minecraft:wool 8
fill ~28~3~4 ~32~3~5 minecraft:wool 11
fill ~28~12~4 ~32~12~6 minecraft:wool 11
fill ~28~13~4 ~32~14~4 minecraft:wool 11
fill ~33~3~4 ~34~3~6 minecraft:wool 8
fill ~33~12~4 ~35~12~5 minecraft:wool 8
fill ~33~13~4 ~35~13~4 minecraft:wool 8
fill ~33~14~4 ~34~14~9 minecraft:wool 8
fill ~35~2~4 ~39~2~4 minecraft:wool 8
fill ~9~2~5 ~14~2~5 minecraft:wool 8
fill ~14~11~5 ~17~11~5 minecraft:wool 8
fill ~14~12~5 ~15~13~5 minecraft:wool 8
fill ~15~3~5 ~16~3~5 minecraft:wool 8
fill ~15~9~5 ~17~10~5 minecraft:wool 8
fill ~15~14~5 ~16~14~5 minecraft:wool 8
fill ~16~4~5 ~17~4~6 minecraft:wool 8
fill ~16~7~5 ~17~8~6 minecraft:wool 8
setblock ~16~13~5 minecraft:wool 8
fill ~16~15~5 ~17~15~7 minecraft:wool 8
fill ~17~5~5 ~17~6~7 minecraft:wool 8
fill ~17~16~5 ~17~16~7 minecraft:wool 8
fill ~19~14~5 ~23~14~6 minecraft:wool 11
fill ~21~18~5 ~23~18~6 minecraft:wool 11
fill ~24~14~5 ~27~14~9 minecraft:wool 8
fill ~24~18~5 ~27~18~12 minecraft:wool 8
fill ~28~14~5 ~32~14~6 minecraft:wool 11
fill ~28~18~5 ~30~18~6 minecraft:wool 11
fill ~34~4~5 ~35~4~6 minecraft:wool 8
fill ~34~5~5 ~34~11~7 minecraft:wool 8
fill ~34~15~5 ~35~15~7 minecraft:wool 8
fill ~34~16~5 ~34~16~7 minecraft:wool 8
fill ~35~3~5 ~36~3~5 minecraft:wool 8
fill ~35~7~5 ~35~8~6 minecraft:wool 8
fill ~35~9~5 ~36~11~5 minecraft:wool 8
fill ~35~13~5 ~37~13~5 minecraft:wool 8
fill ~35~14~5 ~36~14~5 minecraft:wool 8
fill ~36~12~5 ~37~12~5 minecraft:wool 8
fill ~37~2~5 ~42~2~5 minecraft:wool 8
fill ~37~11~5 ~37~11~6 minecraft:wool 8
fill ~7~2~6 ~12~2~6 minecraft:wool 8
fill ~11~12~6 ~14~13~6 minecraft:wool 8
fill ~12~11~6 ~14~11~6 minecraft:wool 8
fill ~12~14~6 ~15~14~9 minecraft:wool 8
fill ~13~3~6 ~14~3~7 minecraft:wool 8
fill ~13~9~6 ~15~10~6 minecraft:wool 8
fill ~15~4~6 ~15~5~7 minecraft:wool 8
fill ~15~6~6 ~16~6~6 minecraft:wool 8
fill ~15~15~6 ~15~16~8 minecraft:stained_glass 15
setblock ~16~5~6 minecraft:wool 8
fill ~16~16~6 ~16~17~11 minecraft:wool 8
fill ~17~9~6 ~17~11~7 minecraft:wool 8
fill ~17~12~6 ~18~12~6 minecraft:wool 8
fill ~17~17~6 ~18~18~6 minecraft:wool 8
fill ~18~4~6 ~18~4~7 minecraft:wool 8
fill ~19~3~6 ~21~3~6 minecraft:wool 8
fill ~19~4~6 ~23~4~6 minecraft:wool 11
fill ~19~18~6 ~20~18~6 minecraft:wool 11
fill ~20~19~6 ~23~19~6 minecraft:wool 11
fill ~24~4~6 ~27~4~7 minecraft:wool 8
fill ~24~19~6 ~27~19~6 minecraft:wool 8
fill ~25~15~6 ~26~16~6 minecraft:concrete 14
fill ~25~17~6 ~26~17~6 minecraft:stone 0
fill ~28~4~6 ~32~4~6 minecraft:wool 11
fill ~28~19~6 ~31~19~6 minecraft:wool 11
fill ~30~3~6 ~32~3~6 minecraft:wool 8
fill ~31~18~6 ~32~18~6 minecraft:wool 11
fill ~33~4~6 ~33~4~7 minecraft:wool 8
fill ~33~12~6 ~34~12~6 minecraft:wool 8
fill ~33~17~6 ~35~17~6 minecraft:wool 8
fill ~33~18~6 ~34~18~12 minecraft:wool 8
fill ~35~5~6 ~36~6~6 minecraft:wool 8
fill ~35~16~6 ~35~16~11 minecraft:wool 8
fill ~36~4~6 ~36~4~7 minecraft:wool 8
fill ~36~9~6 ~38~10~6 minecraft:wool 8
fill ~36~14~6 ~39~14~9 minecraft:wool 8
fill ~36~15~6 ~36~16~8 minecraft:stained_glass 15
fill ~37~3~6 ~38~3~7 minecraft:wool 8
fill ~37~12~6 ~40~13~6 minecraft:wool 8
fill ~38~11~6 ~39~11~7 minecraft:wool 8
fill ~39~2~6 ~44~2~6 minecraft:wool 8
fill ~6~2~7 ~9~2~7 minecraft:wool 8
fill ~10~3~7 ~12~3~8 minecraft:wool 8
fill ~10~6~7 ~10~6~10 minecraft:wool 8
fill ~10~7~7 ~10~7~9 minecraft:wool 8
fill ~10~11~7 ~10~12~7 minecraft:stained_glass 15
fill ~10~13~7 ~11~14~7 minecraft:wool 8
fill ~11~5~7 ~11~5~10 minecraft:wool 8
fill ~11~8~7 ~11~8~9 minecraft:wool 8
fill ~11~9~7 ~13~9~7 minecraft:wool 8
fill ~11~10~7 ~12~11~7 minecraft:wool 8
setblock ~11~12~7 minecraft:wool 8
fill ~12~4~7 ~14~4~7 minecraft:wool 8
fill ~12~15~7 ~14~15~8 minecraft:stained_glass 15
fill ~13~7~7 ~15~8~7 minecraft:coal_block
fill ~13~10~7 ~14~10~7 minecraft:coal_block
setblock ~13~11~7 minecraft:wool 8
fill ~14~6~7 ~15~6~7 minecraft:coal_block
setblock ~14~9~7 minecraft:coal_block
fill ~14~16~7 ~14~17~8 minecraft:stained_glass 15
fill ~15~17~7 ~15~17~8 minecraft:stained_glass 15
setblock ~15~18~7 minecraft:wool 7
fill ~16~18~7 ~23~18~12 minecraft:wool 8
fill ~16~19~7 ~18~19~7 minecraft:wool 7
fill ~17~7~7 ~17~8~7 minecraft:wool 8
fill ~18~5~7 ~33~11~7 minecraft:coal_block
fill ~18~12~7 ~23~12~9 minecraft:wool 8
fill ~18~13~7 ~33~13~7 minecraft:wool 8
fill ~18~15~7 ~33~16~7 minecraft:coal_block
fill ~18~17~7 ~18~17~11 minecraft:wool 8
fill ~19~4~7 ~23~4~7 minecraft:wool 8
fill ~19~14~7 ~23~14~9 minecraft:wool 8
fill ~19~17~7 ~32~17~7 minecraft:coal_block
fill ~19~19~7 ~23~19~7 minecraft:stained_hardened_clay 11
fill ~24~19~7 ~27~19~7 minecraft:wool 7
fill ~28~4~7 ~32~4~7 minecraft:wool 8
fill ~28~12~7 ~33~12~9 minecraft:wool 8
fill ~28~14~7 ~32~14~9 minecraft:wool 8
fill ~28~18~7 ~32~18~10 minecraft:wool 8
fill ~28~19~7 ~32~19~7 minecraft:stained_hardened_clay 11
fill ~33~17~7 ~33~17~11 minecraft:wool 8
fill ~33~19~7 ~35~19~7 minecraft:wool 7
fill ~35~17~7 ~35~18~11 minecraft:wool 8
setblock ~36~5~7 minecraft:wool 8
fill ~36~6~7 ~37~8~7 minecraft:coal_block
fill ~36~17~7 ~37~17~8 minecraft:stained_glass 15
setblock ~36~18~7 minecraft:wool 7
fill ~37~4~7 ~39~4~7 minecraft:wool 8
fill ~37~9~7 ~37~10~7 minecraft:coal_block
fill ~37~15~7 ~39~15~8 minecraft:stained_glass 15
fill ~37~16~7 ~37~16~8 minecraft:stained_glass 15
fill ~38~7~7 ~38~8~8 minecraft:coal_block
fill ~38~9~7 ~40~9~7 minecraft:wool 8
fill ~38~10~7 ~38~10~8 minecraft:coal_block
fill ~39~3~7 ~41~3~8 minecraft:wool 8
fill ~39~10~7 ~40~10~7 minecraft:wool 8
fill ~40~5~7 ~40~5~10 minecraft:wool 8
fill ~40~8~7 ~40~8~9 minecraft:wool 8
fill ~40~11~7 ~40~11~8 minecraft:wool 8
fill ~40~12~7 ~40~14~7 minecraft:wool 8
fill ~41~6~7 ~41~6~10 minecraft:wool 8
fill ~41~7~7 ~41~7~9 minecraft:wool 8
fill ~41~11~7 ~41~12~7 minecraft:stained_glass 15
fill ~41~13~7 ~41~14~8 minecraft:wool 8
fill ~42~2~7 ~45~2~7 minecraft:wool 8
fill ~5~2~8 ~8~2~8 minecraft:wool 8
fill ~8~11~8 ~9~12~8 minecraft:stained_glass 15
fill ~8~13~8 ~10~14~8 minecraft:wool 8
fill ~9~3~8 ~9~3~9 minecraft:wool 8
fill ~9~9~8 ~11~9~8 minecraft:wool 8
fill ~9~10~8 ~10~10~8 minecraft:wool 8
fill ~10~11~8 ~10~12~8 minecraft:concrete 1
fill ~10~15~8 ~11~15~10 minecraft:stained_glass 15
fill ~11~6~8 ~13~7~8 minecraft:coal_block
fill ~11~10~8 ~13~10~8 minecraft:coal_block
setblock ~11~11~8 minecraft:wool 8
fill ~11~14~8 ~11~14~10 minecraft:wool 8
fill ~11~16~8 ~13~16~8 minecraft:stained_glass 15
fill ~12~4~8 ~12~4~9 minecraft:wool 8
fill ~12~5~8 ~14~5~8 minecraft:coal_block
fill ~12~8~8 ~13~9~8 minecraft:coal_block
fill ~12~17~8 ~13~17~8 minecraft:stained_glass 15
fill ~13~4~8 ~14~4~8 minecraft:coal_block
fill ~13~18~8 ~15~18~12 minecraft:wool 8
fill ~14~8~8 ~14~9~8 minecraft:wool 8
fill ~14~12~8 ~17~13~9 minecraft:wool 8
fill ~15~19~8 ~18~19~9 minecraft:wool 8
fill ~16~14~8 ~16~15~11 minecraft:wool 8
fill ~17~17~8 ~17~17~11 minecraft:wool 8
fill ~19~17~8 ~32~17~11 minecraft:wool 8
fill ~19~19~8 ~22~19~8 minecraft:wool 11
fill ~22~15~8 ~29~15~9 minecraft:wool 8
fill ~22~16~8 ~29~16~8 minecraft:wool 8
fill ~23~19~8 ~28~19~8 minecraft:wool 8
fill ~23~20~8 ~23~20~11 minecraft:wool 11
fill ~24~20~8 ~27~20~12 minecraft:wool 8
fill ~28~20~8 ~28~20~12 minecraft:wool 11
fill ~29~19~8 ~32~19~8 minecraft:wool 11
fill ~33~19~8 ~36~19~9 minecraft:wool 8
fill ~34~12~8 ~37~13~9 minecraft:wool 8
fill ~34~17~8 ~34~17~11 minecraft:wool 8
fill ~35~14~8 ~35~15~11 minecraft:wool 8
fill ~36~18~8 ~38~18~13 minecraft:wool 8
fill ~37~4~8 ~38~5~8 minecraft:coal_block
fill ~37~8~8 ~37~9~8 minecraft:wool 8
fill ~38~6~8 ~40~6~8 minecraft:coal_block
fill ~38~9~8 ~39~9~8 minecraft:coal_block
fill ~38~16~8 ~40~16~8 minecraft:stained_glass 15
fill ~38~17~8 ~39~17~8 minecraft:stained_glass 15
fill ~39~4~8 ~39~4~9 minecraft:wool 8
fill ~39~5~8 ~39~5~9 minecraft:coal_block
fill ~39~7~8 ~40~7~8 minecraft:coal_block
setblock ~39~8~8 minecraft:coal_block
fill ~39~10~8 ~40~10~8 minecraft:coal_block
fill ~40~9~8 ~42~9~8 minecraft:wool 8
fill ~40~14~8 ~40~14~10 minecraft:wool 8
fill ~40~15~8 ~41~15~10 minecraft:stained_glass 15
fill ~41~10~8 ~42~10~8 minecraft:wool 8
fill ~41~11~8 ~41~12~8 minecraft:concrete 1
fill ~42~3~8 ~42~3~9 minecraft:wool 8
fill ~42~11~8 ~43~12~8 minecraft:stained_glass 15
fill ~42~13~8 ~43~14~8 minecraft:wool 8
fill ~43~2~8 ~46~2~8 minecraft:wool 8
setblock ~4~2~9 minecraft:wool 11
fill ~5~2~9 ~6~2~9 minecraft:wool 8
fill ~6~6~9 ~6~7~11 minecraft:wool 8
fill ~6~10~9 ~8~10~9 minecraft:wool 8
fill ~6~11~9 ~7~11~10 minecraft:wool 8
fill ~6~12~9 ~7~14~9 minecraft:wool 8
fill ~7~3~9 ~8~3~10 minecraft:wool 8
setblock ~7~5~9 minecraft:wool 8
fill ~7~8~9 ~7~8~10 minecraft:wool 8
fill ~7~9~9 ~10~9~9 minecraft:wool 8
fill ~8~4~9 ~9~4~9 minecraft:wool 8
fill ~8~11~9 ~9~13~9 minecraft:concrete 1
fill ~8~14~9 ~10~14~11 minecraft:wool 8
fill ~8~15~9 ~9~15~10 minecraft:stained_glass 15
fill ~9~10~9 ~11~10~9 minecraft:coal_block
fill ~9~16~9 ~11~16~10 minecraft:stained_glass 15
fill ~10~3~9 ~11~3~9 minecraft:wool 8
fill ~10~17~9 ~12~17~10 minecraft:stained_glass 15
fill ~11~6~9 ~11~7~9 minecraft:coal_block
setblock ~11~9~9 minecraft:coal_block
fill ~11~18~9 ~11~18~10 minecraft:stained_glass 15
setblock ~12~5~9 minecraft:coal_block
setblock ~12~6~9 minecraft:wool 8
fill ~12~8~9 ~12~9~9 minecraft:wool 8
fill ~12~12~9 ~13~12~12 minecraft:wool 8
fill ~12~13~9 ~13~13~10 minecraft:wool 8
fill ~12~15~9 ~12~15~10 minecraft:stained_glass 15
fill ~12~16~9 ~12~16~10 minecraft:concrete 0
fill ~12~18~9 ~12~18~13 minecraft:wool 8
fill ~13~15~9 ~15~15~9 minecraft:concrete 0
fill ~13~16~9 ~14~16~9 minecraft:sea_lantern
fill ~13~17~9 ~15~17~9 minecraft:concrete 0
fill ~13~19~9 ~14~19~9 minecraft:wool 8
fill ~14~11~9 ~18~11~11 minecraft:wool 8
fill ~15~10~9 ~18~10~11 minecraft:wool 8
setblock ~15~16~9 minecraft:concrete 0
fill ~16~9~9 ~16~9~13 minecraft:wool 8
fill ~17~15~9 ~21~16~9 minecraft:wool 8
fill ~17~20~9 ~18~20~12 minecraft:wool 8
fill ~18~9~9 ~18~9~11 minecraft:wool 8
fill ~18~13~9 ~33~13~9 minecraft:wool 8
fill ~19~19~9 ~21~19~9 minecraft:wool 8
fill ~19~20~9 ~22~20~11 minecraft:wool 11
fill ~22~11~9 ~29~11~11 minecraft:wool 8
fill ~22~16~9 ~24~16~11 minecraft:wool 8
fill ~27~16~9 ~34~16~11 minecraft:wool 8
fill ~29~20~9 ~32~20~12 minecraft:wool 11
fill ~30~15~9 ~34~15~9 minecraft:wool 8
fill ~30~19~9 ~32~19~9 minecraft:wool 8
fill ~33~9~9 ~33~11~11 minecraft:wool 8
fill ~33~20~9 ~34~20~13 minecraft:wool 8
fill ~34~10~9 ~36~11~11 minecraft:wool 8
fill ~35~9~9 ~35~9~13 minecraft:wool 8
fill ~36~15~9 ~38~15~9 minecraft:concrete 0
fill ~36~16~9 ~36~17~9 minecraft:concrete 0
fill ~37~11~9 ~37~11~12 minecraft:wool 8
fill ~37~16~9 ~38~16~9 minecraft:sea_lantern
fill ~37~17~9 ~38~17~9 minecraft:concrete 0
fill ~37~19~9 ~38~19~13 minecraft:wool 8
fill ~38~12~9 ~39~12~12 minecraft:wool 8
fill ~38~13~9 ~39~13~10 minecraft:wool 8
setblock ~39~6~9 minecraft:wool 8
fill ~39~8~9 ~39~9~9 minecraft:wool 8
fill ~39~15~9 ~39~15~10 minecraft:stained_glass 15
fill ~39~16~9 ~39~16~10 minecraft:concrete 0
fill ~39~17~9 ~41~17~10 minecraft:stained_glass 15
fill ~39~18~9 ~39~18~13 minecraft:wool 8
fill ~40~3~9 ~41~3~9 minecraft:wool 8
fill ~40~6~9 ~40~7~9 minecraft:coal_block
fill ~40~9~9 ~40~10~9 minecraft:coal_block
fill ~40~16~9 ~42~16~10 minecraft:stained_glass 15
fill ~40~18~9 ~40~18~10 minecraft:stained_glass 15
fill ~41~9~9 ~44~9~9 minecraft:wool 8
fill ~41~10~9 ~42~10~9 minecraft:coal_block
fill ~41~14~9 ~45~14~11 minecraft:wool 8
fill ~42~4~9 ~43~4~9 minecraft:wool 8
fill ~42~11~9 ~43~13~9 minecraft:concrete 1
fill ~42~15~9 ~43~15~10 minecraft:stained_glass 15
fill ~43~3~9 ~44~3~10 minecraft:wool 8
fill ~43~10~9 ~45~10~9 minecraft:wool 8
setblock ~44~5~9 minecraft:wool 8
fill ~44~8~9 ~44~8~10 minecraft:wool 8
fill ~44~11~9 ~45~11~10 minecraft:wool 8
fill ~44~12~9 ~45~13~9 minecraft:wool 8
fill ~45~2~9 ~46~2~9 minecraft:wool 8
fill ~45~6~9 ~45~7~11 minecraft:wool 8
setblock ~47~2~9 minecraft:wool 11
fill ~3~2~10 ~3~3~10 minecraft:wool 11
fill ~4~2~10 ~5~3~10 minecraft:wool 8
fill ~5~10~10 ~6~10~10 minecraft:wool 8
fill ~5~11~10 ~5~14~10 minecraft:wool 8
fill ~6~3~10 ~6~5~10 minecraft:wool 8
fill ~6~8~10 ~6~8~11 minecraft:wool 8
setblock ~6~9~10 minecraft:wool 8
fill ~6~12~10 ~6~14~10 minecraft:wool 8
setblock ~7~4~10 minecraft:wool 8
fill ~7~5~10 ~10~5~10 minecraft:coal_block
fill ~7~6~10 ~9~7~10 minecraft:coal_block
fill ~7~9~10 ~9~10~10 minecraft:coal_block
fill ~7~12~10 ~7~13~10 minecraft:concrete 1
fill ~7~14~10 ~7~14~12 minecraft:wool 8
fill ~7~15~10 ~7~16~12 minecraft:stained_glass 15
fill ~8~4~10 ~11~4~10 minecraft:coal_block
fill ~8~8~10 ~10~8~10 minecraft:coal_block
fill ~8~16~10 ~8~17~10 minecraft:stained_glass 15
fill ~9~17~10 ~9~18~10 minecraft:stained_glass 15
setblock ~10~9~10 minecraft:wool 8
fill ~10~12~10 ~11~12~13 minecraft:wool 8
fill ~10~13~10 ~11~13~10 minecraft:wool 8
setblock ~10~18~10 minecraft:stained_glass 15
fill ~10~19~10 ~13~19~10 minecraft:wool 8
setblock ~11~6~10 minecraft:wool 8
fill ~12~11~10 ~13~11~12 minecraft:wool 8
fill ~12~14~10 ~14~14~10 minecraft:wool 8
fill ~13~10~10 ~14~10~12 minecraft:wool 8
setblock ~13~15~10 minecraft:concrete 0
fill ~13~16~10 ~15~16~12 minecraft:wool 8
setblock ~13~17~10 minecraft:concrete 0
fill ~14~8~10 ~37~8~11 minecraft:wool 8
fill ~14~9~10 ~15~9~12 minecraft:wool 8
fill ~14~12~10 ~14~13~12 minecraft:wool 8
fill ~14~15~10 ~15~15~12 minecraft:wool 8
fill ~14~17~10 ~15~17~12 minecraft:wool 8
setblock ~14~19~10 minecraft:wool 11
fill ~15~6~10 ~36~7~10 minecraft:wool 8
fill ~15~19~10 ~16~20~10 minecraft:wool 8
fill ~16~12~10 ~16~12~13 minecraft:wool 8
fill ~16~13~10 ~16~13~11 minecraft:wool 8
fill ~17~5~10 ~34~5~10 minecraft:wool 8
fill ~17~9~10 ~17~9~11 minecraft:wool 8
fill ~17~16~10 ~21~16~11 minecraft:wool 8
fill ~18~4~10 ~18~4~15 minecraft:wool 8
fill ~19~9~10 ~32~10~11 minecraft:wool 8
fill ~19~11~10 ~21~11~11 minecraft:wool 8
fill ~19~12~10 ~20~12~11 minecraft:wool 8
fill ~21~15~10 ~21~15~11 minecraft:wool 8
fill ~23~19~10 ~28~19~10 minecraft:wool 8
fill ~25~16~10 ~26~16~11 minecraft:wool 8
fill ~30~11~10 ~32~11~11 minecraft:wool 8
fill ~30~15~10 ~30~15~11 minecraft:wool 8
fill ~31~12~10 ~32~12~11 minecraft:wool 8
setblock ~33~4~10 minecraft:wool 8
fill ~34~9~10 ~34~9~11 minecraft:wool 8
fill ~35~12~10 ~35~12~13 minecraft:wool 8
fill ~35~13~10 ~35~13~11 minecraft:wool 8
fill ~35~19~10 ~36~20~10 minecraft:wool 8
fill ~36~9~10 ~37~9~12 minecraft:wool 8
fill ~36~15~10 ~37~17~12 minecraft:wool 8
fill ~37~10~10 ~38~10~12 minecraft:wool 8
fill ~37~12~10 ~37~14~12 minecraft:wool 8
fill ~38~11~10 ~39~11~12 minecraft:wool 8
fill ~38~14~10 ~39~14~10 minecraft:wool 8
setblock ~38~15~10 minecraft:concrete 0
fill ~38~16~10 ~38~16~13 minecraft:wool 8
setblock ~38~17~10 minecraft:concrete 0
fill ~39~19~10 ~41~19~13 minecraft:wool 8
fill ~40~4~10 ~43~4~10 minecraft:coal_block
setblock ~40~6~10 minecraft:wool 8
fill ~40~12~10 ~41~12~13 minecraft:wool 8
fill ~40~13~10 ~41~13~10 minecraft:wool 8
fill ~41~5~10 ~44~5~10 minecraft:coal_block
fill ~41~8~10 ~43~8~10 minecraft:coal_block
setblock ~41~9~10 minecraft:wool 8
fill ~41~18~10 ~42~18~10 minecraft:stained_glass 15
fill ~42~6~10 ~44~7~10 minecraft:coal_block
fill ~42~9~10 ~44~10~10 minecraft:coal_block
fill ~42~17~10 ~43~17~10 minecraft:stained_glass 15
fill ~43~16~10 ~44~16~10 minecraft:stained_glass 15
fill ~44~4~10 ~45~4~10 minecraft:wool 8
fill ~44~12~10 ~44~13~10 minecraft:concrete 1
fill ~44~15~10 ~44~15~12 minecraft:stained_glass 15
fill ~45~3~10 ~47~3~10 minecraft:wool 8
fill ~45~5~10 ~45~5~11 minecraft:wool 8
fill ~45~8~10 ~45~8~11 minecraft:wool 8
fill ~45~9~10 ~45~10~10 minecraft:wool 8
fill ~45~12~10 ~46~13~10 minecraft:wool 8
fill ~46~2~10 ~47~2~10 minecraft:wool 8
fill ~46~10~10 ~46~10~12 minecraft:wool 8
setblock ~46~11~10 minecraft:wool 8
fill ~46~14~10 ~46~14~13 minecraft:wool 8
fill ~48~2~10 ~48~3~10 minecraft:wool 11
fill ~3~2~11 ~4~2~13 minecraft:wool 8
fill ~3~3~11 ~5~3~11 minecraft:wool 8
fill ~5~4~11 ~6~5~11 minecraft:wool 8
fill ~5~6~11 ~5~6~13 minecraft:wool 8
fill ~5~7~11 ~5~7~12 minecraft:wool 11
fill ~5~8~11 ~5~8~13 minecraft:wool 8
fill ~5~9~11 ~5~9~12 minecraft:wool 11
fill ~5~10~11 ~5~10~12 minecraft:wool 8
fill ~5~11~11 ~5~13~11 minecraft:wool 11
fill ~5~14~11 ~6~14~12 minecraft:wool 8
fill ~6~15~11 ~6~15~12 minecraft:wool 7
fill ~6~16~11 ~6~16~12 minecraft:stained_glass 15
fill ~7~4~11 ~8~5~11 minecraft:coal_block
fill ~7~6~11 ~9~6~11 minecraft:wool 8
fill ~7~8~11 ~7~10~11 minecraft:coal_block
fill ~7~17~11 ~7~18~12 minecraft:stained_glass 15
fill ~8~8~11 ~8~9~11 minecraft:wool 8
fill ~8~13~11 ~10~13~11 minecraft:wool 8
fill ~8~15~11 ~8~15~12 minecraft:stained_glass 15
fill ~8~16~11 ~8~17~12 minecraft:concrete 0
fill ~8~18~11 ~8~18~12 minecraft:stained_glass 15
fill ~8~19~11 ~10~19~11 minecraft:wool 8
setblock ~9~5~11 minecraft:wool 8
fill ~9~12~11 ~9~12~13 minecraft:wool 8
fill ~9~15~11 ~12~15~11 minecraft:concrete 0
fill ~9~16~11 ~11~17~11 minecraft:sea_lantern
fill ~9~18~11 ~11~18~11 minecraft:concrete 0
fill ~10~7~11 ~11~7~11 minecraft:coal_block
setblock ~10~8~11 minecraft:coal_block
fill ~11~8~11 ~13~9~12 minecraft:wool 8
fill ~11~10~11 ~12~10~13 minecraft:wool 8
fill ~11~11~11 ~11~11~13 minecraft:wool 8
setblock ~11~19~11 minecraft:wool 11
fill ~12~7~11 ~39~7~13 minecraft:wool 8
fill ~12~16~11 ~12~16~13 minecraft:wool 8
setblock ~12~17~11 minecraft:concrete 0
fill ~12~19~11 ~12~19~13 minecraft:wool 8
fill ~13~13~11 ~13~15~12 minecraft:wool 8
fill ~13~17~11 ~13~17~13 minecraft:wool 8
setblock ~13~19~11 minecraft:wool 11
fill ~14~6~11 ~25~6~13 minecraft:wool 8
fill ~14~14~11 ~15~14~12 minecraft:wool 8
fill ~14~19~11 ~14~20~12 minecraft:wool 8
fill ~15~12~11 ~15~13~13 minecraft:wool 8
setblock ~15~20~11 minecraft:wool 11
fill ~16~4~11 ~17~4~15 minecraft:wool 8
fill ~16~5~11 ~25~5~11 minecraft:wool 8
fill ~16~19~11 ~27~19~12 minecraft:wool 8
fill ~16~20~11 ~16~20~13 minecraft:wool 8
fill ~17~12~11 ~18~15~11 minecraft:wool 8
fill ~19~4~11 ~25~4~15 minecraft:wool 8
fill ~19~13~11 ~34~14~11 minecraft:wool 8
fill ~19~15~11 ~20~15~11 minecraft:wool 8
fill ~21~12~11 ~30~12~11 minecraft:wool 8
fill ~22~15~11 ~29~15~11 minecraft:wool 8
fill ~26~4~11 ~33~4~15 minecraft:obsidian
fill ~26~5~11 ~33~6~11 minecraft:obsidian
fill ~28~18~11 ~32~19~12 minecraft:wool 11
fill ~31~15~11 ~34~15~11 minecraft:wool 8
fill ~33~12~11 ~34~12~11 minecraft:wool 8
fill ~33~19~11 ~35~19~12 minecraft:wool 8
fill ~34~4~11 ~35~4~15 minecraft:wool 8
fill ~34~5~11 ~35~6~11 minecraft:wool 8
fill ~35~20~11 ~37~20~13 minecraft:wool 8
fill ~36~6~11 ~37~6~13 minecraft:wool 8
fill ~36~12~11 ~36~14~13 minecraft:wool 8
fill ~38~8~11 ~40~9~12 minecraft:wool 8
fill ~38~13~11 ~38~15~12 minecraft:wool 8
fill ~38~17~11 ~38~17~13 minecraft:wool 8
fill ~39~10~11 ~40~10~13 minecraft:wool 8
fill ~39~15~11 ~42~15~11 minecraft:concrete 0
fill ~39~16~11 ~39~16~13 minecraft:wool 8
setblock ~39~17~11 minecraft:concrete 0
fill ~40~11~11 ~40~11~13 minecraft:wool 8
fill ~40~16~11 ~42~17~11 minecraft:sea_lantern
fill ~40~18~11 ~42~18~11 minecraft:concrete 0
fill ~41~13~11 ~43~13~11 minecraft:wool 8
fill ~42~5~11 ~42~6~11 minecraft:wool 8
fill ~42~12~11 ~42~12~13 minecraft:wool 8
fill ~42~19~11 ~43~19~24 minecraft:wool 8
fill ~43~4~11 ~44~5~11 minecraft:coal_block
fill ~43~6~11 ~44~6~11 minecraft:wool 8
fill ~43~8~11 ~43~9~11 minecraft:wool 8
fill ~43~15~11 ~43~15~12 minecraft:stained_glass 15
fill ~43~16~11 ~43~17~12 minecraft:concrete 0
fill ~43~18~11 ~44~18~12 minecraft:stained_glass 15
fill ~44~8~11 ~44~10~11 minecraft:coal_block
fill ~44~16~11 ~45~16~12 minecraft:stained_glass 15
fill ~44~17~11 ~44~17~12 minecraft:stained_glass 15
fill ~45~4~11 ~46~4~11 minecraft:wool 8
fill ~45~15~11 ~45~15~12 minecraft:wool 7
fill ~46~3~11 ~48~3~11 minecraft:wool 8
fill ~46~5~11 ~46~6~13 minecraft:wool 8
setblock ~46~7~11 minecraft:wool 11
fill ~46~8~11 ~46~8~13 minecraft:wool 8
setblock ~46~9~11 minecraft:wool 11
setblock ~46~11~11 minecraft:wool 11
fill ~46~12~11 ~46~12~12 minecraft:wool 8
setblock ~46~13~11 minecraft:wool 11
fill ~47~2~11 ~48~2~13 minecraft:wool 8
fill ~2~2~12 ~2~4~13 minecraft:wool 11
fill ~3~3~12 ~3~4~12 minecraft:wool 8
fill ~4~4~12 ~5~4~13 minecraft:wool 8
fill ~4~10~12 ~4~10~19 minecraft:wool 8
fill ~4~11~12 ~5~11~12 minecraft:wool 8
fill ~4~12~12 ~4~12~14 minecraft:wool 11
fill ~4~13~12 ~5~13~12 minecraft:wool 8
setblock ~5~3~12 minecraft:wool 8
fill ~5~5~12 ~5~5~13 minecraft:wool 8
setblock ~5~12~12 minecraft:wool 8
fill ~5~15~12 ~5~15~13 minecraft:wool 7
setblock ~6~17~12 minecraft:stained_glass 15
setblock ~6~18~12 minecraft:wool 8
fill ~7~19~12 ~7~19~14 minecraft:wool 7
fill ~8~12~12 ~8~14~14 minecraft:wool 8
fill ~8~19~12 ~8~19~24 minecraft:wool 8
setblock ~9~15~12 minecraft:concrete 0
fill ~9~16~12 ~11~17~13 minecraft:wool 8
setblock ~9~18~12 minecraft:concrete 0
fill ~9~19~12 ~10~19~12 minecraft:wool 11
fill ~10~6~12 ~13~6~12 minecraft:wool 8
fill ~10~7~12 ~11~7~13 minecraft:wool 8
fill ~10~8~12 ~10~11~13 minecraft:wool 8
fill ~10~13~12 ~12~15~12 minecraft:wool 8
fill ~10~18~12 ~11~18~13 minecraft:wool 8
fill ~11~4~12 ~15~4~15 minecraft:wool 8
fill ~11~5~12 ~16~5~12 minecraft:wool 8
fill ~11~19~12 ~11~19~13 minecraft:wool 8
fill ~11~20~12 ~12~20~12 minecraft:wool 11
fill ~12~17~12 ~12~17~13 minecraft:wool 8
fill ~13~19~12 ~13~20~13 minecraft:wool 8
fill ~14~8~12 ~16~8~12 minecraft:wool 8
fill ~14~11~12 ~16~11~12 minecraft:wool 8
fill ~15~10~12 ~16~10~13 minecraft:wool 8
fill ~15~19~12 ~15~20~12 minecraft:wool 8
fill ~18~21~12 ~18~21~17 minecraft:wool 8
fill ~19~20~12 ~23~20~12 minecraft:wool 8
fill ~19~21~12 ~23~21~15 minecraft:wool 11
fill ~24~21~12 ~27~21~15 minecraft:wool 8
fill ~26~6~12 ~33~6~13 minecraft:obsidian
fill ~28~21~12 ~32~21~15 minecraft:wool 11
fill ~33~21~12 ~33~21~17 minecraft:wool 8
fill ~34~6~12 ~35~6~13 minecraft:wool 8
fill ~35~5~12 ~40~5~12 minecraft:wool 8
fill ~35~8~12 ~37~8~12 minecraft:wool 8
fill ~35~10~12 ~36~11~13 minecraft:wool 8
setblock ~35~18~12 minecraft:wool 8
fill ~36~4~12 ~40~4~15 minecraft:wool 8
fill ~36~19~12 ~36~19~13 minecraft:wool 8
fill ~38~6~12 ~41~6~12 minecraft:wool 8
fill ~38~20~12 ~40~20~13 minecraft:wool 8
fill ~39~13~12 ~41~15~12 minecraft:wool 8
fill ~39~17~12 ~42~17~13 minecraft:wool 8
fill ~40~7~12 ~41~7~13 minecraft:wool 8
fill ~40~16~12 ~42~16~13 minecraft:wool 8
fill ~40~18~12 ~41~18~13 minecraft:wool 8
fill ~41~8~12 ~41~11~13 minecraft:wool 8
setblock ~42~15~12 minecraft:concrete 0
setblock ~42~18~12 minecraft:concrete 0
fill ~43~12~12 ~43~14~14 minecraft:wool 8
fill ~44~14~12 ~45~14~12 minecraft:wool 8
fill ~44~19~12 ~44~19~14 minecraft:wool 7
setblock ~45~17~12 minecraft:stained_glass 15
setblock ~45~18~12 minecraft:wool 8
fill ~46~3~12 ~46~4~12 minecraft:wool 8
fill ~46~7~12 ~46~7~13 minecraft:wool 8
setblock ~46~9~12 minecraft:wool 8
fill ~46~11~12 ~47~11~12 minecraft:wool 8
fill ~46~13~12 ~47~13~12 minecraft:wool 8
fill ~46~15~12 ~46~15~13 minecraft:wool 7
fill ~47~4~12 ~48~4~13 minecraft:wool 8
fill ~47~10~12 ~47~10~19 minecraft:wool 8
fill ~47~12~12 ~47~12~14 minecraft:wool 11
setblock ~48~3~12 minecraft:wool 8
fill ~49~2~12 ~49~4~13 minecraft:wool 11
setblock ~3~4~13 minecraft:wool 8
fill ~4~3~13 ~4~3~15 minecraft:wool 8
fill ~4~5~13 ~4~6~19 minecraft:wool 8
setblock ~4~7~13 minecraft:wool 11
fill ~4~8~13 ~4~8~19 minecraft:wool 8
setblock ~4~9~13 minecraft:wool 11
setblock ~4~11~13 minecraft:wool 11
setblock ~4~13~13 minecraft:wool 11
fill ~4~14~13 ~5~14~13 minecraft:wool 8
setblock ~5~7~13 minecraft:wool 8
fill ~5~16~13 ~5~18~15 minecraft:wool 8
fill ~6~15~13 ~8~15~13 minecraft:concrete 0
fill ~6~16~13 ~7~18~13 minecraft:concrete 0
fill ~6~19~13 ~6~19~17 minecraft:wool 8
fill ~8~16~13 ~8~17~14 minecraft:wool 8
setblock ~8~18~13 minecraft:concrete 0
fill ~9~5~13 ~10~6~13 minecraft:wool 8
fill ~9~7~13 ~9~10~14 minecraft:wool 8
setblock ~9~11~13 minecraft:wool 8
fill ~9~13~13 ~10~15~13 minecraft:wool 8
fill ~9~18~13 ~9~18~31 minecraft:wool 8
fill ~9~19~13 ~10~19~16 minecraft:wool 8
fill ~9~20~13 ~10~20~13 minecraft:wool 11
fill ~10~4~13 ~10~4~16 minecraft:wool 8
fill ~11~8~13 ~11~9~14 minecraft:wool 8
fill ~11~20~13 ~12~20~14 minecraft:wool 8
fill ~12~11~13 ~12~12~13 minecraft:wool 8
setblock ~13~10~13 minecraft:wool 8
fill ~13~15~13 ~13~15~16 minecraft:concrete 15
setblock ~13~16~13 minecraft:wool 8
setblock ~13~18~13 minecraft:wool 8
fill ~14~15~13 ~35~19~14 minecraft:stone 5
fill ~14~20~13 ~15~20~13 minecraft:wool 8
fill ~15~8~13 ~36~8~13 minecraft:wool 8
setblock ~15~9~13 minecraft:wool 8
fill ~15~11~13 ~34~11~13 minecraft:wool 8
fill ~15~14~13 ~35~14~13 minecraft:wool 8
fill ~15~21~13 ~17~21~13 minecraft:wool 8
setblock ~16~5~13 minecraft:wool 8
fill ~16~13~13 ~35~13~13 minecraft:wool 8
fill ~17~9~13 ~34~10~13 minecraft:wool 8
fill ~17~12~13 ~34~12~13 minecraft:wool 8
fill ~27~20~13 ~28~20~14 minecraft:stone_block_slab 5
fill ~34~21~13 ~36~21~17 minecraft:wool 8
setblock ~35~5~13 minecraft:wool 8
setblock ~36~9~13 minecraft:wool 8
fill ~36~15~13 ~36~15~24 minecraft:concrete 15
fill ~36~16~13 ~37~17~13 minecraft:wool 8
setblock ~38~10~13 minecraft:wool 8
fill ~39~11~13 ~39~12~13 minecraft:wool 8
fill ~39~15~13 ~42~15~13 minecraft:wool 8
fill ~40~8~13 ~40~9~14 minecraft:wool 8
fill ~41~4~13 ~41~4~16 minecraft:wool 8
fill ~41~5~13 ~42~6~13 minecraft:wool 8
fill ~41~13~13 ~42~14~13 minecraft:wool 8
fill ~41~20~13 ~42~20~17 minecraft:wool 8
fill ~42~7~13 ~42~10~14 minecraft:wool 8
setblock ~42~11~13 minecraft:wool 8
fill ~42~18~13 ~42~18~16 minecraft:wool 8
fill ~43~15~13 ~45~15~13 minecraft:concrete 0
fill ~43~16~13 ~43~17~14 minecraft:wool 8
fill ~43~18~13 ~45~18~13 minecraft:concrete 0
fill ~44~16~13 ~45~17~13 minecraft:concrete 0
fill ~45~19~13 ~45~19~17 minecraft:wool 8
setblock ~46~4~13 minecraft:wool 8
fill ~46~16~13 ~46~18~15 minecraft:wool 8
fill ~47~3~13 ~47~3~15 minecraft:wool 8
fill ~47~5~13 ~47~6~19 minecraft:wool 8
fill ~47~7~13 ~47~7~14 minecraft:wool 11
fill ~47~8~13 ~47~8~19 minecraft:wool 8
fill ~47~9~13 ~47~9~14 minecraft:wool 11
setblock ~47~11~13 minecraft:wool 11
setblock ~47~13~13 minecraft:wool 11
fill ~47~14~13 ~47~14~16 minecraft:wool 8
fill ~2~2~14 ~3~2~19 minecraft:wool 8
fill ~2~3~14 ~2~5~15 minecraft:wool 8
fill ~3~5~14 ~3~5~19 minecraft:wool 8
fill ~4~4~14 ~4~4~19 minecraft:wool 8
fill ~4~7~14 ~4~7~19 minecraft:wool 8
fill ~4~9~14 ~4~9~19 minecraft:wool 8
fill ~4~11~14 ~4~11~19 minecraft:wool 8
fill ~4~13~14 ~4~14~14 minecraft:wool 8
fill ~4~15~14 ~4~15~17 minecraft:wool 7
fill ~5~15~14 ~9~15~14 minecraft:wool 8
fill ~6~16~14 ~7~18~15 minecraft:wool 8
fill ~7~10~14 ~8~11~14 minecraft:wool 8
fill ~7~12~14 ~7~14~15 minecraft:wool 8
fill ~8~5~14 ~9~6~14 minecraft:wool 8
fill ~8~7~14 ~8~9~15 minecraft:wool 8
fill ~8~18~14 ~8~18~15 minecraft:wool 8
fill ~8~20~14 ~10~20~15 minecraft:wool 8
fill ~9~4~14 ~9~4~17 minecraft:wool 8
fill ~9~16~14 ~10~17~14 minecraft:wool 8
fill ~10~15~14 ~12~15~20 minecraft:concrete 15
fill ~10~18~14 ~10~18~16 minecraft:wool 8
fill ~13~21~14 ~14~21~14 minecraft:wool 8
fill ~15~21~14 ~15~21~15 minecraft:wool 11
fill ~16~21~14 ~17~21~17 minecraft:wool 8
fill ~37~15~14 ~40~15~20 minecraft:concrete 15
fill ~37~21~14 ~38~21~19 minecraft:wool 8
fill ~39~20~14 ~40~20~14 minecraft:wool 8
fill ~41~16~14 ~42~17~14 minecraft:wool 8
fill ~41~18~14 ~41~18~17 minecraft:wool 8
fill ~41~19~14 ~41~19~16 minecraft:wool 8
fill ~42~4~14 ~42~4~17 minecraft:wool 8
fill ~42~5~14 ~43~6~14 minecraft:wool 8
fill ~42~15~14 ~46~15~14 minecraft:wool 8
fill ~43~7~14 ~43~9~15 minecraft:wool 8
fill ~43~10~14 ~44~11~14 minecraft:wool 8
fill ~43~18~14 ~45~18~15 minecraft:wool 8
fill ~43~20~14 ~43~20~23 minecraft:wool 8
fill ~44~12~14 ~44~14~15 minecraft:wool 8
fill ~44~16~14 ~45~17~15 minecraft:wool 8
fill ~47~4~14 ~47~4~19 minecraft:wool 8
fill ~47~11~14 ~47~11~19 minecraft:wool 8
setblock ~47~13~14 minecraft:wool 8
fill ~47~15~14 ~47~15~17 minecraft:wool 7
fill ~48~2~14 ~49~2~19 minecraft:wool 8
fill ~48~5~14 ~49~5~15 minecraft:wool 8
fill ~49~3~14 ~49~4~15 minecraft:wool 8
fill ~1~2~15 ~1~4~16 minecraft:wool 11
setblock ~1~5~15 minecraft:wool 8
setblock ~3~7~15 minecraft:wool 11
fill ~3~8~15 ~3~8~19 minecraft:wool 8
setblock ~3~9~15 minecraft:wool 11
fill ~3~10~15 ~3~10~19 minecraft:wool 8
setblock ~3~11~15 minecraft:wool 11
fill ~3~12~15 ~4~12~20 minecraft:wool 8
setblock ~4~13~15 minecraft:wool 11
fill ~4~14~15 ~4~14~16 minecraft:wool 8
fill ~4~16~15 ~4~16~23 minecraft:wool 8
fill ~5~15~15 ~8~15~15 minecraft:wool 8
fill ~6~9~15 ~7~11~15 minecraft:wool 8
fill ~6~12~15 ~6~14~16 minecraft:wool 8
fill ~7~4~15 ~8~4~18 minecraft:wool 8
fill ~7~5~15 ~8~6~15 minecraft:wool 8
fill ~7~7~15 ~7~8~16 minecraft:wool 8
setblock ~7~19~15 minecraft:wool 8
fill ~7~20~15 ~7~20~18 minecraft:wool 7
setblock ~8~17~15 minecraft:wool 8
fill ~10~16~15 ~10~17~16 minecraft:wool 8
fill ~11~21~15 ~12~21~15 minecraft:wool 8
fill ~12~5~15 ~25~5~19 minecraft:wool 8
fill ~13~21~15 ~14~21~15 minecraft:wool 11
fill ~14~15~15 ~35~19~15 minecraft:stained_hardened_clay 15
fill ~21~10~15 ~30~14~15 minecraft:wool 8
fill ~26~5~15 ~33~5~19 minecraft:obsidian
fill ~34~5~15 ~39~5~19 minecraft:wool 8
fill ~37~16~15 ~38~19~18 minecraft:stone 0
fill ~39~21~15 ~40~21~20 minecraft:wool 8
setblock ~40~20~15 minecraft:wool 8
fill ~41~16~15 ~41~17~15 minecraft:wool 8
fill ~43~4~15 ~44~4~18 minecraft:wool 8
fill ~43~5~15 ~44~6~15 minecraft:wool 8
fill ~43~15~15 ~46~15~15 minecraft:wool 8
setblock ~43~17~15 minecraft:wool 8
fill ~44~7~15 ~44~8~16 minecraft:wool 8
fill ~44~9~15 ~45~11~15 minecraft:wool 8
setblock ~44~19~15 minecraft:wool 8
fill ~44~20~15 ~44~20~18 minecraft:wool 7
fill ~45~12~15 ~45~14~16 minecraft:wool 8
fill ~47~7~15 ~47~7~19 minecraft:wool 8
fill ~47~9~15 ~47~9~19 minecraft:wool 8
fill ~47~12~15 ~47~12~20 minecraft:wool 8
setblock ~47~13~15 minecraft:wool 11
fill ~47~16~15 ~47~16~23 minecraft:wool 8
setblock ~48~7~15 minecraft:wool 11
fill ~48~8~15 ~48~8~19 minecraft:wool 8
setblock ~48~9~15 minecraft:wool 11
fill ~48~10~15 ~48~10~19 minecraft:wool 8
fill ~48~11~15 ~48~12~15 minecraft:wool 11
fill ~50~2~15 ~50~4~16 minecraft:wool 11
setblock ~50~5~15 minecraft:wool 8
fill ~1~5~16 ~1~6~17 minecraft:wool 11
fill ~2~6~16 ~3~6~19 minecraft:wool 8
fill ~2~8~16 ~2~10~16 minecraft:wool 8
fill ~3~3~16 ~3~4~19 minecraft:wool 8
fill ~3~7~16 ~3~7~19 minecraft:wool 8
fill ~3~9~16 ~3~9~19 minecraft:wool 8
fill ~3~11~16 ~3~11~19 minecraft:wool 8
fill ~3~13~16 ~5~13~17 minecraft:wool 8
fill ~3~14~16 ~3~14~21 minecraft:wool 8
fill ~4~17~16 ~5~17~16 minecraft:wool 8
fill ~5~6~16 ~7~6~16 minecraft:wool 8
fill ~5~8~16 ~6~11~16 minecraft:wool 8
fill ~5~12~16 ~5~12~17 minecraft:wool 8
fill ~5~15~16 ~7~15~16 minecraft:wool 8
fill ~5~18~16 ~5~19~18 minecraft:wool 8
fill ~6~4~16 ~6~4~19 minecraft:wool 8
fill ~6~5~16 ~7~5~16 minecraft:wool 8
setblock ~6~7~16 minecraft:wool 8
fill ~6~20~16 ~6~20~21 minecraft:wool 8
fill ~8~20~16 ~8~20~23 minecraft:wool 8
setblock ~9~20~16 minecraft:wool 11
fill ~10~20~16 ~10~21~16 minecraft:wool 8
fill ~11~5~16 ~11~5~19 minecraft:wool 8
fill ~11~21~16 ~11~21~17 minecraft:wool 11
fill ~12~21~16 ~12~21~18 minecraft:wool 8
setblock ~13~21~16 minecraft:wool 11
fill ~14~15~16 ~24~15~16 minecraft:concrete 15
fill ~14~21~16 ~15~21~17 minecraft:wool 8
fill ~19~21~16 ~22~21~16 minecraft:wool 11
fill ~21~10~16 ~21~14~16 minecraft:wool 8
fill ~23~22~16 ~23~22~20 minecraft:wool 11
fill ~24~22~16 ~27~22~20 minecraft:wool 8
fill ~25~15~16 ~33~16~16 minecraft:stained_hardened_clay 15
fill ~26~17~16 ~32~17~16 minecraft:stained_hardened_clay 15
fill ~28~18~16 ~30~18~16 minecraft:stained_hardened_clay 15
fill ~28~22~16 ~28~22~20 minecraft:wool 11
fill ~29~21~16 ~32~21~16 minecraft:wool 11
fill ~30~10~16 ~30~14~16 minecraft:wool 8
fill ~34~15~16 ~35~15~27 minecraft:concrete 15
fill ~39~16~16 ~40~19~18 minecraft:stone 0
fill ~40~5~16 ~40~5~19 minecraft:wool 8
setblock ~41~17~16 minecraft:wool 8
fill ~41~21~16 ~41~21~23 minecraft:wool 8
fill ~44~5~16 ~45~6~16 minecraft:wool 8
fill ~44~15~16 ~46~15~16 minecraft:wool 8
fill ~45~4~16 ~45~4~19 minecraft:wool 8
fill ~45~7~16 ~45~11~16 minecraft:wool 8
fill ~45~20~16 ~45~20~21 minecraft:wool 8
fill ~46~6~16 ~46~6~17 minecraft:wool 8
fill ~46~8~16 ~46~13~17 minecraft:wool 8
fill ~46~17~16 ~47~17~16 minecraft:wool 8
fill ~46~18~16 ~46~19~18 minecraft:wool 8
fill ~47~13~16 ~48~13~20 minecraft:wool 8
fill ~48~3~16 ~48~7~19 minecraft:wool 8
fill ~48~9~16 ~49~9~16 minecraft:wool 8
fill ~48~11~16 ~48~12~19 minecraft:wool 8
fill ~48~14~16 ~48~14~21 minecraft:wool 8
fill ~49~6~16 ~49~6~19 minecraft:wool 8
setblock ~49~8~16 minecraft:wool 8
setblock ~49~10~16 minecraft:wool 8
fill ~50~5~16 ~50~6~17 minecraft:wool 11
fill ~1~2~17 ~1~3~17 minecraft:wool 8
setblock ~1~4~17 minecraft:wool 11
fill ~2~7~17 ~2~7~19 minecraft:wool 8
fill ~2~11~17 ~2~12~17 minecraft:wool 8
fill ~3~15~17 ~3~15~19 minecraft:wool 7
fill ~4~17~17 ~4~17~25 minecraft:wool 8
fill ~5~4~17 ~5~4~19 minecraft:wool 8
fill ~5~5~17 ~6~5~17 minecraft:wool 8
fill ~5~6~17 ~5~11~17 minecraft:wool 8
fill ~5~14~17 ~5~15~18 minecraft:wool 8
setblock ~6~15~17 minecraft:wool 8
fill ~8~15~17 ~8~15~21 minecraft:wool 8
fill ~8~16~17 ~9~16~17 minecraft:wool 8
fill ~8~18~17 ~8~18~26 minecraft:wool 8
fill ~9~17~17 ~9~17~25 minecraft:wool 8
fill ~9~19~17 ~9~19~26 minecraft:wool 8
fill ~9~20~17 ~9~20~23 minecraft:wool 8
fill ~9~21~17 ~9~21~18 minecraft:wool 8
fill ~10~5~17 ~10~5~19 minecraft:wool 8
fill ~10~16~17 ~11~17~18 minecraft:concrete 14
setblock ~10~21~17 minecraft:wool 11
fill ~13~15~17 ~14~15~17 minecraft:stone 6
setblock ~13~21~17 minecraft:wool 8
fill ~15~15~17 ~31~15~17 minecraft:concrete 15
setblock ~19~21~17 minecraft:wool 11
fill ~20~22~17 ~22~22~20 minecraft:wool 11
fill ~21~11~17 ~21~14~26 minecraft:wool 8
fill ~29~22~17 ~31~22~20 minecraft:wool 11
fill ~30~11~17 ~30~14~26 minecraft:wool 8
fill ~32~15~17 ~33~16~19 minecraft:stone 5
setblock ~32~21~17 minecraft:wool 11
fill ~41~5~17 ~41~5~19 minecraft:wool 8
fill ~42~16~17 ~43~16~17 minecraft:wool 8
fill ~42~21~17 ~42~21~22 minecraft:wool 8
fill ~43~15~17 ~43~15~21 minecraft:wool 8
fill ~43~18~17 ~43~18~26 minecraft:wool 8
fill ~45~5~17 ~46~5~17 minecraft:wool 8
fill ~45~15~17 ~46~15~17 minecraft:wool 8
fill ~46~4~17 ~46~4~19 minecraft:wool 8
setblock ~46~7~17 minecraft:wool 8
fill ~46~14~17 ~46~14~18 minecraft:wool 8
fill ~47~17~17 ~47~17~25 minecraft:wool 8
fill ~48~9~17 ~48~9~19 minecraft:wool 8
fill ~48~15~17 ~48~15~19 minecraft:wool 7
fill ~49~7~17 ~49~7~19 minecraft:wool 8
fill ~49~11~17 ~49~12~17 minecraft:wool 8
fill ~50~2~17 ~50~3~17 minecraft:wool 8
setblock ~50~4~17 minecraft:wool 11
fill ~1~2~18 ~1~2~19 minecraft:wool 11
fill ~1~3~18 ~1~7~18 minecraft:wool 8
fill ~1~12~18 ~2~12~18 minecraft:wool 8
fill ~2~13~18 ~4~13~20 minecraft:wool 8
fill ~2~14~18 ~2~14~21 minecraft:wool 8
fill ~3~16~18 ~3~16~23 minecraft:wool 8
fill ~4~14~18 ~4~15~21 minecraft:wool 8
fill ~4~18~18 ~4~18~22 minecraft:wool 8
fill ~5~20~18 ~5~20~25 minecraft:wool 8
fill ~8~17~18 ~8~17~25 minecraft:wool 8
fill ~8~21~18 ~8~21~24 minecraft:wool 8
fill ~9~5~18 ~9~5~19 minecraft:wool 8
fill ~9~15~18 ~9~16~19 minecraft:wool 8
fill ~10~21~18 ~11~21~18 minecraft:wool 8
fill ~12~16~18 ~12~17~18 minecraft:concrete 14
fill ~13~15~18 ~16~15~18 minecraft:concrete 15
fill ~13~21~18 ~15~21~18 minecraft:wool 11
fill ~14~16~18 ~15~16~18 minecraft:stone 6
setblock ~16~21~18 minecraft:wool 8
fill ~17~15~18 ~17~15~19 minecraft:stone 5
fill ~17~22~18 ~18~22~21 minecraft:wool 8
fill ~18~15~18 ~31~15~19 minecraft:concrete 15
fill ~19~22~18 ~19~22~21 minecraft:wool 11
setblock ~20~19~18 minecraft:stone_button 2
setblock ~21~16~18 minecraft:stone_button 2
setblock ~21~17~18 minecraft:nether_brick_stairs 4
setblock ~21~18~18 minecraft:nether_brick_stairs 0
setblock ~22~17~18 minecraft:nether_brick_stairs 5
setblock ~22~18~18 minecraft:nether_brick_stairs 1
fill ~29~16~18 ~30~16~18 minecraft:stone_button 2
setblock ~29~20~18 minecraft:stone_button 2
fill ~32~17~18 ~33~17~34 minecraft:stone 5
fill ~32~22~18 ~32~22~21 minecraft:wool 11
fill ~33~22~18 ~34~22~21 minecraft:wool 8
fill ~35~21~18 ~36~21~18 minecraft:wool 8
setblock ~37~20~18 minecraft:stone_block_slab 5
setblock ~39~20~18 minecraft:stone_block_slab 5
fill ~41~15~18 ~42~17~19 minecraft:wool 8
fill ~41~20~18 ~41~20~26 minecraft:wool 8
fill ~42~5~18 ~42~5~19 minecraft:wool 8
fill ~43~17~18 ~43~17~25 minecraft:wool 8
fill ~43~21~18 ~43~21~23 minecraft:wool 8
fill ~46~15~18 ~47~15~18 minecraft:wool 8
fill ~46~20~18 ~46~20~25 minecraft:wool 8
fill ~47~14~18 ~47~14~21 minecraft:wool 8
fill ~47~18~18 ~47~18~22 minecraft:wool 8
fill ~48~16~18 ~48~16~23 minecraft:wool 8
fill ~49~12~18 ~50~12~18 minecraft:wool 8
fill ~49~13~18 ~49~14~20 minecraft:wool 8
fill ~50~2~18 ~50~2~19 minecraft:wool 11
fill ~50~3~18 ~50~7~18 minecraft:wool 8
fill ~1~3~19 ~1~6~19 minecraft:wool 11
fill ~1~7~19 ~1~13~19 minecraft:wool 8
fill ~2~3~19 ~2~5~19 minecraft:wool 8
fill ~2~15~19 ~2~15~21 minecraft:wool 7
fill ~3~17~19 ~3~17~25 minecraft:wool 8
fill ~5~5~19 ~8~11~19 minecraft:wool 8
fill ~5~19~19 ~5~19~21 minecraft:wool 8
setblock ~7~4~19 minecraft:wool 8
fill ~7~16~19 ~8~16~23 minecraft:wool 8
fill ~7~20~19 ~7~20~37 minecraft:wool 8
fill ~7~21~19 ~7~21~23 minecraft:wool 7
fill ~9~6~19 ~13~11~19 minecraft:wool 8
fill ~9~21~19 ~9~21~20 minecraft:wool 11
setblock ~10~21~19 minecraft:wool 8
fill ~11~16~19 ~11~17~19 minecraft:concrete 14
fill ~11~21~19 ~12~21~19 minecraft:wool 11
fill ~12~16~19 ~13~16~19 minecraft:stone 5
fill ~13~15~19 ~15~15~20 minecraft:concrete 15
setblock ~13~21~19 minecraft:wool 8
setblock ~14~21~19 minecraft:wool 11
fill ~15~16~19 ~16~16~19 minecraft:stone 6
fill ~15~22~19 ~16~22~20 minecraft:wool 8
fill ~16~15~19 ~16~15~20 minecraft:stone 5
fill ~16~17~19 ~16~17~20 minecraft:stone 6
fill ~19~17~19 ~20~18~19 minecraft:concrete 14
fill ~20~16~19 ~30~16~19 minecraft:concrete 14
fill ~20~19~19 ~30~19~19 minecraft:concrete 14
fill ~21~17~19 ~21~18~19 minecraft:stone 0
fill ~22~17~19 ~31~17~19 minecraft:concrete 14
setblock ~22~18~19 minecraft:stone 0
fill ~23~18~19 ~31~18~19 minecraft:concrete 14
fill ~25~20~19 ~29~20~21 minecraft:concrete 14
fill ~35~22~19 ~36~22~22 minecraft:wool 8
fill ~38~6~19 ~46~11~19 minecraft:wool 8
fill ~41~18~19 ~41~19~20 minecraft:wool 8
fill ~42~20~19 ~42~20~21 minecraft:wool 8
fill ~43~5~19 ~46~5~19 minecraft:wool 8
fill ~43~16~19 ~44~16~23 minecraft:wool 8
setblock ~44~4~19 minecraft:wool 8
fill ~44~20~19 ~44~20~37 minecraft:wool 8
fill ~44~21~19 ~44~21~23 minecraft:wool 7
fill ~46~19~19 ~46~19~21 minecraft:wool 8
fill ~47~15~19 ~47~15~21 minecraft:wool 8
fill ~48~17~19 ~48~17~25 minecraft:wool 8
fill ~49~3~19 ~49~5~19 minecraft:wool 8
fill ~49~15~19 ~49~15~21 minecraft:wool 7
fill ~50~3~19 ~50~6~19 minecraft:wool 11
fill ~50~7~19 ~50~13~19 minecraft:wool 8
fill ~1~13~20 ~1~14~20 minecraft:wool 8
fill ~1~15~20 ~1~15~21 minecraft:wool 7
fill ~2~7~20 ~8~10~20 minecraft:coal_block
fill ~2~16~20 ~2~16~23 minecraft:wool 8
fill ~3~15~20 ~3~15~21 minecraft:wool 8
fill ~4~19~20 ~4~19~25 minecraft:wool 8
fill ~5~12~20 ~13~13~20 minecraft:wool 8
fill ~5~14~20 ~8~14~21 minecraft:wool 8
fill ~5~15~20 ~7~15~21 minecraft:wool 8
fill ~5~16~20 ~6~17~23 minecraft:wool 8
fill ~6~21~20 ~6~21~26 minecraft:wool 8
fill ~7~17~20 ~7~17~25 minecraft:wool 8
fill ~9~16~20 ~9~16~23 minecraft:wool 8
setblock ~10~21~20 minecraft:wool 11
setblock ~11~21~20 minecraft:wool 8
setblock ~12~21~20 minecraft:wool 11
fill ~13~16~20 ~14~16~20 minecraft:stone 5
fill ~13~22~20 ~14~22~20 minecraft:wool 8
fill ~14~5~20 ~37~5~38 minecraft:wool 8
fill ~14~6~20 ~14~11~37 minecraft:wool 8
fill ~17~15~20 ~20~15~23 minecraft:concrete 15
fill ~17~17~20 ~17~18~20 minecraft:stone 6
fill ~19~17~20 ~19~18~21 minecraft:concrete 14
fill ~20~16~20 ~20~16~21 minecraft:concrete 14
fill ~20~19~20 ~24~19~21 minecraft:concrete 14
fill ~21~15~20 ~29~15~20 minecraft:concrete 14
fill ~30~15~20 ~31~15~23 minecraft:concrete 15
fill ~30~16~20 ~30~16~21 minecraft:concrete 14
fill ~30~19~20 ~30~19~21 minecraft:concrete 14
fill ~31~17~20 ~31~18~21 minecraft:concrete 14
fill ~32~16~20 ~33~16~34 minecraft:stone 5
fill ~36~16~20 ~37~19~20 minecraft:stained_hardened_clay 15
fill ~37~6~20 ~37~11~37 minecraft:wool 8
fill ~37~22~20 ~38~22~23 minecraft:wool 8
fill ~38~12~20 ~46~13~20 minecraft:wool 8
setblock ~38~16~20 minecraft:stone 5
fill ~38~18~20 ~40~19~20 minecraft:stained_hardened_clay 15
setblock ~41~15~20 minecraft:concrete 15
fill ~42~16~20 ~42~18~23 minecraft:wool 8
fill ~43~7~20 ~49~10~20 minecraft:coal_block
fill ~43~14~20 ~46~14~21 minecraft:wool 8
fill ~44~15~20 ~46~15~21 minecraft:wool 8
fill ~44~17~20 ~46~17~25 minecraft:wool 8
fill ~45~16~20 ~46~16~23 minecraft:wool 8
fill ~45~21~20 ~45~21~26 minecraft:wool 8
fill ~47~19~20 ~47~19~25 minecraft:wool 8
setblock ~48~12~20 minecraft:wool 8
fill ~48~15~20 ~48~15~21 minecraft:wool 8
fill ~49~16~20 ~49~16~23 minecraft:wool 8
fill ~50~13~20 ~50~14~20 minecraft:wool 8
fill ~50~15~20 ~50~15~21 minecraft:wool 7
fill ~1~7~21 ~1~10~21 minecraft:coal_block
setblock ~1~14~21 minecraft:wool 8
fill ~2~5~21 ~8~6~21 minecraft:coal_block
fill ~2~7~21 ~8~10~21 minecraft:concrete 8
fill ~2~11~21 ~8~12~21 minecraft:coal_block
fill ~2~17~21 ~2~17~25 minecraft:wool 8
fill ~3~18~21 ~3~18~44 minecraft:wool 8
fill ~9~7~21 ~9~10~21 minecraft:coal_block
fill ~9~14~21 ~13~15~21 minecraft:wool 8
fill ~9~21~21 ~10~21~21 minecraft:wool 8
fill ~10~16~21 ~11~18~21 minecraft:concrete 14
fill ~11~22~21 ~13~22~21 minecraft:wool 8
fill ~12~16~21 ~13~16~23 minecraft:wool 8
fill ~14~12~21 ~14~13~36 minecraft:wool 8
fill ~14~15~21 ~16~15~21 minecraft:concrete 15
fill ~14~16~21 ~16~16~21 minecraft:stone 5
fill ~14~22~21 ~15~22~21 minecraft:wool 11
fill ~16~22~21 ~16~22~22 minecraft:wool 8
fill ~17~18~21 ~18~18~22 minecraft:stone 6
setblock ~20~22~21 minecraft:wool 11
setblock ~21~15~21 minecraft:concrete 14
fill ~21~23~21 ~23~23~28 minecraft:wool 11
fill ~24~23~21 ~27~23~27 minecraft:wool 8
fill ~28~23~21 ~30~23~28 minecraft:wool 11
setblock ~29~15~21 minecraft:concrete 14
setblock ~31~22~21 minecraft:wool 11
fill ~36~16~21 ~36~19~23 minecraft:stained_hardened_clay 15
fill ~37~12~21 ~37~13~36 minecraft:wool 8
setblock ~37~15~21 minecraft:concrete 15
fill ~37~19~21 ~40~19~23 minecraft:stained_hardened_clay 15
fill ~38~14~21 ~42~15~21 minecraft:wool 8
fill ~38~16~21 ~39~16~23 minecraft:wool 8
fill ~39~22~21 ~40~22~24 minecraft:wool 8
fill ~40~16~21 ~41~17~21 minecraft:concrete 14
fill ~41~19~21 ~41~19~26 minecraft:wool 8
fill ~42~7~21 ~42~10~21 minecraft:coal_block
fill ~43~5~21 ~49~6~21 minecraft:coal_block
fill ~43~7~21 ~49~10~21 minecraft:concrete 8
fill ~43~11~21 ~49~12~21 minecraft:coal_block
fill ~48~18~21 ~48~18~44 minecraft:wool 8
fill ~49~14~21 ~50~14~21 minecraft:wool 8
fill ~49~17~21 ~49~17~25 minecraft:wool 8
fill ~50~7~21 ~50~10~21 minecraft:coal_block
fill ~1~5~22 ~1~6~22 minecraft:coal_block
fill ~1~7~22 ~3~10~22 minecraft:concrete 8
fill ~1~11~22 ~1~12~22 minecraft:coal_block
fill ~1~16~22 ~1~16~23 minecraft:wool 8
fill ~2~3~22 ~8~4~22 minecraft:coal_block
fill ~2~5~22 ~8~6~22 minecraft:concrete 8
fill ~2~11~22 ~8~12~22 minecraft:concrete 8
fill ~2~13~22 ~8~14~22 minecraft:coal_block
fill ~4~20~22 ~4~20~56 minecraft:wool 8
fill ~5~21~22 ~5~21~32 minecraft:wool 8
setblock ~7~19~22 minecraft:wool 8
fill ~9~5~22 ~9~6~22 minecraft:coal_block
fill ~9~7~22 ~9~10~22 minecraft:concrete 8
fill ~9~11~22 ~9~12~22 minecraft:coal_block
fill ~9~21~22 ~9~21~24 minecraft:wool 8
fill ~9~22~22 ~11~22~22 minecraft:wool 8
fill ~10~16~22 ~11~16~23 minecraft:wool 8
fill ~10~17~22 ~11~18~23 minecraft:concrete 14
fill ~12~17~22 ~14~17~22 minecraft:stone 0
fill ~12~22~22 ~12~22~23 minecraft:wool 11
fill ~13~22~22 ~13~22~23 minecraft:wool 8
fill ~14~14~22 ~14~15~35 minecraft:wool 8
setblock ~14~16~22 minecraft:wool 8
setblock ~14~22~22 minecraft:wool 11
fill ~15~15~22 ~16~15~28 minecraft:concrete 15
setblock ~15~22~22 minecraft:wool 8
fill ~17~23~22 ~18~23~29 minecraft:wool 8
fill ~19~23~22 ~20~23~28 minecraft:wool 11
fill ~20~17~22 ~20~18~36 minecraft:concrete 14
fill ~21~15~22 ~21~15~23 minecraft:concrete 15
fill ~21~16~22 ~21~16~36 minecraft:stone 0
fill ~21~18~22 ~23~18~36 minecraft:concrete 14
fill ~22~15~22 ~22~15~36 minecraft:stone 0
fill ~24~18~22 ~24~18~32 minecraft:stained_hardened_clay 15
fill ~25~19~22 ~25~19~32 minecraft:stained_hardened_clay 15
fill ~26~19~22 ~29~19~22 minecraft:concrete 14
fill ~28~15~22 ~28~15~36 minecraft:stone 0
fill ~29~15~22 ~29~15~23 minecraft:concrete 15
fill ~29~16~22 ~29~16~36 minecraft:stone 0
fill ~30~17~22 ~30~17~36 minecraft:stone 0
fill ~30~18~22 ~30~18~36 minecraft:concrete 14
fill ~31~23~22 ~32~23~28 minecraft:wool 11
fill ~33~23~22 ~34~23~29 minecraft:wool 8
fill ~37~14~22 ~37~15~35 minecraft:wool 8
fill ~38~17~22 ~39~17~22 minecraft:stone 0
fill ~40~16~22 ~41~16~23 minecraft:wool 8
fill ~40~17~22 ~41~17~23 minecraft:concrete 14
fill ~41~22~22 ~42~22~33 minecraft:wool 8
fill ~42~5~22 ~42~6~22 minecraft:coal_block
fill ~42~7~22 ~42~10~22 minecraft:concrete 8
fill ~42~11~22 ~42~12~22 minecraft:coal_block
fill ~43~3~22 ~49~4~22 minecraft:coal_block
fill ~43~5~22 ~49~6~22 minecraft:concrete 8
fill ~43~11~22 ~49~12~22 minecraft:concrete 8
fill ~43~13~22 ~49~14~22 minecraft:coal_block
setblock ~44~19~22 minecraft:wool 8
fill ~46~21~22 ~46~21~32 minecraft:wool 8
fill ~47~20~22 ~47~20~56 minecraft:wool 8
fill ~48~7~22 ~50~10~22 minecraft:concrete 8
fill ~50~5~22 ~50~6~22 minecraft:coal_block
fill ~50~11~22 ~50~12~22 minecraft:coal_block
fill ~50~16~22 ~50~16~23 minecraft:wool 8
fill ~1~3~23 ~1~3~24 minecraft:coal_block
setblock ~1~4~23 minecraft:coal_block
fill ~1~5~23 ~3~6~23 minecraft:concrete 8
fill ~1~7~23 ~1~10~23 minecraft:stone_button 3
fill ~1~11~23 ~3~12~23 minecraft:concrete 8
fill ~1~13~23 ~1~14~23 minecraft:coal_block
fill ~1~17~23 ~1~17~25 minecraft:wool 8
fill ~2~2~23 ~8~2~24 minecraft:coal_block
fill ~2~4~23 ~8~4~23 minecraft:concrete 8
fill ~2~13~23 ~8~13~23 minecraft:concrete 8
fill ~2~15~23 ~8~15~24 minecraft:coal_block
fill ~3~8~23 ~3~9~27 minecraft:concrete 8
fill ~3~19~23 ~3~19~44 minecraft:wool 8
fill ~8~22~23 ~8~22~37 minecraft:wool 8
fill ~9~3~23 ~9~3~24 minecraft:coal_block
setblock ~9~4~23 minecraft:coal_block
fill ~9~5~23 ~9~6~23 minecraft:concrete 8
fill ~9~11~23 ~9~12~23 minecraft:concrete 8
fill ~9~13~23 ~9~14~23 minecraft:coal_block
fill ~9~22~23 ~10~22~23 minecraft:wool 11
fill ~11~22~23 ~11~22~25 minecraft:wool 8
fill ~13~7~23 ~13~7~25 minecraft:obsidian
fill ~13~8~23 ~13~9~23 minecraft:obsidian
fill ~14~16~23 ~15~16~23 minecraft:stone 0
setblock ~14~17~23 minecraft:stone 0
setblock ~14~22~23 minecraft:wool 8
fill ~15~23~23 ~16~23~24 minecraft:wool 8
fill ~18~18~23 ~18~18~24 minecraft:stone 6
fill ~26~19~23 ~26~19~36 minecraft:concrete 14
setblock ~27~19~23 minecraft:nether_brick_stairs 0
setblock ~28~19~23 minecraft:nether_brick_stairs 2
fill ~29~19~23 ~29~19~36 minecraft:concrete 14
fill ~35~23~23 ~36~23~29 minecraft:wool 8
fill ~37~16~23 ~37~18~23 minecraft:stained_hardened_clay 15
fill ~38~7~23 ~38~7~25 minecraft:obsidian
fill ~38~8~23 ~38~9~23 minecraft:obsidian
fill ~38~18~23 ~40~18~23 minecraft:stained_hardened_clay 15
fill ~42~3~23 ~42~3~24 minecraft:coal_block
setblock ~42~4~23 minecraft:coal_block
fill ~42~5~23 ~42~6~23 minecraft:concrete 8
fill ~42~11~23 ~42~12~23 minecraft:concrete 8
fill ~42~13~23 ~42~14~23 minecraft:coal_block
fill ~43~2~23 ~49~2~24 minecraft:coal_block
fill ~43~4~23 ~49~4~23 minecraft:concrete 8
fill ~43~13~23 ~49~13~23 minecraft:concrete 8
fill ~43~15~23 ~49~15~24 minecraft:coal_block
fill ~43~22~23 ~43~22~37 minecraft:wool 8
fill ~48~5~23 ~50~6~23 minecraft:concrete 8
fill ~48~8~23 ~48~9~27 minecraft:concrete 8
fill ~48~11~23 ~50~12~23 minecraft:concrete 8
fill ~48~19~23 ~48~19~44 minecraft:wool 8
fill ~50~3~23 ~50~3~24 minecraft:coal_block
setblock ~50~4~23 minecraft:coal_block
fill ~50~7~23 ~50~10~23 minecraft:stone_button 3
fill ~50~13~23 ~50~14~23 minecraft:coal_block
fill ~50~17~23 ~50~17~25 minecraft:wool 8
fill ~1~4~24 ~3~4~24 minecraft:concrete 8
setblock ~1~5~24 minecraft:stone_button 1
setblock ~1~6~24 minecraft:stone_button 3
fill ~1~11~24 ~1~12~24 minecraft:stone_button 3
fill ~1~13~24 ~3~13~24 minecraft:concrete 8
setblock ~1~14~24 minecraft:coal_block
fill ~2~3~24 ~8~3~24 minecraft:concrete 8
fill ~2~14~24 ~8~14~24 minecraft:concrete 8
fill ~2~18~24 ~2~18~37 minecraft:wool 8
fill ~5~8~24 ~5~9~24 minecraft:concrete 14
fill ~5~17~24 ~6~17~25 minecraft:wool 8
fill ~7~19~24 ~7~19~37 minecraft:wool 8
fill ~7~21~24 ~7~21~37 minecraft:wool 8
fill ~7~22~24 ~7~22~27 minecraft:wool 7
setblock ~9~4~24 minecraft:concrete 8
setblock ~9~13~24 minecraft:concrete 8
setblock ~9~14~24 minecraft:coal_block
fill ~9~22~24 ~9~22~25 minecraft:wool 8
fill ~10~8~24 ~13~8~24 minecraft:stained_hardened_clay 9
fill ~10~17~24 ~13~17~25 minecraft:wool 8
fill ~10~18~24 ~13~20~24 minecraft:wool 8
setblock ~10~22~24 minecraft:wool 11
setblock ~12~22~24 minecraft:wool 8
fill ~13~9~24 ~13~9~25 minecraft:obsidian
fill ~13~23~24 ~14~23~24 minecraft:wool 8
fill ~14~16~24 ~14~16~34 minecraft:wool 8
fill ~15~16~24 ~15~16~26 minecraft:stone 0
fill ~17~15~24 ~19~15~26 minecraft:concrete 15
fill ~19~18~24 ~19~18~33 minecraft:stone 6
fill ~20~15~24 ~21~15~24 minecraft:stone 5
fill ~27~19~24 ~28~19~24 minecraft:nether_brick_stairs 3
fill ~29~15~24 ~31~15~24 minecraft:stone 5
setblock ~31~16~24 minecraft:stone 5
fill ~37~16~24 ~37~16~33 minecraft:wool 8
fill ~37~23~24 ~38~23~31 minecraft:wool 8
fill ~38~8~24 ~41~8~24 minecraft:stained_hardened_clay 9
fill ~38~9~24 ~38~9~25 minecraft:obsidian
fill ~38~17~24 ~42~17~25 minecraft:wool 8
fill ~39~18~24 ~40~20~24 minecraft:wool 8
fill ~40~21~24 ~40~21~29 minecraft:wool 8
setblock ~42~4~24 minecraft:concrete 8
setblock ~42~13~24 minecraft:concrete 8
setblock ~42~14~24 minecraft:coal_block
fill ~42~18~24 ~42~18~31 minecraft:wool 8
fill ~43~3~24 ~49~3~24 minecraft:concrete 8
fill ~43~14~24 ~49~14~24 minecraft:concrete 8
fill ~44~19~24 ~44~19~37 minecraft:wool 8
fill ~44~21~24 ~44~21~37 minecraft:wool 8
fill ~44~22~24 ~44~22~27 minecraft:wool 7
fill ~46~8~24 ~46~9~24 minecraft:concrete 14
fill ~48~4~24 ~50~4~24 minecraft:concrete 8
fill ~48~13~24 ~50~13~24 minecraft:concrete 8
fill ~49~18~24 ~49~18~37 minecraft:wool 8
setblock ~50~5~24 minecraft:stone_button 1
setblock ~50~6~24 minecraft:stone_button 3
fill ~50~11~24 ~50~12~24 minecraft:stone_button 3
setblock ~50~14~24 minecraft:coal_block
fill ~1~2~25 ~1~2~26 minecraft:coal_block
fill ~1~3~25 ~3~3~26 minecraft:concrete 8
fill ~1~4~25 ~1~4~26 minecraft:stone_button 1
setblock ~1~13~25 minecraft:stone_button 3
fill ~1~14~25 ~3~14~26 minecraft:concrete 8
fill ~1~15~25 ~1~15~26 minecraft:coal_block
fill ~1~18~25 ~1~18~33 minecraft:wool 8
fill ~2~1~25 ~8~1~26 minecraft:coal_block
fill ~2~2~25 ~8~2~26 minecraft:concrete 8
fill ~2~15~25 ~8~15~26 minecraft:concrete 8
fill ~2~16~25 ~8~16~26 minecraft:coal_block
fill ~3~4~25 ~3~4~27 minecraft:concrete 8
fill ~3~13~25 ~3~13~27 minecraft:concrete 8
fill ~4~8~25 ~4~9~26 minecraft:concrete 14
fill ~5~6~25 ~5~7~25 minecraft:concrete 14
fill ~5~8~25 ~5~9~32 minecraft:stone 0
fill ~5~10~25 ~5~11~25 minecraft:concrete 14
fill ~6~8~25 ~6~9~26 minecraft:concrete 14
fill ~6~22~25 ~6~22~27 minecraft:wool 8
fill ~7~7~25 ~8~7~25 minecraft:stone 5
fill ~7~8~25 ~7~10~32 minecraft:stone 5
setblock ~8~6~25 minecraft:stone_button 0
fill ~8~8~25 ~9~8~25 minecraft:stained_hardened_clay 9
setblock ~8~9~25 minecraft:stone 5
setblock ~8~10~25 minecraft:stone_button 1
fill ~9~2~25 ~9~2~26 minecraft:coal_block
fill ~9~3~25 ~9~3~26 minecraft:concrete 8
fill ~9~14~25 ~9~14~26 minecraft:concrete 8
fill ~9~15~25 ~9~15~26 minecraft:coal_block
fill ~10~18~25 ~10~18~31 minecraft:wool 8
fill ~10~19~25 ~10~22~26 minecraft:wool 8
fill ~11~21~25 ~12~21~27 minecraft:wool 8
fill ~12~18~25 ~13~18~33 minecraft:wool 8
fill ~12~19~25 ~13~20~25 minecraft:wool 8
fill ~12~23~25 ~13~23~25 minecraft:wool 8
setblock ~13~8~25 minecraft:obsidian
fill ~14~17~25 ~14~17~32 minecraft:wool 8
fill ~14~23~25 ~15~23~25 minecraft:wool 11
fill ~16~23~25 ~16~23~29 minecraft:wool 8
fill ~20~15~25 ~20~15~28 minecraft:stone 5
fill ~27~19~25 ~28~19~36 minecraft:concrete 14
fill ~29~15~25 ~31~15~25 minecraft:concrete 15
fill ~36~15~25 ~36~20~27 minecraft:wool 8
fill ~37~17~25 ~37~20~33 minecraft:wool 8
setblock ~38~8~25 minecraft:obsidian
fill ~38~18~25 ~38~18~31 minecraft:wool 8
fill ~38~19~25 ~40~19~25 minecraft:wool 8
fill ~38~20~25 ~39~20~25 minecraft:wool 8
fill ~39~23~25 ~39~23~32 minecraft:wool 8
fill ~40~22~25 ~40~22~37 minecraft:wool 8
fill ~42~2~25 ~42~2~26 minecraft:coal_block
fill ~42~3~25 ~42~3~26 minecraft:concrete 8
fill ~42~8~25 ~43~8~25 minecraft:stained_hardened_clay 9
fill ~42~14~25 ~42~14~26 minecraft:concrete 8
fill ~42~15~25 ~42~15~26 minecraft:coal_block
fill ~42~19~25 ~42~19~26 minecraft:wool 8
fill ~43~1~25 ~49~1~26 minecraft:coal_block
fill ~43~2~25 ~49~2~26 minecraft:concrete 8
setblock ~43~6~25 minecraft:stone_button 0
fill ~43~7~25 ~44~7~25 minecraft:stone 5
fill ~43~9~25 ~44~9~25 minecraft:stone 5
setblock ~43~10~25 minecraft:stone_button 1
fill ~43~15~25 ~49~15~26 minecraft:concrete 8
fill ~43~16~25 ~49~16~26 minecraft:coal_block
fill ~44~8~25 ~44~8~32 minecraft:stone 5
fill ~44~10~25 ~44~10~32 minecraft:stone 5
fill ~45~8~25 ~45~9~26 minecraft:concrete 14
fill ~45~22~25 ~45~22~27 minecraft:wool 8
fill ~46~6~25 ~46~7~25 minecraft:concrete 14
fill ~46~8~25 ~46~9~32 minecraft:stone 0
fill ~46~10~25 ~46~11~25 minecraft:concrete 14
fill ~47~8~25 ~47~9~26 minecraft:concrete 14
fill ~48~3~25 ~50~3~26 minecraft:concrete 8
fill ~48~4~25 ~48~4~27 minecraft:concrete 8
fill ~48~13~25 ~48~13~27 minecraft:concrete 8
fill ~48~14~25 ~50~14~26 minecraft:concrete 8
fill ~50~2~25 ~50~2~26 minecraft:coal_block
fill ~50~4~25 ~50~4~26 minecraft:stone_button 1
setblock ~50~13~25 minecraft:stone_button 3
fill ~50~15~25 ~50~15~26 minecraft:coal_block
fill ~50~18~25 ~50~18~33 minecraft:wool 8
setblock ~1~13~26 minecraft:stone_button 0
fill ~3~5~26 ~3~6~27 minecraft:concrete 8
fill ~3~11~26 ~3~11~31 minecraft:concrete 8
fill ~3~12~26 ~3~12~27 minecraft:concrete 8
fill ~3~20~26 ~3~20~45 minecraft:wool 8
fill ~4~6~26 ~4~7~26 minecraft:concrete 14
fill ~4~10~26 ~4~11~26 minecraft:concrete 14
fill ~4~18~26 ~7~18~26 minecraft:wool 8
fill ~4~21~26 ~4~21~45 minecraft:wool 8
setblock ~5~5~26 minecraft:concrete 14
fill ~5~6~26 ~5~7~31 minecraft:stone 0
fill ~5~10~26 ~5~11~31 minecraft:stone 0
setblock ~5~12~26 minecraft:concrete 14
fill ~6~6~26 ~6~7~26 minecraft:concrete 14
fill ~6~10~26 ~6~11~26 minecraft:concrete 14
fill ~7~6~26 ~7~7~31 minecraft:stone 5
fill ~7~11~26 ~7~11~31 minecraft:stone 5
fill ~8~19~26 ~8~21~26 minecraft:wool 8
fill ~9~20~26 ~9~21~26 minecraft:wool 8
fill ~9~22~26 ~9~22~27 minecraft:wool 11
fill ~11~18~26 ~11~18~33 minecraft:wool 8
fill ~11~22~26 ~11~22~27 minecraft:wool 11
fill ~12~23~26 ~14~23~26 minecraft:wool 11
fill ~13~19~26 ~13~20~27 minecraft:wool 8
fill ~14~18~26 ~14~18~31 minecraft:wool 8
fill ~15~23~26 ~15~23~27 minecraft:wool 8
fill ~16~16~26 ~16~16~29 minecraft:stone 0
fill ~17~14~26 ~18~14~29 minecraft:wool 8
fill ~18~13~26 ~18~13~30 minecraft:wool 8
setblock ~21~15~26 minecraft:stone 5
fill ~29~15~26 ~31~15~26 minecraft:stone 5
setblock ~31~16~26 minecraft:stone 5
fill ~33~13~26 ~33~13~30 minecraft:wool 8
fill ~33~14~26 ~34~14~29 minecraft:wool 8
fill ~37~21~26 ~39~21~27 minecraft:wool 8
fill ~39~18~26 ~41~18~31 minecraft:wool 8
fill ~40~19~26 ~40~20~26 minecraft:wool 8
fill ~41~21~26 ~43~21~26 minecraft:wool 8
fill ~42~20~26 ~43~20~26 minecraft:wool 8
setblock ~43~19~26 minecraft:wool 8
fill ~44~6~26 ~44~7~31 minecraft:stone 5
fill ~44~9~26 ~44~9~32 minecraft:stone 5
fill ~44~11~26 ~44~11~31 minecraft:stone 5
fill ~44~18~26 ~47~18~26 minecraft:wool 8
fill ~45~6~26 ~45~7~26 minecraft:concrete 14
fill ~45~10~26 ~45~11~26 minecraft:concrete 14
setblock ~46~5~26 minecraft:concrete 14
fill ~46~6~26 ~46~7~31 minecraft:stone 0
fill ~46~10~26 ~46~11~31 minecraft:stone 0
setblock ~46~12~26 minecraft:concrete 14
fill ~47~6~26 ~47~7~26 minecraft:concrete 14
fill ~47~10~26 ~47~11~26 minecraft:concrete 14
fill ~47~21~26 ~47~21~45 minecraft:wool 8
fill ~48~5~26 ~48~6~27 minecraft:concrete 8
fill ~48~11~26 ~48~11~31 minecraft:concrete 8
fill ~48~12~26 ~48~12~27 minecraft:concrete 8
fill ~48~20~26 ~48~20~45 minecraft:wool 8
setblock ~50~13~26 minecraft:stone_button 0
fill ~1~1~27 ~1~1~30 minecraft:coal_block
fill ~1~2~27 ~3~2~30 minecraft:concrete 8
fill ~1~3~27 ~1~3~30 minecraft:stone_button 1
fill ~1~14~27 ~1~14~30 minecraft:stone_button 0
fill ~1~15~27 ~3~15~30 minecraft:concrete 8
fill ~1~16~27 ~1~16~30 minecraft:coal_block
fill ~2~0~27 ~8~0~30 minecraft:coal_block
fill ~2~1~27 ~8~1~30 minecraft:concrete 8
fill ~2~16~27 ~8~16~30 minecraft:concrete 8
fill ~2~17~27 ~8~17~30 minecraft:coal_block
fill ~2~19~27 ~2~19~35 minecraft:wool 8
fill ~3~7~27 ~3~7~30 minecraft:concrete 8
fill ~3~10~27 ~3~10~30 minecraft:concrete 8
fill ~5~22~27 ~5~22~47 minecraft:wool 8
fill ~6~4~27 ~6~4~30 minecraft:stone 5
fill ~6~13~27 ~6~13~30 minecraft:stone 5
fill ~7~5~27 ~7~5~30 minecraft:stone 5
fill ~7~12~27 ~7~12~30 minecraft:stone 5
fill ~7~18~27 ~7~18~37 minecraft:wool 8
fill ~8~8~27 ~8~9~27 minecraft:stone 5
fill ~9~1~27 ~9~1~30 minecraft:coal_block
fill ~9~2~27 ~9~2~30 minecraft:concrete 8
fill ~9~15~27 ~9~15~30 minecraft:concrete 8
fill ~9~16~27 ~9~16~30 minecraft:coal_block
fill ~10~21~27 ~10~21~37 minecraft:wool 8
setblock ~10~22~27 minecraft:wool 11
fill ~11~23~27 ~12~23~27 minecraft:wool 11
fill ~13~8~27 ~13~9~27 minecraft:stone 0
fill ~13~23~27 ~14~23~27 minecraft:wool 8
fill ~14~19~27 ~14~19~28 minecraft:wool 8
fill ~17~13~27 ~17~13~31 minecraft:wool 8
fill ~17~15~27 ~18~15~27 minecraft:stone 6
fill ~18~12~27 ~18~12~30 minecraft:wool 8
fill ~18~16~27 ~18~18~27 minecraft:stone 6
fill ~19~13~27 ~19~13~28 minecraft:wool 8
setblock ~19~14~27 minecraft:wool 8
setblock ~19~15~27 minecraft:concrete 15
fill ~21~12~27 ~21~14~35 minecraft:wool 8
fill ~21~19~27 ~22~19~36 minecraft:concrete 14
fill ~27~20~27 ~28~20~36 minecraft:concrete 14
fill ~29~15~27 ~31~15~27 minecraft:concrete 15
fill ~30~12~27 ~30~14~35 minecraft:wool 8
fill ~32~13~27 ~32~13~28 minecraft:wool 8
setblock ~32~14~27 minecraft:wool 8
fill ~33~12~27 ~33~12~30 minecraft:wool 8
fill ~34~13~27 ~34~13~31 minecraft:wool 8
fill ~38~8~27 ~38~9~27 minecraft:stone 0
fill ~40~23~27 ~40~23~37 minecraft:wool 8
fill ~41~21~27 ~41~21~29 minecraft:wool 8
fill ~42~1~27 ~42~1~30 minecraft:coal_block
fill ~42~2~27 ~42~2~30 minecraft:concrete 8
fill ~42~15~27 ~42~15~30 minecraft:concrete 8
fill ~42~16~27 ~42~16~30 minecraft:coal_block
fill ~43~0~27 ~49~0~30 minecraft:coal_block
fill ~43~1~27 ~49~1~30 minecraft:concrete 8
fill ~43~8~27 ~43~9~27 minecraft:stone 5
fill ~43~16~27 ~49~16~30 minecraft:concrete 8
fill ~43~17~27 ~49~17~30 minecraft:coal_block
fill ~44~5~27 ~44~5~30 minecraft:stone 5
fill ~44~12~27 ~44~12~30 minecraft:stone 5
fill ~44~18~27 ~44~18~37 minecraft:wool 8
fill ~45~4~27 ~45~4~30 minecraft:stone 5
fill ~45~13~27 ~45~13~30 minecraft:stone 5
fill ~46~22~27 ~46~22~47 minecraft:wool 8
fill ~48~2~27 ~50~2~30 minecraft:concrete 8
fill ~48~7~27 ~48~7~30 minecraft:concrete 8
fill ~48~10~27 ~48~10~30 minecraft:concrete 8
fill ~48~15~27 ~50~15~30 minecraft:concrete 8
fill ~49~19~27 ~49~19~35 minecraft:wool 8
fill ~50~1~27 ~50~1~30 minecraft:coal_block
fill ~50~3~27 ~50~3~30 minecraft:stone_button 1
fill ~50~14~27 ~50~14~30 minecraft:stone_button 0
fill ~50~16~27 ~50~16~30 minecraft:coal_block
setblock ~1~0~28 minecraft:coal_block
fill ~3~6~28 ~3~6~31 minecraft:concrete 8
fill ~4~8~28 ~4~9~29 minecraft:wool 7
fill ~5~5~28 ~5~5~29 minecraft:stone 0
fill ~5~12~28 ~5~12~29 minecraft:stone 0
fill ~6~8~28 ~6~9~29 minecraft:stained_hardened_clay 9
fill ~6~22~28 ~6~22~31 minecraft:wool 7
fill ~7~22~28 ~7~22~37 minecraft:wool 8
fill ~8~3~28 ~8~3~29 minecraft:stone_button 0
fill ~8~4~28 ~14~4~29 minecraft:stained_hardened_clay 9
fill ~8~5~28 ~8~5~29 minecraft:stone 5
fill ~8~6~28 ~8~6~29 minecraft:stone_button 1
fill ~8~7~28 ~8~7~29 minecraft:stone 5
fill ~8~8~28 ~13~9~29 minecraft:stained_hardened_clay 9
fill ~8~10~28 ~8~10~29 minecraft:stone 5
fill ~9~22~28 ~9~22~34 minecraft:wool 8
fill ~10~23~28 ~13~23~28 minecraft:wool 8
setblock ~11~21~28 minecraft:wool 8
fill ~12~21~28 ~13~21~31 minecraft:stone 0
fill ~13~7~28 ~13~7~29 minecraft:stone 0
fill ~13~10~28 ~13~10~29 minecraft:stone 0
setblock ~14~20~28 minecraft:wool 8
fill ~14~23~28 ~15~23~28 minecraft:wool 11
fill ~17~12~28 ~17~12~31 minecraft:wool 8
fill ~17~15~28 ~17~15~32 minecraft:concrete 15
fill ~18~15~28 ~19~15~28 minecraft:stone 5
fill ~20~24~28 ~23~24~39 minecraft:wool 11
setblock ~21~15~28 minecraft:stone 5
setblock ~24~23~28 minecraft:wool 11
fill ~24~24~28 ~27~24~37 minecraft:wool 8
fill ~25~23~28 ~27~23~28 minecraft:wool 8
fill ~28~24~28 ~31~24~39 minecraft:wool 11
fill ~29~15~28 ~31~15~28 minecraft:stone 5
setblock ~31~16~28 minecraft:stone 5
fill ~34~12~28 ~34~12~31 minecraft:wool 8
setblock ~34~15~28 minecraft:concrete 15
fill ~35~15~28 ~35~20~28 minecraft:wool 8
setblock ~36~18~28 minecraft:wool 8
fill ~36~21~28 ~37~21~31 minecraft:stone 0
fill ~37~4~28 ~43~4~29 minecraft:stained_hardened_clay 9
fill ~38~7~28 ~38~7~29 minecraft:stone 0
fill ~38~8~28 ~43~9~29 minecraft:stained_hardened_clay 9
fill ~38~10~28 ~38~10~29 minecraft:stone 0
fill ~38~21~28 ~39~21~28 minecraft:wool 8
fill ~41~23~28 ~41~23~34 minecraft:wool 8
fill ~43~3~28 ~43~3~29 minecraft:stone_button 0
fill ~43~5~28 ~43~5~29 minecraft:stone 5
fill ~43~6~28 ~43~6~29 minecraft:stone_button 1
fill ~43~7~28 ~43~7~29 minecraft:stone 5
fill ~43~10~28 ~43~10~29 minecraft:stone 5
fill ~44~22~28 ~44~22~37 minecraft:wool 8
fill ~45~8~28 ~45~9~29 minecraft:stained_hardened_clay 9
fill ~45~22~28 ~45~22~31 minecraft:wool 7
fill ~46~5~28 ~46~5~29 minecraft:stone 0
fill ~46~12~28 ~46~12~29 minecraft:stone 0
fill ~47~8~28 ~47~9~29 minecraft:wool 7
fill ~48~6~28 ~48~6~31 minecraft:concrete 8
fill ~4~18~29 ~4~18~31 minecraft:wool 8
fill ~9~23~29 ~10~23~29 minecraft:wool 8
fill ~11~21~29 ~11~21~30 minecraft:stone 0
fill ~11~23~29 ~12~23~30 minecraft:wool 11
setblock ~12~14~29 minecraft:stone_button 2
fill ~12~22~29 ~37~22~30 minecraft:stone 5
fill ~13~23~29 ~13~23~31 minecraft:wool 8
fill ~14~21~29 ~14~21~30 minecraft:stone 0
setblock ~14~23~29 minecraft:wool 11
fill ~15~10~29 ~15~11~30 minecraft:wool 8
fill ~15~13~29 ~16~13~34 minecraft:wool 8
fill ~15~14~29 ~16~14~32 minecraft:wool 8
fill ~15~15~29 ~15~20~30 minecraft:wool 8
fill ~15~23~29 ~15~23~30 minecraft:wool 8
fill ~16~11~29 ~16~11~31 minecraft:wool 8
fill ~16~15~29 ~16~15~36 minecraft:concrete 15
fill ~17~16~29 ~17~16~30 minecraft:stone 0
fill ~17~24~29 ~18~24~40 minecraft:wool 8
fill ~18~15~29 ~21~15~29 minecraft:concrete 15
setblock ~19~23~29 minecraft:wool 8
fill ~19~24~29 ~19~24~38 minecraft:wool 11
fill ~29~15~29 ~31~15~29 minecraft:concrete 15
fill ~32~23~29 ~32~24~29 minecraft:wool 11
fill ~33~24~29 ~34~24~40 minecraft:wool 8
fill ~34~15~29 ~34~20~30 minecraft:wool 8
fill ~35~11~29 ~36~11~31 minecraft:wool 8
fill ~35~13~29 ~36~13~34 minecraft:wool 8
fill ~35~14~29 ~36~14~32 minecraft:wool 8
setblock ~35~19~29 minecraft:wool 8
fill ~35~21~29 ~35~21~30 minecraft:stone 0
fill ~36~10~29 ~36~10~30 minecraft:wool 8
fill ~38~21~29 ~38~21~30 minecraft:stone 0
setblock ~39~14~29 minecraft:stone_button 2
fill ~39~21~29 ~39~21~37 minecraft:wool 8
fill ~42~23~29 ~42~23~38 minecraft:wool 8
fill ~47~18~29 ~47~18~31 minecraft:wool 8
fill ~3~4~30 ~3~4~34 minecraft:concrete 8
fill ~3~5~30 ~3~5~31 minecraft:concrete 8
fill ~3~8~30 ~3~9~36 minecraft:concrete 8
fill ~3~12~30 ~3~13~31 minecraft:concrete 8
fill ~8~8~30 ~8~9~30 minecraft:stone 5
setblock ~8~23~30 minecraft:wool 8
fill ~9~23~30 ~9~23~31 minecraft:wool 11
fill ~10~23~30 ~10~23~32 minecraft:wool 8
fill ~11~4~30 ~13~4~30 minecraft:stained_hardened_clay 9
fill ~11~9~30 ~11~11~30 minecraft:stone 0
fill ~12~12~30 ~12~14~30 minecraft:stone 0
fill ~13~8~30 ~13~9~30 minecraft:stone 0
setblock ~14~23~30 minecraft:wool 8
fill ~15~12~30 ~16~12~34 minecraft:wool 8
fill ~15~24~30 ~16~24~30 minecraft:wool 8
setblock ~16~10~30 minecraft:wool 8
fill ~17~14~30 ~17~14~31 minecraft:wool 8
fill ~18~15~30 ~19~15~30 minecraft:concrete 15
setblock ~18~16~30 minecraft:stone 0
fill ~20~15~30 ~21~15~30 minecraft:stone 5
fill ~29~15~30 ~31~15~30 minecraft:stone 5
setblock ~31~16~30 minecraft:stone 5
fill ~32~24~30 ~32~24~39 minecraft:wool 11
fill ~34~14~30 ~34~14~31 minecraft:wool 8
setblock ~35~10~30 minecraft:wool 8
fill ~35~12~30 ~36~12~34 minecraft:wool 8
fill ~35~24~30 ~36~24~40 minecraft:wool 8
setblock ~36~23~30 minecraft:wool 8
fill ~38~4~30 ~40~4~30 minecraft:stained_hardened_clay 9
fill ~38~8~30 ~38~9~30 minecraft:stone 0
fill ~39~12~30 ~39~14~30 minecraft:stone 0
fill ~40~9~30 ~40~11~30 minecraft:stone 0
fill ~43~8~30 ~43~9~30 minecraft:stone 5
fill ~43~23~30 ~43~23~39 minecraft:wool 8
fill ~48~4~30 ~48~4~34 minecraft:concrete 8
fill ~48~5~30 ~48~5~31 minecraft:concrete 8
fill ~48~8~30 ~48~9~36 minecraft:concrete 8
fill ~48~12~30 ~48~13~31 minecraft:concrete 8
fill ~1~2~31 ~1~2~32 minecraft:coal_block
fill ~1~3~31 ~3~3~32 minecraft:concrete 8
setblock ~1~4~31 minecraft:stone_button 1
fill ~1~13~31 ~1~13~32 minecraft:stone_button 0
fill ~1~14~31 ~3~14~32 minecraft:concrete 8
fill ~1~15~31 ~1~15~32 minecraft:coal_block
fill ~2~1~31 ~8~1~32 minecraft:coal_block
fill ~2~2~31 ~8~2~32 minecraft:concrete 8
fill ~2~15~31 ~8~15~32 minecraft:concrete 8
fill ~2~16~31 ~8~16~32 minecraft:coal_block
fill ~5~18~31 ~6~18~31 minecraft:wool 8
setblock ~6~5~31 minecraft:stone 5
setblock ~6~12~31 minecraft:stone 5
fill ~7~23~31 ~7~23~41 minecraft:wool 8
setblock ~8~18~31 minecraft:wool 8
setblock ~8~23~31 minecraft:wool 11
fill ~9~2~31 ~9~2~32 minecraft:coal_block
fill ~9~3~31 ~9~3~32 minecraft:concrete 8
fill ~9~14~31 ~9~14~32 minecraft:concrete 8
fill ~9~15~31 ~9~15~32 minecraft:coal_block
setblock ~10~7~31 minecraft:stone_button 4
fill ~11~7~31 ~11~9~31 minecraft:stone 5
fill ~11~13~31 ~12~16~32 minecraft:obsidian
fill ~11~17~31 ~12~17~31 minecraft:obsidian
fill ~11~21~31 ~11~21~32 minecraft:wool 8
fill ~11~23~31 ~12~23~31 minecraft:wool 8
fill ~12~4~31 ~12~6~31 minecraft:stone 5
fill ~12~7~31 ~12~7~35 minecraft:stone 0
setblock ~13~7~31 minecraft:stone_button 5
setblock ~13~24~31 minecraft:wool 8
fill ~14~19~31 ~14~20~31 minecraft:wool 8
fill ~14~24~31 ~15~24~31 minecraft:wool 11
fill ~15~11~31 ~15~11~32 minecraft:wool 8
fill ~15~15~31 ~15~15~36 minecraft:concrete 15
fill ~16~24~31 ~16~24~40 minecraft:wool 8
setblock ~18~15~31 minecraft:stone 0
fill ~19~15~31 ~19~15~33 minecraft:concrete 15
fill ~20~15~31 ~20~15~34 minecraft:stone 5
fill ~24~6~31 ~24~6~39 minecraft:wool 8
fill ~27~6~31 ~27~6~39 minecraft:wool 8
fill ~29~15~31 ~31~15~31 minecraft:concrete 15
fill ~34~15~31 ~34~15~36 minecraft:concrete 15
fill ~35~15~31 ~35~20~31 minecraft:wool 8
fill ~37~24~31 ~38~24~41 minecraft:wool 8
setblock ~38~7~31 minecraft:stone_button 4
fill ~38~21~31 ~38~21~32 minecraft:wool 8
fill ~39~4~31 ~39~6~31 minecraft:stone 5
fill ~39~7~31 ~39~7~35 minecraft:stone 0
fill ~39~13~31 ~40~16~32 minecraft:obsidian
fill ~39~17~31 ~40~17~31 minecraft:obsidian
fill ~40~7~31 ~40~9~31 minecraft:stone 5
setblock ~41~7~31 minecraft:stone_button 5
fill ~42~2~31 ~42~2~32 minecraft:coal_block
fill ~42~3~31 ~42~3~32 minecraft:concrete 8
fill ~42~14~31 ~42~14~32 minecraft:concrete 8
fill ~42~15~31 ~42~15~32 minecraft:coal_block
fill ~43~1~31 ~49~1~32 minecraft:coal_block
fill ~43~2~31 ~49~2~32 minecraft:concrete 8
fill ~43~15~31 ~49~15~32 minecraft:concrete 8
fill ~43~16~31 ~49~16~32 minecraft:coal_block
setblock ~43~18~31 minecraft:wool 8
fill ~44~23~31 ~44~23~41 minecraft:wool 8
setblock ~45~5~31 minecraft:stone 5
setblock ~45~12~31 minecraft:stone 5
fill ~45~18~31 ~46~18~31 minecraft:wool 8
fill ~48~3~31 ~50~3~32 minecraft:concrete 8
fill ~48~14~31 ~50~14~32 minecraft:concrete 8
fill ~50~2~31 ~50~2~32 minecraft:coal_block
setblock ~50~4~31 minecraft:stone_button 1
fill ~50~13~31 ~50~13~32 minecraft:stone_button 0
fill ~50~15~31 ~50~15~32 minecraft:coal_block
setblock ~1~4~32 minecraft:stone_button 2
fill ~1~17~32 ~13~17~33 minecraft:wool 8
fill ~3~13~32 ~3~13~34 minecraft:concrete 8
setblock ~6~6~32 minecraft:stone 5
setblock ~6~11~32 minecraft:stone 5
fill ~6~22~32 ~6~22~33 minecraft:wool 8
fill ~6~23~32 ~6~23~40 minecraft:wool 7
setblock ~7~7~32 minecraft:stone 5
fill ~8~9~32 ~11~9~32 minecraft:stone 0
fill ~8~23~32 ~9~23~32 minecraft:wool 8
setblock ~11~23~32 minecraft:wool 11
setblock ~12~4~32 minecraft:stone_button 3
setblock ~12~21~32 minecraft:wool 8
setblock ~12~24~32 minecraft:wool 8
fill ~13~19~32 ~13~20~33 minecraft:wool 8
setblock ~13~24~32 minecraft:wool 11
fill ~14~24~32 ~14~24~34 minecraft:wool 8
setblock ~15~24~32 minecraft:wool 11
setblock ~18~15~32 minecraft:concrete 15
setblock ~21~15~32 minecraft:stone 5
fill ~22~6~32 ~23~6~32 minecraft:wool 8
fill ~23~7~32 ~24~7~34 minecraft:wool 8
fill ~27~7~32 ~28~7~34 minecraft:wool 8
fill ~28~6~32 ~29~6~32 minecraft:wool 8
fill ~29~15~32 ~31~15~32 minecraft:stone 5
setblock ~31~16~32 minecraft:stone 5
fill ~35~15~32 ~35~15~36 minecraft:concrete 15
setblock ~36~11~32 minecraft:wool 8
fill ~36~15~32 ~36~20~33 minecraft:wool 8
setblock ~37~21~32 minecraft:wool 8
fill ~38~17~32 ~50~17~33 minecraft:wool 8
setblock ~39~4~32 minecraft:stone_button 3
fill ~39~24~32 ~39~24~42 minecraft:wool 8
fill ~40~9~32 ~43~9~32 minecraft:stone 0
setblock ~44~7~32 minecraft:stone 5
setblock ~45~6~32 minecraft:stone 5
setblock ~45~11~32 minecraft:stone 5
fill ~45~22~32 ~45~22~33 minecraft:wool 8
fill ~45~23~32 ~45~23~40 minecraft:wool 7
fill ~48~13~32 ~48~13~34 minecraft:concrete 8
setblock ~50~4~32 minecraft:stone_button 2
fill ~1~3~33 ~1~3~34 minecraft:coal_block
fill ~1~4~33 ~2~4~33 minecraft:concrete 8
fill ~1~5~33 ~1~6~33 minecraft:stone_button 2
setblock ~1~11~33 minecraft:stone_button 2
setblock ~1~12~33 minecraft:stone_button 0
fill ~1~13~33 ~2~13~33 minecraft:concrete 8
fill ~1~14~33 ~1~14~34 minecraft:coal_block
fill ~2~2~33 ~8~2~34 minecraft:coal_block
fill ~2~3~33 ~8~3~33 minecraft:concrete 8
fill ~2~14~33 ~8~14~33 minecraft:concrete 8
fill ~2~15~33 ~8~15~34 minecraft:coal_block
fill ~6~7~33 ~6~10~33 minecraft:stone 5
fill ~7~9~33 ~8~9~33 minecraft:stone 0
fill ~8~18~33 ~10~19~33 minecraft:wool 8
fill ~8~20~33 ~9~21~33 minecraft:wool 8
fill ~8~23~33 ~10~23~33 minecraft:wool 11
fill ~9~3~33 ~9~3~34 minecraft:coal_block
setblock ~9~4~33 minecraft:concrete 8
setblock ~9~13~33 minecraft:concrete 8
fill ~9~14~33 ~9~14~34 minecraft:coal_block
setblock ~11~9~33 minecraft:stone_button 3
fill ~11~19~33 ~12~20~33 minecraft:wool 8
fill ~11~24~33 ~12~24~33 minecraft:wool 11
setblock ~12~14~33 minecraft:stone_button 3
fill ~13~24~33 ~13~24~34 minecraft:wool 8
fill ~14~17~33 ~15~19~33 minecraft:stone 0
fill ~15~16~33 ~15~16~36 minecraft:stone 0
fill ~15~24~33 ~15~24~37 minecraft:wool 8
fill ~17~12~33 ~17~14~34 minecraft:wool 8
fill ~17~15~33 ~18~15~33 minecraft:stone 6
fill ~18~13~33 ~18~14~34 minecraft:wool 8
fill ~18~16~33 ~18~18~33 minecraft:stone 6
fill ~23~6~33 ~23~6~36 minecraft:wool 8
fill ~23~19~33 ~25~19~34 minecraft:concrete 14
fill ~24~18~33 ~24~18~36 minecraft:concrete 14
fill ~25~6~33 ~26~6~55 minecraft:wool 8
fill ~25~20~33 ~26~20~34 minecraft:concrete 14
fill ~28~6~33 ~28~6~36 minecraft:wool 8
fill ~29~15~33 ~33~15~33 minecraft:concrete 15
fill ~33~13~33 ~34~14~34 minecraft:wool 8
fill ~34~12~33 ~34~12~34 minecraft:wool 8
fill ~38~18~33 ~43~20~33 minecraft:wool 8
setblock ~39~14~33 minecraft:stone_button 3
setblock ~40~9~33 minecraft:stone_button 3
fill ~40~21~33 ~43~21~33 minecraft:wool 8
fill ~40~24~33 ~40~24~42 minecraft:wool 8
fill ~42~3~33 ~42~3~34 minecraft:coal_block
setblock ~42~4~33 minecraft:concrete 8
setblock ~42~13~33 minecraft:concrete 8
fill ~42~14~33 ~42~14~34 minecraft:coal_block
fill ~43~2~33 ~49~2~34 minecraft:coal_block
fill ~43~3~33 ~49~3~33 minecraft:concrete 8
fill ~43~9~33 ~44~9~33 minecraft:stone 0
fill ~43~14~33 ~49~14~33 minecraft:concrete 8
fill ~43~15~33 ~49~15~34 minecraft:coal_block
fill ~45~7~33 ~45~10~33 minecraft:stone 5
fill ~49~4~33 ~50~4~33 minecraft:concrete 8
fill ~49~13~33 ~50~13~33 minecraft:concrete 8
fill ~50~3~33 ~50~3~34 minecraft:coal_block
fill ~50~5~33 ~50~6~33 minecraft:stone_button 2
setblock ~50~11~33 minecraft:stone_button 2
setblock ~50~12~33 minecraft:stone_button 0
fill ~50~14~33 ~50~14~34 minecraft:coal_block
setblock ~1~4~34 minecraft:coal_block
fill ~1~5~34 ~3~6~34 minecraft:concrete 8
fill ~1~7~34 ~1~10~34 minecraft:stone_button 2
fill ~1~11~34 ~3~12~34 minecraft:concrete 8
setblock ~1~13~34 minecraft:coal_block
fill ~1~16~34 ~13~16~35 minecraft:wool 8
fill ~1~17~34 ~10~17~34 minecraft:wool 8
setblock ~2~4~34 minecraft:concrete 8
setblock ~2~13~34 minecraft:concrete 8
fill ~4~4~34 ~8~4~34 minecraft:concrete 8
fill ~4~13~34 ~8~13~34 minecraft:concrete 8
fill ~4~22~34 ~4~22~45 minecraft:wool 8
fill ~5~23~34 ~5~23~45 minecraft:wool 8
setblock ~7~9~34 minecraft:stone_button 3
fill ~8~18~34 ~8~21~37 minecraft:wool 8
fill ~8~23~34 ~8~23~39 minecraft:wool 8
setblock ~9~4~34 minecraft:coal_block
fill ~9~5~34 ~9~6~34 minecraft:concrete 8
fill ~9~11~34 ~9~12~34 minecraft:concrete 8
setblock ~9~13~34 minecraft:coal_block
setblock ~9~21~34 minecraft:wool 8
setblock ~9~23~34 minecraft:wool 11
fill ~10~18~34 ~10~20~37 minecraft:wool 8
fill ~10~24~34 ~12~24~35 minecraft:wool 8
fill ~11~19~34 ~15~19~36 minecraft:stone 0
fill ~11~20~34 ~13~20~37 minecraft:wool 8
fill ~13~6~34 ~13~6~36 minecraft:obsidian
fill ~13~7~34 ~13~8~34 minecraft:obsidian
fill ~15~17~34 ~15~18~36 minecraft:stone 0
setblock ~16~17~34 minecraft:stone_stairs 6
setblock ~16~18~34 minecraft:stone_stairs 2
fill ~17~15~34 ~17~15~36 minecraft:concrete 15
fill ~18~15~34 ~19~15~34 minecraft:stone 5
setblock ~21~15~34 minecraft:stone 5
fill ~29~15~34 ~31~15~34 minecraft:stone 5
setblock ~31~16~34 minecraft:stone 5
fill ~32~15~34 ~33~15~36 minecraft:concrete 15
fill ~36~15~34 ~36~15~36 minecraft:concrete 15
fill ~36~16~34 ~36~20~37 minecraft:wool 8
fill ~37~20~34 ~40~20~37 minecraft:wool 8
fill ~38~6~34 ~38~6~36 minecraft:obsidian
fill ~38~7~34 ~38~8~34 minecraft:obsidian
fill ~38~16~34 ~50~16~35 minecraft:wool 8
fill ~39~18~34 ~40~19~34 minecraft:wool 8
fill ~40~21~34 ~40~21~37 minecraft:wool 8
fill ~41~17~34 ~50~17~34 minecraft:wool 8
fill ~41~24~34 ~41~24~43 minecraft:wool 8
setblock ~42~4~34 minecraft:coal_block
fill ~42~5~34 ~42~6~34 minecraft:concrete 8
fill ~42~11~34 ~42~12~34 minecraft:concrete 8
setblock ~42~13~34 minecraft:coal_block
fill ~43~4~34 ~47~4~34 minecraft:concrete 8
fill ~43~13~34 ~47~13~34 minecraft:concrete 8
fill ~43~18~34 ~43~21~37 minecraft:wool 8
setblock ~44~9~34 minecraft:stone_button 3
fill ~46~23~34 ~46~23~45 minecraft:wool 8
fill ~47~22~34 ~47~22~45 minecraft:wool 8
fill ~48~5~34 ~50~6~34 minecraft:concrete 8
fill ~48~11~34 ~50~12~34 minecraft:concrete 8
setblock ~49~4~34 minecraft:concrete 8
setblock ~49~13~34 minecraft:concrete 8
setblock ~50~4~34 minecraft:coal_block
fill ~50~7~34 ~50~10~34 minecraft:stone_button 2
setblock ~50~13~34 minecraft:coal_block
fill ~1~5~35 ~1~6~35 minecraft:coal_block
fill ~1~7~35 ~3~7~35 minecraft:concrete 8
fill ~1~8~35 ~2~10~35 minecraft:concrete 8
fill ~1~11~35 ~1~12~35 minecraft:coal_block
fill ~1~17~35 ~8~17~35 minecraft:wool 8
fill ~2~3~35 ~8~4~35 minecraft:coal_block
fill ~2~5~35 ~8~6~35 minecraft:concrete 8
fill ~2~11~35 ~8~12~35 minecraft:concrete 8
fill ~2~13~35 ~8~14~35 minecraft:coal_block
fill ~3~10~35 ~3~10~36 minecraft:concrete 8
fill ~9~5~35 ~9~6~35 minecraft:coal_block
fill ~9~7~35 ~9~10~35 minecraft:concrete 8
fill ~9~11~35 ~9~12~35 minecraft:coal_block
fill ~9~23~35 ~9~23~38 minecraft:wool 8
fill ~10~17~35 ~10~17~36 minecraft:wool 8
fill ~10~22~35 ~10~22~37 minecraft:wool 8
setblock ~13~7~35 minecraft:stone 0
fill ~13~8~35 ~13~8~36 minecraft:obsidian
fill ~13~24~35 ~14~24~35 minecraft:wool 11
setblock ~16~17~35 minecraft:stone_stairs 7
setblock ~16~18~35 minecraft:stone_stairs 3
fill ~18~15~35 ~21~15~36 minecraft:concrete 15
fill ~24~7~35 ~24~7~36 minecraft:wool 8
fill ~25~19~35 ~25~19~36 minecraft:concrete 14
fill ~27~7~35 ~27~7~36 minecraft:wool 8
fill ~29~15~35 ~31~15~36 minecraft:concrete 15
setblock ~38~7~35 minecraft:stone 0
fill ~38~8~35 ~38~8~36 minecraft:obsidian
fill ~39~22~35 ~39~22~37 minecraft:wool 8
fill ~41~17~35 ~41~17~36 minecraft:wool 8
fill ~42~5~35 ~42~6~35 minecraft:coal_block
fill ~42~7~35 ~42~10~35 minecraft:concrete 8
fill ~42~11~35 ~42~12~35 minecraft:coal_block
fill ~43~3~35 ~49~4~35 minecraft:coal_block
fill ~43~5~35 ~49~6~35 minecraft:concrete 8
fill ~43~11~35 ~49~12~35 minecraft:concrete 8
fill ~43~13~35 ~49~14~35 minecraft:coal_block
fill ~43~17~35 ~50~17~35 minecraft:wool 8
fill ~48~7~35 ~50~7~35 minecraft:concrete 8
fill ~48~10~35 ~50~10~35 minecraft:concrete 8
fill ~49~8~35 ~50~9~35 minecraft:concrete 8
fill ~50~5~35 ~50~6~35 minecraft:coal_block
fill ~50~11~35 ~50~12~35 minecraft:coal_block
fill ~1~7~36 ~1~10~36 minecraft:coal_block
fill ~1~14~36 ~13~15~36 minecraft:wool 8
fill ~1~16~36 ~8~16~36 minecraft:wool 8
fill ~2~5~36 ~8~6~36 minecraft:coal_block
fill ~2~7~36 ~8~7~36 minecraft:concrete 8
fill ~2~8~36 ~2~10~36 minecraft:concrete 8
fill ~2~11~36 ~8~12~36 minecraft:coal_block
fill ~2~17~36 ~8~17~37 minecraft:wool 8
fill ~4~8~36 ~8~10~36 minecraft:concrete 8
fill ~9~7~36 ~9~10~36 minecraft:coal_block
fill ~9~18~36 ~9~22~37 minecraft:wool 8
fill ~9~24~36 ~10~24~36 minecraft:wool 8
setblock ~10~16~36 minecraft:wool 8
fill ~10~23~36 ~10~23~37 minecraft:wool 8
fill ~11~21~36 ~11~21~37 minecraft:wool 8
fill ~11~24~36 ~11~24~37 minecraft:wool 11
fill ~12~24~36 ~12~24~38 minecraft:wool 8
setblock ~13~7~36 minecraft:obsidian
fill ~13~21~36 ~18~21~37 minecraft:wool 8
setblock ~13~24~36 minecraft:wool 11
setblock ~14~15~36 minecraft:concrete 15
fill ~14~23~36 ~19~23~37 minecraft:wool 8
fill ~14~24~36 ~14~24~37 minecraft:wool 8
fill ~15~22~36 ~19~22~37 minecraft:wool 8
fill ~20~22~36 ~24~23~37 minecraft:wool 11
fill ~21~13~36 ~30~14~36 minecraft:wool 8
fill ~22~12~36 ~29~12~36 minecraft:wool 8
fill ~25~7~36 ~26~7~37 minecraft:wool 8
fill ~25~22~36 ~27~23~37 minecraft:wool 8
fill ~28~22~36 ~32~23~37 minecraft:wool 11
fill ~31~21~36 ~32~21~37 minecraft:wool 11
fill ~33~21~36 ~36~21~37 minecraft:wool 8
fill ~33~22~36 ~34~23~37 minecraft:wool 8
fill ~35~23~36 ~37~23~37 minecraft:wool 8
setblock ~37~15~36 minecraft:concrete 15
setblock ~38~7~36 minecraft:obsidian
fill ~38~14~36 ~50~15~36 minecraft:wool 8
fill ~38~21~36 ~38~21~37 minecraft:wool 8
fill ~39~23~36 ~39~23~37 minecraft:wool 8
setblock ~41~16~36 minecraft:wool 8
fill ~42~7~36 ~42~10~36 minecraft:coal_block
fill ~42~18~36 ~42~22~37 minecraft:wool 8
fill ~42~24~36 ~42~24~43 minecraft:wool 8
fill ~43~5~36 ~49~6~36 minecraft:coal_block
fill ~43~7~36 ~49~7~36 minecraft:concrete 8
fill ~43~8~36 ~47~10~36 minecraft:concrete 8
fill ~43~11~36 ~49~12~36 minecraft:coal_block
fill ~43~16~36 ~50~16~36 minecraft:wool 8
fill ~43~17~36 ~49~17~37 minecraft:wool 8
fill ~48~10~36 ~49~10~36 minecraft:concrete 8
fill ~49~8~36 ~49~9~36 minecraft:concrete 8
fill ~50~7~36 ~50~10~36 minecraft:coal_block
fill ~1~12~37 ~13~13~37 minecraft:wool 8
fill ~1~14~37 ~8~15~37 minecraft:wool 8
fill ~2~7~37 ~8~10~37 minecraft:coal_block
fill ~2~16~37 ~8~16~37 minecraft:wool 8
fill ~8~24~37 ~9~24~38 minecraft:wool 11
fill ~10~24~37 ~10~24~43 minecraft:wool 8
fill ~11~18~37 ~27~19~37 minecraft:wool 8
fill ~11~22~37 ~14~22~37 minecraft:wool 8
fill ~11~23~37 ~13~23~37 minecraft:wool 8
setblock ~12~21~37 minecraft:wool 8
fill ~13~24~37 ~13~24~42 minecraft:wool 8
fill ~14~20~37 ~27~20~37 minecraft:wool 8
fill ~16~16~37 ~20~16~37 minecraft:wool 8
fill ~16~17~37 ~19~17~37 minecraft:wool 8
setblock ~19~21~37 minecraft:wool 8
fill ~20~21~37 ~24~21~37 minecraft:wool 11
fill ~25~21~37 ~27~21~37 minecraft:wool 8
fill ~28~18~37 ~32~20~37 minecraft:wool 11
fill ~28~21~37 ~30~21~37 minecraft:wool 11
fill ~30~16~37 ~35~16~37 minecraft:wool 8
fill ~31~17~37 ~35~17~37 minecraft:wool 8
fill ~33~18~37 ~35~20~37 minecraft:wool 8
fill ~35~22~37 ~38~22~37 minecraft:wool 8
fill ~37~18~37 ~41~19~37 minecraft:wool 8
setblock ~37~21~37 minecraft:wool 8
fill ~38~12~37 ~50~13~37 minecraft:wool 8
setblock ~38~23~37 minecraft:wool 8
fill ~41~20~37 ~41~23~37 minecraft:wool 8
fill ~43~7~37 ~49~10~37 minecraft:coal_block
fill ~43~14~37 ~50~15~37 minecraft:wool 8
fill ~43~16~37 ~49~16~37 minecraft:wool 8
fill ~43~24~37 ~43~24~44 minecraft:wool 8
fill ~1~4~38 ~5~7~38 minecraft:wool 8
setblock ~1~8~38 minecraft:wool 11
fill ~1~9~38 ~2~9~38 minecraft:wool 7
fill ~1~10~38 ~13~11~38 minecraft:wool 8
fill ~1~12~38 ~5~12~38 minecraft:wool 8
fill ~1~13~38 ~3~13~38 minecraft:wool 8
fill ~1~14~38 ~2~14~38 minecraft:wool 8
fill ~2~3~38 ~4~3~38 minecraft:wool 8
fill ~2~8~38 ~13~8~38 minecraft:wool 8
fill ~2~15~38 ~2~16~39 minecraft:wool 8
fill ~2~17~38 ~3~17~38 minecraft:wool 8
fill ~3~9~38 ~13~9~38 minecraft:wool 8
fill ~3~16~38 ~3~16~44 minecraft:wool 8
fill ~6~5~38 ~13~5~90 minecraft:wool 8
fill ~6~6~38 ~13~7~38 minecraft:wool 8
fill ~7~24~38 ~7~24~44 minecraft:wool 8
fill ~8~12~38 ~8~13~38 minecraft:wool 8
fill ~9~12~38 ~20~12~38 minecraft:coal_block
fill ~9~13~38 ~21~13~38 minecraft:wool 8
setblock ~11~24~38 minecraft:wool 8
fill ~14~11~38 ~21~11~38 minecraft:wool 8
fill ~14~24~38 ~15~24~39 minecraft:wool 11
setblock ~21~12~38 minecraft:wool 8
fill ~21~25~38 ~23~25~39 minecraft:wool 11
fill ~24~24~38 ~24~24~39 minecraft:wool 11
fill ~24~25~38 ~27~25~39 minecraft:wool 8
fill ~25~24~38 ~27~24~39 minecraft:wool 8
fill ~28~25~38 ~30~25~39 minecraft:wool 11
fill ~30~11~38 ~50~11~38 minecraft:wool 8
fill ~30~12~38 ~30~13~38 minecraft:wool 8
fill ~31~12~38 ~39~12~38 minecraft:coal_block
fill ~31~13~38 ~43~13~38 minecraft:wool 8
fill ~38~5~38 ~50~7~38 minecraft:wool 8
fill ~38~8~38 ~49~8~38 minecraft:wool 8
fill ~38~9~38 ~48~10~38 minecraft:wool 8
setblock ~40~12~38 minecraft:wool 8
fill ~41~12~38 ~42~12~38 minecraft:coal_block
setblock ~43~12~38 minecraft:wool 8
fill ~46~4~38 ~50~4~38 minecraft:wool 8
fill ~46~12~38 ~50~12~38 minecraft:wool 8
fill ~47~3~38 ~49~3~38 minecraft:wool 8
fill ~48~13~38 ~50~13~38 minecraft:wool 8
fill ~48~16~38 ~49~16~39 minecraft:wool 8
fill ~48~17~38 ~49~17~38 minecraft:wool 8
fill ~49~9~38 ~50~9~38 minecraft:wool 7
fill ~49~10~38 ~50~10~39 minecraft:wool 8
fill ~49~14~38 ~50~14~38 minecraft:wool 8
fill ~49~15~38 ~49~15~39 minecraft:wool 8
setblock ~50~8~38 minecraft:wool 11
fill ~1~3~39 ~1~5~40 minecraft:wool 11
fill ~1~6~39 ~11~6~39 minecraft:wool 8
setblock ~1~9~39 minecraft:stained_hardened_clay 11
fill ~1~10~39 ~3~10~39 minecraft:wool 8
fill ~1~11~39 ~2~12~39 minecraft:wool 8
fill ~2~2~39 ~2~2~40 minecraft:wool 11
fill ~2~3~39 ~2~3~90 minecraft:wool 8
fill ~2~4~39 ~2~4~46 minecraft:wool 8
fill ~2~5~39 ~5~5~39 minecraft:wool 8
fill ~2~7~39 ~20~7~39 minecraft:wool 8
fill ~2~8~39 ~2~8~40 minecraft:wool 11
setblock ~2~9~39 minecraft:wool 7
fill ~2~13~39 ~3~14~40 minecraft:wool 8
fill ~3~8~39 ~8~8~39 minecraft:wool 8
fill ~3~9~39 ~6~9~39 minecraft:wool 8
fill ~3~15~39 ~3~15~44 minecraft:wool 8
setblock ~3~17~39 minecraft:wool 8
fill ~8~9~39 ~8~11~39 minecraft:wool 8
fill ~8~12~39 ~8~12~53 minecraft:obsidian
fill ~8~13~39 ~8~13~48 minecraft:wool 8
fill ~8~24~39 ~9~24~39 minecraft:wool 8
fill ~9~8~39 ~19~11~39 minecraft:coal_block
fill ~9~13~39 ~20~13~48 minecraft:coal_block
fill ~11~24~39 ~12~24~40 minecraft:wool 11
fill ~14~5~39 ~24~5~97 minecraft:wool 8
fill ~16~23~39 ~19~23~39 minecraft:wool 8
fill ~18~25~39 ~18~25~40 minecraft:wool 8
setblock ~19~24~39 minecraft:wool 8
fill ~19~25~39 ~20~25~39 minecraft:wool 11
fill ~20~8~39 ~21~8~39 minecraft:wool 8
fill ~20~9~39 ~20~11~39 minecraft:coal_block
fill ~20~23~39 ~22~23~39 minecraft:wool 11
fill ~21~9~39 ~21~11~39 minecraft:wool 8
fill ~21~12~39 ~21~12~49 minecraft:coal_block
fill ~21~13~39 ~21~13~48 minecraft:wool 8
fill ~25~5~39 ~26~5~40 minecraft:stone 0
fill ~25~23~39 ~26~23~39 minecraft:wool 8
fill ~27~5~39 ~49~5~39 minecraft:wool 8
fill ~29~23~39 ~32~23~39 minecraft:wool 11
fill ~30~8~39 ~31~8~39 minecraft:wool 8
fill ~30~9~39 ~30~11~39 minecraft:wool 8
fill ~30~12~39 ~30~12~49 minecraft:coal_block
fill ~30~13~39 ~30~13~48 minecraft:wool 8
fill ~31~7~39 ~49~7~39 minecraft:wool 8
fill ~31~9~39 ~42~11~39 minecraft:coal_block
fill ~31~13~39 ~42~13~48 minecraft:coal_block
fill ~31~25~39 ~32~25~39 minecraft:wool 11
fill ~32~8~39 ~42~8~39 minecraft:coal_block
fill ~33~23~39 ~35~23~40 minecraft:wool 8
fill ~33~25~39 ~33~25~40 minecraft:wool 8
fill ~40~6~39 ~50~6~39 minecraft:wool 8
setblock ~40~12~39 minecraft:stone 0
fill ~43~8~39 ~48~8~39 minecraft:wool 8
fill ~43~9~39 ~43~11~39 minecraft:wool 8
fill ~43~12~39 ~43~12~53 minecraft:obsidian
fill ~43~13~39 ~43~13~48 minecraft:wool 8
fill ~44~24~39 ~44~24~44 minecraft:wool 8
fill ~45~9~39 ~48~9~39 minecraft:wool 8
fill ~48~10~39 ~48~10~42 minecraft:wool 8
fill ~48~13~39 ~49~14~40 minecraft:wool 8
fill ~48~15~39 ~48~15~44 minecraft:wool 8
setblock ~48~17~39 minecraft:wool 8
fill ~49~2~39 ~49~2~40 minecraft:wool 11
fill ~49~3~39 ~49~3~90 minecraft:wool 8
fill ~49~4~39 ~49~4~46 minecraft:wool 8
fill ~49~8~39 ~49~8~40 minecraft:wool 11
setblock ~49~9~39 minecraft:wool 7
fill ~49~11~39 ~50~12~39 minecraft:wool 8
fill ~50~3~39 ~50~5~40 minecraft:wool 11
setblock ~50~9~39 minecraft:stained_hardened_clay 11
fill ~2~5~40 ~3~6~42 minecraft:wool 8
fill ~2~7~40 ~5~7~40 minecraft:wool 8
setblock ~2~9~40 minecraft:stained_hardened_clay 11
fill ~2~10~40 ~3~12~40 minecraft:wool 8
fill ~3~8~40 ~4~8~42 minecraft:wool 8
setblock ~3~9~40 minecraft:wool 7
fill ~3~17~40 ~3~17~41 minecraft:glass
fill ~4~17~40 ~4~17~41 minecraft:concrete 1
fill ~5~5~40 ~5~6~90 minecraft:wool 8
setblock ~8~7~40 minecraft:wool 8
fill ~8~8~40 ~8~8~79 minecraft:obsidian
fill ~8~9~40 ~8~11~78 minecraft:obsidian
fill ~8~24~40 ~9~24~41 minecraft:wool 11
fill ~9~6~40 ~20~6~40 minecraft:wool 8
fill ~9~7~40 ~19~7~40 minecraft:concrete 15
fill ~13~23~40 ~18~23~40 minecraft:wool 8
setblock ~14~14~40 minecraft:wool 8
fill ~14~24~40 ~15~24~41 minecraft:wool 8
fill ~16~25~40 ~17~25~40 minecraft:wool 8
setblock ~17~14~40 minecraft:wool 8
fill ~19~24~40 ~32~24~41 minecraft:stained_hardened_clay 9
setblock ~20~7~40 minecraft:wool 8
fill ~20~8~40 ~20~8~47 minecraft:coal_block
fill ~21~8~40 ~21~8~47 minecraft:wool 8
fill ~21~9~40 ~21~9~53 minecraft:coal_block
fill ~21~10~40 ~21~11~48 minecraft:coal_block
fill ~27~5~40 ~46~5~90 minecraft:wool 8
fill ~30~8~40 ~30~8~47 minecraft:wool 8
fill ~30~9~40 ~30~9~50 minecraft:coal_block
fill ~30~10~40 ~30~11~48 minecraft:coal_block
fill ~31~6~40 ~42~6~40 minecraft:wool 8
setblock ~31~7~40 minecraft:wool 8
fill ~31~8~40 ~31~8~47 minecraft:coal_block
fill ~32~7~40 ~42~7~40 minecraft:concrete 15
fill ~34~12~40 ~34~12~41 minecraft:stone 0
setblock ~34~14~40 minecraft:wool 8
fill ~34~25~40 ~35~25~40 minecraft:wool 8
fill ~36~23~40 ~38~23~40 minecraft:wool 8
fill ~37~12~40 ~37~12~41 minecraft:stone 0
setblock ~37~14~40 minecraft:wool 8
fill ~40~9~40 ~40~9~42 minecraft:stone 0
fill ~40~10~40 ~40~11~40 minecraft:stone 0
setblock ~43~7~40 minecraft:wool 8
fill ~43~8~40 ~43~8~79 minecraft:obsidian
fill ~43~9~40 ~43~11~78 minecraft:obsidian
fill ~46~6~40 ~46~7~90 minecraft:wool 8
fill ~47~7~40 ~49~7~40 minecraft:wool 8
fill ~47~8~40 ~48~8~42 minecraft:wool 8
fill ~47~17~40 ~47~17~41 minecraft:concrete 1
fill ~48~5~40 ~49~6~42 minecraft:wool 8
setblock ~48~9~40 minecraft:wool 7
fill ~48~11~40 ~49~12~40 minecraft:wool 8
fill ~48~16~40 ~48~16~44 minecraft:wool 8
fill ~48~17~40 ~48~17~41 minecraft:glass
setblock ~49~9~40 minecraft:stained_hardened_clay 11
setblock ~49~10~40 minecraft:wool 8
fill ~1~3~41 ~1~3~42 minecraft:wool 8
fill ~1~4~41 ~1~5~41 minecraft:wool 11
setblock ~2~2~41 minecraft:wool 8
fill ~3~3~41 ~3~4~70 minecraft:wool 8
fill ~3~7~41 ~5~7~46 minecraft:wool 8
setblock ~3~9~41 minecraft:stained_hardened_clay 11
fill ~3~10~41 ~3~11~42 minecraft:wool 8
setblock ~3~12~41 minecraft:stone 0
fill ~3~13~41 ~3~14~44 minecraft:wool 8
fill ~6~23~41 ~6~23~43 minecraft:wool 8
fill ~6~24~41 ~6~24~44 minecraft:wool 7
fill ~8~6~41 ~8~6~79 minecraft:wool 8
fill ~8~7~41 ~8~7~78 minecraft:obsidian
fill ~9~6~41 ~19~6~63 minecraft:concrete 15
fill ~10~23~41 ~14~23~41 minecraft:wool 8
fill ~11~24~41 ~12~24~42 minecraft:wool 8
fill ~14~25~41 ~15~25~41 minecraft:wool 8
fill ~16~24~41 ~18~24~42 minecraft:stained_hardened_clay 9
fill ~20~6~41 ~20~6~50 minecraft:wool 8
fill ~20~7~41 ~20~7~50 minecraft:coal_block
fill ~23~23~41 ~28~23~42 minecraft:wool 8
fill ~25~4~41 ~26~4~51 minecraft:stone 0
fill ~25~5~41 ~26~5~113 minecraft:wool 8
fill ~31~6~41 ~31~6~50 minecraft:wool 8
fill ~31~7~41 ~31~7~50 minecraft:coal_block
fill ~32~6~41 ~42~6~78 minecraft:concrete 15
fill ~33~24~41 ~35~24~42 minecraft:stained_hardened_clay 9
fill ~34~10~41 ~34~10~43 minecraft:stone 0
setblock ~34~11~41 minecraft:stone 0
fill ~36~24~41 ~36~25~41 minecraft:wool 8
fill ~37~10~41 ~37~10~43 minecraft:stone 0
setblock ~37~11~41 minecraft:stone 0
fill ~37~23~41 ~41~23~41 minecraft:wool 8
setblock ~37~25~41 minecraft:wool 8
fill ~40~8~41 ~40~8~42 minecraft:stone 0
fill ~43~6~41 ~43~6~79 minecraft:wool 8
fill ~43~7~41 ~43~7~78 minecraft:obsidian
fill ~45~23~41 ~45~23~43 minecraft:wool 8
fill ~45~24~41 ~45~24~44 minecraft:wool 7
fill ~47~7~41 ~48~7~46 minecraft:wool 8
fill ~48~3~41 ~48~4~70 minecraft:wool 8
setblock ~48~9~41 minecraft:stained_hardened_clay 11
fill ~48~11~41 ~48~11~45 minecraft:wool 8
setblock ~48~12~41 minecraft:stone 0
fill ~48~13~41 ~48~14~44 minecraft:wool 8
setblock ~49~2~41 minecraft:wool 8
fill ~50~3~41 ~50~3~42 minecraft:wool 8
fill ~50~4~41 ~50~5~41 minecraft:wool 11
setblock ~1~4~42 minecraft:wool 8
fill ~2~2~42 ~2~2~44 minecraft:wool 11
setblock ~3~9~42 minecraft:wool 7
fill ~3~12~42 ~3~12~44 minecraft:wool 8
fill ~3~17~42 ~3~17~44 minecraft:wool 8
fill ~8~23~42 ~12~23~44 minecraft:wool 8
fill ~8~24~42 ~9~24~43 minecraft:wool 8
setblock ~13~25~42 minecraft:wool 8
fill ~14~24~42 ~15~24~42 minecraft:stained_hardened_clay 9
fill ~15~23~42 ~22~23~42 minecraft:wool 8
setblock ~19~24~42 minecraft:stained_hardened_clay 9
fill ~20~24~42 ~22~24~48 minecraft:coal_block
fill ~20~25~42 ~31~25~43 minecraft:stained_glass 15
fill ~23~24~42 ~28~24~47 minecraft:concrete 11
fill ~29~23~42 ~36~23~42 minecraft:wool 8
fill ~29~24~42 ~31~24~46 minecraft:coal_block
setblock ~32~24~42 minecraft:stained_hardened_clay 9
fill ~34~9~42 ~34~9~43 minecraft:stone 0
fill ~36~24~42 ~37~24~42 minecraft:stained_hardened_clay 9
fill ~37~9~42 ~37~9~43 minecraft:stone 0
fill ~38~24~42 ~38~25~42 minecraft:wool 8
fill ~39~8~42 ~39~10~42 minecraft:stone 0
fill ~39~23~42 ~43~23~44 minecraft:wool 8
setblock ~40~10~42 minecraft:stone 0
setblock ~48~9~42 minecraft:wool 7
fill ~48~12~42 ~48~12~44 minecraft:wool 8
fill ~48~17~42 ~48~17~44 minecraft:wool 8
fill ~49~2~42 ~49~2~44 minecraft:wool 11
setblock ~50~4~42 minecraft:wool 8
fill ~1~3~43 ~1~4~44 minecraft:wool 11
fill ~2~5~43 ~2~5~45 minecraft:wool 11
fill ~2~6~43 ~3~6~43 minecraft:wool 8
fill ~3~5~43 ~3~5~46 minecraft:wool 8
setblock ~3~8~43 minecraft:wool 11
fill ~3~9~43 ~3~9~45 minecraft:stained_hardened_clay 11
fill ~3~10~43 ~3~10~45 minecraft:wool 11
fill ~3~11~43 ~3~11~45 minecraft:wool 8
fill ~4~8~43 ~4~9~56 minecraft:wool 8
fill ~7~23~43 ~7~23~52 minecraft:wool 8
fill ~11~24~43 ~14~24~43 minecraft:stained_hardened_clay 9
fill ~13~23~43 ~15~23~43 minecraft:wool 8
fill ~15~24~43 ~19~24~48 minecraft:coal_block
fill ~15~25~43 ~19~25~44 minecraft:stained_glass 15
fill ~21~23~43 ~22~23~49 minecraft:wool 8
fill ~21~26~43 ~30~26~45 minecraft:stained_glass 15
fill ~29~23~43 ~30~23~49 minecraft:wool 8
fill ~32~24~43 ~36~24~46 minecraft:coal_block
fill ~32~25~43 ~36~25~44 minecraft:stained_glass 15
fill ~33~9~43 ~33~10~43 minecraft:stone 0
fill ~36~9~43 ~36~10~43 minecraft:stone 0
fill ~36~23~43 ~38~23~43 minecraft:wool 8
fill ~37~24~43 ~40~24~43 minecraft:stained_hardened_clay 9
fill ~39~7~43 ~40~7~43 minecraft:stone 0
fill ~44~23~43 ~44~23~52 minecraft:wool 8
fill ~47~8~43 ~47~9~56 minecraft:wool 8
fill ~48~5~43 ~48~5~46 minecraft:wool 8
fill ~48~6~43 ~49~6~43 minecraft:wool 8
setblock ~48~8~43 minecraft:wool 11
fill ~48~9~43 ~48~9~45 minecraft:stained_hardened_clay 11
fill ~48~10~43 ~48~10~45 minecraft:wool 11
fill ~49~5~43 ~49~5~45 minecraft:wool 11
fill ~50~3~43 ~50~4~44 minecraft:wool 11
fill ~3~6~44 ~3~6~45 minecraft:wool 11
fill ~3~8~44 ~3~8~45 minecraft:wool 8
fill ~4~12~44 ~4~19~46 minecraft:wool 8
fill ~5~24~44 ~5~24~46 minecraft:wool 8
setblock ~8~24~44 minecraft:wool 8
fill ~9~24~44 ~10~24~44 minecraft:stained_hardened_clay 9
fill ~11~24~44 ~14~24~48 minecraft:coal_block
fill ~11~25~44 ~14~25~45 minecraft:stained_glass 15
fill ~15~26~44 ~20~26~45 minecraft:stained_glass 15
setblock ~20~25~44 minecraft:stained_glass 15
fill ~31~25~44 ~31~26~44 minecraft:stained_glass 15
fill ~32~26~44 ~36~26~45 minecraft:stained_glass 15
fill ~37~24~44 ~40~24~46 minecraft:coal_block
fill ~37~25~44 ~40~25~45 minecraft:stained_glass 15
fill ~41~24~44 ~42~24~44 minecraft:stained_hardened_clay 9
fill ~46~24~44 ~46~24~46 minecraft:wool 8
fill ~47~12~44 ~47~19~46 minecraft:wool 8
fill ~48~6~44 ~48~6~45 minecraft:wool 11
fill ~48~8~44 ~48~8~45 minecraft:wool 8
fill ~1~3~45 ~1~4~45 minecraft:wool 8
setblock ~2~2~45 minecraft:wool 8
fill ~3~12~45 ~3~19~45 minecraft:wool 7
fill ~4~10~45 ~5~11~46 minecraft:wool 8
fill ~5~9~45 ~5~9~47 minecraft:wool 8
fill ~5~12~45 ~7~20~46 minecraft:wool 8
fill ~5~21~45 ~5~21~47 minecraft:wool 8
fill ~6~11~45 ~7~11~46 minecraft:wool 8
fill ~6~24~45 ~6~24~53 minecraft:wool 8
setblock ~7~24~45 minecraft:wool 7
fill ~8~23~45 ~10~23~49 minecraft:wool 8
setblock ~8~24~45 minecraft:stained_hardened_clay 9
fill ~9~24~45 ~10~24~49 minecraft:coal_block
fill ~9~25~45 ~10~25~46 minecraft:stained_glass 15
fill ~12~26~45 ~14~26~46 minecraft:stained_glass 15
fill ~20~27~45 ~31~27~47 minecraft:stained_glass 15
setblock ~31~26~45 minecraft:stained_glass 15
fill ~37~26~45 ~39~26~46 minecraft:stained_glass 15
fill ~41~23~45 ~43~23~49 minecraft:wool 8
fill ~41~24~45 ~42~24~49 minecraft:coal_block
fill ~41~25~45 ~42~25~46 minecraft:stained_glass 15
setblock ~43~24~45 minecraft:stained_hardened_clay 9
fill ~44~11~45 ~47~11~46 minecraft:wool 8
fill ~44~12~45 ~46~20~46 minecraft:wool 8
setblock ~44~24~45 minecraft:wool 7
fill ~45~24~45 ~45~24~53 minecraft:wool 8
fill ~46~9~45 ~46~9~47 minecraft:wool 8
fill ~46~10~45 ~47~10~46 minecraft:wool 8
fill ~46~21~45 ~46~21~47 minecraft:wool 8
fill ~48~12~45 ~48~19~45 minecraft:wool 7
setblock ~49~2~45 minecraft:wool 8
fill ~50~3~45 ~50~4~45 minecraft:wool 8
fill ~1~3~46 ~1~3~48 minecraft:wool 11
setblock ~1~4~46 minecraft:wool 8
fill ~2~2~46 ~2~2~48 minecraft:wool 11
setblock ~2~5~46 minecraft:wool 8
setblock ~3~6~46 minecraft:wool 8
fill ~3~8~46 ~3~11~46 minecraft:wool 7
fill ~3~12~46 ~3~19~52 minecraft:wool 8
setblock ~3~20~46 minecraft:wool 7
fill ~4~21~46 ~4~22~46 minecraft:wool 7
fill ~5~8~46 ~6~8~73 minecraft:wool 8
setblock ~5~23~46 minecraft:wool 7
fill ~6~9~46 ~7~9~47 minecraft:wool 8
fill ~6~10~46 ~7~10~46 minecraft:wool 8
fill ~6~21~46 ~8~21~47 minecraft:wool 8
fill ~6~22~46 ~6~23~47 minecraft:wool 8
fill ~7~24~46 ~7~24~49 minecraft:wool 8
fill ~7~25~46 ~7~25~47 minecraft:wool 8
fill ~8~14~46 ~8~20~49 minecraft:wool 8
fill ~8~24~46 ~8~24~50 minecraft:coal_block
setblock ~8~25~46 minecraft:stained_glass 15
fill ~10~26~46 ~11~26~47 minecraft:stained_glass 15
setblock ~11~25~46 minecraft:stained_glass 15
fill ~15~26~46 ~18~27~46 minecraft:stained_glass 15
fill ~19~27~46 ~19~27~47 minecraft:stained_glass 15
fill ~32~27~46 ~36~27~47 minecraft:stained_glass 15
fill ~33~26~46 ~36~26~46 minecraft:stained_glass 15
fill ~40~25~46 ~40~26~46 minecraft:stained_glass 15
fill ~41~26~46 ~41~26~48 minecraft:stained_glass 15
fill ~43~14~46 ~43~21~49 minecraft:wool 8
fill ~43~24~46 ~43~24~49 minecraft:coal_block
setblock ~43~25~46 minecraft:stained_glass 15
fill ~44~9~46 ~45~9~47 minecraft:wool 8
fill ~44~10~46 ~45~10~46 minecraft:wool 8
fill ~44~21~46 ~45~21~47 minecraft:wool 8
fill ~44~24~46 ~44~24~49 minecraft:wool 8
fill ~44~25~46 ~44~25~47 minecraft:wool 8
fill ~45~8~46 ~46~8~73 minecraft:wool 8
fill ~45~22~46 ~45~23~47 minecraft:wool 8
setblock ~46~23~46 minecraft:wool 7
fill ~47~21~46 ~47~22~46 minecraft:wool 7
setblock ~48~6~46 minecraft:wool 8
fill ~48~8~46 ~48~11~46 minecraft:wool 7
fill ~48~12~46 ~48~19~52 minecraft:wool 8
setblock ~48~20~46 minecraft:wool 7
fill ~49~2~46 ~49~2~48 minecraft:wool 11
setblock ~49~5~46 minecraft:wool 8
fill ~50~3~46 ~50~3~48 minecraft:wool 11
setblock ~50~4~46 minecraft:wool 8
fill ~1~4~47 ~2~4~48 minecraft:wool 11
fill ~3~5~47 ~3~6~49 minecraft:wool 11
fill ~3~7~47 ~3~7~51 minecraft:wool 7
fill ~3~9~47 ~3~10~48 minecraft:wool 11
setblock ~3~11~47 minecraft:wool 8
fill ~3~20~47 ~3~20~78 minecraft:wool 8
fill ~4~6~47 ~4~7~47 minecraft:wool 8
fill ~4~21~47 ~4~22~72 minecraft:wool 8
fill ~5~7~47 ~5~7~90 minecraft:wool 8
fill ~5~20~47 ~6~20~47 minecraft:wool 8
fill ~5~23~47 ~5~23~81 minecraft:wool 8
setblock ~5~24~47 minecraft:wool 7
fill ~6~14~47 ~7~17~47 minecraft:wool 8
fill ~6~18~47 ~6~19~48 minecraft:wool 8
fill ~6~25~47 ~6~25~53 minecraft:wool 8
fill ~7~8~47 ~7~8~72 minecraft:wool 8
setblock ~7~13~47 minecraft:wool 8
fill ~7~22~47 ~8~22~50 minecraft:wool 8
fill ~8~25~47 ~8~25~51 minecraft:coal_block
fill ~8~26~47 ~9~26~48 minecraft:stained_glass 15
fill ~12~26~47 ~13~27~47 minecraft:stained_glass 15
fill ~13~25~47 ~18~25~49 minecraft:coal_block
fill ~14~27~47 ~18~27~47 minecraft:stained_glass 15
fill ~18~28~47 ~33~28~49 minecraft:stained_glass 15
fill ~29~24~47 ~30~24~48 minecraft:coal_block
fill ~31~24~47 ~31~24~50 minecraft:wool 8
fill ~31~25~47 ~39~25~52 minecraft:coal_block
fill ~35~24~47 ~39~24~47 minecraft:wool 8
fill ~37~27~47 ~39~27~48 minecraft:stained_glass 15
fill ~38~26~47 ~40~26~47 minecraft:stained_glass 15
fill ~40~24~47 ~40~24~48 minecraft:coal_block
fill ~42~26~47 ~43~26~48 minecraft:stained_glass 15
fill ~43~22~47 ~44~22~50 minecraft:wool 8
setblock ~43~25~47 minecraft:coal_block
fill ~44~8~47 ~44~8~72 minecraft:wool 8
fill ~44~13~47 ~44~17~47 minecraft:wool 8
fill ~45~14~47 ~45~20~47 minecraft:wool 8
fill ~45~25~47 ~45~25~53 minecraft:wool 8
setblock ~46~20~47 minecraft:wool 8
fill ~46~23~47 ~46~23~81 minecraft:wool 8
setblock ~46~24~47 minecraft:wool 7
fill ~47~6~47 ~47~7~47 minecraft:wool 8
fill ~47~21~47 ~47~22~72 minecraft:wool 8
fill ~48~5~47 ~48~6~49 minecraft:wool 11
fill ~48~7~47 ~48~7~51 minecraft:wool 7
fill ~48~9~47 ~48~10~48 minecraft:wool 11
setblock ~48~11~47 minecraft:wool 8
fill ~48~20~47 ~48~20~78 minecraft:wool 8
fill ~49~4~47 ~50~4~48 minecraft:wool 11
fill ~3~11~48 ~3~11~50 minecraft:wool 11
fill ~4~7~48 ~4~7~90 minecraft:wool 8
fill ~5~24~48 ~5~24~52 minecraft:wool 8
fill ~6~20~48 ~7~20~48 minecraft:wool 8
setblock ~6~23~48 minecraft:wool 8
fill ~7~14~48 ~7~19~48 minecraft:wool 8
fill ~7~21~48 ~8~21~50 minecraft:wool 8
fill ~7~25~48 ~7~25~49 minecraft:coal_block
fill ~7~26~48 ~7~26~52 minecraft:wool 8
fill ~9~14~48 ~21~14~48 minecraft:wool 8
fill ~10~26~48 ~10~27~48 minecraft:stained_glass 15
fill ~11~27~48 ~17~27~48 minecraft:stained_glass 15
fill ~12~25~48 ~12~25~49 minecraft:coal_block
fill ~13~26~48 ~18~26~49 minecraft:coal_block
fill ~14~28~48 ~17~28~49 minecraft:stained_glass 15
fill ~19~25~48 ~19~25~49 minecraft:coal_block
fill ~21~7~48 ~21~7~50 minecraft:wool 8
fill ~21~8~48 ~21~8~58 minecraft:coal_block
fill ~23~24~48 ~25~24~48 minecraft:concrete 11
fill ~26~24~48 ~27~24~48 minecraft:wool 8
fill ~26~25~48 ~28~25~48 minecraft:concrete 11
fill ~27~26~48 ~27~26~50 minecraft:concrete 11
fill ~30~7~48 ~30~7~50 minecraft:wool 8
fill ~30~8~48 ~30~8~50 minecraft:coal_block
fill ~30~14~48 ~42~14~48 minecraft:wool 8
fill ~34~27~48 ~36~28~48 minecraft:stained_glass 15
