setblock ~26 ~0 ~29 furnace 3  
setblock ~27 ~0 ~28 furnace 3  
setblock ~27 ~0 ~30 furnace 3  
setblock ~28 ~0 ~29 furnace 5  
setblock ~26 ~0 ~56 furnace 4  
setblock ~27 ~0 ~55 furnace 2  
setblock ~27 ~0 ~57 furnace 3  
setblock ~28 ~0 ~56 furnace 5  
setblock ~50 ~0 ~29 furnace 3  
setblock ~51 ~0 ~28 furnace 3  
setblock ~51 ~0 ~30 furnace 3  
setblock ~52 ~0 ~29 furnace 5  
setblock ~50 ~0 ~56 furnace 3  
setblock ~51 ~0 ~55 furnace 3  
setblock ~51 ~0 ~57 furnace 4  
setblock ~52 ~0 ~56 furnace 5  
fill ~4 ~-2 ~33 ~9 ~-2 ~33 lapis_block 0  
fill ~4 ~-2 ~34 ~9 ~-2 ~34 lapis_block 0  
fill ~4 ~-2 ~51 ~9 ~-2 ~51 lapis_block 0  
fill ~4 ~-2 ~52 ~9 ~-2 ~52 lapis_block 0  
fill ~6 ~-2 ~31 ~9 ~-2 ~31 lapis_block 0  
fill ~6 ~-2 ~32 ~9 ~-2 ~32 lapis_block 0  
fill ~6 ~-2 ~53 ~9 ~-2 ~53 lapis_block 0 
setblock ~20 ~-2 ~70 redstone_wire 8 
setblock ~20 ~-2 ~71 redstone_wire 7 
setblock ~20 ~-2 ~72 redstone_wire 6 
setblock ~21 ~-2 ~69 redstone_wire 10 
setblock ~21 ~-2 ~70 redstone_wire 9 
setblock ~21 ~-2 ~72 redstone_wire 5 
setblock ~21 ~-2 ~73 redstone_wire 4 
setblock ~22 ~-2 ~69 redstone_wire 11 
setblock ~22 ~-2 ~73 redstone_wire 3 
setblock ~23 ~-2 ~69 redstone_wire 12 
setblock ~23 ~-2 ~73 redstone_wire 2 
setblock ~24 ~-2 ~68 redstone_wire 14 
setblock ~24 ~-2 ~69 redstone_wire 13 
setblock ~24 ~-2 ~73 redstone_wire 1  
fill ~24 ~-2 ~74 ~28 ~-2 ~74 redstone_wire 0 
setblock ~25 ~-2 ~66 redstone_wire 1 
setblock ~25 ~-2 ~67 powered_repeater 2 
setblock ~25 ~-2 ~68 redstone_wire 15 
setblock ~26 ~-2 ~65 redstone_wire 3 
setblock ~26 ~-2 ~66 redstone_wire 2  
fill ~26 ~-2 ~72 ~29 ~-2 ~72 redstone_wire 0  
fill ~26 ~-2 ~73 ~26 ~-2 ~72 redstone_wire 0 
setblock ~27 ~-2 ~64 redstone_wire 5 
setblock ~27 ~-2 ~65 redstone_wire 4 
setblock ~28 ~-2 ~64 redstone_wire 6  
fill ~28 ~-2 ~75 ~34 ~-2 ~75 redstone_wire 0 
setblock ~29 ~-2 ~62 redstone_wire 9 
setblock ~29 ~-2 ~63 redstone_wire 8 
setblock ~29 ~-2 ~64 redstone_wire 7 
setblock ~29 ~-2 ~65 redstone_wire 6  
fill ~29 ~-2 ~67 ~29 ~-2 ~70 redstone_wire 0 
setblock ~29 ~-2 ~71 unpowered_repeater 2  
fill ~30 ~-2 ~33 ~32 ~-2 ~33 wool 11  
fill ~30 ~-2 ~34 ~30 ~-1 ~34 gold_block 0  
fill ~30 ~-2 ~35 ~30 ~-1 ~35 gold_block 0  
fill ~30 ~-2 ~36 ~32 ~-2 ~36 wool 11  
fill ~30 ~-2 ~37 ~31 ~-2 ~37 gold_block 0  
fill ~30 ~-2 ~38 ~30 ~-2 ~40 gold_block 0 
setblock ~30 ~-2 ~41 wool 11  
fill ~30 ~-2 ~42 ~31 ~-2 ~42 gold_block 0  
fill ~30 ~-2 ~43 ~30 ~-2 ~44 wool 11  
fill ~30 ~-2 ~45 ~31 ~-2 ~45 gold_block 0  
fill ~30 ~-2 ~46 ~31 ~-2 ~46 wool 11  
fill ~30 ~-2 ~47 ~30 ~-2 ~49 wool 11  
fill ~30 ~-2 ~50 ~31 ~-2 ~50 gold_block 0  
fill ~30 ~-2 ~51 ~30 ~-1 ~51 wool 11 
setblock ~30 ~-2 ~61 redstone_wire 11 
setblock ~30 ~-2 ~62 redstone_wire 10  
fill ~31 ~-2 ~2 ~31 ~-2 ~6 gold_block 0  
fill ~31 ~-2 ~7 ~31 ~-1 ~7 wool 11  
fill ~31 ~-2 ~8 ~31 ~-1 ~8 wool 11  
fill ~31 ~-2 ~9 ~31 ~-1 ~9 wool 11  
fill ~31 ~-2 ~34 ~31 ~-2 ~36 wool 11  
fill ~31 ~-2 ~38 ~33 ~-2 ~38 wool 11  
fill ~31 ~-2 ~39 ~31 ~-2 ~38 wool 11  
fill ~31 ~-2 ~40 ~31 ~-2 ~45 gold_block 0 
setblock ~31 ~-2 ~47 gold_block 0  
fill ~31 ~-2 ~48 ~35 ~-2 ~48 wool 11  
fill ~31 ~-2 ~49 ~32 ~-2 ~49 gold_block 0  
fill ~31 ~-2 ~51 ~33 ~-2 ~51 gold_block 0 
setblock ~31 ~-2 ~60 redstone_wire 13 
setblock ~31 ~-2 ~61 redstone_wire 12  
fill ~32 ~-2 ~2 ~32 ~-2 ~3 wool 11  
fill ~32 ~-2 ~4 ~33 ~-2 ~4 gold_block 0  
fill ~32 ~-2 ~5 ~32 ~-2 ~6 wool 11  
fill ~32 ~-2 ~7 ~33 ~-2 ~7 gold_block 0  
fill ~32 ~-2 ~8 ~32 ~-1 ~8 gold_block 0  
fill ~32 ~-2 ~9 ~33 ~-2 ~9 gold_block 0  
fill ~32 ~-2 ~34 ~35 ~-2 ~34 gold_block 0  
fill ~32 ~-2 ~35 ~32 ~-2 ~34 gold_block 0 
setblock ~32 ~-2 ~37 wool 11  
fill ~32 ~-2 ~39 ~33 ~-2 ~39 gold_block 0 
setblock ~32 ~-2 ~40 wool 11  
fill ~32 ~-2 ~41 ~33 ~-2 ~41 gold_block 0  
fill ~32 ~-2 ~42 ~33 ~-2 ~42 wool 11  
fill ~32 ~-2 ~43 ~32 ~-2 ~42 wool 11  
fill ~32 ~-2 ~44 ~33 ~-2 ~44 gold_block 0 
setblock ~32 ~-2 ~45 wool 11  
fill ~32 ~-2 ~46 ~33 ~-2 ~46 gold_block 0 
setblock ~32 ~-2 ~47 wool 11 
setblock ~32 ~-2 ~50 wool 11 
setblock ~32 ~-2 ~60 redstone_wire 14  
fill ~33 ~-2 ~2 ~33 ~-2 ~7 gold_block 0 
setblock ~33 ~-2 ~8 wool 11 
setblock ~33 ~-2 ~33 gold_block 0  
fill ~33 ~-2 ~35 ~34 ~-2 ~35 wool 11  
fill ~33 ~-2 ~36 ~33 ~-2 ~37 gold_block 0  
fill ~33 ~-2 ~40 ~33 ~-1 ~40 gold_block 0  
fill ~33 ~-2 ~43 ~33 ~-1 ~43 gold_block 0  
fill ~33 ~-2 ~45 ~33 ~-1 ~45 gold_block 0 
setblock ~33 ~-2 ~47 gold_block 0  
fill ~33 ~-2 ~49 ~34 ~-2 ~49 wool 11 
setblock ~33 ~-2 ~50 gold_block 0 
setblock ~33 ~-2 ~58 redstone_wire 5 
setblock ~33 ~-2 ~59 powered_repeater 2 
setblock ~33 ~-2 ~60 redstone_wire 15  
fill ~34 ~-2 ~2 ~35 ~-2 ~2 wool 11  
fill ~34 ~-2 ~3 ~38 ~-2 ~3 gold_block 0  
fill ~34 ~-2 ~4 ~35 ~-2 ~4 wool 11  
fill ~34 ~-2 ~5 ~34 ~-2 ~4 wool 11 
setblock ~34 ~-2 ~6 gold_block 0  
fill ~34 ~-2 ~7 ~37 ~-2 ~7 wool 11  
fill ~34 ~-2 ~8 ~35 ~-2 ~8 gold_block 0 
setblock ~34 ~-2 ~9 wool 11  
fill ~34 ~-2 ~33 ~35 ~-2 ~33 wool 11  
fill ~34 ~-2 ~36 ~36 ~-2 ~36 wool 11  
fill ~34 ~-2 ~50 ~34 ~-2 ~51 wool 11 
setblock ~34 ~-2 ~57 redstone_wire 7 
setblock ~34 ~-2 ~58 redstone_wire 6  
fill ~35 ~-2 ~5 ~36 ~-2 ~5 gold_block 0 
setblock ~35 ~-2 ~6 wool 11 
setblock ~35 ~-2 ~9 gold_block 0  
fill ~35 ~-2 ~35 ~37 ~-2 ~35 gold_block 0  
fill ~35 ~-2 ~49 ~35 ~-2 ~50 gold_block 0 
setblock ~35 ~-2 ~51 wool 11 
setblock ~35 ~-2 ~56 redstone_wire 9 
setblock ~35 ~-2 ~57 redstone_wire 8 
setblock ~36 ~-2 ~2 gold_block 0 
setblock ~36 ~-2 ~4 gold_block 0 
setblock ~36 ~-2 ~6 gold_block 0 
setblock ~36 ~-2 ~8 wool 11 
setblock ~36 ~-2 ~9 log 0 
setblock ~36 ~-2 ~33 log 0 
setblock ~36 ~-2 ~34 wool 11  
fill ~36 ~-2 ~48 ~38 ~-2 ~48 gold_block 0  
fill ~36 ~-2 ~49 ~37 ~-2 ~49 wool 11  
fill ~36 ~-2 ~50 ~38 ~-2 ~50 gold_block 0  
fill ~36 ~-2 ~51 ~36 ~-2 ~50 gold_block 0 
setblock ~36 ~-2 ~55 redstone_wire 11 
setblock ~36 ~-2 ~56 redstone_wire 10  
fill ~37 ~-2 ~2 ~38 ~-2 ~2 wool 11  
fill ~37 ~-2 ~4 ~37 ~-2 ~7 wool 11  
fill ~37 ~-2 ~8 ~38 ~-2 ~8 gold_block 0  
fill ~37 ~-2 ~9 ~41 ~-2 ~9 wool 14  
fill ~37 ~-2 ~33 ~41 ~-2 ~33 wool 14  
fill ~37 ~-2 ~34 ~38 ~-2 ~34 gold_block 0  
fill ~37 ~-2 ~36 ~37 ~-1 ~36 gold_block 0 
setblock ~37 ~-2 ~51 wool 11 
setblock ~37 ~-2 ~52 redstone_wire 15 
setblock ~37 ~-2 ~53 redstone_wire 14 
setblock ~37 ~-2 ~54 redstone_wire 13 
setblock ~37 ~-2 ~55 redstone_wire 12  
fill ~38 ~-2 ~4 ~38 ~-2 ~5 gold_block 0  
fill ~38 ~-2 ~6 ~42 ~-2 ~6 wool 11  
fill ~38 ~-2 ~7 ~40 ~-2 ~7 gold_block 0  
fill ~38 ~-2 ~35 ~39 ~-2 ~35 wool 11  
fill ~38 ~-2 ~36 ~38 ~-2 ~35 wool 11  
fill ~38 ~-2 ~49 ~38 ~-1 ~49 gold_block 0  
fill ~38 ~-2 ~51 ~40 ~-2 ~51 gold_block 0  
fill ~39 ~-2 ~2 ~40 ~-2 ~2 gold_block 0  
fill ~39 ~-2 ~3 ~39 ~-2 ~4 wool 11  
fill ~39 ~-2 ~5 ~43 ~-2 ~5 gold_block 0 
setblock ~39 ~-2 ~8 wool 11 
setblock ~39 ~-2 ~34 wool 11  
fill ~39 ~-2 ~36 ~42 ~-2 ~36 gold_block 0  
fill ~39 ~-2 ~48 ~44 ~-2 ~48 wool 11  
fill ~39 ~-2 ~49 ~39 ~-2 ~50 wool 11  
fill ~40 ~-2 ~3 ~41 ~-2 ~3 gold_block 0 
setblock ~40 ~-2 ~4 wool 11 
setblock ~40 ~-2 ~8 gold_block 0  
fill ~40 ~-2 ~34 ~40 ~-2 ~36 gold_block 0  
fill ~40 ~-2 ~49 ~40 ~-1 ~49 gold_block 0  
fill ~40 ~-2 ~50 ~40 ~-2 ~49 gold_block 0  
fill ~41 ~-2 ~2 ~42 ~-2 ~2 wool 11 
setblock ~41 ~-2 ~4 gold_block 0  
fill ~41 ~-2 ~7 ~41 ~-2 ~8 wool 11  
fill ~41 ~-2 ~34 ~44 ~-2 ~34 wool 11  
fill ~41 ~-2 ~35 ~41 ~-2 ~34 wool 11  
fill ~41 ~-2 ~49 ~41 ~-2 ~51 wool 11  
fill ~42 ~-2 ~3 ~42 ~-2 ~4 wool 11  
fill ~42 ~-2 ~7 ~42 ~-2 ~8 gold_block 0 
setblock ~42 ~-2 ~9 log 0 
setblock ~42 ~-2 ~33 log 0  
fill ~42 ~-2 ~35 ~43 ~-2 ~35 gold_block 0  
fill ~42 ~-2 ~49 ~44 ~-2 ~49 gold_block 0  
fill ~42 ~-2 ~50 ~43 ~-2 ~50 wool 11 
setblock ~42 ~-2 ~51 gold_block 0  
fill ~43 ~-2 ~2 ~43 ~-2 ~3 gold_block 0 
setblock ~43 ~-2 ~4 wool 11  
fill ~43 ~-2 ~6 ~45 ~-2 ~6 gold_block 0 
setblock ~43 ~-2 ~7 wool 11  
fill ~43 ~-2 ~8 ~44 ~-2 ~8 gold_block 0 
setblock ~43 ~-2 ~9 wool 11  
fill ~43 ~-2 ~33 ~45 ~-2 ~33 gold_block 0  
fill ~43 ~-2 ~36 ~44 ~-2 ~36 wool 11 
setblock ~43 ~-2 ~51 wool 11 
setblock ~44 ~-2 ~2 wool 11  
fill ~44 ~-2 ~3 ~44 ~-2 ~4 gold_block 0 
setblock ~44 ~-2 ~5 wool 11 
setblock ~44 ~-2 ~7 gold_block 0  
fill ~44 ~-2 ~9 ~45 ~-2 ~9 gold_block 0 
setblock ~44 ~-2 ~35 wool 11  
fill ~44 ~-2 ~50 ~44 ~-2 ~51 gold_block 0  
fill ~45 ~-2 ~2 ~47 ~-2 ~2 gold_block 0  
fill ~45 ~-2 ~3 ~46 ~-2 ~3 wool 11  
fill ~45 ~-2 ~4 ~45 ~-2 ~6 gold_block 0  
fill ~45 ~-2 ~7 ~45 ~-2 ~8 wool 11  
fill ~45 ~-2 ~34 ~45 ~-1 ~34 log 0  
fill ~45 ~-2 ~35 ~48 ~-2 ~35 gold_block 0  
fill ~45 ~-2 ~36 ~45 ~-2 ~35 gold_block 0  
fill ~45 ~-2 ~37 ~45 ~-2 ~41 wool 11  
fill ~45 ~-2 ~42 ~48 ~-2 ~42 gold_block 0  
fill ~45 ~-2 ~43 ~46 ~-2 ~43 wool 11  
fill ~45 ~-2 ~44 ~46 ~-2 ~44 gold_block 0  
fill ~45 ~-2 ~45 ~45 ~-1 ~45 gold_block 0  
fill ~45 ~-2 ~46 ~48 ~-2 ~46 gold_block 0  
fill ~45 ~-2 ~47 ~45 ~-2 ~48 gold_block 0  
fill ~45 ~-2 ~49 ~48 ~-2 ~49 wool 11  
fill ~45 ~-2 ~50 ~45 ~-2 ~51 wool 11  
fill ~46 ~-2 ~4 ~46 ~-2 ~6 wool 11  
fill ~46 ~-2 ~7 ~46 ~-2 ~8 gold_block 0  
fill ~46 ~-2 ~9 ~46 ~-1 ~9 wool 11  
fill ~46 ~-2 ~33 ~46 ~-2 ~34 wool 11  
fill ~46 ~-2 ~36 ~47 ~-2 ~36 wool 11  
fill ~46 ~-2 ~37 ~48 ~-2 ~37 gold_block 0  
fill ~46 ~-2 ~38 ~46 ~-2 ~37 gold_block 0  
fill ~46 ~-2 ~39 ~47 ~-2 ~39 wool 11  
fill ~46 ~-2 ~40 ~48 ~-2 ~40 gold_block 0  
fill ~46 ~-2 ~41 ~46 ~-2 ~40 gold_block 0 
setblock ~46 ~-2 ~45 wool 11  
fill ~46 ~-2 ~47 ~47 ~-2 ~47 wool 11  
fill ~46 ~-2 ~48 ~46 ~-2 ~47 wool 11  
fill ~46 ~-2 ~50 ~48 ~-2 ~50 gold_block 0  
fill ~46 ~-2 ~51 ~48 ~-2 ~51 wool 11  
fill ~47 ~-2 ~3 ~47 ~-2 ~6 gold_block 0  
fill ~47 ~-2 ~7 ~48 ~-2 ~7 wool 11  
fill ~47 ~-2 ~8 ~47 ~-1 ~8 gold_block 0  
fill ~47 ~-2 ~9 ~48 ~-2 ~9 gold_block 0  
fill ~47 ~-2 ~33 ~47 ~-2 ~35 gold_block 0  
fill ~47 ~-2 ~38 ~48 ~-2 ~38 wool 11  
fill ~47 ~-2 ~41 ~48 ~-2 ~41 wool 11 
setblock ~47 ~-2 ~43 gold_block 0 
setblock ~47 ~-2 ~44 wool 11 
setblock ~47 ~-2 ~45 gold_block 0  
fill ~47 ~-2 ~48 ~48 ~-2 ~48 gold_block 0  
fill ~48 ~-2 ~2 ~48 ~-2 ~3 wool 11 
setblock ~48 ~-2 ~4 gold_block 0 
setblock ~48 ~-2 ~5 wool 11  
fill ~48 ~-2 ~6 ~48 ~-1 ~6 gold_block 0  
fill ~48 ~-2 ~8 ~48 ~-1 ~8 wool 11  
fill ~48 ~-2 ~33 ~48 ~-2 ~34 wool 11 
setblock ~48 ~-2 ~36 gold_block 0 
setblock ~48 ~-2 ~39 gold_block 0 
setblock ~48 ~-2 ~43 wool 11 
setblock ~48 ~-2 ~44 gold_block 0 
setblock ~48 ~-2 ~45 wool 11 
setblock ~48 ~-2 ~47 gold_block 0 
setblock ~49 ~-2 ~42 lever 14  
fill ~71 ~-2 ~1 ~75 ~-2 ~1 stone 0  
fill ~71 ~-2 ~2 ~75 ~-2 ~2 stone 0  
fill ~71 ~-2 ~3 ~75 ~-2 ~3 stone 0  
fill ~71 ~-2 ~4 ~75 ~-2 ~4 stone 0  
fill ~71 ~-2 ~5 ~75 ~-2 ~5 stone 0  
fill ~71 ~-2 ~6 ~75 ~-2 ~6 stone 0  
fill ~71 ~-2 ~7 ~75 ~-2 ~7 stone 0  
fill ~71 ~-2 ~8 ~75 ~-2 ~8 stone 0  
fill ~71 ~-2 ~9 ~75 ~-2 ~9 stone 0  
fill ~71 ~-2 ~10 ~75 ~-2 ~10 stone 0  
fill ~71 ~-2 ~11 ~75 ~-2 ~11 stone 0  
fill ~71 ~-2 ~12 ~75 ~-2 ~12 stone 0  
fill ~71 ~-2 ~13 ~75 ~-2 ~13 stone 0  
fill ~71 ~-2 ~14 ~75 ~-2 ~14 stone 0  
fill ~71 ~-2 ~15 ~75 ~-2 ~15 stone 0  
fill ~71 ~-2 ~16 ~75 ~-2 ~16 stone 0  
fill ~71 ~-2 ~17 ~75 ~-2 ~17 stone 0  
fill ~71 ~-2 ~18 ~75 ~-2 ~18 stone 0  
fill ~71 ~-2 ~19 ~75 ~-2 ~19 stone 0  
fill ~71 ~-2 ~20 ~75 ~-2 ~20 stone 0  
fill ~71 ~-2 ~21 ~75 ~-2 ~21 stone 0  
fill ~71 ~-2 ~22 ~75 ~-2 ~22 stone 0  
fill ~71 ~-2 ~23 ~75 ~-2 ~23 stone 0  
fill ~71 ~-2 ~24 ~75 ~-2 ~24 stone 0  
fill ~71 ~-2 ~25 ~75 ~-2 ~25 stone 0  
fill ~71 ~-2 ~26 ~75 ~-2 ~26 stone 0  
fill ~71 ~-2 ~27 ~75 ~-2 ~27 stone 0  
fill ~71 ~-2 ~28 ~75 ~-2 ~28 stone 0  
fill ~71 ~-2 ~29 ~76 ~-2 ~29 stone 0 
setblock ~75 ~-2 ~62 glowstone 0 
setblock ~75 ~-2 ~66 glowstone 0 
setblock ~75 ~-2 ~71 glowstone 0 
setblock ~75 ~-2 ~75 glowstone 0  
fill ~76 ~-2 ~30 ~76 ~-2 ~77 stone 0  
fill ~1 ~-1 ~1 ~17 ~-1 ~1 grass 0  
fill ~1 ~-1 ~2 ~16 ~-1 ~2 grass 0  
fill ~1 ~-1 ~3 ~16 ~-1 ~3 grass 0  
fill ~1 ~-1 ~4 ~16 ~-1 ~4 grass 0  
fill ~1 ~-1 ~5 ~16 ~-1 ~5 grass 0  
fill ~1 ~-1 ~6 ~16 ~-1 ~6 grass 0  
fill ~1 ~-1 ~7 ~16 ~-1 ~7 grass 0  
fill ~1 ~-1 ~8 ~16 ~-1 ~8 grass 0  
fill ~1 ~-1 ~9 ~16 ~-1 ~9 grass 0  
fill ~1 ~-1 ~10 ~16 ~-1 ~10 grass 0  
fill ~1 ~-1 ~11 ~16 ~-1 ~11 grass 0  
fill ~1 ~-1 ~12 ~16 ~-1 ~12 grass 0  
fill ~1 ~-1 ~13 ~16 ~-1 ~13 grass 0  
fill ~1 ~-1 ~14 ~16 ~-1 ~14 grass 0  
fill ~1 ~-1 ~15 ~16 ~-1 ~15 grass 0  
fill ~1 ~-1 ~16 ~16 ~-1 ~16 grass 0  
fill ~1 ~-1 ~17 ~16 ~-1 ~17 grass 0  
fill ~1 ~-1 ~18 ~16 ~-1 ~18 grass 0  
fill ~1 ~-1 ~19 ~16 ~-1 ~19 grass 0  
fill ~1 ~-1 ~20 ~16 ~-1 ~20 grass 0  
fill ~1 ~-1 ~21 ~16 ~-1 ~21 grass 0  
fill ~1 ~-1 ~22 ~16 ~-1 ~22 grass 0  
fill ~1 ~-1 ~23 ~16 ~-1 ~23 grass 0  
fill ~1 ~-1 ~24 ~16 ~-1 ~24 grass 0  
fill ~1 ~-1 ~25 ~16 ~-1 ~25 grass 0  
fill ~1 ~-1 ~26 ~16 ~-1 ~26 grass 0  
fill ~1 ~-1 ~27 ~16 ~-1 ~27 grass 0  
fill ~1 ~-1 ~28 ~16 ~-1 ~28 grass 0  
fill ~1 ~-1 ~29 ~15 ~-1 ~29 grass 0  
fill ~1 ~-1 ~30 ~3 ~-1 ~30 grass 0  
fill ~1 ~-1 ~31 ~1 ~-1 ~31 grass 0  
fill ~1 ~-1 ~32 ~1 ~-1 ~32 grass 0  
fill ~1 ~-1 ~33 ~2 ~-1 ~33 dirt 0  
fill ~1 ~-1 ~34 ~1 ~-1 ~52 dirt 0  
fill ~1 ~-1 ~53 ~1 ~-1 ~53 grass 0  
fill ~1 ~-1 ~54 ~1 ~-1 ~54 grass 0  
fill ~1 ~-1 ~55 ~3 ~-1 ~55 grass 0  
fill ~1 ~-1 ~56 ~15 ~-1 ~56 grass 0  
fill ~1 ~-1 ~57 ~16 ~-1 ~57 grass 0  
fill ~1 ~-1 ~58 ~16 ~-1 ~58 grass 0  
fill ~1 ~-1 ~59 ~16 ~-1 ~59 grass 0  
fill ~1 ~-1 ~60 ~16 ~-1 ~60 grass 0  
fill ~1 ~-1 ~61 ~16 ~-1 ~61 grass 0  
fill ~1 ~-1 ~62 ~16 ~-1 ~62 grass 0  
fill ~1 ~-1 ~63 ~16 ~-1 ~63 grass 0  
fill ~1 ~-1 ~64 ~16 ~-1 ~64 grass 0  
fill ~1 ~-1 ~65 ~16 ~-1 ~65 grass 0  
fill ~1 ~-1 ~66 ~16 ~-1 ~66 grass 0  
fill ~1 ~-1 ~67 ~16 ~-1 ~67 grass 0  
fill ~1 ~-1 ~68 ~17 ~-1 ~68 grass 0  
fill ~1 ~-1 ~69 ~17 ~-1 ~69 grass 0  
fill ~1 ~-1 ~70 ~17 ~-1 ~70 grass 0  
fill ~1 ~-1 ~71 ~18 ~-1 ~71 grass 0  
fill ~1 ~-1 ~72 ~18 ~-1 ~72 grass 0  
fill ~1 ~-1 ~73 ~19 ~-1 ~73 grass 0  
fill ~1 ~-1 ~74 ~20 ~-1 ~74 grass 0  
fill ~1 ~-1 ~75 ~22 ~-1 ~75 grass 0  
fill ~1 ~-1 ~76 ~25 ~-1 ~76 grass 0  
fill ~1 ~-1 ~77 ~35 ~-1 ~77 grass 0  
fill ~2 ~-1 ~31 ~4 ~-1 ~31 dirt 0  
fill ~2 ~-1 ~32 ~2 ~-1 ~31 dirt 0  
fill ~2 ~-1 ~34 ~3 ~-1 ~34 gold_block 0  
fill ~2 ~-1 ~35 ~10 ~-1 ~35 log 0  
fill ~2 ~-1 ~36 ~9 ~-1 ~36 wool 14  
fill ~2 ~-1 ~37 ~9 ~-1 ~37 wool 14  
fill ~2 ~-1 ~38 ~6 ~-1 ~38 gold_block 0  
fill ~2 ~-1 ~39 ~3 ~-1 ~39 wool 13  
fill ~2 ~-1 ~40 ~2 ~-1 ~42 wool 13  
fill ~2 ~-1 ~43 ~3 ~-1 ~43 gold_block 0 
setblock ~2 ~-1 ~45 gold_block 0  
fill ~2 ~-1 ~46 ~4 ~-1 ~46 wool 13 
setblock ~2 ~-1 ~47 wool 11  
fill ~2 ~-1 ~48 ~9 ~-1 ~48 wool 14  
fill ~2 ~-1 ~49 ~9 ~-1 ~49 wool 14  
fill ~2 ~-1 ~50 ~10 ~-1 ~50 log 0  
fill ~2 ~-1 ~51 ~3 ~-1 ~51 gold_block 0  
fill ~2 ~-1 ~52 ~2 ~-1 ~54 dirt 0  
fill ~3 ~-1 ~32 ~5 ~-1 ~32 gold_block 0  
fill ~3 ~-1 ~33 ~3 ~-1 ~32 gold_block 0  
fill ~3 ~-1 ~40 ~4 ~-1 ~40 gold_block 0  
fill ~3 ~-1 ~41 ~3 ~-1 ~40 gold_block 0  
fill ~3 ~-1 ~42 ~4 ~-1 ~42 wool 13  
fill ~3 ~-1 ~44 ~4 ~-1 ~44 wool 13  
fill ~3 ~-1 ~45 ~3 ~-1 ~44 wool 13  
fill ~3 ~-1 ~47 ~5 ~-1 ~47 gold_block 0  
fill ~3 ~-1 ~52 ~3 ~-1 ~53 gold_block 0  
fill ~3 ~-1 ~54 ~4 ~-1 ~54 dirt 0  
fill ~4 ~-1 ~30 ~16 ~-1 ~30 dirt 0 
setblock ~4 ~-1 ~39 gold_block 0  
fill ~4 ~-1 ~41 ~5 ~-1 ~41 wool 13  
fill ~4 ~-1 ~43 ~6 ~-1 ~43 wool 13  
fill ~4 ~-1 ~45 ~5 ~-1 ~45 gold_block 0  
fill ~4 ~-1 ~53 ~5 ~-1 ~53 gold_block 0  
fill ~4 ~-1 ~55 ~16 ~-1 ~55 dirt 0  
fill ~5 ~-1 ~31 ~9 ~-1 ~31 gold_block 0  
fill ~5 ~-1 ~39 ~5 ~-1 ~41 wool 13  
fill ~5 ~-1 ~42 ~7 ~-1 ~42 gold_block 0 
setblock ~5 ~-1 ~44 gold_block 0 
setblock ~5 ~-1 ~46 gold_block 0  
fill ~5 ~-1 ~54 ~9 ~-1 ~54 gold_block 0  
fill ~6 ~-1 ~39 ~6 ~-1 ~42 gold_block 0  
fill ~6 ~-1 ~44 ~6 ~-1 ~46 wool 13  
fill ~6 ~-1 ~47 ~7 ~-1 ~47 wool 11  
fill ~7 ~-1 ~38 ~7 ~-1 ~41 wool 11  
fill ~7 ~-1 ~43 ~7 ~0 ~43 gold_block 0  
fill ~7 ~-1 ~44 ~7 ~0 ~44 gold_block 0  
fill ~7 ~-1 ~45 ~7 ~0 ~45 gold_block 0  
fill ~7 ~-1 ~46 ~7 ~0 ~46 gold_block 0  
fill ~8 ~-1 ~38 ~9 ~-1 ~38 wool 14  
fill ~8 ~-1 ~39 ~9 ~-1 ~39 wool 14  
fill ~8 ~-1 ~40 ~9 ~-1 ~40 wool 14  
fill ~8 ~-1 ~41 ~32 ~-1 ~41 wool 14  
fill ~8 ~-1 ~42 ~32 ~-1 ~42 wool 14  
fill ~8 ~-1 ~43 ~32 ~-1 ~43 wool 14  
fill ~8 ~-1 ~44 ~32 ~-1 ~44 wool 14  
fill ~8 ~-1 ~45 ~9 ~-1 ~45 wool 14  
fill ~8 ~-1 ~46 ~9 ~-1 ~46 wool 14  
fill ~8 ~-1 ~47 ~9 ~-1 ~47 wool 14  
fill ~10 ~-1 ~31 ~10 ~-1 ~40 log 0  
fill ~10 ~-1 ~45 ~19 ~-1 ~45 log 0  
fill ~10 ~-1 ~46 ~10 ~-1 ~54 log 0  
fill ~11 ~-1 ~31 ~16 ~-1 ~31 glowstone 0  
fill ~11 ~-1 ~32 ~11 ~-1 ~39 glowstone 0  
fill ~11 ~-1 ~40 ~19 ~-1 ~40 log 0  
fill ~11 ~-1 ~46 ~19 ~-1 ~46 glowstone 0  
fill ~11 ~-1 ~47 ~11 ~-1 ~54 glowstone 0  
fill ~12 ~-1 ~32 ~12 ~-1 ~34 gold_block 0  
fill ~12 ~-1 ~35 ~13 ~-1 ~35 wool 11  
fill ~12 ~-1 ~36 ~14 ~-1 ~36 gold_block 0  
fill ~12 ~-1 ~37 ~13 ~-1 ~37 wool 11 
setblock ~12 ~-1 ~38 gold_block 0  
fill ~12 ~-1 ~39 ~19 ~-1 ~39 glowstone 0  
fill ~12 ~-1 ~47 ~17 ~-1 ~47 wool 11  
fill ~12 ~-1 ~48 ~18 ~-1 ~48 gold_block 0  
fill ~12 ~-1 ~49 ~15 ~-1 ~49 wool 11  
fill ~12 ~-1 ~50 ~12 ~-1 ~49 wool 11  
fill ~12 ~-1 ~51 ~13 ~-1 ~51 gold_block 0  
fill ~12 ~-1 ~52 ~12 ~-1 ~53 gold_block 0  
fill ~12 ~-1 ~54 ~16 ~-1 ~54 glowstone 0  
fill ~13 ~-1 ~32 ~16 ~-1 ~32 wool 11  
fill ~13 ~-1 ~33 ~21 ~-1 ~33 gold_block 0  
fill ~13 ~-1 ~34 ~16 ~-1 ~34 wool 11  
fill ~13 ~-1 ~38 ~15 ~-1 ~38 wool 11 
setblock ~13 ~-1 ~50 gold_block 0  
fill ~13 ~-1 ~52 ~15 ~-1 ~52 wool 11 
setblock ~13 ~-1 ~53 gold_block 0  
fill ~14 ~-1 ~35 ~15 ~-1 ~35 gold_block 0  
fill ~14 ~-1 ~37 ~16 ~-1 ~37 gold_block 0  
fill ~14 ~-1 ~50 ~14 ~-1 ~53 wool 11  
fill ~15 ~-1 ~36 ~17 ~-1 ~36 wool 11  
fill ~15 ~-1 ~50 ~16 ~-1 ~50 gold_block 0  
fill ~15 ~-1 ~51 ~16 ~-1 ~51 wool 11 
setblock ~15 ~-1 ~53 gold_block 0  
fill ~16 ~-1 ~29 ~17 ~-1 ~29 dirt 0  
fill ~16 ~-1 ~35 ~18 ~-1 ~35 wool 11  
fill ~16 ~-1 ~38 ~17 ~-1 ~38 gold_block 0 
setblock ~16 ~-1 ~49 gold_block 0 
setblock ~16 ~-1 ~52 gold_block 0  
fill ~16 ~-1 ~53 ~17 ~-1 ~53 wool 11  
fill ~16 ~-1 ~56 ~17 ~-1 ~56 dirt 0  
fill ~17 ~-1 ~2 ~17 ~-1 ~29 dirt 0 
setblock ~17 ~-1 ~30 glowstone 0  
fill ~17 ~-1 ~31 ~17 ~-1 ~34 gold_block 0  
fill ~17 ~-1 ~37 ~18 ~-1 ~37 wool 11  
fill ~17 ~-1 ~49 ~17 ~-1 ~50 wool 11 
setblock ~17 ~-1 ~51 gold_block 0 
setblock ~17 ~-1 ~52 wool 11  
fill ~17 ~-1 ~54 ~18 ~-1 ~54 gold_block 0 
setblock ~17 ~-1 ~55 glowstone 0  
fill ~17 ~-1 ~57 ~17 ~-1 ~67 dirt 0  
fill ~18 ~-1 ~1 ~53 ~-1 ~1 dirt 0  
fill ~18 ~-1 ~2 ~18 ~0 ~2 gold_block 0  
fill ~18 ~-1 ~3 ~18 ~-1 ~29 glowstone 0  
fill ~18 ~-1 ~30 ~19 ~-1 ~30 gold_block 0  
fill ~18 ~-1 ~31 ~18 ~-1 ~32 wool 11  
fill ~18 ~-1 ~34 ~19 ~-1 ~34 wool 11  
fill ~18 ~-1 ~36 ~19 ~-1 ~36 gold_block 0  
fill ~18 ~-1 ~38 ~23 ~-1 ~38 wool 11  
fill ~18 ~-1 ~47 ~20 ~-1 ~47 gold_block 0  
fill ~18 ~-1 ~49 ~19 ~-1 ~49 gold_block 0  
fill ~18 ~-1 ~50 ~18 ~-1 ~51 wool 11  
fill ~18 ~-1 ~52 ~19 ~-1 ~52 gold_block 0  
fill ~18 ~-1 ~53 ~18 ~-1 ~52 gold_block 0  
fill ~18 ~-1 ~55 ~20 ~-1 ~55 wool 11  
fill ~18 ~-1 ~56 ~18 ~-1 ~66 glowstone 0  
fill ~18 ~-1 ~67 ~18 ~-1 ~70 dirt 0  
fill ~19 ~-1 ~2 ~30 ~-1 ~2 glowstone 0 
setblock ~19 ~-1 ~3 wool 11  
fill ~19 ~-1 ~4 ~22 ~-1 ~4 gold_block 0  
fill ~19 ~-1 ~5 ~19 ~-1 ~7 wool 11  
fill ~19 ~-1 ~8 ~21 ~-1 ~8 gold_block 0  
fill ~19 ~-1 ~9 ~20 ~-1 ~9 wool 11  
fill ~19 ~-1 ~10 ~20 ~-1 ~10 gold_block 0  
fill ~19 ~-1 ~11 ~19 ~-1 ~12 wool 11  
fill ~19 ~-1 ~13 ~21 ~-1 ~13 gold_block 0  
fill ~19 ~-1 ~14 ~21 ~-1 ~14 wool 11  
fill ~19 ~-1 ~15 ~21 ~-1 ~15 gold_block 0 
setblock ~19 ~-1 ~16 wool 11  
fill ~19 ~-1 ~17 ~23 ~-1 ~17 gold_block 0  
fill ~19 ~-1 ~18 ~19 ~0 ~18 gold_block 0  
fill ~19 ~-1 ~19 ~19 ~0 ~19 gold_block 0  
fill ~19 ~-1 ~20 ~19 ~0 ~20 gold_block 0  
fill ~19 ~-1 ~21 ~22 ~-1 ~21 wool 11  
fill ~19 ~-1 ~22 ~21 ~-1 ~22 gold_block 0  
fill ~19 ~-1 ~23 ~24 ~-1 ~23 wool 11  
fill ~19 ~-1 ~24 ~20 ~-1 ~24 gold_block 0  
fill ~19 ~-1 ~25 ~19 ~-1 ~27 wool 11  
fill ~19 ~-1 ~28 ~22 ~-1 ~28 gold_block 0  
fill ~19 ~-1 ~29 ~20 ~-1 ~29 wool 11 
setblock ~19 ~-1 ~31 gold_block 0  
fill ~19 ~-1 ~32 ~21 ~-1 ~32 wool 11  
fill ~19 ~-1 ~35 ~22 ~-1 ~35 gold_block 0  
fill ~19 ~-1 ~37 ~20 ~-1 ~37 gold_block 0  
fill ~19 ~-1 ~48 ~22 ~-1 ~48 wool 11  
fill ~19 ~-1 ~50 ~21 ~-1 ~50 gold_block 0  
fill ~19 ~-1 ~51 ~20 ~-1 ~51 wool 11  
fill ~19 ~-1 ~53 ~20 ~-1 ~53 wool 11  
fill ~19 ~-1 ~54 ~19 ~-1 ~53 wool 11 
setblock ~19 ~-1 ~56 gold_block 0  
fill ~19 ~-1 ~57 ~21 ~-1 ~57 wool 11  
fill ~19 ~-1 ~58 ~19 ~-1 ~57 wool 11  
fill ~19 ~-1 ~59 ~20 ~-1 ~59 gold_block 0  
fill ~19 ~-1 ~60 ~22 ~-1 ~60 wool 11  
fill ~19 ~-1 ~61 ~19 ~-1 ~62 wool 11  
fill ~19 ~-1 ~63 ~19 ~-1 ~64 gold_block 0  
fill ~19 ~-1 ~65 ~19 ~-1 ~66 wool 11  
fill ~19 ~-1 ~67 ~19 ~-1 ~69 glowstone 0 
setblock ~19 ~-1 ~70 dirt 0 
setblock ~19 ~-1 ~71 stone 0  
fill ~19 ~-1 ~72 ~20 ~-1 ~72 dirt 0  
fill ~20 ~-1 ~3 ~20 ~0 ~3 gold_block 0  
fill ~20 ~-1 ~5 ~20 ~-1 ~6 gold_block 0  
fill ~20 ~-1 ~7 ~22 ~-1 ~7 wool 11  
fill ~20 ~-1 ~11 ~22 ~-1 ~11 gold_block 0  
fill ~20 ~-1 ~12 ~20 ~-1 ~10 gold_block 0 
setblock ~20 ~-1 ~16 gold_block 0  
fill ~20 ~-1 ~18 ~21 ~-1 ~18 wool 11  
fill ~20 ~-1 ~19 ~20 ~-1 ~21 wool 11  
fill ~20 ~-1 ~25 ~20 ~-1 ~26 gold_block 0  
fill ~20 ~-1 ~27 ~21 ~-1 ~27 wool 11  
fill ~20 ~-1 ~30 ~21 ~-1 ~30 wool 11  
fill ~20 ~-1 ~31 ~20 ~-1 ~29 wool 11 
setblock ~20 ~-1 ~34 gold_block 0  
fill ~20 ~-1 ~36 ~21 ~-1 ~36 wool 11 
setblock ~20 ~-1 ~39 wool 11  
fill ~20 ~-1 ~40 ~21 ~-1 ~40 gold_block 0  
fill ~20 ~-1 ~45 ~21 ~-1 ~45 gold_block 0  
fill ~20 ~-1 ~46 ~20 ~-1 ~45 gold_block 0 
setblock ~20 ~-1 ~49 wool 11  
fill ~20 ~-1 ~52 ~22 ~-1 ~52 wool 11  
fill ~20 ~-1 ~54 ~22 ~-1 ~54 gold_block 0 
setblock ~20 ~-1 ~56 wool 11 
setblock ~20 ~-1 ~58 gold_block 0  
fill ~20 ~-1 ~61 ~21 ~-1 ~61 gold_block 0  
fill ~20 ~-1 ~62 ~20 ~-1 ~63 wool 11  
fill ~20 ~-1 ~64 ~20 ~-1 ~67 gold_block 0  
fill ~20 ~-1 ~68 ~20 ~-1 ~69 wool 11  
fill ~20 ~-1 ~70 ~20 ~-1 ~71 glowstone 0  
fill ~20 ~-1 ~73 ~21 ~-1 ~73 dirt 0 
setblock ~21 ~-1 ~3 wool 11  
fill ~21 ~-1 ~5 ~23 ~-1 ~5 wool 11  
fill ~21 ~-1 ~6 ~21 ~-1 ~5 wool 11  
fill ~21 ~-1 ~9 ~22 ~-1 ~9 gold_block 0  
fill ~21 ~-1 ~10 ~23 ~-1 ~10 wool 11 
setblock ~21 ~-1 ~12 wool 11  
fill ~21 ~-1 ~16 ~22 ~-1 ~16 wool 11  
fill ~21 ~-1 ~19 ~22 ~-1 ~19 gold_block 0  
fill ~21 ~-1 ~20 ~21 ~-1 ~19 gold_block 0  
fill ~21 ~-1 ~24 ~22 ~-1 ~24 wool 11  
fill ~21 ~-1 ~25 ~22 ~-1 ~25 wool 11  
fill ~21 ~-1 ~26 ~23 ~-1 ~26 gold_block 0  
fill ~21 ~-1 ~29 ~22 ~-1 ~29 gold_block 0  
fill ~21 ~-1 ~31 ~22 ~-1 ~31 gold_block 0  
fill ~21 ~-1 ~34 ~22 ~-1 ~34 wool 11 
setblock ~21 ~-1 ~37 wool 11 
setblock ~21 ~-1 ~39 gold_block 0  
fill ~21 ~-1 ~46 ~21 ~-1 ~48 wool 11  
fill ~21 ~-1 ~49 ~23 ~-1 ~49 gold_block 0 
setblock ~21 ~-1 ~51 gold_block 0  
fill ~21 ~-1 ~53 ~23 ~-1 ~53 gold_block 0  
fill ~21 ~-1 ~55 ~22 ~-1 ~55 gold_block 0  
fill ~21 ~-1 ~56 ~22 ~-1 ~56 gold_block 0  
fill ~21 ~-1 ~58 ~21 ~-1 ~60 wool 11 
setblock ~21 ~-1 ~62 gold_block 0  
fill ~21 ~-1 ~63 ~21 ~-1 ~64 wool 11  
fill ~21 ~-1 ~65 ~22 ~-1 ~65 gold_block 0 
setblock ~21 ~-1 ~66 wool 11  
fill ~21 ~-1 ~67 ~21 ~-1 ~68 gold_block 0  
fill ~21 ~-1 ~69 ~22 ~-1 ~69 wool 11  
fill ~21 ~-1 ~70 ~21 ~-1 ~71 wool 11 
setblock ~21 ~-1 ~72 glowstone 0  
fill ~21 ~-1 ~74 ~23 ~-1 ~74 dirt 0  
fill ~22 ~-1 ~3 ~24 ~-1 ~3 gold_block 0  
fill ~22 ~-1 ~6 ~23 ~-1 ~6 gold_block 0  
fill ~22 ~-1 ~8 ~23 ~-1 ~8 wool 11  
fill ~22 ~-1 ~12 ~24 ~-1 ~12 gold_block 0 
setblock ~22 ~-1 ~13 wool 11  
fill ~22 ~-1 ~14 ~22 ~0 ~14 gold_block 0  
fill ~22 ~-1 ~15 ~25 ~-1 ~15 wool 11  
fill ~22 ~-1 ~18 ~22 ~0 ~18 gold_block 0 
setblock ~22 ~-1 ~20 wool 11 
setblock ~22 ~-1 ~22 wool 11 
setblock ~22 ~-1 ~27 gold_block 0 
setblock ~22 ~-1 ~30 gold_block 0  
fill ~22 ~-1 ~32 ~23 ~-1 ~32 gold_block 0 
setblock ~22 ~-1 ~33 wool 11  
fill ~22 ~-1 ~36 ~26 ~-1 ~36 gold_block 0  
fill ~22 ~-1 ~37 ~22 ~-1 ~35 gold_block 0  
fill ~22 ~-1 ~39 ~29 ~-1 ~39 glowstone 0  
fill ~22 ~-1 ~40 ~30 ~-1 ~40 log 0  
fill ~22 ~-1 ~45 ~30 ~-1 ~45 log 0  
fill ~22 ~-1 ~46 ~29 ~-1 ~46 glowstone 0  
fill ~22 ~-1 ~47 ~24 ~-1 ~47 gold_block 0  
fill ~22 ~-1 ~50 ~24 ~-1 ~50 wool 11  
fill ~22 ~-1 ~51 ~22 ~-1 ~50 wool 11  
fill ~22 ~-1 ~57 ~22 ~-1 ~59 gold_block 0  
fill ~22 ~-1 ~61 ~22 ~-1 ~62 wool 11  
fill ~22 ~-1 ~63 ~24 ~-1 ~63 gold_block 0  
fill ~22 ~-1 ~64 ~23 ~-1 ~64 wool 11 
setblock ~22 ~-1 ~66 gold_block 0  
fill ~22 ~-1 ~67 ~23 ~-1 ~67 wool 11  
fill ~22 ~-1 ~68 ~22 ~-1 ~67 wool 11  
fill ~22 ~-1 ~70 ~26 ~-1 ~70 gold_block 0 
setblock ~22 ~-1 ~71 wool 11  
fill ~22 ~-1 ~72 ~23 ~-1 ~72 gold_block 0  
fill ~22 ~-1 ~73 ~23 ~-1 ~73 glowstone 0 
setblock ~23 ~-1 ~4 wool 11  
fill ~23 ~-1 ~7 ~26 ~-1 ~7 gold_block 0 
setblock ~23 ~-1 ~9 wool 11 
setblock ~23 ~-1 ~11 wool 11 
setblock ~23 ~-1 ~13 gold_block 0 
setblock ~23 ~-1 ~14 wool 11 
setblock ~23 ~-1 ~16 gold_block 0  
fill ~23 ~-1 ~18 ~24 ~-1 ~18 wool 11  
fill ~23 ~-1 ~19 ~23 ~-1 ~18 wool 11  
fill ~23 ~-1 ~20 ~24 ~-1 ~20 gold_block 0  
fill ~23 ~-1 ~21 ~23 ~0 ~21 gold_block 0  
fill ~23 ~-1 ~22 ~24 ~-1 ~22 gold_block 0  
fill ~23 ~-1 ~24 ~29 ~-1 ~24 gold_block 0  
fill ~23 ~-1 ~25 ~24 ~-1 ~25 gold_block 0  
fill ~23 ~-1 ~27 ~24 ~-1 ~27 wool 14  
fill ~23 ~-1 ~28 ~23 ~-1 ~31 wool 14  
fill ~23 ~-1 ~33 ~24 ~-1 ~33 gold_block 0  
fill ~23 ~-1 ~34 ~23 ~-1 ~32 gold_block 0  
fill ~23 ~-1 ~35 ~24 ~-1 ~35 wool 11  
fill ~23 ~-1 ~37 ~25 ~-1 ~37 wool 11 
setblock ~23 ~-1 ~48 gold_block 0  
fill ~23 ~-1 ~51 ~29 ~-1 ~51 gold_block 0  
fill ~23 ~-1 ~52 ~24 ~-1 ~52 gold_block 0  
fill ~23 ~-1 ~54 ~24 ~-1 ~54 wool 14  
fill ~23 ~-1 ~55 ~23 ~-1 ~58 wool 14  
fill ~23 ~-1 ~59 ~23 ~-1 ~63 gold_block 0  
fill ~23 ~-1 ~65 ~23 ~-1 ~67 wool 11  
fill ~23 ~-1 ~68 ~24 ~-1 ~68 gold_block 0  
fill ~23 ~-1 ~69 ~23 ~0 ~69 gold_block 0  
fill ~23 ~-1 ~71 ~23 ~0 ~71 gold_block 0  
fill ~23 ~-1 ~75 ~26 ~-1 ~75 dirt 0  
fill ~24 ~-1 ~4 ~26 ~-1 ~4 gold_block 0  
fill ~24 ~-1 ~5 ~24 ~-1 ~3 gold_block 0 
setblock ~24 ~-1 ~6 wool 11  
fill ~24 ~-1 ~8 ~24 ~-1 ~12 gold_block 0 
setblock ~24 ~-1 ~13 wool 11  
fill ~24 ~-1 ~14 ~25 ~-1 ~14 gold_block 0  
fill ~24 ~-1 ~16 ~24 ~-1 ~18 wool 11  
fill ~24 ~-1 ~19 ~24 ~0 ~19 gold_block 0 
setblock ~24 ~-1 ~21 wool 11  
fill ~24 ~-1 ~26 ~25 ~-1 ~26 wool 14  
fill ~24 ~-1 ~28 ~24 ~0 ~28 gold_block 0  
fill ~24 ~-1 ~29 ~28 ~-1 ~29 gold_block 0  
fill ~24 ~-1 ~30 ~24 ~0 ~30 gold_block 0  
fill ~24 ~-1 ~31 ~24 ~-1 ~32 wool 14 
setblock ~24 ~-1 ~34 wool 11 
setblock ~24 ~-1 ~38 gold_block 0  
fill ~24 ~-1 ~48 ~25 ~-1 ~48 wool 11  
fill ~24 ~-1 ~49 ~24 ~-1 ~48 wool 11  
fill ~24 ~-1 ~53 ~25 ~-1 ~53 wool 14  
fill ~24 ~-1 ~55 ~24 ~0 ~55 gold_block 0  
fill ~24 ~-1 ~56 ~28 ~-1 ~56 gold_block 0  
fill ~24 ~-1 ~57 ~24 ~0 ~57 gold_block 0  
fill ~24 ~-1 ~58 ~24 ~-1 ~59 wool 14 
setblock ~24 ~-1 ~60 gold_block 0  
fill ~24 ~-1 ~61 ~24 ~-1 ~62 wool 11  
fill ~24 ~-1 ~64 ~24 ~-1 ~65 gold_block 0  
fill ~24 ~-1 ~66 ~25 ~-1 ~66 wool 11  
fill ~24 ~-1 ~67 ~25 ~-1 ~67 gold_block 0  
fill ~24 ~-1 ~69 ~25 ~-1 ~69 wool 11  
fill ~24 ~-1 ~71 ~24 ~-1 ~72 wool 11 
setblock ~24 ~-1 ~73 gold_block 0  
fill ~24 ~-1 ~74 ~26 ~-1 ~74 glass 0 
setblock ~25 ~-1 ~3 wool 11  
fill ~25 ~-1 ~5 ~27 ~-1 ~5 wool 11  
fill ~25 ~-1 ~6 ~28 ~-1 ~6 gold_block 0 
setblock ~25 ~-1 ~8 wool 11 
setblock ~25 ~-1 ~9 gold_block 0  
fill ~25 ~-1 ~10 ~26 ~-1 ~10 wool 11  
fill ~25 ~-1 ~11 ~25 ~0 ~11 gold_block 0  
fill ~25 ~-1 ~12 ~28 ~-1 ~12 wool 11  
fill ~25 ~-1 ~13 ~27 ~-1 ~13 gold_block 0  
fill ~25 ~-1 ~16 ~26 ~-1 ~16 gold_block 0  
fill ~25 ~-1 ~17 ~25 ~-1 ~18 gold_block 0  
fill ~25 ~-1 ~19 ~27 ~-1 ~19 wool 11  
fill ~25 ~-1 ~20 ~25 ~-1 ~19 wool 11  
fill ~25 ~-1 ~21 ~26 ~-1 ~21 gold_block 0 
setblock ~25 ~-1 ~22 wool 11 
setblock ~25 ~-1 ~23 gold_block 0  
fill ~25 ~-1 ~25 ~29 ~-1 ~25 wool 14  
fill ~25 ~-1 ~27 ~25 ~0 ~27 gold_block 0  
fill ~25 ~-1 ~28 ~26 ~-1 ~28 wool 11  
fill ~25 ~-1 ~30 ~25 ~-1 ~31 wool 11  
fill ~25 ~-1 ~32 ~25 ~-1 ~33 wool 14  
fill ~25 ~-1 ~34 ~31 ~-1 ~34 gold_block 0  
fill ~25 ~-1 ~35 ~25 ~-1 ~34 gold_block 0  
fill ~25 ~-1 ~38 ~27 ~-1 ~38 wool 11 
setblock ~25 ~-1 ~47 wool 11  
fill ~25 ~-1 ~49 ~27 ~-1 ~49 gold_block 0  
fill ~25 ~-1 ~50 ~25 ~-1 ~49 gold_block 0  
fill ~25 ~-1 ~52 ~29 ~-1 ~52 wool 14  
fill ~25 ~-1 ~54 ~25 ~0 ~54 gold_block 0  
fill ~25 ~-1 ~55 ~26 ~-1 ~55 wool 11  
fill ~25 ~-1 ~57 ~25 ~-1 ~58 wool 11  
fill ~25 ~-1 ~59 ~25 ~-1 ~60 wool 14  
fill ~25 ~-1 ~61 ~31 ~-1 ~61 gold_block 0  
fill ~25 ~-1 ~62 ~27 ~-1 ~62 wool 11  
fill ~25 ~-1 ~63 ~25 ~-1 ~66 wool 11  
fill ~25 ~-1 ~68 ~26 ~-1 ~68 wool 11  
fill ~25 ~-1 ~71 ~25 ~0 ~71 gold_block 0  
fill ~25 ~-1 ~72 ~26 ~-1 ~72 wool 11  
fill ~25 ~-1 ~73 ~25 ~-1 ~72 wool 11  
fill ~26 ~-1 ~3 ~26 ~0 ~3 gold_block 0 
setblock ~26 ~-1 ~8 gold_block 0 
setblock ~26 ~-1 ~9 wool 11 
setblock ~26 ~-1 ~11 wool 11  
fill ~26 ~-1 ~14 ~27 ~-1 ~14 wool 11  
fill ~26 ~-1 ~15 ~28 ~-1 ~15 gold_block 0 
setblock ~26 ~-1 ~17 wool 11  
fill ~26 ~-1 ~18 ~27 ~-1 ~18 gold_block 0 
setblock ~26 ~-1 ~20 gold_block 0  
fill ~26 ~-1 ~22 ~28 ~-1 ~22 gold_block 0  
fill ~26 ~-1 ~23 ~28 ~-1 ~23 wool 11  
fill ~26 ~-1 ~26 ~26 ~-1 ~28 wool 11 
setblock ~26 ~-1 ~30 gold_block 0  
fill ~26 ~-1 ~31 ~26 ~-1 ~32 wool 11  
fill ~26 ~-1 ~33 ~29 ~-1 ~33 wool 14  
fill ~26 ~-1 ~35 ~27 ~-1 ~35 wool 11  
fill ~26 ~-1 ~37 ~28 ~-1 ~37 gold_block 0  
fill ~26 ~-1 ~47 ~26 ~-1 ~49 gold_block 0  
fill ~26 ~-1 ~50 ~27 ~-1 ~50 wool 11  
fill ~26 ~-1 ~53 ~26 ~-1 ~55 wool 11 
setblock ~26 ~-1 ~57 gold_block 0  
fill ~26 ~-1 ~58 ~26 ~-1 ~59 wool 11  
fill ~26 ~-1 ~60 ~29 ~-1 ~60 wool 14  
fill ~26 ~-1 ~63 ~33 ~-1 ~63 gold_block 0  
fill ~26 ~-1 ~64 ~26 ~0 ~64 gold_block 0  
fill ~26 ~-1 ~65 ~26 ~0 ~65 gold_block 0  
fill ~26 ~-1 ~66 ~26 ~-1 ~63 gold_block 0 
setblock ~26 ~-1 ~67 wool 11  
fill ~26 ~-1 ~69 ~26 ~0 ~69 gold_block 0  
fill ~26 ~-1 ~71 ~28 ~-1 ~71 wool 11  
fill ~26 ~-1 ~73 ~27 ~-1 ~73 gold_block 0  
fill ~26 ~-1 ~76 ~36 ~-1 ~76 dirt 0  
fill ~27 ~-1 ~3 ~28 ~-1 ~3 wool 11  
fill ~27 ~-1 ~4 ~27 ~-1 ~3 wool 11  
fill ~27 ~-1 ~7 ~29 ~-1 ~7 wool 11  
fill ~27 ~-1 ~8 ~27 ~-1 ~7 wool 11  
fill ~27 ~-1 ~9 ~27 ~0 ~9 gold_block 0  
fill ~27 ~-1 ~10 ~28 ~-1 ~10 gold_block 0  
fill ~27 ~-1 ~11 ~27 ~0 ~11 gold_block 0  
fill ~27 ~-1 ~16 ~28 ~-1 ~16 wool 11  
fill ~27 ~-1 ~17 ~28 ~-1 ~17 gold_block 0  
fill ~27 ~-1 ~20 ~27 ~-1 ~21 wool 11  
fill ~27 ~-1 ~26 ~27 ~0 ~26 gold_block 0  
fill ~27 ~-1 ~27 ~29 ~-1 ~27 wool 11 
setblock ~27 ~-1 ~28 gold_block 0 
setblock ~27 ~-1 ~30 wool 11  
fill ~27 ~-1 ~31 ~29 ~-1 ~31 gold_block 0  
fill ~27 ~-1 ~32 ~28 ~-1 ~32 wool 11 
setblock ~27 ~-1 ~36 wool 11  
fill ~27 ~-1 ~47 ~27 ~-1 ~48 wool 11  
fill ~27 ~-1 ~53 ~27 ~0 ~53 gold_block 0  
fill ~27 ~-1 ~54 ~29 ~-1 ~54 wool 11 
setblock ~27 ~-1 ~55 gold_block 0 
setblock ~27 ~-1 ~57 wool 11  
fill ~27 ~-1 ~58 ~29 ~-1 ~58 gold_block 0  
fill ~27 ~-1 ~59 ~28 ~-1 ~59 wool 11  
fill ~27 ~-1 ~64 ~31 ~-1 ~64 wool 11  
fill ~27 ~-1 ~65 ~27 ~-1 ~64 wool 11  
fill ~27 ~-1 ~66 ~28 ~-1 ~66 glowstone 0  
fill ~27 ~-1 ~67 ~28 ~-1 ~67 glowstone 0 
setblock ~27 ~-1 ~68 gold_block 0  
fill ~27 ~-1 ~69 ~29 ~-1 ~69 wool 11  
fill ~27 ~-1 ~70 ~27 ~-1 ~69 wool 11  
fill ~27 ~-1 ~72 ~31 ~-1 ~72 gold_block 0  
fill ~27 ~-1 ~74 ~28 ~-1 ~74 wool 11 
setblock ~27 ~-1 ~75 glowstone 0  
fill ~28 ~-1 ~4 ~29 ~-1 ~4 gold_block 0  
fill ~28 ~-1 ~5 ~28 ~-1 ~4 gold_block 0  
fill ~28 ~-1 ~8 ~29 ~-1 ~8 gold_block 0 
setblock ~28 ~-1 ~9 wool 11  
fill ~28 ~-1 ~11 ~30 ~-1 ~11 wool 11 
setblock ~28 ~-1 ~13 wool 11  
fill ~28 ~-1 ~14 ~29 ~-1 ~14 gold_block 0  
fill ~28 ~-1 ~18 ~29 ~-1 ~18 wool 11  
fill ~28 ~-1 ~19 ~28 ~-1 ~22 gold_block 0 
setblock ~28 ~-1 ~26 wool 11 
setblock ~28 ~-1 ~28 wool 11 
setblock ~28 ~-1 ~30 gold_block 0  
fill ~28 ~-1 ~35 ~30 ~-1 ~35 gold_block 0  
fill ~28 ~-1 ~36 ~28 ~-1 ~34 gold_block 0 
setblock ~28 ~-1 ~38 gold_block 0 
setblock ~28 ~-1 ~47 gold_block 0  
fill ~28 ~-1 ~48 ~28 ~-1 ~49 wool 11  
fill ~28 ~-1 ~50 ~30 ~-1 ~50 gold_block 0 
setblock ~28 ~-1 ~53 wool 11 
setblock ~28 ~-1 ~55 wool 11 
setblock ~28 ~-1 ~57 gold_block 0 
setblock ~28 ~-1 ~62 gold_block 0   
fill ~28 ~-1 ~65 ~30 ~-1 ~65 gold_block 0  
fill ~28 ~-1 ~68 ~29 ~-1 ~68 wool 11  
fill ~28 ~-1 ~70 ~29 ~-1 ~70 gold_block 0  
fill ~28 ~-1 ~73 ~30 ~-1 ~73 wool 11  
fill ~28 ~-1 ~75 ~34 ~-1 ~75 glass 0 
setblock ~29 ~-1 ~3 gold_block 0  
fill ~29 ~-1 ~5 ~29 ~-1 ~7 wool 11  
fill ~29 ~-1 ~9 ~30 ~-1 ~9 gold_block 0 
setblock ~29 ~-1 ~10 glowstone 0  
fill ~29 ~-1 ~12 ~31 ~-1 ~12 gold_block 0  
fill ~29 ~-1 ~13 ~29 ~-1 ~12 gold_block 0 
setblock ~29 ~-1 ~15 glowstone 0  
fill ~29 ~-1 ~16 ~30 ~-1 ~16 gold_block 0  
fill ~29 ~-1 ~17 ~31 ~-1 ~17 wool 11 
setblock ~29 ~-1 ~19 wool 11 
setblock ~29 ~-1 ~20 glowstone 0  
fill ~29 ~-1 ~21 ~29 ~-1 ~22 wool 11 
setblock ~29 ~-1 ~23 gold_block 0  
fill ~29 ~-1 ~26 ~30 ~-1 ~26 wool 14  
fill ~29 ~-1 ~28 ~30 ~-1 ~28 gold_block 0  
fill ~29 ~-1 ~29 ~29 ~-1 ~30 wool 11  
fill ~29 ~-1 ~32 ~30 ~-1 ~32 wool 14  
fill ~29 ~-1 ~36 ~29 ~-1 ~37 wool 11 
setblock ~29 ~-1 ~38 glowstone 0 
setblock ~29 ~-1 ~47 glowstone 0  
fill ~29 ~-1 ~48 ~29 ~-1 ~51 gold_block 0  
fill ~29 ~-1 ~53 ~30 ~-1 ~53 wool 14  
fill ~29 ~-1 ~55 ~30 ~-1 ~55 gold_block 0  
fill ~29 ~-1 ~56 ~29 ~-1 ~57 wool 11  
fill ~29 ~-1 ~59 ~30 ~-1 ~59 wool 14  
fill ~29 ~-1 ~62 ~32 ~-1 ~62 wool 11  
fill ~29 ~-1 ~66 ~29 ~-1 ~67 gold_block 0  
fill ~29 ~-1 ~71 ~29 ~0 ~71 gold_block 0 
setblock ~29 ~-1 ~74 gold_block 0  
fill ~30 ~-1 ~3 ~30 ~-1 ~5 glowstone 0  
fill ~30 ~-1 ~6 ~30 ~-1 ~7 gold_block 0 
setblock ~30 ~-1 ~8 wool 11  
fill ~30 ~-1 ~10 ~32 ~-1 ~10 wool 11  
fill ~30 ~-1 ~13 ~30 ~-1 ~14 wool 11  
fill ~30 ~-1 ~15 ~31 ~-1 ~15 gold_block 0  
fill ~30 ~-1 ~18 ~32 ~-1 ~18 gold_block 0  
fill ~30 ~-1 ~19 ~30 ~-1 ~22 gold_block 0  
fill ~30 ~-1 ~23 ~30 ~-1 ~24 wool 11 
setblock ~30 ~-1 ~25 gold_block 0  
fill ~30 ~-1 ~27 ~31 ~-1 ~27 wool 14  
fill ~30 ~-1 ~29 ~30 ~0 ~29 gold_block 0  
fill ~30 ~-1 ~30 ~30 ~0 ~30 gold_block 0  
fill ~30 ~-1 ~31 ~31 ~-1 ~31 wool 14 
setblock ~30 ~-1 ~33 gold_block 0  
fill ~30 ~-1 ~36 ~30 ~-1 ~37 glowstone 0  
fill ~30 ~-1 ~38 ~30 ~-1 ~40 log 0  
fill ~30 ~-1 ~46 ~30 ~-1 ~47 log 0  
fill ~30 ~-1 ~48 ~30 ~-1 ~49 glowstone 0 
setblock ~30 ~-1 ~52 gold_block 0  
fill ~30 ~-1 ~54 ~31 ~-1 ~54 wool 14  
fill ~30 ~-1 ~56 ~30 ~0 ~56 gold_block 0  
fill ~30 ~-1 ~57 ~30 ~0 ~57 gold_block 0  
fill ~30 ~-1 ~58 ~31 ~-1 ~58 wool 14 
setblock ~30 ~-1 ~60 gold_block 0  
fill ~30 ~-1 ~66 ~31 ~-1 ~66 wool 11  
fill ~30 ~-1 ~67 ~30 ~-1 ~69 gold_block 0  
fill ~30 ~-1 ~70 ~32 ~-1 ~70 wool 11  
fill ~30 ~-1 ~71 ~30 ~-1 ~70 wool 11  
fill ~30 ~-1 ~74 ~32 ~-1 ~74 wool 11  
fill ~31 ~-1 ~2 ~31 ~-1 ~5 log 0 
setblock ~31 ~-1 ~6 glowstone 0 
setblock ~31 ~-1 ~11 gold_block 0  
fill ~31 ~-1 ~13 ~33 ~-1 ~13 gold_block 0  
fill ~31 ~-1 ~14 ~31 ~-1 ~11 gold_block 0  
fill ~31 ~-1 ~16 ~32 ~-1 ~16 wool 11  
fill ~31 ~-1 ~19 ~34 ~-1 ~19 wool 11  
fill ~31 ~-1 ~20 ~31 ~-1 ~21 wool 11  
fill ~31 ~-1 ~22 ~31 ~-1 ~24 gold_block 0 
setblock ~31 ~-1 ~25 wool 11  
fill ~31 ~-1 ~26 ~34 ~-1 ~26 gold_block 0  
fill ~31 ~-1 ~28 ~31 ~-1 ~31 wool 14  
fill ~31 ~-1 ~32 ~33 ~-1 ~32 gold_block 0  
fill ~31 ~-1 ~33 ~32 ~-1 ~33 wool 11 
setblock ~31 ~-1 ~35 glowstone 0  
fill ~31 ~-1 ~36 ~31 ~-1 ~37 log 0  
fill ~31 ~-1 ~38 ~33 ~-1 ~38 wool 14  
fill ~31 ~-1 ~39 ~32 ~-1 ~39 wool 14  
fill ~31 ~-1 ~40 ~32 ~-1 ~40 wool 14  
fill ~31 ~-1 ~45 ~32 ~-1 ~45 wool 14  
fill ~31 ~-1 ~46 ~32 ~-1 ~46 wool 14  
fill ~31 ~-1 ~47 ~33 ~-1 ~47 wool 14  
fill ~31 ~-1 ~48 ~31 ~-1 ~49 log 0 
setblock ~31 ~-1 ~50 glowstone 0  
fill ~31 ~-1 ~51 ~31 ~-2 ~51 gold_block 0 
setblock ~31 ~-1 ~52 wool 11 
setblock ~31 ~-1 ~53 gold_block 0  
fill ~31 ~-1 ~55 ~31 ~-1 ~58 wool 14  
fill ~31 ~-1 ~59 ~33 ~-1 ~59 gold_block 0  
fill ~31 ~-1 ~60 ~32 ~-1 ~60 wool 11 
setblock ~31 ~-1 ~65 wool 11  
fill ~31 ~-1 ~67 ~31 ~-1 ~68 wool 11  
fill ~31 ~-1 ~69 ~33 ~-1 ~69 gold_block 0  
fill ~31 ~-1 ~71 ~31 ~0 ~71 gold_block 0 
setblock ~31 ~-1 ~73 gold_block 0  
fill ~32 ~-1 ~2 ~33 ~-1 ~2 wool 14  
fill ~32 ~-1 ~3 ~33 ~-1 ~3 wool 14  
fill ~32 ~-1 ~4 ~34 ~-1 ~4 wool 14  
fill ~32 ~-1 ~5 ~35 ~-1 ~5 wool 14 
setblock ~32 ~-1 ~6 log 0 
setblock ~32 ~-1 ~7 glowstone 0  
fill ~32 ~-1 ~9 ~33 ~-1 ~9 gold_block 0  
fill ~32 ~-1 ~11 ~34 ~-1 ~11 wool 11  
fill ~32 ~-1 ~12 ~32 ~-1 ~10 wool 11  
fill ~32 ~-1 ~14 ~34 ~-1 ~14 wool 11  
fill ~32 ~-1 ~15 ~32 ~-1 ~14 wool 11  
fill ~32 ~-1 ~17 ~34 ~-1 ~17 gold_block 0  
fill ~32 ~-1 ~20 ~33 ~-1 ~20 gold_block 0  
fill ~32 ~-1 ~21 ~32 ~-1 ~22 wool 11  
fill ~32 ~-1 ~23 ~32 ~-1 ~32 gold_block 0 
setblock ~32 ~-1 ~34 glowstone 0 
setblock ~32 ~-1 ~35 log 0  
fill ~32 ~-1 ~36 ~35 ~-1 ~36 wool 14  
fill ~32 ~-1 ~37 ~34 ~-1 ~37 wool 14  
fill ~32 ~-1 ~48 ~34 ~-1 ~48 wool 14  
fill ~32 ~-1 ~49 ~35 ~-1 ~49 wool 14 
setblock ~32 ~-1 ~50 log 0 
setblock ~32 ~-1 ~51 glowstone 0 
setblock ~32 ~-1 ~52 gold_block 0 
setblock ~32 ~-1 ~53 wool 11  
fill ~32 ~-1 ~54 ~34 ~-1 ~54 gold_block 0  
fill ~32 ~-1 ~55 ~32 ~-1 ~59 gold_block 0  
fill ~32 ~-1 ~61 ~34 ~-1 ~61 wool 11  
fill ~32 ~-1 ~64 ~32 ~0 ~64 gold_block 0  
fill ~32 ~-1 ~65 ~33 ~-1 ~65 gold_block 0  
fill ~32 ~-1 ~66 ~32 ~-1 ~67 gold_block 0  
fill ~32 ~-1 ~68 ~34 ~-1 ~68 wool 11  
fill ~32 ~-1 ~71 ~33 ~-1 ~71 wool 11  
fill ~32 ~-1 ~72 ~32 ~-1 ~74 wool 11  
fill ~33 ~-1 ~6 ~36 ~-1 ~6 wool 14 
setblock ~33 ~-1 ~7 log 0 
setblock ~33 ~-1 ~8 glowstone 0  
fill ~33 ~-1 ~10 ~34 ~-1 ~10 gold_block 0  
fill ~33 ~-1 ~12 ~34 ~-1 ~12 gold_block 0  
fill ~33 ~-1 ~15 ~34 ~-1 ~15 gold_block 0  
fill ~33 ~-1 ~16 ~33 ~-1 ~15 gold_block 0 
setblock ~33 ~-1 ~18 wool 11  
fill ~33 ~-1 ~21 ~34 ~-1 ~21 gold_block 0  
fill ~33 ~-1 ~22 ~33 ~-1 ~20 gold_block 0  
fill ~33 ~-1 ~23 ~34 ~-1 ~23 wool 11  
fill ~33 ~-1 ~24 ~33 ~-1 ~25 wool 11  
fill ~33 ~-1 ~27 ~34 ~-1 ~27 wool 11  
fill ~33 ~-1 ~28 ~33 ~-1 ~27 wool 11 
setblock ~33 ~-1 ~29 gold_block 0  
fill ~33 ~-1 ~30 ~34 ~-1 ~30 wool 11 
setblock ~33 ~-1 ~31 gold_block 0 
setblock ~33 ~-1 ~33 glowstone 0 
setblock ~33 ~-1 ~34 log 0  
fill ~33 ~-1 ~35 ~38 ~-1 ~35 wool 14 
setblock ~33 ~-1 ~39 gold_block 0  
fill ~33 ~-1 ~41 ~33 ~-1 ~46 gold_block 0  
fill ~33 ~-1 ~50 ~38 ~-1 ~50 wool 14 
setblock ~33 ~-1 ~51 log 0 
setblock ~33 ~-1 ~52 glowstone 0 
setblock ~33 ~-1 ~53 gold_block 0 
setblock ~33 ~-1 ~55 wool 11  
fill ~33 ~-1 ~56 ~34 ~-1 ~56 gold_block 0 
setblock ~33 ~-1 ~57 wool 11  
fill ~33 ~-1 ~58 ~34 ~-1 ~58 gold_block 0  
fill ~33 ~-1 ~60 ~34 ~-1 ~60 gold_block 0 
setblock ~33 ~-1 ~62 gold_block 0  
fill ~33 ~-1 ~64 ~34 ~-1 ~64 wool 11  
fill ~33 ~-1 ~66 ~34 ~-1 ~66 wool 11  
fill ~33 ~-1 ~67 ~33 ~-1 ~66 wool 11  
fill ~33 ~-1 ~70 ~34 ~-1 ~70 gold_block 0  
fill ~33 ~-1 ~72 ~34 ~-1 ~72 gold_block 0 
setblock ~33 ~-1 ~73 wool 11 
setblock ~33 ~-1 ~74 gold_block 0  
fill ~34 ~-1 ~2 ~34 ~-1 ~3 log 0  
fill ~34 ~-1 ~7 ~38 ~-1 ~7 wool 14 
setblock ~34 ~-1 ~8 log 0 
setblock ~34 ~-1 ~9 glowstone 0 
setblock ~34 ~-1 ~13 wool 11 
setblock ~34 ~-1 ~16 wool 11  
fill ~34 ~-1 ~18 ~36 ~-1 ~18 gold_block 0 
setblock ~34 ~-1 ~20 wool 11 
setblock ~34 ~-1 ~22 wool 11 
setblock ~34 ~-1 ~24 gold_block 0 
setblock ~34 ~-1 ~25 wool 11 
setblock ~34 ~-1 ~28 gold_block 0 
setblock ~34 ~-1 ~29 wool 11 
setblock ~34 ~-1 ~31 wool 11  
fill ~34 ~-1 ~32 ~35 ~-1 ~32 glowstone 0  
fill ~34 ~-1 ~33 ~35 ~-1 ~33 log 0  
fill ~34 ~-1 ~34 ~38 ~-1 ~34 wool 14 
setblock ~34 ~-1 ~38 gold_block 0 
setblock ~34 ~-1 ~39 glowstone 0  
fill ~34 ~-1 ~40 ~34 ~-1 ~43 wool 11 
setblock ~34 ~-1 ~44 gold_block 0  
fill ~34 ~-1 ~45 ~34 ~-1 ~46 glowstone 0 
setblock ~34 ~-1 ~47 gold_block 0  
fill ~34 ~-1 ~51 ~38 ~-1 ~51 wool 14  
fill ~34 ~-1 ~52 ~35 ~-1 ~52 log 0  
fill ~34 ~-1 ~53 ~35 ~-1 ~53 glowstone 0 
setblock ~34 ~-1 ~55 gold_block 0 
setblock ~34 ~-1 ~57 gold_block 0 
setblock ~34 ~-1 ~59 wool 11  
fill ~34 ~-1 ~62 ~34 ~-1 ~66 wool 11 
setblock ~34 ~-1 ~67 gold_block 0 
setblock ~34 ~-1 ~69 wool 11 
setblock ~34 ~-1 ~71 gold_block 0 
setblock ~34 ~-1 ~73 gold_block 0 
setblock ~34 ~-1 ~74 wool 11  
fill ~35 ~-1 ~2 ~43 ~-1 ~2 lapis_block 0  
fill ~35 ~-1 ~3 ~36 ~-1 ~3 lapis_block 0 
setblock ~35 ~-1 ~4 log 0  
fill ~35 ~-1 ~8 ~38 ~-1 ~8 wool 14 
setblock ~35 ~-1 ~9 log 0  
fill ~35 ~-1 ~10 ~35 ~-1 ~16 glowstone 0 
setblock ~35 ~-1 ~17 wool 11  
fill ~35 ~-1 ~19 ~35 ~-1 ~32 glowstone 0 
setblock ~35 ~-1 ~37 gold_block 0 
setblock ~35 ~-1 ~38 glowstone 0 
setblock ~35 ~-1 ~39 gold_block 0 
setblock ~35 ~-1 ~40 diamond_block 0 
setblock ~35 ~-1 ~41 gold_block 0 
setblock ~35 ~-1 ~42 diamond_block 0 
setblock ~35 ~-1 ~43 gold_block 0 
setblock ~35 ~-1 ~44 diamond_block 0 
setblock ~35 ~-1 ~45 gold_block 0  
fill ~35 ~-1 ~46 ~35 ~-1 ~47 glowstone 0 
setblock ~35 ~-1 ~48 gold_block 0  
fill ~35 ~-1 ~54 ~35 ~-1 ~60 glowstone 0  
fill ~35 ~-1 ~61 ~36 ~-1 ~61 gold_block 0  
fill ~35 ~-1 ~62 ~36 ~-1 ~62 gold_block 0  
fill ~35 ~-1 ~63 ~35 ~-1 ~75 glowstone 0  
fill ~36 ~-1 ~4 ~38 ~-1 ~4 lapis_block 0 
setblock ~36 ~-1 ~5 log 0 
setblock ~36 ~-1 ~9 leaves 12  
fill ~36 ~-1 ~10 ~36 ~-1 ~16 log 0 
setblock ~36 ~-1 ~17 gold_block 0  
fill ~36 ~-1 ~19 ~36 ~-1 ~32 log 0  
fill ~36 ~-1 ~33 ~38 ~-1 ~33 wool 14 
setblock ~36 ~-1 ~36 gold_block 0 
setblock ~36 ~-1 ~37 glowstone 0 
setblock ~36 ~-1 ~38 gold_block 0 
setblock ~36 ~-1 ~39 diamond_block 0 
setblock ~36 ~-1 ~40 gold_block 0 
setblock ~36 ~-1 ~41 diamond_block 0 
setblock ~36 ~-1 ~42 gold_block 0  
fill ~36 ~-1 ~43 ~36 ~0 ~43 diamond_block 0 
setblock ~36 ~-1 ~44 gold_block 0 
setblock ~36 ~-1 ~45 diamond_block 0 
setblock ~36 ~-1 ~46 gold_block 0  
fill ~36 ~-1 ~47 ~36 ~-1 ~48 glowstone 0  
fill ~36 ~-1 ~49 ~42 ~-1 ~49 gold_block 0  
fill ~36 ~-1 ~52 ~38 ~-1 ~52 wool 14  
fill ~36 ~-1 ~53 ~36 ~-1 ~60 log 0  
fill ~36 ~-1 ~63 ~36 ~-1 ~75 log 0 
setblock ~36 ~-1 ~77 dirt 0 
setblock ~37 ~-1 ~3 glowstone 0  
fill ~37 ~-1 ~5 ~41 ~-1 ~5 lapis_block 0  
fill ~37 ~-1 ~6 ~41 ~-1 ~6 log 0  
fill ~37 ~-1 ~9 ~38 ~-1 ~9 wool 14  
fill ~37 ~-1 ~10 ~38 ~-1 ~10 wool 14  
fill ~37 ~-1 ~11 ~38 ~-1 ~11 wool 14  
fill ~37 ~-1 ~12 ~38 ~-1 ~12 wool 14  
fill ~37 ~-1 ~13 ~38 ~-1 ~13 wool 14  
fill ~37 ~-1 ~14 ~38 ~-1 ~14 wool 14  
fill ~37 ~-1 ~15 ~38 ~-1 ~15 wool 14  
fill ~37 ~-1 ~16 ~38 ~-1 ~16 wool 14  
fill ~37 ~-1 ~17 ~38 ~-1 ~17 wool 14  
fill ~37 ~-1 ~18 ~38 ~-1 ~18 wool 14  
fill ~37 ~-1 ~19 ~38 ~-1 ~19 wool 14  
fill ~37 ~-1 ~20 ~38 ~-1 ~20 wool 14  
fill ~37 ~-1 ~21 ~38 ~-1 ~21 wool 14  
fill ~37 ~-1 ~22 ~38 ~-1 ~22 wool 14  
fill ~37 ~-1 ~23 ~38 ~-1 ~23 wool 14  
fill ~37 ~-1 ~24 ~38 ~-1 ~24 wool 14  
fill ~37 ~-1 ~25 ~38 ~-1 ~25 wool 14  
fill ~37 ~-1 ~26 ~38 ~-1 ~26 wool 14  
fill ~37 ~-1 ~27 ~38 ~-1 ~27 wool 14  
fill ~37 ~-1 ~28 ~38 ~-1 ~28 wool 14  
fill ~37 ~-1 ~29 ~38 ~-1 ~29 wool 14  
fill ~37 ~-1 ~30 ~38 ~-1 ~30 wool 14  
fill ~37 ~-1 ~31 ~38 ~-1 ~31 wool 14  
fill ~37 ~-1 ~32 ~38 ~-1 ~32 wool 14 
setblock ~37 ~-1 ~37 gold_block 0 
setblock ~37 ~-1 ~38 diamond_block 0 
setblock ~37 ~-1 ~39 gold_block 0 
setblock ~37 ~-1 ~40 diamond_block 0 
setblock ~37 ~-1 ~41 gold_block 0  
fill ~37 ~-1 ~42 ~37 ~1 ~42 diamond_block 0 
setblock ~37 ~-1 ~43 gold_block 0  
fill ~37 ~-1 ~44 ~37 ~0 ~44 diamond_block 0 
setblock ~37 ~-1 ~45 gold_block 0 
setblock ~37 ~-1 ~46 diamond_block 0  
fill ~37 ~-1 ~47 ~37 ~-1 ~49 gold_block 0  
fill ~37 ~-1 ~53 ~38 ~-1 ~53 wool 14  
fill ~37 ~-1 ~54 ~38 ~-1 ~54 wool 14  
fill ~37 ~-1 ~55 ~38 ~-1 ~55 wool 14  
fill ~37 ~-1 ~56 ~38 ~-1 ~56 wool 14  
fill ~37 ~-1 ~57 ~38 ~-1 ~57 wool 14  
fill ~37 ~-1 ~58 ~38 ~-1 ~58 wool 14  
fill ~37 ~-1 ~59 ~38 ~-1 ~59 wool 14  
fill ~37 ~-1 ~60 ~38 ~-1 ~60 wool 14  
fill ~37 ~-1 ~61 ~38 ~-1 ~61 wool 14  
fill ~37 ~-1 ~62 ~38 ~-1 ~62 wool 14  
fill ~37 ~-1 ~63 ~38 ~-1 ~63 wool 14  
fill ~37 ~-1 ~64 ~38 ~-1 ~64 wool 14  
fill ~37 ~-1 ~65 ~38 ~-1 ~65 wool 14  
fill ~37 ~-1 ~66 ~38 ~-1 ~66 wool 14  
fill ~37 ~-1 ~67 ~38 ~-1 ~67 wool 14  
fill ~37 ~-1 ~68 ~38 ~-1 ~68 wool 14  
fill ~37 ~-1 ~69 ~38 ~-1 ~69 wool 14  
fill ~37 ~-1 ~70 ~38 ~-1 ~70 wool 14  
fill ~37 ~-1 ~71 ~38 ~-1 ~71 wool 14  
fill ~37 ~-1 ~72 ~38 ~-1 ~72 wool 14  
fill ~37 ~-1 ~73 ~38 ~-1 ~73 wool 14  
fill ~37 ~-1 ~74 ~38 ~-1 ~74 wool 14  
fill ~37 ~-1 ~75 ~38 ~-1 ~75 wool 14  
fill ~37 ~-1 ~76 ~38 ~-1 ~76 wool 14  
fill ~37 ~-1 ~77 ~38 ~-1 ~77 wool 14  
fill ~38 ~-1 ~3 ~40 ~-1 ~3 lapis_block 0  
fill ~38 ~-1 ~36 ~42 ~-1 ~36 gold_block 0  
fill ~38 ~-1 ~37 ~40 ~-1 ~37 dirt 0 
setblock ~38 ~-1 ~38 gold_block 0 
setblock ~38 ~-1 ~39 diamond_block 0 
setblock ~38 ~-1 ~40 gold_block 0  
fill ~38 ~-1 ~41 ~38 ~2 ~41 diamond_block 0  
fill ~38 ~-1 ~42 ~40 ~-1 ~42 gold_block 0  
fill ~38 ~-1 ~43 ~38 ~3 ~43 diamond_block 0 
setblock ~38 ~-1 ~44 gold_block 0  
fill ~38 ~-1 ~45 ~38 ~0 ~45 diamond_block 0 
setblock ~38 ~-1 ~46 gold_block 0 
setblock ~38 ~-1 ~47 diamond_block 0  
fill ~38 ~-1 ~48 ~41 ~-1 ~48 gold_block 0 
setblock ~39 ~-1 ~4 glowstone 0  
fill ~39 ~-1 ~7 ~39 ~-1 ~36 gold_block 0 
setblock ~39 ~-1 ~38 diamond_block 0 
setblock ~39 ~-1 ~39 gold_block 0  
fill ~39 ~-1 ~40 ~39 ~1 ~40 diamond_block 0 
setblock ~39 ~-1 ~41 gold_block 0 
setblock ~39 ~-1 ~43 gold_block 0  
fill ~39 ~-1 ~44 ~39 ~3 ~44 diamond_block 0 
setblock ~39 ~-1 ~45 gold_block 0  
fill ~39 ~-1 ~46 ~39 ~0 ~46 diamond_block 0 
setblock ~39 ~-1 ~47 gold_block 0  
fill ~39 ~-1 ~50 ~39 ~-1 ~75 gold_block 0  
fill ~39 ~-1 ~76 ~39 ~-1 ~77 dirt 0  
fill ~40 ~-1 ~4 ~42 ~-1 ~4 lapis_block 0  
fill ~40 ~-1 ~7 ~44 ~-1 ~7 wool 14  
fill ~40 ~-1 ~8 ~43 ~-1 ~8 wool 14  
fill ~40 ~-1 ~9 ~41 ~-1 ~9 wool 14  
fill ~40 ~-1 ~10 ~41 ~-1 ~10 wool 14  
fill ~40 ~-1 ~11 ~41 ~-1 ~11 wool 14  
fill ~40 ~-1 ~12 ~41 ~-1 ~12 wool 14  
fill ~40 ~-1 ~13 ~41 ~-1 ~13 wool 14  
fill ~40 ~-1 ~14 ~41 ~-1 ~14 wool 14  
fill ~40 ~-1 ~15 ~41 ~-1 ~15 wool 14  
fill ~40 ~-1 ~16 ~41 ~-1 ~16 wool 14  
fill ~40 ~-1 ~17 ~41 ~-1 ~17 wool 14  
fill ~40 ~-1 ~18 ~41 ~-1 ~18 wool 14  
fill ~40 ~-1 ~19 ~41 ~-1 ~19 wool 14  
fill ~40 ~-1 ~20 ~41 ~-1 ~20 wool 14  
fill ~40 ~-1 ~21 ~41 ~-1 ~21 wool 14  
fill ~40 ~-1 ~22 ~41 ~-1 ~22 wool 14  
fill ~40 ~-1 ~23 ~41 ~-1 ~23 wool 14  
fill ~40 ~-1 ~24 ~41 ~-1 ~24 wool 14  
fill ~40 ~-1 ~25 ~41 ~-1 ~25 wool 14  
fill ~40 ~-1 ~26 ~41 ~-1 ~26 wool 14  
fill ~40 ~-1 ~27 ~41 ~-1 ~27 wool 14  
fill ~40 ~-1 ~28 ~41 ~-1 ~28 wool 14  
fill ~40 ~-1 ~29 ~41 ~-1 ~29 wool 14  
fill ~40 ~-1 ~30 ~41 ~-1 ~30 wool 14  
fill ~40 ~-1 ~31 ~41 ~-1 ~31 wool 14  
fill ~40 ~-1 ~32 ~41 ~-1 ~32 wool 14  
fill ~40 ~-1 ~33 ~42 ~-1 ~33 wool 14  
fill ~40 ~-1 ~34 ~44 ~-1 ~34 wool 14  
fill ~40 ~-1 ~35 ~45 ~-1 ~35 wool 14 
setblock ~40 ~-1 ~38 gold_block 0 
setblock ~40 ~-1 ~39 diamond_block 0 
setblock ~40 ~-1 ~40 gold_block 0  
fill ~40 ~-1 ~41 ~40 ~2 ~41 diamond_block 0  
fill ~40 ~-1 ~43 ~40 ~3 ~43 diamond_block 0 
setblock ~40 ~-1 ~44 gold_block 0  
fill ~40 ~-1 ~45 ~40 ~0 ~45 diamond_block 0 
setblock ~40 ~-1 ~46 gold_block 0 
setblock ~40 ~-1 ~47 diamond_block 0  
fill ~40 ~-1 ~50 ~45 ~-1 ~50 wool 14  
fill ~40 ~-1 ~51 ~44 ~-1 ~51 wool 14  
fill ~40 ~-1 ~52 ~42 ~-1 ~52 wool 14  
fill ~40 ~-1 ~53 ~41 ~-1 ~53 wool 14  
fill ~40 ~-1 ~54 ~41 ~-1 ~54 wool 14  
fill ~40 ~-1 ~55 ~41 ~-1 ~55 wool 14  
fill ~40 ~-1 ~56 ~41 ~-1 ~56 wool 14  
fill ~40 ~-1 ~57 ~41 ~-1 ~57 wool 14  
fill ~40 ~-1 ~58 ~41 ~-1 ~58 wool 14  
fill ~40 ~-1 ~59 ~41 ~-1 ~59 wool 14  
fill ~40 ~-1 ~60 ~41 ~-1 ~60 wool 14  
fill ~40 ~-1 ~61 ~41 ~-1 ~61 wool 14  
fill ~40 ~-1 ~62 ~41 ~-1 ~62 wool 14  
fill ~40 ~-1 ~63 ~41 ~-1 ~63 wool 14  
fill ~40 ~-1 ~64 ~41 ~-1 ~64 wool 14  
fill ~40 ~-1 ~65 ~41 ~-1 ~65 wool 14  
fill ~40 ~-1 ~66 ~41 ~-1 ~66 wool 14  
fill ~40 ~-1 ~67 ~41 ~-1 ~67 wool 14  
fill ~40 ~-1 ~68 ~41 ~-1 ~68 wool 14  
fill ~40 ~-1 ~69 ~41 ~-1 ~69 wool 14  
fill ~40 ~-1 ~70 ~41 ~-1 ~70 wool 14  
fill ~40 ~-1 ~71 ~41 ~-1 ~71 wool 14  
fill ~40 ~-1 ~72 ~41 ~-1 ~72 wool 14  
fill ~40 ~-1 ~73 ~41 ~-1 ~73 wool 14  
fill ~40 ~-1 ~74 ~41 ~-1 ~74 wool 14  
fill ~40 ~-1 ~75 ~41 ~-1 ~75 wool 14  
fill ~40 ~-1 ~76 ~41 ~-1 ~76 wool 14  
fill ~40 ~-1 ~77 ~41 ~-1 ~77 wool 14 
setblock ~41 ~-1 ~3 glowstone 0 
setblock ~41 ~-1 ~37 gold_block 0 
setblock ~41 ~-1 ~38 diamond_block 0 
setblock ~41 ~-1 ~39 gold_block 0 
setblock ~41 ~-1 ~40 diamond_block 0 
setblock ~41 ~-1 ~41 gold_block 0  
fill ~41 ~-1 ~42 ~41 ~1 ~42 diamond_block 0 
setblock ~41 ~-1 ~43 gold_block 0  
fill ~41 ~-1 ~44 ~41 ~0 ~44 diamond_block 0 
setblock ~41 ~-1 ~45 gold_block 0 
setblock ~41 ~-1 ~46 diamond_block 0 
setblock ~41 ~-1 ~47 gold_block 0  
fill ~42 ~-1 ~3 ~43 ~-1 ~3 lapis_block 0 
setblock ~42 ~-1 ~5 log 0  
fill ~42 ~-1 ~6 ~45 ~-1 ~6 wool 14 
setblock ~42 ~-1 ~9 leaves 12  
fill ~42 ~-1 ~10 ~42 ~-1 ~16 log 0  
fill ~42 ~-1 ~17 ~46 ~-1 ~17 gold_block 0  
fill ~42 ~-1 ~18 ~42 ~-1 ~17 gold_block 0  
fill ~42 ~-1 ~19 ~42 ~-1 ~32 log 0 
setblock ~42 ~-1 ~37 glowstone 0 
setblock ~42 ~-1 ~38 gold_block 0 
setblock ~42 ~-1 ~39 diamond_block 0 
setblock ~42 ~-1 ~40 gold_block 0 
setblock ~42 ~-1 ~41 diamond_block 0 
setblock ~42 ~-1 ~42 gold_block 0  
fill ~42 ~-1 ~43 ~42 ~0 ~43 diamond_block 0 
setblock ~42 ~-1 ~44 gold_block 0 
setblock ~42 ~-1 ~45 diamond_block 0 
setblock ~42 ~-1 ~46 gold_block 0  
fill ~42 ~-1 ~47 ~43 ~-1 ~47 glowstone 0  
fill ~42 ~-1 ~48 ~42 ~-1 ~47 glowstone 0  
fill ~42 ~-1 ~53 ~42 ~-1 ~60 log 0  
fill ~42 ~-1 ~61 ~42 ~-1 ~62 gold_block 0  
fill ~42 ~-1 ~63 ~42 ~-1 ~75 log 0  
fill ~42 ~-1 ~76 ~52 ~-1 ~76 dirt 0  
fill ~42 ~-1 ~77 ~42 ~-1 ~76 dirt 0 
setblock ~43 ~-1 ~4 log 0  
fill ~43 ~-1 ~5 ~46 ~-1 ~5 wool 14 
setblock ~43 ~-1 ~9 log 0  
fill ~43 ~-1 ~10 ~43 ~-1 ~16 glowstone 0  
fill ~43 ~-1 ~18 ~45 ~-1 ~18 wool 11  
fill ~43 ~-1 ~19 ~43 ~-1 ~32 glowstone 0  
fill ~43 ~-1 ~33 ~44 ~-1 ~33 log 0  
fill ~43 ~-1 ~36 ~46 ~-1 ~36 wool 14 
setblock ~43 ~-1 ~37 gold_block 0 
setblock ~43 ~-1 ~38 glowstone 0 
setblock ~43 ~-1 ~39 wool 11 
setblock ~43 ~-1 ~40 diamond_block 0 
setblock ~43 ~-1 ~41 gold_block 0 
setblock ~43 ~-1 ~42 diamond_block 0 
setblock ~43 ~-1 ~43 gold_block 0 
setblock ~43 ~-1 ~44 diamond_block 0 
setblock ~43 ~-1 ~45 gold_block 0  
fill ~43 ~-1 ~46 ~44 ~-1 ~46 glowstone 0 
setblock ~43 ~-1 ~48 gold_block 0  
fill ~43 ~-1 ~49 ~46 ~-1 ~49 wool 14  
fill ~43 ~-1 ~52 ~44 ~-1 ~52 log 0  
fill ~43 ~-1 ~53 ~44 ~-1 ~53 glowstone 0  
fill ~43 ~-1 ~54 ~43 ~-1 ~60 glowstone 0  
fill ~43 ~-1 ~61 ~44 ~-1 ~61 wool 11 
setblock ~43 ~-1 ~62 gold_block 0  
fill ~43 ~-1 ~63 ~43 ~-1 ~75 glowstone 0  
fill ~43 ~-1 ~77 ~77 ~-1 ~77 grass 0  
fill ~44 ~-1 ~2 ~44 ~-1 ~3 log 0  
fill ~44 ~-1 ~4 ~46 ~-1 ~4 wool 14 
setblock ~44 ~-1 ~8 log 0 
setblock ~44 ~-1 ~9 glowstone 0 
setblock ~44 ~-1 ~10 gold_block 0  
fill ~44 ~-1 ~11 ~45 ~-1 ~11 wool 11  
fill ~44 ~-1 ~12 ~46 ~-1 ~12 gold_block 0  
fill ~44 ~-1 ~13 ~44 ~-1 ~12 gold_block 0  
fill ~44 ~-1 ~14 ~45 ~-1 ~14 wool 11  
fill ~44 ~-1 ~15 ~46 ~-1 ~15 gold_block 0 
setblock ~44 ~-1 ~16 wool 11  
fill ~44 ~-1 ~19 ~46 ~-1 ~19 gold_block 0  
fill ~44 ~-1 ~20 ~44 ~-1 ~21 wool 11  
fill ~44 ~-1 ~22 ~46 ~-1 ~22 gold_block 0  
fill ~44 ~-1 ~23 ~45 ~-1 ~23 wool 11 
setblock ~44 ~-1 ~24 gold_block 0  
fill ~44 ~-1 ~25 ~45 ~-1 ~25 wool 11  
fill ~44 ~-1 ~26 ~44 ~-1 ~25 wool 11  
fill ~44 ~-1 ~27 ~46 ~-1 ~27 gold_block 0  
fill ~44 ~-1 ~28 ~45 ~-1 ~28 wool 11  
fill ~44 ~-1 ~29 ~46 ~-1 ~29 gold_block 0  
fill ~44 ~-1 ~30 ~44 ~-1 ~31 wool 11 
setblock ~44 ~-1 ~32 glowstone 0  
fill ~44 ~-1 ~37 ~46 ~-1 ~37 wool 14 
setblock ~44 ~-1 ~38 gold_block 0 
setblock ~44 ~-1 ~39 glowstone 0  
fill ~44 ~-1 ~40 ~45 ~-1 ~40 gold_block 0 
setblock ~44 ~-1 ~41 wool 11  
fill ~44 ~-1 ~42 ~45 ~-1 ~42 gold_block 0  
fill ~44 ~-1 ~43 ~44 ~-1 ~44 wool 11 
setblock ~44 ~-1 ~45 glowstone 0 
setblock ~44 ~-1 ~47 gold_block 0  
fill ~44 ~-1 ~48 ~46 ~-1 ~48 wool 14 
setblock ~44 ~-1 ~54 gold_block 0  
fill ~44 ~-1 ~55 ~45 ~-1 ~55 wool 11 
setblock ~44 ~-1 ~56 gold_block 0  
fill ~44 ~-1 ~57 ~45 ~-1 ~57 wool 11  
fill ~44 ~-1 ~58 ~46 ~-1 ~58 gold_block 0  
fill ~44 ~-1 ~59 ~44 ~-1 ~62 wool 11  
fill ~44 ~-1 ~63 ~45 ~-1 ~63 gold_block 0  
fill ~44 ~-1 ~64 ~44 ~-1 ~65 gold_block 0  
fill ~44 ~-1 ~66 ~48 ~-1 ~66 wool 11  
fill ~44 ~-1 ~67 ~44 ~-1 ~68 gold_block 0  
fill ~44 ~-1 ~69 ~45 ~-1 ~69 wool 11  
fill ~44 ~-1 ~70 ~44 ~-1 ~71 gold_block 0  
fill ~44 ~-1 ~72 ~45 ~-1 ~72 wool 11  
fill ~44 ~-1 ~73 ~45 ~-1 ~73 gold_block 0 
setblock ~44 ~-1 ~74 wool 11  
fill ~44 ~-1 ~75 ~51 ~-1 ~75 glowstone 0  
fill ~45 ~-1 ~2 ~46 ~-1 ~2 wool 14  
fill ~45 ~-1 ~3 ~46 ~-1 ~3 wool 14 
setblock ~45 ~-1 ~7 log 0 
setblock ~45 ~-1 ~8 glowstone 0 
setblock ~45 ~-1 ~9 gold_block 0  
fill ~45 ~-1 ~10 ~47 ~-1 ~10 wool 11  
fill ~45 ~-1 ~13 ~47 ~-1 ~13 wool 11 
setblock ~45 ~-1 ~16 gold_block 0  
fill ~45 ~-1 ~20 ~47 ~-1 ~20 gold_block 0  
fill ~45 ~-1 ~21 ~46 ~-1 ~21 wool 11  
fill ~45 ~-1 ~24 ~47 ~-1 ~24 wool 11 
setblock ~45 ~-1 ~26 gold_block 0  
fill ~45 ~-1 ~30 ~46 ~-1 ~30 gold_block 0  
fill ~45 ~-1 ~31 ~46 ~-1 ~31 gold_block 0 
setblock ~45 ~-1 ~32 wool 11 
setblock ~45 ~-1 ~33 glowstone 0  
fill ~45 ~-1 ~38 ~47 ~-1 ~38 wool 14 
setblock ~45 ~-1 ~39 gold_block 0 
setblock ~45 ~-1 ~41 gold_block 0  
fill ~45 ~-1 ~43 ~45 ~-1 ~46 gold_block 0  
fill ~45 ~-1 ~47 ~47 ~-1 ~47 wool 14 
setblock ~45 ~-1 ~51 log 0 
setblock ~45 ~-1 ~52 glowstone 0  
fill ~45 ~-1 ~53 ~45 ~-1 ~57 wool 11  
fill ~45 ~-1 ~59 ~47 ~-1 ~59 gold_block 0  
fill ~45 ~-1 ~60 ~45 ~-1 ~61 gold_block 0  
fill ~45 ~-1 ~62 ~46 ~-1 ~62 wool 11  
fill ~45 ~-1 ~64 ~46 ~-1 ~64 wool 11  
fill ~45 ~-1 ~65 ~45 ~-1 ~64 wool 11  
fill ~45 ~-1 ~67 ~45 ~-1 ~72 wool 11  
fill ~45 ~-1 ~74 ~47 ~-1 ~74 gold_block 0 
setblock ~46 ~-1 ~6 log 0 
setblock ~46 ~-1 ~7 glowstone 0 
setblock ~46 ~-1 ~8 gold_block 0 
setblock ~46 ~-1 ~11 gold_block 0  
fill ~46 ~-1 ~14 ~47 ~-1 ~14 gold_block 0  
fill ~46 ~-1 ~16 ~47 ~-1 ~16 wool 11  
fill ~46 ~-1 ~18 ~47 ~-1 ~18 gold_block 0 
setblock ~46 ~-1 ~23 gold_block 0  
fill ~46 ~-1 ~25 ~48 ~-1 ~25 gold_block 0 
setblock ~46 ~-1 ~26 wool 11 
setblock ~46 ~-1 ~28 gold_block 0  
fill ~46 ~-1 ~32 ~47 ~-1 ~32 gold_block 0  
fill ~46 ~-1 ~33 ~46 ~-1 ~27 gold_block 0 
setblock ~46 ~-1 ~34 glowstone 0 
setblock ~46 ~-1 ~35 log 0  
fill ~46 ~-1 ~39 ~47 ~-1 ~39 wool 14  
fill ~46 ~-1 ~40 ~48 ~-1 ~40 wool 14  
fill ~46 ~-1 ~41 ~72 ~-1 ~41 wool 14  
fill ~46 ~-1 ~42 ~72 ~-1 ~42 wool 14  
fill ~46 ~-1 ~43 ~72 ~-1 ~43 wool 14  
fill ~46 ~-1 ~44 ~72 ~-1 ~44 wool 14  
fill ~46 ~-1 ~45 ~47 ~-1 ~45 wool 14  
fill ~46 ~-1 ~46 ~47 ~-1 ~46 wool 14 
setblock ~46 ~-1 ~50 log 0 
setblock ~46 ~-1 ~51 glowstone 0 
setblock ~46 ~-1 ~52 wool 11  
fill ~46 ~-1 ~53 ~47 ~-1 ~53 gold_block 0  
fill ~46 ~-1 ~54 ~46 ~-1 ~59 gold_block 0  
fill ~46 ~-1 ~60 ~46 ~-1 ~64 wool 11  
fill ~46 ~-1 ~65 ~47 ~-1 ~65 gold_block 0  
fill ~46 ~-1 ~67 ~49 ~-1 ~67 gold_block 0  
fill ~46 ~-1 ~68 ~46 ~-1 ~69 gold_block 0  
fill ~46 ~-1 ~70 ~47 ~-1 ~70 wool 11  
fill ~46 ~-1 ~71 ~46 ~-1 ~72 gold_block 0  
fill ~46 ~-1 ~73 ~48 ~-1 ~73 wool 11  
fill ~47 ~-1 ~2 ~47 ~-1 ~5 log 0 
setblock ~47 ~-1 ~6 glowstone 0 
setblock ~47 ~-1 ~7 gold_block 0  
fill ~47 ~-1 ~9 ~48 ~-1 ~9 gold_block 0  
fill ~47 ~-1 ~11 ~49 ~-1 ~11 wool 11  
fill ~47 ~-1 ~12 ~47 ~-1 ~10 wool 11 
setblock ~47 ~-1 ~15 wool 11 
setblock ~47 ~-1 ~17 wool 11  
fill ~47 ~-1 ~19 ~48 ~-1 ~19 wool 11  
fill ~47 ~-1 ~21 ~48 ~-1 ~21 gold_block 0  
fill ~47 ~-1 ~22 ~47 ~-1 ~24 wool 11 
setblock ~47 ~-1 ~26 gold_block 0  
fill ~47 ~-1 ~27 ~48 ~-1 ~27 wool 14  
fill ~47 ~-1 ~28 ~47 ~-1 ~31 wool 14 
setblock ~47 ~-1 ~33 wool 11 
setblock ~47 ~-1 ~34 gold_block 0 
setblock ~47 ~-1 ~35 glowstone 0  
fill ~47 ~-1 ~36 ~47 ~-1 ~37 log 0  
fill ~47 ~-1 ~48 ~47 ~-1 ~49 log 0 
setblock ~47 ~-1 ~50 glowstone 0  
fill ~47 ~-1 ~51 ~53 ~-1 ~51 gold_block 0  
fill ~47 ~-1 ~52 ~48 ~-1 ~52 gold_block 0  
fill ~47 ~-1 ~54 ~48 ~-1 ~54 wool 14  
fill ~47 ~-1 ~55 ~47 ~-1 ~58 wool 14  
fill ~47 ~-1 ~60 ~48 ~-1 ~60 gold_block 0  
fill ~47 ~-1 ~61 ~47 ~-1 ~62 gold_block 0  
fill ~47 ~-1 ~63 ~49 ~-1 ~63 wool 11  
fill ~47 ~-1 ~64 ~48 ~-1 ~64 gold_block 0  
fill ~47 ~-1 ~68 ~48 ~-1 ~68 wool 11  
fill ~47 ~-1 ~69 ~48 ~-1 ~69 gold_block 0  
fill ~47 ~-1 ~71 ~50 ~-1 ~71 wool 11  
fill ~47 ~-1 ~72 ~47 ~-1 ~70 wool 11  
fill ~48 ~-1 ~2 ~59 ~-1 ~2 glowstone 0  
fill ~48 ~-1 ~3 ~48 ~-1 ~5 glowstone 0  
fill ~48 ~-1 ~7 ~49 ~-1 ~7 wool 11 
setblock ~48 ~-1 ~10 gold_block 0  
fill ~48 ~-1 ~12 ~48 ~-1 ~13 gold_block 0  
fill ~48 ~-1 ~14 ~49 ~-1 ~14 wool 11  
fill ~48 ~-1 ~15 ~48 ~-1 ~17 gold_block 0  
fill ~48 ~-1 ~18 ~49 ~-1 ~18 wool 11 
setblock ~48 ~-1 ~20 wool 11  
fill ~48 ~-1 ~22 ~49 ~-1 ~22 gold_block 0  
fill ~48 ~-1 ~23 ~48 ~-1 ~25 gold_block 0  
fill ~48 ~-1 ~26 ~49 ~-1 ~26 wool 14  
fill ~48 ~-1 ~28 ~49 ~-1 ~28 wool 11  
fill ~48 ~-1 ~29 ~48 ~-1 ~30 wool 11  
fill ~48 ~-1 ~31 ~48 ~-1 ~32 wool 14 
setblock ~48 ~-1 ~33 gold_block 0 
setblock ~48 ~-1 ~34 wool 11  
fill ~48 ~-1 ~35 ~49 ~-1 ~35 gold_block 0  
fill ~48 ~-1 ~36 ~48 ~-1 ~37 glowstone 0  
fill ~48 ~-1 ~38 ~48 ~-1 ~39 log 0  
fill ~48 ~-1 ~45 ~52 ~-1 ~45 log 0  
fill ~48 ~-1 ~46 ~48 ~-1 ~47 log 0  
fill ~48 ~-1 ~48 ~48 ~-1 ~49 glowstone 0  
fill ~48 ~-1 ~50 ~49 ~-1 ~50 gold_block 0  
fill ~48 ~-1 ~53 ~49 ~-1 ~53 wool 14  
fill ~48 ~-1 ~55 ~48 ~0 ~55 gold_block 0  
fill ~48 ~-1 ~56 ~52 ~-1 ~56 gold_block 0  
fill ~48 ~-1 ~57 ~48 ~0 ~57 gold_block 0  
fill ~48 ~-1 ~58 ~48 ~-1 ~59 wool 14  
fill ~48 ~-1 ~61 ~48 ~-1 ~63 wool 11 
setblock ~48 ~-1 ~65 wool 11  
fill ~48 ~-1 ~70 ~49 ~-1 ~70 gold_block 0  
fill ~48 ~-1 ~72 ~51 ~-1 ~72 gold_block 0  
fill ~48 ~-1 ~74 ~50 ~-1 ~74 wool 11  
fill ~49 ~-1 ~3 ~49 ~-1 ~4 gold_block 0  
fill ~49 ~-1 ~5 ~49 ~-1 ~7 wool 11 
setblock ~49 ~-1 ~8 gold_block 0 
setblock ~49 ~-1 ~9 wool 11 
setblock ~49 ~-1 ~10 glowstone 0 
setblock ~49 ~-1 ~12 wool 11  
fill ~49 ~-1 ~13 ~51 ~-1 ~13 gold_block 0 
setblock ~49 ~-1 ~15 glowstone 0 
setblock ~49 ~-1 ~16 wool 11  
fill ~49 ~-1 ~17 ~52 ~-1 ~17 gold_block 0  
fill ~49 ~-1 ~19 ~50 ~-1 ~19 gold_block 0 
setblock ~49 ~-1 ~20 glowstone 0 
setblock ~49 ~-1 ~21 wool 11 
setblock ~49 ~-1 ~23 wool 11  
fill ~49 ~-1 ~24 ~54 ~-1 ~24 gold_block 0  
fill ~49 ~-1 ~25 ~53 ~-1 ~25 wool 14  
fill ~49 ~-1 ~27 ~50 ~-1 ~27 wool 11  
fill ~49 ~-1 ~29 ~49 ~-1 ~31 gold_block 0  
fill ~49 ~-1 ~32 ~49 ~-1 ~33 wool 14  
fill ~49 ~-1 ~34 ~54 ~-1 ~34 gold_block 0 
setblock ~49 ~-1 ~36 wool 11  
fill ~49 ~-1 ~37 ~50 ~-1 ~37 gold_block 0  
fill ~49 ~-1 ~38 ~49 ~-1 ~39 glowstone 0  
fill ~49 ~-1 ~40 ~52 ~-1 ~40 log 0  
fill ~49 ~-1 ~46 ~52 ~-1 ~46 glowstone 0  
fill ~49 ~-1 ~47 ~49 ~-1 ~46 glowstone 0 
setblock ~49 ~-1 ~48 wool 11 
setblock ~49 ~-1 ~49 gold_block 0  
fill ~49 ~-1 ~52 ~53 ~-1 ~52 wool 14  
fill ~49 ~-1 ~54 ~49 ~0 ~54 gold_block 0  
fill ~49 ~-1 ~55 ~50 ~-1 ~55 wool 11  
fill ~49 ~-1 ~57 ~49 ~-1 ~58 wool 11  
fill ~49 ~-1 ~59 ~49 ~-1 ~60 wool 14  
fill ~49 ~-1 ~61 ~56 ~-1 ~61 gold_block 0  
fill ~49 ~-1 ~62 ~50 ~-1 ~62 gold_block 0 
setblock ~49 ~-1 ~64 wool 11  
fill ~49 ~-1 ~65 ~49 ~0 ~65 gold_block 0  
fill ~49 ~-1 ~66 ~50 ~-1 ~66 gold_block 0 
setblock ~49 ~-1 ~68 gold_block 0  
fill ~49 ~-1 ~69 ~50 ~-1 ~69 wool 11 
setblock ~49 ~-1 ~73 gold_block 0  
fill ~50 ~-1 ~3 ~52 ~-1 ~3 wool 11  
fill ~50 ~-1 ~4 ~50 ~-1 ~3 wool 11  
fill ~50 ~-1 ~5 ~51 ~-1 ~5 gold_block 0  
fill ~50 ~-1 ~6 ~50 ~-1 ~7 gold_block 0 
setblock ~50 ~-1 ~8 wool 11  
fill ~50 ~-1 ~9 ~52 ~-1 ~9 gold_block 0  
fill ~50 ~-1 ~10 ~51 ~-1 ~10 wool 11  
fill ~50 ~-1 ~11 ~53 ~-1 ~11 gold_block 0  
fill ~50 ~-1 ~12 ~50 ~-1 ~11 gold_block 0  
fill ~50 ~-1 ~14 ~50 ~-1 ~21 gold_block 0  
fill ~50 ~-1 ~22 ~51 ~-1 ~22 wool 11  
fill ~50 ~-1 ~23 ~52 ~-1 ~23 gold_block 0  
fill ~50 ~-1 ~26 ~52 ~-1 ~26 gold_block 0  
fill ~50 ~-1 ~28 ~51 ~-1 ~28 gold_block 0 
setblock ~50 ~-1 ~29 wool 11  
fill ~50 ~-1 ~30 ~51 ~-1 ~30 gold_block 0  
fill ~50 ~-1 ~31 ~51 ~-1 ~31 wool 11  
fill ~50 ~-1 ~32 ~52 ~-1 ~32 gold_block 0  
fill ~50 ~-1 ~33 ~53 ~-1 ~33 wool 14 
setblock ~50 ~-1 ~35 wool 11 
setblock ~50 ~-1 ~36 gold_block 0  
fill ~50 ~-1 ~38 ~51 ~-1 ~38 gold_block 0  
fill ~50 ~-1 ~39 ~52 ~-1 ~39 glowstone 0  
fill ~50 ~-1 ~47 ~51 ~-1 ~47 wool 11  
fill ~50 ~-1 ~48 ~55 ~-1 ~48 gold_block 0  
fill ~50 ~-1 ~49 ~51 ~-1 ~49 wool 11  
fill ~50 ~-1 ~50 ~50 ~-1 ~49 wool 11  
fill ~50 ~-1 ~53 ~50 ~-1 ~55 wool 11 
setblock ~50 ~-1 ~57 gold_block 0  
fill ~50 ~-1 ~58 ~50 ~-1 ~59 wool 11  
fill ~50 ~-1 ~60 ~53 ~-1 ~60 wool 14  
fill ~50 ~-1 ~63 ~52 ~-1 ~63 gold_block 0  
fill ~50 ~-1 ~64 ~50 ~-1 ~61 gold_block 0  
fill ~50 ~-1 ~65 ~51 ~-1 ~65 wool 11  
fill ~50 ~-1 ~67 ~51 ~-1 ~67 glowstone 0  
fill ~50 ~-1 ~68 ~51 ~-1 ~68 glowstone 0  
fill ~50 ~-1 ~70 ~51 ~-1 ~70 wool 11 
setblock ~50 ~-1 ~73 wool 11  
fill ~51 ~-1 ~4 ~52 ~-1 ~4 gold_block 0  
fill ~51 ~-1 ~6 ~53 ~-1 ~6 wool 11  
fill ~51 ~-1 ~7 ~54 ~-1 ~7 gold_block 0  
fill ~51 ~-1 ~8 ~51 ~0 ~8 gold_block 0 
setblock ~51 ~-1 ~12 wool 11  
fill ~51 ~-1 ~14 ~52 ~-1 ~14 wool 11  
fill ~51 ~-1 ~15 ~51 ~-1 ~16 wool 11  
fill ~51 ~-1 ~18 ~52 ~-1 ~18 wool 11  
fill ~51 ~-1 ~19 ~51 ~-1 ~20 wool 11  
fill ~51 ~-1 ~21 ~53 ~-1 ~21 gold_block 0 
setblock ~51 ~-1 ~27 gold_block 0  
fill ~51 ~-1 ~29 ~52 ~-1 ~29 gold_block 0  
fill ~51 ~-1 ~35 ~52 ~-1 ~35 gold_block 0  
fill ~51 ~-1 ~36 ~51 ~-1 ~37 wool 11  
fill ~51 ~-1 ~50 ~53 ~-1 ~50 gold_block 0  
fill ~51 ~-1 ~53 ~51 ~0 ~53 gold_block 0  
fill ~51 ~-1 ~54 ~53 ~-1 ~54 wool 11 
setblock ~51 ~-1 ~55 gold_block 0 
setblock ~51 ~-1 ~57 wool 11  
fill ~51 ~-1 ~58 ~53 ~-1 ~58 gold_block 0  
fill ~51 ~-1 ~59 ~52 ~-1 ~59 wool 11 
setblock ~51 ~-1 ~62 wool 11 
setblock ~51 ~-1 ~64 wool 11  
fill ~51 ~-1 ~66 ~54 ~-1 ~66 wool 11  
fill ~51 ~-1 ~69 ~52 ~-1 ~69 gold_block 0 
setblock ~51 ~-1 ~71 gold_block 0  
fill ~51 ~-1 ~73 ~51 ~-1 ~74 gold_block 0 
setblock ~52 ~-1 ~5 wool 11  
fill ~52 ~-1 ~8 ~53 ~-1 ~8 wool 11 
setblock ~52 ~-1 ~10 gold_block 0 
setblock ~52 ~-1 ~12 gold_block 0  
fill ~52 ~-1 ~13 ~54 ~-1 ~13 wool 11  
fill ~52 ~-1 ~15 ~53 ~-1 ~15 gold_block 0 
setblock ~52 ~-1 ~16 wool 11  
fill ~52 ~-1 ~19 ~53 ~-1 ~19 gold_block 0  
fill ~52 ~-1 ~20 ~52 ~-1 ~19 gold_block 0 
setblock ~52 ~-1 ~22 gold_block 0  
fill ~52 ~-1 ~27 ~52 ~-1 ~28 wool 11  
fill ~52 ~-1 ~30 ~54 ~-1 ~30 wool 11 
setblock ~52 ~-1 ~31 gold_block 0  
fill ~52 ~-1 ~36 ~53 ~-1 ~36 gold_block 0  
fill ~52 ~-1 ~37 ~52 ~-1 ~38 wool 11 
setblock ~52 ~-1 ~47 gold_block 0 
setblock ~52 ~-1 ~49 gold_block 0 
setblock ~52 ~-1 ~53 wool 11 
setblock ~52 ~-1 ~55 wool 11 
setblock ~52 ~-1 ~57 gold_block 0  
fill ~52 ~-1 ~62 ~53 ~-1 ~62 gold_block 0  
fill ~52 ~-1 ~64 ~52 ~-1 ~65 gold_block 0  
fill ~52 ~-1 ~67 ~52 ~-1 ~68 wool 11  
fill ~52 ~-1 ~70 ~54 ~-1 ~70 gold_block 0  
fill ~52 ~-1 ~71 ~52 ~-1 ~73 wool 11  
fill ~52 ~-1 ~74 ~54 ~-1 ~74 glowstone 0  
fill ~52 ~-1 ~75 ~55 ~-1 ~75 dirt 0  
fill ~53 ~-1 ~3 ~53 ~0 ~3 gold_block 0  
fill ~53 ~-1 ~4 ~54 ~-1 ~4 wool 11  
fill ~53 ~-1 ~5 ~54 ~-1 ~5 gold_block 0  
fill ~53 ~-1 ~9 ~53 ~-1 ~10 wool 11  
fill ~53 ~-1 ~12 ~54 ~-1 ~12 wool 11  
fill ~53 ~-1 ~14 ~57 ~-1 ~14 gold_block 0 
setblock ~53 ~-1 ~16 gold_block 0  
fill ~53 ~-1 ~17 ~54 ~-1 ~17 wool 11  
fill ~53 ~-1 ~18 ~55 ~-1 ~18 gold_block 0 
setblock ~53 ~-1 ~20 wool 11  
fill ~53 ~-1 ~22 ~53 ~-1 ~23 wool 11  
fill ~53 ~-1 ~26 ~54 ~-1 ~26 wool 14  
fill ~53 ~-1 ~27 ~53 ~0 ~27 gold_block 0  
fill ~53 ~-1 ~28 ~54 ~-1 ~28 wool 11  
fill ~53 ~-1 ~29 ~53 ~-1 ~28 wool 11 
setblock ~53 ~-1 ~31 wool 11  
fill ~53 ~-1 ~32 ~54 ~-1 ~32 wool 14 
setblock ~53 ~-1 ~35 wool 11  
fill ~53 ~-1 ~37 ~54 ~-1 ~37 gold_block 0  
fill ~53 ~-1 ~38 ~53 ~-1 ~39 wool 11  
fill ~53 ~-1 ~40 ~54 ~-1 ~40 gold_block 0  
fill ~53 ~-1 ~45 ~54 ~-1 ~45 gold_block 0  
fill ~53 ~-1 ~46 ~53 ~-1 ~47 wool 11  
fill ~53 ~-1 ~49 ~55 ~-1 ~49 wool 11  
fill ~53 ~-1 ~53 ~54 ~-1 ~53 wool 14  
fill ~53 ~-1 ~55 ~54 ~-1 ~55 gold_block 0  
fill ~53 ~-1 ~56 ~53 ~-1 ~57 wool 11  
fill ~53 ~-1 ~59 ~54 ~-1 ~59 wool 14  
fill ~53 ~-1 ~63 ~54 ~-1 ~63 wool 11  
fill ~53 ~-1 ~64 ~53 ~-1 ~66 wool 11  
fill ~53 ~-1 ~67 ~55 ~-1 ~67 gold_block 0  
fill ~53 ~-1 ~68 ~53 ~-1 ~67 gold_block 0  
fill ~53 ~-1 ~69 ~55 ~-1 ~69 wool 11  
fill ~53 ~-1 ~71 ~53 ~-1 ~73 gold_block 0  
fill ~53 ~-1 ~76 ~77 ~-1 ~76 grass 0 
setblock ~54 ~-1 ~1 wool 11 
setblock ~54 ~-1 ~3 wool 11 
setblock ~54 ~-1 ~6 gold_block 0   
fill ~54 ~-1 ~8 ~54 ~-1 ~10 gold_block 0 
setblock ~54 ~-1 ~11 wool 11  
fill ~54 ~-1 ~15 ~56 ~-1 ~15 wool 11  
fill ~54 ~-1 ~16 ~54 ~-1 ~15 wool 11  
fill ~54 ~-1 ~19 ~55 ~-1 ~19 wool 11  
fill ~54 ~-1 ~20 ~56 ~-1 ~20 gold_block 0  
fill ~54 ~-1 ~21 ~56 ~-1 ~21 wool 11  
fill ~54 ~-1 ~22 ~57 ~-1 ~22 gold_block 0  
fill ~54 ~-1 ~23 ~54 ~-1 ~22 gold_block 0  
fill ~54 ~-1 ~25 ~58 ~-1 ~25 gold_block 0  
fill ~54 ~-1 ~27 ~55 ~-1 ~27 wool 14  
fill ~54 ~-1 ~29 ~54 ~0 ~29 gold_block 0  
fill ~54 ~-1 ~31 ~55 ~-1 ~31 wool 14 
setblock ~54 ~-1 ~33 gold_block 0 
setblock ~54 ~-1 ~35 gold_block 0 
setblock ~54 ~-1 ~36 wool 11 
setblock ~54 ~-1 ~38 gold_block 0 
setblock ~54 ~-1 ~39 wool 11 
setblock ~54 ~-1 ~46 gold_block 0  
fill ~54 ~-1 ~47 ~56 ~-1 ~47 wool 11  
fill ~54 ~-1 ~50 ~54 ~-1 ~51 wool 11 
setblock ~54 ~-1 ~52 gold_block 0  
fill ~54 ~-1 ~54 ~55 ~-1 ~54 wool 14  
fill ~54 ~-1 ~56 ~54 ~0 ~56 gold_block 0  
fill ~54 ~-1 ~57 ~54 ~0 ~57 gold_block 0  
fill ~54 ~-1 ~58 ~55 ~-1 ~58 wool 14 
setblock ~54 ~-1 ~60 gold_block 0 
setblock ~54 ~-1 ~62 wool 11  
fill ~54 ~-1 ~64 ~55 ~-1 ~64 gold_block 0  
fill ~54 ~-1 ~65 ~59 ~-1 ~65 wool 11 
setblock ~54 ~-1 ~68 wool 11  
fill ~54 ~-1 ~71 ~56 ~-1 ~71 wool 11  
fill ~54 ~-1 ~72 ~55 ~-1 ~72 gold_block 0 
setblock ~54 ~-1 ~73 wool 11  
fill ~55 ~-1 ~1 ~60 ~-1 ~1 dirt 0  
fill ~55 ~-1 ~3 ~55 ~0 ~3 gold_block 0  
fill ~55 ~-1 ~4 ~55 ~-1 ~3 gold_block 0  
fill ~55 ~-1 ~5 ~55 ~-1 ~8 wool 11 
setblock ~55 ~-1 ~9 gold_block 0  
fill ~55 ~-1 ~10 ~56 ~-1 ~10 wool 11  
fill ~55 ~-1 ~11 ~55 ~-1 ~14 gold_block 0  
fill ~55 ~-1 ~16 ~55 ~-1 ~18 gold_block 0  
fill ~55 ~-1 ~23 ~55 ~-1 ~24 wool 11  
fill ~55 ~-1 ~26 ~57 ~-1 ~26 gold_block 0  
fill ~55 ~-1 ~28 ~55 ~-1 ~31 wool 14 
setblock ~55 ~-1 ~32 gold_block 0  
fill ~55 ~-1 ~33 ~55 ~-1 ~35 wool 11  
fill ~55 ~-1 ~36 ~56 ~-1 ~36 gold_block 0  
fill ~55 ~-1 ~37 ~55 ~-1 ~38 wool 11  
fill ~55 ~-1 ~39 ~63 ~-1 ~39 glowstone 0  
fill ~55 ~-1 ~40 ~63 ~-1 ~40 log 0  
fill ~55 ~-1 ~45 ~63 ~-1 ~45 log 0  
fill ~55 ~-1 ~46 ~63 ~-1 ~46 glowstone 0  
fill ~55 ~-1 ~50 ~56 ~-1 ~50 gold_block 0  
fill ~55 ~-1 ~51 ~56 ~-1 ~51 gold_block 0  
fill ~55 ~-1 ~52 ~57 ~-1 ~52 wool 11  
fill ~55 ~-1 ~53 ~56 ~-1 ~53 gold_block 0  
fill ~55 ~-1 ~55 ~55 ~-1 ~58 wool 14  
fill ~55 ~-1 ~59 ~56 ~-1 ~59 gold_block 0 
setblock ~55 ~-1 ~60 wool 11  
fill ~55 ~-1 ~62 ~56 ~-1 ~62 gold_block 0  
fill ~55 ~-1 ~63 ~55 ~-1 ~61 gold_block 0  
fill ~55 ~-1 ~66 ~57 ~-1 ~66 gold_block 0  
fill ~55 ~-1 ~68 ~58 ~-1 ~68 gold_block 0 
setblock ~55 ~-1 ~70 wool 11  
fill ~55 ~-1 ~73 ~56 ~-1 ~73 glowstone 0  
fill ~55 ~-1 ~74 ~57 ~-1 ~74 dirt 0  
fill ~56 ~-1 ~3 ~57 ~-1 ~3 wool 11  
fill ~56 ~-1 ~4 ~56 ~-1 ~3 wool 11  
fill ~56 ~-1 ~5 ~57 ~-1 ~5 gold_block 0  
fill ~56 ~-1 ~6 ~56 ~-1 ~5 gold_block 0  
fill ~56 ~-1 ~7 ~57 ~-1 ~7 wool 11  
fill ~56 ~-1 ~8 ~59 ~-1 ~8 gold_block 0  
fill ~56 ~-1 ~9 ~58 ~-1 ~9 wool 11 
setblock ~56 ~-1 ~11 wool 11  
fill ~56 ~-1 ~12 ~59 ~-1 ~12 gold_block 0  
fill ~56 ~-1 ~13 ~58 ~-1 ~13 wool 11  
fill ~56 ~-1 ~16 ~58 ~-1 ~16 wool 11  
fill ~56 ~-1 ~17 ~57 ~-1 ~17 gold_block 0 
setblock ~56 ~-1 ~18 wool 11  
fill ~56 ~-1 ~19 ~59 ~-1 ~19 gold_block 0  
fill ~56 ~-1 ~23 ~59 ~-1 ~23 gold_block 0  
fill ~56 ~-1 ~24 ~58 ~-1 ~24 wool 11  
fill ~56 ~-1 ~27 ~59 ~-1 ~27 gold_block 0  
fill ~56 ~-1 ~28 ~56 ~-1 ~31 gold_block 0 
setblock ~56 ~-1 ~32 wool 11  
fill ~56 ~-1 ~33 ~56 ~-1 ~34 gold_block 0  
fill ~56 ~-1 ~35 ~57 ~-1 ~35 wool 11  
fill ~56 ~-1 ~37 ~58 ~-1 ~37 gold_block 0  
fill ~56 ~-1 ~38 ~56 ~-1 ~36 gold_block 0 
setblock ~56 ~-1 ~48 wool 11  
fill ~56 ~-1 ~49 ~59 ~-1 ~49 gold_block 0  
fill ~56 ~-1 ~54 ~58 ~-1 ~54 gold_block 0  
fill ~56 ~-1 ~55 ~56 ~-1 ~62 gold_block 0  
fill ~56 ~-1 ~63 ~57 ~-1 ~63 wool 11  
fill ~56 ~-1 ~64 ~56 ~-1 ~63 wool 11  
fill ~56 ~-1 ~67 ~58 ~-1 ~67 wool 11  
fill ~56 ~-1 ~69 ~56 ~-1 ~70 gold_block 0 
setblock ~56 ~-1 ~72 wool 11  
fill ~56 ~-1 ~75 ~77 ~-1 ~75 grass 0  
fill ~57 ~-1 ~4 ~59 ~-1 ~4 gold_block 0 
setblock ~57 ~-1 ~6 wool 11  
fill ~57 ~-1 ~10 ~57 ~-1 ~12 gold_block 0  
fill ~57 ~-1 ~15 ~59 ~-1 ~15 gold_block 0 
setblock ~57 ~-1 ~18 gold_block 0  
fill ~57 ~-1 ~20 ~58 ~-1 ~20 wool 11  
fill ~57 ~-1 ~21 ~57 ~0 ~21 gold_block 0 
setblock ~57 ~-1 ~28 wool 11  
fill ~57 ~-1 ~29 ~59 ~-1 ~29 gold_block 0  
fill ~57 ~-1 ~30 ~58 ~-1 ~30 wool 11  
fill ~57 ~-1 ~31 ~61 ~-1 ~31 gold_block 0  
fill ~57 ~-1 ~32 ~57 ~-1 ~31 gold_block 0 
setblock ~57 ~-1 ~33 wool 11  
fill ~57 ~-1 ~34 ~63 ~-1 ~34 gold_block 0  
fill ~57 ~-1 ~36 ~58 ~-1 ~36 wool 11 
setblock ~57 ~-1 ~38 wool 11  
fill ~57 ~-1 ~47 ~57 ~-1 ~49 gold_block 0  
fill ~57 ~-1 ~50 ~60 ~-1 ~50 wool 11  
fill ~57 ~-1 ~51 ~57 ~-1 ~50 wool 11 
setblock ~57 ~-1 ~53 wool 11  
fill ~57 ~-1 ~55 ~59 ~-1 ~55 wool 11  
fill ~57 ~-1 ~56 ~59 ~-1 ~56 gold_block 0  
fill ~57 ~-1 ~57 ~57 ~-1 ~59 wool 11  
fill ~57 ~-1 ~60 ~58 ~-1 ~60 gold_block 0  
fill ~57 ~-1 ~61 ~57 ~-1 ~63 wool 11  
fill ~57 ~-1 ~64 ~58 ~-1 ~64 gold_block 0  
fill ~57 ~-1 ~69 ~58 ~-1 ~69 wool 11  
fill ~57 ~-1 ~70 ~57 ~-1 ~71 gold_block 0 
setblock ~57 ~-1 ~72 glowstone 0  
fill ~57 ~-1 ~73 ~58 ~-1 ~73 dirt 0  
fill ~58 ~-1 ~3 ~58 ~0 ~3 gold_block 0 
setblock ~58 ~-1 ~5 wool 11  
fill ~58 ~-1 ~6 ~59 ~-1 ~6 gold_block 0  
fill ~58 ~-1 ~7 ~58 ~-1 ~6 gold_block 0  
fill ~58 ~-1 ~10 ~58 ~-1 ~11 wool 11 
setblock ~58 ~-1 ~14 wool 11  
fill ~58 ~-1 ~17 ~58 ~-1 ~18 wool 11  
fill ~58 ~-1 ~21 ~58 ~-1 ~22 wool 11  
fill ~58 ~-1 ~26 ~59 ~-1 ~26 wool 11 
setblock ~58 ~-1 ~28 gold_block 0  
fill ~58 ~-1 ~32 ~59 ~-1 ~32 wool 11 
setblock ~58 ~-1 ~33 gold_block 0 
setblock ~58 ~-1 ~35 gold_block 0 
setblock ~58 ~-1 ~38 gold_block 0  
fill ~58 ~-1 ~47 ~62 ~-1 ~47 wool 11  
fill ~58 ~-1 ~48 ~58 ~-1 ~47 wool 11  
fill ~58 ~-1 ~51 ~59 ~-1 ~51 gold_block 0  
fill ~58 ~-1 ~52 ~58 ~-1 ~54 gold_block 0  
fill ~58 ~-1 ~57 ~58 ~-1 ~64 gold_block 0 
setblock ~58 ~-1 ~66 wool 11  
fill ~58 ~-1 ~70 ~58 ~-1 ~71 glowstone 0  
fill ~58 ~-1 ~72 ~59 ~-1 ~72 dirt 0  
fill ~58 ~-1 ~74 ~77 ~-1 ~74 grass 0 
setblock ~59 ~-1 ~3 wool 11  
fill ~59 ~-1 ~5 ~59 ~0 ~5 gold_block 0 
setblock ~59 ~-1 ~7 wool 11  
fill ~59 ~-1 ~9 ~59 ~0 ~9 gold_block 0  
fill ~59 ~-1 ~10 ~59 ~0 ~10 gold_block 0 
setblock ~59 ~-1 ~11 wool 11  
fill ~59 ~-1 ~13 ~59 ~0 ~13 gold_block 0  
fill ~59 ~-1 ~14 ~59 ~0 ~14 gold_block 0  
fill ~59 ~-1 ~16 ~59 ~0 ~16 gold_block 0  
fill ~59 ~-1 ~17 ~59 ~0 ~17 gold_block 0 
setblock ~59 ~-1 ~18 wool 11  
fill ~59 ~-1 ~20 ~59 ~0 ~20 gold_block 0  
fill ~59 ~-1 ~21 ~59 ~0 ~21 gold_block 0  
fill ~59 ~-1 ~22 ~59 ~-1 ~19 gold_block 0 
setblock ~59 ~-1 ~24 gold_block 0 
setblock ~59 ~-1 ~25 wool 11 
setblock ~59 ~-1 ~28 wool 11 
setblock ~59 ~-1 ~30 gold_block 0  
fill ~59 ~-1 ~33 ~61 ~-1 ~33 wool 11 
setblock ~59 ~-1 ~35 wool 11  
fill ~59 ~-1 ~36 ~61 ~-1 ~36 gold_block 0  
fill ~59 ~-1 ~37 ~59 ~-1 ~38 wool 11  
fill ~59 ~-1 ~48 ~63 ~-1 ~48 gold_block 0  
fill ~59 ~-1 ~52 ~60 ~-1 ~52 wool 11  
fill ~59 ~-1 ~53 ~59 ~-1 ~55 wool 11  
fill ~59 ~-1 ~57 ~59 ~-1 ~61 wool 11 
setblock ~59 ~-1 ~62 gold_block 0  
fill ~59 ~-1 ~63 ~59 ~-1 ~65 wool 11 
setblock ~59 ~-1 ~66 gold_block 0  
fill ~59 ~-1 ~67 ~59 ~-1 ~69 glowstone 0  
fill ~59 ~-1 ~70 ~60 ~-1 ~70 dirt 0  
fill ~59 ~-1 ~71 ~59 ~-1 ~70 dirt 0  
fill ~59 ~-1 ~73 ~77 ~-1 ~73 grass 0  
fill ~60 ~-1 ~2 ~61 ~-1 ~2 dirt 0  
fill ~60 ~-1 ~3 ~60 ~-1 ~29 glowstone 0 
setblock ~60 ~-1 ~30 wool 11 
setblock ~60 ~-1 ~32 gold_block 0 
setblock ~60 ~-1 ~35 gold_block 0 
setblock ~60 ~-1 ~37 gold_block 0  
fill ~60 ~-1 ~38 ~61 ~-1 ~38 wool 11 
setblock ~60 ~-1 ~49 wool 11 
setblock ~60 ~-1 ~51 wool 11 
setblock ~60 ~-1 ~53 gold_block 0  
fill ~60 ~-1 ~54 ~61 ~-1 ~54 wool 11 
setblock ~60 ~-1 ~55 gold_block 0  
fill ~60 ~-1 ~56 ~60 ~-1 ~66 glowstone 0  
fill ~60 ~-1 ~67 ~61 ~-1 ~67 dirt 0 
setblock ~60 ~-1 ~69 dirt 0  
fill ~60 ~-1 ~71 ~77 ~-1 ~71 grass 0  
fill ~60 ~-1 ~72 ~77 ~-1 ~72 grass 0  
fill ~61 ~-1 ~1 ~77 ~-1 ~1 grass 0  
fill ~61 ~-1 ~3 ~61 ~-1 ~29 dirt 0 
setblock ~61 ~-1 ~30 glowstone 0  
fill ~61 ~-1 ~32 ~64 ~-1 ~32 wool 11  
fill ~61 ~-1 ~35 ~63 ~-1 ~35 wool 11 
setblock ~61 ~-1 ~37 wool 11  
fill ~61 ~-1 ~49 ~61 ~-1 ~52 gold_block 0  
fill ~61 ~-1 ~53 ~62 ~-1 ~53 wool 11 
setblock ~61 ~-1 ~55 glowstone 0  
fill ~61 ~-1 ~56 ~62 ~-1 ~56 dirt 0  
fill ~61 ~-1 ~57 ~61 ~-1 ~65 dirt 0  
fill ~61 ~-1 ~68 ~77 ~-1 ~68 grass 0  
fill ~61 ~-1 ~69 ~77 ~-1 ~69 grass 0  
fill ~61 ~-1 ~70 ~77 ~-1 ~70 grass 0  
fill ~62 ~-1 ~2 ~77 ~-1 ~2 grass 0  
fill ~62 ~-1 ~3 ~77 ~-1 ~3 grass 0  
fill ~62 ~-1 ~4 ~77 ~-1 ~4 grass 0  
fill ~62 ~-1 ~5 ~77 ~-1 ~5 grass 0  
fill ~62 ~-1 ~6 ~77 ~-1 ~6 grass 0  
fill ~62 ~-1 ~7 ~77 ~-1 ~7 grass 0  
fill ~62 ~-1 ~8 ~77 ~-1 ~8 grass 0  
fill ~62 ~-1 ~9 ~77 ~-1 ~9 grass 0  
fill ~62 ~-1 ~10 ~77 ~-1 ~10 grass 0  
fill ~62 ~-1 ~11 ~77 ~-1 ~11 grass 0  
fill ~62 ~-1 ~12 ~77 ~-1 ~12 grass 0  
fill ~62 ~-1 ~13 ~77 ~-1 ~13 grass 0  
fill ~62 ~-1 ~14 ~77 ~-1 ~14 grass 0  
fill ~62 ~-1 ~15 ~77 ~-1 ~15 grass 0  
fill ~62 ~-1 ~16 ~77 ~-1 ~16 grass 0  
fill ~62 ~-1 ~17 ~77 ~-1 ~17 grass 0  
fill ~62 ~-1 ~18 ~77 ~-1 ~18 grass 0  
fill ~62 ~-1 ~19 ~77 ~-1 ~19 grass 0  
fill ~62 ~-1 ~20 ~77 ~-1 ~20 grass 0  
fill ~62 ~-1 ~21 ~77 ~-1 ~21 grass 0  
fill ~62 ~-1 ~22 ~77 ~-1 ~22 grass 0  
fill ~62 ~-1 ~23 ~77 ~-1 ~23 grass 0  
fill ~62 ~-1 ~24 ~77 ~-1 ~24 grass 0  
fill ~62 ~-1 ~25 ~77 ~-1 ~25 grass 0  
fill ~62 ~-1 ~26 ~77 ~-1 ~26 grass 0  
fill ~62 ~-1 ~27 ~77 ~-1 ~27 grass 0  
fill ~62 ~-1 ~28 ~77 ~-1 ~28 grass 0  
fill ~62 ~-1 ~29 ~77 ~-1 ~29 grass 0  
fill ~62 ~-1 ~30 ~74 ~-1 ~30 dirt 0  
fill ~62 ~-1 ~31 ~73 ~-1 ~31 glowstone 0 
setblock ~62 ~-1 ~33 gold_block 0 
setblock ~62 ~-1 ~36 wool 11  
fill ~62 ~-1 ~37 ~63 ~-1 ~37 gold_block 0  
fill ~62 ~-1 ~38 ~62 ~-1 ~37 gold_block 0  
fill ~62 ~-1 ~49 ~62 ~-1 ~50 wool 11 
setblock ~62 ~-1 ~51 gold_block 0  
fill ~62 ~-1 ~52 ~64 ~-1 ~52 wool 11  
fill ~62 ~-1 ~54 ~73 ~-1 ~54 glowstone 0  
fill ~62 ~-1 ~55 ~72 ~-1 ~55 dirt 0  
fill ~62 ~-1 ~57 ~77 ~-1 ~57 grass 0  
fill ~62 ~-1 ~58 ~77 ~-1 ~58 grass 0  
fill ~62 ~-1 ~59 ~77 ~-1 ~59 grass 0  
fill ~62 ~-1 ~60 ~77 ~-1 ~60 grass 0  
fill ~62 ~-1 ~61 ~77 ~-1 ~61 grass 0  
fill ~62 ~-1 ~62 ~77 ~-1 ~62 grass 0  
fill ~62 ~-1 ~63 ~77 ~-1 ~63 grass 0  
fill ~62 ~-1 ~64 ~77 ~-1 ~64 grass 0  
fill ~62 ~-1 ~65 ~77 ~-1 ~65 grass 0  
fill ~62 ~-1 ~66 ~77 ~-1 ~66 grass 0  
fill ~62 ~-1 ~67 ~77 ~-1 ~67 grass 0 
setblock ~63 ~-1 ~33 wool 11  
fill ~63 ~-1 ~36 ~64 ~-1 ~36 gold_block 0  
fill ~63 ~-1 ~38 ~64 ~-1 ~38 wool 11 
setblock ~63 ~-1 ~47 gold_block 0  
fill ~63 ~-1 ~49 ~67 ~-1 ~49 gold_block 0  
fill ~63 ~-1 ~50 ~66 ~-1 ~50 wool 11  
fill ~63 ~-1 ~51 ~63 ~-1 ~50 wool 11 
setblock ~63 ~-1 ~53 gold_block 0  
fill ~63 ~-1 ~56 ~77 ~-1 ~56 grass 0  
fill ~64 ~-1 ~33 ~65 ~-1 ~33 gold_block 0  
fill ~64 ~-1 ~34 ~66 ~-1 ~34 wool 11 
setblock ~64 ~-1 ~35 gold_block 0  
fill ~64 ~-1 ~37 ~65 ~-1 ~37 wool 11  
fill ~64 ~-1 ~39 ~65 ~-1 ~39 gold_block 0  
fill ~64 ~-1 ~40 ~65 ~-1 ~40 gold_block 0  
fill ~64 ~-1 ~45 ~65 ~-1 ~45 gold_block 0  
fill ~64 ~-1 ~46 ~64 ~-1 ~45 gold_block 0  
fill ~64 ~-1 ~47 ~64 ~-1 ~48 wool 11  
fill ~64 ~-1 ~51 ~65 ~-1 ~51 gold_block 0  
fill ~64 ~-1 ~53 ~65 ~-1 ~53 wool 11 
setblock ~65 ~-1 ~32 gold_block 0  
fill ~65 ~-1 ~35 ~65 ~-1 ~37 wool 11  
fill ~65 ~-1 ~38 ~66 ~-1 ~38 gold_block 0 
setblock ~65 ~-1 ~46 wool 11  
fill ~65 ~-1 ~47 ~66 ~-1 ~47 gold_block 0  
fill ~65 ~-1 ~48 ~65 ~-1 ~47 gold_block 0  
fill ~65 ~-1 ~52 ~71 ~-1 ~52 gold_block 0  
fill ~66 ~-1 ~32 ~66 ~-1 ~34 wool 11  
fill ~66 ~-1 ~35 ~67 ~-1 ~35 gold_block 0  
fill ~66 ~-1 ~36 ~66 ~-1 ~38 gold_block 0  
fill ~66 ~-1 ~39 ~70 ~-1 ~39 glowstone 0  
fill ~66 ~-1 ~40 ~71 ~-1 ~40 log 0  
fill ~66 ~-1 ~45 ~71 ~-1 ~45 log 0  
fill ~66 ~-1 ~46 ~70 ~-1 ~46 glowstone 0 
setblock ~66 ~-1 ~48 wool 11 
setblock ~66 ~-1 ~51 wool 11 
setblock ~66 ~-1 ~53 gold_block 0  
fill ~67 ~-1 ~32 ~67 ~-1 ~35 gold_block 0  
fill ~67 ~-1 ~36 ~68 ~-1 ~36 wool 11  
fill ~67 ~-1 ~37 ~69 ~-1 ~37 gold_block 0 
setblock ~67 ~-1 ~38 wool 11 
setblock ~67 ~-1 ~47 wool 11  
fill ~67 ~-1 ~48 ~68 ~-1 ~48 gold_block 0  
fill ~67 ~-1 ~50 ~67 ~-1 ~52 gold_block 0 
setblock ~67 ~-1 ~53 wool 11 
setblock ~68 ~-1 ~32 wool 11  
fill ~68 ~-1 ~33 ~71 ~-1 ~33 gold_block 0  
fill ~68 ~-1 ~34 ~70 ~-1 ~34 wool 11  
fill ~68 ~-1 ~35 ~68 ~-1 ~34 wool 11  
fill ~68 ~-1 ~38 ~70 ~-1 ~38 gold_block 0 
setblock ~68 ~-1 ~47 gold_block 0  
fill ~68 ~-1 ~49 ~68 ~-1 ~51 wool 11 
setblock ~68 ~-1 ~53 gold_block 0 
setblock ~69 ~-1 ~32 gold_block 0  
fill ~69 ~-1 ~35 ~69 ~-1 ~38 gold_block 0  
fill ~69 ~-1 ~47 ~69 ~-1 ~48 wool 11  
fill ~69 ~-1 ~49 ~71 ~-1 ~49 gold_block 0  
fill ~69 ~-1 ~50 ~70 ~-1 ~50 wool 11 
setblock ~69 ~-1 ~51 gold_block 0  
fill ~69 ~-1 ~53 ~70 ~-1 ~53 wool 11 
setblock ~70 ~-1 ~32 wool 11  
fill ~70 ~-1 ~35 ~70 ~-1 ~37 wool 11 
setblock ~70 ~-1 ~47 gold_block 0 
setblock ~70 ~-1 ~48 wool 11 
setblock ~70 ~-1 ~51 wool 11 
setblock ~71 ~-1 ~32 gold_block 0  
fill ~71 ~-1 ~34 ~71 ~-1 ~35 gold_block 0  
fill ~71 ~-1 ~36 ~72 ~-1 ~36 wool 11 
setblock ~71 ~-1 ~37 gold_block 0 
setblock ~71 ~-1 ~38 glowstone 0  
fill ~71 ~-1 ~39 ~72 ~-1 ~39 log 0  
fill ~71 ~-1 ~46 ~72 ~-1 ~46 log 0 
setblock ~71 ~-1 ~47 glowstone 0 
setblock ~71 ~-1 ~48 gold_block 0  
fill ~71 ~-1 ~50 ~71 ~-1 ~53 gold_block 0  
fill ~72 ~-1 ~32 ~72 ~-1 ~34 wool 11  
fill ~72 ~-1 ~35 ~75 ~-1 ~35 gold_block 0 
setblock ~72 ~-1 ~37 glowstone 0  
fill ~72 ~-1 ~38 ~73 ~-1 ~38 log 0  
fill ~72 ~-1 ~40 ~73 ~-1 ~40 wool 14  
fill ~72 ~-1 ~45 ~73 ~-1 ~45 wool 14  
fill ~72 ~-1 ~47 ~73 ~-1 ~47 log 0 
setblock ~72 ~-1 ~48 glowstone 0  
fill ~72 ~-1 ~49 ~72 ~-1 ~52 wool 11  
fill ~72 ~-1 ~53 ~73 ~-1 ~53 gold_block 0 
setblock ~73 ~-1 ~32 gold_block 0  
fill ~73 ~-1 ~33 ~74 ~-1 ~33 wool 11 
setblock ~73 ~-1 ~34 gold_block 0  
fill ~73 ~-1 ~36 ~76 ~-1 ~36 glowstone 0  
fill ~73 ~-1 ~37 ~76 ~-1 ~37 log 0  
fill ~73 ~-1 ~39 ~74 ~-1 ~39 wool 14 
setblock ~73 ~-1 ~41 wool 11  
fill ~73 ~-1 ~42 ~73 ~0 ~42 gold_block 0  
fill ~73 ~-1 ~43 ~73 ~0 ~43 gold_block 0  
fill ~73 ~-1 ~44 ~73 ~0 ~44 gold_block 0  
fill ~73 ~-1 ~46 ~74 ~-1 ~46 wool 14  
fill ~73 ~-1 ~48 ~76 ~-1 ~48 log 0  
fill ~73 ~-1 ~49 ~76 ~-1 ~49 glowstone 0  
fill ~73 ~-1 ~50 ~74 ~-1 ~50 wool 11  
fill ~73 ~-1 ~51 ~73 ~-1 ~53 gold_block 0  
fill ~73 ~-1 ~55 ~73 ~0 ~55 gold_block 0  
fill ~74 ~-1 ~31 ~76 ~-1 ~31 dirt 0  
fill ~74 ~-1 ~32 ~75 ~-1 ~32 glowstone 0  
fill ~74 ~-1 ~34 ~75 ~-1 ~34 wool 11  
fill ~74 ~-1 ~38 ~76 ~-1 ~38 wool 14  
fill ~74 ~-1 ~40 ~74 ~0 ~40 gold_block 0  
fill ~74 ~-1 ~41 ~76 ~-1 ~41 lapis_block 0  
fill ~74 ~-1 ~42 ~76 ~-1 ~42 lapis_block 0  
fill ~74 ~-1 ~43 ~76 ~-1 ~43 lapis_block 0  
fill ~74 ~-1 ~44 ~76 ~-1 ~44 lapis_block 0  
fill ~74 ~-1 ~45 ~74 ~0 ~45 gold_block 0  
fill ~74 ~-1 ~47 ~76 ~-1 ~47 wool 14 
setblock ~74 ~-1 ~51 wool 11 
setblock ~74 ~-1 ~52 gold_block 0  
fill ~74 ~-1 ~53 ~75 ~-1 ~53 glowstone 0  
fill ~74 ~-1 ~54 ~76 ~-1 ~54 dirt 0  
fill ~74 ~-1 ~55 ~74 ~-1 ~54 dirt 0  
fill ~75 ~-1 ~30 ~77 ~-1 ~30 grass 0 
setblock ~75 ~-1 ~33 glowstone 0  
fill ~75 ~-1 ~39 ~76 ~-1 ~39 gold_block 0  
fill ~75 ~-1 ~40 ~76 ~-1 ~40 lapis_block 0  
fill ~75 ~-1 ~45 ~76 ~-1 ~45 lapis_block 0  
fill ~75 ~-1 ~46 ~76 ~-1 ~46 gold_block 0  
fill ~75 ~-1 ~50 ~75 ~-1 ~51 gold_block 0 
setblock ~75 ~-1 ~52 glowstone 0  
fill ~75 ~-1 ~55 ~77 ~-1 ~55 grass 0  
fill ~76 ~-1 ~32 ~76 ~-1 ~33 dirt 0  
fill ~76 ~-1 ~34 ~76 ~-1 ~36 glowstone 0  
fill ~76 ~-1 ~50 ~76 ~-1 ~51 glowstone 0  
fill ~76 ~-1 ~52 ~77 ~-1 ~52 dirt 0  
fill ~76 ~-1 ~53 ~76 ~-1 ~52 dirt 0  
fill ~77 ~-1 ~31 ~77 ~-1 ~31 grass 0  
fill ~77 ~-1 ~32 ~77 ~-1 ~32 grass 0  
fill ~77 ~-1 ~33 ~77 ~-1 ~52 dirt 0  
fill ~77 ~-1 ~53 ~77 ~-1 ~53 grass 0  
fill ~77 ~-1 ~54 ~77 ~-1 ~54 grass 0  
fill ~1 ~0 ~33 ~2 ~0 ~33 gold_block 0  
fill ~1 ~0 ~34 ~1 ~0 ~52 gold_block 0  
fill ~2 ~0 ~31 ~4 ~0 ~31 gold_block 0  
fill ~2 ~0 ~32 ~2 ~0 ~31 gold_block 0  
fill ~2 ~0 ~35 ~10 ~0 ~35 leaves 12  
fill ~2 ~0 ~38 ~7 ~0 ~38 gold_block 0  
fill ~2 ~0 ~39 ~6 ~0 ~39 stone_slab 2  
fill ~2 ~0 ~40 ~3 ~0 ~40 wool 15  
fill ~2 ~0 ~41 ~3 ~0 ~41 wool 15  
fill ~2 ~0 ~44 ~3 ~0 ~44 wool 15  
fill ~2 ~0 ~45 ~3 ~0 ~45 wool 15  
fill ~2 ~0 ~46 ~6 ~0 ~46 stone_slab 2  
fill ~2 ~0 ~47 ~7 ~0 ~47 gold_block 0  
fill ~2 ~0 ~50 ~10 ~0 ~50 leaves 4  
fill ~2 ~0 ~52 ~2 ~0 ~54 gold_block 0  
fill ~3 ~0 ~54 ~4 ~0 ~54 gold_block 0  
fill ~4 ~0 ~30 ~16 ~0 ~30 gold_block 0  
fill ~4 ~0 ~55 ~16 ~0 ~55 gold_block 0  
fill ~6 ~0 ~40 ~6 ~0 ~46 stone_slab 2  
fill ~7 ~0 ~39 ~7 ~0 ~47 gold_block 0  
fill ~10 ~0 ~31 ~10 ~0 ~32 leaves 12  
fill ~10 ~0 ~33 ~10 ~0 ~34 leaves 4  
fill ~10 ~0 ~36 ~10 ~0 ~37 leaves 4  
fill ~10 ~0 ~38 ~10 ~0 ~40 leaves 12  
fill ~10 ~0 ~45 ~14 ~0 ~45 leaves 4  
fill ~10 ~0 ~46 ~10 ~0 ~54 leaves 4  
fill ~11 ~0 ~40 ~14 ~0 ~40 leaves 4 
setblock ~12 ~0 ~32 oak_stairs 3 
setblock ~12 ~0 ~33 fence 0 
setblock ~12 ~0 ~34 oak_stairs 2 
setblock ~12 ~0 ~36 oak_stairs 3 
setblock ~12 ~0 ~37 fence 0 
setblock ~12 ~0 ~38 oak_stairs 2  
fill ~12 ~0 ~47 ~15 ~0 ~47 oak_stairs 3  
fill ~12 ~0 ~48 ~15 ~0 ~48 fence 0  
fill ~12 ~0 ~49 ~15 ~0 ~49 oak_stairs 2  
fill ~12 ~0 ~51 ~14 ~0 ~51 oak_stairs 3  
fill ~12 ~0 ~52 ~14 ~0 ~52 fence 0  
fill ~12 ~0 ~53 ~14 ~0 ~53 oak_stairs 2 
setblock ~14 ~0 ~32 oak_stairs 3 
setblock ~14 ~0 ~33 fence 0 
setblock ~14 ~0 ~34 oak_stairs 2 
setblock ~14 ~0 ~36 oak_stairs 3 
setblock ~14 ~0 ~37 fence 0 
setblock ~14 ~0 ~38 oak_stairs 2  
fill ~15 ~0 ~40 ~18 ~0 ~40 leaves 12  
fill ~15 ~0 ~45 ~19 ~0 ~45 leaves 12  
fill ~16 ~0 ~29 ~17 ~0 ~29 gold_block 0 
setblock ~16 ~0 ~32 oak_stairs 3 
setblock ~16 ~0 ~33 fence 0 
setblock ~16 ~0 ~34 oak_stairs 2 
setblock ~16 ~0 ~36 oak_stairs 3 
setblock ~16 ~0 ~37 fence 0 
setblock ~16 ~0 ~38 oak_stairs 2  
fill ~16 ~0 ~51 ~18 ~0 ~51 oak_stairs 3  
fill ~16 ~0 ~52 ~18 ~0 ~52 fence 0  
fill ~16 ~0 ~53 ~18 ~0 ~53 oak_stairs 2  
fill ~16 ~0 ~56 ~17 ~0 ~56 gold_block 0  
fill ~17 ~0 ~2 ~17 ~0 ~29 gold_block 0  
fill ~17 ~0 ~47 ~18 ~0 ~47 oak_stairs 3  
fill ~17 ~0 ~48 ~18 ~0 ~48 fence 0  
fill ~17 ~0 ~49 ~18 ~0 ~49 oak_stairs 2  
fill ~17 ~0 ~57 ~17 ~0 ~67 gold_block 0  
fill ~18 ~0 ~1 ~60 ~0 ~1 gold_block 0 
setblock ~18 ~0 ~32 oak_stairs 3 
setblock ~18 ~0 ~33 fence 0 
setblock ~18 ~0 ~34 oak_stairs 2 
setblock ~18 ~0 ~36 oak_stairs 3 
setblock ~18 ~0 ~37 fence 0 
setblock ~18 ~0 ~38 oak_stairs 2  
fill ~18 ~0 ~67 ~18 ~0 ~70 gold_block 0  
fill ~19 ~0 ~3 ~19 ~0 ~21 gold_block 0 
setblock ~19 ~0 ~40 leaves 4  
fill ~19 ~0 ~70 ~19 ~0 ~72 gold_block 0  
fill ~20 ~0 ~11 ~22 ~0 ~11 gold_block 0  
fill ~20 ~0 ~12 ~21 ~0 ~12 grass 0  
fill ~20 ~0 ~13 ~21 ~0 ~13 grass 0  
fill ~20 ~0 ~14 ~21 ~0 ~14 grass 0  
fill ~20 ~0 ~15 ~21 ~0 ~15 grass 0  
fill ~20 ~0 ~16 ~21 ~0 ~16 grass 0  
fill ~20 ~0 ~17 ~21 ~0 ~17 grass 0  
fill ~20 ~0 ~18 ~21 ~0 ~18 grass 0  
fill ~20 ~0 ~19 ~21 ~0 ~19 grass 0  
fill ~20 ~0 ~20 ~21 ~0 ~20 grass 0  
fill ~20 ~0 ~21 ~27 ~0 ~21 gold_block 0  
fill ~20 ~0 ~72 ~20 ~0 ~73 gold_block 0  
fill ~21 ~0 ~3 ~27 ~0 ~3 gold_block 0  
fill ~21 ~0 ~5 ~25 ~0 ~5 glass 0  
fill ~21 ~0 ~6 ~21 ~1 ~6 glass 0  
fill ~21 ~0 ~7 ~21 ~1 ~7 glass 0  
fill ~21 ~0 ~8 ~21 ~1 ~8 glass 0  
fill ~21 ~0 ~9 ~25 ~0 ~9 glass 0  
fill ~21 ~0 ~73 ~21 ~0 ~74 gold_block 0  
fill ~22 ~0 ~6 ~24 ~0 ~6 grass 0  
fill ~22 ~0 ~7 ~22 ~0 ~8 grass 0  
fill ~22 ~0 ~12 ~22 ~-1 ~12 gold_block 0  
fill ~22 ~0 ~13 ~22 ~0 ~11 gold_block 0  
fill ~22 ~0 ~15 ~22 ~0 ~21 gold_block 0  
fill ~22 ~0 ~40 ~25 ~0 ~40 leaves 12  
fill ~22 ~0 ~45 ~26 ~0 ~45 leaves 12  
fill ~22 ~0 ~74 ~23 ~0 ~74 gold_block 0 
setblock ~23 ~0 ~7 dirt 0  
fill ~23 ~0 ~8 ~24 ~0 ~8 grass 0  
fill ~23 ~0 ~62 ~26 ~0 ~62 gold_block 0  
fill ~23 ~0 ~63 ~23 ~0 ~65 gold_block 0  
fill ~23 ~0 ~68 ~26 ~0 ~68 gold_block 0 
setblock ~23 ~0 ~70 gold_block 0  
fill ~23 ~0 ~75 ~26 ~0 ~75 gold_block 0 
setblock ~24 ~0 ~7 grass 0  
fill ~24 ~0 ~11 ~24 ~0 ~21 gold_block 0  
fill ~24 ~0 ~29 ~24 ~-1 ~29 gold_block 0  
fill ~24 ~0 ~56 ~24 ~-1 ~56 gold_block 0  
fill ~24 ~0 ~63 ~25 ~0 ~63 wool 13  
fill ~24 ~0 ~64 ~25 ~0 ~64 wool 13  
fill ~24 ~0 ~65 ~26 ~0 ~65 gold_block 0  
fill ~24 ~0 ~69 ~25 ~0 ~69 wool 13  
fill ~24 ~0 ~70 ~25 ~0 ~70 wool 13 
setblock ~24 ~0 ~71 gold_block 0  
fill ~25 ~0 ~6 ~25 ~1 ~6 glass 0  
fill ~25 ~0 ~7 ~25 ~1 ~7 glass 0  
fill ~25 ~0 ~8 ~25 ~1 ~8 glass 0  
fill ~25 ~0 ~12 ~26 ~0 ~12 grass 0  
fill ~25 ~0 ~13 ~26 ~0 ~13 grass 0  
fill ~25 ~0 ~14 ~26 ~0 ~14 grass 0  
fill ~25 ~0 ~15 ~26 ~0 ~15 grass 0  
fill ~25 ~0 ~16 ~26 ~0 ~16 grass 0  
fill ~25 ~0 ~17 ~26 ~0 ~17 grass 0  
fill ~25 ~0 ~18 ~26 ~0 ~18 grass 0  
fill ~25 ~0 ~19 ~26 ~0 ~19 grass 0  
fill ~25 ~0 ~20 ~26 ~0 ~20 grass 0 
setblock ~25 ~0 ~31 gold_block 0 
setblock ~25 ~0 ~58 gold_block 0 
setblock ~26 ~0 ~11 gold_block 0 
setblock ~26 ~0 ~26 gold_block 0  
fill ~26 ~0 ~32 ~28 ~0 ~32 gold_block 0  
fill ~26 ~0 ~40 ~30 ~0 ~40 leaves 4 
setblock ~26 ~0 ~53 gold_block 0  
fill ~26 ~0 ~59 ~28 ~0 ~59 gold_block 0 
setblock ~26 ~0 ~63 gold_block 0  
fill ~26 ~0 ~70 ~26 ~0 ~71 gold_block 0  
fill ~26 ~0 ~76 ~36 ~0 ~76 gold_block 0  
fill ~27 ~0 ~4 ~27 ~0 ~21 gold_block 0  
fill ~27 ~0 ~29 ~27 ~1 ~29 gold_block 0 
setblock ~27 ~0 ~45 leaves 4  
fill ~27 ~0 ~56 ~27 ~1 ~56 gold_block 0 
setblock ~28 ~0 ~26 gold_block 0  
fill ~28 ~0 ~45 ~30 ~0 ~45 leaves 12 
setblock ~28 ~0 ~53 gold_block 0 
setblock ~29 ~0 ~9 oak_stairs 3 
setblock ~29 ~0 ~11 oak_stairs 2 
setblock ~29 ~0 ~14 oak_stairs 3 
setblock ~29 ~0 ~16 oak_stairs 2 
setblock ~29 ~0 ~19 oak_stairs 3 
setblock ~29 ~0 ~21 oak_stairs 2 
setblock ~29 ~0 ~27 gold_block 0 
setblock ~29 ~0 ~31 gold_block 0 
setblock ~29 ~0 ~54 gold_block 0 
setblock ~29 ~0 ~58 gold_block 0  
fill ~29 ~0 ~62 ~32 ~0 ~62 gold_block 0  
fill ~29 ~0 ~63 ~29 ~0 ~65 gold_block 0  
fill ~29 ~0 ~68 ~32 ~0 ~68 gold_block 0  
fill ~29 ~0 ~69 ~29 ~0 ~71 gold_block 0 
setblock ~30 ~0 ~28 gold_block 0  
fill ~30 ~0 ~38 ~30 ~0 ~40 leaves 4 
setblock ~30 ~0 ~46 leaves 12 
setblock ~30 ~0 ~47 leaves 4 
setblock ~30 ~0 ~55 gold_block 0  
fill ~30 ~0 ~63 ~31 ~0 ~63 wool 13  
fill ~30 ~0 ~64 ~31 ~0 ~64 wool 13  
fill ~30 ~0 ~65 ~32 ~0 ~65 gold_block 0  
fill ~30 ~0 ~69 ~31 ~0 ~69 wool 13  
fill ~30 ~0 ~70 ~31 ~0 ~70 wool 13 
setblock ~30 ~0 ~71 gold_block 0  
fill ~31 ~0 ~2 ~31 ~0 ~5 leaves 12  
fill ~31 ~0 ~36 ~31 ~0 ~37 leaves 4 
setblock ~31 ~0 ~48 leaves 4 
setblock ~31 ~0 ~49 leaves 12 
setblock ~32 ~0 ~6 leaves 12 
setblock ~32 ~0 ~35 leaves 4 
setblock ~32 ~0 ~50 leaves 12 
setblock ~32 ~0 ~63 gold_block 0  
fill ~32 ~0 ~69 ~32 ~0 ~71 gold_block 0 
setblock ~33 ~0 ~7 leaves 12 
setblock ~33 ~0 ~34 leaves 4 
setblock ~33 ~0 ~51 leaves 12  
fill ~34 ~0 ~2 ~34 ~0 ~3 leaves 12 
setblock ~34 ~0 ~8 leaves 12  
fill ~34 ~0 ~33 ~35 ~0 ~33 leaves 4  
fill ~34 ~0 ~40 ~34 ~0 ~45 stone_slab 0  
fill ~34 ~0 ~52 ~35 ~0 ~52 leaves 4 
setblock ~35 ~0 ~4 leaves 12 
setblock ~35 ~0 ~9 leaves 12  
fill ~35 ~0 ~11 ~35 ~0 ~12 oak_stairs 0  
fill ~35 ~0 ~14 ~35 ~0 ~15 oak_stairs 0  
fill ~35 ~0 ~20 ~35 ~0 ~21 oak_stairs 0  
fill ~35 ~0 ~23 ~35 ~0 ~24 oak_stairs 0  
fill ~35 ~0 ~26 ~35 ~0 ~27 oak_stairs 0  
fill ~35 ~0 ~29 ~35 ~0 ~30 oak_stairs 0 
setblock ~35 ~0 ~39 stone_slab 0 
setblock ~35 ~0 ~46 stone_slab 0 
setblock ~36 ~0 ~5 leaves 12 
setblock ~36 ~0 ~9 leaves 4  
fill ~36 ~0 ~10 ~36 ~0 ~16 leaves 12  
fill ~36 ~0 ~19 ~36 ~0 ~25 leaves 12 
setblock ~36 ~0 ~26 leaves 4  
fill ~36 ~0 ~27 ~36 ~0 ~32 leaves 12 
setblock ~36 ~0 ~38 stone_slab 0 
setblock ~36 ~0 ~42 diamond_block 0 
setblock ~36 ~0 ~47 stone_slab 0 
setblock ~36 ~0 ~53 leaves 4  
fill ~36 ~0 ~54 ~36 ~0 ~60 leaves 12  
fill ~36 ~0 ~63 ~36 ~0 ~66 leaves 12  
fill ~36 ~0 ~67 ~36 ~0 ~75 leaves 4  
fill ~36 ~0 ~77 ~36 ~3 ~77 gold_block 0  
fill ~37 ~0 ~6 ~41 ~0 ~6 leaves 12  
fill ~37 ~0 ~37 ~41 ~0 ~37 stone_slab 0 
setblock ~37 ~0 ~41 diamond_block 0  
fill ~37 ~0 ~43 ~37 ~1 ~43 diamond_block 0  
fill ~37 ~0 ~48 ~41 ~0 ~48 stone_slab 0 
setblock ~38 ~0 ~40 diamond_block 0  
fill ~38 ~0 ~42 ~42 ~0 ~42 diamond_block 0  
fill ~38 ~0 ~44 ~38 ~2 ~44 diamond_block 0 
setblock ~39 ~0 ~39 diamond_block 0  
fill ~39 ~0 ~41 ~39 ~3 ~41 diamond_block 0  
fill ~39 ~0 ~43 ~39 ~4 ~43 diamond_block 0  
fill ~39 ~0 ~45 ~39 ~1 ~45 diamond_block 0  
fill ~39 ~0 ~76 ~39 ~3 ~76 gold_block 0  
fill ~39 ~0 ~77 ~39 ~3 ~77 gold_block 0 
setblock ~40 ~0 ~40 diamond_block 0  
fill ~40 ~0 ~44 ~40 ~2 ~44 diamond_block 0 
setblock ~41 ~0 ~41 diamond_block 0  
fill ~41 ~0 ~43 ~41 ~1 ~43 diamond_block 0 
setblock ~42 ~0 ~5 leaves 12 
setblock ~42 ~0 ~9 leaves 4  
fill ~42 ~0 ~10 ~42 ~0 ~16 leaves 12  
fill ~42 ~0 ~19 ~42 ~0 ~22 leaves 12 
setblock ~42 ~0 ~23 leaves 4  
fill ~42 ~0 ~24 ~42 ~0 ~32 leaves 12 
setblock ~42 ~0 ~38 stone_slab 0 
setblock ~42 ~0 ~47 stone_slab 0  
fill ~42 ~0 ~53 ~42 ~0 ~60 leaves 12  
fill ~42 ~0 ~63 ~42 ~0 ~75 leaves 12  
fill ~42 ~0 ~76 ~52 ~0 ~76 gold_block 0  
fill ~42 ~0 ~77 ~42 ~3 ~77 gold_block 0 
setblock ~43 ~0 ~4 leaves 12 
setblock ~43 ~0 ~9 leaves 12  
fill ~43 ~0 ~11 ~43 ~0 ~12 oak_stairs 1  
fill ~43 ~0 ~14 ~43 ~0 ~15 oak_stairs 1  
fill ~43 ~0 ~20 ~43 ~0 ~21 oak_stairs 1  
fill ~43 ~0 ~23 ~43 ~0 ~24 oak_stairs 1  
fill ~43 ~0 ~26 ~43 ~0 ~27 oak_stairs 1  
fill ~43 ~0 ~29 ~43 ~0 ~30 oak_stairs 1  
fill ~43 ~0 ~33 ~44 ~0 ~33 leaves 12 
setblock ~43 ~0 ~39 stone_slab 0 
setblock ~43 ~0 ~46 stone_slab 0  
fill ~43 ~0 ~52 ~44 ~0 ~52 leaves 12  
fill ~44 ~0 ~2 ~44 ~0 ~3 leaves 12 
setblock ~44 ~0 ~8 leaves 12  
fill ~44 ~0 ~40 ~44 ~0 ~45 stone_slab 0 
setblock ~45 ~0 ~7 leaves 12 
setblock ~45 ~0 ~34 leaves 12 
setblock ~45 ~0 ~51 leaves 4  
fill ~45 ~0 ~63 ~49 ~0 ~63 gold_block 0  
fill ~45 ~0 ~64 ~45 ~0 ~66 gold_block 0  
fill ~45 ~0 ~69 ~49 ~0 ~69 gold_block 0  
fill ~45 ~0 ~70 ~45 ~0 ~72 gold_block 0 
setblock ~46 ~0 ~6 leaves 12 
setblock ~46 ~0 ~35 leaves 4 
setblock ~46 ~0 ~50 leaves 4  
fill ~46 ~0 ~64 ~48 ~0 ~64 wool 13  
fill ~46 ~0 ~65 ~48 ~0 ~65 wool 13  
fill ~46 ~0 ~66 ~49 ~0 ~66 gold_block 0  
fill ~46 ~0 ~70 ~48 ~0 ~70 wool 13  
fill ~46 ~0 ~71 ~48 ~0 ~71 wool 13  
fill ~46 ~0 ~72 ~49 ~0 ~72 gold_block 0  
fill ~47 ~0 ~2 ~47 ~0 ~5 leaves 12  
fill ~47 ~0 ~36 ~47 ~0 ~37 leaves 12  
fill ~47 ~0 ~48 ~47 ~0 ~49 leaves 12  
fill ~48 ~0 ~28 ~48 ~0 ~30 gold_block 0  
fill ~48 ~0 ~38 ~48 ~0 ~40 leaves 12  
fill ~48 ~0 ~45 ~52 ~0 ~45 leaves 12  
fill ~48 ~0 ~46 ~48 ~0 ~47 leaves 12  
fill ~48 ~0 ~56 ~48 ~-1 ~56 gold_block 0 
setblock ~49 ~0 ~9 oak_stairs 3 
setblock ~49 ~0 ~11 oak_stairs 2 
setblock ~49 ~0 ~14 oak_stairs 3 
setblock ~49 ~0 ~16 oak_stairs 2 
setblock ~49 ~0 ~19 oak_stairs 3 
setblock ~49 ~0 ~21 oak_stairs 2 
setblock ~49 ~0 ~27 gold_block 0 
setblock ~49 ~0 ~31 gold_block 0  
fill ~49 ~0 ~40 ~52 ~0 ~40 leaves 12 
setblock ~49 ~0 ~58 gold_block 0 
setblock ~49 ~0 ~64 gold_block 0  
fill ~49 ~0 ~70 ~49 ~0 ~72 gold_block 0  
fill ~50 ~0 ~26 ~52 ~0 ~26 gold_block 0  
fill ~50 ~0 ~32 ~52 ~0 ~32 gold_block 0 
setblock ~50 ~0 ~53 gold_block 0  
fill ~50 ~0 ~59 ~52 ~0 ~59 gold_block 0  
fill ~51 ~0 ~3 ~59 ~0 ~3 gold_block 0  
fill ~51 ~0 ~4 ~51 ~-1 ~4 gold_block 0  
fill ~51 ~0 ~5 ~51 ~0 ~21 gold_block 0  
fill ~51 ~0 ~29 ~51 ~1 ~29 gold_block 0  
fill ~51 ~0 ~56 ~51 ~1 ~56 gold_block 0  
fill ~52 ~0 ~11 ~54 ~0 ~11 gold_block 0  
fill ~52 ~0 ~12 ~53 ~0 ~12 grass 0  
fill ~52 ~0 ~13 ~53 ~0 ~13 grass 0  
fill ~52 ~0 ~14 ~53 ~0 ~14 grass 0  
fill ~52 ~0 ~15 ~53 ~0 ~15 grass 0  
fill ~52 ~0 ~16 ~53 ~0 ~16 grass 0  
fill ~52 ~0 ~17 ~53 ~0 ~17 grass 0  
fill ~52 ~0 ~18 ~53 ~0 ~18 grass 0  
fill ~52 ~0 ~19 ~53 ~0 ~19 grass 0  
fill ~52 ~0 ~20 ~53 ~0 ~20 grass 0  
fill ~52 ~0 ~21 ~59 ~0 ~21 gold_block 0 
setblock ~52 ~0 ~53 gold_block 0  
fill ~52 ~0 ~65 ~55 ~0 ~65 gold_block 0  
fill ~52 ~0 ~66 ~52 ~0 ~70 gold_block 0  
fill ~52 ~0 ~75 ~55 ~0 ~75 gold_block 0  
fill ~53 ~0 ~5 ~57 ~0 ~5 glass 0  
fill ~53 ~0 ~6 ~53 ~1 ~6 glass 0  
fill ~53 ~0 ~7 ~53 ~1 ~7 glass 0  
fill ~53 ~0 ~8 ~53 ~1 ~8 glass 0  
fill ~53 ~0 ~9 ~57 ~0 ~9 glass 0 
setblock ~53 ~0 ~31 gold_block 0 
setblock ~53 ~0 ~54 gold_block 0 
setblock ~53 ~0 ~58 gold_block 0  
fill ~53 ~0 ~66 ~54 ~0 ~66 wool 13  
fill ~53 ~0 ~67 ~54 ~0 ~67 wool 13  
fill ~53 ~0 ~68 ~54 ~0 ~68 wool 13  
fill ~53 ~0 ~69 ~54 ~0 ~69 wool 13  
fill ~53 ~0 ~70 ~55 ~0 ~70 gold_block 0  
fill ~54 ~0 ~6 ~56 ~0 ~6 grass 0  
fill ~54 ~0 ~7 ~54 ~0 ~8 grass 0  
fill ~54 ~0 ~12 ~54 ~0 ~21 gold_block 0 
setblock ~54 ~0 ~28 gold_block 0 
setblock ~54 ~0 ~30 gold_block 0 
setblock ~54 ~0 ~55 gold_block 0 
setblock ~55 ~0 ~7 dirt 0  
fill ~55 ~0 ~8 ~56 ~0 ~8 grass 0  
fill ~55 ~0 ~40 ~58 ~0 ~40 leaves 12  
fill ~55 ~0 ~45 ~58 ~0 ~45 leaves 12  
fill ~55 ~0 ~66 ~55 ~-1 ~66 gold_block 0  
fill ~55 ~0 ~67 ~55 ~0 ~70 gold_block 0  
fill ~55 ~0 ~74 ~57 ~0 ~74 gold_block 0 
setblock ~56 ~0 ~7 grass 0  
fill ~56 ~0 ~11 ~59 ~0 ~11 gold_block 0  
fill ~56 ~0 ~12 ~56 ~-1 ~12 gold_block 0  
fill ~56 ~0 ~13 ~56 ~0 ~21 gold_block 0  
fill ~57 ~0 ~6 ~57 ~1 ~6 glass 0  
fill ~57 ~0 ~7 ~57 ~1 ~7 glass 0  
fill ~57 ~0 ~8 ~57 ~1 ~8 glass 0  
fill ~57 ~0 ~12 ~58 ~0 ~12 grass 0  
fill ~57 ~0 ~13 ~58 ~0 ~13 grass 0  
fill ~57 ~0 ~14 ~58 ~0 ~14 grass 0  
fill ~57 ~0 ~15 ~58 ~0 ~15 grass 0  
fill ~57 ~0 ~16 ~58 ~0 ~16 grass 0  
fill ~57 ~0 ~17 ~58 ~0 ~17 grass 0  
fill ~57 ~0 ~18 ~58 ~0 ~18 grass 0  
fill ~57 ~0 ~19 ~58 ~0 ~19 grass 0  
fill ~57 ~0 ~20 ~58 ~0 ~20 grass 0  
fill ~57 ~0 ~73 ~58 ~0 ~73 gold_block 0  
fill ~58 ~0 ~72 ~59 ~0 ~72 gold_block 0 
setblock ~59 ~0 ~4 gold_block 0  
fill ~59 ~0 ~6 ~59 ~0 ~21 gold_block 0 
setblock ~59 ~0 ~40 leaves 4 
setblock ~59 ~0 ~45 leaves 4  
fill ~59 ~0 ~70 ~60 ~0 ~70 gold_block 0  
fill ~59 ~0 ~71 ~59 ~0 ~70 gold_block 0  
fill ~60 ~0 ~2 ~61 ~0 ~2 gold_block 0  
fill ~60 ~0 ~33 ~60 ~2 ~33 planks 0  
fill ~60 ~0 ~40 ~63 ~0 ~40 leaves 12  
fill ~60 ~0 ~45 ~63 ~0 ~45 leaves 12  
fill ~60 ~0 ~52 ~60 ~2 ~52 planks 0  
fill ~60 ~0 ~67 ~61 ~0 ~67 gold_block 0  
fill ~60 ~0 ~68 ~60 ~0 ~70 gold_block 0  
fill ~61 ~0 ~3 ~61 ~0 ~29 gold_block 0  
fill ~61 ~0 ~56 ~62 ~0 ~56 gold_block 0  
fill ~61 ~0 ~57 ~61 ~0 ~67 gold_block 0  
fill ~62 ~0 ~30 ~74 ~0 ~30 gold_block 0  
fill ~62 ~0 ~33 ~62 ~2 ~33 planks 0 
setblock ~62 ~0 ~36 noteblock 0 
setblock ~62 ~0 ~49 noteblock 0  
fill ~62 ~0 ~52 ~62 ~2 ~52 planks 0  
fill ~62 ~0 ~55 ~74 ~0 ~55 gold_block 0  
fill ~64 ~0 ~33 ~64 ~2 ~33 planks 0  
fill ~64 ~0 ~52 ~64 ~2 ~52 planks 0  
fill ~66 ~0 ~40 ~69 ~0 ~40 leaves 12  
fill ~66 ~0 ~45 ~69 ~0 ~45 leaves 12  
fill ~67 ~0 ~33 ~67 ~2 ~33 planks 0  
fill ~67 ~0 ~52 ~67 ~2 ~52 planks 0  
fill ~69 ~0 ~33 ~69 ~2 ~33 planks 0 
setblock ~69 ~0 ~36 noteblock 0 
setblock ~69 ~0 ~49 noteblock 0  
fill ~69 ~0 ~52 ~69 ~2 ~52 planks 0  
fill ~70 ~0 ~40 ~71 ~0 ~40 leaves 4  
fill ~70 ~0 ~45 ~71 ~0 ~45 leaves 4  
fill ~71 ~0 ~33 ~71 ~2 ~33 planks 0  
fill ~71 ~0 ~39 ~72 ~0 ~39 leaves 4  
fill ~71 ~0 ~46 ~72 ~0 ~46 leaves 4  
fill ~71 ~0 ~52 ~71 ~2 ~52 planks 0  
fill ~72 ~0 ~38 ~73 ~0 ~38 leaves 4  
fill ~72 ~0 ~47 ~73 ~0 ~47 leaves 4  
fill ~73 ~0 ~37 ~76 ~0 ~37 leaves 4 
setblock ~73 ~0 ~41 gold_block 0  
fill ~73 ~0 ~48 ~76 ~0 ~48 leaves 4  
fill ~74 ~0 ~31 ~76 ~0 ~31 gold_block 0  
fill ~74 ~0 ~54 ~76 ~0 ~54 gold_block 0  
fill ~75 ~0 ~39 ~77 ~0 ~39 gold_block 0  
fill ~75 ~0 ~46 ~77 ~0 ~46 gold_block 0  
fill ~76 ~0 ~32 ~76 ~0 ~33 gold_block 0  
fill ~76 ~0 ~52 ~77 ~0 ~52 gold_block 0  
fill ~76 ~0 ~53 ~76 ~0 ~52 gold_block 0  
fill ~77 ~0 ~33 ~77 ~0 ~52 gold_block 0  
fill ~1 ~1 ~33 ~2 ~1 ~33 lapis_block 0  
fill ~1 ~1 ~34 ~1 ~1 ~52 lapis_block 0  
fill ~2 ~1 ~31 ~4 ~1 ~31 lapis_block 0  
fill ~2 ~1 ~32 ~2 ~1 ~31 lapis_block 0  
fill ~2 ~1 ~38 ~6 ~1 ~38 stone_slab 2  
fill ~2 ~1 ~40 ~3 ~1 ~40 wool 15  
fill ~2 ~1 ~41 ~3 ~1 ~41 wool 15  
fill ~2 ~1 ~44 ~3 ~1 ~44 wool 15  
fill ~2 ~1 ~45 ~3 ~1 ~45 wool 15  
fill ~2 ~1 ~47 ~6 ~1 ~47 stone_slab 2  
fill ~2 ~1 ~52 ~2 ~1 ~54 lapis_block 0  
fill ~3 ~1 ~54 ~4 ~1 ~54 lapis_block 0  
fill ~4 ~1 ~30 ~16 ~1 ~30 lapis_block 0  
fill ~4 ~1 ~55 ~16 ~1 ~55 lapis_block 0  
fill ~7 ~1 ~38 ~7 ~2 ~38 glass 0  
fill ~7 ~1 ~39 ~7 ~1 ~46 stone_slab 2   
fill ~7 ~1 ~47 ~7 ~2 ~47 glass 0 
setblock ~12 ~1 ~33 wooden_pressure_plate 0 
setblock ~12 ~1 ~37 wooden_pressure_plate 0  
fill ~12 ~1 ~48 ~15 ~1 ~48 wooden_pressure_plate 0  
fill ~12 ~1 ~52 ~14 ~1 ~52 wooden_pressure_plate 0 
setblock ~14 ~1 ~33 wooden_pressure_plate 0 
setblock ~14 ~1 ~37 wooden_pressure_plate 0  
fill ~16 ~1 ~29 ~17 ~1 ~29 lapis_block 0 
setblock ~16 ~1 ~33 wooden_pressure_plate 0 
setblock ~16 ~1 ~37 wooden_pressure_plate 0  
fill ~16 ~1 ~52 ~18 ~1 ~52 wooden_pressure_plate 0  
fill ~16 ~1 ~56 ~17 ~1 ~56 lapis_block 0  
fill ~17 ~1 ~2 ~18 ~1 ~2 lapis_block 0  
fill ~17 ~1 ~3 ~17 ~1 ~29 lapis_block 0  
fill ~17 ~1 ~48 ~18 ~1 ~48 wooden_pressure_plate 0  
fill ~17 ~1 ~57 ~17 ~1 ~67 lapis_block 0  
fill ~18 ~1 ~1 ~60 ~1 ~1 lapis_block 0 
setblock ~18 ~1 ~33 wooden_pressure_plate 0 
setblock ~18 ~1 ~37 wooden_pressure_plate 0  
fill ~18 ~1 ~67 ~18 ~1 ~70 lapis_block 0  
fill ~19 ~1 ~70 ~19 ~1 ~72 lapis_block 0  
fill ~20 ~1 ~12 ~21 ~1 ~12 red_flower 0  
fill ~20 ~1 ~13 ~21 ~1 ~13 red_flower 0  
fill ~20 ~1 ~14 ~21 ~1 ~14 red_flower 0  
fill ~20 ~1 ~15 ~21 ~1 ~15 red_flower 0  
fill ~20 ~1 ~16 ~21 ~1 ~16 red_flower 0  
fill ~20 ~1 ~17 ~21 ~1 ~17 red_flower 0  
fill ~20 ~1 ~18 ~21 ~1 ~18 red_flower 0  
fill ~20 ~1 ~19 ~21 ~1 ~19 red_flower 0  
fill ~20 ~1 ~20 ~21 ~1 ~20 red_flower 0  
fill ~20 ~1 ~72 ~20 ~1 ~73 lapis_block 0  
fill ~21 ~1 ~5 ~25 ~1 ~5 glass 0  
fill ~21 ~1 ~9 ~25 ~1 ~9 glass 0  
fill ~21 ~1 ~73 ~21 ~1 ~74 lapis_block 0  
fill ~22 ~1 ~74 ~23 ~1 ~74 lapis_block 0  
fill ~23 ~1 ~7 ~23 ~6 ~7 log 1  
fill ~23 ~1 ~75 ~26 ~1 ~75 lapis_block 0  
fill ~24 ~1 ~28 ~24 ~2 ~28 glass 0  
fill ~24 ~1 ~30 ~24 ~2 ~30 glass 0  
fill ~24 ~1 ~55 ~24 ~2 ~55 glass 0  
fill ~24 ~1 ~57 ~24 ~2 ~57 glass 0  
fill ~25 ~1 ~12 ~26 ~1 ~12 red_flower 0  
fill ~25 ~1 ~13 ~26 ~1 ~13 red_flower 0  
fill ~25 ~1 ~14 ~26 ~1 ~14 red_flower 0  
fill ~25 ~1 ~15 ~26 ~1 ~15 red_flower 0  
fill ~25 ~1 ~16 ~26 ~1 ~16 red_flower 0  
fill ~25 ~1 ~17 ~26 ~1 ~17 red_flower 0  
fill ~25 ~1 ~18 ~26 ~1 ~18 red_flower 0  
fill ~25 ~1 ~19 ~26 ~1 ~19 red_flower 0  
fill ~25 ~1 ~20 ~26 ~1 ~20 red_flower 0  
fill ~25 ~1 ~27 ~25 ~2 ~27 glass 0  
fill ~25 ~1 ~31 ~25 ~2 ~31 glass 0  
fill ~25 ~1 ~54 ~25 ~2 ~54 glass 0  
fill ~25 ~1 ~58 ~25 ~2 ~58 glass 0  
fill ~26 ~1 ~26 ~26 ~2 ~26 glass 0  
fill ~26 ~1 ~32 ~26 ~2 ~32 glass 0  
fill ~26 ~1 ~53 ~26 ~2 ~53 glass 0  
fill ~26 ~1 ~59 ~26 ~2 ~59 glass 0  
fill ~26 ~1 ~76 ~34 ~1 ~76 lapis_block 0  
fill ~28 ~1 ~26 ~28 ~2 ~26 glass 0  
fill ~28 ~1 ~32 ~28 ~2 ~32 glass 0  
fill ~28 ~1 ~53 ~28 ~2 ~53 glass 0  
fill ~28 ~1 ~59 ~28 ~2 ~59 glass 0  
fill ~29 ~1 ~27 ~29 ~2 ~27 glass 0  
fill ~29 ~1 ~31 ~29 ~2 ~31 glass 0  
fill ~29 ~1 ~54 ~29 ~2 ~54 glass 0  
fill ~29 ~1 ~58 ~29 ~2 ~58 glass 0  
fill ~30 ~1 ~28 ~30 ~2 ~28 glass 0  
fill ~30 ~1 ~30 ~30 ~2 ~30 glass 0  
fill ~30 ~1 ~55 ~30 ~2 ~55 glass 0  
fill ~30 ~1 ~57 ~30 ~2 ~57 glass 0  
fill ~35 ~1 ~76 ~36 ~1 ~76 gold_block 0  
fill ~38 ~1 ~42 ~41 ~1 ~42 diamond_block 0  
fill ~42 ~1 ~76 ~43 ~1 ~76 gold_block 0  
fill ~44 ~1 ~76 ~52 ~1 ~76 lapis_block 0  
fill ~48 ~1 ~28 ~48 ~2 ~28 glass 0  
fill ~48 ~1 ~30 ~48 ~2 ~30 glass 0  
fill ~48 ~1 ~55 ~48 ~2 ~55 glass 0  
fill ~48 ~1 ~57 ~48 ~2 ~57 glass 0  
fill ~49 ~1 ~27 ~49 ~2 ~27 glass 0  
fill ~49 ~1 ~31 ~49 ~2 ~31 glass 0  
fill ~49 ~1 ~54 ~49 ~2 ~54 glass 0  
fill ~49 ~1 ~58 ~49 ~2 ~58 glass 0  
fill ~50 ~1 ~26 ~50 ~2 ~26 glass 0  
fill ~50 ~1 ~32 ~50 ~2 ~32 glass 0  
fill ~50 ~1 ~53 ~50 ~2 ~53 glass 0  
fill ~50 ~1 ~59 ~50 ~2 ~59 glass 0  
fill ~52 ~1 ~12 ~53 ~1 ~12 red_flower 0  
fill ~52 ~1 ~13 ~53 ~1 ~13 red_flower 0  
fill ~52 ~1 ~14 ~53 ~1 ~14 red_flower 0  
fill ~52 ~1 ~15 ~53 ~1 ~15 red_flower 0  
fill ~52 ~1 ~16 ~53 ~1 ~16 red_flower 0  
fill ~52 ~1 ~17 ~53 ~1 ~17 red_flower 0  
fill ~52 ~1 ~18 ~53 ~1 ~18 red_flower 0  
fill ~52 ~1 ~19 ~53 ~1 ~19 red_flower 0  
fill ~52 ~1 ~20 ~53 ~1 ~20 red_flower 0  
fill ~52 ~1 ~26 ~52 ~2 ~26 glass 0  
fill ~52 ~1 ~32 ~52 ~2 ~32 glass 0  
fill ~52 ~1 ~53 ~52 ~2 ~53 glass 0  
fill ~52 ~1 ~59 ~52 ~2 ~59 glass 0  
fill ~52 ~1 ~75 ~55 ~1 ~75 lapis_block 0  
fill ~53 ~1 ~5 ~57 ~1 ~5 glass 0  
fill ~53 ~1 ~9 ~57 ~1 ~9 glass 0  
fill ~53 ~1 ~27 ~53 ~2 ~27 glass 0  
fill ~53 ~1 ~31 ~53 ~2 ~31 glass 0  
fill ~53 ~1 ~54 ~53 ~2 ~54 glass 0  
fill ~53 ~1 ~58 ~53 ~2 ~58 glass 0  
fill ~54 ~1 ~28 ~54 ~2 ~28 glass 0  
fill ~54 ~1 ~30 ~54 ~2 ~30 glass 0  
fill ~54 ~1 ~55 ~54 ~2 ~55 glass 0  
fill ~54 ~1 ~57 ~54 ~2 ~57 glass 0  
fill ~55 ~1 ~7 ~55 ~6 ~7 log 1  
fill ~55 ~1 ~74 ~57 ~1 ~74 lapis_block 0  
fill ~57 ~1 ~12 ~58 ~1 ~12 red_flower 0  
fill ~57 ~1 ~13 ~58 ~1 ~13 red_flower 0  
fill ~57 ~1 ~14 ~58 ~1 ~14 red_flower 0  
fill ~57 ~1 ~15 ~58 ~1 ~15 red_flower 0  
