setblock ~18 ~33 ~49 chest 5 
setblock ~18 ~33 ~51 chest 5 
setblock ~18 ~33 ~53 chest 5 
setblock ~18 ~33 ~55 chest 5 
setblock ~9 ~4 ~73 chest 2 
setblock ~8 ~4 ~73 chest 2 
setblock ~12 ~3 ~72 chest 2 
setblock ~11 ~3 ~72 chest 2 
setblock ~11 ~3 ~64 chest 3 
setblock ~15 ~3 ~72 chest 2 
setblock ~15 ~4 ~73 chest 2 
setblock ~14 ~3 ~72 chest 2 
setblock ~12 ~4 ~73 chest 2 
setblock ~11 ~4 ~73 chest 2 
setblock ~9 ~3 ~72 chest 2 
setblock ~8 ~3 ~72 chest 2 
setblock ~14 ~4 ~73 chest 2 
setblock ~18 ~4 ~73 chest 2 
setblock ~17 ~4 ~73 chest 2 
setblock ~18 ~3 ~72 chest 2 
setblock ~17 ~3 ~72 chest 2 
setblock ~26 ~23 ~57 chest 2 
setblock ~25 ~23 ~57 chest 2 
setblock ~29 ~45 ~60 chest 3 
setblock ~20 ~4 ~73 chest 2 
setblock ~20 ~3 ~72 chest 2 
setblock ~24 ~16 ~70 chest 4 
setblock ~24 ~4 ~73 chest 2 
setblock ~21 ~4 ~73 chest 2 
setblock ~23 ~4 ~73 chest 2 
setblock ~21 ~3 ~72 chest 2 
setblock ~23 ~3 ~72 chest 2 
setblock ~24 ~3 ~72 chest 2 
fill ~3 ~0 ~36 ~5 ~0 ~36 stone 0  
fill ~3 ~0 ~44 ~5 ~0 ~44 stone 0  
fill ~3 ~0 ~52 ~4 ~0 ~52 double_stone_slab 0  
fill ~3 ~0 ~53 ~3 ~0 ~52 double_stone_slab 0  
fill ~3 ~0 ~54 ~3 ~21 ~54 stone 0  
fill ~3 ~0 ~55 ~3 ~21 ~55 stone 0  
fill ~3 ~0 ~56 ~3 ~12 ~56 stone 0  
fill ~3 ~0 ~57 ~3 ~21 ~57 stone 0  
fill ~3 ~0 ~58 ~3 ~21 ~58 stone 0  
fill ~3 ~0 ~59 ~3 ~21 ~59 stone 0  
fill ~3 ~0 ~60 ~3 ~21 ~60 stone 0  
fill ~3 ~0 ~61 ~3 ~21 ~61 stone 0  
fill ~3 ~0 ~62 ~3 ~12 ~62 stone 0  
fill ~3 ~0 ~63 ~3 ~21 ~63 stone 0  
fill ~3 ~0 ~64 ~3 ~21 ~64 stone 0  
fill ~3 ~0 ~65 ~3 ~0 ~66 double_stone_slab 0  
fill ~4 ~0 ~21 ~5 ~0 ~21 double_stone_slab 0  
fill ~4 ~0 ~22 ~4 ~0 ~21 double_stone_slab 0  
fill ~4 ~0 ~23 ~4 ~19 ~23 stone 0  
fill ~4 ~0 ~24 ~4 ~16 ~24 stone 0  
fill ~4 ~0 ~25 ~4 ~19 ~25 stone 0  
fill ~4 ~0 ~26 ~4 ~0 ~27 double_stone_slab 0  
fill ~4 ~0 ~53 ~37 ~0 ~53 dirt 0  
fill ~4 ~0 ~54 ~37 ~0 ~54 dirt 0  
fill ~4 ~0 ~55 ~36 ~0 ~55 dirt 0  
fill ~4 ~0 ~56 ~36 ~0 ~56 dirt 0  
fill ~4 ~0 ~57 ~36 ~0 ~57 dirt 0  
fill ~4 ~0 ~58 ~37 ~0 ~58 dirt 0  
fill ~4 ~0 ~59 ~37 ~0 ~59 dirt 0  
fill ~4 ~0 ~60 ~37 ~0 ~60 dirt 0  
fill ~4 ~0 ~61 ~38 ~0 ~61 dirt 0  
fill ~4 ~0 ~62 ~40 ~0 ~62 dirt 0  
fill ~4 ~0 ~63 ~38 ~0 ~63 dirt 0  
fill ~4 ~0 ~64 ~34 ~0 ~64 dirt 0  
fill ~4 ~0 ~65 ~29 ~0 ~65 dirt 0 
setblock ~4 ~0 ~66 double_stone_slab 0  
fill ~5 ~0 ~22 ~9 ~0 ~22 dirt 0  
fill ~5 ~0 ~23 ~9 ~0 ~23 dirt 0  
fill ~5 ~0 ~24 ~9 ~0 ~24 dirt 0  
fill ~5 ~0 ~25 ~9 ~0 ~25 dirt 0  
fill ~5 ~0 ~26 ~9 ~0 ~26 dirt 0 
setblock ~5 ~0 ~27 double_stone_slab 0  
fill ~5 ~0 ~52 ~5 ~21 ~52 stone 0  
fill ~5 ~0 ~66 ~5 ~21 ~66 stone 0  
fill ~6 ~0 ~21 ~8 ~0 ~21 stone 0  
fill ~6 ~0 ~27 ~8 ~0 ~27 stone 0  
fill ~6 ~0 ~28 ~6 ~12 ~28 stone 0  
fill ~6 ~0 ~29 ~6 ~14 ~29 double_stone_slab 0  
fill ~6 ~0 ~30 ~6 ~13 ~30 stone 0  
fill ~6 ~0 ~34 ~6 ~13 ~34 stone 0  
fill ~6 ~0 ~35 ~6 ~14 ~35 double_stone_slab 0  
fill ~6 ~0 ~36 ~38 ~0 ~36 dirt 0  
fill ~6 ~0 ~37 ~6 ~14 ~37 double_stone_slab 0  
fill ~6 ~0 ~38 ~6 ~13 ~38 stone 0  
fill ~6 ~0 ~42 ~6 ~13 ~42 stone 0  
fill ~6 ~0 ~43 ~6 ~14 ~43 double_stone_slab 0  
fill ~6 ~0 ~44 ~38 ~0 ~44 dirt 0  
fill ~6 ~0 ~45 ~6 ~14 ~45 double_stone_slab 0  
fill ~6 ~0 ~46 ~6 ~13 ~46 stone 0  
fill ~6 ~0 ~50 ~6 ~13 ~50 stone 0  
fill ~6 ~0 ~51 ~6 ~14 ~51 double_stone_slab 0  
fill ~6 ~0 ~52 ~38 ~0 ~52 dirt 0  
fill ~6 ~0 ~66 ~26 ~0 ~66 dirt 0  
fill ~6 ~0 ~67 ~6 ~13 ~67 stone 0  
fill ~6 ~0 ~68 ~6 ~13 ~68 stone 0  
fill ~6 ~0 ~69 ~6 ~13 ~69 stone 0  
fill ~6 ~0 ~70 ~6 ~13 ~70 stone 0  
fill ~6 ~0 ~71 ~6 ~13 ~71 stone 0  
fill ~6 ~0 ~72 ~6 ~13 ~72 stone 0  
fill ~6 ~0 ~73 ~6 ~13 ~73 stone 0  
fill ~7 ~0 ~28 ~37 ~0 ~28 dirt 0  
fill ~7 ~0 ~29 ~37 ~0 ~29 dirt 0  
fill ~7 ~0 ~30 ~37 ~0 ~30 dirt 0  
fill ~7 ~0 ~31 ~7 ~12 ~31 stone 0  
fill ~7 ~0 ~32 ~7 ~12 ~32 stone 0  
fill ~7 ~0 ~33 ~7 ~12 ~33 stone 0  
fill ~7 ~0 ~34 ~37 ~0 ~34 dirt 0  
fill ~7 ~0 ~35 ~37 ~0 ~35 dirt 0  
fill ~7 ~0 ~37 ~37 ~0 ~37 dirt 0  
fill ~7 ~0 ~38 ~37 ~0 ~38 dirt 0  
fill ~7 ~0 ~39 ~7 ~12 ~39 stone 0  
fill ~7 ~0 ~40 ~7 ~12 ~40 stone 0  
fill ~7 ~0 ~41 ~7 ~12 ~41 stone 0  
fill ~7 ~0 ~42 ~37 ~0 ~42 dirt 0  
fill ~7 ~0 ~43 ~37 ~0 ~43 dirt 0  
fill ~7 ~0 ~45 ~37 ~0 ~45 dirt 0  
fill ~7 ~0 ~46 ~37 ~0 ~46 dirt 0  
fill ~7 ~0 ~47 ~7 ~12 ~47 stone 0  
fill ~7 ~0 ~48 ~7 ~12 ~48 stone 0  
fill ~7 ~0 ~49 ~7 ~12 ~49 stone 0  
fill ~7 ~0 ~50 ~37 ~0 ~50 dirt 0  
fill ~7 ~0 ~51 ~37 ~0 ~51 dirt 0  
fill ~7 ~0 ~67 ~25 ~0 ~67 dirt 0  
fill ~7 ~0 ~68 ~25 ~0 ~68 dirt 0  
fill ~7 ~0 ~69 ~25 ~0 ~69 dirt 0  
fill ~7 ~0 ~70 ~25 ~0 ~70 dirt 0  
fill ~7 ~0 ~71 ~25 ~0 ~71 dirt 0  
fill ~7 ~0 ~72 ~25 ~0 ~72 dirt 0  
fill ~7 ~0 ~73 ~25 ~0 ~73 dirt 0  
fill ~7 ~0 ~74 ~25 ~0 ~74 stone 0  
fill ~8 ~0 ~31 ~36 ~0 ~31 dirt 0  
fill ~8 ~0 ~32 ~36 ~0 ~32 dirt 0  
fill ~8 ~0 ~33 ~36 ~0 ~33 dirt 0  
fill ~8 ~0 ~39 ~36 ~0 ~39 dirt 0  
fill ~8 ~0 ~40 ~36 ~0 ~40 dirt 0  
fill ~8 ~0 ~41 ~36 ~0 ~41 dirt 0  
fill ~8 ~0 ~47 ~36 ~0 ~47 dirt 0  
fill ~8 ~0 ~48 ~36 ~0 ~48 dirt 0  
fill ~8 ~0 ~49 ~36 ~0 ~49 dirt 0  
fill ~9 ~0 ~21 ~10 ~0 ~21 double_stone_slab 0  
fill ~9 ~0 ~27 ~10 ~0 ~27 double_stone_slab 0 
setblock ~10 ~0 ~22 double_stone_slab 0  
fill ~10 ~0 ~23 ~10 ~19 ~23 stone 0  
fill ~10 ~0 ~24 ~10 ~6 ~24 stone 0  
fill ~10 ~0 ~25 ~10 ~19 ~25 stone 0 
setblock ~10 ~0 ~26 double_stone_slab 0  
fill ~11 ~0 ~23 ~11 ~14 ~23 double_stone_slab 0  
fill ~11 ~0 ~24 ~12 ~0 ~24 dirt 0  
fill ~11 ~0 ~25 ~39 ~0 ~25 dirt 0  
fill ~11 ~0 ~26 ~39 ~0 ~26 dirt 0  
fill ~11 ~0 ~27 ~37 ~0 ~27 dirt 0  
fill ~12 ~0 ~23 ~12 ~13 ~23 stone 0  
fill ~13 ~0 ~24 ~15 ~0 ~24 stone 0  
fill ~14 ~0 ~0 ~28 ~0 ~0 dirt 0  
fill ~14 ~0 ~1 ~28 ~0 ~1 dirt 0  
fill ~14 ~0 ~2 ~19 ~0 ~2 dirt 0  
fill ~14 ~0 ~3 ~19 ~0 ~3 dirt 0  
fill ~14 ~0 ~4 ~19 ~0 ~4 dirt 0  
fill ~16 ~0 ~23 ~16 ~13 ~23 stone 0  
fill ~16 ~0 ~24 ~28 ~0 ~24 dirt 0  
fill ~17 ~0 ~5 ~19 ~0 ~5 dirt 0  
fill ~17 ~0 ~19 ~17 ~6 ~19 double_stone_slab 0  
fill ~17 ~0 ~20 ~17 ~6 ~20 stone 0  
fill ~17 ~0 ~21 ~17 ~6 ~21 stone 0  
fill ~17 ~0 ~22 ~17 ~6 ~22 double_stone_slab 0  
fill ~17 ~0 ~23 ~17 ~14 ~23 double_stone_slab 0  
fill ~18 ~0 ~18 ~18 ~6 ~18 stone 0  
fill ~18 ~0 ~19 ~26 ~0 ~19 dirt 0  
fill ~18 ~0 ~20 ~26 ~0 ~20 dirt 0  
fill ~18 ~0 ~21 ~26 ~0 ~21 dirt 0  
fill ~18 ~0 ~22 ~26 ~0 ~22 dirt 0  
fill ~18 ~0 ~23 ~18 ~12 ~23 stone 0  
fill ~19 ~0 ~17 ~19 ~6 ~17 stone 0  
fill ~19 ~0 ~18 ~25 ~0 ~18 dirt 0  
fill ~19 ~0 ~23 ~19 ~14 ~23 double_stone_slab 0 
setblock ~20 ~0 ~2 double_stone_slab 0  
fill ~20 ~0 ~3 ~24 ~0 ~3 stone 0  
fill ~20 ~0 ~4 ~20 ~0 ~5 stone 0  
fill ~20 ~0 ~13 ~20 ~7 ~13 stone 0  
fill ~20 ~0 ~14 ~20 ~6 ~14 stone 0  
fill ~20 ~0 ~15 ~24 ~0 ~15 stone 0  
fill ~20 ~0 ~16 ~20 ~6 ~16 double_stone_slab 0  
fill ~20 ~0 ~17 ~24 ~0 ~17 dirt 0 
setblock ~20 ~0 ~23 stone 0  
fill ~21 ~0 ~2 ~23 ~0 ~2 dirt 0  
fill ~21 ~0 ~4 ~23 ~0 ~4 dirt 0  
fill ~21 ~0 ~5 ~23 ~0 ~5 cobblestone 0  
fill ~21 ~0 ~13 ~23 ~0 ~13 cobblestone 0  
fill ~21 ~0 ~14 ~23 ~0 ~14 dirt 0  
fill ~21 ~0 ~16 ~23 ~0 ~16 dirt 0  
fill ~21 ~0 ~23 ~27 ~0 ~23 dirt 0 
setblock ~24 ~0 ~2 double_stone_slab 0  
fill ~24 ~0 ~4 ~24 ~0 ~5 stone 0  
fill ~24 ~0 ~13 ~24 ~7 ~13 stone 0  
fill ~24 ~0 ~14 ~24 ~6 ~14 stone 0  
fill ~24 ~0 ~16 ~24 ~6 ~16 double_stone_slab 0  
fill ~25 ~0 ~2 ~27 ~0 ~2 dirt 0  
fill ~25 ~0 ~3 ~27 ~0 ~3 dirt 0  
fill ~25 ~0 ~4 ~26 ~0 ~4 dirt 0  
fill ~25 ~0 ~17 ~25 ~6 ~17 stone 0  
fill ~26 ~0 ~18 ~26 ~6 ~18 stone 0  
fill ~26 ~0 ~67 ~26 ~13 ~67 stone 0  
fill ~26 ~0 ~68 ~26 ~13 ~68 stone 0  
fill ~26 ~0 ~69 ~26 ~13 ~69 stone 0  
fill ~26 ~0 ~70 ~26 ~13 ~70 stone 0  
fill ~26 ~0 ~71 ~26 ~13 ~71 stone 0  
fill ~26 ~0 ~72 ~26 ~13 ~72 stone 0  
fill ~26 ~0 ~73 ~26 ~13 ~73 stone 0  
fill ~27 ~0 ~19 ~27 ~6 ~19 double_stone_slab 0  
fill ~27 ~0 ~20 ~27 ~6 ~20 stone 0  
fill ~27 ~0 ~21 ~27 ~6 ~21 stone 0  
fill ~27 ~0 ~22 ~27 ~6 ~22 double_stone_slab 0  
fill ~27 ~0 ~66 ~27 ~21 ~66 stone 0  
fill ~28 ~0 ~23 ~28 ~13 ~23 stone 0  
fill ~28 ~0 ~66 ~29 ~0 ~66 double_stone_slab 0  
fill ~29 ~0 ~24 ~31 ~0 ~24 stone 0  
fill ~30 ~0 ~65 ~32 ~0 ~65 stone 0  
fill ~32 ~0 ~23 ~32 ~13 ~23 stone 0  
fill ~32 ~0 ~24 ~39 ~0 ~24 dirt 0  
fill ~33 ~0 ~23 ~33 ~14 ~23 double_stone_slab 0  
fill ~33 ~0 ~65 ~34 ~0 ~65 double_stone_slab 0  
fill ~34 ~0 ~21 ~35 ~0 ~21 double_stone_slab 0  
fill ~34 ~0 ~22 ~34 ~0 ~21 double_stone_slab 0  
fill ~34 ~0 ~23 ~34 ~5 ~23 stone 0  
fill ~35 ~0 ~22 ~39 ~0 ~22 dirt 0  
fill ~35 ~0 ~23 ~39 ~0 ~23 dirt 0  
fill ~35 ~0 ~64 ~35 ~14 ~64 double_stone_slab 0  
fill ~36 ~0 ~21 ~38 ~0 ~21 stone 0  
fill ~36 ~0 ~64 ~36 ~12 ~64 stone 0  
fill ~37 ~0 ~31 ~37 ~12 ~31 stone 0  
fill ~37 ~0 ~32 ~37 ~12 ~32 stone 0  
fill ~37 ~0 ~33 ~37 ~12 ~33 stone 0  
fill ~37 ~0 ~39 ~37 ~12 ~39 stone 0  
fill ~37 ~0 ~40 ~37 ~12 ~40 stone 0  
fill ~37 ~0 ~41 ~37 ~12 ~41 stone 0  
fill ~37 ~0 ~47 ~37 ~12 ~47 stone 0  
fill ~37 ~0 ~48 ~37 ~12 ~48 stone 0  
fill ~37 ~0 ~49 ~37 ~12 ~49 stone 0  
fill ~37 ~0 ~55 ~37 ~12 ~55 stone 0  
fill ~37 ~0 ~56 ~37 ~12 ~56 stone 0  
fill ~37 ~0 ~57 ~37 ~12 ~57 stone 0  
fill ~37 ~0 ~64 ~37 ~14 ~64 double_stone_slab 0  
fill ~38 ~0 ~27 ~38 ~19 ~27 stone 0  
fill ~38 ~0 ~28 ~38 ~12 ~28 stone 0  
fill ~38 ~0 ~29 ~38 ~14 ~29 double_stone_slab 0  
fill ~38 ~0 ~30 ~38 ~13 ~30 stone 0  
fill ~38 ~0 ~34 ~38 ~13 ~34 stone 0  
fill ~38 ~0 ~35 ~38 ~14 ~35 double_stone_slab 0  
fill ~38 ~0 ~37 ~38 ~14 ~37 double_stone_slab 0  
fill ~38 ~0 ~38 ~38 ~13 ~38 stone 0  
fill ~38 ~0 ~42 ~38 ~13 ~42 stone 0  
fill ~38 ~0 ~43 ~38 ~14 ~43 double_stone_slab 0  
fill ~38 ~0 ~45 ~38 ~14 ~45 double_stone_slab 0  
fill ~38 ~0 ~46 ~38 ~13 ~46 stone 0  
fill ~38 ~0 ~50 ~38 ~13 ~50 stone 0  
fill ~38 ~0 ~51 ~38 ~14 ~51 double_stone_slab 0  
fill ~38 ~0 ~53 ~38 ~14 ~53 double_stone_slab 0  
fill ~38 ~0 ~54 ~38 ~13 ~54 stone 0  
fill ~38 ~0 ~58 ~38 ~13 ~58 stone 0  
fill ~38 ~0 ~59 ~38 ~14 ~59 double_stone_slab 0  
fill ~38 ~0 ~60 ~38 ~13 ~60 stone 0  
fill ~38 ~0 ~64 ~38 ~13 ~64 stone 0  
fill ~39 ~0 ~21 ~40 ~0 ~21 double_stone_slab 0  
fill ~39 ~0 ~27 ~40 ~0 ~27 double_stone_slab 0  
fill ~39 ~0 ~36 ~41 ~0 ~36 stone 0  
fill ~39 ~0 ~44 ~41 ~0 ~44 stone 0  
fill ~39 ~0 ~52 ~41 ~0 ~52 stone 0  
fill ~39 ~0 ~61 ~39 ~14 ~61 double_stone_slab 0  
fill ~39 ~0 ~63 ~41 ~0 ~63 stone 0 
setblock ~40 ~0 ~22 double_stone_slab 0  
fill ~40 ~0 ~23 ~40 ~19 ~23 stone 0  
fill ~40 ~0 ~24 ~40 ~16 ~24 stone 0  
fill ~40 ~0 ~25 ~40 ~19 ~25 stone 0 
setblock ~40 ~0 ~26 double_stone_slab 0  
fill ~40 ~0 ~61 ~40 ~13 ~61 stone 0  
fill ~41 ~0 ~62 ~44 ~0 ~62 stone 0  
fill ~42 ~0 ~63 ~45 ~0 ~63 dirt 0  
fill ~42 ~0 ~64 ~42 ~13 ~64 stone 0  
fill ~43 ~0 ~64 ~43 ~14 ~64 double_stone_slab 0  
fill ~44 ~0 ~61 ~44 ~13 ~61 stone 0  
fill ~44 ~0 ~64 ~44 ~12 ~64 stone 0  
fill ~45 ~0 ~61 ~45 ~14 ~61 double_stone_slab 0 
setblock ~45 ~0 ~62 dirt 0  
fill ~45 ~0 ~64 ~46 ~0 ~64 double_stone_slab 0  
fill ~46 ~0 ~59 ~47 ~0 ~59 double_stone_slab 0  
fill ~46 ~0 ~60 ~46 ~0 ~59 double_stone_slab 0  
fill ~46 ~0 ~61 ~46 ~0 ~63 stone 0  
fill ~46 ~0 ~65 ~47 ~0 ~65 double_stone_slab 0  
fill ~47 ~0 ~60 ~51 ~0 ~60 dirt 0  
fill ~47 ~0 ~61 ~51 ~0 ~61 dirt 0  
fill ~47 ~0 ~62 ~51 ~0 ~62 dirt 0  
fill ~47 ~0 ~63 ~51 ~0 ~63 dirt 0  
fill ~47 ~0 ~64 ~51 ~0 ~64 dirt 0  
fill ~48 ~0 ~59 ~50 ~0 ~59 stone 0  
fill ~48 ~0 ~65 ~50 ~0 ~65 stone 0  
fill ~51 ~0 ~59 ~52 ~0 ~59 double_stone_slab 0  
fill ~51 ~0 ~65 ~52 ~0 ~65 double_stone_slab 0 
setblock ~52 ~0 ~60 double_stone_slab 0  
fill ~52 ~0 ~61 ~52 ~37 ~61 stone 0  
fill ~52 ~0 ~62 ~52 ~24 ~62 stone 0  
fill ~52 ~0 ~63 ~52 ~37 ~63 stone 0 
setblock ~52 ~0 ~64 double_stone_slab 0  
fill ~3 ~1 ~36 ~5 ~1 ~36 stone 0  
fill ~3 ~1 ~44 ~5 ~1 ~44 stone 0  
fill ~3 ~1 ~52 ~3 ~22 ~52 double_stone_slab 0 
setblock ~3 ~1 ~53 stone 0 
setblock ~3 ~1 ~65 stone 0  
fill ~3 ~1 ~66 ~3 ~22 ~66 double_stone_slab 0  
fill ~4 ~1 ~21 ~4 ~20 ~21 double_stone_slab 0 
setblock ~4 ~1 ~22 stone 0 
setblock ~4 ~1 ~26 stone 0  
fill ~4 ~1 ~27 ~4 ~20 ~27 double_stone_slab 0 
setblock ~4 ~1 ~52 stone 0  
fill ~4 ~1 ~53 ~14 ~1 ~53 dirt 0  
fill ~4 ~1 ~54 ~15 ~1 ~54 dirt 0  
fill ~4 ~1 ~55 ~16 ~1 ~55 dirt 0  
fill ~4 ~1 ~56 ~31 ~1 ~56 dirt 0  
fill ~4 ~1 ~57 ~27 ~1 ~57 dirt 0  
fill ~4 ~1 ~58 ~28 ~1 ~58 dirt 0  
fill ~4 ~1 ~59 ~29 ~1 ~59 dirt 0  
fill ~4 ~1 ~60 ~29 ~1 ~60 dirt 0  
fill ~4 ~1 ~61 ~29 ~1 ~61 dirt 0  
fill ~4 ~1 ~62 ~29 ~1 ~62 dirt 0  
fill ~4 ~1 ~63 ~29 ~1 ~63 dirt 0  
fill ~4 ~1 ~64 ~6 ~1 ~64 dirt 0  
fill ~4 ~1 ~65 ~6 ~1 ~65 dirt 0 
setblock ~4 ~1 ~66 stone 0  
fill ~5 ~1 ~21 ~9 ~1 ~21 stone 0  
fill ~5 ~1 ~22 ~9 ~1 ~22 dirt 0  
fill ~5 ~1 ~23 ~9 ~1 ~23 dirt 0  
fill ~5 ~1 ~24 ~9 ~1 ~24 dirt 0  
fill ~5 ~1 ~25 ~9 ~1 ~25 dirt 0  
fill ~5 ~1 ~26 ~9 ~1 ~26 dirt 0  
fill ~5 ~1 ~27 ~9 ~1 ~27 stone 0  
fill ~6 ~1 ~36 ~38 ~1 ~36 dirt 0  
fill ~6 ~1 ~44 ~7 ~1 ~44 sand 0  
fill ~6 ~1 ~52 ~14 ~1 ~52 dirt 0  
fill ~6 ~1 ~66 ~26 ~1 ~66 dirt 0  
fill ~7 ~1 ~28 ~13 ~1 ~28 dirt 0  
fill ~7 ~1 ~29 ~14 ~1 ~29 dirt 0  
fill ~7 ~1 ~30 ~8 ~1 ~30 sand 0  
fill ~7 ~1 ~34 ~7 ~2 ~34 sand 0  
fill ~7 ~1 ~35 ~37 ~1 ~35 dirt 0  
fill ~7 ~1 ~37 ~37 ~1 ~37 dirt 0  
fill ~7 ~1 ~38 ~10 ~1 ~38 dirt 0  
fill ~7 ~1 ~42 ~9 ~1 ~42 sand 0  
fill ~7 ~1 ~43 ~9 ~1 ~43 sand 0  
fill ~7 ~1 ~45 ~9 ~1 ~45 sand 0  
fill ~7 ~1 ~46 ~9 ~1 ~46 sand 0  
fill ~7 ~1 ~50 ~15 ~1 ~50 dirt 0  
fill ~7 ~1 ~51 ~14 ~1 ~51 dirt 0  
fill ~7 ~1 ~64 ~8 ~1 ~64 stone 0  
fill ~7 ~1 ~65 ~8 ~1 ~65 stone 0  
fill ~7 ~1 ~67 ~25 ~1 ~67 dirt 0  
fill ~7 ~1 ~68 ~25 ~1 ~68 dirt 0  
fill ~7 ~1 ~69 ~25 ~1 ~69 dirt 0  
fill ~7 ~1 ~70 ~25 ~1 ~70 dirt 0  
fill ~7 ~1 ~71 ~25 ~1 ~71 dirt 0  
fill ~7 ~1 ~72 ~25 ~1 ~72 dirt 0  
fill ~7 ~1 ~73 ~25 ~1 ~73 dirt 0  
fill ~7 ~1 ~74 ~25 ~1 ~74 stone 0  
fill ~8 ~1 ~31 ~36 ~1 ~31 dirt 0  
fill ~8 ~1 ~32 ~8 ~2 ~32 sand 0  
fill ~8 ~1 ~33 ~17 ~1 ~33 dirt 0  
fill ~8 ~1 ~34 ~37 ~1 ~34 dirt 0  
fill ~8 ~1 ~39 ~10 ~1 ~39 dirt 0  
fill ~8 ~1 ~40 ~8 ~2 ~40 sand 0  
fill ~8 ~1 ~41 ~9 ~1 ~41 sand 0 
setblock ~8 ~1 ~44 cobblestone 0  
fill ~8 ~1 ~47 ~9 ~1 ~47 sand 0  
fill ~8 ~1 ~48 ~8 ~2 ~48 sand 0  
fill ~8 ~1 ~49 ~15 ~1 ~49 dirt 0  
fill ~9 ~1 ~30 ~17 ~1 ~30 dirt 0  
fill ~9 ~1 ~32 ~36 ~1 ~32 dirt 0  
fill ~9 ~1 ~40 ~10 ~1 ~40 dirt 0  
fill ~9 ~1 ~44 ~12 ~1 ~44 redstone_wire 0  
fill ~9 ~1 ~48 ~16 ~1 ~48 dirt 0  
fill ~9 ~1 ~64 ~34 ~1 ~64 dirt 0  
fill ~9 ~1 ~65 ~28 ~1 ~65 dirt 0  
fill ~10 ~1 ~21 ~10 ~20 ~21 double_stone_slab 0 
setblock ~10 ~1 ~22 stone 0 
setblock ~10 ~1 ~26 stone 0  
fill ~10 ~1 ~27 ~10 ~20 ~27 double_stone_slab 0  
fill ~10 ~1 ~41 ~10 ~1 ~43 dirt 0  
fill ~10 ~1 ~45 ~14 ~1 ~45 dirt 0  
fill ~10 ~1 ~46 ~15 ~1 ~46 dirt 0  
fill ~10 ~1 ~47 ~16 ~1 ~47 dirt 0  
fill ~11 ~1 ~24 ~12 ~1 ~24 dirt 0  
fill ~11 ~1 ~25 ~17 ~1 ~25 dirt 0  
fill ~11 ~1 ~26 ~13 ~1 ~26 dirt 0  
fill ~11 ~1 ~27 ~13 ~1 ~27 dirt 0 
setblock ~11 ~1 ~38 cobblestone 0  
fill ~11 ~1 ~39 ~11 ~1 ~41 redstone_wire 0 
setblock ~11 ~1 ~42 unpowered_repeater 6 
setblock ~11 ~1 ~43 redstone_wire 0  
fill ~12 ~1 ~38 ~32 ~1 ~38 dirt 0  
fill ~12 ~1 ~39 ~29 ~1 ~39 dirt 0  
fill ~12 ~1 ~40 ~28 ~1 ~40 dirt 0  
fill ~12 ~1 ~41 ~14 ~1 ~41 dirt 0  
fill ~12 ~1 ~42 ~15 ~1 ~42 dirt 0  
fill ~12 ~1 ~43 ~14 ~1 ~43 dirt 0  
fill ~13 ~1 ~24 ~15 ~1 ~24 stone 0 
setblock ~13 ~1 ~44 cobblestone 0  
fill ~14 ~1 ~0 ~28 ~1 ~0 dirt 0  
fill ~14 ~1 ~1 ~20 ~1 ~1 dirt 0  
fill ~14 ~1 ~2 ~20 ~1 ~2 dirt 0  
fill ~14 ~1 ~3 ~15 ~1 ~3 dirt 0  
fill ~14 ~1 ~4 ~20 ~1 ~4 sand 0  
fill ~14 ~1 ~26 ~24 ~1 ~26 sand 0  
fill ~14 ~1 ~27 ~24 ~1 ~27 sand 0  
fill ~14 ~1 ~28 ~24 ~1 ~28 sand 0 
setblock ~14 ~1 ~44 dirt 0  
fill ~15 ~1 ~29 ~21 ~1 ~29 sand 0 
setblock ~15 ~1 ~41 grass 0 
setblock ~15 ~1 ~43 grass 0  
fill ~15 ~1 ~44 ~17 ~1 ~44 cobblestone 0 
setblock ~15 ~1 ~45 grass 0  
fill ~15 ~1 ~51 ~16 ~1 ~51 grass 0  
fill ~15 ~1 ~52 ~17 ~1 ~52 cobblestone 0 
setblock ~15 ~1 ~53 grass 0  
fill ~16 ~1 ~3 ~17 ~1 ~3 sand 0  
fill ~16 ~1 ~24 ~18 ~1 ~24 dirt 0 
setblock ~16 ~1 ~41 dirt 0 
setblock ~16 ~1 ~42 grass 0  
fill ~16 ~1 ~43 ~28 ~1 ~43 cobblestone 0 
setblock ~16 ~1 ~45 dirt 0 
setblock ~16 ~1 ~46 grass 0  
fill ~16 ~1 ~49 ~16 ~1 ~51 grass 0  
fill ~16 ~1 ~53 ~28 ~1 ~53 cobblestone 0 
setblock ~16 ~1 ~54 grass 0  
fill ~17 ~1 ~5 ~19 ~1 ~5 sand 0 
setblock ~17 ~1 ~41 grass 0  
fill ~17 ~1 ~42 ~19 ~1 ~42 cobblestone 0  
fill ~17 ~1 ~45 ~17 ~1 ~54 cobblestone 0 
setblock ~17 ~1 ~55 grass 0  
fill ~18 ~1 ~3 ~20 ~1 ~3 dirt 0  
fill ~18 ~1 ~19 ~26 ~1 ~19 dirt 0  
fill ~18 ~1 ~20 ~26 ~1 ~20 dirt 0  
fill ~18 ~1 ~21 ~19 ~1 ~21 dirt 0  
fill ~18 ~1 ~22 ~19 ~1 ~22 dirt 0  
fill ~18 ~1 ~25 ~25 ~1 ~25 sand 0  
fill ~18 ~1 ~30 ~18 ~2 ~30 sand 0 
setblock ~18 ~1 ~33 stone 0  
fill ~18 ~1 ~41 ~19 ~1 ~41 cobblestone 0  
fill ~18 ~1 ~44 ~21 ~1 ~44 stone 0  
fill ~18 ~1 ~45 ~18 ~1 ~52 stone 0  
fill ~18 ~1 ~54 ~27 ~1 ~54 cobblestone 0  
fill ~18 ~1 ~55 ~26 ~1 ~55 cobblestone 0  
fill ~19 ~1 ~18 ~25 ~1 ~18 dirt 0  
fill ~19 ~1 ~24 ~24 ~1 ~24 sand 0  
fill ~19 ~1 ~30 ~35 ~1 ~30 dirt 0  
fill ~19 ~1 ~33 ~36 ~1 ~33 dirt 0  
fill ~19 ~1 ~52 ~26 ~1 ~52 stone 0  
fill ~20 ~1 ~5 ~20 ~7 ~5 stone 0  
fill ~20 ~1 ~15 ~24 ~1 ~15 stone 0  
fill ~20 ~1 ~17 ~24 ~1 ~17 dirt 0  
fill ~20 ~1 ~21 ~21 ~1 ~21 sand 0  
fill ~20 ~1 ~22 ~22 ~1 ~22 sand 0  
fill ~20 ~1 ~23 ~24 ~1 ~23 sand 0  
fill ~20 ~1 ~41 ~20 ~1 ~42 grass 0  
fill ~21 ~1 ~1 ~23 ~1 ~1 sand 0  
fill ~21 ~1 ~2 ~23 ~1 ~2 sand 0  
fill ~21 ~1 ~3 ~21 ~1 ~1 sand 0  
fill ~21 ~1 ~4 ~22 ~1 ~4 dirt 0  
fill ~21 ~1 ~5 ~23 ~1 ~5 cobblestone 0  
fill ~21 ~1 ~13 ~23 ~1 ~13 cobblestone 0  
fill ~21 ~1 ~14 ~23 ~1 ~14 dirt 0  
fill ~21 ~1 ~16 ~23 ~1 ~16 dirt 0 
setblock ~21 ~1 ~41 dirt 0 
setblock ~21 ~1 ~42 grass 0  
fill ~21 ~1 ~45 ~21 ~1 ~47 stone 0  
fill ~22 ~1 ~3 ~23 ~1 ~3 dirt 0  
fill ~22 ~1 ~21 ~26 ~1 ~21 dirt 0  
fill ~22 ~1 ~29 ~34 ~1 ~29 dirt 0  
fill ~22 ~1 ~41 ~23 ~1 ~41 gravel 0  
fill ~22 ~1 ~42 ~23 ~1 ~42 gravel 0  
fill ~22 ~1 ~44 ~23 ~1 ~44 cobblestone 0  
fill ~22 ~1 ~45 ~22 ~1 ~46 cobblestone 0  
fill ~22 ~1 ~47 ~23 ~1 ~47 stone 0  
fill ~23 ~1 ~4 ~24 ~1 ~4 sand 0  
fill ~23 ~1 ~22 ~26 ~1 ~22 dirt 0  
fill ~23 ~1 ~45 ~23 ~1 ~46 stone_stairs 1  
fill ~24 ~1 ~1 ~27 ~1 ~1 dirt 0  
fill ~24 ~1 ~2 ~24 ~1 ~0 dirt 0  
fill ~24 ~1 ~3 ~27 ~1 ~3 sand 0  
fill ~24 ~1 ~5 ~24 ~7 ~5 stone 0  
fill ~24 ~1 ~41 ~24 ~1 ~42 grass 0  
fill ~24 ~1 ~44 ~26 ~1 ~44 stone 0 
setblock ~25 ~1 ~2 sand 0  
fill ~25 ~1 ~4 ~25 ~0 ~4 dirt 0  
fill ~25 ~1 ~23 ~27 ~1 ~23 dirt 0  
fill ~25 ~1 ~24 ~28 ~1 ~24 dirt 0  
fill ~25 ~1 ~26 ~32 ~1 ~26 dirt 0  
fill ~25 ~1 ~27 ~32 ~1 ~27 dirt 0  
fill ~25 ~1 ~28 ~33 ~1 ~28 dirt 0  
fill ~25 ~1 ~41 ~26 ~1 ~41 cobblestone 0  
fill ~25 ~1 ~42 ~27 ~1 ~42 cobblestone 0  
fill ~26 ~1 ~2 ~27 ~1 ~2 dirt 0 
setblock ~26 ~1 ~4 sand 0  
fill ~26 ~1 ~25 ~31 ~1 ~25 dirt 0  
fill ~26 ~1 ~45 ~26 ~1 ~52 stone 0 
setblock ~27 ~1 ~41 grass 0  
fill ~27 ~1 ~44 ~29 ~1 ~44 cobblestone 0  
fill ~27 ~1 ~45 ~27 ~1 ~54 cobblestone 0 
setblock ~27 ~1 ~55 grass 0 
setblock ~28 ~1 ~1 sand 0  
fill ~28 ~1 ~41 ~28 ~1 ~42 dirt 0  
fill ~28 ~1 ~45 ~28 ~1 ~50 grass 0 
setblock ~28 ~1 ~51 dirt 0  
fill ~28 ~1 ~52 ~29 ~1 ~52 cobblestone 0 
setblock ~28 ~1 ~54 grass 0 
setblock ~28 ~1 ~55 dirt 0  
fill ~28 ~1 ~57 ~34 ~1 ~57 stone 0 
setblock ~28 ~1 ~66 stone 0  
fill ~29 ~1 ~24 ~40 ~1 ~24 stone 0  
fill ~29 ~1 ~40 ~33 ~1 ~40 sand 0  
fill ~29 ~1 ~41 ~33 ~1 ~41 sand 0  
fill ~29 ~1 ~42 ~33 ~1 ~42 sand 0  
fill ~29 ~1 ~43 ~32 ~1 ~43 sand 0  
fill ~29 ~1 ~45 ~37 ~1 ~45 sand 0  
fill ~29 ~1 ~46 ~37 ~1 ~46 sand 0  
fill ~29 ~1 ~47 ~29 ~1 ~50 dirt 0 
setblock ~29 ~1 ~51 grass 0 
setblock ~29 ~1 ~53 grass 0  
fill ~29 ~1 ~54 ~33 ~1 ~54 dirt 0 
setblock ~29 ~1 ~55 grass 0  
fill ~29 ~1 ~58 ~34 ~1 ~58 stone 0 
setblock ~29 ~1 ~65 sand 0  
fill ~29 ~1 ~66 ~29 ~22 ~66 double_stone_slab 0  
fill ~30 ~1 ~39 ~33 ~1 ~39 sand 0 
setblock ~30 ~1 ~44 sand 0  
fill ~30 ~1 ~47 ~36 ~1 ~47 sand 0  
fill ~30 ~1 ~48 ~32 ~1 ~48 dirt 0  
fill ~30 ~1 ~49 ~36 ~1 ~49 dirt 0  
fill ~30 ~1 ~50 ~35 ~1 ~50 dirt 0  
fill ~30 ~1 ~51 ~34 ~1 ~51 dirt 0  
fill ~30 ~1 ~52 ~34 ~1 ~52 dirt 0  
fill ~30 ~1 ~53 ~34 ~1 ~53 dirt 0  
fill ~30 ~1 ~55 ~34 ~1 ~55 dirt 0  
fill ~30 ~1 ~59 ~31 ~1 ~59 stone 0  
fill ~30 ~1 ~60 ~32 ~1 ~60 stone 0  
fill ~30 ~1 ~61 ~30 ~1 ~63 stone 0  
fill ~30 ~1 ~65 ~33 ~1 ~65 stone 0 
setblock ~31 ~1 ~44 cobblestone 0  
fill ~31 ~1 ~61 ~38 ~1 ~61 dirt 0  
fill ~31 ~1 ~62 ~38 ~1 ~62 dirt 0  
fill ~31 ~1 ~63 ~36 ~1 ~63 dirt 0  
fill ~32 ~1 ~25 ~40 ~1 ~25 stone 0  
fill ~32 ~1 ~44 ~35 ~1 ~44 redstone_wire 0  
fill ~32 ~1 ~56 ~34 ~1 ~56 stone 0  
fill ~32 ~1 ~59 ~37 ~1 ~59 dirt 0  
fill ~33 ~1 ~26 ~40 ~1 ~26 stone 0  
fill ~33 ~1 ~27 ~39 ~1 ~27 stone 0  
fill ~33 ~1 ~38 ~33 ~2 ~38 sand 0 
setblock ~33 ~1 ~43 torch 5 
setblock ~33 ~1 ~48 sand 0  
fill ~33 ~1 ~60 ~37 ~1 ~60 dirt 0  
fill ~34 ~1 ~21 ~34 ~20 ~21 double_stone_slab 0  
fill ~34 ~1 ~22 ~40 ~1 ~22 stone 0  
fill ~34 ~1 ~28 ~38 ~1 ~28 stone 0 
setblock ~34 ~1 ~38 cobblestone 0  
fill ~34 ~1 ~39 ~34 ~1 ~40 redstone_wire 0 
setblock ~34 ~1 ~41 unpowered_repeater 2  
fill ~34 ~1 ~42 ~34 ~1 ~44 redstone_wire 0  
fill ~34 ~1 ~48 ~36 ~1 ~48 dirt 0  
fill ~34 ~1 ~54 ~37 ~1 ~54 sand 0  
fill ~34 ~1 ~65 ~34 ~42 ~65 double_stone_slab 0  
fill ~35 ~1 ~21 ~39 ~1 ~21 stone 0  
fill ~35 ~1 ~23 ~40 ~1 ~23 stone 0  
fill ~35 ~1 ~29 ~37 ~1 ~29 stone 0  
fill ~35 ~1 ~38 ~37 ~1 ~38 dirt 0  
fill ~35 ~1 ~39 ~36 ~1 ~39 sand 0  
fill ~35 ~1 ~40 ~36 ~1 ~40 sand 0  
fill ~35 ~1 ~41 ~36 ~1 ~41 sand 0  
fill ~35 ~1 ~42 ~37 ~1 ~42 sand 0  
fill ~35 ~1 ~43 ~37 ~1 ~43 sand 0  
fill ~35 ~1 ~51 ~37 ~1 ~51 sand 0  
fill ~35 ~1 ~52 ~38 ~1 ~52 sand 0  
fill ~35 ~1 ~53 ~37 ~1 ~53 sand 0  
fill ~35 ~1 ~55 ~36 ~1 ~55 sand 0  
fill ~35 ~1 ~56 ~36 ~1 ~56 sand 0  
fill ~35 ~1 ~57 ~36 ~1 ~57 sand 0  
fill ~35 ~1 ~58 ~35 ~2 ~58 dirt 0  
fill ~36 ~1 ~30 ~38 ~1 ~30 stone 0 
setblock ~36 ~1 ~44 cobblestone 0  
fill ~36 ~1 ~50 ~37 ~1 ~50 sand 0  
fill ~36 ~1 ~58 ~37 ~1 ~58 sand 0 
setblock ~37 ~1 ~44 sand 0  
fill ~37 ~1 ~63 ~38 ~1 ~63 sand 0  
fill ~38 ~1 ~44 ~38 ~14 ~44 dirt 0  
fill ~39 ~1 ~36 ~41 ~1 ~36 stone 0  
fill ~39 ~1 ~44 ~41 ~1 ~44 stone 0  
fill ~39 ~1 ~52 ~41 ~1 ~52 stone 0  
fill ~39 ~1 ~62 ~39 ~2 ~62 sand 0  
fill ~39 ~1 ~63 ~41 ~1 ~63 stone 0  
fill ~40 ~1 ~21 ~40 ~20 ~21 double_stone_slab 0  
fill ~40 ~1 ~27 ~40 ~20 ~27 double_stone_slab 0  
fill ~40 ~1 ~62 ~40 ~15 ~62 dirt 0  
fill ~41 ~1 ~62 ~43 ~1 ~62 stone 0  
fill ~42 ~1 ~63 ~42 ~15 ~63 dirt 0  
fill ~43 ~1 ~63 ~51 ~1 ~63 sand 0  
fill ~44 ~1 ~62 ~51 ~1 ~62 sand 0  
fill ~45 ~1 ~64 ~45 ~14 ~64 double_stone_slab 0  
fill ~46 ~1 ~59 ~46 ~38 ~59 double_stone_slab 0 
setblock ~46 ~1 ~60 stone 0  
fill ~46 ~1 ~61 ~51 ~1 ~61 sand 0  
fill ~46 ~1 ~64 ~51 ~1 ~64 sand 0  
fill ~46 ~1 ~65 ~46 ~38 ~65 double_stone_slab 0  
fill ~47 ~1 ~59 ~51 ~1 ~59 stone 0  
fill ~47 ~1 ~60 ~51 ~1 ~60 sand 0  
fill ~47 ~1 ~65 ~51 ~1 ~65 stone 0  
fill ~52 ~1 ~59 ~52 ~38 ~59 double_stone_slab 0 
setblock ~52 ~1 ~60 stone 0 
setblock ~52 ~1 ~64 stone 0  
fill ~52 ~1 ~65 ~52 ~38 ~65 double_stone_slab 0  
fill ~3 ~2 ~36 ~5 ~2 ~36 stone 0  
fill ~3 ~2 ~44 ~5 ~2 ~44 stone 0 
setblock ~3 ~2 ~53 double_stone_slab 0 
setblock ~3 ~2 ~65 double_stone_slab 0 
setblock ~4 ~2 ~22 double_stone_slab 0 
setblock ~4 ~2 ~26 double_stone_slab 0 
setblock ~4 ~2 ~52 double_stone_slab 0  
fill ~4 ~2 ~53 ~9 ~2 ~53 dirt 0  
fill ~4 ~2 ~54 ~4 ~2 ~59 sand 0  
fill ~4 ~2 ~60 ~9 ~2 ~60 dirt 0  
fill ~4 ~2 ~61 ~9 ~2 ~61 dirt 0  
fill ~4 ~2 ~62 ~9 ~2 ~62 dirt 0  
fill ~4 ~2 ~63 ~6 ~2 ~63 dirt 0  
fill ~4 ~2 ~64 ~5 ~2 ~64 dirt 0  
fill ~4 ~2 ~65 ~5 ~2 ~65 dirt 0 
setblock ~4 ~2 ~66 double_stone_slab 0 
setblock ~5 ~2 ~21 double_stone_slab 0  
fill ~5 ~2 ~22 ~9 ~2 ~22 dirt 0  
fill ~5 ~2 ~23 ~9 ~2 ~23 dirt 0  
fill ~5 ~2 ~24 ~9 ~2 ~24 dirt 0  
fill ~5 ~2 ~25 ~9 ~2 ~25 dirt 0  
fill ~5 ~2 ~26 ~9 ~2 ~26 dirt 0 
setblock ~5 ~2 ~27 double_stone_slab 0  
fill ~5 ~2 ~54 ~9 ~2 ~54 dirt 0  
fill ~5 ~2 ~55 ~5 ~2 ~59 sand 0  
fill ~6 ~2 ~21 ~8 ~2 ~21 stone 0  
fill ~6 ~2 ~27 ~8 ~2 ~27 stone 0  
fill ~6 ~2 ~36 ~6 ~8 ~36 dirt 0  
fill ~6 ~2 ~44 ~7 ~2 ~44 dirt 0  
fill ~6 ~2 ~52 ~9 ~2 ~52 dirt 0  
fill ~6 ~2 ~55 ~9 ~2 ~55 dirt 0  
fill ~6 ~2 ~56 ~9 ~2 ~56 dirt 0 
setblock ~6 ~2 ~57 sand 0  
fill ~6 ~2 ~58 ~9 ~2 ~58 dirt 0  
fill ~6 ~2 ~59 ~9 ~2 ~59 dirt 0  
fill ~6 ~2 ~64 ~6 ~8 ~64 stone 0  
fill ~6 ~2 ~65 ~6 ~8 ~65 stone 0  
fill ~6 ~2 ~66 ~6 ~0 ~66 dirt 0  
fill ~7 ~2 ~28 ~37 ~2 ~28 sand 0  
fill ~7 ~2 ~29 ~37 ~2 ~29 sand 0  
fill ~7 ~2 ~30 ~37 ~2 ~30 sand 0  
fill ~7 ~2 ~35 ~12 ~2 ~35 sand 0  
fill ~7 ~2 ~36 ~10 ~2 ~36 sand 0  
fill ~7 ~2 ~37 ~10 ~2 ~37 sand 0  
fill ~7 ~2 ~38 ~10 ~2 ~38 sand 0  
fill ~7 ~2 ~42 ~9 ~2 ~42 dirt 0  
fill ~7 ~2 ~43 ~7 ~15 ~43 dirt 0  
fill ~7 ~2 ~45 ~8 ~2 ~45 dirt 0  
fill ~7 ~2 ~46 ~7 ~15 ~46 dirt 0  
fill ~7 ~2 ~50 ~9 ~2 ~50 dirt 0  
fill ~7 ~2 ~51 ~9 ~2 ~51 dirt 0  
fill ~7 ~2 ~57 ~9 ~2 ~57 dirt 0  
fill ~7 ~2 ~63 ~8 ~2 ~63 stone 0  
fill ~7 ~2 ~64 ~8 ~2 ~64 water 0  
fill ~7 ~2 ~65 ~8 ~2 ~65 water 0  
fill ~7 ~2 ~66 ~12 ~2 ~66 stonebrick 0  
fill ~7 ~2 ~67 ~25 ~2 ~67 stonebrick 0  
fill ~7 ~2 ~68 ~25 ~2 ~68 stonebrick 0  
fill ~7 ~2 ~69 ~25 ~2 ~69 stonebrick 0  
fill ~7 ~2 ~70 ~25 ~2 ~70 stonebrick 0  
fill ~7 ~2 ~71 ~25 ~2 ~71 stonebrick 0  
fill ~7 ~2 ~72 ~25 ~2 ~72 stonebrick 0  
fill ~7 ~2 ~73 ~25 ~2 ~73 stonebrick 0  
fill ~7 ~2 ~74 ~25 ~2 ~74 stone 0  
fill ~8 ~2 ~31 ~36 ~2 ~31 sand 0  
fill ~8 ~2 ~33 ~11 ~2 ~33 sand 0  
fill ~8 ~2 ~34 ~9 ~2 ~34 sand 0  
fill ~8 ~2 ~39 ~10 ~2 ~39 sand 0  
fill ~8 ~2 ~41 ~9 ~2 ~41 sand 0 
setblock ~8 ~2 ~43 cobblestone 0 
setblock ~8 ~2 ~44 redstone_wire 0  
fill ~8 ~2 ~46 ~9 ~2 ~46 sand 0  
fill ~8 ~2 ~47 ~9 ~2 ~47 sand 0  
fill ~8 ~2 ~49 ~9 ~2 ~49 dirt 0 
setblock ~9 ~2 ~21 double_stone_slab 0 
setblock ~9 ~2 ~27 double_stone_slab 0  
fill ~9 ~2 ~32 ~11 ~2 ~32 sand 0 
setblock ~9 ~2 ~40 sand 0 
setblock ~9 ~2 ~43 dirt 0 
setblock ~9 ~2 ~45 sand 0  
fill ~9 ~2 ~48 ~9 ~0 ~48 dirt 0  
fill ~9 ~2 ~63 ~20 ~2 ~63 dirt 0  
fill ~9 ~2 ~64 ~25 ~2 ~64 stonebrick 0  
fill ~9 ~2 ~65 ~25 ~2 ~65 stonebrick 0 
setblock ~10 ~2 ~22 double_stone_slab 0 
setblock ~10 ~2 ~26 double_stone_slab 0 
setblock ~10 ~2 ~34 dirt 0 
setblock ~10 ~2 ~40 dirt 0  
fill ~10 ~2 ~41 ~11 ~2 ~41 cobblestone 0  
fill ~10 ~2 ~42 ~11 ~2 ~42 cobblestone 0  
fill ~10 ~2 ~43 ~11 ~2 ~43 cobblestone 0  
fill ~10 ~2 ~44 ~11 ~2 ~44 cobblestone 0  
fill ~10 ~2 ~45 ~11 ~2 ~45 cobblestone 0  
fill ~10 ~2 ~46 ~12 ~2 ~46 cobblestone 0  
fill ~10 ~2 ~47 ~15 ~2 ~47 cobblestone 0  
fill ~10 ~2 ~48 ~15 ~2 ~48 cobblestone 0  
fill ~10 ~2 ~49 ~15 ~2 ~49 cobblestone 0  
fill ~10 ~2 ~50 ~12 ~2 ~50 cobblestone 0  
fill ~10 ~2 ~51 ~11 ~2 ~51 cobblestone 0  
fill ~10 ~2 ~52 ~11 ~2 ~52 cobblestone 0  
fill ~10 ~2 ~53 ~11 ~2 ~53 cobblestone 0  
fill ~10 ~2 ~54 ~11 ~2 ~54 cobblestone 0  
fill ~10 ~2 ~55 ~11 ~2 ~55 cobblestone 0  
fill ~10 ~2 ~56 ~11 ~2 ~56 cobblestone 0  
fill ~10 ~2 ~57 ~34 ~2 ~57 cobblestone 0  
fill ~10 ~2 ~58 ~34 ~2 ~58 cobblestone 0  
fill ~10 ~2 ~59 ~34 ~2 ~59 cobblestone 0  
fill ~10 ~2 ~60 ~34 ~2 ~60 cobblestone 0  
fill ~10 ~2 ~61 ~34 ~2 ~61 cobblestone 0  
fill ~10 ~2 ~62 ~34 ~2 ~62 cobblestone 0  
fill ~11 ~2 ~24 ~12 ~2 ~24 sand 0  
fill ~11 ~2 ~25 ~33 ~2 ~25 sand 0  
fill ~11 ~2 ~26 ~33 ~2 ~26 sand 0  
fill ~11 ~2 ~27 ~33 ~2 ~27 sand 0  
fill ~11 ~2 ~34 ~12 ~2 ~34 cobblestone 0  
fill ~11 ~2 ~36 ~15 ~2 ~36 cobblestone 0  
fill ~11 ~2 ~37 ~11 ~2 ~36 cobblestone 0 
setblock ~11 ~2 ~38 redstone_wire 0  
fill ~12 ~2 ~32 ~15 ~2 ~32 dirt 0 
setblock ~12 ~2 ~33 cobblestone 0  
fill ~12 ~2 ~37 ~19 ~2 ~37 sand 0  
fill ~12 ~2 ~38 ~19 ~2 ~38 sand 0  
fill ~12 ~2 ~39 ~19 ~2 ~39 sand 0  
fill ~12 ~2 ~40 ~14 ~2 ~40 sand 0  
fill ~12 ~2 ~41 ~13 ~2 ~41 sand 0  
fill ~12 ~2 ~42 ~13 ~2 ~42 dirt 0  
fill ~12 ~2 ~43 ~12 ~0 ~43 dirt 0  
fill ~12 ~2 ~45 ~13 ~2 ~45 dirt 0  
fill ~12 ~2 ~51 ~13 ~2 ~51 dirt 0  
fill ~12 ~2 ~52 ~13 ~2 ~52 dirt 0  
fill ~12 ~2 ~53 ~13 ~2 ~53 dirt 0  
fill ~12 ~2 ~54 ~13 ~2 ~54 dirt 0  
fill ~12 ~2 ~55 ~13 ~2 ~55 dirt 0  
fill ~12 ~2 ~56 ~14 ~2 ~56 dirt 0  
fill ~13 ~2 ~24 ~15 ~2 ~24 stone 0  
fill ~13 ~2 ~33 ~14 ~2 ~33 sand 0 
setblock ~13 ~2 ~34 dirt 0 
setblock ~13 ~2 ~35 cobblestone 0 
setblock ~13 ~2 ~43 cobblestone 0 
setblock ~13 ~2 ~44 redstone_wire 0 
setblock ~13 ~2 ~46 dirt 0 
setblock ~13 ~2 ~50 dirt 0 
setblock ~13 ~2 ~66 dirt 0  
fill ~14 ~2 ~0 ~27 ~2 ~0 dirt 0  
fill ~14 ~2 ~1 ~26 ~2 ~1 dirt 0  
fill ~14 ~2 ~2 ~15 ~2 ~2 dirt 0  
fill ~14 ~2 ~3 ~15 ~2 ~3 grass 0  
fill ~14 ~2 ~34 ~15 ~2 ~34 cobblestone 0 
setblock ~14 ~2 ~35 sand 0  
fill ~14 ~2 ~41 ~14 ~2 ~45 stonebrick 0  
fill ~14 ~2 ~46 ~15 ~2 ~46 cobblestone 0  
fill ~14 ~2 ~50 ~15 ~2 ~50 cobblestone 0  
fill ~14 ~2 ~51 ~14 ~2 ~55 stonebrick 0  
fill ~14 ~2 ~66 ~18 ~2 ~66 stonebrick 0 
setblock ~15 ~2 ~33 cobblestone 0 
setblock ~15 ~2 ~35 cobblestone 0  
fill ~15 ~2 ~40 ~29 ~2 ~40 stonebrick 0  
fill ~15 ~2 ~42 ~15 ~7 ~42 stonebrick 0 
setblock ~15 ~2 ~43 stone_slab 5  
fill ~15 ~2 ~45 ~16 ~2 ~45 stone_slab 3  
fill ~15 ~2 ~51 ~16 ~2 ~51 stone_slab 3 
setblock ~15 ~2 ~53 stone_slab 5  
fill ~15 ~2 ~54 ~15 ~7 ~54 stonebrick 0  
fill ~15 ~2 ~55 ~15 ~7 ~55 dirt 0  
fill ~15 ~2 ~56 ~29 ~2 ~56 stonebrick 0  
fill ~16 ~2 ~2 ~17 ~2 ~2 grass 0  
fill ~16 ~2 ~24 ~28 ~2 ~24 sand 0  
fill ~16 ~2 ~32 ~28 ~2 ~32 sand 0  
fill ~16 ~2 ~33 ~28 ~2 ~33 sand 0  
fill ~16 ~2 ~34 ~28 ~2 ~34 sand 0  
fill ~16 ~2 ~35 ~28 ~2 ~35 sand 0  
fill ~16 ~2 ~36 ~28 ~2 ~36 sand 0  
fill ~16 ~2 ~41 ~16 ~7 ~41 stonebrick 0 
setblock ~16 ~2 ~42 stone_slab 5  
fill ~16 ~2 ~46 ~16 ~2 ~51 stone_slab 3 
setblock ~16 ~2 ~54 stone_slab 5  
fill ~16 ~2 ~55 ~16 ~7 ~55 stonebrick 0 
setblock ~17 ~2 ~41 stone_slab 5 
setblock ~17 ~2 ~55 stone_slab 5  
fill ~18 ~2 ~2 ~19 ~2 ~2 dirt 0  
fill ~18 ~2 ~3 ~19 ~2 ~3 grass 0  
fill ~18 ~2 ~19 ~26 ~2 ~19 dirt 0  
fill ~18 ~2 ~20 ~26 ~2 ~20 dirt 0  
fill ~18 ~2 ~21 ~26 ~2 ~21 dirt 0  
fill ~18 ~2 ~22 ~21 ~2 ~22 dirt 0 
setblock ~18 ~2 ~44 torch 5 
setblock ~18 ~2 ~52 torch 5  
fill ~19 ~2 ~18 ~25 ~2 ~18 dirt 0 
setblock ~19 ~2 ~66 dirt 0  
fill ~20 ~2 ~2 ~20 ~6 ~2 double_stone_slab 0  
fill ~20 ~2 ~3 ~24 ~2 ~3 stone 0  
fill ~20 ~2 ~4 ~20 ~6 ~4 stone 0  
fill ~20 ~2 ~15 ~24 ~2 ~15 stone 0  
fill ~20 ~2 ~17 ~24 ~2 ~17 dirt 0  
fill ~20 ~2 ~23 ~20 ~13 ~23 stone 0  
fill ~20 ~2 ~37 ~24 ~2 ~37 dirt 0  
fill ~20 ~2 ~38 ~24 ~2 ~38 cobblestone 0  
fill ~20 ~2 ~39 ~24 ~2 ~39 cobblestone 0  
fill ~20 ~2 ~41 ~20 ~2 ~42 stone_slab 3  
fill ~20 ~2 ~66 ~24 ~2 ~66 stonebrick 0  
fill ~21 ~2 ~2 ~23 ~2 ~2 dirt 0  
fill ~21 ~2 ~4 ~23 ~2 ~4 dirt 0  
fill ~21 ~2 ~5 ~23 ~2 ~5 cobblestone 0  
fill ~21 ~2 ~13 ~23 ~2 ~13 cobblestone 0  
fill ~21 ~2 ~14 ~23 ~2 ~14 dirt 0  
fill ~21 ~2 ~16 ~23 ~2 ~16 dirt 0 
setblock ~21 ~2 ~23 dirt 0  
fill ~21 ~2 ~41 ~23 ~2 ~41 cobblestone 0  
fill ~21 ~2 ~42 ~24 ~2 ~42 stone_slab 3  
fill ~21 ~2 ~63 ~23 ~2 ~63 cobblestone 0  
fill ~22 ~2 ~22 ~22 ~2 ~36 sand 0  
fill ~23 ~2 ~22 ~26 ~2 ~22 dirt 0  
fill ~23 ~2 ~23 ~24 ~2 ~23 sand 0 
setblock ~23 ~2 ~47 torch 5  
fill ~24 ~2 ~2 ~24 ~6 ~2 double_stone_slab 0  
fill ~24 ~2 ~4 ~24 ~6 ~4 stone 0 
setblock ~24 ~2 ~41 stone_slab 3  
fill ~24 ~2 ~63 ~36 ~2 ~63 dirt 0  
fill ~25 ~2 ~2 ~26 ~2 ~2 dirt 0  
fill ~25 ~2 ~3 ~25 ~2 ~0 dirt 0 
setblock ~25 ~2 ~4 grass 0  
fill ~25 ~2 ~23 ~27 ~2 ~23 dirt 0  
fill ~25 ~2 ~37 ~33 ~2 ~37 sand 0  
fill ~25 ~2 ~38 ~33 ~2 ~38 sand 0  
fill ~25 ~2 ~39 ~33 ~2 ~39 sand 0  
fill ~25 ~2 ~66 ~26 ~2 ~66 dirt 0 
setblock ~26 ~2 ~3 grass 0 
setblock ~26 ~2 ~44 torch 5 
setblock ~26 ~2 ~52 torch 5  
fill ~26 ~2 ~64 ~26 ~2 ~66 dirt 0  
fill ~27 ~2 ~1 ~27 ~2 ~2 grass 0 
setblock ~27 ~2 ~41 stone_slab 5 
setblock ~27 ~2 ~55 stone_slab 5  
fill ~27 ~2 ~64 ~34 ~2 ~64 grass 0  
fill ~27 ~2 ~65 ~29 ~2 ~65 grass 0 
setblock ~28 ~2 ~0 grass 0  
fill ~28 ~2 ~41 ~28 ~7 ~41 stonebrick 0 
setblock ~28 ~2 ~42 stone_slab 5  
fill ~28 ~2 ~45 ~29 ~2 ~45 stone_slab 3  
fill ~28 ~2 ~46 ~28 ~2 ~51 stone_slab 3 
setblock ~28 ~2 ~54 stone_slab 5  
fill ~28 ~2 ~55 ~28 ~7 ~55 stonebrick 0 
setblock ~28 ~2 ~66 double_stone_slab 0  
fill ~29 ~2 ~24 ~31 ~2 ~24 stone 0  
fill ~29 ~2 ~32 ~29 ~3 ~32 cobblestone 0  
fill ~29 ~2 ~33 ~29 ~2 ~35 cobblestone 0 
setblock ~29 ~2 ~36 dirt 0  
fill ~29 ~2 ~42 ~30 ~2 ~42 stonebrick 0 
setblock ~29 ~2 ~43 stone_slab 5  
fill ~29 ~2 ~46 ~30 ~2 ~46 cobblestone 0  
fill ~29 ~2 ~47 ~34 ~2 ~47 cobblestone 0  
fill ~29 ~2 ~48 ~34 ~2 ~48 cobblestone 0  
fill ~29 ~2 ~49 ~34 ~2 ~49 cobblestone 0  
fill ~29 ~2 ~50 ~30 ~2 ~50 cobblestone 0 
setblock ~29 ~2 ~51 stone_slab 3 
setblock ~29 ~2 ~53 stone_slab 5  
fill ~29 ~2 ~54 ~30 ~2 ~54 stonebrick 0  
fill ~30 ~2 ~32 ~31 ~2 ~32 dirt 0  
fill ~30 ~2 ~33 ~31 ~2 ~33 sand 0 
setblock ~30 ~2 ~34 cobblestone 0 
setblock ~30 ~2 ~35 sand 0  
fill ~30 ~2 ~36 ~34 ~2 ~36 cobblestone 0  
fill ~30 ~2 ~40 ~33 ~2 ~40 sand 0 
setblock ~30 ~2 ~41 stonebrick 0  
fill ~30 ~2 ~43 ~30 ~2 ~45 stonebrick 0  
fill ~30 ~2 ~51 ~30 ~2 ~55 stonebrick 0  
fill ~30 ~2 ~56 ~32 ~2 ~56 dirt 0  
fill ~30 ~2 ~65 ~32 ~2 ~65 stone 0 
setblock ~31 ~2 ~34 dirt 0 
setblock ~31 ~2 ~35 cobblestone 0  
fill ~31 ~2 ~41 ~32 ~2 ~41 sand 0  
fill ~31 ~2 ~42 ~32 ~2 ~42 sand 0 
setblock ~31 ~2 ~43 cobblestone 0 
setblock ~31 ~2 ~44 redstone_wire 0  
fill ~31 ~2 ~45 ~31 ~2 ~46 sand 0  
fill ~31 ~2 ~50 ~31 ~2 ~56 dirt 0  
fill ~32 ~2 ~24 ~33 ~2 ~24 sand 0  
fill ~32 ~2 ~32 ~32 ~3 ~32 cobblestone 0  
fill ~32 ~2 ~33 ~32 ~2 ~34 cobblestone 0  
fill ~32 ~2 ~35 ~37 ~2 ~35 sand 0 
setblock ~32 ~2 ~43 dirt 0 
setblock ~32 ~2 ~45 dirt 0  
fill ~32 ~2 ~46 ~34 ~2 ~46 cobblestone 0  
fill ~32 ~2 ~50 ~34 ~2 ~50 cobblestone 0  
fill ~32 ~2 ~51 ~32 ~2 ~56 dirt 0  
fill ~33 ~2 ~32 ~36 ~2 ~32 sand 0  
fill ~33 ~2 ~33 ~36 ~2 ~33 sand 0 
setblock ~33 ~2 ~34 cobblestone 0  
fill ~33 ~2 ~41 ~34 ~2 ~41 cobblestone 0  
fill ~33 ~2 ~42 ~34 ~2 ~42 cobblestone 0  
fill ~33 ~2 ~43 ~34 ~2 ~43 cobblestone 0  
fill ~33 ~2 ~44 ~34 ~2 ~44 cobblestone 0  
fill ~33 ~2 ~45 ~34 ~2 ~45 cobblestone 0  
fill ~33 ~2 ~51 ~34 ~2 ~51 cobblestone 0  
fill ~33 ~2 ~52 ~34 ~2 ~52 cobblestone 0  
fill ~33 ~2 ~53 ~34 ~2 ~53 cobblestone 0  
fill ~33 ~2 ~54 ~34 ~2 ~54 cobblestone 0  
fill ~33 ~2 ~55 ~34 ~2 ~55 cobblestone 0  
fill ~33 ~2 ~56 ~34 ~2 ~56 cobblestone 0 
setblock ~33 ~2 ~65 double_stone_slab 0 
setblock ~34 ~2 ~22 double_stone_slab 0  
fill ~34 ~2 ~24 ~40 ~2 ~24 stone 0  
fill ~34 ~2 ~25 ~40 ~2 ~25 stone 0  
fill ~34 ~2 ~26 ~39 ~2 ~26 stone 0  
fill ~34 ~2 ~27 ~38 ~2 ~27 stone 0 
setblock ~34 ~2 ~34 dirt 0 
setblock ~34 ~2 ~37 cobblestone 0 
setblock ~34 ~2 ~38 redstone_wire 0 
setblock ~35 ~2 ~21 double_stone_slab 0  
fill ~35 ~2 ~22 ~39 ~2 ~22 stone 0  
fill ~35 ~2 ~23 ~40 ~2 ~23 stone 0  
fill ~35 ~2 ~34 ~37 ~2 ~34 sand 0  
fill ~35 ~2 ~36 ~37 ~2 ~36 sand 0  
fill ~35 ~2 ~37 ~37 ~2 ~37 sand 0  
fill ~35 ~2 ~38 ~37 ~2 ~38 sand 0  
fill ~35 ~2 ~39 ~36 ~2 ~39 sand 0  
fill ~35 ~2 ~40 ~36 ~2 ~40 sand 0  
fill ~35 ~2 ~41 ~36 ~2 ~41 sand 0  
fill ~35 ~2 ~42 ~37 ~2 ~42 dirt 0  
fill ~35 ~2 ~43 ~35 ~2 ~42 dirt 0  
fill ~35 ~2 ~45 ~37 ~2 ~45 dirt 0  
fill ~35 ~2 ~46 ~37 ~2 ~46 dirt 0 
setblock ~35 ~2 ~47 sand 0  
fill ~35 ~2 ~48 ~36 ~2 ~48 dirt 0  
fill ~35 ~2 ~49 ~36 ~2 ~49 dirt 0  
fill ~35 ~2 ~50 ~35 ~2 ~48 dirt 0  
fill ~35 ~2 ~51 ~37 ~2 ~51 sand 0  
fill ~35 ~2 ~52 ~37 ~2 ~52 sand 0  
fill ~35 ~2 ~53 ~37 ~2 ~53 sand 0  
fill ~35 ~2 ~54 ~37 ~2 ~54 sand 0  
fill ~35 ~2 ~55 ~36 ~2 ~55 sand 0  
fill ~35 ~2 ~56 ~36 ~2 ~56 sand 0  
fill ~35 ~2 ~57 ~36 ~2 ~57 sand 0  
fill ~35 ~2 ~59 ~37 ~2 ~59 dirt 0  
fill ~35 ~2 ~60 ~37 ~2 ~60 dirt 0  
fill ~35 ~2 ~61 ~38 ~2 ~61 dirt 0  
fill ~35 ~2 ~62 ~38 ~2 ~62 dirt 0  
fill ~36 ~2 ~21 ~38 ~2 ~21 stone 0 
setblock ~36 ~2 ~43 cobblestone 0 
setblock ~36 ~2 ~44 redstone_wire 0  
fill ~36 ~2 ~47 ~36 ~15 ~47 dirt 0  
fill ~36 ~2 ~50 ~37 ~2 ~50 sand 0  
fill ~36 ~2 ~58 ~37 ~2 ~58 sand 0  
fill ~37 ~2 ~43 ~37 ~15 ~43 dirt 0  
fill ~37 ~2 ~44 ~37 ~15 ~44 dirt 0  
fill ~37 ~2 ~63 ~38 ~2 ~63 sand 0  
fill ~38 ~2 ~36 ~38 ~8 ~36 dirt 0  
fill ~38 ~2 ~52 ~38 ~14 ~52 dirt 0 
setblock ~39 ~2 ~21 double_stone_slab 0 
setblock ~39 ~2 ~27 double_stone_slab 0  
fill ~39 ~2 ~36 ~41 ~2 ~36 stone 0  
fill ~39 ~2 ~44 ~41 ~2 ~44 stone 0  
fill ~39 ~2 ~52 ~41 ~2 ~52 stone 0  
fill ~39 ~2 ~63 ~41 ~2 ~63 stone 0 
setblock ~40 ~2 ~22 double_stone_slab 0 
setblock ~40 ~2 ~26 double_stone_slab 0  
fill ~41 ~2 ~62 ~44 ~2 ~62 stone 0  
fill ~43 ~2 ~63 ~45 ~2 ~63 dirt 0  
fill ~45 ~2 ~62 ~45 ~15 ~62 dirt 0 
setblock ~46 ~2 ~60 double_stone_slab 0  
fill ~46 ~2 ~61 ~46 ~37 ~61 stone 0  
fill ~46 ~2 ~62 ~46 ~17 ~62 stone 0  
fill ~46 ~2 ~63 ~46 ~37 ~63 stone 0 
setblock ~46 ~2 ~64 double_stone_slab 0 
setblock ~47 ~2 ~59 double_stone_slab 0  
fill ~47 ~2 ~60 ~51 ~2 ~60 water 0  
fill ~47 ~2 ~61 ~51 ~2 ~61 water 0  
fill ~47 ~2 ~62 ~51 ~2 ~62 water 0  
fill ~47 ~2 ~63 ~51 ~2 ~63 water 0  
fill ~47 ~2 ~64 ~51 ~2 ~64 water 0 
setblock ~47 ~2 ~65 double_stone_slab 0  
fill ~48 ~2 ~59 ~50 ~2 ~59 stone 0  
fill ~48 ~2 ~65 ~50 ~2 ~65 stone 0 
setblock ~51 ~2 ~59 double_stone_slab 0 
setblock ~51 ~2 ~65 double_stone_slab 0 
setblock ~52 ~2 ~60 double_stone_slab 0 
setblock ~52 ~2 ~64 double_stone_slab 0  
fill ~3 ~3 ~36 ~5 ~3 ~36 stone 0  
fill ~3 ~3 ~44 ~5 ~3 ~44 stone 0 
setblock ~3 ~3 ~53 stone 0 
setblock ~3 ~3 ~65 stone 0 
setblock ~4 ~3 ~22 stone 0 
setblock ~4 ~3 ~26 stone 0 
setblock ~4 ~3 ~52 stone 0  
fill ~4 ~3 ~53 ~8 ~3 ~53 dirt 0  
fill ~4 ~3 ~54 ~8 ~3 ~54 dirt 0  
fill ~4 ~3 ~55 ~8 ~3 ~55 dirt 0  
fill ~4 ~3 ~56 ~8 ~3 ~56 dirt 0  
fill ~4 ~3 ~57 ~8 ~3 ~57 dirt 0  
fill ~4 ~3 ~58 ~8 ~3 ~58 dirt 0  
fill ~4 ~3 ~59 ~8 ~3 ~59 dirt 0  
fill ~4 ~3 ~60 ~8 ~3 ~60 dirt 0  
fill ~4 ~3 ~61 ~8 ~3 ~61 dirt 0  
fill ~4 ~3 ~62 ~8 ~3 ~62 dirt 0  
fill ~4 ~3 ~63 ~5 ~3 ~63 dirt 0  
fill ~4 ~3 ~64 ~5 ~3 ~64 dirt 0  
fill ~4 ~3 ~65 ~5 ~3 ~65 dirt 0 
setblock ~4 ~3 ~66 stone 0  
fill ~5 ~3 ~21 ~9 ~3 ~21 stone 0  
fill ~5 ~3 ~22 ~9 ~3 ~22 dirt 0  
fill ~5 ~3 ~23 ~9 ~3 ~23 dirt 0  
fill ~5 ~3 ~24 ~9 ~3 ~24 dirt 0  
fill ~5 ~3 ~25 ~9 ~3 ~25 dirt 0  
fill ~5 ~3 ~26 ~9 ~3 ~26 dirt 0  
fill ~5 ~3 ~27 ~9 ~3 ~27 stone 0  
fill ~6 ~3 ~44 ~7 ~3 ~44 dirt 0  
fill ~6 ~3 ~52 ~8 ~3 ~52 dirt 0  
fill ~6 ~3 ~63 ~21 ~3 ~63 stone 0  
fill ~6 ~3 ~66 ~6 ~15 ~66 stone 0  
fill ~7 ~3 ~42 ~7 ~15 ~42 dirt 0  
fill ~7 ~3 ~45 ~8 ~3 ~45 dirt 0  
fill ~7 ~3 ~50 ~8 ~3 ~50 dirt 0  
fill ~7 ~3 ~51 ~8 ~3 ~51 dirt 0 
setblock ~7 ~3 ~66 double_stone_slab 0  
fill ~7 ~3 ~74 ~25 ~3 ~74 stone 0 
setblock ~8 ~3 ~32 torch 5  
fill ~8 ~3 ~40 ~9 ~3 ~40 stone 0  
fill ~8 ~3 ~41 ~9 ~3 ~41 dirt 0 
setblock ~8 ~3 ~42 cobblestone 0 
setblock ~8 ~3 ~43 redstone_wire 0  
fill ~8 ~3 ~46 ~8 ~15 ~46 dirt 0  
fill ~8 ~3 ~47 ~8 ~15 ~47 dirt 0  
fill ~8 ~3 ~48 ~8 ~15 ~48 dirt 0  
fill ~8 ~3 ~49 ~8 ~15 ~49 dirt 0  
fill ~8 ~3 ~73 ~9 ~3 ~73 planks 0 
setblock ~9 ~3 ~39 torch 5  
fill ~9 ~3 ~42 ~9 ~8 ~42 stone 0  
fill ~9 ~3 ~43 ~9 ~7 ~43 stone 0  
fill ~9 ~3 ~44 ~9 ~7 ~44 stone 0  
fill ~9 ~3 ~45 ~9 ~7 ~45 stone 0  
fill ~9 ~3 ~46 ~9 ~7 ~46 stone 0  
fill ~9 ~3 ~47 ~9 ~7 ~47 stone 0  
fill ~9 ~3 ~48 ~9 ~7 ~48 stone 0  
fill ~9 ~3 ~49 ~9 ~7 ~49 stone 0  
fill ~9 ~3 ~50 ~9 ~7 ~50 stone 0  
fill ~9 ~3 ~51 ~9 ~7 ~51 stone 0  
fill ~9 ~3 ~52 ~9 ~7 ~52 stone 0  
fill ~9 ~3 ~53 ~9 ~7 ~53 stone 0  
fill ~9 ~3 ~54 ~9 ~7 ~54 stone 0  
fill ~9 ~3 ~55 ~9 ~7 ~55 stone 0  
fill ~9 ~3 ~56 ~9 ~7 ~56 stone 0  
fill ~9 ~3 ~57 ~9 ~7 ~57 stone 0  
fill ~9 ~3 ~58 ~9 ~7 ~58 stone 0  
fill ~9 ~3 ~59 ~9 ~7 ~59 stone 0  
fill ~9 ~3 ~60 ~9 ~7 ~60 stone 0  
fill ~9 ~3 ~61 ~9 ~7 ~61 stone 0  
fill ~9 ~3 ~62 ~9 ~7 ~62 stone 0 
setblock ~9 ~3 ~64 cauldron 6 
setblock ~10 ~3 ~22 stone 0 
setblock ~10 ~3 ~26 stone 0 
setblock ~10 ~3 ~28 torch 5 
setblock ~10 ~3 ~34 cobblestone 0  
fill ~10 ~3 ~40 ~11 ~3 ~40 cobblestone 0  
fill ~10 ~3 ~41 ~11 ~3 ~41 cobblestone 0  
fill ~10 ~3 ~42 ~11 ~3 ~42 stone_stairs 3 
setblock ~10 ~3 ~64 stone 0 
setblock ~11 ~3 ~27 torch 5  
fill ~11 ~3 ~34 ~12 ~3 ~34 redstone_wire 0  
fill ~11 ~3 ~36 ~14 ~3 ~36 redstone_wire 0  
fill ~11 ~3 ~37 ~11 ~3 ~36 redstone_wire 0  
fill ~11 ~3 ~73 ~12 ~3 ~73 planks 0  
fill ~12 ~3 ~32 ~15 ~3 ~32 cobblestone 0 
setblock ~12 ~3 ~33 redstone_wire 0  
fill ~12 ~3 ~40 ~21 ~3 ~40 stone 0  
fill ~12 ~3 ~41 ~13 ~3 ~41 dirt 0  
fill ~12 ~3 ~42 ~12 ~8 ~42 stone 0  
fill ~12 ~3 ~43 ~12 ~7 ~43 stone 0  
fill ~12 ~3 ~44 ~12 ~7 ~44 stone 0  
fill ~12 ~3 ~45 ~12 ~7 ~45 stone 0  
fill ~12 ~3 ~51 ~12 ~7 ~51 stone 0  
fill ~12 ~3 ~52 ~12 ~7 ~52 stone 0  
fill ~12 ~3 ~53 ~12 ~7 ~53 stone 0  
fill ~12 ~3 ~54 ~12 ~7 ~54 stone 0  
fill ~12 ~3 ~55 ~12 ~7 ~55 stone 0  
fill ~12 ~3 ~56 ~32 ~3 ~56 stone 0  
fill ~13 ~3 ~24 ~15 ~3 ~24 stone 0 
setblock ~13 ~3 ~33 torch 5 
setblock ~13 ~3 ~34 cobblestone 0 
setblock ~13 ~3 ~35 unlit_redstone_torch 3 
setblock ~13 ~3 ~42 cobblestone 0 
setblock ~13 ~3 ~43 redstone_wire 0  
fill ~13 ~3 ~45 ~13 ~21 ~45 dirt 0  
fill ~13 ~3 ~46 ~13 ~5 ~46 cobblestone 0  
fill ~13 ~3 ~50 ~13 ~5 ~50 cobblestone 0  
fill ~13 ~3 ~51 ~13 ~8 ~51 dirt 0  
fill ~13 ~3 ~52 ~13 ~9 ~52 dirt 0  
fill ~13 ~3 ~53 ~13 ~8 ~53 dirt 0  
fill ~13 ~3 ~54 ~13 ~8 ~54 dirt 0  
fill ~13 ~3 ~55 ~13 ~8 ~55 dirt 0 
setblock ~13 ~3 ~66 double_stone_slab 0  
fill ~14 ~3 ~0 ~26 ~3 ~0 dirt 0  
fill ~14 ~3 ~1 ~17 ~3 ~1 grass 0  
fill ~14 ~3 ~2 ~15 ~3 ~2 grass 0 
setblock ~14 ~3 ~34 redstone_wire 14 
setblock ~14 ~3 ~35 torch 5  
fill ~14 ~3 ~41 ~14 ~7 ~41 stone 0  
fill ~14 ~3 ~42 ~14 ~7 ~42 stone 0  
fill ~14 ~3 ~43 ~14 ~7 ~43 stone 0  
fill ~14 ~3 ~44 ~14 ~7 ~44 stone 0  
fill ~14 ~3 ~45 ~14 ~7 ~45 stone 0  
fill ~14 ~3 ~51 ~14 ~7 ~51 stone 0  
fill ~14 ~3 ~52 ~14 ~7 ~52 stone 0  
fill ~14 ~3 ~53 ~14 ~7 ~53 stone 0  
fill ~14 ~3 ~54 ~14 ~7 ~54 stone 0  
fill ~14 ~3 ~55 ~14 ~7 ~55 stone 0  
fill ~14 ~3 ~73 ~15 ~3 ~73 planks 0 
setblock ~15 ~3 ~33 redstone_wire 14 
setblock ~15 ~3 ~34 redstone_wire 15 
setblock ~15 ~3 ~35 redstone_torch 4 
setblock ~15 ~3 ~36 cobblestone 0 
setblock ~16 ~3 ~39 torch 5 
setblock ~17 ~3 ~24 torch 5  
fill ~17 ~3 ~73 ~18 ~3 ~73 planks 0  
fill ~18 ~3 ~1 ~25 ~3 ~1 dirt 0 
setblock ~18 ~3 ~2 grass 0  
fill ~18 ~3 ~19 ~26 ~3 ~19 dirt 0  
fill ~18 ~3 ~20 ~26 ~3 ~20 dirt 0  
fill ~18 ~3 ~21 ~26 ~3 ~21 dirt 0  
fill ~18 ~3 ~22 ~26 ~3 ~22 dirt 0 
setblock ~19 ~3 ~2 dirt 0  
fill ~19 ~3 ~18 ~25 ~3 ~18 dirt 0 
setblock ~19 ~3 ~55 torch 4 
setblock ~19 ~3 ~66 double_stone_slab 0  
fill ~20 ~3 ~3 ~24 ~3 ~3 stone 0  
fill ~20 ~3 ~15 ~24 ~3 ~15 stone 0  
fill ~20 ~3 ~17 ~24 ~3 ~17 dirt 0  
fill ~20 ~3 ~37 ~24 ~3 ~37 stone 0 
setblock ~20 ~3 ~64 crafting_table 0  
fill ~20 ~3 ~73 ~21 ~3 ~73 planks 0  
fill ~21 ~3 ~2 ~23 ~3 ~2 dirt 0  
fill ~21 ~3 ~4 ~23 ~3 ~4 dirt 0  
fill ~21 ~3 ~5 ~23 ~3 ~5 cobblestone 0  
fill ~21 ~3 ~13 ~23 ~3 ~13 cobblestone 0  
fill ~21 ~3 ~14 ~23 ~3 ~14 dirt 0  
fill ~21 ~3 ~16 ~23 ~3 ~16 dirt 0  
fill ~21 ~3 ~23 ~24 ~3 ~23 stone 0 
setblock ~21 ~3 ~62 stone_stairs 2 
setblock ~21 ~3 ~64 stone_stairs 3 
setblock ~22 ~3 ~24 torch 5 
setblock ~22 ~3 ~31 torch 5 
setblock ~22 ~3 ~39 wooden_pressure_plate 0 
setblock ~22 ~3 ~40 iron_door 1  
fill ~23 ~3 ~40 ~32 ~3 ~40 stone 0  
fill ~23 ~3 ~73 ~24 ~3 ~73 planks 0 
setblock ~24 ~3 ~62 stone_stairs 2  
fill ~24 ~3 ~63 ~35 ~3 ~63 stone 0 
setblock ~24 ~3 ~64 stone_stairs 3 
setblock ~25 ~3 ~2 dirt 0 
setblock ~25 ~3 ~3 grass 0  
fill ~25 ~3 ~23 ~25 ~14 ~23 double_stone_slab 0 
setblock ~25 ~3 ~55 torch 4 
setblock ~25 ~3 ~66 double_stone_slab 0  
fill ~26 ~3 ~1 ~26 ~3 ~2 grass 0  
fill ~26 ~3 ~23 ~26 ~12 ~23 stone 0  
fill ~26 ~3 ~64 ~26 ~8 ~64 stone 0  
fill ~26 ~3 ~65 ~26 ~9 ~65 stone 0  
fill ~26 ~3 ~66 ~26 ~10 ~66 stone 0 
setblock ~27 ~3 ~0 grass 0  
fill ~27 ~3 ~23 ~27 ~14 ~23 double_stone_slab 0 
setblock ~27 ~3 ~24 torch 5 
setblock ~28 ~3 ~35 torch 5 
setblock ~28 ~3 ~39 torch 5 
setblock ~28 ~3 ~64 torch 5 
setblock ~28 ~3 ~66 stone 0  
fill ~29 ~3 ~24 ~31 ~3 ~24 stone 0 
setblock ~29 ~3 ~33 redstone_wire 14 
setblock ~29 ~3 ~34 redstone_wire 15 
setblock ~29 ~3 ~35 redstone_torch 4 
setblock ~29 ~3 ~36 cobblestone 0  
fill ~29 ~3 ~42 ~29 ~7 ~42 stonebrick 0  
fill ~29 ~3 ~54 ~29 ~7 ~54 stonebrick 0  
fill ~30 ~3 ~32 ~32 ~3 ~32 cobblestone 0 
setblock ~30 ~3 ~34 redstone_wire 14 
setblock ~30 ~3 ~35 torch 5  
fill ~30 ~3 ~36 ~34 ~3 ~36 redstone_wire 0  
fill ~30 ~3 ~41 ~30 ~7 ~41 stone 0  
fill ~30 ~3 ~42 ~30 ~7 ~42 stone 0  
fill ~30 ~3 ~43 ~30 ~7 ~43 stone 0  
fill ~30 ~3 ~44 ~30 ~7 ~44 stone 0  
fill ~30 ~3 ~45 ~30 ~7 ~45 stone 0  
fill ~30 ~3 ~51 ~30 ~7 ~51 stone 0  
fill ~30 ~3 ~52 ~30 ~7 ~52 stone 0  
fill ~30 ~3 ~53 ~30 ~7 ~53 stone 0  
fill ~30 ~3 ~54 ~30 ~7 ~54 stone 0  
fill ~30 ~3 ~55 ~30 ~7 ~55 stone 0  
fill ~30 ~3 ~65 ~33 ~3 ~65 stone 0 
setblock ~31 ~3 ~33 torch 5 
setblock ~31 ~3 ~34 cobblestone 0 
setblock ~31 ~3 ~35 unlit_redstone_torch 3  
fill ~31 ~3 ~41 ~32 ~3 ~41 dirt 0 
setblock ~31 ~3 ~42 cobblestone 0 
setblock ~31 ~3 ~43 redstone_wire 0  
fill ~31 ~3 ~46 ~31 ~5 ~46 cobblestone 0  
fill ~31 ~3 ~50 ~31 ~5 ~50 cobblestone 0  
fill ~31 ~3 ~51 ~31 ~8 ~51 dirt 0  
fill ~31 ~3 ~52 ~31 ~9 ~52 dirt 0  
fill ~31 ~3 ~53 ~31 ~8 ~53 dirt 0  
fill ~31 ~3 ~54 ~31 ~8 ~54 dirt 0  
fill ~31 ~3 ~55 ~31 ~8 ~55 dirt 0  
fill ~32 ~3 ~33 ~32 ~3 ~34 redstone_wire 0  
fill ~32 ~3 ~42 ~32 ~8 ~42 stone 0  
fill ~32 ~3 ~43 ~32 ~8 ~43 stone 0  
fill ~32 ~3 ~44 ~32 ~7 ~44 stone 0  
fill ~32 ~3 ~45 ~32 ~7 ~45 stone 0  
fill ~32 ~3 ~51 ~32 ~7 ~51 stone 0  
fill ~32 ~3 ~52 ~32 ~7 ~52 stone 0  
fill ~32 ~3 ~53 ~32 ~7 ~53 stone 0  
fill ~32 ~3 ~54 ~32 ~7 ~54 stone 0  
fill ~32 ~3 ~55 ~32 ~7 ~55 stone 0 
setblock ~33 ~3 ~27 torch 5 
setblock ~33 ~3 ~34 redstone_wire 0  
fill ~33 ~3 ~40 ~34 ~3 ~40 cobblestone 0  
fill ~33 ~3 ~41 ~34 ~3 ~41 cobblestone 0  
fill ~33 ~3 ~42 ~34 ~3 ~42 stone_stairs 3  
fill ~34 ~3 ~22 ~38 ~3 ~22 stone 0  
fill ~34 ~3 ~24 ~40 ~3 ~24 stone 0  
fill ~34 ~3 ~25 ~40 ~3 ~25 stone 0  
fill ~34 ~3 ~26 ~40 ~3 ~26 stone 0  
fill ~34 ~3 ~27 ~34 ~20 ~27 double_stone_slab 0 
setblock ~34 ~3 ~28 torch 5 
setblock ~34 ~3 ~34 cobblestone 0 
setblock ~34 ~3 ~37 redstone_wire 0  
fill ~35 ~3 ~21 ~39 ~3 ~21 stone 0  
fill ~35 ~3 ~23 ~40 ~3 ~23 stone 0  
fill ~35 ~3 ~27 ~39 ~3 ~27 stone 0 
setblock ~35 ~3 ~39 torch 5  
fill ~35 ~3 ~40 ~37 ~3 ~40 stone 0  
fill ~35 ~3 ~41 ~36 ~3 ~41 dirt 0  
fill ~35 ~3 ~42 ~35 ~8 ~42 stone 0  
fill ~35 ~3 ~43 ~35 ~8 ~43 stone 0  
fill ~35 ~3 ~44 ~35 ~8 ~44 stone 0  
fill ~35 ~3 ~45 ~35 ~7 ~45 stone 0  
fill ~35 ~3 ~46 ~35 ~7 ~46 stone 0  
fill ~35 ~3 ~47 ~35 ~7 ~47 stone 0  
fill ~35 ~3 ~48 ~35 ~7 ~48 stone 0  
fill ~35 ~3 ~49 ~35 ~7 ~49 stone 0  
fill ~35 ~3 ~50 ~35 ~7 ~50 stone 0  
fill ~35 ~3 ~51 ~35 ~7 ~51 stone 0  
fill ~35 ~3 ~52 ~35 ~7 ~52 stone 0  
fill ~35 ~3 ~53 ~35 ~7 ~53 stone 0  
fill ~35 ~3 ~54 ~35 ~7 ~54 stone 0  
fill ~35 ~3 ~55 ~35 ~7 ~55 stone 0  
fill ~35 ~3 ~56 ~35 ~7 ~56 stone 0  
fill ~35 ~3 ~57 ~35 ~7 ~57 stone 0  
fill ~35 ~3 ~58 ~35 ~7 ~58 stone 0  
fill ~35 ~3 ~59 ~35 ~7 ~59 stone 0  
fill ~35 ~3 ~60 ~35 ~7 ~60 stone 0  
fill ~35 ~3 ~61 ~35 ~7 ~61 stone 0  
fill ~35 ~3 ~62 ~35 ~7 ~62 stone 0 
setblock ~36 ~3 ~32 torch 5 
setblock ~36 ~3 ~42 cobblestone 0 
setblock ~36 ~3 ~43 redstone_wire 0  
fill ~36 ~3 ~45 ~37 ~3 ~45 dirt 0  
fill ~36 ~3 ~46 ~37 ~3 ~46 dirt 0  
fill ~36 ~3 ~48 ~36 ~15 ~48 dirt 0  
fill ~36 ~3 ~49 ~36 ~15 ~49 dirt 0  
fill ~36 ~3 ~50 ~37 ~3 ~50 dirt 0  
fill ~36 ~3 ~51 ~37 ~3 ~51 dirt 0  
fill ~36 ~3 ~52 ~38 ~3 ~52 dirt 0  
fill ~36 ~3 ~53 ~37 ~3 ~53 dirt 0  
fill ~36 ~3 ~54 ~37 ~3 ~54 dirt 0  
fill ~36 ~3 ~55 ~36 ~15 ~55 dirt 0  
fill ~36 ~3 ~56 ~36 ~15 ~56 dirt 0  
fill ~36 ~3 ~57 ~36 ~15 ~57 dirt 0  
fill ~36 ~3 ~58 ~37 ~3 ~58 dirt 0  
fill ~36 ~3 ~59 ~37 ~3 ~59 dirt 0  
fill ~36 ~3 ~60 ~37 ~3 ~60 dirt 0  
fill ~36 ~3 ~61 ~38 ~3 ~61 dirt 0  
fill ~36 ~3 ~62 ~40 ~3 ~62 dirt 0  
fill ~36 ~3 ~63 ~38 ~3 ~63 dirt 0  
fill ~37 ~3 ~42 ~37 ~15 ~42 dirt 0  
fill ~39 ~3 ~22 ~39 ~5 ~22 dirt 0  
fill ~39 ~3 ~36 ~41 ~3 ~36 stone 0  
fill ~39 ~3 ~44 ~41 ~3 ~44 stone 0  
fill ~39 ~3 ~52 ~41 ~3 ~52 stone 0  
fill ~39 ~3 ~63 ~41 ~3 ~63 stone 0 
setblock ~40 ~3 ~22 stone 0  
fill ~41 ~3 ~62 ~43 ~3 ~62 stone 0  
fill ~43 ~3 ~63 ~45 ~3 ~63 dirt 0  
fill ~44 ~3 ~62 ~44 ~15 ~62 dirt 0 
setblock ~46 ~3 ~60 stone 0 
setblock ~46 ~3 ~64 stone 0  
fill ~47 ~3 ~59 ~51 ~3 ~59 stone 0  
fill ~47 ~3 ~62 ~47 ~17 ~62 ladder 5  
fill ~47 ~3 ~65 ~51 ~3 ~65 stone 0 
setblock ~52 ~3 ~60 stone 0 
setblock ~52 ~3 ~64 stone 0  
fill ~3 ~4 ~36 ~5 ~4 ~36 stone 0  
fill ~3 ~4 ~44 ~5 ~4 ~44 stone 0 
setblock ~3 ~4 ~53 double_stone_slab 0 
setblock ~3 ~4 ~65 double_stone_slab 0 
setblock ~4 ~4 ~22 double_stone_slab 0 
setblock ~4 ~4 ~26 double_stone_slab 0 
setblock ~4 ~4 ~52 double_stone_slab 0  
fill ~4 ~4 ~53 ~8 ~4 ~53 dirt 0  
fill ~4 ~4 ~54 ~8 ~4 ~54 dirt 0  
fill ~4 ~4 ~55 ~8 ~4 ~55 dirt 0  
fill ~4 ~4 ~56 ~8 ~4 ~56 dirt 0  
fill ~4 ~4 ~57 ~8 ~4 ~57 dirt 0  
fill ~4 ~4 ~58 ~8 ~4 ~58 dirt 0  
fill ~4 ~4 ~59 ~8 ~4 ~59 dirt 0  
fill ~4 ~4 ~60 ~8 ~4 ~60 dirt 0  
fill ~4 ~4 ~61 ~8 ~4 ~61 dirt 0  
fill ~4 ~4 ~62 ~8 ~4 ~62 dirt 0  
fill ~4 ~4 ~63 ~5 ~4 ~63 dirt 0  
fill ~4 ~4 ~64 ~5 ~4 ~64 dirt 0  
fill ~4 ~4 ~65 ~5 ~4 ~65 dirt 0 
setblock ~4 ~4 ~66 double_stone_slab 0 
setblock ~5 ~4 ~21 double_stone_slab 0  
fill ~5 ~4 ~22 ~9 ~4 ~22 dirt 0  
fill ~5 ~4 ~23 ~9 ~4 ~23 dirt 0  
fill ~5 ~4 ~24 ~9 ~4 ~24 dirt 0  
fill ~5 ~4 ~25 ~9 ~4 ~25 dirt 0  
fill ~5 ~4 ~26 ~9 ~4 ~26 dirt 0 
setblock ~5 ~4 ~27 double_stone_slab 0  
fill ~6 ~4 ~21 ~8 ~4 ~21 stone 0  
fill ~6 ~4 ~27 ~8 ~4 ~27 stone 0  
fill ~6 ~4 ~44 ~7 ~4 ~44 dirt 0  
fill ~6 ~4 ~52 ~8 ~4 ~52 dirt 0  
fill ~6 ~4 ~63 ~21 ~4 ~63 stone 0  
fill ~7 ~4 ~45 ~8 ~4 ~45 dirt 0  
fill ~7 ~4 ~50 ~8 ~4 ~50 dirt 0  
fill ~7 ~4 ~51 ~8 ~4 ~51 dirt 0  
fill ~7 ~4 ~66 ~7 ~7 ~66 log 0  
fill ~7 ~4 ~74 ~25 ~4 ~74 stone 0  
fill ~8 ~4 ~40 ~9 ~4 ~40 stone 0 
setblock ~8 ~4 ~41 cobblestone 0 
setblock ~8 ~4 ~42 redstone_wire 0 
setblock ~9 ~4 ~21 double_stone_slab 0 
setblock ~9 ~4 ~27 double_stone_slab 0 
setblock ~9 ~4 ~34 cobblestone 0  
fill ~9 ~4 ~41 ~9 ~9 ~41 stone 0 
setblock ~10 ~4 ~22 double_stone_slab 0 
setblock ~10 ~4 ~26 double_stone_slab 0 
setblock ~10 ~4 ~34 redstone_wire 0  
fill ~10 ~4 ~39 ~11 ~4 ~39 cobblestone 0  
fill ~10 ~4 ~40 ~11 ~4 ~40 cobblestone 0  
fill ~10 ~4 ~41 ~11 ~4 ~41 stone_stairs 3 
setblock ~10 ~4 ~64 brewing_stand 0 
setblock ~12 ~4 ~32 redstone_torch 5  
fill ~12 ~4 ~40 ~21 ~4 ~40 stone 0  
fill ~12 ~4 ~41 ~12 ~10 ~41 stone 0 
setblock ~12 ~4 ~46 torch 2 
setblock ~12 ~4 ~50 torch 2  
fill ~12 ~4 ~56 ~17 ~4 ~56 stone 0  
fill ~13 ~4 ~24 ~15 ~4 ~24 stone 0 
setblock ~13 ~4 ~32 redstone_wire 15 
setblock ~13 ~4 ~34 redstone_wire 0 
setblock ~13 ~4 ~41 cobblestone 0 
setblock ~13 ~4 ~42 redstone_wire 0  
fill ~13 ~4 ~66 ~13 ~7 ~66 log 0  
fill ~14 ~4 ~0 ~16 ~4 ~0 grass 0 
setblock ~14 ~4 ~32 redstone_wire 14  
fill ~14 ~4 ~33 ~14 ~4 ~36 cobblestone 0 
setblock ~14 ~4 ~46 torch 1 
setblock ~14 ~4 ~50 torch 1 
setblock ~15 ~4 ~32 unlit_redstone_torch 5 
setblock ~15 ~4 ~36 redstone_wire 0 
setblock ~15 ~4 ~44 torch 1 
setblock ~15 ~4 ~52 torch 1  
fill ~17 ~4 ~0 ~25 ~4 ~0 dirt 0 
setblock ~18 ~4 ~1 grass 0  
fill ~18 ~4 ~19 ~26 ~4 ~19 dirt 0  
fill ~18 ~4 ~20 ~26 ~4 ~20 dirt 0  
fill ~18 ~4 ~21 ~26 ~4 ~21 dirt 0  
fill ~18 ~4 ~22 ~26 ~4 ~22 dirt 0 
setblock ~18 ~4 ~56 stone_slab 0  
fill ~19 ~4 ~1 ~25 ~4 ~1 dirt 0 
setblock ~19 ~4 ~2 grass 0  
fill ~19 ~4 ~18 ~25 ~4 ~18 dirt 0  
fill ~19 ~4 ~56 ~19 ~7 ~56 stone 0  
fill ~19 ~4 ~66 ~19 ~7 ~66 log 0  
fill ~20 ~4 ~3 ~24 ~4 ~3 stone 0  
fill ~20 ~4 ~6 ~20 ~5 ~6 stone 0  
fill ~20 ~4 ~12 ~20 ~5 ~12 stone 0  
fill ~20 ~4 ~15 ~24 ~4 ~15 stone 0  
fill ~20 ~4 ~17 ~24 ~4 ~17 dirt 0  
fill ~20 ~4 ~37 ~24 ~4 ~37 stone 0 
setblock ~20 ~4 ~41 torch 3 
setblock ~20 ~4 ~56 stone_slab 0  
fill ~21 ~4 ~2 ~23 ~4 ~2 dirt 0  
fill ~21 ~4 ~4 ~23 ~4 ~4 dirt 0  
fill ~21 ~4 ~5 ~23 ~4 ~5 dirt 0  
fill ~21 ~4 ~6 ~23 ~4 ~6 cobblestone 0  
fill ~21 ~4 ~12 ~23 ~4 ~12 cobblestone 0  
fill ~21 ~4 ~13 ~23 ~4 ~13 dirt 0  
fill ~21 ~4 ~14 ~23 ~4 ~14 dirt 0  
fill ~21 ~4 ~16 ~23 ~4 ~16 dirt 0  
fill ~21 ~4 ~23 ~24 ~4 ~23 stone 0 
setblock ~21 ~4 ~41 lever 3  
fill ~21 ~4 ~56 ~21 ~7 ~56 stone 0  
fill ~21 ~4 ~62 ~21 ~5 ~62 fence 0  
fill ~21 ~4 ~64 ~21 ~5 ~64 fence 0 
setblock ~22 ~4 ~36 torch 4 
setblock ~22 ~4 ~38 torch 3 
setblock ~22 ~4 ~40 iron_door 9 
setblock ~22 ~4 ~56 stone_slab 0  
fill ~23 ~4 ~40 ~32 ~4 ~40 stone 0  
fill ~23 ~4 ~56 ~23 ~7 ~56 stone 0  
fill ~24 ~4 ~6 ~24 ~5 ~6 stone 0  
fill ~24 ~4 ~12 ~24 ~5 ~12 stone 0 
setblock ~24 ~4 ~41 torch 3 
setblock ~24 ~4 ~56 stone_slab 0  
fill ~24 ~4 ~62 ~24 ~5 ~62 fence 0  
fill ~24 ~4 ~63 ~35 ~4 ~63 stone 0  
fill ~24 ~4 ~64 ~24 ~5 ~64 fence 0 
setblock ~25 ~4 ~2 grass 0  
fill ~25 ~4 ~56 ~25 ~7 ~56 stone 0  
fill ~25 ~4 ~66 ~25 ~7 ~66 log 0 
setblock ~26 ~4 ~0 grass 0 
setblock ~26 ~4 ~56 stone_slab 0 
setblock ~27 ~4 ~0 tallgrass 0  
fill ~27 ~4 ~56 ~32 ~4 ~56 stone 0 
setblock ~28 ~4 ~66 double_stone_slab 0  
fill ~29 ~4 ~24 ~31 ~4 ~24 stone 0 
setblock ~29 ~4 ~32 unlit_redstone_torch 5 
setblock ~29 ~4 ~36 redstone_wire 0 
setblock ~29 ~4 ~44 torch 2 
setblock ~29 ~4 ~52 torch 2 
setblock ~30 ~4 ~32 redstone_wire 14  
fill ~30 ~4 ~33 ~30 ~4 ~36 cobblestone 0 
setblock ~30 ~4 ~46 torch 2 
setblock ~30 ~4 ~50 torch 2  
fill ~30 ~4 ~65 ~32 ~4 ~65 stone 0 
setblock ~31 ~4 ~32 redstone_wire 15 
setblock ~31 ~4 ~34 redstone_wire 0 
setblock ~31 ~4 ~41 cobblestone 0 
setblock ~31 ~4 ~42 redstone_wire 0 
setblock ~32 ~4 ~32 redstone_torch 5  
fill ~32 ~4 ~41 ~32 ~10 ~41 stone 0 
setblock ~32 ~4 ~46 torch 1 
setblock ~32 ~4 ~50 torch 1  
fill ~33 ~4 ~39 ~34 ~4 ~39 cobblestone 0  
fill ~33 ~4 ~40 ~34 ~4 ~40 cobblestone 0  
fill ~33 ~4 ~41 ~34 ~4 ~41 stone_stairs 3 
setblock ~33 ~4 ~65 double_stone_slab 0 
setblock ~34 ~4 ~22 double_stone_slab 0  
fill ~34 ~4 ~24 ~34 ~5 ~24 stone 0  
fill ~34 ~4 ~25 ~34 ~5 ~25 stone 0 
setblock ~34 ~4 ~26 double_stone_slab 0 
setblock ~34 ~4 ~34 redstone_wire 0 
setblock ~35 ~4 ~21 double_stone_slab 0  
fill ~35 ~4 ~22 ~39 ~4 ~22 dirt 0  
fill ~35 ~4 ~23 ~39 ~4 ~23 dirt 0  
fill ~35 ~4 ~24 ~39 ~4 ~24 dirt 0  
fill ~35 ~4 ~25 ~39 ~4 ~25 dirt 0  
fill ~35 ~4 ~26 ~39 ~4 ~26 dirt 0 
setblock ~35 ~4 ~27 double_stone_slab 0 
setblock ~35 ~4 ~34 cobblestone 0  
fill ~35 ~4 ~40 ~37 ~4 ~40 stone 0  
fill ~35 ~4 ~41 ~35 ~9 ~41 stone 0  
fill ~36 ~4 ~21 ~38 ~4 ~21 stone 0  
fill ~36 ~4 ~27 ~38 ~4 ~27 stone 0 
setblock ~36 ~4 ~41 cobblestone 0 
setblock ~36 ~4 ~42 redstone_wire 0  
fill ~36 ~4 ~45 ~37 ~4 ~45 dirt 0  
fill ~36 ~4 ~46 ~37 ~4 ~46 dirt 0  
fill ~36 ~4 ~50 ~37 ~4 ~50 dirt 0  
fill ~36 ~4 ~51 ~37 ~4 ~51 dirt 0  
fill ~36 ~4 ~52 ~38 ~4 ~52 dirt 0  
fill ~36 ~4 ~53 ~37 ~4 ~53 dirt 0  
fill ~36 ~4 ~54 ~37 ~4 ~54 dirt 0  
fill ~36 ~4 ~58 ~37 ~4 ~58 dirt 0  
fill ~36 ~4 ~59 ~37 ~4 ~59 dirt 0  
fill ~36 ~4 ~60 ~37 ~4 ~60 dirt 0  
fill ~36 ~4 ~61 ~38 ~4 ~61 dirt 0  
fill ~36 ~4 ~62 ~40 ~4 ~62 dirt 0  
fill ~36 ~4 ~63 ~38 ~4 ~63 dirt 0 
setblock ~39 ~4 ~21 double_stone_slab 0 
setblock ~39 ~4 ~27 double_stone_slab 0  
fill ~39 ~4 ~36 ~41 ~4 ~36 stone 0  
fill ~39 ~4 ~44 ~41 ~4 ~44 stone 0  
fill ~39 ~4 ~52 ~41 ~4 ~52 stone 0  
fill ~39 ~4 ~63 ~41 ~4 ~63 stone 0 
setblock ~40 ~4 ~22 double_stone_slab 0 
setblock ~40 ~4 ~26 double_stone_slab 0  
fill ~41 ~4 ~62 ~43 ~4 ~62 stone 0  
fill ~43 ~4 ~63 ~45 ~4 ~63 dirt 0 
setblock ~46 ~4 ~60 double_stone_slab 0 
setblock ~46 ~4 ~64 double_stone_slab 0 
setblock ~47 ~4 ~59 double_stone_slab 0 
setblock ~47 ~4 ~65 double_stone_slab 0  
fill ~48 ~4 ~59 ~50 ~4 ~59 stone 0  
fill ~48 ~4 ~65 ~50 ~4 ~65 stone 0 
setblock ~51 ~4 ~59 double_stone_slab 0 
setblock ~51 ~4 ~65 double_stone_slab 0 
setblock ~52 ~4 ~60 double_stone_slab 0 
setblock ~52 ~4 ~64 double_stone_slab 0  
fill ~3 ~5 ~36 ~5 ~5 ~36 stone 0  
fill ~3 ~5 ~44 ~5 ~5 ~44 stone 0 
setblock ~3 ~5 ~53 stone 0 
setblock ~3 ~5 ~65 stone 0 
setblock ~4 ~5 ~22 stone 0 
setblock ~4 ~5 ~26 stone 0 
setblock ~4 ~5 ~52 stone 0  
fill ~4 ~5 ~53 ~8 ~5 ~53 dirt 0  
fill ~4 ~5 ~54 ~8 ~5 ~54 dirt 0  
fill ~4 ~5 ~55 ~8 ~5 ~55 dirt 0  
fill ~4 ~5 ~56 ~8 ~5 ~56 dirt 0  
fill ~4 ~5 ~57 ~8 ~5 ~57 dirt 0  
fill ~4 ~5 ~58 ~8 ~5 ~58 dirt 0  
fill ~4 ~5 ~59 ~8 ~5 ~59 dirt 0  
fill ~4 ~5 ~60 ~8 ~5 ~60 dirt 0  
fill ~4 ~5 ~61 ~8 ~5 ~61 dirt 0  
fill ~4 ~5 ~62 ~8 ~5 ~62 dirt 0  
fill ~4 ~5 ~63 ~5 ~5 ~63 dirt 0  
fill ~4 ~5 ~64 ~5 ~5 ~64 dirt 0  
fill ~4 ~5 ~65 ~5 ~5 ~65 dirt 0 
setblock ~4 ~5 ~66 stone 0  
fill ~5 ~5 ~21 ~9 ~5 ~21 stone 0  
fill ~5 ~5 ~22 ~9 ~5 ~22 dirt 0  
fill ~5 ~5 ~23 ~9 ~5 ~23 dirt 0  
fill ~5 ~5 ~24 ~9 ~5 ~24 dirt 0  
fill ~5 ~5 ~25 ~9 ~5 ~25 dirt 0  
fill ~5 ~5 ~26 ~9 ~5 ~26 dirt 0  
fill ~5 ~5 ~27 ~9 ~5 ~27 stone 0  
fill ~6 ~5 ~44 ~7 ~5 ~44 dirt 0  
fill ~6 ~5 ~52 ~8 ~5 ~52 dirt 0  
fill ~6 ~5 ~63 ~21 ~5 ~63 stone 0  
fill ~7 ~5 ~45 ~8 ~5 ~45 dirt 0  
fill ~7 ~5 ~50 ~8 ~5 ~50 dirt 0  
fill ~7 ~5 ~51 ~8 ~5 ~51 dirt 0 
setblock ~7 ~5 ~67 torch 3 
setblock ~7 ~5 ~71 torch 1  
fill ~7 ~5 ~74 ~25 ~5 ~74 stone 0 
setblock ~8 ~5 ~34 cobblestone 0 
setblock ~8 ~5 ~40 cobblestone 0 
setblock ~8 ~5 ~41 redstone_wire 0 
setblock ~9 ~5 ~34 redstone_wire 0  
fill ~9 ~5 ~40 ~9 ~10 ~40 stone 0 
setblock ~9 ~5 ~64 torch 3 
setblock ~9 ~5 ~73 torch 4 
setblock ~10 ~5 ~22 stone 0 
setblock ~10 ~5 ~26 stone 0  
fill ~10 ~5 ~38 ~11 ~5 ~38 cobblestone 0  
fill ~10 ~5 ~39 ~11 ~5 ~39 cobblestone 0  
fill ~10 ~5 ~40 ~11 ~5 ~40 stone_stairs 3 
setblock ~10 ~5 ~48 torch 1 
setblock ~10 ~5 ~61 torch 1 
setblock ~11 ~5 ~55 torch 2 
setblock ~11 ~5 ~62 torch 4  
fill ~12 ~5 ~40 ~12 ~10 ~40 stone 0  
fill ~12 ~5 ~56 ~17 ~5 ~56 stone 0  
fill ~13 ~5 ~24 ~15 ~5 ~24 stone 0 
setblock ~13 ~5 ~40 cobblestone 0 
setblock ~13 ~5 ~41 redstone_wire 0 
setblock ~13 ~5 ~57 torch 3 
setblock ~13 ~5 ~64 torch 3 
setblock ~13 ~5 ~67 torch 3 
setblock ~13 ~5 ~73 torch 4 
setblock ~14 ~5 ~33 redstone_wire 13  
fill ~14 ~5 ~34 ~14 ~6 ~34 cobblestone 0 
setblock ~14 ~5 ~35 unlit_redstone_torch 3 
setblock ~14 ~5 ~36 redstone_wire 0  
fill ~14 ~5 ~40 ~30 ~5 ~40 stone 0 
setblock ~16 ~5 ~64 torch 3  
fill ~17 ~5 ~0 ~18 ~5 ~0 grass 0 
setblock ~17 ~5 ~57 torch 3  
fill ~18 ~5 ~19 ~26 ~5 ~19 dirt 0  
fill ~18 ~5 ~20 ~26 ~5 ~20 dirt 0  
fill ~18 ~5 ~21 ~26 ~5 ~21 dirt 0  
fill ~18 ~5 ~22 ~26 ~5 ~22 dirt 0  
fill ~19 ~5 ~0 ~24 ~5 ~0 dirt 0 
setblock ~19 ~5 ~1 grass 0  
fill ~19 ~5 ~18 ~25 ~5 ~18 dirt 0 
setblock ~19 ~5 ~57 torch 3 
setblock ~19 ~5 ~67 torch 3 
setblock ~19 ~5 ~73 torch 4  
fill ~20 ~5 ~1 ~24 ~5 ~1 dirt 0  
fill ~20 ~5 ~3 ~24 ~5 ~3 stone 0  
fill ~20 ~5 ~7 ~20 ~8 ~7 stone 0  
fill ~20 ~5 ~11 ~20 ~8 ~11 stone 0  
fill ~20 ~5 ~15 ~24 ~5 ~15 stone 0  
fill ~20 ~5 ~17 ~24 ~5 ~17 dirt 0  
fill ~20 ~5 ~37 ~24 ~5 ~37 stone 0 
setblock ~20 ~5 ~62 torch 4 
setblock ~20 ~5 ~64 torch 3  
fill ~21 ~5 ~2 ~23 ~5 ~2 dirt 0  
fill ~21 ~5 ~4 ~23 ~5 ~4 dirt 0  
fill ~21 ~5 ~5 ~23 ~5 ~5 dirt 0  
fill ~21 ~5 ~6 ~23 ~5 ~6 dirt 0  
fill ~21 ~5 ~7 ~23 ~5 ~7 cobblestone 0  
fill ~21 ~5 ~11 ~23 ~5 ~11 cobblestone 0  
fill ~21 ~5 ~12 ~23 ~5 ~12 dirt 0  
fill ~21 ~5 ~13 ~23 ~5 ~13 dirt 0  
fill ~21 ~5 ~14 ~23 ~5 ~14 dirt 0  
fill ~21 ~5 ~16 ~23 ~5 ~16 dirt 0  
fill ~21 ~5 ~23 ~24 ~5 ~23 stone 0 
setblock ~21 ~5 ~57 torch 3 
setblock ~23 ~5 ~57 torch 3 
setblock ~23 ~5 ~73 torch 4  
fill ~24 ~5 ~7 ~24 ~8 ~7 stone 0  
fill ~24 ~5 ~11 ~24 ~8 ~11 stone 0  
fill ~24 ~5 ~63 ~35 ~5 ~63 stone 0  
fill ~25 ~5 ~0 ~25 ~5 ~1 grass 0 
setblock ~25 ~5 ~57 torch 3 
setblock ~25 ~5 ~62 torch 4 
setblock ~25 ~5 ~64 torch 3 
setblock ~25 ~5 ~67 torch 3 
setblock ~25 ~5 ~71 torch 2 
setblock ~26 ~5 ~0 tallgrass 0  
fill ~27 ~5 ~56 ~32 ~5 ~56 stone 0 
setblock ~27 ~5 ~57 torch 3 
setblock ~28 ~5 ~66 stone 0  
fill ~29 ~5 ~24 ~31 ~5 ~24 stone 0 
setblock ~30 ~5 ~33 redstone_wire 13  
fill ~30 ~5 ~34 ~30 ~6 ~34 cobblestone 0 
setblock ~30 ~5 ~35 unlit_redstone_torch 3 
setblock ~30 ~5 ~36 redstone_wire 0  
fill ~30 ~5 ~65 ~33 ~5 ~65 stone 0 
setblock ~31 ~5 ~40 cobblestone 0 
setblock ~31 ~5 ~41 redstone_wire 0 
setblock ~31 ~5 ~57 torch 3  
fill ~32 ~5 ~40 ~32 ~10 ~40 stone 0  
fill ~33 ~5 ~38 ~34 ~5 ~38 cobblestone 0  
fill ~33 ~5 ~39 ~34 ~5 ~39 cobblestone 0  
fill ~33 ~5 ~40 ~34 ~5 ~40 stone_stairs 3 
setblock ~33 ~5 ~55 torch 1 
setblock ~33 ~5 ~62 torch 4 
setblock ~34 ~5 ~22 stone 0 
setblock ~34 ~5 ~26 stone 0 
setblock ~34 ~5 ~48 torch 2 
setblock ~34 ~5 ~61 torch 2  
fill ~35 ~5 ~21 ~39 ~5 ~21 stone 0  
fill ~35 ~5 ~22 ~39 ~5 ~22 dirt 0  
fill ~35 ~5 ~23 ~39 ~5 ~23 dirt 0  
fill ~35 ~5 ~24 ~39 ~5 ~24 dirt 0  
fill ~35 ~5 ~25 ~39 ~5 ~25 dirt 0  
fill ~35 ~5 ~26 ~39 ~5 ~26 dirt 0  
fill ~35 ~5 ~27 ~39 ~5 ~27 stone 0 
setblock ~35 ~5 ~34 redstone_wire 0  
fill ~35 ~5 ~40 ~35 ~10 ~40 stone 0 
setblock ~36 ~5 ~34 cobblestone 0 
setblock ~36 ~5 ~40 cobblestone 0 
setblock ~36 ~5 ~41 redstone_wire 0  
fill ~36 ~5 ~45 ~37 ~5 ~45 dirt 0  
fill ~36 ~5 ~46 ~37 ~5 ~46 dirt 0  
fill ~36 ~5 ~50 ~37 ~5 ~50 dirt 0  
fill ~36 ~5 ~51 ~37 ~5 ~51 dirt 0  
fill ~36 ~5 ~52 ~38 ~5 ~52 dirt 0  
fill ~36 ~5 ~53 ~37 ~5 ~53 dirt 0  
fill ~36 ~5 ~54 ~37 ~5 ~54 dirt 0  
fill ~36 ~5 ~58 ~37 ~5 ~58 dirt 0  
fill ~36 ~5 ~59 ~37 ~5 ~59 dirt 0  
fill ~36 ~5 ~60 ~37 ~5 ~60 dirt 0  
fill ~36 ~5 ~61 ~38 ~5 ~61 dirt 0  
fill ~36 ~5 ~62 ~40 ~5 ~62 dirt 0  
fill ~36 ~5 ~63 ~38 ~5 ~63 dirt 0  
fill ~39 ~5 ~36 ~41 ~5 ~36 stone 0  
fill ~39 ~5 ~44 ~41 ~5 ~44 stone 0  
fill ~39 ~5 ~52 ~41 ~5 ~52 stone 0  
fill ~39 ~5 ~63 ~41 ~5 ~63 stone 0 
setblock ~40 ~5 ~22 stone 0 
setblock ~40 ~5 ~26 stone 0  
fill ~41 ~5 ~62 ~43 ~5 ~62 stone 0  
fill ~43 ~5 ~63 ~45 ~5 ~63 dirt 0 
setblock ~46 ~5 ~60 stone 0 
setblock ~46 ~5 ~64 stone 0  
fill ~47 ~5 ~59 ~51 ~5 ~59 stone 0  
fill ~47 ~5 ~65 ~51 ~5 ~65 stone 0 
setblock ~52 ~5 ~60 stone 0 
setblock ~52 ~5 ~64 stone 0  
fill ~3 ~6 ~36 ~5 ~6 ~36 stone 0  
fill ~3 ~6 ~44 ~5 ~6 ~44 stone 0 
setblock ~3 ~6 ~53 double_stone_slab 0 
setblock ~3 ~6 ~65 double_stone_slab 0 
setblock ~4 ~6 ~22 double_stone_slab 0 
setblock ~4 ~6 ~26 double_stone_slab 0 
setblock ~4 ~6 ~52 double_stone_slab 0  
fill ~4 ~6 ~53 ~8 ~6 ~53 dirt 0  
fill ~4 ~6 ~54 ~8 ~6 ~54 dirt 0  
fill ~4 ~6 ~55 ~8 ~6 ~55 dirt 0  
fill ~4 ~6 ~56 ~8 ~6 ~56 dirt 0  
fill ~4 ~6 ~57 ~8 ~6 ~57 dirt 0  
fill ~4 ~6 ~58 ~8 ~6 ~58 dirt 0  
fill ~4 ~6 ~59 ~8 ~6 ~59 dirt 0  
fill ~4 ~6 ~60 ~8 ~6 ~60 dirt 0  
fill ~4 ~6 ~61 ~8 ~6 ~61 dirt 0  
fill ~4 ~6 ~62 ~8 ~6 ~62 dirt 0  
fill ~4 ~6 ~63 ~5 ~6 ~63 dirt 0  
fill ~4 ~6 ~64 ~5 ~6 ~64 dirt 0  
fill ~4 ~6 ~65 ~5 ~6 ~65 dirt 0 
setblock ~4 ~6 ~66 double_stone_slab 0 
setblock ~5 ~6 ~21 double_stone_slab 0  
fill ~5 ~6 ~22 ~9 ~6 ~22 cobblestone 0  
fill ~5 ~6 ~23 ~9 ~6 ~23 cobblestone 0  
fill ~5 ~6 ~24 ~9 ~6 ~24 cobblestone 0  
fill ~5 ~6 ~25 ~9 ~6 ~25 cobblestone 0  
fill ~5 ~6 ~26 ~9 ~6 ~26 cobblestone 0 
setblock ~5 ~6 ~27 double_stone_slab 0  
fill ~6 ~6 ~21 ~8 ~6 ~21 stone 0  
fill ~6 ~6 ~27 ~8 ~6 ~27 stone 0  
fill ~6 ~6 ~44 ~7 ~6 ~44 dirt 0  
fill ~6 ~6 ~52 ~8 ~6 ~52 dirt 0  
fill ~6 ~6 ~63 ~21 ~6 ~63 stone 0  
fill ~7 ~6 ~28 ~9 ~6 ~28 dirt 0  
fill ~7 ~6 ~29 ~9 ~6 ~29 dirt 0  
fill ~7 ~6 ~30 ~9 ~6 ~30 dirt 0  
fill ~7 ~6 ~34 ~7 ~6 ~38 dirt 0  
fill ~7 ~6 ~45 ~8 ~6 ~45 dirt 0  
fill ~7 ~6 ~50 ~8 ~6 ~50 dirt 0  
fill ~7 ~6 ~51 ~8 ~6 ~51 dirt 0  
fill ~7 ~6 ~74 ~25 ~6 ~74 stone 0  
fill ~8 ~6 ~31 ~9 ~6 ~31 dirt 0  
fill ~8 ~6 ~32 ~9 ~6 ~32 dirt 0  
fill ~8 ~6 ~33 ~9 ~6 ~33 dirt 0 
setblock ~8 ~6 ~34 redstone_wire 0 
setblock ~8 ~6 ~35 cobblestone 0  
fill ~8 ~6 ~36 ~9 ~6 ~36 dirt 0  
fill ~8 ~6 ~37 ~9 ~6 ~37 dirt 0  
fill ~8 ~6 ~38 ~9 ~6 ~38 stone 0 
setblock ~8 ~6 ~39 cobblestone 0 
setblock ~8 ~6 ~40 redstone_wire 0 
setblock ~9 ~6 ~21 double_stone_slab 0 
setblock ~9 ~6 ~27 double_stone_slab 0  
fill ~9 ~6 ~39 ~9 ~10 ~39 stone 0 
setblock ~10 ~6 ~22 double_stone_slab 0 
setblock ~10 ~6 ~26 double_stone_slab 0  
fill ~10 ~6 ~28 ~13 ~6 ~28 double_stone_slab 0  
fill ~10 ~6 ~29 ~13 ~6 ~29 double_stone_slab 0  
fill ~10 ~6 ~30 ~13 ~6 ~30 double_stone_slab 0  
fill ~10 ~6 ~31 ~11 ~6 ~31 double_stone_slab 0  
fill ~10 ~6 ~32 ~13 ~6 ~32 double_stone_slab 0  
fill ~10 ~6 ~33 ~13 ~6 ~33 double_stone_slab 0  
fill ~10 ~6 ~34 ~13 ~6 ~34 double_stone_slab 0  
fill ~10 ~6 ~35 ~11 ~6 ~35 double_stone_slab 0  
fill ~10 ~6 ~36 ~11 ~6 ~36 double_stone_slab 0  
fill ~10 ~6 ~37 ~11 ~6 ~37 double_stone_slab 0  
fill ~10 ~6 ~38 ~11 ~6 ~38 cobblestone 0  
fill ~10 ~6 ~39 ~11 ~6 ~39 stone_stairs 3  
fill ~11 ~6 ~24 ~12 ~6 ~24 cobblestone 0  
fill ~11 ~6 ~25 ~12 ~6 ~25 cobblestone 0  
fill ~11 ~6 ~26 ~12 ~6 ~26 cobblestone 0 
setblock ~11 ~6 ~27 double_stone_slab 0 
setblock ~12 ~6 ~27 dirt 0 
setblock ~12 ~6 ~31 dirt 0  
fill ~12 ~6 ~35 ~12 ~6 ~37 dirt 0  
fill ~12 ~6 ~38 ~13 ~6 ~38 stone 0  
fill ~12 ~6 ~39 ~12 ~10 ~39 stone 0  
fill ~12 ~6 ~46 ~12 ~7 ~46 stone 0  
fill ~12 ~6 ~50 ~12 ~7 ~50 stone 0  
fill ~12 ~6 ~56 ~17 ~6 ~56 stone 0  
fill ~13 ~6 ~24 ~15 ~6 ~24 stone 0  
fill ~13 ~6 ~25 ~14 ~6 ~25 dirt 0  
fill ~13 ~6 ~26 ~13 ~6 ~25 dirt 0  
fill ~13 ~6 ~27 ~20 ~6 ~27 double_stone_slab 0 
setblock ~13 ~6 ~31 double_stone_slab 0  
fill ~13 ~6 ~35 ~31 ~6 ~35 double_stone_slab 0  
fill ~13 ~6 ~36 ~13 ~6 ~37 dirt 0 
setblock ~13 ~6 ~39 cobblestone 0 
setblock ~13 ~6 ~40 redstone_wire 0  
fill ~13 ~6 ~46 ~13 ~21 ~46 dirt 0  
fill ~13 ~6 ~47 ~13 ~6 ~49 cobblestone 0  
fill ~13 ~6 ~50 ~13 ~8 ~50 dirt 0  
fill ~14 ~6 ~26 ~14 ~11 ~26 stone 0  
fill ~14 ~6 ~28 ~30 ~6 ~28 cobblestone 0  
fill ~14 ~6 ~29 ~30 ~6 ~29 cobblestone 0  
fill ~14 ~6 ~30 ~30 ~6 ~30 cobblestone 0  
fill ~14 ~6 ~31 ~30 ~6 ~31 cobblestone 0  
fill ~14 ~6 ~32 ~30 ~6 ~32 cobblestone 0  
fill ~14 ~6 ~33 ~30 ~6 ~33 cobblestone 0  
fill ~14 ~6 ~40 ~30 ~6 ~40 stone 0  
fill ~14 ~6 ~46 ~14 ~7 ~46 stone 0  
fill ~14 ~6 ~50 ~14 ~7 ~50 stone 0  
fill ~15 ~6 ~34 ~30 ~6 ~34 cobblestone 0  
fill ~18 ~6 ~19 ~26 ~6 ~19 cobblestone 0  
fill ~18 ~6 ~20 ~26 ~6 ~20 cobblestone 0  
fill ~18 ~6 ~21 ~26 ~6 ~21 cobblestone 0  
fill ~18 ~6 ~22 ~26 ~6 ~22 cobblestone 0  
fill ~19 ~6 ~0 ~20 ~6 ~0 grass 0 
setblock ~19 ~6 ~18 planks 0 
setblock ~20 ~6 ~1 grass 0  
fill ~20 ~6 ~3 ~20 ~2 ~3 stone 0 
setblock ~20 ~6 ~6 double_stone_slab 0  
fill ~20 ~6 ~8 ~20 ~8 ~8 stone 0  
fill ~20 ~6 ~9 ~20 ~8 ~9 stone 0  
fill ~20 ~6 ~10 ~20 ~8 ~10 stone 0 
setblock ~20 ~6 ~12 double_stone_slab 0  
fill ~20 ~6 ~15 ~20 ~0 ~15 stone 0  
fill ~20 ~6 ~17 ~24 ~6 ~17 cobblestone 0  
fill ~20 ~6 ~18 ~24 ~6 ~18 cobblestone 0  
fill ~20 ~6 ~36 ~24 ~6 ~36 dirt 0  
fill ~20 ~6 ~37 ~24 ~6 ~37 dirt 0  
fill ~20 ~6 ~38 ~24 ~6 ~38 stone 0  
fill ~20 ~6 ~39 ~24 ~6 ~39 stone 0  
fill ~21 ~6 ~0 ~23 ~6 ~0 stone_slab 3  
fill ~21 ~6 ~1 ~23 ~6 ~1 cobblestone 0  
fill ~21 ~6 ~2 ~23 ~6 ~2 cobblestone 0  
fill ~21 ~6 ~3 ~23 ~6 ~3 cobblestone 0  
fill ~21 ~6 ~4 ~23 ~6 ~4 cobblestone 0  
fill ~21 ~6 ~5 ~23 ~6 ~5 cobblestone 0  
fill ~21 ~6 ~6 ~23 ~6 ~6 cobblestone 0  
fill ~21 ~6 ~7 ~23 ~6 ~7 cobblestone 0  
fill ~21 ~6 ~8 ~23 ~6 ~8 cobblestone 0  
fill ~21 ~6 ~9 ~23 ~6 ~9 cobblestone 0  
fill ~21 ~6 ~10 ~23 ~6 ~10 cobblestone 0  
fill ~21 ~6 ~11 ~23 ~6 ~11 cobblestone 0  
fill ~21 ~6 ~12 ~23 ~6 ~12 cobblestone 0  
fill ~21 ~6 ~13 ~23 ~6 ~13 cobblestone 0  
fill ~21 ~6 ~14 ~23 ~6 ~14 cobblestone 0  
fill ~21 ~6 ~15 ~23 ~6 ~15 cobblestone 0  
fill ~21 ~6 ~16 ~23 ~6 ~16 cobblestone 0  
fill ~21 ~6 ~23 ~23 ~6 ~23 cobblestone 0  
fill ~21 ~6 ~24 ~23 ~6 ~24 cobblestone 0  
fill ~21 ~6 ~25 ~23 ~6 ~25 cobblestone 0  
fill ~21 ~6 ~26 ~23 ~6 ~26 cobblestone 0  
fill ~21 ~6 ~27 ~23 ~6 ~27 cobblestone 0 
setblock ~21 ~6 ~62 stone_stairs 0 
setblock ~21 ~6 ~64 stone_stairs 0  
fill ~24 ~6 ~0 ~24 ~6 ~1 grass 0 
setblock ~24 ~6 ~3 stone 0 
setblock ~24 ~6 ~6 double_stone_slab 0  
fill ~24 ~6 ~8 ~24 ~8 ~8 stone 0  
fill ~24 ~6 ~9 ~24 ~8 ~9 stone 0  
fill ~24 ~6 ~10 ~24 ~8 ~10 stone 0 
setblock ~24 ~6 ~12 double_stone_slab 0 
setblock ~24 ~6 ~15 stone 0  
fill ~24 ~6 ~23 ~24 ~13 ~23 stone 0  
fill ~24 ~6 ~27 ~31 ~6 ~27 double_stone_slab 0 
setblock ~24 ~6 ~62 stone_stairs 1  
fill ~24 ~6 ~63 ~35 ~6 ~63 stone 0 
setblock ~24 ~6 ~64 stone_stairs 1 
setblock ~25 ~6 ~18 planks 0  
fill ~27 ~6 ~56 ~32 ~6 ~56 stone 0 
setblock ~28 ~6 ~66 double_stone_slab 0  
fill ~29 ~6 ~24 ~31 ~6 ~24 stone 0  
fill ~30 ~6 ~25 ~30 ~7 ~25 dirt 0  
fill ~30 ~6 ~26 ~31 ~6 ~26 dirt 0  
fill ~30 ~6 ~46 ~30 ~7 ~46 stone 0  
fill ~30 ~6 ~50 ~30 ~7 ~50 stone 0  
fill ~30 ~6 ~65 ~32 ~6 ~65 stone 0  
fill ~31 ~6 ~25 ~39 ~6 ~25 cobblestone 0  
fill ~31 ~6 ~28 ~34 ~6 ~28 double_stone_slab 0  
fill ~31 ~6 ~29 ~34 ~6 ~29 double_stone_slab 0  
fill ~31 ~6 ~30 ~34 ~6 ~30 double_stone_slab 0  
fill ~31 ~6 ~31 ~31 ~6 ~35 double_stone_slab 0  
fill ~31 ~6 ~36 ~32 ~6 ~36 dirt 0  
fill ~31 ~6 ~37 ~32 ~6 ~37 dirt 0  
fill ~31 ~6 ~38 ~32 ~6 ~38 stone 0 
setblock ~31 ~6 ~39 cobblestone 0 
setblock ~31 ~6 ~40 redstone_wire 0  
fill ~31 ~6 ~46 ~31 ~21 ~46 dirt 0  
fill ~31 ~6 ~47 ~31 ~6 ~49 cobblestone 0  
fill ~31 ~6 ~50 ~31 ~8 ~50 dirt 0  
fill ~32 ~6 ~24 ~39 ~6 ~24 cobblestone 0  
fill ~32 ~6 ~26 ~33 ~6 ~26 cobblestone 0 
setblock ~32 ~6 ~27 dirt 0 
setblock ~32 ~6 ~31 dirt 0  
fill ~32 ~6 ~32 ~34 ~6 ~32 double_stone_slab 0  
fill ~32 ~6 ~33 ~34 ~6 ~33 double_stone_slab 0  
fill ~32 ~6 ~34 ~34 ~6 ~34 double_stone_slab 0 
setblock ~32 ~6 ~35 dirt 0  
fill ~32 ~6 ~39 ~32 ~10 ~39 stone 0  
fill ~32 ~6 ~46 ~32 ~7 ~46 stone 0  
fill ~32 ~6 ~50 ~32 ~7 ~50 stone 0 
setblock ~33 ~6 ~27 cobblestone 0  
fill ~33 ~6 ~31 ~34 ~6 ~31 double_stone_slab 0  
fill ~33 ~6 ~35 ~34 ~6 ~35 double_stone_slab 0  
fill ~33 ~6 ~36 ~34 ~6 ~36 double_stone_slab 0  
fill ~33 ~6 ~37 ~34 ~6 ~37 double_stone_slab 0  
fill ~33 ~6 ~38 ~34 ~6 ~38 cobblestone 0  
fill ~33 ~6 ~39 ~34 ~6 ~39 stone_stairs 3 
setblock ~33 ~6 ~65 double_stone_slab 0 
setblock ~34 ~6 ~22 double_stone_slab 0  
fill ~34 ~6 ~23 ~39 ~6 ~23 cobblestone 0 
setblock ~34 ~6 ~26 double_stone_slab 0 
setblock ~35 ~6 ~21 double_stone_slab 0  
fill ~35 ~6 ~22 ~39 ~6 ~22 cobblestone 0  
fill ~35 ~6 ~26 ~39 ~6 ~26 cobblestone 0 
setblock ~35 ~6 ~27 double_stone_slab 0  
fill ~35 ~6 ~28 ~37 ~6 ~28 dirt 0  
fill ~35 ~6 ~29 ~37 ~6 ~29 dirt 0  
fill ~35 ~6 ~30 ~37 ~6 ~30 dirt 0  
fill ~35 ~6 ~31 ~36 ~6 ~31 dirt 0  
fill ~35 ~6 ~32 ~36 ~6 ~32 dirt 0  
fill ~35 ~6 ~33 ~36 ~6 ~33 dirt 0  
fill ~35 ~6 ~35 ~35 ~6 ~37 dirt 0  
fill ~35 ~6 ~38 ~36 ~6 ~38 stone 0  
fill ~35 ~6 ~39 ~35 ~10 ~39 stone 0  
fill ~36 ~6 ~21 ~38 ~6 ~21 stone 0  
fill ~36 ~6 ~27 ~38 ~6 ~27 stone 0 
setblock ~36 ~6 ~34 redstone_wire 0 
setblock ~36 ~6 ~35 cobblestone 0  
fill ~36 ~6 ~36 ~38 ~6 ~36 dirt 0  
fill ~36 ~6 ~37 ~37 ~6 ~37 dirt 0 
setblock ~36 ~6 ~39 cobblestone 0 
setblock ~36 ~6 ~40 redstone_wire 0  
fill ~36 ~6 ~45 ~37 ~6 ~45 dirt 0  
fill ~36 ~6 ~46 ~37 ~6 ~46 dirt 0  
fill ~36 ~6 ~50 ~37 ~6 ~50 dirt 0  
fill ~36 ~6 ~51 ~37 ~6 ~51 dirt 0  
fill ~36 ~6 ~52 ~38 ~6 ~52 dirt 0  
fill ~36 ~6 ~53 ~37 ~6 ~53 dirt 0  
fill ~36 ~6 ~54 ~37 ~6 ~54 dirt 0  
fill ~36 ~6 ~58 ~37 ~6 ~58 dirt 0  
fill ~36 ~6 ~59 ~37 ~6 ~59 dirt 0  
fill ~36 ~6 ~60 ~37 ~6 ~60 dirt 0  
fill ~36 ~6 ~61 ~38 ~6 ~61 dirt 0  
fill ~36 ~6 ~62 ~40 ~6 ~62 dirt 0  
fill ~36 ~6 ~63 ~38 ~6 ~63 dirt 0  
fill ~37 ~6 ~34 ~37 ~6 ~38 dirt 0 
setblock ~39 ~6 ~21 double_stone_slab 0 
setblock ~39 ~6 ~27 double_stone_slab 0  
fill ~39 ~6 ~36 ~41 ~6 ~36 stone 0  
fill ~39 ~6 ~44 ~41 ~6 ~44 stone 0  
fill ~39 ~6 ~52 ~41 ~6 ~52 stone 0  
fill ~39 ~6 ~63 ~41 ~6 ~63 stone 0 
setblock ~40 ~6 ~22 double_stone_slab 0 
setblock ~40 ~6 ~26 double_stone_slab 0  
fill ~41 ~6 ~62 ~43 ~6 ~62 stone 0  
fill ~43 ~6 ~63 ~45 ~6 ~63 dirt 0 
setblock ~46 ~6 ~60 double_stone_slab 0 
setblock ~46 ~6 ~64 double_stone_slab 0 
setblock ~47 ~6 ~59 double_stone_slab 0 
setblock ~47 ~6 ~65 double_stone_slab 0  
fill ~48 ~6 ~59 ~50 ~6 ~59 stone 0  
fill ~48 ~6 ~65 ~50 ~6 ~65 stone 0 
setblock ~51 ~6 ~59 double_stone_slab 0 
setblock ~51 ~6 ~65 double_stone_slab 0 
setblock ~52 ~6 ~60 double_stone_slab 0 
setblock ~52 ~6 ~64 double_stone_slab 0  
fill ~3 ~7 ~36 ~5 ~7 ~36 stone 0  
fill ~3 ~7 ~44 ~5 ~7 ~44 stone 0 
setblock ~3 ~7 ~53 stone 0 
setblock ~3 ~7 ~65 stone 0 
setblock ~4 ~7 ~22 stone 0 
setblock ~4 ~7 ~26 stone 0 
setblock ~4 ~7 ~52 stone 0  
fill ~4 ~7 ~53 ~8 ~7 ~53 dirt 0  
fill ~4 ~7 ~54 ~8 ~7 ~54 dirt 0  
fill ~4 ~7 ~55 ~8 ~7 ~55 dirt 0  
fill ~4 ~7 ~56 ~8 ~7 ~56 dirt 0  
fill ~4 ~7 ~57 ~8 ~7 ~57 dirt 0  
fill ~4 ~7 ~58 ~8 ~7 ~58 dirt 0  
fill ~4 ~7 ~59 ~8 ~7 ~59 dirt 0  
fill ~4 ~7 ~60 ~8 ~7 ~60 dirt 0  
fill ~4 ~7 ~61 ~8 ~7 ~61 dirt 0  
fill ~4 ~7 ~62 ~8 ~7 ~62 dirt 0  
fill ~4 ~7 ~63 ~5 ~7 ~63 dirt 0  
fill ~4 ~7 ~64 ~5 ~7 ~64 dirt 0  
fill ~4 ~7 ~65 ~5 ~7 ~65 dirt 0 
setblock ~4 ~7 ~66 stone 0  
fill ~5 ~7 ~21 ~9 ~7 ~21 stone 0  
fill ~5 ~7 ~27 ~9 ~7 ~27 stone 0  
fill ~6 ~7 ~44 ~7 ~7 ~44 dirt 0  
fill ~6 ~7 ~52 ~8 ~7 ~52 dirt 0  
fill ~6 ~7 ~63 ~35 ~7 ~63 stone 0  
fill ~7 ~7 ~28 ~8 ~7 ~28 dirt 0  
fill ~7 ~7 ~29 ~8 ~7 ~29 dirt 0  
fill ~7 ~7 ~30 ~8 ~7 ~30 dirt 0 
setblock ~7 ~7 ~35 cobblestone 0  
fill ~7 ~7 ~36 ~8 ~7 ~36 dirt 0 
setblock ~7 ~7 ~37 cobblestone 0  
fill ~7 ~7 ~38 ~7 ~8 ~38 dirt 0  
fill ~7 ~7 ~45 ~8 ~7 ~45 dirt 0  
fill ~7 ~7 ~50 ~8 ~7 ~50 dirt 0  
fill ~7 ~7 ~51 ~8 ~7 ~51 dirt 0 
setblock ~7 ~7 ~67 stone_button 3  
fill ~7 ~7 ~74 ~25 ~7 ~74 stone 0  
fill ~8 ~7 ~31 ~8 ~15 ~31 dirt 0  
fill ~8 ~7 ~32 ~8 ~15 ~32 dirt 0  
fill ~8 ~7 ~33 ~8 ~15 ~33 dirt 0 
setblock ~8 ~7 ~35 redstone_wire 0  
fill ~8 ~7 ~37 ~8 ~8 ~37 dirt 0  
fill ~8 ~7 ~38 ~9 ~7 ~38 wool 0 
setblock ~8 ~7 ~39 redstone_torch 5  
fill ~8 ~7 ~66 ~8 ~8 ~66 log 0  
fill ~9 ~7 ~28 ~9 ~11 ~28 stone 0  
fill ~9 ~7 ~29 ~9 ~11 ~29 double_stone_slab 0  
fill ~9 ~7 ~30 ~9 ~11 ~30 stone 0  
fill ~9 ~7 ~31 ~9 ~11 ~31 stone 0  
fill ~9 ~7 ~32 ~9 ~11 ~32 stone 0  
fill ~9 ~7 ~33 ~9 ~11 ~33 stone 0  
fill ~9 ~7 ~34 ~9 ~11 ~34 stone 0  
fill ~9 ~7 ~35 ~9 ~11 ~35 double_stone_slab 0  
fill ~9 ~7 ~36 ~9 ~11 ~36 stone 0  
fill ~9 ~7 ~37 ~9 ~11 ~37 double_stone_slab 0 
setblock ~10 ~7 ~22 stone 0 
setblock ~10 ~7 ~26 stone 0  
fill ~10 ~7 ~38 ~11 ~7 ~38 stone 0 
setblock ~10 ~7 ~44 stone_brick_stairs 1 
setblock ~10 ~7 ~48 stone_brick_stairs 1 
setblock ~10 ~7 ~52 stone_brick_stairs 1 
setblock ~10 ~7 ~56 stone_brick_stairs 1 
setblock ~11 ~7 ~26 wooden_pressure_plate 0 
setblock ~11 ~7 ~27 wooden_door 1 
setblock ~11 ~7 ~44 stone_brick_stairs 0 
setblock ~11 ~7 ~48 stone_brick_stairs 0 
setblock ~11 ~7 ~52 stone_brick_stairs 0 
setblock ~11 ~7 ~56 stone_brick_stairs 0 
setblock ~12 ~7 ~27 double_stone_slab 0 
setblock ~12 ~7 ~31 double_stone_slab 0 
setblock ~12 ~7 ~35 double_stone_slab 0  
fill ~12 ~7 ~36 ~12 ~10 ~36 stone 0  
fill ~12 ~7 ~37 ~12 ~10 ~37 stone 0  
fill ~12 ~7 ~38 ~13 ~7 ~38 wool 0  
fill ~12 ~7 ~47 ~12 ~7 ~56 stone 0  
fill ~12 ~7 ~66 ~12 ~8 ~66 log 0  
fill ~13 ~7 ~24 ~15 ~7 ~24 stone 0  
fill ~13 ~7 ~25 ~13 ~7 ~26 stone 0  
fill ~13 ~7 ~36 ~17 ~7 ~36 cobblestone 0  
fill ~13 ~7 ~37 ~18 ~7 ~37 dirt 0 
setblock ~13 ~7 ~39 redstone_torch 5  
fill ~13 ~7 ~47 ~13 ~13 ~47 dirt 0  
fill ~13 ~7 ~48 ~13 ~9 ~48 dirt 0  
fill ~13 ~7 ~49 ~13 ~8 ~49 dirt 0  
fill ~13 ~7 ~56 ~32 ~7 ~56 stone 0 
setblock ~13 ~7 ~67 stone_button 3  
fill ~14 ~7 ~25 ~19 ~7 ~25 dirt 0  
fill ~14 ~7 ~38 ~30 ~7 ~38 dirt 0  
fill ~14 ~7 ~39 ~30 ~7 ~39 dirt 0  
fill ~14 ~7 ~40 ~30 ~7 ~40 stone 0  
fill ~14 ~7 ~47 ~14 ~7 ~56 stone 0  
fill ~14 ~7 ~66 ~14 ~8 ~66 log 0  
fill ~15 ~7 ~26 ~16 ~7 ~26 stone 0 
setblock ~15 ~7 ~43 stone_brick_stairs 1 
setblock ~15 ~7 ~44 stonebrick 0 
setblock ~15 ~7 ~45 stone_slab 5 
setblock ~15 ~7 ~51 stone_slab 5 
setblock ~15 ~7 ~52 stonebrick 0 
setblock ~15 ~7 ~53 stone_brick_stairs 1  
fill ~16 ~7 ~24 ~19 ~7 ~24 dirt 0 
setblock ~16 ~7 ~42 stone_slab 5  
fill ~16 ~7 ~44 ~17 ~7 ~44 stone_slab 5  
fill ~16 ~7 ~52 ~17 ~7 ~52 stone_slab 5 
setblock ~16 ~7 ~54 stone_slab 5  
fill ~17 ~7 ~19 ~17 ~7 ~22 stone_slab 0  
fill ~17 ~7 ~26 ~17 ~14 ~26 double_stone_slab 0 
setblock ~17 ~7 ~41 stone_brick_stairs 3 
setblock ~17 ~7 ~55 stone_brick_stairs 2 
setblock ~18 ~7 ~18 stone_slab 0  
fill ~18 ~7 ~26 ~18 ~14 ~26 stone 0  
fill ~18 ~7 ~36 ~18 ~9 ~36 stone 0 
setblock ~18 ~7 ~41 stonebrick 0  
fill ~18 ~7 ~42 ~18 ~7 ~43 stone_slab 5 
setblock ~18 ~7 ~44 stonebrick 0  
fill ~18 ~7 ~45 ~18 ~7 ~51 stone_slab 5 
setblock ~18 ~7 ~52 stonebrick 0  
fill ~18 ~7 ~53 ~18 ~7 ~54 stone_slab 5 
setblock ~18 ~7 ~55 stonebrick 0  
fill ~18 ~7 ~66 ~18 ~8 ~66 log 0 
setblock ~19 ~7 ~17 stone_slab 0  
fill ~19 ~7 ~18 ~19 ~9 ~18 fence 0  
fill ~19 ~7 ~26 ~19 ~14 ~26 double_stone_slab 0  
fill ~19 ~7 ~36 ~25 ~7 ~36 stone_slab 0  
fill ~19 ~7 ~37 ~25 ~7 ~37 double_stone_slab 0 
setblock ~19 ~7 ~41 stone_slab 5  
fill ~19 ~7 ~44 ~25 ~7 ~44 stone_slab 5  
fill ~19 ~7 ~52 ~25 ~7 ~52 stone_slab 5 
setblock ~19 ~7 ~55 stone_slab 5 
setblock ~19 ~7 ~67 stone_button 3 
setblock ~20 ~7 ~0 fence 0  
fill ~20 ~7 ~2 ~20 ~7 ~4 stone_slab 0 
setblock ~20 ~7 ~6 stone 0 
setblock ~20 ~7 ~12 stone 0  
fill ~20 ~7 ~14 ~20 ~7 ~16 stone_slab 0  
fill ~20 ~7 ~24 ~20 ~13 ~24 stone 0  
fill ~20 ~7 ~25 ~20 ~13 ~25 double_stone_slab 0  
fill ~20 ~7 ~26 ~20 ~13 ~26 stone 0  
fill ~20 ~7 ~66 ~20 ~8 ~66 log 0  
fill ~21 ~7 ~5 ~23 ~7 ~5 stone_slab 3  
fill ~21 ~7 ~6 ~23 ~7 ~6 cobblestone 0  
fill ~21 ~7 ~7 ~23 ~7 ~7 cobblestone 0  
fill ~21 ~7 ~8 ~23 ~7 ~8 cobblestone 0  
fill ~21 ~7 ~9 ~23 ~7 ~9 cobblestone 0  
fill ~21 ~7 ~10 ~23 ~7 ~10 cobblestone 0  
fill ~21 ~7 ~11 ~23 ~7 ~11 cobblestone 0  
fill ~21 ~7 ~12 ~23 ~7 ~12 cobblestone 0  
fill ~21 ~7 ~13 ~23 ~7 ~13 stone_slab 3  
fill ~22 ~7 ~62 ~23 ~7 ~62 stone_slab 3  
fill ~22 ~7 ~64 ~23 ~7 ~64 stone_slab 3  
fill ~24 ~7 ~2 ~24 ~7 ~4 stone_slab 0 
setblock ~24 ~7 ~6 stone 0 
setblock ~24 ~7 ~12 stone 0  
fill ~24 ~7 ~14 ~24 ~7 ~16 stone_slab 0  
fill ~24 ~7 ~24 ~24 ~13 ~24 stone 0  
fill ~24 ~7 ~25 ~24 ~13 ~25 double_stone_slab 0  
fill ~24 ~7 ~26 ~24 ~13 ~26 stone 0  
fill ~24 ~7 ~66 ~24 ~8 ~66 log 0 
setblock ~25 ~7 ~17 stone_slab 0  
fill ~25 ~7 ~18 ~25 ~9 ~18 fence 0  
fill ~25 ~7 ~24 ~28 ~7 ~24 dirt 0  
fill ~25 ~7 ~25 ~30 ~7 ~25 dirt 0  
fill ~25 ~7 ~26 ~25 ~14 ~26 double_stone_slab 0 
setblock ~25 ~7 ~41 stone_slab 5 
setblock ~25 ~7 ~55 stone_slab 5 
setblock ~25 ~7 ~67 stone_button 3 
setblock ~26 ~7 ~18 stone_slab 0  
fill ~26 ~7 ~26 ~26 ~14 ~26 stone 0  
fill ~26 ~7 ~36 ~26 ~9 ~36 stone 0  
fill ~26 ~7 ~37 ~31 ~7 ~37 dirt 0 
setblock ~26 ~7 ~41 stonebrick 0  
fill ~26 ~7 ~42 ~26 ~7 ~43 stone_slab 5 
setblock ~26 ~7 ~44 stonebrick 0  
fill ~26 ~7 ~45 ~26 ~7 ~51 stone_slab 5 
setblock ~26 ~7 ~52 stonebrick 0  
fill ~26 ~7 ~53 ~26 ~7 ~54 stone_slab 5 
setblock ~26 ~7 ~55 stonebrick 0  
fill ~27 ~7 ~19 ~27 ~7 ~22 stone_slab 0  
fill ~27 ~7 ~26 ~27 ~14 ~26 double_stone_slab 0  
fill ~27 ~7 ~36 ~31 ~7 ~36 cobblestone 0 
setblock ~27 ~7 ~41 stone_brick_stairs 3  
fill ~27 ~7 ~44 ~28 ~7 ~44 stone_slab 5  
fill ~27 ~7 ~52 ~28 ~7 ~52 stone_slab 5 
setblock ~27 ~7 ~55 stone_brick_stairs 2  
fill ~28 ~7 ~26 ~31 ~7 ~26 stone 0 
setblock ~28 ~7 ~42 stone_slab 5 
setblock ~28 ~7 ~54 stone_slab 5 
setblock ~28 ~7 ~66 stone 0  
fill ~29 ~7 ~24 ~31 ~7 ~24 stone 0 
setblock ~29 ~7 ~43 stone_brick_stairs 0 
setblock ~29 ~7 ~44 stonebrick 0 
setblock ~29 ~7 ~45 stone_slab 5 
setblock ~29 ~7 ~51 stone_slab 5 
setblock ~29 ~7 ~52 stonebrick 0 
setblock ~29 ~7 ~53 stone_brick_stairs 0  
fill ~30 ~7 ~47 ~30 ~7 ~56 stone 0  
fill ~30 ~7 ~65 ~33 ~7 ~65 stone 0 
setblock ~31 ~7 ~25 stone 0  
fill ~31 ~7 ~38 ~32 ~7 ~38 wool 0 
setblock ~31 ~7 ~39 redstone_torch 5  
fill ~31 ~7 ~41 ~31 ~8 ~41 dirt 0  
fill ~31 ~7 ~42 ~31 ~8 ~42 dirt 0  
fill ~31 ~7 ~43 ~31 ~8 ~43 dirt 0  
fill ~31 ~7 ~44 ~31 ~9 ~44 dirt 0  
fill ~31 ~7 ~45 ~31 ~21 ~45 dirt 0  
fill ~31 ~7 ~47 ~31 ~13 ~47 dirt 0  
fill ~31 ~7 ~48 ~31 ~9 ~48 dirt 0  
fill ~31 ~7 ~49 ~31 ~8 ~49 dirt 0 
setblock ~32 ~7 ~27 double_stone_slab 0 
setblock ~32 ~7 ~31 double_stone_slab 0 
setblock ~32 ~7 ~35 double_stone_slab 0  
fill ~32 ~7 ~36 ~32 ~10 ~36 stone 0  
fill ~32 ~7 ~37 ~32 ~10 ~37 stone 0  
fill ~32 ~7 ~47 ~32 ~7 ~56 stone 0 
setblock ~33 ~7 ~26 wooden_pressure_plate 0 
setblock ~33 ~7 ~27 wooden_door 1  
fill ~33 ~7 ~38 ~34 ~7 ~38 stone 0 
setblock ~33 ~7 ~44 stone_brick_stairs 1 
setblock ~33 ~7 ~48 stone_brick_stairs 1 
setblock ~33 ~7 ~52 stone_brick_stairs 1 
setblock ~33 ~7 ~56 stone_brick_stairs 1  
fill ~34 ~7 ~22 ~34 ~7 ~23 stone 0  
fill ~34 ~7 ~25 ~34 ~19 ~25 stone 0  
fill ~34 ~7 ~26 ~34 ~7 ~25 stone 0 
setblock ~34 ~7 ~44 stone_brick_stairs 0 
setblock ~34 ~7 ~48 stone_brick_stairs 0 
setblock ~34 ~7 ~52 stone_brick_stairs 0 
setblock ~34 ~7 ~56 stone_brick_stairs 0  
fill ~35 ~7 ~21 ~39 ~7 ~21 stone 0  
fill ~35 ~7 ~27 ~39 ~7 ~27 stone 0  
fill ~35 ~7 ~28 ~35 ~11 ~28 stone 0  
fill ~35 ~7 ~29 ~35 ~11 ~29 double_stone_slab 0  
fill ~35 ~7 ~30 ~35 ~11 ~30 stone 0  
fill ~35 ~7 ~31 ~35 ~11 ~31 stone 0  
fill ~35 ~7 ~32 ~35 ~11 ~32 stone 0  
fill ~35 ~7 ~33 ~35 ~11 ~33 stone 0  
fill ~35 ~7 ~34 ~35 ~11 ~34 stone 0  
fill ~35 ~7 ~35 ~35 ~11 ~35 double_stone_slab 0  
fill ~35 ~7 ~36 ~35 ~11 ~36 stone 0  
fill ~35 ~7 ~37 ~35 ~11 ~37 double_stone_slab 0  
fill ~35 ~7 ~38 ~36 ~7 ~38 wool 0  
fill ~36 ~7 ~28 ~37 ~7 ~28 dirt 0  
fill ~36 ~7 ~29 ~37 ~7 ~29 dirt 0  
fill ~36 ~7 ~30 ~37 ~7 ~30 dirt 0  
fill ~36 ~7 ~31 ~36 ~15 ~31 dirt 0  
fill ~36 ~7 ~32 ~36 ~15 ~32 dirt 0  
fill ~36 ~7 ~33 ~36 ~15 ~33 dirt 0 
setblock ~36 ~7 ~35 redstone_wire 0  
fill ~36 ~7 ~36 ~38 ~7 ~36 dirt 0  
fill ~36 ~7 ~37 ~37 ~7 ~37 dirt 0 
setblock ~36 ~7 ~39 redstone_torch 5  
fill ~36 ~7 ~41 ~36 ~15 ~41 dirt 0  
fill ~36 ~7 ~42 ~36 ~15 ~42 dirt 0  
fill ~36 ~7 ~43 ~36 ~15 ~43 dirt 0  
fill ~36 ~7 ~44 ~36 ~15 ~44 dirt 0  
fill ~36 ~7 ~45 ~37 ~7 ~45 dirt 0  
fill ~36 ~7 ~46 ~37 ~7 ~46 dirt 0  
fill ~36 ~7 ~50 ~37 ~7 ~50 dirt 0  
fill ~36 ~7 ~51 ~37 ~7 ~51 dirt 0  
fill ~36 ~7 ~52 ~38 ~7 ~52 dirt 0  
fill ~36 ~7 ~53 ~37 ~7 ~53 dirt 0  
fill ~36 ~7 ~54 ~37 ~7 ~54 dirt 0  
fill ~36 ~7 ~58 ~37 ~7 ~58 dirt 0  
fill ~36 ~7 ~59 ~37 ~7 ~59 dirt 0  
fill ~36 ~7 ~60 ~37 ~7 ~60 dirt 0  
fill ~36 ~7 ~61 ~38 ~7 ~61 dirt 0  
fill ~36 ~7 ~62 ~40 ~7 ~62 dirt 0  
fill ~36 ~7 ~63 ~38 ~7 ~63 dirt 0 
setblock ~37 ~7 ~34 torch 5 
setblock ~37 ~7 ~35 cobblestone 0  
fill ~37 ~7 ~38 ~37 ~8 ~38 dirt 0  
fill ~39 ~7 ~36 ~41 ~7 ~36 stone 0  
fill ~39 ~7 ~44 ~41 ~7 ~44 stone 0  
fill ~39 ~7 ~52 ~41 ~7 ~52 stone 0  
fill ~39 ~7 ~63 ~41 ~7 ~63 stone 0 
setblock ~40 ~7 ~22 stone 0 
setblock ~40 ~7 ~26 stone 0  
fill ~41 ~7 ~62 ~43 ~7 ~62 stone 0  
fill ~43 ~7 ~63 ~45 ~7 ~63 dirt 0 
setblock ~46 ~7 ~60 stone 0 
setblock ~46 ~7 ~64 stone 0  
fill ~47 ~7 ~59 ~51 ~7 ~59 stone 0  
fill ~47 ~7 ~65 ~51 ~7 ~65 stone 0 
setblock ~52 ~7 ~60 stone 0 
setblock ~52 ~7 ~64 stone 0  
fill ~3 ~8 ~36 ~5 ~8 ~36 stone 0  
fill ~3 ~8 ~44 ~5 ~8 ~44 stone 0 
setblock ~3 ~8 ~53 double_stone_slab 0 
setblock ~3 ~8 ~65 double_stone_slab 0 
setblock ~4 ~8 ~22 double_stone_slab 0 
setblock ~4 ~8 ~26 double_stone_slab 0 
setblock ~4 ~8 ~52 double_stone_slab 0  
fill ~4 ~8 ~53 ~9 ~8 ~53 dirt 0  
fill ~4 ~8 ~54 ~9 ~8 ~54 dirt 0  
fill ~4 ~8 ~55 ~9 ~8 ~55 dirt 0  
fill ~4 ~8 ~56 ~9 ~8 ~56 dirt 0  
fill ~4 ~8 ~57 ~9 ~8 ~57 dirt 0  
fill ~4 ~8 ~58 ~9 ~8 ~58 dirt 0  
fill ~4 ~8 ~59 ~9 ~8 ~59 dirt 0  
fill ~4 ~8 ~60 ~9 ~8 ~60 dirt 0  
fill ~4 ~8 ~61 ~9 ~8 ~61 dirt 0  
fill ~4 ~8 ~62 ~9 ~8 ~62 dirt 0  
fill ~4 ~8 ~63 ~5 ~8 ~63 dirt 0  
fill ~4 ~8 ~64 ~5 ~8 ~64 dirt 0  
fill ~4 ~8 ~65 ~5 ~8 ~65 dirt 0 
setblock ~4 ~8 ~66 double_stone_slab 0 
setblock ~5 ~8 ~21 double_stone_slab 0  
fill ~5 ~8 ~24 ~5 ~16 ~24 ladder 5 
setblock ~5 ~8 ~27 double_stone_slab 0  
fill ~6 ~8 ~21 ~8 ~8 ~21 stone 0  
fill ~6 ~8 ~27 ~8 ~8 ~27 stone 0  
fill ~6 ~8 ~44 ~9 ~8 ~44 dirt 0  
fill ~6 ~8 ~52 ~9 ~8 ~52 dirt 0  
fill ~6 ~8 ~63 ~9 ~8 ~63 stone 0  
fill ~7 ~8 ~28 ~8 ~8 ~28 dirt 0  
fill ~7 ~8 ~29 ~8 ~8 ~29 dirt 0  
fill ~7 ~8 ~30 ~8 ~8 ~30 dirt 0 
setblock ~7 ~8 ~35 redstone_wire 0 
setblock ~7 ~8 ~36 cobblestone 0 
setblock ~7 ~8 ~37 dirt 0  
fill ~7 ~8 ~45 ~9 ~8 ~45 dirt 0  
fill ~7 ~8 ~50 ~9 ~8 ~50 dirt 0  
fill ~7 ~8 ~51 ~9 ~8 ~51 dirt 0  
fill ~7 ~8 ~64 ~26 ~8 ~64 stone 0  
fill ~7 ~8 ~65 ~26 ~8 ~65 stone 0  
fill ~7 ~8 ~66 ~7 ~15 ~66 stone 0  
fill ~7 ~8 ~74 ~25 ~8 ~74 stone 0 
setblock ~8 ~8 ~36 dirt 0  
fill ~8 ~8 ~38 ~9 ~8 ~38 wool 0 
setblock ~8 ~8 ~39 dirt 0 
setblock ~8 ~8 ~40 cobblestone 0  
fill ~8 ~8 ~41 ~8 ~15 ~41 dirt 0  
fill ~8 ~8 ~42 ~8 ~15 ~42 dirt 0  
fill ~8 ~8 ~43 ~9 ~8 ~43 dirt 0 
setblock ~9 ~8 ~21 double_stone_slab 0 
setblock ~9 ~8 ~27 double_stone_slab 0  
fill ~9 ~8 ~46 ~9 ~15 ~46 dirt 0  
fill ~9 ~8 ~47 ~9 ~15 ~47 dirt 0  
fill ~9 ~8 ~48 ~9 ~15 ~48 dirt 0  
fill ~9 ~8 ~49 ~9 ~15 ~49 dirt 0  
fill ~9 ~8 ~66 ~12 ~8 ~66 log 0 
setblock ~10 ~8 ~22 double_stone_slab 0 
setblock ~10 ~8 ~26 double_stone_slab 0  
fill ~10 ~8 ~38 ~11 ~8 ~38 stone 0  
fill ~10 ~8 ~42 ~12 ~8 ~42 stone 0  
fill ~10 ~8 ~43 ~11 ~8 ~43 stone 0  
fill ~10 ~8 ~44 ~11 ~8 ~44 stone 0  
fill ~10 ~8 ~45 ~11 ~8 ~45 stone 0  
fill ~10 ~8 ~46 ~11 ~8 ~46 stone 0  
fill ~10 ~8 ~47 ~11 ~8 ~47 stone 0  
fill ~10 ~8 ~48 ~11 ~8 ~48 stone 0  
fill ~10 ~8 ~49 ~11 ~8 ~49 stone 0  
fill ~10 ~8 ~50 ~11 ~8 ~50 stone 0  
fill ~10 ~8 ~51 ~11 ~8 ~51 stone 0  
fill ~10 ~8 ~52 ~11 ~8 ~52 stone 0  
fill ~10 ~8 ~53 ~11 ~8 ~53 stone 0  
fill ~10 ~8 ~54 ~11 ~8 ~54 stone 0  
fill ~10 ~8 ~55 ~11 ~8 ~55 stone 0  
fill ~10 ~8 ~56 ~11 ~8 ~56 stone 0  
fill ~10 ~8 ~57 ~34 ~8 ~57 stone 0  
fill ~10 ~8 ~58 ~34 ~8 ~58 stone 0  
fill ~10 ~8 ~59 ~34 ~8 ~59 stone 0  
fill ~10 ~8 ~60 ~34 ~8 ~60 stone 0  
fill ~10 ~8 ~61 ~34 ~8 ~61 stone 0  
fill ~10 ~8 ~62 ~34 ~8 ~62 stone 0 
setblock ~11 ~8 ~27 wooden_door 9  
fill ~12 ~8 ~27 ~12 ~9 ~27 stone 0  
fill ~12 ~8 ~31 ~12 ~9 ~31 stone 0  
fill ~12 ~8 ~35 ~12 ~9 ~35 stone 0  
fill ~12 ~8 ~38 ~13 ~8 ~38 wool 0  
fill ~12 ~8 ~43 ~14 ~8 ~43 dirt 0  
fill ~12 ~8 ~44 ~14 ~8 ~44 dirt 0  
fill ~12 ~8 ~45 ~12 ~21 ~45 dirt 0  
fill ~12 ~8 ~46 ~12 ~21 ~46 dirt 0  
fill ~12 ~8 ~47 ~12 ~21 ~47 dirt 0  
fill ~12 ~8 ~48 ~12 ~9 ~48 dirt 0  
fill ~12 ~8 ~49 ~12 ~8 ~56 dirt 0  
fill ~13 ~8 ~24 ~15 ~8 ~24 stone 0 
setblock ~13 ~8 ~25 torch 5  
fill ~13 ~8 ~26 ~13 ~13 ~26 stone 0  
fill ~13 ~8 ~36 ~17 ~8 ~36 cobblestone 0  
fill ~13 ~8 ~37 ~17 ~8 ~37 dirt 0  
fill ~13 ~8 ~39 ~18 ~8 ~39 dirt 0  
fill ~13 ~8 ~40 ~30 ~8 ~40 dirt 0  
fill ~13 ~8 ~41 ~14 ~8 ~41 dirt 0  
fill ~13 ~8 ~42 ~14 ~8 ~42 dirt 0  
fill ~13 ~8 ~56 ~32 ~8 ~56 dirt 0  
fill ~13 ~8 ~66 ~13 ~15 ~66 stone 0 
setblock ~14 ~8 ~25 stone 0  
fill ~14 ~8 ~38 ~17 ~8 ~38 dirt 0  
fill ~14 ~8 ~45 ~14 ~21 ~45 dirt 0  
fill ~14 ~8 ~46 ~14 ~21 ~46 dirt 0  
fill ~14 ~8 ~47 ~14 ~13 ~47 dirt 0  
fill ~14 ~8 ~48 ~14 ~9 ~48 dirt 0  
fill ~14 ~8 ~49 ~14 ~8 ~56 dirt 0  
fill ~15 ~8 ~25 ~19 ~8 ~25 dirt 0  
fill ~15 ~8 ~26 ~16 ~8 ~26 stone 0  
fill ~15 ~8 ~41 ~29 ~8 ~41 stone 0  
fill ~15 ~8 ~42 ~29 ~8 ~42 stone 0  
fill ~15 ~8 ~43 ~29 ~8 ~43 stone 0  
fill ~15 ~8 ~44 ~29 ~8 ~44 stone 0  
fill ~15 ~8 ~45 ~29 ~8 ~45 stone 0  
fill ~15 ~8 ~46 ~29 ~8 ~46 stone 0  
fill ~15 ~8 ~47 ~29 ~8 ~47 stone 0  
fill ~15 ~8 ~48 ~29 ~8 ~48 stone 0  
fill ~15 ~8 ~49 ~29 ~8 ~49 stone 0  
fill ~15 ~8 ~50 ~29 ~8 ~50 stone 0  
fill ~15 ~8 ~51 ~29 ~8 ~51 stone 0  
fill ~15 ~8 ~52 ~29 ~8 ~52 stone 0  
fill ~15 ~8 ~53 ~29 ~8 ~53 stone 0  
fill ~15 ~8 ~54 ~29 ~8 ~54 stone 0  
fill ~15 ~8 ~55 ~29 ~8 ~55 stone 0  
fill ~15 ~8 ~66 ~18 ~8 ~66 log 0  
fill ~16 ~8 ~24 ~19 ~8 ~24 dirt 0 
setblock ~18 ~8 ~35 torch 4  
fill ~18 ~8 ~37 ~18 ~9 ~37 stone 0  
fill ~18 ~8 ~38 ~18 ~9 ~38 stone 0 
setblock ~19 ~8 ~9 torch 2  
fill ~19 ~8 ~38 ~25 ~8 ~38 stone_slab 0  
fill ~19 ~8 ~39 ~25 ~8 ~39 double_stone_slab 0  
fill ~19 ~8 ~66 ~19 ~15 ~66 stone 0 
setblock ~20 ~8 ~0 torch 5  
fill ~20 ~8 ~5 ~20 ~8 ~6 stone_slab 0  
fill ~20 ~8 ~12 ~20 ~8 ~13 stone_slab 0  
fill ~21 ~8 ~7 ~23 ~8 ~7 stone_slab 3  
fill ~21 ~8 ~8 ~23 ~8 ~8 cobblestone 0  
fill ~21 ~8 ~9 ~23 ~8 ~9 cobblestone 0  
fill ~21 ~8 ~10 ~23 ~8 ~10 cobblestone 0  
fill ~21 ~8 ~11 ~23 ~8 ~11 stone_slab 3  
fill ~21 ~8 ~66 ~24 ~8 ~66 log 0  
fill ~24 ~8 ~5 ~24 ~8 ~6 stone_slab 0  
fill ~24 ~8 ~12 ~24 ~8 ~13 stone_slab 0 
setblock ~25 ~8 ~9 torch 1  
fill ~25 ~8 ~24 ~28 ~8 ~24 dirt 0  
fill ~25 ~8 ~25 ~29 ~8 ~25 dirt 0  
fill ~25 ~8 ~66 ~25 ~21 ~66 stone 0 
setblock ~26 ~8 ~35 torch 4  
fill ~26 ~8 ~37 ~26 ~9 ~37 stone 0  
fill ~26 ~8 ~38 ~26 ~9 ~38 stone 0  
fill ~26 ~8 ~39 ~31 ~8 ~39 dirt 0 
setblock ~26 ~8 ~63 stone 0  
fill ~27 ~8 ~36 ~31 ~8 ~36 cobblestone 0  
fill ~27 ~8 ~37 ~31 ~8 ~37 dirt 0  
fill ~27 ~8 ~38 ~30 ~8 ~38 dirt 0  
fill ~28 ~8 ~26 ~31 ~8 ~26 stone 0 
setblock ~28 ~8 ~66 double_stone_slab 0  
fill ~29 ~8 ~24 ~31 ~8 ~24 stone 0 
setblock ~30 ~8 ~25 stone 0  
fill ~30 ~8 ~41 ~30 ~8 ~56 dirt 0  
fill ~30 ~8 ~65 ~32 ~8 ~65 stone 0 
setblock ~31 ~8 ~25 torch 5  
fill ~31 ~8 ~38 ~32 ~8 ~38 wool 0  
fill ~32 ~8 ~27 ~32 ~9 ~27 stone 0  
fill ~32 ~8 ~31 ~32 ~9 ~31 stone 0  
fill ~32 ~8 ~35 ~32 ~9 ~35 stone 0  
fill ~32 ~8 ~44 ~32 ~9 ~44 dirt 0  
fill ~32 ~8 ~45 ~32 ~21 ~45 dirt 0  
fill ~32 ~8 ~46 ~32 ~21 ~46 dirt 0  
fill ~32 ~8 ~47 ~32 ~21 ~47 dirt 0  
fill ~32 ~8 ~48 ~32 ~9 ~48 dirt 0  
fill ~32 ~8 ~49 ~32 ~8 ~56 dirt 0 
setblock ~33 ~8 ~27 wooden_door 9  
fill ~33 ~8 ~38 ~34 ~8 ~38 stone 0  
fill ~33 ~8 ~42 ~35 ~8 ~42 stone 0  
fill ~33 ~8 ~43 ~35 ~8 ~43 stone 0  
fill ~33 ~8 ~44 ~35 ~8 ~44 stone 0  
fill ~33 ~8 ~45 ~34 ~8 ~45 stone 0  
fill ~33 ~8 ~46 ~34 ~8 ~46 stone 0  
fill ~33 ~8 ~47 ~34 ~8 ~47 stone 0  
fill ~33 ~8 ~48 ~34 ~8 ~48 stone 0  
fill ~33 ~8 ~49 ~34 ~8 ~49 stone 0  
fill ~33 ~8 ~50 ~34 ~8 ~50 stone 0  
fill ~33 ~8 ~51 ~34 ~8 ~51 stone 0  
fill ~33 ~8 ~52 ~34 ~8 ~52 stone 0  
fill ~33 ~8 ~53 ~34 ~8 ~53 stone 0  
fill ~33 ~8 ~54 ~34 ~8 ~54 stone 0  
fill ~33 ~8 ~55 ~34 ~8 ~55 stone 0  
fill ~33 ~8 ~56 ~34 ~8 ~56 stone 0 
setblock ~33 ~8 ~65 double_stone_slab 0 
setblock ~34 ~8 ~22 double_stone_slab 0  
fill ~34 ~8 ~23 ~34 ~19 ~23 stone 0 
setblock ~34 ~8 ~26 double_stone_slab 0  
fill ~34 ~8 ~63 ~38 ~8 ~63 dirt 0 
setblock ~35 ~8 ~21 double_stone_slab 0 
setblock ~35 ~8 ~27 double_stone_slab 0  
fill ~35 ~8 ~38 ~36 ~8 ~38 wool 0  
fill ~35 ~8 ~45 ~37 ~8 ~45 dirt 0  
fill ~35 ~8 ~46 ~37 ~8 ~46 dirt 0  
fill ~35 ~8 ~47 ~35 ~15 ~47 dirt 0  
fill ~35 ~8 ~48 ~35 ~15 ~48 dirt 0  
fill ~35 ~8 ~49 ~35 ~15 ~49 dirt 0  
fill ~35 ~8 ~50 ~37 ~8 ~50 dirt 0  
fill ~35 ~8 ~51 ~37 ~8 ~51 dirt 0  
fill ~35 ~8 ~52 ~38 ~8 ~52 dirt 0  
fill ~35 ~8 ~53 ~37 ~8 ~53 dirt 0  
fill ~35 ~8 ~54 ~37 ~8 ~54 dirt 0  
fill ~35 ~8 ~55 ~35 ~15 ~55 dirt 0  
fill ~35 ~8 ~56 ~35 ~15 ~56 dirt 0  
fill ~35 ~8 ~57 ~35 ~15 ~57 dirt 0  
fill ~35 ~8 ~58 ~37 ~8 ~58 dirt 0  
fill ~35 ~8 ~59 ~37 ~8 ~59 dirt 0  
fill ~35 ~8 ~60 ~37 ~8 ~60 dirt 0  
fill ~35 ~8 ~61 ~38 ~8 ~61 dirt 0  
fill ~35 ~8 ~62 ~40 ~8 ~62 dirt 0  
fill ~36 ~8 ~21 ~38 ~8 ~21 stone 0  
fill ~36 ~8 ~27 ~38 ~8 ~27 stone 0  
fill ~36 ~8 ~28 ~37 ~8 ~28 dirt 0  
fill ~36 ~8 ~29 ~37 ~8 ~29 dirt 0  
fill ~36 ~8 ~30 ~37 ~8 ~30 dirt 0  
fill ~36 ~8 ~36 ~36 ~6 ~36 dirt 0  
fill ~36 ~8 ~37 ~37 ~8 ~37 dirt 0 
setblock ~36 ~8 ~39 dirt 0 
setblock ~36 ~8 ~40 cobblestone 0 
setblock ~37 ~8 ~35 redstone_wire 0 
setblock ~37 ~8 ~36 cobblestone 0 
setblock ~39 ~8 ~21 double_stone_slab 0  
fill ~39 ~8 ~24 ~39 ~16 ~24 ladder 4 
setblock ~39 ~8 ~27 double_stone_slab 0  
fill ~39 ~8 ~36 ~41 ~8 ~36 stone 0  
fill ~39 ~8 ~44 ~41 ~8 ~44 stone 0  
fill ~39 ~8 ~52 ~41 ~8 ~52 stone 0  
fill ~39 ~8 ~63 ~41 ~8 ~63 stone 0 
setblock ~40 ~8 ~22 double_stone_slab 0 
setblock ~40 ~8 ~26 double_stone_slab 0  
fill ~41 ~8 ~62 ~43 ~8 ~62 stone 0  
fill ~43 ~8 ~63 ~45 ~8 ~63 dirt 0 
setblock ~46 ~8 ~60 double_stone_slab 0 
setblock ~46 ~8 ~64 double_stone_slab 0 
setblock ~47 ~8 ~59 double_stone_slab 0 
setblock ~47 ~8 ~65 double_stone_slab 0  
fill ~48 ~8 ~59 ~50 ~8 ~59 stone 0  
fill ~48 ~8 ~65 ~50 ~8 ~65 stone 0 
setblock ~51 ~8 ~59 double_stone_slab 0 
setblock ~51 ~8 ~65 double_stone_slab 0 
setblock ~52 ~8 ~60 double_stone_slab 0 
setblock ~52 ~8 ~64 double_stone_slab 0 
setblock ~3 ~9 ~36 stone_slab 0 
setblock ~3 ~9 ~44 stone_slab 0 
setblock ~3 ~9 ~53 stone 0 
setblock ~3 ~9 ~65 stone 0 
setblock ~4 ~9 ~22 stone 0 
setblock ~4 ~9 ~26 stone 0  
fill ~4 ~9 ~36 ~5 ~9 ~36 stone 0  
fill ~4 ~9 ~44 ~5 ~9 ~44 stone 0 
setblock ~4 ~9 ~52 stone 0  
fill ~4 ~9 ~53 ~9 ~9 ~53 cobblestone 0  
fill ~4 ~9 ~54 ~9 ~9 ~54 cobblestone 0  
fill ~4 ~9 ~55 ~9 ~9 ~55 cobblestone 0  
fill ~4 ~9 ~56 ~9 ~9 ~56 cobblestone 0  
fill ~4 ~9 ~57 ~9 ~9 ~57 cobblestone 0  
fill ~4 ~9 ~58 ~9 ~9 ~58 cobblestone 0  
fill ~4 ~9 ~59 ~9 ~9 ~59 cobblestone 0  
fill ~4 ~9 ~60 ~9 ~9 ~60 cobblestone 0  
fill ~4 ~9 ~61 ~9 ~9 ~61 cobblestone 0  
fill ~4 ~9 ~62 ~9 ~9 ~62 cobblestone 0  
fill ~4 ~9 ~63 ~9 ~9 ~63 cobblestone 0  
fill ~4 ~9 ~64 ~9 ~9 ~64 cobblestone 0  
fill ~4 ~9 ~65 ~9 ~9 ~65 cobblestone 0 
setblock ~4 ~9 ~66 stone 0  
fill ~5 ~9 ~21 ~9 ~9 ~21 stone 0  
fill ~5 ~9 ~27 ~9 ~9 ~27 stone 0 
setblock ~6 ~9 ~36 torch 5  
fill ~6 ~9 ~44 ~10 ~9 ~44 dirt 0  
fill ~6 ~9 ~52 ~10 ~9 ~52 dirt 0 
setblock ~7 ~9 ~22 torch 3 
setblock ~7 ~9 ~26 torch 4  
fill ~7 ~9 ~28 ~8 ~9 ~28 dirt 0  
fill ~7 ~9 ~29 ~8 ~9 ~29 dirt 0  
fill ~7 ~9 ~30 ~8 ~9 ~30 dirt 0 
setblock ~7 ~9 ~36 redstone_wire 0 
setblock ~7 ~9 ~38 torch 5  
fill ~7 ~9 ~45 ~17 ~9 ~45 dirt 0  
fill ~7 ~9 ~50 ~11 ~9 ~50 dirt 0  
fill ~7 ~9 ~51 ~12 ~9 ~51 dirt 0  
fill ~7 ~9 ~74 ~25 ~9 ~74 stone 0  
fill ~8 ~9 ~36 ~8 ~9 ~39 cobblestone 0 
setblock ~8 ~9 ~40 redstone_wire 0  
fill ~8 ~9 ~43 ~10 ~9 ~43 dirt 0  
fill ~8 ~9 ~66 ~28 ~9 ~66 stone 0 
setblock ~9 ~9 ~24 torch 2  
fill ~9 ~9 ~38 ~12 ~9 ~38 stone 0  
fill ~9 ~9 ~42 ~10 ~9 ~42 dirt 0 
setblock ~10 ~9 ~22 stone 0  
fill ~10 ~9 ~24 ~10 ~16 ~24 stone 0 
setblock ~10 ~9 ~26 stone 0 
setblock ~10 ~9 ~40 stone_button 1  
fill ~10 ~9 ~41 ~12 ~9 ~41 stone 0  
fill ~10 ~9 ~46 ~17 ~9 ~46 dirt 0  
fill ~10 ~9 ~47 ~19 ~9 ~47 dirt 0  
fill ~10 ~9 ~48 ~18 ~9 ~48 dirt 0  
fill ~10 ~9 ~49 ~11 ~9 ~49 dirt 0  
fill ~10 ~9 ~53 ~10 ~9 ~61 dirt 0  
fill ~10 ~9 ~62 ~10 ~8 ~62 stone 0  
fill ~10 ~9 ~63 ~10 ~9 ~62 stone 0 
setblock ~10 ~9 ~64 dirt 0  
fill ~11 ~9 ~27 ~11 ~11 ~27 stone 0 
setblock ~11 ~9 ~31 torch 2 
setblock ~11 ~9 ~35 torch 2  
fill ~11 ~9 ~52 ~12 ~9 ~52 double_stone_slab 0  
fill ~11 ~9 ~53 ~12 ~9 ~53 double_stone_slab 0  
fill ~11 ~9 ~54 ~20 ~9 ~54 double_stone_slab 0  
fill ~11 ~9 ~55 ~20 ~9 ~55 double_stone_slab 0  
fill ~11 ~9 ~56 ~12 ~9 ~56 double_stone_slab 0  
fill ~11 ~9 ~57 ~20 ~9 ~57 double_stone_slab 0  
fill ~11 ~9 ~58 ~20 ~9 ~58 double_stone_slab 0  
fill ~11 ~9 ~59 ~12 ~9 ~59 double_stone_slab 0  
fill ~11 ~9 ~60 ~20 ~9 ~60 double_stone_slab 0  
fill ~11 ~9 ~61 ~33 ~9 ~61 double_stone_slab 0  
fill ~11 ~9 ~62 ~12 ~9 ~62 double_stone_slab 0  
fill ~11 ~9 ~63 ~33 ~9 ~63 double_stone_slab 0  
fill ~11 ~9 ~64 ~33 ~9 ~64 double_stone_slab 0  
fill ~12 ~9 ~42 ~12 ~9 ~48 dirt 0  
fill ~12 ~9 ~49 ~15 ~9 ~49 stone 0  
fill ~12 ~9 ~50 ~15 ~9 ~50 stone 0  
fill ~13 ~9 ~24 ~15 ~9 ~24 stone 0  
fill ~13 ~9 ~25 ~13 ~10 ~25 stone 0 
setblock ~13 ~9 ~27 torch 1 
setblock ~13 ~9 ~31 torch 1 
setblock ~13 ~9 ~35 torch 1  
fill ~13 ~9 ~36 ~18 ~9 ~36 stone 0  
fill ~13 ~9 ~37 ~17 ~9 ~37 grass 0  
fill ~13 ~9 ~38 ~15 ~9 ~38 grass 0  
fill ~13 ~9 ~39 ~17 ~9 ~39 grass 0  
fill ~13 ~9 ~40 ~15 ~9 ~40 grass 0  
fill ~13 ~9 ~41 ~17 ~9 ~41 grass 0  
fill ~13 ~9 ~42 ~15 ~9 ~42 grass 0  
fill ~13 ~9 ~43 ~17 ~9 ~43 grass 0  
fill ~13 ~9 ~44 ~17 ~9 ~44 dirt 0  
fill ~13 ~9 ~51 ~14 ~9 ~51 stone 0 
setblock ~13 ~9 ~53 wool 15 
setblock ~13 ~9 ~56 wool 15 
setblock ~13 ~9 ~59 wool 15 
setblock ~13 ~9 ~62 wool 15  
fill ~14 ~9 ~25 ~19 ~9 ~25 dirt 0 
setblock ~14 ~9 ~52 dirt 0  
fill ~14 ~9 ~53 ~15 ~9 ~53 double_stone_slab 0  
fill ~14 ~9 ~56 ~15 ~9 ~56 double_stone_slab 0  
fill ~14 ~9 ~59 ~15 ~9 ~59 double_stone_slab 0  
fill ~14 ~9 ~62 ~15 ~9 ~62 double_stone_slab 0  
fill ~15 ~9 ~26 ~16 ~9 ~26 stone 0  
fill ~15 ~9 ~52 ~16 ~9 ~52 double_stone_slab 0  
fill ~16 ~9 ~24 ~19 ~9 ~24 dirt 0 
setblock ~16 ~9 ~38 log 0 
setblock ~16 ~9 ~40 log 0 
setblock ~16 ~9 ~42 log 0  
fill ~16 ~9 ~49 ~18 ~9 ~49 dirt 0  
fill ~16 ~9 ~50 ~18 ~9 ~50 dirt 0  
fill ~16 ~9 ~51 ~18 ~9 ~51 dirt 0 
setblock ~16 ~9 ~53 wool 15 
setblock ~16 ~9 ~56 wool 15 
setblock ~16 ~9 ~59 wool 15 
setblock ~16 ~9 ~62 wool 15 
setblock ~17 ~9 ~38 grass 0 
setblock ~17 ~9 ~40 grass 0 
setblock ~17 ~9 ~42 grass 0  
fill ~17 ~9 ~52 ~18 ~9 ~52 dirt 0 
setblock ~17 ~9 ~53 double_stone_slab 0  
fill ~17 ~9 ~56 ~18 ~9 ~56 double_stone_slab 0 
setblock ~17 ~9 ~59 double_stone_slab 0  
fill ~17 ~9 ~62 ~18 ~9 ~62 double_stone_slab 0  
fill ~18 ~9 ~39 ~18 ~9 ~41 stone 0  
fill ~18 ~9 ~42 ~26 ~9 ~42 cobblestone 0  
fill ~18 ~9 ~43 ~26 ~9 ~43 cobblestone 0  
fill ~18 ~9 ~44 ~26 ~9 ~44 cobblestone 0  
fill ~18 ~9 ~45 ~26 ~9 ~45 cobblestone 0  
fill ~18 ~9 ~46 ~26 ~9 ~46 cobblestone 0 
setblock ~18 ~9 ~53 dirt 0 
setblock ~18 ~9 ~59 dirt 0 
setblock ~18 ~9 ~65 dirt 0 
setblock ~19 ~9 ~38 torch 1  
fill ~19 ~9 ~40 ~25 ~9 ~40 stone_slab 0  
fill ~19 ~9 ~41 ~25 ~9 ~41 double_stone_slab 0  
fill ~19 ~9 ~48 ~25 ~9 ~48 double_stone_slab 0  
fill ~19 ~9 ~49 ~25 ~9 ~49 double_stone_slab 0 
setblock ~19 ~9 ~50 wool 15  
fill ~19 ~9 ~51 ~25 ~9 ~51 double_stone_slab 0  
fill ~19 ~9 ~52 ~20 ~9 ~52 double_stone_slab 0 
setblock ~19 ~9 ~53 wool 15 
setblock ~19 ~9 ~56 wool 15 
setblock ~19 ~9 ~59 wool 15 
setblock ~19 ~9 ~62 wool 15  
fill ~19 ~9 ~65 ~25 ~9 ~65 double_stone_slab 0  
fill ~20 ~9 ~7 ~20 ~9 ~11 stone_slab 0 
setblock ~20 ~9 ~22 torch 4 
setblock ~20 ~9 ~27 torch 3  
fill ~20 ~9 ~47 ~24 ~9 ~47 cobblestone 0  
fill ~20 ~9 ~50 ~21 ~9 ~50 double_stone_slab 0 
setblock ~20 ~9 ~53 double_stone_slab 0 
setblock ~20 ~9 ~56 double_stone_slab 0 
setblock ~20 ~9 ~59 double_stone_slab 0  
fill ~20 ~9 ~62 ~21 ~9 ~62 double_stone_slab 0  
fill ~21 ~9 ~24 ~23 ~9 ~24 stone_button 4  
fill ~21 ~9 ~25 ~23 ~9 ~25 planks 0  
fill ~21 ~9 ~26 ~23 ~9 ~26 stone_button 3  
fill ~21 ~9 ~52 ~23 ~9 ~52 wool 14  
fill ~21 ~9 ~53 ~23 ~9 ~53 wool 14  
fill ~21 ~9 ~54 ~23 ~9 ~54 wool 14  
fill ~21 ~9 ~55 ~23 ~9 ~55 wool 14  
fill ~21 ~9 ~56 ~23 ~9 ~56 wool 14  
fill ~21 ~9 ~57 ~23 ~9 ~57 wool 14  
fill ~21 ~9 ~58 ~23 ~9 ~58 wool 14  
fill ~21 ~9 ~59 ~23 ~9 ~59 wool 14  
fill ~21 ~9 ~60 ~23 ~9 ~60 wool 14 
setblock ~22 ~9 ~50 wool 15 
setblock ~22 ~9 ~62 dirt 0  
fill ~23 ~9 ~50 ~24 ~9 ~50 double_stone_slab 0  
fill ~23 ~9 ~62 ~24 ~9 ~62 double_stone_slab 0  
fill ~24 ~9 ~7 ~24 ~9 ~11 stone_slab 0 
setblock ~24 ~9 ~22 torch 4 
setblock ~24 ~9 ~27 torch 3  
fill ~24 ~9 ~52 ~25 ~9 ~52 double_stone_slab 0  
fill ~24 ~9 ~53 ~24 ~9 ~65 double_stone_slab 0  
fill ~25 ~9 ~24 ~28 ~9 ~24 dirt 0  
fill ~25 ~9 ~25 ~30 ~9 ~25 dirt 0 
setblock ~25 ~9 ~38 torch 2  
fill ~25 ~9 ~47 ~36 ~9 ~47 dirt 0 
setblock ~25 ~9 ~50 wool 15 
setblock ~25 ~9 ~53 wool 15  
fill ~25 ~9 ~54 ~33 ~9 ~54 double_stone_slab 0  
fill ~25 ~9 ~55 ~33 ~9 ~55 double_stone_slab 0 
setblock ~25 ~9 ~56 wool 15  
fill ~25 ~9 ~57 ~33 ~9 ~57 double_stone_slab 0  
fill ~25 ~9 ~58 ~33 ~9 ~58 double_stone_slab 0 
setblock ~25 ~9 ~59 wool 15  
fill ~25 ~9 ~60 ~33 ~9 ~60 double_stone_slab 0 
setblock ~25 ~9 ~62 wool 15  
fill ~26 ~9 ~39 ~26 ~9 ~41 stone 0  
fill ~26 ~9 ~48 ~36 ~9 ~48 dirt 0  
fill ~26 ~9 ~49 ~28 ~9 ~49 dirt 0  
fill ~26 ~9 ~50 ~28 ~9 ~50 dirt 0  
fill ~26 ~9 ~51 ~28 ~9 ~51 dirt 0  
fill ~26 ~9 ~52 ~27 ~9 ~52 dirt 0  
fill ~26 ~9 ~53 ~26 ~9 ~47 dirt 0  
fill ~26 ~9 ~56 ~27 ~9 ~56 double_stone_slab 0 
setblock ~26 ~9 ~59 dirt 0  
fill ~26 ~9 ~62 ~27 ~9 ~62 double_stone_slab 0  
fill ~27 ~9 ~36 ~32 ~9 ~36 stone 0  
fill ~27 ~9 ~37 ~31 ~9 ~37 grass 0  
fill ~27 ~9 ~38 ~27 ~9 ~43 grass 0  
fill ~27 ~9 ~44 ~38 ~9 ~44 dirt 0  
fill ~27 ~9 ~45 ~37 ~9 ~45 dirt 0  
fill ~27 ~9 ~46 ~37 ~9 ~46 dirt 0 
setblock ~27 ~9 ~53 double_stone_slab 0 
setblock ~27 ~9 ~59 double_stone_slab 0  
fill ~28 ~9 ~26 ~31 ~9 ~26 stone 0 
setblock ~28 ~9 ~38 log 0  
fill ~28 ~9 ~39 ~31 ~9 ~39 grass 0 
setblock ~28 ~9 ~40 log 0  
fill ~28 ~9 ~41 ~31 ~9 ~41 grass 0 
setblock ~28 ~9 ~42 log 0  
fill ~28 ~9 ~43 ~31 ~9 ~43 grass 0  
fill ~28 ~9 ~52 ~29 ~9 ~52 double_stone_slab 0 
setblock ~28 ~9 ~53 wool 15 
setblock ~28 ~9 ~56 wool 15 
setblock ~28 ~9 ~59 wool 15 
setblock ~28 ~9 ~62 wool 15  
fill ~29 ~9 ~24 ~31 ~9 ~24 stone 0  
fill ~29 ~9 ~38 ~31 ~9 ~38 grass 0  
fill ~29 ~9 ~40 ~31 ~9 ~40 grass 0  
fill ~29 ~9 ~42 ~31 ~9 ~42 grass 0  
fill ~29 ~9 ~49 ~32 ~9 ~49 stone 0  
fill ~29 ~9 ~50 ~32 ~9 ~50 stone 0  
fill ~29 ~9 ~53 ~30 ~9 ~53 double_stone_slab 0  
fill ~29 ~9 ~56 ~30 ~9 ~56 double_stone_slab 0  
fill ~29 ~9 ~59 ~30 ~9 ~59 double_stone_slab 0  
fill ~29 ~9 ~62 ~30 ~9 ~62 double_stone_slab 0  
fill ~30 ~9 ~51 ~31 ~9 ~51 stone 0 
setblock ~30 ~9 ~52 dirt 0  
fill ~30 ~9 ~65 ~33 ~9 ~65 stone 0  
fill ~31 ~9 ~25 ~31 ~10 ~25 stone 0 
setblock ~31 ~9 ~27 torch 2 
setblock ~31 ~9 ~31 torch 2 
setblock ~31 ~9 ~35 torch 2 
setblock ~31 ~9 ~53 wool 15 
setblock ~31 ~9 ~56 wool 15 
setblock ~31 ~9 ~59 wool 15 
setblock ~31 ~9 ~62 wool 15  
fill ~32 ~9 ~38 ~35 ~9 ~38 stone 0  
fill ~32 ~9 ~42 ~37 ~9 ~42 dirt 0  
fill ~32 ~9 ~43 ~37 ~9 ~43 dirt 0  
fill ~32 ~9 ~51 ~37 ~9 ~51 dirt 0  
