setblock ~14~1~0 minecraft:stone_brick_stairs 4
setblock ~14~2~0 minecraft:cobblestone_wall 1
fill ~15~1~0 ~23~1~0 minecraft:stone_brick_stairs 6
fill ~15~2~0 ~23~2~0 minecraft:cobblestone_wall 1
setblock ~24~1~0 minecraft:stone_brick_stairs 5
setblock ~24~2~0 minecraft:cobblestone_wall 1
setblock ~75~1~0 minecraft:stone_brick_stairs 4
setblock ~75~2~0 minecraft:cobblestone_wall 1
fill ~76~1~0 ~84~1~0 minecraft:stone_brick_stairs 6
fill ~76~2~0 ~84~2~0 minecraft:cobblestone_wall 1
fill ~85~1~0 ~85~1~1 minecraft:stone_brick_stairs 5
setblock ~85~2~0 minecraft:cobblestone_wall 1
setblock ~11~1~1 minecraft:stone_brick_stairs 4
setblock ~11~2~1 minecraft:cobblestone_wall 1
fill ~12~1~1 ~14~1~1 minecraft:stone_brick_stairs 6
fill ~12~2~1 ~13~2~1 minecraft:cobblestone_wall 1
setblock ~14~2~1 minecraft:cobblestone_wall 1
fill ~15~1~1 ~23~1~3 minecraft:stonebrick 0
fill ~24~1~1 ~26~1~1 minecraft:stone_brick_stairs 6
setblock ~24~2~1 minecraft:cobblestone_wall 1
fill ~25~2~1 ~26~2~1 minecraft:cobblestone_wall 1
setblock ~27~1~1 minecraft:stone_brick_stairs 5
setblock ~27~2~1 minecraft:cobblestone_wall 1
fill ~72~1~1 ~72~1~2 minecraft:stone_brick_stairs 4
setblock ~72~2~1 minecraft:cobblestone_wall 1
fill ~73~1~1 ~75~1~1 minecraft:stone_brick_stairs 6
fill ~73~2~1 ~74~2~1 minecraft:cobblestone_wall 1
setblock ~75~2~1 minecraft:cobblestone_wall 1
fill ~76~1~1 ~84~1~3 minecraft:stonebrick 0
setblock ~85~2~1 minecraft:cobblestone_wall 1
fill ~86~1~1 ~87~1~1 minecraft:stone_brick_stairs 6
fill ~86~2~1 ~87~2~1 minecraft:cobblestone_wall 1
setblock ~88~1~1 minecraft:stone_brick_stairs 5
setblock ~88~2~1 minecraft:cobblestone_wall 1
fill ~9~1~2 ~9~1~3 minecraft:stone_brick_stairs 4
setblock ~9~2~2 minecraft:cobblestone_wall 1
fill ~10~1~2 ~11~1~2 minecraft:stone_brick_stairs 6
setblock ~10~2~2 minecraft:cobblestone_wall 1
setblock ~11~2~2 minecraft:cobblestone_wall 1
fill ~12~1~2 ~14~1~4 minecraft:stonebrick 0
fill ~24~1~2 ~26~1~4 minecraft:stonebrick 0
fill ~27~1~2 ~28~1~2 minecraft:stone_brick_stairs 6
setblock ~27~2~2 minecraft:cobblestone_wall 1
setblock ~28~2~2 minecraft:cobblestone_wall 1
setblock ~29~1~2 minecraft:stone_brick_stairs 5
setblock ~29~2~2 minecraft:cobblestone_wall 1
setblock ~70~1~2 minecraft:stone_brick_stairs 4
setblock ~70~2~2 minecraft:cobblestone_wall 1
setblock ~71~1~2 minecraft:stone_brick_stairs 6
setblock ~71~2~2 minecraft:cobblestone_wall 1
setblock ~72~2~2 minecraft:cobblestone_wall 1
fill ~73~1~2 ~75~1~4 minecraft:stonebrick 0
fill ~85~1~2 ~87~1~4 minecraft:stonebrick 0
fill ~88~1~2 ~89~1~2 minecraft:stone_brick_stairs 6
setblock ~88~2~2 minecraft:cobblestone_wall 1
setblock ~89~2~2 minecraft:cobblestone_wall 1
setblock ~90~1~2 minecraft:stone_brick_stairs 5
setblock ~90~2~2 minecraft:cobblestone_wall 1
setblock ~8~1~3 minecraft:stone_brick_stairs 6
setblock ~8~2~3 minecraft:cobblestone_wall 1
setblock ~9~2~3 minecraft:cobblestone_wall 1
fill ~10~1~3 ~11~1~5 minecraft:stonebrick 0
fill ~27~1~3 ~28~1~5 minecraft:stonebrick 0
setblock ~29~1~3 minecraft:stone_brick_stairs 6
setblock ~29~2~3 minecraft:cobblestone_wall 1
setblock ~30~1~3 minecraft:stone_brick_stairs 5
setblock ~30~2~3 minecraft:cobblestone_wall 1
fill ~69~1~3 ~69~1~4 minecraft:stone_brick_stairs 4
setblock ~69~2~3 minecraft:cobblestone_wall 1
setblock ~70~1~3 minecraft:stone_brick_stairs 6
setblock ~70~2~3 minecraft:cobblestone_wall 1
fill ~71~1~3 ~72~1~5 minecraft:stonebrick 0
fill ~88~1~3 ~89~1~5 minecraft:stonebrick 0
setblock ~90~1~3 minecraft:stone_brick_stairs 6
setblock ~90~2~3 minecraft:cobblestone_wall 1
setblock ~91~1~3 minecraft:stone_brick_stairs 5
setblock ~91~2~3 minecraft:cobblestone_wall 1
setblock ~7~1~4 minecraft:stone_brick_stairs 6
setblock ~7~2~4 minecraft:cobblestone_wall 1
setblock ~8~1~4 minecraft:stone_brick_stairs 4
setblock ~8~2~4 minecraft:cobblestone_wall 1
fill ~9~1~4 ~9~1~6 minecraft:stonebrick 0
fill ~15~0~4 ~23~0~4 minecraft:glowstone
fill ~15~1~4 ~23~1~4 minecraft:stained_glass 7
fill ~29~1~4 ~29~1~6 minecraft:stonebrick 0
setblock ~30~1~4 minecraft:stone_brick_stairs 6
setblock ~30~2~4 minecraft:cobblestone_wall 1
setblock ~31~1~4 minecraft:stone_brick_stairs 5
setblock ~31~2~4 minecraft:cobblestone_wall 1
setblock ~68~1~4 minecraft:stone_brick_stairs 6
setblock ~68~2~4 minecraft:cobblestone_wall 1
setblock ~69~2~4 minecraft:cobblestone_wall 1
fill ~70~1~4 ~70~1~6 minecraft:stonebrick 0
fill ~76~0~4 ~84~0~4 minecraft:glowstone
fill ~76~1~4 ~84~1~4 minecraft:stained_glass 7
fill ~90~1~4 ~90~1~6 minecraft:stonebrick 0
setblock ~91~1~4 minecraft:stone_brick_stairs 6
setblock ~91~2~4 minecraft:cobblestone_wall 1
fill ~92~1~4 ~92~1~5 minecraft:stone_brick_stairs 5
setblock ~92~2~4 minecraft:cobblestone_wall 1
setblock ~6~1~5 minecraft:stone_brick_stairs 6
setblock ~6~2~5 minecraft:cobblestone_wall 1
setblock ~7~1~5 minecraft:stone_brick_stairs 4
setblock ~7~2~5 minecraft:cobblestone_wall 1
fill ~8~1~5 ~8~1~7 minecraft:stonebrick 0
fill ~12~0~5 ~14~0~5 minecraft:glowstone
fill ~12~1~5 ~14~1~5 minecraft:stained_glass 7
fill ~15~1~5 ~23~1~17 minecraft:stonebrick 0
fill ~24~0~5 ~26~0~5 minecraft:glowstone
fill ~24~1~5 ~26~1~5 minecraft:stained_glass 7
fill ~30~1~5 ~30~1~7 minecraft:stonebrick 0
fill ~31~1~5 ~44~1~5 minecraft:stone_brick_stairs 6
setblock ~31~2~5 minecraft:cobblestone_wall 1
fill ~32~2~5 ~44~2~5 minecraft:cobblestone_wall 1
setblock ~45~1~5 minecraft:stone_brick_stairs 4
setblock ~45~2~5 minecraft:cobblestone_wall 1
fill ~46~1~5 ~53~1~8 minecraft:stonebrick 0
setblock ~54~1~5 minecraft:stone_brick_stairs 5
setblock ~54~2~5 minecraft:cobblestone_wall 1
fill ~55~1~5 ~67~1~5 minecraft:stone_brick_stairs 6
fill ~55~2~5 ~67~2~5 minecraft:cobblestone_wall 1
setblock ~68~1~5 minecraft:stone_brick_stairs 4
setblock ~68~2~5 minecraft:cobblestone_wall 1
fill ~69~1~5 ~69~1~7 minecraft:stonebrick 0
fill ~73~0~5 ~75~0~5 minecraft:glowstone
fill ~73~1~5 ~75~1~5 minecraft:stained_glass 7
fill ~76~1~5 ~84~1~15 minecraft:stonebrick 0
fill ~85~0~5 ~87~0~5 minecraft:glowstone
fill ~85~1~5 ~87~1~5 minecraft:stained_glass 7
fill ~91~1~5 ~91~1~7 minecraft:stonebrick 0
setblock ~92~2~5 minecraft:cobblestone_wall 1
setblock ~93~1~5 minecraft:stone_brick_stairs 6
setblock ~93~2~5 minecraft:cobblestone_wall 1
setblock ~5~1~6 minecraft:stone_brick_stairs 6
setblock ~5~2~6 minecraft:cobblestone_wall 1
setblock ~6~1~6 minecraft:stone_brick_stairs 4
setblock ~6~2~6 minecraft:cobblestone_wall 1
fill ~7~1~6 ~7~1~8 minecraft:stonebrick 0
fill ~10~0~6 ~11~0~6 minecraft:glowstone
fill ~10~1~6 ~11~1~6 minecraft:stained_glass 7
fill ~12~1~6 ~14~1~91 minecraft:stonebrick 0
fill ~24~1~6 ~26~1~31 minecraft:stonebrick 0
fill ~27~0~6 ~28~0~6 minecraft:glowstone
fill ~27~1~6 ~28~1~6 minecraft:stained_glass 7
fill ~31~1~6 ~45~1~8 minecraft:stonebrick 0
fill ~54~1~6 ~68~1~8 minecraft:stonebrick 0
fill ~71~0~6 ~72~0~6 minecraft:glowstone
fill ~71~1~6 ~72~1~6 minecraft:stained_glass 7
fill ~73~1~6 ~75~1~31 minecraft:stonebrick 0
fill ~85~1~6 ~87~1~90 minecraft:stonebrick 0
fill ~88~0~6 ~89~0~6 minecraft:glowstone
fill ~88~1~6 ~89~1~6 minecraft:stained_glass 7
fill ~92~1~6 ~92~1~8 minecraft:stonebrick 0
setblock ~93~1~6 minecraft:stone_brick_stairs 5
setblock ~93~2~6 minecraft:cobblestone_wall 1
setblock ~94~1~6 minecraft:stone_brick_stairs 6
setblock ~94~2~6 minecraft:cobblestone_wall 1
setblock ~4~1~7 minecraft:stone_brick_stairs 6
setblock ~4~2~7 minecraft:cobblestone_wall 1
setblock ~5~1~7 minecraft:stone_brick_stairs 4
setblock ~5~2~7 minecraft:cobblestone_wall 1
fill ~6~1~7 ~6~1~10 minecraft:stonebrick 0
setblock ~9~0~7 minecraft:glowstone
setblock ~9~1~7 minecraft:stained_glass 7
fill ~10~1~7 ~11~1~29 minecraft:stonebrick 0
fill ~27~1~7 ~28~1~29 minecraft:stonebrick 0
setblock ~29~0~7 minecraft:glowstone
setblock ~29~1~7 minecraft:stained_glass 7
setblock ~70~0~7 minecraft:glowstone
setblock ~70~1~7 minecraft:stained_glass 7
fill ~71~1~7 ~72~1~29 minecraft:stonebrick 0
fill ~88~1~7 ~89~1~29 minecraft:stonebrick 0
setblock ~90~0~7 minecraft:glowstone
setblock ~90~1~7 minecraft:stained_glass 7
fill ~93~1~7 ~93~1~10 minecraft:stonebrick 0
setblock ~94~1~7 minecraft:stone_brick_stairs 5
setblock ~94~2~7 minecraft:cobblestone_wall 1
setblock ~95~1~7 minecraft:stone_brick_stairs 6
setblock ~95~2~7 minecraft:cobblestone_wall 1
setblock ~3~1~8 minecraft:stone_brick_stairs 6
setblock ~3~2~8 minecraft:cobblestone_wall 1
setblock ~4~1~8 minecraft:stone_brick_stairs 4
setblock ~4~2~8 minecraft:cobblestone_wall 1
fill ~5~1~8 ~5~1~13 minecraft:stonebrick 0
setblock ~8~0~8 minecraft:glowstone
setblock ~8~1~8 minecraft:stained_glass 7
fill ~9~1~8 ~9~1~28 minecraft:stonebrick 0
fill ~29~1~8 ~29~1~28 minecraft:stonebrick 0
setblock ~30~0~8 minecraft:glowstone
setblock ~30~1~8 minecraft:stained_glass 7
setblock ~69~0~8 minecraft:glowstone
setblock ~69~1~8 minecraft:stained_glass 7
fill ~70~1~8 ~70~1~28 minecraft:stonebrick 0
fill ~90~1~8 ~90~1~28 minecraft:stonebrick 0
setblock ~91~0~8 minecraft:glowstone
setblock ~91~1~8 minecraft:stained_glass 7
fill ~94~1~8 ~94~1~13 minecraft:stonebrick 0
setblock ~95~1~8 minecraft:stone_brick_stairs 5
setblock ~95~2~8 minecraft:cobblestone_wall 1
setblock ~96~1~8 minecraft:stone_brick_stairs 6
setblock ~96~2~8 minecraft:cobblestone_wall 1
fill ~3~1~9 ~3~1~10 minecraft:stone_brick_stairs 4
setblock ~3~2~9 minecraft:cobblestone_wall 1
fill ~4~1~9 ~4~1~27 minecraft:stonebrick 0
fill ~7~0~9 ~7~0~10 minecraft:glowstone
fill ~7~1~9 ~7~1~10 minecraft:stained_glass 7
fill ~8~1~9 ~8~1~27 minecraft:stonebrick 0
fill ~19~21~9 ~19~21~10 minecraft:planks 5
fill ~30~1~9 ~30~1~27 minecraft:stonebrick 0
fill ~31~0~9 ~67~0~9 minecraft:glowstone
fill ~31~1~9 ~68~1~9 minecraft:stained_glass 7
fill ~69~1~9 ~69~1~27 minecraft:stonebrick 0
fill ~80~21~9 ~80~21~10 minecraft:planks 5
fill ~91~1~9 ~91~1~27 minecraft:stonebrick 0
fill ~92~0~9 ~92~0~10 minecraft:glowstone
fill ~92~1~9 ~92~1~10 minecraft:stained_glass 7
fill ~95~1~9 ~95~1~27 minecraft:stonebrick 0
fill ~96~1~9 ~96~1~10 minecraft:stone_brick_stairs 5
setblock ~96~2~9 minecraft:cobblestone_wall 1
setblock ~2~1~10 minecraft:stone_brick_stairs 6
setblock ~2~2~10 minecraft:cobblestone_wall 1
setblock ~3~2~10 minecraft:cobblestone_wall 1
fill ~16~21~10 ~18~21~10 minecraft:planks 5
setblock ~17~12~10 minecraft:end_rod 0
setblock ~17~13~10 minecraft:stone_brick_stairs 4
fill ~17~14~10 ~21~14~10 minecraft:fence 5
fill ~18~13~10 ~20~13~10 minecraft:stone_brick_stairs 6
setblock ~18~20~10 minecraft:end_rod 0
fill ~19~22~10 ~19~22~11 minecraft:planks 5
fill ~20~21~10 ~22~21~10 minecraft:planks 5
setblock ~21~12~10 minecraft:end_rod 0
setblock ~21~13~10 minecraft:stone_brick_stairs 5
fill ~31~1~10 ~68~1~24 minecraft:stonebrick 0
fill ~77~21~10 ~79~21~10 minecraft:planks 5
setblock ~78~12~10 minecraft:end_rod 0
fill ~78~13~10 ~82~13~10 minecraft:stone_brick_stairs 6
fill ~78~14~10 ~82~14~10 minecraft:fence 5
fill ~80~22~10 ~80~22~11 minecraft:planks 5
fill ~81~21~10 ~83~21~10 minecraft:planks 5
setblock ~82~12~10 minecraft:end_rod 0
setblock ~96~2~10 minecraft:cobblestone_wall 1
setblock ~97~1~10 minecraft:stone_brick_stairs 6
setblock ~97~2~10 minecraft:cobblestone_wall 1
fill ~2~1~11 ~2~1~13 minecraft:stone_brick_stairs 4
fill ~2~2~11 ~2~2~12 minecraft:cobblestone_wall 1
fill ~3~1~11 ~3~1~25 minecraft:stonebrick 0
fill ~6~0~11 ~6~0~13 minecraft:glowstone
fill ~6~1~11 ~6~1~13 minecraft:stained_glass 7
fill ~7~1~11 ~7~1~25 minecraft:stonebrick 0
fill ~14~21~11 ~16~21~11 minecraft:planks 5
fill ~16~2~11 ~16~20~11 minecraft:cobblestone_wall 1
fill ~16~22~11 ~18~22~11 minecraft:planks 5
fill ~17~2~11 ~17~3~11 minecraft:cobblestone
fill ~17~4~11 ~18~5~11 minecraft:stonebrick 0
fill ~17~6~11 ~17~8~11 minecraft:stonebrick 0
fill ~17~9~11 ~18~9~11 minecraft:nether_brick
fill ~17~10~11 ~18~11~11 minecraft:stonebrick 0
fill ~17~12~11 ~17~18~11 minecraft:stonebrick 0
fill ~17~19~11 ~17~21~11 minecraft:cobblestone
fill ~18~2~11 ~18~3~11 minecraft:stonebrick 0
setblock ~18~6~11 minecraft:nether_brick
fill ~18~7~11 ~18~8~11 minecraft:stonebrick 0
setblock ~18~12~11 minecraft:nether_brick
fill ~18~13~11 ~21~13~11 minecraft:stonebrick 0
fill ~18~14~11 ~20~14~11 minecraft:stone_block_slab 0
fill ~18~16~11 ~18~17~11 minecraft:fence 5
fill ~18~18~11 ~18~21~11 minecraft:stonebrick 0
fill ~19~2~11 ~19~5~11 minecraft:nether_brick
setblock ~19~6~11 minecraft:double_stone_block_slab 0
fill ~19~7~11 ~19~8~11 minecraft:nether_brick
setblock ~19~9~11 minecraft:double_stone_block_slab 0
setblock ~19~11~11 minecraft:wall_banner 2
setblock ~19~12~11 minecraft:double_stone_block_slab 0
fill ~19~17~11 ~20~17~11 minecraft:fence 5
setblock ~19~18~11 minecraft:fence 5
fill ~19~19~11 ~20~21~11 minecraft:stonebrick 0
fill ~19~23~11 ~19~23~12 minecraft:planks 5
fill ~20~2~11 ~20~5~11 minecraft:stonebrick 0
setblock ~20~6~11 minecraft:nether_brick
fill ~20~7~11 ~21~8~11 minecraft:stonebrick 0
fill ~20~9~11 ~21~9~11 minecraft:nether_brick
fill ~20~10~11 ~21~11~11 minecraft:stonebrick 0
setblock ~20~12~11 minecraft:nether_brick
setblock ~20~16~11 minecraft:fence 5
fill ~20~18~11 ~21~18~11 minecraft:stonebrick 0
fill ~20~22~11 ~22~22~11 minecraft:planks 5
fill ~21~2~11 ~21~3~11 minecraft:cobblestone
fill ~21~4~11 ~21~6~11 minecraft:stonebrick 0
setblock ~21~12~11 minecraft:stonebrick 0
fill ~21~14~11 ~21~17~11 minecraft:stonebrick 0
fill ~21~19~11 ~21~21~11 minecraft:cobblestone
fill ~22~2~11 ~22~20~11 minecraft:cobblestone_wall 1
fill ~22~21~11 ~24~21~11 minecraft:planks 5
setblock ~75~20~11 minecraft:end_rod 0
fill ~75~21~11 ~77~21~11 minecraft:planks 5
fill ~77~2~11 ~77~20~11 minecraft:cobblestone_wall 1
fill ~77~22~11 ~79~22~11 minecraft:planks 5
fill ~78~2~11 ~78~3~11 minecraft:cobblestone
fill ~78~4~11 ~79~4~11 minecraft:double_stone_block_slab 0
fill ~78~5~11 ~79~5~11 minecraft:stonebrick 0
fill ~78~6~11 ~78~8~11 minecraft:stonebrick 0
fill ~78~9~11 ~79~9~11 minecraft:nether_brick
fill ~78~10~11 ~79~11~11 minecraft:stonebrick 0
fill ~78~12~11 ~78~18~11 minecraft:stonebrick 0
fill ~78~19~11 ~78~21~11 minecraft:cobblestone
fill ~79~2~11 ~79~3~11 minecraft:stonebrick 0
setblock ~79~6~11 minecraft:nether_brick
fill ~79~7~11 ~79~8~11 minecraft:stonebrick 0
fill ~79~12~11 ~79~13~11 minecraft:nether_brick
fill ~79~14~11 ~81~14~11 minecraft:stone_block_slab 0
fill ~79~16~11 ~79~17~11 minecraft:fence 5
fill ~79~18~11 ~79~21~11 minecraft:stonebrick 0
fill ~80~2~11 ~80~5~11 minecraft:nether_brick
setblock ~80~6~11 minecraft:double_stone_block_slab 0
fill ~80~7~11 ~80~8~11 minecraft:nether_brick
setblock ~80~9~11 minecraft:quartz_stairs 2
setblock ~80~11~11 minecraft:wall_banner 2
setblock ~80~12~11 minecraft:quartz_stairs 6
setblock ~80~13~11 minecraft:stonebrick 0
fill ~80~17~11 ~81~17~11 minecraft:fence 5
setblock ~80~18~11 minecraft:fence 5
fill ~80~19~11 ~81~21~11 minecraft:stonebrick 0
fill ~80~23~11 ~80~23~12 minecraft:planks 5
fill ~81~2~11 ~81~3~11 minecraft:stonebrick 0
fill ~81~4~11 ~82~4~11 minecraft:double_stone_block_slab 0
fill ~81~5~11 ~82~5~11 minecraft:stonebrick 0
setblock ~81~6~11 minecraft:nether_brick
fill ~81~7~11 ~82~8~11 minecraft:stonebrick 0
fill ~81~9~11 ~82~9~11 minecraft:nether_brick
fill ~81~10~11 ~82~11~11 minecraft:stonebrick 0
fill ~81~12~11 ~81~13~11 minecraft:nether_brick
setblock ~81~16~11 minecraft:fence 5
fill ~81~18~11 ~82~18~11 minecraft:stonebrick 0
fill ~81~22~11 ~83~22~11 minecraft:planks 5
fill ~82~2~11 ~82~3~11 minecraft:cobblestone
setblock ~82~6~11 minecraft:stonebrick 0
fill ~82~12~11 ~82~17~11 minecraft:stonebrick 0
fill ~82~19~11 ~82~21~11 minecraft:cobblestone
fill ~83~2~11 ~83~20~11 minecraft:cobblestone_wall 1
fill ~83~21~11 ~85~21~11 minecraft:planks 5
fill ~92~1~11 ~92~1~25 minecraft:stonebrick 0
fill ~93~0~11 ~93~0~13 minecraft:glowstone
fill ~93~1~11 ~93~1~13 minecraft:stained_glass 7
fill ~96~1~11 ~96~1~25 minecraft:stonebrick 0
fill ~97~1~11 ~97~1~13 minecraft:stone_brick_stairs 5
fill ~97~2~11 ~97~2~12 minecraft:cobblestone_wall 1
setblock ~13~20~12 minecraft:end_rod 0
fill ~13~21~12 ~14~21~12 minecraft:planks 5
fill ~14~2~12 ~14~5~12 minecraft:iron_bars
fill ~14~17~12 ~14~20~12 minecraft:iron_bars
fill ~14~22~12 ~16~22~12 minecraft:planks 5
fill ~15~2~12 ~16~4~12 minecraft:cobblestone
setblock ~15~5~12 minecraft:cobblestone
fill ~15~6~12 ~16~16~12 minecraft:stonebrick 0
fill ~15~17~12 ~15~21~12 minecraft:cobblestone
setblock ~16~5~12 minecraft:stonebrick 0
setblock ~16~17~12 minecraft:stonebrick 0
fill ~16~18~12 ~16~21~12 minecraft:cobblestone
fill ~16~23~12 ~18~23~12 minecraft:planks 5
fill ~17~3~12 ~20~3~12 minecraft:wooden_slab 1
fill ~17~13~12 ~21~13~17 minecraft:planks 1
setblock ~19~9~12 minecraft:stone_brick_stairs 7
fill ~19~10~12 ~19~11~12 minecraft:nether_brick
setblock ~19~12~12 minecraft:stone_brick_stairs 3
setblock ~19~24~12 minecraft:planks 5
fill ~20~23~12 ~22~23~12 minecraft:planks 5
fill ~21~2~12 ~21~2~13 minecraft:planks 1
fill ~22~2~12 ~23~4~12 minecraft:cobblestone
fill ~22~5~12 ~22~17~12 minecraft:stonebrick 0
fill ~22~18~12 ~23~21~12 minecraft:cobblestone
fill ~22~22~12 ~24~22~12 minecraft:planks 5
setblock ~23~5~12 minecraft:cobblestone
fill ~23~6~12 ~23~16~12 minecraft:stonebrick 0
setblock ~23~17~12 minecraft:cobblestone
fill ~24~2~12 ~24~5~12 minecraft:iron_bars
fill ~24~17~12 ~24~20~12 minecraft:iron_bars
fill ~24~21~12 ~25~21~12 minecraft:planks 5
fill ~74~21~12 ~75~21~12 minecraft:planks 5
fill ~75~2~12 ~75~5~12 minecraft:iron_bars
fill ~75~17~12 ~75~20~12 minecraft:iron_bars
fill ~75~22~12 ~77~22~12 minecraft:planks 5
fill ~76~2~12 ~77~4~12 minecraft:cobblestone
setblock ~76~5~12 minecraft:cobblestone
fill ~76~6~12 ~77~16~12 minecraft:stonebrick 0
fill ~76~17~12 ~76~21~12 minecraft:cobblestone
setblock ~77~5~12 minecraft:stonebrick 0
setblock ~77~17~12 minecraft:stonebrick 0
fill ~77~18~12 ~77~21~12 minecraft:cobblestone
fill ~77~23~12 ~79~23~12 minecraft:planks 5
fill ~78~5~12 ~81~5~13 minecraft:planks 1
fill ~78~6~12 ~79~6~13 minecraft:wooden_slab 1
fill ~78~13~12 ~82~13~17 minecraft:planks 1
setblock ~80~9~12 minecraft:stone_brick_stairs 7
fill ~80~10~12 ~80~11~12 minecraft:nether_brick
setblock ~80~12~12 minecraft:stone_brick_stairs 3
setblock ~80~24~12 minecraft:planks 5
fill ~81~23~12 ~83~23~12 minecraft:planks 5
fill ~82~5~12 ~82~5~15 minecraft:wooden_slab 1
fill ~83~2~12 ~84~4~12 minecraft:cobblestone
fill ~83~5~12 ~83~17~12 minecraft:stonebrick 0
fill ~83~18~12 ~84~21~12 minecraft:cobblestone
fill ~83~22~12 ~85~22~12 minecraft:planks 5
setblock ~84~5~12 minecraft:cobblestone
fill ~84~6~12 ~84~16~12 minecraft:stonebrick 0
setblock ~84~17~12 minecraft:cobblestone
fill ~85~2~12 ~85~5~12 minecraft:iron_bars
fill ~85~17~12 ~85~20~12 minecraft:iron_bars
fill ~85~21~12 ~86~21~12 minecraft:planks 5
setblock ~86~20~12 minecraft:end_rod 0
setblock ~1~1~13 minecraft:stone_brick_stairs 6
setblock ~1~2~13 minecraft:cobblestone_wall 1
setblock ~2~2~13 minecraft:cobblestone_wall 1
fill ~12~21~13 ~13~21~13 minecraft:planks 5
fill ~13~2~13 ~13~5~13 minecraft:iron_bars
fill ~13~17~13 ~13~20~13 minecraft:iron_bars
fill ~13~22~13 ~14~22~13 minecraft:planks 5
fill ~14~2~13 ~14~5~13 minecraft:nether_brick
fill ~14~6~13 ~14~8~13 minecraft:glowstone
fill ~14~9~13 ~14~20~13 minecraft:nether_brick
setblock ~14~21~13 minecraft:cobblestone
fill ~14~23~13 ~16~23~13 minecraft:planks 5
setblock ~14~24~13 minecraft:end_rod 1
fill ~15~3~13 ~18~3~13 minecraft:planks 1
fill ~15~13~13 ~16~13~23 minecraft:planks 1
fill ~16~24~13 ~18~24~13 minecraft:planks 5
fill ~19~2~13 ~20~2~14 minecraft:planks 1
fill ~19~3~13 ~19~3~14 minecraft:wooden_slab 1
fill ~19~25~13 ~19~25~14 minecraft:planks 5
fill ~20~24~13 ~22~24~13 minecraft:planks 5
setblock ~22~2~13 minecraft:wooden_slab 1
fill ~22~12~13 ~22~12~17 minecraft:planks 1
fill ~22~13~13 ~23~13~15 minecraft:planks 1
fill ~22~23~13 ~24~23~13 minecraft:planks 5
fill ~24~2~13 ~24~4~13 minecraft:nether_brick
fill ~24~5~13 ~24~7~13 minecraft:glowstone
fill ~24~8~13 ~24~20~13 minecraft:nether_brick
setblock ~24~21~13 minecraft:cobblestone
fill ~24~22~13 ~25~22~13 minecraft:planks 5
setblock ~24~24~13 minecraft:end_rod 1
fill ~25~2~13 ~25~5~13 minecraft:iron_bars
fill ~25~17~13 ~25~20~13 minecraft:iron_bars
fill ~25~21~13 ~26~21~13 minecraft:planks 5
setblock ~26~20~13 minecraft:end_rod 0
fill ~43~2~13 ~43~2~14 minecraft:stone_brick_stairs 0
fill ~44~2~13 ~45~2~13 minecraft:stone_brick_stairs 2
fill ~54~2~13 ~54~2~27 minecraft:stone_brick_stairs 0
fill ~55~2~13 ~56~2~13 minecraft:stone_brick_stairs 2
setblock ~73~20~13 minecraft:end_rod 0
fill ~73~21~13 ~74~21~13 minecraft:planks 5
fill ~74~2~13 ~74~5~13 minecraft:iron_bars
fill ~74~17~13 ~74~20~13 minecraft:iron_bars
fill ~74~22~13 ~75~22~13 minecraft:planks 5
fill ~75~2~13 ~75~20~13 minecraft:nether_brick
setblock ~75~21~13 minecraft:cobblestone
fill ~75~23~13 ~77~23~13 minecraft:planks 5
setblock ~75~24~13 minecraft:end_rod 1
fill ~76~5~13 ~77~5~13 minecraft:planks 1
fill ~76~6~13 ~77~6~13 minecraft:wooden_slab 1
setblock ~76~13~13 minecraft:glowstone
fill ~77~13~13 ~77~13~19 minecraft:planks 1
fill ~77~24~13 ~79~24~13 minecraft:planks 5
fill ~80~25~13 ~80~25~14 minecraft:planks 5
fill ~81~24~13 ~83~24~13 minecraft:planks 5
fill ~83~4~13 ~83~4~16 minecraft:planks 1
fill ~83~13~13 ~83~13~23 minecraft:planks 1
fill ~83~23~13 ~85~23~13 minecraft:planks 5
fill ~84~4~13 ~84~4~16 minecraft:wooden_slab 1
setblock ~84~13~13 minecraft:glowstone
fill ~85~2~13 ~85~5~13 minecraft:nether_brick
fill ~85~6~13 ~85~8~13 minecraft:glowstone
fill ~85~9~13 ~85~20~13 minecraft:nether_brick
setblock ~85~21~13 minecraft:cobblestone
fill ~85~22~13 ~86~22~13 minecraft:planks 5
setblock ~85~24~13 minecraft:end_rod 1
fill ~86~2~13 ~86~5~13 minecraft:iron_bars
fill ~86~17~13 ~86~20~13 minecraft:iron_bars
fill ~86~21~13 ~87~21~13 minecraft:planks 5
setblock ~97~2~13 minecraft:cobblestone_wall 1
setblock ~98~1~13 minecraft:stone_brick_stairs 6
setblock ~98~2~13 minecraft:cobblestone_wall 1
fill ~1~1~14 ~1~1~22 minecraft:stone_brick_stairs 4
fill ~1~2~14 ~1~2~22 minecraft:cobblestone_wall 1
fill ~2~1~14 ~2~1~22 minecraft:stonebrick 0
fill ~5~0~14 ~5~0~22 minecraft:glowstone
fill ~5~1~14 ~5~1~22 minecraft:stained_glass 7
fill ~6~1~14 ~6~1~22 minecraft:stonebrick 0
fill ~12~21~14 ~12~21~15 minecraft:planks 5
fill ~13~2~14 ~13~4~15 minecraft:cobblestone
setblock ~13~5~14 minecraft:cobblestone
fill ~13~6~14 ~13~16~15 minecraft:stonebrick 0
fill ~13~17~14 ~13~21~14 minecraft:cobblestone
fill ~13~22~14 ~13~22~15 minecraft:planks 5
fill ~14~4~14 ~17~4~14 minecraft:wooden_slab 1
setblock ~14~13~14 minecraft:glowstone
fill ~14~23~14 ~14~23~15 minecraft:planks 5
fill ~15~24~14 ~16~24~14 minecraft:planks 5
fill ~17~25~14 ~18~25~14 minecraft:planks 5
fill ~18~2~14 ~18~3~15 minecraft:planks 1
fill ~18~26~14 ~20~26~14 minecraft:planks 5
fill ~19~27~14 ~19~27~15 minecraft:planks 5
fill ~20~25~14 ~21~25~14 minecraft:planks 5
setblock ~21~2~14 minecraft:wooden_slab 1
fill ~22~24~14 ~23~24~14 minecraft:planks 5
setblock ~24~13~14 minecraft:glowstone
fill ~24~23~14 ~24~23~15 minecraft:planks 5
fill ~25~2~14 ~25~5~14 minecraft:cobblestone
fill ~25~6~14 ~26~12~15 minecraft:stonebrick 0
fill ~25~13~14 ~25~16~15 minecraft:stonebrick 0
fill ~25~17~14 ~25~21~14 minecraft:cobblestone
fill ~25~22~14 ~25~22~15 minecraft:planks 5
fill ~26~2~14 ~26~5~19 minecraft:stonebrick 0
fill ~26~21~14 ~26~21~15 minecraft:planks 5
fill ~44~2~14 ~44~13~19 minecraft:stonebrick 0
fill ~45~2~14 ~45~2~22 minecraft:stone_brick_stairs 1
fill ~45~12~14 ~46~13~14 minecraft:fence 0
fill ~45~14~14 ~45~15~14 minecraft:stonebrick 0
setblock ~45~16~14 minecraft:stone_brick_stairs 2
fill ~46~14~14 ~48~14~14 minecraft:fence 0
fill ~46~15~14 ~46~17~14 minecraft:stonebrick 0
setblock ~46~18~14 minecraft:stone_brick_stairs 2
setblock ~47~13~14 minecraft:fence 0
fill ~47~15~14 ~52~16~14 minecraft:fence 0
fill ~47~17~14 ~47~19~14 minecraft:stonebrick 0
setblock ~47~20~14 minecraft:stone_brick_stairs 2
fill ~48~17~14 ~51~18~14 minecraft:fence 0
fill ~48~19~14 ~48~21~14 minecraft:stonebrick 0
setblock ~48~22~14 minecraft:stone_brick_stairs 2
fill ~49~19~14 ~50~20~14 minecraft:fence 0
fill ~49~21~14 ~51~21~14 minecraft:stonebrick 0
fill ~49~22~14 ~50~22~83 minecraft:stonebrick 0
fill ~49~23~14 ~50~23~38 minecraft:stonebrick 0
fill ~49~24~14 ~50~24~14 minecraft:stone_brick_stairs 2
fill ~51~14~14 ~53~14~14 minecraft:fence 0
fill ~51~19~14 ~52~19~14 minecraft:stonebrick 0
setblock ~51~20~14 minecraft:stonebrick 0
setblock ~51~22~14 minecraft:stone_brick_stairs 2
fill ~52~13~14 ~54~13~14 minecraft:fence 0
fill ~52~17~14 ~53~17~14 minecraft:stonebrick 0
setblock ~52~18~14 minecraft:stonebrick 0
setblock ~52~20~14 minecraft:stone_brick_stairs 2
fill ~53~12~14 ~54~12~14 minecraft:fence 0
fill ~53~15~14 ~54~16~14 minecraft:stonebrick 0
setblock ~53~18~14 minecraft:stone_brick_stairs 2
setblock ~54~14~14 minecraft:stonebrick 0
setblock ~54~17~14 minecraft:stone_brick_stairs 2
fill ~55~2~14 ~55~2~26 minecraft:stonebrick 0
fill ~55~3~14 ~55~13~24 minecraft:stonebrick 0
fill ~56~2~14 ~56~2~15 minecraft:stone_brick_stairs 1
fill ~73~21~14 ~73~21~15 minecraft:planks 5
fill ~74~2~14 ~74~4~15 minecraft:cobblestone
setblock ~74~5~14 minecraft:cobblestone
fill ~74~6~14 ~74~16~15 minecraft:stonebrick 0
fill ~74~17~14 ~74~21~14 minecraft:cobblestone
fill ~74~22~14 ~74~22~15 minecraft:planks 5
fill ~75~6~14 ~78~6~14 minecraft:planks 1
fill ~75~13~14 ~76~13~16 minecraft:planks 1
fill ~75~23~14 ~75~23~15 minecraft:planks 5
fill ~76~24~14 ~77~24~14 minecraft:planks 5
fill ~78~25~14 ~79~25~14 minecraft:planks 5
fill ~79~5~14 ~81~5~15 minecraft:planks 1
fill ~79~6~14 ~79~6~15 minecraft:wooden_slab 1
fill ~79~26~14 ~81~26~14 minecraft:planks 5
fill ~80~27~14 ~80~27~15 minecraft:planks 5
fill ~81~25~14 ~82~25~14 minecraft:planks 5
fill ~83~24~14 ~84~24~14 minecraft:planks 5
fill ~84~13~14 ~85~13~22 minecraft:planks 1
fill ~85~3~14 ~85~3~17 minecraft:planks 1
fill ~85~23~14 ~85~23~15 minecraft:planks 5
fill ~86~2~14 ~86~4~15 minecraft:cobblestone
setblock ~86~5~14 minecraft:cobblestone
fill ~86~6~14 ~86~16~15 minecraft:stonebrick 0
fill ~86~17~14 ~86~21~14 minecraft:cobblestone
fill ~86~22~14 ~86~22~15 minecraft:planks 5
fill ~87~21~14 ~87~21~15 minecraft:planks 5
fill ~93~1~14 ~93~1~22 minecraft:stonebrick 0
fill ~94~0~14 ~94~0~22 minecraft:glowstone
fill ~94~1~14 ~94~1~22 minecraft:stained_glass 7
fill ~97~1~14 ~97~1~22 minecraft:stonebrick 0
fill ~98~1~14 ~98~1~22 minecraft:stone_brick_stairs 5
fill ~98~2~14 ~98~2~22 minecraft:cobblestone_wall 1
fill ~11~21~15 ~11~21~21 minecraft:planks 5
fill ~12~2~15 ~12~20~15 minecraft:cobblestone_wall 1
fill ~12~22~15 ~12~22~21 minecraft:planks 5
setblock ~13~5~15 minecraft:stonebrick 0
setblock ~13~17~15 minecraft:stonebrick 0
fill ~13~18~15 ~13~21~15 minecraft:cobblestone
fill ~13~23~15 ~13~23~21 minecraft:planks 5
fill ~14~4~15 ~17~4~15 minecraft:planks 1
fill ~14~13~15 ~14~13~21 minecraft:planks 1
fill ~14~24~15 ~15~24~15 minecraft:planks 5
fill ~16~3~15 ~17~3~15 minecraft:planks 1
fill ~16~25~15 ~16~25~16 minecraft:planks 5
setblock ~17~2~15 minecraft:planks 1
fill ~17~26~15 ~18~26~15 minecraft:planks 5
fill ~18~27~15 ~18~27~16 minecraft:planks 5
setblock ~19~2~15 minecraft:planks 1
fill ~19~28~15 ~19~29~15 minecraft:planks 5
setblock ~20~2~15 minecraft:wooden_slab 1
fill ~20~26~15 ~21~26~15 minecraft:planks 5
fill ~20~27~15 ~20~27~16 minecraft:planks 5
fill ~21~25~15 ~22~25~15 minecraft:planks 5
fill ~23~24~15 ~24~24~15 minecraft:planks 5
setblock ~24~13~15 minecraft:planks 1
fill ~25~2~15 ~25~5~15 minecraft:stonebrick 0
setblock ~25~17~15 minecraft:stonebrick 0
fill ~25~18~15 ~25~21~15 minecraft:cobblestone
fill ~25~23~15 ~25~23~21 minecraft:planks 5
setblock ~26~13~15 minecraft:cobblestone_wall 1
fill ~26~14~15 ~26~20~15 minecraft:cobblestone_wall 1
fill ~26~22~15 ~26~22~21 minecraft:planks 5
fill ~27~2~15 ~27~12~20 minecraft:stonebrick 0
setblock ~27~13~15 minecraft:quartz_stairs 2
fill ~27~21~15 ~27~21~21 minecraft:planks 5
fill ~28~2~15 ~29~2~15 minecraft:stonebrick 3
fill ~28~3~15 ~29~3~20 minecraft:stonebrick 0
fill ~28~4~15 ~29~4~15 minecraft:stonebrick 3
fill ~28~5~15 ~29~5~20 minecraft:stonebrick 0
fill ~28~6~15 ~29~6~15 minecraft:stonebrick 3
fill ~28~7~15 ~29~7~20 minecraft:stonebrick 0
fill ~28~8~15 ~29~8~15 minecraft:stonebrick 3
fill ~28~9~15 ~29~9~20 minecraft:stonebrick 0
fill ~28~10~15 ~29~10~15 minecraft:stonebrick 3
fill ~28~11~15 ~29~11~20 minecraft:stonebrick 0
fill ~28~12~15 ~29~12~15 minecraft:stonebrick 3
fill ~28~13~15 ~29~13~15 minecraft:nether_brick_stairs 2
fill ~30~2~15 ~32~2~15 minecraft:cobblestone_wall 0
setblock ~30~6~15 minecraft:cobblestone_wall 0
setblock ~30~7~15 minecraft:cobblestone_wall 0
setblock ~30~8~15 minecraft:cobblestone_wall 0
setblock ~30~13~15 minecraft:quartz_stairs 2
setblock ~31~3~15 minecraft:piston 1
setblock ~31~4~15 minecraft:end_rod 1
setblock ~31~6~15 minecraft:quartz_stairs 6
setblock ~31~8~15 minecraft:wall_banner 2
setblock ~31~9~15 minecraft:quartz_stairs 2
setblock ~31~11~15 minecraft:end_rod 0
setblock ~31~12~15 minecraft:piston 0
setblock ~31~13~15 minecraft:cobblestone_wall 0
setblock ~32~6~15 minecraft:cobblestone_wall 0
setblock ~32~7~15 minecraft:cobblestone_wall 0
setblock ~32~8~15 minecraft:cobblestone_wall 0
setblock ~32~13~15 minecraft:quartz_stairs 2
fill ~33~2~15 ~34~2~15 minecraft:stonebrick 3
fill ~33~3~15 ~34~3~19 minecraft:stonebrick 0
fill ~33~4~15 ~34~4~15 minecraft:stonebrick 3
fill ~33~5~15 ~34~5~19 minecraft:stonebrick 0
fill ~33~6~15 ~34~6~15 minecraft:stonebrick 3
fill ~33~7~15 ~34~7~19 minecraft:stonebrick 0
fill ~33~8~15 ~34~8~15 minecraft:stonebrick 3
fill ~33~9~15 ~34~9~19 minecraft:stonebrick 0
fill ~33~10~15 ~34~10~15 minecraft:stonebrick 3
fill ~33~11~15 ~34~11~19 minecraft:stonebrick 0
fill ~33~12~15 ~34~12~15 minecraft:stonebrick 3
fill ~33~13~15 ~34~13~15 minecraft:nether_brick_stairs 2
fill ~35~2~15 ~37~2~15 minecraft:cobblestone_wall 0
setblock ~35~6~15 minecraft:cobblestone_wall 0
setblock ~35~7~15 minecraft:cobblestone_wall 0
setblock ~35~8~15 minecraft:cobblestone_wall 0
setblock ~35~13~15 minecraft:quartz_stairs 2
setblock ~36~3~15 minecraft:piston 1
setblock ~36~4~15 minecraft:end_rod 1
setblock ~36~6~15 minecraft:quartz_stairs 6
setblock ~36~8~15 minecraft:wall_banner 2
setblock ~36~9~15 minecraft:quartz_stairs 2
setblock ~36~11~15 minecraft:end_rod 0
setblock ~36~12~15 minecraft:piston 0
setblock ~36~13~15 minecraft:cobblestone_wall 0
setblock ~37~6~15 minecraft:cobblestone_wall 0
setblock ~37~7~15 minecraft:cobblestone_wall 0
setblock ~37~8~15 minecraft:cobblestone_wall 0
setblock ~37~13~15 minecraft:quartz_stairs 2
fill ~38~2~15 ~39~2~15 minecraft:stonebrick 3
fill ~38~3~15 ~39~3~18 minecraft:stonebrick 0
fill ~38~4~15 ~39~4~15 minecraft:stonebrick 3
fill ~38~5~15 ~39~5~18 minecraft:stonebrick 0
fill ~38~6~15 ~39~6~15 minecraft:stonebrick 3
fill ~38~7~15 ~39~7~17 minecraft:stonebrick 0
fill ~38~8~15 ~39~8~15 minecraft:stonebrick 3
fill ~38~9~15 ~39~9~18 minecraft:stonebrick 0
fill ~38~10~15 ~39~10~15 minecraft:stonebrick 3
fill ~38~11~15 ~39~11~18 minecraft:stonebrick 0
fill ~38~12~15 ~39~12~15 minecraft:stonebrick 3
fill ~38~13~15 ~39~13~15 minecraft:nether_brick_stairs 2
fill ~40~2~15 ~42~2~15 minecraft:cobblestone_wall 0
setblock ~40~6~15 minecraft:cobblestone_wall 0
setblock ~40~7~15 minecraft:cobblestone_wall 0
setblock ~40~8~15 minecraft:cobblestone_wall 0
setblock ~40~13~15 minecraft:quartz_stairs 2
setblock ~41~3~15 minecraft:piston 1
setblock ~41~4~15 minecraft:end_rod 1
setblock ~41~6~15 minecraft:quartz_stairs 6
setblock ~41~8~15 minecraft:wall_banner 2
setblock ~41~9~15 minecraft:quartz_stairs 2
setblock ~41~11~15 minecraft:end_rod 0
setblock ~41~12~15 minecraft:piston 0
setblock ~41~13~15 minecraft:cobblestone_wall 0
setblock ~42~6~15 minecraft:cobblestone_wall 0
setblock ~42~7~15 minecraft:cobblestone_wall 0
setblock ~42~8~15 minecraft:cobblestone_wall 0
setblock ~42~13~15 minecraft:quartz_stairs 2
setblock ~43~2~15 minecraft:stonebrick 3
fill ~43~3~15 ~43~3~20 minecraft:stonebrick 0
setblock ~43~4~15 minecraft:stonebrick 3
fill ~43~5~15 ~43~5~20 minecraft:stonebrick 0
setblock ~43~6~15 minecraft:stonebrick 3
fill ~43~7~15 ~43~7~20 minecraft:stonebrick 0
setblock ~43~8~15 minecraft:stonebrick 3
fill ~43~9~15 ~43~9~20 minecraft:stonebrick 0
setblock ~43~10~15 minecraft:stonebrick 3
fill ~43~11~15 ~43~11~20 minecraft:stonebrick 0
setblock ~43~12~15 minecraft:stonebrick 3
setblock ~43~13~15 minecraft:nether_brick_stairs 2
fill ~45~14~15 ~45~15~43 minecraft:log2 1
fill ~46~16~15 ~46~17~44 minecraft:log2 1
fill ~47~18~15 ~47~19~45 minecraft:log2 1
fill ~48~20~15 ~48~21~15 minecraft:stonebrick 0
fill ~49~21~15 ~50~21~15 minecraft:glowstone
fill ~51~20~15 ~51~21~46 minecraft:log2 1
fill ~52~18~15 ~52~19~45 minecraft:log2 1
fill ~53~16~15 ~53~17~44 minecraft:log2 1
fill ~54~14~15 ~54~15~43 minecraft:log2 1
fill ~72~21~15 ~72~21~21 minecraft:planks 5
fill ~73~2~15 ~73~20~15 minecraft:cobblestone_wall 1
fill ~73~22~15 ~73~22~21 minecraft:planks 5
setblock ~74~5~15 minecraft:stonebrick 0
setblock ~74~17~15 minecraft:stonebrick 0
fill ~74~18~15 ~74~21~15 minecraft:cobblestone
fill ~74~23~15 ~74~23~21 minecraft:planks 5
fill ~75~7~15 ~78~7~15 minecraft:wooden_slab 1
fill ~75~24~15 ~76~24~15 minecraft:planks 5
fill ~77~25~15 ~77~25~16 minecraft:planks 5
setblock ~78~6~15 minecraft:planks 1
fill ~78~26~15 ~79~26~15 minecraft:planks 5
fill ~79~27~15 ~79~27~16 minecraft:planks 5
fill ~80~28~15 ~80~29~15 minecraft:planks 5
fill ~81~26~15 ~82~26~15 minecraft:planks 5
fill ~81~27~15 ~81~27~16 minecraft:planks 5
fill ~82~25~15 ~83~25~15 minecraft:planks 5
fill ~83~3~15 ~83~3~17 minecraft:planks 1
fill ~84~24~15 ~85~24~15 minecraft:planks 5
setblock ~86~5~15 minecraft:stonebrick 0
setblock ~86~17~15 minecraft:stonebrick 0
fill ~86~18~15 ~86~21~15 minecraft:cobblestone
fill ~86~23~15 ~86~23~21 minecraft:planks 5
fill ~87~2~15 ~87~20~15 minecraft:cobblestone_wall 1
fill ~87~22~15 ~87~22~21 minecraft:planks 5
fill ~88~21~15 ~88~21~21 minecraft:planks 5
setblock ~11~12~16 minecraft:end_rod 0
setblock ~11~13~16 minecraft:stone_brick_stairs 6
fill ~11~14~16 ~11~14~20 minecraft:fence 5
fill ~12~2~16 ~12~3~16 minecraft:cobblestone
fill ~12~4~16 ~12~4~17 minecraft:double_stone_block_slab 0
fill ~12~5~16 ~12~5~17 minecraft:stonebrick 0
fill ~12~6~16 ~12~8~16 minecraft:stonebrick 0
fill ~12~9~16 ~12~9~17 minecraft:nether_brick
fill ~12~10~16 ~12~11~17 minecraft:stonebrick 0
fill ~12~12~16 ~12~18~16 minecraft:stonebrick 0
fill ~12~19~16 ~12~21~16 minecraft:cobblestone
fill ~13~5~16 ~16~5~16 minecraft:wooden_slab 1
fill ~13~13~16 ~13~13~20 minecraft:planks 1
fill ~14~24~16 ~14~24~17 minecraft:planks 5
fill ~15~25~16 ~15~25~20 minecraft:planks 5
fill ~16~26~16 ~17~26~16 minecraft:planks 5
fill ~17~27~16 ~17~27~17 minecraft:planks 5
setblock ~17~28~16 minecraft:end_rod 1
fill ~18~28~16 ~18~28~17 minecraft:planks 5
setblock ~19~2~16 minecraft:wooden_slab 1
fill ~19~29~16 ~19~32~17 minecraft:planks 5
fill ~20~28~16 ~20~28~17 minecraft:planks 5
fill ~21~26~16 ~22~26~16 minecraft:planks 5
fill ~21~27~16 ~21~27~17 minecraft:planks 5
setblock ~21~28~16 minecraft:end_rod 1
fill ~22~13~16 ~25~13~16 minecraft:wooden_slab 1
fill ~23~25~16 ~23~25~20 minecraft:planks 5
fill ~24~24~16 ~24~24~17 minecraft:planks 5
fill ~26~6~16 ~26~10~19 minecraft:stonebrick 0
fill ~26~11~16 ~26~18~18 minecraft:stonebrick 0
fill ~26~19~16 ~26~21~16 minecraft:cobblestone
fill ~27~13~16 ~27~13~20 minecraft:stonebrick 0
setblock ~27~14~16 minecraft:end_rod 0
fill ~27~15~16 ~44~15~17 minecraft:nether_brick
fill ~28~2~16 ~30~2~20 minecraft:stonebrick 0
fill ~28~4~16 ~30~4~20 minecraft:stonebrick 0
fill ~28~6~16 ~30~6~20 minecraft:stonebrick 0
fill ~28~8~16 ~30~8~20 minecraft:stonebrick 0
fill ~28~10~16 ~30~10~20 minecraft:stonebrick 0
fill ~28~12~16 ~30~12~20 minecraft:stonebrick 0
setblock ~28~13~16 minecraft:nether_brick
fill ~29~13~16 ~30~13~20 minecraft:stonebrick 0
setblock ~29~14~16 minecraft:quartz_stairs 2
fill ~30~3~16 ~30~3~20 minecraft:stonebrick 0
fill ~30~5~16 ~30~5~20 minecraft:stonebrick 0
fill ~30~7~16 ~30~7~20 minecraft:stonebrick 0
fill ~30~9~16 ~30~9~20 minecraft:stonebrick 0
fill ~30~11~16 ~30~11~20 minecraft:stonebrick 0
fill ~31~2~16 ~31~13~16 minecraft:nether_brick
setblock ~31~14~16 minecraft:end_rod 0
fill ~32~2~16 ~35~2~19 minecraft:stonebrick 0
fill ~32~3~16 ~32~13~20 minecraft:stonebrick 0
fill ~33~4~16 ~35~4~19 minecraft:stonebrick 0
fill ~33~6~16 ~35~6~19 minecraft:stonebrick 0
fill ~33~8~16 ~35~8~19 minecraft:stonebrick 0
fill ~33~10~16 ~35~10~19 minecraft:stonebrick 0
fill ~33~12~16 ~35~13~19 minecraft:stonebrick 0
fill ~33~14~16 ~34~14~16 minecraft:quartz_stairs 2
fill ~35~3~16 ~35~3~19 minecraft:stonebrick 0
fill ~35~5~16 ~35~5~19 minecraft:stonebrick 0
fill ~35~7~16 ~35~7~19 minecraft:stonebrick 0
fill ~35~9~16 ~35~9~19 minecraft:stonebrick 0
fill ~35~11~16 ~35~11~19 minecraft:stonebrick 0
fill ~36~2~16 ~36~13~16 minecraft:nether_brick
setblock ~36~14~16 minecraft:end_rod 0
fill ~37~2~16 ~40~2~18 minecraft:stonebrick 0
fill ~37~3~16 ~37~13~20 minecraft:stonebrick 0
fill ~38~4~16 ~40~4~18 minecraft:stonebrick 0
fill ~38~6~16 ~40~6~18 minecraft:stonebrick 0
fill ~38~8~16 ~40~8~17 minecraft:stonebrick 0
fill ~38~10~16 ~40~10~18 minecraft:stonebrick 0
fill ~38~12~16 ~40~13~18 minecraft:stonebrick 0
fill ~38~14~16 ~39~14~16 minecraft:quartz_stairs 2
fill ~40~3~16 ~40~3~20 minecraft:stonebrick 0
fill ~40~5~16 ~40~5~20 minecraft:stonebrick 0
fill ~40~7~16 ~40~7~20 minecraft:stonebrick 0
fill ~40~9~16 ~40~9~20 minecraft:stonebrick 0
fill ~40~11~16 ~40~11~20 minecraft:stonebrick 0
fill ~41~2~16 ~41~13~16 minecraft:nether_brick
setblock ~41~14~16 minecraft:end_rod 0
fill ~42~2~16 ~43~2~19 minecraft:stonebrick 0
fill ~42~3~16 ~42~13~19 minecraft:stonebrick 0
fill ~43~4~16 ~43~4~20 minecraft:stonebrick 0
fill ~43~6~16 ~43~6~20 minecraft:stonebrick 0
fill ~43~8~16 ~43~8~20 minecraft:stonebrick 0
fill ~43~10~16 ~43~10~20 minecraft:stonebrick 0
fill ~43~12~16 ~43~13~20 minecraft:stonebrick 0
setblock ~43~14~16 minecraft:quartz_stairs 2
setblock ~44~14~16 minecraft:end_rod 0
fill ~48~20~16 ~48~21~46 minecraft:log2 1
fill ~49~21~16 ~50~21~19 minecraft:stonebrick 0
fill ~55~14~16 ~56~14~16 minecraft:quartz_stairs 2
fill ~56~2~16 ~58~2~19 minecraft:stonebrick 0
fill ~56~3~16 ~56~13~19 minecraft:stonebrick 0
fill ~57~3~16 ~58~3~16 minecraft:stonebrick 3
fill ~57~4~16 ~58~4~20 minecraft:stonebrick 0
fill ~57~5~16 ~58~5~16 minecraft:stonebrick 3
fill ~57~6~16 ~58~6~20 minecraft:stonebrick 0
fill ~57~7~16 ~58~7~16 minecraft:stonebrick 3
fill ~57~8~16 ~58~8~20 minecraft:stonebrick 0
fill ~57~9~16 ~58~9~16 minecraft:stonebrick 3
fill ~57~10~16 ~58~10~20 minecraft:stonebrick 0
fill ~57~11~16 ~58~11~16 minecraft:stonebrick 3
fill ~57~12~16 ~58~12~20 minecraft:stonebrick 0
fill ~57~13~16 ~58~13~16 minecraft:stonebrick 3
fill ~57~14~16 ~58~14~16 minecraft:nether_brick_stairs 2
fill ~59~2~16 ~61~2~16 minecraft:cobblestone_wall 0
setblock ~59~8~16 minecraft:cobblestone_wall 0
fill ~59~9~16 ~59~10~16 minecraft:cobblestone_wall 0
setblock ~59~14~16 minecraft:quartz_stairs 2
setblock ~60~3~16 minecraft:piston 1
setblock ~60~4~16 minecraft:end_rod 1
setblock ~60~7~16 minecraft:quartz_stairs 6
setblock ~60~9~16 minecraft:wall_banner 2
setblock ~60~10~16 minecraft:quartz_stairs 2
setblock ~60~12~16 minecraft:end_rod 0
setblock ~60~13~16 minecraft:piston 0
setblock ~60~14~16 minecraft:cobblestone_wall 0
setblock ~61~8~16 minecraft:cobblestone_wall 0
fill ~61~9~16 ~61~10~16 minecraft:cobblestone_wall 0
setblock ~61~14~16 minecraft:quartz_stairs 2
fill ~62~2~16 ~63~2~18 minecraft:stonebrick 0
fill ~62~3~16 ~63~3~16 minecraft:stonebrick 3
fill ~62~4~16 ~63~4~18 minecraft:stonebrick 0
fill ~62~5~16 ~63~5~16 minecraft:stonebrick 3
fill ~62~6~16 ~63~6~18 minecraft:stonebrick 0
fill ~62~7~16 ~63~7~16 minecraft:stonebrick 3
fill ~62~8~16 ~63~8~18 minecraft:stonebrick 0
fill ~62~9~16 ~63~9~16 minecraft:stonebrick 3
fill ~62~10~16 ~63~10~18 minecraft:stonebrick 0
fill ~62~11~16 ~63~11~16 minecraft:stonebrick 3
fill ~62~12~16 ~63~12~18 minecraft:stonebrick 0
fill ~62~13~16 ~63~13~16 minecraft:stonebrick 3
fill ~62~14~16 ~63~14~16 minecraft:nether_brick_stairs 2
fill ~64~2~16 ~66~2~16 minecraft:cobblestone_wall 0
setblock ~64~8~16 minecraft:cobblestone_wall 0
fill ~64~9~16 ~64~10~16 minecraft:cobblestone_wall 0
setblock ~64~14~16 minecraft:quartz_stairs 2
setblock ~65~3~16 minecraft:piston 1
setblock ~65~4~16 minecraft:end_rod 1
setblock ~65~7~16 minecraft:quartz_stairs 6
setblock ~65~9~16 minecraft:wall_banner 2
setblock ~65~10~16 minecraft:quartz_stairs 2
setblock ~65~12~16 minecraft:end_rod 0
setblock ~65~13~16 minecraft:piston 0
setblock ~65~14~16 minecraft:cobblestone_wall 0
setblock ~66~8~16 minecraft:cobblestone_wall 0
fill ~66~9~16 ~66~10~16 minecraft:cobblestone_wall 0
setblock ~66~14~16 minecraft:quartz_stairs 2
fill ~67~2~16 ~68~2~19 minecraft:stonebrick 0
fill ~67~3~16 ~68~3~16 minecraft:stonebrick 3
fill ~67~4~16 ~68~4~19 minecraft:stonebrick 0
fill ~67~5~16 ~68~5~16 minecraft:stonebrick 3
fill ~67~6~16 ~68~6~19 minecraft:stonebrick 0
fill ~67~7~16 ~68~7~16 minecraft:stonebrick 3
fill ~67~8~16 ~68~8~19 minecraft:stonebrick 0
fill ~67~9~16 ~68~9~16 minecraft:stonebrick 3
fill ~67~10~16 ~68~10~19 minecraft:stonebrick 0
fill ~67~11~16 ~68~11~16 minecraft:stonebrick 3
fill ~67~12~16 ~68~12~19 minecraft:stonebrick 0
fill ~67~13~16 ~68~13~16 minecraft:stonebrick 3
fill ~67~14~16 ~68~14~16 minecraft:nether_brick_stairs 2
fill ~69~2~16 ~71~2~16 minecraft:cobblestone_wall 0
setblock ~69~8~16 minecraft:cobblestone_wall 0
fill ~69~9~16 ~69~10~16 minecraft:cobblestone_wall 0
setblock ~69~14~16 minecraft:quartz_stairs 2
setblock ~70~3~16 minecraft:piston 1
setblock ~70~4~16 minecraft:end_rod 1
setblock ~70~7~16 minecraft:quartz_stairs 6
setblock ~70~9~16 minecraft:wall_banner 2
setblock ~70~10~16 minecraft:quartz_stairs 2
setblock ~70~12~16 minecraft:end_rod 0
setblock ~70~13~16 minecraft:piston 0
setblock ~70~14~16 minecraft:cobblestone_wall 0
setblock ~71~8~16 minecraft:cobblestone_wall 0
fill ~71~9~16 ~71~10~16 minecraft:cobblestone_wall 0
setblock ~71~14~16 minecraft:quartz_stairs 2
fill ~72~2~16 ~73~2~19 minecraft:stonebrick 0
fill ~72~3~16 ~73~3~16 minecraft:stonebrick 3
fill ~72~4~16 ~73~4~19 minecraft:stonebrick 0
fill ~72~5~16 ~73~5~16 minecraft:stonebrick 3
fill ~72~6~16 ~73~6~19 minecraft:stonebrick 0
fill ~72~7~16 ~73~7~16 minecraft:stonebrick 3
fill ~72~8~16 ~73~8~19 minecraft:stonebrick 0
setblock ~72~9~16 minecraft:stonebrick 3
fill ~72~10~16 ~73~10~18 minecraft:stonebrick 0
fill ~72~11~16 ~73~11~16 minecraft:stonebrick 3
fill ~72~12~16 ~73~12~18 minecraft:stonebrick 0
fill ~72~13~16 ~73~13~16 minecraft:stonebrick 3
setblock ~72~14~16 minecraft:nether_brick_stairs 2
fill ~73~9~16 ~73~9~19 minecraft:stonebrick 0
fill ~73~14~16 ~73~18~19 minecraft:stonebrick 0
fill ~73~19~16 ~73~21~16 minecraft:cobblestone
fill ~74~7~16 ~77~7~16 minecraft:planks 1
fill ~74~12~16 ~76~12~16 minecraft:wooden_slab 9
setblock ~74~13~16 minecraft:planks 1
fill ~75~24~16 ~75~24~17 minecraft:planks 5
setblock ~76~1~16 minecraft:glowstone
fill ~76~25~16 ~76~25~20 minecraft:planks 5
fill ~77~1~16 ~83~1~17 minecraft:stonebrick 0
fill ~77~26~16 ~78~26~16 minecraft:planks 5
fill ~78~27~16 ~78~27~17 minecraft:planks 5
setblock ~78~28~16 minecraft:end_rod 1
fill ~79~28~16 ~79~28~17 minecraft:planks 5
fill ~80~29~16 ~80~32~17 minecraft:planks 5
fill ~81~28~16 ~81~28~17 minecraft:planks 5
fill ~82~26~16 ~83~26~16 minecraft:planks 5
fill ~82~27~16 ~82~27~17 minecraft:planks 5
setblock ~82~28~16 minecraft:end_rod 1
fill ~83~2~16 ~84~2~18 minecraft:planks 1
setblock ~84~1~16 minecraft:glowstone
fill ~84~25~16 ~84~25~20 minecraft:planks 5
fill ~85~24~16 ~85~24~21 minecraft:planks 5
fill ~86~3~16 ~86~3~19 minecraft:wooden_slab 1
fill ~86~13~16 ~86~13~20 minecraft:planks 1
fill ~87~2~16 ~87~3~16 minecraft:cobblestone
fill ~87~4~16 ~87~5~17 minecraft:stonebrick 0
fill ~87~6~16 ~87~8~16 minecraft:stonebrick 0
fill ~87~9~16 ~87~9~17 minecraft:nether_brick
fill ~87~10~16 ~87~11~17 minecraft:stonebrick 0
fill ~87~12~16 ~87~18~16 minecraft:stonebrick 0
fill ~87~19~16 ~87~21~16 minecraft:cobblestone
setblock ~88~12~16 minecraft:end_rod 0
setblock ~88~13~16 minecraft:stone_brick_stairs 6
fill ~88~14~16 ~88~14~20 minecraft:fence 5
fill ~11~13~17 ~11~13~19 minecraft:stone_brick_stairs 4
fill ~12~2~17 ~12~3~17 minecraft:stonebrick 0
setblock ~12~6~17 minecraft:nether_brick
fill ~12~7~17 ~12~8~17 minecraft:stonebrick 0
fill ~12~12~17 ~12~13~17 minecraft:nether_brick
fill ~12~14~17 ~12~14~19 minecraft:stone_block_slab 0
fill ~12~16~17 ~12~17~17 minecraft:fence 5
fill ~12~18~17 ~12~21~17 minecraft:stonebrick 0
fill ~13~5~17 ~16~5~19 minecraft:planks 1
fill ~15~26~17 ~16~26~17 minecraft:planks 5
fill ~16~27~17 ~16~27~19 minecraft:planks 5
setblock ~17~28~17 minecraft:planks 5
fill ~18~2~17 ~20~2~17 minecraft:stone_block_slab 0
fill ~18~29~17 ~18~31~19 minecraft:planks 5
setblock ~18~32~17 minecraft:end_rod 1
fill ~19~33~17 ~19~35~17 minecraft:planks 5
fill ~20~29~17 ~20~31~19 minecraft:planks 5
setblock ~20~32~17 minecraft:end_rod 1
setblock ~21~28~17 minecraft:planks 5
fill ~22~11~17 ~22~11~19 minecraft:planks 1
fill ~22~26~17 ~23~26~17 minecraft:planks 5
fill ~22~27~17 ~22~27~19 minecraft:planks 5
fill ~23~12~17 ~25~12~17 minecraft:planks 1
fill ~26~19~17 ~26~21~19 minecraft:stonebrick 0
fill ~27~14~17 ~27~14~20 minecraft:stonebrick 0
fill ~27~16~17 ~45~16~17 minecraft:nether_brick
fill ~28~13~17 ~28~13~20 minecraft:stonebrick 0
setblock ~28~14~17 minecraft:nether_brick
fill ~29~14~17 ~30~14~20 minecraft:stonebrick 0
fill ~31~2~17 ~31~13~20 minecraft:stonebrick 0
setblock ~31~14~17 minecraft:nether_brick
fill ~32~14~17 ~35~14~19 minecraft:stonebrick 0
fill ~36~2~17 ~36~13~20 minecraft:stonebrick 0
setblock ~36~14~17 minecraft:nether_brick
fill ~37~14~17 ~40~14~18 minecraft:stonebrick 0
fill ~41~2~17 ~41~13~19 minecraft:stonebrick 0
setblock ~41~14~17 minecraft:nether_brick
fill ~42~14~17 ~44~14~19 minecraft:stonebrick 0
fill ~54~16~17 ~72~16~17 minecraft:nether_brick
fill ~55~14~17 ~59~14~19 minecraft:stonebrick 0
setblock ~55~15~17 minecraft:end_rod 1
fill ~57~3~17 ~59~3~19 minecraft:stonebrick 0
fill ~57~5~17 ~59~5~19 minecraft:stonebrick 0
fill ~57~7~17 ~59~7~19 minecraft:stonebrick 0
fill ~57~9~17 ~59~9~19 minecraft:stonebrick 0
fill ~57~11~17 ~59~11~19 minecraft:stonebrick 0
fill ~57~13~17 ~59~13~19 minecraft:stonebrick 0
fill ~57~15~17 ~58~15~17 minecraft:quartz_stairs 2
fill ~59~2~17 ~59~2~19 minecraft:stonebrick 0
fill ~59~4~17 ~59~4~19 minecraft:stonebrick 0
fill ~59~6~17 ~59~6~19 minecraft:stonebrick 0
fill ~59~8~17 ~59~8~19 minecraft:stonebrick 0
fill ~59~10~17 ~59~10~19 minecraft:stonebrick 0
fill ~59~12~17 ~59~12~19 minecraft:stonebrick 0
fill ~60~2~17 ~60~14~17 minecraft:nether_brick
setblock ~60~15~17 minecraft:end_rod 1
fill ~61~2~17 ~61~14~20 minecraft:stonebrick 0
fill ~62~3~17 ~64~3~18 minecraft:stonebrick 0
fill ~62~5~17 ~64~5~18 minecraft:stonebrick 0
fill ~62~7~17 ~64~7~18 minecraft:stonebrick 0
fill ~62~9~17 ~64~9~18 minecraft:stonebrick 0
fill ~62~11~17 ~64~11~18 minecraft:stonebrick 0
fill ~62~13~17 ~64~14~18 minecraft:stonebrick 0
fill ~62~15~17 ~63~15~17 minecraft:quartz_stairs 2
fill ~64~2~17 ~64~2~20 minecraft:stonebrick 0
fill ~64~4~17 ~64~4~20 minecraft:stonebrick 0
fill ~64~6~17 ~64~6~20 minecraft:stonebrick 0
fill ~64~8~17 ~64~8~20 minecraft:stonebrick 0
fill ~64~10~17 ~64~10~20 minecraft:stonebrick 0
fill ~64~12~17 ~64~12~20 minecraft:stonebrick 0
fill ~65~2~17 ~65~14~17 minecraft:nether_brick
setblock ~65~15~17 minecraft:end_rod 1
fill ~66~2~17 ~66~14~19 minecraft:stonebrick 0
fill ~67~3~17 ~69~3~19 minecraft:stonebrick 0
fill ~67~5~17 ~69~5~19 minecraft:stonebrick 0
fill ~67~7~17 ~69~7~19 minecraft:stonebrick 0
fill ~67~9~17 ~69~9~19 minecraft:stonebrick 0
fill ~67~11~17 ~69~11~19 minecraft:stonebrick 0
fill ~67~13~17 ~69~14~18 minecraft:stonebrick 0
fill ~67~15~17 ~68~15~17 minecraft:quartz_stairs 2
fill ~69~2~17 ~69~2~20 minecraft:stonebrick 0
fill ~69~4~17 ~69~4~20 minecraft:stonebrick 0
fill ~69~6~17 ~69~6~20 minecraft:stonebrick 0
fill ~69~8~17 ~69~8~20 minecraft:stonebrick 0
fill ~69~10~17 ~69~10~20 minecraft:stonebrick 0
fill ~69~12~17 ~69~12~20 minecraft:stonebrick 0
fill ~70~2~17 ~70~14~17 minecraft:nether_brick
setblock ~70~15~17 minecraft:end_rod 1
fill ~71~2~17 ~71~10~20 minecraft:stonebrick 0
fill ~71~11~17 ~73~11~18 minecraft:stonebrick 0
fill ~71~12~17 ~71~14~18 minecraft:stonebrick 0
fill ~72~3~17 ~73~3~19 minecraft:stonebrick 0
fill ~72~5~17 ~73~5~19 minecraft:stonebrick 0
fill ~72~7~17 ~73~7~19 minecraft:stonebrick 0
fill ~72~9~17 ~72~9~20 minecraft:stonebrick 0
fill ~72~13~17 ~73~13~18 minecraft:stonebrick 0
fill ~72~14~17 ~72~14~18 minecraft:stonebrick 0
setblock ~72~15~17 minecraft:quartz_stairs 2
fill ~73~19~17 ~73~21~19 minecraft:stonebrick 0
fill ~74~8~17 ~77~8~17 minecraft:wooden_slab 1
fill ~76~1~17 ~76~1~91 minecraft:stonebrick 0
fill ~76~12~17 ~76~12~18 minecraft:wooden_slab 9
fill ~76~13~17 ~76~13~18 minecraft:planks 1
fill ~76~26~17 ~77~26~17 minecraft:planks 5
fill ~77~7~17 ~77~7~18 minecraft:planks 1
fill ~77~27~17 ~77~27~19 minecraft:planks 5
setblock ~78~28~17 minecraft:planks 5
fill ~79~2~17 ~81~2~17 minecraft:stone_block_slab 0
fill ~79~29~17 ~79~31~19 minecraft:planks 5
setblock ~79~32~17 minecraft:end_rod 1
fill ~80~33~17 ~80~35~17 minecraft:planks 5
fill ~81~29~17 ~81~31~19 minecraft:planks 5
setblock ~81~32~17 minecraft:end_rod 1
setblock ~82~28~17 minecraft:planks 5
fill ~83~26~17 ~84~26~17 minecraft:planks 5
fill ~83~27~17 ~83~27~19 minecraft:planks 5
fill ~84~1~17 ~84~1~25 minecraft:stonebrick 0
setblock ~84~3~17 minecraft:planks 1
fill ~87~2~17 ~87~3~17 minecraft:stonebrick 0
setblock ~87~6~17 minecraft:nether_brick
fill ~87~7~17 ~87~8~17 minecraft:stonebrick 0
setblock ~87~12~17 minecraft:nether_brick
fill ~87~13~17 ~87~13~20 minecraft:stonebrick 0
fill ~87~14~17 ~87~14~19 minecraft:stone_block_slab 0
fill ~87~16~17 ~87~17~17 minecraft:fence 5
fill ~87~18~17 ~87~21~17 minecraft:stonebrick 0
fill ~88~13~17 ~88~13~19 minecraft:stone_brick_stairs 5
setblock ~88~20~17 minecraft:end_rod 0
setblock ~10~21~18 minecraft:planks 5
setblock ~11~22~18 minecraft:planks 5
fill ~12~2~18 ~12~5~18 minecraft:nether_brick
setblock ~12~6~18 minecraft:double_stone_block_slab 0
fill ~12~7~18 ~12~8~18 minecraft:nether_brick
setblock ~12~9~18 minecraft:quartz_stairs 0
setblock ~12~11~18 minecraft:wall_banner 4
setblock ~12~12~18 minecraft:quartz_stairs 4
setblock ~12~13~18 minecraft:stonebrick 0
fill ~12~17~18 ~12~17~19 minecraft:fence 5
setblock ~12~18~18 minecraft:fence 5
fill ~12~19~18 ~12~21~19 minecraft:stonebrick 0
setblock ~12~23~18 minecraft:planks 5
setblock ~13~9~18 minecraft:stone_brick_stairs 5
fill ~13~10~18 ~13~11~18 minecraft:nether_brick
setblock ~13~12~18 minecraft:stone_brick_stairs 1
setblock ~13~24~18 minecraft:planks 5
setblock ~14~25~18 minecraft:planks 5
fill ~15~1~18 ~18~1~83 minecraft:stonebrick 0
fill ~15~26~18 ~15~26~19 minecraft:planks 5
setblock ~15~27~18 minecraft:planks 5
fill ~16~28~18 ~16~29~18 minecraft:planks 5
fill ~17~13~18 ~18~13~22 minecraft:planks 1
fill ~17~29~18 ~17~32~18 minecraft:planks 5
fill ~18~2~18 ~18~2~19 minecraft:stone_block_slab 0
fill ~18~32~18 ~18~35~18 minecraft:planks 5
setblock ~19~1~18 minecraft:quartz_block 2
setblock ~19~2~18 minecraft:quartz_block 2
setblock ~19~3~18 minecraft:end_rod 1
setblock ~19~4~18 minecraft:end_rod 0
fill ~19~5~18 ~19~6~18 minecraft:quartz_block 2
setblock ~19~7~18 minecraft:end_rod 1
setblock ~19~8~18 minecraft:end_rod 0
fill ~19~9~18 ~19~10~18 minecraft:quartz_block 2
setblock ~19~11~18 minecraft:end_rod 1
setblock ~19~12~18 minecraft:end_rod 0
fill ~19~13~18 ~19~14~18 minecraft:quartz_block 2
setblock ~19~15~18 minecraft:end_rod 1
setblock ~19~16~18 minecraft:end_rod 0
fill ~19~17~18 ~19~18~18 minecraft:quartz_block 2
setblock ~19~19~18 minecraft:end_rod 1
setblock ~19~20~18 minecraft:end_rod 0
fill ~19~21~18 ~19~23~18 minecraft:quartz_block 2
setblock ~19~24~18 minecraft:end_rod 1
setblock ~19~25~18 minecraft:end_rod 0
fill ~19~26~18 ~19~28~18 minecraft:quartz_block 2
fill ~19~29~18 ~19~30~18 minecraft:quartz_block 2
fill ~19~35~18 ~20~35~18 minecraft:planks 5
fill ~19~36~18 ~19~39~18 minecraft:planks 5
setblock ~19~40~18 minecraft:end_rod 1
fill ~20~1~18 ~23~1~83 minecraft:stonebrick 0
fill ~20~2~18 ~20~2~19 minecraft:stone_block_slab 0
fill ~20~13~18 ~21~13~19 minecraft:planks 1
fill ~20~32~18 ~21~32~18 minecraft:planks 5
fill ~20~33~18 ~20~34~18 minecraft:planks 5
fill ~21~12~18 ~21~12~19 minecraft:wooden_slab 9
fill ~21~29~18 ~22~29~18 minecraft:planks 5
fill ~21~30~18 ~21~31~18 minecraft:planks 5
fill ~22~12~18 ~25~12~18 minecraft:wooden_slab 1
setblock ~22~28~18 minecraft:planks 5
fill ~23~26~18 ~23~26~19 minecraft:planks 5
setblock ~23~27~18 minecraft:planks 5
setblock ~24~25~18 minecraft:planks 5
setblock ~25~24~18 minecraft:planks 5
setblock ~26~23~18 minecraft:planks 5
fill ~27~15~18 ~30~15~20 minecraft:stonebrick 0
fill ~27~17~18 ~45~17~18 minecraft:nether_brick
setblock ~27~22~18 minecraft:planks 5
fill ~28~14~18 ~28~14~20 minecraft:stonebrick 0
setblock ~28~21~18 minecraft:planks 5
fill ~31~14~18 ~31~14~20 minecraft:stonebrick 0
setblock ~31~15~18 minecraft:nether_brick
fill ~32~15~18 ~35~15~19 minecraft:stonebrick 0
fill ~36~14~18 ~36~14~20 minecraft:stonebrick 0
setblock ~36~15~18 minecraft:nether_brick
fill ~37~15~18 ~40~15~18 minecraft:stonebrick 0
fill ~39~7~18 ~39~8~20 minecraft:stonebrick 0
fill ~40~8~18 ~40~8~20 minecraft:stonebrick 0
fill ~41~14~18 ~41~14~19 minecraft:stonebrick 0
setblock ~41~15~18 minecraft:nether_brick
fill ~42~15~18 ~44~15~19 minecraft:stonebrick 0
fill ~54~17~18 ~72~17~18 minecraft:nether_brick
fill ~55~15~18 ~72~15~18 minecraft:stonebrick 0
fill ~60~2~18 ~60~14~19 minecraft:stonebrick 0
fill ~65~2~18 ~65~14~20 minecraft:stonebrick 0
fill ~70~2~18 ~70~11~20 minecraft:stonebrick 0
fill ~70~12~18 ~70~14~18 minecraft:stonebrick 0
setblock ~71~21~18 minecraft:planks 5
setblock ~72~22~18 minecraft:planks 5
setblock ~73~23~18 minecraft:planks 5
fill ~74~8~18 ~77~8~18 minecraft:planks 1
setblock ~74~24~18 minecraft:planks 5
setblock ~75~25~18 minecraft:planks 5
fill ~76~26~18 ~76~26~19 minecraft:planks 5
setblock ~76~27~18 minecraft:planks 5
fill ~77~1~18 ~79~1~91 minecraft:stonebrick 0
fill ~77~28~18 ~77~29~18 minecraft:planks 5
fill ~78~13~18 ~79~13~19 minecraft:planks 1
fill ~78~29~18 ~78~32~18 minecraft:planks 5
fill ~79~2~18 ~79~2~19 minecraft:stone_block_slab 0
fill ~79~32~18 ~79~35~18 minecraft:planks 5
setblock ~80~1~18 minecraft:quartz_block 2
setblock ~80~2~18 minecraft:quartz_block 2
setblock ~80~3~18 minecraft:end_rod 1
setblock ~80~4~18 minecraft:end_rod 0
fill ~80~5~18 ~80~6~18 minecraft:quartz_block 2
setblock ~80~7~18 minecraft:end_rod 1
setblock ~80~8~18 minecraft:end_rod 0
fill ~80~9~18 ~80~10~18 minecraft:quartz_block 2
setblock ~80~11~18 minecraft:end_rod 1
setblock ~80~12~18 minecraft:end_rod 0
fill ~80~13~18 ~80~14~18 minecraft:quartz_block 2
setblock ~80~15~18 minecraft:end_rod 1
setblock ~80~16~18 minecraft:end_rod 0
fill ~80~17~18 ~80~18~18 minecraft:quartz_block 2
setblock ~80~19~18 minecraft:end_rod 1
setblock ~80~20~18 minecraft:end_rod 0
fill ~80~21~18 ~80~23~18 minecraft:quartz_block 2
setblock ~80~24~18 minecraft:end_rod 1
setblock ~80~25~18 minecraft:end_rod 0
fill ~80~26~18 ~80~28~18 minecraft:quartz_block 2
fill ~80~29~18 ~80~30~18 minecraft:quartz_block 2
fill ~80~35~18 ~81~35~18 minecraft:planks 5
fill ~80~36~18 ~80~39~18 minecraft:planks 5
setblock ~80~40~18 minecraft:end_rod 1
fill ~81~1~18 ~83~1~91 minecraft:stonebrick 0
fill ~81~2~18 ~81~2~19 minecraft:stone_block_slab 0
fill ~81~13~18 ~82~13~20 minecraft:planks 1
fill ~81~32~18 ~82~32~18 minecraft:planks 5
fill ~81~33~18 ~81~34~18 minecraft:planks 5
setblock ~82~2~18 minecraft:wooden_slab 1
fill ~82~29~18 ~83~29~18 minecraft:planks 5
fill ~82~30~18 ~82~31~18 minecraft:planks 5
setblock ~83~28~18 minecraft:planks 5
fill ~84~3~18 ~85~3~18 minecraft:wooden_slab 1
fill ~84~26~18 ~84~26~19 minecraft:planks 5
setblock ~84~27~18 minecraft:planks 5
fill ~85~2~18 ~85~2~20 minecraft:planks 1
setblock ~85~25~18 minecraft:planks 5
setblock ~86~9~18 minecraft:stone_brick_stairs 4
fill ~86~10~18 ~86~11~18 minecraft:nether_brick
setblock ~86~12~18 minecraft:stone_brick_stairs 0
setblock ~86~24~18 minecraft:planks 5
fill ~87~2~18 ~87~5~18 minecraft:nether_brick
setblock ~87~6~18 minecraft:double_stone_block_slab 0
fill ~87~7~18 ~87~8~18 minecraft:nether_brick
setblock ~87~9~18 minecraft:quartz_stairs 1
setblock ~87~11~18 minecraft:wall_banner 5
setblock ~87~12~18 minecraft:quartz_stairs 5
fill ~87~17~18 ~87~17~19 minecraft:fence 5
setblock ~87~18~18 minecraft:fence 5
fill ~87~19~18 ~87~21~19 minecraft:stonebrick 0
setblock ~87~23~18 minecraft:planks 5
setblock ~88~22~18 minecraft:planks 5
setblock ~89~21~18 minecraft:planks 5
fill ~12~2~19 ~12~3~19 minecraft:stonebrick 0
fill ~12~4~19 ~12~4~20 minecraft:double_stone_block_slab 0
fill ~12~5~19 ~12~5~20 minecraft:stonebrick 0
setblock ~12~6~19 minecraft:nether_brick
fill ~12~7~19 ~12~8~20 minecraft:stonebrick 0
fill ~12~9~19 ~12~9~20 minecraft:nether_brick
fill ~12~10~19 ~12~11~20 minecraft:stonebrick 0
fill ~12~12~19 ~12~13~19 minecraft:nether_brick
setblock ~12~16~19 minecraft:fence 5
fill ~12~18~19 ~12~18~20 minecraft:stonebrick 0
fill ~13~6~19 ~16~6~19 minecraft:wooden_slab 1
fill ~14~24~19 ~14~24~21 minecraft:planks 5
fill ~16~26~19 ~16~26~20 minecraft:planks 5
fill ~17~27~19 ~17~27~20 minecraft:planks 5
fill ~17~28~19 ~18~28~19 minecraft:planks 5
setblock ~18~32~19 minecraft:end_rod 1
fill ~19~1~19 ~19~1~83 minecraft:stonebrick 0
setblock ~19~2~19 minecraft:stone_block_slab 0
fill ~19~13~19 ~19~13~22 minecraft:planks 1
fill ~19~29~19 ~19~29~21 minecraft:planks 5
fill ~19~30~19 ~19~32~20 minecraft:planks 5
fill ~19~33~19 ~19~35~19 minecraft:planks 5
fill ~20~28~19 ~21~28~19 minecraft:planks 5
setblock ~20~32~19 minecraft:end_rod 1
fill ~21~27~19 ~21~27~20 minecraft:planks 5
fill ~22~10~19 ~22~10~21 minecraft:planks 1
fill ~22~26~19 ~22~26~20 minecraft:planks 5
fill ~23~11~19 ~25~11~19 minecraft:planks 1
fill ~24~24~19 ~24~24~21 minecraft:planks 5
fill ~26~12~19 ~26~18~19 minecraft:stonebrick 0
fill ~27~18~19 ~46~18~19 minecraft:nether_brick
fill ~31~15~19 ~31~15~20 minecraft:stonebrick 0
setblock ~33~17~19 minecraft:stone 6
fill ~36~15~19 ~37~15~20 minecraft:stonebrick 0
fill ~37~2~19 ~37~2~20 minecraft:stonebrick 0
fill ~37~14~19 ~37~14~20 minecraft:stonebrick 0
setblock ~38~2~19 minecraft:lever 4
setblock ~38~5~19 minecraft:lever 4
setblock ~38~8~19 minecraft:lever 4
setblock ~38~11~19 minecraft:lever 4
setblock ~38~14~19 minecraft:lever 4
setblock ~38~17~19 minecraft:lever 4
fill ~39~2~19 ~40~2~20 minecraft:stonebrick 0
fill ~39~3~19 ~39~6~20 minecraft:stonebrick 0
fill ~39~9~19 ~39~15~20 minecraft:stonebrick 0
fill ~40~4~19 ~40~4~20 minecraft:stonebrick 0
fill ~40~6~19 ~40~6~20 minecraft:stonebrick 0
fill ~40~10~19 ~40~10~20 minecraft:stonebrick 0
fill ~40~12~19 ~40~15~20 minecraft:stonebrick 0
setblock ~41~15~19 minecraft:stonebrick 0
setblock ~43~16~19 minecraft:snow_layer 0
fill ~53~18~19 ~72~18~19 minecraft:nether_brick
fill ~55~15~19 ~62~15~19 minecraft:stonebrick 0
fill ~62~2~19 ~62~14~20 minecraft:stonebrick 0
setblock ~63~3~19 minecraft:lever 4
setblock ~63~5~19 minecraft:lever 4
setblock ~63~8~19 minecraft:lever 4
setblock ~63~11~19 minecraft:lever 4
setblock ~63~14~19 minecraft:lever 4
setblock ~63~17~19 minecraft:lever 4
fill ~64~3~19 ~64~3~20 minecraft:stonebrick 0
fill ~64~5~19 ~64~5~20 minecraft:stonebrick 0
fill ~64~7~19 ~64~7~20 minecraft:stonebrick 0
fill ~64~9~19 ~64~9~20 minecraft:stonebrick 0
fill ~64~11~19 ~64~11~20 minecraft:stonebrick 0
fill ~64~13~19 ~64~17~20 minecraft:stonebrick 0
fill ~65~15~19 ~66~15~19 minecraft:stonebrick 0
fill ~65~16~19 ~65~16~20 minecraft:stonebrick 0
fill ~67~13~19 ~68~13~19 minecraft:stonebrick 0
setblock ~67~14~19 minecraft:stonebrick 0
fill ~72~15~19 ~72~15~20 minecraft:stonebrick 0
fill ~73~10~19 ~73~13~19 minecraft:stonebrick 0
fill ~74~9~19 ~77~9~19 minecraft:wooden_slab 1
fill ~75~24~19 ~75~24~21 minecraft:planks 5
fill ~77~8~19 ~77~8~20 minecraft:planks 1
fill ~77~12~19 ~78~12~19 minecraft:wooden_slab 9
fill ~77~26~19 ~77~26~20 minecraft:planks 5
fill ~78~27~19 ~78~27~20 minecraft:planks 5
fill ~78~28~19 ~79~28~19 minecraft:planks 5
setblock ~79~32~19 minecraft:end_rod 1
fill ~80~1~19 ~80~1~91 minecraft:stonebrick 0
setblock ~80~2~19 minecraft:stone_block_slab 0
fill ~80~13~19 ~80~13~20 minecraft:planks 1
fill ~80~29~19 ~80~29~21 minecraft:planks 5
fill ~80~30~19 ~80~32~20 minecraft:planks 5
fill ~80~33~19 ~80~35~19 minecraft:planks 5
fill ~81~28~19 ~82~28~19 minecraft:planks 5
setblock ~81~32~19 minecraft:end_rod 1
fill ~82~27~19 ~82~27~20 minecraft:planks 5
setblock ~83~2~19 minecraft:wooden_slab 1
fill ~83~26~19 ~83~26~20 minecraft:planks 5
setblock ~84~2~19 minecraft:planks 1
fill ~87~2~19 ~87~5~19 minecraft:stonebrick 0
setblock ~87~6~19 minecraft:nether_brick
fill ~87~7~19 ~87~8~20 minecraft:stonebrick 0
fill ~87~9~19 ~87~9~20 minecraft:nether_brick
fill ~87~10~19 ~87~11~20 minecraft:stonebrick 0
setblock ~87~12~19 minecraft:nether_brick
setblock ~87~16~19 minecraft:fence 5
fill ~87~18~19 ~87~18~20 minecraft:stonebrick 0
setblock ~11~12~20 minecraft:end_rod 0
setblock ~11~13~20 minecraft:stone_brick_stairs 7
fill ~12~2~20 ~12~3~20 minecraft:cobblestone
setblock ~12~6~20 minecraft:stonebrick 0
fill ~12~12~20 ~12~17~20 minecraft:stonebrick 0
fill ~12~19~20 ~12~21~20 minecraft:cobblestone
fill ~13~5~20 ~14~5~20 minecraft:planks 1
fill ~13~6~20 ~14~6~20 minecraft:wooden_slab 1
fill ~15~6~20 ~16~6~20 minecraft:planks 1
fill ~16~7~20 ~16~7~23 minecraft:wooden_slab 1
fill ~17~26~20 ~17~26~21 minecraft:planks 5
setblock ~17~28~20 minecraft:end_rod 1
fill ~18~27~20 ~18~27~21 minecraft:planks 5
setblock ~18~28~20 minecraft:planks 5
fill ~20~12~20 ~20~12~21 minecraft:wooden_slab 9
fill ~20~13~20 ~20~13~21 minecraft:planks 1
fill ~20~27~20 ~20~27~21 minecraft:planks 5
setblock ~20~28~20 minecraft:planks 5
fill ~21~26~20 ~21~26~21 minecraft:planks 5
setblock ~21~28~20 minecraft:end_rod 1
fill ~22~11~20 ~25~11~20 minecraft:wooden_slab 1
fill ~22~25~20 ~22~25~21 minecraft:planks 5
fill ~26~2~20 ~26~6~20 minecraft:double_stone_block_slab 6
fill ~26~7~20 ~26~18~20 minecraft:stone 6
fill ~26~19~20 ~26~21~20 minecraft:cobblestone
fill ~27~16~20 ~33~18~20 minecraft:stonebrick 0
fill ~27~19~20 ~46~19~20 minecraft:nether_brick
fill ~32~2~20 ~33~2~20 minecraft:stonebrick 0
fill ~32~14~20 ~33~15~20 minecraft:stonebrick 0
fill ~33~3~20 ~33~13~20 minecraft:stonebrick 0
fill ~34~2~20 ~35~18~20 minecraft:stone 6
fill ~36~16~20 ~37~18~20 minecraft:stonebrick 0
fill ~38~2~20 ~38~18~20 minecraft:lit_redstone_lamp
fill ~39~16~20 ~40~18~20 minecraft:stonebrick 0
fill ~41~2~20 ~42~18~20 minecraft:stone 6
setblock ~43~2~20 minecraft:stonebrick 0
fill ~43~14~20 ~44~18~20 minecraft:stonebrick 0
fill ~44~2~20 ~44~13~21 minecraft:log2 1
fill ~45~16~20 ~45~18~20 minecraft:stonebrick 0
setblock ~46~18~20 minecraft:stonebrick 0
fill ~49~21~20 ~50~21~20 minecraft:glowstone
fill ~53~19~20 ~72~19~20 minecraft:nether_brick
fill ~54~16~20 ~55~18~20 minecraft:stonebrick 0
fill ~55~14~20 ~55~15~20 minecraft:stonebrick 0
fill ~56~2~20 ~56~18~20 minecraft:stone 6
fill ~57~2~20 ~58~3~20 minecraft:stonebrick 0
fill ~57~5~20 ~58~5~20 minecraft:stonebrick 0
fill ~57~7~20 ~58~7~20 minecraft:stonebrick 0
fill ~57~9~20 ~58~9~20 minecraft:stonebrick 0
fill ~57~11~20 ~58~11~20 minecraft:stonebrick 0
fill ~57~13~20 ~58~18~20 minecraft:stonebrick 0
fill ~59~2~20 ~60~18~20 minecraft:stone 6
fill ~61~15~20 ~62~18~20 minecraft:stonebrick 0
fill ~63~2~20 ~63~18~20 minecraft:lit_redstone_lamp
fill ~64~18~20 ~65~18~20 minecraft:stonebrick 0
setblock ~65~15~20 minecraft:stonebrick 0
setblock ~65~17~20 minecraft:stonebrick 0
fill ~66~2~20 ~67~18~20 minecraft:stone 6
fill ~68~2~20 ~68~18~20 minecraft:stonebrick 0
setblock ~69~3~20 minecraft:stonebrick 0
setblock ~69~5~20 minecraft:stonebrick 0
setblock ~69~7~20 minecraft:stonebrick 0
setblock ~69~9~20 minecraft:stonebrick 0
setblock ~69~11~20 minecraft:stonebrick 0
fill ~69~13~20 ~72~14~20 minecraft:stonebrick 0
fill ~69~15~20 ~71~18~20 minecraft:stonebrick 0
fill ~70~12~20 ~72~12~20 minecraft:stonebrick 0
fill ~71~11~20 ~72~11~20 minecraft:stonebrick 0
fill ~72~2~20 ~72~8~20 minecraft:stonebrick 0
setblock ~72~10~20 minecraft:stonebrick 0
fill ~72~16~20 ~72~18~20 minecraft:stonebrick 0
fill ~73~2~20 ~73~6~20 minecraft:double_stone_block_slab 6
fill ~73~7~20 ~73~18~20 minecraft:stone 6
fill ~73~19~20 ~73~21~20 minecraft:cobblestone
setblock ~74~9~20 minecraft:wooden_slab 1
fill ~75~9~20 ~77~9~20 minecraft:planks 1
fill ~78~26~20 ~78~26~21 minecraft:planks 5
setblock ~78~28~20 minecraft:end_rod 1
fill ~79~12~20 ~80~12~20 minecraft:wooden_slab 9
setblock ~79~13~20 minecraft:planks 1
fill ~79~27~20 ~79~27~21 minecraft:planks 5
setblock ~79~28~20 minecraft:planks 5
fill ~81~27~20 ~81~27~21 minecraft:planks 5
setblock ~81~28~20 minecraft:planks 5
fill ~82~26~20 ~82~26~21 minecraft:planks 5
setblock ~82~28~20 minecraft:end_rod 1
fill ~83~25~20 ~83~25~21 minecraft:planks 5
setblock ~84~2~20 minecraft:wooden_slab 1
setblock ~86~2~20 minecraft:planks 1
fill ~87~2~20 ~87~3~20 minecraft:cobblestone
fill ~87~4~20 ~87~6~20 minecraft:stonebrick 0
setblock ~87~12~20 minecraft:stonebrick 0
fill ~87~14~20 ~87~17~20 minecraft:stonebrick 0
fill ~87~19~20 ~87~21~20 minecraft:cobblestone
setblock ~88~12~20 minecraft:end_rod 0
setblock ~88~13~20 minecraft:stone_brick_stairs 7
setblock ~89~20~20 minecraft:end_rod 0
fill ~12~2~21 ~12~20~21 minecraft:cobblestone_wall 1
fill ~12~21~21 ~12~21~23 minecraft:planks 5
fill ~13~2~21 ~13~4~22 minecraft:cobblestone
fill ~13~5~21 ~13~17~21 minecraft:stonebrick 0
fill ~13~18~21 ~13~21~22 minecraft:cobblestone
fill ~13~22~21 ~13~22~23 minecraft:planks 5
fill ~14~5~21 ~14~5~22 minecraft:planks 1
fill ~14~6~21 ~14~6~22 minecraft:wooden_slab 1
fill ~14~23~21 ~14~23~23 minecraft:planks 5
fill ~15~6~21 ~15~6~23 minecraft:planks 1
fill ~15~24~21 ~15~24~22 minecraft:planks 5
fill ~16~25~21 ~17~25~21 minecraft:planks 5
fill ~17~7~21 ~19~7~21 minecraft:planks 1
fill ~18~8~21 ~18~8~24 minecraft:wooden_slab 1
fill ~18~26~21 ~18~26~22 minecraft:planks 5
fill ~19~8~21 ~21~8~21 minecraft:planks 1
fill ~19~27~21 ~19~27~22 minecraft:planks 5
setblock ~19~28~21 minecraft:planks 5
fill ~20~9~21 ~20~9~24 minecraft:wooden_slab 1
fill ~20~26~21 ~20~26~22 minecraft:planks 5
fill ~21~9~21 ~24~9~21 minecraft:planks 1
fill ~23~10~21 ~24~10~21 minecraft:planks 1
fill ~23~24~21 ~23~24~22 minecraft:planks 5
fill ~24~23~21 ~24~23~23 minecraft:planks 5
setblock ~25~6~21 minecraft:double_stone_block_slab 6
fill ~25~7~21 ~25~17~21 minecraft:stonebrick 0
fill ~25~18~21 ~25~21~22 minecraft:cobblestone
fill ~25~22~21 ~25~22~23 minecraft:planks 5
setblock ~26~19~21 minecraft:quartz_stairs 7
fill ~26~20~21 ~47~20~21 minecraft:nether_brick
fill ~26~21~21 ~26~21~23 minecraft:planks 5
fill ~29~19~21 ~46~19~21 minecraft:quartz_stairs 7
fill ~30~21~21 ~43~21~21 minecraft:fence 5
fill ~31~9~21 ~31~9~22 minecraft:fence 5
setblock ~31~10~21 minecraft:fence 5
fill ~38~9~21 ~38~9~22 minecraft:fence 5
setblock ~38~10~21 minecraft:fence 5
setblock ~43~2~21 minecraft:stone_brick_stairs 0
setblock ~44~14~21 minecraft:sea_lantern
setblock ~45~16~21 minecraft:sea_lantern
fill ~45~21~21 ~47~21~21 minecraft:nether_brick_stairs 2
setblock ~46~18~21 minecraft:sea_lantern
fill ~49~21~21 ~50~21~24 minecraft:stonebrick 0
fill ~52~20~21 ~73~20~23 minecraft:nether_brick
fill ~52~21~21 ~54~21~21 minecraft:nether_brick_stairs 2
fill ~53~18~21 ~53~19~21 minecraft:nether_brick
setblock ~54~16~21 minecraft:sea_lantern
fill ~54~19~21 ~73~19~21 minecraft:quartz_stairs 7
setblock ~55~14~21 minecraft:sea_lantern
fill ~55~21~21 ~71~21~21 minecraft:fence 5
fill ~56~2~21 ~56~2~26 minecraft:stone_brick_stairs 1
fill ~63~9~21 ~63~9~22 minecraft:fence 5
setblock ~63~10~21 minecraft:fence 5
fill ~70~9~21 ~70~9~22 minecraft:fence 5
setblock ~70~10~21 minecraft:fence 5
fill ~73~21~21 ~73~21~23 minecraft:planks 5
setblock ~74~6~21 minecraft:double_stone_block_slab 6
fill ~74~7~21 ~74~17~21 minecraft:stonebrick 0
fill ~74~18~21 ~74~21~22 minecraft:cobblestone
fill ~74~22~21 ~74~22~23 minecraft:planks 5
fill ~75~9~21 ~75~9~22 minecraft:planks 1
fill ~75~23~21 ~75~23~23 minecraft:planks 5
fill ~76~10~21 ~76~10~23 minecraft:wooden_slab 1
fill ~76~24~21 ~76~24~22 minecraft:planks 5
fill ~77~9~21 ~77~10~23 minecraft:planks 1
fill ~77~25~21 ~78~25~21 minecraft:planks 5
fill ~78~10~21 ~79~10~21 minecraft:planks 1
fill ~78~11~21 ~78~11~24 minecraft:wooden_slab 1
fill ~79~11~21 ~81~11~21 minecraft:planks 1
fill ~79~26~21 ~79~26~22 minecraft:planks 5
fill ~80~12~21 ~80~12~24 minecraft:wooden_slab 1
fill ~80~27~21 ~80~27~22 minecraft:planks 5
setblock ~80~28~21 minecraft:planks 5
fill ~81~12~21 ~85~12~21 minecraft:planks 1
fill ~81~26~21 ~81~26~22 minecraft:planks 5
fill ~82~13~21 ~82~13~24 minecraft:wooden_slab 1
fill ~84~24~21 ~84~24~22 minecraft:planks 5
setblock ~85~2~21 minecraft:wooden_slab 1
fill ~85~23~21 ~85~23~23 minecraft:planks 5
fill ~86~2~21 ~86~4~22 minecraft:cobblestone
fill ~86~5~21 ~86~17~21 minecraft:stonebrick 0
fill ~86~18~21 ~86~21~22 minecraft:cobblestone
fill ~86~22~21 ~86~22~23 minecraft:planks 5
fill ~87~2~21 ~87~20~21 minecraft:cobblestone_wall 1
fill ~87~21~21 ~87~21~23 minecraft:planks 5
setblock ~13~5~22 minecraft:cobblestone
fill ~13~6~22 ~13~16~22 minecraft:stonebrick 0
setblock ~13~17~22 minecraft:cobblestone
setblock ~14~13~22 minecraft:glowstone
fill ~16~24~22 ~16~24~23 minecraft:planks 5
fill ~17~7~22 ~17~7~24 minecraft:planks 1
fill ~17~12~22 ~19~12~22 minecraft:wooden_slab 9
fill ~17~25~22 ~21~25~22 minecraft:planks 5
fill ~19~8~22 ~19~8~24 minecraft:planks 1
setblock ~19~26~22 minecraft:planks 5
fill ~21~9~22 ~21~9~23 minecraft:planks 1
fill ~22~10~22 ~24~10~22 minecraft:wooden_slab 1
fill ~22~24~22 ~22~24~23 minecraft:planks 5
setblock ~25~7~22 minecraft:double_stone_block_slab 6
fill ~25~8~22 ~25~16~22 minecraft:stonebrick 0
setblock ~25~17~22 minecraft:cobblestone
setblock ~26~19~22 minecraft:quartz_stairs 5
fill ~26~20~22 ~31~20~29 minecraft:nether_brick
setblock ~31~8~22 minecraft:end_rod 0
fill ~32~20~22 ~32~20~23 minecraft:prismarine 2
fill ~33~20~22 ~33~20~23 minecraft:nether_brick
fill ~34~20~22 ~34~20~23 minecraft:prismarine 2
fill ~35~20~22 ~47~20~29 minecraft:nether_brick
setblock ~36~21~22 minecraft:torch 5
setblock ~38~8~22 minecraft:end_rod 0
fill ~43~2~22 ~44~2~22 minecraft:stone_brick_stairs 3
fill ~43~8~22 ~45~8~22 minecraft:quartz_stairs 7
setblock ~43~9~22 minecraft:quartz_stairs 2
fill ~44~9~22 ~44~13~22 minecraft:stonebrick 0
fill ~44~14~22 ~44~14~42 minecraft:stone_block_slab 0
setblock ~45~9~22 minecraft:quartz_stairs 2
fill ~45~21~22 ~45~21~29 minecraft:nether_brick_stairs 0
fill ~46~19~22 ~46~19~45 minecraft:quartz_stairs 4
fill ~46~21~22 ~46~21~27 minecraft:stonebrick 0
fill ~46~22~22 ~46~22~29 minecraft:nether_brick_stairs 0
fill ~47~21~22 ~47~21~27 minecraft:snow_layer 0
fill ~47~22~22 ~48~22~22 minecraft:nether_brick_stairs 2
fill ~51~22~22 ~52~22~22 minecraft:nether_brick_stairs 2
setblock ~53~18~22 minecraft:stonebrick 0
setblock ~53~19~22 minecraft:nether_brick
fill ~53~22~22 ~53~22~29 minecraft:nether_brick_stairs 1
fill ~54~21~22 ~54~21~29 minecraft:nether_brick_stairs 1
fill ~55~14~22 ~55~14~42 minecraft:stone_block_slab 0
setblock ~58~2~22 minecraft:stone_block_slab 6
setblock ~61~2~22 minecraft:stone_block_slab 6
setblock ~63~8~22 minecraft:end_rod 0
setblock ~64~2~22 minecraft:stone_block_slab 6
setblock ~67~2~22 minecraft:stone_block_slab 6
setblock ~70~2~22 minecraft:stone_block_slab 6
setblock ~70~8~22 minecraft:end_rod 0
setblock ~73~19~22 minecraft:quartz_stairs 4
setblock ~74~7~22 minecraft:double_stone_block_slab 6
fill ~74~8~22 ~74~16~22 minecraft:stonebrick 0
setblock ~74~17~22 minecraft:cobblestone
fill ~77~24~22 ~77~24~23 minecraft:planks 5
fill ~78~25~22 ~82~25~22 minecraft:planks 5
fill ~79~11~22 ~79~11~24 minecraft:planks 1
setblock ~80~26~22 minecraft:planks 5
fill ~81~12~22 ~81~12~24 minecraft:planks 1
fill ~83~24~22 ~83~24~23 minecraft:planks 5
setblock ~86~5~22 minecraft:cobblestone
fill ~86~6~22 ~86~16~22 minecraft:stonebrick 0
setblock ~86~17~22 minecraft:cobblestone
setblock ~1~1~23 minecraft:stone_brick_stairs 7
setblock ~1~2~23 minecraft:cobblestone_wall 1
fill ~2~1~23 ~2~1~25 minecraft:stone_brick_stairs 4
setblock ~2~2~23 minecraft:cobblestone_wall 1
fill ~5~1~23 ~5~1~28 minecraft:stonebrick 0
fill ~6~0~23 ~6~0~25 minecraft:glowstone
fill ~6~1~23 ~6~1~25 minecraft:stained_glass 7
setblock ~12~20~23 minecraft:end_rod 0
fill ~13~2~23 ~13~5~23 minecraft:iron_bars
fill ~13~17~23 ~13~20~23 minecraft:iron_bars
fill ~13~21~23 ~13~21~24 minecraft:planks 5
fill ~14~2~23 ~14~20~23 minecraft:nether_brick
setblock ~14~21~23 minecraft:cobblestone
fill ~14~22~23 ~14~22~24 minecraft:planks 5
setblock ~14~24~23 minecraft:end_rod 1
fill ~15~23~23 ~16~23~23 minecraft:planks 5
fill ~17~12~23 ~17~12~24 minecraft:wooden_slab 9
fill ~17~13~23 ~17~13~24 minecraft:planks 1
fill ~17~24~23 ~18~24~23 minecraft:planks 5
setblock ~19~25~23 minecraft:planks 5
fill ~20~24~23 ~21~24~23 minecraft:planks 5
fill ~22~9~23 ~23~9~23 minecraft:planks 1
fill ~22~23~23 ~23~23~23 minecraft:planks 5
setblock ~24~8~23 minecraft:double_stone_block_slab 6
fill ~24~9~23 ~24~11~23 minecraft:nether_brick
fill ~24~12~23 ~24~15~23 minecraft:glowstone
fill ~24~16~23 ~24~18~23 minecraft:nether_brick
setblock ~24~19~23 minecraft:sea_lantern
fill ~24~20~23 ~25~20~31 minecraft:nether_brick
setblock ~24~21~23 minecraft:cobblestone
fill ~24~22~23 ~24~22~24 minecraft:planks 5
setblock ~24~24~23 minecraft:end_rod 1
setblock ~25~14~23 minecraft:wall_banner 5
fill ~25~17~23 ~25~19~23 minecraft:iron_bars
fill ~25~21~23 ~25~21~24 minecraft:planks 5
setblock ~33~34~23 minecraft:end_rod 0
fill ~33~35~23 ~33~35~24 minecraft:planks 5
fill ~43~9~23 ~45~9~23 minecraft:quartz_stairs 7
setblock ~43~10~23 minecraft:quartz_stairs 2
fill ~44~10~23 ~44~13~23 minecraft:stonebrick 0
setblock ~45~10~23 minecraft:quartz_stairs 2
fill ~47~22~23 ~47~23~29 minecraft:stonebrick 0
fill ~47~24~23 ~52~24~23 minecraft:fence 5
fill ~48~22~23 ~48~22~27 minecraft:snow_layer 0
fill ~48~23~23 ~48~23~29 minecraft:stonebrick 0
fill ~51~22~23 ~52~23~29 minecraft:stonebrick 0
fill ~52~21~23 ~52~21~29 minecraft:stonebrick 0
setblock ~53~18~23 minecraft:sea_lantern
fill ~53~19~23 ~53~19~44 minecraft:quartz_stairs 5
setblock ~58~2~23 minecraft:wall_sign 3
setblock ~61~2~23 minecraft:wall_sign 3
setblock ~64~2~23 minecraft:wall_sign 3
setblock ~66~34~23 minecraft:end_rod 0
fill ~66~35~23 ~66~35~24 minecraft:planks 5
setblock ~67~2~23 minecraft:wall_sign 3
setblock ~70~2~23 minecraft:wall_sign 3
setblock ~74~14~23 minecraft:wall_banner 4
fill ~74~17~23 ~74~19~23 minecraft:iron_bars
fill ~74~20~23 ~75~20~30 minecraft:nether_brick
fill ~74~21~23 ~75~21~23 minecraft:cobblestone
setblock ~75~8~23 minecraft:double_stone_block_slab 6
fill ~75~9~23 ~75~11~23 minecraft:nether_brick
fill ~75~12~23 ~75~15~23 minecraft:glowstone
fill ~75~16~23 ~75~18~23 minecraft:nether_brick
setblock ~75~19~23 minecraft:sea_lantern
setblock ~75~22~23 minecraft:planks 5
setblock ~75~24~23 minecraft:end_rod 1
fill ~76~23~23 ~77~23~23 minecraft:planks 5
fill ~78~24~23 ~79~24~23 minecraft:planks 5
setblock ~80~25~23 minecraft:planks 5
fill ~81~24~23 ~82~24~23 minecraft:planks 5
fill ~83~23~23 ~84~23~23 minecraft:planks 5
setblock ~84~13~23 minecraft:glowstone
fill ~85~2~23 ~85~4~23 minecraft:nether_brick
fill ~85~5~23 ~85~7~23 minecraft:glowstone
fill ~85~8~23 ~85~20~23 minecraft:nether_brick
setblock ~85~21~23 minecraft:cobblestone
fill ~85~22~23 ~85~22~24 minecraft:planks 5
setblock ~85~24~23 minecraft:end_rod 1
fill ~86~2~23 ~86~5~23 minecraft:iron_bars
fill ~86~17~23 ~86~20~23 minecraft:iron_bars
fill ~86~21~23 ~86~21~24 minecraft:planks 5
setblock ~88~20~23 minecraft:end_rod 0
fill ~93~0~23 ~93~0~25 minecraft:glowstone
fill ~93~1~23 ~93~1~25 minecraft:stained_glass 7
fill ~94~1~23 ~94~1~28 minecraft:stonebrick 0
fill ~97~1~23 ~98~1~23 minecraft:stone_brick_stairs 7
setblock ~97~2~23 minecraft:cobblestone_wall 1
setblock ~98~2~23 minecraft:cobblestone_wall 1
fill ~2~2~24 ~2~2~25 minecraft:cobblestone_wall 1
fill ~14~2~24 ~14~5~24 minecraft:iron_bars
fill ~14~17~24 ~14~20~24 minecraft:iron_bars
fill ~14~21~24 ~14~21~25 minecraft:planks 5
fill ~15~2~24 ~16~4~24 minecraft:cobblestone
setblock ~15~5~24 minecraft:cobblestone
fill ~15~6~24 ~16~16~24 minecraft:stonebrick 0
fill ~15~17~24 ~15~21~24 minecraft:cobblestone
fill ~15~22~24 ~16~22~24 minecraft:planks 5
setblock ~16~5~24 minecraft:stonebrick 0
setblock ~16~17~24 minecraft:stonebrick 0
fill ~16~18~24 ~16~21~24 minecraft:cobblestone
fill ~16~23~24 ~22~23~24 minecraft:planks 5
setblock ~19~24~24 minecraft:planks 5
setblock ~21~9~24 minecraft:wooden_slab 1
setblock ~22~6~24 minecraft:double_stone_block_slab 6
fill ~22~7~24 ~22~17~24 minecraft:stonebrick 0
fill ~22~18~24 ~23~21~24 minecraft:cobblestone
fill ~22~22~24 ~23~22~24 minecraft:planks 5
setblock ~23~7~24 minecraft:double_stone_block_slab 6
fill ~23~8~24 ~23~16~24 minecraft:stonebrick 0
setblock ~23~17~24 minecraft:cobblestone
setblock ~24~14~24 minecraft:wall_banner 3
fill ~24~17~24 ~24~19~24 minecraft:iron_bars
fill ~24~21~24 ~24~21~25 minecraft:planks 5
fill ~30~27~24 ~30~27~25 minecraft:quartz_stairs 0
fill ~30~35~24 ~32~35~24 minecraft:planks 5
setblock ~31~28~24 minecraft:quartz_stairs 0
setblock ~32~20~24 minecraft:nether_brick
setblock ~32~29~24 minecraft:quartz_stairs 0
setblock ~33~20~24 minecraft:prismarine 2
fill ~33~21~24 ~33~27~24 minecraft:stained_glass_pane 5
setblock ~33~28~24 minecraft:double_stone_block_slab 6
setblock ~33~29~24 minecraft:end_rod 1
setblock ~33~30~24 minecraft:stone_block_slab 6
setblock ~33~33~24 minecraft:wall_banner 2
fill ~33~36~24 ~33~36~25 minecraft:planks 5
setblock ~34~20~24 minecraft:nether_brick
setblock ~34~29~24 minecraft:quartz_stairs 1
fill ~34~35~24 ~36~35~24 minecraft:planks 5
setblock ~35~28~24 minecraft:quartz_stairs 1
fill ~36~27~24 ~36~27~25 minecraft:quartz_stairs 1
fill ~43~10~24 ~45~10~24 minecraft:quartz_stairs 7
setblock ~43~11~24 minecraft:quartz_stairs 2
fill ~44~11~24 ~44~13~28 minecraft:stonebrick 0
setblock ~45~11~24 minecraft:quartz_stairs 2
fill ~47~24~24 ~47~24~29 minecraft:fence 5
setblock ~48~24~24 minecraft:chest 3
setblock ~51~24~24 minecraft:chest 3
fill ~52~20~24 ~65~20~24 minecraft:nether_brick
fill ~52~24~24 ~52~24~29 minecraft:fence 5
fill ~63~27~24 ~63~27~25 minecraft:quartz_stairs 0
setblock ~63~34~24 minecraft:end_rod 0
fill ~63~35~24 ~65~35~24 minecraft:planks 5
setblock ~64~28~24 minecraft:quartz_stairs 0
setblock ~65~21~24 minecraft:torch 5
setblock ~65~29~24 minecraft:quartz_stairs 0
setblock ~66~20~24 minecraft:prismarine 2
fill ~66~21~24 ~66~27~24 minecraft:stained_glass_pane 2
setblock ~66~28~24 minecraft:double_stone_block_slab 6
setblock ~66~29~24 minecraft:end_rod 1
setblock ~66~30~24 minecraft:stone_block_slab 6
setblock ~66~33~24 minecraft:wall_banner 2
fill ~66~36~24 ~66~36~25 minecraft:planks 5
fill ~67~20~24 ~73~20~24 minecraft:nether_brick
setblock ~67~21~24 minecraft:torch 5
setblock ~67~29~24 minecraft:quartz_stairs 1
fill ~67~35~24 ~69~35~24 minecraft:planks 5
setblock ~68~28~24 minecraft:quartz_stairs 1
fill ~69~27~24 ~69~27~25 minecraft:quartz_stairs 1
setblock ~69~34~24 minecraft:end_rod 0
fill ~74~21~24 ~75~21~24 minecraft:planks 5
setblock ~75~14~24 minecraft:wall_banner 3
fill ~75~17~24 ~75~19~24 minecraft:iron_bars
setblock ~76~7~24 minecraft:double_stone_block_slab 6
fill ~76~8~24 ~77~16~24 minecraft:stonebrick 0
fill ~76~17~24 ~76~21~24 minecraft:cobblestone
fill ~76~22~24 ~77~22~24 minecraft:planks 5
setblock ~77~6~24 minecraft:double_stone_block_slab 6
setblock ~77~7~24 minecraft:stonebrick 0
setblock ~77~17~24 minecraft:stonebrick 0
fill ~77~18~24 ~77~21~24 minecraft:cobblestone
fill ~77~23~24 ~83~23~24 minecraft:planks 5
setblock ~80~24~24 minecraft:planks 5
fill ~83~2~24 ~83~17~24 minecraft:stonebrick 0
fill ~83~18~24 ~84~21~24 minecraft:cobblestone
fill ~84~2~24 ~84~5~24 minecraft:cobblestone
fill ~84~6~24 ~84~16~24 minecraft:stonebrick 0
setblock ~84~17~24 minecraft:cobblestone
setblock ~84~22~24 minecraft:planks 5
fill ~85~2~24 ~85~5~24 minecraft:iron_bars
fill ~85~17~24 ~85~20~24 minecraft:iron_bars
fill ~85~21~24 ~85~21~25 minecraft:planks 5
fill ~97~1~24 ~97~1~26 minecraft:stone_brick_stairs 5
fill ~97~2~24 ~97~2~25 minecraft:cobblestone_wall 1
setblock ~14~20~25 minecraft:end_rod 0
fill ~15~21~25 ~16~21~25 minecraft:planks 5
fill ~16~2~25 ~16~20~25 minecraft:cobblestone_wall 1
fill ~16~22~25 ~22~22~25 minecraft:planks 5
fill ~17~2~25 ~20~2~26 minecraft:stonebrick 0
fill ~17~3~25 ~17~3~26 minecraft:stonebrick 3
fill ~17~4~25 ~20~4~26 minecraft:stonebrick 0
fill ~17~5~25 ~17~5~26 minecraft:stonebrick 3
fill ~17~6~25 ~20~6~26 minecraft:stonebrick 0
fill ~17~7~25 ~17~7~26 minecraft:stonebrick 3
fill ~17~8~25 ~20~8~26 minecraft:stonebrick 0
fill ~17~9~25 ~20~10~25 minecraft:stonebrick 0
fill ~17~11~25 ~17~11~26 minecraft:stonebrick 3
fill ~17~12~25 ~20~12~26 minecraft:stonebrick 0
fill ~17~13~25 ~17~13~26 minecraft:stonebrick 3
fill ~17~14~25 ~20~18~25 minecraft:stonebrick 0
fill ~17~19~25 ~17~21~25 minecraft:cobblestone
fill ~18~3~25 ~20~3~27 minecraft:stonebrick 0
fill ~18~5~25 ~20~5~27 minecraft:stonebrick 0
fill ~18~7~25 ~20~7~27 minecraft:stonebrick 0
fill ~18~11~25 ~20~11~27 minecraft:stonebrick 0
fill ~18~13~25 ~20~13~27 minecraft:stonebrick 0
fill ~18~19~25 ~20~21~25 minecraft:stonebrick 0
setblock ~19~23~25 minecraft:planks 5
fill ~21~2~25 ~21~6~25 minecraft:double_stone_block_slab 6
fill ~21~7~25 ~21~18~25 minecraft:stone 6
fill ~21~19~25 ~21~21~25 minecraft:cobblestone
fill ~22~19~25 ~22~19~44 minecraft:quartz_stairs 5
fill ~22~20~25 ~23~20~46 minecraft:nether_brick
fill ~22~21~25 ~23~21~25 minecraft:planks 5
setblock ~23~19~25 minecraft:quartz_stairs 7
setblock ~28~34~25 minecraft:end_rod 0
fill ~28~35~25 ~30~35~25 minecraft:planks 5
fill ~30~36~25 ~32~36~25 minecraft:planks 5
fill ~31~1~25 ~32~1~25 minecraft:stonebrick 0
setblock ~31~27~25 minecraft:nether_brick_stairs 5
fill ~31~28~25 ~31~30~25 minecraft:stonebrick 0
fill ~31~31~25 ~32~31~25 minecraft:nether_brick
fill ~31~32~25 ~32~33~25 minecraft:stonebrick 0
fill ~31~34~25 ~31~35~25 minecraft:stonebrick 0
setblock ~32~20~25 minecraft:prismarine 2
setblock ~32~28~25 minecraft:nether_brick_stairs 5
fill ~32~29~25 ~32~30~25 minecraft:stonebrick 0
setblock ~32~34~25 minecraft:nether_brick
setblock ~32~35~25 minecraft:stonebrick 0
setblock ~33~1~25 minecraft:glowstone
setblock ~33~20~25 minecraft:glowstone
setblock ~33~28~25 minecraft:stone_block_slab 15
fill ~33~29~25 ~33~30~25 minecraft:nether_brick
setblock ~33~31~25 minecraft:double_stone_block_slab 0
fill ~33~32~25 ~33~33~25 minecraft:nether_brick
setblock ~33~34~25 minecraft:double_stone_block_slab 0
setblock ~33~35~25 minecraft:nether_brick
fill ~33~37~25 ~33~37~26 minecraft:planks 5
fill ~34~1~25 ~65~1~25 minecraft:stonebrick 0
setblock ~34~20~25 minecraft:prismarine 2
setblock ~34~28~25 minecraft:nether_brick_stairs 4
fill ~34~29~25 ~35~30~25 minecraft:stonebrick 0
fill ~34~31~25 ~35~31~25 minecraft:nether_brick
fill ~34~32~25 ~35~33~25 minecraft:stonebrick 0
setblock ~34~34~25 minecraft:nether_brick
fill ~34~35~25 ~35~35~25 minecraft:stonebrick 0
fill ~34~36~25 ~36~36~25 minecraft:planks 5
setblock ~35~27~25 minecraft:nether_brick_stairs 4
setblock ~35~28~25 minecraft:stonebrick 0
setblock ~35~34~25 minecraft:stonebrick 0
fill ~36~35~25 ~38~35~25 minecraft:planks 5
setblock ~38~34~25 minecraft:end_rod 0
fill ~43~10~25 ~45~10~25 minecraft:stone_block_slab 14
setblock ~43~11~25 minecraft:end_rod 1
setblock ~43~12~25 minecraft:stone_block_slab 6
fill ~44~2~25 ~44~9~25 minecraft:stained_glass_pane 5
setblock ~45~11~25 minecraft:end_rod 1
setblock ~45~12~25 minecraft:stone_block_slab 6
fill ~49~21~25 ~50~21~25 minecraft:glowstone
fill ~52~20~25 ~64~20~29 minecraft:nether_brick
fill ~55~3~25 ~55~7~25 minecraft:stained_glass 15
fill ~55~8~25 ~55~13~26 minecraft:stonebrick 0
fill ~61~35~25 ~63~35~25 minecraft:planks 5
fill ~63~36~25 ~65~36~25 minecraft:planks 5
setblock ~64~27~25 minecraft:nether_brick_stairs 5
fill ~64~28~25 ~64~30~25 minecraft:stonebrick 0
fill ~64~31~25 ~65~31~25 minecraft:nether_brick
fill ~64~32~25 ~65~33~25 minecraft:stonebrick 0
fill ~64~34~25 ~64~35~25 minecraft:stonebrick 0
setblock ~65~20~25 minecraft:prismarine 2
setblock ~65~28~25 minecraft:nether_brick_stairs 5
fill ~65~29~25 ~65~30~25 minecraft:stonebrick 0
setblock ~65~34~25 minecraft:nether_brick
setblock ~65~35~25 minecraft:stonebrick 0
setblock ~66~1~25 minecraft:glowstone
setblock ~66~20~25 minecraft:glowstone
setblock ~66~28~25 minecraft:stone_block_slab 15
fill ~66~29~25 ~66~30~25 minecraft:nether_brick
setblock ~66~31~25 minecraft:double_stone_block_slab 0
fill ~66~32~25 ~66~33~25 minecraft:nether_brick
setblock ~66~34~25 minecraft:double_stone_block_slab 0
setblock ~66~35~25 minecraft:nether_brick
fill ~66~37~25 ~66~37~26 minecraft:planks 5
fill ~67~1~25 ~68~1~25 minecraft:stonebrick 0
setblock ~67~20~25 minecraft:prismarine 2
setblock ~67~28~25 minecraft:nether_brick_stairs 4
fill ~67~29~25 ~68~30~25 minecraft:stonebrick 0
fill ~67~31~25 ~68~31~25 minecraft:nether_brick
fill ~67~32~25 ~68~33~25 minecraft:stonebrick 0
setblock ~67~34~25 minecraft:nether_brick
fill ~67~35~25 ~68~35~25 minecraft:stonebrick 0
fill ~67~36~25 ~69~36~25 minecraft:planks 5
fill ~68~20~25 ~73~20~29 minecraft:nether_brick
setblock ~68~27~25 minecraft:nether_brick_stairs 4
setblock ~68~28~25 minecraft:stonebrick 0
setblock ~68~34~25 minecraft:stonebrick 0
fill ~69~35~25 ~71~35~25 minecraft:planks 5
fill ~75~21~25 ~77~21~25 minecraft:planks 5
setblock ~76~19~25 minecraft:quartz_stairs 7
fill ~76~20~25 ~77~20~30 minecraft:nether_brick
setblock ~77~19~25 minecraft:quartz_stairs 4
fill ~77~22~25 ~83~22~25 minecraft:planks 5
fill ~78~2~25 ~78~6~25 minecraft:double_stone_block_slab 6
fill ~78~7~25 ~78~18~25 minecraft:stone 6
fill ~78~19~25 ~78~21~25 minecraft:cobblestone
fill ~79~2~25 ~82~13~29 minecraft:stonebrick 0
fill ~79~14~25 ~82~18~25 minecraft:stonebrick 0
fill ~79~19~25 ~81~21~25 minecraft:stonebrick 0
setblock ~80~23~25 minecraft:planks 5
fill ~82~19~25 ~82~21~25 minecraft:cobblestone
fill ~83~2~25 ~83~20~25 minecraft:cobblestone_wall 1
fill ~83~21~25 ~84~21~25 minecraft:planks 5
setblock ~85~20~25 minecraft:end_rod 0
setblock ~2~1~26 minecraft:stone_brick_stairs 7
setblock ~2~2~26 minecraft:cobblestone_wall 1
fill ~3~1~26 ~3~1~27 minecraft:stone_brick_stairs 4
setblock ~3~2~26 minecraft:cobblestone_wall 1
fill ~6~1~26 ~6~1~29 minecraft:stonebrick 0
fill ~7~0~26 ~7~0~27 minecraft:glowstone
fill ~7~1~26 ~7~1~27 minecraft:stained_glass 7
fill ~16~21~26 ~22~21~26 minecraft:planks 5
setblock ~17~9~26 minecraft:stonebrick 3
fill ~17~10~26 ~21~10~26 minecraft:stonebrick 0
setblock ~17~14~26 minecraft:nether_brick_stairs 0
fill ~18~9~26 ~21~9~27 minecraft:stonebrick 0
fill ~18~14~26 ~21~14~27 minecraft:stonebrick 0
setblock ~18~15~26 minecraft:quartz_stairs 0
fill ~18~16~26 ~18~16~44 minecraft:nether_brick
fill ~19~15~26 ~21~15~30 minecraft:stonebrick 0
fill ~19~17~26 ~19~17~44 minecraft:nether_brick
setblock ~19~22~26 minecraft:planks 5
fill ~20~18~26 ~20~18~45 minecraft:nether_brick
fill ~21~2~26 ~21~8~28 minecraft:stonebrick 0
fill ~21~11~26 ~21~13~30 minecraft:stonebrick 0
fill ~21~16~26 ~21~18~30 minecraft:stonebrick 0
fill ~21~19~26 ~21~19~45 minecraft:nether_brick
fill ~28~21~26 ~28~23~26 minecraft:iron_bars
fill ~28~32~26 ~28~34~26 minecraft:iron_bars
fill ~28~35~26 ~28~36~26 minecraft:planks 5
fill ~29~21~26 ~29~23~26 minecraft:cobblestone
fill ~29~24~26 ~29~31~26 minecraft:stonebrick 0
fill ~29~32~26 ~29~34~26 minecraft:cobblestone
fill ~29~35~26 ~30~35~26 minecraft:stonebrick 0
fill ~29~36~26 ~30~36~26 minecraft:planks 5
fill ~30~21~26 ~30~26~26 minecraft:log2 1
fill ~30~27~26 ~30~34~26 minecraft:stonebrick 0
fill ~30~37~26 ~32~37~26 minecraft:planks 5
setblock ~31~1~26 minecraft:stonebrick 0
setblock ~31~21~26 minecraft:trapdoor 1
setblock ~31~22~26 minecraft:trapdoor 0
fill ~31~23~26 ~31~27~26 minecraft:trapdoor 1
setblock ~31~28~26 minecraft:quartz_stairs 0
setblock ~32~1~26 minecraft:glowstone
fill ~32~20~26 ~32~20~27 minecraft:nether_brick
setblock ~32~29~26 minecraft:quartz_stairs 0
fill ~33~1~26 ~33~1~31 minecraft:stonebrick 0
fill ~33~20~26 ~33~20~27 minecraft:prismarine 2
setblock ~33~28~26 minecraft:stone_block_slab 14
setblock ~33~29~26 minecraft:end_rod 1
setblock ~33~30~26 minecraft:stone_block_slab 6
fill ~33~38~26 ~33~38~27 minecraft:planks 5
setblock ~34~1~26 minecraft:glowstone
fill ~34~20~26 ~34~20~27 minecraft:nether_brick
setblock ~34~29~26 minecraft:quartz_stairs 1
fill ~34~37~26 ~36~37~26 minecraft:planks 5
fill ~35~1~26 ~64~1~26 minecraft:stonebrick 0
fill ~35~21~26 ~35~27~26 minecraft:trapdoor 1
setblock ~35~28~26 minecraft:quartz_stairs 1
fill ~36~21~26 ~36~26~26 minecraft:log2 1
fill ~36~27~26 ~37~31~26 minecraft:stonebrick 0
fill ~36~32~26 ~36~35~26 minecraft:stonebrick 0
fill ~36~36~26 ~38~36~26 minecraft:planks 5
fill ~37~21~26 ~37~23~26 minecraft:cobblestone
fill ~37~24~26 ~37~26~26 minecraft:stonebrick 0
fill ~37~32~26 ~37~35~26 minecraft:cobblestone
fill ~38~21~26 ~38~23~26 minecraft:iron_bars
fill ~38~32~26 ~38~34~26 minecraft:iron_bars
fill ~38~35~26 ~39~35~26 minecraft:planks 5
fill ~43~10~26 ~45~10~26 minecraft:quartz_stairs 6
setblock ~43~11~26 minecraft:quartz_stairs 3
setblock ~45~11~26 minecraft:quartz_stairs 3
fill ~49~21~26 ~50~21~29 minecraft:stonebrick 0
setblock ~53~21~26 minecraft:torch 5
setblock ~54~8~26 minecraft:quartz_stairs 2
fill ~55~3~26 ~55~7~26 minecraft:stonebrick 0
setblock ~56~8~26 minecraft:quartz_stairs 2
setblock ~59~21~26 minecraft:torch 5
fill ~60~35~26 ~61~35~26 minecraft:planks 5
fill ~61~21~26 ~61~23~26 minecraft:iron_bars
fill ~61~32~26 ~61~34~26 minecraft:iron_bars
fill ~61~36~26 ~63~36~26 minecraft:planks 5
fill ~62~21~26 ~62~23~26 minecraft:cobblestone
fill ~62~24~26 ~62~31~26 minecraft:stonebrick 0
fill ~62~32~26 ~62~35~26 minecraft:cobblestone
fill ~63~21~26 ~63~26~26 minecraft:log2 1
fill ~63~27~26 ~63~35~26 minecraft:stonebrick 0
fill ~63~37~26 ~65~37~26 minecraft:planks 5
setblock ~64~21~26 minecraft:trapdoor 1
setblock ~64~22~26 minecraft:trapdoor 0
fill ~64~23~26 ~64~27~26 minecraft:trapdoor 1
setblock ~64~28~26 minecraft:quartz_stairs 0
setblock ~65~1~26 minecraft:glowstone
fill ~65~20~26 ~65~20~27 minecraft:nether_brick
setblock ~65~29~26 minecraft:quartz_stairs 0
fill ~66~1~26 ~66~1~31 minecraft:stonebrick 0
fill ~66~20~26 ~66~20~27 minecraft:prismarine 2
setblock ~66~28~26 minecraft:stone_block_slab 14
setblock ~66~29~26 minecraft:end_rod 1
setblock ~66~30~26 minecraft:stone_block_slab 6
setblock ~66~33~26 minecraft:trapdoor 3
fill ~66~38~26 ~66~38~27 minecraft:planks 5
setblock ~67~1~26 minecraft:glowstone
fill ~67~20~26 ~67~20~27 minecraft:nether_brick
setblock ~67~29~26 minecraft:quartz_stairs 1
fill ~67~37~26 ~69~37~26 minecraft:planks 5
setblock ~68~1~26 minecraft:stonebrick 0
setblock ~68~21~26 minecraft:trapdoor 1
fill ~68~22~26 ~68~23~26 minecraft:trapdoor 1
fill ~68~24~26 ~68~25~26 minecraft:trapdoor 1
fill ~68~26~26 ~68~27~26 minecraft:trapdoor 1
setblock ~68~28~26 minecraft:quartz_stairs 1
fill ~69~21~26 ~69~26~26 minecraft:log2 1
fill ~69~27~26 ~70~31~26 minecraft:stonebrick 0
fill ~69~32~26 ~69~35~26 minecraft:stonebrick 0
fill ~69~36~26 ~71~36~26 minecraft:planks 5
fill ~70~21~26 ~70~23~26 minecraft:cobblestone
fill ~70~24~26 ~70~26~26 minecraft:stonebrick 0
fill ~70~32~26 ~70~34~26 minecraft:cobblestone
setblock ~70~35~26 minecraft:stonebrick 0
fill ~71~21~26 ~71~23~26 minecraft:iron_bars
fill ~71~32~26 ~71~34~26 minecraft:iron_bars
fill ~71~35~26 ~72~35~26 minecraft:planks 5
fill ~77~21~26 ~83~21~26 minecraft:planks 5
fill ~78~2~26 ~78~18~32 minecraft:stonebrick 0
fill ~78~19~26 ~78~19~45 minecraft:nether_brick
fill ~79~14~26 ~79~14~36 minecraft:stonebrick 0
setblock ~79~15~26 minecraft:stonebrick 0
fill ~79~18~26 ~79~18~45 minecraft:nether_brick
fill ~80~17~26 ~80~17~44 minecraft:nether_brick
setblock ~80~22~26 minecraft:planks 5
fill ~81~14~26 ~81~14~29 minecraft:stonebrick 0
fill ~81~15~26 ~82~15~33 minecraft:nether_brick
fill ~81~16~26 ~81~16~44 minecraft:nether_brick
setblock ~82~14~26 minecraft:end_rod 1
setblock ~84~1~26 minecraft:glowstone
fill ~92~0~26 ~92~0~27 minecraft:glowstone
fill ~92~1~26 ~92~1~27 minecraft:stained_glass 7
fill ~93~1~26 ~93~1~29 minecraft:stonebrick 0
setblock ~96~1~26 minecraft:stone_brick_stairs 7
setblock ~96~2~26 minecraft:cobblestone_wall 1
setblock ~97~2~26 minecraft:cobblestone_wall 1
setblock ~3~2~27 minecraft:cobblestone_wall 1
fill ~17~2~27 ~17~2~29 minecraft:cobblestone_wall 0
setblock ~17~8~27 minecraft:cobblestone_wall 0
fill ~17~9~27 ~17~10~27 minecraft:cobblestone_wall 0
setblock ~17~14~27 minecraft:quartz_stairs 0
fill ~18~2~27 ~20~2~27 minecraft:stonebrick 0
fill ~18~4~27 ~20~4~27 minecraft:stonebrick 0
fill ~18~6~27 ~20~6~27 minecraft:stonebrick 0
fill ~18~8~27 ~20~8~27 minecraft:stonebrick 0
fill ~18~10~27 ~21~10~27 minecraft:stonebrick 0
fill ~18~12~27 ~20~12~27 minecraft:stonebrick 0
setblock ~19~21~27 minecraft:planks 5
fill ~24~21~27 ~24~21~43 minecraft:fence 5
fill ~26~35~27 ~27~35~27 minecraft:planks 5
fill ~27~21~27 ~27~23~27 minecraft:iron_bars
fill ~27~32~27 ~27~34~27 minecraft:iron_bars
fill ~27~36~27 ~28~36~27 minecraft:planks 5
fill ~28~21~27 ~28~35~27 minecraft:nether_brick
fill ~28~37~27 ~30~37~27 minecraft:planks 5
setblock ~28~38~27 minecraft:end_rod 1
setblock ~29~21~27 minecraft:crafting_table
setblock ~29~22~27 minecraft:chest 3
fill ~29~26~27 ~29~28~27 minecraft:stained_glass_pane 5
fill ~30~38~27 ~32~38~27 minecraft:planks 5
setblock ~31~1~27 minecraft:glowstone
fill ~32~1~27 ~32~1~37 minecraft:stonebrick 0
fill ~33~39~27 ~33~39~28 minecraft:planks 5
fill ~34~1~27 ~34~1~37 minecraft:stonebrick 0
fill ~34~38~27 ~36~38~27 minecraft:planks 5
setblock ~35~1~27 minecraft:glowstone
fill ~36~1~27 ~48~1~27 minecraft:stonebrick 0
fill ~36~37~27 ~38~37~27 minecraft:planks 5
setblock ~37~21~27 minecraft:crafting_table
setblock ~37~22~27 minecraft:chest 3
fill ~37~26~27 ~37~28~27 minecraft:stained_glass_pane 5
fill ~38~21~27 ~38~34~27 minecraft:nether_brick
setblock ~38~35~27 minecraft:cobblestone
fill ~38~36~27 ~39~36~27 minecraft:planks 5
setblock ~38~38~27 minecraft:end_rod 1
fill ~39~21~27 ~39~23~27 minecraft:iron_bars
fill ~39~32~27 ~39~34~27 minecraft:iron_bars
fill ~39~35~27 ~40~35~27 minecraft:planks 5
fill ~43~9~27 ~45~9~27 minecraft:quartz_stairs 6
setblock ~43~10~27 minecraft:quartz_stairs 3
fill ~44~10~27 ~44~10~28 minecraft:stonebrick 0
setblock ~45~10~27 minecraft:quartz_stairs 3
fill ~49~1~27 ~50~1~29 minecraft:glowstone
fill ~51~1~27 ~63~1~27 minecraft:stonebrick 0
fill ~54~8~27 ~56~8~27 minecraft:quartz_stairs 7
setblock ~54~9~27 minecraft:quartz_stairs 2
fill ~55~2~27 ~56~2~27 minecraft:stone_brick_stairs 3
fill ~55~9~27 ~55~13~27 minecraft:stonebrick 0
setblock ~56~9~27 minecraft:quartz_stairs 2
setblock ~59~34~27 minecraft:end_rod 0
fill ~59~35~27 ~60~35~27 minecraft:planks 5
fill ~60~21~27 ~60~23~27 minecraft:iron_bars
fill ~60~32~27 ~60~34~27 minecraft:iron_bars
fill ~60~36~27 ~61~36~27 minecraft:planks 5
fill ~61~21~27 ~61~34~27 minecraft:nether_brick
setblock ~61~35~27 minecraft:cobblestone
fill ~61~37~27 ~63~37~27 minecraft:planks 5
setblock ~61~38~27 minecraft:end_rod 1
setblock ~62~21~27 minecraft:ender_chest 3
setblock ~62~22~27 minecraft:anvil 3
fill ~62~26~27 ~62~28~27 minecraft:stained_glass_pane 2
fill ~63~38~27 ~65~38~27 minecraft:planks 5
setblock ~64~1~27 minecraft:glowstone
fill ~65~1~27 ~65~1~37 minecraft:stonebrick 0
setblock ~65~33~27 minecraft:trapdoor 1
setblock ~66~32~27 minecraft:trapdoor 1
setblock ~66~33~27 minecraft:glowstone
setblock ~66~34~27 minecraft:end_rod 1
setblock ~66~35~27 minecraft:end_rod 0
setblock ~66~36~27 minecraft:end_rod 1
setblock ~66~37~27 minecraft:end_rod 0
fill ~66~39~27 ~66~39~28 minecraft:planks 5
fill ~67~1~27 ~67~1~37 minecraft:stonebrick 0
setblock ~67~33~27 minecraft:trapdoor 1
fill ~67~38~27 ~69~38~27 minecraft:planks 5
setblock ~68~1~27 minecraft:glowstone
fill ~69~37~27 ~71~37~27 minecraft:planks 5
setblock ~70~21~27 minecraft:ender_chest 3
setblock ~70~22~27 minecraft:anvil 3
fill ~70~26~27 ~70~28~27 minecraft:stained_glass_pane 2
fill ~71~21~27 ~71~35~27 minecraft:nether_brick
fill ~71~36~27 ~72~36~27 minecraft:planks 5
setblock ~71~38~27 minecraft:end_rod 1
fill ~72~21~27 ~72~23~27 minecraft:iron_bars
fill ~72~32~27 ~72~34~27 minecraft:iron_bars
fill ~72~35~27 ~73~35~27 minecraft:planks 5
setblock ~73~34~27 minecraft:end_rod 0
fill ~80~14~27 ~80~14~43 minecraft:stonebrick 0
setblock ~80~20~27 minecraft:end_rod 0
setblock ~80~21~27 minecraft:planks 5
fill ~82~14~27 ~82~14~28 minecraft:quartz_stairs 1
fill ~83~2~27 ~83~2~28 minecraft:stonebrick 3
fill ~83~3~27 ~83~3~28 minecraft:stonebrick 0
fill ~83~4~27 ~83~4~28 minecraft:stonebrick 3
fill ~83~5~27 ~83~5~28 minecraft:stonebrick 0
fill ~83~6~27 ~83~6~28 minecraft:stonebrick 3
fill ~83~7~27 ~83~7~28 minecraft:stonebrick 0
fill ~83~8~27 ~83~8~28 minecraft:stonebrick 3
fill ~83~9~27 ~83~9~28 minecraft:stonebrick 0
fill ~83~10~27 ~83~10~28 minecraft:stonebrick 3
fill ~83~11~27 ~83~11~28 minecraft:stonebrick 0
fill ~83~12~27 ~83~12~28 minecraft:stonebrick 3
fill ~83~13~27 ~83~13~28 minecraft:nether_brick_stairs 1
fill ~84~1~27 ~84~1~77 minecraft:stonebrick 0
fill ~96~1~27 ~96~1~28 minecraft:stone_brick_stairs 5
setblock ~96~2~27 minecraft:cobblestone_wall 1
setblock ~3~1~28 minecraft:stone_brick_stairs 7
setblock ~3~2~28 minecraft:cobblestone_wall 1
fill ~4~1~28 ~4~1~29 minecraft:stone_brick_stairs 4
setblock ~4~2~28 minecraft:cobblestone_wall 1
fill ~7~1~28 ~7~1~69 minecraft:stonebrick 0
setblock ~8~0~28 minecraft:glowstone
setblock ~8~1~28 minecraft:stained_glass 7
setblock ~17~3~28 minecraft:piston 1
setblock ~17~4~28 minecraft:end_rod 1
setblock ~17~7~28 minecraft:quartz_stairs 4
setblock ~17~9~28 minecraft:wall_banner 4
setblock ~17~10~28 minecraft:quartz_stairs 0
setblock ~17~12~28 minecraft:end_rod 0
setblock ~17~13~28 minecraft:piston 0
setblock ~17~14~28 minecraft:cobblestone_wall 0
fill ~18~2~28 ~18~14~28 minecraft:nether_brick
setblock ~18~15~28 minecraft:end_rod 1
fill ~19~2~28 ~20~14~28 minecraft:stonebrick 0
fill ~21~9~28 ~21~10~30 minecraft:stonebrick 0
fill ~21~14~28 ~21~14~30 minecraft:stonebrick 0
fill ~22~9~28 ~23~9~28 minecraft:fence 5
setblock ~22~10~28 minecraft:fence 5
setblock ~23~8~28 minecraft:end_rod 0
fill ~26~35~28 ~26~35~29 minecraft:planks 5
fill ~27~21~28 ~27~23~28 minecraft:cobblestone
fill ~27~24~28 ~27~31~28 minecraft:stonebrick 0
fill ~27~32~28 ~27~34~28 minecraft:cobblestone
fill ~27~35~28 ~27~35~29 minecraft:stonebrick 0
fill ~27~36~28 ~27~36~29 minecraft:planks 5
setblock ~28~21~28 minecraft:ender_chest 5
setblock ~28~22~28 minecraft:anvil 3
fill ~28~26~28 ~28~28~28 minecraft:stained_glass_pane 2
fill ~28~37~28 ~28~37~29 minecraft:planks 5
fill ~29~38~28 ~30~38~28 minecraft:planks 5
setblock ~30~1~28 minecraft:glowstone
fill ~31~1~28 ~31~1~36 minecraft:stonebrick 0
fill ~31~39~28 ~32~39~28 minecraft:planks 5
fill ~32~20~28 ~32~20~29 minecraft:prismarine 2
fill ~32~40~28 ~34~40~28 minecraft:planks 5
fill ~33~20~28 ~33~20~29 minecraft:nether_brick
fill ~33~41~28 ~33~41~29 minecraft:planks 5
fill ~34~20~28 ~34~20~29 minecraft:prismarine 2
fill ~34~39~28 ~35~39~28 minecraft:planks 5
fill ~35~1~28 ~35~1~36 minecraft:stonebrick 0
setblock ~36~1~28 minecraft:glowstone
fill ~36~38~28 ~37~38~28 minecraft:planks 5
fill ~37~1~28 ~47~1~28 minecraft:stonebrick 0
setblock ~38~21~28 minecraft:ender_chest 4
setblock ~38~22~28 minecraft:anvil 0
fill ~38~26~28 ~38~28~28 minecraft:stained_glass_pane 2
fill ~38~37~28 ~38~37~29 minecraft:planks 5
fill ~39~21~28 ~39~23~28 minecraft:cobblestone
fill ~39~24~28 ~39~31~28 minecraft:stonebrick 0
fill ~39~32~28 ~39~35~28 minecraft:cobblestone
fill ~39~36~28 ~39~36~29 minecraft:planks 5
