fill ~-5 ~0 ~20 ~29 ~0 ~20 obsidian 0  
fill ~-5 ~0 ~21 ~29 ~0 ~21 obsidian 0  
fill ~-5 ~0 ~22 ~29 ~0 ~22 obsidian 0  
fill ~-5 ~0 ~23 ~29 ~0 ~23 obsidian 0  
fill ~-5 ~0 ~24 ~29 ~0 ~24 obsidian 0  
fill ~-5 ~0 ~25 ~19 ~0 ~25 obsidian 0  
fill ~-5 ~0 ~26 ~19 ~0 ~26 obsidian 0  
fill ~-5 ~0 ~27 ~19 ~0 ~27 obsidian 0  
fill ~-5 ~0 ~28 ~19 ~0 ~28 obsidian 0  
fill ~-5 ~0 ~29 ~19 ~0 ~29 obsidian 0  
fill ~-5 ~0 ~30 ~29 ~0 ~30 obsidian 0  
fill ~-5 ~0 ~31 ~29 ~0 ~31 obsidian 0  
fill ~-5 ~0 ~32 ~29 ~0 ~32 obsidian 0  
fill ~-5 ~0 ~33 ~29 ~0 ~33 obsidian 0  
fill ~-5 ~0 ~34 ~29 ~0 ~34 obsidian 0  
fill ~0 ~0 ~15 ~54 ~0 ~15 obsidian 0  
fill ~0 ~0 ~16 ~54 ~0 ~16 obsidian 0  
fill ~0 ~0 ~17 ~54 ~0 ~17 obsidian 0  
fill ~0 ~0 ~18 ~54 ~0 ~18 obsidian 0  
fill ~0 ~0 ~19 ~54 ~0 ~19 obsidian 0  
fill ~0 ~0 ~35 ~54 ~0 ~35 obsidian 0  
fill ~0 ~0 ~36 ~54 ~0 ~36 obsidian 0  
fill ~0 ~0 ~37 ~54 ~0 ~37 obsidian 0  
fill ~0 ~0 ~38 ~54 ~0 ~38 obsidian 0  
fill ~0 ~0 ~39 ~54 ~0 ~39 obsidian 0  
fill ~5 ~0 ~10 ~49 ~0 ~10 obsidian 0  
fill ~5 ~0 ~11 ~49 ~0 ~11 obsidian 0  
fill ~5 ~0 ~12 ~49 ~0 ~12 obsidian 0  
fill ~5 ~0 ~13 ~49 ~0 ~13 obsidian 0  
fill ~5 ~0 ~14 ~49 ~0 ~14 obsidian 0  
fill ~5 ~0 ~40 ~49 ~0 ~40 obsidian 0  
fill ~5 ~0 ~41 ~49 ~0 ~41 obsidian 0  
fill ~5 ~0 ~42 ~49 ~0 ~42 obsidian 0  
fill ~5 ~0 ~43 ~49 ~0 ~43 obsidian 0  
fill ~5 ~0 ~44 ~49 ~0 ~44 obsidian 0  
fill ~10 ~0 ~5 ~44 ~0 ~5 obsidian 0  
fill ~10 ~0 ~6 ~44 ~0 ~6 obsidian 0  
fill ~10 ~0 ~7 ~44 ~0 ~7 obsidian 0  
fill ~10 ~0 ~8 ~44 ~0 ~8 obsidian 0  
fill ~10 ~0 ~9 ~44 ~0 ~9 obsidian 0  
fill ~10 ~0 ~45 ~44 ~0 ~45 obsidian 0  
fill ~10 ~0 ~46 ~44 ~0 ~46 obsidian 0  
fill ~10 ~0 ~47 ~44 ~0 ~47 obsidian 0  
fill ~10 ~0 ~48 ~44 ~0 ~48 obsidian 0  
fill ~10 ~0 ~49 ~44 ~0 ~49 obsidian 0  
fill ~15 ~0 ~0 ~39 ~0 ~0 obsidian 0  
fill ~15 ~0 ~1 ~39 ~0 ~1 obsidian 0  
fill ~15 ~0 ~2 ~39 ~0 ~2 obsidian 0  
fill ~15 ~0 ~3 ~39 ~0 ~3 obsidian 0  
fill ~15 ~0 ~4 ~39 ~0 ~4 obsidian 0  
fill ~15 ~0 ~50 ~39 ~0 ~50 obsidian 0  
fill ~15 ~0 ~51 ~39 ~0 ~51 obsidian 0  
fill ~15 ~0 ~52 ~39 ~0 ~52 obsidian 0  
fill ~15 ~0 ~53 ~39 ~0 ~53 obsidian 0  
fill ~15 ~0 ~54 ~39 ~0 ~54 obsidian 0  
fill ~20 ~0 ~-5 ~34 ~0 ~-5 obsidian 0  
fill ~20 ~0 ~-4 ~34 ~0 ~-4 obsidian 0  
fill ~20 ~0 ~-3 ~34 ~0 ~-3 obsidian 0  
fill ~20 ~0 ~-2 ~34 ~0 ~-2 obsidian 0  
fill ~20 ~0 ~-1 ~34 ~0 ~-1 obsidian 0  
fill ~20 ~0 ~25 ~29 ~0 ~25 glowstone 0  
fill ~20 ~0 ~26 ~29 ~0 ~26 glowstone 0  
fill ~20 ~0 ~27 ~29 ~0 ~27 glowstone 0  
fill ~20 ~0 ~28 ~29 ~0 ~28 glowstone 0  
fill ~20 ~0 ~29 ~29 ~0 ~29 glowstone 0  
fill ~20 ~0 ~55 ~34 ~0 ~55 obsidian 0  
fill ~20 ~0 ~56 ~34 ~0 ~56 obsidian 0  
fill ~20 ~0 ~57 ~34 ~0 ~57 obsidian 0  
fill ~20 ~0 ~58 ~34 ~0 ~58 obsidian 0  
fill ~20 ~0 ~59 ~34 ~0 ~59 obsidian 0  
fill ~30 ~0 ~20 ~34 ~0 ~20 glowstone 0  
fill ~30 ~0 ~21 ~34 ~0 ~21 glowstone 0  
fill ~30 ~0 ~22 ~34 ~0 ~22 glowstone 0  
fill ~30 ~0 ~23 ~34 ~0 ~23 glowstone 0  
fill ~30 ~0 ~24 ~34 ~0 ~24 glowstone 0  
fill ~30 ~0 ~25 ~59 ~0 ~25 obsidian 0  
fill ~30 ~0 ~26 ~59 ~0 ~26 obsidian 0  
fill ~30 ~0 ~27 ~59 ~0 ~27 obsidian 0  
fill ~30 ~0 ~28 ~59 ~0 ~28 obsidian 0  
fill ~30 ~0 ~29 ~59 ~0 ~29 obsidian 0  
fill ~30 ~0 ~30 ~34 ~0 ~30 glowstone 0  
fill ~30 ~0 ~31 ~34 ~0 ~31 glowstone 0  
fill ~30 ~0 ~32 ~34 ~0 ~32 glowstone 0  
fill ~30 ~0 ~33 ~34 ~0 ~33 glowstone 0  
fill ~30 ~0 ~34 ~34 ~0 ~34 glowstone 0  
fill ~35 ~0 ~20 ~59 ~0 ~20 obsidian 0  
fill ~35 ~0 ~21 ~59 ~0 ~21 obsidian 0  
fill ~35 ~0 ~22 ~59 ~0 ~22 obsidian 0  
fill ~35 ~0 ~23 ~59 ~0 ~23 obsidian 0  
fill ~35 ~0 ~24 ~59 ~0 ~24 obsidian 0  
fill ~35 ~0 ~30 ~59 ~0 ~30 obsidian 0  
fill ~35 ~0 ~31 ~59 ~0 ~31 obsidian 0  
fill ~35 ~0 ~32 ~59 ~0 ~32 obsidian 0  
fill ~35 ~0 ~33 ~59 ~0 ~33 obsidian 0  
fill ~35 ~0 ~34 ~59 ~0 ~34 obsidian 0  
fill ~-5 ~1 ~20 ~29 ~1 ~20 obsidian 0  
fill ~-5 ~1 ~21 ~29 ~1 ~21 obsidian 0  
fill ~-5 ~1 ~22 ~29 ~1 ~22 obsidian 0  
fill ~-5 ~1 ~23 ~29 ~1 ~23 obsidian 0  
fill ~-5 ~1 ~24 ~29 ~1 ~24 obsidian 0  
fill ~-5 ~1 ~25 ~19 ~1 ~25 obsidian 0  
fill ~-5 ~1 ~26 ~19 ~1 ~26 obsidian 0  
fill ~-5 ~1 ~27 ~19 ~1 ~27 obsidian 0  
fill ~-5 ~1 ~28 ~19 ~1 ~28 obsidian 0  
fill ~-5 ~1 ~29 ~19 ~1 ~29 obsidian 0  
fill ~-5 ~1 ~30 ~29 ~1 ~30 obsidian 0  
fill ~-5 ~1 ~31 ~29 ~1 ~31 obsidian 0  
fill ~-5 ~1 ~32 ~29 ~1 ~32 obsidian 0  
fill ~-5 ~1 ~33 ~29 ~1 ~33 obsidian 0  
fill ~-5 ~1 ~34 ~29 ~1 ~34 obsidian 0  
fill ~0 ~1 ~15 ~54 ~1 ~15 obsidian 0  
fill ~0 ~1 ~16 ~54 ~1 ~16 obsidian 0  
fill ~0 ~1 ~17 ~54 ~1 ~17 obsidian 0  
fill ~0 ~1 ~18 ~54 ~1 ~18 obsidian 0  
fill ~0 ~1 ~19 ~54 ~1 ~19 obsidian 0  
fill ~0 ~1 ~35 ~54 ~1 ~35 obsidian 0  
fill ~0 ~1 ~36 ~54 ~1 ~36 obsidian 0  
fill ~0 ~1 ~37 ~54 ~1 ~37 obsidian 0  
fill ~0 ~1 ~38 ~54 ~1 ~38 obsidian 0  
fill ~0 ~1 ~39 ~54 ~1 ~39 obsidian 0  
fill ~5 ~1 ~10 ~49 ~1 ~10 obsidian 0  
fill ~5 ~1 ~11 ~49 ~1 ~11 obsidian 0  
fill ~5 ~1 ~12 ~49 ~1 ~12 obsidian 0  
fill ~5 ~1 ~13 ~49 ~1 ~13 obsidian 0  
fill ~5 ~1 ~14 ~49 ~1 ~14 obsidian 0  
fill ~5 ~1 ~40 ~49 ~1 ~40 obsidian 0  
fill ~5 ~1 ~41 ~49 ~1 ~41 obsidian 0  
fill ~5 ~1 ~42 ~49 ~1 ~42 obsidian 0  
fill ~5 ~1 ~43 ~49 ~1 ~43 obsidian 0  
fill ~5 ~1 ~44 ~49 ~1 ~44 obsidian 0  
fill ~10 ~1 ~5 ~44 ~1 ~5 obsidian 0  
fill ~10 ~1 ~6 ~44 ~1 ~6 obsidian 0  
fill ~10 ~1 ~7 ~44 ~1 ~7 obsidian 0  
fill ~10 ~1 ~8 ~44 ~1 ~8 obsidian 0  
fill ~10 ~1 ~9 ~44 ~1 ~9 obsidian 0  
fill ~10 ~1 ~45 ~44 ~1 ~45 obsidian 0  
fill ~10 ~1 ~46 ~44 ~1 ~46 obsidian 0  
fill ~10 ~1 ~47 ~44 ~1 ~47 obsidian 0  
fill ~10 ~1 ~48 ~44 ~1 ~48 obsidian 0  
fill ~10 ~1 ~49 ~44 ~1 ~49 obsidian 0  
fill ~15 ~1 ~0 ~39 ~1 ~0 obsidian 0  
fill ~15 ~1 ~1 ~39 ~1 ~1 obsidian 0  
fill ~15 ~1 ~2 ~39 ~1 ~2 obsidian 0  
fill ~15 ~1 ~3 ~39 ~1 ~3 obsidian 0  
fill ~15 ~1 ~4 ~39 ~1 ~4 obsidian 0  
fill ~15 ~1 ~50 ~39 ~1 ~50 obsidian 0  
fill ~15 ~1 ~51 ~39 ~1 ~51 obsidian 0  
fill ~15 ~1 ~52 ~39 ~1 ~52 obsidian 0  
fill ~15 ~1 ~53 ~39 ~1 ~53 obsidian 0  
fill ~15 ~1 ~54 ~39 ~1 ~54 obsidian 0  
fill ~20 ~1 ~-5 ~34 ~1 ~-5 obsidian 0  
fill ~20 ~1 ~-4 ~34 ~1 ~-4 obsidian 0  
fill ~20 ~1 ~-3 ~34 ~1 ~-3 obsidian 0  
fill ~20 ~1 ~-2 ~34 ~1 ~-2 obsidian 0  
fill ~20 ~1 ~-1 ~34 ~1 ~-1 obsidian 0  
fill ~20 ~1 ~25 ~29 ~1 ~25 glowstone 0  
fill ~20 ~1 ~26 ~29 ~1 ~26 glowstone 0  
fill ~20 ~1 ~27 ~29 ~1 ~27 glowstone 0  
fill ~20 ~1 ~28 ~29 ~1 ~28 glowstone 0  
fill ~20 ~1 ~29 ~29 ~1 ~29 glowstone 0  
fill ~20 ~1 ~55 ~34 ~1 ~55 obsidian 0  
fill ~20 ~1 ~56 ~34 ~1 ~56 obsidian 0  
fill ~20 ~1 ~57 ~34 ~1 ~57 obsidian 0  
fill ~20 ~1 ~58 ~34 ~1 ~58 obsidian 0  
fill ~20 ~1 ~59 ~34 ~1 ~59 obsidian 0  
fill ~30 ~1 ~20 ~34 ~1 ~20 glowstone 0  
fill ~30 ~1 ~21 ~34 ~1 ~21 glowstone 0  
fill ~30 ~1 ~22 ~34 ~1 ~22 glowstone 0  
fill ~30 ~1 ~23 ~34 ~1 ~23 glowstone 0  
fill ~30 ~1 ~24 ~34 ~1 ~24 glowstone 0  
fill ~30 ~1 ~25 ~59 ~1 ~25 obsidian 0  
fill ~30 ~1 ~26 ~59 ~1 ~26 obsidian 0  
fill ~30 ~1 ~27 ~59 ~1 ~27 obsidian 0  
fill ~30 ~1 ~28 ~59 ~1 ~28 obsidian 0  
fill ~30 ~1 ~29 ~59 ~1 ~29 obsidian 0  
fill ~30 ~1 ~30 ~34 ~1 ~30 glowstone 0  
fill ~30 ~1 ~31 ~34 ~1 ~31 glowstone 0  
fill ~30 ~1 ~32 ~34 ~1 ~32 glowstone 0  
fill ~30 ~1 ~33 ~34 ~1 ~33 glowstone 0  
fill ~30 ~1 ~34 ~34 ~1 ~34 glowstone 0  
fill ~35 ~1 ~20 ~59 ~1 ~20 obsidian 0  
fill ~35 ~1 ~21 ~59 ~1 ~21 obsidian 0  
fill ~35 ~1 ~22 ~59 ~1 ~22 obsidian 0  
fill ~35 ~1 ~23 ~59 ~1 ~23 obsidian 0  
fill ~35 ~1 ~24 ~59 ~1 ~24 obsidian 0  
fill ~35 ~1 ~30 ~59 ~1 ~30 obsidian 0  
fill ~35 ~1 ~31 ~59 ~1 ~31 obsidian 0  
fill ~35 ~1 ~32 ~59 ~1 ~32 obsidian 0  
fill ~35 ~1 ~33 ~59 ~1 ~33 obsidian 0  
fill ~35 ~1 ~34 ~59 ~1 ~34 obsidian 0  
fill ~-5 ~2 ~20 ~29 ~2 ~20 obsidian 0  
fill ~-5 ~2 ~21 ~29 ~2 ~21 obsidian 0  
fill ~-5 ~2 ~22 ~29 ~2 ~22 obsidian 0  
fill ~-5 ~2 ~23 ~29 ~2 ~23 obsidian 0  
fill ~-5 ~2 ~24 ~29 ~2 ~24 obsidian 0  
fill ~-5 ~2 ~25 ~19 ~2 ~25 obsidian 0  
fill ~-5 ~2 ~26 ~19 ~2 ~26 obsidian 0  
fill ~-5 ~2 ~27 ~19 ~2 ~27 obsidian 0  
fill ~-5 ~2 ~28 ~19 ~2 ~28 obsidian 0  
fill ~-5 ~2 ~29 ~19 ~2 ~29 obsidian 0  
fill ~-5 ~2 ~30 ~29 ~2 ~30 obsidian 0  
fill ~-5 ~2 ~31 ~29 ~2 ~31 obsidian 0  
fill ~-5 ~2 ~32 ~29 ~2 ~32 obsidian 0  
fill ~-5 ~2 ~33 ~29 ~2 ~33 obsidian 0  
fill ~-5 ~2 ~34 ~29 ~2 ~34 obsidian 0  
fill ~0 ~2 ~15 ~54 ~2 ~15 obsidian 0  
fill ~0 ~2 ~16 ~54 ~2 ~16 obsidian 0  
fill ~0 ~2 ~17 ~54 ~2 ~17 obsidian 0  
fill ~0 ~2 ~18 ~54 ~2 ~18 obsidian 0  
fill ~0 ~2 ~19 ~54 ~2 ~19 obsidian 0  
fill ~0 ~2 ~35 ~54 ~2 ~35 obsidian 0  
fill ~0 ~2 ~36 ~54 ~2 ~36 obsidian 0  
fill ~0 ~2 ~37 ~54 ~2 ~37 obsidian 0  
fill ~0 ~2 ~38 ~54 ~2 ~38 obsidian 0  
fill ~0 ~2 ~39 ~54 ~2 ~39 obsidian 0  
fill ~5 ~2 ~10 ~49 ~2 ~10 obsidian 0  
fill ~5 ~2 ~11 ~49 ~2 ~11 obsidian 0  
fill ~5 ~2 ~12 ~49 ~2 ~12 obsidian 0  
fill ~5 ~2 ~13 ~49 ~2 ~13 obsidian 0  
fill ~5 ~2 ~14 ~49 ~2 ~14 obsidian 0  
fill ~5 ~2 ~40 ~49 ~2 ~40 obsidian 0  
fill ~5 ~2 ~41 ~49 ~2 ~41 obsidian 0  
fill ~5 ~2 ~42 ~49 ~2 ~42 obsidian 0  
fill ~5 ~2 ~43 ~49 ~2 ~43 obsidian 0  
fill ~5 ~2 ~44 ~49 ~2 ~44 obsidian 0  
fill ~10 ~2 ~5 ~44 ~2 ~5 obsidian 0  
fill ~10 ~2 ~6 ~44 ~2 ~6 obsidian 0  
fill ~10 ~2 ~7 ~44 ~2 ~7 obsidian 0  
fill ~10 ~2 ~8 ~44 ~2 ~8 obsidian 0  
fill ~10 ~2 ~9 ~44 ~2 ~9 obsidian 0  
fill ~10 ~2 ~45 ~44 ~2 ~45 obsidian 0  
fill ~10 ~2 ~46 ~44 ~2 ~46 obsidian 0  
fill ~10 ~2 ~47 ~44 ~2 ~47 obsidian 0  
fill ~10 ~2 ~48 ~44 ~2 ~48 obsidian 0  
fill ~10 ~2 ~49 ~44 ~2 ~49 obsidian 0  
fill ~15 ~2 ~0 ~39 ~2 ~0 obsidian 0  
fill ~15 ~2 ~1 ~39 ~2 ~1 obsidian 0  
fill ~15 ~2 ~2 ~39 ~2 ~2 obsidian 0  
fill ~15 ~2 ~3 ~39 ~2 ~3 obsidian 0  
fill ~15 ~2 ~4 ~39 ~2 ~4 obsidian 0  
fill ~15 ~2 ~50 ~39 ~2 ~50 obsidian 0  
fill ~15 ~2 ~51 ~39 ~2 ~51 obsidian 0  
fill ~15 ~2 ~52 ~39 ~2 ~52 obsidian 0  
fill ~15 ~2 ~53 ~39 ~2 ~53 obsidian 0  
fill ~15 ~2 ~54 ~39 ~2 ~54 obsidian 0  
fill ~20 ~2 ~-5 ~34 ~2 ~-5 obsidian 0  
fill ~20 ~2 ~-4 ~34 ~2 ~-4 obsidian 0  
fill ~20 ~2 ~-3 ~34 ~2 ~-3 obsidian 0  
fill ~20 ~2 ~-2 ~34 ~2 ~-2 obsidian 0  
fill ~20 ~2 ~-1 ~34 ~2 ~-1 obsidian 0  
fill ~20 ~2 ~25 ~29 ~2 ~25 glowstone 0  
fill ~20 ~2 ~26 ~29 ~2 ~26 glowstone 0  
fill ~20 ~2 ~27 ~29 ~2 ~27 glowstone 0  
fill ~20 ~2 ~28 ~29 ~2 ~28 glowstone 0  
fill ~20 ~2 ~29 ~29 ~2 ~29 glowstone 0  
fill ~20 ~2 ~55 ~34 ~2 ~55 obsidian 0  
fill ~20 ~2 ~56 ~34 ~2 ~56 obsidian 0  
fill ~20 ~2 ~57 ~34 ~2 ~57 obsidian 0  
fill ~20 ~2 ~58 ~34 ~2 ~58 obsidian 0  
fill ~20 ~2 ~59 ~34 ~2 ~59 obsidian 0  
fill ~30 ~2 ~20 ~34 ~2 ~20 glowstone 0  
fill ~30 ~2 ~21 ~34 ~2 ~21 glowstone 0  
fill ~30 ~2 ~22 ~34 ~2 ~22 glowstone 0  
fill ~30 ~2 ~23 ~34 ~2 ~23 glowstone 0  
fill ~30 ~2 ~24 ~34 ~2 ~24 glowstone 0  
fill ~30 ~2 ~25 ~59 ~2 ~25 obsidian 0  
fill ~30 ~2 ~26 ~59 ~2 ~26 obsidian 0  
fill ~30 ~2 ~27 ~59 ~2 ~27 obsidian 0  
fill ~30 ~2 ~28 ~59 ~2 ~28 obsidian 0  
fill ~30 ~2 ~29 ~59 ~2 ~29 obsidian 0  
fill ~30 ~2 ~30 ~34 ~2 ~30 glowstone 0  
fill ~30 ~2 ~31 ~34 ~2 ~31 glowstone 0  
fill ~30 ~2 ~32 ~34 ~2 ~32 glowstone 0  
fill ~30 ~2 ~33 ~34 ~2 ~33 glowstone 0  
fill ~30 ~2 ~34 ~34 ~2 ~34 glowstone 0  
fill ~35 ~2 ~20 ~59 ~2 ~20 obsidian 0  
fill ~35 ~2 ~21 ~59 ~2 ~21 obsidian 0  
fill ~35 ~2 ~22 ~59 ~2 ~22 obsidian 0  
fill ~35 ~2 ~23 ~59 ~2 ~23 obsidian 0  
fill ~35 ~2 ~24 ~59 ~2 ~24 obsidian 0  
fill ~35 ~2 ~30 ~59 ~2 ~30 obsidian 0  
fill ~35 ~2 ~31 ~59 ~2 ~31 obsidian 0  
fill ~35 ~2 ~32 ~59 ~2 ~32 obsidian 0  
fill ~35 ~2 ~33 ~59 ~2 ~33 obsidian 0  
fill ~35 ~2 ~34 ~59 ~2 ~34 obsidian 0  
fill ~-5 ~3 ~20 ~29 ~3 ~20 obsidian 0  
fill ~-5 ~3 ~21 ~29 ~3 ~21 obsidian 0  
fill ~-5 ~3 ~22 ~29 ~3 ~22 obsidian 0  
fill ~-5 ~3 ~23 ~29 ~3 ~23 obsidian 0  
fill ~-5 ~3 ~24 ~29 ~3 ~24 obsidian 0  
fill ~-5 ~3 ~25 ~19 ~3 ~25 obsidian 0  
fill ~-5 ~3 ~26 ~19 ~3 ~26 obsidian 0  
fill ~-5 ~3 ~27 ~19 ~3 ~27 obsidian 0  
fill ~-5 ~3 ~28 ~19 ~3 ~28 obsidian 0  
fill ~-5 ~3 ~29 ~19 ~3 ~29 obsidian 0  
fill ~-5 ~3 ~30 ~29 ~3 ~30 obsidian 0  
fill ~-5 ~3 ~31 ~29 ~3 ~31 obsidian 0  
fill ~-5 ~3 ~32 ~29 ~3 ~32 obsidian 0  
fill ~-5 ~3 ~33 ~29 ~3 ~33 obsidian 0  
fill ~-5 ~3 ~34 ~29 ~3 ~34 obsidian 0  
fill ~0 ~3 ~15 ~54 ~3 ~15 obsidian 0  
fill ~0 ~3 ~16 ~54 ~3 ~16 obsidian 0  
fill ~0 ~3 ~17 ~54 ~3 ~17 obsidian 0  
fill ~0 ~3 ~18 ~54 ~3 ~18 obsidian 0  
fill ~0 ~3 ~19 ~54 ~3 ~19 obsidian 0  
fill ~0 ~3 ~35 ~54 ~3 ~35 obsidian 0  
fill ~0 ~3 ~36 ~54 ~3 ~36 obsidian 0  
fill ~0 ~3 ~37 ~54 ~3 ~37 obsidian 0  
fill ~0 ~3 ~38 ~54 ~3 ~38 obsidian 0  
fill ~0 ~3 ~39 ~54 ~3 ~39 obsidian 0  
fill ~5 ~3 ~10 ~49 ~3 ~10 obsidian 0  
fill ~5 ~3 ~11 ~49 ~3 ~11 obsidian 0  
fill ~5 ~3 ~12 ~49 ~3 ~12 obsidian 0  
fill ~5 ~3 ~13 ~49 ~3 ~13 obsidian 0  
fill ~5 ~3 ~14 ~49 ~3 ~14 obsidian 0  
fill ~5 ~3 ~40 ~49 ~3 ~40 obsidian 0  
fill ~5 ~3 ~41 ~49 ~3 ~41 obsidian 0  
fill ~5 ~3 ~42 ~49 ~3 ~42 obsidian 0  
fill ~5 ~3 ~43 ~49 ~3 ~43 obsidian 0  
fill ~5 ~3 ~44 ~49 ~3 ~44 obsidian 0  
fill ~10 ~3 ~5 ~44 ~3 ~5 obsidian 0  
fill ~10 ~3 ~6 ~44 ~3 ~6 obsidian 0  
fill ~10 ~3 ~7 ~44 ~3 ~7 obsidian 0  
fill ~10 ~3 ~8 ~44 ~3 ~8 obsidian 0  
fill ~10 ~3 ~9 ~44 ~3 ~9 obsidian 0  
fill ~10 ~3 ~45 ~44 ~3 ~45 obsidian 0  
fill ~10 ~3 ~46 ~44 ~3 ~46 obsidian 0  
fill ~10 ~3 ~47 ~44 ~3 ~47 obsidian 0  
fill ~10 ~3 ~48 ~44 ~3 ~48 obsidian 0  
fill ~10 ~3 ~49 ~44 ~3 ~49 obsidian 0  
fill ~15 ~3 ~0 ~39 ~3 ~0 obsidian 0  
fill ~15 ~3 ~1 ~39 ~3 ~1 obsidian 0  
fill ~15 ~3 ~2 ~39 ~3 ~2 obsidian 0  
fill ~15 ~3 ~3 ~39 ~3 ~3 obsidian 0  
fill ~15 ~3 ~4 ~39 ~3 ~4 obsidian 0  
fill ~15 ~3 ~50 ~39 ~3 ~50 obsidian 0  
fill ~15 ~3 ~51 ~39 ~3 ~51 obsidian 0  
fill ~15 ~3 ~52 ~39 ~3 ~52 obsidian 0  
fill ~15 ~3 ~53 ~39 ~3 ~53 obsidian 0  
fill ~15 ~3 ~54 ~39 ~3 ~54 obsidian 0  
fill ~20 ~3 ~-5 ~34 ~3 ~-5 obsidian 0  
fill ~20 ~3 ~-4 ~34 ~3 ~-4 obsidian 0  
fill ~20 ~3 ~-3 ~34 ~3 ~-3 obsidian 0  
fill ~20 ~3 ~-2 ~34 ~3 ~-2 obsidian 0  
fill ~20 ~3 ~-1 ~34 ~3 ~-1 obsidian 0  
fill ~20 ~3 ~25 ~29 ~3 ~25 glowstone 0  
fill ~20 ~3 ~26 ~29 ~3 ~26 glowstone 0  
fill ~20 ~3 ~27 ~29 ~3 ~27 glowstone 0  
fill ~20 ~3 ~28 ~29 ~3 ~28 glowstone 0  
fill ~20 ~3 ~29 ~29 ~3 ~29 glowstone 0  
fill ~20 ~3 ~55 ~34 ~3 ~55 obsidian 0  
fill ~20 ~3 ~56 ~34 ~3 ~56 obsidian 0  
fill ~20 ~3 ~57 ~34 ~3 ~57 obsidian 0  
fill ~20 ~3 ~58 ~34 ~3 ~58 obsidian 0  
fill ~20 ~3 ~59 ~34 ~3 ~59 obsidian 0  
fill ~30 ~3 ~20 ~34 ~3 ~20 glowstone 0  
fill ~30 ~3 ~21 ~34 ~3 ~21 glowstone 0  
fill ~30 ~3 ~22 ~34 ~3 ~22 glowstone 0  
fill ~30 ~3 ~23 ~34 ~3 ~23 glowstone 0  
fill ~30 ~3 ~24 ~34 ~3 ~24 glowstone 0  
fill ~30 ~3 ~25 ~59 ~3 ~25 obsidian 0  
fill ~30 ~3 ~26 ~59 ~3 ~26 obsidian 0  
fill ~30 ~3 ~27 ~59 ~3 ~27 obsidian 0  
fill ~30 ~3 ~28 ~59 ~3 ~28 obsidian 0  
fill ~30 ~3 ~29 ~59 ~3 ~29 obsidian 0  
fill ~30 ~3 ~30 ~34 ~3 ~30 glowstone 0  
fill ~30 ~3 ~31 ~34 ~3 ~31 glowstone 0  
fill ~30 ~3 ~32 ~34 ~3 ~32 glowstone 0  
fill ~30 ~3 ~33 ~34 ~3 ~33 glowstone 0  
fill ~30 ~3 ~34 ~34 ~3 ~34 glowstone 0  
fill ~35 ~3 ~20 ~59 ~3 ~20 obsidian 0  
fill ~35 ~3 ~21 ~59 ~3 ~21 obsidian 0  
fill ~35 ~3 ~22 ~59 ~3 ~22 obsidian 0  
fill ~35 ~3 ~23 ~59 ~3 ~23 obsidian 0  
fill ~35 ~3 ~24 ~59 ~3 ~24 obsidian 0  
fill ~35 ~3 ~30 ~59 ~3 ~30 obsidian 0  
fill ~35 ~3 ~31 ~59 ~3 ~31 obsidian 0  
fill ~35 ~3 ~32 ~59 ~3 ~32 obsidian 0  
fill ~35 ~3 ~33 ~59 ~3 ~33 obsidian 0  
fill ~35 ~3 ~34 ~59 ~3 ~34 obsidian 0  
fill ~-5 ~4 ~20 ~29 ~4 ~20 obsidian 0  
fill ~-5 ~4 ~21 ~29 ~4 ~21 obsidian 0  
fill ~-5 ~4 ~22 ~29 ~4 ~22 obsidian 0  
fill ~-5 ~4 ~23 ~29 ~4 ~23 obsidian 0  
fill ~-5 ~4 ~24 ~29 ~4 ~24 obsidian 0  
fill ~-5 ~4 ~25 ~19 ~4 ~25 obsidian 0  
fill ~-5 ~4 ~26 ~19 ~4 ~26 obsidian 0  
fill ~-5 ~4 ~27 ~19 ~4 ~27 obsidian 0  
fill ~-5 ~4 ~28 ~19 ~4 ~28 obsidian 0  
fill ~-5 ~4 ~29 ~19 ~4 ~29 obsidian 0  
fill ~-5 ~4 ~30 ~29 ~4 ~30 obsidian 0  
fill ~-5 ~4 ~31 ~29 ~4 ~31 obsidian 0  
fill ~-5 ~4 ~32 ~29 ~4 ~32 obsidian 0  
fill ~-5 ~4 ~33 ~29 ~4 ~33 obsidian 0  
fill ~-5 ~4 ~34 ~29 ~4 ~34 obsidian 0  
fill ~0 ~4 ~15 ~54 ~4 ~15 obsidian 0  
fill ~0 ~4 ~16 ~54 ~4 ~16 obsidian 0  
fill ~0 ~4 ~17 ~54 ~4 ~17 obsidian 0  
fill ~0 ~4 ~18 ~54 ~4 ~18 obsidian 0  
fill ~0 ~4 ~19 ~54 ~4 ~19 obsidian 0  
fill ~0 ~4 ~35 ~54 ~4 ~35 obsidian 0  
fill ~0 ~4 ~36 ~54 ~4 ~36 obsidian 0  
fill ~0 ~4 ~37 ~54 ~4 ~37 obsidian 0  
fill ~0 ~4 ~38 ~54 ~4 ~38 obsidian 0  
fill ~0 ~4 ~39 ~54 ~4 ~39 obsidian 0  
fill ~5 ~4 ~10 ~49 ~4 ~10 obsidian 0  
fill ~5 ~4 ~11 ~49 ~4 ~11 obsidian 0  
fill ~5 ~4 ~12 ~49 ~4 ~12 obsidian 0  
fill ~5 ~4 ~13 ~49 ~4 ~13 obsidian 0  
fill ~5 ~4 ~14 ~49 ~4 ~14 obsidian 0  
fill ~5 ~4 ~40 ~49 ~4 ~40 obsidian 0  
fill ~5 ~4 ~41 ~49 ~4 ~41 obsidian 0  
fill ~5 ~4 ~42 ~49 ~4 ~42 obsidian 0  
fill ~5 ~4 ~43 ~49 ~4 ~43 obsidian 0  
fill ~5 ~4 ~44 ~49 ~4 ~44 obsidian 0  
fill ~10 ~4 ~5 ~44 ~4 ~5 obsidian 0  
fill ~10 ~4 ~6 ~44 ~4 ~6 obsidian 0  
fill ~10 ~4 ~7 ~44 ~4 ~7 obsidian 0  
fill ~10 ~4 ~8 ~44 ~4 ~8 obsidian 0  
fill ~10 ~4 ~9 ~44 ~4 ~9 obsidian 0  
fill ~10 ~4 ~45 ~44 ~4 ~45 obsidian 0  
fill ~10 ~4 ~46 ~44 ~4 ~46 obsidian 0  
fill ~10 ~4 ~47 ~44 ~4 ~47 obsidian 0  
fill ~10 ~4 ~48 ~44 ~4 ~48 obsidian 0  
fill ~10 ~4 ~49 ~44 ~4 ~49 obsidian 0  
fill ~15 ~4 ~0 ~39 ~4 ~0 obsidian 0  
fill ~15 ~4 ~1 ~39 ~4 ~1 obsidian 0  
fill ~15 ~4 ~2 ~39 ~4 ~2 obsidian 0  
fill ~15 ~4 ~3 ~39 ~4 ~3 obsidian 0  
fill ~15 ~4 ~4 ~39 ~4 ~4 obsidian 0  
fill ~15 ~4 ~50 ~39 ~4 ~50 obsidian 0  
fill ~15 ~4 ~51 ~39 ~4 ~51 obsidian 0  
fill ~15 ~4 ~52 ~39 ~4 ~52 obsidian 0  
fill ~15 ~4 ~53 ~39 ~4 ~53 obsidian 0  
fill ~15 ~4 ~54 ~39 ~4 ~54 obsidian 0  
fill ~20 ~4 ~-5 ~34 ~4 ~-5 obsidian 0  
fill ~20 ~4 ~-4 ~34 ~4 ~-4 obsidian 0  
fill ~20 ~4 ~-3 ~34 ~4 ~-3 obsidian 0  
fill ~20 ~4 ~-2 ~34 ~4 ~-2 obsidian 0  
fill ~20 ~4 ~-1 ~34 ~4 ~-1 obsidian 0  
fill ~20 ~4 ~25 ~29 ~4 ~25 glowstone 0  
fill ~20 ~4 ~26 ~29 ~4 ~26 glowstone 0  
fill ~20 ~4 ~27 ~29 ~4 ~27 glowstone 0  
fill ~20 ~4 ~28 ~29 ~4 ~28 glowstone 0  
fill ~20 ~4 ~29 ~29 ~4 ~29 glowstone 0  
fill ~20 ~4 ~55 ~34 ~4 ~55 obsidian 0  
fill ~20 ~4 ~56 ~34 ~4 ~56 obsidian 0  
fill ~20 ~4 ~57 ~34 ~4 ~57 obsidian 0  
fill ~20 ~4 ~58 ~34 ~4 ~58 obsidian 0  
fill ~20 ~4 ~59 ~34 ~4 ~59 obsidian 0  
fill ~30 ~4 ~20 ~34 ~4 ~20 glowstone 0  
fill ~30 ~4 ~21 ~34 ~4 ~21 glowstone 0  
fill ~30 ~4 ~22 ~34 ~4 ~22 glowstone 0  
fill ~30 ~4 ~23 ~34 ~4 ~23 glowstone 0  
fill ~30 ~4 ~24 ~34 ~4 ~24 glowstone 0  
fill ~30 ~4 ~25 ~59 ~4 ~25 obsidian 0  
fill ~30 ~4 ~26 ~59 ~4 ~26 obsidian 0  
fill ~30 ~4 ~27 ~59 ~4 ~27 obsidian 0  
fill ~30 ~4 ~28 ~59 ~4 ~28 obsidian 0  
fill ~30 ~4 ~29 ~59 ~4 ~29 obsidian 0  
fill ~30 ~4 ~30 ~34 ~4 ~30 glowstone 0  
fill ~30 ~4 ~31 ~34 ~4 ~31 glowstone 0  
fill ~30 ~4 ~32 ~34 ~4 ~32 glowstone 0  
fill ~30 ~4 ~33 ~34 ~4 ~33 glowstone 0  
fill ~30 ~4 ~34 ~34 ~4 ~34 glowstone 0  
fill ~35 ~4 ~20 ~59 ~4 ~20 obsidian 0  
fill ~35 ~4 ~21 ~59 ~4 ~21 obsidian 0  
fill ~35 ~4 ~22 ~59 ~4 ~22 obsidian 0  
fill ~35 ~4 ~23 ~59 ~4 ~23 obsidian 0  
fill ~35 ~4 ~24 ~59 ~4 ~24 obsidian 0  
fill ~35 ~4 ~30 ~59 ~4 ~30 obsidian 0  
fill ~35 ~4 ~31 ~59 ~4 ~31 obsidian 0  
fill ~35 ~4 ~32 ~59 ~4 ~32 obsidian 0  
fill ~35 ~4 ~33 ~59 ~4 ~33 obsidian 0  
fill ~35 ~4 ~34 ~59 ~4 ~34 obsidian 0  
fill ~10 ~5 ~20 ~14 ~5 ~20 gold_block 0  
fill ~10 ~5 ~21 ~14 ~5 ~21 gold_block 0  
fill ~10 ~5 ~22 ~14 ~5 ~22 gold_block 0  
fill ~10 ~5 ~23 ~14 ~5 ~23 gold_block 0  
fill ~10 ~5 ~24 ~14 ~5 ~24 gold_block 0  
fill ~10 ~5 ~25 ~14 ~5 ~25 gold_block 0  
fill ~10 ~5 ~26 ~14 ~5 ~26 gold_block 0  
fill ~10 ~5 ~27 ~14 ~5 ~27 gold_block 0  
fill ~10 ~5 ~28 ~14 ~5 ~28 gold_block 0  
fill ~10 ~5 ~29 ~14 ~5 ~29 gold_block 0  
fill ~10 ~5 ~30 ~14 ~5 ~30 gold_block 0  
fill ~10 ~5 ~31 ~14 ~5 ~31 gold_block 0  
fill ~10 ~5 ~32 ~14 ~5 ~32 gold_block 0  
fill ~10 ~5 ~33 ~14 ~5 ~33 gold_block 0  
fill ~10 ~5 ~34 ~14 ~5 ~34 gold_block 0  
fill ~15 ~5 ~15 ~19 ~5 ~15 gold_block 0  
fill ~15 ~5 ~16 ~19 ~5 ~16 gold_block 0  
fill ~15 ~5 ~17 ~19 ~5 ~17 gold_block 0  
fill ~15 ~5 ~18 ~19 ~5 ~18 gold_block 0  
fill ~15 ~5 ~19 ~19 ~5 ~19 gold_block 0  
fill ~15 ~5 ~20 ~19 ~5 ~20 glowstone 0  
fill ~15 ~5 ~21 ~19 ~5 ~21 glowstone 0  
fill ~15 ~5 ~22 ~19 ~5 ~22 glowstone 0  
fill ~15 ~5 ~23 ~19 ~5 ~23 glowstone 0  
fill ~15 ~5 ~24 ~19 ~5 ~24 glowstone 0  
fill ~15 ~5 ~25 ~19 ~5 ~25 wool 12  
fill ~15 ~5 ~26 ~19 ~5 ~26 wool 12  
fill ~15 ~5 ~27 ~19 ~5 ~27 wool 12  
fill ~15 ~5 ~28 ~19 ~5 ~28 wool 12  
fill ~15 ~5 ~29 ~19 ~5 ~29 wool 12  
fill ~15 ~5 ~30 ~19 ~5 ~30 glowstone 0  
fill ~15 ~5 ~31 ~19 ~5 ~31 glowstone 0  
fill ~15 ~5 ~32 ~19 ~5 ~32 glowstone 0  
fill ~15 ~5 ~33 ~19 ~5 ~33 glowstone 0  
fill ~15 ~5 ~34 ~19 ~5 ~34 glowstone 0  
fill ~15 ~5 ~35 ~19 ~5 ~35 gold_block 0  
fill ~15 ~5 ~36 ~19 ~5 ~36 gold_block 0  
fill ~15 ~5 ~37 ~19 ~5 ~37 gold_block 0  
fill ~15 ~5 ~38 ~19 ~5 ~38 gold_block 0  
fill ~15 ~5 ~39 ~19 ~5 ~39 gold_block 0  
fill ~20 ~5 ~10 ~34 ~5 ~10 gold_block 0  
fill ~20 ~5 ~11 ~34 ~5 ~11 gold_block 0  
fill ~20 ~5 ~12 ~34 ~5 ~12 gold_block 0  
fill ~20 ~5 ~13 ~34 ~5 ~13 gold_block 0  
fill ~20 ~5 ~14 ~34 ~5 ~14 gold_block 0  
fill ~20 ~5 ~15 ~34 ~5 ~15 wool 12  
fill ~20 ~5 ~16 ~34 ~5 ~16 wool 12  
fill ~20 ~5 ~17 ~34 ~5 ~17 wool 12  
fill ~20 ~5 ~18 ~34 ~5 ~18 wool 12  
fill ~20 ~5 ~19 ~34 ~5 ~19 wool 12  
fill ~20 ~5 ~20 ~24 ~5 ~20 wool 12  
fill ~20 ~5 ~21 ~24 ~5 ~21 wool 12  
fill ~20 ~5 ~22 ~24 ~5 ~22 wool 12  
fill ~20 ~5 ~23 ~24 ~5 ~23 wool 12  
fill ~20 ~5 ~24 ~24 ~5 ~24 wool 12  
fill ~20 ~5 ~25 ~29 ~5 ~25 glowstone 0  
fill ~20 ~5 ~26 ~29 ~5 ~26 glowstone 0  
fill ~20 ~5 ~27 ~29 ~5 ~27 glowstone 0  
fill ~20 ~5 ~28 ~29 ~5 ~28 glowstone 0  
fill ~20 ~5 ~29 ~29 ~5 ~29 glowstone 0  
fill ~20 ~5 ~30 ~24 ~5 ~30 wool 12  
fill ~20 ~5 ~31 ~24 ~5 ~31 wool 12  
fill ~20 ~5 ~32 ~24 ~5 ~32 wool 12  
fill ~20 ~5 ~33 ~24 ~5 ~33 wool 12  
fill ~20 ~5 ~34 ~24 ~5 ~34 wool 12  
fill ~20 ~5 ~35 ~34 ~5 ~35 wool 12  
fill ~20 ~5 ~36 ~34 ~5 ~36 wool 12  
fill ~20 ~5 ~37 ~34 ~5 ~37 wool 12  
fill ~20 ~5 ~38 ~34 ~5 ~38 wool 12  
fill ~20 ~5 ~39 ~34 ~5 ~39 wool 12  
fill ~20 ~5 ~40 ~34 ~5 ~40 gold_block 0  
fill ~20 ~5 ~41 ~34 ~5 ~41 gold_block 0  
fill ~20 ~5 ~42 ~34 ~5 ~42 gold_block 0  
fill ~20 ~5 ~43 ~34 ~5 ~43 gold_block 0  
fill ~20 ~5 ~44 ~34 ~5 ~44 gold_block 0  
fill ~25 ~5 ~20 ~34 ~5 ~20 glowstone 0  
fill ~25 ~5 ~21 ~34 ~5 ~21 glowstone 0  
fill ~25 ~5 ~22 ~34 ~5 ~22 glowstone 0  
fill ~25 ~5 ~23 ~34 ~5 ~23 glowstone 0  
fill ~25 ~5 ~24 ~34 ~5 ~24 glowstone 0  
fill ~25 ~5 ~30 ~34 ~5 ~30 glowstone 0  
fill ~25 ~5 ~31 ~34 ~5 ~31 glowstone 0  
fill ~25 ~5 ~32 ~34 ~5 ~32 glowstone 0  
fill ~25 ~5 ~33 ~34 ~5 ~33 glowstone 0  
fill ~25 ~5 ~34 ~34 ~5 ~34 glowstone 0  
fill ~30 ~5 ~25 ~39 ~5 ~25 wool 12  
fill ~30 ~5 ~26 ~39 ~5 ~26 wool 12  
fill ~30 ~5 ~27 ~39 ~5 ~27 wool 12  
fill ~30 ~5 ~28 ~39 ~5 ~28 wool 12  
fill ~30 ~5 ~29 ~39 ~5 ~29 wool 12  
fill ~35 ~5 ~15 ~39 ~5 ~15 gold_block 0  
fill ~35 ~5 ~16 ~39 ~5 ~16 gold_block 0  
fill ~35 ~5 ~17 ~39 ~5 ~17 gold_block 0  
fill ~35 ~5 ~18 ~39 ~5 ~18 gold_block 0  
fill ~35 ~5 ~19 ~39 ~5 ~19 gold_block 0  
fill ~35 ~5 ~20 ~39 ~5 ~20 wool 12  
fill ~35 ~5 ~21 ~39 ~5 ~21 wool 12  
fill ~35 ~5 ~22 ~39 ~5 ~22 wool 12  
fill ~35 ~5 ~23 ~39 ~5 ~23 wool 12  
fill ~35 ~5 ~24 ~39 ~5 ~24 wool 12  
fill ~35 ~5 ~30 ~39 ~5 ~30 wool 12  
fill ~35 ~5 ~31 ~39 ~5 ~31 wool 12  
fill ~35 ~5 ~32 ~39 ~5 ~32 wool 12  
fill ~35 ~5 ~33 ~39 ~5 ~33 wool 12  
fill ~35 ~5 ~34 ~39 ~5 ~34 wool 12  
fill ~35 ~5 ~35 ~39 ~5 ~35 gold_block 0  
fill ~35 ~5 ~36 ~39 ~5 ~36 gold_block 0  
fill ~35 ~5 ~37 ~39 ~5 ~37 gold_block 0  
fill ~35 ~5 ~38 ~39 ~5 ~38 gold_block 0  
fill ~35 ~5 ~39 ~39 ~5 ~39 gold_block 0  
fill ~40 ~5 ~20 ~44 ~5 ~20 gold_block 0  
fill ~40 ~5 ~21 ~44 ~5 ~21 gold_block 0  
fill ~40 ~5 ~22 ~44 ~5 ~22 gold_block 0  
fill ~40 ~5 ~23 ~44 ~5 ~23 gold_block 0  
fill ~40 ~5 ~24 ~44 ~5 ~24 gold_block 0  
fill ~40 ~5 ~25 ~44 ~5 ~25 gold_block 0  
fill ~40 ~5 ~26 ~44 ~5 ~26 gold_block 0  
fill ~40 ~5 ~27 ~44 ~5 ~27 gold_block 0  
fill ~40 ~5 ~28 ~44 ~5 ~28 gold_block 0  
fill ~40 ~5 ~29 ~44 ~5 ~29 gold_block 0  
fill ~40 ~5 ~30 ~44 ~5 ~30 gold_block 0  
fill ~40 ~5 ~31 ~44 ~5 ~31 gold_block 0  
fill ~40 ~5 ~32 ~44 ~5 ~32 gold_block 0  
fill ~40 ~5 ~33 ~44 ~5 ~33 gold_block 0  
fill ~40 ~5 ~34 ~44 ~5 ~34 gold_block 0  
fill ~55 ~5 ~25 ~69 ~5 ~25 gold_block 0  
fill ~55 ~5 ~26 ~69 ~5 ~26 gold_block 0  
fill ~55 ~5 ~27 ~69 ~5 ~27 gold_block 0  
fill ~55 ~5 ~28 ~69 ~5 ~28 gold_block 0  
fill ~55 ~5 ~29 ~69 ~5 ~29 gold_block 0  
fill ~10 ~6 ~20 ~14 ~6 ~20 gold_block 0  
fill ~10 ~6 ~21 ~14 ~6 ~21 gold_block 0  
fill ~10 ~6 ~22 ~14 ~6 ~22 gold_block 0  
fill ~10 ~6 ~23 ~14 ~6 ~23 gold_block 0  
fill ~10 ~6 ~24 ~14 ~6 ~24 gold_block 0  
fill ~10 ~6 ~25 ~14 ~6 ~25 gold_block 0  
fill ~10 ~6 ~26 ~14 ~6 ~26 gold_block 0  
fill ~10 ~6 ~27 ~14 ~6 ~27 gold_block 0  
fill ~10 ~6 ~28 ~14 ~6 ~28 gold_block 0  
fill ~10 ~6 ~29 ~14 ~6 ~29 gold_block 0  
fill ~10 ~6 ~30 ~14 ~6 ~30 gold_block 0  
fill ~10 ~6 ~31 ~14 ~6 ~31 gold_block 0  
fill ~10 ~6 ~32 ~14 ~6 ~32 gold_block 0  
fill ~10 ~6 ~33 ~14 ~6 ~33 gold_block 0  
fill ~10 ~6 ~34 ~14 ~6 ~34 gold_block 0  
fill ~15 ~6 ~15 ~19 ~6 ~15 gold_block 0  
fill ~15 ~6 ~16 ~19 ~6 ~16 gold_block 0  
fill ~15 ~6 ~17 ~19 ~6 ~17 gold_block 0  
fill ~15 ~6 ~18 ~19 ~6 ~18 gold_block 0  
fill ~15 ~6 ~19 ~19 ~6 ~19 gold_block 0  
fill ~15 ~6 ~20 ~19 ~6 ~20 glowstone 0  
fill ~15 ~6 ~21 ~19 ~6 ~21 glowstone 0  
fill ~15 ~6 ~22 ~19 ~6 ~22 glowstone 0  
fill ~15 ~6 ~23 ~19 ~6 ~23 glowstone 0  
fill ~15 ~6 ~24 ~19 ~6 ~24 glowstone 0  
fill ~15 ~6 ~25 ~19 ~6 ~25 wool 12  
fill ~15 ~6 ~26 ~19 ~6 ~26 wool 12  
fill ~15 ~6 ~27 ~19 ~6 ~27 wool 12  
fill ~15 ~6 ~28 ~19 ~6 ~28 wool 12  
fill ~15 ~6 ~29 ~19 ~6 ~29 wool 12  
fill ~15 ~6 ~30 ~19 ~6 ~30 glowstone 0  
fill ~15 ~6 ~31 ~19 ~6 ~31 glowstone 0  
fill ~15 ~6 ~32 ~19 ~6 ~32 glowstone 0  
fill ~15 ~6 ~33 ~19 ~6 ~33 glowstone 0  
fill ~15 ~6 ~34 ~19 ~6 ~34 glowstone 0  
fill ~15 ~6 ~35 ~19 ~6 ~35 gold_block 0  
fill ~15 ~6 ~36 ~19 ~6 ~36 gold_block 0  
fill ~15 ~6 ~37 ~19 ~6 ~37 gold_block 0  
fill ~15 ~6 ~38 ~19 ~6 ~38 gold_block 0  
fill ~15 ~6 ~39 ~19 ~6 ~39 gold_block 0  
fill ~20 ~6 ~10 ~34 ~6 ~10 gold_block 0  
fill ~20 ~6 ~11 ~34 ~6 ~11 gold_block 0  
fill ~20 ~6 ~12 ~34 ~6 ~12 gold_block 0  
fill ~20 ~6 ~13 ~34 ~6 ~13 gold_block 0  
fill ~20 ~6 ~14 ~34 ~6 ~14 gold_block 0  
fill ~20 ~6 ~15 ~34 ~6 ~15 wool 12  
fill ~20 ~6 ~16 ~34 ~6 ~16 wool 12  
fill ~20 ~6 ~17 ~34 ~6 ~17 wool 12  
fill ~20 ~6 ~18 ~34 ~6 ~18 wool 12  
fill ~20 ~6 ~19 ~34 ~6 ~19 wool 12  
fill ~20 ~6 ~20 ~24 ~6 ~20 wool 12  
fill ~20 ~6 ~21 ~24 ~6 ~21 wool 12  
fill ~20 ~6 ~22 ~24 ~6 ~22 wool 12  
fill ~20 ~6 ~23 ~24 ~6 ~23 wool 12  
fill ~20 ~6 ~24 ~24 ~6 ~24 wool 12  
fill ~20 ~6 ~25 ~29 ~6 ~25 glowstone 0  
fill ~20 ~6 ~26 ~29 ~6 ~26 glowstone 0  
fill ~20 ~6 ~27 ~29 ~6 ~27 glowstone 0  
fill ~20 ~6 ~28 ~29 ~6 ~28 glowstone 0  
fill ~20 ~6 ~29 ~29 ~6 ~29 glowstone 0  
fill ~20 ~6 ~30 ~24 ~6 ~30 wool 12  
fill ~20 ~6 ~31 ~24 ~6 ~31 wool 12  
fill ~20 ~6 ~32 ~24 ~6 ~32 wool 12  
fill ~20 ~6 ~33 ~24 ~6 ~33 wool 12  
fill ~20 ~6 ~34 ~24 ~6 ~34 wool 12  
fill ~20 ~6 ~35 ~34 ~6 ~35 wool 12  
fill ~20 ~6 ~36 ~34 ~6 ~36 wool 12  
fill ~20 ~6 ~37 ~34 ~6 ~37 wool 12  
fill ~20 ~6 ~38 ~34 ~6 ~38 wool 12  
fill ~20 ~6 ~39 ~34 ~6 ~39 wool 12  
fill ~20 ~6 ~40 ~34 ~6 ~40 gold_block 0  
fill ~20 ~6 ~41 ~34 ~6 ~41 gold_block 0  
fill ~20 ~6 ~42 ~34 ~6 ~42 gold_block 0  
fill ~20 ~6 ~43 ~34 ~6 ~43 gold_block 0  
fill ~20 ~6 ~44 ~34 ~6 ~44 gold_block 0  
fill ~25 ~6 ~20 ~34 ~6 ~20 glowstone 0  
fill ~25 ~6 ~21 ~34 ~6 ~21 glowstone 0  
fill ~25 ~6 ~22 ~34 ~6 ~22 glowstone 0  
fill ~25 ~6 ~23 ~34 ~6 ~23 glowstone 0  
fill ~25 ~6 ~24 ~34 ~6 ~24 glowstone 0  
fill ~25 ~6 ~30 ~34 ~6 ~30 glowstone 0  
fill ~25 ~6 ~31 ~34 ~6 ~31 glowstone 0  
fill ~25 ~6 ~32 ~34 ~6 ~32 glowstone 0  
fill ~25 ~6 ~33 ~34 ~6 ~33 glowstone 0  
fill ~25 ~6 ~34 ~34 ~6 ~34 glowstone 0  
fill ~30 ~6 ~25 ~39 ~6 ~25 wool 12  
fill ~30 ~6 ~26 ~39 ~6 ~26 wool 12  
fill ~30 ~6 ~27 ~39 ~6 ~27 wool 12  
fill ~30 ~6 ~28 ~39 ~6 ~28 wool 12  
fill ~30 ~6 ~29 ~39 ~6 ~29 wool 12  
fill ~35 ~6 ~15 ~39 ~6 ~15 gold_block 0  
fill ~35 ~6 ~16 ~39 ~6 ~16 gold_block 0  
fill ~35 ~6 ~17 ~39 ~6 ~17 gold_block 0  
fill ~35 ~6 ~18 ~39 ~6 ~18 gold_block 0  
fill ~35 ~6 ~19 ~39 ~6 ~19 gold_block 0  
fill ~35 ~6 ~20 ~39 ~6 ~20 wool 12  
fill ~35 ~6 ~21 ~39 ~6 ~21 wool 12  
fill ~35 ~6 ~22 ~39 ~6 ~22 wool 12  
fill ~35 ~6 ~23 ~39 ~6 ~23 wool 12  
fill ~35 ~6 ~24 ~39 ~6 ~24 wool 12  
fill ~35 ~6 ~30 ~39 ~6 ~30 wool 12  
fill ~35 ~6 ~31 ~39 ~6 ~31 wool 12  
fill ~35 ~6 ~32 ~39 ~6 ~32 wool 12  
fill ~35 ~6 ~33 ~39 ~6 ~33 wool 12  
fill ~35 ~6 ~34 ~39 ~6 ~34 wool 12  
fill ~35 ~6 ~35 ~39 ~6 ~35 gold_block 0  
fill ~35 ~6 ~36 ~39 ~6 ~36 gold_block 0  
fill ~35 ~6 ~37 ~39 ~6 ~37 gold_block 0  
fill ~35 ~6 ~38 ~39 ~6 ~38 gold_block 0  
fill ~35 ~6 ~39 ~39 ~6 ~39 gold_block 0  
fill ~40 ~6 ~20 ~44 ~6 ~20 gold_block 0  
fill ~40 ~6 ~21 ~44 ~6 ~21 gold_block 0  
fill ~40 ~6 ~22 ~44 ~6 ~22 gold_block 0  
fill ~40 ~6 ~23 ~44 ~6 ~23 gold_block 0  
fill ~40 ~6 ~24 ~44 ~6 ~24 gold_block 0  
fill ~40 ~6 ~25 ~44 ~6 ~25 gold_block 0  
fill ~40 ~6 ~26 ~44 ~6 ~26 gold_block 0  
fill ~40 ~6 ~27 ~44 ~6 ~27 gold_block 0  
fill ~40 ~6 ~28 ~44 ~6 ~28 gold_block 0  
fill ~40 ~6 ~29 ~44 ~6 ~29 gold_block 0  
fill ~40 ~6 ~30 ~44 ~6 ~30 gold_block 0  
fill ~40 ~6 ~31 ~44 ~6 ~31 gold_block 0  
fill ~40 ~6 ~32 ~44 ~6 ~32 gold_block 0  
fill ~40 ~6 ~33 ~44 ~6 ~33 gold_block 0  
fill ~40 ~6 ~34 ~44 ~6 ~34 gold_block 0  
fill ~55 ~6 ~25 ~69 ~6 ~25 gold_block 0  
fill ~55 ~6 ~26 ~69 ~6 ~26 gold_block 0  
fill ~55 ~6 ~27 ~69 ~6 ~27 gold_block 0  
fill ~55 ~6 ~28 ~69 ~6 ~28 gold_block 0  
fill ~55 ~6 ~29 ~69 ~6 ~29 gold_block 0  
fill ~10 ~7 ~20 ~14 ~7 ~20 gold_block 0  
fill ~10 ~7 ~21 ~14 ~7 ~21 gold_block 0  
fill ~10 ~7 ~22 ~14 ~7 ~22 gold_block 0  
fill ~10 ~7 ~23 ~14 ~7 ~23 gold_block 0  
fill ~10 ~7 ~24 ~14 ~7 ~24 gold_block 0  
fill ~10 ~7 ~25 ~14 ~7 ~25 gold_block 0  
fill ~10 ~7 ~26 ~14 ~7 ~26 gold_block 0  
fill ~10 ~7 ~27 ~14 ~7 ~27 gold_block 0  
fill ~10 ~7 ~28 ~14 ~7 ~28 gold_block 0  
fill ~10 ~7 ~29 ~14 ~7 ~29 gold_block 0  
fill ~10 ~7 ~30 ~14 ~7 ~30 gold_block 0  
fill ~10 ~7 ~31 ~14 ~7 ~31 gold_block 0  
fill ~10 ~7 ~32 ~14 ~7 ~32 gold_block 0  
fill ~10 ~7 ~33 ~14 ~7 ~33 gold_block 0  
fill ~10 ~7 ~34 ~14 ~7 ~34 gold_block 0  
fill ~15 ~7 ~15 ~19 ~7 ~15 gold_block 0  
fill ~15 ~7 ~16 ~19 ~7 ~16 gold_block 0  
fill ~15 ~7 ~17 ~19 ~7 ~17 gold_block 0  
fill ~15 ~7 ~18 ~19 ~7 ~18 gold_block 0  
fill ~15 ~7 ~19 ~19 ~7 ~19 gold_block 0  
fill ~15 ~7 ~20 ~19 ~7 ~20 glowstone 0  
fill ~15 ~7 ~21 ~19 ~7 ~21 glowstone 0  
fill ~15 ~7 ~22 ~19 ~7 ~22 glowstone 0  
fill ~15 ~7 ~23 ~19 ~7 ~23 glowstone 0  
fill ~15 ~7 ~24 ~19 ~7 ~24 glowstone 0  
fill ~15 ~7 ~25 ~19 ~7 ~25 wool 12  
fill ~15 ~7 ~26 ~19 ~7 ~26 wool 12  
fill ~15 ~7 ~27 ~19 ~7 ~27 wool 12  
fill ~15 ~7 ~28 ~19 ~7 ~28 wool 12  
fill ~15 ~7 ~29 ~19 ~7 ~29 wool 12  
fill ~15 ~7 ~30 ~19 ~7 ~30 glowstone 0  
fill ~15 ~7 ~31 ~19 ~7 ~31 glowstone 0  
fill ~15 ~7 ~32 ~19 ~7 ~32 glowstone 0  
fill ~15 ~7 ~33 ~19 ~7 ~33 glowstone 0  
fill ~15 ~7 ~34 ~19 ~7 ~34 glowstone 0  
fill ~15 ~7 ~35 ~19 ~7 ~35 gold_block 0  
fill ~15 ~7 ~36 ~19 ~7 ~36 gold_block 0  
fill ~15 ~7 ~37 ~19 ~7 ~37 gold_block 0  
fill ~15 ~7 ~38 ~19 ~7 ~38 gold_block 0  
fill ~15 ~7 ~39 ~19 ~7 ~39 gold_block 0  
fill ~20 ~7 ~10 ~34 ~7 ~10 gold_block 0  
fill ~20 ~7 ~11 ~34 ~7 ~11 gold_block 0  
fill ~20 ~7 ~12 ~34 ~7 ~12 gold_block 0  
fill ~20 ~7 ~13 ~34 ~7 ~13 gold_block 0  
fill ~20 ~7 ~14 ~34 ~7 ~14 gold_block 0  
fill ~20 ~7 ~15 ~34 ~7 ~15 wool 12  
fill ~20 ~7 ~16 ~34 ~7 ~16 wool 12  
fill ~20 ~7 ~17 ~34 ~7 ~17 wool 12  
fill ~20 ~7 ~18 ~34 ~7 ~18 wool 12  
fill ~20 ~7 ~19 ~34 ~7 ~19 wool 12  
fill ~20 ~7 ~20 ~24 ~7 ~20 wool 12  
fill ~20 ~7 ~21 ~24 ~7 ~21 wool 12  
fill ~20 ~7 ~22 ~24 ~7 ~22 wool 12  
fill ~20 ~7 ~23 ~24 ~7 ~23 wool 12  
fill ~20 ~7 ~24 ~24 ~7 ~24 wool 12  
fill ~20 ~7 ~25 ~29 ~7 ~25 glowstone 0  
fill ~20 ~7 ~26 ~29 ~7 ~26 glowstone 0  
fill ~20 ~7 ~27 ~29 ~7 ~27 glowstone 0  
fill ~20 ~7 ~28 ~29 ~7 ~28 glowstone 0   
fill ~20 ~7 ~29 ~29 ~7 ~29 glowstone 0  
fill ~20 ~7 ~30 ~24 ~7 ~30 wool 12  
fill ~20 ~7 ~31 ~24 ~7 ~31 wool 12  
fill ~20 ~7 ~32 ~24 ~7 ~32 wool 12  
fill ~20 ~7 ~33 ~24 ~7 ~33 wool 12  
fill ~20 ~7 ~34 ~24 ~7 ~34 wool 12  
fill ~20 ~7 ~35 ~34 ~7 ~35 wool 12  
fill ~20 ~7 ~36 ~34 ~7 ~36 wool 12  
fill ~20 ~7 ~37 ~34 ~7 ~37 wool 12  
fill ~20 ~7 ~38 ~34 ~7 ~38 wool 12  
fill ~20 ~7 ~39 ~34 ~7 ~39 wool 12  
fill ~20 ~7 ~40 ~34 ~7 ~40 gold_block 0  
fill ~20 ~7 ~41 ~34 ~7 ~41 gold_block 0  
fill ~20 ~7 ~42 ~34 ~7 ~42 gold_block 0  
fill ~20 ~7 ~43 ~34 ~7 ~43 gold_block 0  
fill ~20 ~7 ~44 ~34 ~7 ~44 gold_block 0  
fill ~25 ~7 ~20 ~34 ~7 ~20 glowstone 0  
fill ~25 ~7 ~21 ~34 ~7 ~21 glowstone 0  
fill ~25 ~7 ~22 ~34 ~7 ~22 glowstone 0  
fill ~25 ~7 ~23 ~34 ~7 ~23 glowstone 0  
fill ~25 ~7 ~24 ~34 ~7 ~24 glowstone 0  
fill ~25 ~7 ~30 ~34 ~7 ~30 glowstone 0  
fill ~25 ~7 ~31 ~34 ~7 ~31 glowstone 0  
fill ~25 ~7 ~32 ~34 ~7 ~32 glowstone 0  
fill ~25 ~7 ~33 ~34 ~7 ~33 glowstone 0  
fill ~25 ~7 ~34 ~34 ~7 ~34 glowstone 0  
fill ~30 ~7 ~25 ~39 ~7 ~25 wool 12  
fill ~30 ~7 ~26 ~39 ~7 ~26 wool 12  
fill ~30 ~7 ~27 ~39 ~7 ~27 wool 12  
fill ~30 ~7 ~28 ~39 ~7 ~28 wool 12  
fill ~30 ~7 ~29 ~39 ~7 ~29 wool 12  
fill ~35 ~7 ~15 ~39 ~7 ~15 gold_block 0  
fill ~35 ~7 ~16 ~39 ~7 ~16 gold_block 0  
fill ~35 ~7 ~17 ~39 ~7 ~17 gold_block 0  
fill ~35 ~7 ~18 ~39 ~7 ~18 gold_block 0  
fill ~35 ~7 ~19 ~39 ~7 ~19 gold_block 0  
fill ~35 ~7 ~20 ~39 ~7 ~20 wool 12  
fill ~35 ~7 ~21 ~39 ~7 ~21 wool 12  
fill ~35 ~7 ~22 ~39 ~7 ~22 wool 12  
fill ~35 ~7 ~23 ~39 ~7 ~23 wool 12  
fill ~35 ~7 ~24 ~39 ~7 ~24 wool 12  
fill ~35 ~7 ~30 ~39 ~7 ~30 wool 12  
fill ~35 ~7 ~31 ~39 ~7 ~31 wool 12  
fill ~35 ~7 ~32 ~39 ~7 ~32 wool 12  
fill ~35 ~7 ~33 ~39 ~7 ~33 wool 12  
fill ~35 ~7 ~34 ~39 ~7 ~34 wool 12  
fill ~35 ~7 ~35 ~39 ~7 ~35 gold_block 0  
fill ~35 ~7 ~36 ~39 ~7 ~36 gold_block 0  
fill ~35 ~7 ~37 ~39 ~7 ~37 gold_block 0  
fill ~35 ~7 ~38 ~39 ~7 ~38 gold_block 0  
fill ~35 ~7 ~39 ~39 ~7 ~39 gold_block 0  
fill ~40 ~7 ~20 ~44 ~7 ~20 gold_block 0  
fill ~40 ~7 ~21 ~44 ~7 ~21 gold_block 0  
fill ~40 ~7 ~22 ~44 ~7 ~22 gold_block 0  
fill ~40 ~7 ~23 ~44 ~7 ~23 gold_block 0  
fill ~40 ~7 ~24 ~44 ~7 ~24 gold_block 0  
fill ~40 ~7 ~25 ~44 ~7 ~25 gold_block 0  
fill ~40 ~7 ~26 ~44 ~7 ~26 gold_block 0  
fill ~40 ~7 ~27 ~44 ~7 ~27 gold_block 0  
fill ~40 ~7 ~28 ~44 ~7 ~28 gold_block 0  
fill ~40 ~7 ~29 ~44 ~7 ~29 gold_block 0  
fill ~40 ~7 ~30 ~44 ~7 ~30 gold_block 0  
fill ~40 ~7 ~31 ~44 ~7 ~31 gold_block 0  
fill ~40 ~7 ~32 ~44 ~7 ~32 gold_block 0  
fill ~40 ~7 ~33 ~44 ~7 ~33 gold_block 0  
fill ~40 ~7 ~34 ~44 ~7 ~34 gold_block 0  
fill ~55 ~7 ~25 ~69 ~7 ~25 gold_block 0  
fill ~55 ~7 ~26 ~69 ~7 ~26 gold_block 0  
fill ~55 ~7 ~27 ~69 ~7 ~27 gold_block 0  
fill ~55 ~7 ~28 ~69 ~7 ~28 gold_block 0  
fill ~55 ~7 ~29 ~69 ~7 ~29 gold_block 0  
fill ~10 ~8 ~20 ~14 ~8 ~20 gold_block 0  
fill ~10 ~8 ~21 ~14 ~8 ~21 gold_block 0  
fill ~10 ~8 ~22 ~14 ~8 ~22 gold_block 0  
fill ~10 ~8 ~23 ~14 ~8 ~23 gold_block 0  
fill ~10 ~8 ~24 ~14 ~8 ~24 gold_block 0  
fill ~10 ~8 ~25 ~14 ~8 ~25 gold_block 0  
fill ~10 ~8 ~26 ~14 ~8 ~26 gold_block 0  
fill ~10 ~8 ~27 ~14 ~8 ~27 gold_block 0  
fill ~10 ~8 ~28 ~14 ~8 ~28 gold_block 0  
fill ~10 ~8 ~29 ~14 ~8 ~29 gold_block 0  
fill ~10 ~8 ~30 ~14 ~8 ~30 gold_block 0  
fill ~10 ~8 ~31 ~14 ~8 ~31 gold_block 0  
fill ~10 ~8 ~32 ~14 ~8 ~32 gold_block 0  
fill ~10 ~8 ~33 ~14 ~8 ~33 gold_block 0  
fill ~10 ~8 ~34 ~14 ~8 ~34 gold_block 0  
fill ~15 ~8 ~15 ~19 ~8 ~15 gold_block 0  
fill ~15 ~8 ~16 ~19 ~8 ~16 gold_block 0  
fill ~15 ~8 ~17 ~19 ~8 ~17 gold_block 0  
fill ~15 ~8 ~18 ~19 ~8 ~18 gold_block 0  
fill ~15 ~8 ~19 ~19 ~8 ~19 gold_block 0  
fill ~15 ~8 ~20 ~19 ~8 ~20 glowstone 0  
fill ~15 ~8 ~21 ~19 ~8 ~21 glowstone 0  
fill ~15 ~8 ~22 ~19 ~8 ~22 glowstone 0  
fill ~15 ~8 ~23 ~19 ~8 ~23 glowstone 0  
fill ~15 ~8 ~24 ~19 ~8 ~24 glowstone 0  
fill ~15 ~8 ~25 ~19 ~8 ~25 wool 12  
fill ~15 ~8 ~26 ~19 ~8 ~26 wool 12  
fill ~15 ~8 ~27 ~19 ~8 ~27 wool 12  
fill ~15 ~8 ~28 ~19 ~8 ~28 wool 12  
fill ~15 ~8 ~29 ~19 ~8 ~29 wool 12  
fill ~15 ~8 ~30 ~19 ~8 ~30 glowstone 0  
fill ~15 ~8 ~31 ~19 ~8 ~31 glowstone 0  
fill ~15 ~8 ~32 ~19 ~8 ~32 glowstone 0  
fill ~15 ~8 ~33 ~19 ~8 ~33 glowstone 0  
fill ~15 ~8 ~34 ~19 ~8 ~34 glowstone 0  
fill ~15 ~8 ~35 ~19 ~8 ~35 gold_block 0  
fill ~15 ~8 ~36 ~19 ~8 ~36 gold_block 0  
fill ~15 ~8 ~37 ~19 ~8 ~37 gold_block 0  
fill ~15 ~8 ~38 ~19 ~8 ~38 gold_block 0  
fill ~15 ~8 ~39 ~19 ~8 ~39 gold_block 0  
fill ~20 ~8 ~10 ~34 ~8 ~10 gold_block 0  
fill ~20 ~8 ~11 ~34 ~8 ~11 gold_block 0  
fill ~20 ~8 ~12 ~34 ~8 ~12 gold_block 0  
fill ~20 ~8 ~13 ~34 ~8 ~13 gold_block 0  
fill ~20 ~8 ~14 ~34 ~8 ~14 gold_block 0  
fill ~20 ~8 ~15 ~34 ~8 ~15 wool 12  
fill ~20 ~8 ~16 ~34 ~8 ~16 wool 12  
fill ~20 ~8 ~17 ~34 ~8 ~17 wool 12  
fill ~20 ~8 ~18 ~34 ~8 ~18 wool 12  
fill ~20 ~8 ~19 ~34 ~8 ~19 wool 12  
fill ~20 ~8 ~20 ~24 ~8 ~20 wool 12  
fill ~20 ~8 ~21 ~24 ~8 ~21 wool 12  
fill ~20 ~8 ~22 ~24 ~8 ~22 wool 12  
fill ~20 ~8 ~23 ~24 ~8 ~23 wool 12  
fill ~20 ~8 ~24 ~24 ~8 ~24 wool 12  
fill ~20 ~8 ~25 ~29 ~8 ~25 glowstone 0  
fill ~20 ~8 ~26 ~29 ~8 ~26 glowstone 0  
fill ~20 ~8 ~27 ~29 ~8 ~27 glowstone 0  
fill ~20 ~8 ~28 ~29 ~8 ~28 glowstone 0  
fill ~20 ~8 ~29 ~29 ~8 ~29 glowstone 0  
fill ~20 ~8 ~30 ~24 ~8 ~30 wool 12  
fill ~20 ~8 ~31 ~24 ~8 ~31 wool 12  
fill ~20 ~8 ~32 ~24 ~8 ~32 wool 12  
fill ~20 ~8 ~33 ~24 ~8 ~33 wool 12  
fill ~20 ~8 ~34 ~24 ~8 ~34 wool 12  
fill ~20 ~8 ~35 ~34 ~8 ~35 wool 12  
fill ~20 ~8 ~36 ~34 ~8 ~36 wool 12  
fill ~20 ~8 ~37 ~34 ~8 ~37 wool 12  
fill ~20 ~8 ~38 ~34 ~8 ~38 wool 12  
fill ~20 ~8 ~39 ~34 ~8 ~39 wool 12  
fill ~20 ~8 ~40 ~34 ~8 ~40 gold_block 0  
fill ~20 ~8 ~41 ~34 ~8 ~41 gold_block 0  
fill ~20 ~8 ~42 ~34 ~8 ~42 gold_block 0  
fill ~20 ~8 ~43 ~34 ~8 ~43 gold_block 0  
fill ~20 ~8 ~44 ~34 ~8 ~44 gold_block 0  
fill ~25 ~8 ~20 ~34 ~8 ~20 glowstone 0  
fill ~25 ~8 ~21 ~34 ~8 ~21 glowstone 0  
fill ~25 ~8 ~22 ~34 ~8 ~22 glowstone 0  
fill ~25 ~8 ~23 ~34 ~8 ~23 glowstone 0  
fill ~25 ~8 ~24 ~34 ~8 ~24 glowstone 0  
fill ~25 ~8 ~30 ~34 ~8 ~30 glowstone 0  
fill ~25 ~8 ~31 ~34 ~8 ~31 glowstone 0  
fill ~25 ~8 ~32 ~34 ~8 ~32 glowstone 0  
fill ~25 ~8 ~33 ~34 ~8 ~33 glowstone 0  
fill ~25 ~8 ~34 ~34 ~8 ~34 glowstone 0  
fill ~30 ~8 ~25 ~39 ~8 ~25 wool 12  
fill ~30 ~8 ~26 ~39 ~8 ~26 wool 12  
fill ~30 ~8 ~27 ~39 ~8 ~27 wool 12  
fill ~30 ~8 ~28 ~39 ~8 ~28 wool 12  
fill ~30 ~8 ~29 ~39 ~8 ~29 wool 12  
fill ~35 ~8 ~15 ~39 ~8 ~15 gold_block 0  
fill ~35 ~8 ~16 ~39 ~8 ~16 gold_block 0  
fill ~35 ~8 ~17 ~39 ~8 ~17 gold_block 0  
fill ~35 ~8 ~18 ~39 ~8 ~18 gold_block 0  
fill ~35 ~8 ~19 ~39 ~8 ~19 gold_block 0  
fill ~35 ~8 ~20 ~39 ~8 ~20 wool 12  
fill ~35 ~8 ~21 ~39 ~8 ~21 wool 12  
fill ~35 ~8 ~22 ~39 ~8 ~22 wool 12  
fill ~35 ~8 ~23 ~39 ~8 ~23 wool 12  
fill ~35 ~8 ~24 ~39 ~8 ~24 wool 12  
fill ~35 ~8 ~30 ~39 ~8 ~30 wool 12  
fill ~35 ~8 ~31 ~39 ~8 ~31 wool 12  
fill ~35 ~8 ~32 ~39 ~8 ~32 wool 12  
fill ~35 ~8 ~33 ~39 ~8 ~33 wool 12  
fill ~35 ~8 ~34 ~39 ~8 ~34 wool 12  
fill ~35 ~8 ~35 ~39 ~8 ~35 gold_block 0  
fill ~35 ~8 ~36 ~39 ~8 ~36 gold_block 0  
fill ~35 ~8 ~37 ~39 ~8 ~37 gold_block 0  
fill ~35 ~8 ~38 ~39 ~8 ~38 gold_block 0  
fill ~35 ~8 ~39 ~39 ~8 ~39 gold_block 0  
fill ~40 ~8 ~20 ~44 ~8 ~20 gold_block 0  
fill ~40 ~8 ~21 ~44 ~8 ~21 gold_block 0  
fill ~40 ~8 ~22 ~44 ~8 ~22 gold_block 0  
fill ~40 ~8 ~23 ~44 ~8 ~23 gold_block 0  
fill ~40 ~8 ~24 ~44 ~8 ~24 gold_block 0  
fill ~40 ~8 ~25 ~44 ~8 ~25 gold_block 0  
fill ~40 ~8 ~26 ~44 ~8 ~26 gold_block 0  
fill ~40 ~8 ~27 ~44 ~8 ~27 gold_block 0  
fill ~40 ~8 ~28 ~44 ~8 ~28 gold_block 0  
fill ~40 ~8 ~29 ~44 ~8 ~29 gold_block 0  
fill ~40 ~8 ~30 ~44 ~8 ~30 gold_block 0  
fill ~40 ~8 ~31 ~44 ~8 ~31 gold_block 0  
fill ~40 ~8 ~32 ~44 ~8 ~32 gold_block 0  
fill ~40 ~8 ~33 ~44 ~8 ~33 gold_block 0  
fill ~40 ~8 ~34 ~44 ~8 ~34 gold_block 0  
fill ~55 ~8 ~25 ~69 ~8 ~25 gold_block 0  
fill ~55 ~8 ~26 ~69 ~8 ~26 gold_block 0  
fill ~55 ~8 ~27 ~69 ~8 ~27 gold_block 0  
fill ~55 ~8 ~28 ~69 ~8 ~28 gold_block 0  
fill ~55 ~8 ~29 ~69 ~8 ~29 gold_block 0  
fill ~10 ~9 ~20 ~14 ~9 ~20 gold_block 0  
fill ~10 ~9 ~21 ~14 ~9 ~21 gold_block 0  
fill ~10 ~9 ~22 ~14 ~9 ~22 gold_block 0  
fill ~10 ~9 ~23 ~14 ~9 ~23 gold_block 0  
fill ~10 ~9 ~24 ~14 ~9 ~24 gold_block 0  
fill ~10 ~9 ~25 ~14 ~9 ~25 gold_block 0  
fill ~10 ~9 ~26 ~14 ~9 ~26 gold_block 0  
fill ~10 ~9 ~27 ~14 ~9 ~27 gold_block 0  
fill ~10 ~9 ~28 ~14 ~9 ~28 gold_block 0  
fill ~10 ~9 ~29 ~14 ~9 ~29 gold_block 0  
fill ~10 ~9 ~30 ~14 ~9 ~30 gold_block 0  
fill ~10 ~9 ~31 ~14 ~9 ~31 gold_block 0  
fill ~10 ~9 ~32 ~14 ~9 ~32 gold_block 0  
fill ~10 ~9 ~33 ~14 ~9 ~33 gold_block 0  
fill ~10 ~9 ~34 ~14 ~9 ~34 gold_block 0  
fill ~15 ~9 ~15 ~19 ~9 ~15 gold_block 0  
fill ~15 ~9 ~16 ~19 ~9 ~16 gold_block 0  
fill ~15 ~9 ~17 ~19 ~9 ~17 gold_block 0  
fill ~15 ~9 ~18 ~19 ~9 ~18 gold_block 0  
fill ~15 ~9 ~19 ~19 ~9 ~19 gold_block 0  
fill ~15 ~9 ~20 ~19 ~9 ~20 glowstone 0  
fill ~15 ~9 ~21 ~19 ~9 ~21 glowstone 0  
fill ~15 ~9 ~22 ~19 ~9 ~22 glowstone 0  
fill ~15 ~9 ~23 ~19 ~9 ~23 glowstone 0  
fill ~15 ~9 ~24 ~19 ~9 ~24 glowstone 0  
fill ~15 ~9 ~25 ~19 ~9 ~25 wool 12  
fill ~15 ~9 ~26 ~19 ~9 ~26 wool 12  
fill ~15 ~9 ~27 ~19 ~9 ~27 wool 12  
fill ~15 ~9 ~28 ~19 ~9 ~28 wool 12  
fill ~15 ~9 ~29 ~19 ~9 ~29 wool 12  
fill ~15 ~9 ~30 ~19 ~9 ~30 glowstone 0  
fill ~15 ~9 ~31 ~19 ~9 ~31 glowstone 0  
fill ~15 ~9 ~32 ~19 ~9 ~32 glowstone 0  
fill ~15 ~9 ~33 ~19 ~9 ~33 glowstone 0  
fill ~15 ~9 ~34 ~19 ~9 ~34 glowstone 0  
fill ~15 ~9 ~35 ~19 ~9 ~35 gold_block 0  
fill ~15 ~9 ~36 ~19 ~9 ~36 gold_block 0  
fill ~15 ~9 ~37 ~19 ~9 ~37 gold_block 0  
fill ~15 ~9 ~38 ~19 ~9 ~38 gold_block 0  
fill ~15 ~9 ~39 ~19 ~9 ~39 gold_block 0  
fill ~20 ~9 ~10 ~34 ~9 ~10 gold_block 0  
fill ~20 ~9 ~11 ~34 ~9 ~11 gold_block 0  
fill ~20 ~9 ~12 ~34 ~9 ~12 gold_block 0  
fill ~20 ~9 ~13 ~34 ~9 ~13 gold_block 0  
fill ~20 ~9 ~14 ~34 ~9 ~14 gold_block 0  
fill ~20 ~9 ~15 ~34 ~9 ~15 wool 12  
fill ~20 ~9 ~16 ~34 ~9 ~16 wool 12  
fill ~20 ~9 ~17 ~34 ~9 ~17 wool 12  
fill ~20 ~9 ~18 ~34 ~9 ~18 wool 12  
fill ~20 ~9 ~19 ~34 ~9 ~19 wool 12  
fill ~20 ~9 ~20 ~24 ~9 ~20 wool 12  
fill ~20 ~9 ~21 ~24 ~9 ~21 wool 12  
fill ~20 ~9 ~22 ~24 ~9 ~22 wool 12  
fill ~20 ~9 ~23 ~24 ~9 ~23 wool 12  
fill ~20 ~9 ~24 ~24 ~9 ~24 wool 12  
fill ~20 ~9 ~25 ~29 ~9 ~25 glowstone 0  
fill ~20 ~9 ~26 ~29 ~9 ~26 glowstone 0  
fill ~20 ~9 ~27 ~29 ~9 ~27 glowstone 0  
fill ~20 ~9 ~28 ~29 ~9 ~28 glowstone 0  
fill ~20 ~9 ~29 ~29 ~9 ~29 glowstone 0  
fill ~20 ~9 ~30 ~24 ~9 ~30 wool 12  
fill ~20 ~9 ~31 ~24 ~9 ~31 wool 12  
fill ~20 ~9 ~32 ~24 ~9 ~32 wool 12  
fill ~20 ~9 ~33 ~24 ~9 ~33 wool 12  
fill ~20 ~9 ~34 ~24 ~9 ~34 wool 12  
fill ~20 ~9 ~35 ~34 ~9 ~35 wool 12  
fill ~20 ~9 ~36 ~34 ~9 ~36 wool 12  
fill ~20 ~9 ~37 ~34 ~9 ~37 wool 12  
fill ~20 ~9 ~38 ~34 ~9 ~38 wool 12  
fill ~20 ~9 ~39 ~34 ~9 ~39 wool 12  
fill ~20 ~9 ~40 ~34 ~9 ~40 gold_block 0  
fill ~20 ~9 ~41 ~34 ~9 ~41 gold_block 0  
fill ~20 ~9 ~42 ~34 ~9 ~42 gold_block 0  
fill ~20 ~9 ~43 ~34 ~9 ~43 gold_block 0  
fill ~20 ~9 ~44 ~34 ~9 ~44 gold_block 0  
fill ~25 ~9 ~20 ~34 ~9 ~20 glowstone 0  
fill ~25 ~9 ~21 ~34 ~9 ~21 glowstone 0  
fill ~25 ~9 ~22 ~34 ~9 ~22 glowstone 0  
fill ~25 ~9 ~23 ~34 ~9 ~23 glowstone 0  
fill ~25 ~9 ~24 ~34 ~9 ~24 glowstone 0  
fill ~25 ~9 ~30 ~34 ~9 ~30 glowstone 0  
fill ~25 ~9 ~31 ~34 ~9 ~31 glowstone 0  
fill ~25 ~9 ~32 ~34 ~9 ~32 glowstone 0  
fill ~25 ~9 ~33 ~34 ~9 ~33 glowstone 0  
fill ~25 ~9 ~34 ~34 ~9 ~34 glowstone 0  
fill ~30 ~9 ~25 ~39 ~9 ~25 wool 12  
fill ~30 ~9 ~26 ~39 ~9 ~26 wool 12  
fill ~30 ~9 ~27 ~39 ~9 ~27 wool 12  
fill ~30 ~9 ~28 ~39 ~9 ~28 wool 12  
fill ~30 ~9 ~29 ~39 ~9 ~29 wool 12  
fill ~35 ~9 ~15 ~39 ~9 ~15 gold_block 0  
fill ~35 ~9 ~16 ~39 ~9 ~16 gold_block 0  
fill ~35 ~9 ~17 ~39 ~9 ~17 gold_block 0  
fill ~35 ~9 ~18 ~39 ~9 ~18 gold_block 0  
fill ~35 ~9 ~19 ~39 ~9 ~19 gold_block 0  
fill ~35 ~9 ~20 ~39 ~9 ~20 wool 12  
fill ~35 ~9 ~21 ~39 ~9 ~21 wool 12  
fill ~35 ~9 ~22 ~39 ~9 ~22 wool 12  
fill ~35 ~9 ~23 ~39 ~9 ~23 wool 12  
fill ~35 ~9 ~24 ~39 ~9 ~24 wool 12  
fill ~35 ~9 ~30 ~39 ~9 ~30 wool 12  
fill ~35 ~9 ~31 ~39 ~9 ~31 wool 12  
fill ~35 ~9 ~32 ~39 ~9 ~32 wool 12  
fill ~35 ~9 ~33 ~39 ~9 ~33 wool 12  
fill ~35 ~9 ~34 ~39 ~9 ~34 wool 12  
fill ~35 ~9 ~35 ~39 ~9 ~35 gold_block 0  
fill ~35 ~9 ~36 ~39 ~9 ~36 gold_block 0  
fill ~35 ~9 ~37 ~39 ~9 ~37 gold_block 0  
fill ~35 ~9 ~38 ~39 ~9 ~38 gold_block 0  
fill ~35 ~9 ~39 ~39 ~9 ~39 gold_block 0  
fill ~40 ~9 ~20 ~44 ~9 ~20 gold_block 0  
fill ~40 ~9 ~21 ~44 ~9 ~21 gold_block 0  
fill ~40 ~9 ~22 ~44 ~9 ~22 gold_block 0  
fill ~40 ~9 ~23 ~44 ~9 ~23 gold_block 0  
fill ~40 ~9 ~24 ~44 ~9 ~24 gold_block 0  
fill ~40 ~9 ~25 ~44 ~9 ~25 gold_block 0  
fill ~40 ~9 ~26 ~44 ~9 ~26 gold_block 0  
fill ~40 ~9 ~27 ~44 ~9 ~27 gold_block 0  
fill ~40 ~9 ~28 ~44 ~9 ~28 gold_block 0  
fill ~40 ~9 ~29 ~44 ~9 ~29 gold_block 0  
fill ~40 ~9 ~30 ~44 ~9 ~30 gold_block 0  
fill ~40 ~9 ~31 ~44 ~9 ~31 gold_block 0  
fill ~40 ~9 ~32 ~44 ~9 ~32 gold_block 0  
fill ~40 ~9 ~33 ~44 ~9 ~33 gold_block 0  
fill ~40 ~9 ~34 ~44 ~9 ~34 gold_block 0  
fill ~55 ~9 ~25 ~69 ~9 ~25 gold_block 0  
fill ~55 ~9 ~26 ~69 ~9 ~26 gold_block 0  
fill ~55 ~9 ~27 ~69 ~9 ~27 gold_block 0  
fill ~55 ~9 ~28 ~69 ~9 ~28 gold_block 0  
fill ~55 ~9 ~29 ~69 ~9 ~29 gold_block 0  
fill ~5 ~10 ~20 ~9 ~10 ~20 iron_block 0  
fill ~5 ~10 ~21 ~9 ~10 ~21 iron_block 0  
fill ~5 ~10 ~22 ~9 ~10 ~22 iron_block 0  
fill ~5 ~10 ~23 ~9 ~10 ~23 iron_block 0  
fill ~5 ~10 ~24 ~9 ~10 ~24 iron_block 0  
fill ~5 ~10 ~25 ~9 ~10 ~25 iron_block 0  
fill ~5 ~10 ~26 ~9 ~10 ~26 iron_block 0  
fill ~5 ~10 ~27 ~9 ~10 ~27 iron_block 0  
fill ~5 ~10 ~28 ~9 ~10 ~28 iron_block 0  
fill ~5 ~10 ~29 ~9 ~10 ~29 iron_block 0  
fill ~5 ~10 ~30 ~9 ~10 ~30 iron_block 0  
fill ~5 ~10 ~31 ~9 ~10 ~31 iron_block 0  
fill ~5 ~10 ~32 ~9 ~10 ~32 iron_block 0  
fill ~5 ~10 ~33 ~9 ~10 ~33 iron_block 0  
fill ~5 ~10 ~34 ~9 ~10 ~34 iron_block 0  
fill ~10 ~10 ~15 ~14 ~10 ~15 iron_block 0  
fill ~10 ~10 ~16 ~14 ~10 ~16 iron_block 0  
fill ~10 ~10 ~17 ~14 ~10 ~17 iron_block 0  
fill ~10 ~10 ~18 ~14 ~10 ~18 iron_block 0  
fill ~10 ~10 ~19 ~14 ~10 ~19 iron_block 0  
fill ~10 ~10 ~20 ~39 ~10 ~20 wool 12  
fill ~10 ~10 ~21 ~39 ~10 ~21 wool 12  
fill ~10 ~10 ~22 ~39 ~10 ~22 wool 12  
fill ~10 ~10 ~23 ~39 ~10 ~23 wool 12  
fill ~10 ~10 ~24 ~39 ~10 ~24 wool 12  
fill ~10 ~10 ~25 ~44 ~10 ~25 wool 12  
fill ~10 ~10 ~26 ~44 ~10 ~26 wool 12  
fill ~10 ~10 ~27 ~44 ~10 ~27 wool 12  
fill ~10 ~10 ~28 ~44 ~10 ~28 wool 12  
fill ~10 ~10 ~29 ~44 ~10 ~29 wool 12  
fill ~10 ~10 ~30 ~44 ~10 ~30 wool 12  
fill ~10 ~10 ~31 ~44 ~10 ~31 wool 12  
fill ~10 ~10 ~32 ~44 ~10 ~32 wool 12  
fill ~10 ~10 ~33 ~44 ~10 ~33 wool 12  
fill ~10 ~10 ~34 ~44 ~10 ~34 wool 12  
fill ~10 ~10 ~35 ~14 ~10 ~35 iron_block 0  
fill ~10 ~10 ~36 ~14 ~10 ~36 iron_block 0  
fill ~10 ~10 ~37 ~14 ~10 ~37 iron_block 0  
fill ~10 ~10 ~38 ~14 ~10 ~38 iron_block 0  
fill ~10 ~10 ~39 ~14 ~10 ~39 iron_block 0  
fill ~15 ~10 ~10 ~19 ~10 ~10 iron_block 0  
fill ~15 ~10 ~11 ~19 ~10 ~11 iron_block 0  
fill ~15 ~10 ~12 ~19 ~10 ~12 iron_block 0  
fill ~15 ~10 ~13 ~19 ~10 ~13 iron_block 0  
fill ~15 ~10 ~14 ~19 ~10 ~14 iron_block 0  
fill ~15 ~10 ~15 ~39 ~10 ~15 wool 12  
fill ~15 ~10 ~16 ~39 ~10 ~16 wool 12  
fill ~15 ~10 ~17 ~39 ~10 ~17 wool 12  
fill ~15 ~10 ~18 ~39 ~10 ~18 wool 12  
fill ~15 ~10 ~19 ~39 ~10 ~19 wool 12  
fill ~15 ~10 ~35 ~39 ~10 ~35 wool 12  
fill ~15 ~10 ~36 ~39 ~10 ~36 wool 12  
fill ~15 ~10 ~37 ~39 ~10 ~37 wool 12  
fill ~15 ~10 ~38 ~39 ~10 ~38 wool 12  
fill ~15 ~10 ~39 ~39 ~10 ~39 wool 12  
fill ~15 ~10 ~40 ~19 ~10 ~40 iron_block 0  
fill ~15 ~10 ~41 ~19 ~10 ~41 iron_block 0  
fill ~15 ~10 ~42 ~19 ~10 ~42 iron_block 0  
fill ~15 ~10 ~43 ~19 ~10 ~43 iron_block 0  
fill ~15 ~10 ~44 ~19 ~10 ~44 iron_block 0  
fill ~20 ~10 ~5 ~34 ~10 ~5 iron_block 0  
fill ~20 ~10 ~6 ~34 ~10 ~6 iron_block 0  
fill ~20 ~10 ~7 ~34 ~10 ~7 iron_block 0  
fill ~20 ~10 ~8 ~34 ~10 ~8 iron_block 0  
fill ~20 ~10 ~9 ~34 ~10 ~9 iron_block 0  
fill ~20 ~10 ~10 ~34 ~10 ~10 wool 12  
fill ~20 ~10 ~11 ~34 ~10 ~11 wool 12  
fill ~20 ~10 ~12 ~34 ~10 ~12 wool 12  
fill ~20 ~10 ~13 ~34 ~10 ~13 wool 12  
fill ~20 ~10 ~14 ~34 ~10 ~14 wool 12  
fill ~20 ~10 ~40 ~34 ~10 ~40 wool 12  
fill ~20 ~10 ~41 ~34 ~10 ~41 wool 12  
fill ~20 ~10 ~42 ~34 ~10 ~42 wool 12  
fill ~20 ~10 ~43 ~34 ~10 ~43 wool 12  
fill ~20 ~10 ~44 ~34 ~10 ~44 wool 12  
fill ~20 ~10 ~45 ~34 ~10 ~45 iron_block 0  
fill ~20 ~10 ~46 ~34 ~10 ~46 iron_block 0  
fill ~20 ~10 ~47 ~34 ~10 ~47 iron_block 0  
fill ~20 ~10 ~48 ~34 ~10 ~48 iron_block 0  
fill ~20 ~10 ~49 ~34 ~10 ~49 iron_block 0  
fill ~35 ~10 ~10 ~39 ~10 ~10 iron_block 0  
fill ~35 ~10 ~11 ~39 ~10 ~11 iron_block 0  
fill ~35 ~10 ~12 ~39 ~10 ~12 iron_block 0  
fill ~35 ~10 ~13 ~39 ~10 ~13 iron_block 0  
fill ~35 ~10 ~14 ~39 ~10 ~14 iron_block 0  
fill ~35 ~10 ~40 ~39 ~10 ~40 iron_block 0  
fill ~35 ~10 ~41 ~39 ~10 ~41 iron_block 0  
fill ~35 ~10 ~42 ~39 ~10 ~42 iron_block 0  
fill ~35 ~10 ~43 ~39 ~10 ~43 iron_block 0  
fill ~35 ~10 ~44 ~39 ~10 ~44 iron_block 0  
fill ~40 ~10 ~15 ~44 ~10 ~15 iron_block 0  
fill ~40 ~10 ~16 ~44 ~10 ~16 iron_block 0  
fill ~40 ~10 ~17 ~44 ~10 ~17 iron_block 0  
fill ~40 ~10 ~18 ~44 ~10 ~18 iron_block 0  
fill ~40 ~10 ~19 ~44 ~10 ~19 iron_block 0  
fill ~40 ~10 ~20 ~44 ~10 ~20 glowstone 0  
fill ~40 ~10 ~21 ~44 ~10 ~21 glowstone 0  
fill ~40 ~10 ~22 ~44 ~10 ~22 glowstone 0  
fill ~40 ~10 ~23 ~44 ~10 ~23 glowstone 0  
fill ~40 ~10 ~24 ~44 ~10 ~24 glowstone 0  
fill ~40 ~10 ~35 ~44 ~10 ~35 iron_block 0  
fill ~40 ~10 ~36 ~44 ~10 ~36 iron_block 0  
fill ~40 ~10 ~37 ~44 ~10 ~37 iron_block 0  
fill ~40 ~10 ~38 ~44 ~10 ~38 iron_block 0  
fill ~40 ~10 ~39 ~44 ~10 ~39 iron_block 0  
fill ~45 ~10 ~20 ~49 ~10 ~20 iron_block 0  
fill ~45 ~10 ~21 ~49 ~10 ~21 iron_block 0  
fill ~45 ~10 ~22 ~49 ~10 ~22 iron_block 0  
fill ~45 ~10 ~23 ~49 ~10 ~23 iron_block 0  
fill ~45 ~10 ~24 ~49 ~10 ~24 iron_block 0  
fill ~45 ~10 ~25 ~49 ~10 ~25 iron_block 0  
fill ~45 ~10 ~26 ~49 ~10 ~26 iron_block 0  
fill ~45 ~10 ~27 ~49 ~10 ~27 iron_block 0  
fill ~45 ~10 ~28 ~49 ~10 ~28 iron_block 0  
fill ~45 ~10 ~29 ~49 ~10 ~29 iron_block 0  
fill ~45 ~10 ~30 ~49 ~10 ~30 iron_block 0  
fill ~45 ~10 ~31 ~49 ~10 ~31 iron_block 0  
fill ~45 ~10 ~32 ~49 ~10 ~32 iron_block 0  
fill ~45 ~10 ~33 ~49 ~10 ~33 iron_block 0  
fill ~45 ~10 ~34 ~49 ~10 ~34 iron_block 0  
fill ~50 ~10 ~25 ~54 ~10 ~25 gold_block 0  
fill ~50 ~10 ~26 ~54 ~10 ~26 gold_block 0  
fill ~50 ~10 ~27 ~54 ~10 ~27 gold_block 0  
fill ~50 ~10 ~28 ~54 ~10 ~28 gold_block 0  
fill ~50 ~10 ~29 ~54 ~10 ~29 gold_block 0  
fill ~70 ~10 ~25 ~74 ~10 ~25 gold_block 0  
fill ~70 ~10 ~26 ~74 ~10 ~26 gold_block 0  
fill ~70 ~10 ~27 ~74 ~10 ~27 gold_block 0  
fill ~70 ~10 ~28 ~74 ~10 ~28 gold_block 0  
fill ~70 ~10 ~29 ~74 ~10 ~29 gold_block 0  
fill ~5 ~11 ~20 ~9 ~11 ~20 iron_block 0  
fill ~5 ~11 ~21 ~9 ~11 ~21 iron_block 0  
fill ~5 ~11 ~22 ~9 ~11 ~22 iron_block 0  
fill ~5 ~11 ~23 ~9 ~11 ~23 iron_block 0  
fill ~5 ~11 ~24 ~9 ~11 ~24 iron_block 0  
fill ~5 ~11 ~25 ~9 ~11 ~25 iron_block 0  
fill ~5 ~11 ~26 ~9 ~11 ~26 iron_block 0  
fill ~5 ~11 ~27 ~9 ~11 ~27 iron_block 0  
fill ~5 ~11 ~28 ~9 ~11 ~28 iron_block 0  
fill ~5 ~11 ~29 ~9 ~11 ~29 iron_block 0  
fill ~5 ~11 ~30 ~9 ~11 ~30 iron_block 0  
fill ~5 ~11 ~31 ~9 ~11 ~31 iron_block 0  
fill ~5 ~11 ~32 ~9 ~11 ~32 iron_block 0  
fill ~5 ~11 ~33 ~9 ~11 ~33 iron_block 0  
fill ~5 ~11 ~34 ~9 ~11 ~34 iron_block 0  
fill ~10 ~11 ~15 ~14 ~11 ~15 iron_block 0  
fill ~10 ~11 ~16 ~14 ~11 ~16 iron_block 0  
fill ~10 ~11 ~17 ~14 ~11 ~17 iron_block 0  
fill ~10 ~11 ~18 ~14 ~11 ~18 iron_block 0  
fill ~10 ~11 ~19 ~14 ~11 ~19 iron_block 0  
fill ~10 ~11 ~20 ~39 ~11 ~20 wool 12  
fill ~10 ~11 ~21 ~39 ~11 ~21 wool 12  
fill ~10 ~11 ~22 ~39 ~11 ~22 wool 12  
fill ~10 ~11 ~23 ~39 ~11 ~23 wool 12  
fill ~10 ~11 ~24 ~39 ~11 ~24 wool 12  
fill ~10 ~11 ~25 ~44 ~11 ~25 wool 12  
fill ~10 ~11 ~26 ~44 ~11 ~26 wool 12  
fill ~10 ~11 ~27 ~44 ~11 ~27 wool 12  
fill ~10 ~11 ~28 ~44 ~11 ~28 wool 12  
fill ~10 ~11 ~29 ~44 ~11 ~29 wool 12  
fill ~10 ~11 ~30 ~44 ~11 ~30 wool 12  
fill ~10 ~11 ~31 ~44 ~11 ~31 wool 12  
fill ~10 ~11 ~32 ~44 ~11 ~32 wool 12  
fill ~10 ~11 ~33 ~44 ~11 ~33 wool 12  
fill ~10 ~11 ~34 ~44 ~11 ~34 wool 12  
fill ~10 ~11 ~35 ~14 ~11 ~35 iron_block 0  
fill ~10 ~11 ~36 ~14 ~11 ~36 iron_block 0  
fill ~10 ~11 ~37 ~14 ~11 ~37 iron_block 0  
fill ~10 ~11 ~38 ~14 ~11 ~38 iron_block 0  
fill ~10 ~11 ~39 ~14 ~11 ~39 iron_block 0  
fill ~15 ~11 ~10 ~19 ~11 ~10 iron_block 0  
fill ~15 ~11 ~11 ~19 ~11 ~11 iron_block 0  
fill ~15 ~11 ~12 ~19 ~11 ~12 iron_block 0  
fill ~15 ~11 ~13 ~19 ~11 ~13 iron_block 0  
fill ~15 ~11 ~14 ~19 ~11 ~14 iron_block 0  
fill ~15 ~11 ~15 ~39 ~11 ~15 wool 12  
fill ~15 ~11 ~16 ~39 ~11 ~16 wool 12  
fill ~15 ~11 ~17 ~39 ~11 ~17 wool 12  
fill ~15 ~11 ~18 ~39 ~11 ~18 wool 12  
fill ~15 ~11 ~19 ~39 ~11 ~19 wool 12  
fill ~15 ~11 ~35 ~39 ~11 ~35 wool 12  
fill ~15 ~11 ~36 ~39 ~11 ~36 wool 12  
fill ~15 ~11 ~37 ~39 ~11 ~37 wool 12  
fill ~15 ~11 ~38 ~39 ~11 ~38 wool 12  
fill ~15 ~11 ~39 ~39 ~11 ~39 wool 12  
fill ~15 ~11 ~40 ~19 ~11 ~40 iron_block 0  
fill ~15 ~11 ~41 ~19 ~11 ~41 iron_block 0  
fill ~15 ~11 ~42 ~19 ~11 ~42 iron_block 0  
fill ~15 ~11 ~43 ~19 ~11 ~43 iron_block 0  
fill ~15 ~11 ~44 ~19 ~11 ~44 iron_block 0  
fill ~20 ~11 ~5 ~34 ~11 ~5 iron_block 0  
fill ~20 ~11 ~6 ~34 ~11 ~6 iron_block 0  
fill ~20 ~11 ~7 ~34 ~11 ~7 iron_block 0  
fill ~20 ~11 ~8 ~34 ~11 ~8 iron_block 0  
fill ~20 ~11 ~9 ~34 ~11 ~9 iron_block 0  
fill ~20 ~11 ~10 ~34 ~11 ~10 wool 12  
fill ~20 ~11 ~11 ~34 ~11 ~11 wool 12  
fill ~20 ~11 ~12 ~34 ~11 ~12 wool 12  
fill ~20 ~11 ~13 ~34 ~11 ~13 wool 12  
fill ~20 ~11 ~14 ~34 ~11 ~14 wool 12  
fill ~20 ~11 ~40 ~34 ~11 ~40 wool 12  
fill ~20 ~11 ~41 ~34 ~11 ~41 wool 12  
fill ~20 ~11 ~42 ~34 ~11 ~42 wool 12  
fill ~20 ~11 ~43 ~34 ~11 ~43 wool 12  
fill ~20 ~11 ~44 ~34 ~11 ~44 wool 12  
fill ~20 ~11 ~45 ~34 ~11 ~45 iron_block 0  
fill ~20 ~11 ~46 ~34 ~11 ~46 iron_block 0  
fill ~20 ~11 ~47 ~34 ~11 ~47 iron_block 0  
fill ~20 ~11 ~48 ~34 ~11 ~48 iron_block 0  
fill ~20 ~11 ~49 ~34 ~11 ~49 iron_block 0  
fill ~35 ~11 ~10 ~39 ~11 ~10 iron_block 0  
fill ~35 ~11 ~11 ~39 ~11 ~11 iron_block 0  
fill ~35 ~11 ~12 ~39 ~11 ~12 iron_block 0  
fill ~35 ~11 ~13 ~39 ~11 ~13 iron_block 0  
fill ~35 ~11 ~14 ~39 ~11 ~14 iron_block 0  
fill ~35 ~11 ~40 ~39 ~11 ~40 iron_block 0  
fill ~35 ~11 ~41 ~39 ~11 ~41 iron_block 0  
fill ~35 ~11 ~42 ~39 ~11 ~42 iron_block 0  
fill ~35 ~11 ~43 ~39 ~11 ~43 iron_block 0  
fill ~35 ~11 ~44 ~39 ~11 ~44 iron_block 0  
fill ~40 ~11 ~15 ~44 ~11 ~15 iron_block 0  
fill ~40 ~11 ~16 ~44 ~11 ~16 iron_block 0  
fill ~40 ~11 ~17 ~44 ~11 ~17 iron_block 0  
fill ~40 ~11 ~18 ~44 ~11 ~18 iron_block 0  
fill ~40 ~11 ~19 ~44 ~11 ~19 iron_block 0  
fill ~40 ~11 ~20 ~44 ~11 ~20 glowstone 0  
fill ~40 ~11 ~21 ~44 ~11 ~21 glowstone 0  
fill ~40 ~11 ~22 ~44 ~11 ~22 glowstone 0  
fill ~40 ~11 ~23 ~44 ~11 ~23 glowstone 0  
fill ~40 ~11 ~24 ~44 ~11 ~24 glowstone 0  
fill ~40 ~11 ~35 ~44 ~11 ~35 iron_block 0  
fill ~40 ~11 ~36 ~44 ~11 ~36 iron_block 0  
fill ~40 ~11 ~37 ~44 ~11 ~37 iron_block 0  
fill ~40 ~11 ~38 ~44 ~11 ~38 iron_block 0  
fill ~40 ~11 ~39 ~44 ~11 ~39 iron_block 0  
fill ~45 ~11 ~20 ~49 ~11 ~20 iron_block 0  
fill ~45 ~11 ~21 ~49 ~11 ~21 iron_block 0  
fill ~45 ~11 ~22 ~49 ~11 ~22 iron_block 0  
fill ~45 ~11 ~23 ~49 ~11 ~23 iron_block 0  
fill ~45 ~11 ~24 ~49 ~11 ~24 iron_block 0  
fill ~45 ~11 ~25 ~49 ~11 ~25 iron_block 0  
fill ~45 ~11 ~26 ~49 ~11 ~26 iron_block 0  
fill ~45 ~11 ~27 ~49 ~11 ~27 iron_block 0  
fill ~45 ~11 ~28 ~49 ~11 ~28 iron_block 0  
fill ~45 ~11 ~29 ~49 ~11 ~29 iron_block 0  
fill ~45 ~11 ~30 ~49 ~11 ~30 iron_block 0  
fill ~45 ~11 ~31 ~49 ~11 ~31 iron_block 0  
fill ~45 ~11 ~32 ~49 ~11 ~32 iron_block 0  
fill ~45 ~11 ~33 ~49 ~11 ~33 iron_block 0  
fill ~45 ~11 ~34 ~49 ~11 ~34 iron_block 0  
fill ~50 ~11 ~25 ~54 ~11 ~25 gold_block 0  
fill ~50 ~11 ~26 ~54 ~11 ~26 gold_block 0  
fill ~50 ~11 ~27 ~54 ~11 ~27 gold_block 0  
fill ~50 ~11 ~28 ~54 ~11 ~28 gold_block 0  
fill ~50 ~11 ~29 ~54 ~11 ~29 gold_block 0  
fill ~70 ~11 ~25 ~74 ~11 ~25 gold_block 0  
fill ~70 ~11 ~26 ~74 ~11 ~26 gold_block 0  
fill ~70 ~11 ~27 ~74 ~11 ~27 gold_block 0  
fill ~70 ~11 ~28 ~74 ~11 ~28 gold_block 0  
fill ~70 ~11 ~29 ~74 ~11 ~29 gold_block 0  
fill ~5 ~12 ~20 ~9 ~12 ~20 iron_block 0  
fill ~5 ~12 ~21 ~9 ~12 ~21 iron_block 0  
fill ~5 ~12 ~22 ~9 ~12 ~22 iron_block 0  
fill ~5 ~12 ~23 ~9 ~12 ~23 iron_block 0  
fill ~5 ~12 ~24 ~9 ~12 ~24 iron_block 0  
fill ~5 ~12 ~25 ~9 ~12 ~25 iron_block 0  
fill ~5 ~12 ~26 ~9 ~12 ~26 iron_block 0  
fill ~5 ~12 ~27 ~9 ~12 ~27 iron_block 0  
fill ~5 ~12 ~28 ~9 ~12 ~28 iron_block 0  
fill ~5 ~12 ~29 ~9 ~12 ~29 iron_block 0  
fill ~5 ~12 ~30 ~9 ~12 ~30 iron_block 0  
fill ~5 ~12 ~31 ~9 ~12 ~31 iron_block 0  
fill ~5 ~12 ~32 ~9 ~12 ~32 iron_block 0  
fill ~5 ~12 ~33 ~9 ~12 ~33 iron_block 0  
fill ~5 ~12 ~34 ~9 ~12 ~34 iron_block 0  
fill ~10 ~12 ~15 ~14 ~12 ~15 iron_block 0  
fill ~10 ~12 ~16 ~14 ~12 ~16 iron_block 0  
fill ~10 ~12 ~17 ~14 ~12 ~17 iron_block 0  
fill ~10 ~12 ~18 ~14 ~12 ~18 iron_block 0  
fill ~10 ~12 ~19 ~14 ~12 ~19 iron_block 0  
fill ~10 ~12 ~20 ~39 ~12 ~20 wool 12  
fill ~10 ~12 ~21 ~39 ~12 ~21 wool 12  
fill ~10 ~12 ~22 ~39 ~12 ~22 wool 12  
fill ~10 ~12 ~23 ~39 ~12 ~23 wool 12  
fill ~10 ~12 ~24 ~39 ~12 ~24 wool 12  
fill ~10 ~12 ~25 ~44 ~12 ~25 wool 12  
fill ~10 ~12 ~26 ~44 ~12 ~26 wool 12  
fill ~10 ~12 ~27 ~44 ~12 ~27 wool 12  
fill ~10 ~12 ~28 ~44 ~12 ~28 wool 12  
fill ~10 ~12 ~29 ~44 ~12 ~29 wool 12  
fill ~10 ~12 ~30 ~44 ~12 ~30 wool 12  
fill ~10 ~12 ~31 ~44 ~12 ~31 wool 12  
fill ~10 ~12 ~32 ~44 ~12 ~32 wool 12  
fill ~10 ~12 ~33 ~44 ~12 ~33 wool 12  
fill ~10 ~12 ~34 ~44 ~12 ~34 wool 12  
fill ~10 ~12 ~35 ~14 ~12 ~35 iron_block 0  
fill ~10 ~12 ~36 ~14 ~12 ~36 iron_block 0  
fill ~10 ~12 ~37 ~14 ~12 ~37 iron_block 0  
fill ~10 ~12 ~38 ~14 ~12 ~38 iron_block 0  
fill ~10 ~12 ~39 ~14 ~12 ~39 iron_block 0  
fill ~15 ~12 ~10 ~19 ~12 ~10 iron_block 0  
fill ~15 ~12 ~11 ~19 ~12 ~11 iron_block 0  
fill ~15 ~12 ~12 ~19 ~12 ~12 iron_block 0  
fill ~15 ~12 ~13 ~19 ~12 ~13 iron_block 0  
fill ~15 ~12 ~14 ~19 ~12 ~14 iron_block 0  
fill ~15 ~12 ~15 ~39 ~12 ~15 wool 12  
fill ~15 ~12 ~16 ~39 ~12 ~16 wool 12  
fill ~15 ~12 ~17 ~39 ~12 ~17 wool 12  
fill ~15 ~12 ~18 ~39 ~12 ~18 wool 12  
fill ~15 ~12 ~19 ~39 ~12 ~19 wool 12  
fill ~15 ~12 ~35 ~39 ~12 ~35 wool 12  
fill ~15 ~12 ~36 ~39 ~12 ~36 wool 12  
fill ~15 ~12 ~37 ~39 ~12 ~37 wool 12  
fill ~15 ~12 ~38 ~39 ~12 ~38 wool 12  
fill ~15 ~12 ~39 ~39 ~12 ~39 wool 12  
fill ~15 ~12 ~40 ~19 ~12 ~40 iron_block 0  
fill ~15 ~12 ~41 ~19 ~12 ~41 iron_block 0  
fill ~15 ~12 ~42 ~19 ~12 ~42 iron_block 0  
fill ~15 ~12 ~43 ~19 ~12 ~43 iron_block 0  
fill ~15 ~12 ~44 ~19 ~12 ~44 iron_block 0  
fill ~20 ~12 ~5 ~34 ~12 ~5 iron_block 0  
fill ~20 ~12 ~6 ~34 ~12 ~6 iron_block 0  
fill ~20 ~12 ~7 ~34 ~12 ~7 iron_block 0  
fill ~20 ~12 ~8 ~34 ~12 ~8 iron_block 0  
fill ~20 ~12 ~9 ~34 ~12 ~9 iron_block 0  
fill ~20 ~12 ~10 ~34 ~12 ~10 wool 12  
fill ~20 ~12 ~11 ~34 ~12 ~11 wool 12  
fill ~20 ~12 ~12 ~34 ~12 ~12 wool 12  
fill ~20 ~12 ~13 ~34 ~12 ~13 wool 12  
fill ~20 ~12 ~14 ~34 ~12 ~14 wool 12  
fill ~20 ~12 ~40 ~34 ~12 ~40 wool 12  
fill ~20 ~12 ~41 ~34 ~12 ~41 wool 12  
fill ~20 ~12 ~42 ~34 ~12 ~42 wool 12  
fill ~20 ~12 ~43 ~34 ~12 ~43 wool 12  
fill ~20 ~12 ~44 ~34 ~12 ~44 wool 12  
fill ~20 ~12 ~45 ~34 ~12 ~45 iron_block 0  
fill ~20 ~12 ~46 ~34 ~12 ~46 iron_block 0  
fill ~20 ~12 ~47 ~34 ~12 ~47 iron_block 0  
fill ~20 ~12 ~48 ~34 ~12 ~48 iron_block 0  
fill ~20 ~12 ~49 ~34 ~12 ~49 iron_block 0  
fill ~35 ~12 ~10 ~39 ~12 ~10 iron_block 0  
fill ~35 ~12 ~11 ~39 ~12 ~11 iron_block 0  
fill ~35 ~12 ~12 ~39 ~12 ~12 iron_block 0  
fill ~35 ~12 ~13 ~39 ~12 ~13 iron_block 0  
fill ~35 ~12 ~14 ~39 ~12 ~14 iron_block 0  
fill ~35 ~12 ~40 ~39 ~12 ~40 iron_block 0  
fill ~35 ~12 ~41 ~39 ~12 ~41 iron_block 0  
fill ~35 ~12 ~42 ~39 ~12 ~42 iron_block 0  
fill ~35 ~12 ~43 ~39 ~12 ~43 iron_block 0  
fill ~35 ~12 ~44 ~39 ~12 ~44 iron_block 0  
fill ~40 ~12 ~15 ~44 ~12 ~15 iron_block 0  
fill ~40 ~12 ~16 ~44 ~12 ~16 iron_block 0  
fill ~40 ~12 ~17 ~44 ~12 ~17 iron_block 0  
fill ~40 ~12 ~18 ~44 ~12 ~18 iron_block 0  
fill ~40 ~12 ~19 ~44 ~12 ~19 iron_block 0  
fill ~40 ~12 ~20 ~44 ~12 ~20 glowstone 0  
fill ~40 ~12 ~21 ~44 ~12 ~21 glowstone 0  
fill ~40 ~12 ~22 ~44 ~12 ~22 glowstone 0  
fill ~40 ~12 ~23 ~44 ~12 ~23 glowstone 0  
fill ~40 ~12 ~24 ~44 ~12 ~24 glowstone 0  
fill ~40 ~12 ~35 ~44 ~12 ~35 iron_block 0  
fill ~40 ~12 ~36 ~44 ~12 ~36 iron_block 0  
fill ~40 ~12 ~37 ~44 ~12 ~37 iron_block 0  
fill ~40 ~12 ~38 ~44 ~12 ~38 iron_block 0  
fill ~40 ~12 ~39 ~44 ~12 ~39 iron_block 0  
fill ~45 ~12 ~20 ~49 ~12 ~20 iron_block 0  
fill ~45 ~12 ~21 ~49 ~12 ~21 iron_block 0  
fill ~45 ~12 ~22 ~49 ~12 ~22 iron_block 0  
fill ~45 ~12 ~23 ~49 ~12 ~23 iron_block 0  
fill ~45 ~12 ~24 ~49 ~12 ~24 iron_block 0  
fill ~45 ~12 ~25 ~49 ~12 ~25 iron_block 0  
fill ~45 ~12 ~26 ~49 ~12 ~26 iron_block 0  
fill ~45 ~12 ~27 ~49 ~12 ~27 iron_block 0  
fill ~45 ~12 ~28 ~49 ~12 ~28 iron_block 0  
fill ~45 ~12 ~29 ~49 ~12 ~29 iron_block 0  
fill ~45 ~12 ~30 ~49 ~12 ~30 iron_block 0  
fill ~45 ~12 ~31 ~49 ~12 ~31 iron_block 0  
fill ~45 ~12 ~32 ~49 ~12 ~32 iron_block 0  
fill ~45 ~12 ~33 ~49 ~12 ~33 iron_block 0  
fill ~45 ~12 ~34 ~49 ~12 ~34 iron_block 0  
fill ~50 ~12 ~25 ~54 ~12 ~25 gold_block 0  
fill ~50 ~12 ~26 ~54 ~12 ~26 gold_block 0  
fill ~50 ~12 ~27 ~54 ~12 ~27 gold_block 0  
fill ~50 ~12 ~28 ~54 ~12 ~28 gold_block 0  
fill ~50 ~12 ~29 ~54 ~12 ~29 gold_block 0  
fill ~70 ~12 ~25 ~74 ~12 ~25 gold_block 0  
fill ~70 ~12 ~26 ~74 ~12 ~26 gold_block 0  
fill ~70 ~12 ~27 ~74 ~12 ~27 gold_block 0  
fill ~70 ~12 ~28 ~74 ~12 ~28 gold_block 0  
fill ~70 ~12 ~29 ~74 ~12 ~29 gold_block 0  
fill ~5 ~13 ~20 ~9 ~13 ~20 iron_block 0  
fill ~5 ~13 ~21 ~9 ~13 ~21 iron_block 0  
fill ~5 ~13 ~22 ~9 ~13 ~22 iron_block 0  
fill ~5 ~13 ~23 ~9 ~13 ~23 iron_block 0  
fill ~5 ~13 ~24 ~9 ~13 ~24 iron_block 0  
fill ~5 ~13 ~25 ~9 ~13 ~25 iron_block 0  
fill ~5 ~13 ~26 ~9 ~13 ~26 iron_block 0  
fill ~5 ~13 ~27 ~9 ~13 ~27 iron_block 0  
fill ~5 ~13 ~28 ~9 ~13 ~28 iron_block 0  
fill ~5 ~13 ~29 ~9 ~13 ~29 iron_block 0  
fill ~5 ~13 ~30 ~9 ~13 ~30 iron_block 0  
fill ~5 ~13 ~31 ~9 ~13 ~31 iron_block 0  
fill ~5 ~13 ~32 ~9 ~13 ~32 iron_block 0  
fill ~5 ~13 ~33 ~9 ~13 ~33 iron_block 0  
fill ~5 ~13 ~34 ~9 ~13 ~34 iron_block 0  
fill ~10 ~13 ~15 ~14 ~13 ~15 iron_block 0  
fill ~10 ~13 ~16 ~14 ~13 ~16 iron_block 0  
fill ~10 ~13 ~17 ~14 ~13 ~17 iron_block 0  
fill ~10 ~13 ~18 ~14 ~13 ~18 iron_block 0  
fill ~10 ~13 ~19 ~14 ~13 ~19 iron_block 0  
fill ~10 ~13 ~20 ~39 ~13 ~20 wool 12  
fill ~10 ~13 ~21 ~39 ~13 ~21 wool 12  
fill ~10 ~13 ~22 ~39 ~13 ~22 wool 12  
fill ~10 ~13 ~23 ~39 ~13 ~23 wool 12  
fill ~10 ~13 ~24 ~39 ~13 ~24 wool 12  
fill ~10 ~13 ~25 ~44 ~13 ~25 wool 12  
fill ~10 ~13 ~26 ~44 ~13 ~26 wool 12  
fill ~10 ~13 ~27 ~44 ~13 ~27 wool 12  
fill ~10 ~13 ~28 ~44 ~13 ~28 wool 12  
fill ~10 ~13 ~29 ~44 ~13 ~29 wool 12  
fill ~10 ~13 ~30 ~44 ~13 ~30 wool 12  
fill ~10 ~13 ~31 ~44 ~13 ~31 wool 12  
fill ~10 ~13 ~32 ~44 ~13 ~32 wool 12  
fill ~10 ~13 ~33 ~44 ~13 ~33 wool 12  
fill ~10 ~13 ~34 ~44 ~13 ~34 wool 12  
fill ~10 ~13 ~35 ~14 ~13 ~35 iron_block 0  
fill ~10 ~13 ~36 ~14 ~13 ~36 iron_block 0  
fill ~10 ~13 ~37 ~14 ~13 ~37 iron_block 0  
fill ~10 ~13 ~38 ~14 ~13 ~38 iron_block 0  
fill ~10 ~13 ~39 ~14 ~13 ~39 iron_block 0  
fill ~15 ~13 ~10 ~19 ~13 ~10 iron_block 0  
fill ~15 ~13 ~11 ~19 ~13 ~11 iron_block 0  
fill ~15 ~13 ~12 ~19 ~13 ~12 iron_block 0  
fill ~15 ~13 ~13 ~19 ~13 ~13 iron_block 0  
fill ~15 ~13 ~14 ~19 ~13 ~14 iron_block 0  
fill ~15 ~13 ~15 ~39 ~13 ~15 wool 12  
fill ~15 ~13 ~16 ~39 ~13 ~16 wool 12   
fill ~15 ~13 ~17 ~39 ~13 ~17 wool 12  
fill ~15 ~13 ~18 ~39 ~13 ~18 wool 12  
fill ~15 ~13 ~19 ~39 ~13 ~19 wool 12  
fill ~15 ~13 ~35 ~39 ~13 ~35 wool 12  
fill ~15 ~13 ~36 ~39 ~13 ~36 wool 12  
fill ~15 ~13 ~37 ~39 ~13 ~37 wool 12  
fill ~15 ~13 ~38 ~39 ~13 ~38 wool 12  
fill ~15 ~13 ~39 ~39 ~13 ~39 wool 12  
fill ~15 ~13 ~40 ~19 ~13 ~40 iron_block 0  
fill ~15 ~13 ~41 ~19 ~13 ~41 iron_block 0  
fill ~15 ~13 ~42 ~19 ~13 ~42 iron_block 0  
fill ~15 ~13 ~43 ~19 ~13 ~43 iron_block 0  
fill ~15 ~13 ~44 ~19 ~13 ~44 iron_block 0  
fill ~20 ~13 ~5 ~34 ~13 ~5 iron_block 0  
fill ~20 ~13 ~6 ~34 ~13 ~6 iron_block 0  
fill ~20 ~13 ~7 ~34 ~13 ~7 iron_block 0  
fill ~20 ~13 ~8 ~34 ~13 ~8 iron_block 0  
fill ~20 ~13 ~9 ~34 ~13 ~9 iron_block 0  
fill ~20 ~13 ~10 ~34 ~13 ~10 wool 12  
fill ~20 ~13 ~11 ~34 ~13 ~11 wool 12  
fill ~20 ~13 ~12 ~34 ~13 ~12 wool 12  
fill ~20 ~13 ~13 ~34 ~13 ~13 wool 12  
fill ~20 ~13 ~14 ~34 ~13 ~14 wool 12  
fill ~20 ~13 ~40 ~34 ~13 ~40 wool 12  
fill ~20 ~13 ~41 ~34 ~13 ~41 wool 12  
fill ~20 ~13 ~42 ~34 ~13 ~42 wool 12  
fill ~20 ~13 ~43 ~34 ~13 ~43 wool 12  
fill ~20 ~13 ~44 ~34 ~13 ~44 wool 12  
fill ~20 ~13 ~45 ~34 ~13 ~45 iron_block 0  
fill ~20 ~13 ~46 ~34 ~13 ~46 iron_block 0  
fill ~20 ~13 ~47 ~34 ~13 ~47 iron_block 0  
fill ~20 ~13 ~48 ~34 ~13 ~48 iron_block 0  
fill ~20 ~13 ~49 ~34 ~13 ~49 iron_block 0  
fill ~35 ~13 ~10 ~39 ~13 ~10 iron_block 0  
fill ~35 ~13 ~11 ~39 ~13 ~11 iron_block 0  
fill ~35 ~13 ~12 ~39 ~13 ~12 iron_block 0  
fill ~35 ~13 ~13 ~39 ~13 ~13 iron_block 0  
fill ~35 ~13 ~14 ~39 ~13 ~14 iron_block 0  
fill ~35 ~13 ~40 ~39 ~13 ~40 iron_block 0  
fill ~35 ~13 ~41 ~39 ~13 ~41 iron_block 0  
fill ~35 ~13 ~42 ~39 ~13 ~42 iron_block 0  
fill ~35 ~13 ~43 ~39 ~13 ~43 iron_block 0  
fill ~35 ~13 ~44 ~39 ~13 ~44 iron_block 0  
fill ~40 ~13 ~15 ~44 ~13 ~15 iron_block 0  
fill ~40 ~13 ~16 ~44 ~13 ~16 iron_block 0  
fill ~40 ~13 ~17 ~44 ~13 ~17 iron_block 0  
fill ~40 ~13 ~18 ~44 ~13 ~18 iron_block 0  
fill ~40 ~13 ~19 ~44 ~13 ~19 iron_block 0  
fill ~40 ~13 ~20 ~44 ~13 ~20 glowstone 0  
fill ~40 ~13 ~21 ~44 ~13 ~21 glowstone 0  
fill ~40 ~13 ~22 ~44 ~13 ~22 glowstone 0  
fill ~40 ~13 ~23 ~44 ~13 ~23 glowstone 0  
fill ~40 ~13 ~24 ~44 ~13 ~24 glowstone 0  
fill ~40 ~13 ~35 ~44 ~13 ~35 iron_block 0  
fill ~40 ~13 ~36 ~44 ~13 ~36 iron_block 0  
fill ~40 ~13 ~37 ~44 ~13 ~37 iron_block 0  
fill ~40 ~13 ~38 ~44 ~13 ~38 iron_block 0  
fill ~40 ~13 ~39 ~44 ~13 ~39 iron_block 0  
fill ~45 ~13 ~20 ~49 ~13 ~20 iron_block 0  
fill ~45 ~13 ~21 ~49 ~13 ~21 iron_block 0  
fill ~45 ~13 ~22 ~49 ~13 ~22 iron_block 0  
fill ~45 ~13 ~23 ~49 ~13 ~23 iron_block 0  
fill ~45 ~13 ~24 ~49 ~13 ~24 iron_block 0  
fill ~45 ~13 ~25 ~49 ~13 ~25 iron_block 0  
fill ~45 ~13 ~26 ~49 ~13 ~26 iron_block 0  
fill ~45 ~13 ~27 ~49 ~13 ~27 iron_block 0  
fill ~45 ~13 ~28 ~49 ~13 ~28 iron_block 0  
fill ~45 ~13 ~29 ~49 ~13 ~29 iron_block 0  
fill ~45 ~13 ~30 ~49 ~13 ~30 iron_block 0  
fill ~45 ~13 ~31 ~49 ~13 ~31 iron_block 0  
fill ~45 ~13 ~32 ~49 ~13 ~32 iron_block 0  
fill ~45 ~13 ~33 ~49 ~13 ~33 iron_block 0  
fill ~45 ~13 ~34 ~49 ~13 ~34 iron_block 0  
fill ~50 ~13 ~25 ~54 ~13 ~25 gold_block 0  
fill ~50 ~13 ~26 ~54 ~13 ~26 gold_block 0  
fill ~50 ~13 ~27 ~54 ~13 ~27 gold_block 0  
fill ~50 ~13 ~28 ~54 ~13 ~28 gold_block 0  
fill ~50 ~13 ~29 ~54 ~13 ~29 gold_block 0  
fill ~70 ~13 ~25 ~74 ~13 ~25 gold_block 0  
fill ~70 ~13 ~26 ~74 ~13 ~26 gold_block 0  
fill ~70 ~13 ~27 ~74 ~13 ~27 gold_block 0  
fill ~70 ~13 ~28 ~74 ~13 ~28 gold_block 0  
fill ~70 ~13 ~29 ~74 ~13 ~29 gold_block 0  
fill ~5 ~14 ~20 ~9 ~14 ~20 iron_block 0  
fill ~5 ~14 ~21 ~9 ~14 ~21 iron_block 0  
fill ~5 ~14 ~22 ~9 ~14 ~22 iron_block 0  
fill ~5 ~14 ~23 ~9 ~14 ~23 iron_block 0  
fill ~5 ~14 ~24 ~9 ~14 ~24 iron_block 0  
fill ~5 ~14 ~25 ~9 ~14 ~25 iron_block 0  
fill ~5 ~14 ~26 ~9 ~14 ~26 iron_block 0  
fill ~5 ~14 ~27 ~9 ~14 ~27 iron_block 0  
fill ~5 ~14 ~28 ~9 ~14 ~28 iron_block 0  
fill ~5 ~14 ~29 ~9 ~14 ~29 iron_block 0  
fill ~5 ~14 ~30 ~9 ~14 ~30 iron_block 0  
fill ~5 ~14 ~31 ~9 ~14 ~31 iron_block 0  
fill ~5 ~14 ~32 ~9 ~14 ~32 iron_block 0  
fill ~5 ~14 ~33 ~9 ~14 ~33 iron_block 0  
fill ~5 ~14 ~34 ~9 ~14 ~34 iron_block 0  
fill ~10 ~14 ~15 ~14 ~14 ~15 iron_block 0  
fill ~10 ~14 ~16 ~14 ~14 ~16 iron_block 0  
fill ~10 ~14 ~17 ~14 ~14 ~17 iron_block 0  
fill ~10 ~14 ~18 ~14 ~14 ~18 iron_block 0  
fill ~10 ~14 ~19 ~14 ~14 ~19 iron_block 0  
fill ~10 ~14 ~20 ~39 ~14 ~20 wool 12  
fill ~10 ~14 ~21 ~39 ~14 ~21 wool 12  
fill ~10 ~14 ~22 ~39 ~14 ~22 wool 12  
fill ~10 ~14 ~23 ~39 ~14 ~23 wool 12  
fill ~10 ~14 ~24 ~39 ~14 ~24 wool 12  
fill ~10 ~14 ~25 ~44 ~14 ~25 wool 12  
fill ~10 ~14 ~26 ~44 ~14 ~26 wool 12  
fill ~10 ~14 ~27 ~44 ~14 ~27 wool 12  
fill ~10 ~14 ~28 ~44 ~14 ~28 wool 12  
fill ~10 ~14 ~29 ~44 ~14 ~29 wool 12  
fill ~10 ~14 ~30 ~44 ~14 ~30 wool 12  
fill ~10 ~14 ~31 ~44 ~14 ~31 wool 12  
fill ~10 ~14 ~32 ~44 ~14 ~32 wool 12  
fill ~10 ~14 ~33 ~44 ~14 ~33 wool 12  
fill ~10 ~14 ~34 ~44 ~14 ~34 wool 12  
fill ~10 ~14 ~35 ~14 ~14 ~35 iron_block 0  
fill ~10 ~14 ~36 ~14 ~14 ~36 iron_block 0  
fill ~10 ~14 ~37 ~14 ~14 ~37 iron_block 0  
fill ~10 ~14 ~38 ~14 ~14 ~38 iron_block 0  
fill ~10 ~14 ~39 ~14 ~14 ~39 iron_block 0  
fill ~15 ~14 ~10 ~19 ~14 ~10 iron_block 0  
fill ~15 ~14 ~11 ~19 ~14 ~11 iron_block 0  
fill ~15 ~14 ~12 ~19 ~14 ~12 iron_block 0  
fill ~15 ~14 ~13 ~19 ~14 ~13 iron_block 0  
fill ~15 ~14 ~14 ~19 ~14 ~14 iron_block 0  
fill ~15 ~14 ~15 ~39 ~14 ~15 wool 12  
fill ~15 ~14 ~16 ~39 ~14 ~16 wool 12  
fill ~15 ~14 ~17 ~39 ~14 ~17 wool 12  
fill ~15 ~14 ~18 ~39 ~14 ~18 wool 12  
fill ~15 ~14 ~19 ~39 ~14 ~19 wool 12  
fill ~15 ~14 ~35 ~39 ~14 ~35 wool 12  
fill ~15 ~14 ~36 ~39 ~14 ~36 wool 12  
fill ~15 ~14 ~37 ~39 ~14 ~37 wool 12  
fill ~15 ~14 ~38 ~39 ~14 ~38 wool 12  
fill ~15 ~14 ~39 ~39 ~14 ~39 wool 12  
fill ~15 ~14 ~40 ~19 ~14 ~40 iron_block 0  
fill ~15 ~14 ~41 ~19 ~14 ~41 iron_block 0  
fill ~15 ~14 ~42 ~19 ~14 ~42 iron_block 0  
fill ~15 ~14 ~43 ~19 ~14 ~43 iron_block 0  
fill ~15 ~14 ~44 ~19 ~14 ~44 iron_block 0  
fill ~20 ~14 ~5 ~34 ~14 ~5 iron_block 0  
fill ~20 ~14 ~6 ~34 ~14 ~6 iron_block 0  
fill ~20 ~14 ~7 ~34 ~14 ~7 iron_block 0  
fill ~20 ~14 ~8 ~34 ~14 ~8 iron_block 0  
fill ~20 ~14 ~9 ~34 ~14 ~9 iron_block 0  
fill ~20 ~14 ~10 ~34 ~14 ~10 wool 12  
fill ~20 ~14 ~11 ~34 ~14 ~11 wool 12  
fill ~20 ~14 ~12 ~34 ~14 ~12 wool 12  
fill ~20 ~14 ~13 ~34 ~14 ~13 wool 12  
fill ~20 ~14 ~14 ~34 ~14 ~14 wool 12  
fill ~20 ~14 ~40 ~34 ~14 ~40 wool 12  
fill ~20 ~14 ~41 ~34 ~14 ~41 wool 12  
fill ~20 ~14 ~42 ~34 ~14 ~42 wool 12  
fill ~20 ~14 ~43 ~34 ~14 ~43 wool 12  
fill ~20 ~14 ~44 ~34 ~14 ~44 wool 12  
fill ~20 ~14 ~45 ~34 ~14 ~45 iron_block 0  
fill ~20 ~14 ~46 ~34 ~14 ~46 iron_block 0  
fill ~20 ~14 ~47 ~34 ~14 ~47 iron_block 0  
fill ~20 ~14 ~48 ~34 ~14 ~48 iron_block 0  
fill ~20 ~14 ~49 ~34 ~14 ~49 iron_block 0  
fill ~35 ~14 ~10 ~39 ~14 ~10 iron_block 0  
fill ~35 ~14 ~11 ~39 ~14 ~11 iron_block 0  
fill ~35 ~14 ~12 ~39 ~14 ~12 iron_block 0  
fill ~35 ~14 ~13 ~39 ~14 ~13 iron_block 0  
fill ~35 ~14 ~14 ~39 ~14 ~14 iron_block 0  
fill ~35 ~14 ~40 ~39 ~14 ~40 iron_block 0  
fill ~35 ~14 ~41 ~39 ~14 ~41 iron_block 0  
fill ~35 ~14 ~42 ~39 ~14 ~42 iron_block 0  
fill ~35 ~14 ~43 ~39 ~14 ~43 iron_block 0  
fill ~35 ~14 ~44 ~39 ~14 ~44 iron_block 0  
fill ~40 ~14 ~15 ~44 ~14 ~15 iron_block 0  
fill ~40 ~14 ~16 ~44 ~14 ~16 iron_block 0  
fill ~40 ~14 ~17 ~44 ~14 ~17 iron_block 0  
fill ~40 ~14 ~18 ~44 ~14 ~18 iron_block 0  
fill ~40 ~14 ~19 ~44 ~14 ~19 iron_block 0  
fill ~40 ~14 ~20 ~44 ~14 ~20 glowstone 0  
fill ~40 ~14 ~21 ~44 ~14 ~21 glowstone 0  
fill ~40 ~14 ~22 ~44 ~14 ~22 glowstone 0  
fill ~40 ~14 ~23 ~44 ~14 ~23 glowstone 0  
fill ~40 ~14 ~24 ~44 ~14 ~24 glowstone 0  
fill ~40 ~14 ~35 ~44 ~14 ~35 iron_block 0  
fill ~40 ~14 ~36 ~44 ~14 ~36 iron_block 0  
fill ~40 ~14 ~37 ~44 ~14 ~37 iron_block 0  
fill ~40 ~14 ~38 ~44 ~14 ~38 iron_block 0  
fill ~40 ~14 ~39 ~44 ~14 ~39 iron_block 0  
fill ~45 ~14 ~20 ~49 ~14 ~20 iron_block 0  
fill ~45 ~14 ~21 ~49 ~14 ~21 iron_block 0  
fill ~45 ~14 ~22 ~49 ~14 ~22 iron_block 0  
fill ~45 ~14 ~23 ~49 ~14 ~23 iron_block 0  
fill ~45 ~14 ~24 ~49 ~14 ~24 iron_block 0  
fill ~45 ~14 ~25 ~49 ~14 ~25 iron_block 0  
fill ~45 ~14 ~26 ~49 ~14 ~26 iron_block 0  
fill ~45 ~14 ~27 ~49 ~14 ~27 iron_block 0  
fill ~45 ~14 ~28 ~49 ~14 ~28 iron_block 0  
fill ~45 ~14 ~29 ~49 ~14 ~29 iron_block 0  
fill ~45 ~14 ~30 ~49 ~14 ~30 iron_block 0  
fill ~45 ~14 ~31 ~49 ~14 ~31 iron_block 0  
fill ~45 ~14 ~32 ~49 ~14 ~32 iron_block 0  
fill ~45 ~14 ~33 ~49 ~14 ~33 iron_block 0  
fill ~45 ~14 ~34 ~49 ~14 ~34 iron_block 0  
fill ~50 ~14 ~25 ~54 ~14 ~25 gold_block 0  
fill ~50 ~14 ~26 ~54 ~14 ~26 gold_block 0  
fill ~50 ~14 ~27 ~54 ~14 ~27 gold_block 0  
fill ~50 ~14 ~28 ~54 ~14 ~28 gold_block 0  
fill ~50 ~14 ~29 ~54 ~14 ~29 gold_block 0  
fill ~70 ~14 ~25 ~74 ~14 ~25 gold_block 0  
fill ~70 ~14 ~26 ~74 ~14 ~26 gold_block 0  
fill ~70 ~14 ~27 ~74 ~14 ~27 gold_block 0  
fill ~70 ~14 ~28 ~74 ~14 ~28 gold_block 0  
fill ~70 ~14 ~29 ~74 ~14 ~29 gold_block 0  
fill ~5 ~15 ~20 ~9 ~15 ~20 iron_block 0  
fill ~5 ~15 ~21 ~9 ~15 ~21 iron_block 0  
fill ~5 ~15 ~22 ~9 ~15 ~22 iron_block 0  
fill ~5 ~15 ~23 ~9 ~15 ~23 iron_block 0  
fill ~5 ~15 ~24 ~9 ~15 ~24 iron_block 0  
fill ~5 ~15 ~25 ~9 ~15 ~25 iron_block 0  
fill ~5 ~15 ~26 ~9 ~15 ~26 iron_block 0  
fill ~5 ~15 ~27 ~9 ~15 ~27 iron_block 0  
fill ~5 ~15 ~28 ~9 ~15 ~28 iron_block 0  
fill ~5 ~15 ~29 ~9 ~15 ~29 iron_block 0  
fill ~5 ~15 ~30 ~9 ~15 ~30 iron_block 0  
fill ~5 ~15 ~31 ~9 ~15 ~31 iron_block 0  
fill ~5 ~15 ~32 ~9 ~15 ~32 iron_block 0  
fill ~5 ~15 ~33 ~9 ~15 ~33 iron_block 0  
fill ~5 ~15 ~34 ~9 ~15 ~34 iron_block 0  
fill ~10 ~15 ~15 ~14 ~15 ~15 iron_block 0  
fill ~10 ~15 ~16 ~14 ~15 ~16 iron_block 0  
fill ~10 ~15 ~17 ~14 ~15 ~17 iron_block 0  
fill ~10 ~15 ~18 ~14 ~15 ~18 iron_block 0  
fill ~10 ~15 ~19 ~14 ~15 ~19 iron_block 0  
fill ~10 ~15 ~20 ~44 ~15 ~20 wool 12  
fill ~10 ~15 ~21 ~44 ~15 ~21 wool 12  
fill ~10 ~15 ~22 ~44 ~15 ~22 wool 12  
fill ~10 ~15 ~23 ~44 ~15 ~23 wool 12  
fill ~10 ~15 ~24 ~44 ~15 ~24 wool 12  
fill ~10 ~15 ~25 ~44 ~15 ~25 wool 12  
fill ~10 ~15 ~26 ~44 ~15 ~26 wool 12  
fill ~10 ~15 ~27 ~44 ~15 ~27 wool 12  
fill ~10 ~15 ~28 ~44 ~15 ~28 wool 12  
fill ~10 ~15 ~29 ~44 ~15 ~29 wool 12  
fill ~10 ~15 ~30 ~44 ~15 ~30 wool 12  
fill ~10 ~15 ~31 ~44 ~15 ~31 wool 12  
fill ~10 ~15 ~32 ~44 ~15 ~32 wool 12  
fill ~10 ~15 ~33 ~44 ~15 ~33 wool 12  
fill ~10 ~15 ~34 ~44 ~15 ~34 wool 12  
fill ~10 ~15 ~35 ~14 ~15 ~35 iron_block 0  
fill ~10 ~15 ~36 ~14 ~15 ~36 iron_block 0  
fill ~10 ~15 ~37 ~14 ~15 ~37 iron_block 0  
fill ~10 ~15 ~38 ~14 ~15 ~38 iron_block 0  
fill ~10 ~15 ~39 ~14 ~15 ~39 iron_block 0  
fill ~15 ~15 ~10 ~19 ~15 ~10 iron_block 0  
fill ~15 ~15 ~11 ~19 ~15 ~11 iron_block 0  
fill ~15 ~15 ~12 ~19 ~15 ~12 iron_block 0  
fill ~15 ~15 ~13 ~19 ~15 ~13 iron_block 0  
fill ~15 ~15 ~14 ~19 ~15 ~14 iron_block 0  
fill ~15 ~15 ~15 ~39 ~15 ~15 wool 12  
fill ~15 ~15 ~16 ~39 ~15 ~16 wool 12  
fill ~15 ~15 ~17 ~39 ~15 ~17 wool 12  
fill ~15 ~15 ~18 ~39 ~15 ~18 wool 12  
fill ~15 ~15 ~19 ~39 ~15 ~19 wool 12  
fill ~15 ~15 ~35 ~39 ~15 ~35 wool 12  
fill ~15 ~15 ~36 ~39 ~15 ~36 wool 12  
fill ~15 ~15 ~37 ~39 ~15 ~37 wool 12  
fill ~15 ~15 ~38 ~39 ~15 ~38 wool 12  
fill ~15 ~15 ~39 ~39 ~15 ~39 wool 12  
fill ~15 ~15 ~40 ~19 ~15 ~40 iron_block 0  
fill ~15 ~15 ~41 ~19 ~15 ~41 iron_block 0  
fill ~15 ~15 ~42 ~19 ~15 ~42 iron_block 0  
fill ~15 ~15 ~43 ~19 ~15 ~43 iron_block 0  
fill ~15 ~15 ~44 ~19 ~15 ~44 iron_block 0  
fill ~20 ~15 ~5 ~34 ~15 ~5 iron_block 0  
fill ~20 ~15 ~6 ~34 ~15 ~6 iron_block 0  
fill ~20 ~15 ~7 ~34 ~15 ~7 iron_block 0  
fill ~20 ~15 ~8 ~34 ~15 ~8 iron_block 0  
fill ~20 ~15 ~9 ~34 ~15 ~9 iron_block 0  
fill ~20 ~15 ~10 ~34 ~15 ~10 wool 12  
fill ~20 ~15 ~11 ~34 ~15 ~11 wool 12  
fill ~20 ~15 ~12 ~34 ~15 ~12 wool 12  
fill ~20 ~15 ~13 ~34 ~15 ~13 wool 12  
fill ~20 ~15 ~14 ~34 ~15 ~14 wool 12  
fill ~20 ~15 ~40 ~34 ~15 ~40 wool 12  
fill ~20 ~15 ~41 ~34 ~15 ~41 wool 12  
fill ~20 ~15 ~42 ~34 ~15 ~42 wool 12  
fill ~20 ~15 ~43 ~34 ~15 ~43 wool 12  
fill ~20 ~15 ~44 ~34 ~15 ~44 wool 12  
fill ~20 ~15 ~45 ~34 ~15 ~45 iron_block 0  
fill ~20 ~15 ~46 ~34 ~15 ~46 iron_block 0  
fill ~20 ~15 ~47 ~34 ~15 ~47 iron_block 0  
fill ~20 ~15 ~48 ~34 ~15 ~48 iron_block 0  
fill ~20 ~15 ~49 ~34 ~15 ~49 iron_block 0  
fill ~35 ~15 ~10 ~39 ~15 ~10 iron_block 0  
fill ~35 ~15 ~11 ~39 ~15 ~11 iron_block 0  
fill ~35 ~15 ~12 ~39 ~15 ~12 iron_block 0  
fill ~35 ~15 ~13 ~39 ~15 ~13 iron_block 0  
fill ~35 ~15 ~14 ~39 ~15 ~14 iron_block 0  
fill ~35 ~15 ~40 ~39 ~15 ~40 iron_block 0  
fill ~35 ~15 ~41 ~39 ~15 ~41 iron_block 0  
fill ~35 ~15 ~42 ~39 ~15 ~42 iron_block 0  
fill ~35 ~15 ~43 ~39 ~15 ~43 iron_block 0  
fill ~35 ~15 ~44 ~39 ~15 ~44 iron_block 0  
fill ~40 ~15 ~15 ~44 ~15 ~15 iron_block 0  
fill ~40 ~15 ~16 ~44 ~15 ~16 iron_block 0  
fill ~40 ~15 ~17 ~44 ~15 ~17 iron_block 0  
fill ~40 ~15 ~18 ~44 ~15 ~18 iron_block 0  
fill ~40 ~15 ~19 ~44 ~15 ~19 iron_block 0  
fill ~40 ~15 ~35 ~44 ~15 ~35 iron_block 0  
fill ~40 ~15 ~36 ~44 ~15 ~36 iron_block 0  
fill ~40 ~15 ~37 ~44 ~15 ~37 iron_block 0  
fill ~40 ~15 ~38 ~44 ~15 ~38 iron_block 0  
fill ~40 ~15 ~39 ~44 ~15 ~39 iron_block 0  
fill ~45 ~15 ~20 ~49 ~15 ~20 iron_block 0  
fill ~45 ~15 ~21 ~49 ~15 ~21 iron_block 0  
fill ~45 ~15 ~22 ~49 ~15 ~22 iron_block 0  
fill ~45 ~15 ~23 ~49 ~15 ~23 iron_block 0  
fill ~45 ~15 ~24 ~49 ~15 ~24 iron_block 0  
fill ~45 ~15 ~25 ~49 ~15 ~25 iron_block 0  
fill ~45 ~15 ~26 ~49 ~15 ~26 iron_block 0  
fill ~45 ~15 ~27 ~49 ~15 ~27 iron_block 0  
fill ~45 ~15 ~28 ~49 ~15 ~28 iron_block 0  
fill ~45 ~15 ~29 ~49 ~15 ~29 iron_block 0  
fill ~45 ~15 ~30 ~49 ~15 ~30 iron_block 0  
fill ~45 ~15 ~31 ~49 ~15 ~31 iron_block 0  
fill ~45 ~15 ~32 ~49 ~15 ~32 iron_block 0  
fill ~45 ~15 ~33 ~49 ~15 ~33 iron_block 0  
fill ~45 ~15 ~34 ~49 ~15 ~34 iron_block 0  
fill ~70 ~15 ~25 ~74 ~15 ~25 gold_block 0  
fill ~70 ~15 ~26 ~74 ~15 ~26 gold_block 0  
fill ~70 ~15 ~27 ~74 ~15 ~27 gold_block 0  
fill ~70 ~15 ~28 ~74 ~15 ~28 gold_block 0  
fill ~70 ~15 ~29 ~74 ~15 ~29 gold_block 0  
fill ~5 ~16 ~20 ~9 ~16 ~20 iron_block 0  
fill ~5 ~16 ~21 ~9 ~16 ~21 iron_block 0  
fill ~5 ~16 ~22 ~9 ~16 ~22 iron_block 0  
fill ~5 ~16 ~23 ~9 ~16 ~23 iron_block 0  
fill ~5 ~16 ~24 ~9 ~16 ~24 iron_block 0  
fill ~5 ~16 ~25 ~9 ~16 ~25 iron_block 0  
fill ~5 ~16 ~26 ~9 ~16 ~26 iron_block 0  
fill ~5 ~16 ~27 ~9 ~16 ~27 iron_block 0  
fill ~5 ~16 ~28 ~9 ~16 ~28 iron_block 0  
fill ~5 ~16 ~29 ~9 ~16 ~29 iron_block 0  
fill ~5 ~16 ~30 ~9 ~16 ~30 iron_block 0  
fill ~5 ~16 ~31 ~9 ~16 ~31 iron_block 0  
fill ~5 ~16 ~32 ~9 ~16 ~32 iron_block 0  
fill ~5 ~16 ~33 ~9 ~16 ~33 iron_block 0  
fill ~5 ~16 ~34 ~9 ~16 ~34 iron_block 0  
fill ~10 ~16 ~15 ~14 ~16 ~15 iron_block 0  
fill ~10 ~16 ~16 ~14 ~16 ~16 iron_block 0  
fill ~10 ~16 ~17 ~14 ~16 ~17 iron_block 0  
fill ~10 ~16 ~18 ~14 ~16 ~18 iron_block 0  
fill ~10 ~16 ~19 ~14 ~16 ~19 iron_block 0  
fill ~10 ~16 ~20 ~44 ~16 ~20 wool 12  
fill ~10 ~16 ~21 ~44 ~16 ~21 wool 12  
fill ~10 ~16 ~22 ~44 ~16 ~22 wool 12  
fill ~10 ~16 ~23 ~44 ~16 ~23 wool 12  
fill ~10 ~16 ~24 ~44 ~16 ~24 wool 12  
fill ~10 ~16 ~25 ~44 ~16 ~25 wool 12  
fill ~10 ~16 ~26 ~44 ~16 ~26 wool 12  
fill ~10 ~16 ~27 ~44 ~16 ~27 wool 12  
fill ~10 ~16 ~28 ~44 ~16 ~28 wool 12  
fill ~10 ~16 ~29 ~44 ~16 ~29 wool 12  
fill ~10 ~16 ~30 ~44 ~16 ~30 wool 12  
fill ~10 ~16 ~31 ~44 ~16 ~31 wool 12  
fill ~10 ~16 ~32 ~44 ~16 ~32 wool 12  
fill ~10 ~16 ~33 ~44 ~16 ~33 wool 12  
fill ~10 ~16 ~34 ~44 ~16 ~34 wool 12  
fill ~10 ~16 ~35 ~14 ~16 ~35 iron_block 0  
fill ~10 ~16 ~36 ~14 ~16 ~36 iron_block 0  
fill ~10 ~16 ~37 ~14 ~16 ~37 iron_block 0  
fill ~10 ~16 ~38 ~14 ~16 ~38 iron_block 0  
fill ~10 ~16 ~39 ~14 ~16 ~39 iron_block 0  
fill ~15 ~16 ~10 ~19 ~16 ~10 iron_block 0  
fill ~15 ~16 ~11 ~19 ~16 ~11 iron_block 0  
fill ~15 ~16 ~12 ~19 ~16 ~12 iron_block 0  
fill ~15 ~16 ~13 ~19 ~16 ~13 iron_block 0  
fill ~15 ~16 ~14 ~19 ~16 ~14 iron_block 0  
fill ~15 ~16 ~15 ~39 ~16 ~15 wool 12  
fill ~15 ~16 ~16 ~39 ~16 ~16 wool 12  
fill ~15 ~16 ~17 ~39 ~16 ~17 wool 12  
fill ~15 ~16 ~18 ~39 ~16 ~18 wool 12  
fill ~15 ~16 ~19 ~39 ~16 ~19 wool 12  
fill ~15 ~16 ~35 ~39 ~16 ~35 wool 12  
fill ~15 ~16 ~36 ~39 ~16 ~36 wool 12  
fill ~15 ~16 ~37 ~39 ~16 ~37 wool 12  
fill ~15 ~16 ~38 ~39 ~16 ~38 wool 12  
fill ~15 ~16 ~39 ~39 ~16 ~39 wool 12  
fill ~15 ~16 ~40 ~19 ~16 ~40 iron_block 0  
fill ~15 ~16 ~41 ~19 ~16 ~41 iron_block 0  
fill ~15 ~16 ~42 ~19 ~16 ~42 iron_block 0  
fill ~15 ~16 ~43 ~19 ~16 ~43 iron_block 0  
fill ~15 ~16 ~44 ~19 ~16 ~44 iron_block 0  
fill ~20 ~16 ~5 ~34 ~16 ~5 iron_block 0  
fill ~20 ~16 ~6 ~34 ~16 ~6 iron_block 0  
fill ~20 ~16 ~7 ~34 ~16 ~7 iron_block 0  
fill ~20 ~16 ~8 ~34 ~16 ~8 iron_block 0  
fill ~20 ~16 ~9 ~34 ~16 ~9 iron_block 0  
fill ~20 ~16 ~10 ~34 ~16 ~10 wool 12  
fill ~20 ~16 ~11 ~34 ~16 ~11 wool 12  
fill ~20 ~16 ~12 ~34 ~16 ~12 wool 12  
fill ~20 ~16 ~13 ~34 ~16 ~13 wool 12  
fill ~20 ~16 ~14 ~34 ~16 ~14 wool 12  
fill ~20 ~16 ~40 ~34 ~16 ~40 wool 12  
fill ~20 ~16 ~41 ~34 ~16 ~41 wool 12  
fill ~20 ~16 ~42 ~34 ~16 ~42 wool 12  
fill ~20 ~16 ~43 ~34 ~16 ~43 wool 12  
fill ~20 ~16 ~44 ~34 ~16 ~44 wool 12  
fill ~20 ~16 ~45 ~34 ~16 ~45 iron_block 0  
fill ~20 ~16 ~46 ~34 ~16 ~46 iron_block 0  
fill ~20 ~16 ~47 ~34 ~16 ~47 iron_block 0  
fill ~20 ~16 ~48 ~34 ~16 ~48 iron_block 0  
fill ~20 ~16 ~49 ~34 ~16 ~49 iron_block 0  
fill ~35 ~16 ~10 ~39 ~16 ~10 iron_block 0  
fill ~35 ~16 ~11 ~39 ~16 ~11 iron_block 0  
fill ~35 ~16 ~12 ~39 ~16 ~12 iron_block 0  
fill ~35 ~16 ~13 ~39 ~16 ~13 iron_block 0  
fill ~35 ~16 ~14 ~39 ~16 ~14 iron_block 0  
fill ~35 ~16 ~40 ~39 ~16 ~40 iron_block 0  
fill ~35 ~16 ~41 ~39 ~16 ~41 iron_block 0  
fill ~35 ~16 ~42 ~39 ~16 ~42 iron_block 0  
fill ~35 ~16 ~43 ~39 ~16 ~43 iron_block 0  
fill ~35 ~16 ~44 ~39 ~16 ~44 iron_block 0  
fill ~40 ~16 ~15 ~44 ~16 ~15 iron_block 0  
fill ~40 ~16 ~16 ~44 ~16 ~16 iron_block 0  
fill ~40 ~16 ~17 ~44 ~16 ~17 iron_block 0  
fill ~40 ~16 ~18 ~44 ~16 ~18 iron_block 0  
fill ~40 ~16 ~19 ~44 ~16 ~19 iron_block 0  
fill ~40 ~16 ~35 ~44 ~16 ~35 iron_block 0  
fill ~40 ~16 ~36 ~44 ~16 ~36 iron_block 0  
fill ~40 ~16 ~37 ~44 ~16 ~37 iron_block 0  
fill ~40 ~16 ~38 ~44 ~16 ~38 iron_block 0  
fill ~40 ~16 ~39 ~44 ~16 ~39 iron_block 0  
fill ~45 ~16 ~20 ~49 ~16 ~20 iron_block 0  
fill ~45 ~16 ~21 ~49 ~16 ~21 iron_block 0  
fill ~45 ~16 ~22 ~49 ~16 ~22 iron_block 0  
fill ~45 ~16 ~23 ~49 ~16 ~23 iron_block 0  
fill ~45 ~16 ~24 ~49 ~16 ~24 iron_block 0  
fill ~45 ~16 ~25 ~49 ~16 ~25 iron_block 0  
fill ~45 ~16 ~26 ~49 ~16 ~26 iron_block 0  
fill ~45 ~16 ~27 ~49 ~16 ~27 iron_block 0  
fill ~45 ~16 ~28 ~49 ~16 ~28 iron_block 0  
fill ~45 ~16 ~29 ~49 ~16 ~29 iron_block 0  
fill ~45 ~16 ~30 ~49 ~16 ~30 iron_block 0  
fill ~45 ~16 ~31 ~49 ~16 ~31 iron_block 0  
fill ~45 ~16 ~32 ~49 ~16 ~32 iron_block 0  
fill ~45 ~16 ~33 ~49 ~16 ~33 iron_block 0  
fill ~45 ~16 ~34 ~49 ~16 ~34 iron_block 0  
fill ~70 ~16 ~25 ~74 ~16 ~25 gold_block 0  
fill ~70 ~16 ~26 ~74 ~16 ~26 gold_block 0  
fill ~70 ~16 ~27 ~74 ~16 ~27 gold_block 0  
fill ~70 ~16 ~28 ~74 ~16 ~28 gold_block 0  
fill ~70 ~16 ~29 ~74 ~16 ~29 gold_block 0  
fill ~5 ~17 ~20 ~9 ~17 ~20 iron_block 0  
fill ~5 ~17 ~21 ~9 ~17 ~21 iron_block 0  
fill ~5 ~17 ~22 ~9 ~17 ~22 iron_block 0  
fill ~5 ~17 ~23 ~9 ~17 ~23 iron_block 0  
fill ~5 ~17 ~24 ~9 ~17 ~24 iron_block 0  
fill ~5 ~17 ~25 ~9 ~17 ~25 iron_block 0  
fill ~5 ~17 ~26 ~9 ~17 ~26 iron_block 0  
fill ~5 ~17 ~27 ~9 ~17 ~27 iron_block 0  
fill ~5 ~17 ~28 ~9 ~17 ~28 iron_block 0  
fill ~5 ~17 ~29 ~9 ~17 ~29 iron_block 0  
fill ~5 ~17 ~30 ~9 ~17 ~30 iron_block 0  
fill ~5 ~17 ~31 ~9 ~17 ~31 iron_block 0  
fill ~5 ~17 ~32 ~9 ~17 ~32 iron_block 0  
fill ~5 ~17 ~33 ~9 ~17 ~33 iron_block 0  
fill ~5 ~17 ~34 ~9 ~17 ~34 iron_block 0  
fill ~10 ~17 ~15 ~14 ~17 ~15 iron_block 0  
fill ~10 ~17 ~16 ~14 ~17 ~16 iron_block 0  
fill ~10 ~17 ~17 ~14 ~17 ~17 iron_block 0  
fill ~10 ~17 ~18 ~14 ~17 ~18 iron_block 0  
fill ~10 ~17 ~19 ~14 ~17 ~19 iron_block 0  
fill ~10 ~17 ~20 ~44 ~17 ~20 wool 12  
fill ~10 ~17 ~21 ~44 ~17 ~21 wool 12  
fill ~10 ~17 ~22 ~44 ~17 ~22 wool 12  
fill ~10 ~17 ~23 ~44 ~17 ~23 wool 12  
fill ~10 ~17 ~24 ~44 ~17 ~24 wool 12  
fill ~10 ~17 ~25 ~44 ~17 ~25 wool 12  
fill ~10 ~17 ~26 ~44 ~17 ~26 wool 12  
fill ~10 ~17 ~27 ~44 ~17 ~27 wool 12  
fill ~10 ~17 ~28 ~44 ~17 ~28 wool 12  
fill ~10 ~17 ~29 ~44 ~17 ~29 wool 12  
fill ~10 ~17 ~30 ~44 ~17 ~30 wool 12  
fill ~10 ~17 ~31 ~44 ~17 ~31 wool 12  
fill ~10 ~17 ~32 ~44 ~17 ~32 wool 12  
fill ~10 ~17 ~33 ~44 ~17 ~33 wool 12  
fill ~10 ~17 ~34 ~44 ~17 ~34 wool 12  
fill ~10 ~17 ~35 ~14 ~17 ~35 iron_block 0  
fill ~10 ~17 ~36 ~14 ~17 ~36 iron_block 0  
fill ~10 ~17 ~37 ~14 ~17 ~37 iron_block 0  
fill ~10 ~17 ~38 ~14 ~17 ~38 iron_block 0  
fill ~10 ~17 ~39 ~14 ~17 ~39 iron_block 0  
fill ~15 ~17 ~10 ~19 ~17 ~10 iron_block 0  
fill ~15 ~17 ~11 ~19 ~17 ~11 iron_block 0  
fill ~15 ~17 ~12 ~19 ~17 ~12 iron_block 0  
fill ~15 ~17 ~13 ~19 ~17 ~13 iron_block 0  
fill ~15 ~17 ~14 ~19 ~17 ~14 iron_block 0  
fill ~15 ~17 ~15 ~39 ~17 ~15 wool 12  
fill ~15 ~17 ~16 ~39 ~17 ~16 wool 12  
fill ~15 ~17 ~17 ~39 ~17 ~17 wool 12  
fill ~15 ~17 ~18 ~39 ~17 ~18 wool 12  
fill ~15 ~17 ~19 ~39 ~17 ~19 wool 12  
fill ~15 ~17 ~35 ~39 ~17 ~35 wool 12  
fill ~15 ~17 ~36 ~39 ~17 ~36 wool 12  
fill ~15 ~17 ~37 ~39 ~17 ~37 wool 12  
fill ~15 ~17 ~38 ~39 ~17 ~38 wool 12  
fill ~15 ~17 ~39 ~39 ~17 ~39 wool 12  
fill ~15 ~17 ~40 ~19 ~17 ~40 iron_block 0  
fill ~15 ~17 ~41 ~19 ~17 ~41 iron_block 0  
fill ~15 ~17 ~42 ~19 ~17 ~42 iron_block 0  
fill ~15 ~17 ~43 ~19 ~17 ~43 iron_block 0  
fill ~15 ~17 ~44 ~19 ~17 ~44 iron_block 0  
fill ~20 ~17 ~5 ~34 ~17 ~5 iron_block 0  
fill ~20 ~17 ~6 ~34 ~17 ~6 iron_block 0  
fill ~20 ~17 ~7 ~34 ~17 ~7 iron_block 0  
fill ~20 ~17 ~8 ~34 ~17 ~8 iron_block 0  
fill ~20 ~17 ~9 ~34 ~17 ~9 iron_block 0  
fill ~20 ~17 ~10 ~34 ~17 ~10 wool 12  
fill ~20 ~17 ~11 ~34 ~17 ~11 wool 12  
fill ~20 ~17 ~12 ~34 ~17 ~12 wool 12  
fill ~20 ~17 ~13 ~34 ~17 ~13 wool 12  
fill ~20 ~17 ~14 ~34 ~17 ~14 wool 12  
fill ~20 ~17 ~40 ~34 ~17 ~40 wool 12  
fill ~20 ~17 ~41 ~34 ~17 ~41 wool 12  
fill ~20 ~17 ~42 ~34 ~17 ~42 wool 12  
fill ~20 ~17 ~43 ~34 ~17 ~43 wool 12  
fill ~20 ~17 ~44 ~34 ~17 ~44 wool 12  
fill ~20 ~17 ~45 ~34 ~17 ~45 iron_block 0  
fill ~20 ~17 ~46 ~34 ~17 ~46 iron_block 0  
fill ~20 ~17 ~47 ~34 ~17 ~47 iron_block 0  
fill ~20 ~17 ~48 ~34 ~17 ~48 iron_block 0  
fill ~20 ~17 ~49 ~34 ~17 ~49 iron_block 0  
fill ~35 ~17 ~10 ~39 ~17 ~10 iron_block 0  
fill ~35 ~17 ~11 ~39 ~17 ~11 iron_block 0  
fill ~35 ~17 ~12 ~39 ~17 ~12 iron_block 0  
fill ~35 ~17 ~13 ~39 ~17 ~13 iron_block 0  
fill ~35 ~17 ~14 ~39 ~17 ~14 iron_block 0  
fill ~35 ~17 ~40 ~39 ~17 ~40 iron_block 0  
fill ~35 ~17 ~41 ~39 ~17 ~41 iron_block 0  
fill ~35 ~17 ~42 ~39 ~17 ~42 iron_block 0  
fill ~35 ~17 ~43 ~39 ~17 ~43 iron_block 0  
fill ~35 ~17 ~44 ~39 ~17 ~44 iron_block 0  
fill ~40 ~17 ~15 ~44 ~17 ~15 iron_block 0  
fill ~40 ~17 ~16 ~44 ~17 ~16 iron_block 0  
fill ~40 ~17 ~17 ~44 ~17 ~17 iron_block 0  
fill ~40 ~17 ~18 ~44 ~17 ~18 iron_block 0  
fill ~40 ~17 ~19 ~44 ~17 ~19 iron_block 0  
fill ~40 ~17 ~35 ~44 ~17 ~35 iron_block 0  
fill ~40 ~17 ~36 ~44 ~17 ~36 iron_block 0  
fill ~40 ~17 ~37 ~44 ~17 ~37 iron_block 0  
fill ~40 ~17 ~38 ~44 ~17 ~38 iron_block 0  
fill ~40 ~17 ~39 ~44 ~17 ~39 iron_block 0  
fill ~45 ~17 ~20 ~49 ~17 ~20 iron_block 0  
fill ~45 ~17 ~21 ~49 ~17 ~21 iron_block 0  
fill ~45 ~17 ~22 ~49 ~17 ~22 iron_block 0  
fill ~45 ~17 ~23 ~49 ~17 ~23 iron_block 0  
fill ~45 ~17 ~24 ~49 ~17 ~24 iron_block 0  
fill ~45 ~17 ~25 ~49 ~17 ~25 iron_block 0  
fill ~45 ~17 ~26 ~49 ~17 ~26 iron_block 0  
fill ~45 ~17 ~27 ~49 ~17 ~27 iron_block 0  
fill ~45 ~17 ~28 ~49 ~17 ~28 iron_block 0  
fill ~45 ~17 ~29 ~49 ~17 ~29 iron_block 0  
fill ~45 ~17 ~30 ~49 ~17 ~30 iron_block 0  
fill ~45 ~17 ~31 ~49 ~17 ~31 iron_block 0  
fill ~45 ~17 ~32 ~49 ~17 ~32 iron_block 0  
fill ~45 ~17 ~33 ~49 ~17 ~33 iron_block 0  
fill ~45 ~17 ~34 ~49 ~17 ~34 iron_block 0  
fill ~70 ~17 ~25 ~74 ~17 ~25 gold_block 0  
fill ~70 ~17 ~26 ~74 ~17 ~26 gold_block 0  
fill ~70 ~17 ~27 ~74 ~17 ~27 gold_block 0  
fill ~70 ~17 ~28 ~74 ~17 ~28 gold_block 0  
fill ~70 ~17 ~29 ~74 ~17 ~29 gold_block 0  
fill ~5 ~18 ~20 ~9 ~18 ~20 iron_block 0  
fill ~5 ~18 ~21 ~9 ~18 ~21 iron_block 0  
fill ~5 ~18 ~22 ~9 ~18 ~22 iron_block 0  
fill ~5 ~18 ~23 ~9 ~18 ~23 iron_block 0  
fill ~5 ~18 ~24 ~9 ~18 ~24 iron_block 0  
fill ~5 ~18 ~25 ~9 ~18 ~25 iron_block 0  
fill ~5 ~18 ~26 ~9 ~18 ~26 iron_block 0  
fill ~5 ~18 ~27 ~9 ~18 ~27 iron_block 0  
fill ~5 ~18 ~28 ~9 ~18 ~28 iron_block 0  
fill ~5 ~18 ~29 ~9 ~18 ~29 iron_block 0  
fill ~5 ~18 ~30 ~9 ~18 ~30 iron_block 0  
fill ~5 ~18 ~31 ~9 ~18 ~31 iron_block 0  
fill ~5 ~18 ~32 ~9 ~18 ~32 iron_block 0  
fill ~5 ~18 ~33 ~9 ~18 ~33 iron_block 0  
fill ~5 ~18 ~34 ~9 ~18 ~34 iron_block 0  
fill ~10 ~18 ~15 ~14 ~18 ~15 iron_block 0  
fill ~10 ~18 ~16 ~14 ~18 ~16 iron_block 0  
fill ~10 ~18 ~17 ~14 ~18 ~17 iron_block 0  
fill ~10 ~18 ~18 ~14 ~18 ~18 iron_block 0  
fill ~10 ~18 ~19 ~14 ~18 ~19 iron_block 0  
fill ~10 ~18 ~20 ~44 ~18 ~20 wool 12  
fill ~10 ~18 ~21 ~44 ~18 ~21 wool 12  
fill ~10 ~18 ~22 ~44 ~18 ~22 wool 12  
fill ~10 ~18 ~23 ~44 ~18 ~23 wool 12  
fill ~10 ~18 ~24 ~44 ~18 ~24 wool 12  
fill ~10 ~18 ~25 ~44 ~18 ~25 wool 12  
fill ~10 ~18 ~26 ~44 ~18 ~26 wool 12  
fill ~10 ~18 ~27 ~44 ~18 ~27 wool 12  
fill ~10 ~18 ~28 ~44 ~18 ~28 wool 12  
fill ~10 ~18 ~29 ~44 ~18 ~29 wool 12  
fill ~10 ~18 ~30 ~44 ~18 ~30 wool 12  
fill ~10 ~18 ~31 ~44 ~18 ~31 wool 12  
fill ~10 ~18 ~32 ~44 ~18 ~32 wool 12  
fill ~10 ~18 ~33 ~44 ~18 ~33 wool 12  
fill ~10 ~18 ~34 ~44 ~18 ~34 wool 12  
fill ~10 ~18 ~35 ~14 ~18 ~35 iron_block 0  
fill ~10 ~18 ~36 ~14 ~18 ~36 iron_block 0  
fill ~10 ~18 ~37 ~14 ~18 ~37 iron_block 0  
fill ~10 ~18 ~38 ~14 ~18 ~38 iron_block 0  
fill ~10 ~18 ~39 ~14 ~18 ~39 iron_block 0  
fill ~15 ~18 ~10 ~19 ~18 ~10 iron_block 0  
fill ~15 ~18 ~11 ~19 ~18 ~11 iron_block 0  
fill ~15 ~18 ~12 ~19 ~18 ~12 iron_block 0  
fill ~15 ~18 ~13 ~19 ~18 ~13 iron_block 0  
fill ~15 ~18 ~14 ~19 ~18 ~14 iron_block 0  
fill ~15 ~18 ~15 ~39 ~18 ~15 wool 12  
fill ~15 ~18 ~16 ~39 ~18 ~16 wool 12  
fill ~15 ~18 ~17 ~39 ~18 ~17 wool 12  
fill ~15 ~18 ~18 ~39 ~18 ~18 wool 12  
fill ~15 ~18 ~19 ~39 ~18 ~19 wool 12  
fill ~15 ~18 ~35 ~39 ~18 ~35 wool 12  
fill ~15 ~18 ~36 ~39 ~18 ~36 wool 12  
fill ~15 ~18 ~37 ~39 ~18 ~37 wool 12  
fill ~15 ~18 ~38 ~39 ~18 ~38 wool 12  
fill ~15 ~18 ~39 ~39 ~18 ~39 wool 12  
fill ~15 ~18 ~40 ~19 ~18 ~40 iron_block 0  
fill ~15 ~18 ~41 ~19 ~18 ~41 iron_block 0  
fill ~15 ~18 ~42 ~19 ~18 ~42 iron_block 0  
fill ~15 ~18 ~43 ~19 ~18 ~43 iron_block 0  
fill ~15 ~18 ~44 ~19 ~18 ~44 iron_block 0  
fill ~20 ~18 ~5 ~34 ~18 ~5 iron_block 0  
fill ~20 ~18 ~6 ~34 ~18 ~6 iron_block 0  
fill ~20 ~18 ~7 ~34 ~18 ~7 iron_block 0  
fill ~20 ~18 ~8 ~34 ~18 ~8 iron_block 0  
fill ~20 ~18 ~9 ~34 ~18 ~9 iron_block 0  
fill ~20 ~18 ~10 ~34 ~18 ~10 wool 12  
fill ~20 ~18 ~11 ~34 ~18 ~11 wool 12  
fill ~20 ~18 ~12 ~34 ~18 ~12 wool 12  
fill ~20 ~18 ~13 ~34 ~18 ~13 wool 12  
fill ~20 ~18 ~14 ~34 ~18 ~14 wool 12  
fill ~20 ~18 ~40 ~34 ~18 ~40 wool 12  
fill ~20 ~18 ~41 ~34 ~18 ~41 wool 12  
fill ~20 ~18 ~42 ~34 ~18 ~42 wool 12  
fill ~20 ~18 ~43 ~34 ~18 ~43 wool 12  
fill ~20 ~18 ~44 ~34 ~18 ~44 wool 12  
fill ~20 ~18 ~45 ~34 ~18 ~45 iron_block 0  
fill ~20 ~18 ~46 ~34 ~18 ~46 iron_block 0  
fill ~20 ~18 ~47 ~34 ~18 ~47 iron_block 0  
fill ~20 ~18 ~48 ~34 ~18 ~48 iron_block 0  
fill ~20 ~18 ~49 ~34 ~18 ~49 iron_block 0  
fill ~35 ~18 ~10 ~39 ~18 ~10 iron_block 0  
fill ~35 ~18 ~11 ~39 ~18 ~11 iron_block 0  
fill ~35 ~18 ~12 ~39 ~18 ~12 iron_block 0  
fill ~35 ~18 ~13 ~39 ~18 ~13 iron_block 0  
fill ~35 ~18 ~14 ~39 ~18 ~14 iron_block 0  
fill ~35 ~18 ~40 ~39 ~18 ~40 iron_block 0  
fill ~35 ~18 ~41 ~39 ~18 ~41 iron_block 0  
fill ~35 ~18 ~42 ~39 ~18 ~42 iron_block 0  
fill ~35 ~18 ~43 ~39 ~18 ~43 iron_block 0  
fill ~35 ~18 ~44 ~39 ~18 ~44 iron_block 0  
fill ~40 ~18 ~15 ~44 ~18 ~15 iron_block 0  
fill ~40 ~18 ~16 ~44 ~18 ~16 iron_block 0  
fill ~40 ~18 ~17 ~44 ~18 ~17 iron_block 0  
fill ~40 ~18 ~18 ~44 ~18 ~18 iron_block 0  
fill ~40 ~18 ~19 ~44 ~18 ~19 iron_block 0  
fill ~40 ~18 ~35 ~44 ~18 ~35 iron_block 0  
fill ~40 ~18 ~36 ~44 ~18 ~36 iron_block 0  
fill ~40 ~18 ~37 ~44 ~18 ~37 iron_block 0  
fill ~40 ~18 ~38 ~44 ~18 ~38 iron_block 0  
fill ~40 ~18 ~39 ~44 ~18 ~39 iron_block 0  
fill ~45 ~18 ~20 ~49 ~18 ~20 iron_block 0  
fill ~45 ~18 ~21 ~49 ~18 ~21 iron_block 0  
fill ~45 ~18 ~22 ~49 ~18 ~22 iron_block 0  
fill ~45 ~18 ~23 ~49 ~18 ~23 iron_block 0  
fill ~45 ~18 ~24 ~49 ~18 ~24 iron_block 0  
fill ~45 ~18 ~25 ~49 ~18 ~25 iron_block 0  
fill ~45 ~18 ~26 ~49 ~18 ~26 iron_block 0  
fill ~45 ~18 ~27 ~49 ~18 ~27 iron_block 0  
fill ~45 ~18 ~28 ~49 ~18 ~28 iron_block 0  
fill ~45 ~18 ~29 ~49 ~18 ~29 iron_block 0  
fill ~45 ~18 ~30 ~49 ~18 ~30 iron_block 0  
fill ~45 ~18 ~31 ~49 ~18 ~31 iron_block 0  
fill ~45 ~18 ~32 ~49 ~18 ~32 iron_block 0  
fill ~45 ~18 ~33 ~49 ~18 ~33 iron_block 0  
fill ~45 ~18 ~34 ~49 ~18 ~34 iron_block 0  
fill ~70 ~18 ~25 ~74 ~18 ~25 gold_block 0  
fill ~70 ~18 ~26 ~74 ~18 ~26 gold_block 0  
fill ~70 ~18 ~27 ~74 ~18 ~27 gold_block 0  
fill ~70 ~18 ~28 ~74 ~18 ~28 gold_block 0  
fill ~70 ~18 ~29 ~74 ~18 ~29 gold_block 0  
fill ~5 ~19 ~20 ~9 ~19 ~20 iron_block 0  
fill ~5 ~19 ~21 ~9 ~19 ~21 iron_block 0  
fill ~5 ~19 ~22 ~9 ~19 ~22 iron_block 0  
fill ~5 ~19 ~23 ~9 ~19 ~23 iron_block 0  
fill ~5 ~19 ~24 ~9 ~19 ~24 iron_block 0  
fill ~5 ~19 ~25 ~9 ~19 ~25 iron_block 0  
fill ~5 ~19 ~26 ~9 ~19 ~26 iron_block 0  
fill ~5 ~19 ~27 ~9 ~19 ~27 iron_block 0  
fill ~5 ~19 ~28 ~9 ~19 ~28 iron_block 0  
fill ~5 ~19 ~29 ~9 ~19 ~29 iron_block 0  
fill ~5 ~19 ~30 ~9 ~19 ~30 iron_block 0  
fill ~5 ~19 ~31 ~9 ~19 ~31 iron_block 0  
fill ~5 ~19 ~32 ~9 ~19 ~32 iron_block 0  
fill ~5 ~19 ~33 ~9 ~19 ~33 iron_block 0  
fill ~5 ~19 ~34 ~9 ~19 ~34 iron_block 0  
fill ~10 ~19 ~15 ~14 ~19 ~15 iron_block 0  
fill ~10 ~19 ~16 ~14 ~19 ~16 iron_block 0  
fill ~10 ~19 ~17 ~14 ~19 ~17 iron_block 0  
fill ~10 ~19 ~18 ~14 ~19 ~18 iron_block 0  
fill ~10 ~19 ~19 ~14 ~19 ~19 iron_block 0  
fill ~10 ~19 ~20 ~44 ~19 ~20 wool 12  
fill ~10 ~19 ~21 ~44 ~19 ~21 wool 12  
fill ~10 ~19 ~22 ~44 ~19 ~22 wool 12  
fill ~10 ~19 ~23 ~44 ~19 ~23 wool 12  
fill ~10 ~19 ~24 ~44 ~19 ~24 wool 12  
fill ~10 ~19 ~25 ~44 ~19 ~25 wool 12  
fill ~10 ~19 ~26 ~44 ~19 ~26 wool 12  
fill ~10 ~19 ~27 ~44 ~19 ~27 wool 12  
fill ~10 ~19 ~28 ~44 ~19 ~28 wool 12  
fill ~10 ~19 ~29 ~44 ~19 ~29 wool 12  
fill ~10 ~19 ~30 ~44 ~19 ~30 wool 12  
fill ~10 ~19 ~31 ~44 ~19 ~31 wool 12  
fill ~10 ~19 ~32 ~44 ~19 ~32 wool 12  
fill ~10 ~19 ~33 ~44 ~19 ~33 wool 12  
fill ~10 ~19 ~34 ~44 ~19 ~34 wool 12  
fill ~10 ~19 ~35 ~14 ~19 ~35 iron_block 0  
fill ~10 ~19 ~36 ~14 ~19 ~36 iron_block 0  
fill ~10 ~19 ~37 ~14 ~19 ~37 iron_block 0  
fill ~10 ~19 ~38 ~14 ~19 ~38 iron_block 0  
fill ~10 ~19 ~39 ~14 ~19 ~39 iron_block 0  
fill ~15 ~19 ~10 ~19 ~19 ~10 iron_block 0  
fill ~15 ~19 ~11 ~19 ~19 ~11 iron_block 0  
fill ~15 ~19 ~12 ~19 ~19 ~12 iron_block 0  
fill ~15 ~19 ~13 ~19 ~19 ~13 iron_block 0  
fill ~15 ~19 ~14 ~19 ~19 ~14 iron_block 0  
fill ~15 ~19 ~15 ~39 ~19 ~15 wool 12  
fill ~15 ~19 ~16 ~39 ~19 ~16 wool 12  
fill ~15 ~19 ~17 ~39 ~19 ~17 wool 12  
fill ~15 ~19 ~18 ~39 ~19 ~18 wool 12  
fill ~15 ~19 ~19 ~39 ~19 ~19 wool 12  
fill ~15 ~19 ~35 ~39 ~19 ~35 wool 12  
fill ~15 ~19 ~36 ~39 ~19 ~36 wool 12  
fill ~15 ~19 ~37 ~39 ~19 ~37 wool 12  
fill ~15 ~19 ~38 ~39 ~19 ~38 wool 12  
fill ~15 ~19 ~39 ~39 ~19 ~39 wool 12  
fill ~15 ~19 ~40 ~19 ~19 ~40 iron_block 0  
fill ~15 ~19 ~41 ~19 ~19 ~41 iron_block 0  
fill ~15 ~19 ~42 ~19 ~19 ~42 iron_block 0  
fill ~15 ~19 ~43 ~19 ~19 ~43 iron_block 0   
fill ~15 ~19 ~44 ~19 ~19 ~44 iron_block 0  
fill ~20 ~19 ~5 ~34 ~19 ~5 iron_block 0  
fill ~20 ~19 ~6 ~34 ~19 ~6 iron_block 0  
fill ~20 ~19 ~7 ~34 ~19 ~7 iron_block 0  
fill ~20 ~19 ~8 ~34 ~19 ~8 iron_block 0  
fill ~20 ~19 ~9 ~34 ~19 ~9 iron_block 0  
fill ~20 ~19 ~10 ~34 ~19 ~10 wool 12  
fill ~20 ~19 ~11 ~34 ~19 ~11 wool 12  
fill ~20 ~19 ~12 ~34 ~19 ~12 wool 12  
fill ~20 ~19 ~13 ~34 ~19 ~13 wool 12  
fill ~20 ~19 ~14 ~34 ~19 ~14 wool 12  
fill ~20 ~19 ~40 ~34 ~19 ~40 wool 12  
fill ~20 ~19 ~41 ~34 ~19 ~41 wool 12  
fill ~20 ~19 ~42 ~34 ~19 ~42 wool 12  
fill ~20 ~19 ~43 ~34 ~19 ~43 wool 12  
fill ~20 ~19 ~44 ~34 ~19 ~44 wool 12  
fill ~20 ~19 ~45 ~34 ~19 ~45 iron_block 0  
fill ~20 ~19 ~46 ~34 ~19 ~46 iron_block 0  
fill ~20 ~19 ~47 ~34 ~19 ~47 iron_block 0  
fill ~20 ~19 ~48 ~34 ~19 ~48 iron_block 0  
fill ~20 ~19 ~49 ~34 ~19 ~49 iron_block 0  
fill ~35 ~19 ~10 ~39 ~19 ~10 iron_block 0  
fill ~35 ~19 ~11 ~39 ~19 ~11 iron_block 0  
fill ~35 ~19 ~12 ~39 ~19 ~12 iron_block 0  
fill ~35 ~19 ~13 ~39 ~19 ~13 iron_block 0  
fill ~35 ~19 ~14 ~39 ~19 ~14 iron_block 0  
fill ~35 ~19 ~40 ~39 ~19 ~40 iron_block 0  
fill ~35 ~19 ~41 ~39 ~19 ~41 iron_block 0  
fill ~35 ~19 ~42 ~39 ~19 ~42 iron_block 0  
fill ~35 ~19 ~43 ~39 ~19 ~43 iron_block 0  
fill ~35 ~19 ~44 ~39 ~19 ~44 iron_block 0  
fill ~40 ~19 ~15 ~44 ~19 ~15 iron_block 0  
fill ~40 ~19 ~16 ~44 ~19 ~16 iron_block 0  
fill ~40 ~19 ~17 ~44 ~19 ~17 iron_block 0  
fill ~40 ~19 ~18 ~44 ~19 ~18 iron_block 0  
fill ~40 ~19 ~19 ~44 ~19 ~19 iron_block 0  
fill ~40 ~19 ~35 ~44 ~19 ~35 iron_block 0  
fill ~40 ~19 ~36 ~44 ~19 ~36 iron_block 0  
fill ~40 ~19 ~37 ~44 ~19 ~37 iron_block 0  
fill ~40 ~19 ~38 ~44 ~19 ~38 iron_block 0  
fill ~40 ~19 ~39 ~44 ~19 ~39 iron_block 0  
fill ~45 ~19 ~20 ~49 ~19 ~20 iron_block 0  
fill ~45 ~19 ~21 ~49 ~19 ~21 iron_block 0  
fill ~45 ~19 ~22 ~49 ~19 ~22 iron_block 0  
fill ~45 ~19 ~23 ~49 ~19 ~23 iron_block 0  
fill ~45 ~19 ~24 ~49 ~19 ~24 iron_block 0  
fill ~45 ~19 ~25 ~49 ~19 ~25 iron_block 0  
fill ~45 ~19 ~26 ~49 ~19 ~26 iron_block 0  
fill ~45 ~19 ~27 ~49 ~19 ~27 iron_block 0  
fill ~45 ~19 ~28 ~49 ~19 ~28 iron_block 0  
fill ~45 ~19 ~29 ~49 ~19 ~29 iron_block 0  
fill ~45 ~19 ~30 ~49 ~19 ~30 iron_block 0  
fill ~45 ~19 ~31 ~49 ~19 ~31 iron_block 0  
fill ~45 ~19 ~32 ~49 ~19 ~32 iron_block 0  
fill ~45 ~19 ~33 ~49 ~19 ~33 iron_block 0  
fill ~45 ~19 ~34 ~49 ~19 ~34 iron_block 0  
fill ~70 ~19 ~25 ~74 ~19 ~25 gold_block 0  
fill ~70 ~19 ~26 ~74 ~19 ~26 gold_block 0  
fill ~70 ~19 ~27 ~74 ~19 ~27 gold_block 0  
fill ~70 ~19 ~28 ~74 ~19 ~28 gold_block 0  
fill ~70 ~19 ~29 ~74 ~19 ~29 gold_block 0  
fill ~5 ~20 ~20 ~9 ~20 ~20 iron_block 0  
fill ~5 ~20 ~21 ~9 ~20 ~21 iron_block 0  
fill ~5 ~20 ~22 ~9 ~20 ~22 iron_block 0  
fill ~5 ~20 ~23 ~9 ~20 ~23 iron_block 0  
fill ~5 ~20 ~24 ~9 ~20 ~24 iron_block 0  
fill ~5 ~20 ~25 ~9 ~20 ~25 iron_block 0  
fill ~5 ~20 ~26 ~9 ~20 ~26 iron_block 0  
fill ~5 ~20 ~27 ~9 ~20 ~27 iron_block 0  
fill ~5 ~20 ~28 ~9 ~20 ~28 iron_block 0  
fill ~5 ~20 ~29 ~9 ~20 ~29 iron_block 0  
fill ~5 ~20 ~30 ~9 ~20 ~30 iron_block 0  
fill ~5 ~20 ~31 ~9 ~20 ~31 iron_block 0  
fill ~5 ~20 ~32 ~9 ~20 ~32 iron_block 0  
fill ~5 ~20 ~33 ~9 ~20 ~33 iron_block 0  
fill ~5 ~20 ~34 ~9 ~20 ~34 iron_block 0  
fill ~10 ~20 ~15 ~14 ~20 ~15 iron_block 0  
fill ~10 ~20 ~16 ~14 ~20 ~16 iron_block 0  
fill ~10 ~20 ~17 ~14 ~20 ~17 iron_block 0  
fill ~10 ~20 ~18 ~14 ~20 ~18 iron_block 0  
fill ~10 ~20 ~19 ~14 ~20 ~19 iron_block 0  
fill ~10 ~20 ~20 ~44 ~20 ~20 wool 12  
fill ~10 ~20 ~21 ~44 ~20 ~21 wool 12  
fill ~10 ~20 ~22 ~44 ~20 ~22 wool 12  
fill ~10 ~20 ~23 ~44 ~20 ~23 wool 12  
fill ~10 ~20 ~24 ~44 ~20 ~24 wool 12  
fill ~10 ~20 ~25 ~44 ~20 ~25 wool 12  
fill ~10 ~20 ~26 ~44 ~20 ~26 wool 12  
fill ~10 ~20 ~27 ~44 ~20 ~27 wool 12  
fill ~10 ~20 ~28 ~44 ~20 ~28 wool 12  
fill ~10 ~20 ~29 ~44 ~20 ~29 wool 12  
fill ~10 ~20 ~30 ~44 ~20 ~30 wool 12  
fill ~10 ~20 ~31 ~44 ~20 ~31 wool 12  
fill ~10 ~20 ~32 ~44 ~20 ~32 wool 12  
fill ~10 ~20 ~33 ~44 ~20 ~33 wool 12  
fill ~10 ~20 ~34 ~44 ~20 ~34 wool 12  
fill ~10 ~20 ~35 ~14 ~20 ~35 iron_block 0  
fill ~10 ~20 ~36 ~14 ~20 ~36 iron_block 0  
fill ~10 ~20 ~37 ~14 ~20 ~37 iron_block 0  
fill ~10 ~20 ~38 ~14 ~20 ~38 iron_block 0  
fill ~10 ~20 ~39 ~14 ~20 ~39 iron_block 0  
fill ~15 ~20 ~10 ~19 ~20 ~10 iron_block 0  
fill ~15 ~20 ~11 ~19 ~20 ~11 iron_block 0  
fill ~15 ~20 ~12 ~19 ~20 ~12 iron_block 0  
fill ~15 ~20 ~13 ~19 ~20 ~13 iron_block 0  
fill ~15 ~20 ~14 ~19 ~20 ~14 iron_block 0  
fill ~15 ~20 ~15 ~39 ~20 ~15 wool 12  
fill ~15 ~20 ~16 ~39 ~20 ~16 wool 12  
fill ~15 ~20 ~17 ~39 ~20 ~17 wool 12  
fill ~15 ~20 ~18 ~39 ~20 ~18 wool 12  
fill ~15 ~20 ~19 ~39 ~20 ~19 wool 12  
fill ~15 ~20 ~35 ~39 ~20 ~35 wool 12  
