    
fill ~2 ~0 ~5 ~15 ~0 ~5 stone  
fill ~2 ~0 ~6 ~3 ~0 ~6 stone  
fill ~2 ~0 ~7 ~3 ~0 ~7 stone  
fill ~2 ~0 ~10 ~3 ~0 ~10 stone  
fill ~2 ~0 ~11 ~3 ~0 ~11 stone  
fill ~2 ~0 ~12 ~3 ~0 ~12 stone  
fill ~2 ~0 ~15 ~3 ~0 ~15 stone  
fill ~2 ~0 ~16 ~3 ~0 ~16 stone  
fill ~2 ~0 ~17 ~3 ~0 ~17 stone 
setblock ~2 ~0 ~21 stone 0  
fill ~2 ~0 ~25 ~3 ~0 ~25 stone  
fill ~2 ~0 ~26 ~3 ~0 ~26 stone  
fill ~2 ~0 ~27 ~3 ~0 ~27 stone  
fill ~2 ~0 ~30 ~3 ~0 ~30 stone  
fill ~2 ~0 ~31 ~3 ~0 ~31 stone  
fill ~2 ~0 ~32 ~3 ~0 ~32 stone  
fill ~2 ~0 ~35 ~3 ~0 ~35 stone  
fill ~2 ~0 ~36 ~3 ~0 ~36 stone  
fill ~2 ~0 ~37 ~3 ~0 ~37 stone  
fill ~2 ~0 ~40 ~3 ~0 ~40 stone  
fill ~2 ~0 ~41 ~3 ~0 ~41 stone  
fill ~2 ~0 ~42 ~3 ~0 ~42 stone  
fill ~2 ~0 ~45 ~3 ~0 ~45 stone  
fill ~2 ~0 ~46 ~3 ~0 ~46 stone  
fill ~2 ~0 ~47 ~3 ~0 ~47 stone  
fill ~2 ~0 ~50 ~3 ~0 ~50 stone  
fill ~2 ~0 ~51 ~3 ~0 ~51 stone  
fill ~2 ~0 ~52 ~3 ~0 ~52 stone  
fill ~2 ~0 ~55 ~3 ~0 ~55 stone  
fill ~2 ~0 ~56 ~3 ~0 ~56 stone  
fill ~2 ~0 ~57 ~3 ~0 ~57 stone  
fill ~2 ~0 ~60 ~3 ~0 ~60 stone  
fill ~2 ~0 ~61 ~3 ~0 ~61 stone  
fill ~2 ~0 ~62 ~3 ~0 ~62 stone  
fill ~2 ~0 ~65 ~3 ~0 ~65 stone  
fill ~2 ~0 ~66 ~3 ~0 ~66 stone  
fill ~2 ~0 ~67 ~3 ~0 ~67 stone  
fill ~2 ~0 ~70 ~3 ~0 ~70 stone  
fill ~2 ~0 ~71 ~3 ~0 ~71 stone  
fill ~2 ~0 ~72 ~3 ~0 ~72 stone  
fill ~2 ~0 ~75 ~3 ~0 ~75 stone  
fill ~2 ~0 ~76 ~3 ~0 ~76 stone  
fill ~2 ~0 ~77 ~3 ~0 ~77 stone  
fill ~2 ~0 ~80 ~3 ~0 ~80 stone  
fill ~2 ~0 ~81 ~3 ~0 ~81 stone  
fill ~2 ~0 ~82 ~3 ~0 ~82 stone  
fill ~2 ~0 ~85 ~3 ~0 ~85 stone  
fill ~2 ~0 ~86 ~3 ~0 ~86 stone  
fill ~2 ~0 ~87 ~6 ~0 ~87 stone  
fill ~3 ~0 ~4 ~5 ~0 ~4 stone  
fill ~3 ~0 ~8 ~3 ~0 ~18 stone  
fill ~3 ~0 ~19 ~3 ~0 ~23 stone 
setblock ~3 ~0 ~24 stone 0  
fill ~3 ~0 ~28 ~3 ~0 ~89 stone  
fill ~4 ~0 ~6 ~13 ~0 ~6 stone  
fill ~4 ~0 ~7 ~13 ~0 ~7 stone  
fill ~4 ~0 ~8 ~13 ~0 ~8 stone  
fill ~4 ~0 ~9 ~13 ~0 ~9 stone  
fill ~4 ~0 ~10 ~13 ~0 ~10 stone  
fill ~4 ~0 ~11 ~13 ~0 ~11 stone  
fill ~4 ~0 ~12 ~13 ~0 ~12 stone  
fill ~4 ~0 ~13 ~35 ~0 ~13 stone  
fill ~4 ~0 ~14 ~35 ~0 ~14 stone  
fill ~4 ~0 ~15 ~35 ~0 ~15 stone  
fill ~4 ~0 ~16 ~35 ~0 ~16 stone  
fill ~4 ~0 ~17 ~35 ~0 ~17 stone  
fill ~4 ~0 ~18 ~4 ~0 ~6 stone 
setblock ~4 ~0 ~19 stonebrick 3  
fill ~4 ~0 ~20 ~4 ~0 ~22 stone 
setblock ~4 ~0 ~23 stonebrick 3 
setblock ~4 ~0 ~24 stone 6 
setblock ~4 ~0 ~25 stonebrick 3  
fill ~4 ~0 ~26 ~6 ~0 ~26 stone  
fill ~4 ~0 ~27 ~13 ~0 ~27 stone  
fill ~4 ~0 ~28 ~14 ~0 ~28 stone  
fill ~4 ~0 ~29 ~6 ~0 ~29 stone  
fill ~4 ~0 ~30 ~16 ~0 ~30 stone  
fill ~4 ~0 ~31 ~6 ~0 ~31 stone  
fill ~4 ~0 ~32 ~6 ~0 ~32 stone  
fill ~4 ~0 ~33 ~6 ~0 ~33 stone  
fill ~4 ~0 ~34 ~6 ~0 ~34 stone  
fill ~4 ~0 ~35 ~6 ~0 ~35 stone  
fill ~4 ~0 ~36 ~6 ~0 ~36 stone  
fill ~4 ~0 ~37 ~6 ~0 ~37 stone  
fill ~4 ~0 ~38 ~6 ~0 ~38 stone  
fill ~4 ~0 ~39 ~6 ~0 ~39 stone  
fill ~4 ~0 ~40 ~6 ~0 ~40 stone  
fill ~4 ~0 ~41 ~6 ~0 ~41 stone  
fill ~4 ~0 ~42 ~6 ~0 ~42 stone  
fill ~4 ~0 ~43 ~6 ~0 ~43 stone  
fill ~4 ~0 ~44 ~6 ~0 ~44 stone  
fill ~4 ~0 ~45 ~6 ~0 ~45 stone  
fill ~4 ~0 ~46 ~6 ~0 ~46 stone  
fill ~4 ~0 ~47 ~6 ~0 ~47 stone  
fill ~4 ~0 ~48 ~6 ~0 ~48 stone  
fill ~4 ~0 ~49 ~6 ~0 ~49 stone  
fill ~4 ~0 ~50 ~6 ~0 ~50 stone  
fill ~4 ~0 ~51 ~6 ~0 ~51 stone  
fill ~4 ~0 ~52 ~6 ~0 ~52 stone  
fill ~4 ~0 ~53 ~6 ~0 ~53 stone  
fill ~4 ~0 ~54 ~6 ~0 ~54 stone  
fill ~4 ~0 ~55 ~6 ~0 ~55 stone  
fill ~4 ~0 ~56 ~6 ~0 ~56 stone  
fill ~4 ~0 ~57 ~6 ~0 ~57 stone  
fill ~4 ~0 ~58 ~6 ~0 ~58 stone  
fill ~4 ~0 ~59 ~6 ~0 ~59 stone  
fill ~4 ~0 ~60 ~6 ~0 ~60 stone  
fill ~4 ~0 ~61 ~6 ~0 ~61 stone  
fill ~4 ~0 ~62 ~6 ~0 ~62 stone  
fill ~4 ~0 ~63 ~6 ~0 ~63 stone  
fill ~4 ~0 ~64 ~6 ~0 ~64 stone  
fill ~4 ~0 ~65 ~6 ~0 ~65 stone  
fill ~4 ~0 ~66 ~6 ~0 ~66 stone  
fill ~4 ~0 ~67 ~6 ~0 ~67 stone  
fill ~4 ~0 ~68 ~6 ~0 ~68 stone  
fill ~4 ~0 ~69 ~6 ~0 ~69 stone  
fill ~4 ~0 ~70 ~6 ~0 ~70 stone  
fill ~4 ~0 ~71 ~6 ~0 ~71 stone  
fill ~4 ~0 ~72 ~6 ~0 ~72 stone  
fill ~4 ~0 ~73 ~6 ~0 ~73 stone  
fill ~4 ~0 ~74 ~6 ~0 ~74 stone  
fill ~4 ~0 ~75 ~6 ~0 ~75 stone  
fill ~4 ~0 ~76 ~16 ~0 ~76 stone  
fill ~4 ~0 ~77 ~5 ~0 ~77 stone  
fill ~4 ~0 ~78 ~5 ~0 ~78 stone  
fill ~4 ~0 ~79 ~12 ~0 ~79 stone  
fill ~4 ~0 ~85 ~17 ~0 ~85 stone  
fill ~4 ~0 ~86 ~5 ~0 ~86 stone 
setblock ~4 ~0 ~88 stone 0  
fill ~4 ~0 ~89 ~11 ~0 ~89 stone 
setblock ~5 ~0 ~18 stonebrick 3 
setblock ~5 ~0 ~19 stone 6 
setblock ~5 ~0 ~20 stonebrick 3 
setblock ~5 ~0 ~21 stone 6 
setblock ~5 ~0 ~22 stonebrick 3 
setblock ~5 ~0 ~23 stone 6 
setblock ~5 ~0 ~24 stonebrick 3 
setblock ~5 ~0 ~25 stone 6  
fill ~5 ~0 ~88 ~10 ~0 ~88 stone 
setblock ~6 ~0 ~18 stone 6 
setblock ~6 ~0 ~19 stonebrick 3 
setblock ~6 ~0 ~20 stone 6 
setblock ~6 ~0 ~21 stonebrick 3 
setblock ~6 ~0 ~22 stone 6 
setblock ~6 ~0 ~23 stonebrick 3 
setblock ~6 ~0 ~24 stone 6 
setblock ~6 ~0 ~25 stonebrick 3 
setblock ~6 ~0 ~78 stone 0  
fill ~6 ~0 ~83 ~8 ~0 ~83 stone  
fill ~6 ~0 ~84 ~6 ~0 ~83 stone 
setblock ~6 ~0 ~86 stone 0 
setblock ~7 ~0 ~18 stonebrick 3 
setblock ~7 ~0 ~19 stone 6 
setblock ~7 ~0 ~20 stonebrick 3 
setblock ~7 ~0 ~21 stone 6 
setblock ~7 ~0 ~22 stonebrick 3 
setblock ~7 ~0 ~23 stone 6 
setblock ~7 ~0 ~24 stonebrick 3 
setblock ~7 ~0 ~25 stone 6 
setblock ~7 ~0 ~26 stonebrick 3 
setblock ~7 ~0 ~29 stone_slab 8  
fill ~7 ~0 ~31 ~12 ~0 ~31 stone 
setblock ~7 ~0 ~32 stone_slab 8  
fill ~7 ~0 ~33 ~8 ~0 ~33 stone  
fill ~7 ~0 ~34 ~10 ~0 ~34 stone 
setblock ~7 ~0 ~35 stone_slab 8  
fill ~7 ~0 ~36 ~8 ~0 ~36 stone  
fill ~7 ~0 ~37 ~9 ~0 ~37 stone 
setblock ~7 ~0 ~38 stone_slab 8  
fill ~7 ~0 ~39 ~7 ~0 ~40 stone 
setblock ~7 ~0 ~41 stone_slab 8  
fill ~7 ~0 ~42 ~14 ~0 ~42 stone  
fill ~7 ~0 ~43 ~8 ~0 ~43 stone 
setblock ~7 ~0 ~44 stone_slab 8  
fill ~7 ~0 ~45 ~12 ~0 ~45 stone  
fill ~7 ~0 ~46 ~8 ~0 ~46 stone 
setblock ~7 ~0 ~47 stone_slab 8  
fill ~7 ~0 ~48 ~10 ~0 ~48 stone 
setblock ~7 ~0 ~50 stone_slab 8  
fill ~7 ~0 ~51 ~12 ~0 ~51 stone  
fill ~7 ~0 ~52 ~8 ~0 ~52 stone 
setblock ~7 ~0 ~53 stone_slab 8  
fill ~7 ~0 ~54 ~7 ~0 ~55 stone 
setblock ~7 ~0 ~56 stone_slab 8  
fill ~7 ~0 ~57 ~10 ~0 ~57 stone  
fill ~7 ~0 ~58 ~12 ~0 ~58 stone 
setblock ~7 ~0 ~59 stone_slab 8  
fill ~7 ~0 ~60 ~13 ~0 ~60 stone  
fill ~7 ~0 ~61 ~7 ~0 ~60 stone 
setblock ~7 ~0 ~62 stone_slab 8  
fill ~7 ~0 ~63 ~8 ~0 ~63 stone  
fill ~7 ~0 ~64 ~13 ~0 ~64 stone 
setblock ~7 ~0 ~65 stone_slab 8  
fill ~7 ~0 ~66 ~8 ~0 ~66 stone  
fill ~7 ~0 ~67 ~8 ~0 ~67 stone 
setblock ~7 ~0 ~68 stone_slab 8  
fill ~7 ~0 ~69 ~8 ~0 ~69 stone  
fill ~7 ~0 ~70 ~13 ~0 ~70 stone 
setblock ~7 ~0 ~71 stone_slab 8  
fill ~7 ~0 ~72 ~8 ~0 ~72 stone  
fill ~7 ~0 ~73 ~8 ~0 ~73 stone 
setblock ~7 ~0 ~74 stone_slab 8  
fill ~7 ~0 ~75 ~14 ~0 ~75 stone  
fill ~7 ~0 ~77 ~17 ~0 ~77 stone  
fill ~7 ~0 ~78 ~9 ~0 ~78 stone  
fill ~7 ~0 ~84 ~16 ~0 ~84 stone  
fill ~7 ~0 ~86 ~16 ~0 ~86 stone  
fill ~7 ~0 ~87 ~8 ~0 ~87 stone  
fill ~8 ~0 ~4 ~10 ~0 ~4 stone  
fill ~8 ~0 ~18 ~32 ~0 ~18 stone 
setblock ~8 ~0 ~19 stonebrick 3 
setblock ~8 ~0 ~20 stone 6 
setblock ~8 ~0 ~21 stonebrick 3 
setblock ~8 ~0 ~22 stone 6 
setblock ~8 ~0 ~23 stonebrick 3 
setblock ~8 ~0 ~24 stone 6 
setblock ~8 ~0 ~25 stonebrick 3 
setblock ~8 ~0 ~26 stone 6  
fill ~8 ~0 ~29 ~14 ~0 ~29 stone  
fill ~8 ~0 ~32 ~14 ~0 ~32 stone  
fill ~8 ~0 ~35 ~14 ~0 ~35 stone  
fill ~8 ~0 ~38 ~14 ~0 ~38 stone 
setblock ~8 ~0 ~40 stone 0  
fill ~8 ~0 ~44 ~14 ~0 ~44 stone  
fill ~8 ~0 ~47 ~14 ~0 ~47 stone  
fill ~8 ~0 ~50 ~14 ~0 ~50 stone  
fill ~8 ~0 ~53 ~14 ~0 ~53 stone  
fill ~8 ~0 ~55 ~11 ~0 ~55 stone  
fill ~8 ~0 ~56 ~14 ~0 ~56 stone  
fill ~8 ~0 ~59 ~14 ~0 ~59 stone  
fill ~8 ~0 ~62 ~14 ~0 ~62 stone  
fill ~8 ~0 ~68 ~14 ~0 ~68 stone  
fill ~8 ~0 ~71 ~14 ~0 ~71 stone  
fill ~8 ~0 ~74 ~14 ~0 ~74 stone  
fill ~8 ~0 ~80 ~8 ~0 ~83 stone  
fill ~9 ~0 ~19 ~31 ~0 ~19 stone 
setblock ~9 ~0 ~20 stonebrick 3 
setblock ~9 ~0 ~21 stone 6 
setblock ~9 ~0 ~22 stonebrick 3 
setblock ~9 ~0 ~23 stone 6 
setblock ~9 ~0 ~24 stonebrick 3 
setblock ~9 ~0 ~25 stone 6 
setblock ~9 ~0 ~26 stonebrick 3  
fill ~9 ~0 ~39 ~12 ~0 ~39 stone  
fill ~9 ~0 ~41 ~14 ~0 ~41 stone 
setblock ~9 ~0 ~54 stone 0 
setblock ~9 ~0 ~61 stone 0  
fill ~9 ~0 ~65 ~14 ~0 ~65 stone  
fill ~9 ~0 ~81 ~9 ~0 ~86 stone  
fill ~9 ~0 ~87 ~16 ~0 ~87 stone  
fill ~10 ~0 ~20 ~30 ~0 ~20 stone 
setblock ~10 ~0 ~21 stonebrick 3 
setblock ~10 ~0 ~22 stone 6 
setblock ~10 ~0 ~23 stonebrick 3 
setblock ~10 ~0 ~24 stone 6 
setblock ~10 ~0 ~25 stonebrick 3 
setblock ~10 ~0 ~26 stone 6  
fill ~10 ~0 ~33 ~11 ~0 ~33 stone  
fill ~10 ~0 ~36 ~11 ~0 ~36 stone 
setblock ~10 ~0 ~43 stone 0  
fill ~10 ~0 ~46 ~11 ~0 ~46 stone  
fill ~10 ~0 ~49 ~11 ~0 ~49 stone  
fill ~10 ~0 ~63 ~14 ~0 ~63 stone 
setblock ~10 ~0 ~66 stone 0  
fill ~10 ~0 ~69 ~14 ~0 ~69 stone  
fill ~10 ~0 ~72 ~13 ~0 ~72 stone  
fill ~10 ~0 ~73 ~13 ~0 ~73 stone 
setblock ~10 ~0 ~78 stone 0  
fill ~10 ~0 ~80 ~10 ~0 ~83 stone  
fill ~11 ~0 ~21 ~29 ~0 ~21 stone 
setblock ~11 ~0 ~22 stonebrick 3 
setblock ~11 ~0 ~23 stone 6 
setblock ~11 ~0 ~24 stonebrick 3 
setblock ~11 ~0 ~25 stone 6 
setblock ~11 ~0 ~26 stonebrick 3  
fill ~11 ~0 ~37 ~14 ~0 ~37 stone  
fill ~11 ~0 ~52 ~14 ~0 ~52 stone 
setblock ~11 ~0 ~54 stone 0  
fill ~11 ~0 ~61 ~13 ~0 ~61 stone 
setblock ~11 ~0 ~67 stone 0  
fill ~11 ~0 ~78 ~16 ~0 ~78 stone  
fill ~11 ~0 ~81 ~17 ~0 ~81 stone  
fill ~11 ~0 ~82 ~11 ~0 ~81 stone  
fill ~11 ~0 ~83 ~12 ~0 ~83 stone  
fill ~11 ~0 ~88 ~15 ~0 ~88 stone  
fill ~12 ~0 ~22 ~28 ~0 ~22 stone 
setblock ~12 ~0 ~23 stonebrick 3 
setblock ~12 ~0 ~24 stone 6 
setblock ~12 ~0 ~25 stonebrick 3 
setblock ~12 ~0 ~26 stone 6 
setblock ~12 ~0 ~34 stone 0  
fill ~12 ~0 ~40 ~14 ~0 ~40 stone 
setblock ~12 ~0 ~43 stone 0  
fill ~12 ~0 ~48 ~13 ~0 ~48 stone  
fill ~12 ~0 ~80 ~13 ~0 ~80 stone  
fill ~12 ~0 ~82 ~14 ~0 ~82 stone  
fill ~12 ~0 ~89 ~14 ~0 ~89 stone  
fill ~13 ~0 ~2 ~26 ~0 ~2 stone  
fill ~13 ~0 ~3 ~15 ~0 ~3 stone  
fill ~13 ~0 ~4 ~15 ~0 ~4 stone  
fill ~13 ~0 ~23 ~27 ~0 ~23 stone 
setblock ~13 ~0 ~24 stonebrick 3 
setblock ~13 ~0 ~25 stone 6 
setblock ~13 ~0 ~26 stonebrick 3  
fill ~13 ~0 ~33 ~14 ~0 ~33 stone 
setblock ~13 ~0 ~46 stone 0  
fill ~13 ~0 ~49 ~14 ~0 ~49 stone  
fill ~13 ~0 ~54 ~13 ~0 ~56 stone  
fill ~13 ~0 ~66 ~13 ~0 ~75 stone  
fill ~13 ~0 ~79 ~17 ~0 ~79 stone  
fill ~13 ~0 ~83 ~17 ~0 ~83 stone 
setblock ~13 ~0 ~90 stone 0  
fill ~14 ~0 ~1 ~25 ~0 ~1 stone  
fill ~14 ~0 ~6 ~15 ~0 ~6 stone  
fill ~14 ~0 ~7 ~15 ~0 ~7 stone  
fill ~14 ~0 ~8 ~15 ~0 ~8 stone  
fill ~14 ~0 ~9 ~15 ~0 ~9 stone  
fill ~14 ~0 ~10 ~15 ~0 ~10 stone  
fill ~14 ~0 ~11 ~25 ~0 ~11 stone  
fill ~14 ~0 ~12 ~25 ~0 ~12 stone  
fill ~14 ~0 ~24 ~26 ~0 ~24 stone 
setblock ~14 ~0 ~25 stonebrick 3 
setblock ~14 ~0 ~26 stone 6 
setblock ~14 ~0 ~27 stonebrick 3 
setblock ~14 ~0 ~34 stone 0 
setblock ~14 ~0 ~36 stone 0 
setblock ~14 ~0 ~39 stone 0  
fill ~14 ~0 ~57 ~14 ~0 ~59 stone  
fill ~14 ~0 ~90 ~25 ~0 ~90 stone  
fill ~15 ~0 ~0 ~17 ~0 ~0 stone  
fill ~15 ~0 ~25 ~25 ~0 ~25 stone 
setblock ~15 ~0 ~26 stonebrick 3 
setblock ~15 ~0 ~27 stone 6 
setblock ~15 ~0 ~28 stonebrick 3 
setblock ~15 ~0 ~29 stone_slab 8  
fill ~15 ~0 ~80 ~16 ~0 ~80 stone  
fill ~15 ~0 ~82 ~16 ~0 ~82 stone  
fill ~15 ~0 ~89 ~24 ~0 ~89 stone  
fill ~16 ~0 ~26 ~24 ~0 ~26 stone 
setblock ~16 ~0 ~27 stonebrick 3 
setblock ~16 ~0 ~28 stone 6 
setblock ~16 ~0 ~29 stonebrick 3 
setblock ~16 ~0 ~31 stone 0 
setblock ~16 ~0 ~32 stone_slab 8  
fill ~16 ~0 ~33 ~16 ~0 ~34 stone 
setblock ~16 ~0 ~35 stone_slab 8  
fill ~16 ~0 ~36 ~16 ~0 ~37 stone 
setblock ~16 ~0 ~38 stone_slab 8  
fill ~16 ~0 ~39 ~16 ~0 ~40 stone 
setblock ~16 ~0 ~41 stone_slab 8  
fill ~16 ~0 ~42 ~16 ~0 ~43 stone 
setblock ~16 ~0 ~44 stone_slab 8  
fill ~16 ~0 ~45 ~16 ~0 ~46 stone 
setblock ~16 ~0 ~47 stone_slab 8  
fill ~16 ~0 ~48 ~16 ~0 ~49 stone 
setblock ~16 ~0 ~50 stone_slab 8  
fill ~16 ~0 ~51 ~16 ~0 ~52 stone 
setblock ~16 ~0 ~53 stone_slab 8  
fill ~16 ~0 ~54 ~16 ~0 ~55 stone 
setblock ~16 ~0 ~56 stone_slab 8  
fill ~16 ~0 ~57 ~16 ~0 ~58 stone 
setblock ~16 ~0 ~59 stone_slab 8  
fill ~16 ~0 ~60 ~16 ~0 ~61 stone 
setblock ~16 ~0 ~62 stone_slab 8  
fill ~16 ~0 ~63 ~16 ~0 ~64 stone 
setblock ~16 ~0 ~65 stone_slab 8  
fill ~16 ~0 ~66 ~16 ~0 ~67 stone 
setblock ~16 ~0 ~68 stone_slab 8  
fill ~16 ~0 ~69 ~16 ~0 ~70 stone 
setblock ~16 ~0 ~71 stone_slab 8  
fill ~16 ~0 ~72 ~16 ~0 ~73 stone 
setblock ~16 ~0 ~74 stone_slab 8 
setblock ~16 ~0 ~75 stone 0  
fill ~16 ~0 ~88 ~23 ~0 ~88 stone  
fill ~17 ~0 ~27 ~23 ~0 ~27 stone 
setblock ~17 ~0 ~28 stonebrick 3 
setblock ~17 ~0 ~29 stone 6 
setblock ~17 ~0 ~30 stonebrick 3 
setblock ~17 ~0 ~31 stone 6 
setblock ~17 ~0 ~32 stonebrick 3 
setblock ~17 ~0 ~33 stone 6 
setblock ~17 ~0 ~34 stonebrick 3 
setblock ~17 ~0 ~35 stone 6 
setblock ~17 ~0 ~36 stonebrick 3 
setblock ~17 ~0 ~37 stone 6 
setblock ~17 ~0 ~38 stonebrick 3 
setblock ~17 ~0 ~39 stone 6 
setblock ~17 ~0 ~40 stonebrick 3 
setblock ~17 ~0 ~41 stone 6 
setblock ~17 ~0 ~42 stonebrick 3 
setblock ~17 ~0 ~43 stone 6 
setblock ~17 ~0 ~44 stonebrick 3 
setblock ~17 ~0 ~45 stone 6 
setblock ~17 ~0 ~46 stonebrick 3 
setblock ~17 ~0 ~47 stone 6 
setblock ~17 ~0 ~48 stonebrick 3 
setblock ~17 ~0 ~49 stone 6 
setblock ~17 ~0 ~50 stonebrick 3 
setblock ~17 ~0 ~51 stone 6 
setblock ~17 ~0 ~52 stonebrick 3 
setblock ~17 ~0 ~53 stone 6 
setblock ~17 ~0 ~54 stonebrick 3 
setblock ~17 ~0 ~55 stone 6 
setblock ~17 ~0 ~56 stonebrick 3 
setblock ~17 ~0 ~57 stone 6 
setblock ~17 ~0 ~58 stonebrick 3 
setblock ~17 ~0 ~59 stone 6 
setblock ~17 ~0 ~60 stonebrick 3 
setblock ~17 ~0 ~61 stone 6 
setblock ~17 ~0 ~62 stonebrick 3 
setblock ~17 ~0 ~63 stone 6 
setblock ~17 ~0 ~64 stonebrick 3 
setblock ~17 ~0 ~65 stone 6 
setblock ~17 ~0 ~66 stonebrick 3 
setblock ~17 ~0 ~67 stone 6 
setblock ~17 ~0 ~68 stonebrick 3 
setblock ~17 ~0 ~69 stone 6 
setblock ~17 ~0 ~70 stonebrick 3 
setblock ~17 ~0 ~71 stone 6 
setblock ~17 ~0 ~72 stonebrick 3 
setblock ~17 ~0 ~73 stone 6 
setblock ~17 ~0 ~74 stonebrick 3 
setblock ~17 ~0 ~75 stone 6 
setblock ~17 ~0 ~76 stonebrick 3 
setblock ~17 ~0 ~78 stonebrick 3 
setblock ~17 ~0 ~80 stonebrick 3 
setblock ~17 ~0 ~82 stonebrick 3 
setblock ~17 ~0 ~84 stonebrick 3 
setblock ~17 ~0 ~86 stonebrick 3  
fill ~17 ~0 ~87 ~18 ~0 ~87 stone 
setblock ~18 ~0 ~28 stone 6 
setblock ~18 ~0 ~29 stonebrick 3 
setblock ~18 ~0 ~30 stone 6 
setblock ~18 ~0 ~31 stonebrick 3 
setblock ~18 ~0 ~32 stone 6 
setblock ~18 ~0 ~33 stonebrick 3 
setblock ~18 ~0 ~34 stone 6 
setblock ~18 ~0 ~35 stonebrick 3 
setblock ~18 ~0 ~36 stone 6 
setblock ~18 ~0 ~37 stonebrick 3 
setblock ~18 ~0 ~38 stone 6 
setblock ~18 ~0 ~39 stonebrick 3 
setblock ~18 ~0 ~40 stone 6 
setblock ~18 ~0 ~41 stonebrick 3 
setblock ~18 ~0 ~42 stone 6 
setblock ~18 ~0 ~43 stonebrick 3 
setblock ~18 ~0 ~44 stone 6 
setblock ~18 ~0 ~45 stonebrick 3 
setblock ~18 ~0 ~46 stone 6 
setblock ~18 ~0 ~47 stonebrick 3 
setblock ~18 ~0 ~48 stone 6 
setblock ~18 ~0 ~49 stonebrick 3 
setblock ~18 ~0 ~50 stone 6 
setblock ~18 ~0 ~51 stonebrick 3 
setblock ~18 ~0 ~52 stone 6 
setblock ~18 ~0 ~53 stonebrick 3 
setblock ~18 ~0 ~54 stone 6 
setblock ~18 ~0 ~55 stonebrick 3 
setblock ~18 ~0 ~56 stone 6 
setblock ~18 ~0 ~57 stonebrick 3 
setblock ~18 ~0 ~58 stone 6 
setblock ~18 ~0 ~59 stonebrick 3 
setblock ~18 ~0 ~60 stone 6 
setblock ~18 ~0 ~61 stonebrick 3 
setblock ~18 ~0 ~62 stone 6 
setblock ~18 ~0 ~63 stonebrick 3 
setblock ~18 ~0 ~64 stone 6 
setblock ~18 ~0 ~65 stonebrick 3 
setblock ~18 ~0 ~66 stone 6 
setblock ~18 ~0 ~67 stonebrick 3 
setblock ~18 ~0 ~68 stone 6 
setblock ~18 ~0 ~69 stonebrick 3 
setblock ~18 ~0 ~70 stone 6 
setblock ~18 ~0 ~71 stonebrick 3 
setblock ~18 ~0 ~72 stone 6 
setblock ~18 ~0 ~73 stonebrick 3 
setblock ~18 ~0 ~74 stone 6 
setblock ~18 ~0 ~75 stonebrick 3 
setblock ~18 ~0 ~76 stone 6 
setblock ~18 ~0 ~77 stonebrick 3 
setblock ~18 ~0 ~78 stone 6 
setblock ~18 ~0 ~79 stonebrick 3 
setblock ~18 ~0 ~80 stone 6 
setblock ~18 ~0 ~81 stonebrick 3 
setblock ~18 ~0 ~82 stone 6 
setblock ~18 ~0 ~83 stonebrick 3  
fill ~18 ~0 ~84 ~20 ~0 ~84 stone 
setblock ~18 ~0 ~85 stonebrick 3  
fill ~18 ~0 ~86 ~20 ~0 ~86 stone 
setblock ~19 ~0 ~28 stonebrick 3 
setblock ~19 ~0 ~29 stone 6 
setblock ~19 ~0 ~30 stonebrick 3 
setblock ~19 ~0 ~31 stone 6 
setblock ~19 ~0 ~32 stonebrick 3 
setblock ~19 ~0 ~33 stone 6 
setblock ~19 ~0 ~34 stonebrick 3 
setblock ~19 ~0 ~35 stone 6 
setblock ~19 ~0 ~36 stonebrick 3 
setblock ~19 ~0 ~37 stone 6 
setblock ~19 ~0 ~38 stonebrick 3 
setblock ~19 ~0 ~39 stone 6 
setblock ~19 ~0 ~40 stonebrick 3 
setblock ~19 ~0 ~41 stone 6 
setblock ~19 ~0 ~42 stonebrick 3 
setblock ~19 ~0 ~43 stone 6 
setblock ~19 ~0 ~44 stonebrick 3 
setblock ~19 ~0 ~45 stone 6 
setblock ~19 ~0 ~46 stonebrick 3 
setblock ~19 ~0 ~47 stone 6 
setblock ~19 ~0 ~48 stonebrick 3 
setblock ~19 ~0 ~49 stone 6 
setblock ~19 ~0 ~50 stonebrick 3 
setblock ~19 ~0 ~51 stone 6 
setblock ~19 ~0 ~52 stonebrick 3 
setblock ~19 ~0 ~53 stone 6 
setblock ~19 ~0 ~54 stonebrick 3 
setblock ~19 ~0 ~55 stone 6 
setblock ~19 ~0 ~56 stonebrick 3 
setblock ~19 ~0 ~57 stone 6 
setblock ~19 ~0 ~58 stonebrick 3 
setblock ~19 ~0 ~59 stone 6 
setblock ~19 ~0 ~60 stonebrick 3 
setblock ~19 ~0 ~61 stone 6 
setblock ~19 ~0 ~62 stonebrick 3 
setblock ~19 ~0 ~63 stone 6 
setblock ~19 ~0 ~64 stonebrick 3 
setblock ~19 ~0 ~65 stone 6 
setblock ~19 ~0 ~66 stonebrick 3 
setblock ~19 ~0 ~67 stone 6 
setblock ~19 ~0 ~68 stonebrick 3 
setblock ~19 ~0 ~69 stone 6 
setblock ~19 ~0 ~70 stonebrick 3 
setblock ~19 ~0 ~71 stone 6 
setblock ~19 ~0 ~72 stonebrick 3 
setblock ~19 ~0 ~73 stone 6 
setblock ~19 ~0 ~74 stonebrick 3 
setblock ~19 ~0 ~75 stone 6 
setblock ~19 ~0 ~76 stonebrick 3 
setblock ~19 ~0 ~77 stone 6 
setblock ~19 ~0 ~78 stonebrick 3 
setblock ~19 ~0 ~79 stone 6 
setblock ~19 ~0 ~80 stonebrick 3 
setblock ~19 ~0 ~81 stone 6 
setblock ~19 ~0 ~82 stonebrick 3 
setblock ~19 ~0 ~83 stone 6  
fill ~19 ~0 ~85 ~21 ~0 ~85 stone  
fill ~19 ~0 ~87 ~20 ~0 ~87 stone 
setblock ~20 ~0 ~28 stone 6 
setblock ~20 ~0 ~29 stonebrick 3 
setblock ~20 ~0 ~30 stone 6 
setblock ~20 ~0 ~31 stonebrick 3 
setblock ~20 ~0 ~32 stone 6 
setblock ~20 ~0 ~33 stonebrick 3 
setblock ~20 ~0 ~34 stone 6 
setblock ~20 ~0 ~35 stonebrick 3 
setblock ~20 ~0 ~36 stone 6 
setblock ~20 ~0 ~37 stonebrick 3 
setblock ~20 ~0 ~38 stone 6 
setblock ~20 ~0 ~39 stonebrick 3 
setblock ~20 ~0 ~40 stone 6 
setblock ~20 ~0 ~41 stonebrick 3 
setblock ~20 ~0 ~42 stone 6 
setblock ~20 ~0 ~43 stonebrick 3 
setblock ~20 ~0 ~44 stone 6 
setblock ~20 ~0 ~45 stonebrick 3 
setblock ~20 ~0 ~46 stone 6 
setblock ~20 ~0 ~47 stonebrick 3 
setblock ~20 ~0 ~48 stone 6 
setblock ~20 ~0 ~49 stonebrick 3 
setblock ~20 ~0 ~50 stone 6 
setblock ~20 ~0 ~51 stonebrick 3 
setblock ~20 ~0 ~52 stone 6 
setblock ~20 ~0 ~53 stonebrick 3 
setblock ~20 ~0 ~54 stone 6 
setblock ~20 ~0 ~55 stonebrick 3 
setblock ~20 ~0 ~56 stone 6 
setblock ~20 ~0 ~57 stonebrick 3 
setblock ~20 ~0 ~58 stone 6 
setblock ~20 ~0 ~59 stonebrick 3 
setblock ~20 ~0 ~60 stone 6 
setblock ~20 ~0 ~61 stonebrick 3 
setblock ~20 ~0 ~62 stone 6 
setblock ~20 ~0 ~63 stonebrick 3 
setblock ~20 ~0 ~64 stone 6 
setblock ~20 ~0 ~65 stonebrick 3 
setblock ~20 ~0 ~66 stone 6 
setblock ~20 ~0 ~67 stonebrick 3 
setblock ~20 ~0 ~68 stone 6 
setblock ~20 ~0 ~69 stonebrick 3 
setblock ~20 ~0 ~70 stone 6 
setblock ~20 ~0 ~71 stonebrick 3 
setblock ~20 ~0 ~72 stone 6 
setblock ~20 ~0 ~73 stonebrick 3 
setblock ~20 ~0 ~74 stone 6 
setblock ~20 ~0 ~75 stonebrick 3 
setblock ~20 ~0 ~76 stone 6 
setblock ~20 ~0 ~77 stonebrick 3 
setblock ~20 ~0 ~78 stone 6 
setblock ~20 ~0 ~79 stonebrick 3 
setblock ~20 ~0 ~80 stone 6 
setblock ~20 ~0 ~81 stonebrick 3 
setblock ~20 ~0 ~82 stone 6 
setblock ~20 ~0 ~83 stonebrick 3 
setblock ~21 ~0 ~28 stonebrick 3 
setblock ~21 ~0 ~29 stone 6 
setblock ~21 ~0 ~30 stonebrick 3 
setblock ~21 ~0 ~31 stone 6 
setblock ~21 ~0 ~32 stonebrick 3 
setblock ~21 ~0 ~33 stone 6 
setblock ~21 ~0 ~34 stonebrick 3 
setblock ~21 ~0 ~35 stone 6 
setblock ~21 ~0 ~36 stonebrick 3 
setblock ~21 ~0 ~37 stone 6 
setblock ~21 ~0 ~38 stonebrick 3 
setblock ~21 ~0 ~39 stone 6 
setblock ~21 ~0 ~40 stonebrick 3 
setblock ~21 ~0 ~41 stone 6 
setblock ~21 ~0 ~42 stonebrick 3 
setblock ~21 ~0 ~43 stone 6 
setblock ~21 ~0 ~44 stonebrick 3 
setblock ~21 ~0 ~45 stone 6 
setblock ~21 ~0 ~46 stonebrick 3 
setblock ~21 ~0 ~47 stone 6 
setblock ~21 ~0 ~48 stonebrick 3 
setblock ~21 ~0 ~49 stone 6 
setblock ~21 ~0 ~50 stonebrick 3 
setblock ~21 ~0 ~51 stone 6 
setblock ~21 ~0 ~52 stonebrick 3 
setblock ~21 ~0 ~53 stone 6 
setblock ~21 ~0 ~54 stonebrick 3 
setblock ~21 ~0 ~55 stone 6 
setblock ~21 ~0 ~56 stonebrick 3 
setblock ~21 ~0 ~57 stone 6 
setblock ~21 ~0 ~58 stonebrick 3 
setblock ~21 ~0 ~59 stone 6 
setblock ~21 ~0 ~60 stonebrick 3 
setblock ~21 ~0 ~61 stone 6 
setblock ~21 ~0 ~62 stonebrick 3 
setblock ~21 ~0 ~63 stone 6 
setblock ~21 ~0 ~64 stonebrick 3 
setblock ~21 ~0 ~65 stone 6 
setblock ~21 ~0 ~66 stonebrick 3 
setblock ~21 ~0 ~67 stone 6 
setblock ~21 ~0 ~68 stonebrick 3 
setblock ~21 ~0 ~69 stone 6 
setblock ~21 ~0 ~70 stonebrick 3 
setblock ~21 ~0 ~71 stone 6 
setblock ~21 ~0 ~72 stonebrick 3 
setblock ~21 ~0 ~73 stone 6 
setblock ~21 ~0 ~74 stonebrick 3 
setblock ~21 ~0 ~75 stone 6 
setblock ~21 ~0 ~76 stonebrick 3 
setblock ~21 ~0 ~77 stone 6 
setblock ~21 ~0 ~78 stonebrick 3 
setblock ~21 ~0 ~79 stone 6 
setblock ~21 ~0 ~80 stonebrick 3 
setblock ~21 ~0 ~81 stone 6 
setblock ~21 ~0 ~82 stonebrick 3 
setblock ~21 ~0 ~83 stone 6 
setblock ~21 ~0 ~84 stonebrick 3 
setblock ~21 ~0 ~86 stonebrick 3  
fill ~21 ~0 ~87 ~22 ~0 ~87 stone  
fill ~22 ~0 ~0 ~24 ~0 ~0 stone 
setblock ~22 ~0 ~28 stone 6 
setblock ~22 ~0 ~29 stonebrick 3 
setblock ~22 ~0 ~30 stone 6 
setblock ~22 ~0 ~31 stonebrick 3 
setblock ~22 ~0 ~32 stone 6 
setblock ~22 ~0 ~33 stonebrick 3 
setblock ~22 ~0 ~34 stone 6 
setblock ~22 ~0 ~35 stonebrick 3 
setblock ~22 ~0 ~36 stone 6 
setblock ~22 ~0 ~37 stonebrick 3 
setblock ~22 ~0 ~38 stone 6 
setblock ~22 ~0 ~39 stonebrick 3 
setblock ~22 ~0 ~40 stone 6 
setblock ~22 ~0 ~41 stonebrick 3 
setblock ~22 ~0 ~42 stone 6 
setblock ~22 ~0 ~43 stonebrick 3 
setblock ~22 ~0 ~44 stone 6 
setblock ~22 ~0 ~45 stonebrick 3 
setblock ~22 ~0 ~46 stone 6 
setblock ~22 ~0 ~47 stonebrick 3 
setblock ~22 ~0 ~48 stone 6 
setblock ~22 ~0 ~49 stonebrick 3 
setblock ~22 ~0 ~50 stone 6 
setblock ~22 ~0 ~51 stonebrick 3 
setblock ~22 ~0 ~52 stone 6 
setblock ~22 ~0 ~53 stonebrick 3 
setblock ~22 ~0 ~54 stone 6 
setblock ~22 ~0 ~55 stonebrick 3 
setblock ~22 ~0 ~56 stone 6 
setblock ~22 ~0 ~57 stonebrick 3 
setblock ~22 ~0 ~58 stone 6 
setblock ~22 ~0 ~59 stonebrick 3 
setblock ~22 ~0 ~60 stone 6 
setblock ~22 ~0 ~61 stonebrick 3 
setblock ~22 ~0 ~62 stone 6 
setblock ~22 ~0 ~63 stonebrick 3 
setblock ~22 ~0 ~64 stone 6 
setblock ~22 ~0 ~65 stonebrick 3 
setblock ~22 ~0 ~66 stone 6 
setblock ~22 ~0 ~67 stonebrick 3 
setblock ~22 ~0 ~68 stone 6 
setblock ~22 ~0 ~69 stonebrick 3 
setblock ~22 ~0 ~70 stone 6 
setblock ~22 ~0 ~71 stonebrick 3 
setblock ~22 ~0 ~72 stone 6 
setblock ~22 ~0 ~73 stonebrick 3 
setblock ~22 ~0 ~74 stone 6 
setblock ~22 ~0 ~75 stonebrick 3  
fill ~22 ~0 ~76 ~35 ~0 ~76 stone 
setblock ~22 ~0 ~77 stonebrick 3  
fill ~22 ~0 ~78 ~28 ~0 ~78 stone 
setblock ~22 ~0 ~79 stonebrick 3  
fill ~22 ~0 ~80 ~24 ~0 ~80 stone 
setblock ~22 ~0 ~81 stonebrick 3  
fill ~22 ~0 ~82 ~24 ~0 ~82 stone 
setblock ~22 ~0 ~83 stonebrick 3  
fill ~22 ~0 ~84 ~32 ~0 ~84 stone 
setblock ~22 ~0 ~85 stonebrick 3  
fill ~22 ~0 ~86 ~32 ~0 ~86 stone 
setblock ~23 ~0 ~28 stonebrick 3 
setblock ~23 ~0 ~29 stone 6 
setblock ~23 ~0 ~30 stonebrick 3 
setblock ~23 ~0 ~31 stone 0 
setblock ~23 ~0 ~32 stone_slab 8  
fill ~23 ~0 ~33 ~32 ~0 ~33 stone  
fill ~23 ~0 ~34 ~32 ~0 ~34 stone 
setblock ~23 ~0 ~35 stone_slab 8  
fill ~23 ~0 ~36 ~32 ~0 ~36 stone  
fill ~23 ~0 ~37 ~32 ~0 ~37 stone 
setblock ~23 ~0 ~38 stone_slab 8  
fill ~23 ~0 ~39 ~32 ~0 ~39 stone  
fill ~23 ~0 ~40 ~32 ~0 ~40 stone 
setblock ~23 ~0 ~41 stone_slab 8  
fill ~23 ~0 ~42 ~32 ~0 ~42 stone  
fill ~23 ~0 ~43 ~32 ~0 ~43 stone 
setblock ~23 ~0 ~44 stone_slab 8  
fill ~23 ~0 ~45 ~32 ~0 ~45 stone  
fill ~23 ~0 ~46 ~29 ~0 ~46 stone 
setblock ~23 ~0 ~47 stone_slab 8  
fill ~23 ~0 ~48 ~32 ~0 ~48 stone  
fill ~23 ~0 ~49 ~32 ~0 ~49 stone 
setblock ~23 ~0 ~50 stone_slab 8  
fill ~23 ~0 ~51 ~32 ~0 ~51 stone  
fill ~23 ~0 ~52 ~32 ~0 ~52 stone 
setblock ~23 ~0 ~53 stone_slab 8  
fill ~23 ~0 ~54 ~32 ~0 ~54 stone  
fill ~23 ~0 ~55 ~32 ~0 ~55 stone 
setblock ~23 ~0 ~56 stone_slab 8  
fill ~23 ~0 ~57 ~32 ~0 ~57 stone  
fill ~23 ~0 ~58 ~32 ~0 ~58 stone 
setblock ~23 ~0 ~59 stone_slab 8  
fill ~23 ~0 ~60 ~32 ~0 ~60 stone  
fill ~23 ~0 ~61 ~32 ~0 ~61 stone 
setblock ~23 ~0 ~62 stone_slab 8  
fill ~23 ~0 ~63 ~30 ~0 ~63 stone  
fill ~23 ~0 ~64 ~24 ~0 ~64 stone 
setblock ~23 ~0 ~65 stone_slab 8  
fill ~23 ~0 ~66 ~24 ~0 ~66 stone  
fill ~23 ~0 ~67 ~24 ~0 ~67 stone 
setblock ~23 ~0 ~68 stone_slab 8  
fill ~23 ~0 ~69 ~23 ~0 ~70 stone 
setblock ~23 ~0 ~71 stone_slab 8  
fill ~23 ~0 ~72 ~24 ~0 ~72 stone  
fill ~23 ~0 ~73 ~32 ~0 ~73 stone 
setblock ~23 ~0 ~74 stone_slab 8  
fill ~23 ~0 ~75 ~32 ~0 ~75 stone  
fill ~23 ~0 ~77 ~32 ~0 ~77 stone  
fill ~23 ~0 ~79 ~26 ~0 ~79 stone  
fill ~23 ~0 ~81 ~28 ~0 ~81 stone  
fill ~23 ~0 ~83 ~26 ~0 ~83 stone  
fill ~23 ~0 ~85 ~35 ~0 ~85 stone  
fill ~23 ~0 ~87 ~30 ~0 ~87 stone  
fill ~24 ~0 ~3 ~26 ~0 ~3 stone  
fill ~24 ~0 ~4 ~26 ~0 ~4 stone  
fill ~24 ~0 ~5 ~37 ~0 ~5 stone  
fill ~24 ~0 ~6 ~25 ~0 ~6 stone  
fill ~24 ~0 ~7 ~25 ~0 ~7 stone  
fill ~24 ~0 ~8 ~25 ~0 ~8 stone  
fill ~24 ~0 ~9 ~25 ~0 ~9 stone  
fill ~24 ~0 ~10 ~25 ~0 ~10 stone 
setblock ~24 ~0 ~27 stonebrick 3 
setblock ~24 ~0 ~28 stone 6 
setblock ~24 ~0 ~29 stone_slab 8 
setblock ~24 ~0 ~30 stone 6  
fill ~24 ~0 ~32 ~31 ~0 ~32 stone  
fill ~24 ~0 ~35 ~31 ~0 ~35 stone  
fill ~24 ~0 ~38 ~31 ~0 ~38 stone  
fill ~24 ~0 ~41 ~31 ~0 ~41 stone  
fill ~24 ~0 ~44 ~31 ~0 ~44 stone  
fill ~24 ~0 ~47 ~31 ~0 ~47 stone  
fill ~24 ~0 ~50 ~31 ~0 ~50 stone  
fill ~24 ~0 ~53 ~31 ~0 ~53 stone  
fill ~24 ~0 ~56 ~31 ~0 ~56 stone  
fill ~24 ~0 ~59 ~31 ~0 ~59 stone  
fill ~24 ~0 ~62 ~31 ~0 ~62 stone  
fill ~24 ~0 ~65 ~31 ~0 ~65 stone  
fill ~24 ~0 ~68 ~31 ~0 ~68 stone  
fill ~24 ~0 ~70 ~24 ~0 ~75 stone  
fill ~24 ~0 ~88 ~28 ~0 ~88 stone 
setblock ~25 ~0 ~26 stonebrick 3 
setblock ~25 ~0 ~27 stone 6 
setblock ~25 ~0 ~28 stonebrick 3  
fill ~25 ~0 ~29 ~31 ~0 ~29 stone 
setblock ~25 ~0 ~30 stonebrick 3  
fill ~25 ~0 ~71 ~30 ~0 ~71 stone  
fill ~25 ~0 ~74 ~31 ~0 ~74 stone  
fill ~25 ~0 ~80 ~27 ~0 ~80 stone  
fill ~25 ~0 ~82 ~27 ~0 ~82 stone  
fill ~25 ~0 ~89 ~27 ~0 ~89 stone  
fill ~26 ~0 ~6 ~35 ~0 ~6 stone  
fill ~26 ~0 ~7 ~35 ~0 ~7 stone  
fill ~26 ~0 ~8 ~35 ~0 ~8 stone  
fill ~26 ~0 ~9 ~35 ~0 ~9 stone  
fill ~26 ~0 ~10 ~35 ~0 ~10 stone  
fill ~26 ~0 ~11 ~35 ~0 ~11 stone  
fill ~26 ~0 ~12 ~35 ~0 ~12 stone 
setblock ~26 ~0 ~25 stonebrick 3 
setblock ~26 ~0 ~26 stone 6 
setblock ~26 ~0 ~27 stonebrick 3  
fill ~26 ~0 ~28 ~35 ~0 ~28 stone  
fill ~26 ~0 ~30 ~35 ~0 ~30 stone  
fill ~26 ~0 ~64 ~29 ~0 ~64 stone  
fill ~26 ~0 ~67 ~29 ~0 ~67 stone  
fill ~26 ~0 ~70 ~29 ~0 ~70 stone  
fill ~26 ~0 ~72 ~27 ~0 ~72 stone 
setblock ~26 ~0 ~90 stone 0 
setblock ~27 ~0 ~24 stonebrick 3 
setblock ~27 ~0 ~25 stone 6 
setblock ~27 ~0 ~26 stonebrick 3  
fill ~27 ~0 ~27 ~35 ~0 ~27 stone  
fill ~27 ~0 ~31 ~32 ~0 ~31 stone  
fill ~27 ~0 ~66 ~28 ~0 ~66 stone  
fill ~27 ~0 ~69 ~29 ~0 ~69 stone  
fill ~27 ~0 ~79 ~36 ~0 ~79 stone  
fill ~27 ~0 ~83 ~29 ~0 ~83 stone 
setblock ~28 ~0 ~23 stonebrick 3 
setblock ~28 ~0 ~24 stone 6 
setblock ~28 ~0 ~25 stonebrick 3 
setblock ~28 ~0 ~26 stone 6 
setblock ~28 ~0 ~82 stone 6  
fill ~28 ~0 ~89 ~35 ~0 ~89 stone  
fill ~29 ~0 ~4 ~31 ~0 ~4 stone 
setblock ~29 ~0 ~22 stonebrick 3 
setblock ~29 ~0 ~23 stone 6 
setblock ~29 ~0 ~24 stonebrick 3 
setblock ~29 ~0 ~25 stone 6 
setblock ~29 ~0 ~26 stonebrick 3 
setblock ~29 ~0 ~78 stone 0  
fill ~29 ~0 ~80 ~29 ~0 ~83 stone  
fill ~29 ~0 ~88 ~34 ~0 ~88 stone 
setblock ~30 ~0 ~21 stonebrick 3 
setblock ~30 ~0 ~22 stone 6 
setblock ~30 ~0 ~23 stonebrick 3 
setblock ~30 ~0 ~24 stone 6 
setblock ~30 ~0 ~25 stonebrick 3 
setblock ~30 ~0 ~26 stone 6  
fill ~30 ~0 ~78 ~32 ~0 ~78 stone  
fill ~30 ~0 ~81 ~30 ~0 ~86 stone 
setblock ~31 ~0 ~20 stonebrick 3 
setblock ~31 ~0 ~21 stone 6 
setblock ~31 ~0 ~22 stonebrick 3 
setblock ~31 ~0 ~23 stone 6 
setblock ~31 ~0 ~24 stonebrick 3 
setblock ~31 ~0 ~25 stone 6 
setblock ~31 ~0 ~26 stonebrick 3  
fill ~31 ~0 ~46 ~32 ~0 ~46 stone  
fill ~31 ~0 ~64 ~32 ~0 ~64 stone  
fill ~31 ~0 ~69 ~32 ~0 ~69 stone  
fill ~31 ~0 ~80 ~31 ~0 ~83 stone  
fill ~31 ~0 ~87 ~32 ~0 ~87 stone 
setblock ~32 ~0 ~19 stonebrick 3 
setblock ~32 ~0 ~20 stone 6 
setblock ~32 ~0 ~21 stonebrick 3 
setblock ~32 ~0 ~22 stone 6 
setblock ~32 ~0 ~23 stonebrick 3 
setblock ~32 ~0 ~24 stone 6 
setblock ~32 ~0 ~25 stonebrick 3 
setblock ~32 ~0 ~26 stone 6 
setblock ~32 ~0 ~29 stone_slab 8 
setblock ~32 ~0 ~32 stone_slab 8 
setblock ~32 ~0 ~35 stone_slab 8 
setblock ~32 ~0 ~38 stone_slab 8 
setblock ~32 ~0 ~41 stone_slab 8 
setblock ~32 ~0 ~44 stone_slab 8 
setblock ~32 ~0 ~47 stone_slab 8 
setblock ~32 ~0 ~50 stone_slab 8 
setblock ~32 ~0 ~53 stone_slab 8 
setblock ~32 ~0 ~56 stone_slab 8 
setblock ~32 ~0 ~59 stone_slab 8 
setblock ~32 ~0 ~62 stone_slab 8 
setblock ~32 ~0 ~63 stone 0 
setblock ~32 ~0 ~65 stone_slab 8  
fill ~32 ~0 ~66 ~32 ~0 ~67 stone 
setblock ~32 ~0 ~68 stone_slab 8 
setblock ~32 ~0 ~70 stone 0 
setblock ~32 ~0 ~71 stone_slab 8 
setblock ~32 ~0 ~72 stone 0 
setblock ~32 ~0 ~74 stone_slab 8  
fill ~32 ~0 ~82 ~32 ~4 ~82 stonebrick  
fill ~32 ~0 ~83 ~33 ~0 ~83 stone 
setblock ~33 ~0 ~18 stonebrick 3 
setblock ~33 ~0 ~19 stone 6 
setblock ~33 ~0 ~20 stonebrick 3  
fill ~33 ~0 ~21 ~35 ~0 ~21 stone 
setblock ~33 ~0 ~22 stonebrick 3 
setblock ~33 ~0 ~23 stone 6 
setblock ~33 ~0 ~24 stonebrick 3 
setblock ~33 ~0 ~25 stone 6 
setblock ~33 ~0 ~26 stonebrick 3  
fill ~33 ~0 ~29 ~35 ~0 ~29 stone  
fill ~33 ~0 ~31 ~35 ~0 ~31 stone  
fill ~33 ~0 ~32 ~35 ~0 ~32 stone  
fill ~33 ~0 ~33 ~35 ~0 ~33 stone  
fill ~33 ~0 ~34 ~35 ~0 ~34 stone  
fill ~33 ~0 ~35 ~35 ~0 ~35 stone  
fill ~33 ~0 ~36 ~35 ~0 ~36 stone  
fill ~33 ~0 ~37 ~35 ~0 ~37 stone  
fill ~33 ~0 ~38 ~35 ~0 ~38 stone  
fill ~33 ~0 ~39 ~35 ~0 ~39 stone  
fill ~33 ~0 ~40 ~35 ~0 ~40 stone  
fill ~33 ~0 ~41 ~35 ~0 ~41 stone  
fill ~33 ~0 ~42 ~35 ~0 ~42 stone  
fill ~33 ~0 ~43 ~35 ~0 ~43 stone  
fill ~33 ~0 ~44 ~35 ~0 ~44 stone  
fill ~33 ~0 ~45 ~35 ~0 ~45 stone  
fill ~33 ~0 ~46 ~35 ~0 ~46 stone  
fill ~33 ~0 ~47 ~35 ~0 ~47 stone  
fill ~33 ~0 ~48 ~35 ~0 ~48 stone  
fill ~33 ~0 ~49 ~35 ~0 ~49 stone  
fill ~33 ~0 ~50 ~35 ~0 ~50 stone  
fill ~33 ~0 ~51 ~35 ~0 ~51 stone  
fill ~33 ~0 ~52 ~35 ~0 ~52 stone  
fill ~33 ~0 ~53 ~35 ~0 ~53 stone  
fill ~33 ~0 ~54 ~35 ~0 ~54 stone  
fill ~33 ~0 ~55 ~35 ~0 ~55 stone  
fill ~33 ~0 ~56 ~35 ~0 ~56 stone  
fill ~33 ~0 ~57 ~35 ~0 ~57 stone  
fill ~33 ~0 ~58 ~35 ~0 ~58 stone  
fill ~33 ~0 ~59 ~35 ~0 ~59 stone  
fill ~33 ~0 ~60 ~35 ~0 ~60 stone  
fill ~33 ~0 ~61 ~35 ~0 ~61 stone  
fill ~33 ~0 ~62 ~35 ~0 ~62 stone  
fill ~33 ~0 ~63 ~35 ~0 ~63 stone  
fill ~33 ~0 ~64 ~35 ~0 ~64 stone  
fill ~33 ~0 ~65 ~35 ~0 ~65 stone  
fill ~33 ~0 ~66 ~35 ~0 ~66 stone  
fill ~33 ~0 ~67 ~35 ~0 ~67 stone  
fill ~33 ~0 ~68 ~35 ~0 ~68 stone  
fill ~33 ~0 ~69 ~35 ~0 ~69 stone  
fill ~33 ~0 ~70 ~35 ~0 ~70 stone  
fill ~33 ~0 ~71 ~35 ~0 ~71 stone  
fill ~33 ~0 ~72 ~35 ~0 ~72 stone  
fill ~33 ~0 ~73 ~35 ~0 ~73 stone  
fill ~33 ~0 ~74 ~35 ~0 ~74 stone  
fill ~33 ~0 ~75 ~35 ~0 ~75 stone  
fill ~33 ~0 ~77 ~33 ~0 ~84 stone  
fill ~33 ~0 ~86 ~33 ~0 ~87 stone  
fill ~34 ~0 ~4 ~36 ~0 ~4 stone  
fill ~34 ~0 ~18 ~35 ~0 ~18 stone 
setblock ~34 ~0 ~19 stonebrick 3 
setblock ~34 ~0 ~20 stone 6 
setblock ~34 ~0 ~22 stone 6 
setblock ~34 ~0 ~23 stonebrick 3  
fill ~34 ~0 ~24 ~35 ~0 ~24 stone 
setblock ~34 ~0 ~25 stonebrick 3  
fill ~34 ~0 ~26 ~35 ~0 ~26 stone  
fill ~34 ~0 ~77 ~35 ~0 ~77 stone  
fill ~34 ~0 ~78 ~35 ~0 ~78 stone  

KittysCommands:   
fill ~34 ~0 ~80 ~35 ~0 ~80 stone  
fill ~34 ~0 ~81 ~35 ~0 ~81 stone  
fill ~34 ~0 ~82 ~35 ~0 ~82 stone  
fill ~34 ~0 ~83 ~35 ~0 ~83 stone  
fill ~34 ~0 ~84 ~35 ~0 ~84 stone  
fill ~34 ~0 ~86 ~35 ~0 ~86 stone  
fill ~34 ~0 ~87 ~37 ~0 ~87 stone  
fill ~35 ~0 ~19 ~36 ~0 ~19 stone 
setblock ~35 ~0 ~20 stonebrick 3 
setblock ~35 ~0 ~22 stonebrick 3  
fill ~35 ~0 ~23 ~36 ~0 ~23 stone 
setblock ~35 ~0 ~25 stone 6  
fill ~35 ~0 ~88 ~36 ~0 ~88 stone  
fill ~36 ~0 ~6 ~37 ~0 ~6 stone  
fill ~36 ~0 ~7 ~37 ~0 ~7 stone  
fill ~36 ~0 ~8 ~36 ~0 ~18 stone 
setblock ~36 ~0 ~20 stone 6  
fill ~36 ~0 ~21 ~37 ~0 ~21 stone 
setblock ~36 ~0 ~22 stone 6  
fill ~36 ~0 ~24 ~36 ~0 ~89 stone  
fill ~37 ~0 ~10 ~37 ~0 ~12 stone  
fill ~37 ~0 ~15 ~37 ~0 ~17 stone  
fill ~37 ~0 ~25 ~37 ~0 ~27 stone  
fill ~37 ~0 ~30 ~37 ~0 ~32 stone  
fill ~37 ~0 ~35 ~37 ~0 ~37 stone  
fill ~37 ~0 ~40 ~37 ~0 ~42 stone  
fill ~37 ~0 ~45 ~37 ~0 ~47 stone  
fill ~37 ~0 ~50 ~37 ~0 ~52 stone  
fill ~37 ~0 ~55 ~37 ~0 ~57 stone  
fill ~37 ~0 ~60 ~37 ~0 ~62 stone  
fill ~37 ~0 ~65 ~37 ~0 ~67 stone  
fill ~37 ~0 ~70 ~37 ~0 ~72 stone  
fill ~37 ~0 ~75 ~37 ~0 ~77 stone  
fill ~37 ~0 ~80 ~37 ~0 ~82 stone  
fill ~37 ~0 ~85 ~37 ~0 ~87 stone  
fill ~2 ~1 ~5 ~2 ~2 ~5 stone  
fill ~2 ~1 ~6 ~2 ~16 ~6 stonebrick  
fill ~2 ~1 ~7 ~2 ~2 ~7 stone  
fill ~2 ~1 ~10 ~2 ~2 ~10 stone  
fill ~2 ~1 ~11 ~2 ~16 ~11 stonebrick  
fill ~2 ~1 ~12 ~2 ~2 ~12 stone  
fill ~2 ~1 ~15 ~2 ~2 ~15 stone  
fill ~2 ~1 ~16 ~2 ~16 ~16 stonebrick  
fill ~2 ~1 ~17 ~2 ~5 ~17 stone  
fill ~2 ~1 ~21 ~2 ~16 ~21 stonebrick  
fill ~2 ~1 ~25 ~2 ~5 ~25 stone  
fill ~2 ~1 ~26 ~2 ~16 ~26 stonebrick  
fill ~2 ~1 ~27 ~2 ~2 ~27 stone  
fill ~2 ~1 ~30 ~2 ~2 ~30 stone  
fill ~2 ~1 ~31 ~2 ~16 ~31 stonebrick  
fill ~2 ~1 ~32 ~2 ~2 ~32 stone  
fill ~2 ~1 ~35 ~2 ~2 ~35 stone  
fill ~2 ~1 ~36 ~2 ~16 ~36 stonebrick  
fill ~2 ~1 ~37 ~2 ~2 ~37 stone  
fill ~2 ~1 ~40 ~2 ~2 ~40 stone  
fill ~2 ~1 ~41 ~2 ~16 ~41 stonebrick  
fill ~2 ~1 ~42 ~2 ~2 ~42 stone  
fill ~2 ~1 ~45 ~2 ~2 ~45 stone  
fill ~2 ~1 ~46 ~2 ~16 ~46 stonebrick  
fill ~2 ~1 ~47 ~2 ~2 ~47 stone  
fill ~2 ~1 ~50 ~2 ~2 ~50 stone  
fill ~2 ~1 ~51 ~2 ~16 ~51 stonebrick  
fill ~2 ~1 ~52 ~2 ~2 ~52 stone  
fill ~2 ~1 ~55 ~2 ~2 ~55 stone  
fill ~2 ~1 ~56 ~2 ~16 ~56 stonebrick  
fill ~2 ~1 ~57 ~2 ~2 ~57 stone  
fill ~2 ~1 ~60 ~2 ~2 ~60 stone  
fill ~2 ~1 ~61 ~2 ~16 ~61 stonebrick  
fill ~2 ~1 ~62 ~2 ~2 ~62 stone  
fill ~2 ~1 ~65 ~2 ~2 ~65 stone  
fill ~2 ~1 ~66 ~2 ~16 ~66 stonebrick  
fill ~2 ~1 ~67 ~2 ~2 ~67 stone  
fill ~2 ~1 ~70 ~2 ~2 ~70 stone  
fill ~2 ~1 ~71 ~2 ~16 ~71 stonebrick  
fill ~2 ~1 ~72 ~2 ~2 ~72 stone  
fill ~2 ~1 ~75 ~2 ~2 ~75 stone  
fill ~2 ~1 ~76 ~2 ~16 ~76 stonebrick  
fill ~2 ~1 ~77 ~2 ~2 ~77 stone  
fill ~2 ~1 ~80 ~2 ~2 ~80 stone  
fill ~2 ~1 ~81 ~2 ~16 ~81 stonebrick  
fill ~2 ~1 ~82 ~2 ~2 ~82 stone  
fill ~2 ~1 ~85 ~2 ~2 ~85 stone  
fill ~2 ~1 ~86 ~2 ~16 ~86 stonebrick  
fill ~2 ~1 ~87 ~2 ~2 ~87 stone  
fill ~3 ~1 ~4 ~3 ~2 ~4 stone  
fill ~3 ~1 ~5 ~15 ~1 ~5 stonebrick  
fill ~3 ~1 ~6 ~3 ~23 ~6 stonebrick  
fill ~3 ~1 ~7 ~3 ~23 ~7 stonebrick  
fill ~3 ~1 ~8 ~3 ~17 ~8 stonebrick  
fill ~3 ~1 ~9 ~3 ~17 ~9 stonebrick  
fill ~3 ~1 ~10 ~3 ~23 ~10 stonebrick  
fill ~3 ~1 ~11 ~3 ~23 ~11 stonebrick  
fill ~3 ~1 ~12 ~36 ~1 ~12 stonebrick  
fill ~3 ~1 ~13 ~3 ~23 ~13 stonebrick  
fill ~3 ~1 ~14 ~3 ~23 ~14 stonebrick  
fill ~3 ~1 ~15 ~3 ~23 ~15 stonebrick  
fill ~3 ~1 ~16 ~3 ~23 ~16 stonebrick  
fill ~3 ~1 ~17 ~3 ~23 ~17 stonebrick  
fill ~3 ~1 ~18 ~3 ~17 ~18 stonebrick  
fill ~3 ~1 ~19 ~3 ~1 ~20 spruce_door  
fill ~3 ~1 ~21 ~3 ~23 ~21 stonebrick  
fill ~3 ~1 ~22 ~3 ~1 ~23 spruce_door  
fill ~3 ~1 ~24 ~3 ~17 ~24 stonebrick  
fill ~3 ~1 ~25 ~3 ~23 ~25 stonebrick  
fill ~3 ~1 ~26 ~3 ~23 ~26 stonebrick  
fill ~3 ~1 ~27 ~3 ~23 ~27 stonebrick  
fill ~3 ~1 ~28 ~3 ~17 ~28 stonebrick  
fill ~3 ~1 ~29 ~3 ~17 ~29 stonebrick  
fill ~3 ~1 ~30 ~3 ~23 ~30 stonebrick  
fill ~3 ~1 ~31 ~3 ~23 ~31 stonebrick  
fill ~3 ~1 ~32 ~3 ~23 ~32 stonebrick  
fill ~3 ~1 ~33 ~3 ~17 ~33 stonebrick  
fill ~3 ~1 ~34 ~3 ~17 ~34 stonebrick  
fill ~3 ~1 ~35 ~3 ~23 ~35 stonebrick  
fill ~3 ~1 ~36 ~3 ~23 ~36 stonebrick  
fill ~3 ~1 ~37 ~3 ~23 ~37 stonebrick  
fill ~3 ~1 ~38 ~3 ~17 ~38 stonebrick  
fill ~3 ~1 ~39 ~3 ~17 ~39 stonebrick  
fill ~3 ~1 ~40 ~3 ~23 ~40 stonebrick  
fill ~3 ~1 ~41 ~3 ~23 ~41 stonebrick  
fill ~3 ~1 ~42 ~3 ~23 ~42 stonebrick  
fill ~3 ~1 ~43 ~3 ~17 ~43 stonebrick  
fill ~3 ~1 ~44 ~3 ~17 ~44 stonebrick  
fill ~3 ~1 ~45 ~3 ~23 ~45 stonebrick  
fill ~3 ~1 ~46 ~3 ~23 ~46 stonebrick  
fill ~3 ~1 ~47 ~3 ~23 ~47 stonebrick  
fill ~3 ~1 ~48 ~3 ~17 ~48 stonebrick  
fill ~3 ~1 ~49 ~3 ~17 ~49 stonebrick  
fill ~3 ~1 ~50 ~3 ~23 ~50 stonebrick  
fill ~3 ~1 ~51 ~3 ~23 ~51 stonebrick  
fill ~3 ~1 ~52 ~3 ~23 ~52 stonebrick  
fill ~3 ~1 ~53 ~3 ~17 ~53 stonebrick  
fill ~3 ~1 ~54 ~3 ~17 ~54 stonebrick  
fill ~3 ~1 ~55 ~3 ~23 ~55 stonebrick  
fill ~3 ~1 ~56 ~3 ~23 ~56 stonebrick  
fill ~3 ~1 ~57 ~3 ~23 ~57 stonebrick  
fill ~3 ~1 ~58 ~3 ~17 ~58 stonebrick  
fill ~3 ~1 ~59 ~3 ~17 ~59 stonebrick  
fill ~3 ~1 ~60 ~3 ~23 ~60 stonebrick  
fill ~3 ~1 ~61 ~3 ~23 ~61 stonebrick  
fill ~3 ~1 ~62 ~3 ~23 ~62 stonebrick  
fill ~3 ~1 ~63 ~3 ~17 ~63 stonebrick  
fill ~3 ~1 ~64 ~3 ~17 ~64 stonebrick  
fill ~3 ~1 ~65 ~3 ~23 ~65 stonebrick  
fill ~3 ~1 ~66 ~3 ~23 ~66 stonebrick  
fill ~3 ~1 ~67 ~3 ~23 ~67 stonebrick  
fill ~3 ~1 ~68 ~3 ~17 ~68 stonebrick  
fill ~3 ~1 ~69 ~3 ~17 ~69 stonebrick  
fill ~3 ~1 ~70 ~3 ~23 ~70 stonebrick  
fill ~3 ~1 ~71 ~3 ~23 ~71 stonebrick  
fill ~3 ~1 ~72 ~3 ~23 ~72 stonebrick  
fill ~3 ~1 ~73 ~3 ~17 ~73 stonebrick  
fill ~3 ~1 ~74 ~3 ~17 ~74 stonebrick  
fill ~3 ~1 ~75 ~3 ~23 ~75 stonebrick  
fill ~3 ~1 ~76 ~3 ~23 ~76 stonebrick  
fill ~3 ~1 ~77 ~3 ~23 ~77 stonebrick  
fill ~3 ~1 ~78 ~3 ~17 ~78 stonebrick  
fill ~3 ~1 ~79 ~12 ~1 ~79 stonebrick  
fill ~3 ~1 ~80 ~3 ~46 ~80 stonebrick  
fill ~3 ~1 ~81 ~3 ~46 ~81 stonebrick  
fill ~3 ~1 ~82 ~3 ~46 ~82 stonebrick  
fill ~3 ~1 ~83 ~3 ~17 ~83 stonebrick  
fill ~3 ~1 ~84 ~3 ~17 ~84 stonebrick  
fill ~3 ~1 ~85 ~3 ~46 ~85 stonebrick  
fill ~3 ~1 ~86 ~3 ~46 ~86 stonebrick  
fill ~3 ~1 ~87 ~6 ~1 ~87 stonebrick  
fill ~3 ~1 ~88 ~3 ~46 ~88 stonebrick  
fill ~3 ~1 ~89 ~3 ~6 ~89 stonebrick  
fill ~4 ~1 ~4 ~4 ~16 ~4 stonebrick  
fill ~4 ~1 ~17 ~8 ~1 ~17 fence  
fill ~4 ~1 ~18 ~4 ~3 ~18 stonebrick  
fill ~4 ~1 ~21 ~4 ~4 ~21 stonebrick  
fill ~4 ~1 ~24 ~4 ~3 ~24 stonebrick  
fill ~4 ~1 ~26 ~4 ~3 ~26 stone  
fill ~4 ~1 ~29 ~4 ~3 ~29 stone  
fill ~4 ~1 ~32 ~4 ~3 ~32 stone  
fill ~4 ~1 ~35 ~4 ~3 ~35 stonebrick 
setblock ~4 ~1 ~36 stone_brick_stairs 3  
fill ~4 ~1 ~37 ~4 ~2 ~37 cobblestone_wall  
fill ~4 ~1 ~38 ~4 ~2 ~38 cobblestone_wall  
fill ~4 ~1 ~39 ~4 ~2 ~39 cobblestone_wall 
setblock ~4 ~1 ~40 stone_brick_stairs 2  
fill ~4 ~1 ~41 ~4 ~3 ~41 stonebrick  
fill ~4 ~1 ~44 ~4 ~3 ~44 stone  
fill ~4 ~1 ~47 ~4 ~3 ~47 stone  
fill ~4 ~1 ~50 ~4 ~3 ~50 stonebrick 
setblock ~4 ~1 ~51 stone_brick_stairs 3  
fill ~4 ~1 ~52 ~4 ~2 ~52 cobblestone_wall  
fill ~4 ~1 ~53 ~4 ~2 ~53 cobblestone_wall  
fill ~4 ~1 ~54 ~4 ~2 ~54 cobblestone_wall 
setblock ~4 ~1 ~55 stone_brick_stairs 2  
fill ~4 ~1 ~56 ~4 ~3 ~56 stonebrick  
fill ~4 ~1 ~59 ~4 ~3 ~59 stone  
fill ~4 ~1 ~62 ~4 ~3 ~62 stone  
fill ~4 ~1 ~65 ~4 ~3 ~65 stonebrick 
setblock ~4 ~1 ~66 stone_brick_stairs 3  
fill ~4 ~1 ~67 ~4 ~2 ~67 cobblestone_wall  
fill ~4 ~1 ~68 ~4 ~2 ~68 cobblestone_wall  
fill ~4 ~1 ~69 ~4 ~2 ~69 cobblestone_wall 
setblock ~4 ~1 ~70 stone_brick_stairs 2  
fill ~4 ~1 ~71 ~4 ~3 ~71 stonebrick  
fill ~4 ~1 ~74 ~4 ~3 ~74 stone  
fill ~4 ~1 ~84 ~5 ~1 ~84 stone_stairs  
fill ~4 ~1 ~88 ~4 ~5 ~88 stonebrick  
fill ~5 ~1 ~4 ~5 ~2 ~4 stone 
setblock ~5 ~1 ~13 stone_stairs 0 
setblock ~5 ~1 ~21 cauldron 6 
setblock ~5 ~1 ~26 stone_stairs 1 
setblock ~5 ~1 ~29 stone_stairs 1 
setblock ~5 ~1 ~32 stone_stairs 1 
setblock ~5 ~1 ~44 stone_stairs 1 
setblock ~5 ~1 ~47 stone_stairs 1 
setblock ~5 ~1 ~59 stone_stairs 1 
setblock ~5 ~1 ~62 stone_stairs 1 
setblock ~5 ~1 ~74 stone_stairs 1  
fill ~6 ~1 ~13 ~6 ~8 ~13 stonebrick 
setblock ~6 ~1 ~21 jukebox 0 
setblock ~6 ~1 ~77 stone_stairs 2  
fill ~6 ~1 ~78 ~6 ~3 ~78 stone  
fill ~6 ~1 ~84 ~6 ~7 ~84 stonebrick 
setblock ~6 ~1 ~85 spruce_door 0  
fill ~6 ~1 ~86 ~6 ~8 ~86 stonebrick 
setblock ~7 ~1 ~13 stone_brick_stairs 1  
fill ~7 ~1 ~27 ~12 ~1 ~27 stone_slab  
fill ~7 ~1 ~28 ~13 ~1 ~28 stone_slab  
fill ~7 ~1 ~29 ~7 ~2 ~29 fence  
fill ~7 ~1 ~30 ~15 ~1 ~30 stone_slab  
fill ~7 ~1 ~31 ~16 ~1 ~31 stone_slab  
fill ~7 ~1 ~32 ~7 ~2 ~32 fence  
fill ~7 ~1 ~33 ~16 ~1 ~33 stone_slab  
fill ~7 ~1 ~34 ~16 ~1 ~34 stone_slab  
fill ~7 ~1 ~35 ~7 ~2 ~35 fence  
fill ~7 ~1 ~36 ~16 ~1 ~36 stone_slab  
fill ~7 ~1 ~37 ~16 ~1 ~37 stone_slab  
fill ~7 ~1 ~38 ~7 ~2 ~38 fence  
fill ~7 ~1 ~39 ~16 ~1 ~39 stone_slab  
fill ~7 ~1 ~40 ~16 ~1 ~40 stone_slab  
fill ~7 ~1 ~41 ~7 ~2 ~41 fence  
fill ~7 ~1 ~42 ~16 ~1 ~42 stone_slab  
fill ~7 ~1 ~43 ~16 ~1 ~43 stone_slab  
fill ~7 ~1 ~44 ~7 ~2 ~44 fence  
fill ~7 ~1 ~45 ~16 ~1 ~45 stone_slab  
fill ~7 ~1 ~46 ~16 ~1 ~46 stone_slab  
fill ~7 ~1 ~47 ~7 ~2 ~47 fence  
fill ~7 ~1 ~48 ~16 ~1 ~48 stone_slab  
fill ~7 ~1 ~49 ~16 ~1 ~49 stone_slab  
fill ~7 ~1 ~50 ~7 ~2 ~50 fence  
fill ~7 ~1 ~51 ~16 ~1 ~51 stone_slab  
fill ~7 ~1 ~52 ~16 ~1 ~52 stone_slab  
fill ~7 ~1 ~53 ~7 ~2 ~53 fence  
fill ~7 ~1 ~54 ~16 ~1 ~54 stone_slab  
fill ~7 ~1 ~55 ~16 ~1 ~55 stone_slab  
fill ~7 ~1 ~56 ~7 ~2 ~56 fence  
fill ~7 ~1 ~57 ~16 ~1 ~57 stone_slab  
fill ~7 ~1 ~58 ~16 ~1 ~58 stone_slab  
fill ~7 ~1 ~59 ~7 ~2 ~59 fence  
fill ~7 ~1 ~60 ~16 ~1 ~60 stone_slab  
fill ~7 ~1 ~61 ~16 ~1 ~61 stone_slab  
fill ~7 ~1 ~62 ~7 ~2 ~62 fence  
fill ~7 ~1 ~63 ~16 ~1 ~63 stone_slab  
fill ~7 ~1 ~64 ~16 ~1 ~64 stone_slab  
fill ~7 ~1 ~65 ~7 ~2 ~65 fence  
fill ~7 ~1 ~66 ~16 ~1 ~66 stone_slab  
fill ~7 ~1 ~67 ~16 ~1 ~67 stone_slab  
fill ~7 ~1 ~68 ~7 ~2 ~68 fence  
fill ~7 ~1 ~69 ~16 ~1 ~69 stone_slab  
fill ~7 ~1 ~70 ~16 ~1 ~70 stone_slab  
fill ~7 ~1 ~71 ~7 ~2 ~71 fence  
fill ~7 ~1 ~72 ~16 ~1 ~72 stone_slab  
fill ~7 ~1 ~73 ~16 ~1 ~73 stone_slab  
fill ~7 ~1 ~74 ~7 ~2 ~74 fence  
fill ~7 ~1 ~75 ~16 ~1 ~75 stone_slab  
fill ~7 ~1 ~78 ~7 ~2 ~78 fence  
fill ~7 ~1 ~83 ~8 ~1 ~83 stonebrick  
fill ~7 ~1 ~87 ~8 ~1 ~87 spruce_door  
fill ~8 ~1 ~4 ~8 ~2 ~4 stone 
setblock ~8 ~1 ~13 stone_brick_stairs 0  
fill ~8 ~1 ~18 ~9 ~1 ~18 fence 
setblock ~8 ~1 ~29 stone_slab 0 
setblock ~8 ~1 ~32 stone_slab 0 
setblock ~8 ~1 ~35 stone_slab 0 
setblock ~8 ~1 ~38 stone_slab 0 
setblock ~8 ~1 ~41 stone_slab 0 
setblock ~8 ~1 ~44 stone_slab 0 
setblock ~8 ~1 ~47 stone_slab 0 
setblock ~8 ~1 ~50 stone_slab 0 
setblock ~8 ~1 ~53 stone_slab 0 
setblock ~8 ~1 ~56 stone_slab 0 
setblock ~8 ~1 ~59 stone_slab 0 
setblock ~8 ~1 ~62 stone_slab 0 
setblock ~8 ~1 ~65 stone_slab 0 
setblock ~8 ~1 ~68 stone_slab 0 
setblock ~8 ~1 ~71 stone_slab 0 
setblock ~8 ~1 ~74 stone_slab 0  
fill ~8 ~1 ~78 ~8 ~2 ~78 stonebrick  
fill ~8 ~1 ~80 ~8 ~3 ~80 stonebrick  
fill ~8 ~1 ~81 ~8 ~3 ~81 stonebrick  
fill ~8 ~1 ~82 ~8 ~3 ~82 stonebrick  
fill ~9 ~1 ~4 ~9 ~21 ~4 stonebrick 
setblock ~9 ~1 ~13 stone_brick_stairs 1  
fill ~9 ~1 ~19 ~10 ~1 ~19 fence 
setblock ~9 ~1 ~29 planks 5 
setblock ~9 ~1 ~32 planks 5 
setblock ~9 ~1 ~35 planks 5 
setblock ~9 ~1 ~38 planks 5 
setblock ~9 ~1 ~41 planks 5 
setblock ~9 ~1 ~44 planks 5 
setblock ~9 ~1 ~47 planks 5 
setblock ~9 ~1 ~50 planks 5 
setblock ~9 ~1 ~53 planks 5 
setblock ~9 ~1 ~56 planks 5 
setblock ~9 ~1 ~59 planks 5 
setblock ~9 ~1 ~62 planks 5 
setblock ~9 ~1 ~65 planks 5 
setblock ~9 ~1 ~68 planks 5 
setblock ~9 ~1 ~71 planks 5 
setblock ~9 ~1 ~74 planks 5  
fill ~9 ~1 ~78 ~9 ~2 ~78 fence 
setblock ~9 ~1 ~80 stone_stairs 3 
setblock ~9 ~1 ~83 spruce_door 1  
fill ~9 ~1 ~87 ~16 ~1 ~87 stonebrick  
fill ~10 ~1 ~4 ~10 ~2 ~4 stone 
setblock ~10 ~1 ~13 stone_brick_stairs 0  
fill ~10 ~1 ~20 ~11 ~1 ~20 fence  
fill ~10 ~1 ~29 ~12 ~1 ~29 stone_slab  
fill ~10 ~1 ~32 ~13 ~1 ~32 stone_slab  
fill ~10 ~1 ~35 ~13 ~1 ~35 stone_slab  
fill ~10 ~1 ~38 ~13 ~1 ~38 stone_slab  
fill ~10 ~1 ~41 ~13 ~1 ~41 stone_slab  
fill ~10 ~1 ~44 ~13 ~1 ~44 stone_slab  
fill ~10 ~1 ~47 ~13 ~1 ~47 stone_slab  
fill ~10 ~1 ~50 ~13 ~1 ~50 stone_slab  
fill ~10 ~1 ~53 ~13 ~1 ~53 stone_slab  
fill ~10 ~1 ~56 ~13 ~1 ~56 stone_slab  
fill ~10 ~1 ~59 ~13 ~1 ~59 stone_slab  
fill ~10 ~1 ~62 ~13 ~1 ~62 stone_slab  
fill ~10 ~1 ~65 ~13 ~1 ~65 stone_slab  
fill ~10 ~1 ~68 ~13 ~1 ~68 stone_slab  
fill ~10 ~1 ~71 ~13 ~1 ~71 stone_slab  
fill ~10 ~1 ~74 ~13 ~1 ~74 stone_slab 
setblock ~10 ~1 ~77 stone_stairs 2  
fill ~10 ~1 ~78 ~10 ~3 ~78 stone  
fill ~10 ~1 ~80 ~10 ~1 ~83 stonebrick  
fill ~11 ~1 ~13 ~11 ~8 ~13 stonebrick  
fill ~11 ~1 ~21 ~12 ~1 ~21 fence 
setblock ~11 ~1 ~80 stone_stairs 3  
fill ~11 ~1 ~83 ~12 ~1 ~83 stonebrick  
fill ~11 ~1 ~88 ~11 ~5 ~88 stonebrick 
setblock ~12 ~1 ~13 stone_stairs 1  
fill ~12 ~1 ~22 ~13 ~1 ~22 fence  
fill ~12 ~1 ~80 ~12 ~13 ~80 stonebrick 
setblock ~12 ~1 ~81 spruce_door 0  
fill ~12 ~1 ~82 ~12 ~13 ~82 stonebrick  
fill ~12 ~1 ~88 ~14 ~1 ~88 stonebrick  
fill ~12 ~1 ~89 ~12 ~6 ~89 stonebrick  
fill ~13 ~1 ~2 ~13 ~2 ~2 stone  
fill ~13 ~1 ~3 ~13 ~24 ~3 stonebrick  
fill ~13 ~1 ~4 ~13 ~2 ~4 stone 
setblock ~13 ~1 ~23 fence 0 
setblock ~13 ~1 ~29 planks 5  
fill ~13 ~1 ~80 ~13 ~3 ~80 stone  
fill ~13 ~1 ~82 ~13 ~3 ~82 stone  
fill ~13 ~1 ~89 ~13 ~18 ~89 stonebrick  
fill ~13 ~1 ~90 ~13 ~7 ~90 stonebrick  
fill ~14 ~1 ~1 ~25 ~1 ~1 stonebrick  
fill ~14 ~1 ~2 ~25 ~1 ~2 stonebrick  
fill ~14 ~1 ~3 ~15 ~1 ~3 stonebrick  
fill ~14 ~1 ~4 ~15 ~1 ~4 stonebrick  
fill ~14 ~1 ~6 ~15 ~1 ~6 stonebrick  
fill ~14 ~1 ~7 ~15 ~1 ~7 stonebrick  
fill ~14 ~1 ~8 ~15 ~1 ~8 stonebrick  
fill ~14 ~1 ~9 ~15 ~1 ~9 stonebrick  
fill ~14 ~1 ~10 ~15 ~1 ~10 stonebrick  
fill ~14 ~1 ~11 ~25 ~1 ~11 stonebrick  
fill ~14 ~1 ~13 ~14 ~6 ~13 stonebrick  
fill ~14 ~1 ~14 ~14 ~1 ~24 carpet 
setblock ~14 ~1 ~29 stone_slab 0 
setblock ~14 ~1 ~32 planks 5 
setblock ~14 ~1 ~35 planks 5 
setblock ~14 ~1 ~38 planks 5 
setblock ~14 ~1 ~41 planks 5 
setblock ~14 ~1 ~44 planks 5 
setblock ~14 ~1 ~47 planks 5 
setblock ~14 ~1 ~50 planks 5 
setblock ~14 ~1 ~53 planks 5 
setblock ~14 ~1 ~56 planks 5 
setblock ~14 ~1 ~59 planks 5 
setblock ~14 ~1 ~62 planks 5 
setblock ~14 ~1 ~65 planks 5 
setblock ~14 ~1 ~68 planks 5 
setblock ~14 ~1 ~71 planks 5 
setblock ~14 ~1 ~74 planks 5 
setblock ~14 ~1 ~80 stone_stairs 1 
setblock ~14 ~1 ~82 stone_stairs 1  
fill ~14 ~1 ~89 ~14 ~6 ~89 stonebrick  
fill ~15 ~1 ~0 ~15 ~2 ~0 stone  
fill ~15 ~1 ~13 ~16 ~1 ~13 cobblestone_wall  
fill ~15 ~1 ~14 ~16 ~1 ~14 stone_slab  
fill ~15 ~1 ~15 ~17 ~1 ~15 stone_slab  
fill ~15 ~1 ~16 ~15 ~1 ~23 stone_slab  
fill ~15 ~1 ~24 ~15 ~1 ~25 carpet  
fill ~15 ~1 ~29 ~15 ~2 ~29 fence 
setblock ~15 ~1 ~32 stone_slab 0 
setblock ~15 ~1 ~35 stone_slab 0 
setblock ~15 ~1 ~38 stone_slab 0 
setblock ~15 ~1 ~41 stone_slab 0 
setblock ~15 ~1 ~44 stone_slab 0 
setblock ~15 ~1 ~47 stone_slab 0 
setblock ~15 ~1 ~50 stone_slab 0 
setblock ~15 ~1 ~53 stone_slab 0 
setblock ~15 ~1 ~56 stone_slab 0 
setblock ~15 ~1 ~59 stone_slab 0 
setblock ~15 ~1 ~62 stone_slab 0 
setblock ~15 ~1 ~65 stone_slab 0 
setblock ~15 ~1 ~68 stone_slab 0 
setblock ~15 ~1 ~71 stone_slab 0 
setblock ~15 ~1 ~74 stone_slab 0  
fill ~15 ~1 ~88 ~15 ~5 ~88 stonebrick  
fill ~16 ~1 ~0 ~16 ~24 ~0 stonebrick  
fill ~16 ~1 ~16 ~22 ~1 ~16 stone_brick_stairs  
fill ~16 ~1 ~17 ~16 ~1 ~23 stone_brick_stairs 
setblock ~16 ~1 ~24 stone_slab 0  
fill ~16 ~1 ~25 ~16 ~1 ~26 carpet  
fill ~16 ~1 ~32 ~16 ~2 ~32 fence  
fill ~16 ~1 ~35 ~16 ~2 ~35 fence  
fill ~16 ~1 ~38 ~16 ~2 ~38 fence  
fill ~16 ~1 ~41 ~16 ~2 ~41 fence  
fill ~16 ~1 ~44 ~16 ~2 ~44 fence  
fill ~16 ~1 ~47 ~16 ~2 ~47 fence  
fill ~16 ~1 ~50 ~16 ~2 ~50 fence  
fill ~16 ~1 ~53 ~16 ~2 ~53 fence  
fill ~16 ~1 ~56 ~16 ~2 ~56 fence  
fill ~16 ~1 ~59 ~16 ~2 ~59 fence  
fill ~16 ~1 ~62 ~16 ~2 ~62 fence  
fill ~16 ~1 ~65 ~16 ~2 ~65 fence  
fill ~16 ~1 ~68 ~16 ~2 ~68 fence  
fill ~16 ~1 ~71 ~16 ~2 ~71 fence  
fill ~16 ~1 ~74 ~16 ~2 ~74 fence  
fill ~16 ~1 ~86 ~16 ~3 ~86 stone  
fill ~17 ~1 ~0 ~17 ~2 ~0 stone  
fill ~17 ~1 ~13 ~17 ~3 ~13 stonebrick  
fill ~17 ~1 ~14 ~17 ~2 ~14 stonebrick 
setblock ~17 ~1 ~17 stone 6  
fill ~17 ~1 ~18 ~22 ~1 ~18 stonebrick 
setblock ~17 ~1 ~19 stone 6  
fill ~17 ~1 ~20 ~22 ~1 ~20 stonebrick 
setblock ~17 ~1 ~21 stone 6  
fill ~17 ~1 ~22 ~22 ~1 ~22 stonebrick 
setblock ~17 ~1 ~23 stone 6  
fill ~17 ~1 ~24 ~22 ~1 ~24 stone_brick_stairs  
fill ~17 ~1 ~25 ~22 ~1 ~25 stone_slab  
fill ~17 ~1 ~26 ~23 ~1 ~26 carpet  
fill ~17 ~1 ~27 ~22 ~1 ~27 carpet  
fill ~17 ~1 ~87 ~18 ~1 ~87 spruce_door  
fill ~18 ~1 ~15 ~18 ~3 ~15 stonebrick  
fill ~18 ~1 ~17 ~21 ~1 ~17 stonebrick  
fill ~18 ~1 ~19 ~21 ~1 ~19 stonebrick  
fill ~18 ~1 ~21 ~21 ~1 ~21 stonebrick  
fill ~18 ~1 ~23 ~21 ~1 ~23 stonebrick  
fill ~19 ~1 ~15 ~20 ~1 ~15 stone_brick_stairs  
fill ~19 ~1 ~84 ~20 ~1 ~84 jukebox  
fill ~19 ~1 ~85 ~20 ~1 ~85 cauldron  
fill ~19 ~1 ~86 ~20 ~1 ~86 stone_stairs  
fill ~19 ~1 ~87 ~20 ~1 ~87 stonebrick  
fill ~21 ~1 ~15 ~21 ~3 ~15 stonebrick  
fill ~21 ~1 ~87 ~22 ~1 ~87 spruce_door  
fill ~22 ~1 ~0 ~22 ~2 ~0 stone  
fill ~22 ~1 ~13 ~22 ~2 ~13 stonebrick  
fill ~22 ~1 ~14 ~22 ~2 ~14 stonebrick  
fill ~22 ~1 ~15 ~24 ~1 ~15 stone_slab 
setblock ~22 ~1 ~17 stone 6 
setblock ~22 ~1 ~19 stone 6 
setblock ~22 ~1 ~21 stone 6 
setblock ~22 ~1 ~23 stone 6  
fill ~23 ~1 ~0 ~23 ~24 ~0 stonebrick  
fill ~23 ~1 ~13 ~24 ~1 ~13 cobblestone_wall  
fill ~23 ~1 ~14 ~24 ~1 ~14 stone_slab  
fill ~23 ~1 ~16 ~23 ~1 ~23 stone_brick_stairs 
setblock ~23 ~1 ~24 stone_slab 0  
fill ~23 ~1 ~25 ~24 ~1 ~25 carpet  
fill ~23 ~1 ~31 ~32 ~1 ~31 stone_slab  
fill ~23 ~1 ~32 ~23 ~2 ~32 fence  
fill ~23 ~1 ~33 ~32 ~1 ~33 stone_slab  
fill ~23 ~1 ~34 ~32 ~1 ~34 stone_slab  
fill ~23 ~1 ~35 ~23 ~2 ~35 fence  
fill ~23 ~1 ~36 ~32 ~1 ~36 stone_slab  
fill ~23 ~1 ~37 ~32 ~1 ~37 stone_slab  
fill ~23 ~1 ~38 ~23 ~2 ~38 fence  
fill ~23 ~1 ~39 ~32 ~1 ~39 stone_slab  
fill ~23 ~1 ~40 ~32 ~1 ~40 stone_slab  
fill ~23 ~1 ~41 ~23 ~2 ~41 fence  
fill ~23 ~1 ~42 ~32 ~1 ~42 stone_slab  
fill ~23 ~1 ~43 ~32 ~1 ~43 stone_slab  
fill ~23 ~1 ~44 ~23 ~2 ~44 fence  
fill ~23 ~1 ~45 ~32 ~1 ~45 stone_slab  
fill ~23 ~1 ~46 ~32 ~1 ~46 stone_slab  
fill ~23 ~1 ~47 ~23 ~2 ~47 fence  
fill ~23 ~1 ~48 ~32 ~1 ~48 stone_slab  
fill ~23 ~1 ~49 ~32 ~1 ~49 stone_slab  
fill ~23 ~1 ~50 ~23 ~2 ~50 fence  
fill ~23 ~1 ~51 ~32 ~1 ~51 stone_slab  
fill ~23 ~1 ~52 ~32 ~1 ~52 stone_slab  
fill ~23 ~1 ~53 ~23 ~2 ~53 fence  
fill ~23 ~1 ~54 ~32 ~1 ~54 stone_slab  
fill ~23 ~1 ~55 ~32 ~1 ~55 stone_slab  
fill ~23 ~1 ~56 ~23 ~2 ~56 fence  
fill ~23 ~1 ~57 ~32 ~1 ~57 stone_slab  
fill ~23 ~1 ~58 ~32 ~1 ~58 stone_slab  
fill ~23 ~1 ~59 ~23 ~2 ~59 fence  
fill ~23 ~1 ~60 ~32 ~1 ~60 stone_slab  
fill ~23 ~1 ~61 ~32 ~1 ~61 stone_slab  
fill ~23 ~1 ~62 ~23 ~2 ~62 fence  
fill ~23 ~1 ~63 ~32 ~1 ~63 stone_slab  
fill ~23 ~1 ~64 ~32 ~1 ~64 stone_slab  
fill ~23 ~1 ~65 ~23 ~2 ~65 fence  
fill ~23 ~1 ~66 ~32 ~1 ~66 stone_slab  
fill ~23 ~1 ~67 ~32 ~1 ~67 stone_slab  
fill ~23 ~1 ~68 ~23 ~2 ~68 fence  
fill ~23 ~1 ~69 ~32 ~1 ~69 stone_slab  
fill ~23 ~1 ~70 ~32 ~1 ~70 stone_slab  
fill ~23 ~1 ~71 ~23 ~2 ~71 fence  
fill ~23 ~1 ~72 ~32 ~1 ~72 stone_slab  
fill ~23 ~1 ~73 ~32 ~1 ~73 stone_slab  
fill ~23 ~1 ~74 ~23 ~2 ~74 fence  
fill ~23 ~1 ~75 ~32 ~1 ~75 stone_slab  
fill ~23 ~1 ~86 ~23 ~3 ~86 stone  
fill ~23 ~1 ~87 ~30 ~1 ~87 stonebrick  
fill ~24 ~1 ~0 ~24 ~2 ~0 stone  
fill ~24 ~1 ~3 ~25 ~1 ~3 stonebrick  
fill ~24 ~1 ~4 ~25 ~1 ~4 stonebrick  
fill ~24 ~1 ~5 ~36 ~1 ~5 stonebrick  
fill ~24 ~1 ~6 ~25 ~1 ~6 stonebrick  
fill ~24 ~1 ~7 ~25 ~1 ~7 stonebrick  
fill ~24 ~1 ~8 ~25 ~1 ~8 stonebrick  
fill ~24 ~1 ~9 ~25 ~1 ~9 stonebrick  
fill ~24 ~1 ~10 ~25 ~1 ~10 stonebrick  
fill ~24 ~1 ~16 ~24 ~1 ~23 stone_slab  
fill ~24 ~1 ~24 ~25 ~1 ~24 carpet  
fill ~24 ~1 ~29 ~24 ~2 ~29 fence  
fill ~24 ~1 ~30 ~32 ~1 ~30 stone_slab 
setblock ~24 ~1 ~32 stone_slab 0 
setblock ~24 ~1 ~35 stone_slab 0 
setblock ~24 ~1 ~38 stone_slab 0 
setblock ~24 ~1 ~41 stone_slab 0 
setblock ~24 ~1 ~44 stone_slab 0 
setblock ~24 ~1 ~47 stone_slab 0 
setblock ~24 ~1 ~50 stone_slab 0 
setblock ~24 ~1 ~53 stone_slab 0 
setblock ~24 ~1 ~56 stone_slab 0 
setblock ~24 ~1 ~59 stone_slab 0 
setblock ~24 ~1 ~62 stone_slab 0 
setblock ~24 ~1 ~65 stone_slab 0 
setblock ~24 ~1 ~68 stone_slab 0 
setblock ~24 ~1 ~71 stone_slab 0 
setblock ~24 ~1 ~74 stone_slab 0  
fill ~24 ~1 ~88 ~24 ~5 ~88 stonebrick  
fill ~25 ~1 ~13 ~25 ~6 ~13 stonebrick  
fill ~25 ~1 ~14 ~25 ~1 ~24 carpet 
setblock ~25 ~1 ~29 stone_slab 0 
setblock ~25 ~1 ~32 planks 5 
setblock ~25 ~1 ~35 planks 5 
setblock ~25 ~1 ~38 planks 5 
setblock ~25 ~1 ~41 planks 5 
setblock ~25 ~1 ~44 planks 5 
setblock ~25 ~1 ~47 planks 5 
setblock ~25 ~1 ~50 planks 5 
setblock ~25 ~1 ~53 planks 5 
setblock ~25 ~1 ~56 planks 5 
setblock ~25 ~1 ~59 planks 5 
setblock ~25 ~1 ~62 planks 5 
setblock ~25 ~1 ~65 planks 5 
setblock ~25 ~1 ~68 planks 5 
setblock ~25 ~1 ~71 planks 5 
setblock ~25 ~1 ~74 planks 5 
setblock ~25 ~1 ~80 stone_stairs 0 
setblock ~25 ~1 ~82 stone_stairs 0  
fill ~25 ~1 ~88 ~27 ~1 ~88 stonebrick  
fill ~25 ~1 ~89 ~25 ~6 ~89 stonebrick  
fill ~26 ~1 ~2 ~26 ~2 ~2 stone  
fill ~26 ~1 ~3 ~26 ~24 ~3 stonebrick  
fill ~26 ~1 ~4 ~26 ~2 ~4 stone  
fill ~26 ~1 ~22 ~27 ~1 ~22 fence  
fill ~26 ~1 ~23 ~26 ~1 ~22 fence  
fill ~26 ~1 ~28 ~32 ~1 ~28 stone_slab 
setblock ~26 ~1 ~29 planks 5  
fill ~26 ~1 ~32 ~29 ~1 ~32 stone_slab  
fill ~26 ~1 ~35 ~29 ~1 ~35 stone_slab  
fill ~26 ~1 ~38 ~29 ~1 ~38 stone_slab  
fill ~26 ~1 ~41 ~29 ~1 ~41 stone_slab  
fill ~26 ~1 ~44 ~29 ~1 ~44 stone_slab  
fill ~26 ~1 ~47 ~29 ~1 ~47 stone_slab  
fill ~26 ~1 ~50 ~29 ~1 ~50 stone_slab  
fill ~26 ~1 ~53 ~29 ~1 ~53 stone_slab  
fill ~26 ~1 ~56 ~29 ~1 ~56 stone_slab  
fill ~26 ~1 ~59 ~29 ~1 ~59 stone_slab  
fill ~26 ~1 ~62 ~29 ~1 ~62 stone_slab  
fill ~26 ~1 ~65 ~29 ~1 ~65 stone_slab  
fill ~26 ~1 ~68 ~29 ~1 ~68 stone_slab  
fill ~26 ~1 ~71 ~29 ~1 ~71 stone_slab  
fill ~26 ~1 ~74 ~29 ~1 ~74 stone_slab  
fill ~26 ~1 ~80 ~26 ~3 ~80 stone  
fill ~26 ~1 ~82 ~26 ~3 ~82 stone  
fill ~26 ~1 ~89 ~26 ~18 ~89 stonebrick  
fill ~26 ~1 ~90 ~26 ~7 ~90 stonebrick 
setblock ~27 ~1 ~13 stone_stairs 0  
fill ~27 ~1 ~21 ~28 ~1 ~21 fence  
fill ~27 ~1 ~27 ~32 ~1 ~27 stone_slab  
fill ~27 ~1 ~29 ~29 ~1 ~29 stone_slab  
fill ~27 ~1 ~79 ~36 ~1 ~79 stonebrick  
fill ~27 ~1 ~80 ~27 ~13 ~80 stonebrick 
setblock ~27 ~1 ~81 spruce_door 2  
fill ~27 ~1 ~82 ~27 ~13 ~82 stonebrick  
fill ~27 ~1 ~83 ~29 ~1 ~83 stonebrick  
fill ~27 ~1 ~89 ~27 ~6 ~89 stonebrick  
fill ~28 ~1 ~13 ~28 ~8 ~13 stonebrick  
fill ~28 ~1 ~20 ~29 ~1 ~20 fence 
setblock ~28 ~1 ~80 stone_stairs 3  
fill ~28 ~1 ~88 ~28 ~5 ~88 stonebrick  
fill ~29 ~1 ~4 ~29 ~2 ~4 stone 
setblock ~29 ~1 ~13 stone_brick_stairs 1  
fill ~29 ~1 ~19 ~30 ~1 ~19 fence 
setblock ~29 ~1 ~77 stone_stairs 2  
fill ~29 ~1 ~78 ~29 ~3 ~78 stone  
fill ~29 ~1 ~80 ~29 ~1 ~83 stonebrick  
fill ~30 ~1 ~4 ~30 ~21 ~4 stonebrick 
setblock ~30 ~1 ~13 stone_brick_stairs 0  
fill ~30 ~1 ~18 ~31 ~1 ~18 fence 
setblock ~30 ~1 ~29 planks 5 
setblock ~30 ~1 ~32 planks 5 
setblock ~30 ~1 ~35 planks 5 
setblock ~30 ~1 ~38 planks 5 
setblock ~30 ~1 ~41 planks 5 
setblock ~30 ~1 ~44 planks 5 
setblock ~30 ~1 ~47 planks 5 
setblock ~30 ~1 ~50 planks 5 
setblock ~30 ~1 ~53 planks 5 
setblock ~30 ~1 ~56 planks 5 
setblock ~30 ~1 ~59 planks 5 
setblock ~30 ~1 ~62 planks 5 
setblock ~30 ~1 ~65 planks 5 
setblock ~30 ~1 ~68 planks 5 
setblock ~30 ~1 ~71 planks 5 
setblock ~30 ~1 ~74 planks 5  
fill ~30 ~1 ~78 ~30 ~2 ~78 fence 
setblock ~30 ~1 ~80 stone_stairs 3 
setblock ~30 ~1 ~83 spruce_door 1  
fill ~31 ~1 ~4 ~31 ~2 ~4 stone 
setblock ~31 ~1 ~13 stone_brick_stairs 1  
fill ~31 ~1 ~17 ~35 ~1 ~17 fence 
setblock ~31 ~1 ~29 stone_slab 0 
setblock ~31 ~1 ~32 stone_slab 0 
setblock ~31 ~1 ~35 stone_slab 0 
setblock ~31 ~1 ~38 stone_slab 0 
setblock ~31 ~1 ~41 stone_slab 0 
setblock ~31 ~1 ~44 stone_slab 0 
setblock ~31 ~1 ~47 stone_slab 0 
setblock ~31 ~1 ~50 stone_slab 0 
setblock ~31 ~1 ~53 stone_slab 0 
setblock ~31 ~1 ~56 stone_slab 0 
setblock ~31 ~1 ~59 stone_slab 0 
setblock ~31 ~1 ~62 stone_slab 0 
setblock ~31 ~1 ~65 stone_slab 0 
setblock ~31 ~1 ~68 stone_slab 0 
setblock ~31 ~1 ~71 stone_slab 0 
setblock ~31 ~1 ~74 stone_slab 0  
fill ~31 ~1 ~78 ~31 ~2 ~78 stonebrick  
fill ~31 ~1 ~80 ~31 ~13 ~80 stonebrick  
fill ~31 ~1 ~81 ~31 ~13 ~81 stonebrick  
fill ~31 ~1 ~82 ~31 ~12 ~82 stonebrick  
fill ~31 ~1 ~83 ~33 ~1 ~83 stonebrick  
fill ~31 ~1 ~87 ~32 ~1 ~87 spruce_door 
setblock ~32 ~1 ~13 stone_brick_stairs 0  
fill ~32 ~1 ~29 ~32 ~2 ~29 fence  
fill ~32 ~1 ~32 ~32 ~2 ~32 fence  
fill ~32 ~1 ~35 ~32 ~2 ~35 fence  
fill ~32 ~1 ~38 ~32 ~2 ~38 fence  
fill ~32 ~1 ~41 ~32 ~2 ~41 fence  
fill ~32 ~1 ~44 ~32 ~2 ~44 fence  
fill ~32 ~1 ~47 ~32 ~2 ~47 fence  
fill ~32 ~1 ~50 ~32 ~2 ~50 fence  
fill ~32 ~1 ~53 ~32 ~2 ~53 fence  
fill ~32 ~1 ~56 ~32 ~2 ~56 fence  
fill ~32 ~1 ~59 ~32 ~2 ~59 fence  
fill ~32 ~1 ~62 ~32 ~2 ~62 fence  
fill ~32 ~1 ~65 ~32 ~2 ~65 fence  
fill ~32 ~1 ~68 ~32 ~2 ~68 fence  
fill ~32 ~1 ~71 ~32 ~2 ~71 fence  
fill ~32 ~1 ~74 ~32 ~2 ~74 fence  
fill ~32 ~1 ~78 ~32 ~2 ~78 fence  
fill ~33 ~1 ~13 ~33 ~8 ~13 stonebrick 
setblock ~33 ~1 ~21 jukebox 0 
setblock ~33 ~1 ~77 stone_stairs 2  
fill ~33 ~1 ~78 ~33 ~3 ~78 stone  
fill ~33 ~1 ~80 ~33 ~3 ~80 stonebrick  
fill ~33 ~1 ~81 ~33 ~4 ~81 stonebrick  
fill ~33 ~1 ~82 ~33 ~5 ~82 stonebrick  
fill ~33 ~1 ~84 ~33 ~7 ~84 stonebrick 
setblock ~33 ~1 ~85 spruce_door 6  
fill ~33 ~1 ~86 ~33 ~8 ~86 stonebrick  
fill ~33 ~1 ~87 ~36 ~1 ~87 stonebrick  
fill ~34 ~1 ~4 ~34 ~2 ~4 stone 
setblock ~34 ~1 ~13 stone_stairs 1 
setblock ~34 ~1 ~21 cauldron 6 
setblock ~34 ~1 ~26 stone_stairs 0 
setblock ~34 ~1 ~29 stone_stairs 0 
setblock ~34 ~1 ~32 stone_stairs 0 
setblock ~34 ~1 ~44 stone_stairs 0 
setblock ~34 ~1 ~47 stone_stairs 0 
setblock ~34 ~1 ~59 stone_stairs 0 
setblock ~34 ~1 ~62 stone_stairs 0 
setblock ~34 ~1 ~74 stone_stairs 0  
fill ~34 ~1 ~83 ~35 ~1 ~83 stone_stairs  
fill ~34 ~1 ~84 ~35 ~1 ~84 stone_stairs  
fill ~35 ~1 ~4 ~35 ~16 ~4 stonebrick  
fill ~35 ~1 ~18 ~35 ~3 ~18 stonebrick  
fill ~35 ~1 ~21 ~35 ~4 ~21 stonebrick  
fill ~35 ~1 ~24 ~35 ~3 ~24 stonebrick  
fill ~35 ~1 ~26 ~35 ~3 ~26 stone  
fill ~35 ~1 ~29 ~35 ~3 ~29 stone  
fill ~35 ~1 ~32 ~35 ~3 ~32 stone  
fill ~35 ~1 ~35 ~35 ~3 ~35 stonebrick 
setblock ~35 ~1 ~36 stone_brick_stairs 3  
fill ~35 ~1 ~37 ~35 ~2 ~37 cobblestone_wall  
fill ~35 ~1 ~38 ~35 ~2 ~38 cobblestone_wall  
fill ~35 ~1 ~39 ~35 ~2 ~39 cobblestone_wall 
setblock ~35 ~1 ~40 stone_brick_stairs 2  
fill ~35 ~1 ~41 ~35 ~3 ~41 stonebrick  
fill ~35 ~1 ~44 ~35 ~3 ~44 stone  
fill ~35 ~1 ~47 ~35 ~3 ~47 stone  
fill ~35 ~1 ~50 ~35 ~3 ~50 stonebrick 
setblock ~35 ~1 ~51 stone_brick_stairs 3  
fill ~35 ~1 ~52 ~35 ~2 ~52 cobblestone_wall  
fill ~35 ~1 ~53 ~35 ~2 ~53 cobblestone_wall  
fill ~35 ~1 ~54 ~35 ~2 ~54 cobblestone_wall 
setblock ~35 ~1 ~55 stone_brick_stairs 2  
fill ~35 ~1 ~56 ~35 ~3 ~56 stonebrick  
fill ~35 ~1 ~59 ~35 ~3 ~59 stone  
fill ~35 ~1 ~62 ~35 ~3 ~62 stone  
fill ~35 ~1 ~65 ~35 ~3 ~65 stonebrick 
setblock ~35 ~1 ~66 stone_brick_stairs 3  
fill ~35 ~1 ~67 ~35 ~2 ~67 cobblestone_wall  
fill ~35 ~1 ~68 ~35 ~2 ~68 cobblestone_wall  
fill ~35 ~1 ~69 ~35 ~2 ~69 cobblestone_wall 
setblock ~35 ~1 ~70 stone_brick_stairs 2  
fill ~35 ~1 ~71 ~35 ~3 ~71 stonebrick  
fill ~35 ~1 ~74 ~35 ~3 ~74 stone  
fill ~35 ~1 ~88 ~35 ~5 ~88 stonebrick  
fill ~36 ~1 ~4 ~36 ~2 ~4 stone  
fill ~36 ~1 ~6 ~36 ~23 ~6 stonebrick  
fill ~36 ~1 ~7 ~36 ~23 ~7 stonebrick  
fill ~36 ~1 ~8 ~36 ~17 ~8 stonebrick  
fill ~36 ~1 ~9 ~36 ~17 ~9 stonebrick  
fill ~36 ~1 ~10 ~36 ~23 ~10 stonebrick  
fill ~36 ~1 ~11 ~36 ~23 ~11 stonebrick  
fill ~36 ~1 ~13 ~36 ~23 ~13 stonebrick  
fill ~36 ~1 ~14 ~36 ~23 ~14 stonebrick  
fill ~36 ~1 ~15 ~36 ~23 ~15 stonebrick  
fill ~36 ~1 ~16 ~36 ~23 ~16 stonebrick  
fill ~36 ~1 ~17 ~36 ~23 ~17 stonebrick  
fill ~36 ~1 ~18 ~36 ~17 ~18 stonebrick  
fill ~36 ~1 ~19 ~36 ~1 ~20 spruce_door  
fill ~36 ~1 ~21 ~36 ~23 ~21 stonebrick  
fill ~36 ~1 ~22 ~36 ~1 ~23 spruce_door  
fill ~36 ~1 ~24 ~36 ~17 ~24 stonebrick  
fill ~36 ~1 ~25 ~36 ~23 ~25 stonebrick  
fill ~36 ~1 ~26 ~36 ~23 ~26 stonebrick  
fill ~36 ~1 ~27 ~36 ~23 ~27 stonebrick  
fill ~36 ~1 ~28 ~36 ~17 ~28 stonebrick  
fill ~36 ~1 ~29 ~36 ~17 ~29 stonebrick  
fill ~36 ~1 ~30 ~36 ~23 ~30 stonebrick  
fill ~36 ~1 ~31 ~36 ~23 ~31 stonebrick  
fill ~36 ~1 ~32 ~36 ~23 ~32 stonebrick  
fill ~36 ~1 ~33 ~36 ~17 ~33 stonebrick  
fill ~36 ~1 ~34 ~36 ~17 ~34 stonebrick  
fill ~36 ~1 ~35 ~36 ~23 ~35 stonebrick  
fill ~36 ~1 ~36 ~36 ~23 ~36 stonebrick  
fill ~36 ~1 ~37 ~36 ~23 ~37 stonebrick  
fill ~36 ~1 ~38 ~36 ~17 ~38 stonebrick  
fill ~36 ~1 ~39 ~36 ~17 ~39 stonebrick  
fill ~36 ~1 ~40 ~36 ~23 ~40 stonebrick  
fill ~36 ~1 ~41 ~36 ~23 ~41 stonebrick  
fill ~36 ~1 ~42 ~36 ~23 ~42 stonebrick  
fill ~36 ~1 ~43 ~36 ~17 ~43 stonebrick  
fill ~36 ~1 ~44 ~36 ~17 ~44 stonebrick  
fill ~36 ~1 ~45 ~36 ~23 ~45 stonebrick  
fill ~36 ~1 ~46 ~36 ~23 ~46 stonebrick  
fill ~36 ~1 ~47 ~36 ~23 ~47 stonebrick  
fill ~36 ~1 ~48 ~36 ~17 ~48 stonebrick  
fill ~36 ~1 ~49 ~36 ~17 ~49 stonebrick  
fill ~36 ~1 ~50 ~36 ~23 ~50 stonebrick  
fill ~36 ~1 ~51 ~36 ~23 ~51 stonebrick  
fill ~36 ~1 ~52 ~36 ~23 ~52 stonebrick  
fill ~36 ~1 ~53 ~36 ~17 ~53 stonebrick  
fill ~36 ~1 ~54 ~36 ~17 ~54 stonebrick  
fill ~36 ~1 ~55 ~36 ~23 ~55 stonebrick  
fill ~36 ~1 ~56 ~36 ~23 ~56 stonebrick  
fill ~36 ~1 ~57 ~36 ~23 ~57 stonebrick  
fill ~36 ~1 ~58 ~36 ~17 ~58 stonebrick  
fill ~36 ~1 ~59 ~36 ~17 ~59 stonebrick  
fill ~36 ~1 ~60 ~36 ~23 ~60 stonebrick  
fill ~36 ~1 ~61 ~36 ~23 ~61 stonebrick  
fill ~36 ~1 ~62 ~36 ~23 ~62 stonebrick  
fill ~36 ~1 ~63 ~36 ~17 ~63 stonebrick  
fill ~36 ~1 ~64 ~36 ~17 ~64 stonebrick  
fill ~36 ~1 ~65 ~36 ~23 ~65 stonebrick  
fill ~36 ~1 ~66 ~36 ~23 ~66 stonebrick  
fill ~36 ~1 ~67 ~36 ~23 ~67 stonebrick  
fill ~36 ~1 ~68 ~36 ~17 ~68 stonebrick  
fill ~36 ~1 ~69 ~36 ~17 ~69 stonebrick  
fill ~36 ~1 ~70 ~36 ~23 ~70 stonebrick  
fill ~36 ~1 ~71 ~36 ~23 ~71 stonebrick  
fill ~36 ~1 ~72 ~36 ~23 ~72 stonebrick  
fill ~36 ~1 ~73 ~36 ~17 ~73 stonebrick  
fill ~36 ~1 ~74 ~36 ~17 ~74 stonebrick  
fill ~36 ~1 ~75 ~36 ~23 ~75 stonebrick  
fill ~36 ~1 ~76 ~36 ~23 ~76 stonebrick  
fill ~36 ~1 ~77 ~36 ~23 ~77 stonebrick  
fill ~36 ~1 ~78 ~36 ~17 ~78 stonebrick  
fill ~36 ~1 ~80 ~36 ~46 ~80 stonebrick  
fill ~36 ~1 ~81 ~36 ~46 ~81 stonebrick  
fill ~36 ~1 ~82 ~36 ~46 ~82 stonebrick  
fill ~36 ~1 ~83 ~36 ~17 ~83 stonebrick  
fill ~36 ~1 ~84 ~36 ~17 ~84 stonebrick  
fill ~36 ~1 ~85 ~36 ~46 ~85 stonebrick  
fill ~36 ~1 ~86 ~36 ~46 ~86 stonebrick  
fill ~36 ~1 ~88 ~36 ~46 ~88 stonebrick  
fill ~36 ~1 ~89 ~36 ~6 ~89 stonebrick  
fill ~37 ~1 ~5 ~37 ~2 ~5 stone  
fill ~37 ~1 ~6 ~37 ~16 ~6 stonebrick  
fill ~37 ~1 ~7 ~37 ~2 ~7 stone  
fill ~37 ~1 ~10 ~37 ~2 ~10 stone  
fill ~37 ~1 ~11 ~37 ~16 ~11 stonebrick  
fill ~37 ~1 ~12 ~37 ~2 ~12 stone  
fill ~37 ~1 ~15 ~37 ~2 ~15 stone  
fill ~37 ~1 ~16 ~37 ~16 ~16 stonebrick  
fill ~37 ~1 ~17 ~37 ~5 ~17 stone  
fill ~37 ~1 ~21 ~37 ~16 ~21 stonebrick  
fill ~37 ~1 ~25 ~37 ~5 ~25 stone  
fill ~37 ~1 ~26 ~37 ~16 ~26 stonebrick  
fill ~37 ~1 ~27 ~37 ~2 ~27 stone  
fill ~37 ~1 ~30 ~37 ~2 ~30 stone  
fill ~37 ~1 ~31 ~37 ~16 ~31 stonebrick  
fill ~37 ~1 ~32 ~37 ~2 ~32 stone  
fill ~37 ~1 ~35 ~37 ~2 ~35 stone  
fill ~37 ~1 ~36 ~37 ~16 ~36 stonebrick  
fill ~37 ~1 ~37 ~37 ~2 ~37 stone  
fill ~37 ~1 ~40 ~37 ~2 ~40 stone  
fill ~37 ~1 ~41 ~37 ~16 ~41 stonebrick  
fill ~37 ~1 ~42 ~37 ~2 ~42 stone  
fill ~37 ~1 ~45 ~37 ~2 ~45 stone  
fill ~37 ~1 ~46 ~37 ~16 ~46 stonebrick  
fill ~37 ~1 ~47 ~37 ~2 ~47 stone  
fill ~37 ~1 ~50 ~37 ~2 ~50 stone  
fill ~37 ~1 ~51 ~37 ~16 ~51 stonebrick  
fill ~37 ~1 ~52 ~37 ~2 ~52 stone  
fill ~37 ~1 ~55 ~37 ~2 ~55 stone  
fill ~37 ~1 ~56 ~37 ~16 ~56 stonebrick  
fill ~37 ~1 ~57 ~37 ~2 ~57 stone  
fill ~37 ~1 ~60 ~37 ~2 ~60 stone  

KittysCommands:   
fill ~37 ~1 ~61 ~37 ~16 ~61 stonebrick  
fill ~37 ~1 ~62 ~37 ~2 ~62 stone  
fill ~37 ~1 ~65 ~37 ~2 ~65 stone  
fill ~37 ~1 ~66 ~37 ~16 ~66 stonebrick  
fill ~37 ~1 ~67 ~37 ~2 ~67 stone  
fill ~37 ~1 ~70 ~37 ~2 ~70 stone  
fill ~37 ~1 ~71 ~37 ~16 ~71 stonebrick  
fill ~37 ~1 ~72 ~37 ~2 ~72 stone  
fill ~37 ~1 ~75 ~37 ~2 ~75 stone  
fill ~37 ~1 ~76 ~37 ~16 ~76 stonebrick  
fill ~37 ~1 ~77 ~37 ~2 ~77 stone  
fill ~37 ~1 ~80 ~37 ~2 ~80 stone  
fill ~37 ~1 ~81 ~37 ~16 ~81 stonebrick  
fill ~37 ~1 ~82 ~37 ~2 ~82 stone  
fill ~37 ~1 ~85 ~37 ~2 ~85 stone  
fill ~37 ~1 ~86 ~37 ~16 ~86 stonebrick  
fill ~37 ~1 ~87 ~37 ~2 ~87 stone 
setblock ~2 ~2 ~18 torch 2 
setblock ~2 ~2 ~24 torch 2  
fill ~3 ~2 ~5 ~15 ~2 ~5 stonebrick  
fill ~3 ~2 ~12 ~36 ~2 ~12 stonebrick 
setblock ~3 ~2 ~19 spruce_door 9 
setblock ~3 ~2 ~20 spruce_door 8 
setblock ~3 ~2 ~22 spruce_door 9 
setblock ~3 ~2 ~23 spruce_door 8  
fill ~3 ~2 ~79 ~12 ~2 ~79 stonebrick  
fill ~3 ~2 ~87 ~6 ~2 ~87 stonebrick 
setblock ~4 ~2 ~36 stone_brick_stairs 7 
setblock ~4 ~2 ~40 stone_brick_stairs 6 
setblock ~4 ~2 ~51 stone_brick_stairs 7 
setblock ~4 ~2 ~55 stone_brick_stairs 6 
setblock ~4 ~2 ~66 stone_brick_stairs 7 
setblock ~4 ~2 ~70 stone_brick_stairs 6  
fill ~4 ~2 ~83 ~5 ~2 ~83 stone_stairs 
setblock ~5 ~2 ~13 stone_stairs 4 
setblock ~6 ~2 ~14 fence 0 
setblock ~6 ~2 ~17 torch 5  
fill ~6 ~2 ~83 ~8 ~2 ~83 stonebrick 
setblock ~6 ~2 ~85 spruce_door 8 
setblock ~7 ~2 ~13 stone_brick_stairs 5 
setblock ~7 ~2 ~87 spruce_door 9 
setblock ~8 ~2 ~13 stone_brick_stairs 4 
setblock ~8 ~2 ~18 torch 5  
fill ~8 ~2 ~29 ~14 ~2 ~29 dark_oak_stairs  
fill ~8 ~2 ~32 ~15 ~2 ~32 dark_oak_stairs  
fill ~8 ~2 ~35 ~15 ~2 ~35 dark_oak_stairs  
fill ~8 ~2 ~38 ~15 ~2 ~38 dark_oak_stairs  
fill ~8 ~2 ~41 ~15 ~2 ~41 dark_oak_stairs  
fill ~8 ~2 ~44 ~15 ~2 ~44 dark_oak_stairs  
fill ~8 ~2 ~47 ~15 ~2 ~47 dark_oak_stairs  
fill ~8 ~2 ~50 ~15 ~2 ~50 dark_oak_stairs  
fill ~8 ~2 ~53 ~15 ~2 ~53 dark_oak_stairs  
fill ~8 ~2 ~56 ~15 ~2 ~56 dark_oak_stairs  
fill ~8 ~2 ~59 ~15 ~2 ~59 dark_oak_stairs  
fill ~8 ~2 ~62 ~15 ~2 ~62 dark_oak_stairs  
fill ~8 ~2 ~65 ~15 ~2 ~65 dark_oak_stairs  
fill ~8 ~2 ~68 ~15 ~2 ~68 dark_oak_stairs  
fill ~8 ~2 ~71 ~15 ~2 ~71 dark_oak_stairs  
fill ~8 ~2 ~74 ~15 ~2 ~74 dark_oak_stairs 
setblock ~8 ~2 ~87 spruce_door 8 
setblock ~9 ~2 ~13 stone_brick_stairs 5 
setblock ~9 ~2 ~83 spruce_door 8  
fill ~9 ~2 ~87 ~16 ~2 ~87 stonebrick 
setblock ~10 ~2 ~13 stone_brick_stairs 4 
setblock ~10 ~2 ~19 torch 5  
fill ~10 ~2 ~80 ~10 ~2 ~81 iron_bars  
fill ~10 ~2 ~82 ~10 ~4 ~82 stonebrick  
fill ~10 ~2 ~83 ~12 ~2 ~83 stonebrick 
setblock ~11 ~2 ~14 fence 0 
setblock ~12 ~2 ~13 stone_stairs 5 
setblock ~12 ~2 ~21 torch 5 
setblock ~12 ~2 ~81 spruce_door 8  
fill ~12 ~2 ~88 ~14 ~2 ~88 stonebrick 
setblock ~13 ~2 ~23 torch 5  
fill ~14 ~2 ~1 ~25 ~2 ~1 stonebrick  
fill ~14 ~2 ~2 ~25 ~2 ~2 stonebrick  
fill ~14 ~2 ~3 ~15 ~2 ~3 stonebrick  
fill ~14 ~2 ~4 ~15 ~2 ~4 stonebrick  
fill ~14 ~2 ~6 ~15 ~2 ~6 stonebrick  
fill ~14 ~2 ~7 ~15 ~2 ~7 stonebrick  
fill ~14 ~2 ~8 ~15 ~2 ~8 stonebrick  
fill ~14 ~2 ~9 ~15 ~2 ~9 stonebrick  
fill ~14 ~2 ~10 ~15 ~2 ~10 stonebrick  
fill ~14 ~2 ~11 ~25 ~2 ~11 stonebrick 
setblock ~14 ~2 ~14 fence 1 
setblock ~15 ~2 ~13 stone_stairs 1 
setblock ~16 ~2 ~13 stone_stairs 0 
setblock ~17 ~2 ~17 fence 0  
fill ~17 ~2 ~23 ~18 ~2 ~23 fence 
setblock ~17 ~2 ~87 spruce_door 9 
setblock ~18 ~2 ~16 stone_slab 8 
setblock ~18 ~2 ~17 stone_brick_stairs 3 
setblock ~18 ~2 ~22 fence 1 
setblock ~18 ~2 ~87 spruce_door 8  
fill ~19 ~2 ~15 ~20 ~2 ~15 stone_brick_stairs  
fill ~19 ~2 ~22 ~19 ~2 ~23 dark_oak_stairs  
fill ~19 ~2 ~86 ~20 ~2 ~86 stone  
fill ~19 ~2 ~87 ~20 ~2 ~87 stonebrick 
setblock ~20 ~2 ~22 enchanting_table 0 
setblock ~20 ~2 ~23 dark_oak_stairs 4 
setblock ~21 ~2 ~16 stone_slab 8 
setblock ~21 ~2 ~17 stone_brick_stairs 3  
fill ~21 ~2 ~22 ~21 ~2 ~23 fence 
setblock ~21 ~2 ~87 spruce_door 9 
setblock ~22 ~2 ~17 fence 0 
setblock ~22 ~2 ~23 fence 1 
setblock ~22 ~2 ~87 spruce_door 8 
setblock ~23 ~2 ~13 stone_stairs 1  
fill ~23 ~2 ~87 ~30 ~2 ~87 stonebrick  
fill ~24 ~2 ~3 ~25 ~2 ~3 stonebrick  
fill ~24 ~2 ~4 ~25 ~2 ~4 stonebrick  
fill ~24 ~2 ~5 ~36 ~2 ~5 stonebrick  
fill ~24 ~2 ~6 ~25 ~2 ~6 stonebrick  
fill ~24 ~2 ~7 ~25 ~2 ~7 stonebrick  
fill ~24 ~2 ~8 ~25 ~2 ~8 stonebrick  
fill ~24 ~2 ~9 ~25 ~2 ~9 stonebrick  
fill ~24 ~2 ~10 ~25 ~2 ~10 stonebrick 
setblock ~24 ~2 ~13 stone_stairs 0  
fill ~24 ~2 ~32 ~31 ~2 ~32 dark_oak_stairs  
fill ~24 ~2 ~35 ~31 ~2 ~35 dark_oak_stairs  
fill ~24 ~2 ~38 ~31 ~2 ~38 dark_oak_stairs  
fill ~24 ~2 ~41 ~31 ~2 ~41 dark_oak_stairs  
fill ~24 ~2 ~44 ~31 ~2 ~44 dark_oak_stairs  
fill ~24 ~2 ~47 ~31 ~2 ~47 dark_oak_stairs  
fill ~24 ~2 ~50 ~31 ~2 ~50 dark_oak_stairs  
fill ~24 ~2 ~53 ~31 ~2 ~53 dark_oak_stairs  
fill ~24 ~2 ~56 ~31 ~2 ~56 dark_oak_stairs  
fill ~24 ~2 ~59 ~31 ~2 ~59 dark_oak_stairs  
fill ~24 ~2 ~62 ~31 ~2 ~62 dark_oak_stairs  
fill ~24 ~2 ~65 ~31 ~2 ~65 dark_oak_stairs  
fill ~24 ~2 ~68 ~31 ~2 ~68 dark_oak_stairs  
fill ~24 ~2 ~71 ~31 ~2 ~71 dark_oak_stairs  
fill ~24 ~2 ~74 ~31 ~2 ~74 dark_oak_stairs 
setblock ~25 ~2 ~14 fence 1  
fill ~25 ~2 ~29 ~31 ~2 ~29 dark_oak_stairs  
fill ~25 ~2 ~88 ~27 ~2 ~88 stonebrick 
setblock ~26 ~2 ~23 torch 5 
setblock ~27 ~2 ~13 stone_stairs 4 
setblock ~27 ~2 ~21 torch 5  
fill ~27 ~2 ~79 ~36 ~2 ~79 stonebrick 
setblock ~27 ~2 ~81 spruce_door 9  
fill ~27 ~2 ~83 ~29 ~2 ~83 stonebrick 
setblock ~28 ~2 ~14 fence 0 
setblock ~29 ~2 ~13 stone_brick_stairs 5 
setblock ~29 ~2 ~19 torch 5  
fill ~29 ~2 ~80 ~29 ~2 ~81 iron_bars  
fill ~29 ~2 ~82 ~29 ~4 ~82 stonebrick 
setblock ~30 ~2 ~13 stone_brick_stairs 4 
setblock ~30 ~2 ~83 spruce_door 8 
setblock ~31 ~2 ~13 stone_brick_stairs 5 
setblock ~31 ~2 ~18 torch 5  
fill ~31 ~2 ~83 ~33 ~2 ~83 stonebrick 
setblock ~31 ~2 ~87 spruce_door 9 
setblock ~32 ~2 ~13 stone_brick_stairs 4  
fill ~32 ~2 ~80 ~32 ~3 ~80 stonebrick 
setblock ~32 ~2 ~87 spruce_door 8 
setblock ~33 ~2 ~14 fence 0 
setblock ~33 ~2 ~17 torch 5 
setblock ~33 ~2 ~85 spruce_door 8  
fill ~33 ~2 ~87 ~36 ~2 ~87 stonebrick 
setblock ~34 ~2 ~13 stone_stairs 5  
fill ~34 ~2 ~82 ~35 ~2 ~82 stone_stairs  
fill ~34 ~2 ~83 ~35 ~2 ~83 stone_stairs 
setblock ~35 ~2 ~36 stone_brick_stairs 7 
setblock ~35 ~2 ~40 stone_brick_stairs 6 
setblock ~35 ~2 ~51 stone_brick_stairs 7 
setblock ~35 ~2 ~55 stone_brick_stairs 6 
setblock ~35 ~2 ~66 stone_brick_stairs 7 
setblock ~35 ~2 ~70 stone_brick_stairs 6 
setblock ~36 ~2 ~19 spruce_door 8 
setblock ~36 ~2 ~20 spruce_door 9 
setblock ~36 ~2 ~22 spruce_door 8 
setblock ~36 ~2 ~23 spruce_door 9 
setblock ~37 ~2 ~18 torch 1 
setblock ~37 ~2 ~24 torch 1 
setblock ~2 ~3 ~5 nether_brick_stairs 2 
setblock ~2 ~3 ~7 nether_brick_stairs 3 
setblock ~2 ~3 ~10 nether_brick_stairs 2 
setblock ~2 ~3 ~12 nether_brick_stairs 3 
setblock ~2 ~3 ~15 nether_brick_stairs 2 
setblock ~2 ~3 ~18 nether_brick_stairs 7 
setblock ~2 ~3 ~20 torch 4 
setblock ~2 ~3 ~22 torch 3 
setblock ~2 ~3 ~24 nether_brick_stairs 6 
setblock ~2 ~3 ~27 nether_brick_stairs 3 
setblock ~2 ~3 ~30 nether_brick_stairs 2 
setblock ~2 ~3 ~32 nether_brick_stairs 3 
setblock ~2 ~3 ~35 nether_brick_stairs 2 
setblock ~2 ~3 ~37 nether_brick_stairs 3 
setblock ~2 ~3 ~40 nether_brick_stairs 2 
setblock ~2 ~3 ~42 nether_brick_stairs 3 
setblock ~2 ~3 ~45 nether_brick_stairs 2 
setblock ~2 ~3 ~47 nether_brick_stairs 3 
setblock ~2 ~3 ~50 nether_brick_stairs 2 
setblock ~2 ~3 ~52 nether_brick_stairs 3 
setblock ~2 ~3 ~55 nether_brick_stairs 2 
setblock ~2 ~3 ~57 nether_brick_stairs 3 
setblock ~2 ~3 ~60 nether_brick_stairs 2 
setblock ~2 ~3 ~62 nether_brick_stairs 3 
setblock ~2 ~3 ~65 nether_brick_stairs 2 
setblock ~2 ~3 ~67 nether_brick_stairs 3 
setblock ~2 ~3 ~70 nether_brick_stairs 2 
setblock ~2 ~3 ~72 nether_brick_stairs 3 
setblock ~2 ~3 ~75 nether_brick_stairs 2 
setblock ~2 ~3 ~77 nether_brick_stairs 3 
setblock ~2 ~3 ~80 nether_brick_stairs 2 
setblock ~2 ~3 ~82 nether_brick_stairs 3 
setblock ~2 ~3 ~85 nether_brick_stairs 2 
setblock ~2 ~3 ~87 nether_brick_stairs 3 
setblock ~3 ~3 ~4 nether_brick_stairs 0  
fill ~3 ~3 ~5 ~15 ~3 ~5 stonebrick  
fill ~3 ~3 ~12 ~36 ~3 ~12 stonebrick  
fill ~3 ~3 ~19 ~4 ~3 ~19 stone_brick_stairs  
fill ~3 ~3 ~20 ~4 ~3 ~20 stone_brick_stairs  
fill ~3 ~3 ~22 ~4 ~3 ~22 stone_brick_stairs  
fill ~3 ~3 ~23 ~4 ~3 ~23 stone_brick_stairs  
fill ~3 ~3 ~79 ~12 ~3 ~79 stonebrick  
fill ~3 ~3 ~87 ~6 ~3 ~87 stonebrick  
fill ~4 ~3 ~36 ~4 ~7 ~36 stone 
setblock ~4 ~3 ~37 stone_brick_stairs 3 
setblock ~4 ~3 ~38 stone_slab 0 
setblock ~4 ~3 ~39 stone_brick_stairs 2  
fill ~4 ~3 ~40 ~4 ~7 ~40 stone  
fill ~4 ~3 ~51 ~4 ~7 ~51 stone 
setblock ~4 ~3 ~52 stone_brick_stairs 3 
setblock ~4 ~3 ~53 stone_slab 0 
setblock ~4 ~3 ~54 stone_brick_stairs 2  
fill ~4 ~3 ~55 ~4 ~7 ~55 stone  
fill ~4 ~3 ~66 ~4 ~7 ~66 stone 
setblock ~4 ~3 ~67 stone_brick_stairs 3 
setblock ~4 ~3 ~68 stone_slab 0 
setblock ~4 ~3 ~69 stone_brick_stairs 2  
fill ~4 ~3 ~70 ~4 ~7 ~70 stone  
fill ~4 ~3 ~82 ~5 ~3 ~82 stone_stairs 
setblock ~5 ~3 ~4 nether_brick_stairs 1 
setblock ~5 ~3 ~13 stone_stairs 0 
setblock ~5 ~3 ~18 torch 1 
setblock ~5 ~3 ~24 torch 1 
setblock ~5 ~3 ~26 wool 0 
setblock ~5 ~3 ~29 wool 0 
setblock ~5 ~3 ~32 wool 0 
setblock ~5 ~3 ~44 wool 0 
setblock ~5 ~3 ~47 wool 0 
setblock ~5 ~3 ~59 wool 0 
setblock ~5 ~3 ~62 wool 0 
setblock ~5 ~3 ~74 wool 0 
setblock ~5 ~3 ~85 torch 2 
setblock ~6 ~3 ~14 torch 5 
setblock ~6 ~3 ~77 torch 4  
fill ~6 ~3 ~82 ~6 ~5 ~82 stonebrick  
fill ~6 ~3 ~83 ~12 ~3 ~83 stonebrick  
fill ~6 ~3 ~85 ~6 ~8 ~85 stonebrick 
setblock ~6 ~3 ~88 torch 3  
fill ~7 ~3 ~13 ~10 ~3 ~13 cobblestone_wall 
setblock ~7 ~3 ~29 torch 5 
setblock ~7 ~3 ~32 torch 5 
setblock ~7 ~3 ~35 torch 5 
setblock ~7 ~3 ~38 torch 5 
setblock ~7 ~3 ~41 torch 5 
setblock ~7 ~3 ~44 torch 5 
setblock ~7 ~3 ~47 torch 5 
setblock ~7 ~3 ~50 torch 5 
setblock ~7 ~3 ~53 torch 5 
setblock ~7 ~3 ~56 torch 5 
setblock ~7 ~3 ~59 torch 5 
setblock ~7 ~3 ~62 torch 5 
setblock ~7 ~3 ~65 torch 5 
setblock ~7 ~3 ~68 torch 5 
setblock ~7 ~3 ~71 torch 5 
setblock ~7 ~3 ~74 torch 5 
setblock ~7 ~3 ~78 stone_stairs 1 
setblock ~7 ~3 ~85 torch 1 
setblock ~7 ~3 ~87 stone_brick_stairs 5 
setblock ~8 ~3 ~4 nether_brick_stairs 0 
setblock ~8 ~3 ~78 stone_slab 0 
setblock ~8 ~3 ~87 stone_brick_stairs 4 
setblock ~9 ~3 ~78 stone_stairs 0 
setblock ~9 ~3 ~82 torch 4  
fill ~9 ~3 ~87 ~16 ~3 ~87 stonebrick 
setblock ~9 ~3 ~88 torch 3 
setblock ~10 ~3 ~4 nether_brick_stairs 1 
setblock ~10 ~3 ~77 torch 4  
fill ~10 ~3 ~80 ~10 ~4 ~80 stonebrick  
fill ~10 ~3 ~81 ~10 ~4 ~81 stonebrick 
setblock ~11 ~3 ~14 torch 5 
setblock ~11 ~3 ~82 torch 4 
setblock ~12 ~3 ~13 stone_stairs 1  
fill ~12 ~3 ~81 ~12 ~13 ~81 stonebrick  
fill ~12 ~3 ~88 ~14 ~3 ~88 stonebrick 
setblock ~13 ~3 ~2 nether_brick_stairs 2 
setblock ~13 ~3 ~4 nether_brick_stairs 3  
fill ~14 ~3 ~1 ~25 ~3 ~1 stonebrick  
fill ~14 ~3 ~2 ~25 ~3 ~2 stonebrick  
fill ~14 ~3 ~3 ~15 ~3 ~3 stonebrick  
fill ~14 ~3 ~4 ~15 ~3 ~4 stonebrick  
fill ~14 ~3 ~6 ~15 ~3 ~6 stonebrick  
fill ~14 ~3 ~7 ~15 ~3 ~7 stonebrick  
fill ~14 ~3 ~8 ~15 ~3 ~8 stonebrick  
fill ~14 ~3 ~9 ~15 ~3 ~9 stonebrick  
fill ~14 ~3 ~10 ~15 ~3 ~10 stonebrick  
fill ~14 ~3 ~11 ~25 ~3 ~11 stonebrick 
setblock ~14 ~3 ~14 torch 5 
setblock ~14 ~3 ~80 torch 1 
setblock ~14 ~3 ~82 torch 1 
setblock ~15 ~3 ~0 nether_brick_stairs 0 
setblock ~15 ~3 ~13 stone_stairs 5 
setblock ~15 ~3 ~29 torch 5 
setblock ~16 ~3 ~13 stone_stairs 4 
setblock ~16 ~3 ~32 torch 5 
setblock ~16 ~3 ~35 torch 5 
setblock ~16 ~3 ~38 torch 5 
setblock ~16 ~3 ~41 torch 5 
setblock ~16 ~3 ~44 torch 5 
setblock ~16 ~3 ~47 torch 5 
setblock ~16 ~3 ~50 torch 5 
setblock ~16 ~3 ~53 torch 5 
setblock ~16 ~3 ~56 torch 5 
setblock ~16 ~3 ~59 torch 5 
setblock ~16 ~3 ~62 torch 5 
setblock ~16 ~3 ~65 torch 5 
setblock ~16 ~3 ~68 torch 5 
setblock ~16 ~3 ~71 torch 5 
setblock ~16 ~3 ~74 torch 5 
setblock ~16 ~3 ~85 torch 4 
setblock ~16 ~3 ~88 torch 3 
setblock ~17 ~3 ~0 nether_brick_stairs 1 
setblock ~17 ~3 ~14 stone 6 
setblock ~17 ~3 ~17 torch 5 
setblock ~17 ~3 ~23 torch 5 
setblock ~17 ~3 ~87 stone_brick_stairs 5 
setblock ~18 ~3 ~16 stone_brick_stairs 3  
fill ~18 ~3 ~22 ~19 ~3 ~22 carpet  
fill ~18 ~3 ~23 ~21 ~3 ~23 carpet 
setblock ~18 ~3 ~87 stone_brick_stairs 4  
fill ~19 ~3 ~15 ~20 ~3 ~15 stone  
fill ~19 ~3 ~85 ~20 ~3 ~85 torch  
fill ~19 ~3 ~86 ~20 ~3 ~86 stone  
fill ~19 ~3 ~87 ~20 ~3 ~87 stonebrick  
fill ~19 ~3 ~88 ~20 ~3 ~88 torch 
setblock ~21 ~3 ~16 stone_brick_stairs 3 
setblock ~21 ~3 ~22 carpet 12 
setblock ~21 ~3 ~87 stone_brick_stairs 5 
setblock ~22 ~3 ~0 nether_brick_stairs 0 
setblock ~22 ~3 ~13 sea_lantern 0 
setblock ~22 ~3 ~14 stone 6 
setblock ~22 ~3 ~17 torch 5 
setblock ~22 ~3 ~23 torch 5 
setblock ~22 ~3 ~87 stone_brick_stairs 4 
setblock ~23 ~3 ~13 stone_stairs 5 
setblock ~23 ~3 ~32 torch 5 
setblock ~23 ~3 ~35 torch 5 
setblock ~23 ~3 ~38 torch 5 
setblock ~23 ~3 ~41 torch 5 
setblock ~23 ~3 ~44 torch 5 
setblock ~23 ~3 ~47 torch 5 
setblock ~23 ~3 ~50 torch 5 
setblock ~23 ~3 ~53 torch 5 
setblock ~23 ~3 ~56 torch 5 
setblock ~23 ~3 ~59 torch 5 
setblock ~23 ~3 ~62 torch 5 
setblock ~23 ~3 ~65 torch 5 
setblock ~23 ~3 ~68 torch 5 
setblock ~23 ~3 ~71 torch 5 
setblock ~23 ~3 ~74 torch 5 
setblock ~23 ~3 ~85 torch 4  
fill ~23 ~3 ~87 ~30 ~3 ~87 stonebrick 
setblock ~23 ~3 ~88 torch 3 
setblock ~24 ~3 ~0 nether_brick_stairs 1  
fill ~24 ~3 ~3 ~25 ~3 ~3 stonebrick  
fill ~24 ~3 ~4 ~25 ~3 ~4 stonebrick  
fill ~24 ~3 ~5 ~36 ~3 ~5 stonebrick  
fill ~24 ~3 ~6 ~25 ~3 ~6 stonebrick  
fill ~24 ~3 ~7 ~25 ~3 ~7 stonebrick  
fill ~24 ~3 ~8 ~25 ~3 ~8 stonebrick  
fill ~24 ~3 ~9 ~25 ~3 ~9 stonebrick  
fill ~24 ~3 ~10 ~25 ~3 ~10 stonebrick 
setblock ~24 ~3 ~13 stone_stairs 4 
setblock ~24 ~3 ~29 torch 5 
setblock ~25 ~3 ~14 torch 5 
setblock ~25 ~3 ~80 torch 2 
setblock ~25 ~3 ~82 torch 2  
fill ~25 ~3 ~88 ~27 ~3 ~88 stonebrick 
setblock ~26 ~3 ~2 nether_brick_stairs 2 
setblock ~26 ~3 ~4 nether_brick_stairs 3 
setblock ~27 ~3 ~13 stone_stairs 0  
fill ~27 ~3 ~79 ~36 ~3 ~79 stonebrick  
fill ~27 ~3 ~81 ~27 ~13 ~81 stonebrick  
fill ~27 ~3 ~83 ~33 ~3 ~83 stonebrick 
setblock ~28 ~3 ~14 torch 5 
setblock ~28 ~3 ~82 torch 4 
setblock ~29 ~3 ~4 nether_brick_stairs 0  
fill ~29 ~3 ~13 ~32 ~3 ~13 cobblestone_wall 
setblock ~29 ~3 ~77 torch 4  
fill ~29 ~3 ~80 ~29 ~4 ~80 stonebrick  
fill ~29 ~3 ~81 ~29 ~4 ~81 stonebrick 
setblock ~30 ~3 ~78 stone_stairs 1 
setblock ~30 ~3 ~82 torch 4 
setblock ~30 ~3 ~84 torch 3 
setblock ~30 ~3 ~88 torch 3 
setblock ~31 ~3 ~4 nether_brick_stairs 1 
setblock ~31 ~3 ~78 stone_slab 0 
setblock ~31 ~3 ~87 stone_brick_stairs 5 
setblock ~32 ~3 ~29 torch 5 
setblock ~32 ~3 ~32 torch 5 
setblock ~32 ~3 ~35 torch 5 
setblock ~32 ~3 ~38 torch 5 
setblock ~32 ~3 ~41 torch 5 
setblock ~32 ~3 ~44 torch 5 
setblock ~32 ~3 ~47 torch 5 
setblock ~32 ~3 ~50 torch 5 
setblock ~32 ~3 ~53 torch 5 
setblock ~32 ~3 ~56 torch 5 
setblock ~32 ~3 ~59 torch 5 
setblock ~32 ~3 ~62 torch 5 
setblock ~32 ~3 ~65 torch 5 
setblock ~32 ~3 ~68 torch 5 
setblock ~32 ~3 ~71 torch 5 
setblock ~32 ~3 ~74 torch 5 
setblock ~32 ~3 ~78 stone_stairs 0 
setblock ~32 ~3 ~85 torch 2 
setblock ~32 ~3 ~87 stone_brick_stairs 4 
setblock ~33 ~3 ~14 torch 5 
setblock ~33 ~3 ~77 torch 4  
fill ~33 ~3 ~85 ~33 ~8 ~85 stonebrick  
fill ~33 ~3 ~87 ~36 ~3 ~87 stonebrick 
setblock ~33 ~3 ~88 torch 3 
setblock ~34 ~3 ~4 nether_brick_stairs 0 
setblock ~34 ~3 ~13 stone_stairs 1 
setblock ~34 ~3 ~18 torch 2 
setblock ~34 ~3 ~24 torch 2 
setblock ~34 ~3 ~26 wool 0 
setblock ~34 ~3 ~29 wool 0 
setblock ~34 ~3 ~32 wool 0 
setblock ~34 ~3 ~44 wool 0 
setblock ~34 ~3 ~47 wool 0 
setblock ~34 ~3 ~59 wool 0 
setblock ~34 ~3 ~62 wool 0 
setblock ~34 ~3 ~74 wool 0  
fill ~34 ~3 ~81 ~35 ~3 ~81 stone_stairs  
fill ~34 ~3 ~82 ~35 ~3 ~82 stone_stairs 
setblock ~34 ~3 ~85 torch 1  
fill ~35 ~3 ~19 ~36 ~3 ~19 stone_brick_stairs  
fill ~35 ~3 ~20 ~36 ~3 ~20 stone_brick_stairs  
fill ~35 ~3 ~22 ~36 ~3 ~22 stone_brick_stairs  
fill ~35 ~3 ~23 ~36 ~3 ~23 stone_brick_stairs  
fill ~35 ~3 ~36 ~35 ~7 ~36 stone 
setblock ~35 ~3 ~37 stone_brick_stairs 3 
setblock ~35 ~3 ~38 stone_slab 0 
setblock ~35 ~3 ~39 stone_brick_stairs 2  
fill ~35 ~3 ~40 ~35 ~7 ~40 stone  
fill ~35 ~3 ~51 ~35 ~7 ~51 stone 
setblock ~35 ~3 ~52 stone_brick_stairs 3 
setblock ~35 ~3 ~53 stone_slab 0 
setblock ~35 ~3 ~54 stone_brick_stairs 2  
fill ~35 ~3 ~55 ~35 ~7 ~55 stone  
fill ~35 ~3 ~66 ~35 ~7 ~66 stone 
setblock ~35 ~3 ~67 stone_brick_stairs 3 
setblock ~35 ~3 ~68 stone_slab 0 
setblock ~35 ~3 ~69 stone_brick_stairs 2  
fill ~35 ~3 ~70 ~35 ~7 ~70 stone 
setblock ~36 ~3 ~4 nether_brick_stairs 1 
setblock ~37 ~3 ~5 nether_brick_stairs 2 
setblock ~37 ~3 ~7 nether_brick_stairs 3 
setblock ~37 ~3 ~10 nether_brick_stairs 2 
setblock ~37 ~3 ~12 nether_brick_stairs 3 
setblock ~37 ~3 ~15 nether_brick_stairs 2 
setblock ~37 ~3 ~18 nether_brick_stairs 7 
setblock ~37 ~3 ~20 torch 4 
setblock ~37 ~3 ~22 torch 3 
setblock ~37 ~3 ~24 nether_brick_stairs 6 
setblock ~37 ~3 ~27 nether_brick_stairs 3 
setblock ~37 ~3 ~30 nether_brick_stairs 2 
setblock ~37 ~3 ~32 nether_brick_stairs 3 
setblock ~37 ~3 ~35 nether_brick_stairs 2 
setblock ~37 ~3 ~37 nether_brick_stairs 3 
setblock ~37 ~3 ~40 nether_brick_stairs 2 
setblock ~37 ~3 ~42 nether_brick_stairs 3 
setblock ~37 ~3 ~45 nether_brick_stairs 2 
setblock ~37 ~3 ~47 nether_brick_stairs 3 
setblock ~37 ~3 ~50 nether_brick_stairs 2 
setblock ~37 ~3 ~52 nether_brick_stairs 3 
setblock ~37 ~3 ~55 nether_brick_stairs 2 
setblock ~37 ~3 ~57 nether_brick_stairs 3 
setblock ~37 ~3 ~60 nether_brick_stairs 2 
setblock ~37 ~3 ~62 nether_brick_stairs 3 
setblock ~37 ~3 ~65 nether_brick_stairs 2 
setblock ~37 ~3 ~67 nether_brick_stairs 3 
setblock ~37 ~3 ~70 nether_brick_stairs 2 
setblock ~37 ~3 ~72 nether_brick_stairs 3 
setblock ~37 ~3 ~75 nether_brick_stairs 2 
setblock ~37 ~3 ~77 nether_brick_stairs 3 
setblock ~37 ~3 ~80 nether_brick_stairs 2 
setblock ~37 ~3 ~82 nether_brick_stairs 3 
setblock ~37 ~3 ~85 nether_brick_stairs 2 
setblock ~37 ~3 ~87 nether_brick_stairs 3 
setblock ~2 ~4 ~5 nether_brick_stairs 6 
setblock ~2 ~4 ~7 nether_brick_stairs 7 
setblock ~2 ~4 ~10 nether_brick_stairs 6 
setblock ~2 ~4 ~12 nether_brick_stairs 7 
setblock ~2 ~4 ~15 nether_brick_stairs 6  
fill ~2 ~4 ~18 ~2 ~5 ~18 stone 
setblock ~2 ~4 ~19 nether_brick_stairs 7 
setblock ~2 ~4 ~23 nether_brick_stairs 6  
fill ~2 ~4 ~24 ~2 ~5 ~24 stone 
setblock ~2 ~4 ~27 nether_brick_stairs 7 
setblock ~2 ~4 ~30 nether_brick_stairs 6 
setblock ~2 ~4 ~32 nether_brick_stairs 7 
setblock ~2 ~4 ~35 nether_brick_stairs 6 
setblock ~2 ~4 ~37 nether_brick_stairs 7 
setblock ~2 ~4 ~40 nether_brick_stairs 6 
setblock ~2 ~4 ~42 nether_brick_stairs 7 
setblock ~2 ~4 ~45 nether_brick_stairs 6 
setblock ~2 ~4 ~47 nether_brick_stairs 7 
setblock ~2 ~4 ~50 nether_brick_stairs 6 
setblock ~2 ~4 ~52 nether_brick_stairs 7 
setblock ~2 ~4 ~55 nether_brick_stairs 6 
setblock ~2 ~4 ~57 nether_brick_stairs 7 
setblock ~2 ~4 ~60 nether_brick_stairs 6 
setblock ~2 ~4 ~62 nether_brick_stairs 7 
setblock ~2 ~4 ~65 nether_brick_stairs 6 
setblock ~2 ~4 ~67 nether_brick_stairs 7 
setblock ~2 ~4 ~70 nether_brick_stairs 6 
setblock ~2 ~4 ~72 nether_brick_stairs 7 
setblock ~2 ~4 ~75 nether_brick_stairs 6 
setblock ~2 ~4 ~77 nether_brick_stairs 7 
setblock ~2 ~4 ~80 nether_brick_stairs 6 
setblock ~2 ~4 ~82 nether_brick_stairs 7 
setblock ~2 ~4 ~85 nether_brick_stairs 6 
setblock ~2 ~4 ~87 nether_brick_stairs 7 
setblock ~3 ~4 ~4 nether_brick_stairs 4  
fill ~3 ~4 ~5 ~15 ~4 ~5 stonebrick  
fill ~3 ~4 ~12 ~36 ~4 ~12 stonebrick  
fill ~3 ~4 ~19 ~3 ~17 ~19 stonebrick  
fill ~3 ~4 ~20 ~3 ~23 ~20 stonebrick  
fill ~3 ~4 ~22 ~3 ~23 ~22 stonebrick  
fill ~3 ~4 ~23 ~3 ~17 ~23 stonebrick  
fill ~3 ~4 ~79 ~12 ~4 ~79 stonebrick  
fill ~3 ~4 ~87 ~6 ~4 ~87 stonebrick 
setblock ~4 ~4 ~18 stone_stairs 2  
fill ~4 ~4 ~19 ~4 ~4 ~20 stone  
fill ~4 ~4 ~22 ~4 ~4 ~23 stone 
setblock ~4 ~4 ~24 stone_stairs 3 
setblock ~4 ~4 ~26 stone_stairs 1 
setblock ~4 ~4 ~29 stone_stairs 1 
setblock ~4 ~4 ~32 stone_stairs 1 
setblock ~4 ~4 ~35 stone_stairs 2 
setblock ~4 ~4 ~37 nether_brick_stairs 7 
setblock ~4 ~4 ~38 stone_slab 7 
setblock ~4 ~4 ~39 nether_brick_stairs 6 
setblock ~4 ~4 ~41 stone_stairs 3 
setblock ~4 ~4 ~44 stone_stairs 1 
setblock ~4 ~4 ~47 stone_stairs 1 
setblock ~4 ~4 ~50 stone_stairs 2 
setblock ~4 ~4 ~52 nether_brick_stairs 7 
setblock ~4 ~4 ~53 stone_slab 7 
setblock ~4 ~4 ~54 nether_brick_stairs 6 
setblock ~4 ~4 ~56 stone_stairs 3 
setblock ~4 ~4 ~59 stone_stairs 1 
setblock ~4 ~4 ~62 stone_stairs 1 
setblock ~4 ~4 ~65 stone_stairs 2 
setblock ~4 ~4 ~67 nether_brick_stairs 7 
setblock ~4 ~4 ~68 stone_slab 7 
setblock ~4 ~4 ~69 nether_brick_stairs 6 
setblock ~4 ~4 ~71 stone_stairs 3 
setblock ~4 ~4 ~74 stone_stairs 1  
fill ~4 ~4 ~80 ~7 ~4 ~80 stone  
fill ~4 ~4 ~81 ~5 ~4 ~81 stone_stairs 
setblock ~5 ~4 ~4 nether_brick_stairs 5 
setblock ~5 ~4 ~13 stone_stairs 4 
setblock ~5 ~4 ~21 torch 1 
setblock ~5 ~4 ~88 nether_brick_stairs 5 
setblock ~6 ~4 ~14 fence 0 
setblock ~6 ~4 ~78 stone_stairs 2 
setblock ~6 ~4 ~81 stonebrick 0  
fill ~6 ~4 ~83 ~12 ~4 ~83 stonebrick  
fill ~7 ~4 ~13 ~7 ~6 ~13 cobblestone_wall  
fill ~7 ~4 ~87 ~8 ~4 ~87 cobblestone_wall 
setblock ~8 ~4 ~4 nether_brick_stairs 4 
setblock ~8 ~4 ~13 nether_brick_stairs 1 
setblock ~9 ~4 ~13 nether_brick_stairs 0  
fill ~9 ~4 ~80 ~9 ~4 ~83 stonebrick  
fill ~9 ~4 ~87 ~16 ~4 ~87 stonebrick 
setblock ~10 ~4 ~4 nether_brick_stairs 5  
fill ~10 ~4 ~13 ~10 ~6 ~13 cobblestone_wall 
setblock ~10 ~4 ~78 stone_stairs 2 
setblock ~10 ~4 ~88 nether_brick_stairs 4 
setblock ~11 ~4 ~14 fence 0  
fill ~11 ~4 ~80 ~11 ~4 ~83 stonebrick 
setblock ~12 ~4 ~13 stone_stairs 5  
fill ~12 ~4 ~88 ~14 ~4 ~88 stonebrick 
setblock ~13 ~4 ~2 nether_brick_stairs 6 
setblock ~13 ~4 ~4 nether_brick_stairs 7 
setblock ~13 ~4 ~80 stone_stairs 1 
setblock ~13 ~4 ~82 stone_stairs 1  
fill ~14 ~4 ~1 ~25 ~4 ~1 stonebrick  
fill ~14 ~4 ~2 ~25 ~4 ~2 stonebrick  
fill ~14 ~4 ~3 ~15 ~4 ~3 stonebrick  
fill ~14 ~4 ~4 ~15 ~4 ~4 stonebrick  
fill ~14 ~4 ~6 ~15 ~4 ~6 stonebrick  
fill ~14 ~4 ~7 ~15 ~4 ~7 stonebrick  
fill ~14 ~4 ~8 ~15 ~4 ~8 stonebrick  
fill ~14 ~4 ~9 ~15 ~4 ~9 stonebrick  
fill ~14 ~4 ~10 ~15 ~4 ~10 stonebrick  
fill ~14 ~4 ~11 ~25 ~4 ~11 stonebrick 
setblock ~14 ~4 ~14 fence 1 
setblock ~15 ~4 ~0 nether_brick_stairs 4 
setblock ~15 ~4 ~13 stone_stairs 1 
setblock ~16 ~4 ~13 stone_stairs 0 
setblock ~16 ~4 ~86 stone_stairs 0 
setblock ~16 ~4 ~88 nether_brick_stairs 5 
setblock ~17 ~4 ~0 nether_brick_stairs 5  
fill ~17 ~4 ~13 ~17 ~4 ~14 cobblestone_wall 
setblock ~17 ~4 ~86 stone_stairs 5  
fill ~17 ~4 ~87 ~18 ~4 ~87 cobblestone_wall  
fill ~18 ~4 ~13 ~18 ~4 ~14 stonebrick  
fill ~18 ~4 ~15 ~21 ~4 ~15 cobblestone_wall 
setblock ~18 ~4 ~86 stone_stairs 4  
fill ~19 ~4 ~14 ~21 ~4 ~14 stonebrick 
setblock ~19 ~4 ~86 stone_stairs 1  
fill ~19 ~4 ~87 ~20 ~4 ~87 stonebrick 
setblock ~20 ~4 ~86 stone_stairs 0 
setblock ~21 ~4 ~13 stonebrick 3 
setblock ~21 ~4 ~86 stone_stairs 5  
fill ~21 ~4 ~87 ~22 ~4 ~87 cobblestone_wall 
setblock ~22 ~4 ~0 nether_brick_stairs 4  
fill ~22 ~4 ~13 ~22 ~4 ~14 cobblestone_wall 
setblock ~22 ~4 ~86 stone_stairs 4 
setblock ~23 ~4 ~13 stone_stairs 1 
setblock ~23 ~4 ~86 stone_stairs 1  
fill ~23 ~4 ~87 ~30 ~4 ~87 stonebrick 
setblock ~23 ~4 ~88 nether_brick_stairs 4 
setblock ~24 ~4 ~0 nether_brick_stairs 5  
fill ~24 ~4 ~3 ~25 ~4 ~3 stonebrick  
fill ~24 ~4 ~4 ~25 ~4 ~4 stonebrick  
fill ~24 ~4 ~5 ~36 ~4 ~5 stonebrick  
fill ~24 ~4 ~6 ~25 ~4 ~6 stonebrick  
fill ~24 ~4 ~7 ~25 ~4 ~7 stonebrick  
fill ~24 ~4 ~8 ~25 ~4 ~8 stonebrick  
fill ~24 ~4 ~9 ~25 ~4 ~9 stonebrick  
fill ~24 ~4 ~10 ~25 ~4 ~10 stonebrick 
setblock ~24 ~4 ~13 stone_stairs 0 
setblock ~25 ~4 ~14 fence 1  
fill ~25 ~4 ~88 ~27 ~4 ~88 stonebrick 
setblock ~26 ~4 ~2 nether_brick_stairs 6 
setblock ~26 ~4 ~4 nether_brick_stairs 7 
setblock ~26 ~4 ~80 stone_stairs 0 
setblock ~26 ~4 ~82 stone_stairs 0 
setblock ~27 ~4 ~13 stone_stairs 4  
fill ~27 ~4 ~79 ~36 ~4 ~79 stonebrick  
fill ~27 ~4 ~83 ~33 ~4 ~83 stonebrick 
setblock ~28 ~4 ~14 fence 0  
fill ~28 ~4 ~80 ~28 ~4 ~83 stonebrick 
setblock ~29 ~4 ~4 nether_brick_stairs 4  
fill ~29 ~4 ~13 ~29 ~6 ~13 cobblestone_wall 
setblock ~29 ~4 ~78 stone_stairs 2 
setblock ~29 ~4 ~88 nether_brick_stairs 5 
setblock ~30 ~4 ~13 nether_brick_stairs 1  
fill ~30 ~4 ~80 ~30 ~4 ~83 stonebrick 
setblock ~31 ~4 ~4 nether_brick_stairs 5 
setblock ~31 ~4 ~13 nether_brick_stairs 0  
fill ~31 ~4 ~87 ~32 ~4 ~87 cobblestone_wall  
fill ~32 ~4 ~13 ~32 ~6 ~13 cobblestone_wall  
fill ~32 ~4 ~80 ~35 ~4 ~80 stone 
setblock ~32 ~4 ~81 stonebrick 0 
setblock ~33 ~4 ~14 fence 0 
setblock ~33 ~4 ~78 stone_stairs 2  
fill ~33 ~4 ~87 ~36 ~4 ~87 stonebrick 
setblock ~34 ~4 ~4 nether_brick_stairs 4 
setblock ~34 ~4 ~13 stone_stairs 5 
setblock ~34 ~4 ~21 torch 2  
fill ~34 ~4 ~81 ~35 ~4 ~81 stone_stairs 
setblock ~34 ~4 ~88 nether_brick_stairs 4 
setblock ~35 ~4 ~18 stone_stairs 2  
fill ~35 ~4 ~19 ~35 ~4 ~20 stone  
fill ~35 ~4 ~22 ~35 ~4 ~23 stone 
setblock ~35 ~4 ~24 stone_stairs 3 
setblock ~35 ~4 ~26 stone_stairs 0 
setblock ~35 ~4 ~29 stone_stairs 0 
setblock ~35 ~4 ~32 stone_stairs 0 
setblock ~35 ~4 ~35 stone_stairs 2 
setblock ~35 ~4 ~37 nether_brick_stairs 7 
setblock ~35 ~4 ~38 stone_slab 7 
setblock ~35 ~4 ~39 nether_brick_stairs 6 
setblock ~35 ~4 ~41 stone_stairs 3 
setblock ~35 ~4 ~44 stone_stairs 0 
setblock ~35 ~4 ~47 stone_stairs 0 
setblock ~35 ~4 ~50 stone_stairs 2 
setblock ~35 ~4 ~52 nether_brick_stairs 7 
setblock ~35 ~4 ~53 stone_slab 7 
setblock ~35 ~4 ~54 nether_brick_stairs 6 
setblock ~35 ~4 ~56 stone_stairs 3 
setblock ~35 ~4 ~59 stone_stairs 0 
setblock ~35 ~4 ~62 stone_stairs 0 
setblock ~35 ~4 ~65 stone_stairs 2 
setblock ~35 ~4 ~67 nether_brick_stairs 7 
setblock ~35 ~4 ~68 stone_slab 7 
setblock ~35 ~4 ~69 nether_brick_stairs 6 
setblock ~35 ~4 ~71 stone_stairs 3 
setblock ~35 ~4 ~74 stone_stairs 0 
setblock ~36 ~4 ~4 nether_brick_stairs 5  
fill ~36 ~4 ~19 ~36 ~17 ~19 stonebrick  
fill ~36 ~4 ~20 ~36 ~23 ~20 stonebrick  
fill ~36 ~4 ~22 ~36 ~23 ~22 stonebrick  
fill ~36 ~4 ~23 ~36 ~17 ~23 stonebrick 
setblock ~37 ~4 ~5 nether_brick_stairs 6 
setblock ~37 ~4 ~7 nether_brick_stairs 7 
setblock ~37 ~4 ~10 nether_brick_stairs 6 
setblock ~37 ~4 ~12 nether_brick_stairs 7 
setblock ~37 ~4 ~15 nether_brick_stairs 6  
fill ~37 ~4 ~18 ~37 ~5 ~18 stone 
setblock ~37 ~4 ~19 nether_brick_stairs 7 
setblock ~37 ~4 ~23 nether_brick_stairs 6  
fill ~37 ~4 ~24 ~37 ~5 ~24 stone 
setblock ~37 ~4 ~27 nether_brick_stairs 7 
setblock ~37 ~4 ~30 nether_brick_stairs 6 
setblock ~37 ~4 ~32 nether_brick_stairs 7 
setblock ~37 ~4 ~35 nether_brick_stairs 6 
setblock ~37 ~4 ~37 nether_brick_stairs 7 
setblock ~37 ~4 ~40 nether_brick_stairs 6 
setblock ~37 ~4 ~42 nether_brick_stairs 7 
setblock ~37 ~4 ~45 nether_brick_stairs 6 
setblock ~37 ~4 ~47 nether_brick_stairs 7 
setblock ~37 ~4 ~50 nether_brick_stairs 6 
setblock ~37 ~4 ~52 nether_brick_stairs 7 
setblock ~37 ~4 ~55 nether_brick_stairs 6 
setblock ~37 ~4 ~57 nether_brick_stairs 7 
setblock ~37 ~4 ~60 nether_brick_stairs 6 
setblock ~37 ~4 ~62 nether_brick_stairs 7 
setblock ~37 ~4 ~65 nether_brick_stairs 6 
setblock ~37 ~4 ~67 nether_brick_stairs 7 
setblock ~37 ~4 ~70 nether_brick_stairs 6 
setblock ~37 ~4 ~72 nether_brick_stairs 7 
setblock ~37 ~4 ~75 nether_brick_stairs 6 
setblock ~37 ~4 ~77 nether_brick_stairs 7 
setblock ~37 ~4 ~80 nether_brick_stairs 6 
setblock ~37 ~4 ~82 nether_brick_stairs 7 
setblock ~37 ~4 ~85 nether_brick_stairs 6 
setblock ~37 ~4 ~87 nether_brick_stairs 7 
setblock ~1 ~5 ~6 torch 2 
setblock ~1 ~5 ~11 torch 2 
setblock ~1 ~5 ~16 torch 2 
setblock ~1 ~5 ~21 torch 2 
setblock ~1 ~5 ~26 torch 2 
setblock ~1 ~5 ~31 torch 2 
setblock ~1 ~5 ~36 torch 2 
setblock ~1 ~5 ~41 torch 2 
setblock ~1 ~5 ~46 torch 2 
setblock ~1 ~5 ~51 torch 2 
setblock ~1 ~5 ~56 torch 2 
setblock ~1 ~5 ~61 torch 2 
setblock ~1 ~5 ~66 torch 2 
setblock ~1 ~5 ~71 torch 2 
setblock ~1 ~5 ~76 torch 2 
setblock ~1 ~5 ~81 torch 2 
setblock ~1 ~5 ~86 torch 2 
setblock ~2 ~5 ~5 nether_brick_stairs 2 
setblock ~2 ~5 ~7 nether_brick_stairs 3 
setblock ~2 ~5 ~10 nether_brick_stairs 2 
setblock ~2 ~5 ~12 nether_brick_stairs 3 
setblock ~2 ~5 ~15 nether_brick_stairs 2  
fill ~2 ~5 ~19 ~2 ~6 ~19 stone 
setblock ~2 ~5 ~20 nether_brick_stairs 7 
setblock ~2 ~5 ~22 nether_brick_stairs 6  
fill ~2 ~5 ~23 ~2 ~6 ~23 stone 
setblock ~2 ~5 ~27 nether_brick_stairs 3 
setblock ~2 ~5 ~30 nether_brick_stairs 2 
setblock ~2 ~5 ~32 nether_brick_stairs 3 
setblock ~2 ~5 ~35 nether_brick_stairs 2 
setblock ~2 ~5 ~37 nether_brick_stairs 3 
setblock ~2 ~5 ~40 nether_brick_stairs 2 
setblock ~2 ~5 ~42 nether_brick_stairs 3 
setblock ~2 ~5 ~45 nether_brick_stairs 2 
setblock ~2 ~5 ~47 nether_brick_stairs 3 
setblock ~2 ~5 ~50 nether_brick_stairs 2 
setblock ~2 ~5 ~52 nether_brick_stairs 3 
setblock ~2 ~5 ~55 nether_brick_stairs 2 
setblock ~2 ~5 ~57 nether_brick_stairs 3 
setblock ~2 ~5 ~60 nether_brick_stairs 2 
setblock ~2 ~5 ~62 nether_brick_stairs 3 
setblock ~2 ~5 ~65 nether_brick_stairs 2 
setblock ~2 ~5 ~67 nether_brick_stairs 3 
setblock ~2 ~5 ~70 nether_brick_stairs 2 
setblock ~2 ~5 ~72 nether_brick_stairs 3 
setblock ~2 ~5 ~75 nether_brick_stairs 2 
setblock ~2 ~5 ~77 nether_brick_stairs 3 
setblock ~2 ~5 ~80 nether_brick_stairs 2 
setblock ~2 ~5 ~82 nether_brick_stairs 3 
setblock ~2 ~5 ~85 nether_brick_stairs 2 
setblock ~2 ~5 ~87 nether_brick_stairs 3 
setblock ~3 ~5 ~4 nether_brick_stairs 0  
fill ~3 ~5 ~5 ~15 ~5 ~5 stonebrick  
fill ~3 ~5 ~12 ~36 ~5 ~12 stonebrick  
fill ~3 ~5 ~79 ~12 ~5 ~79 stonebrick  
fill ~3 ~5 ~87 ~36 ~5 ~87 stonebrick 
setblock ~3 ~5 ~90 torch 3 
setblock ~4 ~5 ~3 torch 4 
setblock ~4 ~5 ~19 stone_slab 0 
setblock ~4 ~5 ~20 double_stone_slab 0 
setblock ~4 ~5 ~21 stone_brick_stairs 1 
setblock ~4 ~5 ~22 double_stone_slab 0 
setblock ~4 ~5 ~23 stone_slab 0 
setblock ~4 ~5 ~37 stone 6 
setblock ~4 ~5 ~38 cobblestone_wall 0 
setblock ~4 ~5 ~39 stone 6 
setblock ~4 ~5 ~52 stone 6 
setblock ~4 ~5 ~53 cobblestone_wall 0 
setblock ~4 ~5 ~54 stone 6 
setblock ~4 ~5 ~67 stone 6 
setblock ~4 ~5 ~68 cobblestone_wall 0 
setblock ~4 ~5 ~69 stone 6 
setblock ~4 ~5 ~89 nether_brick_stairs 5 
setblock ~5 ~5 ~4 nether_brick_stairs 1 
setblock ~5 ~5 ~13 stone_stairs 0  
fill ~5 ~5 ~88 ~5 ~6 ~88 stone 
setblock ~6 ~5 ~14 torch 5  
fill ~6 ~5 ~81 ~7 ~5 ~81 stone_stairs  
fill ~6 ~5 ~83 ~12 ~5 ~83 stonebrick 
setblock ~6 ~5 ~88 nether_brick_stairs 5 
setblock ~8 ~5 ~4 nether_brick_stairs 0 
setblock ~8 ~5 ~13 nether_brick_stairs 5  
fill ~8 ~5 ~80 ~8 ~13 ~80 stonebrick  
fill ~8 ~5 ~81 ~8 ~13 ~81 stonebrick  
fill ~8 ~5 ~82 ~8 ~12 ~82 stonebrick 
setblock ~9 ~5 ~3 torch 4 
setblock ~9 ~5 ~13 nether_brick_stairs 4 
setblock ~9 ~5 ~88 nether_brick_stairs 4 
setblock ~10 ~5 ~4 nether_brick_stairs 1  
fill ~10 ~5 ~88 ~10 ~6 ~88 stone 
setblock ~11 ~5 ~14 torch 5 
setblock ~11 ~5 ~89 nether_brick_stairs 4 
setblock ~12 ~5 ~3 torch 2 
setblock ~12 ~5 ~13 stone_stairs 1  
fill ~12 ~5 ~88 ~14 ~5 ~88 stonebrick 
setblock ~12 ~5 ~90 torch 3 
setblock ~13 ~5 ~2 nether_brick_stairs 2 
setblock ~13 ~5 ~4 nether_brick_stairs 3  
fill ~14 ~5 ~1 ~25 ~5 ~1 stonebrick  
fill ~14 ~5 ~2 ~25 ~5 ~2 stonebrick  
fill ~14 ~5 ~3 ~15 ~5 ~3 stonebrick  
fill ~14 ~5 ~4 ~15 ~5 ~4 stonebrick  
fill ~14 ~5 ~6 ~15 ~5 ~6 stonebrick  
fill ~14 ~5 ~7 ~15 ~5 ~7 stonebrick  
fill ~14 ~5 ~8 ~15 ~5 ~8 stonebrick  
fill ~14 ~5 ~9 ~15 ~5 ~9 stonebrick  
fill ~14 ~5 ~10 ~15 ~5 ~10 stonebrick  
fill ~14 ~5 ~11 ~25 ~5 ~11 stonebrick 
setblock ~14 ~5 ~14 torch 5 
setblock ~14 ~5 ~90 torch 3 
setblock ~15 ~5 ~0 nether_brick_stairs 0 
setblock ~15 ~5 ~13 nether_brick_stairs 5 
setblock ~15 ~5 ~89 nether_brick_stairs 5  

KittysCommands:   
fill ~16 ~5 ~88 ~16 ~6 ~88 stone 
setblock ~17 ~5 ~0 nether_brick_stairs 1  
fill ~17 ~5 ~13 ~17 ~5 ~14 stone_brick_stairs  
fill ~17 ~5 ~86 ~18 ~5 ~86 stone_slab 
setblock ~17 ~5 ~88 nether_brick_stairs 5  
fill ~18 ~5 ~13 ~18 ~7 ~13 cobblestone_wall  
fill ~18 ~5 ~15 ~21 ~5 ~15 stone_brick_stairs 
setblock ~19 ~5 ~86 stone_stairs 5 
setblock ~20 ~5 ~86 stone_stairs 4  
fill ~21 ~5 ~13 ~21 ~7 ~13 cobblestone_wall  
fill ~21 ~5 ~86 ~22 ~5 ~86 stone_slab 
setblock ~22 ~5 ~0 nether_brick_stairs 0  
fill ~22 ~5 ~13 ~22 ~5 ~14 stone_brick_stairs 
setblock ~22 ~5 ~88 nether_brick_stairs 4  
fill ~23 ~5 ~88 ~23 ~6 ~88 stone 
setblock ~24 ~5 ~0 nether_brick_stairs 1  
fill ~24 ~5 ~3 ~25 ~5 ~3 stonebrick  
fill ~24 ~5 ~4 ~25 ~5 ~4 stonebrick  
fill ~24 ~5 ~5 ~36 ~5 ~5 stonebrick  
fill ~24 ~5 ~6 ~25 ~5 ~6 stonebrick  
fill ~24 ~5 ~7 ~25 ~5 ~7 stonebrick  
fill ~24 ~5 ~8 ~25 ~5 ~8 stonebrick  
fill ~24 ~5 ~9 ~25 ~5 ~9 stonebrick  
fill ~24 ~5 ~10 ~25 ~5 ~10 stonebrick 
setblock ~24 ~5 ~13 nether_brick_stairs 4 
setblock ~24 ~5 ~89 nether_brick_stairs 4 
setblock ~25 ~5 ~14 torch 5  
fill ~25 ~5 ~88 ~27 ~5 ~88 stonebrick 
setblock ~25 ~5 ~90 torch 3 
setblock ~26 ~5 ~2 nether_brick_stairs 2 
setblock ~26 ~5 ~4 nether_brick_stairs 3 
setblock ~27 ~5 ~3 torch 1 
setblock ~27 ~5 ~13 stone_stairs 0  
fill ~27 ~5 ~79 ~36 ~5 ~79 stonebrick  
fill ~27 ~5 ~83 ~33 ~5 ~83 stonebrick 
setblock ~27 ~5 ~90 torch 3 
setblock ~28 ~5 ~14 torch 5 
setblock ~28 ~5 ~89 nether_brick_stairs 5 
setblock ~29 ~5 ~4 nether_brick_stairs 0  
fill ~29 ~5 ~88 ~29 ~6 ~88 stone 
setblock ~30 ~5 ~3 torch 4 
setblock ~30 ~5 ~13 nether_brick_stairs 5 
setblock ~30 ~5 ~88 nether_brick_stairs 5 
setblock ~31 ~5 ~4 nether_brick_stairs 1 
setblock ~31 ~5 ~13 nether_brick_stairs 4  
fill ~32 ~5 ~81 ~33 ~5 ~81 stone_stairs 
setblock ~33 ~5 ~14 torch 5 
setblock ~33 ~5 ~88 nether_brick_stairs 4 
setblock ~34 ~5 ~4 nether_brick_stairs 0 
setblock ~34 ~5 ~13 stone_stairs 1  
fill ~34 ~5 ~88 ~34 ~6 ~88 stone 
setblock ~35 ~5 ~3 torch 4 
setblock ~35 ~5 ~19 stone_slab 0 
setblock ~35 ~5 ~20 double_stone_slab 0 
setblock ~35 ~5 ~21 stone_brick_stairs 0 
setblock ~35 ~5 ~22 double_stone_slab 0 
setblock ~35 ~5 ~23 stone_slab 0 
setblock ~35 ~5 ~37 stone 6 
setblock ~35 ~5 ~38 cobblestone_wall 0 
setblock ~35 ~5 ~39 stone 6 
setblock ~35 ~5 ~52 stone 6 
setblock ~35 ~5 ~53 cobblestone_wall 0 
setblock ~35 ~5 ~54 stone 6 
setblock ~35 ~5 ~67 stone 6 
setblock ~35 ~5 ~68 cobblestone_wall 0 
setblock ~35 ~5 ~69 stone 6 
setblock ~35 ~5 ~89 nether_brick_stairs 4 
setblock ~36 ~5 ~4 nether_brick_stairs 1 
setblock ~36 ~5 ~90 torch 3 
setblock ~37 ~5 ~5 nether_brick_stairs 2 
setblock ~37 ~5 ~7 nether_brick_stairs 3 
setblock ~37 ~5 ~10 nether_brick_stairs 2 
setblock ~37 ~5 ~12 nether_brick_stairs 3 
setblock ~37 ~5 ~15 nether_brick_stairs 2  
fill ~37 ~5 ~19 ~37 ~6 ~19 stone 
setblock ~37 ~5 ~20 nether_brick_stairs 7 
setblock ~37 ~5 ~22 nether_brick_stairs 6  
fill ~37 ~5 ~23 ~37 ~6 ~23 stone 
setblock ~37 ~5 ~27 nether_brick_stairs 3 
setblock ~37 ~5 ~30 nether_brick_stairs 2 
setblock ~37 ~5 ~32 nether_brick_stairs 3 
setblock ~37 ~5 ~35 nether_brick_stairs 2 
setblock ~37 ~5 ~37 nether_brick_stairs 3 
setblock ~37 ~5 ~40 nether_brick_stairs 2 
setblock ~37 ~5 ~42 nether_brick_stairs 3 
setblock ~37 ~5 ~45 nether_brick_stairs 2 
setblock ~37 ~5 ~47 nether_brick_stairs 3 
setblock ~37 ~5 ~50 nether_brick_stairs 2 
setblock ~37 ~5 ~52 nether_brick_stairs 3 
setblock ~37 ~5 ~55 nether_brick_stairs 2 
setblock ~37 ~5 ~57 nether_brick_stairs 3 
setblock ~37 ~5 ~60 nether_brick_stairs 2 
setblock ~37 ~5 ~62 nether_brick_stairs 3 
setblock ~37 ~5 ~65 nether_brick_stairs 2 
setblock ~37 ~5 ~67 nether_brick_stairs 3 
setblock ~37 ~5 ~70 nether_brick_stairs 2 
setblock ~37 ~5 ~72 nether_brick_stairs 3 
setblock ~37 ~5 ~75 nether_brick_stairs 2 
setblock ~37 ~5 ~77 nether_brick_stairs 3 
setblock ~37 ~5 ~80 nether_brick_stairs 2 
setblock ~37 ~5 ~82 nether_brick_stairs 3 
setblock ~37 ~5 ~85 nether_brick_stairs 2 
setblock ~37 ~5 ~87 nether_brick_stairs 3 
setblock ~2 ~6 ~17 stone_slab 7 
setblock ~2 ~6 ~18 nether_brick_stairs 2  
fill ~2 ~6 ~20 ~2 ~7 ~20 stone  
fill ~2 ~6 ~22 ~2 ~7 ~22 stone 
setblock ~2 ~6 ~24 nether_brick_stairs 3 
setblock ~2 ~6 ~25 stone_slab 7  
fill ~3 ~6 ~5 ~15 ~6 ~5 stonebrick  
fill ~3 ~6 ~12 ~36 ~6 ~12 stonebrick  
fill ~3 ~6 ~79 ~12 ~6 ~79 stonebrick  
fill ~3 ~6 ~87 ~36 ~6 ~87 stonebrick 
setblock ~4 ~6 ~20 stone_stairs 2 
setblock ~4 ~6 ~21 nether_brick 0 
setblock ~4 ~6 ~22 stone_stairs 3 
setblock ~4 ~6 ~37 nether_brick_stairs 3 
setblock ~4 ~6 ~38 stone_slab 15 
setblock ~4 ~6 ~39 nether_brick_stairs 2 
