setblock ~-15 ~62 ~98 hopper 3  
setblock ~-16 ~62 ~98 hopper 3  
setblock ~-3 ~62 ~3 hopper 2  
setblock ~-1 ~62 ~84 hopper 5  
setblock ~-1 ~62 ~83 hopper 5  
setblock ~39 ~62 ~3 hopper 2  
setblock ~39 ~62 ~95 hopper 3 
setblock ~46 ~0 ~-13 sapling 3  
fill ~11 ~1 ~44 ~11 ~29 ~44 stained_hardened_clay 12  
fill ~11 ~1 ~45 ~11 ~27 ~45 stained_hardened_clay 12  
fill ~11 ~1 ~46 ~11 ~57 ~46 stained_hardened_clay 12  
fill ~11 ~1 ~52 ~11 ~57 ~52 stained_hardened_clay 12  
fill ~11 ~1 ~53 ~11 ~27 ~53 stained_hardened_clay 12  
fill ~11 ~1 ~54 ~11 ~29 ~54 stained_hardened_clay 12  
fill ~12 ~1 ~43 ~12 ~29 ~43 stained_hardened_clay 12  
fill ~12 ~1 ~47 ~12 ~57 ~47 stained_hardened_clay 12  
fill ~12 ~1 ~51 ~12 ~57 ~51 stained_hardened_clay 12  
fill ~12 ~1 ~55 ~12 ~29 ~55 stained_hardened_clay 12  
fill ~13 ~1 ~42 ~15 ~1 ~42 stained_hardened_clay 12  
fill ~13 ~1 ~48 ~15 ~1 ~48 stained_hardened_clay 12  
fill ~13 ~1 ~50 ~15 ~1 ~50 stained_hardened_clay 12  
fill ~13 ~1 ~56 ~15 ~1 ~56 stained_hardened_clay 12  
fill ~16 ~1 ~43 ~16 ~57 ~43 stained_hardened_clay 12  
fill ~16 ~1 ~47 ~16 ~57 ~47 stained_hardened_clay 12  
fill ~16 ~1 ~48 ~20 ~1 ~48 double_stone_slab 0  
fill ~16 ~1 ~50 ~20 ~1 ~50 double_stone_slab 0  
fill ~16 ~1 ~51 ~16 ~57 ~51 stained_hardened_clay 12  
fill ~16 ~1 ~55 ~16 ~57 ~55 stained_hardened_clay 12  
fill ~17 ~1 ~44 ~17 ~57 ~44 stained_hardened_clay 12  
fill ~17 ~1 ~45 ~17 ~57 ~45 stained_hardened_clay 12  
fill ~17 ~1 ~46 ~17 ~57 ~46 stained_hardened_clay 12 
setblock ~17 ~1 ~47 double_stone_slab 0 
setblock ~17 ~1 ~49 double_stone_slab 0 
setblock ~17 ~1 ~51 double_stone_slab 0  
fill ~17 ~1 ~52 ~17 ~57 ~52 stained_hardened_clay 12  
fill ~17 ~1 ~53 ~17 ~57 ~53 stained_hardened_clay 12  
fill ~17 ~1 ~54 ~17 ~57 ~54 stained_hardened_clay 12 
setblock ~18 ~1 ~49 glowstone 0  
fill ~19 ~1 ~44 ~19 ~57 ~44 stained_hardened_clay 12  
fill ~19 ~1 ~45 ~19 ~57 ~45 stained_hardened_clay 12  
fill ~19 ~1 ~46 ~19 ~57 ~46 stained_hardened_clay 12 
setblock ~19 ~1 ~47 double_stone_slab 0 
setblock ~19 ~1 ~49 double_stone_slab 0 
setblock ~19 ~1 ~51 double_stone_slab 0  
fill ~19 ~1 ~52 ~19 ~57 ~52 stained_hardened_clay 12  
fill ~19 ~1 ~53 ~19 ~57 ~53 stained_hardened_clay 12  
fill ~19 ~1 ~54 ~19 ~57 ~54 stained_hardened_clay 12  
fill ~20 ~1 ~43 ~20 ~57 ~43 stained_hardened_clay 12  
fill ~20 ~1 ~47 ~20 ~57 ~47 stained_hardened_clay 12  
fill ~20 ~1 ~51 ~20 ~57 ~51 stained_hardened_clay 12  
fill ~20 ~1 ~55 ~20 ~57 ~55 stained_hardened_clay 12  
fill ~21 ~1 ~42 ~23 ~1 ~42 stained_hardened_clay 12  
fill ~21 ~1 ~48 ~23 ~1 ~48 stained_hardened_clay 12  
fill ~21 ~1 ~50 ~23 ~1 ~50 stained_hardened_clay 12  
fill ~21 ~1 ~56 ~23 ~1 ~56 stained_hardened_clay 12  
fill ~24 ~1 ~43 ~24 ~29 ~43 stained_hardened_clay 12  
fill ~24 ~1 ~47 ~24 ~57 ~47 stained_hardened_clay 12  
fill ~24 ~1 ~51 ~24 ~57 ~51 stained_hardened_clay 12  
fill ~24 ~1 ~55 ~24 ~29 ~55 stained_hardened_clay 12  
fill ~25 ~1 ~44 ~25 ~29 ~44 stained_hardened_clay 12  
fill ~25 ~1 ~45 ~25 ~27 ~45 stained_hardened_clay 12  
fill ~25 ~1 ~46 ~25 ~57 ~46 stained_hardened_clay 12  
fill ~25 ~1 ~52 ~25 ~57 ~52 stained_hardened_clay 12  
fill ~25 ~1 ~53 ~25 ~27 ~53 stained_hardened_clay 12  
fill ~25 ~1 ~54 ~25 ~29 ~54 stained_hardened_clay 12  
fill ~13 ~2 ~42 ~15 ~2 ~42 stained_hardened_clay 12  
fill ~13 ~2 ~48 ~15 ~2 ~48 stained_hardened_clay 12  
fill ~13 ~2 ~50 ~15 ~2 ~50 stained_hardened_clay 12  
fill ~13 ~2 ~56 ~15 ~2 ~56 stained_hardened_clay 12  
fill ~21 ~2 ~42 ~23 ~2 ~42 stained_hardened_clay 12  
fill ~21 ~2 ~48 ~23 ~2 ~48 stained_hardened_clay 12  
fill ~21 ~2 ~50 ~23 ~2 ~50 stained_hardened_clay 12  
fill ~21 ~2 ~56 ~23 ~2 ~56 stained_hardened_clay 12  
fill ~13 ~3 ~42 ~15 ~3 ~42 stained_hardened_clay 12  
fill ~13 ~3 ~48 ~15 ~3 ~48 stained_hardened_clay 12  
fill ~13 ~3 ~50 ~15 ~3 ~50 stained_hardened_clay 12  
fill ~13 ~3 ~56 ~15 ~3 ~56 stained_hardened_clay 12  
fill ~21 ~3 ~42 ~23 ~3 ~42 stained_hardened_clay 12  
fill ~21 ~3 ~48 ~23 ~3 ~48 stained_hardened_clay 12  
fill ~21 ~3 ~50 ~23 ~3 ~50 stained_hardened_clay 12  
fill ~21 ~3 ~56 ~23 ~3 ~56 stained_hardened_clay 12  
fill ~13 ~4 ~42 ~15 ~4 ~42 stained_hardened_clay 12  
fill ~13 ~4 ~48 ~15 ~4 ~48 stained_hardened_clay 12  
fill ~13 ~4 ~50 ~15 ~4 ~50 stained_hardened_clay 12  
fill ~13 ~4 ~56 ~15 ~4 ~56 stained_hardened_clay 12  
fill ~21 ~4 ~42 ~23 ~4 ~42 stained_hardened_clay 12  
fill ~21 ~4 ~48 ~23 ~4 ~48 stained_hardened_clay 12  
fill ~21 ~4 ~50 ~23 ~4 ~50 stained_hardened_clay 12  
fill ~21 ~4 ~56 ~23 ~4 ~56 stained_hardened_clay 12 
setblock ~35 ~4 ~49 stone 0  
fill ~13 ~5 ~42 ~15 ~5 ~42 stained_hardened_clay 12  
fill ~13 ~5 ~48 ~15 ~5 ~48 stained_hardened_clay 12  
fill ~13 ~5 ~50 ~15 ~5 ~50 stained_hardened_clay 12  
fill ~13 ~5 ~56 ~15 ~5 ~56 stained_hardened_clay 12  
fill ~21 ~5 ~42 ~23 ~5 ~42 stained_hardened_clay 12  
fill ~21 ~5 ~48 ~23 ~5 ~48 stained_hardened_clay 12  
fill ~21 ~5 ~50 ~23 ~5 ~50 stained_hardened_clay 12  
fill ~21 ~5 ~56 ~23 ~5 ~56 stained_hardened_clay 12  
fill ~13 ~6 ~42 ~15 ~6 ~42 stained_hardened_clay 12  
fill ~13 ~6 ~48 ~15 ~6 ~48 stained_hardened_clay 12  
fill ~13 ~6 ~50 ~15 ~6 ~50 stained_hardened_clay 12  
fill ~13 ~6 ~56 ~15 ~6 ~56 stained_hardened_clay 12  
fill ~21 ~6 ~42 ~23 ~6 ~42 stained_hardened_clay 12  
fill ~21 ~6 ~48 ~23 ~6 ~48 stained_hardened_clay 12  
fill ~21 ~6 ~50 ~23 ~6 ~50 stained_hardened_clay 12  
fill ~21 ~6 ~56 ~23 ~6 ~56 stained_hardened_clay 12  
fill ~13 ~7 ~42 ~15 ~7 ~42 stained_hardened_clay 12  
fill ~13 ~7 ~48 ~15 ~7 ~48 stained_hardened_clay 12  
fill ~13 ~7 ~50 ~15 ~7 ~50 stained_hardened_clay 12  
fill ~13 ~7 ~56 ~15 ~7 ~56 stained_hardened_clay 12  
fill ~21 ~7 ~42 ~23 ~7 ~42 stained_hardened_clay 12  
fill ~21 ~7 ~48 ~23 ~7 ~48 stained_hardened_clay 12  
fill ~21 ~7 ~50 ~23 ~7 ~50 stained_hardened_clay 12  
fill ~21 ~7 ~56 ~23 ~7 ~56 stained_hardened_clay 12  
fill ~13 ~8 ~42 ~15 ~8 ~42 stained_hardened_clay 12  
fill ~13 ~8 ~48 ~15 ~8 ~48 stained_hardened_clay 12  
fill ~13 ~8 ~50 ~15 ~8 ~50 stained_hardened_clay 12  
fill ~13 ~8 ~56 ~15 ~8 ~56 stained_hardened_clay 12  
fill ~16 ~8 ~48 ~20 ~8 ~48 double_stone_slab 0  
fill ~16 ~8 ~50 ~20 ~8 ~50 double_stone_slab 0 
setblock ~17 ~8 ~47 double_stone_slab 0 
setblock ~17 ~8 ~49 double_stone_slab 0 
setblock ~17 ~8 ~51 double_stone_slab 0 
setblock ~18 ~8 ~49 glowstone 0 
setblock ~19 ~8 ~47 double_stone_slab 0 
setblock ~19 ~8 ~49 double_stone_slab 0 
setblock ~19 ~8 ~51 double_stone_slab 0  
fill ~21 ~8 ~42 ~23 ~8 ~42 stained_hardened_clay 12  
fill ~21 ~8 ~48 ~23 ~8 ~48 stained_hardened_clay 12  
fill ~21 ~8 ~50 ~23 ~8 ~50 stained_hardened_clay 12  
fill ~21 ~8 ~56 ~23 ~8 ~56 stained_hardened_clay 12  
fill ~13 ~9 ~42 ~15 ~9 ~42 stained_hardened_clay 12  
fill ~13 ~9 ~48 ~15 ~9 ~48 stained_hardened_clay 12  
fill ~13 ~9 ~50 ~15 ~9 ~50 stained_hardened_clay 12  
fill ~13 ~9 ~56 ~15 ~9 ~56 stained_hardened_clay 12  
fill ~21 ~9 ~42 ~23 ~9 ~42 stained_hardened_clay 12  
fill ~21 ~9 ~48 ~23 ~9 ~48 stained_hardened_clay 12  
fill ~21 ~9 ~50 ~23 ~9 ~50 stained_hardened_clay 12  
fill ~21 ~9 ~56 ~23 ~9 ~56 stained_hardened_clay 12  
fill ~13 ~10 ~42 ~15 ~10 ~42 stained_hardened_clay 12  
fill ~13 ~10 ~48 ~15 ~10 ~48 stained_hardened_clay 12  
fill ~13 ~10 ~50 ~15 ~10 ~50 stained_hardened_clay 12  
fill ~13 ~10 ~56 ~15 ~10 ~56 stained_hardened_clay 12  
fill ~21 ~10 ~42 ~23 ~10 ~42 stained_hardened_clay 12  
fill ~21 ~10 ~48 ~23 ~10 ~48 stained_hardened_clay 12  
fill ~21 ~10 ~50 ~23 ~10 ~50 stained_hardened_clay 12  
fill ~21 ~10 ~56 ~23 ~10 ~56 stained_hardened_clay 12  
fill ~13 ~11 ~42 ~15 ~11 ~42 stained_hardened_clay 12  
fill ~13 ~11 ~48 ~15 ~11 ~48 stained_hardened_clay 12  
fill ~13 ~11 ~50 ~15 ~11 ~50 stained_hardened_clay 12  
fill ~13 ~11 ~56 ~15 ~11 ~56 stained_hardened_clay 12  
fill ~21 ~11 ~42 ~23 ~11 ~42 stained_hardened_clay 12  
fill ~21 ~11 ~48 ~23 ~11 ~48 stained_hardened_clay 12  
fill ~21 ~11 ~50 ~23 ~11 ~50 stained_hardened_clay 12  
fill ~21 ~11 ~56 ~23 ~11 ~56 stained_hardened_clay 12  
fill ~13 ~12 ~42 ~15 ~12 ~42 stained_hardened_clay 12  
fill ~13 ~12 ~48 ~15 ~12 ~48 stained_hardened_clay 12  
fill ~13 ~12 ~50 ~15 ~12 ~50 stained_hardened_clay 12  
fill ~13 ~12 ~56 ~15 ~12 ~56 stained_hardened_clay 12  
fill ~21 ~12 ~42 ~23 ~12 ~42 stained_hardened_clay 12  
fill ~21 ~12 ~48 ~23 ~12 ~48 stained_hardened_clay 12  
fill ~21 ~12 ~50 ~23 ~12 ~50 stained_hardened_clay 12  
fill ~21 ~12 ~56 ~23 ~12 ~56 stained_hardened_clay 12  
fill ~13 ~13 ~42 ~15 ~13 ~42 stained_hardened_clay 12  
fill ~13 ~13 ~48 ~15 ~13 ~48 stained_hardened_clay 12  
fill ~13 ~13 ~50 ~15 ~13 ~50 stained_hardened_clay 12  
fill ~13 ~13 ~56 ~15 ~13 ~56 stained_hardened_clay 12  
fill ~21 ~13 ~42 ~23 ~13 ~42 stained_hardened_clay 12  
fill ~21 ~13 ~48 ~23 ~13 ~48 stained_hardened_clay 12  
fill ~21 ~13 ~50 ~23 ~13 ~50 stained_hardened_clay 12  
fill ~21 ~13 ~56 ~23 ~13 ~56 stained_hardened_clay 12  
fill ~13 ~14 ~42 ~15 ~14 ~42 stained_hardened_clay 12  
fill ~13 ~14 ~48 ~15 ~14 ~48 stained_hardened_clay 12  
fill ~13 ~14 ~50 ~15 ~14 ~50 stained_hardened_clay 12  
fill ~13 ~14 ~56 ~15 ~14 ~56 stained_hardened_clay 12  
fill ~21 ~14 ~42 ~23 ~14 ~42 stained_hardened_clay 12  
fill ~21 ~14 ~48 ~23 ~14 ~48 stained_hardened_clay 12  
fill ~21 ~14 ~50 ~23 ~14 ~50 stained_hardened_clay 12  
fill ~21 ~14 ~56 ~23 ~14 ~56 stained_hardened_clay 12  
fill ~13 ~15 ~42 ~15 ~15 ~42 stained_hardened_clay 12  
fill ~13 ~15 ~48 ~15 ~15 ~48 stained_hardened_clay 12  
fill ~13 ~15 ~50 ~15 ~15 ~50 stained_hardened_clay 12  
fill ~13 ~15 ~56 ~15 ~15 ~56 stained_hardened_clay 12  
fill ~21 ~15 ~42 ~23 ~15 ~42 stained_hardened_clay 12  
fill ~21 ~15 ~48 ~23 ~15 ~48 stained_hardened_clay 12  
fill ~21 ~15 ~50 ~23 ~15 ~50 stained_hardened_clay 12  
fill ~21 ~15 ~56 ~23 ~15 ~56 stained_hardened_clay 12  
fill ~10 ~16 ~44 ~10 ~17 ~44 double_stone_slab 0  
fill ~10 ~16 ~45 ~10 ~17 ~45 double_stone_slab 0  
fill ~10 ~16 ~53 ~10 ~17 ~53 double_stone_slab 0  
fill ~10 ~16 ~54 ~10 ~17 ~54 double_stone_slab 0  
fill ~11 ~16 ~43 ~11 ~17 ~43 double_stone_slab 0  
fill ~11 ~16 ~55 ~11 ~17 ~55 double_stone_slab 0  
fill ~12 ~16 ~42 ~12 ~17 ~42 double_stone_slab 0  
fill ~12 ~16 ~56 ~12 ~17 ~56 double_stone_slab 0  
fill ~13 ~16 ~41 ~14 ~16 ~41 double_stone_slab 0  
fill ~13 ~16 ~42 ~15 ~16 ~42 stained_hardened_clay 12  
fill ~13 ~16 ~48 ~15 ~16 ~48 stained_hardened_clay 12  
fill ~13 ~16 ~50 ~15 ~16 ~50 stained_hardened_clay 12  
fill ~13 ~16 ~56 ~15 ~16 ~56 stained_hardened_clay 12  
fill ~13 ~16 ~57 ~14 ~16 ~57 double_stone_slab 0  
fill ~21 ~16 ~42 ~23 ~16 ~42 stained_hardened_clay 12  
fill ~21 ~16 ~48 ~23 ~16 ~48 stained_hardened_clay 12  
fill ~21 ~16 ~50 ~23 ~16 ~50 stained_hardened_clay 12  
fill ~21 ~16 ~56 ~23 ~16 ~56 stained_hardened_clay 12  
fill ~22 ~16 ~41 ~23 ~16 ~41 double_stone_slab 0  
fill ~22 ~16 ~57 ~23 ~16 ~57 double_stone_slab 0  
fill ~24 ~16 ~42 ~24 ~17 ~42 double_stone_slab 0  
fill ~24 ~16 ~56 ~24 ~17 ~56 double_stone_slab 0  
fill ~25 ~16 ~43 ~25 ~17 ~43 double_stone_slab 0  
fill ~25 ~16 ~55 ~25 ~17 ~55 double_stone_slab 0  
fill ~26 ~16 ~44 ~26 ~17 ~44 double_stone_slab 0  
fill ~26 ~16 ~45 ~26 ~17 ~45 double_stone_slab 0  
fill ~26 ~16 ~53 ~26 ~17 ~53 double_stone_slab 0  
fill ~26 ~16 ~54 ~26 ~17 ~54 double_stone_slab 0  
fill ~13 ~17 ~41 ~14 ~17 ~41 double_stone_slab 0  
fill ~13 ~17 ~42 ~15 ~17 ~42 stained_hardened_clay 12  
fill ~13 ~17 ~48 ~15 ~17 ~48 stained_hardened_clay 12  
fill ~13 ~17 ~50 ~15 ~17 ~50 stained_hardened_clay 12  
fill ~13 ~17 ~56 ~15 ~17 ~56 stained_hardened_clay 12  
fill ~13 ~17 ~57 ~14 ~17 ~57 double_stone_slab 0  
fill ~21 ~17 ~42 ~23 ~17 ~42 stained_hardened_clay 12  
fill ~21 ~17 ~48 ~23 ~17 ~48 stained_hardened_clay 12  
fill ~21 ~17 ~50 ~23 ~17 ~50 stained_hardened_clay 12  
fill ~21 ~17 ~56 ~23 ~17 ~56 stained_hardened_clay 12  
fill ~22 ~17 ~41 ~23 ~17 ~41 double_stone_slab 0  
fill ~22 ~17 ~57 ~23 ~17 ~57 double_stone_slab 0  
fill ~13 ~18 ~42 ~15 ~18 ~42 stained_hardened_clay 12  
fill ~13 ~18 ~48 ~15 ~18 ~48 stained_hardened_clay 12  
fill ~13 ~18 ~50 ~15 ~18 ~50 stained_hardened_clay 12  
fill ~13 ~18 ~56 ~15 ~18 ~56 stained_hardened_clay 12  
fill ~21 ~18 ~42 ~23 ~18 ~42 stained_hardened_clay 12  
fill ~21 ~18 ~48 ~23 ~18 ~48 stained_hardened_clay 12  
fill ~21 ~18 ~50 ~23 ~18 ~50 stained_hardened_clay 12  
fill ~21 ~18 ~56 ~23 ~18 ~56 stained_hardened_clay 12  
fill ~13 ~19 ~42 ~15 ~19 ~42 stained_hardened_clay 12  
fill ~13 ~19 ~48 ~15 ~19 ~48 stained_hardened_clay 12  
fill ~13 ~19 ~50 ~15 ~19 ~50 stained_hardened_clay 12  
fill ~13 ~19 ~56 ~15 ~19 ~56 stained_hardened_clay 12  
fill ~21 ~19 ~42 ~23 ~19 ~42 stained_hardened_clay 12  
fill ~21 ~19 ~48 ~23 ~19 ~48 stained_hardened_clay 12  
fill ~21 ~19 ~50 ~23 ~19 ~50 stained_hardened_clay 12  
fill ~21 ~19 ~56 ~23 ~19 ~56 stained_hardened_clay 12  
fill ~13 ~20 ~42 ~15 ~20 ~42 stained_hardened_clay 12  
fill ~13 ~20 ~48 ~15 ~20 ~48 stained_hardened_clay 12  
fill ~13 ~20 ~50 ~15 ~20 ~50 stained_hardened_clay 12  
fill ~13 ~20 ~56 ~15 ~20 ~56 stained_hardened_clay 12  
fill ~21 ~20 ~42 ~23 ~20 ~42 stained_hardened_clay 12  
fill ~21 ~20 ~48 ~23 ~20 ~48 stained_hardened_clay 12  
fill ~21 ~20 ~50 ~23 ~20 ~50 stained_hardened_clay 12  
fill ~21 ~20 ~56 ~23 ~20 ~56 stained_hardened_clay 12  
fill ~13 ~21 ~42 ~15 ~21 ~42 stained_hardened_clay 12  
fill ~13 ~21 ~48 ~15 ~21 ~48 stained_hardened_clay 12  
fill ~13 ~21 ~50 ~15 ~21 ~50 stained_hardened_clay 12  
fill ~13 ~21 ~56 ~15 ~21 ~56 stained_hardened_clay 12  
fill ~21 ~21 ~42 ~23 ~21 ~42 stained_hardened_clay 12  
fill ~21 ~21 ~48 ~23 ~21 ~48 stained_hardened_clay 12  
fill ~21 ~21 ~50 ~23 ~21 ~50 stained_hardened_clay 12  
fill ~21 ~21 ~56 ~23 ~21 ~56 stained_hardened_clay 12  
fill ~13 ~22 ~42 ~15 ~22 ~42 stained_hardened_clay 12  
fill ~13 ~22 ~48 ~15 ~22 ~48 stained_hardened_clay 12  
fill ~13 ~22 ~50 ~15 ~22 ~50 stained_hardened_clay 12  
fill ~13 ~22 ~56 ~15 ~22 ~56 stained_hardened_clay 12  
fill ~21 ~22 ~42 ~23 ~22 ~42 stained_hardened_clay 12  
fill ~21 ~22 ~48 ~23 ~22 ~48 stained_hardened_clay 12  
fill ~21 ~22 ~50 ~23 ~22 ~50 stained_hardened_clay 12  
fill ~21 ~22 ~56 ~23 ~22 ~56 stained_hardened_clay 12  
fill ~13 ~23 ~42 ~15 ~23 ~42 stained_hardened_clay 12  
fill ~13 ~23 ~48 ~15 ~23 ~48 stained_hardened_clay 12  
fill ~13 ~23 ~50 ~15 ~23 ~50 stained_hardened_clay 12  
fill ~13 ~23 ~56 ~15 ~23 ~56 stained_hardened_clay 12  
fill ~21 ~23 ~42 ~23 ~23 ~42 stained_hardened_clay 12  
fill ~21 ~23 ~48 ~23 ~23 ~48 stained_hardened_clay 12  
fill ~21 ~23 ~50 ~23 ~23 ~50 stained_hardened_clay 12  
fill ~21 ~23 ~56 ~23 ~23 ~56 stained_hardened_clay 12  
fill ~13 ~24 ~42 ~15 ~24 ~42 stained_hardened_clay 12  
fill ~13 ~24 ~48 ~15 ~24 ~48 stained_hardened_clay 12  
fill ~13 ~24 ~50 ~15 ~24 ~50 stained_hardened_clay 12  
fill ~13 ~24 ~56 ~15 ~24 ~56 stained_hardened_clay 12  
fill ~21 ~24 ~42 ~23 ~24 ~42 stained_hardened_clay 12  
fill ~21 ~24 ~48 ~23 ~24 ~48 stained_hardened_clay 12  
fill ~21 ~24 ~50 ~23 ~24 ~50 stained_hardened_clay 12  
fill ~21 ~24 ~56 ~23 ~24 ~56 stained_hardened_clay 12  
fill ~13 ~25 ~42 ~15 ~25 ~42 stained_hardened_clay 12  
fill ~13 ~25 ~48 ~15 ~25 ~48 stained_hardened_clay 12  
fill ~13 ~25 ~50 ~15 ~25 ~50 stained_hardened_clay 12  
fill ~13 ~25 ~56 ~15 ~25 ~56 stained_hardened_clay 12  
fill ~21 ~25 ~42 ~23 ~25 ~42 stained_hardened_clay 12  
fill ~21 ~25 ~48 ~23 ~25 ~48 stained_hardened_clay 12  
fill ~21 ~25 ~50 ~23 ~25 ~50 stained_hardened_clay 12  
fill ~21 ~25 ~56 ~23 ~25 ~56 stained_hardened_clay 12  
fill ~13 ~26 ~42 ~15 ~26 ~42 stained_hardened_clay 12  
fill ~13 ~26 ~48 ~15 ~26 ~48 stained_hardened_clay 12  
fill ~13 ~26 ~50 ~15 ~26 ~50 stained_hardened_clay 12  
fill ~13 ~26 ~56 ~15 ~26 ~56 stained_hardened_clay 12  
fill ~21 ~26 ~42 ~23 ~26 ~42 stained_hardened_clay 12  
fill ~21 ~26 ~48 ~23 ~26 ~48 stained_hardened_clay 12  
fill ~21 ~26 ~50 ~23 ~26 ~50 stained_hardened_clay 12  
fill ~21 ~26 ~56 ~23 ~26 ~56 stained_hardened_clay 12  
fill ~13 ~27 ~42 ~15 ~27 ~42 stained_hardened_clay 12  
fill ~13 ~27 ~48 ~15 ~27 ~48 stained_hardened_clay 12  
fill ~13 ~27 ~50 ~15 ~27 ~50 stained_hardened_clay 12  
fill ~13 ~27 ~56 ~15 ~27 ~56 stained_hardened_clay 12  
fill ~21 ~27 ~42 ~23 ~27 ~42 stained_hardened_clay 12  
fill ~21 ~27 ~48 ~23 ~27 ~48 stained_hardened_clay 12  
fill ~21 ~27 ~50 ~23 ~27 ~50 stained_hardened_clay 12  
fill ~21 ~27 ~56 ~23 ~27 ~56 stained_hardened_clay 12 
setblock ~11 ~28 ~45 glowstone 0 
setblock ~11 ~28 ~53 glowstone 0  
fill ~13 ~28 ~42 ~13 ~29 ~42 stained_hardened_clay 12  
fill ~13 ~28 ~48 ~15 ~28 ~48 stained_hardened_clay 12  
fill ~13 ~28 ~50 ~15 ~28 ~50 stained_hardened_clay 12  
fill ~13 ~28 ~56 ~13 ~29 ~56 stained_hardened_clay 12 
setblock ~14 ~28 ~42 glowstone 0 
setblock ~14 ~28 ~56 glowstone 0  
fill ~15 ~28 ~42 ~15 ~57 ~42 stained_hardened_clay 12  
fill ~15 ~28 ~56 ~15 ~57 ~56 stained_hardened_clay 12  
fill ~21 ~28 ~42 ~21 ~57 ~42 stained_hardened_clay 12  
fill ~21 ~28 ~48 ~23 ~28 ~48 stained_hardened_clay 12  
fill ~21 ~28 ~50 ~23 ~28 ~50 stained_hardened_clay 12  
fill ~21 ~28 ~56 ~21 ~57 ~56 stained_hardened_clay 12 
setblock ~22 ~28 ~42 glowstone 0 
setblock ~22 ~28 ~56 glowstone 0  
fill ~23 ~28 ~42 ~23 ~29 ~42 stained_hardened_clay 12  
fill ~23 ~28 ~56 ~23 ~29 ~56 stained_hardened_clay 12 
setblock ~25 ~28 ~45 glowstone 0 
setblock ~25 ~28 ~53 glowstone 0 
setblock ~11 ~29 ~45 stained_hardened_clay 12 
setblock ~11 ~29 ~53 stained_hardened_clay 12  
fill ~13 ~29 ~48 ~15 ~29 ~48 stained_hardened_clay 12  
fill ~13 ~29 ~50 ~15 ~29 ~50 stained_hardened_clay 12 
setblock ~14 ~29 ~42 stained_hardened_clay 12 
setblock ~14 ~29 ~56 stained_hardened_clay 12  
fill ~21 ~29 ~48 ~23 ~29 ~48 stained_hardened_clay 12  
fill ~21 ~29 ~50 ~23 ~29 ~50 stained_hardened_clay 12 
setblock ~22 ~29 ~42 stained_hardened_clay 12 
setblock ~22 ~29 ~56 stained_hardened_clay 12 
setblock ~25 ~29 ~45 stained_hardened_clay 12 
setblock ~25 ~29 ~53 stained_hardened_clay 12  
fill ~12 ~30 ~44 ~12 ~32 ~44 wool 15  
fill ~12 ~30 ~45 ~12 ~32 ~45 wool 15  
fill ~12 ~30 ~53 ~12 ~32 ~53 wool 15  
fill ~12 ~30 ~54 ~12 ~32 ~54 wool 15  
fill ~13 ~30 ~43 ~14 ~30 ~43 wool 15  
fill ~13 ~30 ~48 ~15 ~30 ~48 stained_hardened_clay 12  
fill ~13 ~30 ~50 ~15 ~30 ~50 stained_hardened_clay 12  
fill ~13 ~30 ~55 ~14 ~30 ~55 wool 15  
fill ~21 ~30 ~48 ~23 ~30 ~48 stained_hardened_clay 12  
fill ~21 ~30 ~50 ~23 ~30 ~50 stained_hardened_clay 12  
fill ~22 ~30 ~43 ~23 ~30 ~43 wool 15  
fill ~22 ~30 ~55 ~23 ~30 ~55 wool 15  
fill ~24 ~30 ~44 ~24 ~32 ~44 wool 15  
fill ~24 ~30 ~45 ~24 ~32 ~45 wool 15  
fill ~24 ~30 ~53 ~24 ~32 ~53 wool 15  
fill ~24 ~30 ~54 ~24 ~32 ~54 wool 15  
fill ~13 ~31 ~43 ~14 ~31 ~43 wool 15  
fill ~13 ~31 ~48 ~15 ~31 ~48 stained_hardened_clay 12  
fill ~13 ~31 ~50 ~15 ~31 ~50 stained_hardened_clay 12  
fill ~13 ~31 ~55 ~14 ~31 ~55 wool 15  
fill ~21 ~31 ~48 ~23 ~31 ~48 stained_hardened_clay 12  
fill ~21 ~31 ~50 ~23 ~31 ~50 stained_hardened_clay 12  
fill ~22 ~31 ~43 ~23 ~31 ~43 wool 15  
fill ~22 ~31 ~55 ~23 ~31 ~55 wool 15  
fill ~13 ~32 ~43 ~14 ~32 ~43 wool 15  
fill ~13 ~32 ~48 ~15 ~32 ~48 stained_hardened_clay 12  
fill ~13 ~32 ~50 ~15 ~32 ~50 stained_hardened_clay 12  
fill ~13 ~32 ~55 ~14 ~32 ~55 wool 15  
fill ~21 ~32 ~48 ~23 ~32 ~48 stained_hardened_clay 12  
fill ~21 ~32 ~50 ~23 ~32 ~50 stained_hardened_clay 12  
fill ~22 ~32 ~43 ~23 ~32 ~43 wool 15  
fill ~22 ~32 ~55 ~23 ~32 ~55 wool 15  
fill ~11 ~33 ~44 ~11 ~57 ~44 stained_hardened_clay 12  
fill ~11 ~33 ~45 ~11 ~49 ~45 stained_hardened_clay 12  
fill ~11 ~33 ~53 ~11 ~49 ~53 stained_hardened_clay 12  
fill ~11 ~33 ~54 ~11 ~57 ~54 stained_hardened_clay 12  
fill ~12 ~33 ~43 ~12 ~57 ~43 stained_hardened_clay 12  
fill ~12 ~33 ~55 ~12 ~57 ~55 stained_hardened_clay 12  
fill ~13 ~33 ~42 ~15 ~33 ~42 stained_hardened_clay 12  
fill ~13 ~33 ~48 ~15 ~33 ~48 stained_hardened_clay 12  
fill ~13 ~33 ~50 ~15 ~33 ~50 stained_hardened_clay 12  
fill ~13 ~33 ~56 ~15 ~33 ~56 stained_hardened_clay 12  
fill ~21 ~33 ~48 ~23 ~33 ~48 stained_hardened_clay 12  
fill ~21 ~33 ~50 ~23 ~33 ~50 stained_hardened_clay 12  
fill ~22 ~33 ~42 ~23 ~33 ~42 stained_hardened_clay 12  
fill ~22 ~33 ~56 ~23 ~33 ~56 stained_hardened_clay 12  
fill ~24 ~33 ~43 ~24 ~57 ~43 stained_hardened_clay 12  
fill ~24 ~33 ~55 ~24 ~57 ~55 stained_hardened_clay 12  
fill ~25 ~33 ~44 ~25 ~57 ~44 stained_hardened_clay 12  
fill ~25 ~33 ~45 ~25 ~49 ~45 stained_hardened_clay 12  
fill ~25 ~33 ~53 ~25 ~49 ~53 stained_hardened_clay 12  
fill ~25 ~33 ~54 ~25 ~57 ~54 stained_hardened_clay 12  
fill ~13 ~34 ~42 ~15 ~34 ~42 stained_hardened_clay 12  
fill ~13 ~34 ~48 ~15 ~34 ~48 stained_hardened_clay 12  
fill ~13 ~34 ~50 ~15 ~34 ~50 stained_hardened_clay 12  
fill ~13 ~34 ~56 ~15 ~34 ~56 stained_hardened_clay 12  
fill ~21 ~34 ~48 ~23 ~34 ~48 stained_hardened_clay 12  
fill ~21 ~34 ~50 ~23 ~34 ~50 stained_hardened_clay 12  
fill ~22 ~34 ~42 ~23 ~34 ~42 stained_hardened_clay 12  
fill ~22 ~34 ~56 ~23 ~34 ~56 stained_hardened_clay 12  
fill ~13 ~35 ~42 ~15 ~35 ~42 stained_hardened_clay 12  
fill ~13 ~35 ~48 ~15 ~35 ~48 stained_hardened_clay 12  
fill ~13 ~35 ~50 ~15 ~35 ~50 stained_hardened_clay 12  
fill ~13 ~35 ~56 ~15 ~35 ~56 stained_hardened_clay 12  
fill ~21 ~35 ~48 ~23 ~35 ~48 stained_hardened_clay 12  
fill ~21 ~35 ~50 ~23 ~35 ~50 stained_hardened_clay 12  
fill ~22 ~35 ~42 ~23 ~35 ~42 stained_hardened_clay 12  
fill ~22 ~35 ~56 ~23 ~35 ~56 stained_hardened_clay 12  
fill ~13 ~36 ~42 ~15 ~36 ~42 stained_hardened_clay 12  
fill ~13 ~36 ~48 ~15 ~36 ~48 stained_hardened_clay 12  
fill ~13 ~36 ~50 ~15 ~36 ~50 stained_hardened_clay 12  
fill ~13 ~36 ~56 ~15 ~36 ~56 stained_hardened_clay 12  
fill ~21 ~36 ~48 ~23 ~36 ~48 stained_hardened_clay 12  
fill ~21 ~36 ~50 ~23 ~36 ~50 stained_hardened_clay 12  
fill ~22 ~36 ~42 ~23 ~36 ~42 stained_hardened_clay 12  
fill ~22 ~36 ~56 ~23 ~36 ~56 stained_hardened_clay 12  
fill ~13 ~37 ~42 ~15 ~37 ~42 stained_hardened_clay 12  
fill ~13 ~37 ~48 ~15 ~37 ~48 stained_hardened_clay 12  
fill ~13 ~37 ~50 ~15 ~37 ~50 stained_hardened_clay 12  
fill ~13 ~37 ~56 ~15 ~37 ~56 stained_hardened_clay 12  
fill ~21 ~37 ~48 ~23 ~37 ~48 stained_hardened_clay 12  
fill ~21 ~37 ~50 ~23 ~37 ~50 stained_hardened_clay 12  
fill ~22 ~37 ~42 ~23 ~37 ~42 stained_hardened_clay 12  
fill ~22 ~37 ~56 ~23 ~37 ~56 stained_hardened_clay 12  
fill ~13 ~38 ~42 ~15 ~38 ~42 stained_hardened_clay 12  
fill ~13 ~38 ~48 ~15 ~38 ~48 stained_hardened_clay 12  
fill ~13 ~38 ~50 ~15 ~38 ~50 stained_hardened_clay 12  
fill ~13 ~38 ~56 ~15 ~38 ~56 stained_hardened_clay 12  
fill ~21 ~38 ~48 ~23 ~38 ~48 stained_hardened_clay 12  
fill ~21 ~38 ~50 ~23 ~38 ~50 stained_hardened_clay 12  
fill ~22 ~38 ~42 ~23 ~38 ~42 stained_hardened_clay 12  
fill ~22 ~38 ~56 ~23 ~38 ~56 stained_hardened_clay 12  
fill ~13 ~39 ~42 ~15 ~39 ~42 stained_hardened_clay 12  
fill ~13 ~39 ~48 ~15 ~39 ~48 stained_hardened_clay 12  
fill ~13 ~39 ~50 ~15 ~39 ~50 stained_hardened_clay 12  
fill ~13 ~39 ~56 ~15 ~39 ~56 stained_hardened_clay 12  
fill ~21 ~39 ~48 ~23 ~39 ~48 stained_hardened_clay 12  
fill ~21 ~39 ~50 ~23 ~39 ~50 stained_hardened_clay 12  
fill ~22 ~39 ~42 ~23 ~39 ~42 stained_hardened_clay 12  
fill ~22 ~39 ~56 ~23 ~39 ~56 stained_hardened_clay 12  
fill ~13 ~40 ~42 ~15 ~40 ~42 stained_hardened_clay 12  
fill ~13 ~40 ~48 ~15 ~40 ~48 stained_hardened_clay 12  
fill ~13 ~40 ~50 ~15 ~40 ~50 stained_hardened_clay 12  
fill ~13 ~40 ~56 ~15 ~40 ~56 stained_hardened_clay 12  
fill ~21 ~40 ~48 ~23 ~40 ~48 stained_hardened_clay 12  
fill ~21 ~40 ~50 ~23 ~40 ~50 stained_hardened_clay 12  
fill ~22 ~40 ~42 ~23 ~40 ~42 stained_hardened_clay 12  
fill ~22 ~40 ~56 ~23 ~40 ~56 stained_hardened_clay 12  
fill ~13 ~41 ~42 ~15 ~41 ~42 stained_hardened_clay 12  
fill ~13 ~41 ~48 ~15 ~41 ~48 stained_hardened_clay 12  
fill ~13 ~41 ~50 ~15 ~41 ~50 stained_hardened_clay 12  
fill ~13 ~41 ~56 ~15 ~41 ~56 stained_hardened_clay 12  
fill ~21 ~41 ~48 ~23 ~41 ~48 stained_hardened_clay 12  
fill ~21 ~41 ~50 ~23 ~41 ~50 stained_hardened_clay 12  
fill ~22 ~41 ~42 ~23 ~41 ~42 stained_hardened_clay 12  
fill ~22 ~41 ~56 ~23 ~41 ~56 stained_hardened_clay 12  
fill ~13 ~42 ~42 ~15 ~42 ~42 stained_hardened_clay 12  
fill ~13 ~42 ~48 ~15 ~42 ~48 stained_hardened_clay 12  
fill ~13 ~42 ~50 ~15 ~42 ~50 stained_hardened_clay 12  
fill ~13 ~42 ~56 ~15 ~42 ~56 stained_hardened_clay 12  
fill ~21 ~42 ~48 ~23 ~42 ~48 stained_hardened_clay 12  
fill ~21 ~42 ~50 ~23 ~42 ~50 stained_hardened_clay 12  
fill ~22 ~42 ~42 ~23 ~42 ~42 stained_hardened_clay 12  
fill ~22 ~42 ~56 ~23 ~42 ~56 stained_hardened_clay 12  
fill ~13 ~43 ~42 ~15 ~43 ~42 stained_hardened_clay 12  
fill ~13 ~43 ~48 ~15 ~43 ~48 stained_hardened_clay 12  
fill ~13 ~43 ~50 ~15 ~43 ~50 stained_hardened_clay 12  
fill ~13 ~43 ~56 ~15 ~43 ~56 stained_hardened_clay 12  
fill ~21 ~43 ~48 ~23 ~43 ~48 stained_hardened_clay 12  
fill ~21 ~43 ~50 ~23 ~43 ~50 stained_hardened_clay 12  
fill ~22 ~43 ~42 ~23 ~43 ~42 stained_hardened_clay 12  
fill ~22 ~43 ~56 ~23 ~43 ~56 stained_hardened_clay 12  
fill ~13 ~44 ~42 ~15 ~44 ~42 stained_hardened_clay 12  
fill ~13 ~44 ~48 ~15 ~44 ~48 stained_hardened_clay 12  
fill ~13 ~44 ~50 ~15 ~44 ~50 stained_hardened_clay 12  
fill ~13 ~44 ~56 ~15 ~44 ~56 stained_hardened_clay 12  
fill ~21 ~44 ~48 ~23 ~44 ~48 stained_hardened_clay 12  
fill ~21 ~44 ~50 ~23 ~44 ~50 stained_hardened_clay 12  
fill ~22 ~44 ~42 ~23 ~44 ~42 stained_hardened_clay 12  
fill ~22 ~44 ~56 ~23 ~44 ~56 stained_hardened_clay 12  
fill ~13 ~45 ~42 ~15 ~45 ~42 stained_hardened_clay 12  
fill ~13 ~45 ~48 ~15 ~45 ~48 stained_hardened_clay 12  
fill ~13 ~45 ~50 ~15 ~45 ~50 stained_hardened_clay 12  
fill ~13 ~45 ~56 ~15 ~45 ~56 stained_hardened_clay 12  
fill ~21 ~45 ~48 ~23 ~45 ~48 stained_hardened_clay 12  
fill ~21 ~45 ~50 ~23 ~45 ~50 stained_hardened_clay 12  
fill ~22 ~45 ~42 ~23 ~45 ~42 stained_hardened_clay 12  
fill ~22 ~45 ~56 ~23 ~45 ~56 stained_hardened_clay 12  
fill ~13 ~46 ~42 ~15 ~46 ~42 stained_hardened_clay 12  
fill ~13 ~46 ~48 ~15 ~46 ~48 stained_hardened_clay 12  
fill ~13 ~46 ~50 ~15 ~46 ~50 stained_hardened_clay 12  
fill ~13 ~46 ~56 ~15 ~46 ~56 stained_hardened_clay 12  
fill ~21 ~46 ~48 ~23 ~46 ~48 stained_hardened_clay 12  
fill ~21 ~46 ~50 ~23 ~46 ~50 stained_hardened_clay 12  
fill ~22 ~46 ~42 ~23 ~46 ~42 stained_hardened_clay 12  
fill ~22 ~46 ~56 ~23 ~46 ~56 stained_hardened_clay 12  
fill ~13 ~47 ~42 ~15 ~47 ~42 stained_hardened_clay 12  
fill ~13 ~47 ~48 ~15 ~47 ~48 stained_hardened_clay 12  
fill ~13 ~47 ~50 ~15 ~47 ~50 stained_hardened_clay 12  
fill ~13 ~47 ~56 ~15 ~47 ~56 stained_hardened_clay 12  
fill ~21 ~47 ~48 ~23 ~47 ~48 stained_hardened_clay 12  
fill ~21 ~47 ~50 ~23 ~47 ~50 stained_hardened_clay 12  
fill ~22 ~47 ~42 ~23 ~47 ~42 stained_hardened_clay 12  
fill ~22 ~47 ~56 ~23 ~47 ~56 stained_hardened_clay 12  
fill ~13 ~48 ~42 ~15 ~48 ~42 stained_hardened_clay 12  
fill ~13 ~48 ~48 ~15 ~48 ~48 stained_hardened_clay 12  
fill ~13 ~48 ~50 ~15 ~48 ~50 stained_hardened_clay 12  
fill ~13 ~48 ~56 ~15 ~48 ~56 stained_hardened_clay 12  
fill ~21 ~48 ~48 ~23 ~48 ~48 stained_hardened_clay 12  
fill ~21 ~48 ~50 ~23 ~48 ~50 stained_hardened_clay 12  
fill ~22 ~48 ~42 ~23 ~48 ~42 stained_hardened_clay 12  
fill ~22 ~48 ~56 ~23 ~48 ~56 stained_hardened_clay 12  
fill ~11 ~49 ~48 ~11 ~51 ~48 double_stone_slab 0  
fill ~11 ~49 ~49 ~11 ~50 ~49 double_stone_slab 0  
fill ~11 ~49 ~50 ~11 ~51 ~50 double_stone_slab 0  
fill ~13 ~49 ~42 ~15 ~49 ~42 stained_hardened_clay 12  
fill ~13 ~49 ~48 ~15 ~49 ~48 stained_hardened_clay 12  
fill ~13 ~49 ~50 ~15 ~49 ~50 stained_hardened_clay 12  
fill ~13 ~49 ~56 ~15 ~49 ~56 stained_hardened_clay 12  
fill ~17 ~49 ~42 ~19 ~49 ~42 double_stone_slab 0  
fill ~17 ~49 ~56 ~19 ~49 ~56 double_stone_slab 0  
fill ~21 ~49 ~48 ~23 ~49 ~48 stained_hardened_clay 12  
fill ~21 ~49 ~50 ~23 ~49 ~50 stained_hardened_clay 12  
fill ~22 ~49 ~42 ~23 ~49 ~42 stained_hardened_clay 12  
fill ~22 ~49 ~56 ~23 ~49 ~56 stained_hardened_clay 12  
fill ~25 ~49 ~48 ~25 ~51 ~48 double_stone_slab 0  
fill ~25 ~49 ~49 ~25 ~50 ~49 double_stone_slab 0  
fill ~25 ~49 ~50 ~25 ~51 ~50 double_stone_slab 0  
fill ~-5 ~50 ~42 ~-3 ~50 ~42 double_stone_slab 0  
fill ~-5 ~50 ~43 ~-3 ~50 ~43 double_stone_slab 0  
fill ~-5 ~50 ~44 ~-3 ~50 ~44 double_stone_slab 0  
fill ~-5 ~50 ~45 ~-4 ~50 ~45 double_stone_slab 0  
fill ~-5 ~50 ~46 ~-4 ~50 ~46 double_stone_slab 0  
fill ~-5 ~50 ~47 ~-4 ~50 ~47 double_stone_slab 0  
fill ~-5 ~50 ~48 ~-4 ~50 ~48 double_stone_slab 0  
fill ~-5 ~50 ~49 ~-4 ~50 ~49 double_stone_slab 0  
fill ~-5 ~50 ~50 ~-4 ~50 ~50 double_stone_slab 0  
fill ~-5 ~50 ~51 ~-4 ~50 ~51 double_stone_slab 0  
fill ~-5 ~50 ~52 ~-4 ~50 ~52 double_stone_slab 0  
fill ~-5 ~50 ~53 ~-4 ~50 ~53 double_stone_slab 0  
fill ~-5 ~50 ~54 ~-3 ~50 ~54 double_stone_slab 0  
fill ~-5 ~50 ~55 ~-3 ~50 ~55 double_stone_slab 0  
fill ~-5 ~50 ~56 ~-3 ~50 ~56 double_stone_slab 0  
fill ~-4 ~50 ~40 ~-2 ~50 ~40 double_stone_slab 0  
fill ~-4 ~50 ~41 ~-2 ~50 ~41 double_stone_slab 0  
fill ~-4 ~50 ~57 ~-2 ~50 ~57 double_stone_slab 0  
fill ~-4 ~50 ~58 ~-2 ~50 ~58 double_stone_slab 0  
fill ~-3 ~50 ~37 ~0 ~50 ~37 double_stone_slab 0  
fill ~-3 ~50 ~38 ~-1 ~50 ~38 double_stone_slab 0  
fill ~-3 ~50 ~39 ~-2 ~50 ~39 double_stone_slab 0  
fill ~-3 ~50 ~59 ~-2 ~50 ~59 double_stone_slab 0  
fill ~-3 ~50 ~60 ~-1 ~50 ~60 double_stone_slab 0  
fill ~-3 ~50 ~61 ~0 ~50 ~61 double_stone_slab 0  
fill ~-2 ~50 ~36 ~0 ~50 ~36 double_stone_slab 0  
fill ~-2 ~50 ~62 ~0 ~50 ~62 double_stone_slab 0  
fill ~-1 ~50 ~34 ~2 ~50 ~34 double_stone_slab 0  
fill ~-1 ~50 ~35 ~1 ~50 ~35 double_stone_slab 0  
fill ~-1 ~50 ~63 ~1 ~50 ~63 double_stone_slab 0  
fill ~-1 ~50 ~64 ~2 ~50 ~64 double_stone_slab 0  
fill ~0 ~50 ~33 ~3 ~50 ~33 double_stone_slab 0  
fill ~0 ~50 ~65 ~3 ~50 ~65 double_stone_slab 0  
fill ~1 ~50 ~32 ~4 ~50 ~32 double_stone_slab 0  
fill ~1 ~50 ~66 ~4 ~50 ~66 double_stone_slab 0  
fill ~2 ~50 ~31 ~6 ~50 ~31 double_stone_slab 0  
fill ~2 ~50 ~67 ~6 ~50 ~67 double_stone_slab 0  
fill ~3 ~50 ~30 ~7 ~50 ~30 double_stone_slab 0  
fill ~3 ~50 ~68 ~7 ~50 ~68 double_stone_slab 0  
fill ~5 ~50 ~29 ~10 ~50 ~29 double_stone_slab 0  
fill ~5 ~50 ~69 ~10 ~50 ~69 double_stone_slab 0  
fill ~6 ~50 ~28 ~13 ~50 ~28 double_stone_slab 0  
fill ~6 ~50 ~70 ~13 ~50 ~70 double_stone_slab 0  
fill ~9 ~50 ~27 ~27 ~50 ~27 double_stone_slab 0  
fill ~9 ~50 ~71 ~27 ~50 ~71 double_stone_slab 0  
fill ~11 ~50 ~26 ~25 ~50 ~26 double_stone_slab 0 
setblock ~11 ~50 ~45 glowstone 0  
fill ~11 ~50 ~47 ~11 ~60 ~47 double_stone_slab 0  
fill ~11 ~50 ~51 ~11 ~60 ~51 double_stone_slab 0 
setblock ~11 ~50 ~53 glowstone 0  
fill ~11 ~50 ~72 ~25 ~50 ~72 double_stone_slab 0  
fill ~13 ~50 ~42 ~13 ~57 ~42 stained_hardened_clay 12  
fill ~13 ~50 ~48 ~15 ~50 ~48 stained_hardened_clay 12  
fill ~13 ~50 ~50 ~15 ~50 ~50 stained_hardened_clay 12  
fill ~13 ~50 ~56 ~13 ~57 ~56 stained_hardened_clay 12 
setblock ~14 ~50 ~42 glowstone 0 
setblock ~14 ~50 ~56 glowstone 0  
fill ~16 ~50 ~42 ~20 ~50 ~42 double_stone_slab 0  
fill ~16 ~50 ~56 ~20 ~50 ~56 double_stone_slab 0  
fill ~21 ~50 ~48 ~23 ~50 ~48 stained_hardened_clay 12  
fill ~21 ~50 ~50 ~23 ~50 ~50 stained_hardened_clay 12 
setblock ~22 ~50 ~42 glowstone 0 
setblock ~22 ~50 ~56 glowstone 0  
fill ~23 ~50 ~28 ~30 ~50 ~28 double_stone_slab 0  
fill ~23 ~50 ~42 ~23 ~57 ~42 stained_hardened_clay 12  
fill ~23 ~50 ~56 ~23 ~57 ~56 stained_hardened_clay 12  
fill ~23 ~50 ~70 ~30 ~50 ~70 double_stone_slab 0 
setblock ~25 ~50 ~45 glowstone 0  
fill ~25 ~50 ~47 ~25 ~60 ~47 double_stone_slab 0  
fill ~25 ~50 ~51 ~25 ~60 ~51 double_stone_slab 0 
setblock ~25 ~50 ~53 glowstone 0  
fill ~26 ~50 ~29 ~31 ~50 ~29 double_stone_slab 0  
fill ~26 ~50 ~69 ~31 ~50 ~69 double_stone_slab 0  
fill ~29 ~50 ~30 ~33 ~50 ~30 double_stone_slab 0   
fill ~29 ~50 ~68 ~33 ~50 ~68 double_stone_slab 0  
fill ~30 ~50 ~31 ~34 ~50 ~31 double_stone_slab 0  
fill ~30 ~50 ~67 ~34 ~50 ~67 double_stone_slab 0  
fill ~32 ~50 ~32 ~35 ~50 ~32 double_stone_slab 0  
fill ~32 ~50 ~66 ~35 ~50 ~66 double_stone_slab 0  
fill ~33 ~50 ~33 ~36 ~50 ~33 double_stone_slab 0  
fill ~33 ~50 ~65 ~36 ~50 ~65 double_stone_slab 0  
fill ~34 ~50 ~34 ~37 ~50 ~34 double_stone_slab 0  
fill ~34 ~50 ~64 ~37 ~50 ~64 double_stone_slab 0  
fill ~35 ~50 ~35 ~37 ~50 ~35 double_stone_slab 0  
fill ~35 ~50 ~63 ~37 ~50 ~63 double_stone_slab 0  
fill ~36 ~50 ~36 ~38 ~50 ~36 double_stone_slab 0  
fill ~36 ~50 ~37 ~39 ~50 ~37 double_stone_slab 0  
fill ~36 ~50 ~61 ~39 ~50 ~61 double_stone_slab 0  
fill ~36 ~50 ~62 ~38 ~50 ~62 double_stone_slab 0  
fill ~37 ~50 ~38 ~39 ~50 ~38 double_stone_slab 0  
fill ~37 ~50 ~60 ~39 ~50 ~60 double_stone_slab 0  
fill ~38 ~50 ~39 ~39 ~50 ~39 double_stone_slab 0  
fill ~38 ~50 ~40 ~40 ~50 ~40 double_stone_slab 0  
fill ~38 ~50 ~41 ~40 ~50 ~41 double_stone_slab 0  
fill ~38 ~50 ~57 ~40 ~50 ~57 double_stone_slab 0  
fill ~38 ~50 ~58 ~40 ~50 ~58 double_stone_slab 0  
fill ~38 ~50 ~59 ~39 ~50 ~59 double_stone_slab 0  
fill ~39 ~50 ~42 ~41 ~50 ~42 double_stone_slab 0  
fill ~39 ~50 ~43 ~41 ~50 ~43 double_stone_slab 0  
fill ~39 ~50 ~44 ~41 ~50 ~44 double_stone_slab 0  
fill ~39 ~50 ~46 ~41 ~50 ~46 double_stone_slab 0  
fill ~39 ~50 ~47 ~41 ~50 ~47 double_stone_slab 0  
fill ~39 ~50 ~48 ~41 ~50 ~48 double_stone_slab 0  
fill ~39 ~50 ~49 ~41 ~50 ~49 double_stone_slab 0  
fill ~39 ~50 ~50 ~41 ~50 ~50 double_stone_slab 0  
fill ~39 ~50 ~51 ~41 ~50 ~51 double_stone_slab 0  
fill ~39 ~50 ~52 ~41 ~50 ~52 double_stone_slab 0  
fill ~39 ~50 ~54 ~41 ~50 ~54 double_stone_slab 0  
fill ~39 ~50 ~55 ~41 ~50 ~55 double_stone_slab 0  
fill ~39 ~50 ~56 ~41 ~50 ~56 double_stone_slab 0  
fill ~40 ~50 ~45 ~41 ~50 ~45 double_stone_slab 0  
fill ~40 ~50 ~53 ~41 ~50 ~53 double_stone_slab 0  
fill ~-7 ~51 ~42 ~-6 ~51 ~42 wool 7  
fill ~-7 ~51 ~43 ~-6 ~51 ~43 wool 7  
fill ~-7 ~51 ~44 ~-6 ~51 ~44 wool 7  
fill ~-7 ~51 ~45 ~-6 ~51 ~45 wool 7  
fill ~-7 ~51 ~46 ~-6 ~51 ~46 wool 7  
fill ~-7 ~51 ~47 ~-6 ~51 ~47 wool 7  
fill ~-7 ~51 ~48 ~-6 ~51 ~48 wool 7  
fill ~-7 ~51 ~49 ~-6 ~51 ~49 wool 7  
fill ~-7 ~51 ~50 ~-6 ~51 ~50 wool 7  
fill ~-7 ~51 ~51 ~-6 ~51 ~51 wool 7  
fill ~-7 ~51 ~52 ~-6 ~51 ~52 wool 7  
fill ~-7 ~51 ~53 ~-6 ~51 ~53 wool 7  
fill ~-7 ~51 ~54 ~-6 ~51 ~54 wool 7  
fill ~-7 ~51 ~55 ~-6 ~51 ~55 wool 7  
fill ~-7 ~51 ~56 ~-6 ~51 ~56 wool 7  
fill ~-6 ~51 ~40 ~-5 ~51 ~40 wool 7  
fill ~-6 ~51 ~41 ~-5 ~51 ~41 wool 7  
fill ~-6 ~51 ~57 ~-5 ~51 ~57 wool 7  
fill ~-6 ~51 ~58 ~-5 ~51 ~58 wool 7  
fill ~-5 ~51 ~37 ~-4 ~51 ~37 wool 7  
fill ~-5 ~51 ~38 ~-4 ~51 ~38 wool 7  
fill ~-5 ~51 ~39 ~-4 ~51 ~39 wool 7  
fill ~-5 ~51 ~42 ~-5 ~51 ~56 grass 0  
fill ~-5 ~51 ~59 ~-4 ~51 ~59 wool 7  
fill ~-5 ~51 ~60 ~-4 ~51 ~60 wool 7  
fill ~-5 ~51 ~61 ~-4 ~51 ~61 wool 7  
fill ~-4 ~51 ~36 ~-3 ~51 ~36 wool 7  
fill ~-4 ~51 ~40 ~-4 ~51 ~41 grass 0  
fill ~-4 ~51 ~42 ~-3 ~51 ~42 wool 7  
fill ~-4 ~51 ~43 ~-3 ~51 ~43 wool 7  
fill ~-4 ~51 ~44 ~-3 ~51 ~44 wool 7  
fill ~-4 ~51 ~45 ~-4 ~51 ~56 wool 7  
fill ~-4 ~51 ~57 ~-4 ~51 ~58 grass 0  
fill ~-4 ~51 ~62 ~-3 ~51 ~62 wool 7  
fill ~-3 ~51 ~34 ~-2 ~51 ~34 wool 7  
fill ~-3 ~51 ~35 ~-2 ~51 ~35 wool 7  
fill ~-3 ~51 ~37 ~-3 ~51 ~39 grass 0  
fill ~-3 ~51 ~40 ~-2 ~51 ~40 wool 7  
fill ~-3 ~51 ~41 ~-2 ~51 ~41 wool 7  
fill ~-3 ~51 ~45 ~-3 ~51 ~53 stained_hardened_clay 8  
fill ~-3 ~51 ~54 ~-3 ~51 ~58 wool 7  
fill ~-3 ~51 ~59 ~-3 ~51 ~61 grass 0  
fill ~-3 ~51 ~63 ~-2 ~51 ~63 wool 7  
fill ~-3 ~51 ~64 ~-2 ~51 ~64 wool 7  
fill ~-2 ~51 ~33 ~-1 ~51 ~33 wool 7 
setblock ~-2 ~51 ~36 grass 0  
fill ~-2 ~51 ~37 ~0 ~51 ~37 wool 7  
fill ~-2 ~51 ~38 ~-1 ~51 ~38 wool 7  
fill ~-2 ~51 ~39 ~-2 ~51 ~37 wool 7  
fill ~-2 ~51 ~42 ~-2 ~51 ~44 stained_hardened_clay 8  
fill ~-2 ~51 ~45 ~-2 ~51 ~53 wool 7  
fill ~-2 ~51 ~54 ~-2 ~51 ~56 stained_hardened_clay 8  
fill ~-2 ~51 ~57 ~-2 ~51 ~61 wool 7 
setblock ~-2 ~51 ~62 grass 0  
fill ~-2 ~51 ~65 ~-1 ~51 ~65 wool 7  
fill ~-1 ~51 ~32 ~0 ~51 ~32 wool 7  
fill ~-1 ~51 ~34 ~-1 ~51 ~35 grass 0  
fill ~-1 ~51 ~36 ~0 ~51 ~36 wool 7  
fill ~-1 ~51 ~39 ~-1 ~51 ~41 stained_hardened_clay 8  
fill ~-1 ~51 ~42 ~-1 ~51 ~44 wool 7  
fill ~-1 ~51 ~48 ~0 ~51 ~48 double_stone_slab 0  
fill ~-1 ~51 ~49 ~0 ~51 ~49 double_stone_slab 0  
fill ~-1 ~51 ~50 ~0 ~51 ~50 double_stone_slab 0  
fill ~-1 ~51 ~54 ~-1 ~51 ~56 wool 7  
fill ~-1 ~51 ~57 ~-1 ~51 ~59 stained_hardened_clay 8  
fill ~-1 ~51 ~60 ~-1 ~51 ~62 wool 7  
fill ~-1 ~51 ~63 ~-1 ~51 ~64 grass 0  
fill ~-1 ~51 ~66 ~0 ~51 ~66 wool 7  
fill ~0 ~51 ~31 ~1 ~51 ~31 wool 7 
setblock ~0 ~51 ~33 grass 0  
fill ~0 ~51 ~34 ~2 ~51 ~34 wool 7  
fill ~0 ~51 ~35 ~1 ~51 ~35 wool 7 
setblock ~0 ~51 ~38 stained_hardened_clay 8  
fill ~0 ~51 ~39 ~0 ~51 ~41 wool 7  
fill ~0 ~51 ~57 ~0 ~51 ~59 wool 7 
setblock ~0 ~51 ~60 stained_hardened_clay 8  
fill ~0 ~51 ~61 ~0 ~51 ~64 wool 7 
setblock ~0 ~51 ~65 grass 0  
fill ~0 ~51 ~67 ~1 ~51 ~67 wool 7  
fill ~1 ~51 ~30 ~2 ~51 ~30 wool 7 
setblock ~1 ~51 ~32 grass 0  
fill ~1 ~51 ~33 ~3 ~51 ~33 wool 7  
fill ~1 ~51 ~36 ~1 ~51 ~37 stained_hardened_clay 8 
setblock ~1 ~51 ~38 wool 7 
setblock ~1 ~51 ~60 wool 7  
fill ~1 ~51 ~61 ~1 ~51 ~62 stained_hardened_clay 8  
fill ~1 ~51 ~63 ~1 ~51 ~65 wool 7 
setblock ~1 ~51 ~66 grass 0  
fill ~1 ~51 ~68 ~2 ~51 ~68 wool 7  
fill ~2 ~51 ~29 ~4 ~51 ~29 wool 7 
setblock ~2 ~51 ~31 grass 0  
fill ~2 ~51 ~32 ~4 ~51 ~32 wool 7 
setblock ~2 ~51 ~35 stained_hardened_clay 8  
fill ~2 ~51 ~36 ~2 ~51 ~37 wool 7  
fill ~2 ~51 ~61 ~2 ~51 ~62 wool 7 
setblock ~2 ~51 ~63 stained_hardened_clay 8  
fill ~2 ~51 ~64 ~2 ~51 ~66 wool 7 
setblock ~2 ~51 ~67 grass 0  
fill ~2 ~51 ~69 ~4 ~51 ~69 wool 7  
fill ~3 ~51 ~28 ~5 ~51 ~28 wool 7  
fill ~3 ~51 ~30 ~4 ~51 ~30 grass 0  
fill ~3 ~51 ~31 ~6 ~51 ~31 wool 7 
setblock ~3 ~51 ~34 stained_hardened_clay 8 
setblock ~3 ~51 ~35 wool 7 
setblock ~3 ~51 ~63 wool 7 
setblock ~3 ~51 ~64 stained_hardened_clay 8  
fill ~3 ~51 ~65 ~3 ~51 ~67 wool 7  
fill ~3 ~51 ~68 ~4 ~51 ~68 grass 0  
fill ~3 ~51 ~70 ~5 ~51 ~70 wool 7 
setblock ~4 ~51 ~33 stained_hardened_clay 8 
setblock ~4 ~51 ~34 wool 7 
setblock ~4 ~51 ~64 wool 7 
setblock ~4 ~51 ~65 stained_hardened_clay 8  
fill ~4 ~51 ~66 ~4 ~51 ~67 wool 7  
fill ~5 ~51 ~27 ~8 ~51 ~27 wool 7 
setblock ~5 ~51 ~29 grass 0  
fill ~5 ~51 ~30 ~7 ~51 ~30 wool 7  
fill ~5 ~51 ~32 ~6 ~51 ~32 stained_hardened_clay 8  
fill ~5 ~51 ~33 ~6 ~51 ~33 wool 7  
fill ~5 ~51 ~65 ~6 ~51 ~65 wool 7  
fill ~5 ~51 ~66 ~6 ~51 ~66 stained_hardened_clay 8  
fill ~5 ~51 ~67 ~6 ~51 ~67 wool 7  
fill ~5 ~51 ~68 ~7 ~51 ~68 wool 7 
setblock ~5 ~51 ~69 grass 0  
fill ~5 ~51 ~71 ~8 ~51 ~71 wool 7  
fill ~6 ~51 ~26 ~10 ~51 ~26 wool 7  
fill ~6 ~51 ~28 ~8 ~51 ~28 grass 0  
fill ~6 ~51 ~29 ~10 ~51 ~29 wool 7  
fill ~6 ~51 ~69 ~10 ~51 ~69 wool 7  
fill ~6 ~51 ~70 ~8 ~51 ~70 grass 0  
fill ~6 ~51 ~72 ~10 ~51 ~72 wool 7 
setblock ~7 ~51 ~31 stained_hardened_clay 8 
setblock ~7 ~51 ~32 wool 7 
setblock ~7 ~51 ~66 wool 7 
setblock ~7 ~51 ~67 stained_hardened_clay 8  
fill ~8 ~51 ~30 ~10 ~51 ~30 stained_hardened_clay 8  
fill ~8 ~51 ~31 ~10 ~51 ~31 wool 7  
fill ~8 ~51 ~67 ~10 ~51 ~67 wool 7  
fill ~8 ~51 ~68 ~10 ~51 ~68 stained_hardened_clay 8  
fill ~9 ~51 ~25 ~27 ~51 ~25 wool 7  
fill ~9 ~51 ~27 ~10 ~51 ~27 grass 0  
fill ~9 ~51 ~28 ~13 ~51 ~28 wool 7  
fill ~9 ~51 ~70 ~13 ~51 ~70 wool 7  
fill ~9 ~51 ~71 ~10 ~51 ~71 grass 0  
fill ~9 ~51 ~73 ~27 ~51 ~73 wool 7  
fill ~11 ~51 ~24 ~25 ~51 ~24 wool 7  
fill ~11 ~51 ~26 ~25 ~51 ~26 grass 0  
fill ~11 ~51 ~27 ~25 ~51 ~27 wool 7  
fill ~11 ~51 ~29 ~13 ~51 ~29 stained_hardened_clay 8  
fill ~11 ~51 ~30 ~13 ~51 ~30 wool 7  
fill ~11 ~51 ~45 ~11 ~57 ~45 stained_hardened_clay 12  
fill ~11 ~51 ~53 ~11 ~57 ~53 stained_hardened_clay 12  
fill ~11 ~51 ~68 ~13 ~51 ~68 wool 7  
fill ~11 ~51 ~69 ~13 ~51 ~69 stained_hardened_clay 8  
fill ~11 ~51 ~71 ~25 ~51 ~71 wool 7  
fill ~11 ~51 ~72 ~25 ~51 ~72 grass 0  
fill ~11 ~51 ~74 ~25 ~51 ~74 wool 7  
fill ~13 ~51 ~48 ~15 ~51 ~48 stained_hardened_clay 12  
fill ~13 ~51 ~50 ~15 ~51 ~50 stained_hardened_clay 12  
fill ~14 ~51 ~28 ~22 ~51 ~28 stained_hardened_clay 8  
fill ~14 ~51 ~29 ~22 ~51 ~29 wool 7  
fill ~14 ~51 ~42 ~14 ~57 ~42 stained_hardened_clay 12  
fill ~14 ~51 ~56 ~14 ~57 ~56 stained_hardened_clay 12  
fill ~14 ~51 ~69 ~22 ~51 ~69 wool 7  
fill ~14 ~51 ~70 ~22 ~51 ~70 stained_hardened_clay 8  
fill ~16 ~51 ~42 ~17 ~51 ~42 double_stone_slab 0  
fill ~16 ~51 ~56 ~17 ~51 ~56 double_stone_slab 0  
fill ~17 ~51 ~30 ~19 ~51 ~30 double_stone_slab 0  
fill ~17 ~51 ~31 ~19 ~51 ~31 double_stone_slab 0  
fill ~17 ~51 ~67 ~19 ~51 ~67 double_stone_slab 0  
fill ~17 ~51 ~68 ~19 ~51 ~68 double_stone_slab 0  
fill ~19 ~51 ~42 ~20 ~51 ~42 double_stone_slab 0  
fill ~19 ~51 ~56 ~20 ~51 ~56 double_stone_slab 0  
fill ~21 ~51 ~48 ~23 ~51 ~48 stained_hardened_clay 12  
fill ~21 ~51 ~50 ~23 ~51 ~50 stained_hardened_clay 12  
fill ~22 ~51 ~42 ~22 ~57 ~42 stained_hardened_clay 12  
fill ~22 ~51 ~56 ~22 ~57 ~56 stained_hardened_clay 12  
fill ~23 ~51 ~28 ~27 ~51 ~28 wool 7  
fill ~23 ~51 ~29 ~25 ~51 ~29 stained_hardened_clay 8  
fill ~23 ~51 ~30 ~25 ~51 ~30 wool 7  
fill ~23 ~51 ~68 ~25 ~51 ~68 wool 7  
fill ~23 ~51 ~69 ~25 ~51 ~69 stained_hardened_clay 8  
fill ~23 ~51 ~70 ~27 ~51 ~70 wool 7  
fill ~25 ~51 ~45 ~25 ~57 ~45 stained_hardened_clay 12  
fill ~25 ~51 ~53 ~25 ~57 ~53 stained_hardened_clay 12  
fill ~26 ~51 ~26 ~30 ~51 ~26 wool 7  
fill ~26 ~51 ~27 ~27 ~51 ~27 grass 0  
fill ~26 ~51 ~29 ~30 ~51 ~29 wool 7  
fill ~26 ~51 ~30 ~28 ~51 ~30 stained_hardened_clay 8  
fill ~26 ~51 ~31 ~28 ~51 ~31 wool 7  
fill ~26 ~51 ~67 ~28 ~51 ~67 wool 7  
fill ~26 ~51 ~68 ~28 ~51 ~68 stained_hardened_clay 8  
fill ~26 ~51 ~69 ~30 ~51 ~69 wool 7  
fill ~26 ~51 ~71 ~27 ~51 ~71 grass 0  
fill ~26 ~51 ~72 ~30 ~51 ~72 wool 7  
fill ~28 ~51 ~27 ~31 ~51 ~27 wool 7  
fill ~28 ~51 ~28 ~30 ~51 ~28 grass 0  
fill ~28 ~51 ~70 ~30 ~51 ~70 grass 0  
fill ~28 ~51 ~71 ~31 ~51 ~71 wool 7  
fill ~29 ~51 ~30 ~31 ~51 ~30 wool 7 
setblock ~29 ~51 ~31 stained_hardened_clay 8 
setblock ~29 ~51 ~32 wool 7 
setblock ~29 ~51 ~66 wool 7 
setblock ~29 ~51 ~67 stained_hardened_clay 8  
fill ~29 ~51 ~68 ~31 ~51 ~68 wool 7  
fill ~30 ~51 ~31 ~33 ~51 ~31 wool 7  
fill ~30 ~51 ~32 ~31 ~51 ~32 stained_hardened_clay 8  
fill ~30 ~51 ~33 ~31 ~51 ~33 wool 7  
fill ~30 ~51 ~65 ~31 ~51 ~65 wool 7  
fill ~30 ~51 ~66 ~31 ~51 ~66 stained_hardened_clay 8  
fill ~30 ~51 ~67 ~33 ~51 ~67 wool 7  
fill ~31 ~51 ~28 ~33 ~51 ~28 wool 7 
setblock ~31 ~51 ~29 grass 0 
setblock ~31 ~51 ~69 grass 0  
fill ~31 ~51 ~70 ~33 ~51 ~70 wool 7  
fill ~32 ~51 ~29 ~34 ~51 ~29 wool 7  
fill ~32 ~51 ~30 ~33 ~51 ~30 grass 0  
fill ~32 ~51 ~32 ~34 ~51 ~32 wool 7 
setblock ~32 ~51 ~33 stained_hardened_clay 8 
setblock ~32 ~51 ~34 wool 7 
setblock ~32 ~51 ~64 wool 7 
setblock ~32 ~51 ~65 stained_hardened_clay 8  
fill ~32 ~51 ~66 ~34 ~51 ~66 wool 7  
fill ~32 ~51 ~68 ~33 ~51 ~68 grass 0  
fill ~32 ~51 ~69 ~34 ~51 ~69 wool 7  
fill ~33 ~51 ~33 ~35 ~51 ~33 wool 7 
setblock ~33 ~51 ~34 stained_hardened_clay 8 
setblock ~33 ~51 ~35 wool 7 
setblock ~33 ~51 ~63 wool 7 
setblock ~33 ~51 ~64 stained_hardened_clay 8  
fill ~33 ~51 ~65 ~35 ~51 ~65 wool 7  
fill ~34 ~51 ~30 ~35 ~51 ~30 wool 7 
setblock ~34 ~51 ~31 grass 0  
fill ~34 ~51 ~34 ~36 ~51 ~34 wool 7 
setblock ~34 ~51 ~35 stained_hardened_clay 8  
fill ~34 ~51 ~36 ~34 ~51 ~37 wool 7  
fill ~34 ~51 ~61 ~34 ~51 ~62 wool 7 
setblock ~34 ~51 ~63 stained_hardened_clay 8  
fill ~34 ~51 ~64 ~36 ~51 ~64 wool 7 
setblock ~34 ~51 ~67 grass 0  
fill ~34 ~51 ~68 ~35 ~51 ~68 wool 7  
fill ~35 ~51 ~31 ~36 ~51 ~31 wool 7 
setblock ~35 ~51 ~32 grass 0  
fill ~35 ~51 ~35 ~36 ~51 ~35 wool 7  
fill ~35 ~51 ~36 ~35 ~51 ~37 stained_hardened_clay 8 
setblock ~35 ~51 ~38 wool 7  
fill ~35 ~51 ~48 ~36 ~51 ~48 double_stone_slab 0  
fill ~35 ~51 ~49 ~36 ~51 ~49 double_stone_slab 0  
fill ~35 ~51 ~50 ~36 ~51 ~50 double_stone_slab 0 
setblock ~35 ~51 ~60 wool 7  
fill ~35 ~51 ~61 ~35 ~51 ~62 stained_hardened_clay 8  
fill ~35 ~51 ~63 ~36 ~51 ~63 wool 7 
setblock ~35 ~51 ~66 grass 0  
fill ~35 ~51 ~67 ~36 ~51 ~67 wool 7  
fill ~36 ~51 ~32 ~37 ~51 ~32 wool 7 
setblock ~36 ~51 ~33 grass 0  
fill ~36 ~51 ~36 ~37 ~51 ~36 wool 7  
fill ~36 ~51 ~37 ~38 ~51 ~37 wool 7 
setblock ~36 ~51 ~38 stained_hardened_clay 8  
fill ~36 ~51 ~39 ~36 ~51 ~41 wool 7  
fill ~36 ~51 ~57 ~36 ~51 ~59 wool 7 
setblock ~36 ~51 ~60 stained_hardened_clay 8  
fill ~36 ~51 ~61 ~38 ~51 ~61 wool 7  
fill ~36 ~51 ~62 ~37 ~51 ~62 wool 7 
setblock ~36 ~51 ~65 grass 0  
fill ~36 ~51 ~66 ~37 ~51 ~66 wool 7  
fill ~37 ~51 ~33 ~38 ~51 ~33 wool 7  
fill ~37 ~51 ~34 ~37 ~51 ~35 grass 0  
fill ~37 ~51 ~38 ~38 ~51 ~38 wool 7  
fill ~37 ~51 ~39 ~37 ~51 ~41 stained_hardened_clay 8  
fill ~37 ~51 ~42 ~37 ~51 ~56 wool 7  
fill ~37 ~51 ~57 ~37 ~51 ~59 stained_hardened_clay 8  
fill ~37 ~51 ~60 ~38 ~51 ~60 wool 7  
fill ~37 ~51 ~63 ~37 ~51 ~64 grass 0  
fill ~37 ~51 ~65 ~38 ~51 ~65 wool 7  
fill ~38 ~51 ~34 ~39 ~51 ~34 wool 7  
fill ~38 ~51 ~35 ~39 ~51 ~35 wool 7 
setblock ~38 ~51 ~36 grass 0  
fill ~38 ~51 ~39 ~38 ~51 ~41 wool 7  
fill ~38 ~51 ~42 ~38 ~51 ~44 stained_hardened_clay 8  
fill ~38 ~51 ~45 ~38 ~51 ~53 wool 7  
fill ~38 ~51 ~54 ~38 ~51 ~56 stained_hardened_clay 8  
fill ~38 ~51 ~57 ~39 ~51 ~57 wool 7  
fill ~38 ~51 ~58 ~39 ~51 ~58 wool 7  
fill ~38 ~51 ~59 ~38 ~51 ~57 wool 7 
setblock ~38 ~51 ~62 grass 0  
fill ~38 ~51 ~63 ~39 ~51 ~63 wool 7  
fill ~38 ~51 ~64 ~39 ~51 ~64 wool 7  
fill ~39 ~51 ~36 ~40 ~51 ~36 wool 7  
fill ~39 ~51 ~37 ~39 ~51 ~39 grass 0  
fill ~39 ~51 ~40 ~39 ~51 ~44 wool 7  
fill ~39 ~51 ~45 ~39 ~51 ~53 stained_hardened_clay 8  
fill ~39 ~51 ~54 ~40 ~51 ~54 wool 7  
fill ~39 ~51 ~55 ~40 ~51 ~55 wool 7  
fill ~39 ~51 ~56 ~40 ~51 ~56 wool 7  
fill ~39 ~51 ~59 ~39 ~51 ~61 grass 0  
fill ~39 ~51 ~62 ~40 ~51 ~62 wool 7  
fill ~40 ~51 ~37 ~41 ~51 ~37 wool 7  
fill ~40 ~51 ~38 ~41 ~51 ~38 wool 7  
fill ~40 ~51 ~39 ~41 ~51 ~39 wool 7  
fill ~40 ~51 ~40 ~40 ~51 ~41 grass 0  
fill ~40 ~51 ~42 ~40 ~51 ~56 wool 7  
fill ~40 ~51 ~57 ~40 ~51 ~58 grass 0  
fill ~40 ~51 ~59 ~41 ~51 ~59 wool 7  
fill ~40 ~51 ~60 ~41 ~51 ~60 wool 7  
fill ~40 ~51 ~61 ~41 ~51 ~61 wool 7  
fill ~41 ~51 ~40 ~42 ~51 ~40 wool 7  
fill ~41 ~51 ~41 ~42 ~51 ~41 wool 7  
fill ~41 ~51 ~42 ~41 ~51 ~56 grass 0  
fill ~41 ~51 ~57 ~42 ~51 ~57 wool 7  
fill ~41 ~51 ~58 ~42 ~51 ~58 wool 7  
fill ~42 ~51 ~42 ~43 ~51 ~42 wool 7  
fill ~42 ~51 ~43 ~43 ~51 ~43 wool 7  
fill ~42 ~51 ~44 ~43 ~51 ~44 wool 7  
fill ~42 ~51 ~45 ~43 ~51 ~45 wool 7  
fill ~42 ~51 ~46 ~43 ~51 ~46 wool 7  
fill ~42 ~51 ~47 ~43 ~51 ~47 wool 7  
fill ~42 ~51 ~48 ~43 ~51 ~48 wool 7  
fill ~42 ~51 ~49 ~43 ~51 ~49 wool 7  
fill ~42 ~51 ~50 ~43 ~51 ~50 wool 7  
fill ~42 ~51 ~51 ~43 ~51 ~51 wool 7  
fill ~42 ~51 ~52 ~43 ~51 ~52 wool 7  
fill ~42 ~51 ~53 ~43 ~51 ~53 wool 7  
fill ~42 ~51 ~54 ~43 ~51 ~54 wool 7  
fill ~42 ~51 ~55 ~43 ~51 ~55 wool 7  
fill ~42 ~51 ~56 ~43 ~51 ~56 wool 7  
fill ~-9 ~52 ~41 ~-7 ~52 ~41 wool 7  
fill ~-9 ~52 ~42 ~-8 ~52 ~42 wool 7  
fill ~-9 ~52 ~43 ~-8 ~52 ~43 glass 0  
fill ~-9 ~52 ~44 ~-8 ~52 ~44 glass 0  
fill ~-9 ~52 ~45 ~-8 ~52 ~45 glass 0  
fill ~-9 ~52 ~46 ~-8 ~52 ~46 wool 7  
fill ~-9 ~52 ~47 ~-8 ~52 ~47 wool 7  
fill ~-9 ~52 ~48 ~-8 ~52 ~48 glass 0  
fill ~-9 ~52 ~49 ~-8 ~52 ~49 glass 0  
fill ~-9 ~52 ~50 ~-8 ~52 ~50 glass 0  
fill ~-9 ~52 ~51 ~-8 ~52 ~51 wool 7  
fill ~-9 ~52 ~52 ~-8 ~52 ~52 wool 7  
fill ~-9 ~52 ~53 ~-8 ~52 ~53 glass 0  
fill ~-9 ~52 ~54 ~-8 ~52 ~54 glass 0  
fill ~-9 ~52 ~55 ~-8 ~52 ~55 glass 0  
fill ~-9 ~52 ~56 ~-8 ~52 ~56 wool 7  
fill ~-9 ~52 ~57 ~-7 ~52 ~57 wool 7  
fill ~-8 ~52 ~39 ~-6 ~52 ~39 glass 0  
fill ~-8 ~52 ~40 ~-7 ~52 ~40 glass 0  
fill ~-8 ~52 ~58 ~-7 ~52 ~58 glass 0  
fill ~-8 ~52 ~59 ~-6 ~52 ~59 glass 0  
fill ~-7 ~52 ~36 ~-6 ~52 ~36 wool 7  
fill ~-7 ~52 ~37 ~-6 ~52 ~37 wool 7  
fill ~-7 ~52 ~38 ~-6 ~52 ~38 glass 0  
fill ~-7 ~52 ~42 ~-6 ~52 ~42 grass 0  
fill ~-7 ~52 ~43 ~-6 ~52 ~43 grass 0  
fill ~-7 ~52 ~44 ~-6 ~52 ~44 grass 0  
fill ~-7 ~52 ~45 ~-6 ~52 ~45 grass 0  
fill ~-7 ~52 ~46 ~-6 ~52 ~46 grass 0  
fill ~-7 ~52 ~47 ~-6 ~52 ~47 grass 0  
fill ~-7 ~52 ~48 ~-6 ~52 ~48 grass 0  
fill ~-7 ~52 ~49 ~-6 ~52 ~49 grass 0  
fill ~-7 ~52 ~50 ~-6 ~52 ~50 grass 0  
fill ~-7 ~52 ~51 ~-6 ~52 ~51 grass 0  
fill ~-7 ~52 ~52 ~-6 ~52 ~52 grass 0  
fill ~-7 ~52 ~53 ~-6 ~52 ~53 grass 0  
fill ~-7 ~52 ~54 ~-6 ~52 ~54 grass 0  
fill ~-7 ~52 ~55 ~-6 ~52 ~55 grass 0  
fill ~-7 ~52 ~56 ~-6 ~52 ~56 grass 0  
fill ~-7 ~52 ~60 ~-6 ~52 ~60 glass 0  
fill ~-7 ~52 ~61 ~-6 ~52 ~61 wool 7  
fill ~-7 ~52 ~62 ~-6 ~52 ~62 wool 7  
fill ~-6 ~52 ~35 ~-4 ~52 ~35 glass 0  
fill ~-6 ~52 ~40 ~-5 ~52 ~40 grass 0  
fill ~-6 ~52 ~41 ~-5 ~52 ~41 grass 0  
fill ~-6 ~52 ~57 ~-5 ~52 ~57 grass 0  
fill ~-6 ~52 ~58 ~-5 ~52 ~58 grass 0  
fill ~-6 ~52 ~63 ~-4 ~52 ~63 glass 0  
fill ~-5 ~52 ~33 ~-3 ~52 ~33 wool 7  
fill ~-5 ~52 ~34 ~-4 ~52 ~34 glass 0 
setblock ~-5 ~52 ~36 glass 0  
fill ~-5 ~52 ~37 ~-4 ~52 ~37 grass 0  
fill ~-5 ~52 ~38 ~-4 ~52 ~38 grass 0  
fill ~-5 ~52 ~39 ~-4 ~52 ~39 grass 0  
fill ~-5 ~52 ~50 ~-4 ~52 ~50 fence 0  
fill ~-5 ~52 ~59 ~-4 ~52 ~59 grass 0  
fill ~-5 ~52 ~60 ~-4 ~52 ~60 grass 0  
fill ~-5 ~52 ~61 ~-4 ~52 ~61 grass 0 
setblock ~-5 ~52 ~62 glass 0  
fill ~-5 ~52 ~64 ~-4 ~52 ~64 glass 0  
fill ~-5 ~52 ~65 ~-3 ~52 ~65 wool 7  
fill ~-4 ~52 ~32 ~-2 ~52 ~32 wool 7  
fill ~-4 ~52 ~36 ~-3 ~52 ~36 grass 0 
setblock ~-4 ~52 ~40 oak_stairs 3 
setblock ~-4 ~52 ~41 fence 0 
setblock ~-4 ~52 ~42 oak_stairs 2  
fill ~-4 ~52 ~48 ~-4 ~52 ~50 fence 0 
setblock ~-4 ~52 ~54 oak_stairs 3 
setblock ~-4 ~52 ~55 fence 0 
setblock ~-4 ~52 ~56 oak_stairs 2  
fill ~-4 ~52 ~62 ~-3 ~52 ~62 grass 0  
fill ~-4 ~52 ~66 ~-2 ~52 ~66 wool 7  
fill ~-3 ~52 ~31 ~-2 ~52 ~31 wool 7  
fill ~-3 ~52 ~34 ~-2 ~52 ~34 grass 0  
fill ~-3 ~52 ~35 ~-2 ~52 ~35 grass 0  
fill ~-3 ~52 ~63 ~-2 ~52 ~63 grass 0  
fill ~-3 ~52 ~64 ~-2 ~52 ~64 grass 0  
fill ~-3 ~52 ~67 ~-2 ~52 ~67 wool 7  
fill ~-2 ~52 ~33 ~-1 ~52 ~33 grass 0 
setblock ~-2 ~52 ~36 oak_stairs 3 
setblock ~-2 ~52 ~37 fence 0 
setblock ~-2 ~52 ~38 oak_stairs 2 
setblock ~-2 ~52 ~47 log 2 
setblock ~-2 ~52 ~51 log 2 
setblock ~-2 ~52 ~59 oak_stairs 3 
setblock ~-2 ~52 ~60 fence 0 
setblock ~-2 ~52 ~61 oak_stairs 2  
fill ~-2 ~52 ~65 ~-1 ~52 ~65 grass 0  
fill ~-1 ~52 ~30 ~0 ~52 ~30 glass 0  
fill ~-1 ~52 ~31 ~-1 ~52 ~30 glass 0  
fill ~-1 ~52 ~32 ~0 ~52 ~32 grass 0  
fill ~-1 ~52 ~45 ~0 ~52 ~45 wool 7  
fill ~-1 ~52 ~46 ~-1 ~53 ~46 wool 7  
fill ~-1 ~52 ~47 ~-1 ~53 ~47 wool 7  
fill ~-1 ~52 ~51 ~-1 ~53 ~51 wool 7  
fill ~-1 ~52 ~52 ~-1 ~53 ~52 wool 7  
fill ~-1 ~52 ~53 ~0 ~52 ~53 wool 7  
fill ~-1 ~52 ~66 ~0 ~52 ~66 grass 0  
fill ~-1 ~52 ~67 ~-1 ~52 ~68 glass 0  
fill ~0 ~52 ~28 ~2 ~52 ~28 wool 7  
fill ~0 ~52 ~29 ~1 ~52 ~29 wool 7  
fill ~0 ~52 ~31 ~1 ~52 ~31 grass 0 
setblock ~0 ~52 ~41 log 2  
fill ~0 ~52 ~42 ~1 ~52 ~42 wool 7  
fill ~0 ~52 ~43 ~0 ~53 ~43 wool 7  
fill ~0 ~52 ~44 ~0 ~53 ~44 glass 0  
fill ~0 ~52 ~47 ~0 ~55 ~47 double_stone_slab 0  
fill ~0 ~52 ~48 ~0 ~52 ~50 stone_brick_stairs 0  
fill ~0 ~52 ~51 ~0 ~55 ~51 double_stone_slab 0  
fill ~0 ~52 ~54 ~0 ~53 ~54 glass 0  
fill ~0 ~52 ~55 ~0 ~53 ~55 wool 7  
fill ~0 ~52 ~56 ~1 ~52 ~56 wool 7 
setblock ~0 ~52 ~57 log 2  
fill ~0 ~52 ~67 ~1 ~52 ~67 grass 0 
setblock ~0 ~52 ~68 glass 0  
fill ~0 ~52 ~69 ~1 ~52 ~69 wool 7  
fill ~0 ~52 ~70 ~2 ~52 ~70 wool 7  
fill ~1 ~52 ~27 ~2 ~52 ~27 wool 7  
fill ~1 ~52 ~30 ~2 ~52 ~30 grass 0  
fill ~1 ~52 ~39 ~2 ~52 ~39 wool 7  
fill ~1 ~52 ~40 ~1 ~53 ~40 wool 7  
fill ~1 ~52 ~41 ~1 ~53 ~41 wool 7  
fill ~1 ~52 ~48 ~1 ~52 ~50 double_stone_slab 0  
fill ~1 ~52 ~57 ~1 ~53 ~57 wool 7  
fill ~1 ~52 ~58 ~1 ~53 ~58 wool 7  
fill ~1 ~52 ~59 ~2 ~52 ~59 wool 7 
setblock ~1 ~52 ~66 oak_stairs 1  
fill ~1 ~52 ~68 ~2 ~52 ~68 grass 0  
fill ~1 ~52 ~71 ~2 ~52 ~71 wool 7 
setblock ~2 ~52 ~26 wool 7  
fill ~2 ~52 ~29 ~4 ~52 ~29 grass 0 
setblock ~2 ~52 ~37 log 2  
fill ~2 ~52 ~38 ~3 ~52 ~38 wool 7  
fill ~2 ~52 ~60 ~3 ~52 ~60 wool 7 
setblock ~2 ~52 ~61 log 2 
setblock ~2 ~52 ~66 fence 0  
fill ~2 ~52 ~69 ~4 ~52 ~69 grass 0 
setblock ~2 ~52 ~72 wool 7  
fill ~3 ~52 ~26 ~5 ~52 ~26 glass 0  
fill ~3 ~52 ~27 ~4 ~52 ~27 glass 0  
fill ~3 ~52 ~28 ~5 ~52 ~28 grass 0 
setblock ~3 ~52 ~30 oak_stairs 1  
fill ~3 ~52 ~36 ~3 ~52 ~38 wool 7  
fill ~3 ~52 ~61 ~3 ~53 ~61 wool 7  
fill ~3 ~52 ~62 ~3 ~52 ~60 wool 7 
setblock ~3 ~52 ~66 oak_stairs 0  
fill ~3 ~52 ~70 ~5 ~52 ~70 grass 0  
fill ~3 ~52 ~71 ~4 ~52 ~71 glass 0  
fill ~3 ~52 ~72 ~5 ~52 ~72 glass 0  
fill ~4 ~52 ~25 ~5 ~52 ~25 glass 0 
setblock ~4 ~52 ~30 fence 0  
fill ~4 ~52 ~35 ~5 ~52 ~35 glass 0  
fill ~4 ~52 ~36 ~4 ~53 ~36 glass 0  
fill ~4 ~52 ~62 ~4 ~53 ~62 glass 0  
fill ~4 ~52 ~63 ~5 ~52 ~63 glass 0 
setblock ~4 ~52 ~73 glass 0  
fill ~5 ~52 ~24 ~6 ~52 ~24 wool 7  
fill ~5 ~52 ~27 ~8 ~52 ~27 grass 0 
setblock ~5 ~52 ~30 oak_stairs 0  
fill ~5 ~52 ~34 ~7 ~52 ~34 wool 7  
fill ~5 ~52 ~64 ~7 ~52 ~64 wool 7  
fill ~5 ~52 ~71 ~8 ~52 ~71 grass 0  
fill ~5 ~52 ~73 ~6 ~52 ~73 wool 7  
fill ~5 ~52 ~74 ~6 ~52 ~74 wool 7 
setblock ~6 ~52 ~25 wool 7  
fill ~6 ~52 ~26 ~10 ~52 ~26 grass 0 
setblock ~6 ~52 ~33 log 2 
setblock ~6 ~52 ~65 log 2 
setblock ~6 ~52 ~69 oak_stairs 1  
fill ~6 ~52 ~72 ~10 ~52 ~72 grass 0  
fill ~7 ~52 ~24 ~9 ~52 ~24 glass 0  
fill ~7 ~52 ~25 ~8 ~52 ~25 glass 0  
fill ~7 ~52 ~33 ~8 ~52 ~33 wool 7  
fill ~7 ~52 ~65 ~8 ~52 ~65 wool 7 
setblock ~7 ~52 ~69 fence 0  
fill ~7 ~52 ~73 ~8 ~52 ~73 glass 0  
fill ~7 ~52 ~74 ~9 ~52 ~74 glass 0  
fill ~8 ~52 ~23 ~9 ~52 ~23 glass 0  
fill ~8 ~52 ~32 ~11 ~52 ~32 wool 7  
fill ~8 ~52 ~66 ~11 ~52 ~66 wool 7 
setblock ~8 ~52 ~69 oak_stairs 0  
fill ~8 ~52 ~75 ~9 ~52 ~75 glass 0  
fill ~9 ~52 ~25 ~27 ~52 ~25 grass 0 
setblock ~9 ~52 ~27 oak_stairs 1  
fill ~9 ~52 ~73 ~27 ~52 ~73 grass 0  
fill ~10 ~52 ~22 ~11 ~52 ~22 wool 7  
fill ~10 ~52 ~23 ~11 ~52 ~23 wool 7  
fill ~10 ~52 ~24 ~10 ~52 ~22 wool 7 
setblock ~10 ~52 ~27 fence 0 
setblock ~10 ~52 ~31 log 2 
setblock ~10 ~52 ~67 log 2  
fill ~10 ~52 ~74 ~10 ~52 ~76 wool 7  
fill ~11 ~52 ~24 ~25 ~52 ~24 grass 0 
setblock ~11 ~52 ~27 oak_stairs 0  
fill ~11 ~52 ~31 ~12 ~52 ~31 wool 7  
fill ~11 ~52 ~67 ~12 ~52 ~67 wool 7 
setblock ~11 ~52 ~72 oak_stairs 1  
fill ~11 ~52 ~74 ~25 ~52 ~74 grass 0  
fill ~11 ~52 ~75 ~11 ~52 ~76 wool 7  
fill ~12 ~52 ~22 ~14 ~52 ~22 glass 0  
fill ~12 ~52 ~23 ~14 ~52 ~23 glass 0 
setblock ~12 ~52 ~72 fence 0  
fill ~12 ~52 ~75 ~14 ~52 ~75 glass 0  
fill ~12 ~52 ~76 ~14 ~52 ~76 glass 0  
fill ~13 ~52 ~31 ~13 ~53 ~31 glass 0  
fill ~13 ~52 ~48 ~15 ~52 ~48 stained_hardened_clay 12  
fill ~13 ~52 ~50 ~15 ~52 ~50 stained_hardened_clay 12  
fill ~13 ~52 ~67 ~13 ~53 ~67 glass 0 
setblock ~13 ~52 ~72 oak_stairs 0  
fill ~14 ~52 ~30 ~16 ~52 ~30 wool 7  
fill ~14 ~52 ~31 ~14 ~53 ~31 wool 7  
fill ~14 ~52 ~67 ~14 ~53 ~67 wool 7  
fill ~14 ~52 ~68 ~16 ~52 ~68 wool 7  
fill ~15 ~52 ~22 ~16 ~52 ~22 wool 7  
fill ~15 ~52 ~23 ~16 ~52 ~23 wool 7  
fill ~15 ~52 ~75 ~16 ~52 ~75 wool 7  
fill ~15 ~52 ~76 ~16 ~52 ~76 wool 7 
setblock ~16 ~52 ~29 log 2  
fill ~16 ~52 ~31 ~16 ~55 ~31 double_stone_slab 0  
fill ~16 ~52 ~42 ~16 ~62 ~42 double_stone_slab 0 
setblock ~16 ~52 ~48 double_stone_slab 0 
setblock ~16 ~52 ~50 double_stone_slab 0  
fill ~16 ~52 ~56 ~16 ~62 ~56 double_stone_slab 0  
fill ~16 ~52 ~67 ~16 ~55 ~67 double_stone_slab 0 
setblock ~16 ~52 ~69 log 2  
fill ~17 ~52 ~22 ~19 ~52 ~22 glass 0  
fill ~17 ~52 ~23 ~19 ~52 ~23 glass 0  
fill ~17 ~52 ~26 ~17 ~54 ~26 fence 0  
fill ~17 ~52 ~27 ~19 ~52 ~27 fence 0  
fill ~17 ~52 ~31 ~19 ~52 ~31 stone_brick_stairs 2  
fill ~17 ~52 ~32 ~19 ~52 ~32 double_stone_slab 0 
setblock ~17 ~52 ~47 double_stone_slab 0 
setblock ~17 ~52 ~51 double_stone_slab 0  
fill ~17 ~52 ~66 ~19 ~52 ~66 double_stone_slab 0  
fill ~17 ~52 ~67 ~19 ~52 ~67 stone_brick_stairs 3  
fill ~17 ~52 ~71 ~19 ~52 ~71 fence 0  
fill ~17 ~52 ~75 ~19 ~52 ~75 glass 0  
fill ~17 ~52 ~76 ~19 ~52 ~76 glass 0 
setblock ~19 ~52 ~47 double_stone_slab 0 
setblock ~19 ~52 ~51 double_stone_slab 0  
fill ~19 ~52 ~72 ~19 ~54 ~72 fence 0  
fill ~20 ~52 ~22 ~21 ~52 ~22 wool 7  
fill ~20 ~52 ~23 ~21 ~52 ~23 wool 7 
setblock ~20 ~52 ~29 log 2  
fill ~20 ~52 ~30 ~22 ~52 ~30 wool 7  
fill ~20 ~52 ~31 ~20 ~55 ~31 double_stone_slab 0  
fill ~20 ~52 ~42 ~20 ~62 ~42 double_stone_slab 0 
setblock ~20 ~52 ~48 double_stone_slab 0 
setblock ~20 ~52 ~50 double_stone_slab 0  
fill ~20 ~52 ~56 ~20 ~62 ~56 double_stone_slab 0  
fill ~20 ~52 ~67 ~20 ~55 ~67 double_stone_slab 0  
fill ~20 ~52 ~68 ~22 ~52 ~68 wool 7 
setblock ~20 ~52 ~69 log 2  
fill ~20 ~52 ~75 ~21 ~52 ~75 wool 7  
fill ~20 ~52 ~76 ~21 ~52 ~76 wool 7  
fill ~21 ~52 ~48 ~23 ~52 ~48 stained_hardened_clay 12  
fill ~21 ~52 ~50 ~23 ~52 ~50 stained_hardened_clay 12  
fill ~22 ~52 ~22 ~24 ~52 ~22 glass 0  
fill ~22 ~52 ~23 ~24 ~52 ~23 glass 0  
fill ~22 ~52 ~31 ~22 ~53 ~31 wool 7  
fill ~22 ~52 ~67 ~22 ~53 ~67 wool 7  
fill ~22 ~52 ~75 ~24 ~52 ~75 glass 0  
fill ~22 ~52 ~76 ~24 ~52 ~76 glass 0  
fill ~23 ~52 ~31 ~23 ~53 ~31 glass 0  
fill ~23 ~52 ~67 ~23 ~53 ~67 glass 0 
setblock ~23 ~52 ~72 oak_stairs 1  
fill ~24 ~52 ~31 ~25 ~52 ~31 wool 7  
fill ~24 ~52 ~67 ~25 ~52 ~67 wool 7 
setblock ~24 ~52 ~72 fence 0  
fill ~25 ~52 ~22 ~26 ~52 ~22 wool 7  
fill ~25 ~52 ~23 ~26 ~52 ~23 wool 7 
setblock ~25 ~52 ~27 oak_stairs 1  
fill ~25 ~52 ~32 ~28 ~52 ~32 wool 7  
fill ~25 ~52 ~66 ~28 ~52 ~66 wool 7 
setblock ~25 ~52 ~72 oak_stairs 0  
fill ~25 ~52 ~75 ~26 ~52 ~75 wool 7  
fill ~25 ~52 ~76 ~26 ~52 ~76 wool 7 
setblock ~26 ~52 ~24 wool 7  
fill ~26 ~52 ~26 ~30 ~52 ~26 grass 0 
setblock ~26 ~52 ~27 fence 0 
setblock ~26 ~52 ~31 log 2 
setblock ~26 ~52 ~67 log 2  
fill ~26 ~52 ~72 ~30 ~52 ~72 grass 0 
setblock ~26 ~52 ~74 wool 7  
fill ~27 ~52 ~23 ~28 ~52 ~23 glass 0  
fill ~27 ~52 ~24 ~29 ~52 ~24 glass 0 
setblock ~27 ~52 ~27 oak_stairs 0 
setblock ~27 ~52 ~70 oak_stairs 1  
fill ~27 ~52 ~74 ~29 ~52 ~74 glass 0  
fill ~27 ~52 ~75 ~28 ~52 ~75 glass 0  
fill ~28 ~52 ~25 ~29 ~52 ~25 glass 0  
fill ~28 ~52 ~27 ~31 ~52 ~27 grass 0  
fill ~28 ~52 ~33 ~29 ~52 ~33 wool 7  
fill ~28 ~52 ~65 ~29 ~52 ~65 wool 7 
setblock ~28 ~52 ~70 fence 0  
fill ~28 ~52 ~71 ~31 ~52 ~71 grass 0  
fill ~28 ~52 ~73 ~29 ~52 ~73 glass 0 
setblock ~29 ~52 ~29 oak_stairs 1  
fill ~29 ~52 ~34 ~31 ~52 ~34 wool 7  
fill ~29 ~52 ~64 ~31 ~52 ~64 wool 7 
setblock ~29 ~52 ~70 oak_stairs 0  
fill ~30 ~52 ~24 ~31 ~52 ~24 wool 7  
fill ~30 ~52 ~25 ~31 ~52 ~25 wool 7 
setblock ~30 ~52 ~29 fence 0 
setblock ~30 ~52 ~33 log 2 
setblock ~30 ~52 ~65 log 2  
fill ~30 ~52 ~73 ~31 ~52 ~73 wool 7  
fill ~30 ~52 ~74 ~31 ~52 ~74 wool 7  
fill ~31 ~52 ~26 ~33 ~52 ~26 glass 0  
fill ~31 ~52 ~28 ~33 ~52 ~28 grass 0 
setblock ~31 ~52 ~29 oak_stairs 0  
fill ~31 ~52 ~35 ~32 ~52 ~35 glass 0  
fill ~31 ~52 ~63 ~32 ~52 ~63 glass 0 
setblock ~31 ~52 ~68 oak_stairs 1  
fill ~31 ~52 ~70 ~33 ~52 ~70 grass 0  
fill ~31 ~52 ~72 ~33 ~52 ~72 glass 0 
setblock ~32 ~52 ~25 glass 0  
fill ~32 ~52 ~27 ~33 ~52 ~27 glass 0  
fill ~32 ~52 ~29 ~34 ~52 ~29 grass 0  
fill ~32 ~52 ~36 ~32 ~53 ~36 glass 0  
fill ~32 ~52 ~62 ~32 ~53 ~62 glass 0 
setblock ~32 ~52 ~68 fence 0  
fill ~32 ~52 ~69 ~34 ~52 ~69 grass 0  
fill ~32 ~52 ~71 ~33 ~52 ~71 glass 0 
setblock ~32 ~52 ~73 glass 0  
fill ~33 ~52 ~36 ~33 ~52 ~38 wool 7  
fill ~33 ~52 ~60 ~34 ~52 ~60 wool 7  
fill ~33 ~52 ~61 ~33 ~53 ~61 wool 7  
fill ~33 ~52 ~62 ~33 ~52 ~60 wool 7 
setblock ~33 ~52 ~68 oak_stairs 0  
fill ~34 ~52 ~26 ~34 ~52 ~28 wool 7  
fill ~34 ~52 ~30 ~35 ~52 ~30 grass 0 
setblock ~34 ~52 ~37 log 2  
fill ~34 ~52 ~38 ~34 ~52 ~39 wool 7  
fill ~34 ~52 ~48 ~34 ~52 ~50 double_stone_slab 0  
fill ~34 ~52 ~59 ~35 ~52 ~59 wool 7 
setblock ~34 ~52 ~61 log 2  
fill ~34 ~52 ~68 ~35 ~52 ~68 grass 0  
fill ~34 ~52 ~70 ~36 ~52 ~70 wool 7  
fill ~34 ~52 ~71 ~35 ~52 ~71 wool 7  
fill ~34 ~52 ~72 ~34 ~52 ~70 wool 7  
fill ~35 ~52 ~27 ~35 ~52 ~29 wool 7  
fill ~35 ~52 ~31 ~36 ~52 ~31 grass 0  
fill ~35 ~52 ~39 ~35 ~52 ~42 wool 7  
fill ~35 ~52 ~47 ~35 ~55 ~47 double_stone_slab 0  
fill ~35 ~52 ~48 ~35 ~52 ~50 stone_brick_stairs 1  
fill ~35 ~52 ~51 ~35 ~54 ~51 double_stone_slab 0  
fill ~35 ~52 ~56 ~36 ~52 ~56 wool 7  
fill ~35 ~52 ~57 ~35 ~53 ~57 wool 7  
fill ~35 ~52 ~58 ~35 ~53 ~58 wool 7  
fill ~35 ~52 ~67 ~36 ~52 ~67 grass 0  
fill ~35 ~52 ~69 ~36 ~52 ~69 wool 7  
fill ~36 ~52 ~28 ~36 ~52 ~29 wool 7  
fill ~36 ~52 ~30 ~37 ~52 ~30 glass 0  
fill ~36 ~52 ~32 ~37 ~52 ~32 grass 0 
setblock ~36 ~52 ~41 log 2  
fill ~36 ~52 ~42 ~36 ~52 ~43 wool 7  
fill ~36 ~52 ~44 ~36 ~53 ~44 glass 0  
fill ~36 ~52 ~45 ~36 ~53 ~45 wool 7  
fill ~36 ~52 ~46 ~36 ~53 ~46 wool 7  
fill ~36 ~52 ~47 ~36 ~53 ~47 wool 7  
fill ~36 ~52 ~51 ~36 ~53 ~51 wool 7  
fill ~36 ~52 ~52 ~36 ~53 ~52 wool 7  
fill ~36 ~52 ~53 ~36 ~53 ~53 wool 7  
fill ~36 ~52 ~54 ~36 ~53 ~54 glass 0  
fill ~36 ~52 ~55 ~36 ~53 ~55 wool 7 
setblock ~36 ~52 ~57 log 2  
fill ~36 ~52 ~66 ~37 ~52 ~66 grass 0  
fill ~36 ~52 ~68 ~37 ~52 ~68 glass 0 
setblock ~37 ~52 ~31 glass 0  
fill ~37 ~52 ~33 ~38 ~52 ~33 grass 0 
setblock ~37 ~52 ~34 oak_stairs 3 
setblock ~37 ~52 ~35 fence 0 
setblock ~37 ~52 ~36 oak_stairs 2 
setblock ~37 ~52 ~47 log 2 
setblock ~37 ~52 ~51 log 2 
setblock ~37 ~52 ~62 oak_stairs 3 
setblock ~37 ~52 ~63 fence 0 
setblock ~37 ~52 ~64 oak_stairs 2  
fill ~37 ~52 ~65 ~38 ~52 ~65 grass 0 
setblock ~37 ~52 ~67 glass 0  
fill ~38 ~52 ~31 ~39 ~52 ~31 wool 7  
fill ~38 ~52 ~32 ~40 ~52 ~32 wool 7  
fill ~38 ~52 ~34 ~39 ~52 ~34 grass 0  
fill ~38 ~52 ~35 ~39 ~52 ~35 grass 0  
fill ~38 ~52 ~63 ~39 ~52 ~63 grass 0  
fill ~38 ~52 ~64 ~39 ~52 ~64 grass 0  
fill ~38 ~52 ~66 ~40 ~52 ~66 wool 7  
fill ~38 ~52 ~67 ~39 ~52 ~67 wool 7  
fill ~39 ~52 ~33 ~41 ~52 ~33 wool 7  
fill ~39 ~52 ~36 ~40 ~52 ~36 grass 0  
fill ~39 ~52 ~62 ~40 ~52 ~62 grass 0  
fill ~39 ~52 ~65 ~41 ~52 ~65 wool 7  
fill ~40 ~52 ~34 ~41 ~52 ~34 glass 0  
fill ~40 ~52 ~35 ~42 ~52 ~35 glass 0  
fill ~40 ~52 ~37 ~41 ~52 ~37 grass 0  
fill ~40 ~52 ~38 ~41 ~52 ~38 grass 0  
fill ~40 ~52 ~39 ~41 ~52 ~39 grass 0 
setblock ~40 ~52 ~40 oak_stairs 3 
setblock ~40 ~52 ~41 fence 0 
setblock ~40 ~52 ~42 oak_stairs 2  
fill ~40 ~52 ~48 ~41 ~52 ~48 fence 0  
fill ~40 ~52 ~49 ~40 ~52 ~50 fence 0 
setblock ~40 ~52 ~56 oak_stairs 3 
setblock ~40 ~52 ~57 fence 0 
setblock ~40 ~52 ~58 oak_stairs 2  
fill ~40 ~52 ~59 ~41 ~52 ~59 grass 0  
fill ~40 ~52 ~60 ~41 ~52 ~60 grass 0  
fill ~40 ~52 ~61 ~41 ~52 ~61 grass 0  
fill ~40 ~52 ~63 ~42 ~52 ~63 glass 0  
fill ~40 ~52 ~64 ~41 ~52 ~64 glass 0 
setblock ~41 ~52 ~36 glass 0  
fill ~41 ~52 ~40 ~42 ~52 ~40 grass 0  
fill ~41 ~52 ~41 ~42 ~52 ~41 grass 0  
fill ~41 ~52 ~57 ~42 ~52 ~57 grass 0  
fill ~41 ~52 ~58 ~42 ~52 ~58 grass 0 
setblock ~41 ~52 ~62 glass 0  
fill ~42 ~52 ~36 ~43 ~52 ~36 wool 7  
fill ~42 ~52 ~37 ~43 ~52 ~37 wool 7  
fill ~42 ~52 ~38 ~43 ~52 ~38 glass 0  
fill ~42 ~52 ~39 ~44 ~52 ~39 glass 0  
fill ~42 ~52 ~42 ~43 ~52 ~42 grass 0  
fill ~42 ~52 ~43 ~43 ~52 ~43 grass 0  
fill ~42 ~52 ~44 ~43 ~52 ~44 grass 0  
fill ~42 ~52 ~45 ~43 ~52 ~45 grass 0  
fill ~42 ~52 ~46 ~43 ~52 ~46 grass 0  
fill ~42 ~52 ~47 ~43 ~52 ~47 grass 0  
fill ~42 ~52 ~48 ~43 ~52 ~48 grass 0  
fill ~42 ~52 ~49 ~43 ~52 ~49 grass 0  
fill ~42 ~52 ~50 ~43 ~52 ~50 grass 0  
fill ~42 ~52 ~51 ~43 ~52 ~51 grass 0  
fill ~42 ~52 ~52 ~43 ~52 ~52 grass 0  
fill ~42 ~52 ~53 ~43 ~52 ~53 grass 0  
fill ~42 ~52 ~54 ~43 ~52 ~54 grass 0  
fill ~42 ~52 ~55 ~43 ~52 ~55 grass 0  
fill ~42 ~52 ~56 ~43 ~52 ~56 grass 0  
fill ~42 ~52 ~59 ~44 ~52 ~59 glass 0  
fill ~42 ~52 ~60 ~43 ~52 ~60 glass 0  
fill ~42 ~52 ~61 ~43 ~52 ~61 wool 7  
fill ~42 ~52 ~62 ~43 ~52 ~62 wool 7  
fill ~43 ~52 ~40 ~45 ~52 ~40 glass 0  
fill ~43 ~52 ~41 ~45 ~52 ~41 wool 7  
fill ~43 ~52 ~57 ~45 ~52 ~57 wool 7  
fill ~43 ~52 ~58 ~44 ~52 ~58 glass 0  
fill ~44 ~52 ~42 ~45 ~52 ~42 wool 7  
fill ~44 ~52 ~43 ~45 ~52 ~43 glass 0  
fill ~44 ~52 ~44 ~45 ~52 ~44 glass 0   
fill ~44 ~52 ~45 ~45 ~52 ~45 glass 0  
fill ~44 ~52 ~46 ~45 ~52 ~46 wool 7  
fill ~44 ~52 ~47 ~45 ~52 ~47 wool 7  
fill ~44 ~52 ~48 ~45 ~52 ~48 glass 0  
fill ~44 ~52 ~49 ~45 ~52 ~49 glass 0  
fill ~44 ~52 ~50 ~45 ~52 ~50 glass 0  
fill ~44 ~52 ~51 ~45 ~52 ~51 wool 7  
fill ~44 ~52 ~52 ~45 ~52 ~52 wool 7  
fill ~44 ~52 ~53 ~45 ~52 ~53 glass 0  
fill ~44 ~52 ~54 ~45 ~52 ~54 glass 0  
fill ~44 ~52 ~55 ~45 ~52 ~55 glass 0  
fill ~44 ~52 ~56 ~45 ~52 ~56 wool 7  
fill ~-11 ~53 ~40 ~-9 ~53 ~40 glass 0  
fill ~-11 ~53 ~41 ~-10 ~53 ~41 wool 7  
fill ~-11 ~53 ~42 ~-10 ~53 ~42 wool 7  
fill ~-11 ~53 ~43 ~-10 ~53 ~43 glass 0  
fill ~-11 ~53 ~44 ~-10 ~53 ~44 glass 0  
fill ~-11 ~53 ~45 ~-10 ~53 ~45 glass 0  
fill ~-11 ~53 ~46 ~-10 ~53 ~46 wool 7  
fill ~-11 ~53 ~47 ~-10 ~53 ~47 wool 7  
fill ~-11 ~53 ~48 ~-10 ~53 ~48 glass 0  
fill ~-11 ~53 ~49 ~-10 ~53 ~49 glass 0  
fill ~-11 ~53 ~50 ~-10 ~53 ~50 glass 0  
fill ~-11 ~53 ~51 ~-10 ~53 ~51 wool 7  
fill ~-11 ~53 ~52 ~-10 ~53 ~52 wool 7  
fill ~-11 ~53 ~53 ~-10 ~53 ~53 glass 0  
fill ~-11 ~53 ~54 ~-10 ~53 ~54 glass 0  
fill ~-11 ~53 ~55 ~-10 ~53 ~55 glass 0  
fill ~-11 ~53 ~56 ~-10 ~53 ~56 wool 7  
fill ~-11 ~53 ~57 ~-10 ~53 ~57 wool 7  
fill ~-11 ~53 ~58 ~-9 ~53 ~58 glass 0  
fill ~-10 ~53 ~38 ~-8 ~53 ~38 glass 0  
fill ~-10 ~53 ~39 ~-8 ~53 ~39 glass 0  
fill ~-10 ~53 ~59 ~-8 ~53 ~59 glass 0  
fill ~-10 ~53 ~60 ~-8 ~53 ~60 glass 0  
fill ~-9 ~53 ~35 ~-7 ~53 ~35 glass 0  
fill ~-9 ~53 ~36 ~-8 ~53 ~36 wool 7  
fill ~-9 ~53 ~37 ~-8 ~53 ~37 wool 7  
fill ~-9 ~53 ~61 ~-8 ~53 ~61 wool 7  
fill ~-9 ~53 ~62 ~-8 ~53 ~62 wool 7  
fill ~-9 ~53 ~63 ~-7 ~53 ~63 glass 0  
fill ~-8 ~53 ~34 ~-6 ~53 ~34 glass 0  
fill ~-8 ~53 ~64 ~-6 ~53 ~64 glass 0  
fill ~-7 ~53 ~32 ~-5 ~53 ~32 wool 7  
fill ~-7 ~53 ~33 ~-6 ~53 ~33 glass 0 
setblock ~-7 ~53 ~51 red_flower 3  
fill ~-7 ~53 ~65 ~-6 ~53 ~65 glass 0  
fill ~-7 ~53 ~66 ~-5 ~53 ~66 wool 7  
fill ~-6 ~53 ~31 ~-4 ~53 ~31 wool 7 
setblock ~-6 ~53 ~47 red_flower 8  
fill ~-6 ~53 ~50 ~-4 ~53 ~50 fence 0  
fill ~-6 ~53 ~67 ~-4 ~53 ~67 wool 7  
fill ~-5 ~53 ~30 ~-3 ~53 ~30 wool 7 
setblock ~-5 ~53 ~39 red_flower 3 
setblock ~-5 ~53 ~61 red_flower 3  
fill ~-5 ~53 ~68 ~-3 ~53 ~68 wool 7 
setblock ~-4 ~53 ~29 wool 7 
setblock ~-4 ~53 ~38 red_flower 8 
setblock ~-4 ~53 ~41 wooden_pressure_plate 0  
fill ~-4 ~53 ~48 ~-4 ~53 ~49 carpet 3 
setblock ~-4 ~53 ~55 wooden_pressure_plate 0 
setblock ~-4 ~53 ~69 wool 7  
fill ~-3 ~53 ~28 ~-2 ~53 ~28 glass 0  
fill ~-3 ~53 ~29 ~-1 ~53 ~29 glass 0  
fill ~-3 ~53 ~34 ~-2 ~53 ~34 red_flower 8 
setblock ~-3 ~53 ~63 red_flower 0  
fill ~-3 ~53 ~69 ~-1 ~53 ~69 glass 0  
fill ~-3 ~53 ~70 ~-2 ~53 ~70 glass 0  
fill ~-2 ~53 ~27 ~0 ~53 ~27 wool 7 
setblock ~-2 ~53 ~30 glass 0 
setblock ~-2 ~53 ~37 wooden_pressure_plate 0 
setblock ~-2 ~53 ~47 leaves 6 
setblock ~-2 ~53 ~51 leaves 6 
setblock ~-2 ~53 ~60 wooden_pressure_plate 0 
setblock ~-2 ~53 ~68 glass 0  
fill ~-2 ~53 ~71 ~0 ~53 ~71 wool 7  
fill ~-1 ~53 ~26 ~1 ~53 ~26 wool 7 
setblock ~-1 ~53 ~28 wool 7 
setblock ~-1 ~53 ~70 wool 7  
fill ~-1 ~53 ~72 ~1 ~53 ~72 wool 7  
fill ~0 ~53 ~25 ~1 ~53 ~25 wool 7 
setblock ~0 ~53 ~32 red_flower 0 
setblock ~0 ~53 ~41 leaves 6 
setblock ~0 ~53 ~45 wool 7 
setblock ~0 ~53 ~53 wool 7 
setblock ~0 ~53 ~57 leaves 14  
fill ~0 ~53 ~73 ~1 ~53 ~73 wool 7 
setblock ~1 ~53 ~24 wool 7 
setblock ~1 ~53 ~42 wool 7  
fill ~1 ~53 ~47 ~1 ~56 ~47 double_stone_slab 0  
fill ~1 ~53 ~48 ~1 ~53 ~50 stone_brick_stairs 0  
fill ~1 ~53 ~51 ~1 ~56 ~51 double_stone_slab 0 
setblock ~1 ~53 ~56 wool 7 
setblock ~1 ~53 ~68 red_flower 0 
setblock ~1 ~53 ~74 wool 7  
fill ~2 ~53 ~24 ~4 ~53 ~24 glass 0  
fill ~2 ~53 ~25 ~3 ~53 ~25 glass 0 
setblock ~2 ~53 ~29 red_flower 8 
setblock ~2 ~53 ~37 leaves 6 
setblock ~2 ~53 ~39 wool 7  
fill ~2 ~53 ~48 ~2 ~53 ~50 double_stone_slab 0 
setblock ~2 ~53 ~59 wool 7 
setblock ~2 ~53 ~61 leaves 6 
setblock ~2 ~53 ~66 wooden_pressure_plate 0  
fill ~2 ~53 ~73 ~3 ~53 ~73 glass 0  
fill ~2 ~53 ~74 ~4 ~53 ~74 glass 0  
fill ~3 ~53 ~23 ~4 ~53 ~23 glass 0 
setblock ~3 ~53 ~28 red_flower 3  
fill ~3 ~53 ~37 ~3 ~53 ~38 wool 7 
setblock ~3 ~53 ~60 wool 7  
fill ~3 ~53 ~75 ~4 ~53 ~75 glass 0 
setblock ~4 ~53 ~22 glass 0 
setblock ~4 ~53 ~30 wooden_pressure_plate 0 
setblock ~4 ~53 ~76 glass 0  
fill ~5 ~53 ~22 ~6 ~53 ~22 wool 7  
fill ~5 ~53 ~23 ~6 ~53 ~23 wool 7 
setblock ~5 ~53 ~35 glass 0 
setblock ~5 ~53 ~63 glass 0 
setblock ~5 ~53 ~71 red_flower 8  
fill ~5 ~53 ~75 ~6 ~53 ~75 wool 7  
fill ~5 ~53 ~76 ~6 ~53 ~76 wool 7 
setblock ~6 ~53 ~33 leaves 6  
fill ~6 ~53 ~34 ~7 ~53 ~34 wool 7  
fill ~6 ~53 ~64 ~7 ~53 ~64 wool 7 
setblock ~6 ~53 ~65 leaves 14  
fill ~7 ~53 ~21 ~9 ~53 ~21 glass 0  
fill ~7 ~53 ~22 ~9 ~53 ~22 glass 0  
fill ~7 ~53 ~23 ~8 ~53 ~23 glass 0 
setblock ~7 ~53 ~27 yellow_flower 0 
setblock ~7 ~53 ~69 wooden_pressure_plate 0  
fill ~7 ~53 ~75 ~8 ~53 ~75 glass 0  
fill ~7 ~53 ~76 ~9 ~53 ~76 glass 0  
fill ~7 ~53 ~77 ~9 ~53 ~77 glass 0 
setblock ~8 ~53 ~26 yellow_flower 0 
setblock ~8 ~53 ~33 wool 7 
setblock ~8 ~53 ~65 wool 7 
setblock ~9 ~53 ~20 glass 0  
fill ~9 ~53 ~32 ~11 ~53 ~32 wool 7  
fill ~9 ~53 ~66 ~11 ~53 ~66 wool 7 
setblock ~9 ~53 ~73 red_flower 8 
setblock ~9 ~53 ~78 glass 0  
fill ~10 ~53 ~20 ~11 ~53 ~20 wool 7  
fill ~10 ~53 ~21 ~11 ~53 ~21 wool 7 
setblock ~10 ~53 ~27 wooden_pressure_plate 0 
setblock ~10 ~53 ~31 leaves 6 
setblock ~10 ~53 ~67 leaves 6  
fill ~10 ~53 ~77 ~11 ~53 ~77 wool 7  
fill ~10 ~53 ~78 ~11 ~53 ~78 wool 7 
setblock ~11 ~53 ~24 yellow_flower 0  
fill ~12 ~53 ~20 ~14 ~53 ~20 glass 0  
fill ~12 ~53 ~21 ~14 ~53 ~21 glass 0 
setblock ~12 ~53 ~31 wool 7 
setblock ~12 ~53 ~67 wool 7 
setblock ~12 ~53 ~72 wooden_pressure_plate 0  
fill ~12 ~53 ~77 ~14 ~53 ~77 glass 0  
fill ~12 ~53 ~78 ~14 ~53 ~78 glass 0 
setblock ~13 ~53 ~25 yellow_flower 0  
fill ~13 ~53 ~48 ~15 ~53 ~48 stained_hardened_clay 12  
fill ~13 ~53 ~50 ~15 ~53 ~50 stained_hardened_clay 12  
fill ~15 ~53 ~20 ~16 ~53 ~20 wool 7  
fill ~15 ~53 ~21 ~16 ~53 ~21 wool 7  
fill ~15 ~53 ~30 ~16 ~53 ~30 wool 7  
fill ~15 ~53 ~68 ~16 ~53 ~68 wool 7 
setblock ~15 ~53 ~74 red_flower 0  
fill ~15 ~53 ~77 ~16 ~53 ~77 wool 7  
fill ~15 ~53 ~78 ~16 ~53 ~78 wool 7 
setblock ~16 ~53 ~29 leaves 6  
fill ~16 ~53 ~32 ~16 ~56 ~32 double_stone_slab 0 
setblock ~16 ~53 ~48 glowstone 0 
setblock ~16 ~53 ~50 glowstone 0  
fill ~16 ~53 ~66 ~16 ~56 ~66 double_stone_slab 0 
setblock ~16 ~53 ~69 leaves 6  
fill ~17 ~53 ~20 ~19 ~53 ~20 glass 0  
fill ~17 ~53 ~21 ~19 ~53 ~21 glass 0  
fill ~17 ~53 ~25 ~17 ~54 ~25 fence 0  
fill ~17 ~53 ~27 ~17 ~54 ~27 fence 0  
fill ~17 ~53 ~32 ~19 ~53 ~32 stone_brick_stairs 2  
fill ~17 ~53 ~33 ~19 ~53 ~33 double_stone_slab 0 
setblock ~17 ~53 ~47 glowstone 0 
setblock ~17 ~53 ~51 glowstone 0  
fill ~17 ~53 ~65 ~19 ~53 ~65 double_stone_slab 0  
fill ~17 ~53 ~66 ~19 ~53 ~66 stone_brick_stairs 3  
fill ~17 ~53 ~71 ~18 ~53 ~71 carpet 3 
setblock ~17 ~53 ~74 red_flower 3  
fill ~17 ~53 ~77 ~19 ~53 ~77 glass 0  
fill ~17 ~53 ~78 ~19 ~53 ~78 glass 0  
fill ~18 ~53 ~27 ~19 ~53 ~27 carpet 3 
setblock ~19 ~53 ~47 glowstone 0 
setblock ~19 ~53 ~51 glowstone 0  
fill ~19 ~53 ~71 ~19 ~54 ~71 fence 0  
fill ~19 ~53 ~73 ~19 ~54 ~73 fence 0  
fill ~20 ~53 ~20 ~21 ~53 ~20 wool 7  
fill ~20 ~53 ~21 ~21 ~53 ~21 wool 7 
setblock ~20 ~53 ~29 leaves 6  
fill ~20 ~53 ~30 ~21 ~53 ~30 wool 7  
fill ~20 ~53 ~32 ~20 ~56 ~32 double_stone_slab 0 
setblock ~20 ~53 ~48 glowstone 0 
setblock ~20 ~53 ~50 glowstone 0  
fill ~20 ~53 ~66 ~20 ~56 ~66 double_stone_slab 0  
fill ~20 ~53 ~68 ~21 ~53 ~68 wool 7 
setblock ~20 ~53 ~69 leaves 6 
setblock ~20 ~53 ~74 red_flower 0  
fill ~20 ~53 ~77 ~21 ~53 ~77 wool 7  
fill ~20 ~53 ~78 ~21 ~53 ~78 wool 7 
setblock ~21 ~53 ~24 red_flower 3  
fill ~21 ~53 ~48 ~23 ~53 ~48 stained_hardened_clay 12  
fill ~21 ~53 ~50 ~23 ~53 ~50 stained_hardened_clay 12 
setblock ~21 ~53 ~73 red_flower 8 
setblock ~21 ~53 ~74 yellow_flower 0  
fill ~22 ~53 ~20 ~24 ~53 ~20 glass 0  
fill ~22 ~53 ~21 ~24 ~53 ~21 glass 0 
setblock ~22 ~53 ~25 yellow_flower 0  
fill ~22 ~53 ~77 ~24 ~53 ~77 glass 0  
fill ~22 ~53 ~78 ~24 ~53 ~78 glass 0 
setblock ~23 ~53 ~25 red_flower 0  
fill ~24 ~53 ~31 ~24 ~52 ~31 wool 7  
fill ~24 ~53 ~67 ~24 ~52 ~67 wool 7 
setblock ~24 ~53 ~72 wooden_pressure_plate 0  
fill ~25 ~53 ~20 ~26 ~53 ~20 wool 7  
fill ~25 ~53 ~21 ~26 ~53 ~21 wool 7 
setblock ~25 ~53 ~25 red_flower 8  
fill ~25 ~53 ~32 ~27 ~53 ~32 wool 7  
fill ~25 ~53 ~66 ~27 ~53 ~66 wool 7  
fill ~25 ~53 ~77 ~26 ~53 ~77 wool 7  
fill ~25 ~53 ~78 ~26 ~53 ~78 wool 7 
setblock ~26 ~53 ~27 wooden_pressure_plate 0 
setblock ~26 ~53 ~31 leaves 6 
setblock ~26 ~53 ~67 leaves 6 
setblock ~26 ~53 ~72 red_flower 0  
fill ~27 ~53 ~20 ~27 ~53 ~22 glass 0  
fill ~27 ~53 ~76 ~29 ~53 ~76 glass 0  
fill ~27 ~53 ~77 ~29 ~53 ~77 glass 0  
fill ~27 ~53 ~78 ~27 ~53 ~76 glass 0  
fill ~28 ~53 ~21 ~29 ~53 ~21 glass 0  
fill ~28 ~53 ~22 ~29 ~53 ~22 glass 0  
fill ~28 ~53 ~23 ~29 ~53 ~23 glass 0 
setblock ~28 ~53 ~26 yellow_flower 0  
fill ~28 ~53 ~33 ~28 ~52 ~33 wool 7  
fill ~28 ~53 ~65 ~28 ~52 ~65 wool 7 
setblock ~28 ~53 ~70 wooden_pressure_plate 0  
fill ~28 ~53 ~75 ~29 ~53 ~75 glass 0  
fill ~29 ~53 ~34 ~30 ~53 ~34 wool 7  
fill ~29 ~53 ~64 ~30 ~53 ~64 wool 7  
fill ~30 ~53 ~22 ~31 ~53 ~22 wool 7  
fill ~30 ~53 ~23 ~31 ~53 ~23 wool 7 
setblock ~30 ~53 ~29 wooden_pressure_plate 0 
setblock ~30 ~53 ~33 leaves 6 
setblock ~30 ~53 ~65 leaves 6  
fill ~30 ~53 ~75 ~31 ~53 ~75 wool 7  
fill ~30 ~53 ~76 ~31 ~53 ~76 wool 7  
fill ~31 ~53 ~35 ~31 ~52 ~35 glass 0  
fill ~31 ~53 ~63 ~31 ~52 ~63 glass 0  
fill ~32 ~53 ~22 ~32 ~53 ~24 glass 0  
fill ~32 ~53 ~29 ~33 ~53 ~29 yellow_flower 0 
setblock ~32 ~53 ~68 wooden_pressure_plate 0  
fill ~32 ~53 ~74 ~34 ~53 ~74 glass 0  
fill ~32 ~53 ~75 ~33 ~53 ~75 glass 0  
fill ~32 ~53 ~76 ~32 ~53 ~74 glass 0  
fill ~33 ~53 ~23 ~33 ~53 ~25 glass 0  
fill ~33 ~53 ~37 ~33 ~53 ~38 wool 7  
fill ~33 ~53 ~48 ~33 ~53 ~50 double_stone_slab 0 
setblock ~33 ~53 ~60 wool 7  
fill ~33 ~53 ~73 ~34 ~53 ~73 glass 0  
fill ~34 ~53 ~24 ~34 ~53 ~25 glass 0 
setblock ~34 ~53 ~29 red_flower 3 
setblock ~34 ~53 ~37 leaves 6 
setblock ~34 ~53 ~39 wool 7  
fill ~34 ~53 ~47 ~34 ~56 ~47 double_stone_slab 0  
fill ~34 ~53 ~48 ~34 ~53 ~50 stone_brick_stairs 1  
fill ~34 ~53 ~51 ~34 ~56 ~51 double_stone_slab 0  
fill ~34 ~53 ~59 ~34 ~52 ~59 wool 7 
setblock ~34 ~53 ~61 leaves 6  
fill ~35 ~53 ~24 ~35 ~53 ~26 wool 7  
fill ~35 ~53 ~40 ~35 ~53 ~42 wool 7  
fill ~35 ~53 ~56 ~35 ~52 ~56 wool 7  
fill ~35 ~53 ~72 ~37 ~53 ~72 wool 7  
fill ~35 ~53 ~73 ~36 ~53 ~73 wool 7  
fill ~35 ~53 ~74 ~35 ~53 ~72 wool 7  
fill ~36 ~53 ~25 ~36 ~53 ~27 wool 7 
setblock ~36 ~53 ~41 leaves 14 
setblock ~36 ~53 ~43 wool 7 
setblock ~36 ~53 ~57 leaves 6 
setblock ~36 ~53 ~66 yellow_flower 0  
fill ~36 ~53 ~71 ~38 ~53 ~71 wool 7  
fill ~37 ~53 ~26 ~37 ~53 ~28 wool 7  
fill ~37 ~53 ~29 ~39 ~53 ~29 glass 0 
setblock ~37 ~53 ~35 wooden_pressure_plate 0 
setblock ~37 ~53 ~47 leaves 6 
setblock ~37 ~53 ~51 leaves 6 
setblock ~37 ~53 ~63 wooden_pressure_plate 0 
setblock ~37 ~53 ~66 red_flower 3  
fill ~37 ~53 ~69 ~39 ~53 ~69 glass 0 
setblock ~37 ~53 ~70 wool 7 
setblock ~38 ~53 ~27 wool 7  
fill ~38 ~53 ~28 ~39 ~53 ~28 glass 0 
setblock ~38 ~53 ~30 glass 0 
setblock ~38 ~53 ~68 glass 0  
fill ~38 ~53 ~70 ~39 ~53 ~70 glass 0  
fill ~39 ~53 ~30 ~41 ~53 ~30 wool 7 
setblock ~39 ~53 ~62 yellow_flower 0  
fill ~39 ~53 ~68 ~41 ~53 ~68 wool 7 
setblock ~40 ~53 ~29 wool 7  
fill ~40 ~53 ~31 ~42 ~53 ~31 wool 7 
setblock ~40 ~53 ~36 yellow_flower 0 
setblock ~40 ~53 ~41 wooden_pressure_plate 0  
fill ~40 ~53 ~48 ~42 ~53 ~48 fence 0  
fill ~40 ~53 ~49 ~40 ~53 ~50 carpet 3 
setblock ~40 ~53 ~57 wooden_pressure_plate 0 
setblock ~40 ~53 ~61 red_flower 0  
fill ~40 ~53 ~67 ~42 ~53 ~67 wool 7 
setblock ~40 ~53 ~69 wool 7  
fill ~41 ~53 ~32 ~43 ~53 ~32 wool 7 
setblock ~41 ~53 ~59 red_flower 0  
fill ~41 ~53 ~66 ~43 ~53 ~66 wool 7  
fill ~42 ~53 ~33 ~43 ~53 ~33 glass 0  
fill ~42 ~53 ~34 ~44 ~53 ~34 glass 0 
setblock ~42 ~53 ~44 red_flower 8 
setblock ~42 ~53 ~52 yellow_flower 0  
fill ~42 ~53 ~64 ~44 ~53 ~64 glass 0  
fill ~42 ~53 ~65 ~43 ~53 ~65 glass 0  
fill ~43 ~53 ~35 ~44 ~53 ~35 glass 0 
setblock ~43 ~53 ~53 red_flower 0 
setblock ~43 ~53 ~54 yellow_flower 0  
fill ~43 ~53 ~63 ~45 ~53 ~63 glass 0  
fill ~44 ~53 ~36 ~45 ~53 ~36 wool 7  
fill ~44 ~53 ~37 ~45 ~53 ~37 wool 7  
fill ~44 ~53 ~38 ~46 ~53 ~38 glass 0  
fill ~44 ~53 ~39 ~46 ~53 ~39 glass 0  
fill ~44 ~53 ~59 ~46 ~53 ~59 glass 0  
fill ~44 ~53 ~60 ~46 ~53 ~60 glass 0  
fill ~44 ~53 ~61 ~45 ~53 ~61 wool 7  
fill ~44 ~53 ~62 ~45 ~53 ~62 wool 7 
setblock ~45 ~53 ~35 wool 7  
fill ~45 ~53 ~58 ~47 ~53 ~58 glass 0  
fill ~46 ~53 ~40 ~47 ~53 ~40 glass 0  
fill ~46 ~53 ~41 ~47 ~53 ~41 wool 7  
fill ~46 ~53 ~42 ~47 ~53 ~42 wool 7  
fill ~46 ~53 ~43 ~47 ~53 ~43 glass 0  
fill ~46 ~53 ~44 ~47 ~53 ~44 glass 0  
fill ~46 ~53 ~45 ~47 ~53 ~45 glass 0  
fill ~46 ~53 ~46 ~47 ~53 ~46 wool 7  
fill ~46 ~53 ~47 ~47 ~53 ~47 wool 7  
fill ~46 ~53 ~48 ~47 ~53 ~48 glass 0  
fill ~46 ~53 ~49 ~47 ~53 ~49 glass 0  
fill ~46 ~53 ~50 ~47 ~53 ~50 glass 0  
fill ~46 ~53 ~51 ~47 ~53 ~51 wool 7  
fill ~46 ~53 ~52 ~47 ~53 ~52 wool 7  
fill ~46 ~53 ~53 ~47 ~53 ~53 glass 0  
fill ~46 ~53 ~54 ~47 ~53 ~54 glass 0  
fill ~46 ~53 ~55 ~47 ~53 ~55 glass 0  
fill ~46 ~53 ~56 ~47 ~53 ~56 wool 7  
fill ~46 ~53 ~57 ~47 ~53 ~57 wool 7  
fill ~-13 ~54 ~39 ~-11 ~54 ~39 double_stone_slab 0  
fill ~-13 ~54 ~40 ~-12 ~54 ~40 double_stone_slab 0  
fill ~-13 ~54 ~41 ~-12 ~54 ~41 double_stone_slab 0  
fill ~-13 ~54 ~42 ~-12 ~54 ~42 double_stone_slab 0  
fill ~-13 ~54 ~43 ~-12 ~54 ~43 double_stone_slab 0  
fill ~-13 ~54 ~44 ~-12 ~54 ~44 double_stone_slab 0  
fill ~-13 ~54 ~45 ~-12 ~54 ~45 double_stone_slab 0  
fill ~-13 ~54 ~46 ~-12 ~54 ~46 double_stone_slab 0  
fill ~-13 ~54 ~47 ~-12 ~54 ~47 double_stone_slab 0  
fill ~-13 ~54 ~48 ~-12 ~54 ~48 double_stone_slab 0  
fill ~-13 ~54 ~49 ~-12 ~54 ~49 double_stone_slab 0  
fill ~-13 ~54 ~50 ~-12 ~54 ~50 double_stone_slab 0  
fill ~-13 ~54 ~51 ~-12 ~54 ~51 double_stone_slab 0  
fill ~-13 ~54 ~52 ~-12 ~54 ~52 double_stone_slab 0  
fill ~-13 ~54 ~53 ~-12 ~54 ~53 double_stone_slab 0  
fill ~-13 ~54 ~54 ~-12 ~54 ~54 double_stone_slab 0  
fill ~-13 ~54 ~55 ~-12 ~54 ~55 double_stone_slab 0  
fill ~-13 ~54 ~56 ~-12 ~54 ~56 double_stone_slab 0  
fill ~-13 ~54 ~57 ~-12 ~54 ~57 double_stone_slab 0  
fill ~-13 ~54 ~58 ~-12 ~54 ~58 double_stone_slab 0  
fill ~-13 ~54 ~59 ~-11 ~54 ~59 double_stone_slab 0  
fill ~-12 ~54 ~36 ~-10 ~54 ~36 double_stone_slab 0  
fill ~-12 ~54 ~37 ~-10 ~54 ~37 double_stone_slab 0  
fill ~-12 ~54 ~38 ~-11 ~54 ~38 double_stone_slab 0  
fill ~-12 ~54 ~60 ~-11 ~54 ~60 double_stone_slab 0  
fill ~-12 ~54 ~61 ~-10 ~54 ~61 double_stone_slab 0  
fill ~-12 ~54 ~62 ~-10 ~54 ~62 double_stone_slab 0  
fill ~-11 ~54 ~34 ~-9 ~54 ~34 double_stone_slab 0  
fill ~-11 ~54 ~35 ~-10 ~54 ~35 double_stone_slab 0  
fill ~-11 ~54 ~63 ~-10 ~54 ~63 double_stone_slab 0  
fill ~-11 ~54 ~64 ~-9 ~54 ~64 double_stone_slab 0  
fill ~-10 ~54 ~32 ~-8 ~54 ~32 double_stone_slab 0  
fill ~-10 ~54 ~33 ~-8 ~54 ~33 double_stone_slab 0  
fill ~-10 ~54 ~65 ~-8 ~54 ~65 double_stone_slab 0  
fill ~-10 ~54 ~66 ~-8 ~54 ~66 double_stone_slab 0  
fill ~-9 ~54 ~31 ~-7 ~54 ~31 double_stone_slab 0  
fill ~-9 ~54 ~67 ~-7 ~54 ~67 double_stone_slab 0  
fill ~-8 ~54 ~30 ~-6 ~54 ~30 double_stone_slab 0  
fill ~-8 ~54 ~68 ~-6 ~54 ~68 double_stone_slab 0  
fill ~-7 ~54 ~29 ~-5 ~54 ~29 double_stone_slab 0  
fill ~-7 ~54 ~69 ~-5 ~54 ~69 double_stone_slab 0  
fill ~-6 ~54 ~28 ~-4 ~54 ~28 double_stone_slab 0  
fill ~-6 ~54 ~50 ~-4 ~54 ~50 fence 0  
fill ~-6 ~54 ~70 ~-4 ~54 ~70 double_stone_slab 0  
fill ~-5 ~54 ~27 ~-3 ~54 ~27 double_stone_slab 0  
fill ~-5 ~54 ~71 ~-3 ~54 ~71 double_stone_slab 0  
fill ~-4 ~54 ~26 ~-2 ~54 ~26 double_stone_slab 0  
fill ~-4 ~54 ~48 ~-4 ~54 ~50 fence 0  
fill ~-4 ~54 ~72 ~-2 ~54 ~72 double_stone_slab 0  
fill ~-3 ~54 ~25 ~-1 ~54 ~25 double_stone_slab 0  
fill ~-3 ~54 ~73 ~-1 ~54 ~73 double_stone_slab 0  
fill ~-2 ~54 ~24 ~0 ~54 ~24 double_stone_slab 0  
fill ~-2 ~54 ~74 ~0 ~54 ~74 double_stone_slab 0  
fill ~-1 ~54 ~23 ~2 ~54 ~23 double_stone_slab 0  
fill ~-1 ~54 ~46 ~-1 ~54 ~47 double_stone_slab 0  
fill ~-1 ~54 ~51 ~-1 ~54 ~52 double_stone_slab 0  
fill ~-1 ~54 ~75 ~2 ~54 ~75 double_stone_slab 0  
fill ~0 ~54 ~22 ~3 ~54 ~22 double_stone_slab 0  
fill ~0 ~54 ~43 ~0 ~54 ~45 double_stone_slab 0  
fill ~0 ~54 ~53 ~0 ~54 ~55 double_stone_slab 0  
fill ~0 ~54 ~76 ~3 ~54 ~76 double_stone_slab 0  
fill ~1 ~54 ~21 ~6 ~54 ~21 double_stone_slab 0  
fill ~1 ~54 ~40 ~1 ~54 ~42 double_stone_slab 0  
fill ~1 ~54 ~56 ~1 ~54 ~58 double_stone_slab 0  
fill ~1 ~54 ~77 ~6 ~54 ~77 double_stone_slab 0 
setblock ~2 ~54 ~39 double_stone_slab 0  
fill ~2 ~54 ~47 ~2 ~57 ~47 double_stone_slab 0  
fill ~2 ~54 ~48 ~2 ~54 ~50 stone_brick_stairs 0  
fill ~2 ~54 ~51 ~2 ~57 ~51 double_stone_slab 0 
setblock ~2 ~54 ~59 double_stone_slab 0  
fill ~3 ~54 ~20 ~8 ~54 ~20 double_stone_slab 0  
fill ~3 ~54 ~37 ~3 ~54 ~38 double_stone_slab 0  
fill ~3 ~54 ~48 ~3 ~54 ~50 double_stone_slab 0  
fill ~3 ~54 ~60 ~3 ~54 ~61 double_stone_slab 0  
fill ~3 ~54 ~78 ~8 ~54 ~78 double_stone_slab 0 
setblock ~4 ~54 ~36 double_stone_slab 0 
setblock ~4 ~54 ~62 double_stone_slab 0  
fill ~5 ~54 ~19 ~31 ~54 ~19 double_stone_slab 0 
setblock ~5 ~54 ~35 double_stone_slab 0 
setblock ~5 ~54 ~63 double_stone_slab 0  
fill ~5 ~54 ~79 ~31 ~54 ~79 double_stone_slab 0  
fill ~6 ~54 ~34 ~7 ~54 ~34 double_stone_slab 0  
fill ~6 ~54 ~64 ~7 ~54 ~64 double_stone_slab 0  
fill ~8 ~54 ~18 ~28 ~54 ~18 double_stone_slab 0 
setblock ~8 ~54 ~33 double_stone_slab 0 
setblock ~8 ~54 ~65 double_stone_slab 0  
fill ~8 ~54 ~80 ~28 ~54 ~80 double_stone_slab 0  
fill ~9 ~54 ~32 ~11 ~54 ~32 double_stone_slab 0  
fill ~9 ~54 ~66 ~11 ~54 ~66 double_stone_slab 0  
fill ~12 ~54 ~31 ~14 ~54 ~31 double_stone_slab 0  
fill ~12 ~54 ~67 ~14 ~54 ~67 double_stone_slab 0  
fill ~13 ~54 ~48 ~15 ~54 ~48 stained_hardened_clay 12  
fill ~13 ~54 ~50 ~15 ~54 ~50 stained_hardened_clay 12  
fill ~15 ~54 ~30 ~16 ~54 ~30 double_stone_slab 0  
fill ~15 ~54 ~68 ~16 ~54 ~68 double_stone_slab 0  
fill ~16 ~54 ~33 ~16 ~57 ~33 double_stone_slab 0 
setblock ~16 ~54 ~48 double_stone_slab 0 
setblock ~16 ~54 ~50 double_stone_slab 0  
fill ~16 ~54 ~65 ~16 ~57 ~65 double_stone_slab 0  
fill ~17 ~54 ~33 ~19 ~54 ~33 stone_brick_stairs 2  
fill ~17 ~54 ~34 ~19 ~54 ~34 double_stone_slab 0 
setblock ~17 ~54 ~47 double_stone_slab 0 
setblock ~17 ~54 ~51 double_stone_slab 0  
fill ~17 ~54 ~64 ~19 ~54 ~64 double_stone_slab 0  
fill ~17 ~54 ~65 ~19 ~54 ~65 stone_brick_stairs 3  
fill ~17 ~54 ~71 ~19 ~54 ~71 fence 0  
fill ~18 ~54 ~27 ~19 ~54 ~27 fence 0 
setblock ~19 ~54 ~47 double_stone_slab 0 
setblock ~19 ~54 ~51 double_stone_slab 0  
fill ~20 ~54 ~30 ~21 ~54 ~30 double_stone_slab 0  
fill ~20 ~54 ~33 ~20 ~57 ~33 double_stone_slab 0 
setblock ~20 ~54 ~48 double_stone_slab 0 
setblock ~20 ~54 ~50 double_stone_slab 0  
fill ~20 ~54 ~65 ~20 ~57 ~65 double_stone_slab 0  
fill ~20 ~54 ~68 ~21 ~54 ~68 double_stone_slab 0  
fill ~21 ~54 ~48 ~23 ~54 ~48 stained_hardened_clay 12  
fill ~21 ~54 ~50 ~23 ~54 ~50 stained_hardened_clay 12  
fill ~22 ~54 ~31 ~24 ~54 ~31 double_stone_slab 0  
fill ~22 ~54 ~67 ~24 ~54 ~67 double_stone_slab 0  
fill ~25 ~54 ~32 ~27 ~54 ~32 double_stone_slab 0  
fill ~25 ~54 ~66 ~27 ~54 ~66 double_stone_slab 0  
fill ~28 ~54 ~20 ~33 ~54 ~20 double_stone_slab 0 
setblock ~28 ~54 ~33 double_stone_slab 0 
setblock ~28 ~54 ~65 double_stone_slab 0  
fill ~28 ~54 ~78 ~33 ~54 ~78 double_stone_slab 0  
fill ~29 ~54 ~34 ~30 ~54 ~34 double_stone_slab 0  
fill ~29 ~54 ~64 ~30 ~54 ~64 double_stone_slab 0  
fill ~30 ~54 ~21 ~35 ~54 ~21 double_stone_slab 0  
fill ~30 ~54 ~77 ~35 ~54 ~77 double_stone_slab 0 
setblock ~31 ~54 ~35 double_stone_slab 0 
setblock ~31 ~54 ~63 double_stone_slab 0 
setblock ~32 ~54 ~36 double_stone_slab 0  
fill ~32 ~54 ~48 ~32 ~54 ~50 double_stone_slab 0 
setblock ~32 ~54 ~62 double_stone_slab 0  
fill ~33 ~54 ~22 ~36 ~54 ~22 double_stone_slab 0  
fill ~33 ~54 ~37 ~33 ~54 ~38 double_stone_slab 0  
fill ~33 ~54 ~47 ~33 ~57 ~47 double_stone_slab 0  
fill ~33 ~54 ~48 ~33 ~54 ~50 stone_brick_stairs 1  
fill ~33 ~54 ~51 ~33 ~57 ~51 double_stone_slab 0  
fill ~33 ~54 ~60 ~33 ~54 ~61 double_stone_slab 0  
fill ~33 ~54 ~76 ~36 ~54 ~76 double_stone_slab 0  
fill ~34 ~54 ~23 ~37 ~54 ~23 double_stone_slab 0 
setblock ~34 ~54 ~39 double_stone_slab 0 
setblock ~34 ~54 ~59 double_stone_slab 0  
fill ~34 ~54 ~75 ~37 ~54 ~75 double_stone_slab 0  
fill ~35 ~54 ~40 ~35 ~54 ~42 double_stone_slab 0  
fill ~35 ~54 ~56 ~35 ~54 ~58 double_stone_slab 0  
fill ~36 ~54 ~24 ~38 ~54 ~24 double_stone_slab 0  
fill ~36 ~54 ~43 ~36 ~54 ~47 double_stone_slab 0  
fill ~36 ~54 ~51 ~36 ~54 ~55 double_stone_slab 0  
fill ~36 ~54 ~74 ~38 ~54 ~74 double_stone_slab 0  
fill ~37 ~54 ~25 ~39 ~54 ~25 double_stone_slab 0  
fill ~37 ~54 ~73 ~39 ~54 ~73 double_stone_slab 0  
fill ~38 ~54 ~26 ~40 ~54 ~26 double_stone_slab 0  
fill ~38 ~54 ~72 ~40 ~54 ~72 double_stone_slab 0  
fill ~39 ~54 ~27 ~41 ~54 ~27 double_stone_slab 0  
fill ~39 ~54 ~71 ~41 ~54 ~71 double_stone_slab 0  
fill ~40 ~54 ~28 ~42 ~54 ~28 double_stone_slab 0  
fill ~40 ~54 ~48 ~42 ~54 ~48 fence 0  
fill ~40 ~54 ~49 ~40 ~54 ~50 fence 0  
fill ~40 ~54 ~70 ~42 ~54 ~70 double_stone_slab 0  
fill ~41 ~54 ~29 ~43 ~54 ~29 double_stone_slab 0  
fill ~41 ~54 ~69 ~43 ~54 ~69 double_stone_slab 0  
fill ~42 ~54 ~30 ~44 ~54 ~30 double_stone_slab 0  
fill ~42 ~54 ~68 ~44 ~54 ~68 double_stone_slab 0  
fill ~43 ~54 ~31 ~45 ~54 ~31 double_stone_slab 0  
fill ~43 ~54 ~67 ~45 ~54 ~67 double_stone_slab 0  
fill ~44 ~54 ~32 ~46 ~54 ~32 double_stone_slab 0  
fill ~44 ~54 ~33 ~46 ~54 ~33 double_stone_slab 0  
fill ~44 ~54 ~65 ~46 ~54 ~65 double_stone_slab 0  
fill ~44 ~54 ~66 ~46 ~54 ~66 double_stone_slab 0  
fill ~45 ~54 ~34 ~47 ~54 ~34 double_stone_slab 0  
fill ~45 ~54 ~64 ~47 ~54 ~64 double_stone_slab 0  
fill ~46 ~54 ~35 ~47 ~54 ~35 double_stone_slab 0  
fill ~46 ~54 ~36 ~48 ~54 ~36 double_stone_slab 0  
fill ~46 ~54 ~37 ~48 ~54 ~37 double_stone_slab 0  
fill ~46 ~54 ~61 ~48 ~54 ~61 double_stone_slab 0  
fill ~46 ~54 ~62 ~48 ~54 ~62 double_stone_slab 0  
fill ~46 ~54 ~63 ~47 ~54 ~63 double_stone_slab 0  
fill ~47 ~54 ~38 ~48 ~54 ~38 double_stone_slab 0  
fill ~47 ~54 ~39 ~49 ~54 ~39 double_stone_slab 0  
fill ~47 ~54 ~59 ~49 ~54 ~59 double_stone_slab 0  
fill ~47 ~54 ~60 ~48 ~54 ~60 double_stone_slab 0  
fill ~48 ~54 ~40 ~49 ~54 ~40 double_stone_slab 0  
fill ~48 ~54 ~41 ~49 ~54 ~41 double_stone_slab 0  
fill ~48 ~54 ~42 ~49 ~54 ~42 double_stone_slab 0  
fill ~48 ~54 ~43 ~49 ~54 ~43 double_stone_slab 0  
fill ~48 ~54 ~44 ~49 ~54 ~44 double_stone_slab 0  
fill ~48 ~54 ~45 ~49 ~54 ~45 double_stone_slab 0  
fill ~48 ~54 ~46 ~49 ~54 ~46 double_stone_slab 0  
fill ~48 ~54 ~47 ~49 ~54 ~47 double_stone_slab 0  
fill ~48 ~54 ~48 ~49 ~54 ~48 double_stone_slab 0  
fill ~48 ~54 ~49 ~49 ~54 ~49 double_stone_slab 0  
fill ~48 ~54 ~50 ~49 ~54 ~50 double_stone_slab 0  
fill ~48 ~54 ~51 ~49 ~54 ~51 double_stone_slab 0  
fill ~48 ~54 ~52 ~49 ~54 ~52 double_stone_slab 0  
fill ~48 ~54 ~53 ~49 ~54 ~53 double_stone_slab 0  
fill ~48 ~54 ~54 ~49 ~54 ~54 double_stone_slab 0  
fill ~48 ~54 ~55 ~49 ~54 ~55 double_stone_slab 0  
fill ~48 ~54 ~56 ~49 ~54 ~56 double_stone_slab 0  
fill ~48 ~54 ~57 ~49 ~54 ~57 double_stone_slab 0  
fill ~48 ~54 ~58 ~49 ~54 ~58 double_stone_slab 0  
fill ~-12 ~55 ~40 ~-4 ~55 ~40 double_stone_slab 0  
fill ~-12 ~55 ~41 ~-5 ~55 ~41 double_stone_slab 0  
fill ~-12 ~55 ~42 ~-5 ~55 ~42 double_stone_slab 0  
fill ~-12 ~55 ~43 ~-5 ~55 ~43 double_stone_slab 0  
fill ~-12 ~55 ~44 ~-5 ~55 ~44 double_stone_slab 0  
fill ~-12 ~55 ~45 ~-6 ~55 ~45 double_stone_slab 0  
fill ~-12 ~55 ~46 ~-6 ~55 ~46 double_stone_slab 0  
fill ~-12 ~55 ~47 ~-6 ~55 ~47 double_stone_slab 0  
fill ~-12 ~55 ~48 ~-6 ~55 ~48 double_stone_slab 0 
setblock ~-12 ~55 ~49 stained_hardened_clay 14  
fill ~-12 ~55 ~50 ~-6 ~55 ~50 double_stone_slab 0  
fill ~-12 ~55 ~51 ~-6 ~55 ~51 double_stone_slab 0  
fill ~-12 ~55 ~52 ~-6 ~55 ~52 double_stone_slab 0  
fill ~-12 ~55 ~53 ~-6 ~55 ~53 double_stone_slab 0  
fill ~-12 ~55 ~54 ~-5 ~55 ~54 double_stone_slab 0  
fill ~-12 ~55 ~55 ~-5 ~55 ~55 double_stone_slab 0  
fill ~-12 ~55 ~56 ~-5 ~55 ~56 double_stone_slab 0  
fill ~-12 ~55 ~57 ~-5 ~55 ~57 double_stone_slab 0  
fill ~-12 ~55 ~58 ~-4 ~55 ~58 double_stone_slab 0  
fill ~-11 ~55 ~38 ~-3 ~55 ~38 double_stone_slab 0  
fill ~-11 ~55 ~39 ~-4 ~55 ~39 double_stone_slab 0  
fill ~-11 ~55 ~49 ~-6 ~55 ~49 double_stone_slab 0  
fill ~-11 ~55 ~59 ~-4 ~55 ~59 double_stone_slab 0  
fill ~-11 ~55 ~60 ~-3 ~55 ~60 double_stone_slab 0  
fill ~-10 ~55 ~35 ~-1 ~55 ~35 double_stone_slab 0  
fill ~-10 ~55 ~36 ~-2 ~55 ~36 double_stone_slab 0  
fill ~-10 ~55 ~37 ~-3 ~55 ~37 double_stone_slab 0  
fill ~-10 ~55 ~61 ~-3 ~55 ~61 double_stone_slab 0  
fill ~-10 ~55 ~62 ~-2 ~55 ~62 double_stone_slab 0  
fill ~-10 ~55 ~63 ~-1 ~55 ~63 double_stone_slab 0  
fill ~-9 ~55 ~34 ~-1 ~55 ~34 double_stone_slab 0  
fill ~-9 ~55 ~64 ~-1 ~55 ~64 double_stone_slab 0  
fill ~-8 ~55 ~32 ~1 ~55 ~32 double_stone_slab 0  
fill ~-8 ~55 ~33 ~0 ~55 ~33 double_stone_slab 0  
fill ~-8 ~55 ~65 ~0 ~55 ~65 double_stone_slab 0  
fill ~-8 ~55 ~66 ~1 ~55 ~66 double_stone_slab 0  
fill ~-7 ~55 ~31 ~2 ~55 ~31 double_stone_slab 0  
fill ~-7 ~55 ~67 ~2 ~55 ~67 double_stone_slab 0  
fill ~-6 ~55 ~30 ~4 ~55 ~30 double_stone_slab 0  
fill ~-6 ~55 ~68 ~4 ~55 ~68 double_stone_slab 0  
fill ~-5 ~55 ~29 ~5 ~55 ~29 double_stone_slab 0  
fill ~-5 ~55 ~45 ~-5 ~55 ~53 glowstone 0  
fill ~-5 ~55 ~69 ~5 ~55 ~69 double_stone_slab 0  
fill ~-4 ~55 ~28 ~7 ~55 ~28 double_stone_slab 0  
fill ~-4 ~55 ~41 ~-4 ~55 ~44 glowstone 0  
fill ~-4 ~55 ~45 ~-1 ~55 ~45 double_stone_slab 0  
fill ~-4 ~55 ~46 ~-2 ~55 ~46 double_stone_slab 0  
fill ~-4 ~55 ~47 ~-2 ~55 ~47 double_stone_slab 0  
fill ~-4 ~55 ~48 ~-1 ~55 ~48 double_stone_slab 0  
fill ~-4 ~55 ~49 ~-2 ~55 ~49 double_stone_slab 0  
fill ~-4 ~55 ~50 ~-1 ~55 ~50 double_stone_slab 0  
fill ~-4 ~55 ~51 ~-2 ~55 ~51 double_stone_slab 0  
fill ~-4 ~55 ~52 ~-2 ~55 ~52 double_stone_slab 0  
fill ~-4 ~55 ~53 ~-1 ~55 ~53 double_stone_slab 0  
fill ~-4 ~55 ~54 ~-4 ~55 ~57 glowstone 0  
fill ~-4 ~55 ~70 ~7 ~55 ~70 double_stone_slab 0  
fill ~-3 ~55 ~27 ~9 ~55 ~27 double_stone_slab 0  
fill ~-3 ~55 ~39 ~-3 ~55 ~40 glowstone 0  
fill ~-3 ~55 ~41 ~0 ~55 ~41 double_stone_slab 0  
fill ~-3 ~55 ~42 ~0 ~55 ~42 double_stone_slab 0  
fill ~-3 ~55 ~43 ~-1 ~55 ~43 double_stone_slab 0  
fill ~-3 ~55 ~44 ~-1 ~55 ~44 double_stone_slab 0  
fill ~-3 ~55 ~54 ~-1 ~55 ~54 double_stone_slab 0  
fill ~-3 ~55 ~55 ~-1 ~55 ~55 double_stone_slab 0  
fill ~-3 ~55 ~56 ~0 ~55 ~56 double_stone_slab 0  
fill ~-3 ~55 ~57 ~0 ~55 ~57 double_stone_slab 0  
fill ~-3 ~55 ~58 ~-3 ~55 ~59 glowstone 0  
fill ~-3 ~55 ~71 ~9 ~55 ~71 double_stone_slab 0  
fill ~-2 ~55 ~26 ~13 ~55 ~26 double_stone_slab 0  
fill ~-2 ~55 ~37 ~-2 ~55 ~38 glowstone 0  
fill ~-2 ~55 ~39 ~1 ~55 ~39 double_stone_slab 0  
fill ~-2 ~55 ~40 ~0 ~55 ~40 double_stone_slab 0  
fill ~-2 ~55 ~58 ~0 ~55 ~58 double_stone_slab 0  
fill ~-2 ~55 ~59 ~1 ~55 ~59 double_stone_slab 0  
fill ~-2 ~55 ~60 ~-2 ~55 ~61 glowstone 0  
fill ~-2 ~55 ~72 ~13 ~55 ~72 double_stone_slab 0  
fill ~-1 ~55 ~25 ~37 ~55 ~25 double_stone_slab 0 
setblock ~-1 ~55 ~36 glowstone 0  
fill ~-1 ~55 ~37 ~2 ~55 ~37 double_stone_slab 0  
fill ~-1 ~55 ~38 ~2 ~55 ~38 double_stone_slab 0 
setblock ~-1 ~55 ~49 glowstone 0  
fill ~-1 ~55 ~60 ~2 ~55 ~60 double_stone_slab 0  
fill ~-1 ~55 ~61 ~2 ~55 ~61 double_stone_slab 0 
setblock ~-1 ~55 ~62 glowstone 0  
fill ~-1 ~55 ~73 ~37 ~55 ~73 double_stone_slab 0  
fill ~0 ~55 ~24 ~36 ~55 ~24 double_stone_slab 0  
fill ~0 ~55 ~34 ~0 ~55 ~35 glowstone 0  
fill ~0 ~55 ~36 ~3 ~55 ~36 double_stone_slab 0  
fill ~0 ~55 ~62 ~3 ~55 ~62 double_stone_slab 0  
fill ~0 ~55 ~63 ~0 ~55 ~64 glowstone 0  
fill ~0 ~55 ~74 ~36 ~55 ~74 double_stone_slab 0  
fill ~1 ~55 ~23 ~35 ~55 ~23 double_stone_slab 0 
setblock ~1 ~55 ~33 glowstone 0  
fill ~1 ~55 ~34 ~5 ~55 ~34 double_stone_slab 0  
fill ~1 ~55 ~35 ~4 ~55 ~35 double_stone_slab 0  
fill ~1 ~55 ~63 ~4 ~55 ~63 double_stone_slab 0  
fill ~1 ~55 ~64 ~5 ~55 ~64 double_stone_slab 0 
setblock ~1 ~55 ~65 glowstone 0  
fill ~1 ~55 ~75 ~35 ~55 ~75 double_stone_slab 0 
setblock ~2 ~55 ~32 glowstone 0  
fill ~2 ~55 ~33 ~7 ~55 ~33 double_stone_slab 0  
fill ~2 ~55 ~65 ~7 ~55 ~65 double_stone_slab 0 
setblock ~2 ~55 ~66 glowstone 0  
fill ~3 ~55 ~22 ~33 ~55 ~22 double_stone_slab 0  
fill ~3 ~55 ~31 ~4 ~55 ~31 glowstone 0  
fill ~3 ~55 ~32 ~8 ~55 ~32 double_stone_slab 0  
fill ~3 ~55 ~47 ~3 ~58 ~47 double_stone_slab 0  
fill ~3 ~55 ~48 ~3 ~55 ~50 stone_brick_stairs 0  
fill ~3 ~55 ~51 ~3 ~58 ~51 double_stone_slab 0  
fill ~3 ~55 ~66 ~8 ~55 ~66 double_stone_slab 0  
fill ~3 ~55 ~67 ~4 ~55 ~67 glowstone 0  
fill ~3 ~55 ~76 ~33 ~55 ~76 double_stone_slab 0  
fill ~4 ~55 ~21 ~32 ~55 ~21 double_stone_slab 0  
fill ~4 ~55 ~48 ~4 ~55 ~50 double_stone_slab 0  
fill ~4 ~55 ~77 ~32 ~55 ~77 double_stone_slab 0 
setblock ~5 ~55 ~30 glowstone 0  
fill ~5 ~55 ~31 ~11 ~55 ~31 double_stone_slab 0  
fill ~5 ~55 ~67 ~11 ~55 ~67 double_stone_slab 0 
setblock ~5 ~55 ~68 glowstone 0  
fill ~6 ~55 ~29 ~7 ~55 ~29 glowstone 0  
fill ~6 ~55 ~30 ~14 ~55 ~30 double_stone_slab 0  
fill ~6 ~55 ~68 ~14 ~55 ~68 double_stone_slab 0  
fill ~6 ~55 ~69 ~7 ~55 ~69 glowstone 0  
fill ~7 ~55 ~20 ~29 ~55 ~20 double_stone_slab 0  
fill ~7 ~55 ~78 ~29 ~55 ~78 double_stone_slab 0  
fill ~8 ~55 ~28 ~9 ~55 ~28 glowstone 0  
fill ~8 ~55 ~29 ~28 ~55 ~29 double_stone_slab 0  
fill ~8 ~55 ~69 ~28 ~55 ~69 double_stone_slab 0  
fill ~8 ~55 ~70 ~9 ~55 ~70 glowstone 0  
fill ~9 ~55 ~19 ~17 ~55 ~19 double_stone_slab 0  
fill ~9 ~55 ~79 ~17 ~55 ~79 double_stone_slab 0  
fill ~10 ~55 ~27 ~13 ~55 ~27 glowstone 0  
fill ~10 ~55 ~28 ~26 ~55 ~28 double_stone_slab 0  
fill ~10 ~55 ~70 ~26 ~55 ~70 double_stone_slab 0  
fill ~10 ~55 ~71 ~13 ~55 ~71 glowstone 0  
fill ~13 ~55 ~48 ~15 ~55 ~48 stained_hardened_clay 12  
fill ~13 ~55 ~50 ~15 ~55 ~50 stained_hardened_clay 12  
fill ~14 ~55 ~26 ~22 ~55 ~26 glowstone 0  
fill ~14 ~55 ~27 ~22 ~55 ~27 double_stone_slab 0  
fill ~14 ~55 ~71 ~22 ~55 ~71 double_stone_slab 0  
fill ~14 ~55 ~72 ~22 ~55 ~72 glowstone 0  
fill ~16 ~55 ~34 ~16 ~58 ~34 double_stone_slab 0  
fill ~16 ~55 ~64 ~16 ~58 ~64 double_stone_slab 0 
setblock ~17 ~55 ~30 double_stone_slab 0  
fill ~17 ~55 ~34 ~19 ~55 ~34 stone_brick_stairs 2  
fill ~17 ~55 ~35 ~19 ~55 ~35 double_stone_slab 0  
fill ~17 ~55 ~63 ~19 ~55 ~63 double_stone_slab 0  
fill ~17 ~55 ~64 ~19 ~55 ~64 stone_brick_stairs 3 
setblock ~17 ~55 ~68 double_stone_slab 0 
setblock ~18 ~55 ~19 stained_hardened_clay 14 
setblock ~18 ~55 ~30 glowstone 0 
setblock ~18 ~55 ~68 glowstone 0 
setblock ~18 ~55 ~79 stained_hardened_clay 14  
fill ~19 ~55 ~19 ~27 ~55 ~19 double_stone_slab 0 
setblock ~19 ~55 ~30 double_stone_slab 0 
setblock ~19 ~55 ~68 double_stone_slab 0  
fill ~19 ~55 ~79 ~27 ~55 ~79 double_stone_slab 0  
fill ~20 ~55 ~34 ~20 ~58 ~34 double_stone_slab 0  
fill ~20 ~55 ~64 ~20 ~58 ~64 double_stone_slab 0  
fill ~21 ~55 ~48 ~23 ~55 ~48 stained_hardened_clay 12  
fill ~21 ~55 ~50 ~23 ~55 ~50 stained_hardened_clay 12  
fill ~22 ~55 ~30 ~30 ~55 ~30 double_stone_slab 0  
fill ~22 ~55 ~68 ~30 ~55 ~68 double_stone_slab 0  
fill ~23 ~55 ~26 ~38 ~55 ~26 double_stone_slab 0  
fill ~23 ~55 ~27 ~26 ~55 ~27 glowstone 0  
fill ~23 ~55 ~71 ~26 ~55 ~71 glowstone 0  
fill ~23 ~55 ~72 ~38 ~55 ~72 double_stone_slab 0  
fill ~25 ~55 ~31 ~31 ~55 ~31 double_stone_slab 0  
fill ~25 ~55 ~67 ~31 ~55 ~67 double_stone_slab 0  
fill ~27 ~55 ~27 ~39 ~55 ~27 double_stone_slab 0  
fill ~27 ~55 ~28 ~28 ~55 ~28 glowstone 0  
fill ~27 ~55 ~70 ~28 ~55 ~70 glowstone 0  
fill ~27 ~55 ~71 ~39 ~55 ~71 double_stone_slab 0  
fill ~28 ~55 ~32 ~33 ~55 ~32 double_stone_slab 0   
fill ~28 ~55 ~66 ~33 ~55 ~66 double_stone_slab 0  
fill ~29 ~55 ~28 ~40 ~55 ~28 double_stone_slab 0  
fill ~29 ~55 ~29 ~30 ~55 ~29 glowstone 0  
fill ~29 ~55 ~33 ~34 ~55 ~33 double_stone_slab 0  
fill ~29 ~55 ~65 ~34 ~55 ~65 double_stone_slab 0  
fill ~29 ~55 ~69 ~30 ~55 ~69 glowstone 0  
fill ~29 ~55 ~70 ~40 ~55 ~70 double_stone_slab 0  
fill ~31 ~55 ~29 ~41 ~55 ~29 double_stone_slab 0 
setblock ~31 ~55 ~30 glowstone 0  
fill ~31 ~55 ~34 ~35 ~55 ~34 double_stone_slab 0  
fill ~31 ~55 ~48 ~31 ~55 ~50 double_stone_slab 0  
fill ~31 ~55 ~64 ~35 ~55 ~64 double_stone_slab 0 
setblock ~31 ~55 ~68 glowstone 0  
fill ~31 ~55 ~69 ~41 ~55 ~69 double_stone_slab 0  
fill ~32 ~55 ~30 ~42 ~55 ~30 double_stone_slab 0  
fill ~32 ~55 ~31 ~33 ~55 ~31 glowstone 0  
fill ~32 ~55 ~35 ~35 ~55 ~35 double_stone_slab 0  
fill ~32 ~55 ~47 ~32 ~58 ~47 double_stone_slab 0  
fill ~32 ~55 ~48 ~32 ~55 ~50 stone_brick_stairs 1  
fill ~32 ~55 ~51 ~32 ~58 ~51 double_stone_slab 0  
fill ~32 ~55 ~63 ~35 ~55 ~63 double_stone_slab 0  
fill ~32 ~55 ~67 ~33 ~55 ~67 glowstone 0  
fill ~32 ~55 ~68 ~42 ~55 ~68 double_stone_slab 0  
fill ~33 ~55 ~36 ~36 ~55 ~36 double_stone_slab 0  
fill ~33 ~55 ~62 ~36 ~55 ~62 double_stone_slab 0  
fill ~34 ~55 ~31 ~43 ~55 ~31 double_stone_slab 0 
setblock ~34 ~55 ~32 glowstone 0  
fill ~34 ~55 ~37 ~37 ~55 ~37 double_stone_slab 0  
fill ~34 ~55 ~38 ~37 ~55 ~38 double_stone_slab 0  
fill ~34 ~55 ~60 ~37 ~55 ~60 double_stone_slab 0  
fill ~34 ~55 ~61 ~37 ~55 ~61 double_stone_slab 0 
setblock ~34 ~55 ~66 glowstone 0  
fill ~34 ~55 ~67 ~43 ~55 ~67 double_stone_slab 0  
fill ~35 ~55 ~32 ~44 ~55 ~32 double_stone_slab 0 
setblock ~35 ~55 ~33 glowstone 0  
fill ~35 ~55 ~39 ~38 ~55 ~39 double_stone_slab 0  
fill ~35 ~55 ~59 ~38 ~55 ~59 double_stone_slab 0 
setblock ~35 ~55 ~65 glowstone 0  
fill ~35 ~55 ~66 ~44 ~55 ~66 double_stone_slab 0  
fill ~36 ~55 ~33 ~44 ~55 ~33 double_stone_slab 0  
fill ~36 ~55 ~34 ~36 ~55 ~35 glowstone 0  
fill ~36 ~55 ~40 ~38 ~55 ~40 double_stone_slab 0  
fill ~36 ~55 ~41 ~39 ~55 ~41 double_stone_slab 0  
fill ~36 ~55 ~42 ~39 ~55 ~42 double_stone_slab 0  
fill ~36 ~55 ~48 ~40 ~55 ~48 double_stone_slab 0 
setblock ~36 ~55 ~49 glowstone 0  
fill ~36 ~55 ~50 ~40 ~55 ~50 double_stone_slab 0  
fill ~36 ~55 ~56 ~39 ~55 ~56 double_stone_slab 0  
fill ~36 ~55 ~57 ~39 ~55 ~57 double_stone_slab 0  
fill ~36 ~55 ~58 ~38 ~55 ~58 double_stone_slab 0  
fill ~36 ~55 ~63 ~36 ~55 ~64 glowstone 0  
fill ~36 ~55 ~65 ~44 ~55 ~65 double_stone_slab 0  
fill ~37 ~55 ~34 ~45 ~55 ~34 double_stone_slab 0  
fill ~37 ~55 ~35 ~46 ~55 ~35 double_stone_slab 0 
setblock ~37 ~55 ~36 glowstone 0  
fill ~37 ~55 ~43 ~39 ~55 ~43 double_stone_slab 0  
fill ~37 ~55 ~44 ~39 ~55 ~44 double_stone_slab 0  
fill ~37 ~55 ~45 ~40 ~55 ~45 double_stone_slab 0  
fill ~37 ~55 ~46 ~40 ~55 ~46 double_stone_slab 0  
fill ~37 ~55 ~47 ~40 ~55 ~47 double_stone_slab 0  
fill ~37 ~55 ~49 ~40 ~55 ~49 double_stone_slab 0  
fill ~37 ~55 ~51 ~40 ~55 ~51 double_stone_slab 0  
fill ~37 ~55 ~52 ~40 ~55 ~52 double_stone_slab 0  
fill ~37 ~55 ~53 ~40 ~55 ~53 double_stone_slab 0  
fill ~37 ~55 ~54 ~39 ~55 ~54 double_stone_slab 0  
fill ~37 ~55 ~55 ~39 ~55 ~55 double_stone_slab 0 
setblock ~37 ~55 ~62 glowstone 0  
fill ~37 ~55 ~63 ~46 ~55 ~63 double_stone_slab 0  
fill ~37 ~55 ~64 ~45 ~55 ~64 double_stone_slab 0  
fill ~38 ~55 ~36 ~46 ~55 ~36 double_stone_slab 0  
fill ~38 ~55 ~37 ~38 ~55 ~38 glowstone 0  
fill ~38 ~55 ~60 ~38 ~55 ~61 glowstone 0  
fill ~38 ~55 ~62 ~46 ~55 ~62 double_stone_slab 0  
fill ~39 ~55 ~37 ~46 ~55 ~37 double_stone_slab 0  
fill ~39 ~55 ~38 ~47 ~55 ~38 double_stone_slab 0  
fill ~39 ~55 ~39 ~39 ~55 ~40 glowstone 0  
fill ~39 ~55 ~58 ~39 ~55 ~59 glowstone 0  
fill ~39 ~55 ~60 ~47 ~55 ~60 double_stone_slab 0  
fill ~39 ~55 ~61 ~46 ~55 ~61 double_stone_slab 0  
fill ~40 ~55 ~39 ~47 ~55 ~39 double_stone_slab 0  
fill ~40 ~55 ~40 ~48 ~55 ~40 double_stone_slab 0  
fill ~40 ~55 ~41 ~40 ~55 ~44 glowstone 0  
fill ~40 ~55 ~54 ~40 ~55 ~57 glowstone 0  
fill ~40 ~55 ~58 ~48 ~55 ~58 double_stone_slab 0  
fill ~40 ~55 ~59 ~47 ~55 ~59 double_stone_slab 0  
fill ~41 ~55 ~41 ~48 ~55 ~41 double_stone_slab 0  
fill ~41 ~55 ~42 ~48 ~55 ~42 double_stone_slab 0  
fill ~41 ~55 ~43 ~48 ~55 ~43 double_stone_slab 0  
fill ~41 ~55 ~44 ~48 ~55 ~44 double_stone_slab 0  
fill ~41 ~55 ~45 ~41 ~55 ~53 glowstone 0  
fill ~41 ~55 ~54 ~48 ~55 ~54 double_stone_slab 0  
fill ~41 ~55 ~55 ~48 ~55 ~55 double_stone_slab 0  
fill ~41 ~55 ~56 ~48 ~55 ~56 double_stone_slab 0  
fill ~41 ~55 ~57 ~48 ~55 ~57 double_stone_slab 0  
fill ~42 ~55 ~45 ~48 ~55 ~45 double_stone_slab 0  
fill ~42 ~55 ~46 ~48 ~55 ~46 double_stone_slab 0  
fill ~42 ~55 ~47 ~48 ~55 ~47 double_stone_slab 0  
