setblock ~4 ~3 ~9 chest 3  
setblock ~3 ~1 ~9 chest 3  
setblock ~4 ~1 ~9 chest 3  
setblock ~3 ~3 ~9 chest 3  
setblock ~11 ~2 ~14 chest 4  
setblock ~11 ~2 ~15 chest 4  
setblock ~33 ~17 ~23 dropper 4  
setblock ~30 ~17 ~30 chest 2  
setblock ~31 ~17 ~30 chest 2  
setblock ~28 ~18 ~29 chest 5  
setblock ~28 ~18 ~28 chest 5  
setblock ~31 ~17 ~27 chest 3  
setblock ~30 ~17 ~27 chest 3  
setblock ~29 ~18 ~40 chest 5  
setblock ~29 ~17 ~35 chest 5  
setblock ~29 ~18 ~36 chest 5  
setblock ~29 ~20 ~40 chest 5  
setblock ~28 ~20 ~29 chest 5  
setblock ~28 ~20 ~28 chest 5  
setblock ~42 ~1 ~9 chest 3  
setblock ~43 ~1 ~9 chest 3  
setblock ~42 ~3 ~9 chest 3  
setblock ~43 ~3 ~9 chest 3  
fill ~1 ~-1 ~1 ~13 ~-1 ~1 grass 0  
fill ~1 ~-1 ~2 ~10 ~-1 ~2 grass 0  
fill ~1 ~-1 ~3 ~7 ~-1 ~3 grass 0  
fill ~1 ~-1 ~4 ~4 ~-1 ~4 grass 0  
fill ~1 ~-1 ~5 ~3 ~-1 ~5 grass 0  
fill ~1 ~-1 ~6 ~2 ~-1 ~6 grass 0  
fill ~1 ~-1 ~7 ~2 ~-1 ~7 dirt 0  
fill ~1 ~-1 ~8 ~14 ~-1 ~8 dirt 0  
fill ~1 ~-1 ~9 ~1 ~-1 ~9 dirt 0  
fill ~1 ~-1 ~10 ~1 ~-1 ~10 grass 0  
fill ~1 ~-1 ~11 ~1 ~-1 ~11 grass 0  
fill ~1 ~-1 ~12 ~1 ~-1 ~12 grass 0  
fill ~1 ~-1 ~13 ~1 ~-1 ~13 grass 0  
fill ~1 ~-1 ~14 ~1 ~-1 ~14 grass 0  
fill ~1 ~-1 ~15 ~1 ~-1 ~15 grass 0  
fill ~1 ~-1 ~16 ~1 ~-1 ~16 grass 0  
fill ~1 ~-1 ~17 ~1 ~-1 ~17 grass 0  
fill ~1 ~-1 ~18 ~1 ~-1 ~18 grass 0  
fill ~1 ~-1 ~19 ~1 ~-1 ~19 grass 0  
fill ~1 ~-1 ~20 ~1 ~-1 ~20 grass 0  
fill ~1 ~-1 ~21 ~1 ~-1 ~21 grass 0  
fill ~1 ~-1 ~22 ~1 ~-1 ~22 grass 0  
fill ~1 ~-1 ~23 ~1 ~-1 ~23 grass 0  
fill ~1 ~-1 ~24 ~1 ~-1 ~24 grass 0  
fill ~1 ~-1 ~25 ~2 ~-1 ~25 brick_block 0  
fill ~1 ~-1 ~26 ~2 ~-1 ~26 brick_block 0  
fill ~1 ~-1 ~27 ~2 ~-1 ~27 brick_block 0  
fill ~1 ~-1 ~28 ~1 ~-1 ~28 grass 0  
fill ~1 ~-1 ~29 ~1 ~-1 ~29 grass 0  
fill ~1 ~-1 ~30 ~1 ~-1 ~30 grass 0  
fill ~1 ~-1 ~31 ~1 ~-1 ~31 grass 0  
fill ~1 ~-1 ~32 ~1 ~-1 ~32 grass 0  
fill ~1 ~-1 ~33 ~1 ~-1 ~33 grass 0  
fill ~1 ~-1 ~34 ~1 ~-1 ~34 grass 0  
fill ~1 ~-1 ~35 ~1 ~-1 ~35 grass 0  
fill ~1 ~-1 ~36 ~1 ~-1 ~36 grass 0  
fill ~1 ~-1 ~37 ~1 ~-1 ~37 grass 0  
fill ~1 ~-1 ~38 ~1 ~-1 ~38 grass 0  
fill ~1 ~-1 ~39 ~1 ~-1 ~39 grass 0  
fill ~1 ~-1 ~40 ~1 ~-1 ~40 grass 0  
fill ~1 ~-1 ~41 ~1 ~-1 ~41 grass 0  
fill ~1 ~-1 ~42 ~1 ~-1 ~42 grass 0  
fill ~1 ~-1 ~43 ~1 ~-1 ~43 dirt 0  
fill ~1 ~-1 ~44 ~1 ~-1 ~44 dirt 0  
fill ~1 ~-1 ~45 ~1 ~-1 ~45 dirt 0  
fill ~1 ~-1 ~46 ~1 ~-1 ~46 grass 0  
fill ~1 ~-1 ~47 ~1 ~-1 ~47 grass 0  
fill ~1 ~-1 ~48 ~1 ~-1 ~48 grass 0  
fill ~1 ~-1 ~49 ~1 ~-1 ~49 grass 0  
fill ~1 ~-1 ~50 ~1 ~-1 ~50 grass 0  
fill ~1 ~-1 ~51 ~1 ~-1 ~51 grass 0  
fill ~1 ~-1 ~52 ~1 ~-1 ~52 grass 0  
fill ~1 ~-1 ~53 ~1 ~-1 ~53 grass 0  
fill ~1 ~-1 ~54 ~1 ~-1 ~54 grass 0  
fill ~1 ~-1 ~55 ~1 ~-1 ~55 grass 0  
fill ~1 ~-1 ~56 ~1 ~-1 ~56 grass 0  
fill ~1 ~-1 ~57 ~1 ~-1 ~57 grass 0  
fill ~1 ~-1 ~58 ~1 ~-1 ~58 grass 0  
fill ~1 ~-1 ~59 ~1 ~-1 ~59 grass 0  
fill ~1 ~-1 ~60 ~1 ~-1 ~60 grass 0  
fill ~1 ~-1 ~61 ~1 ~-1 ~61 dirt 0  
fill ~1 ~-1 ~62 ~1 ~-1 ~62 dirt 0  
fill ~1 ~-1 ~63 ~2 ~-1 ~63 dirt 0  
fill ~1 ~-1 ~64 ~14 ~-1 ~64 grass 0  
fill ~1 ~-1 ~65 ~14 ~-1 ~65 grass 0  
fill ~1 ~-1 ~66 ~15 ~-1 ~66 grass 0  
fill ~1 ~-1 ~67 ~14 ~-1 ~67 grass 0  
fill ~1 ~-1 ~68 ~14 ~-1 ~68 grass 0  
fill ~1 ~-1 ~69 ~45 ~-1 ~69 grass 0  
fill ~2 ~-1 ~9 ~2 ~15 ~9 brick_block 0  
fill ~2 ~-1 ~10 ~2 ~6 ~10 brick_block 0  
fill ~2 ~-1 ~11 ~2 ~6 ~11 brick_block 0  
fill ~2 ~-1 ~12 ~2 ~6 ~12 brick_block 0  
fill ~2 ~-1 ~13 ~2 ~-1 ~54 brick_block 0  
fill ~2 ~-1 ~55 ~2 ~-1 ~55 dirt 0  
fill ~2 ~-1 ~56 ~2 ~-1 ~56 dirt 0  
fill ~2 ~-1 ~57 ~2 ~-1 ~57 dirt 0  
fill ~2 ~-1 ~58 ~2 ~-1 ~58 dirt 0  
fill ~2 ~-1 ~59 ~2 ~-1 ~59 dirt 0  
fill ~2 ~-1 ~60 ~2 ~-1 ~60 dirt 0  
fill ~2 ~-1 ~61 ~2 ~15 ~61 brick_block 0  
fill ~2 ~-1 ~62 ~2 ~26 ~62 brick_block 0  
fill ~3 ~-1 ~6 ~4 ~-1 ~6 stonebrick 0  
fill ~3 ~-1 ~7 ~14 ~-1 ~7 grass 0  
fill ~3 ~-1 ~9 ~14 ~-1 ~9 planks 1  
fill ~3 ~-1 ~10 ~14 ~-1 ~10 planks 1  
fill ~3 ~-1 ~11 ~14 ~-1 ~11 planks 1  
fill ~3 ~-1 ~12 ~5 ~-1 ~12 planks 1  
fill ~3 ~-1 ~13 ~5 ~-1 ~13 planks 1  
fill ~3 ~-1 ~14 ~14 ~-1 ~14 planks 1  
fill ~3 ~-1 ~15 ~14 ~-1 ~15 planks 1  
fill ~3 ~-1 ~16 ~14 ~-1 ~16 planks 1  
fill ~3 ~-1 ~17 ~7 ~-1 ~17 planks 1  
fill ~3 ~-1 ~18 ~14 ~-1 ~18 planks 1  
fill ~3 ~-1 ~19 ~14 ~-1 ~19 planks 1  
fill ~3 ~-1 ~20 ~7 ~-1 ~20 planks 1  
fill ~3 ~-1 ~21 ~15 ~-1 ~21 planks 1  
fill ~3 ~-1 ~22 ~11 ~-1 ~22 planks 1  
fill ~3 ~-1 ~23 ~43 ~-1 ~23 planks 1  
fill ~3 ~-1 ~24 ~42 ~-1 ~24 planks 1 
setblock ~3 ~-1 ~25 glowstone 0  
fill ~3 ~-1 ~26 ~4 ~-1 ~26 planks 1  
fill ~3 ~-1 ~27 ~15 ~-1 ~27 planks 1  
fill ~3 ~-1 ~28 ~43 ~-1 ~28 planks 1  
fill ~3 ~-1 ~29 ~43 ~-1 ~29 planks 1  
fill ~3 ~-1 ~30 ~8 ~-1 ~30 planks 1  
fill ~3 ~-1 ~31 ~43 ~-1 ~31 planks 1  
fill ~3 ~-1 ~32 ~6 ~-1 ~32 planks 1  
fill ~3 ~-1 ~33 ~43 ~-1 ~33 planks 1  
fill ~3 ~-1 ~34 ~43 ~-1 ~34 planks 1  
fill ~3 ~-1 ~35 ~43 ~-1 ~35 planks 1  
fill ~3 ~-1 ~36 ~9 ~-1 ~36 planks 1  
fill ~3 ~-1 ~37 ~15 ~-1 ~37 planks 1  
fill ~3 ~-1 ~38 ~16 ~-1 ~38 planks 1  
fill ~3 ~-1 ~39 ~5 ~-1 ~39 planks 1  
fill ~3 ~-1 ~40 ~5 ~-1 ~40 planks 1  
fill ~3 ~-1 ~41 ~33 ~-1 ~41 planks 1  
fill ~3 ~-1 ~42 ~17 ~-1 ~42 planks 1  
fill ~3 ~-1 ~43 ~43 ~-1 ~43 planks 1  
fill ~3 ~-1 ~44 ~10 ~-1 ~44 planks 1  
fill ~3 ~-1 ~45 ~43 ~-1 ~45 planks 1  
fill ~3 ~-1 ~46 ~3 ~-1 ~61 planks 1  
fill ~3 ~-1 ~62 ~14 ~-1 ~62 dirt 0  
fill ~3 ~-1 ~63 ~13 ~-1 ~63 grass 0 
setblock ~4 ~-1 ~5 stonebrick 0  
fill ~4 ~-1 ~25 ~43 ~-1 ~25 planks 1 
setblock ~4 ~-1 ~46 glowstone 0  
fill ~4 ~-1 ~47 ~14 ~-1 ~47 planks 1  
fill ~4 ~-1 ~48 ~23 ~-1 ~48 planks 1  
fill ~4 ~-1 ~49 ~8 ~-1 ~49 planks 1  
fill ~4 ~-1 ~50 ~14 ~-1 ~50 planks 1  
fill ~4 ~-1 ~51 ~43 ~-1 ~51 planks 1  
fill ~4 ~-1 ~52 ~24 ~-1 ~52 planks 1  
fill ~4 ~-1 ~53 ~39 ~-1 ~53 planks 1  
fill ~4 ~-1 ~54 ~19 ~-1 ~54 planks 1  
fill ~4 ~-1 ~55 ~5 ~-1 ~55 planks 1  
fill ~4 ~-1 ~56 ~10 ~-1 ~56 planks 1  
fill ~4 ~-1 ~57 ~43 ~-1 ~57 planks 1  
fill ~4 ~-1 ~58 ~4 ~-1 ~61 planks 1  
fill ~5 ~-1 ~4 ~7 ~-1 ~4 stonebrick 0  
fill ~5 ~-1 ~5 ~17 ~-1 ~5 grass 0  
fill ~5 ~-1 ~6 ~14 ~-1 ~6 grass 0 
setblock ~5 ~-1 ~26 glowstone 0  
fill ~5 ~-1 ~46 ~15 ~-1 ~46 planks 1 
setblock ~5 ~-1 ~58 glowstone 0  
fill ~5 ~-1 ~59 ~5 ~-1 ~61 planks 1  
fill ~6 ~-1 ~12 ~7 ~-1 ~12 glowstone 0  
fill ~6 ~-1 ~13 ~7 ~-1 ~13 glowstone 0  
fill ~6 ~-1 ~26 ~40 ~-1 ~26 planks 1  
fill ~6 ~-1 ~39 ~6 ~-1 ~40 glowstone 0 
setblock ~6 ~-1 ~55 glowstone 0  
fill ~6 ~-1 ~58 ~40 ~-1 ~58 planks 1 
setblock ~6 ~-1 ~59 glowstone 0  
fill ~6 ~-1 ~60 ~43 ~-1 ~60 planks 1  
fill ~6 ~-1 ~61 ~43 ~-1 ~61 planks 1 
setblock ~7 ~-1 ~32 glowstone 0  
fill ~7 ~-1 ~39 ~8 ~-1 ~39 planks 1 
setblock ~7 ~-1 ~40 glowstone 0  
fill ~7 ~-1 ~55 ~19 ~-1 ~55 planks 1 
setblock ~7 ~-1 ~59 planks 1  
fill ~8 ~-1 ~3 ~10 ~-1 ~3 stonebrick 0  
fill ~8 ~-1 ~4 ~16 ~-1 ~4 grass 0  
fill ~8 ~-1 ~12 ~14 ~-1 ~12 planks 1  
fill ~8 ~-1 ~13 ~14 ~-1 ~13 planks 1 
setblock ~8 ~-1 ~17 glowstone 0 
setblock ~8 ~-1 ~20 glowstone 0 
setblock ~8 ~-1 ~32 planks 1  
fill ~8 ~-1 ~40 ~43 ~-1 ~40 planks 1 
setblock ~8 ~-1 ~59 glowstone 0  
fill ~9 ~-1 ~17 ~14 ~-1 ~17 planks 1  
fill ~9 ~-1 ~20 ~14 ~-1 ~20 planks 1 
setblock ~9 ~-1 ~30 glowstone 0 
setblock ~9 ~-1 ~32 glowstone 0 
setblock ~9 ~-1 ~39 glowstone 0 
setblock ~9 ~-1 ~49 glowstone 0  
fill ~9 ~-1 ~59 ~16 ~-1 ~59 planks 1  
fill ~10 ~-1 ~30 ~36 ~-1 ~30 planks 1  
fill ~10 ~-1 ~32 ~36 ~-1 ~32 planks 1 
setblock ~10 ~-1 ~36 glowstone 0  
fill ~10 ~-1 ~39 ~43 ~-1 ~39 planks 1  
fill ~10 ~-1 ~49 ~43 ~-1 ~49 planks 1  
fill ~11 ~-1 ~2 ~13 ~-1 ~2 stonebrick 0  
fill ~11 ~-1 ~3 ~15 ~-1 ~3 grass 0  
fill ~11 ~-1 ~36 ~43 ~-1 ~36 planks 1 
setblock ~11 ~-1 ~44 glowstone 0 
setblock ~11 ~-1 ~56 glowstone 0 
setblock ~12 ~-1 ~22 glowstone 0  
fill ~12 ~-1 ~44 ~21 ~-1 ~44 planks 1  
fill ~12 ~-1 ~56 ~34 ~-1 ~56 planks 1  
fill ~13 ~-1 ~22 ~33 ~-1 ~22 planks 1 
setblock ~14 ~-1 ~1 stonebrick 0 
setblock ~14 ~-1 ~2 grass 0  
fill ~14 ~-1 ~63 ~32 ~-1 ~63 dirt 0  
fill ~15 ~-1 ~1 ~22 ~-1 ~1 grass 0  
fill ~15 ~-1 ~2 ~15 ~-1 ~2 dirt 0  
fill ~15 ~-1 ~6 ~19 ~-1 ~6 dirt 0  
fill ~15 ~-1 ~7 ~31 ~-1 ~7 dirt 0  
fill ~15 ~-1 ~8 ~15 ~-1 ~20 stone 0 
setblock ~15 ~-1 ~47 glowstone 0 
setblock ~15 ~-1 ~50 glowstone 0  
fill ~15 ~-1 ~62 ~31 ~-1 ~62 grass 0  
fill ~15 ~-1 ~64 ~19 ~-1 ~64 dirt 0  
fill ~15 ~-1 ~65 ~16 ~-1 ~65 dirt 0  
fill ~15 ~-1 ~67 ~16 ~-1 ~67 dirt 0  
fill ~15 ~-1 ~68 ~20 ~-1 ~68 dirt 0  
fill ~16 ~-1 ~2 ~21 ~-1 ~2 grass 0  
fill ~16 ~-1 ~3 ~16 ~-1 ~3 dirt 0 
setblock ~16 ~-1 ~8 glowstone 0  
fill ~16 ~-1 ~9 ~31 ~-1 ~9 stone 0  
fill ~16 ~-1 ~10 ~31 ~-1 ~10 stone 0  
fill ~16 ~-1 ~11 ~31 ~-1 ~11 stone 0  
fill ~16 ~-1 ~12 ~31 ~-1 ~12 stone 0  
fill ~16 ~-1 ~13 ~31 ~-1 ~13 stone 0  
fill ~16 ~-1 ~14 ~31 ~-1 ~14 stone 0  
fill ~16 ~-1 ~15 ~31 ~-1 ~15 stone 0  
fill ~16 ~-1 ~16 ~31 ~-1 ~16 stone 0  
fill ~16 ~-1 ~17 ~31 ~-1 ~17 stone 0  
fill ~16 ~-1 ~18 ~31 ~-1 ~18 stone 0  
fill ~16 ~-1 ~19 ~31 ~-1 ~19 stone 0  
fill ~16 ~-1 ~20 ~31 ~-1 ~20 stone 0  
fill ~16 ~-1 ~21 ~19 ~-1 ~21 stonebrick 0 
setblock ~16 ~-1 ~27 glowstone 0 
setblock ~16 ~-1 ~37 glowstone 0 
setblock ~16 ~-1 ~46 glowstone 0  
fill ~16 ~-1 ~47 ~23 ~-1 ~47 planks 1  
fill ~16 ~-1 ~50 ~35 ~-1 ~50 planks 1  
fill ~16 ~-1 ~66 ~16 ~-1 ~66 dirt 0  
fill ~17 ~-1 ~3 ~20 ~-1 ~3 grass 0  
fill ~17 ~-1 ~4 ~17 ~-1 ~4 dirt 0  
fill ~17 ~-1 ~8 ~29 ~-1 ~8 stone 0  
fill ~17 ~-1 ~27 ~29 ~-1 ~27 planks 1  
fill ~17 ~-1 ~37 ~29 ~-1 ~37 planks 1 
setblock ~17 ~-1 ~38 glowstone 0  
fill ~17 ~-1 ~46 ~43 ~-1 ~46 planks 1 
setblock ~17 ~-1 ~59 glowstone 0  
fill ~17 ~-1 ~65 ~29 ~-1 ~65 grass 0  
fill ~17 ~-1 ~66 ~29 ~-1 ~66 grass 0  
fill ~17 ~-1 ~67 ~19 ~-1 ~67 grass 0  
fill ~18 ~-1 ~4 ~21 ~-1 ~4 grass 0  
fill ~18 ~-1 ~5 ~18 ~-1 ~5 dirt 0  
fill ~18 ~-1 ~38 ~28 ~-1 ~38 planks 1 
setblock ~18 ~-1 ~42 glowstone 0  
fill ~18 ~-1 ~59 ~28 ~-1 ~59 planks 1  
fill ~19 ~-1 ~5 ~21 ~-1 ~5 grass 0  
fill ~19 ~-1 ~42 ~43 ~-1 ~42 planks 1  
fill ~20 ~-1 ~6 ~22 ~-1 ~6 grass 0 
setblock ~20 ~-1 ~21 glowstone 0  
fill ~20 ~-1 ~54 ~20 ~-1 ~55 glowstone 0  
fill ~20 ~-1 ~64 ~26 ~-1 ~64 grass 0  
fill ~20 ~-1 ~67 ~26 ~-1 ~67 dirt 0  
fill ~21 ~-1 ~3 ~25 ~-1 ~3 dirt 0 
setblock ~21 ~-1 ~21 brick_stairs 1  
fill ~21 ~-1 ~54 ~30 ~-1 ~54 planks 1  
fill ~21 ~-1 ~55 ~25 ~-1 ~55 planks 1  
fill ~21 ~-1 ~68 ~25 ~-1 ~68 grass 0  
fill ~22 ~-1 ~2 ~24 ~-1 ~2 dirt 0  
fill ~22 ~-1 ~4 ~24 ~-1 ~4 dirt 0  
fill ~22 ~-1 ~5 ~22 ~-1 ~5 dirt 0  
fill ~22 ~-1 ~21 ~24 ~-1 ~21 brick_stairs 3 
setblock ~22 ~-1 ~44 glowstone 0  
fill ~23 ~-1 ~1 ~23 ~-1 ~1 dirt 0 
setblock ~23 ~-1 ~5 grass 0  
fill ~23 ~-1 ~6 ~23 ~-1 ~6 dirt 0  
fill ~23 ~-1 ~44 ~43 ~-1 ~44 planks 1  
fill ~24 ~-1 ~1 ~31 ~-1 ~1 grass 0  
fill ~24 ~-1 ~5 ~24 ~-1 ~5 dirt 0  
fill ~24 ~-1 ~6 ~26 ~-1 ~6 grass 0  
fill ~24 ~-1 ~47 ~24 ~-1 ~48 glowstone 0  
fill ~25 ~-1 ~2 ~30 ~-1 ~2 grass 0  
fill ~25 ~-1 ~4 ~28 ~-1 ~4 grass 0  
fill ~25 ~-1 ~5 ~27 ~-1 ~5 grass 0 
setblock ~25 ~-1 ~21 brick_stairs 0  
fill ~25 ~-1 ~47 ~26 ~-1 ~47 planks 1  
fill ~25 ~-1 ~48 ~43 ~-1 ~48 planks 1 
setblock ~25 ~-1 ~52 glowstone 0  
fill ~26 ~-1 ~3 ~29 ~-1 ~3 grass 0 
setblock ~26 ~-1 ~21 glowstone 0  
fill ~26 ~-1 ~52 ~43 ~-1 ~52 planks 1 
setblock ~26 ~-1 ~55 glowstone 0  
fill ~26 ~-1 ~68 ~31 ~-1 ~68 dirt 0  
fill ~27 ~-1 ~6 ~31 ~-1 ~6 dirt 0  
fill ~27 ~-1 ~21 ~30 ~-1 ~21 stonebrick 0 
setblock ~27 ~-1 ~47 glowstone 0  
fill ~27 ~-1 ~55 ~39 ~-1 ~55 planks 1  
fill ~27 ~-1 ~64 ~31 ~-1 ~64 dirt 0  
fill ~27 ~-1 ~67 ~29 ~-1 ~67 grass 0  
fill ~28 ~-1 ~5 ~28 ~-1 ~5 dirt 0  
fill ~28 ~-1 ~47 ~42 ~-1 ~47 planks 1  
fill ~29 ~-1 ~4 ~29 ~-1 ~4 dirt 0  
fill ~29 ~-1 ~5 ~41 ~-1 ~5 grass 0 
setblock ~29 ~-1 ~38 glowstone 0 
setblock ~29 ~-1 ~59 glowstone 0  
fill ~30 ~-1 ~3 ~30 ~-1 ~3 dirt 0  
fill ~30 ~-1 ~4 ~38 ~-1 ~4 grass 0 
setblock ~30 ~-1 ~8 glowstone 0 
setblock ~30 ~-1 ~27 glowstone 0 
setblock ~30 ~-1 ~37 glowstone 0  
fill ~30 ~-1 ~38 ~43 ~-1 ~38 planks 1  
fill ~30 ~-1 ~59 ~37 ~-1 ~59 planks 1  
fill ~30 ~-1 ~65 ~31 ~-1 ~65 dirt 0  
fill ~30 ~-1 ~66 ~30 ~-1 ~66 dirt 0  
fill ~30 ~-1 ~67 ~31 ~-1 ~67 dirt 0  
fill ~31 ~-1 ~2 ~31 ~-1 ~2 dirt 0  
fill ~31 ~-1 ~3 ~35 ~-1 ~3 grass 0 
setblock ~31 ~-1 ~8 stone 0  
fill ~31 ~-1 ~21 ~43 ~-1 ~21 planks 1  
fill ~31 ~-1 ~27 ~35 ~-1 ~27 planks 1  
fill ~31 ~-1 ~37 ~37 ~-1 ~37 planks 1 
setblock ~31 ~-1 ~54 glowstone 0  
fill ~31 ~-1 ~66 ~45 ~-1 ~66 grass 0 
setblock ~32 ~-1 ~1 stonebrick 0 
setblock ~32 ~-1 ~2 grass 0  
fill ~32 ~-1 ~6 ~41 ~-1 ~6 grass 0  
fill ~32 ~-1 ~7 ~43 ~-1 ~7 grass 0  
fill ~32 ~-1 ~8 ~45 ~-1 ~8 dirt 0  
fill ~32 ~-1 ~9 ~43 ~-1 ~9 planks 1  
fill ~32 ~-1 ~10 ~43 ~-1 ~10 planks 1  
fill ~32 ~-1 ~11 ~36 ~-1 ~11 planks 1  
fill ~32 ~-1 ~12 ~38 ~-1 ~12 planks 1  
fill ~32 ~-1 ~13 ~38 ~-1 ~13 planks 1  
fill ~32 ~-1 ~14 ~43 ~-1 ~14 planks 1  
fill ~32 ~-1 ~15 ~38 ~-1 ~15 planks 1  
fill ~32 ~-1 ~16 ~43 ~-1 ~16 planks 1  
fill ~32 ~-1 ~17 ~37 ~-1 ~17 planks 1  
fill ~32 ~-1 ~18 ~43 ~-1 ~18 planks 1  
fill ~32 ~-1 ~19 ~43 ~-1 ~19 planks 1  
fill ~32 ~-1 ~20 ~37 ~-1 ~20 planks 1  
fill ~32 ~-1 ~54 ~43 ~-1 ~54 planks 1  
fill ~32 ~-1 ~62 ~43 ~-1 ~62 dirt 0  
fill ~32 ~-1 ~64 ~45 ~-1 ~64 grass 0  
fill ~32 ~-1 ~65 ~45 ~-1 ~65 grass 0  
fill ~32 ~-1 ~67 ~45 ~-1 ~67 grass 0  
fill ~32 ~-1 ~68 ~45 ~-1 ~68 grass 0  
fill ~33 ~-1 ~1 ~45 ~-1 ~1 grass 0  
fill ~33 ~-1 ~2 ~35 ~-1 ~2 stonebrick 0  
fill ~33 ~-1 ~63 ~43 ~-1 ~63 grass 0 
setblock ~34 ~-1 ~22 glowstone 0 
setblock ~34 ~-1 ~41 glowstone 0  
fill ~35 ~-1 ~22 ~43 ~-1 ~22 planks 1  
fill ~35 ~-1 ~41 ~43 ~-1 ~41 planks 1 
setblock ~35 ~-1 ~56 glowstone 0  
fill ~36 ~-1 ~2 ~45 ~-1 ~2 grass 0  
fill ~36 ~-1 ~3 ~38 ~-1 ~3 stonebrick 0 
setblock ~36 ~-1 ~50 glowstone 0  
fill ~36 ~-1 ~56 ~43 ~-1 ~56 planks 1  
fill ~37 ~-1 ~11 ~37 ~0 ~11 carpet 13  
fill ~37 ~-1 ~27 ~43 ~-1 ~27 planks 1 
setblock ~37 ~-1 ~30 glowstone 0 
setblock ~37 ~-1 ~32 glowstone 0  
fill ~37 ~-1 ~50 ~43 ~-1 ~50 planks 1  
fill ~38 ~-1 ~11 ~43 ~-1 ~11 planks 1 
setblock ~38 ~-1 ~17 glowstone 0 
setblock ~38 ~-1 ~20 glowstone 0  
fill ~38 ~-1 ~30 ~43 ~-1 ~30 planks 1 
setblock ~38 ~-1 ~32 planks 1  
fill ~38 ~-1 ~37 ~39 ~-1 ~37 glowstone 0 
setblock ~38 ~-1 ~59 glowstone 0  
fill ~39 ~-1 ~3 ~45 ~-1 ~3 grass 0  
fill ~39 ~-1 ~4 ~41 ~-1 ~4 stonebrick 0  
fill ~39 ~-1 ~12 ~40 ~-1 ~12 glowstone 0  
fill ~39 ~-1 ~13 ~40 ~-1 ~13 glowstone 0  
fill ~39 ~-1 ~15 ~39 ~0 ~15 carpet 13  
fill ~39 ~-1 ~17 ~43 ~-1 ~17 planks 1  
fill ~39 ~-1 ~20 ~43 ~-1 ~20 planks 1 
setblock ~39 ~-1 ~32 glowstone 0 
setblock ~39 ~-1 ~59 planks 1  
fill ~40 ~-1 ~15 ~43 ~-1 ~15 planks 1  
fill ~40 ~-1 ~32 ~43 ~-1 ~32 planks 1  
fill ~40 ~-1 ~37 ~43 ~-1 ~37 planks 1 
setblock ~40 ~-1 ~53 glowstone 0 
setblock ~40 ~-1 ~55 glowstone 0 
setblock ~40 ~-1 ~59 glowstone 0  
fill ~41 ~-1 ~12 ~43 ~-1 ~12 planks 1  
fill ~41 ~-1 ~13 ~43 ~-1 ~13 planks 1 
setblock ~41 ~-1 ~26 glowstone 0  
fill ~41 ~-1 ~53 ~43 ~-1 ~53 planks 1  
fill ~41 ~-1 ~55 ~43 ~-1 ~55 planks 1 
setblock ~41 ~-1 ~58 glowstone 0  
fill ~41 ~-1 ~59 ~43 ~-1 ~59 planks 1  
fill ~42 ~-1 ~4 ~45 ~-1 ~4 grass 0  
fill ~42 ~-1 ~5 ~42 ~-1 ~6 stonebrick 0  
fill ~42 ~-1 ~26 ~43 ~-1 ~26 planks 1  
fill ~42 ~-1 ~58 ~43 ~-1 ~58 planks 1  
fill ~43 ~-1 ~5 ~45 ~-1 ~5 grass 0 
setblock ~43 ~-1 ~6 stonebrick 0 
setblock ~43 ~-1 ~24 glowstone 0 
setblock ~43 ~-1 ~47 glowstone 0  
fill ~44 ~-1 ~6 ~45 ~-1 ~6 grass 0  
fill ~44 ~-1 ~7 ~45 ~-1 ~7 dirt 0  
fill ~44 ~-1 ~9 ~45 ~-1 ~9 dirt 0  
fill ~44 ~-1 ~10 ~44 ~-1 ~10 dirt 0  
fill ~44 ~-1 ~11 ~44 ~-1 ~11 dirt 0  
fill ~44 ~-1 ~12 ~44 ~-1 ~12 dirt 0  
fill ~44 ~-1 ~13 ~44 ~-1 ~13 dirt 0  
fill ~44 ~-1 ~14 ~44 ~-1 ~14 dirt 0  
fill ~44 ~-1 ~15 ~44 ~-1 ~15 dirt 0  
fill ~44 ~-1 ~16 ~44 ~-1 ~16 dirt 0  
fill ~44 ~-1 ~17 ~44 ~-1 ~17 dirt 0  
fill ~44 ~-1 ~18 ~44 ~-1 ~18 dirt 0  
fill ~44 ~-1 ~19 ~44 ~-1 ~19 dirt 0  
fill ~44 ~-1 ~20 ~44 ~-1 ~20 dirt 0  
fill ~44 ~-1 ~21 ~44 ~-1 ~21 dirt 0  
fill ~44 ~-1 ~22 ~44 ~-1 ~22 dirt 0  
fill ~44 ~-1 ~23 ~44 ~-1 ~23 dirt 0  
fill ~44 ~-1 ~24 ~44 ~-1 ~24 dirt 0  
fill ~44 ~-1 ~25 ~45 ~-1 ~25 dirt 0  
fill ~44 ~-1 ~26 ~45 ~-1 ~26 dirt 0  
fill ~44 ~-1 ~27 ~45 ~-1 ~27 dirt 0  
fill ~44 ~-1 ~28 ~44 ~-1 ~28 dirt 0  
fill ~44 ~-1 ~29 ~44 ~-1 ~29 dirt 0  
fill ~44 ~-1 ~30 ~44 ~-1 ~30 dirt 0  
fill ~44 ~-1 ~31 ~44 ~-1 ~31 dirt 0  
fill ~44 ~-1 ~32 ~44 ~-1 ~32 dirt 0  
fill ~44 ~-1 ~33 ~44 ~-1 ~33 dirt 0  
fill ~44 ~-1 ~34 ~44 ~-1 ~34 dirt 0  
fill ~44 ~-1 ~35 ~44 ~-1 ~35 dirt 0  
fill ~44 ~-1 ~36 ~44 ~-1 ~36 dirt 0  
fill ~44 ~-1 ~37 ~44 ~-1 ~37 dirt 0  
fill ~44 ~-1 ~38 ~44 ~-1 ~38 dirt 0  
fill ~44 ~-1 ~39 ~44 ~-1 ~39 dirt 0  
fill ~44 ~-1 ~40 ~44 ~-1 ~40 dirt 0  
fill ~44 ~-1 ~41 ~44 ~-1 ~41 dirt 0  
fill ~44 ~-1 ~42 ~44 ~-1 ~42 dirt 0  
fill ~44 ~-1 ~43 ~45 ~-1 ~43 dirt 0  
fill ~44 ~-1 ~44 ~45 ~-1 ~44 dirt 0  
fill ~44 ~-1 ~45 ~45 ~-1 ~45 dirt 0  
fill ~44 ~-1 ~46 ~44 ~-1 ~46 dirt 0  
fill ~44 ~-1 ~47 ~44 ~-1 ~47 dirt 0  
fill ~44 ~-1 ~48 ~44 ~-1 ~48 dirt 0  
fill ~44 ~-1 ~49 ~44 ~-1 ~49 dirt 0  
fill ~44 ~-1 ~50 ~44 ~-1 ~50 dirt 0  
fill ~44 ~-1 ~51 ~44 ~-1 ~51 dirt 0  
fill ~44 ~-1 ~52 ~44 ~-1 ~52 dirt 0  
fill ~44 ~-1 ~53 ~44 ~-1 ~53 dirt 0  
fill ~44 ~-1 ~54 ~44 ~-1 ~54 dirt 0  
fill ~44 ~-1 ~55 ~44 ~-1 ~55 dirt 0  
fill ~44 ~-1 ~56 ~44 ~-1 ~56 dirt 0  
fill ~44 ~-1 ~57 ~44 ~-1 ~57 dirt 0  
fill ~44 ~-1 ~58 ~44 ~-1 ~58 dirt 0  
fill ~44 ~-1 ~59 ~44 ~-1 ~59 dirt 0  
fill ~44 ~-1 ~60 ~44 ~-1 ~60 dirt 0  
fill ~44 ~-1 ~61 ~44 ~15 ~61 brick_block 0  
fill ~44 ~-1 ~62 ~44 ~26 ~62 brick_block 0  
fill ~44 ~-1 ~63 ~45 ~-1 ~63 dirt 0  
fill ~45 ~-1 ~10 ~45 ~-1 ~10 grass 0  
fill ~45 ~-1 ~11 ~45 ~-1 ~11 grass 0  
fill ~45 ~-1 ~12 ~45 ~-1 ~12 grass 0  
fill ~45 ~-1 ~13 ~45 ~-1 ~13 grass 0  
fill ~45 ~-1 ~14 ~45 ~-1 ~14 grass 0  
fill ~45 ~-1 ~15 ~45 ~-1 ~15 grass 0  
fill ~45 ~-1 ~16 ~45 ~-1 ~16 grass 0  
fill ~45 ~-1 ~17 ~45 ~-1 ~17 grass 0  
fill ~45 ~-1 ~18 ~45 ~-1 ~18 grass 0  
fill ~45 ~-1 ~19 ~45 ~-1 ~19 grass 0  
fill ~45 ~-1 ~20 ~45 ~-1 ~20 grass 0  
fill ~45 ~-1 ~21 ~45 ~-1 ~21 grass 0  
fill ~45 ~-1 ~22 ~45 ~-1 ~22 grass 0  
fill ~45 ~-1 ~23 ~45 ~-1 ~23 grass 0  
fill ~45 ~-1 ~24 ~45 ~-1 ~24 grass 0  
fill ~45 ~-1 ~28 ~45 ~-1 ~28 grass 0  
fill ~45 ~-1 ~29 ~45 ~-1 ~29 grass 0  
fill ~45 ~-1 ~30 ~45 ~-1 ~30 grass 0  
fill ~45 ~-1 ~31 ~45 ~-1 ~31 grass 0  
fill ~45 ~-1 ~32 ~45 ~-1 ~32 grass 0  
fill ~45 ~-1 ~33 ~45 ~-1 ~33 grass 0  
fill ~45 ~-1 ~34 ~45 ~-1 ~34 grass 0  
fill ~45 ~-1 ~35 ~45 ~-1 ~35 grass 0  
fill ~45 ~-1 ~36 ~45 ~-1 ~36 grass 0  
fill ~45 ~-1 ~37 ~45 ~-1 ~37 grass 0  
fill ~45 ~-1 ~38 ~45 ~-1 ~38 grass 0  
fill ~45 ~-1 ~39 ~45 ~-1 ~39 grass 0  
fill ~45 ~-1 ~40 ~45 ~-1 ~40 grass 0  
fill ~45 ~-1 ~41 ~45 ~-1 ~41 grass 0  
fill ~45 ~-1 ~42 ~45 ~-1 ~42 grass 0  
fill ~45 ~-1 ~46 ~45 ~-1 ~46 grass 0  
fill ~45 ~-1 ~47 ~45 ~-1 ~47 grass 0  
fill ~45 ~-1 ~48 ~45 ~-1 ~48 grass 0  
fill ~45 ~-1 ~49 ~45 ~-1 ~49 grass 0  
fill ~45 ~-1 ~50 ~45 ~-1 ~50 grass 0  
fill ~45 ~-1 ~51 ~45 ~-1 ~51 grass 0  
fill ~45 ~-1 ~52 ~45 ~-1 ~52 grass 0  
fill ~45 ~-1 ~53 ~45 ~-1 ~53 grass 0  
fill ~45 ~-1 ~54 ~45 ~-1 ~54 grass 0  
fill ~45 ~-1 ~55 ~45 ~-1 ~55 grass 0  
fill ~45 ~-1 ~56 ~45 ~-1 ~56 grass 0  
fill ~45 ~-1 ~57 ~45 ~-1 ~57 grass 0  
fill ~45 ~-1 ~58 ~45 ~-1 ~58 grass 0  
fill ~45 ~-1 ~59 ~45 ~-1 ~59 grass 0  
fill ~45 ~-1 ~60 ~45 ~-1 ~60 grass 0  
fill ~45 ~-1 ~61 ~45 ~-1 ~61 dirt 0  
fill ~45 ~-1 ~62 ~45 ~-1 ~62 dirt 0  
fill ~1 ~0 ~7 ~2 ~0 ~7 stonebrick 0  
fill ~1 ~0 ~8 ~1 ~6 ~8 stonebrick 0  
fill ~1 ~0 ~9 ~1 ~0 ~7 stonebrick 0  
fill ~1 ~0 ~10 ~1 ~1 ~10 cobblestone_wall 0 
setblock ~1 ~0 ~11 stone_brick_stairs 0  
fill ~1 ~0 ~12 ~1 ~1 ~12 cobblestone_wall 0 
setblock ~1 ~0 ~13 stone_brick_stairs 0  
fill ~1 ~0 ~14 ~1 ~1 ~14 cobblestone_wall 0 
setblock ~1 ~0 ~15 stone_brick_stairs 0  
fill ~1 ~0 ~16 ~1 ~1 ~16 cobblestone_wall 0 
setblock ~1 ~0 ~17 stone_brick_stairs 0  
fill ~1 ~0 ~18 ~1 ~1 ~18 cobblestone_wall 0 
setblock ~1 ~0 ~19 stone_brick_stairs 0  
fill ~1 ~0 ~20 ~1 ~1 ~20 cobblestone_wall 0 
setblock ~1 ~0 ~21 stone_brick_stairs 0  
fill ~1 ~0 ~22 ~1 ~1 ~22 cobblestone_wall 0 
setblock ~1 ~0 ~23 stone_brick_stairs 0  
fill ~1 ~0 ~24 ~1 ~1 ~24 cobblestone_wall 0  
fill ~1 ~0 ~25 ~1 ~0 ~27 stonebrick 0  
fill ~1 ~0 ~28 ~1 ~1 ~28 cobblestone_wall 0 
setblock ~1 ~0 ~29 stone_brick_stairs 0  
fill ~1 ~0 ~30 ~1 ~1 ~30 cobblestone_wall 0 
setblock ~1 ~0 ~31 stone_brick_stairs 0  
fill ~1 ~0 ~32 ~1 ~1 ~32 cobblestone_wall 0 
setblock ~1 ~0 ~33 stone_brick_stairs 0  
fill ~1 ~0 ~34 ~1 ~1 ~34 cobblestone_wall 0 
setblock ~1 ~0 ~35 stone_brick_stairs 0  
fill ~1 ~0 ~36 ~1 ~1 ~36 cobblestone_wall 0 
setblock ~1 ~0 ~37 stone_brick_stairs 0  
fill ~1 ~0 ~38 ~1 ~1 ~38 cobblestone_wall 0 
setblock ~1 ~0 ~39 stone_brick_stairs 0  
fill ~1 ~0 ~40 ~1 ~1 ~40 cobblestone_wall 0 
setblock ~1 ~0 ~41 stone_brick_stairs 0  
fill ~1 ~0 ~42 ~1 ~1 ~42 cobblestone_wall 0  
fill ~1 ~0 ~43 ~1 ~0 ~45 stonebrick 0  
fill ~1 ~0 ~46 ~1 ~1 ~46 cobblestone_wall 0 
setblock ~1 ~0 ~47 stone_brick_stairs 0  
fill ~1 ~0 ~48 ~1 ~1 ~48 cobblestone_wall 0 
setblock ~1 ~0 ~49 stone_brick_stairs 0  
fill ~1 ~0 ~50 ~1 ~1 ~50 cobblestone_wall 0 
setblock ~1 ~0 ~51 stone_brick_stairs 0  
fill ~1 ~0 ~52 ~1 ~1 ~52 cobblestone_wall 0 
setblock ~1 ~0 ~53 stone_brick_stairs 0  
fill ~1 ~0 ~54 ~1 ~1 ~54 cobblestone_wall 0 
setblock ~1 ~0 ~55 stone_brick_stairs 0  
fill ~1 ~0 ~56 ~1 ~1 ~56 cobblestone_wall 0 
setblock ~1 ~0 ~57 stone_brick_stairs 0  
fill ~1 ~0 ~58 ~1 ~1 ~58 cobblestone_wall 0 
setblock ~1 ~0 ~59 stone_brick_stairs 0  
fill ~1 ~0 ~60 ~1 ~1 ~60 cobblestone_wall 0  
fill ~1 ~0 ~61 ~1 ~0 ~63 stonebrick 0 
setblock ~2 ~0 ~4 tallgrass 1  
fill ~2 ~0 ~8 ~2 ~26 ~8 brick_block 0 
setblock ~2 ~0 ~13 brick_stairs 1  
fill ~2 ~0 ~14 ~2 ~6 ~14 brick_block 0 
setblock ~2 ~0 ~15 brick_stairs 1  
fill ~2 ~0 ~16 ~2 ~6 ~16 brick_block 0 
setblock ~2 ~0 ~17 brick_stairs 1  
fill ~2 ~0 ~18 ~2 ~6 ~18 brick_block 0  
fill ~2 ~0 ~19 ~2 ~6 ~19 brick_block 0  
fill ~2 ~0 ~20 ~2 ~6 ~20 brick_block 0  
fill ~2 ~0 ~21 ~3 ~0 ~21 brick_block 0  
fill ~2 ~0 ~22 ~3 ~0 ~22 brick_block 0  
fill ~2 ~0 ~23 ~2 ~6 ~23 brick_block 0  
fill ~2 ~0 ~24 ~2 ~6 ~24 brick_block 0  
fill ~2 ~0 ~25 ~2 ~26 ~25 brick_block 0  
fill ~2 ~0 ~26 ~3 ~0 ~26 brick_block 0  
fill ~2 ~0 ~27 ~2 ~26 ~27 brick_block 0  
fill ~2 ~0 ~28 ~2 ~6 ~28 brick_block 0  
fill ~2 ~0 ~29 ~2 ~6 ~29 brick_block 0  
fill ~2 ~0 ~30 ~2 ~6 ~30 brick_block 0  
fill ~2 ~0 ~31 ~2 ~6 ~31 brick_block 0  
fill ~2 ~0 ~32 ~2 ~6 ~32 brick_block 0  
fill ~2 ~0 ~33 ~2 ~6 ~33 brick_block 0  
fill ~2 ~0 ~34 ~2 ~6 ~34 brick_block 0  
fill ~2 ~0 ~35 ~2 ~6 ~35 brick_block 0  
fill ~2 ~0 ~36 ~2 ~6 ~36 brick_block 0  
fill ~2 ~0 ~37 ~2 ~6 ~37 brick_block 0  
fill ~2 ~0 ~38 ~2 ~6 ~38 brick_block 0  
fill ~2 ~0 ~39 ~2 ~6 ~39 brick_block 0  
fill ~2 ~0 ~40 ~2 ~6 ~40 brick_block 0  
fill ~2 ~0 ~41 ~2 ~6 ~41 brick_block 0  
fill ~2 ~0 ~42 ~2 ~6 ~42 brick_block 0  
fill ~2 ~0 ~43 ~2 ~26 ~43 brick_block 0  
fill ~2 ~0 ~44 ~2 ~26 ~44 brick_block 0  
fill ~2 ~0 ~45 ~2 ~26 ~45 brick_block 0  
fill ~2 ~0 ~46 ~2 ~6 ~46 brick_block 0  
fill ~2 ~0 ~47 ~2 ~6 ~47 brick_block 0  
fill ~2 ~0 ~48 ~2 ~6 ~48 brick_block 0  
fill ~2 ~0 ~49 ~2 ~6 ~49 brick_block 0  
fill ~2 ~0 ~50 ~2 ~6 ~50 brick_block 0  
fill ~2 ~0 ~51 ~2 ~6 ~51 brick_block 0  
fill ~2 ~0 ~52 ~2 ~6 ~52 brick_block 0  
fill ~2 ~0 ~53 ~2 ~6 ~53 brick_block 0  
fill ~2 ~0 ~54 ~2 ~6 ~54 brick_block 0  
fill ~2 ~0 ~55 ~2 ~6 ~55 brick_block 0  
fill ~2 ~0 ~56 ~2 ~6 ~56 brick_block 0  
fill ~2 ~0 ~57 ~2 ~6 ~57 brick_block 0  
fill ~2 ~0 ~58 ~2 ~6 ~58 brick_block 0  
fill ~2 ~0 ~59 ~2 ~6 ~59 brick_block 0  
fill ~2 ~0 ~60 ~2 ~6 ~60 brick_block 0  
fill ~2 ~0 ~63 ~2 ~1 ~63 stonebrick 0 
setblock ~3 ~0 ~6 stone_slab 5  
fill ~3 ~0 ~8 ~5 ~0 ~8 stonebrick 0  
fill ~3 ~0 ~9 ~4 ~0 ~9 brick_stairs 7 
setblock ~3 ~0 ~25 anvil 2  
fill ~3 ~0 ~62 ~5 ~0 ~62 stonebrick 0 
setblock ~4 ~0 ~5 stone_slab 5 
setblock ~4 ~0 ~6 leaves 12  
fill ~4 ~0 ~7 ~4 ~6 ~7 cobblestone_wall 0 
setblock ~4 ~0 ~10 carpet 12  
fill ~4 ~0 ~11 ~9 ~0 ~11 carpet 13  
fill ~4 ~0 ~12 ~5 ~0 ~12 carpet 13  
fill ~4 ~0 ~13 ~5 ~0 ~13 carpet 13  
fill ~4 ~0 ~14 ~9 ~0 ~14 carpet 13 
setblock ~4 ~0 ~15 carpet 12  
fill ~4 ~0 ~25 ~5 ~0 ~25 stone_slab 4 
setblock ~4 ~0 ~26 brick_stairs 2  
fill ~4 ~0 ~27 ~4 ~4 ~27 brick_block 0  
fill ~4 ~0 ~63 ~4 ~6 ~63 cobblestone_wall 0  
fill ~5 ~0 ~4 ~7 ~0 ~4 stone_slab 5 
setblock ~5 ~0 ~5 red_flower 0 
setblock ~5 ~0 ~7 stone_brick_stairs 2  
fill ~5 ~0 ~10 ~8 ~0 ~10 carpet 13  
fill ~5 ~0 ~15 ~8 ~0 ~15 carpet 13  
fill ~5 ~0 ~26 ~5 ~4 ~26 quartz_block 0 
setblock ~5 ~0 ~27 brick_stairs 1  
fill ~5 ~0 ~28 ~6 ~0 ~28 brick_block 0 
setblock ~5 ~0 ~63 stone_brick_stairs 3  
fill ~6 ~0 ~5 ~6 ~0 ~7 tallgrass 1  
fill ~6 ~0 ~8 ~7 ~0 ~8 stone_stairs 6  
fill ~6 ~0 ~12 ~7 ~0 ~12 carpet 12  
fill ~6 ~0 ~13 ~7 ~0 ~13 carpet 12  
fill ~6 ~0 ~26 ~6 ~0 ~27 stone_slab 4  
fill ~6 ~0 ~29 ~13 ~0 ~29 brick_block 0  
fill ~6 ~0 ~62 ~7 ~0 ~62 stone_stairs 7 
setblock ~7 ~0 ~5 red_flower 8  
fill ~7 ~0 ~6 ~7 ~0 ~7 leaves 4  
fill ~7 ~0 ~21 ~8 ~0 ~21 brick_block 0  
fill ~7 ~0 ~22 ~13 ~0 ~22 brick_block 0 
setblock ~7 ~0 ~28 quartz_stairs 1  
fill ~8 ~0 ~3 ~10 ~0 ~3 stone_slab 5  
fill ~8 ~0 ~4 ~8 ~0 ~6 tallgrass 1 
setblock ~8 ~0 ~7 stone_brick_stairs 2  
fill ~8 ~0 ~8 ~8 ~6 ~8 stonebrick 0  
fill ~8 ~0 ~12 ~9 ~0 ~12 carpet 13  
fill ~8 ~0 ~13 ~9 ~0 ~13 carpet 13  
fill ~8 ~0 ~17 ~8 ~4 ~17 brick_stairs 0  
fill ~8 ~0 ~18 ~8 ~4 ~18 brick_block 0  
fill ~8 ~0 ~19 ~8 ~4 ~19 brick_block 0  
fill ~8 ~0 ~20 ~8 ~4 ~20 brick_block 0  
fill ~8 ~0 ~23 ~8 ~1 ~23 brick_block 0 
setblock ~8 ~0 ~28 quartz_stairs 0  
fill ~8 ~0 ~62 ~8 ~6 ~62 stonebrick 0 
setblock ~8 ~0 ~63 stone_brick_stairs 3  
fill ~9 ~0 ~5 ~10 ~0 ~5 tallgrass 1  
fill ~9 ~0 ~6 ~10 ~0 ~6 tallgrass 1  
fill ~9 ~0 ~7 ~9 ~0 ~5 tallgrass 1  
fill ~9 ~0 ~8 ~10 ~0 ~8 stone_stairs 6 
setblock ~9 ~0 ~10 carpet 12 
setblock ~9 ~0 ~15 carpet 12  
fill ~9 ~0 ~17 ~12 ~0 ~17 brick_block 0  
fill ~9 ~0 ~21 ~10 ~0 ~21 bookshelf 0  
fill ~9 ~0 ~28 ~10 ~0 ~28 bookshelf 0  
fill ~9 ~0 ~62 ~10 ~0 ~62 stone_stairs 7 
setblock ~10 ~0 ~4 tallgrass 1  
fill ~11 ~0 ~2 ~13 ~0 ~2 stone_slab 5  
fill ~11 ~0 ~3 ~12 ~0 ~3 tallgrass 1 
setblock ~11 ~0 ~4 red_flower 0 
setblock ~11 ~0 ~7 stone_brick_stairs 2  
fill ~11 ~0 ~8 ~14 ~0 ~8 stonebrick 0  
fill ~11 ~0 ~9 ~11 ~1 ~9 planks 5  
fill ~11 ~0 ~10 ~11 ~3 ~10 bookshelf 0  
fill ~11 ~0 ~11 ~11 ~3 ~11 bookshelf 0  
fill ~11 ~0 ~12 ~11 ~1 ~12 planks 5  
fill ~11 ~0 ~14 ~13 ~0 ~14 brick_block 0  
fill ~11 ~0 ~15 ~13 ~0 ~15 brick_block 0  
fill ~11 ~0 ~20 ~12 ~0 ~20 brick_block 0  
fill ~11 ~0 ~21 ~11 ~4 ~21 brick_block 0  
fill ~11 ~0 ~23 ~11 ~1 ~23 brick_block 0 
setblock ~11 ~0 ~28 quartz_stairs 1  
fill ~11 ~0 ~62 ~14 ~0 ~62 stonebrick 0 
setblock ~11 ~0 ~63 stone_brick_stairs 3 
setblock ~12 ~0 ~4 red_flower 4 
setblock ~12 ~0 ~6 leaves 4  
fill ~12 ~0 ~7 ~12 ~6 ~7 cobblestone_wall 0  
fill ~12 ~0 ~9 ~12 ~4 ~9 brick_block 0  
fill ~12 ~0 ~10 ~12 ~4 ~10 brick_block 0  
fill ~12 ~0 ~11 ~12 ~4 ~11 brick_block 0  
fill ~12 ~0 ~12 ~12 ~4 ~12 brick_block 0  
fill ~12 ~0 ~13 ~13 ~0 ~13 brick_block 0  
fill ~12 ~0 ~16 ~13 ~0 ~16 brick_block 0  
fill ~12 ~0 ~19 ~14 ~0 ~19 brick_block 0  
fill ~12 ~0 ~21 ~13 ~0 ~21 grass 0 
setblock ~12 ~0 ~28 quartz_stairs 0  
fill ~12 ~0 ~63 ~12 ~6 ~63 cobblestone_wall 0 
setblock ~13 ~0 ~4 tallgrass 1 
setblock ~13 ~0 ~6 tallgrass 1  
fill ~13 ~0 ~7 ~14 ~0 ~7 leaves 4  
fill ~13 ~0 ~12 ~13 ~4 ~12 quartz_block 0  
fill ~13 ~0 ~17 ~13 ~4 ~17 quartz_block 0 
setblock ~13 ~0 ~20 glowstone 0  
fill ~13 ~0 ~26 ~13 ~0 ~27 stone_slab 4  
fill ~13 ~0 ~28 ~15 ~0 ~28 brick_block 0 
setblock ~14 ~0 ~1 stone_slab 5 
setblock ~14 ~0 ~2 red_flower 4  
fill ~14 ~0 ~3 ~15 ~0 ~3 tallgrass 1 
setblock ~14 ~0 ~5 double_plant 2 
setblock ~14 ~0 ~6 leaves 4  
fill ~14 ~0 ~9 ~14 ~4 ~9 brick_block 0  
fill ~14 ~0 ~10 ~14 ~0 ~12 brick_block 0  
fill ~14 ~0 ~13 ~14 ~1 ~13 stonebrick 0  
fill ~14 ~0 ~14 ~14 ~4 ~14 stonebrick 0  
fill ~14 ~0 ~15 ~14 ~4 ~15 stonebrick 0  
fill ~14 ~0 ~16 ~14 ~1 ~16 stonebrick 0  
fill ~14 ~0 ~17 ~16 ~0 ~17 brick_block 0  
fill ~14 ~0 ~18 ~14 ~4 ~18 brick_block 0  
fill ~14 ~0 ~20 ~14 ~4 ~20 brick_block 0  
fill ~14 ~0 ~21 ~15 ~0 ~21 brick_block 0  
fill ~14 ~0 ~25 ~15 ~0 ~25 stone_slab 4  
fill ~14 ~0 ~26 ~14 ~4 ~26 quartz_block 0 
setblock ~14 ~0 ~27 brick_stairs 0  
fill ~14 ~0 ~29 ~14 ~4 ~29 bookshelf 0  
fill ~14 ~0 ~30 ~14 ~4 ~30 bookshelf 0  
fill ~14 ~0 ~31 ~14 ~4 ~31 bookshelf 0  
fill ~14 ~0 ~32 ~14 ~4 ~32 bookshelf 0  
fill ~14 ~0 ~33 ~14 ~4 ~33 bookshelf 0  
fill ~14 ~0 ~34 ~14 ~4 ~34 bookshelf 0  
fill ~14 ~0 ~35 ~14 ~4 ~35 bookshelf 0  
fill ~14 ~0 ~36 ~14 ~4 ~36 bookshelf 0  
fill ~14 ~0 ~37 ~14 ~4 ~37 bookshelf 0  
fill ~14 ~0 ~63 ~14 ~0 ~64 stone_brick_stairs 0 
setblock ~14 ~0 ~65 stone_brick_stairs 3 
setblock ~14 ~0 ~67 stone_brick_stairs 2  
fill ~14 ~0 ~68 ~14 ~0 ~69 stone_brick_stairs 0 
setblock ~15 ~0 ~2 quartz_block 2 
setblock ~15 ~0 ~4 tallgrass 1  
fill ~15 ~0 ~5 ~16 ~0 ~5 leaves 4  
fill ~15 ~0 ~6 ~15 ~6 ~6 quartz_block 2  
fill ~15 ~0 ~7 ~31 ~0 ~7 stonebrick 0  
fill ~15 ~0 ~9 ~15 ~3 ~9 stonebrick 0  
fill ~15 ~0 ~10 ~15 ~3 ~10 quartz_block 0  
fill ~15 ~0 ~11 ~15 ~3 ~11 stonebrick 0  
fill ~15 ~0 ~12 ~16 ~0 ~12 brick_block 0  
fill ~15 ~0 ~18 ~15 ~3 ~18 stonebrick 0  
fill ~15 ~0 ~19 ~15 ~3 ~19 quartz_block 0  
fill ~15 ~0 ~20 ~15 ~3 ~20 stonebrick 0 
setblock ~15 ~0 ~26 brick_stairs 2  
fill ~15 ~0 ~27 ~15 ~4 ~27 brick_block 0  
fill ~15 ~0 ~29 ~15 ~4 ~29 brick_block 0 
setblock ~15 ~0 ~30 brick_stairs 1  
fill ~15 ~0 ~31 ~15 ~4 ~31 brick_block 0 
setblock ~15 ~0 ~32 brick_stairs 1  
fill ~15 ~0 ~33 ~15 ~4 ~33 brick_block 0 
setblock ~15 ~0 ~34 brick_stairs 1  
fill ~15 ~0 ~35 ~15 ~4 ~35 brick_block 0  
fill ~15 ~0 ~36 ~15 ~4 ~36 brick_block 0  
fill ~15 ~0 ~37 ~15 ~4 ~37 brick_block 0  
fill ~15 ~0 ~63 ~31 ~0 ~63 stonebrick 0  
fill ~15 ~0 ~64 ~15 ~6 ~64 quartz_block 2 
setblock ~15 ~0 ~65 stone_brick_stairs 0 
setblock ~15 ~0 ~66 stone_stairs 0 
setblock ~15 ~0 ~67 stone_brick_stairs 0  
fill ~15 ~0 ~68 ~15 ~6 ~68 quartz_block 2  
fill ~15 ~0 ~69 ~16 ~0 ~69 stone_brick_stairs 3 
setblock ~16 ~0 ~2 stone_brick_stairs 2  
fill ~16 ~0 ~3 ~16 ~1 ~3 quartz_block 2 
setblock ~16 ~0 ~4 leaves 4  
fill ~16 ~0 ~6 ~19 ~0 ~6 stonebrick 0  
fill ~16 ~0 ~8 ~20 ~0 ~8 brick_block 0 
setblock ~16 ~0 ~10 snow_layer 6  
fill ~16 ~0 ~13 ~16 ~3 ~13 brick_block 0  
fill ~16 ~0 ~14 ~16 ~3 ~14 brick_block 0  
fill ~16 ~0 ~15 ~16 ~3 ~15 brick_block 0  
fill ~16 ~0 ~16 ~16 ~3 ~16 brick_block 0  
fill ~16 ~0 ~18 ~16 ~1 ~18 quartz_stairs 1  
fill ~16 ~0 ~19 ~16 ~0 ~20 stone_slab 15  
fill ~16 ~0 ~21 ~19 ~0 ~21 iron_bars 0  
fill ~16 ~0 ~26 ~21 ~0 ~26 brick_block 0 
setblock ~16 ~0 ~27 trapdoor 3 
setblock ~16 ~0 ~28 brick_stairs 0 
setblock ~16 ~0 ~36 brick_stairs 0 
setblock ~16 ~0 ~37 trapdoor 3  
fill ~16 ~0 ~38 ~20 ~0 ~38 brick_block 0  
fill ~16 ~0 ~39 ~30 ~0 ~39 bookshelf 0  
fill ~16 ~0 ~64 ~19 ~0 ~64 stonebrick 0  
fill ~16 ~0 ~65 ~16 ~6 ~65 stonebrick 0  
fill ~16 ~0 ~66 ~16 ~1 ~66 stonebrick 0  
fill ~16 ~0 ~67 ~16 ~6 ~67 stonebrick 0  
fill ~16 ~0 ~68 ~18 ~0 ~68 stonebrick 0 
setblock ~17 ~0 ~2 stone_stairs 2  
fill ~17 ~0 ~4 ~17 ~2 ~4 quartz_block 2 
setblock ~17 ~0 ~5 double_plant 2 
setblock ~17 ~0 ~12 quartz_stairs 1 
setblock ~17 ~0 ~14 quartz_stairs 1 
setblock ~17 ~0 ~16 quartz_stairs 1 
setblock ~17 ~0 ~27 brick_stairs 2  
fill ~17 ~0 ~28 ~17 ~4 ~28 quartz_block 2 
setblock ~17 ~0 ~29 brick_stairs 3 
setblock ~17 ~0 ~35 brick_stairs 2  
fill ~17 ~0 ~36 ~17 ~4 ~36 quartz_block 2 
setblock ~17 ~0 ~37 brick_stairs 3 
setblock ~17 ~0 ~69 stone_stairs 3 
setblock ~18 ~0 ~2 stone_brick_stairs 2  
fill ~18 ~0 ~5 ~18 ~3 ~5 quartz_block 2 
setblock ~18 ~0 ~28 brick_stairs 1 
setblock ~18 ~0 ~36 brick_stairs 1  
fill ~18 ~0 ~69 ~19 ~0 ~69 stone_brick_stairs 3 
setblock ~19 ~0 ~2 stone_stairs 2  
fill ~19 ~0 ~68 ~19 ~6 ~68 quartz_block 2 
setblock ~20 ~0 ~2 stone_brick_stairs 2  
summon Bat ~5.39911547123 ~4.10000002384 ~11.4953310417 
summon Item ~3.95524520336 ~-0.0822688407313 ~25.4813254435 
summon Item ~20.2263041337 ~18.0 ~29.9098412968 
summon Item ~24.6413462467 ~18.0 ~29.7746175617 
summon Bat ~13.4110205866 ~25.1000000238 ~38.3962277453 
summon Bat ~9.46479924808 ~28.1000000238 ~37.6473646444 
summon Bat ~18.7462075157 ~10.5 ~53.2537924843 
summon Bat ~11.1433035253 ~27.1000000238 ~41.0095267817 
summon Bat ~11.6450272878 ~27.1000000238 ~42.1271590712 
summon Bat ~17.75 ~25.1000000238 ~47.75 
summon Bat ~10.2426869283 ~25.1000000238 ~44.362465482 
summon Bat ~17.75 ~20.1000000238 ~47.6206804112 
summon Bat ~30.75 ~3.10000002384 ~11.75 
summon Bat ~37.1529514442 ~6.0699677831 ~35.6417150846 
summon Bat ~40.6673937784 ~12.1052648114 ~26.5673937769 
summon Bat ~27.5184738691 ~4.10000002384 ~56.3541716083 
summon Bat ~35.5527613243 ~10.1022736673 ~53.75 
summon Item ~39.125 ~5.0 ~57.125 
summon Bat ~42.9972235176 ~20.825205481 ~43.3004788432 
summon Bat ~42.75 ~27.0 ~62.75  
fill ~20 ~0 ~9 ~20 ~3 ~9 iron_bars 0  
fill ~20 ~0 ~10 ~20 ~3 ~10 iron_bars 0  
fill ~20 ~0 ~11 ~20 ~3 ~11 iron_bars 0  
fill ~20 ~0 ~12 ~20 ~3 ~12 brick_block 0  
fill ~20 ~0 ~13 ~20 ~3 ~13 iron_bars 0  
fill ~20 ~0 ~14 ~20 ~3 ~14 iron_bars 0  
fill ~20 ~0 ~16 ~20 ~3 ~16 iron_bars 0  
fill ~20 ~0 ~17 ~20 ~3 ~17 brick_block 0  
fill ~20 ~0 ~18 ~20 ~3 ~18 iron_bars 0  
fill ~20 ~0 ~19 ~20 ~3 ~19 iron_bars 0  
fill ~20 ~0 ~20 ~20 ~3 ~20 iron_bars 0  
fill ~20 ~0 ~21 ~20 ~4 ~21 brick_block 0  
fill ~20 ~0 ~25 ~20 ~4 ~25 brick_block 0 
setblock ~20 ~0 ~31 dark_oak_stairs 1 
setblock ~20 ~0 ~33 dark_oak_stairs 1 
setblock ~20 ~0 ~37 brick_block 0  
fill ~20 ~0 ~67 ~26 ~0 ~67 stonebrick 0  
fill ~20 ~0 ~68 ~20 ~0 ~69 stone_brick_stairs 1 
setblock ~21 ~0 ~2 stone_stairs 2  
fill ~21 ~0 ~3 ~25 ~0 ~3 stonebrick 0 
setblock ~21 ~0 ~8 anvil 1  
fill ~21 ~0 ~38 ~22 ~0 ~38 stone_slab 4 
setblock ~21 ~0 ~68 stone_stairs 3  
fill ~22 ~0 ~2 ~24 ~0 ~2 stonebrick 0  
fill ~22 ~0 ~4 ~24 ~0 ~4 stonebrick 0 
setblock ~22 ~0 ~30 dark_oak_stairs 6  
fill ~22 ~0 ~31 ~24 ~0 ~31 wooden_slab 13  
fill ~22 ~0 ~32 ~24 ~0 ~32 wooden_slab 13  
fill ~22 ~0 ~33 ~24 ~0 ~33 wooden_slab 13 
setblock ~22 ~0 ~34 dark_oak_stairs 7 
setblock ~22 ~0 ~53 standing_sign 6 
setblock ~22 ~0 ~68 stone_brick_stairs 3 
setblock ~23 ~0 ~1 stonebrick 0 
setblock ~23 ~0 ~6 stonebrick 0 
setblock ~23 ~0 ~8 anvil 1 
setblock ~23 ~0 ~30 wooden_slab 13 
setblock ~23 ~0 ~34 wooden_slab 13  
fill ~23 ~0 ~37 ~23 ~0 ~38 brick_block 0 
setblock ~23 ~0 ~68 stone_stairs 3 
setblock ~24 ~0 ~30 dark_oak_stairs 6 
setblock ~24 ~0 ~34 dark_oak_stairs 7  
fill ~24 ~0 ~38 ~25 ~0 ~38 stone_slab 4 
setblock ~24 ~0 ~68 stone_brick_stairs 3 
setblock ~25 ~0 ~2 stone_stairs 2 
setblock ~25 ~0 ~8 anvil 1  
fill ~25 ~0 ~26 ~30 ~0 ~26 brick_block 0 
setblock ~25 ~0 ~68 stone_stairs 3 
setblock ~26 ~0 ~2 stone_brick_stairs 2  
fill ~26 ~0 ~8 ~30 ~0 ~8 brick_block 0  
fill ~26 ~0 ~9 ~26 ~3 ~9 iron_bars 0  
fill ~26 ~0 ~10 ~26 ~3 ~10 iron_bars 0  
fill ~26 ~0 ~11 ~26 ~3 ~11 iron_bars 0  
fill ~26 ~0 ~12 ~26 ~3 ~12 brick_block 0  
fill ~26 ~0 ~13 ~26 ~3 ~13 iron_bars 0  
fill ~26 ~0 ~14 ~26 ~3 ~14 iron_bars 0  
fill ~26 ~0 ~16 ~26 ~3 ~16 iron_bars 0  
fill ~26 ~0 ~17 ~26 ~3 ~17 brick_block 0  
fill ~26 ~0 ~18 ~26 ~3 ~18 iron_bars 0  
fill ~26 ~0 ~19 ~26 ~3 ~19 iron_bars 0  
fill ~26 ~0 ~20 ~26 ~3 ~20 iron_bars 0  
fill ~26 ~0 ~21 ~26 ~4 ~21 brick_block 0  
fill ~26 ~0 ~25 ~26 ~4 ~25 brick_block 0 
setblock ~26 ~0 ~31 dark_oak_stairs 0 
setblock ~26 ~0 ~33 dark_oak_stairs 0  
fill ~26 ~0 ~37 ~26 ~0 ~38 brick_block 0  
fill ~26 ~0 ~68 ~26 ~0 ~69 stone_brick_stairs 0 
setblock ~27 ~0 ~2 stone_stairs 2  
fill ~27 ~0 ~6 ~30 ~0 ~6 stonebrick 0  
fill ~27 ~0 ~21 ~30 ~0 ~21 iron_bars 0  
fill ~27 ~0 ~38 ~30 ~0 ~38 brick_block 0  
fill ~27 ~0 ~64 ~30 ~0 ~64 stonebrick 0  
fill ~27 ~0 ~68 ~27 ~6 ~68 quartz_block 2  
fill ~27 ~0 ~69 ~28 ~0 ~69 stone_brick_stairs 3 
setblock ~28 ~0 ~2 stone_brick_stairs 2 
setblock ~28 ~0 ~3 tallgrass 1  
fill ~28 ~0 ~5 ~28 ~3 ~5 quartz_block 2 
setblock ~28 ~0 ~28 brick_stairs 0 
setblock ~28 ~0 ~36 brick_stairs 0  
fill ~28 ~0 ~68 ~30 ~0 ~68 stonebrick 0 
setblock ~29 ~0 ~2 stone_stairs 2  
fill ~29 ~0 ~4 ~29 ~2 ~4 quartz_block 2 
setblock ~29 ~0 ~5 double_plant 2 
setblock ~29 ~0 ~12 quartz_stairs 0 
setblock ~29 ~0 ~14 quartz_stairs 0 
setblock ~29 ~0 ~16 quartz_stairs 0 
setblock ~29 ~0 ~27 brick_stairs 2  
fill ~29 ~0 ~28 ~29 ~4 ~28 quartz_block 2 
setblock ~29 ~0 ~29 brick_stairs 3 
setblock ~29 ~0 ~35 brick_stairs 2  
fill ~29 ~0 ~36 ~29 ~4 ~36 quartz_block 2 
setblock ~29 ~0 ~37 brick_stairs 3 
setblock ~29 ~0 ~69 stone_stairs 3 
setblock ~30 ~0 ~2 stone_brick_stairs 2  
fill ~30 ~0 ~3 ~30 ~1 ~3 quartz_block 2 
setblock ~30 ~0 ~10 snow_layer 6  
fill ~30 ~0 ~12 ~32 ~0 ~12 brick_block 0  
fill ~30 ~0 ~13 ~30 ~3 ~13 brick_block 0  
fill ~30 ~0 ~14 ~30 ~3 ~14 brick_block 0  
fill ~30 ~0 ~15 ~30 ~3 ~15 brick_block 0  
fill ~30 ~0 ~16 ~30 ~3 ~16 brick_block 0  
fill ~30 ~0 ~17 ~32 ~0 ~17 brick_block 0  
fill ~30 ~0 ~18 ~30 ~1 ~18 quartz_stairs 0  
fill ~30 ~0 ~19 ~30 ~0 ~20 stone_slab 15 
setblock ~30 ~0 ~27 trapdoor 2 
setblock ~30 ~0 ~28 brick_stairs 1 
setblock ~30 ~0 ~36 brick_stairs 1 
setblock ~30 ~0 ~37 trapdoor 2  
fill ~30 ~0 ~65 ~30 ~6 ~65 stonebrick 0  
fill ~30 ~0 ~66 ~30 ~1 ~66 stonebrick 0  
fill ~30 ~0 ~67 ~30 ~6 ~67 stonebrick 0  
fill ~30 ~0 ~69 ~31 ~0 ~69 stone_brick_stairs 3 
setblock ~31 ~0 ~2 quartz_block 2  
fill ~31 ~0 ~4 ~34 ~0 ~4 tallgrass 1  
fill ~31 ~0 ~6 ~31 ~6 ~6 quartz_block 2  
fill ~31 ~0 ~9 ~31 ~3 ~9 stonebrick 0  
fill ~31 ~0 ~10 ~31 ~3 ~10 quartz_block 0  
fill ~31 ~0 ~11 ~31 ~3 ~11 stonebrick 0  
fill ~31 ~0 ~18 ~31 ~3 ~18 stonebrick 0  
fill ~31 ~0 ~19 ~31 ~3 ~19 quartz_block 0  
fill ~31 ~0 ~20 ~31 ~3 ~20 stonebrick 0  
fill ~31 ~0 ~21 ~32 ~0 ~21 brick_block 0  
fill ~31 ~0 ~25 ~32 ~0 ~25 stone_slab 4 
setblock ~31 ~0 ~26 brick_stairs 2  
fill ~31 ~0 ~27 ~31 ~4 ~27 brick_block 0  
fill ~31 ~0 ~28 ~32 ~0 ~28 brick_block 0  
fill ~31 ~0 ~29 ~31 ~4 ~29 brick_block 0 
setblock ~31 ~0 ~30 brick_stairs 0  
fill ~31 ~0 ~31 ~31 ~4 ~31 brick_block 0 
setblock ~31 ~0 ~32 brick_stairs 0  
fill ~31 ~0 ~33 ~31 ~4 ~33 brick_block 0 
setblock ~31 ~0 ~34 brick_stairs 0  
fill ~31 ~0 ~35 ~31 ~4 ~35 brick_block 0  
fill ~31 ~0 ~36 ~31 ~4 ~36 brick_block 0  
fill ~31 ~0 ~37 ~31 ~4 ~37 brick_block 0  
fill ~31 ~0 ~64 ~31 ~6 ~64 quartz_block 2 
setblock ~31 ~0 ~65 stone_brick_stairs 1 
setblock ~31 ~0 ~66 stone_stairs 1 
setblock ~31 ~0 ~67 stone_brick_stairs 1  
fill ~31 ~0 ~68 ~31 ~6 ~68 quartz_block 2 
setblock ~32 ~0 ~1 stone_slab 5 
setblock ~32 ~0 ~2 yellow_flower 0 
setblock ~32 ~0 ~3 tallgrass 1  
fill ~32 ~0 ~6 ~32 ~0 ~7 leaves 4  
fill ~32 ~0 ~8 ~35 ~0 ~8 stonebrick 0  
fill ~32 ~0 ~9 ~32 ~4 ~9 brick_block 0  
fill ~32 ~0 ~10 ~32 ~0 ~12 brick_block 0  
fill ~32 ~0 ~13 ~32 ~1 ~13 stonebrick 0  
fill ~32 ~0 ~14 ~32 ~4 ~14 stonebrick 0  
fill ~32 ~0 ~15 ~32 ~4 ~15 stonebrick 0  
fill ~32 ~0 ~16 ~32 ~1 ~16 stonebrick 0  
fill ~32 ~0 ~18 ~32 ~4 ~18 brick_block 0  
fill ~32 ~0 ~19 ~34 ~0 ~19 brick_block 0  
fill ~32 ~0 ~20 ~32 ~4 ~20 brick_block 0  
fill ~32 ~0 ~26 ~32 ~4 ~26 quartz_block 0 
setblock ~32 ~0 ~27 brick_stairs 1  
fill ~32 ~0 ~29 ~32 ~4 ~29 bookshelf 0  
fill ~32 ~0 ~30 ~32 ~4 ~30 bookshelf 0  
fill ~32 ~0 ~31 ~32 ~4 ~31 bookshelf 0  
fill ~32 ~0 ~32 ~32 ~4 ~32 bookshelf 0  
fill ~32 ~0 ~33 ~32 ~4 ~33 bookshelf 0  
fill ~32 ~0 ~34 ~32 ~4 ~34 bookshelf 0  
fill ~32 ~0 ~35 ~32 ~4 ~35 bookshelf 0  
fill ~32 ~0 ~36 ~32 ~4 ~36 bookshelf 0  
fill ~32 ~0 ~37 ~32 ~4 ~37 bookshelf 0  
fill ~32 ~0 ~62 ~35 ~0 ~62 stonebrick 0  
fill ~32 ~0 ~63 ~32 ~0 ~64 stone_brick_stairs 1 
setblock ~32 ~0 ~65 stone_brick_stairs 3 
setblock ~32 ~0 ~67 stone_brick_stairs 2  
fill ~32 ~0 ~68 ~32 ~0 ~69 stone_brick_stairs 1  
fill ~33 ~0 ~2 ~35 ~0 ~2 stone_slab 5  
fill ~33 ~0 ~5 ~34 ~0 ~5 yellow_flower 0 
setblock ~33 ~0 ~7 double_plant 2  
fill ~33 ~0 ~12 ~33 ~4 ~12 quartz_block 0  
fill ~33 ~0 ~13 ~35 ~0 ~13 brick_block 0  
fill ~33 ~0 ~14 ~35 ~0 ~14 brick_block 0  
fill ~33 ~0 ~15 ~35 ~0 ~15 brick_block 0  
fill ~33 ~0 ~16 ~34 ~0 ~16 brick_block 0  
fill ~33 ~0 ~17 ~33 ~4 ~17 quartz_block 0  
fill ~33 ~0 ~26 ~33 ~0 ~27 stone_slab 4 
setblock ~33 ~0 ~28 double_stone_slab 4  
fill ~33 ~0 ~29 ~40 ~0 ~29 brick_block 0  
fill ~34 ~0 ~3 ~35 ~0 ~3 tallgrass 1 
setblock ~34 ~0 ~6 leaves 4  
fill ~34 ~0 ~7 ~34 ~6 ~7 cobblestone_wall 0  
fill ~34 ~0 ~9 ~34 ~4 ~9 brick_block 0  
fill ~34 ~0 ~10 ~35 ~0 ~10 brick_block 0  
fill ~34 ~0 ~11 ~35 ~0 ~11 brick_block 0  
fill ~34 ~0 ~12 ~35 ~0 ~12 brick_block 0  
fill ~34 ~0 ~17 ~37 ~0 ~17 brick_block 0  
fill ~34 ~0 ~20 ~35 ~0 ~20 brick_block 0  
fill ~34 ~0 ~22 ~35 ~0 ~22 brick_block 0 
setblock ~34 ~0 ~27 brick_stairs 2  
fill ~34 ~0 ~28 ~39 ~0 ~28 glowstone 0  
fill ~34 ~0 ~63 ~34 ~6 ~63 cobblestone_wall 0  
fill ~35 ~0 ~5 ~38 ~0 ~5 tallgrass 1  
fill ~35 ~0 ~6 ~38 ~0 ~6 tallgrass 1 
setblock ~35 ~0 ~7 stone_brick_stairs 2  
fill ~35 ~0 ~21 ~35 ~7 ~21 brick_block 0  
fill ~35 ~0 ~23 ~35 ~1 ~23 brick_block 0 
setblock ~35 ~0 ~27 double_stone_slab 4 
setblock ~35 ~0 ~63 stone_brick_stairs 3  
fill ~36 ~0 ~3 ~38 ~0 ~3 stone_slab 5  
fill ~36 ~0 ~4 ~38 ~0 ~4 tallgrass 1  
fill ~36 ~0 ~8 ~37 ~0 ~8 stone_stairs 6  
fill ~36 ~0 ~22 ~37 ~0 ~22 spruce_stairs 3  
fill ~36 ~0 ~27 ~37 ~0 ~27 brick_stairs 2  
fill ~36 ~0 ~62 ~37 ~0 ~62 stone_stairs 7 
setblock ~37 ~0 ~7 tallgrass 1 
setblock ~37 ~0 ~10 carpet 12  
fill ~37 ~0 ~12 ~38 ~0 ~12 carpet 13  
fill ~37 ~0 ~13 ~38 ~0 ~13 carpet 13  
fill ~37 ~0 ~14 ~42 ~0 ~14 carpet 13 
setblock ~37 ~0 ~15 carpet 12 
setblock ~38 ~0 ~7 stone_brick_stairs 2  
fill ~38 ~0 ~8 ~38 ~6 ~8 stonebrick 0  
fill ~38 ~0 ~10 ~41 ~0 ~10 carpet 13  
fill ~38 ~0 ~11 ~42 ~0 ~11 carpet 13 
setblock ~38 ~0 ~15 carpet 13  
fill ~38 ~0 ~17 ~38 ~4 ~17 brick_stairs 1  
fill ~38 ~0 ~18 ~38 ~13 ~18 brick_block 0  
fill ~38 ~0 ~19 ~38 ~26 ~19 brick_block 0  
fill ~38 ~0 ~20 ~38 ~26 ~20 brick_block 0  
fill ~38 ~0 ~21 ~39 ~0 ~21 brick_block 0  
fill ~38 ~0 ~22 ~39 ~0 ~22 brick_block 0  
fill ~38 ~0 ~23 ~38 ~1 ~23 brick_block 0 
setblock ~38 ~0 ~27 double_stone_slab 4  
fill ~38 ~0 ~62 ~38 ~6 ~62 stonebrick 0 
setblock ~38 ~0 ~63 stone_brick_stairs 3  
fill ~39 ~0 ~4 ~41 ~0 ~4 stone_slab 5 
setblock ~39 ~0 ~7 red_flower 3  
fill ~39 ~0 ~8 ~40 ~0 ~8 stone_stairs 6  
fill ~39 ~0 ~12 ~40 ~0 ~12 carpet 12  
fill ~39 ~0 ~13 ~40 ~0 ~13 carpet 12 
setblock ~39 ~0 ~27 brick_stairs 2  
fill ~39 ~0 ~62 ~40 ~0 ~62 stone_stairs 7  
fill ~40 ~0 ~5 ~41 ~0 ~5 tallgrass 1  
fill ~40 ~0 ~6 ~40 ~0 ~7 tallgrass 1  
fill ~40 ~0 ~15 ~41 ~0 ~15 carpet 13  
fill ~40 ~0 ~26 ~40 ~0 ~27 stone_slab 4 
setblock ~40 ~0 ~28 double_stone_slab 4 
setblock ~41 ~0 ~6 double_plant 2 
setblock ~41 ~0 ~7 stone_brick_stairs 2  
fill ~41 ~0 ~8 ~43 ~0 ~8 stonebrick 0  
fill ~41 ~0 ~12 ~42 ~0 ~12 carpet 13  
fill ~41 ~0 ~13 ~42 ~0 ~13 carpet 13  
fill ~41 ~0 ~25 ~42 ~0 ~25 stone_slab 4  
fill ~41 ~0 ~26 ~41 ~4 ~26 quartz_block 0 
setblock ~41 ~0 ~27 brick_stairs 0  
fill ~41 ~0 ~28 ~41 ~4 ~28 brick_block 0  
fill ~41 ~0 ~62 ~43 ~0 ~62 stonebrick 0 
setblock ~41 ~0 ~63 stone_brick_stairs 3 
setblock ~42 ~0 ~5 stone_slab 5 
setblock ~42 ~0 ~6 leaves 4  
fill ~42 ~0 ~7 ~42 ~6 ~7 cobblestone_wall 0  
fill ~42 ~0 ~9 ~43 ~0 ~9 brick_stairs 7 
setblock ~42 ~0 ~10 carpet 12 
setblock ~42 ~0 ~15 carpet 12 
setblock ~42 ~0 ~26 brick_stairs 2  
fill ~42 ~0 ~27 ~42 ~4 ~27 brick_block 0  
fill ~42 ~0 ~63 ~42 ~6 ~63 cobblestone_wall 0 
setblock ~43 ~0 ~6 stone_slab 5  
fill ~43 ~0 ~7 ~43 ~1 ~7 leaves 4  
fill ~43 ~0 ~21 ~44 ~0 ~21 brick_block 0  
fill ~43 ~0 ~22 ~44 ~0 ~22 brick_block 0 
setblock ~43 ~0 ~24 anvil 2  
fill ~43 ~0 ~26 ~44 ~0 ~26 brick_block 0  
fill ~44 ~0 ~7 ~45 ~0 ~7 stonebrick 0  
fill ~44 ~0 ~8 ~44 ~26 ~8 brick_block 0  
fill ~44 ~0 ~9 ~44 ~26 ~9 brick_block 0  
fill ~44 ~0 ~10 ~44 ~6 ~10 brick_block 0  
fill ~44 ~0 ~11 ~44 ~6 ~11 brick_block 0  
fill ~44 ~0 ~12 ~44 ~6 ~12 brick_block 0 
setblock ~44 ~0 ~13 brick_stairs 0  
fill ~44 ~0 ~14 ~44 ~6 ~14 brick_block 0 
setblock ~44 ~0 ~15 brick_stairs 0  
fill ~44 ~0 ~16 ~44 ~6 ~16 brick_block 0 
setblock ~44 ~0 ~17 brick_stairs 0  
fill ~44 ~0 ~18 ~44 ~6 ~18 brick_block 0  
fill ~44 ~0 ~19 ~44 ~6 ~19 brick_block 0  
fill ~44 ~0 ~20 ~44 ~6 ~20 brick_block 0  
fill ~44 ~0 ~23 ~44 ~6 ~23 brick_block 0  
fill ~44 ~0 ~24 ~44 ~6 ~24 brick_block 0  
fill ~44 ~0 ~25 ~44 ~26 ~25 brick_block 0  
fill ~44 ~0 ~27 ~44 ~26 ~27 brick_block 0  
fill ~44 ~0 ~28 ~44 ~6 ~28 brick_block 0  
fill ~44 ~0 ~29 ~44 ~6 ~29 brick_block 0  
fill ~44 ~0 ~30 ~44 ~6 ~30 brick_block 0  
fill ~44 ~0 ~31 ~44 ~6 ~31 brick_block 0  
fill ~44 ~0 ~32 ~44 ~6 ~32 brick_block 0  
fill ~44 ~0 ~33 ~44 ~6 ~33 brick_block 0  
fill ~44 ~0 ~34 ~44 ~6 ~34 brick_block 0  
fill ~44 ~0 ~35 ~44 ~6 ~35 brick_block 0  
fill ~44 ~0 ~36 ~44 ~6 ~36 brick_block 0  
fill ~44 ~0 ~37 ~44 ~6 ~37 brick_block 0  
fill ~44 ~0 ~38 ~44 ~6 ~38 brick_block 0  
fill ~44 ~0 ~39 ~44 ~6 ~39 brick_block 0  
fill ~44 ~0 ~40 ~44 ~6 ~40 brick_block 0  
fill ~44 ~0 ~41 ~44 ~6 ~41 brick_block 0  
fill ~44 ~0 ~42 ~44 ~6 ~42 brick_block 0  
fill ~44 ~0 ~43 ~44 ~26 ~43 brick_block 0  
fill ~44 ~0 ~44 ~44 ~26 ~44 brick_block 0  
fill ~44 ~0 ~45 ~44 ~26 ~45 brick_block 0  
fill ~44 ~0 ~46 ~44 ~6 ~46 brick_block 0  
fill ~44 ~0 ~47 ~44 ~6 ~47 brick_block 0  
fill ~44 ~0 ~48 ~44 ~6 ~48 brick_block 0  
fill ~44 ~0 ~49 ~44 ~6 ~49 brick_block 0  
fill ~44 ~0 ~50 ~44 ~6 ~50 brick_block 0  
fill ~44 ~0 ~51 ~44 ~6 ~51 brick_block 0  
fill ~44 ~0 ~52 ~44 ~6 ~52 brick_block 0  
fill ~44 ~0 ~53 ~44 ~6 ~53 brick_block 0  
fill ~44 ~0 ~54 ~44 ~6 ~54 brick_block 0  
fill ~44 ~0 ~55 ~44 ~6 ~55 brick_block 0  
fill ~44 ~0 ~56 ~44 ~6 ~56 brick_block 0  
fill ~44 ~0 ~57 ~44 ~6 ~57 brick_block 0  
fill ~44 ~0 ~58 ~44 ~6 ~58 brick_block 0  
fill ~44 ~0 ~59 ~44 ~6 ~59 brick_block 0  
fill ~44 ~0 ~60 ~44 ~6 ~60 brick_block 0  
fill ~44 ~0 ~63 ~45 ~0 ~63 stonebrick 0  
fill ~45 ~0 ~8 ~45 ~6 ~8 stonebrick 0  
fill ~45 ~0 ~9 ~45 ~0 ~7 stonebrick 0  
fill ~45 ~0 ~10 ~45 ~1 ~10 cobblestone_wall 0 
setblock ~45 ~0 ~11 stone_brick_stairs 1  
fill ~45 ~0 ~12 ~45 ~1 ~12 cobblestone_wall 0 
setblock ~45 ~0 ~13 stone_brick_stairs 1  
fill ~45 ~0 ~14 ~45 ~1 ~14 cobblestone_wall 0 
setblock ~45 ~0 ~15 stone_brick_stairs 1  
fill ~45 ~0 ~16 ~45 ~1 ~16 cobblestone_wall 0 
setblock ~45 ~0 ~17 stone_brick_stairs 1  
fill ~45 ~0 ~18 ~45 ~1 ~18 cobblestone_wall 0 
setblock ~45 ~0 ~19 stone_brick_stairs 1  
fill ~45 ~0 ~20 ~45 ~1 ~20 cobblestone_wall 0 
setblock ~45 ~0 ~21 stone_brick_stairs 1  
fill ~45 ~0 ~22 ~45 ~1 ~22 cobblestone_wall 0 
setblock ~45 ~0 ~23 stone_brick_stairs 1  
fill ~45 ~0 ~24 ~45 ~1 ~24 cobblestone_wall 0  
fill ~45 ~0 ~25 ~45 ~0 ~27 stonebrick 0  
fill ~45 ~0 ~28 ~45 ~1 ~28 cobblestone_wall 0 
setblock ~45 ~0 ~29 stone_brick_stairs 1  
fill ~45 ~0 ~30 ~45 ~1 ~30 cobblestone_wall 0 
setblock ~45 ~0 ~31 stone_brick_stairs 1  
fill ~45 ~0 ~32 ~45 ~1 ~32 cobblestone_wall 0 
setblock ~45 ~0 ~33 stone_brick_stairs 1  
fill ~45 ~0 ~34 ~45 ~1 ~34 cobblestone_wall 0 
setblock ~45 ~0 ~35 stone_brick_stairs 1  
fill ~45 ~0 ~36 ~45 ~1 ~36 cobblestone_wall 0 
setblock ~45 ~0 ~37 stone_brick_stairs 1  
fill ~45 ~0 ~38 ~45 ~1 ~38 cobblestone_wall 0 
setblock ~45 ~0 ~39 stone_brick_stairs 1  
fill ~45 ~0 ~40 ~45 ~1 ~40 cobblestone_wall 0 
setblock ~45 ~0 ~41 stone_brick_stairs 1  
fill ~45 ~0 ~42 ~45 ~1 ~42 cobblestone_wall 0  
fill ~45 ~0 ~43 ~45 ~0 ~45 stonebrick 0  
fill ~45 ~0 ~46 ~45 ~1 ~46 cobblestone_wall 0 
setblock ~45 ~0 ~47 stone_brick_stairs 1  
fill ~45 ~0 ~48 ~45 ~1 ~48 cobblestone_wall 0 
setblock ~45 ~0 ~49 stone_brick_stairs 1  
fill ~45 ~0 ~50 ~45 ~1 ~50 cobblestone_wall 0 
setblock ~45 ~0 ~51 stone_brick_stairs 1  
fill ~45 ~0 ~52 ~45 ~1 ~52 cobblestone_wall 0 
setblock ~45 ~0 ~53 stone_brick_stairs 1  
fill ~45 ~0 ~54 ~45 ~1 ~54 cobblestone_wall 0 
setblock ~45 ~0 ~55 stone_brick_stairs 1  
fill ~45 ~0 ~56 ~45 ~1 ~56 cobblestone_wall 0 
setblock ~45 ~0 ~57 stone_brick_stairs 1  
fill ~45 ~0 ~58 ~45 ~1 ~58 cobblestone_wall 0 
setblock ~45 ~0 ~59 stone_brick_stairs 1  
fill ~45 ~0 ~60 ~45 ~1 ~60 cobblestone_wall 0  
fill ~45 ~0 ~61 ~45 ~0 ~63 stonebrick 0 
setblock ~1 ~1 ~7 stone 0 
setblock ~1 ~1 ~9 stone 0 
setblock ~1 ~1 ~11 stone_brick_stairs 4 
setblock ~1 ~1 ~13 stone_brick_stairs 4 
setblock ~1 ~1 ~15 stone_brick_stairs 4 
setblock ~1 ~1 ~17 stone_brick_stairs 4 
setblock ~1 ~1 ~19 stone_brick_stairs 4 
setblock ~1 ~1 ~21 stone_brick_stairs 4 
setblock ~1 ~1 ~23 stone_brick_stairs 4 
setblock ~1 ~1 ~25 stone 0  
fill ~1 ~1 ~26 ~1 ~6 ~26 stonebrick 0 
setblock ~1 ~1 ~27 stone 0 
setblock ~1 ~1 ~29 stone_brick_stairs 4 
setblock ~1 ~1 ~31 stone_brick_stairs 4 
setblock ~1 ~1 ~33 stone_brick_stairs 4 
setblock ~1 ~1 ~35 stone_brick_stairs 4 
setblock ~1 ~1 ~37 stone_brick_stairs 4 
setblock ~1 ~1 ~39 stone_brick_stairs 4 
setblock ~1 ~1 ~41 stone_brick_stairs 4 
setblock ~1 ~1 ~43 stone 0  
fill ~1 ~1 ~44 ~1 ~6 ~44 stonebrick 0 
setblock ~1 ~1 ~45 stone 0 
setblock ~1 ~1 ~47 stone_brick_stairs 4 
setblock ~1 ~1 ~49 stone_brick_stairs 4 
setblock ~1 ~1 ~51 stone_brick_stairs 4 
setblock ~1 ~1 ~53 stone_brick_stairs 4 
setblock ~1 ~1 ~55 stone_brick_stairs 4 
setblock ~1 ~1 ~57 stone_brick_stairs 4 
setblock ~1 ~1 ~59 stone_brick_stairs 4 
setblock ~1 ~1 ~61 stone 0  
fill ~1 ~1 ~62 ~1 ~6 ~62 stonebrick 0 
setblock ~1 ~1 ~63 stone 0 
setblock ~2 ~1 ~7 stonebrick 0  
fill ~2 ~1 ~13 ~2 ~3 ~13 bookshelf 0  
fill ~2 ~1 ~15 ~2 ~3 ~15 bookshelf 0  
fill ~2 ~1 ~17 ~2 ~3 ~17 bookshelf 0  
fill ~2 ~1 ~21 ~3 ~1 ~21 brick_block 0  
fill ~2 ~1 ~22 ~2 ~6 ~22 brick_block 0  
fill ~2 ~1 ~26 ~3 ~1 ~26 brick_block 0  
fill ~3 ~1 ~8 ~5 ~1 ~8 stonebrick 0 
setblock ~3 ~1 ~22 brick_stairs 1  
fill ~3 ~1 ~25 ~3 ~3 ~25 leaves 4  
fill ~3 ~1 ~62 ~5 ~1 ~62 stonebrick 0 
setblock ~5 ~1 ~7 stone_brick_stairs 6  
fill ~5 ~1 ~28 ~5 ~4 ~28 brick_block 0 
setblock ~5 ~1 ~63 stone_brick_stairs 7  
fill ~6 ~1 ~8 ~7 ~1 ~8 stained_glass_pane 15  
fill ~6 ~1 ~29 ~13 ~1 ~29 brick_block 0  
fill ~6 ~1 ~61 ~7 ~1 ~61 wool 7  
fill ~6 ~1 ~62 ~7 ~1 ~62 stained_glass_pane 15 
setblock ~7 ~1 ~7 leaves 4  
fill ~7 ~1 ~21 ~8 ~1 ~21 brick_block 0 
setblock ~7 ~1 ~22 brick_stairs 0 
setblock ~8 ~1 ~7 stone_brick_stairs 6 
setblock ~8 ~1 ~63 stone_brick_stairs 7  
fill ~9 ~1 ~8 ~10 ~1 ~8 stained_glass_pane 15  
fill ~9 ~1 ~17 ~12 ~1 ~17 brick_block 0  
fill ~9 ~1 ~21 ~10 ~1 ~21 bookshelf 0 
setblock ~9 ~1 ~22 brick_stairs 1 
setblock ~9 ~1 ~28 heavy_weighted_pressure_plate 0  
fill ~9 ~1 ~61 ~10 ~1 ~61 wool 7  
fill ~9 ~1 ~62 ~10 ~1 ~62 stained_glass_pane 15 
setblock ~10 ~1 ~22 brick_stairs 0 
setblock ~10 ~1 ~28 flower_pot 0 
setblock ~11 ~1 ~7 stone_brick_stairs 6  
fill ~11 ~1 ~8 ~11 ~6 ~8 stonebrick 0  
fill ~11 ~1 ~14 ~11 ~1 ~15 brick_stairs 4  
fill ~11 ~1 ~18 ~11 ~4 ~18 brick_block 0  
fill ~11 ~1 ~19 ~13 ~1 ~19 brick_block 0  
fill ~11 ~1 ~20 ~12 ~1 ~20 brick_block 0  
fill ~11 ~1 ~62 ~11 ~6 ~62 stonebrick 0 
setblock ~11 ~1 ~63 stone_brick_stairs 7 
setblock ~12 ~1 ~8 stone 0  
fill ~12 ~1 ~13 ~12 ~4 ~13 brick_block 0  
fill ~12 ~1 ~14 ~12 ~4 ~14 brick_block 0  
fill ~12 ~1 ~15 ~12 ~4 ~15 brick_block 0  
fill ~12 ~1 ~16 ~12 ~4 ~16 brick_block 0  
fill ~12 ~1 ~21 ~13 ~1 ~21 leaves 4 
setblock ~12 ~1 ~22 brick_stairs 1 
setblock ~12 ~1 ~62 stone 0  
fill ~13 ~1 ~8 ~14 ~1 ~8 stonebrick 0 
setblock ~13 ~1 ~13 brick_stairs 0 
setblock ~13 ~1 ~14 brick_stairs 3 
setblock ~13 ~1 ~15 brick_stairs 2 
setblock ~13 ~1 ~16 brick_stairs 0  
fill ~13 ~1 ~20 ~13 ~2 ~20 leaves 4  
fill ~13 ~1 ~62 ~14 ~1 ~62 stonebrick 0 
setblock ~14 ~1 ~5 double_plant 8 
setblock ~14 ~1 ~7 leaves 12 
setblock ~14 ~1 ~10 brick_stairs 0  
fill ~14 ~1 ~11 ~14 ~4 ~11 brick_block 0  
fill ~14 ~1 ~12 ~16 ~1 ~12 brick_block 0  
fill ~14 ~1 ~17 ~16 ~1 ~17 brick_block 0 
setblock ~14 ~1 ~19 brick_stairs 0 
setblock ~14 ~1 ~21 brick_stairs 0  
fill ~14 ~1 ~28 ~15 ~1 ~28 brick_block 0  
fill ~14 ~1 ~63 ~14 ~1 ~64 stone_brick_stairs 4 
setblock ~14 ~1 ~65 stone_brick_stairs 7 
setblock ~14 ~1 ~67 stone_brick_stairs 6  
fill ~14 ~1 ~68 ~14 ~1 ~69 stone_brick_stairs 4 
setblock ~15 ~1 ~2 stone_slab 4  
fill ~15 ~1 ~7 ~15 ~6 ~7 stonebrick 0 
setblock ~15 ~1 ~14 brick_block 0  
fill ~15 ~1 ~21 ~15 ~4 ~21 brick_block 0  
fill ~15 ~1 ~63 ~15 ~6 ~63 stonebrick 0 
setblock ~15 ~1 ~65 stone_brick_stairs 4 
setblock ~15 ~1 ~66 stone_stairs 4 
setblock ~15 ~1 ~67 stone_brick_stairs 4  
fill ~15 ~1 ~69 ~16 ~1 ~69 stone_brick_stairs 7 
setblock ~16 ~1 ~5 leaves 4  
fill ~16 ~1 ~6 ~16 ~6 ~6 stonebrick 0  
fill ~16 ~1 ~8 ~20 ~1 ~8 brick_block 0 
setblock ~16 ~1 ~10 carpet 0  
fill ~16 ~1 ~21 ~19 ~1 ~21 iron_bars 0  
fill ~16 ~1 ~26 ~18 ~1 ~26 brick_block 0  
fill ~16 ~1 ~38 ~20 ~1 ~38 brick_block 0  
fill ~16 ~1 ~39 ~30 ~1 ~39 bookshelf 0  
fill ~16 ~1 ~64 ~16 ~6 ~64 stonebrick 0  
fill ~16 ~1 ~68 ~16 ~6 ~68 stonebrick 0  
fill ~17 ~1 ~3 ~18 ~1 ~3 stone_brick_stairs 2 
setblock ~17 ~1 ~5 double_plant 8  
fill ~17 ~1 ~6 ~17 ~5 ~6 cobblestone 0  
fill ~17 ~1 ~64 ~17 ~5 ~64 cobblestone 0  
fill ~17 ~1 ~68 ~17 ~5 ~68 cobblestone 0 
setblock ~17 ~1 ~69 stone_stairs 7  
fill ~18 ~1 ~6 ~19 ~1 ~6 stonebrick 0  
fill ~18 ~1 ~64 ~19 ~1 ~64 stonebrick 0  
fill ~18 ~1 ~68 ~18 ~6 ~68 stonebrick 0  
fill ~18 ~1 ~69 ~19 ~1 ~69 stone_brick_stairs 7 
setblock ~19 ~1 ~3 stone_stairs 2  
fill ~19 ~1 ~7 ~19 ~4 ~7 stonebrick 0  
fill ~19 ~1 ~26 ~20 ~1 ~26 brick_stairs 3  
fill ~19 ~1 ~63 ~19 ~4 ~63 stonebrick 0 
setblock ~20 ~1 ~3 stone_brick_stairs 2 
setblock ~20 ~1 ~37 brick_stairs 6  
fill ~20 ~1 ~67 ~26 ~1 ~67 stonebrick 0  
fill ~20 ~1 ~68 ~20 ~1 ~69 stone_brick_stairs 5 
setblock ~21 ~1 ~3 stone 0  
fill ~21 ~1 ~7 ~25 ~1 ~7 stonebrick 0 
setblock ~21 ~1 ~8 leaves 4  
fill ~21 ~1 ~26 ~21 ~4 ~26 brick_block 0  
fill ~21 ~1 ~38 ~22 ~1 ~38 stone_slab 4 
setblock ~21 ~1 ~68 stone_stairs 7 
setblock ~22 ~1 ~2 stone 0  
fill ~22 ~1 ~3 ~24 ~1 ~3 stonebrick 0  
fill ~22 ~1 ~4 ~24 ~1 ~4 stonebrick 0 
setblock ~22 ~1 ~31 stone_pressure_plate 0 
setblock ~22 ~1 ~33 wooden_pressure_plate 0 
setblock ~22 ~1 ~34 flower_pot 0 
setblock ~22 ~1 ~68 stone_brick_stairs 7 
setblock ~23 ~1 ~1 stone 0  
fill ~23 ~1 ~2 ~23 ~2 ~2 stonebrick 0  
fill ~23 ~1 ~8 ~23 ~2 ~8 leaves 4 
setblock ~23 ~1 ~32 flower_pot 0 
setblock ~23 ~1 ~37 brick_stairs 6  
fill ~23 ~1 ~38 ~23 ~4 ~38 brick_block 0 
setblock ~23 ~1 ~68 stone_stairs 7 
setblock ~24 ~1 ~2 stone 0 
setblock ~24 ~1 ~30 stone_pressure_plate 0 
setblock ~24 ~1 ~31 flower_pot 0 
setblock ~24 ~1 ~33 wooden_pressure_plate 0  
fill ~24 ~1 ~38 ~25 ~1 ~38 stone_slab 4 
setblock ~24 ~1 ~68 stone_brick_stairs 7  
fill ~25 ~1 ~3 ~25 ~1 ~4 cobblestone 0 
setblock ~25 ~1 ~8 leaves 4  
fill ~25 ~1 ~26 ~25 ~4 ~26 brick_block 0 
setblock ~25 ~1 ~68 stone_stairs 7 
setblock ~26 ~1 ~3 stone_brick_stairs 2  
fill ~26 ~1 ~8 ~30 ~1 ~8 brick_block 0  
fill ~26 ~1 ~26 ~27 ~1 ~26 brick_stairs 3 
setblock ~26 ~1 ~37 brick_stairs 6  
fill ~26 ~1 ~38 ~30 ~1 ~38 brick_block 0  
fill ~26 ~1 ~68 ~26 ~1 ~69 stone_brick_stairs 4 
setblock ~27 ~1 ~3 stone_stairs 2  
fill ~27 ~1 ~6 ~28 ~1 ~6 stonebrick 0  
fill ~27 ~1 ~7 ~27 ~4 ~7 stonebrick 0  
fill ~27 ~1 ~21 ~30 ~1 ~21 iron_bars 0  
fill ~27 ~1 ~63 ~27 ~4 ~63 stonebrick 0  
fill ~27 ~1 ~64 ~28 ~1 ~64 stonebrick 0  
fill ~27 ~1 ~69 ~28 ~1 ~69 stone_brick_stairs 7  
fill ~28 ~1 ~3 ~29 ~1 ~3 stone_brick_stairs 2  
fill ~28 ~1 ~26 ~30 ~1 ~26 brick_block 0  
fill ~28 ~1 ~68 ~28 ~6 ~68 stonebrick 0 
setblock ~29 ~1 ~5 double_plant 8  
fill ~29 ~1 ~6 ~29 ~5 ~6 cobblestone 0  
fill ~29 ~1 ~64 ~29 ~5 ~64 cobblestone 0  
fill ~29 ~1 ~68 ~29 ~5 ~68 cobblestone 0 
setblock ~29 ~1 ~69 stone_stairs 7  
fill ~30 ~1 ~6 ~30 ~6 ~6 stonebrick 0 
setblock ~30 ~1 ~10 carpet 0  
fill ~30 ~1 ~12 ~32 ~1 ~12 brick_block 0  
fill ~30 ~1 ~17 ~32 ~1 ~17 brick_block 0  
fill ~30 ~1 ~64 ~30 ~6 ~64 stonebrick 0  
fill ~30 ~1 ~68 ~30 ~6 ~68 stonebrick 0  
fill ~30 ~1 ~69 ~31 ~1 ~69 stone_brick_stairs 7 
setblock ~31 ~1 ~2 stone_slab 4  
fill ~31 ~1 ~7 ~31 ~6 ~7 stonebrick 0  
fill ~31 ~1 ~21 ~31 ~4 ~21 brick_block 0  
fill ~31 ~1 ~28 ~32 ~1 ~28 brick_block 0  
fill ~31 ~1 ~63 ~31 ~6 ~63 stonebrick 0 
setblock ~31 ~1 ~65 stone_brick_stairs 5 
setblock ~31 ~1 ~66 stone_stairs 5 
setblock ~31 ~1 ~67 stone_brick_stairs 5  
fill ~32 ~1 ~7 ~32 ~2 ~7 leaves 4  
fill ~32 ~1 ~8 ~33 ~1 ~8 stonebrick 0 
setblock ~32 ~1 ~10 brick_stairs 1  
fill ~32 ~1 ~11 ~32 ~4 ~11 brick_block 0 
setblock ~32 ~1 ~19 brick_stairs 1 
setblock ~32 ~1 ~21 brick_stairs 1  
fill ~32 ~1 ~62 ~33 ~1 ~62 stonebrick 0  
fill ~32 ~1 ~63 ~32 ~1 ~64 stone_brick_stairs 5 
setblock ~32 ~1 ~65 stone_brick_stairs 7 
setblock ~32 ~1 ~67 stone_brick_stairs 6  
fill ~32 ~1 ~68 ~32 ~1 ~69 stone_brick_stairs 5 
setblock ~33 ~1 ~7 double_plant 8 
setblock ~33 ~1 ~13 brick_stairs 1 
setblock ~33 ~1 ~14 brick_stairs 3 
setblock ~33 ~1 ~15 brick_stairs 2 
setblock ~33 ~1 ~16 brick_stairs 1  
fill ~33 ~1 ~19 ~35 ~1 ~19 brick_block 0 
setblock ~33 ~1 ~28 stone_slab 4  
fill ~33 ~1 ~29 ~40 ~1 ~29 brick_block 0 
setblock ~34 ~1 ~8 stone 0  
fill ~34 ~1 ~10 ~35 ~1 ~10 brick_block 0  
fill ~34 ~1 ~11 ~34 ~4 ~11 brick_block 0  
fill ~34 ~1 ~12 ~34 ~4 ~12 brick_block 0  
fill ~34 ~1 ~13 ~34 ~4 ~13 brick_block 0  
fill ~34 ~1 ~14 ~34 ~4 ~14 brick_block 0  
fill ~34 ~1 ~15 ~35 ~1 ~15 brick_block 0  
fill ~34 ~1 ~16 ~34 ~4 ~16 brick_block 0  
fill ~34 ~1 ~17 ~37 ~1 ~17 brick_block 0  
fill ~34 ~1 ~20 ~35 ~1 ~20 brick_block 0 
setblock ~34 ~1 ~22 brick_stairs 0 
setblock ~34 ~1 ~27 stone_slab 4 
setblock ~34 ~1 ~62 stone 0 
setblock ~35 ~1 ~7 stone_brick_stairs 6  
fill ~35 ~1 ~8 ~35 ~6 ~8 stonebrick 0  
fill ~35 ~1 ~11 ~35 ~1 ~14 brick_stairs 1  
fill ~35 ~1 ~18 ~35 ~13 ~18 brick_block 0 
setblock ~35 ~1 ~22 brick_stairs 1 
setblock ~35 ~1 ~27 flower_pot 0 
setblock ~35 ~1 ~28 anvil 3  
fill ~35 ~1 ~62 ~35 ~6 ~62 stonebrick 0 
setblock ~35 ~1 ~63 stone_brick_stairs 7  
fill ~36 ~1 ~8 ~37 ~1 ~8 stained_glass_pane 15  
fill ~36 ~1 ~21 ~37 ~1 ~21 spruce_stairs 3  
fill ~36 ~1 ~27 ~37 ~1 ~27 stone_slab 4  
fill ~36 ~1 ~61 ~37 ~1 ~61 wool 7  
fill ~36 ~1 ~62 ~37 ~1 ~62 stained_glass_pane 15 
setblock ~38 ~1 ~7 stone_brick_stairs 6  
fill ~38 ~1 ~21 ~39 ~1 ~21 brick_block 0 
setblock ~38 ~1 ~28 anvil 3 
setblock ~38 ~1 ~63 stone_brick_stairs 7  
fill ~39 ~1 ~8 ~40 ~1 ~8 stained_glass_pane 15 
setblock ~39 ~1 ~22 brick_stairs 1 
setblock ~39 ~1 ~27 stone_slab 4  
fill ~39 ~1 ~61 ~40 ~1 ~61 wool 7  
fill ~39 ~1 ~62 ~40 ~1 ~62 stained_glass_pane 15 
setblock ~40 ~1 ~28 stone_slab 4 
setblock ~41 ~1 ~6 double_plant 8 
setblock ~41 ~1 ~7 stone_brick_stairs 6  
fill ~41 ~1 ~8 ~43 ~1 ~8 stonebrick 0  
fill ~41 ~1 ~62 ~43 ~1 ~62 stonebrick 0 
setblock ~41 ~1 ~63 stone_brick_stairs 7  
fill ~43 ~1 ~21 ~44 ~1 ~21 brick_block 0 
setblock ~43 ~1 ~22 brick_stairs 0  
fill ~43 ~1 ~24 ~43 ~2 ~24 leaves 4  
fill ~43 ~1 ~26 ~44 ~1 ~26 brick_block 0  
fill ~44 ~1 ~7 ~44 ~0 ~7 stonebrick 0  
fill ~44 ~1 ~13 ~44 ~3 ~13 bookshelf 0  
fill ~44 ~1 ~15 ~44 ~3 ~15 bookshelf 0  
fill ~44 ~1 ~17 ~44 ~3 ~17 bookshelf 0  
fill ~44 ~1 ~22 ~44 ~6 ~22 brick_block 0  
fill ~44 ~1 ~63 ~44 ~0 ~63 stonebrick 0 
setblock ~45 ~1 ~7 stone 0 
setblock ~45 ~1 ~9 stone 0 
setblock ~45 ~1 ~11 stone_brick_stairs 5 
setblock ~45 ~1 ~13 stone_brick_stairs 5 
setblock ~45 ~1 ~15 stone_brick_stairs 5 
setblock ~45 ~1 ~17 stone_brick_stairs 5 
setblock ~45 ~1 ~19 stone_brick_stairs 5 
setblock ~45 ~1 ~21 stone_brick_stairs 5 
setblock ~45 ~1 ~23 stone_brick_stairs 5 
setblock ~45 ~1 ~25 stone 0  
fill ~45 ~1 ~26 ~45 ~6 ~26 stonebrick 0 
setblock ~45 ~1 ~27 stone 0 
setblock ~45 ~1 ~29 stone_brick_stairs 5 
setblock ~45 ~1 ~31 stone_brick_stairs 5 
setblock ~45 ~1 ~33 stone_brick_stairs 5 
setblock ~45 ~1 ~35 stone_brick_stairs 5 
setblock ~45 ~1 ~37 stone_brick_stairs 5 
setblock ~45 ~1 ~39 stone_brick_stairs 5 
setblock ~45 ~1 ~41 stone_brick_stairs 5 
setblock ~45 ~1 ~43 stone 0  
fill ~45 ~1 ~44 ~45 ~6 ~44 stonebrick 0 
setblock ~45 ~1 ~45 stone 0 
setblock ~45 ~1 ~47 stone_brick_stairs 5 
setblock ~45 ~1 ~49 stone_brick_stairs 5 
setblock ~45 ~1 ~51 stone_brick_stairs 5 
setblock ~45 ~1 ~53 stone_brick_stairs 5 
setblock ~45 ~1 ~55 stone_brick_stairs 5 
setblock ~45 ~1 ~57 stone_brick_stairs 5 
setblock ~45 ~1 ~59 stone_brick_stairs 5 
setblock ~45 ~1 ~61 stone 0  
fill ~45 ~1 ~62 ~45 ~6 ~62 stonebrick 0 
setblock ~45 ~1 ~63 stone 0 
setblock ~1 ~2 ~7 stonebrick 0 
setblock ~1 ~2 ~9 stonebrick 0 
setblock ~1 ~2 ~10 stone_brick_stairs 0  
fill ~1 ~2 ~11 ~1 ~5 ~11 stone 0 
setblock ~1 ~2 ~12 stone_brick_stairs 0  
fill ~1 ~2 ~13 ~1 ~5 ~13 stone 0 
setblock ~1 ~2 ~14 stone_brick_stairs 0  
fill ~1 ~2 ~15 ~1 ~5 ~15 stone 0 
setblock ~1 ~2 ~16 stone_brick_stairs 0  
fill ~1 ~2 ~17 ~1 ~5 ~17 stone 0 
setblock ~1 ~2 ~18 stone_brick_stairs 0  
fill ~1 ~2 ~19 ~1 ~5 ~19 stone 0 
setblock ~1 ~2 ~20 stone_brick_stairs 0  
fill ~1 ~2 ~21 ~1 ~5 ~21 stone 0 
setblock ~1 ~2 ~22 stone_brick_stairs 0  
fill ~1 ~2 ~23 ~1 ~5 ~23 stone 0 
setblock ~1 ~2 ~24 stone_brick_stairs 0 
setblock ~1 ~2 ~25 stonebrick 0 
setblock ~1 ~2 ~27 stonebrick 0 
setblock ~1 ~2 ~28 stone_brick_stairs 0  
fill ~1 ~2 ~29 ~1 ~5 ~29 stone 0 
setblock ~1 ~2 ~30 stone_brick_stairs 0  
fill ~1 ~2 ~31 ~1 ~5 ~31 stone 0 
setblock ~1 ~2 ~32 stone_brick_stairs 0  
fill ~1 ~2 ~33 ~1 ~5 ~33 stone 0 
setblock ~1 ~2 ~34 stone_brick_stairs 0  
fill ~1 ~2 ~35 ~1 ~5 ~35 stone 0 
setblock ~1 ~2 ~36 stone_brick_stairs 0  
fill ~1 ~2 ~37 ~1 ~5 ~37 stone 0 
setblock ~1 ~2 ~38 stone_brick_stairs 0  
fill ~1 ~2 ~39 ~1 ~5 ~39 stone 0 
setblock ~1 ~2 ~40 stone_brick_stairs 0  
fill ~1 ~2 ~41 ~1 ~5 ~41 stone 0 
setblock ~1 ~2 ~42 stone_brick_stairs 0 
setblock ~1 ~2 ~43 stonebrick 0 
setblock ~1 ~2 ~45 stonebrick 0 
setblock ~1 ~2 ~46 stone_brick_stairs 0  
fill ~1 ~2 ~47 ~1 ~5 ~47 stone 0 
setblock ~1 ~2 ~48 stone_brick_stairs 0  
fill ~1 ~2 ~49 ~1 ~5 ~49 stone 0 
setblock ~1 ~2 ~50 stone_brick_stairs 0  
fill ~1 ~2 ~51 ~1 ~5 ~51 stone 0 
setblock ~1 ~2 ~52 stone_brick_stairs 0  
fill ~1 ~2 ~53 ~1 ~5 ~53 stone 0 
setblock ~1 ~2 ~54 stone_brick_stairs 0  
fill ~1 ~2 ~55 ~1 ~5 ~55 stone 0 
setblock ~1 ~2 ~56 stone_brick_stairs 0  
fill ~1 ~2 ~57 ~1 ~5 ~57 stone 0 
setblock ~1 ~2 ~58 stone_brick_stairs 0  
fill ~1 ~2 ~59 ~1 ~5 ~59 stone 0 
setblock ~1 ~2 ~60 stone_brick_stairs 0 
setblock ~1 ~2 ~61 stonebrick 0 
setblock ~1 ~2 ~63 stonebrick 0 
setblock ~2 ~2 ~7 stone 0  
fill ~2 ~2 ~21 ~3 ~2 ~21 brick_block 0  
fill ~2 ~2 ~26 ~3 ~2 ~26 brick_block 0 
setblock ~2 ~2 ~63 stone 0  
fill ~3 ~2 ~8 ~5 ~2 ~8 stonebrick 0  
fill ~3 ~2 ~9 ~4 ~2 ~9 brick_stairs 7  
fill ~3 ~2 ~62 ~5 ~2 ~62 stonebrick 0 
setblock ~5 ~2 ~7 stone_brick_stairs 2 
setblock ~5 ~2 ~63 stone_brick_stairs 3  
fill ~6 ~2 ~8 ~7 ~2 ~8 stained_glass_pane 15  
fill ~6 ~2 ~29 ~13 ~2 ~29 brick_block 0  
fill ~6 ~2 ~61 ~7 ~2 ~61 wool 7  
fill ~6 ~2 ~62 ~7 ~2 ~62 stained_glass_pane 15  
fill ~7 ~2 ~21 ~8 ~2 ~21 brick_block 0 
setblock ~8 ~2 ~7 stone_brick_stairs 2  
fill ~8 ~2 ~22 ~8 ~4 ~22 quartz_block 0 
setblock ~8 ~2 ~23 brick_stairs 3 
setblock ~8 ~2 ~63 stone_brick_stairs 3  
fill ~9 ~2 ~8 ~10 ~2 ~8 stained_glass_pane 15  
fill ~9 ~2 ~17 ~12 ~2 ~17 brick_block 0  
fill ~9 ~2 ~20 ~10 ~2 ~20 spruce_stairs 3  
fill ~9 ~2 ~21 ~10 ~2 ~21 bookshelf 0  
fill ~9 ~2 ~61 ~10 ~2 ~61 wool 7  
fill ~9 ~2 ~62 ~10 ~2 ~62 stained_glass_pane 15 
setblock ~11 ~2 ~7 stone_brick_stairs 2 
setblock ~11 ~2 ~9 dark_oak_stairs 4 
setblock ~11 ~2 ~12 dark_oak_stairs 4  
fill ~11 ~2 ~19 ~13 ~2 ~19 brick_block 0  
fill ~11 ~2 ~20 ~12 ~2 ~20 brick_block 0  
fill ~11 ~2 ~22 ~11 ~4 ~22 quartz_block 0 
setblock ~11 ~2 ~23 brick_stairs 3 
setblock ~11 ~2 ~63 stone_brick_stairs 3  
fill ~12 ~2 ~8 ~14 ~2 ~8 stonebrick 0  
fill ~12 ~2 ~62 ~14 ~2 ~62 stonebrick 0  
fill ~14 ~2 ~12 ~16 ~2 ~12 brick_block 0  
fill ~14 ~2 ~13 ~14 ~3 ~13 brick_block 0  
fill ~14 ~2 ~16 ~14 ~3 ~16 brick_block 0  
fill ~14 ~2 ~17 ~16 ~2 ~17 brick_block 0  
fill ~14 ~2 ~28 ~15 ~2 ~28 brick_block 0 
setblock ~15 ~2 ~65 stone_slab 0 
setblock ~15 ~2 ~66 stone_slab 3 
setblock ~15 ~2 ~67 stone_slab 0 
setblock ~16 ~2 ~3 stone_slab 4  
fill ~16 ~2 ~8 ~20 ~2 ~8 brick_block 0  
fill ~16 ~2 ~18 ~16 ~2 ~20 stone_slab 7  
fill ~16 ~2 ~21 ~19 ~2 ~21 iron_bars 0  
fill ~16 ~2 ~26 ~18 ~2 ~26 brick_block 0  
fill ~16 ~2 ~38 ~20 ~2 ~38 brick_block 0  
fill ~16 ~2 ~39 ~30 ~2 ~39 bookshelf 0  
fill ~16 ~2 ~66 ~16 ~4 ~66 cobblestone 0 
setblock ~16 ~2 ~69 stone_slab 0 
setblock ~17 ~2 ~5 leaves 4 
setblock ~17 ~2 ~69 stone_slab 3  
fill ~18 ~2 ~4 ~20 ~2 ~4 stone_brick_stairs 2  
fill ~18 ~2 ~6 ~19 ~2 ~6 stonebrick 0  
fill ~18 ~2 ~64 ~19 ~2 ~64 stonebrick 0 
setblock ~18 ~2 ~69 stone_slab 0  
fill ~19 ~2 ~26 ~20 ~2 ~26 brick_stairs 3  
fill ~20 ~2 ~15 ~20 ~3 ~15 iron_bars 0 
setblock ~20 ~2 ~37 anvil 3  
fill ~20 ~2 ~67 ~20 ~6 ~67 stonebrick 0 
setblock ~20 ~2 ~68 stone_slab 0  
fill ~21 ~2 ~3 ~25 ~2 ~3 stonebrick 0   
fill ~21 ~2 ~4 ~25 ~2 ~4 stonebrick 0  
fill ~21 ~2 ~7 ~25 ~2 ~7 stonebrick 0  
fill ~21 ~2 ~38 ~22 ~2 ~38 stone_slab 4  
fill ~21 ~2 ~67 ~21 ~4 ~67 cobblestone 0 
setblock ~21 ~2 ~68 stone_slab 3 
setblock ~22 ~2 ~2 stonebrick 0  
fill ~22 ~2 ~67 ~22 ~6 ~67 stonebrick 0 
setblock ~22 ~2 ~68 stone_slab 0 
setblock ~23 ~2 ~1 stone_brick_stairs 2 
setblock ~23 ~2 ~37 anvil 3  
fill ~23 ~2 ~67 ~23 ~5 ~67 cobblestone 0 
setblock ~23 ~2 ~68 stone_slab 3 
setblock ~24 ~2 ~2 stonebrick 0  
fill ~24 ~2 ~38 ~25 ~2 ~38 stone_slab 4  
fill ~24 ~2 ~67 ~24 ~6 ~67 stonebrick 0 
setblock ~24 ~2 ~68 stone_slab 0  
fill ~25 ~2 ~67 ~25 ~4 ~67 cobblestone 0 
setblock ~25 ~2 ~68 stone_slab 3  
fill ~26 ~2 ~4 ~28 ~2 ~4 stone_brick_stairs 2  
fill ~26 ~2 ~8 ~30 ~2 ~8 brick_block 0  
fill ~26 ~2 ~15 ~26 ~3 ~15 iron_bars 0  
fill ~26 ~2 ~26 ~27 ~2 ~26 brick_stairs 3 
setblock ~26 ~2 ~37 anvil 3  
fill ~26 ~2 ~38 ~30 ~2 ~38 brick_block 0  
fill ~26 ~2 ~67 ~26 ~6 ~67 stonebrick 0 
setblock ~26 ~2 ~68 stone_slab 0  
fill ~27 ~2 ~6 ~28 ~2 ~6 stonebrick 0  
fill ~27 ~2 ~21 ~30 ~2 ~21 iron_bars 0  
fill ~27 ~2 ~64 ~28 ~2 ~64 stonebrick 0  
fill ~28 ~2 ~26 ~30 ~2 ~26 brick_block 0 
setblock ~28 ~2 ~69 stone_slab 0 
setblock ~29 ~2 ~69 stone_slab 3 
setblock ~30 ~2 ~3 stone_slab 4  
fill ~30 ~2 ~12 ~32 ~2 ~12 brick_block 0  
fill ~30 ~2 ~17 ~32 ~2 ~17 brick_block 0  
fill ~30 ~2 ~18 ~30 ~2 ~20 stone_slab 7  
fill ~30 ~2 ~66 ~30 ~4 ~66 cobblestone 0 
setblock ~30 ~2 ~69 stone_slab 0  
fill ~31 ~2 ~28 ~32 ~2 ~28 brick_block 0 
setblock ~31 ~2 ~65 stone_slab 0 
setblock ~31 ~2 ~66 stone_slab 3 
setblock ~31 ~2 ~67 stone_slab 0  
fill ~32 ~2 ~8 ~35 ~2 ~8 stonebrick 0  
fill ~32 ~2 ~13 ~32 ~3 ~13 brick_block 0  
fill ~32 ~2 ~16 ~32 ~3 ~16 brick_block 0  
fill ~32 ~2 ~62 ~35 ~2 ~62 stonebrick 0  
fill ~33 ~2 ~19 ~35 ~2 ~19 brick_block 0  
fill ~33 ~2 ~29 ~40 ~2 ~29 brick_block 0  
fill ~34 ~2 ~10 ~35 ~2 ~10 brick_block 0  
fill ~34 ~2 ~15 ~35 ~2 ~15 brick_block 0  
fill ~34 ~2 ~17 ~37 ~2 ~17 brick_block 0  
fill ~34 ~2 ~20 ~35 ~2 ~20 brick_block 0 
setblock ~35 ~2 ~7 stone_brick_stairs 2  
fill ~35 ~2 ~11 ~35 ~3 ~11 bookshelf 0  
fill ~35 ~2 ~12 ~35 ~3 ~12 bookshelf 0  
fill ~35 ~2 ~13 ~35 ~3 ~13 bookshelf 0  
fill ~35 ~2 ~14 ~35 ~3 ~14 bookshelf 0  
fill ~35 ~2 ~22 ~35 ~5 ~22 quartz_block 0 
setblock ~35 ~2 ~23 brick_stairs 3  
fill ~35 ~2 ~28 ~35 ~3 ~28 leaves 4 
setblock ~35 ~2 ~63 stone_brick_stairs 3  
fill ~36 ~2 ~8 ~37 ~2 ~8 stained_glass_pane 15  
fill ~36 ~2 ~20 ~37 ~2 ~20 spruce_stairs 3  
fill ~36 ~2 ~61 ~37 ~2 ~61 wool 7  
fill ~36 ~2 ~62 ~37 ~2 ~62 stained_glass_pane 15 
setblock ~38 ~2 ~7 stone_brick_stairs 2  
fill ~38 ~2 ~21 ~39 ~2 ~21 brick_block 0  
fill ~38 ~2 ~22 ~38 ~5 ~22 quartz_block 0 
setblock ~38 ~2 ~23 brick_stairs 3  
fill ~38 ~2 ~28 ~38 ~3 ~28 leaves 4 
setblock ~38 ~2 ~63 stone_brick_stairs 3  
fill ~39 ~2 ~8 ~40 ~2 ~8 stained_glass_pane 15  
fill ~39 ~2 ~61 ~40 ~2 ~61 wool 7  
fill ~39 ~2 ~62 ~40 ~2 ~62 stained_glass_pane 15 
setblock ~41 ~2 ~7 stone_brick_stairs 2  
fill ~41 ~2 ~8 ~43 ~2 ~8 stonebrick 0  
fill ~41 ~2 ~62 ~43 ~2 ~62 stonebrick 0 
setblock ~41 ~2 ~63 stone_brick_stairs 3  
fill ~42 ~2 ~9 ~43 ~2 ~9 brick_stairs 7  
fill ~43 ~2 ~21 ~44 ~2 ~21 brick_block 0  
fill ~43 ~2 ~26 ~44 ~2 ~26 brick_block 0 
setblock ~44 ~2 ~7 stone 0 
setblock ~44 ~2 ~63 stone 0 
setblock ~45 ~2 ~7 stonebrick 0 
setblock ~45 ~2 ~9 stonebrick 0 
setblock ~45 ~2 ~10 stone_brick_stairs 1  
fill ~45 ~2 ~11 ~45 ~5 ~11 stone 0 
setblock ~45 ~2 ~12 stone_brick_stairs 1  
fill ~45 ~2 ~13 ~45 ~5 ~13 stone 0 
setblock ~45 ~2 ~14 stone_brick_stairs 1  
fill ~45 ~2 ~15 ~45 ~5 ~15 stone 0 
setblock ~45 ~2 ~16 stone_brick_stairs 1  
fill ~45 ~2 ~17 ~45 ~5 ~17 stone 0 
setblock ~45 ~2 ~18 stone_brick_stairs 1  
fill ~45 ~2 ~19 ~45 ~5 ~19 stone 0 
setblock ~45 ~2 ~20 stone_brick_stairs 1  
fill ~45 ~2 ~21 ~45 ~5 ~21 stone 0 
setblock ~45 ~2 ~22 stone_brick_stairs 1  
fill ~45 ~2 ~23 ~45 ~5 ~23 stone 0 
setblock ~45 ~2 ~24 stone_brick_stairs 1 
setblock ~45 ~2 ~25 stonebrick 0 
setblock ~45 ~2 ~27 stonebrick 0 
setblock ~45 ~2 ~28 stone_brick_stairs 1  
fill ~45 ~2 ~29 ~45 ~5 ~29 stone 0 
setblock ~45 ~2 ~30 stone_brick_stairs 1  
fill ~45 ~2 ~31 ~45 ~5 ~31 stone 0 
setblock ~45 ~2 ~32 stone_brick_stairs 1  
fill ~45 ~2 ~33 ~45 ~5 ~33 stone 0 
setblock ~45 ~2 ~34 stone_brick_stairs 1  
fill ~45 ~2 ~35 ~45 ~5 ~35 stone 0 
setblock ~45 ~2 ~36 stone_brick_stairs 1  
fill ~45 ~2 ~37 ~45 ~5 ~37 stone 0 
setblock ~45 ~2 ~38 stone_brick_stairs 1  
fill ~45 ~2 ~39 ~45 ~5 ~39 stone 0 
setblock ~45 ~2 ~40 stone_brick_stairs 1  
fill ~45 ~2 ~41 ~45 ~5 ~41 stone 0 
setblock ~45 ~2 ~42 stone_brick_stairs 1 
setblock ~45 ~2 ~43 stonebrick 0 
setblock ~45 ~2 ~45 stonebrick 0 
setblock ~45 ~2 ~46 stone_brick_stairs 1  
fill ~45 ~2 ~47 ~45 ~5 ~47 stone 0 
setblock ~45 ~2 ~48 stone_brick_stairs 1  
fill ~45 ~2 ~49 ~45 ~5 ~49 stone 0 
setblock ~45 ~2 ~50 stone_brick_stairs 1  
fill ~45 ~2 ~51 ~45 ~5 ~51 stone 0 
setblock ~45 ~2 ~52 stone_brick_stairs 1  
fill ~45 ~2 ~53 ~45 ~5 ~53 stone 0 
setblock ~45 ~2 ~54 stone_brick_stairs 1  
fill ~45 ~2 ~55 ~45 ~5 ~55 stone 0 
setblock ~45 ~2 ~56 stone_brick_stairs 1  
fill ~45 ~2 ~57 ~45 ~5 ~57 stone 0 
setblock ~45 ~2 ~58 stone_brick_stairs 1  
fill ~45 ~2 ~59 ~45 ~5 ~59 stone 0 
setblock ~45 ~2 ~60 stone_brick_stairs 1 
setblock ~45 ~2 ~61 stonebrick 0 
setblock ~45 ~2 ~63 stonebrick 0 
setblock ~1 ~3 ~7 stone 0 
setblock ~1 ~3 ~9 stone 0 
setblock ~1 ~3 ~10 stone_brick_stairs 4 
setblock ~1 ~3 ~24 stone_brick_stairs 4 
setblock ~1 ~3 ~25 stone 0 
setblock ~1 ~3 ~27 stone 0 
setblock ~1 ~3 ~28 stone_brick_stairs 4 
setblock ~1 ~3 ~42 stone_brick_stairs 4 
setblock ~1 ~3 ~43 stone 0 
setblock ~1 ~3 ~45 stone 0 
setblock ~1 ~3 ~46 stone_brick_stairs 4 
setblock ~1 ~3 ~60 stone_brick_stairs 4 
setblock ~1 ~3 ~61 stone 0 
setblock ~1 ~3 ~63 stone 0 
setblock ~2 ~3 ~7 stonebrick 0  
fill ~2 ~3 ~21 ~3 ~3 ~21 brick_block 0  
fill ~2 ~3 ~26 ~3 ~3 ~26 brick_block 0 
setblock ~2 ~3 ~63 stonebrick 0  
fill ~3 ~3 ~8 ~5 ~3 ~8 stonebrick 0  
fill ~3 ~3 ~62 ~5 ~3 ~62 stonebrick 0 
setblock ~4 ~3 ~21 brick_stairs 5 
setblock ~5 ~3 ~7 stone_brick_stairs 6 
setblock ~5 ~3 ~63 stone_brick_stairs 7  
fill ~6 ~3 ~8 ~7 ~3 ~8 stained_glass_pane 15 
setblock ~6 ~3 ~21 brick_stairs 4  
fill ~6 ~3 ~29 ~13 ~3 ~29 brick_block 0  
fill ~6 ~3 ~61 ~7 ~3 ~61 wool 7  
fill ~6 ~3 ~62 ~7 ~3 ~62 stained_glass_pane 15  
fill ~7 ~3 ~21 ~8 ~3 ~21 brick_block 0 
setblock ~8 ~3 ~7 stone_brick_stairs 6 
setblock ~8 ~3 ~63 stone_brick_stairs 7  
fill ~9 ~3 ~8 ~10 ~3 ~8 stained_glass_pane 15  
fill ~9 ~3 ~17 ~12 ~3 ~17 brick_block 0  
fill ~9 ~3 ~19 ~10 ~3 ~19 spruce_stairs 3  
fill ~9 ~3 ~21 ~10 ~3 ~21 bookshelf 0  
fill ~9 ~3 ~61 ~10 ~3 ~61 wool 7  
fill ~9 ~3 ~62 ~10 ~3 ~62 stained_glass_pane 15 
setblock ~11 ~3 ~7 stone_brick_stairs 6 
setblock ~11 ~3 ~9 dark_oak_stairs 0 
setblock ~11 ~3 ~12 dark_oak_stairs 0  
fill ~11 ~3 ~19 ~13 ~3 ~19 brick_block 0  
fill ~11 ~3 ~20 ~12 ~3 ~20 brick_block 0 
setblock ~11 ~3 ~63 stone_brick_stairs 7  
fill ~12 ~3 ~8 ~13 ~3 ~8 stonebrick 0  
fill ~12 ~3 ~62 ~12 ~4 ~62 stonebrick 0  
fill ~13 ~3 ~62 ~14 ~3 ~62 stone 0 
setblock ~14 ~3 ~8 stone 0  
fill ~14 ~3 ~12 ~16 ~3 ~12 brick_block 0  
fill ~14 ~3 ~17 ~16 ~3 ~17 brick_block 0  
fill ~14 ~3 ~28 ~15 ~3 ~28 brick_block 0  
fill ~15 ~3 ~8 ~20 ~3 ~8 brick_block 0  
fill ~16 ~3 ~21 ~19 ~3 ~21 iron_bars 0  
fill ~16 ~3 ~26 ~18 ~3 ~26 brick_block 0  
fill ~16 ~3 ~38 ~20 ~3 ~38 brick_block 0  
fill ~16 ~3 ~39 ~30 ~3 ~39 bookshelf 0 
setblock ~17 ~3 ~4 stone_slab 4  
fill ~18 ~3 ~6 ~19 ~3 ~6 stonebrick 0  
fill ~18 ~3 ~64 ~19 ~3 ~64 stonebrick 0  
fill ~19 ~3 ~5 ~20 ~3 ~5 stone_brick_stairs 2  
fill ~19 ~3 ~26 ~20 ~3 ~26 brick_stairs 3 
setblock ~20 ~3 ~22 brick_stairs 7 
setblock ~20 ~3 ~24 brick_stairs 6 
setblock ~20 ~3 ~37 leaves 5 
setblock ~21 ~3 ~3 stone_brick_stairs 4 
setblock ~21 ~3 ~5 stone_stairs 2  
fill ~21 ~3 ~7 ~25 ~3 ~7 stonebrick 0 
setblock ~21 ~3 ~8 brick_stairs 5  
fill ~21 ~3 ~38 ~22 ~3 ~38 stone_slab 4 
setblock ~22 ~3 ~2 stone_brick_stairs 4  
fill ~22 ~3 ~3 ~24 ~3 ~3 grass 0  
fill ~22 ~3 ~4 ~22 ~3 ~5 stonebrick 0 
setblock ~22 ~3 ~26 brick_stairs 5 
setblock ~23 ~3 ~1 stone_brick_stairs 6 
setblock ~23 ~3 ~2 grass 0 
setblock ~23 ~3 ~4 grass 0  
fill ~23 ~3 ~5 ~24 ~3 ~5 stonebrick 0 
setblock ~23 ~3 ~37 leaves 5 
setblock ~24 ~3 ~2 stone_brick_stairs 5 
setblock ~24 ~3 ~4 stonebrick 0 
setblock ~24 ~3 ~26 brick_stairs 4  
fill ~24 ~3 ~38 ~25 ~3 ~38 stone_slab 4 
setblock ~25 ~3 ~3 stone_brick_stairs 5 
setblock ~25 ~3 ~5 stone_stairs 2 
setblock ~25 ~3 ~8 brick_stairs 4  
fill ~26 ~3 ~5 ~27 ~3 ~5 stone_brick_stairs 2  
fill ~26 ~3 ~8 ~31 ~3 ~8 brick_block 0 
setblock ~26 ~3 ~22 brick_stairs 7 
setblock ~26 ~3 ~24 brick_stairs 6  
fill ~26 ~3 ~26 ~27 ~3 ~26 brick_stairs 3 
setblock ~26 ~3 ~37 leaves 5  
fill ~26 ~3 ~38 ~30 ~3 ~38 brick_block 0  
fill ~27 ~3 ~6 ~28 ~3 ~6 stonebrick 0  
fill ~27 ~3 ~21 ~30 ~3 ~21 iron_bars 0  
fill ~27 ~3 ~64 ~28 ~3 ~64 stonebrick 0  
fill ~28 ~3 ~26 ~30 ~3 ~26 brick_block 0 
setblock ~29 ~3 ~4 stone_slab 4  
fill ~30 ~3 ~12 ~32 ~3 ~12 brick_block 0  
fill ~30 ~3 ~17 ~32 ~3 ~17 brick_block 0  
fill ~31 ~3 ~28 ~32 ~3 ~28 brick_block 0 
setblock ~32 ~3 ~8 stone 0  
fill ~32 ~3 ~62 ~33 ~3 ~62 stone 0  
fill ~33 ~3 ~8 ~35 ~3 ~8 stonebrick 0  
fill ~33 ~3 ~19 ~35 ~3 ~19 brick_block 0  
fill ~33 ~3 ~29 ~40 ~3 ~29 brick_block 0  
fill ~34 ~3 ~10 ~35 ~3 ~10 brick_block 0  
fill ~34 ~3 ~15 ~35 ~3 ~15 brick_block 0  
fill ~34 ~3 ~17 ~37 ~3 ~17 brick_block 0  
fill ~34 ~3 ~20 ~35 ~3 ~20 brick_block 0  
fill ~34 ~3 ~62 ~34 ~4 ~62 stonebrick 0 
setblock ~35 ~3 ~7 stone_brick_stairs 6 
setblock ~35 ~3 ~63 stone_brick_stairs 7  
fill ~36 ~3 ~8 ~37 ~3 ~8 stained_glass_pane 15  
fill ~36 ~3 ~19 ~37 ~3 ~19 spruce_stairs 3  
fill ~36 ~3 ~61 ~37 ~3 ~61 wool 7  
fill ~36 ~3 ~62 ~37 ~3 ~62 stained_glass_pane 15 
setblock ~38 ~3 ~7 stone_brick_stairs 6  
fill ~38 ~3 ~21 ~39 ~3 ~21 brick_block 0 
setblock ~38 ~3 ~63 stone_brick_stairs 7  
fill ~39 ~3 ~8 ~40 ~3 ~8 stained_glass_pane 15  
fill ~39 ~3 ~61 ~40 ~3 ~61 wool 7  
fill ~39 ~3 ~62 ~40 ~3 ~62 stained_glass_pane 15 
setblock ~40 ~3 ~21 brick_stairs 5 
setblock ~41 ~3 ~7 stone_brick_stairs 6  
fill ~41 ~3 ~8 ~43 ~3 ~8 stonebrick 0  
fill ~41 ~3 ~62 ~43 ~3 ~62 stonebrick 0 
setblock ~41 ~3 ~63 stone_brick_stairs 7 
setblock ~42 ~3 ~21 brick_stairs 4  
fill ~43 ~3 ~21 ~44 ~3 ~21 brick_block 0  
fill ~43 ~3 ~26 ~44 ~3 ~26 brick_block 0 
setblock ~44 ~3 ~7 stonebrick 0 
setblock ~44 ~3 ~63 stonebrick 0 
setblock ~45 ~3 ~7 stone 0 
setblock ~45 ~3 ~9 stone 0 
setblock ~45 ~3 ~10 stone_brick_stairs 5 
setblock ~45 ~3 ~24 stone_brick_stairs 5 
setblock ~45 ~3 ~25 stone 0 
setblock ~45 ~3 ~27 stone 0 
setblock ~45 ~3 ~28 stone_brick_stairs 5 
setblock ~45 ~3 ~42 stone_brick_stairs 5 
setblock ~45 ~3 ~43 stone 0 
setblock ~45 ~3 ~45 stone 0 
setblock ~45 ~3 ~46 stone_brick_stairs 5 
setblock ~45 ~3 ~60 stone_brick_stairs 5 
setblock ~45 ~3 ~61 stone 0 
setblock ~45 ~3 ~63 stone 0 
setblock ~1 ~4 ~7 stonebrick 0 
setblock ~1 ~4 ~9 stonebrick 0 
setblock ~1 ~4 ~12 stone_brick_stairs 4 
setblock ~1 ~4 ~22 stone_brick_stairs 4 
setblock ~1 ~4 ~25 stonebrick 0 
setblock ~1 ~4 ~27 stonebrick 0 
setblock ~1 ~4 ~30 stone_brick_stairs 4 
setblock ~1 ~4 ~40 stone_brick_stairs 4 
setblock ~1 ~4 ~43 stonebrick 0 
setblock ~1 ~4 ~45 stonebrick 0 
setblock ~1 ~4 ~48 stone_brick_stairs 4 
setblock ~1 ~4 ~58 stone_brick_stairs 4 
setblock ~1 ~4 ~61 stonebrick 0 
setblock ~1 ~4 ~63 stonebrick 0 
setblock ~2 ~4 ~7 stone 0 
setblock ~2 ~4 ~13 brick_stairs 5 
setblock ~2 ~4 ~15 brick_stairs 5 
setblock ~2 ~4 ~17 brick_stairs 5  
fill ~2 ~4 ~21 ~8 ~4 ~21 brick_block 0  
fill ~2 ~4 ~26 ~3 ~4 ~26 brick_block 0 
setblock ~2 ~4 ~63 stone 0  
fill ~3 ~4 ~8 ~5 ~4 ~8 stonebrick 0 
setblock ~3 ~4 ~22 brick_stairs 5  
fill ~3 ~4 ~23 ~7 ~4 ~23 stone_slab 12  
fill ~3 ~4 ~24 ~19 ~4 ~24 stone_slab 12  
fill ~3 ~4 ~25 ~4 ~4 ~25 stone_slab 12  
fill ~3 ~4 ~62 ~5 ~4 ~62 stonebrick 0  
fill ~4 ~4 ~22 ~6 ~4 ~22 stone_slab 12 
setblock ~4 ~4 ~26 brick_stairs 6 
setblock ~5 ~4 ~7 stone_brick_stairs 2 
setblock ~5 ~4 ~25 brick_stairs 6 
setblock ~5 ~4 ~27 brick_stairs 5 
setblock ~5 ~4 ~63 stone_brick_stairs 3  
fill ~6 ~4 ~8 ~7 ~4 ~8 stained_glass_pane 15  
fill ~6 ~4 ~25 ~13 ~4 ~25 stone_slab 12 
setblock ~6 ~4 ~26 brick_stairs 5  
fill ~6 ~4 ~27 ~13 ~4 ~27 stone_slab 12  
fill ~6 ~4 ~28 ~13 ~4 ~28 stone_slab 12  
fill ~6 ~4 ~29 ~13 ~4 ~29 brick_block 0  
fill ~6 ~4 ~61 ~7 ~4 ~61 wool 7  
fill ~6 ~4 ~62 ~7 ~4 ~62 stained_glass_pane 15 
setblock ~7 ~4 ~22 brick_stairs 4  
fill ~7 ~4 ~26 ~12 ~4 ~26 stone_slab 12  
fill ~7 ~4 ~56 ~7 ~4 ~60 brick_block 0 
setblock ~8 ~4 ~7 stone_brick_stairs 2 
setblock ~8 ~4 ~23 brick_stairs 7 
setblock ~8 ~4 ~46 glowstone 0 
setblock ~8 ~4 ~63 stone_brick_stairs 3  
fill ~9 ~4 ~8 ~10 ~4 ~8 stained_glass_pane 15  
fill ~9 ~4 ~17 ~12 ~4 ~17 brick_block 0  
fill ~9 ~4 ~18 ~10 ~4 ~18 spruce_stairs 3  
fill ~9 ~4 ~21 ~10 ~4 ~21 bookshelf 0 
setblock ~9 ~4 ~22 brick_stairs 5  
fill ~9 ~4 ~23 ~10 ~4 ~23 stone_slab 12 
setblock ~9 ~4 ~39 glowstone 0  
fill ~9 ~4 ~61 ~10 ~4 ~61 wool 7  
fill ~9 ~4 ~62 ~10 ~4 ~62 stained_glass_pane 15 
setblock ~10 ~4 ~22 brick_stairs 4 
setblock ~11 ~4 ~7 stone_brick_stairs 2  
fill ~11 ~4 ~9 ~11 ~4 ~12 dark_oak_stairs 4  
fill ~11 ~4 ~19 ~13 ~4 ~19 brick_block 0  
fill ~11 ~4 ~20 ~12 ~4 ~20 brick_block 0 
setblock ~11 ~4 ~23 brick_stairs 7 
setblock ~11 ~4 ~63 stone_brick_stairs 3  
fill ~12 ~4 ~8 ~14 ~4 ~8 stonebrick 0  
fill ~12 ~4 ~21 ~14 ~4 ~21 stone_slab 12 
setblock ~12 ~4 ~22 brick_stairs 5  
fill ~12 ~4 ~23 ~19 ~4 ~23 stone_slab 12 
setblock ~13 ~4 ~13 brick_stairs 4 
setblock ~13 ~4 ~14 brick_stairs 7 
setblock ~13 ~4 ~15 brick_stairs 6 
setblock ~13 ~4 ~16 brick_stairs 4 
setblock ~13 ~4 ~20 stone_slab 12  
fill ~13 ~4 ~22 ~19 ~4 ~22 stone_slab 12 
setblock ~13 ~4 ~26 brick_stairs 4  
fill ~13 ~4 ~56 ~13 ~4 ~60 brick_block 0  
fill ~13 ~4 ~62 ~14 ~4 ~62 stonebrick 0 
setblock ~14 ~4 ~10 brick_stairs 4 
setblock ~14 ~4 ~13 stonebrick 0 
setblock ~14 ~4 ~16 stonebrick 0 
setblock ~14 ~4 ~19 brick_stairs 4 
setblock ~14 ~4 ~25 brick_stairs 6 
setblock ~14 ~4 ~27 brick_stairs 4  
fill ~14 ~4 ~28 ~15 ~4 ~28 brick_block 0  
fill ~15 ~4 ~8 ~31 ~4 ~8 stone 0  
fill ~15 ~4 ~9 ~22 ~4 ~9 stone 0  
fill ~15 ~4 ~10 ~21 ~4 ~10 stone 0  
fill ~15 ~4 ~11 ~22 ~4 ~11 stone 0  
fill ~15 ~4 ~12 ~31 ~4 ~12 stone 0  
fill ~15 ~4 ~13 ~31 ~4 ~13 stone 0  
fill ~15 ~4 ~14 ~31 ~4 ~14 stone 0  
fill ~15 ~4 ~15 ~31 ~4 ~15 stone 0  
fill ~15 ~4 ~16 ~31 ~4 ~16 stone 0  
fill ~15 ~4 ~17 ~31 ~4 ~17 stone 0  
fill ~15 ~4 ~18 ~22 ~4 ~18 stone 0  
fill ~15 ~4 ~19 ~21 ~4 ~19 stone 0  
fill ~15 ~4 ~20 ~22 ~4 ~20 stone 0  
fill ~15 ~4 ~25 ~19 ~4 ~25 stone_slab 12 
setblock ~15 ~4 ~26 brick_stairs 6 
setblock ~15 ~4 ~30 brick_block 0 
setblock ~15 ~4 ~32 brick_block 0 
setblock ~15 ~4 ~34 brick_block 0  
fill ~16 ~4 ~21 ~19 ~4 ~21 brick_stairs 7  
fill ~16 ~4 ~26 ~30 ~4 ~26 brick_block 0 
setblock ~16 ~4 ~27 stone_slab 12 
setblock ~16 ~4 ~28 brick_stairs 4  
fill ~16 ~4 ~29 ~16 ~4 ~35 stone_slab 12 
setblock ~16 ~4 ~36 brick_stairs 4 
setblock ~16 ~4 ~37 stone_slab 12  
fill ~16 ~4 ~38 ~30 ~4 ~38 brick_block 0  
fill ~16 ~4 ~39 ~30 ~4 ~39 bookshelf 0 
setblock ~17 ~4 ~27 brick_stairs 6 
setblock ~17 ~4 ~29 brick_stairs 7  
fill ~17 ~4 ~30 ~17 ~4 ~34 trapdoor 11 
setblock ~17 ~4 ~35 brick_stairs 6 
setblock ~17 ~4 ~37 brick_stairs 7 
setblock ~18 ~4 ~5 stone_slab 4  
fill ~18 ~4 ~6 ~18 ~6 ~6 stonebrick 0  
fill ~18 ~4 ~27 ~28 ~4 ~27 stone_slab 12 
setblock ~18 ~4 ~28 brick_stairs 5  
fill ~18 ~4 ~29 ~28 ~4 ~29 stone_slab 12  
fill ~18 ~4 ~30 ~19 ~4 ~30 stone_slab 12  
fill ~18 ~4 ~31 ~19 ~4 ~31 stone_slab 12  
fill ~18 ~4 ~32 ~19 ~4 ~32 stone_slab 12  
fill ~18 ~4 ~33 ~19 ~4 ~33 stone_slab 12  
fill ~18 ~4 ~34 ~19 ~4 ~34 stone_slab 12  
fill ~18 ~4 ~35 ~28 ~4 ~35 stone_slab 12 
setblock ~18 ~4 ~36 brick_stairs 5  
fill ~18 ~4 ~37 ~28 ~4 ~37 stone_slab 12  
fill ~18 ~4 ~64 ~18 ~6 ~64 stonebrick 0  
fill ~19 ~4 ~6 ~19 ~6 ~6 quartz_block 2  
fill ~19 ~4 ~28 ~27 ~4 ~28 trapdoor 8  
fill ~19 ~4 ~36 ~27 ~4 ~36 trapdoor 8  
fill ~19 ~4 ~64 ~19 ~6 ~64 quartz_block 2 
setblock ~20 ~4 ~6 stone_brick_stairs 2  
fill ~20 ~4 ~22 ~20 ~4 ~26 brick_block 0  
fill ~20 ~4 ~30 ~20 ~4 ~33 trapdoor 10 
setblock ~20 ~4 ~34 trapdoor 8 
setblock ~21 ~4 ~3 stone_slab 5 
setblock ~21 ~4 ~6 stone_stairs 2  
fill ~21 ~4 ~21 ~25 ~4 ~21 brick_stairs 7  
fill ~21 ~4 ~22 ~22 ~4 ~22 wooden_slab 9  
fill ~21 ~4 ~23 ~21 ~4 ~25 wooden_slab 9  
fill ~21 ~4 ~30 ~25 ~4 ~30 stone_slab 12  
fill ~21 ~4 ~31 ~25 ~4 ~31 stone_slab 12  
fill ~21 ~4 ~32 ~25 ~4 ~32 stone_slab 12  
fill ~21 ~4 ~33 ~25 ~4 ~33 stone_slab 12  
fill ~21 ~4 ~34 ~25 ~4 ~34 stone_slab 12 
setblock ~21 ~4 ~53 glowstone 0 
setblock ~22 ~4 ~2 stone_slab 5 
setblock ~22 ~4 ~3 tallgrass 1 
setblock ~22 ~4 ~4 leaves 4  
fill ~22 ~4 ~5 ~24 ~4 ~5 stone_slab 5 
setblock ~22 ~4 ~6 stone_brick_stairs 2 
setblock ~22 ~4 ~10 brick_stairs 5 
setblock ~22 ~4 ~19 brick_stairs 5  
fill ~22 ~4 ~23 ~22 ~4 ~24 brick_stairs 5 
setblock ~22 ~4 ~25 wooden_slab 9 
setblock ~23 ~4 ~1 stone_slab 5 
setblock ~23 ~4 ~3 leaves 4  
fill ~23 ~4 ~4 ~23 ~5 ~4 leaves 12 
setblock ~23 ~4 ~6 stone_stairs 2 
setblock ~23 ~4 ~9 brick_stairs 7 
setblock ~23 ~4 ~10 glowstone 0 
setblock ~23 ~4 ~11 brick_stairs 6 
setblock ~23 ~4 ~18 brick_stairs 7 
setblock ~23 ~4 ~19 glowstone 0 
setblock ~23 ~4 ~20 brick_stairs 6 
setblock ~23 ~4 ~22 brick_stairs 7  
fill ~23 ~4 ~23 ~23 ~4 ~24 glowstone 0 
setblock ~23 ~4 ~25 brick_stairs 6 
setblock ~24 ~4 ~2 stone_slab 5 
setblock ~24 ~4 ~3 double_plant 2 
setblock ~24 ~4 ~4 stone_slab 5 
setblock ~24 ~4 ~6 stone_brick_stairs 2  
fill ~24 ~4 ~9 ~31 ~4 ~9 stone 0 
setblock ~24 ~4 ~10 brick_stairs 4  
fill ~24 ~4 ~11 ~31 ~4 ~11 stone 0  
fill ~24 ~4 ~18 ~31 ~4 ~18 stone 0 
setblock ~24 ~4 ~19 brick_stairs 4  
fill ~24 ~4 ~20 ~31 ~4 ~20 stone 0  
fill ~24 ~4 ~22 ~25 ~4 ~22 wooden_slab 9  
fill ~24 ~4 ~23 ~24 ~4 ~24 brick_stairs 4  
fill ~24 ~4 ~25 ~25 ~4 ~25 wooden_slab 9 
setblock ~25 ~4 ~3 stone_slab 5 
setblock ~25 ~4 ~6 stone_stairs 2  
fill ~25 ~4 ~10 ~31 ~4 ~10 stone 0  
fill ~25 ~4 ~19 ~31 ~4 ~19 stone 0  
fill ~25 ~4 ~23 ~25 ~4 ~25 wooden_slab 9 
setblock ~25 ~4 ~53 glowstone 0 
setblock ~26 ~4 ~6 stone_brick_stairs 2  
fill ~26 ~4 ~22 ~26 ~4 ~26 brick_block 0  
fill ~26 ~4 ~30 ~26 ~4 ~34 trapdoor 10  
fill ~27 ~4 ~6 ~27 ~6 ~6 quartz_block 2  
fill ~27 ~4 ~21 ~30 ~4 ~21 brick_stairs 7  
fill ~27 ~4 ~22 ~33 ~4 ~22 stone_slab 12  
fill ~27 ~4 ~23 ~34 ~4 ~23 stone_slab 12  
fill ~27 ~4 ~24 ~43 ~4 ~24 stone_slab 12  
fill ~27 ~4 ~25 ~31 ~4 ~25 stone_slab 12  
fill ~27 ~4 ~30 ~28 ~4 ~30 stone_slab 12  
fill ~27 ~4 ~31 ~28 ~4 ~31 stone_slab 12  
fill ~27 ~4 ~32 ~28 ~4 ~32 stone_slab 12  
fill ~27 ~4 ~33 ~28 ~4 ~33 stone_slab 12  
fill ~27 ~4 ~34 ~28 ~4 ~34 stone_slab 12  
fill ~27 ~4 ~64 ~27 ~6 ~64 quartz_block 2 
setblock ~28 ~4 ~5 stone_slab 4  
fill ~28 ~4 ~6 ~28 ~6 ~6 stonebrick 0 
setblock ~28 ~4 ~28 brick_stairs 4 
setblock ~28 ~4 ~36 brick_stairs 4  
fill ~28 ~4 ~64 ~28 ~6 ~64 stonebrick 0 
setblock ~29 ~4 ~27 brick_stairs 6 
setblock ~29 ~4 ~29 brick_stairs 7  
fill ~29 ~4 ~30 ~29 ~4 ~34 trapdoor 10 
setblock ~29 ~4 ~35 brick_stairs 6 
setblock ~29 ~4 ~37 brick_stairs 7 
setblock ~30 ~4 ~27 stone_slab 12 
setblock ~30 ~4 ~28 brick_stairs 5  
fill ~30 ~4 ~29 ~30 ~4 ~35 stone_slab 12 
setblock ~30 ~4 ~36 brick_stairs 5 
setblock ~30 ~4 ~37 stone_slab 12 
setblock ~31 ~4 ~26 brick_stairs 6  
fill ~31 ~4 ~28 ~32 ~4 ~28 brick_block 0 
setblock ~31 ~4 ~30 brick_block 0 
setblock ~31 ~4 ~32 brick_block 0 
setblock ~31 ~4 ~34 brick_block 0  
fill ~32 ~4 ~8 ~35 ~4 ~8 stonebrick 0 
setblock ~32 ~4 ~10 brick_stairs 5 
setblock ~32 ~4 ~13 stonebrick 0 
setblock ~32 ~4 ~16 stonebrick 0 
setblock ~32 ~4 ~19 brick_stairs 5  
fill ~32 ~4 ~21 ~34 ~4 ~21 stone_slab 12 
setblock ~32 ~4 ~25 brick_stairs 6 
setblock ~32 ~4 ~27 brick_stairs 5  
fill ~32 ~4 ~62 ~35 ~4 ~62 stonebrick 0 
setblock ~33 ~4 ~13 brick_stairs 5 
setblock ~33 ~4 ~14 brick_stairs 7 
setblock ~33 ~4 ~15 brick_stairs 6 
setblock ~33 ~4 ~16 brick_stairs 5  
fill ~33 ~4 ~19 ~35 ~4 ~19 brick_block 0 
setblock ~33 ~4 ~20 stone_slab 12  
fill ~33 ~4 ~25 ~40 ~4 ~25 stone_slab 12 
setblock ~33 ~4 ~26 brick_stairs 5  
fill ~33 ~4 ~27 ~40 ~4 ~27 stone_slab 12  
fill ~33 ~4 ~28 ~40 ~4 ~28 brick_stairs 6  
fill ~33 ~4 ~29 ~40 ~4 ~29 brick_block 0  
fill ~33 ~4 ~57 ~33 ~4 ~59 brick_block 0  
fill ~34 ~4 ~10 ~35 ~4 ~10 brick_block 0  
fill ~34 ~4 ~15 ~35 ~4 ~15 brick_block 0  
fill ~34 ~4 ~17 ~37 ~4 ~17 brick_block 0  
fill ~34 ~4 ~20 ~35 ~4 ~20 brick_block 0 
setblock ~34 ~4 ~22 brick_stairs 4  
fill ~34 ~4 ~26 ~39 ~4 ~26 stone_slab 12 
setblock ~35 ~4 ~7 stone_brick_stairs 2  
fill ~35 ~4 ~11 ~35 ~4 ~14 brick_stairs 5 
setblock ~35 ~4 ~23 brick_stairs 7 
setblock ~35 ~4 ~63 stone_brick_stairs 3  
fill ~36 ~4 ~8 ~37 ~4 ~8 stained_glass_pane 15  
fill ~36 ~4 ~18 ~37 ~4 ~18 spruce_stairs 3  
fill ~36 ~4 ~61 ~37 ~4 ~61 wool 7  
fill ~36 ~4 ~62 ~37 ~4 ~62 stained_glass_pane 15 
setblock ~37 ~4 ~39 glowstone 0 
setblock ~37 ~4 ~45 glowstone 0 
setblock ~38 ~4 ~7 stone_brick_stairs 2  
fill ~38 ~4 ~21 ~44 ~4 ~21 brick_block 0 
setblock ~38 ~4 ~23 brick_stairs 7 
setblock ~38 ~4 ~46 glowstone 0 
setblock ~38 ~4 ~63 stone_brick_stairs 3  
fill ~39 ~4 ~8 ~40 ~4 ~8 stained_glass_pane 15 
setblock ~39 ~4 ~22 brick_stairs 5  
fill ~39 ~4 ~23 ~43 ~4 ~23 stone_slab 12  
fill ~39 ~4 ~46 ~39 ~15 ~46 brick_block 0  
fill ~39 ~4 ~57 ~39 ~4 ~59 brick_block 0  
fill ~39 ~4 ~61 ~40 ~4 ~61 wool 7  
fill ~39 ~4 ~62 ~40 ~4 ~62 stained_glass_pane 15  
fill ~40 ~4 ~22 ~42 ~4 ~22 stone_slab 12 
setblock ~40 ~4 ~26 brick_stairs 4 
setblock ~41 ~4 ~7 stone_brick_stairs 2  
fill ~41 ~4 ~8 ~43 ~4 ~8 stonebrick 0 
setblock ~41 ~4 ~25 brick_stairs 6 
setblock ~41 ~4 ~27 brick_stairs 4  
fill ~41 ~4 ~62 ~43 ~4 ~62 stonebrick 0 
setblock ~41 ~4 ~63 stone_brick_stairs 3  
fill ~42 ~4 ~25 ~43 ~4 ~25 stone_slab 12 
setblock ~42 ~4 ~26 brick_stairs 6 
setblock ~43 ~4 ~22 brick_stairs 4  
fill ~43 ~4 ~26 ~44 ~4 ~26 brick_block 0 
setblock ~44 ~4 ~7 stone 0 
setblock ~44 ~4 ~13 brick_stairs 4 
setblock ~44 ~4 ~15 brick_stairs 4 
setblock ~44 ~4 ~17 brick_stairs 4 
setblock ~44 ~4 ~63 stone 0 
setblock ~45 ~4 ~7 stonebrick 0 
setblock ~45 ~4 ~9 stonebrick 0 
setblock ~45 ~4 ~12 stone_brick_stairs 5 
setblock ~45 ~4 ~22 stone_brick_stairs 5 
setblock ~45 ~4 ~25 stonebrick 0 
setblock ~45 ~4 ~27 stonebrick 0 
setblock ~45 ~4 ~30 stone_brick_stairs 5 
setblock ~45 ~4 ~40 stone_brick_stairs 5 
setblock ~45 ~4 ~43 stonebrick 0 
setblock ~45 ~4 ~45 stonebrick 0 
setblock ~45 ~4 ~48 stone_brick_stairs 5 
setblock ~45 ~4 ~58 stone_brick_stairs 5 
setblock ~45 ~4 ~61 stonebrick 0 
setblock ~45 ~4 ~63 stonebrick 0 
setblock ~1 ~5 ~7 stone 0 
setblock ~1 ~5 ~9 stone 0 
setblock ~1 ~5 ~14 stone_brick_stairs 4 
setblock ~1 ~5 ~20 stone_brick_stairs 4 
setblock ~1 ~5 ~25 stone 0 
setblock ~1 ~5 ~27 stone 0 
setblock ~1 ~5 ~32 stone_brick_stairs 4 
setblock ~1 ~5 ~38 stone_brick_stairs 4 
setblock ~1 ~5 ~43 stone 0 
setblock ~1 ~5 ~45 stone 0 
setblock ~1 ~5 ~50 stone_brick_stairs 4 
setblock ~1 ~5 ~56 stone_brick_stairs 4 
setblock ~1 ~5 ~61 stone 0 
setblock ~1 ~5 ~63 stone 0  
fill ~2 ~5 ~7 ~2 ~6 ~7 stonebrick 0  
fill ~2 ~5 ~13 ~2 ~6 ~13 brick_block 0  
fill ~2 ~5 ~15 ~2 ~6 ~15 brick_block 0  
fill ~2 ~5 ~17 ~2 ~6 ~17 brick_block 0  
fill ~2 ~5 ~21 ~2 ~6 ~21 brick_block 0  
fill ~2 ~5 ~26 ~2 ~26 ~26 brick_block 0  
fill ~2 ~5 ~63 ~2 ~6 ~63 stonebrick 0  
fill ~3 ~5 ~8 ~12 ~5 ~8 stonebrick 0  
fill ~3 ~5 ~9 ~21 ~5 ~9 planks 1  
fill ~3 ~5 ~10 ~22 ~5 ~10 planks 1  
fill ~3 ~5 ~11 ~43 ~5 ~11 planks 1  
fill ~3 ~5 ~12 ~43 ~5 ~12 planks 1  
fill ~3 ~5 ~13 ~43 ~5 ~13 planks 1  
fill ~3 ~5 ~14 ~21 ~5 ~14 planks 1  
fill ~3 ~5 ~15 ~43 ~5 ~15 planks 1  
fill ~3 ~5 ~16 ~43 ~5 ~16 planks 1  
fill ~3 ~5 ~17 ~34 ~5 ~17 planks 1  
fill ~3 ~5 ~18 ~12 ~5 ~18 planks 1  
fill ~3 ~5 ~19 ~34 ~5 ~19 planks 1  
fill ~3 ~5 ~20 ~12 ~5 ~20 planks 1  
fill ~3 ~5 ~21 ~8 ~5 ~21 planks 1  
fill ~3 ~5 ~22 ~12 ~5 ~22 planks 1  
fill ~3 ~5 ~23 ~12 ~5 ~23 planks 1  
fill ~3 ~5 ~24 ~12 ~5 ~24 planks 1  
fill ~3 ~5 ~25 ~12 ~5 ~25 planks 1  
fill ~3 ~5 ~26 ~12 ~5 ~26 planks 1  
fill ~3 ~5 ~27 ~12 ~5 ~27 planks 1  
fill ~3 ~5 ~28 ~11 ~5 ~28 planks 1  
fill ~3 ~5 ~29 ~12 ~5 ~29 planks 1  
fill ~3 ~5 ~30 ~11 ~5 ~30 planks 1  
fill ~3 ~5 ~31 ~12 ~5 ~31 planks 1  
fill ~3 ~5 ~32 ~11 ~5 ~32 planks 1  
fill ~3 ~5 ~33 ~12 ~5 ~33 planks 1  
fill ~3 ~5 ~34 ~11 ~5 ~34 planks 1  
fill ~3 ~5 ~35 ~11 ~5 ~35 planks 1  
fill ~3 ~5 ~36 ~8 ~5 ~36 planks 1  
fill ~3 ~5 ~37 ~7 ~5 ~37 planks 1  
fill ~3 ~5 ~38 ~7 ~5 ~38 planks 1  
fill ~3 ~5 ~39 ~7 ~5 ~39 planks 1  
fill ~3 ~5 ~40 ~7 ~5 ~40 planks 1  
fill ~3 ~5 ~41 ~7 ~5 ~41 planks 1  
fill ~3 ~5 ~42 ~7 ~5 ~42 planks 1  
fill ~3 ~5 ~43 ~7 ~5 ~43 planks 1  
fill ~3 ~5 ~44 ~7 ~5 ~44 planks 1  
fill ~3 ~5 ~45 ~3 ~15 ~45 quartz_block 2  
fill ~3 ~5 ~46 ~6 ~5 ~46 planks 1  
fill ~3 ~5 ~47 ~7 ~5 ~47 planks 1  
fill ~3 ~5 ~48 ~7 ~5 ~48 planks 1  
fill ~3 ~5 ~49 ~7 ~5 ~49 planks 1  
fill ~3 ~5 ~50 ~7 ~5 ~50 planks 1  
fill ~3 ~5 ~51 ~7 ~5 ~51 planks 1  
fill ~3 ~5 ~52 ~7 ~5 ~52 planks 1  
fill ~3 ~5 ~53 ~7 ~5 ~53 planks 1  
fill ~3 ~5 ~54 ~15 ~5 ~54 planks 1  
fill ~3 ~5 ~55 ~43 ~5 ~55 planks 1  
fill ~3 ~5 ~56 ~43 ~5 ~56 planks 1  
fill ~3 ~5 ~57 ~6 ~5 ~57 planks 1  
fill ~3 ~5 ~58 ~6 ~5 ~58 planks 1  
fill ~3 ~5 ~59 ~6 ~5 ~59 planks 1  
fill ~3 ~5 ~60 ~43 ~5 ~60 planks 1  
fill ~3 ~5 ~61 ~43 ~5 ~61 planks 1  
fill ~3 ~5 ~62 ~11 ~5 ~62 stonebrick 0  
fill ~4 ~5 ~45 ~7 ~5 ~45 planks 1 
setblock ~5 ~5 ~7 stone_brick_stairs 6 
setblock ~5 ~5 ~63 stone_brick_stairs 7  
fill ~7 ~5 ~46 ~7 ~15 ~46 brick_block 0 
setblock ~7 ~5 ~57 standing_sign 14 
setblock ~7 ~5 ~58 standing_sign 12 
setblock ~7 ~5 ~59 standing_sign 10 
setblock ~8 ~5 ~7 stone_brick_stairs 6  
fill ~8 ~5 ~37 ~38 ~5 ~37 wool 13  
fill ~8 ~5 ~38 ~38 ~5 ~38 wool 13  
fill ~8 ~5 ~39 ~8 ~5 ~45 wool 13 
setblock ~8 ~5 ~46 cauldron 0  
fill ~8 ~5 ~47 ~38 ~5 ~47 wool 13  
fill ~8 ~5 ~48 ~38 ~5 ~48 wool 13  
fill ~8 ~5 ~49 ~38 ~5 ~49 wool 13  
fill ~8 ~5 ~50 ~38 ~5 ~50 wool 13  
fill ~8 ~5 ~51 ~38 ~5 ~51 wool 13  
fill ~8 ~5 ~52 ~38 ~5 ~52 wool 13  
fill ~8 ~5 ~53 ~20 ~5 ~53 wool 13  
fill ~8 ~5 ~57 ~12 ~5 ~57 planks 1  
fill ~8 ~5 ~58 ~8 ~5 ~61 planks 1 
setblock ~8 ~5 ~63 stone_brick_stairs 7  
fill ~9 ~5 ~36 ~10 ~5 ~36 wool 13 
setblock ~9 ~5 ~39 cauldron 0  
fill ~9 ~5 ~40 ~32 ~5 ~40 wool 13  
fill ~9 ~5 ~41 ~21 ~5 ~41 wool 13  
fill ~9 ~5 ~42 ~21 ~5 ~42 wool 13  
fill ~9 ~5 ~43 ~38 ~5 ~43 wool 13  
fill ~9 ~5 ~44 ~38 ~5 ~44 wool 13  
fill ~9 ~5 ~45 ~38 ~5 ~45 wool 13  
fill ~9 ~5 ~46 ~37 ~5 ~46 wool 13  
fill ~9 ~5 ~58 ~11 ~5 ~58 glowstone 0  
fill ~9 ~5 ~59 ~12 ~5 ~59 planks 1  
fill ~10 ~5 ~21 ~12 ~5 ~21 planks 1  
fill ~10 ~5 ~39 ~36 ~5 ~39 wool 13 
setblock ~11 ~5 ~7 stone_brick_stairs 6 
setblock ~11 ~5 ~36 planks 1 
setblock ~11 ~5 ~63 stone_brick_stairs 7  
fill ~12 ~5 ~28 ~33 ~5 ~28 wool 13  
fill ~12 ~5 ~30 ~34 ~5 ~30 wool 13  
fill ~12 ~5 ~32 ~34 ~5 ~32 wool 13  
fill ~12 ~5 ~34 ~34 ~5 ~34 wool 13  
fill ~12 ~5 ~35 ~34 ~5 ~35 wool 13  
fill ~12 ~5 ~36 ~34 ~5 ~36 wool 13 
setblock ~12 ~5 ~58 planks 1 
setblock ~12 ~5 ~62 stone 0  
fill ~13 ~5 ~8 ~14 ~5 ~8 stone 0 
setblock ~13 ~5 ~18 glowstone 0  
fill ~13 ~5 ~20 ~13 ~5 ~53 wool 13 
setblock ~13 ~5 ~57 standing_sign 2 
setblock ~13 ~5 ~58 standing_sign 4 
setblock ~13 ~5 ~59 standing_sign 6  
fill ~13 ~5 ~62 ~14 ~5 ~62 stonebrick 0  
fill ~14 ~5 ~7 ~14 ~6 ~7 leaves 4  
fill ~14 ~5 ~18 ~32 ~5 ~18 planks 1 
setblock ~14 ~5 ~20 glowstone 0  
fill ~14 ~5 ~21 ~16 ~5 ~21 wool 13  
fill ~14 ~5 ~22 ~33 ~5 ~22 wool 13  
fill ~14 ~5 ~23 ~19 ~5 ~23 wool 13  
fill ~14 ~5 ~24 ~33 ~5 ~24 wool 13  
fill ~14 ~5 ~25 ~33 ~5 ~25 wool 13  
fill ~14 ~5 ~26 ~22 ~5 ~26 wool 13  
fill ~14 ~5 ~27 ~33 ~5 ~27 wool 13  
fill ~14 ~5 ~29 ~33 ~5 ~29 wool 13  
fill ~14 ~5 ~31 ~33 ~5 ~31 wool 13  
fill ~14 ~5 ~33 ~33 ~5 ~33 wool 13  
fill ~14 ~5 ~57 ~32 ~5 ~57 planks 1  
fill ~14 ~5 ~58 ~32 ~5 ~58 planks 1  
fill ~14 ~5 ~59 ~32 ~5 ~59 planks 1 
setblock ~15 ~5 ~20 planks 1  
fill ~16 ~5 ~54 ~16 ~15 ~54 brick_block 0 
setblock ~16 ~5 ~66 stone_brick_stairs 4  
fill ~17 ~5 ~20 ~20 ~5 ~20 planks 1  
fill ~17 ~5 ~21 ~29 ~5 ~21 planks 1  
fill ~17 ~5 ~54 ~18 ~5 ~54 brick_stairs 2 
setblock ~18 ~5 ~63 brick_stairs 6  
fill ~19 ~5 ~7 ~20 ~5 ~7 quartz_block 2  
fill ~19 ~5 ~54 ~19 ~15 ~54 brick_block 0  
fill ~19 ~5 ~63 ~19 ~6 ~63 quartz_block 2  
fill ~20 ~5 ~8 ~26 ~5 ~8 stonebrick 0 
setblock ~20 ~5 ~23 planks 1  
fill ~20 ~5 ~54 ~22 ~5 ~54 planks 1  
fill ~20 ~5 ~62 ~26 ~5 ~62 stonebrick 0 
setblock ~20 ~5 ~66 stonebrick 0 
setblock ~20 ~5 ~68 quartz_stairs 3  
fill ~21 ~5 ~7 ~22 ~5 ~7 stone_brick_stairs 2  
fill ~21 ~5 ~20 ~22 ~5 ~20 glowstone 0 
setblock ~21 ~5 ~23 glowstone 0 
setblock ~21 ~5 ~53 cauldron 0 
setblock ~21 ~5 ~67 stone_brick_stairs 7  
fill ~22 ~5 ~9 ~24 ~5 ~9 stonebrick 0  
fill ~22 ~5 ~14 ~24 ~5 ~14 glowstone 0  
fill ~22 ~5 ~23 ~24 ~5 ~23 wool 13  
fill ~22 ~5 ~41 ~24 ~5 ~41 glowstone 0  
fill ~22 ~5 ~42 ~22 ~5 ~41 glowstone 0  
fill ~22 ~5 ~53 ~24 ~5 ~53 wool 13 
setblock ~22 ~5 ~68 stone_slab 15 
setblock ~23 ~5 ~7 stone_stairs 2 
setblock ~23 ~5 ~10 stonebrick 0 
setblock ~23 ~5 ~20 planks 1 
setblock ~23 ~5 ~42 wool 13 
setblock ~23 ~5 ~54 glowstone 0 
setblock ~24 ~5 ~3 double_plant 8  
fill ~24 ~5 ~7 ~25 ~5 ~7 stone_brick_stairs 2  
fill ~24 ~5 ~10 ~43 ~5 ~10 planks 1  
fill ~24 ~5 ~20 ~25 ~5 ~20 glowstone 0  
fill ~24 ~5 ~26 ~33 ~5 ~26 wool 13 
setblock ~24 ~5 ~42 glowstone 0  
fill ~24 ~5 ~54 ~27 ~5 ~54 planks 1 
setblock ~24 ~5 ~68 stone_slab 15  
fill ~25 ~5 ~9 ~43 ~5 ~9 planks 1  
fill ~25 ~5 ~14 ~43 ~5 ~14 planks 1 
setblock ~25 ~5 ~23 glowstone 0  
fill ~25 ~5 ~41 ~38 ~5 ~41 wool 13  
fill ~25 ~5 ~42 ~38 ~5 ~42 wool 13 
setblock ~25 ~5 ~53 cauldron 0 
setblock ~25 ~5 ~67 stone_brick_stairs 7  
fill ~26 ~5 ~7 ~27 ~5 ~7 quartz_block 2  
fill ~26 ~5 ~20 ~31 ~5 ~20 planks 1  
fill ~26 ~5 ~23 ~33 ~5 ~23 wool 13  
fill ~26 ~5 ~53 ~38 ~5 ~53 wool 13 
setblock ~26 ~5 ~68 quartz_stairs 3  
fill ~27 ~5 ~63 ~27 ~6 ~63 quartz_block 2  
fill ~28 ~5 ~54 ~29 ~5 ~54 brick_stairs 2 
setblock ~28 ~5 ~63 brick_stairs 6  
fill ~30 ~5 ~21 ~33 ~5 ~21 wool 13  
fill ~30 ~5 ~54 ~30 ~15 ~54 brick_block 0 
setblock ~30 ~5 ~66 stone_brick_stairs 5  
fill ~31 ~5 ~54 ~43 ~5 ~54 planks 1  
fill ~32 ~5 ~7 ~32 ~6 ~7 leaves 4  
fill ~32 ~5 ~8 ~33 ~5 ~8 stone 0 
setblock ~32 ~5 ~20 glowstone 0  
fill ~32 ~5 ~62 ~33 ~5 ~62 stonebrick 0 
setblock ~33 ~5 ~18 glowstone 0 
setblock ~33 ~5 ~20 wool 13 
setblock ~33 ~5 ~40 cobblestone_wall 0 
setblock ~33 ~5 ~57 standing_sign 6 
setblock ~33 ~5 ~58 standing_sign 4 
setblock ~33 ~5 ~59 standing_sign 2  
fill ~34 ~5 ~8 ~34 ~6 ~8 stonebrick 0 
setblock ~34 ~5 ~18 planks 1  
fill ~34 ~5 ~20 ~34 ~5 ~29 planks 1  
fill ~34 ~5 ~31 ~43 ~5 ~31 planks 1  
fill ~34 ~5 ~33 ~43 ~5 ~33 planks 1  
fill ~34 ~5 ~40 ~38 ~5 ~40 wool 13  
fill ~34 ~5 ~57 ~38 ~5 ~57 planks 1  
fill ~34 ~5 ~58 ~34 ~5 ~61 planks 1 
setblock ~34 ~5 ~62 stone 0 
setblock ~35 ~5 ~7 stone_brick_stairs 6  
fill ~35 ~5 ~17 ~35 ~26 ~17 brick_block 0  
fill ~35 ~5 ~19 ~35 ~26 ~19 brick_block 0  
fill ~35 ~5 ~20 ~35 ~8 ~20 brick_block 0  
fill ~35 ~5 ~23 ~35 ~5 ~36 planks 1  
fill ~35 ~5 ~58 ~37 ~5 ~58 glowstone 0  
fill ~35 ~5 ~59 ~38 ~5 ~59 planks 1 
setblock ~35 ~5 ~63 stone_brick_stairs 7  
fill ~36 ~5 ~8 ~43 ~5 ~8 stonebrick 0  
fill ~36 ~5 ~17 ~37 ~5 ~17 spruce_stairs 3  
fill ~36 ~5 ~22 ~37 ~5 ~22 brick_stairs 6  
fill ~36 ~5 ~23 ~37 ~5 ~23 brick_block 0  
fill ~36 ~5 ~24 ~43 ~5 ~24 planks 1  
fill ~36 ~5 ~25 ~43 ~5 ~25 planks 1  
fill ~36 ~5 ~26 ~43 ~5 ~26 planks 1  
fill ~36 ~5 ~27 ~43 ~5 ~27 planks 1  
fill ~36 ~5 ~28 ~43 ~5 ~28 planks 1   
fill ~36 ~5 ~29 ~43 ~5 ~29 planks 1  
fill ~36 ~5 ~30 ~43 ~5 ~30 planks 1  
fill ~36 ~5 ~32 ~43 ~5 ~32 planks 1  
fill ~36 ~5 ~34 ~43 ~5 ~34 planks 1  
fill ~36 ~5 ~35 ~43 ~5 ~35 planks 1  
fill ~36 ~5 ~36 ~37 ~5 ~36 wool 13  
fill ~36 ~5 ~62 ~43 ~5 ~62 stonebrick 0 
setblock ~37 ~5 ~39 cauldron 0 
setblock ~38 ~5 ~7 stone_brick_stairs 6  
fill ~38 ~5 ~17 ~38 ~26 ~17 brick_block 0  
fill ~38 ~5 ~21 ~38 ~13 ~21 brick_block 0  
fill ~38 ~5 ~23 ~43 ~5 ~23 planks 1  
fill ~38 ~5 ~36 ~43 ~5 ~36 planks 1 
setblock ~38 ~5 ~39 wool 13 
setblock ~38 ~5 ~46 cauldron 0 
setblock ~38 ~5 ~58 planks 1 
setblock ~38 ~5 ~63 stone_brick_stairs 7  
fill ~39 ~5 ~17 ~43 ~5 ~17 planks 1  
fill ~39 ~5 ~18 ~43 ~5 ~18 planks 1  
fill ~39 ~5 ~19 ~43 ~5 ~19 planks 1  
fill ~39 ~5 ~20 ~43 ~5 ~20 planks 1  
fill ~39 ~5 ~21 ~43 ~5 ~21 planks 1  
fill ~39 ~5 ~22 ~43 ~5 ~22 planks 1  
fill ~39 ~5 ~37 ~43 ~5 ~37 planks 1  
fill ~39 ~5 ~38 ~43 ~5 ~38 planks 1  
fill ~39 ~5 ~39 ~43 ~5 ~39 planks 1  
fill ~39 ~5 ~40 ~43 ~5 ~40 planks 1  
fill ~39 ~5 ~41 ~43 ~5 ~41 planks 1  
fill ~39 ~5 ~42 ~43 ~5 ~42 planks 1  
fill ~39 ~5 ~43 ~43 ~5 ~43 planks 1  
fill ~39 ~5 ~44 ~43 ~5 ~44 planks 1  
fill ~39 ~5 ~45 ~43 ~5 ~45 planks 1  
fill ~39 ~5 ~47 ~43 ~5 ~47 planks 1  
fill ~39 ~5 ~48 ~43 ~5 ~48 planks 1  
fill ~39 ~5 ~49 ~43 ~5 ~49 planks 1  
fill ~39 ~5 ~50 ~43 ~5 ~50 planks 1  
fill ~39 ~5 ~51 ~43 ~5 ~51 planks 1  
fill ~39 ~5 ~52 ~43 ~5 ~52 planks 1  
fill ~39 ~5 ~53 ~43 ~5 ~53 planks 1 
setblock ~39 ~5 ~57 standing_sign 10 
setblock ~39 ~5 ~58 standing_sign 12 
setblock ~39 ~5 ~59 standing_sign 14  
fill ~40 ~5 ~46 ~43 ~5 ~46 planks 1  
fill ~40 ~5 ~57 ~43 ~5 ~57 planks 1  
fill ~40 ~5 ~58 ~43 ~5 ~58 planks 1  
fill ~40 ~5 ~59 ~43 ~5 ~59 planks 1 
setblock ~41 ~5 ~7 stone_brick_stairs 6 
setblock ~41 ~5 ~63 stone_brick_stairs 7  
fill ~44 ~5 ~7 ~44 ~6 ~7 stonebrick 0  
fill ~44 ~5 ~13 ~44 ~6 ~13 brick_block 0  
fill ~44 ~5 ~15 ~44 ~6 ~15 brick_block 0  
fill ~44 ~5 ~17 ~44 ~6 ~17 brick_block 0  
fill ~44 ~5 ~21 ~44 ~6 ~21 brick_block 0  
fill ~44 ~5 ~26 ~44 ~26 ~26 brick_block 0  
fill ~44 ~5 ~63 ~44 ~6 ~63 stonebrick 0 
setblock ~45 ~5 ~7 stone 0 
setblock ~45 ~5 ~9 stone 0 
setblock ~45 ~5 ~14 stone_brick_stairs 5 
setblock ~45 ~5 ~20 stone_brick_stairs 5 
setblock ~45 ~5 ~25 stone 0 
setblock ~45 ~5 ~27 stone 0 
setblock ~45 ~5 ~32 stone_brick_stairs 5 
setblock ~45 ~5 ~38 stone_brick_stairs 5 
setblock ~45 ~5 ~43 stone 0 
setblock ~45 ~5 ~45 stone 0 
setblock ~45 ~5 ~50 stone_brick_stairs 5 
setblock ~45 ~5 ~56 stone_brick_stairs 5 
setblock ~45 ~5 ~61 stone 0 
setblock ~45 ~5 ~63 stone 0 
setblock ~1 ~6 ~7 stonebrick 0 
setblock ~1 ~6 ~9 stonebrick 0 
setblock ~1 ~6 ~11 stonebrick 0 
setblock ~1 ~6 ~13 stonebrick 0 
setblock ~1 ~6 ~15 stonebrick 0 
setblock ~1 ~6 ~16 stone_brick_stairs 4 
setblock ~1 ~6 ~17 stonebrick 0 
setblock ~1 ~6 ~18 stone_brick_stairs 4 
setblock ~1 ~6 ~19 stonebrick 0 
setblock ~1 ~6 ~21 stonebrick 0 
setblock ~1 ~6 ~23 stonebrick 0 
setblock ~1 ~6 ~25 stonebrick 0 
setblock ~1 ~6 ~27 stonebrick 0 
setblock ~1 ~6 ~29 stonebrick 0 
setblock ~1 ~6 ~31 stonebrick 0 
setblock ~1 ~6 ~33 stonebrick 0 
setblock ~1 ~6 ~34 stone_brick_stairs 4 
setblock ~1 ~6 ~35 stonebrick 0 
setblock ~1 ~6 ~36 stone_brick_stairs 4 
setblock ~1 ~6 ~37 stonebrick 0 
setblock ~1 ~6 ~39 stonebrick 0 
setblock ~1 ~6 ~41 stonebrick 0 
setblock ~1 ~6 ~43 stonebrick 0 
setblock ~1 ~6 ~45 stonebrick 0 
setblock ~1 ~6 ~47 stonebrick 0 
setblock ~1 ~6 ~49 stonebrick 0 
setblock ~1 ~6 ~51 stonebrick 0 
setblock ~1 ~6 ~52 stone_brick_stairs 4 
setblock ~1 ~6 ~53 stonebrick 0 
setblock ~1 ~6 ~54 stone_brick_stairs 4 
setblock ~1 ~6 ~55 stonebrick 0 
setblock ~1 ~6 ~57 stonebrick 0 
