setblock ~88 ~0 ~91 stone_slab 13 
setblock ~88 ~0 ~111 stone_slab 13 
setblock ~91 ~0 ~88 stone_slab 13  
fill ~91 ~0 ~101 ~111 ~0 ~101 stone 0 
setblock ~91 ~0 ~114 stone_slab 13  
fill ~92 ~0 ~97 ~92 ~200 ~97 stained_hardened_clay 9  
fill ~92 ~0 ~98 ~94 ~0 ~98 stained_hardened_clay 9  
fill ~92 ~0 ~99 ~94 ~0 ~99 stone 0  
fill ~92 ~0 ~100 ~94 ~0 ~100 stained_hardened_clay 9  
fill ~92 ~0 ~102 ~94 ~0 ~102 stained_hardened_clay 9  
fill ~92 ~0 ~103 ~94 ~0 ~103 stone 0  
fill ~92 ~0 ~104 ~94 ~0 ~104 stained_hardened_clay 9  
fill ~92 ~0 ~105 ~92 ~200 ~105 stained_hardened_clay 9  
fill ~93 ~0 ~96 ~95 ~0 ~96 stained_hardened_clay 9  
fill ~93 ~0 ~97 ~94 ~0 ~97 stone 0  
fill ~93 ~0 ~105 ~94 ~0 ~105 stone 0  
fill ~93 ~0 ~106 ~95 ~0 ~106 stained_hardened_clay 9 
setblock ~94 ~0 ~94 stone 0  
fill ~94 ~0 ~95 ~94 ~200 ~95 stained_hardened_clay 9  
fill ~94 ~0 ~107 ~94 ~200 ~107 stained_hardened_clay 9 
setblock ~94 ~0 ~108 stone 0 
setblock ~95 ~0 ~86 stone_slab 13  
fill ~95 ~0 ~93 ~96 ~0 ~93 stained_hardened_clay 9  
fill ~95 ~0 ~94 ~96 ~0 ~94 stained_hardened_clay 9 
setblock ~95 ~0 ~95 stone 0  
fill ~95 ~0 ~97 ~96 ~0 ~97 stained_hardened_clay 9  
fill ~95 ~0 ~98 ~96 ~0 ~98 stone 0  
fill ~95 ~0 ~99 ~96 ~0 ~99 stained_hardened_clay 9  
fill ~95 ~0 ~100 ~107 ~0 ~100 stone 0  
fill ~95 ~0 ~102 ~107 ~0 ~102 stone 0  
fill ~95 ~0 ~103 ~96 ~0 ~103 stained_hardened_clay 9  
fill ~95 ~0 ~104 ~96 ~0 ~104 stone 0  
fill ~95 ~0 ~105 ~96 ~0 ~105 stained_hardened_clay 9 
setblock ~95 ~0 ~107 stone 0  
fill ~95 ~0 ~108 ~96 ~0 ~108 stained_hardened_clay 9  
fill ~95 ~0 ~109 ~96 ~0 ~109 stained_hardened_clay 9 
setblock ~95 ~0 ~116 stone_slab 13  
fill ~96 ~0 ~95 ~97 ~0 ~95 stained_hardened_clay 9 
setblock ~96 ~0 ~96 stone 0 
setblock ~96 ~0 ~106 stone 0  
fill ~96 ~0 ~107 ~97 ~0 ~107 stained_hardened_clay 9  
fill ~97 ~0 ~92 ~98 ~0 ~92 stained_hardened_clay 9  
fill ~97 ~0 ~93 ~97 ~0 ~94 stone 0  
fill ~97 ~0 ~96 ~97 ~200 ~96 stained_hardened_clay 9 
setblock ~97 ~0 ~97 stone 0  
fill ~97 ~0 ~98 ~97 ~200 ~98 stained_hardened_clay 9  
fill ~97 ~0 ~99 ~105 ~0 ~99 stone 0  
fill ~97 ~0 ~103 ~105 ~0 ~103 stone 0  
fill ~97 ~0 ~104 ~97 ~200 ~104 stained_hardened_clay 9 
setblock ~97 ~0 ~105 stone 0  
fill ~97 ~0 ~106 ~97 ~200 ~106 stained_hardened_clay 9  
fill ~97 ~0 ~108 ~97 ~0 ~109 stone 0  
fill ~97 ~0 ~110 ~98 ~0 ~110 stained_hardened_clay 9  
fill ~98 ~0 ~93 ~98 ~200 ~93 stained_hardened_clay 9  
fill ~98 ~0 ~94 ~98 ~200 ~94 stained_hardened_clay 9  
fill ~98 ~0 ~95 ~98 ~0 ~96 stone 0  
fill ~98 ~0 ~97 ~98 ~200 ~97 stained_hardened_clay 9  
fill ~98 ~0 ~98 ~104 ~0 ~98 stone 0  
fill ~98 ~0 ~104 ~104 ~0 ~104 stone 0  
fill ~98 ~0 ~105 ~98 ~200 ~105 stained_hardened_clay 9  
fill ~98 ~0 ~106 ~98 ~0 ~107 stone 0  
fill ~98 ~0 ~108 ~98 ~200 ~108 stained_hardened_clay 9  
fill ~98 ~0 ~109 ~98 ~200 ~109 stained_hardened_clay 9 
setblock ~99 ~0 ~85 stone_slab 13  
fill ~99 ~0 ~92 ~99 ~0 ~94 stone 0  
fill ~99 ~0 ~95 ~99 ~200 ~95 stained_hardened_clay 9  
fill ~99 ~0 ~96 ~99 ~200 ~96 stained_hardened_clay 9  
fill ~99 ~0 ~97 ~103 ~0 ~97 stone 0  
fill ~99 ~0 ~105 ~103 ~0 ~105 stone 0  
fill ~99 ~0 ~106 ~99 ~200 ~106 stained_hardened_clay 9  
fill ~99 ~0 ~107 ~99 ~200 ~107 stained_hardened_clay 9  
fill ~99 ~0 ~108 ~99 ~0 ~110 stone 0 
setblock ~99 ~0 ~117 stone_slab 13  
fill ~100 ~0 ~92 ~100 ~200 ~92 stained_hardened_clay 9  
fill ~100 ~0 ~93 ~100 ~200 ~93 stained_hardened_clay 9  
fill ~100 ~0 ~94 ~100 ~200 ~94 stained_hardened_clay 9  
fill ~100 ~0 ~95 ~102 ~0 ~95 stone 0  
fill ~100 ~0 ~96 ~102 ~0 ~96 stone 0  
fill ~100 ~0 ~106 ~102 ~0 ~106 stone 0  
fill ~100 ~0 ~107 ~102 ~0 ~107 stone 0  
fill ~100 ~0 ~108 ~100 ~200 ~108 stained_hardened_clay 9  
fill ~100 ~0 ~109 ~100 ~200 ~109 stained_hardened_clay 9  
fill ~100 ~0 ~110 ~100 ~200 ~110 stained_hardened_clay 9  
fill ~101 ~0 ~91 ~101 ~0 ~111 stone 0  
fill ~102 ~0 ~92 ~102 ~200 ~92 stained_hardened_clay 9  
fill ~102 ~0 ~93 ~102 ~200 ~93 stained_hardened_clay 9  
fill ~102 ~0 ~94 ~102 ~200 ~94 stained_hardened_clay 9  
fill ~102 ~0 ~108 ~102 ~200 ~108 stained_hardened_clay 9  
fill ~102 ~0 ~109 ~102 ~200 ~109 stained_hardened_clay 9  
fill ~102 ~0 ~110 ~102 ~200 ~110 stained_hardened_clay 9 
setblock ~103 ~0 ~85 stone_slab 13  
fill ~103 ~0 ~92 ~103 ~0 ~94 stone 0  
fill ~103 ~0 ~95 ~103 ~200 ~95 stained_hardened_clay 9  
fill ~103 ~0 ~96 ~103 ~200 ~96 stained_hardened_clay 9  
fill ~103 ~0 ~106 ~103 ~200 ~106 stained_hardened_clay 9  
fill ~103 ~0 ~107 ~103 ~200 ~107 stained_hardened_clay 9  
fill ~103 ~0 ~108 ~103 ~0 ~110 stone 0 
setblock ~103 ~0 ~117 stone_slab 13  
fill ~104 ~0 ~92 ~105 ~0 ~92 stained_hardened_clay 9  
fill ~104 ~0 ~93 ~104 ~200 ~93 stained_hardened_clay 9  
fill ~104 ~0 ~94 ~104 ~200 ~94 stained_hardened_clay 9  
fill ~104 ~0 ~95 ~104 ~0 ~96 stone 0  
fill ~104 ~0 ~97 ~104 ~200 ~97 stained_hardened_clay 9  
fill ~104 ~0 ~105 ~104 ~200 ~105 stained_hardened_clay 9  
fill ~104 ~0 ~106 ~104 ~0 ~107 stone 0  
fill ~104 ~0 ~108 ~104 ~200 ~108 stained_hardened_clay 9  
fill ~104 ~0 ~109 ~104 ~200 ~109 stained_hardened_clay 9  
fill ~104 ~0 ~110 ~105 ~0 ~110 stained_hardened_clay 9  
fill ~105 ~0 ~93 ~105 ~0 ~94 stone 0  
fill ~105 ~0 ~95 ~106 ~0 ~95 stained_hardened_clay 9  
fill ~105 ~0 ~96 ~105 ~200 ~96 stained_hardened_clay 9 
setblock ~105 ~0 ~97 stone 0  
fill ~105 ~0 ~98 ~105 ~200 ~98 stained_hardened_clay 9  
fill ~105 ~0 ~104 ~105 ~200 ~104 stained_hardened_clay 9 
setblock ~105 ~0 ~105 stone 0  
fill ~105 ~0 ~106 ~105 ~200 ~106 stained_hardened_clay 9  
fill ~105 ~0 ~107 ~106 ~0 ~107 stained_hardened_clay 9  
fill ~105 ~0 ~108 ~105 ~0 ~109 stone 0  
fill ~106 ~0 ~93 ~107 ~0 ~93 stained_hardened_clay 9  
fill ~106 ~0 ~94 ~107 ~0 ~94 stained_hardened_clay 9 
setblock ~106 ~0 ~96 stone 0  
fill ~106 ~0 ~97 ~107 ~0 ~97 stained_hardened_clay 9  
fill ~106 ~0 ~98 ~107 ~0 ~98 stone 0  
fill ~106 ~0 ~99 ~107 ~0 ~99 stained_hardened_clay 9  
fill ~106 ~0 ~103 ~107 ~0 ~103 stained_hardened_clay 9  
fill ~106 ~0 ~104 ~107 ~0 ~104 stone 0  
fill ~106 ~0 ~105 ~107 ~0 ~105 stained_hardened_clay 9 
setblock ~106 ~0 ~106 stone 0  
fill ~106 ~0 ~108 ~107 ~0 ~108 stained_hardened_clay 9  
fill ~106 ~0 ~109 ~107 ~0 ~109 stained_hardened_clay 9 
setblock ~107 ~0 ~86 stone_slab 13 
setblock ~107 ~0 ~95 stone 0  
fill ~107 ~0 ~96 ~109 ~0 ~96 stained_hardened_clay 9  
fill ~107 ~0 ~106 ~109 ~0 ~106 stained_hardened_clay 9 
setblock ~107 ~0 ~107 stone 0 
setblock ~107 ~0 ~116 stone_slab 13 
setblock ~108 ~0 ~94 stone 0  
fill ~108 ~0 ~95 ~108 ~200 ~95 stained_hardened_clay 9  
fill ~108 ~0 ~97 ~109 ~0 ~97 stone 0  
fill ~108 ~0 ~98 ~110 ~0 ~98 stained_hardened_clay 9  
fill ~108 ~0 ~99 ~110 ~0 ~99 stone 0  
fill ~108 ~0 ~100 ~110 ~0 ~100 stained_hardened_clay 9  
fill ~108 ~0 ~102 ~110 ~0 ~102 stained_hardened_clay 9  
fill ~108 ~0 ~103 ~110 ~0 ~103 stone 0  
fill ~108 ~0 ~104 ~110 ~0 ~104 stained_hardened_clay 9  
fill ~108 ~0 ~105 ~109 ~0 ~105 stone 0  
fill ~108 ~0 ~107 ~108 ~200 ~107 stained_hardened_clay 9 
setblock ~108 ~0 ~108 stone 0  
fill ~110 ~0 ~97 ~110 ~200 ~97 stained_hardened_clay 9  
fill ~110 ~0 ~105 ~110 ~200 ~105 stained_hardened_clay 9 
setblock ~111 ~0 ~88 stone_slab 13 
setblock ~111 ~0 ~114 stone_slab 13 
setblock ~114 ~0 ~91 stone_slab 13 
setblock ~114 ~0 ~111 stone_slab 13 
setblock ~84 ~1 ~88 stone_slab 13  
fill ~84 ~1 ~98 ~86 ~1 ~98 stained_hardened_clay 9  
fill ~84 ~1 ~99 ~90 ~1 ~99 stained_hardened_clay 9  
fill ~84 ~1 ~100 ~118 ~1 ~100 stained_hardened_clay 9  
fill ~84 ~1 ~101 ~90 ~1 ~101 stone 0  
fill ~84 ~1 ~102 ~118 ~1 ~102 stained_hardened_clay 9  
fill ~84 ~1 ~103 ~90 ~1 ~103 stained_hardened_clay 9  
fill ~84 ~1 ~104 ~86 ~1 ~104 stained_hardened_clay 9 
setblock ~84 ~1 ~114 stone_slab 13  
fill ~85 ~1 ~95 ~88 ~1 ~95 stained_hardened_clay 9  
fill ~85 ~1 ~96 ~90 ~1 ~96 stained_hardened_clay 9  
fill ~85 ~1 ~97 ~86 ~1 ~97 stone 0  
fill ~85 ~1 ~105 ~86 ~1 ~105 stone 0  
fill ~85 ~1 ~106 ~90 ~1 ~106 stained_hardened_clay 9  
fill ~85 ~1 ~107 ~88 ~1 ~107 stained_hardened_clay 9 
setblock ~86 ~1 ~93 stone 0  
fill ~86 ~1 ~94 ~86 ~199 ~94 stained_hardened_clay 9  
fill ~86 ~1 ~108 ~86 ~199 ~108 stained_hardened_clay 9 
setblock ~86 ~1 ~109 stone 0 
setblock ~87 ~1 ~91 stone_brick_stairs 6  
fill ~87 ~1 ~92 ~91 ~1 ~92 stained_hardened_clay 9  
fill ~87 ~1 ~93 ~92 ~1 ~93 stained_hardened_clay 9  
fill ~87 ~1 ~94 ~88 ~1 ~94 stone 0  
fill ~87 ~1 ~97 ~115 ~1 ~97 stained_hardened_clay 9  
fill ~87 ~1 ~98 ~90 ~1 ~98 stone 0  
fill ~87 ~1 ~104 ~90 ~1 ~104 stone 0  
fill ~87 ~1 ~105 ~115 ~1 ~105 stained_hardened_clay 9  
fill ~87 ~1 ~108 ~88 ~1 ~108 stone 0  
fill ~87 ~1 ~109 ~92 ~1 ~109 stained_hardened_clay 9  
fill ~87 ~1 ~110 ~91 ~1 ~110 stained_hardened_clay 9 
setblock ~87 ~1 ~111 stone_brick_stairs 7  
fill ~88 ~1 ~90 ~89 ~1 ~90 stained_hardened_clay 9 
setblock ~88 ~1 ~91 sea_lantern 0 
setblock ~88 ~1 ~111 sea_lantern 0  
fill ~88 ~1 ~112 ~89 ~1 ~112 stained_hardened_clay 9 
setblock ~89 ~1 ~89 stone 0  
fill ~89 ~1 ~91 ~90 ~1 ~91 stained_hardened_clay 9  
fill ~89 ~1 ~94 ~113 ~1 ~94 stained_hardened_clay 9  
fill ~89 ~1 ~95 ~90 ~1 ~95 stone 0  
fill ~89 ~1 ~107 ~90 ~1 ~107 stone 0  
fill ~89 ~1 ~108 ~113 ~1 ~108 stained_hardened_clay 9  
fill ~89 ~1 ~111 ~90 ~1 ~111 stained_hardened_clay 9 
setblock ~89 ~1 ~113 stone 0  
fill ~90 ~1 ~88 ~90 ~199 ~88 stained_hardened_clay 9  
fill ~90 ~1 ~89 ~94 ~1 ~89 stained_hardened_clay 9 
setblock ~90 ~1 ~90 stone 0 
setblock ~90 ~1 ~112 stone 0  
fill ~90 ~1 ~113 ~94 ~1 ~113 stained_hardened_clay 9  
fill ~90 ~1 ~114 ~90 ~199 ~114 stained_hardened_clay 9 
setblock ~91 ~1 ~87 stone_brick_stairs 4 
setblock ~91 ~1 ~88 sea_lantern 0  
fill ~91 ~1 ~90 ~94 ~1 ~90 stained_hardened_clay 9 
setblock ~91 ~1 ~91 stone 0  
fill ~91 ~1 ~95 ~111 ~1 ~95 stained_hardened_clay 9  
fill ~91 ~1 ~96 ~92 ~1 ~96 stone 0  
fill ~91 ~1 ~98 ~111 ~1 ~98 stained_hardened_clay 9 
setblock ~91 ~1 ~99 stone 0  
fill ~91 ~1 ~101 ~111 ~1 ~101 stained_hardened_clay 9 
setblock ~91 ~1 ~103 stone 0  
fill ~91 ~1 ~104 ~111 ~1 ~104 stained_hardened_clay 9  
fill ~91 ~1 ~106 ~92 ~1 ~106 stone 0  
fill ~91 ~1 ~107 ~111 ~1 ~107 stained_hardened_clay 9 
setblock ~91 ~1 ~111 stone 0  
fill ~91 ~1 ~112 ~94 ~1 ~112 stained_hardened_clay 9 
setblock ~91 ~1 ~114 sea_lantern 0 
setblock ~91 ~1 ~115 stone_brick_stairs 4  
fill ~92 ~1 ~87 ~93 ~1 ~87 stained_hardened_clay 9  
fill ~92 ~1 ~88 ~93 ~1 ~88 stained_hardened_clay 9  
fill ~92 ~1 ~91 ~95 ~1 ~91 stained_hardened_clay 9 
setblock ~92 ~1 ~92 stone 0  
fill ~92 ~1 ~99 ~110 ~1 ~99 stained_hardened_clay 9  
fill ~92 ~1 ~103 ~110 ~1 ~103 stained_hardened_clay 9 
setblock ~92 ~1 ~110 stone 0  
fill ~92 ~1 ~111 ~95 ~1 ~111 stained_hardened_clay 9  
fill ~92 ~1 ~114 ~93 ~1 ~114 stained_hardened_clay 9  
fill ~92 ~1 ~115 ~93 ~1 ~115 stained_hardened_clay 9 
setblock ~93 ~1 ~86 stone 0  
fill ~93 ~1 ~92 ~95 ~1 ~92 stained_hardened_clay 9 
setblock ~93 ~1 ~93 stone 0  
fill ~93 ~1 ~96 ~109 ~1 ~96 stained_hardened_clay 9  
fill ~93 ~1 ~106 ~109 ~1 ~106 stained_hardened_clay 9 
setblock ~93 ~1 ~109 stone 0  
fill ~93 ~1 ~110 ~95 ~1 ~110 stained_hardened_clay 9 
setblock ~93 ~1 ~116 stone 0  
fill ~94 ~1 ~86 ~94 ~199 ~86 stained_hardened_clay 9  
fill ~94 ~1 ~87 ~94 ~1 ~88 stone 0  
fill ~94 ~1 ~93 ~108 ~1 ~93 stained_hardened_clay 9  
fill ~94 ~1 ~109 ~108 ~1 ~109 stained_hardened_clay 9  
fill ~94 ~1 ~114 ~94 ~1 ~115 stone 0  
fill ~94 ~1 ~116 ~94 ~199 ~116 stained_hardened_clay 9 
setblock ~95 ~1 ~85 stone_brick_stairs 4 
setblock ~95 ~1 ~86 sea_lantern 0  
fill ~95 ~1 ~87 ~97 ~1 ~87 stained_hardened_clay 9  
fill ~95 ~1 ~88 ~97 ~1 ~88 stained_hardened_clay 9  
fill ~95 ~1 ~89 ~95 ~1 ~90 stone 0  
fill ~95 ~1 ~112 ~95 ~1 ~113 stone 0  
fill ~95 ~1 ~114 ~97 ~1 ~114 stained_hardened_clay 9  
fill ~95 ~1 ~115 ~97 ~1 ~115 stained_hardened_clay 9 
setblock ~95 ~1 ~116 sea_lantern 0 
setblock ~95 ~1 ~117 stone_brick_stairs 4  
fill ~96 ~1 ~85 ~96 ~199 ~85 stained_hardened_clay 9  
fill ~96 ~1 ~86 ~96 ~199 ~86 stained_hardened_clay 9  
fill ~96 ~1 ~89 ~97 ~1 ~89 stained_hardened_clay 9  
fill ~96 ~1 ~90 ~97 ~1 ~90 stained_hardened_clay 9  
fill ~96 ~1 ~91 ~96 ~1 ~92 stone 0  
fill ~96 ~1 ~110 ~96 ~1 ~111 stone 0  
fill ~96 ~1 ~112 ~97 ~1 ~112 stained_hardened_clay 9  
fill ~96 ~1 ~113 ~97 ~1 ~113 stained_hardened_clay 9  
fill ~96 ~1 ~116 ~96 ~199 ~116 stained_hardened_clay 9  
fill ~96 ~1 ~117 ~96 ~199 ~117 stained_hardened_clay 9  
fill ~97 ~1 ~85 ~97 ~1 ~86 stone 0  
fill ~97 ~1 ~91 ~98 ~1 ~91 stained_hardened_clay 9  
fill ~97 ~1 ~92 ~105 ~1 ~92 stained_hardened_clay 9  
fill ~97 ~1 ~110 ~105 ~1 ~110 stained_hardened_clay 9  
fill ~97 ~1 ~111 ~98 ~1 ~111 stained_hardened_clay 9  
fill ~97 ~1 ~116 ~97 ~1 ~117 stone 0  
fill ~98 ~1 ~84 ~98 ~199 ~84 stained_hardened_clay 9  
fill ~98 ~1 ~85 ~98 ~199 ~85 stained_hardened_clay 9  
fill ~98 ~1 ~86 ~100 ~1 ~86 stained_hardened_clay 9  
fill ~98 ~1 ~87 ~98 ~1 ~90 stone 0  
fill ~98 ~1 ~112 ~98 ~1 ~115 stone 0  
fill ~98 ~1 ~116 ~100 ~1 ~116 stained_hardened_clay 9  
fill ~98 ~1 ~117 ~98 ~199 ~117 stained_hardened_clay 9  
fill ~98 ~1 ~118 ~98 ~199 ~118 stained_hardened_clay 9 
setblock ~99 ~1 ~80 stone_slab 13 
setblock ~99 ~1 ~84 stone_brick_stairs 4 
setblock ~99 ~1 ~85 sea_lantern 0  
fill ~99 ~1 ~87 ~100 ~1 ~87 stained_hardened_clay 9  
fill ~99 ~1 ~88 ~100 ~1 ~88 stained_hardened_clay 9  
fill ~99 ~1 ~89 ~100 ~1 ~89 stained_hardened_clay 9  
fill ~99 ~1 ~90 ~100 ~1 ~90 stained_hardened_clay 9 
setblock ~99 ~1 ~91 stone 0 
setblock ~99 ~1 ~111 stone 0  
fill ~99 ~1 ~112 ~100 ~1 ~112 stained_hardened_clay 9  
fill ~99 ~1 ~113 ~100 ~1 ~113 stained_hardened_clay 9  
fill ~99 ~1 ~114 ~100 ~1 ~114 stained_hardened_clay 9  
fill ~99 ~1 ~115 ~100 ~1 ~115 stained_hardened_clay 9 
setblock ~99 ~1 ~117 sea_lantern 0 
setblock ~99 ~1 ~118 stone_brick_stairs 4 
setblock ~99 ~1 ~122 stone_slab 13  
fill ~100 ~1 ~84 ~100 ~199 ~84 stained_hardened_clay 9  
fill ~100 ~1 ~85 ~100 ~199 ~85 stained_hardened_clay 9  
fill ~100 ~1 ~91 ~102 ~1 ~91 stained_hardened_clay 9  
fill ~100 ~1 ~111 ~102 ~1 ~111 stained_hardened_clay 9  
fill ~100 ~1 ~117 ~100 ~199 ~117 stained_hardened_clay 9  
fill ~100 ~1 ~118 ~100 ~199 ~118 stained_hardened_clay 9  
fill ~101 ~1 ~84 ~101 ~1 ~90 stone 0  
fill ~101 ~1 ~112 ~101 ~1 ~118 stone 0  
fill ~102 ~1 ~84 ~102 ~199 ~84 stained_hardened_clay 9  
fill ~102 ~1 ~85 ~102 ~199 ~85 stained_hardened_clay 9  
fill ~102 ~1 ~86 ~104 ~1 ~86 stained_hardened_clay 9  
fill ~102 ~1 ~87 ~103 ~1 ~87 stained_hardened_clay 9  
fill ~102 ~1 ~88 ~103 ~1 ~88 stained_hardened_clay 9  
fill ~102 ~1 ~89 ~103 ~1 ~89 stained_hardened_clay 9  
fill ~102 ~1 ~90 ~103 ~1 ~90 stained_hardened_clay 9  
fill ~102 ~1 ~112 ~103 ~1 ~112 stained_hardened_clay 9  
fill ~102 ~1 ~113 ~103 ~1 ~113 stained_hardened_clay 9  
fill ~102 ~1 ~114 ~103 ~1 ~114 stained_hardened_clay 9  
fill ~102 ~1 ~115 ~103 ~1 ~115 stained_hardened_clay 9  
fill ~102 ~1 ~116 ~104 ~1 ~116 stained_hardened_clay 9  
fill ~102 ~1 ~117 ~102 ~199 ~117 stained_hardened_clay 9  
fill ~102 ~1 ~118 ~102 ~199 ~118 stained_hardened_clay 9 
setblock ~103 ~1 ~80 stone_slab 13 
setblock ~103 ~1 ~84 stone_brick_stairs 5 
setblock ~103 ~1 ~85 sea_lantern 0 
setblock ~103 ~1 ~91 stone 0 
setblock ~103 ~1 ~111 stone 0 
setblock ~103 ~1 ~117 sea_lantern 0 
setblock ~103 ~1 ~118 stone_brick_stairs 5 
setblock ~103 ~1 ~122 stone_slab 13  
fill ~104 ~1 ~84 ~104 ~199 ~84 stained_hardened_clay 9  
fill ~104 ~1 ~85 ~104 ~199 ~85 stained_hardened_clay 9  
fill ~104 ~1 ~87 ~104 ~1 ~90 stone 0  
fill ~104 ~1 ~91 ~105 ~1 ~91 stained_hardened_clay 9  
fill ~104 ~1 ~111 ~105 ~1 ~111 stained_hardened_clay 9  
fill ~104 ~1 ~112 ~104 ~1 ~115 stone 0  
fill ~104 ~1 ~117 ~104 ~199 ~117 stained_hardened_clay 9  
fill ~104 ~1 ~118 ~104 ~199 ~118 stained_hardened_clay 9  
fill ~105 ~1 ~85 ~105 ~1 ~86 stone 0  
fill ~105 ~1 ~87 ~107 ~1 ~87 stained_hardened_clay 9  
fill ~105 ~1 ~88 ~107 ~1 ~88 stained_hardened_clay 9  
fill ~105 ~1 ~89 ~106 ~1 ~89 stained_hardened_clay 9  
fill ~105 ~1 ~90 ~106 ~1 ~90 stained_hardened_clay 9  
fill ~105 ~1 ~112 ~106 ~1 ~112 stained_hardened_clay 9  
fill ~105 ~1 ~113 ~106 ~1 ~113 stained_hardened_clay 9  
fill ~105 ~1 ~114 ~107 ~1 ~114 stained_hardened_clay 9  
fill ~105 ~1 ~115 ~107 ~1 ~115 stained_hardened_clay 9  
fill ~105 ~1 ~116 ~105 ~1 ~117 stone 0  
fill ~106 ~1 ~85 ~106 ~199 ~85 stained_hardened_clay 9  
fill ~106 ~1 ~86 ~106 ~199 ~86 stained_hardened_clay 9  
fill ~106 ~1 ~91 ~106 ~1 ~92 stone 0  
fill ~106 ~1 ~110 ~106 ~1 ~111 stone 0  
fill ~106 ~1 ~116 ~106 ~199 ~116 stained_hardened_clay 9  
fill ~106 ~1 ~117 ~106 ~199 ~117 stained_hardened_clay 9 
setblock ~107 ~1 ~85 stone_brick_stairs 5 
setblock ~107 ~1 ~86 sea_lantern 0  
fill ~107 ~1 ~89 ~107 ~1 ~90 stone 0  
fill ~107 ~1 ~91 ~110 ~1 ~91 stained_hardened_clay 9  
fill ~107 ~1 ~92 ~109 ~1 ~92 stained_hardened_clay 9  
fill ~107 ~1 ~110 ~109 ~1 ~110 stained_hardened_clay 9  
fill ~107 ~1 ~111 ~110 ~1 ~111 stained_hardened_clay 9  
fill ~107 ~1 ~112 ~107 ~1 ~113 stone 0 
setblock ~107 ~1 ~116 sea_lantern 0 
setblock ~107 ~1 ~117 stone_brick_stairs 5  
fill ~108 ~1 ~86 ~108 ~199 ~86 stained_hardened_clay 9  
fill ~108 ~1 ~87 ~108 ~1 ~88 stone 0  
fill ~108 ~1 ~89 ~112 ~1 ~89 stained_hardened_clay 9  
fill ~108 ~1 ~90 ~111 ~1 ~90 stained_hardened_clay 9  
fill ~108 ~1 ~112 ~111 ~1 ~112 stained_hardened_clay 9  
fill ~108 ~1 ~113 ~112 ~1 ~113 stained_hardened_clay 9  
fill ~108 ~1 ~114 ~108 ~1 ~115 stone 0  
fill ~108 ~1 ~116 ~108 ~199 ~116 stained_hardened_clay 9 
setblock ~109 ~1 ~86 stone 0  
fill ~109 ~1 ~87 ~110 ~1 ~87 stained_hardened_clay 9  
fill ~109 ~1 ~88 ~110 ~1 ~88 stained_hardened_clay 9 
setblock ~109 ~1 ~93 stone 0 
setblock ~109 ~1 ~109 stone 0  
fill ~109 ~1 ~114 ~110 ~1 ~114 stained_hardened_clay 9  
fill ~109 ~1 ~115 ~110 ~1 ~115 stained_hardened_clay 9 
setblock ~109 ~1 ~116 stone 0 
setblock ~110 ~1 ~92 stone 0  
fill ~110 ~1 ~93 ~115 ~1 ~93 stained_hardened_clay 9  
fill ~110 ~1 ~96 ~111 ~1 ~96 stone 0  
fill ~110 ~1 ~106 ~111 ~1 ~106 stone 0  
fill ~110 ~1 ~109 ~115 ~1 ~109 stained_hardened_clay 9 
setblock ~110 ~1 ~110 stone 0 
setblock ~111 ~1 ~87 stone_brick_stairs 5 
setblock ~111 ~1 ~88 sea_lantern 0 
setblock ~111 ~1 ~91 stone 0  
fill ~111 ~1 ~92 ~115 ~1 ~92 stained_hardened_clay 9 
setblock ~111 ~1 ~99 stone 0 
setblock ~111 ~1 ~103 stone 0  
fill ~111 ~1 ~110 ~115 ~1 ~110 stained_hardened_clay 9 
setblock ~111 ~1 ~111 stone 0 
setblock ~111 ~1 ~114 sea_lantern 0 
setblock ~111 ~1 ~115 stone_brick_stairs 5  
fill ~112 ~1 ~88 ~112 ~199 ~88 stained_hardened_clay 9 
setblock ~112 ~1 ~90 stone 0  
fill ~112 ~1 ~91 ~113 ~1 ~91 stained_hardened_clay 9  
fill ~112 ~1 ~95 ~113 ~1 ~95 stone 0  
fill ~112 ~1 ~96 ~117 ~1 ~96 stained_hardened_clay 9  
fill ~112 ~1 ~98 ~115 ~1 ~98 stone 0  
fill ~112 ~1 ~99 ~118 ~1 ~99 stained_hardened_clay 9  
fill ~112 ~1 ~101 ~118 ~1 ~101 stone 0  
fill ~112 ~1 ~103 ~118 ~1 ~103 stained_hardened_clay 9  
fill ~112 ~1 ~104 ~115 ~1 ~104 stone 0  
fill ~112 ~1 ~106 ~117 ~1 ~106 stained_hardened_clay 9  
fill ~112 ~1 ~107 ~113 ~1 ~107 stone 0  
fill ~112 ~1 ~111 ~113 ~1 ~111 stained_hardened_clay 9 
setblock ~112 ~1 ~112 stone 0  
fill ~112 ~1 ~114 ~112 ~199 ~114 stained_hardened_clay 9 
setblock ~113 ~1 ~89 stone 0  
fill ~113 ~1 ~90 ~114 ~1 ~90 stained_hardened_clay 9  
fill ~113 ~1 ~112 ~114 ~1 ~112 stained_hardened_clay 9 
setblock ~113 ~1 ~113 stone 0 
setblock ~114 ~1 ~91 sea_lantern 0  
fill ~114 ~1 ~94 ~115 ~1 ~94 stone 0  
fill ~114 ~1 ~95 ~117 ~1 ~95 stained_hardened_clay 9  
fill ~114 ~1 ~107 ~117 ~1 ~107 stained_hardened_clay 9  
fill ~114 ~1 ~108 ~115 ~1 ~108 stone 0 
setblock ~114 ~1 ~111 sea_lantern 0 
setblock ~115 ~1 ~91 stone_brick_stairs 6 
setblock ~115 ~1 ~111 stone_brick_stairs 7 
setblock ~116 ~1 ~93 stone 0  
fill ~116 ~1 ~94 ~116 ~199 ~94 stained_hardened_clay 9  
fill ~116 ~1 ~97 ~117 ~1 ~97 stone 0  
fill ~116 ~1 ~98 ~118 ~1 ~98 stained_hardened_clay 9  
fill ~116 ~1 ~104 ~118 ~1 ~104 stained_hardened_clay 9  
fill ~116 ~1 ~105 ~117 ~1 ~105 stone 0  
fill ~116 ~1 ~108 ~116 ~199 ~108 stained_hardened_clay 9 
setblock ~116 ~1 ~109 stone 0 
setblock ~118 ~1 ~88 stone_slab 13 
setblock ~118 ~1 ~114 stone_slab 13  
fill ~79 ~2 ~98 ~123 ~2 ~98 stained_hardened_clay 9  
fill ~79 ~2 ~99 ~123 ~2 ~99 stained_hardened_clay 9  
fill ~79 ~2 ~100 ~123 ~2 ~100 stained_hardened_clay 9  
fill ~79 ~2 ~101 ~83 ~2 ~101 stone 0  
fill ~79 ~2 ~102 ~123 ~2 ~102 stained_hardened_clay 9  
fill ~79 ~2 ~103 ~123 ~2 ~103 stained_hardened_clay 9  
fill ~79 ~2 ~104 ~123 ~2 ~104 stained_hardened_clay 9 
setblock ~80 ~2 ~87 stone_slab 13  
fill ~80 ~2 ~94 ~122 ~2 ~94 stained_hardened_clay 9  
fill ~80 ~2 ~95 ~122 ~2 ~95 stained_hardened_clay 9  
fill ~80 ~2 ~96 ~82 ~2 ~96 stone 0  
fill ~80 ~2 ~97 ~82 ~2 ~97 stained_hardened_clay 9  
fill ~80 ~2 ~105 ~82 ~2 ~105 stained_hardened_clay 9  
fill ~80 ~2 ~106 ~82 ~2 ~106 stone 0  
fill ~80 ~2 ~107 ~122 ~2 ~107 stained_hardened_clay 9  
fill ~80 ~2 ~108 ~122 ~2 ~108 stained_hardened_clay 9 
setblock ~80 ~2 ~115 stone_slab 13 
setblock ~81 ~2 ~85 stone_slab 13  
fill ~81 ~2 ~92 ~82 ~2 ~92 stained_hardened_clay 9  
fill ~81 ~2 ~93 ~84 ~2 ~93 stained_hardened_clay 9  
fill ~81 ~2 ~109 ~84 ~2 ~109 stained_hardened_clay 9  
fill ~81 ~2 ~110 ~82 ~2 ~110 stained_hardened_clay 9 
setblock ~81 ~2 ~117 stone_slab 13  
fill ~82 ~2 ~90 ~120 ~2 ~90 stained_hardened_clay 9 
setblock ~82 ~2 ~91 stone 0 
setblock ~82 ~2 ~111 stone 0  
fill ~82 ~2 ~112 ~120 ~2 ~112 stained_hardened_clay 9 
setblock ~83 ~2 ~88 stone_brick_stairs 6  
fill ~83 ~2 ~89 ~119 ~2 ~89 stained_hardened_clay 9  
fill ~83 ~2 ~91 ~119 ~2 ~91 stained_hardened_clay 9  
fill ~83 ~2 ~92 ~84 ~2 ~92 stone 0  
fill ~83 ~2 ~96 ~119 ~2 ~96 stained_hardened_clay 9  
fill ~83 ~2 ~97 ~84 ~2 ~97 stone 0  
fill ~83 ~2 ~105 ~84 ~2 ~105 stone 0  
fill ~83 ~2 ~106 ~119 ~2 ~106 stained_hardened_clay 9  
fill ~83 ~2 ~110 ~84 ~2 ~110 stone 0  
fill ~83 ~2 ~111 ~119 ~2 ~111 stained_hardened_clay 9  
fill ~83 ~2 ~113 ~119 ~2 ~113 stained_hardened_clay 9 
setblock ~83 ~2 ~114 stone_brick_stairs 7  
fill ~84 ~2 ~87 ~86 ~2 ~87 stained_hardened_clay 9 
setblock ~84 ~2 ~88 sea_lantern 0  
fill ~84 ~2 ~101 ~118 ~2 ~101 stained_hardened_clay 9 
setblock ~84 ~2 ~114 sea_lantern 0  
fill ~84 ~2 ~115 ~86 ~2 ~115 stained_hardened_clay 9 
setblock ~85 ~2 ~82 stone_slab 13  
fill ~85 ~2 ~86 ~85 ~198 ~86 stained_hardened_clay 9  
fill ~85 ~2 ~88 ~87 ~2 ~88 stained_hardened_clay 9  
fill ~85 ~2 ~92 ~117 ~2 ~92 stained_hardened_clay 9 
setblock ~85 ~2 ~93 stone 0  
fill ~85 ~2 ~97 ~117 ~2 ~97 stained_hardened_clay 9  
fill ~85 ~2 ~105 ~117 ~2 ~105 stained_hardened_clay 9 
setblock ~85 ~2 ~109 stone 0  
fill ~85 ~2 ~110 ~117 ~2 ~110 stained_hardened_clay 9  
fill ~85 ~2 ~114 ~87 ~2 ~114 stained_hardened_clay 9  
fill ~85 ~2 ~116 ~85 ~198 ~116 stained_hardened_clay 9 
setblock ~85 ~2 ~120 stone_slab 13  
fill ~86 ~2 ~85 ~92 ~2 ~85 stained_hardened_clay 9 
setblock ~86 ~2 ~86 stone 0  
fill ~86 ~2 ~93 ~116 ~2 ~93 stained_hardened_clay 9  
fill ~86 ~2 ~109 ~116 ~2 ~109 stained_hardened_clay 9 
setblock ~86 ~2 ~116 stone 0  
fill ~86 ~2 ~117 ~92 ~2 ~117 stained_hardened_clay 9 
setblock ~87 ~2 ~80 stone_slab 13  
fill ~87 ~2 ~84 ~91 ~2 ~84 stained_hardened_clay 9  
fill ~87 ~2 ~86 ~115 ~2 ~86 stained_hardened_clay 9 
setblock ~87 ~2 ~87 stone 0 
setblock ~87 ~2 ~115 stone 0  
fill ~87 ~2 ~116 ~115 ~2 ~116 stained_hardened_clay 9  
fill ~87 ~2 ~118 ~91 ~2 ~118 stained_hardened_clay 9 
setblock ~87 ~2 ~122 stone_slab 13  
fill ~88 ~2 ~83 ~91 ~2 ~83 stained_hardened_clay 9  
fill ~88 ~2 ~87 ~114 ~2 ~87 stained_hardened_clay 9 
setblock ~88 ~2 ~88 stone 0 
setblock ~88 ~2 ~114 stone 0  
fill ~88 ~2 ~115 ~114 ~2 ~115 stained_hardened_clay 9  
fill ~88 ~2 ~119 ~91 ~2 ~119 stained_hardened_clay 9  
fill ~89 ~2 ~88 ~89 ~198 ~88 stained_hardened_clay 9  
fill ~89 ~2 ~114 ~89 ~198 ~114 stained_hardened_clay 9  
fill ~90 ~2 ~82 ~90 ~198 ~82 stained_hardened_clay 9  
fill ~90 ~2 ~120 ~90 ~198 ~120 stained_hardened_clay 9 
setblock ~91 ~2 ~82 stone 0  
fill ~91 ~2 ~88 ~113 ~2 ~88 stained_hardened_clay 9  
fill ~91 ~2 ~114 ~113 ~2 ~114 stained_hardened_clay 9 
setblock ~91 ~2 ~120 stone 0 
setblock ~92 ~2 ~78 stone_slab 13  
fill ~92 ~2 ~81 ~95 ~2 ~81 stained_hardened_clay 9  
fill ~92 ~2 ~82 ~95 ~2 ~82 stained_hardened_clay 9  
fill ~92 ~2 ~83 ~92 ~2 ~84 stone 0  
fill ~92 ~2 ~118 ~92 ~2 ~119 stone 0  
fill ~92 ~2 ~120 ~95 ~2 ~120 stained_hardened_clay 9  
fill ~92 ~2 ~121 ~95 ~2 ~121 stained_hardened_clay 9 
setblock ~92 ~2 ~124 stone_slab 13  
fill ~93 ~2 ~83 ~96 ~2 ~83 stained_hardened_clay 9  
fill ~93 ~2 ~84 ~96 ~2 ~84 stained_hardened_clay 9 
setblock ~93 ~2 ~85 stone 0 
setblock ~93 ~2 ~117 stone 0  
fill ~93 ~2 ~118 ~96 ~2 ~118 stained_hardened_clay 9  
fill ~93 ~2 ~119 ~96 ~2 ~119 stained_hardened_clay 9  
fill ~94 ~2 ~80 ~95 ~2 ~80 stained_hardened_clay 9  
fill ~94 ~2 ~85 ~108 ~2 ~85 stained_hardened_clay 9  
fill ~94 ~2 ~117 ~108 ~2 ~117 stained_hardened_clay 9  
fill ~94 ~2 ~122 ~95 ~2 ~122 stained_hardened_clay 9  
fill ~96 ~2 ~80 ~96 ~2 ~82 stone 0  
fill ~96 ~2 ~120 ~96 ~2 ~122 stone 0 
setblock ~97 ~2 ~77 stone_slab 13  
fill ~97 ~2 ~80 ~98 ~2 ~80 stained_hardened_clay 9  
fill ~97 ~2 ~81 ~100 ~2 ~81 stained_hardened_clay 9  
fill ~97 ~2 ~82 ~100 ~2 ~82 stained_hardened_clay 9  
fill ~97 ~2 ~83 ~97 ~2 ~84 stone 0  
fill ~97 ~2 ~118 ~97 ~2 ~119 stone 0  
fill ~97 ~2 ~120 ~100 ~2 ~120 stained_hardened_clay 9  
fill ~97 ~2 ~121 ~100 ~2 ~121 stained_hardened_clay 9  
fill ~97 ~2 ~122 ~98 ~2 ~122 stained_hardened_clay 9 
setblock ~97 ~2 ~125 stone_slab 13  
fill ~98 ~2 ~79 ~98 ~198 ~79 stained_hardened_clay 9  
fill ~98 ~2 ~83 ~100 ~2 ~83 stained_hardened_clay 9  
fill ~98 ~2 ~119 ~100 ~2 ~119 stained_hardened_clay 9  
fill ~98 ~2 ~123 ~98 ~198 ~123 stained_hardened_clay 9 
setblock ~99 ~2 ~76 stone_slab 13 
setblock ~99 ~2 ~79 stone_brick_stairs 4 
setblock ~99 ~2 ~80 sea_lantern 0  
fill ~99 ~2 ~84 ~99 ~198 ~84 stained_hardened_clay 9  
fill ~99 ~2 ~118 ~99 ~198 ~118 stained_hardened_clay 9 
setblock ~99 ~2 ~122 sea_lantern 0 
setblock ~99 ~2 ~123 stone_brick_stairs 4 
setblock ~99 ~2 ~126 stone_slab 13  
fill ~100 ~2 ~79 ~100 ~198 ~79 stained_hardened_clay 9  
fill ~100 ~2 ~80 ~100 ~198 ~80 stained_hardened_clay 9  
fill ~100 ~2 ~122 ~100 ~198 ~122 stained_hardened_clay 9  
fill ~100 ~2 ~123 ~100 ~198 ~123 stained_hardened_clay 9  
fill ~101 ~2 ~79 ~101 ~2 ~83 stone 0  
fill ~101 ~2 ~84 ~101 ~198 ~84 stained_hardened_clay 9  
fill ~101 ~2 ~118 ~101 ~198 ~118 stained_hardened_clay 9  
fill ~101 ~2 ~119 ~101 ~2 ~123 stone 0  
fill ~102 ~2 ~79 ~102 ~198 ~79 stained_hardened_clay 9  
fill ~102 ~2 ~80 ~102 ~198 ~80 stained_hardened_clay 9  
fill ~102 ~2 ~81 ~105 ~2 ~81 stained_hardened_clay 9  
fill ~102 ~2 ~82 ~105 ~2 ~82 stained_hardened_clay 9  
fill ~102 ~2 ~83 ~104 ~2 ~83 stained_hardened_clay 9  
fill ~102 ~2 ~119 ~104 ~2 ~119 stained_hardened_clay 9  
fill ~102 ~2 ~120 ~105 ~2 ~120 stained_hardened_clay 9  
fill ~102 ~2 ~121 ~105 ~2 ~121 stained_hardened_clay 9  
fill ~102 ~2 ~122 ~102 ~198 ~122 stained_hardened_clay 9  
fill ~102 ~2 ~123 ~102 ~198 ~123 stained_hardened_clay 9 
setblock ~103 ~2 ~76 stone_slab 13 
setblock ~103 ~2 ~79 stone_brick_stairs 5 
setblock ~103 ~2 ~80 sea_lantern 0  
fill ~103 ~2 ~84 ~103 ~198 ~84 stained_hardened_clay 9  
fill ~103 ~2 ~118 ~103 ~198 ~118 stained_hardened_clay 9 
setblock ~103 ~2 ~122 sea_lantern 0 
setblock ~103 ~2 ~123 stone_brick_stairs 5 
setblock ~103 ~2 ~126 stone_slab 13  
fill ~104 ~2 ~79 ~104 ~198 ~79 stained_hardened_clay 9  
fill ~104 ~2 ~80 ~105 ~2 ~80 stained_hardened_clay 9  
fill ~104 ~2 ~122 ~105 ~2 ~122 stained_hardened_clay 9  
fill ~104 ~2 ~123 ~104 ~198 ~123 stained_hardened_clay 9 
setblock ~105 ~2 ~77 stone_slab 13  
fill ~105 ~2 ~83 ~105 ~2 ~84 stone 0  
fill ~105 ~2 ~118 ~105 ~2 ~119 stone 0 
setblock ~105 ~2 ~125 stone_slab 13  
fill ~106 ~2 ~80 ~106 ~2 ~82 stone 0  
fill ~106 ~2 ~83 ~109 ~2 ~83 stained_hardened_clay 9  
fill ~106 ~2 ~84 ~109 ~2 ~84 stained_hardened_clay 9  
fill ~106 ~2 ~118 ~109 ~2 ~118 stained_hardened_clay 9  
fill ~106 ~2 ~119 ~109 ~2 ~119 stained_hardened_clay 9  
fill ~106 ~2 ~120 ~106 ~2 ~122 stone 0  
fill ~107 ~2 ~80 ~108 ~2 ~80 stained_hardened_clay 9  
fill ~107 ~2 ~81 ~110 ~2 ~81 stained_hardened_clay 9  
fill ~107 ~2 ~82 ~110 ~2 ~82 stained_hardened_clay 9  
fill ~107 ~2 ~120 ~110 ~2 ~120 stained_hardened_clay 9  
fill ~107 ~2 ~121 ~110 ~2 ~121 stained_hardened_clay 9  
fill ~107 ~2 ~122 ~108 ~2 ~122 stained_hardened_clay 9 
setblock ~109 ~2 ~85 stone 0 
setblock ~109 ~2 ~117 stone 0 
setblock ~110 ~2 ~78 stone_slab 13  
fill ~110 ~2 ~83 ~110 ~2 ~84 stone 0  
fill ~110 ~2 ~85 ~116 ~2 ~85 stained_hardened_clay 9  
fill ~110 ~2 ~117 ~116 ~2 ~117 stained_hardened_clay 9  
fill ~110 ~2 ~118 ~110 ~2 ~119 stone 0 
setblock ~110 ~2 ~124 stone_slab 13 
setblock ~111 ~2 ~82 stone 0  
fill ~111 ~2 ~83 ~114 ~2 ~83 stained_hardened_clay 9  
fill ~111 ~2 ~84 ~115 ~2 ~84 stained_hardened_clay 9  
fill ~111 ~2 ~118 ~115 ~2 ~118 stained_hardened_clay 9  
fill ~111 ~2 ~119 ~114 ~2 ~119 stained_hardened_clay 9 
setblock ~111 ~2 ~120 stone 0  
fill ~112 ~2 ~82 ~112 ~198 ~82 stained_hardened_clay 9  
fill ~112 ~2 ~120 ~112 ~198 ~120 stained_hardened_clay 9 
setblock ~114 ~2 ~88 stone 0 
setblock ~114 ~2 ~114 stone 0 
setblock ~115 ~2 ~80 stone_slab 13 
setblock ~115 ~2 ~87 stone 0  
fill ~115 ~2 ~88 ~117 ~2 ~88 stained_hardened_clay 9  
fill ~115 ~2 ~114 ~117 ~2 ~114 stained_hardened_clay 9 
setblock ~115 ~2 ~115 stone 0 
setblock ~115 ~2 ~122 stone_slab 13 
setblock ~116 ~2 ~86 stone 0  
fill ~116 ~2 ~87 ~118 ~2 ~87 stained_hardened_clay 9  
fill ~116 ~2 ~115 ~118 ~2 ~115 stained_hardened_clay 9 
setblock ~116 ~2 ~116 stone 0 
setblock ~117 ~2 ~82 stone_slab 13  
fill ~117 ~2 ~86 ~117 ~198 ~86 stained_hardened_clay 9 
setblock ~117 ~2 ~93 stone 0 
setblock ~117 ~2 ~109 stone 0  
fill ~117 ~2 ~116 ~117 ~198 ~116 stained_hardened_clay 9 
setblock ~117 ~2 ~120 stone_slab 13 
setblock ~118 ~2 ~88 sea_lantern 0  
fill ~118 ~2 ~92 ~119 ~2 ~92 stone 0  
fill ~118 ~2 ~93 ~121 ~2 ~93 stained_hardened_clay 9  
fill ~118 ~2 ~97 ~119 ~2 ~97 stone 0  
fill ~118 ~2 ~105 ~119 ~2 ~105 stone 0  
fill ~118 ~2 ~109 ~121 ~2 ~109 stained_hardened_clay 9  
fill ~118 ~2 ~110 ~119 ~2 ~110 stone 0 
setblock ~118 ~2 ~114 sea_lantern 0 
setblock ~119 ~2 ~88 stone_brick_stairs 6  
fill ~119 ~2 ~101 ~123 ~2 ~101 stone 0 
setblock ~119 ~2 ~114 stone_brick_stairs 7 
setblock ~120 ~2 ~91 stone 0  
fill ~120 ~2 ~92 ~121 ~2 ~92 stained_hardened_clay 9  
fill ~120 ~2 ~96 ~122 ~2 ~96 stone 0  
fill ~120 ~2 ~97 ~122 ~2 ~97 stained_hardened_clay 9  
fill ~120 ~2 ~105 ~122 ~2 ~105 stained_hardened_clay 9  
fill ~120 ~2 ~106 ~122 ~2 ~106 stone 0  
fill ~120 ~2 ~110 ~121 ~2 ~110 stained_hardened_clay 9 
setblock ~120 ~2 ~111 stone 0 
setblock ~121 ~2 ~85 stone_slab 13 
setblock ~121 ~2 ~117 stone_slab 13 
setblock ~122 ~2 ~87 stone_slab 13 
setblock ~122 ~2 ~115 stone_slab 13  
fill ~75 ~3 ~98 ~127 ~3 ~98 stained_hardened_clay 9  
fill ~75 ~3 ~99 ~127 ~3 ~99 stained_hardened_clay 9  
fill ~75 ~3 ~100 ~127 ~3 ~100 stained_hardened_clay 9  
fill ~75 ~3 ~101 ~78 ~3 ~101 stone 0  
fill ~75 ~3 ~102 ~127 ~3 ~102 stained_hardened_clay 9  
fill ~75 ~3 ~103 ~127 ~3 ~103 stained_hardened_clay 9  
fill ~75 ~3 ~104 ~127 ~3 ~104 stained_hardened_clay 9  
fill ~76 ~3 ~93 ~126 ~3 ~93 stained_hardened_clay 9  
fill ~76 ~3 ~94 ~126 ~3 ~94 stained_hardened_clay 9  
fill ~76 ~3 ~95 ~78 ~3 ~95 stone 0  
fill ~76 ~3 ~96 ~78 ~3 ~96 stained_hardened_clay 9  
fill ~76 ~3 ~97 ~126 ~3 ~97 stained_hardened_clay 9  
fill ~76 ~3 ~105 ~126 ~3 ~105 stained_hardened_clay 9  
fill ~76 ~3 ~106 ~78 ~3 ~106 stained_hardened_clay 9  
fill ~76 ~3 ~107 ~78 ~3 ~107 stone 0  
fill ~76 ~3 ~108 ~126 ~3 ~108 stained_hardened_clay 9  
fill ~76 ~3 ~109 ~126 ~3 ~109 stained_hardened_clay 9   
fill ~77 ~3 ~91 ~80 ~3 ~91 stained_hardened_clay 9  
fill ~77 ~3 ~92 ~125 ~3 ~92 stained_hardened_clay 9  
fill ~77 ~3 ~110 ~125 ~3 ~110 stained_hardened_clay 9  
fill ~77 ~3 ~111 ~80 ~3 ~111 stained_hardened_clay 9 
setblock ~78 ~3 ~89 stone 0  
fill ~78 ~3 ~90 ~78 ~197 ~90 stained_hardened_clay 9  
fill ~78 ~3 ~112 ~78 ~197 ~112 stained_hardened_clay 9 
setblock ~78 ~3 ~113 stone 0 
setblock ~79 ~3 ~87 stone_brick_stairs 6  
fill ~79 ~3 ~88 ~123 ~3 ~88 stained_hardened_clay 9  
fill ~79 ~3 ~89 ~123 ~3 ~89 stained_hardened_clay 9  
fill ~79 ~3 ~90 ~80 ~3 ~90 stone 0  
fill ~79 ~3 ~95 ~123 ~3 ~95 stained_hardened_clay 9 
setblock ~79 ~3 ~96 stone 0  
fill ~79 ~3 ~101 ~123 ~3 ~101 stained_hardened_clay 9 
setblock ~79 ~3 ~106 stone 0  
fill ~79 ~3 ~107 ~123 ~3 ~107 stained_hardened_clay 9  
fill ~79 ~3 ~112 ~80 ~3 ~112 stone 0  
fill ~79 ~3 ~113 ~123 ~3 ~113 stained_hardened_clay 9  
fill ~79 ~3 ~114 ~123 ~3 ~114 stained_hardened_clay 9 
setblock ~79 ~3 ~115 stone_brick_stairs 7 
setblock ~80 ~3 ~85 stone_brick_stairs 6  
fill ~80 ~3 ~86 ~122 ~3 ~86 stained_hardened_clay 9 
setblock ~80 ~3 ~87 sea_lantern 0  
fill ~80 ~3 ~96 ~122 ~3 ~96 stained_hardened_clay 9  
fill ~80 ~3 ~106 ~122 ~3 ~106 stained_hardened_clay 9 
setblock ~80 ~3 ~115 sea_lantern 0  
fill ~80 ~3 ~116 ~122 ~3 ~116 stained_hardened_clay 9 
setblock ~80 ~3 ~117 stone_brick_stairs 7  
fill ~81 ~3 ~84 ~83 ~3 ~84 stained_hardened_clay 9 
setblock ~81 ~3 ~85 sea_lantern 0  
fill ~81 ~3 ~87 ~121 ~3 ~87 stained_hardened_clay 9  
fill ~81 ~3 ~90 ~121 ~3 ~90 stained_hardened_clay 9 
setblock ~81 ~3 ~91 stone 0 
setblock ~81 ~3 ~111 stone 0  
fill ~81 ~3 ~112 ~121 ~3 ~112 stained_hardened_clay 9  
fill ~81 ~3 ~115 ~121 ~3 ~115 stained_hardened_clay 9 
setblock ~81 ~3 ~117 sea_lantern 0  
fill ~81 ~3 ~118 ~83 ~3 ~118 stained_hardened_clay 9  
fill ~82 ~3 ~83 ~82 ~197 ~83 stained_hardened_clay 9  
fill ~82 ~3 ~85 ~84 ~3 ~85 stained_hardened_clay 9  
fill ~82 ~3 ~91 ~120 ~3 ~91 stained_hardened_clay 9  
fill ~82 ~3 ~111 ~120 ~3 ~111 stained_hardened_clay 9  
fill ~82 ~3 ~117 ~84 ~3 ~117 stained_hardened_clay 9  
fill ~82 ~3 ~119 ~82 ~197 ~119 stained_hardened_clay 9  
fill ~83 ~3 ~82 ~84 ~3 ~82 stained_hardened_clay 9 
setblock ~83 ~3 ~83 stone 0 
setblock ~83 ~3 ~119 stone 0  
fill ~83 ~3 ~120 ~84 ~3 ~120 stained_hardened_clay 9  
fill ~84 ~3 ~81 ~84 ~197 ~81 stained_hardened_clay 9  
fill ~84 ~3 ~83 ~118 ~3 ~83 stained_hardened_clay 9 
setblock ~84 ~3 ~84 stone 0 
setblock ~84 ~3 ~118 stone 0  
fill ~84 ~3 ~119 ~118 ~3 ~119 stained_hardened_clay 9  
fill ~84 ~3 ~121 ~84 ~197 ~121 stained_hardened_clay 9 
setblock ~85 ~3 ~81 stone_brick_stairs 4 
setblock ~85 ~3 ~82 sea_lantern 0  
fill ~85 ~3 ~84 ~117 ~3 ~84 stained_hardened_clay 9 
setblock ~85 ~3 ~85 stone 0 
setblock ~85 ~3 ~117 stone 0  
fill ~85 ~3 ~118 ~117 ~3 ~118 stained_hardened_clay 9 
setblock ~85 ~3 ~120 sea_lantern 0 
setblock ~85 ~3 ~121 stone_brick_stairs 4  
fill ~86 ~3 ~80 ~86 ~197 ~80 stained_hardened_clay 9  
fill ~86 ~3 ~81 ~90 ~3 ~81 stained_hardened_clay 9  
fill ~86 ~3 ~82 ~116 ~3 ~82 stained_hardened_clay 9  
fill ~86 ~3 ~85 ~116 ~3 ~85 stained_hardened_clay 9  
fill ~86 ~3 ~117 ~116 ~3 ~117 stained_hardened_clay 9  
fill ~86 ~3 ~120 ~116 ~3 ~120 stained_hardened_clay 9  
fill ~86 ~3 ~121 ~90 ~3 ~121 stained_hardened_clay 9  
fill ~86 ~3 ~122 ~86 ~197 ~122 stained_hardened_clay 9 
setblock ~87 ~3 ~79 stone_brick_stairs 4 
setblock ~87 ~3 ~80 sea_lantern 0 
setblock ~87 ~3 ~122 sea_lantern 0 
setblock ~87 ~3 ~123 stone_brick_stairs 4  
fill ~88 ~3 ~79 ~89 ~3 ~79 stained_hardened_clay 9  
fill ~88 ~3 ~80 ~89 ~3 ~80 stained_hardened_clay 9  
fill ~88 ~3 ~122 ~89 ~3 ~122 stained_hardened_clay 9  
fill ~88 ~3 ~123 ~89 ~3 ~123 stained_hardened_clay 9 
setblock ~89 ~3 ~78 stone 0 
setblock ~89 ~3 ~124 stone 0  
fill ~90 ~3 ~78 ~91 ~3 ~78 stained_hardened_clay 9  
fill ~90 ~3 ~79 ~90 ~3 ~80 stone 0  
fill ~90 ~3 ~122 ~90 ~3 ~123 stone 0  
fill ~90 ~3 ~124 ~91 ~3 ~124 stained_hardened_clay 9  
fill ~91 ~3 ~77 ~91 ~197 ~77 stained_hardened_clay 9  
fill ~91 ~3 ~79 ~95 ~3 ~79 stained_hardened_clay 9  
fill ~91 ~3 ~80 ~111 ~3 ~80 stained_hardened_clay 9 
setblock ~91 ~3 ~81 stone 0 
setblock ~91 ~3 ~121 stone 0  
fill ~91 ~3 ~122 ~111 ~3 ~122 stained_hardened_clay 9  
fill ~91 ~3 ~123 ~95 ~3 ~123 stained_hardened_clay 9  
fill ~91 ~3 ~125 ~91 ~197 ~125 stained_hardened_clay 9 
setblock ~92 ~3 ~77 stone_brick_stairs 4 
setblock ~92 ~3 ~78 sea_lantern 0  
fill ~92 ~3 ~81 ~110 ~3 ~81 stained_hardened_clay 9  
fill ~92 ~3 ~121 ~110 ~3 ~121 stained_hardened_clay 9 
setblock ~92 ~3 ~124 sea_lantern 0 
setblock ~92 ~3 ~125 stone_brick_stairs 4  
fill ~93 ~3 ~76 ~94 ~3 ~76 stained_hardened_clay 9  
fill ~93 ~3 ~77 ~94 ~3 ~77 stained_hardened_clay 9  
fill ~93 ~3 ~78 ~94 ~3 ~78 stained_hardened_clay 9  
fill ~93 ~3 ~124 ~94 ~3 ~124 stained_hardened_clay 9  
fill ~93 ~3 ~125 ~94 ~3 ~125 stained_hardened_clay 9  
fill ~93 ~3 ~126 ~94 ~3 ~126 stained_hardened_clay 9  
fill ~95 ~3 ~76 ~95 ~3 ~78 stone 0  
fill ~95 ~3 ~124 ~95 ~3 ~126 stone 0  
fill ~96 ~3 ~76 ~96 ~197 ~76 stained_hardened_clay 9  
fill ~96 ~3 ~77 ~96 ~197 ~77 stained_hardened_clay 9  
fill ~96 ~3 ~78 ~100 ~3 ~78 stained_hardened_clay 9 
setblock ~96 ~3 ~79 stone 0 
setblock ~96 ~3 ~123 stone 0  
fill ~96 ~3 ~124 ~100 ~3 ~124 stained_hardened_clay 9  
fill ~96 ~3 ~125 ~96 ~197 ~125 stained_hardened_clay 9  
fill ~96 ~3 ~126 ~96 ~197 ~126 stained_hardened_clay 9 
setblock ~97 ~3 ~76 stone_brick_stairs 4 
setblock ~97 ~3 ~77 sea_lantern 0  
fill ~97 ~3 ~79 ~97 ~197 ~79 stained_hardened_clay 9  
fill ~97 ~3 ~123 ~97 ~197 ~123 stained_hardened_clay 9 
setblock ~97 ~3 ~125 sea_lantern 0 
setblock ~97 ~3 ~126 stone_brick_stairs 4  
fill ~98 ~3 ~75 ~98 ~197 ~75 stained_hardened_clay 9  
fill ~98 ~3 ~76 ~98 ~197 ~76 stained_hardened_clay 9  
fill ~98 ~3 ~77 ~100 ~3 ~77 stained_hardened_clay 9  
fill ~98 ~3 ~125 ~100 ~3 ~125 stained_hardened_clay 9  
fill ~98 ~3 ~126 ~98 ~197 ~126 stained_hardened_clay 9  
fill ~98 ~3 ~127 ~98 ~197 ~127 stained_hardened_clay 9 
setblock ~99 ~3 ~75 stone_brick_stairs 4 
setblock ~99 ~3 ~76 sea_lantern 0  
fill ~99 ~3 ~79 ~99 ~197 ~79 stained_hardened_clay 9  
fill ~99 ~3 ~123 ~99 ~197 ~123 stained_hardened_clay 9 
setblock ~99 ~3 ~126 sea_lantern 0 
setblock ~99 ~3 ~127 stone_brick_stairs 4  
fill ~100 ~3 ~75 ~100 ~197 ~75 stained_hardened_clay 9  
fill ~100 ~3 ~76 ~100 ~197 ~76 stained_hardened_clay 9  
fill ~100 ~3 ~126 ~100 ~197 ~126 stained_hardened_clay 9  
fill ~100 ~3 ~127 ~100 ~197 ~127 stained_hardened_clay 9  
fill ~101 ~3 ~75 ~101 ~3 ~78 stone 0  
fill ~101 ~3 ~79 ~101 ~197 ~79 stained_hardened_clay 9  
fill ~101 ~3 ~123 ~101 ~197 ~123 stained_hardened_clay 9  
fill ~101 ~3 ~124 ~101 ~3 ~127 stone 0  
fill ~102 ~3 ~75 ~102 ~197 ~75 stained_hardened_clay 9  
fill ~102 ~3 ~76 ~102 ~197 ~76 stained_hardened_clay 9  
fill ~102 ~3 ~77 ~104 ~3 ~77 stained_hardened_clay 9  
fill ~102 ~3 ~78 ~106 ~3 ~78 stained_hardened_clay 9  
fill ~102 ~3 ~124 ~106 ~3 ~124 stained_hardened_clay 9  
fill ~102 ~3 ~125 ~104 ~3 ~125 stained_hardened_clay 9  
fill ~102 ~3 ~126 ~102 ~197 ~126 stained_hardened_clay 9  
fill ~102 ~3 ~127 ~102 ~197 ~127 stained_hardened_clay 9 
setblock ~103 ~3 ~75 stone_brick_stairs 5 
setblock ~103 ~3 ~76 sea_lantern 0  
fill ~103 ~3 ~79 ~103 ~197 ~79 stained_hardened_clay 9  
fill ~103 ~3 ~123 ~103 ~197 ~123 stained_hardened_clay 9 
setblock ~103 ~3 ~126 sea_lantern 0 
setblock ~103 ~3 ~127 stone_brick_stairs 5  
fill ~104 ~3 ~75 ~104 ~197 ~75 stained_hardened_clay 9  
fill ~104 ~3 ~76 ~104 ~197 ~76 stained_hardened_clay 9  
fill ~104 ~3 ~126 ~104 ~197 ~126 stained_hardened_clay 9  
fill ~104 ~3 ~127 ~104 ~197 ~127 stained_hardened_clay 9 
setblock ~105 ~3 ~76 stone_brick_stairs 5 
setblock ~105 ~3 ~77 sea_lantern 0  
fill ~105 ~3 ~79 ~105 ~197 ~79 stained_hardened_clay 9  
fill ~105 ~3 ~123 ~105 ~197 ~123 stained_hardened_clay 9 
setblock ~105 ~3 ~125 sea_lantern 0 
setblock ~105 ~3 ~126 stone_brick_stairs 5  
fill ~106 ~3 ~76 ~106 ~197 ~76 stained_hardened_clay 9  
fill ~106 ~3 ~77 ~106 ~197 ~77 stained_hardened_clay 9 
setblock ~106 ~3 ~79 stone 0 
setblock ~106 ~3 ~123 stone 0  
fill ~106 ~3 ~125 ~106 ~197 ~125 stained_hardened_clay 9  
fill ~106 ~3 ~126 ~106 ~197 ~126 stained_hardened_clay 9  
fill ~107 ~3 ~76 ~107 ~3 ~78 stone 0  
fill ~107 ~3 ~79 ~111 ~3 ~79 stained_hardened_clay 9  
fill ~107 ~3 ~123 ~111 ~3 ~123 stained_hardened_clay 9  
fill ~107 ~3 ~124 ~107 ~3 ~126 stone 0  
fill ~108 ~3 ~76 ~109 ~3 ~76 stained_hardened_clay 9  
fill ~108 ~3 ~77 ~109 ~3 ~77 stained_hardened_clay 9  
fill ~108 ~3 ~78 ~109 ~3 ~78 stained_hardened_clay 9  
fill ~108 ~3 ~124 ~109 ~3 ~124 stained_hardened_clay 9  
fill ~108 ~3 ~125 ~109 ~3 ~125 stained_hardened_clay 9  
fill ~108 ~3 ~126 ~109 ~3 ~126 stained_hardened_clay 9 
setblock ~110 ~3 ~77 stone_brick_stairs 5 
setblock ~110 ~3 ~78 sea_lantern 0 
setblock ~110 ~3 ~124 sea_lantern 0 
setblock ~110 ~3 ~125 stone_brick_stairs 5  
fill ~111 ~3 ~77 ~111 ~197 ~77 stained_hardened_clay 9  
fill ~111 ~3 ~78 ~112 ~3 ~78 stained_hardened_clay 9 
setblock ~111 ~3 ~81 stone 0 
setblock ~111 ~3 ~121 stone 0  
fill ~111 ~3 ~124 ~112 ~3 ~124 stained_hardened_clay 9  
fill ~111 ~3 ~125 ~111 ~197 ~125 stained_hardened_clay 9  
fill ~112 ~3 ~79 ~112 ~3 ~80 stone 0  
fill ~112 ~3 ~81 ~116 ~3 ~81 stained_hardened_clay 9  
fill ~112 ~3 ~121 ~116 ~3 ~121 stained_hardened_clay 9  
fill ~112 ~3 ~122 ~112 ~3 ~123 stone 0 
setblock ~113 ~3 ~78 stone 0  
fill ~113 ~3 ~79 ~114 ~3 ~79 stained_hardened_clay 9  
fill ~113 ~3 ~80 ~114 ~3 ~80 stained_hardened_clay 9  
fill ~113 ~3 ~122 ~114 ~3 ~122 stained_hardened_clay 9  
fill ~113 ~3 ~123 ~114 ~3 ~123 stained_hardened_clay 9 
setblock ~113 ~3 ~124 stone 0 
setblock ~115 ~3 ~79 stone_brick_stairs 5 
setblock ~115 ~3 ~80 sea_lantern 0 
setblock ~115 ~3 ~122 sea_lantern 0 
setblock ~115 ~3 ~123 stone_brick_stairs 5  
fill ~116 ~3 ~80 ~116 ~197 ~80 stained_hardened_clay 9  
fill ~116 ~3 ~122 ~116 ~197 ~122 stained_hardened_clay 9 
setblock ~117 ~3 ~81 stone_brick_stairs 5 
setblock ~117 ~3 ~82 sea_lantern 0 
setblock ~117 ~3 ~85 stone 0 
setblock ~117 ~3 ~117 stone 0 
setblock ~117 ~3 ~120 sea_lantern 0 
setblock ~117 ~3 ~121 stone_brick_stairs 5  
fill ~118 ~3 ~81 ~118 ~197 ~81 stained_hardened_clay 9  
fill ~118 ~3 ~82 ~119 ~3 ~82 stained_hardened_clay 9 
setblock ~118 ~3 ~84 stone 0  
fill ~118 ~3 ~85 ~120 ~3 ~85 stained_hardened_clay 9  
fill ~118 ~3 ~117 ~120 ~3 ~117 stained_hardened_clay 9 
setblock ~118 ~3 ~118 stone 0  
fill ~118 ~3 ~120 ~119 ~3 ~120 stained_hardened_clay 9  
fill ~118 ~3 ~121 ~118 ~197 ~121 stained_hardened_clay 9 
setblock ~119 ~3 ~83 stone 0  
fill ~119 ~3 ~84 ~121 ~3 ~84 stained_hardened_clay 9  
fill ~119 ~3 ~118 ~121 ~3 ~118 stained_hardened_clay 9 
setblock ~119 ~3 ~119 stone 0  
fill ~120 ~3 ~83 ~120 ~197 ~83 stained_hardened_clay 9  
fill ~120 ~3 ~119 ~120 ~197 ~119 stained_hardened_clay 9 
setblock ~121 ~3 ~85 sea_lantern 0 
setblock ~121 ~3 ~91 stone 0 
setblock ~121 ~3 ~111 stone 0 
setblock ~121 ~3 ~117 sea_lantern 0 
setblock ~122 ~3 ~85 stone_brick_stairs 6 
setblock ~122 ~3 ~87 sea_lantern 0  
fill ~122 ~3 ~90 ~123 ~3 ~90 stone 0  
fill ~122 ~3 ~91 ~125 ~3 ~91 stained_hardened_clay 9  
fill ~122 ~3 ~111 ~125 ~3 ~111 stained_hardened_clay 9  
fill ~122 ~3 ~112 ~123 ~3 ~112 stone 0 
setblock ~122 ~3 ~115 sea_lantern 0 
setblock ~122 ~3 ~117 stone_brick_stairs 7 
setblock ~123 ~3 ~87 stone_brick_stairs 6 
setblock ~123 ~3 ~96 stone 0 
setblock ~123 ~3 ~106 stone 0 
setblock ~123 ~3 ~115 stone_brick_stairs 7 
setblock ~124 ~3 ~89 stone 0  
fill ~124 ~3 ~90 ~124 ~197 ~90 stained_hardened_clay 9  
fill ~124 ~3 ~95 ~126 ~3 ~95 stone 0  
fill ~124 ~3 ~96 ~126 ~3 ~96 stained_hardened_clay 9  
fill ~124 ~3 ~101 ~127 ~3 ~101 stone 0  
fill ~124 ~3 ~106 ~126 ~3 ~106 stained_hardened_clay 9  
fill ~124 ~3 ~107 ~126 ~3 ~107 stone 0  
fill ~124 ~3 ~112 ~124 ~197 ~112 stained_hardened_clay 9 
setblock ~124 ~3 ~113 stone 0  
fill ~70 ~4 ~97 ~70 ~4 ~99 stone_slab 13  
fill ~70 ~4 ~103 ~70 ~4 ~105 stone_slab 13 
setblock ~71 ~4 ~92 stone_slab 13 
setblock ~71 ~4 ~110 stone_slab 13  
fill ~72 ~4 ~95 ~72 ~4 ~107 stone 0  
fill ~73 ~4 ~91 ~73 ~4 ~94 stone 0  
fill ~73 ~4 ~95 ~74 ~4 ~95 stained_hardened_clay 9  
fill ~73 ~4 ~96 ~129 ~4 ~96 stained_hardened_clay 9  
fill ~73 ~4 ~97 ~129 ~4 ~97 stained_hardened_clay 9  
fill ~73 ~4 ~98 ~129 ~4 ~98 stained_hardened_clay 9  
fill ~73 ~4 ~99 ~129 ~4 ~99 stained_hardened_clay 9  
fill ~73 ~4 ~100 ~129 ~4 ~100 stained_hardened_clay 9  
fill ~73 ~4 ~101 ~74 ~4 ~101 stone 0  
fill ~73 ~4 ~102 ~129 ~4 ~102 stained_hardened_clay 9  
fill ~73 ~4 ~103 ~129 ~4 ~103 stained_hardened_clay 9  
fill ~73 ~4 ~104 ~129 ~4 ~104 stained_hardened_clay 9  
fill ~73 ~4 ~105 ~129 ~4 ~105 stained_hardened_clay 9  
fill ~73 ~4 ~106 ~129 ~4 ~106 stained_hardened_clay 9  
fill ~73 ~4 ~107 ~74 ~4 ~107 stained_hardened_clay 9  
fill ~73 ~4 ~108 ~74 ~4 ~108 stone 0  
fill ~73 ~4 ~109 ~73 ~4 ~111 stone 0  
fill ~74 ~4 ~89 ~74 ~4 ~90 stone 0  
fill ~74 ~4 ~91 ~128 ~4 ~91 stained_hardened_clay 9  
fill ~74 ~4 ~92 ~128 ~4 ~92 stained_hardened_clay 9  
fill ~74 ~4 ~93 ~128 ~4 ~93 stained_hardened_clay 9 
setblock ~74 ~4 ~94 stone 0  
fill ~74 ~4 ~109 ~128 ~4 ~109 stained_hardened_clay 9  
fill ~74 ~4 ~110 ~128 ~4 ~110 stained_hardened_clay 9  
fill ~74 ~4 ~111 ~128 ~4 ~111 stained_hardened_clay 9  
fill ~74 ~4 ~112 ~74 ~4 ~113 stone 0  
fill ~75 ~4 ~87 ~75 ~4 ~88 stone 0  
fill ~75 ~4 ~89 ~76 ~4 ~89 stained_hardened_clay 9  
fill ~75 ~4 ~90 ~127 ~4 ~90 stained_hardened_clay 9  
fill ~75 ~4 ~94 ~127 ~4 ~94 stained_hardened_clay 9 
setblock ~75 ~4 ~95 stone 0  
fill ~75 ~4 ~101 ~127 ~4 ~101 stained_hardened_clay 9 
setblock ~75 ~4 ~107 stone 0  
fill ~75 ~4 ~108 ~127 ~4 ~108 stained_hardened_clay 9  
fill ~75 ~4 ~112 ~127 ~4 ~112 stained_hardened_clay 9  
fill ~75 ~4 ~113 ~76 ~4 ~113 stained_hardened_clay 9  
fill ~75 ~4 ~114 ~76 ~4 ~114 stone 0  
fill ~75 ~4 ~115 ~75 ~4 ~114 stone 0  
fill ~76 ~4 ~85 ~76 ~4 ~86 stone 0  
fill ~76 ~4 ~87 ~126 ~4 ~87 stained_hardened_clay 9 
setblock ~76 ~4 ~88 stone 0  
fill ~76 ~4 ~95 ~126 ~4 ~95 stained_hardened_clay 9  
fill ~76 ~4 ~107 ~126 ~4 ~107 stained_hardened_clay 9  
fill ~76 ~4 ~115 ~126 ~4 ~115 stained_hardened_clay 9  
fill ~76 ~4 ~116 ~76 ~4 ~117 stone 0 
setblock ~77 ~4 ~84 stone 0  
fill ~77 ~4 ~85 ~125 ~4 ~85 stained_hardened_clay 9  
fill ~77 ~4 ~86 ~125 ~4 ~86 stained_hardened_clay 9  
fill ~77 ~4 ~88 ~125 ~4 ~88 stained_hardened_clay 9 
setblock ~77 ~4 ~89 stone 0 
setblock ~77 ~4 ~113 stone 0  
fill ~77 ~4 ~114 ~125 ~4 ~114 stained_hardened_clay 9  
fill ~77 ~4 ~116 ~125 ~4 ~116 stained_hardened_clay 9  
fill ~77 ~4 ~117 ~125 ~4 ~117 stained_hardened_clay 9 
setblock ~77 ~4 ~118 stone 0 
setblock ~78 ~4 ~83 stone 0  
fill ~78 ~4 ~84 ~124 ~4 ~84 stained_hardened_clay 9  
fill ~78 ~4 ~89 ~124 ~4 ~89 stained_hardened_clay 9  
fill ~78 ~4 ~113 ~124 ~4 ~113 stained_hardened_clay 9  
fill ~78 ~4 ~118 ~124 ~4 ~118 stained_hardened_clay 9 
setblock ~78 ~4 ~119 stone 0 
setblock ~79 ~4 ~78 stone_slab 13  
fill ~79 ~4 ~81 ~79 ~4 ~82 stone 0  
fill ~79 ~4 ~83 ~123 ~4 ~83 stained_hardened_clay 9  
fill ~79 ~4 ~119 ~123 ~4 ~119 stained_hardened_clay 9  
fill ~79 ~4 ~120 ~79 ~4 ~121 stone 0 
setblock ~79 ~4 ~124 stone_slab 13 
setblock ~80 ~4 ~80 stone 0  
fill ~80 ~4 ~81 ~80 ~196 ~81 stained_hardened_clay 9  
fill ~80 ~4 ~82 ~81 ~4 ~82 stained_hardened_clay 9  
fill ~80 ~4 ~120 ~81 ~4 ~120 stained_hardened_clay 9  
fill ~80 ~4 ~121 ~80 ~196 ~121 stained_hardened_clay 9 
setblock ~80 ~4 ~122 stone 0 
setblock ~81 ~4 ~77 stone_slab 13  
fill ~81 ~4 ~79 ~82 ~4 ~79 stone 0  
fill ~81 ~4 ~80 ~121 ~4 ~80 stained_hardened_clay 9 
setblock ~81 ~4 ~81 stone 0 
setblock ~81 ~4 ~121 stone 0  
fill ~81 ~4 ~122 ~121 ~4 ~122 stained_hardened_clay 9  
fill ~81 ~4 ~123 ~82 ~4 ~123 stone 0 
setblock ~81 ~4 ~125 stone_slab 13  
fill ~82 ~4 ~81 ~120 ~4 ~81 stained_hardened_clay 9 
setblock ~82 ~4 ~82 stone 0 
setblock ~82 ~4 ~120 stone 0  
fill ~82 ~4 ~121 ~120 ~4 ~121 stained_hardened_clay 9 
setblock ~83 ~4 ~75 stone_slab 13 
setblock ~83 ~4 ~78 stone 0  
fill ~83 ~4 ~79 ~119 ~4 ~79 stained_hardened_clay 9  
fill ~83 ~4 ~82 ~119 ~4 ~82 stained_hardened_clay 9  
fill ~83 ~4 ~120 ~119 ~4 ~120 stained_hardened_clay 9  
fill ~83 ~4 ~123 ~119 ~4 ~123 stained_hardened_clay 9 
setblock ~83 ~4 ~124 stone 0 
setblock ~83 ~4 ~127 stone_slab 13 
setblock ~84 ~4 ~77 stone 0  
fill ~84 ~4 ~78 ~118 ~4 ~78 stained_hardened_clay 9  
fill ~84 ~4 ~124 ~118 ~4 ~124 stained_hardened_clay 9 
setblock ~84 ~4 ~125 stone 0  
fill ~85 ~4 ~76 ~86 ~4 ~76 stone 0  
fill ~85 ~4 ~77 ~88 ~4 ~77 stained_hardened_clay 9  
fill ~85 ~4 ~125 ~88 ~4 ~125 stained_hardened_clay 9  
fill ~85 ~4 ~126 ~86 ~4 ~126 stone 0  
fill ~87 ~4 ~75 ~88 ~4 ~75 stone 0  
fill ~87 ~4 ~76 ~87 ~196 ~76 stained_hardened_clay 9  
fill ~87 ~4 ~126 ~87 ~196 ~126 stained_hardened_clay 9  
fill ~87 ~4 ~127 ~88 ~4 ~127 stone 0 
setblock ~88 ~4 ~76 stone 0 
setblock ~88 ~4 ~126 stone 0 
setblock ~89 ~4 ~72 stone_slab 13  
fill ~89 ~4 ~74 ~90 ~4 ~74 stone 0  
fill ~89 ~4 ~75 ~94 ~4 ~75 stained_hardened_clay 9  
fill ~89 ~4 ~76 ~113 ~4 ~76 stained_hardened_clay 9 
setblock ~89 ~4 ~77 stone 0 
setblock ~89 ~4 ~125 stone 0  
fill ~89 ~4 ~126 ~113 ~4 ~126 stained_hardened_clay 9  
fill ~89 ~4 ~127 ~94 ~4 ~127 stained_hardened_clay 9  
fill ~89 ~4 ~128 ~90 ~4 ~128 stone 0 
setblock ~89 ~4 ~130 stone_slab 13  
fill ~90 ~4 ~77 ~90 ~196 ~77 stained_hardened_clay 9  
fill ~90 ~4 ~125 ~90 ~196 ~125 stained_hardened_clay 9  
fill ~91 ~4 ~73 ~94 ~4 ~73 stone 0  
fill ~91 ~4 ~74 ~93 ~4 ~74 stained_hardened_clay 9  
fill ~91 ~4 ~128 ~93 ~4 ~128 stained_hardened_clay 9  
fill ~91 ~4 ~129 ~94 ~4 ~129 stone 0  
fill ~92 ~4 ~77 ~112 ~4 ~77 stained_hardened_clay 9  
fill ~92 ~4 ~125 ~112 ~4 ~125 stained_hardened_clay 9 
setblock ~94 ~4 ~74 stone 0 
setblock ~94 ~4 ~128 stone 0  
fill ~95 ~4 ~72 ~107 ~4 ~72 stone 0  
fill ~95 ~4 ~73 ~100 ~4 ~73 stained_hardened_clay 9  
fill ~95 ~4 ~74 ~100 ~4 ~74 stained_hardened_clay 9 
setblock ~95 ~4 ~75 stone 0 
setblock ~95 ~4 ~127 stone 0  
fill ~95 ~4 ~128 ~100 ~4 ~128 stained_hardened_clay 9  
fill ~95 ~4 ~129 ~100 ~4 ~129 stained_hardened_clay 9  
fill ~95 ~4 ~130 ~107 ~4 ~130 stone 0 
setblock ~96 ~4 ~70 stone_slab 13  
fill ~96 ~4 ~75 ~106 ~4 ~75 stained_hardened_clay 9  
fill ~96 ~4 ~127 ~106 ~4 ~127 stained_hardened_clay 9 
setblock ~96 ~4 ~132 stone_slab 13 
setblock ~98 ~4 ~70 stone_slab 13 
setblock ~98 ~4 ~132 stone_slab 13 
setblock ~100 ~4 ~70 stone_slab 13 
setblock ~100 ~4 ~132 stone_slab 13  
fill ~101 ~4 ~73 ~101 ~4 ~74 stone 0  
fill ~101 ~4 ~128 ~101 ~4 ~130 stone 0 
setblock ~102 ~4 ~70 stone_slab 13  
fill ~102 ~4 ~73 ~107 ~4 ~73 stained_hardened_clay 9  
fill ~102 ~4 ~74 ~107 ~4 ~74 stained_hardened_clay 9  
fill ~102 ~4 ~128 ~107 ~4 ~128 stained_hardened_clay 9  
fill ~102 ~4 ~129 ~107 ~4 ~129 stained_hardened_clay 9 
setblock ~102 ~4 ~132 stone_slab 13 
setblock ~104 ~4 ~70 stone_slab 13 
setblock ~104 ~4 ~132 stone_slab 13 
setblock ~106 ~4 ~70 stone_slab 13 
setblock ~106 ~4 ~132 stone_slab 13 
setblock ~107 ~4 ~75 stone 0 
setblock ~107 ~4 ~127 stone 0  
fill ~108 ~4 ~73 ~111 ~4 ~73 stone 0  
fill ~108 ~4 ~74 ~108 ~4 ~73 stone 0  
fill ~108 ~4 ~75 ~113 ~4 ~75 stained_hardened_clay 9  
fill ~108 ~4 ~127 ~113 ~4 ~127 stained_hardened_clay 9  
fill ~108 ~4 ~128 ~108 ~4 ~129 stone 0  
fill ~109 ~4 ~74 ~111 ~4 ~74 stained_hardened_clay 9  
fill ~109 ~4 ~128 ~111 ~4 ~128 stained_hardened_clay 9  
fill ~109 ~4 ~129 ~111 ~4 ~129 stone 0  
fill ~112 ~4 ~74 ~113 ~4 ~74 stone 0  
fill ~112 ~4 ~128 ~113 ~4 ~128 stone 0 
setblock ~113 ~4 ~72 stone_slab 13 
setblock ~113 ~4 ~77 stone 0 
setblock ~113 ~4 ~125 stone 0 
setblock ~113 ~4 ~130 stone_slab 13  
fill ~114 ~4 ~75 ~115 ~4 ~75 stone 0  
fill ~114 ~4 ~76 ~114 ~4 ~75 stone 0  
fill ~114 ~4 ~77 ~117 ~4 ~77 stained_hardened_clay 9  
fill ~114 ~4 ~125 ~117 ~4 ~125 stained_hardened_clay 9  
fill ~114 ~4 ~126 ~114 ~4 ~127 stone 0  
fill ~115 ~4 ~76 ~115 ~196 ~76 stained_hardened_clay 9  
fill ~115 ~4 ~126 ~115 ~196 ~126 stained_hardened_clay 9 
setblock ~115 ~4 ~127 stone 0  
fill ~116 ~4 ~76 ~117 ~4 ~76 stone 0  
fill ~116 ~4 ~126 ~117 ~4 ~126 stone 0 
setblock ~118 ~4 ~77 stone 0 
setblock ~118 ~4 ~125 stone 0 
setblock ~119 ~4 ~75 stone_slab 13 
setblock ~119 ~4 ~78 stone 0 
setblock ~119 ~4 ~124 stone 0 
setblock ~119 ~4 ~127 stone_slab 13  
fill ~120 ~4 ~79 ~121 ~4 ~79 stone 0 
setblock ~120 ~4 ~82 stone 0 
setblock ~120 ~4 ~120 stone 0  
fill ~120 ~4 ~123 ~121 ~4 ~123 stone 0 
setblock ~121 ~4 ~77 stone_slab 13 
setblock ~121 ~4 ~81 stone 0  
fill ~121 ~4 ~82 ~122 ~4 ~82 stained_hardened_clay 9  
fill ~121 ~4 ~120 ~122 ~4 ~120 stained_hardened_clay 9 
setblock ~121 ~4 ~121 stone 0 
setblock ~121 ~4 ~125 stone_slab 13 
setblock ~122 ~4 ~80 stone 0  
fill ~122 ~4 ~81 ~122 ~196 ~81 stained_hardened_clay 9  
fill ~122 ~4 ~121 ~122 ~196 ~121 stained_hardened_clay 9 
setblock ~122 ~4 ~122 stone 0 
setblock ~123 ~4 ~78 stone_slab 13  
fill ~123 ~4 ~81 ~123 ~4 ~82 stone 0  
fill ~123 ~4 ~120 ~123 ~4 ~121 stone 0 
setblock ~123 ~4 ~124 stone_slab 13 
setblock ~124 ~4 ~83 stone 0 
setblock ~124 ~4 ~119 stone 0 
setblock ~125 ~4 ~84 stone 0 
setblock ~125 ~4 ~89 stone 0 
setblock ~125 ~4 ~113 stone 0 
setblock ~125 ~4 ~118 stone 0  
fill ~126 ~4 ~85 ~126 ~4 ~86 stone 0  
fill ~126 ~4 ~88 ~127 ~4 ~88 stone 0  
fill ~126 ~4 ~89 ~127 ~4 ~89 stained_hardened_clay 9  
fill ~126 ~4 ~113 ~127 ~4 ~113 stained_hardened_clay 9  
fill ~126 ~4 ~114 ~127 ~4 ~114 stone 0  
fill ~126 ~4 ~116 ~126 ~4 ~117 stone 0 
setblock ~127 ~4 ~87 stone 0 
setblock ~127 ~4 ~95 stone 0 
setblock ~127 ~4 ~107 stone 0 
setblock ~127 ~4 ~115 stone 0  
fill ~128 ~4 ~89 ~128 ~4 ~90 stone 0  
fill ~128 ~4 ~94 ~129 ~4 ~94 stone 0  
fill ~128 ~4 ~95 ~129 ~4 ~95 stained_hardened_clay 9  
fill ~128 ~4 ~101 ~130 ~4 ~101 stone 0  
fill ~128 ~4 ~107 ~129 ~4 ~107 stained_hardened_clay 9  
fill ~128 ~4 ~108 ~129 ~4 ~108 stone 0  
fill ~128 ~4 ~112 ~128 ~4 ~113 stone 0  
fill ~129 ~4 ~91 ~129 ~4 ~94 stone 0  
fill ~129 ~4 ~109 ~129 ~4 ~111 stone 0  
fill ~130 ~4 ~95 ~130 ~4 ~107 stone 0 
setblock ~131 ~4 ~92 stone_slab 13 
setblock ~131 ~4 ~110 stone_slab 13  
fill ~132 ~4 ~97 ~132 ~4 ~99 stone_slab 13  
fill ~132 ~4 ~103 ~132 ~4 ~105 stone_slab 13  
fill ~69 ~5 ~94 ~133 ~5 ~94 stained_hardened_clay 9  
fill ~69 ~5 ~95 ~71 ~5 ~95 stone 0  
fill ~69 ~5 ~96 ~133 ~5 ~96 stained_hardened_clay 9  
fill ~69 ~5 ~97 ~69 ~5 ~99 stone_brick_stairs 6  
fill ~69 ~5 ~100 ~133 ~5 ~100 stained_hardened_clay 9  
fill ~69 ~5 ~101 ~71 ~5 ~101 stone 0  
fill ~69 ~5 ~102 ~133 ~5 ~102 stained_hardened_clay 9  
fill ~69 ~5 ~103 ~69 ~5 ~105 stone_brick_stairs 7  
fill ~69 ~5 ~106 ~133 ~5 ~106 stained_hardened_clay 9  
fill ~69 ~5 ~107 ~71 ~5 ~107 stone 0  
fill ~69 ~5 ~108 ~133 ~5 ~108 stained_hardened_clay 9  
fill ~70 ~5 ~91 ~132 ~5 ~91 stained_hardened_clay 9 
setblock ~70 ~5 ~92 stone_brick_stairs 6  
fill ~70 ~5 ~93 ~132 ~5 ~93 stained_hardened_clay 9  
fill ~70 ~5 ~97 ~70 ~5 ~99 sea_lantern 0  
fill ~70 ~5 ~103 ~70 ~5 ~105 sea_lantern 0  
fill ~70 ~5 ~109 ~132 ~5 ~109 stained_hardened_clay 9 
setblock ~70 ~5 ~110 stone_brick_stairs 7  
fill ~70 ~5 ~111 ~132 ~5 ~111 stained_hardened_clay 9 
setblock ~71 ~5 ~85 stone_slab 13  
fill ~71 ~5 ~88 ~131 ~5 ~88 stained_hardened_clay 9  
fill ~71 ~5 ~89 ~73 ~5 ~89 stone 0  
fill ~71 ~5 ~90 ~131 ~5 ~90 stained_hardened_clay 9 
setblock ~71 ~5 ~92 sea_lantern 0  
fill ~71 ~5 ~97 ~131 ~5 ~97 stained_hardened_clay 9  
fill ~71 ~5 ~98 ~131 ~5 ~98 stained_hardened_clay 9  
fill ~71 ~5 ~99 ~131 ~5 ~99 stained_hardened_clay 9  
fill ~71 ~5 ~103 ~131 ~5 ~103 stained_hardened_clay 9  
fill ~71 ~5 ~104 ~131 ~5 ~104 stained_hardened_clay 9  
fill ~71 ~5 ~105 ~131 ~5 ~105 stained_hardened_clay 9 
setblock ~71 ~5 ~110 sea_lantern 0  
fill ~71 ~5 ~112 ~131 ~5 ~112 stained_hardened_clay 9  
fill ~71 ~5 ~113 ~73 ~5 ~113 stone 0  
fill ~71 ~5 ~114 ~131 ~5 ~114 stained_hardened_clay 9 
setblock ~71 ~5 ~117 stone_slab 13 
setblock ~72 ~5 ~82 stone_slab 13  
fill ~72 ~5 ~86 ~130 ~5 ~86 stained_hardened_clay 9  
fill ~72 ~5 ~87 ~130 ~5 ~87 stained_hardened_clay 9  
fill ~72 ~5 ~92 ~130 ~5 ~92 stained_hardened_clay 9  
fill ~72 ~5 ~95 ~130 ~5 ~95 stained_hardened_clay 9  
fill ~72 ~5 ~101 ~130 ~5 ~101 stained_hardened_clay 9  
fill ~72 ~5 ~107 ~130 ~5 ~107 stained_hardened_clay 9  
fill ~72 ~5 ~110 ~130 ~5 ~110 stained_hardened_clay 9  
fill ~72 ~5 ~115 ~130 ~5 ~115 stained_hardened_clay 9  
fill ~72 ~5 ~116 ~130 ~5 ~116 stained_hardened_clay 9 
setblock ~72 ~5 ~120 stone_slab 13  
fill ~73 ~5 ~84 ~129 ~5 ~84 stained_hardened_clay 9  
fill ~73 ~5 ~85 ~129 ~5 ~85 stained_hardened_clay 9  
fill ~73 ~5 ~117 ~129 ~5 ~117 stained_hardened_clay 9  
fill ~73 ~5 ~118 ~129 ~5 ~118 stained_hardened_clay 9 
setblock ~74 ~5 ~80 stone_slab 13  
fill ~74 ~5 ~83 ~128 ~5 ~83 stained_hardened_clay 9  
fill ~74 ~5 ~89 ~128 ~5 ~89 stained_hardened_clay 9  
fill ~74 ~5 ~113 ~128 ~5 ~113 stained_hardened_clay 9  
fill ~74 ~5 ~119 ~128 ~5 ~119 stained_hardened_clay 9 
setblock ~74 ~5 ~122 stone_slab 13  
fill ~75 ~5 ~82 ~127 ~5 ~82 stained_hardened_clay 9  
fill ~75 ~5 ~120 ~127 ~5 ~120 stained_hardened_clay 9  
fill ~76 ~5 ~80 ~77 ~5 ~80 stained_hardened_clay 9  
fill ~76 ~5 ~81 ~77 ~5 ~81 stained_hardened_clay 9  
fill ~76 ~5 ~121 ~77 ~5 ~121 stained_hardened_clay 9  
fill ~76 ~5 ~122 ~77 ~5 ~122 stained_hardened_clay 9  
fill ~77 ~5 ~79 ~78 ~5 ~79 stone 0  
fill ~77 ~5 ~123 ~78 ~5 ~123 stone 0  
fill ~78 ~5 ~78 ~78 ~195 ~78 stained_hardened_clay 9  
fill ~78 ~5 ~80 ~78 ~5 ~81 stone 0  
fill ~78 ~5 ~121 ~78 ~5 ~123 stone 0  
fill ~78 ~5 ~124 ~78 ~195 ~124 stained_hardened_clay 9 
setblock ~79 ~5 ~77 stone_brick_stairs 4 
setblock ~79 ~5 ~78 sea_lantern 0  
fill ~79 ~5 ~79 ~123 ~5 ~79 stained_hardened_clay 9  
fill ~79 ~5 ~80 ~123 ~5 ~80 stained_hardened_clay 9  
fill ~79 ~5 ~81 ~79 ~195 ~81 stained_hardened_clay 9  
fill ~79 ~5 ~121 ~79 ~195 ~121 stained_hardened_clay 9  
fill ~79 ~5 ~122 ~123 ~5 ~122 stained_hardened_clay 9  
fill ~79 ~5 ~123 ~123 ~5 ~123 stained_hardened_clay 9 
setblock ~79 ~5 ~124 sea_lantern 0 
setblock ~79 ~5 ~125 stone_brick_stairs 4  
fill ~80 ~5 ~76 ~80 ~195 ~76 stained_hardened_clay 9  
fill ~80 ~5 ~77 ~80 ~195 ~77 stained_hardened_clay 9  
fill ~80 ~5 ~78 ~122 ~5 ~78 stained_hardened_clay 9  
fill ~80 ~5 ~124 ~122 ~5 ~124 stained_hardened_clay 9  
fill ~80 ~5 ~125 ~80 ~195 ~125 stained_hardened_clay 9  
fill ~80 ~5 ~126 ~80 ~195 ~126 stained_hardened_clay 9 
setblock ~81 ~5 ~76 stone_brick_stairs 4 
setblock ~81 ~5 ~77 sea_lantern 0  
fill ~81 ~5 ~81 ~123 ~5 ~81 stained_hardened_clay 9  
fill ~81 ~5 ~121 ~123 ~5 ~121 stained_hardened_clay 9 
setblock ~81 ~5 ~125 sea_lantern 0 
setblock ~81 ~5 ~126 stone_brick_stairs 4  
fill ~82 ~5 ~75 ~82 ~195 ~75 stained_hardened_clay 9  
fill ~82 ~5 ~76 ~120 ~5 ~76 stained_hardened_clay 9  
fill ~82 ~5 ~77 ~120 ~5 ~77 stained_hardened_clay 9  
fill ~82 ~5 ~125 ~120 ~5 ~125 stained_hardened_clay 9  
fill ~82 ~5 ~126 ~120 ~5 ~126 stained_hardened_clay 9  
fill ~82 ~5 ~127 ~82 ~195 ~127 stained_hardened_clay 9 
setblock ~83 ~5 ~74 stone_brick_stairs 4 
setblock ~83 ~5 ~75 sea_lantern 0 
setblock ~83 ~5 ~127 sea_lantern 0 
setblock ~83 ~5 ~128 stone_brick_stairs 4  
fill ~84 ~5 ~73 ~84 ~195 ~73 stained_hardened_clay 9  
fill ~84 ~5 ~74 ~85 ~5 ~74 stained_hardened_clay 9  
fill ~84 ~5 ~75 ~85 ~5 ~75 stained_hardened_clay 9  
fill ~84 ~5 ~127 ~85 ~5 ~127 stained_hardened_clay 9  
fill ~84 ~5 ~128 ~85 ~5 ~128 stained_hardened_clay 9  
fill ~84 ~5 ~129 ~84 ~195 ~129 stained_hardened_clay 9  
fill ~85 ~5 ~73 ~86 ~5 ~73 stone 0  
fill ~85 ~5 ~129 ~86 ~5 ~129 stone 0  
fill ~86 ~5 ~72 ~88 ~5 ~72 stained_hardened_clay 9  
fill ~86 ~5 ~74 ~86 ~5 ~75 stone 0  
fill ~86 ~5 ~127 ~86 ~5 ~129 stone 0  
fill ~86 ~5 ~130 ~88 ~5 ~130 stained_hardened_clay 9 
setblock ~87 ~5 ~70 stone_slab 13  
fill ~87 ~5 ~73 ~115 ~5 ~73 stained_hardened_clay 9  
fill ~87 ~5 ~74 ~115 ~5 ~74 stained_hardened_clay 9  
fill ~87 ~5 ~75 ~115 ~5 ~75 stained_hardened_clay 9  
fill ~87 ~5 ~127 ~115 ~5 ~127 stained_hardened_clay 9  
fill ~87 ~5 ~128 ~115 ~5 ~128 stained_hardened_clay 9  
fill ~87 ~5 ~129 ~115 ~5 ~129 stained_hardened_clay 9 
setblock ~87 ~5 ~132 stone_slab 13  
fill ~88 ~5 ~71 ~88 ~195 ~71 stained_hardened_clay 9  
fill ~88 ~5 ~131 ~88 ~195 ~131 stained_hardened_clay 9 
setblock ~89 ~5 ~69 stone_slab 13 
setblock ~89 ~5 ~71 stone_brick_stairs 4 
setblock ~89 ~5 ~72 sea_lantern 0 
setblock ~89 ~5 ~130 sea_lantern 0 
setblock ~89 ~5 ~131 stone_brick_stairs 4 
setblock ~89 ~5 ~133 stone_slab 13  
fill ~90 ~5 ~71 ~92 ~5 ~71 stained_hardened_clay 9  
fill ~90 ~5 ~72 ~92 ~5 ~72 stained_hardened_clay 9  
fill ~90 ~5 ~130 ~92 ~5 ~130 stained_hardened_clay 9  
fill ~90 ~5 ~131 ~92 ~5 ~131 stained_hardened_clay 9  
fill ~91 ~5 ~70 ~92 ~5 ~70 stained_hardened_clay 9  
fill ~91 ~5 ~132 ~92 ~5 ~132 stained_hardened_clay 9  
fill ~93 ~5 ~70 ~93 ~5 ~72 stone 0  
fill ~93 ~5 ~130 ~93 ~5 ~132 stone 0 
setblock ~94 ~5 ~68 stone_slab 13  
fill ~94 ~5 ~69 ~95 ~5 ~69 stained_hardened_clay 9  
fill ~94 ~5 ~70 ~95 ~5 ~70 stained_hardened_clay 9  
fill ~94 ~5 ~71 ~100 ~5 ~71 stained_hardened_clay 9  
fill ~94 ~5 ~72 ~108 ~5 ~72 stained_hardened_clay 9  
fill ~94 ~5 ~130 ~108 ~5 ~130 stained_hardened_clay 9  
fill ~94 ~5 ~131 ~100 ~5 ~131 stained_hardened_clay 9  
fill ~94 ~5 ~132 ~95 ~5 ~132 stained_hardened_clay 9  
fill ~94 ~5 ~133 ~95 ~5 ~133 stained_hardened_clay 9 
setblock ~94 ~5 ~134 stone_slab 13 
setblock ~96 ~5 ~69 stone_brick_stairs 4 
setblock ~96 ~5 ~70 sea_lantern 0 
setblock ~96 ~5 ~132 sea_lantern 0 
setblock ~96 ~5 ~133 stone_brick_stairs 4  
fill ~97 ~5 ~69 ~97 ~195 ~69 stained_hardened_clay 9  
fill ~97 ~5 ~70 ~97 ~195 ~70 stained_hardened_clay 9  
fill ~97 ~5 ~132 ~97 ~195 ~132 stained_hardened_clay 9  
fill ~97 ~5 ~133 ~97 ~195 ~133 stained_hardened_clay 9 
setblock ~98 ~5 ~69 stone_brick_stairs 4 
setblock ~98 ~5 ~70 sea_lantern 0 
setblock ~98 ~5 ~132 sea_lantern 0 
setblock ~98 ~5 ~133 stone_brick_stairs 4 
setblock ~99 ~5 ~67 stone_slab 13  
fill ~99 ~5 ~69 ~99 ~195 ~69 stained_hardened_clay 9  
fill ~99 ~5 ~70 ~99 ~195 ~70 stained_hardened_clay 9  
fill ~99 ~5 ~132 ~99 ~195 ~132 stained_hardened_clay 9  
fill ~99 ~5 ~133 ~99 ~195 ~133 stained_hardened_clay 9 
setblock ~99 ~5 ~135 stone_slab 13 
setblock ~100 ~5 ~69 stone_brick_stairs 4 
setblock ~100 ~5 ~70 sea_lantern 0 
setblock ~100 ~5 ~132 sea_lantern 0 
setblock ~100 ~5 ~133 stone_brick_stairs 4  
fill ~101 ~5 ~69 ~101 ~5 ~71 stone 0  
fill ~101 ~5 ~131 ~101 ~5 ~133 stone 0 
setblock ~102 ~5 ~69 stone_brick_stairs 5 
setblock ~102 ~5 ~70 sea_lantern 0  
fill ~102 ~5 ~71 ~108 ~5 ~71 stained_hardened_clay 9  
fill ~102 ~5 ~131 ~108 ~5 ~131 stained_hardened_clay 9 
setblock ~102 ~5 ~132 sea_lantern 0 
setblock ~102 ~5 ~133 stone_brick_stairs 5 
setblock ~103 ~5 ~67 stone_slab 13  
fill ~103 ~5 ~69 ~103 ~195 ~69 stained_hardened_clay 9  
fill ~103 ~5 ~70 ~103 ~195 ~70 stained_hardened_clay 9  
fill ~103 ~5 ~132 ~103 ~195 ~132 stained_hardened_clay 9  
fill ~103 ~5 ~133 ~103 ~195 ~133 stained_hardened_clay 9 
setblock ~103 ~5 ~135 stone_slab 13 
setblock ~104 ~5 ~69 stone_brick_stairs 5 
setblock ~104 ~5 ~70 sea_lantern 0 
setblock ~104 ~5 ~132 sea_lantern 0 
setblock ~104 ~5 ~133 stone_brick_stairs 5  
fill ~105 ~5 ~69 ~105 ~195 ~69 stained_hardened_clay 9  
fill ~105 ~5 ~70 ~105 ~195 ~70 stained_hardened_clay 9  
fill ~105 ~5 ~132 ~105 ~195 ~132 stained_hardened_clay 9  
fill ~105 ~5 ~133 ~105 ~195 ~133 stained_hardened_clay 9 
setblock ~106 ~5 ~69 stone_brick_stairs 5 
setblock ~106 ~5 ~70 sea_lantern 0 
setblock ~106 ~5 ~132 sea_lantern 0 
setblock ~106 ~5 ~133 stone_brick_stairs 5  
fill ~107 ~5 ~69 ~108 ~5 ~69 stained_hardened_clay 9   
fill ~107 ~5 ~70 ~108 ~5 ~70 stained_hardened_clay 9  
fill ~107 ~5 ~132 ~108 ~5 ~132 stained_hardened_clay 9  
fill ~107 ~5 ~133 ~108 ~5 ~133 stained_hardened_clay 9 
setblock ~108 ~5 ~68 stone_slab 13 
setblock ~108 ~5 ~134 stone_slab 13  
fill ~109 ~5 ~70 ~109 ~5 ~72 stone 0  
fill ~109 ~5 ~130 ~109 ~5 ~132 stone 0  
fill ~110 ~5 ~70 ~111 ~5 ~70 stained_hardened_clay 9  
fill ~110 ~5 ~71 ~112 ~5 ~71 stained_hardened_clay 9  
fill ~110 ~5 ~72 ~112 ~5 ~72 stained_hardened_clay 9  
fill ~110 ~5 ~130 ~112 ~5 ~130 stained_hardened_clay 9  
fill ~110 ~5 ~131 ~112 ~5 ~131 stained_hardened_clay 9  
fill ~110 ~5 ~132 ~111 ~5 ~132 stained_hardened_clay 9 
setblock ~113 ~5 ~69 stone_slab 13 
setblock ~113 ~5 ~71 stone_brick_stairs 5 
setblock ~113 ~5 ~72 sea_lantern 0 
setblock ~113 ~5 ~130 sea_lantern 0 
setblock ~113 ~5 ~131 stone_brick_stairs 5 
setblock ~113 ~5 ~133 stone_slab 13  
fill ~114 ~5 ~71 ~114 ~195 ~71 stained_hardened_clay 9  
fill ~114 ~5 ~72 ~116 ~5 ~72 stained_hardened_clay 9  
fill ~114 ~5 ~130 ~116 ~5 ~130 stained_hardened_clay 9  
fill ~114 ~5 ~131 ~114 ~195 ~131 stained_hardened_clay 9 
setblock ~115 ~5 ~70 stone_slab 13 
setblock ~115 ~5 ~132 stone_slab 13  
fill ~116 ~5 ~73 ~117 ~5 ~73 stone 0  
fill ~116 ~5 ~74 ~116 ~5 ~75 stone 0  
fill ~116 ~5 ~127 ~116 ~5 ~129 stone 0  
fill ~117 ~5 ~74 ~118 ~5 ~74 stained_hardened_clay 9  
fill ~117 ~5 ~75 ~118 ~5 ~75 stained_hardened_clay 9  
fill ~117 ~5 ~127 ~118 ~5 ~127 stained_hardened_clay 9  
fill ~117 ~5 ~128 ~118 ~5 ~128 stained_hardened_clay 9 
setblock ~117 ~5 ~129 stone 0  
fill ~118 ~5 ~73 ~118 ~195 ~73 stained_hardened_clay 9  
fill ~118 ~5 ~129 ~118 ~195 ~129 stained_hardened_clay 9 
setblock ~119 ~5 ~74 stone_brick_stairs 5 
setblock ~119 ~5 ~75 sea_lantern 0 
setblock ~119 ~5 ~127 sea_lantern 0 
setblock ~119 ~5 ~128 stone_brick_stairs 5  
fill ~120 ~5 ~75 ~120 ~195 ~75 stained_hardened_clay 9  
fill ~120 ~5 ~127 ~120 ~195 ~127 stained_hardened_clay 9 
setblock ~121 ~5 ~76 stone_brick_stairs 5 
setblock ~121 ~5 ~77 sea_lantern 0 
setblock ~121 ~5 ~125 sea_lantern 0 
setblock ~121 ~5 ~126 stone_brick_stairs 5  
fill ~122 ~5 ~76 ~122 ~195 ~76 stained_hardened_clay 9  
fill ~122 ~5 ~77 ~122 ~195 ~77 stained_hardened_clay 9  
fill ~122 ~5 ~125 ~122 ~195 ~125 stained_hardened_clay 9  
fill ~122 ~5 ~126 ~122 ~195 ~126 stained_hardened_clay 9 
setblock ~123 ~5 ~77 stone_brick_stairs 5 
setblock ~123 ~5 ~78 sea_lantern 0 
setblock ~123 ~5 ~124 sea_lantern 0 
setblock ~123 ~5 ~125 stone_brick_stairs 5  
fill ~124 ~5 ~78 ~124 ~195 ~78 stained_hardened_clay 9  
fill ~124 ~5 ~79 ~125 ~5 ~79 stone 0  
fill ~124 ~5 ~80 ~124 ~5 ~81 stone 0  
fill ~124 ~5 ~121 ~124 ~5 ~123 stone 0  
fill ~124 ~5 ~124 ~124 ~195 ~124 stained_hardened_clay 9  
fill ~125 ~5 ~80 ~126 ~5 ~80 stained_hardened_clay 9  
fill ~125 ~5 ~81 ~126 ~5 ~81 stained_hardened_clay 9  
fill ~125 ~5 ~121 ~126 ~5 ~121 stained_hardened_clay 9  
fill ~125 ~5 ~122 ~126 ~5 ~122 stained_hardened_clay 9 
setblock ~125 ~5 ~123 stone 0 
setblock ~128 ~5 ~80 stone_slab 13 
setblock ~128 ~5 ~122 stone_slab 13  
fill ~129 ~5 ~89 ~131 ~5 ~89 stone 0  
fill ~129 ~5 ~113 ~131 ~5 ~113 stone 0 
setblock ~130 ~5 ~82 stone_slab 13 
setblock ~130 ~5 ~120 stone_slab 13 
setblock ~131 ~5 ~85 stone_slab 13 
setblock ~131 ~5 ~92 sea_lantern 0  
fill ~131 ~5 ~95 ~133 ~5 ~95 stone 0  
fill ~131 ~5 ~101 ~133 ~5 ~101 stone 0  
fill ~131 ~5 ~107 ~133 ~5 ~107 stone 0 
setblock ~131 ~5 ~110 sea_lantern 0 
setblock ~131 ~5 ~117 stone_slab 13 
setblock ~132 ~5 ~92 stone_brick_stairs 6  
fill ~132 ~5 ~97 ~132 ~5 ~99 sea_lantern 0  
fill ~132 ~5 ~103 ~132 ~5 ~105 sea_lantern 0 
setblock ~132 ~5 ~110 stone_brick_stairs 7  
fill ~133 ~5 ~97 ~133 ~5 ~99 stone_brick_stairs 6  
fill ~133 ~5 ~103 ~133 ~5 ~105 stone_brick_stairs 7 
setblock ~65 ~6 ~97 stone_slab 13 
setblock ~65 ~6 ~105 stone_slab 13 
setblock ~66 ~6 ~89 stone_slab 13 
setblock ~66 ~6 ~91 stone_slab 13  
fill ~66 ~6 ~95 ~136 ~6 ~95 stained_hardened_clay 9  
fill ~66 ~6 ~96 ~136 ~6 ~96 stained_hardened_clay 9  
fill ~66 ~6 ~97 ~136 ~6 ~97 stained_hardened_clay 9  
fill ~66 ~6 ~98 ~136 ~6 ~98 stained_hardened_clay 9  
fill ~66 ~6 ~99 ~136 ~6 ~99 stained_hardened_clay 9  
fill ~66 ~6 ~100 ~136 ~6 ~100 stained_hardened_clay 9  
fill ~66 ~6 ~101 ~68 ~6 ~101 stone 0  
fill ~66 ~6 ~102 ~136 ~6 ~102 stained_hardened_clay 9  
fill ~66 ~6 ~103 ~136 ~6 ~103 stained_hardened_clay 9  
fill ~66 ~6 ~104 ~136 ~6 ~104 stained_hardened_clay 9  
fill ~66 ~6 ~105 ~136 ~6 ~105 stained_hardened_clay 9  
fill ~66 ~6 ~106 ~136 ~6 ~106 stained_hardened_clay 9  
fill ~66 ~6 ~107 ~136 ~6 ~107 stained_hardened_clay 9 
setblock ~66 ~6 ~111 stone_slab 13 
setblock ~66 ~6 ~113 stone_slab 13  
fill ~67 ~6 ~91 ~135 ~6 ~91 stained_hardened_clay 9  
fill ~67 ~6 ~92 ~135 ~6 ~92 stained_hardened_clay 9  
fill ~67 ~6 ~93 ~135 ~6 ~93 stained_hardened_clay 9  
fill ~67 ~6 ~94 ~68 ~6 ~94 stone 0  
fill ~67 ~6 ~108 ~68 ~6 ~108 stone 0  
fill ~67 ~6 ~109 ~135 ~6 ~109 stained_hardened_clay 9  
fill ~67 ~6 ~110 ~135 ~6 ~110 stained_hardened_clay 9  
fill ~67 ~6 ~111 ~135 ~6 ~111 stained_hardened_clay 9  
fill ~68 ~6 ~88 ~70 ~6 ~88 stone 0  
fill ~68 ~6 ~89 ~134 ~6 ~89 stained_hardened_clay 9  
fill ~68 ~6 ~90 ~134 ~6 ~90 stained_hardened_clay 9  
fill ~68 ~6 ~112 ~134 ~6 ~112 stained_hardened_clay 9  
fill ~68 ~6 ~113 ~134 ~6 ~113 stained_hardened_clay 9  
fill ~68 ~6 ~114 ~70 ~6 ~114 stone 0  
fill ~69 ~6 ~86 ~133 ~6 ~86 stained_hardened_clay 9  
fill ~69 ~6 ~87 ~133 ~6 ~87 stained_hardened_clay 9  
fill ~69 ~6 ~94 ~133 ~6 ~94 stained_hardened_clay 9  
fill ~69 ~6 ~101 ~133 ~6 ~101 stained_hardened_clay 9  
fill ~69 ~6 ~108 ~133 ~6 ~108 stained_hardened_clay 9  
fill ~69 ~6 ~115 ~133 ~6 ~115 stained_hardened_clay 9  
fill ~69 ~6 ~116 ~133 ~6 ~116 stained_hardened_clay 9  
fill ~70 ~6 ~84 ~132 ~6 ~84 stained_hardened_clay 9 
setblock ~70 ~6 ~85 stone_brick_stairs 6 
setblock ~70 ~6 ~117 stone_brick_stairs 7  
fill ~70 ~6 ~118 ~132 ~6 ~118 stained_hardened_clay 9 
setblock ~71 ~6 ~82 stone_brick_stairs 6  
fill ~71 ~6 ~83 ~131 ~6 ~83 stained_hardened_clay 9 
setblock ~71 ~6 ~85 sea_lantern 0  
fill ~71 ~6 ~88 ~131 ~6 ~88 stained_hardened_clay 9  
fill ~71 ~6 ~114 ~131 ~6 ~114 stained_hardened_clay 9 
setblock ~71 ~6 ~117 sea_lantern 0  
fill ~71 ~6 ~119 ~131 ~6 ~119 stained_hardened_clay 9 
setblock ~71 ~6 ~120 stone_brick_stairs 7  
fill ~72 ~6 ~81 ~130 ~6 ~81 stained_hardened_clay 9 
setblock ~72 ~6 ~82 sea_lantern 0  
fill ~72 ~6 ~85 ~130 ~6 ~85 stained_hardened_clay 9  
fill ~72 ~6 ~117 ~130 ~6 ~117 stained_hardened_clay 9 
setblock ~72 ~6 ~120 sea_lantern 0  
fill ~72 ~6 ~121 ~130 ~6 ~121 stained_hardened_clay 9 
setblock ~73 ~6 ~80 stone_brick_stairs 6  
fill ~73 ~6 ~82 ~129 ~6 ~82 stained_hardened_clay 9  
fill ~73 ~6 ~120 ~129 ~6 ~120 stained_hardened_clay 9 
setblock ~73 ~6 ~122 stone_brick_stairs 7  
fill ~74 ~6 ~78 ~75 ~6 ~78 stained_hardened_clay 9  
fill ~74 ~6 ~79 ~128 ~6 ~79 stained_hardened_clay 9 
setblock ~74 ~6 ~80 sea_lantern 0 
setblock ~74 ~6 ~122 sea_lantern 0  
fill ~74 ~6 ~123 ~128 ~6 ~123 stained_hardened_clay 9  
fill ~74 ~6 ~124 ~75 ~6 ~124 stained_hardened_clay 9  
fill ~75 ~6 ~77 ~76 ~6 ~77 stone 0  
fill ~75 ~6 ~80 ~127 ~6 ~80 stained_hardened_clay 9  
fill ~75 ~6 ~122 ~127 ~6 ~122 stained_hardened_clay 9  
fill ~75 ~6 ~125 ~76 ~6 ~125 stone 0  
fill ~76 ~6 ~76 ~126 ~6 ~76 stained_hardened_clay 9  
fill ~76 ~6 ~78 ~77 ~6 ~78 stone 0  
fill ~76 ~6 ~124 ~77 ~6 ~124 stone 0  
fill ~76 ~6 ~126 ~126 ~6 ~126 stained_hardened_clay 9 
setblock ~77 ~6 ~73 stone_slab 13  
fill ~77 ~6 ~75 ~125 ~6 ~75 stained_hardened_clay 9  
fill ~77 ~6 ~77 ~125 ~6 ~77 stained_hardened_clay 9  
fill ~77 ~6 ~125 ~125 ~6 ~125 stained_hardened_clay 9  
fill ~77 ~6 ~127 ~125 ~6 ~127 stained_hardened_clay 9 
setblock ~77 ~6 ~129 stone_slab 13  
fill ~78 ~6 ~74 ~124 ~6 ~74 stained_hardened_clay 9  
fill ~78 ~6 ~128 ~124 ~6 ~128 stained_hardened_clay 9  
fill ~79 ~6 ~78 ~124 ~6 ~78 stained_hardened_clay 9  
fill ~79 ~6 ~124 ~124 ~6 ~124 stained_hardened_clay 9 
setblock ~80 ~6 ~71 stone_slab 13  
fill ~80 ~6 ~73 ~122 ~6 ~73 stained_hardened_clay 9  
fill ~80 ~6 ~129 ~122 ~6 ~129 stained_hardened_clay 9 
setblock ~80 ~6 ~131 stone_slab 13  
fill ~81 ~6 ~72 ~84 ~6 ~72 stained_hardened_clay 9  
fill ~81 ~6 ~130 ~84 ~6 ~130 stained_hardened_clay 9  
fill ~82 ~6 ~71 ~83 ~6 ~71 stained_hardened_clay 9  
fill ~82 ~6 ~131 ~83 ~6 ~131 stained_hardened_clay 9  
fill ~84 ~6 ~70 ~84 ~6 ~71 stone 0  
fill ~84 ~6 ~131 ~85 ~6 ~131 stone 0  
fill ~84 ~6 ~132 ~84 ~6 ~131 stone 0  
fill ~85 ~6 ~70 ~86 ~6 ~70 stained_hardened_clay 9  
fill ~85 ~6 ~71 ~85 ~6 ~72 stone 0 
setblock ~85 ~6 ~130 stone 0  
fill ~85 ~6 ~132 ~86 ~6 ~132 stained_hardened_clay 9  
fill ~86 ~6 ~69 ~86 ~194 ~69 stained_hardened_clay 9  
fill ~86 ~6 ~71 ~116 ~6 ~71 stained_hardened_clay 9  
fill ~86 ~6 ~72 ~116 ~6 ~72 stained_hardened_clay 9  
fill ~86 ~6 ~130 ~116 ~6 ~130 stained_hardened_clay 9  
fill ~86 ~6 ~131 ~116 ~6 ~131 stained_hardened_clay 9  
fill ~86 ~6 ~133 ~86 ~194 ~133 stained_hardened_clay 9 
setblock ~87 ~6 ~69 stone_brick_stairs 4 
setblock ~87 ~6 ~70 sea_lantern 0 
setblock ~87 ~6 ~132 sea_lantern 0 
setblock ~87 ~6 ~133 stone_brick_stairs 4  
fill ~88 ~6 ~68 ~88 ~194 ~68 stained_hardened_clay 9  
fill ~88 ~6 ~69 ~88 ~194 ~69 stained_hardened_clay 9  
fill ~88 ~6 ~70 ~114 ~6 ~70 stained_hardened_clay 9  
fill ~88 ~6 ~132 ~114 ~6 ~132 stained_hardened_clay 9  
fill ~88 ~6 ~133 ~88 ~194 ~133 stained_hardened_clay 9  
fill ~88 ~6 ~134 ~88 ~194 ~134 stained_hardened_clay 9 
setblock ~89 ~6 ~68 stone_brick_stairs 4 
setblock ~89 ~6 ~69 sea_lantern 0 
setblock ~89 ~6 ~133 sea_lantern 0 
setblock ~89 ~6 ~134 stone_brick_stairs 4  
fill ~90 ~6 ~68 ~91 ~6 ~68 stained_hardened_clay 9  
fill ~90 ~6 ~69 ~91 ~6 ~69 stained_hardened_clay 9  
fill ~90 ~6 ~133 ~91 ~6 ~133 stained_hardened_clay 9  
fill ~90 ~6 ~134 ~91 ~6 ~134 stained_hardened_clay 9  
fill ~91 ~6 ~67 ~91 ~194 ~67 stained_hardened_clay 9  
fill ~91 ~6 ~135 ~91 ~194 ~135 stained_hardened_clay 9  
fill ~92 ~6 ~67 ~92 ~6 ~69 stone 0  
fill ~92 ~6 ~133 ~92 ~6 ~135 stone 0  
fill ~93 ~6 ~67 ~93 ~194 ~67 stained_hardened_clay 9  
fill ~93 ~6 ~68 ~93 ~194 ~68 stained_hardened_clay 9  
fill ~93 ~6 ~69 ~109 ~6 ~69 stained_hardened_clay 9  
fill ~93 ~6 ~133 ~109 ~6 ~133 stained_hardened_clay 9  
fill ~93 ~6 ~134 ~93 ~194 ~134 stained_hardened_clay 9  
fill ~93 ~6 ~135 ~93 ~194 ~135 stained_hardened_clay 9 
setblock ~94 ~6 ~67 stone_brick_stairs 4 
setblock ~94 ~6 ~68 sea_lantern 0 
setblock ~94 ~6 ~134 sea_lantern 0 
setblock ~94 ~6 ~135 stone_brick_stairs 4 
setblock ~95 ~6 ~65 stone_slab 13  
fill ~95 ~6 ~66 ~98 ~6 ~66 stained_hardened_clay 9  
fill ~95 ~6 ~67 ~98 ~6 ~67 stained_hardened_clay 9  
fill ~95 ~6 ~68 ~100 ~6 ~68 stained_hardened_clay 9  
fill ~95 ~6 ~134 ~100 ~6 ~134 stained_hardened_clay 9  
fill ~95 ~6 ~135 ~98 ~6 ~135 stained_hardened_clay 9  
fill ~95 ~6 ~136 ~98 ~6 ~136 stained_hardened_clay 9 
setblock ~95 ~6 ~137 stone_slab 13 
setblock ~97 ~6 ~65 stone_slab 13 
setblock ~97 ~6 ~137 stone_slab 13 
setblock ~99 ~6 ~66 stone_brick_stairs 4 
setblock ~99 ~6 ~67 sea_lantern 0 
setblock ~99 ~6 ~135 sea_lantern 0 
setblock ~99 ~6 ~136 stone_brick_stairs 4  
fill ~100 ~6 ~66 ~100 ~194 ~66 stained_hardened_clay 9  
fill ~100 ~6 ~67 ~100 ~194 ~67 stained_hardened_clay 9  
fill ~100 ~6 ~135 ~100 ~194 ~135 stained_hardened_clay 9  
fill ~100 ~6 ~136 ~100 ~194 ~136 stained_hardened_clay 9  
fill ~101 ~6 ~66 ~101 ~6 ~68 stone 0  
fill ~101 ~6 ~134 ~101 ~6 ~136 stone 0  
fill ~102 ~6 ~66 ~102 ~194 ~66 stained_hardened_clay 9  
fill ~102 ~6 ~67 ~102 ~194 ~67 stained_hardened_clay 9  
fill ~102 ~6 ~68 ~107 ~6 ~68 stained_hardened_clay 9  
fill ~102 ~6 ~134 ~107 ~6 ~134 stained_hardened_clay 9  
fill ~102 ~6 ~135 ~102 ~194 ~135 stained_hardened_clay 9  
fill ~102 ~6 ~136 ~102 ~194 ~136 stained_hardened_clay 9 
setblock ~103 ~6 ~66 stone_brick_stairs 5 
setblock ~103 ~6 ~67 sea_lantern 0 
setblock ~103 ~6 ~135 sea_lantern 0 
setblock ~103 ~6 ~136 stone_brick_stairs 5  
fill ~104 ~6 ~66 ~107 ~6 ~66 stained_hardened_clay 9  
fill ~104 ~6 ~67 ~107 ~6 ~67 stained_hardened_clay 9  
fill ~104 ~6 ~135 ~107 ~6 ~135 stained_hardened_clay 9  
fill ~104 ~6 ~136 ~107 ~6 ~136 stained_hardened_clay 9 
setblock ~105 ~6 ~65 stone_slab 13 
setblock ~105 ~6 ~137 stone_slab 13 
setblock ~107 ~6 ~65 stone_slab 13 
setblock ~107 ~6 ~137 stone_slab 13 
setblock ~108 ~6 ~67 stone_brick_stairs 5 
setblock ~108 ~6 ~68 sea_lantern 0 
setblock ~108 ~6 ~134 sea_lantern 0 
setblock ~108 ~6 ~135 stone_brick_stairs 5  
fill ~109 ~6 ~67 ~109 ~194 ~67 stained_hardened_clay 9  
fill ~109 ~6 ~68 ~109 ~194 ~68 stained_hardened_clay 9  
fill ~109 ~6 ~134 ~109 ~194 ~134 stained_hardened_clay 9  
fill ~109 ~6 ~135 ~109 ~194 ~135 stained_hardened_clay 9  
fill ~110 ~6 ~67 ~110 ~6 ~69 stone 0  
fill ~110 ~6 ~133 ~110 ~6 ~135 stone 0  
fill ~111 ~6 ~67 ~111 ~194 ~67 stained_hardened_clay 9  
fill ~111 ~6 ~68 ~112 ~6 ~68 stained_hardened_clay 9  
fill ~111 ~6 ~69 ~112 ~6 ~69 stained_hardened_clay 9  
fill ~111 ~6 ~133 ~112 ~6 ~133 stained_hardened_clay 9  
fill ~111 ~6 ~134 ~112 ~6 ~134 stained_hardened_clay 9  
fill ~111 ~6 ~135 ~111 ~194 ~135 stained_hardened_clay 9 
setblock ~113 ~6 ~68 stone_brick_stairs 5 
setblock ~113 ~6 ~69 sea_lantern 0 
setblock ~113 ~6 ~133 sea_lantern 0 
setblock ~113 ~6 ~134 stone_brick_stairs 5  
fill ~114 ~6 ~68 ~114 ~194 ~68 stained_hardened_clay 9  
fill ~114 ~6 ~69 ~114 ~194 ~69 stained_hardened_clay 9  
fill ~114 ~6 ~133 ~114 ~194 ~133 stained_hardened_clay 9  
fill ~114 ~6 ~134 ~114 ~194 ~134 stained_hardened_clay 9 
setblock ~115 ~6 ~69 stone_brick_stairs 5 
setblock ~115 ~6 ~70 sea_lantern 0 
setblock ~115 ~6 ~132 sea_lantern 0 
setblock ~115 ~6 ~133 stone_brick_stairs 5  
fill ~116 ~6 ~69 ~116 ~194 ~69 stained_hardened_clay 9  
fill ~116 ~6 ~70 ~117 ~6 ~70 stained_hardened_clay 9  
fill ~116 ~6 ~132 ~117 ~6 ~132 stained_hardened_clay 9  
fill ~116 ~6 ~133 ~116 ~194 ~133 stained_hardened_clay 9  
fill ~117 ~6 ~71 ~118 ~6 ~71 stone 0  
fill ~117 ~6 ~72 ~117 ~6 ~71 stone 0  
fill ~117 ~6 ~130 ~117 ~6 ~131 stone 0 
setblock ~118 ~6 ~70 stone 0  
fill ~118 ~6 ~72 ~121 ~6 ~72 stained_hardened_clay 9  
fill ~118 ~6 ~130 ~121 ~6 ~130 stained_hardened_clay 9  
fill ~118 ~6 ~131 ~118 ~6 ~132 stone 0  
fill ~119 ~6 ~71 ~120 ~6 ~71 stained_hardened_clay 9  
fill ~119 ~6 ~131 ~120 ~6 ~131 stained_hardened_clay 9 
setblock ~122 ~6 ~71 stone_slab 13 
setblock ~122 ~6 ~131 stone_slab 13 
setblock ~125 ~6 ~73 stone_slab 13  
fill ~125 ~6 ~78 ~126 ~6 ~78 stone 0  
fill ~125 ~6 ~124 ~126 ~6 ~124 stone 0 
setblock ~125 ~6 ~129 stone_slab 13  
fill ~126 ~6 ~77 ~127 ~6 ~77 stone 0  
fill ~126 ~6 ~125 ~127 ~6 ~125 stone 0  
fill ~127 ~6 ~78 ~128 ~6 ~78 stained_hardened_clay 9  
fill ~127 ~6 ~124 ~128 ~6 ~124 stained_hardened_clay 9 
setblock ~128 ~6 ~80 sea_lantern 0 
setblock ~128 ~6 ~122 sea_lantern 0 
setblock ~129 ~6 ~80 stone_brick_stairs 6 
setblock ~129 ~6 ~122 stone_brick_stairs 7 
setblock ~130 ~6 ~82 sea_lantern 0 
setblock ~130 ~6 ~120 sea_lantern 0 
setblock ~131 ~6 ~82 stone_brick_stairs 6 
setblock ~131 ~6 ~85 sea_lantern 0 
setblock ~131 ~6 ~117 sea_lantern 0 
setblock ~131 ~6 ~120 stone_brick_stairs 7 
setblock ~132 ~6 ~85 stone_brick_stairs 6  
fill ~132 ~6 ~88 ~134 ~6 ~88 stone 0  
fill ~132 ~6 ~114 ~134 ~6 ~114 stone 0 
setblock ~132 ~6 ~117 stone_brick_stairs 7  
fill ~134 ~6 ~94 ~135 ~6 ~94 stone 0  
fill ~134 ~6 ~101 ~136 ~6 ~101 stone 0  
fill ~134 ~6 ~108 ~135 ~6 ~108 stone 0 
setblock ~136 ~6 ~89 stone_slab 13 
setblock ~136 ~6 ~91 stone_slab 13 
setblock ~136 ~6 ~111 stone_slab 13 
setblock ~136 ~6 ~113 stone_slab 13 
setblock ~137 ~6 ~97 stone_slab 13 
setblock ~137 ~6 ~105 stone_slab 13  
fill ~63 ~7 ~99 ~139 ~7 ~99 stained_hardened_clay 9  
fill ~63 ~7 ~100 ~139 ~7 ~100 stained_hardened_clay 9  
fill ~63 ~7 ~101 ~65 ~7 ~101 stone 0  
fill ~63 ~7 ~102 ~139 ~7 ~102 stained_hardened_clay 9  
fill ~63 ~7 ~103 ~139 ~7 ~103 stained_hardened_clay 9  
fill ~64 ~7 ~92 ~138 ~7 ~92 stained_hardened_clay 9 
setblock ~64 ~7 ~93 stone 0  
fill ~64 ~7 ~94 ~64 ~193 ~94 stained_hardened_clay 9  
fill ~64 ~7 ~95 ~138 ~7 ~95 stained_hardened_clay 9  
fill ~64 ~7 ~96 ~138 ~7 ~96 stained_hardened_clay 9 
setblock ~64 ~7 ~97 stone_brick_stairs 6  
fill ~64 ~7 ~98 ~138 ~7 ~98 stained_hardened_clay 9  
fill ~64 ~7 ~104 ~138 ~7 ~104 stained_hardened_clay 9 
setblock ~64 ~7 ~105 stone_brick_stairs 7  
fill ~64 ~7 ~106 ~138 ~7 ~106 stained_hardened_clay 9  
fill ~64 ~7 ~107 ~138 ~7 ~107 stained_hardened_clay 9  
fill ~64 ~7 ~108 ~64 ~193 ~108 stained_hardened_clay 9 
setblock ~64 ~7 ~109 stone 0  
fill ~64 ~7 ~110 ~138 ~7 ~110 stained_hardened_clay 9 
setblock ~65 ~7 ~89 stone_brick_stairs 6  
fill ~65 ~7 ~90 ~137 ~7 ~90 stained_hardened_clay 9 
setblock ~65 ~7 ~91 stone_brick_stairs 6  
fill ~65 ~7 ~93 ~137 ~7 ~93 stained_hardened_clay 9  
fill ~65 ~7 ~94 ~66 ~7 ~94 stone 0 
setblock ~65 ~7 ~97 sea_lantern 0 
setblock ~65 ~7 ~105 sea_lantern 0  
fill ~65 ~7 ~108 ~66 ~7 ~108 stone 0  
fill ~65 ~7 ~109 ~137 ~7 ~109 stained_hardened_clay 9 
setblock ~65 ~7 ~111 stone_brick_stairs 7  
fill ~65 ~7 ~112 ~137 ~7 ~112 stained_hardened_clay 9 
setblock ~65 ~7 ~113 stone_brick_stairs 7  
fill ~66 ~7 ~86 ~136 ~7 ~86 stained_hardened_clay 9  
fill ~66 ~7 ~87 ~67 ~7 ~87 stone 0  
fill ~66 ~7 ~88 ~136 ~7 ~88 stained_hardened_clay 9 
setblock ~66 ~7 ~89 sea_lantern 0 
setblock ~66 ~7 ~91 sea_lantern 0  
fill ~66 ~7 ~97 ~136 ~7 ~97 stained_hardened_clay 9  
fill ~66 ~7 ~101 ~136 ~7 ~101 stained_hardened_clay 9  
fill ~66 ~7 ~105 ~136 ~7 ~105 stained_hardened_clay 9 
setblock ~66 ~7 ~111 sea_lantern 0 
setblock ~66 ~7 ~113 sea_lantern 0  
fill ~66 ~7 ~114 ~136 ~7 ~114 stained_hardened_clay 9  
fill ~66 ~7 ~115 ~67 ~7 ~115 stone 0  
fill ~66 ~7 ~116 ~136 ~7 ~116 stained_hardened_clay 9 
setblock ~67 ~7 ~82 stone_slab 13  
fill ~67 ~7 ~84 ~135 ~7 ~84 stained_hardened_clay 9  
fill ~67 ~7 ~85 ~135 ~7 ~85 stained_hardened_clay 9  
fill ~67 ~7 ~89 ~135 ~7 ~89 stained_hardened_clay 9  
fill ~67 ~7 ~91 ~135 ~7 ~91 stained_hardened_clay 9  
fill ~67 ~7 ~94 ~135 ~7 ~94 stained_hardened_clay 9  
fill ~67 ~7 ~108 ~135 ~7 ~108 stained_hardened_clay 9  
fill ~67 ~7 ~111 ~135 ~7 ~111 stained_hardened_clay 9  
fill ~67 ~7 ~113 ~135 ~7 ~113 stained_hardened_clay 9  
fill ~67 ~7 ~117 ~135 ~7 ~117 stained_hardened_clay 9  
fill ~67 ~7 ~118 ~135 ~7 ~118 stained_hardened_clay 9 
setblock ~67 ~7 ~120 stone_slab 13  
fill ~68 ~7 ~82 ~134 ~7 ~82 stained_hardened_clay 9  
fill ~68 ~7 ~83 ~134 ~7 ~83 stained_hardened_clay 9  
fill ~68 ~7 ~87 ~134 ~7 ~87 stained_hardened_clay 9  
fill ~68 ~7 ~115 ~134 ~7 ~115 stained_hardened_clay 9  
fill ~68 ~7 ~119 ~134 ~7 ~119 stained_hardened_clay 9  
fill ~68 ~7 ~120 ~134 ~7 ~120 stained_hardened_clay 9 
setblock ~69 ~7 ~79 stone_slab 13  
fill ~69 ~7 ~81 ~133 ~7 ~81 stained_hardened_clay 9  
fill ~69 ~7 ~121 ~133 ~7 ~121 stained_hardened_clay 9 
setblock ~69 ~7 ~123 stone_slab 13  
fill ~70 ~7 ~79 ~132 ~7 ~79 stained_hardened_clay 9  
fill ~70 ~7 ~80 ~132 ~7 ~80 stained_hardened_clay 9  
fill ~70 ~7 ~122 ~132 ~7 ~122 stained_hardened_clay 9  
fill ~70 ~7 ~123 ~132 ~7 ~123 stained_hardened_clay 9 
setblock ~71 ~7 ~76 stone_slab 13  
fill ~71 ~7 ~78 ~131 ~7 ~78 stained_hardened_clay 9  
fill ~71 ~7 ~124 ~131 ~7 ~124 stained_hardened_clay 9 
setblock ~71 ~7 ~126 stone_slab 13  
fill ~72 ~7 ~77 ~130 ~7 ~77 stained_hardened_clay 9  
fill ~72 ~7 ~125 ~130 ~7 ~125 stained_hardened_clay 9  
fill ~73 ~7 ~76 ~73 ~193 ~76 stained_hardened_clay 9  
fill ~73 ~7 ~126 ~73 ~193 ~126 stained_hardened_clay 9  
fill ~74 ~7 ~75 ~74 ~7 ~76 stone 0  
fill ~74 ~7 ~126 ~75 ~7 ~126 stone 0  
fill ~74 ~7 ~127 ~74 ~7 ~126 stone 0  
fill ~75 ~7 ~74 ~127 ~7 ~74 stained_hardened_clay 9  
fill ~75 ~7 ~75 ~127 ~7 ~75 stained_hardened_clay 9 
setblock ~75 ~7 ~76 stone 0  
fill ~75 ~7 ~127 ~127 ~7 ~127 stained_hardened_clay 9  
fill ~75 ~7 ~128 ~127 ~7 ~128 stained_hardened_clay 9  
fill ~76 ~7 ~73 ~76 ~193 ~73 stained_hardened_clay 9  
fill ~76 ~7 ~76 ~126 ~7 ~76 stained_hardened_clay 9  
fill ~76 ~7 ~126 ~126 ~7 ~126 stained_hardened_clay 9  
fill ~76 ~7 ~129 ~76 ~193 ~129 stained_hardened_clay 9 
setblock ~77 ~7 ~72 stone_brick_stairs 4 
setblock ~77 ~7 ~73 sea_lantern 0 
setblock ~77 ~7 ~129 sea_lantern 0 
setblock ~77 ~7 ~130 stone_brick_stairs 4  
fill ~78 ~7 ~71 ~79 ~7 ~71 stained_hardened_clay 9  
fill ~78 ~7 ~72 ~124 ~7 ~72 stained_hardened_clay 9  
fill ~78 ~7 ~73 ~124 ~7 ~73 stained_hardened_clay 9  
fill ~78 ~7 ~129 ~124 ~7 ~129 stained_hardened_clay 9  
fill ~78 ~7 ~130 ~124 ~7 ~130 stained_hardened_clay 9  
fill ~78 ~7 ~131 ~79 ~7 ~131 stained_hardened_clay 9  
fill ~79 ~7 ~70 ~79 ~193 ~70 stained_hardened_clay 9  
fill ~79 ~7 ~132 ~79 ~193 ~132 stained_hardened_clay 9 
setblock ~80 ~7 ~70 stone_brick_stairs 4 
setblock ~80 ~7 ~71 sea_lantern 0 
setblock ~80 ~7 ~131 sea_lantern 0 
setblock ~80 ~7 ~132 stone_brick_stairs 4  
fill ~81 ~7 ~69 ~82 ~7 ~69 stained_hardened_clay 9  
fill ~81 ~7 ~70 ~121 ~7 ~70 stained_hardened_clay 9  
fill ~81 ~7 ~71 ~121 ~7 ~71 stained_hardened_clay 9  
fill ~81 ~7 ~131 ~121 ~7 ~131 stained_hardened_clay 9  
fill ~81 ~7 ~132 ~121 ~7 ~132 stained_hardened_clay 9  
fill ~81 ~7 ~133 ~82 ~7 ~133 stained_hardened_clay 9  
fill ~82 ~7 ~68 ~82 ~193 ~68 stained_hardened_clay 9  
fill ~82 ~7 ~134 ~82 ~193 ~134 stained_hardened_clay 9  
fill ~83 ~7 ~68 ~83 ~7 ~69 stone 0  
fill ~83 ~7 ~133 ~84 ~7 ~133 stone 0  
fill ~83 ~7 ~134 ~83 ~7 ~133 stone 0  
fill ~84 ~7 ~67 ~118 ~7 ~67 stained_hardened_clay 9  
fill ~84 ~7 ~68 ~118 ~7 ~68 stained_hardened_clay 9 
setblock ~84 ~7 ~69 stone 0  
fill ~84 ~7 ~134 ~118 ~7 ~134 stained_hardened_clay 9  
fill ~84 ~7 ~135 ~118 ~7 ~135 stained_hardened_clay 9  
fill ~85 ~7 ~69 ~85 ~193 ~69 stained_hardened_clay 9  
fill ~85 ~7 ~133 ~85 ~193 ~133 stained_hardened_clay 9 
setblock ~86 ~7 ~65 stone_slab 13  
fill ~86 ~7 ~66 ~91 ~7 ~66 stained_hardened_clay 9  
fill ~86 ~7 ~136 ~91 ~7 ~136 stained_hardened_clay 9 
setblock ~86 ~7 ~137 stone_slab 13  
fill ~87 ~7 ~69 ~87 ~193 ~69 stained_hardened_clay 9  
fill ~87 ~7 ~133 ~87 ~193 ~133 stained_hardened_clay 9 
setblock ~89 ~7 ~64 stone_slab 13  
fill ~89 ~7 ~65 ~91 ~7 ~65 stained_hardened_clay 9  
fill ~89 ~7 ~69 ~117 ~7 ~69 stained_hardened_clay 9  
fill ~89 ~7 ~133 ~117 ~7 ~133 stained_hardened_clay 9  
fill ~89 ~7 ~137 ~91 ~7 ~137 stained_hardened_clay 9 
setblock ~89 ~7 ~138 stone_slab 13  
fill ~92 ~7 ~64 ~92 ~7 ~66 stone 0  
fill ~92 ~7 ~136 ~92 ~7 ~138 stone 0  
fill ~93 ~7 ~64 ~94 ~7 ~64 stained_hardened_clay 9  
fill ~93 ~7 ~65 ~94 ~7 ~65 stained_hardened_clay 9  
fill ~93 ~7 ~66 ~109 ~7 ~66 stained_hardened_clay 9  
fill ~93 ~7 ~136 ~109 ~7 ~136 stained_hardened_clay 9  
fill ~93 ~7 ~137 ~94 ~7 ~137 stained_hardened_clay 9  
fill ~93 ~7 ~138 ~94 ~7 ~138 stained_hardened_clay 9 
setblock ~95 ~7 ~64 stone_brick_stairs 4 
setblock ~95 ~7 ~65 sea_lantern 0 
setblock ~95 ~7 ~137 sea_lantern 0 
setblock ~95 ~7 ~138 stone_brick_stairs 4  
fill ~96 ~7 ~64 ~96 ~193 ~64 stained_hardened_clay 9  
fill ~96 ~7 ~65 ~96 ~193 ~65 stained_hardened_clay 9  
fill ~96 ~7 ~137 ~96 ~193 ~137 stained_hardened_clay 9  
fill ~96 ~7 ~138 ~96 ~193 ~138 stained_hardened_clay 9 
setblock ~97 ~7 ~64 stone_brick_stairs 4 
setblock ~97 ~7 ~65 sea_lantern 0 
setblock ~97 ~7 ~137 sea_lantern 0 
setblock ~97 ~7 ~138 stone_brick_stairs 4  
fill ~98 ~7 ~64 ~100 ~7 ~64 stained_hardened_clay 9  
fill ~98 ~7 ~65 ~100 ~7 ~65 stained_hardened_clay 9  
fill ~98 ~7 ~137 ~100 ~7 ~137 stained_hardened_clay 9  
fill ~98 ~7 ~138 ~100 ~7 ~138 stained_hardened_clay 9  
fill ~99 ~7 ~63 ~100 ~7 ~63 stained_hardened_clay 9  
fill ~99 ~7 ~139 ~100 ~7 ~139 stained_hardened_clay 9  
fill ~101 ~7 ~63 ~101 ~7 ~65 stone 0  
fill ~101 ~7 ~137 ~101 ~7 ~139 stone 0  
fill ~102 ~7 ~63 ~103 ~7 ~63 stained_hardened_clay 9  
fill ~102 ~7 ~64 ~104 ~7 ~64 stained_hardened_clay 9  
fill ~102 ~7 ~65 ~104 ~7 ~65 stained_hardened_clay 9  
fill ~102 ~7 ~137 ~104 ~7 ~137 stained_hardened_clay 9  
fill ~102 ~7 ~138 ~104 ~7 ~138 stained_hardened_clay 9  
fill ~102 ~7 ~139 ~103 ~7 ~139 stained_hardened_clay 9 
setblock ~105 ~7 ~64 stone_brick_stairs 5 
setblock ~105 ~7 ~65 sea_lantern 0 
setblock ~105 ~7 ~137 sea_lantern 0 
setblock ~105 ~7 ~138 stone_brick_stairs 5  
fill ~106 ~7 ~64 ~106 ~193 ~64 stained_hardened_clay 9  
fill ~106 ~7 ~65 ~106 ~193 ~65 stained_hardened_clay 9  
fill ~106 ~7 ~137 ~106 ~193 ~137 stained_hardened_clay 9  
fill ~106 ~7 ~138 ~106 ~193 ~138 stained_hardened_clay 9 
setblock ~107 ~7 ~64 stone_brick_stairs 5 
setblock ~107 ~7 ~65 sea_lantern 0 
setblock ~107 ~7 ~137 sea_lantern 0 
setblock ~107 ~7 ~138 stone_brick_stairs 5  
fill ~108 ~7 ~64 ~109 ~7 ~64 stained_hardened_clay 9  
fill ~108 ~7 ~65 ~109 ~7 ~65 stained_hardened_clay 9  
fill ~108 ~7 ~137 ~109 ~7 ~137 stained_hardened_clay 9  
fill ~108 ~7 ~138 ~109 ~7 ~138 stained_hardened_clay 9  
fill ~110 ~7 ~64 ~110 ~7 ~66 stone 0  
fill ~110 ~7 ~136 ~110 ~7 ~138 stone 0  
fill ~111 ~7 ~65 ~113 ~7 ~65 stained_hardened_clay 9  
fill ~111 ~7 ~66 ~116 ~7 ~66 stained_hardened_clay 9  
fill ~111 ~7 ~136 ~116 ~7 ~136 stained_hardened_clay 9  
fill ~111 ~7 ~137 ~113 ~7 ~137 stained_hardened_clay 9 
setblock ~113 ~7 ~64 stone_slab 13 
setblock ~113 ~7 ~138 stone_slab 13 
setblock ~116 ~7 ~65 stone_slab 13 
setblock ~116 ~7 ~137 stone_slab 13  
fill ~118 ~7 ~69 ~119 ~7 ~69 stone 0  
fill ~118 ~7 ~133 ~119 ~7 ~133 stone 0 
setblock ~119 ~7 ~68 stone 0 
setblock ~119 ~7 ~134 stone 0  
fill ~120 ~7 ~68 ~120 ~193 ~68 stained_hardened_clay 9  
fill ~120 ~7 ~69 ~121 ~7 ~69 stained_hardened_clay 9  
fill ~120 ~7 ~133 ~121 ~7 ~133 stained_hardened_clay 9  
fill ~120 ~7 ~134 ~120 ~193 ~134 stained_hardened_clay 9 
setblock ~122 ~7 ~70 stone_brick_stairs 5 
setblock ~122 ~7 ~71 sea_lantern 0 
setblock ~122 ~7 ~131 sea_lantern 0 
setblock ~122 ~7 ~132 stone_brick_stairs 5  
fill ~123 ~7 ~70 ~123 ~193 ~70 stained_hardened_clay 9  
fill ~123 ~7 ~71 ~124 ~7 ~71 stained_hardened_clay 9  
fill ~123 ~7 ~131 ~124 ~7 ~131 stained_hardened_clay 9  
fill ~123 ~7 ~132 ~123 ~193 ~132 stained_hardened_clay 9 
setblock ~125 ~7 ~72 stone_brick_stairs 5 
setblock ~125 ~7 ~73 sea_lantern 0 
setblock ~125 ~7 ~129 sea_lantern 0 
setblock ~125 ~7 ~130 stone_brick_stairs 5  
fill ~126 ~7 ~73 ~126 ~193 ~73 stained_hardened_clay 9  
fill ~126 ~7 ~129 ~126 ~193 ~129 stained_hardened_clay 9  
fill ~127 ~7 ~76 ~128 ~7 ~76 stone 0  
fill ~127 ~7 ~126 ~128 ~7 ~126 stone 0 
setblock ~128 ~7 ~75 stone 0 
setblock ~128 ~7 ~127 stone 0  
fill ~129 ~7 ~76 ~129 ~193 ~76 stained_hardened_clay 9  
fill ~129 ~7 ~126 ~129 ~193 ~126 stained_hardened_clay 9 
setblock ~131 ~7 ~76 stone_slab 13 
setblock ~131 ~7 ~126 stone_slab 13 
setblock ~133 ~7 ~79 stone_slab 13 
setblock ~133 ~7 ~123 stone_slab 13 
setblock ~135 ~7 ~82 stone_slab 13  
fill ~135 ~7 ~87 ~136 ~7 ~87 stone 0  
fill ~135 ~7 ~115 ~136 ~7 ~115 stone 0 
setblock ~135 ~7 ~120 stone_slab 13 
setblock ~136 ~7 ~89 sea_lantern 0 
setblock ~136 ~7 ~91 sea_lantern 0  
fill ~136 ~7 ~94 ~137 ~7 ~94 stone 0  
fill ~136 ~7 ~108 ~137 ~7 ~108 stone 0 
setblock ~136 ~7 ~111 sea_lantern 0 
setblock ~136 ~7 ~113 sea_lantern 0 
setblock ~137 ~7 ~89 stone_brick_stairs 6 
setblock ~137 ~7 ~91 stone_brick_stairs 6 
setblock ~137 ~7 ~97 sea_lantern 0  
fill ~137 ~7 ~101 ~139 ~7 ~101 stone 0 
setblock ~137 ~7 ~105 sea_lantern 0 
setblock ~137 ~7 ~111 stone_brick_stairs 7 
setblock ~137 ~7 ~113 stone_brick_stairs 7 
setblock ~138 ~7 ~93 stone 0  
fill ~138 ~7 ~94 ~138 ~193 ~94 stained_hardened_clay 9 
setblock ~138 ~7 ~97 stone_brick_stairs 6 
setblock ~138 ~7 ~105 stone_brick_stairs 7  
fill ~138 ~7 ~108 ~138 ~193 ~108 stained_hardened_clay 9 
setblock ~138 ~7 ~109 stone 0 
setblock ~60 ~8 ~95 stone_slab 13 
setblock ~60 ~8 ~98 stone_slab 13 
setblock ~60 ~8 ~104 stone_slab 13 
setblock ~60 ~8 ~107 stone_slab 13  
fill ~61 ~8 ~95 ~141 ~8 ~95 stained_hardened_clay 9  
fill ~61 ~8 ~96 ~141 ~8 ~96 stained_hardened_clay 9  
fill ~61 ~8 ~97 ~141 ~8 ~97 stained_hardened_clay 9  
fill ~61 ~8 ~98 ~141 ~8 ~98 stained_hardened_clay 9  
fill ~61 ~8 ~99 ~141 ~8 ~99 stained_hardened_clay 9  
fill ~61 ~8 ~100 ~141 ~8 ~100 stained_hardened_clay 9  
fill ~61 ~8 ~101 ~62 ~8 ~101 stone 0  
fill ~61 ~8 ~102 ~141 ~8 ~102 stained_hardened_clay 9  
fill ~61 ~8 ~103 ~141 ~8 ~103 stained_hardened_clay 9  
fill ~61 ~8 ~104 ~141 ~8 ~104 stained_hardened_clay 9  
fill ~61 ~8 ~105 ~141 ~8 ~105 stained_hardened_clay 9  
fill ~61 ~8 ~106 ~141 ~8 ~106 stained_hardened_clay 9  
fill ~61 ~8 ~107 ~141 ~8 ~107 stained_hardened_clay 9 
setblock ~62 ~8 ~89 stone_slab 13  
fill ~62 ~8 ~91 ~140 ~8 ~91 stained_hardened_clay 9  
fill ~62 ~8 ~92 ~140 ~8 ~92 stained_hardened_clay 9  
fill ~62 ~8 ~93 ~63 ~8 ~93 stone 0  
fill ~62 ~8 ~94 ~140 ~8 ~94 stained_hardened_clay 9  
fill ~62 ~8 ~108 ~140 ~8 ~108 stained_hardened_clay 9  
fill ~62 ~8 ~109 ~63 ~8 ~109 stone 0  
fill ~62 ~8 ~110 ~140 ~8 ~110 stained_hardened_clay 9  
fill ~62 ~8 ~111 ~140 ~8 ~111 stained_hardened_clay 9 
setblock ~62 ~8 ~113 stone_slab 13  
fill ~63 ~8 ~88 ~139 ~8 ~88 stained_hardened_clay 9  
fill ~63 ~8 ~89 ~139 ~8 ~89 stained_hardened_clay 9  
fill ~63 ~8 ~90 ~139 ~8 ~90 stained_hardened_clay 9  
fill ~63 ~8 ~101 ~139 ~8 ~101 stained_hardened_clay 9  
fill ~63 ~8 ~112 ~139 ~8 ~112 stained_hardened_clay 9  
fill ~63 ~8 ~113 ~139 ~8 ~113 stained_hardened_clay 9  
fill ~63 ~8 ~114 ~139 ~8 ~114 stained_hardened_clay 9  
fill ~64 ~8 ~85 ~138 ~8 ~85 stained_hardened_clay 9 
setblock ~64 ~8 ~86 stone 0  
fill ~64 ~8 ~87 ~64 ~192 ~87 stained_hardened_clay 9  
fill ~64 ~8 ~93 ~138 ~8 ~93 stained_hardened_clay 9  
fill ~64 ~8 ~109 ~138 ~8 ~109 stained_hardened_clay 9  
fill ~64 ~8 ~115 ~64 ~192 ~115 stained_hardened_clay 9 
setblock ~64 ~8 ~116 stone 0  
fill ~64 ~8 ~117 ~138 ~8 ~117 stained_hardened_clay 9  
fill ~65 ~8 ~83 ~137 ~8 ~83 stained_hardened_clay 9  
fill ~65 ~8 ~84 ~137 ~8 ~84 stained_hardened_clay 9  
fill ~65 ~8 ~86 ~137 ~8 ~86 stained_hardened_clay 9 
setblock ~65 ~8 ~87 stone 0 
setblock ~65 ~8 ~115 stone 0  
fill ~65 ~8 ~116 ~137 ~8 ~116 stained_hardened_clay 9  
fill ~65 ~8 ~118 ~137 ~8 ~118 stained_hardened_clay 9  
fill ~65 ~8 ~119 ~137 ~8 ~119 stained_hardened_clay 9  
fill ~66 ~8 ~81 ~136 ~8 ~81 stained_hardened_clay 9 
setblock ~66 ~8 ~82 stone_brick_stairs 6  
fill ~66 ~8 ~87 ~136 ~8 ~87 stained_hardened_clay 9  
fill ~66 ~8 ~115 ~136 ~8 ~115 stained_hardened_clay 9 
setblock ~66 ~8 ~120 stone_brick_stairs 7  
fill ~66 ~8 ~121 ~136 ~8 ~121 stained_hardened_clay 9  
fill ~67 ~8 ~80 ~135 ~8 ~80 stained_hardened_clay 9 
setblock ~67 ~8 ~82 sea_lantern 0 
setblock ~67 ~8 ~120 sea_lantern 0  
fill ~67 ~8 ~122 ~135 ~8 ~122 stained_hardened_clay 9  
fill ~68 ~8 ~78 ~134 ~8 ~78 stained_hardened_clay 9 
setblock ~68 ~8 ~79 stone_brick_stairs 6  
fill ~68 ~8 ~82 ~134 ~8 ~82 stained_hardened_clay 9  
fill ~68 ~8 ~120 ~134 ~8 ~120 stained_hardened_clay 9 
setblock ~68 ~8 ~123 stone_brick_stairs 7  
fill ~68 ~8 ~124 ~134 ~8 ~124 stained_hardened_clay 9  
fill ~69 ~8 ~77 ~133 ~8 ~77 stained_hardened_clay 9 
setblock ~69 ~8 ~79 sea_lantern 0 
setblock ~69 ~8 ~123 sea_lantern 0  
fill ~69 ~8 ~125 ~133 ~8 ~125 stained_hardened_clay 9 
setblock ~70 ~8 ~76 stone_brick_stairs 6  
fill ~70 ~8 ~79 ~132 ~8 ~79 stained_hardened_clay 9  
fill ~70 ~8 ~123 ~132 ~8 ~123 stained_hardened_clay 9 
setblock ~70 ~8 ~126 stone_brick_stairs 7  
fill ~71 ~8 ~74 ~72 ~8 ~74 stained_hardened_clay 9  
fill ~71 ~8 ~75 ~131 ~8 ~75 stained_hardened_clay 9 
setblock ~71 ~8 ~76 sea_lantern 0 
setblock ~71 ~8 ~126 sea_lantern 0  
fill ~71 ~8 ~127 ~131 ~8 ~127 stained_hardened_clay 9  
fill ~71 ~8 ~128 ~72 ~8 ~128 stained_hardened_clay 9  
fill ~72 ~8 ~73 ~73 ~8 ~73 stone 0  
fill ~72 ~8 ~76 ~72 ~192 ~76 stained_hardened_clay 9  
fill ~72 ~8 ~126 ~72 ~192 ~126 stained_hardened_clay 9   
fill ~72 ~8 ~129 ~73 ~8 ~129 stone 0  
fill ~73 ~8 ~72 ~129 ~8 ~72 stained_hardened_clay 9  
fill ~73 ~8 ~74 ~74 ~8 ~74 stone 0  
fill ~73 ~8 ~128 ~74 ~8 ~128 stone 0  
fill ~73 ~8 ~130 ~129 ~8 ~130 stained_hardened_clay 9  
fill ~74 ~8 ~71 ~128 ~8 ~71 stained_hardened_clay 9  
fill ~74 ~8 ~73 ~128 ~8 ~73 stained_hardened_clay 9  
fill ~74 ~8 ~76 ~130 ~8 ~76 stained_hardened_clay 9  
fill ~74 ~8 ~126 ~130 ~8 ~126 stained_hardened_clay 9  
fill ~74 ~8 ~129 ~128 ~8 ~129 stained_hardened_clay 9  
fill ~74 ~8 ~131 ~128 ~8 ~131 stained_hardened_clay 9 
setblock ~75 ~8 ~69 stone_slab 13  
fill ~75 ~8 ~74 ~127 ~8 ~74 stained_hardened_clay 9  
fill ~75 ~8 ~128 ~127 ~8 ~128 stained_hardened_clay 9 
setblock ~75 ~8 ~133 stone_slab 13  
fill ~76 ~8 ~70 ~126 ~8 ~70 stained_hardened_clay 9  
fill ~76 ~8 ~132 ~126 ~8 ~132 stained_hardened_clay 9  
fill ~77 ~8 ~69 ~125 ~8 ~69 stained_hardened_clay 9  
fill ~77 ~8 ~133 ~125 ~8 ~133 stained_hardened_clay 9 
setblock ~78 ~8 ~67 stone_slab 13  
fill ~78 ~8 ~68 ~124 ~8 ~68 stained_hardened_clay 9  
fill ~78 ~8 ~134 ~124 ~8 ~134 stained_hardened_clay 9 
setblock ~78 ~8 ~135 stone_slab 13  
fill ~80 ~8 ~67 ~81 ~8 ~67 stained_hardened_clay 9  
fill ~80 ~8 ~135 ~81 ~8 ~135 stained_hardened_clay 9  
fill ~81 ~8 ~66 ~81 ~192 ~66 stained_hardened_clay 9  
fill ~81 ~8 ~136 ~81 ~192 ~136 stained_hardened_clay 9  
fill ~82 ~8 ~66 ~82 ~8 ~67 stone 0  
fill ~82 ~8 ~135 ~83 ~8 ~135 stone 0  
fill ~82 ~8 ~136 ~82 ~8 ~135 stone 0  
fill ~83 ~8 ~65 ~85 ~8 ~65 stained_hardened_clay 9  
fill ~83 ~8 ~66 ~119 ~8 ~66 stained_hardened_clay 9 
setblock ~83 ~8 ~67 stone 0  
fill ~83 ~8 ~136 ~119 ~8 ~136 stained_hardened_clay 9  
fill ~83 ~8 ~137 ~85 ~8 ~137 stained_hardened_clay 9  
fill ~84 ~8 ~67 ~118 ~8 ~67 stained_hardened_clay 9  
fill ~84 ~8 ~135 ~118 ~8 ~135 stained_hardened_clay 9  
fill ~85 ~8 ~64 ~85 ~192 ~64 stained_hardened_clay 9  
fill ~85 ~8 ~138 ~85 ~192 ~138 stained_hardened_clay 9 
setblock ~86 ~8 ~64 stone_brick_stairs 4 
setblock ~86 ~8 ~65 sea_lantern 0 
setblock ~86 ~8 ~137 sea_lantern 0 
setblock ~86 ~8 ~138 stone_brick_stairs 4  
fill ~87 ~8 ~64 ~88 ~8 ~64 stained_hardened_clay 9  
fill ~87 ~8 ~65 ~115 ~8 ~65 stained_hardened_clay 9  
fill ~87 ~8 ~137 ~115 ~8 ~137 stained_hardened_clay 9  
fill ~87 ~8 ~138 ~88 ~8 ~138 stained_hardened_clay 9  
fill ~88 ~8 ~63 ~88 ~192 ~63 stained_hardened_clay 9  
fill ~88 ~8 ~139 ~88 ~192 ~139 stained_hardened_clay 9 
setblock ~89 ~8 ~63 stone_brick_stairs 4 
setblock ~89 ~8 ~64 sea_lantern 0 
setblock ~89 ~8 ~138 sea_lantern 0 
setblock ~89 ~8 ~139 stone_brick_stairs 4  
fill ~90 ~8 ~63 ~90 ~192 ~63 stained_hardened_clay 9  
fill ~90 ~8 ~64 ~90 ~192 ~64 stained_hardened_clay 9  
fill ~90 ~8 ~138 ~90 ~192 ~138 stained_hardened_clay 9  
fill ~90 ~8 ~139 ~90 ~192 ~139 stained_hardened_clay 9  
fill ~91 ~8 ~62 ~94 ~8 ~62 stone 0  
fill ~91 ~8 ~63 ~91 ~8 ~64 stone 0  
fill ~91 ~8 ~138 ~91 ~8 ~140 stone 0  
fill ~92 ~8 ~63 ~110 ~8 ~63 stained_hardened_clay 9  
fill ~92 ~8 ~64 ~110 ~8 ~64 stained_hardened_clay 9  
fill ~92 ~8 ~138 ~110 ~8 ~138 stained_hardened_clay 9  
fill ~92 ~8 ~139 ~110 ~8 ~139 stained_hardened_clay 9  
fill ~92 ~8 ~140 ~94 ~8 ~140 stone 0 
setblock ~95 ~8 ~60 stone_slab 13  
fill ~95 ~8 ~61 ~107 ~8 ~61 stone 0  
fill ~95 ~8 ~62 ~100 ~8 ~62 stained_hardened_clay 9  
fill ~95 ~8 ~140 ~100 ~8 ~140 stained_hardened_clay 9  
fill ~95 ~8 ~141 ~107 ~8 ~141 stone 0 
setblock ~95 ~8 ~142 stone_slab 13 
setblock ~97 ~8 ~60 stone_slab 13 
setblock ~97 ~8 ~142 stone_slab 13 
setblock ~99 ~8 ~60 stone_slab 13 
setblock ~99 ~8 ~142 stone_slab 13 
setblock ~101 ~8 ~62 stone 0 
setblock ~101 ~8 ~140 stone 0  
fill ~102 ~8 ~62 ~107 ~8 ~62 stained_hardened_clay 9  
fill ~102 ~8 ~140 ~107 ~8 ~140 stained_hardened_clay 9 
setblock ~103 ~8 ~60 stone_slab 13 
setblock ~103 ~8 ~142 stone_slab 13 
setblock ~105 ~8 ~60 stone_slab 13 
setblock ~105 ~8 ~142 stone_slab 13 
setblock ~107 ~8 ~60 stone_slab 13 
setblock ~107 ~8 ~142 stone_slab 13  
fill ~108 ~8 ~62 ~111 ~8 ~62 stone 0  
fill ~108 ~8 ~140 ~111 ~8 ~140 stone 0  
fill ~111 ~8 ~63 ~111 ~8 ~64 stone 0  
fill ~111 ~8 ~138 ~111 ~8 ~140 stone 0  
fill ~112 ~8 ~63 ~112 ~192 ~63 stained_hardened_clay 9  
fill ~112 ~8 ~64 ~112 ~192 ~64 stained_hardened_clay 9  
fill ~112 ~8 ~138 ~112 ~192 ~138 stained_hardened_clay 9  
fill ~112 ~8 ~139 ~112 ~192 ~139 stained_hardened_clay 9 
setblock ~113 ~8 ~63 stone_brick_stairs 5 
setblock ~113 ~8 ~64 sea_lantern 0 
setblock ~113 ~8 ~138 sea_lantern 0 
setblock ~113 ~8 ~139 stone_brick_stairs 5  
fill ~114 ~8 ~63 ~114 ~192 ~63 stained_hardened_clay 9  
fill ~114 ~8 ~64 ~115 ~8 ~64 stained_hardened_clay 9  
fill ~114 ~8 ~138 ~115 ~8 ~138 stained_hardened_clay 9  
