setblock ~24~34~7 minecraft:stained_glass 1
fill ~25~33~7 ~25~35~7 minecraft:stained_glass 14
fill ~26~34~7 ~27~35~7 minecraft:stained_glass 14
fill ~21~32~8 ~21~32~9 minecraft:stained_glass 1
fill ~22~32~8 ~22~32~10 minecraft:stained_glass 14
setblock ~22~33~8 minecraft:stained_glass 1
fill ~23~33~8 ~24~34~8 minecraft:stained_glass 14
fill ~25~34~8 ~26~34~8 minecraft:stained_glass 14
fill ~27~35~8 ~28~35~8 minecraft:stained_glass 14
setblock ~21~31~9 minecraft:stained_glass 1
setblock ~24~34~9 minecraft:stained_glass 14
setblock ~25~1~9 minecraft:stained_glass 4
fill ~28~35~9 ~29~35~9 minecraft:stained_glass 14
fill ~29~36~9 ~30~36~9 minecraft:stained_glass 14
setblock ~2~27~10 minecraft:planks 1
fill ~21~31~10 ~22~31~10 minecraft:stained_glass 14
setblock ~23~1~10 minecraft:stained_glass 4
fill ~24~1~10 ~24~1~11 minecraft:polished_blackstone_bricks
setblock ~25~1~10 minecraft:blackstone
fill ~25~26~10 ~25~28~10 minecraft:polished_blackstone
fill ~26~25~10 ~26~26~10 minecraft:polished_blackstone_bricks
fill ~26~27~10 ~26~27~11 minecraft:polished_blackstone
fill ~26~28~10 ~26~28~11 minecraft:polished_blackstone_bricks
setblock ~27~1~10 minecraft:stained_glass 4
fill ~27~25~10 ~27~26~11 minecraft:polished_blackstone
setblock ~30~36~10 minecraft:stained_glass 14
fill ~2~23~11 ~2~26~11 minecraft:stone 5
setblock ~3~27~11 minecraft:stone 5
fill ~3~28~11 ~3~28~12 minecraft:planks 1
fill ~20~30~11 ~20~30~13 minecraft:stained_glass 1
fill ~21~1~11 ~21~1~12 minecraft:stained_glass 4
fill ~21~30~11 ~21~31~11 minecraft:stained_glass 14
setblock ~22~1~11 minecraft:polished_blackstone
setblock ~22~29~11 minecraft:stained_glass 14
fill ~22~31~11 ~22~31~12 minecraft:polished_blackstone_bricks
setblock ~22~32~11 minecraft:polished_blackstone
fill ~23~1~11 ~23~1~12 minecraft:blackstone
fill ~23~2~11 ~23~2~12 minecraft:stained_hardened_clay 9
fill ~23~26~11 ~23~27~11 minecraft:stained_hardened_clay 9
setblock ~23~28~11 minecraft:netherite_block
setblock ~23~29~11 minecraft:stained_hardened_clay 9
fill ~23~30~11 ~26~30~11 minecraft:polished_blackstone_bricks
fill ~23~31~11 ~24~31~11 minecraft:polished_blackstone
fill ~23~32~11 ~23~33~11 minecraft:blackstone
setblock ~24~2~11 minecraft:netherite_block
fill ~24~3~11 ~26~3~11 minecraft:stained_hardened_clay 9
fill ~24~25~11 ~24~25~12 minecraft:stained_hardened_clay 9
setblock ~24~26~11 minecraft:netherite_block
fill ~24~27~11 ~24~28~11 minecraft:polished_blackstone
setblock ~24~29~11 minecraft:blackstone
setblock ~24~32~11 minecraft:polished_blackstone
fill ~25~1~11 ~27~1~11 minecraft:polished_blackstone
setblock ~25~2~11 minecraft:stained_hardened_clay 9
setblock ~25~4~11 minecraft:netherite_block
setblock ~25~5~11 minecraft:polished_blackstone
fill ~25~6~11 ~26~6~11 minecraft:stained_hardened_clay 9
setblock ~25~24~11 minecraft:polished_blackstone_bricks
fill ~25~25~11 ~25~25~12 minecraft:blackstone
fill ~25~26~11 ~25~28~11 minecraft:blackstone
setblock ~25~29~11 minecraft:polished_blackstone
setblock ~25~31~11 minecraft:polished_blackstone_bricks
fill ~26~2~11 ~26~2~12 minecraft:polished_blackstone_bricks
fill ~26~4~11 ~26~5~12 minecraft:stained_hardened_clay 9
fill ~26~7~11 ~27~7~11 minecraft:netherite_block
fill ~26~8~11 ~27~8~11 minecraft:stained_hardened_clay 9
setblock ~26~18~11 minecraft:blackstone
setblock ~26~19~11 minecraft:polished_blackstone
fill ~26~20~11 ~28~20~12 minecraft:stained_hardened_clay 9
setblock ~26~21~11 minecraft:stained_hardened_clay 9
setblock ~26~22~11 minecraft:polished_blackstone_bricks
fill ~26~23~11 ~26~24~11 minecraft:blackstone
setblock ~26~25~11 minecraft:polished_blackstone
setblock ~26~26~11 minecraft:polished_blackstone_bricks
setblock ~26~29~11 minecraft:blackstone
setblock ~26~31~11 minecraft:blackstone
fill ~27~17~11 ~27~17~13 minecraft:stained_hardened_clay 9
fill ~27~18~11 ~28~18~12 minecraft:stained_hardened_clay 9
fill ~27~19~11 ~27~19~12 minecraft:stained_hardened_clay 9
fill ~27~21~11 ~27~22~11 minecraft:netherite_block
fill ~27~23~11 ~27~23~12 minecraft:polished_blackstone_bricks
setblock ~27~24~11 minecraft:blackstone
setblock ~27~27~11 minecraft:blackstone
fill ~27~28~11 ~27~30~11 minecraft:polished_blackstone
setblock ~28~19~11 minecraft:netherite_block
fill ~28~21~11 ~28~21~12 minecraft:stained_hardened_clay 9
setblock ~28~22~11 minecraft:stained_hardened_clay 9
fill ~28~23~11 ~29~23~11 minecraft:polished_blackstone
fill ~28~24~11 ~28~27~11 minecraft:polished_blackstone_bricks
setblock ~28~28~11 minecraft:blackstone
setblock ~28~35~11 minecraft:stained_glass 1
setblock ~29~24~11 minecraft:polished_blackstone
setblock ~29~25~11 minecraft:polished_blackstone_bricks
setblock ~29~35~11 minecraft:stained_glass 14
setblock ~32~36~11 minecraft:stained_glass 14
fill ~3~19~12 ~3~20~12 minecraft:stone 5
fill ~3~21~12 ~3~27~12 minecraft:stone 6
fill ~19~41~12 ~22~42~25 minecraft:concrete 0
fill ~19~43~12 ~21~43~22 minecraft:concrete 0
setblock ~20~29~12 minecraft:stained_glass 1
fill ~20~31~12 ~20~31~13 minecraft:stained_glass 14
fill ~20~38~12 ~20~40~22 minecraft:concrete 0
fill ~20~44~12 ~21~44~22 minecraft:concrete 0
setblock ~21~28~12 minecraft:stained_glass 1
setblock ~21~29~12 minecraft:stained_glass 14
fill ~21~30~12 ~21~31~12 minecraft:stained_hardened_clay 9
fill ~21~32~12 ~21~33~12 minecraft:blackstone
fill ~21~34~12 ~21~34~14 minecraft:polished_blackstone_bricks
fill ~21~35~12 ~21~35~15 minecraft:blackstone
fill ~21~36~12 ~21~37~12 minecraft:blackstone
setblock ~21~38~12 minecraft:polished_blackstone
fill ~21~39~12 ~22~40~25 minecraft:concrete 0
setblock ~22~1~12 minecraft:polished_blackstone_bricks
fill ~22~2~12 ~22~2~13 minecraft:stained_glass 1
fill ~22~25~12 ~22~25~15 minecraft:stained_hardened_clay 9
setblock ~22~26~12 minecraft:stained_hardened_clay 9
fill ~22~27~12 ~22~28~12 minecraft:netherite_block
fill ~22~29~12 ~22~29~14 minecraft:stained_hardened_clay 9
fill ~22~30~12 ~23~30~12 minecraft:polished_blackstone
fill ~22~32~12 ~22~32~13 minecraft:polished_blackstone_bricks
fill ~22~33~12 ~22~34~12 minecraft:polished_blackstone
setblock ~22~35~12 minecraft:polished_blackstone_bricks
fill ~22~36~12 ~23~36~12 minecraft:polished_blackstone
setblock ~22~37~12 minecraft:polished_blackstone_bricks
fill ~22~38~12 ~23~38~12 minecraft:blackstone
setblock ~23~24~12 minecraft:stained_hardened_clay 9
fill ~23~25~12 ~23~25~13 minecraft:netherite_block
setblock ~23~26~12 minecraft:polished_blackstone
fill ~23~27~12 ~24~27~12 minecraft:stained_hardened_clay 9
fill ~23~28~12 ~23~28~13 minecraft:stained_hardened_clay 9
fill ~23~29~12 ~23~29~14 minecraft:polished_blackstone
fill ~23~31~12 ~23~32~12 minecraft:polished_blackstone
fill ~23~33~12 ~25~33~12 minecraft:blackstone
fill ~23~34~12 ~23~34~14 minecraft:polished_blackstone_bricks
setblock ~23~35~12 minecraft:polished_blackstone
setblock ~23~37~12 minecraft:blackstone
setblock ~24~1~12 minecraft:polished_blackstone
fill ~24~2~12 ~24~3~13 minecraft:stained_hardened_clay 9
fill ~24~4~12 ~25~5~12 minecraft:stained_hardened_clay 9
setblock ~24~6~12 minecraft:netherite_block
setblock ~24~24~12 minecraft:polished_blackstone
setblock ~24~26~12 minecraft:stained_hardened_clay 9
setblock ~24~28~12 minecraft:netherite_block
fill ~24~29~12 ~24~29~14 minecraft:stained_hardened_clay 9
fill ~24~30~12 ~24~30~13 minecraft:blackstone
fill ~24~31~12 ~24~31~13 minecraft:polished_blackstone_bricks
setblock ~24~32~12 minecraft:polished_blackstone_bricks
fill ~24~34~12 ~24~35~12 minecraft:blackstone
setblock ~25~1~12 minecraft:blackstone
fill ~25~2~12 ~25~2~13 minecraft:netherite_block
fill ~25~3~12 ~26~3~12 minecraft:netherite_block
fill ~25~6~12 ~25~6~13 minecraft:stained_hardened_clay 9
fill ~25~7~12 ~26~7~12 minecraft:netherite_block
fill ~25~8~12 ~25~8~14 minecraft:stained_hardened_clay 9
setblock ~25~9~12 minecraft:polished_blackstone
setblock ~25~18~12 minecraft:polished_blackstone
fill ~25~19~12 ~25~23~12 minecraft:blackstone
setblock ~25~24~12 minecraft:concrete 0
fill ~25~26~12 ~25~27~12 minecraft:polished_blackstone_bricks
fill ~25~28~12 ~27~28~12 minecraft:blackstone
fill ~25~29~12 ~25~30~12 minecraft:polished_blackstone_bricks
fill ~25~31~12 ~25~32~12 minecraft:blackstone
fill ~26~1~12 ~26~1~14 minecraft:polished_blackstone_bricks
fill ~26~6~12 ~27~6~12 minecraft:netherite_block
fill ~26~8~12 ~26~8~14 minecraft:polished_blackstone
fill ~26~9~12 ~27~9~12 minecraft:stained_hardened_clay 9
fill ~26~10~12 ~27~10~12 minecraft:netherite_block
fill ~26~11~12 ~27~11~13 minecraft:stained_hardened_clay 9
fill ~26~16~12 ~26~17~12 minecraft:polished_blackstone
fill ~26~18~12 ~26~18~13 minecraft:polished_blackstone_bricks
setblock ~26~19~12 minecraft:stained_hardened_clay 9
fill ~26~21~12 ~26~22~12 minecraft:polished_blackstone
setblock ~26~23~12 minecraft:polished_blackstone_bricks
fill ~26~24~12 ~28~24~12 minecraft:polished_blackstone
fill ~26~25~12 ~27~25~12 minecraft:polished_blackstone_bricks
fill ~26~26~12 ~26~27~12 minecraft:blackstone
setblock ~26~29~12 minecraft:polished_blackstone
fill ~26~30~12 ~27~30~12 minecraft:blackstone
setblock ~26~31~12 minecraft:polished_blackstone
fill ~26~32~12 ~27~32~13 minecraft:blackstone
fill ~27~1~12 ~27~1~13 minecraft:blackstone
fill ~27~2~12 ~27~4~12 minecraft:blackstone
setblock ~27~5~12 minecraft:polished_blackstone
fill ~27~7~12 ~27~7~13 minecraft:stained_hardened_clay 9
setblock ~27~8~12 minecraft:stained_hardened_clay 9
setblock ~27~12~12 minecraft:stained_hardened_clay 9
fill ~27~13~12 ~27~13~13 minecraft:polished_blackstone
fill ~27~14~12 ~27~15~12 minecraft:polished_blackstone
setblock ~27~16~12 minecraft:netherite_block
fill ~27~21~12 ~27~21~13 minecraft:stained_hardened_clay 9
fill ~27~22~12 ~28~22~12 minecraft:netherite_block
setblock ~27~26~12 minecraft:polished_blackstone
fill ~27~27~12 ~27~27~13 minecraft:polished_blackstone_bricks
fill ~27~29~12 ~27~29~13 minecraft:polished_blackstone_bricks
fill ~27~31~12 ~28~31~12 minecraft:polished_blackstone_bricks
setblock ~28~1~12 minecraft:stained_glass 4
fill ~28~7~12 ~28~7~13 minecraft:blackstone
setblock ~28~8~12 minecraft:polished_blackstone_bricks
setblock ~28~9~12 minecraft:netherite_block
setblock ~28~10~12 minecraft:polished_blackstone
setblock ~28~11~12 minecraft:netherite_block
fill ~28~12~12 ~29~12~12 minecraft:blackstone
setblock ~28~13~12 minecraft:polished_blackstone_bricks
fill ~28~14~12 ~29~14~12 minecraft:netherite_block
fill ~28~15~12 ~28~16~14 minecraft:stained_hardened_clay 9
fill ~28~17~12 ~28~17~13 minecraft:netherite_block
fill ~28~19~12 ~29~19~13 minecraft:stained_hardened_clay 9
setblock ~28~23~12 minecraft:polished_blackstone
fill ~28~25~12 ~29~26~12 minecraft:blackstone
setblock ~28~27~12 minecraft:blackstone
setblock ~28~28~12 minecraft:polished_blackstone
setblock ~28~29~12 minecraft:blackstone
setblock ~28~30~12 minecraft:polished_blackstone
setblock ~29~13~12 minecraft:blackstone
setblock ~29~15~12 minecraft:netherite_block
fill ~29~16~12 ~29~16~13 minecraft:polished_blackstone
fill ~29~17~12 ~29~17~15 minecraft:stained_hardened_clay 9
fill ~29~18~12 ~29~18~13 minecraft:stained_hardened_clay 9
fill ~29~20~12 ~29~21~14 minecraft:stained_hardened_clay 9
fill ~29~22~12 ~29~22~13 minecraft:stained_hardened_clay 9
setblock ~29~23~12 minecraft:stained_hardened_clay 9
fill ~29~24~12 ~29~24~13 minecraft:polished_blackstone_bricks
fill ~29~27~12 ~29~27~13 minecraft:polished_blackstone
setblock ~29~28~12 minecraft:blackstone
setblock ~29~35~12 minecraft:stained_glass 1
fill ~4~15~13 ~4~17~13 minecraft:stone 5
fill ~4~18~13 ~4~20~13 minecraft:stone 6
fill ~4~21~13 ~4~28~13 minecraft:stone 5
setblock ~4~29~13 minecraft:planks 1
fill ~14~16~13 ~16~16~13 minecraft:blackstone
fill ~14~17~13 ~14~17~15 minecraft:blackstone
setblock ~14~18~13 minecraft:polished_blackstone
fill ~15~15~13 ~15~15~16 minecraft:polished_blackstone
fill ~15~17~13 ~15~17~14 minecraft:polished_blackstone_bricks
setblock ~15~18~13 minecraft:blackstone
fill ~17~43~13 ~18~44~17 minecraft:concrete 0
fill ~18~40~13 ~19~40~28 minecraft:concrete 0
fill ~18~41~13 ~18~42~28 minecraft:concrete 0
setblock ~19~27~13 minecraft:stained_glass 4
fill ~19~38~13 ~19~39~25 minecraft:concrete 0
fill ~19~44~13 ~19~44~23 minecraft:concrete 0
setblock ~20~26~13 minecraft:stained_glass 1
setblock ~20~27~13 minecraft:stained_glass 14
fill ~20~28~13 ~20~28~14 minecraft:stained_glass 1
setblock ~20~29~13 minecraft:stained_glass 14
fill ~20~32~13 ~21~32~14 minecraft:stained_hardened_clay 9
setblock ~20~33~13 minecraft:polished_blackstone
fill ~20~34~13 ~20~34~14 minecraft:polished_blackstone_bricks
setblock ~20~35~13 minecraft:blackstone
fill ~20~36~13 ~21~36~13 minecraft:polished_blackstone
setblock ~20~37~13 minecraft:blackstone
fill ~20~45~13 ~22~45~23 minecraft:concrete 0
setblock ~21~25~13 minecraft:netherite_block
setblock ~21~26~13 minecraft:polished_blackstone
fill ~21~27~13 ~22~27~13 minecraft:stained_hardened_clay 9
fill ~21~28~13 ~21~29~14 minecraft:stained_hardened_clay 9
fill ~21~30~13 ~21~30~14 minecraft:polished_blackstone
fill ~21~31~13 ~22~31~13 minecraft:netherite_block
setblock ~21~33~13 minecraft:blackstone
setblock ~21~37~13 minecraft:polished_blackstone
fill ~21~38~13 ~23~38~22 minecraft:concrete 0
setblock ~22~1~13 minecraft:stained_glass 4
fill ~22~24~13 ~22~24~14 minecraft:stained_hardened_clay 9
setblock ~22~26~13 minecraft:netherite_block
setblock ~22~28~13 minecraft:polished_blackstone
fill ~22~30~13 ~23~30~13 minecraft:stained_hardened_clay 9
fill ~22~33~13 ~22~33~15 minecraft:polished_blackstone_bricks
setblock ~22~34~13 minecraft:blackstone
fill ~22~35~13 ~22~35~14 minecraft:polished_blackstone
fill ~22~36~13 ~25~36~13 minecraft:blackstone
setblock ~22~37~13 minecraft:blackstone
fill ~22~43~13 ~23~43~24 minecraft:concrete 0
fill ~22~44~13 ~23~44~23 minecraft:concrete 0
fill ~23~1~13 ~25~1~13 minecraft:polished_blackstone_bricks
setblock ~23~2~13 minecraft:netherite_block
fill ~23~3~13 ~23~3~14 minecraft:stained_hardened_clay 9
fill ~23~4~13 ~24~4~13 minecraft:netherite_block
setblock ~23~24~13 minecraft:netherite_block
setblock ~23~26~13 minecraft:stained_hardened_clay 9
setblock ~23~27~13 minecraft:netherite_block
fill ~23~31~13 ~23~32~13 minecraft:polished_blackstone_bricks
fill ~23~33~13 ~25~33~13 minecraft:polished_blackstone
fill ~23~35~13 ~25~35~13 minecraft:polished_blackstone_bricks
setblock ~23~37~13 minecraft:polished_blackstone_bricks
fill ~23~39~13 ~24~39~25 minecraft:concrete 0
fill ~23~40~13 ~23~41~25 minecraft:concrete 0
fill ~23~42~13 ~23~42~24 minecraft:concrete 0
setblock ~24~5~13 minecraft:netherite_block
setblock ~24~6~13 minecraft:polished_blackstone
fill ~24~7~13 ~24~7~14 minecraft:stained_hardened_clay 9
fill ~24~8~13 ~24~8~14 minecraft:netherite_block
setblock ~24~23~13 minecraft:polished_blackstone_bricks
setblock ~24~24~13 minecraft:stained_hardened_clay 9
fill ~24~25~13 ~24~26~13 minecraft:netherite_block
fill ~24~27~13 ~24~27~14 minecraft:stained_hardened_clay 9
setblock ~24~28~13 minecraft:stained_hardened_clay 9
setblock ~24~32~13 minecraft:blackstone
setblock ~24~34~13 minecraft:polished_blackstone_bricks
setblock ~24~37~13 minecraft:blackstone
setblock ~24~38~13 minecraft:polished_blackstone
fill ~25~3~13 ~26~3~13 minecraft:stained_hardened_clay 9
fill ~25~4~13 ~25~5~13 minecraft:polished_blackstone
setblock ~25~7~13 minecraft:polished_blackstone
fill ~25~9~13 ~25~10~13 minecraft:stained_hardened_clay 9
fill ~25~17~13 ~26~17~13 minecraft:blackstone
setblock ~25~18~13 minecraft:blackstone
setblock ~25~19~13 minecraft:polished_blackstone
fill ~25~20~13 ~25~20~14 minecraft:polished_blackstone_bricks
setblock ~25~21~13 minecraft:polished_blackstone
setblock ~25~22~13 minecraft:blackstone
fill ~25~23~13 ~27~23~13 minecraft:polished_blackstone
fill ~25~24~13 ~25~24~15 minecraft:blackstone
fill ~25~25~13 ~27~26~14 minecraft:concrete 0
fill ~25~27~13 ~26~28~26 minecraft:concrete 0
setblock ~25~29~13 minecraft:polished_blackstone
setblock ~25~30~13 minecraft:blackstone
fill ~25~31~13 ~27~31~13 minecraft:polished_blackstone_bricks
setblock ~25~32~13 minecraft:polished_blackstone_bricks
setblock ~25~34~13 minecraft:blackstone
setblock ~26~2~13 minecraft:polished_blackstone
setblock ~26~4~13 minecraft:netherite_block
setblock ~26~5~13 minecraft:polished_blackstone
setblock ~26~6~13 minecraft:netherite_block
setblock ~26~7~13 minecraft:stained_hardened_clay 9
setblock ~26~9~13 minecraft:polished_blackstone
fill ~26~10~13 ~26~10~14 minecraft:stained_hardened_clay 9
setblock ~26~12~13 minecraft:stained_hardened_clay 9
fill ~26~13~13 ~26~15~13 minecraft:polished_blackstone
setblock ~26~16~13 minecraft:blackstone
fill ~26~19~13 ~26~19~15 minecraft:polished_blackstone_bricks
fill ~26~20~13 ~26~21~13 minecraft:blackstone
setblock ~26~22~13 minecraft:polished_blackstone_bricks
setblock ~26~24~13 minecraft:polished_blackstone_bricks
setblock ~26~29~13 minecraft:blackstone
setblock ~26~30~13 minecraft:polished_blackstone_bricks
fill ~26~33~13 ~26~33~14 minecraft:blackstone
setblock ~26~34~13 minecraft:polished_blackstone_bricks
fill ~26~35~13 ~26~35~14 minecraft:blackstone
fill ~27~2~13 ~28~2~13 minecraft:polished_blackstone_bricks
setblock ~27~3~13 minecraft:polished_blackstone_bricks
fill ~27~4~13 ~27~4~15 minecraft:polished_blackstone
setblock ~27~5~13 minecraft:polished_blackstone_bricks
setblock ~27~6~13 minecraft:stained_hardened_clay 9
setblock ~27~8~13 minecraft:polished_blackstone
fill ~27~9~13 ~28~9~13 minecraft:stained_hardened_clay 9
fill ~27~10~13 ~27~10~14 minecraft:polished_blackstone
fill ~27~12~13 ~28~12~13 minecraft:polished_blackstone
fill ~27~14~13 ~27~14~14 minecraft:polished_blackstone_bricks
fill ~27~15~13 ~27~16~13 minecraft:stained_hardened_clay 9
setblock ~27~18~13 minecraft:polished_blackstone_bricks
setblock ~27~19~13 minecraft:netherite_block
fill ~27~20~13 ~28~20~13 minecraft:stained_hardened_clay 9
fill ~27~22~13 ~28~22~13 minecraft:stained_hardened_clay 9
fill ~27~24~13 ~27~24~28 minecraft:concrete 0
setblock ~27~28~13 minecraft:polished_blackstone
fill ~27~30~13 ~28~30~13 minecraft:blackstone
setblock ~27~33~13 minecraft:polished_blackstone_bricks
setblock ~28~1~13 minecraft:blackstone
fill ~28~3~13 ~28~3~14 minecraft:polished_blackstone
setblock ~28~4~13 minecraft:polished_blackstone_bricks
setblock ~28~5~13 minecraft:polished_blackstone
fill ~28~6~13 ~28~6~14 minecraft:polished_blackstone_bricks
fill ~28~8~13 ~28~8~14 minecraft:blackstone
setblock ~28~10~13 minecraft:netherite_block
setblock ~28~11~13 minecraft:polished_blackstone
fill ~28~13~13 ~30~13~14 minecraft:polished_blackstone
fill ~28~14~13 ~29~14~13 minecraft:stained_hardened_clay 9
setblock ~28~18~13 minecraft:stained_hardened_clay 9
setblock ~28~21~13 minecraft:polished_blackstone
setblock ~28~23~13 minecraft:stained_hardened_clay 9
setblock ~28~24~13 minecraft:polished_blackstone_bricks
fill ~28~25~13 ~28~26~13 minecraft:blackstone
fill ~28~27~13 ~28~27~16 minecraft:polished_blackstone_bricks
fill ~28~28~13 ~29~28~13 minecraft:polished_blackstone_bricks
setblock ~28~29~13 minecraft:polished_blackstone_bricks
setblock ~28~31~13 minecraft:blackstone
setblock ~28~32~13 minecraft:polished_blackstone
setblock ~29~10~13 minecraft:polished_blackstone_bricks
setblock ~29~11~13 minecraft:blackstone
fill ~29~12~13 ~29~12~14 minecraft:polished_blackstone_bricks
fill ~29~15~13 ~30~15~13 minecraft:stained_hardened_clay 9
fill ~29~23~13 ~30~23~13 minecraft:polished_blackstone
setblock ~29~25~13 minecraft:polished_blackstone_bricks
fill ~29~26~13 ~29~26~15 minecraft:blackstone
setblock ~29~29~13 minecraft:blackstone
fill ~29~30~13 ~29~30~14 minecraft:polished_blackstone
fill ~29~35~13 ~29~36~13 minecraft:stained_glass 14
fill ~30~12~13 ~30~12~14 minecraft:blackstone
setblock ~30~14~13 minecraft:netherite_block
setblock ~30~16~13 minecraft:stained_hardened_clay 9
fill ~30~17~13 ~30~17~14 minecraft:netherite_block
fill ~30~18~13 ~30~19~13 minecraft:stained_hardened_clay 9
setblock ~30~20~13 minecraft:polished_blackstone
fill ~30~21~13 ~30~22~14 minecraft:stained_hardened_clay 9
setblock ~30~24~13 minecraft:blackstone
fill ~30~36~13 ~30~36~14 minecraft:stained_glass 14
fill ~5~13~14 ~5~14~14 minecraft:stone 5
fill ~5~15~14 ~5~17~14 minecraft:stone 6
fill ~5~18~14 ~5~28~14 minecraft:stone 5
setblock ~5~29~14 minecraft:planks 1
fill ~13~16~14 ~14~16~14 minecraft:blackstone
setblock ~13~17~14 minecraft:polished_blackstone
fill ~13~18~14 ~13~18~15 minecraft:polished_blackstone_bricks
setblock ~13~19~14 minecraft:netherite_block
fill ~14~15~14 ~14~15~16 minecraft:polished_blackstone_bricks
fill ~14~18~14 ~14~18~15 minecraft:blackstone
fill ~14~19~14 ~15~20~15 minecraft:stained_hardened_clay 9
fill ~15~14~14 ~15~14~16 minecraft:polished_blackstone
fill ~15~16~14 ~17~16~14 minecraft:polished_blackstone
setblock ~15~18~14 minecraft:polished_blackstone_bricks
setblock ~15~21~14 minecraft:stained_hardened_clay 9
setblock ~16~15~14 minecraft:polished_blackstone
fill ~16~17~14 ~16~17~15 minecraft:polished_blackstone_bricks
fill ~16~18~14 ~16~19~14 minecraft:blackstone
setblock ~16~20~14 minecraft:stained_hardened_clay 9
fill ~16~44~14 ~16~44~18 minecraft:concrete 0
fill ~17~39~14 ~18~39~27 minecraft:concrete 0
fill ~17~40~14 ~17~41~27 minecraft:concrete 0
fill ~17~42~14 ~17~42~18 minecraft:concrete 0
setblock ~17~45~14 minecraft:polished_blackstone
fill ~17~46~14 ~17~47~14 minecraft:polished_blackstone_bricks
fill ~17~48~14 ~17~48~15 minecraft:blackstone
fill ~17~49~14 ~17~51~14 minecraft:blackstone
fill ~18~38~14 ~18~38~27 minecraft:concrete 0
setblock ~18~45~14 minecraft:polished_blackstone_bricks
fill ~18~46~14 ~19~46~14 minecraft:blackstone
fill ~18~47~14 ~18~47~15 minecraft:polished_blackstone
setblock ~19~28~14 minecraft:stained_glass 1
fill ~19~30~14 ~19~30~15 minecraft:stained_glass 1
fill ~19~36~14 ~19~36~16 minecraft:polished_blackstone_bricks
setblock ~19~37~14 minecraft:polished_blackstone_bricks
fill ~19~45~14 ~19~45~24 minecraft:concrete 0
fill ~20~26~14 ~20~27~14 minecraft:stained_glass 4
setblock ~20~29~14 minecraft:stained_glass 1
setblock ~20~30~14 minecraft:netherite_block
fill ~20~31~14 ~22~31~15 minecraft:stained_hardened_clay 9
fill ~20~33~14 ~21~33~14 minecraft:polished_blackstone_bricks
fill ~20~35~14 ~20~36~14 minecraft:polished_blackstone
fill ~20~37~14 ~23~37~20 minecraft:concrete 0
fill ~20~46~14 ~21~46~22 minecraft:concrete 0
setblock ~21~25~14 minecraft:stained_glass 1
setblock ~21~26~14 minecraft:stained_hardened_clay 9
fill ~21~27~14 ~21~27~16 minecraft:shroomlight
fill ~21~36~14 ~22~36~14 minecraft:blackstone
fill ~22~1~14 ~23~1~14 minecraft:stained_glass 1
setblock ~22~26~14 minecraft:polished_blackstone
setblock ~22~27~14 minecraft:netherite_block
fill ~22~28~14 ~22~28~17 minecraft:stained_hardened_clay 9
fill ~22~30~14 ~22~30~15 minecraft:stained_hardened_clay 9
setblock ~22~32~14 minecraft:blackstone
setblock ~22~34~14 minecraft:polished_blackstone
setblock ~23~2~14 minecraft:stained_glass 1
setblock ~23~4~14 minecraft:polished_blackstone
fill ~23~24~14 ~23~24~17 minecraft:stained_hardened_clay 9
fill ~23~25~14 ~23~25~15 minecraft:stained_hardened_clay 9
setblock ~23~26~14 minecraft:netherite_block
fill ~23~27~14 ~23~28~14 minecraft:polished_blackstone
setblock ~23~30~14 minecraft:netherite_block
fill ~23~31~14 ~24~31~23 minecraft:concrete 0
fill ~23~32~14 ~23~32~22 minecraft:concrete 0
fill ~23~33~14 ~23~33~21 minecraft:concrete 0
fill ~23~35~14 ~23~36~14 minecraft:polished_blackstone_bricks
fill ~23~45~14 ~23~45~22 minecraft:concrete 0
fill ~24~1~14 ~24~2~14 minecraft:blackstone
fill ~24~3~14 ~25~3~14 minecraft:stained_hardened_clay 9
fill ~24~4~14 ~24~6~14 minecraft:stained_hardened_clay 9
fill ~24~23~14 ~25~23~14 minecraft:blackstone
setblock ~24~24~14 minecraft:polished_blackstone_bricks
setblock ~24~25~14 minecraft:blackstone
setblock ~24~26~14 minecraft:concrete 0
setblock ~24~28~14 minecraft:netherite_block
fill ~24~30~14 ~26~30~25 minecraft:concrete 0
fill ~24~32~14 ~24~33~14 minecraft:polished_blackstone
fill ~24~34~14 ~24~36~14 minecraft:blackstone
setblock ~24~37~14 minecraft:polished_blackstone
fill ~24~38~14 ~24~38~25 minecraft:concrete 0
fill ~24~40~14 ~25~40~24 minecraft:concrete 0
fill ~24~41~14 ~24~42~24 minecraft:concrete 0
fill ~24~43~14 ~24~43~23 minecraft:concrete 0
fill ~24~44~14 ~24~44~22 minecraft:concrete 0
fill ~25~1~14 ~25~1~15 minecraft:polished_blackstone_bricks
setblock ~25~2~14 minecraft:polished_blackstone
setblock ~25~4~14 minecraft:netherite_block
setblock ~25~5~14 minecraft:polished_blackstone
setblock ~25~6~14 minecraft:netherite_block
setblock ~25~7~14 minecraft:stained_hardened_clay 9
setblock ~25~9~14 minecraft:polished_blackstone
fill ~25~18~14 ~27~18~14 minecraft:polished_blackstone
setblock ~25~19~14 minecraft:blackstone
fill ~25~21~14 ~27~21~14 minecraft:polished_blackstone_bricks
setblock ~25~22~14 minecraft:polished_blackstone_bricks
fill ~25~29~14 ~26~29~26 minecraft:concrete 0
setblock ~25~31~14 minecraft:polished_blackstone_bricks
fill ~25~32~14 ~26~32~14 minecraft:blackstone
setblock ~25~33~14 minecraft:blackstone
fill ~25~34~14 ~25~34~15 minecraft:polished_blackstone_bricks
fill ~25~35~14 ~25~36~14 minecraft:polished_blackstone_bricks
fill ~25~37~14 ~26~37~14 minecraft:blackstone
setblock ~25~38~14 minecraft:polished_blackstone_bricks
fill ~25~39~14 ~25~39~25 minecraft:concrete 0
fill ~26~2~14 ~26~5~14 minecraft:polished_blackstone_bricks
setblock ~26~6~14 minecraft:stained_hardened_clay 9
setblock ~26~7~14 minecraft:netherite_block
setblock ~26~9~14 minecraft:netherite_block
fill ~26~11~14 ~27~11~14 minecraft:netherite_block
setblock ~26~12~14 minecraft:polished_blackstone
fill ~26~13~14 ~26~13~15 minecraft:polished_blackstone_bricks
fill ~26~14~14 ~26~14~15 minecraft:blackstone
fill ~26~15~14 ~26~17~14 minecraft:polished_blackstone
fill ~26~20~14 ~28~20~14 minecraft:polished_blackstone
fill ~26~22~14 ~29~22~14 minecraft:polished_blackstone
fill ~26~23~14 ~28~23~14 minecraft:polished_blackstone_bricks
setblock ~26~24~14 minecraft:polished_blackstone
setblock ~26~31~14 minecraft:blackstone
fill ~26~34~14 ~26~34~15 minecraft:blackstone
setblock ~26~36~14 minecraft:polished_blackstone_bricks
setblock ~26~38~14 minecraft:polished_blackstone
setblock ~27~1~14 minecraft:polished_blackstone_bricks
fill ~27~2~14 ~27~3~14 minecraft:blackstone
fill ~27~5~14 ~27~6~14 minecraft:polished_blackstone
fill ~27~7~14 ~27~7~15 minecraft:polished_blackstone_bricks
setblock ~27~8~14 minecraft:polished_blackstone_bricks
fill ~27~9~14 ~27~9~15 minecraft:polished_blackstone
setblock ~27~12~14 minecraft:polished_blackstone_bricks
setblock ~27~13~14 minecraft:blackstone
fill ~27~15~14 ~27~15~16 minecraft:blackstone
setblock ~27~16~14 minecraft:polished_blackstone_bricks
setblock ~27~17~14 minecraft:blackstone
setblock ~27~19~14 minecraft:blackstone
setblock ~27~27~14 minecraft:polished_blackstone
setblock ~27~28~14 minecraft:blackstone
fill ~27~29~14 ~28~29~14 minecraft:polished_blackstone
setblock ~27~30~14 minecraft:blackstone
fill ~27~31~14 ~28~32~14 minecraft:polished_blackstone_bricks
setblock ~27~33~14 minecraft:polished_blackstone
fill ~27~34~14 ~27~34~15 minecraft:polished_blackstone_bricks
setblock ~27~35~14 minecraft:blackstone
setblock ~28~1~14 minecraft:stained_glass 1
setblock ~28~2~14 minecraft:polished_blackstone
fill ~28~4~14 ~28~5~14 minecraft:blackstone
setblock ~28~7~14 minecraft:polished_blackstone
fill ~28~9~14 ~28~11~14 minecraft:blackstone
setblock ~28~12~14 minecraft:polished_blackstone
fill ~28~14~14 ~30~14~14 minecraft:blackstone
setblock ~28~17~14 minecraft:polished_blackstone
setblock ~28~18~14 minecraft:netherite_block
fill ~28~19~14 ~29~19~15 minecraft:polished_blackstone
setblock ~28~21~14 minecraft:stained_hardened_clay 9
fill ~28~24~14 ~29~24~14 minecraft:blackstone
fill ~28~25~14 ~28~26~15 minecraft:polished_blackstone
setblock ~28~28~14 minecraft:polished_blackstone_bricks
setblock ~28~30~14 minecraft:polished_blackstone
setblock ~28~33~14 minecraft:polished_blackstone_bricks
setblock ~29~10~14 minecraft:blackstone
setblock ~29~11~14 minecraft:polished_blackstone
setblock ~29~15~14 minecraft:stained_hardened_clay 9
setblock ~29~16~14 minecraft:netherite_block
fill ~29~18~14 ~30~18~14 minecraft:polished_blackstone
setblock ~29~23~14 minecraft:polished_blackstone
setblock ~29~25~14 minecraft:blackstone
fill ~29~27~14 ~30~27~14 minecraft:blackstone
setblock ~29~28~14 minecraft:blackstone
fill ~29~29~14 ~29~29~15 minecraft:polished_blackstone_bricks
setblock ~29~31~14 minecraft:polished_blackstone
setblock ~30~11~14 minecraft:polished_blackstone_bricks
setblock ~30~15~14 minecraft:netherite_block
setblock ~30~16~14 minecraft:polished_blackstone
fill ~30~19~14 ~31~19~14 minecraft:stained_hardened_clay 9
fill ~30~20~14 ~30~20~15 minecraft:stained_hardened_clay 9
fill ~30~23~14 ~31~23~14 minecraft:polished_blackstone_bricks
fill ~30~24~14 ~30~24~15 minecraft:polished_blackstone_bricks
fill ~30~25~14 ~30~25~15 minecraft:polished_blackstone
fill ~30~26~14 ~30~26~17 minecraft:polished_blackstone_bricks
fill ~31~18~14 ~31~18~15 minecraft:stained_hardened_clay 9
setblock ~31~20~14 minecraft:polished_blackstone
setblock ~31~21~14 minecraft:stained_hardened_clay 9
setblock ~31~22~14 minecraft:polished_blackstone
fill ~6~12~15 ~6~12~16 minecraft:stone 5
setblock ~6~13~15 minecraft:stone 5
setblock ~6~14~15 minecraft:stone 6
fill ~6~15~15 ~6~16~16 minecraft:stone 5
fill ~6~17~15 ~6~23~15 minecraft:stone 5
setblock ~6~30~15 minecraft:planks 1
fill ~13~15~15 ~13~16~15 minecraft:polished_blackstone
fill ~13~17~15 ~13~17~16 minecraft:polished_blackstone_bricks
fill ~13~19~15 ~13~19~16 minecraft:polished_blackstone
fill ~13~20~15 ~13~20~17 minecraft:stained_hardened_clay 9
setblock ~14~14~15 minecraft:polished_blackstone
fill ~14~16~15 ~14~16~17 minecraft:polished_blackstone_bricks
fill ~14~21~15 ~15~21~15 minecraft:polished_blackstone
fill ~15~16~15 ~15~17~15 minecraft:polished_blackstone
fill ~15~18~15 ~15~18~16 minecraft:blackstone
setblock ~15~22~15 minecraft:stained_hardened_clay 9
fill ~15~43~15 ~16~43~18 minecraft:concrete 0
fill ~15~44~15 ~15~44~18 minecraft:concrete 0
fill ~16~14~15 ~16~16~15 minecraft:blackstone
setblock ~16~18~15 minecraft:polished_blackstone
setblock ~16~19~15 minecraft:blackstone
setblock ~16~20~15 minecraft:netherite_block
setblock ~16~21~15 minecraft:stained_hardened_clay 9
fill ~16~40~15 ~16~40~32 minecraft:concrete 0
fill ~16~41~15 ~16~41~30 minecraft:concrete 0
fill ~16~42~15 ~16~42~28 minecraft:concrete 0
fill ~16~45~15 ~16~46~16 minecraft:polished_blackstone
fill ~16~47~15 ~16~47~16 minecraft:blackstone
setblock ~16~48~15 minecraft:polished_blackstone_bricks
fill ~16~49~15 ~17~49~15 minecraft:polished_blackstone
fill ~16~50~15 ~17~51~15 minecraft:blackstone
setblock ~17~15~15 minecraft:polished_blackstone
setblock ~17~16~15 minecraft:polished_blackstone_bricks
setblock ~17~17~15 minecraft:polished_blackstone
setblock ~17~18~15 minecraft:polished_blackstone_bricks
setblock ~17~20~15 minecraft:polished_blackstone_bricks
fill ~17~38~15 ~17~38~29 minecraft:concrete 0
setblock ~17~45~15 minecraft:polished_blackstone_bricks
fill ~17~46~15 ~18~46~15 minecraft:polished_blackstone
setblock ~17~47~15 minecraft:polished_blackstone
setblock ~17~52~15 minecraft:blackstone
fill ~18~37~15 ~19~37~20 minecraft:concrete 0
setblock ~18~45~15 minecraft:polished_blackstone
setblock ~18~48~15 minecraft:polished_blackstone
fill ~18~49~15 ~19~49~15 minecraft:polished_blackstone_bricks
setblock ~18~50~15 minecraft:polished_blackstone_bricks
setblock ~18~51~15 minecraft:blackstone
fill ~19~27~15 ~19~27~17 minecraft:stained_glass 4
setblock ~19~31~15 minecraft:polished_blackstone
fill ~19~32~15 ~19~33~15 minecraft:stained_hardened_clay 9
fill ~19~34~15 ~19~34~16 minecraft:polished_blackstone
fill ~19~35~15 ~20~35~15 minecraft:blackstone
fill ~19~46~15 ~19~48~15 minecraft:polished_blackstone_bricks
fill ~20~26~15 ~20~27~15 minecraft:stained_glass 1
fill ~20~28~15 ~20~29~15 minecraft:stained_glass 4
fill ~20~30~15 ~20~30~17 minecraft:stained_hardened_clay 9
fill ~20~32~15 ~20~32~17 minecraft:polished_blackstone
setblock ~20~33~15 minecraft:polished_blackstone_bricks
setblock ~20~34~15 minecraft:blackstone
setblock ~20~36~15 minecraft:polished_blackstone
fill ~20~47~15 ~20~47~21 minecraft:concrete 0
fill ~21~25~15 ~21~25~16 minecraft:stained_glass 4
fill ~21~26~15 ~21~26~16 minecraft:shroomlight
fill ~21~28~15 ~21~28~16 minecraft:shroomlight
setblock ~21~29~15 minecraft:polished_blackstone
setblock ~21~30~15 minecraft:netherite_block
setblock ~21~32~15 minecraft:stained_hardened_clay 9
fill ~21~33~15 ~21~33~16 minecraft:polished_blackstone
setblock ~21~34~15 minecraft:polished_blackstone
fill ~21~36~15 ~23~36~20 minecraft:concrete 0
setblock ~22~26~15 minecraft:netherite_block
fill ~22~27~15 ~23~27~16 minecraft:stained_hardened_clay 9
setblock ~22~29~15 minecraft:netherite_block
setblock ~22~32~15 minecraft:polished_blackstone
fill ~22~34~15 ~24~34~21 minecraft:concrete 0
fill ~22~35~15 ~23~35~21 minecraft:concrete 0
fill ~22~46~15 ~23~46~20 minecraft:concrete 0
fill ~23~1~15 ~24~1~15 minecraft:stained_glass 1
setblock ~23~3~15 minecraft:stained_glass 1
setblock ~23~26~15 minecraft:stained_hardened_clay 9
fill ~23~28~15 ~23~28~16 minecraft:stained_hardened_clay 9
setblock ~23~29~15 minecraft:stained_hardened_clay 9
fill ~23~30~15 ~23~30~24 minecraft:concrete 0
setblock ~24~2~15 minecraft:stained_glass 1
fill ~24~3~15 ~24~4~15 minecraft:polished_blackstone
fill ~24~23~15 ~24~23~16 minecraft:stained_hardened_clay 9
setblock ~24~24~15 minecraft:stained_hardened_clay 9
fill ~24~25~15 ~24~26~15 minecraft:netherite_block
fill ~24~27~15 ~24~29~24 minecraft:concrete 0
fill ~24~32~15 ~24~32~24 minecraft:concrete 0
fill ~24~33~15 ~24~33~22 minecraft:concrete 0
setblock ~24~35~15 minecraft:polished_blackstone
setblock ~24~36~15 minecraft:blackstone
setblock ~24~37~15 minecraft:polished_blackstone_bricks
fill ~24~45~15 ~24~45~21 minecraft:concrete 0
setblock ~25~2~15 minecraft:blackstone
setblock ~25~3~15 minecraft:polished_blackstone_bricks
setblock ~25~4~15 minecraft:polished_blackstone
setblock ~25~5~15 minecraft:blackstone
fill ~25~6~15 ~27~6~15 minecraft:polished_blackstone_bricks
fill ~25~7~15 ~26~8~15 minecraft:blackstone
fill ~25~22~15 ~26~22~15 minecraft:stained_hardened_clay 9
fill ~25~23~15 ~26~23~15 minecraft:polished_blackstone
fill ~25~25~15 ~25~25~17 minecraft:blackstone
fill ~25~26~15 ~27~26~25 minecraft:concrete 0
fill ~25~31~15 ~26~31~26 minecraft:concrete 0
fill ~25~32~15 ~25~33~15 minecraft:polished_blackstone_bricks
setblock ~25~35~15 minecraft:blackstone
fill ~25~36~15 ~25~36~16 minecraft:polished_blackstone
fill ~25~37~15 ~25~38~15 minecraft:blackstone
fill ~25~41~15 ~25~41~24 minecraft:concrete 0
fill ~25~42~15 ~25~42~23 minecraft:concrete 0
fill ~25~43~15 ~25~43~22 minecraft:concrete 0
fill ~25~44~15 ~25~44~21 minecraft:concrete 0
fill ~26~1~15 ~27~1~15 minecraft:stained_glass 1
setblock ~26~2~15 minecraft:polished_blackstone
fill ~26~3~15 ~27~3~15 minecraft:blackstone
fill ~26~4~15 ~26~5~15 minecraft:polished_blackstone_bricks
fill ~26~9~15 ~26~10~15 minecraft:polished_blackstone_bricks
setblock ~26~11~15 minecraft:polished_blackstone
setblock ~26~12~15 minecraft:blackstone
setblock ~26~15~15 minecraft:blackstone
setblock ~26~16~15 minecraft:polished_blackstone
fill ~26~17~15 ~26~18~15 minecraft:blackstone
setblock ~26~20~15 minecraft:polished_blackstone
setblock ~26~21~15 minecraft:stained_hardened_clay 9
setblock ~26~24~15 minecraft:blackstone
fill ~26~25~15 ~27~25~27 minecraft:concrete 0
setblock ~26~32~15 minecraft:blackstone
setblock ~26~33~15 minecraft:polished_blackstone_bricks
setblock ~26~35~15 minecraft:polished_blackstone
fill ~26~36~15 ~27~36~15 minecraft:blackstone
setblock ~26~37~15 minecraft:polished_blackstone_bricks
fill ~26~38~15 ~27~38~15 minecraft:blackstone
fill ~26~39~15 ~26~39~21 minecraft:concrete 0
setblock ~27~2~15 minecraft:stained_glass 14
setblock ~27~5~15 minecraft:blackstone
setblock ~27~8~15 minecraft:blackstone
fill ~27~10~15 ~27~11~15 minecraft:blackstone
setblock ~27~12~15 minecraft:polished_blackstone
setblock ~27~13~15 minecraft:polished_blackstone_bricks
setblock ~27~14~15 minecraft:polished_blackstone
setblock ~27~16~15 minecraft:blackstone
fill ~27~17~15 ~27~18~15 minecraft:polished_blackstone
fill ~27~19~15 ~27~19~16 minecraft:polished_blackstone_bricks
setblock ~27~20~15 minecraft:polished_blackstone_bricks
setblock ~27~21~15 minecraft:polished_blackstone
setblock ~27~22~15 minecraft:polished_blackstone_bricks
setblock ~27~23~15 minecraft:blackstone
setblock ~27~27~15 minecraft:blackstone
setblock ~27~28~15 minecraft:polished_blackstone
setblock ~27~29~15 minecraft:blackstone
fill ~27~30~15 ~27~30~28 minecraft:concrete 0
setblock ~27~31~15 minecraft:blackstone
fill ~27~32~15 ~27~32~16 minecraft:polished_blackstone
fill ~27~33~15 ~28~33~15 minecraft:blackstone
fill ~27~35~15 ~27~35~16 minecraft:polished_blackstone_bricks
setblock ~27~37~15 minecraft:blackstone
setblock ~28~8~15 minecraft:polished_blackstone
setblock ~28~9~15 minecraft:polished_blackstone_bricks
setblock ~28~10~15 minecraft:polished_blackstone
fill ~28~11~15 ~28~12~15 minecraft:blackstone
fill ~28~13~15 ~29~13~15 minecraft:polished_blackstone
fill ~28~14~15 ~30~14~15 minecraft:polished_blackstone_bricks
setblock ~28~15~15 minecraft:blackstone
fill ~28~16~15 ~28~16~16 minecraft:polished_blackstone_bricks
setblock ~28~17~15 minecraft:blackstone
fill ~28~18~15 ~29~18~15 minecraft:polished_blackstone
fill ~28~20~15 ~29~20~15 minecraft:polished_blackstone
fill ~28~21~15 ~28~23~17 minecraft:concrete 0
fill ~28~24~15 ~29~24~15 minecraft:polished_blackstone_bricks
setblock ~28~28~15 minecraft:blackstone
fill ~28~29~15 ~28~29~16 minecraft:polished_blackstone_bricks
fill ~28~30~15 ~29~30~15 minecraft:polished_blackstone_bricks
setblock ~28~31~15 minecraft:polished_blackstone
setblock ~28~32~15 minecraft:blackstone
setblock ~28~34~15 minecraft:blackstone
setblock ~29~11~15 minecraft:polished_blackstone_bricks
setblock ~29~12~15 minecraft:blackstone
setblock ~29~15~15 minecraft:polished_blackstone
setblock ~29~16~15 minecraft:stained_hardened_clay 9
setblock ~29~21~15 minecraft:polished_blackstone_bricks
setblock ~29~22~15 minecraft:blackstone
fill ~29~23~15 ~29~23~17 minecraft:polished_blackstone_bricks
fill ~29~25~15 ~29~25~16 minecraft:polished_blackstone_bricks
setblock ~29~27~15 minecraft:polished_blackstone
setblock ~29~28~15 minecraft:polished_blackstone_bricks
fill ~29~31~15 ~29~31~19 minecraft:blackstone
fill ~29~32~15 ~29~32~16 minecraft:polished_blackstone_bricks
setblock ~30~12~15 minecraft:polished_blackstone
setblock ~30~13~15 minecraft:blackstone
setblock ~30~15~15 minecraft:polished_blackstone_bricks
setblock ~30~16~15 minecraft:netherite_block
fill ~30~17~15 ~31~17~15 minecraft:stained_hardened_clay 9
setblock ~30~18~15 minecraft:stained_hardened_clay 9
fill ~30~19~15 ~30~19~18 minecraft:polished_blackstone
fill ~30~21~15 ~31~21~15 minecraft:blackstone
fill ~30~22~15 ~30~22~17 minecraft:polished_blackstone
fill ~30~23~15 ~31~23~15 minecraft:polished_blackstone
fill ~30~27~15 ~30~27~17 minecraft:blackstone
fill ~30~28~15 ~30~28~16 minecraft:polished_blackstone
fill ~31~19~15 ~31~20~15 minecraft:stained_hardened_clay 9
fill ~31~22~15 ~31~22~18 minecraft:polished_blackstone_bricks
setblock ~31~24~15 minecraft:blackstone
fill ~31~25~15 ~31~27~15 minecraft:polished_blackstone_bricks
setblock ~6~13~16 minecraft:stone 6
setblock ~6~14~16 minecraft:stone 5
setblock ~6~31~16 minecraft:planks 1
setblock ~13~16~16 minecraft:polished_blackstone
fill ~13~18~16 ~14~18~16 minecraft:polished_blackstone
fill ~13~21~16 ~15~21~16 minecraft:stained_hardened_clay 9
setblock ~14~17~16 minecraft:polished_blackstone_bricks
fill ~14~19~16 ~15~19~16 minecraft:polished_blackstone
fill ~14~20~16 ~16~20~16 minecraft:stained_hardened_clay 9
fill ~14~22~16 ~16~22~16 minecraft:netherite_block
fill ~15~16~16 ~16~16~16 minecraft:polished_blackstone_bricks
fill ~15~17~16 ~16~17~16 minecraft:polished_blackstone
fill ~15~42~16 ~15~42~19 minecraft:concrete 0
setblock ~16~15~16 minecraft:polished_blackstone_bricks
fill ~16~18~16 ~16~19~16 minecraft:polished_blackstone_bricks
fill ~16~21~16 ~17~21~16 minecraft:polished_blackstone
fill ~16~39~16 ~16~39~19 minecraft:concrete 0
setblock ~17~16~16 minecraft:polished_blackstone
setblock ~17~17~16 minecraft:polished_blackstone_bricks
setblock ~17~18~16 minecraft:polished_blackstone
setblock ~17~19~16 minecraft:polished_blackstone_bricks
setblock ~17~20~16 minecraft:polished_blackstone
fill ~17~37~16 ~17~37~20 minecraft:concrete 0
fill ~17~45~16 ~18~45~16 minecraft:blackstone
fill ~17~46~16 ~17~47~16 minecraft:blackstone
fill ~17~48~16 ~17~48~17 minecraft:polished_blackstone_bricks
setblock ~17~49~16 minecraft:polished_blackstone
setblock ~17~50~16 minecraft:blackstone
setblock ~17~51~16 minecraft:polished_blackstone_bricks
setblock ~18~32~16 minecraft:blackstone
setblock ~18~36~16 minecraft:polished_blackstone_bricks
setblock ~18~46~16 minecraft:polished_blackstone_bricks
fill ~18~47~16 ~19~47~16 minecraft:blackstone
fill ~18~48~16 ~18~49~17 minecraft:blackstone
setblock ~19~28~16 minecraft:stained_glass 4
fill ~19~29~16 ~19~29~17 minecraft:stained_glass 1
setblock ~19~31~16 minecraft:stained_hardened_clay 9
setblock ~19~32~16 minecraft:polished_blackstone_bricks
fill ~19~33~16 ~20~33~16 minecraft:blackstone
fill ~19~35~16 ~21~35~16 minecraft:polished_blackstone_bricks
setblock ~19~46~16 minecraft:polished_blackstone
fill ~19~48~16 ~19~48~17 minecraft:polished_blackstone
setblock ~20~26~16 minecraft:stained_glass 4
setblock ~20~28~16 minecraft:stained_glass 14
fill ~20~29~16 ~20~29~18 minecraft:stained_hardened_clay 9
setblock ~20~31~16 minecraft:polished_blackstone
fill ~20~34~16 ~20~34~18 minecraft:polished_blackstone
setblock ~20~36~16 minecraft:blackstone
setblock ~21~29~16 minecraft:shroomlight
fill ~21~30~16 ~21~30~18 minecraft:stained_hardened_clay 9
setblock ~21~31~16 minecraft:stained_hardened_clay 9
setblock ~21~32~16 minecraft:blackstone
setblock ~21~34~16 minecraft:polished_blackstone_bricks
fill ~21~47~16 ~22~47~16 minecraft:concrete 0
setblock ~22~24~16 minecraft:stained_glass 1
fill ~22~25~16 ~23~25~16 minecraft:polished_blackstone
setblock ~22~26~16 minecraft:stained_hardened_clay 9
fill ~22~29~16 ~22~29~18 minecraft:stained_hardened_clay 9
fill ~22~30~16 ~22~30~17 minecraft:polished_blackstone
fill ~22~31~16 ~22~31~22 minecraft:concrete 0
fill ~22~32~16 ~22~33~21 minecraft:concrete 0
setblock ~23~26~16 minecraft:polished_blackstone
setblock ~23~29~16 minecraft:blackstone
fill ~24~1~16 ~26~1~16 minecraft:stained_glass 1
setblock ~24~24~16 minecraft:polished_blackstone
fill ~24~25~16 ~24~26~16 minecraft:stained_hardened_clay 9
fill ~24~35~16 ~24~37~22 minecraft:concrete 0
fill ~24~46~16 ~24~46~20 minecraft:concrete 0
setblock ~25~2~16 minecraft:stained_glass 1
fill ~25~3~16 ~26~3~16 minecraft:stained_glass 14
fill ~25~22~16 ~26~22~16 minecraft:polished_blackstone
fill ~25~23~16 ~25~23~21 minecraft:stained_hardened_clay 9
fill ~25~24~16 ~26~24~18 minecraft:stained_hardened_clay 9
fill ~25~32~16 ~26~32~26 minecraft:concrete 0
fill ~25~33~16 ~25~33~25 minecraft:concrete 0
fill ~25~34~16 ~25~34~24 minecraft:concrete 0
setblock ~25~35~16 minecraft:polished_blackstone_bricks
setblock ~25~37~16 minecraft:polished_blackstone_bricks
fill ~25~38~16 ~25~38~24 minecraft:concrete 0
fill ~25~45~16 ~25~45~20 minecraft:concrete 0
fill ~26~2~16 ~26~2~17 minecraft:stained_glass 14
setblock ~26~4~16 minecraft:stained_glass 14
setblock ~26~19~16 minecraft:polished_blackstone
setblock ~26~20~16 minecraft:netherite_block
fill ~26~21~16 ~26~21~17 minecraft:polished_blackstone
setblock ~26~23~16 minecraft:netherite_block
setblock ~26~33~16 minecraft:blackstone
setblock ~26~34~16 minecraft:polished_blackstone_bricks
setblock ~26~35~16 minecraft:blackstone
setblock ~26~36~16 minecraft:polished_blackstone_bricks
fill ~26~37~16 ~27~37~16 minecraft:polished_blackstone
setblock ~26~38~16 minecraft:polished_blackstone
fill ~26~40~16 ~26~41~23 minecraft:concrete 0
fill ~26~42~16 ~26~42~22 minecraft:concrete 0
setblock ~27~12~16 minecraft:polished_blackstone_bricks
setblock ~27~13~16 minecraft:polished_blackstone
fill ~27~14~16 ~28~14~16 minecraft:blackstone
setblock ~27~16~16 minecraft:polished_blackstone
setblock ~27~17~16 minecraft:blackstone
setblock ~27~18~16 minecraft:polished_blackstone_bricks
fill ~27~20~16 ~27~20~17 minecraft:polished_blackstone
fill ~27~21~16 ~27~22~16 minecraft:stained_hardened_clay 9
setblock ~27~23~16 minecraft:polished_blackstone
fill ~27~27~16 ~27~27~30 minecraft:concrete 0
fill ~27~28~16 ~27~28~29 minecraft:concrete 0
fill ~27~29~16 ~27~29~28 minecraft:concrete 0
fill ~27~31~16 ~28~31~28 minecraft:concrete 0
setblock ~27~33~16 minecraft:polished_blackstone_bricks
fill ~27~34~16 ~28~34~16 minecraft:polished_blackstone
fill ~27~36~16 ~27~36~17 minecraft:blackstone
setblock ~27~38~16 minecraft:blackstone
setblock ~28~11~16 minecraft:polished_blackstone
fill ~28~12~16 ~28~13~16 minecraft:blackstone
setblock ~28~15~16 minecraft:polished_blackstone
setblock ~28~17~16 minecraft:polished_blackstone_bricks
fill ~28~18~16 ~28~19~16 minecraft:blackstone
fill ~28~20~16 ~30~20~17 minecraft:polished_blackstone_bricks
fill ~28~24~16 ~28~26~30 minecraft:concrete 0
setblock ~28~28~16 minecraft:polished_blackstone_bricks
fill ~28~30~16 ~28~30~29 minecraft:concrete 0
fill ~28~32~16 ~28~33~16 minecraft:polished_blackstone
setblock ~28~35~16 minecraft:polished_blackstone_bricks
fill ~28~36~16 ~28~36~17 minecraft:polished_blackstone
fill ~28~37~16 ~28~37~17 minecraft:polished_blackstone_bricks
setblock ~29~12~16 minecraft:polished_blackstone
setblock ~29~13~16 minecraft:polished_blackstone_bricks
setblock ~29~14~16 minecraft:polished_blackstone
setblock ~29~15~16 minecraft:polished_blackstone_bricks
fill ~29~16~16 ~30~16~16 minecraft:blackstone
fill ~29~17~16 ~31~17~16 minecraft:polished_blackstone
fill ~29~18~16 ~30~18~16 minecraft:polished_blackstone_bricks
fill ~29~19~16 ~29~19~17 minecraft:blackstone
setblock ~29~21~16 minecraft:blackstone
setblock ~29~22~16 minecraft:polished_blackstone
setblock ~29~24~16 minecraft:polished_blackstone_bricks
setblock ~29~26~16 minecraft:polished_blackstone
setblock ~29~27~16 minecraft:polished_blackstone_bricks
fill ~29~28~16 ~29~28~17 minecraft:polished_blackstone
fill ~29~29~16 ~30~29~16 minecraft:polished_blackstone
setblock ~29~30~16 minecraft:blackstone
setblock ~29~33~16 minecraft:polished_blackstone_bricks
setblock ~30~21~16 minecraft:polished_blackstone
setblock ~30~23~16 minecraft:polished_blackstone
fill ~30~24~16 ~30~25~16 minecraft:blackstone
setblock ~30~30~16 minecraft:polished_blackstone
fill ~30~31~16 ~30~31~17 minecraft:polished_blackstone_bricks
fill ~31~18~16 ~31~18~17 minecraft:polished_blackstone
setblock ~31~19~16 minecraft:blackstone
setblock ~31~20~16 minecraft:polished_blackstone
fill ~31~21~16 ~31~21~18 minecraft:blackstone
fill ~31~23~16 ~31~24~16 minecraft:polished_blackstone_bricks
setblock ~31~25~16 minecraft:blackstone
fill ~31~26~16 ~31~28~16 minecraft:polished_blackstone_bricks
setblock ~32~19~16 minecraft:polished_blackstone
setblock ~32~20~16 minecraft:blackstone
setblock ~32~21~16 minecraft:polished_blackstone
setblock ~7~11~17 minecraft:stone 5
setblock ~7~12~17 minecraft:stone 6
fill ~7~13~17 ~7~14~17 minecraft:stone 5
setblock ~7~31~17 minecraft:planks 1
setblock ~13~18~17 minecraft:polished_blackstone
setblock ~13~19~17 minecraft:blackstone
fill ~14~17~17 ~15~17~17 minecraft:polished_blackstone
setblock ~14~18~17 minecraft:blackstone
fill ~14~19~17 ~16~19~17 minecraft:polished_blackstone_bricks
setblock ~14~20~17 minecraft:polished_blackstone
fill ~14~21~17 ~15~21~17 minecraft:netherite_block
setblock ~15~15~17 minecraft:polished_blackstone_bricks
setblock ~15~16~17 minecraft:blackstone
setblock ~15~18~17 minecraft:polished_blackstone_bricks
fill ~15~20~17 ~16~20~17 minecraft:stained_hardened_clay 9
setblock ~15~22~17 minecraft:polished_blackstone
fill ~15~41~17 ~15~41~31 minecraft:concrete 0
fill ~15~45~17 ~18~45~20 minecraft:concrete 0
setblock ~16~16~17 minecraft:polished_blackstone
fill ~16~17~17 ~16~18~17 minecraft:blackstone
fill ~16~21~17 ~16~21~19 minecraft:stained_hardened_clay 9
setblock ~16~22~17 minecraft:netherite_block
setblock ~16~46~17 minecraft:blackstone
fill ~17~18~17 ~17~18~18 minecraft:blackstone
setblock ~17~19~17 minecraft:polished_blackstone
setblock ~17~20~17 minecraft:blackstone
setblock ~17~21~17 minecraft:netherite_block
setblock ~17~46~17 minecraft:polished_blackstone
setblock ~17~47~17 minecraft:blackstone
setblock ~17~49~17 minecraft:blackstone
setblock ~18~18~17 minecraft:polished_blackstone_bricks
fill ~18~19~17 ~19~19~17 minecraft:blackstone
fill ~18~20~17 ~18~20~18 minecraft:polished_blackstone
setblock ~18~21~17 minecraft:polished_blackstone
fill ~18~28~17 ~19~28~17 minecraft:stained_glass 1
setblock ~18~31~17 minecraft:blackstone
fill ~18~32~17 ~18~32~18 minecraft:polished_blackstone_bricks
fill ~18~33~17 ~18~34~17 minecraft:polished_blackstone_bricks
fill ~18~35~17 ~19~35~17 minecraft:polished_blackstone
setblock ~18~36~17 minecraft:blackstone
setblock ~18~46~17 minecraft:blackstone
setblock ~18~47~17 minecraft:polished_blackstone
setblock ~19~26~17 minecraft:stained_glass 1
setblock ~19~30~17 minecraft:netherite_block
setblock ~19~31~17 minecraft:polished_blackstone
setblock ~19~32~17 minecraft:blackstone
setblock ~19~33~17 minecraft:polished_blackstone
fill ~19~34~17 ~19~34~19 minecraft:blackstone
fill ~19~36~17 ~20~36~19 minecraft:concrete 0
fill ~19~46~17 ~19~46~23 minecraft:concrete 0
fill ~19~47~17 ~19~47~21 minecraft:concrete 0
setblock ~20~25~17 minecraft:stained_glass 4
fill ~20~26~17 ~20~27~17 minecraft:shroomlight
fill ~20~28~17 ~20~28~19 minecraft:stained_hardened_clay 9
fill ~20~31~17 ~21~31~18 minecraft:concrete 0
fill ~20~33~17 ~20~33~18 minecraft:polished_blackstone_bricks
setblock ~20~35~17 minecraft:polished_blackstone_bricks
setblock ~21~24~17 minecraft:stained_glass 4
setblock ~21~25~17 minecraft:polished_blackstone
setblock ~21~26~17 minecraft:stained_hardened_clay 9
fill ~21~27~17 ~22~27~17 minecraft:polished_blackstone
fill ~21~28~17 ~21~28~18 minecraft:polished_blackstone
fill ~21~29~17 ~21~29~18 minecraft:stained_hardened_clay 9
fill ~21~32~17 ~21~33~21 minecraft:concrete 0
fill ~21~34~17 ~21~35~20 minecraft:concrete 0
fill ~21~47~17 ~21~47~20 minecraft:concrete 0
fill ~22~24~17 ~22~25~18 minecraft:stained_hardened_clay 9
setblock ~22~26~17 minecraft:netherite_block
fill ~22~47~17 ~23~47~17 minecraft:polished_blackstone
setblock ~22~48~17 minecraft:blackstone
fill ~23~25~17 ~23~27~17 minecraft:stained_hardened_clay 9
fill ~23~28~17 ~23~29~17 minecraft:polished_blackstone
fill ~23~48~17 ~23~49~17 minecraft:polished_blackstone
setblock ~24~23~17 minecraft:polished_blackstone
fill ~24~24~17 ~24~24~18 minecraft:stained_hardened_clay 9
setblock ~24~25~17 minecraft:netherite_block
setblock ~24~26~17 minecraft:stained_hardened_clay 9
fill ~24~47~17 ~24~48~17 minecraft:blackstone
setblock ~24~49~17 minecraft:polished_blackstone
setblock ~25~3~17 minecraft:stained_glass 1
fill ~25~4~17 ~25~4~18 minecraft:stained_glass 14
fill ~25~22~17 ~26~22~17 minecraft:stained_hardened_clay 9
fill ~25~35~17 ~25~37~23 minecraft:concrete 0
fill ~25~46~17 ~25~46~19 minecraft:polished_blackstone
fill ~25~47~17 ~25~48~17 minecraft:polished_blackstone_bricks
setblock ~25~49~17 minecraft:blackstone
fill ~25~50~17 ~25~50~19 minecraft:polished_blackstone_bricks
setblock ~25~51~17 minecraft:blackstone
fill ~26~23~17 ~27~23~18 minecraft:stained_hardened_clay 9
setblock ~26~33~17 minecraft:polished_blackstone_bricks
fill ~26~34~17 ~27~34~17 minecraft:blackstone
setblock ~26~35~17 minecraft:polished_blackstone_bricks
setblock ~26~36~17 minecraft:polished_blackstone
fill ~26~37~17 ~27~37~17 minecraft:polished_blackstone_bricks
setblock ~26~38~17 minecraft:polished_blackstone_bricks
fill ~26~43~17 ~26~43~20 minecraft:concrete 0
setblock ~27~21~17 minecraft:netherite_block
setblock ~27~22~17 minecraft:polished_blackstone
fill ~27~32~17 ~28~32~17 minecraft:polished_blackstone_bricks
fill ~27~33~17 ~28~33~17 minecraft:blackstone
fill ~27~35~17 ~28~35~17 minecraft:blackstone
fill ~27~38~17 ~27~41~17 minecraft:concrete 0
setblock ~28~17~17 minecraft:blackstone
setblock ~28~18~17 minecraft:polished_blackstone
fill ~28~19~17 ~28~19~18 minecraft:polished_blackstone_bricks
fill ~28~27~17 ~28~28~31 minecraft:concrete 0
fill ~28~29~17 ~28~29~29 minecraft:concrete 0
fill ~28~34~17 ~28~34~19 minecraft:polished_blackstone_bricks
fill ~28~38~17 ~28~38~18 minecraft:polished_blackstone
fill ~29~17~17 ~29~18~17 minecraft:polished_blackstone_bricks
fill ~29~21~17 ~30~21~17 minecraft:polished_blackstone_bricks
setblock ~29~22~17 minecraft:polished_blackstone_bricks
fill ~29~24~17 ~29~25~30 minecraft:concrete 0
setblock ~29~26~17 minecraft:polished_blackstone_bricks
setblock ~29~27~17 minecraft:polished_blackstone
fill ~29~29~17 ~29~30~17 minecraft:polished_blackstone_bricks
setblock ~29~32~17 minecraft:blackstone
setblock ~29~33~17 minecraft:polished_blackstone
setblock ~29~34~17 minecraft:blackstone
fill ~29~35~17 ~29~36~17 minecraft:polished_blackstone_bricks
setblock ~30~17~17 minecraft:blackstone
setblock ~30~18~17 minecraft:polished_blackstone
fill ~30~23~17 ~30~24~17 minecraft:polished_blackstone_bricks
setblock ~30~25~17 minecraft:blackstone
fill ~30~28~17 ~31~29~17 minecraft:blackstone
setblock ~30~30~17 minecraft:blackstone
setblock ~30~32~17 minecraft:polished_blackstone
setblock ~30~33~17 minecraft:polished_blackstone_bricks
setblock ~30~34~17 minecraft:concrete 0
fill ~31~17~17 ~31~17~18 minecraft:polished_blackstone_bricks
fill ~31~19~17 ~32~19~17 minecraft:polished_blackstone_bricks
fill ~31~20~17 ~31~20~19 minecraft:blackstone
fill ~31~23~17 ~31~23~21 minecraft:polished_blackstone
setblock ~31~24~17 minecraft:polished_blackstone
setblock ~31~25~17 minecraft:polished_blackstone_bricks
fill ~31~26~17 ~31~26~18 minecraft:polished_blackstone
setblock ~31~27~17 minecraft:polished_blackstone
setblock ~31~30~17 minecraft:polished_blackstone
setblock ~32~18~17 minecraft:blackstone
fill ~32~20~17 ~32~22~17 minecraft:polished_blackstone_bricks
fill ~32~23~17 ~32~23~18 minecraft:blackstone
fill ~32~24~17 ~32~25~17 minecraft:blackstone
fill ~32~26~17 ~32~26~18 minecraft:polished_blackstone_bricks
setblock ~32~27~17 minecraft:blackstone
fill ~8~11~18 ~8~11~19 minecraft:stone 5
setblock ~8~12~18 minecraft:stone 6
setblock ~8~13~18 minecraft:stone 5
fill ~8~32~18 ~8~32~19 minecraft:planks 1
fill ~14~18~18 ~14~19~18 minecraft:polished_blackstone
fill ~14~20~18 ~14~21~18 minecraft:stained_hardened_clay 9
fill ~15~17~18 ~16~17~18 minecraft:polished_blackstone_bricks
setblock ~15~18~18 minecraft:blackstone
fill ~15~19~18 ~16~19~18 minecraft:polished_blackstone
fill ~15~20~18 ~15~20~19 minecraft:polished_blackstone
fill ~15~21~18 ~15~21~19 minecraft:stained_hardened_clay 9
fill ~15~22~18 ~16~22~18 minecraft:stained_hardened_clay 9
setblock ~16~18~18 minecraft:polished_blackstone
fill ~16~20~18 ~16~20~19 minecraft:stained_hardened_clay 9
fill ~16~46~18 ~18~46~19 minecraft:concrete 0
setblock ~17~17~18 minecraft:polished_blackstone
setblock ~17~19~18 minecraft:blackstone
fill ~17~20~18 ~17~20~19 minecraft:polished_blackstone_bricks
fill ~17~21~18 ~17~21~19 minecraft:stained_hardened_clay 9
setblock ~17~29~18 minecraft:stained_glass 1
setblock ~17~30~18 minecraft:stained_glass 14
fill ~17~36~18 ~18~36~19 minecraft:concrete 0
fill ~17~43~18 ~17~44~18 minecraft:blackstone
setblock ~18~17~18 minecraft:blackstone
fill ~18~18~18 ~18~18~19 minecraft:polished_blackstone
setblock ~18~19~18 minecraft:polished_blackstone_bricks
setblock ~18~21~18 minecraft:blackstone
setblock ~18~28~18 minecraft:stained_glass 1
setblock ~18~29~18 minecraft:stained_glass 14
fill ~18~30~18 ~18~30~19 minecraft:polished_blackstone_bricks
fill ~18~31~18 ~19~31~18 minecraft:polished_blackstone_bricks
fill ~18~33~18 ~18~34~18 minecraft:polished_blackstone
setblock ~18~35~18 minecraft:polished_blackstone_bricks
fill ~18~43~18 ~18~44~18 minecraft:concrete 0
fill ~18~47~18 ~18~47~20 minecraft:concrete 0
fill ~19~18~18 ~20~18~18 minecraft:blackstone
fill ~19~19~18 ~19~20~19 minecraft:polished_blackstone
setblock ~19~27~18 minecraft:stained_glass 1
setblock ~19~28~18 minecraft:stained_glass 14
fill ~19~29~18 ~19~29~19 minecraft:netherite_block
fill ~19~30~18 ~20~30~18 minecraft:polished_blackstone
fill ~19~32~18 ~19~33~18 minecraft:polished_blackstone_bricks
setblock ~19~35~18 minecraft:blackstone
setblock ~20~19~18 minecraft:polished_blackstone_bricks
fill ~20~20~18 ~20~20~19 minecraft:blackstone
fill ~20~26~18 ~20~26~20 minecraft:stained_hardened_clay 9
fill ~20~27~18 ~22~27~18 minecraft:stained_hardened_clay 9
setblock ~20~32~18 minecraft:blackstone
fill ~20~35~18 ~20~35~19 minecraft:concrete 0
setblock ~21~25~18 minecraft:stained_hardened_clay 9
setblock ~21~26~18 minecraft:netherite_block
fill ~22~26~18 ~23~26~19 minecraft:stained_hardened_clay 9
setblock ~22~28~18 minecraft:netherite_block
fill ~22~30~18 ~22~30~23 minecraft:concrete 0
fill ~22~47~18 ~22~48~18 minecraft:polished_blackstone_bricks
fill ~23~5~18 ~23~5~19 minecraft:stained_glass 1
fill ~23~23~18 ~23~24~18 minecraft:polished_blackstone
setblock ~23~25~18 minecraft:netherite_block
fill ~23~27~18 ~23~29~23 minecraft:concrete 0
fill ~23~47~18 ~24~47~18 minecraft:polished_blackstone
setblock ~23~48~18 minecraft:polished_blackstone_bricks
setblock ~23~49~18 minecraft:polished_blackstone
fill ~24~22~18 ~24~23~19 minecraft:stained_hardened_clay 9
setblock ~24~25~18 minecraft:stained_hardened_clay 9
fill ~24~26~18 ~24~26~24 minecraft:concrete 0
fill ~24~48~18 ~24~48~19 minecraft:polished_blackstone
setblock ~24~49~18 minecraft:blackstone
setblock ~24~50~18 minecraft:polished_blackstone_bricks
setblock ~24~51~18 minecraft:blackstone
setblock ~25~3~18 minecraft:stained_glass 14
setblock ~25~22~18 minecraft:polished_blackstone
fill ~25~25~18 ~25~25~25 minecraft:concrete 0
fill ~25~47~18 ~25~48~19 minecraft:blackstone
fill ~25~49~18 ~25~49~19 minecraft:polished_blackstone_bricks
setblock ~25~51~18 minecraft:polished_blackstone
setblock ~25~52~18 minecraft:blackstone
fill ~26~4~18 ~26~4~19 minecraft:stained_glass 14
fill ~26~21~18 ~28~22~19 minecraft:stained_hardened_clay 9
fill ~26~33~18 ~26~33~26 minecraft:concrete 0
fill ~26~34~18 ~26~34~24 minecraft:concrete 0
fill ~26~35~18 ~26~35~23 minecraft:concrete 0
fill ~26~36~18 ~26~36~22 minecraft:concrete 0
fill ~26~37~18 ~26~38~21 minecraft:concrete 0
fill ~26~44~18 ~26~44~19 minecraft:concrete 0
setblock ~26~45~18 minecraft:concrete 0
setblock ~26~46~18 minecraft:blackstone
setblock ~26~47~18 minecraft:polished_blackstone
setblock ~26~48~18 minecraft:polished_blackstone_bricks
setblock ~26~49~18 minecraft:polished_blackstone
fill ~26~50~18 ~26~51~18 minecraft:blackstone
fill ~27~32~18 ~29~32~27 minecraft:concrete 0
fill ~27~33~18 ~29~33~18 minecraft:polished_blackstone_bricks
setblock ~27~34~18 minecraft:polished_blackstone
setblock ~27~35~18 minecraft:polished_blackstone_bricks
setblock ~27~36~18 minecraft:polished_blackstone
fill ~27~37~18 ~28~37~20 minecraft:blackstone
setblock ~27~38~18 minecraft:polished_blackstone_bricks
fill ~27~39~18 ~28~39~18 minecraft:concrete 0
fill ~27~40~18 ~27~40~22 minecraft:concrete 0
fill ~27~41~18 ~27~41~20 minecraft:concrete 0
fill ~27~42~18 ~27~42~19 minecraft:concrete 0
setblock ~28~18~18 minecraft:polished_blackstone_bricks
setblock ~28~20~18 minecraft:netherite_block
fill ~28~23~18 ~29~23~18 minecraft:concrete 0
fill ~28~35~18 ~28~35~19 minecraft:polished_blackstone
fill ~28~36~18 ~30~36~18 minecraft:polished_blackstone_bricks
setblock ~29~17~18 minecraft:blackstone
setblock ~29~18~18 minecraft:polished_blackstone
setblock ~29~19~18 minecraft:polished_blackstone_bricks
fill ~29~20~18 ~29~22~18 minecraft:polished_blackstone
fill ~29~26~18 ~29~28~32 minecraft:concrete 0
fill ~29~29~18 ~30~29~18 minecraft:blackstone
setblock ~29~30~18 minecraft:blackstone
fill ~29~34~18 ~29~34~19 minecraft:polished_blackstone
setblock ~29~35~18 minecraft:blackstone
fill ~29~37~18 ~29~38~18 minecraft:polished_blackstone_bricks
fill ~30~17~18 ~30~18~18 minecraft:polished_blackstone_bricks
setblock ~30~20~18 minecraft:blackstone
setblock ~30~21~18 minecraft:polished_blackstone
setblock ~30~22~18 minecraft:polished_blackstone_bricks
setblock ~30~23~18 minecraft:blackstone
setblock ~30~24~18 minecraft:polished_blackstone
setblock ~30~25~18 minecraft:polished_blackstone_bricks
setblock ~30~26~18 minecraft:blackstone
setblock ~30~27~18 minecraft:polished_blackstone
fill ~30~28~18 ~30~28~19 minecraft:polished_blackstone_bricks
fill ~30~30~18 ~31~30~18 minecraft:polished_blackstone_bricks
setblock ~30~31~18 minecraft:polished_blackstone
setblock ~30~32~18 minecraft:blackstone
setblock ~30~33~18 minecraft:polished_blackstone
setblock ~30~34~18 minecraft:blackstone
setblock ~30~35~18 minecraft:polished_blackstone_bricks
fill ~31~18~18 ~31~18~19 minecraft:blackstone
setblock ~31~19~18 minecraft:blackstone
setblock ~31~24~18 minecraft:blackstone
setblock ~31~25~18 minecraft:polished_blackstone
fill ~31~27~18 ~32~27~18 minecraft:polished_blackstone_bricks
setblock ~31~28~18 minecraft:blackstone
fill ~31~29~18 ~31~29~19 minecraft:polished_blackstone
setblock ~31~31~18 minecraft:blackstone
setblock ~31~32~18 minecraft:polished_blackstone_bricks
fill ~31~33~18 ~31~34~18 minecraft:concrete 0
fill ~32~18~18 ~32~19~18 minecraft:polished_blackstone_bricks
fill ~32~20~18 ~32~21~18 minecraft:blackstone
fill ~32~22~18 ~33~22~18 minecraft:polished_blackstone
fill ~32~24~18 ~32~24~19 minecraft:polished_blackstone_bricks
fill ~32~25~18 ~32~25~19 minecraft:blackstone
setblock ~33~21~18 minecraft:polished_blackstone
fill ~33~23~18 ~33~23~22 minecraft:polished_blackstone
fill ~9~12~19 ~9~12~20 minecraft:stone 6
setblock ~9~13~19 minecraft:stone 5
setblock ~15~19~19 minecraft:blackstone
fill ~16~18~19 ~16~19~19 minecraft:polished_blackstone_bricks
fill ~17~17~19 ~18~17~19 minecraft:polished_blackstone_bricks
setblock ~17~18~19 minecraft:polished_blackstone
fill ~17~19~19 ~17~19~20 minecraft:polished_blackstone_bricks
setblock ~17~30~19 minecraft:stained_glass 1
setblock ~17~42~19 minecraft:blackstone
fill ~18~19~19 ~18~19~20 minecraft:polished_blackstone
setblock ~18~20~19 minecraft:polished_blackstone_bricks
fill ~18~21~19 ~18~21~20 minecraft:polished_blackstone
setblock ~18~29~19 minecraft:stained_glass 1
fill ~18~31~19 ~18~31~22 minecraft:blackstone
fill ~18~32~19 ~18~32~21 minecraft:blackstone
fill ~18~33~19 ~18~33~20 minecraft:blackstone
fill ~18~34~19 ~18~34~20 minecraft:polished_blackstone_bricks
fill ~18~35~19 ~18~35~20 minecraft:polished_blackstone
fill ~18~43~19 ~18~43~20 minecraft:blackstone
setblock ~18~44~19 minecraft:blackstone
fill ~19~17~19 ~20~17~19 minecraft:blackstone
setblock ~19~18~19 minecraft:polished_blackstone
setblock ~19~21~19 minecraft:blackstone
setblock ~19~28~19 minecraft:netherite_block
setblock ~19~30~19 minecraft:blackstone
fill ~19~31~19 ~19~31~20 minecraft:polished_blackstone
setblock ~19~32~19 minecraft:polished_blackstone
fill ~19~33~19 ~19~33~20 minecraft:polished_blackstone_bricks
setblock ~19~35~19 minecraft:concrete 0
fill ~20~18~19 ~21~18~19 minecraft:polished_blackstone_bricks
setblock ~20~19~19 minecraft:polished_blackstone
setblock ~20~21~19 minecraft:polished_blackstone_bricks
setblock ~20~27~19 minecraft:stained_hardened_clay 9
fill ~20~29~19 ~21~29~19 minecraft:polished_blackstone
setblock ~20~30~19 minecraft:polished_blackstone
fill ~20~31~19 ~20~32~19 minecraft:polished_blackstone_bricks
setblock ~20~33~19 minecraft:blackstone
setblock ~20~34~19 minecraft:concrete 0
fill ~21~19~19 ~21~19~20 minecraft:polished_blackstone_bricks
fill ~21~20~19 ~21~20~21 minecraft:polished_blackstone
setblock ~21~25~19 minecraft:netherite_block
fill ~21~26~19 ~21~26~20 minecraft:stained_hardened_clay 9
setblock ~21~27~19 minecraft:netherite_block
setblock ~21~28~19 minecraft:stained_hardened_clay 9
setblock ~21~30~19 minecraft:blackstone
fill ~21~31~19 ~21~31~22 minecraft:concrete 0
fill ~22~24~19 ~22~25~19 minecraft:polished_blackstone
setblock ~22~27~19 minecraft:stained_hardened_clay 9
setblock ~22~28~19 minecraft:polished_blackstone
setblock ~22~29~19 minecraft:blackstone
setblock ~22~47~19 minecraft:polished_blackstone
setblock ~22~48~19 minecraft:blackstone
fill ~23~6~19 ~23~6~20 minecraft:stained_glass 14
fill ~23~22~19 ~23~22~20 minecraft:stained_hardened_clay 9
fill ~23~23~19 ~23~25~19 minecraft:stained_hardened_clay 9
setblock ~23~47~19 minecraft:polished_blackstone_bricks
setblock ~23~48~19 minecraft:polished_blackstone
fill ~24~24~19 ~24~25~19 minecraft:netherite_block
setblock ~24~47~19 minecraft:blackstone
setblock ~24~49~19 minecraft:polished_blackstone_bricks
setblock ~25~21~19 minecraft:polished_blackstone
fill ~25~22~19 ~25~22~20 minecraft:stained_hardened_clay 9
fill ~25~24~19 ~25~24~20 minecraft:stained_hardened_clay 9
setblock ~25~51~19 minecraft:blackstone
fill ~26~5~19 ~26~5~20 minecraft:stained_glass 14
setblock ~26~23~19 minecraft:netherite_block
fill ~26~24~19 ~26~24~27 minecraft:concrete 0
setblock ~27~23~19 minecraft:stained_hardened_clay 9
fill ~27~33~19 ~28~33~26 minecraft:concrete 0
fill ~27~34~19 ~27~34~24 minecraft:concrete 0
fill ~27~35~19 ~27~35~22 minecraft:concrete 0
setblock ~27~36~19 minecraft:polished_blackstone_bricks
fill ~27~38~19 ~27~38~20 minecraft:blackstone
setblock ~27~39~19 minecraft:polished_blackstone
setblock ~28~23~19 minecraft:netherite_block
fill ~28~36~19 ~28~36~20 minecraft:polished_blackstone
setblock ~28~38~19 minecraft:polished_blackstone_bricks
setblock ~28~39~19 minecraft:concrete 0
setblock ~29~18~19 minecraft:polished_blackstone_bricks
fill ~29~19~19 ~29~20~19 minecraft:stained_hardened_clay 9
setblock ~29~21~19 minecraft:netherite_block
fill ~29~22~19 ~30~22~20 minecraft:stained_hardened_clay 9
fill ~29~23~19 ~29~23~21 minecraft:stained_hardened_clay 9
setblock ~29~29~19 minecraft:blackstone
setblock ~29~30~19 minecraft:polished_blackstone_bricks
setblock ~29~33~19 minecraft:polished_blackstone_bricks
fill ~29~35~19 ~29~36~19 minecraft:polished_blackstone_bricks
fill ~29~37~19 ~30~37~19 minecraft:polished_blackstone
setblock ~29~38~19 minecraft:polished_blackstone
setblock ~30~18~19 minecraft:blackstone
setblock ~30~19~19 minecraft:polished_blackstone_bricks
fill ~30~20~19 ~30~20~20 minecraft:stained_hardened_clay 9
setblock ~30~21~19 minecraft:stained_hardened_clay 9
fill ~30~23~19 ~30~27~30 minecraft:concrete 0
fill ~30~29~19 ~30~30~19 minecraft:polished_blackstone
setblock ~30~31~19 minecraft:blackstone
setblock ~30~32~19 minecraft:polished_blackstone
fill ~30~33~19 ~31~33~19 minecraft:blackstone
setblock ~30~34~19 minecraft:polished_blackstone_bricks
setblock ~30~35~19 minecraft:polished_blackstone
setblock ~30~36~19 minecraft:polished_blackstone_bricks
fill ~31~19~19 ~32~19~19 minecraft:polished_blackstone
setblock ~31~21~19 minecraft:polished_blackstone_bricks
fill ~31~22~19 ~32~22~19 minecraft:blackstone
fill ~31~24~19 ~31~26~19 minecraft:polished_blackstone_bricks
fill ~31~27~19 ~32~27~19 minecraft:blackstone
setblock ~31~28~19 minecraft:polished_blackstone
fill ~31~30~19 ~32~30~19 minecraft:polished_blackstone_bricks
setblock ~31~31~19 minecraft:polished_blackstone_bricks
fill ~31~32~19 ~31~32~20 minecraft:blackstone
setblock ~31~34~19 minecraft:concrete 0
fill ~32~20~19 ~33~20~19 minecraft:polished_blackstone_bricks
setblock ~32~21~19 minecraft:polished_blackstone
setblock ~32~23~19 minecraft:polished_blackstone_bricks
setblock ~32~26~19 minecraft:polished_blackstone
setblock ~32~28~19 minecraft:polished_blackstone_bricks
fill ~32~29~19 ~32~29~23 minecraft:blackstone
fill ~32~31~19 ~32~31~20 minecraft:blackstone
fill ~32~33~19 ~32~33~20 minecraft:concrete 0
setblock ~33~21~19 minecraft:polished_blackstone_bricks
fill ~33~22~19 ~33~22~20 minecraft:polished_blackstone
setblock ~33~24~19 minecraft:blackstone
setblock ~33~25~19 minecraft:polished_blackstone
setblock ~9~33~20 minecraft:planks 1
setblock ~16~19~20 minecraft:blackstone
fill ~16~20~20 ~17~20~20 minecraft:polished_blackstone
setblock ~16~30~20 minecraft:stained_glass 1
fill ~17~18~20 ~18~18~20 minecraft:blackstone
setblock ~17~30~20 minecraft:stained_glass 14
fill ~17~42~20 ~17~42~28 minecraft:concrete 0
fill ~17~46~20 ~18~46~21 minecraft:concrete 0
setblock ~18~17~20 minecraft:blackstone
fill ~18~20~20 ~20~20~20 minecraft:stained_hardened_clay 9
fill ~18~29~20 ~21~29~20 minecraft:blackstone
fill ~18~30~20 ~19~30~20 minecraft:polished_blackstone
setblock ~18~36~20 minecraft:polished_blackstone_bricks
fill ~18~44~20 ~18~44~21 minecraft:shroomlight
setblock ~19~17~20 minecraft:polished_blackstone
fill ~19~18~20 ~20~18~20 minecraft:polished_blackstone_bricks
fill ~19~19~20 ~20~19~20 minecraft:stained_hardened_clay 9
fill ~19~21~20 ~20~21~20 minecraft:stained_hardened_clay 9
fill ~19~26~20 ~19~26~21 minecraft:blackstone
fill ~19~27~20 ~22~27~20 minecraft:polished_blackstone_bricks
setblock ~19~28~20 minecraft:polished_blackstone_bricks
fill ~19~32~20 ~20~32~20 minecraft:polished_blackstone_bricks
setblock ~19~34~20 minecraft:polished_blackstone
fill ~19~35~20 ~20~35~21 minecraft:polished_blackstone_bricks
setblock ~19~36~20 minecraft:polished_blackstone
setblock ~20~17~20 minecraft:blackstone
fill ~20~25~20 ~22~25~20 minecraft:stained_hardened_clay 9
fill ~20~28~20 ~21~28~20 minecraft:blackstone
setblock ~20~30~20 minecraft:polished_blackstone_bricks
setblock ~20~31~20 minecraft:blackstone
fill ~20~33~20 ~20~34~20 minecraft:polished_blackstone_bricks
fill ~20~36~20 ~20~36~22 minecraft:polished_blackstone_bricks
fill ~21~17~20 ~22~17~20 minecraft:polished_blackstone_bricks
setblock ~21~18~20 minecraft:polished_blackstone
setblock ~21~21~20 minecraft:blackstone
fill ~21~24~20 ~21~24~21 minecraft:polished_blackstone
fill ~21~30~20 ~21~30~22 minecraft:concrete 0
setblock ~22~18~20 minecraft:polished_blackstone_bricks
fill ~22~19~20 ~22~20~20 minecraft:polished_blackstone
fill ~22~21~20 ~22~24~20 minecraft:stained_hardened_clay 9
setblock ~22~26~20 minecraft:polished_blackstone
fill ~22~28~20 ~22~29~23 minecraft:concrete 0
fill ~23~19~20 ~23~19~22 minecraft:polished_blackstone_bricks
setblock ~23~20~20 minecraft:netherite_block
setblock ~23~21~20 minecraft:polished_blackstone
setblock ~23~23~20 minecraft:polished_blackstone
setblock ~23~24~20 minecraft:netherite_block
fill ~23~25~20 ~23~26~20 minecraft:polished_blackstone_bricks
setblock ~24~21~20 minecraft:stained_hardened_clay 9
fill ~24~22~20 ~24~22~21 minecraft:polished_blackstone
fill ~24~23~20 ~24~23~21 minecraft:stained_hardened_clay 9
setblock ~24~24~20 minecraft:stained_hardened_clay 9
fill ~24~25~20 ~24~25~24 minecraft:concrete 0
setblock ~25~21~20 minecraft:netherite_block
fill ~26~8~20 ~26~8~21 minecraft:stained_glass 14
fill ~26~21~20 ~26~21~23 minecraft:stained_hardened_clay 9
setblock ~26~22~20 minecraft:netherite_block
fill ~26~23~20 ~26~23~21 minecraft:stained_hardened_clay 9
setblock ~27~5~20 minecraft:stained_glass 1
fill ~27~6~20 ~27~6~21 minecraft:stained_glass 14
fill ~27~21~20 ~27~23~20 minecraft:polished_blackstone
setblock ~27~36~20 minecraft:concrete 0
setblock ~27~39~20 minecraft:blackstone
fill ~28~21~20 ~29~21~21 minecraft:stained_hardened_clay 9
fill ~28~22~20 ~28~22~22 minecraft:stained_hardened_clay 9
fill ~28~23~20 ~28~23~21 minecraft:stained_hardened_clay 9
fill ~28~34~20 ~28~34~22 minecraft:concrete 0
setblock ~28~35~20 minecraft:concrete 0
setblock ~28~38~20 minecraft:polished_blackstone
setblock ~28~39~20 minecraft:polished_blackstone_bricks
fill ~29~20~20 ~29~20~21 minecraft:stained_hardened_clay 9
fill ~29~29~20 ~29~29~32 minecraft:concrete 0
fill ~29~30~20 ~29~30~30 minecraft:concrete 0
fill ~29~31~20 ~29~31~29 minecraft:concrete 0
fill ~29~33~20 ~29~33~23 minecraft:concrete 0
fill ~29~34~20 ~30~34~21 minecraft:blackstone
fill ~29~35~20 ~30~35~20 minecraft:blackstone
setblock ~29~36~20 minecraft:polished_blackstone_bricks
fill ~29~37~20 ~29~37~22 minecraft:blackstone
fill ~29~38~20 ~29~38~21 minecraft:blackstone
setblock ~30~19~20 minecraft:blackstone
fill ~30~21~20 ~31~21~20 minecraft:polished_blackstone
fill ~30~28~20 ~30~28~35 minecraft:concrete 0
setblock ~30~29~20 minecraft:blackstone
fill ~30~30~20 ~31~30~20 minecraft:polished_blackstone_bricks
fill ~30~31~20 ~30~33~20 minecraft:polished_blackstone_bricks
fill ~30~36~20 ~30~36~21 minecraft:blackstone
setblock ~30~37~20 minecraft:polished_blackstone_bricks
fill ~31~19~20 ~31~19~21 minecraft:stained_hardened_clay 9
setblock ~31~20~20 minecraft:netherite_block
fill ~31~22~20 ~32~22~20 minecraft:polished_blackstone
fill ~31~24~20 ~33~24~20 minecraft:polished_blackstone
setblock ~31~25~20 minecraft:polished_blackstone_bricks
setblock ~31~26~20 minecraft:blackstone
setblock ~31~27~20 minecraft:polished_blackstone_bricks
fill ~31~28~20 ~32~28~20 minecraft:blackstone
fill ~31~29~20 ~31~29~21 minecraft:polished_blackstone_bricks
setblock ~31~31~20 minecraft:blackstone
setblock ~31~33~20 minecraft:blackstone
setblock ~31~34~20 minecraft:polished_blackstone
setblock ~31~35~20 minecraft:polished_blackstone_bricks
setblock ~32~19~20 minecraft:netherite_block
fill ~32~20~20 ~33~21~20 minecraft:stained_hardened_clay 9
setblock ~32~23~20 minecraft:polished_blackstone
setblock ~32~25~20 minecraft:polished_blackstone
fill ~32~26~20 ~33~26~20 minecraft:polished_blackstone_bricks
fill ~32~27~20 ~33~27~21 minecraft:polished_blackstone
fill ~32~30~20 ~33~30~20 minecraft:blackstone
fill ~32~32~20 ~32~32~21 minecraft:polished_blackstone
fill ~32~34~20 ~32~34~21 minecraft:concrete 0
fill ~33~25~20 ~33~25~21 minecraft:polished_blackstone_bricks
fill ~33~28~20 ~33~29~20 minecraft:polished_blackstone
setblock ~9~13~21 minecraft:stone 6
setblock ~10~34~21 minecraft:planks 1
fill ~16~31~21 ~17~31~21 minecraft:stained_glass 14
setblock ~16~32~21 minecraft:stained_glass 1
fill ~16~45~21 ~18~45~21 minecraft:concrete 0
fill ~17~19~21 ~19~19~21 minecraft:netherite_block
setblock ~17~30~21 minecraft:stained_glass 1
setblock ~17~32~21 minecraft:stained_glass 14
setblock ~18~18~21 minecraft:polished_blackstone
setblock ~18~20~21 minecraft:polished_blackstone
fill ~18~27~21 ~18~27~22 minecraft:polished_blackstone
fill ~18~28~21 ~19~28~21 minecraft:polished_blackstone
fill ~18~29~21 ~18~30~21 minecraft:polished_blackstone_bricks
setblock ~18~33~21 minecraft:polished_blackstone_bricks
setblock ~18~36~21 minecraft:polished_blackstone
setblock ~18~37~21 minecraft:blackstone
setblock ~18~43~21 minecraft:shroomlight
fill ~19~17~21 ~20~17~21 minecraft:polished_blackstone_bricks
setblock ~19~18~21 minecraft:stained_hardened_clay 9
setblock ~19~20~21 minecraft:netherite_block
fill ~19~21~21 ~20~21~21 minecraft:polished_blackstone
fill ~19~25~21 ~19~25~23 minecraft:blackstone
fill ~19~27~21 ~19~27~23 minecraft:polished_blackstone_bricks
fill ~19~29~21 ~19~31~21 minecraft:blackstone
fill ~19~32~21 ~20~32~21 minecraft:polished_blackstone
fill ~19~33~21 ~19~34~21 minecraft:blackstone
setblock ~19~36~21 minecraft:blackstone
setblock ~19~37~21 minecraft:polished_blackstone
fill ~20~18~21 ~20~19~21 minecraft:polished_blackstone
fill ~20~20~21 ~20~20~23 minecraft:stained_hardened_clay 9
setblock ~20~22~21 minecraft:stained_hardened_clay 9
setblock ~20~24~21 minecraft:blackstone
fill ~20~25~21 ~21~25~21 minecraft:polished_blackstone
fill ~20~26~21 ~20~26~22 minecraft:polished_blackstone_bricks
setblock ~20~27~21 minecraft:blackstone
fill ~20~28~21 ~20~28~22 minecraft:polished_blackstone_bricks
setblock ~20~29~21 minecraft:polished_blackstone_bricks
fill ~20~30~21 ~20~30~22 minecraft:polished_blackstone
setblock ~20~31~21 minecraft:polished_blackstone_bricks
setblock ~20~33~21 minecraft:polished_blackstone
fill ~20~34~21 ~20~34~22 minecraft:polished_blackstone_bricks
setblock ~20~37~21 minecraft:polished_blackstone_bricks
fill ~21~17~21 ~22~17~21 minecraft:polished_blackstone
fill ~21~18~21 ~21~18~22 minecraft:polished_blackstone_bricks
fill ~21~19~21 ~21~19~22 minecraft:stained_hardened_clay 9
fill ~21~21~21 ~21~21~23 minecraft:stained_hardened_clay 9
setblock ~21~22~21 minecraft:polished_blackstone
setblock ~21~23~21 minecraft:blackstone
fill ~21~26~21 ~21~26~22 minecraft:polished_blackstone
fill ~21~27~21 ~22~27~21 minecraft:concrete 0
fill ~21~28~21 ~21~29~22 minecraft:concrete 0
fill ~21~34~21 ~21~36~21 minecraft:blackstone
fill ~21~37~21 ~23~37~21 minecraft:concrete 0
fill ~22~18~21 ~22~18~23 minecraft:blackstone
fill ~22~19~21 ~22~20~22 minecraft:polished_blackstone_bricks
setblock ~22~21~21 minecraft:polished_blackstone_bricks
setblock ~22~22~21 minecraft:blackstone
setblock ~22~23~21 minecraft:polished_blackstone
fill ~22~24~21 ~22~24~23 minecraft:blackstone
fill ~22~25~21 ~22~25~22 minecraft:polished_blackstone_bricks
fill ~22~26~21 ~22~26~22 minecraft:blackstone
fill ~22~36~21 ~23~36~21 minecraft:concrete 0
setblock ~22~46~21 minecraft:concrete 0
setblock ~23~17~21 minecraft:blackstone
fill ~23~18~21 ~23~18~22 minecraft:polished_blackstone_bricks
fill ~23~20~21 ~24~20~21 minecraft:polished_blackstone
setblock ~23~21~21 minecraft:stained_hardened_clay 9
setblock ~23~22~21 minecraft:netherite_block
setblock ~23~23~21 minecraft:stained_hardened_clay 9
fill ~23~24~21 ~25~24~24 minecraft:concrete 0
fill ~23~25~21 ~23~25~24 minecraft:concrete 0
fill ~23~26~21 ~23~26~23 minecraft:concrete 0
fill ~24~18~21 ~24~18~22 minecraft:polished_blackstone
setblock ~24~19~21 minecraft:polished_blackstone
setblock ~24~21~21 minecraft:netherite_block
fill ~25~8~21 ~25~8~22 minecraft:stained_glass 14
setblock ~25~20~21 minecraft:netherite_block
fill ~25~21~21 ~25~21~22 minecraft:stained_hardened_clay 9
setblock ~25~22~21 minecraft:netherite_block
fill ~26~22~21 ~26~22~22 minecraft:stained_hardened_clay 9
setblock ~27~5~21 minecraft:stained_glass 14
setblock ~27~21~21 minecraft:netherite_block
setblock ~27~22~21 minecraft:polished_blackstone
setblock ~27~23~21 minecraft:stained_hardened_clay 9
fill ~27~36~21 ~27~38~21 minecraft:polished_blackstone
setblock ~27~39~21 minecraft:polished_blackstone_bricks
setblock ~28~20~21 minecraft:stained_hardened_clay 9
fill ~28~35~21 ~29~35~21 minecraft:polished_blackstone_bricks
setblock ~28~36~21 minecraft:polished_blackstone_bricks
setblock ~28~37~21 minecraft:polished_blackstone
fill ~28~38~21 ~28~38~22 minecraft:polished_blackstone_bricks
setblock ~28~39~21 minecraft:polished_blackstone
fill ~29~22~21 ~29~22~22 minecraft:netherite_block
fill ~29~36~21 ~29~36~22 minecraft:polished_blackstone
setblock ~30~19~21 minecraft:stained_hardened_clay 9
setblock ~30~20~21 minecraft:netherite_block
fill ~30~21~21 ~31~21~23 minecraft:stained_hardened_clay 9
setblock ~30~22~21 minecraft:stained_hardened_clay 9
fill ~30~29~21 ~30~29~32 minecraft:concrete 0
fill ~30~30~21 ~30~30~30 minecraft:concrete 0
fill ~30~31~21 ~30~31~29 minecraft:concrete 0
fill ~30~32~21 ~30~32~22 minecraft:polished_blackstone
setblock ~30~33~21 minecraft:polished_blackstone
fill ~30~35~21 ~31~35~21 minecraft:blackstone
fill ~31~20~21 ~32~20~21 minecraft:stained_hardened_clay 9
fill ~31~22~21 ~33~22~21 minecraft:netherite_block
fill ~31~24~21 ~31~26~31 minecraft:concrete 0
setblock ~31~27~21 minecraft:blackstone
fill ~31~28~21 ~32~28~21 minecraft:polished_blackstone
setblock ~31~30~21 minecraft:polished_blackstone
fill ~31~31~21 ~31~34~21 minecraft:polished_blackstone_bricks
setblock ~32~19~21 minecraft:stained_hardened_clay 9
setblock ~32~21~21 minecraft:netherite_block
setblock ~32~23~21 minecraft:blackstone
fill ~32~24~21 ~34~24~21 minecraft:polished_blackstone
fill ~32~25~21 ~32~25~22 minecraft:polished_blackstone_bricks
fill ~32~26~21 ~33~26~21 minecraft:blackstone
fill ~32~30~21 ~33~30~21 minecraft:polished_blackstone_bricks
setblock ~32~31~21 minecraft:polished_blackstone
setblock ~32~33~21 minecraft:polished_blackstone_bricks
setblock ~32~35~21 minecraft:concrete 0
fill ~33~21~21 ~33~21~22 minecraft:stained_hardened_clay 9
setblock ~33~28~21 minecraft:polished_blackstone_bricks
setblock ~33~29~21 minecraft:blackstone
setblock ~33~31~21 minecraft:polished_blackstone_bricks
setblock ~34~23~21 minecraft:blackstone
setblock ~34~25~21 minecraft:blackstone
setblock ~34~26~21 minecraft:polished_blackstone
setblock ~34~27~21 minecraft:blackstone
setblock ~34~28~21 minecraft:polished_blackstone
setblock ~34~29~21 minecraft:polished_blackstone_bricks
setblock ~11~34~22 minecraft:planks 1
fill ~15~40~22 ~15~40~29 minecraft:concrete 0
fill ~15~42~22 ~15~42~29 minecraft:concrete 0
fill ~15~43~22 ~18~43~23 minecraft:concrete 0
setblock ~16~31~22 minecraft:stained_glass 1
setblock ~16~32~22 minecraft:stained_glass 14
fill ~16~39~22 ~16~39~29 minecraft:concrete 0
fill ~16~44~22 ~18~44~22 minecraft:concrete 0
fill ~17~45~22 ~18~45~22 minecraft:concrete 0
setblock ~18~19~22 minecraft:netherite_block
fill ~18~28~22 ~19~28~22 minecraft:polished_blackstone_bricks
fill ~18~29~22 ~18~30~22 minecraft:blackstone
setblock ~18~32~22 minecraft:polished_blackstone_bricks
setblock ~18~37~22 minecraft:polished_blackstone
setblock ~18~46~22 minecraft:concrete 0
setblock ~19~18~22 minecraft:polished_blackstone
fill ~19~19~22 ~20~19~22 minecraft:stained_hardened_clay 9
setblock ~19~20~22 minecraft:stained_hardened_clay 9
fill ~19~26~22 ~19~26~24 minecraft:polished_blackstone_bricks
fill ~19~29~22 ~19~31~22 minecraft:polished_blackstone_bricks
setblock ~19~32~22 minecraft:polished_blackstone
fill ~19~33~22 ~23~33~22 minecraft:polished_blackstone_bricks
setblock ~19~34~22 minecraft:polished_blackstone
setblock ~19~35~22 minecraft:polished_blackstone_bricks
setblock ~19~36~22 minecraft:polished_blackstone
setblock ~19~37~22 minecraft:blackstone
setblock ~20~17~22 minecraft:polished_blackstone_bricks
fill ~20~18~22 ~20~18~24 minecraft:stained_hardened_clay 9
setblock ~20~21~22 minecraft:stained_hardened_clay 9
setblock ~20~22~22 minecraft:polished_blackstone
setblock ~20~24~22 minecraft:polished_blackstone
setblock ~20~25~22 minecraft:blackstone
setblock ~20~27~22 minecraft:polished_blackstone
setblock ~20~29~22 minecraft:blackstone
setblock ~20~31~22 minecraft:blackstone
fill ~20~32~22 ~20~32~23 minecraft:polished_blackstone_bricks
setblock ~20~35~22 minecraft:polished_blackstone
setblock ~20~37~22 minecraft:polished_blackstone
fill ~21~17~22 ~21~17~23 minecraft:blackstone
fill ~21~20~22 ~21~20~23 minecraft:stained_hardened_clay 9
setblock ~21~22~22 minecraft:polished_blackstone_bricks
setblock ~21~23~22 minecraft:polished_blackstone
fill ~21~24~22 ~21~24~23 minecraft:blackstone
setblock ~21~25~22 minecraft:polished_blackstone_bricks
setblock ~21~27~22 minecraft:blackstone
fill ~21~32~22 ~22~32~22 minecraft:polished_blackstone
fill ~21~34~22 ~22~34~22 minecraft:polished_blackstone
fill ~21~35~22 ~21~35~23 minecraft:polished_blackstone_bricks
fill ~21~36~22 ~22~36~22 minecraft:blackstone
setblock ~21~37~22 minecraft:polished_blackstone_bricks
fill ~22~16~22 ~23~16~22 minecraft:blackstone
fill ~22~17~22 ~24~17~22 minecraft:polished_blackstone_bricks
fill ~22~21~22 ~22~21~23 minecraft:polished_blackstone
setblock ~22~22~22 minecraft:polished_blackstone
fill ~22~23~22 ~23~23~22 minecraft:polished_blackstone_bricks
fill ~22~27~22 ~22~27~23 minecraft:concrete 0
setblock ~22~35~22 minecraft:polished_blackstone
fill ~22~37~22 ~22~37~23 minecraft:blackstone
setblock ~23~20~22 minecraft:polished_blackstone
setblock ~23~21~22 minecraft:blackstone
setblock ~23~22~22 minecraft:polished_blackstone_bricks
setblock ~23~34~22 minecraft:blackstone
fill ~23~35~22 ~23~36~22 minecraft:polished_blackstone_bricks
setblock ~23~37~22 minecraft:concrete 0
fill ~24~19~22 ~25~19~22 minecraft:polished_blackstone_bricks
setblock ~24~20~22 minecraft:polished_blackstone_bricks
fill ~24~21~22 ~24~23~24 minecraft:concrete 0
setblock ~24~34~22 minecraft:concrete 0
fill ~25~9~22 ~25~9~23 minecraft:stained_glass 14
setblock ~25~18~22 minecraft:blackstone
fill ~25~20~22 ~27~20~22 minecraft:stained_hardened_clay 9
setblock ~25~22~22 minecraft:stained_hardened_clay 9
fill ~25~23~22 ~29~23~25 minecraft:concrete 0
fill ~26~37~22 ~26~38~22 minecraft:polished_blackstone_bricks
fill ~26~39~22 ~27~39~22 minecraft:polished_blackstone
fill ~27~21~22 ~28~21~22 minecraft:stained_hardened_clay 9
setblock ~27~22~22 minecraft:stained_hardened_clay 9
setblock ~27~36~22 minecraft:blackstone
setblock ~27~37~22 minecraft:polished_blackstone
setblock ~27~38~22 minecraft:blackstone
setblock ~28~7~22 minecraft:stained_glass 1
fill ~28~20~22 ~29~20~22 minecraft:polished_blackstone
setblock ~28~35~22 minecraft:polished_blackstone_bricks
setblock ~28~36~22 minecraft:polished_blackstone
setblock ~28~37~22 minecraft:polished_blackstone_bricks
fill ~28~39~22 ~28~39~23 minecraft:concrete 0
setblock ~29~21~22 minecraft:netherite_block
fill ~29~34~22 ~29~34~23 minecraft:polished_blackstone
setblock ~29~35~22 minecraft:blackstone
fill ~30~20~22 ~30~20~27 minecraft:stained_hardened_clay 9
fill ~30~22~22 ~30~22~23 minecraft:concrete 0
fill ~30~33~22 ~31~33~22 minecraft:blackstone
fill ~30~34~22 ~30~34~23 minecraft:polished_blackstone_bricks
setblock ~30~35~22 minecraft:polished_blackstone_bricks
fill ~30~36~22 ~30~36~24 minecraft:concrete 0
fill ~31~20~22 ~32~20~22 minecraft:netherite_block
setblock ~31~22~22 minecraft:netherite_block
fill ~31~23~22 ~31~23~23 minecraft:concrete 0
fill ~31~27~22 ~31~27~46 minecraft:concrete 0
fill ~31~28~22 ~31~29~36 minecraft:concrete 0
fill ~31~30~22 ~31~30~32 minecraft:concrete 0
setblock ~31~31~22 minecraft:polished_blackstone
fill ~31~32~22 ~31~32~24 minecraft:polished_blackstone_bricks
setblock ~31~34~22 minecraft:polished_blackstone
fill ~31~35~22 ~31~35~23 minecraft:concrete 0
fill ~32~21~22 ~32~23~22 minecraft:stained_hardened_clay 9
fill ~32~24~22 ~33~24~22 minecraft:polished_blackstone
fill ~32~26~22 ~33~26~22 minecraft:polished_blackstone_bricks
setblock ~32~27~22 minecraft:polished_blackstone
fill ~32~28~22 ~32~28~23 minecraft:blackstone
fill ~32~30~22 ~32~30~23 minecraft:polished_blackstone
fill ~32~31~22 ~32~32~23 minecraft:blackstone
fill ~32~33~22 ~32~33~26 minecraft:polished_blackstone
fill ~33~22~22 ~34~22~22 minecraft:polished_blackstone
setblock ~33~25~22 minecraft:blackstone
setblock ~33~27~22 minecraft:blackstone
fill ~33~28~22 ~33~28~23 minecraft:polished_blackstone
fill ~33~29~22 ~34~29~22 minecraft:polished_blackstone
setblock ~33~30~22 minecraft:blackstone
fill ~33~31~22 ~33~31~24 minecraft:polished_blackstone
fill ~33~32~22 ~33~32~23 minecraft:polished_blackstone
fill ~34~23~22 ~35~23~22 minecraft:stained_hardened_clay 9
setblock ~34~24~22 minecraft:blackstone
setblock ~34~25~22 minecraft:polished_blackstone
fill ~34~26~22 ~35~26~22 minecraft:blackstone
fill ~34~27~22 ~34~28~22 minecraft:polished_blackstone_bricks
fill ~35~27~22 ~35~28~22 minecraft:polished_blackstone
setblock ~11~35~23 minecraft:planks 1
fill ~14~41~23 ~14~41~30 minecraft:concrete 0
setblock ~16~32~23 minecraft:stained_glass 1
setblock ~16~33~23 minecraft:stained_glass 14
fill ~17~29~23 ~17~29~24 minecraft:stained_glass 1
fill ~17~44~23 ~18~44~25 minecraft:concrete 0
fill ~18~28~23 ~18~29~23 minecraft:polished_blackstone
setblock ~18~30~23 minecraft:blackstone
setblock ~18~37~23 minecraft:blackstone
fill ~18~45~23 ~18~45~24 minecraft:concrete 0
setblock ~19~19~23 minecraft:polished_blackstone
fill ~19~28~23 ~19~28~24 minecraft:polished_blackstone_bricks
setblock ~19~29~23 minecraft:blackstone
fill ~19~30~23 ~21~30~23 minecraft:polished_blackstone_bricks
setblock ~19~31~23 minecraft:blackstone
setblock ~19~32~23 minecraft:polished_blackstone_bricks
fill ~19~36~23 ~20~36~23 minecraft:blackstone
setblock ~19~37~23 minecraft:polished_blackstone
setblock ~19~43~23 minecraft:concrete 0
setblock ~20~17~23 minecraft:blackstone
fill ~20~19~23 ~20~19~24 minecraft:stained_hardened_clay 9
setblock ~20~21~23 minecraft:netherite_block
setblock ~20~24~23 minecraft:blackstone
fill ~20~25~23 ~20~26~23 minecraft:polished_blackstone
fill ~20~27~23 ~20~28~23 minecraft:blackstone
fill ~20~29~23 ~21~29~23 minecraft:polished_blackstone
setblock ~20~31~23 minecraft:polished_blackstone_bricks
fill ~20~33~23 ~21~33~23 minecraft:polished_blackstone_bricks
fill ~20~34~23 ~21~34~23 minecraft:polished_blackstone
setblock ~20~35~23 minecraft:polished_blackstone_bricks
setblock ~20~37~23 minecraft:polished_blackstone_bricks
setblock ~20~38~23 minecraft:polished_blackstone
fill ~20~39~23 ~20~40~25 minecraft:concrete 0
fill ~20~43~23 ~21~43~23 minecraft:blackstone
setblock ~20~44~23 minecraft:shroomlight
setblock ~20~46~23 minecraft:concrete 0
setblock ~21~16~23 minecraft:polished_blackstone
setblock ~21~18~23 minecraft:blackstone
setblock ~21~19~23 minecraft:polished_blackstone
setblock ~21~22~23 minecraft:polished_blackstone
setblock ~21~23~23 minecraft:polished_blackstone_bricks
fill ~21~25~23 ~21~26~23 minecraft:blackstone
fill ~21~27~23 ~21~28~24 minecraft:polished_blackstone
fill ~21~31~23 ~22~31~23 minecraft:polished_blackstone
fill ~21~32~23 ~22~32~23 minecraft:blackstone
fill ~21~36~23 ~23~36~23 minecraft:polished_blackstone
setblock ~21~37~23 minecraft:polished_blackstone
setblock ~21~38~23 minecraft:blackstone
setblock ~21~44~23 minecraft:blackstone
setblock ~22~16~23 minecraft:polished_blackstone_bricks
setblock ~22~17~23 minecraft:polished_blackstone
fill ~22~19~23 ~22~19~26 minecraft:stained_hardened_clay 9
fill ~22~20~23 ~22~20~25 minecraft:stained_hardened_clay 9
setblock ~22~22~23 minecraft:blackstone
setblock ~22~23~23 minecraft:polished_blackstone
fill ~22~25~23 ~22~26~23 minecraft:polished_blackstone
fill ~22~33~23 ~22~33~24 minecraft:polished_blackstone
fill ~22~34~23 ~23~34~23 minecraft:polished_blackstone_bricks
fill ~22~35~23 ~24~35~23 minecraft:blackstone
setblock ~22~38~23 minecraft:polished_blackstone_bricks
setblock ~23~16~23 minecraft:polished_blackstone
fill ~23~17~23 ~24~17~23 minecraft:blackstone
fill ~23~18~23 ~23~19~23 minecraft:blackstone
fill ~23~20~23 ~25~20~23 minecraft:concrete 0
fill ~23~21~23 ~23~23~23 minecraft:concrete 0
fill ~23~32~23 ~23~32~24 minecraft:polished_blackstone_bricks
fill ~23~33~23 ~24~33~23 minecraft:blackstone
setblock ~23~37~23 minecraft:polished_blackstone
fill ~23~38~23 ~23~38~25 minecraft:concrete 0
fill ~24~16~23 ~25~16~23 minecraft:polished_blackstone_bricks
fill ~24~18~23 ~25~18~23 minecraft:polished_blackstone_bricks
fill ~24~19~23 ~25~19~23 minecraft:polished_blackstone
fill ~24~34~23 ~24~34~26 minecraft:polished_blackstone
setblock ~24~36~23 minecraft:polished_blackstone_bricks
setblock ~24~37~23 minecraft:concrete 0
fill ~25~17~23 ~25~17~24 minecraft:polished_blackstone
fill ~25~21~23 ~25~22~25 minecraft:concrete 0
setblock ~26~17~23 minecraft:blackstone
setblock ~26~18~23 minecraft:polished_blackstone
fill ~26~19~23 ~27~19~23 minecraft:stained_hardened_clay 9
setblock ~26~20~23 minecraft:stained_hardened_clay 9
fill ~26~22~23 ~26~22~27 minecraft:concrete 0
setblock ~26~36~23 minecraft:blackstone
setblock ~26~37~23 minecraft:polished_blackstone
fill ~26~38~23 ~26~39~23 minecraft:blackstone
setblock ~27~20~23 minecraft:polished_blackstone
fill ~27~21~23 ~27~21~24 minecraft:stained_hardened_clay 9
setblock ~27~22~23 minecraft:polished_blackstone
fill ~27~35~23 ~27~35~24 minecraft:polished_blackstone
setblock ~27~36~23 minecraft:polished_blackstone_bricks
fill ~27~37~23 ~28~37~23 minecraft:blackstone
setblock ~27~38~23 minecraft:polished_blackstone_bricks
setblock ~27~39~23 minecraft:blackstone
fill ~28~20~23 ~28~20~29 minecraft:stained_hardened_clay 9
setblock ~28~21~23 minecraft:polished_blackstone
setblock ~28~22~23 minecraft:netherite_block
setblock ~28~34~23 minecraft:polished_blackstone
fill ~28~35~23 ~28~36~24 minecraft:blackstone
setblock ~28~38~23 minecraft:polished_blackstone
setblock ~29~20~23 minecraft:polished_blackstone
fill ~29~21~23 ~29~21~24 minecraft:stained_hardened_clay 9
setblock ~29~22~23 minecraft:stained_hardened_clay 9
fill ~29~35~23 ~29~35~24 minecraft:polished_blackstone_bricks
setblock ~29~36~23 minecraft:polished_blackstone_bricks
fill ~29~37~23 ~29~37~25 minecraft:concrete 0
setblock ~29~38~23 minecraft:concrete 0
setblock ~30~32~23 minecraft:polished_blackstone_bricks
setblock ~30~33~23 minecraft:polished_blackstone
setblock ~30~35~23 minecraft:blackstone
fill ~31~22~23 ~31~22~24 minecraft:polished_blackstone
setblock ~31~31~23 minecraft:polished_blackstone_bricks
setblock ~31~33~23 minecraft:blackstone
fill ~31~34~23 ~31~34~24 minecraft:polished_blackstone_bricks
fill ~32~21~23 ~32~21~24 minecraft:polished_blackstone
fill ~32~22~23 ~32~22~25 minecraft:stained_hardened_clay 9
fill ~32~23~23 ~32~23~24 minecraft:netherite_block
fill ~32~24~23 ~32~27~27 minecraft:concrete 0
fill ~33~21~23 ~33~22~23 minecraft:netherite_block
fill ~33~23~23 ~33~23~24 minecraft:stained_hardened_clay 9
setblock ~33~24~23 minecraft:blackstone
setblock ~33~25~23 minecraft:polished_blackstone_bricks
fill ~33~26~23 ~34~26~23 minecraft:polished_blackstone
setblock ~33~27~23 minecraft:polished_blackstone_bricks
setblock ~33~29~23 minecraft:blackstone
setblock ~33~30~23 minecraft:polished_blackstone
fill ~34~22~23 ~34~22~26 minecraft:stained_hardened_clay 9
setblock ~34~23~23 minecraft:netherite_block
fill ~34~24~23 ~35~24~23 minecraft:stained_hardened_clay 9
setblock ~34~25~23 minecraft:blackstone
fill ~34~27~23 ~34~27~24 minecraft:polished_blackstone
setblock ~34~28~23 minecraft:blackstone
fill ~34~29~23 ~34~29~24 minecraft:polished_blackstone_bricks
setblock ~34~30~23 minecraft:polished_blackstone_bricks
fill ~35~23~23 ~35~23~29 minecraft:stained_hardened_clay 9
setblock ~35~25~23 minecraft:polished_blackstone
fill ~35~26~23 ~35~26~24 minecraft:blackstone
fill ~35~27~23 ~35~28~23 minecraft:polished_blackstone_bricks
fill ~35~29~23 ~35~29~24 minecraft:polished_blackstone
fill ~35~30~23 ~35~30~24 minecraft:concrete 0
fill ~36~24~23 ~36~24~24 minecraft:polished_blackstone
fill ~36~25~23 ~36~25~25 minecraft:stained_hardened_clay 9
fill ~36~26~23 ~36~26~28 minecraft:polished_blackstone_bricks
setblock ~36~27~23 minecraft:blackstone
fill ~36~29~23 ~36~29~24 minecraft:concrete 0
fill ~37~26~23 ~37~28~23 minecraft:concrete 0
setblock ~12~35~24 minecraft:planks 1
fill ~14~40~24 ~14~40~31 minecraft:concrete 0
fill ~15~39~24 ~15~39~29 minecraft:concrete 0
setblock ~16~32~24 minecraft:stained_glass 14
setblock ~16~33~24 minecraft:stained_glass 1
fill ~16~38~24 ~16~38~28 minecraft:concrete 0
fill ~16~43~24 ~18~43~27 minecraft:concrete 0
setblock ~17~30~24 minecraft:stained_glass 1
fill ~17~33~24 ~17~33~25 minecraft:stained_glass 14
setblock ~19~27~24 minecraft:blackstone
setblock ~19~29~24 minecraft:polished_blackstone
setblock ~19~30~24 minecraft:blackstone
fill ~19~31~24 ~20~31~24 minecraft:polished_blackstone
fill ~19~43~24 ~19~44~24 minecraft:shroomlight
setblock ~20~20~24 minecraft:polished_blackstone
fill ~20~24~24 ~20~25~24 minecraft:polished_blackstone_bricks
fill ~20~26~24 ~20~27~25 minecraft:polished_blackstone
fill ~20~28~24 ~20~28~25 minecraft:polished_blackstone_bricks
fill ~20~29~24 ~21~30~24 minecraft:polished_blackstone_bricks
fill ~20~32~24 ~21~32~24 minecraft:polished_blackstone
setblock ~20~37~24 minecraft:blackstone
setblock ~20~38~24 minecraft:polished_blackstone_bricks
fill ~20~45~24 ~21~45~24 minecraft:concrete 0
fill ~21~16~24 ~22~16~24 minecraft:blackstone
fill ~21~17~24 ~22~17~24 minecraft:polished_blackstone_bricks
fill ~21~18~24 ~22~18~24 minecraft:netherite_block
setblock ~21~19~24 minecraft:stained_hardened_clay 9
fill ~21~20~24 ~21~21~24 minecraft:netherite_block
setblock ~21~22~24 minecraft:stained_hardened_clay 9
setblock ~21~23~24 minecraft:blackstone
fill ~21~24~24 ~22~24~24 minecraft:polished_blackstone
fill ~21~25~24 ~22~25~25 minecraft:polished_blackstone_bricks
fill ~21~26~24 ~21~26~25 minecraft:polished_blackstone_bricks
setblock ~21~31~24 minecraft:polished_blackstone_bricks
setblock ~21~33~24 minecraft:polished_blackstone
fill ~21~36~24 ~21~37~24 minecraft:polished_blackstone_bricks
setblock ~21~38~24 minecraft:polished_blackstone
fill ~22~21~24 ~23~21~25 minecraft:stained_hardened_clay 9
fill ~22~22~24 ~22~22~26 minecraft:polished_blackstone
fill ~22~23~24 ~23~23~24 minecraft:stained_hardened_clay 9
fill ~22~26~24 ~23~26~24 minecraft:polished_blackstone
fill ~22~27~24 ~22~27~25 minecraft:polished_blackstone_bricks
setblock ~22~28~24 minecraft:polished_blackstone_bricks
fill ~22~29~24 ~22~29~25 minecraft:blackstone
fill ~22~30~24 ~22~32~24 minecraft:blackstone
fill ~22~34~24 ~23~34~24 minecraft:blackstone
setblock ~22~35~24 minecraft:polished_blackstone_bricks
fill ~22~36~24 ~22~37~24 minecraft:polished_blackstone
setblock ~22~38~24 minecraft:blackstone
setblock ~22~44~24 minecraft:concrete 0
fill ~23~16~24 ~24~16~24 minecraft:polished_blackstone_bricks
fill ~23~17~24 ~23~17~25 minecraft:polished_blackstone
setblock ~23~18~24 minecraft:polished_blackstone_bricks
setblock ~23~19~24 minecraft:polished_blackstone
setblock ~23~20~24 minecraft:stained_hardened_clay 9
fill ~23~22~24 ~23~22~25 minecraft:stained_hardened_clay 9
fill ~23~27~24 ~23~28~24 minecraft:blackstone
setblock ~23~29~24 minecraft:concrete 0
fill ~23~31~24 ~23~31~25 minecraft:polished_blackstone
fill ~23~33~24 ~24~33~24 minecraft:polished_blackstone_bricks
setblock ~23~35~24 minecraft:blackstone
setblock ~23~36~24 minecraft:polished_blackstone_bricks
fill ~23~37~24 ~24~37~24 minecraft:blackstone
fill ~24~17~24 ~24~17~26 minecraft:polished_blackstone_bricks
setblock ~24~18~24 minecraft:blackstone
fill ~24~19~24 ~26~20~24 minecraft:concrete 0
setblock ~24~31~24 minecraft:concrete 0
setblock ~24~35~24 minecraft:polished_blackstone_bricks
fill ~24~36~24 ~25~36~24 minecraft:blackstone
setblock ~25~16~24 minecraft:blackstone
fill ~25~18~24 ~26~18~24 minecraft:polished_blackstone_bricks
fill ~25~35~24 ~25~35~26 minecraft:blackstone
setblock ~25~37~24 minecraft:polished_blackstone
setblock ~26~17~24 minecraft:polished_blackstone_bricks
fill ~26~21~24 ~26~21~26 minecraft:concrete 0
setblock ~26~35~24 minecraft:polished_blackstone_bricks
fill ~26~36~24 ~27~36~24 minecraft:polished_blackstone
fill ~26~37~24 ~27~37~24 minecraft:blackstone
fill ~26~38~24 ~27~38~24 minecraft:polished_blackstone
fill ~27~19~24 ~30~19~24 minecraft:stained_hardened_clay 9
setblock ~27~20~24 minecraft:stained_hardened_clay 9
fill ~27~22~24 ~29~22~27 minecraft:concrete 0
fill ~28~21~24 ~28~21~26 minecraft:netherite_block
setblock ~28~34~24 minecraft:blackstone
fill ~28~37~24 ~28~37~25 minecraft:polished_blackstone_bricks
fill ~28~38~24 ~28~38~25 minecraft:concrete 0
fill ~29~20~24 ~29~20~27 minecraft:stained_hardened_clay 9
fill ~29~33~24 ~29~33~26 minecraft:blackstone
setblock ~29~34~24 minecraft:polished_blackstone_bricks
fill ~29~36~24 ~29~36~25 minecraft:blackstone
fill ~30~21~24 ~30~21~25 minecraft:stained_hardened_clay 9
setblock ~30~22~24 minecraft:stained_hardened_clay 9
setblock ~30~32~24 minecraft:blackstone
fill ~30~33~24 ~31~33~24 minecraft:polished_blackstone_bricks
setblock ~30~34~24 minecraft:blackstone
fill ~30~35~24 ~30~35~25 minecraft:polished_blackstone
setblock ~30~37~24 minecraft:concrete 0
setblock ~31~20~24 minecraft:stained_hardened_clay 9
setblock ~31~21~24 minecraft:netherite_block
setblock ~31~23~24 minecraft:netherite_block
setblock ~31~31~24 minecraft:polished_blackstone
fill ~32~28~24 ~32~28~46 minecraft:concrete 0
fill ~32~29~24 ~33~29~24 minecraft:polished_blackstone
fill ~32~30~24 ~34~30~24 minecraft:blackstone
fill ~32~31~24 ~32~32~24 minecraft:polished_blackstone_bricks
fill ~33~21~24 ~33~21~27 minecraft:stained_hardened_clay 9
fill ~33~22~24 ~33~22~26 minecraft:polished_blackstone
fill ~33~24~24 ~33~25~27 minecraft:concrete 0
fill ~33~26~24 ~33~28~24 minecraft:blackstone
setblock ~33~32~24 minecraft:blackstone
fill ~34~23~24 ~34~23~26 minecraft:stained_hardened_clay 9
setblock ~34~24~24 minecraft:polished_blackstone
fill ~34~25~24 ~34~26~24 minecraft:polished_blackstone_bricks
setblock ~34~28~24 minecraft:polished_blackstone_bricks
fill ~34~31~24 ~34~32~24 minecraft:concrete 0
setblock ~35~22~24 minecraft:polished_blackstone
