fill ~-5 ~-1 ~38 ~-5 ~1 ~38 glass 0  
fill ~-5 ~-1 ~39 ~-5 ~3 ~39 glass 0  
fill ~-5 ~-1 ~40 ~-5 ~5 ~40 glass 0  
fill ~-5 ~-1 ~41 ~-5 ~5 ~41 glass 0  
fill ~-5 ~-1 ~42 ~-5 ~6 ~42 glass 0  
fill ~-5 ~-1 ~43 ~-5 ~6 ~43 glass 0  
fill ~-5 ~-1 ~44 ~-5 ~7 ~44 glass 0  
fill ~-5 ~-1 ~45 ~-5 ~7 ~45 glass 0  
fill ~-5 ~-1 ~46 ~-5 ~7 ~46 glass 0  
fill ~-5 ~-1 ~47 ~-5 ~6 ~47 glass 0  
fill ~-5 ~-1 ~48 ~-5 ~6 ~48 glass 0  
fill ~-5 ~-1 ~49 ~-5 ~5 ~49 glass 0  
fill ~-5 ~-1 ~50 ~-5 ~5 ~50 glass 0  
fill ~-5 ~-1 ~51 ~-5 ~3 ~51 glass 0  
fill ~-5 ~-1 ~52 ~-5 ~1 ~52 glass 0  
fill ~-4 ~-1 ~33 ~-4 ~2 ~33 glass 0  
fill ~-4 ~-1 ~34 ~-4 ~5 ~34 glass 0  
fill ~-4 ~-1 ~35 ~-4 ~7 ~35 glass 0  
fill ~-4 ~-1 ~36 ~-4 ~8 ~36 glass 0  
fill ~-4 ~-1 ~37 ~-4 ~9 ~37 glass 0  
fill ~-4 ~-1 ~53 ~-4 ~9 ~53 glass 0  
fill ~-4 ~-1 ~54 ~-4 ~8 ~54 glass 0  
fill ~-4 ~-1 ~55 ~-4 ~7 ~55 glass 0  
fill ~-4 ~-1 ~56 ~-4 ~5 ~56 glass 0  
fill ~-4 ~-1 ~57 ~-4 ~2 ~57 glass 0  
fill ~-3 ~-1 ~30 ~-3 ~4 ~30 glass 0  
fill ~-3 ~-1 ~31 ~-3 ~7 ~31 glass 0  
fill ~-3 ~-1 ~32 ~-3 ~8 ~32 glass 0  
fill ~-3 ~-1 ~58 ~-3 ~8 ~58 glass 0  
fill ~-3 ~-1 ~59 ~-3 ~7 ~59 glass 0  
fill ~-3 ~-1 ~60 ~-3 ~4 ~60 glass 0  
fill ~-2 ~-1 ~27 ~-2 ~4 ~27 glass 0  
fill ~-2 ~-1 ~28 ~-2 ~7 ~28 glass 0  
fill ~-2 ~-1 ~29 ~-2 ~9 ~29 glass 0  
fill ~-2 ~-1 ~61 ~-2 ~9 ~61 glass 0  
fill ~-2 ~-1 ~62 ~-2 ~7 ~62 glass 0  
fill ~-2 ~-1 ~63 ~-2 ~4 ~63 glass 0  
fill ~-1 ~-1 ~25 ~-1 ~5 ~25 glass 0  
fill ~-1 ~-1 ~26 ~-1 ~8 ~26 glass 0  
fill ~-1 ~-1 ~64 ~-1 ~8 ~64 glass 0  
fill ~-1 ~-1 ~65 ~-1 ~5 ~65 glass 0  
fill ~0 ~-1 ~23 ~0 ~6 ~23 glass 0  
fill ~0 ~-1 ~24 ~0 ~9 ~24 glass 0  
fill ~0 ~-1 ~66 ~0 ~9 ~66 glass 0  
fill ~0 ~-1 ~67 ~0 ~6 ~67 glass 0  
fill ~1 ~-1 ~21 ~1 ~6 ~21 glass 0  
fill ~1 ~-1 ~22 ~1 ~9 ~22 glass 0  
fill ~1 ~-1 ~23 ~89 ~-1 ~23 dirt 0  
fill ~1 ~-1 ~24 ~89 ~-1 ~24 dirt 0  
fill ~1 ~-1 ~25 ~89 ~-1 ~25 dirt 0  
fill ~1 ~-1 ~26 ~89 ~-1 ~26 dirt 0  
fill ~1 ~-1 ~27 ~89 ~-1 ~27 dirt 0  
fill ~1 ~-1 ~28 ~89 ~-1 ~28 dirt 0  
fill ~1 ~-1 ~29 ~89 ~-1 ~29 dirt 0  
fill ~1 ~-1 ~30 ~89 ~-1 ~30 dirt 0  
fill ~1 ~-1 ~31 ~89 ~-1 ~31 dirt 0  
fill ~1 ~-1 ~32 ~89 ~-1 ~32 dirt 0  
fill ~1 ~-1 ~33 ~89 ~-1 ~33 dirt 0  
fill ~1 ~-1 ~34 ~43 ~-1 ~34 dirt 0  
fill ~1 ~-1 ~35 ~43 ~-1 ~35 dirt 0  
fill ~1 ~-1 ~36 ~43 ~-1 ~36 dirt 0  
fill ~1 ~-1 ~37 ~43 ~-1 ~37 dirt 0  
fill ~1 ~-1 ~38 ~89 ~-1 ~38 dirt 0  
fill ~1 ~-1 ~39 ~89 ~-1 ~39 dirt 0  
fill ~1 ~-1 ~40 ~89 ~-1 ~40 dirt 0  
fill ~1 ~-1 ~41 ~89 ~-1 ~41 dirt 0  
fill ~1 ~-1 ~42 ~89 ~-1 ~42 dirt 0  
fill ~1 ~-1 ~43 ~89 ~-1 ~43 dirt 0  
fill ~1 ~-1 ~44 ~89 ~-1 ~44 dirt 0  
fill ~1 ~-1 ~45 ~44 ~-1 ~45 dirt 0  
fill ~1 ~-1 ~46 ~89 ~-1 ~46 dirt 0  
fill ~1 ~-1 ~47 ~89 ~-1 ~47 dirt 0  
fill ~1 ~-1 ~48 ~89 ~-1 ~48 dirt 0  
fill ~1 ~-1 ~49 ~89 ~-1 ~49 dirt 0  
fill ~1 ~-1 ~50 ~89 ~-1 ~50 dirt 0  
fill ~1 ~-1 ~51 ~89 ~-1 ~51 dirt 0  
fill ~1 ~-1 ~52 ~89 ~-1 ~52 dirt 0  
fill ~1 ~-1 ~53 ~89 ~-1 ~53 dirt 0  
fill ~1 ~-1 ~54 ~89 ~-1 ~54 dirt 0  
fill ~1 ~-1 ~55 ~89 ~-1 ~55 dirt 0  
fill ~1 ~-1 ~56 ~89 ~-1 ~56 dirt 0  
fill ~1 ~-1 ~57 ~89 ~-1 ~57 dirt 0  
fill ~1 ~-1 ~58 ~89 ~-1 ~58 dirt 0  
fill ~1 ~-1 ~59 ~89 ~-1 ~59 dirt 0  
fill ~1 ~-1 ~60 ~89 ~-1 ~60 dirt 0  
fill ~1 ~-1 ~61 ~89 ~-1 ~61 dirt 0  
fill ~1 ~-1 ~62 ~89 ~-1 ~62 dirt 0  
fill ~1 ~-1 ~63 ~89 ~-1 ~63 dirt 0  
fill ~1 ~-1 ~64 ~89 ~-1 ~64 dirt 0  
fill ~1 ~-1 ~65 ~89 ~-1 ~65 dirt 0  
fill ~1 ~-1 ~66 ~89 ~-1 ~66 dirt 0  
fill ~1 ~-1 ~67 ~89 ~-1 ~67 dirt 0  
fill ~1 ~-1 ~68 ~1 ~9 ~68 glass 0  
fill ~1 ~-1 ~69 ~1 ~6 ~69 glass 0  
fill ~2 ~-1 ~19 ~2 ~5 ~19 glass 0  
fill ~2 ~-1 ~20 ~2 ~8 ~20 glass 0  
fill ~2 ~-1 ~21 ~88 ~-1 ~21 dirt 0  
fill ~2 ~-1 ~22 ~88 ~-1 ~22 dirt 0  
fill ~2 ~-1 ~68 ~88 ~-1 ~68 dirt 0  
fill ~2 ~-1 ~69 ~88 ~-1 ~69 dirt 0  
fill ~2 ~-1 ~70 ~2 ~8 ~70 glass 0  
fill ~2 ~-1 ~71 ~2 ~5 ~71 glass 0  
fill ~3 ~-1 ~17 ~3 ~1 ~17 glass 0  
fill ~3 ~-1 ~18 ~3 ~7 ~18 glass 0  
fill ~3 ~-1 ~19 ~87 ~-1 ~19 dirt 0  
fill ~3 ~-1 ~20 ~87 ~-1 ~20 dirt 0  
fill ~3 ~-1 ~70 ~87 ~-1 ~70 dirt 0  
fill ~3 ~-1 ~71 ~87 ~-1 ~71 dirt 0  
fill ~3 ~-1 ~72 ~3 ~7 ~72 glass 0  
fill ~3 ~-1 ~73 ~3 ~1 ~73 glass 0  
fill ~4 ~-1 ~16 ~4 ~5 ~16 glass 0  
fill ~4 ~-1 ~17 ~86 ~-1 ~17 dirt 0  
fill ~4 ~-1 ~18 ~86 ~-1 ~18 dirt 0  
fill ~4 ~-1 ~72 ~86 ~-1 ~72 dirt 0  
fill ~4 ~-1 ~73 ~86 ~-1 ~73 dirt 0  
fill ~4 ~-1 ~74 ~4 ~5 ~74 glass 0  
fill ~5 ~-1 ~15 ~5 ~7 ~15 glass 0  
fill ~5 ~-1 ~16 ~85 ~-1 ~16 dirt 0  
fill ~5 ~-1 ~74 ~85 ~-1 ~74 dirt 0  
fill ~5 ~-1 ~75 ~5 ~7 ~75 glass 0  
fill ~6 ~-1 ~13 ~6 ~2 ~13 glass 0  
fill ~6 ~-1 ~14 ~6 ~8 ~14 glass 0  
fill ~6 ~-1 ~15 ~84 ~-1 ~15 dirt 0  
fill ~6 ~-1 ~75 ~84 ~-1 ~75 dirt 0  
fill ~6 ~-1 ~76 ~6 ~8 ~76 glass 0  
fill ~6 ~-1 ~77 ~6 ~2 ~77 glass 0  
fill ~7 ~-1 ~12 ~7 ~4 ~12 glass 0  
fill ~7 ~-1 ~13 ~83 ~-1 ~13 dirt 0  
fill ~7 ~-1 ~14 ~83 ~-1 ~14 dirt 0  
fill ~7 ~-1 ~76 ~83 ~-1 ~76 dirt 0  
fill ~7 ~-1 ~77 ~83 ~-1 ~77 dirt 0  
fill ~7 ~-1 ~78 ~7 ~4 ~78 glass 0  
fill ~8 ~-1 ~11 ~8 ~5 ~11 glass 0  
fill ~8 ~-1 ~12 ~82 ~-1 ~12 dirt 0  
fill ~8 ~-1 ~78 ~82 ~-1 ~78 dirt 0  
fill ~8 ~-1 ~79 ~8 ~5 ~79 glass 0  
fill ~9 ~-1 ~10 ~9 ~5 ~10 glass 0  
fill ~9 ~-1 ~11 ~81 ~-1 ~11 dirt 0  
fill ~9 ~-1 ~79 ~81 ~-1 ~79 dirt 0  
fill ~9 ~-1 ~80 ~9 ~5 ~80 glass 0  
fill ~10 ~-1 ~9 ~10 ~5 ~9 glass 0  
fill ~10 ~-1 ~10 ~80 ~-1 ~10 dirt 0  
fill ~10 ~-1 ~80 ~80 ~-1 ~80 dirt 0  
fill ~10 ~-1 ~81 ~10 ~5 ~81 glass 0  
fill ~11 ~-1 ~8 ~11 ~5 ~8 glass 0  
fill ~11 ~-1 ~9 ~79 ~-1 ~9 dirt 0  
fill ~11 ~-1 ~81 ~79 ~-1 ~81 dirt 0  
fill ~11 ~-1 ~82 ~11 ~5 ~82 glass 0  
fill ~12 ~-1 ~7 ~12 ~4 ~7 glass 0  
fill ~12 ~-1 ~8 ~78 ~-1 ~8 dirt 0  
fill ~12 ~-1 ~82 ~78 ~-1 ~82 dirt 0  
fill ~12 ~-1 ~83 ~12 ~4 ~83 glass 0  
fill ~13 ~-1 ~6 ~14 ~-1 ~6 glass 0 
setblock ~13 ~-1 ~7 grass 0  
fill ~13 ~-1 ~83 ~77 ~-1 ~83 dirt 0  
fill ~13 ~-1 ~84 ~14 ~-1 ~84 glass 0  
fill ~14 ~-1 ~7 ~77 ~-1 ~7 dirt 0  
fill ~15 ~-1 ~5 ~15 ~7 ~5 glass 0  
fill ~15 ~-1 ~6 ~75 ~-1 ~6 dirt 0  
fill ~15 ~-1 ~84 ~75 ~-1 ~84 dirt 0  
fill ~15 ~-1 ~85 ~15 ~7 ~85 glass 0  
fill ~16 ~-1 ~4 ~16 ~5 ~4 glass 0  
fill ~16 ~-1 ~5 ~74 ~-1 ~5 dirt 0  
fill ~16 ~-1 ~85 ~74 ~-1 ~85 dirt 0  
fill ~16 ~-1 ~86 ~16 ~5 ~86 glass 0  
fill ~17 ~-1 ~3 ~18 ~-1 ~3 glass 0  
fill ~17 ~-1 ~4 ~73 ~-1 ~4 dirt 0  
fill ~17 ~-1 ~86 ~73 ~-1 ~86 dirt 0  
fill ~18 ~-1 ~87 ~18 ~7 ~87 glass 0  
fill ~19 ~-1 ~2 ~20 ~-1 ~2 glass 0  
fill ~19 ~-1 ~3 ~71 ~-1 ~3 dirt 0  
fill ~19 ~-1 ~87 ~71 ~-1 ~87 dirt 0  
fill ~19 ~-1 ~88 ~20 ~-1 ~88 glass 0  
fill ~21 ~-1 ~1 ~22 ~-1 ~1 glass 0  
fill ~21 ~-1 ~2 ~69 ~-1 ~2 dirt 0  
fill ~21 ~-1 ~88 ~69 ~-1 ~88 dirt 0  
fill ~21 ~-1 ~89 ~22 ~-1 ~89 glass 0  
fill ~23 ~-1 ~0 ~24 ~-1 ~0 glass 0  
fill ~23 ~-1 ~1 ~67 ~-1 ~1 dirt 0  
fill ~23 ~-1 ~89 ~67 ~-1 ~89 dirt 0  
fill ~23 ~-1 ~90 ~24 ~-1 ~90 glass 0  
fill ~25 ~-1 ~-1 ~26 ~-1 ~-1 glass 0  
fill ~25 ~-1 ~91 ~26 ~-1 ~91 glass 0  
fill ~27 ~-1 ~-2 ~29 ~-1 ~-2 glass 0  
fill ~27 ~-1 ~92 ~29 ~-1 ~92 glass 0  
fill ~30 ~-1 ~-3 ~32 ~-1 ~-3 glass 0  
fill ~30 ~-1 ~93 ~32 ~-1 ~93 glass 0  
fill ~33 ~-1 ~-4 ~37 ~-1 ~-4 glass 0  
fill ~33 ~-1 ~94 ~37 ~-1 ~94 glass 0  
fill ~38 ~-1 ~-5 ~52 ~-1 ~-5 glass 0  
fill ~38 ~-1 ~95 ~52 ~-1 ~95 glass 0  
fill ~44 ~-1 ~34 ~47 ~-1 ~34 cobblestone 0  
fill ~44 ~-1 ~35 ~44 ~3 ~35 cobblestone 0  
fill ~44 ~-1 ~36 ~44 ~3 ~36 cobblestone 0  
fill ~44 ~-1 ~37 ~47 ~-1 ~37 cobblestone 0 
setblock ~45 ~-1 ~45 log 4  
fill ~46 ~-1 ~45 ~89 ~-1 ~45 dirt 0  
fill ~47 ~-1 ~35 ~47 ~3 ~35 cobblestone 0  
fill ~47 ~-1 ~36 ~47 ~3 ~36 cobblestone 0  
fill ~48 ~-1 ~34 ~89 ~-1 ~34 dirt 0  
fill ~48 ~-1 ~35 ~89 ~-1 ~35 dirt 0  
fill ~48 ~-1 ~36 ~89 ~-1 ~36 dirt 0  
fill ~48 ~-1 ~37 ~89 ~-1 ~37 dirt 0  
fill ~53 ~-1 ~-4 ~57 ~-1 ~-4 glass 0  
fill ~53 ~-1 ~94 ~57 ~-1 ~94 glass 0  
fill ~58 ~-1 ~-3 ~60 ~-1 ~-3 glass 0  
fill ~58 ~-1 ~93 ~60 ~-1 ~93 glass 0  
fill ~61 ~-1 ~-2 ~63 ~-1 ~-2 glass 0  
fill ~61 ~-1 ~92 ~63 ~-1 ~92 glass 0  
fill ~64 ~-1 ~-1 ~65 ~-1 ~-1 glass 0  
fill ~64 ~-1 ~91 ~65 ~-1 ~91 glass 0  
fill ~66 ~-1 ~0 ~67 ~-1 ~0 glass 0  
fill ~66 ~-1 ~90 ~67 ~-1 ~90 glass 0  
fill ~68 ~-1 ~1 ~69 ~-1 ~1 glass 0  
fill ~68 ~-1 ~89 ~69 ~-1 ~89 glass 0  
fill ~70 ~-1 ~2 ~71 ~-1 ~2 glass 0  
fill ~70 ~-1 ~88 ~71 ~-1 ~88 glass 0  
fill ~72 ~-1 ~3 ~73 ~-1 ~3 glass 0  
fill ~72 ~-1 ~87 ~73 ~-1 ~87 glass 0  
fill ~74 ~-1 ~4 ~74 ~5 ~4 glass 0  
fill ~74 ~-1 ~86 ~74 ~5 ~86 glass 0  
fill ~75 ~-1 ~5 ~75 ~7 ~5 glass 0  
fill ~75 ~-1 ~85 ~75 ~7 ~85 glass 0  
fill ~76 ~-1 ~6 ~77 ~-1 ~6 glass 0  
fill ~76 ~-1 ~84 ~77 ~-1 ~84 glass 0  
fill ~78 ~-1 ~7 ~78 ~4 ~7 glass 0  
fill ~78 ~-1 ~83 ~78 ~4 ~83 glass 0  
fill ~79 ~-1 ~8 ~79 ~5 ~8 glass 0  
fill ~79 ~-1 ~82 ~79 ~5 ~82 glass 0  
fill ~80 ~-1 ~9 ~80 ~5 ~9 glass 0  
fill ~80 ~-1 ~81 ~80 ~5 ~81 glass 0  
fill ~81 ~-1 ~10 ~81 ~5 ~10 glass 0  
fill ~81 ~-1 ~80 ~81 ~5 ~80 glass 0  
fill ~82 ~-1 ~11 ~82 ~5 ~11 glass 0  
fill ~82 ~-1 ~79 ~82 ~5 ~79 glass 0  
fill ~83 ~-1 ~12 ~83 ~4 ~12 glass 0  
fill ~83 ~-1 ~78 ~83 ~4 ~78 glass 0  
fill ~84 ~-1 ~13 ~84 ~2 ~13 glass 0  
fill ~84 ~-1 ~14 ~84 ~8 ~14 glass 0  
fill ~84 ~-1 ~76 ~84 ~8 ~76 glass 0  
fill ~84 ~-1 ~77 ~84 ~2 ~77 glass 0  
fill ~85 ~-1 ~15 ~85 ~7 ~15 glass 0  
fill ~85 ~-1 ~75 ~85 ~7 ~75 glass 0  
fill ~86 ~-1 ~16 ~86 ~5 ~16 glass 0  
fill ~86 ~-1 ~74 ~86 ~5 ~74 glass 0  
fill ~87 ~-1 ~17 ~87 ~1 ~17 glass 0  
fill ~87 ~-1 ~18 ~87 ~7 ~18 glass 0  
fill ~87 ~-1 ~72 ~87 ~7 ~72 glass 0  
fill ~87 ~-1 ~73 ~87 ~1 ~73 glass 0  
fill ~88 ~-1 ~19 ~88 ~5 ~19 glass 0  
fill ~88 ~-1 ~20 ~88 ~8 ~20 glass 0  
fill ~88 ~-1 ~70 ~88 ~8 ~70 glass 0  
fill ~88 ~-1 ~71 ~88 ~5 ~71 glass 0  
fill ~89 ~-1 ~21 ~89 ~6 ~21 glass 0  
fill ~89 ~-1 ~22 ~89 ~9 ~22 glass 0  
fill ~89 ~-1 ~68 ~89 ~9 ~68 glass 0  
fill ~89 ~-1 ~69 ~89 ~6 ~69 glass 0  
fill ~90 ~-1 ~23 ~90 ~6 ~23 glass 0  
fill ~90 ~-1 ~24 ~90 ~9 ~24 glass 0  
fill ~90 ~-1 ~66 ~90 ~9 ~66 glass 0  
fill ~90 ~-1 ~67 ~90 ~6 ~67 glass 0  
fill ~91 ~-1 ~25 ~91 ~5 ~25 glass 0  
fill ~91 ~-1 ~26 ~91 ~8 ~26 glass 0  
fill ~91 ~-1 ~64 ~91 ~8 ~64 glass 0  
fill ~91 ~-1 ~65 ~91 ~5 ~65 glass 0  
fill ~92 ~-1 ~27 ~92 ~4 ~27 glass 0  
fill ~92 ~-1 ~28 ~92 ~7 ~28 glass 0  
fill ~92 ~-1 ~29 ~92 ~9 ~29 glass 0  
fill ~92 ~-1 ~61 ~92 ~9 ~61 glass 0  
fill ~92 ~-1 ~62 ~92 ~7 ~62 glass 0  
fill ~92 ~-1 ~63 ~92 ~4 ~63 glass 0  
fill ~93 ~-1 ~30 ~93 ~4 ~30 glass 0  
fill ~93 ~-1 ~31 ~93 ~7 ~31 glass 0  
fill ~93 ~-1 ~32 ~93 ~8 ~32 glass 0  
fill ~93 ~-1 ~58 ~93 ~8 ~58 glass 0  
fill ~93 ~-1 ~59 ~93 ~7 ~59 glass 0  
fill ~93 ~-1 ~60 ~93 ~4 ~60 glass 0  
fill ~94 ~-1 ~33 ~94 ~2 ~33 glass 0  
fill ~94 ~-1 ~34 ~94 ~5 ~34 glass 0  
fill ~94 ~-1 ~35 ~94 ~7 ~35 glass 0  
fill ~94 ~-1 ~36 ~94 ~8 ~36 glass 0  
fill ~94 ~-1 ~37 ~94 ~9 ~37 glass 0  
fill ~94 ~-1 ~53 ~94 ~9 ~53 glass 0  
fill ~94 ~-1 ~54 ~94 ~8 ~54 glass 0  
fill ~94 ~-1 ~55 ~94 ~7 ~55 glass 0  
fill ~94 ~-1 ~56 ~94 ~5 ~56 glass 0  
fill ~94 ~-1 ~57 ~94 ~2 ~57 glass 0  
fill ~95 ~-1 ~38 ~95 ~1 ~38 glass 0  
fill ~95 ~-1 ~39 ~95 ~3 ~39 glass 0  
fill ~95 ~-1 ~40 ~95 ~5 ~40 glass 0  
fill ~95 ~-1 ~41 ~95 ~5 ~41 glass 0  
fill ~95 ~-1 ~42 ~95 ~6 ~42 glass 0  
fill ~95 ~-1 ~43 ~95 ~6 ~43 glass 0  
fill ~95 ~-1 ~44 ~95 ~7 ~44 glass 0  
fill ~95 ~-1 ~45 ~95 ~7 ~45 glass 0  
fill ~95 ~-1 ~46 ~95 ~7 ~46 glass 0  
fill ~95 ~-1 ~47 ~95 ~6 ~47 glass 0  
fill ~95 ~-1 ~48 ~95 ~6 ~48 glass 0  
fill ~95 ~-1 ~49 ~95 ~5 ~49 glass 0  
fill ~95 ~-1 ~50 ~95 ~5 ~50 glass 0  
fill ~95 ~-1 ~51 ~95 ~3 ~51 glass 0  
fill ~95 ~-1 ~52 ~95 ~1 ~52 glass 0  
fill ~-4 ~0 ~38 ~0 ~0 ~38 glass 0  
fill ~-4 ~0 ~39 ~0 ~0 ~39 glass 0  
fill ~-4 ~0 ~40 ~0 ~0 ~40 glass 0  
fill ~-4 ~0 ~41 ~0 ~0 ~41 glass 0  
fill ~-4 ~0 ~42 ~0 ~0 ~42 glass 0  
fill ~-4 ~0 ~43 ~0 ~0 ~43 glass 0  
fill ~-4 ~0 ~44 ~0 ~0 ~44 glass 0  
fill ~-4 ~0 ~45 ~0 ~0 ~45 glass 0  
fill ~-4 ~0 ~46 ~0 ~0 ~46 glass 0  
fill ~-4 ~0 ~47 ~0 ~0 ~47 glass 0  
fill ~-4 ~0 ~48 ~0 ~0 ~48 glass 0  
fill ~-4 ~0 ~49 ~0 ~0 ~49 glass 0  
fill ~-4 ~0 ~50 ~0 ~0 ~50 glass 0  
fill ~-4 ~0 ~51 ~0 ~0 ~51 glass 0  
fill ~-4 ~0 ~52 ~0 ~0 ~52 glass 0  
fill ~-3 ~0 ~33 ~0 ~0 ~33 glass 0  
fill ~-3 ~0 ~34 ~0 ~0 ~34 glass 0  
fill ~-3 ~0 ~35 ~0 ~0 ~35 glass 0  
fill ~-3 ~0 ~36 ~0 ~0 ~36 glass 0  
fill ~-3 ~0 ~37 ~0 ~0 ~37 glass 0  
fill ~-3 ~0 ~53 ~0 ~0 ~53 glass 0  
fill ~-3 ~0 ~54 ~0 ~0 ~54 glass 0  
fill ~-3 ~0 ~55 ~0 ~0 ~55 glass 0  
fill ~-3 ~0 ~56 ~0 ~0 ~56 glass 0  
fill ~-3 ~0 ~57 ~0 ~0 ~57 glass 0  
fill ~-2 ~0 ~30 ~0 ~0 ~30 glass 0  
fill ~-2 ~0 ~31 ~0 ~0 ~31 glass 0  
fill ~-2 ~0 ~32 ~0 ~0 ~32 glass 0  
fill ~-2 ~0 ~58 ~0 ~0 ~58 glass 0  
fill ~-2 ~0 ~59 ~0 ~0 ~59 glass 0  
fill ~-2 ~0 ~60 ~0 ~0 ~60 glass 0  
fill ~-1 ~0 ~27 ~0 ~0 ~27 glass 0  
fill ~-1 ~0 ~28 ~0 ~0 ~28 glass 0  
fill ~-1 ~0 ~29 ~0 ~0 ~29 glass 0  
fill ~-1 ~0 ~61 ~0 ~0 ~61 glass 0  
fill ~-1 ~0 ~62 ~0 ~0 ~62 glass 0  
fill ~-1 ~0 ~63 ~0 ~0 ~63 glass 0  
fill ~0 ~0 ~25 ~0 ~0 ~67 glass 0  
fill ~1 ~0 ~23 ~89 ~0 ~23 dirt 0  
fill ~1 ~0 ~24 ~89 ~0 ~24 dirt 0  
fill ~1 ~0 ~25 ~89 ~0 ~25 dirt 0  
fill ~1 ~0 ~26 ~89 ~0 ~26 dirt 0  
fill ~1 ~0 ~27 ~89 ~0 ~27 dirt 0  
fill ~1 ~0 ~28 ~89 ~0 ~28 dirt 0  
fill ~1 ~0 ~29 ~89 ~0 ~29 dirt 0  
fill ~1 ~0 ~30 ~89 ~0 ~30 dirt 0  
fill ~1 ~0 ~31 ~89 ~0 ~31 dirt 0  
fill ~1 ~0 ~32 ~89 ~0 ~32 dirt 0  
fill ~1 ~0 ~33 ~89 ~0 ~33 dirt 0  
fill ~1 ~0 ~34 ~43 ~0 ~34 dirt 0  
fill ~1 ~0 ~35 ~43 ~0 ~35 dirt 0  
fill ~1 ~0 ~36 ~43 ~0 ~36 dirt 0  
fill ~1 ~0 ~37 ~43 ~0 ~37 dirt 0  
fill ~1 ~0 ~38 ~89 ~0 ~38 dirt 0  
fill ~1 ~0 ~39 ~89 ~0 ~39 dirt 0  
fill ~1 ~0 ~40 ~89 ~0 ~40 dirt 0  
fill ~1 ~0 ~41 ~89 ~0 ~41 dirt 0  
fill ~1 ~0 ~42 ~89 ~0 ~42 dirt 0  
fill ~1 ~0 ~43 ~89 ~0 ~43 dirt 0  
fill ~1 ~0 ~44 ~89 ~0 ~44 dirt 0  
fill ~1 ~0 ~45 ~44 ~0 ~45 dirt 0  
fill ~1 ~0 ~46 ~89 ~0 ~46 dirt 0  
fill ~1 ~0 ~47 ~89 ~0 ~47 dirt 0  
fill ~1 ~0 ~48 ~89 ~0 ~48 dirt 0  
fill ~1 ~0 ~49 ~89 ~0 ~49 dirt 0  
fill ~1 ~0 ~50 ~89 ~0 ~50 dirt 0  
fill ~1 ~0 ~51 ~89 ~0 ~51 dirt 0  
fill ~1 ~0 ~52 ~89 ~0 ~52 dirt 0  
fill ~1 ~0 ~53 ~89 ~0 ~53 dirt 0  
fill ~1 ~0 ~54 ~89 ~0 ~54 dirt 0  
fill ~1 ~0 ~55 ~89 ~0 ~55 dirt 0  
fill ~1 ~0 ~56 ~89 ~0 ~56 dirt 0  
fill ~1 ~0 ~57 ~89 ~0 ~57 dirt 0  
fill ~1 ~0 ~58 ~89 ~0 ~58 dirt 0  
fill ~1 ~0 ~59 ~89 ~0 ~59 dirt 0  
fill ~1 ~0 ~60 ~89 ~0 ~60 dirt 0  
fill ~1 ~0 ~61 ~89 ~0 ~61 dirt 0  
fill ~1 ~0 ~62 ~89 ~0 ~62 dirt 0  
fill ~1 ~0 ~63 ~89 ~0 ~63 dirt 0  
fill ~1 ~0 ~64 ~89 ~0 ~64 dirt 0  
fill ~1 ~0 ~65 ~89 ~0 ~65 dirt 0  
fill ~1 ~0 ~66 ~89 ~0 ~66 dirt 0  
fill ~1 ~0 ~67 ~89 ~0 ~67 dirt 0  
fill ~2 ~0 ~21 ~88 ~0 ~21 dirt 0  
fill ~2 ~0 ~22 ~88 ~0 ~22 dirt 0  
fill ~2 ~0 ~68 ~88 ~0 ~68 dirt 0  
fill ~2 ~0 ~69 ~88 ~0 ~69 dirt 0  
fill ~3 ~0 ~19 ~87 ~0 ~19 dirt 0  
fill ~3 ~0 ~20 ~87 ~0 ~20 dirt 0  
fill ~3 ~0 ~70 ~87 ~0 ~70 dirt 0  
fill ~3 ~0 ~71 ~87 ~0 ~71 dirt 0  
fill ~4 ~0 ~17 ~86 ~0 ~17 dirt 0  
fill ~4 ~0 ~18 ~86 ~0 ~18 dirt 0  
fill ~4 ~0 ~72 ~86 ~0 ~72 dirt 0  
fill ~4 ~0 ~73 ~86 ~0 ~73 dirt 0  
fill ~5 ~0 ~16 ~85 ~0 ~16 dirt 0  
fill ~5 ~0 ~74 ~85 ~0 ~74 dirt 0  
fill ~6 ~0 ~15 ~84 ~0 ~15 dirt 0  
fill ~6 ~0 ~75 ~84 ~0 ~75 dirt 0  
fill ~7 ~0 ~13 ~83 ~0 ~13 dirt 0  
fill ~7 ~0 ~14 ~83 ~0 ~14 dirt 0  
fill ~7 ~0 ~76 ~83 ~0 ~76 dirt 0  
fill ~7 ~0 ~77 ~83 ~0 ~77 dirt 0  
fill ~8 ~0 ~12 ~82 ~0 ~12 dirt 0  
fill ~8 ~0 ~78 ~82 ~0 ~78 dirt 0  
fill ~9 ~0 ~11 ~81 ~0 ~11 dirt 0  
fill ~9 ~0 ~79 ~81 ~0 ~79 dirt 0  
fill ~10 ~0 ~10 ~80 ~0 ~10 dirt 0  
fill ~10 ~0 ~80 ~80 ~0 ~80 dirt 0  
fill ~11 ~0 ~9 ~79 ~0 ~9 dirt 0  
fill ~11 ~0 ~81 ~79 ~0 ~81 dirt 0  
fill ~12 ~0 ~8 ~78 ~0 ~8 dirt 0  
fill ~12 ~0 ~82 ~78 ~0 ~82 dirt 0  
fill ~13 ~0 ~6 ~14 ~0 ~6 glass 0  
fill ~13 ~0 ~83 ~77 ~0 ~83 dirt 0  
fill ~13 ~0 ~84 ~14 ~0 ~84 glass 0  
fill ~14 ~0 ~7 ~77 ~0 ~7 dirt 0  
fill ~15 ~0 ~6 ~75 ~0 ~6 dirt 0  
fill ~15 ~0 ~84 ~75 ~0 ~84 dirt 0  
fill ~16 ~0 ~5 ~74 ~0 ~5 dirt 0  
fill ~16 ~0 ~85 ~74 ~0 ~85 dirt 0  
fill ~17 ~0 ~3 ~18 ~0 ~3 glass 0  
fill ~17 ~0 ~4 ~73 ~0 ~4 dirt 0  
fill ~17 ~0 ~86 ~73 ~0 ~86 dirt 0  
fill ~17 ~0 ~87 ~17 ~1 ~87 glass 0  
fill ~19 ~0 ~2 ~20 ~0 ~2 glass 0  
fill ~19 ~0 ~3 ~71 ~0 ~3 dirt 0  
fill ~19 ~0 ~87 ~71 ~0 ~87 dirt 0  
fill ~19 ~0 ~88 ~20 ~0 ~88 glass 0  
fill ~21 ~0 ~1 ~22 ~0 ~1 glass 0  
fill ~21 ~0 ~2 ~69 ~0 ~2 dirt 0  
fill ~21 ~0 ~88 ~69 ~0 ~88 dirt 0  
fill ~21 ~0 ~89 ~22 ~0 ~89 glass 0  
fill ~23 ~0 ~0 ~67 ~0 ~0 glass 0  
fill ~23 ~0 ~1 ~67 ~0 ~1 dirt 0  
fill ~23 ~0 ~89 ~67 ~0 ~89 dirt 0  
fill ~23 ~0 ~90 ~67 ~0 ~90 glass 0  
fill ~25 ~0 ~-1 ~65 ~0 ~-1 glass 0  
fill ~25 ~0 ~91 ~65 ~0 ~91 glass 0  
fill ~27 ~0 ~-2 ~63 ~0 ~-2 glass 0  
fill ~27 ~0 ~92 ~63 ~0 ~92 glass 0  
fill ~30 ~0 ~-3 ~60 ~0 ~-3 glass 0  
fill ~30 ~0 ~93 ~60 ~0 ~93 glass 0  
fill ~33 ~0 ~-4 ~57 ~0 ~-4 glass 0  
fill ~33 ~0 ~94 ~57 ~0 ~94 glass 0  
fill ~38 ~0 ~-5 ~52 ~0 ~-5 glass 0  
fill ~38 ~0 ~95 ~52 ~0 ~95 glass 0  
fill ~44 ~0 ~34 ~47 ~0 ~34 cobblestone 0  
fill ~44 ~0 ~37 ~47 ~0 ~37 cobblestone 0  
fill ~45 ~0 ~45 ~45 ~1 ~45 log 0  
fill ~46 ~0 ~45 ~89 ~0 ~45 dirt 0  
fill ~48 ~0 ~34 ~89 ~0 ~34 dirt 0  
fill ~48 ~0 ~35 ~89 ~0 ~35 dirt 0  
fill ~48 ~0 ~36 ~89 ~0 ~36 dirt 0  
fill ~48 ~0 ~37 ~89 ~0 ~37 dirt 0  
fill ~68 ~0 ~1 ~69 ~0 ~1 glass 0  
fill ~68 ~0 ~89 ~69 ~0 ~89 glass 0  
fill ~70 ~0 ~2 ~71 ~0 ~2 glass 0  
fill ~70 ~0 ~88 ~71 ~0 ~88 glass 0  
fill ~72 ~0 ~3 ~73 ~0 ~3 glass 0  
fill ~72 ~0 ~87 ~73 ~0 ~87 glass 0  
fill ~76 ~0 ~6 ~77 ~0 ~6 glass 0  
fill ~76 ~0 ~84 ~77 ~0 ~84 glass 0  
fill ~90 ~0 ~25 ~90 ~0 ~67 glass 0  
fill ~91 ~0 ~27 ~91 ~0 ~65 glass 0  
fill ~92 ~0 ~30 ~92 ~0 ~63 glass 0  
fill ~93 ~0 ~33 ~93 ~0 ~60 glass 0  
fill ~94 ~0 ~38 ~94 ~0 ~57 glass 0  
fill ~-4 ~1 ~38 ~14 ~1 ~38 grass 0  
fill ~-4 ~1 ~39 ~14 ~1 ~39 grass 0  
fill ~-4 ~1 ~40 ~14 ~1 ~40 grass 0  
fill ~-4 ~1 ~41 ~14 ~1 ~41 grass 0  
fill ~-4 ~1 ~42 ~32 ~1 ~42 grass 0  
fill ~-4 ~1 ~43 ~15 ~1 ~43 grass 0  
fill ~-4 ~1 ~44 ~15 ~1 ~44 grass 0  
fill ~-4 ~1 ~45 ~15 ~1 ~45 grass 0  
fill ~-4 ~1 ~46 ~15 ~1 ~46 grass 0  
fill ~-4 ~1 ~47 ~15 ~1 ~47 grass 0  
fill ~-4 ~1 ~48 ~15 ~1 ~48 grass 0  
fill ~-4 ~1 ~49 ~15 ~1 ~49 grass 0  
fill ~-4 ~1 ~50 ~15 ~1 ~50 grass 0  
fill ~-4 ~1 ~51 ~15 ~1 ~51 grass 0  
fill ~-4 ~1 ~52 ~15 ~1 ~52 grass 0  
fill ~-3 ~1 ~33 ~18 ~1 ~33 grass 0  
fill ~-3 ~1 ~34 ~14 ~1 ~34 grass 0  
fill ~-3 ~1 ~35 ~14 ~1 ~35 grass 0  
fill ~-3 ~1 ~36 ~14 ~1 ~36 grass 0  
fill ~-3 ~1 ~37 ~14 ~1 ~37 grass 0  
fill ~-3 ~1 ~53 ~15 ~1 ~53 grass 0  
fill ~-3 ~1 ~54 ~15 ~1 ~54 grass 0  
fill ~-3 ~1 ~55 ~15 ~1 ~55 grass 0  
fill ~-3 ~1 ~56 ~15 ~1 ~56 grass 0  
fill ~-3 ~1 ~57 ~15 ~1 ~57 grass 0  
fill ~-2 ~1 ~30 ~18 ~1 ~30 grass 0  
fill ~-2 ~1 ~31 ~18 ~1 ~31 grass 0  
fill ~-2 ~1 ~32 ~18 ~1 ~32 grass 0  
fill ~-2 ~1 ~58 ~15 ~1 ~58 grass 0  
fill ~-2 ~1 ~59 ~15 ~1 ~59 grass 0  
fill ~-2 ~1 ~60 ~15 ~1 ~60 grass 0  
fill ~-1 ~1 ~27 ~18 ~1 ~27 grass 0  
fill ~-1 ~1 ~28 ~18 ~1 ~28 grass 0  
fill ~-1 ~1 ~29 ~18 ~1 ~29 grass 0  
fill ~-1 ~1 ~61 ~15 ~1 ~61 grass 0  
fill ~-1 ~1 ~62 ~15 ~1 ~62 grass 0  
fill ~-1 ~1 ~63 ~15 ~1 ~63 grass 0  
fill ~0 ~1 ~25 ~18 ~1 ~25 grass 0  
fill ~0 ~1 ~26 ~18 ~1 ~26 grass 0  
fill ~0 ~1 ~64 ~15 ~1 ~64 grass 0  
fill ~0 ~1 ~65 ~15 ~1 ~65 grass 0  
fill ~1 ~1 ~23 ~34 ~1 ~23 grass 0  
fill ~1 ~1 ~24 ~34 ~1 ~24 grass 0  
fill ~1 ~1 ~66 ~15 ~1 ~66 grass 0  
fill ~1 ~1 ~67 ~15 ~1 ~67 grass 0  
fill ~2 ~1 ~21 ~34 ~1 ~21 grass 0  
fill ~2 ~1 ~22 ~34 ~1 ~22 grass 0  
fill ~2 ~1 ~68 ~15 ~1 ~68 grass 0  
fill ~2 ~1 ~69 ~15 ~1 ~69 grass 0  
fill ~3 ~1 ~19 ~34 ~1 ~19 grass 0  
fill ~3 ~1 ~20 ~34 ~1 ~20 grass 0  
fill ~3 ~1 ~70 ~15 ~1 ~70 grass 0  
fill ~3 ~1 ~71 ~15 ~1 ~71 grass 0  
fill ~4 ~1 ~17 ~34 ~1 ~17 grass 0  
fill ~4 ~1 ~18 ~34 ~1 ~18 grass 0  
fill ~4 ~1 ~72 ~15 ~1 ~72 grass 0  
fill ~4 ~1 ~73 ~15 ~1 ~73 grass 0  
fill ~5 ~1 ~16 ~34 ~1 ~16 grass 0  
fill ~5 ~1 ~74 ~15 ~1 ~74 grass 0  
fill ~6 ~1 ~15 ~34 ~1 ~15 grass 0  
fill ~6 ~1 ~75 ~15 ~1 ~75 grass 0  
fill ~7 ~1 ~13 ~34 ~1 ~13 grass 0  
fill ~7 ~1 ~14 ~34 ~1 ~14 grass 0  
fill ~7 ~1 ~76 ~15 ~1 ~76 grass 0  
fill ~7 ~1 ~77 ~15 ~1 ~77 grass 0  
fill ~8 ~1 ~12 ~43 ~1 ~12 grass 0  
fill ~8 ~1 ~78 ~15 ~1 ~78 grass 0  
fill ~9 ~1 ~11 ~64 ~1 ~11 grass 0  
fill ~9 ~1 ~79 ~15 ~1 ~79 grass 0  
fill ~10 ~1 ~10 ~64 ~1 ~10 grass 0  
fill ~10 ~1 ~80 ~15 ~1 ~80 grass 0  
fill ~11 ~1 ~9 ~64 ~1 ~9 grass 0  
fill ~11 ~1 ~81 ~17 ~1 ~81 grass 0  
fill ~12 ~1 ~8 ~64 ~1 ~8 grass 0  
fill ~12 ~1 ~82 ~17 ~1 ~82 grass 0  
fill ~13 ~1 ~6 ~14 ~1 ~6 glass 0  
fill ~13 ~1 ~83 ~17 ~1 ~83 grass 0  
fill ~13 ~1 ~84 ~14 ~1 ~84 glass 0  
fill ~14 ~1 ~7 ~64 ~1 ~7 grass 0  
fill ~15 ~1 ~6 ~64 ~1 ~6 grass 0  
fill ~15 ~1 ~34 ~42 ~1 ~34 gravel 0  
fill ~15 ~1 ~35 ~42 ~1 ~35 gravel 0  
fill ~15 ~1 ~36 ~42 ~1 ~36 gravel 0  
fill ~15 ~1 ~37 ~19 ~1 ~37 dirt 0  
fill ~15 ~1 ~38 ~19 ~1 ~38 dirt 0  
fill ~15 ~1 ~39 ~19 ~1 ~39 dirt 0  
fill ~15 ~1 ~40 ~19 ~1 ~40 dirt 0  
fill ~15 ~1 ~41 ~19 ~1 ~41 dirt 0  
fill ~15 ~1 ~84 ~17 ~1 ~84 grass 0  
fill ~16 ~1 ~5 ~64 ~1 ~5 grass 0  
fill ~16 ~1 ~43 ~18 ~1 ~43 gravel 0  
fill ~16 ~1 ~44 ~18 ~1 ~44 gravel 0  
fill ~16 ~1 ~45 ~18 ~1 ~45 gravel 0  
fill ~16 ~1 ~46 ~18 ~1 ~46 gravel 0  
fill ~16 ~1 ~47 ~18 ~1 ~47 gravel 0  
fill ~16 ~1 ~48 ~18 ~1 ~48 gravel 0  
fill ~16 ~1 ~49 ~18 ~1 ~49 gravel 0  
fill ~16 ~1 ~50 ~18 ~1 ~50 gravel 0  
fill ~16 ~1 ~51 ~18 ~1 ~51 gravel 0  
fill ~16 ~1 ~52 ~18 ~1 ~52 gravel 0  
fill ~16 ~1 ~53 ~18 ~1 ~53 gravel 0  
fill ~16 ~1 ~54 ~18 ~1 ~54 gravel 0  
fill ~16 ~1 ~55 ~18 ~1 ~55 gravel 0  
fill ~16 ~1 ~56 ~18 ~1 ~56 gravel 0  
fill ~16 ~1 ~57 ~18 ~1 ~57 gravel 0  
fill ~16 ~1 ~58 ~18 ~1 ~58 gravel 0  
fill ~16 ~1 ~59 ~18 ~1 ~59 gravel 0  
fill ~16 ~1 ~60 ~18 ~1 ~60 gravel 0  
fill ~16 ~1 ~61 ~18 ~1 ~61 gravel 0  
fill ~16 ~1 ~62 ~18 ~1 ~62 gravel 0  
fill ~16 ~1 ~63 ~18 ~1 ~63 gravel 0  
fill ~16 ~1 ~64 ~18 ~1 ~64 gravel 0  
fill ~16 ~1 ~65 ~18 ~1 ~65 gravel 0  
fill ~16 ~1 ~66 ~18 ~1 ~66 gravel 0  
fill ~16 ~1 ~67 ~18 ~1 ~67 gravel 0  
fill ~16 ~1 ~68 ~18 ~1 ~68 gravel 0  
fill ~16 ~1 ~69 ~18 ~1 ~69 gravel 0  
fill ~16 ~1 ~70 ~18 ~1 ~70 gravel 0  
fill ~16 ~1 ~71 ~81 ~1 ~71 gravel 0  
fill ~16 ~1 ~72 ~81 ~1 ~72 gravel 0  
fill ~16 ~1 ~73 ~81 ~1 ~73 gravel 0  
fill ~16 ~1 ~74 ~16 ~1 ~80 gravel 0  
fill ~16 ~1 ~85 ~74 ~1 ~85 grass 0  
fill ~17 ~1 ~3 ~18 ~1 ~3 glass 0  
fill ~17 ~1 ~4 ~64 ~1 ~4 grass 0  
fill ~17 ~1 ~74 ~24 ~1 ~74 dirt 0  
fill ~17 ~1 ~75 ~24 ~1 ~75 dirt 0  
fill ~17 ~1 ~76 ~24 ~1 ~76 dirt 0  
fill ~17 ~1 ~77 ~24 ~1 ~77 dirt 0  
fill ~17 ~1 ~78 ~24 ~1 ~78 dirt 0  
fill ~17 ~1 ~79 ~24 ~1 ~79 dirt 0 
setblock ~17 ~1 ~80 grass 0  
fill ~17 ~1 ~86 ~73 ~1 ~86 grass 0  
fill ~18 ~1 ~80 ~24 ~1 ~80 dirt 0  
fill ~18 ~1 ~81 ~24 ~1 ~81 dirt 0  
fill ~18 ~1 ~82 ~24 ~1 ~82 dirt 0  
fill ~18 ~1 ~83 ~24 ~1 ~83 dirt 0  
fill ~18 ~1 ~84 ~24 ~1 ~84 dirt 0  
fill ~19 ~1 ~2 ~20 ~1 ~2 glass 0  
fill ~19 ~1 ~3 ~64 ~1 ~3 grass 0  
fill ~19 ~1 ~25 ~25 ~1 ~25 dirt 0  
fill ~19 ~1 ~26 ~19 ~1 ~33 dirt 0  
fill ~19 ~1 ~43 ~32 ~1 ~43 grass 0  
fill ~19 ~1 ~44 ~32 ~1 ~44 grass 0  
fill ~19 ~1 ~45 ~32 ~1 ~45 grass 0  
fill ~19 ~1 ~46 ~32 ~1 ~46 grass 0  
fill ~19 ~1 ~47 ~32 ~1 ~47 grass 0  
fill ~19 ~1 ~48 ~43 ~1 ~48 grass 0  
fill ~19 ~1 ~49 ~43 ~1 ~49 grass 0  
fill ~19 ~1 ~50 ~43 ~1 ~50 grass 0  
fill ~19 ~1 ~51 ~43 ~1 ~51 grass 0  
fill ~19 ~1 ~52 ~43 ~1 ~52 grass 0  
fill ~19 ~1 ~53 ~43 ~1 ~53 grass 0  
fill ~19 ~1 ~54 ~43 ~1 ~54 grass 0  
fill ~19 ~1 ~55 ~34 ~1 ~55 grass 0  
fill ~19 ~1 ~56 ~34 ~1 ~56 grass 0  
fill ~19 ~1 ~57 ~34 ~1 ~57 grass 0  
fill ~19 ~1 ~58 ~34 ~1 ~58 grass 0  
fill ~19 ~1 ~59 ~34 ~1 ~59 grass 0  
fill ~19 ~1 ~60 ~34 ~1 ~60 grass 0  
fill ~19 ~1 ~61 ~34 ~1 ~61 grass 0  
fill ~19 ~1 ~62 ~43 ~1 ~62 grass 0  
fill ~19 ~1 ~63 ~43 ~1 ~63 grass 0  
fill ~19 ~1 ~64 ~43 ~1 ~64 grass 0  
fill ~19 ~1 ~65 ~43 ~1 ~65 grass 0  
fill ~19 ~1 ~66 ~19 ~1 ~70 grass 0  
fill ~19 ~1 ~87 ~71 ~1 ~87 grass 0  
fill ~19 ~1 ~88 ~20 ~1 ~88 glass 0  
fill ~20 ~1 ~26 ~21 ~1 ~26 grass 0  
fill ~20 ~1 ~27 ~21 ~1 ~27 grass 0  
fill ~20 ~1 ~28 ~21 ~1 ~28 grass 0  
fill ~20 ~1 ~29 ~21 ~1 ~29 grass 0  
fill ~20 ~1 ~30 ~21 ~1 ~30 grass 0  
fill ~20 ~1 ~31 ~21 ~1 ~31 grass 0  
fill ~20 ~1 ~32 ~21 ~1 ~32 grass 0  
fill ~20 ~1 ~33 ~25 ~1 ~33 dirt 0  
fill ~20 ~1 ~37 ~22 ~1 ~37 grass 0  
fill ~20 ~1 ~38 ~22 ~1 ~38 grass 0  
fill ~20 ~1 ~39 ~22 ~1 ~39 grass 0  
fill ~20 ~1 ~40 ~22 ~1 ~40 grass 0  
fill ~20 ~1 ~41 ~22 ~1 ~41 grass 0  
fill ~20 ~1 ~66 ~23 ~1 ~66 dirt 0  
fill ~20 ~1 ~67 ~23 ~1 ~67 dirt 0  
fill ~20 ~1 ~68 ~23 ~1 ~68 dirt 0  
fill ~20 ~1 ~69 ~23 ~1 ~69 dirt 0  
fill ~20 ~1 ~70 ~23 ~1 ~70 dirt 0  
fill ~21 ~1 ~1 ~22 ~1 ~1 glass 0  
fill ~21 ~1 ~2 ~64 ~1 ~2 grass 0  
fill ~21 ~1 ~88 ~69 ~1 ~88 grass 0  
fill ~21 ~1 ~89 ~22 ~1 ~89 glass 0  
fill ~22 ~1 ~26 ~22 ~1 ~33 dirt 0  
fill ~23 ~1 ~0 ~24 ~1 ~0 glass 0  
fill ~23 ~1 ~1 ~64 ~1 ~1 grass 0  
fill ~23 ~1 ~26 ~24 ~1 ~26 grass 0  
fill ~23 ~1 ~27 ~24 ~1 ~27 grass 0  
fill ~23 ~1 ~28 ~24 ~1 ~28 grass 0  
fill ~23 ~1 ~29 ~24 ~1 ~29 grass 0  
fill ~23 ~1 ~30 ~24 ~1 ~30 grass 0  
fill ~23 ~1 ~31 ~24 ~1 ~31 grass 0  
fill ~23 ~1 ~32 ~24 ~1 ~32 grass 0  
fill ~23 ~1 ~37 ~26 ~1 ~37 dirt 0  
fill ~23 ~1 ~38 ~26 ~1 ~38 dirt 0  
fill ~23 ~1 ~39 ~26 ~1 ~39 dirt 0  
fill ~23 ~1 ~40 ~26 ~1 ~40 dirt 0  
fill ~23 ~1 ~41 ~26 ~1 ~41 dirt 0  
fill ~23 ~1 ~89 ~67 ~1 ~89 grass 0  
fill ~23 ~1 ~90 ~24 ~1 ~90 glass 0  
fill ~24 ~1 ~66 ~43 ~1 ~66 grass 0  
fill ~24 ~1 ~67 ~43 ~1 ~67 grass 0  
fill ~24 ~1 ~68 ~43 ~1 ~68 grass 0  
fill ~24 ~1 ~69 ~43 ~1 ~69 grass 0  
fill ~24 ~1 ~70 ~43 ~1 ~70 grass 0  
fill ~25 ~1 ~-1 ~26 ~1 ~-1 glass 0  
fill ~25 ~1 ~0 ~65 ~1 ~0 grass 0  
fill ~25 ~1 ~26 ~25 ~1 ~33 dirt 0  
fill ~25 ~1 ~74 ~29 ~1 ~74 grass 0  
fill ~25 ~1 ~75 ~29 ~1 ~75 grass 0  
fill ~25 ~1 ~76 ~29 ~1 ~76 grass 0  
fill ~25 ~1 ~77 ~29 ~1 ~77 grass 0  
fill ~25 ~1 ~78 ~29 ~1 ~78 grass 0  
fill ~25 ~1 ~79 ~29 ~1 ~79 grass 0  
fill ~25 ~1 ~80 ~29 ~1 ~80 grass 0  
fill ~25 ~1 ~81 ~29 ~1 ~81 grass 0  
fill ~25 ~1 ~82 ~29 ~1 ~82 grass 0  
fill ~25 ~1 ~83 ~61 ~1 ~83 grass 0  
fill ~25 ~1 ~84 ~61 ~1 ~84 grass 0  
fill ~25 ~1 ~91 ~26 ~1 ~91 glass 0  
fill ~26 ~1 ~25 ~34 ~1 ~25 grass 0  
fill ~26 ~1 ~26 ~43 ~1 ~26 grass 0  
fill ~26 ~1 ~27 ~39 ~1 ~27 grass 0  
fill ~26 ~1 ~28 ~39 ~1 ~28 grass 0  
fill ~26 ~1 ~29 ~33 ~1 ~29 grass 0  
fill ~26 ~1 ~30 ~33 ~1 ~30 grass 0  
fill ~26 ~1 ~31 ~33 ~1 ~31 grass 0  
fill ~26 ~1 ~32 ~33 ~1 ~32 grass 0  
fill ~26 ~1 ~33 ~33 ~1 ~33 grass 0  
fill ~26 ~1 ~90 ~65 ~1 ~90 grass 0  
fill ~27 ~1 ~-2 ~29 ~1 ~-2 glass 0  
fill ~27 ~1 ~-1 ~63 ~1 ~-1 grass 0  
fill ~27 ~1 ~37 ~42 ~1 ~37 grass 0  
fill ~27 ~1 ~38 ~42 ~1 ~38 grass 0  
fill ~27 ~1 ~39 ~37 ~1 ~39 grass 0  
fill ~27 ~1 ~40 ~37 ~1 ~40 grass 0  
fill ~27 ~1 ~41 ~32 ~1 ~41 grass 0  
fill ~27 ~1 ~91 ~63 ~1 ~91 grass 0  
fill ~27 ~1 ~92 ~29 ~1 ~92 glass 0  
fill ~30 ~1 ~-3 ~32 ~1 ~-3 glass 0  
fill ~30 ~1 ~-2 ~60 ~1 ~-2 grass 0  
fill ~30 ~1 ~74 ~42 ~1 ~74 dirt 0  
fill ~30 ~1 ~75 ~30 ~1 ~82 dirt 0  
fill ~30 ~1 ~92 ~60 ~1 ~92 grass 0  
fill ~30 ~1 ~93 ~32 ~1 ~93 glass 0  
fill ~31 ~1 ~75 ~32 ~1 ~75 grass 0  
fill ~31 ~1 ~76 ~32 ~1 ~76 grass 0  
fill ~31 ~1 ~77 ~32 ~1 ~77 grass 0  
fill ~31 ~1 ~78 ~32 ~1 ~78 grass 0  
fill ~31 ~1 ~79 ~32 ~1 ~79 grass 0  
fill ~31 ~1 ~80 ~32 ~1 ~80 grass 0  
fill ~31 ~1 ~81 ~32 ~1 ~81 grass 0  
fill ~31 ~1 ~82 ~42 ~1 ~82 dirt 0  
fill ~33 ~1 ~-4 ~37 ~1 ~-4 glass 0  
fill ~33 ~1 ~-3 ~57 ~1 ~-3 grass 0  
fill ~33 ~1 ~41 ~43 ~1 ~41 dirt 0  
fill ~33 ~1 ~42 ~43 ~1 ~42 dirt 0  
fill ~33 ~1 ~43 ~43 ~1 ~43 dirt 0  
fill ~33 ~1 ~44 ~39 ~1 ~44 dirt 0  
fill ~33 ~1 ~45 ~39 ~1 ~45 dirt 0  
fill ~33 ~1 ~46 ~39 ~1 ~46 dirt 0  
fill ~33 ~1 ~47 ~43 ~1 ~47 dirt 0  
fill ~33 ~1 ~75 ~33 ~1 ~82 dirt 0  
fill ~33 ~1 ~93 ~57 ~1 ~93 grass 0  
fill ~33 ~1 ~94 ~37 ~1 ~94 glass 0  
fill ~34 ~1 ~29 ~37 ~1 ~29 dirt 0  
fill ~34 ~1 ~30 ~37 ~1 ~30 dirt 0  
fill ~34 ~1 ~31 ~37 ~1 ~31 dirt 0  
fill ~34 ~1 ~32 ~37 ~1 ~32 dirt 0  
fill ~34 ~1 ~33 ~37 ~1 ~33 dirt 0  
fill ~34 ~1 ~75 ~35 ~1 ~75 grass 0  
fill ~34 ~1 ~76 ~35 ~1 ~76 grass 0  
fill ~34 ~1 ~77 ~35 ~1 ~77 grass 0  
fill ~34 ~1 ~78 ~35 ~1 ~78 grass 0  
fill ~34 ~1 ~79 ~35 ~1 ~79 grass 0  
fill ~34 ~1 ~80 ~35 ~1 ~80 grass 0  
fill ~34 ~1 ~81 ~35 ~1 ~81 grass 0  
fill ~35 ~1 ~13 ~43 ~1 ~13 dirt 0  
fill ~35 ~1 ~14 ~35 ~1 ~25 dirt 0  
fill ~35 ~1 ~55 ~43 ~1 ~55 dirt 0  
fill ~35 ~1 ~56 ~35 ~1 ~61 dirt 0  
fill ~36 ~1 ~14 ~42 ~1 ~14 grass 0  
fill ~36 ~1 ~15 ~42 ~1 ~15 grass 0  
fill ~36 ~1 ~16 ~43 ~1 ~16 dirt 0  
fill ~36 ~1 ~17 ~42 ~1 ~17 grass 0  
fill ~36 ~1 ~18 ~42 ~1 ~18 grass 0  
fill ~36 ~1 ~19 ~43 ~1 ~19 dirt 0  
fill ~36 ~1 ~20 ~42 ~1 ~20 grass 0  
fill ~36 ~1 ~21 ~42 ~1 ~21 grass 0  
fill ~36 ~1 ~22 ~43 ~1 ~22 dirt 0  
fill ~36 ~1 ~23 ~42 ~1 ~23 grass 0  
fill ~36 ~1 ~24 ~42 ~1 ~24 grass 0  
fill ~36 ~1 ~25 ~43 ~1 ~25 dirt 0  
fill ~36 ~1 ~56 ~42 ~1 ~56 grass 0  
fill ~36 ~1 ~57 ~42 ~1 ~57 grass 0  
fill ~36 ~1 ~58 ~43 ~1 ~58 dirt 0  
fill ~36 ~1 ~59 ~42 ~1 ~59 grass 0  
fill ~36 ~1 ~60 ~42 ~1 ~60 grass 0  
fill ~36 ~1 ~61 ~43 ~1 ~61 dirt 0  
fill ~36 ~1 ~75 ~36 ~1 ~82 dirt 0  
fill ~37 ~1 ~75 ~38 ~1 ~75 grass 0  
fill ~37 ~1 ~76 ~38 ~1 ~76 grass 0  
fill ~37 ~1 ~77 ~38 ~1 ~77 grass 0  
fill ~37 ~1 ~78 ~38 ~1 ~78 grass 0  
fill ~37 ~1 ~79 ~38 ~1 ~79 grass 0  
fill ~37 ~1 ~80 ~38 ~1 ~80 grass 0  
fill ~37 ~1 ~81 ~38 ~1 ~81 grass 0  
fill ~38 ~1 ~-5 ~52 ~1 ~-5 glass 0  
fill ~38 ~1 ~-4 ~52 ~1 ~-4 grass 0  
fill ~38 ~1 ~29 ~39 ~1 ~29 grass 0  
fill ~38 ~1 ~30 ~39 ~1 ~30 grass 0  
fill ~38 ~1 ~31 ~39 ~1 ~31 grass 0  
fill ~38 ~1 ~32 ~39 ~1 ~32 grass 0  
fill ~38 ~1 ~33 ~38 ~1 ~26 grass 0  
fill ~38 ~1 ~39 ~43 ~1 ~39 dirt 0  
fill ~38 ~1 ~40 ~43 ~1 ~40 dirt 0  
fill ~38 ~1 ~94 ~52 ~1 ~94 grass 0  
fill ~38 ~1 ~95 ~52 ~1 ~95 glass 0  
fill ~39 ~1 ~33 ~42 ~1 ~33 gravel 0  
fill ~39 ~1 ~75 ~39 ~1 ~82 dirt 0  
fill ~40 ~1 ~27 ~46 ~1 ~27 gravel 0  
fill ~40 ~1 ~28 ~41 ~1 ~28 gravel 0  
fill ~40 ~1 ~29 ~40 ~1 ~36 gravel 0  
fill ~40 ~1 ~44 ~42 ~1 ~44 grass 0  
fill ~40 ~1 ~45 ~40 ~1 ~46 grass 0  
fill ~40 ~1 ~75 ~41 ~1 ~75 grass 0  
fill ~40 ~1 ~76 ~41 ~1 ~76 grass 0  
fill ~40 ~1 ~77 ~41 ~1 ~77 grass 0  
fill ~40 ~1 ~78 ~41 ~1 ~78 grass 0  
fill ~40 ~1 ~79 ~41 ~1 ~79 grass 0  
fill ~40 ~1 ~80 ~41 ~1 ~80 grass 0  
fill ~40 ~1 ~81 ~41 ~1 ~81 grass 0 
setblock ~41 ~1 ~29 glowstone 0  
fill ~41 ~1 ~30 ~41 ~1 ~36 gravel 0  
fill ~41 ~1 ~45 ~43 ~1 ~45 dirt 0  
fill ~41 ~1 ~46 ~42 ~1 ~46 grass 0 
setblock ~42 ~1 ~28 glowstone 0 
setblock ~42 ~1 ~29 gravel 0 
setblock ~42 ~1 ~30 glowstone 0  
fill ~42 ~1 ~31 ~47 ~1 ~31 gravel 0  
fill ~42 ~1 ~32 ~49 ~1 ~32 gravel 0  
fill ~42 ~1 ~75 ~42 ~1 ~82 dirt 0  
fill ~43 ~1 ~14 ~43 ~1 ~25 dirt 0  
fill ~43 ~1 ~28 ~46 ~1 ~28 gravel 0 
setblock ~43 ~1 ~29 glowstone 0  
fill ~43 ~1 ~30 ~46 ~1 ~30 gravel 0  
fill ~43 ~1 ~33 ~48 ~1 ~33 dirt 0  
fill ~43 ~1 ~34 ~43 ~1 ~47 dirt 0  
fill ~43 ~1 ~56 ~43 ~1 ~61 dirt 0  
fill ~43 ~1 ~74 ~48 ~1 ~74 grass 0  
fill ~43 ~1 ~75 ~48 ~1 ~75 grass 0  
fill ~43 ~1 ~76 ~48 ~1 ~76 grass 0  
fill ~43 ~1 ~77 ~48 ~1 ~77 grass 0  
fill ~43 ~1 ~78 ~48 ~1 ~78 grass 0  
fill ~43 ~1 ~79 ~59 ~1 ~79 grass 0  
fill ~43 ~1 ~80 ~61 ~1 ~80 grass 0  
fill ~43 ~1 ~81 ~61 ~1 ~81 grass 0  
fill ~43 ~1 ~82 ~61 ~1 ~82 grass 0  
fill ~44 ~1 ~12 ~46 ~1 ~12 gravel 0  
fill ~44 ~1 ~13 ~46 ~1 ~13 gravel 0  
fill ~44 ~1 ~14 ~46 ~1 ~14 gravel 0  
fill ~44 ~1 ~15 ~46 ~1 ~15 gravel 0  
fill ~44 ~1 ~16 ~46 ~1 ~16 gravel 0  
fill ~44 ~1 ~17 ~46 ~1 ~17 gravel 0  
fill ~44 ~1 ~18 ~46 ~1 ~18 gravel 0  
fill ~44 ~1 ~19 ~46 ~1 ~19 gravel 0  
fill ~44 ~1 ~20 ~46 ~1 ~20 gravel 0  
fill ~44 ~1 ~21 ~46 ~1 ~21 gravel 0  
fill ~44 ~1 ~22 ~46 ~1 ~22 gravel 0  
fill ~44 ~1 ~23 ~46 ~1 ~23 gravel 0  
fill ~44 ~1 ~24 ~46 ~1 ~24 gravel 0  
fill ~44 ~1 ~25 ~46 ~1 ~25 gravel 0  
fill ~44 ~1 ~26 ~46 ~1 ~26 gravel 0  
fill ~44 ~1 ~29 ~46 ~1 ~29 gravel 0  
fill ~44 ~1 ~34 ~47 ~1 ~34 cobblestone 0  
fill ~44 ~1 ~37 ~47 ~1 ~37 cobblestone 0  
fill ~44 ~1 ~38 ~48 ~1 ~38 dirt 0  
fill ~44 ~1 ~39 ~49 ~1 ~39 gravel 0  
fill ~44 ~1 ~40 ~47 ~1 ~40 gravel 0  
fill ~44 ~1 ~41 ~46 ~1 ~41 gravel 0  
fill ~44 ~1 ~42 ~46 ~1 ~42 gravel 0  
fill ~44 ~1 ~43 ~46 ~1 ~43 gravel 0  
fill ~44 ~1 ~44 ~46 ~1 ~44 gravel 0  
fill ~44 ~1 ~45 ~44 ~1 ~73 gravel 0  
fill ~45 ~1 ~46 ~46 ~1 ~46 gravel 0   
fill ~45 ~1 ~47 ~46 ~1 ~47 gravel 0  
fill ~45 ~1 ~48 ~46 ~1 ~48 gravel 0  
fill ~45 ~1 ~49 ~46 ~1 ~49 gravel 0  
fill ~45 ~1 ~50 ~46 ~1 ~50 gravel 0  
fill ~45 ~1 ~51 ~46 ~1 ~51 gravel 0  
fill ~45 ~1 ~52 ~46 ~1 ~52 gravel 0  
fill ~45 ~1 ~53 ~46 ~1 ~53 gravel 0  
fill ~45 ~1 ~54 ~46 ~1 ~54 gravel 0  
fill ~45 ~1 ~55 ~46 ~1 ~55 gravel 0  
fill ~45 ~1 ~56 ~46 ~1 ~56 gravel 0  
fill ~45 ~1 ~57 ~46 ~1 ~57 gravel 0  
fill ~45 ~1 ~58 ~46 ~1 ~58 gravel 0  
fill ~45 ~1 ~59 ~46 ~1 ~59 gravel 0  
fill ~45 ~1 ~60 ~46 ~1 ~60 gravel 0  
fill ~45 ~1 ~61 ~46 ~1 ~61 gravel 0  
fill ~45 ~1 ~62 ~46 ~1 ~62 gravel 0  
fill ~45 ~1 ~63 ~46 ~1 ~63 gravel 0  
fill ~45 ~1 ~64 ~46 ~1 ~64 gravel 0  
fill ~45 ~1 ~65 ~46 ~1 ~65 gravel 0  
fill ~45 ~1 ~66 ~46 ~1 ~66 gravel 0  
fill ~45 ~1 ~67 ~46 ~1 ~67 gravel 0  
fill ~45 ~1 ~68 ~46 ~1 ~68 gravel 0  
fill ~45 ~1 ~69 ~46 ~1 ~69 gravel 0  
fill ~45 ~1 ~70 ~46 ~1 ~70 gravel 0 
setblock ~46 ~1 ~45 gravel 0  
fill ~47 ~1 ~12 ~64 ~1 ~12 grass 0  
fill ~47 ~1 ~13 ~52 ~1 ~13 dirt 0  
fill ~47 ~1 ~14 ~52 ~1 ~14 dirt 0  
fill ~47 ~1 ~15 ~57 ~1 ~15 dirt 0  
fill ~47 ~1 ~16 ~57 ~1 ~16 dirt 0  
fill ~47 ~1 ~17 ~57 ~1 ~17 dirt 0  
fill ~47 ~1 ~18 ~57 ~1 ~18 dirt 0  
fill ~47 ~1 ~19 ~57 ~1 ~19 dirt 0  
fill ~47 ~1 ~20 ~57 ~1 ~20 dirt 0  
fill ~47 ~1 ~21 ~57 ~1 ~21 dirt 0  
fill ~47 ~1 ~22 ~73 ~1 ~22 grass 0  
fill ~47 ~1 ~23 ~52 ~1 ~23 grass 0  
fill ~47 ~1 ~24 ~52 ~1 ~24 grass 0  
fill ~47 ~1 ~25 ~52 ~1 ~25 grass 0  
fill ~47 ~1 ~26 ~52 ~1 ~26 grass 0  
fill ~47 ~1 ~27 ~52 ~1 ~27 grass 0  
fill ~47 ~1 ~28 ~50 ~1 ~28 grass 0  
fill ~47 ~1 ~29 ~50 ~1 ~29 grass 0  
fill ~47 ~1 ~30 ~50 ~1 ~30 grass 0  
fill ~47 ~1 ~41 ~60 ~1 ~41 dirt 0  
fill ~47 ~1 ~42 ~60 ~1 ~42 dirt 0  
fill ~47 ~1 ~43 ~51 ~1 ~43 dirt 0  
fill ~47 ~1 ~44 ~51 ~1 ~44 dirt 0  
fill ~47 ~1 ~45 ~53 ~1 ~45 grass 0  
fill ~47 ~1 ~46 ~53 ~1 ~46 grass 0  
fill ~47 ~1 ~47 ~53 ~1 ~47 grass 0  
fill ~47 ~1 ~48 ~94 ~1 ~48 grass 0  
fill ~47 ~1 ~49 ~51 ~1 ~49 dirt 0  
fill ~47 ~1 ~50 ~51 ~1 ~50 dirt 0  
fill ~47 ~1 ~51 ~51 ~1 ~51 dirt 0  
fill ~47 ~1 ~52 ~51 ~1 ~52 dirt 0  
fill ~47 ~1 ~53 ~51 ~1 ~53 dirt 0  
fill ~47 ~1 ~54 ~93 ~1 ~54 grass 0  
fill ~47 ~1 ~55 ~93 ~1 ~55 grass 0  
fill ~47 ~1 ~56 ~93 ~1 ~56 grass 0  
fill ~47 ~1 ~57 ~52 ~1 ~57 dirt 0  
fill ~47 ~1 ~58 ~52 ~1 ~58 dirt 0  
fill ~47 ~1 ~59 ~52 ~1 ~59 dirt 0  
fill ~47 ~1 ~60 ~52 ~1 ~60 dirt 0  
fill ~47 ~1 ~61 ~52 ~1 ~61 dirt 0  
fill ~47 ~1 ~62 ~52 ~1 ~62 dirt 0  
fill ~47 ~1 ~63 ~52 ~1 ~63 dirt 0  
fill ~47 ~1 ~64 ~52 ~1 ~64 dirt 0  
fill ~47 ~1 ~65 ~52 ~1 ~65 dirt 0  
fill ~47 ~1 ~66 ~51 ~1 ~66 dirt 0  
fill ~47 ~1 ~67 ~51 ~1 ~67 dirt 0  
fill ~47 ~1 ~68 ~51 ~1 ~68 dirt 0  
fill ~47 ~1 ~69 ~51 ~1 ~69 dirt 0  
fill ~47 ~1 ~70 ~51 ~1 ~70 dirt 0  
fill ~48 ~1 ~31 ~50 ~1 ~31 grass 0  
fill ~48 ~1 ~34 ~48 ~-1 ~34 dirt 0  
fill ~48 ~1 ~35 ~48 ~-1 ~35 dirt 0  
fill ~48 ~1 ~36 ~48 ~-1 ~36 dirt 0  
fill ~48 ~1 ~37 ~48 ~-1 ~37 dirt 0  
fill ~48 ~1 ~40 ~51 ~1 ~40 grass 0  
fill ~49 ~1 ~33 ~50 ~1 ~33 gravel 0  
fill ~49 ~1 ~34 ~76 ~1 ~34 gravel 0  
fill ~49 ~1 ~35 ~76 ~1 ~35 gravel 0  
fill ~49 ~1 ~36 ~76 ~1 ~36 gravel 0  
fill ~49 ~1 ~37 ~50 ~1 ~37 gravel 0  
fill ~49 ~1 ~38 ~49 ~1 ~32 gravel 0  
fill ~49 ~1 ~74 ~53 ~1 ~74 dirt 0  
fill ~49 ~1 ~75 ~53 ~1 ~75 dirt 0  
fill ~49 ~1 ~76 ~53 ~1 ~76 dirt 0  
fill ~49 ~1 ~77 ~53 ~1 ~77 dirt 0  
fill ~49 ~1 ~78 ~53 ~1 ~78 dirt 0 
setblock ~50 ~1 ~32 grass 0  
fill ~50 ~1 ~38 ~51 ~1 ~38 grass 0  
fill ~50 ~1 ~39 ~51 ~1 ~39 grass 0  
fill ~51 ~1 ~28 ~59 ~1 ~28 dirt 0  
fill ~51 ~1 ~29 ~59 ~1 ~29 dirt 0  
fill ~51 ~1 ~30 ~55 ~1 ~30 dirt 0  
fill ~51 ~1 ~31 ~55 ~1 ~31 dirt 0  
fill ~51 ~1 ~32 ~55 ~1 ~32 dirt 0  
fill ~51 ~1 ~33 ~59 ~1 ~33 dirt 0 
setblock ~51 ~1 ~37 grass 0  
fill ~52 ~1 ~37 ~60 ~1 ~37 dirt 0  
fill ~52 ~1 ~38 ~60 ~1 ~38 dirt 0  
fill ~52 ~1 ~39 ~60 ~1 ~39 dirt 0  
fill ~52 ~1 ~40 ~60 ~1 ~40 dirt 0  
fill ~52 ~1 ~43 ~53 ~1 ~43 grass 0  
fill ~52 ~1 ~44 ~53 ~1 ~44 grass 0  
fill ~52 ~1 ~49 ~94 ~1 ~49 grass 0  
fill ~52 ~1 ~50 ~94 ~1 ~50 grass 0  
fill ~52 ~1 ~51 ~94 ~1 ~51 grass 0  
fill ~52 ~1 ~52 ~94 ~1 ~52 grass 0  
fill ~52 ~1 ~53 ~93 ~1 ~53 grass 0  
fill ~52 ~1 ~66 ~56 ~1 ~66 grass 0  
fill ~52 ~1 ~67 ~56 ~1 ~67 grass 0  
fill ~52 ~1 ~68 ~56 ~1 ~68 grass 0  
fill ~52 ~1 ~69 ~56 ~1 ~69 grass 0  
fill ~52 ~1 ~70 ~56 ~1 ~70 grass 0  
fill ~53 ~1 ~-4 ~57 ~1 ~-4 glass 0  
fill ~53 ~1 ~13 ~64 ~1 ~13 grass 0  
fill ~53 ~1 ~14 ~73 ~1 ~14 grass 0  
fill ~53 ~1 ~23 ~59 ~1 ~23 dirt 0  
fill ~53 ~1 ~24 ~59 ~1 ~24 dirt 0  
fill ~53 ~1 ~25 ~59 ~1 ~25 dirt 0  
fill ~53 ~1 ~26 ~59 ~1 ~26 dirt 0  
fill ~53 ~1 ~27 ~59 ~1 ~27 dirt 0  
fill ~53 ~1 ~57 ~93 ~1 ~57 grass 0  
fill ~53 ~1 ~58 ~92 ~1 ~58 grass 0  
fill ~53 ~1 ~59 ~92 ~1 ~59 grass 0  
fill ~53 ~1 ~60 ~92 ~1 ~60 grass 0  
fill ~53 ~1 ~61 ~91 ~1 ~61 grass 0  
fill ~53 ~1 ~62 ~65 ~1 ~62 grass 0  
fill ~53 ~1 ~63 ~65 ~1 ~63 grass 0  
fill ~53 ~1 ~64 ~65 ~1 ~64 grass 0  
fill ~53 ~1 ~65 ~65 ~1 ~65 grass 0  
fill ~53 ~1 ~94 ~57 ~1 ~94 glass 0  
fill ~54 ~1 ~43 ~60 ~1 ~43 dirt 0  
fill ~54 ~1 ~44 ~60 ~1 ~44 dirt 0  
fill ~54 ~1 ~45 ~60 ~1 ~45 dirt 0  
fill ~54 ~1 ~46 ~60 ~1 ~46 dirt 0  
fill ~54 ~1 ~47 ~60 ~1 ~47 dirt 0  
fill ~54 ~1 ~74 ~59 ~1 ~74 grass 0  
fill ~54 ~1 ~75 ~59 ~1 ~75 grass 0  
fill ~54 ~1 ~76 ~59 ~1 ~76 grass 0  
fill ~54 ~1 ~77 ~59 ~1 ~77 grass 0  
fill ~54 ~1 ~78 ~59 ~1 ~78 grass 0  
fill ~56 ~1 ~30 ~58 ~1 ~30 grass 0  
fill ~56 ~1 ~31 ~56 ~1 ~32 grass 0  
fill ~57 ~1 ~31 ~57 ~1 ~33 dirt 0  
fill ~57 ~1 ~66 ~60 ~1 ~66 dirt 0  
fill ~57 ~1 ~67 ~60 ~1 ~67 dirt 0  
fill ~57 ~1 ~68 ~60 ~1 ~68 dirt 0  
fill ~57 ~1 ~69 ~60 ~1 ~69 dirt 0  
fill ~57 ~1 ~70 ~60 ~1 ~70 dirt 0  
fill ~58 ~1 ~-3 ~60 ~1 ~-3 glass 0  
fill ~58 ~1 ~15 ~73 ~1 ~15 grass 0  
fill ~58 ~1 ~16 ~73 ~1 ~16 grass 0  
fill ~58 ~1 ~17 ~73 ~1 ~17 grass 0  
fill ~58 ~1 ~18 ~73 ~1 ~18 grass 0  
fill ~58 ~1 ~19 ~73 ~1 ~19 grass 0  
fill ~58 ~1 ~20 ~73 ~1 ~20 grass 0  
fill ~58 ~1 ~21 ~73 ~1 ~21 grass 0  
fill ~58 ~1 ~31 ~58 ~1 ~32 grass 0  
fill ~58 ~1 ~93 ~60 ~1 ~93 glass 0  
fill ~59 ~1 ~30 ~59 ~1 ~33 dirt 0  
fill ~60 ~1 ~23 ~73 ~1 ~23 grass 0  
fill ~60 ~1 ~24 ~73 ~1 ~24 grass 0  
fill ~60 ~1 ~25 ~68 ~1 ~25 grass 0  
fill ~60 ~1 ~26 ~67 ~1 ~26 grass 0  
fill ~60 ~1 ~27 ~67 ~1 ~27 grass 0  
fill ~60 ~1 ~28 ~67 ~1 ~28 grass 0  
fill ~60 ~1 ~29 ~67 ~1 ~29 grass 0  
fill ~60 ~1 ~30 ~68 ~1 ~30 grass 0  
fill ~60 ~1 ~31 ~68 ~1 ~31 grass 0  
fill ~60 ~1 ~32 ~68 ~1 ~32 grass 0  
fill ~60 ~1 ~33 ~68 ~1 ~33 grass 0  
fill ~60 ~1 ~74 ~68 ~1 ~74 dirt 0  
fill ~60 ~1 ~75 ~68 ~1 ~75 dirt 0  
fill ~60 ~1 ~76 ~68 ~1 ~76 dirt 0  
fill ~60 ~1 ~77 ~68 ~1 ~77 dirt 0  
fill ~60 ~1 ~78 ~68 ~1 ~78 dirt 0  
fill ~60 ~1 ~79 ~68 ~1 ~79 dirt 0  
fill ~61 ~1 ~-2 ~63 ~1 ~-2 glass 0  
fill ~61 ~1 ~37 ~66 ~1 ~37 grass 0  
fill ~61 ~1 ~38 ~66 ~1 ~38 grass 0  
fill ~61 ~1 ~39 ~66 ~1 ~39 grass 0  
fill ~61 ~1 ~40 ~66 ~1 ~40 grass 0  
fill ~61 ~1 ~41 ~65 ~1 ~41 grass 0  
fill ~61 ~1 ~42 ~65 ~1 ~42 grass 0  
fill ~61 ~1 ~43 ~65 ~1 ~43 grass 0  
fill ~61 ~1 ~44 ~65 ~1 ~44 grass 0  
fill ~61 ~1 ~45 ~66 ~1 ~45 grass 0  
fill ~61 ~1 ~46 ~94 ~1 ~46 grass 0  
fill ~61 ~1 ~47 ~94 ~1 ~47 grass 0  
fill ~61 ~1 ~66 ~65 ~1 ~66 grass 0  
fill ~61 ~1 ~67 ~65 ~1 ~67 grass 0  
fill ~61 ~1 ~68 ~65 ~1 ~68 grass 0  
fill ~61 ~1 ~69 ~65 ~1 ~69 grass 0  
fill ~61 ~1 ~70 ~65 ~1 ~70 grass 0  
fill ~61 ~1 ~92 ~63 ~1 ~92 glass 0  
fill ~62 ~1 ~80 ~68 ~1 ~80 dirt 0  
fill ~62 ~1 ~81 ~68 ~1 ~81 dirt 0  
fill ~62 ~1 ~82 ~68 ~1 ~82 dirt 0  
fill ~62 ~1 ~83 ~68 ~1 ~83 dirt 0  
fill ~62 ~1 ~84 ~68 ~1 ~84 dirt 0  
fill ~64 ~1 ~-1 ~65 ~1 ~-1 glass 0  
fill ~64 ~1 ~91 ~65 ~1 ~91 glass 0  
fill ~65 ~1 ~1 ~67 ~1 ~1 dirt 0  
fill ~65 ~1 ~2 ~65 ~1 ~13 dirt 0  
fill ~66 ~1 ~0 ~67 ~1 ~0 glass 0  
fill ~66 ~1 ~2 ~69 ~1 ~2 grass 0  
fill ~66 ~1 ~3 ~71 ~1 ~3 grass 0  
fill ~66 ~1 ~4 ~72 ~1 ~4 dirt 0  
fill ~66 ~1 ~5 ~72 ~1 ~5 grass 0  
fill ~66 ~1 ~6 ~72 ~1 ~6 grass 0  
fill ~66 ~1 ~7 ~73 ~1 ~7 dirt 0  
fill ~66 ~1 ~8 ~72 ~1 ~8 grass 0  
fill ~66 ~1 ~9 ~72 ~1 ~9 grass 0  
fill ~66 ~1 ~10 ~73 ~1 ~10 dirt 0  
fill ~66 ~1 ~11 ~72 ~1 ~11 grass 0  
fill ~66 ~1 ~12 ~72 ~1 ~12 grass 0  
fill ~66 ~1 ~13 ~73 ~1 ~13 dirt 0  
fill ~66 ~1 ~41 ~70 ~1 ~41 dirt 0  
fill ~66 ~1 ~42 ~70 ~1 ~42 dirt 0  
fill ~66 ~1 ~43 ~70 ~1 ~43 dirt 0  
fill ~66 ~1 ~44 ~70 ~1 ~44 dirt 0  
fill ~66 ~1 ~62 ~72 ~1 ~62 dirt 0  
fill ~66 ~1 ~63 ~66 ~1 ~70 dirt 0  
fill ~66 ~1 ~90 ~67 ~1 ~90 glass 0  
fill ~67 ~1 ~37 ~69 ~1 ~37 dirt 0  
fill ~67 ~1 ~38 ~69 ~1 ~38 dirt 0  
fill ~67 ~1 ~39 ~69 ~1 ~39 dirt 0  
fill ~67 ~1 ~40 ~69 ~1 ~40 dirt 0  
fill ~67 ~1 ~45 ~69 ~1 ~45 dirt 0  
fill ~67 ~1 ~63 ~68 ~1 ~63 grass 0  
fill ~67 ~1 ~64 ~68 ~1 ~64 grass 0  
fill ~67 ~1 ~65 ~68 ~1 ~65 grass 0  
fill ~67 ~1 ~66 ~68 ~1 ~66 grass 0  
fill ~67 ~1 ~67 ~68 ~1 ~67 grass 0  
fill ~67 ~1 ~68 ~68 ~1 ~68 grass 0  
fill ~67 ~1 ~69 ~68 ~1 ~69 grass 0  
fill ~67 ~1 ~70 ~72 ~1 ~70 dirt 0  
fill ~68 ~1 ~1 ~69 ~1 ~1 glass 0  
fill ~68 ~1 ~26 ~72 ~1 ~26 dirt 0  
fill ~68 ~1 ~27 ~72 ~1 ~27 dirt 0  
fill ~68 ~1 ~28 ~72 ~1 ~28 dirt 0  
fill ~68 ~1 ~29 ~72 ~1 ~29 dirt 0  
fill ~68 ~1 ~89 ~69 ~1 ~89 glass 0  
fill ~69 ~1 ~25 ~71 ~1 ~25 dirt 0  
fill ~69 ~1 ~30 ~71 ~1 ~30 dirt 0  
fill ~69 ~1 ~31 ~71 ~1 ~31 dirt 0  
fill ~69 ~1 ~32 ~71 ~1 ~32 dirt 0  
fill ~69 ~1 ~33 ~71 ~1 ~33 dirt 0  
fill ~69 ~1 ~63 ~69 ~1 ~70 dirt 0  
fill ~69 ~1 ~74 ~85 ~1 ~74 grass 0  
fill ~69 ~1 ~75 ~84 ~1 ~75 grass 0  
fill ~69 ~1 ~76 ~83 ~1 ~76 grass 0  
fill ~69 ~1 ~77 ~83 ~1 ~77 grass 0  
fill ~69 ~1 ~78 ~82 ~1 ~78 grass 0  
fill ~69 ~1 ~79 ~81 ~1 ~79 grass 0  
fill ~69 ~1 ~80 ~80 ~1 ~80 grass 0  
fill ~69 ~1 ~81 ~79 ~1 ~81 grass 0  
fill ~69 ~1 ~82 ~78 ~1 ~82 grass 0  
fill ~69 ~1 ~83 ~77 ~1 ~83 grass 0  
fill ~69 ~1 ~84 ~75 ~1 ~84 grass 0  
fill ~70 ~1 ~2 ~71 ~1 ~2 glass 0  
fill ~70 ~1 ~37 ~93 ~1 ~37 grass 0  
fill ~70 ~1 ~38 ~94 ~1 ~38 grass 0  
fill ~70 ~1 ~39 ~94 ~1 ~39 grass 0  
fill ~70 ~1 ~40 ~94 ~1 ~40 grass 0  
fill ~70 ~1 ~45 ~89 ~1 ~45 grass 0  
fill ~70 ~1 ~63 ~71 ~1 ~63 grass 0  
fill ~70 ~1 ~64 ~71 ~1 ~64 grass 0  
fill ~70 ~1 ~65 ~71 ~1 ~65 grass 0  
fill ~70 ~1 ~66 ~71 ~1 ~66 grass 0  
fill ~70 ~1 ~67 ~71 ~1 ~67 grass 0  
fill ~70 ~1 ~68 ~71 ~1 ~68 grass 0  
fill ~70 ~1 ~69 ~71 ~1 ~69 grass 0  
fill ~70 ~1 ~88 ~71 ~1 ~88 glass 0  
fill ~71 ~1 ~41 ~94 ~1 ~41 grass 0  
fill ~71 ~1 ~42 ~94 ~1 ~42 grass 0  
fill ~71 ~1 ~43 ~94 ~1 ~43 grass 0  
fill ~71 ~1 ~44 ~94 ~1 ~44 grass 0  
fill ~72 ~1 ~3 ~73 ~1 ~3 glass 0  
fill ~72 ~1 ~25 ~73 ~1 ~25 grass 0  
fill ~72 ~1 ~30 ~73 ~1 ~30 grass 0  
fill ~72 ~1 ~31 ~73 ~1 ~31 grass 0  
fill ~72 ~1 ~32 ~73 ~1 ~32 grass 0  
fill ~72 ~1 ~33 ~73 ~1 ~33 grass 0  
fill ~72 ~1 ~63 ~72 ~1 ~70 dirt 0  
fill ~72 ~1 ~87 ~73 ~1 ~87 glass 0 
setblock ~73 ~1 ~4 grass 0  
fill ~73 ~1 ~5 ~73 ~1 ~13 dirt 0  
fill ~73 ~1 ~26 ~73 ~1 ~33 grass 0  
fill ~73 ~1 ~62 ~91 ~1 ~62 grass 0  
fill ~73 ~1 ~63 ~91 ~1 ~63 grass 0  
fill ~73 ~1 ~64 ~90 ~1 ~64 grass 0  
fill ~73 ~1 ~65 ~90 ~1 ~65 grass 0  
fill ~73 ~1 ~66 ~89 ~1 ~66 grass 0  
fill ~73 ~1 ~67 ~89 ~1 ~67 grass 0  
fill ~73 ~1 ~68 ~88 ~1 ~68 grass 0  
fill ~73 ~1 ~69 ~88 ~1 ~69 grass 0  
fill ~73 ~1 ~70 ~87 ~1 ~70 grass 0  
fill ~74 ~1 ~5 ~74 ~1 ~36 gravel 0  
fill ~75 ~1 ~6 ~75 ~1 ~8 gravel 0  
fill ~75 ~1 ~9 ~79 ~1 ~9 grass 0  
fill ~75 ~1 ~10 ~80 ~1 ~10 grass 0  
fill ~75 ~1 ~11 ~81 ~1 ~11 grass 0  
fill ~75 ~1 ~12 ~82 ~1 ~12 grass 0  
fill ~75 ~1 ~13 ~83 ~1 ~13 grass 0  
fill ~75 ~1 ~14 ~83 ~1 ~14 grass 0  
fill ~75 ~1 ~15 ~84 ~1 ~15 grass 0  
fill ~75 ~1 ~16 ~85 ~1 ~16 grass 0  
fill ~75 ~1 ~17 ~76 ~1 ~17 gravel 0  
fill ~75 ~1 ~18 ~76 ~1 ~18 gravel 0  
fill ~75 ~1 ~19 ~76 ~1 ~19 gravel 0  
fill ~75 ~1 ~20 ~76 ~1 ~20 gravel 0  
fill ~75 ~1 ~21 ~76 ~1 ~21 gravel 0  
fill ~75 ~1 ~22 ~76 ~1 ~22 gravel 0  
fill ~75 ~1 ~23 ~76 ~1 ~23 gravel 0  
fill ~75 ~1 ~24 ~76 ~1 ~24 gravel 0  
fill ~75 ~1 ~25 ~76 ~1 ~25 gravel 0  
fill ~75 ~1 ~26 ~76 ~1 ~26 gravel 0  
fill ~75 ~1 ~27 ~76 ~1 ~27 gravel 0  
fill ~75 ~1 ~28 ~76 ~1 ~28 gravel 0  
fill ~75 ~1 ~29 ~76 ~1 ~29 gravel 0  
fill ~75 ~1 ~30 ~76 ~1 ~30 gravel 0  
fill ~75 ~1 ~31 ~76 ~1 ~31 gravel 0  
fill ~75 ~1 ~32 ~76 ~1 ~32 gravel 0  
fill ~75 ~1 ~33 ~76 ~1 ~33 gravel 0  
fill ~76 ~1 ~6 ~77 ~1 ~6 glass 0  
fill ~76 ~1 ~7 ~76 ~1 ~8 gravel 0  
fill ~76 ~1 ~84 ~77 ~1 ~84 glass 0  
fill ~77 ~1 ~7 ~77 ~1 ~70 grass 0 
setblock ~78 ~1 ~8 grass 0  
fill ~78 ~1 ~17 ~86 ~1 ~17 grass 0  
fill ~78 ~1 ~18 ~86 ~1 ~18 grass 0  
fill ~78 ~1 ~19 ~87 ~1 ~19 grass 0  
fill ~78 ~1 ~20 ~87 ~1 ~20 grass 0  
fill ~78 ~1 ~21 ~88 ~1 ~21 grass 0  
fill ~78 ~1 ~22 ~88 ~1 ~22 grass 0  
fill ~78 ~1 ~23 ~89 ~1 ~23 grass 0  
fill ~78 ~1 ~24 ~89 ~1 ~24 grass 0  
fill ~78 ~1 ~25 ~90 ~1 ~25 grass 0  
fill ~78 ~1 ~26 ~90 ~1 ~26 grass 0  
fill ~78 ~1 ~27 ~91 ~1 ~27 grass 0  
fill ~78 ~1 ~28 ~91 ~1 ~28 grass 0  
fill ~78 ~1 ~29 ~91 ~1 ~29 grass 0  
fill ~78 ~1 ~30 ~92 ~1 ~30 grass 0  
fill ~78 ~1 ~31 ~92 ~1 ~31 grass 0  
fill ~78 ~1 ~32 ~92 ~1 ~32 grass 0  
fill ~78 ~1 ~33 ~93 ~1 ~33 grass 0  
fill ~78 ~1 ~34 ~93 ~1 ~34 grass 0  
fill ~78 ~1 ~35 ~93 ~1 ~35 grass 0  
fill ~78 ~1 ~36 ~93 ~1 ~36 grass 0  
fill ~82 ~1 ~71 ~87 ~1 ~71 grass 0  
fill ~82 ~1 ~72 ~86 ~1 ~72 grass 0  
fill ~82 ~1 ~73 ~86 ~1 ~73 grass 0 
setblock ~90 ~1 ~45 dirt 0  
fill ~91 ~1 ~45 ~94 ~1 ~45 grass 0  
fill ~-4 ~2 ~38 ~-4 ~10 ~38 glass 0  
fill ~-4 ~2 ~52 ~-4 ~10 ~52 glass 0  
fill ~-2 ~2 ~43 ~2 ~2 ~43 glass 0  
fill ~-2 ~2 ~44 ~-2 ~2 ~47 glass 0  
fill ~-1 ~2 ~47 ~2 ~2 ~47 glass 0  
fill ~2 ~2 ~44 ~2 ~2 ~47 glass 0  
fill ~4 ~2 ~17 ~4 ~9 ~17 glass 0  
fill ~4 ~2 ~73 ~4 ~9 ~73 glass 0  
fill ~11 ~2 ~11 ~15 ~2 ~11 glass 0  
fill ~11 ~2 ~12 ~11 ~2 ~15 glass 0  
fill ~11 ~2 ~75 ~15 ~2 ~75 glass 0  
fill ~11 ~2 ~76 ~11 ~2 ~79 glass 0  
fill ~12 ~2 ~15 ~15 ~2 ~15 glass 0  
fill ~12 ~2 ~79 ~15 ~2 ~79 glass 0  
fill ~13 ~2 ~6 ~14 ~2 ~6 glass 0  
fill ~13 ~2 ~84 ~14 ~2 ~84 glass 0  
fill ~15 ~2 ~12 ~15 ~2 ~15 glass 0  
fill ~15 ~2 ~37 ~19 ~2 ~37 cobblestone 0  
fill ~15 ~2 ~38 ~19 ~2 ~38 cobblestone 0  
fill ~15 ~2 ~39 ~19 ~2 ~39 cobblestone 0  
fill ~15 ~2 ~40 ~19 ~2 ~40 cobblestone 0  
fill ~15 ~2 ~41 ~19 ~2 ~41 cobblestone 0  
fill ~15 ~2 ~76 ~15 ~2 ~79 glass 0  
fill ~17 ~2 ~4 ~17 ~9 ~4 glass 0 
setblock ~17 ~2 ~36 stone_stairs 2  
fill ~17 ~2 ~74 ~24 ~2 ~74 cobblestone 0  
fill ~17 ~2 ~75 ~17 ~4 ~75 cobblestone 0  
fill ~17 ~2 ~76 ~17 ~4 ~76 cobblestone 0  
fill ~17 ~2 ~77 ~17 ~4 ~77 cobblestone 0  
fill ~17 ~2 ~78 ~17 ~4 ~78 cobblestone 0  
fill ~17 ~2 ~79 ~18 ~2 ~79 cobblestone 0  
fill ~17 ~2 ~86 ~17 ~9 ~86 glass 0  
fill ~18 ~2 ~3 ~18 ~7 ~3 glass 0 
setblock ~18 ~2 ~73 stone_stairs 2  
fill ~18 ~2 ~75 ~23 ~2 ~75 planks 0  
fill ~18 ~2 ~76 ~23 ~2 ~76 planks 0  
fill ~18 ~2 ~77 ~23 ~2 ~77 planks 0  
fill ~18 ~2 ~78 ~23 ~2 ~78 planks 0  
fill ~18 ~2 ~80 ~18 ~3 ~80 cobblestone 0  
fill ~18 ~2 ~81 ~18 ~3 ~81 cobblestone 0  
fill ~18 ~2 ~82 ~18 ~3 ~82 cobblestone 0  
fill ~18 ~2 ~83 ~18 ~3 ~83 cobblestone 0  
fill ~18 ~2 ~84 ~24 ~2 ~84 cobblestone 0  
fill ~19 ~2 ~2 ~20 ~2 ~2 glass 0  
fill ~19 ~2 ~25 ~25 ~2 ~25 log 0  
fill ~19 ~2 ~26 ~19 ~2 ~33 log 0  
fill ~19 ~2 ~79 ~23 ~2 ~79 planks 0  
fill ~19 ~2 ~80 ~23 ~2 ~80 planks 0  
fill ~19 ~2 ~81 ~23 ~2 ~81 planks 0  
fill ~19 ~2 ~82 ~23 ~2 ~82 planks 0  
fill ~19 ~2 ~83 ~23 ~2 ~83 planks 0  
fill ~19 ~2 ~88 ~20 ~2 ~88 glass 0  
fill ~20 ~2 ~26 ~21 ~2 ~26 farmland 7  
fill ~20 ~2 ~27 ~21 ~2 ~27 farmland 7  
fill ~20 ~2 ~28 ~21 ~2 ~28 farmland 7  
fill ~20 ~2 ~29 ~21 ~2 ~29 farmland 7  
fill ~20 ~2 ~30 ~21 ~2 ~30 farmland 7  
fill ~20 ~2 ~31 ~21 ~2 ~31 farmland 7  
fill ~20 ~2 ~32 ~21 ~2 ~32 farmland 7  
fill ~20 ~2 ~33 ~25 ~2 ~33 log 0  
fill ~20 ~2 ~66 ~23 ~2 ~66 cobblestone 0  
fill ~20 ~2 ~67 ~20 ~2 ~70 cobblestone 0  
fill ~21 ~2 ~1 ~22 ~2 ~1 glass 0  
fill ~21 ~2 ~67 ~22 ~2 ~67 dirt 0  
fill ~21 ~2 ~68 ~22 ~2 ~68 dirt 0  
fill ~21 ~2 ~69 ~22 ~2 ~69 dirt 0  
fill ~21 ~2 ~70 ~23 ~2 ~70 cobblestone 0  
fill ~21 ~2 ~89 ~22 ~2 ~89 glass 0  
fill ~23 ~2 ~0 ~24 ~2 ~0 glass 0  
fill ~23 ~2 ~26 ~24 ~2 ~26 farmland 7  
fill ~23 ~2 ~27 ~24 ~2 ~27 farmland 7  
fill ~23 ~2 ~28 ~24 ~2 ~28 farmland 7  
fill ~23 ~2 ~29 ~24 ~2 ~29 farmland 7  
fill ~23 ~2 ~30 ~24 ~2 ~30 farmland 7  
fill ~23 ~2 ~31 ~24 ~2 ~31 farmland 7  
fill ~23 ~2 ~32 ~24 ~2 ~32 farmland 7  
fill ~23 ~2 ~37 ~26 ~2 ~37 cobblestone 0  
fill ~23 ~2 ~38 ~23 ~2 ~41 cobblestone 0  
fill ~23 ~2 ~67 ~23 ~2 ~70 cobblestone 0  
fill ~23 ~2 ~90 ~24 ~2 ~90 glass 0 
setblock ~24 ~2 ~36 stone_stairs 2  
fill ~24 ~2 ~38 ~25 ~2 ~38 dirt 0  
fill ~24 ~2 ~39 ~25 ~2 ~39 dirt 0  
fill ~24 ~2 ~40 ~25 ~2 ~40 dirt 0  
fill ~24 ~2 ~41 ~26 ~2 ~41 cobblestone 0  
fill ~24 ~2 ~75 ~24 ~3 ~75 cobblestone 0  
fill ~24 ~2 ~76 ~24 ~3 ~76 cobblestone 0  
fill ~24 ~2 ~77 ~24 ~3 ~77 cobblestone 0  
fill ~24 ~2 ~78 ~24 ~3 ~78 cobblestone 0  
fill ~24 ~2 ~79 ~24 ~3 ~79 cobblestone 0  
fill ~24 ~2 ~80 ~24 ~3 ~80 cobblestone 0  
fill ~24 ~2 ~81 ~24 ~3 ~81 cobblestone 0  
fill ~24 ~2 ~82 ~24 ~3 ~82 cobblestone 0  
fill ~24 ~2 ~83 ~24 ~3 ~83 cobblestone 0  
fill ~25 ~2 ~-1 ~26 ~2 ~-1 glass 0  
fill ~25 ~2 ~26 ~25 ~2 ~33 log 0  
fill ~25 ~2 ~91 ~26 ~2 ~91 glass 0  
fill ~26 ~2 ~38 ~26 ~2 ~41 cobblestone 0  
fill ~27 ~2 ~-2 ~29 ~2 ~-2 glass 0  
fill ~27 ~2 ~92 ~29 ~2 ~92 glass 0  
fill ~29 ~2 ~70 ~29 ~4 ~70 fence 0  
fill ~30 ~2 ~-3 ~32 ~2 ~-3 glass 0  
fill ~30 ~2 ~74 ~42 ~2 ~74 log 0  
fill ~30 ~2 ~75 ~30 ~2 ~82 log 0  
fill ~30 ~2 ~93 ~32 ~2 ~93 glass 0  
fill ~31 ~2 ~75 ~32 ~2 ~75 farmland 7  
fill ~31 ~2 ~76 ~32 ~2 ~76 farmland 7  
fill ~31 ~2 ~77 ~32 ~2 ~77 farmland 7  
fill ~31 ~2 ~78 ~32 ~2 ~78 farmland 7  
fill ~31 ~2 ~79 ~32 ~2 ~79 farmland 7  
fill ~31 ~2 ~80 ~32 ~2 ~80 farmland 7  
fill ~31 ~2 ~81 ~32 ~2 ~81 farmland 7  
fill ~31 ~2 ~82 ~42 ~2 ~82 log 0  
fill ~33 ~2 ~-4 ~38 ~2 ~-4 glass 0  
fill ~33 ~2 ~41 ~37 ~2 ~41 grass 0  
fill ~33 ~2 ~42 ~37 ~2 ~42 grass 0  
fill ~33 ~2 ~43 ~37 ~2 ~43 grass 0  
fill ~33 ~2 ~44 ~37 ~2 ~44 grass 0  
fill ~33 ~2 ~45 ~36 ~2 ~45 grass 0  
fill ~33 ~2 ~46 ~37 ~2 ~46 grass 0  
fill ~33 ~2 ~47 ~37 ~2 ~47 grass 0  
fill ~33 ~2 ~94 ~38 ~2 ~94 glass 0  
fill ~34 ~2 ~29 ~37 ~2 ~29 cobblestone 0  
fill ~34 ~2 ~30 ~34 ~2 ~33 cobblestone 0  
fill ~34 ~2 ~37 ~34 ~4 ~37 fence 0  
fill ~34 ~2 ~75 ~35 ~2 ~75 farmland 7  
fill ~34 ~2 ~76 ~35 ~2 ~76 farmland 7  
fill ~34 ~2 ~77 ~35 ~2 ~77 farmland 7  
fill ~34 ~2 ~78 ~35 ~2 ~78 farmland 7  
fill ~34 ~2 ~79 ~35 ~2 ~79 farmland 7  
fill ~34 ~2 ~80 ~35 ~2 ~80 farmland 7  
fill ~34 ~2 ~81 ~35 ~2 ~81 farmland 7  
fill ~35 ~2 ~13 ~43 ~2 ~13 log 0  
fill ~35 ~2 ~14 ~35 ~2 ~25 log 0  
fill ~35 ~2 ~30 ~36 ~2 ~30 dirt 0  
fill ~35 ~2 ~31 ~36 ~2 ~31 dirt 0  
fill ~35 ~2 ~32 ~36 ~2 ~32 dirt 0  
fill ~35 ~2 ~33 ~37 ~2 ~33 cobblestone 0 
setblock ~35 ~2 ~34 stone_stairs 3  
fill ~35 ~2 ~55 ~43 ~2 ~55 log 0  
fill ~35 ~2 ~56 ~35 ~2 ~61 log 0  
fill ~36 ~2 ~14 ~42 ~2 ~14 farmland 7  
fill ~36 ~2 ~15 ~42 ~2 ~15 farmland 7  
fill ~36 ~2 ~17 ~42 ~2 ~17 farmland 7  
fill ~36 ~2 ~18 ~42 ~2 ~18 farmland 7  
fill ~36 ~2 ~19 ~43 ~2 ~19 log 0  
fill ~36 ~2 ~20 ~42 ~2 ~20 farmland 7  
fill ~36 ~2 ~21 ~42 ~2 ~21 farmland 7  
fill ~36 ~2 ~23 ~42 ~2 ~23 farmland 7  
fill ~36 ~2 ~24 ~42 ~2 ~24 farmland 7  
fill ~36 ~2 ~25 ~43 ~2 ~25 log 0  
fill ~36 ~2 ~56 ~42 ~2 ~56 farmland 7  
fill ~36 ~2 ~57 ~42 ~2 ~57 farmland 7  
fill ~36 ~2 ~59 ~42 ~2 ~59 farmland 7  
fill ~36 ~2 ~60 ~42 ~2 ~60 farmland 7  
fill ~36 ~2 ~61 ~43 ~2 ~61 log 0  
fill ~36 ~2 ~70 ~36 ~4 ~70 fence 0  
fill ~36 ~2 ~75 ~36 ~2 ~82 log 0  
fill ~37 ~2 ~30 ~37 ~2 ~33 cobblestone 0  
fill ~37 ~2 ~45 ~38 ~2 ~45 cobblestone 0  
fill ~37 ~2 ~75 ~38 ~2 ~75 farmland 7  
fill ~37 ~2 ~76 ~38 ~2 ~76 farmland 7  
fill ~37 ~2 ~77 ~38 ~2 ~77 farmland 7  
fill ~37 ~2 ~78 ~38 ~2 ~78 farmland 7  
fill ~37 ~2 ~79 ~38 ~2 ~79 farmland 7  
fill ~37 ~2 ~80 ~38 ~2 ~80 farmland 7  
fill ~37 ~2 ~81 ~38 ~2 ~81 farmland 7  
fill ~38 ~2 ~39 ~43 ~2 ~39 cobblestone 0  
fill ~38 ~2 ~40 ~38 ~3 ~40 cobblestone 0  
fill ~38 ~2 ~41 ~38 ~3 ~41 cobblestone 0  
fill ~38 ~2 ~42 ~38 ~3 ~42 cobblestone 0  
fill ~38 ~2 ~43 ~38 ~3 ~43 cobblestone 0  
fill ~38 ~2 ~44 ~38 ~3 ~44 cobblestone 0  
fill ~38 ~2 ~46 ~38 ~3 ~46 cobblestone 0  
fill ~38 ~2 ~47 ~43 ~2 ~47 cobblestone 0  
fill ~39 ~2 ~-5 ~51 ~2 ~-5 glass 0  
fill ~39 ~2 ~40 ~42 ~2 ~40 planks 0  
fill ~39 ~2 ~41 ~42 ~2 ~41 planks 0  
fill ~39 ~2 ~42 ~42 ~2 ~42 planks 0  
fill ~39 ~2 ~43 ~42 ~2 ~43 planks 0  
fill ~39 ~2 ~44 ~39 ~2 ~46 planks 0  
fill ~39 ~2 ~95 ~51 ~2 ~95 glass 0  
fill ~40 ~2 ~44 ~42 ~2 ~44 double_stone_slab 0  
fill ~40 ~2 ~45 ~42 ~2 ~45 double_stone_slab 0  
fill ~40 ~2 ~46 ~42 ~2 ~46 double_stone_slab 0  
fill ~40 ~2 ~75 ~41 ~2 ~75 farmland 7  
fill ~40 ~2 ~76 ~41 ~2 ~76 farmland 7  
fill ~40 ~2 ~77 ~41 ~2 ~77 farmland 7  
fill ~40 ~2 ~78 ~41 ~2 ~78 farmland 7  
fill ~40 ~2 ~79 ~41 ~2 ~79 farmland 7  
fill ~40 ~2 ~80 ~41 ~2 ~80 farmland 7  
fill ~40 ~2 ~81 ~41 ~2 ~81 farmland 7 
setblock ~41 ~2 ~28 anvil 0 
setblock ~41 ~2 ~30 anvil 0 
setblock ~42 ~2 ~29 enchanting_table 0  
fill ~42 ~2 ~75 ~42 ~2 ~82 log 0  
fill ~43 ~2 ~-2 ~47 ~2 ~-2 glass 0  
fill ~43 ~2 ~-1 ~43 ~2 ~2 glass 0  
fill ~43 ~2 ~14 ~43 ~2 ~25 log 0  
fill ~43 ~2 ~33 ~48 ~2 ~33 gravel 0  
fill ~43 ~2 ~34 ~43 ~2 ~38 gravel 0  
fill ~43 ~2 ~40 ~43 ~3 ~40 cobblestone 0  
fill ~43 ~2 ~41 ~43 ~2 ~47 cobblestone 0  
fill ~43 ~2 ~56 ~43 ~2 ~61 log 0  
fill ~43 ~2 ~88 ~47 ~2 ~88 glass 0  
fill ~43 ~2 ~89 ~43 ~2 ~92 glass 0  
fill ~44 ~2 ~2 ~47 ~2 ~2 glass 0  
fill ~44 ~2 ~34 ~47 ~2 ~34 cobblestone 0  
fill ~44 ~2 ~37 ~47 ~2 ~37 cobblestone 0  
fill ~44 ~2 ~38 ~48 ~2 ~38 gravel 0 
setblock ~44 ~2 ~41 stone_stairs 1  
fill ~44 ~2 ~92 ~47 ~2 ~92 glass 0 
setblock ~46 ~2 ~15 stone_stairs 0 
setblock ~46 ~2 ~42 stone_stairs 0 
setblock ~46 ~2 ~51 stone_stairs 0 
setblock ~46 ~2 ~58 stone_stairs 0  
fill ~47 ~2 ~-1 ~47 ~2 ~2 glass 0  
fill ~47 ~2 ~13 ~52 ~2 ~13 cobblestone 0  
fill ~47 ~2 ~14 ~47 ~3 ~14 cobblestone 0  
fill ~47 ~2 ~15 ~47 ~2 ~21 cobblestone 0  
fill ~47 ~2 ~41 ~52 ~2 ~41 cobblestone 0  
fill ~47 ~2 ~42 ~47 ~2 ~44 cobblestone 0  
fill ~47 ~2 ~49 ~51 ~2 ~49 cobblestone 0  
fill ~47 ~2 ~50 ~51 ~2 ~50 cobblestone 0  
fill ~47 ~2 ~51 ~51 ~2 ~51 cobblestone 0  
fill ~47 ~2 ~52 ~51 ~2 ~52 cobblestone 0  
fill ~47 ~2 ~53 ~51 ~2 ~53 cobblestone 0  
fill ~47 ~2 ~57 ~52 ~2 ~57 cobblestone 0  
fill ~47 ~2 ~58 ~52 ~2 ~58 cobblestone 0  
fill ~47 ~2 ~59 ~52 ~2 ~59 cobblestone 0  
fill ~47 ~2 ~60 ~52 ~2 ~60 cobblestone 0  
fill ~47 ~2 ~61 ~52 ~2 ~61 cobblestone 0  
fill ~47 ~2 ~62 ~52 ~2 ~62 cobblestone 0  
fill ~47 ~2 ~63 ~52 ~2 ~63 cobblestone 0  
fill ~47 ~2 ~64 ~52 ~2 ~64 cobblestone 0  
fill ~47 ~2 ~65 ~52 ~2 ~65 cobblestone 0  
fill ~47 ~2 ~66 ~51 ~2 ~66 cobblestone 0  
fill ~47 ~2 ~67 ~51 ~2 ~67 cobblestone 0  
fill ~47 ~2 ~68 ~51 ~2 ~68 cobblestone 0  
fill ~47 ~2 ~69 ~51 ~2 ~69 cobblestone 0  
fill ~47 ~2 ~70 ~51 ~2 ~70 cobblestone 0  
fill ~47 ~2 ~89 ~47 ~2 ~92 glass 0  
fill ~48 ~2 ~14 ~51 ~2 ~14 planks 0  
fill ~48 ~2 ~15 ~51 ~2 ~15 planks 0  
fill ~48 ~2 ~16 ~56 ~2 ~16 planks 0  
fill ~48 ~2 ~17 ~56 ~2 ~17 planks 0  
fill ~48 ~2 ~18 ~56 ~2 ~18 planks 0  
fill ~48 ~2 ~19 ~56 ~2 ~19 planks 0  
fill ~48 ~2 ~20 ~56 ~2 ~20 planks 0  
fill ~48 ~2 ~21 ~57 ~2 ~21 cobblestone 0  
fill ~48 ~2 ~34 ~48 ~2 ~38 gravel 0  
fill ~48 ~2 ~42 ~50 ~2 ~42 dirt 0  
fill ~48 ~2 ~43 ~50 ~2 ~43 dirt 0  
fill ~48 ~2 ~44 ~51 ~2 ~44 cobblestone 0  
fill ~49 ~2 ~74 ~53 ~2 ~74 cobblestone 0  
fill ~49 ~2 ~75 ~53 ~2 ~75 cobblestone 0  
fill ~49 ~2 ~76 ~53 ~2 ~76 cobblestone 0  
fill ~49 ~2 ~77 ~53 ~2 ~77 cobblestone 0  
fill ~49 ~2 ~78 ~53 ~2 ~78 cobblestone 0  
fill ~51 ~2 ~28 ~59 ~2 ~28 cobblestone 0  
fill ~51 ~2 ~29 ~51 ~3 ~29 cobblestone 0  
fill ~51 ~2 ~30 ~51 ~3 ~30 cobblestone 0  
fill ~51 ~2 ~31 ~51 ~3 ~31 cobblestone 0  
fill ~51 ~2 ~32 ~51 ~3 ~32 cobblestone 0  
fill ~51 ~2 ~33 ~59 ~2 ~33 cobblestone 0  
fill ~51 ~2 ~42 ~54 ~2 ~42 cobblestone 0  
fill ~51 ~2 ~43 ~51 ~2 ~41 cobblestone 0 
setblock ~51 ~2 ~73 stone_stairs 2  
fill ~52 ~2 ~-4 ~57 ~2 ~-4 glass 0  
fill ~52 ~2 ~14 ~52 ~3 ~14 cobblestone 0  
fill ~52 ~2 ~15 ~57 ~2 ~15 cobblestone 0  
fill ~52 ~2 ~29 ~58 ~2 ~29 planks 0  
fill ~52 ~2 ~30 ~55 ~2 ~30 planks 0  
fill ~52 ~2 ~31 ~55 ~2 ~31 planks 0  
fill ~52 ~2 ~32 ~55 ~2 ~32 planks 0  
fill ~52 ~2 ~37 ~60 ~2 ~37 cobblestone 0  
fill ~52 ~2 ~38 ~52 ~3 ~38 cobblestone 0  
fill ~52 ~2 ~39 ~52 ~3 ~39 cobblestone 0  
fill ~52 ~2 ~40 ~52 ~3 ~40 cobblestone 0  
fill ~52 ~2 ~94 ~57 ~2 ~94 glass 0  
fill ~53 ~2 ~23 ~59 ~2 ~23 grass 0  
fill ~53 ~2 ~24 ~59 ~2 ~24 grass 0  
fill ~53 ~2 ~25 ~59 ~2 ~25 grass 0  
fill ~53 ~2 ~26 ~59 ~2 ~26 grass 0  
fill ~53 ~2 ~27 ~56 ~2 ~27 grass 0 
setblock ~53 ~2 ~34 stone_stairs 3  
fill ~53 ~2 ~38 ~59 ~2 ~38 planks 0  
fill ~53 ~2 ~39 ~59 ~2 ~39 planks 0  
fill ~53 ~2 ~40 ~59 ~2 ~40 planks 0  
fill ~53 ~2 ~41 ~59 ~2 ~41 planks 0 
setblock ~54 ~2 ~36 stone_stairs 2  
fill ~54 ~2 ~43 ~54 ~3 ~43 cobblestone 0  
fill ~54 ~2 ~44 ~54 ~3 ~44 cobblestone 0  
fill ~54 ~2 ~45 ~54 ~3 ~45 cobblestone 0  
fill ~54 ~2 ~46 ~54 ~3 ~46 cobblestone 0  
fill ~54 ~2 ~47 ~60 ~2 ~47 cobblestone 0  
fill ~55 ~2 ~42 ~59 ~2 ~42 planks 0  
fill ~55 ~2 ~43 ~59 ~2 ~43 planks 0  
fill ~55 ~2 ~44 ~59 ~2 ~44 planks 0  
fill ~55 ~2 ~45 ~59 ~2 ~45 planks 0  
fill ~55 ~2 ~46 ~59 ~2 ~46 planks 0  
fill ~56 ~2 ~30 ~58 ~2 ~30 double_stone_slab 0  
fill ~56 ~2 ~31 ~58 ~2 ~31 double_stone_slab 0  
fill ~56 ~2 ~32 ~58 ~2 ~32 double_stone_slab 0  
fill ~57 ~2 ~16 ~57 ~5 ~16 cobblestone 0  
fill ~57 ~2 ~17 ~57 ~5 ~17 cobblestone 0  
fill ~57 ~2 ~18 ~57 ~5 ~18 cobblestone 0  
fill ~57 ~2 ~19 ~57 ~5 ~19 cobblestone 0  
fill ~57 ~2 ~20 ~57 ~5 ~20 cobblestone 0 
setblock ~57 ~2 ~27 cobblestone 0  
fill ~57 ~2 ~66 ~60 ~2 ~66 cobblestone 0  
fill ~57 ~2 ~67 ~57 ~2 ~70 cobblestone 0  
fill ~58 ~2 ~-3 ~60 ~2 ~-3 glass 0  
fill ~58 ~2 ~27 ~59 ~2 ~27 grass 0  
fill ~58 ~2 ~67 ~59 ~2 ~67 dirt 0  
fill ~58 ~2 ~68 ~59 ~2 ~68 dirt 0  
fill ~58 ~2 ~69 ~59 ~2 ~69 dirt 0  
fill ~58 ~2 ~70 ~60 ~2 ~70 cobblestone 0  
fill ~58 ~2 ~93 ~60 ~2 ~93 glass 0  
fill ~59 ~2 ~29 ~59 ~3 ~29 cobblestone 0  
fill ~59 ~2 ~30 ~59 ~3 ~30 cobblestone 0  
fill ~59 ~2 ~31 ~59 ~3 ~31 cobblestone 0  
fill ~59 ~2 ~32 ~59 ~3 ~32 cobblestone 0  
fill ~60 ~2 ~38 ~60 ~3 ~38 cobblestone 0  
fill ~60 ~2 ~39 ~60 ~3 ~39 cobblestone 0  
fill ~60 ~2 ~40 ~60 ~3 ~40 cobblestone 0  
fill ~60 ~2 ~41 ~60 ~3 ~41 cobblestone 0  
fill ~60 ~2 ~42 ~60 ~3 ~42 cobblestone 0  
fill ~60 ~2 ~43 ~60 ~3 ~43 cobblestone 0  
fill ~60 ~2 ~44 ~60 ~3 ~44 cobblestone 0  
fill ~60 ~2 ~45 ~60 ~3 ~45 cobblestone 0  
fill ~60 ~2 ~46 ~60 ~3 ~46 cobblestone 0  
fill ~60 ~2 ~67 ~60 ~2 ~70 cobblestone 0  
fill ~60 ~2 ~74 ~68 ~2 ~74 cobblestone 0  
fill ~60 ~2 ~75 ~60 ~3 ~75 cobblestone 0  
fill ~60 ~2 ~76 ~60 ~3 ~76 cobblestone 0  
fill ~60 ~2 ~77 ~60 ~3 ~77 cobblestone 0  
fill ~60 ~2 ~78 ~60 ~3 ~78 cobblestone 0  
fill ~60 ~2 ~79 ~62 ~2 ~79 cobblestone 0  
fill ~61 ~2 ~-2 ~63 ~2 ~-2 glass 0  
fill ~61 ~2 ~75 ~67 ~2 ~75 planks 0  
fill ~61 ~2 ~76 ~67 ~2 ~76 planks 0  
fill ~61 ~2 ~77 ~67 ~2 ~77 planks 0  
fill ~61 ~2 ~78 ~67 ~2 ~78 planks 0  
fill ~61 ~2 ~92 ~63 ~2 ~92 glass 0 
setblock ~62 ~2 ~73 stone_stairs 2  
fill ~62 ~2 ~80 ~62 ~3 ~80 cobblestone 0  
fill ~62 ~2 ~81 ~62 ~3 ~81 cobblestone 0  
fill ~62 ~2 ~82 ~62 ~3 ~82 cobblestone 0  
fill ~62 ~2 ~83 ~62 ~3 ~83 cobblestone 0  
fill ~62 ~2 ~84 ~68 ~2 ~84 cobblestone 0  
fill ~63 ~2 ~79 ~67 ~2 ~79 planks 0  
fill ~63 ~2 ~80 ~67 ~2 ~80 planks 0  
fill ~63 ~2 ~81 ~67 ~2 ~81 planks 0  
fill ~63 ~2 ~82 ~67 ~2 ~82 planks 0  
fill ~63 ~2 ~83 ~67 ~2 ~83 planks 0  
fill ~64 ~2 ~-1 ~65 ~2 ~-1 glass 0  
fill ~64 ~2 ~91 ~65 ~2 ~91 glass 0  
fill ~65 ~2 ~1 ~67 ~2 ~1 log 0  
fill ~65 ~2 ~2 ~65 ~2 ~13 log 0  
fill ~66 ~2 ~0 ~67 ~2 ~0 glass 0  
fill ~66 ~2 ~2 ~69 ~2 ~2 farmland 7  
fill ~66 ~2 ~3 ~71 ~2 ~3 farmland 7  
fill ~66 ~2 ~5 ~72 ~2 ~5 farmland 7  
fill ~66 ~2 ~6 ~72 ~2 ~6 farmland 7  
fill ~66 ~2 ~7 ~73 ~2 ~7 log 0  
fill ~66 ~2 ~8 ~72 ~2 ~8 farmland 7  
fill ~66 ~2 ~9 ~72 ~2 ~9 farmland 7  
fill ~66 ~2 ~11 ~72 ~2 ~11 farmland 7  
fill ~66 ~2 ~12 ~72 ~2 ~12 farmland 7  
fill ~66 ~2 ~13 ~73 ~2 ~13 log 0  
fill ~66 ~2 ~41 ~70 ~2 ~41 cobblestone 0  
fill ~66 ~2 ~42 ~70 ~2 ~42 cobblestone 0  
fill ~66 ~2 ~43 ~70 ~2 ~43 cobblestone 0  
fill ~66 ~2 ~44 ~70 ~2 ~44 cobblestone 0  
fill ~66 ~2 ~62 ~72 ~2 ~62 log 0  
fill ~66 ~2 ~63 ~66 ~2 ~70 log 0  
fill ~66 ~2 ~90 ~67 ~2 ~90 glass 0  
fill ~67 ~2 ~37 ~69 ~2 ~37 cobblestone 0  
fill ~67 ~2 ~38 ~69 ~2 ~38 cobblestone 0  
fill ~67 ~2 ~39 ~69 ~2 ~39 cobblestone 0  
fill ~67 ~2 ~40 ~69 ~2 ~40 cobblestone 0  
fill ~67 ~2 ~45 ~69 ~2 ~45 cobblestone 0  
fill ~67 ~2 ~63 ~68 ~2 ~63 farmland 7  
fill ~67 ~2 ~64 ~68 ~2 ~64 farmland 7  
fill ~67 ~2 ~65 ~68 ~2 ~65 farmland 7  
fill ~67 ~2 ~66 ~68 ~2 ~66 farmland 7  
fill ~67 ~2 ~67 ~68 ~2 ~67 farmland 7  
fill ~67 ~2 ~68 ~68 ~2 ~68 farmland 7  
fill ~67 ~2 ~69 ~68 ~2 ~69 farmland 7  
fill ~67 ~2 ~70 ~72 ~2 ~70 log 0  
fill ~68 ~2 ~1 ~69 ~2 ~1 glass 0  
fill ~68 ~2 ~26 ~72 ~2 ~26 cobblestone 0  
fill ~68 ~2 ~27 ~72 ~2 ~27 cobblestone 0  
fill ~68 ~2 ~28 ~72 ~2 ~28 cobblestone 0  
fill ~68 ~2 ~29 ~72 ~2 ~29 cobblestone 0 
setblock ~68 ~2 ~36 stone_stairs 2  
fill ~68 ~2 ~75 ~68 ~3 ~75 cobblestone 0  
fill ~68 ~2 ~76 ~68 ~3 ~76 cobblestone 0  
fill ~68 ~2 ~77 ~68 ~3 ~77 cobblestone 0  
fill ~68 ~2 ~78 ~68 ~3 ~78 cobblestone 0  
fill ~68 ~2 ~79 ~68 ~3 ~79 cobblestone 0  
fill ~68 ~2 ~80 ~68 ~3 ~80 cobblestone 0  
fill ~68 ~2 ~81 ~68 ~3 ~81 cobblestone 0  
fill ~68 ~2 ~82 ~68 ~3 ~82 cobblestone 0  
fill ~68 ~2 ~83 ~68 ~3 ~83 cobblestone 0  
fill ~68 ~2 ~89 ~69 ~2 ~89 glass 0  
fill ~69 ~2 ~25 ~71 ~2 ~25 cobblestone 0  
fill ~69 ~2 ~30 ~71 ~2 ~30 cobblestone 0  
fill ~69 ~2 ~31 ~71 ~2 ~31 cobblestone 0  
fill ~69 ~2 ~32 ~71 ~2 ~32 cobblestone 0  
fill ~69 ~2 ~33 ~71 ~2 ~33 cobblestone 0  
fill ~70 ~2 ~2 ~71 ~2 ~2 glass 0 
setblock ~70 ~2 ~34 stone_stairs 3  
fill ~70 ~2 ~63 ~71 ~2 ~63 farmland 7  
fill ~70 ~2 ~64 ~71 ~2 ~64 farmland 7  
fill ~70 ~2 ~65 ~71 ~2 ~65 farmland 7  
fill ~70 ~2 ~66 ~71 ~2 ~66 farmland 7  
fill ~70 ~2 ~67 ~71 ~2 ~67 farmland 7  
fill ~70 ~2 ~68 ~71 ~2 ~68 farmland 7  
fill ~70 ~2 ~69 ~71 ~2 ~69 farmland 7  
fill ~70 ~2 ~88 ~71 ~2 ~88 glass 0  
fill ~72 ~2 ~3 ~72 ~7 ~3 glass 0  
fill ~72 ~2 ~63 ~72 ~2 ~70 log 0  
fill ~72 ~2 ~87 ~72 ~7 ~87 glass 0  
fill ~73 ~2 ~4 ~73 ~9 ~4 glass 0  
fill ~73 ~2 ~5 ~73 ~2 ~13 log 0  
fill ~73 ~2 ~19 ~73 ~4 ~19 fence 0  
fill ~73 ~2 ~86 ~73 ~9 ~86 glass 0  
fill ~75 ~2 ~11 ~79 ~2 ~11 glass 0  
fill ~75 ~2 ~12 ~75 ~2 ~15 glass 0  
fill ~76 ~2 ~6 ~77 ~2 ~6 glass 0  
fill ~76 ~2 ~15 ~79 ~2 ~15 glass 0  
fill ~76 ~2 ~74 ~80 ~2 ~74 glass 0  
fill ~76 ~2 ~75 ~76 ~2 ~78 glass 0  
fill ~76 ~2 ~84 ~77 ~2 ~84 glass 0  
fill ~77 ~2 ~7 ~77 ~9 ~7 glass 0  
fill ~77 ~2 ~78 ~80 ~2 ~78 glass 0  
fill ~79 ~2 ~12 ~79 ~2 ~15 glass 0  
fill ~80 ~2 ~75 ~80 ~2 ~78 glass 0  
fill ~83 ~2 ~13 ~83 ~9 ~13 glass 0  
fill ~86 ~2 ~17 ~86 ~9 ~17 glass 0  
fill ~86 ~2 ~73 ~86 ~9 ~73 glass 0  
fill ~88 ~2 ~43 ~92 ~2 ~43 glass 0  
fill ~88 ~2 ~44 ~88 ~2 ~47 glass 0  
fill ~89 ~2 ~47 ~92 ~2 ~47 glass 0  
fill ~92 ~2 ~44 ~92 ~2 ~47 glass 0  
fill ~94 ~2 ~38 ~94 ~10 ~38 glass 0  
fill ~94 ~2 ~52 ~94 ~10 ~52 glass 0  
fill ~-3 ~3 ~33 ~-3 ~10 ~33 glass 0  
fill ~-3 ~3 ~57 ~-3 ~10 ~57 glass 0  
fill ~7 ~3 ~13 ~7 ~9 ~13 glass 0  
fill ~7 ~3 ~77 ~7 ~9 ~77 glass 0  
fill ~13 ~3 ~6 ~14 ~3 ~6 glass 0  
fill ~13 ~3 ~7 ~13 ~9 ~7 glass 0  
fill ~13 ~3 ~83 ~13 ~9 ~83 glass 0  
fill ~14 ~3 ~84 ~14 ~8 ~84 glass 0  
fill ~15 ~3 ~37 ~15 ~5 ~37 cobblestone 0  
fill ~15 ~3 ~38 ~15 ~5 ~38 planks 0  
fill ~15 ~3 ~39 ~15 ~3 ~40 planks 0  
fill ~15 ~3 ~41 ~15 ~5 ~41 cobblestone 0  
fill ~16 ~3 ~37 ~16 ~5 ~37 planks 0  
fill ~16 ~3 ~41 ~18 ~3 ~41 planks 0  
fill ~17 ~3 ~74 ~17 ~4 ~74 cobblestone 0  
fill ~17 ~3 ~79 ~18 ~3 ~79 cobblestone 0  
fill ~18 ~3 ~37 ~18 ~5 ~37 planks 0  
fill ~18 ~3 ~40 ~18 ~6 ~40 ladder 2 
setblock ~18 ~3 ~74 wooden_door 5  
fill ~18 ~3 ~84 ~24 ~3 ~84 cobblestone 0  
fill ~19 ~3 ~2 ~20 ~3 ~2 glass 0  
fill ~19 ~3 ~37 ~19 ~5 ~37 cobblestone 0   
fill ~19 ~3 ~38 ~19 ~5 ~38 planks 0  
fill ~19 ~3 ~39 ~19 ~3 ~40 planks 0  
fill ~19 ~3 ~41 ~19 ~5 ~41 cobblestone 0  
fill ~19 ~3 ~74 ~24 ~3 ~74 cobblestone 0  
fill ~19 ~3 ~88 ~20 ~3 ~88 glass 0  
fill ~20 ~3 ~26 ~21 ~3 ~26 carrots 7  
fill ~20 ~3 ~27 ~21 ~3 ~27 carrots 7  
fill ~20 ~3 ~28 ~21 ~3 ~28 carrots 7  
fill ~20 ~3 ~29 ~21 ~3 ~29 carrots 7  
fill ~20 ~3 ~30 ~21 ~3 ~30 carrots 7  
fill ~20 ~3 ~31 ~21 ~3 ~31 carrots 7  
fill ~20 ~3 ~32 ~21 ~3 ~32 carrots 7  
fill ~20 ~3 ~66 ~20 ~5 ~66 log 0  
fill ~20 ~3 ~67 ~20 ~5 ~67 planks 0  
fill ~20 ~3 ~68 ~20 ~3 ~69 planks 0  
fill ~20 ~3 ~70 ~20 ~5 ~70 log 0  
fill ~21 ~3 ~1 ~22 ~3 ~1 glass 0  
fill ~21 ~3 ~66 ~22 ~3 ~66 planks 0 
setblock ~21 ~3 ~70 wooden_door 5  
fill ~21 ~3 ~89 ~22 ~3 ~89 glass 0  
fill ~22 ~3 ~70 ~22 ~5 ~70 planks 0  
fill ~23 ~3 ~0 ~24 ~3 ~0 glass 0  
fill ~23 ~3 ~26 ~24 ~3 ~26 wheat 7  
fill ~23 ~3 ~27 ~24 ~3 ~27 wheat 7  
fill ~23 ~3 ~28 ~24 ~3 ~28 wheat 7  
fill ~23 ~3 ~29 ~24 ~3 ~29 wheat 7  
fill ~23 ~3 ~30 ~24 ~3 ~30 wheat 7  
fill ~23 ~3 ~31 ~24 ~3 ~31 wheat 7  
fill ~23 ~3 ~32 ~24 ~3 ~32 wheat 7  
fill ~23 ~3 ~37 ~23 ~5 ~37 log 0  
fill ~23 ~3 ~38 ~23 ~5 ~38 planks 0  
fill ~23 ~3 ~39 ~23 ~3 ~40 planks 0  
fill ~23 ~3 ~41 ~23 ~5 ~41 log 0  
fill ~23 ~3 ~66 ~23 ~5 ~66 log 0  
fill ~23 ~3 ~67 ~23 ~5 ~67 planks 0  
fill ~23 ~3 ~68 ~23 ~3 ~69 planks 0  
fill ~23 ~3 ~70 ~23 ~5 ~70 log 0  
fill ~23 ~3 ~90 ~24 ~3 ~90 glass 0 
setblock ~24 ~3 ~37 wooden_door 5  
fill ~24 ~3 ~41 ~25 ~3 ~41 planks 0  
fill ~25 ~3 ~-1 ~26 ~3 ~-1 glass 0  
fill ~25 ~3 ~37 ~25 ~5 ~37 planks 0 
setblock ~25 ~3 ~40 fence 0  
fill ~25 ~3 ~91 ~26 ~3 ~91 glass 0  
fill ~26 ~3 ~37 ~26 ~5 ~37 log 0  
fill ~26 ~3 ~38 ~26 ~5 ~38 planks 0  
fill ~26 ~3 ~39 ~26 ~3 ~40 planks 0  
fill ~26 ~3 ~41 ~26 ~5 ~41 log 0  
fill ~27 ~3 ~-2 ~29 ~3 ~-2 glass 0  
fill ~27 ~3 ~92 ~29 ~3 ~92 glass 0  
fill ~30 ~3 ~-3 ~33 ~3 ~-3 glass 0  
fill ~30 ~3 ~93 ~33 ~3 ~93 glass 0  
fill ~31 ~3 ~75 ~32 ~3 ~75 wheat 7  
fill ~31 ~3 ~76 ~32 ~3 ~76 wheat 7  
fill ~31 ~3 ~77 ~32 ~3 ~77 wheat 7  
fill ~31 ~3 ~78 ~32 ~3 ~78 wheat 7  
fill ~31 ~3 ~79 ~32 ~3 ~79 wheat 7  
fill ~31 ~3 ~80 ~32 ~3 ~80 wheat 7  
fill ~31 ~3 ~81 ~32 ~3 ~81 wheat 7  
fill ~33 ~3 ~41 ~37 ~3 ~41 fence 0  
fill ~33 ~3 ~42 ~33 ~3 ~47 fence 0  
fill ~34 ~3 ~-4 ~38 ~3 ~-4 glass 0  
fill ~34 ~3 ~29 ~34 ~5 ~29 log 0  
fill ~34 ~3 ~30 ~34 ~5 ~30 planks 0  
fill ~34 ~3 ~31 ~34 ~3 ~32 planks 0  
fill ~34 ~3 ~33 ~34 ~5 ~33 log 0  
fill ~34 ~3 ~47 ~37 ~3 ~47 fence 0  
fill ~34 ~3 ~75 ~35 ~3 ~75 potatoes 7  
fill ~34 ~3 ~76 ~35 ~3 ~76 potatoes 7  
fill ~34 ~3 ~77 ~35 ~3 ~77 potatoes 7  
fill ~34 ~3 ~78 ~35 ~3 ~78 potatoes 7  
fill ~34 ~3 ~79 ~35 ~3 ~79 potatoes 7  
fill ~34 ~3 ~80 ~35 ~3 ~80 potatoes 7  
fill ~34 ~3 ~81 ~35 ~3 ~81 potatoes 7  
fill ~34 ~3 ~94 ~38 ~3 ~94 glass 0  
fill ~35 ~3 ~29 ~36 ~3 ~29 planks 0 
setblock ~35 ~3 ~30 fence 0 
setblock ~35 ~3 ~33 wooden_door 5  
fill ~36 ~3 ~14 ~42 ~3 ~14 carrots 7  
fill ~36 ~3 ~15 ~42 ~3 ~15 carrots 7  
fill ~36 ~3 ~17 ~42 ~3 ~17 carrots 7  
fill ~36 ~3 ~18 ~42 ~3 ~18 carrots 7  
fill ~36 ~3 ~20 ~42 ~3 ~20 potatoes 7  
fill ~36 ~3 ~21 ~42 ~3 ~21 potatoes 7  
fill ~36 ~3 ~23 ~42 ~3 ~23 potatoes 7  
fill ~36 ~3 ~24 ~42 ~3 ~24 potatoes 7  
fill ~36 ~3 ~33 ~36 ~5 ~33 planks 0  
fill ~36 ~3 ~56 ~42 ~3 ~56 wheat 7  
fill ~36 ~3 ~57 ~42 ~3 ~57 wheat 7  
fill ~36 ~3 ~59 ~42 ~3 ~59 potatoes 7  
fill ~36 ~3 ~60 ~42 ~3 ~60 potatoes 7  
fill ~37 ~3 ~29 ~37 ~5 ~29 log 0  
fill ~37 ~3 ~30 ~37 ~5 ~30 planks 0  
fill ~37 ~3 ~31 ~37 ~3 ~32 planks 0  
fill ~37 ~3 ~33 ~37 ~5 ~33 log 0  
fill ~37 ~3 ~75 ~38 ~3 ~75 potatoes 7  
fill ~37 ~3 ~76 ~38 ~3 ~76 potatoes 7  
fill ~37 ~3 ~77 ~38 ~3 ~77 potatoes 7  
fill ~37 ~3 ~78 ~38 ~3 ~78 potatoes 7  
fill ~37 ~3 ~79 ~38 ~3 ~79 potatoes 7  
fill ~37 ~3 ~80 ~38 ~3 ~80 potatoes 7  
fill ~37 ~3 ~81 ~38 ~3 ~81 potatoes 7  
fill ~38 ~3 ~39 ~43 ~3 ~39 cobblestone 0 
setblock ~38 ~3 ~45 wooden_door 6  
fill ~38 ~3 ~47 ~43 ~3 ~47 cobblestone 0  
fill ~39 ~3 ~-5 ~51 ~3 ~-5 glass 0  
fill ~39 ~3 ~40 ~39 ~2 ~40 planks 0 
setblock ~39 ~3 ~41 oak_stairs 1  
fill ~39 ~3 ~95 ~51 ~3 ~95 glass 0 
setblock ~40 ~3 ~40 oak_stairs 3 
setblock ~40 ~3 ~41 fence 0  
fill ~40 ~3 ~75 ~41 ~3 ~75 wheat 7  
fill ~40 ~3 ~76 ~41 ~3 ~76 wheat 7  
fill ~40 ~3 ~77 ~41 ~3 ~77 wheat 7  
fill ~40 ~3 ~78 ~41 ~3 ~78 wheat 7  
fill ~40 ~3 ~79 ~41 ~3 ~79 wheat 7  
fill ~40 ~3 ~80 ~41 ~3 ~80 wheat 7  
fill ~40 ~3 ~81 ~41 ~3 ~81 wheat 7  
fill ~41 ~3 ~45 ~42 ~3 ~45 double_stone_slab 0 
setblock ~43 ~3 ~41 wooden_door 6  
fill ~43 ~3 ~42 ~43 ~3 ~47 cobblestone 0  
fill ~44 ~3 ~34 ~47 ~3 ~34 cobblestone 0  
fill ~44 ~3 ~37 ~47 ~3 ~37 cobblestone 0  
fill ~47 ~3 ~13 ~52 ~3 ~13 cobblestone 0 
setblock ~47 ~3 ~15 wooden_door 4  
fill ~47 ~3 ~16 ~47 ~3 ~21 cobblestone 0  
fill ~47 ~3 ~41 ~47 ~5 ~41 log 0 
setblock ~47 ~3 ~42 wooden_door 4  
fill ~47 ~3 ~43 ~47 ~5 ~43 planks 0  
fill ~47 ~3 ~44 ~47 ~5 ~44 log 0  
fill ~47 ~3 ~49 ~47 ~5 ~49 cobblestone 0  
fill ~47 ~3 ~50 ~47 ~5 ~50 planks 0  
fill ~47 ~3 ~52 ~47 ~5 ~52 planks 0  
fill ~47 ~3 ~53 ~47 ~5 ~53 cobblestone 0  
fill ~47 ~3 ~57 ~52 ~3 ~57 cobblestone 0 
setblock ~47 ~3 ~58 wooden_door 4  
fill ~47 ~3 ~59 ~47 ~2 ~59 cobblestone 0  
fill ~47 ~3 ~60 ~47 ~2 ~60 cobblestone 0  
fill ~47 ~3 ~61 ~47 ~2 ~61 cobblestone 0  
fill ~47 ~3 ~62 ~47 ~2 ~62 cobblestone 0  
fill ~47 ~3 ~63 ~47 ~2 ~63 cobblestone 0  
fill ~47 ~3 ~64 ~47 ~2 ~64 cobblestone 0  
fill ~47 ~3 ~65 ~52 ~3 ~65 cobblestone 0  
fill ~47 ~3 ~66 ~47 ~5 ~66 cobblestone 0  
fill ~47 ~3 ~67 ~47 ~5 ~67 planks 0  
fill ~47 ~3 ~68 ~47 ~3 ~69 planks 0  
fill ~47 ~3 ~70 ~47 ~5 ~70 cobblestone 0  
fill ~48 ~3 ~21 ~57 ~3 ~21 cobblestone 0  
fill ~48 ~3 ~41 ~50 ~3 ~41 planks 0  
fill ~48 ~3 ~44 ~50 ~3 ~44 planks 0  
fill ~48 ~3 ~49 ~50 ~3 ~49 planks 0  
fill ~48 ~3 ~53 ~50 ~3 ~53 planks 0 
setblock ~48 ~3 ~64 crafting_table 0  
fill ~48 ~3 ~66 ~50 ~3 ~66 planks 0  
fill ~48 ~3 ~70 ~48 ~5 ~70 planks 0  
fill ~49 ~3 ~74 ~49 ~5 ~74 cobblestone 0  
fill ~49 ~3 ~75 ~49 ~5 ~75 planks 0  
fill ~49 ~3 ~76 ~49 ~3 ~77 planks 0  
fill ~49 ~3 ~78 ~49 ~5 ~78 cobblestone 0  
fill ~50 ~3 ~52 ~50 ~6 ~52 ladder 4 
setblock ~50 ~3 ~61 fence 0 
setblock ~50 ~3 ~63 fence 0 
setblock ~50 ~3 ~64 oak_stairs 2  
fill ~50 ~3 ~70 ~50 ~5 ~70 planks 0  
fill ~50 ~3 ~74 ~50 ~5 ~74 planks 0  
fill ~50 ~3 ~78 ~52 ~3 ~78 planks 0  
fill ~51 ~3 ~28 ~56 ~3 ~28 cobblestone 0  
fill ~51 ~3 ~33 ~52 ~3 ~33 cobblestone 0  
fill ~51 ~3 ~41 ~51 ~5 ~41 log 0  
fill ~51 ~3 ~42 ~51 ~5 ~42 planks 0  
fill ~51 ~3 ~43 ~51 ~5 ~43 planks 0  
fill ~51 ~3 ~44 ~51 ~5 ~44 log 0  
fill ~51 ~3 ~49 ~51 ~5 ~49 cobblestone 0  
fill ~51 ~3 ~50 ~51 ~5 ~50 planks 0  
fill ~51 ~3 ~51 ~51 ~3 ~52 planks 0  
fill ~51 ~3 ~53 ~51 ~5 ~53 cobblestone 0  
fill ~51 ~3 ~60 ~51 ~3 ~63 oak_stairs 0 
setblock ~51 ~3 ~64 planks 0  
fill ~51 ~3 ~66 ~51 ~5 ~66 cobblestone 0  
fill ~51 ~3 ~67 ~51 ~5 ~67 planks 0  
fill ~51 ~3 ~68 ~51 ~3 ~69 planks 0  
fill ~51 ~3 ~70 ~51 ~5 ~70 cobblestone 0  
fill ~52 ~3 ~-4 ~56 ~3 ~-4 glass 0  
fill ~52 ~3 ~15 ~57 ~3 ~15 cobblestone 0  
fill ~52 ~3 ~29 ~52 ~2 ~29 planks 0 
setblock ~52 ~3 ~30 oak_stairs 1  
fill ~52 ~3 ~37 ~53 ~3 ~37 cobblestone 0  
fill ~52 ~3 ~41 ~52 ~3 ~42 cobblestone 0  
fill ~52 ~3 ~58 ~52 ~3 ~65 cobblestone 0  
fill ~52 ~3 ~74 ~52 ~5 ~74 planks 0  
fill ~52 ~3 ~77 ~52 ~6 ~77 ladder 2  
fill ~52 ~3 ~94 ~56 ~3 ~94 glass 0  
fill ~53 ~3 ~23 ~59 ~3 ~23 fence 0  
fill ~53 ~3 ~24 ~53 ~3 ~27 fence 0 
setblock ~53 ~3 ~29 oak_stairs 3 
setblock ~53 ~3 ~30 fence 0 
setblock ~53 ~3 ~33 wooden_door 5  
fill ~53 ~3 ~42 ~54 ~3 ~42 cobblestone 0  
fill ~53 ~3 ~74 ~53 ~5 ~74 cobblestone 0  
fill ~53 ~3 ~75 ~53 ~5 ~75 planks 0  
fill ~53 ~3 ~76 ~53 ~3 ~77 planks 0  
fill ~53 ~3 ~78 ~53 ~5 ~78 cobblestone 0  
fill ~54 ~3 ~33 ~59 ~3 ~33 cobblestone 0 
setblock ~54 ~3 ~37 wooden_door 5  
fill ~54 ~3 ~47 ~60 ~3 ~47 cobblestone 0  
fill ~55 ~3 ~37 ~60 ~3 ~37 cobblestone 0  
fill ~57 ~3 ~-3 ~60 ~3 ~-3 glass 0 
setblock ~57 ~3 ~28 wooden_door 5  
fill ~57 ~3 ~31 ~57 ~3 ~32 double_stone_slab 0  
fill ~57 ~3 ~66 ~57 ~5 ~66 log 0  
fill ~57 ~3 ~67 ~57 ~5 ~67 planks 0  
fill ~57 ~3 ~68 ~57 ~3 ~69 planks 0  
fill ~57 ~3 ~70 ~57 ~5 ~70 log 0  
fill ~57 ~3 ~93 ~60 ~3 ~93 glass 0  
fill ~58 ~3 ~28 ~59 ~3 ~28 cobblestone 0  
fill ~58 ~3 ~66 ~59 ~3 ~66 planks 0 
setblock ~58 ~3 ~67 fence 0 
setblock ~58 ~3 ~70 wooden_door 5  
fill ~59 ~3 ~24 ~59 ~3 ~27 fence 0  
fill ~59 ~3 ~70 ~59 ~5 ~70 planks 0  
fill ~60 ~3 ~66 ~60 ~5 ~66 log 0  
fill ~60 ~3 ~67 ~60 ~5 ~67 planks 0  
fill ~60 ~3 ~68 ~60 ~3 ~69 planks 0  
fill ~60 ~3 ~70 ~60 ~5 ~70 log 0  
fill ~60 ~3 ~74 ~61 ~3 ~74 cobblestone 0  
fill ~60 ~3 ~79 ~62 ~3 ~79 cobblestone 0  
fill ~61 ~3 ~-2 ~63 ~3 ~-2 glass 0  
fill ~61 ~3 ~92 ~63 ~3 ~92 glass 0 
setblock ~62 ~3 ~74 wooden_door 5  
fill ~62 ~3 ~84 ~68 ~3 ~84 cobblestone 0  
fill ~63 ~3 ~74 ~68 ~3 ~74 cobblestone 0  
fill ~64 ~3 ~-1 ~65 ~3 ~-1 glass 0  
fill ~64 ~3 ~91 ~65 ~3 ~91 glass 0  
fill ~66 ~3 ~0 ~67 ~3 ~0 glass 0  
fill ~66 ~3 ~2 ~69 ~3 ~2 potatoes 7  
fill ~66 ~3 ~3 ~71 ~3 ~3 potatoes 7  
fill ~66 ~3 ~5 ~72 ~3 ~5 wheat 7  
fill ~66 ~3 ~6 ~72 ~3 ~6 wheat 7  
fill ~66 ~3 ~8 ~72 ~3 ~8 potatoes 7  
fill ~66 ~3 ~9 ~72 ~3 ~9 potatoes 7  
fill ~66 ~3 ~11 ~72 ~3 ~11 wheat 7  
fill ~66 ~3 ~12 ~72 ~3 ~12 wheat 7  
fill ~66 ~3 ~38 ~66 ~12 ~38 cobblestone 0  
fill ~66 ~3 ~39 ~66 ~3 ~44 cobblestone 0  
fill ~66 ~3 ~90 ~67 ~3 ~90 glass 0  
fill ~67 ~3 ~37 ~67 ~12 ~37 cobblestone 0 
setblock ~67 ~3 ~42 stone_stairs 2  
fill ~67 ~3 ~43 ~67 ~3 ~45 cobblestone 0  
fill ~67 ~3 ~63 ~68 ~3 ~63 wheat 7  
fill ~67 ~3 ~64 ~68 ~3 ~64 wheat 7  
fill ~67 ~3 ~65 ~68 ~3 ~65 wheat 7  
fill ~67 ~3 ~66 ~68 ~3 ~66 wheat 7  
fill ~67 ~3 ~67 ~68 ~3 ~67 wheat 7  
fill ~67 ~3 ~68 ~68 ~3 ~68 wheat 7  
fill ~67 ~3 ~69 ~68 ~3 ~69 wheat 7  
fill ~68 ~3 ~1 ~69 ~3 ~1 glass 0  
fill ~68 ~3 ~26 ~72 ~3 ~26 cobblestone 0  
fill ~68 ~3 ~27 ~69 ~3 ~27 cobblestone 0  
fill ~68 ~3 ~28 ~68 ~6 ~28 cobblestone 0  
fill ~68 ~3 ~29 ~68 ~6 ~29 cobblestone 0  
fill ~68 ~3 ~30 ~68 ~12 ~30 cobblestone 0  
fill ~68 ~3 ~31 ~68 ~3 ~32 cobblestone 0 
setblock ~68 ~3 ~37 wooden_door 5 
setblock ~68 ~3 ~43 stone_stairs 2  
fill ~68 ~3 ~44 ~70 ~3 ~44 cobblestone 0  
fill ~68 ~3 ~45 ~69 ~3 ~45 cobblestone 0  
fill ~68 ~3 ~89 ~69 ~3 ~89 glass 0  
fill ~69 ~3 ~25 ~71 ~3 ~25 cobblestone 0 
setblock ~69 ~3 ~28 stone_stairs 3  
fill ~69 ~3 ~33 ~69 ~12 ~33 cobblestone 0  
fill ~69 ~3 ~37 ~69 ~12 ~37 cobblestone 0  
fill ~69 ~3 ~40 ~69 ~11 ~40 ladder 4 
setblock ~69 ~3 ~42 stone_stairs 2  
fill ~69 ~3 ~43 ~70 ~3 ~43 cobblestone 0  
fill ~70 ~3 ~2 ~71 ~3 ~2 glass 0 
setblock ~70 ~3 ~27 stone_stairs 3 
setblock ~70 ~3 ~33 wooden_door 1  
fill ~70 ~3 ~38 ~70 ~12 ~38 cobblestone 0  
fill ~70 ~3 ~39 ~70 ~3 ~44 cobblestone 0  
fill ~70 ~3 ~63 ~71 ~3 ~63 wheat 7  
fill ~70 ~3 ~64 ~71 ~3 ~64 wheat 7  
fill ~70 ~3 ~65 ~71 ~3 ~65 wheat 7  
fill ~70 ~3 ~66 ~71 ~3 ~66 wheat 7  
fill ~70 ~3 ~67 ~71 ~3 ~67 wheat 7  
fill ~70 ~3 ~68 ~71 ~3 ~68 wheat 7  
fill ~70 ~3 ~69 ~71 ~3 ~69 wheat 7  
fill ~70 ~3 ~88 ~71 ~3 ~88 glass 0  
fill ~71 ~3 ~27 ~72 ~3 ~27 cobblestone 0 
setblock ~71 ~3 ~28 stone_stairs 3  
fill ~71 ~3 ~30 ~71 ~11 ~30 ladder 4  
fill ~71 ~3 ~33 ~71 ~12 ~33 cobblestone 0  
fill ~72 ~3 ~28 ~72 ~6 ~28 cobblestone 0  
fill ~72 ~3 ~29 ~72 ~6 ~29 cobblestone 0  
fill ~72 ~3 ~30 ~72 ~12 ~30 cobblestone 0  
fill ~72 ~3 ~31 ~72 ~3 ~32 cobblestone 0  
fill ~76 ~3 ~6 ~76 ~8 ~6 glass 0  
fill ~76 ~3 ~84 ~76 ~8 ~84 glass 0  
fill ~77 ~3 ~83 ~77 ~9 ~83 glass 0  
fill ~83 ~3 ~77 ~83 ~9 ~77 glass 0  
fill ~93 ~3 ~33 ~93 ~10 ~33 glass 0  
fill ~93 ~3 ~57 ~93 ~10 ~57 glass 0  
fill ~-4 ~4 ~39 ~-4 ~10 ~39 glass 0  
fill ~-4 ~4 ~51 ~-4 ~10 ~51 glass 0  
fill ~14 ~4 ~6 ~14 ~8 ~6 glass 0 
setblock ~15 ~4 ~39 glass_pane 0  
fill ~15 ~4 ~40 ~15 ~5 ~40 planks 0  
fill ~16 ~4 ~41 ~16 ~5 ~41 planks 0 
setblock ~17 ~4 ~41 glass_pane 0  
fill ~17 ~4 ~79 ~18 ~4 ~79 cobblestone 0  
fill ~18 ~4 ~41 ~18 ~5 ~41 planks 0 
setblock ~18 ~4 ~74 wooden_door 8 
setblock ~18 ~4 ~80 log 0  
fill ~18 ~4 ~81 ~18 ~4 ~82 glass_pane 0 
setblock ~18 ~4 ~83 log 0  
fill ~18 ~4 ~84 ~24 ~4 ~84 cobblestone 0  
fill ~19 ~4 ~2 ~20 ~4 ~2 glass 0 
setblock ~19 ~4 ~39 glass_pane 0  
fill ~19 ~4 ~40 ~19 ~5 ~40 planks 0  
fill ~19 ~4 ~74 ~19 ~5 ~74 planks 0  
fill ~19 ~4 ~88 ~20 ~4 ~88 glass 0 
setblock ~20 ~4 ~68 glass_pane 0  
fill ~20 ~4 ~69 ~20 ~5 ~69 planks 0 
setblock ~20 ~4 ~74 log 0  
fill ~21 ~4 ~1 ~22 ~4 ~1 glass 0  
fill ~21 ~4 ~66 ~22 ~4 ~66 planks 0 
setblock ~21 ~4 ~70 wooden_door 8 
setblock ~21 ~4 ~74 glass_pane 0  
fill ~21 ~4 ~89 ~22 ~4 ~89 glass 0 
setblock ~22 ~4 ~74 log 0  
fill ~23 ~4 ~0 ~24 ~4 ~0 glass 0 
setblock ~23 ~4 ~39 glass_pane 0  
fill ~23 ~4 ~40 ~23 ~5 ~40 planks 0 
setblock ~23 ~4 ~68 glass_pane 0  
fill ~23 ~4 ~69 ~23 ~5 ~69 planks 0  
fill ~23 ~4 ~74 ~23 ~5 ~74 planks 0  
fill ~23 ~4 ~90 ~24 ~4 ~90 glass 0 
setblock ~24 ~4 ~37 wooden_door 8  
fill ~24 ~4 ~41 ~25 ~4 ~41 planks 0  
fill ~24 ~4 ~74 ~24 ~5 ~74 cobblestone 0 
setblock ~24 ~4 ~75 log 0  
fill ~24 ~4 ~76 ~24 ~4 ~77 glass_pane 0 
setblock ~24 ~4 ~78 log 0 
setblock ~24 ~4 ~79 planks 0 
setblock ~24 ~4 ~80 log 0  
fill ~24 ~4 ~81 ~24 ~4 ~82 glass_pane 0 
setblock ~24 ~4 ~83 log 0  
fill ~25 ~4 ~-1 ~26 ~4 ~-1 glass 0 
setblock ~25 ~4 ~40 wooden_pressure_plate 0  
fill ~25 ~4 ~91 ~26 ~4 ~91 glass 0 
setblock ~26 ~4 ~39 glass_pane 0  
fill ~26 ~4 ~40 ~26 ~5 ~40 planks 0  
fill ~27 ~4 ~-2 ~29 ~4 ~-2 glass 0  
fill ~27 ~4 ~92 ~29 ~4 ~92 glass 0  
fill ~30 ~4 ~-3 ~33 ~4 ~-3 glass 0  
fill ~30 ~4 ~93 ~33 ~4 ~93 glass 0  
fill ~34 ~4 ~-4 ~39 ~4 ~-4 glass 0 
setblock ~34 ~4 ~31 glass_pane 0  
fill ~34 ~4 ~32 ~34 ~5 ~32 planks 0  
fill ~34 ~4 ~94 ~39 ~4 ~94 glass 0  
fill ~35 ~4 ~29 ~36 ~4 ~29 planks 0 
setblock ~35 ~4 ~30 wooden_pressure_plate 0 
setblock ~35 ~4 ~33 wooden_door 8 
setblock ~37 ~4 ~31 glass_pane 0  
fill ~37 ~4 ~32 ~37 ~5 ~32 planks 0  
fill ~38 ~4 ~39 ~38 ~5 ~39 cobblestone 0  
fill ~38 ~4 ~40 ~38 ~5 ~40 planks 0  
fill ~38 ~4 ~41 ~38 ~4 ~42 glass_pane 0  
fill ~38 ~4 ~43 ~38 ~5 ~43 planks 0  
fill ~38 ~4 ~44 ~38 ~5 ~44 planks 0 
setblock ~38 ~4 ~45 wooden_door 8  
fill ~38 ~4 ~46 ~38 ~5 ~46 planks 0  
fill ~38 ~4 ~47 ~38 ~5 ~47 cobblestone 0 
setblock ~39 ~4 ~39 log 0 
setblock ~39 ~4 ~47 log 0  
fill ~40 ~4 ~-5 ~50 ~4 ~-5 glass 0  
fill ~40 ~4 ~39 ~41 ~4 ~39 glass_pane 0 
setblock ~40 ~4 ~41 wooden_pressure_plate 0  
fill ~40 ~4 ~47 ~41 ~4 ~47 glass_pane 0  
fill ~40 ~4 ~95 ~50 ~4 ~95 glass 0 
setblock ~42 ~4 ~39 log 0 
setblock ~42 ~4 ~47 log 0  
fill ~43 ~4 ~39 ~43 ~5 ~39 cobblestone 0  
fill ~43 ~4 ~40 ~43 ~5 ~40 planks 0 
setblock ~43 ~4 ~41 wooden_door 8  
fill ~43 ~4 ~42 ~43 ~5 ~42 planks 0  
fill ~43 ~4 ~43 ~43 ~5 ~43 planks 0 
setblock ~43 ~4 ~44 glass_pane 0  
fill ~43 ~4 ~45 ~43 ~5 ~45 planks 0  
fill ~43 ~4 ~46 ~43 ~5 ~46 planks 0  
fill ~43 ~4 ~47 ~43 ~5 ~47 cobblestone 0  
fill ~44 ~4 ~34 ~44 ~5 ~34 fence 0  
fill ~44 ~4 ~37 ~44 ~5 ~37 fence 0  
fill ~47 ~4 ~13 ~47 ~5 ~13 cobblestone 0  
fill ~47 ~4 ~14 ~47 ~5 ~14 planks 0 
setblock ~47 ~4 ~15 wooden_door 8  
fill ~47 ~4 ~16 ~47 ~5 ~16 planks 0 
setblock ~47 ~4 ~17 log 0 
setblock ~47 ~4 ~18 glass_pane 0 
setblock ~47 ~4 ~19 log 0  
fill ~47 ~4 ~20 ~47 ~5 ~20 planks 0  
fill ~47 ~4 ~21 ~47 ~5 ~21 cobblestone 0  
fill ~47 ~4 ~34 ~47 ~5 ~34 fence 0  
fill ~47 ~4 ~37 ~47 ~5 ~37 fence 0 
setblock ~47 ~4 ~42 wooden_door 8  
fill ~47 ~4 ~57 ~47 ~7 ~57 cobblestone 0 
setblock ~47 ~4 ~58 wooden_door 8  
fill ~47 ~4 ~59 ~47 ~6 ~59 planks 0  
fill ~47 ~4 ~60 ~47 ~6 ~60 planks 0  
fill ~47 ~4 ~61 ~47 ~5 ~61 glass_pane 0  
fill ~47 ~4 ~62 ~47 ~5 ~62 glass_pane 0  
fill ~47 ~4 ~63 ~47 ~5 ~63 glass_pane 0  
fill ~47 ~4 ~64 ~47 ~6 ~64 planks 0  
fill ~47 ~4 ~65 ~47 ~7 ~65 cobblestone 0 
setblock ~47 ~4 ~68 glass_pane 0  
fill ~47 ~4 ~69 ~47 ~5 ~69 planks 0 
setblock ~48 ~4 ~13 log 0 
setblock ~48 ~4 ~21 log 0  
fill ~48 ~4 ~41 ~48 ~5 ~41 planks 0  
fill ~48 ~4 ~44 ~48 ~5 ~44 planks 0  
fill ~48 ~4 ~49 ~48 ~5 ~49 planks 0  
fill ~48 ~4 ~53 ~48 ~5 ~53 planks 0  
fill ~48 ~4 ~57 ~48 ~6 ~57 planks 0  
fill ~48 ~4 ~65 ~48 ~6 ~65 planks 0  
fill ~48 ~4 ~66 ~48 ~5 ~66 planks 0  
fill ~49 ~4 ~13 ~50 ~4 ~13 glass_pane 0  
fill ~49 ~4 ~21 ~50 ~4 ~21 glass_pane 0 
setblock ~49 ~4 ~41 glass_pane 0 
setblock ~49 ~4 ~44 glass_pane 0 
setblock ~49 ~4 ~49 glass_pane 0 
setblock ~49 ~4 ~53 glass_pane 0  
fill ~49 ~4 ~57 ~50 ~4 ~57 glass_pane 0  
fill ~49 ~4 ~65 ~50 ~4 ~65 glass_pane 0  
fill ~49 ~4 ~66 ~49 ~4 ~65 glass_pane 0 
setblock ~49 ~4 ~76 glass_pane 0  
fill ~49 ~4 ~77 ~49 ~5 ~77 planks 0  
fill ~50 ~4 ~41 ~50 ~5 ~41 planks 0  
fill ~50 ~4 ~44 ~50 ~5 ~44 planks 0  
fill ~50 ~4 ~49 ~50 ~5 ~49 planks 0  
fill ~50 ~4 ~53 ~50 ~5 ~53 planks 0 
setblock ~50 ~4 ~61 wooden_pressure_plate 0 
setblock ~50 ~4 ~63 wooden_pressure_plate 0  
fill ~50 ~4 ~66 ~50 ~5 ~66 planks 0  
fill ~50 ~4 ~78 ~50 ~5 ~78 planks 0  
fill ~51 ~4 ~-4 ~56 ~4 ~-4 glass 0 
setblock ~51 ~4 ~13 log 0 
setblock ~51 ~4 ~21 log 0  
fill ~51 ~4 ~28 ~51 ~5 ~28 cobblestone 0 
setblock ~51 ~4 ~29 log 0  
fill ~51 ~4 ~30 ~51 ~4 ~31 glass_pane 0 
setblock ~51 ~4 ~32 log 0  
fill ~51 ~4 ~33 ~51 ~5 ~33 cobblestone 0 
setblock ~51 ~4 ~51 glass_pane 0  
fill ~51 ~4 ~52 ~51 ~5 ~52 planks 0  
fill ~51 ~4 ~57 ~51 ~6 ~57 planks 0  
fill ~51 ~4 ~65 ~51 ~6 ~65 planks 0 
setblock ~51 ~4 ~68 glass_pane 0  
fill ~51 ~4 ~69 ~51 ~5 ~69 planks 0 
setblock ~51 ~4 ~78 glass_pane 0  
fill ~51 ~4 ~94 ~56 ~4 ~94 glass 0  
fill ~52 ~4 ~13 ~52 ~5 ~13 cobblestone 0  
fill ~52 ~4 ~14 ~52 ~5 ~14 planks 0  
fill ~52 ~4 ~15 ~52 ~6 ~15 planks 0 
setblock ~52 ~4 ~21 planks 0  
fill ~52 ~4 ~28 ~52 ~5 ~28 planks 0  
fill ~52 ~4 ~33 ~52 ~5 ~33 planks 0  
fill ~52 ~4 ~37 ~52 ~5 ~37 cobblestone 0 
setblock ~52 ~4 ~38 log 0  
fill ~52 ~4 ~39 ~52 ~4 ~40 glass_pane 0 
setblock ~52 ~4 ~41 log 0  
fill ~52 ~4 ~42 ~52 ~5 ~42 cobblestone 0  
fill ~52 ~4 ~57 ~52 ~7 ~57 cobblestone 0  
fill ~52 ~4 ~58 ~52 ~6 ~58 planks 0  
fill ~52 ~4 ~59 ~52 ~4 ~60 glass_pane 0  
fill ~52 ~4 ~61 ~52 ~6 ~61 planks 0  
fill ~52 ~4 ~62 ~52 ~4 ~63 glass_pane 0  
fill ~52 ~4 ~64 ~52 ~6 ~64 planks 0  
fill ~52 ~4 ~65 ~52 ~7 ~65 cobblestone 0  
fill ~52 ~4 ~78 ~52 ~5 ~78 planks 0 
setblock ~53 ~4 ~15 log 0 
setblock ~53 ~4 ~21 log 0  
fill ~53 ~4 ~28 ~54 ~4 ~28 glass_pane 0 
setblock ~53 ~4 ~30 wooden_pressure_plate 0 
setblock ~53 ~4 ~33 wooden_door 8  
fill ~53 ~4 ~37 ~53 ~5 ~37 planks 0  
fill ~53 ~4 ~42 ~54 ~4 ~42 planks 0 
setblock ~53 ~4 ~76 glass_pane 0  
fill ~53 ~4 ~77 ~53 ~5 ~77 planks 0  
fill ~54 ~4 ~15 ~55 ~4 ~15 glass_pane 0  
fill ~54 ~4 ~21 ~55 ~4 ~21 glass_pane 0  
fill ~54 ~4 ~33 ~55 ~4 ~33 planks 0 
setblock ~54 ~4 ~37 wooden_door 8 
setblock ~54 ~4 ~43 log 0  
fill ~54 ~4 ~44 ~54 ~4 ~45 glass_pane 0 
setblock ~54 ~4 ~46 log 0  
fill ~54 ~4 ~47 ~60 ~4 ~47 cobblestone 0  
fill ~55 ~4 ~28 ~56 ~4 ~28 planks 0  
fill ~55 ~4 ~37 ~55 ~5 ~37 planks 0 
setblock ~56 ~4 ~15 log 0 
setblock ~56 ~4 ~21 log 0 
setblock ~56 ~4 ~33 glass_pane 0 
setblock ~56 ~4 ~37 log 0  
fill ~57 ~4 ~-3 ~60 ~4 ~-3 glass 0  
fill ~57 ~4 ~15 ~57 ~5 ~15 cobblestone 0  
fill ~57 ~4 ~21 ~57 ~5 ~21 cobblestone 0 
setblock ~57 ~4 ~28 wooden_door 8  
fill ~57 ~4 ~33 ~58 ~4 ~33 planks 0 
setblock ~57 ~4 ~37 glass_pane 0 
setblock ~57 ~4 ~68 glass_pane 0  
fill ~57 ~4 ~69 ~57 ~5 ~69 planks 0  
fill ~57 ~4 ~93 ~60 ~4 ~93 glass 0  
fill ~58 ~4 ~28 ~58 ~5 ~28 planks 0 
setblock ~58 ~4 ~37 log 0  
fill ~58 ~4 ~66 ~59 ~4 ~66 planks 0 
setblock ~58 ~4 ~67 wooden_pressure_plate 0 
setblock ~58 ~4 ~70 wooden_door 8  
fill ~59 ~4 ~28 ~59 ~5 ~28 cobblestone 0 
setblock ~59 ~4 ~29 log 0  
fill ~59 ~4 ~30 ~59 ~4 ~31 glass_pane 0 
setblock ~59 ~4 ~32 log 0  
fill ~59 ~4 ~33 ~59 ~5 ~33 cobblestone 0  
fill ~59 ~4 ~37 ~59 ~5 ~37 planks 0  
fill ~60 ~4 ~37 ~60 ~5 ~37 cobblestone 0 
setblock ~60 ~4 ~38 log 0  
fill ~60 ~4 ~39 ~60 ~4 ~40 glass_pane 0 
setblock ~60 ~4 ~41 log 0 
setblock ~60 ~4 ~42 planks 0 
setblock ~60 ~4 ~43 log 0  
fill ~60 ~4 ~44 ~60 ~4 ~45 glass_pane 0 
setblock ~60 ~4 ~46 log 0 
setblock ~60 ~4 ~68 glass_pane 0  
fill ~60 ~4 ~69 ~60 ~5 ~69 planks 0  
fill ~60 ~4 ~74 ~60 ~5 ~74 cobblestone 0 
setblock ~60 ~4 ~75 log 0  
fill ~60 ~4 ~76 ~60 ~4 ~77 glass_pane 0 
setblock ~60 ~4 ~78 log 0  
fill ~60 ~4 ~79 ~60 ~5 ~79 cobblestone 0  
fill ~61 ~4 ~-2 ~63 ~4 ~-2 glass 0  
fill ~61 ~4 ~74 ~61 ~5 ~74 planks 0  
fill ~61 ~4 ~79 ~62 ~4 ~79 planks 0  
fill ~61 ~4 ~92 ~63 ~4 ~92 glass 0 
setblock ~62 ~4 ~74 wooden_door 8 
setblock ~62 ~4 ~80 log 0  
fill ~62 ~4 ~81 ~62 ~4 ~82 glass_pane 0 
setblock ~62 ~4 ~83 log 0  
fill ~62 ~4 ~84 ~68 ~4 ~84 cobblestone 0  
fill ~63 ~4 ~74 ~63 ~5 ~74 planks 0  
fill ~64 ~4 ~-1 ~65 ~4 ~-1 glass 0 
setblock ~64 ~4 ~74 log 0  
fill ~64 ~4 ~91 ~65 ~4 ~91 glass 0 
setblock ~65 ~4 ~74 glass_pane 0  
fill ~66 ~4 ~0 ~67 ~4 ~0 glass 0  
fill ~66 ~4 ~39 ~66 ~5 ~39 glass_pane 0  
fill ~66 ~4 ~40 ~66 ~12 ~40 cobblestone 0  
fill ~66 ~4 ~41 ~66 ~6 ~41 cobblestone 0  
fill ~66 ~4 ~42 ~66 ~6 ~42 cobblestone 0  
fill ~66 ~4 ~43 ~66 ~4 ~44 cobblestone 0 
setblock ~66 ~4 ~74 log 0  
fill ~66 ~4 ~90 ~67 ~4 ~90 glass 0 
setblock ~67 ~4 ~44 stone_stairs 1  
fill ~67 ~4 ~45 ~69 ~4 ~45 cobblestone 0  
fill ~67 ~4 ~74 ~67 ~5 ~74 planks 0  
fill ~68 ~4 ~1 ~69 ~4 ~1 glass 0  
fill ~68 ~4 ~26 ~68 ~6 ~26 cobblestone 0  
fill ~68 ~4 ~27 ~68 ~2 ~27 cobblestone 0  
fill ~68 ~4 ~31 ~68 ~5 ~31 glass_pane 0  
fill ~68 ~4 ~32 ~68 ~12 ~32 cobblestone 0 
setblock ~68 ~4 ~37 wooden_door 8  
fill ~68 ~4 ~74 ~68 ~5 ~74 cobblestone 0 
setblock ~68 ~4 ~75 log 0  
fill ~68 ~4 ~76 ~68 ~4 ~77 glass_pane 0 
setblock ~68 ~4 ~78 log 0 
setblock ~68 ~4 ~79 planks 0 
setblock ~68 ~4 ~80 log 0  
fill ~68 ~4 ~81 ~68 ~4 ~82 glass_pane 0 
setblock ~68 ~4 ~83 log 0  
fill ~68 ~4 ~89 ~69 ~4 ~89 glass 0  
fill ~69 ~4 ~25 ~71 ~4 ~25 cobblestone 0 
setblock ~69 ~4 ~26 stone_stairs 1 
setblock ~69 ~4 ~44 stone_stairs 0  
fill ~70 ~4 ~2 ~71 ~4 ~2 glass 0 
setblock ~70 ~4 ~33 wooden_door 8  
fill ~70 ~4 ~39 ~70 ~5 ~39 glass_pane 0  
fill ~70 ~4 ~40 ~70 ~12 ~40 cobblestone 0  
fill ~70 ~4 ~41 ~70 ~6 ~41 cobblestone 0  
fill ~70 ~4 ~42 ~70 ~6 ~42 cobblestone 0  
fill ~70 ~4 ~43 ~70 ~4 ~44 cobblestone 0  
fill ~70 ~4 ~88 ~71 ~4 ~88 glass 0 
setblock ~71 ~4 ~26 stone_stairs 0  
fill ~72 ~4 ~26 ~72 ~6 ~26 cobblestone 0  
fill ~72 ~4 ~27 ~72 ~4 ~26 cobblestone 0  
fill ~72 ~4 ~31 ~72 ~5 ~31 glass_pane 0  
fill ~72 ~4 ~32 ~72 ~12 ~32 cobblestone 0  
fill ~94 ~4 ~39 ~94 ~10 ~39 glass 0  
fill ~94 ~4 ~51 ~94 ~10 ~51 glass 0  
fill ~-5 ~5 ~-5 ~-4 ~5 ~-5 glass 0  
fill ~-5 ~5 ~-4 ~-5 ~5 ~-4 glass 0  
fill ~-5 ~5 ~94 ~-5 ~5 ~94 glass 0  
fill ~-5 ~5 ~95 ~-4 ~5 ~95 glass 0  
fill ~-2 ~5 ~30 ~-2 ~10 ~30 glass 0  
fill ~-2 ~5 ~60 ~-2 ~10 ~60 glass 0  
fill ~-1 ~5 ~27 ~-1 ~10 ~27 glass 0  
fill ~-1 ~5 ~63 ~-1 ~10 ~63 glass 0  
fill ~8 ~5 ~12 ~8 ~9 ~12 glass 0  
fill ~8 ~5 ~78 ~8 ~9 ~78 glass 0  
fill ~9 ~5 ~11 ~9 ~9 ~11 glass 0  
fill ~11 ~5 ~81 ~11 ~9 ~81 glass 0  
fill ~12 ~5 ~8 ~12 ~9 ~8 glass 0  
fill ~12 ~5 ~82 ~12 ~9 ~82 glass 0 
setblock ~15 ~5 ~39 planks 0 
setblock ~17 ~5 ~37 planks 0 
setblock ~17 ~5 ~38 torch 3 
setblock ~17 ~5 ~41 planks 0  
fill ~17 ~5 ~73 ~24 ~5 ~73 oak_stairs 2  
fill ~17 ~5 ~74 ~23 ~5 ~74 planks 0  
fill ~17 ~5 ~75 ~17 ~6 ~75 planks 0  
fill ~17 ~5 ~76 ~17 ~7 ~76 planks 0  
fill ~17 ~5 ~77 ~17 ~7 ~77 planks 0  
fill ~17 ~5 ~78 ~17 ~6 ~78 planks 0  
fill ~17 ~5 ~79 ~17 ~5 ~80 planks 0  
fill ~17 ~5 ~81 ~17 ~5 ~84 oak_stairs 0 
setblock ~18 ~5 ~75 torch 3  
fill ~18 ~5 ~79 ~18 ~5 ~84 cobblestone 0  
fill ~19 ~5 ~2 ~20 ~5 ~2 glass 0 
setblock ~19 ~5 ~39 planks 0  
fill ~19 ~5 ~84 ~24 ~5 ~84 cobblestone 0  
fill ~19 ~5 ~88 ~20 ~5 ~88 glass 0 
setblock ~20 ~5 ~68 planks 0  
fill ~21 ~5 ~1 ~22 ~5 ~1 glass 0  
fill ~21 ~5 ~66 ~22 ~5 ~66 planks 0 
setblock ~21 ~5 ~70 planks 0  
fill ~21 ~5 ~89 ~22 ~5 ~89 glass 0  
fill ~23 ~5 ~0 ~24 ~5 ~0 glass 0 
setblock ~23 ~5 ~39 planks 0 
setblock ~23 ~5 ~68 planks 0  
fill ~23 ~5 ~90 ~24 ~5 ~90 glass 0 
setblock ~24 ~5 ~37 planks 0  
fill ~24 ~5 ~41 ~25 ~5 ~41 planks 0  
fill ~24 ~5 ~75 ~24 ~5 ~84 cobblestone 0  
fill ~25 ~5 ~-1 ~27 ~5 ~-1 glass 0  
fill ~25 ~5 ~91 ~27 ~5 ~91 glass 0 
setblock ~26 ~5 ~39 planks 0  
fill ~28 ~5 ~-2 ~30 ~5 ~-2 glass 0 
setblock ~28 ~5 ~70 torch 2  
fill ~28 ~5 ~92 ~30 ~5 ~92 glass 0 
setblock ~29 ~5 ~69 torch 4 
setblock ~29 ~5 ~70 wool 15 
setblock ~30 ~5 ~70 torch 1  
fill ~31 ~5 ~-3 ~33 ~5 ~-3 glass 0  
fill ~31 ~5 ~93 ~33 ~5 ~93 glass 0 
setblock ~33 ~5 ~37 torch 2  
fill ~34 ~5 ~-4 ~39 ~5 ~-4 glass 0 
setblock ~34 ~5 ~31 planks 0 
setblock ~34 ~5 ~36 torch 4 
setblock ~34 ~5 ~37 wool 15 
setblock ~34 ~5 ~38 torch 3  
fill ~34 ~5 ~94 ~39 ~5 ~94 glass 0  
fill ~35 ~5 ~29 ~36 ~5 ~29 planks 0 
setblock ~35 ~5 ~33 planks 0 
setblock ~35 ~5 ~37 torch 1 
setblock ~35 ~5 ~70 torch 2 
setblock ~36 ~5 ~69 torch 4 
setblock ~36 ~5 ~70 wool 15 
setblock ~37 ~5 ~31 planks 0  
fill ~37 ~5 ~39 ~37 ~5 ~47 oak_stairs 0 
setblock ~37 ~5 ~70 torch 1  
fill ~38 ~5 ~41 ~38 ~5 ~46 planks 0  
fill ~39 ~5 ~39 ~43 ~5 ~39 cobblestone 0 
setblock ~39 ~5 ~45 torch 1  
fill ~39 ~5 ~47 ~43 ~5 ~47 cobblestone 0  
fill ~40 ~5 ~-5 ~50 ~5 ~-5 glass 0  
fill ~40 ~5 ~95 ~50 ~5 ~95 glass 0 
setblock ~42 ~5 ~41 torch 2 
setblock ~43 ~5 ~41 planks 0 
setblock ~43 ~5 ~44 planks 0  
fill ~44 ~5 ~39 ~44 ~5 ~47 oak_stairs 1  
fill ~46 ~5 ~13 ~46 ~5 ~21 oak_stairs 0 
setblock ~47 ~5 ~15 planks 0  
fill ~47 ~5 ~17 ~47 ~5 ~20 planks 0 
setblock ~47 ~5 ~42 planks 0 
setblock ~47 ~5 ~51 planks 0  
fill ~47 ~5 ~58 ~47 ~6 ~58 planks 0 
setblock ~47 ~5 ~68 planks 0  
fill ~48 ~5 ~13 ~52 ~5 ~13 cobblestone 0 
setblock ~48 ~5 ~15 torch 1  
fill ~48 ~5 ~21 ~57 ~5 ~21 cobblestone 0 
setblock ~48 ~5 ~51 torch 1 
setblock ~49 ~5 ~41 planks 0 
setblock ~49 ~5 ~44 planks 0 
setblock ~49 ~5 ~49 planks 0 
setblock ~49 ~5 ~53 planks 0  
fill ~49 ~5 ~57 ~50 ~5 ~57 glass_pane 0  
fill ~49 ~5 ~65 ~50 ~5 ~65 glass_pane 0 
setblock ~49 ~5 ~66 planks 0 
setblock ~49 ~5 ~69 torch 4 
setblock ~49 ~5 ~70 planks 0 
setblock ~49 ~5 ~76 planks 0  
fill ~51 ~5 ~-4 ~56 ~5 ~-4 glass 0  
fill ~51 ~5 ~27 ~59 ~5 ~27 oak_stairs 2  
fill ~51 ~5 ~29 ~51 ~5 ~33 cobblestone 0  
fill ~51 ~5 ~34 ~59 ~5 ~34 oak_stairs 3 
setblock ~51 ~5 ~51 planks 0  
fill ~51 ~5 ~58 ~51 ~5 ~64 bookshelf 0 
setblock ~51 ~5 ~68 planks 0 
setblock ~51 ~5 ~74 planks 0 
setblock ~51 ~5 ~75 torch 3 
setblock ~51 ~5 ~78 planks 0  
fill ~51 ~5 ~94 ~56 ~5 ~94 glass 0  
fill ~52 ~5 ~36 ~60 ~5 ~36 oak_stairs 2  
fill ~52 ~5 ~38 ~52 ~5 ~42 cobblestone 0 
setblock ~52 ~5 ~43 oak_stairs 3  
fill ~52 ~5 ~59 ~52 ~6 ~59 planks 0  
fill ~52 ~5 ~60 ~52 ~6 ~60 planks 0  
fill ~52 ~5 ~62 ~52 ~6 ~62 planks 0  
fill ~52 ~5 ~63 ~52 ~6 ~63 planks 0 
setblock ~53 ~5 ~13 oak_stairs 1 
setblock ~53 ~5 ~14 planks 0  
fill ~53 ~5 ~15 ~57 ~5 ~15 cobblestone 0  
fill ~53 ~5 ~28 ~58 ~5 ~28 planks 0 
setblock ~53 ~5 ~32 torch 4  
fill ~53 ~5 ~33 ~58 ~5 ~33 planks 0  
fill ~53 ~5 ~42 ~54 ~5 ~42 planks 0  
fill ~53 ~5 ~43 ~53 ~5 ~42 planks 0  
fill ~53 ~5 ~44 ~53 ~5 ~47 oak_stairs 0 
setblock ~53 ~5 ~76 planks 0  
fill ~54 ~5 ~14 ~57 ~5 ~14 oak_stairs 2 
setblock ~54 ~5 ~37 planks 0 
setblock ~54 ~5 ~38 torch 3  
fill ~54 ~5 ~43 ~54 ~5 ~47 cobblestone 0  
fill ~55 ~5 ~47 ~60 ~5 ~47 cobblestone 0  
fill ~56 ~5 ~37 ~59 ~5 ~37 planks 0  
fill ~57 ~5 ~-3 ~59 ~5 ~-3 glass 0 
setblock ~57 ~5 ~29 torch 3 
setblock ~57 ~5 ~68 planks 0  
fill ~57 ~5 ~93 ~59 ~5 ~93 glass 0  
fill ~58 ~5 ~66 ~59 ~5 ~66 planks 0 
setblock ~58 ~5 ~70 planks 0  
fill ~59 ~5 ~29 ~59 ~5 ~33 cobblestone 0  
fill ~60 ~5 ~-2 ~62 ~5 ~-2 glass 0  
fill ~60 ~5 ~38 ~60 ~5 ~47 cobblestone 0 
setblock ~60 ~5 ~68 planks 0  
fill ~60 ~5 ~73 ~68 ~5 ~73 oak_stairs 2  
fill ~60 ~5 ~75 ~60 ~5 ~79 cobblestone 0 
setblock ~60 ~5 ~80 oak_stairs 3  
fill ~60 ~5 ~92 ~62 ~5 ~92 glass 0  
fill ~61 ~5 ~79 ~62 ~5 ~79 planks 0  
fill ~61 ~5 ~80 ~61 ~5 ~79 planks 0  
fill ~61 ~5 ~81 ~61 ~5 ~84 oak_stairs 0 
setblock ~62 ~5 ~74 planks 0 
setblock ~62 ~5 ~75 torch 3  
fill ~62 ~5 ~80 ~62 ~5 ~84 cobblestone 0  
fill ~63 ~5 ~-1 ~65 ~5 ~-1 glass 0  
fill ~63 ~5 ~84 ~68 ~5 ~84 cobblestone 0  
fill ~63 ~5 ~91 ~65 ~5 ~91 glass 0  
fill ~64 ~5 ~74 ~67 ~5 ~74 planks 0  
fill ~66 ~5 ~0 ~67 ~5 ~0 glass 0 
setblock ~66 ~5 ~43 glass_pane 0  
fill ~66 ~5 ~44 ~66 ~6 ~44 cobblestone 0  
fill ~66 ~5 ~90 ~67 ~5 ~90 glass 0  
fill ~67 ~5 ~45 ~67 ~6 ~45 cobblestone 0  
fill ~68 ~5 ~1 ~69 ~5 ~1 glass 0 
setblock ~68 ~5 ~27 glass_pane 0  
fill ~68 ~5 ~37 ~68 ~7 ~37 cobblestone 0 
setblock ~68 ~5 ~45 glass_pane 0  
fill ~68 ~5 ~75 ~68 ~5 ~84 cobblestone 0  
fill ~68 ~5 ~89 ~69 ~5 ~89 glass 0  
fill ~69 ~5 ~25 ~69 ~6 ~25 cobblestone 0  
fill ~69 ~5 ~45 ~69 ~6 ~45 cobblestone 0  
fill ~70 ~5 ~2 ~71 ~5 ~2 glass 0 
setblock ~70 ~5 ~25 glass_pane 0  
fill ~70 ~5 ~33 ~70 ~7 ~33 cobblestone 0 
setblock ~70 ~5 ~43 glass_pane 0  
fill ~70 ~5 ~44 ~70 ~6 ~44 cobblestone 0  
fill ~70 ~5 ~88 ~71 ~5 ~88 glass 0  
fill ~71 ~5 ~25 ~71 ~6 ~25 cobblestone 0 
setblock ~72 ~5 ~19 torch 2 
setblock ~72 ~5 ~27 glass_pane 0 
setblock ~73 ~5 ~18 torch 4 
setblock ~73 ~5 ~19 wool 15 
setblock ~73 ~5 ~20 torch 3 
setblock ~74 ~5 ~19 torch 1  
fill ~78 ~5 ~8 ~78 ~9 ~8 glass 0  
fill ~78 ~5 ~82 ~78 ~9 ~82 glass 0  
fill ~79 ~5 ~9 ~79 ~9 ~9 glass 0  
fill ~82 ~5 ~12 ~82 ~9 ~12 glass 0  
fill ~82 ~5 ~78 ~82 ~9 ~78 glass 0  
fill ~91 ~5 ~27 ~91 ~10 ~27 glass 0  
fill ~91 ~5 ~63 ~91 ~10 ~63 glass 0  
fill ~92 ~5 ~30 ~92 ~10 ~30 glass 0  
fill ~92 ~5 ~60 ~92 ~10 ~60 glass 0  
fill ~94 ~5 ~-5 ~95 ~5 ~-5 glass 0  
fill ~95 ~5 ~-4 ~95 ~5 ~-4 glass 0  
fill ~95 ~5 ~94 ~95 ~5 ~94 glass 0  
fill ~95 ~5 ~95 ~95 ~5 ~95 glass 0  
fill ~-5 ~6 ~-5 ~-4 ~6 ~-5 obsidian 0  
fill ~-5 ~6 ~-4 ~-5 ~6 ~-4 obsidian 0  
fill ~-5 ~6 ~-3 ~-4 ~6 ~-3 glass 0  
fill ~-5 ~6 ~93 ~-4 ~6 ~93 glass 0  
fill ~-5 ~6 ~94 ~-5 ~6 ~94 obsidian 0  
fill ~-5 ~6 ~95 ~-4 ~6 ~95 obsidian 0  
fill ~-4 ~6 ~-4 ~-3 ~6 ~-4 glass 0  
fill ~-4 ~6 ~40 ~-4 ~11 ~40 glass 0  
fill ~-4 ~6 ~41 ~-4 ~11 ~41 glass 0  
fill ~-4 ~6 ~49 ~-4 ~11 ~49 glass 0  
fill ~-4 ~6 ~50 ~-4 ~11 ~50 glass 0  
fill ~-4 ~6 ~94 ~-3 ~6 ~94 glass 0  
fill ~-3 ~6 ~-5 ~-3 ~6 ~-5 glass 0  
fill ~-3 ~6 ~34 ~-3 ~11 ~34 glass 0  
fill ~-3 ~6 ~56 ~-3 ~11 ~56 glass 0  
fill ~-3 ~6 ~95 ~-3 ~6 ~95 glass 0  
fill ~0 ~6 ~25 ~0 ~11 ~25 glass 0  
fill ~0 ~6 ~65 ~0 ~11 ~65 glass 0  
fill ~3 ~6 ~19 ~3 ~10 ~19 glass 0  
fill ~3 ~6 ~71 ~3 ~10 ~71 glass 0  
fill ~5 ~6 ~16 ~5 ~10 ~16 glass 0  
fill ~5 ~6 ~74 ~5 ~10 ~74 glass 0  
fill ~9 ~6 ~79 ~9 ~10 ~79 glass 0  
fill ~10 ~6 ~10 ~10 ~9 ~10 glass 0  
fill ~10 ~6 ~80 ~10 ~9 ~80 glass 0  
fill ~11 ~6 ~9 ~11 ~10 ~9 glass 0  
fill ~15 ~6 ~37 ~19 ~6 ~37 log 0  
fill ~15 ~6 ~38 ~15 ~6 ~41 log 0  
fill ~16 ~6 ~5 ~16 ~10 ~5 glass 0  
fill ~16 ~6 ~38 ~18 ~6 ~38 planks 0  
fill ~16 ~6 ~39 ~18 ~6 ~39 planks 0  
fill ~16 ~6 ~40 ~17 ~6 ~40 planks 0  
fill ~16 ~6 ~41 ~19 ~6 ~41 log 0  
fill ~16 ~6 ~85 ~16 ~10 ~85 glass 0  
fill ~17 ~6 ~74 ~24 ~6 ~74 oak_stairs 2 
setblock ~17 ~6 ~79 oak_stairs 3  
fill ~18 ~6 ~75 ~24 ~6 ~75 planks 0  
fill ~18 ~6 ~78 ~19 ~6 ~78 planks 0  
fill ~18 ~6 ~79 ~19 ~6 ~79 planks 0  
fill ~18 ~6 ~80 ~18 ~6 ~84 oak_stairs 0  
fill ~19 ~6 ~3 ~19 ~10 ~3 glass 0  
fill ~19 ~6 ~38 ~19 ~6 ~41 log 0  
fill ~19 ~6 ~80 ~19 ~6 ~84 planks 0  
fill ~19 ~6 ~87 ~19 ~10 ~87 glass 0  
fill ~20 ~6 ~2 ~20 ~8 ~2 glass 0  
fill ~20 ~6 ~67 ~23 ~6 ~67 log 0  
fill ~20 ~6 ~68 ~23 ~6 ~68 log 0  
fill ~20 ~6 ~69 ~23 ~6 ~69 log 0 
setblock ~20 ~6 ~84 log 0  
fill ~20 ~6 ~88 ~20 ~8 ~88 glass 0  
fill ~21 ~6 ~1 ~22 ~6 ~1 glass 0  
fill ~21 ~6 ~66 ~22 ~6 ~66 log 0  
fill ~21 ~6 ~70 ~22 ~6 ~70 log 0 
setblock ~21 ~6 ~84 glass_pane 0  
fill ~21 ~6 ~89 ~22 ~6 ~89 glass 0 
setblock ~22 ~6 ~84 log 0  
fill ~23 ~6 ~0 ~25 ~6 ~0 glass 0  
fill ~23 ~6 ~38 ~23 ~6 ~40 log 0  
fill ~23 ~6 ~76 ~24 ~6 ~76 planks 0  
fill ~23 ~6 ~77 ~24 ~6 ~77 planks 0  
fill ~23 ~6 ~78 ~24 ~6 ~78 planks 0  
fill ~23 ~6 ~79 ~23 ~6 ~84 planks 0  
fill ~23 ~6 ~90 ~25 ~6 ~90 glass 0   
fill ~24 ~6 ~37 ~25 ~6 ~37 log 0  
fill ~24 ~6 ~41 ~25 ~6 ~41 log 0  
fill ~24 ~6 ~79 ~24 ~6 ~84 oak_stairs 1  
fill ~26 ~6 ~-1 ~27 ~6 ~-1 glass 0  
fill ~26 ~6 ~38 ~26 ~6 ~40 log 0  
fill ~26 ~6 ~91 ~27 ~6 ~91 glass 0  
fill ~28 ~6 ~-2 ~30 ~6 ~-2 glass 0  
fill ~28 ~6 ~92 ~30 ~6 ~92 glass 0  
fill ~31 ~6 ~-3 ~34 ~6 ~-3 glass 0  
fill ~31 ~6 ~93 ~34 ~6 ~93 glass 0  
fill ~34 ~6 ~30 ~37 ~6 ~30 log 0  
fill ~34 ~6 ~31 ~37 ~6 ~31 log 0  
fill ~34 ~6 ~32 ~37 ~6 ~32 log 0  
fill ~35 ~6 ~-4 ~41 ~6 ~-4 glass 0  
fill ~35 ~6 ~29 ~36 ~6 ~29 log 0  
fill ~35 ~6 ~33 ~36 ~6 ~33 log 0  
fill ~35 ~6 ~94 ~41 ~6 ~94 glass 0  
fill ~38 ~6 ~39 ~38 ~6 ~47 oak_stairs 0  
fill ~39 ~6 ~39 ~42 ~6 ~39 planks 0  
fill ~39 ~6 ~40 ~39 ~6 ~47 planks 0  
fill ~40 ~6 ~47 ~42 ~6 ~47 planks 0  
fill ~42 ~6 ~-5 ~48 ~6 ~-5 glass 0  
fill ~42 ~6 ~40 ~42 ~6 ~47 planks 0  
fill ~42 ~6 ~95 ~48 ~6 ~95 glass 0  
fill ~43 ~6 ~39 ~43 ~6 ~47 oak_stairs 1  
fill ~44 ~6 ~34 ~47 ~6 ~34 cobblestone 0  
fill ~44 ~6 ~35 ~47 ~6 ~35 cobblestone 0  
fill ~44 ~6 ~36 ~47 ~6 ~36 cobblestone 0  
fill ~44 ~6 ~37 ~47 ~6 ~37 cobblestone 0  
fill ~47 ~6 ~13 ~47 ~6 ~21 oak_stairs 0  
fill ~47 ~6 ~42 ~51 ~6 ~42 log 0  
fill ~47 ~6 ~43 ~51 ~6 ~43 log 0  
fill ~47 ~6 ~49 ~51 ~6 ~49 log 0  
fill ~47 ~6 ~50 ~47 ~6 ~53 log 0  
fill ~47 ~6 ~61 ~48 ~6 ~61 planks 0  
fill ~47 ~6 ~62 ~48 ~6 ~62 planks 0  
fill ~47 ~6 ~63 ~48 ~6 ~63 planks 0  
fill ~47 ~6 ~66 ~51 ~6 ~66 log 0  
fill ~47 ~6 ~67 ~47 ~6 ~70 log 0  
fill ~48 ~6 ~13 ~51 ~6 ~13 planks 0  
fill ~48 ~6 ~14 ~48 ~6 ~21 planks 0  
fill ~48 ~6 ~41 ~50 ~6 ~41 log 0  
fill ~48 ~6 ~44 ~50 ~6 ~44 log 0  
fill ~48 ~6 ~50 ~50 ~6 ~50 planks 0  
fill ~48 ~6 ~51 ~50 ~6 ~51 planks 0  
fill ~48 ~6 ~52 ~49 ~6 ~52 planks 0  
fill ~48 ~6 ~53 ~51 ~6 ~53 log 0  
fill ~48 ~6 ~58 ~48 ~6 ~65 planks 0  
fill ~48 ~6 ~67 ~50 ~6 ~67 planks 0  
fill ~48 ~6 ~68 ~50 ~6 ~68 planks 0  
fill ~48 ~6 ~69 ~50 ~6 ~69 planks 0  
fill ~48 ~6 ~70 ~51 ~6 ~70 log 0  
fill ~49 ~6 ~-4 ~55 ~6 ~-4 glass 0  
fill ~49 ~6 ~20 ~57 ~6 ~20 planks 0  
fill ~49 ~6 ~21 ~51 ~6 ~21 planks 0  
fill ~49 ~6 ~57 ~51 ~6 ~57 planks 0  
fill ~49 ~6 ~65 ~51 ~6 ~65 planks 0  
fill ~49 ~6 ~74 ~53 ~6 ~74 log 0  
fill ~49 ~6 ~75 ~49 ~6 ~78 log 0  
fill ~49 ~6 ~94 ~55 ~6 ~94 glass 0  
fill ~50 ~6 ~75 ~52 ~6 ~75 planks 0  
fill ~50 ~6 ~76 ~52 ~6 ~76 planks 0  
fill ~50 ~6 ~77 ~51 ~6 ~77 planks 0  
fill ~50 ~6 ~78 ~53 ~6 ~78 log 0  
fill ~51 ~6 ~14 ~51 ~6 ~16 planks 0  
fill ~51 ~6 ~28 ~59 ~6 ~28 oak_stairs 2  
fill ~51 ~6 ~29 ~59 ~6 ~29 planks 0  
fill ~51 ~6 ~30 ~51 ~7 ~30 planks 0  
fill ~51 ~6 ~31 ~51 ~7 ~31 planks 0  
fill ~51 ~6 ~32 ~59 ~6 ~32 planks 0  
fill ~51 ~6 ~33 ~59 ~6 ~33 oak_stairs 3  
fill ~51 ~6 ~50 ~51 ~6 ~53 log 0  
fill ~51 ~6 ~58 ~51 ~6 ~65 planks 0  
fill ~51 ~6 ~67 ~51 ~6 ~70 log 0  
fill ~52 ~6 ~13 ~52 ~6 ~14 oak_stairs 1  
fill ~52 ~6 ~16 ~57 ~6 ~16 planks 0  
fill ~52 ~6 ~21 ~57 ~6 ~21 oak_stairs 3  
fill ~52 ~6 ~37 ~60 ~6 ~37 oak_stairs 2  
fill ~52 ~6 ~38 ~60 ~6 ~38 planks 0  
fill ~52 ~6 ~39 ~52 ~7 ~39 planks 0  
fill ~52 ~6 ~40 ~52 ~7 ~40 planks 0  
fill ~52 ~6 ~41 ~55 ~6 ~41 planks 0  
fill ~52 ~6 ~42 ~53 ~6 ~42 oak_stairs 3  
fill ~53 ~6 ~15 ~57 ~6 ~15 oak_stairs 2  
fill ~53 ~6 ~75 ~53 ~6 ~78 log 0  
fill ~54 ~6 ~42 ~55 ~6 ~42 planks 0  
fill ~54 ~6 ~43 ~54 ~6 ~47 oak_stairs 0  
fill ~55 ~6 ~43 ~55 ~6 ~47 planks 0  
fill ~56 ~6 ~-3 ~59 ~6 ~-3 glass 0 
setblock ~56 ~6 ~47 log 0  
fill ~56 ~6 ~93 ~59 ~6 ~93 glass 0 
setblock ~57 ~6 ~17 log 0 
setblock ~57 ~6 ~18 glass_pane 0 
setblock ~57 ~6 ~19 log 0 
setblock ~57 ~6 ~47 glass_pane 0  
fill ~57 ~6 ~67 ~57 ~6 ~69 log 0 
setblock ~58 ~6 ~47 log 0  
fill ~58 ~6 ~66 ~59 ~6 ~66 log 0  
fill ~58 ~6 ~70 ~59 ~6 ~70 log 0  
fill ~59 ~6 ~30 ~59 ~7 ~30 planks 0  
fill ~59 ~6 ~31 ~59 ~7 ~31 planks 0  
fill ~59 ~6 ~39 ~60 ~6 ~39 planks 0  
fill ~59 ~6 ~40 ~60 ~6 ~40 planks 0  
fill ~59 ~6 ~41 ~60 ~6 ~41 planks 0  
fill ~59 ~6 ~42 ~59 ~6 ~47 planks 0  
fill ~60 ~6 ~-2 ~62 ~6 ~-2 glass 0  
fill ~60 ~6 ~42 ~60 ~6 ~47 oak_stairs 1  
fill ~60 ~6 ~67 ~60 ~6 ~69 log 0  
fill ~60 ~6 ~74 ~68 ~6 ~74 oak_stairs 2  
fill ~60 ~6 ~75 ~68 ~6 ~75 planks 0  
fill ~60 ~6 ~76 ~60 ~7 ~76 planks 0  
fill ~60 ~6 ~77 ~60 ~7 ~77 planks 0  
fill ~60 ~6 ~78 ~63 ~6 ~78 planks 0  
fill ~60 ~6 ~79 ~61 ~6 ~79 oak_stairs 3  
fill ~60 ~6 ~92 ~62 ~6 ~92 glass 0  
fill ~62 ~6 ~79 ~63 ~6 ~79 planks 0  
fill ~62 ~6 ~80 ~62 ~6 ~84 oak_stairs 0  
fill ~63 ~6 ~-1 ~64 ~6 ~-1 glass 0  
fill ~63 ~6 ~80 ~63 ~6 ~84 planks 0  
fill ~63 ~6 ~91 ~64 ~6 ~91 glass 0 
setblock ~64 ~6 ~84 log 0  
fill ~65 ~6 ~0 ~67 ~6 ~0 glass 0 
setblock ~65 ~6 ~84 glass_pane 0  
fill ~65 ~6 ~90 ~67 ~6 ~90 glass 0 
setblock ~66 ~6 ~37 cobblestone 0  
fill ~66 ~6 ~39 ~70 ~6 ~39 cobblestone 0 
setblock ~66 ~6 ~43 cobblestone 0 
