fill ~26~10~2 ~28~11~2 minecraft:wool 6
setblock ~27~9~2 minecraft:wool 6
fill ~27~12~2 ~28~12~2 minecraft:wool 6
fill ~28~13~2 ~41~13~2 minecraft:wool 6
fill ~30~11~2 ~30~12~2 minecraft:wool 6
fill ~30~14~2 ~40~14~2 minecraft:wool 6
fill ~32~9~2 ~32~12~2 minecraft:wool 6
fill ~32~15~2 ~34~15~3 minecraft:wool 6
setblock ~33~12~2 minecraft:wool 6
fill ~35~8~2 ~35~12~2 minecraft:wool 6
fill ~36~12~2 ~37~12~2 minecraft:wool 6
setblock ~37~11~2 minecraft:wool 6
fill ~38~15~2 ~39~15~3 minecraft:wool 6
fill ~39~12~2 ~41~12~2 minecraft:wool 6
setblock ~40~6~2 minecraft:wool 6
fill ~40~9~2 ~40~11~2 minecraft:wool 6
fill ~23~10~3 ~25~12~3 minecraft:wool 6
fill ~24~8~3 ~24~9~3 minecraft:wool 6
fill ~24~13~3 ~27~13~3 minecraft:wool 6
fill ~25~14~3 ~29~14~3 minecraft:wool 6
fill ~26~9~3 ~40~11~3 minecraft:sandstone 0
setblock ~26~12~3 minecraft:wool 6
fill ~27~8~3 ~39~8~3 minecraft:sandstone 0
fill ~27~12~3 ~39~12~3 minecraft:sandstone 0
fill ~27~15~3 ~31~15~3 minecraft:wool 6
fill ~28~7~3 ~38~7~3 minecraft:sandstone 0
fill ~28~13~3 ~38~13~3 minecraft:sandstone 0
fill ~30~6~3 ~31~6~3 minecraft:sandstone 0
fill ~30~14~3 ~36~14~3 minecraft:sandstone 0
fill ~35~6~3 ~36~6~3 minecraft:sandstone 0
fill ~35~15~3 ~37~15~3 minecraft:wool 6
fill ~37~14~3 ~42~14~3 minecraft:wool 6
fill ~39~13~3 ~42~13~3 minecraft:wool 6
fill ~39~16~3 ~40~16~4 minecraft:wool 6
fill ~40~12~3 ~43~12~3 minecraft:wool 6
fill ~40~15~3 ~41~15~4 minecraft:wool 6
fill ~41~9~3 ~41~11~3 minecraft:wool 6
fill ~42~10~3 ~42~11~3 minecraft:wool 6
setblock ~43~11~3 minecraft:wool 6
fill ~20~9~4 ~20~11~4 minecraft:wool 6
fill ~21~10~4 ~22~12~4 minecraft:wool 6
setblock ~22~9~4 minecraft:wool 6
fill ~22~13~4 ~23~14~4 minecraft:wool 6
fill ~23~8~4 ~26~8~4 minecraft:sandstone 0
fill ~23~9~4 ~25~12~4 minecraft:sandstone 0
fill ~24~7~4 ~27~7~4 minecraft:sandstone 0
fill ~24~13~4 ~27~13~4 minecraft:sandstone 0
fill ~24~14~4 ~24~15~4 minecraft:wool 6
fill ~25~6~4 ~29~6~4 minecraft:sandstone 0
fill ~25~14~4 ~29~14~4 minecraft:sandstone 0
fill ~25~15~4 ~26~15~4 minecraft:wool 6
setblock ~26~12~4 minecraft:sandstone 0
fill ~26~16~4 ~38~16~4 minecraft:wool 6
fill ~27~5~4 ~30~5~4 minecraft:sandstone 0
fill ~27~15~4 ~39~15~4 minecraft:sandstone 0
fill ~31~17~4 ~35~17~4 minecraft:wool 6
fill ~36~5~4 ~39~5~4 minecraft:sandstone 0
fill ~37~6~4 ~41~6~4 minecraft:sandstone 0
fill ~37~14~4 ~41~14~4 minecraft:sandstone 0
fill ~39~7~4 ~42~7~4 minecraft:sandstone 0
fill ~39~13~4 ~42~13~4 minecraft:sandstone 0
fill ~40~8~4 ~43~8~4 minecraft:sandstone 0
fill ~40~12~4 ~43~12~4 minecraft:sandstone 0
fill ~41~9~4 ~43~11~4 minecraft:sandstone 0
fill ~42~14~4 ~44~14~4 minecraft:wool 6
setblock ~42~15~4 minecraft:wool 6
fill ~43~13~4 ~45~13~4 minecraft:wool 6
fill ~44~9~4 ~44~12~4 minecraft:wool 6
fill ~45~11~4 ~45~12~4 minecraft:wool 6
fill ~19~9~5 ~19~13~5 minecraft:wool 6
fill ~20~10~5 ~22~10~5 minecraft:sandstone 0
fill ~20~11~5 ~20~14~5 minecraft:wool 6
fill ~21~8~5 ~22~9~5 minecraft:sandstone 0
fill ~21~11~5 ~22~12~5 minecraft:sandstone 0
fill ~21~13~5 ~21~15~5 minecraft:wool 6
fill ~22~6~5 ~24~6~5 minecraft:sandstone 0
fill ~22~7~5 ~23~7~5 minecraft:sandstone 0
fill ~22~13~5 ~23~14~5 minecraft:sandstone 0
fill ~22~15~5 ~23~15~5 minecraft:wool 6
fill ~23~16~5 ~25~16~5 minecraft:wool 6
fill ~24~5~5 ~26~5~5 minecraft:sandstone 0
fill ~24~14~5 ~24~15~5 minecraft:sandstone 0
fill ~25~15~5 ~26~15~5 minecraft:sandstone 0
fill ~26~4~5 ~29~4~5 minecraft:sandstone 0
fill ~26~16~5 ~40~16~5 minecraft:sandstone 0
fill ~26~17~5 ~30~17~5 minecraft:wool 6
fill ~31~17~5 ~35~17~6 minecraft:sandstone 0
fill ~31~18~5 ~35~18~6 minecraft:wool 6
fill ~36~17~5 ~40~17~5 minecraft:wool 6
fill ~37~4~5 ~40~4~5 minecraft:sandstone 0
fill ~40~5~5 ~42~5~5 minecraft:sandstone 0
fill ~40~15~5 ~42~15~5 minecraft:sandstone 0
fill ~41~16~5 ~43~16~5 minecraft:wool 6
fill ~42~6~5 ~44~6~5 minecraft:sandstone 0
fill ~42~14~5 ~44~14~5 minecraft:sandstone 0
fill ~43~7~5 ~44~7~5 minecraft:sandstone 0
fill ~43~13~5 ~44~13~5 minecraft:sandstone 0
fill ~43~15~5 ~45~15~5 minecraft:wool 6
fill ~44~8~5 ~45~12~5 minecraft:sandstone 0
fill ~45~13~5 ~47~13~5 minecraft:wool 6
fill ~45~14~5 ~46~14~5 minecraft:wool 6
setblock ~46~10~5 minecraft:sandstone 0
fill ~46~11~5 ~47~12~5 minecraft:wool 6
fill ~17~10~6 ~18~12~6 minecraft:wool 6
setblock ~18~9~6 minecraft:wool 6
fill ~18~13~6 ~18~14~6 minecraft:wool 6
fill ~19~7~6 ~21~7~6 minecraft:sandstone 0
fill ~19~8~6 ~20~9~6 minecraft:sandstone 0
fill ~19~10~6 ~19~13~6 minecraft:sandstone 0
fill ~19~14~6 ~19~15~6 minecraft:wool 6
fill ~20~6~6 ~21~6~6 minecraft:sandstone 0
fill ~20~11~6 ~20~14~6 minecraft:sandstone 0
setblock ~20~15~6 minecraft:wool 6
fill ~21~5~6 ~23~5~6 minecraft:sandstone 0
fill ~21~13~6 ~21~15~6 minecraft:sandstone 0
fill ~21~16~6 ~22~16~6 minecraft:wool 6
fill ~22~15~6 ~23~15~6 minecraft:sandstone 0
fill ~23~4~6 ~25~4~6 minecraft:sandstone 0
fill ~23~16~6 ~25~16~6 minecraft:sandstone 0
fill ~23~17~6 ~25~17~6 minecraft:wool 6
fill ~26~3~6 ~29~3~6 minecraft:sandstone 0
fill ~26~17~6 ~30~17~6 minecraft:sandstone 0
fill ~26~18~6 ~30~18~6 minecraft:wool 6
fill ~36~17~6 ~40~17~6 minecraft:sandstone 0
fill ~36~18~6 ~40~18~6 minecraft:wool 6
fill ~37~3~6 ~40~3~6 minecraft:sandstone 0
fill ~41~4~6 ~43~4~6 minecraft:sandstone 0
fill ~41~16~6 ~43~16~6 minecraft:sandstone 0
fill ~41~17~6 ~43~17~6 minecraft:wool 6
fill ~43~5~6 ~45~5~6 minecraft:sandstone 0
fill ~43~15~6 ~45~15~6 minecraft:sandstone 0
fill ~44~16~6 ~45~16~6 minecraft:wool 6
fill ~45~6~6 ~46~7~6 minecraft:sandstone 0
fill ~45~13~6 ~47~13~6 minecraft:sandstone 0
fill ~45~14~6 ~46~14~6 minecraft:sandstone 0
fill ~46~8~6 ~47~9~6 minecraft:sandstone 0
fill ~46~11~6 ~47~12~6 minecraft:sandstone 0
fill ~46~15~6 ~47~15~6 minecraft:wool 6
setblock ~47~7~6 minecraft:sandstone 0
setblock ~47~10~6 minecraft:sandstone 0
fill ~47~14~6 ~48~14~6 minecraft:wool 6
fill ~48~8~6 ~48~13~6 minecraft:wool 6
fill ~49~10~6 ~49~13~6 minecraft:wool 6
fill ~16~9~7 ~16~13~7 minecraft:wool 6
fill ~17~8~7 ~18~12~7 minecraft:sandstone 0
fill ~17~13~7 ~17~14~7 minecraft:wool 6
fill ~18~6~7 ~19~6~7 minecraft:sandstone 0
setblock ~18~7~7 minecraft:sandstone 0
fill ~18~13~7 ~18~14~7 minecraft:sandstone 0
setblock ~18~15~7 minecraft:wool 6
fill ~19~5~7 ~20~5~7 minecraft:sandstone 0
fill ~19~14~7 ~19~15~7 minecraft:sandstone 0
fill ~19~16~7 ~20~16~7 minecraft:wool 6
setblock ~20~15~7 minecraft:sandstone 0
fill ~21~4~7 ~22~4~7 minecraft:sandstone 0
fill ~21~16~7 ~22~16~7 minecraft:sandstone 0
fill ~21~17~7 ~22~17~7 minecraft:wool 6
fill ~23~3~7 ~25~3~7 minecraft:sandstone 0
fill ~23~17~7 ~25~17~7 minecraft:sandstone 0
fill ~23~18~7 ~25~18~7 minecraft:wool 6
fill ~26~2~7 ~29~2~7 minecraft:sandstone 0
fill ~26~18~7 ~40~18~7 minecraft:sandstone 0
fill ~26~19~7 ~40~19~7 minecraft:wool 6
fill ~37~2~7 ~40~2~7 minecraft:sandstone 0
fill ~41~3~7 ~43~3~7 minecraft:sandstone 0
fill ~41~17~7 ~43~17~7 minecraft:sandstone 0
fill ~41~18~7 ~43~18~7 minecraft:wool 6
fill ~44~4~7 ~45~4~7 minecraft:sandstone 0
fill ~44~16~7 ~45~16~7 minecraft:sandstone 0
fill ~44~17~7 ~45~17~7 minecraft:wool 6
fill ~46~5~7 ~47~5~7 minecraft:sandstone 0
fill ~46~15~7 ~47~15~7 minecraft:sandstone 0
fill ~46~16~7 ~47~16~7 minecraft:wool 6
fill ~47~6~7 ~48~6~7 minecraft:sandstone 0
fill ~47~14~7 ~48~14~7 minecraft:sandstone 0
fill ~48~7~7 ~48~13~7 minecraft:sandstone 0
setblock ~48~15~7 minecraft:wool 6
fill ~49~8~7 ~49~12~7 minecraft:sandstone 0
fill ~49~13~7 ~50~13~7 minecraft:wool 6
setblock ~49~14~7 minecraft:wool 6
fill ~50~8~7 ~50~12~7 minecraft:wool 6
fill ~14~10~8 ~15~12~8 minecraft:wool 6
fill ~15~8~8 ~15~9~8 minecraft:wool 6
setblock ~15~13~8 minecraft:wool 6
fill ~16~7~8 ~17~7~8 minecraft:sandstone 0
fill ~16~8~8 ~16~13~8 minecraft:sandstone 0
fill ~16~14~8 ~16~15~8 minecraft:wool 6
setblock ~17~6~8 minecraft:sandstone 0
fill ~17~13~8 ~17~14~8 minecraft:sandstone 0
setblock ~17~15~8 minecraft:wool 6
setblock ~18~5~8 minecraft:sandstone 0
setblock ~18~15~8 minecraft:sandstone 0
setblock ~18~16~8 minecraft:wool 6
fill ~19~4~8 ~20~4~8 minecraft:sandstone 0
fill ~19~16~8 ~20~16~8 minecraft:sandstone 0
fill ~19~17~8 ~20~17~8 minecraft:wool 6
fill ~21~3~8 ~23~3~8 minecraft:sandstone 0
fill ~21~17~8 ~23~17~8 minecraft:sandstone 0
fill ~21~18~8 ~23~18~8 minecraft:wool 6
fill ~24~2~8 ~28~2~8 minecraft:sandstone 0
fill ~24~18~8 ~28~18~8 minecraft:sandstone 0
fill ~24~19~8 ~28~19~8 minecraft:wool 6
fill ~29~0~8 ~30~0~8 minecraft:stone 5
fill ~29~1~8 ~30~1~16 minecraft:sandstone 0
setblock ~29~2~8 minecraft:sea_lantern
fill ~29~19~8 ~37~19~16 minecraft:sandstone 0
fill ~29~20~8 ~37~20~16 minecraft:wool 6
fill ~31~0~8 ~35~0~8 minecraft:sandstone 0
fill ~36~0~8 ~37~0~8 minecraft:stone 5
fill ~36~1~8 ~37~1~16 minecraft:sandstone 0
fill ~36~21~8 ~37~21~8 minecraft:wool 1
setblock ~37~2~8 minecraft:sea_lantern
fill ~38~2~8 ~42~2~8 minecraft:sandstone 0
fill ~38~18~8 ~42~18~8 minecraft:sandstone 0
fill ~38~19~8 ~42~19~8 minecraft:wool 6
fill ~43~3~8 ~45~3~8 minecraft:sandstone 0
fill ~43~17~8 ~45~17~8 minecraft:sandstone 0
fill ~43~18~8 ~45~18~8 minecraft:wool 6
fill ~46~4~8 ~47~4~8 minecraft:sandstone 0
fill ~46~16~8 ~47~16~8 minecraft:sandstone 0
fill ~46~17~8 ~47~17~8 minecraft:wool 6
setblock ~48~5~8 minecraft:sandstone 0
setblock ~48~15~8 minecraft:sandstone 0
setblock ~48~16~8 minecraft:wool 6
fill ~49~6~8 ~49~7~8 minecraft:sandstone 0
fill ~49~13~8 ~50~13~8 minecraft:sandstone 0
setblock ~49~14~8 minecraft:sandstone 0
fill ~49~15~8 ~50~15~8 minecraft:wool 6
fill ~50~7~8 ~50~12~8 minecraft:sandstone 0
setblock ~50~14~8 minecraft:wool 6
fill ~51~10~8 ~52~11~8 minecraft:wool 6
fill ~51~12~8 ~51~13~8 minecraft:wool 6
setblock ~52~9~8 minecraft:wool 6
fill ~13~10~9 ~13~12~9 minecraft:wool 6
fill ~14~9~9 ~15~11~9 minecraft:sandstone 0
fill ~14~12~9 ~14~14~9 minecraft:wool 6
fill ~15~7~9 ~15~8~9 minecraft:sandstone 0
fill ~15~12~9 ~15~13~9 minecraft:sandstone 0
fill ~15~14~9 ~15~15~9 minecraft:wool 6
fill ~16~5~9 ~17~5~9 minecraft:sandstone 0
setblock ~16~6~9 minecraft:sandstone 0
fill ~16~14~9 ~16~15~9 minecraft:sandstone 0
fill ~16~16~9 ~17~16~9 minecraft:wool 6
setblock ~17~15~9 minecraft:sandstone 0
setblock ~18~4~9 minecraft:sandstone 0
setblock ~18~16~9 minecraft:sandstone 0
setblock ~18~17~9 minecraft:wool 6
fill ~19~3~9 ~20~3~9 minecraft:sandstone 0
fill ~19~17~9 ~20~17~9 minecraft:sandstone 0
fill ~19~18~9 ~20~18~9 minecraft:wool 6
fill ~21~2~9 ~24~2~9 minecraft:sandstone 0
fill ~21~18~9 ~24~18~9 minecraft:sandstone 0
fill ~21~19~9 ~24~19~9 minecraft:wool 6
fill ~25~0~9 ~28~0~9 minecraft:stone 5
fill ~25~1~9 ~28~1~17 minecraft:sandstone 0
fill ~25~19~9 ~28~19~17 minecraft:sandstone 0
fill ~25~20~9 ~28~20~17 minecraft:wool 6
fill ~29~0~9 ~37~0~16 minecraft:dirt 0
fill ~31~1~9 ~35~1~16 minecraft:sandstone 0
fill ~33~21~9 ~34~21~9 minecraft:wool 11
fill ~38~0~9 ~41~0~9 minecraft:stone 5
fill ~38~1~9 ~41~1~17 minecraft:sandstone 0
fill ~38~19~9 ~41~19~17 minecraft:sandstone 0
fill ~38~20~9 ~41~20~17 minecraft:wool 6
fill ~42~2~9 ~45~2~9 minecraft:sandstone 0
fill ~42~18~9 ~45~18~9 minecraft:sandstone 0
fill ~42~19~9 ~45~19~9 minecraft:wool 6
fill ~46~3~9 ~47~3~9 minecraft:sandstone 0
fill ~46~17~9 ~47~17~9 minecraft:sandstone 0
fill ~46~18~9 ~47~18~9 minecraft:wool 6
setblock ~48~4~9 minecraft:sandstone 0
setblock ~48~16~9 minecraft:sandstone 0
setblock ~48~17~9 minecraft:wool 6
fill ~49~5~9 ~50~5~9 minecraft:sandstone 0
fill ~49~15~9 ~50~15~9 minecraft:sandstone 0
fill ~49~16~9 ~50~16~9 minecraft:wool 6
setblock ~50~6~9 minecraft:sandstone 0
setblock ~50~14~9 minecraft:sandstone 0
fill ~51~7~9 ~51~13~9 minecraft:sandstone 0
fill ~51~14~9 ~52~14~9 minecraft:wool 6
setblock ~51~15~9 minecraft:wool 6
fill ~52~9~9 ~52~11~9 minecraft:sandstone 0
fill ~52~12~9 ~53~12~9 minecraft:wool 6
setblock ~52~13~9 minecraft:wool 6
fill ~53~9~9 ~53~11~9 minecraft:wool 6
setblock ~12~4~10 minecraft:wool 6
fill ~12~9~10 ~12~13~10 minecraft:wool 6
fill ~13~8~10 ~14~8~10 minecraft:sandstone 0
fill ~13~9~10 ~13~12~10 minecraft:sandstone 0
fill ~13~13~10 ~13~14~10 minecraft:wool 6
fill ~14~6~10 ~15~6~10 minecraft:sandstone 0
setblock ~14~7~10 minecraft:sandstone 0
fill ~14~12~10 ~14~14~10 minecraft:sandstone 0
setblock ~14~15~10 minecraft:wool 6
setblock ~15~5~10 minecraft:sandstone 0
fill ~15~14~10 ~15~15~10 minecraft:sandstone 0
setblock ~15~16~10 minecraft:wool 6
fill ~16~4~10 ~17~4~10 minecraft:sandstone 0
fill ~16~16~10 ~17~16~10 minecraft:sandstone 0
fill ~16~17~10 ~17~17~10 minecraft:wool 6
fill ~18~3~10 ~19~3~10 minecraft:sandstone 0
fill ~18~17~10 ~19~17~10 minecraft:sandstone 0
fill ~18~18~10 ~19~18~10 minecraft:wool 6
fill ~20~2~10 ~22~2~10 minecraft:sandstone 0
fill ~20~18~10 ~22~18~10 minecraft:sandstone 0
fill ~20~19~10 ~22~19~10 minecraft:wool 6
fill ~23~0~10 ~24~0~10 minecraft:stone 5
fill ~23~1~10 ~24~1~19 minecraft:sandstone 0
fill ~23~19~10 ~24~19~19 minecraft:sandstone 0
fill ~23~20~10 ~24~20~19 minecraft:wool 6
fill ~24~21~10 ~24~21~11 minecraft:wool 10
fill ~25~0~10 ~28~0~17 minecraft:dirt 0
fill ~27~21~10 ~27~21~11 minecraft:wool 9
fill ~29~21~10 ~30~21~10 minecraft:wool 4
fill ~37~21~10 ~38~21~10 minecraft:wool 5
fill ~38~0~10 ~41~0~17 minecraft:dirt 0
fill ~40~21~10 ~40~21~11 minecraft:wool 3
fill ~42~0~10 ~43~0~10 minecraft:stone 5
fill ~42~1~10 ~43~1~19 minecraft:sandstone 0
fill ~42~19~10 ~43~19~19 minecraft:sandstone 0
fill ~42~20~10 ~43~20~19 minecraft:wool 6
fill ~44~2~10 ~46~2~10 minecraft:sandstone 0
fill ~44~18~10 ~46~18~10 minecraft:sandstone 0
fill ~44~19~10 ~46~19~10 minecraft:wool 6
fill ~47~3~10 ~48~3~10 minecraft:sandstone 0
fill ~47~17~10 ~48~17~10 minecraft:sandstone 0
fill ~47~18~10 ~48~18~10 minecraft:wool 6
fill ~49~4~10 ~50~4~10 minecraft:sandstone 0
fill ~49~16~10 ~50~16~10 minecraft:sandstone 0
fill ~49~17~10 ~50~17~10 minecraft:wool 6
fill ~51~5~10 ~51~6~10 minecraft:sandstone 0
fill ~51~14~10 ~52~14~10 minecraft:sandstone 0
setblock ~51~15~10 minecraft:sandstone 0
setblock ~51~16~10 minecraft:wool 6
fill ~52~6~10 ~52~8~10 minecraft:sandstone 0
fill ~52~12~10 ~53~12~10 minecraft:sandstone 0
setblock ~52~13~10 minecraft:sandstone 0
setblock ~52~15~10 minecraft:wool 6
fill ~53~8~10 ~53~11~10 minecraft:sandstone 0
fill ~53~13~10 ~53~14~10 minecraft:wool 6
fill ~54~10~10 ~54~12~10 minecraft:wool 6
fill ~11~11~11 ~11~12~11 minecraft:wool 6
fill ~12~8~11 ~12~12~11 minecraft:sandstone 0
fill ~12~13~11 ~12~14~11 minecraft:wool 6
fill ~13~6~11 ~13~7~11 minecraft:sandstone 0
fill ~13~13~11 ~13~14~11 minecraft:sandstone 0
setblock ~13~15~11 minecraft:wool 6
setblock ~14~5~11 minecraft:sandstone 0
setblock ~14~15~11 minecraft:sandstone 0
setblock ~14~16~11 minecraft:wool 6
setblock ~15~4~11 minecraft:sandstone 0
setblock ~15~16~11 minecraft:sandstone 0
setblock ~15~17~11 minecraft:wool 6
fill ~16~3~11 ~17~3~11 minecraft:sandstone 0
fill ~16~17~11 ~17~17~11 minecraft:sandstone 0
fill ~16~18~11 ~17~18~11 minecraft:wool 6
fill ~18~2~11 ~20~2~11 minecraft:sandstone 0
fill ~18~18~11 ~20~18~11 minecraft:sandstone 0
fill ~18~19~11 ~20~19~11 minecraft:wool 6
fill ~21~0~11 ~22~0~11 minecraft:stone 5
fill ~21~1~11 ~22~1~20 minecraft:sandstone 0
fill ~21~19~11 ~22~19~20 minecraft:sandstone 0
fill ~21~20~11 ~22~20~20 minecraft:wool 6
fill ~23~0~11 ~24~0~19 minecraft:dirt 0
fill ~32~21~11 ~32~21~12 minecraft:wool 14
fill ~42~0~11 ~43~0~19 minecraft:dirt 0
fill ~44~0~11 ~45~0~11 minecraft:stone 5
fill ~44~1~11 ~45~1~20 minecraft:sandstone 0
fill ~44~19~11 ~45~19~20 minecraft:sandstone 0
fill ~44~20~11 ~45~20~20 minecraft:wool 6
fill ~46~2~11 ~48~2~11 minecraft:sandstone 0
fill ~46~18~11 ~48~18~11 minecraft:sandstone 0
fill ~46~19~11 ~48~19~11 minecraft:wool 6
fill ~49~3~11 ~50~3~11 minecraft:sandstone 0
fill ~49~17~11 ~50~17~11 minecraft:sandstone 0
fill ~49~18~11 ~50~18~11 minecraft:wool 6
setblock ~51~4~11 minecraft:sandstone 0
setblock ~51~16~11 minecraft:sandstone 0
setblock ~51~17~11 minecraft:wool 6
setblock ~52~5~11 minecraft:sandstone 0
setblock ~52~15~11 minecraft:sandstone 0
setblock ~52~16~11 minecraft:wool 6
fill ~53~6~11 ~53~7~11 minecraft:sandstone 0
fill ~53~13~11 ~53~14~11 minecraft:sandstone 0
setblock ~53~15~11 minecraft:wool 6
fill ~54~8~11 ~54~12~11 minecraft:sandstone 0
fill ~54~13~11 ~54~14~11 minecraft:wool 6
fill ~55~8~11 ~55~12~11 minecraft:wool 6
fill ~10~10~12 ~10~12~12 minecraft:wool 6
fill ~11~8~12 ~11~8~13 minecraft:sandstone 0
fill ~11~9~12 ~11~12~12 minecraft:sandstone 0
fill ~11~13~12 ~11~14~12 minecraft:wool 6
fill ~12~6~12 ~12~7~12 minecraft:sandstone 0
fill ~12~13~12 ~12~14~12 minecraft:sandstone 0
setblock ~12~15~12 minecraft:wool 6
setblock ~13~5~12 minecraft:sandstone 0
setblock ~13~15~12 minecraft:sandstone 0
setblock ~13~16~12 minecraft:wool 6
setblock ~14~4~12 minecraft:sandstone 0
setblock ~14~16~12 minecraft:sandstone 0
setblock ~14~17~12 minecraft:wool 6
fill ~15~3~12 ~16~3~12 minecraft:sandstone 0
fill ~15~17~12 ~16~17~12 minecraft:sandstone 0
fill ~15~18~12 ~16~18~12 minecraft:wool 6
fill ~17~2~12 ~19~2~12 minecraft:sandstone 0
fill ~17~18~12 ~19~18~12 minecraft:sandstone 0
fill ~17~19~12 ~19~19~12 minecraft:wool 6
setblock ~20~0~12 minecraft:stone 5
fill ~20~1~12 ~20~1~23 minecraft:sandstone 0
fill ~20~19~12 ~20~19~23 minecraft:sandstone 0
fill ~20~20~12 ~20~20~23 minecraft:wool 6
fill ~20~21~12 ~21~21~12 minecraft:wool 5
fill ~21~0~12 ~22~0~20 minecraft:dirt 0
fill ~34~21~12 ~34~21~13 minecraft:wool 13
fill ~37~21~12 ~37~21~13 minecraft:wool 2
fill ~42~21~12 ~43~21~12 minecraft:wool 13
fill ~44~0~12 ~45~0~20 minecraft:dirt 0
fill ~45~21~12 ~45~21~13 minecraft:wool 10
setblock ~46~0~12 minecraft:stone 5
fill ~46~1~12 ~46~1~23 minecraft:sandstone 0
fill ~46~19~12 ~46~19~23 minecraft:sandstone 0
fill ~46~20~12 ~46~20~23 minecraft:wool 6
fill ~47~2~12 ~49~2~12 minecraft:sandstone 0
fill ~47~18~12 ~49~18~12 minecraft:sandstone 0
fill ~47~19~12 ~49~19~12 minecraft:wool 6
fill ~50~3~12 ~51~3~12 minecraft:sandstone 0
fill ~50~17~12 ~51~17~12 minecraft:sandstone 0
fill ~50~18~12 ~51~18~12 minecraft:wool 6
setblock ~52~4~12 minecraft:sandstone 0
setblock ~52~16~12 minecraft:sandstone 0
setblock ~52~17~12 minecraft:wool 6
setblock ~53~5~12 minecraft:sandstone 0
setblock ~53~15~12 minecraft:sandstone 0
setblock ~53~16~12 minecraft:wool 6
fill ~54~6~12 ~54~7~12 minecraft:sandstone 0
fill ~54~13~12 ~54~14~12 minecraft:sandstone 0
setblock ~54~15~12 minecraft:wool 6
fill ~55~8~12 ~55~8~13 minecraft:sandstone 0
fill ~55~9~12 ~55~12~12 minecraft:sandstone 0
fill ~55~13~12 ~55~14~12 minecraft:wool 6
fill ~56~9~12 ~56~12~12 minecraft:wool 6
fill ~9~9~13 ~9~13~13 minecraft:wool 6
fill ~10~9~13 ~10~11~14 minecraft:sandstone 0
fill ~10~12~13 ~10~14~13 minecraft:wool 6
fill ~11~6~13 ~11~6~14 minecraft:sandstone 0
setblock ~11~7~13 minecraft:sandstone 0
fill ~11~12~13 ~11~14~13 minecraft:sandstone 0
setblock ~11~15~13 minecraft:wool 6
setblock ~12~5~13 minecraft:sandstone 0
setblock ~12~15~13 minecraft:sandstone 0
setblock ~12~16~13 minecraft:wool 6
setblock ~13~4~13 minecraft:sandstone 0
setblock ~13~16~13 minecraft:sandstone 0
setblock ~13~17~13 minecraft:wool 6
fill ~14~3~13 ~15~3~13 minecraft:sandstone 0
fill ~14~17~13 ~15~17~13 minecraft:sandstone 0
fill ~14~18~13 ~15~18~13 minecraft:wool 6
fill ~16~2~13 ~17~2~13 minecraft:sandstone 0
fill ~16~18~13 ~17~18~13 minecraft:sandstone 0
fill ~16~19~13 ~17~19~13 minecraft:wool 6
fill ~18~0~13 ~19~0~13 minecraft:stone 5
fill ~18~1~13 ~19~1~25 minecraft:sandstone 0
fill ~18~19~13 ~19~19~25 minecraft:sandstone 0
fill ~18~20~13 ~19~20~25 minecraft:wool 6
fill ~20~0~13 ~20~0~23 minecraft:dirt 0
fill ~23~21~13 ~24~21~13 minecraft:wool 2
fill ~26~21~13 ~26~21~14 minecraft:wool 14
fill ~29~21~13 ~30~21~13 minecraft:wool 3
fill ~39~21~13 ~40~21~13 minecraft:wool 14
fill ~46~0~13 ~46~0~23 minecraft:dirt 0
fill ~47~0~13 ~48~0~13 minecraft:stone 5
fill ~47~1~13 ~48~1~25 minecraft:sandstone 0
fill ~47~19~13 ~48~19~25 minecraft:sandstone 0
fill ~47~20~13 ~48~20~25 minecraft:wool 6
fill ~49~2~13 ~50~2~13 minecraft:sandstone 0
fill ~49~18~13 ~50~18~13 minecraft:sandstone 0
fill ~49~19~13 ~50~19~13 minecraft:wool 6
fill ~51~3~13 ~52~3~13 minecraft:sandstone 0
fill ~51~17~13 ~52~17~13 minecraft:sandstone 0
fill ~51~18~13 ~52~18~13 minecraft:wool 6
setblock ~53~4~13 minecraft:sandstone 0
setblock ~53~16~13 minecraft:sandstone 0
setblock ~53~17~13 minecraft:wool 6
setblock ~54~5~13 minecraft:sandstone 0
setblock ~54~15~13 minecraft:sandstone 0
setblock ~54~16~13 minecraft:wool 6
fill ~55~6~13 ~55~6~14 minecraft:sandstone 0
setblock ~55~7~13 minecraft:sandstone 0
fill ~55~12~13 ~55~14~13 minecraft:sandstone 0
setblock ~55~15~13 minecraft:wool 6
fill ~56~9~13 ~56~11~14 minecraft:sandstone 0
fill ~56~12~13 ~56~14~13 minecraft:wool 6
fill ~57~9~13 ~57~11~14 minecraft:wool 6
fill ~8~12~14 ~9~13~14 minecraft:wool 6
setblock ~9~11~14 minecraft:wool 6
fill ~9~14~14 ~10~14~14 minecraft:wool 6
fill ~10~7~14 ~10~8~14 minecraft:sandstone 0
fill ~10~12~14 ~10~13~14 minecraft:sandstone 0
setblock ~10~15~14 minecraft:wool 6
setblock ~11~5~14 minecraft:sandstone 0
fill ~11~14~14 ~11~15~14 minecraft:sandstone 0
setblock ~11~16~14 minecraft:wool 6
setblock ~12~4~14 minecraft:sandstone 0
setblock ~12~16~14 minecraft:sandstone 0
setblock ~12~17~14 minecraft:wool 6
fill ~13~3~14 ~14~3~14 minecraft:sandstone 0
fill ~13~17~14 ~14~17~14 minecraft:sandstone 0
fill ~13~18~14 ~14~18~14 minecraft:wool 6
fill ~15~2~14 ~16~2~14 minecraft:sandstone 0
fill ~15~18~14 ~16~18~14 minecraft:sandstone 0
fill ~15~19~14 ~16~19~14 minecraft:wool 6
setblock ~17~0~14 minecraft:stone 5
fill ~17~1~14 ~17~1~50 minecraft:sandstone 0
fill ~17~19~14 ~17~19~50 minecraft:sandstone 0
fill ~17~20~14 ~17~20~50 minecraft:wool 6
fill ~18~0~14 ~19~0~25 minecraft:dirt 0
fill ~19~21~14 ~19~21~15 minecraft:wool 1
fill ~47~0~14 ~48~0~25 minecraft:dirt 0
fill ~47~21~14 ~48~21~14 minecraft:wool 9
setblock ~49~0~14 minecraft:stone 5
fill ~49~1~14 ~49~1~50 minecraft:sandstone 0
fill ~49~19~14 ~49~19~50 minecraft:sandstone 0
fill ~49~20~14 ~49~20~50 minecraft:wool 6
fill ~50~2~14 ~51~2~14 minecraft:sandstone 0
fill ~50~18~14 ~51~18~14 minecraft:sandstone 0
fill ~50~19~14 ~51~19~14 minecraft:wool 6
fill ~52~3~14 ~53~3~14 minecraft:sandstone 0
fill ~52~17~14 ~53~17~14 minecraft:sandstone 0
fill ~52~18~14 ~53~18~14 minecraft:wool 6
setblock ~54~4~14 minecraft:sandstone 0
setblock ~54~16~14 minecraft:sandstone 0
setblock ~54~17~14 minecraft:wool 6
setblock ~55~5~14 minecraft:sandstone 0
fill ~55~14~14 ~55~15~14 minecraft:sandstone 0
setblock ~55~16~14 minecraft:wool 6
fill ~56~7~14 ~56~8~14 minecraft:sandstone 0
fill ~56~12~14 ~56~13~14 minecraft:sandstone 0
fill ~56~14~14 ~56~15~14 minecraft:wool 6
setblock ~57~8~14 minecraft:wool 6
fill ~57~12~14 ~57~13~14 minecraft:wool 6
fill ~8~9~15 ~8~14~15 minecraft:wool 6
fill ~9~7~15 ~9~7~16 minecraft:sandstone 0
fill ~9~8~15 ~9~13~15 minecraft:sandstone 0
fill ~9~14~15 ~9~15~15 minecraft:wool 6
fill ~10~5~15 ~10~5~16 minecraft:sandstone 0
setblock ~10~6~15 minecraft:sandstone 0
fill ~10~14~15 ~10~15~15 minecraft:sandstone 0
fill ~10~16~15 ~10~16~16 minecraft:wool 6
fill ~11~4~15 ~11~4~16 minecraft:sandstone 0
fill ~11~16~15 ~11~16~16 minecraft:sandstone 0
fill ~11~17~15 ~11~17~16 minecraft:wool 6
fill ~12~3~15 ~13~3~15 minecraft:sandstone 0
fill ~12~17~15 ~13~17~15 minecraft:sandstone 0
fill ~12~18~15 ~13~18~15 minecraft:wool 6
fill ~14~2~15 ~15~2~15 minecraft:sandstone 0
fill ~14~18~15 ~15~18~15 minecraft:sandstone 0
fill ~14~19~15 ~15~19~15 minecraft:wool 6
setblock ~16~0~15 minecraft:stone 5
fill ~16~1~15 ~16~1~49 minecraft:sandstone 0
fill ~16~19~15 ~16~19~49 minecraft:sandstone 0
fill ~16~20~15 ~16~20~49 minecraft:wool 6
fill ~16~21~15 ~17~21~15 minecraft:wool 9
fill ~17~0~15 ~17~0~49 minecraft:dirt 0
fill ~21~21~15 ~21~21~16 minecraft:wool 3
fill ~23~21~15 ~24~21~15 minecraft:wool 11
fill ~29~21~15 ~29~21~16 minecraft:wool 5
fill ~32~21~15 ~33~21~15 minecraft:wool 10
fill ~35~21~15 ~35~21~16 minecraft:wool 9
fill ~37~21~15 ~38~21~15 minecraft:wool 4
fill ~43~21~15 ~43~21~16 minecraft:wool 1
fill ~49~0~15 ~49~0~49 minecraft:dirt 0
setblock ~50~0~15 minecraft:stone 5
fill ~50~1~15 ~50~1~49 minecraft:sandstone 0
fill ~50~19~15 ~50~19~49 minecraft:sandstone 0
fill ~50~20~15 ~50~20~49 minecraft:wool 6
fill ~51~2~15 ~52~2~15 minecraft:sandstone 0
fill ~51~18~15 ~52~18~15 minecraft:sandstone 0
fill ~51~19~15 ~52~19~15 minecraft:wool 6
fill ~53~3~15 ~54~3~15 minecraft:sandstone 0
fill ~53~17~15 ~54~17~15 minecraft:sandstone 0
fill ~53~18~15 ~54~18~15 minecraft:wool 6
fill ~55~4~15 ~55~4~16 minecraft:sandstone 0
fill ~55~16~15 ~55~16~16 minecraft:sandstone 0
fill ~55~17~15 ~55~17~16 minecraft:wool 6
fill ~56~5~15 ~56~5~16 minecraft:sandstone 0
setblock ~56~6~15 minecraft:sandstone 0
fill ~56~14~15 ~56~15~15 minecraft:sandstone 0
fill ~56~16~15 ~56~16~16 minecraft:wool 6
fill ~57~7~15 ~57~7~16 minecraft:sandstone 0
fill ~57~8~15 ~57~13~15 minecraft:sandstone 0
fill ~57~14~15 ~57~15~15 minecraft:wool 6
fill ~58~9~15 ~58~13~15 minecraft:wool 6
fill ~7~11~16 ~7~12~17 minecraft:wool 6
fill ~8~8~16 ~8~12~17 minecraft:sandstone 0
fill ~8~13~16 ~8~14~16 minecraft:wool 6
setblock ~9~6~16 minecraft:sandstone 0
fill ~9~13~16 ~9~14~16 minecraft:sandstone 0
setblock ~9~15~16 minecraft:wool 6
setblock ~10~15~16 minecraft:sandstone 0
setblock ~12~3~16 minecraft:sandstone 0
setblock ~12~17~16 minecraft:sandstone 0
setblock ~12~18~16 minecraft:wool 6
fill ~13~2~16 ~14~2~16 minecraft:sandstone 0
fill ~13~18~16 ~14~18~16 minecraft:sandstone 0
fill ~13~19~16 ~14~19~16 minecraft:wool 6
setblock ~15~0~16 minecraft:stone 5
fill ~15~1~16 ~15~1~48 minecraft:sandstone 0
fill ~15~19~16 ~15~19~48 minecraft:sandstone 0
fill ~15~20~16 ~15~20~48 minecraft:wool 6
fill ~16~0~16 ~16~0~48 minecraft:dirt 0
fill ~26~21~16 ~27~21~16 minecraft:wool 1
fill ~40~21~16 ~40~21~17 minecraft:wool 11
fill ~45~21~16 ~46~21~16 minecraft:wool 4
fill ~48~21~16 ~49~21~16 minecraft:wool 2
fill ~50~0~16 ~50~0~48 minecraft:dirt 0
setblock ~51~0~16 minecraft:stone 5
fill ~51~1~16 ~51~1~48 minecraft:sandstone 0
fill ~51~19~16 ~51~19~48 minecraft:sandstone 0
fill ~51~20~16 ~51~20~48 minecraft:wool 6
fill ~52~2~16 ~53~2~16 minecraft:sandstone 0
fill ~52~18~16 ~53~18~16 minecraft:sandstone 0
fill ~52~19~16 ~53~19~16 minecraft:wool 6
setblock ~54~3~16 minecraft:sandstone 0
setblock ~54~17~16 minecraft:sandstone 0
setblock ~54~18~16 minecraft:wool 6
setblock ~56~15~16 minecraft:sandstone 0
setblock ~57~6~16 minecraft:sandstone 0
fill ~57~13~16 ~57~14~16 minecraft:sandstone 0
setblock ~57~15~16 minecraft:wool 6
fill ~58~8~16 ~58~12~17 minecraft:sandstone 0
fill ~58~13~16 ~58~14~16 minecraft:wool 6
fill ~59~10~16 ~59~12~17 minecraft:wool 6
setblock ~7~10~17 minecraft:wool 6
fill ~7~13~17 ~7~14~17 minecraft:wool 6
fill ~8~6~17 ~8~6~18 minecraft:sandstone 0
setblock ~8~7~17 minecraft:sandstone 0
fill ~8~13~17 ~8~14~17 minecraft:sandstone 0
setblock ~8~15~17 minecraft:wool 6
setblock ~9~5~17 minecraft:sandstone 0
setblock ~9~15~17 minecraft:sandstone 0
setblock ~9~16~17 minecraft:wool 6
setblock ~10~4~17 minecraft:sandstone 0
setblock ~10~16~17 minecraft:sandstone 0
setblock ~10~17~17 minecraft:wool 6
fill ~11~3~17 ~11~3~18 minecraft:sandstone 0
fill ~11~17~17 ~11~17~18 minecraft:sandstone 0
fill ~11~18~17 ~11~18~18 minecraft:wool 6
fill ~12~2~17 ~13~2~18 minecraft:sandstone 0
fill ~12~18~17 ~13~18~18 minecraft:sandstone 0
fill ~12~19~17 ~13~19~18 minecraft:wool 6
fill ~14~0~17 ~14~0~18 minecraft:stone 5
fill ~14~1~17 ~14~1~47 minecraft:sandstone 0
fill ~14~19~17 ~14~19~47 minecraft:sandstone 0
fill ~14~20~17 ~14~20~47 minecraft:wool 6
fill ~15~0~17 ~15~0~47 minecraft:dirt 0
fill ~15~21~17 ~16~21~17 minecraft:wool 13
fill ~24~21~17 ~24~21~18 minecraft:wool 13
setblock ~28~2~17 minecraft:sea_lantern
fill ~29~0~17 ~37~0~47 minecraft:mycelium
fill ~29~2~17 ~37~2~17 minecraft:sandstone 0
fill ~29~18~17 ~37~18~17 minecraft:sandstone 0
fill ~29~19~17 ~37~19~17 minecraft:wool 6
setblock ~38~2~17 minecraft:sea_lantern
fill ~51~0~17 ~51~0~47 minecraft:dirt 0
fill ~52~0~17 ~52~0~18 minecraft:stone 5
fill ~52~1~17 ~52~1~47 minecraft:sandstone 0
fill ~52~19~17 ~52~19~47 minecraft:sandstone 0
fill ~52~20~17 ~52~20~47 minecraft:wool 6
fill ~53~2~17 ~54~2~18 minecraft:sandstone 0
fill ~53~18~17 ~54~18~18 minecraft:sandstone 0
fill ~53~19~17 ~54~19~18 minecraft:wool 6
fill ~55~3~17 ~55~3~18 minecraft:sandstone 0
fill ~55~17~17 ~55~17~18 minecraft:sandstone 0
fill ~55~18~17 ~55~18~18 minecraft:wool 6
setblock ~56~4~17 minecraft:sandstone 0
setblock ~56~16~17 minecraft:sandstone 0
setblock ~56~17~17 minecraft:wool 6
setblock ~57~5~17 minecraft:sandstone 0
setblock ~57~15~17 minecraft:sandstone 0
setblock ~57~16~17 minecraft:wool 6
fill ~58~6~17 ~58~6~18 minecraft:sandstone 0
setblock ~58~7~17 minecraft:sandstone 0
fill ~58~13~17 ~58~14~17 minecraft:sandstone 0
setblock ~58~15~17 minecraft:wool 6
setblock ~59~9~17 minecraft:wool 6
fill ~59~13~17 ~59~14~17 minecraft:wool 6
fill ~6~11~18 ~6~13~19 minecraft:wool 6
fill ~7~7~18 ~7~7~20 minecraft:sandstone 0
fill ~7~8~18 ~7~9~19 minecraft:sandstone 0
fill ~7~10~18 ~7~13~18 minecraft:sandstone 0
fill ~7~14~18 ~7~15~18 minecraft:wool 6
fill ~8~5~18 ~8~5~19 minecraft:sandstone 0
fill ~8~14~18 ~8~15~18 minecraft:sandstone 0
fill ~8~16~18 ~8~16~19 minecraft:wool 6
fill ~9~4~18 ~9~4~19 minecraft:sandstone 0
fill ~9~16~18 ~9~16~19 minecraft:sandstone 0
fill ~9~17~18 ~9~17~19 minecraft:wool 6
fill ~10~3~18 ~10~3~19 minecraft:sandstone 0
fill ~10~17~18 ~10~17~19 minecraft:sandstone 0
fill ~10~18~18 ~10~18~19 minecraft:wool 6
fill ~19~21~18 ~19~21~19 minecraft:wool 10
fill ~21~21~18 ~22~21~18 minecraft:wool 4
fill ~25~0~18 ~26~0~18 minecraft:dirt 0
fill ~25~1~18 ~26~1~18 minecraft:sandstone 0
fill ~25~19~18 ~26~19~18 minecraft:sandstone 0
fill ~25~20~18 ~26~20~18 minecraft:wool 6
fill ~27~0~18 ~28~0~46 minecraft:mycelium
fill ~27~2~18 ~32~2~18 minecraft:sandstone 0
fill ~27~18~18 ~32~18~18 minecraft:sandstone 0
fill ~27~19~18 ~32~19~18 minecraft:wool 6
fill ~33~3~18 ~33~3~19 minecraft:sandstone 0
fill ~33~17~18 ~33~17~19 minecraft:sandstone 0
fill ~33~18~18 ~33~18~19 minecraft:wool 6
fill ~34~2~18 ~39~2~18 minecraft:sandstone 0
fill ~34~18~18 ~39~18~18 minecraft:sandstone 0
fill ~34~19~18 ~39~19~18 minecraft:wool 6
fill ~38~0~18 ~39~0~46 minecraft:mycelium
fill ~40~0~18 ~41~0~18 minecraft:dirt 0
fill ~40~1~18 ~41~1~18 minecraft:sandstone 0
fill ~40~19~18 ~41~19~18 minecraft:sandstone 0
fill ~40~20~18 ~41~20~18 minecraft:wool 6
fill ~42~21~18 ~43~21~18 minecraft:wool 5
fill ~47~21~18 ~47~21~19 minecraft:wool 14
fill ~49~21~18 ~49~21~19 minecraft:wool 13
fill ~51~21~18 ~52~21~18 minecraft:wool 11
fill ~56~3~18 ~56~3~19 minecraft:sandstone 0
fill ~56~17~18 ~56~17~19 minecraft:sandstone 0
fill ~56~18~18 ~56~18~19 minecraft:wool 6
fill ~57~4~18 ~57~4~19 minecraft:sandstone 0
fill ~57~16~18 ~57~16~19 minecraft:sandstone 0
fill ~57~17~18 ~57~17~19 minecraft:wool 6
fill ~58~5~18 ~58~5~19 minecraft:sandstone 0
fill ~58~14~18 ~58~15~18 minecraft:sandstone 0
fill ~58~16~18 ~58~16~19 minecraft:wool 6
fill ~59~7~18 ~59~7~20 minecraft:sandstone 0
fill ~59~8~18 ~59~9~19 minecraft:sandstone 0
fill ~59~10~18 ~59~13~18 minecraft:sandstone 0
fill ~59~14~18 ~59~15~18 minecraft:wool 6
fill ~60~9~18 ~60~9~19 minecraft:wool 6
fill ~60~10~18 ~60~13~18 minecraft:wool 6
fill ~6~10~19 ~6~10~21 minecraft:sandstone 0
fill ~6~14~19 ~6~14~20 minecraft:wool 6
fill ~7~6~19 ~7~6~20 minecraft:sandstone 0
fill ~7~11~19 ~7~14~19 minecraft:sandstone 0
setblock ~7~15~19 minecraft:wool 6
setblock ~8~15~19 minecraft:sandstone 0
fill ~11~2~19 ~12~2~19 minecraft:sandstone 0
fill ~11~18~19 ~12~18~19 minecraft:sandstone 0
fill ~11~19~19 ~12~19~19 minecraft:wool 6
setblock ~13~0~19 minecraft:stone 5
fill ~13~1~19 ~13~1~45 minecraft:sandstone 0
fill ~13~19~19 ~13~19~45 minecraft:sandstone 0
fill ~13~20~19 ~13~20~45 minecraft:wool 6
fill ~14~0~19 ~14~0~45 minecraft:dirt 0
fill ~14~21~19 ~14~21~20 minecraft:wool 4
fill ~25~0~19 ~26~0~45 minecraft:mycelium
fill ~25~2~19 ~27~2~19 minecraft:sandstone 0
fill ~25~18~19 ~27~18~19 minecraft:sandstone 0
fill ~25~19~19 ~27~19~19 minecraft:wool 6
fill ~28~3~19 ~32~3~19 minecraft:sandstone 0
fill ~28~17~19 ~32~17~19 minecraft:sandstone 0
fill ~28~18~19 ~32~18~19 minecraft:wool 6
setblock ~33~4~19 minecraft:sandstone 0
setblock ~33~16~19 minecraft:sandstone 0
fill ~34~3~19 ~38~3~19 minecraft:sandstone 0
fill ~34~17~19 ~38~17~19 minecraft:sandstone 0
fill ~34~18~19 ~38~18~19 minecraft:wool 6
fill ~39~2~19 ~41~2~19 minecraft:sandstone 0
fill ~39~18~19 ~41~18~19 minecraft:sandstone 0
fill ~39~19~19 ~41~19~19 minecraft:wool 6
fill ~40~0~19 ~41~0~45 minecraft:mycelium
fill ~45~21~19 ~45~21~20 minecraft:wool 3
fill ~52~0~19 ~52~0~45 minecraft:dirt 0
setblock ~53~0~19 minecraft:stone 5
fill ~53~1~19 ~53~1~45 minecraft:sandstone 0
fill ~53~19~19 ~53~19~45 minecraft:sandstone 0
fill ~53~20~19 ~53~20~45 minecraft:wool 6
fill ~54~2~19 ~55~2~19 minecraft:sandstone 0
fill ~54~18~19 ~55~18~19 minecraft:sandstone 0
fill ~54~19~19 ~55~19~19 minecraft:wool 6
setblock ~58~15~19 minecraft:sandstone 0
fill ~59~6~19 ~59~6~20 minecraft:sandstone 0
fill ~59~11~19 ~59~14~19 minecraft:sandstone 0
setblock ~59~15~19 minecraft:wool 6
fill ~60~7~19 ~60~8~19 minecraft:wool 6
fill ~60~10~19 ~60~10~21 minecraft:sandstone 0
fill ~60~11~19 ~61~11~19 minecraft:wool 6
fill ~60~12~19 ~60~14~19 minecraft:wool 6
fill ~61~9~19 ~61~10~19 minecraft:wool 6
fill ~6~8~20 ~6~9~21 minecraft:sandstone 0
fill ~6~11~20 ~6~12~21 minecraft:sandstone 0
setblock ~6~13~20 minecraft:wool 6
fill ~6~15~20 ~6~15~22 minecraft:wool 6
fill ~7~5~20 ~7~5~22 minecraft:sandstone 0
fill ~7~13~20 ~7~15~20 minecraft:sandstone 0
fill ~7~16~20 ~7~16~21 minecraft:wool 6
fill ~8~4~20 ~8~4~21 minecraft:sandstone 0
fill ~8~16~20 ~8~16~21 minecraft:sandstone 0
fill ~8~17~20 ~8~17~21 minecraft:wool 6
fill ~9~3~20 ~9~3~22 minecraft:sandstone 0
fill ~9~17~20 ~9~17~22 minecraft:sandstone 0
fill ~9~18~20 ~9~18~22 minecraft:wool 6
fill ~10~2~20 ~11~2~21 minecraft:sandstone 0
fill ~10~18~20 ~11~18~21 minecraft:sandstone 0
fill ~10~19~20 ~11~19~21 minecraft:wool 6
fill ~12~0~20 ~12~0~21 minecraft:stone 5
fill ~12~1~20 ~12~1~44 minecraft:sandstone 0
fill ~12~19~20 ~12~19~44 minecraft:sandstone 0
fill ~12~20~20 ~12~20~44 minecraft:wool 6
fill ~13~0~20 ~13~0~44 minecraft:dirt 0
fill ~16~21~20 ~16~21~21 minecraft:wool 11
fill ~21~21~20 ~21~21~21 minecraft:wool 9
setblock ~22~2~20 minecraft:sea_lantern
fill ~23~0~20 ~24~0~44 minecraft:mycelium
fill ~23~2~20 ~25~2~20 minecraft:sandstone 0
fill ~23~18~20 ~25~18~20 minecraft:sandstone 0
fill ~23~19~20 ~25~19~20 minecraft:wool 6
fill ~26~3~20 ~28~3~20 minecraft:sandstone 0
fill ~26~17~20 ~28~17~20 minecraft:sandstone 0
fill ~26~18~20 ~28~18~20 minecraft:wool 6
fill ~29~4~20 ~32~4~20 minecraft:sandstone 0
fill ~29~16~20 ~32~16~20 minecraft:sandstone 0
fill ~29~17~20 ~37~17~20 minecraft:wool 6
fill ~31~5~20 ~35~5~20 minecraft:sandstone 0
fill ~31~15~20 ~35~15~20 minecraft:sandstone 0
fill ~33~16~20 ~33~16~21 minecraft:wool 6
fill ~34~4~20 ~37~4~20 minecraft:sandstone 0
fill ~34~16~20 ~37~16~20 minecraft:sandstone 0
fill ~38~3~20 ~40~3~20 minecraft:sandstone 0
fill ~38~17~20 ~40~17~20 minecraft:sandstone 0
fill ~38~18~20 ~40~18~20 minecraft:wool 6
fill ~41~2~20 ~43~2~20 minecraft:sandstone 0
fill ~41~18~20 ~43~18~20 minecraft:sandstone 0
fill ~41~19~20 ~43~19~20 minecraft:wool 6
fill ~42~0~20 ~43~0~44 minecraft:mycelium
setblock ~44~2~20 minecraft:sea_lantern
fill ~52~21~20 ~52~21~21 minecraft:wool 10
fill ~53~0~20 ~53~0~44 minecraft:dirt 0
fill ~54~0~20 ~54~0~21 minecraft:stone 5
fill ~54~1~20 ~54~1~44 minecraft:sandstone 0
fill ~54~19~20 ~54~19~44 minecraft:sandstone 0
fill ~54~20~20 ~54~20~44 minecraft:wool 6
fill ~55~2~20 ~56~2~21 minecraft:sandstone 0
fill ~55~18~20 ~56~18~21 minecraft:sandstone 0
fill ~55~19~20 ~56~19~21 minecraft:wool 6
fill ~57~3~20 ~57~3~22 minecraft:sandstone 0
fill ~57~17~20 ~57~17~22 minecraft:sandstone 0
fill ~57~18~20 ~57~18~22 minecraft:wool 6
fill ~58~4~20 ~58~4~21 minecraft:sandstone 0
fill ~58~16~20 ~58~16~21 minecraft:sandstone 0
fill ~58~17~20 ~58~17~21 minecraft:wool 6
fill ~59~5~20 ~59~5~22 minecraft:sandstone 0
fill ~59~13~20 ~59~15~20 minecraft:sandstone 0
fill ~59~16~20 ~59~16~21 minecraft:wool 6
fill ~60~8~20 ~60~9~21 minecraft:sandstone 0
fill ~60~11~20 ~60~12~21 minecraft:sandstone 0
fill ~60~13~20 ~60~15~20 minecraft:wool 6
fill ~61~11~20 ~61~12~21 minecraft:wool 6
fill ~5~12~21 ~5~14~21 minecraft:wool 6
fill ~6~6~21 ~6~6~23 minecraft:sandstone 0
fill ~6~7~21 ~6~7~22 minecraft:sandstone 0
fill ~6~13~21 ~6~14~22 minecraft:sandstone 0
fill ~7~15~21 ~7~15~22 minecraft:sandstone 0
fill ~12~21~21 ~12~21~22 minecraft:wool 3
setblock ~21~0~21 minecraft:dirt 0
setblock ~21~1~21 minecraft:sandstone 0
setblock ~21~2~21 minecraft:sea_lantern
setblock ~21~19~21 minecraft:sandstone 0
setblock ~21~20~21 minecraft:wool 6
fill ~22~0~21 ~22~0~43 minecraft:mycelium
fill ~22~2~21 ~24~2~21 minecraft:sandstone 0
fill ~22~18~21 ~24~18~21 minecraft:sandstone 0
fill ~22~19~21 ~24~19~21 minecraft:wool 6
fill ~25~3~21 ~26~3~21 minecraft:sandstone 0
fill ~25~17~21 ~26~17~21 minecraft:sandstone 0
fill ~25~18~21 ~26~18~21 minecraft:wool 6
fill ~27~4~21 ~28~4~21 minecraft:sandstone 0
fill ~27~16~21 ~28~16~21 minecraft:sandstone 0
fill ~27~17~21 ~28~17~21 minecraft:wool 6
fill ~28~5~21 ~30~5~21 minecraft:sandstone 0
fill ~28~15~21 ~30~15~21 minecraft:sandstone 0
fill ~29~6~21 ~37~6~21 minecraft:sandstone 0
fill ~29~14~21 ~37~14~21 minecraft:sandstone 0
fill ~29~16~21 ~32~16~21 minecraft:wool 6
fill ~30~7~21 ~36~7~21 minecraft:sandstone 0
fill ~30~13~21 ~36~13~21 minecraft:sandstone 0
fill ~31~8~21 ~35~8~21 minecraft:sandstone 0
fill ~31~12~21 ~35~12~21 minecraft:sandstone 0
fill ~31~15~21 ~35~15~21 minecraft:wool 6
fill ~32~9~21 ~34~9~21 minecraft:sandstone 0
fill ~32~11~21 ~34~11~21 minecraft:sandstone 0
setblock ~33~10~21 minecraft:sea_lantern
fill ~34~16~21 ~37~16~21 minecraft:wool 6
fill ~36~5~21 ~38~5~21 minecraft:sandstone 0
fill ~36~15~21 ~38~15~21 minecraft:sandstone 0
fill ~38~4~21 ~39~4~21 minecraft:sandstone 0
fill ~38~16~21 ~39~16~21 minecraft:sandstone 0
fill ~38~17~21 ~39~17~21 minecraft:wool 6
fill ~40~3~21 ~41~3~21 minecraft:sandstone 0
fill ~40~17~21 ~41~17~21 minecraft:sandstone 0
fill ~40~18~21 ~41~18~21 minecraft:wool 6
fill ~42~2~21 ~44~2~21 minecraft:sandstone 0
fill ~42~18~21 ~44~18~21 minecraft:sandstone 0
fill ~42~19~21 ~44~19~21 minecraft:wool 6
fill ~44~0~21 ~44~0~43 minecraft:mycelium
setblock ~45~0~21 minecraft:dirt 0
setblock ~45~1~21 minecraft:sandstone 0
setblock ~45~2~21 minecraft:sea_lantern
setblock ~45~19~21 minecraft:sandstone 0
setblock ~45~20~21 minecraft:wool 6
fill ~49~21~21 ~50~21~21 minecraft:wool 4
fill ~59~15~21 ~59~15~22 minecraft:sandstone 0
fill ~60~6~21 ~60~6~23 minecraft:sandstone 0
fill ~60~7~21 ~60~7~22 minecraft:sandstone 0
fill ~60~13~21 ~60~14~22 minecraft:sandstone 0
fill ~60~15~21 ~60~15~22 minecraft:wool 6
fill ~61~7~21 ~61~10~21 minecraft:wool 6
fill ~61~13~21 ~61~14~22 minecraft:wool 6
fill ~4~10~22 ~4~13~23 minecraft:wool 6
fill ~5~8~22 ~5~8~25 minecraft:sandstone 0
fill ~5~9~22 ~5~12~24 minecraft:sandstone 0
fill ~5~13~22 ~5~14~22 minecraft:wool 6
fill ~6~16~22 ~6~16~24 minecraft:wool 6
fill ~7~4~22 ~7~4~24 minecraft:sandstone 0
fill ~7~16~22 ~7~16~24 minecraft:sandstone 0
fill ~7~17~22 ~7~17~24 minecraft:wool 6
fill ~8~3~22 ~8~3~24 minecraft:sandstone 0
fill ~8~17~22 ~8~17~24 minecraft:sandstone 0
fill ~8~18~22 ~8~18~24 minecraft:wool 6
fill ~10~2~22 ~10~2~23 minecraft:sandstone 0
fill ~10~18~22 ~10~18~23 minecraft:sandstone 0
fill ~10~19~22 ~10~19~23 minecraft:wool 6
fill ~11~0~22 ~11~0~23 minecraft:stone 5
fill ~11~1~22 ~11~1~42 minecraft:sandstone 0
fill ~11~19~22 ~11~19~42 minecraft:sandstone 0
fill ~11~20~22 ~11~20~42 minecraft:wool 6
fill ~12~0~22 ~12~0~42 minecraft:dirt 0
fill ~18~21~22 ~19~21~22 minecraft:wool 14
fill ~21~0~22 ~21~0~42 minecraft:mycelium
fill ~21~2~22 ~23~2~22 minecraft:sandstone 0
fill ~21~18~22 ~23~18~22 minecraft:sandstone 0
fill ~21~19~22 ~23~19~22 minecraft:wool 6
setblock ~24~3~22 minecraft:sandstone 0
setblock ~24~17~22 minecraft:sandstone 0
fill ~24~18~22 ~25~18~23 minecraft:wool 6
fill ~25~4~22 ~26~4~22 minecraft:sandstone 0
fill ~25~16~22 ~26~16~22 minecraft:sandstone 0
fill ~25~17~22 ~26~17~23 minecraft:wool 6
fill ~27~5~22 ~27~6~22 minecraft:sandstone 0
fill ~27~14~22 ~28~14~22 minecraft:sandstone 0
setblock ~27~15~22 minecraft:sandstone 0
fill ~27~16~22 ~28~16~22 minecraft:wool 6
fill ~28~6~22 ~28~7~22 minecraft:sandstone 0
fill ~28~13~22 ~29~13~22 minecraft:sandstone 0
fill ~28~15~22 ~30~15~22 minecraft:wool 6
fill ~29~7~22 ~29~12~22 minecraft:sandstone 0
fill ~29~14~22 ~37~14~22 minecraft:wool 6
fill ~30~8~22 ~30~12~22 minecraft:sandstone 0
fill ~30~13~22 ~36~13~22 minecraft:wool 6
fill ~31~9~22 ~31~11~22 minecraft:sandstone 0
fill ~31~12~22 ~35~12~23 minecraft:wool 6
setblock ~32~10~22 minecraft:sandstone 0
fill ~32~11~22 ~34~11~23 minecraft:wool 6
fill ~32~15~22 ~38~15~22 minecraft:wool 6
fill ~33~9~22 ~33~10~22 minecraft:wool 6
fill ~34~10~22 ~37~10~22 minecraft:sandstone 0
fill ~35~9~22 ~37~9~22 minecraft:sandstone 0
fill ~35~11~22 ~37~11~22 minecraft:sandstone 0
fill ~36~8~22 ~37~8~22 minecraft:sandstone 0
fill ~36~12~22 ~37~12~22 minecraft:sandstone 0
fill ~37~7~22 ~38~7~22 minecraft:sandstone 0
fill ~37~13~22 ~38~13~22 minecraft:sandstone 0
fill ~38~6~22 ~39~6~22 minecraft:sandstone 0
fill ~38~14~22 ~39~14~22 minecraft:sandstone 0
fill ~38~16~22 ~39~16~22 minecraft:wool 6
setblock ~39~5~22 minecraft:sandstone 0
setblock ~39~15~22 minecraft:sandstone 0
fill ~40~4~22 ~41~4~22 minecraft:sandstone 0
fill ~40~16~22 ~41~16~22 minecraft:sandstone 0
fill ~40~17~22 ~41~17~22 minecraft:wool 6
setblock ~42~3~22 minecraft:sandstone 0
setblock ~42~17~22 minecraft:sandstone 0
setblock ~42~18~22 minecraft:wool 6
fill ~43~2~22 ~45~2~22 minecraft:sandstone 0
fill ~43~18~22 ~45~18~22 minecraft:sandstone 0
fill ~43~19~22 ~45~19~22 minecraft:wool 6
fill ~45~0~22 ~45~0~42 minecraft:mycelium
fill ~47~21~22 ~47~21~23 minecraft:wool 5
fill ~54~0~22 ~54~0~42 minecraft:dirt 0
fill ~54~21~22 ~55~21~22 minecraft:wool 1
fill ~55~0~22 ~55~0~23 minecraft:stone 5
fill ~55~1~22 ~55~1~42 minecraft:sandstone 0
fill ~55~19~22 ~55~19~42 minecraft:sandstone 0
fill ~55~20~22 ~55~20~42 minecraft:wool 6
fill ~56~2~22 ~56~2~23 minecraft:sandstone 0
fill ~56~18~22 ~56~18~23 minecraft:sandstone 0
fill ~56~19~22 ~56~19~23 minecraft:wool 6
fill ~58~3~22 ~58~3~24 minecraft:sandstone 0
fill ~58~17~22 ~58~17~24 minecraft:sandstone 0
fill ~58~18~22 ~58~18~24 minecraft:wool 6
fill ~59~4~22 ~59~4~24 minecraft:sandstone 0
fill ~59~16~22 ~59~16~24 minecraft:sandstone 0
fill ~59~17~22 ~59~17~24 minecraft:wool 6
fill ~60~16~22 ~60~16~24 minecraft:wool 6
fill ~61~8~22 ~61~8~25 minecraft:sandstone 0
fill ~61~9~22 ~61~12~24 minecraft:sandstone 0
fill ~62~11~22 ~62~12~24 minecraft:wool 6
fill ~4~8~23 ~4~9~23 minecraft:wool 6
fill ~4~14~23 ~5~14~23 minecraft:wool 6
fill ~5~7~23 ~5~7~26 minecraft:sandstone 0
fill ~5~13~23 ~5~13~26 minecraft:sandstone 0
fill ~5~15~23 ~5~15~25 minecraft:wool 6
fill ~6~5~23 ~6~5~25 minecraft:sandstone 0
fill ~6~14~23 ~6~15~23 minecraft:sandstone 0
fill ~9~2~23 ~9~2~27 minecraft:sandstone 0
fill ~9~18~23 ~9~18~27 minecraft:sandstone 0
fill ~9~19~23 ~9~19~27 minecraft:wool 6
fill ~14~21~23 ~14~21~24 minecraft:wool 1
fill ~16~21~23 ~16~21~24 minecraft:wool 5
fill ~21~2~23 ~22~2~23 minecraft:sandstone 0
fill ~21~18~23 ~22~18~23 minecraft:sandstone 0
fill ~21~19~23 ~22~19~23 minecraft:wool 6
setblock ~23~3~23 minecraft:sandstone 0
setblock ~23~17~23 minecraft:sandstone 0
setblock ~23~18~23 minecraft:wool 6
fill ~24~4~23 ~25~4~23 minecraft:sandstone 0
fill ~24~16~23 ~25~16~23 minecraft:sandstone 0
fill ~24~17~23 ~24~17~24 minecraft:wool 6
fill ~25~5~23 ~26~5~23 minecraft:sandstone 0
fill ~25~15~23 ~26~15~23 minecraft:sandstone 0
setblock ~26~6~23 minecraft:sandstone 0
setblock ~26~14~23 minecraft:sandstone 0
setblock ~26~16~23 minecraft:wool 6
fill ~27~7~23 ~27~13~23 minecraft:sandstone 0
fill ~27~14~23 ~28~14~23 minecraft:wool 6
setblock ~27~15~23 minecraft:wool 6
fill ~28~8~23 ~28~12~23 minecraft:sandstone 0
fill ~28~13~23 ~30~13~23 minecraft:wool 6
fill ~29~9~23 ~29~12~23 minecraft:wool 6
fill ~30~10~23 ~32~10~23 minecraft:wool 6
fill ~30~11~23 ~31~11~23 minecraft:wool 6
setblock ~30~12~23 minecraft:wool 6
fill ~31~9~23 ~32~9~23 minecraft:wool 6
setblock ~32~8~23 minecraft:wool 6
fill ~33~13~23 ~38~13~23 minecraft:wool 6
fill ~36~10~23 ~36~12~23 minecraft:wool 6
fill ~37~11~23 ~37~12~23 minecraft:wool 6
fill ~38~8~23 ~39~12~23 minecraft:sandstone 0
fill ~38~14~23 ~39~14~23 minecraft:wool 6
setblock ~39~7~23 minecraft:sandstone 0
setblock ~39~13~23 minecraft:sandstone 0
fill ~39~15~23 ~39~15~24 minecraft:wool 6
fill ~40~5~23 ~41~5~23 minecraft:sandstone 0
setblock ~40~6~23 minecraft:sandstone 0
fill ~40~14~23 ~40~15~23 minecraft:sandstone 0
setblock ~40~16~23 minecraft:wool 6
fill ~41~4~23 ~42~4~23 minecraft:sandstone 0
fill ~41~15~23 ~41~16~23 minecraft:sandstone 0
fill ~41~17~23 ~42~17~23 minecraft:wool 6
fill ~42~16~23 ~42~16~24 minecraft:sandstone 0
setblock ~43~3~23 minecraft:sandstone 0
setblock ~43~17~23 minecraft:sandstone 0
setblock ~43~18~23 minecraft:wool 6
fill ~44~2~23 ~45~2~23 minecraft:sandstone 0
fill ~44~18~23 ~45~18~23 minecraft:sandstone 0
fill ~44~19~23 ~45~19~23 minecraft:wool 6
fill ~49~21~23 ~50~21~23 minecraft:wool 3
fill ~57~2~23 ~57~2~27 minecraft:sandstone 0
fill ~57~18~23 ~57~18~27 minecraft:sandstone 0
fill ~57~19~23 ~57~19~27 minecraft:wool 6
fill ~60~5~23 ~60~5~25 minecraft:sandstone 0
fill ~60~14~23 ~60~15~23 minecraft:sandstone 0
fill ~61~7~23 ~61~7~26 minecraft:sandstone 0
fill ~61~13~23 ~61~13~26 minecraft:sandstone 0
fill ~61~14~23 ~61~15~23 minecraft:wool 6
fill ~62~8~23 ~62~10~23 minecraft:wool 6
fill ~62~13~23 ~62~13~26 minecraft:wool 6
fill ~4~11~24 ~4~14~24 minecraft:wool 6
fill ~5~6~24 ~5~6~28 minecraft:sandstone 0
fill ~5~14~24 ~5~14~28 minecraft:sandstone 0
fill ~6~15~24 ~6~15~25 minecraft:sandstone 0
fill ~10~0~24 ~10~0~27 minecraft:stone 5
fill ~10~1~24 ~10~1~40 minecraft:sandstone 0
fill ~10~19~24 ~10~19~40 minecraft:sandstone 0
fill ~10~20~24 ~10~20~40 minecraft:wool 6
fill ~11~0~24 ~11~0~40 minecraft:dirt 0
fill ~11~21~24 ~11~21~25 minecraft:wool 10
fill ~18~21~24 ~18~21~25 minecraft:wool 2
fill ~20~0~24 ~20~0~40 minecraft:mycelium
fill ~20~2~24 ~21~2~24 minecraft:sandstone 0
fill ~20~18~24 ~21~18~24 minecraft:sandstone 0
fill ~20~19~24 ~21~19~24 minecraft:wool 6
fill ~22~3~24 ~22~3~25 minecraft:sandstone 0
fill ~22~17~24 ~22~17~25 minecraft:sandstone 0
fill ~22~18~24 ~22~18~25 minecraft:wool 6
fill ~23~4~24 ~24~4~24 minecraft:sandstone 0
fill ~23~16~24 ~24~16~24 minecraft:sandstone 0
fill ~23~17~24 ~23~17~25 minecraft:wool 6
fill ~24~5~24 ~24~5~25 minecraft:sandstone 0
fill ~24~15~24 ~24~15~25 minecraft:sandstone 0
setblock ~25~6~24 minecraft:sandstone 0
setblock ~25~14~24 minecraft:sandstone 0
fill ~25~15~24 ~26~15~24 minecraft:wool 6
setblock ~25~16~24 minecraft:wool 6
fill ~26~7~24 ~26~13~24 minecraft:sandstone 0
fill ~26~14~24 ~27~14~24 minecraft:wool 6
fill ~27~9~24 ~27~13~24 minecraft:wool 6
fill ~28~11~24 ~28~13~24 minecraft:wool 6
fill ~38~12~24 ~39~13~24 minecraft:wool 6
fill ~39~9~24 ~39~11~24 minecraft:wool 6
fill ~39~14~24 ~40~14~24 minecraft:wool 6
fill ~40~7~24 ~40~13~24 minecraft:sandstone 0
fill ~40~15~24 ~41~15~24 minecraft:wool 6
setblock ~41~6~24 minecraft:sandstone 0
setblock ~41~14~24 minecraft:sandstone 0
setblock ~41~16~24 minecraft:wool 6
fill ~42~4~24 ~43~4~24 minecraft:sandstone 0
fill ~42~5~24 ~42~5~25 minecraft:sandstone 0
fill ~42~15~24 ~42~15~25 minecraft:sandstone 0
fill ~42~17~24 ~43~17~24 minecraft:wool 6
fill ~43~16~24 ~43~16~25 minecraft:sandstone 0
fill ~44~3~24 ~44~3~25 minecraft:sandstone 0
fill ~44~17~24 ~44~17~25 minecraft:sandstone 0
fill ~44~18~24 ~44~18~25 minecraft:wool 6
fill ~45~2~24 ~46~2~24 minecraft:sandstone 0
fill ~45~18~24 ~46~18~24 minecraft:sandstone 0
fill ~45~19~24 ~46~19~24 minecraft:wool 6
fill ~46~0~24 ~46~0~40 minecraft:mycelium
fill ~52~21~24 ~53~21~24 minecraft:wool 5
fill ~55~0~24 ~55~0~40 minecraft:dirt 0
fill ~55~21~24 ~55~21~25 minecraft:wool 9
fill ~56~0~24 ~56~0~27 minecraft:stone 5
fill ~56~1~24 ~56~1~40 minecraft:sandstone 0
fill ~56~19~24 ~56~19~40 minecraft:sandstone 0
fill ~56~20~24 ~56~20~40 minecraft:wool 6
fill ~60~15~24 ~60~15~25 minecraft:sandstone 0
fill ~61~6~24 ~61~6~28 minecraft:sandstone 0
fill ~61~14~24 ~61~14~28 minecraft:sandstone 0
fill ~61~15~24 ~61~15~25 minecraft:wool 6
fill ~62~9~24 ~62~10~24 minecraft:wool 6
fill ~62~14~24 ~62~14~28 minecraft:wool 6
fill ~3~11~25 ~3~11~28 minecraft:wool 6
fill ~4~9~25 ~4~11~39 minecraft:sandstone 0
fill ~4~12~25 ~4~15~25 minecraft:wool 6
setblock ~5~12~25 minecraft:sandstone 0
fill ~5~16~25 ~5~16~39 minecraft:wool 6
fill ~6~4~25 ~6~4~39 minecraft:sandstone 0
fill ~6~16~25 ~6~16~39 minecraft:sandstone 0
fill ~6~17~25 ~6~17~29 minecraft:wool 6
fill ~7~3~25 ~7~3~39 minecraft:sandstone 0
fill ~7~17~25 ~7~17~39 minecraft:sandstone 0
fill ~7~18~25 ~7~18~39 minecraft:wool 6
fill ~8~2~25 ~8~2~39 minecraft:sandstone 0
fill ~8~18~25 ~8~18~39 minecraft:sandstone 0
fill ~8~19~25 ~8~19~39 minecraft:wool 6
fill ~20~2~25 ~20~2~26 minecraft:sandstone 0
fill ~20~18~25 ~20~18~26 minecraft:sandstone 0
fill ~20~19~25 ~20~19~26 minecraft:wool 6
fill ~21~3~25 ~21~3~27 minecraft:sandstone 0
fill ~21~17~25 ~21~17~27 minecraft:sandstone 0
fill ~21~18~25 ~21~18~27 minecraft:wool 6
setblock ~23~4~25 minecraft:sandstone 0
setblock ~23~16~25 minecraft:sandstone 0
setblock ~24~6~25 minecraft:sandstone 0
setblock ~24~14~25 minecraft:sandstone 0
setblock ~24~16~25 minecraft:wool 6
fill ~25~7~25 ~25~13~25 minecraft:sandstone 0
fill ~25~14~25 ~25~15~25 minecraft:wool 6
fill ~26~10~25 ~26~13~25 minecraft:wool 6
fill ~40~10~25 ~40~13~25 minecraft:wool 6
fill ~41~7~25 ~41~13~25 minecraft:sandstone 0
fill ~41~14~25 ~41~15~25 minecraft:wool 6
setblock ~42~6~25 minecraft:sandstone 0
setblock ~42~14~25 minecraft:sandstone 0
setblock ~42~16~25 minecraft:wool 6
setblock ~43~4~25 minecraft:sandstone 0
setblock ~43~17~25 minecraft:wool 6
fill ~45~3~25 ~45~3~27 minecraft:sandstone 0
fill ~45~17~25 ~45~17~27 minecraft:sandstone 0
fill ~45~18~25 ~45~18~27 minecraft:wool 6
fill ~46~2~25 ~46~2~26 minecraft:sandstone 0
fill ~46~18~25 ~46~18~26 minecraft:sandstone 0
fill ~46~19~25 ~46~19~26 minecraft:wool 6
fill ~48~21~25 ~49~21~25 minecraft:wool 2
fill ~58~2~25 ~58~2~39 minecraft:sandstone 0
fill ~58~18~25 ~58~18~39 minecraft:sandstone 0
fill ~58~19~25 ~58~19~39 minecraft:wool 6
fill ~59~3~25 ~59~3~39 minecraft:sandstone 0
fill ~59~17~25 ~59~17~39 minecraft:sandstone 0
fill ~59~18~25 ~59~18~39 minecraft:wool 6
fill ~60~4~25 ~60~4~39 minecraft:sandstone 0
fill ~60~16~25 ~60~16~39 minecraft:sandstone 0
fill ~60~17~25 ~60~17~29 minecraft:wool 6
setblock ~61~12~25 minecraft:sandstone 0
fill ~61~16~25 ~61~16~39 minecraft:wool 6
fill ~62~9~25 ~62~11~39 minecraft:sandstone 0
setblock ~62~12~25 minecraft:wool 6
fill ~63~7~25 ~63~11~25 minecraft:wool 6
fill ~3~12~26 ~3~12~29 minecraft:wool 6
fill ~4~8~26 ~4~8~38 minecraft:sandstone 0
fill ~4~12~26 ~4~12~38 minecraft:sandstone 0
fill ~4~13~26 ~4~15~26 minecraft:wool 6
fill ~5~5~26 ~5~5~38 minecraft:sandstone 0
fill ~5~15~26 ~5~15~38 minecraft:sandstone 0
fill ~13~21~26 ~13~21~27 minecraft:wool 14
fill ~15~21~26 ~16~21~26 minecraft:wool 9
fill ~18~0~26 ~18~0~27 minecraft:dirt 0
fill ~18~1~26 ~18~1~27 minecraft:sandstone 0
fill ~18~19~26 ~18~19~27 minecraft:sandstone 0
fill ~18~20~26 ~18~20~27 minecraft:wool 6
fill ~19~0~26 ~19~0~38 minecraft:mycelium
fill ~19~2~26 ~19~2~31 minecraft:sandstone 0
fill ~19~18~26 ~19~18~31 minecraft:sandstone 0
fill ~19~19~26 ~19~19~31 minecraft:wool 6
fill ~22~4~26 ~22~4~27 minecraft:sandstone 0
fill ~22~16~26 ~22~16~27 minecraft:sandstone 0
fill ~22~17~26 ~22~17~27 minecraft:wool 6
fill ~23~5~26 ~23~6~26 minecraft:sandstone 0
fill ~23~14~26 ~23~14~27 minecraft:sandstone 0
setblock ~23~15~26 minecraft:sandstone 0
fill ~23~16~26 ~23~16~27 minecraft:wool 6
fill ~24~7~26 ~24~13~26 minecraft:sandstone 0
fill ~24~14~26 ~24~14~28 minecraft:wool 6
setblock ~24~15~26 minecraft:wool 6
fill ~25~9~26 ~25~13~26 minecraft:wool 6
fill ~41~7~26 ~41~13~26 minecraft:wool 6
fill ~42~7~26 ~42~13~26 minecraft:sandstone 0
fill ~42~14~26 ~42~14~27 minecraft:wool 6
setblock ~42~15~26 minecraft:wool 6
fill ~43~5~26 ~43~6~26 minecraft:sandstone 0
fill ~43~14~26 ~43~14~27 minecraft:sandstone 0
setblock ~43~15~26 minecraft:sandstone 0
fill ~43~16~26 ~43~16~27 minecraft:wool 6
fill ~44~4~26 ~44~4~27 minecraft:sandstone 0
fill ~44~16~26 ~44~16~27 minecraft:sandstone 0
fill ~44~17~26 ~44~17~27 minecraft:wool 6
fill ~47~0~26 ~47~0~38 minecraft:mycelium
fill ~47~2~26 ~47~2~31 minecraft:sandstone 0
fill ~47~18~26 ~47~18~31 minecraft:sandstone 0
fill ~47~19~26 ~47~19~31 minecraft:wool 6
fill ~48~0~26 ~48~0~27 minecraft:dirt 0
fill ~48~1~26 ~48~1~27 minecraft:sandstone 0
fill ~48~19~26 ~48~19~27 minecraft:sandstone 0
fill ~48~20~26 ~48~20~27 minecraft:wool 6
fill ~53~21~26 ~53~21~27 minecraft:wool 14
fill ~61~5~26 ~61~5~38 minecraft:sandstone 0
fill ~61~15~26 ~61~15~38 minecraft:sandstone 0
fill ~62~8~26 ~62~8~38 minecraft:sandstone 0
fill ~62~12~26 ~62~12~38 minecraft:sandstone 0
fill ~62~15~26 ~62~15~39 minecraft:wool 6
fill ~63~9~26 ~63~13~26 minecraft:wool 6
fill ~3~13~27 ~3~13~39 minecraft:wool 6
fill ~4~7~27 ~4~7~37 minecraft:sandstone 0
fill ~4~13~27 ~4~13~37 minecraft:sandstone 0
fill ~4~14~27 ~4~15~28 minecraft:wool 6
fill ~10~21~27 ~11~21~27 minecraft:wool 13
setblock ~18~2~27 minecraft:sea_lantern
fill ~20~3~27 ~20~3~37 minecraft:sandstone 0
fill ~20~17~27 ~20~17~37 minecraft:sandstone 0
fill ~20~18~27 ~20~18~37 minecraft:wool 6
fill ~22~5~27 ~22~5~29 minecraft:sandstone 0
fill ~22~15~27 ~22~15~29 minecraft:sandstone 0
fill ~23~6~27 ~23~7~27 minecraft:sandstone 0
fill ~23~13~27 ~23~13~28 minecraft:sandstone 0
fill ~23~15~27 ~23~15~29 minecraft:wool 6
fill ~24~8~27 ~24~12~27 minecraft:sandstone 0
fill ~24~13~27 ~24~13~34 minecraft:wool 6
fill ~25~10~27 ~25~12~27 minecraft:wool 6
fill ~41~10~27 ~41~12~27 minecraft:wool 6
fill ~42~8~27 ~42~12~27 minecraft:sandstone 0
fill ~42~13~27 ~42~13~37 minecraft:wool 6
fill ~43~6~27 ~43~7~27 minecraft:sandstone 0
fill ~43~13~27 ~43~13~28 minecraft:sandstone 0
fill ~43~15~27 ~43~15~29 minecraft:wool 6
fill ~44~5~27 ~44~5~29 minecraft:sandstone 0
fill ~44~15~27 ~44~15~29 minecraft:sandstone 0
fill ~46~3~27 ~46~3~37 minecraft:sandstone 0
fill ~46~17~27 ~46~17~37 minecraft:sandstone 0
fill ~46~18~27 ~46~18~37 minecraft:wool 6
setblock ~48~2~27 minecraft:sea_lantern
fill ~50~21~27 ~51~21~27 minecraft:wool 11
fill ~55~21~27 ~56~21~27 minecraft:wool 13
fill ~62~7~27 ~62~7~37 minecraft:sandstone 0
fill ~62~13~27 ~62~13~37 minecraft:sandstone 0
fill ~63~13~27 ~63~13~39 minecraft:wool 6
fill ~63~14~27 ~63~14~36 minecraft:wool 6
fill ~3~9~28 ~3~10~28 minecraft:wool 6
fill ~9~0~28 ~9~0~36 minecraft:stone 5
fill ~9~1~28 ~9~1~36 minecraft:sandstone 0
fill ~9~19~28 ~9~19~36 minecraft:sandstone 0
fill ~9~20~28 ~9~20~36 minecraft:wool 6
fill ~10~0~28 ~10~0~36 minecraft:dirt 0
fill ~15~21~28 ~15~21~29 minecraft:wool 4
fill ~17~21~28 ~17~21~29 minecraft:wool 13
fill ~18~0~28 ~18~0~36 minecraft:mycelium
fill ~18~2~28 ~18~2~36 minecraft:sandstone 0
fill ~18~18~28 ~18~18~36 minecraft:sandstone 0
fill ~18~19~28 ~18~19~36 minecraft:wool 6
fill ~21~4~28 ~21~4~31 minecraft:sandstone 0
fill ~21~16~28 ~21~16~31 minecraft:sandstone 0
fill ~21~17~28 ~21~17~36 minecraft:wool 6
fill ~22~6~28 ~22~6~36 minecraft:sandstone 0
fill ~22~14~28 ~22~14~36 minecraft:sandstone 0
fill ~22~16~28 ~22~16~31 minecraft:wool 6
fill ~23~7~28 ~23~12~28 minecraft:sandstone 0
fill ~23~14~28 ~23~14~36 minecraft:wool 6
fill ~24~9~28 ~24~12~28 minecraft:wool 6
fill ~42~11~28 ~42~12~30 minecraft:wool 6
fill ~43~7~28 ~43~12~28 minecraft:sandstone 0
fill ~43~14~28 ~43~14~36 minecraft:wool 6
fill ~44~6~28 ~44~6~36 minecraft:sandstone 0
fill ~44~14~28 ~44~14~36 minecraft:sandstone 0
fill ~44~16~28 ~44~16~31 minecraft:wool 6
fill ~45~4~28 ~45~4~31 minecraft:sandstone 0
fill ~45~16~28 ~45~16~31 minecraft:sandstone 0
fill ~45~17~28 ~45~17~36 minecraft:wool 6
fill ~48~0~28 ~48~0~36 minecraft:mycelium
fill ~48~2~28 ~48~2~36 minecraft:sandstone 0
fill ~48~18~28 ~48~18~36 minecraft:sandstone 0
fill ~48~19~28 ~48~19~36 minecraft:wool 6
fill ~56~0~28 ~56~0~36 minecraft:dirt 0
fill ~57~0~28 ~57~0~36 minecraft:stone 5
fill ~57~1~28 ~57~1~36 minecraft:sandstone 0
fill ~57~19~28 ~57~19~36 minecraft:sandstone 0
fill ~57~20~28 ~57~20~36 minecraft:wool 6
fill ~62~16~28 ~62~16~29 minecraft:wool 6
fill ~63~12~28 ~63~12~32 minecraft:wool 6
fill ~3~14~29 ~3~14~35 minecraft:wool 6
fill ~4~6~29 ~4~6~35 minecraft:sandstone 0
fill ~4~14~29 ~4~14~35 minecraft:sandstone 0
fill ~4~15~29 ~4~15~39 minecraft:wool 6
fill ~12~21~29 ~13~21~29 minecraft:wool 11
fill ~22~7~29 ~22~7~35 minecraft:sandstone 0
fill ~22~13~29 ~22~13~35 minecraft:sandstone 0
fill ~23~8~29 ~23~12~29 minecraft:sandstone 0
fill ~23~13~29 ~23~13~35 minecraft:wool 6
fill ~24~11~29 ~24~12~36 minecraft:wool 6
fill ~42~9~29 ~42~10~29 minecraft:wool 6
fill ~43~8~29 ~43~12~29 minecraft:sandstone 0
fill ~43~13~29 ~43~13~35 minecraft:wool 6
fill ~44~7~29 ~44~7~35 minecraft:sandstone 0
fill ~44~13~29 ~44~13~35 minecraft:sandstone 0
fill ~49~21~29 ~50~21~29 minecraft:wool 1
fill ~52~21~29 ~52~21~30 minecraft:wool 4
fill ~54~21~29 ~55~21~29 minecraft:wool 10
fill ~57~21~29 ~57~21~30 minecraft:wool 3
fill ~62~6~29 ~62~6~35 minecraft:sandstone 0
fill ~62~14~29 ~62~14~35 minecraft:sandstone 0
fill ~63~8~29 ~63~11~29 minecraft:wool 6
fill ~5~17~30 ~5~17~34 minecraft:wool 6
fill ~6~17~30 ~6~17~34 minecraft:sandstone 0
fill ~6~18~30 ~6~18~34 minecraft:wool 6
fill ~10~21~30 ~10~21~31 minecraft:wool 5
fill ~21~5~30 ~21~5~34 minecraft:sandstone 0
fill ~21~15~30 ~21~15~34 minecraft:sandstone 0
fill ~22~8~30 ~22~8~34 minecraft:sandstone 0
fill ~22~12~30 ~22~12~34 minecraft:sandstone 0
fill ~22~15~30 ~22~15~34 minecraft:wool 6
fill ~23~9~30 ~23~11~30 minecraft:sandstone 0
fill ~23~12~30 ~23~12~34 minecraft:wool 6
setblock ~24~10~30 minecraft:wool 6
setblock ~42~10~30 minecraft:wool 6
setblock ~42~14~30 minecraft:wool 6
fill ~43~9~30 ~43~11~30 minecraft:sandstone 0
fill ~43~12~30 ~43~12~34 minecraft:wool 6
fill ~44~8~30 ~44~8~34 minecraft:sandstone 0
fill ~44~12~30 ~44~12~34 minecraft:sandstone 0
fill ~44~15~30 ~44~15~34 minecraft:wool 6
fill ~45~5~30 ~45~5~34 minecraft:sandstone 0
fill ~45~15~30 ~45~15~34 minecraft:sandstone 0
fill ~60~17~30 ~60~17~34 minecraft:sandstone 0
fill ~60~18~30 ~60~18~34 minecraft:wool 6
fill ~61~17~30 ~61~17~34 minecraft:wool 6
fill ~3~10~31 ~3~12~31 minecraft:wool 6
fill ~12~21~31 ~12~21~32 minecraft:wool 2
fill ~14~21~31 ~14~21~32 minecraft:wool 9
fill ~16~21~31 ~17~21~31 minecraft:wool 1
fill ~22~9~31 ~22~9~33 minecraft:sandstone 0
fill ~22~11~31 ~22~11~33 minecraft:sandstone 0
setblock ~23~10~31 minecraft:sandstone 0
fill ~23~11~31 ~23~11~33 minecraft:wool 6
fill ~42~12~31 ~42~12~36 minecraft:wool 6
setblock ~43~10~31 minecraft:sandstone 0
fill ~43~11~31 ~43~11~33 minecraft:wool 6
fill ~44~9~31 ~44~9~33 minecraft:sandstone 0
fill ~44~11~31 ~44~11~33 minecraft:sandstone 0
fill ~54~21~31 ~55~21~31 minecraft:wool 9
fill ~3~12~32 ~3~12~33 minecraft:wool 6
setblock ~19~3~32 minecraft:sandstone 0
setblock ~19~17~32 minecraft:sandstone 0
setblock ~19~18~32 minecraft:wool 6
setblock ~20~4~32 minecraft:sandstone 0
setblock ~20~16~32 minecraft:sandstone 0
setblock ~21~16~32 minecraft:wool 6
setblock ~22~10~32 minecraft:sea_lantern
fill ~23~10~32 ~24~10~32 minecraft:wool 6
fill ~24~8~32 ~24~9~32 minecraft:wool 6
setblock ~42~6~32 minecraft:wool 6
fill ~42~9~32 ~42~11~32 minecraft:wool 6
setblock ~43~10~32 minecraft:wool 6
setblock ~44~10~32 minecraft:sea_lantern
setblock ~45~16~32 minecraft:wool 6
setblock ~46~4~32 minecraft:sandstone 0
setblock ~46~16~32 minecraft:sandstone 0
setblock ~47~3~32 minecraft:sandstone 0
setblock ~47~17~32 minecraft:sandstone 0
setblock ~47~18~32 minecraft:wool 6
fill ~50~21~32 ~50~21~33 minecraft:wool 13
fill ~63~10~32 ~63~11~32 minecraft:wool 6
fill ~3~7~33 ~3~11~33 minecraft:wool 6
fill ~16~21~33 ~16~21~34 minecraft:wool 3
fill ~19~2~33 ~19~2~38 minecraft:sandstone 0
fill ~19~18~33 ~19~18~38 minecraft:sandstone 0
fill ~19~19~33 ~19~19~38 minecraft:wool 6
fill ~21~4~33 ~21~4~36 minecraft:sandstone 0
fill ~21~16~33 ~21~16~36 minecraft:sandstone 0
fill ~22~16~33 ~22~16~36 minecraft:wool 6
fill ~23~10~33 ~23~10~36 minecraft:sandstone 0
fill ~24~9~33 ~24~10~33 minecraft:wool 6
fill ~42~11~33 ~42~11~34 minecraft:wool 6
fill ~43~10~33 ~43~10~36 minecraft:sandstone 0
fill ~44~16~33 ~44~16~36 minecraft:wool 6
fill ~45~4~33 ~45~4~36 minecraft:sandstone 0
fill ~45~16~33 ~45~16~36 minecraft:sandstone 0
fill ~47~2~33 ~47~2~38 minecraft:sandstone 0
fill ~47~18~33 ~47~18~38 minecraft:sandstone 0
fill ~47~19~33 ~47~19~38 minecraft:wool 6
fill ~53~21~33 ~54~21~33 minecraft:wool 2
fill ~56~21~33 ~56~21~34 minecraft:wool 5
fill ~63~15~33 ~63~15~35 minecraft:wool 6
fill ~9~21~34 ~10~21~34 minecraft:wool 14
fill ~13~21~34 ~14~21~34 minecraft:wool 13
fill ~23~9~34 ~23~9~36 minecraft:sandstone 0
fill ~23~11~34 ~23~11~36 minecraft:sandstone 0
setblock ~42~10~34 minecraft:wool 6
fill ~43~9~34 ~43~9~36 minecraft:sandstone 0
fill ~43~11~34 ~43~11~36 minecraft:sandstone 0
setblock ~63~4~34 minecraft:wool 6
fill ~63~7~34 ~63~12~34 minecraft:wool 6
fill ~3~12~35 ~3~12~36 minecraft:wool 6
fill ~6~17~35 ~6~17~39 minecraft:wool 6
fill ~22~5~35 ~22~5~37 minecraft:sandstone 0
fill ~22~15~35 ~22~15~37 minecraft:sandstone 0
fill ~23~8~35 ~23~8~36 minecraft:sandstone 0
fill ~23~12~35 ~23~12~36 minecraft:sandstone 0
fill ~23~15~35 ~23~15~37 minecraft:wool 6
fill ~24~9~35 ~24~10~35 minecraft:wool 6
fill ~43~8~35 ~43~8~36 minecraft:sandstone 0
fill ~43~12~35 ~43~12~36 minecraft:sandstone 0
fill ~43~15~35 ~43~15~37 minecraft:wool 6
fill ~44~5~35 ~44~5~37 minecraft:sandstone 0
fill ~44~15~35 ~44~15~37 minecraft:sandstone 0
fill ~49~21~35 ~50~21~35 minecraft:wool 3
fill ~52~21~35 ~52~21~36 minecraft:wool 14
fill ~60~17~35 ~60~17~39 minecraft:wool 6
fill ~3~10~36 ~3~11~36 minecraft:wool 6
fill ~4~14~36 ~4~14~40 minecraft:wool 6
fill ~5~6~36 ~5~6~40 minecraft:sandstone 0
fill ~5~14~36 ~5~14~40 minecraft:sandstone 0
fill ~10~21~36 ~10~21~37 minecraft:wool 11
fill ~13~21~36 ~13~21~37 minecraft:wool 4
fill ~16~21~36 ~17~21~36 minecraft:wool 10
fill ~23~7~36 ~23~7~37 minecraft:sandstone 0
fill ~23~13~36 ~23~13~37 minecraft:sandstone 0
fill ~23~16~36 ~23~16~38 minecraft:wool 6
fill ~24~13~36 ~24~13~37 minecraft:wool 6
fill ~42~9~36 ~42~11~36 minecraft:wool 6
fill ~43~7~36 ~43~7~37 minecraft:sandstone 0
fill ~43~13~36 ~43~13~37 minecraft:sandstone 0
fill ~54~21~36 ~55~21~36 minecraft:wool 11
fill ~61~6~36 ~61~6~40 minecraft:sandstone 0
fill ~61~14~36 ~61~14~40 minecraft:sandstone 0
fill ~62~14~36 ~62~14~40 minecraft:wool 6
fill ~3~14~37 ~3~14~38 minecraft:wool 6
fill ~9~2~37 ~9~2~41 minecraft:sandstone 0
fill ~9~18~37 ~9~18~41 minecraft:sandstone 0
fill ~9~19~37 ~9~19~41 minecraft:wool 6
fill ~10~0~37 ~10~0~40 minecraft:stone 5
fill ~18~0~37 ~18~0~50 minecraft:dirt 0
fill ~18~1~37 ~18~1~51 minecraft:sandstone 0
setblock ~18~2~37 minecraft:sea_lantern
fill ~18~19~37 ~18~19~51 minecraft:sandstone 0
fill ~18~20~37 ~18~20~51 minecraft:wool 6
fill ~21~3~37 ~21~3~39 minecraft:sandstone 0
fill ~21~17~37 ~21~17~39 minecraft:sandstone 0
fill ~21~18~37 ~21~18~39 minecraft:wool 6
fill ~22~4~37 ~22~4~38 minecraft:sandstone 0
fill ~22~16~37 ~22~16~38 minecraft:sandstone 0
fill ~22~17~37 ~22~17~38 minecraft:wool 6
fill ~23~6~37 ~23~6~38 minecraft:sandstone 0
fill ~23~14~37 ~23~14~38 minecraft:sandstone 0
fill ~24~8~37 ~24~12~38 minecraft:sandstone 0
fill ~24~14~37 ~24~14~38 minecraft:wool 6
fill ~25~9~37 ~25~12~37 minecraft:wool 6
fill ~41~10~37 ~41~12~38 minecraft:wool 6
fill ~42~8~37 ~42~12~38 minecraft:sandstone 0
fill ~42~14~37 ~42~14~38 minecraft:wool 6
fill ~43~6~37 ~43~6~38 minecraft:sandstone 0
fill ~43~14~37 ~43~14~38 minecraft:sandstone 0
fill ~43~16~37 ~43~16~38 minecraft:wool 6
fill ~44~4~37 ~44~4~38 minecraft:sandstone 0
fill ~44~16~37 ~44~16~38 minecraft:sandstone 0
fill ~44~17~37 ~44~17~38 minecraft:wool 6
fill ~45~3~37 ~45~3~39 minecraft:sandstone 0
fill ~45~17~37 ~45~17~39 minecraft:sandstone 0
fill ~45~18~37 ~45~18~39 minecraft:wool 6
fill ~48~0~37 ~48~0~50 minecraft:dirt 0
fill ~48~1~37 ~48~1~51 minecraft:sandstone 0
setblock ~48~2~37 minecraft:sea_lantern
fill ~48~19~37 ~48~19~51 minecraft:sandstone 0
fill ~48~20~37 ~48~20~51 minecraft:wool 6
fill ~49~21~37 ~49~21~38 minecraft:wool 1
fill ~56~0~37 ~56~0~40 minecraft:stone 5
fill ~57~2~37 ~57~2~41 minecraft:sandstone 0
fill ~57~18~37 ~57~18~41 minecraft:sandstone 0
fill ~57~19~37 ~57~19~41 minecraft:wool 6
fill ~63~9~37 ~63~12~37 minecraft:wool 6
fill ~3~11~38 ~3~12~39 minecraft:wool 6
fill ~4~13~38 ~4~13~41 minecraft:wool 6
fill ~5~7~38 ~5~7~41 minecraft:sandstone 0
fill ~5~13~38 ~5~13~41 minecraft:sandstone 0
fill ~16~21~38 ~16~21~39 minecraft:wool 5
fill ~20~2~38 ~20~2~40 minecraft:sandstone 0
fill ~20~18~38 ~20~18~40 minecraft:sandstone 0
fill ~20~19~38 ~20~19~40 minecraft:wool 6
setblock ~23~5~38 minecraft:sandstone 0
setblock ~23~15~38 minecraft:sandstone 0
setblock ~24~7~38 minecraft:sandstone 0
setblock ~24~13~38 minecraft:sandstone 0
setblock ~24~15~38 minecraft:wool 6
fill ~25~10~38 ~25~13~38 minecraft:wool 6
setblock ~41~9~38 minecraft:wool 6
setblock ~41~13~38 minecraft:wool 6
setblock ~42~7~38 minecraft:sandstone 0
setblock ~42~13~38 minecraft:sandstone 0
setblock ~42~15~38 minecraft:wool 6
setblock ~43~5~38 minecraft:sandstone 0
setblock ~43~15~38 minecraft:sandstone 0
fill ~46~2~38 ~46~2~40 minecraft:sandstone 0
fill ~46~18~38 ~46~18~40 minecraft:sandstone 0
fill ~46~19~38 ~46~19~40 minecraft:wool 6
fill ~51~21~38 ~52~21~38 minecraft:wool 13
fill ~55~21~38 ~56~21~38 minecraft:wool 4
fill ~61~7~38 ~61~7~41 minecraft:sandstone 0
fill ~61~13~38 ~61~13~41 minecraft:sandstone 0
fill ~62~13~38 ~62~13~41 minecraft:wool 6
fill ~63~12~38 ~63~12~39 minecraft:wool 6
setblock ~3~10~39 minecraft:wool 6
fill ~4~12~39 ~4~12~42 minecraft:wool 6
fill ~5~8~39 ~5~8~42 minecraft:sandstone 0
fill ~5~12~39 ~5~12~42 minecraft:sandstone 0
fill ~5~15~39 ~5~15~41 minecraft:wool 6
fill ~6~5~39 ~6~5~41 minecraft:sandstone 0
fill ~6~15~39 ~6~15~41 minecraft:sandstone 0
fill ~11~21~39 ~12~21~39 minecraft:wool 9
fill ~19~0~39 ~19~0~50 minecraft:dirt 0
fill ~19~1~39 ~19~1~51 minecraft:sandstone 0
fill ~19~19~39 ~19~19~51 minecraft:sandstone 0
fill ~19~20~39 ~19~20~51 minecraft:wool 6
fill ~22~3~39 ~22~3~40 minecraft:sandstone 0
fill ~22~17~39 ~22~17~40 minecraft:sandstone 0
fill ~22~18~39 ~22~18~40 minecraft:wool 6
fill ~23~4~39 ~23~4~40 minecraft:sandstone 0
fill ~23~16~39 ~23~16~40 minecraft:sandstone 0
fill ~23~17~39 ~23~17~40 minecraft:wool 6
fill ~24~5~39 ~24~5~40 minecraft:sandstone 0
setblock ~24~6~39 minecraft:sandstone 0
fill ~24~14~39 ~24~15~39 minecraft:sandstone 0
setblock ~24~16~39 minecraft:wool 6
fill ~25~7~39 ~25~13~39 minecraft:sandstone 0
fill ~25~14~39 ~25~15~39 minecraft:wool 6
fill ~26~11~39 ~26~13~39 minecraft:wool 6
fill ~40~10~39 ~40~13~39 minecraft:wool 6
fill ~41~7~39 ~41~13~39 minecraft:sandstone 0
fill ~41~14~39 ~41~15~39 minecraft:wool 6
fill ~42~5~39 ~42~5~40 minecraft:sandstone 0
setblock ~42~6~39 minecraft:sandstone 0
fill ~42~14~39 ~42~15~39 minecraft:sandstone 0
setblock ~42~16~39 minecraft:wool 6
fill ~43~4~39 ~43~4~40 minecraft:sandstone 0
fill ~43~16~39 ~43~16~40 minecraft:sandstone 0
fill ~43~17~39 ~43~17~40 minecraft:wool 6
fill ~44~3~39 ~44~3~40 minecraft:sandstone 0
fill ~44~17~39 ~44~17~40 minecraft:sandstone 0
fill ~44~18~39 ~44~18~40 minecraft:wool 6
fill ~47~0~39 ~47~0~50 minecraft:dirt 0
fill ~47~1~39 ~47~1~51 minecraft:sandstone 0
fill ~47~19~39 ~47~19~51 minecraft:sandstone 0
fill ~47~20~39 ~47~20~51 minecraft:wool 6
fill ~60~5~39 ~60~5~41 minecraft:sandstone 0
fill ~60~15~39 ~60~15~41 minecraft:sandstone 0
fill ~61~8~39 ~61~8~42 minecraft:sandstone 0
fill ~61~12~39 ~61~12~42 minecraft:sandstone 0
fill ~61~15~39 ~61~15~41 minecraft:wool 6
fill ~62~12~39 ~62~12~42 minecraft:wool 6
setblock ~63~11~39 minecraft:wool 6
setblock ~63~14~39 minecraft:wool 6
setblock ~3~12~40 minecraft:wool 6
fill ~4~9~40 ~4~11~40 minecraft:wool 6
fill ~5~9~40 ~5~11~42 minecraft:sandstone 0
fill ~6~16~40 ~6~16~42 minecraft:wool 6
fill ~7~4~40 ~7~4~42 minecraft:sandstone 0
fill ~7~16~40 ~7~16~42 minecraft:sandstone 0
fill ~7~17~40 ~7~17~42 minecraft:wool 6
fill ~8~3~40 ~8~3~42 minecraft:sandstone 0
fill ~8~17~40 ~8~17~42 minecraft:sandstone 0
fill ~8~18~40 ~8~18~42 minecraft:wool 6
fill ~14~21~40 ~14~21~41 minecraft:wool 2
fill ~18~21~40 ~19~21~40 minecraft:wool 14
fill ~21~2~40 ~21~2~42 minecraft:sandstone 0
fill ~21~18~40 ~21~18~42 minecraft:sandstone 0
fill ~21~19~40 ~21~19~42 minecraft:wool 6
fill ~24~4~40 ~24~4~41 minecraft:sandstone 0
fill ~24~15~40 ~24~16~40 minecraft:sandstone 0
fill ~24~17~40 ~24~17~41 minecraft:wool 6
setblock ~25~6~40 minecraft:sandstone 0
setblock ~25~14~40 minecraft:sandstone 0
fill ~25~15~40 ~26~15~40 minecraft:wool 6
setblock ~25~16~40 minecraft:wool 6
fill ~26~7~40 ~26~13~40 minecraft:sandstone 0
fill ~26~14~40 ~27~14~40 minecraft:wool 6
fill ~27~9~40 ~27~13~40 minecraft:wool 6
fill ~28~11~40 ~28~12~40 minecraft:wool 6
fill ~38~10~40 ~39~12~40 minecraft:wool 6
setblock ~39~3~40 minecraft:wool 6
fill ~39~8~40 ~39~9~40 minecraft:wool 6
fill ~39~13~40 ~39~14~40 minecraft:wool 6
fill ~40~7~40 ~40~13~40 minecraft:sandstone 0
fill ~40~14~40 ~40~15~40 minecraft:wool 6
setblock ~41~6~40 minecraft:sandstone 0
setblock ~41~14~40 minecraft:sandstone 0
fill ~41~15~40 ~41~16~40 minecraft:wool 6
fill ~42~4~40 ~42~4~41 minecraft:sandstone 0
fill ~42~15~40 ~42~16~40 minecraft:sandstone 0
fill ~42~17~40 ~42~17~41 minecraft:wool 6
fill ~45~2~40 ~45~2~42 minecraft:sandstone 0
fill ~45~18~40 ~45~18~42 minecraft:sandstone 0
fill ~45~19~40 ~45~19~42 minecraft:wool 6
fill ~47~21~40 ~48~21~40 minecraft:wool 10
fill ~50~21~40 ~51~21~40 minecraft:wool 9
fill ~53~21~40 ~53~21~41 minecraft:wool 5
fill ~55~21~40 ~55~21~41 minecraft:wool 10
fill ~58~3~40 ~58~3~42 minecraft:sandstone 0
fill ~58~17~40 ~58~17~42 minecraft:sandstone 0
fill ~58~18~40 ~58~18~42 minecraft:wool 6
fill ~59~4~40 ~59~4~42 minecraft:sandstone 0
fill ~59~16~40 ~59~16~42 minecraft:sandstone 0
fill ~59~17~40 ~59~17~42 minecraft:wool 6
fill ~60~16~40 ~60~16~42 minecraft:wool 6
fill ~61~9~40 ~61~11~42 minecraft:sandstone 0
fill ~62~10~40 ~62~11~40 minecraft:wool 6
fill ~4~10~41 ~4~11~42 minecraft:wool 6
fill ~5~14~41 ~5~14~43 minecraft:wool 6
fill ~6~6~41 ~6~6~43 minecraft:sandstone 0
fill ~6~14~41 ~6~14~43 minecraft:sandstone 0
fill ~10~2~41 ~10~2~44 minecraft:sandstone 0
fill ~10~18~41 ~10~18~44 minecraft:sandstone 0
fill ~10~19~41 ~10~19~44 minecraft:wool 6
fill ~11~0~41 ~11~0~42 minecraft:stone 5
fill ~12~21~41 ~12~21~42 minecraft:wool 1
fill ~16~21~41 ~16~21~42 minecraft:wool 4
fill ~20~0~41 ~20~0~51 minecraft:dirt 0
fill ~20~1~41 ~20~1~52 minecraft:sandstone 0
fill ~20~19~41 ~20~19~52 minecraft:sandstone 0
fill ~20~20~41 ~20~20~52 minecraft:wool 6
fill ~22~2~41 ~22~2~43 minecraft:sandstone 0
fill ~22~18~41 ~22~18~43 minecraft:sandstone 0
fill ~22~19~41 ~22~19~43 minecraft:wool 6
setblock ~23~3~41 minecraft:sandstone 0
setblock ~23~17~41 minecraft:sandstone 0
setblock ~23~18~41 minecraft:wool 6
fill ~24~16~41 ~25~16~41 minecraft:sandstone 0
fill ~25~4~41 ~25~4~42 minecraft:sandstone 0
fill ~25~5~41 ~26~5~41 minecraft:sandstone 0
fill ~25~15~41 ~26~15~41 minecraft:sandstone 0
fill ~25~17~41 ~25~17~42 minecraft:wool 6
setblock ~26~6~41 minecraft:sandstone 0
setblock ~26~14~41 minecraft:sandstone 0
setblock ~26~16~41 minecraft:wool 6
fill ~27~7~41 ~27~13~41 minecraft:sandstone 0
fill ~27~14~41 ~30~14~41 minecraft:wool 6
fill ~27~15~41 ~28~15~41 minecraft:wool 6
fill ~28~8~41 ~28~12~41 minecraft:sandstone 0
fill ~28~13~41 ~35~13~41 minecraft:wool 6
fill ~29~10~41 ~29~12~41 minecraft:wool 6
fill ~30~11~41 ~31~12~41 minecraft:wool 6
setblock ~31~10~41 minecraft:wool 6
fill ~32~12~41 ~37~12~41 minecraft:wool 6
fill ~32~14~41 ~33~14~42 minecraft:wool 6
fill ~33~11~41 ~33~11~42 minecraft:wool 6
fill ~35~8~41 ~35~11~41 minecraft:wool 6
setblock ~37~11~41 minecraft:wool 6
fill ~37~13~41 ~38~13~41 minecraft:wool 6
fill ~38~8~41 ~39~12~41 minecraft:sandstone 0
fill ~38~14~41 ~39~14~41 minecraft:wool 6
setblock ~39~7~41 minecraft:sandstone 0
setblock ~39~13~41 minecraft:sandstone 0
setblock ~39~15~41 minecraft:wool 6
fill ~40~5~41 ~41~5~41 minecraft:sandstone 0
setblock ~40~6~41 minecraft:sandstone 0
fill ~40~14~41 ~40~15~41 minecraft:sandstone 0
setblock ~40~16~41 minecraft:wool 6
fill ~41~4~41 ~41~4~42 minecraft:sandstone 0
fill ~41~15~41 ~41~16~41 minecraft:sandstone 0
fill ~41~17~41 ~41~17~42 minecraft:wool 6
setblock ~42~16~41 minecraft:sandstone 0
setblock ~43~3~41 minecraft:sandstone 0
setblock ~43~17~41 minecraft:sandstone 0
setblock ~43~18~41 minecraft:wool 6
fill ~44~2~41 ~44~2~43 minecraft:sandstone 0
fill ~44~18~41 ~44~18~43 minecraft:sandstone 0
fill ~44~19~41 ~44~19~43 minecraft:wool 6
fill ~46~0~41 ~46~0~51 minecraft:dirt 0
fill ~46~1~41 ~46~1~52 minecraft:sandstone 0
fill ~46~19~41 ~46~19~52 minecraft:sandstone 0
fill ~46~20~41 ~46~20~52 minecraft:wool 6
fill ~55~0~41 ~55~0~42 minecraft:stone 5
fill ~56~2~41 ~56~2~44 minecraft:sandstone 0
fill ~56~18~41 ~56~18~44 minecraft:sandstone 0
fill ~56~19~41 ~56~19~44 minecraft:wool 6
fill ~60~6~41 ~60~6~43 minecraft:sandstone 0
fill ~60~14~41 ~60~14~43 minecraft:sandstone 0
fill ~61~14~41 ~61~14~43 minecraft:wool 6
fill ~62~11~41 ~62~11~42 minecraft:wool 6
fill ~4~8~42 ~4~9~42 minecraft:wool 6
fill ~5~13~42 ~5~13~43 minecraft:wool 6
fill ~6~7~42 ~6~7~43 minecraft:sandstone 0
fill ~6~13~42 ~6~13~43 minecraft:sandstone 0
fill ~6~15~42 ~6~15~44 minecraft:wool 6
fill ~7~5~42 ~7~5~44 minecraft:sandstone 0
fill ~7~15~42 ~7~15~44 minecraft:sandstone 0
fill ~9~3~42 ~9~3~44 minecraft:sandstone 0
fill ~9~17~42 ~9~17~44 minecraft:sandstone 0
fill ~9~18~42 ~9~18~44 minecraft:wool 6
fill ~18~21~42 ~19~21~42 minecraft:wool 11
fill ~23~2~42 ~23~2~44 minecraft:sandstone 0
fill ~23~18~42 ~23~18~44 minecraft:sandstone 0
fill ~23~19~42 ~23~19~44 minecraft:wool 6
setblock ~24~3~42 minecraft:sandstone 0
setblock ~24~17~42 minecraft:sandstone 0
setblock ~24~18~42 minecraft:wool 6
fill ~25~16~42 ~26~16~42 minecraft:sandstone 0
setblock ~26~4~42 minecraft:sandstone 0
setblock ~26~17~42 minecraft:wool 6
fill ~27~5~42 ~27~6~42 minecraft:sandstone 0
fill ~27~14~42 ~28~14~42 minecraft:sandstone 0
setblock ~27~15~42 minecraft:sandstone 0
fill ~27~16~42 ~28~16~42 minecraft:wool 6
fill ~28~6~42 ~28~7~42 minecraft:sandstone 0
fill ~28~13~42 ~29~13~42 minecraft:sandstone 0
fill ~28~15~42 ~30~15~42 minecraft:wool 6
fill ~29~7~42 ~29~12~42 minecraft:sandstone 0
fill ~29~14~42 ~31~14~42 minecraft:wool 6
fill ~30~8~42 ~30~12~42 minecraft:sandstone 0
fill ~30~13~42 ~36~13~42 minecraft:wool 6
fill ~31~9~42 ~31~11~42 minecraft:sandstone 0
fill ~31~12~42 ~35~12~42 minecraft:wool 6
setblock ~32~10~42 minecraft:sandstone 0
setblock ~32~11~42 minecraft:wool 6
setblock ~33~10~42 minecraft:wool 6
fill ~34~10~42 ~37~10~42 minecraft:sandstone 0
setblock ~34~11~42 minecraft:wool 6
fill ~34~14~42 ~37~14~42 minecraft:wool 6
fill ~34~15~42 ~34~15~43 minecraft:wool 6
fill ~35~9~42 ~37~9~42 minecraft:sandstone 0
fill ~35~11~42 ~37~11~42 minecraft:sandstone 0
fill ~36~8~42 ~37~8~42 minecraft:sandstone 0
fill ~36~12~42 ~37~12~42 minecraft:sandstone 0
fill ~36~15~42 ~38~15~42 minecraft:wool 6
fill ~37~7~42 ~38~7~42 minecraft:sandstone 0
fill ~37~13~42 ~38~13~42 minecraft:sandstone 0
fill ~38~6~42 ~39~6~42 minecraft:sandstone 0
fill ~38~14~42 ~39~14~42 minecraft:sandstone 0
fill ~38~16~42 ~39~16~42 minecraft:wool 6
setblock ~39~5~42 minecraft:sandstone 0
setblock ~39~15~42 minecraft:sandstone 0
setblock ~40~4~42 minecraft:sandstone 0
fill ~40~16~42 ~41~16~42 minecraft:sandstone 0
setblock ~40~17~42 minecraft:wool 6
setblock ~42~3~42 minecraft:sandstone 0
setblock ~42~17~42 minecraft:sandstone 0
setblock ~42~18~42 minecraft:wool 6
fill ~43~2~42 ~43~2~44 minecraft:sandstone 0
fill ~43~18~42 ~43~18~44 minecraft:sandstone 0
fill ~43~19~42 ~43~19~44 minecraft:wool 6
fill ~46~21~42 ~46~21~43 minecraft:wool 5
fill ~48~21~42 ~48~21~43 minecraft:wool 11
fill ~50~21~42 ~51~21~42 minecraft:wool 2
fill ~57~3~42 ~57~3~44 minecraft:sandstone 0
fill ~57~17~42 ~57~17~44 minecraft:sandstone 0
fill ~57~18~42 ~57~18~44 minecraft:wool 6
fill ~59~5~42 ~59~5~44 minecraft:sandstone 0
fill ~59~15~42 ~59~15~44 minecraft:sandstone 0
fill ~60~7~42 ~60~7~43 minecraft:sandstone 0
fill ~60~13~42 ~60~13~43 minecraft:sandstone 0
fill ~60~15~42 ~60~15~44 minecraft:wool 6
fill ~61~13~42 ~61~13~43 minecraft:wool 6
fill ~62~9~42 ~62~10~42 minecraft:wool 6
fill ~5~10~43 ~5~11~45 minecraft:wool 6
fill ~5~12~43 ~5~12~44 minecraft:wool 6
fill ~6~8~43 ~6~12~44 minecraft:sandstone 0
fill ~7~16~43 ~7~16~44 minecraft:wool 6
fill ~8~4~43 ~8~4~44 minecraft:sandstone 0
fill ~8~16~43 ~8~16~44 minecraft:sandstone 0
fill ~8~17~43 ~8~17~44 minecraft:wool 6
fill ~11~2~43 ~11~2~45 minecraft:sandstone 0
fill ~11~18~43 ~11~18~45 minecraft:sandstone 0
fill ~11~19~43 ~11~19~45 minecraft:wool 6
fill ~12~0~43 ~12~0~44 minecraft:stone 5
fill ~21~0~43 ~21~0~52 minecraft:dirt 0
fill ~21~1~43 ~21~1~53 minecraft:sandstone 0
setblock ~21~2~43 minecraft:sea_lantern
fill ~21~19~43 ~21~19~53 minecraft:sandstone 0
fill ~21~20~43 ~21~20~53 minecraft:wool 6
fill ~24~2~43 ~24~2~44 minecraft:sandstone 0
fill ~24~18~43 ~24~18~44 minecraft:sandstone 0
fill ~24~19~43 ~24~19~44 minecraft:wool 6
fill ~25~3~43 ~26~3~43 minecraft:sandstone 0
fill ~25~17~43 ~26~17~43 minecraft:sandstone 0
fill ~25~18~43 ~26~18~43 minecraft:wool 6
fill ~27~4~43 ~28~4~43 minecraft:sandstone 0
fill ~27~16~43 ~28~16~43 minecraft:sandstone 0
fill ~27~17~43 ~28~17~43 minecraft:wool 6
fill ~28~5~43 ~30~5~43 minecraft:sandstone 0
fill ~28~15~43 ~30~15~43 minecraft:sandstone 0
fill ~29~6~43 ~37~6~43 minecraft:sandstone 0
fill ~29~14~43 ~37~14~43 minecraft:sandstone 0
fill ~29~16~43 ~32~16~43 minecraft:wool 6
fill ~30~7~43 ~36~7~43 minecraft:sandstone 0
fill ~30~13~43 ~36~13~43 minecraft:sandstone 0
fill ~31~8~43 ~35~8~43 minecraft:sandstone 0
fill ~31~12~43 ~35~12~43 minecraft:sandstone 0
fill ~31~15~43 ~33~15~43 minecraft:wool 6
fill ~32~9~43 ~34~9~43 minecraft:sandstone 0
fill ~32~11~43 ~34~11~43 minecraft:sandstone 0
setblock ~33~10~43 minecraft:sea_lantern
fill ~34~16~43 ~37~16~43 minecraft:wool 6
setblock ~35~15~43 minecraft:wool 6
fill ~36~5~43 ~38~5~43 minecraft:sandstone 0
fill ~36~15~43 ~38~15~43 minecraft:sandstone 0
fill ~38~4~43 ~39~4~43 minecraft:sandstone 0
fill ~38~16~43 ~39~16~43 minecraft:sandstone 0
fill ~38~17~43 ~39~17~43 minecraft:wool 6
fill ~40~3~43 ~41~3~43 minecraft:sandstone 0
fill ~40~17~43 ~41~17~43 minecraft:sandstone 0
fill ~40~18~43 ~41~18~43 minecraft:wool 6
fill ~42~2~43 ~42~2~44 minecraft:sandstone 0
fill ~42~18~43 ~42~18~44 minecraft:sandstone 0
fill ~42~19~43 ~42~19~44 minecraft:wool 6
fill ~45~0~43 ~45~0~52 minecraft:dirt 0
fill ~45~1~43 ~45~1~53 minecraft:sandstone 0
setblock ~45~2~43 minecraft:sea_lantern
fill ~45~19~43 ~45~19~53 minecraft:sandstone 0
fill ~45~20~43 ~45~20~53 minecraft:wool 6
fill ~54~0~43 ~54~0~44 minecraft:stone 5
fill ~54~21~43 ~54~21~44 minecraft:wool 14
fill ~55~2~43 ~55~2~45 minecraft:sandstone 0
fill ~55~18~43 ~55~18~45 minecraft:sandstone 0
fill ~55~19~43 ~55~19~45 minecraft:wool 6
fill ~58~4~43 ~58~4~44 minecraft:sandstone 0
fill ~58~16~43 ~58~16~44 minecraft:sandstone 0
fill ~58~17~43 ~58~17~44 minecraft:wool 6
fill ~59~16~43 ~59~16~44 minecraft:wool 6
fill ~60~8~43 ~60~12~44 minecraft:sandstone 0
fill ~61~10~43 ~61~11~45 minecraft:wool 6
fill ~61~12~43 ~61~12~44 minecraft:wool 6
fill ~5~8~44 ~5~9~44 minecraft:wool 6
fill ~6~13~44 ~6~13~46 minecraft:wool 6
fill ~6~14~44 ~6~14~45 minecraft:wool 6
fill ~7~6~44 ~7~7~45 minecraft:sandstone 0
fill ~7~13~44 ~7~13~46 minecraft:sandstone 0
fill ~7~14~44 ~7~14~45 minecraft:sandstone 0
fill ~13~21~44 ~14~21~44 minecraft:wool 3
fill ~16~21~44 ~16~21~45 minecraft:wool 13
fill ~22~0~44 ~22~0~52 minecraft:dirt 0
fill ~22~1~44 ~22~1~53 minecraft:sandstone 0
setblock ~22~2~44 minecraft:sea_lantern
fill ~22~19~44 ~22~19~53 minecraft:sandstone 0
fill ~22~20~44 ~22~20~53 minecraft:wool 6
fill ~25~2~44 ~25~2~45 minecraft:sandstone 0
fill ~25~18~44 ~25~18~45 minecraft:sandstone 0
fill ~25~19~44 ~25~19~45 minecraft:wool 6
fill ~26~3~44 ~28~3~44 minecraft:sandstone 0
fill ~26~17~44 ~28~17~44 minecraft:sandstone 0
fill ~26~18~44 ~28~18~44 minecraft:wool 6
fill ~29~4~44 ~32~4~44 minecraft:sandstone 0
fill ~29~16~44 ~32~16~44 minecraft:sandstone 0
fill ~29~17~44 ~37~17~44 minecraft:wool 6
fill ~31~5~44 ~35~5~44 minecraft:sandstone 0
fill ~31~15~44 ~35~15~44 minecraft:sandstone 0
fill ~31~18~44 ~31~18~45 minecraft:wool 6
setblock ~33~16~44 minecraft:wool 6
fill ~34~4~44 ~37~4~44 minecraft:sandstone 0
fill ~34~16~44 ~37~16~44 minecraft:sandstone 0
fill ~36~18~44 ~36~18~45 minecraft:wool 6
fill ~38~3~44 ~40~3~44 minecraft:sandstone 0
fill ~38~17~44 ~40~17~44 minecraft:sandstone 0
fill ~38~18~44 ~40~18~44 minecraft:wool 6
fill ~41~2~44 ~41~2~45 minecraft:sandstone 0
fill ~41~18~44 ~41~18~45 minecraft:sandstone 0
fill ~41~19~44 ~41~19~45 minecraft:wool 6
fill ~44~0~44 ~44~0~52 minecraft:dirt 0
fill ~44~1~44 ~44~1~53 minecraft:sandstone 0
setblock ~44~2~44 minecraft:sea_lantern
fill ~44~19~44 ~44~19~53 minecraft:sandstone 0
fill ~44~20~44 ~44~20~53 minecraft:wool 6
fill ~51~21~44 ~52~21~44 minecraft:wool 3
fill ~59~6~44 ~59~7~45 minecraft:sandstone 0
fill ~59~13~44 ~59~13~46 minecraft:sandstone 0
fill ~59~14~44 ~59~14~45 minecraft:sandstone 0
fill ~60~13~44 ~60~13~46 minecraft:wool 6
fill ~60~14~44 ~60~14~45 minecraft:wool 6
setblock ~61~9~44 minecraft:wool 6
fill ~6~7~45 ~6~9~45 minecraft:wool 6
setblock ~6~10~45 minecraft:sandstone 0
fill ~6~11~45 ~6~12~46 minecraft:wool 6
fill ~7~8~45 ~7~9~46 minecraft:sandstone 0
fill ~7~11~45 ~7~12~46 minecraft:sandstone 0
fill ~7~15~45 ~7~15~46 minecraft:wool 6
fill ~8~5~45 ~8~5~46 minecraft:sandstone 0
fill ~8~15~45 ~8~15~46 minecraft:sandstone 0
fill ~8~16~45 ~8~16~46 minecraft:wool 6
fill ~9~4~45 ~9~4~46 minecraft:sandstone 0
fill ~9~16~45 ~9~16~46 minecraft:sandstone 0
fill ~9~17~45 ~9~17~46 minecraft:wool 6
fill ~10~3~45 ~10~3~46 minecraft:sandstone 0
fill ~10~17~45 ~10~17~46 minecraft:sandstone 0
fill ~10~18~45 ~10~18~46 minecraft:wool 6
fill ~12~2~45 ~12~2~47 minecraft:sandstone 0
fill ~12~18~45 ~12~18~47 minecraft:sandstone 0
fill ~12~19~45 ~12~19~47 minecraft:wool 6
setblock ~13~0~45 minecraft:stone 5
fill ~18~21~45 ~18~21~46 minecraft:wool 10
fill ~20~21~45 ~21~21~45 minecraft:wool 9
fill ~23~0~45 ~24~0~53 minecraft:dirt 0
fill ~23~1~45 ~24~1~54 minecraft:sandstone 0
fill ~23~19~45 ~24~19~54 minecraft:sandstone 0
fill ~23~20~45 ~24~20~54 minecraft:wool 6
fill ~26~2~45 ~27~2~45 minecraft:sandstone 0
fill ~26~18~45 ~27~18~45 minecraft:sandstone 0
fill ~26~19~45 ~27~19~45 minecraft:wool 6
fill ~28~3~45 ~38~3~45 minecraft:sandstone 0
fill ~28~17~45 ~38~17~45 minecraft:sandstone 0
fill ~28~18~45 ~30~18~45 minecraft:wool 6
fill ~32~18~45 ~35~18~45 minecraft:wool 6
setblock ~33~4~45 minecraft:sandstone 0
setblock ~33~16~45 minecraft:sandstone 0
fill ~37~18~45 ~38~18~45 minecraft:wool 6
fill ~39~2~45 ~40~2~45 minecraft:sandstone 0
fill ~39~18~45 ~40~18~45 minecraft:sandstone 0
fill ~39~19~45 ~40~19~45 minecraft:wool 6
fill ~42~0~45 ~43~0~53 minecraft:dirt 0
fill ~42~1~45 ~43~1~54 minecraft:sandstone 0
fill ~42~19~45 ~43~19~53 minecraft:sandstone 0
fill ~42~20~45 ~43~20~53 minecraft:wool 6
fill ~44~21~45 ~45~21~45 minecraft:wool 14
fill ~48~21~45 ~48~21~46 minecraft:wool 1
setblock ~53~0~45 minecraft:stone 5
fill ~54~2~45 ~54~2~47 minecraft:sandstone 0
fill ~54~18~45 ~54~18~47 minecraft:sandstone 0
fill ~54~19~45 ~54~19~47 minecraft:wool 6
fill ~56~3~45 ~56~3~46 minecraft:sandstone 0
fill ~56~17~45 ~56~17~46 minecraft:sandstone 0
fill ~56~18~45 ~56~18~46 minecraft:wool 6
fill ~57~4~45 ~57~4~46 minecraft:sandstone 0
fill ~57~16~45 ~57~16~46 minecraft:sandstone 0
fill ~57~17~45 ~57~17~46 minecraft:wool 6
fill ~58~5~45 ~58~5~46 minecraft:sandstone 0
fill ~58~15~45 ~58~15~46 minecraft:sandstone 0
fill ~58~16~45 ~58~16~46 minecraft:wool 6
fill ~59~8~45 ~59~9~46 minecraft:sandstone 0
fill ~59~11~45 ~59~12~46 minecraft:sandstone 0
fill ~59~15~45 ~59~15~46 minecraft:wool 6
fill ~60~8~45 ~60~9~45 minecraft:wool 6
setblock ~60~10~45 minecraft:sandstone 0
fill ~60~11~45 ~60~12~46 minecraft:wool 6
fill ~6~9~46 ~6~10~46 minecraft:wool 6
setblock ~7~7~46 minecraft:sandstone 0
setblock ~7~10~46 minecraft:sandstone 0
fill ~7~14~46 ~7~14~47 minecraft:wool 6
fill ~8~6~46 ~8~6~47 minecraft:sandstone 0
fill ~8~14~46 ~8~14~47 minecraft:sandstone 0
fill ~11~3~46 ~11~3~47 minecraft:sandstone 0
fill ~11~17~46 ~11~17~47 minecraft:sandstone 0
fill ~11~18~46 ~11~18~47 minecraft:wool 6
fill ~13~2~46 ~13~2~48 minecraft:sandstone 0
fill ~13~18~46 ~13~18~48 minecraft:sandstone 0
fill ~13~19~46 ~13~19~48 minecraft:wool 6
fill ~14~0~46 ~14~0~47 minecraft:stone 5
fill ~25~0~46 ~26~0~54 minecraft:dirt 0
fill ~25~1~46 ~26~1~55 minecraft:sandstone 0
fill ~25~19~46 ~26~19~55 minecraft:sandstone 0
fill ~25~20~46 ~26~20~55 minecraft:wool 6
fill ~25~21~46 ~25~21~47 minecraft:wool 10
fill ~27~2~46 ~32~2~46 minecraft:sandstone 0
fill ~27~18~46 ~32~18~46 minecraft:sandstone 0
fill ~27~19~46 ~32~19~46 minecraft:wool 6
setblock ~33~3~46 minecraft:sandstone 0
setblock ~33~17~46 minecraft:sandstone 0
setblock ~33~18~46 minecraft:wool 6
fill ~34~2~46 ~39~2~46 minecraft:sandstone 0
fill ~34~18~46 ~39~18~46 minecraft:sandstone 0
fill ~34~19~46 ~39~19~46 minecraft:wool 6
fill ~40~0~46 ~41~0~54 minecraft:dirt 0
fill ~40~1~46 ~41~1~55 minecraft:sandstone 0
fill ~40~19~46 ~41~19~55 minecraft:sandstone 0
fill ~40~20~46 ~41~20~55 minecraft:wool 6
fill ~50~21~46 ~51~21~46 minecraft:wool 4
fill ~52~0~46 ~52~0~47 minecraft:stone 5
fill ~53~2~46 ~53~2~48 minecraft:sandstone 0
fill ~53~18~46 ~53~18~48 minecraft:sandstone 0
fill ~53~19~46 ~53~19~48 minecraft:wool 6
fill ~55~3~46 ~55~3~47 minecraft:sandstone 0
fill ~55~17~46 ~55~17~47 minecraft:sandstone 0
fill ~55~18~46 ~55~18~47 minecraft:wool 6
fill ~58~6~46 ~58~6~47 minecraft:sandstone 0
fill ~58~14~46 ~58~14~47 minecraft:sandstone 0
setblock ~59~7~46 minecraft:sandstone 0
setblock ~59~10~46 minecraft:sandstone 0
fill ~59~14~46 ~59~14~47 minecraft:wool 6
setblock ~60~10~46 minecraft:wool 6
fill ~7~8~47 ~7~13~47 minecraft:wool 6
fill ~8~7~47 ~8~13~47 minecraft:sandstone 0
setblock ~8~15~47 minecraft:wool 6
setblock ~9~5~47 minecraft:sandstone 0
setblock ~9~15~47 minecraft:sandstone 0
setblock ~9~16~47 minecraft:wool 6
setblock ~10~4~47 minecraft:sandstone 0
setblock ~10~16~47 minecraft:sandstone 0
setblock ~10~17~47 minecraft:wool 6
fill ~15~21~47 ~16~21~47 minecraft:wool 14
fill ~20~21~47 ~20~21~48 minecraft:wool 5
fill ~22~21~47 ~23~21~47 minecraft:wool 1
fill ~27~0~47 ~28~0~54 minecraft:dirt 0
fill ~27~1~47 ~28~1~55 minecraft:sandstone 0
fill ~27~19~47 ~28~19~55 minecraft:sandstone 0
fill ~27~20~47 ~28~20~55 minecraft:wool 6
setblock ~28~2~47 minecraft:sea_lantern
fill ~29~2~47 ~37~2~47 minecraft:sandstone 0
fill ~29~18~47 ~37~18~47 minecraft:sandstone 0
fill ~29~19~47 ~37~19~47 minecraft:wool 6
fill ~38~0~47 ~39~0~54 minecraft:dirt 0
fill ~38~1~47 ~39~1~55 minecraft:sandstone 0
setblock ~38~2~47 minecraft:sea_lantern
fill ~38~19~47 ~39~19~55 minecraft:sandstone 0
fill ~38~20~47 ~39~20~55 minecraft:wool 6
fill ~40~21~47 ~41~21~47 minecraft:wool 11
fill ~43~21~47 ~43~21~48 minecraft:wool 2
fill ~45~21~47 ~46~21~47 minecraft:wool 4
setblock ~56~4~47 minecraft:sandstone 0
setblock ~56~16~47 minecraft:sandstone 0
setblock ~56~17~47 minecraft:wool 6
setblock ~57~5~47 minecraft:sandstone 0
setblock ~57~15~47 minecraft:sandstone 0
setblock ~57~16~47 minecraft:wool 6
fill ~58~7~47 ~58~13~47 minecraft:sandstone 0
setblock ~58~15~47 minecraft:wool 6
fill ~59~5~47 ~59~13~47 minecraft:wool 6
fill ~7~10~48 ~7~12~48 minecraft:wool 6
fill ~8~8~48 ~8~12~48 minecraft:sandstone 0
fill ~8~13~48 ~8~13~49 minecraft:wool 6
setblock ~8~14~48 minecraft:wool 6
fill ~9~6~48 ~9~7~48 minecraft:sandstone 0
fill ~9~13~48 ~9~13~49 minecraft:sandstone 0
setblock ~9~14~48 minecraft:sandstone 0
fill ~9~15~48 ~9~15~49 minecraft:wool 6
fill ~10~5~48 ~10~5~49 minecraft:sandstone 0
fill ~10~15~48 ~10~15~49 minecraft:sandstone 0
fill ~10~16~48 ~10~16~49 minecraft:wool 6
fill ~11~4~48 ~11~4~49 minecraft:sandstone 0
fill ~11~16~48 ~11~16~49 minecraft:sandstone 0
fill ~11~17~48 ~11~17~49 minecraft:wool 6
fill ~12~3~48 ~12~3~49 minecraft:sandstone 0
fill ~12~17~48 ~12~17~49 minecraft:sandstone 0
fill ~12~18~48 ~12~18~49 minecraft:wool 6
fill ~14~2~48 ~14~2~49 minecraft:sandstone 0
fill ~14~18~48 ~14~18~49 minecraft:sandstone 0
fill ~14~19~48 ~14~19~49 minecraft:wool 6
setblock ~15~0~48 minecraft:stone 5
fill ~27~21~48 ~28~21~48 minecraft:wool 4
fill ~29~0~48 ~37~0~55 minecraft:dirt 0
fill ~29~1~48 ~37~1~56 minecraft:sandstone 0
fill ~29~19~48 ~37~19~56 minecraft:sandstone 0
fill ~29~20~48 ~37~20~56 minecraft:wool 6
fill ~30~21~48 ~31~21~48 minecraft:wool 14
fill ~38~21~48 ~38~21~49 minecraft:wool 4
fill ~49~21~48 ~49~21~49 minecraft:wool 10
setblock ~51~0~48 minecraft:stone 5
fill ~52~2~48 ~52~2~49 minecraft:sandstone 0
fill ~52~18~48 ~52~18~49 minecraft:sandstone 0
fill ~52~19~48 ~52~19~49 minecraft:wool 6
fill ~54~3~48 ~54~3~49 minecraft:sandstone 0
fill ~54~17~48 ~54~17~49 minecraft:sandstone 0
fill ~54~18~48 ~54~18~49 minecraft:wool 6
fill ~55~4~48 ~55~4~49 minecraft:sandstone 0
fill ~55~16~48 ~55~16~49 minecraft:sandstone 0
fill ~55~17~48 ~55~17~49 minecraft:wool 6
fill ~56~5~48 ~56~5~49 minecraft:sandstone 0
fill ~56~15~48 ~56~15~49 minecraft:sandstone 0
fill ~56~16~48 ~56~16~49 minecraft:wool 6
fill ~57~6~48 ~57~7~48 minecraft:sandstone 0
fill ~57~13~48 ~57~13~49 minecraft:sandstone 0
setblock ~57~14~48 minecraft:sandstone 0
fill ~57~15~48 ~57~15~49 minecraft:wool 6
fill ~58~8~48 ~58~12~48 minecraft:sandstone 0
fill ~58~13~48 ~58~13~49 minecraft:wool 6
setblock ~58~14~48 minecraft:wool 6
fill ~59~11~48 ~59~12~48 minecraft:wool 6
fill ~8~10~49 ~8~12~49 minecraft:wool 6
fill ~9~7~49 ~9~12~49 minecraft:sandstone 0
setblock ~9~14~49 minecraft:wool 6
setblock ~10~6~49 minecraft:sandstone 0
setblock ~10~14~49 minecraft:sandstone 0
fill ~13~3~49 ~13~3~50 minecraft:sandstone 0
fill ~13~17~49 ~13~17~50 minecraft:sandstone 0
fill ~13~18~49 ~13~18~50 minecraft:wool 6
fill ~15~2~49 ~15~2~50 minecraft:sandstone 0
fill ~15~18~49 ~15~18~50 minecraft:sandstone 0
fill ~15~19~49 ~15~19~50 minecraft:wool 6
setblock ~16~0~49 minecraft:stone 5
fill ~16~21~49 ~17~21~49 minecraft:wool 1
fill ~24~21~49 ~24~21~50 minecraft:wool 3
fill ~34~21~49 ~34~21~50 minecraft:wool 9
fill ~47~21~49 ~47~21~50 minecraft:wool 11
setblock ~50~0~49 minecraft:stone 5
fill ~51~2~49 ~51~2~50 minecraft:sandstone 0
fill ~51~18~49 ~51~18~50 minecraft:sandstone 0
fill ~51~19~49 ~51~19~50 minecraft:wool 6
fill ~53~3~49 ~53~3~50 minecraft:sandstone 0
fill ~53~17~49 ~53~17~50 minecraft:sandstone 0
fill ~53~18~49 ~53~18~50 minecraft:wool 6
setblock ~56~6~49 minecraft:sandstone 0
setblock ~56~14~49 minecraft:sandstone 0
fill ~57~7~49 ~57~12~49 minecraft:sandstone 0
setblock ~57~14~49 minecraft:wool 6
fill ~58~9~49 ~58~12~49 minecraft:wool 6
fill ~9~8~50 ~9~13~50 minecraft:wool 6
fill ~10~7~50 ~10~13~50 minecraft:sandstone 0
fill ~10~14~50 ~10~14~51 minecraft:wool 6
setblock ~10~15~50 minecraft:wool 6
fill ~11~5~50 ~11~6~50 minecraft:sandstone 0
fill ~11~14~50 ~11~14~51 minecraft:sandstone 0
setblock ~11~15~50 minecraft:sandstone 0
setblock ~11~16~50 minecraft:wool 6
setblock ~12~4~50 minecraft:sandstone 0
setblock ~12~16~50 minecraft:sandstone 0
setblock ~12~17~50 minecraft:wool 6
fill ~14~3~50 ~14~3~51 minecraft:sandstone 0
fill ~14~17~50 ~14~17~51 minecraft:sandstone 0
fill ~14~18~50 ~14~18~51 minecraft:wool 6
fill ~16~2~50 ~16~2~51 minecraft:sandstone 0
fill ~16~18~50 ~16~18~51 minecraft:sandstone 0
fill ~16~19~50 ~16~19~51 minecraft:wool 6
setblock ~17~0~50 minecraft:stone 5
fill ~19~21~50 ~19~21~51 minecraft:wool 4
fill ~21~21~50 ~22~21~50 minecraft:wool 2
fill ~26~21~50 ~27~21~50 minecraft:wool 2
fill ~29~21~50 ~30~21~50 minecraft:wool 11
fill ~32~21~50 ~32~21~51 minecraft:wool 13
fill ~36~21~50 ~36~21~51 minecraft:wool 5
fill ~40~21~50 ~41~21~50 minecraft:wool 3
fill ~44~21~50 ~45~21~50 minecraft:wool 9
setblock ~49~0~50 minecraft:stone 5
fill ~50~2~50 ~50~2~51 minecraft:sandstone 0
fill ~50~18~50 ~50~18~51 minecraft:sandstone 0
fill ~50~19~50 ~50~19~51 minecraft:wool 6
fill ~52~3~50 ~52~3~51 minecraft:sandstone 0
fill ~52~17~50 ~52~17~51 minecraft:sandstone 0
fill ~52~18~50 ~52~18~51 minecraft:wool 6
setblock ~54~4~50 minecraft:sandstone 0
setblock ~54~16~50 minecraft:sandstone 0
setblock ~54~17~50 minecraft:wool 6
fill ~55~5~50 ~55~6~50 minecraft:sandstone 0
fill ~55~14~50 ~55~14~51 minecraft:sandstone 0
setblock ~55~15~50 minecraft:sandstone 0
setblock ~55~16~50 minecraft:wool 6
fill ~56~7~50 ~56~13~50 minecraft:sandstone 0
fill ~56~14~50 ~56~14~51 minecraft:wool 6
setblock ~56~15~50 minecraft:wool 6
fill ~57~7~50 ~57~13~50 minecraft:wool 6
fill ~9~10~51 ~9~11~51 minecraft:wool 6
fill ~10~9~51 ~10~11~51 minecraft:sandstone 0
fill ~10~12~51 ~10~12~52 minecraft:wool 6
setblock ~10~13~51 minecraft:wool 6
fill ~11~6~51 ~11~8~51 minecraft:sandstone 0
fill ~11~12~51 ~11~12~52 minecraft:sandstone 0
setblock ~11~13~51 minecraft:sandstone 0
setblock ~11~15~51 minecraft:wool 6
setblock ~12~5~51 minecraft:sandstone 0
setblock ~12~15~51 minecraft:sandstone 0
setblock ~12~16~51 minecraft:wool 6
setblock ~13~4~51 minecraft:sandstone 0
setblock ~13~16~51 minecraft:sandstone 0
setblock ~13~17~51 minecraft:wool 6
fill ~15~3~51 ~15~3~52 minecraft:sandstone 0
fill ~15~17~51 ~15~17~52 minecraft:sandstone 0
fill ~15~18~51 ~15~18~52 minecraft:wool 6
fill ~17~2~51 ~17~2~52 minecraft:sandstone 0
fill ~17~18~51 ~17~18~52 minecraft:sandstone 0
fill ~17~19~51 ~17~19~52 minecraft:wool 6
fill ~18~0~51 ~19~0~51 minecraft:stone 5
fill ~47~0~51 ~48~0~51 minecraft:stone 5
fill ~49~2~51 ~49~2~52 minecraft:sandstone 0
fill ~49~18~51 ~49~18~52 minecraft:sandstone 0
fill ~49~19~51 ~49~19~52 minecraft:wool 6
fill ~51~3~51 ~51~3~52 minecraft:sandstone 0
fill ~51~17~51 ~51~17~52 minecraft:sandstone 0
fill ~51~18~51 ~51~18~52 minecraft:wool 6
setblock ~53~4~51 minecraft:sandstone 0
setblock ~53~16~51 minecraft:sandstone 0
setblock ~53~17~51 minecraft:wool 6
setblock ~54~5~51 minecraft:sandstone 0
setblock ~54~15~51 minecraft:sandstone 0
setblock ~54~16~51 minecraft:wool 6
fill ~55~6~51 ~55~8~51 minecraft:sandstone 0
fill ~55~12~51 ~55~12~52 minecraft:sandstone 0
setblock ~55~13~51 minecraft:sandstone 0
setblock ~55~15~51 minecraft:wool 6
fill ~56~9~51 ~56~11~51 minecraft:sandstone 0
fill ~56~12~51 ~56~12~52 minecraft:wool 6
setblock ~56~13~51 minecraft:wool 6
fill ~57~9~51 ~57~11~51 minecraft:wool 6
fill ~10~10~52 ~10~11~52 minecraft:wool 6
fill ~11~8~52 ~11~11~52 minecraft:sandstone 0
fill ~11~13~52 ~11~14~52 minecraft:wool 6
fill ~12~6~52 ~12~7~52 minecraft:sandstone 0
fill ~12~13~52 ~12~14~52 minecraft:sandstone 0
setblock ~12~15~52 minecraft:wool 6
setblock ~13~5~52 minecraft:sandstone 0
setblock ~13~15~52 minecraft:sandstone 0
setblock ~13~16~52 minecraft:wool 6
setblock ~14~4~52 minecraft:sandstone 0
setblock ~14~16~52 minecraft:sandstone 0
setblock ~14~17~52 minecraft:wool 6
fill ~16~3~52 ~16~3~53 minecraft:sandstone 0
fill ~16~17~52 ~16~17~53 minecraft:sandstone 0
fill ~16~18~52 ~16~18~53 minecraft:wool 6
fill ~18~2~52 ~19~2~53 minecraft:sandstone 0
fill ~18~18~52 ~19~18~53 minecraft:sandstone 0
fill ~18~19~52 ~19~19~53 minecraft:wool 6
setblock ~20~0~52 minecraft:stone 5
fill ~22~21~52 ~22~21~53 minecraft:wool 11
fill ~25~21~52 ~26~21~52 minecraft:wool 13
fill ~29~21~52 ~29~21~53 minecraft:wool 1
fill ~38~21~52 ~39~21~52 minecraft:wool 1
fill ~43~21~52 ~44~21~52 minecraft:wool 14
setblock ~46~0~52 minecraft:stone 5
fill ~47~2~52 ~48~2~53 minecraft:sandstone 0
fill ~47~18~52 ~48~18~53 minecraft:sandstone 0
fill ~47~19~52 ~48~19~53 minecraft:wool 6
fill ~50~3~52 ~50~3~53 minecraft:sandstone 0
fill ~50~17~52 ~50~17~53 minecraft:sandstone 0
fill ~50~18~52 ~50~18~53 minecraft:wool 6
setblock ~52~4~52 minecraft:sandstone 0
setblock ~52~16~52 minecraft:sandstone 0
setblock ~52~17~52 minecraft:wool 6
setblock ~53~5~52 minecraft:sandstone 0
setblock ~53~15~52 minecraft:sandstone 0
setblock ~53~16~52 minecraft:wool 6
fill ~54~6~52 ~54~7~52 minecraft:sandstone 0
fill ~54~13~52 ~54~14~52 minecraft:sandstone 0
setblock ~54~15~52 minecraft:wool 6
fill ~55~8~52 ~55~11~52 minecraft:sandstone 0
fill ~55~13~52 ~55~14~52 minecraft:wool 6
setblock ~56~11~52 minecraft:wool 6
fill ~11~11~53 ~11~12~53 minecraft:wool 6
fill ~12~8~53 ~12~12~53 minecraft:sandstone 0
fill ~12~13~53 ~12~14~53 minecraft:wool 6
fill ~13~6~53 ~13~7~53 minecraft:sandstone 0
fill ~13~13~53 ~13~14~53 minecraft:sandstone 0
setblock ~13~15~53 minecraft:wool 6
setblock ~14~5~53 minecraft:sandstone 0
setblock ~14~15~53 minecraft:sandstone 0
setblock ~14~16~53 minecraft:wool 6
setblock ~15~4~53 minecraft:sandstone 0
setblock ~15~16~53 minecraft:sandstone 0
setblock ~15~17~53 minecraft:wool 6
setblock ~17~3~53 minecraft:sandstone 0
setblock ~17~17~53 minecraft:sandstone 0
setblock ~17~18~53 minecraft:wool 6
fill ~20~2~53 ~20~2~54 minecraft:sandstone 0
fill ~20~18~53 ~20~18~54 minecraft:sandstone 0
fill ~20~19~53 ~20~19~54 minecraft:wool 6
fill ~21~0~53 ~22~0~53 minecraft:stone 5
fill ~31~21~53 ~32~21~53 minecraft:wool 3
fill ~34~21~53 ~34~21~54 minecraft:wool 2
fill ~41~21~53 ~41~21~54 minecraft:wool 13
fill ~44~0~53 ~45~0~53 minecraft:stone 5
fill ~46~2~53 ~46~2~54 minecraft:sandstone 0
fill ~46~18~53 ~46~18~54 minecraft:sandstone 0
fill ~46~19~53 ~46~19~54 minecraft:wool 6
setblock ~49~3~53 minecraft:sandstone 0
setblock ~49~17~53 minecraft:sandstone 0
setblock ~49~18~53 minecraft:wool 6
setblock ~51~4~53 minecraft:sandstone 0
setblock ~51~16~53 minecraft:sandstone 0
setblock ~51~17~53 minecraft:wool 6
setblock ~52~5~53 minecraft:sandstone 0
setblock ~52~15~53 minecraft:sandstone 0
setblock ~52~16~53 minecraft:wool 6
fill ~53~6~53 ~53~7~53 minecraft:sandstone 0
fill ~53~13~53 ~53~14~53 minecraft:sandstone 0
setblock ~53~15~53 minecraft:wool 6
fill ~54~8~53 ~54~12~53 minecraft:sandstone 0
fill ~54~13~53 ~54~14~53 minecraft:wool 6
fill ~55~9~53 ~55~12~53 minecraft:wool 6
setblock ~12~4~54 minecraft:wool 6
fill ~12~8~54 ~12~12~54 minecraft:wool 6
fill ~13~8~54 ~14~8~54 minecraft:sandstone 0
fill ~13~9~54 ~13~12~54 minecraft:sandstone 0
fill ~13~13~54 ~13~14~54 minecraft:wool 6
fill ~14~6~54 ~15~6~54 minecraft:sandstone 0
setblock ~14~7~54 minecraft:sandstone 0
fill ~14~12~54 ~14~14~54 minecraft:sandstone 0
setblock ~14~15~54 minecraft:wool 6
setblock ~15~5~54 minecraft:sandstone 0
fill ~15~14~54 ~15~15~54 minecraft:sandstone 0
setblock ~15~16~54 minecraft:wool 6
fill ~16~4~54 ~17~4~54 minecraft:sandstone 0
fill ~16~16~54 ~17~16~54 minecraft:sandstone 0
fill ~16~17~54 ~17~17~54 minecraft:wool 6
fill ~18~3~54 ~19~3~54 minecraft:sandstone 0
fill ~18~17~54 ~19~17~54 minecraft:sandstone 0
fill ~18~18~54 ~19~18~54 minecraft:wool 6
fill ~21~2~54 ~22~2~55 minecraft:sandstone 0
fill ~21~18~54 ~22~18~55 minecraft:sandstone 0
fill ~21~19~54 ~22~19~55 minecraft:wool 6
fill ~23~0~54 ~24~0~54 minecraft:stone 5
fill ~24~21~54 ~25~21~54 minecraft:wool 14
fill ~27~21~54 ~27~21~55 minecraft:wool 9
fill ~36~21~54 ~37~21~54 minecraft:wool 11
fill ~39~21~54 ~39~21~55 minecraft:wool 10
fill ~42~0~54 ~43~0~54 minecraft:stone 5
setblock ~42~19~54 minecraft:sandstone 0
setblock ~42~20~54 minecraft:wool 6
fill ~43~18~54 ~45~18~55 minecraft:sandstone 0
fill ~43~19~54 ~45~19~55 minecraft:wool 6
fill ~44~2~54 ~45~2~55 minecraft:sandstone 0
fill ~47~3~54 ~48~3~54 minecraft:sandstone 0
fill ~47~17~54 ~48~17~54 minecraft:sandstone 0
fill ~47~18~54 ~48~18~54 minecraft:wool 6
fill ~49~4~54 ~50~4~54 minecraft:sandstone 0
fill ~49~16~54 ~50~16~54 minecraft:sandstone 0
fill ~49~17~54 ~50~17~54 minecraft:wool 6
fill ~51~5~54 ~51~6~54 minecraft:sandstone 0
fill ~51~14~54 ~52~14~54 minecraft:sandstone 0
