fill ~47~20~7 ~53~22~7 minecraft:obsidian
fill ~47~23~7 ~52~23~7 minecraft:obsidian
fill ~48~24~7 ~51~24~7 minecraft:obsidian
fill ~46~20~8 ~46~21~18 minecraft:obsidian
fill ~46~22~8 ~46~23~17 minecraft:obsidian
fill ~47~19~8 ~53~19~16 minecraft:obsidian
fill ~47~20~8 ~47~21~8 minecraft:stained_glass 2
fill ~47~22~8 ~48~23~8 minecraft:stained_glass 10
fill ~47~24~8 ~47~24~16 minecraft:obsidian
setblock ~48~20~8 minecraft:stained_glass 10
fill ~48~21~8 ~49~21~8 minecraft:stained_glass 2
fill ~48~24~8 ~51~24~8 minecraft:stained_glass 2
fill ~48~25~8 ~51~25~16 minecraft:obsidian
fill ~49~20~8 ~50~20~8 minecraft:stained_glass 2
fill ~49~22~8 ~52~22~8 minecraft:stained_glass 2
fill ~49~23~8 ~49~23~9 minecraft:stained_glass 10
fill ~50~21~8 ~50~21~9 minecraft:stained_glass 10
fill ~50~23~8 ~52~23~8 minecraft:stained_glass 2
setblock ~50~26~8 minecraft:skull 1
fill ~51~20~8 ~53~20~11 minecraft:stained_glass 10
fill ~51~21~8 ~53~21~8 minecraft:stained_glass 2
fill ~52~24~8 ~52~24~16 minecraft:obsidian
setblock ~53~22~8 minecraft:stained_glass 10
fill ~53~23~8 ~53~23~15 minecraft:obsidian
fill ~54~20~8 ~54~20~18 minecraft:obsidian
fill ~54~21~8 ~54~22~17 minecraft:obsidian
fill ~47~20~9 ~47~20~11 minecraft:stained_glass 10
fill ~47~21~9 ~47~21~11 minecraft:stained_glass 2
fill ~47~22~9 ~47~23~9 minecraft:stained_glass 2
setblock ~48~20~9 minecraft:stained_glass 2
fill ~48~21~9 ~48~22~9 minecraft:stained_glass 10
fill ~48~23~9 ~48~23~11 minecraft:stained_glass 2
setblock ~48~24~9 minecraft:stained_glass 2
setblock ~49~20~9 minecraft:stained_glass 10
fill ~49~21~9 ~49~22~10 minecraft:stained_glass 2
fill ~49~24~9 ~50~24~9 minecraft:stained_glass 10
fill ~50~20~9 ~50~20~10 minecraft:stained_glass 2
setblock ~50~22~9 minecraft:stained_glass 2
setblock ~50~23~9 minecraft:stained_glass 10
fill ~51~21~9 ~53~21~9 minecraft:stained_glass 10
fill ~51~22~9 ~52~22~9 minecraft:stained_glass 10
fill ~51~23~9 ~51~24~9 minecraft:stained_glass 2
setblock ~52~23~9 minecraft:stained_glass 10
setblock ~53~22~9 minecraft:stained_glass 2
fill ~47~22~10 ~47~23~10 minecraft:stained_glass 10
fill ~48~20~10 ~48~20~11 minecraft:stained_glass 10
fill ~48~21~10 ~48~22~10 minecraft:stained_glass 2
setblock ~48~24~10 minecraft:stained_glass 10
setblock ~49~20~10 minecraft:stained_glass 2
fill ~49~23~10 ~50~23~10 minecraft:stained_glass 2
setblock ~49~24~10 minecraft:stained_glass 2
setblock ~50~21~10 minecraft:stained_glass 2
fill ~50~22~10 ~51~22~10 minecraft:stained_glass 10
setblock ~50~24~10 minecraft:stained_glass 10
fill ~51~21~10 ~52~21~10 minecraft:stained_glass 10
fill ~51~23~10 ~51~23~12 minecraft:stained_glass 10
setblock ~51~24~10 minecraft:stained_glass 2
fill ~52~22~10 ~52~23~10 minecraft:stained_glass 2
fill ~53~21~10 ~53~21~12 minecraft:stained_glass 2
setblock ~53~22~10 minecraft:stained_glass 10
fill ~47~22~11 ~51~22~11 minecraft:stained_glass 2
fill ~47~23~11 ~47~23~13 minecraft:stained_glass 2
fill ~48~21~11 ~51~21~11 minecraft:stained_glass 10
setblock ~48~24~11 minecraft:stained_glass 2
fill ~49~20~11 ~50~20~11 minecraft:stained_glass 10
fill ~49~23~11 ~49~24~11 minecraft:stained_glass 10
fill ~50~23~11 ~50~23~12 minecraft:stained_glass 2
setblock ~50~24~11 minecraft:stained_glass 2
fill ~51~24~11 ~51~24~12 minecraft:stained_glass 10
setblock ~52~21~11 minecraft:stained_glass 2
fill ~52~22~11 ~52~23~11 minecraft:stained_glass 10
fill ~53~22~11 ~53~22~14 minecraft:stained_glass 2
fill ~47~20~12 ~48~20~12 minecraft:stained_glass 2
fill ~47~21~12 ~47~21~14 minecraft:stained_glass 10
fill ~47~22~12 ~47~22~13 minecraft:stained_glass 2
fill ~48~21~12 ~51~21~12 minecraft:stained_glass 2
fill ~48~22~12 ~48~24~12 minecraft:stained_glass 10
setblock ~49~20~12 minecraft:stained_glass 10
fill ~49~22~12 ~52~22~12 minecraft:stained_glass 2
fill ~49~23~12 ~49~23~13 minecraft:stained_glass 2
fill ~49~24~12 ~50~24~12 minecraft:stained_glass 10
fill ~50~20~12 ~52~20~12 minecraft:stained_glass 2
setblock ~52~21~12 minecraft:stained_glass 10
fill ~52~23~12 ~52~23~15 minecraft:stained_glass 10
fill ~53~20~12 ~53~20~15 minecraft:stained_glass 10
setblock ~47~20~13 minecraft:stained_glass 2
fill ~48~20~13 ~48~20~14 minecraft:stained_glass 10
fill ~48~21~13 ~48~24~13 minecraft:stained_glass 2
setblock ~49~20~13 minecraft:stained_glass 2
setblock ~49~21~13 minecraft:stained_glass 10
fill ~49~22~13 ~51~22~13 minecraft:glowstone
fill ~49~24~13 ~51~24~13 minecraft:stained_glass 2
fill ~50~20~13 ~51~20~13 minecraft:stained_glass 10
setblock ~50~21~13 minecraft:glowstone
setblock ~50~23~13 minecraft:glowstone
setblock ~51~21~13 minecraft:stained_glass 10
setblock ~51~23~13 minecraft:stained_glass 2
fill ~52~20~13 ~52~20~14 minecraft:stained_glass 2
fill ~52~21~13 ~52~22~13 minecraft:stained_glass 2
fill ~53~21~13 ~53~21~14 minecraft:stained_glass 10
fill ~47~20~14 ~47~20~15 minecraft:stained_glass 10
fill ~47~22~14 ~49~22~14 minecraft:stained_glass 10
fill ~47~23~14 ~47~23~15 minecraft:stained_glass 10
fill ~48~21~14 ~48~21~15 minecraft:stained_glass 10
fill ~48~23~14 ~48~23~15 minecraft:stained_glass 2
fill ~48~24~14 ~50~24~14 minecraft:stained_glass 2
fill ~49~20~14 ~49~20~15 minecraft:stained_glass 10
setblock ~49~21~14 minecraft:glowstone
setblock ~49~23~14 minecraft:glowstone
fill ~50~20~14 ~50~21~15 minecraft:stained_glass 2
setblock ~50~22~14 minecraft:glowstone
setblock ~50~23~14 minecraft:stained_glass 10
fill ~51~20~14 ~51~20~15 minecraft:stained_glass 10
setblock ~51~21~14 minecraft:glowstone
setblock ~51~22~14 minecraft:stained_glass 10
setblock ~51~23~14 minecraft:glowstone
setblock ~51~24~14 minecraft:stained_glass 10
setblock ~52~21~14 minecraft:stained_glass 10
fill ~52~22~14 ~52~22~15 minecraft:stained_glass 2
fill ~45~12~15 ~55~12~17 minecraft:stone
fill ~45~13~15 ~46~14~15 minecraft:dirt 1
fill ~45~15~15 ~48~15~15 minecraft:dirt
setblock ~45~16~15 minecraft:dirt
fill ~45~17~15 ~46~17~15 minecraft:dirt 1
fill ~45~18~15 ~45~19~15 minecraft:dirt
fill ~45~20~15 ~45~24~15 minecraft:dirt 1
fill ~45~25~15 ~46~25~15 minecraft:dirt
fill ~45~26~15 ~47~26~15 minecraft:dirt 1
fill ~45~27~15 ~46~27~15 minecraft:dirt
fill ~45~28~15 ~45~28~16 minecraft:dirt 1
fill ~45~29~15 ~45~30~15 minecraft:dirt 1
fill ~45~31~15 ~46~31~15 minecraft:stained_hardened_clay 13
fill ~46~16~15 ~47~16~15 minecraft:dirt 1
fill ~46~18~15 ~48~18~15 minecraft:dirt 1
setblock ~46~19~15 minecraft:obsidian
fill ~46~24~15 ~46~24~17 minecraft:obsidian
fill ~46~28~15 ~46~28~16 minecraft:dirt
setblock ~46~29~15 minecraft:dirt
fill ~46~30~15 ~48~30~15 minecraft:dirt 1
fill ~47~13~15 ~47~14~15 minecraft:dirt
fill ~47~17~15 ~49~17~15 minecraft:dirt
fill ~47~21~15 ~47~22~15 minecraft:stained_glass 2
fill ~47~25~15 ~47~25~17 minecraft:obsidian
fill ~47~27~15 ~47~29~15 minecraft:dirt 1
fill ~47~31~15 ~47~32~15 minecraft:stained_hardened_clay 5
fill ~48~13~15 ~48~14~15 minecraft:dirt 1
setblock ~48~16~15 minecraft:dirt
setblock ~48~20~15 minecraft:stained_glass 2
fill ~48~22~15 ~51~22~15 minecraft:stained_glass 2
fill ~48~24~15 ~49~24~15 minecraft:stained_glass 10
fill ~48~26~15 ~51~26~17 minecraft:obsidian
setblock ~48~27~15 minecraft:dirt
fill ~48~28~15 ~48~29~15 minecraft:dirt 1
fill ~48~31~15 ~49~31~15 minecraft:stained_hardened_clay 13
fill ~48~32~15 ~49~32~15 minecraft:stained_hardened_clay 5
setblock ~49~13~15 minecraft:dirt
fill ~49~14~15 ~49~16~15 minecraft:dirt 1
fill ~49~18~15 ~54~18~15 minecraft:obsidian
setblock ~49~21~15 minecraft:stained_glass 10
setblock ~49~23~15 minecraft:stained_glass 10
fill ~49~27~15 ~50~27~15 minecraft:dirt 1
fill ~49~28~15 ~50~29~15 minecraft:dirt
setblock ~49~30~15 minecraft:dirt
fill ~50~13~15 ~55~13~15 minecraft:dirt 1
setblock ~50~14~15 minecraft:dirt
fill ~50~15~15 ~50~17~15 minecraft:dirt 1
fill ~50~23~15 ~50~24~15 minecraft:stained_glass 2
fill ~50~30~15 ~53~30~15 minecraft:dirt 1
fill ~50~31~15 ~52~31~15 minecraft:stained_hardened_clay 5
fill ~50~32~15 ~51~32~15 minecraft:stained_hardened_clay 13
fill ~51~14~15 ~52~14~15 minecraft:dirt 1
setblock ~51~15~15 minecraft:dirt
fill ~51~16~15 ~53~16~15 minecraft:dirt 1
fill ~51~17~15 ~53~17~15 minecraft:dirt
fill ~51~21~15 ~53~21~15 minecraft:stained_glass 2
setblock ~51~23~15 minecraft:stained_glass 10
setblock ~51~24~15 minecraft:stained_glass 2
fill ~51~27~15 ~52~27~15 minecraft:dirt
fill ~51~28~15 ~52~29~15 minecraft:dirt 1
fill ~52~15~15 ~53~15~15 minecraft:dirt 1
setblock ~52~20~15 minecraft:stained_glass 10
fill ~52~25~15 ~52~25~16 minecraft:obsidian
setblock ~52~26~15 minecraft:dirt
fill ~52~32~15 ~53~32~15 minecraft:stained_hardened_clay 5
setblock ~53~14~15 minecraft:dirt
setblock ~53~22~15 minecraft:stained_glass 10
fill ~53~24~15 ~53~24~17 minecraft:obsidian
fill ~53~25~15 ~54~25~15 minecraft:dirt 1
fill ~53~26~15 ~53~27~15 minecraft:dirt 1
setblock ~53~28~15 minecraft:dirt
fill ~53~29~15 ~55~29~15 minecraft:dirt 1
fill ~53~31~15 ~55~31~16 minecraft:stained_hardened_clay 13
setblock ~54~14~15 minecraft:dirt 1
fill ~54~15~15 ~54~16~15 minecraft:dirt
setblock ~54~17~15 minecraft:dirt 1
setblock ~54~19~15 minecraft:obsidian
fill ~54~23~15 ~54~23~18 minecraft:obsidian
setblock ~54~24~15 minecraft:dirt 1
fill ~54~26~15 ~55~27~15 minecraft:dirt
setblock ~54~28~15 minecraft:dirt 1
fill ~54~30~15 ~55~30~15 minecraft:dirt
setblock ~55~14~15 minecraft:dirt
fill ~55~15~15 ~55~16~15 minecraft:dirt 1
setblock ~55~17~15 minecraft:dirt
setblock ~55~18~15 minecraft:dirt 1
setblock ~55~19~15 minecraft:dirt
fill ~55~20~15 ~55~22~15 minecraft:obsidian
fill ~55~23~15 ~55~23~16 minecraft:dirt
fill ~55~24~15 ~55~25~15 minecraft:dirt
setblock ~55~28~15 minecraft:dirt
fill ~42~12~16 ~44~12~21 minecraft:stone
fill ~42~13~16 ~42~14~16 minecraft:dirt 1
fill ~42~15~16 ~43~15~16 minecraft:dirt
setblock ~42~16~16 minecraft:dirt 1
fill ~42~17~16 ~42~18~16 minecraft:dirt
fill ~42~19~16 ~44~19~17 minecraft:dirt 1
fill ~42~20~16 ~45~20~16 minecraft:dirt
setblock ~42~21~16 minecraft:dirt 1
fill ~42~22~16 ~44~23~16 minecraft:dirt
fill ~42~24~16 ~43~26~16 minecraft:dirt
fill ~42~27~16 ~43~28~16 minecraft:dirt 1
fill ~42~29~16 ~42~29~17 minecraft:dirt
setblock ~42~30~16 minecraft:dirt
fill ~42~31~16 ~45~31~16 minecraft:stained_hardened_clay 13
fill ~43~13~16 ~43~14~16 minecraft:dirt
setblock ~43~16~16 minecraft:dirt
fill ~43~17~16 ~44~17~16 minecraft:dirt 1
setblock ~43~18~16 minecraft:dirt 1
fill ~43~21~16 ~45~21~16 minecraft:dirt
fill ~43~29~16 ~44~30~16 minecraft:dirt 1
fill ~44~13~16 ~44~16~16 minecraft:dirt 1
setblock ~44~18~16 minecraft:dirt
fill ~44~24~16 ~45~24~16 minecraft:dirt 1
setblock ~44~25~16 minecraft:dirt
setblock ~44~26~16 minecraft:dirt 1
fill ~44~27~16 ~44~28~17 minecraft:dirt
fill ~45~19~16 ~45~19~18 minecraft:dirt
fill ~45~22~16 ~45~23~18 minecraft:obsidian
fill ~45~25~16 ~46~25~17 minecraft:obsidian
setblock ~45~26~16 minecraft:dirt
setblock ~45~27~16 minecraft:dirt 1
fill ~45~29~16 ~45~29~17 minecraft:dirt
fill ~45~30~16 ~46~30~16 minecraft:dirt 1
fill ~46~19~16 ~46~19~17 minecraft:dirt 1
fill ~46~26~16 ~47~26~17 minecraft:obsidian
setblock ~46~27~16 minecraft:dirt
fill ~46~29~16 ~47~29~16 minecraft:dirt 1
setblock ~46~31~16 minecraft:stained_hardened_clay 5
fill ~47~27~16 ~52~27~17 minecraft:obsidian
setblock ~47~30~16 minecraft:dirt
setblock ~47~31~16 minecraft:stained_hardened_clay 13
fill ~48~28~16 ~51~28~16 minecraft:obsidian
setblock ~48~29~16 minecraft:stained_hardened_clay 13
setblock ~48~30~16 minecraft:dirt 1
setblock ~48~31~16 minecraft:stained_hardened_clay 5
fill ~49~30~16 ~51~30~16 minecraft:stained_hardened_clay 13
setblock ~49~31~16 minecraft:stained_hardened_clay 13
setblock ~50~29~16 minecraft:stained_hardened_clay 5
setblock ~50~31~16 minecraft:stained_hardened_clay 5
fill ~52~26~16 ~53~26~18 minecraft:obsidian
fill ~52~30~16 ~54~30~16 minecraft:dirt
setblock ~52~31~16 minecraft:stained_hardened_clay 5
fill ~53~25~16 ~54~25~17 minecraft:obsidian
setblock ~53~27~16 minecraft:dirt
fill ~53~29~16 ~54~29~16 minecraft:dirt
fill ~54~19~16 ~58~19~16 minecraft:dirt 1
fill ~54~24~16 ~54~24~18 minecraft:obsidian
fill ~54~26~16 ~57~26~16 minecraft:dirt 1
fill ~54~27~16 ~56~27~16 minecraft:dirt 1
setblock ~54~28~16 minecraft:dirt
fill ~55~20~16 ~55~20~17 minecraft:dirt 1
setblock ~55~21~16 minecraft:dirt 1
fill ~55~22~16 ~55~22~18 minecraft:obsidian
setblock ~55~24~16 minecraft:dirt 1
setblock ~55~25~16 minecraft:dirt
fill ~55~28~16 ~55~30~16 minecraft:dirt 1
fill ~56~12~16 ~58~12~21 minecraft:stone
fill ~56~13~16 ~58~13~16 minecraft:dirt 1
setblock ~56~14~16 minecraft:dirt
setblock ~56~15~16 minecraft:dirt 1
fill ~56~16~16 ~58~17~16 minecraft:dirt
setblock ~56~18~16 minecraft:dirt 1
fill ~56~20~16 ~58~20~16 minecraft:dirt
fill ~56~21~16 ~56~22~16 minecraft:dirt
setblock ~56~23~16 minecraft:dirt 1
fill ~56~24~16 ~58~24~16 minecraft:dirt
setblock ~56~25~16 minecraft:dirt 1
fill ~56~28~16 ~58~28~17 minecraft:dirt
fill ~56~29~16 ~56~29~17 minecraft:dirt 1
setblock ~56~30~16 minecraft:dirt
fill ~56~31~16 ~58~31~16 minecraft:stained_hardened_clay 13
fill ~57~14~16 ~58~14~16 minecraft:dirt 1
fill ~57~15~16 ~58~15~16 minecraft:dirt
fill ~57~18~16 ~58~18~16 minecraft:dirt
fill ~57~21~16 ~58~22~16 minecraft:dirt 1
fill ~57~23~16 ~58~23~16 minecraft:dirt
fill ~57~25~16 ~58~25~16 minecraft:dirt
setblock ~57~27~16 minecraft:dirt
fill ~57~29~16 ~58~29~16 minecraft:dirt
fill ~57~30~16 ~57~30~17 minecraft:dirt 1
fill ~58~26~16 ~58~26~17 minecraft:dirt
setblock ~58~27~16 minecraft:dirt 1
fill ~58~30~16 ~58~30~17 minecraft:dirt
fill ~39~12~17 ~41~12~22 minecraft:stone
fill ~39~13~17 ~41~13~17 minecraft:dirt 1
fill ~39~14~17 ~39~15~17 minecraft:dirt 1
fill ~39~16~17 ~40~16~17 minecraft:dirt
fill ~39~17~17 ~39~18~17 minecraft:dirt
setblock ~39~19~17 minecraft:dirt 1
fill ~39~20~17 ~39~20~18 minecraft:dirt
fill ~39~21~17 ~40~22~17 minecraft:dirt 1
fill ~39~23~17 ~39~23~18 minecraft:dirt 1
setblock ~39~24~17 minecraft:dirt 1
fill ~39~25~17 ~41~25~17 minecraft:dirt
fill ~39~26~17 ~39~26~18 minecraft:dirt 1
setblock ~39~27~17 minecraft:dirt 1
fill ~39~28~17 ~40~29~17 minecraft:dirt
fill ~39~30~17 ~40~30~17 minecraft:dirt 1
fill ~39~31~17 ~39~31~18 minecraft:stained_hardened_clay 5
fill ~40~14~17 ~41~14~17 minecraft:dirt
setblock ~40~15~17 minecraft:dirt 1
fill ~40~17~17 ~40~18~17 minecraft:dirt 1
fill ~40~19~17 ~41~19~17 minecraft:dirt
setblock ~40~20~17 minecraft:dirt 1
fill ~40~23~17 ~41~23~17 minecraft:dirt
setblock ~40~24~17 minecraft:dirt
fill ~40~26~17 ~40~27~17 minecraft:dirt
fill ~40~31~17 ~43~31~17 minecraft:stained_hardened_clay 13
setblock ~41~15~17 minecraft:dirt
setblock ~41~16~17 minecraft:dirt 1
setblock ~41~17~17 minecraft:dirt
setblock ~41~18~17 minecraft:dirt 1
fill ~41~20~17 ~43~20~17 minecraft:dirt
fill ~41~21~17 ~42~21~17 minecraft:dirt
setblock ~41~22~17 minecraft:dirt 1
fill ~41~24~17 ~42~24~17 minecraft:dirt 1
fill ~41~26~17 ~42~26~17 minecraft:dirt 1
fill ~41~27~17 ~42~27~17 minecraft:dirt
fill ~41~28~17 ~41~29~17 minecraft:dirt 1
fill ~41~30~17 ~41~30~18 minecraft:dirt
fill ~42~22~17 ~43~22~17 minecraft:dirt
setblock ~42~23~17 minecraft:dirt 1
setblock ~42~28~17 minecraft:dirt
fill ~42~30~17 ~43~30~17 minecraft:dirt 1
fill ~43~21~17 ~44~21~17 minecraft:dirt 1
fill ~43~27~17 ~43~28~17 minecraft:dirt 1
setblock ~43~29~17 minecraft:dirt
setblock ~44~20~17 minecraft:dirt 1
fill ~44~22~17 ~44~22~18 minecraft:obsidian
fill ~44~23~17 ~44~24~17 minecraft:obsidian
setblock ~44~29~17 minecraft:dirt 1
setblock ~44~30~17 minecraft:dirt
fill ~44~31~17 ~45~31~17 minecraft:stained_hardened_clay 5
setblock ~45~20~17 minecraft:dirt
fill ~45~21~17 ~45~21~18 minecraft:obsidian
setblock ~45~24~17 minecraft:obsidian
setblock ~45~26~17 minecraft:obsidian
setblock ~45~28~17 minecraft:stained_hardened_clay 13
setblock ~45~30~17 minecraft:dirt 1
setblock ~46~27~17 minecraft:obsidian
fill ~46~29~17 ~46~31~17 minecraft:stained_hardened_clay 13
fill ~47~19~17 ~48~19~17 minecraft:obsidian
setblock ~47~30~17 minecraft:stained_hardened_clay 5
setblock ~48~30~17 minecraft:stained_hardened_clay 13
fill ~49~19~17 ~49~19~18 minecraft:planks 5
setblock ~49~28~17 minecraft:obsidian
fill ~50~19~17 ~51~19~17 minecraft:obsidian
setblock ~50~25~17 minecraft:obsidian
fill ~51~30~17 ~52~30~17 minecraft:stained_hardened_clay 5
fill ~52~19~17 ~52~19~18 minecraft:planks 5
setblock ~53~19~17 minecraft:obsidian
setblock ~53~27~17 minecraft:obsidian
fill ~53~29~17 ~54~29~17 minecraft:stained_hardened_clay 5
fill ~53~30~17 ~54~30~17 minecraft:stained_hardened_clay 13
fill ~54~19~17 ~54~19~18 minecraft:dirt 1
fill ~54~26~17 ~55~26~17 minecraft:obsidian
setblock ~54~28~17 minecraft:stained_hardened_clay 13
fill ~54~31~17 ~55~31~17 minecraft:stained_hardened_clay 13
fill ~55~19~17 ~56~19~17 minecraft:dirt
fill ~55~21~17 ~56~21~18 minecraft:obsidian
fill ~55~23~17 ~56~25~17 minecraft:obsidian
setblock ~55~29~17 minecraft:dirt 1
setblock ~55~30~17 minecraft:dirt
setblock ~56~20~17 minecraft:dirt 1
setblock ~56~22~17 minecraft:obsidian
fill ~56~27~17 ~57~27~17 minecraft:dirt 1
setblock ~56~30~17 minecraft:dirt 1
fill ~56~31~17 ~57~31~17 minecraft:stained_hardened_clay 5
setblock ~57~19~17 minecraft:dirt 1
setblock ~57~20~17 minecraft:dirt
setblock ~57~21~17 minecraft:dirt 1
setblock ~57~26~17 minecraft:dirt
setblock ~57~29~17 minecraft:dirt
setblock ~58~19~17 minecraft:dirt
fill ~58~20~17 ~59~20~17 minecraft:dirt 1
setblock ~58~21~17 minecraft:dirt
fill ~58~22~17 ~59~22~17 minecraft:dirt 1
fill ~58~24~17 ~59~24~17 minecraft:dirt
fill ~58~25~17 ~59~25~17 minecraft:dirt 1
fill ~58~27~17 ~59~27~17 minecraft:dirt
fill ~58~29~17 ~59~29~17 minecraft:dirt 1
fill ~58~31~17 ~59~31~17 minecraft:stained_hardened_clay 13
fill ~59~12~17 ~61~12~23 minecraft:stone
fill ~59~13~17 ~59~14~17 minecraft:dirt
fill ~59~15~17 ~59~16~17 minecraft:dirt 1
fill ~59~17~17 ~61~17~17 minecraft:dirt
setblock ~59~18~17 minecraft:dirt
fill ~59~19~17 ~60~19~17 minecraft:dirt 1
fill ~59~21~17 ~61~21~17 minecraft:dirt 1
setblock ~59~23~17 minecraft:dirt
setblock ~59~26~17 minecraft:dirt 1
fill ~59~28~17 ~60~28~18 minecraft:dirt 1
fill ~59~30~17 ~61~30~17 minecraft:dirt 1
fill ~60~13~17 ~61~13~17 minecraft:dirt 1
setblock ~60~14~17 minecraft:dirt 1
fill ~60~15~17 ~61~15~17 minecraft:dirt
setblock ~60~16~17 minecraft:dirt
fill ~60~18~17 ~61~18~17 minecraft:dirt 1
setblock ~60~20~17 minecraft:dirt
setblock ~60~22~17 minecraft:dirt
fill ~60~23~17 ~61~23~17 minecraft:dirt 1
setblock ~60~24~17 minecraft:dirt 1
fill ~60~25~17 ~61~25~17 minecraft:dirt
setblock ~60~26~17 minecraft:dirt
fill ~60~27~17 ~61~27~17 minecraft:dirt 1
setblock ~60~29~17 minecraft:dirt
fill ~60~31~17 ~60~31~19 minecraft:stained_hardened_clay 5
setblock ~61~14~17 minecraft:dirt
setblock ~61~16~17 minecraft:dirt 1
fill ~61~19~17 ~61~19~18 minecraft:dirt
setblock ~61~20~17 minecraft:dirt 1
setblock ~61~22~17 minecraft:dirt 1
setblock ~61~24~17 minecraft:dirt
setblock ~61~26~17 minecraft:dirt 1
setblock ~61~28~17 minecraft:dirt
setblock ~61~29~17 minecraft:dirt 1
fill ~61~31~17 ~61~31~19 minecraft:stained_hardened_clay 13
fill ~37~12~18 ~38~12~24 minecraft:stone
fill ~37~13~18 ~38~13~18 minecraft:dirt 1
setblock ~37~14~18 minecraft:dirt 1
setblock ~37~15~18 minecraft:dirt
fill ~37~16~18 ~38~17~18 minecraft:dirt 1
setblock ~37~18~18 minecraft:dirt
fill ~37~19~18 ~38~20~18 minecraft:dirt 1
fill ~37~21~18 ~39~21~18 minecraft:dirt
fill ~37~22~18 ~38~22~18 minecraft:dirt
fill ~37~23~18 ~37~24~18 minecraft:dirt 1
fill ~37~25~18 ~37~26~19 minecraft:dirt
setblock ~37~27~18 minecraft:dirt 1
fill ~37~28~18 ~38~28~19 minecraft:dirt
fill ~37~29~18 ~40~29~18 minecraft:dirt
fill ~37~30~18 ~38~30~18 minecraft:stained_hardened_clay 5
setblock ~38~14~18 minecraft:dirt
setblock ~38~15~18 minecraft:dirt 1
setblock ~38~18~18 minecraft:dirt 1
fill ~38~23~18 ~38~24~18 minecraft:dirt
setblock ~38~25~18 minecraft:dirt 1
fill ~38~26~18 ~38~27~18 minecraft:dirt
setblock ~38~31~18 minecraft:stained_hardened_clay 13
setblock ~39~19~18 minecraft:dirt
setblock ~39~22~18 minecraft:dirt 1
fill ~39~27~18 ~40~27~18 minecraft:dirt
fill ~39~28~18 ~40~28~18 minecraft:dirt 1
setblock ~39~30~18 minecraft:dirt 1
setblock ~40~19~18 minecraft:dirt 1
fill ~40~20~18 ~41~20~18 minecraft:dirt
setblock ~40~21~18 minecraft:dirt 1
setblock ~40~22~18 minecraft:leaves
setblock ~40~30~18 minecraft:dirt
setblock ~40~31~18 minecraft:stained_hardened_clay 13
fill ~41~19~18 ~42~19~18 minecraft:dirt
setblock ~41~21~18 minecraft:leaves
setblock ~41~28~18 minecraft:dirt
setblock ~41~29~18 minecraft:dirt 1
fill ~41~31~18 ~43~31~18 minecraft:stained_hardened_clay 5
setblock ~42~20~18 minecraft:dirt 1
setblock ~42~21~18 minecraft:leaves
setblock ~42~28~18 minecraft:stained_hardened_clay 5
fill ~42~29~18 ~43~29~18 minecraft:stained_hardened_clay 13
setblock ~42~30~18 minecraft:dirt
setblock ~43~19~18 minecraft:planks 5
setblock ~43~20~18 minecraft:leaves
setblock ~43~30~18 minecraft:stained_hardened_clay 5
setblock ~44~19~18 minecraft:dirt
fill ~44~20~18 ~45~20~18 minecraft:obsidian
setblock ~44~21~18 minecraft:obsidian
setblock ~44~30~18 minecraft:stained_hardened_clay 13
fill ~45~12~18 ~49~12~18 minecraft:stone
fill ~45~29~18 ~45~30~18 minecraft:stained_hardened_clay 5
setblock ~46~19~18 minecraft:dirt
setblock ~46~25~18 minecraft:obsidian
setblock ~47~19~18 minecraft:obsidian
setblock ~47~26~18 minecraft:obsidian
setblock ~48~19~18 minecraft:planks 5
setblock ~49~13~18 minecraft:stone 6
setblock ~49~14~18 minecraft:cobblestone
fill ~49~15~18 ~50~15~18 minecraft:stonebrick
fill ~49~27~18 ~50~27~18 minecraft:obsidian
setblock ~50~12~18 minecraft:stonebrick
fill ~50~13~18 ~51~13~18 minecraft:stone
setblock ~50~14~18 minecraft:stonebrick
setblock ~50~19~18 minecraft:planks 5
setblock ~51~12~18 minecraft:cobblestone
setblock ~51~14~18 minecraft:stone 5
setblock ~51~15~18 minecraft:stone
setblock ~51~19~18 minecraft:obsidian
fill ~52~12~18 ~55~12~19 minecraft:stone
fill ~53~19~18 ~53~19~19 minecraft:planks 5
fill ~54~25~18 ~55~25~18 minecraft:obsidian
setblock ~54~26~18 minecraft:obsidian
setblock ~55~19~18 minecraft:dirt 1
fill ~55~20~18 ~56~20~18 minecraft:obsidian
setblock ~55~23~18 minecraft:obsidian
fill ~55~30~18 ~56~30~18 minecraft:stained_hardened_clay 13
setblock ~56~19~18 minecraft:dirt
setblock ~56~29~18 minecraft:stained_hardened_clay 13
fill ~57~19~18 ~58~19~19 minecraft:planks 5
fill ~57~20~18 ~58~20~18 minecraft:leaves
setblock ~57~30~18 minecraft:stained_hardened_clay 5
setblock ~57~31~18 minecraft:stained_hardened_clay 13
fill ~58~21~18 ~59~21~18 minecraft:leaves
setblock ~58~30~18 minecraft:dirt 1
setblock ~58~31~18 minecraft:stained_hardened_clay 5
fill ~59~19~18 ~60~19~18 minecraft:dirt
fill ~59~20~18 ~60~20~18 minecraft:dirt 1
fill ~59~29~18 ~59~30~18 minecraft:dirt
setblock ~59~31~18 minecraft:stained_hardened_clay 13
fill ~60~21~18 ~61~21~18 minecraft:dirt
setblock ~60~22~18 minecraft:leaves
setblock ~60~27~18 minecraft:dirt
fill ~60~29~18 ~60~30~18 minecraft:dirt 1
fill ~61~20~18 ~63~20~18 minecraft:dirt
fill ~61~22~18 ~62~22~18 minecraft:dirt
fill ~61~23~18 ~63~23~18 minecraft:dirt 1
setblock ~61~26~18 minecraft:dirt
fill ~61~27~18 ~63~28~18 minecraft:dirt 1
fill ~61~29~18 ~62~29~18 minecraft:dirt
fill ~61~30~18 ~61~30~19 minecraft:dirt
fill ~62~12~18 ~63~12~24 minecraft:stone
fill ~62~13~18 ~63~13~18 minecraft:dirt
fill ~62~14~18 ~62~15~18 minecraft:dirt 1
fill ~62~16~18 ~63~18~18 minecraft:dirt
fill ~62~19~18 ~63~19~18 minecraft:dirt 1
fill ~62~21~18 ~63~21~18 minecraft:dirt 1
fill ~62~24~18 ~62~25~18 minecraft:dirt
setblock ~62~26~18 minecraft:dirt 1
fill ~62~30~18 ~62~31~18 minecraft:stained_hardened_clay 13
fill ~63~14~18 ~63~15~18 minecraft:dirt
fill ~63~22~18 ~63~22~19 minecraft:dirt 1
fill ~63~24~18 ~63~25~18 minecraft:dirt 1
setblock ~63~26~18 minecraft:dirt
setblock ~63~29~18 minecraft:dirt 1
setblock ~63~30~18 minecraft:stained_hardened_clay 5
fill ~35~12~19 ~36~12~26 minecraft:stone
fill ~35~13~19 ~36~13~19 minecraft:dirt
fill ~35~14~19 ~36~14~19 minecraft:dirt 1
fill ~35~15~19 ~35~21~19 minecraft:dirt
setblock ~35~22~19 minecraft:dirt 1
fill ~35~23~19 ~36~24~19 minecraft:dirt
fill ~35~25~19 ~36~25~19 minecraft:dirt 1
fill ~35~26~19 ~35~26~20 minecraft:dirt
fill ~35~27~19 ~35~27~20 minecraft:dirt 1
fill ~35~28~19 ~35~29~19 minecraft:dirt 1
setblock ~35~30~19 minecraft:stained_hardened_clay 13
fill ~36~15~19 ~36~16~19 minecraft:dirt 1
setblock ~36~17~19 minecraft:dirt
setblock ~36~18~19 minecraft:dirt 1
fill ~36~19~19 ~37~19~20 minecraft:dirt
fill ~36~20~19 ~36~20~20 minecraft:dirt
fill ~36~21~19 ~36~22~19 minecraft:dirt
setblock ~36~26~19 minecraft:dirt 1
fill ~36~27~19 ~38~27~19 minecraft:dirt
fill ~36~28~19 ~36~29~19 minecraft:dirt
setblock ~36~30~19 minecraft:stained_hardened_clay 5
fill ~37~20~19 ~37~22~19 minecraft:dirt 1
fill ~37~29~19 ~37~29~20 minecraft:dirt 1
fill ~37~30~19 ~38~30~20 minecraft:stained_hardened_clay 13
setblock ~38~19~19 minecraft:dirt 1
setblock ~38~20~19 minecraft:dirt
setblock ~38~21~19 minecraft:dirt 1
setblock ~38~22~19 minecraft:leaves
setblock ~38~26~19 minecraft:dirt 1
fill ~38~29~19 ~39~29~19 minecraft:dirt
fill ~39~19~19 ~40~19~19 minecraft:planks 1
fill ~39~20~19 ~42~20~19 minecraft:leaves
setblock ~39~21~19 minecraft:leaves
setblock ~39~28~19 minecraft:dirt 1
setblock ~39~30~19 minecraft:dirt
setblock ~39~31~19 minecraft:stained_hardened_clay 13
setblock ~40~21~19 minecraft:leaves
setblock ~40~28~19 minecraft:stained_hardened_clay 5
fill ~40~29~19 ~41~29~19 minecraft:stained_hardened_clay 13
setblock ~40~30~19 minecraft:stained_hardened_clay 5
fill ~41~19~19 ~42~19~19 minecraft:planks 5
setblock ~41~30~19 minecraft:stained_hardened_clay 13
setblock ~42~30~19 minecraft:stained_hardened_clay 5
setblock ~43~19~19 minecraft:planks 1
fill ~44~19~19 ~45~19~22 minecraft:planks 5
fill ~45~12~19 ~47~12~21 minecraft:stone
setblock ~46~19~19 minecraft:planks 1
fill ~47~19~19 ~47~19~20 minecraft:planks 5
setblock ~48~12~19 minecraft:stonebrick
fill ~48~13~19 ~48~14~19 minecraft:stone
fill ~48~15~19 ~49~15~19 minecraft:cobblestone
fill ~48~19~19 ~50~19~19 minecraft:planks 1
setblock ~49~11~19 minecraft:stonebrick
setblock ~49~12~19 minecraft:stone_block_slab 4
setblock ~49~13~19 minecraft:air
setblock ~49~14~19 minecraft:stone_brick_stairs 5
setblock ~50~11~19 minecraft:stone 5
fill ~50~12~19 ~51~12~19 minecraft:brick_block
fill ~50~13~19 ~51~13~19 minecraft:skull 1
setblock ~50~15~19 minecraft:stone 5
setblock ~50~20~19 minecraft:light_weighted_pressure_plate
setblock ~51~11~19 minecraft:stonebrick
setblock ~51~15~19 minecraft:cobblestone
fill ~51~19~19 ~51~19~21 minecraft:planks 5
setblock ~52~13~19 minecraft:stonebrick
fill ~52~14~19 ~52~15~19 minecraft:stone 5
setblock ~52~19~19 minecraft:planks 1
fill ~54~19~19 ~56~19~20 minecraft:planks 5
setblock ~58~30~19 minecraft:stained_hardened_clay 5
fill ~59~19~19 ~61~19~19 minecraft:planks 5
fill ~59~20~19 ~61~20~19 minecraft:leaves
setblock ~59~29~19 minecraft:stained_hardened_clay 5
setblock ~59~30~19 minecraft:stained_hardened_clay 13
fill ~60~21~19 ~61~21~19 minecraft:leaves
setblock ~60~30~19 minecraft:stained_hardened_clay 5
setblock ~61~29~19 minecraft:dirt 1
fill ~62~19~19 ~65~19~19 minecraft:dirt
fill ~62~20~19 ~64~20~19 minecraft:dirt 1
setblock ~62~21~19 minecraft:leaves
setblock ~62~22~19 minecraft:leaves
setblock ~62~28~19 minecraft:dirt 1
fill ~62~29~19 ~63~29~19 minecraft:dirt
setblock ~62~30~19 minecraft:stained_hardened_clay 5
fill ~63~21~19 ~64~21~19 minecraft:dirt
fill ~63~25~19 ~63~26~19 minecraft:dirt 1
fill ~63~27~19 ~65~27~19 minecraft:dirt
setblock ~63~28~19 minecraft:dirt
setblock ~63~30~19 minecraft:stained_hardened_clay 13
fill ~64~12~19 ~65~12~24 minecraft:stone
fill ~64~13~19 ~65~14~19 minecraft:dirt 1
fill ~64~15~19 ~64~16~19 minecraft:dirt
fill ~64~17~19 ~65~17~19 minecraft:dirt 1
setblock ~64~18~19 minecraft:dirt 1
fill ~64~22~19 ~65~22~19 minecraft:dirt 1
fill ~64~23~19 ~65~23~19 minecraft:dirt
fill ~64~24~19 ~65~24~19 minecraft:dirt 1
fill ~64~25~19 ~65~25~19 minecraft:dirt
setblock ~64~26~19 minecraft:dirt 1
fill ~64~28~19 ~65~29~19 minecraft:dirt 1
fill ~64~30~19 ~64~30~20 minecraft:stained_hardened_clay 5
setblock ~65~15~19 minecraft:dirt 1
setblock ~65~16~19 minecraft:dirt
setblock ~65~18~19 minecraft:dirt
setblock ~65~20~19 minecraft:dirt
setblock ~65~21~19 minecraft:dirt 1
fill ~65~26~19 ~65~26~20 minecraft:dirt
fill ~65~30~19 ~65~30~20 minecraft:stained_hardened_clay 13
fill ~34~12~20 ~34~12~28 minecraft:stone
setblock ~34~13~20 minecraft:dirt
fill ~34~14~20 ~34~16~20 minecraft:dirt 1
fill ~34~17~20 ~34~18~20 minecraft:dirt
setblock ~34~19~20 minecraft:dirt 1
fill ~34~20~20 ~34~20~21 minecraft:dirt
fill ~34~21~20 ~35~21~20 minecraft:dirt 1
fill ~34~22~20 ~34~22~21 minecraft:dirt 1
setblock ~34~23~20 minecraft:dirt 1
fill ~34~24~20 ~34~28~20 minecraft:dirt
fill ~34~29~20 ~35~29~21 minecraft:dirt 1
setblock ~34~30~20 minecraft:stained_hardened_clay 13
setblock ~35~19~20 minecraft:dirt
setblock ~35~20~20 minecraft:dirt 1
fill ~35~22~20 ~35~23~20 minecraft:dirt
fill ~35~24~20 ~35~25~20 minecraft:dirt 1
fill ~35~28~20 ~35~28~21 minecraft:dirt
setblock ~35~30~20 minecraft:stained_hardened_clay 5
setblock ~36~21~20 minecraft:stained_hardened_clay 5
setblock ~36~22~20 minecraft:leaves
fill ~36~26~20 ~36~27~20 minecraft:dirt
fill ~36~28~20 ~37~28~20 minecraft:dirt 1
fill ~36~29~20 ~36~29~21 minecraft:dirt
setblock ~36~30~20 minecraft:stained_hardened_clay 13
setblock ~37~20~20 minecraft:grass
fill ~37~21~20 ~38~21~20 minecraft:leaves
setblock ~37~27~20 minecraft:dirt
fill ~38~19~20 ~41~19~21 minecraft:planks 5
setblock ~38~20~20 minecraft:leaves
setblock ~38~29~20 minecraft:dirt 1
setblock ~39~29~20 minecraft:stained_hardened_clay 13
setblock ~39~30~20 minecraft:stained_hardened_clay 5
setblock ~40~30~20 minecraft:stained_hardened_clay 13
setblock ~42~19~20 minecraft:planks 1
setblock ~43~19~20 minecraft:planks 5
setblock ~46~19~20 minecraft:planks 5
setblock ~47~13~20 minecraft:stonebrick
fill ~47~14~20 ~47~14~22 minecraft:stone 5
setblock ~48~11~20 minecraft:stone
setblock ~48~12~20 minecraft:stone_brick_stairs 3
setblock ~48~13~20 minecraft:redstone_torch
setblock ~48~14~20 minecraft:stone_brick_stairs 7
setblock ~48~15~20 minecraft:stonebrick
fill ~48~19~20 ~50~19~20 minecraft:planks 5
fill ~49~11~20 ~49~11~22 minecraft:stone 5
setblock ~49~12~20 minecraft:air
setblock ~49~15~20 minecraft:stone 5
setblock ~50~11~20 minecraft:stone_block_slab 11
setblock ~50~12~20 minecraft:skull 1
setblock ~50~15~20 minecraft:stone 6
setblock ~51~11~20 minecraft:double_stone_block_slab
setblock ~51~12~20 minecraft:stone_block_slab 4
setblock ~51~15~20 minecraft:stonebrick
setblock ~52~12~20 minecraft:stonebrick
fill ~52~13~20 ~52~14~20 minecraft:cobblestone
setblock ~52~15~20 minecraft:stone
setblock ~52~19~20 minecraft:planks 5
fill ~53~12~20 ~55~12~20 minecraft:stone
setblock ~53~19~20 minecraft:planks 1
fill ~57~19~20 ~57~19~22 minecraft:planks 5
setblock ~58~19~20 minecraft:planks 1
fill ~59~19~20 ~59~19~21 minecraft:planks 5
setblock ~60~19~20 minecraft:planks 1
fill ~61~19~20 ~62~19~21 minecraft:planks 5
setblock ~61~30~20 minecraft:stained_hardened_clay 5
fill ~62~20~20 ~62~20~21 minecraft:fence 5
fill ~62~29~20 ~63~29~20 minecraft:stained_hardened_clay 13
fill ~63~19~20 ~63~19~22 minecraft:stained_hardened_clay 5
setblock ~63~20~20 minecraft:leaves
setblock ~63~28~20 minecraft:stained_hardened_clay 5
setblock ~63~30~20 minecraft:stained_hardened_clay 5
fill ~64~19~20 ~64~20~20 minecraft:dirt
setblock ~64~21~20 minecraft:dirt 1
fill ~64~28~20 ~64~29~20 minecraft:dirt 1
fill ~65~19~20 ~66~19~20 minecraft:dirt 1
setblock ~65~20~20 minecraft:dirt 1
setblock ~65~21~20 minecraft:dirt
fill ~65~22~20 ~66~22~20 minecraft:dirt 1
fill ~65~27~20 ~65~28~20 minecraft:dirt
fill ~65~29~20 ~65~29~21 minecraft:dirt 1
fill ~66~12~20 ~66~12~24 minecraft:stone
setblock ~66~13~20 minecraft:dirt 1
setblock ~66~14~20 minecraft:dirt
fill ~66~15~20 ~66~16~20 minecraft:dirt 1
fill ~66~17~20 ~66~18~20 minecraft:dirt
fill ~66~20~20 ~66~20~21 minecraft:dirt
fill ~66~21~20 ~66~21~21 minecraft:dirt 1
fill ~66~23~20 ~66~25~20 minecraft:dirt 1
setblock ~66~26~20 minecraft:dirt
fill ~66~27~20 ~66~27~21 minecraft:dirt 1
fill ~66~28~20 ~66~29~20 minecraft:dirt
setblock ~66~30~20 minecraft:stained_hardened_clay 5
fill ~32~12~21 ~33~12~30 minecraft:stone
fill ~32~13~21 ~32~14~21 minecraft:dirt 1
setblock ~32~15~21 minecraft:dirt
fill ~32~16~21 ~32~17~21 minecraft:dirt 1
fill ~32~18~21 ~32~20~21 minecraft:dirt
fill ~32~21~21 ~33~21~21 minecraft:dirt 1
fill ~32~22~21 ~32~23~21 minecraft:dirt 1
fill ~32~24~21 ~33~25~21 minecraft:dirt
fill ~32~26~21 ~33~26~21 minecraft:dirt 1
fill ~32~27~21 ~33~28~21 minecraft:dirt
fill ~32~29~21 ~32~29~22 minecraft:dirt 1
fill ~32~30~21 ~32~30~23 minecraft:stained_hardened_clay 5
fill ~33~13~21 ~33~14~21 minecraft:dirt
setblock ~33~15~21 minecraft:dirt 1
fill ~33~16~21 ~33~17~21 minecraft:dirt
fill ~33~18~21 ~33~19~21 minecraft:dirt 1
setblock ~33~20~21 minecraft:dirt
setblock ~33~22~21 minecraft:dirt
setblock ~33~23~21 minecraft:dirt 1
setblock ~33~29~21 minecraft:dirt
setblock ~33~30~21 minecraft:stained_hardened_clay 13
setblock ~34~19~21 minecraft:dirt
setblock ~34~21~21 minecraft:dirt
setblock ~34~25~21 minecraft:dirt 1
setblock ~34~26~21 minecraft:dirt
setblock ~34~27~21 minecraft:dirt 1
setblock ~34~28~21 minecraft:dirt
setblock ~34~30~21 minecraft:stained_hardened_clay 5
fill ~35~19~21 ~36~19~21 minecraft:grass
fill ~35~20~21 ~37~20~21 minecraft:leaves
setblock ~35~27~21 minecraft:dirt
setblock ~35~30~21 minecraft:stained_hardened_clay 13
setblock ~36~21~21 minecraft:leaves
setblock ~36~30~21 minecraft:stained_hardened_clay 5
fill ~37~19~21 ~37~19~22 minecraft:stained_hardened_clay 5
setblock ~37~28~21 minecraft:stained_hardened_clay 13
fill ~37~29~21 ~38~29~21 minecraft:stained_hardened_clay 5
fill ~42~19~21 ~42~19~28 minecraft:planks 5
setblock ~43~19~21 minecraft:planks 1
fill ~46~19~21 ~47~19~21 minecraft:planks 1
setblock ~47~13~21 minecraft:stone 6
fill ~47~15~21 ~48~15~21 minecraft:stone 6
fill ~48~11~21 ~48~11~22 minecraft:stone 5
fill ~48~19~21 ~49~19~22 minecraft:planks 5
fill ~49~15~21 ~51~15~21 minecraft:stone
fill ~50~10~21 ~51~10~21 minecraft:cobblestone
setblock ~50~11~21 minecraft:stone
fill ~50~12~21 ~51~12~21 minecraft:iron_bars
fill ~50~14~21 ~51~14~21 minecraft:iron_bars
setblock ~50~19~21 minecraft:planks 1
fill ~51~5~21 ~51~6~21 minecraft:stonebrick
setblock ~51~7~21 minecraft:cobblestone
fill ~51~8~21 ~51~9~21 minecraft:stone 5
setblock ~51~11~21 minecraft:stonebrick
setblock ~51~13~21 minecraft:iron_bars
setblock ~52~11~21 minecraft:stone 6
setblock ~52~12~21 minecraft:stone
setblock ~52~13~21 minecraft:stonebrick
setblock ~52~14~21 minecraft:stone 5
setblock ~52~15~21 minecraft:cobblestone
setblock ~52~19~21 minecraft:planks 1
setblock ~53~12~21 minecraft:stone 6
setblock ~53~13~21 minecraft:stone 5
fill ~53~19~21 ~53~19~26 minecraft:planks 5
fill ~54~12~21 ~54~12~22 minecraft:stone 5
fill ~54~19~21 ~56~19~21 minecraft:planks 1
fill ~55~12~21 ~55~12~22 minecraft:grass
fill ~58~19~21 ~58~19~22 minecraft:planks 5
fill ~60~19~21 ~60~19~25 minecraft:planks 5
fill ~61~20~21 ~61~20~22 minecraft:fence 5
setblock ~61~21~21 minecraft:torch
fill ~64~19~21 ~64~19~22 minecraft:grass
setblock ~64~20~21 minecraft:leaves
setblock ~64~29~21 minecraft:stained_hardened_clay 5
setblock ~65~19~21 minecraft:stained_hardened_clay 5
fill ~65~20~21 ~65~21~21 minecraft:leaves
setblock ~65~30~21 minecraft:stained_hardened_clay 5
setblock ~66~19~21 minecraft:dirt
fill ~66~28~21 ~66~29~21 minecraft:dirt 1
setblock ~66~30~21 minecraft:stained_hardened_clay 13
fill ~67~12~21 ~68~12~24 minecraft:stone
fill ~67~13~21 ~67~16~21 minecraft:dirt 1
fill ~67~17~21 ~67~18~21 minecraft:dirt
fill ~67~19~21 ~68~19~21 minecraft:dirt 1
fill ~67~20~21 ~68~20~21 minecraft:dirt
fill ~67~21~21 ~68~21~21 minecraft:dirt 1
setblock ~67~22~21 minecraft:dirt
fill ~67~23~21 ~68~23~21 minecraft:dirt 1
setblock ~67~24~21 minecraft:dirt
fill ~67~25~21 ~68~26~21 minecraft:dirt 1
fill ~67~27~21 ~67~29~21 minecraft:dirt
fill ~67~30~21 ~68~30~22 minecraft:stained_hardened_clay 5
fill ~68~13~21 ~68~14~21 minecraft:dirt
fill ~68~15~21 ~68~17~21 minecraft:dirt 1
setblock ~68~18~21 minecraft:dirt
setblock ~68~22~21 minecraft:dirt 1
setblock ~68~24~21 minecraft:dirt 1
fill ~68~27~21 ~68~28~21 minecraft:dirt 1
setblock ~68~29~21 minecraft:dirt
fill ~31~12~22 ~31~12~38 minecraft:stone
setblock ~31~13~22 minecraft:dirt 1
fill ~31~14~22 ~31~15~22 minecraft:dirt
fill ~31~16~22 ~31~18~22 minecraft:dirt 1
fill ~31~19~22 ~33~19~22 minecraft:dirt
fill ~31~20~22 ~31~20~23 minecraft:dirt
fill ~31~21~22 ~32~21~22 minecraft:dirt 1
setblock ~31~22~22 minecraft:dirt
fill ~31~23~22 ~31~28~22 minecraft:dirt 1
setblock ~31~29~22 minecraft:stained_hardened_clay 13
setblock ~31~30~22 minecraft:stained_hardened_clay 5
fill ~32~20~22 ~33~20~22 minecraft:dirt 1
fill ~32~24~22 ~32~25~22 minecraft:dirt
fill ~32~26~22 ~32~28~22 minecraft:dirt 1
setblock ~33~21~22 minecraft:leaves
setblock ~33~26~22 minecraft:dirt
fill ~33~27~22 ~33~29~22 minecraft:dirt 1
setblock ~33~30~22 minecraft:stained_hardened_clay 5
setblock ~34~19~22 minecraft:grass
setblock ~34~20~22 minecraft:leaves
fill ~34~26~22 ~34~27~22 minecraft:stained_hardened_clay 13
setblock ~34~28~22 minecraft:stained_hardened_clay 5
setblock ~34~29~22 minecraft:dirt 1
setblock ~34~30~22 minecraft:stained_hardened_clay 13
setblock ~35~19~22 minecraft:stained_hardened_clay 5
fill ~35~28~22 ~35~29~22 minecraft:stained_hardened_clay 13
fill ~36~19~22 ~36~19~23 minecraft:grass
setblock ~36~20~22 minecraft:tallgrass
setblock ~36~29~22 minecraft:stained_hardened_clay 5
setblock ~38~19~22 minecraft:grass
fill ~39~19~22 ~40~19~22 minecraft:planks 5
fill ~39~20~22 ~39~20~24 minecraft:fence 5
setblock ~41~19~22 minecraft:planks 1
fill ~42~12~22 ~43~12~22 minecraft:stained_hardened_clay 5
fill ~43~19~22 ~43~19~24 minecraft:planks 5
fill ~44~12~22 ~45~12~22 minecraft:grass
setblock ~46~12~22 minecraft:stained_hardened_clay 5
fill ~46~19~22 ~47~19~22 minecraft:planks 5
fill ~47~12~22 ~47~12~23 minecraft:stone 5
setblock ~47~13~22 minecraft:stone 5
setblock ~47~15~22 minecraft:cobblestone
setblock ~48~3~22 minecraft:stone
fill ~48~4~22 ~52~4~26 minecraft:wool 13
setblock ~48~5~22 minecraft:stone 5
setblock ~48~6~22 minecraft:stone
setblock ~48~7~22 minecraft:stone 5
fill ~48~8~22 ~48~9~22 minecraft:cobblestone
setblock ~48~10~22 minecraft:stone 5
fill ~48~12~22 ~49~13~22 minecraft:iron_bars
setblock ~48~14~22 minecraft:iron_bars
fill ~48~15~22 ~48~15~23 minecraft:stone
setblock ~49~3~22 minecraft:cobblestone
fill ~49~5~22 ~49~7~22 minecraft:stonebrick
setblock ~49~8~22 minecraft:stone
setblock ~49~9~22 minecraft:stone 5
setblock ~49~10~22 minecraft:stone 6
setblock ~49~15~22 minecraft:stone 5
setblock ~50~3~22 minecraft:stonebrick
fill ~50~5~22 ~50~6~22 minecraft:stone
fill ~50~7~22 ~50~9~22 minecraft:stonebrick
setblock ~50~10~22 minecraft:cobblestone
setblock ~50~11~22 minecraft:stone_block_slab 4
setblock ~50~14~22 minecraft:iron_bars
fill ~50~15~22 ~50~15~23 minecraft:cobblestone
fill ~50~19~22 ~50~19~25 minecraft:planks 5
setblock ~51~3~22 minecraft:stained_glass 5
fill ~51~5~22 ~51~5~26 minecraft:stained_glass 13
fill ~51~6~22 ~51~7~23 minecraft:stained_glass 13
setblock ~51~8~22 minecraft:stained_glass 5
fill ~51~9~22 ~51~9~23 minecraft:stained_glass 13
setblock ~51~10~22 minecraft:stained_glass 13
setblock ~51~15~22 minecraft:stone 5
fill ~51~19~22 ~51~19~23 minecraft:planks 1
setblock ~52~3~22 minecraft:stone 6
setblock ~52~5~22 minecraft:stone 5
fill ~52~6~22 ~52~7~22 minecraft:stonebrick
setblock ~52~8~22 minecraft:cobblestone
setblock ~52~9~22 minecraft:stone 6
fill ~52~10~22 ~52~11~22 minecraft:stone 5
setblock ~52~12~22 minecraft:skull 1
setblock ~52~13~22 minecraft:stone 6
setblock ~52~14~22 minecraft:stone
fill ~52~19~22 ~52~19~23 minecraft:planks 5
fill ~53~10~22 ~53~11~22 minecraft:stone
setblock ~53~12~22 minecraft:cobblestone
setblock ~53~13~22 minecraft:stone
setblock ~53~14~22 minecraft:stone 6
fill ~54~13~22 ~54~13~23 minecraft:cobblestone
fill ~54~19~22 ~56~19~22 minecraft:planks 5
fill ~56~12~22 ~57~12~22 minecraft:stained_hardened_clay 5
setblock ~58~12~22 minecraft:stone
setblock ~59~19~22 minecraft:planks 1
fill ~61~19~22 ~61~19~23 minecraft:planks 5
setblock ~62~19~22 minecraft:stained_hardened_clay 5
fill ~65~19~22 ~65~19~23 minecraft:grass
fill ~65~29~22 ~68~29~22 minecraft:stained_hardened_clay 13
fill ~66~19~22 ~67~19~22 minecraft:stained_hardened_clay 5
fill ~66~20~22 ~67~20~22 minecraft:leaves
setblock ~66~28~22 minecraft:stained_hardened_clay 5
setblock ~67~18~22 minecraft:dirt
fill ~67~21~22 ~68~21~22 minecraft:leaves
fill ~68~18~22 ~68~19~22 minecraft:dirt 1
setblock ~68~20~22 minecraft:stained_hardened_clay 5
fill ~68~26~22 ~69~26~22 minecraft:dirt 1
fill ~68~27~22 ~68~28~22 minecraft:dirt
fill ~69~12~22 ~69~12~25 minecraft:stone
fill ~69~13~22 ~69~14~22 minecraft:dirt 1
fill ~69~15~22 ~69~20~22 minecraft:dirt
fill ~69~21~22 ~69~21~23 minecraft:dirt 1
setblock ~69~22~22 minecraft:dirt 1
fill ~69~23~22 ~69~24~22 minecraft:dirt
setblock ~69~25~22 minecraft:dirt 1
setblock ~69~27~22 minecraft:dirt 1
fill ~69~28~22 ~69~28~24 minecraft:dirt
fill ~69~29~22 ~69~29~23 minecraft:stained_hardened_clay 5
setblock ~69~30~22 minecraft:stained_hardened_clay 5
fill ~30~12~23 ~30~12~39 minecraft:stone
setblock ~30~13~23 minecraft:dirt
fill ~30~14~23 ~30~15~23 minecraft:dirt 1
setblock ~30~16~23 minecraft:dirt
fill ~30~17~23 ~30~19~23 minecraft:dirt 1
fill ~30~20~23 ~30~21~23 minecraft:dirt
setblock ~30~22~23 minecraft:dirt 1
fill ~30~23~23 ~30~24~23 minecraft:dirt
fill ~30~25~23 ~30~26~23 minecraft:dirt 1
fill ~30~27~23 ~30~28~24 minecraft:dirt
fill ~30~29~23 ~30~29~24 minecraft:stained_hardened_clay 13
setblock ~31~19~23 minecraft:dirt
setblock ~31~21~23 minecraft:stained_hardened_clay 5
setblock ~31~22~23 minecraft:leaves
fill ~31~26~23 ~31~27~23 minecraft:dirt 1
setblock ~31~28~23 minecraft:dirt
fill ~31~29~23 ~31~29~24 minecraft:stained_hardened_clay 5
fill ~32~19~23 ~32~19~24 minecraft:stained_hardened_clay 5
fill ~32~20~23 ~33~20~23 minecraft:leaves
setblock ~32~27~23 minecraft:stained_hardened_clay 13
setblock ~32~28~23 minecraft:dirt 1
setblock ~32~29~23 minecraft:dirt
fill ~33~19~23 ~33~19~24 minecraft:grass
fill ~33~28~23 ~33~29~23 minecraft:stained_hardened_clay 5
setblock ~34~19~23 minecraft:stained_hardened_clay 5
setblock ~34~29~23 minecraft:stained_hardened_clay 5
fill ~35~19~23 ~35~19~24 minecraft:grass
setblock ~35~20~23 minecraft:tallgrass
setblock ~36~20~23 minecraft:red_flower
fill ~37~19~23 ~37~19~24 minecraft:grass
setblock ~37~20~23 minecraft:tallgrass
fill ~38~19~23 ~38~19~24 minecraft:stained_hardened_clay 5
setblock ~39~12~23 minecraft:stone
fill ~39~19~23 ~39~19~24 minecraft:planks 5
setblock ~39~21~23 minecraft:torch
fill ~40~12~23 ~40~12~27 minecraft:grass
setblock ~40~19~23 minecraft:planks 1
setblock ~41~12~23 minecraft:stained_hardened_clay 5
setblock ~41~19~23 minecraft:planks 5
fill ~42~12~23 ~43~12~23 minecraft:grass
fill ~44~12~23 ~45~12~23 minecraft:stained_hardened_clay 5
setblock ~44~19~23 minecraft:planks 1
setblock ~45~19~23 minecraft:planks 5
fill ~46~12~23 ~46~12~24 minecraft:dirt 1
fill ~46~13~23 ~47~13~23 minecraft:cobblestone
setblock ~46~14~23 minecraft:stone
setblock ~46~19~23 minecraft:planks 1
setblock ~47~3~23 minecraft:stone
fill ~47~4~23 ~47~4~25 minecraft:wool 13
setblock ~47~5~23 minecraft:stone 5
setblock ~47~6~23 minecraft:cobblestone
fill ~47~7~23 ~47~9~23 minecraft:stone 6
setblock ~47~10~23 minecraft:stonebrick
fill ~47~11~23 ~47~11~24 minecraft:cobblestone
setblock ~47~14~23 minecraft:cobblestone
setblock ~47~15~23 minecraft:stone
fill ~47~19~23 ~48~19~23 minecraft:planks 5
fill ~48~3~23 ~48~3~24 minecraft:stained_glass 13
fill ~48~5~23 ~48~7~24 minecraft:stained_glass 5
fill ~48~8~23 ~48~8~25 minecraft:stained_glass 13
fill ~48~9~23 ~48~10~23 minecraft:stained_glass 5
setblock ~48~11~23 minecraft:stone_block_slab 4
setblock ~49~3~23 minecraft:stained_glass 5
fill ~49~5~23 ~50~6~24 minecraft:stained_glass 13
fill ~49~7~23 ~49~8~24 minecraft:stained_glass 5
fill ~49~9~23 ~50~9~23 minecraft:stained_glass 13
fill ~49~10~23 ~49~10~26 minecraft:stained_glass 5
setblock ~49~15~23 minecraft:cobblestone
setblock ~49~19~23 minecraft:planks 1
fill ~50~3~23 ~52~3~23 minecraft:stained_glass 13
setblock ~50~8~23 minecraft:stained_glass 5
setblock ~50~10~23 minecraft:stained_glass 13
fill ~51~8~23 ~52~8~24 minecraft:stained_glass 13
fill ~51~10~23 ~52~10~23 minecraft:stained_glass 5
setblock ~51~15~23 minecraft:stone
setblock ~52~5~23 minecraft:stained_glass 13
setblock ~52~6~23 minecraft:stained_glass 5
fill ~52~7~23 ~52~7~24 minecraft:stained_glass 13
fill ~52~9~23 ~52~9~24 minecraft:stained_glass 13
setblock ~52~14~23 minecraft:stonebrick
fill ~52~15~23 ~52~15~24 minecraft:stone 6
setblock ~53~3~23 minecraft:stone 5
fill ~53~4~23 ~53~4~25 minecraft:wool 13
setblock ~53~5~23 minecraft:stonebrick
setblock ~53~6~23 minecraft:cobblestone
setblock ~53~7~23 minecraft:stonebrick
setblock ~53~8~23 minecraft:cobblestone
setblock ~53~9~23 minecraft:stone 6
setblock ~53~10~23 minecraft:cobblestone
setblock ~53~11~23 minecraft:stone
setblock ~53~12~23 minecraft:log2
setblock ~53~13~23 minecraft:stone 6
setblock ~53~14~23 minecraft:log2
setblock ~54~11~23 minecraft:cobblestone
setblock ~54~12~23 minecraft:stone 6
setblock ~54~14~23 minecraft:cobblestone
fill ~54~19~23 ~55~19~23 minecraft:planks 1
setblock ~55~12~23 minecraft:stained_hardened_clay 5
setblock ~55~14~23 minecraft:stone
fill ~56~12~23 ~58~12~23 minecraft:grass
fill ~56~19~23 ~56~19~24 minecraft:planks 5
fill ~57~19~23 ~58~19~23 minecraft:planks 1
fill ~59~19~23 ~59~19~27 minecraft:planks 5
fill ~62~19~23 ~63~19~23 minecraft:grass
setblock ~62~20~23 minecraft:red_flower
setblock ~64~19~23 minecraft:stained_hardened_clay 5
setblock ~65~20~23 minecraft:vine
fill ~66~18~23 ~67~18~23 minecraft:dirt 1
setblock ~66~19~23 minecraft:grass
setblock ~66~20~23 minecraft:tallgrass
fill ~67~19~23 ~68~19~23 minecraft:stained_hardened_clay 5
fill ~68~18~23 ~69~18~23 minecraft:dirt
setblock ~68~20~23 minecraft:leaves
setblock ~68~27~23 minecraft:stained_hardened_clay 13
setblock ~68~28~23 minecraft:stained_hardened_clay 5
setblock ~68~29~23 minecraft:stained_hardened_clay 13
fill ~69~19~23 ~69~20~23 minecraft:dirt 1
setblock ~69~22~23 minecraft:leaves
setblock ~69~25~23 minecraft:dirt
fill ~69~26~23 ~70~26~23 minecraft:dirt 1
setblock ~69~27~23 minecraft:dirt
setblock ~69~30~23 minecraft:stained_hardened_clay 13
fill ~70~12~23 ~70~12~25 minecraft:stone
setblock ~70~13~23 minecraft:dirt 1
setblock ~70~14~23 minecraft:dirt
setblock ~70~15~23 minecraft:dirt 1
setblock ~70~16~23 minecraft:dirt
fill ~70~17~23 ~70~18~23 minecraft:dirt 1
setblock ~70~19~23 minecraft:dirt
fill ~70~20~23 ~70~20~24 minecraft:dirt 1
setblock ~70~21~23 minecraft:dirt 1
fill ~70~22~23 ~70~24~23 minecraft:dirt
setblock ~70~25~23 minecraft:dirt 1
fill ~70~27~23 ~70~27~25 minecraft:dirt 1
setblock ~70~28~23 minecraft:dirt
fill ~70~29~23 ~70~29~25 minecraft:stained_hardened_clay 5
fill ~29~12~24 ~29~12~39 minecraft:stone
fill ~29~13~24 ~29~15~24 minecraft:dirt
fill ~29~16~24 ~29~18~24 minecraft:dirt 1
setblock ~29~19~24 minecraft:dirt
fill ~29~20~24 ~29~20~25 minecraft:dirt 1
fill ~29~21~24 ~29~21~25 minecraft:dirt
fill ~29~22~24 ~29~25~24 minecraft:dirt
setblock ~29~26~24 minecraft:dirt 1
fill ~29~27~24 ~29~28~24 minecraft:dirt
setblock ~29~29~24 minecraft:stained_hardened_clay 13
setblock ~30~19~24 minecraft:dirt 1
setblock ~30~20~24 minecraft:grass
fill ~30~21~24 ~31~21~24 minecraft:leaves
setblock ~30~22~24 minecraft:leaves
setblock ~30~26~24 minecraft:dirt
setblock ~31~19~24 minecraft:grass
fill ~31~20~24 ~32~20~24 minecraft:leaves
fill ~31~26~24 ~31~27~24 minecraft:stained_hardened_clay 5
setblock ~31~28~24 minecraft:dirt 1
fill ~32~28~24 ~32~29~24 minecraft:stained_hardened_clay 13
setblock ~33~20~24 minecraft:red_flower
fill ~34~19~24 ~34~19~25 minecraft:grass
setblock ~36~19~24 minecraft:stained_hardened_clay 5
fill ~39~12~24 ~39~12~25 minecraft:stained_hardened_clay 5
fill ~40~19~24 ~40~19~26 minecraft:planks 5
fill ~41~12~24 ~41~12~26 minecraft:grass
setblock ~41~19~24 minecraft:planks 1
fill ~42~12~24 ~42~12~27 minecraft:stained_hardened_clay 5
fill ~43~12~24 ~45~12~24 minecraft:grass
fill ~44~19~24 ~44~19~26 minecraft:planks 5
setblock ~45~19~24 minecraft:planks 1
setblock ~46~13~24 minecraft:stone 5
fill ~46~14~24 ~46~15~24 minecraft:stone 6
fill ~46~19~24 ~47~19~26 minecraft:planks 5
setblock ~47~3~24 minecraft:stone 6
setblock ~47~5~24 minecraft:stone 6
fill ~47~6~24 ~47~7~24 minecraft:stonebrick
setblock ~47~8~24 minecraft:stone
fill ~47~9~24 ~47~9~25 minecraft:stone 5
setblock ~47~10~24 minecraft:stone 5
setblock ~47~12~24 minecraft:stonebrick
setblock ~47~13~24 minecraft:stone_stairs 3
setblock ~47~14~24 minecraft:web
setblock ~47~15~24 minecraft:stone 5
fill ~48~9~24 ~49~9~24 minecraft:stained_glass 13
fill ~48~10~24 ~48~10~25 minecraft:stained_glass 5
setblock ~48~15~24 minecraft:stone_block_slab 11
fill ~48~16~24 ~48~16~26 minecraft:cobblestone
fill ~48~19~24 ~48~19~25 minecraft:planks 1
fill ~49~3~24 ~50~3~25 minecraft:stained_glass 13
setblock ~49~15~24 minecraft:stone_block_slab 13
setblock ~49~16~24 minecraft:stone 5
fill ~49~19~24 ~49~19~29 minecraft:planks 5
fill ~50~7~24 ~51~7~25 minecraft:stained_glass 13
fill ~50~8~24 ~50~8~25 minecraft:stained_glass 13
fill ~50~9~24 ~51~9~25 minecraft:stained_glass 5
fill ~50~10~24 ~50~10~26 minecraft:stained_glass 5
setblock ~50~16~24 minecraft:stone 6
setblock ~51~3~24 minecraft:stained_glass 5
fill ~51~6~24 ~51~6~25 minecraft:stained_glass 5
fill ~51~10~24 ~52~10~25 minecraft:stained_glass 13
setblock ~51~15~24 minecraft:stone_block_slab 11
fill ~51~16~24 ~51~16~25 minecraft:cobblestone
fill ~51~19~24 ~51~19~27 minecraft:planks 5
setblock ~52~3~24 minecraft:stained_glass 13
fill ~52~5~24 ~52~5~25 minecraft:stained_glass 5
fill ~52~6~24 ~52~6~25 minecraft:stained_glass 13
fill ~52~16~24 ~52~16~25 minecraft:stone 5
setblock ~52~19~24 minecraft:planks 1
setblock ~53~3~24 minecraft:stone
setblock ~53~5~24 minecraft:stone
fill ~53~6~24 ~53~7~24 minecraft:stone 5
setblock ~53~8~24 minecraft:stone
fill ~53~9~24 ~53~10~24 minecraft:stonebrick
fill ~53~11~24 ~53~11~25 minecraft:stone_block_slab 4
setblock ~53~15~24 minecraft:cobblestone
setblock ~54~11~24 minecraft:stone 6
fill ~54~12~24 ~54~12~25 minecraft:leaves
setblock ~54~13~24 minecraft:leaves
setblock ~54~14~24 minecraft:stone_brick_stairs 4
setblock ~54~15~24 minecraft:stone 5
fill ~54~19~24 ~54~19~27 minecraft:planks 5
fill ~55~12~24 ~55~12~25 minecraft:stone
setblock ~55~13~24 minecraft:stone
setblock ~55~14~24 minecraft:stone 6
setblock ~55~19~24 minecraft:planks 1
setblock ~56~12~24 minecraft:dirt
fill ~56~13~24 ~56~14~24 minecraft:stonebrick
setblock ~57~12~24 minecraft:grass
fill ~57~19~24 ~58~19~25 minecraft:planks 5
fill ~58~12~24 ~58~12~25 minecraft:stained_hardened_clay 5
fill ~59~12~24 ~59~12~29 minecraft:grass
fill ~60~12~24 ~61~12~24 minecraft:stone
fill ~60~20~24 ~60~20~25 minecraft:fence 5
fill ~61~19~24 ~62~19~24 minecraft:grass
setblock ~61~20~24 minecraft:tallgrass
setblock ~63~19~24 minecraft:stained_hardened_clay 5
setblock ~63~20~24 minecraft:vine
fill ~64~19~24 ~64~19~26 minecraft:dirt
setblock ~64~20~24 minecraft:double_stone_block_slab
fill ~65~18~24 ~66~18~27 minecraft:dirt
fill ~65~19~24 ~65~19~25 minecraft:dirt 1
setblock ~65~20~24 minecraft:mossy_cobblestone
fill ~65~21~24 ~65~22~24 minecraft:cobblestone_wall
setblock ~65~23~24 minecraft:vine
setblock ~66~19~24 minecraft:dirt
setblock ~66~20~24 minecraft:stone_stairs 2
fill ~67~18~24 ~67~18~27 minecraft:dirt 1
setblock ~67~19~24 minecraft:stained_hardened_clay 5
setblock ~67~20~24 minecraft:stone_block_slab
setblock ~68~18~24 minecraft:dirt
fill ~68~19~24 ~69~19~24 minecraft:grass
setblock ~68~28~24 minecraft:stained_hardened_clay 13
fill ~69~18~24 ~70~18~25 minecraft:dirt 1
fill ~69~20~24 ~69~20~25 minecraft:leaves
setblock ~69~29~24 minecraft:stained_hardened_clay 13
fill ~69~30~24 ~70~30~24 minecraft:stained_hardened_clay 5
setblock ~70~19~24 minecraft:dirt 1
fill ~70~21~24 ~71~21~24 minecraft:dirt
fill ~70~22~24 ~71~22~24 minecraft:dirt 1
fill ~70~23~24 ~71~23~24 minecraft:dirt
fill ~70~24~24 ~70~25~24 minecraft:dirt
fill ~70~26~24 ~71~26~24 minecraft:dirt 1
fill ~70~28~24 ~71~28~25 minecraft:dirt 1
fill ~71~12~24 ~71~12~25 minecraft:stone
setblock ~71~13~24 minecraft:dirt
setblock ~71~14~24 minecraft:dirt 1
setblock ~71~15~24 minecraft:dirt
fill ~71~16~24 ~71~17~24 minecraft:dirt 1
fill ~71~18~24 ~71~20~24 minecraft:dirt
setblock ~71~24~24 minecraft:dirt 1
fill ~71~25~24 ~71~25~25 minecraft:dirt
setblock ~71~27~24 minecraft:dirt 1
fill ~71~29~24 ~71~29~25 minecraft:stained_hardened_clay 5
fill ~28~12~25 ~28~12~33 minecraft:stone
fill ~28~13~25 ~28~14~25 minecraft:dirt
fill ~28~15~25 ~28~18~25 minecraft:dirt 1
setblock ~28~19~25 minecraft:dirt
fill ~28~20~25 ~28~20~26 minecraft:dirt 1
fill ~28~21~25 ~28~22~25 minecraft:dirt
fill ~28~23~25 ~28~24~25 minecraft:dirt 1
setblock ~28~25~25 minecraft:dirt
fill ~28~26~25 ~28~26~26 minecraft:dirt 1
fill ~28~27~25 ~29~27~25 minecraft:dirt 1
setblock ~28~28~25 minecraft:dirt
setblock ~28~29~25 minecraft:stained_hardened_clay 13
fill ~29~18~25 ~29~19~25 minecraft:dirt 1
setblock ~29~22~25 minecraft:dirt 1
setblock ~29~28~25 minecraft:dirt 1
setblock ~29~29~25 minecraft:stained_hardened_clay 5
fill ~30~19~25 ~30~19~27 minecraft:grass
fill ~30~20~25 ~30~20~26 minecraft:leaves
setblock ~30~21~25 minecraft:leaves
fill ~30~27~25 ~30~28~25 minecraft:stained_hardened_clay 13
setblock ~31~19~25 minecraft:stained_hardened_clay 5
setblock ~31~28~25 minecraft:stained_hardened_clay 13
fill ~32~19~25 ~32~19~26 minecraft:grass
setblock ~32~20~25 minecraft:tallgrass
fill ~33~19~25 ~33~19~26 minecraft:stained_hardened_clay 5
setblock ~34~20~25 minecraft:stone_block_slab
setblock ~35~19~25 minecraft:dirt 1
fill ~35~20~25 ~35~20~27 minecraft:cobblestone
fill ~35~21~25 ~35~22~25 minecraft:cobblestone_wall
fill ~35~23~25 ~35~24~25 minecraft:vine
fill ~36~19~25 ~36~19~26 minecraft:dirt
setblock ~36~20~25 minecraft:stone_block_slab
setblock ~37~12~25 minecraft:stone
setblock ~37~19~25 minecraft:stained_hardened_clay 5
setblock ~38~12~25 minecraft:grass
fill ~38~19~25 ~38~19~26 minecraft:grass
setblock ~39~19~25 minecraft:stained_hardened_clay 5
fill ~41~19~25 ~41~19~27 minecraft:planks 5
fill ~43~12~25 ~43~12~28 minecraft:grass
setblock ~43~19~25 minecraft:planks 1
fill ~44~12~25 ~44~12~26 minecraft:stained_hardened_clay 5
fill ~45~12~25 ~45~12~28 minecraft:grass
fill ~45~19~25 ~45~19~29 minecraft:planks 5
fill ~46~12~25 ~46~13~25 minecraft:cobblestone
setblock ~46~14~25 minecraft:stonebrick
setblock ~46~15~25 minecraft:cobblestone
setblock ~46~16~25 minecraft:stone 6
setblock ~47~3~25 minecraft:stone 5
fill ~47~5~25 ~47~6~25 minecraft:stone 5
setblock ~47~7~25 minecraft:stonebrick
setblock ~47~8~25 minecraft:stone 5
setblock ~47~10~25 minecraft:stone 6
setblock ~47~11~25 minecraft:stone 5
setblock ~47~12~25 minecraft:leaves
setblock ~47~15~25 minecraft:stone_block_slab 11
fill ~47~16~25 ~47~16~26 minecraft:cobblestone
setblock ~48~3~25 minecraft:stained_glass 5
setblock ~48~5~25 minecraft:stained_glass 13
fill ~48~6~25 ~49~6~25 minecraft:stained_glass 5
setblock ~48~7~25 minecraft:stained_glass 5
setblock ~48~9~25 minecraft:stained_glass 13
fill ~49~5~25 ~49~5~26 minecraft:stained_glass 5
fill ~49~7~25 ~49~8~26 minecraft:stained_glass 13
setblock ~49~9~25 minecraft:stained_glass 5
fill ~49~16~25 ~49~17~25 minecraft:stone 6
fill ~50~5~25 ~50~6~25 minecraft:stained_glass 13
setblock ~50~16~25 minecraft:stone
setblock ~50~17~25 minecraft:cobblestone
setblock ~51~3~25 minecraft:stained_glass 13
fill ~51~8~25 ~52~8~25 minecraft:stained_glass 5
setblock ~52~3~25 minecraft:stained_glass 5
setblock ~52~7~25 minecraft:stained_glass 5
setblock ~52~9~25 minecraft:stained_glass 5
setblock ~52~19~25 minecraft:planks 5
setblock ~53~3~25 minecraft:stonebrick
setblock ~53~5~25 minecraft:stone 5
setblock ~53~6~25 minecraft:stone 6
setblock ~53~7~25 minecraft:stonebrick
fill ~53~8~25 ~53~9~25 minecraft:stone 5
setblock ~53~10~25 minecraft:stone
setblock ~53~15~25 minecraft:stone_block_slab 11
fill ~53~16~25 ~53~16~26 minecraft:stone 5
fill ~54~11~25 ~54~11~26 minecraft:stone 5
setblock ~54~15~25 minecraft:stone_brick_stairs 4
setblock ~55~14~25 minecraft:stone 5
setblock ~55~19~25 minecraft:planks 5
fill ~56~12~25 ~56~12~27 minecraft:stonebrick
fill ~56~14~25 ~57~14~25 minecraft:stonebrick
setblock ~56~19~25 minecraft:planks 1
fill ~57~12~25 ~57~12~26 minecraft:dirt
fill ~57~13~25 ~57~13~27 minecraft:stonebrick
setblock ~60~12~25 minecraft:grass
setblock ~60~21~25 minecraft:torch
fill ~61~12~25 ~64~12~25 minecraft:stained_hardened_clay 5
fill ~61~19~25 ~61~19~28 minecraft:grass
setblock ~61~20~25 minecraft:red_flower
setblock ~62~19~25 minecraft:stained_hardened_clay 5
setblock ~63~19~25 minecraft:dirt
setblock ~63~20~25 minecraft:stone_block_slab
setblock ~64~18~25 minecraft:dirt 1
fill ~64~20~25 ~66~20~25 minecraft:cobblestone
setblock ~64~21~25 minecraft:mossy_cobblestone
fill ~64~22~25 ~64~22~26 minecraft:vine
setblock ~64~23~25 minecraft:vine
fill ~65~12~25 ~66~12~25 minecraft:grass
fill ~65~21~25 ~66~21~26 minecraft:cobblestone
fill ~65~22~25 ~65~22~26 minecraft:mossy_cobblestone
setblock ~65~23~25 minecraft:cobblestone
fill ~65~24~25 ~65~25~25 minecraft:cobblestone_wall
fill ~66~19~25 ~67~19~25 minecraft:dirt 1
setblock ~66~22~25 minecraft:stone_stairs 1
setblock ~66~23~25 minecraft:vine
fill ~67~12~25 ~67~12~26 minecraft:stained_hardened_clay 5
setblock ~67~20~25 minecraft:mossy_cobblestone
setblock ~67~21~25 minecraft:stone_block_slab
fill ~68~12~25 ~68~12~27 minecraft:grass
setblock ~68~18~25 minecraft:dirt 1
setblock ~68~19~25 minecraft:grass
fill ~69~19~25 ~70~19~25 minecraft:stained_hardened_clay 5
setblock ~69~28~25 minecraft:stained_hardened_clay 5
fill ~70~17~25 ~71~17~25 minecraft:dirt
setblock ~70~20~25 minecraft:leaves
fill ~71~18~25 ~71~19~25 minecraft:dirt 1
fill ~71~20~25 ~72~20~25 minecraft:dirt
setblock ~71~21~25 minecraft:dirt 1
setblock ~71~26~25 minecraft:dirt 1
setblock ~71~27~25 minecraft:dirt
setblock ~72~12~25 minecraft:stone
setblock ~72~13~25 minecraft:dirt
fill ~72~14~25 ~72~15~25 minecraft:dirt 1
setblock ~72~16~25 minecraft:dirt
setblock ~72~17~25 minecraft:dirt 1
fill ~72~18~25 ~72~19~25 minecraft:dirt
fill ~72~21~25 ~72~24~25 minecraft:dirt
fill ~72~25~25 ~72~25~26 minecraft:dirt 1
setblock ~72~26~25 minecraft:dirt
fill ~72~27~25 ~72~27~27 minecraft:dirt 1
fill ~72~28~25 ~72~28~26 minecraft:dirt
fill ~72~29~25 ~72~29~26 minecraft:stained_hardened_clay 13
fill ~27~12~26 ~27~12~32 minecraft:stone
fill ~27~13~26 ~27~17~26 minecraft:dirt 1
fill ~27~18~26 ~27~18~27 minecraft:dirt
fill ~27~19~26 ~28~19~26 minecraft:dirt 1
fill ~27~20~26 ~27~21~26 minecraft:dirt
setblock ~27~22~26 minecraft:dirt 1
fill ~27~23~26 ~27~26~26 minecraft:dirt
fill ~27~27~26 ~27~28~26 minecraft:dirt 1
fill ~27~29~26 ~28~29~26 minecraft:stained_hardened_clay 5
setblock ~28~18~26 minecraft:dirt 1
setblock ~28~27~26 minecraft:dirt
setblock ~28~28~26 minecraft:dirt 1
setblock ~29~18~26 minecraft:stained_hardened_clay 5
fill ~29~19~26 ~29~19~27 minecraft:leaves
fill ~29~20~26 ~29~21~26 minecraft:leaves
fill ~29~26~26 ~29~27~26 minecraft:stained_hardened_clay 5
fill ~29~28~26 ~29~28~27 minecraft:stained_hardened_clay 13
setblock ~29~29~26 minecraft:stained_hardened_clay 13
fill ~31~19~26 ~31~19~28 minecraft:grass
setblock ~32~20~26 minecraft:tallgrass
fill ~34~19~26 ~35~19~26 minecraft:dirt
setblock ~34~20~26 minecraft:mossy_cobblestone
setblock ~34~21~26 minecraft:stone_stairs
fill ~34~22~26 ~34~24~26 minecraft:vine
fill ~35~21~26 ~36~21~26 minecraft:mossy_cobblestone
fill ~35~22~26 ~35~22~27 minecraft:cobblestone
setblock ~35~23~26 minecraft:mossy_cobblestone
setblock ~35~24~26 minecraft:cobblestone
setblock ~35~25~26 minecraft:cobblestone_wall
setblock ~36~20~26 minecraft:mossy_cobblestone
setblock ~36~22~26 minecraft:stone_stairs 1
fill ~36~23~26 ~36~24~26 minecraft:vine
setblock ~37~12~26 minecraft:grass
fill ~37~19~26 ~37~19~27 minecraft:grass
setblock ~38~12~26 minecraft:stained_hardened_clay 5
setblock ~38~20~26 minecraft:red_flower
setblock ~39~12~26 minecraft:grass
setblock ~39~19~26 minecraft:dirt 1
fill ~43~19~26 ~43~19~28 minecraft:planks 5
setblock ~46~12~26 minecraft:dirt
setblock ~46~13~26 minecraft:log2air
setblock ~46~14~26 minecraft:stone
setblock ~46~15~26 minecraft:stonebrick
setblock ~46~16~26 minecraft:cobblestone
fill ~47~11~26 ~47~12~26 minecraft:stonebrick
fill ~47~17~26 ~47~17~27 minecraft:stonebrick
setblock ~48~3~26 minecraft:stone
setblock ~48~5~26 minecraft:stone 5
setblock ~48~6~26 minecraft:stonebrick
setblock ~48~7~26 minecraft:stone 5
setblock ~48~8~26 minecraft:stonebrick
setblock ~48~9~26 minecraft:stone 5
setblock ~48~10~26 minecraft:stonebrick
fill ~48~11~26 ~48~11~27 minecraft:cobblestone
setblock ~48~12~26 minecraft:cobblestone_wall
fill ~48~13~26 ~48~15~26 minecraft:cobblestone_wall
setblock ~48~17~26 minecraft:stone 5
fill ~48~19~26 ~48~19~28 minecraft:planks 5
fill ~49~3~26 ~51~3~26 minecraft:stained_glass 5
fill ~49~6~26 ~50~6~26 minecraft:stained_glass 5
fill ~49~9~26 ~50~9~26 minecraft:stained_glass 13
setblock ~49~16~26 minecraft:stone_stairs 7
setblock ~49~17~26 minecraft:stonebrick
setblock ~50~5~26 minecraft:stained_glass 5
setblock ~50~7~26 minecraft:stained_glass 13
setblock ~50~8~26 minecraft:stained_glass 5
setblock ~50~17~26 minecraft:stone_stairs 7
setblock ~50~18~26 minecraft:stone
setblock ~50~19~26 minecraft:planks 1
fill ~51~6~26 ~51~6~29 minecraft:stained_glass 13
setblock ~51~7~26 minecraft:stained_glass 5
setblock ~51~8~26 minecraft:stained_glass 13
setblock ~51~9~26 minecraft:stained_glass 5
fill ~51~10~26 ~51~10~28 minecraft:stained_glass 13
setblock ~51~16~26 minecraft:stone_block_slab 13
setblock ~51~17~26 minecraft:stone 5
setblock ~52~3~26 minecraft:stone 6
setblock ~52~5~26 minecraft:stonebrick
fill ~52~6~26 ~52~7~26 minecraft:cobblestone
fill ~52~8~26 ~52~10~26 minecraft:stone 5
fill ~52~11~26 ~52~11~27 minecraft:stone_block_slab 4
fill ~52~16~26 ~52~16~27 minecraft:stone_block_slab 11
fill ~52~17~26 ~52~17~27 minecraft:stonebrick
fill ~52~19~26 ~52~19~27 minecraft:planks 1
setblock ~53~11~26 minecraft:cobblestone
setblock ~53~17~26 minecraft:stone 5
setblock ~54~12~26 minecraft:stone_brick_stairs 2
setblock ~54~16~26 minecraft:stone
setblock ~54~17~26 minecraft:cobblestone
fill ~55~12~26 ~55~12~27 minecraft:stone 5
fill ~55~13~26 ~55~14~27 minecraft:iron_bars
setblock ~55~15~26 minecraft:cobblestone
setblock ~55~19~26 minecraft:planks 1
setblock ~56~13~26 minecraft:skull 1
setblock ~56~14~26 minecraft:stone_block_slab 13
fill ~56~15~26 ~56~15~27 minecraft:stonebrick
fill ~56~19~26 ~57~19~26 minecraft:planks 5
fill ~57~14~26 ~57~14~27 minecraft:stonebrick
setblock ~58~12~26 minecraft:grass
setblock ~58~19~26 minecraft:planks 1
fill ~60~12~26 ~61~12~26 minecraft:stained_hardened_clay 5
setblock ~60~19~26 minecraft:grass
setblock ~60~20~26 minecraft:tallgrass
fill ~62~12~26 ~64~12~26 minecraft:grass
fill ~62~19~26 ~63~19~26 minecraft:grass
setblock ~63~20~26 minecraft:vine
fill ~64~18~26 ~64~18~27 minecraft:dirt
setblock ~64~20~26 minecraft:double_stone_block_slab
setblock ~64~21~26 minecraft:vine
fill ~65~12~26 ~65~12~27 minecraft:stained_hardened_clay 5
setblock ~65~19~26 minecraft:dirt
setblock ~65~20~26 minecraft:cobblestone
setblock ~65~23~26 minecraft:stone_stairs 3
setblock ~66~12~26 minecraft:grass
setblock ~66~19~26 minecraft:dirt 1
setblock ~66~20~26 minecraft:mossy_cobblestone
setblock ~66~22~26 minecraft:stone_block_slab
fill ~67~19~26 ~69~19~26 minecraft:stained_hardened_clay 5
setblock ~67~20~26 minecraft:stone_block_slab
fill ~68~18~26 ~69~18~26 minecraft:dirt
fill ~69~12~26 ~70~12~26 minecraft:stained_hardened_clay 5
fill ~70~17~26 ~71~17~27 minecraft:dirt 1
setblock ~70~18~26 minecraft:dirt 1
setblock ~70~19~26 minecraft:grass
setblock ~70~27~26 minecraft:stained_hardened_clay 13
setblock ~70~28~26 minecraft:stained_hardened_clay 5
fill ~71~12~26 ~72~12~26 minecraft:grass
fill ~71~18~26 ~71~18~27 minecraft:stained_hardened_clay 5
setblock ~71~19~26 minecraft:leaves
setblock ~71~27~26 minecraft:dirt 1
setblock ~71~28~26 minecraft:dirt
setblock ~71~29~26 minecraft:stained_hardened_clay 13
fill ~72~17~26 ~72~17~28 minecraft:dirt
setblock ~72~18~26 minecraft:dirt 1
fill ~72~19~26 ~73~19~26 minecraft:dirt
setblock ~72~20~26 minecraft:dirt 1
fill ~72~26~26 ~72~26~27 minecraft:dirt 1
fill ~73~12~26 ~73~12~37 minecraft:stone
setblock ~73~13~26 minecraft:dirt 1
setblock ~73~14~26 minecraft:dirt
setblock ~73~15~26 minecraft:dirt 1
setblock ~73~16~26 minecraft:dirt
fill ~73~17~26 ~73~17~27 minecraft:dirt 1
setblock ~73~18~26 minecraft:dirt
fill ~73~20~26 ~73~22~26 minecraft:dirt
setblock ~73~23~26 minecraft:dirt 1
fill ~73~24~26 ~73~26~26 minecraft:dirt
setblock ~73~27~26 minecraft:dirt 1
fill ~73~28~26 ~73~28~27 minecraft:dirt
setblock ~73~29~26 minecraft:stained_hardened_clay 13
fill ~26~12~27 ~26~12~31 minecraft:stone
fill ~26~13~27 ~26~17~27 minecraft:dirt
fill ~26~18~27 ~26~18~28 minecraft:dirt 1
fill ~26~19~27 ~27~19~27 minecraft:dirt
fill ~26~20~27 ~26~20~28 minecraft:dirt
fill ~26~21~27 ~27~21~27 minecraft:dirt 1
setblock ~26~22~27 minecraft:dirt
fill ~26~23~27 ~26~26~27 minecraft:dirt 1
fill ~26~27~27 ~27~27~27 minecraft:dirt
setblock ~26~28~27 minecraft:dirt
fill ~26~29~27 ~27~29~27 minecraft:stained_hardened_clay 13
setblock ~27~20~27 minecraft:dirt 1
setblock ~27~25~27 minecraft:dirt
setblock ~27~26~27 minecraft:dirt 1
setblock ~27~28~27 minecraft:dirt 1
fill ~28~18~27 ~28~18~30 minecraft:stained_hardened_clay 5
fill ~28~19~27 ~28~20~27 minecraft:leaves
setblock ~28~27~27 minecraft:stained_hardened_clay 5
setblock ~28~28~27 minecraft:dirt
setblock ~28~29~27 minecraft:stained_hardened_clay 5
fill ~29~18~27 ~29~18~29 minecraft:grass
setblock ~30~20~27 minecraft:tallgrass
fill ~32~19~27 ~32~19~28 minecraft:stained_hardened_clay 5
setblock ~33~19~27 minecraft:grass
setblock ~34~19~27 minecraft:dirt
setblock ~34~20~27 minecraft:stone_block_slab
setblock ~34~21~27 minecraft:vine
setblock ~35~12~27 minecraft:stone
setblock ~35~19~27 minecraft:dirt 1
setblock ~35~21~27 minecraft:mossy_cobblestone
setblock ~35~23~27 minecraft:stone_stairs 3
fill ~36~12~27 ~37~12~27 minecraft:stained_hardened_clay 5
fill ~36~19~27 ~36~19~28 minecraft:stained_hardened_clay 5
setblock ~36~20~27 minecraft:stone_stairs 3
setblock ~36~21~27 minecraft:vine
fill ~38~12~27 ~38~12~29 minecraft:grass
setblock ~38~19~27 minecraft:dirt 1
setblock ~39~12~27 minecraft:stained_hardened_clay 5
setblock ~39~19~27 minecraft:grass
setblock ~40~19~27 minecraft:stained_hardened_clay 5
fill ~41~12~27 ~41~12~32 minecraft:stained_hardened_clay 5
setblock ~44~12~27 minecraft:grass
setblock ~44~19~27 minecraft:planks 1
fill ~46~12~27 ~46~12~29 minecraft:dirt 1
fill ~46~13~27 ~46~13~28 minecraft:stone 6
setblock ~46~14~27 minecraft:stonebrick
setblock ~46~15~27 minecraft:log2
setblock ~46~16~27 minecraft:stone
setblock ~46~19~27 minecraft:planks 1
setblock ~47~11~27 minecraft:stone 5
setblock ~47~12~27 minecraft:stone
setblock ~47~16~27 minecraft:stone_stairs 7
fill ~47~18~27 ~47~18~28 minecraft:stonebrick
fill ~47~19~27 ~47~19~28 minecraft:planks 5
setblock ~48~17~27 minecraft:stonebrick
setblock ~48~18~27 minecraft:cobblestone
setblock ~49~3~27 minecraft:stone 6
setblock ~49~4~27 minecraft:stone 5
fill ~49~5~27 ~52~5~29 minecraft:wool 13
setblock ~49~6~27 minecraft:stone 6
setblock ~49~7~27 minecraft:stonebrick
setblock ~49~8~27 minecraft:stone
setblock ~49~9~27 minecraft:stonebrick
setblock ~49~10~27 minecraft:stone 5
setblock ~49~11~27 minecraft:stone_block_slab 4
setblock ~49~17~27 minecraft:double_stone_block_slab
setblock ~49~18~27 minecraft:stone 5
fill ~50~3~27 ~51~3~27 minecraft:stained_glass 13
setblock ~50~4~27 minecraft:stained_glass 5
fill ~50~6~27 ~50~6~29 minecraft:stained_glass 13
fill ~50~7~27 ~50~7~31 minecraft:stained_glass 5
setblock ~50~8~27 minecraft:stained_glass 13
fill ~50~9~27 ~50~9~31 minecraft:stained_glass 5
setblock ~50~10~27 minecraft:stained_glass 13
fill ~50~17~27 ~51~17~27 minecraft:stone_block_slab 11
fill ~50~18~27 ~51~18~27 minecraft:stone 6
fill ~50~19~27 ~50~19~31 minecraft:planks 5
fill ~51~4~27 ~51~4~28 minecraft:stained_glass 13
fill ~51~7~27 ~51~7~28 minecraft:stained_glass 13
fill ~51~8~27 ~51~8~28 minecraft:stained_glass 5
fill ~51~9~27 ~51~9~28 minecraft:stained_glass 13
fill ~52~3~27 ~52~4~27 minecraft:stonebrick
fill ~52~6~27 ~52~7~27 minecraft:stonebrick
fill ~52~8~27 ~52~8~28 minecraft:stone
setblock ~52~9~27 minecraft:stone
setblock ~52~10~27 minecraft:stonebrick
setblock ~52~18~27 minecraft:stonebrick
setblock ~53~11~27 minecraft:stone 6
setblock ~53~17~27 minecraft:stonebrick
setblock ~53~19~27 minecraft:planks 1
setblock ~54~11~27 minecraft:stonebrick
setblock ~54~12~27 minecraft:stone 5
setblock ~54~16~27 minecraft:stone_brick_stairs 7
setblock ~54~17~27 minecraft:stone 5
setblock ~55~15~27 minecraft:log2air
setblock ~55~16~27 minecraft:stone 5
fill ~55~17~27 ~55~17~28 minecraft:cobblestone
fill ~55~19~27 ~55~19~30 minecraft:planks 5
setblock ~56~14~27 minecraft:air
fill ~56~19~27 ~56~19~28 minecraft:planks 1
setblock ~57~12~27 minecraft:dirt 1
fill ~57~19~27 ~58~19~28 minecraft:planks 5
fill ~58~12~27 ~58~12~29 minecraft:stained_hardened_clay 5
setblock ~60~12~27 minecraft:grass
setblock ~60~19~27 minecraft:stained_hardened_clay 5
fill ~61~12~27 ~61~12~28 minecraft:stained_hardened_clay 5
setblock ~61~20~27 minecraft:stone_pressure_plate
fill ~62~12~27 ~63~12~27 minecraft:grass
setblock ~62~19~27 minecraft:stained_hardened_clay 5
setblock ~63~18~27 minecraft:dirt
setblock ~63~19~27 minecraft:grass
setblock ~64~12~27 minecraft:stained_hardened_clay 5
fill ~64~19~27 ~65~19~27 minecraft:stained_hardened_clay 5
setblock ~64~20~27 minecraft:vine
setblock ~65~20~27 minecraft:stone_block_slab
setblock ~65~21~27 minecraft:vine
fill ~66~12~27 ~66~12~28 minecraft:stained_hardened_clay 5
fill ~66~19~27 ~67~19~27 minecraft:grass
fill ~67~12~27 ~67~12~28 minecraft:grass
setblock ~67~20~27 minecraft:tallgrass
setblock ~68~18~27 minecraft:dirt
fill ~68~19~27 ~68~19~29 minecraft:stained_hardened_clay 5
setblock ~69~12~27 minecraft:grass
fill ~69~17~27 ~69~17~30 minecraft:dirt
setblock ~69~18~27 minecraft:dirt 1
setblock ~69~19~27 minecraft:grass
fill ~70~12~27 ~70~12~29 minecraft:stained_hardened_clay 5
fill ~70~18~27 ~70~18~28 minecraft:stained_hardened_clay 5
setblock ~71~12~27 minecraft:grass
setblock ~71~28~27 minecraft:stained_hardened_clay 13
setblock ~72~12~27 minecraft:stained_hardened_clay 5
fill ~72~18~27 ~72~18~28 minecraft:stained_hardened_clay 5
setblock ~72~19~27 minecraft:leaves
setblock ~72~28~27 minecraft:dirt 1
fill ~72~29~27 ~74~29~27 minecraft:stained_hardened_clay 5
fill ~73~16~27 ~74~16~28 minecraft:dirt 1
setblock ~73~18~27 minecraft:dirt 1
setblock ~73~19~27 minecraft:grass
setblock ~73~20~27 minecraft:leaves
fill ~73~25~27 ~74~25~27 minecraft:dirt 1
fill ~73~26~27 ~74~27~27 minecraft:dirt
fill ~74~12~27 ~74~12~37 minecraft:stone
fill ~74~13~27 ~74~15~27 minecraft:dirt
fill ~74~17~27 ~74~18~27 minecraft:dirt
setblock ~74~19~27 minecraft:dirt 1
setblock ~74~20~27 minecraft:dirt
setblock ~74~21~27 minecraft:dirt 1
fill ~74~22~27 ~74~23~27 minecraft:dirt
setblock ~74~24~27 minecraft:dirt 1
setblock ~74~28~27 minecraft:dirt
fill ~25~12~28 ~25~12~31 minecraft:stone
fill ~25~13~28 ~25~13~29 minecraft:dirt
fill ~25~14~28 ~25~15~29 minecraft:dirt 1
fill ~25~16~28 ~25~18~28 minecraft:dirt
setblock ~25~19~28 minecraft:dirt 1
fill ~25~20~28 ~25~23~28 minecraft:dirt
fill ~25~24~28 ~25~25~29 minecraft:dirt 1
fill ~25~26~28 ~26~26~28 minecraft:dirt 1
fill ~25~27~28 ~25~27~30 minecraft:dirt 1
fill ~25~28~28 ~27~28~28 minecraft:stained_hardened_clay 5
setblock ~26~19~28 minecraft:dirt
setblock ~26~21~28 minecraft:dirt 1
setblock ~26~25~28 minecraft:dirt 1
setblock ~26~27~28 minecraft:dirt
setblock ~27~18~28 minecraft:stained_hardened_clay 5
fill ~27~19~28 ~27~20~28 minecraft:leaves
setblock ~27~26~28 minecraft:stained_hardened_clay 13
fill ~27~27~28 ~27~27~29 minecraft:stained_hardened_clay 5
setblock ~28~28~28 minecraft:stained_hardened_clay 13
setblock ~30~18~28 minecraft:stained_hardened_clay 5
fill ~33~19~28 ~34~19~28 minecraft:stained_hardened_clay 5
setblock ~35~12~28 minecraft:stained_hardened_clay 5
setblock ~35~19~28 minecraft:dirt
setblock ~35~20~28 minecraft:stone_block_slab
fill ~35~21~28 ~35~22~28 minecraft:vine
fill ~36~12~28 ~37~12~28 minecraft:grass
setblock ~37~19~28 minecraft:dirt 1
setblock ~38~19~28 minecraft:stained_hardened_clay 5
setblock ~39~12~28 minecraft:grass
fill ~39~19~28 ~39~19~29 minecraft:stone
setblock ~39~20~28 minecraft:stone_pressure_plate
fill ~40~12~28 ~40~12~30 minecraft:stained_hardened_clay 5
fill ~40~19~28 ~40~19~29 minecraft:grass
setblock ~40~20~28 minecraft:stone_button 1
setblock ~41~19~28 minecraft:cobblestone
setblock ~42~12~28 minecraft:grass
fill ~42~20~28 ~43~20~28 minecraft:fence 5
setblock ~43~21~28 minecraft:torch
setblock ~44~12~28 minecraft:stained_hardened_clay 5
fill ~44~19~28 ~44~19~29 minecraft:planks 5
setblock ~46~14~28 minecraft:stone 6
setblock ~46~15~28 minecraft:stone 5
setblock ~46~16~28 minecraft:cobblestone
setblock ~46~17~28 minecraft:stone 5
fill ~46~18~28 ~46~18~29 minecraft:stone
fill ~46~19~28 ~46~19~30 minecraft:planks 5
fill ~47~12~28 ~47~13~28 minecraft:stone 6
setblock ~47~14~28 minecraft:stone_brick_stairs 2
fill ~47~17~28 ~50~17~28 minecraft:stone_block_slab 11
setblock ~48~11~28 minecraft:stone 6
setblock ~48~12~28 minecraft:leaves
setblock ~48~18~28 minecraft:stone 6
setblock ~49~3~28 minecraft:cobblestone
fill ~49~4~28 ~49~4~29 minecraft:stonebrick
setblock ~49~6~28 minecraft:stone
setblock ~49~7~28 minecraft:stone 6
setblock ~49~8~28 minecraft:stone 5
fill ~49~9~28 ~49~10~28 minecraft:cobblestone
setblock ~49~11~28 minecraft:stone 5
setblock ~49~18~28 minecraft:stone
fill ~50~3~28 ~51~3~29 minecraft:stained_glass 5
setblock ~50~4~28 minecraft:stained_glass 13
setblock ~50~8~28 minecraft:stained_glass 5
fill ~50~10~28 ~50~10~30 minecraft:stained_glass 5
fill ~50~18~28 ~50~18~31 minecraft:stonebrick
fill ~51~11~28 ~51~11~29 minecraft:stained_glass 13
setblock ~51~18~28 minecraft:stone 5
setblock ~51~19~28 minecraft:planks 1
fill ~52~3~28 ~52~3~29 minecraft:stone
setblock ~52~4~28 minecraft:stone 5
fill ~52~6~28 ~52~7~28 minecraft:cobblestone
setblock ~52~9~28 minecraft:cobblestone
fill ~52~10~28 ~52~10~29 minecraft:stone
setblock ~52~11~28 minecraft:stone 5
fill ~52~12~28 ~52~15~28 minecraft:cobblestone_wall
setblock ~52~16~28 minecraft:cobblestone_wall
setblock ~52~17~28 minecraft:cobblestone
setblock ~52~18~28 minecraft:stone
fill ~52~19~28 ~53~19~28 minecraft:planks 5
setblock ~53~11~28 minecraft:cobblestone
setblock ~53~17~28 minecraft:stone_block_slab 13
fill ~53~18~28 ~54~18~28 minecraft:stone 5
setblock ~54~12~28 minecraft:stonebrick
setblock ~54~13~28 minecraft:stone_stairs 2
setblock ~54~16~28 minecraft:stone_stairs 6
setblock ~54~17~28 minecraft:cobblestone
setblock ~54~19~28 minecraft:planks 1
setblock ~55~12~28 minecraft:dirt 1
setblock ~55~13~28 minecraft:cobblestone
fill ~55~14~28 ~55~14~29 minecraft:stone 5
setblock ~55~15~28 minecraft:stone 5
setblock ~55~16~28 minecraft:log2
setblock ~55~18~28 minecraft:cobblestone
setblock ~56~12~28 minecraft:dirt
fill ~56~13~28 ~56~14~28 minecraft:stonebrick
fill ~57~12~28 ~57~12~29 minecraft:stained_hardened_clay 5
setblock ~59~19~28 minecraft:stained_hardened_clay 5
setblock ~60~12~28 minecraft:stained_hardened_clay 5
fill ~60~19~28 ~60~19~29 minecraft:stone
setblock ~61~20~28 minecraft:stone_button 1
setblock ~62~12~28 minecraft:stained_hardened_clay 5
setblock ~62~19~28 minecraft:stone
fill ~63~12~28 ~65~12~28 minecraft:grass
fill ~63~18~28 ~66~18~28 minecraft:dirt 1
setblock ~63~19~28 minecraft:stained_hardened_clay 5
setblock ~64~19~28 minecraft:stone
fill ~65~19~28 ~65~19~29 minecraft:stained_hardened_clay 5
fill ~66~19~28 ~66~19~29 minecraft:grass
fill ~67~18~28 ~67~18~29 minecraft:dirt
fill ~67~19~28 ~67~19~30 minecraft:stained_hardened_clay 5
fill ~68~12~28 ~69~12~28 minecraft:stained_hardened_clay 5
fill ~68~18~28 ~68~18~29 minecraft:dirt 1
setblock ~69~18~28 minecraft:stained_hardened_clay 5
setblock ~70~17~28 minecraft:dirt
setblock ~71~12~28 minecraft:stained_hardened_clay 5
setblock ~71~17~28 minecraft:dirt 1
setblock ~71~18~28 minecraft:grass
setblock ~71~19~28 minecraft:tallgrass
fill ~72~12~28 ~72~12~37 minecraft:stone
fill ~72~16~28 ~72~16~29 minecraft:dirt 1
setblock ~72~28~28 minecraft:stained_hardened_clay 13
setblock ~73~17~28 minecraft:stained_hardened_clay 5
setblock ~73~18~28 minecraft:leaves
fill ~73~26~28 ~73~27~28 minecraft:stained_hardened_clay 13
fill ~73~28~28 ~74~28~28 minecraft:dirt 1
fill ~73~29~28 ~74~29~28 minecraft:stained_hardened_clay 5
fill ~74~17~28 ~75~17~28 minecraft:dirt 1
setblock ~74~18~28 minecraft:grass
setblock ~74~19~28 minecraft:leaves
fill ~74~26~28 ~75~26~28 minecraft:dirt 1
fill ~74~27~28 ~75~27~28 minecraft:dirt
fill ~75~12~28 ~75~12~36 minecraft:stone
setblock ~75~13~28 minecraft:dirt 1
fill ~75~14~28 ~75~16~28 minecraft:dirt
fill ~75~18~28 ~75~18~30 minecraft:dirt
fill ~75~19~28 ~75~21~28 minecraft:dirt
fill ~75~22~28 ~75~24~28 minecraft:dirt 1
setblock ~75~25~28 minecraft:dirt
setblock ~75~28~28 minecraft:stained_hardened_clay 13
fill ~25~16~29 ~25~18~29 minecraft:dirt 1
setblock ~25~19~29 minecraft:dirt
fill ~25~20~29 ~25~21~29 minecraft:dirt 1
fill ~25~22~29 ~25~23~29 minecraft:dirt
fill ~25~26~29 ~26~26~29 minecraft:dirt
fill ~25~28~29 ~25~28~30 minecraft:stained_hardened_clay 13
fill ~26~18~29 ~26~18~30 minecraft:stained_hardened_clay 5
fill ~26~19~29 ~26~19~30 minecraft:leaves
setblock ~26~27~29 minecraft:dirt 1
setblock ~26~28~29 minecraft:stained_hardened_clay 5
setblock ~27~18~29 minecraft:grass
setblock ~27~19~29 minecraft:tallgrass
setblock ~29~19~29 minecraft:stone_block_slab 4
fill ~30~18~29 ~31~18~29 minecraft:grass
setblock ~31~19~29 minecraft:tallgrass
setblock ~32~19~29 minecraft:grass
setblock ~32~20~29 minecraft:red_flower
setblock ~33~19~29 minecraft:stained_hardened_clay 5
fill ~34~12~29 ~34~12~30 minecraft:stained_hardened_clay 5
setblock ~34~19~29 minecraft:grass
setblock ~35~12~29 minecraft:grass
setblock ~35~19~29 minecraft:stone 5
fill ~36~12~29 ~37~12~29 minecraft:stained_hardened_clay 5
setblock ~36~19~29 minecraft:dirt 1
fill ~37~19~29 ~37~19~30 minecraft:stained_hardened_clay 5
fill ~38~19~29 ~38~19~31 minecraft:stone
setblock ~39~12~29 minecraft:stained_hardened_clay 5
fill ~41~19~29 ~42~19~29 minecraft:grass
setblock ~41~20~29 minecraft:stone_pressure_plate
fill ~42~12~29 ~43~12~30 minecraft:stained_hardened_clay 5
fill ~43~19~29 ~43~19~30 minecraft:stained_hardened_clay 5
fill ~43~20~29 ~44~20~29 minecraft:fence 5
setblock ~44~12~29 minecraft:grass
setblock ~45~12~29 minecraft:stained_hardened_clay 5
fill ~46~13~29 ~46~14~29 minecraft:stone
setblock ~46~15~29 minecraft:stone 6
fill ~46~16~29 ~46~17~29 minecraft:stone
setblock ~47~12~29 minecraft:dirt 1
setblock ~47~13~29 minecraft:stonebrick
setblock ~47~14~29 minecraft:cobblestone
setblock ~47~16~29 minecraft:stone_stairs 6
setblock ~47~17~29 minecraft:double_stone_block_slab
setblock ~47~18~29 minecraft:stone
fill ~47~19~29 ~48~19~29 minecraft:planks 1
setblock ~48~12~29 minecraft:stone
fill ~48~13~29 ~48~14~29 minecraft:leaves
setblock ~48~17~29 minecraft:stone_block_slab 11
setblock ~48~18~29 minecraft:stonebrick
setblock ~49~3~29 minecraft:stone 6
setblock ~49~6~29 minecraft:stonebrick
setblock ~49~7~29 minecraft:stone
fill ~49~8~29 ~49~8~31 minecraft:stonebrick
setblock ~49~9~29 minecraft:stonebrick
setblock ~49~10~29 minecraft:stone 5
setblock ~49~11~29 minecraft:stone
setblock ~49~12~29 minecraft:leaves
setblock ~49~18~29 minecraft:stone 6
fill ~50~4~29 ~51~4~30 minecraft:stained_glass 5
fill ~50~8~29 ~51~8~29 minecraft:stained_glass 13
fill ~50~11~29 ~50~11~30 minecraft:stained_glass 13
fill ~51~7~29 ~51~7~30 minecraft:stained_glass 5
fill ~51~9~29 ~51~10~30 minecraft:stained_glass 5
setblock ~51~18~29 minecraft:stone
fill ~51~19~29 ~52~19~29 minecraft:planks 5
setblock ~52~4~29 minecraft:cobblestone
fill ~52~6~29 ~52~7~29 minecraft:stone
setblock ~52~8~29 minecraft:stone 6
setblock ~52~9~29 minecraft:stonebrick
fill ~52~11~29 ~53~11~29 minecraft:stonebrick
setblock ~52~17~29 minecraft:stone_block_slab 11
fill ~52~18~29 ~52~18~30 minecraft:stone 6
setblock ~53~12~29 minecraft:stone_brick_stairs 2
setblock ~53~16~29 minecraft:stone_brick_stairs 6
fill ~53~17~29 ~54~17~29 minecraft:stone 6
setblock ~53~18~29 minecraft:stone 5
setblock ~53~19~29 minecraft:planks 1
setblock ~54~12~29 minecraft:stone 5
setblock ~54~13~29 minecraft:log2
setblock ~54~14~29 minecraft:stone 5
setblock ~54~15~29 minecraft:stone_stairs 6
setblock ~54~16~29 minecraft:stone 5
setblock ~54~18~29 minecraft:cobblestone
fill ~54~19~29 ~54~19~31 minecraft:planks 5
setblock ~55~12~29 minecraft:dirt
setblock ~55~13~29 minecraft:stonebrick
fill ~55~15~29 ~55~16~29 minecraft:cobblestone
setblock ~55~17~29 minecraft:stonebrick
setblock ~55~18~29 minecraft:stone 6
setblock ~56~12~29 minecraft:stained_hardened_clay 5
fill ~56~19~29 ~57~19~29 minecraft:planks 5
fill ~56~20~29 ~57~20~29 minecraft:fence 5
setblock ~58~19~29 minecraft:stained_hardened_clay 5
setblock ~59~19~29 minecraft:stone 5
fill ~60~12~29 ~62~12~29 minecraft:grass
fill ~61~19~29 ~61~19~30 minecraft:stone 5
setblock ~62~19~29 minecraft:dirt 1
fill ~63~12~29 ~63~12~30 minecraft:stained_hardened_clay 5
fill ~63~18~29 ~65~18~30 minecraft:dirt 1
fill ~63~19~29 ~64~19~29 minecraft:grass
fill ~64~12~29 ~66~12~29 minecraft:grass
setblock ~64~20~29 minecraft:stone_pressure_plate
fill ~66~18~29 ~66~18~32 minecraft:dirt
setblock ~66~20~29 minecraft:tallgrass
setblock ~67~12~29 minecraft:stained_hardened_clay 5
fill ~68~12~29 ~69~12~29 minecraft:grass
setblock ~68~17~29 minecraft:dirt 1
fill ~69~18~29 ~70~18~30 minecraft:grass
fill ~69~19~29 ~70~19~29 minecraft:tallgrass
fill ~70~17~29 ~70~17~30 minecraft:dirt 1
fill ~71~12~29 ~71~12~39 minecraft:stone
setblock ~71~16~29 minecraft:dirt 1
fill ~71~17~29 ~71~17~30 minecraft:dirt
setblock ~71~18~29 minecraft:stained_hardened_clay 5
setblock ~72~17~29 minecraft:stained_hardened_clay 5
fill ~73~16~29 ~75~16~29 minecraft:dirt
fill ~73~17~29 ~73~17~30 minecraft:grass
setblock ~73~18~29 minecraft:red_flower
setblock ~73~28~29 minecraft:stained_hardened_clay 13
fill ~74~17~29 ~74~17~30 minecraft:stained_hardened_clay 5
setblock ~74~18~29 minecraft:leaves
setblock ~74~27~29 minecraft:stained_hardened_clay 13
fill ~74~28~29 ~75~28~29 minecraft:stained_hardened_clay 5
setblock ~75~13~29 minecraft:dirt
setblock ~75~14~29 minecraft:dirt 1
setblock ~75~15~29 minecraft:dirt
setblock ~75~17~29 minecraft:dirt
setblock ~75~19~29 minecraft:dirt 1
setblock ~75~20~29 minecraft:dirt
setblock ~75~21~29 minecraft:dirt 1
fill ~75~22~29 ~75~24~29 minecraft:dirt
fill ~75~25~29 ~75~25~30 minecraft:dirt 1
setblock ~75~26~29 minecraft:dirt
fill ~75~27~29 ~75~27~30 minecraft:dirt 1
fill ~24~12~30 ~24~12~35 minecraft:stone
fill ~24~13~30 ~24~14~30 minecraft:dirt 1
setblock ~24~15~30 minecraft:dirt
setblock ~24~16~30 minecraft:dirt 1
fill ~24~17~30 ~25~17~30 minecraft:dirt
fill ~24~18~30 ~24~20~30 minecraft:dirt
fill ~24~21~30 ~24~25~30 minecraft:dirt 1
fill ~24~26~30 ~25~26~30 minecraft:dirt
setblock ~24~27~30 minecraft:dirt 1
setblock ~24~28~30 minecraft:stained_hardened_clay 13
setblock ~25~18~30 minecraft:dirt 1
setblock ~25~19~30 minecraft:stained_hardened_clay 5
fill ~25~20~30 ~25~21~30 minecraft:leaves
fill ~25~24~30 ~25~25~30 minecraft:dirt
fill ~26~25~30 ~26~27~30 minecraft:stained_hardened_clay 13
setblock ~27~18~30 minecraft:stained_hardened_clay 5
setblock ~28~19~30 minecraft:stone_block_slab 4
fill ~29~18~30 ~32~18~30 minecraft:stained_hardened_clay 5
fill ~29~19~30 ~29~20~30 minecraft:log
setblock ~30~19~30 minecraft:stone_stairs 1
setblock ~33~19~30 minecraft:grass
fill ~34~19~30 ~35~19~30 minecraft:stained_hardened_clay 5
fill ~35~12~30 ~36~12~30 minecraft:stained_hardened_clay 5
fill ~35~20~30 ~35~20~31 minecraft:stone_button 1
setblock ~36~19~30 minecraft:grass
setblock ~36~20~30 minecraft:stone_pressure_plate
fill ~37~12~30 ~37~12~31 minecraft:grass
setblock ~38~12~30 minecraft:stained_hardened_clay 5
setblock ~38~20~30 minecraft:stone_button 1
fill ~39~12~30 ~39~12~31 minecraft:grass
setblock ~39~19~30 minecraft:stained_hardened_clay 5
setblock ~40~19~30 minecraft:cobblestone
fill ~41~19~30 ~42~19~30 minecraft:stained_hardened_clay 5
setblock ~44~12~30 minecraft:stained_hardened_clay 5
setblock ~44~19~30 minecraft:grass
setblock ~45~12~30 minecraft:grass
setblock ~45~19~30 minecraft:dirt
fill ~45~20~30 ~45~20~33 minecraft:cobblestone
setblock ~46~12~30 minecraft:stained_hardened_clay 5
setblock ~47~12~30 minecraft:dirt
setblock ~47~13~30 minecraft:stone 6
setblock ~47~14~30 minecraft:stonebrick
setblock ~47~15~30 minecraft:cobblestone
fill ~47~16~30 ~47~17~30 minecraft:stone 6
setblock ~47~18~30 minecraft:stonebrick
fill ~47~19~30 ~48~19~31 minecraft:planks 5
fill ~48~12~30 ~48~12~31 minecraft:dirt 1
setblock ~48~13~30 minecraft:stone 5
fill ~48~14~30 ~48~15~30 minecraft:leaves
setblock ~48~17~30 minecraft:stone 6
fill ~48~18~30 ~49~18~30 minecraft:stone 5
setblock ~49~3~30 minecraft:stonebrick
fill ~49~4~30 ~49~4~31 minecraft:stone
setblock ~49~5~30 minecraft:stone
fill ~49~6~30 ~52~6~32 minecraft:wool 13
setblock ~49~7~30 minecraft:stone 6
setblock ~49~9~30 minecraft:stone
fill ~49~10~30 ~49~10~31 minecraft:cobblestone
fill ~49~11~30 ~49~11~31 minecraft:stone 6
setblock ~49~12~30 minecraft:cobblestone
setblock ~49~17~30 minecraft:stone_block_slab 11
setblock ~49~19~30 minecraft:planks 1
setblock ~50~3~30 minecraft:stained_glass 5
setblock ~50~5~30 minecraft:stained_glass 13
fill ~50~8~30 ~50~8~36 minecraft:stained_glass 5
fill ~51~3~30 ~51~3~32 minecraft:stained_glass 13
setblock ~51~5~30 minecraft:stained_glass 5
setblock ~51~8~30 minecraft:stained_glass 13
setblock ~51~11~30 minecraft:stained_glass 5
setblock ~51~12~30 minecraft:stained_glass 13
setblock ~51~17~30 minecraft:stone_block_slab 13
setblock ~51~18~30 minecraft:stone 6
setblock ~51~19~30 minecraft:planks 1
setblock ~52~3~30 minecraft:stone 5
setblock ~52~4~30 minecraft:stone 6
setblock ~52~5~30 minecraft:stonebrick
setblock ~52~7~30 minecraft:cobblestone
fill ~52~8~30 ~52~8~31 minecraft:stone 5
setblock ~52~9~30 minecraft:stone
setblock ~52~10~30 minecraft:cobblestone
fill ~52~11~30 ~52~11~32 minecraft:stone 5
setblock ~52~17~30 minecraft:double_stone_block_slab
fill ~52~19~30 ~53~19~31 minecraft:planks 5
setblock ~53~12~30 minecraft:dirt
setblock ~53~13~30 minecraft:stone_stairs 2
setblock ~53~15~30 minecraft:stone_stairs 6
setblock ~53~16~30 minecraft:cobblestone
setblock ~53~17~30 minecraft:stone
setblock ~53~18~30 minecraft:stonebrick
setblock ~54~12~30 minecraft:dirt 1
fill ~54~13~30 ~54~15~30 minecraft:stonebrick
setblock ~54~16~30 minecraft:stone
setblock ~54~17~30 minecraft:stonebrick
fill ~55~12~30 ~58~12~30 minecraft:grass
fill ~55~20~30 ~56~20~30 minecraft:fence 5
setblock ~56~19~30 minecraft:planks 5
setblock ~57~19~30 minecraft:dirt 1
setblock ~58~19~30 minecraft:cobblestone
fill ~59~12~30 ~59~12~32 minecraft:stained_hardened_clay 5
setblock ~59~19~30 minecraft:grass
fill ~60~12~30 ~61~12~31 minecraft:grass
setblock ~60~19~30 minecraft:dirt 1
setblock ~61~20~30 minecraft:stone_pressure_plate
setblock ~62~12~30 minecraft:stained_hardened_clay 5
fill ~62~18~30 ~62~18~32 minecraft:dirt 1
fill ~62~19~30 ~62~19~31 minecraft:stone 5
setblock ~63~19~30 minecraft:grass
setblock ~64~12~30 minecraft:grass
setblock ~64~19~30 minecraft:dirt 1
fill ~65~12~30 ~65~12~34 minecraft:stained_hardened_clay 5
setblock ~65~19~30 minecraft:stone 5
fill ~66~12~30 ~68~12~30 minecraft:grass
setblock ~66~19~30 minecraft:cobblestone
fill ~67~17~30 ~68~17~30 minecraft:dirt
setblock ~67~18~30 minecraft:dirt 1
fill ~68~18~30 ~68~18~31 minecraft:grass
setblock ~68~19~30 minecraft:stone_block_slab
setblock ~69~12~30 minecraft:stained_hardened_clay 5
setblock ~69~19~30 minecraft:tallgrass
setblock ~70~12~30 minecraft:grass
setblock ~70~19~30 minecraft:red_flower
fill ~71~16~30 ~72~16~30 minecraft:dirt
setblock ~71~18~30 minecraft:grass
setblock ~71~19~30 minecraft:tallgrass
fill ~72~17~30 ~72~17~32 minecraft:grass
fill ~72~18~30 ~73~18~30 minecraft:tallgrass
fill ~73~16~30 ~76~16~30 minecraft:dirt 1
setblock ~74~15~30 minecraft:dirt
setblock ~74~28~30 minecraft:stained_hardened_clay 5
fill ~75~15~30 ~76~15~30 minecraft:dirt 1
fill ~75~17~30 ~76~17~30 minecraft:dirt 1
fill ~75~19~30 ~76~19~30 minecraft:dirt
setblock ~75~26~30 minecraft:dirt 1
fill ~75~28~30 ~76~28~30 minecraft:stained_hardened_clay 13
fill ~76~12~30 ~76~12~36 minecraft:stone
setblock ~76~13~30 minecraft:dirt
setblock ~76~14~30 minecraft:dirt 1
setblock ~76~18~30 minecraft:dirt 1
fill ~76~20~30 ~76~20~31 minecraft:dirt 1
setblock ~76~21~30 minecraft:dirt 1
fill ~76~22~30 ~76~24~30 minecraft:dirt
setblock ~76~25~30 minecraft:dirt 1
fill ~76~26~30 ~76~26~31 minecraft:dirt
fill ~76~27~30 ~76~27~31 minecraft:dirt 1
fill ~23~12~31 ~23~12~35 minecraft:stone
fill ~23~13~31 ~23~14~31 minecraft:dirt
fill ~23~15~31 ~23~17~31 minecraft:dirt 1
fill ~23~18~31 ~23~18~32 minecraft:dirt
setblock ~23~19~31 minecraft:dirt
setblock ~23~20~31 minecraft:dirt 1
fill ~23~21~31 ~23~22~31 minecraft:dirt
fill ~23~23~31 ~23~27~31 minecraft:dirt 1
fill ~23~28~31 ~24~28~31 minecraft:stained_hardened_clay 5
setblock ~24~17~31 minecraft:dirt
setblock ~24~18~31 minecraft:grass
fill ~24~19~31 ~25~19~31 minecraft:leaves
fill ~24~26~31 ~24~27~31 minecraft:dirt
fill ~25~17~31 ~25~17~32 minecraft:grass
setblock ~25~18~31 minecraft:leaves
setblock ~25~26~31 minecraft:stained_hardened_clay 13
setblock ~25~27~31 minecraft:stained_hardened_clay 5
fill ~26~17~31 ~26~17~32 minecraft:stained_hardened_clay 5
setblock ~27~17~31 minecraft:grass
setblock ~27~18~31 minecraft:red_flower
setblock ~28~18~31 minecraft:grass
setblock ~28~19~31 minecraft:red_flower
fill ~29~18~31 ~30~18~31 minecraft:stained_hardened_clay 5
setblock ~29~19~31 minecraft:stone_block_slab 4
setblock ~31~18~31 minecraft:cobblestone
fill ~32~12~31 ~32~12~37 minecraft:stone
setblock ~32~18~31 minecraft:grass
setblock ~32~19~31 minecraft:stone_pressure_plate
fill ~33~12~31 ~34~12~31 minecraft:grass
setblock ~33~18~31 minecraft:cobblestone
fill ~33~19~31 ~34~19~31 minecraft:stone_block_slab
setblock ~34~18~31 minecraft:dirt 1
fill ~35~12~31 ~35~12~32 minecraft:stained_hardened_clay 5
setblock ~35~19~31 minecraft:cobblestone
setblock ~36~12~31 minecraft:grass
setblock ~36~19~31 minecraft:stained_hardened_clay 5
setblock ~37~19~31 minecraft:grass
fill ~38~12~31 ~38~12~33 minecraft:grass
setblock ~38~20~31 minecraft:stone_pressure_plate
fill ~39~19~31 ~40~19~31 minecraft:stone 5
fill ~40~12~31 ~40~12~32 minecraft:grass
setblock ~41~19~31 minecraft:grass
setblock ~42~12~31 minecraft:grass
fill ~42~19~31 ~42~19~33 minecraft:stained_hardened_clay 5
fill ~43~12~31 ~43~12~32 minecraft:stained_hardened_clay 5
fill ~43~19~31 ~43~19~33 minecraft:grass
setblock ~44~12~31 minecraft:grass
fill ~44~19~31 ~46~19~31 minecraft:dirt 1
fill ~44~20~31 ~44~20~32 minecraft:cobblestone
setblock ~45~12~31 minecraft:stained_hardened_clay 5
fill ~45~21~31 ~45~21~32 minecraft:cobblestone
setblock ~46~12~31 minecraft:grass
fill ~46~20~31 ~46~20~32 minecraft:cobblestone
setblock ~47~12~31 minecraft:stained_hardened_clay 5
setblock ~47~15~31 minecraft:dirt
setblock ~47~16~31 minecraft:stained_hardened_clay 5
fill ~48~13~31 ~49~14~31 minecraft:stonebrick
fill ~48~15~31 ~48~16~31 minecraft:stonebrick
setblock ~48~17~31 minecraft:stained_hardened_clay 5
setblock ~49~3~31 minecraft:stone 5
setblock ~49~5~31 minecraft:cobblestone
setblock ~49~7~31 minecraft:stonebrick
setblock ~49~9~31 minecraft:cobblestone
setblock ~49~12~31 minecraft:stone 6
setblock ~49~15~31 minecraft:iron_bars
fill ~49~16~31 ~49~17~31 minecraft:stonebrick
setblock ~49~18~31 minecraft:dirt
setblock ~49~19~31 minecraft:planks 5
fill ~50~3~31 ~50~3~35 minecraft:stained_glass 13
fill ~50~4~31 ~51~4~31 minecraft:stained_glass 13
setblock ~50~5~31 minecraft:stained_glass 5
setblock ~50~10~31 minecraft:stained_glass 13
setblock ~50~11~31 minecraft:stained_glass 5
setblock ~50~12~31 minecraft:stained_glass 13
fill ~50~13~31 ~51~13~31 minecraft:iron_bars
setblock ~50~14~31 minecraft:iron_bars
fill ~50~16~31 ~52~16~31 minecraft:iron_bars
setblock ~50~17~31 minecraft:iron_bars
fill ~51~5~31 ~51~5~34 minecraft:stained_glass 13
setblock ~51~7~31 minecraft:stained_glass 13
setblock ~51~8~31 minecraft:stained_glass 5
setblock ~51~9~31 minecraft:stained_glass 13
fill ~51~10~31 ~51~10~33 minecraft:stained_glass 5
fill ~51~11~31 ~51~11~36 minecraft:stained_glass 13
fill ~51~12~31 ~51~12~32 minecraft:stained_glass 5
setblock ~51~15~31 minecraft:iron_bars
fill ~51~17~31 ~52~17~31 minecraft:stonebrick
setblock ~51~18~31 minecraft:stonebrick
setblock ~51~19~31 minecraft:planks 5
fill ~52~3~31 ~52~4~31 minecraft:cobblestone
setblock ~52~5~31 minecraft:stone 6
setblock ~52~7~31 minecraft:stone
setblock ~52~9~31 minecraft:stonebrick
setblock ~52~10~31 minecraft:stone 5
setblock ~52~12~31 minecraft:stone 5
fill ~52~13~31 ~52~15~31 minecraft:stonebrick
fill ~52~18~31 ~53~18~31 minecraft:dirt
setblock ~53~12~31 minecraft:dirt 1
fill ~53~13~31 ~53~13~33 minecraft:cobblestone
fill ~53~14~31 ~53~14~32 minecraft:cobblestone
fill ~53~15~31 ~54~15~31 minecraft:stonebrick
setblock ~53~16~31 minecraft:stonebrick
setblock ~53~17~31 minecraft:dirt 1
setblock ~54~12~31 minecraft:stained_hardened_clay 5
setblock ~54~14~31 minecraft:stone 6
fill ~55~12~31 ~56~12~31 minecraft:grass
fill ~55~19~31 ~55~19~32 minecraft:dirt
fill ~55~20~31 ~55~20~33 minecraft:cobblestone
setblock ~56~19~31 minecraft:stained_hardened_clay 5
setblock ~57~12~31 minecraft:stained_hardened_clay 5
fill ~57~19~31 ~58~19~31 minecraft:grass
setblock ~58~12~31 minecraft:grass
setblock ~59~19~31 minecraft:cobblestone
setblock ~60~19~31 minecraft:stained_hardened_clay 5
setblock ~61~19~31 minecraft:dirt 1
fill ~62~12~31 ~63~12~32 minecraft:grass
fill ~63~18~31 ~65~18~31 minecraft:dirt
setblock ~63~19~31 minecraft:stone
setblock ~63~20~31 minecraft:stone_button 1
setblock ~64~12~31 minecraft:stained_hardened_clay 5
fill ~64~19~31 ~65~19~31 minecraft:grass
setblock ~65~20~31 minecraft:stone_pressure_plate
fill ~66~12~31 ~68~12~31 minecraft:stained_hardened_clay 5
setblock ~66~19~31 minecraft:stone 5
setblock ~66~20~31 minecraft:stone_button 1
fill ~67~17~31 ~69~17~31 minecraft:dirt 1
setblock ~67~18~31 minecraft:stained_hardened_clay 5
setblock ~67~19~31 minecraft:stone_block_slab
fill ~69~12~31 ~69~12~32 minecraft:grass
fill ~69~18~31 ~70~18~31 minecraft:stained_hardened_clay 5
fill ~70~12~31 ~70~12~38 minecraft:stone
fill ~70~16~31 ~70~16~36 minecraft:dirt
fill ~70~17~31 ~70~17~32 minecraft:dirt
fill ~71~16~31 ~71~16~32 minecraft:dirt 1
fill ~71~17~31 ~71~17~32 minecraft:stained_hardened_clay 5
fill ~72~16~31 ~73~16~31 minecraft:dirt
setblock ~72~18~31 minecraft:red_flower
fill ~73~17~31 ~73~17~32 minecraft:stained_hardened_clay 5
setblock ~74~15~31 minecraft:dirt 1
setblock ~74~16~31 minecraft:grass
setblock ~74~17~31 minecraft:tallgrass
fill ~75~15~31 ~75~15~32 minecraft:dirt
fill ~75~16~31 ~75~16~32 minecraft:stained_hardened_clay 5
setblock ~75~17~31 minecraft:leaves
fill ~75~26~31 ~75~28~31 minecraft:stained_hardened_clay 5
fill ~76~15~31 ~76~15~32 minecraft:dirt 1
fill ~76~16~31 ~77~17~31 minecraft:dirt 1
setblock ~76~18~31 minecraft:dirt
fill ~76~19~31 ~77~19~31 minecraft:dirt 1
setblock ~76~28~31 minecraft:stained_hardened_clay 13
fill ~77~12~31 ~77~12~36 minecraft:stone
setblock ~77~13~31 minecraft:dirt 1
fill ~77~14~31 ~77~14~32 minecraft:dirt
setblock ~77~15~31 minecraft:dirt
setblock ~77~18~31 minecraft:dirt 1
setblock ~77~20~31 minecraft:dirt
setblock ~77~21~31 minecraft:dirt 1
fill ~77~22~31 ~77~22~32 minecraft:dirt
setblock ~77~23~31 minecraft:dirt
setblock ~77~24~31 minecraft:dirt 1
fill ~77~25~31 ~77~26~31 minecraft:dirt
fill ~77~27~31 ~77~27~34 minecraft:dirt 1
fill ~77~28~31 ~77~28~32 minecraft:stained_hardened_clay 5
fill ~22~12~32 ~22~12~35 minecraft:stone
fill ~22~13~32 ~22~13~33 minecraft:dirt 1
fill ~22~14~32 ~22~18~32 minecraft:dirt
fill ~22~19~32 ~23~19~32 minecraft:dirt 1
fill ~22~20~32 ~22~20~34 minecraft:dirt 1
fill ~22~21~32 ~22~21~34 minecraft:dirt
setblock ~22~22~32 minecraft:dirt 1
fill ~22~23~32 ~22~23~34 minecraft:dirt
fill ~22~24~32 ~22~24~33 minecraft:dirt
fill ~22~25~32 ~22~26~33 minecraft:dirt 1
setblock ~22~27~32 minecraft:dirt 1
fill ~22~28~32 ~23~28~32 minecraft:stained_hardened_clay 13
fill ~23~16~32 ~23~17~33 minecraft:dirt 1
setblock ~23~20~32 minecraft:leaves
fill ~23~26~32 ~23~27~32 minecraft:stained_hardened_clay 5
fill ~24~16~32 ~24~16~34 minecraft:grass
setblock ~24~17~32 minecraft:leaves
fill ~24~18~32 ~24~18~33 minecraft:leaves
setblock ~24~19~32 minecraft:leaves
setblock ~24~27~32 minecraft:stained_hardened_clay 13
setblock ~25~12~32 minecraft:grass
setblock ~25~18~32 minecraft:red_flower
setblock ~26~12~32 minecraft:stained_hardened_clay 5
fill ~27~17~32 ~28~17~32 minecraft:stained_hardened_clay 5
setblock ~29~18~32 minecraft:stained_hardened_clay 5
setblock ~30~18~32 minecraft:grass
setblock ~30~19~32 minecraft:stone_button 1
setblock ~31~18~32 minecraft:stone 5
setblock ~32~18~32 minecraft:dirt 1
fill ~33~12~32 ~34~12~32 minecraft:stained_hardened_clay 5
fill ~33~18~32 ~34~18~32 minecraft:grass
setblock ~34~19~32 minecraft:stone_pressure_plate
setblock ~35~18~32 minecraft:stone 5
fill ~35~19~32 ~36~19~32 minecraft:stone_block_slab
fill ~36~12~32 ~37~12~32 minecraft:stained_hardened_clay 5
fill ~36~18~32 ~37~18~32 minecraft:dirt
setblock ~37~19~32 minecraft:stone_stairs 3
setblock ~38~19~32 minecraft:stone 5
setblock ~39~12~32 minecraft:stained_hardened_clay 5
fill ~39~19~32 ~41~19~32 minecraft:stained_hardened_clay 5
setblock ~42~12~32 minecraft:stained_hardened_clay 5
fill ~44~12~32 ~48~12~32 minecraft:stone
fill ~44~13~32 ~46~16~32 minecraft:dirt
setblock ~44~17~32 minecraft:dirt 1
fill ~44~18~32 ~47~18~32 minecraft:dirt
fill ~44~19~32 ~46~19~32 minecraft:dirt
setblock ~44~21~32 minecraft:cobblestone
fill ~45~17~32 ~46~17~32 minecraft:dirt
fill ~45~22~32 ~45~26~32 minecraft:cobblestone_wall
setblock ~45~27~32 minecraft:cobblestone_wall
setblock ~45~28~32 minecraft:stone_block_slab
setblock ~46~21~32 minecraft:cobblestone_wall
setblock ~46~27~32 minecraft:cobblestone_wall
fill ~47~13~32 ~48~13~32 minecraft:cobblestone
fill ~47~14~32 ~47~14~33 minecraft:cobblestone
fill ~47~15~32 ~47~17~32 minecraft:cobblestone
fill ~47~19~32 ~53~19~32 minecraft:cobblestone
setblock ~47~20~32 minecraft:cobblestone_wall
setblock ~47~26~32 minecraft:sea_lantern
setblock ~47~27~32 minecraft:cobblestone_wall
setblock ~47~28~32 minecraft:stone_block_slab
fill ~48~17~32 ~48~18~32 minecraft:cobblestone
setblock ~48~20~32 minecraft:stone_block_slab
fill ~49~3~32 ~49~5~33 minecraft:dirt
fill ~49~7~32 ~49~11~32 minecraft:dirt
setblock ~49~12~32 minecraft:stonebrick
setblock ~49~18~32 minecraft:cobblestone
fill ~50~4~32 ~51~4~32 minecraft:stained_glass 5
fill ~50~5~32 ~50~5~34 minecraft:stained_glass 13
setblock ~50~7~32 minecraft:stained_glass 13
setblock ~50~9~32 minecraft:stained_glass 13
fill ~50~10~32 ~50~10~34 minecraft:stained_glass 5
setblock ~50~11~32 minecraft:stained_glass 13
setblock ~50~12~32 minecraft:stained_glass 5
fill ~50~18~32 ~51~18~32 minecraft:stone_block_slab 11
setblock ~51~7~32 minecraft:stained_glass 5
fill ~51~8~32 ~51~8~33 minecraft:stained_glass 13
fill ~51~9~32 ~51~9~33 minecraft:stained_glass 5
fill ~52~3~32 ~52~5~34 minecraft:dirt
fill ~52~7~32 ~52~10~32 minecraft:dirt
setblock ~52~12~32 minecraft:dirt 1
fill ~52~18~32 ~53~18~32 minecraft:cobblestone
setblock ~52~20~32 minecraft:stone_block_slab
fill ~53~12~32 ~56~12~33 minecraft:stone
fill ~53~17~32 ~54~17~32 minecraft:cobblestone
setblock ~53~20~32 minecraft:cobblestone_wall
setblock ~53~26~32 minecraft:sea_lantern
