fill ~63~52~3 ~70~52~99 minecraft:concrete 11
fill ~64~49~3 ~76~49~101 minecraft:concrete 11
fill ~64~50~3 ~72~50~101 minecraft:concrete 11
fill ~64~51~3 ~71~51~101 minecraft:concrete 11
fill ~64~53~3 ~70~53~98 minecraft:concrete 11
fill ~64~54~3 ~70~55~97 minecraft:concrete 11
fill ~65~48~3 ~75~48~101 minecraft:concrete 11
fill ~65~56~3 ~72~56~97 minecraft:concrete 11
fill ~66~47~3 ~74~47~101 minecraft:concrete 11
fill ~66~57~3 ~74~57~97 minecraft:concrete 11
fill ~67~46~3 ~73~46~101 minecraft:concrete 11
fill ~67~58~3 ~73~58~96 minecraft:concrete 11
fill ~70~45~3 ~70~45~101 minecraft:concrete 11
fill ~70~59~3 ~70~59~97 minecraft:concrete 11
fill ~71~52~3 ~77~52~4 minecraft:concrete 13
fill ~71~53~3 ~76~54~4 minecraft:concrete 13
fill ~71~55~3 ~71~55~97 minecraft:concrete 11
fill ~72~51~3 ~76~51~5 minecraft:concrete 13
fill ~72~55~3 ~76~55~5 minecraft:concrete 13
fill ~73~50~3 ~75~50~4 minecraft:concrete 13
fill ~73~56~3 ~75~56~4 minecraft:concrete 13
fill ~76~50~3 ~76~50~97 minecraft:concrete 11
fill ~58~51~4 ~63~51~96 minecraft:concrete 11
fill ~58~52~4 ~62~53~96 minecraft:concrete 11
fill ~59~47~4 ~65~47~100 minecraft:concrete 11
fill ~59~48~4 ~64~48~100 minecraft:concrete 11
fill ~59~49~4 ~63~50~100 minecraft:concrete 11
fill ~59~54~4 ~63~57~97 minecraft:concrete 11
fill ~60~46~4 ~66~46~100 minecraft:concrete 11
fill ~60~58~4 ~66~58~98 minecraft:concrete 11
fill ~61~44~4 ~79~44~100 minecraft:concrete 11
fill ~61~45~4 ~69~45~100 minecraft:concrete 11
fill ~61~59~4 ~69~59~97 minecraft:concrete 11
fill ~61~60~4 ~79~60~96 minecraft:concrete 11
fill ~62~43~4 ~78~43~100 minecraft:concrete 11
fill ~62~61~4 ~78~61~95 minecraft:concrete 11
fill ~63~53~4 ~63~53~100 minecraft:concrete 11
fill ~64~42~4 ~76~42~100 minecraft:concrete 11
fill ~64~56~4 ~64~57~100 minecraft:concrete 11
fill ~64~62~4 ~76~62~96 minecraft:concrete 11
fill ~65~41~4 ~75~41~100 minecraft:concrete 11
fill ~65~57~4 ~65~57~100 minecraft:concrete 11
fill ~65~63~4 ~75~63~96 minecraft:concrete 11
fill ~69~40~4 ~71~40~100 minecraft:concrete 11
fill ~69~64~4 ~71~64~96 minecraft:concrete 11
fill ~71~45~4 ~79~45~100 minecraft:concrete 11
fill ~71~59~4 ~79~59~96 minecraft:concrete 11
fill ~74~46~4 ~80~46~100 minecraft:concrete 11
fill ~74~58~4 ~80~58~96 minecraft:concrete 11
fill ~75~47~4 ~81~47~100 minecraft:concrete 11
fill ~75~57~4 ~81~57~96 minecraft:concrete 11
fill ~76~48~4 ~81~48~100 minecraft:concrete 11
fill ~76~56~4 ~81~56~96 minecraft:concrete 11
fill ~77~49~4 ~81~49~98 minecraft:concrete 11
fill ~77~50~4 ~81~50~97 minecraft:concrete 11
fill ~77~51~4 ~82~51~96 minecraft:concrete 11
fill ~77~53~4 ~77~54~4 minecraft:concrete 13
fill ~77~55~4 ~81~55~96 minecraft:concrete 11
fill ~78~52~4 ~82~53~96 minecraft:concrete 11
fill ~78~54~4 ~81~54~96 minecraft:concrete 11
fill ~55~48~5 ~58~50~95 minecraft:concrete 11
fill ~55~51~5 ~57~51~96 minecraft:concrete 11
fill ~55~52~5 ~57~56~95 minecraft:concrete 11
fill ~56~46~5 ~59~46~96 minecraft:concrete 11
fill ~56~47~5 ~58~47~96 minecraft:concrete 11
fill ~56~57~5 ~58~58~99 minecraft:concrete 11
fill ~57~44~5 ~60~45~99 minecraft:concrete 11
fill ~57~59~5 ~60~59~99 minecraft:concrete 11
fill ~57~60~5 ~60~60~95 minecraft:concrete 11
fill ~58~43~5 ~61~43~99 minecraft:concrete 11
fill ~58~54~5 ~58~56~96 minecraft:concrete 11
fill ~58~61~5 ~61~61~96 minecraft:concrete 11
fill ~59~42~5 ~63~42~99 minecraft:concrete 11
fill ~59~58~5 ~59~58~99 minecraft:concrete 11
fill ~59~62~5 ~63~62~97 minecraft:concrete 11
fill ~60~41~5 ~64~41~99 minecraft:concrete 11
fill ~60~63~5 ~64~63~96 minecraft:concrete 11
fill ~61~40~5 ~68~40~99 minecraft:concrete 11
fill ~61~64~5 ~68~64~95 minecraft:concrete 11
fill ~62~39~5 ~72~39~99 minecraft:concrete 11
fill ~62~65~5 ~78~65~95 minecraft:concrete 11
fill ~64~38~5 ~67~38~99 minecraft:concrete 11
fill ~64~66~5 ~76~66~95 minecraft:concrete 11
fill ~66~37~5 ~66~37~99 minecraft:concrete 11
fill ~66~67~5 ~74~67~95 minecraft:concrete 11
fill ~67~37~5 ~74~37~8 minecraft:concrete 13
fill ~68~38~5 ~70~38~7 minecraft:concrete 13
fill ~71~38~5 ~71~38~99 minecraft:concrete 11
fill ~71~52~5 ~71~52~99 minecraft:concrete 11
fill ~71~53~5 ~71~53~98 minecraft:concrete 11
fill ~71~54~5 ~71~54~97 minecraft:concrete 11
fill ~72~38~5 ~76~38~7 minecraft:concrete 13
fill ~72~40~5 ~73~40~99 minecraft:concrete 11
fill ~72~52~5 ~76~54~5 minecraft:concrete 13
fill ~72~64~5 ~79~64~95 minecraft:concrete 11
fill ~73~39~5 ~78~39~8 minecraft:concrete 13
fill ~73~50~5 ~75~50~101 minecraft:concrete 11
fill ~73~56~5 ~75~56~96 minecraft:concrete 11
fill ~74~40~5 ~76~40~7 minecraft:concrete 13
fill ~76~41~5 ~80~41~99 minecraft:concrete 11
fill ~76~63~5 ~80~63~95 minecraft:concrete 11
fill ~77~40~5 ~78~40~99 minecraft:concrete 11
fill ~77~42~5 ~81~42~99 minecraft:concrete 11
fill ~77~52~5 ~77~54~96 minecraft:concrete 11
fill ~77~62~5 ~81~62~94 minecraft:concrete 11
fill ~79~40~5 ~79~40~7 minecraft:concrete 13
fill ~79~43~5 ~82~43~99 minecraft:concrete 11
fill ~79~61~5 ~82~61~95 minecraft:concrete 11
fill ~80~44~5 ~83~45~99 minecraft:concrete 11
fill ~80~59~5 ~83~60~95 minecraft:concrete 11
fill ~81~46~5 ~84~46~99 minecraft:concrete 11
fill ~81~58~5 ~84~58~95 minecraft:concrete 11
fill ~82~47~5 ~84~47~99 minecraft:concrete 11
fill ~82~48~5 ~85~48~97 minecraft:concrete 11
fill ~82~49~5 ~85~49~96 minecraft:concrete 11
fill ~82~50~5 ~85~50~95 minecraft:concrete 11
fill ~82~54~5 ~85~56~95 minecraft:concrete 11
fill ~82~57~5 ~84~57~95 minecraft:concrete 11
fill ~83~51~5 ~85~53~95 minecraft:concrete 11
fill ~52~49~6 ~54~55~96 minecraft:concrete 11
fill ~53~46~6 ~55~47~94 minecraft:concrete 11
fill ~53~48~6 ~54~48~95 minecraft:concrete 11
fill ~53~56~6 ~54~58~98 minecraft:concrete 11
fill ~54~44~6 ~56~44~95 minecraft:concrete 11
fill ~54~45~6 ~56~45~94 minecraft:concrete 11
fill ~54~59~6 ~56~59~96 minecraft:concrete 11
fill ~54~60~6 ~56~60~95 minecraft:concrete 11
fill ~55~42~6 ~58~42~98 minecraft:concrete 11
fill ~55~43~6 ~57~43~98 minecraft:concrete 11
fill ~55~57~6 ~55~58~98 minecraft:concrete 11
fill ~55~61~6 ~57~62~94 minecraft:concrete 11
fill ~56~41~6 ~59~41~98 minecraft:concrete 11
fill ~56~63~6 ~59~63~94 minecraft:concrete 11
fill ~57~40~6 ~60~40~98 minecraft:concrete 11
fill ~57~64~6 ~60~64~95 minecraft:concrete 11
fill ~58~39~6 ~61~39~98 minecraft:concrete 11
fill ~58~62~6 ~58~62~96 minecraft:concrete 11
fill ~58~65~6 ~61~65~96 minecraft:concrete 11
fill ~59~38~6 ~63~38~98 minecraft:concrete 11
fill ~59~66~6 ~63~66~95 minecraft:concrete 11
fill ~60~37~6 ~65~37~98 minecraft:concrete 11
fill ~60~67~6 ~65~67~95 minecraft:concrete 11
fill ~62~36~6 ~65~36~98 minecraft:concrete 11
fill ~62~68~6 ~69~68~94 minecraft:concrete 11
fill ~64~35~6 ~65~35~98 minecraft:concrete 11
fill ~64~69~6 ~68~69~93 minecraft:concrete 11
fill ~66~35~6 ~76~36~7 minecraft:concrete 13
fill ~67~34~6 ~73~34~8 minecraft:concrete 13
fill ~67~70~6 ~67~70~93 minecraft:concrete 11
fill ~68~70~6 ~73~70~8 minecraft:concrete 13
fill ~69~69~6 ~73~69~9 minecraft:concrete 13
fill ~70~68~6 ~72~68~8 minecraft:concrete 13
fill ~72~51~6 ~76~51~97 minecraft:concrete 11
fill ~72~52~6 ~72~52~99 minecraft:concrete 11
fill ~72~53~6 ~72~53~98 minecraft:concrete 11
fill ~72~54~6 ~72~55~97 minecraft:concrete 11
fill ~73~52~6 ~75~54~6 minecraft:concrete 13
fill ~73~55~6 ~76~55~97 minecraft:concrete 11
fill ~73~68~6 ~78~68~94 minecraft:concrete 11
fill ~74~69~6 ~76~69~6 minecraft:concrete 11
fill ~75~37~6 ~80~37~8 minecraft:concrete 13
fill ~75~67~6 ~80~67~94 minecraft:concrete 11
fill ~76~52~6 ~76~54~97 minecraft:concrete 11
fill ~77~36~6 ~78~36~8 minecraft:concrete 13
fill ~77~38~6 ~81~38~8 minecraft:concrete 13
fill ~77~66~6 ~81~66~93 minecraft:concrete 11
fill ~79~39~6 ~82~39~8 minecraft:concrete 13
fill ~79~65~6 ~82~65~93 minecraft:concrete 11
fill ~80~40~6 ~81~40~7 minecraft:concrete 13
fill ~80~64~6 ~83~64~94 minecraft:concrete 11
fill ~81~41~6 ~84~41~98 minecraft:concrete 11
fill ~81~63~6 ~84~63~94 minecraft:concrete 11
fill ~82~40~6 ~83~40~98 minecraft:concrete 11
fill ~82~42~6 ~85~42~98 minecraft:concrete 11
fill ~82~62~6 ~85~62~94 minecraft:concrete 11
fill ~83~43~6 ~85~43~98 minecraft:concrete 11
fill ~83~61~6 ~85~61~94 minecraft:concrete 11
fill ~84~44~6 ~86~45~98 minecraft:concrete 11
fill ~84~59~6 ~86~59~94 minecraft:concrete 11
fill ~84~60~6 ~86~60~93 minecraft:concrete 11
fill ~85~46~6 ~87~47~98 minecraft:concrete 11
fill ~85~57~6 ~87~58~94 minecraft:concrete 11
fill ~86~48~6 ~87~48~95 minecraft:concrete 11
fill ~86~49~6 ~88~49~94 minecraft:concrete 11
fill ~86~50~6 ~88~55~93 minecraft:concrete 11
fill ~86~56~6 ~87~56~94 minecraft:concrete 11
fill ~50~47~7 ~52~48~94 minecraft:concrete 11
fill ~50~49~7 ~51~57~97 minecraft:concrete 11
fill ~51~44~7 ~53~44~95 minecraft:concrete 11
fill ~51~45~7 ~53~45~94 minecraft:concrete 11
fill ~51~46~7 ~52~46~94 minecraft:concrete 11
fill ~51~58~7 ~52~60~97 minecraft:concrete 11
fill ~52~42~7 ~54~42~97 minecraft:concrete 11
fill ~52~43~7 ~54~43~96 minecraft:concrete 11
fill ~52~56~7 ~52~57~97 minecraft:concrete 11
fill ~52~61~7 ~54~62~94 minecraft:concrete 11
fill ~53~41~7 ~55~41~97 minecraft:concrete 11
fill ~53~59~7 ~53~59~97 minecraft:concrete 11
fill ~53~60~7 ~53~60~95 minecraft:concrete 11
fill ~53~63~7 ~55~63~94 minecraft:concrete 11
fill ~54~39~7 ~57~39~97 minecraft:concrete 11
fill ~54~40~7 ~56~40~97 minecraft:concrete 11
fill ~54~64~7 ~56~65~95 minecraft:concrete 11
fill ~55~38~7 ~58~38~97 minecraft:concrete 11
fill ~55~66~7 ~58~66~97 minecraft:concrete 11
fill ~56~37~7 ~59~37~97 minecraft:concrete 11
fill ~56~67~7 ~59~67~97 minecraft:concrete 11
fill ~57~36~7 ~61~36~97 minecraft:concrete 11
fill ~57~65~7 ~57~65~97 minecraft:concrete 11
fill ~57~68~7 ~61~68~95 minecraft:concrete 11
fill ~59~35~7 ~63~35~97 minecraft:concrete 11
fill ~59~69~7 ~63~69~94 minecraft:concrete 11
fill ~60~34~7 ~65~34~97 minecraft:concrete 11
fill ~60~70~7 ~66~70~93 minecraft:concrete 11
fill ~62~33~7 ~66~33~97 minecraft:concrete 11
fill ~62~71~7 ~67~71~93 minecraft:concrete 11
fill ~65~32~7 ~67~32~97 minecraft:concrete 11
fill ~65~72~7 ~67~72~92 minecraft:concrete 11
setblock ~66~34~7 minecraft:concrete 13
fill ~67~33~7 ~78~33~8 minecraft:concrete 13
fill ~68~32~7 ~75~32~8 minecraft:concrete 13
fill ~68~71~7 ~78~71~8 minecraft:concrete 13
fill ~68~72~7 ~75~72~8 minecraft:concrete 13
fill ~73~52~7 ~75~54~98 minecraft:concrete 11
fill ~74~34~7 ~80~34~9 minecraft:concrete 13
fill ~74~69~7 ~75~69~94 minecraft:concrete 11
fill ~74~70~7 ~79~70~9 minecraft:concrete 13
fill ~76~69~7 ~78~69~9 minecraft:concrete 13
fill ~77~35~7 ~81~35~9 minecraft:concrete 13
fill ~79~36~7 ~83~36~9 minecraft:concrete 13
fill ~79~68~7 ~83~68~93 minecraft:concrete 11
fill ~79~69~7 ~81~69~92 minecraft:concrete 11
fill ~80~70~7 ~80~70~93 minecraft:concrete 11
fill ~81~37~7 ~84~37~9 minecraft:concrete 13
fill ~81~67~7 ~84~67~93 minecraft:concrete 11
fill ~82~38~7 ~85~38~8 minecraft:concrete 13
fill ~82~66~7 ~85~66~93 minecraft:concrete 11
fill ~83~39~7 ~86~39~97 minecraft:concrete 11
fill ~83~65~7 ~86~65~93 minecraft:concrete 11
fill ~84~40~7 ~86~40~97 minecraft:concrete 11
fill ~84~64~7 ~86~64~93 minecraft:concrete 11
fill ~85~41~7 ~87~41~97 minecraft:concrete 11
fill ~85~63~7 ~87~63~92 minecraft:concrete 11
fill ~86~42~7 ~88~43~97 minecraft:concrete 11
fill ~86~61~7 ~88~62~93 minecraft:concrete 11
fill ~87~44~7 ~89~45~97 minecraft:concrete 11
fill ~87~59~7 ~89~59~94 minecraft:concrete 11
fill ~87~60~7 ~89~60~92 minecraft:concrete 11
fill ~88~46~7 ~89~47~97 minecraft:concrete 11
fill ~88~48~7 ~90~48~95 minecraft:concrete 11
fill ~88~56~7 ~90~57~92 minecraft:concrete 11
fill ~88~58~7 ~89~58~95 minecraft:concrete 11
fill ~89~49~7 ~90~49~94 minecraft:concrete 11
fill ~89~50~7 ~90~53~93 minecraft:concrete 11
fill ~89~54~7 ~90~55~92 minecraft:concrete 11
fill ~90~47~7 ~90~47~97 minecraft:concrete 11
fill ~48~47~8 ~49~57~96 minecraft:concrete 11
fill ~49~44~8 ~50~46~96 minecraft:concrete 11
fill ~49~58~8 ~50~60~96 minecraft:concrete 11
fill ~50~42~8 ~51~43~96 minecraft:concrete 11
fill ~50~61~8 ~51~62~96 minecraft:concrete 11
fill ~51~40~8 ~53~40~96 minecraft:concrete 11
fill ~51~41~8 ~52~41~96 minecraft:concrete 11
fill ~51~63~8 ~52~64~96 minecraft:concrete 11
fill ~52~39~8 ~53~39~96 minecraft:concrete 11
fill ~52~65~8 ~53~65~96 minecraft:concrete 11
fill ~53~37~8 ~55~37~96 minecraft:concrete 11
fill ~53~38~8 ~54~38~96 minecraft:concrete 11
fill ~53~64~8 ~53~64~95 minecraft:concrete 11
fill ~53~66~8 ~54~67~96 minecraft:concrete 11
fill ~54~36~8 ~56~36~96 minecraft:concrete 11
fill ~54~68~8 ~56~68~96 minecraft:concrete 11
fill ~55~35~8 ~58~35~96 minecraft:concrete 11
fill ~55~67~8 ~55~67~96 minecraft:concrete 11
fill ~55~69~8 ~58~69~96 minecraft:concrete 11
fill ~57~34~8 ~59~34~96 minecraft:concrete 11
fill ~57~70~8 ~59~70~95 minecraft:concrete 11
fill ~58~33~8 ~61~33~96 minecraft:concrete 11
fill ~58~71~8 ~61~71~93 minecraft:concrete 11
fill ~60~32~8 ~64~32~96 minecraft:concrete 11
fill ~60~72~8 ~64~72~92 minecraft:concrete 11
fill ~62~31~8 ~68~31~90 minecraft:concrete 11
fill ~62~73~8 ~68~73~91 minecraft:concrete 11
fill ~65~30~8 ~69~30~88 minecraft:concrete 11
fill ~65~74~8 ~67~74~91 minecraft:concrete 11
fill ~66~34~8 ~66~36~97 minecraft:concrete 11
fill ~67~35~8 ~76~36~8 minecraft:concrete 13
fill ~68~38~8 ~70~38~99 minecraft:concrete 11
fill ~68~74~8 ~75~74~11 minecraft:concrete 13
fill ~69~31~8 ~78~31~9 minecraft:concrete 13
fill ~69~73~8 ~78~73~10 minecraft:concrete 13
fill ~70~30~8 ~75~30~8 minecraft:concrete 13
fill ~72~38~8 ~72~38~99 minecraft:concrete 11
fill ~73~38~8 ~76~38~8 minecraft:concrete 13
fill ~74~40~8 ~76~40~99 minecraft:concrete 11
fill ~76~32~8 ~80~32~10 minecraft:concrete 13
fill ~76~72~8 ~80~72~11 minecraft:concrete 13
fill ~79~33~8 ~82~33~10 minecraft:concrete 13
fill ~79~40~8 ~81~40~98 minecraft:concrete 11
fill ~79~71~8 ~80~71~9 minecraft:concrete 13
fill ~81~34~8 ~83~34~11 minecraft:concrete 13
fill ~81~70~8 ~83~70~91 minecraft:concrete 11
fill ~81~71~8 ~82~71~91 minecraft:concrete 11
fill ~82~35~8 ~85~35~10 minecraft:concrete 13
fill ~82~69~8 ~85~69~91 minecraft:concrete 11
fill ~84~36~8 ~86~36~11 minecraft:concrete 13
fill ~84~68~8 ~86~68~92 minecraft:concrete 11
fill ~85~37~8 ~86~37~10 minecraft:concrete 13
fill ~85~67~8 ~87~67~92 minecraft:concrete 11
fill ~86~38~8 ~87~38~96 minecraft:concrete 11
fill ~86~66~8 ~87~66~92 minecraft:concrete 11
fill ~87~37~8 ~87~37~96 minecraft:concrete 11
fill ~87~39~8 ~88~40~96 minecraft:concrete 11
fill ~87~64~8 ~89~64~91 minecraft:concrete 11
fill ~87~65~8 ~88~65~91 minecraft:concrete 11
fill ~88~41~8 ~89~41~96 minecraft:concrete 11
fill ~88~63~8 ~89~63~92 minecraft:concrete 11
fill ~89~40~8 ~89~40~96 minecraft:concrete 11
fill ~89~42~8 ~90~43~96 minecraft:concrete 11
fill ~89~61~8 ~90~62~91 minecraft:concrete 11
fill ~90~44~8 ~91~46~96 minecraft:concrete 11
fill ~90~58~8 ~91~59~93 minecraft:concrete 11
fill ~90~60~8 ~91~60~92 minecraft:concrete 11
fill ~91~47~8 ~92~47~96 minecraft:concrete 11
fill ~91~48~8 ~92~48~93 minecraft:concrete 11
fill ~91~49~8 ~92~49~92 minecraft:concrete 11
fill ~91~50~8 ~92~57~91 minecraft:concrete 11
fill ~46~47~9 ~47~57~95 minecraft:concrete 11
fill ~47~44~9 ~48~46~95 minecraft:concrete 11
fill ~47~58~9 ~48~60~95 minecraft:concrete 11
fill ~48~42~9 ~49~43~95 minecraft:concrete 11
fill ~48~61~9 ~49~62~95 minecraft:concrete 11
fill ~49~40~9 ~50~41~95 minecraft:concrete 11
fill ~49~63~9 ~50~64~95 minecraft:concrete 11
fill ~50~38~9 ~52~38~95 minecraft:concrete 11
fill ~50~39~9 ~51~39~95 minecraft:concrete 11
fill ~50~65~9 ~51~66~95 minecraft:concrete 11
fill ~51~37~9 ~52~37~95 minecraft:concrete 11
fill ~51~67~9 ~52~67~95 minecraft:concrete 11
fill ~52~36~9 ~53~36~95 minecraft:concrete 11
fill ~52~66~9 ~52~66~95 minecraft:concrete 11
fill ~52~68~9 ~53~68~95 minecraft:concrete 11
fill ~53~35~9 ~54~35~95 minecraft:concrete 11
fill ~53~69~9 ~54~69~95 minecraft:concrete 11
fill ~54~34~9 ~56~34~95 minecraft:concrete 11
fill ~54~70~9 ~56~70~95 minecraft:concrete 11
fill ~55~33~9 ~57~33~95 minecraft:concrete 11
fill ~55~71~9 ~57~71~95 minecraft:concrete 11
fill ~56~32~9 ~59~32~95 minecraft:concrete 11
fill ~56~72~9 ~59~72~95 minecraft:concrete 11
fill ~58~31~9 ~61~31~95 minecraft:concrete 11
fill ~58~73~9 ~61~73~92 minecraft:concrete 11
fill ~60~30~9 ~64~30~95 minecraft:concrete 11
fill ~60~74~9 ~64~74~91 minecraft:concrete 11
fill ~62~29~9 ~71~29~88 minecraft:concrete 11
fill ~62~75~9 ~66~75~91 minecraft:concrete 11
fill ~65~28~9 ~72~28~87 minecraft:concrete 11
fill ~65~76~9 ~66~76~91 minecraft:concrete 11
fill ~67~33~9 ~68~33~97 minecraft:concrete 11
fill ~67~34~9 ~67~37~98 minecraft:concrete 11
fill ~67~75~9 ~78~75~10 minecraft:concrete 13
fill ~67~76~9 ~75~76~10 minecraft:concrete 13
fill ~68~32~9 ~68~32~92 minecraft:concrete 11
fill ~68~34~9 ~73~35~9 minecraft:concrete 13
fill ~68~36~9 ~70~36~9 minecraft:concrete 13
fill ~68~37~9 ~73~37~99 minecraft:concrete 11
fill ~68~70~9 ~68~72~94 minecraft:concrete 11
fill ~69~32~9 ~75~33~9 minecraft:concrete 13
fill ~69~70~9 ~73~72~9 minecraft:concrete 13
fill ~70~30~9 ~70~30~88 minecraft:concrete 11
fill ~70~68~9 ~72~68~95 minecraft:concrete 11
fill ~71~30~9 ~80~30~9 minecraft:concrete 13
fill ~71~36~9 ~71~36~98 minecraft:concrete 11
fill ~72~29~9 ~78~29~10 minecraft:concrete 13
fill ~72~36~9 ~76~36~9 minecraft:concrete 13
fill ~73~28~9 ~75~28~9 minecraft:concrete 13
fill ~73~38~9 ~73~39~99 minecraft:concrete 11
fill ~74~35~9 ~76~35~9 minecraft:concrete 13
fill ~74~37~9 ~76~38~9 minecraft:concrete 13
fill ~74~39~9 ~82~39~98 minecraft:concrete 11
fill ~74~71~9 ~78~71~9 minecraft:concrete 13
fill ~74~72~9 ~75~72~10 minecraft:concrete 13
fill ~76~33~9 ~78~33~10 minecraft:concrete 13
fill ~76~74~9 ~80~74~12 minecraft:concrete 13
fill ~77~36~9 ~78~38~93 minecraft:concrete 11
fill ~79~31~9 ~82~31~11 minecraft:concrete 13
fill ~79~37~9 ~80~38~9 minecraft:concrete 13
fill ~79~73~9 ~82~73~12 minecraft:concrete 13
fill ~81~32~9 ~84~32~11 minecraft:concrete 13
setblock ~81~38~9 minecraft:concrete 13
fill ~81~72~9 ~81~72~11 minecraft:concrete 13
fill ~82~38~9 ~82~38~97 minecraft:concrete 11
fill ~82~72~9 ~84~72~91 minecraft:concrete 11
fill ~83~33~9 ~85~33~11 minecraft:concrete 13
fill ~83~38~9 ~85~38~9 minecraft:concrete 13
fill ~83~71~9 ~85~71~91 minecraft:concrete 11
fill ~84~34~9 ~86~34~12 minecraft:concrete 13
fill ~84~70~9 ~86~70~91 minecraft:concrete 11
fill ~86~35~9 ~87~35~12 minecraft:concrete 13
fill ~86~69~9 ~87~69~91 minecraft:concrete 11
fill ~87~36~9 ~87~36~11 minecraft:concrete 13
fill ~87~68~9 ~88~68~91 minecraft:concrete 11
fill ~88~36~9 ~88~38~95 minecraft:concrete 11
fill ~88~66~9 ~90~66~90 minecraft:concrete 11
fill ~88~67~9 ~89~67~91 minecraft:concrete 11
fill ~89~37~9 ~89~39~95 minecraft:concrete 11
fill ~89~65~9 ~90~65~90 minecraft:concrete 11
fill ~90~38~9 ~90~41~95 minecraft:concrete 11
fill ~90~63~9 ~91~64~91 minecraft:concrete 11
fill ~91~40~9 ~91~43~95 minecraft:concrete 11
fill ~91~61~9 ~92~61~91 minecraft:concrete 11
fill ~91~62~9 ~92~62~90 minecraft:concrete 11
fill ~92~42~9 ~92~46~95 minecraft:concrete 11
fill ~92~58~9 ~93~59~91 minecraft:concrete 11
fill ~92~60~9 ~93~60~90 minecraft:concrete 11
fill ~93~44~9 ~93~47~95 minecraft:concrete 11
fill ~93~48~9 ~94~48~93 minecraft:concrete 11
fill ~93~49~9 ~94~49~92 minecraft:concrete 11
fill ~93~50~9 ~94~57~91 minecraft:concrete 11
fill ~94~47~9 ~94~47~95 minecraft:concrete 11
fill ~44~49~10 ~45~55~89 minecraft:concrete 11
fill ~45~45~10 ~46~46~94 minecraft:concrete 11
fill ~45~47~10 ~45~48~94 minecraft:concrete 11
fill ~45~56~10 ~45~59~94 minecraft:concrete 11
fill ~46~42~10 ~47~43~94 minecraft:concrete 11
fill ~46~44~10 ~46~44~94 minecraft:concrete 11
fill ~46~58~10 ~46~62~94 minecraft:concrete 11
fill ~47~40~10 ~48~41~94 minecraft:concrete 11
fill ~47~61~10 ~47~64~94 minecraft:concrete 11
fill ~48~38~10 ~49~39~94 minecraft:concrete 11
fill ~48~63~10 ~48~66~94 minecraft:concrete 11
fill ~49~37~10 ~50~37~94 minecraft:concrete 11
fill ~49~65~10 ~49~67~94 minecraft:concrete 11
fill ~50~36~10 ~51~36~94 minecraft:concrete 11
fill ~50~67~10 ~50~68~94 minecraft:concrete 11
fill ~51~34~10 ~53~34~94 minecraft:concrete 11
fill ~51~35~10 ~52~35~94 minecraft:concrete 11
fill ~51~68~10 ~51~68~94 minecraft:concrete 11
fill ~51~69~10 ~52~69~91 minecraft:concrete 11
fill ~51~70~10 ~53~70~90 minecraft:concrete 11
fill ~52~33~10 ~54~33~94 minecraft:concrete 11
fill ~52~71~10 ~54~71~89 minecraft:concrete 11
fill ~54~32~10 ~55~32~94 minecraft:concrete 11
fill ~54~72~10 ~55~72~91 minecraft:concrete 11
fill ~55~31~10 ~57~31~94 minecraft:concrete 11
fill ~55~73~10 ~57~73~94 minecraft:concrete 11
fill ~56~30~10 ~59~30~94 minecraft:concrete 11
fill ~56~74~10 ~59~74~93 minecraft:concrete 11
fill ~58~29~10 ~61~29~94 minecraft:concrete 11
fill ~58~75~10 ~61~75~91 minecraft:concrete 11
fill ~60~28~10 ~64~28~92 minecraft:concrete 11
fill ~60~76~10 ~64~76~91 minecraft:concrete 11
fill ~63~27~10 ~75~27~87 minecraft:concrete 11
fill ~63~77~10 ~66~77~90 minecraft:concrete 11
fill ~67~26~10 ~73~26~87 minecraft:concrete 11
fill ~67~77~10 ~77~77~10 minecraft:concrete 13
fill ~67~78~10 ~67~78~90 minecraft:concrete 11
fill ~68~34~10 ~69~36~98 minecraft:concrete 11
fill ~68~78~10 ~73~78~11 minecraft:concrete 13
fill ~69~31~10 ~71~31~89 minecraft:concrete 11
fill ~69~32~10 ~69~33~91 minecraft:concrete 11
fill ~69~69~10 ~73~69~95 minecraft:concrete 11
fill ~69~70~10 ~69~70~95 minecraft:concrete 11
fill ~69~71~10 ~69~72~93 minecraft:concrete 11
fill ~70~32~10 ~75~33~10 minecraft:concrete 13
fill ~70~34~10 ~72~34~10 minecraft:concrete 13
fill ~70~35~10 ~79~35~90 minecraft:concrete 11
fill ~70~36~10 ~70~36~98 minecraft:concrete 11
fill ~70~70~10 ~72~72~10 minecraft:concrete 13
fill ~71~30~10 ~71~30~88 minecraft:concrete 11
fill ~72~30~10 ~84~30~10 minecraft:concrete 13
fill ~72~31~10 ~78~31~10 minecraft:concrete 13
fill ~72~36~10 ~76~36~98 minecraft:concrete 11
fill ~73~28~10 ~74~28~88 minecraft:concrete 11
fill ~73~34~10 ~74~34~97 minecraft:concrete 11
fill ~73~70~10 ~74~70~94 minecraft:concrete 11
fill ~73~71~10 ~73~72~10 minecraft:concrete 13
fill ~74~37~10 ~76~38~98 minecraft:concrete 11
fill ~74~71~10 ~74~71~93 minecraft:concrete 11
fill ~75~28~10 ~80~28~10 minecraft:concrete 13
fill ~75~34~10 ~80~34~10 minecraft:concrete 13
fill ~75~70~10 ~79~71~10 minecraft:concrete 13
fill ~76~27~10 ~77~27~11 minecraft:concrete 13
fill ~76~69~10 ~78~69~94 minecraft:concrete 11
fill ~76~76~10 ~80~76~13 minecraft:concrete 13
fill ~79~29~10 ~82~29~13 minecraft:concrete 13
fill ~79~36~10 ~81~38~92 minecraft:concrete 11
fill ~79~75~10 ~82~75~13 minecraft:concrete 13
fill ~80~35~10 ~81~35~10 minecraft:concrete 13
fill ~80~71~10 ~80~71~93 minecraft:concrete 11
fill ~81~74~10 ~83~74~11 minecraft:concrete 13
fill ~82~36~10 ~83~37~10 minecraft:concrete 13
fill ~83~31~10 ~85~31~10 minecraft:concrete 13
fill ~83~38~10 ~85~38~97 minecraft:concrete 11
fill ~83~73~10 ~85~73~90 minecraft:concrete 11
setblock ~84~37~10 minecraft:concrete 13
fill ~84~74~10 ~84~74~89 minecraft:concrete 11
fill ~85~32~10 ~86~32~13 minecraft:concrete 13
fill ~85~72~10 ~86~72~92 minecraft:concrete 11
fill ~86~33~10 ~88~33~12 minecraft:concrete 13
fill ~86~71~10 ~88~71~90 minecraft:concrete 11
fill ~87~34~10 ~89~34~11 minecraft:concrete 13
fill ~87~70~10 ~89~70~90 minecraft:concrete 11
fill ~88~35~10 ~88~35~12 minecraft:concrete 13
fill ~88~69~10 ~89~69~90 minecraft:concrete 11
fill ~89~35~10 ~89~36~94 minecraft:concrete 11
fill ~89~68~10 ~90~68~89 minecraft:concrete 11
fill ~90~36~10 ~90~37~94 minecraft:concrete 11
fill ~90~67~10 ~91~67~89 minecraft:concrete 11
fill ~91~37~10 ~91~39~94 minecraft:concrete 11
fill ~91~65~10 ~92~66~90 minecraft:concrete 11
fill ~92~38~10 ~92~41~94 minecraft:concrete 11
fill ~92~63~10 ~93~64~90 minecraft:concrete 11
fill ~93~40~10 ~93~43~94 minecraft:concrete 11
fill ~93~61~10 ~94~62~90 minecraft:concrete 11
fill ~94~42~10 ~94~46~94 minecraft:concrete 11
fill ~94~58~10 ~95~59~90 minecraft:concrete 11
fill ~94~60~10 ~94~60~90 minecraft:concrete 11
fill ~95~45~10 ~95~48~94 minecraft:concrete 11
fill ~95~49~10 ~96~49~91 minecraft:concrete 11
fill ~95~50~10 ~96~50~90 minecraft:concrete 11
fill ~95~51~10 ~96~55~89 minecraft:concrete 11
fill ~95~56~10 ~95~56~91 minecraft:concrete 11
fill ~95~57~10 ~95~57~90 minecraft:concrete 11
fill ~43~46~11 ~44~48~88 minecraft:concrete 11
fill ~43~49~11 ~43~58~88 minecraft:concrete 11
fill ~44~43~11 ~45~44~93 minecraft:concrete 11
fill ~44~45~11 ~44~45~93 minecraft:concrete 11
fill ~44~56~11 ~44~61~93 minecraft:concrete 11
fill ~45~40~11 ~46~41~93 minecraft:concrete 11
fill ~45~42~11 ~45~42~93 minecraft:concrete 11
fill ~45~60~11 ~45~64~93 minecraft:concrete 11
fill ~46~39~11 ~47~39~93 minecraft:concrete 11
fill ~46~63~11 ~46~65~93 minecraft:concrete 11
fill ~47~37~11 ~48~37~93 minecraft:concrete 11
fill ~47~38~11 ~47~38~93 minecraft:concrete 11
fill ~47~65~11 ~47~67~93 minecraft:concrete 11
fill ~48~36~11 ~49~36~93 minecraft:concrete 11
fill ~48~67~11 ~48~68~93 minecraft:concrete 11
fill ~49~34~11 ~50~35~93 minecraft:concrete 11
fill ~49~68~11 ~49~69~93 minecraft:concrete 11
fill ~49~70~11 ~50~70~90 minecraft:concrete 11
fill ~50~33~11 ~51~33~93 minecraft:concrete 11
fill ~50~69~11 ~50~69~91 minecraft:concrete 11
fill ~50~71~11 ~51~71~89 minecraft:concrete 11
fill ~51~32~11 ~53~32~93 minecraft:concrete 11
fill ~51~72~11 ~53~72~89 minecraft:concrete 11
fill ~52~31~11 ~54~31~93 minecraft:concrete 11
fill ~52~73~11 ~54~73~88 minecraft:concrete 11
fill ~54~30~11 ~55~30~93 minecraft:concrete 11
fill ~54~74~11 ~55~74~11 minecraft:concrete 11
fill ~55~29~11 ~57~29~93 minecraft:concrete 11
fill ~55~75~11 ~55~75~15 minecraft:concrete 13
fill ~56~75~11 ~57~75~93 minecraft:concrete 11
fill ~57~28~11 ~59~28~93 minecraft:concrete 11
fill ~57~76~11 ~59~76~93 minecraft:concrete 11
fill ~58~27~11 ~62~27~86 minecraft:concrete 11
fill ~58~77~11 ~62~77~92 minecraft:concrete 11
fill ~61~26~11 ~66~26~84 minecraft:concrete 11
fill ~61~78~11 ~66~78~89 minecraft:concrete 11
fill ~64~25~11 ~76~25~85 minecraft:concrete 11
fill ~64~79~11 ~67~79~89 minecraft:concrete 11
fill ~67~75~11 ~67~76~91 minecraft:concrete 11
fill ~67~77~11 ~67~77~90 minecraft:concrete 11
fill ~68~75~11 ~78~75~11 minecraft:concrete 13
fill ~68~76~11 ~75~77~11 minecraft:concrete 13
fill ~68~79~11 ~76~79~11 minecraft:concrete 13
fill ~69~73~11 ~72~73~92 minecraft:concrete 11
fill ~70~32~11 ~72~34~91 minecraft:concrete 11
fill ~70~70~11 ~72~70~94 minecraft:concrete 11
fill ~70~71~11 ~73~71~93 minecraft:concrete 11
fill ~70~72~11 ~75~72~92 minecraft:concrete 11
fill ~72~29~11 ~75~29~88 minecraft:concrete 11
fill ~72~30~11 ~72~31~89 minecraft:concrete 11
fill ~73~30~11 ~86~30~11 minecraft:concrete 13
fill ~73~31~11 ~78~31~11 minecraft:concrete 13
fill ~73~32~11 ~75~32~11 minecraft:concrete 13
fill ~73~33~11 ~76~33~90 minecraft:concrete 11
fill ~73~73~11 ~78~73~11 minecraft:concrete 13
fill ~74~26~11 ~78~26~88 minecraft:concrete 11
fill ~74~78~11 ~79~78~14 minecraft:concrete 13
fill ~75~28~11 ~75~28~90 minecraft:concrete 11
fill ~75~34~11 ~80~34~89 minecraft:concrete 11
fill ~75~70~11 ~79~70~93 minecraft:concrete 11
fill ~75~71~11 ~75~71~93 minecraft:concrete 11
fill ~76~28~11 ~83~28~11 minecraft:concrete 13
fill ~76~29~11 ~78~29~11 minecraft:concrete 13
fill ~76~32~11 ~76~32~90 minecraft:concrete 11
fill ~76~71~11 ~78~71~11 minecraft:concrete 13
fill ~76~77~11 ~82~77~14 minecraft:concrete 13
fill ~77~32~11 ~79~33~11 minecraft:concrete 13
fill ~78~27~11 ~82~27~12 minecraft:concrete 13
fill ~79~26~11 ~79~26~13 minecraft:concrete 13
fill ~79~71~11 ~79~71~93 minecraft:concrete 11
fill ~80~32~11 ~80~33~88 minecraft:concrete 11
fill ~80~35~11 ~82~35~90 minecraft:concrete 11
fill ~81~33~11 ~82~33~11 minecraft:concrete 13
fill ~81~76~11 ~83~76~13 minecraft:concrete 13
fill ~82~36~11 ~82~37~93 minecraft:concrete 11
fill ~83~29~11 ~85~29~13 minecraft:concrete 13
fill ~83~31~11 ~83~31~89 minecraft:concrete 11
fill ~83~35~11 ~85~35~11 minecraft:concrete 13
setblock ~83~36~11 minecraft:concrete 13
fill ~83~37~11 ~86~37~96 minecraft:concrete 11
fill ~83~75~11 ~83~75~13 minecraft:concrete 13
fill ~84~31~11 ~88~31~12 minecraft:concrete 13
fill ~84~75~11 ~85~75~88 minecraft:concrete 11
fill ~85~74~11 ~86~74~89 minecraft:concrete 11
fill ~86~73~11 ~88~73~89 minecraft:concrete 11
fill ~87~32~11 ~89~32~11 minecraft:concrete 13
fill ~87~72~11 ~89~72~88 minecraft:concrete 11
setblock ~89~33~11 minecraft:concrete 13
fill ~89~71~11 ~90~71~89 minecraft:concrete 11
fill ~90~33~11 ~90~35~93 minecraft:concrete 11
fill ~90~69~11 ~91~70~88 minecraft:concrete 11
fill ~91~34~11 ~91~36~93 minecraft:concrete 11
fill ~91~68~11 ~92~68~88 minecraft:concrete 11
fill ~92~36~11 ~92~37~93 minecraft:concrete 11
fill ~92~67~11 ~93~67~89 minecraft:concrete 11
fill ~93~37~11 ~93~39~93 minecraft:concrete 11
fill ~93~65~11 ~94~65~90 minecraft:concrete 11
fill ~93~66~11 ~93~66~90 minecraft:concrete 11
fill ~94~39~11 ~94~41~93 minecraft:concrete 11
fill ~94~63~11 ~95~64~90 minecraft:concrete 11
fill ~95~40~11 ~95~44~93 minecraft:concrete 11
fill ~95~60~11 ~96~61~89 minecraft:concrete 11
fill ~95~62~11 ~95~62~89 minecraft:concrete 11
fill ~96~43~11 ~96~48~93 minecraft:concrete 11
fill ~96~56~11 ~97~58~88 minecraft:concrete 11
fill ~96~59~11 ~96~59~89 minecraft:concrete 11
fill ~97~46~11 ~97~48~93 minecraft:concrete 11
fill ~97~49~11 ~97~49~91 minecraft:concrete 11
fill ~97~50~11 ~97~50~90 minecraft:concrete 11
fill ~97~51~11 ~97~55~89 minecraft:concrete 11
fill ~41~49~12 ~42~55~87 minecraft:concrete 11
fill ~42~44~12 ~43~44~92 minecraft:concrete 11
fill ~42~45~12 ~43~45~89 minecraft:concrete 11
fill ~42~46~12 ~42~46~88 minecraft:concrete 11
fill ~42~47~12 ~42~48~87 minecraft:concrete 11
fill ~42~56~12 ~42~60~92 minecraft:concrete 11
fill ~43~41~12 ~44~42~92 minecraft:concrete 11
fill ~43~43~12 ~43~43~92 minecraft:concrete 11
fill ~43~59~12 ~43~63~92 minecraft:concrete 11
fill ~44~39~12 ~45~39~92 minecraft:concrete 11
fill ~44~40~12 ~44~40~92 minecraft:concrete 11
fill ~44~62~12 ~44~65~92 minecraft:concrete 11
fill ~45~37~12 ~46~38~92 minecraft:concrete 11
fill ~45~65~12 ~45~67~92 minecraft:concrete 11
fill ~46~36~12 ~47~36~92 minecraft:concrete 11
fill ~46~66~12 ~46~68~92 minecraft:concrete 11
fill ~47~35~12 ~48~35~92 minecraft:concrete 11
fill ~47~68~12 ~47~69~92 minecraft:concrete 11
fill ~48~33~12 ~49~33~92 minecraft:concrete 11
fill ~48~34~12 ~48~34~92 minecraft:concrete 11
fill ~48~69~12 ~48~70~92 minecraft:concrete 11
fill ~48~71~12 ~49~71~90 minecraft:concrete 11
fill ~49~32~12 ~50~32~92 minecraft:concrete 11
fill ~49~72~12 ~50~72~89 minecraft:concrete 11
fill ~50~31~12 ~51~31~92 minecraft:concrete 11
fill ~50~73~12 ~51~73~88 minecraft:concrete 11
fill ~51~30~12 ~53~30~84 minecraft:concrete 11
fill ~51~74~12 ~51~74~87 minecraft:concrete 11
fill ~52~74~12 ~54~74~14 minecraft:concrete 13
fill ~53~29~12 ~54~29~92 minecraft:concrete 11
fill ~53~75~12 ~54~75~15 minecraft:concrete 13
fill ~54~28~12 ~56~28~92 minecraft:concrete 11
fill ~54~76~12 ~56~76~14 minecraft:concrete 13
fill ~55~27~12 ~57~27~92 minecraft:concrete 11
fill ~55~74~12 ~55~74~89 minecraft:concrete 11
fill ~55~77~12 ~56~77~14 minecraft:concrete 13
fill ~57~26~12 ~60~26~84 minecraft:concrete 11
fill ~57~77~12 ~57~78~87 minecraft:concrete 11
fill ~58~78~12 ~60~78~88 minecraft:concrete 11
fill ~59~25~12 ~63~25~83 minecraft:concrete 11
fill ~59~79~12 ~63~79~90 minecraft:concrete 11
fill ~62~24~12 ~78~24~83 minecraft:concrete 11
fill ~62~80~12 ~68~80~89 minecraft:concrete 11
fill ~67~23~12 ~73~23~88 minecraft:concrete 11
fill ~67~81~12 ~69~81~90 minecraft:concrete 11
fill ~68~74~12 ~74~74~92 minecraft:concrete 11
fill ~68~75~12 ~68~79~91 minecraft:concrete 11
fill ~69~75~12 ~78~75~12 minecraft:concrete 13
fill ~69~76~12 ~75~77~12 minecraft:concrete 13
fill ~69~78~12 ~73~80~12 minecraft:concrete 13
fill ~70~81~12 ~73~81~13 minecraft:concrete 13
fill ~73~30~12 ~76~31~89 minecraft:concrete 11
fill ~73~32~12 ~75~32~91 minecraft:concrete 11
fill ~73~73~12 ~77~73~92 minecraft:concrete 11
fill ~74~79~12 ~81~79~15 minecraft:concrete 13
fill ~74~80~12 ~78~80~15 minecraft:concrete 13
setblock ~75~74~12 minecraft:concrete 13
fill ~76~27~12 ~77~27~90 minecraft:concrete 11
fill ~76~28~12 ~76~28~90 minecraft:concrete 11
fill ~76~29~12 ~76~29~89 minecraft:concrete 11
fill ~76~71~12 ~78~72~92 minecraft:concrete 11
fill ~77~25~12 ~79~25~90 minecraft:concrete 11
fill ~77~28~12 ~86~28~12 minecraft:concrete 13
fill ~77~29~12 ~78~30~12 minecraft:concrete 13
fill ~77~31~12 ~79~33~88 minecraft:concrete 11
setblock ~78~73~12 minecraft:concrete 13
fill ~79~30~12 ~88~30~13 minecraft:concrete 13
fill ~79~72~12 ~81~72~92 minecraft:concrete 11
fill ~80~25~12 ~81~26~12 minecraft:concrete 13
fill ~80~31~12 ~82~31~12 minecraft:concrete 13
fill ~80~78~12 ~83~78~13 minecraft:concrete 13
fill ~81~32~12 ~83~34~88 minecraft:concrete 11
fill ~81~74~12 ~82~74~12 minecraft:concrete 13
fill ~82~26~12 ~83~26~13 minecraft:concrete 13
fill ~83~27~12 ~85~27~13 minecraft:concrete 13
fill ~83~35~12 ~83~36~92 minecraft:concrete 11
fill ~83~74~12 ~83~74~91 minecraft:concrete 11
fill ~83~77~12 ~84~77~12 minecraft:concrete 13
fill ~84~32~12 ~84~33~12 minecraft:concrete 13
fill ~84~35~12 ~85~35~12 minecraft:concrete 13
fill ~84~36~12 ~87~36~95 minecraft:concrete 11
setblock ~84~76~12 minecraft:concrete 13
fill ~85~33~12 ~85~33~13 minecraft:concrete 13
fill ~85~76~12 ~86~76~88 minecraft:concrete 11
fill ~85~77~12 ~85~77~88 minecraft:concrete 11
fill ~86~29~12 ~87~29~15 minecraft:concrete 13
fill ~86~75~12 ~87~75~88 minecraft:concrete 11
fill ~87~32~12 ~88~32~12 minecraft:concrete 13
fill ~87~34~12 ~88~34~12 minecraft:concrete 13
fill ~87~74~12 ~89~74~88 minecraft:concrete 11
fill ~89~30~12 ~89~34~92 minecraft:concrete 11
fill ~89~73~12 ~90~73~87 minecraft:concrete 11
fill ~90~31~12 ~90~32~92 minecraft:concrete 11
fill ~90~72~12 ~91~72~88 minecraft:concrete 11
fill ~91~32~12 ~91~33~92 minecraft:concrete 11
fill ~91~71~12 ~92~71~88 minecraft:concrete 11
fill ~92~33~12 ~92~35~92 minecraft:concrete 11
fill ~92~69~12 ~93~69~87 minecraft:concrete 11
fill ~92~70~12 ~92~70~88 minecraft:concrete 11
fill ~93~35~12 ~93~36~92 minecraft:concrete 11
fill ~93~68~12 ~94~68~87 minecraft:concrete 11
fill ~94~36~12 ~94~38~92 minecraft:concrete 11
fill ~94~66~12 ~95~67~87 minecraft:concrete 11
fill ~95~37~12 ~95~39~92 minecraft:concrete 11
fill ~95~65~12 ~96~65~87 minecraft:concrete 11
fill ~96~39~12 ~96~42~92 minecraft:concrete 11
fill ~96~62~12 ~97~63~87 minecraft:concrete 11
fill ~96~64~12 ~96~64~88 minecraft:concrete 11
fill ~97~41~12 ~97~45~92 minecraft:concrete 11
fill ~97~59~12 ~98~60~87 minecraft:concrete 11
fill ~97~61~12 ~97~61~89 minecraft:concrete 11
fill ~98~44~12 ~98~48~92 minecraft:concrete 11
fill ~98~49~12 ~99~49~91 minecraft:concrete 11
fill ~98~50~12 ~99~50~90 minecraft:concrete 11
fill ~98~51~12 ~99~55~87 minecraft:concrete 11
fill ~98~56~12 ~98~56~88 minecraft:concrete 11
fill ~98~57~12 ~98~58~87 minecraft:concrete 11
fill ~40~47~13 ~41~47~86 minecraft:concrete 11
fill ~40~48~13 ~41~48~14 minecraft:concrete 11
fill ~40~49~13 ~40~57~14 minecraft:concrete 11
fill ~41~43~13 ~42~43~91 minecraft:concrete 11
fill ~41~44~13 ~41~44~91 minecraft:concrete 11
fill ~41~45~13 ~41~45~89 minecraft:concrete 11
fill ~41~46~13 ~41~46~88 minecraft:concrete 11
fill ~41~56~13 ~41~61~91 minecraft:concrete 11
fill ~42~40~13 ~43~40~91 minecraft:concrete 11
fill ~42~41~13 ~42~42~91 minecraft:concrete 11
fill ~42~61~13 ~42~64~91 minecraft:concrete 11
fill ~43~38~13 ~44~38~91 minecraft:concrete 11
fill ~43~39~13 ~43~39~91 minecraft:concrete 11
fill ~43~64~13 ~43~66~91 minecraft:concrete 11
fill ~44~37~13 ~44~37~91 minecraft:concrete 11
fill ~44~66~13 ~44~67~91 minecraft:concrete 11
fill ~45~35~13 ~46~35~91 minecraft:concrete 11
fill ~45~36~13 ~45~36~91 minecraft:concrete 11
fill ~45~68~13 ~45~69~91 minecraft:concrete 11
fill ~46~34~13 ~47~34~91 minecraft:concrete 11
fill ~46~69~13 ~46~70~91 minecraft:concrete 11
fill ~47~32~13 ~48~32~91 minecraft:concrete 11
fill ~47~33~13 ~47~33~91 minecraft:concrete 11
fill ~47~70~13 ~47~72~91 minecraft:concrete 11
fill ~48~31~13 ~49~31~83 minecraft:concrete 11
fill ~48~72~13 ~48~73~91 minecraft:concrete 11
fill ~49~30~13 ~50~30~82 minecraft:concrete 11
fill ~49~73~13 ~49~73~90 minecraft:concrete 11
fill ~49~74~13 ~50~74~88 minecraft:concrete 11
fill ~50~29~13 ~52~29~81 minecraft:concrete 11
fill ~50~75~13 ~50~75~88 minecraft:concrete 11
fill ~51~75~13 ~52~75~15 minecraft:concrete 13
fill ~52~28~13 ~53~28~83 minecraft:concrete 11
fill ~52~76~13 ~53~76~16 minecraft:concrete 13
fill ~53~27~13 ~54~27~84 minecraft:concrete 11
fill ~53~77~13 ~54~77~16 minecraft:concrete 13
fill ~55~26~13 ~56~26~87 minecraft:concrete 11
fill ~55~78~13 ~56~78~14 minecraft:concrete 13
fill ~56~25~13 ~58~25~84 minecraft:concrete 11
fill ~56~79~13 ~58~79~86 minecraft:concrete 11
fill ~58~24~13 ~61~24~83 minecraft:concrete 11
fill ~58~80~13 ~61~80~88 minecraft:concrete 11
fill ~61~23~13 ~66~23~82 minecraft:concrete 11
fill ~61~81~13 ~66~81~90 minecraft:concrete 11
fill ~65~22~13 ~75~22~16 minecraft:concrete 11
fill ~65~82~13 ~70~82~91 minecraft:concrete 11
fill ~69~75~13 ~76~75~91 minecraft:concrete 11
fill ~69~76~13 ~71~76~91 minecraft:concrete 11
fill ~69~77~13 ~69~80~91 minecraft:concrete 11
fill ~70~77~13 ~75~77~13 minecraft:concrete 13
fill ~70~78~13 ~73~80~13 minecraft:concrete 13
fill ~71~82~13 ~75~82~14 minecraft:concrete 13
fill ~72~76~13 ~75~76~13 minecraft:concrete 13
fill ~74~23~13 ~79~23~85 minecraft:concrete 11
fill ~74~81~13 ~79~81~15 minecraft:concrete 13
fill ~75~74~13 ~78~74~91 minecraft:concrete 11
fill ~77~28~13 ~78~28~89 minecraft:concrete 11
fill ~77~29~13 ~78~30~88 minecraft:concrete 11
fill ~77~75~13 ~78~75~13 minecraft:concrete 13
fill ~78~27~13 ~78~27~89 minecraft:concrete 11
fill ~78~73~13 ~82~73~91 minecraft:concrete 11
fill ~79~24~13 ~82~24~91 minecraft:concrete 11
fill ~79~27~13 ~82~28~13 minecraft:concrete 13
fill ~79~74~13 ~81~74~13 minecraft:concrete 13
fill ~79~80~13 ~82~80~14 minecraft:concrete 13
fill ~80~25~13 ~84~25~90 minecraft:concrete 11
fill ~80~26~13 ~81~26~13 minecraft:concrete 13
fill ~80~31~13 ~82~31~88 minecraft:concrete 11
fill ~82~74~13 ~82~74~90 minecraft:concrete 11
fill ~82~79~13 ~83~79~13 minecraft:concrete 13
fill ~83~28~13 ~88~28~13 minecraft:concrete 13
setblock ~83~77~13 minecraft:concrete 13
fill ~84~26~13 ~85~26~14 minecraft:concrete 13
fill ~84~31~13 ~84~35~89 minecraft:concrete 11
fill ~84~76~13 ~84~79~89 minecraft:concrete 11
fill ~85~31~13 ~87~31~13 minecraft:concrete 13
fill ~85~34~13 ~87~34~13 minecraft:concrete 13
fill ~85~35~13 ~88~35~94 minecraft:concrete 11
fill ~85~78~13 ~85~78~89 minecraft:concrete 11
fill ~86~27~13 ~87~27~15 minecraft:concrete 13
fill ~86~33~13 ~87~33~13 minecraft:concrete 13
fill ~86~77~13 ~87~77~88 minecraft:concrete 11
setblock ~87~32~13 minecraft:concrete 13
fill ~87~76~13 ~88~76~88 minecraft:concrete 11
fill ~88~29~13 ~89~29~13 minecraft:concrete 13
fill ~88~31~13 ~88~34~93 minecraft:concrete 11
fill ~88~75~13 ~90~75~87 minecraft:concrete 11
fill ~90~29~13 ~90~30~91 minecraft:concrete 11
fill ~90~74~13 ~91~74~87 minecraft:concrete 11
fill ~91~30~13 ~91~31~91 minecraft:concrete 11
fill ~91~73~13 ~92~73~87 minecraft:concrete 11
fill ~92~31~13 ~92~32~91 minecraft:concrete 11
fill ~92~72~13 ~93~72~87 minecraft:concrete 11
fill ~93~32~13 ~93~34~91 minecraft:concrete 11
fill ~93~70~13 ~94~70~86 minecraft:concrete 11
fill ~93~71~13 ~93~71~87 minecraft:concrete 11
fill ~94~34~13 ~94~35~91 minecraft:concrete 11
fill ~94~69~13 ~95~69~86 minecraft:concrete 11
fill ~95~35~13 ~95~36~91 minecraft:concrete 11
fill ~95~68~13 ~95~68~87 minecraft:concrete 11
fill ~96~37~13 ~96~38~91 minecraft:concrete 11
fill ~96~66~13 ~97~66~86 minecraft:concrete 11
fill ~96~67~13 ~96~67~86 minecraft:concrete 11
fill ~97~38~13 ~97~40~91 minecraft:concrete 11
fill ~97~64~13 ~98~64~86 minecraft:concrete 11
fill ~97~65~13 ~97~65~87 minecraft:concrete 11
fill ~98~40~13 ~98~43~91 minecraft:concrete 11
fill ~98~61~13 ~99~61~85 minecraft:concrete 11
fill ~98~62~13 ~98~63~86 minecraft:concrete 11
fill ~99~43~13 ~99~48~91 minecraft:concrete 11
fill ~99~56~13 ~100~57~86 minecraft:concrete 11
fill ~99~58~13 ~99~60~87 minecraft:concrete 11
fill ~100~47~13 ~100~49~91 minecraft:concrete 11
fill ~100~50~13 ~100~50~88 minecraft:concrete 11
fill ~100~51~13 ~100~51~87 minecraft:concrete 11
fill ~100~52~13 ~100~55~86 minecraft:concrete 11
fill ~39~46~14 ~40~46~15 minecraft:concrete 11
fill ~39~47~14 ~39~51~18 minecraft:concrete 13
fill ~39~52~14 ~39~58~85 minecraft:concrete 11
fill ~40~42~14 ~41~42~90 minecraft:concrete 11
fill ~40~43~14 ~40~44~90 minecraft:concrete 11
fill ~40~45~14 ~40~45~89 minecraft:concrete 11
fill ~40~58~14 ~40~62~90 minecraft:concrete 11
fill ~41~40~14 ~41~41~90 minecraft:concrete 11
fill ~41~62~14 ~41~64~90 minecraft:concrete 11
fill ~42~38~14 ~42~39~90 minecraft:concrete 11
fill ~42~65~14 ~42~66~90 minecraft:concrete 11
fill ~43~36~14 ~44~36~90 minecraft:concrete 11
fill ~43~37~14 ~43~37~90 minecraft:concrete 11
fill ~43~67~14 ~43~68~90 minecraft:concrete 11
fill ~44~34~14 ~45~34~90 minecraft:concrete 11
fill ~44~35~14 ~44~35~90 minecraft:concrete 11
fill ~44~68~14 ~44~70~90 minecraft:concrete 11
fill ~45~33~14 ~46~33~90 minecraft:concrete 11
fill ~45~70~14 ~45~71~90 minecraft:concrete 11
fill ~46~32~14 ~46~32~90 minecraft:concrete 11
fill ~46~71~14 ~46~72~90 minecraft:concrete 11
fill ~47~31~14 ~47~31~83 minecraft:concrete 11
fill ~47~73~14 ~47~73~90 minecraft:concrete 11
fill ~48~30~14 ~48~30~81 minecraft:concrete 11
fill ~48~74~14 ~48~74~90 minecraft:concrete 11
fill ~49~29~14 ~49~29~81 minecraft:concrete 11
fill ~49~75~14 ~49~75~89 minecraft:concrete 11
fill ~50~28~14 ~51~28~81 minecraft:concrete 11
fill ~50~76~14 ~51~76~14 minecraft:concrete 13
fill ~51~27~14 ~52~27~81 minecraft:concrete 11
fill ~51~77~14 ~52~77~15 minecraft:concrete 13
fill ~52~26~14 ~54~26~81 minecraft:concrete 11
fill ~52~78~14 ~54~78~16 minecraft:concrete 13
fill ~54~25~14 ~55~25~87 minecraft:concrete 11
fill ~54~79~14 ~55~79~15 minecraft:concrete 13
fill ~56~24~14 ~57~24~84 minecraft:concrete 11
fill ~56~80~14 ~57~80~86 minecraft:concrete 11
fill ~58~23~14 ~60~23~82 minecraft:concrete 11
fill ~58~81~14 ~60~81~90 minecraft:concrete 11
fill ~60~22~14 ~64~22~16 minecraft:concrete 11
fill ~60~82~14 ~64~82~90 minecraft:concrete 11
fill ~64~21~14 ~76~21~14 minecraft:concrete 11
fill ~64~83~14 ~74~83~90 minecraft:concrete 11
fill ~70~77~14 ~74~77~90 minecraft:concrete 11
fill ~70~78~14 ~70~81~91 minecraft:concrete 11
fill ~71~78~14 ~73~81~14 minecraft:concrete 13
fill ~72~76~14 ~77~76~90 minecraft:concrete 11
setblock ~75~77~14 minecraft:concrete 13
fill ~75~83~14 ~76~83~15 minecraft:concrete 13
fill ~76~22~14 ~80~22~16 minecraft:concrete 11
fill ~76~82~14 ~80~82~15 minecraft:concrete 13
fill ~77~75~14 ~83~75~90 minecraft:concrete 11
fill ~78~76~14 ~82~76~14 minecraft:concrete 13
fill ~79~26~14 ~83~26~89 minecraft:concrete 11
fill ~79~27~14 ~79~27~89 minecraft:concrete 11
fill ~79~28~14 ~79~30~88 minecraft:concrete 11
fill ~79~74~14 ~81~74~90 minecraft:concrete 11
fill ~80~23~14 ~82~23~17 minecraft:concrete 11
fill ~80~27~14 ~82~29~14 minecraft:concrete 13
fill ~80~30~14 ~83~30~88 minecraft:concrete 11
fill ~80~78~14 ~82~78~14 minecraft:concrete 13
fill ~80~81~14 ~82~81~14 minecraft:concrete 13
setblock ~82~79~14 minecraft:concrete 13
fill ~83~24~14 ~84~24~85 minecraft:concrete 11
fill ~83~27~14 ~83~27~90 minecraft:concrete 11
fill ~83~28~14 ~83~29~89 minecraft:concrete 11
fill ~83~76~14 ~83~80~89 minecraft:concrete 11
fill ~84~27~14 ~85~30~14 minecraft:concrete 13
fill ~84~80~14 ~84~80~90 minecraft:concrete 11
fill ~85~25~14 ~86~25~90 minecraft:concrete 11
fill ~85~31~14 ~87~34~90 minecraft:concrete 11
fill ~85~79~14 ~86~79~90 minecraft:concrete 11
fill ~86~26~14 ~88~26~14 minecraft:concrete 13
fill ~86~28~14 ~88~28~14 minecraft:concrete 13
fill ~86~30~14 ~88~30~14 minecraft:concrete 13
fill ~86~78~14 ~88~78~89 minecraft:concrete 11
setblock ~88~27~14 minecraft:concrete 13
setblock ~88~29~14 minecraft:concrete 13
fill ~88~77~14 ~89~77~89 minecraft:concrete 11
fill ~89~27~14 ~89~29~90 minecraft:concrete 11
fill ~89~76~14 ~90~76~88 minecraft:concrete 11
fill ~90~28~14 ~90~28~90 minecraft:concrete 11
fill ~91~29~14 ~91~29~90 minecraft:concrete 11
fill ~91~75~14 ~91~75~87 minecraft:concrete 11
fill ~92~30~14 ~92~30~90 minecraft:concrete 11
fill ~92~74~14 ~92~74~87 minecraft:concrete 11
fill ~93~31~14 ~93~31~82 minecraft:concrete 11
fill ~93~73~14 ~93~73~88 minecraft:concrete 11
fill ~94~32~14 ~94~33~82 minecraft:concrete 11
fill ~94~71~14 ~95~71~86 minecraft:concrete 11
fill ~94~72~14 ~94~72~87 minecraft:concrete 11
fill ~95~33~14 ~95~34~90 minecraft:concrete 11
fill ~95~70~14 ~96~70~86 minecraft:concrete 11
fill ~96~34~14 ~96~36~90 minecraft:concrete 11
fill ~96~68~14 ~97~68~86 minecraft:concrete 11
fill ~96~69~14 ~96~69~86 minecraft:concrete 11
fill ~97~36~14 ~97~37~90 minecraft:concrete 11
fill ~97~67~14 ~97~67~86 minecraft:concrete 11
fill ~98~38~14 ~98~39~90 minecraft:concrete 11
fill ~98~65~14 ~98~66~86 minecraft:concrete 11
fill ~99~40~14 ~99~42~90 minecraft:concrete 11
fill ~99~62~14 ~100~62~84 minecraft:concrete 11
fill ~99~63~14 ~99~64~85 minecraft:concrete 11
fill ~100~42~14 ~100~46~90 minecraft:concrete 11
fill ~100~58~14 ~101~58~86 minecraft:concrete 11
fill ~100~59~14 ~100~59~87 minecraft:concrete 11
fill ~100~60~14 ~100~60~86 minecraft:concrete 11
fill ~100~61~14 ~100~61~85 minecraft:concrete 11
fill ~101~46~14 ~101~49~90 minecraft:concrete 11
fill ~101~50~14 ~101~50~88 minecraft:concrete 11
fill ~101~51~14 ~101~51~87 minecraft:concrete 11
fill ~101~52~14 ~101~54~86 minecraft:concrete 11
fill ~101~55~14 ~101~57~85 minecraft:concrete 11
fill ~38~45~15 ~38~50~19 minecraft:concrete 13
fill ~38~51~15 ~38~51~18 minecraft:concrete 13
fill ~38~52~15 ~38~52~17 minecraft:concrete 13
fill ~38~53~15 ~38~59~84 minecraft:concrete 11
fill ~39~42~15 ~39~44~89 minecraft:concrete 11
setblock ~39~45~15 minecraft:concrete 11
fill ~39~59~15 ~39~60~89 minecraft:concrete 11
fill ~39~61~15 ~39~62~84 minecraft:concrete 11
fill ~40~39~15 ~41~39~89 minecraft:concrete 11
fill ~40~40~15 ~40~41~89 minecraft:concrete 11
fill ~40~48~15 ~40~50~17 minecraft:concrete 13
fill ~40~51~15 ~40~57~86 minecraft:concrete 11
fill ~40~63~15 ~40~65~89 minecraft:concrete 11
fill ~41~37~15 ~42~37~89 minecraft:concrete 11
fill ~41~38~15 ~41~38~89 minecraft:concrete 11
fill ~41~48~15 ~41~48~87 minecraft:concrete 11
fill ~41~65~15 ~41~67~89 minecraft:concrete 11
fill ~42~35~15 ~43~35~89 minecraft:concrete 11
fill ~42~36~15 ~42~36~89 minecraft:concrete 11
fill ~42~67~15 ~42~69~89 minecraft:concrete 11
fill ~43~34~15 ~43~34~89 minecraft:concrete 11
fill ~43~69~15 ~43~70~89 minecraft:concrete 11
fill ~44~32~15 ~45~32~89 minecraft:concrete 11
fill ~44~33~15 ~44~33~89 minecraft:concrete 11
fill ~44~71~15 ~44~72~89 minecraft:concrete 11
fill ~45~31~15 ~46~31~81 minecraft:concrete 11
fill ~45~72~15 ~45~73~89 minecraft:concrete 11
fill ~46~30~15 ~47~30~80 minecraft:concrete 11
fill ~46~73~15 ~46~74~89 minecraft:concrete 11
fill ~47~29~15 ~48~29~79 minecraft:concrete 11
fill ~47~74~15 ~47~75~89 minecraft:concrete 11
fill ~48~28~15 ~49~28~79 minecraft:concrete 11
fill ~48~75~15 ~48~76~89 minecraft:concrete 11
fill ~49~27~15 ~50~27~80 minecraft:concrete 11
fill ~49~76~15 ~50~77~88 minecraft:concrete 11
fill ~50~26~15 ~51~26~80 minecraft:concrete 11
fill ~50~78~15 ~50~78~89 minecraft:concrete 11
setblock ~51~76~15 minecraft:concrete 13
setblock ~51~78~15 minecraft:concrete 13
fill ~52~25~15 ~53~25~81 minecraft:concrete 11
fill ~52~74~15 ~54~74~87 minecraft:concrete 11
fill ~52~79~15 ~53~79~15 minecraft:concrete 13
fill ~53~24~15 ~55~24~83 minecraft:concrete 11
fill ~53~80~15 ~55~80~86 minecraft:concrete 11
fill ~54~76~15 ~55~76~15 minecraft:concrete 13
fill ~55~23~15 ~57~23~83 minecraft:concrete 11
fill ~55~77~15 ~55~78~15 minecraft:concrete 13
fill ~55~81~15 ~57~81~87 minecraft:concrete 11
fill ~56~76~15 ~56~76~88 minecraft:concrete 11
fill ~56~77~15 ~56~77~87 minecraft:concrete 11
fill ~56~78~15 ~56~78~86 minecraft:concrete 11
fill ~57~22~15 ~59~22~19 minecraft:concrete 11
fill ~57~82~15 ~59~82~89 minecraft:concrete 11
fill ~60~21~15 ~62~21~15 minecraft:concrete 11
fill ~60~83~15 ~63~83~89 minecraft:concrete 11
fill ~63~20~15 ~67~20~23 minecraft:snow
fill ~63~21~15 ~65~21~23 minecraft:snow
fill ~63~84~15 ~77~84~79 minecraft:concrete 11
fill ~66~21~15 ~80~21~15 minecraft:concrete 11
fill ~68~20~15 ~77~20~15 minecraft:concrete 11
fill ~71~78~15 ~76~78~89 minecraft:concrete 11
fill ~71~79~15 ~71~82~90 minecraft:concrete 11
fill ~72~79~15 ~73~81~15 minecraft:concrete 13
fill ~72~82~15 ~74~82~91 minecraft:concrete 11
fill ~75~77~15 ~82~77~88 minecraft:concrete 11
setblock ~75~82~15 minecraft:concrete 13
fill ~77~78~15 ~81~78~15 minecraft:concrete 13
fill ~77~83~15 ~79~83~15 minecraft:concrete 13
fill ~78~76~15 ~82~76~89 minecraft:concrete 11
fill ~79~80~15 ~81~80~15 minecraft:concrete 13
fill ~80~27~15 ~82~27~89 minecraft:concrete 11
fill ~80~28~15 ~82~29~88 minecraft:concrete 11
fill ~80~81~15 ~81~81~15 minecraft:concrete 13
fill ~80~83~15 ~80~83~89 minecraft:concrete 11
fill ~81~22~15 ~83~22~15 minecraft:concrete 11
setblock ~81~82~15 minecraft:concrete 13
fill ~82~78~15 ~82~82~88 minecraft:concrete 11
fill ~83~23~15 ~85~23~17 minecraft:concrete 11
fill ~83~81~15 ~85~81~89 minecraft:concrete 11
fill ~83~82~15 ~83~82~89 minecraft:concrete 11
fill ~84~26~15 ~90~26~89 minecraft:concrete 11
fill ~84~27~15 ~84~28~90 minecraft:concrete 11
fill ~84~29~15 ~84~30~89 minecraft:concrete 11
fill ~85~24~15 ~87~24~89 minecraft:concrete 11
fill ~85~27~15 ~85~29~15 minecraft:concrete 13
fill ~85~30~15 ~88~30~90 minecraft:concrete 11
fill ~85~80~15 ~87~80~89 minecraft:concrete 11
fill ~86~28~15 ~87~28~15 minecraft:concrete 13
fill ~87~25~15 ~88~25~89 minecraft:concrete 11
fill ~87~79~15 ~88~79~89 minecraft:concrete 11
fill ~88~27~15 ~88~29~90 minecraft:concrete 11
fill ~89~78~15 ~90~78~89 minecraft:concrete 11
fill ~90~27~15 ~91~27~89 minecraft:concrete 11
fill ~90~77~15 ~91~77~89 minecraft:concrete 11
fill ~91~28~15 ~92~28~81 minecraft:concrete 11
fill ~91~76~15 ~92~76~88 minecraft:concrete 11
fill ~92~29~15 ~93~29~80 minecraft:concrete 11
fill ~92~75~15 ~93~75~87 minecraft:concrete 11
fill ~93~30~15 ~94~30~79 minecraft:concrete 11
fill ~93~74~15 ~94~74~88 minecraft:concrete 11
fill ~94~31~15 ~95~31~79 minecraft:concrete 11
fill ~94~73~15 ~95~73~88 minecraft:concrete 11
fill ~95~32~15 ~96~32~80 minecraft:concrete 11
fill ~95~72~15 ~96~72~87 minecraft:concrete 11
fill ~96~33~15 ~96~33~82 minecraft:concrete 11
fill ~96~71~15 ~96~71~86 minecraft:concrete 11
fill ~97~34~15 ~97~35~89 minecraft:concrete 11
fill ~97~69~15 ~98~69~87 minecraft:concrete 11
fill ~97~70~15 ~97~70~87 minecraft:concrete 11
fill ~98~35~15 ~98~37~89 minecraft:concrete 11
fill ~98~67~15 ~99~67~86 minecraft:concrete 11
fill ~98~68~15 ~98~68~86 minecraft:concrete 11
fill ~99~37~15 ~99~39~89 minecraft:concrete 11
fill ~99~65~15 ~100~65~85 minecraft:concrete 11
fill ~99~66~15 ~99~66~87 minecraft:concrete 11
fill ~100~39~15 ~100~41~89 minecraft:concrete 11
fill ~100~63~15 ~100~64~84 minecraft:concrete 11
fill ~101~42~15 ~101~45~89 minecraft:concrete 11
fill ~101~59~15 ~102~59~84 minecraft:concrete 11
fill ~101~60~15 ~101~60~86 minecraft:concrete 11
fill ~101~61~15 ~101~61~85 minecraft:concrete 11
fill ~101~62~15 ~101~62~84 minecraft:concrete 11
fill ~102~45~15 ~102~49~89 minecraft:concrete 11
fill ~102~50~15 ~102~50~88 minecraft:concrete 11
fill ~102~51~15 ~102~51~87 minecraft:concrete 11
fill ~102~52~15 ~102~54~86 minecraft:concrete 11
fill ~102~55~15 ~102~57~85 minecraft:concrete 11
fill ~102~58~15 ~102~58~84 minecraft:concrete 11
fill ~37~44~16 ~38~44~19 minecraft:concrete 13
fill ~37~45~16 ~37~50~20 minecraft:concrete 13
fill ~37~51~16 ~37~51~18 minecraft:concrete 13
fill ~37~52~16 ~37~52~17 minecraft:concrete 13
fill ~37~53~16 ~37~60~83 minecraft:concrete 11
fill ~38~41~16 ~39~41~88 minecraft:concrete 11
fill ~38~42~16 ~38~43~88 minecraft:concrete 11
fill ~38~60~16 ~38~61~83 minecraft:concrete 11
fill ~38~62~16 ~38~63~82 minecraft:concrete 11
fill ~39~39~16 ~39~40~88 minecraft:concrete 11
fill ~39~45~16 ~39~46~18 minecraft:concrete 13
fill ~39~63~16 ~39~65~83 minecraft:concrete 11
fill ~40~37~16 ~40~38~88 minecraft:concrete 11
fill ~40~46~16 ~40~46~88 minecraft:concrete 11
fill ~40~66~16 ~40~66~88 minecraft:concrete 11
fill ~40~67~16 ~40~67~82 minecraft:concrete 11
fill ~41~35~16 ~41~36~88 minecraft:concrete 11
fill ~41~68~16 ~41~69~83 minecraft:concrete 11
fill ~42~33~16 ~43~33~88 minecraft:concrete 11
fill ~42~34~16 ~42~34~88 minecraft:concrete 11
fill ~42~70~16 ~42~71~88 minecraft:concrete 11
fill ~43~32~16 ~43~32~88 minecraft:concrete 11
fill ~43~71~16 ~43~72~88 minecraft:concrete 11
fill ~44~31~16 ~44~31~81 minecraft:concrete 11
fill ~44~73~16 ~44~73~88 minecraft:concrete 11
fill ~45~29~16 ~46~29~78 minecraft:concrete 11
fill ~45~30~16 ~45~30~79 minecraft:concrete 11
fill ~45~74~16 ~45~75~88 minecraft:concrete 11
fill ~46~28~16 ~47~28~78 minecraft:concrete 11
fill ~46~75~16 ~46~76~88 minecraft:concrete 11
fill ~47~27~16 ~48~27~78 minecraft:concrete 11
fill ~47~76~16 ~47~77~88 minecraft:concrete 11
fill ~48~77~16 ~48~77~88 minecraft:concrete 11
fill ~49~26~16 ~49~26~79 minecraft:concrete 11
fill ~49~78~16 ~49~78~88 minecraft:concrete 11
fill ~50~25~16 ~51~25~80 minecraft:concrete 11
fill ~50~79~16 ~55~79~86 minecraft:concrete 11
fill ~51~24~16 ~52~24~80 minecraft:concrete 11
fill ~51~75~16 ~55~75~87 minecraft:concrete 11
fill ~51~76~16 ~51~78~87 minecraft:concrete 11
fill ~51~80~16 ~52~80~88 minecraft:concrete 11
setblock ~52~77~16 minecraft:concrete 13
fill ~53~23~16 ~54~23~82 minecraft:concrete 11
fill ~53~81~16 ~54~81~87 minecraft:concrete 11
setblock ~54~76~16 minecraft:concrete 13
fill ~55~22~16 ~56~22~83 minecraft:concrete 11
fill ~55~76~16 ~55~76~88 minecraft:concrete 11
fill ~55~77~16 ~55~77~87 minecraft:concrete 11
fill ~55~78~16 ~55~78~86 minecraft:concrete 11
fill ~55~82~16 ~56~82~88 minecraft:concrete 11
fill ~57~21~16 ~61~21~16 minecraft:concrete 11
fill ~57~83~16 ~59~83~88 minecraft:concrete 11
fill ~59~20~16 ~59~20~17 minecraft:concrete 11
fill ~59~84~16 ~62~84~80 minecraft:concrete 11
fill ~60~20~16 ~62~20~25 minecraft:snow
fill ~62~19~16 ~68~19~23 minecraft:snow
fill ~62~21~16 ~62~21~24 minecraft:snow
fill ~62~85~16 ~78~85~77 minecraft:concrete 11
fill ~66~21~16 ~66~21~22 minecraft:snow
fill ~67~21~16 ~78~21~16 minecraft:concrete 11
fill ~68~20~16 ~68~20~22 minecraft:snow
fill ~69~19~16 ~77~20~16 minecraft:concrete 11
fill ~72~79~16 ~77~79~89 minecraft:concrete 11
fill ~72~80~16 ~75~81~89 minecraft:concrete 11
fill ~75~82~16 ~75~82~91 minecraft:concrete 11
fill ~75~83~16 ~79~83~89 minecraft:concrete 11
fill ~76~80~16 ~80~81~16 minecraft:concrete 13
fill ~76~82~16 ~78~82~16 minecraft:concrete 13
fill ~77~78~16 ~81~78~88 minecraft:concrete 11
fill ~78~19~16 ~78~19~25 minecraft:snow
fill ~78~20~16 ~81~20~24 minecraft:snow
fill ~78~79~16 ~80~79~16 minecraft:concrete 13
fill ~78~84~16 ~81~84~88 minecraft:concrete 11
fill ~79~21~16 ~83~21~24 minecraft:snow
fill ~79~82~16 ~81~82~89 minecraft:concrete 11
fill ~81~22~16 ~83~22~24 minecraft:snow
fill ~81~79~16 ~81~81~88 minecraft:concrete 11
fill ~81~83~16 ~83~83~88 minecraft:concrete 11
fill ~84~22~16 ~85~22~16 minecraft:concrete 11
fill ~84~82~16 ~85~82~88 minecraft:concrete 11
fill ~85~27~16 ~87~28~91 minecraft:concrete 11
fill ~85~29~16 ~87~29~90 minecraft:concrete 11
fill ~86~23~16 ~87~23~83 minecraft:concrete 11
fill ~86~81~16 ~87~81~88 minecraft:concrete 11
fill ~88~24~16 ~89~24~82 minecraft:concrete 11
fill ~88~80~16 ~89~80~88 minecraft:concrete 11
fill ~89~25~16 ~90~25~88 minecraft:concrete 11
fill ~89~79~16 ~90~79~88 minecraft:concrete 11
fill ~91~26~16 ~91~26~88 minecraft:concrete 11
fill ~91~78~16 ~91~78~88 minecraft:concrete 11
fill ~92~27~16 ~93~27~79 minecraft:concrete 11
fill ~92~77~16 ~93~77~88 minecraft:concrete 11
fill ~93~28~16 ~94~28~78 minecraft:concrete 11
fill ~93~76~16 ~94~76~88 minecraft:concrete 11
fill ~94~29~16 ~95~29~78 minecraft:concrete 11
fill ~94~75~16 ~95~75~88 minecraft:concrete 11
fill ~95~30~16 ~95~30~79 minecraft:concrete 11
fill ~95~74~16 ~95~74~88 minecraft:concrete 11
fill ~96~31~16 ~96~31~79 minecraft:concrete 11
fill ~96~73~16 ~96~73~88 minecraft:concrete 11
fill ~97~32~16 ~97~33~79 minecraft:concrete 11
fill ~97~71~16 ~98~71~87 minecraft:concrete 11
fill ~97~72~16 ~97~72~87 minecraft:concrete 11
fill ~98~33~16 ~98~34~81 minecraft:concrete 11
fill ~98~70~16 ~98~70~88 minecraft:concrete 11
fill ~99~35~16 ~99~36~88 minecraft:concrete 11
fill ~99~68~16 ~99~69~87 minecraft:concrete 11
fill ~100~37~16 ~100~38~88 minecraft:concrete 11
fill ~100~66~16 ~100~67~86 minecraft:concrete 11
fill ~101~39~16 ~101~41~88 minecraft:concrete 11
fill ~101~63~16 ~102~63~84 minecraft:concrete 11
fill ~101~64~16 ~101~65~84 minecraft:concrete 11
fill ~102~41~16 ~102~44~88 minecraft:concrete 11
fill ~102~60~16 ~103~60~83 minecraft:concrete 11
fill ~102~61~16 ~102~61~85 minecraft:concrete 11
fill ~102~62~16 ~102~62~84 minecraft:concrete 11
fill ~103~44~16 ~103~50~88 minecraft:concrete 11
fill ~103~51~16 ~103~53~87 minecraft:concrete 11
fill ~103~54~16 ~103~54~86 minecraft:concrete 11
fill ~103~55~16 ~103~56~85 minecraft:concrete 11
fill ~103~57~16 ~103~59~83 minecraft:concrete 11
setblock ~35~52~17 minecraft:concrete 11
fill ~36~44~17 ~36~44~22 minecraft:concrete 13
fill ~36~45~17 ~36~51~20 minecraft:concrete 13
setblock ~36~52~17 minecraft:concrete 13
fill ~36~53~17 ~36~60~82 minecraft:concrete 11
fill ~37~41~17 ~37~42~87 minecraft:concrete 11
fill ~37~43~17 ~37~43~18 minecraft:concrete 13
fill ~37~61~17 ~37~62~82 minecraft:concrete 11
fill ~37~63~17 ~37~63~81 minecraft:concrete 11
fill ~38~38~17 ~39~38~87 minecraft:concrete 11
fill ~38~39~17 ~38~40~87 minecraft:concrete 11
fill ~38~64~17 ~38~66~82 minecraft:concrete 11
fill ~39~36~17 ~40~36~87 minecraft:concrete 11
fill ~39~37~17 ~39~37~87 minecraft:concrete 11
fill ~39~66~17 ~39~66~83 minecraft:concrete 11
fill ~39~67~17 ~39~67~82 minecraft:concrete 11
fill ~39~68~17 ~40~68~81 minecraft:concrete 11
fill ~40~34~17 ~41~34~87 minecraft:concrete 11
fill ~40~35~17 ~40~35~87 minecraft:concrete 11
fill ~40~69~17 ~40~69~82 minecraft:concrete 11
fill ~40~70~17 ~41~70~81 minecraft:concrete 11
fill ~41~33~17 ~41~33~87 minecraft:concrete 11
fill ~41~71~17 ~41~71~81 minecraft:concrete 11
fill ~42~31~17 ~43~31~77 minecraft:concrete 11
fill ~42~32~17 ~42~32~87 minecraft:concrete 11
fill ~42~72~17 ~42~73~82 minecraft:concrete 11
fill ~43~30~17 ~44~30~76 minecraft:concrete 11
fill ~43~73~17 ~43~74~87 minecraft:concrete 11
fill ~44~29~17 ~44~29~77 minecraft:concrete 11
fill ~44~74~17 ~44~75~87 minecraft:concrete 11
fill ~45~28~17 ~45~28~78 minecraft:concrete 11
fill ~45~76~17 ~45~76~87 minecraft:concrete 11
fill ~46~27~17 ~46~27~78 minecraft:concrete 11
fill ~46~77~17 ~46~77~87 minecraft:concrete 11
fill ~47~26~17 ~48~26~78 minecraft:concrete 11
fill ~47~78~17 ~48~78~87 minecraft:concrete 11
fill ~48~25~17 ~49~25~78 minecraft:concrete 11
fill ~48~79~17 ~49~79~87 minecraft:concrete 11
fill ~49~24~17 ~50~24~79 minecraft:concrete 11
fill ~49~80~17 ~50~80~87 minecraft:concrete 11
fill ~51~23~17 ~52~23~81 minecraft:concrete 11
fill ~51~81~17 ~52~81~87 minecraft:concrete 11
fill ~52~22~17 ~54~22~20 minecraft:concrete 11
fill ~52~76~17 ~54~77~87 minecraft:concrete 11
fill ~52~78~17 ~54~78~86 minecraft:concrete 11
fill ~52~82~17 ~54~82~87 minecraft:concrete 11
fill ~54~21~17 ~60~21~17 minecraft:concrete 11
fill ~54~83~17 ~56~83~87 minecraft:concrete 11
fill ~56~20~17 ~58~20~21 minecraft:concrete 11
fill ~56~84~17 ~58~84~87 minecraft:concrete 11
fill ~59~19~17 ~61~19~26 minecraft:snow
fill ~59~85~17 ~61~85~79 minecraft:concrete 11
fill ~60~22~17 ~62~22~17 minecraft:concrete 11
fill ~61~21~17 ~61~21~25 minecraft:snow
fill ~62~18~17 ~69~18~23 minecraft:snow
fill ~62~86~17 ~78~86~76 minecraft:concrete 11
fill ~63~22~17 ~65~22~21 minecraft:snow
fill ~66~22~17 ~79~22~17 minecraft:concrete 11
fill ~67~21~17 ~67~21~21 minecraft:snow
fill ~68~21~17 ~77~21~17 minecraft:concrete 11
fill ~69~19~17 ~69~19~21 minecraft:snow
fill ~69~20~17 ~77~20~17 minecraft:concrete 11
fill ~70~17~17 ~70~17~27 minecraft:snow
fill ~70~18~17 ~76~19~17 minecraft:concrete 11
fill ~70~87~17 ~70~87~77 minecraft:concrete 11
fill ~76~80~17 ~80~81~89 minecraft:concrete 11
fill ~76~82~17 ~78~82~90 minecraft:concrete 11
fill ~77~18~17 ~78~18~25 minecraft:snow
fill ~77~19~17 ~77~19~25 minecraft:snow
fill ~78~21~17 ~78~21~23 minecraft:snow
fill ~78~79~17 ~80~79~88 minecraft:concrete 11
fill ~79~19~17 ~81~19~25 minecraft:snow
fill ~79~85~17 ~81~85~87 minecraft:concrete 11
fill ~80~22~17 ~80~22~23 minecraft:snow
fill ~82~20~17 ~84~20~25 minecraft:snow
fill ~82~84~17 ~84~84~77 minecraft:concrete 11
fill ~84~21~17 ~86~21~23 minecraft:snow
fill ~84~22~17 ~84~22~23 minecraft:snow
fill ~84~83~17 ~86~83~87 minecraft:concrete 11
fill ~85~22~17 ~88~22~17 minecraft:concrete 11
fill ~86~82~17 ~88~82~87 minecraft:concrete 11
fill ~88~23~17 ~89~23~82 minecraft:concrete 11
fill ~88~81~17 ~89~81~87 minecraft:concrete 11
fill ~90~24~17 ~91~24~23 minecraft:concrete 11
fill ~90~80~17 ~91~80~87 minecraft:concrete 11
fill ~91~25~17 ~92~25~82 minecraft:concrete 11
fill ~91~79~17 ~92~79~87 minecraft:concrete 11
fill ~92~26~17 ~93~26~79 minecraft:concrete 11
fill ~92~78~17 ~93~78~87 minecraft:concrete 11
fill ~94~27~17 ~94~27~78 minecraft:concrete 11
fill ~94~77~17 ~94~77~87 minecraft:concrete 11
fill ~95~28~17 ~95~28~78 minecraft:concrete 11
fill ~95~76~17 ~95~76~87 minecraft:concrete 11
fill ~96~29~17 ~96~30~78 minecraft:concrete 11
fill ~96~74~17 ~97~74~87 minecraft:concrete 11
fill ~96~75~17 ~96~75~87 minecraft:concrete 11
fill ~97~30~17 ~97~31~78 minecraft:concrete 11
fill ~97~73~17 ~98~73~87 minecraft:concrete 11
fill ~98~31~17 ~98~32~77 minecraft:concrete 11
fill ~98~72~17 ~98~72~87 minecraft:concrete 11
fill ~99~33~17 ~99~34~77 minecraft:concrete 11
fill ~99~70~17 ~100~70~87 minecraft:concrete 11
fill ~99~71~17 ~99~71~87 minecraft:concrete 11
fill ~100~34~17 ~100~36~77 minecraft:concrete 11
fill ~100~68~17 ~101~68~87 minecraft:concrete 11
fill ~100~69~17 ~100~69~87 minecraft:concrete 11
fill ~101~36~17 ~101~38~87 minecraft:concrete 11
fill ~101~66~17 ~102~66~86 minecraft:concrete 11
fill ~101~67~17 ~101~67~87 minecraft:concrete 11
fill ~102~38~17 ~102~40~87 minecraft:concrete 11
fill ~102~64~17 ~102~65~84 minecraft:concrete 11
fill ~103~41~17 ~103~43~87 minecraft:concrete 11
fill ~103~61~17 ~103~63~83 minecraft:concrete 11
fill ~104~44~17 ~104~53~87 minecraft:concrete 11
fill ~104~54~17 ~104~55~86 minecraft:concrete 11
fill ~104~56~17 ~104~56~84 minecraft:concrete 11
fill ~104~57~17 ~104~57~83 minecraft:concrete 11
fill ~104~58~17 ~104~60~82 minecraft:concrete 11
fill ~105~52~17 ~105~52~87 minecraft:concrete 11
fill ~35~44~18 ~35~45~23 minecraft:concrete 13
fill ~35~46~18 ~35~52~20 minecraft:concrete 13
fill ~35~53~18 ~35~60~81 minecraft:concrete 11
fill ~36~41~18 ~36~41~86 minecraft:concrete 11
fill ~36~42~18 ~36~42~19 minecraft:concrete 11
setblock ~36~43~18 minecraft:concrete 13
fill ~36~52~18 ~38~52~82 minecraft:concrete 11
fill ~36~61~18 ~36~62~82 minecraft:concrete 11
fill ~36~63~18 ~36~63~81 minecraft:concrete 11
fill ~37~38~18 ~37~40~86 minecraft:concrete 11
fill ~37~64~18 ~37~66~81 minecraft:concrete 11
fill ~38~36~18 ~38~37~86 minecraft:concrete 11
fill ~38~67~18 ~38~67~82 minecraft:concrete 11
fill ~38~68~18 ~38~68~81 minecraft:concrete 11
fill ~39~34~18 ~39~35~86 minecraft:concrete 11
fill ~39~69~18 ~39~70~80 minecraft:concrete 11
fill ~40~33~18 ~40~33~86 minecraft:concrete 11
fill ~40~48~18 ~40~50~86 minecraft:concrete 11
fill ~40~71~18 ~40~71~81 minecraft:concrete 11
fill ~41~31~18 ~41~32~76 minecraft:concrete 11
fill ~41~72~18 ~41~72~81 minecraft:concrete 11
fill ~41~73~18 ~41~73~80 minecraft:concrete 11
fill ~42~30~18 ~42~30~75 minecraft:concrete 11
fill ~42~74~18 ~42~74~82 minecraft:concrete 11
fill ~43~29~18 ~43~29~75 minecraft:concrete 11
fill ~43~75~18 ~43~75~86 minecraft:concrete 11
fill ~44~28~18 ~44~28~76 minecraft:concrete 11
fill ~44~76~18 ~44~76~86 minecraft:concrete 11
fill ~45~27~18 ~45~27~77 minecraft:concrete 11
fill ~45~77~18 ~45~77~86 minecraft:concrete 11
fill ~46~26~18 ~46~26~77 minecraft:concrete 11
fill ~46~78~18 ~46~78~86 minecraft:concrete 11
fill ~47~25~18 ~47~25~24 minecraft:concrete 11
fill ~47~79~18 ~47~79~86 minecraft:concrete 11
fill ~48~24~18 ~48~24~24 minecraft:concrete 11
fill ~48~80~18 ~48~80~86 minecraft:concrete 11
fill ~49~23~18 ~50~23~79 minecraft:concrete 11
fill ~49~81~18 ~50~81~86 minecraft:concrete 11
fill ~51~22~18 ~51~22~81 minecraft:concrete 11
fill ~51~82~18 ~51~82~86 minecraft:concrete 11
fill ~52~21~18 ~59~21~20 minecraft:concrete 11
fill ~52~83~18 ~53~83~86 minecraft:concrete 11
fill ~54~20~18 ~55~20~22 minecraft:concrete 11
fill ~54~84~18 ~55~84~86 minecraft:concrete 11
fill ~56~19~18 ~58~19~21 minecraft:concrete 11
fill ~56~85~18 ~58~85~86 minecraft:concrete 11
fill ~59~18~18 ~61~18~27 minecraft:snow
fill ~59~20~18 ~59~20~20 minecraft:snow
fill ~59~86~18 ~61~86~77 minecraft:concrete 11
fill ~60~21~18 ~60~21~25 minecraft:snow
fill ~60~22~18 ~61~22~18 minecraft:concrete 11
fill ~62~17~18 ~69~17~26 minecraft:snow
fill ~62~22~18 ~62~22~22 minecraft:snow
fill ~62~87~18 ~69~87~76 minecraft:concrete 11
fill ~66~22~18 ~66~22~20 minecraft:snow
fill ~67~22~18 ~78~22~18 minecraft:concrete 11
fill ~68~21~18 ~68~21~20 minecraft:snow
fill ~69~20~18 ~69~20~20 minecraft:snow
fill ~69~21~18 ~77~21~18 minecraft:concrete 11
fill ~70~18~18 ~70~18~25 minecraft:snow
fill ~70~19~18 ~76~20~18 minecraft:concrete 11
fill ~71~17~18 ~75~17~20 minecraft:concrete 11
fill ~71~18~18 ~75~18~19 minecraft:concrete 11
fill ~71~87~18 ~78~87~75 minecraft:concrete 11
fill ~76~17~18 ~78~17~26 minecraft:snow
fill ~76~18~18 ~76~18~25 minecraft:snow
fill ~77~20~18 ~77~20~24 minecraft:snow
fill ~79~18~18 ~81~18~25 minecraft:snow
fill ~79~22~18 ~79~22~22 minecraft:snow
fill ~79~86~18 ~81~86~77 minecraft:concrete 11
setblock ~80~23~18 minecraft:concrete 11
fill ~81~23~18 ~83~23~22 minecraft:snow
fill ~82~19~18 ~84~19~25 minecraft:snow
fill ~82~85~18 ~84~85~75 minecraft:concrete 11
fill ~84~23~18 ~85~23~18 minecraft:concrete 11
fill ~85~20~18 ~86~20~24 minecraft:snow
fill ~85~22~18 ~85~22~22 minecraft:snow
fill ~85~84~18 ~86~84~76 minecraft:concrete 11
fill ~86~22~18 ~89~22~18 minecraft:concrete 11
fill ~87~21~18 ~88~21~18 minecraft:concrete 11
fill ~87~83~18 ~88~83~86 minecraft:concrete 11
fill ~89~82~18 ~89~82~86 minecraft:concrete 11
fill ~90~23~18 ~91~23~21 minecraft:concrete 11
fill ~90~81~18 ~91~81~86 minecraft:concrete 11
fill ~92~24~18 ~92~24~22 minecraft:concrete 11
fill ~92~80~18 ~92~80~86 minecraft:concrete 11
fill ~93~25~18 ~93~25~23 minecraft:concrete 11
fill ~93~79~18 ~93~79~86 minecraft:concrete 11
fill ~94~26~18 ~94~26~78 minecraft:concrete 11
fill ~94~78~18 ~94~78~86 minecraft:concrete 11
fill ~95~27~18 ~95~27~78 minecraft:concrete 11
fill ~95~77~18 ~95~77~86 minecraft:concrete 11
fill ~96~28~18 ~96~28~77 minecraft:concrete 11
fill ~96~76~18 ~96~76~86 minecraft:concrete 11
fill ~97~29~18 ~97~29~77 minecraft:concrete 11
fill ~97~75~18 ~97~75~86 minecraft:concrete 11
fill ~98~30~18 ~98~30~76 minecraft:concrete 11
fill ~98~74~18 ~98~74~86 minecraft:concrete 11
fill ~99~31~18 ~99~32~75 minecraft:concrete 11
fill ~99~72~18 ~99~73~86 minecraft:concrete 11
fill ~100~33~18 ~100~33~75 minecraft:concrete 11
fill ~100~71~18 ~100~71~86 minecraft:concrete 11
fill ~101~34~18 ~101~35~76 minecraft:concrete 11
fill ~101~69~18 ~101~70~86 minecraft:concrete 11
fill ~102~36~18 ~102~37~86 minecraft:concrete 11
fill ~102~67~18 ~102~68~86 minecraft:concrete 11
fill ~103~38~18 ~103~40~86 minecraft:concrete 11
fill ~103~64~18 ~103~66~85 minecraft:concrete 11
fill ~104~41~18 ~104~43~86 minecraft:concrete 11
fill ~104~61~18 ~104~63~83 minecraft:concrete 11
fill ~105~44~18 ~105~51~86 minecraft:concrete 11
fill ~105~53~18 ~105~55~86 minecraft:concrete 11
fill ~105~56~18 ~105~56~84 minecraft:concrete 11
fill ~105~57~18 ~105~57~83 minecraft:concrete 11
fill ~105~58~18 ~105~60~82 minecraft:concrete 11
fill ~34~44~19 ~34~44~24 minecraft:concrete 13
fill ~34~45~19 ~34~48~23 minecraft:concrete 13
fill ~34~49~19 ~34~50~22 minecraft:concrete 13
fill ~34~51~19 ~34~51~21 minecraft:concrete 13
fill ~34~52~19 ~34~52~20 minecraft:concrete 13
fill ~34~53~19 ~34~55~80 minecraft:concrete 11
fill ~34~56~19 ~34~59~79 minecraft:concrete 11
fill ~34~60~19 ~34~60~77 minecraft:concrete 11
fill ~35~41~19 ~35~41~24 minecraft:concrete 13
fill ~35~42~19 ~35~43~23 minecraft:concrete 13
fill ~35~61~19 ~35~62~81 minecraft:concrete 11
fill ~35~63~19 ~35~63~79 minecraft:concrete 11
fill ~36~38~19 ~36~40~20 minecraft:concrete 11
fill ~36~43~19 ~37~43~19 minecraft:concrete 11
fill ~36~64~19 ~36~64~81 minecraft:concrete 11
fill ~36~65~19 ~36~66~79 minecraft:concrete 11
fill ~37~36~19 ~37~37~21 minecraft:concrete 11
fill ~37~51~19 ~39~51~83 minecraft:concrete 11
fill ~37~67~19 ~37~67~81 minecraft:concrete 11
fill ~37~68~19 ~37~68~78 minecraft:concrete 11
fill ~38~34~19 ~38~35~85 minecraft:concrete 11
fill ~38~69~19 ~38~70~79 minecraft:concrete 11
fill ~39~32~19 ~40~32~77 minecraft:concrete 11
fill ~39~33~19 ~39~33~85 minecraft:concrete 11
fill ~39~45~19 ~39~45~89 minecraft:concrete 11
fill ~39~46~19 ~39~46~87 minecraft:concrete 11
fill ~39~47~19 ~39~47~86 minecraft:concrete 11
fill ~39~48~19 ~39~50~85 minecraft:concrete 11
fill ~39~71~19 ~39~71~80 minecraft:concrete 11
fill ~39~72~19 ~40~72~79 minecraft:concrete 11
fill ~40~31~19 ~40~31~75 minecraft:concrete 11
fill ~40~73~19 ~40~73~79 minecraft:concrete 11
fill ~41~30~19 ~41~30~74 minecraft:concrete 11
fill ~41~74~19 ~41~74~79 minecraft:concrete 11
fill ~42~28~19 ~43~28~73 minecraft:concrete 11
fill ~42~29~19 ~42~29~74 minecraft:concrete 11
fill ~42~75~19 ~42~76~78 minecraft:concrete 11
fill ~43~27~19 ~44~27~74 minecraft:concrete 11
fill ~43~76~19 ~43~77~79 minecraft:concrete 11
fill ~44~26~19 ~45~26~23 minecraft:concrete 11
fill ~44~77~19 ~44~78~80 minecraft:concrete 11
fill ~45~25~19 ~46~25~22 minecraft:concrete 11
fill ~45~78~19 ~45~79~85 minecraft:concrete 11
fill ~46~24~19 ~47~24~21 minecraft:concrete 11
fill ~46~79~19 ~46~79~85 minecraft:concrete 11
fill ~46~80~19 ~47~80~26 minecraft:concrete 11
fill ~48~23~19 ~48~23~23 minecraft:concrete 11
fill ~48~81~19 ~48~81~26 minecraft:concrete 11
fill ~49~22~19 ~50~22~23 minecraft:concrete 11
fill ~49~82~19 ~50~82~25 minecraft:concrete 11
fill ~50~21~19 ~51~21~23 minecraft:concrete 11
fill ~50~83~19 ~51~83~24 minecraft:concrete 11
fill ~52~20~19 ~53~20~22 minecraft:concrete 11
fill ~52~84~19 ~53~84~25 minecraft:concrete 11
fill ~54~19~19 ~55~19~22 minecraft:concrete 11
fill ~54~85~19 ~55~85~25 minecraft:concrete 11
fill ~56~18~19 ~57~18~21 minecraft:concrete 11
fill ~56~86~19 ~58~86~25 minecraft:concrete 11
fill ~58~18~19 ~58~18~20 minecraft:snow
fill ~59~17~19 ~61~17~28 minecraft:snow
fill ~59~87~19 ~61~87~77 minecraft:concrete 11
fill ~60~22~19 ~61~22~23 minecraft:snow
fill ~62~16~19 ~70~16~28 minecraft:snow
fill ~62~88~19 ~78~88~75 minecraft:concrete 11
fill ~67~22~19 ~77~22~85 minecraft:concrete 11
fill ~69~21~19 ~74~21~86 minecraft:concrete 11
fill ~70~19~19 ~70~19~83 minecraft:concrete 11
fill ~70~20~19 ~71~20~19 minecraft:snow
fill ~71~16~19 ~75~16~20 minecraft:concrete 11
fill ~71~19~19 ~71~19~23 minecraft:snow
fill ~72~19~19 ~75~20~19 minecraft:concrete 11
fill ~75~21~19 ~77~21~21 minecraft:snow
fill ~76~16~19 ~78~16~26 minecraft:snow
fill ~76~19~19 ~76~19~25 minecraft:snow
setblock ~76~20~19 minecraft:concrete 11
fill ~78~22~19 ~78~22~21 minecraft:snow
fill ~79~17~19 ~81~17~25 minecraft:snow
fill ~79~87~19 ~81~87~76 minecraft:concrete 11
fill ~80~23~19 ~80~23~21 minecraft:snow
fill ~82~18~19 ~84~18~26 minecraft:snow
fill ~82~86~19 ~84~86~74 minecraft:concrete 11
fill ~84~23~19 ~84~23~21 minecraft:snow
fill ~85~19~19 ~86~19~25 minecraft:snow
fill ~85~23~19 ~85~23~84 minecraft:concrete 11
fill ~85~85~19 ~86~85~74 minecraft:concrete 11
fill ~86~22~19 ~86~22~21 minecraft:snow
fill ~87~20~19 ~87~20~22 minecraft:snow
fill ~87~21~19 ~87~21~21 minecraft:snow
fill ~87~22~19 ~91~22~20 minecraft:concrete 11
fill ~87~84~19 ~88~84~76 minecraft:concrete 11
fill ~88~20~19 ~88~21~23 minecraft:concrete 11
fill ~89~21~19 ~90~21~21 minecraft:concrete 11
fill ~89~83~19 ~90~83~85 minecraft:concrete 11
fill ~90~82~19 ~91~82~85 minecraft:concrete 11
fill ~92~23~19 ~92~23~20 minecraft:concrete 11
fill ~92~81~19 ~92~81~85 minecraft:concrete 11
fill ~93~24~19 ~94~24~20 minecraft:concrete 11
fill ~93~80~19 ~94~80~85 minecraft:concrete 11
fill ~94~25~19 ~95~25~22 minecraft:concrete 11
fill ~94~79~19 ~95~79~85 minecraft:concrete 11
fill ~95~26~19 ~96~26~77 minecraft:concrete 11
fill ~95~78~19 ~96~78~85 minecraft:concrete 11
fill ~96~27~19 ~97~27~77 minecraft:concrete 11
fill ~96~77~19 ~97~77~85 minecraft:concrete 11
fill ~97~28~19 ~98~28~76 minecraft:concrete 11
fill ~97~76~19 ~98~76~85 minecraft:concrete 11
fill ~98~29~19 ~98~29~76 minecraft:concrete 11
fill ~98~75~19 ~98~75~85 minecraft:concrete 11
fill ~99~30~19 ~99~30~74 minecraft:concrete 11
fill ~99~74~19 ~99~74~85 minecraft:concrete 11
fill ~100~31~19 ~100~32~74 minecraft:concrete 11
fill ~100~72~19 ~101~72~85 minecraft:concrete 11
fill ~100~73~19 ~100~73~85 minecraft:concrete 11
fill ~101~32~19 ~101~33~74 minecraft:concrete 11
fill ~101~71~19 ~101~71~85 minecraft:concrete 11
fill ~102~34~19 ~102~35~75 minecraft:concrete 11
fill ~102~69~19 ~102~70~85 minecraft:concrete 11
fill ~103~36~19 ~103~37~85 minecraft:concrete 11
fill ~103~67~19 ~103~68~85 minecraft:concrete 11
fill ~104~38~19 ~104~40~85 minecraft:concrete 11
fill ~104~64~19 ~104~64~85 minecraft:concrete 11
fill ~104~65~19 ~104~66~21 minecraft:concrete 11
fill ~105~41~19 ~105~43~85 minecraft:concrete 11
fill ~105~61~19 ~105~63~83 minecraft:concrete 11
fill ~106~44~19 ~106~55~85 minecraft:concrete 11
fill ~106~56~19 ~106~56~84 minecraft:concrete 11
fill ~106~57~19 ~106~57~83 minecraft:concrete 11
fill ~106~58~19 ~106~60~82 minecraft:concrete 11
fill ~33~45~20 ~33~49~24 minecraft:concrete 13
fill ~33~50~20 ~33~50~22 minecraft:concrete 13
fill ~33~51~20 ~33~51~21 minecraft:concrete 13
setblock ~33~52~20 minecraft:concrete 13
fill ~33~53~20 ~33~54~79 minecraft:concrete 11
fill ~33~55~20 ~33~58~78 minecraft:concrete 11
fill ~33~59~20 ~33~59~76 minecraft:concrete 11
fill ~34~41~20 ~34~42~25 minecraft:concrete 13
fill ~34~43~20 ~34~43~24 minecraft:concrete 13
fill ~34~61~20 ~34~63~77 minecraft:concrete 11
fill ~35~38~20 ~35~40~20 minecraft:concrete 11
fill ~35~64~20 ~35~66~78 minecraft:concrete 11
fill ~36~36~20 ~36~37~20 minecraft:concrete 11
fill ~36~42~20 ~36~43~22 minecraft:concrete 13
fill ~36~67~20 ~36~67~79 minecraft:concrete 11
fill ~36~68~20 ~36~68~78 minecraft:concrete 11
fill ~37~34~20 ~37~34~84 minecraft:concrete 11
fill ~37~35~20 ~37~35~21 minecraft:concrete 11
fill ~37~43~20 ~37~44~87 minecraft:concrete 11
fill ~37~69~20 ~37~70~78 minecraft:concrete 11
fill ~38~32~20 ~38~33~77 minecraft:concrete 11
fill ~38~44~20 ~38~45~88 minecraft:concrete 11
fill ~38~46~20 ~38~46~87 minecraft:concrete 11
fill ~38~47~20 ~38~47~86 minecraft:concrete 11
fill ~38~48~20 ~38~48~85 minecraft:concrete 11
fill ~38~49~20 ~38~50~84 minecraft:concrete 11
fill ~38~71~20 ~38~72~79 minecraft:concrete 11
fill ~39~31~20 ~39~31~74 minecraft:concrete 11
fill ~39~73~20 ~39~73~78 minecraft:concrete 11
fill ~40~30~20 ~40~30~73 minecraft:concrete 11
fill ~40~74~20 ~40~74~79 minecraft:concrete 11
fill ~41~28~20 ~41~29~71 minecraft:concrete 11
fill ~41~75~20 ~41~75~78 minecraft:concrete 11
fill ~41~76~20 ~41~76~77 minecraft:concrete 11
fill ~42~27~20 ~42~27~72 minecraft:concrete 11
fill ~42~77~20 ~42~77~78 minecraft:concrete 11
fill ~43~26~20 ~43~26~23 minecraft:concrete 11
fill ~43~78~20 ~43~78~28 minecraft:concrete 11
fill ~44~25~20 ~44~25~21 minecraft:concrete 11
fill ~44~79~20 ~44~79~28 minecraft:concrete 11
fill ~45~24~20 ~45~24~22 minecraft:concrete 11
fill ~45~80~20 ~45~80~25 minecraft:concrete 11
fill ~46~23~20 ~47~23~21 minecraft:concrete 11
fill ~46~81~20 ~47~81~24 minecraft:concrete 11
fill ~48~22~20 ~48~22~22 minecraft:concrete 11
fill ~48~82~20 ~48~82~24 minecraft:concrete 11
fill ~49~21~20 ~49~21~23 minecraft:concrete 11
fill ~49~83~20 ~49~83~23 minecraft:concrete 11
fill ~50~20~20 ~51~20~25 minecraft:concrete 11
fill ~50~84~20 ~51~84~22 minecraft:concrete 11
fill ~52~19~20 ~53~19~22 minecraft:concrete 11
fill ~52~85~20 ~53~85~24 minecraft:concrete 11
fill ~54~18~20 ~55~18~22 minecraft:concrete 11
fill ~54~86~20 ~55~86~23 minecraft:concrete 11
fill ~56~17~20 ~57~17~20 minecraft:concrete 11
fill ~56~87~20 ~58~87~23 minecraft:concrete 11
fill ~57~22~20 ~57~22~83 minecraft:concrete 11
fill ~58~17~20 ~58~17~27 minecraft:snow
fill ~58~22~20 ~59~22~22 minecraft:snow
fill ~59~16~20 ~61~16~28 minecraft:snow
fill ~59~88~20 ~61~88~28 minecraft:concrete 11
fill ~63~15~20 ~70~15~29 minecraft:snow
fill ~63~89~20 ~77~89~74 minecraft:concrete 11
fill ~70~20~20 ~72~20~89 minecraft:concrete 11
fill ~71~15~20 ~75~15~20 minecraft:concrete 11
fill ~71~18~20 ~71~18~25 minecraft:snow
fill ~72~18~20 ~75~18~21 minecraft:concrete 11
fill ~72~19~20 ~72~19~24 minecraft:snow
fill ~73~19~20 ~75~19~20 minecraft:concrete 11
fill ~73~20~20 ~76~20~21 minecraft:snow
fill ~76~15~20 ~77~15~21 minecraft:snow
fill ~79~16~20 ~81~16~26 minecraft:snow
fill ~79~88~20 ~81~88~75 minecraft:concrete 11
fill ~82~17~20 ~84~17~26 minecraft:snow
fill ~82~87~20 ~84~87~73 minecraft:concrete 11
fill ~85~18~20 ~86~18~25 minecraft:snow
fill ~85~86~20 ~86~86~73 minecraft:concrete 11
fill ~87~19~20 ~88~19~21 minecraft:snow
fill ~87~85~20 ~88~85~74 minecraft:concrete 11
fill ~89~20~20 ~90~20~20 minecraft:concrete 11
fill ~89~84~20 ~90~84~84 minecraft:concrete 11
setblock ~91~21~20 minecraft:concrete 11
fill ~91~83~20 ~91~83~84 minecraft:concrete 11
setblock ~92~22~20 minecraft:concrete 11
fill ~92~82~20 ~92~82~84 minecraft:concrete 11
setblock ~93~23~20 minecraft:concrete 11
fill ~93~81~20 ~94~81~84 minecraft:concrete 11
fill ~94~23~20 ~94~23~30 minecraft:snow
setblock ~95~24~20 minecraft:concrete 11
fill ~95~80~20 ~95~80~84 minecraft:concrete 11
fill ~96~25~20 ~96~25~22 minecraft:concrete 11
fill ~96~79~20 ~96~79~84 minecraft:concrete 11
fill ~97~26~20 ~97~26~77 minecraft:concrete 11
fill ~97~78~20 ~97~78~84 minecraft:concrete 11
fill ~98~27~20 ~98~27~77 minecraft:concrete 11
fill ~98~77~20 ~98~77~84 minecraft:concrete 11
fill ~99~28~20 ~99~29~74 minecraft:concrete 11
fill ~99~75~20 ~99~76~84 minecraft:concrete 11
fill ~100~30~20 ~100~30~73 minecraft:concrete 11
fill ~100~74~20 ~100~74~84 minecraft:concrete 11
fill ~101~31~20 ~101~31~73 minecraft:concrete 11
fill ~101~73~20 ~101~73~84 minecraft:concrete 11
fill ~102~32~20 ~102~33~73 minecraft:concrete 11
fill ~102~71~20 ~102~72~84 minecraft:concrete 11
fill ~103~34~20 ~103~35~74 minecraft:concrete 11
fill ~103~69~20 ~103~70~84 minecraft:concrete 11
fill ~104~36~20 ~104~37~84 minecraft:concrete 11
fill ~104~67~20 ~104~68~21 minecraft:concrete 11
fill ~105~38~20 ~105~40~84 minecraft:concrete 11
fill ~105~64~20 ~105~66~20 minecraft:concrete 11
fill ~106~41~20 ~106~43~84 minecraft:concrete 11
fill ~106~61~20 ~106~62~22 minecraft:concrete 11
fill ~106~63~20 ~106~63~21 minecraft:concrete 11
fill ~107~45~20 ~107~56~84 minecraft:concrete 11
fill ~107~57~20 ~107~59~83 minecraft:concrete 11
fill ~32~46~21 ~32~46~27 minecraft:concrete 13
fill ~32~47~21 ~32~48~25 minecraft:concrete 13
fill ~32~49~21 ~32~49~24 minecraft:concrete 13
fill ~32~50~21 ~32~50~23 minecraft:concrete 13
setblock ~32~51~21 minecraft:concrete 13
fill ~32~52~21 ~35~52~78 minecraft:concrete 11
fill ~32~53~21 ~32~53~78 minecraft:concrete 11
fill ~32~54~21 ~32~58~76 minecraft:concrete 11
fill ~33~42~21 ~33~42~25 minecraft:concrete 13
fill ~33~43~21 ~33~44~24 minecraft:concrete 13
fill ~33~60~21 ~33~62~76 minecraft:concrete 11
fill ~34~39~21 ~34~40~25 minecraft:concrete 13
fill ~34~64~21 ~34~64~78 minecraft:concrete 11
fill ~34~65~21 ~34~65~77 minecraft:concrete 11
fill ~35~36~21 ~36~38~25 minecraft:concrete 13
fill ~35~39~21 ~36~40~21 minecraft:concrete 11
fill ~35~46~21 ~37~46~86 minecraft:concrete 11
fill ~35~47~21 ~36~51~21 minecraft:concrete 13
fill ~35~67~21 ~35~67~77 minecraft:concrete 11
fill ~35~68~21 ~35~68~76 minecraft:concrete 11
fill ~36~34~21 ~36~34~27 minecraft:concrete 13
fill ~36~35~21 ~36~35~25 minecraft:concrete 13
fill ~36~45~21 ~37~45~87 minecraft:concrete 11
fill ~36~69~21 ~36~70~77 minecraft:concrete 11
fill ~37~32~21 ~37~33~78 minecraft:concrete 11
fill ~37~47~21 ~37~47~86 minecraft:concrete 11
fill ~37~48~21 ~37~48~85 minecraft:concrete 11
fill ~37~49~21 ~37~50~84 minecraft:concrete 11
fill ~37~71~21 ~37~71~78 minecraft:concrete 11
fill ~37~72~21 ~37~72~76 minecraft:concrete 11
fill ~38~31~21 ~38~31~73 minecraft:concrete 11
fill ~38~73~21 ~38~73~76 minecraft:concrete 11
fill ~39~30~21 ~39~30~72 minecraft:concrete 11
fill ~39~74~21 ~39~74~77 minecraft:concrete 11
fill ~40~28~21 ~40~29~71 minecraft:concrete 11
fill ~40~75~21 ~40~75~78 minecraft:concrete 11
fill ~40~76~21 ~40~76~76 minecraft:concrete 11
fill ~41~27~21 ~41~27~71 minecraft:concrete 11
fill ~41~77~21 ~41~77~28 minecraft:concrete 11
fill ~42~26~21 ~42~26~23 minecraft:concrete 11
fill ~42~78~21 ~42~78~27 minecraft:concrete 11
setblock ~43~25~21 minecraft:concrete 11
fill ~43~79~21 ~43~79~26 minecraft:concrete 11
setblock ~44~24~21 minecraft:concrete 11
fill ~44~80~21 ~44~80~25 minecraft:concrete 11
fill ~45~23~21 ~45~23~22 minecraft:concrete 11
fill ~45~81~21 ~45~81~23 minecraft:concrete 11
fill ~46~22~21 ~47~22~22 minecraft:concrete 11
fill ~46~82~21 ~47~82~23 minecraft:concrete 11
setblock ~48~21~21 minecraft:concrete 11
fill ~48~83~21 ~48~83~22 minecraft:concrete 11
fill ~49~20~21 ~49~20~23 minecraft:concrete 11
fill ~49~84~21 ~49~84~22 minecraft:concrete 11
fill ~50~19~21 ~51~19~25 minecraft:concrete 11
fill ~50~85~21 ~51~85~22 minecraft:concrete 11
fill ~52~18~21 ~53~18~22 minecraft:concrete 11
fill ~52~21~21 ~56~21~21 minecraft:concrete 11
fill ~52~22~21 ~52~22~83 minecraft:concrete 11
fill ~52~86~21 ~53~86~23 minecraft:concrete 11
setblock ~53~22~21 minecraft:snow
fill ~54~17~21 ~56~17~21 minecraft:concrete 11
fill ~54~22~21 ~54~22~86 minecraft:concrete 11
fill ~54~87~21 ~55~87~22 minecraft:concrete 11
fill ~57~16~21 ~58~16~28 minecraft:snow
fill ~57~17~21 ~57~17~29 minecraft:snow
fill ~57~21~21 ~59~21~23 minecraft:snow
fill ~57~88~21 ~58~88~23 minecraft:concrete 11
setblock ~58~18~21 minecraft:concrete 11
setblock ~59~20~21 minecraft:concrete 11
fill ~60~15~21 ~62~15~29 minecraft:snow
fill ~60~89~21 ~62~89~28 minecraft:concrete 11
fill ~64~14~21 ~71~14~30 minecraft:snow
fill ~64~90~21 ~76~90~74 minecraft:concrete 11
fill ~66~22~21 ~66~22~86 minecraft:concrete 11
fill ~68~21~21 ~68~21~86 minecraft:concrete 11
fill ~69~20~21 ~69~20~89 minecraft:concrete 11
fill ~71~15~21 ~71~15~30 minecraft:snow
fill ~71~16~21 ~71~16~29 minecraft:snow
fill ~71~17~21 ~71~17~27 minecraft:snow
fill ~72~14~21 ~76~14~21 minecraft:concrete 11
fill ~72~15~21 ~75~17~21 minecraft:concrete 11
fill ~73~19~21 ~75~19~24 minecraft:snow
fill ~78~15~21 ~80~15~26 minecraft:snow
fill ~78~89~21 ~80~89~76 minecraft:concrete 11
fill ~82~16~21 ~83~16~26 minecraft:snow
fill ~82~88~21 ~83~88~73 minecraft:concrete 11
fill ~85~17~21 ~86~17~25 minecraft:snow
fill ~85~87~21 ~86~87~73 minecraft:concrete 11
fill ~87~18~21 ~88~18~22 minecraft:snow
fill ~87~22~21 ~90~22~22 minecraft:concrete 11
fill ~87~86~21 ~88~86~73 minecraft:concrete 11
fill ~89~19~21 ~89~20~22 minecraft:concrete 11
fill ~89~85~21 ~90~85~76 minecraft:concrete 11
fill ~90~19~21 ~90~20~29 minecraft:snow
fill ~91~20~21 ~91~20~30 minecraft:snow
fill ~91~21~21 ~92~22~29 minecraft:snow
fill ~91~84~21 ~91~84~83 minecraft:concrete 11
fill ~92~23~21 ~93~23~29 minecraft:snow
fill ~92~83~21 ~92~83~83 minecraft:concrete 11
fill ~93~22~21 ~94~22~30 minecraft:snow
setblock ~93~24~21 minecraft:concrete 11
fill ~93~82~21 ~94~82~83 minecraft:concrete 11
fill ~94~24~21 ~96~24~29 minecraft:snow
fill ~95~23~21 ~95~23~30 minecraft:snow
fill ~95~81~21 ~95~81~83 minecraft:concrete 11
fill ~96~80~21 ~96~80~83 minecraft:concrete 11
fill ~97~25~21 ~97~25~23 minecraft:concrete 11
fill ~97~79~21 ~97~79~83 minecraft:concrete 11
fill ~98~26~21 ~98~26~77 minecraft:concrete 11
fill ~98~78~21 ~98~78~83 minecraft:concrete 11
fill ~99~27~21 ~99~27~75 minecraft:concrete 11
fill ~99~77~21 ~99~77~83 minecraft:concrete 11
fill ~100~28~21 ~100~29~73 minecraft:concrete 11
fill ~100~75~21 ~100~76~83 minecraft:concrete 11
fill ~101~30~21 ~101~30~73 minecraft:concrete 11
fill ~101~74~21 ~101~74~83 minecraft:concrete 11
fill ~102~31~21 ~102~31~73 minecraft:concrete 11
fill ~102~73~21 ~102~73~83 minecraft:concrete 11
fill ~103~32~21 ~103~33~73 minecraft:concrete 11
fill ~103~71~21 ~103~72~83 minecraft:concrete 11
fill ~104~34~21 ~104~35~74 minecraft:concrete 11
fill ~104~69~21 ~104~70~83 minecraft:concrete 11
fill ~105~36~21 ~105~37~83 minecraft:concrete 11
fill ~105~64~21 ~106~65~25 minecraft:concrete 13
fill ~105~66~21 ~105~68~25 minecraft:concrete 13
fill ~106~39~21 ~106~40~83 minecraft:concrete 11
fill ~107~42~21 ~107~44~83 minecraft:concrete 11
fill ~107~60~21 ~107~62~21 minecraft:concrete 11
fill ~108~46~21 ~108~54~83 minecraft:concrete 11
fill ~108~55~21 ~108~56~24 minecraft:concrete 11
fill ~108~57~21 ~108~58~23 minecraft:concrete 11
fill ~31~47~22 ~31~47~28 minecraft:concrete 13
fill ~31~48~22 ~31~48~25 minecraft:concrete 13
fill ~31~49~22 ~31~49~24 minecraft:concrete 13
fill ~31~50~22 ~31~50~23 minecraft:concrete 13
fill ~31~51~22 ~36~51~79 minecraft:concrete 11
fill ~31~52~22 ~31~57~75 minecraft:concrete 11
fill ~32~42~22 ~32~42~25 minecraft:concrete 13
fill ~32~43~22 ~32~45~24 minecraft:concrete 13
fill ~32~59~22 ~32~59~76 minecraft:concrete 11
fill ~32~60~22 ~32~62~74 minecraft:concrete 11
fill ~33~39~22 ~33~40~28 minecraft:concrete 13
fill ~33~41~22 ~33~41~26 minecraft:concrete 13
fill ~33~63~22 ~33~64~76 minecraft:concrete 11
fill ~33~65~22 ~33~65~75 minecraft:concrete 11
fill ~34~37~22 ~34~37~26 minecraft:concrete 13
fill ~34~38~22 ~34~38~25 minecraft:concrete 13
fill ~34~66~22 ~34~66~76 minecraft:concrete 11
fill ~34~67~22 ~34~67~75 minecraft:concrete 11
fill ~35~34~22 ~35~34~29 minecraft:concrete 13
fill ~35~35~22 ~35~35~28 minecraft:concrete 13
fill ~35~39~22 ~35~40~24 minecraft:concrete 13
fill ~35~47~22 ~36~47~86 minecraft:concrete 11
fill ~35~48~22 ~35~50~22 minecraft:concrete 13
fill ~35~69~22 ~35~70~76 minecraft:concrete 11
fill ~36~33~22 ~36~33~24 minecraft:concrete 11
fill ~36~39~22 ~36~40~85 minecraft:concrete 11
fill ~36~48~22 ~36~48~85 minecraft:concrete 11
fill ~36~49~22 ~36~50~84 minecraft:concrete 11
fill ~36~71~22 ~36~71~77 minecraft:concrete 11
fill ~37~31~22 ~37~31~73 minecraft:concrete 11
fill ~37~35~22 ~37~37~24 minecraft:concrete 13
fill ~37~73~22 ~37~73~76 minecraft:concrete 11
fill ~38~30~22 ~38~30~71 minecraft:concrete 11
fill ~38~74~22 ~38~74~76 minecraft:concrete 11
fill ~39~28~22 ~39~29~70 minecraft:concrete 11
fill ~39~75~22 ~39~76~75 minecraft:concrete 11
fill ~40~27~22 ~40~27~70 minecraft:concrete 11
fill ~40~77~22 ~40~77~27 minecraft:concrete 11
fill ~41~26~22 ~41~26~24 minecraft:concrete 11
fill ~41~78~22 ~41~78~26 minecraft:concrete 11
fill ~42~25~22 ~42~25~24 minecraft:concrete 11
fill ~42~79~22 ~42~79~25 minecraft:concrete 11
fill ~43~24~22 ~43~24~24 minecraft:concrete 11
fill ~43~25~22 ~44~25~22 minecraft:snow
fill ~43~80~22 ~43~80~25 minecraft:concrete 11
setblock ~44~23~22 minecraft:concrete 11
fill ~44~24~22 ~44~24~31 minecraft:snow
fill ~44~81~22 ~44~81~23 minecraft:concrete 11
fill ~45~22~22 ~45~22~24 minecraft:concrete 11
setblock ~45~82~22 minecraft:concrete 11
fill ~46~21~22 ~46~21~24 minecraft:concrete 11
setblock ~46~23~22 minecraft:concrete 11
fill ~46~24~22 ~46~24~30 minecraft:snow
fill ~46~83~22 ~47~83~22 minecraft:concrete 11
fill ~47~21~22 ~48~21~32 minecraft:snow
fill ~47~23~22 ~47~23~30 minecraft:snow
setblock ~47~24~22 minecraft:concrete 11
setblock ~48~20~22 minecraft:concrete 11
fill ~48~84~22 ~48~84~32 minecraft:snow
fill ~49~19~22 ~49~19~23 minecraft:concrete 11
fill ~49~85~22 ~49~85~32 minecraft:snow
fill ~51~18~22 ~51~18~25 minecraft:concrete 11
setblock ~51~86~22 minecraft:concrete 11
fill ~52~17~22 ~52~17~24 minecraft:concrete 11
setblock ~52~21~22 minecraft:concrete 11
fill ~52~87~22 ~53~87~23 minecraft:concrete 11
fill ~53~17~22 ~56~17~31 minecraft:snow
fill ~53~21~22 ~54~21~22 minecraft:snow
fill ~53~22~22 ~53~22~87 minecraft:concrete 11
fill ~55~16~22 ~56~16~32 minecraft:snow
fill ~55~21~22 ~55~21~84 minecraft:concrete 11
fill ~55~88~22 ~56~88~22 minecraft:concrete 11
fill ~56~18~22 ~58~19~26 minecraft:snow
fill ~56~20~22 ~59~20~25 minecraft:snow
setblock ~56~21~22 minecraft:snow
fill ~57~15~22 ~59~15~29 minecraft:snow
fill ~57~89~22 ~59~89~23 minecraft:concrete 11
fill ~60~14~22 ~63~14~30 minecraft:snow
fill ~60~90~22 ~63~90~27 minecraft:concrete 11
fill ~63~22~22 ~65~22~83 minecraft:concrete 11
fill ~65~13~22 ~72~13~30 minecraft:snow
fill ~65~91~22 ~75~91~74 minecraft:concrete 11
fill ~67~21~22 ~67~21~86 minecraft:concrete 11
fill ~69~19~22 ~69~19~83 minecraft:concrete 11
fill ~72~14~22 ~72~15~30 minecraft:snow
fill ~72~16~22 ~72~16~29 minecraft:snow
fill ~72~17~22 ~72~17~27 minecraft:snow
fill ~72~18~22 ~75~18~25 minecraft:snow
fill ~73~13~22 ~75~13~23 minecraft:concrete 11
fill ~73~14~22 ~75~17~22 minecraft:concrete 11
fill ~73~20~22 ~73~20~84 minecraft:concrete 11
fill ~74~20~22 ~76~20~22 minecraft:snow
fill ~75~21~22 ~75~21~90 minecraft:concrete 11
fill ~76~14~22 ~80~14~27 minecraft:snow
setblock ~76~15~22 minecraft:concrete 11
fill ~76~21~22 ~77~21~22 minecraft:snow
fill ~77~15~22 ~77~15~26 minecraft:snow
fill ~77~90~22 ~80~90~75 minecraft:concrete 11
fill ~78~22~22 ~78~22~85 minecraft:concrete 11
fill ~80~23~22 ~80~23~85 minecraft:concrete 11
fill ~81~15~22 ~83~15~26 minecraft:snow
fill ~81~89~22 ~83~89~73 minecraft:concrete 11
fill ~84~16~22 ~85~16~25 minecraft:snow
fill ~84~23~22 ~84~23~84 minecraft:concrete 11
fill ~84~88~22 ~85~88~72 minecraft:concrete 11
fill ~86~22~22 ~86~22~83 minecraft:concrete 11
fill ~87~17~22 ~88~17~22 minecraft:snow
fill ~87~19~22 ~87~19~23 minecraft:snow
fill ~87~21~22 ~87~21~81 minecraft:concrete 11
fill ~87~87~22 ~88~87~73 minecraft:concrete 11
fill ~88~19~22 ~88~19~78 minecraft:concrete 11
setblock ~89~18~22 minecraft:concrete 11
fill ~89~21~22 ~89~21~23 minecraft:concrete 11
fill ~89~86~22 ~89~86~74 minecraft:concrete 11
fill ~90~21~22 ~90~21~28 minecraft:snow
fill ~90~23~22 ~90~23~23 minecraft:concrete 11
fill ~91~19~22 ~91~19~30 minecraft:snow
fill ~91~23~22 ~91~23~28 minecraft:snow
fill ~91~85~22 ~91~85~82 minecraft:concrete 11
fill ~92~20~22 ~92~20~30 minecraft:snow
fill ~92~84~22 ~92~84~82 minecraft:concrete 11
fill ~93~21~22 ~94~21~30 minecraft:snow
fill ~93~24~22 ~93~24~28 minecraft:snow
fill ~93~83~22 ~94~83~82 minecraft:concrete 11
fill ~95~22~22 ~95~22~30 minecraft:snow
fill ~95~82~22 ~95~82~82 minecraft:concrete 11
fill ~96~23~22 ~96~23~30 minecraft:snow
fill ~96~81~22 ~96~81~82 minecraft:concrete 11
fill ~97~24~22 ~97~24~28 minecraft:snow
fill ~97~80~22 ~97~80~82 minecraft:concrete 11
fill ~98~25~22 ~98~25~30 minecraft:concrete 11
fill ~98~79~22 ~98~79~82 minecraft:concrete 11
fill ~99~26~22 ~99~26~76 minecraft:concrete 11
fill ~99~78~22 ~99~78~82 minecraft:concrete 11
fill ~100~27~22 ~100~27~74 minecraft:concrete 11
fill ~100~77~22 ~100~77~82 minecraft:concrete 11
fill ~101~28~22 ~101~29~73 minecraft:concrete 11
fill ~101~75~22 ~101~76~82 minecraft:concrete 11
fill ~102~30~22 ~102~30~72 minecraft:concrete 11
fill ~102~74~22 ~102~74~82 minecraft:concrete 11
fill ~103~31~22 ~103~31~72 minecraft:concrete 11
fill ~103~73~22 ~103~73~82 minecraft:concrete 11
fill ~104~33~22 ~104~33~73 minecraft:concrete 11
fill ~104~65~22 ~104~67~24 minecraft:concrete 13
fill ~104~68~22 ~104~68~84 minecraft:concrete 11
fill ~104~71~22 ~104~71~82 minecraft:concrete 11
fill ~105~34~22 ~105~35~74 minecraft:concrete 11
fill ~105~69~22 ~105~70~82 minecraft:concrete 11
fill ~106~37~22 ~106~38~82 minecraft:concrete 11
fill ~106~63~22 ~107~63~25 minecraft:concrete 13
fill ~106~66~22 ~106~67~27 minecraft:concrete 13
fill ~107~39~22 ~107~41~82 minecraft:concrete 11
fill ~107~60~22 ~108~62~26 minecraft:concrete 13
fill ~107~64~22 ~107~65~26 minecraft:concrete 13
fill ~108~42~22 ~108~45~82 minecraft:concrete 11
setblock ~108~59~22 minecraft:concrete 11
fill ~109~47~22 ~109~53~82 minecraft:concrete 11
fill ~109~54~22 ~109~55~23 minecraft:concrete 11
fill ~109~56~22 ~109~57~22 minecraft:concrete 11
fill ~30~49~23 ~30~49~24 minecraft:concrete 13
setblock ~30~50~23 minecraft:concrete 13
fill ~30~51~23 ~30~55~74 minecraft:concrete 11
fill ~31~43~23 ~31~46~28 minecraft:concrete 13
fill ~31~58~23 ~31~58~77 minecraft:concrete 11
fill ~31~59~23 ~31~61~73 minecraft:concrete 11
fill ~32~40~23 ~32~41~29 minecraft:concrete 13
fill ~32~63~23 ~32~63~76 minecraft:concrete 11
fill ~32~64~23 ~32~64~73 minecraft:concrete 11
fill ~33~37~23 ~33~38~26 minecraft:concrete 13
fill ~33~50~23 ~35~50~84 minecraft:concrete 11
fill ~33~66~23 ~33~67~75 minecraft:concrete 11
fill ~34~35~23 ~34~35~30 minecraft:concrete 13
fill ~34~36~23 ~34~36~27 minecraft:concrete 13
fill ~34~49~23 ~35~49~85 minecraft:concrete 11
fill ~34~68~23 ~34~69~75 minecraft:concrete 11
fill ~35~33~23 ~35~33~29 minecraft:concrete 13
fill ~35~48~23 ~35~48~85 minecraft:concrete 11
fill ~35~71~23 ~35~71~77 minecraft:concrete 11
fill ~36~31~23 ~36~31~73 minecraft:concrete 11
fill ~36~32~23 ~36~32~24 minecraft:concrete 11
fill ~36~42~23 ~36~44~86 minecraft:concrete 11
fill ~36~72~23 ~36~72~76 minecraft:concrete 11
fill ~36~73~23 ~36~73~74 minecraft:concrete 11
fill ~37~30~23 ~37~30~71 minecraft:concrete 11
fill ~37~74~23 ~37~74~75 minecraft:concrete 11
fill ~38~28~23 ~38~29~70 minecraft:concrete 11
fill ~38~75~23 ~38~75~75 minecraft:concrete 11
fill ~38~76~23 ~38~76~74 minecraft:concrete 11
fill ~39~27~23 ~39~27~70 minecraft:concrete 11
fill ~39~77~23 ~39~77~27 minecraft:concrete 11
fill ~40~26~23 ~40~26~35 minecraft:concrete 11
fill ~40~78~23 ~40~78~25 minecraft:concrete 11
fill ~41~25~23 ~41~25~25 minecraft:concrete 11
fill ~41~79~23 ~41~79~25 minecraft:concrete 11
fill ~42~24~23 ~42~24~25 minecraft:concrete 11
fill ~42~80~23 ~42~80~25 minecraft:concrete 11
fill ~43~23~23 ~43~23~25 minecraft:concrete 11
setblock ~43~25~23 minecraft:concrete 11
setblock ~43~81~23 minecraft:concrete 11
setblock ~44~22~23 minecraft:concrete 11
fill ~44~23~23 ~46~23~30 minecraft:snow
fill ~44~25~23 ~45~25~29 minecraft:snow
fill ~44~82~23 ~45~82~33 minecraft:snow
fill ~45~21~23 ~45~21~24 minecraft:concrete 11
fill ~45~24~23 ~45~24~30 minecraft:snow
fill ~45~83~23 ~48~83~32 minecraft:snow
fill ~46~20~23 ~47~20~24 minecraft:concrete 11
setblock ~46~22~23 minecraft:concrete 11
setblock ~46~25~23 minecraft:concrete 11
fill ~46~84~23 ~47~84~33 minecraft:snow
fill ~47~22~23 ~48~22~29 minecraft:snow
fill ~47~24~23 ~47~24~29 minecraft:snow
fill ~48~19~23 ~48~19~25 minecraft:concrete 11
setblock ~48~20~23 minecraft:snow
fill ~48~85~23 ~48~85~33 minecraft:snow
fill ~49~18~23 ~50~18~24 minecraft:concrete 11
fill ~49~84~23 ~50~84~31 minecraft:snow
fill ~49~86~23 ~51~86~31 minecraft:snow
fill ~50~85~23 ~51~85~31 minecraft:snow
fill ~51~17~23 ~51~17~25 minecraft:concrete 11
setblock ~51~84~23 minecraft:concrete 11
fill ~51~87~23 ~51~87~25 minecraft:concrete 11
fill ~52~18~23 ~52~19~24 minecraft:concrete 11
fill ~52~20~23 ~55~20~27 minecraft:snow
fill ~52~21~23 ~53~21~27 minecraft:snow
fill ~53~16~23 ~54~16~33 minecraft:snow
fill ~53~18~23 ~55~18~30 minecraft:snow
fill ~53~19~23 ~55~19~29 minecraft:snow
fill ~53~88~23 ~55~88~33 minecraft:snow
setblock ~54~21~23 minecraft:concrete 11
fill ~54~87~23 ~54~87~33 minecraft:snow
fill ~55~15~23 ~56~15~32 minecraft:snow
setblock ~55~87~23 minecraft:concrete 11
fill ~55~89~23 ~56~89~35 minecraft:snow
fill ~56~21~23 ~56~21~83 minecraft:concrete 11
setblock ~56~88~23 minecraft:concrete 11
fill ~58~14~23 ~59~14~29 minecraft:snow
fill ~58~22~23 ~58~22~82 minecraft:concrete 11
fill ~58~90~23 ~59~90~23 minecraft:concrete 11
setblock ~59~22~23 minecraft:snow
fill ~61~13~23 ~64~13~30 minecraft:snow
fill ~61~91~23 ~64~91~28 minecraft:concrete 11
fill ~62~22~23 ~62~22~82 minecraft:concrete 11
fill ~66~21~23 ~66~21~86 minecraft:concrete 11
fill ~67~12~23 ~73~12~31 minecraft:snow
fill ~67~92~23 ~73~92~74 minecraft:concrete 11
fill ~68~20~23 ~68~20~89 minecraft:concrete 11
fill ~73~14~23 ~73~14~30 minecraft:snow
fill ~73~15~23 ~76~15~27 minecraft:snow
fill ~73~16~23 ~75~16~27 minecraft:snow
fill ~73~17~23 ~75~17~26 minecraft:snow
setblock ~74~14~23 minecraft:concrete 11
fill ~74~20~23 ~74~20~84 minecraft:concrete 11
fill ~75~14~23 ~75~14~29 minecraft:snow
fill ~75~20~23 ~76~20~23 minecraft:snow
fill ~76~13~23 ~79~13~28 minecraft:snow
fill ~76~21~23 ~77~21~85 minecraft:concrete 11
fill ~76~91~23 ~79~91~74 minecraft:concrete 11
fill ~79~22~23 ~79~22~85 minecraft:concrete 11
fill ~81~14~23 ~82~14~27 minecraft:snow
fill ~81~23~23 ~83~23~84 minecraft:concrete 11
fill ~81~90~23 ~82~90~73 minecraft:concrete 11
fill ~84~15~23 ~85~15~25 minecraft:snow
fill ~84~89~23 ~85~89~72 minecraft:concrete 11
fill ~85~22~23 ~85~22~83 minecraft:concrete 11
fill ~86~16~23 ~87~16~24 minecraft:snow
fill ~86~88~23 ~87~88~72 minecraft:concrete 11
fill ~87~17~23 ~87~18~24 minecraft:snow
setblock ~87~20~23 minecraft:concrete 11
fill ~87~22~23 ~89~22~82 minecraft:concrete 11
fill ~88~17~23 ~89~17~23 minecraft:concrete 11
fill ~88~18~23 ~88~18~27 minecraft:concrete 11
fill ~89~18~23 ~91~18~28 minecraft:snow
fill ~89~19~23 ~89~20~27 minecraft:snow
fill ~89~87~23 ~89~87~74 minecraft:concrete 11
fill ~90~22~23 ~90~22~27 minecraft:snow
fill ~90~86~23 ~91~86~75 minecraft:concrete 11
fill ~92~19~23 ~92~19~30 minecraft:snow
fill ~92~24~23 ~92~24~27 minecraft:snow
fill ~92~85~23 ~92~85~81 minecraft:concrete 11
fill ~93~20~23 ~94~20~31 minecraft:snow
fill ~93~84~23 ~94~84~81 minecraft:concrete 11
fill ~94~25~23 ~96~25~27 minecraft:snow
fill ~95~21~23 ~95~21~31 minecraft:snow
fill ~95~83~23 ~95~83~81 minecraft:concrete 11
fill ~96~22~23 ~96~22~33 minecraft:snow
fill ~96~82~23 ~96~82~81 minecraft:concrete 11
fill ~97~23~23 ~97~23~34 minecraft:snow
fill ~97~81~23 ~97~81~81 minecraft:concrete 11
fill ~98~24~23 ~98~24~27 minecraft:snow
fill ~98~80~23 ~98~80~81 minecraft:concrete 11
fill ~99~25~23 ~99~25~29 minecraft:concrete 11
fill ~99~79~23 ~99~79~81 minecraft:concrete 11
fill ~100~26~23 ~100~26~30 minecraft:concrete 11
fill ~100~78~23 ~100~78~81 minecraft:concrete 11
fill ~101~27~23 ~101~27~73 minecraft:concrete 11
fill ~101~77~23 ~101~77~81 minecraft:concrete 11
fill ~102~28~23 ~102~29~72 minecraft:concrete 11
fill ~102~75~23 ~102~75~81 minecraft:concrete 11
fill ~102~76~23 ~102~76~68 minecraft:concrete 11
fill ~103~30~23 ~103~30~72 minecraft:concrete 11
fill ~103~74~23 ~103~74~68 minecraft:concrete 11
fill ~104~31~23 ~104~32~72 minecraft:concrete 11
fill ~104~72~23 ~104~72~81 minecraft:concrete 11
fill ~104~73~23 ~104~73~68 minecraft:concrete 11
fill ~105~33~23 ~105~33~73 minecraft:concrete 11
fill ~105~71~23 ~105~71~81 minecraft:concrete 11
fill ~106~35~23 ~106~36~77 minecraft:concrete 11
fill ~106~61~23 ~106~62~25 minecraft:concrete 13
fill ~106~68~23 ~106~68~27 minecraft:concrete 13
fill ~106~69~23 ~106~69~24 minecraft:concrete 13
fill ~107~37~23 ~107~38~81 minecraft:concrete 11
fill ~107~66~23 ~107~67~28 minecraft:concrete 13
fill ~108~40~23 ~108~41~81 minecraft:concrete 11
fill ~108~59~23 ~109~59~26 minecraft:concrete 13
fill ~108~63~23 ~108~64~27 minecraft:concrete 13
fill ~109~43~23 ~109~46~81 minecraft:concrete 11
fill ~109~56~23 ~109~58~28 minecraft:concrete 13
fill ~109~60~23 ~109~61~27 minecraft:concrete 13
fill ~110~49~23 ~110~51~81 minecraft:concrete 11
fill ~110~52~23 ~110~52~27 minecraft:concrete 11
fill ~110~53~23 ~110~53~24 minecraft:concrete 11
setblock ~110~54~23 minecraft:concrete 11
fill ~110~55~23 ~110~55~29 minecraft:concrete 13
fill ~30~44~24 ~30~46~30 minecraft:concrete 13
fill ~30~47~24 ~30~47~28 minecraft:concrete 13
fill ~30~48~24 ~30~48~27 minecraft:concrete 13
