fill ~1~0~1 ~16~0~16 minecraft:dirt 0
fill ~1~1~1 ~16~1~0 minecraft:grass
fill ~2~2~0 ~15~2~0 minecraft:double_plant 4
fill ~1~1~1 ~1~1~16 minecraft:grass
fill ~1~2~1 ~1~2~14 minecraft:double_plant
fill ~2~1~1 ~15~1~2 minecraft:dirt 0
fill ~2~2~1 ~15~2~2 minecraft:planks 0
fill ~2~3~1 ~2~15~1 minecraft:planks 0
fill ~3~3~1 ~4~5~1 minecraft:wool 12
fill ~3~6~1 ~4~7~1 minecraft:wool 15
fill ~3~8~1 ~15~8~2 minecraft:planks 0
fill ~3~9~1 ~3~12~1 minecraft:wool 14
setblock ~3~13~1 minecraft:wool 0
setblock ~3~14~1 minecraft:wool 14
fill ~3~15~1 ~15~15~2 minecraft:planks 0
fill ~4~9~1 ~4~12~1 minecraft:wool 3
fill ~4~13~1 ~5~14~1 minecraft:wool 15
fill ~5~3~1 ~6~6~1 minecraft:wool 14
fill ~5~7~1 ~11~7~1 minecraft:wool 15
fill ~5~9~1 ~5~12~1 minecraft:wool 11
fill ~6~9~1 ~7~9~1 minecraft:wool 5
fill ~6~10~1 ~7~11~1 minecraft:wool 7
fill ~6~12~1 ~7~14~1 minecraft:wool 5
fill ~7~3~1 ~7~4~1 minecraft:wool 13
fill ~7~5~1 ~7~6~1 minecraft:wool 12
fill ~8~3~1 ~8~4~1 minecraft:wool 12
fill ~8~5~1 ~8~6~1 minecraft:wool 13
fill ~8~9~1 ~8~10~1 minecraft:wool 15
fill ~8~11~1 ~9~12~1 minecraft:wool 14
fill ~8~13~1 ~10~14~1 minecraft:wool 15
fill ~9~3~1 ~10~4~1 minecraft:wool 4
fill ~9~5~1 ~10~5~1 minecraft:wool 0
fill ~9~6~1 ~10~6~1 minecraft:wool 4
fill ~9~9~1 ~10~10~1 minecraft:wool 14
fill ~10~11~1 ~10~12~1 minecraft:wool 15
fill ~11~3~1 ~11~5~1 minecraft:wool 14
setblock ~11~6~1 minecraft:wool 15
fill ~11~9~1 ~12~13~1 minecraft:wool 4
fill ~11~14~1 ~14~14~1 minecraft:wool 15
fill ~12~3~1 ~12~7~1 minecraft:wool 3
fill ~13~3~1 ~13~7~1 minecraft:wool 11
fill ~13~9~1 ~14~10~1 minecraft:wool 5
fill ~13~11~1 ~14~11~1 minecraft:wool 0
fill ~13~12~1 ~14~12~1 minecraft:wool 5
fill ~13~13~1 ~14~13~1 minecraft:wool 15
fill ~14~3~1 ~14~5~1 minecraft:wool 5
fill ~14~6~1 ~14~7~1 minecraft:wool 15
fill ~15~3~1 ~15~4~1 minecraft:planks 0
setblock ~15~5~1 minecraft:planks 1
fill ~15~6~1 ~15~7~1 minecraft:planks 0
fill ~15~9~1 ~15~14~1 minecraft:planks 0
fill ~16~1~1 ~16~1~5 minecraft:grass
fill ~16~2~1 ~16~2~5 minecraft:double_plant 1
fill ~2~3~2 ~2~5~2 minecraft:wool 5
fill ~2~6~2 ~2~7~2 minecraft:wool 15
fill ~2~8~2 ~2~8~14 minecraft:planks 0
fill ~2~9~2 ~2~10~3 minecraft:wool 5
fill ~2~11~2 ~2~11~3 minecraft:wool 0
fill ~2~12~2 ~2~12~3 minecraft:wool 5
fill ~2~13~2 ~2~14~3 minecraft:wool 15
fill ~2~15~2 ~2~15~14 minecraft:planks 0
fill ~3~3~2 ~14~6~2 minecraft:bookshelf
fill ~3~7~2 ~6~7~2 minecraft:bookshelf
setblock ~7~7~2 minecraft:redstone_block
fill ~8~7~2 ~14~7~2 minecraft:bookshelf
fill ~14~9~2 ~14~14~13 minecraft:bookshelf
fill ~15~3~2 ~15~5~3 minecraft:wool 12
fill ~15~6~2 ~15~7~3 minecraft:wool 15
fill ~15~9~2 ~15~12~2 minecraft:wool 14
setblock ~15~13~2 minecraft:wool 0
setblock ~15~14~2 minecraft:wool 14
fill ~2~1~3 ~3~1~14 minecraft:dirt 0
fill ~2~2~3 ~3~2~14 minecraft:planks 0
fill ~2~3~3 ~2~7~3 minecraft:wool 11
fill ~3~3~3 ~3~7~13 minecraft:bookshelf
fill ~3~8~3 ~6~8~14 minecraft:planks 0
fill ~3~15~3 ~3~15~14 minecraft:planks 0
setblock ~4~1~3 minecraft:redstone_block
setblock ~4~2~3 minecraft:lit_redstone_lamp
setblock ~4~15~3 minecraft:glowstone
fill ~5~1~3 ~13~1~14 minecraft:dirt 0
fill ~5~2~3 ~13~2~14 minecraft:planks 0
fill ~5~15~3 ~12~15~14 minecraft:planks 0
fill ~6~9~3 ~6~9~4 minecraft:carpet 12
fill ~7~3~3 ~7~6~6 minecraft:bookshelf
setblock ~7~7~3 minecraft:bookshelf
fill ~7~8~3 ~7~8~4 minecraft:oak_stairs 1
fill ~8~7~3 ~8~7~4 minecraft:oak_stairs 1
fill ~9~6~3 ~9~6~4 minecraft:oak_stairs 1
fill ~10~5~3 ~10~5~4 minecraft:oak_stairs 1
fill ~11~3~3 ~11~3~4 minecraft:planks 0
fill ~11~4~3 ~11~4~4 minecraft:oak_stairs 1
fill ~12~3~3 ~12~3~4 minecraft:oak_stairs 1
fill ~12~8~3 ~15~8~14 minecraft:planks 0
fill ~13~9~3 ~13~12~3 minecraft:ladder 4
setblock ~13~15~3 minecraft:glowstone
setblock ~14~1~3 minecraft:redstone_block
setblock ~14~2~3 minecraft:lit_redstone_lamp
fill ~14~15~3 ~15~15~14 minecraft:planks 0
fill ~15~1~3 ~15~1~14 minecraft:dirt 0
fill ~15~2~3 ~15~2~14 minecraft:planks 0
fill ~15~9~3 ~15~12~3 minecraft:wool 3
fill ~15~13~3 ~15~14~4 minecraft:wool 15
fill ~2~3~4 ~2~7~4 minecraft:wool 3
fill ~2~9~4 ~2~13~5 minecraft:wool 4
fill ~2~14~4 ~2~14~8 minecraft:wool 15
fill ~4~1~4 ~4~1~11 minecraft:dirt 0
fill ~4~2~4 ~4~2~11 minecraft:planks 0
fill ~4~15~4 ~4~15~11 minecraft:planks 0
setblock ~5~3~4 minecraft:enchanting_table
fill ~7~7~4 ~7~7~6 minecraft:planks 0
fill ~8~3~4 ~10~3~4 minecraft:bookshelf
fill ~8~4~4 ~9~4~4 minecraft:bookshelf
setblock ~8~5~4 minecraft:bookshelf
setblock ~8~6~4 minecraft:planks 0
setblock ~9~5~4 minecraft:planks 0
setblock ~10~4~4 minecraft:planks 0
fill ~13~15~4 ~13~15~11 minecraft:planks 0
fill ~14~1~4 ~14~1~11 minecraft:dirt 0
fill ~14~2~4 ~14~2~11 minecraft:planks 0
fill ~15~3~4 ~15~6~5 minecraft:wool 14
fill ~15~7~4 ~15~7~10 minecraft:wool 15
fill ~15~9~4 ~15~12~4 minecraft:wool 11
fill ~2~3~5 ~2~5~5 minecraft:wool 14
fill ~2~6~5 ~2~7~5 minecraft:wool 15
fill ~7~8~5 ~11~8~10 minecraft:planks 0
fill ~13~9~5 ~13~12~5 minecraft:ladder 4
fill ~15~9~5 ~15~9~6 minecraft:wool 5
fill ~15~10~5 ~15~11~6 minecraft:wool 7
fill ~15~12~5 ~15~14~6 minecraft:wool 5
fill ~16~8~5 ~16~8~10 minecraft:wooden_slab 0
fill ~2~3~6 ~2~4~7 minecraft:wool 4
fill ~2~5~6 ~2~5~7 minecraft:wool 0
fill ~2~6~6 ~2~6~7 minecraft:wool 4
fill ~2~7~6 ~2~7~13 minecraft:wool 15
fill ~2~9~6 ~2~10~7 minecraft:wool 14
fill ~2~11~6 ~2~13~6 minecraft:wool 15
fill ~4~3~6 ~4~6~6 minecraft:bookshelf
fill ~4~7~6 ~6~7~6 minecraft:planks 0
setblock ~5~6~6 minecraft:planks 0
setblock ~5~9~6 minecraft:wall_sign 4
fill ~6~3~6 ~6~6~6 minecraft:bookshelf
setblock ~6~9~6 minecraft:oak_stairs 3
setblock ~7~9~6 minecraft:wall_sign 5
fill ~8~3~6 ~8~5~6 minecraft:ladder 5
setblock ~8~7~6 minecraft:torch 1
setblock ~8~9~6 minecraft:wall_sign 4
setblock ~9~9~6 minecraft:oak_stairs 3
setblock ~10~9~6 minecraft:wall_sign 5
setblock ~11~9~6 minecraft:wall_sign 4
setblock ~12~9~6 minecraft:oak_stairs 3
setblock ~13~9~6 minecraft:wall_sign 5
setblock ~15~6~6 minecraft:wool 12
fill ~16~1~6 ~16~1~9 minecraft:dirt 0
setblock ~16~2~6 minecraft:oak_stairs 2
fill ~2~11~7 ~2~12~8 minecraft:wool 14
fill ~2~13~7 ~2~13~8 minecraft:wool 15
setblock ~5~6~7 minecraft:torch 3
fill ~6~9~7 ~6~9~8 minecraft:fence 0
fill ~6~10~7 ~6~10~8 minecraft:carpet 12
fill ~9~9~7 ~9~9~8 minecraft:fence 0
fill ~9~10~7 ~9~10~8 minecraft:carpet 12
fill ~12~9~7 ~12~9~8 minecraft:fence 0
fill ~12~10~7 ~12~10~8 minecraft:carpet 12
setblock ~15~6~7 minecraft:wool 13
fill ~15~9~7 ~15~10~7 minecraft:wool 15
fill ~15~11~7 ~15~12~8 minecraft:wool 14
fill ~15~13~7 ~15~14~9 minecraft:wool 15
fill ~16~2~7 ~16~2~8 minecraft:oak_stairs 1
fill ~2~3~8 ~2~4~8 minecraft:wool 12
fill ~2~5~8 ~2~6~8 minecraft:wool 13
fill ~2~9~8 ~2~10~8 minecraft:wool 15
setblock ~5~6~8 minecraft:torch 4
fill ~15~6~8 ~15~6~9 minecraft:wool 4
fill ~15~9~8 ~15~10~9 minecraft:wool 14
fill ~2~3~9 ~2~4~9 minecraft:wool 13
fill ~2~5~9 ~2~6~9 minecraft:wool 12
fill ~2~9~9 ~2~9~10 minecraft:wool 5
fill ~2~10~9 ~2~11~10 minecraft:wool 7
fill ~2~12~9 ~2~14~10 minecraft:wool 5
fill ~4~3~9 ~4~6~9 minecraft:bookshelf
fill ~4~7~9 ~7~7~9 minecraft:planks 0
setblock ~5~6~9 minecraft:planks 0
setblock ~5~9~9 minecraft:wall_sign 4
fill ~6~3~9 ~7~6~9 minecraft:bookshelf
setblock ~6~9~9 minecraft:oak_stairs 2
setblock ~7~9~9 minecraft:wall_sign 5
fill ~8~3~9 ~8~5~9 minecraft:ladder 5
setblock ~8~7~9 minecraft:torch 1
setblock ~8~9~9 minecraft:wall_sign 4
setblock ~9~9~9 minecraft:oak_stairs 2
setblock ~10~9~9 minecraft:wall_sign 5
setblock ~11~9~9 minecraft:wall_sign 4
setblock ~12~9~9 minecraft:oak_stairs 2
setblock ~13~9~9 minecraft:wall_sign 5
fill ~15~11~9 ~15~12~9 minecraft:wool 15
setblock ~16~2~9 minecraft:oak_stairs 3
fill ~2~3~10 ~2~6~11 minecraft:wool 14
fill ~7~3~10 ~7~6~13 minecraft:bookshelf
fill ~7~7~10 ~7~7~11 minecraft:planks 0
fill ~13~9~10 ~13~12~10 minecraft:ladder 4
fill ~15~3~10 ~15~5~10 minecraft:wool 14
setblock ~15~6~10 minecraft:wool 15
fill ~15~9~10 ~15~13~11 minecraft:wool 4
fill ~15~14~10 ~15~14~13 minecraft:wool 15
fill ~16~1~10 ~16~1~16 minecraft:grass
fill ~16~2~10 ~16~2~14 minecraft:double_plant 1
fill ~2~9~11 ~2~12~11 minecraft:wool 11
fill ~2~13~11 ~2~14~12 minecraft:wool 15
setblock ~5~3~11 minecraft:enchanting_table
fill ~6~9~11 ~6~9~12 minecraft:carpet 12
fill ~7~8~11 ~7~8~12 minecraft:oak_stairs 1
fill ~8~3~11 ~10~3~11 minecraft:bookshelf
fill ~8~4~11 ~9~4~11 minecraft:bookshelf
setblock ~8~5~11 minecraft:bookshelf
setblock ~8~6~11 minecraft:planks 0
fill ~8~7~11 ~8~7~12 minecraft:oak_stairs 1
setblock ~9~5~11 minecraft:planks 0
fill ~9~6~11 ~9~6~12 minecraft:oak_stairs 1
setblock ~10~4~11 minecraft:planks 0
fill ~10~5~11 ~10~5~12 minecraft:oak_stairs 1
setblock ~11~3~11 minecraft:planks 0
fill ~11~4~11 ~11~4~12 minecraft:oak_stairs 1
fill ~12~3~11 ~12~3~12 minecraft:oak_stairs 1
fill ~15~3~11 ~15~7~11 minecraft:wool 3
fill ~2~3~12 ~2~5~13 minecraft:wool 12
fill ~2~6~12 ~2~6~13 minecraft:wool 15
fill ~2~9~12 ~2~12~12 minecraft:wool 3
setblock ~4~1~12 minecraft:redstone_block
setblock ~4~2~12 minecraft:lit_redstone_lamp
setblock ~4~15~12 minecraft:glowstone
setblock ~7~7~12 minecraft:bookshelf
fill ~13~9~12 ~13~12~12 minecraft:ladder 4
setblock ~13~15~12 minecraft:glowstone
setblock ~14~1~12 minecraft:redstone_block
setblock ~14~2~12 minecraft:lit_redstone_lamp
fill ~15~3~12 ~15~7~12 minecraft:wool 11
fill ~15~9~12 ~15~10~13 minecraft:wool 5
fill ~15~11~12 ~15~11~13 minecraft:wool 0
fill ~15~12~12 ~15~12~13 minecraft:wool 5
fill ~15~13~12 ~15~13~13 minecraft:wool 15
fill ~2~9~13 ~2~12~13 minecraft:wool 14
setblock ~2~13~13 minecraft:wool 0
setblock ~2~14~13 minecraft:wool 14
fill ~4~1~13 ~4~1~14 minecraft:dirt 0
fill ~4~2~13 ~4~2~14 minecraft:planks 0
fill ~4~3~13 ~6~7~13 minecraft:bookshelf
fill ~4~15~13 ~4~15~14 minecraft:planks 0
setblock ~7~7~13 minecraft:redstone_block
fill ~7~8~13 ~11~8~14 minecraft:planks 0
fill ~8~3~13 ~14~7~13 minecraft:bookshelf
fill ~13~15~13 ~13~15~14 minecraft:planks 0
fill ~14~1~13 ~14~1~14 minecraft:dirt 0
fill ~14~2~13 ~14~2~14 minecraft:planks 0
fill ~15~3~13 ~15~5~13 minecraft:wool 5
fill ~15~6~13 ~15~7~13 minecraft:wool 15
fill ~2~3~14 ~2~7~14 minecraft:planks 0
fill ~2~9~14 ~2~14~14 minecraft:planks 0
fill ~3~3~14 ~3~5~14 minecraft:wool 5
fill ~3~6~14 ~3~7~14 minecraft:wool 15
fill ~3~9~14 ~4~10~14 minecraft:wool 5
fill ~3~11~14 ~4~11~14 minecraft:wool 0
fill ~3~12~14 ~4~12~14 minecraft:wool 5
fill ~3~13~14 ~4~14~14 minecraft:wool 15
fill ~4~3~14 ~4~7~14 minecraft:wool 11
fill ~5~3~14 ~5~7~14 minecraft:wool 3
fill ~5~9~14 ~6~13~14 minecraft:wool 4
fill ~5~14~14 ~9~14~14 minecraft:wool 15
fill ~6~3~14 ~6~5~14 minecraft:wool 14
fill ~6~6~14 ~6~7~14 minecraft:wool 15
fill ~7~3~14 ~8~4~14 minecraft:wool 4
fill ~7~5~14 ~8~5~14 minecraft:wool 0
fill ~7~6~14 ~8~6~14 minecraft:wool 4
fill ~7~7~14 ~14~7~14 minecraft:wool 15
fill ~7~9~14 ~8~10~14 minecraft:wool 14
fill ~7~11~14 ~7~13~14 minecraft:wool 15
fill ~8~11~14 ~9~12~14 minecraft:wool 14
fill ~8~13~14 ~9~13~14 minecraft:wool 15
fill ~9~3~14 ~9~4~14 minecraft:wool 12
fill ~9~5~14 ~9~6~14 minecraft:wool 13
fill ~9~9~14 ~9~10~14 minecraft:wool 15
fill ~10~3~14 ~10~4~14 minecraft:wool 13
fill ~10~5~14 ~10~6~14 minecraft:wool 12
fill ~10~9~14 ~11~9~14 minecraft:wool 5
fill ~10~10~14 ~11~11~14 minecraft:wool 7
fill ~10~12~14 ~11~14~14 minecraft:wool 5
fill ~11~3~14 ~12~6~14 minecraft:wool 14
fill ~12~9~14 ~12~12~14 minecraft:wool 11
fill ~12~13~14 ~13~14~14 minecraft:wool 15
fill ~13~3~14 ~14~5~14 minecraft:wool 12
fill ~13~6~14 ~14~6~14 minecraft:wool 15
fill ~13~9~14 ~13~12~14 minecraft:wool 3
fill ~14~9~14 ~14~12~14 minecraft:wool 14
setblock ~14~13~14 minecraft:wool 0
setblock ~14~14~14 minecraft:wool 14
fill ~15~3~14 ~15~7~14 minecraft:planks 0
fill ~15~9~14 ~15~14~14 minecraft:planks 0
fill ~2~1~15 ~15~1~16 minecraft:grass
fill ~2~2~15 ~15~2~15 minecraft:red_flower 1