fill ~1 ~-1 ~12 ~45 ~-1 ~12 end_stone 0  
fill ~1 ~-1 ~13 ~58 ~-1 ~13 end_stone 0  
fill ~1 ~-1 ~14 ~75 ~-1 ~14 end_stone 0  
fill ~1 ~-1 ~21 ~85 ~-1 ~21 end_stone 0  
fill ~1 ~-1 ~22 ~84 ~-1 ~22 end_stone 0  
fill ~1 ~-1 ~23 ~84 ~-1 ~23 end_stone 0  
fill ~1 ~-1 ~32 ~84 ~-1 ~32 end_stone 0  
fill ~1 ~-1 ~33 ~84 ~-1 ~33 end_stone 0  
fill ~1 ~-1 ~34 ~84 ~-1 ~34 end_stone 0  
fill ~1 ~-1 ~35 ~84 ~-1 ~35 end_stone 0  
fill ~1 ~-1 ~36 ~84 ~-1 ~36 end_stone 0  
fill ~1 ~-1 ~37 ~84 ~-1 ~37 end_stone 0  
fill ~1 ~-1 ~38 ~83 ~-1 ~38 end_stone 0  
fill ~1 ~-1 ~39 ~83 ~-1 ~39 end_stone 0  
fill ~1 ~-1 ~40 ~83 ~-1 ~40 end_stone 0  
fill ~1 ~-1 ~41 ~83 ~-1 ~41 end_stone 0  
fill ~1 ~-1 ~42 ~83 ~-1 ~42 end_stone 0  
fill ~1 ~-1 ~43 ~83 ~-1 ~43 end_stone 0  
fill ~1 ~-1 ~44 ~83 ~-1 ~44 end_stone 0  
fill ~1 ~-1 ~45 ~83 ~-1 ~45 end_stone 0  
fill ~1 ~-1 ~46 ~17 ~-1 ~46 end_stone 0  
fill ~1 ~-1 ~90 ~100 ~-1 ~90 end_stone 0  
fill ~1 ~-1 ~91 ~100 ~-1 ~91 end_stone 0  
fill ~1 ~-1 ~92 ~100 ~-1 ~92 end_stone 0  
fill ~1 ~-1 ~93 ~99 ~-1 ~93 end_stone 0  
fill ~1 ~-1 ~94 ~99 ~-1 ~94 end_stone 0  
fill ~1 ~-1 ~95 ~99 ~-1 ~95 end_stone 0  
fill ~2 ~-1 ~9 ~84 ~-1 ~9 end_stone 0  
fill ~2 ~-1 ~10 ~59 ~-1 ~10 end_stone 0  
fill ~2 ~-1 ~11 ~46 ~-1 ~11 end_stone 0  
fill ~2 ~-1 ~15 ~76 ~-1 ~15 end_stone 0  
fill ~2 ~-1 ~16 ~86 ~-1 ~16 end_stone 0  
fill ~2 ~-1 ~17 ~86 ~-1 ~17 end_stone 0  
fill ~2 ~-1 ~20 ~85 ~-1 ~20 end_stone 0  
fill ~2 ~-1 ~24 ~84 ~-1 ~24 end_stone 0  
fill ~2 ~-1 ~25 ~85 ~-1 ~25 end_stone 0  
fill ~2 ~-1 ~26 ~85 ~-1 ~26 end_stone 0  
fill ~2 ~-1 ~27 ~85 ~-1 ~27 end_stone 0  
fill ~2 ~-1 ~28 ~85 ~-1 ~28 end_stone 0  
fill ~2 ~-1 ~29 ~85 ~-1 ~29 end_stone 0  
fill ~2 ~-1 ~30 ~85 ~-1 ~30 end_stone 0  
fill ~2 ~-1 ~31 ~84 ~-1 ~31 end_stone 0  
fill ~2 ~-1 ~47 ~17 ~-1 ~47 end_stone 0  
fill ~2 ~-1 ~48 ~16 ~-1 ~48 end_stone 0  
fill ~2 ~-1 ~49 ~16 ~-1 ~49 end_stone 0  
fill ~2 ~-1 ~50 ~16 ~-1 ~50 end_stone 0  
fill ~2 ~-1 ~51 ~16 ~-1 ~51 end_stone 0  
fill ~2 ~-1 ~52 ~16 ~-1 ~52 end_stone 0  
fill ~2 ~-1 ~53 ~16 ~-1 ~53 end_stone 0  
fill ~2 ~-1 ~54 ~16 ~-1 ~54 end_stone 0  
fill ~2 ~-1 ~55 ~15 ~-1 ~55 end_stone 0  
fill ~2 ~-1 ~56 ~16 ~-1 ~56 end_stone 0  
fill ~2 ~-1 ~57 ~16 ~-1 ~57 end_stone 0  
fill ~2 ~-1 ~58 ~16 ~-1 ~58 end_stone 0  
fill ~2 ~-1 ~59 ~16 ~-1 ~59 end_stone 0  
fill ~2 ~-1 ~60 ~16 ~-1 ~60 end_stone 0  
fill ~2 ~-1 ~61 ~16 ~-1 ~61 end_stone 0  
fill ~2 ~-1 ~62 ~16 ~-1 ~62 end_stone 0  
fill ~2 ~-1 ~63 ~17 ~-1 ~63 end_stone 0  
fill ~2 ~-1 ~64 ~17 ~-1 ~64 end_stone 0  
fill ~2 ~-1 ~65 ~90 ~-1 ~65 end_stone 0  
fill ~2 ~-1 ~66 ~91 ~-1 ~66 end_stone 0  
fill ~2 ~-1 ~67 ~91 ~-1 ~67 end_stone 0  
fill ~2 ~-1 ~68 ~91 ~-1 ~68 end_stone 0  
fill ~2 ~-1 ~69 ~90 ~-1 ~69 end_stone 0  
fill ~2 ~-1 ~70 ~90 ~-1 ~70 end_stone 0  
fill ~2 ~-1 ~71 ~91 ~-1 ~71 end_stone 0  
fill ~2 ~-1 ~72 ~92 ~-1 ~72 end_stone 0  
fill ~2 ~-1 ~73 ~92 ~-1 ~73 end_stone 0  
fill ~2 ~-1 ~74 ~92 ~-1 ~74 end_stone 0  
fill ~2 ~-1 ~75 ~93 ~-1 ~75 end_stone 0  
fill ~2 ~-1 ~76 ~94 ~-1 ~76 end_stone 0  
fill ~2 ~-1 ~77 ~95 ~-1 ~77 end_stone 0  
fill ~2 ~-1 ~78 ~96 ~-1 ~78 end_stone 0  
fill ~2 ~-1 ~79 ~96 ~-1 ~79 end_stone 0  
fill ~2 ~-1 ~80 ~96 ~-1 ~80 end_stone 0  
fill ~2 ~-1 ~81 ~97 ~-1 ~81 end_stone 0  
fill ~2 ~-1 ~82 ~97 ~-1 ~82 end_stone 0  
fill ~2 ~-1 ~83 ~97 ~-1 ~83 end_stone 0  
fill ~2 ~-1 ~84 ~97 ~-1 ~84 end_stone 0  
fill ~2 ~-1 ~85 ~98 ~-1 ~85 end_stone 0  
fill ~2 ~-1 ~89 ~100 ~-1 ~89 end_stone 0  
fill ~2 ~-1 ~96 ~96 ~-1 ~96 end_stone 0  
fill ~2 ~-1 ~97 ~96 ~-1 ~97 end_stone 0  
fill ~2 ~-1 ~98 ~96 ~-1 ~98 end_stone 0  
fill ~3 ~-1 ~8 ~84 ~-1 ~8 end_stone 0  
fill ~3 ~-1 ~18 ~86 ~-1 ~18 end_stone 0  
fill ~3 ~-1 ~19 ~85 ~-1 ~19 end_stone 0  
fill ~3 ~-1 ~86 ~99 ~-1 ~86 end_stone 0  
fill ~3 ~-1 ~87 ~100 ~-1 ~87 end_stone 0  
fill ~3 ~-1 ~88 ~100 ~-1 ~88 end_stone 0  
fill ~3 ~-1 ~99 ~96 ~-1 ~99 end_stone 0  
fill ~3 ~-1 ~100 ~95 ~-1 ~100 end_stone 0  
fill ~3 ~-1 ~101 ~9 ~-1 ~101 end_stone 0  
fill ~4 ~-1 ~4 ~83 ~-1 ~4 end_stone 0  
fill ~4 ~-1 ~5 ~84 ~-1 ~5 end_stone 0  
fill ~4 ~-1 ~6 ~84 ~-1 ~6 end_stone 0  
fill ~4 ~-1 ~7 ~84 ~-1 ~7 end_stone 0  
fill ~4 ~-1 ~102 ~12 ~-1 ~102 end_stone 0  
fill ~4 ~-1 ~103 ~59 ~-1 ~103 end_stone 0  
fill ~4 ~-1 ~104 ~54 ~-1 ~104 end_stone 0  
fill ~4 ~-1 ~105 ~90 ~-1 ~105 end_stone 0  
fill ~4 ~-1 ~106 ~90 ~-1 ~106 end_stone 0  
fill ~4 ~-1 ~107 ~83 ~-1 ~107 end_stone 0  
fill ~5 ~-1 ~3 ~82 ~-1 ~3 end_stone 0  
fill ~6 ~-1 ~2 ~8 ~-1 ~2 end_stone 0  
fill ~6 ~-1 ~108 ~8 ~-1 ~108 end_stone 0  
fill ~10 ~-1 ~108 ~12 ~-1 ~108 end_stone 0  
fill ~11 ~-1 ~2 ~49 ~-1 ~2 end_stone 0  
fill ~13 ~-1 ~101 ~94 ~-1 ~101 end_stone 0  
fill ~14 ~-1 ~1 ~16 ~-1 ~1 end_stone 0  
fill ~14 ~-1 ~102 ~64 ~-1 ~102 end_stone 0  
fill ~14 ~-1 ~108 ~16 ~-1 ~108 end_stone 0 
setblock ~16 ~-1 ~55 stonebrick 0  
fill ~17 ~-1 ~48 ~17 ~-1 ~62 bedrock 0  
fill ~18 ~-1 ~46 ~21 ~-1 ~46 stonebrick 0  
fill ~18 ~-1 ~47 ~19 ~-1 ~47 stonebrick 0  
fill ~18 ~-1 ~48 ~18 ~-1 ~46 stonebrick 0  
fill ~18 ~-1 ~49 ~18 ~-1 ~50 end_stone 0  
fill ~18 ~-1 ~51 ~18 ~-1 ~52 stonebrick 0  
fill ~18 ~-1 ~53 ~19 ~-1 ~53 obsidian 0  
fill ~18 ~-1 ~54 ~21 ~-1 ~54 bedrock 0 
setblock ~18 ~-1 ~55 stonebrick 0  
fill ~18 ~-1 ~56 ~21 ~-1 ~56 bedrock 0  
fill ~18 ~-1 ~57 ~19 ~-1 ~57 obsidian 0  
fill ~18 ~-1 ~58 ~19 ~-1 ~58 stonebrick 0  
fill ~18 ~-1 ~59 ~18 ~-1 ~58 stonebrick 0  
fill ~18 ~-1 ~60 ~18 ~-1 ~61 end_stone 0  
fill ~18 ~-1 ~62 ~18 ~-1 ~64 stonebrick 0  
fill ~18 ~-1 ~108 ~20 ~-1 ~108 end_stone 0 
setblock ~19 ~-1 ~48 end_stone 0  
fill ~19 ~-1 ~49 ~20 ~-1 ~49 stonebrick 0  
fill ~19 ~-1 ~50 ~22 ~-1 ~50 stonebrick 0 
setblock ~19 ~-1 ~51 end_stone 0 
setblock ~19 ~-1 ~52 stonebrick 0 
setblock ~19 ~-1 ~55 glowstone 0 
setblock ~19 ~-1 ~59 end_stone 0  
fill ~19 ~-1 ~60 ~22 ~-1 ~60 stonebrick 0  
fill ~19 ~-1 ~61 ~20 ~-1 ~61 stonebrick 0 
setblock ~19 ~-1 ~62 end_stone 0  
fill ~19 ~-1 ~63 ~19 ~-1 ~64 stonebrick 0  
fill ~20 ~-1 ~1 ~28 ~-1 ~1 end_stone 0  
fill ~20 ~-1 ~47 ~21 ~-1 ~47 end_stone 0  
fill ~20 ~-1 ~48 ~21 ~-1 ~48 stonebrick 0  
fill ~20 ~-1 ~51 ~21 ~-1 ~51 stonebrick 0  
fill ~20 ~-1 ~52 ~21 ~-1 ~52 obsidian 0  
fill ~20 ~-1 ~53 ~21 ~-1 ~53 stonebrick 0  
fill ~20 ~-1 ~55 ~22 ~-1 ~55 stonebrick 0  
fill ~20 ~-1 ~57 ~21 ~-1 ~57 stonebrick 0  
fill ~20 ~-1 ~58 ~21 ~-1 ~58 obsidian 0  
fill ~20 ~-1 ~59 ~21 ~-1 ~59 stonebrick 0  
fill ~20 ~-1 ~62 ~21 ~-1 ~62 stonebrick 0  
fill ~20 ~-1 ~63 ~21 ~-1 ~63 end_stone 0  
fill ~20 ~-1 ~64 ~21 ~-1 ~64 stonebrick 0 
setblock ~21 ~-1 ~49 bedrock 0 
setblock ~21 ~-1 ~61 bedrock 0  
fill ~22 ~-1 ~46 ~25 ~-1 ~46 end_stone 0  
fill ~22 ~-1 ~47 ~25 ~-1 ~47 stonebrick 0  
fill ~22 ~-1 ~48 ~23 ~-1 ~48 bedrock 0  
fill ~22 ~-1 ~49 ~23 ~-1 ~49 stonebrick 0 
setblock ~22 ~-1 ~51 obsidian 0  
fill ~22 ~-1 ~52 ~23 ~-1 ~52 stonebrick 0  
fill ~22 ~-1 ~53 ~23 ~-1 ~53 bedrock 0  
fill ~22 ~-1 ~54 ~24 ~-1 ~54 stonebrick 0  
fill ~22 ~-1 ~56 ~24 ~-1 ~56 stonebrick 0  
fill ~22 ~-1 ~57 ~23 ~-1 ~57 bedrock 0  
fill ~22 ~-1 ~58 ~23 ~-1 ~58 stonebrick 0 
setblock ~22 ~-1 ~59 obsidian 0  
fill ~22 ~-1 ~61 ~23 ~-1 ~61 stonebrick 0  
fill ~22 ~-1 ~62 ~23 ~-1 ~62 bedrock 0  
fill ~22 ~-1 ~63 ~25 ~-1 ~63 stonebrick 0  
fill ~22 ~-1 ~64 ~25 ~-1 ~64 end_stone 0 
setblock ~23 ~-1 ~50 obsidian 0  
fill ~23 ~-1 ~51 ~24 ~-1 ~51 stonebrick 0  
fill ~23 ~-1 ~55 ~24 ~-1 ~55 obsidian 0  
fill ~23 ~-1 ~59 ~24 ~-1 ~59 stonebrick 0 
setblock ~23 ~-1 ~60 obsidian 0  
fill ~23 ~-1 ~108 ~25 ~-1 ~108 end_stone 0  
fill ~24 ~-1 ~48 ~27 ~-1 ~48 stonebrick 0 
setblock ~24 ~-1 ~49 bedrock 0 
setblock ~24 ~-1 ~50 stonebrick 0 
setblock ~24 ~-1 ~52 bedrock 0  
fill ~24 ~-1 ~53 ~27 ~-1 ~53 stonebrick 0  
fill ~24 ~-1 ~57 ~27 ~-1 ~57 stonebrick 0 
setblock ~24 ~-1 ~58 bedrock 0 
setblock ~24 ~-1 ~60 stonebrick 0 
setblock ~24 ~-1 ~61 bedrock 0  
fill ~24 ~-1 ~62 ~27 ~-1 ~62 stonebrick 0  
fill ~25 ~-1 ~49 ~28 ~-1 ~49 stonebrick 0  
fill ~25 ~-1 ~50 ~25 ~-1 ~51 bedrock 0  
fill ~25 ~-1 ~52 ~33 ~-1 ~52 stonebrick 0  
fill ~25 ~-1 ~54 ~27 ~-1 ~54 obsidian 0  
fill ~25 ~-1 ~55 ~28 ~-1 ~55 stonebrick 0  
fill ~25 ~-1 ~56 ~27 ~-1 ~56 obsidian 0  
fill ~25 ~-1 ~58 ~33 ~-1 ~58 stonebrick 0  
fill ~25 ~-1 ~59 ~25 ~-1 ~60 bedrock 0  
fill ~25 ~-1 ~61 ~28 ~-1 ~61 stonebrick 0  
fill ~26 ~-1 ~46 ~32 ~-1 ~46 stonebrick 0  
fill ~26 ~-1 ~47 ~27 ~-1 ~47 end_stone 0  
fill ~26 ~-1 ~50 ~28 ~-1 ~50 stonebrick 0  
fill ~26 ~-1 ~51 ~28 ~-1 ~51 stonebrick 0  
fill ~26 ~-1 ~59 ~28 ~-1 ~59 stonebrick 0  
fill ~26 ~-1 ~60 ~28 ~-1 ~60 stonebrick 0  
fill ~26 ~-1 ~63 ~27 ~-1 ~63 end_stone 0  
fill ~26 ~-1 ~64 ~32 ~-1 ~64 stonebrick 0  
fill ~28 ~-1 ~47 ~30 ~-1 ~47 stonebrick 0 
setblock ~28 ~-1 ~48 end_stone 0  
fill ~28 ~-1 ~53 ~30 ~-1 ~53 obsidian 0  
fill ~28 ~-1 ~54 ~30 ~-1 ~54 stonebrick 0  
fill ~28 ~-1 ~56 ~30 ~-1 ~56 stonebrick 0  
fill ~28 ~-1 ~57 ~30 ~-1 ~57 obsidian 0 
setblock ~28 ~-1 ~62 end_stone 0  
fill ~28 ~-1 ~63 ~30 ~-1 ~63 stonebrick 0  
fill ~28 ~-1 ~108 ~34 ~-1 ~108 end_stone 0 
setblock ~29 ~-1 ~48 stonebrick 0  
fill ~29 ~-1 ~49 ~29 ~-1 ~51 end_stone 0 
setblock ~29 ~-1 ~55 glowstone 0  
fill ~29 ~-1 ~59 ~29 ~-1 ~61 end_stone 0 
setblock ~29 ~-1 ~62 stonebrick 0  
fill ~29 ~-1 ~109 ~31 ~-1 ~109 end_stone 0 
setblock ~30 ~-1 ~48 end_stone 0  
fill ~30 ~-1 ~49 ~33 ~-1 ~49 stonebrick 0  
fill ~30 ~-1 ~50 ~32 ~-1 ~50 stonebrick 0  
fill ~30 ~-1 ~51 ~32 ~-1 ~51 stonebrick 0  
fill ~30 ~-1 ~55 ~33 ~-1 ~55 stonebrick 0  
fill ~30 ~-1 ~59 ~32 ~-1 ~59 stonebrick 0  
fill ~30 ~-1 ~60 ~32 ~-1 ~60 stonebrick 0  
fill ~30 ~-1 ~61 ~33 ~-1 ~61 stonebrick 0 
setblock ~30 ~-1 ~62 end_stone 0  
fill ~31 ~-1 ~47 ~32 ~-1 ~47 end_stone 0  
fill ~31 ~-1 ~48 ~34 ~-1 ~48 stonebrick 0  
fill ~31 ~-1 ~53 ~34 ~-1 ~53 stonebrick 0  
fill ~31 ~-1 ~54 ~33 ~-1 ~54 obsidian 0  
fill ~31 ~-1 ~56 ~33 ~-1 ~56 obsidian 0  
fill ~31 ~-1 ~57 ~34 ~-1 ~57 stonebrick 0  
fill ~31 ~-1 ~62 ~34 ~-1 ~62 stonebrick 0  
fill ~31 ~-1 ~63 ~32 ~-1 ~63 end_stone 0  
fill ~33 ~-1 ~46 ~36 ~-1 ~46 end_stone 0  
fill ~33 ~-1 ~47 ~36 ~-1 ~47 stonebrick 0  
fill ~33 ~-1 ~50 ~33 ~-1 ~51 bedrock 0  
fill ~33 ~-1 ~59 ~33 ~-1 ~60 bedrock 0  
fill ~33 ~-1 ~63 ~36 ~-1 ~63 stonebrick 0  
fill ~33 ~-1 ~64 ~36 ~-1 ~64 end_stone 0 
setblock ~34 ~-1 ~49 bedrock 0  
fill ~34 ~-1 ~50 ~34 ~-1 ~51 stonebrick 0 
setblock ~34 ~-1 ~52 bedrock 0  
fill ~34 ~-1 ~54 ~36 ~-1 ~54 stonebrick 0  
fill ~34 ~-1 ~55 ~35 ~-1 ~55 obsidian 0  
fill ~34 ~-1 ~56 ~36 ~-1 ~56 stonebrick 0 
setblock ~34 ~-1 ~58 bedrock 0  
fill ~34 ~-1 ~59 ~35 ~-1 ~59 stonebrick 0  
fill ~34 ~-1 ~60 ~34 ~-1 ~59 stonebrick 0 
setblock ~34 ~-1 ~61 bedrock 0  
fill ~35 ~-1 ~48 ~36 ~-1 ~48 bedrock 0  
fill ~35 ~-1 ~49 ~36 ~-1 ~49 stonebrick 0 
setblock ~35 ~-1 ~50 obsidian 0  
fill ~35 ~-1 ~51 ~35 ~-1 ~52 stonebrick 0  
fill ~35 ~-1 ~53 ~36 ~-1 ~53 bedrock 0  
fill ~35 ~-1 ~57 ~36 ~-1 ~57 bedrock 0  
fill ~35 ~-1 ~58 ~36 ~-1 ~58 stonebrick 0 
setblock ~35 ~-1 ~60 obsidian 0  
fill ~35 ~-1 ~61 ~36 ~-1 ~61 stonebrick 0  
fill ~35 ~-1 ~62 ~36 ~-1 ~62 bedrock 0  
fill ~36 ~-1 ~50 ~39 ~-1 ~50 stonebrick 0 
setblock ~36 ~-1 ~51 obsidian 0 
setblock ~36 ~-1 ~52 stonebrick 0  
fill ~36 ~-1 ~55 ~38 ~-1 ~55 stonebrick 0 
setblock ~36 ~-1 ~59 obsidian 0  
fill ~36 ~-1 ~60 ~39 ~-1 ~60 stonebrick 0  
fill ~37 ~-1 ~46 ~51 ~-1 ~46 stonebrick 0  
fill ~37 ~-1 ~47 ~38 ~-1 ~47 end_stone 0  
fill ~37 ~-1 ~48 ~38 ~-1 ~48 stonebrick 0 
setblock ~37 ~-1 ~49 bedrock 0  
fill ~37 ~-1 ~51 ~38 ~-1 ~51 stonebrick 0  
fill ~37 ~-1 ~52 ~38 ~-1 ~52 obsidian 0  
fill ~37 ~-1 ~53 ~38 ~-1 ~53 stonebrick 0  
fill ~37 ~-1 ~54 ~40 ~-1 ~54 bedrock 0  
fill ~37 ~-1 ~56 ~40 ~-1 ~56 bedrock 0  
fill ~37 ~-1 ~57 ~38 ~-1 ~57 stonebrick 0  
fill ~37 ~-1 ~58 ~38 ~-1 ~58 obsidian 0  
fill ~37 ~-1 ~59 ~38 ~-1 ~59 stonebrick 0 
setblock ~37 ~-1 ~61 bedrock 0  
fill ~37 ~-1 ~62 ~38 ~-1 ~62 stonebrick 0  
fill ~37 ~-1 ~63 ~38 ~-1 ~63 end_stone 0  
fill ~37 ~-1 ~64 ~51 ~-1 ~64 stonebrick 0  
fill ~38 ~-1 ~49 ~39 ~-1 ~49 stonebrick 0  
fill ~38 ~-1 ~61 ~39 ~-1 ~61 stonebrick 0  
fill ~38 ~-1 ~108 ~79 ~-1 ~108 end_stone 0  
fill ~39 ~-1 ~47 ~43 ~-1 ~47 stonebrick 0 
setblock ~39 ~-1 ~48 end_stone 0 
setblock ~39 ~-1 ~51 end_stone 0  
fill ~39 ~-1 ~52 ~41 ~-1 ~52 stonebrick 0  
fill ~39 ~-1 ~53 ~41 ~-1 ~53 obsidian 0 
setblock ~39 ~-1 ~55 glowstone 0  
fill ~39 ~-1 ~57 ~41 ~-1 ~57 obsidian 0  
fill ~39 ~-1 ~58 ~41 ~-1 ~58 stonebrick 0 
setblock ~39 ~-1 ~59 end_stone 0 
setblock ~39 ~-1 ~62 end_stone 0  
fill ~39 ~-1 ~63 ~43 ~-1 ~63 stonebrick 0  
fill ~40 ~-1 ~48 ~43 ~-1 ~48 stonebrick 0  
fill ~40 ~-1 ~49 ~40 ~-1 ~50 end_stone 0  
fill ~40 ~-1 ~51 ~42 ~-1 ~51 stonebrick 0 
setblock ~40 ~-1 ~55 stonebrick 0  
fill ~40 ~-1 ~59 ~42 ~-1 ~59 stonebrick 0  
fill ~40 ~-1 ~60 ~40 ~-1 ~61 end_stone 0  
fill ~40 ~-1 ~62 ~43 ~-1 ~62 stonebrick 0  
fill ~41 ~-1 ~49 ~43 ~-1 ~49 stonebrick 0  
fill ~41 ~-1 ~50 ~42 ~-1 ~50 stonebrick 0  
fill ~41 ~-1 ~54 ~42 ~-1 ~54 stonebrick 0  
fill ~41 ~-1 ~55 ~42 ~-1 ~55 bedrock 0  
fill ~41 ~-1 ~56 ~42 ~-1 ~56 stonebrick 0  
fill ~41 ~-1 ~60 ~42 ~-1 ~60 stonebrick 0  
fill ~41 ~-1 ~61 ~43 ~-1 ~61 stonebrick 0 
setblock ~42 ~-1 ~52 obsidian 0  
fill ~42 ~-1 ~53 ~46 ~-1 ~53 stonebrick 0  
fill ~42 ~-1 ~57 ~46 ~-1 ~57 stonebrick 0 
setblock ~42 ~-1 ~58 obsidian 0  
fill ~43 ~-1 ~50 ~43 ~-1 ~51 obsidian 0  
fill ~43 ~-1 ~52 ~45 ~-1 ~52 stonebrick 0  
fill ~43 ~-1 ~54 ~45 ~-1 ~54 bedrock 0  
fill ~43 ~-1 ~55 ~45 ~-1 ~55 stonebrick 0  
fill ~43 ~-1 ~56 ~45 ~-1 ~56 bedrock 0  
fill ~43 ~-1 ~58 ~45 ~-1 ~58 stonebrick 0  
fill ~43 ~-1 ~59 ~43 ~-1 ~60 obsidian 0  
fill ~44 ~-1 ~47 ~44 ~-1 ~49 obsidian 0  
fill ~44 ~-1 ~50 ~44 ~-1 ~53 stonebrick 0  
fill ~44 ~-1 ~59 ~44 ~-1 ~60 stonebrick 0  
fill ~44 ~-1 ~61 ~44 ~-1 ~63 obsidian 0  
fill ~44 ~-1 ~109 ~78 ~-1 ~109 end_stone 0  
fill ~45 ~-1 ~47 ~49 ~-1 ~47 stonebrick 0  
fill ~45 ~-1 ~48 ~48 ~-1 ~48 stonebrick 0  
fill ~45 ~-1 ~49 ~47 ~-1 ~49 stonebrick 0  
fill ~45 ~-1 ~50 ~45 ~-1 ~51 obsidian 0  
fill ~45 ~-1 ~59 ~45 ~-1 ~60 obsidian 0  
fill ~45 ~-1 ~61 ~47 ~-1 ~61 stonebrick 0  
fill ~45 ~-1 ~62 ~48 ~-1 ~62 stonebrick 0  
fill ~45 ~-1 ~63 ~49 ~-1 ~63 stonebrick 0  
fill ~46 ~-1 ~50 ~47 ~-1 ~50 stonebrick 0  
fill ~46 ~-1 ~51 ~48 ~-1 ~51 stonebrick 0 
setblock ~46 ~-1 ~52 obsidian 0  
fill ~46 ~-1 ~54 ~47 ~-1 ~54 stonebrick 0  
fill ~46 ~-1 ~55 ~47 ~-1 ~55 bedrock 0  
fill ~46 ~-1 ~56 ~47 ~-1 ~56 stonebrick 0 
setblock ~46 ~-1 ~58 obsidian 0  
fill ~46 ~-1 ~59 ~48 ~-1 ~59 stonebrick 0  
fill ~46 ~-1 ~60 ~47 ~-1 ~60 stonebrick 0  
fill ~47 ~-1 ~12 ~75 ~-1 ~12 end_stone 0  
fill ~47 ~-1 ~52 ~49 ~-1 ~52 stonebrick 0  
fill ~47 ~-1 ~53 ~49 ~-1 ~53 obsidian 0  
fill ~47 ~-1 ~57 ~49 ~-1 ~57 obsidian 0  
fill ~47 ~-1 ~58 ~49 ~-1 ~58 stonebrick 0  
fill ~48 ~-1 ~11 ~60 ~-1 ~11 end_stone 0  
fill ~48 ~-1 ~49 ~48 ~-1 ~50 end_stone 0  
fill ~48 ~-1 ~54 ~51 ~-1 ~54 bedrock 0 
setblock ~48 ~-1 ~55 stonebrick 0  
fill ~48 ~-1 ~56 ~51 ~-1 ~56 bedrock 0  
fill ~48 ~-1 ~60 ~48 ~-1 ~61 end_stone 0 
setblock ~49 ~-1 ~48 end_stone 0  
fill ~49 ~-1 ~49 ~50 ~-1 ~49 stonebrick 0  
fill ~49 ~-1 ~50 ~52 ~-1 ~50 stonebrick 0 
setblock ~49 ~-1 ~51 end_stone 0 
setblock ~49 ~-1 ~55 glowstone 0 
setblock ~49 ~-1 ~59 end_stone 0  
fill ~49 ~-1 ~60 ~52 ~-1 ~60 stonebrick 0  
fill ~49 ~-1 ~61 ~50 ~-1 ~61 stonebrick 0 
setblock ~49 ~-1 ~62 end_stone 0  
fill ~50 ~-1 ~47 ~51 ~-1 ~47 end_stone 0  
fill ~50 ~-1 ~48 ~51 ~-1 ~48 stonebrick 0  
fill ~50 ~-1 ~51 ~51 ~-1 ~51 stonebrick 0  
fill ~50 ~-1 ~52 ~51 ~-1 ~52 obsidian 0  
fill ~50 ~-1 ~53 ~51 ~-1 ~53 stonebrick 0  
fill ~50 ~-1 ~55 ~52 ~-1 ~55 stonebrick 0  
fill ~50 ~-1 ~57 ~51 ~-1 ~57 stonebrick 0  
fill ~50 ~-1 ~58 ~51 ~-1 ~58 obsidian 0  
fill ~50 ~-1 ~59 ~51 ~-1 ~59 stonebrick 0  
fill ~50 ~-1 ~62 ~51 ~-1 ~62 stonebrick 0  
fill ~50 ~-1 ~63 ~51 ~-1 ~63 end_stone 0 
setblock ~51 ~-1 ~49 bedrock 0 
setblock ~51 ~-1 ~61 bedrock 0  
fill ~52 ~-1 ~46 ~55 ~-1 ~46 end_stone 0  
fill ~52 ~-1 ~47 ~55 ~-1 ~47 stonebrick 0  
fill ~52 ~-1 ~48 ~53 ~-1 ~48 bedrock 0  
fill ~52 ~-1 ~49 ~53 ~-1 ~49 stonebrick 0 
setblock ~52 ~-1 ~51 obsidian 0  
fill ~52 ~-1 ~52 ~53 ~-1 ~52 stonebrick 0  
fill ~52 ~-1 ~53 ~53 ~-1 ~53 bedrock 0  
fill ~52 ~-1 ~54 ~54 ~-1 ~54 stonebrick 0  
fill ~52 ~-1 ~56 ~54 ~-1 ~56 stonebrick 0  
fill ~52 ~-1 ~57 ~53 ~-1 ~57 bedrock 0  
fill ~52 ~-1 ~58 ~53 ~-1 ~58 stonebrick 0 
setblock ~52 ~-1 ~59 obsidian 0  
fill ~52 ~-1 ~61 ~53 ~-1 ~61 stonebrick 0  
fill ~52 ~-1 ~62 ~53 ~-1 ~62 bedrock 0  
fill ~52 ~-1 ~63 ~55 ~-1 ~63 stonebrick 0  
fill ~52 ~-1 ~64 ~55 ~-1 ~64 end_stone 0 
setblock ~53 ~-1 ~50 obsidian 0  
fill ~53 ~-1 ~51 ~54 ~-1 ~51 stonebrick 0  
fill ~53 ~-1 ~55 ~54 ~-1 ~55 obsidian 0  
fill ~53 ~-1 ~59 ~54 ~-1 ~59 stonebrick 0 
setblock ~53 ~-1 ~60 obsidian 0  
fill ~54 ~-1 ~2 ~58 ~-1 ~2 end_stone 0  
fill ~54 ~-1 ~48 ~57 ~-1 ~48 stonebrick 0 
setblock ~54 ~-1 ~49 bedrock 0 
setblock ~54 ~-1 ~50 stonebrick 0 
setblock ~54 ~-1 ~52 bedrock 0  
fill ~54 ~-1 ~53 ~57 ~-1 ~53 stonebrick 0  
fill ~54 ~-1 ~57 ~57 ~-1 ~57 stonebrick 0 
setblock ~54 ~-1 ~58 bedrock 0 
setblock ~54 ~-1 ~60 stonebrick 0 
setblock ~54 ~-1 ~61 bedrock 0  
fill ~54 ~-1 ~62 ~57 ~-1 ~62 stonebrick 0  
fill ~55 ~-1 ~1 ~57 ~-1 ~1 end_stone 0  
fill ~55 ~-1 ~49 ~58 ~-1 ~49 stonebrick 0  
fill ~55 ~-1 ~50 ~55 ~-1 ~51 bedrock 0  
fill ~55 ~-1 ~52 ~63 ~-1 ~52 stonebrick 0  
fill ~55 ~-1 ~54 ~57 ~-1 ~54 obsidian 0  
fill ~55 ~-1 ~55 ~58 ~-1 ~55 stonebrick 0  
fill ~55 ~-1 ~56 ~57 ~-1 ~56 obsidian 0  
fill ~55 ~-1 ~58 ~63 ~-1 ~58 stonebrick 0  
fill ~55 ~-1 ~59 ~55 ~-1 ~60 bedrock 0  
fill ~55 ~-1 ~61 ~58 ~-1 ~61 stonebrick 0  
fill ~56 ~-1 ~46 ~62 ~-1 ~46 stonebrick 0  
fill ~56 ~-1 ~47 ~57 ~-1 ~47 end_stone 0  
fill ~56 ~-1 ~50 ~58 ~-1 ~50 stonebrick 0  
fill ~56 ~-1 ~51 ~58 ~-1 ~51 stonebrick 0  
fill ~56 ~-1 ~59 ~58 ~-1 ~59 stonebrick 0  
fill ~56 ~-1 ~60 ~58 ~-1 ~60 stonebrick 0  
fill ~56 ~-1 ~63 ~57 ~-1 ~63 end_stone 0  
fill ~56 ~-1 ~64 ~62 ~-1 ~64 stonebrick 0  
fill ~56 ~-1 ~104 ~58 ~-1 ~104 end_stone 0  
fill ~58 ~-1 ~47 ~60 ~-1 ~47 stonebrick 0 
setblock ~58 ~-1 ~48 end_stone 0  
fill ~58 ~-1 ~53 ~60 ~-1 ~53 obsidian 0  
fill ~58 ~-1 ~54 ~60 ~-1 ~54 stonebrick 0  
fill ~58 ~-1 ~56 ~60 ~-1 ~56 stonebrick 0  
fill ~58 ~-1 ~57 ~60 ~-1 ~57 obsidian 0 
setblock ~58 ~-1 ~62 end_stone 0  
fill ~58 ~-1 ~63 ~60 ~-1 ~63 stonebrick 0 
setblock ~59 ~-1 ~13 bedrock 0 
setblock ~59 ~-1 ~48 stonebrick 0  
fill ~59 ~-1 ~49 ~59 ~-1 ~51 end_stone 0 
setblock ~59 ~-1 ~55 glowstone 0  
fill ~59 ~-1 ~59 ~59 ~-1 ~61 end_stone 0 
setblock ~59 ~-1 ~62 stonebrick 0  
fill ~60 ~-1 ~13 ~75 ~-1 ~13 end_stone 0 
setblock ~60 ~-1 ~48 end_stone 0  
fill ~60 ~-1 ~49 ~63 ~-1 ~49 stonebrick 0  
fill ~60 ~-1 ~50 ~62 ~-1 ~50 stonebrick 0  
fill ~60 ~-1 ~51 ~62 ~-1 ~51 stonebrick 0  
fill ~60 ~-1 ~55 ~63 ~-1 ~55 stonebrick 0  
fill ~60 ~-1 ~59 ~62 ~-1 ~59 stonebrick 0  
fill ~60 ~-1 ~60 ~62 ~-1 ~60 stonebrick 0  
fill ~60 ~-1 ~61 ~63 ~-1 ~61 stonebrick 0 
setblock ~60 ~-1 ~62 end_stone 0  
fill ~60 ~-1 ~104 ~91 ~-1 ~104 end_stone 0  
fill ~61 ~-1 ~2 ~79 ~-1 ~2 end_stone 0  
fill ~61 ~-1 ~10 ~84 ~-1 ~10 end_stone 0  
fill ~61 ~-1 ~47 ~62 ~-1 ~47 end_stone 0  
fill ~61 ~-1 ~48 ~64 ~-1 ~48 stonebrick 0  
fill ~61 ~-1 ~53 ~64 ~-1 ~53 stonebrick 0  
fill ~61 ~-1 ~54 ~63 ~-1 ~54 obsidian 0  
fill ~61 ~-1 ~56 ~63 ~-1 ~56 obsidian 0  
fill ~61 ~-1 ~57 ~64 ~-1 ~57 stonebrick 0  
fill ~61 ~-1 ~62 ~64 ~-1 ~62 stonebrick 0  
fill ~61 ~-1 ~63 ~62 ~-1 ~63 end_stone 0  
fill ~61 ~-1 ~103 ~65 ~-1 ~103 end_stone 0  
fill ~62 ~-1 ~1 ~73 ~-1 ~1 end_stone 0  
fill ~62 ~-1 ~11 ~73 ~-1 ~11 end_stone 0  
fill ~63 ~-1 ~46 ~66 ~-1 ~46 end_stone 0  
fill ~63 ~-1 ~47 ~66 ~-1 ~47 stonebrick 0  
fill ~63 ~-1 ~50 ~63 ~-1 ~51 bedrock 0  
fill ~63 ~-1 ~59 ~63 ~-1 ~60 bedrock 0  
fill ~63 ~-1 ~63 ~66 ~-1 ~63 stonebrick 0  
fill ~63 ~-1 ~64 ~66 ~-1 ~64 end_stone 0 
setblock ~64 ~-1 ~49 bedrock 0  
fill ~64 ~-1 ~50 ~64 ~-1 ~51 stonebrick 0 
setblock ~64 ~-1 ~52 bedrock 0  
fill ~64 ~-1 ~54 ~66 ~-1 ~54 stonebrick 0  
fill ~64 ~-1 ~55 ~65 ~-1 ~55 obsidian 0  
fill ~64 ~-1 ~56 ~66 ~-1 ~56 stonebrick 0 
setblock ~64 ~-1 ~58 bedrock 0  
fill ~64 ~-1 ~59 ~65 ~-1 ~59 stonebrick 0  
fill ~64 ~-1 ~60 ~64 ~-1 ~59 stonebrick 0 
setblock ~64 ~-1 ~61 bedrock 0  
fill ~65 ~-1 ~48 ~66 ~-1 ~48 bedrock 0  
fill ~65 ~-1 ~49 ~66 ~-1 ~49 stonebrick 0 
setblock ~65 ~-1 ~50 obsidian 0  
fill ~65 ~-1 ~51 ~65 ~-1 ~52 stonebrick 0  
fill ~65 ~-1 ~53 ~66 ~-1 ~53 bedrock 0  
fill ~65 ~-1 ~57 ~66 ~-1 ~57 bedrock 0  
fill ~65 ~-1 ~58 ~66 ~-1 ~58 stonebrick 0 
setblock ~65 ~-1 ~60 obsidian 0  
fill ~65 ~-1 ~61 ~66 ~-1 ~61 stonebrick 0  
fill ~65 ~-1 ~62 ~66 ~-1 ~62 bedrock 0  
fill ~66 ~-1 ~50 ~69 ~-1 ~50 stonebrick 0 
setblock ~66 ~-1 ~51 obsidian 0 
setblock ~66 ~-1 ~52 stonebrick 0  
fill ~66 ~-1 ~55 ~68 ~-1 ~55 stonebrick 0 
setblock ~66 ~-1 ~59 obsidian 0  
fill ~66 ~-1 ~60 ~69 ~-1 ~60 stonebrick 0  
fill ~67 ~-1 ~46 ~70 ~-1 ~46 stonebrick 0  
fill ~67 ~-1 ~47 ~68 ~-1 ~47 end_stone 0  
fill ~67 ~-1 ~48 ~68 ~-1 ~48 stonebrick 0 
setblock ~67 ~-1 ~49 bedrock 0  
fill ~67 ~-1 ~51 ~68 ~-1 ~51 stonebrick 0  
fill ~67 ~-1 ~52 ~68 ~-1 ~52 obsidian 0  
fill ~67 ~-1 ~53 ~68 ~-1 ~53 stonebrick 0  
fill ~67 ~-1 ~54 ~71 ~-1 ~54 bedrock 0  
fill ~67 ~-1 ~56 ~71 ~-1 ~56 bedrock 0  
fill ~67 ~-1 ~57 ~68 ~-1 ~57 stonebrick 0  
fill ~67 ~-1 ~58 ~68 ~-1 ~58 obsidian 0  
fill ~67 ~-1 ~59 ~68 ~-1 ~59 stonebrick 0 
setblock ~67 ~-1 ~61 bedrock 0  
fill ~67 ~-1 ~62 ~68 ~-1 ~62 stonebrick 0  
fill ~67 ~-1 ~63 ~68 ~-1 ~63 end_stone 0  
fill ~67 ~-1 ~64 ~70 ~-1 ~64 stonebrick 0  
fill ~67 ~-1 ~103 ~92 ~-1 ~103 end_stone 0  
fill ~68 ~-1 ~49 ~69 ~-1 ~49 stonebrick 0  
fill ~68 ~-1 ~61 ~69 ~-1 ~61 stonebrick 0  
fill ~68 ~-1 ~102 ~93 ~-1 ~102 end_stone 0  
fill ~69 ~-1 ~47 ~70 ~-1 ~47 stonebrick 0 
setblock ~69 ~-1 ~48 end_stone 0 
setblock ~69 ~-1 ~51 end_stone 0  
fill ~69 ~-1 ~52 ~70 ~-1 ~52 stonebrick 0  
fill ~69 ~-1 ~53 ~70 ~-1 ~53 obsidian 0 
setblock ~69 ~-1 ~55 glowstone 0  
fill ~69 ~-1 ~57 ~70 ~-1 ~57 obsidian 0  
fill ~69 ~-1 ~58 ~70 ~-1 ~58 stonebrick 0 
setblock ~69 ~-1 ~59 end_stone 0 
setblock ~69 ~-1 ~62 end_stone 0  
fill ~69 ~-1 ~63 ~70 ~-1 ~63 stonebrick 0 
setblock ~70 ~-1 ~48 stonebrick 0  
fill ~70 ~-1 ~49 ~70 ~-1 ~50 end_stone 0 
setblock ~70 ~-1 ~51 stonebrick 0 
setblock ~70 ~-1 ~55 stonebrick 0 
setblock ~70 ~-1 ~59 stonebrick 0  
fill ~70 ~-1 ~60 ~70 ~-1 ~61 end_stone 0 
setblock ~70 ~-1 ~62 stonebrick 0  
fill ~71 ~-1 ~46 ~83 ~-1 ~46 end_stone 0  
fill ~71 ~-1 ~47 ~83 ~-1 ~47 end_stone 0  
fill ~71 ~-1 ~48 ~71 ~-1 ~62 bedrock 0  
fill ~71 ~-1 ~63 ~83 ~-1 ~63 end_stone 0  
fill ~71 ~-1 ~64 ~83 ~-1 ~64 end_stone 0  
fill ~72 ~-1 ~48 ~83 ~-1 ~48 end_stone 0  
fill ~72 ~-1 ~49 ~83 ~-1 ~49 end_stone 0  
fill ~72 ~-1 ~50 ~83 ~-1 ~50 end_stone 0  
fill ~72 ~-1 ~51 ~83 ~-1 ~51 end_stone 0  
fill ~72 ~-1 ~52 ~83 ~-1 ~52 end_stone 0  
fill ~72 ~-1 ~53 ~83 ~-1 ~53 end_stone 0  
fill ~72 ~-1 ~54 ~83 ~-1 ~54 end_stone 0 
setblock ~72 ~-1 ~55 stonebrick 0  
fill ~72 ~-1 ~56 ~83 ~-1 ~56 end_stone 0  
fill ~72 ~-1 ~57 ~83 ~-1 ~57 end_stone 0  
fill ~72 ~-1 ~58 ~83 ~-1 ~58 end_stone 0  
fill ~72 ~-1 ~59 ~83 ~-1 ~59 end_stone 0  
fill ~72 ~-1 ~60 ~83 ~-1 ~60 end_stone 0  
fill ~72 ~-1 ~61 ~83 ~-1 ~61 end_stone 0  
fill ~72 ~-1 ~62 ~83 ~-1 ~62 end_stone 0  
fill ~73 ~-1 ~55 ~83 ~-1 ~55 end_stone 0  
fill ~78 ~-1 ~11 ~84 ~-1 ~11 end_stone 0  
fill ~78 ~-1 ~12 ~85 ~-1 ~12 end_stone 0  
fill ~78 ~-1 ~13 ~86 ~-1 ~13 end_stone 0  
fill ~78 ~-1 ~14 ~86 ~-1 ~14 end_stone 0  
fill ~79 ~-1 ~15 ~86 ~-1 ~15 end_stone 0  
fill ~86 ~-1 ~107 ~90 ~-1 ~107 end_stone 0  
fill ~87 ~-1 ~64 ~89 ~-1 ~64 end_stone 0  
fill ~1 ~0 ~12 ~8 ~0 ~12 end_stone 0  
fill ~1 ~0 ~13 ~7 ~0 ~13 end_stone 0  
fill ~1 ~0 ~14 ~7 ~0 ~14 end_stone 0  
fill ~1 ~0 ~32 ~8 ~0 ~32 end_stone 0  
fill ~1 ~0 ~33 ~8 ~0 ~33 end_stone 0  
fill ~1 ~0 ~34 ~8 ~0 ~34 end_stone 0  
fill ~1 ~0 ~35 ~7 ~0 ~35 end_stone 0  
fill ~1 ~0 ~36 ~7 ~0 ~36 end_stone 0  
fill ~1 ~0 ~37 ~7 ~0 ~37 end_stone 0  
fill ~1 ~0 ~38 ~7 ~0 ~38 end_stone 0  
fill ~1 ~0 ~39 ~7 ~0 ~39 end_stone 0  
fill ~1 ~0 ~40 ~7 ~0 ~40 end_stone 0  
fill ~1 ~0 ~41 ~7 ~0 ~41 end_stone 0  
fill ~1 ~0 ~42 ~7 ~0 ~42 end_stone 0  
fill ~1 ~0 ~43 ~7 ~0 ~43 end_stone 0  
fill ~1 ~0 ~44 ~7 ~0 ~44 end_stone 0  
fill ~1 ~0 ~45 ~7 ~0 ~45 end_stone 0  
fill ~1 ~0 ~46 ~7 ~0 ~46 end_stone 0  
fill ~1 ~0 ~90 ~7 ~0 ~90 end_stone 0  
fill ~1 ~0 ~91 ~7 ~0 ~91 end_stone 0  
fill ~1 ~0 ~92 ~7 ~0 ~92 end_stone 0  
fill ~1 ~0 ~93 ~7 ~0 ~93 end_stone 0  
fill ~1 ~0 ~94 ~7 ~0 ~94 end_stone 0  
fill ~1 ~0 ~95 ~9 ~0 ~95 end_stone 0  
fill ~2 ~0 ~9 ~24 ~0 ~9 end_stone 0  
fill ~2 ~0 ~10 ~23 ~0 ~10 end_stone 0  
fill ~2 ~0 ~11 ~22 ~0 ~11 end_stone 0  
fill ~2 ~0 ~15 ~8 ~0 ~15 end_stone 0  
fill ~2 ~0 ~16 ~8 ~0 ~16 end_stone 0  
fill ~2 ~0 ~17 ~8 ~0 ~17 end_stone 0  
fill ~2 ~0 ~20 ~7 ~0 ~20 end_stone 0  
fill ~2 ~0 ~21 ~7 ~0 ~21 end_stone 0  
fill ~2 ~0 ~22 ~7 ~0 ~22 end_stone 0  
fill ~2 ~0 ~23 ~8 ~0 ~23 end_stone 0  
fill ~2 ~0 ~24 ~8 ~0 ~24 end_stone 0  
fill ~2 ~0 ~25 ~8 ~0 ~25 end_stone 0  
fill ~2 ~0 ~26 ~8 ~0 ~26 end_stone 0  
fill ~2 ~0 ~27 ~8 ~0 ~27 end_stone 0  
fill ~2 ~0 ~28 ~8 ~0 ~28 end_stone 0  
fill ~2 ~0 ~29 ~8 ~0 ~29 end_stone 0  
fill ~2 ~0 ~30 ~8 ~0 ~30 end_stone 0  
fill ~2 ~0 ~31 ~8 ~0 ~31 end_stone 0  
fill ~2 ~0 ~47 ~8 ~0 ~47 end_stone 0  
fill ~2 ~0 ~48 ~8 ~0 ~48 end_stone 0  
fill ~2 ~0 ~49 ~8 ~0 ~49 end_stone 0  
fill ~2 ~0 ~50 ~8 ~0 ~50 end_stone 0  
fill ~2 ~0 ~51 ~8 ~0 ~51 end_stone 0  
fill ~2 ~0 ~52 ~8 ~0 ~52 end_stone 0  
fill ~2 ~0 ~53 ~8 ~0 ~53 end_stone 0  
fill ~2 ~0 ~54 ~8 ~0 ~54 end_stone 0  
fill ~2 ~0 ~55 ~8 ~0 ~55 end_stone 0  
fill ~2 ~0 ~56 ~8 ~0 ~56 end_stone 0  
fill ~2 ~0 ~57 ~8 ~0 ~57 end_stone 0  
fill ~2 ~0 ~58 ~8 ~0 ~58 end_stone 0  
fill ~2 ~0 ~59 ~8 ~0 ~59 end_stone 0  
fill ~2 ~0 ~60 ~8 ~0 ~60 end_stone 0  
fill ~2 ~0 ~61 ~8 ~0 ~61 end_stone 0  
fill ~2 ~0 ~62 ~8 ~0 ~62 end_stone 0  
fill ~2 ~0 ~63 ~8 ~0 ~63 end_stone 0  
fill ~2 ~0 ~64 ~8 ~0 ~64 end_stone 0  
fill ~2 ~0 ~65 ~8 ~0 ~65 end_stone 0  
fill ~2 ~0 ~66 ~8 ~0 ~66 end_stone 0  
fill ~2 ~0 ~67 ~8 ~0 ~67 end_stone 0  
fill ~2 ~0 ~68 ~8 ~0 ~68 end_stone 0  
fill ~2 ~0 ~69 ~8 ~0 ~69 end_stone 0  
fill ~2 ~0 ~70 ~8 ~0 ~70 end_stone 0  
fill ~2 ~0 ~71 ~8 ~0 ~71 end_stone 0  
fill ~2 ~0 ~72 ~8 ~0 ~72 end_stone 0  
fill ~2 ~0 ~73 ~8 ~0 ~73 end_stone 0  
fill ~2 ~0 ~74 ~8 ~0 ~74 end_stone 0  
fill ~2 ~0 ~75 ~8 ~0 ~75 end_stone 0  
fill ~2 ~0 ~76 ~8 ~0 ~76 end_stone 0  
fill ~2 ~0 ~77 ~8 ~0 ~77 end_stone 0  
fill ~2 ~0 ~78 ~8 ~0 ~78 end_stone 0  
fill ~2 ~0 ~79 ~8 ~0 ~79 end_stone 0  
fill ~2 ~0 ~80 ~8 ~0 ~80 end_stone 0  
fill ~2 ~0 ~81 ~8 ~0 ~81 end_stone 0  
fill ~2 ~0 ~82 ~8 ~0 ~82 end_stone 0  
fill ~2 ~0 ~83 ~8 ~0 ~83 end_stone 0  
fill ~2 ~0 ~84 ~8 ~0 ~84 end_stone 0  
fill ~2 ~0 ~85 ~8 ~0 ~85 end_stone 0  
fill ~2 ~0 ~89 ~8 ~0 ~89 end_stone 0  
fill ~2 ~0 ~96 ~10 ~0 ~96 end_stone 0  
fill ~3 ~0 ~8 ~24 ~0 ~8 end_stone 0  
fill ~3 ~0 ~18 ~7 ~0 ~18 end_stone 0  
fill ~3 ~0 ~19 ~7 ~0 ~19 end_stone 0  
fill ~3 ~0 ~86 ~8 ~0 ~86 end_stone 0  
fill ~3 ~0 ~87 ~8 ~0 ~87 end_stone 0  
fill ~3 ~0 ~88 ~8 ~0 ~88 end_stone 0  
fill ~3 ~0 ~97 ~11 ~0 ~97 end_stone 0  
fill ~3 ~0 ~98 ~11 ~0 ~98 end_stone 0  
fill ~3 ~0 ~99 ~10 ~0 ~99 end_stone 0  
fill ~4 ~0 ~4 ~83 ~0 ~4 end_stone 0  
fill ~4 ~0 ~5 ~83 ~0 ~5 end_stone 0  
fill ~4 ~0 ~6 ~83 ~0 ~6 end_stone 0  
fill ~4 ~0 ~7 ~24 ~0 ~7 end_stone 0  
fill ~4 ~0 ~100 ~10 ~0 ~100 end_stone 0  
fill ~4 ~0 ~101 ~14 ~0 ~101 end_stone 0  
fill ~4 ~0 ~102 ~16 ~0 ~102 end_stone 0  
fill ~4 ~0 ~104 ~49 ~0 ~104 end_stone 0  
fill ~4 ~0 ~105 ~89 ~0 ~105 end_stone 0  
fill ~4 ~0 ~106 ~89 ~0 ~106 end_stone 0  
fill ~5 ~0 ~3 ~50 ~0 ~3 end_stone 0  
fill ~5 ~0 ~103 ~47 ~0 ~103 end_stone 0  
fill ~5 ~0 ~107 ~35 ~0 ~107 end_stone 0  
fill ~6 ~0 ~2 ~8 ~0 ~2 end_stone 0  
fill ~6 ~0 ~108 ~8 ~0 ~108 end_stone 0  
fill ~9 ~0 ~49 ~12 ~0 ~49 obsidian 0  
fill ~9 ~0 ~61 ~12 ~0 ~61 obsidian 0  
fill ~10 ~0 ~47 ~10 ~0 ~50 obsidian 0 
setblock ~10 ~0 ~60 obsidian 0  
fill ~10 ~0 ~62 ~11 ~0 ~62 obsidian 0  
fill ~10 ~0 ~63 ~10 ~0 ~60 obsidian 0  
fill ~10 ~0 ~108 ~12 ~0 ~108 end_stone 0  
fill ~11 ~0 ~2 ~29 ~0 ~2 end_stone 0  
fill ~11 ~0 ~12 ~20 ~0 ~12 end_stone 0 
setblock ~11 ~0 ~48 obsidian 0  
fill ~12 ~0 ~19 ~12 ~41 ~19 bedrock 0  
fill ~12 ~0 ~20 ~12 ~3 ~20 obsidian 0  
fill ~12 ~0 ~26 ~12 ~3 ~26 obsidian 0  
fill ~12 ~0 ~27 ~16 ~0 ~27 bedrock 0  
fill ~12 ~0 ~83 ~16 ~0 ~83 bedrock 0  
fill ~12 ~0 ~84 ~12 ~3 ~84 obsidian 0  
fill ~12 ~0 ~90 ~12 ~3 ~90 obsidian 0  
fill ~12 ~0 ~91 ~12 ~41 ~91 bedrock 0  
fill ~13 ~0 ~19 ~13 ~3 ~19 obsidian 0  
fill ~13 ~0 ~20 ~13 ~40 ~20 stonebrick 0  
fill ~13 ~0 ~26 ~16 ~0 ~26 bedrock 0  
fill ~13 ~0 ~84 ~16 ~0 ~84 bedrock 0  
fill ~13 ~0 ~90 ~13 ~40 ~90 stonebrick 0  
fill ~13 ~0 ~91 ~13 ~3 ~91 obsidian 0  
fill ~14 ~0 ~108 ~16 ~0 ~108 end_stone 0  
fill ~15 ~0 ~13 ~19 ~0 ~13 end_stone 0  
fill ~15 ~0 ~30 ~15 ~0 ~31 obsidian 0  
fill ~15 ~0 ~41 ~15 ~5 ~41 obsidian 0  
fill ~15 ~0 ~45 ~15 ~5 ~45 obsidian 0  
fill ~15 ~0 ~65 ~15 ~5 ~65 obsidian 0  
fill ~15 ~0 ~69 ~15 ~5 ~69 obsidian 0 
setblock ~15 ~0 ~73 obsidian 0  
fill ~15 ~0 ~81 ~15 ~2 ~81 obsidian 0  
fill ~16 ~0 ~14 ~18 ~0 ~14 end_stone 0  
fill ~16 ~0 ~28 ~16 ~0 ~46 bedrock 0  
fill ~16 ~0 ~47 ~16 ~4 ~47 obsidian 0  
fill ~16 ~0 ~63 ~16 ~4 ~63 obsidian 0  
fill ~16 ~0 ~64 ~16 ~0 ~84 bedrock 0 
setblock ~17 ~0 ~40 bedrock 0  
fill ~17 ~0 ~41 ~17 ~5 ~41 end_stone 0  
fill ~17 ~0 ~42 ~17 ~0 ~45 end_stone 0 
setblock ~17 ~0 ~47 bedrock 0 
setblock ~17 ~0 ~63 bedrock 0  
fill ~17 ~0 ~65 ~17 ~5 ~65 end_stone 0  
fill ~17 ~0 ~66 ~17 ~0 ~69 end_stone 0 
setblock ~17 ~0 ~70 bedrock 0  
fill ~18 ~0 ~41 ~18 ~0 ~46 bedrock 0  
fill ~18 ~0 ~47 ~18 ~4 ~47 obsidian 0  
fill ~18 ~0 ~63 ~18 ~4 ~63 obsidian 0  
fill ~18 ~0 ~64 ~18 ~0 ~69 bedrock 0  
fill ~18 ~0 ~87 ~21 ~0 ~87 bedrock 0  
fill ~18 ~0 ~88 ~20 ~0 ~88 bedrock 0  
fill ~18 ~0 ~102 ~20 ~0 ~102 end_stone 0  
fill ~18 ~0 ~108 ~20 ~0 ~108 end_stone 0  
fill ~19 ~0 ~19 ~19 ~3 ~19 obsidian 0  
fill ~19 ~0 ~20 ~20 ~0 ~20 bedrock 0  
fill ~19 ~0 ~21 ~20 ~0 ~21 bedrock 0  
fill ~19 ~0 ~22 ~20 ~0 ~22 bedrock 0  
fill ~19 ~0 ~23 ~21 ~0 ~23 bedrock 0  
fill ~19 ~0 ~89 ~20 ~0 ~89 bedrock 0  
fill ~19 ~0 ~90 ~20 ~0 ~90 bedrock 0  
fill ~19 ~0 ~91 ~19 ~3 ~91 obsidian 0  
fill ~20 ~0 ~19 ~20 ~41 ~19 bedrock 0  
fill ~20 ~0 ~91 ~20 ~41 ~91 bedrock 0  
fill ~21 ~0 ~22 ~21 ~4 ~22 obsidian 0  
fill ~21 ~0 ~88 ~21 ~4 ~88 obsidian 0  
fill ~23 ~0 ~102 ~25 ~0 ~102 end_stone 0  
fill ~23 ~0 ~108 ~25 ~0 ~108 end_stone 0  
fill ~26 ~0 ~7 ~83 ~0 ~7 end_stone 0  
fill ~27 ~0 ~22 ~27 ~4 ~22 obsidian 0  
fill ~27 ~0 ~23 ~31 ~0 ~23 bedrock 0  
fill ~27 ~0 ~87 ~31 ~0 ~87 bedrock 0  
fill ~27 ~0 ~88 ~27 ~4 ~88 obsidian 0  
fill ~27 ~0 ~102 ~42 ~0 ~102 end_stone 0  
fill ~28 ~0 ~16 ~30 ~0 ~16 bedrock 0  
fill ~28 ~0 ~18 ~30 ~0 ~18 bedrock 0  
fill ~28 ~0 ~19 ~30 ~0 ~19 bedrock 0  
fill ~28 ~0 ~21 ~30 ~0 ~21 bedrock 0  
fill ~28 ~0 ~22 ~30 ~0 ~22 bedrock 0  
fill ~28 ~0 ~43 ~28 ~19 ~43 bedrock 0  
fill ~28 ~0 ~45 ~28 ~19 ~45 bedrock 0  
fill ~28 ~0 ~65 ~28 ~19 ~65 bedrock 0  
fill ~28 ~0 ~67 ~28 ~19 ~67 bedrock 0  
fill ~28 ~0 ~88 ~30 ~0 ~88 bedrock 0  
fill ~28 ~0 ~89 ~30 ~0 ~89 bedrock 0  
fill ~28 ~0 ~91 ~30 ~0 ~91 bedrock 0  
fill ~28 ~0 ~92 ~30 ~0 ~92 bedrock 0  
fill ~28 ~0 ~94 ~30 ~0 ~94 bedrock 0  
fill ~28 ~0 ~108 ~34 ~0 ~108 end_stone 0  
fill ~29 ~0 ~8 ~83 ~0 ~8 end_stone 0  
fill ~29 ~0 ~13 ~29 ~0 ~23 bedrock 0  
fill ~29 ~0 ~90 ~29 ~15 ~90 bedrock 0  
fill ~29 ~0 ~93 ~29 ~2 ~93 bedrock 0  
fill ~29 ~0 ~95 ~29 ~0 ~97 bedrock 0  
fill ~29 ~0 ~109 ~31 ~0 ~109 end_stone 0  
fill ~30 ~0 ~9 ~83 ~0 ~9 end_stone 0  
fill ~30 ~0 ~43 ~30 ~19 ~43 bedrock 0  
fill ~30 ~0 ~45 ~30 ~19 ~45 bedrock 0  
fill ~30 ~0 ~65 ~30 ~19 ~65 bedrock 0  
fill ~30 ~0 ~67 ~30 ~19 ~67 bedrock 0  
fill ~31 ~0 ~10 ~83 ~0 ~10 end_stone 0  
fill ~31 ~0 ~22 ~31 ~4 ~22 obsidian 0  
fill ~31 ~0 ~88 ~31 ~4 ~88 obsidian 0  
fill ~35 ~0 ~11 ~39 ~0 ~11 end_stone 0  
fill ~36 ~0 ~12 ~38 ~0 ~12 end_stone 0   
fill ~37 ~0 ~22 ~37 ~4 ~22 obsidian 0  
fill ~37 ~0 ~23 ~41 ~0 ~23 bedrock 0  
fill ~37 ~0 ~87 ~41 ~0 ~87 bedrock 0  
fill ~37 ~0 ~88 ~37 ~4 ~88 obsidian 0  
fill ~37 ~0 ~107 ~83 ~0 ~107 end_stone 0  
fill ~38 ~0 ~16 ~40 ~0 ~16 bedrock 0  
fill ~38 ~0 ~18 ~40 ~0 ~18 bedrock 0  
fill ~38 ~0 ~19 ~40 ~0 ~19 bedrock 0  
fill ~38 ~0 ~21 ~40 ~0 ~21 bedrock 0  
fill ~38 ~0 ~22 ~40 ~0 ~22 bedrock 0  
fill ~38 ~0 ~43 ~38 ~19 ~43 bedrock 0  
fill ~38 ~0 ~45 ~38 ~19 ~45 bedrock 0  
fill ~38 ~0 ~65 ~38 ~19 ~65 bedrock 0  
fill ~38 ~0 ~67 ~38 ~19 ~67 bedrock 0  
fill ~38 ~0 ~88 ~40 ~0 ~88 bedrock 0  
fill ~38 ~0 ~89 ~40 ~0 ~89 bedrock 0  
fill ~38 ~0 ~91 ~40 ~0 ~91 bedrock 0  
fill ~38 ~0 ~92 ~40 ~0 ~92 bedrock 0  
fill ~38 ~0 ~94 ~40 ~0 ~94 bedrock 0  
fill ~38 ~0 ~108 ~79 ~0 ~108 end_stone 0  
fill ~39 ~0 ~13 ~39 ~0 ~23 bedrock 0  
fill ~39 ~0 ~90 ~39 ~15 ~90 bedrock 0  
fill ~39 ~0 ~93 ~39 ~2 ~93 bedrock 0  
fill ~39 ~0 ~95 ~39 ~0 ~97 bedrock 0  
fill ~40 ~0 ~43 ~40 ~19 ~43 bedrock 0  
fill ~40 ~0 ~45 ~40 ~19 ~45 bedrock 0  
fill ~40 ~0 ~65 ~40 ~19 ~65 bedrock 0  
fill ~40 ~0 ~67 ~40 ~19 ~67 bedrock 0  
fill ~41 ~0 ~22 ~41 ~4 ~22 obsidian 0  
fill ~41 ~0 ~88 ~41 ~4 ~88 obsidian 0  
fill ~42 ~0 ~11 ~57 ~0 ~11 end_stone 0  
fill ~43 ~0 ~12 ~46 ~0 ~12 end_stone 0  
fill ~44 ~0 ~109 ~69 ~0 ~109 end_stone 0  
fill ~47 ~0 ~22 ~47 ~4 ~22 obsidian 0  
fill ~47 ~0 ~23 ~51 ~0 ~23 bedrock 0  
fill ~47 ~0 ~87 ~51 ~0 ~87 bedrock 0  
fill ~47 ~0 ~88 ~47 ~4 ~88 obsidian 0  
fill ~48 ~0 ~16 ~50 ~0 ~16 bedrock 0  
fill ~48 ~0 ~18 ~50 ~0 ~18 bedrock 0  
fill ~48 ~0 ~19 ~50 ~0 ~19 bedrock 0  
fill ~48 ~0 ~21 ~50 ~0 ~21 bedrock 0  
fill ~48 ~0 ~22 ~50 ~0 ~22 bedrock 0  
fill ~48 ~0 ~43 ~48 ~19 ~43 bedrock 0  
fill ~48 ~0 ~45 ~48 ~19 ~45 bedrock 0  
fill ~48 ~0 ~65 ~48 ~19 ~65 bedrock 0  
fill ~48 ~0 ~67 ~48 ~19 ~67 bedrock 0  
fill ~48 ~0 ~88 ~50 ~0 ~88 bedrock 0  
fill ~48 ~0 ~89 ~50 ~0 ~89 bedrock 0  
fill ~48 ~0 ~91 ~50 ~0 ~91 bedrock 0  
fill ~48 ~0 ~92 ~50 ~0 ~92 bedrock 0  
fill ~48 ~0 ~94 ~50 ~0 ~94 bedrock 0  
fill ~49 ~0 ~13 ~49 ~0 ~23 bedrock 0  
fill ~49 ~0 ~90 ~49 ~15 ~90 bedrock 0  
fill ~49 ~0 ~93 ~49 ~2 ~93 bedrock 0  
fill ~49 ~0 ~95 ~49 ~0 ~97 bedrock 0  
fill ~50 ~0 ~43 ~50 ~19 ~43 bedrock 0  
fill ~50 ~0 ~45 ~50 ~19 ~45 bedrock 0  
fill ~50 ~0 ~65 ~50 ~19 ~65 bedrock 0  
fill ~50 ~0 ~67 ~50 ~19 ~67 bedrock 0  
fill ~51 ~0 ~12 ~57 ~0 ~12 end_stone 0  
fill ~51 ~0 ~13 ~57 ~0 ~13 end_stone 0  
fill ~51 ~0 ~22 ~51 ~4 ~22 obsidian 0  
fill ~51 ~0 ~88 ~51 ~4 ~88 obsidian 0  
fill ~52 ~0 ~14 ~56 ~0 ~14 end_stone 0  
fill ~53 ~0 ~3 ~59 ~0 ~3 end_stone 0  
fill ~53 ~0 ~15 ~55 ~0 ~15 end_stone 0  
fill ~54 ~0 ~2 ~58 ~0 ~2 end_stone 0  
fill ~55 ~0 ~1 ~57 ~0 ~1 end_stone 0  
fill ~55 ~0 ~104 ~91 ~0 ~104 end_stone 0  
fill ~57 ~0 ~22 ~57 ~4 ~22 obsidian 0  
fill ~57 ~0 ~23 ~61 ~0 ~23 bedrock 0  
fill ~57 ~0 ~87 ~61 ~0 ~87 bedrock 0  
fill ~57 ~0 ~88 ~57 ~4 ~88 obsidian 0  
fill ~58 ~0 ~16 ~60 ~0 ~16 bedrock 0  
fill ~58 ~0 ~18 ~60 ~0 ~18 bedrock 0  
fill ~58 ~0 ~19 ~60 ~0 ~19 bedrock 0  
fill ~58 ~0 ~21 ~60 ~0 ~21 bedrock 0  
fill ~58 ~0 ~22 ~60 ~0 ~22 bedrock 0  
fill ~58 ~0 ~43 ~58 ~19 ~43 bedrock 0  
fill ~58 ~0 ~45 ~58 ~19 ~45 bedrock 0  
fill ~58 ~0 ~65 ~58 ~19 ~65 bedrock 0  
fill ~58 ~0 ~67 ~58 ~19 ~67 bedrock 0  
fill ~58 ~0 ~88 ~60 ~0 ~88 bedrock 0  
fill ~58 ~0 ~89 ~60 ~0 ~89 bedrock 0  
fill ~58 ~0 ~91 ~60 ~0 ~91 bedrock 0  
fill ~58 ~0 ~92 ~60 ~0 ~92 bedrock 0  
fill ~58 ~0 ~94 ~60 ~0 ~94 bedrock 0  
fill ~59 ~0 ~14 ~59 ~0 ~23 bedrock 0  
fill ~59 ~0 ~90 ~59 ~15 ~90 bedrock 0  
fill ~59 ~0 ~93 ~59 ~2 ~93 bedrock 0  
fill ~59 ~0 ~95 ~59 ~0 ~97 bedrock 0  
fill ~60 ~0 ~43 ~60 ~19 ~43 bedrock 0  
fill ~60 ~0 ~45 ~60 ~19 ~45 bedrock 0  
fill ~60 ~0 ~65 ~60 ~19 ~65 bedrock 0  
fill ~60 ~0 ~67 ~60 ~19 ~67 bedrock 0  
fill ~60 ~0 ~102 ~93 ~0 ~102 end_stone 0  
fill ~60 ~0 ~103 ~92 ~0 ~103 end_stone 0  
fill ~61 ~0 ~2 ~74 ~0 ~2 end_stone 0  
fill ~61 ~0 ~3 ~80 ~0 ~3 end_stone 0  
fill ~61 ~0 ~11 ~83 ~0 ~11 end_stone 0  
fill ~61 ~0 ~12 ~67 ~0 ~12 end_stone 0  
fill ~61 ~0 ~22 ~61 ~4 ~22 obsidian 0  
fill ~61 ~0 ~88 ~61 ~4 ~88 obsidian 0  
fill ~67 ~0 ~22 ~67 ~4 ~22 obsidian 0  
fill ~67 ~0 ~23 ~68 ~0 ~23 bedrock 0  
fill ~67 ~0 ~87 ~69 ~0 ~87 bedrock 0  
fill ~67 ~0 ~88 ~67 ~4 ~88 obsidian 0  
fill ~67 ~0 ~101 ~94 ~0 ~101 end_stone 0  
fill ~68 ~0 ~19 ~68 ~41 ~19 bedrock 0  
fill ~68 ~0 ~20 ~69 ~0 ~20 bedrock 0  
fill ~68 ~0 ~21 ~69 ~0 ~21 bedrock 0  
fill ~68 ~0 ~22 ~69 ~0 ~22 bedrock 0  
fill ~68 ~0 ~88 ~69 ~0 ~88 bedrock 0  
fill ~68 ~0 ~89 ~69 ~0 ~89 bedrock 0  
fill ~68 ~0 ~90 ~69 ~0 ~90 bedrock 0  
fill ~68 ~0 ~91 ~68 ~41 ~91 bedrock 0  
fill ~69 ~0 ~19 ~69 ~3 ~19 obsidian 0  
fill ~69 ~0 ~91 ~69 ~3 ~91 obsidian 0  
fill ~70 ~0 ~41 ~70 ~0 ~46 bedrock 0  
fill ~70 ~0 ~47 ~70 ~4 ~47 obsidian 0  
fill ~70 ~0 ~63 ~70 ~4 ~63 obsidian 0  
fill ~70 ~0 ~64 ~70 ~0 ~69 bedrock 0  
fill ~71 ~0 ~40 ~72 ~0 ~40 bedrock 0  
fill ~71 ~0 ~41 ~71 ~5 ~41 end_stone 0  
fill ~71 ~0 ~42 ~71 ~0 ~45 end_stone 0 
setblock ~71 ~0 ~47 bedrock 0 
setblock ~71 ~0 ~63 bedrock 0  
fill ~71 ~0 ~65 ~71 ~5 ~65 end_stone 0  
fill ~71 ~0 ~66 ~71 ~0 ~69 end_stone 0  
fill ~71 ~0 ~70 ~72 ~0 ~70 bedrock 0  
fill ~72 ~0 ~26 ~75 ~0 ~26 bedrock 0  
fill ~72 ~0 ~27 ~76 ~0 ~27 bedrock 0  
fill ~72 ~0 ~28 ~72 ~0 ~46 bedrock 0  
fill ~72 ~0 ~47 ~72 ~4 ~47 obsidian 0  
fill ~72 ~0 ~63 ~72 ~4 ~63 obsidian 0  
fill ~72 ~0 ~64 ~72 ~0 ~84 bedrock 0  
fill ~72 ~0 ~99 ~96 ~0 ~99 end_stone 0  
fill ~72 ~0 ~100 ~95 ~0 ~100 end_stone 0  
fill ~73 ~0 ~29 ~73 ~2 ~29 obsidian 0 
setblock ~73 ~0 ~37 obsidian 0  
fill ~73 ~0 ~41 ~73 ~5 ~41 obsidian 0  
fill ~73 ~0 ~45 ~73 ~5 ~45 obsidian 0  
fill ~73 ~0 ~65 ~73 ~5 ~65 obsidian 0  
fill ~73 ~0 ~69 ~73 ~5 ~69 obsidian 0  
fill ~73 ~0 ~79 ~73 ~0 ~80 obsidian 0  
fill ~73 ~0 ~83 ~76 ~0 ~83 bedrock 0  
fill ~73 ~0 ~84 ~75 ~0 ~84 bedrock 0  
fill ~73 ~0 ~98 ~97 ~0 ~98 end_stone 0  
fill ~74 ~0 ~97 ~76 ~0 ~97 end_stone 0  
fill ~75 ~0 ~19 ~75 ~3 ~19 obsidian 0  
fill ~75 ~0 ~20 ~75 ~40 ~20 stonebrick 0  
fill ~75 ~0 ~90 ~75 ~40 ~90 stonebrick 0  
fill ~75 ~0 ~91 ~75 ~3 ~91 obsidian 0  
fill ~76 ~0 ~12 ~85 ~0 ~12 end_stone 0  
fill ~76 ~0 ~13 ~85 ~0 ~13 end_stone 0  
fill ~76 ~0 ~14 ~85 ~0 ~14 end_stone 0  
fill ~76 ~0 ~19 ~76 ~41 ~19 bedrock 0  
fill ~76 ~0 ~20 ~76 ~3 ~20 obsidian 0  
fill ~76 ~0 ~26 ~76 ~3 ~26 obsidian 0  
fill ~76 ~0 ~49 ~79 ~0 ~49 obsidian 0  
fill ~76 ~0 ~61 ~79 ~0 ~61 obsidian 0  
fill ~76 ~0 ~84 ~76 ~3 ~84 obsidian 0  
fill ~76 ~0 ~90 ~76 ~3 ~90 obsidian 0  
fill ~76 ~0 ~91 ~76 ~41 ~91 bedrock 0  
fill ~77 ~0 ~15 ~85 ~0 ~15 end_stone 0  
fill ~77 ~0 ~16 ~85 ~0 ~16 end_stone 0  
fill ~77 ~0 ~17 ~85 ~0 ~17 end_stone 0  
fill ~77 ~0 ~32 ~83 ~0 ~32 end_stone 0  
fill ~77 ~0 ~33 ~83 ~0 ~33 end_stone 0  
fill ~77 ~0 ~34 ~83 ~0 ~34 end_stone 0  
fill ~77 ~0 ~48 ~78 ~0 ~48 obsidian 0  
fill ~77 ~0 ~62 ~78 ~0 ~62 obsidian 0  
fill ~78 ~0 ~18 ~85 ~0 ~18 end_stone 0  
fill ~78 ~0 ~30 ~84 ~0 ~30 end_stone 0  
fill ~78 ~0 ~31 ~84 ~0 ~31 end_stone 0  
fill ~78 ~0 ~35 ~83 ~0 ~35 end_stone 0 
setblock ~78 ~0 ~47 obsidian 0 
setblock ~78 ~0 ~50 obsidian 0 
setblock ~78 ~0 ~60 obsidian 0 
setblock ~78 ~0 ~63 obsidian 0  
fill ~78 ~0 ~97 ~97 ~0 ~97 end_stone 0  
fill ~79 ~0 ~21 ~84 ~0 ~21 end_stone 0  
fill ~79 ~0 ~22 ~84 ~0 ~22 end_stone 0  
fill ~79 ~0 ~23 ~84 ~0 ~23 end_stone 0  
fill ~79 ~0 ~24 ~84 ~0 ~24 end_stone 0  
fill ~79 ~0 ~25 ~84 ~0 ~25 end_stone 0  
fill ~79 ~0 ~36 ~83 ~0 ~36 end_stone 0  
fill ~79 ~0 ~92 ~100 ~0 ~92 end_stone 0  
fill ~79 ~0 ~93 ~100 ~0 ~93 end_stone 0  
fill ~79 ~0 ~94 ~100 ~0 ~94 end_stone 0  
fill ~79 ~0 ~95 ~99 ~0 ~95 end_stone 0  
fill ~79 ~0 ~96 ~98 ~0 ~96 end_stone 0  
fill ~80 ~0 ~19 ~85 ~0 ~19 end_stone 0  
fill ~80 ~0 ~20 ~84 ~0 ~20 end_stone 0  
fill ~80 ~0 ~26 ~84 ~0 ~26 end_stone 0  
fill ~80 ~0 ~27 ~84 ~0 ~27 end_stone 0  
fill ~80 ~0 ~28 ~84 ~0 ~28 end_stone 0  
fill ~80 ~0 ~29 ~84 ~0 ~29 end_stone 0  
fill ~80 ~0 ~37 ~82 ~0 ~37 end_stone 0  
fill ~80 ~0 ~38 ~82 ~0 ~38 end_stone 0  
fill ~80 ~0 ~39 ~82 ~0 ~39 end_stone 0  
fill ~80 ~0 ~40 ~82 ~0 ~40 end_stone 0  
fill ~80 ~0 ~41 ~82 ~0 ~41 end_stone 0  
fill ~80 ~0 ~42 ~82 ~0 ~42 end_stone 0  
fill ~80 ~0 ~43 ~82 ~0 ~43 end_stone 0  
fill ~80 ~0 ~44 ~82 ~0 ~44 end_stone 0  
fill ~80 ~0 ~45 ~82 ~0 ~45 end_stone 0  
fill ~80 ~0 ~46 ~82 ~0 ~46 end_stone 0  
fill ~80 ~0 ~47 ~82 ~0 ~47 end_stone 0  
fill ~80 ~0 ~48 ~82 ~0 ~48 end_stone 0  
fill ~80 ~0 ~49 ~82 ~0 ~49 end_stone 0  
fill ~80 ~0 ~50 ~82 ~0 ~50 end_stone 0  
fill ~80 ~0 ~51 ~82 ~0 ~51 end_stone 0  
fill ~80 ~0 ~52 ~82 ~0 ~52 end_stone 0  
fill ~80 ~0 ~53 ~82 ~0 ~53 end_stone 0  
fill ~80 ~0 ~54 ~82 ~0 ~54 end_stone 0  
fill ~80 ~0 ~55 ~82 ~0 ~55 end_stone 0  
fill ~80 ~0 ~56 ~82 ~0 ~56 end_stone 0  
fill ~80 ~0 ~57 ~82 ~0 ~57 end_stone 0  
fill ~80 ~0 ~58 ~82 ~0 ~58 end_stone 0  
fill ~80 ~0 ~59 ~82 ~0 ~59 end_stone 0  
fill ~80 ~0 ~60 ~82 ~0 ~60 end_stone 0  
fill ~80 ~0 ~61 ~82 ~0 ~61 end_stone 0  
fill ~80 ~0 ~62 ~82 ~0 ~62 end_stone 0  
fill ~80 ~0 ~63 ~82 ~0 ~63 end_stone 0  
fill ~80 ~0 ~64 ~82 ~0 ~64 end_stone 0  
fill ~80 ~0 ~65 ~82 ~0 ~65 end_stone 0  
fill ~80 ~0 ~66 ~90 ~0 ~66 end_stone 0  
fill ~80 ~0 ~67 ~90 ~0 ~67 end_stone 0  
fill ~80 ~0 ~68 ~90 ~0 ~68 end_stone 0  
fill ~80 ~0 ~69 ~90 ~0 ~69 end_stone 0  
fill ~80 ~0 ~70 ~90 ~0 ~70 end_stone 0  
fill ~80 ~0 ~71 ~91 ~0 ~71 end_stone 0  
fill ~80 ~0 ~72 ~91 ~0 ~72 end_stone 0  
fill ~80 ~0 ~73 ~91 ~0 ~73 end_stone 0  
fill ~80 ~0 ~74 ~92 ~0 ~74 end_stone 0  
fill ~80 ~0 ~75 ~93 ~0 ~75 end_stone 0  
fill ~80 ~0 ~76 ~94 ~0 ~76 end_stone 0  
fill ~80 ~0 ~77 ~95 ~0 ~77 end_stone 0  
fill ~80 ~0 ~78 ~96 ~0 ~78 end_stone 0  
fill ~80 ~0 ~82 ~98 ~0 ~82 end_stone 0  
fill ~80 ~0 ~83 ~98 ~0 ~83 end_stone 0  
fill ~80 ~0 ~84 ~98 ~0 ~84 end_stone 0  
fill ~80 ~0 ~85 ~98 ~0 ~85 end_stone 0  
fill ~80 ~0 ~86 ~99 ~0 ~86 end_stone 0  
fill ~80 ~0 ~87 ~100 ~0 ~87 end_stone 0  
fill ~80 ~0 ~88 ~100 ~0 ~88 end_stone 0  
fill ~80 ~0 ~89 ~100 ~0 ~89 end_stone 0  
fill ~80 ~0 ~90 ~100 ~0 ~90 end_stone 0  
fill ~80 ~0 ~91 ~100 ~0 ~91 end_stone 0  
fill ~81 ~0 ~79 ~97 ~0 ~79 end_stone 0  
fill ~81 ~0 ~80 ~98 ~0 ~80 end_stone 0  
fill ~81 ~0 ~81 ~98 ~0 ~81 end_stone 0  
fill ~86 ~0 ~65 ~90 ~0 ~65 end_stone 0  
fill ~86 ~0 ~107 ~87 ~0 ~107 end_stone 0  
fill ~1 ~1 ~90 ~7 ~1 ~90 end_stone 0  
fill ~1 ~1 ~91 ~7 ~1 ~91 end_stone 0  
fill ~1 ~1 ~92 ~7 ~1 ~92 end_stone 0  
fill ~2 ~1 ~11 ~19 ~1 ~11 end_stone 0  
fill ~2 ~1 ~12 ~7 ~1 ~12 end_stone 0  
fill ~2 ~1 ~13 ~7 ~1 ~13 end_stone 0  
fill ~2 ~1 ~14 ~7 ~1 ~14 end_stone 0  
fill ~2 ~1 ~15 ~8 ~1 ~15 end_stone 0  
fill ~2 ~1 ~16 ~8 ~1 ~16 end_stone 0  
fill ~2 ~1 ~17 ~8 ~1 ~17 end_stone 0  
fill ~2 ~1 ~30 ~7 ~1 ~30 end_stone 0  
fill ~2 ~1 ~31 ~7 ~1 ~31 end_stone 0  
fill ~2 ~1 ~32 ~7 ~1 ~32 end_stone 0  
fill ~2 ~1 ~33 ~7 ~1 ~33 end_stone 0  
fill ~2 ~1 ~34 ~6 ~1 ~34 end_stone 0  
fill ~2 ~1 ~35 ~6 ~1 ~35 end_stone 0  
fill ~2 ~1 ~36 ~6 ~1 ~36 end_stone 0  
fill ~2 ~1 ~37 ~6 ~1 ~37 end_stone 0  
fill ~2 ~1 ~38 ~6 ~1 ~38 end_stone 0  
fill ~2 ~1 ~39 ~6 ~1 ~39 end_stone 0  
fill ~2 ~1 ~40 ~6 ~1 ~40 end_stone 0  
fill ~2 ~1 ~41 ~6 ~1 ~41 end_stone 0  
fill ~2 ~1 ~42 ~6 ~1 ~42 end_stone 0  
fill ~2 ~1 ~43 ~6 ~1 ~43 end_stone 0  
fill ~2 ~1 ~44 ~6 ~1 ~44 end_stone 0  
fill ~2 ~1 ~45 ~6 ~1 ~45 end_stone 0  
fill ~2 ~1 ~46 ~7 ~1 ~46 end_stone 0  
fill ~2 ~1 ~47 ~7 ~1 ~47 end_stone 0  
fill ~2 ~1 ~48 ~7 ~1 ~48 end_stone 0  
fill ~2 ~1 ~49 ~7 ~1 ~49 end_stone 0  
fill ~2 ~1 ~50 ~7 ~1 ~50 end_stone 0  
fill ~2 ~1 ~51 ~7 ~1 ~51 end_stone 0  
fill ~2 ~1 ~89 ~7 ~1 ~89 end_stone 0  
fill ~2 ~1 ~93 ~6 ~1 ~93 end_stone 0  
fill ~2 ~1 ~94 ~6 ~1 ~94 end_stone 0  
fill ~2 ~1 ~95 ~9 ~1 ~95 end_stone 0  
fill ~2 ~1 ~96 ~10 ~1 ~96 end_stone 0  
fill ~3 ~1 ~18 ~7 ~1 ~18 end_stone 0  
fill ~3 ~1 ~21 ~5 ~1 ~21 end_stone 0  
fill ~3 ~1 ~22 ~7 ~1 ~22 end_stone 0  
fill ~3 ~1 ~23 ~7 ~1 ~23 end_stone 0  
fill ~3 ~1 ~24 ~7 ~1 ~24 end_stone 0  
fill ~3 ~1 ~25 ~7 ~1 ~25 end_stone 0  
fill ~3 ~1 ~26 ~7 ~1 ~26 end_stone 0  
fill ~3 ~1 ~27 ~7 ~1 ~27 end_stone 0  
fill ~3 ~1 ~28 ~7 ~1 ~28 end_stone 0  
fill ~3 ~1 ~29 ~7 ~1 ~29 end_stone 0  
fill ~3 ~1 ~52 ~7 ~1 ~52 end_stone 0  
fill ~3 ~1 ~53 ~7 ~1 ~53 end_stone 0  
fill ~3 ~1 ~54 ~7 ~1 ~54 end_stone 0  
fill ~3 ~1 ~55 ~7 ~1 ~55 end_stone 0  
fill ~3 ~1 ~56 ~7 ~1 ~56 end_stone 0  
fill ~3 ~1 ~57 ~7 ~1 ~57 end_stone 0  
fill ~3 ~1 ~58 ~7 ~1 ~58 end_stone 0  
fill ~3 ~1 ~59 ~7 ~1 ~59 end_stone 0  
fill ~3 ~1 ~60 ~7 ~1 ~60 end_stone 0  
fill ~3 ~1 ~61 ~7 ~1 ~61 end_stone 0  
fill ~3 ~1 ~62 ~7 ~1 ~62 end_stone 0  
fill ~3 ~1 ~63 ~7 ~1 ~63 end_stone 0  
fill ~3 ~1 ~64 ~7 ~1 ~64 end_stone 0  
fill ~3 ~1 ~65 ~7 ~1 ~65 end_stone 0  
fill ~3 ~1 ~66 ~7 ~1 ~66 end_stone 0  
fill ~3 ~1 ~67 ~7 ~1 ~67 end_stone 0  
fill ~3 ~1 ~68 ~7 ~1 ~68 end_stone 0  
fill ~3 ~1 ~69 ~7 ~1 ~69 end_stone 0  
fill ~3 ~1 ~70 ~7 ~1 ~70 end_stone 0  
fill ~3 ~1 ~71 ~7 ~1 ~71 end_stone 0  
fill ~3 ~1 ~72 ~7 ~1 ~72 end_stone 0  
fill ~3 ~1 ~73 ~7 ~1 ~73 end_stone 0  
fill ~3 ~1 ~74 ~7 ~1 ~74 end_stone 0  
fill ~3 ~1 ~75 ~7 ~1 ~75 end_stone 0  
fill ~3 ~1 ~76 ~7 ~1 ~76 end_stone 0  
fill ~3 ~1 ~77 ~7 ~1 ~77 end_stone 0  
fill ~3 ~1 ~78 ~7 ~1 ~78 end_stone 0  
fill ~3 ~1 ~79 ~7 ~1 ~79 end_stone 0  
fill ~3 ~1 ~80 ~7 ~1 ~80 end_stone 0  
fill ~3 ~1 ~81 ~7 ~1 ~81 end_stone 0  
fill ~3 ~1 ~82 ~7 ~1 ~82 end_stone 0  
fill ~3 ~1 ~83 ~7 ~1 ~83 end_stone 0  
fill ~3 ~1 ~84 ~7 ~1 ~84 end_stone 0  
fill ~3 ~1 ~85 ~7 ~1 ~85 end_stone 0  
fill ~3 ~1 ~86 ~7 ~1 ~86 end_stone 0  
fill ~3 ~1 ~87 ~7 ~1 ~87 end_stone 0  
fill ~3 ~1 ~88 ~7 ~1 ~88 end_stone 0  
fill ~3 ~1 ~97 ~11 ~1 ~97 end_stone 0  
fill ~3 ~1 ~98 ~11 ~1 ~98 end_stone 0  
fill ~3 ~1 ~99 ~10 ~1 ~99 end_stone 0  
fill ~4 ~1 ~9 ~23 ~1 ~9 end_stone 0  
fill ~4 ~1 ~10 ~23 ~1 ~10 end_stone 0  
fill ~4 ~1 ~100 ~9 ~1 ~100 end_stone 0  
fill ~4 ~1 ~101 ~9 ~1 ~101 end_stone 0  
fill ~4 ~1 ~102 ~9 ~1 ~102 end_stone 0  
fill ~5 ~1 ~3 ~28 ~1 ~3 end_stone 0  
fill ~5 ~1 ~4 ~28 ~1 ~4 end_stone 0  
fill ~5 ~1 ~5 ~28 ~1 ~5 end_stone 0  
fill ~5 ~1 ~6 ~23 ~1 ~6 end_stone 0  
fill ~5 ~1 ~7 ~23 ~1 ~7 end_stone 0  
fill ~5 ~1 ~8 ~23 ~1 ~8 end_stone 0  
fill ~5 ~1 ~103 ~26 ~1 ~103 end_stone 0  
fill ~5 ~1 ~104 ~46 ~1 ~104 end_stone 0  
fill ~5 ~1 ~105 ~46 ~1 ~105 end_stone 0  
fill ~5 ~1 ~106 ~46 ~1 ~106 end_stone 0  
fill ~5 ~1 ~107 ~35 ~1 ~107 end_stone 0  
fill ~9 ~1 ~48 ~10 ~1 ~48 obsidian 0  
fill ~9 ~1 ~62 ~10 ~1 ~62 obsidian 0 
setblock ~10 ~1 ~49 glowstone 0 
setblock ~10 ~1 ~61 glowstone 0  
fill ~11 ~1 ~49 ~11 ~1 ~50 obsidian 0  
fill ~11 ~1 ~60 ~11 ~1 ~61 obsidian 0  
fill ~12 ~1 ~27 ~12 ~41 ~27 bedrock 0  
fill ~12 ~1 ~83 ~12 ~41 ~83 bedrock 0  
fill ~13 ~1 ~26 ~16 ~1 ~26 stonebrick 0  
fill ~13 ~1 ~84 ~16 ~1 ~84 stonebrick 0  
fill ~15 ~1 ~12 ~19 ~1 ~12 end_stone 0  
fill ~15 ~1 ~13 ~19 ~1 ~13 end_stone 0 
setblock ~15 ~1 ~32 obsidian 0  
fill ~15 ~1 ~72 ~15 ~3 ~72 obsidian 0  
fill ~16 ~1 ~27 ~16 ~20 ~27 bedrock 0  
fill ~16 ~1 ~28 ~16 ~20 ~28 stonebrick 0  
fill ~16 ~1 ~29 ~16 ~20 ~29 stonebrick 0  
fill ~16 ~1 ~30 ~16 ~20 ~30 stonebrick 0  
fill ~16 ~1 ~31 ~16 ~20 ~31 stonebrick 0  
fill ~16 ~1 ~32 ~16 ~20 ~32 stonebrick 0  
fill ~16 ~1 ~33 ~16 ~10 ~33 stonebrick 0  
fill ~16 ~1 ~34 ~16 ~10 ~34 stonebrick 0  
fill ~16 ~1 ~35 ~16 ~3 ~35 nether_brick_fence 0  
fill ~16 ~1 ~36 ~16 ~1 ~37 nether_brick_fence 0  
fill ~16 ~1 ~38 ~16 ~15 ~38 stonebrick 0  
fill ~16 ~1 ~39 ~16 ~15 ~39 stonebrick 0  
fill ~16 ~1 ~40 ~17 ~1 ~40 stonebrick 0  
fill ~16 ~1 ~41 ~16 ~10 ~41 stonebrick 0  
fill ~16 ~1 ~45 ~16 ~7 ~45 stonebrick 0  
fill ~16 ~1 ~46 ~16 ~6 ~46 stonebrick 0  
fill ~16 ~1 ~64 ~16 ~6 ~64 stonebrick 0  
fill ~16 ~1 ~65 ~16 ~7 ~65 stonebrick 0  
fill ~16 ~1 ~69 ~16 ~10 ~69 stonebrick 0  
fill ~16 ~1 ~70 ~17 ~1 ~70 stonebrick 0  
fill ~16 ~1 ~71 ~16 ~15 ~71 stonebrick 0  
fill ~16 ~1 ~72 ~16 ~15 ~72 stonebrick 0  
fill ~16 ~1 ~73 ~16 ~3 ~73 nether_brick_fence 0  
fill ~16 ~1 ~74 ~16 ~1 ~75 nether_brick_fence 0  
fill ~16 ~1 ~76 ~16 ~10 ~76 stonebrick 0  
fill ~16 ~1 ~77 ~16 ~10 ~77 stonebrick 0  
fill ~16 ~1 ~78 ~16 ~20 ~78 stonebrick 0  
fill ~16 ~1 ~79 ~16 ~20 ~79 stonebrick 0  
fill ~16 ~1 ~80 ~16 ~20 ~80 stonebrick 0  
fill ~16 ~1 ~81 ~16 ~20 ~81 stonebrick 0  
fill ~16 ~1 ~82 ~16 ~20 ~82 stonebrick 0  
fill ~16 ~1 ~83 ~16 ~20 ~83 bedrock 0  
fill ~17 ~1 ~2 ~24 ~1 ~2 end_stone 0  
fill ~17 ~1 ~42 ~17 ~5 ~42 nether_brick_fence 0  
fill ~17 ~1 ~43 ~17 ~2 ~43 nether_brick_fence 0  
fill ~17 ~1 ~44 ~17 ~5 ~44 nether_brick_fence 0  
fill ~17 ~1 ~45 ~17 ~5 ~45 end_stone 0  
fill ~17 ~1 ~47 ~17 ~3 ~47 end_stone 0  
fill ~17 ~1 ~63 ~17 ~3 ~63 end_stone 0  
fill ~17 ~1 ~66 ~17 ~5 ~66 nether_brick_fence 0  
fill ~17 ~1 ~67 ~17 ~2 ~67 nether_brick_fence 0  
fill ~17 ~1 ~68 ~17 ~5 ~68 nether_brick_fence 0  
fill ~17 ~1 ~69 ~17 ~5 ~69 end_stone 0  
fill ~18 ~1 ~1 ~20 ~1 ~1 end_stone 0  
fill ~18 ~1 ~22 ~18 ~52 ~22 end_stone 0  
fill ~18 ~1 ~41 ~18 ~10 ~41 stonebrick 0  
fill ~18 ~1 ~45 ~18 ~7 ~45 stonebrick 0  
fill ~18 ~1 ~46 ~18 ~6 ~46 stonebrick 0  
fill ~18 ~1 ~64 ~18 ~6 ~64 stonebrick 0  
fill ~18 ~1 ~65 ~18 ~7 ~65 stonebrick 0  
fill ~18 ~1 ~69 ~18 ~10 ~69 stonebrick 0  
fill ~18 ~1 ~87 ~18 ~40 ~87 stonebrick 0  
fill ~18 ~1 ~88 ~18 ~40 ~88 end_stone 0  
fill ~19 ~1 ~20 ~19 ~40 ~20 stonebrick 0  
fill ~19 ~1 ~21 ~19 ~52 ~21 obsidian 0  
fill ~19 ~1 ~22 ~19 ~53 ~22 bedrock 0  
fill ~19 ~1 ~23 ~19 ~53 ~23 bedrock 0  
fill ~19 ~1 ~87 ~20 ~1 ~87 bedrock 0  
fill ~19 ~1 ~88 ~19 ~40 ~88 stonebrick 0  
fill ~19 ~1 ~89 ~19 ~40 ~89 stonebrick 0  
fill ~19 ~1 ~90 ~19 ~40 ~90 stonebrick 0  
fill ~20 ~1 ~22 ~20 ~52 ~22 end_stone 0  
fill ~20 ~1 ~23 ~21 ~1 ~23 stonebrick 0  
fill ~20 ~1 ~88 ~20 ~40 ~88 end_stone 0  
fill ~21 ~1 ~87 ~21 ~29 ~87 stonebrick 0  
fill ~27 ~1 ~23 ~28 ~1 ~23 stonebrick 0  
fill ~27 ~1 ~87 ~28 ~1 ~87 stonebrick 0  
fill ~28 ~1 ~17 ~30 ~1 ~17 bedrock 0  
fill ~28 ~1 ~18 ~30 ~1 ~18 bedrock 0  
fill ~28 ~1 ~20 ~30 ~1 ~20 bedrock 0  
fill ~28 ~1 ~21 ~28 ~7 ~21 bedrock 0  
fill ~28 ~1 ~22 ~28 ~52 ~22 end_stone 0  
fill ~28 ~1 ~88 ~28 ~52 ~88 end_stone 0  
fill ~28 ~1 ~89 ~28 ~7 ~89 bedrock 0  
fill ~28 ~1 ~90 ~28 ~2 ~90 bedrock 0  
fill ~28 ~1 ~92 ~30 ~1 ~92 bedrock 0  
fill ~28 ~1 ~93 ~28 ~1 ~92 bedrock 0  
fill ~28 ~1 ~108 ~34 ~1 ~108 end_stone 0 
setblock ~29 ~1 ~13 torch 5 
setblock ~29 ~1 ~16 bedrock 0  
fill ~29 ~1 ~19 ~29 ~7 ~19 bedrock 0  
fill ~29 ~1 ~21 ~29 ~52 ~21 obsidian 0  
fill ~29 ~1 ~22 ~29 ~53 ~22 bedrock 0  
fill ~29 ~1 ~23 ~29 ~53 ~23 bedrock 0  
fill ~29 ~1 ~87 ~29 ~53 ~87 bedrock 0  
fill ~29 ~1 ~88 ~29 ~53 ~88 bedrock 0  
fill ~29 ~1 ~89 ~29 ~52 ~89 obsidian 0  
fill ~29 ~1 ~91 ~29 ~7 ~91 bedrock 0 
setblock ~29 ~1 ~94 bedrock 0 
setblock ~29 ~1 ~97 torch 5  
fill ~29 ~1 ~109 ~31 ~1 ~109 end_stone 0  
fill ~30 ~1 ~5 ~50 ~1 ~5 end_stone 0  
fill ~30 ~1 ~6 ~82 ~1 ~6 end_stone 0  
fill ~30 ~1 ~7 ~82 ~1 ~7 end_stone 0  
fill ~30 ~1 ~8 ~82 ~1 ~8 end_stone 0  
fill ~30 ~1 ~9 ~58 ~1 ~9 end_stone 0  
fill ~30 ~1 ~21 ~30 ~7 ~21 bedrock 0  
fill ~30 ~1 ~22 ~30 ~52 ~22 end_stone 0  
fill ~30 ~1 ~23 ~31 ~1 ~23 stonebrick 0  
fill ~30 ~1 ~87 ~31 ~1 ~87 stonebrick 0  
fill ~30 ~1 ~88 ~30 ~52 ~88 end_stone 0  
fill ~30 ~1 ~89 ~30 ~7 ~89 bedrock 0  
fill ~30 ~1 ~90 ~30 ~2 ~90 bedrock 0 
setblock ~30 ~1 ~93 bedrock 0  
fill ~30 ~1 ~103 ~35 ~1 ~103 end_stone 0  
fill ~31 ~1 ~4 ~49 ~1 ~4 end_stone 0  
fill ~35 ~1 ~10 ~57 ~1 ~10 end_stone 0  
fill ~35 ~1 ~11 ~39 ~1 ~11 end_stone 0  
fill ~37 ~1 ~23 ~38 ~1 ~23 stonebrick 0  
fill ~37 ~1 ~87 ~38 ~1 ~87 stonebrick 0  
fill ~37 ~1 ~107 ~46 ~1 ~107 end_stone 0  
fill ~38 ~1 ~17 ~40 ~1 ~17 bedrock 0  
fill ~38 ~1 ~18 ~40 ~1 ~18 bedrock 0  
fill ~38 ~1 ~20 ~40 ~1 ~20 bedrock 0  
fill ~38 ~1 ~21 ~38 ~7 ~21 bedrock 0  
fill ~38 ~1 ~22 ~38 ~52 ~22 end_stone 0  
fill ~38 ~1 ~88 ~38 ~52 ~88 end_stone 0  
fill ~38 ~1 ~89 ~38 ~7 ~89 bedrock 0  
fill ~38 ~1 ~90 ~38 ~2 ~90 bedrock 0  
fill ~38 ~1 ~92 ~40 ~1 ~92 bedrock 0  
fill ~38 ~1 ~93 ~38 ~1 ~92 bedrock 0  
fill ~38 ~1 ~103 ~42 ~1 ~103 end_stone 0 
setblock ~39 ~1 ~13 torch 5 
setblock ~39 ~1 ~16 bedrock 0  
fill ~39 ~1 ~19 ~39 ~7 ~19 bedrock 0  
fill ~39 ~1 ~21 ~39 ~52 ~21 obsidian 0  
fill ~39 ~1 ~22 ~39 ~53 ~22 bedrock 0  
fill ~39 ~1 ~23 ~39 ~53 ~23 bedrock 0  
fill ~39 ~1 ~87 ~39 ~53 ~87 bedrock 0  
fill ~39 ~1 ~88 ~39 ~53 ~88 bedrock 0  
fill ~39 ~1 ~89 ~39 ~52 ~89 obsidian 0  
fill ~39 ~1 ~91 ~39 ~7 ~91 bedrock 0 
setblock ~39 ~1 ~94 bedrock 0 
setblock ~39 ~1 ~97 torch 5  
fill ~40 ~1 ~3 ~47 ~1 ~3 end_stone 0  
fill ~40 ~1 ~21 ~40 ~7 ~21 bedrock 0  
fill ~40 ~1 ~22 ~40 ~52 ~22 end_stone 0  
fill ~40 ~1 ~23 ~41 ~1 ~23 stonebrick 0  
fill ~40 ~1 ~87 ~41 ~1 ~87 stonebrick 0  
fill ~40 ~1 ~88 ~40 ~52 ~88 end_stone 0  
fill ~40 ~1 ~89 ~40 ~7 ~89 bedrock 0  
fill ~40 ~1 ~90 ~40 ~2 ~90 bedrock 0 
setblock ~40 ~1 ~93 bedrock 0  
fill ~41 ~1 ~2 ~43 ~1 ~2 end_stone 0  
fill ~41 ~1 ~108 ~46 ~1 ~108 end_stone 0  
fill ~42 ~1 ~11 ~45 ~1 ~11 end_stone 0  
fill ~47 ~1 ~23 ~48 ~1 ~23 stonebrick 0  
fill ~47 ~1 ~87 ~48 ~1 ~87 stonebrick 0  
fill ~48 ~1 ~17 ~50 ~1 ~17 bedrock 0  
fill ~48 ~1 ~18 ~50 ~1 ~18 bedrock 0  
fill ~48 ~1 ~20 ~50 ~1 ~20 bedrock 0  
fill ~48 ~1 ~21 ~48 ~7 ~21 bedrock 0  
fill ~48 ~1 ~22 ~48 ~52 ~22 end_stone 0  
fill ~48 ~1 ~88 ~48 ~52 ~88 end_stone 0  
fill ~48 ~1 ~89 ~48 ~7 ~89 bedrock 0  
fill ~48 ~1 ~90 ~48 ~2 ~90 bedrock 0  
fill ~48 ~1 ~92 ~50 ~1 ~92 bedrock 0  
fill ~48 ~1 ~93 ~48 ~1 ~92 bedrock 0 
setblock ~49 ~1 ~13 torch 5 
setblock ~49 ~1 ~16 bedrock 0  
fill ~49 ~1 ~19 ~49 ~7 ~19 bedrock 0  
fill ~49 ~1 ~21 ~49 ~52 ~21 obsidian 0  
fill ~49 ~1 ~22 ~49 ~53 ~22 bedrock 0  
fill ~49 ~1 ~23 ~49 ~53 ~23 bedrock 0  
fill ~49 ~1 ~87 ~49 ~53 ~87 bedrock 0  
fill ~49 ~1 ~88 ~49 ~53 ~88 bedrock 0  
fill ~49 ~1 ~89 ~49 ~52 ~89 obsidian 0  
fill ~49 ~1 ~91 ~49 ~7 ~91 bedrock 0 
setblock ~49 ~1 ~94 bedrock 0 
setblock ~49 ~1 ~97 torch 5  
fill ~50 ~1 ~21 ~50 ~7 ~21 bedrock 0  
fill ~50 ~1 ~22 ~50 ~52 ~22 end_stone 0  
fill ~50 ~1 ~23 ~51 ~1 ~23 stonebrick 0  
fill ~50 ~1 ~87 ~51 ~1 ~87 stonebrick 0  
fill ~50 ~1 ~88 ~50 ~52 ~88 end_stone 0  
fill ~50 ~1 ~89 ~50 ~7 ~89 bedrock 0  
fill ~50 ~1 ~90 ~50 ~2 ~90 bedrock 0 
setblock ~50 ~1 ~93 bedrock 0  
fill ~52 ~1 ~11 ~56 ~1 ~11 end_stone 0  
fill ~52 ~1 ~12 ~56 ~1 ~12 end_stone 0  
fill ~52 ~1 ~13 ~56 ~1 ~13 end_stone 0  
fill ~52 ~1 ~14 ~56 ~1 ~14 end_stone 0  
fill ~53 ~1 ~3 ~59 ~1 ~3 end_stone 0  
fill ~53 ~1 ~4 ~79 ~1 ~4 end_stone 0  
fill ~53 ~1 ~5 ~82 ~1 ~5 end_stone 0  
fill ~54 ~1 ~2 ~58 ~1 ~2 end_stone 0  
fill ~55 ~1 ~1 ~57 ~1 ~1 end_stone 0  
fill ~56 ~1 ~106 ~64 ~1 ~106 end_stone 0  
fill ~56 ~1 ~107 ~64 ~1 ~107 end_stone 0  
fill ~56 ~1 ~108 ~64 ~1 ~108 end_stone 0  
fill ~56 ~1 ~109 ~57 ~1 ~109 end_stone 0  
fill ~57 ~1 ~23 ~58 ~1 ~23 stonebrick 0  
fill ~57 ~1 ~87 ~58 ~1 ~87 stonebrick 0  
fill ~58 ~1 ~17 ~60 ~1 ~17 bedrock 0  
fill ~58 ~1 ~18 ~60 ~1 ~18 bedrock 0  
fill ~58 ~1 ~20 ~60 ~1 ~20 bedrock 0  
fill ~58 ~1 ~21 ~58 ~7 ~21 bedrock 0  
fill ~58 ~1 ~22 ~58 ~52 ~22 end_stone 0  
fill ~58 ~1 ~88 ~58 ~52 ~88 end_stone 0  
fill ~58 ~1 ~89 ~58 ~7 ~89 bedrock 0  
fill ~58 ~1 ~90 ~58 ~2 ~90 bedrock 0  
fill ~58 ~1 ~92 ~60 ~1 ~92 bedrock 0  
fill ~58 ~1 ~93 ~58 ~1 ~92 bedrock 0 
setblock ~59 ~1 ~14 torch 5 
setblock ~59 ~1 ~16 bedrock 0  
fill ~59 ~1 ~19 ~59 ~7 ~19 bedrock 0  
fill ~59 ~1 ~21 ~59 ~52 ~21 obsidian 0  
fill ~59 ~1 ~22 ~59 ~53 ~22 bedrock 0  
fill ~59 ~1 ~23 ~59 ~53 ~23 bedrock 0  
fill ~59 ~1 ~87 ~59 ~53 ~87 bedrock 0  
fill ~59 ~1 ~88 ~59 ~53 ~88 bedrock 0  
fill ~59 ~1 ~89 ~59 ~52 ~89 obsidian 0  
fill ~59 ~1 ~91 ~59 ~7 ~91 bedrock 0 
setblock ~59 ~1 ~94 bedrock 0 
setblock ~59 ~1 ~97 torch 5  
fill ~60 ~1 ~21 ~60 ~7 ~21 bedrock 0  
fill ~60 ~1 ~22 ~60 ~52 ~22 end_stone 0  
fill ~60 ~1 ~23 ~61 ~1 ~23 stonebrick 0  
fill ~60 ~1 ~87 ~61 ~1 ~87 stonebrick 0  
fill ~60 ~1 ~88 ~60 ~52 ~88 end_stone 0  
fill ~60 ~1 ~89 ~60 ~7 ~89 bedrock 0  
fill ~60 ~1 ~90 ~60 ~2 ~90 bedrock 0 
setblock ~60 ~1 ~93 bedrock 0  
fill ~60 ~1 ~104 ~64 ~1 ~104 end_stone 0  
fill ~60 ~1 ~105 ~64 ~1 ~105 end_stone 0  
fill ~62 ~1 ~3 ~75 ~1 ~3 end_stone 0  
fill ~62 ~1 ~9 ~72 ~1 ~9 end_stone 0  
fill ~62 ~1 ~103 ~64 ~1 ~103 end_stone 0  
fill ~63 ~1 ~10 ~69 ~1 ~10 end_stone 0  
fill ~64 ~1 ~11 ~65 ~1 ~11 end_stone 0  
fill ~67 ~1 ~23 ~67 ~29 ~23 stonebrick 0  
fill ~67 ~1 ~87 ~68 ~1 ~87 stonebrick 0  
fill ~68 ~1 ~22 ~68 ~40 ~22 end_stone 0  
fill ~68 ~1 ~23 ~68 ~52 ~23 bedrock 0  
fill ~68 ~1 ~88 ~68 ~52 ~88 end_stone 0  
fill ~68 ~1 ~103 ~74 ~1 ~103 end_stone 0  
fill ~68 ~1 ~104 ~73 ~1 ~104 end_stone 0  
fill ~68 ~1 ~105 ~73 ~1 ~105 end_stone 0  
fill ~69 ~1 ~20 ~69 ~40 ~20 stonebrick 0  
fill ~69 ~1 ~21 ~69 ~40 ~21 stonebrick 0  
fill ~69 ~1 ~22 ~69 ~40 ~22 stonebrick 0  
fill ~69 ~1 ~87 ~69 ~53 ~87 bedrock 0  
fill ~69 ~1 ~88 ~69 ~53 ~88 bedrock 0  
fill ~69 ~1 ~89 ~69 ~52 ~89 obsidian 0  
fill ~69 ~1 ~90 ~69 ~40 ~90 stonebrick 0  
fill ~69 ~1 ~102 ~85 ~1 ~102 end_stone 0  
fill ~69 ~1 ~106 ~73 ~1 ~106 end_stone 0  
fill ~70 ~1 ~41 ~70 ~10 ~41 stonebrick 0  
fill ~70 ~1 ~45 ~70 ~7 ~45 stonebrick 0  
fill ~70 ~1 ~46 ~70 ~6 ~46 stonebrick 0  
fill ~70 ~1 ~64 ~70 ~6 ~64 stonebrick 0  
fill ~70 ~1 ~65 ~70 ~7 ~65 stonebrick 0  
fill ~70 ~1 ~69 ~70 ~10 ~69 stonebrick 0  
fill ~70 ~1 ~88 ~70 ~52 ~88 end_stone 0  
fill ~71 ~1 ~40 ~72 ~1 ~40 stonebrick 0  
fill ~71 ~1 ~42 ~71 ~5 ~42 nether_brick_fence 0  
fill ~71 ~1 ~43 ~71 ~2 ~43 nether_brick_fence 0  
fill ~71 ~1 ~44 ~71 ~5 ~44 nether_brick_fence 0  
fill ~71 ~1 ~45 ~71 ~5 ~45 end_stone 0  
fill ~71 ~1 ~47 ~71 ~3 ~47 end_stone 0  
fill ~71 ~1 ~63 ~71 ~3 ~63 end_stone 0  
fill ~71 ~1 ~66 ~71 ~5 ~66 nether_brick_fence 0  
fill ~71 ~1 ~67 ~71 ~2 ~67 nether_brick_fence 0  
fill ~71 ~1 ~68 ~71 ~5 ~68 nether_brick_fence 0  
fill ~71 ~1 ~69 ~71 ~5 ~69 end_stone 0  
fill ~71 ~1 ~70 ~72 ~1 ~70 stonebrick 0  
fill ~72 ~1 ~26 ~75 ~1 ~26 stonebrick 0  
fill ~72 ~1 ~27 ~72 ~20 ~27 bedrock 0  
fill ~72 ~1 ~28 ~72 ~20 ~28 stonebrick 0  
fill ~72 ~1 ~29 ~72 ~20 ~29 stonebrick 0  
fill ~72 ~1 ~30 ~72 ~20 ~30 stonebrick 0  
fill ~72 ~1 ~31 ~72 ~20 ~31 stonebrick 0  
fill ~72 ~1 ~32 ~72 ~20 ~32 stonebrick 0  
fill ~72 ~1 ~33 ~72 ~10 ~33 stonebrick 0  
fill ~72 ~1 ~34 ~72 ~10 ~34 stonebrick 0  
fill ~72 ~1 ~35 ~72 ~3 ~35 nether_brick_fence 0  
fill ~72 ~1 ~36 ~72 ~1 ~37 nether_brick_fence 0  
fill ~72 ~1 ~38 ~72 ~15 ~38 stonebrick 0  
fill ~72 ~1 ~39 ~72 ~15 ~39 stonebrick 0  
fill ~72 ~1 ~41 ~72 ~10 ~41 stonebrick 0  
fill ~72 ~1 ~45 ~72 ~7 ~45 stonebrick 0  
fill ~72 ~1 ~46 ~72 ~6 ~46 stonebrick 0  
fill ~72 ~1 ~64 ~72 ~6 ~64 stonebrick 0  
fill ~72 ~1 ~65 ~72 ~7 ~65 stonebrick 0  
fill ~72 ~1 ~69 ~72 ~10 ~69 stonebrick 0  
fill ~72 ~1 ~71 ~72 ~15 ~71 stonebrick 0  
fill ~72 ~1 ~72 ~72 ~15 ~72 stonebrick 0  
fill ~72 ~1 ~73 ~72 ~3 ~73 nether_brick_fence 0  
fill ~72 ~1 ~74 ~72 ~1 ~75 nether_brick_fence 0  
fill ~72 ~1 ~76 ~72 ~10 ~76 stonebrick 0  
fill ~72 ~1 ~77 ~72 ~10 ~77 stonebrick 0  
fill ~72 ~1 ~78 ~72 ~20 ~78 stonebrick 0  
fill ~72 ~1 ~79 ~72 ~20 ~79 stonebrick 0  
fill ~72 ~1 ~80 ~72 ~20 ~80 stonebrick 0  
fill ~72 ~1 ~81 ~72 ~20 ~81 stonebrick 0  
fill ~72 ~1 ~82 ~72 ~20 ~82 stonebrick 0  
fill ~72 ~1 ~83 ~72 ~20 ~83 bedrock 0  
fill ~72 ~1 ~84 ~75 ~1 ~84 stonebrick 0  
fill ~72 ~1 ~101 ~77 ~1 ~101 end_stone 0  
fill ~73 ~1 ~38 ~73 ~3 ~38 obsidian 0 
setblock ~73 ~1 ~78 obsidian 0  
fill ~73 ~1 ~98 ~77 ~1 ~98 end_stone 0  
fill ~73 ~1 ~99 ~77 ~1 ~99 end_stone 0  
fill ~73 ~1 ~100 ~77 ~1 ~100 end_stone 0  
fill ~75 ~1 ~9 ~83 ~1 ~9 end_stone 0  
fill ~76 ~1 ~10 ~83 ~1 ~10 end_stone 0  
fill ~76 ~1 ~27 ~76 ~41 ~27 bedrock 0  
fill ~76 ~1 ~83 ~76 ~41 ~83 bedrock 0  
fill ~76 ~1 ~105 ~85 ~1 ~105 end_stone 0  
fill ~76 ~1 ~106 ~85 ~1 ~106 end_stone 0  
fill ~76 ~1 ~107 ~79 ~1 ~107 end_stone 0  
fill ~77 ~1 ~49 ~77 ~1 ~50 obsidian 0  
fill ~77 ~1 ~60 ~77 ~1 ~61 obsidian 0  
fill ~77 ~1 ~103 ~85 ~1 ~103 end_stone 0  
fill ~77 ~1 ~104 ~85 ~1 ~104 end_stone 0  
fill ~78 ~1 ~11 ~83 ~1 ~11 end_stone 0  
fill ~78 ~1 ~12 ~84 ~1 ~12 end_stone 0  
fill ~78 ~1 ~13 ~84 ~1 ~13 end_stone 0  
fill ~78 ~1 ~14 ~84 ~1 ~14 end_stone 0  
fill ~78 ~1 ~30 ~83 ~1 ~30 end_stone 0  
fill ~78 ~1 ~31 ~82 ~1 ~31 end_stone 0  
fill ~78 ~1 ~32 ~82 ~1 ~32 end_stone 0  
fill ~78 ~1 ~33 ~82 ~1 ~33 end_stone 0  
fill ~78 ~1 ~34 ~82 ~1 ~34 end_stone 0  
fill ~78 ~1 ~35 ~82 ~1 ~35 end_stone 0  
fill ~78 ~1 ~48 ~79 ~1 ~48 obsidian 0 
setblock ~78 ~1 ~49 glowstone 0 
setblock ~78 ~1 ~61 glowstone 0  
fill ~78 ~1 ~62 ~79 ~1 ~62 obsidian 0  
fill ~79 ~1 ~15 ~84 ~1 ~15 end_stone 0  
fill ~79 ~1 ~101 ~83 ~1 ~101 end_stone 0  
fill ~80 ~1 ~16 ~84 ~1 ~16 end_stone 0  
fill ~80 ~1 ~17 ~84 ~1 ~17 end_stone 0  
fill ~80 ~1 ~18 ~84 ~1 ~18 end_stone 0  
fill ~80 ~1 ~19 ~84 ~1 ~19 end_stone 0  
fill ~80 ~1 ~20 ~84 ~1 ~20 end_stone 0  
fill ~80 ~1 ~21 ~82 ~1 ~21 end_stone 0  
fill ~80 ~1 ~22 ~82 ~1 ~22 end_stone 0  
fill ~80 ~1 ~23 ~82 ~1 ~23 end_stone 0  
fill ~80 ~1 ~24 ~82 ~1 ~24 end_stone 0  
fill ~81 ~1 ~25 ~82 ~1 ~25 end_stone 0  
fill ~81 ~1 ~26 ~83 ~1 ~26 end_stone 0  
fill ~81 ~1 ~27 ~83 ~1 ~27 end_stone 0  
fill ~81 ~1 ~28 ~83 ~1 ~28 end_stone 0  
fill ~81 ~1 ~29 ~83 ~1 ~29 end_stone 0  
fill ~81 ~1 ~107 ~83 ~1 ~107 end_stone 0  
fill ~84 ~1 ~67 ~89 ~1 ~67 end_stone 0  
fill ~84 ~1 ~68 ~88 ~1 ~68 end_stone 0  
fill ~84 ~1 ~69 ~86 ~1 ~69 end_stone 0  
fill ~84 ~1 ~82 ~99 ~1 ~82 end_stone 0  
fill ~84 ~1 ~83 ~99 ~1 ~83 end_stone 0  
fill ~84 ~1 ~84 ~98 ~1 ~84 end_stone 0  
fill ~84 ~1 ~85 ~98 ~1 ~85 end_stone 0  
fill ~84 ~1 ~95 ~99 ~1 ~95 end_stone 0  
fill ~84 ~1 ~96 ~98 ~1 ~96 end_stone 0  
fill ~84 ~1 ~97 ~97 ~1 ~97 end_stone 0  
fill ~85 ~1 ~66 ~89 ~1 ~66 end_stone 0  
fill ~85 ~1 ~81 ~99 ~1 ~81 end_stone 0  
fill ~85 ~1 ~86 ~99 ~1 ~86 end_stone 0  
fill ~85 ~1 ~87 ~100 ~1 ~87 end_stone 0  
fill ~85 ~1 ~93 ~100 ~1 ~93 end_stone 0  
fill ~85 ~1 ~94 ~100 ~1 ~94 end_stone 0  
fill ~85 ~1 ~98 ~97 ~1 ~98 end_stone 0  
fill ~85 ~1 ~99 ~96 ~1 ~99 end_stone 0  
fill ~85 ~1 ~100 ~95 ~1 ~100 end_stone 0  
fill ~86 ~1 ~80 ~98 ~1 ~80 end_stone 0  
fill ~86 ~1 ~90 ~100 ~1 ~90 end_stone 0  
fill ~86 ~1 ~91 ~100 ~1 ~91 end_stone 0  
fill ~86 ~1 ~92 ~100 ~1 ~92 end_stone 0  
fill ~87 ~1 ~73 ~91 ~1 ~73 end_stone 0  
fill ~87 ~1 ~74 ~91 ~1 ~74 end_stone 0  
fill ~87 ~1 ~75 ~93 ~1 ~75 end_stone 0  
fill ~87 ~1 ~76 ~94 ~1 ~76 end_stone 0  
fill ~87 ~1 ~77 ~95 ~1 ~77 end_stone 0  
fill ~87 ~1 ~101 ~94 ~1 ~101 end_stone 0  
fill ~87 ~1 ~102 ~92 ~1 ~102 end_stone 0  
fill ~87 ~1 ~103 ~92 ~1 ~103 end_stone 0  
fill ~88 ~1 ~72 ~89 ~1 ~72 end_stone 0  
fill ~88 ~1 ~78 ~96 ~1 ~78 end_stone 0  
fill ~89 ~1 ~79 ~97 ~1 ~79 end_stone 0  
fill ~89 ~1 ~88 ~100 ~1 ~88 end_stone 0  
fill ~89 ~1 ~89 ~100 ~1 ~89 end_stone 0  
fill ~2 ~2 ~89 ~5 ~2 ~89 end_stone 0  
fill ~2 ~2 ~90 ~6 ~2 ~90 end_stone 0  
fill ~2 ~2 ~91 ~6 ~2 ~91 end_stone 0  
fill ~2 ~2 ~92 ~6 ~2 ~92 end_stone 0  
fill ~2 ~2 ~93 ~6 ~2 ~93 end_stone 0  
fill ~3 ~2 ~13 ~5 ~2 ~13 end_stone 0  
fill ~3 ~2 ~14 ~6 ~2 ~14 end_stone 0  
fill ~3 ~2 ~15 ~7 ~2 ~15 end_stone 0  
fill ~3 ~2 ~16 ~7 ~2 ~16 end_stone 0  
fill ~3 ~2 ~17 ~7 ~2 ~17 end_stone 0  
fill ~3 ~2 ~18 ~7 ~2 ~18 end_stone 0  
fill ~3 ~2 ~29 ~6 ~2 ~29 end_stone 0  
fill ~3 ~2 ~30 ~6 ~2 ~30 end_stone 0  
fill ~3 ~2 ~31 ~5 ~2 ~31 end_stone 0  
fill ~3 ~2 ~32 ~5 ~2 ~32 end_stone 0  
fill ~3 ~2 ~33 ~5 ~2 ~33 end_stone 0  
fill ~3 ~2 ~34 ~5 ~2 ~34 end_stone 0  
fill ~3 ~2 ~35 ~5 ~2 ~35 end_stone 0  
fill ~3 ~2 ~36 ~5 ~2 ~36 end_stone 0  
fill ~3 ~2 ~37 ~5 ~2 ~37 end_stone 0  
fill ~3 ~2 ~38 ~5 ~2 ~38 end_stone 0  
fill ~3 ~2 ~39 ~5 ~2 ~39 end_stone 0  
fill ~3 ~2 ~40 ~5 ~2 ~40 end_stone 0  
fill ~3 ~2 ~41 ~5 ~2 ~41 end_stone 0  
fill ~3 ~2 ~42 ~5 ~2 ~42 end_stone 0  
fill ~3 ~2 ~43 ~5 ~2 ~43 end_stone 0  
fill ~3 ~2 ~44 ~6 ~2 ~44 end_stone 0  
fill ~3 ~2 ~45 ~6 ~2 ~45 end_stone 0  
fill ~3 ~2 ~46 ~6 ~2 ~46 end_stone 0  
fill ~3 ~2 ~94 ~5 ~2 ~94 end_stone 0  
fill ~3 ~2 ~95 ~5 ~2 ~95 end_stone 0  
fill ~4 ~2 ~24 ~6 ~2 ~24 end_stone 0  
fill ~4 ~2 ~25 ~6 ~2 ~25 end_stone 0   
fill ~4 ~2 ~26 ~6 ~2 ~26 end_stone 0  
fill ~4 ~2 ~27 ~6 ~2 ~27 end_stone 0  
fill ~4 ~2 ~28 ~6 ~2 ~28 end_stone 0  
fill ~4 ~2 ~47 ~6 ~2 ~47 end_stone 0  
fill ~4 ~2 ~48 ~6 ~2 ~48 end_stone 0  
fill ~4 ~2 ~49 ~6 ~2 ~49 end_stone 0  
fill ~4 ~2 ~50 ~6 ~2 ~50 end_stone 0  
fill ~4 ~2 ~51 ~6 ~2 ~51 end_stone 0  
fill ~4 ~2 ~52 ~6 ~2 ~52 end_stone 0  
fill ~4 ~2 ~53 ~6 ~2 ~53 end_stone 0  
fill ~4 ~2 ~54 ~6 ~2 ~54 end_stone 0  
fill ~4 ~2 ~55 ~6 ~2 ~55 end_stone 0  
fill ~4 ~2 ~56 ~6 ~2 ~56 end_stone 0  
fill ~4 ~2 ~57 ~6 ~2 ~57 end_stone 0  
fill ~4 ~2 ~58 ~6 ~2 ~58 end_stone 0  
fill ~4 ~2 ~59 ~6 ~2 ~59 end_stone 0  
fill ~4 ~2 ~60 ~6 ~2 ~60 end_stone 0  
fill ~4 ~2 ~61 ~6 ~2 ~61 end_stone 0  
fill ~4 ~2 ~62 ~6 ~2 ~62 end_stone 0  
fill ~4 ~2 ~63 ~6 ~2 ~63 end_stone 0  
fill ~4 ~2 ~64 ~6 ~2 ~64 end_stone 0  
fill ~4 ~2 ~65 ~6 ~2 ~65 end_stone 0  
fill ~4 ~2 ~66 ~6 ~2 ~66 end_stone 0  
fill ~4 ~2 ~67 ~6 ~2 ~67 end_stone 0  
fill ~4 ~2 ~68 ~6 ~2 ~68 end_stone 0  
fill ~4 ~2 ~69 ~6 ~2 ~69 end_stone 0  
fill ~4 ~2 ~70 ~6 ~2 ~70 end_stone 0  
fill ~4 ~2 ~71 ~6 ~2 ~71 end_stone 0  
fill ~4 ~2 ~72 ~6 ~2 ~72 end_stone 0  
fill ~4 ~2 ~73 ~6 ~2 ~73 end_stone 0  
fill ~4 ~2 ~74 ~6 ~2 ~74 end_stone 0  
fill ~4 ~2 ~75 ~6 ~2 ~75 end_stone 0  
fill ~4 ~2 ~76 ~6 ~2 ~76 end_stone 0  
fill ~4 ~2 ~77 ~6 ~2 ~77 end_stone 0  
fill ~4 ~2 ~78 ~6 ~2 ~78 end_stone 0  
fill ~4 ~2 ~79 ~6 ~2 ~79 end_stone 0  
fill ~4 ~2 ~80 ~6 ~2 ~80 end_stone 0  
fill ~4 ~2 ~81 ~6 ~2 ~81 end_stone 0  
fill ~4 ~2 ~82 ~6 ~2 ~82 end_stone 0  
fill ~4 ~2 ~83 ~6 ~2 ~83 end_stone 0  
fill ~4 ~2 ~84 ~6 ~2 ~84 end_stone 0  
fill ~4 ~2 ~85 ~6 ~2 ~85 end_stone 0  
fill ~6 ~2 ~4 ~8 ~2 ~4 end_stone 0  
fill ~6 ~2 ~5 ~8 ~2 ~5 end_stone 0  
fill ~6 ~2 ~6 ~8 ~2 ~6 end_stone 0  
fill ~6 ~2 ~7 ~8 ~2 ~7 end_stone 0  
fill ~6 ~2 ~8 ~8 ~2 ~8 end_stone 0  
fill ~6 ~2 ~96 ~10 ~2 ~96 end_stone 0  
fill ~6 ~2 ~97 ~10 ~2 ~97 end_stone 0  
fill ~6 ~2 ~98 ~10 ~2 ~98 end_stone 0  
fill ~6 ~2 ~99 ~10 ~2 ~99 end_stone 0  
fill ~7 ~2 ~9 ~8 ~2 ~9 end_stone 0  
fill ~7 ~2 ~10 ~8 ~2 ~10 end_stone 0  
fill ~7 ~2 ~100 ~9 ~2 ~100 end_stone 0 
setblock ~9 ~2 ~49 obsidian 0 
setblock ~9 ~2 ~61 obsidian 0 
setblock ~10 ~2 ~50 obsidian 0 
setblock ~10 ~2 ~60 obsidian 0  
fill ~11 ~2 ~4 ~13 ~2 ~4 end_stone 0  
fill ~11 ~2 ~5 ~23 ~2 ~5 end_stone 0  
fill ~11 ~2 ~6 ~21 ~2 ~6 end_stone 0  
fill ~11 ~2 ~7 ~22 ~2 ~7 end_stone 0  
fill ~11 ~2 ~8 ~22 ~2 ~8 end_stone 0  
fill ~11 ~2 ~9 ~18 ~2 ~9 end_stone 0  
fill ~11 ~2 ~10 ~13 ~2 ~10 end_stone 0  
fill ~13 ~2 ~26 ~16 ~2 ~26 stonebrick 0  
fill ~13 ~2 ~84 ~16 ~2 ~84 stonebrick 0  
fill ~15 ~2 ~4 ~23 ~2 ~4 end_stone 0  
fill ~15 ~2 ~10 ~18 ~2 ~10 end_stone 0  
fill ~15 ~2 ~33 ~15 ~4 ~33 obsidian 0  
fill ~16 ~2 ~3 ~23 ~2 ~3 end_stone 0  
fill ~16 ~2 ~11 ~18 ~2 ~11 end_stone 0  
fill ~16 ~2 ~12 ~18 ~2 ~12 end_stone 0 
setblock ~16 ~2 ~36 glowstone 0  
fill ~16 ~2 ~37 ~16 ~3 ~37 nether_brick_fence 0  
fill ~16 ~2 ~40 ~17 ~2 ~40 stonebrick 0  
fill ~16 ~2 ~70 ~17 ~2 ~70 stonebrick 0 
setblock ~16 ~2 ~74 glowstone 0  
fill ~16 ~2 ~75 ~16 ~3 ~75 nether_brick_fence 0  
fill ~17 ~2 ~2 ~23 ~2 ~2 end_stone 0  
fill ~18 ~2 ~1 ~20 ~2 ~1 end_stone 0  
fill ~18 ~2 ~89 ~18 ~3 ~89 nether_brick_fence 0  
fill ~19 ~2 ~87 ~20 ~2 ~87 bedrock 0  
fill ~20 ~2 ~9 ~22 ~2 ~9 end_stone 0  
fill ~20 ~2 ~21 ~20 ~3 ~21 nether_brick_fence 0  
fill ~20 ~2 ~23 ~21 ~2 ~23 stonebrick 0  
fill ~20 ~2 ~89 ~20 ~3 ~89 nether_brick_fence 0  
fill ~27 ~2 ~23 ~28 ~2 ~23 stonebrick 0  
fill ~27 ~2 ~87 ~28 ~2 ~87 stonebrick 0  
fill ~28 ~2 ~18 ~30 ~2 ~18 bedrock 0  
fill ~28 ~2 ~19 ~28 ~3 ~19 bedrock 0  
fill ~28 ~2 ~20 ~30 ~2 ~20 bedrock 0  
fill ~28 ~2 ~91 ~28 ~3 ~91 bedrock 0  
fill ~28 ~2 ~92 ~30 ~2 ~92 bedrock 0 
setblock ~29 ~2 ~17 bedrock 0  
fill ~29 ~2 ~44 ~29 ~7 ~44 end_stone 0  
fill ~29 ~2 ~66 ~29 ~7 ~66 end_stone 0  
fill ~30 ~2 ~19 ~30 ~3 ~19 bedrock 0  
fill ~30 ~2 ~23 ~31 ~2 ~23 stonebrick 0  
fill ~30 ~2 ~87 ~31 ~2 ~87 stonebrick 0  
fill ~30 ~2 ~91 ~30 ~3 ~91 bedrock 0  
fill ~30 ~2 ~105 ~32 ~2 ~105 end_stone 0  
fill ~30 ~2 ~106 ~32 ~2 ~106 end_stone 0  
fill ~30 ~2 ~107 ~32 ~2 ~107 end_stone 0  
fill ~36 ~2 ~9 ~50 ~2 ~9 end_stone 0  
fill ~36 ~2 ~10 ~38 ~2 ~10 end_stone 0  
fill ~37 ~2 ~8 ~50 ~2 ~8 end_stone 0  
fill ~37 ~2 ~23 ~38 ~2 ~23 stonebrick 0  
fill ~37 ~2 ~87 ~38 ~2 ~87 stonebrick 0  
fill ~38 ~2 ~5 ~50 ~2 ~5 end_stone 0  
fill ~38 ~2 ~6 ~50 ~2 ~6 end_stone 0  
fill ~38 ~2 ~7 ~50 ~2 ~7 end_stone 0  
fill ~38 ~2 ~18 ~40 ~2 ~18 bedrock 0  
fill ~38 ~2 ~19 ~38 ~3 ~19 bedrock 0  
fill ~38 ~2 ~20 ~40 ~2 ~20 bedrock 0  
fill ~38 ~2 ~91 ~38 ~3 ~91 bedrock 0  
fill ~38 ~2 ~92 ~40 ~2 ~92 bedrock 0  
fill ~39 ~2 ~4 ~48 ~2 ~4 end_stone 0 
setblock ~39 ~2 ~17 bedrock 0  
fill ~39 ~2 ~44 ~39 ~7 ~44 end_stone 0  
fill ~39 ~2 ~66 ~39 ~7 ~66 end_stone 0  
fill ~40 ~2 ~3 ~47 ~2 ~3 end_stone 0  
fill ~40 ~2 ~19 ~40 ~3 ~19 bedrock 0  
fill ~40 ~2 ~23 ~41 ~2 ~23 stonebrick 0  
fill ~40 ~2 ~87 ~41 ~2 ~87 stonebrick 0  
fill ~40 ~2 ~91 ~40 ~3 ~91 bedrock 0  
fill ~41 ~2 ~2 ~43 ~2 ~2 end_stone 0  
fill ~47 ~2 ~23 ~48 ~2 ~23 stonebrick 0  
fill ~47 ~2 ~87 ~48 ~2 ~87 stonebrick 0  
fill ~48 ~2 ~18 ~50 ~2 ~18 bedrock 0  
fill ~48 ~2 ~19 ~48 ~3 ~19 bedrock 0  
fill ~48 ~2 ~20 ~50 ~2 ~20 bedrock 0  
fill ~48 ~2 ~91 ~48 ~3 ~91 bedrock 0  
fill ~48 ~2 ~92 ~50 ~2 ~92 bedrock 0 
setblock ~49 ~2 ~17 bedrock 0  
fill ~49 ~2 ~44 ~49 ~7 ~44 end_stone 0  
fill ~49 ~2 ~66 ~49 ~7 ~66 end_stone 0  
fill ~50 ~2 ~19 ~50 ~3 ~19 bedrock 0  
fill ~50 ~2 ~23 ~51 ~2 ~23 stonebrick 0  
fill ~50 ~2 ~87 ~51 ~2 ~87 stonebrick 0  
fill ~50 ~2 ~91 ~50 ~3 ~91 bedrock 0  
fill ~52 ~2 ~7 ~58 ~2 ~7 end_stone 0  
fill ~52 ~2 ~8 ~58 ~2 ~8 end_stone 0  
fill ~52 ~2 ~9 ~58 ~2 ~9 end_stone 0  
fill ~52 ~2 ~10 ~57 ~2 ~10 end_stone 0  
fill ~52 ~2 ~11 ~56 ~2 ~11 end_stone 0  
fill ~52 ~2 ~12 ~56 ~2 ~12 end_stone 0  
fill ~53 ~2 ~6 ~58 ~2 ~6 end_stone 0  
fill ~53 ~2 ~13 ~56 ~2 ~13 end_stone 0  
fill ~54 ~2 ~2 ~58 ~2 ~2 end_stone 0  
fill ~54 ~2 ~3 ~58 ~2 ~3 end_stone 0  
fill ~54 ~2 ~4 ~58 ~2 ~4 end_stone 0  
fill ~54 ~2 ~5 ~58 ~2 ~5 end_stone 0  
fill ~57 ~2 ~23 ~58 ~2 ~23 stonebrick 0  
fill ~57 ~2 ~87 ~58 ~2 ~87 stonebrick 0  
fill ~58 ~2 ~18 ~60 ~2 ~18 bedrock 0  
fill ~58 ~2 ~19 ~58 ~3 ~19 bedrock 0  
fill ~58 ~2 ~20 ~60 ~2 ~20 bedrock 0  
fill ~58 ~2 ~91 ~58 ~3 ~91 bedrock 0  
fill ~58 ~2 ~92 ~60 ~2 ~92 bedrock 0 
setblock ~59 ~2 ~17 bedrock 0  
fill ~59 ~2 ~44 ~59 ~7 ~44 end_stone 0  
fill ~59 ~2 ~66 ~59 ~7 ~66 end_stone 0  
fill ~60 ~2 ~19 ~60 ~3 ~19 bedrock 0  
fill ~60 ~2 ~23 ~61 ~2 ~23 stonebrick 0  
fill ~60 ~2 ~87 ~61 ~2 ~87 stonebrick 0  
fill ~60 ~2 ~91 ~60 ~3 ~91 bedrock 0  
fill ~67 ~2 ~87 ~68 ~2 ~87 stonebrick 0  
fill ~68 ~2 ~21 ~68 ~3 ~21 nether_brick_fence 0  
fill ~68 ~2 ~89 ~68 ~3 ~89 nether_brick_fence 0  
fill ~71 ~2 ~40 ~72 ~2 ~40 stonebrick 0  
fill ~71 ~2 ~70 ~72 ~2 ~70 stonebrick 0  
fill ~72 ~2 ~26 ~75 ~2 ~26 stonebrick 0 
setblock ~72 ~2 ~36 glowstone 0  
fill ~72 ~2 ~37 ~72 ~3 ~37 nether_brick_fence 0 
setblock ~72 ~2 ~74 glowstone 0  
fill ~72 ~2 ~75 ~72 ~3 ~75 nether_brick_fence 0  
fill ~72 ~2 ~84 ~75 ~2 ~84 stonebrick 0  
fill ~73 ~2 ~77 ~73 ~4 ~77 obsidian 0  
fill ~76 ~2 ~5 ~79 ~2 ~5 end_stone 0  
fill ~76 ~2 ~6 ~79 ~2 ~6 end_stone 0  
fill ~76 ~2 ~7 ~79 ~2 ~7 end_stone 0  
fill ~76 ~2 ~8 ~79 ~2 ~8 end_stone 0  
fill ~76 ~2 ~9 ~79 ~2 ~9 end_stone 0 
setblock ~78 ~2 ~50 obsidian 0 
setblock ~78 ~2 ~60 obsidian 0 
setblock ~79 ~2 ~49 obsidian 0 
setblock ~79 ~2 ~61 obsidian 0  
fill ~80 ~2 ~10 ~81 ~2 ~10 end_stone 0  
fill ~80 ~2 ~11 ~83 ~2 ~11 end_stone 0  
fill ~80 ~2 ~12 ~84 ~2 ~12 end_stone 0  
fill ~80 ~2 ~13 ~84 ~2 ~13 end_stone 0  
fill ~82 ~2 ~14 ~84 ~2 ~14 end_stone 0  
fill ~83 ~2 ~15 ~84 ~2 ~15 end_stone 0  
fill ~83 ~2 ~16 ~84 ~2 ~16 end_stone 0  
fill ~87 ~2 ~82 ~99 ~2 ~82 end_stone 0  
fill ~87 ~2 ~83 ~99 ~2 ~83 end_stone 0  
fill ~87 ~2 ~84 ~98 ~2 ~84 end_stone 0  
fill ~87 ~2 ~85 ~98 ~2 ~85 end_stone 0  
fill ~87 ~2 ~86 ~99 ~2 ~86 end_stone 0  
fill ~87 ~2 ~92 ~100 ~2 ~92 end_stone 0  
fill ~87 ~2 ~93 ~100 ~2 ~93 end_stone 0  
fill ~87 ~2 ~94 ~100 ~2 ~94 end_stone 0  
fill ~88 ~2 ~87 ~99 ~2 ~87 end_stone 0  
fill ~88 ~2 ~91 ~100 ~2 ~91 end_stone 0  
fill ~88 ~2 ~95 ~99 ~2 ~95 end_stone 0  
fill ~88 ~2 ~96 ~98 ~2 ~96 end_stone 0  
fill ~88 ~2 ~97 ~97 ~2 ~97 end_stone 0  
fill ~89 ~2 ~80 ~98 ~2 ~80 end_stone 0  
fill ~89 ~2 ~81 ~99 ~2 ~81 end_stone 0  
fill ~89 ~2 ~100 ~95 ~2 ~100 end_stone 0  
fill ~89 ~2 ~101 ~92 ~2 ~101 end_stone 0  
fill ~90 ~2 ~99 ~96 ~2 ~99 end_stone 0  
fill ~90 ~2 ~102 ~92 ~2 ~102 end_stone 0  
fill ~91 ~2 ~76 ~94 ~2 ~76 end_stone 0  
fill ~91 ~2 ~77 ~95 ~2 ~77 end_stone 0  
fill ~91 ~2 ~78 ~96 ~2 ~78 end_stone 0  
fill ~91 ~2 ~79 ~97 ~2 ~79 end_stone 0  
fill ~91 ~2 ~98 ~97 ~2 ~98 end_stone 0  
fill ~93 ~2 ~88 ~99 ~2 ~88 end_stone 0  
fill ~93 ~2 ~89 ~100 ~2 ~89 end_stone 0  
fill ~93 ~2 ~90 ~100 ~2 ~90 end_stone 0  
fill ~9 ~3 ~50 ~9 ~5 ~50 obsidian 0  
fill ~9 ~3 ~60 ~9 ~5 ~60 obsidian 0  
fill ~13 ~3 ~26 ~16 ~3 ~26 stonebrick 0  
fill ~13 ~3 ~84 ~16 ~3 ~84 stonebrick 0  
fill ~14 ~3 ~5 ~18 ~3 ~5 end_stone 0  
fill ~14 ~3 ~6 ~21 ~3 ~6 end_stone 0  
fill ~14 ~3 ~7 ~20 ~3 ~7 end_stone 0  
fill ~14 ~3 ~8 ~18 ~3 ~8 end_stone 0  
fill ~14 ~3 ~9 ~18 ~3 ~9 end_stone 0  
fill ~15 ~3 ~80 ~15 ~4 ~80 obsidian 0  
fill ~16 ~3 ~3 ~22 ~3 ~3 end_stone 0  
fill ~16 ~3 ~4 ~22 ~3 ~4 end_stone 0  
fill ~16 ~3 ~36 ~16 ~4 ~36 nether_brick_fence 0  
fill ~16 ~3 ~40 ~17 ~3 ~40 stonebrick 0  
fill ~16 ~3 ~70 ~17 ~3 ~70 stonebrick 0  
fill ~16 ~3 ~74 ~16 ~4 ~74 nether_brick_fence 0  
fill ~17 ~3 ~2 ~21 ~3 ~2 end_stone 0 
setblock ~17 ~3 ~43 glowstone 0 
setblock ~17 ~3 ~67 glowstone 0  
fill ~18 ~3 ~1 ~20 ~3 ~1 end_stone 0  
fill ~19 ~3 ~5 ~19 ~19 ~5 bedrock 0  
fill ~19 ~3 ~87 ~20 ~3 ~87 bedrock 0  
fill ~20 ~3 ~5 ~22 ~3 ~5 end_stone 0  
fill ~20 ~3 ~23 ~21 ~3 ~23 stonebrick 0  
fill ~27 ~3 ~23 ~28 ~3 ~23 stonebrick 0  
fill ~27 ~3 ~87 ~28 ~3 ~87 stonebrick 0  
fill ~29 ~3 ~18 ~29 ~4 ~18 bedrock 0  
fill ~29 ~3 ~20 ~29 ~15 ~20 bedrock 0  
fill ~29 ~3 ~92 ~29 ~4 ~92 bedrock 0  
fill ~30 ~3 ~23 ~31 ~3 ~23 stonebrick 0  
fill ~30 ~3 ~87 ~31 ~3 ~87 stonebrick 0  
fill ~37 ~3 ~23 ~38 ~3 ~23 stonebrick 0  
fill ~37 ~3 ~87 ~38 ~3 ~87 stonebrick 0  
fill ~39 ~3 ~4 ~48 ~3 ~4 end_stone 0  
fill ~39 ~3 ~5 ~48 ~3 ~5 end_stone 0  
fill ~39 ~3 ~6 ~48 ~3 ~6 end_stone 0  
fill ~39 ~3 ~7 ~48 ~3 ~7 end_stone 0  
fill ~39 ~3 ~8 ~48 ~3 ~8 end_stone 0  
fill ~39 ~3 ~18 ~39 ~4 ~18 bedrock 0  
fill ~39 ~3 ~20 ~39 ~15 ~20 bedrock 0  
fill ~39 ~3 ~92 ~39 ~4 ~92 bedrock 0  
fill ~40 ~3 ~3 ~45 ~3 ~3 end_stone 0  
fill ~40 ~3 ~23 ~41 ~3 ~23 stonebrick 0  
fill ~40 ~3 ~87 ~41 ~3 ~87 stonebrick 0  
fill ~41 ~3 ~2 ~43 ~3 ~2 end_stone 0  
fill ~47 ~3 ~23 ~48 ~3 ~23 stonebrick 0  
fill ~47 ~3 ~87 ~48 ~3 ~87 stonebrick 0  
fill ~49 ~3 ~18 ~49 ~4 ~18 bedrock 0  
fill ~49 ~3 ~20 ~49 ~15 ~20 bedrock 0  
fill ~49 ~3 ~92 ~49 ~4 ~92 bedrock 0  
fill ~50 ~3 ~23 ~51 ~3 ~23 stonebrick 0  
fill ~50 ~3 ~87 ~51 ~3 ~87 stonebrick 0  
fill ~52 ~3 ~7 ~57 ~3 ~7 end_stone 0  
fill ~52 ~3 ~8 ~57 ~3 ~8 end_stone 0  
fill ~52 ~3 ~9 ~58 ~3 ~9 end_stone 0  
fill ~53 ~3 ~6 ~57 ~3 ~6 end_stone 0  
fill ~54 ~3 ~4 ~57 ~3 ~4 end_stone 0  
fill ~54 ~3 ~5 ~57 ~3 ~5 end_stone 0  
fill ~54 ~3 ~10 ~57 ~3 ~10 end_stone 0  
fill ~55 ~3 ~3 ~57 ~3 ~3 end_stone 0  
fill ~55 ~3 ~11 ~56 ~3 ~11 end_stone 0  
fill ~57 ~3 ~23 ~58 ~3 ~23 stonebrick 0  
fill ~57 ~3 ~87 ~58 ~3 ~87 stonebrick 0  
fill ~59 ~3 ~18 ~59 ~4 ~18 bedrock 0  
fill ~59 ~3 ~20 ~59 ~15 ~20 bedrock 0  
fill ~59 ~3 ~92 ~59 ~4 ~92 bedrock 0  
fill ~60 ~3 ~23 ~61 ~3 ~23 stonebrick 0  
fill ~60 ~3 ~87 ~61 ~3 ~87 stonebrick 0  
fill ~67 ~3 ~87 ~68 ~3 ~87 stonebrick 0  
fill ~71 ~3 ~40 ~72 ~3 ~40 stonebrick 0 
setblock ~71 ~3 ~43 glowstone 0 
setblock ~71 ~3 ~67 glowstone 0  
fill ~71 ~3 ~70 ~72 ~3 ~70 stonebrick 0  
fill ~72 ~3 ~26 ~75 ~3 ~26 stonebrick 0  
fill ~72 ~3 ~36 ~72 ~4 ~36 nether_brick_fence 0  
fill ~72 ~3 ~74 ~72 ~4 ~74 nether_brick_fence 0  
fill ~72 ~3 ~84 ~75 ~3 ~84 stonebrick 0  
fill ~73 ~3 ~30 ~73 ~4 ~30 obsidian 0  
fill ~79 ~3 ~50 ~79 ~5 ~50 obsidian 0  
fill ~79 ~3 ~60 ~79 ~5 ~60 obsidian 0  
fill ~88 ~3 ~95 ~89 ~3 ~95 end_stone 0  
fill ~88 ~3 ~96 ~89 ~3 ~96 end_stone 0  
fill ~90 ~3 ~80 ~98 ~3 ~80 end_stone 0  
fill ~90 ~3 ~81 ~99 ~3 ~81 end_stone 0  
fill ~90 ~3 ~82 ~99 ~3 ~82 end_stone 0  
fill ~90 ~3 ~83 ~99 ~3 ~83 end_stone 0  
fill ~90 ~3 ~84 ~98 ~3 ~84 end_stone 0  
fill ~90 ~3 ~85 ~91 ~3 ~85 end_stone 0  
fill ~90 ~3 ~86 ~91 ~3 ~86 end_stone 0  
fill ~91 ~3 ~78 ~96 ~3 ~78 end_stone 0  
fill ~91 ~3 ~79 ~97 ~3 ~79 end_stone 0  
fill ~92 ~3 ~77 ~93 ~3 ~77 end_stone 0  
fill ~92 ~3 ~96 ~96 ~3 ~96 end_stone 0  
fill ~92 ~3 ~97 ~96 ~3 ~97 end_stone 0  
fill ~92 ~3 ~98 ~96 ~3 ~98 end_stone 0  
fill ~93 ~3 ~85 ~98 ~3 ~85 end_stone 0  
fill ~93 ~3 ~86 ~98 ~3 ~86 end_stone 0  
fill ~93 ~3 ~87 ~98 ~3 ~87 end_stone 0  
fill ~93 ~3 ~95 ~99 ~3 ~95 end_stone 0  
fill ~93 ~3 ~99 ~96 ~3 ~99 end_stone 0  
fill ~94 ~3 ~88 ~98 ~3 ~88 end_stone 0  
fill ~94 ~3 ~94 ~99 ~3 ~94 end_stone 0  
fill ~95 ~3 ~91 ~98 ~3 ~91 end_stone 0  
fill ~95 ~3 ~92 ~99 ~3 ~92 end_stone 0  
fill ~95 ~3 ~93 ~99 ~3 ~93 end_stone 0  
fill ~96 ~3 ~89 ~98 ~3 ~89 end_stone 0  
fill ~96 ~3 ~90 ~98 ~3 ~90 end_stone 0  
fill ~12 ~4 ~21 ~12 ~5 ~21 obsidian 0  
fill ~12 ~4 ~25 ~12 ~5 ~25 obsidian 0  
fill ~12 ~4 ~85 ~12 ~5 ~85 obsidian 0  
fill ~12 ~4 ~89 ~12 ~5 ~89 obsidian 0  
fill ~13 ~4 ~21 ~13 ~11 ~21 stonebrick 0  
fill ~13 ~4 ~25 ~13 ~19 ~25 stonebrick 0  
fill ~13 ~4 ~26 ~16 ~4 ~26 stonebrick 0  
fill ~13 ~4 ~84 ~16 ~4 ~84 stonebrick 0  
fill ~13 ~4 ~85 ~13 ~19 ~85 stonebrick 0  
fill ~13 ~4 ~89 ~13 ~11 ~89 stonebrick 0  
fill ~14 ~4 ~19 ~14 ~5 ~19 obsidian 0  
fill ~14 ~4 ~20 ~14 ~11 ~20 stonebrick 0  
fill ~14 ~4 ~90 ~14 ~11 ~90 stonebrick 0  
fill ~14 ~4 ~91 ~14 ~5 ~91 obsidian 0  
fill ~15 ~4 ~6 ~21 ~4 ~6 end_stone 0  
fill ~15 ~4 ~7 ~17 ~4 ~7 end_stone 0  
fill ~15 ~4 ~8 ~17 ~4 ~8 end_stone 0  
fill ~15 ~4 ~73 ~15 ~5 ~73 obsidian 0  
fill ~16 ~4 ~35 ~16 ~10 ~35 stonebrick 0  
fill ~16 ~4 ~37 ~16 ~15 ~37 stonebrick 0  
fill ~16 ~4 ~40 ~17 ~4 ~40 stonebrick 0  
fill ~16 ~4 ~48 ~16 ~7 ~48 obsidian 0  
fill ~16 ~4 ~62 ~16 ~7 ~62 obsidian 0  
fill ~16 ~4 ~70 ~17 ~4 ~70 stonebrick 0  
fill ~16 ~4 ~73 ~16 ~15 ~73 stonebrick 0  
fill ~16 ~4 ~75 ~16 ~10 ~75 stonebrick 0  
fill ~17 ~4 ~2 ~19 ~4 ~2 end_stone 0  
fill ~17 ~4 ~3 ~20 ~4 ~3 end_stone 0  
fill ~17 ~4 ~4 ~21 ~4 ~4 end_stone 0  
fill ~17 ~4 ~5 ~18 ~4 ~5 end_stone 0  
fill ~17 ~4 ~43 ~17 ~6 ~43 nether_brick_fence 0  
fill ~17 ~4 ~48 ~17 ~6 ~48 end_stone 0  
fill ~17 ~4 ~62 ~17 ~6 ~62 end_stone 0  
fill ~17 ~4 ~67 ~17 ~6 ~67 nether_brick_fence 0  
fill ~18 ~4 ~19 ~18 ~5 ~19 obsidian 0  
fill ~18 ~4 ~20 ~18 ~19 ~20 stonebrick 0  
fill ~18 ~4 ~48 ~18 ~7 ~48 obsidian 0  
fill ~18 ~4 ~62 ~18 ~7 ~62 obsidian 0 
setblock ~18 ~4 ~89 netherrack 0  
fill ~18 ~4 ~90 ~18 ~19 ~90 stonebrick 0  
fill ~18 ~4 ~91 ~18 ~5 ~91 obsidian 0  
fill ~19 ~4 ~7 ~19 ~19 ~7 bedrock 0  
fill ~19 ~4 ~87 ~20 ~4 ~87 bedrock 0  
fill ~20 ~4 ~5 ~21 ~4 ~5 end_stone 0 
setblock ~20 ~4 ~20 trapdoor 4 
setblock ~20 ~4 ~21 netherrack 0  
fill ~20 ~4 ~23 ~21 ~4 ~23 stonebrick 0 
setblock ~20 ~4 ~89 netherrack 0 
setblock ~20 ~4 ~90 trapdoor 5 
setblock ~21 ~4 ~21 trapdoor 7 
setblock ~21 ~4 ~89 trapdoor 7  
fill ~27 ~4 ~23 ~28 ~4 ~23 stonebrick 0  
fill ~27 ~4 ~87 ~28 ~4 ~87 stonebrick 0  
fill ~28 ~4 ~20 ~28 ~5 ~20 bedrock 0  
fill ~28 ~4 ~90 ~28 ~5 ~90 bedrock 0  
fill ~30 ~4 ~20 ~30 ~5 ~20 bedrock 0  
fill ~30 ~4 ~23 ~31 ~4 ~23 stonebrick 0  
fill ~30 ~4 ~87 ~31 ~4 ~87 stonebrick 0  
fill ~30 ~4 ~90 ~30 ~5 ~90 bedrock 0  
fill ~37 ~4 ~23 ~38 ~4 ~23 stonebrick 0  
fill ~37 ~4 ~87 ~38 ~4 ~87 stonebrick 0  
fill ~38 ~4 ~20 ~38 ~5 ~20 bedrock 0  
fill ~38 ~4 ~90 ~38 ~5 ~90 bedrock 0  
fill ~40 ~4 ~4 ~45 ~4 ~4 end_stone 0  
fill ~40 ~4 ~5 ~45 ~4 ~5 end_stone 0  
fill ~40 ~4 ~6 ~45 ~4 ~6 end_stone 0  
fill ~40 ~4 ~7 ~43 ~4 ~7 end_stone 0  
fill ~40 ~4 ~20 ~40 ~5 ~20 bedrock 0  
fill ~40 ~4 ~23 ~41 ~4 ~23 stonebrick 0  
fill ~40 ~4 ~87 ~41 ~4 ~87 stonebrick 0  
fill ~40 ~4 ~90 ~40 ~5 ~90 bedrock 0  
fill ~41 ~4 ~3 ~45 ~4 ~3 end_stone 0  
fill ~47 ~4 ~23 ~48 ~4 ~23 stonebrick 0  
fill ~47 ~4 ~87 ~48 ~4 ~87 stonebrick 0  
fill ~48 ~4 ~20 ~48 ~5 ~20 bedrock 0  
fill ~48 ~4 ~90 ~48 ~5 ~90 bedrock 0  
fill ~50 ~4 ~20 ~50 ~5 ~20 bedrock 0  
fill ~50 ~4 ~23 ~51 ~4 ~23 stonebrick 0  
fill ~50 ~4 ~87 ~51 ~4 ~87 stonebrick 0  
fill ~50 ~4 ~90 ~50 ~5 ~90 bedrock 0  
fill ~53 ~4 ~8 ~56 ~4 ~8 end_stone 0  
fill ~53 ~4 ~9 ~57 ~4 ~9 end_stone 0  
fill ~54 ~4 ~6 ~55 ~4 ~6 end_stone 0  
fill ~54 ~4 ~7 ~56 ~4 ~7 end_stone 0  
fill ~57 ~4 ~23 ~58 ~4 ~23 stonebrick 0  
fill ~57 ~4 ~87 ~58 ~4 ~87 stonebrick 0  
fill ~58 ~4 ~20 ~58 ~5 ~20 bedrock 0  
fill ~58 ~4 ~90 ~58 ~5 ~90 bedrock 0  
fill ~60 ~4 ~20 ~60 ~5 ~20 bedrock 0  
fill ~60 ~4 ~23 ~61 ~4 ~23 stonebrick 0  
fill ~60 ~4 ~87 ~61 ~4 ~87 stonebrick 0  
fill ~60 ~4 ~90 ~60 ~5 ~90 bedrock 0 
setblock ~67 ~4 ~21 trapdoor 6  
fill ~67 ~4 ~87 ~68 ~4 ~87 stonebrick 0 
setblock ~67 ~4 ~89 trapdoor 6 
setblock ~68 ~4 ~20 trapdoor 4 
setblock ~68 ~4 ~21 netherrack 0 
setblock ~68 ~4 ~89 netherrack 0 
setblock ~68 ~4 ~90 trapdoor 5  
fill ~70 ~4 ~19 ~70 ~5 ~19 obsidian 0  
fill ~70 ~4 ~20 ~70 ~19 ~20 stonebrick 0  
fill ~70 ~4 ~48 ~70 ~7 ~48 obsidian 0  
fill ~70 ~4 ~62 ~70 ~7 ~62 obsidian 0  
fill ~70 ~4 ~90 ~70 ~19 ~90 stonebrick 0  
fill ~70 ~4 ~91 ~70 ~5 ~91 obsidian 0  
fill ~71 ~4 ~40 ~72 ~4 ~40 stonebrick 0  
fill ~71 ~4 ~43 ~71 ~6 ~43 nether_brick_fence 0  
fill ~71 ~4 ~48 ~71 ~6 ~48 end_stone 0  
fill ~71 ~4 ~62 ~71 ~6 ~62 end_stone 0  
fill ~71 ~4 ~67 ~71 ~6 ~67 nether_brick_fence 0  
fill ~71 ~4 ~70 ~72 ~4 ~70 stonebrick 0  
fill ~72 ~4 ~26 ~75 ~4 ~26 stonebrick 0  
fill ~72 ~4 ~35 ~72 ~10 ~35 stonebrick 0  
fill ~72 ~4 ~37 ~72 ~15 ~37 stonebrick 0  
fill ~72 ~4 ~48 ~72 ~7 ~48 obsidian 0  
fill ~72 ~4 ~62 ~72 ~7 ~62 obsidian 0  
fill ~72 ~4 ~73 ~72 ~15 ~73 stonebrick 0  
fill ~72 ~4 ~75 ~72 ~10 ~75 stonebrick 0  
fill ~72 ~4 ~84 ~75 ~4 ~84 stonebrick 0  
fill ~73 ~4 ~37 ~73 ~5 ~37 obsidian 0  
fill ~74 ~4 ~19 ~74 ~5 ~19 obsidian 0  
fill ~74 ~4 ~20 ~74 ~11 ~20 stonebrick 0  
fill ~74 ~4 ~90 ~74 ~11 ~90 stonebrick 0  
fill ~74 ~4 ~91 ~74 ~5 ~91 obsidian 0  
fill ~75 ~4 ~21 ~75 ~11 ~21 stonebrick 0  
fill ~75 ~4 ~25 ~75 ~19 ~25 stonebrick 0  
fill ~75 ~4 ~85 ~75 ~19 ~85 stonebrick 0  
fill ~75 ~4 ~89 ~75 ~11 ~89 stonebrick 0  
fill ~76 ~4 ~21 ~76 ~5 ~21 obsidian 0  
fill ~76 ~4 ~25 ~76 ~5 ~25 obsidian 0  
fill ~76 ~4 ~85 ~76 ~5 ~85 obsidian 0  
fill ~76 ~4 ~89 ~76 ~5 ~89 obsidian 0  
fill ~93 ~4 ~79 ~95 ~4 ~79 end_stone 0  
fill ~94 ~4 ~80 ~97 ~4 ~80 end_stone 0  
fill ~94 ~4 ~81 ~98 ~4 ~81 end_stone 0  
fill ~94 ~4 ~82 ~98 ~4 ~82 end_stone 0  
fill ~94 ~4 ~83 ~98 ~4 ~83 end_stone 0  
fill ~94 ~4 ~84 ~98 ~4 ~84 end_stone 0  
fill ~94 ~4 ~85 ~98 ~4 ~85 end_stone 0  
fill ~94 ~4 ~86 ~95 ~4 ~86 end_stone 0  
fill ~13 ~5 ~26 ~16 ~5 ~26 stonebrick 0  
fill ~13 ~5 ~84 ~16 ~5 ~84 stonebrick 0  
fill ~15 ~5 ~32 ~15 ~6 ~32 obsidian 0 
setblock ~15 ~5 ~34 obsidian 0 
setblock ~15 ~5 ~79 obsidian 0  
fill ~16 ~5 ~36 ~16 ~20 ~36 stonebrick 0  
fill ~16 ~5 ~40 ~17 ~5 ~40 stonebrick 0  
fill ~16 ~5 ~47 ~16 ~8 ~47 stonebrick 0  
fill ~16 ~5 ~63 ~16 ~8 ~63 stonebrick 0  
fill ~16 ~5 ~70 ~17 ~5 ~70 stonebrick 0  
fill ~16 ~5 ~74 ~16 ~20 ~74 stonebrick 0  
fill ~17 ~5 ~5 ~17 ~19 ~5 bedrock 0  
fill ~17 ~5 ~7 ~17 ~19 ~7 bedrock 0 
setblock ~17 ~5 ~46 stonebrick 0 
setblock ~17 ~5 ~64 stonebrick 0  
fill ~18 ~5 ~3 ~19 ~5 ~3 end_stone 0  
fill ~18 ~5 ~4 ~20 ~5 ~4 end_stone 0  
fill ~18 ~5 ~5 ~18 ~5 ~6 end_stone 0  
fill ~18 ~5 ~47 ~18 ~8 ~47 stonebrick 0  
fill ~18 ~5 ~63 ~18 ~8 ~63 stonebrick 0 
setblock ~18 ~5 ~89 fire 15  
fill ~19 ~5 ~87 ~20 ~5 ~87 bedrock 0  
fill ~20 ~5 ~5 ~20 ~-1 ~5 end_stone 0 
setblock ~20 ~5 ~21 fire 15  
fill ~20 ~5 ~23 ~22 ~5 ~23 stonebrick 0 
setblock ~20 ~5 ~89 fire 15  
fill ~22 ~5 ~22 ~22 ~6 ~22 obsidian 0  
fill ~22 ~5 ~87 ~22 ~11 ~87 stonebrick 0  
fill ~22 ~5 ~88 ~22 ~6 ~88 obsidian 0  
fill ~26 ~5 ~22 ~26 ~6 ~22 obsidian 0  
fill ~26 ~5 ~23 ~28 ~5 ~23 stonebrick 0  
fill ~26 ~5 ~87 ~28 ~5 ~87 stonebrick 0  
fill ~26 ~5 ~88 ~26 ~6 ~88 obsidian 0  
fill ~30 ~5 ~23 ~32 ~5 ~23 stonebrick 0  
fill ~30 ~5 ~87 ~32 ~5 ~87 stonebrick 0  
fill ~32 ~5 ~22 ~32 ~6 ~22 obsidian 0  
fill ~32 ~5 ~88 ~32 ~6 ~88 obsidian 0  
fill ~36 ~5 ~22 ~36 ~6 ~22 obsidian 0  
fill ~36 ~5 ~23 ~38 ~5 ~23 stonebrick 0  
fill ~36 ~5 ~87 ~38 ~5 ~87 stonebrick 0  
fill ~36 ~5 ~88 ~36 ~6 ~88 obsidian 0  
fill ~40 ~5 ~23 ~42 ~5 ~23 stonebrick 0  
fill ~40 ~5 ~87 ~42 ~5 ~87 stonebrick 0  
fill ~42 ~5 ~22 ~42 ~6 ~22 obsidian 0  
fill ~42 ~5 ~88 ~42 ~6 ~88 obsidian 0  
fill ~46 ~5 ~22 ~46 ~6 ~22 obsidian 0  
fill ~46 ~5 ~23 ~48 ~5 ~23 stonebrick 0  
fill ~46 ~5 ~87 ~48 ~5 ~87 stonebrick 0  
fill ~46 ~5 ~88 ~46 ~6 ~88 obsidian 0  
fill ~50 ~5 ~23 ~52 ~5 ~23 stonebrick 0  
fill ~50 ~5 ~87 ~52 ~5 ~87 stonebrick 0  
fill ~52 ~5 ~22 ~52 ~6 ~22 obsidian 0  
fill ~52 ~5 ~88 ~52 ~6 ~88 obsidian 0  
fill ~56 ~5 ~22 ~56 ~6 ~22 obsidian 0  
fill ~56 ~5 ~23 ~58 ~5 ~23 stonebrick 0  
fill ~56 ~5 ~87 ~58 ~5 ~87 stonebrick 0  
fill ~56 ~5 ~88 ~56 ~6 ~88 obsidian 0  
fill ~60 ~5 ~23 ~62 ~5 ~23 stonebrick 0  
fill ~60 ~5 ~87 ~62 ~5 ~87 stonebrick 0  
fill ~62 ~5 ~22 ~62 ~6 ~22 obsidian 0  
fill ~62 ~5 ~88 ~62 ~6 ~88 obsidian 0  
fill ~66 ~5 ~22 ~66 ~6 ~22 obsidian 0  
fill ~66 ~5 ~23 ~66 ~11 ~23 stonebrick 0  
fill ~66 ~5 ~87 ~68 ~5 ~87 stonebrick 0  
fill ~66 ~5 ~88 ~66 ~6 ~88 obsidian 0 
setblock ~68 ~5 ~21 fire 15 
setblock ~68 ~5 ~89 fire 15  
fill ~70 ~5 ~47 ~70 ~8 ~47 stonebrick 0  
fill ~70 ~5 ~63 ~70 ~8 ~63 stonebrick 0  
fill ~71 ~5 ~40 ~72 ~5 ~40 stonebrick 0 
setblock ~71 ~5 ~46 stonebrick 0 
setblock ~71 ~5 ~64 stonebrick 0  
fill ~71 ~5 ~70 ~72 ~5 ~70 stonebrick 0  
fill ~72 ~5 ~26 ~75 ~5 ~26 stonebrick 0  
fill ~72 ~5 ~36 ~72 ~20 ~36 stonebrick 0  
fill ~72 ~5 ~47 ~72 ~8 ~47 stonebrick 0  
fill ~72 ~5 ~63 ~72 ~8 ~63 stonebrick 0  
fill ~72 ~5 ~74 ~72 ~20 ~74 stonebrick 0  
fill ~72 ~5 ~84 ~75 ~5 ~84 stonebrick 0 
setblock ~73 ~5 ~31 obsidian 0 
setblock ~73 ~5 ~76 obsidian 0  
fill ~73 ~5 ~78 ~73 ~6 ~78 obsidian 0  
fill ~12 ~6 ~22 ~12 ~7 ~22 obsidian 0  
fill ~12 ~6 ~24 ~12 ~7 ~24 obsidian 0  
fill ~12 ~6 ~86 ~12 ~7 ~86 obsidian 0  
fill ~12 ~6 ~88 ~12 ~7 ~88 obsidian 0  
fill ~13 ~6 ~22 ~13 ~11 ~22 stonebrick 0  
fill ~13 ~6 ~24 ~13 ~19 ~24 stonebrick 0  
fill ~13 ~6 ~26 ~16 ~6 ~26 stonebrick 0  
fill ~13 ~6 ~27 ~13 ~7 ~27 obsidian 0  
fill ~13 ~6 ~84 ~16 ~6 ~84 stonebrick 0  
fill ~13 ~6 ~86 ~13 ~19 ~86 stonebrick 0  
fill ~13 ~6 ~88 ~13 ~11 ~88 stonebrick 0  
fill ~15 ~6 ~19 ~15 ~7 ~19 obsidian 0  
fill ~15 ~6 ~20 ~15 ~11 ~20 stonebrick 0  
fill ~15 ~6 ~35 ~15 ~6 ~36 obsidian 0 
setblock ~15 ~6 ~40 obsidian 0 
setblock ~15 ~6 ~42 obsidian 0 
setblock ~15 ~6 ~44 obsidian 0 
setblock ~15 ~6 ~66 obsidian 0 
setblock ~15 ~6 ~68 obsidian 0 
setblock ~15 ~6 ~74 obsidian 0 
setblock ~15 ~6 ~78 obsidian 0  
fill ~15 ~6 ~90 ~15 ~11 ~90 stonebrick 0  
fill ~15 ~6 ~91 ~15 ~7 ~91 obsidian 0  
fill ~16 ~6 ~40 ~17 ~6 ~40 stonebrick 0  
fill ~16 ~6 ~42 ~16 ~10 ~42 stonebrick 0  
fill ~16 ~6 ~44 ~16 ~8 ~44 stonebrick 0  
fill ~16 ~6 ~66 ~16 ~8 ~66 stonebrick 0  
fill ~16 ~6 ~68 ~16 ~10 ~68 stonebrick 0  
fill ~16 ~6 ~70 ~17 ~6 ~70 stonebrick 0  
fill ~17 ~6 ~19 ~17 ~7 ~19 obsidian 0  
fill ~17 ~6 ~20 ~17 ~19 ~20 stonebrick 0 
setblock ~17 ~6 ~42 end_stone 0 
setblock ~17 ~6 ~44 end_stone 0 
setblock ~17 ~6 ~45 stonebrick 0  
fill ~17 ~6 ~46 ~17 ~13 ~46 lava 8  
fill ~17 ~6 ~47 ~17 ~7 ~47 stonebrick 0  
fill ~17 ~6 ~63 ~17 ~7 ~63 stonebrick 0  
fill ~17 ~6 ~64 ~17 ~13 ~64 lava 8 
setblock ~17 ~6 ~65 stonebrick 0 
setblock ~17 ~6 ~66 end_stone 0 
setblock ~17 ~6 ~68 end_stone 0  
fill ~17 ~6 ~90 ~17 ~19 ~90 stonebrick 0  
fill ~17 ~6 ~91 ~17 ~7 ~91 obsidian 0  
fill ~18 ~6 ~6 ~18 ~7 ~6 end_stone 0  
fill ~18 ~6 ~42 ~18 ~10 ~42 stonebrick 0  
fill ~18 ~6 ~44 ~18 ~8 ~44 stonebrick 0  
fill ~18 ~6 ~66 ~18 ~8 ~66 stonebrick 0  
fill ~18 ~6 ~68 ~18 ~10 ~68 stonebrick 0  
fill ~19 ~6 ~87 ~20 ~6 ~87 bedrock 0  
fill ~20 ~6 ~23 ~22 ~6 ~23 stonebrick 0  
fill ~26 ~6 ~23 ~28 ~6 ~23 stonebrick 0  
fill ~26 ~6 ~87 ~28 ~6 ~87 stonebrick 0  
fill ~30 ~6 ~23 ~32 ~6 ~23 stonebrick 0  
fill ~30 ~6 ~87 ~32 ~6 ~87 stonebrick 0  
fill ~36 ~6 ~23 ~38 ~6 ~23 stonebrick 0  
fill ~36 ~6 ~87 ~38 ~6 ~87 stonebrick 0  
fill ~40 ~6 ~23 ~42 ~6 ~23 stonebrick 0  
fill ~40 ~6 ~87 ~42 ~6 ~87 stonebrick 0  
fill ~46 ~6 ~23 ~48 ~6 ~23 stonebrick 0  
fill ~46 ~6 ~87 ~48 ~6 ~87 stonebrick 0  
fill ~50 ~6 ~23 ~52 ~6 ~23 stonebrick 0  
fill ~50 ~6 ~87 ~52 ~6 ~87 stonebrick 0  
fill ~56 ~6 ~23 ~58 ~6 ~23 stonebrick 0  
fill ~56 ~6 ~87 ~58 ~6 ~87 stonebrick 0  
fill ~60 ~6 ~23 ~62 ~6 ~23 stonebrick 0  
fill ~60 ~6 ~87 ~62 ~6 ~87 stonebrick 0  
fill ~66 ~6 ~87 ~68 ~6 ~87 stonebrick 0  
fill ~70 ~6 ~42 ~70 ~10 ~42 stonebrick 0  
fill ~70 ~6 ~44 ~70 ~8 ~44 stonebrick 0  
fill ~70 ~6 ~66 ~70 ~8 ~66 stonebrick 0  
fill ~70 ~6 ~68 ~70 ~10 ~68 stonebrick 0  
fill ~71 ~6 ~19 ~71 ~7 ~19 obsidian 0  
fill ~71 ~6 ~20 ~71 ~19 ~20 stonebrick 0  
fill ~71 ~6 ~40 ~72 ~6 ~40 stonebrick 0 
setblock ~71 ~6 ~42 end_stone 0 
setblock ~71 ~6 ~44 end_stone 0 
setblock ~71 ~6 ~45 stonebrick 0  
fill ~71 ~6 ~46 ~71 ~13 ~46 lava 8  
fill ~71 ~6 ~47 ~71 ~7 ~47 stonebrick 0  
fill ~71 ~6 ~63 ~71 ~7 ~63 stonebrick 0  
fill ~71 ~6 ~64 ~71 ~13 ~64 lava 8 
setblock ~71 ~6 ~65 stonebrick 0 
setblock ~71 ~6 ~66 end_stone 0 
setblock ~71 ~6 ~68 end_stone 0  
fill ~71 ~6 ~70 ~72 ~6 ~70 stonebrick 0  
fill ~71 ~6 ~90 ~71 ~19 ~90 stonebrick 0  
fill ~71 ~6 ~91 ~71 ~7 ~91 obsidian 0  
fill ~72 ~6 ~26 ~75 ~6 ~26 stonebrick 0  
fill ~72 ~6 ~42 ~72 ~10 ~42 stonebrick 0  
fill ~72 ~6 ~44 ~72 ~8 ~44 stonebrick 0  
fill ~72 ~6 ~66 ~72 ~8 ~66 stonebrick 0  
fill ~72 ~6 ~68 ~72 ~10 ~68 stonebrick 0  
fill ~72 ~6 ~84 ~75 ~6 ~84 stonebrick 0  
fill ~73 ~6 ~19 ~73 ~7 ~19 obsidian 0  
fill ~73 ~6 ~20 ~73 ~11 ~20 stonebrick 0 
setblock ~73 ~6 ~32 obsidian 0 
setblock ~73 ~6 ~36 obsidian 0 
setblock ~73 ~6 ~42 obsidian 0 
setblock ~73 ~6 ~44 obsidian 0 
setblock ~73 ~6 ~66 obsidian 0 
setblock ~73 ~6 ~68 obsidian 0 
setblock ~73 ~6 ~70 obsidian 0  
fill ~73 ~6 ~74 ~73 ~6 ~75 obsidian 0  
fill ~73 ~6 ~90 ~73 ~11 ~90 stonebrick 0  
fill ~73 ~6 ~91 ~73 ~7 ~91 obsidian 0  
fill ~75 ~6 ~22 ~75 ~11 ~22 stonebrick 0  
fill ~75 ~6 ~24 ~75 ~19 ~24 stonebrick 0  
fill ~75 ~6 ~83 ~75 ~7 ~83 obsidian 0  
fill ~75 ~6 ~86 ~75 ~19 ~86 stonebrick 0  
fill ~75 ~6 ~88 ~75 ~11 ~88 stonebrick 0  
fill ~76 ~6 ~22 ~76 ~7 ~22 obsidian 0  
fill ~76 ~6 ~24 ~76 ~7 ~24 obsidian 0  
fill ~76 ~6 ~86 ~76 ~7 ~86 obsidian 0  
fill ~76 ~6 ~88 ~76 ~7 ~88 obsidian 0  
fill ~13 ~7 ~26 ~16 ~7 ~26 stonebrick 0  
fill ~13 ~7 ~83 ~13 ~8 ~83 obsidian 0  
fill ~13 ~7 ~84 ~16 ~7 ~84 stonebrick 0 
setblock ~15 ~7 ~31 obsidian 0  
fill ~15 ~7 ~37 ~15 ~7 ~39 obsidian 0 
setblock ~15 ~7 ~43 obsidian 0 
setblock ~15 ~7 ~67 obsidian 0  
fill ~15 ~7 ~75 ~15 ~7 ~77 obsidian 0  
fill ~16 ~7 ~40 ~17 ~7 ~40 stonebrick 0  
fill ~16 ~7 ~43 ~16 ~10 ~43 stonebrick 0  
fill ~16 ~7 ~49 ~16 ~9 ~49 obsidian 0  
fill ~16 ~7 ~61 ~16 ~9 ~61 obsidian 0  
fill ~16 ~7 ~67 ~16 ~10 ~67 stonebrick 0  
fill ~16 ~7 ~70 ~17 ~7 ~70 stonebrick 0 
setblock ~17 ~7 ~43 end_stone 0 
setblock ~17 ~7 ~44 stonebrick 0  
fill ~17 ~7 ~45 ~17 ~11 ~45 lava 8  
fill ~17 ~7 ~49 ~17 ~8 ~49 end_stone 0  
fill ~17 ~7 ~61 ~17 ~8 ~61 end_stone 0  
fill ~17 ~7 ~65 ~17 ~11 ~65 lava 8 
setblock ~17 ~7 ~66 stonebrick 0 
setblock ~17 ~7 ~67 end_stone 0  
fill ~18 ~7 ~43 ~18 ~10 ~43 stonebrick 0  
fill ~18 ~7 ~49 ~18 ~9 ~49 obsidian 0  
fill ~18 ~7 ~61 ~18 ~9 ~61 obsidian 0  
fill ~18 ~7 ~67 ~18 ~10 ~67 stonebrick 0  
fill ~19 ~7 ~87 ~20 ~7 ~87 bedrock 0  
fill ~20 ~7 ~23 ~23 ~7 ~23 stonebrick 0  
fill ~23 ~7 ~22 ~23 ~8 ~22 obsidian 0  
fill ~23 ~7 ~87 ~23 ~10 ~87 stonebrick 0  
fill ~23 ~7 ~88 ~23 ~8 ~88 obsidian 0  
fill ~25 ~7 ~22 ~25 ~8 ~22 obsidian 0  
fill ~25 ~7 ~23 ~28 ~7 ~23 stonebrick 0  
fill ~25 ~7 ~87 ~28 ~7 ~87 stonebrick 0  
fill ~25 ~7 ~88 ~25 ~8 ~88 obsidian 0  
fill ~30 ~7 ~23 ~33 ~7 ~23 stonebrick 0  
fill ~30 ~7 ~87 ~33 ~7 ~87 stonebrick 0  
fill ~33 ~7 ~22 ~33 ~8 ~22 obsidian 0  
fill ~33 ~7 ~88 ~33 ~8 ~88 obsidian 0  
fill ~35 ~7 ~22 ~35 ~8 ~22 obsidian 0  
fill ~35 ~7 ~23 ~38 ~7 ~23 stonebrick 0  
fill ~35 ~7 ~87 ~38 ~7 ~87 stonebrick 0  
fill ~35 ~7 ~88 ~35 ~8 ~88 obsidian 0  
fill ~40 ~7 ~23 ~43 ~7 ~23 stonebrick 0  
fill ~40 ~7 ~87 ~43 ~7 ~87 stonebrick 0  
fill ~43 ~7 ~22 ~43 ~8 ~22 obsidian 0  
fill ~43 ~7 ~88 ~43 ~8 ~88 obsidian 0  
fill ~45 ~7 ~22 ~45 ~8 ~22 obsidian 0  
fill ~45 ~7 ~23 ~48 ~7 ~23 stonebrick 0  
fill ~45 ~7 ~87 ~48 ~7 ~87 stonebrick 0  
fill ~45 ~7 ~88 ~45 ~8 ~88 obsidian 0  
fill ~50 ~7 ~23 ~53 ~7 ~23 stonebrick 0  
fill ~50 ~7 ~87 ~53 ~7 ~87 stonebrick 0  
fill ~53 ~7 ~22 ~53 ~8 ~22 obsidian 0  
fill ~53 ~7 ~88 ~53 ~8 ~88 obsidian 0  
fill ~55 ~7 ~22 ~55 ~8 ~22 obsidian 0  
fill ~55 ~7 ~23 ~58 ~7 ~23 stonebrick 0  
fill ~55 ~7 ~87 ~58 ~7 ~87 stonebrick 0  
fill ~55 ~7 ~88 ~55 ~8 ~88 obsidian 0  
fill ~60 ~7 ~23 ~63 ~7 ~23 stonebrick 0  
fill ~60 ~7 ~87 ~63 ~7 ~87 stonebrick 0  
fill ~63 ~7 ~22 ~63 ~8 ~22 obsidian 0  
fill ~63 ~7 ~88 ~63 ~8 ~88 obsidian 0  
fill ~65 ~7 ~22 ~65 ~8 ~22 obsidian 0  
fill ~65 ~7 ~23 ~65 ~10 ~23 stonebrick 0  
fill ~65 ~7 ~87 ~68 ~7 ~87 stonebrick 0  
fill ~65 ~7 ~88 ~65 ~8 ~88 obsidian 0  
fill ~70 ~7 ~43 ~70 ~10 ~43 stonebrick 0  
fill ~70 ~7 ~49 ~70 ~9 ~49 obsidian 0  
fill ~70 ~7 ~61 ~70 ~9 ~61 obsidian 0  
fill ~70 ~7 ~67 ~70 ~10 ~67 stonebrick 0  
fill ~71 ~7 ~40 ~72 ~7 ~40 stonebrick 0 
setblock ~71 ~7 ~43 end_stone 0 
setblock ~71 ~7 ~44 stonebrick 0  
fill ~71 ~7 ~45 ~71 ~11 ~45 lava 8  
fill ~71 ~7 ~49 ~71 ~8 ~49 end_stone 0  
fill ~71 ~7 ~61 ~71 ~8 ~61 end_stone 0  
fill ~71 ~7 ~65 ~71 ~11 ~65 lava 8 
setblock ~71 ~7 ~66 stonebrick 0 
setblock ~71 ~7 ~67 end_stone 0  
fill ~71 ~7 ~70 ~72 ~7 ~70 stonebrick 0  
fill ~72 ~7 ~26 ~75 ~7 ~26 stonebrick 0  
fill ~72 ~7 ~43 ~72 ~10 ~43 stonebrick 0  
fill ~72 ~7 ~49 ~72 ~9 ~49 obsidian 0  
fill ~72 ~7 ~61 ~72 ~9 ~61 obsidian 0  
fill ~72 ~7 ~67 ~72 ~10 ~67 stonebrick 0  
fill ~72 ~7 ~84 ~75 ~7 ~84 stonebrick 0  
fill ~73 ~7 ~33 ~73 ~7 ~35 obsidian 0 
setblock ~73 ~7 ~43 obsidian 0 
setblock ~73 ~7 ~67 obsidian 0  
fill ~73 ~7 ~71 ~73 ~7 ~73 obsidian 0 
setblock ~73 ~7 ~79 obsidian 0  
fill ~75 ~7 ~27 ~75 ~8 ~27 obsidian 0  
fill ~12 ~8 ~23 ~12 ~9 ~23 obsidian 0  
fill ~12 ~8 ~87 ~12 ~9 ~87 obsidian 0  
fill ~13 ~8 ~23 ~13 ~11 ~23 stonebrick 0  
fill ~13 ~8 ~26 ~16 ~8 ~26 stonebrick 0  
fill ~13 ~8 ~84 ~16 ~8 ~84 stonebrick 0  
fill ~13 ~8 ~87 ~13 ~11 ~87 stonebrick 0  
fill ~14 ~8 ~27 ~14 ~9 ~27 obsidian 0  
fill ~15 ~8 ~29 ~15 ~8 ~30 obsidian 0  
fill ~15 ~8 ~41 ~15 ~8 ~42 obsidian 0  
fill ~15 ~8 ~68 ~15 ~8 ~69 obsidian 0  
fill ~15 ~8 ~73 ~15 ~8 ~74 obsidian 0  
fill ~15 ~8 ~78 ~15 ~8 ~79 obsidian 0  
fill ~16 ~8 ~19 ~16 ~9 ~19 obsidian 0  
fill ~16 ~8 ~20 ~16 ~11 ~20 stonebrick 0  
fill ~16 ~8 ~40 ~17 ~8 ~40 stonebrick 0  
fill ~16 ~8 ~48 ~18 ~8 ~48 stonebrick 0  
fill ~16 ~8 ~62 ~18 ~8 ~62 stonebrick 0  
fill ~16 ~8 ~70 ~17 ~8 ~70 stonebrick 0  
fill ~16 ~8 ~90 ~16 ~11 ~90 stonebrick 0  
fill ~16 ~8 ~91 ~16 ~9 ~91 obsidian 0 
setblock ~17 ~8 ~6 nether_brick_fence 0  
fill ~17 ~8 ~43 ~17 ~9 ~43 stonebrick 0  
fill ~17 ~8 ~44 ~17 ~9 ~44 lava 8  
fill ~17 ~8 ~47 ~17 ~15 ~47 lava 8  
fill ~17 ~8 ~63 ~17 ~15 ~63 lava 8  
fill ~17 ~8 ~66 ~17 ~9 ~66 lava 8  
fill ~17 ~8 ~67 ~17 ~9 ~67 stonebrick 0 
setblock ~18 ~8 ~5 nether_brick_fence 0 
setblock ~18 ~8 ~6 glowstone 0 
setblock ~18 ~8 ~7 nether_brick_fence 0 
setblock ~19 ~8 ~6 nether_brick_fence 0  
fill ~19 ~8 ~87 ~20 ~8 ~87 bedrock 0  
fill ~20 ~8 ~23 ~23 ~8 ~23 stonebrick 0  
fill ~25 ~8 ~23 ~28 ~8 ~23 stonebrick 0  
fill ~25 ~8 ~87 ~28 ~8 ~87 stonebrick 0 
setblock ~28 ~8 ~44 nether_brick_fence 0 
setblock ~28 ~8 ~66 nether_brick_fence 0   

KittysCommands:  
setblock ~29 ~8 ~43 nether_brick_fence 0 
setblock ~29 ~8 ~44 glowstone 0 
setblock ~29 ~8 ~45 nether_brick_fence 0 
setblock ~29 ~8 ~65 nether_brick_fence 0 
setblock ~29 ~8 ~66 glowstone 0 
setblock ~29 ~8 ~67 nether_brick_fence 0  
fill ~30 ~8 ~23 ~33 ~8 ~23 stonebrick 0 
setblock ~30 ~8 ~44 nether_brick_fence 0 
setblock ~30 ~8 ~66 nether_brick_fence 0  
fill ~30 ~8 ~87 ~33 ~8 ~87 stonebrick 0  
fill ~35 ~8 ~23 ~38 ~8 ~23 stonebrick 0  
fill ~35 ~8 ~87 ~38 ~8 ~87 stonebrick 0 
setblock ~38 ~8 ~44 nether_brick_fence 0 
setblock ~38 ~8 ~66 nether_brick_fence 0 
setblock ~39 ~8 ~43 nether_brick_fence 0 
setblock ~39 ~8 ~44 glowstone 0 
setblock ~39 ~8 ~45 nether_brick_fence 0 
setblock ~39 ~8 ~65 nether_brick_fence 0 
setblock ~39 ~8 ~66 glowstone 0 
setblock ~39 ~8 ~67 nether_brick_fence 0  
fill ~40 ~8 ~23 ~43 ~8 ~23 stonebrick 0 
setblock ~40 ~8 ~44 nether_brick_fence 0 
setblock ~40 ~8 ~66 nether_brick_fence 0  
fill ~40 ~8 ~87 ~43 ~8 ~87 stonebrick 0  
fill ~45 ~8 ~23 ~48 ~8 ~23 stonebrick 0  
fill ~45 ~8 ~87 ~48 ~8 ~87 stonebrick 0 
setblock ~48 ~8 ~44 nether_brick_fence 0 
setblock ~48 ~8 ~66 nether_brick_fence 0 
setblock ~49 ~8 ~43 nether_brick_fence 0 
setblock ~49 ~8 ~44 glowstone 0 
setblock ~49 ~8 ~45 nether_brick_fence 0 
setblock ~49 ~8 ~65 nether_brick_fence 0 
setblock ~49 ~8 ~66 glowstone 0 
setblock ~49 ~8 ~67 nether_brick_fence 0  
fill ~50 ~8 ~23 ~53 ~8 ~23 stonebrick 0 
setblock ~50 ~8 ~44 nether_brick_fence 0 
setblock ~50 ~8 ~66 nether_brick_fence 0  
fill ~50 ~8 ~87 ~53 ~8 ~87 stonebrick 0  
fill ~55 ~8 ~23 ~58 ~8 ~23 stonebrick 0  
fill ~55 ~8 ~87 ~58 ~8 ~87 stonebrick 0 
setblock ~58 ~8 ~44 nether_brick_fence 0 
setblock ~58 ~8 ~66 nether_brick_fence 0 
setblock ~59 ~8 ~43 nether_brick_fence 0 
setblock ~59 ~8 ~44 glowstone 0 
setblock ~59 ~8 ~45 nether_brick_fence 0 
setblock ~59 ~8 ~65 nether_brick_fence 0 
setblock ~59 ~8 ~66 glowstone 0 
setblock ~59 ~8 ~67 nether_brick_fence 0  
fill ~60 ~8 ~23 ~63 ~8 ~23 stonebrick 0 
setblock ~60 ~8 ~44 nether_brick_fence 0 
setblock ~60 ~8 ~66 nether_brick_fence 0  
fill ~60 ~8 ~87 ~63 ~8 ~87 stonebrick 0  
fill ~65 ~8 ~87 ~68 ~8 ~87 stonebrick 0  
fill ~70 ~8 ~48 ~72 ~8 ~48 stonebrick 0  
fill ~70 ~8 ~62 ~72 ~8 ~62 stonebrick 0  
fill ~71 ~8 ~40 ~72 ~8 ~40 stonebrick 0  
fill ~71 ~8 ~43 ~71 ~9 ~43 stonebrick 0  
fill ~71 ~8 ~44 ~71 ~9 ~44 lava 8  
fill ~71 ~8 ~47 ~71 ~15 ~47 lava 8  
fill ~71 ~8 ~63 ~71 ~15 ~63 lava 8  
fill ~71 ~8 ~66 ~71 ~9 ~66 lava 8  
fill ~71 ~8 ~67 ~71 ~9 ~67 stonebrick 0  
fill ~71 ~8 ~70 ~72 ~8 ~70 stonebrick 0  
fill ~72 ~8 ~19 ~72 ~9 ~19 obsidian 0  
fill ~72 ~8 ~20 ~72 ~11 ~20 stonebrick 0  
fill ~72 ~8 ~26 ~75 ~8 ~26 stonebrick 0  
fill ~72 ~8 ~84 ~75 ~8 ~84 stonebrick 0  
fill ~72 ~8 ~90 ~72 ~11 ~90 stonebrick 0  
fill ~72 ~8 ~91 ~72 ~9 ~91 obsidian 0  
fill ~73 ~8 ~31 ~73 ~8 ~32 obsidian 0  
fill ~73 ~8 ~36 ~73 ~8 ~37 obsidian 0  
fill ~73 ~8 ~41 ~73 ~8 ~42 obsidian 0  
fill ~73 ~8 ~68 ~73 ~8 ~69 obsidian 0  
fill ~73 ~8 ~80 ~73 ~8 ~81 obsidian 0  
fill ~74 ~8 ~83 ~74 ~9 ~83 obsidian 0  
fill ~75 ~8 ~23 ~75 ~11 ~23 stonebrick 0  
fill ~75 ~8 ~87 ~75 ~11 ~87 stonebrick 0  
fill ~76 ~8 ~23 ~76 ~9 ~23 obsidian 0  
fill ~76 ~8 ~87 ~76 ~9 ~87 obsidian 0  
fill ~13 ~9 ~26 ~16 ~9 ~26 stonebrick 0  
fill ~13 ~9 ~84 ~16 ~9 ~84 stonebrick 0 
setblock ~14 ~9 ~83 obsidian 0 
setblock ~15 ~9 ~28 obsidian 0 
setblock ~15 ~9 ~40 obsidian 0 
setblock ~15 ~9 ~70 obsidian 0 
setblock ~15 ~9 ~72 obsidian 0 
setblock ~15 ~9 ~80 obsidian 0  
fill ~16 ~9 ~40 ~17 ~9 ~40 stonebrick 0  
fill ~16 ~9 ~48 ~16 ~8 ~48 stonebrick 0  
fill ~16 ~9 ~50 ~16 ~10 ~50 obsidian 0  
fill ~16 ~9 ~60 ~16 ~10 ~60 obsidian 0  
fill ~16 ~9 ~62 ~16 ~8 ~62 stonebrick 0  
fill ~16 ~9 ~70 ~17 ~9 ~70 stonebrick 0  
fill ~17 ~9 ~48 ~17 ~15 ~48 lava 8 
setblock ~17 ~9 ~49 stonebrick 0 
setblock ~17 ~9 ~50 end_stone 0 
setblock ~17 ~9 ~60 end_stone 0 
setblock ~17 ~9 ~61 stonebrick 0  
fill ~17 ~9 ~62 ~17 ~15 ~62 lava 8  
fill ~18 ~9 ~6 ~18 ~19 ~6 end_stone 0 
setblock ~18 ~9 ~48 stonebrick 0  
fill ~18 ~9 ~50 ~18 ~10 ~50 obsidian 0  
fill ~18 ~9 ~60 ~18 ~10 ~60 obsidian 0 
setblock ~18 ~9 ~62 stonebrick 0  
fill ~19 ~9 ~87 ~20 ~9 ~87 bedrock 0  
fill ~20 ~9 ~23 ~28 ~9 ~23 stonebrick 0  
fill ~24 ~9 ~22 ~24 ~10 ~22 obsidian 0  
fill ~24 ~9 ~87 ~28 ~9 ~87 stonebrick 0  
fill ~24 ~9 ~88 ~24 ~10 ~88 obsidian 0  
fill ~29 ~9 ~44 ~29 ~19 ~44 end_stone 0  
fill ~29 ~9 ~45 ~29 ~12 ~45 obsidian 0  
fill ~29 ~9 ~65 ~29 ~12 ~65 obsidian 0  
fill ~29 ~9 ~66 ~29 ~19 ~66 end_stone 0  
fill ~30 ~9 ~23 ~38 ~9 ~23 stonebrick 0  
fill ~30 ~9 ~87 ~38 ~9 ~87 stonebrick 0  
fill ~34 ~9 ~22 ~34 ~10 ~22 obsidian 0  
fill ~34 ~9 ~88 ~34 ~10 ~88 obsidian 0  
