fill ~1~2~0 ~1~16~0 minecraft:stonebrick 0
setblock ~2~2~0 minecraft:gold_block
fill ~2~3~0 ~2~16~0 minecraft:stonebrick 0
fill ~3~0~0 ~19~0~1 minecraft:stone 0
fill ~3~1~0 ~20~1~0 minecraft:stone 0
fill ~3~2~0 ~14~2~0 minecraft:stonebrick 0
setblock ~3~3~0 minecraft:gold_block
fill ~3~4~0 ~3~16~0 minecraft:stonebrick 0
fill ~4~3~0 ~13~3~0 minecraft:stonebrick 0
setblock ~4~4~0 minecraft:gold_block
fill ~4~5~0 ~4~16~0 minecraft:stonebrick 0
fill ~5~4~0 ~12~4~0 minecraft:stonebrick 0
setblock ~5~5~0 minecraft:gold_block
fill ~5~6~0 ~5~16~0 minecraft:stonebrick 0
fill ~6~5~0 ~11~5~0 minecraft:stonebrick 0
setblock ~6~6~0 minecraft:gold_block
fill ~6~7~0 ~6~16~0 minecraft:stonebrick 0
fill ~7~6~0 ~10~6~0 minecraft:stonebrick 0
setblock ~7~7~0 minecraft:gold_block
fill ~7~8~0 ~7~16~0 minecraft:stonebrick 0
fill ~8~7~0 ~9~7~0 minecraft:stonebrick 0
fill ~8~8~0 ~9~8~0 minecraft:gold_block
fill ~8~9~0 ~33~10~4 minecraft:stonebrick 0
fill ~8~11~0 ~68~11~0 minecraft:stonebrick 0
fill ~8~12~0 ~67~12~1 minecraft:stonebrick 0
fill ~8~13~0 ~67~15~0 minecraft:stonebrick 0
fill ~8~16~0 ~19~16~0 minecraft:stonebrick 0
setblock ~10~7~0 minecraft:gold_block
fill ~10~8~0 ~14~8~0 minecraft:stonebrick 0
setblock ~11~6~0 minecraft:gold_block
fill ~11~7~0 ~20~7~0 minecraft:stonebrick 0
setblock ~12~5~0 minecraft:gold_block
fill ~12~6~0 ~19~6~0 minecraft:stonebrick 0
setblock ~13~4~0 minecraft:gold_block
fill ~13~5~0 ~18~5~0 minecraft:stonebrick 0
setblock ~14~3~0 minecraft:gold_block
fill ~14~4~0 ~17~4~0 minecraft:stonebrick 0
fill ~15~2~0 ~16~2~0 minecraft:gold_block
fill ~15~3~0 ~16~3~0 minecraft:stonebrick 0
setblock ~15~8~0 minecraft:glowstone
fill ~16~8~0 ~21~8~0 minecraft:stonebrick 0
fill ~17~2~0 ~28~2~0 minecraft:stonebrick 0
setblock ~17~3~0 minecraft:gold_block
fill ~18~3~0 ~27~3~0 minecraft:stonebrick 0
setblock ~18~4~0 minecraft:gold_block
fill ~19~4~0 ~26~4~0 minecraft:stonebrick 0
setblock ~19~5~0 minecraft:gold_block
fill ~20~0~0 ~23~0~0 minecraft:stone 3
fill ~20~5~0 ~25~5~0 minecraft:stonebrick 0
setblock ~20~6~0 minecraft:gold_block
setblock ~20~16~0 minecraft:glowstone
fill ~21~1~0 ~22~1~0 minecraft:stone 3
fill ~21~6~0 ~24~6~0 minecraft:stonebrick 0
setblock ~21~7~0 minecraft:gold_block
setblock ~21~16~0 minecraft:stonebrick 0
fill ~22~7~0 ~23~7~0 minecraft:stonebrick 0
fill ~22~8~0 ~23~8~0 minecraft:gold_block
setblock ~22~16~0 minecraft:glowstone
fill ~23~1~0 ~32~1~0 minecraft:stone 0
setblock ~23~16~0 minecraft:stonebrick 0
fill ~24~0~0 ~33~0~3 minecraft:stone 0
setblock ~24~7~0 minecraft:gold_block
fill ~24~8~0 ~33~8~0 minecraft:stonebrick 0
setblock ~24~16~0 minecraft:glowstone
setblock ~25~6~0 minecraft:gold_block
fill ~25~7~0 ~33~7~0 minecraft:stonebrick 0
fill ~25~16~0 ~44~16~0 minecraft:stonebrick 0
setblock ~26~5~0 minecraft:gold_block
fill ~26~6~0 ~45~6~0 minecraft:stonebrick 0
setblock ~27~4~0 minecraft:gold_block
fill ~27~5~0 ~32~5~0 minecraft:stonebrick 0
setblock ~28~3~0 minecraft:gold_block
fill ~28~4~0 ~31~4~0 minecraft:stonebrick 0
fill ~29~2~0 ~30~2~0 minecraft:gold_block
fill ~29~3~0 ~30~3~0 minecraft:stonebrick 0
fill ~31~2~0 ~32~2~0 minecraft:stonebrick 0
setblock ~31~3~0 minecraft:gold_block
setblock ~32~3~0 minecraft:stonebrick 0
setblock ~32~4~0 minecraft:gold_block
setblock ~33~1~0 minecraft:wool 15
fill ~33~5~0 ~36~5~0 minecraft:stone_block_slab 13
fill ~34~0~0 ~37~0~0 minecraft:stone 1
fill ~34~1~0 ~35~1~1 minecraft:wool 14
fill ~34~8~0 ~34~9~0 minecraft:wall_sign 5
fill ~34~10~0 ~68~10~0 minecraft:stonebrick 0
fill ~35~8~0 ~35~9~0 minecraft:wall_sign 4
setblock ~36~1~0 minecraft:wool 15
fill ~36~7~0 ~46~9~0 minecraft:stonebrick 0
setblock ~37~1~0 minecraft:stone 1
fill ~37~2~0 ~40~2~0 minecraft:stonebrick 0
fill ~37~3~0 ~39~3~0 minecraft:stonebrick 0
fill ~37~4~0 ~38~4~0 minecraft:stonebrick 0
setblock ~37~5~0 minecraft:stonebrick 0
fill ~38~0~0 ~41~1~0 minecraft:stone 0
setblock ~38~5~0 minecraft:gold_block
setblock ~39~4~0 minecraft:gold_block
fill ~39~5~0 ~44~5~0 minecraft:stonebrick 0
setblock ~40~3~0 minecraft:gold_block
fill ~40~4~0 ~43~4~0 minecraft:stonebrick 0
fill ~41~2~0 ~42~2~0 minecraft:gold_block
fill ~41~3~0 ~42~3~0 minecraft:stonebrick 0
fill ~42~0~0 ~49~0~2 minecraft:stone 5
setblock ~42~1~0 minecraft:stone 0
fill ~43~1~0 ~49~1~0 minecraft:stone 5
fill ~43~2~0 ~54~2~0 minecraft:stonebrick 0
setblock ~43~3~0 minecraft:gold_block
fill ~44~3~0 ~53~3~0 minecraft:stonebrick 0
setblock ~44~4~0 minecraft:gold_block
fill ~45~4~0 ~52~4~0 minecraft:stonebrick 0
setblock ~45~5~0 minecraft:gold_block
setblock ~45~16~0 minecraft:glowstone
fill ~46~5~0 ~51~5~0 minecraft:stonebrick 0
setblock ~46~6~0 minecraft:gold_block
setblock ~46~16~0 minecraft:stonebrick 0
fill ~47~6~0 ~50~6~0 minecraft:stonebrick 0
setblock ~47~7~0 minecraft:gold_block
fill ~47~8~0 ~47~9~0 minecraft:stonebrick 0
setblock ~47~16~0 minecraft:glowstone
fill ~48~7~0 ~49~7~0 minecraft:stonebrick 0
fill ~48~8~0 ~49~8~0 minecraft:gold_block
fill ~48~9~0 ~67~9~10 minecraft:stonebrick 0
fill ~48~16~0 ~67~16~0 minecraft:stonebrick 0
fill ~50~0~0 ~53~0~2 minecraft:stone 0
fill ~50~1~0 ~52~1~0 minecraft:stone 0
setblock ~50~7~0 minecraft:gold_block
fill ~50~8~0 ~53~8~0 minecraft:stonebrick 0
setblock ~51~6~0 minecraft:gold_block
fill ~51~7~0 ~60~7~0 minecraft:stonebrick 0
setblock ~52~5~0 minecraft:gold_block
fill ~52~6~0 ~59~6~0 minecraft:stonebrick 0
fill ~53~1~0 ~56~1~0 minecraft:stone 5
setblock ~53~4~0 minecraft:gold_block
fill ~53~5~0 ~58~5~0 minecraft:stonebrick 0
fill ~54~0~0 ~55~0~0 minecraft:stone 5
setblock ~54~3~0 minecraft:gold_block
fill ~54~4~0 ~57~4~0 minecraft:stonebrick 0
setblock ~54~8~0 minecraft:glowstone
fill ~55~2~0 ~56~2~0 minecraft:gold_block
fill ~55~3~0 ~56~3~0 minecraft:stonebrick 0
fill ~55~8~0 ~61~8~0 minecraft:stonebrick 0
fill ~56~0~0 ~59~0~4 minecraft:gravel
fill ~57~1~0 ~58~1~0 minecraft:gravel
fill ~57~2~0 ~67~2~0 minecraft:stonebrick 0
setblock ~57~3~0 minecraft:gold_block
fill ~58~3~0 ~68~3~0 minecraft:stonebrick 0
setblock ~58~4~0 minecraft:gold_block
fill ~59~1~0 ~68~1~0 minecraft:stone 0
fill ~59~4~0 ~66~4~0 minecraft:stonebrick 0
setblock ~59~5~0 minecraft:gold_block
fill ~60~0~0 ~63~0~0 minecraft:coal_ore
fill ~60~5~0 ~65~5~0 minecraft:stonebrick 0
setblock ~60~6~0 minecraft:gold_block
fill ~61~6~0 ~64~6~0 minecraft:stonebrick 0
setblock ~61~7~0 minecraft:gold_block
fill ~62~7~0 ~63~7~0 minecraft:stonebrick 0
fill ~62~8~0 ~63~8~0 minecraft:gold_block
fill ~64~0~0 ~68~0~0 minecraft:stone 0
setblock ~64~7~0 minecraft:gold_block
fill ~64~8~0 ~66~8~0 minecraft:stonebrick 0
setblock ~65~6~0 minecraft:gold_block
fill ~65~7~0 ~67~7~0 minecraft:stonebrick 0
setblock ~66~5~0 minecraft:gold_block
fill ~66~6~0 ~67~6~0 minecraft:stonebrick 0
setblock ~67~4~0 minecraft:gold_block
setblock ~67~5~0 minecraft:stonebrick 0
setblock ~67~8~0 minecraft:glowstone
fill ~68~4~0 ~68~9~0 minecraft:stone 0
setblock ~1~2~1 minecraft:gold_block
fill ~1~3~1 ~1~7~1 minecraft:stonebrick 0
setblock ~1~8~1 minecraft:glowstone
fill ~1~9~1 ~7~9~66 minecraft:stonebrick 0
fill ~1~10~1 ~1~15~66 minecraft:stonebrick 0
fill ~1~16~1 ~7~16~1 minecraft:stonebrick 0
setblock ~2~1~1 minecraft:glowstone
fill ~2~10~1 ~5~10~1 minecraft:stone_block_slab 5
fill ~2~11~1 ~65~11~2 minecraft:stonebrick 0
fill ~2~12~1 ~7~12~2 minecraft:stonebrick 0
fill ~2~13~1 ~7~15~1 minecraft:stonebrick 0
fill ~2~17~1 ~54~17~2 minecraft:stonebrick 0
fill ~3~1~1 ~14~1~1 minecraft:stonebrick 0
fill ~6~10~1 ~7~10~13 minecraft:stonebrick 0
fill ~8~13~1 ~15~13~1 minecraft:stone_block_slab 5
setblock ~15~1~1 minecraft:glowstone
fill ~16~1~1 ~31~1~10 minecraft:stonebrick 0
fill ~16~13~1 ~28~13~1 minecraft:dark_oak_stairs 3
fill ~20~0~1 ~20~0~4 minecraft:stone 0
fill ~21~0~1 ~22~0~1 minecraft:stone 3
fill ~23~0~1 ~23~0~3 minecraft:stone 0
fill ~29~13~1 ~40~13~1 minecraft:stone_block_slab 5
fill ~32~1~1 ~32~1~2 minecraft:wool 15
fill ~32~6~1 ~36~6~2 minecraft:stonebrick 0
fill ~32~8~1 ~33~8~2 minecraft:stonebrick 0
setblock ~33~1~1 minecraft:wool 14
setblock ~33~7~1 minecraft:glowstone
fill ~34~0~1 ~34~0~7 minecraft:stone 0
fill ~34~7~1 ~35~7~1 minecraft:stone_block_slab 5
fill ~35~0~1 ~38~0~1 minecraft:stone 1
setblock ~36~1~1 minecraft:wool 14
setblock ~36~7~1 minecraft:glowstone
fill ~36~8~1 ~37~10~2 minecraft:stonebrick 0
fill ~37~1~1 ~37~1~2 minecraft:wool 15
setblock ~37~6~1 minecraft:gold_block
fill ~38~1~1 ~53~1~10 minecraft:stonebrick 0
fill ~38~9~1 ~47~9~10 minecraft:stonebrick 0
fill ~38~10~1 ~64~10~1 minecraft:stonebrick 0
fill ~39~0~1 ~40~0~1 minecraft:stone 0
fill ~41~0~1 ~41~0~3 minecraft:stone 5
fill ~41~13~1 ~53~13~1 minecraft:dark_oak_stairs 3
fill ~54~0~1 ~54~0~3 minecraft:stone 0
setblock ~54~1~1 minecraft:glowstone
fill ~54~13~1 ~61~13~1 minecraft:stone_block_slab 5
setblock ~55~0~1 minecraft:stone 5
fill ~55~1~1 ~66~1~1 minecraft:stonebrick 0
setblock ~55~17~1 minecraft:glowstone
fill ~56~17~1 ~67~17~37 minecraft:stonebrick 0
fill ~60~0~1 ~60~0~24 minecraft:stone 0
fill ~61~0~1 ~64~0~1 minecraft:coal_ore
fill ~62~13~1 ~68~16~1 minecraft:stonebrick 0
fill ~65~0~1 ~68~0~25 minecraft:stone 0
fill ~65~10~1 ~67~10~2 minecraft:stone_block_slab 5
setblock ~67~1~1 minecraft:glowstone
fill ~67~11~1 ~68~11~66 minecraft:stonebrick 0
fill ~68~1~1 ~68~1~3 minecraft:stone 0
setblock ~68~2~1 minecraft:stonebrick 0
setblock ~68~3~1 minecraft:gold_block
fill ~68~4~1 ~68~7~4 minecraft:stonebrick 0
setblock ~68~8~1 minecraft:glowstone
fill ~68~9~1 ~68~10~66 minecraft:stonebrick 0
fill ~68~12~1 ~68~12~66 minecraft:stonebrick 0
fill ~1~0~2 ~13~0~3 minecraft:stone 0
fill ~1~1~2 ~1~1~36 minecraft:stone 0
fill ~1~2~2 ~1~2~13 minecraft:stonebrick 0
setblock ~1~3~2 minecraft:gold_block
fill ~1~4~2 ~1~8~2 minecraft:stonebrick 0
fill ~1~16~2 ~5~16~2 minecraft:stonebrick 0
fill ~2~1~2 ~2~1~13 minecraft:stonebrick 0
fill ~2~10~2 ~5~10~60 minecraft:stonebrick 0
fill ~2~13~2 ~5~15~2 minecraft:stonebrick 0
setblock ~3~1~2 minecraft:glowstone
fill ~4~1~2 ~15~1~2 minecraft:stonebrick 0
setblock ~6~13~2 minecraft:stone_block_slab 5
fill ~8~12~2 ~14~12~2 minecraft:stonebrick 0
fill ~14~0~2 ~15~0~6 minecraft:stone 5
setblock ~15~12~2 minecraft:glowstone
fill ~16~0~2 ~19~0~2 minecraft:stone 0
fill ~16~12~2 ~33~12~2 minecraft:stonebrick 0
fill ~21~0~2 ~22~0~3 minecraft:stone 0
setblock ~29~2~2 minecraft:standing_sign 12
fill ~32~7~2 ~33~7~2 minecraft:stonebrick 0
fill ~33~1~2 ~36~1~2 minecraft:wool 15
fill ~33~3~2 ~36~4~2 minecraft:wall_sign 2
fill ~34~7~2 ~35~7~2 minecraft:double_stone_block_slab 5
fill ~34~12~2 ~35~12~2 minecraft:glowstone
fill ~35~0~2 ~35~0~12 minecraft:stone 0
fill ~36~0~2 ~38~0~2 minecraft:stone 1
fill ~36~7~2 ~37~7~2 minecraft:stonebrick 0
fill ~36~12~2 ~53~12~2 minecraft:stonebrick 0
setblock ~37~6~2 minecraft:stonebrick 0
fill ~38~10~2 ~62~10~5 minecraft:stonebrick 0
fill ~39~0~2 ~39~0~7 minecraft:stone 0
setblock ~40~0~2 minecraft:stone 5
setblock ~40~2~2 minecraft:standing_sign 4
fill ~54~1~2 ~65~1~2 minecraft:stonebrick 0
setblock ~54~12~2 minecraft:glowstone
setblock ~55~0~2 minecraft:stone 0
fill ~55~12~2 ~67~12~2 minecraft:stonebrick 0
fill ~55~17~2 ~55~17~12 minecraft:stonebrick 0
fill ~61~0~2 ~64~0~24 minecraft:stone 0
fill ~63~10~2 ~63~10~3 minecraft:double_stone_block_slab 5
setblock ~63~13~2 minecraft:stone_block_slab 5
setblock ~64~10~2 minecraft:stonebrick 0
fill ~64~13~2 ~68~16~2 minecraft:stonebrick 0
setblock ~66~1~2 minecraft:glowstone
fill ~66~11~2 ~66~11~67 minecraft:stonebrick 0
fill ~67~1~2 ~67~1~13 minecraft:stonebrick 0
fill ~68~2~2 ~68~2~3 minecraft:gold_block
fill ~68~3~2 ~68~3~3 minecraft:stonebrick 0
fill ~68~8~2 ~68~8~8 minecraft:stonebrick 0
fill ~1~3~3 ~1~3~12 minecraft:stonebrick 0
setblock ~1~4~3 minecraft:gold_block
fill ~1~5~3 ~1~8~3 minecraft:stonebrick 0
fill ~1~16~3 ~3~16~4 minecraft:stonebrick 0
fill ~2~11~3 ~33~11~3 minecraft:stonebrick 0
fill ~2~12~3 ~6~12~3 minecraft:stonebrick 0
fill ~2~13~3 ~3~15~4 minecraft:stonebrick 0
fill ~2~17~3 ~3~17~66 minecraft:stonebrick 0
fill ~3~1~3 ~3~1~64 minecraft:stonebrick 0
setblock ~4~1~3 minecraft:glowstone
fill ~4~13~3 ~4~17~3 minecraft:glowstone
fill ~5~1~3 ~15~1~3 minecraft:stonebrick 0
setblock ~5~13~3 minecraft:stone_block_slab 5
fill ~5~17~3 ~54~17~12 minecraft:stonebrick 0
fill ~7~12~3 ~15~12~3 minecraft:stone_block_slab 5
fill ~16~0~3 ~16~0~6 minecraft:stone 0
fill ~16~12~3 ~28~12~3 minecraft:dark_oak_stairs 3
fill ~17~0~3 ~18~0~4 minecraft:coal_ore
setblock ~19~0~3 minecraft:stone 0
fill ~29~12~3 ~40~12~3 minecraft:stone_block_slab 5
fill ~32~1~3 ~37~1~10 minecraft:stonebrick 0
setblock ~32~2~3 minecraft:glowstone
fill ~32~3~3 ~32~4~3 minecraft:log 1
setblock ~32~5~3 minecraft:glowstone
fill ~32~6~3 ~32~8~3 minecraft:log 1
fill ~33~2~3 ~36~4~3 minecraft:planks 0
fill ~33~5~3 ~36~5~3 minecraft:log 1
fill ~33~6~3 ~36~7~3 minecraft:stonebrick 0
setblock ~33~8~3 minecraft:glowstone
fill ~34~8~3 ~35~8~3 minecraft:stone_block_slab 5
fill ~36~0~3 ~36~0~12 minecraft:stone 0
setblock ~36~8~3 minecraft:glowstone
fill ~36~9~3 ~37~11~4 minecraft:stonebrick 0
fill ~37~0~3 ~38~0~3 minecraft:stone 1
setblock ~37~2~3 minecraft:glowstone
fill ~37~3~3 ~37~4~3 minecraft:log 1
setblock ~37~5~3 minecraft:glowstone
fill ~37~6~3 ~37~8~3 minecraft:log 1
fill ~38~11~3 ~65~11~3 minecraft:stonebrick 0
fill ~40~0~3 ~40~0~7 minecraft:stone 0
fill ~41~12~3 ~53~12~3 minecraft:dark_oak_stairs 3
fill ~42~0~3 ~46~0~3 minecraft:stone 5
fill ~47~0~3 ~50~0~3 minecraft:stone 3
fill ~51~0~3 ~53~0~3 minecraft:stone 0
fill ~54~1~3 ~64~1~3 minecraft:stonebrick 0
fill ~54~12~3 ~62~12~3 minecraft:stone_block_slab 5
fill ~55~0~3 ~55~0~4 minecraft:stone 1
fill ~63~12~3 ~67~12~3 minecraft:stonebrick 0
setblock ~64~10~3 minecraft:double_stone_block_slab 5
setblock ~64~13~3 minecraft:stone_block_slab 5
setblock ~65~1~3 minecraft:glowstone
fill ~65~10~3 ~65~10~64 minecraft:stonebrick 0
fill ~65~13~3 ~65~16~3 minecraft:glowstone
fill ~66~1~3 ~66~1~64 minecraft:stonebrick 0
fill ~66~10~3 ~67~10~3 minecraft:stone_block_slab 5
fill ~66~13~3 ~68~16~4 minecraft:stonebrick 0
fill ~1~0~4 ~12~0~4 minecraft:stone 0
fill ~1~4~4 ~1~4~11 minecraft:stonebrick 0
setblock ~1~5~4 minecraft:gold_block
fill ~1~6~4 ~1~8~4 minecraft:stonebrick 0
fill ~2~11~4 ~14~11~4 minecraft:stonebrick 0
fill ~2~12~4 ~5~12~4 minecraft:stonebrick 0
fill ~4~1~4 ~4~1~63 minecraft:stonebrick 0
setblock ~4~13~4 minecraft:stone_block_slab 5
fill ~4~17~4 ~4~17~63 minecraft:stonebrick 0
setblock ~5~1~4 minecraft:glowstone
fill ~6~1~4 ~15~1~4 minecraft:stonebrick 0
setblock ~6~12~4 minecraft:stone_block_slab 5
fill ~13~0~4 ~13~0~8 minecraft:stone 5
setblock ~15~11~4 minecraft:glowstone
fill ~16~11~4 ~33~11~4 minecraft:stonebrick 0
fill ~19~0~4 ~19~0~6 minecraft:coal_ore
fill ~21~0~4 ~21~0~7 minecraft:stone 0
fill ~22~0~4 ~23~0~4 minecraft:gravel
setblock ~22~6~4 minecraft:netherrack
setblock ~22~7~4 minecraft:fire 15
fill ~24~0~4 ~27~0~4 minecraft:stone 0
fill ~28~0~4 ~29~0~7 minecraft:stone 3
fill ~30~0~4 ~33~0~4 minecraft:stone 0
fill ~32~2~4 ~37~5~4 minecraft:stonebrick 0
fill ~32~6~4 ~33~7~10 minecraft:stonebrick 0
fill ~32~8~4 ~37~8~6 minecraft:stonebrick 0
fill ~34~7~4 ~37~7~4 minecraft:stonebrick 0
fill ~36~6~4 ~37~6~10 minecraft:stonebrick 0
fill ~37~0~4 ~38~0~13 minecraft:stone 0
fill ~38~11~4 ~53~11~4 minecraft:stonebrick 0
fill ~41~0~4 ~46~0~4 minecraft:stone 0
setblock ~46~6~4 minecraft:netherrack
setblock ~46~7~4 minecraft:fire 15
fill ~47~0~4 ~48~0~4 minecraft:coal_ore
fill ~49~0~4 ~50~0~4 minecraft:stone 3
fill ~51~0~4 ~52~0~4 minecraft:stone 0
fill ~53~0~4 ~53~0~7 minecraft:stone 1
setblock ~54~0~4 minecraft:iron_ore
fill ~54~1~4 ~63~1~4 minecraft:stonebrick 0
setblock ~54~11~4 minecraft:glowstone
fill ~55~11~4 ~65~11~4 minecraft:stonebrick 0
fill ~63~10~4 ~64~10~63 minecraft:stonebrick 0
setblock ~63~12~4 minecraft:stone_block_slab 5
setblock ~64~1~4 minecraft:glowstone
fill ~64~12~4 ~67~12~4 minecraft:stonebrick 0
fill ~65~1~4 ~65~1~63 minecraft:stonebrick 0
setblock ~65~13~4 minecraft:stone_block_slab 5
fill ~66~10~4 ~66~10~64 minecraft:stonebrick 0
setblock ~67~10~4 minecraft:stone_block_slab 5
fill ~68~1~4 ~68~1~8 minecraft:stone 1
fill ~68~2~4 ~68~2~15 minecraft:stonebrick 0
setblock ~68~3~4 minecraft:gold_block
fill ~1~0~5 ~11~0~6 minecraft:stone 0
fill ~1~5~5 ~1~5~10 minecraft:stonebrick 0
setblock ~1~6~5 minecraft:gold_block
fill ~1~7~5 ~1~8~5 minecraft:stonebrick 0
fill ~1~16~5 ~2~16~6 minecraft:stonebrick 0
fill ~2~11~5 ~7~11~5 minecraft:stonebrick 0
fill ~2~12~5 ~4~12~5 minecraft:stonebrick 0
fill ~2~13~5 ~2~15~6 minecraft:stonebrick 0
setblock ~3~13~5 minecraft:stone_block_slab 5
fill ~5~1~5 ~5~1~62 minecraft:stonebrick 0
setblock ~5~12~5 minecraft:stone_block_slab 5
setblock ~6~1~5 minecraft:glowstone
fill ~7~1~5 ~15~1~5 minecraft:stonebrick 0
fill ~8~9~5 ~32~9~10 minecraft:stonebrick 0
fill ~8~10~5 ~33~10~5 minecraft:stonebrick 0
fill ~8~11~5 ~15~11~5 minecraft:stone_block_slab 5
fill ~12~0~5 ~12~0~7 minecraft:stone 5
setblock ~15~2~5 minecraft:standing_sign 4
fill ~16~11~5 ~28~11~5 minecraft:dark_oak_stairs 3
fill ~17~0~5 ~17~0~6 minecraft:stone 0
setblock ~18~0~5 minecraft:coal_ore
fill ~20~0~5 ~20~0~6 minecraft:coal_ore
setblock ~22~0~5 minecraft:gravel
fill ~22~6~5 ~22~8~5 minecraft:nether_brick_fence
fill ~23~0~5 ~25~0~9 minecraft:stone 0
fill ~26~0~5 ~27~0~6 minecraft:stone 3
fill ~29~11~5 ~33~11~5 minecraft:stone_block_slab 5
fill ~30~0~5 ~31~0~6 minecraft:stone 3
fill ~32~0~5 ~33~0~5 minecraft:stone 0
fill ~32~2~5 ~33~5~8 minecraft:stonebrick 0
setblock ~33~9~5 minecraft:glowstone
fill ~34~9~5 ~35~9~5 minecraft:stone_block_slab 5
fill ~35~2~5 ~37~2~5 minecraft:stonebrick 0
fill ~36~3~5 ~37~5~10 minecraft:stonebrick 0
fill ~36~7~5 ~37~7~10 minecraft:stonebrick 0
setblock ~36~9~5 minecraft:glowstone
fill ~36~10~5 ~37~10~6 minecraft:stonebrick 0
fill ~36~11~5 ~40~11~5 minecraft:stone_block_slab 5
fill ~37~9~5 ~37~9~10 minecraft:stonebrick 0
fill ~41~0~5 ~45~0~19 minecraft:stone 0
fill ~41~11~5 ~53~11~5 minecraft:dark_oak_stairs 3
fill ~46~0~5 ~47~0~6 minecraft:coal_ore
fill ~46~6~5 ~46~8~5 minecraft:nether_brick_fence
fill ~48~0~5 ~48~0~20 minecraft:stone 0
setblock ~49~0~5 minecraft:stone 3
setblock ~50~0~5 minecraft:stone 0
fill ~51~0~5 ~52~0~8 minecraft:stone 1
fill ~54~0~5 ~54~0~8 minecraft:stone 1
fill ~54~1~5 ~62~1~5 minecraft:stonebrick 0
setblock ~54~2~5 minecraft:standing_sign 12
fill ~54~11~5 ~61~11~5 minecraft:stone_block_slab 5
setblock ~55~0~5 minecraft:iron_ore
fill ~56~0~5 ~58~0~5 minecraft:gravel
fill ~59~0~5 ~59~0~24 minecraft:stone 0
fill ~62~11~5 ~65~11~5 minecraft:stonebrick 0
setblock ~63~1~5 minecraft:glowstone
fill ~64~1~5 ~64~1~62 minecraft:stonebrick 0
setblock ~64~12~5 minecraft:stone_block_slab 5
fill ~65~12~5 ~67~12~5 minecraft:stonebrick 0
setblock ~66~13~5 minecraft:stone_block_slab 5
fill ~67~10~5 ~67~10~64 minecraft:stonebrick 0
fill ~67~13~5 ~68~16~6 minecraft:stonebrick 0
fill ~68~3~5 ~68~3~14 minecraft:stonebrick 0
setblock ~68~4~5 minecraft:gold_block
fill ~68~5~5 ~68~7~5 minecraft:stonebrick 0
fill ~1~6~6 ~1~6~9 minecraft:stonebrick 0
setblock ~1~7~6 minecraft:gold_block
setblock ~1~8~6 minecraft:stonebrick 0
fill ~2~11~6 ~6~11~6 minecraft:stonebrick 0
fill ~2~12~6 ~3~12~13 minecraft:stonebrick 0
fill ~4~12~6 ~4~12~14 minecraft:stone_block_slab 5
fill ~6~1~6 ~6~1~61 minecraft:stonebrick 0
setblock ~7~1~6 minecraft:glowstone
setblock ~7~11~6 minecraft:stone_block_slab 5
fill ~8~1~6 ~15~1~6 minecraft:stonebrick 0
fill ~8~10~6 ~14~10~6 minecraft:stonebrick 0
setblock ~15~10~6 minecraft:glowstone
fill ~16~10~6 ~33~10~6 minecraft:stonebrick 0
setblock ~18~0~6 minecraft:stone 0
fill ~22~0~6 ~22~0~8 minecraft:stone 0
setblock ~22~6~6 minecraft:netherrack
setblock ~22~7~6 minecraft:fire 15
fill ~32~0~6 ~33~0~11 minecraft:stone 1
fill ~33~9~6 ~36~9~10 minecraft:stonebrick 0
fill ~36~2~6 ~37~2~8 minecraft:stonebrick 0
fill ~38~10~6 ~53~10~6 minecraft:stonebrick 0
setblock ~46~6~6 minecraft:netherrack
setblock ~46~7~6 minecraft:fire 15
fill ~49~0~6 ~49~0~23 minecraft:stone 0
fill ~50~0~6 ~50~0~7 minecraft:stone 1
fill ~54~1~6 ~61~1~6 minecraft:stonebrick 0
setblock ~54~10~6 minecraft:glowstone
fill ~55~0~6 ~56~0~7 minecraft:stone 1
fill ~55~10~6 ~62~10~6 minecraft:stonebrick 0
fill ~57~0~6 ~58~0~6 minecraft:gravel
setblock ~62~1~6 minecraft:glowstone
setblock ~62~11~6 minecraft:stone_block_slab 5
fill ~63~1~6 ~63~1~61 minecraft:stonebrick 0
fill ~63~11~6 ~65~11~6 minecraft:stonebrick 0
fill ~65~12~6 ~65~12~14 minecraft:stone_block_slab 5
fill ~66~12~6 ~67~12~13 minecraft:stonebrick 0
fill ~68~4~6 ~68~4~13 minecraft:stonebrick 0
setblock ~68~5~6 minecraft:gold_block
fill ~68~6~6 ~68~7~6 minecraft:stonebrick 0
fill ~1~0~7 ~5~0~27 minecraft:stone 0
fill ~1~7~7 ~1~7~8 minecraft:stonebrick 0
fill ~1~8~7 ~1~8~8 minecraft:gold_block
fill ~1~16~7 ~1~16~18 minecraft:stonebrick 0
fill ~2~11~7 ~5~11~13 minecraft:stonebrick 0
fill ~2~13~7 ~2~13~14 minecraft:stone_block_slab 5
setblock ~6~0~7 minecraft:iron_ore
fill ~6~11~7 ~6~11~14 minecraft:stone_block_slab 5
fill ~7~0~7 ~11~0~15 minecraft:stone 0
fill ~7~1~7 ~7~1~60 minecraft:stonebrick 0
setblock ~8~1~7 minecraft:glowstone
fill ~8~10~7 ~9~10~7 minecraft:double_stone_block_slab 5
fill ~9~1~7 ~15~1~7 minecraft:stonebrick 0
fill ~10~10~7 ~59~10~9 minecraft:stone_block_slab 5
setblock ~14~0~7 minecraft:stone 5
fill ~15~0~7 ~19~0~9 minecraft:dirt 0
setblock ~20~0~7 minecraft:stone 0
fill ~26~0~7 ~27~0~15 minecraft:stone 0
setblock ~30~0~7 minecraft:stone 0
fill ~31~0~7 ~31~0~14 minecraft:stone 1
fill ~32~8~7 ~33~8~8 minecraft:stonebrick 0
fill ~36~8~7 ~37~8~8 minecraft:stonebrick 0
fill ~46~0~7 ~47~0~15 minecraft:stone 0
fill ~54~1~7 ~60~1~7 minecraft:stonebrick 0
fill ~57~0~7 ~58~0~24 minecraft:stone 0
fill ~60~10~7 ~61~10~7 minecraft:double_stone_block_slab 5
setblock ~61~1~7 minecraft:glowstone
fill ~62~1~7 ~62~1~60 minecraft:stonebrick 0
fill ~62~10~7 ~62~10~13 minecraft:stonebrick 0
fill ~63~11~7 ~63~11~14 minecraft:stone_block_slab 5
fill ~64~11~7 ~65~11~13 minecraft:stonebrick 0
fill ~67~13~7 ~67~13~14 minecraft:stone_block_slab 5
fill ~68~5~7 ~68~5~12 minecraft:stonebrick 0
setblock ~68~6~7 minecraft:gold_block
setblock ~68~7~7 minecraft:stonebrick 0
fill ~68~13~7 ~68~15~66 minecraft:stonebrick 0
fill ~68~16~7 ~68~16~18 minecraft:stonebrick 0
fill ~6~0~8 ~6~0~27 minecraft:stone 0
fill ~8~1~8 ~8~1~59 minecraft:stonebrick 0
setblock ~8~10~8 minecraft:double_stone_block_slab 5
setblock ~9~1~8 minecraft:glowstone
fill ~9~10~8 ~9~10~59 minecraft:stone_block_slab 5
fill ~10~1~8 ~15~1~8 minecraft:stonebrick 0
fill ~12~0~8 ~12~0~15 minecraft:stone 0
fill ~14~0~8 ~14~0~16 minecraft:stone 0
fill ~20~0~8 ~21~0~12 minecraft:dirt 0
fill ~28~0~8 ~29~0~9 minecraft:stone 0
fill ~30~0~8 ~30~0~14 minecraft:stone 1
setblock ~34~0~8 minecraft:stone 1
fill ~39~0~8 ~40~0~9 minecraft:iron_ore
fill ~50~0~8 ~50~0~25 minecraft:stone 0
fill ~53~0~8 ~53~0~28 minecraft:stone 0
fill ~54~1~8 ~59~1~8 minecraft:stonebrick 0
fill ~55~0~8 ~56~0~16 minecraft:stone 0
setblock ~60~1~8 minecraft:glowstone
fill ~60~10~8 ~60~10~59 minecraft:stone_block_slab 5
fill ~61~1~8 ~61~1~59 minecraft:stonebrick 0
setblock ~61~10~8 minecraft:double_stone_block_slab 5
fill ~68~6~8 ~68~6~11 minecraft:stonebrick 0
setblock ~68~7~8 minecraft:gold_block
setblock ~1~7~9 minecraft:gold_block
fill ~1~8~9 ~1~8~13 minecraft:stonebrick 0
fill ~8~10~9 ~8~10~58 minecraft:stone_block_slab 5
fill ~9~1~9 ~9~1~58 minecraft:stonebrick 0
setblock ~10~1~9 minecraft:glowstone
fill ~11~1~9 ~14~1~9 minecraft:stonebrick 0
fill ~13~0~9 ~13~0~16 minecraft:stone 0
setblock ~15~1~9 minecraft:glowstone
fill ~22~0~9 ~22~0~12 minecraft:dirt 0
setblock ~32~2~9 minecraft:glowstone
fill ~32~3~9 ~33~5~10 minecraft:stonebrick 0
setblock ~32~8~9 minecraft:glowstone
fill ~33~2~9 ~33~2~10 minecraft:stonebrick 0
fill ~33~8~9 ~33~8~10 minecraft:stonebrick 0
fill ~34~0~9 ~34~0~13 minecraft:stone 0
fill ~36~2~9 ~36~2~10 minecraft:stonebrick 0
fill ~36~8~9 ~36~8~10 minecraft:stonebrick 0
setblock ~37~2~9 minecraft:glowstone
setblock ~37~8~9 minecraft:glowstone
fill ~51~0~9 ~52~0~28 minecraft:stone 0
fill ~54~0~9 ~54~0~43 minecraft:stone 0
setblock ~54~1~9 minecraft:glowstone
fill ~55~1~9 ~58~1~9 minecraft:stonebrick 0
setblock ~59~1~9 minecraft:glowstone
fill ~60~1~9 ~60~1~58 minecraft:stonebrick 0
fill ~61~10~9 ~61~10~58 minecraft:stone_block_slab 5
fill ~68~1~9 ~68~1~32 minecraft:stone 0
fill ~68~7~9 ~68~7~10 minecraft:stonebrick 0
fill ~68~8~9 ~68~8~10 minecraft:gold_block
setblock ~1~6~10 minecraft:gold_block
fill ~1~7~10 ~1~7~19 minecraft:stonebrick 0
fill ~10~1~10 ~10~1~13 minecraft:stonebrick 0
fill ~10~10~10 ~14~10~10 minecraft:stone_block_slab 5
setblock ~11~1~10 minecraft:glowstone
fill ~12~1~10 ~15~1~10 minecraft:stonebrick 0
setblock ~14~2~10 minecraft:glowstone
fill ~15~0~10 ~16~0~10 minecraft:stone 0
fill ~15~2~10 ~30~8~10 minecraft:stonebrick 0
fill ~15~10~10 ~48~10~10 minecraft:stonebrick 0
fill ~15~11~10 ~15~15~10 minecraft:glass
fill ~15~16~10 ~54~16~10 minecraft:stonebrick 0
fill ~16~11~10 ~53~11~10 minecraft:nether_brick_fence
fill ~17~0~10 ~19~0~10 minecraft:dirt 0
fill ~23~0~10 ~23~0~11 minecraft:dirt 0
fill ~24~0~10 ~25~0~12 minecraft:stone 0
fill ~28~0~10 ~28~0~15 minecraft:stone 0
fill ~29~0~10 ~29~0~13 minecraft:stone 1
setblock ~31~2~10 minecraft:glowstone
fill ~31~3~10 ~31~7~10 minecraft:stonebrick 0
setblock ~31~8~10 minecraft:glowstone
setblock ~32~2~10 minecraft:stonebrick 0
setblock ~32~8~10 minecraft:stonebrick 0
fill ~34~2~10 ~35~8~10 minecraft:stonebrick 0
setblock ~37~2~10 minecraft:stonebrick 0
setblock ~37~8~10 minecraft:stonebrick 0
setblock ~38~2~10 minecraft:glowstone
fill ~38~3~10 ~54~7~10 minecraft:stonebrick 0
setblock ~38~8~10 minecraft:glowstone
fill ~39~0~10 ~40~0~18 minecraft:stone 0
fill ~39~2~10 ~54~2~10 minecraft:stonebrick 0
fill ~39~8~10 ~54~8~10 minecraft:stonebrick 0
setblock ~49~10~10 minecraft:double_stone_block_slab 5
fill ~50~10~10 ~54~10~10 minecraft:stonebrick 0
fill ~54~1~10 ~57~1~10 minecraft:stonebrick 0
fill ~54~11~10 ~54~15~10 minecraft:glass
setblock ~55~2~10 minecraft:glowstone
setblock ~55~8~10 minecraft:glowstone
fill ~55~10~10 ~59~10~10 minecraft:stone_block_slab 5
setblock ~58~1~10 minecraft:glowstone
fill ~59~1~10 ~59~1~13 minecraft:stonebrick 0
setblock ~1~5~11 minecraft:gold_block
fill ~1~6~11 ~1~6~18 minecraft:stonebrick 0
fill ~8~9~11 ~14~9~11 minecraft:stonebrick 0
fill ~10~10~11 ~13~10~11 minecraft:stone_block_slab 5
fill ~11~1~11 ~11~1~33 minecraft:stonebrick 0
setblock ~12~1~11 minecraft:glowstone
setblock ~13~1~11 minecraft:stonebrick 0
setblock ~13~2~11 minecraft:dark_oak_door 2
setblock ~13~4~11 minecraft:wall_sign 2
fill ~14~1~11 ~33~1~12 minecraft:sandstone
fill ~14~2~11 ~14~8~11 minecraft:stonebrick 0
setblock ~14~10~11 minecraft:stonebrick 0
fill ~14~11~11 ~14~15~11 minecraft:glass
setblock ~14~16~11 minecraft:stonebrick 0
setblock ~15~0~11 minecraft:stone 0
fill ~16~0~11 ~17~0~12 minecraft:stone 5
fill ~18~0~11 ~19~0~11 minecraft:dirt 0
fill ~20~9~11 ~20~9~12 minecraft:nether_brick_fence
fill ~26~9~11 ~26~9~12 minecraft:nether_brick_fence
fill ~32~9~11 ~32~9~12 minecraft:nether_brick_fence
fill ~34~1~11 ~35~1~11 minecraft:glowstone
fill ~36~1~11 ~55~1~12 minecraft:sandstone
fill ~38~9~11 ~38~9~12 minecraft:nether_brick_fence
fill ~44~9~11 ~44~9~12 minecraft:nether_brick_fence
fill ~50~9~11 ~50~9~12 minecraft:nether_brick_fence
fill ~55~2~11 ~55~10~11 minecraft:stonebrick 0
fill ~55~11~11 ~55~15~11 minecraft:glass
setblock ~55~16~11 minecraft:stonebrick 0
setblock ~56~1~11 minecraft:stonebrick 0
setblock ~56~2~11 minecraft:dark_oak_door 3
setblock ~56~4~11 minecraft:wall_sign 2
setblock ~56~8~11 minecraft:glowstone
fill ~56~9~11 ~67~9~12 minecraft:stonebrick 0
fill ~56~10~11 ~59~10~11 minecraft:stone_block_slab 5
setblock ~57~1~11 minecraft:glowstone
fill ~58~1~11 ~58~1~56 minecraft:stonebrick 0
setblock ~68~7~11 minecraft:gold_block
fill ~68~8~11 ~68~8~13 minecraft:stonebrick 0
setblock ~1~4~12 minecraft:gold_block
fill ~1~5~12 ~1~5~17 minecraft:stonebrick 0
fill ~8~9~12 ~13~9~12 minecraft:stonebrick 0
fill ~10~10~12 ~12~10~12 minecraft:stone_block_slab 5
setblock ~12~1~12 minecraft:stonebrick 0
setblock ~12~2~12 minecraft:dark_oak_door 2
setblock ~12~4~12 minecraft:wall_sign 4
setblock ~13~1~12 minecraft:glowstone
fill ~13~4~12 ~13~8~12 minecraft:stonebrick 0
setblock ~13~10~12 minecraft:glowstone
fill ~13~11~12 ~13~15~12 minecraft:glass
setblock ~13~16~12 minecraft:glowstone
setblock ~15~0~12 minecraft:stone 5
fill ~18~0~12 ~19~0~14 minecraft:stone 5
fill ~20~7~12 ~20~8~12 minecraft:nether_brick_fence
fill ~23~0~12 ~23~0~13 minecraft:stone 5
fill ~26~7~12 ~26~8~12 minecraft:nether_brick_fence
fill ~32~0~12 ~32~0~13 minecraft:stone 1
fill ~32~7~12 ~32~8~12 minecraft:nether_brick_fence
fill ~33~0~12 ~33~0~15 minecraft:stone 0
fill ~34~1~12 ~35~1~12 minecraft:sandstone
fill ~38~7~12 ~38~8~12 minecraft:nether_brick_fence
fill ~44~7~12 ~44~8~12 minecraft:nether_brick_fence
fill ~50~7~12 ~50~8~12 minecraft:nether_brick_fence
setblock ~56~1~12 minecraft:glowstone
fill ~56~4~12 ~56~8~12 minecraft:stonebrick 0
setblock ~56~10~12 minecraft:glowstone
fill ~56~11~12 ~56~15~12 minecraft:glass
setblock ~56~16~12 minecraft:glowstone
setblock ~57~1~12 minecraft:stonebrick 0
setblock ~57~2~12 minecraft:dark_oak_door 0
setblock ~57~4~12 minecraft:wall_sign 5
setblock ~57~8~12 minecraft:glowstone
fill ~57~10~12 ~59~10~12 minecraft:stone_block_slab 5
setblock ~68~6~12 minecraft:gold_block
fill ~68~7~12 ~68~7~21 minecraft:stonebrick 0
setblock ~1~3~13 minecraft:gold_block
fill ~1~4~13 ~1~4~16 minecraft:stonebrick 0
fill ~5~17~13 ~13~17~66 minecraft:stonebrick 0
fill ~8~9~13 ~12~9~13 minecraft:stonebrick 0
fill ~10~10~13 ~11~10~13 minecraft:stone_block_slab 5
setblock ~11~2~13 minecraft:glowstone
fill ~12~1~13 ~13~1~32 minecraft:sandstone
fill ~12~2~13 ~12~8~13 minecraft:stonebrick 0
setblock ~12~10~13 minecraft:stonebrick 0
fill ~12~11~13 ~12~15~13 minecraft:glass
setblock ~12~16~13 minecraft:stonebrick 0
setblock ~14~1~13 minecraft:glowstone
fill ~15~0~13 ~16~0~15 minecraft:stone 0
fill ~15~1~13 ~33~1~13 minecraft:sandstone
fill ~15~17~13 ~54~17~13 minecraft:stonebrick 0
fill ~17~0~13 ~17~0~14 minecraft:stone 5
fill ~20~0~13 ~22~0~14 minecraft:stone 5
setblock ~20~7~13 minecraft:netherrack
setblock ~20~8~13 minecraft:fire 15
fill ~24~0~13 ~24~0~14 minecraft:stone 5
fill ~25~0~13 ~25~0~20 minecraft:stone 0
setblock ~26~7~13 minecraft:netherrack
setblock ~26~8~13 minecraft:fire 15
setblock ~32~7~13 minecraft:netherrack
setblock ~32~8~13 minecraft:fire 15
fill ~34~1~13 ~35~1~13 minecraft:netherrack
fill ~34~2~13 ~35~2~13 minecraft:fire 15
fill ~35~0~13 ~36~0~15 minecraft:stone 1
fill ~36~1~13 ~54~1~13 minecraft:sandstone
setblock ~38~7~13 minecraft:netherrack
setblock ~38~8~13 minecraft:fire 15
setblock ~44~7~13 minecraft:netherrack
setblock ~44~8~13 minecraft:fire 15
setblock ~50~7~13 minecraft:netherrack
setblock ~50~8~13 minecraft:fire 15
setblock ~55~1~13 minecraft:glowstone
fill ~56~1~13 ~57~1~32 minecraft:sandstone
fill ~57~2~13 ~57~10~13 minecraft:stonebrick 0
fill ~57~11~13 ~57~15~13 minecraft:glass
setblock ~57~16~13 minecraft:stonebrick 0
setblock ~58~2~13 minecraft:glowstone
setblock ~58~8~13 minecraft:glowstone
fill ~58~9~13 ~67~9~67 minecraft:stonebrick 0
fill ~58~10~13 ~59~10~13 minecraft:stone_block_slab 5
setblock ~68~5~13 minecraft:gold_block
fill ~68~6~13 ~68~6~20 minecraft:stonebrick 0
fill ~1~2~14 ~1~2~15 minecraft:gold_block
fill ~1~3~14 ~1~3~15 minecraft:stonebrick 0
setblock ~1~8~14 minecraft:glowstone
setblock ~2~1~14 minecraft:glowstone
fill ~2~11~14 ~4~11~63 minecraft:stonebrick 0
fill ~2~12~14 ~2~12~65 minecraft:stonebrick 0
setblock ~3~12~14 minecraft:glowstone
setblock ~5~11~14 minecraft:glowstone
setblock ~6~2~14 minecraft:standing_sign 8
fill ~6~10~14 ~6~10~64 minecraft:stonebrick 0
setblock ~7~10~14 minecraft:glowstone
fill ~8~9~14 ~11~9~67 minecraft:stonebrick 0
setblock ~10~1~14 minecraft:glowstone
fill ~10~10~14 ~10~10~60 minecraft:stone_block_slab 5
fill ~11~2~14 ~11~7~53 minecraft:stonebrick 0
fill ~11~8~14 ~11~8~36 minecraft:stonebrick 0
fill ~11~10~14 ~11~10~53 minecraft:stonebrick 0
fill ~11~11~14 ~11~15~14 minecraft:glass
fill ~11~16~14 ~11~16~53 minecraft:stonebrick 0
fill ~14~1~14 ~14~1~32 minecraft:sandstone
fill ~14~17~14 ~14~17~53 minecraft:stonebrick 0
setblock ~15~1~14 minecraft:glowstone
fill ~16~1~14 ~53~1~14 minecraft:sandstone
fill ~16~17~14 ~53~17~14 minecraft:stonebrick 0
setblock ~23~0~14 minecraft:iron_ore
setblock ~29~0~14 minecraft:stone 0
setblock ~32~0~14 minecraft:stone 0
fill ~34~0~14 ~34~0~15 minecraft:stone 1
setblock ~37~0~14 minecraft:stone 1
fill ~38~0~14 ~38~0~18 minecraft:stone 0
setblock ~54~1~14 minecraft:glowstone
fill ~55~1~14 ~55~1~32 minecraft:sandstone
fill ~55~17~14 ~55~17~53 minecraft:stonebrick 0
fill ~58~2~14 ~58~7~53 minecraft:stonebrick 0
fill ~58~8~14 ~58~8~32 minecraft:stonebrick 0
fill ~58~10~14 ~58~10~53 minecraft:stonebrick 0
fill ~58~11~14 ~58~15~14 minecraft:glass
fill ~58~16~14 ~58~16~53 minecraft:stonebrick 0
setblock ~59~1~14 minecraft:glowstone
fill ~59~10~14 ~59~10~60 minecraft:stone_block_slab 5
setblock ~62~10~14 minecraft:glowstone
setblock ~63~2~14 minecraft:standing_sign 8
setblock ~64~11~14 minecraft:glowstone
fill ~65~11~14 ~65~11~67 minecraft:stonebrick 0
setblock ~66~12~14 minecraft:glowstone
setblock ~67~1~14 minecraft:glowstone
fill ~67~12~14 ~67~12~67 minecraft:stonebrick 0
setblock ~68~4~14 minecraft:gold_block
fill ~68~5~14 ~68~5~19 minecraft:stonebrick 0
setblock ~68~8~14 minecraft:glowstone
fill ~1~8~15 ~1~8~20 minecraft:stonebrick 0
fill ~2~1~15 ~2~1~36 minecraft:stonebrick 0
fill ~2~13~15 ~2~13~27 minecraft:dark_oak_stairs 1
fill ~3~12~15 ~3~12~32 minecraft:stonebrick 0
fill ~4~12~15 ~4~12~27 minecraft:dark_oak_stairs 1
fill ~5~11~15 ~5~11~32 minecraft:stonebrick 0
fill ~6~11~15 ~6~11~27 minecraft:dark_oak_stairs 1
fill ~7~10~15 ~7~10~32 minecraft:stonebrick 0
fill ~10~1~15 ~10~1~36 minecraft:stonebrick 0
fill ~11~11~15 ~11~11~52 minecraft:nether_brick_fence
fill ~15~1~15 ~15~1~52 minecraft:sandstone
fill ~15~17~15 ~15~17~52 minecraft:stonebrick 0
setblock ~16~1~15 minecraft:glowstone
fill ~17~0~15 ~24~0~19 minecraft:stone 0
fill ~17~1~15 ~33~1~15 minecraft:sandstone
fill ~17~17~15 ~52~17~15 minecraft:stonebrick 0
fill ~29~0~15 ~32~0~17 minecraft:stone 5
fill ~34~1~15 ~35~1~15 minecraft:glowstone
fill ~36~1~15 ~52~1~15 minecraft:sandstone
fill ~37~0~15 ~37~0~20 minecraft:stone 0
setblock ~53~1~15 minecraft:glowstone
fill ~54~1~15 ~54~1~52 minecraft:sandstone
fill ~54~17~15 ~54~17~52 minecraft:stonebrick 0
fill ~58~11~15 ~58~11~52 minecraft:nether_brick_fence
fill ~59~1~15 ~59~1~32 minecraft:stonebrick 0
fill ~62~10~15 ~62~10~32 minecraft:stonebrick 0
fill ~63~11~15 ~63~11~27 minecraft:dark_oak_stairs 0
fill ~64~11~15 ~64~11~32 minecraft:stonebrick 0
fill ~65~12~15 ~65~12~27 minecraft:dark_oak_stairs 0
fill ~66~12~15 ~66~12~32 minecraft:stonebrick 0
fill ~67~1~15 ~67~1~32 minecraft:stonebrick 0
fill ~67~13~15 ~67~13~27 minecraft:dark_oak_stairs 0
setblock ~68~3~15 minecraft:gold_block
fill ~68~4~15 ~68~4~18 minecraft:stonebrick 0
fill ~68~8~15 ~68~8~22 minecraft:stonebrick 0
fill ~1~2~16 ~1~2~27 minecraft:stonebrick 0
setblock ~1~3~16 minecraft:gold_block
fill ~7~0~16 ~10~0~27 minecraft:stone 0
fill ~11~0~16 ~12~0~18 minecraft:dirt 0
fill ~15~0~16 ~15~0~17 minecraft:coal_ore
setblock ~16~0~16 minecraft:stone 0
fill ~16~1~16 ~16~1~32 minecraft:sandstone
fill ~16~17~16 ~16~17~51 minecraft:stonebrick 0
setblock ~17~1~16 minecraft:glowstone
fill ~18~1~16 ~21~1~16 minecraft:sandstone
fill ~18~17~16 ~51~17~16 minecraft:stonebrick 0
setblock ~22~1~16 minecraft:glowstone
fill ~23~1~16 ~46~1~17 minecraft:soul_sand
fill ~26~0~16 ~26~0~20 minecraft:stone 0
fill ~27~0~16 ~28~0~18 minecraft:stone 5
fill ~33~0~16 ~33~0~17 minecraft:stone 5
fill ~34~0~16 ~36~0~20 minecraft:stone 0
setblock ~46~0~16 minecraft:stone 0
fill ~47~0~16 ~47~0~20 minecraft:coal_ore
setblock ~47~1~16 minecraft:glowstone
fill ~48~1~16 ~51~1~16 minecraft:sandstone
setblock ~52~1~16 minecraft:glowstone
fill ~53~1~16 ~53~1~32 minecraft:sandstone
fill ~53~17~16 ~53~17~51 minecraft:stonebrick 0
fill ~68~2~16 ~68~2~17 minecraft:gold_block
fill ~68~3~16 ~68~3~17 minecraft:stonebrick 0
fill ~1~3~17 ~1~3~26 minecraft:stonebrick 0
setblock ~1~4~17 minecraft:gold_block
fill ~13~0~17 ~14~0~20 minecraft:dirt 0
setblock ~16~0~17 minecraft:coal_ore
fill ~17~1~17 ~17~1~20 minecraft:sandstone
fill ~17~17~17 ~17~17~50 minecraft:stonebrick 0
setblock ~18~1~17 minecraft:glowstone
fill ~19~1~17 ~21~1~17 minecraft:sandstone
fill ~19~17~17 ~50~17~17 minecraft:stonebrick 0
fill ~22~1~17 ~22~1~19 minecraft:soul_sand
fill ~46~0~17 ~46~0~20 minecraft:coal_ore
fill ~47~1~17 ~47~1~19 minecraft:soul_sand
fill ~48~1~17 ~50~1~17 minecraft:sandstone
setblock ~51~1~17 minecraft:glowstone
fill ~52~1~17 ~52~1~20 minecraft:sandstone
fill ~52~17~17 ~52~17~50 minecraft:stonebrick 0
setblock ~55~0~17 minecraft:stone 3
fill ~56~0~17 ~56~0~67 minecraft:stone 0
fill ~1~4~18 ~1~4~25 minecraft:stonebrick 0
setblock ~1~5~18 minecraft:gold_block
fill ~15~0~18 ~15~0~22 minecraft:dirt 0
setblock ~16~0~18 minecraft:stone 0
fill ~18~1~18 ~18~1~20 minecraft:sandstone
fill ~18~17~18 ~18~17~49 minecraft:stonebrick 0
setblock ~19~1~18 minecraft:glowstone
setblock ~20~1~18 minecraft:sandstone
fill ~20~17~18 ~49~17~18 minecraft:stonebrick 0
fill ~21~1~18 ~21~1~20 minecraft:soul_sand
setblock ~23~1~18 minecraft:soul_sand
setblock ~24~1~18 minecraft:netherrack
setblock ~24~2~18 minecraft:fire 15
fill ~25~1~18 ~33~1~20 minecraft:sandstone
fill ~29~0~18 ~31~0~18 minecraft:stone 5
fill ~32~0~18 ~33~0~20 minecraft:stone 0
fill ~34~1~18 ~35~1~18 minecraft:glowstone
fill ~36~1~18 ~44~1~20 minecraft:sandstone
setblock ~45~1~18 minecraft:netherrack
setblock ~45~2~18 minecraft:fire 15
setblock ~46~1~18 minecraft:soul_sand
fill ~48~1~18 ~48~1~20 minecraft:soul_sand
setblock ~49~1~18 minecraft:sandstone
setblock ~50~1~18 minecraft:glowstone
fill ~51~1~18 ~51~1~20 minecraft:sandstone
fill ~51~17~18 ~51~17~49 minecraft:stonebrick 0
fill ~55~0~18 ~55~0~67 minecraft:stone 0
fill ~68~2~18 ~68~2~29 minecraft:stonebrick 0
setblock ~68~3~18 minecraft:gold_block
fill ~1~5~19 ~1~5~24 minecraft:stonebrick 0
setblock ~1~6~19 minecraft:gold_block
setblock ~1~16~19 minecraft:glowstone
fill ~11~0~19 ~11~0~42 minecraft:stone 0
setblock ~12~0~19 minecraft:dirt 0
fill ~12~9~19 ~13~9~19 minecraft:nether_brick_fence
fill ~13~7~19 ~13~8~19 minecraft:nether_brick_fence
setblock ~14~7~19 minecraft:netherrack
setblock ~14~8~19 minecraft:fire 15
fill ~16~0~19 ~16~0~23 minecraft:dirt 0
setblock ~19~1~19 minecraft:sandstone
fill ~19~17~19 ~19~17~48 minecraft:stonebrick 0
setblock ~20~1~19 minecraft:glowstone
fill ~21~17~19 ~48~17~19 minecraft:stonebrick 0
fill ~23~1~19 ~24~1~29 minecraft:sandstone
fill ~27~0~19 ~31~0~20 minecraft:stone 0
fill ~34~1~19 ~35~1~20 minecraft:sandstone
fill ~38~0~19 ~40~0~20 minecraft:stone 1
fill ~45~1~19 ~46~1~29 minecraft:sandstone
setblock ~49~1~19 minecraft:glowstone
setblock ~50~1~19 minecraft:sandstone
fill ~50~17~19 ~50~17~48 minecraft:stonebrick 0
setblock ~55~7~19 minecraft:netherrack
setblock ~55~8~19 minecraft:fire 15
fill ~56~7~19 ~56~9~19 minecraft:nether_brick_fence
setblock ~57~9~19 minecraft:nether_brick_fence
fill ~68~3~19 ~68~3~28 minecraft:stonebrick 0
setblock ~68~4~19 minecraft:gold_block
setblock ~68~16~19 minecraft:glowstone
fill ~1~6~20 ~1~6~23 minecraft:stonebrick 0
setblock ~1~7~20 minecraft:gold_block
setblock ~1~16~20 minecraft:stonebrick 0
fill ~12~0~20 ~12~0~41 minecraft:stone 0
fill ~17~0~20 ~18~0~23 minecraft:dirt 0
fill ~19~0~20 ~24~0~20 minecraft:stone 0
fill ~19~1~20 ~20~1~21 minecraft:soul_sand
fill ~20~17~20 ~20~17~47 minecraft:stonebrick 0
fill ~22~1~20 ~22~1~30 minecraft:sandstone
fill ~22~17~20 ~47~17~20 minecraft:stonebrick 0
setblock ~41~0~20 minecraft:stone 1
fill ~42~0~20 ~45~0~20 minecraft:stone 0
fill ~47~1~20 ~47~1~30 minecraft:sandstone
fill ~49~1~20 ~50~1~21 minecraft:soul_sand
fill ~49~17~20 ~49~17~47 minecraft:stonebrick 0
fill ~68~4~20 ~68~4~27 minecraft:stonebrick 0
setblock ~68~5~20 minecraft:gold_block
setblock ~68~16~20 minecraft:stonebrick 0
fill ~1~7~21 ~1~7~22 minecraft:stonebrick 0
fill ~1~8~21 ~1~8~22 minecraft:gold_block
setblock ~1~16~21 minecraft:glowstone
fill ~13~0~21 ~13~0~38 minecraft:stone 0
setblock ~14~0~21 minecraft:dirt 0
setblock ~17~1~21 minecraft:glowstone
fill ~18~1~21 ~18~1~46 minecraft:soul_sand
fill ~19~0~21 ~21~0~21 minecraft:stone 0
fill ~21~1~21 ~21~1~46 minecraft:sandstone
fill ~21~17~21 ~21~17~46 minecraft:stonebrick 0
fill ~22~0~21 ~48~0~47 minecraft:sandstone
fill ~23~17~21 ~46~17~21 minecraft:stonebrick 0
fill ~25~1~21 ~31~1~22 minecraft:sandstone
setblock ~32~1~21 minecraft:glowstone
fill ~33~1~21 ~36~1~21 minecraft:stone_block_slab 7
setblock ~37~1~21 minecraft:glowstone
fill ~38~1~21 ~44~1~22 minecraft:sandstone
fill ~48~1~21 ~48~1~46 minecraft:sandstone
fill ~48~17~21 ~48~17~46 minecraft:stonebrick 0
fill ~51~1~21 ~51~1~46 minecraft:soul_sand
setblock ~52~1~21 minecraft:glowstone
fill ~68~5~21 ~68~5~26 minecraft:stonebrick 0
setblock ~68~6~21 minecraft:gold_block
setblock ~68~16~21 minecraft:glowstone
setblock ~1~16~22 minecraft:stonebrick 0
fill ~14~0~22 ~14~0~36 minecraft:stone 0
fill ~17~1~22 ~17~1~45 minecraft:soul_sand
fill ~19~0~22 ~19~0~37 minecraft:stone 0
setblock ~19~1~22 minecraft:soul_sand
fill ~20~0~22 ~20~1~22 minecraft:sandstone
fill ~21~0~22 ~21~0~24 minecraft:stone 0
fill ~22~17~22 ~22~17~45 minecraft:stonebrick 0
fill ~24~17~22 ~45~17~22 minecraft:stonebrick 0
setblock ~32~1~22 minecraft:stone_block_slab 7
fill ~33~1~22 ~36~1~22 minecraft:wooden_slab 5
setblock ~37~1~22 minecraft:stone_block_slab 7
fill ~47~17~22 ~47~17~45 minecraft:stonebrick 0
fill ~49~1~22 ~49~1~45 minecraft:sandstone
setblock ~50~1~22 minecraft:soul_sand
fill ~52~1~22 ~52~1~45 minecraft:soul_sand
fill ~68~6~22 ~68~6~25 minecraft:stonebrick 0
setblock ~68~7~22 minecraft:gold_block
setblock ~68~16~22 minecraft:stonebrick 0
setblock ~1~7~23 minecraft:gold_block
fill ~1~8~23 ~1~8~34 minecraft:stonebrick 0
setblock ~1~16~23 minecraft:glowstone
fill ~15~0~23 ~15~0~35 minecraft:stone 0
setblock ~19~1~23 minecraft:netherrack
setblock ~19~2~23 minecraft:fire 15
fill ~20~0~23 ~20~0~47 minecraft:stone 0
fill ~20~1~23 ~20~1~45 minecraft:sandstone
fill ~23~17~23 ~23~17~44 minecraft:stonebrick 0
fill ~25~1~23 ~30~1~23 minecraft:sandstone
fill ~25~17~23 ~44~17~23 minecraft:stonebrick 0
setblock ~31~1~23 minecraft:stone_block_slab 7
setblock ~32~1~23 minecraft:wooden_slab 5
fill ~33~1~23 ~36~1~23 minecraft:wooden_slab 0
setblock ~37~1~23 minecraft:wooden_slab 5
setblock ~38~1~23 minecraft:stone_block_slab 7
fill ~39~1~23 ~44~1~23 minecraft:sandstone
fill ~46~17~23 ~46~17~44 minecraft:stonebrick 0
setblock ~50~1~23 minecraft:netherrack
setblock ~50~2~23 minecraft:fire 15
setblock ~62~6~23 minecraft:netherrack
setblock ~62~7~23 minecraft:fire 15
fill ~63~6~23 ~63~8~23 minecraft:nether_brick_fence
setblock ~64~6~23 minecraft:netherrack
setblock ~64~7~23 minecraft:fire 15
fill ~68~7~23 ~68~7~24 minecraft:stonebrick 0
fill ~68~8~23 ~68~8~24 minecraft:gold_block
setblock ~68~16~23 minecraft:glowstone
setblock ~1~6~24 minecraft:gold_block
fill ~1~7~24 ~1~7~33 minecraft:stonebrick 0
fill ~1~16~24 ~1~16~43 minecraft:stonebrick 0
fill ~16~0~24 ~18~0~35 minecraft:stone 0
fill ~19~1~24 ~19~1~32 minecraft:sandstone
fill ~24~17~24 ~24~17~43 minecraft:stonebrick 0
fill ~25~1~24 ~29~1~24 minecraft:sandstone
fill ~26~17~24 ~43~17~24 minecraft:stonebrick 0
setblock ~30~1~24 minecraft:stone_block_slab 7
setblock ~31~1~24 minecraft:wooden_slab 5
setblock ~32~1~24 minecraft:wooden_slab 0
setblock ~37~1~24 minecraft:wooden_slab 0
setblock ~38~1~24 minecraft:wooden_slab 5
setblock ~39~1~24 minecraft:stone_block_slab 7
fill ~40~1~24 ~44~1~24 minecraft:sandstone
fill ~45~17~24 ~45~17~43 minecraft:stonebrick 0
fill ~49~0~24 ~49~0~26 minecraft:stone 5
fill ~50~1~24 ~50~1~32 minecraft:sandstone
fill ~68~16~24 ~68~16~43 minecraft:stonebrick 0
setblock ~1~5~25 minecraft:gold_block
fill ~1~6~25 ~1~6~32 minecraft:stonebrick 0
fill ~12~9~25 ~13~9~25 minecraft:nether_brick_fence
fill ~13~7~25 ~13~8~25 minecraft:nether_brick_fence
setblock ~14~7~25 minecraft:netherrack
setblock ~14~8~25 minecraft:fire 15
fill ~21~0~25 ~21~0~26 minecraft:iron_ore
fill ~25~1~25 ~28~1~25 minecraft:sandstone
fill ~25~17~25 ~25~17~42 minecraft:stonebrick 0
fill ~27~17~25 ~42~17~25 minecraft:stonebrick 0
setblock ~29~1~25 minecraft:stone_block_slab 7
setblock ~30~1~25 minecraft:wooden_slab 5
setblock ~31~1~25 minecraft:wooden_slab 0
setblock ~38~1~25 minecraft:wooden_slab 0
setblock ~39~1~25 minecraft:wooden_slab 5
setblock ~40~1~25 minecraft:stone_block_slab 7
fill ~41~1~25 ~44~1~25 minecraft:sandstone
fill ~44~17~25 ~44~17~42 minecraft:stonebrick 0
setblock ~55~7~25 minecraft:netherrack
setblock ~55~8~25 minecraft:fire 15
fill ~56~7~25 ~56~9~25 minecraft:nether_brick_fence
fill ~57~0~25 ~63~0~26 minecraft:stone 3
setblock ~57~9~25 minecraft:nether_brick_fence
setblock ~64~0~25 minecraft:stone 0
setblock ~68~7~25 minecraft:gold_block
fill ~68~8~25 ~68~8~32 minecraft:stonebrick 0
setblock ~1~4~26 minecraft:gold_block
fill ~1~5~26 ~1~5~31 minecraft:stonebrick 0
setblock ~5~6~26 minecraft:netherrack
setblock ~5~7~26 minecraft:fire 15
fill ~6~6~26 ~6~8~26 minecraft:nether_brick_fence
setblock ~7~6~26 minecraft:netherrack
setblock ~7~7~26 minecraft:fire 15
fill ~25~1~26 ~26~1~27 minecraft:sandstone
fill ~26~17~26 ~26~17~41 minecraft:stonebrick 0
setblock ~27~1~26 minecraft:glowstone
setblock ~28~1~26 minecraft:stone_block_slab 7
fill ~28~17~26 ~41~17~26 minecraft:stonebrick 0
setblock ~29~1~26 minecraft:wooden_slab 5
setblock ~30~1~26 minecraft:wooden_slab 0
setblock ~39~1~26 minecraft:wooden_slab 0
setblock ~40~1~26 minecraft:wooden_slab 5
setblock ~41~1~26 minecraft:stone_block_slab 7
setblock ~42~1~26 minecraft:glowstone
fill ~43~1~26 ~44~1~27 minecraft:sandstone
fill ~43~17~26 ~43~17~41 minecraft:stonebrick 0
setblock ~50~0~26 minecraft:stone 5
fill ~64~0~26 ~65~0~28 minecraft:stone 3
fill ~66~0~26 ~68~0~49 minecraft:stone 0
setblock ~68~6~26 minecraft:gold_block
fill ~68~7~26 ~68~7~35 minecraft:stonebrick 0
setblock ~1~3~27 minecraft:gold_block
fill ~1~4~27 ~1~4~30 minecraft:stonebrick 0
fill ~21~0~27 ~21~0~48 minecraft:stone 0
setblock ~27~1~27 minecraft:stone_block_slab 7
fill ~27~17~27 ~27~17~40 minecraft:stonebrick 0
setblock ~28~1~27 minecraft:wooden_slab 5
setblock ~29~1~27 minecraft:wooden_slab 0
fill ~29~17~27 ~40~17~27 minecraft:stonebrick 0
setblock ~40~1~27 minecraft:wooden_slab 0
setblock ~41~1~27 minecraft:wooden_slab 5
setblock ~42~1~27 minecraft:stone_block_slab 7
fill ~42~17~27 ~42~17~40 minecraft:stonebrick 0
fill ~49~0~27 ~50~0~40 minecraft:stone 0
fill ~57~0~27 ~57~0~55 minecraft:stone 0
fill ~58~0~27 ~63~0~27 minecraft:stone 3
setblock ~68~5~27 minecraft:gold_block
fill ~68~6~27 ~68~6~34 minecraft:stonebrick 0
fill ~1~0~28 ~4~0~28 minecraft:stone 0
fill ~1~2~28 ~1~2~29 minecraft:gold_block
fill ~1~3~28 ~1~3~29 minecraft:stonebrick 0
fill ~2~13~28 ~2~13~39 minecraft:stone_block_slab 5
fill ~4~12~28 ~4~12~39 minecraft:stone_block_slab 5
fill ~5~0~28 ~7~0~31 minecraft:stone 1
fill ~6~11~28 ~6~11~39 minecraft:stone_block_slab 5
fill ~8~0~28 ~10~0~28 minecraft:stone 0
setblock ~25~1~28 minecraft:sandstone
setblock ~26~1~28 minecraft:stone_block_slab 7
setblock ~27~1~28 minecraft:wooden_slab 5
setblock ~28~1~28 minecraft:wooden_slab 0
fill ~28~17~28 ~28~17~39 minecraft:stonebrick 0
fill ~30~17~28 ~39~17~28 minecraft:stonebrick 0
setblock ~41~1~28 minecraft:wooden_slab 0
fill ~41~17~28 ~41~17~39 minecraft:stonebrick 0
setblock ~42~1~28 minecraft:wooden_slab 5
setblock ~43~1~28 minecraft:stone_block_slab 7
setblock ~44~1~28 minecraft:sandstone
fill ~58~0~28 ~59~0~41 minecraft:stone 0
fill ~60~0~28 ~63~0~28 minecraft:stone 3
fill ~63~11~28 ~63~11~39 minecraft:stone_block_slab 5
fill ~65~12~28 ~65~12~39 minecraft:stone_block_slab 5
fill ~67~13~28 ~67~13~39 minecraft:stone_block_slab 5
setblock ~68~4~28 minecraft:gold_block
fill ~68~5~28 ~68~5~33 minecraft:stonebrick 0
fill ~1~0~29 ~3~0~29 minecraft:stone 0
fill ~4~0~29 ~4~0~31 minecraft:stone 1
fill ~8~0~29 ~9~0~29 minecraft:stone 1
fill ~10~0~29 ~10~0~43 minecraft:stone 0
setblock ~25~1~29 minecraft:stone_block_slab 7
setblock ~26~1~29 minecraft:wooden_slab 5
setblock ~27~1~29 minecraft:wooden_slab 0
fill ~29~17~29 ~29~17~38 minecraft:stonebrick 0
fill ~31~17~29 ~38~17~29 minecraft:stonebrick 0
fill ~40~17~29 ~40~17~38 minecraft:stonebrick 0
setblock ~42~1~29 minecraft:wooden_slab 0
setblock ~43~1~29 minecraft:wooden_slab 5
setblock ~44~1~29 minecraft:stone_block_slab 7
fill ~51~0~29 ~51~0~41 minecraft:stone 0
fill ~52~0~29 ~53~0~30 minecraft:stone 5
fill ~60~0~29 ~65~0~41 minecraft:stone 0
setblock ~68~3~29 minecraft:gold_block
fill ~68~4~29 ~68~4~32 minecraft:stonebrick 0
fill ~1~0~30 ~2~0~34 minecraft:stone 0
fill ~1~2~30 ~1~2~41 minecraft:stonebrick 0
setblock ~1~3~30 minecraft:gold_block
fill ~3~0~30 ~3~0~31 minecraft:stone 1
setblock ~8~0~30 minecraft:stone 1
fill ~9~0~30 ~9~0~43 minecraft:stone 0
setblock ~23~1~30 minecraft:sandstone
setblock ~24~1~30 minecraft:stone_block_slab 7
setblock ~25~1~30 minecraft:wooden_slab 5
setblock ~26~1~30 minecraft:wooden_slab 0
fill ~30~17~30 ~30~17~37 minecraft:stonebrick 0
fill ~32~17~30 ~37~17~30 minecraft:stonebrick 0
fill ~34~9~30 ~35~9~30 minecraft:trapdoor 3
fill ~39~17~30 ~39~17~37 minecraft:stonebrick 0
setblock ~43~1~30 minecraft:wooden_slab 0
setblock ~44~1~30 minecraft:wooden_slab 5
setblock ~45~1~30 minecraft:stone_block_slab 7
setblock ~46~1~30 minecraft:sandstone
fill ~68~2~30 ~68~2~31 minecraft:gold_block
fill ~68~3~30 ~68~3~31 minecraft:stonebrick 0
fill ~1~3~31 ~1~3~40 minecraft:stonebrick 0
setblock ~1~4~31 minecraft:gold_block
fill ~8~0~31 ~8~0~36 minecraft:stone 0
fill ~12~9~31 ~13~9~31 minecraft:nether_brick_fence
fill ~13~7~31 ~13~8~31 minecraft:nether_brick_fence
setblock ~14~7~31 minecraft:netherrack
setblock ~14~8~31 minecraft:fire 15
setblock ~22~1~31 minecraft:glowstone
setblock ~23~1~31 minecraft:stone_block_slab 7
setblock ~24~1~31 minecraft:wooden_slab 5
setblock ~25~1~31 minecraft:wooden_slab 0
fill ~31~17~31 ~31~17~36 minecraft:stonebrick 0
setblock ~33~9~31 minecraft:trapdoor 1
fill ~33~17~31 ~36~17~31 minecraft:stonebrick 0
fill ~34~9~31 ~35~9~31 minecraft:glowstone
fill ~34~10~31 ~35~11~31 minecraft:nether_brick_fence
setblock ~36~9~31 minecraft:trapdoor 1
fill ~38~17~31 ~38~17~36 minecraft:stonebrick 0
setblock ~44~1~31 minecraft:wooden_slab 0
setblock ~45~1~31 minecraft:wooden_slab 5
setblock ~46~1~31 minecraft:stone_block_slab 7
setblock ~47~1~31 minecraft:glowstone
fill ~52~0~31 ~53~0~42 minecraft:stone 0
setblock ~55~7~31 minecraft:netherrack
setblock ~55~8~31 minecraft:fire 15
fill ~56~7~31 ~56~9~31 minecraft:nether_brick_fence
setblock ~57~9~31 minecraft:nether_brick_fence
fill ~1~4~32 ~1~4~39 minecraft:stonebrick 0
setblock ~1~5~32 minecraft:gold_block
fill ~3~0~32 ~7~0~35 minecraft:stone 0
fill ~22~1~32 ~22~1~35 minecraft:stone_block_slab 7
fill ~23~1~32 ~23~1~35 minecraft:wooden_slab 5
fill ~24~1~32 ~24~1~35 minecraft:wooden_slab 0
setblock ~32~9~32 minecraft:trapdoor 3
fill ~32~17~32 ~32~17~35 minecraft:stonebrick 0
fill ~34~9~32 ~35~9~32 minecraft:trapdoor 2
fill ~34~11~32 ~35~11~36 minecraft:nether_brick_fence
fill ~34~17~32 ~35~17~32 minecraft:stonebrick 0
setblock ~37~9~32 minecraft:trapdoor 3
fill ~37~17~32 ~37~17~35 minecraft:stonebrick 0
fill ~45~1~32 ~45~1~35 minecraft:wooden_slab 0
fill ~46~1~32 ~46~1~35 minecraft:wooden_slab 5
fill ~47~1~32 ~47~1~35 minecraft:stone_block_slab 7
fill ~68~2~32 ~68~2~43 minecraft:stonebrick 0
setblock ~68~3~32 minecraft:gold_block
fill ~1~5~33 ~1~5~38 minecraft:stonebrick 0
setblock ~1~6~33 minecraft:gold_block
fill ~3~12~33 ~3~12~34 minecraft:glowstone
fill ~5~11~33 ~5~11~34 minecraft:glowstone
fill ~7~10~33 ~7~10~34 minecraft:glowstone
fill ~12~1~33 ~12~1~34 minecraft:glowstone
fill ~13~1~33 ~13~1~54 minecraft:sandstone
fill ~14~1~33 ~14~1~34 minecraft:netherrack
fill ~14~2~33 ~14~2~34 minecraft:fire 15
fill ~16~1~33 ~16~1~34 minecraft:glowstone
fill ~19~1~33 ~19~1~34 minecraft:glowstone
fill ~31~9~33 ~31~9~34 minecraft:trapdoor 1
fill ~32~9~33 ~32~9~34 minecraft:glowstone
fill ~32~10~33 ~32~11~34 minecraft:nether_brick_fence
fill ~33~9~33 ~33~9~34 minecraft:trapdoor 1
fill ~33~11~33 ~33~11~34 minecraft:nether_brick_fence
fill ~33~17~33 ~33~17~34 minecraft:stonebrick 0
fill ~34~12~33 ~35~17~34 minecraft:nether_brick_fence
fill ~36~9~33 ~36~9~34 minecraft:trapdoor 1
fill ~36~11~33 ~37~11~34 minecraft:nether_brick_fence
fill ~36~17~33 ~36~17~34 minecraft:stonebrick 0
fill ~37~9~33 ~37~9~34 minecraft:glowstone
fill ~37~10~33 ~37~10~34 minecraft:nether_brick_fence
fill ~38~9~33 ~38~9~34 minecraft:trapdoor 1
fill ~50~1~33 ~50~1~34 minecraft:glowstone
fill ~53~1~33 ~53~1~34 minecraft:glowstone
fill ~55~1~33 ~55~1~34 minecraft:netherrack
fill ~55~2~33 ~55~2~34 minecraft:fire 15
fill ~56~1~33 ~56~1~54 minecraft:sandstone
fill ~57~1~33 ~57~1~34 minecraft:glowstone
setblock ~58~8~33 minecraft:glowstone
setblock ~59~1~33 minecraft:glowstone
fill ~62~10~33 ~62~10~34 minecraft:glowstone
fill ~64~11~33 ~64~11~34 minecraft:glowstone
fill ~66~12~33 ~66~12~34 minecraft:glowstone
setblock ~67~1~33 minecraft:glowstone
fill ~68~1~33 ~68~1~35 minecraft:stone 1
fill ~68~3~33 ~68~3~42 minecraft:stonebrick 0
setblock ~68~4~33 minecraft:gold_block
setblock ~68~8~33 minecraft:glowstone
fill ~1~6~34 ~1~6~37 minecraft:stonebrick 0
setblock ~1~7~34 minecraft:gold_block
setblock ~11~1~34 minecraft:glowstone
fill ~58~8~34 ~58~8~53 minecraft:stonebrick 0
fill ~59~1~34 ~59~1~52 minecraft:stonebrick 0
fill ~67~1~34 ~67~1~52 minecraft:stonebrick 0
fill ~68~4~34 ~68~4~41 minecraft:stonebrick 0
setblock ~68~5~34 minecraft:gold_block
fill ~68~8~34 ~68~8~36 minecraft:stonebrick 0
setblock ~1~0~35 minecraft:stone 0
fill ~1~7~35 ~1~7~36 minecraft:stonebrick 0
fill ~1~8~35 ~1~8~36 minecraft:gold_block
fill ~2~0~35 ~2~0~40 minecraft:stone 5
fill ~3~12~35 ~3~12~52 minecraft:stonebrick 0
fill ~5~11~35 ~5~11~52 minecraft:stonebrick 0
fill ~7~10~35 ~7~10~52 minecraft:stonebrick 0
fill ~11~1~35 ~11~1~56 minecraft:stonebrick 0
fill ~12~1~35 ~12~1~54 minecraft:sandstone
fill ~14~1~35 ~14~1~53 minecraft:sandstone
fill ~16~1~35 ~16~1~51 minecraft:sandstone
fill ~19~1~35 ~19~1~43 minecraft:sandstone
setblock ~32~9~35 minecraft:trapdoor 2
fill ~34~9~35 ~35~9~35 minecraft:trapdoor 3
fill ~34~17~35 ~35~17~66 minecraft:stonebrick 0
setblock ~37~9~35 minecraft:trapdoor 2
fill ~50~1~35 ~50~1~43 minecraft:sandstone
fill ~53~1~35 ~53~1~51 minecraft:sandstone
fill ~55~1~35 ~55~1~53 minecraft:sandstone
fill ~57~1~35 ~57~1~54 minecraft:sandstone
fill ~62~10~35 ~62~10~52 minecraft:stonebrick 0
fill ~64~11~35 ~64~11~52 minecraft:stonebrick 0
fill ~66~12~35 ~66~12~52 minecraft:stonebrick 0
fill ~68~5~35 ~68~5~40 minecraft:stonebrick 0
setblock ~68~6~35 minecraft:gold_block
fill ~1~0~36 ~1~0~40 minecraft:stone 5
fill ~3~0~36 ~4~0~40 minecraft:stone 5
fill ~5~0~36 ~7~0~37 minecraft:stone 0
fill ~15~0~36 ~18~0~38 minecraft:dirt 0
setblock ~22~1~36 minecraft:glowstone
setblock ~23~1~36 minecraft:stone_block_slab 7
setblock ~24~1~36 minecraft:wooden_slab 5
setblock ~25~1~36 minecraft:wooden_slab 0
setblock ~33~9~36 minecraft:trapdoor 1
fill ~33~17~36 ~33~17~66 minecraft:stonebrick 0
fill ~34~9~36 ~35~9~36 minecraft:glowstone
fill ~34~10~36 ~35~10~36 minecraft:nether_brick_fence
setblock ~36~9~36 minecraft:trapdoor 1
fill ~36~17~36 ~36~17~66 minecraft:stonebrick 0
setblock ~44~1~36 minecraft:wooden_slab 0
setblock ~45~1~36 minecraft:wooden_slab 5
setblock ~46~1~36 minecraft:stone_block_slab 7
setblock ~47~1~36 minecraft:glowstone
fill ~68~1~36 ~68~1~67 minecraft:stone 0
fill ~68~6~36 ~68~6~39 minecraft:stonebrick 0
setblock ~68~7~36 minecraft:gold_block
fill ~1~1~37 ~1~1~40 minecraft:stone 5
setblock ~1~7~37 minecraft:gold_block
setblock ~1~8~37 minecraft:glowstone
setblock ~2~1~37 minecraft:glowstone
fill ~8~0~37 ~8~0~40 minecraft:coal_ore
setblock ~10~1~37 minecraft:glowstone
setblock ~11~8~37 minecraft:glowstone
fill ~12~9~37 ~13~9~37 minecraft:nether_brick_fence
fill ~13~7~37 ~13~8~37 minecraft:nether_brick_fence
fill ~14~0~37 ~14~0~42 minecraft:dirt 0
setblock ~14~7~37 minecraft:netherrack
setblock ~14~8~37 minecraft:fire 15
fill ~22~1~37 ~23~1~47 minecraft:sandstone
setblock ~24~1~37 minecraft:stone_block_slab 7
setblock ~25~1~37 minecraft:wooden_slab 5
setblock ~26~1~37 minecraft:wooden_slab 0
fill ~32~17~37 ~32~17~66 minecraft:stonebrick 0
fill ~34~9~37 ~35~9~37 minecraft:trapdoor 2
fill ~37~17~37 ~37~17~66 minecraft:stonebrick 0
setblock ~43~1~37 minecraft:wooden_slab 0
setblock ~44~1~37 minecraft:wooden_slab 5
setblock ~45~1~37 minecraft:stone_block_slab 7
fill ~46~1~37 ~47~1~47 minecraft:sandstone
setblock ~55~7~37 minecraft:netherrack
setblock ~55~8~37 minecraft:fire 15
fill ~56~7~37 ~56~9~37 minecraft:nether_brick_fence
setblock ~57~9~37 minecraft:nether_brick_fence
fill ~68~7~37 ~68~7~38 minecraft:stonebrick 0
fill ~68~8~37 ~68~8~38 minecraft:gold_block
setblock ~1~6~38 minecraft:gold_block
fill ~1~7~38 ~1~8~47 minecraft:stonebrick 0
fill ~2~1~38 ~2~1~52 minecraft:stonebrick 0
fill ~5~0~38 ~5~0~39 minecraft:stone 5
fill ~6~0~38 ~6~0~44 minecraft:stone 0
fill ~7~0~38 ~7~0~41 minecraft:coal_ore
fill ~10~1~38 ~10~1~52 minecraft:stonebrick 0
fill ~11~8~38 ~11~8~53 minecraft:stonebrick 0
setblock ~19~0~38 minecraft:iron_ore
fill ~24~1~38 ~24~1~48 minecraft:sandstone
setblock ~25~1~38 minecraft:stone_block_slab 7
setblock ~26~1~38 minecraft:wooden_slab 5
setblock ~27~1~38 minecraft:wooden_slab 0
fill ~31~17~38 ~31~17~66 minecraft:stonebrick 0
fill ~38~17~38 ~38~17~66 minecraft:stonebrick 0
setblock ~42~1~38 minecraft:wooden_slab 0
setblock ~43~1~38 minecraft:wooden_slab 5
setblock ~44~1~38 minecraft:stone_block_slab 7
fill ~45~1~38 ~45~1~48 minecraft:sandstone
fill ~56~17~38 ~66~17~66 minecraft:stonebrick 0
fill ~68~17~38 ~68~17~40 minecraft:stone 0
setblock ~1~5~39 minecraft:gold_block
fill ~1~6~39 ~1~6~46 minecraft:stonebrick 0
fill ~13~0~39 ~13~0~42 minecraft:dirt 0
fill ~15~0~39 ~17~0~39 minecraft:dirt 0
fill ~18~0~39 ~19~0~47 minecraft:stone 0
fill ~25~1~39 ~25~1~49 minecraft:sandstone
setblock ~26~1~39 minecraft:stone_block_slab 7
setblock ~27~1~39 minecraft:wooden_slab 5
setblock ~28~1~39 minecraft:wooden_slab 0
fill ~30~17~39 ~30~17~66 minecraft:stonebrick 0
fill ~39~17~39 ~39~17~66 minecraft:stonebrick 0
setblock ~41~1~39 minecraft:wooden_slab 0
setblock ~42~1~39 minecraft:wooden_slab 5
setblock ~43~1~39 minecraft:stone_block_slab 7
fill ~44~1~39 ~44~1~49 minecraft:sandstone
setblock ~67~17~39 minecraft:stonebrick 0
setblock ~68~7~39 minecraft:gold_block
fill ~68~8~39 ~68~8~50 minecraft:stonebrick 0
setblock ~1~4~40 minecraft:gold_block
fill ~1~5~40 ~1~5~45 minecraft:stonebrick 0
fill ~2~13~40 ~2~13~52 minecraft:dark_oak_stairs 1
fill ~4~12~40 ~4~12~52 minecraft:dark_oak_stairs 1
fill ~5~0~40 ~5~0~46 minecraft:stone 0
fill ~6~11~40 ~6~11~52 minecraft:dark_oak_stairs 1
fill ~15~0~40 ~16~0~41 minecraft:dirt 0
fill ~17~0~40 ~17~0~67 minecraft:stone 0
fill ~26~1~40 ~26~1~49 minecraft:sandstone
setblock ~27~1~40 minecraft:stone_block_slab 7
setblock ~28~1~40 minecraft:wooden_slab 5
setblock ~29~1~40 minecraft:wooden_slab 0
fill ~29~17~40 ~29~17~66 minecraft:stonebrick 0
setblock ~40~1~40 minecraft:wooden_slab 0
fill ~40~17~40 ~40~17~66 minecraft:stonebrick 0
setblock ~41~1~40 minecraft:wooden_slab 5
setblock ~42~1~40 minecraft:stone_block_slab 7
fill ~43~1~40 ~43~1~49 minecraft:sandstone
fill ~63~11~40 ~63~11~52 minecraft:dark_oak_stairs 0
fill ~65~12~40 ~65~12~52 minecraft:dark_oak_stairs 0
fill ~67~13~40 ~67~13~52 minecraft:dark_oak_stairs 0
setblock ~68~6~40 minecraft:gold_block
fill ~68~7~40 ~68~7~49 minecraft:stonebrick 0
fill ~1~0~41 ~2~0~41 minecraft:stone 0
fill ~1~1~41 ~1~1~44 minecraft:stone 0
setblock ~1~3~41 minecraft:gold_block
fill ~1~4~41 ~1~4~44 minecraft:stonebrick 0
fill ~3~0~41 ~3~0~50 minecraft:stone 5
fill ~4~0~41 ~4~0~42 minecraft:stone 0
fill ~8~0~41 ~8~0~44 minecraft:stone 0
setblock ~27~1~41 minecraft:glowstone
setblock ~28~1~41 minecraft:stone_block_slab 7
fill ~28~17~41 ~28~17~66 minecraft:stonebrick 0
setblock ~29~1~41 minecraft:wooden_slab 5
setblock ~30~1~41 minecraft:wooden_slab 0
setblock ~39~1~41 minecraft:wooden_slab 0
setblock ~40~1~41 minecraft:wooden_slab 5
setblock ~41~1~41 minecraft:stone_block_slab 7
fill ~41~17~41 ~41~17~66 minecraft:stonebrick 0
setblock ~42~1~41 minecraft:glowstone
fill ~49~0~41 ~50~0~45 minecraft:stone 1
setblock ~68~5~41 minecraft:gold_block
fill ~68~6~41 ~68~6~48 minecraft:stonebrick 0
fill ~1~0~42 ~1~0~43 minecraft:stone 0
fill ~1~2~42 ~1~2~43 minecraft:gold_block
fill ~1~3~42 ~1~3~43 minecraft:stonebrick 0
fill ~2~0~42 ~2~0~50 minecraft:stone 5
fill ~7~0~42 ~7~0~44 minecraft:stone 0
setblock ~12~0~42 minecraft:dirt 0
fill ~15~0~42 ~16~0~60 minecraft:stone 0
fill ~27~1~42 ~28~1~49 minecraft:sandstone
fill ~27~17~42 ~27~17~66 minecraft:stonebrick 0
setblock ~29~1~42 minecraft:stone_block_slab 7
setblock ~30~1~42 minecraft:wooden_slab 5
setblock ~31~1~42 minecraft:wooden_slab 0
setblock ~38~1~42 minecraft:wooden_slab 0
setblock ~39~1~42 minecraft:wooden_slab 5
setblock ~40~1~42 minecraft:stone_block_slab 7
fill ~41~1~42 ~42~1~49 minecraft:sandstone
fill ~42~17~42 ~42~17~66 minecraft:stonebrick 0
fill ~51~0~42 ~51~0~45 minecraft:stone 1
setblock ~58~0~42 minecraft:stone 0
fill ~59~0~42 ~60~0~42 minecraft:iron_ore
fill ~61~0~42 ~65~0~48 minecraft:stone 0
setblock ~62~6~42 minecraft:netherrack
setblock ~62~7~42 minecraft:fire 15
fill ~63~6~42 ~63~8~42 minecraft:nether_brick_fence
setblock ~64~6~42 minecraft:netherrack
setblock ~64~7~42 minecraft:fire 15
fill ~67~17~42 ~67~17~66 minecraft:stonebrick 0
setblock ~68~4~42 minecraft:gold_block
fill ~68~5~42 ~68~5~47 minecraft:stonebrick 0
fill ~4~0~43 ~4~0~49 minecraft:stone 5
fill ~11~0~43 ~13~0~45 minecraft:stone 3
fill ~12~9~43 ~13~9~43 minecraft:nether_brick_fence
fill ~13~7~43 ~13~8~43 minecraft:nether_brick_fence
fill ~14~0~43 ~14~0~67 minecraft:stone 0
setblock ~14~7~43 minecraft:netherrack
setblock ~14~8~43 minecraft:fire 15
fill ~26~17~43 ~26~17~66 minecraft:stonebrick 0
fill ~29~1~43 ~29~1~49 minecraft:sandstone
setblock ~30~1~43 minecraft:stone_block_slab 7
setblock ~31~1~43 minecraft:wooden_slab 5
setblock ~32~1~43 minecraft:wooden_slab 0
setblock ~37~1~43 minecraft:wooden_slab 0
setblock ~38~1~43 minecraft:wooden_slab 5
setblock ~39~1~43 minecraft:stone_block_slab 7
fill ~40~1~43 ~40~1~49 minecraft:sandstone
fill ~43~17~43 ~43~17~66 minecraft:stonebrick 0
fill ~52~0~43 ~53~0~45 minecraft:stone 1
setblock ~55~7~43 minecraft:netherrack
setblock ~55~8~43 minecraft:fire 15
fill ~56~7~43 ~56~9~43 minecraft:nether_brick_fence
setblock ~57~9~43 minecraft:nether_brick_fence
fill ~58~0~43 ~59~0~43 minecraft:iron_ore
fill ~60~0~43 ~60~0~67 minecraft:stone 0
setblock ~68~3~43 minecraft:gold_block
fill ~68~4~43 ~68~4~46 minecraft:stonebrick 0
fill ~1~0~44 ~1~0~49 minecraft:stone 5
fill ~1~2~44 ~1~2~55 minecraft:stonebrick 0
setblock ~1~3~44 minecraft:gold_block
setblock ~1~16~44 minecraft:glowstone
fill ~9~0~44 ~9~0~46 minecraft:stone 5
setblock ~10~0~44 minecraft:stone 3
setblock ~19~1~44 minecraft:netherrack
setblock ~19~2~44 minecraft:fire 15
fill ~25~17~44 ~25~17~66 minecraft:stonebrick 0
fill ~30~1~44 ~30~1~49 minecraft:sandstone
setblock ~31~1~44 minecraft:stone_block_slab 7
setblock ~32~1~44 minecraft:wooden_slab 5
fill ~33~1~44 ~36~1~44 minecraft:wooden_slab 0
setblock ~37~1~44 minecraft:wooden_slab 5
setblock ~38~1~44 minecraft:stone_block_slab 7
fill ~39~1~44 ~39~1~49 minecraft:sandstone
fill ~44~17~44 ~44~17~66 minecraft:stonebrick 0
setblock ~50~1~44 minecraft:netherrack
setblock ~50~2~44 minecraft:fire 15
fill ~54~0~44 ~54~0~45 minecraft:stone 1
fill ~58~0~44 ~59~0~56 minecraft:stone 0
fill ~68~2~44 ~68~2~45 minecraft:gold_block
fill ~68~3~44 ~68~3~45 minecraft:stonebrick 0
setblock ~68~16~44 minecraft:glowstone
fill ~1~1~45 ~1~1~49 minecraft:stone 5
fill ~1~3~45 ~1~3~54 minecraft:stonebrick 0
setblock ~1~4~45 minecraft:gold_block
setblock ~1~16~45 minecraft:stonebrick 0
fill ~6~0~45 ~8~0~47 minecraft:stone 5
fill ~10~0~45 ~10~0~46 minecraft:stone 5
fill ~19~1~45 ~19~1~47 minecraft:soul_sand
fill ~24~17~45 ~24~17~66 minecraft:stonebrick 0
fill ~31~1~45 ~31~1~49 minecraft:sandstone
setblock ~32~1~45 minecraft:stone_block_slab 7
fill ~33~1~45 ~36~1~45 minecraft:wooden_slab 5
setblock ~37~1~45 minecraft:stone_block_slab 7
fill ~38~1~45 ~38~1~49 minecraft:sandstone
fill ~45~17~45 ~45~17~66 minecraft:stonebrick 0
fill ~50~1~45 ~50~1~47 minecraft:soul_sand
setblock ~68~16~45 minecraft:stonebrick 0
fill ~1~4~46 ~1~4~53 minecraft:stonebrick 0
setblock ~1~5~46 minecraft:gold_block
setblock ~1~16~46 minecraft:glowstone
setblock ~5~6~46 minecraft:netherrack
setblock ~5~7~46 minecraft:fire 15
fill ~6~6~46 ~6~8~46 minecraft:nether_brick_fence
setblock ~7~6~46 minecraft:netherrack
setblock ~7~7~46 minecraft:fire 15
fill ~11~0~46 ~12~0~47 minecraft:stone 3
fill ~13~0~46 ~13~0~67 minecraft:stone 0
setblock ~17~1~46 minecraft:glowstone
fill ~20~1~46 ~20~1~47 minecraft:soul_sand
fill ~23~17~46 ~23~17~66 minecraft:stonebrick 0
setblock ~32~1~46 minecraft:glowstone
fill ~33~1~46 ~36~1~46 minecraft:stone_block_slab 7
setblock ~37~1~46 minecraft:glowstone
fill ~46~17~46 ~46~17~66 minecraft:stonebrick 0
fill ~49~0~46 ~54~0~67 minecraft:stone 0
fill ~49~1~46 ~49~1~47 minecraft:soul_sand
setblock ~52~1~46 minecraft:glowstone
fill ~68~2~46 ~68~2~57 minecraft:stonebrick 0
setblock ~68~3~46 minecraft:gold_block
setblock ~68~16~46 minecraft:glowstone
fill ~1~5~47 ~1~5~52 minecraft:stonebrick 0
setblock ~1~6~47 minecraft:gold_block
setblock ~1~16~47 minecraft:stonebrick 0
fill ~5~0~47 ~5~0~49 minecraft:stone 3
fill ~9~0~47 ~10~0~48 minecraft:stone 3
fill ~17~1~47 ~18~1~49 minecraft:sandstone
fill ~21~1~47 ~21~1~49 minecraft:soul_sand
fill ~22~17~47 ~22~17~66 minecraft:stonebrick 0
fill ~32~1~47 ~37~1~48 minecraft:sandstone
fill ~47~17~47 ~47~17~66 minecraft:stonebrick 0
fill ~48~1~47 ~48~1~49 minecraft:soul_sand
fill ~51~1~47 ~52~1~49 minecraft:sandstone
fill ~68~3~47 ~68~3~56 minecraft:stonebrick 0
setblock ~68~4~47 minecraft:gold_block
setblock ~68~16~47 minecraft:stonebrick 0
fill ~1~6~48 ~1~6~51 minecraft:stonebrick 0
setblock ~1~7~48 minecraft:gold_block
setblock ~1~8~48 minecraft:stonebrick 0
setblock ~1~16~48 minecraft:glowstone
fill ~6~0~48 ~8~0~49 minecraft:stone 3
fill ~11~0~48 ~12~0~67 minecraft:stone 0
fill ~18~0~48 ~18~0~67 minecraft:stone 0
fill ~19~0~48 ~20~0~49 minecraft:coal_ore
setblock ~19~1~48 minecraft:sandstone
setblock ~20~1~48 minecraft:glowstone
fill ~21~17~48 ~21~17~66 minecraft:stonebrick 0
fill ~22~0~48 ~25~0~48 minecraft:stone 0
fill ~22~1~48 ~22~1~50 minecraft:soul_sand
setblock ~23~1~48 minecraft:sandstone
fill ~26~0~48 ~30~0~48 minecraft:stone 5
fill ~31~0~48 ~34~0~55 minecraft:stone 0
fill ~35~0~48 ~40~0~48 minecraft:stone 3
fill ~41~0~48 ~48~0~57 minecraft:stone 0
setblock ~46~1~48 minecraft:sandstone
fill ~47~1~48 ~47~1~50 minecraft:soul_sand
fill ~48~17~48 ~48~17~66 minecraft:stonebrick 0
setblock ~49~1~48 minecraft:glowstone
setblock ~50~1~48 minecraft:sandstone
fill ~68~4~48 ~68~4~55 minecraft:stonebrick 0
setblock ~68~5~48 minecraft:gold_block
setblock ~68~16~48 minecraft:glowstone
fill ~1~7~49 ~1~7~50 minecraft:stonebrick 0
fill ~1~8~49 ~1~8~50 minecraft:gold_block
fill ~1~16~49 ~1~16~66 minecraft:stonebrick 0
fill ~9~0~49 ~10~0~67 minecraft:stone 0
fill ~12~9~49 ~13~9~49 minecraft:nether_brick_fence
fill ~13~7~49 ~13~8~49 minecraft:nether_brick_fence
setblock ~14~7~49 minecraft:netherrack
setblock ~14~8~49 minecraft:fire 15
setblock ~19~1~49 minecraft:glowstone
fill ~20~1~49 ~20~1~56 minecraft:sandstone
fill ~20~17~49 ~20~17~66 minecraft:stonebrick 0
fill ~21~0~49 ~22~0~49 minecraft:coal_ore
fill ~23~0~49 ~25~0~63 minecraft:stone 0
fill ~23~1~49 ~23~1~51 minecraft:soul_sand
setblock ~24~1~49 minecraft:netherrack
setblock ~24~2~49 minecraft:fire 15
fill ~26~0~49 ~28~0~49 minecraft:stone 5
fill ~29~0~49 ~30~0~67 minecraft:stone 0
fill ~32~1~49 ~33~1~49 minecraft:sandstone
fill ~34~1~49 ~35~1~49 minecraft:glowstone
fill ~35~0~49 ~38~0~49 minecraft:stone 3
fill ~36~1~49 ~37~1~49 minecraft:sandstone
fill ~39~0~49 ~40~0~56 minecraft:stone 0
setblock ~45~1~49 minecraft:netherrack
setblock ~45~2~49 minecraft:fire 15
fill ~46~1~49 ~46~1~51 minecraft:soul_sand
fill ~49~1~49 ~49~1~56 minecraft:sandstone
fill ~49~17~49 ~49~17~66 minecraft:stonebrick 0
setblock ~50~1~49 minecraft:glowstone
setblock ~55~7~49 minecraft:netherrack
setblock ~55~8~49 minecraft:fire 15
fill ~56~7~49 ~56~9~49 minecraft:nether_brick_fence
setblock ~57~9~49 minecraft:nether_brick_fence
fill ~61~0~49 ~64~0~49 minecraft:stone 0
fill ~65~0~49 ~65~0~51 minecraft:stone 5
fill ~68~5~49 ~68~5~54 minecraft:stonebrick 0
setblock ~68~6~49 minecraft:gold_block
fill ~68~16~49 ~68~16~66 minecraft:stonebrick 0
fill ~1~0~50 ~1~1~53 minecraft:stone 0
fill ~4~0~50 ~8~0~50 minecraft:stone 0
setblock ~17~1~50 minecraft:sandstone
setblock ~18~1~50 minecraft:glowstone
fill ~19~0~50 ~22~0~64 minecraft:stone 0
fill ~19~1~50 ~19~1~56 minecraft:sandstone
fill ~19~17~50 ~19~17~66 minecraft:stonebrick 0
fill ~21~1~50 ~21~1~56 minecraft:sandstone
fill ~24~1~50 ~45~1~51 minecraft:soul_sand
fill ~26~0~50 ~28~0~67 minecraft:stone 0
fill ~35~0~50 ~37~0~50 minecraft:stone 3
fill ~38~0~50 ~38~0~56 minecraft:stone 0
fill ~48~1~50 ~48~1~56 minecraft:sandstone
fill ~50~1~50 ~50~1~56 minecraft:sandstone
fill ~50~17~50 ~50~17~66 minecraft:stonebrick 0
setblock ~51~1~50 minecraft:glowstone
setblock ~52~1~50 minecraft:sandstone
fill ~61~0~50 ~63~0~67 minecraft:stone 0
setblock ~64~0~50 minecraft:stone 5
fill ~66~0~50 ~67~0~51 minecraft:stone 5
setblock ~68~0~50 minecraft:stone 0
fill ~68~6~50 ~68~6~53 minecraft:stonebrick 0
setblock ~68~7~50 minecraft:gold_block
setblock ~1~7~51 minecraft:gold_block
fill ~1~8~51 ~1~8~52 minecraft:stonebrick 0
fill ~2~0~51 ~5~0~53 minecraft:stone 0
fill ~6~0~51 ~7~0~52 minecraft:iron_ore
fill ~8~0~51 ~8~0~67 minecraft:stone 0
setblock ~17~1~51 minecraft:glowstone
fill ~18~1~51 ~18~1~56 minecraft:sandstone
fill ~18~17~51 ~18~17~66 minecraft:stonebrick 0
setblock ~22~1~51 minecraft:glowstone
fill ~35~0~51 ~37~0~55 minecraft:stone 0
setblock ~47~1~51 minecraft:glowstone
fill ~51~1~51 ~51~1~56 minecraft:sandstone
fill ~51~17~51 ~51~17~66 minecraft:stonebrick 0
setblock ~52~1~51 minecraft:glowstone
fill ~64~0~51 ~64~0~67 minecraft:stone 0
setblock ~68~0~51 minecraft:stone 5
fill ~68~7~51 ~68~7~52 minecraft:stonebrick 0
fill ~68~8~51 ~68~8~52 minecraft:gold_block
setblock ~1~6~52 minecraft:gold_block
fill ~1~7~52 ~1~7~61 minecraft:stonebrick 0
setblock ~16~1~52 minecraft:glowstone
fill ~17~1~52 ~17~1~56 minecraft:sandstone
fill ~17~17~52 ~17~17~66 minecraft:stonebrick 0
fill ~22~1~52 ~33~1~56 minecraft:sandstone
fill ~34~1~52 ~35~1~52 minecraft:glowstone
fill ~36~1~52 ~47~1~56 minecraft:sandstone
fill ~52~1~52 ~52~1~56 minecraft:sandstone
fill ~52~17~52 ~52~17~66 minecraft:stonebrick 0
setblock ~53~1~52 minecraft:glowstone
fill ~65~0~52 ~68~0~67 minecraft:stone 0
setblock ~1~5~53 minecraft:gold_block
fill ~1~6~53 ~1~6~60 minecraft:stonebrick 0
setblock ~1~8~53 minecraft:glowstone
setblock ~2~1~53 minecraft:glowstone
fill ~2~13~53 ~2~13~60 minecraft:stone_block_slab 5
setblock ~3~12~53 minecraft:glowstone
fill ~4~12~53 ~4~12~61 minecraft:stone_block_slab 5
setblock ~5~11~53 minecraft:glowstone
fill ~6~0~53 ~7~0~66 minecraft:stone 0
setblock ~6~2~53 minecraft:standing_sign 0
fill ~6~11~53 ~6~11~60 minecraft:stone_block_slab 5
setblock ~7~10~53 minecraft:glowstone
setblock ~10~1~53 minecraft:glowstone
fill ~11~11~53 ~11~15~53 minecraft:glass
setblock ~15~1~53 minecraft:glowstone
fill ~16~1~53 ~16~1~56 minecraft:sandstone
fill ~16~17~53 ~16~17~66 minecraft:stonebrick 0
fill ~34~1~53 ~35~1~53 minecraft:sandstone
fill ~53~1~53 ~53~1~56 minecraft:sandstone
fill ~53~17~53 ~53~17~66 minecraft:stonebrick 0
setblock ~54~1~53 minecraft:glowstone
fill ~58~11~53 ~58~15~53 minecraft:glass
setblock ~59~1~53 minecraft:glowstone
setblock ~62~10~53 minecraft:glowstone
setblock ~63~2~53 minecraft:standing_sign 0
fill ~63~11~53 ~63~11~60 minecraft:stone_block_slab 5
setblock ~64~11~53 minecraft:glowstone
fill ~65~12~53 ~65~12~61 minecraft:stone_block_slab 5
setblock ~66~12~53 minecraft:glowstone
setblock ~67~1~53 minecraft:glowstone
fill ~67~13~53 ~67~13~60 minecraft:stone_block_slab 5
setblock ~68~7~53 minecraft:gold_block
setblock ~68~8~53 minecraft:glowstone
fill ~1~0~54 ~3~0~54 minecraft:stone 5
fill ~1~1~54 ~1~1~67 minecraft:stone 0
setblock ~1~4~54 minecraft:gold_block
fill ~1~5~54 ~1~5~59 minecraft:stonebrick 0
fill ~1~8~54 ~1~8~62 minecraft:stonebrick 0
fill ~2~1~54 ~2~1~65 minecraft:stonebrick 0
fill ~3~12~54 ~3~12~67 minecraft:stonebrick 0
fill ~4~0~54 ~5~0~58 minecraft:stone 0
fill ~5~11~54 ~5~11~67 minecraft:stonebrick 0
fill ~7~10~54 ~7~10~67 minecraft:stonebrick 0
fill ~10~1~54 ~10~1~57 minecraft:stonebrick 0
setblock ~11~2~54 minecraft:glowstone
fill ~11~10~54 ~11~10~60 minecraft:stone_block_slab 5
fill ~12~2~54 ~12~10~54 minecraft:stonebrick 0
fill ~12~11~54 ~12~15~54 minecraft:glass
setblock ~12~16~54 minecraft:stonebrick 0
setblock ~14~1~54 minecraft:glowstone
fill ~15~1~54 ~15~1~56 minecraft:sandstone
fill ~15~17~54 ~15~17~66 minecraft:stonebrick 0
setblock ~19~7~54 minecraft:netherrack
setblock ~19~8~54 minecraft:fire 15
setblock ~25~7~54 minecraft:netherrack
setblock ~25~8~54 minecraft:fire 15
setblock ~31~7~54 minecraft:netherrack
setblock ~31~8~54 minecraft:fire 15
fill ~34~1~54 ~35~1~54 minecraft:netherrack
fill ~34~2~54 ~35~2~54 minecraft:fire 15
setblock ~37~7~54 minecraft:netherrack
setblock ~37~8~54 minecraft:fire 15
setblock ~43~7~54 minecraft:netherrack
setblock ~43~8~54 minecraft:fire 15
setblock ~49~7~54 minecraft:netherrack
setblock ~49~8~54 minecraft:fire 15
fill ~54~1~54 ~54~1~56 minecraft:sandstone
fill ~54~17~54 ~54~17~66 minecraft:stonebrick 0
setblock ~55~1~54 minecraft:glowstone
fill ~57~2~54 ~57~10~54 minecraft:stonebrick 0
fill ~57~11~54 ~57~15~54 minecraft:glass
setblock ~57~16~54 minecraft:stonebrick 0
setblock ~58~2~54 minecraft:glowstone
fill ~58~10~54 ~58~10~60 minecraft:stone_block_slab 5
fill ~59~1~54 ~59~1~57 minecraft:stonebrick 0
fill ~62~10~54 ~62~10~63 minecraft:stonebrick 0
fill ~64~11~54 ~64~11~67 minecraft:stonebrick 0
fill ~66~12~54 ~66~12~67 minecraft:stonebrick 0
fill ~67~1~54 ~67~1~65 minecraft:stonebrick 0
setblock ~68~6~54 minecraft:gold_block
fill ~68~7~54 ~68~8~63 minecraft:stonebrick 0
fill ~1~0~55 ~2~0~55 minecraft:stone 5
setblock ~1~3~55 minecraft:gold_block
fill ~1~4~55 ~1~4~58 minecraft:stonebrick 0
fill ~3~0~55 ~3~0~58 minecraft:stone 0
setblock ~12~1~55 minecraft:stonebrick 0
setblock ~12~2~55 minecraft:dark_oak_door 2
setblock ~12~4~55 minecraft:wall_sign 4
fill ~12~9~55 ~13~9~67 minecraft:stonebrick 0
fill ~12~10~55 ~12~10~60 minecraft:stone_block_slab 5
setblock ~13~1~55 minecraft:glowstone
fill ~13~4~55 ~13~8~55 minecraft:stonebrick 0
setblock ~13~10~55 minecraft:glowstone
fill ~13~11~55 ~13~15~55 minecraft:glass
setblock ~13~16~55 minecraft:glowstone
fill ~14~1~55 ~14~1~56 minecraft:sandstone
fill ~14~17~55 ~14~17~66 minecraft:stonebrick 0
fill ~19~7~55 ~19~9~55 minecraft:nether_brick_fence
fill ~25~7~55 ~25~9~55 minecraft:nether_brick_fence
fill ~31~7~55 ~31~9~55 minecraft:nether_brick_fence
fill ~34~1~55 ~35~1~55 minecraft:sandstone
fill ~37~7~55 ~37~9~55 minecraft:nether_brick_fence
fill ~43~7~55 ~43~9~55 minecraft:nether_brick_fence
fill ~49~7~55 ~49~9~55 minecraft:nether_brick_fence
fill ~55~1~55 ~55~1~56 minecraft:sandstone
fill ~55~17~55 ~55~17~66 minecraft:stonebrick 0
setblock ~56~1~55 minecraft:glowstone
fill ~56~4~55 ~56~9~55 minecraft:stonebrick 0
setblock ~56~10~55 minecraft:glowstone
fill ~56~11~55 ~56~15~55 minecraft:glass
setblock ~56~16~55 minecraft:glowstone
setblock ~57~1~55 minecraft:stonebrick 0
setblock ~57~2~55 minecraft:dark_oak_door 0
setblock ~57~4~55 minecraft:wall_sign 5
fill ~57~9~55 ~57~9~67 minecraft:stonebrick 0
fill ~57~10~55 ~57~10~60 minecraft:stone_block_slab 5
setblock ~68~5~55 minecraft:gold_block
fill ~68~6~55 ~68~6~62 minecraft:stonebrick 0
fill ~1~0~56 ~2~0~67 minecraft:stone 0
fill ~1~2~56 ~1~2~57 minecraft:gold_block
fill ~1~3~56 ~1~3~57 minecraft:stonebrick 0
setblock ~12~1~56 minecraft:glowstone
fill ~13~1~56 ~13~1~66 minecraft:stonebrick 0
setblock ~13~2~56 minecraft:dark_oak_door 1
setblock ~13~4~56 minecraft:wall_sign 3
fill ~13~10~56 ~13~10~60 minecraft:stone_block_slab 5
fill ~14~2~56 ~14~10~56 minecraft:stonebrick 0
fill ~14~11~56 ~14~15~56 minecraft:glass
setblock ~14~16~56 minecraft:stonebrick 0
setblock ~19~9~56 minecraft:nether_brick_fence
setblock ~25~9~56 minecraft:nether_brick_fence
fill ~31~0~56 ~32~0~56 minecraft:stone 0
setblock ~31~9~56 minecraft:nether_brick_fence
fill ~33~0~56 ~36~0~56 minecraft:stone 1
fill ~34~1~56 ~35~1~56 minecraft:glowstone
setblock ~37~0~56 minecraft:stone 0
setblock ~37~9~56 minecraft:nether_brick_fence
setblock ~43~9~56 minecraft:nether_brick_fence
setblock ~49~9~56 minecraft:nether_brick_fence
fill ~55~2~56 ~55~10~56 minecraft:stonebrick 0
fill ~55~11~56 ~55~15~56 minecraft:glass
setblock ~55~16~56 minecraft:stonebrick 0
fill ~56~1~56 ~56~1~66 minecraft:stonebrick 0
setblock ~56~2~56 minecraft:dark_oak_door 1
setblock ~56~4~56 minecraft:wall_sign 3
fill ~56~9~56 ~56~9~67 minecraft:stonebrick 0
fill ~56~10~56 ~56~10~60 minecraft:stone_block_slab 5
setblock ~57~0~56 minecraft:stonebrick 0
setblock ~57~1~56 minecraft:glowstone
setblock ~68~4~56 minecraft:gold_block
fill ~68~5~56 ~68~5~61 minecraft:stonebrick 0
setblock ~11~1~57 minecraft:glowstone
fill ~12~1~57 ~12~1~66 minecraft:stonebrick 0
fill ~14~1~57 ~55~1~57 minecraft:stonebrick 0
setblock ~14~2~57 minecraft:glowstone
fill ~14~9~57 ~55~9~67 minecraft:stonebrick 0
fill ~14~10~57 ~14~10~60 minecraft:stone_block_slab 5
fill ~15~2~57 ~54~7~57 minecraft:stonebrick 0
fill ~15~8~57 ~36~8~57 minecraft:stonebrick 0
fill ~15~10~57 ~54~10~57 minecraft:stonebrick 0
fill ~15~11~57 ~15~15~57 minecraft:glass
fill ~15~16~57 ~54~16~57 minecraft:stonebrick 0
fill ~16~11~57 ~53~11~57 minecraft:nether_brick_fence
setblock ~31~0~57 minecraft:stone 0
fill ~32~0~57 ~32~0~59 minecraft:stone 1
fill ~33~0~57 ~40~0~59 minecraft:stone 5
setblock ~37~8~57 minecraft:glowstone
fill ~38~8~57 ~54~8~57 minecraft:stonebrick 0
fill ~54~11~57 ~54~15~57 minecraft:glass
setblock ~55~2~57 minecraft:glowstone
fill ~55~10~57 ~55~10~60 minecraft:stone_block_slab 5
fill ~57~0~57 ~57~0~67 minecraft:stone 0
fill ~57~1~57 ~57~1~66 minecraft:stonebrick 0
setblock ~58~0~57 minecraft:stonebrick 0
setblock ~58~1~57 minecraft:glowstone
fill ~59~0~57 ~59~0~67 minecraft:stone 0
setblock ~68~3~57 minecraft:gold_block
fill ~68~4~57 ~68~4~60 minecraft:stonebrick 0
fill ~1~2~58 ~1~2~66 minecraft:stonebrick 0
setblock ~1~3~58 minecraft:gold_block
setblock ~10~1~58 minecraft:glowstone
fill ~11~1~58 ~11~1~66 minecraft:stonebrick 0
fill ~14~1~58 ~14~1~66 minecraft:stonebrick 0
setblock ~15~1~58 minecraft:glowstone
fill ~15~10~58 ~54~10~60 minecraft:stone_block_slab 5
fill ~16~1~58 ~36~1~66 minecraft:stonebrick 0
fill ~31~0~58 ~31~0~59 minecraft:stone 1
setblock ~37~1~58 minecraft:glowstone
fill ~38~1~58 ~53~1~66 minecraft:stonebrick 0
fill ~41~0~58 ~41~0~60 minecraft:stone 5
fill ~42~0~58 ~48~0~58 minecraft:stone 0
setblock ~54~1~58 minecraft:glowstone
fill ~55~1~58 ~55~1~66 minecraft:stonebrick 0
fill ~58~0~58 ~58~0~67 minecraft:stone 0
fill ~58~1~58 ~58~1~66 minecraft:stonebrick 0
setblock ~59~1~58 minecraft:glowstone
fill ~68~2~58 ~68~2~59 minecraft:gold_block
fill ~68~3~58 ~68~3~59 minecraft:stonebrick 0
fill ~1~3~59 ~1~3~66 minecraft:stonebrick 0
setblock ~1~4~59 minecraft:gold_block
fill ~3~0~59 ~4~0~63 minecraft:coal_ore
fill ~5~0~59 ~5~0~66 minecraft:stone 0
fill ~8~10~59 ~8~10~60 minecraft:double_stone_block_slab 5
setblock ~9~1~59 minecraft:glowstone
fill ~10~1~59 ~10~1~66 minecraft:stonebrick 0
fill ~15~1~59 ~15~1~65 minecraft:stonebrick 0
fill ~37~1~59 ~37~1~65 minecraft:stonebrick 0
setblock ~42~0~59 minecraft:stone 5
fill ~43~0~59 ~48~0~67 minecraft:stone 0
fill ~54~1~59 ~54~1~65 minecraft:stonebrick 0
fill ~59~1~59 ~59~1~66 minecraft:stonebrick 0
setblock ~60~1~59 minecraft:glowstone
fill ~61~10~59 ~61~10~60 minecraft:double_stone_block_slab 5
fill ~1~4~60 ~1~4~66 minecraft:stonebrick 0
setblock ~1~5~60 minecraft:gold_block
setblock ~8~1~60 minecraft:glowstone
fill ~9~1~60 ~9~1~66 minecraft:stonebrick 0
setblock ~9~10~60 minecraft:double_stone_block_slab 5
fill ~31~0~60 ~34~0~67 minecraft:stone 0
fill ~35~0~60 ~40~0~60 minecraft:stone 5
fill ~42~0~60 ~42~0~67 minecraft:stone 0
fill ~60~1~60 ~60~1~66 minecraft:stonebrick 0
setblock ~60~10~60 minecraft:double_stone_block_slab 5
setblock ~61~1~60 minecraft:glowstone
fill ~68~2~60 ~68~2~66 minecraft:stonebrick 0
setblock ~68~3~60 minecraft:gold_block
fill ~1~5~61 ~1~5~66 minecraft:stonebrick 0
setblock ~1~6~61 minecraft:gold_block
fill ~2~10~61 ~2~10~62 minecraft:stonebrick 0
fill ~2~13~61 ~2~16~65 minecraft:stonebrick 0
fill ~3~10~61 ~4~10~62 minecraft:double_stone_block_slab 5
fill ~5~10~61 ~5~10~65 minecraft:stonebrick 0
fill ~6~11~61 ~6~11~67 minecraft:stonebrick 0
setblock ~7~1~61 minecraft:glowstone
setblock ~7~11~61 minecraft:stone_block_slab 5
fill ~8~1~61 ~8~1~66 minecraft:stonebrick 0
fill ~8~10~61 ~14~10~67 minecraft:stonebrick 0
setblock ~15~0~61 minecraft:stone 1
setblock ~15~10~61 minecraft:glowstone
fill ~16~0~61 ~16~0~62 minecraft:stone 0
fill ~16~10~61 ~33~10~67 minecraft:stonebrick 0
setblock ~26~6~61 minecraft:netherrack
setblock ~26~7~61 minecraft:fire 15
fill ~34~10~61 ~35~10~61 minecraft:glowstone
fill ~35~0~61 ~41~0~67 minecraft:stone 0
fill ~36~10~61 ~53~10~67 minecraft:stonebrick 0
setblock ~46~6~61 minecraft:netherrack
setblock ~46~7~61 minecraft:fire 15
setblock ~54~10~61 minecraft:glowstone
fill ~55~10~61 ~61~10~67 minecraft:stonebrick 0
fill ~61~1~61 ~61~1~66 minecraft:stonebrick 0
setblock ~62~1~61 minecraft:glowstone
setblock ~62~11~61 minecraft:stone_block_slab 5
fill ~63~11~61 ~63~11~67 minecraft:stonebrick 0
fill ~67~13~61 ~67~16~67 minecraft:stonebrick 0
fill ~68~3~61 ~68~3~66 minecraft:stonebrick 0
setblock ~68~4~61 minecraft:gold_block
fill ~1~6~62 ~1~6~65 minecraft:stonebrick 0
setblock ~1~7~62 minecraft:gold_block
setblock ~3~13~62 minecraft:stone_block_slab 5
fill ~4~12~62 ~4~12~67 minecraft:stonebrick 0
setblock ~5~12~62 minecraft:stone_block_slab 5
setblock ~6~1~62 minecraft:glowstone
fill ~7~1~62 ~7~1~66 minecraft:stonebrick 0
fill ~7~11~62 ~7~11~67 minecraft:stonebrick 0
fill ~8~11~62 ~15~11~62 minecraft:stone_block_slab 5
setblock ~15~0~62 minecraft:stone 0
setblock ~15~2~62 minecraft:standing_sign 4
fill ~15~10~62 ~15~10~67 minecraft:stonebrick 0
fill ~16~11~62 ~28~11~62 minecraft:dark_oak_stairs 2
fill ~26~6~62 ~26~8~62 minecraft:nether_brick_fence
fill ~29~11~62 ~40~11~62 minecraft:stone_block_slab 5
fill ~34~10~62 ~35~10~67 minecraft:stonebrick 0
fill ~41~11~62 ~53~11~62 minecraft:dark_oak_stairs 2
fill ~46~6~62 ~46~8~62 minecraft:nether_brick_fence
setblock ~54~2~62 minecraft:standing_sign 12
fill ~54~10~62 ~54~10~67 minecraft:stonebrick 0
fill ~54~11~62 ~61~11~62 minecraft:stone_block_slab 5
fill ~62~1~62 ~62~1~66 minecraft:stonebrick 0
fill ~62~11~62 ~62~11~67 minecraft:stonebrick 0
setblock ~63~1~62 minecraft:glowstone
setblock ~64~12~62 minecraft:stone_block_slab 5
fill ~65~12~62 ~65~12~67 minecraft:stonebrick 0
setblock ~66~13~62 minecraft:stone_block_slab 5
fill ~68~4~62 ~68~4~66 minecraft:stonebrick 0
setblock ~68~5~62 minecraft:gold_block
fill ~1~7~63 ~1~7~64 minecraft:stonebrick 0
fill ~1~8~63 ~1~8~64 minecraft:gold_block
fill ~2~10~63 ~2~10~66 minecraft:stone_block_slab 5
setblock ~3~10~63 minecraft:stonebrick 0
fill ~3~13~63 ~3~16~67 minecraft:stonebrick 0
setblock ~4~10~63 minecraft:double_stone_block_slab 5
setblock ~4~13~63 minecraft:stone_block_slab 5
setblock ~5~1~63 minecraft:glowstone
fill ~5~12~63 ~5~12~67 minecraft:stonebrick 0
fill ~6~1~63 ~6~1~66 minecraft:stonebrick 0
setblock ~6~12~63 minecraft:stone_block_slab 5
fill ~8~11~63 ~14~11~67 minecraft:stonebrick 0
fill ~15~0~63 ~16~0~65 minecraft:stone 1
setblock ~15~11~63 minecraft:glowstone
fill ~16~11~63 ~33~11~67 minecraft:stonebrick 0
setblock ~26~6~63 minecraft:netherrack
setblock ~26~7~63 minecraft:fire 15
fill ~34~11~63 ~35~11~63 minecraft:glowstone
fill ~36~11~63 ~53~11~67 minecraft:stonebrick 0
setblock ~46~6~63 minecraft:netherrack
setblock ~46~7~63 minecraft:fire 15
setblock ~54~11~63 minecraft:glowstone
fill ~55~11~63 ~61~11~67 minecraft:stonebrick 0
fill ~63~1~63 ~63~1~66 minecraft:stonebrick 0
setblock ~63~12~63 minecraft:stone_block_slab 5
setblock ~64~1~63 minecraft:glowstone
fill ~64~12~63 ~64~12~67 minecraft:stonebrick 0
setblock ~65~13~63 minecraft:stone_block_slab 5
fill ~66~13~63 ~66~16~67 minecraft:stonebrick 0
fill ~68~5~63 ~68~5~66 minecraft:stonebrick 0
setblock ~68~6~63 minecraft:gold_block
setblock ~2~11~64 minecraft:stonebrick 0
fill ~3~0~64 ~4~0~67 minecraft:stone 0
fill ~3~10~64 ~3~10~66 minecraft:stone_block_slab 5
setblock ~4~1~64 minecraft:glowstone
fill ~4~10~64 ~4~11~64 minecraft:stonebrick 0
fill ~4~13~64 ~4~17~64 minecraft:glowstone
fill ~5~1~64 ~5~1~66 minecraft:stonebrick 0
setblock ~5~13~64 minecraft:stone_block_slab 5
fill ~6~12~64 ~6~12~67 minecraft:stonebrick 0
fill ~7~12~64 ~15~12~64 minecraft:stone_block_slab 5
fill ~15~11~64 ~15~11~67 minecraft:stonebrick 0
fill ~16~12~64 ~28~12~64 minecraft:dark_oak_stairs 2
setblock ~23~0~64 minecraft:stone 0
fill ~24~0~64 ~24~0~67 minecraft:stone 5
setblock ~25~0~64 minecraft:stone 0
fill ~29~12~64 ~40~12~64 minecraft:stone_block_slab 5
fill ~34~11~64 ~35~11~67 minecraft:stonebrick 0
fill ~41~12~64 ~53~12~64 minecraft:dark_oak_stairs 2
fill ~54~11~64 ~54~11~67 minecraft:stonebrick 0
fill ~54~12~64 ~62~12~64 minecraft:stone_block_slab 5
fill ~62~10~64 ~63~10~65 minecraft:double_stone_block_slab 5
fill ~63~12~64 ~63~12~67 minecraft:stonebrick 0
fill ~64~1~64 ~64~1~66 minecraft:stonebrick 0
fill ~64~10~64 ~64~10~65 minecraft:stonebrick 0
setblock ~64~13~64 minecraft:stone_block_slab 5
setblock ~65~1~64 minecraft:glowstone
fill ~65~13~64 ~65~16~64 minecraft:glowstone
fill ~68~6~64 ~68~6~66 minecraft:stonebrick 0
setblock ~68~7~64 minecraft:gold_block
setblock ~68~8~64 minecraft:stonebrick 0
setblock ~1~7~65 minecraft:gold_block
setblock ~1~8~65 minecraft:stonebrick 0
setblock ~3~1~65 minecraft:glowstone
fill ~4~1~65 ~4~1~66 minecraft:stonebrick 0
fill ~4~10~65 ~4~10~66 minecraft:stone_block_slab 5
fill ~4~11~65 ~4~11~67 minecraft:stonebrick 0
fill ~4~13~65 ~5~16~67 minecraft:stonebrick 0
fill ~4~17~65 ~4~17~66 minecraft:stonebrick 0
setblock ~6~10~65 minecraft:double_stone_block_slab 5
setblock ~6~13~65 minecraft:stone_block_slab 5
fill ~7~12~65 ~14~12~67 minecraft:stonebrick 0
setblock ~15~12~65 minecraft:glowstone
fill ~16~12~65 ~33~12~67 minecraft:stonebrick 0
fill ~19~0~65 ~21~0~65 minecraft:stone 0
fill ~22~0~65 ~23~0~67 minecraft:stone 5
setblock ~25~0~65 minecraft:stone 5
fill ~34~12~65 ~35~12~65 minecraft:glowstone
fill ~36~12~65 ~53~12~67 minecraft:stonebrick 0
setblock ~54~12~65 minecraft:glowstone
fill ~55~12~65 ~62~12~67 minecraft:stonebrick 0
setblock ~63~13~65 minecraft:stone_block_slab 5
fill ~64~13~65 ~65~16~67 minecraft:stonebrick 0
fill ~65~1~65 ~65~1~66 minecraft:stonebrick 0
fill ~65~10~65 ~67~10~66 minecraft:stone_block_slab 5
setblock ~66~1~65 minecraft:glowstone
fill ~68~7~65 ~68~7~66 minecraft:stonebrick 0
setblock ~68~8~65 minecraft:gold_block
setblock ~1~6~66 minecraft:gold_block
setblock ~1~7~66 minecraft:stonebrick 0
setblock ~1~8~66 minecraft:glowstone
setblock ~2~1~66 minecraft:glowstone
fill ~2~15~66 ~2~16~67 minecraft:stonebrick 0
setblock ~3~1~66 minecraft:stonebrick 0
setblock ~5~10~66 minecraft:stone_block_slab 5
fill ~6~10~66 ~6~10~67 minecraft:stonebrick 0
fill ~6~13~66 ~7~16~67 minecraft:stonebrick 0
fill ~8~13~66 ~15~13~66 minecraft:stone_block_slab 5
fill ~15~0~66 ~16~0~67 minecraft:stone 0
setblock ~15~1~66 minecraft:glowstone
fill ~15~12~66 ~15~12~67 minecraft:stonebrick 0
fill ~16~13~66 ~28~13~66 minecraft:dark_oak_stairs 2
fill ~19~0~66 ~20~0~66 minecraft:stone 0
fill ~21~0~66 ~21~0~67 minecraft:stone 5
fill ~25~0~66 ~25~0~67 minecraft:stone 0
fill ~29~13~66 ~40~13~66 minecraft:stone_block_slab 5
fill ~34~12~66 ~35~12~67 minecraft:stonebrick 0
setblock ~37~1~66 minecraft:glowstone
fill ~41~13~66 ~53~13~66 minecraft:dark_oak_stairs 2
setblock ~54~1~66 minecraft:glowstone
fill ~54~12~66 ~54~12~67 minecraft:stonebrick 0
fill ~54~13~66 ~61~13~66 minecraft:stone_block_slab 5
fill ~62~10~66 ~63~10~67 minecraft:stonebrick 0
fill ~62~13~66 ~63~16~67 minecraft:stonebrick 0
setblock ~64~10~66 minecraft:stone_block_slab 5
setblock ~66~1~66 minecraft:stonebrick 0
setblock ~67~1~66 minecraft:glowstone
setblock ~68~8~66 minecraft:glowstone
fill ~1~2~67 ~1~3~67 minecraft:stone 0
fill ~1~4~67 ~1~6~67 minecraft:stone 3
fill ~1~7~67 ~1~16~67 minecraft:stone 0
fill ~2~1~67 ~3~1~67 minecraft:stone 0
fill ~2~2~67 ~4~2~67 minecraft:stonebrick 0
fill ~2~3~67 ~3~3~67 minecraft:stonebrick 0
setblock ~2~4~67 minecraft:stonebrick 0
setblock ~2~5~67 minecraft:gold_block
fill ~2~6~67 ~9~7~67 minecraft:stonebrick 0
setblock ~2~8~67 minecraft:glowstone
fill ~2~9~67 ~7~9~67 minecraft:stonebrick 0
fill ~2~10~67 ~5~10~67 minecraft:stonebrick 0
fill ~2~11~67 ~3~11~67 minecraft:stonebrick 0
fill ~2~12~67 ~2~14~67 minecraft:stonebrick 0
setblock ~3~4~67 minecraft:gold_block
fill ~3~5~67 ~8~5~67 minecraft:stonebrick 0
fill ~3~8~67 ~11~8~67 minecraft:stonebrick 0
fill ~4~1~67 ~6~1~67 minecraft:stone 1
setblock ~4~3~67 minecraft:gold_block
fill ~4~4~67 ~7~4~67 minecraft:stonebrick 0
fill ~5~0~67 ~6~0~67 minecraft:stone 1
fill ~5~2~67 ~6~2~67 minecraft:gold_block
fill ~5~3~67 ~6~3~67 minecraft:stonebrick 0
fill ~7~0~67 ~7~1~67 minecraft:stone 0
fill ~7~2~67 ~18~2~67 minecraft:stonebrick 0
setblock ~7~3~67 minecraft:gold_block
fill ~8~1~67 ~14~1~67 minecraft:stone 0
fill ~8~3~67 ~17~3~67 minecraft:stonebrick 0
setblock ~8~4~67 minecraft:gold_block
fill ~8~13~67 ~61~15~67 minecraft:stonebrick 0
fill ~8~16~67 ~19~16~67 minecraft:stonebrick 0
fill ~9~4~67 ~16~4~67 minecraft:stonebrick 0
setblock ~9~5~67 minecraft:gold_block
fill ~10~5~67 ~15~5~67 minecraft:stonebrick 0
setblock ~10~6~67 minecraft:gold_block
setblock ~10~7~67 minecraft:stonebrick 0
fill ~11~6~67 ~14~6~67 minecraft:stonebrick 0
setblock ~11~7~67 minecraft:gold_block
fill ~12~7~67 ~13~7~67 minecraft:stonebrick 0
fill ~12~8~67 ~13~8~67 minecraft:gold_block
setblock ~14~7~67 minecraft:gold_block
setblock ~14~8~67 minecraft:stonebrick 0
fill ~15~1~67 ~16~1~67 minecraft:stone 1
setblock ~15~6~67 minecraft:gold_block
fill ~15~7~67 ~24~7~67 minecraft:stonebrick 0
setblock ~15~8~67 minecraft:glowstone
setblock ~16~5~67 minecraft:gold_block
fill ~16~6~67 ~23~6~67 minecraft:stonebrick 0
fill ~16~8~67 ~25~8~67 minecraft:stonebrick 0
fill ~17~1~67 ~19~1~67 minecraft:stone 0
setblock ~17~4~67 minecraft:gold_block
fill ~17~5~67 ~22~5~67 minecraft:stonebrick 0
setblock ~18~3~67 minecraft:gold_block
fill ~18~4~67 ~21~4~67 minecraft:stonebrick 0
setblock ~19~0~67 minecraft:stone 0
fill ~19~2~67 ~20~2~67 minecraft:gold_block
fill ~19~3~67 ~20~3~67 minecraft:stonebrick 0
fill ~20~0~67 ~20~1~67 minecraft:stone 5
setblock ~20~16~67 minecraft:glowstone
fill ~21~1~67 ~24~1~67 minecraft:stone 5
fill ~21~2~67 ~32~2~67 minecraft:stonebrick 0
setblock ~21~3~67 minecraft:gold_block
setblock ~21~16~67 minecraft:stonebrick 0
fill ~22~3~67 ~31~3~67 minecraft:stonebrick 0
setblock ~22~4~67 minecraft:gold_block
setblock ~22~16~67 minecraft:glowstone
fill ~23~4~67 ~30~4~67 minecraft:stonebrick 0
setblock ~23~5~67 minecraft:gold_block
setblock ~23~16~67 minecraft:stonebrick 0
fill ~24~5~67 ~29~5~67 minecraft:stonebrick 0
setblock ~24~6~67 minecraft:gold_block
setblock ~24~16~67 minecraft:glowstone
fill ~25~1~67 ~67~1~67 minecraft:stone 0
fill ~25~6~67 ~28~6~67 minecraft:stonebrick 0
setblock ~25~7~67 minecraft:gold_block
fill ~25~16~67 ~44~16~67 minecraft:stonebrick 0
fill ~26~7~67 ~27~7~67 minecraft:stonebrick 0
fill ~26~8~67 ~27~8~67 minecraft:gold_block
setblock ~28~7~67 minecraft:gold_block
fill ~28~8~67 ~36~8~67 minecraft:stonebrick 0
setblock ~29~6~67 minecraft:gold_block
fill ~29~7~67 ~38~7~67 minecraft:stonebrick 0
setblock ~30~5~67 minecraft:gold_block
fill ~30~6~67 ~37~6~67 minecraft:stonebrick 0
setblock ~31~4~67 minecraft:gold_block
fill ~31~5~67 ~36~5~67 minecraft:stonebrick 0
setblock ~32~3~67 minecraft:gold_block
fill ~32~4~67 ~35~4~67 minecraft:stonebrick 0
fill ~33~2~67 ~34~2~67 minecraft:gold_block
fill ~33~3~67 ~34~3~67 minecraft:stonebrick 0
fill ~35~2~67 ~46~2~67 minecraft:stonebrick 0
setblock ~35~3~67 minecraft:gold_block
fill ~36~3~67 ~45~3~67 minecraft:stonebrick 0
setblock ~36~4~67 minecraft:gold_block
fill ~37~4~67 ~44~4~67 minecraft:stonebrick 0
setblock ~37~5~67 minecraft:gold_block
setblock ~37~8~67 minecraft:glowstone
fill ~38~5~67 ~43~5~67 minecraft:stonebrick 0
setblock ~38~6~67 minecraft:gold_block
fill ~38~8~67 ~39~8~67 minecraft:stonebrick 0
fill ~39~6~67 ~42~6~67 minecraft:stonebrick 0
setblock ~39~7~67 minecraft:gold_block
fill ~40~7~67 ~41~7~67 minecraft:stonebrick 0
fill ~40~8~67 ~41~8~67 minecraft:gold_block
setblock ~42~7~67 minecraft:gold_block
fill ~42~8~67 ~53~8~67 minecraft:stonebrick 0
setblock ~43~6~67 minecraft:gold_block
fill ~43~7~67 ~52~7~67 minecraft:stonebrick 0
setblock ~44~5~67 minecraft:gold_block
fill ~44~6~67 ~51~6~67 minecraft:stonebrick 0
setblock ~45~4~67 minecraft:gold_block
fill ~45~5~67 ~50~5~67 minecraft:stonebrick 0
setblock ~45~16~67 minecraft:glowstone
setblock ~46~3~67 minecraft:gold_block
fill ~46~4~67 ~49~4~67 minecraft:stonebrick 0
setblock ~46~16~67 minecraft:stonebrick 0
fill ~47~2~67 ~48~2~67 minecraft:gold_block
fill ~47~3~67 ~48~3~67 minecraft:stonebrick 0
setblock ~47~16~67 minecraft:glowstone
setblock ~48~16~67 minecraft:stonebrick 0
fill ~49~2~67 ~60~2~67 minecraft:stonebrick 0
setblock ~49~3~67 minecraft:gold_block
setblock ~49~16~67 minecraft:glowstone
fill ~50~3~67 ~59~3~67 minecraft:stonebrick 0
setblock ~50~4~67 minecraft:gold_block
fill ~50~16~67 ~61~16~67 minecraft:stonebrick 0
fill ~51~4~67 ~58~4~67 minecraft:stonebrick 0
setblock ~51~5~67 minecraft:gold_block
fill ~52~5~67 ~57~5~67 minecraft:stonebrick 0
setblock ~52~6~67 minecraft:gold_block
fill ~53~6~67 ~56~6~67 minecraft:stonebrick 0
setblock ~53~7~67 minecraft:gold_block
fill ~54~7~67 ~55~7~67 minecraft:stonebrick 0
setblock ~54~8~67 minecraft:glowstone
setblock ~55~8~67 minecraft:gold_block
setblock ~56~7~67 minecraft:gold_block
fill ~56~8~67 ~66~8~67 minecraft:stonebrick 0
setblock ~57~6~67 minecraft:gold_block
fill ~57~7~67 ~66~7~67 minecraft:stonebrick 0
setblock ~58~5~67 minecraft:gold_block
fill ~58~6~67 ~65~6~67 minecraft:stonebrick 0
setblock ~59~4~67 minecraft:gold_block
fill ~59~5~67 ~64~5~67 minecraft:stonebrick 0
setblock ~60~3~67 minecraft:gold_block
fill ~60~4~67 ~63~4~67 minecraft:stonebrick 0
fill ~61~2~67 ~62~2~67 minecraft:gold_block
fill ~61~3~67 ~62~3~67 minecraft:stonebrick 0
fill ~63~2~67 ~67~2~67 minecraft:stonebrick 0
setblock ~63~3~67 minecraft:gold_block
fill ~64~3~67 ~67~3~67 minecraft:stonebrick 0
setblock ~64~4~67 minecraft:gold_block
fill ~64~10~67 ~67~10~67 minecraft:stonebrick 0
fill ~65~4~67 ~67~4~67 minecraft:stonebrick 0
setblock ~65~5~67 minecraft:gold_block
fill ~66~5~67 ~67~5~67 minecraft:stonebrick 0
setblock ~66~6~67 minecraft:gold_block
setblock ~67~6~67 minecraft:stonebrick 0
setblock ~67~7~67 minecraft:gold_block
setblock ~67~8~67 minecraft:glowstone
setblock ~67~11~67 minecraft:stonebrick 0
fill ~68~2~67 ~68~16~67 minecraft:stone 0