setblock ~4 ~0 ~94 double_stone_slab 7 
setblock ~4 ~0 ~95 stone_slab 7 
setblock ~5 ~0 ~93 double_stone_slab 7 
setblock ~5 ~0 ~94 stone_slab 7 
setblock ~6 ~0 ~89 quartz_stairs 0 
setblock ~6 ~0 ~92 stone_slab 15 
setblock ~6 ~0 ~97 stone_slab 7  
fill ~7 ~0 ~89 ~7 ~1 ~89 double_stone_slab 7 
setblock ~7 ~0 ~94 double_stone_slab 7 
setblock ~7 ~0 ~96 stone_slab 7 
setblock ~7 ~0 ~97 double_stone_slab 7 
setblock ~8 ~0 ~96 double_stone_slab 7  
fill ~9 ~0 ~90 ~13 ~0 ~90 stained_hardened_clay 0  
fill ~9 ~0 ~91 ~12 ~0 ~91 stained_hardened_clay 0  
fill ~9 ~0 ~92 ~11 ~0 ~92 stained_hardened_clay 0 
setblock ~9 ~0 ~95 stone_slab 15  
fill ~10 ~0 ~89 ~12 ~0 ~89 stained_hardened_clay 8  
fill ~11 ~0 ~88 ~11 ~1 ~88 stained_hardened_clay 8  
fill ~12 ~0 ~94 ~12 ~1 ~94 double_stone_slab 7 
setblock ~12 ~0 ~95 quartz_stairs 3  
fill ~13 ~0 ~85 ~17 ~0 ~85 stained_hardened_clay 0  
fill ~13 ~0 ~86 ~17 ~0 ~86 stained_hardened_clay 0  
fill ~14 ~0 ~87 ~16 ~0 ~87 stained_hardened_clay 0  
fill ~15 ~0 ~84 ~17 ~0 ~84 stained_hardened_clay 0  
fill ~15 ~0 ~88 ~16 ~0 ~88 stained_hardened_clay 0 
setblock ~18 ~0 ~82 stone_slab 15 
setblock ~19 ~0 ~82 double_stone_slab 7 
setblock ~19 ~0 ~83 stone_slab 15 
setblock ~54 ~0 ~92 double_stone_slab 7 
setblock ~54 ~0 ~93 stone_slab 7  
fill ~55 ~0 ~-10 ~59 ~0 ~-10 nether_brick 0 
setblock ~55 ~0 ~-9 bedrock 0 
setblock ~55 ~0 ~91 double_stone_slab 7 
setblock ~55 ~0 ~92 stone_slab 7  
fill ~56 ~0 ~-9 ~60 ~0 ~-9 nether_brick 0  
fill ~56 ~0 ~-8 ~61 ~0 ~-8 nether_brick 0 
setblock ~56 ~0 ~87 quartz_stairs 0 
setblock ~56 ~0 ~90 stone_slab 15 
setblock ~56 ~0 ~95 stone_slab 7  
fill ~57 ~0 ~87 ~57 ~1 ~87 double_stone_slab 7 
setblock ~57 ~0 ~92 double_stone_slab 7 
setblock ~57 ~0 ~94 stone_slab 7 
setblock ~57 ~0 ~95 double_stone_slab 7  
fill ~58 ~0 ~-7 ~62 ~0 ~-7 nether_brick 0 
setblock ~58 ~0 ~94 double_stone_slab 7  
fill ~59 ~0 ~-6 ~63 ~0 ~-6 nether_brick 0  
fill ~59 ~0 ~88 ~63 ~0 ~88 stained_hardened_clay 0  
fill ~59 ~0 ~89 ~62 ~0 ~89 stained_hardened_clay 0  
fill ~59 ~0 ~90 ~61 ~0 ~90 stained_hardened_clay 0 
setblock ~59 ~0 ~93 stone_slab 15  
fill ~60 ~0 ~-5 ~63 ~0 ~-5 nether_brick 0  
fill ~60 ~0 ~-4 ~64 ~0 ~-4 nether_brick 0  
fill ~60 ~0 ~87 ~62 ~0 ~87 stained_hardened_clay 0  
fill ~61 ~0 ~-3 ~62 ~0 ~-3 nether_brick 0  
fill ~61 ~0 ~-2 ~61 ~0 ~-8 nether_brick 0  
fill ~61 ~0 ~86 ~61 ~2 ~86 stained_hardened_clay 0  
fill ~62 ~0 ~-2 ~64 ~0 ~-2 bedrock 0  
fill ~62 ~0 ~-1 ~62 ~1 ~-1 nether_brick 0  
fill ~62 ~0 ~0 ~66 ~0 ~0 bedrock 0  
fill ~62 ~0 ~92 ~62 ~1 ~92 double_stone_slab 7 
setblock ~62 ~0 ~93 quartz_stairs 3 
setblock ~63 ~0 ~-3 soul_sand 0 
setblock ~63 ~0 ~-1 bedrock 0  
fill ~63 ~0 ~1 ~67 ~0 ~1 bedrock 0  
fill ~63 ~0 ~2 ~68 ~0 ~2 bedrock 0  
fill ~63 ~0 ~83 ~67 ~0 ~83 stained_hardened_clay 0  
fill ~63 ~0 ~84 ~67 ~0 ~84 stained_hardened_clay 0 
setblock ~64 ~0 ~-3 nether_brick 0  
fill ~64 ~0 ~-1 ~64 ~2 ~-1 nether_brick 0  
fill ~64 ~0 ~3 ~65 ~0 ~3 bedrock 0  
fill ~64 ~0 ~85 ~66 ~0 ~85 stained_hardened_clay 0 
setblock ~65 ~0 ~-1 bedrock 0  
fill ~65 ~0 ~4 ~67 ~0 ~4 bedrock 0  
fill ~65 ~0 ~82 ~67 ~0 ~82 stained_hardened_clay 0  
fill ~65 ~0 ~86 ~66 ~0 ~86 stained_hardened_clay 0  
fill ~66 ~0 ~3 ~66 ~1 ~3 nether_brick 0  
fill ~66 ~0 ~5 ~73 ~0 ~5 bedrock 0  
fill ~67 ~0 ~3 ~70 ~0 ~3 bedrock 0  
fill ~67 ~0 ~6 ~77 ~0 ~6 bedrock 0  
fill ~68 ~0 ~4 ~68 ~3 ~4 nether_brick 0 
setblock ~68 ~0 ~80 stone_slab 15  
fill ~69 ~0 ~4 ~72 ~0 ~4 bedrock 0 
setblock ~69 ~0 ~80 double_stone_slab 7 
setblock ~69 ~0 ~81 stone_slab 15  
fill ~71 ~0 ~7 ~78 ~0 ~7 bedrock 0  
fill ~72 ~0 ~8 ~78 ~0 ~8 bedrock 0  
fill ~75 ~0 ~9 ~76 ~0 ~9 bedrock 0  
fill ~79 ~0 ~27 ~79 ~0 ~28 stone_slab 7  
fill ~80 ~0 ~23 ~81 ~0 ~23 double_stone_slab 7  
fill ~80 ~0 ~26 ~80 ~0 ~27 double_stone_slab 7 
setblock ~81 ~0 ~25 stone_slab 15 
setblock ~81 ~0 ~28 double_stone_slab 7  
fill ~81 ~0 ~30 ~82 ~0 ~30 stone_slab 7 
setblock ~82 ~0 ~22 stone_slab 15 
setblock ~82 ~0 ~27 stone_slab 15  
fill ~82 ~0 ~29 ~83 ~0 ~29 double_stone_slab 7 
setblock ~83 ~0 ~23 stone_slab 15  
fill ~83 ~0 ~24 ~83 ~0 ~26 stained_hardened_clay 0  
fill ~84 ~0 ~23 ~86 ~0 ~23 stained_hardened_clay 8  
fill ~84 ~0 ~24 ~86 ~0 ~24 stained_hardened_clay 8  
fill ~84 ~0 ~25 ~84 ~1 ~25 stained_hardened_clay 0  
fill ~84 ~0 ~26 ~85 ~0 ~26 stained_hardened_clay 0 
setblock ~84 ~0 ~28 stone_slab 15  
fill ~85 ~0 ~21 ~85 ~1 ~21 stained_hardened_clay 0  
fill ~85 ~0 ~22 ~85 ~3 ~22 stained_hardened_clay 8  
fill ~85 ~0 ~25 ~86 ~0 ~25 stained_hardened_clay 8  
fill ~86 ~0 ~21 ~87 ~0 ~21 stained_hardened_clay 9 
setblock ~86 ~0 ~22 stained_hardened_clay 0 
setblock ~86 ~0 ~26 stone_slab 15  
fill ~86 ~0 ~28 ~86 ~0 ~29 double_stone_slab 7  
fill ~87 ~0 ~22 ~88 ~0 ~22 stained_hardened_clay 9  
fill ~87 ~0 ~23 ~88 ~0 ~23 stained_hardened_clay 0  
fill ~87 ~0 ~24 ~88 ~0 ~24 stained_hardened_clay 0 
setblock ~87 ~0 ~27 stone_slab 15  
fill ~89 ~0 ~18 ~93 ~0 ~18 stained_hardened_clay 0  
fill ~89 ~0 ~19 ~91 ~0 ~19 stained_hardened_clay 0  
fill ~90 ~0 ~17 ~93 ~0 ~17 stained_hardened_clay 0  
fill ~90 ~0 ~20 ~90 ~1 ~20 stained_hardened_clay 0  
fill ~91 ~0 ~16 ~93 ~0 ~16 stained_hardened_clay 0  
fill ~91 ~0 ~20 ~91 ~1 ~20 stained_hardened_clay 8 
setblock ~92 ~0 ~19 stained_hardened_clay 8  
fill ~94 ~0 ~14 ~95 ~0 ~14 stone_slab 15 
setblock ~95 ~0 ~15 stone_slab 15 
setblock ~96 ~0 ~13 double_stone_slab 7  
fill ~108 ~0 ~43 ~108 ~0 ~44 stone_slab 7  
fill ~109 ~0 ~39 ~110 ~0 ~39 double_stone_slab 7  
fill ~109 ~0 ~42 ~109 ~0 ~43 double_stone_slab 7 
setblock ~110 ~0 ~41 stone_slab 15 
setblock ~110 ~0 ~44 double_stone_slab 7  
fill ~110 ~0 ~46 ~111 ~0 ~46 stone_slab 7 
setblock ~111 ~0 ~38 stone_slab 15 
setblock ~111 ~0 ~43 stone_slab 15  
fill ~111 ~0 ~45 ~112 ~0 ~45 double_stone_slab 7 
setblock ~112 ~0 ~39 stone_slab 15  
fill ~112 ~0 ~40 ~112 ~0 ~42 stained_hardened_clay 0  
fill ~113 ~0 ~39 ~115 ~0 ~39 stained_hardened_clay 8  
fill ~113 ~0 ~40 ~115 ~0 ~40 stained_hardened_clay 8  
fill ~113 ~0 ~41 ~113 ~1 ~41 stained_hardened_clay 0  
fill ~113 ~0 ~42 ~114 ~0 ~42 stained_hardened_clay 0 
setblock ~113 ~0 ~44 stone_slab 15  
fill ~114 ~0 ~37 ~114 ~1 ~37 stained_hardened_clay 0  
fill ~114 ~0 ~38 ~114 ~3 ~38 stained_hardened_clay 8  
fill ~114 ~0 ~41 ~115 ~0 ~41 stained_hardened_clay 8  
fill ~115 ~0 ~37 ~116 ~0 ~37 stained_hardened_clay 9 
setblock ~115 ~0 ~38 stained_hardened_clay 0 
setblock ~115 ~0 ~42 stone_slab 15  
fill ~115 ~0 ~44 ~115 ~0 ~45 double_stone_slab 7  
fill ~116 ~0 ~38 ~117 ~0 ~38 stained_hardened_clay 9  
fill ~116 ~0 ~39 ~117 ~0 ~39 stained_hardened_clay 0  
fill ~116 ~0 ~40 ~117 ~0 ~40 stained_hardened_clay 0 
setblock ~116 ~0 ~43 stone_slab 15  
fill ~118 ~0 ~34 ~122 ~0 ~34 stained_hardened_clay 0  
fill ~118 ~0 ~35 ~120 ~0 ~35 stained_hardened_clay 0  
fill ~119 ~0 ~33 ~122 ~0 ~33 stained_hardened_clay 0  
fill ~119 ~0 ~36 ~119 ~1 ~36 stained_hardened_clay 0  
fill ~120 ~0 ~32 ~122 ~0 ~32 stained_hardened_clay 0  
fill ~120 ~0 ~36 ~120 ~1 ~36 stained_hardened_clay 8 
setblock ~121 ~0 ~35 stained_hardened_clay 8  
fill ~123 ~0 ~30 ~124 ~0 ~30 stone_slab 15 
setblock ~124 ~0 ~31 stone_slab 15 
setblock ~125 ~0 ~29 double_stone_slab 7 
setblock ~5 ~1 ~93 stone_slab 7  
fill ~6 ~1 ~92 ~6 ~1 ~93 double_stone_slab 7 
setblock ~7 ~1 ~91 stone_slab 15 
setblock ~7 ~1 ~92 quartz_block 0 
setblock ~7 ~1 ~94 stone_slab 7 
setblock ~8 ~1 ~89 stone_slab 15  
fill ~8 ~1 ~91 ~8 ~1 ~92 stained_hardened_clay 0 
setblock ~8 ~1 ~93 double_stone_slab 7  
fill ~8 ~1 ~95 ~9 ~1 ~95 double_stone_slab 7 
setblock ~8 ~1 ~96 stone_slab 7 
setblock ~9 ~1 ~89 double_stone_slab 7 
setblock ~9 ~1 ~90 stone_slab 15  
fill ~9 ~1 ~91 ~11 ~1 ~91 stained_hardened_clay 8  
fill ~9 ~1 ~92 ~9 ~0 ~92 stained_hardened_clay 0  
fill ~9 ~1 ~93 ~10 ~1 ~93 stained_hardened_clay 0  
fill ~9 ~1 ~94 ~9 ~2 ~94 double_stone_slab 7  
fill ~10 ~1 ~89 ~10 ~3 ~89 stained_hardened_clay 0  
fill ~10 ~1 ~90 ~10 ~2 ~90 stained_hardened_clay 8  
fill ~10 ~1 ~92 ~10 ~2 ~92 stained_hardened_clay 8 
setblock ~10 ~1 ~94 stone_slab 15 
setblock ~11 ~1 ~87 stained_hardened_clay 8 
setblock ~11 ~1 ~89 stained_hardened_clay 8  
fill ~11 ~1 ~90 ~14 ~1 ~90 stained_hardened_clay 0 
setblock ~11 ~1 ~92 stone_slab 15  
fill ~12 ~1 ~86 ~13 ~1 ~86 stained_hardened_clay 0  
fill ~12 ~1 ~87 ~15 ~1 ~87 stained_hardened_clay 0 
setblock ~12 ~1 ~88 stained_hardened_clay 8  
fill ~12 ~1 ~89 ~15 ~1 ~89 stained_hardened_clay 0  
fill ~12 ~1 ~91 ~12 ~3 ~91 stained_hardened_clay 0 
setblock ~12 ~1 ~92 double_stone_slab 7 
setblock ~12 ~1 ~93 stone_slab 15  
fill ~13 ~1 ~88 ~15 ~1 ~88 stained_hardened_clay 0  
fill ~14 ~1 ~85 ~16 ~1 ~85 stained_hardened_clay 9  
fill ~14 ~1 ~86 ~16 ~1 ~86 stained_hardened_clay 9 
setblock ~16 ~1 ~84 stained_hardened_clay 0 
setblock ~16 ~1 ~87 stained_hardened_clay 9 
setblock ~17 ~1 ~83 stone_slab 7  
fill ~17 ~1 ~84 ~17 ~2 ~84 double_stone_slab 7 
setblock ~17 ~1 ~85 stained_hardened_clay 0 
setblock ~18 ~1 ~83 double_stone_slab 7 
setblock ~18 ~1 ~84 stone_slab 7 
setblock ~19 ~1 ~82 stone_slab 7  
fill ~54 ~1 ~-10 ~54 ~1 ~-9 bedrock 0  
fill ~55 ~1 ~-10 ~58 ~1 ~-10 nether_brick 0  
fill ~55 ~1 ~-9 ~60 ~1 ~-9 nether_brick 0 
setblock ~55 ~1 ~-8 bedrock 0 
setblock ~55 ~1 ~91 stone_slab 7  
fill ~56 ~1 ~-8 ~60 ~1 ~-8 nether_brick 0  
fill ~56 ~1 ~90 ~56 ~1 ~91 double_stone_slab 7 
setblock ~57 ~1 ~89 stone_slab 15 
setblock ~57 ~1 ~90 quartz_block 0 
setblock ~57 ~1 ~92 stone_slab 7 
setblock ~58 ~1 ~87 stone_slab 15  
fill ~58 ~1 ~89 ~59 ~1 ~89 stained_hardened_clay 0  
fill ~58 ~1 ~90 ~60 ~1 ~90 stained_hardened_clay 0 
setblock ~58 ~1 ~91 double_stone_slab 7  
fill ~58 ~1 ~93 ~59 ~1 ~93 double_stone_slab 7 
setblock ~58 ~1 ~94 stone_slab 7  
fill ~59 ~1 ~-7 ~61 ~1 ~-7 nether_brick 0 
setblock ~59 ~1 ~87 double_stone_slab 7 
setblock ~59 ~1 ~88 stone_slab 15  
fill ~59 ~1 ~91 ~60 ~1 ~91 stained_hardened_clay 0  
fill ~59 ~1 ~92 ~59 ~2 ~92 double_stone_slab 7  
fill ~60 ~1 ~-6 ~62 ~1 ~-6 nether_brick 0  
fill ~60 ~1 ~87 ~60 ~2 ~87 stained_hardened_clay 8  
fill ~60 ~1 ~88 ~61 ~1 ~88 stained_hardened_clay 8  
fill ~60 ~1 ~89 ~60 ~2 ~89 stained_hardened_clay 8 
setblock ~60 ~1 ~92 stone_slab 15  
fill ~61 ~1 ~-5 ~63 ~1 ~-5 nether_brick 0  
fill ~61 ~1 ~-4 ~62 ~1 ~-4 nether_brick 0  
fill ~61 ~1 ~-3 ~62 ~1 ~-3 nether_brick 0  
fill ~61 ~1 ~85 ~65 ~1 ~85 stained_hardened_clay 0  
fill ~61 ~1 ~87 ~65 ~1 ~87 stained_hardened_clay 0 
setblock ~61 ~1 ~89 stained_hardened_clay 0 
setblock ~61 ~1 ~90 stone_slab 15 
setblock ~62 ~1 ~-2 nether_brick 0 
setblock ~62 ~1 ~0 nether_brick 0  
fill ~62 ~1 ~84 ~63 ~1 ~84 stained_hardened_clay 0  
fill ~62 ~1 ~86 ~65 ~1 ~86 stained_hardened_clay 0 
setblock ~62 ~1 ~88 stained_hardened_clay 0  
fill ~62 ~1 ~89 ~62 ~2 ~89 stained_hardened_clay 8 
setblock ~62 ~1 ~90 double_stone_slab 7 
setblock ~62 ~1 ~91 stone_slab 15 
setblock ~63 ~1 ~-4 soul_sand 0  
fill ~63 ~1 ~-3 ~63 ~1 ~-2 netherrack 0 
setblock ~63 ~1 ~-1 nether_brick 0  
fill ~63 ~1 ~0 ~63 ~1 ~1 bedrock 0  
fill ~63 ~1 ~88 ~63 ~3 ~88 stained_hardened_clay 8 
setblock ~64 ~1 ~-3 soul_sand 0 
setblock ~64 ~1 ~-2 nether_brick 0 
setblock ~64 ~1 ~0 nether_brick 0  
fill ~64 ~1 ~1 ~64 ~1 ~2 bedrock 0  
fill ~64 ~1 ~3 ~64 ~2 ~3 nether_brick 0  
fill ~64 ~1 ~83 ~66 ~1 ~83 stained_hardened_clay 9  
fill ~64 ~1 ~84 ~66 ~1 ~84 stained_hardened_clay 9 
setblock ~64 ~1 ~88 stained_hardened_clay 0 
setblock ~65 ~1 ~-1 nether_brick 0  
fill ~65 ~1 ~0 ~66 ~1 ~0 bedrock 0  
fill ~65 ~1 ~1 ~65 ~2 ~1 nether_brick 0  
fill ~65 ~1 ~2 ~66 ~1 ~2 nether_brick 0 
setblock ~65 ~1 ~3 bedrock 0  
fill ~65 ~1 ~4 ~65 ~2 ~4 nether_brick 0  
fill ~66 ~1 ~1 ~67 ~1 ~1 bedrock 0 
setblock ~66 ~1 ~4 bedrock 0  
fill ~66 ~1 ~5 ~66 ~2 ~5 nether_brick 0 
setblock ~66 ~1 ~82 stained_hardened_clay 0 
setblock ~66 ~1 ~85 stained_hardened_clay 9 
setblock ~67 ~1 ~2 bedrock 0  
fill ~67 ~1 ~3 ~67 ~2 ~3 nether_brick 0  
fill ~67 ~1 ~4 ~67 ~3 ~4 nether_brick 0 
setblock ~67 ~1 ~5 bedrock 0 
setblock ~67 ~1 ~81 stone_slab 7  
fill ~67 ~1 ~82 ~67 ~2 ~82 double_stone_slab 7 
setblock ~67 ~1 ~83 stained_hardened_clay 0  
fill ~68 ~1 ~2 ~68 ~2 ~2 nether_brick 0 
setblock ~68 ~1 ~3 bedrock 0  
fill ~68 ~1 ~5 ~68 ~2 ~5 nether_brick 0  
fill ~68 ~1 ~6 ~71 ~1 ~6 bedrock 0 
setblock ~68 ~1 ~81 double_stone_slab 7 
setblock ~68 ~1 ~82 stone_slab 7  
fill ~69 ~1 ~3 ~70 ~1 ~3 nether_brick 0  
fill ~69 ~1 ~4 ~69 ~3 ~4 nether_brick 0 
setblock ~69 ~1 ~5 bedrock 0 
setblock ~69 ~1 ~80 stone_slab 7 
setblock ~70 ~1 ~4 bedrock 0  
fill ~70 ~1 ~5 ~71 ~1 ~5 nether_brick 0  
fill ~71 ~1 ~4 ~71 ~2 ~4 nether_brick 0  
fill ~71 ~1 ~7 ~74 ~1 ~7 bedrock 0  
fill ~72 ~1 ~4 ~72 ~1 ~5 bedrock 0  
fill ~72 ~1 ~6 ~72 ~3 ~6 nether_brick 0  
fill ~73 ~1 ~5 ~73 ~1 ~8 bedrock 0  
fill ~74 ~1 ~6 ~77 ~1 ~6 bedrock 0  
fill ~74 ~1 ~8 ~81 ~1 ~8 bedrock 0  
fill ~75 ~1 ~7 ~75 ~2 ~7 nether_brick 0  
fill ~75 ~1 ~9 ~77 ~1 ~9 bedrock 0  
fill ~76 ~1 ~7 ~83 ~1 ~7 bedrock 0  
fill ~81 ~1 ~22 ~81 ~1 ~23 stone_slab 7  
fill ~81 ~1 ~25 ~82 ~1 ~25 double_stone_slab 7 
setblock ~81 ~1 ~26 stone_slab 7 
setblock ~81 ~1 ~28 stone_slab 7  
fill ~82 ~1 ~22 ~83 ~1 ~22 double_stone_slab 7 
setblock ~82 ~1 ~27 double_stone_slab 7 
setblock ~83 ~1 ~23 double_stone_slab 7 
setblock ~83 ~1 ~24 stone_slab 7 
setblock ~83 ~1 ~25 stained_hardened_clay 0 
setblock ~83 ~1 ~26 stone_slab 7 
setblock ~83 ~1 ~28 stone_slab 7  
fill ~84 ~1 ~21 ~84 ~1 ~22 stone_slab 15 
setblock ~84 ~1 ~23 stained_hardened_clay 0  
fill ~84 ~1 ~24 ~86 ~1 ~24 stained_hardened_clay 8  
fill ~84 ~1 ~26 ~84 ~0 ~26 stained_hardened_clay 0  
fill ~84 ~1 ~27 ~84 ~1 ~28 double_stone_slab 7  
fill ~85 ~1 ~23 ~86 ~1 ~23 stained_hardened_clay 8  
fill ~85 ~1 ~25 ~85 ~0 ~25 stained_hardened_clay 8 
setblock ~85 ~1 ~26 stone_slab 7  
fill ~86 ~1 ~20 ~88 ~1 ~20 stained_hardened_clay 9  
fill ~86 ~1 ~21 ~89 ~1 ~21 stained_hardened_clay 9  
fill ~86 ~1 ~22 ~86 ~3 ~22 stained_hardened_clay 8 
setblock ~86 ~1 ~25 stained_hardened_clay 0  
fill ~86 ~1 ~26 ~87 ~1 ~26 double_stone_slab 7  
fill ~86 ~1 ~28 ~87 ~1 ~28 stone_slab 7  
fill ~87 ~1 ~22 ~89 ~1 ~22 stained_hardened_clay 9  
fill ~87 ~1 ~23 ~88 ~1 ~23 stained_hardened_clay 0  
fill ~87 ~1 ~24 ~87 ~2 ~24 stained_hardened_clay 0  
fill ~87 ~1 ~25 ~88 ~1 ~25 stone_slab 15 
setblock ~87 ~1 ~27 double_stone_slab 7  
fill ~88 ~1 ~19 ~90 ~1 ~19 stained_hardened_clay 0 
setblock ~88 ~1 ~24 stone_slab 15  
fill ~89 ~1 ~18 ~92 ~1 ~18 stained_hardened_clay 0 
setblock ~89 ~1 ~20 stained_hardened_clay 0 
setblock ~90 ~1 ~21 stained_hardened_clay 0 
setblock ~91 ~1 ~17 stained_hardened_clay 0 
setblock ~91 ~1 ~19 stained_hardened_clay 8 
setblock ~92 ~1 ~16 stone_slab 7 
setblock ~92 ~1 ~17 double_stone_slab 7  
fill ~93 ~1 ~16 ~93 ~2 ~16 double_stone_slab 7 
setblock ~93 ~1 ~17 stone_slab 7 
setblock ~94 ~1 ~15 double_stone_slab 7 
setblock ~94 ~1 ~16 stone_slab 7 
setblock ~95 ~1 ~14 double_stone_slab 7  
fill ~110 ~1 ~38 ~110 ~1 ~39 stone_slab 7  
fill ~110 ~1 ~41 ~111 ~1 ~41 double_stone_slab 7 
setblock ~110 ~1 ~42 stone_slab 7 
setblock ~110 ~1 ~44 stone_slab 7  
fill ~111 ~1 ~38 ~112 ~1 ~38 double_stone_slab 7 
setblock ~111 ~1 ~43 double_stone_slab 7 
setblock ~112 ~1 ~39 double_stone_slab 7 
setblock ~112 ~1 ~40 stone_slab 7 
setblock ~112 ~1 ~41 stained_hardened_clay 0 
setblock ~112 ~1 ~42 stone_slab 7 
setblock ~112 ~1 ~44 stone_slab 7  
fill ~113 ~1 ~37 ~113 ~1 ~38 stone_slab 15 
setblock ~113 ~1 ~39 stained_hardened_clay 0  
fill ~113 ~1 ~40 ~115 ~1 ~40 stained_hardened_clay 8  
fill ~113 ~1 ~42 ~113 ~0 ~42 stained_hardened_clay 0  
fill ~113 ~1 ~43 ~113 ~1 ~44 double_stone_slab 7  
fill ~114 ~1 ~39 ~115 ~1 ~39 stained_hardened_clay 8  
fill ~114 ~1 ~41 ~114 ~0 ~41 stained_hardened_clay 8 
setblock ~114 ~1 ~42 stone_slab 7  
fill ~115 ~1 ~36 ~117 ~1 ~36 stained_hardened_clay 9  
fill ~115 ~1 ~37 ~118 ~1 ~37 stained_hardened_clay 9  
fill ~115 ~1 ~38 ~115 ~5 ~38 stained_hardened_clay 8 
setblock ~115 ~1 ~41 stained_hardened_clay 0  
fill ~115 ~1 ~42 ~116 ~1 ~42 double_stone_slab 7  
fill ~115 ~1 ~44 ~116 ~1 ~44 stone_slab 7  
fill ~116 ~1 ~38 ~118 ~1 ~38 stained_hardened_clay 9  
fill ~116 ~1 ~39 ~117 ~1 ~39 stained_hardened_clay 0  
fill ~116 ~1 ~40 ~116 ~2 ~40 stained_hardened_clay 0  
fill ~116 ~1 ~41 ~117 ~1 ~41 stone_slab 15 
setblock ~116 ~1 ~43 double_stone_slab 7  
fill ~117 ~1 ~35 ~119 ~1 ~35 stained_hardened_clay 0 
setblock ~117 ~1 ~40 stone_slab 15  
fill ~118 ~1 ~34 ~121 ~1 ~34 stained_hardened_clay 0 
setblock ~118 ~1 ~36 stained_hardened_clay 0 
setblock ~119 ~1 ~37 stained_hardened_clay 0 
setblock ~120 ~1 ~33 stained_hardened_clay 0 
setblock ~120 ~1 ~35 stained_hardened_clay 8 
setblock ~121 ~1 ~32 stone_slab 7 
setblock ~121 ~1 ~33 double_stone_slab 7  
fill ~122 ~1 ~32 ~122 ~2 ~32 double_stone_slab 7 
setblock ~122 ~1 ~33 stone_slab 7 
setblock ~123 ~1 ~31 double_stone_slab 7 
setblock ~123 ~1 ~32 stone_slab 7 
setblock ~124 ~1 ~30 double_stone_slab 7 
setblock ~6 ~2 ~92 stone_slab 7 
setblock ~7 ~2 ~92 double_stone_slab 7 
setblock ~8 ~2 ~89 double_stone_slab 7 
setblock ~8 ~2 ~91 double_stone_slab 7 
setblock ~8 ~2 ~92 stone_slab 7 
setblock ~9 ~2 ~89 stone_slab 7  
fill ~9 ~2 ~91 ~11 ~2 ~91 stained_hardened_clay 8  
fill ~9 ~2 ~92 ~9 ~2 ~91 stained_hardened_clay 8 
setblock ~9 ~2 ~93 stone_slab 7 
setblock ~9 ~2 ~95 stone_slab 7  
fill ~10 ~2 ~88 ~14 ~2 ~88 stained_hardened_clay 0 
setblock ~10 ~2 ~93 double_stone_slab 7  
fill ~11 ~2 ~87 ~13 ~2 ~87 stained_hardened_clay 0  
fill ~11 ~2 ~89 ~14 ~2 ~89 stained_hardened_clay 0 
setblock ~11 ~2 ~90 stained_hardened_clay 8  
fill ~12 ~2 ~90 ~14 ~2 ~90 stained_hardened_clay 0 
setblock ~12 ~2 ~92 stone_slab 7 
setblock ~12 ~2 ~93 double_stone_slab 7  
fill ~13 ~2 ~86 ~15 ~2 ~86 stained_hardened_clay 9 
setblock ~13 ~2 ~91 stained_hardened_clay 0  
fill ~14 ~2 ~87 ~15 ~2 ~87 stained_hardened_clay 9 
setblock ~15 ~2 ~85 quartz_stairs 2  
fill ~15 ~2 ~88 ~15 ~4 ~88 stained_hardened_clay 9 
setblock ~16 ~2 ~84 quartz_stairs 1 
setblock ~16 ~2 ~85 stone_slab 7 
setblock ~16 ~2 ~86 quartz_stairs 1 
setblock ~17 ~2 ~85 quartz_stairs 2 
setblock ~18 ~2 ~83 stone_slab 7  
fill ~53 ~2 ~-9 ~53 ~2 ~-8 bedrock 0  
fill ~54 ~2 ~-10 ~56 ~2 ~-10 nether_brick 0  
fill ~54 ~2 ~-9 ~57 ~2 ~-9 nether_brick 0  
fill ~54 ~2 ~-8 ~55 ~2 ~-8 nether_brick 0 
setblock ~56 ~2 ~90 stone_slab 7 
setblock ~57 ~2 ~90 double_stone_slab 7 
setblock ~58 ~2 ~87 double_stone_slab 7 
setblock ~58 ~2 ~89 double_stone_slab 7 
setblock ~58 ~2 ~90 stone_slab 7 
setblock ~59 ~2 ~87 stone_slab 7 
setblock ~59 ~2 ~89 stained_hardened_clay 8  
fill ~59 ~2 ~90 ~60 ~2 ~90 stained_hardened_clay 0 
setblock ~59 ~2 ~91 stone_slab 7 
setblock ~59 ~2 ~93 stone_slab 7 
setblock ~60 ~2 ~86 stained_hardened_clay 0  
fill ~60 ~2 ~88 ~64 ~2 ~88 stained_hardened_clay 8 
setblock ~60 ~2 ~91 double_stone_slab 7  
fill ~61 ~2 ~85 ~63 ~2 ~85 stained_hardened_clay 0  
fill ~61 ~2 ~87 ~61 ~3 ~87 stained_hardened_clay 8 
setblock ~61 ~2 ~89 stained_hardened_clay 8  
fill ~62 ~2 ~86 ~64 ~2 ~86 stained_hardened_clay 0  
fill ~62 ~2 ~87 ~64 ~2 ~87 stained_hardened_clay 0 
setblock ~62 ~2 ~90 stone_slab 7 
setblock ~62 ~2 ~91 double_stone_slab 7  
fill ~63 ~2 ~0 ~63 ~2 ~1 netherrack 0  
fill ~63 ~2 ~84 ~65 ~2 ~84 stained_hardened_clay 9 
setblock ~63 ~2 ~89 stained_hardened_clay 8 
setblock ~64 ~2 ~0 soul_sand 0  
fill ~64 ~2 ~1 ~64 ~2 ~3 nether_brick 0  
fill ~64 ~2 ~85 ~65 ~2 ~85 stained_hardened_clay 9  
fill ~65 ~2 ~0 ~66 ~2 ~0 nether_brick 0  
fill ~65 ~2 ~2 ~68 ~2 ~2 nether_brick 0  
fill ~65 ~2 ~3 ~65 ~2 ~0 nether_brick 0 
setblock ~65 ~2 ~83 quartz_stairs 2 
setblock ~65 ~2 ~86 stained_hardened_clay 9  
fill ~66 ~2 ~1 ~67 ~2 ~1 nether_brick 0 
setblock ~66 ~2 ~3 netherrack 0 
setblock ~66 ~2 ~4 nether_brick 0 
setblock ~66 ~2 ~82 quartz_stairs 1 
setblock ~66 ~2 ~83 stone_slab 7 
setblock ~66 ~2 ~84 quartz_stairs 1 
setblock ~67 ~2 ~5 nether_brick 0 
setblock ~67 ~2 ~83 quartz_stairs 2  
fill ~68 ~2 ~3 ~69 ~2 ~3 nether_brick 0 
setblock ~68 ~2 ~81 stone_slab 7  
fill ~69 ~2 ~5 ~70 ~2 ~5 nether_brick 0  
fill ~69 ~2 ~6 ~74 ~2 ~6 nether_brick 0  
fill ~70 ~2 ~4 ~70 ~3 ~4 nether_brick 0  
fill ~71 ~2 ~5 ~71 ~3 ~5 soul_sand 0  
fill ~71 ~2 ~7 ~77 ~2 ~7 nether_brick 0  
fill ~72 ~2 ~4 ~72 ~2 ~7 nether_brick 0 
setblock ~73 ~2 ~5 nether_brick 0  
fill ~73 ~2 ~8 ~78 ~2 ~8 nether_brick 0  
fill ~75 ~2 ~6 ~75 ~3 ~6 soul_sand 0  
fill ~75 ~2 ~9 ~81 ~2 ~9 nether_brick 0  
fill ~76 ~2 ~6 ~78 ~2 ~6 nether_brick 0  
fill ~78 ~2 ~7 ~83 ~2 ~7 bedrock 0 
setblock ~79 ~2 ~6 bedrock 0 
setblock ~79 ~2 ~8 bedrock 0 
setblock ~80 ~2 ~6 nether_brick 0  
fill ~80 ~2 ~8 ~80 ~4 ~8 nether_brick 0  
fill ~81 ~2 ~6 ~84 ~2 ~6 bedrock 0 
setblock ~81 ~2 ~8 bedrock 0  
fill ~82 ~2 ~8 ~83 ~2 ~8 nether_brick 0 
setblock ~82 ~2 ~25 stone_slab 7 
setblock ~83 ~2 ~22 stone_slab 7  
fill ~84 ~2 ~7 ~84 ~5 ~7 nether_brick 0 
setblock ~84 ~2 ~22 double_stone_slab 7 
setblock ~84 ~2 ~23 stone_slab 7 
setblock ~84 ~2 ~27 stone_slab 7 
setblock ~85 ~2 ~21 stained_hardened_clay 8  
fill ~85 ~2 ~23 ~86 ~2 ~23 stained_hardened_clay 8  
fill ~86 ~2 ~20 ~90 ~2 ~20 stained_hardened_clay 9  
fill ~86 ~2 ~21 ~89 ~2 ~21 stained_hardened_clay 9 
setblock ~86 ~2 ~24 stained_hardened_clay 8 
setblock ~86 ~2 ~25 stone_slab 7  
fill ~87 ~2 ~19 ~87 ~3 ~19 stained_hardened_clay 9  
fill ~87 ~2 ~22 ~89 ~2 ~22 stained_hardened_clay 9  
fill ~87 ~2 ~23 ~89 ~2 ~23 stained_hardened_clay 0 
setblock ~87 ~2 ~25 double_stone_slab 7 
setblock ~87 ~2 ~26 stone_slab 7 
setblock ~88 ~2 ~24 stained_hardened_clay 0  
fill ~89 ~2 ~19 ~89 ~4 ~19 stained_hardened_clay 9  
fill ~90 ~2 ~18 ~90 ~2 ~19 stained_hardened_clay 0 
setblock ~91 ~2 ~19 stained_hardened_clay 0 
setblock ~92 ~2 ~17 stone_slab 7 
setblock ~94 ~2 ~15 stone_slab 7 
setblock ~111 ~2 ~41 stone_slab 7 
setblock ~112 ~2 ~38 stone_slab 7 
setblock ~113 ~2 ~38 double_stone_slab 7 
setblock ~113 ~2 ~39 stone_slab 7 
setblock ~113 ~2 ~43 stone_slab 7 
setblock ~114 ~2 ~37 stained_hardened_clay 8  
fill ~114 ~2 ~39 ~115 ~2 ~39 stained_hardened_clay 8  
fill ~115 ~2 ~36 ~119 ~2 ~36 stained_hardened_clay 9  
fill ~115 ~2 ~37 ~118 ~2 ~37 stained_hardened_clay 9 
setblock ~115 ~2 ~40 stained_hardened_clay 8 
setblock ~115 ~2 ~41 stone_slab 7  
fill ~116 ~2 ~35 ~116 ~4 ~35 stained_hardened_clay 9  
fill ~116 ~2 ~38 ~118 ~2 ~38 stained_hardened_clay 9  
fill ~116 ~2 ~39 ~118 ~2 ~39 stained_hardened_clay 0 
setblock ~116 ~2 ~41 double_stone_slab 7 
setblock ~116 ~2 ~42 stone_slab 7 
setblock ~117 ~2 ~40 stained_hardened_clay 0  
fill ~118 ~2 ~35 ~118 ~6 ~35 stained_hardened_clay 9  
fill ~119 ~2 ~34 ~119 ~2 ~35 stained_hardened_clay 0 
setblock ~120 ~2 ~35 stained_hardened_clay 0 
setblock ~121 ~2 ~33 stone_slab 7 
setblock ~123 ~2 ~31 stone_slab 7 
setblock ~8 ~3 ~91 stone_slab 7 
setblock ~10 ~3 ~93 stone_slab 7  
fill ~11 ~3 ~88 ~12 ~3 ~88 stained_hardened_clay 8  
fill ~11 ~3 ~89 ~11 ~4 ~89 stained_hardened_clay 8  
fill ~11 ~3 ~90 ~13 ~3 ~90 stained_hardened_clay 0  
fill ~12 ~3 ~87 ~13 ~3 ~87 stained_hardened_clay 0  
fill ~12 ~3 ~89 ~14 ~3 ~89 stained_hardened_clay 0  
fill ~13 ~3 ~86 ~16 ~3 ~86 stained_hardened_clay 9  
fill ~13 ~3 ~88 ~14 ~3 ~88 stained_hardened_clay 0  
fill ~14 ~3 ~87 ~15 ~3 ~87 stained_hardened_clay 9  
fill ~15 ~3 ~85 ~15 ~7 ~85 stained_hardened_clay 9  
fill ~52 ~3 ~-9 ~52 ~3 ~-8 bedrock 0  
fill ~53 ~3 ~-10 ~53 ~3 ~-8 nether_brick 0  
fill ~54 ~3 ~-9 ~55 ~3 ~-9 nether_brick 0  
fill ~54 ~3 ~-8 ~54 ~4 ~-8 nether_brick 0  
fill ~61 ~3 ~86 ~61 ~4 ~86 stained_hardened_clay 8 
setblock ~61 ~3 ~88 stained_hardened_clay 8  
fill ~62 ~3 ~85 ~64 ~3 ~85 stained_hardened_clay 9  
fill ~62 ~3 ~86 ~64 ~3 ~86 stained_hardened_clay 9  
fill ~62 ~3 ~87 ~64 ~3 ~87 stained_hardened_clay 9 
setblock ~62 ~3 ~88 stained_hardened_clay 0 
setblock ~63 ~3 ~0 fire 0 
setblock ~65 ~3 ~2 nether_brick 0  
fill ~66 ~3 ~1 ~66 ~2 ~1 nether_brick 0 
setblock ~66 ~3 ~2 netherrack 0 
setblock ~66 ~3 ~3 nether_brick 0 
setblock ~67 ~3 ~2 nether_brick 0 
setblock ~67 ~3 ~3 netherrack 0  
fill ~68 ~3 ~3 ~68 ~2 ~3 nether_brick 0  
fill ~69 ~3 ~5 ~69 ~2 ~5 nether_brick 0 
setblock ~70 ~3 ~5 soul_sand 0 
setblock ~71 ~3 ~6 netherrack 0 
setblock ~72 ~3 ~5 netherrack 0  
fill ~73 ~3 ~6 ~73 ~3 ~7 nether_brick 0 
setblock ~74 ~3 ~6 soul_sand 0  
fill ~74 ~3 ~7 ~74 ~3 ~8 nether_brick 0 
setblock ~75 ~3 ~7 netherrack 0  
fill ~75 ~3 ~8 ~84 ~3 ~8 nether_brick 0 
setblock ~76 ~3 ~6 netherrack 0  
fill ~76 ~3 ~7 ~79 ~3 ~7 nether_brick 0  
fill ~77 ~3 ~6 ~79 ~3 ~6 nether_brick 0  
fill ~77 ~3 ~9 ~82 ~3 ~9 nether_brick 0  
fill ~80 ~3 ~6 ~81 ~3 ~6 soul_sand 0  
fill ~80 ~3 ~7 ~80 ~3 ~6 soul_sand 0  
fill ~81 ~3 ~7 ~84 ~3 ~7 nether_brick 0  
fill ~82 ~3 ~5 ~83 ~3 ~5 nether_brick 0  
fill ~82 ~3 ~6 ~82 ~3 ~5 nether_brick 0  
fill ~83 ~3 ~6 ~86 ~3 ~6 bedrock 0 
setblock ~84 ~3 ~5 bedrock 0  
fill ~85 ~3 ~7 ~86 ~3 ~7 bedrock 0 
setblock ~86 ~3 ~20 stained_hardened_clay 0 
setblock ~86 ~3 ~21 stained_hardened_clay 8 
setblock ~86 ~3 ~23 stained_hardened_clay 8  
fill ~87 ~3 ~20 ~90 ~3 ~20 stained_hardened_clay 9  
fill ~87 ~3 ~21 ~90 ~3 ~21 stained_hardened_clay 9  
fill ~87 ~3 ~22 ~89 ~3 ~22 stained_hardened_clay 0  
fill ~87 ~3 ~23 ~89 ~3 ~23 stained_hardened_clay 0 
setblock ~87 ~3 ~24 stained_hardened_clay 8 
setblock ~88 ~3 ~19 stained_hardened_clay 9  
fill ~90 ~3 ~19 ~90 ~4 ~19 stained_hardened_clay 9 
setblock ~115 ~3 ~36 stained_hardened_clay 0  
fill ~115 ~3 ~37 ~115 ~6 ~37 stained_hardened_clay 8 
setblock ~115 ~3 ~39 stained_hardened_clay 8  
fill ~116 ~3 ~36 ~119 ~3 ~36 stained_hardened_clay 9  
fill ~116 ~3 ~37 ~119 ~3 ~37 stained_hardened_clay 9  
fill ~116 ~3 ~38 ~118 ~3 ~38 stained_hardened_clay 0  
fill ~116 ~3 ~39 ~118 ~3 ~39 stained_hardened_clay 0 
setblock ~116 ~3 ~40 stained_hardened_clay 8  
fill ~117 ~3 ~35 ~117 ~5 ~35 stained_hardened_clay 9  
fill ~119 ~3 ~35 ~119 ~7 ~35 stained_hardened_clay 9  
fill ~11 ~4 ~88 ~14 ~4 ~88 stained_hardened_clay 8  
fill ~12 ~4 ~86 ~12 ~5 ~86 stained_hardened_clay 8  
fill ~12 ~4 ~87 ~12 ~6 ~87 stained_hardened_clay 8  
fill ~12 ~4 ~89 ~15 ~4 ~89 stained_hardened_clay 8 
setblock ~12 ~4 ~90 stained_hardened_clay 0  
fill ~13 ~4 ~86 ~16 ~4 ~86 stained_hardened_clay 9 
setblock ~13 ~4 ~87 stained_hardened_clay 0 
setblock ~13 ~4 ~90 stained_hardened_clay 8  
fill ~14 ~4 ~85 ~14 ~6 ~85 stained_hardened_clay 9  
fill ~14 ~4 ~87 ~16 ~4 ~87 stained_hardened_clay 9  
fill ~16 ~4 ~85 ~16 ~7 ~85 stained_hardened_clay 9  
fill ~51 ~4 ~-9 ~54 ~4 ~-9 nether_brick 0  
fill ~51 ~4 ~-8 ~51 ~4 ~-7 bedrock 0  
fill ~52 ~4 ~-8 ~54 ~4 ~-8 nether_brick 0  
fill ~52 ~4 ~-7 ~53 ~4 ~-7 nether_brick 0  
fill ~62 ~4 ~84 ~65 ~4 ~84 stained_hardened_clay 9  
fill ~62 ~4 ~85 ~65 ~4 ~85 stained_hardened_clay 9  
fill ~62 ~4 ~86 ~65 ~4 ~86 stained_hardened_clay 9 
setblock ~62 ~4 ~87 stained_hardened_clay 8  
fill ~63 ~4 ~87 ~65 ~4 ~87 stained_hardened_clay 9 
setblock ~63 ~4 ~88 stained_hardened_clay 0 
setblock ~72 ~4 ~5 fire 0  
fill ~77 ~4 ~7 ~78 ~4 ~7 nether_brick 0  
fill ~78 ~4 ~8 ~85 ~4 ~8 nether_brick 0 
setblock ~79 ~4 ~6 soul_sand 0 
setblock ~79 ~4 ~7 netherrack 0  
fill ~80 ~4 ~6 ~81 ~4 ~6 netherrack 0  
fill ~80 ~4 ~7 ~81 ~4 ~7 nether_brick 0  
fill ~80 ~4 ~9 ~81 ~4 ~9 nether_brick 0  
fill ~82 ~4 ~6 ~82 ~4 ~7 soul_sand 0  
fill ~83 ~4 ~5 ~84 ~4 ~5 nether_brick 0  
fill ~83 ~4 ~6 ~83 ~4 ~8 nether_brick 0  
fill ~84 ~4 ~6 ~88 ~4 ~6 bedrock 0 
setblock ~85 ~4 ~5 netherrack 0  
fill ~85 ~4 ~7 ~85 ~5 ~7 nether_brick 0  
fill ~86 ~4 ~5 ~88 ~4 ~5 bedrock 0 
setblock ~86 ~4 ~7 bedrock 0  
fill ~87 ~4 ~7 ~87 ~6 ~7 nether_brick 0  
fill ~87 ~4 ~20 ~88 ~4 ~20 stained_hardened_clay 0  
fill ~87 ~4 ~21 ~90 ~4 ~21 stained_hardened_clay 0  
fill ~87 ~4 ~22 ~87 ~3 ~22 stained_hardened_clay 0 
setblock ~88 ~4 ~19 stained_hardened_clay 0  
fill ~88 ~4 ~22 ~90 ~4 ~22 stained_hardened_clay 8  
fill ~89 ~4 ~18 ~94 ~4 ~18 stained_hardened_clay 9  
fill ~89 ~4 ~20 ~94 ~4 ~20 stained_hardened_clay 9  
fill ~89 ~4 ~23 ~90 ~4 ~23 stained_hardened_clay 8  
fill ~91 ~4 ~19 ~94 ~4 ~19 stained_hardened_clay 9  
fill ~91 ~4 ~21 ~93 ~4 ~21 stained_hardened_clay 9  
fill ~91 ~4 ~22 ~92 ~4 ~22 stained_hardened_clay 9  
fill ~92 ~4 ~17 ~93 ~4 ~17 stained_hardened_clay 9  
fill ~115 ~4 ~35 ~115 ~5 ~35 stained_hardened_clay 0  
fill ~115 ~4 ~36 ~115 ~6 ~36 stained_hardened_clay 8  
fill ~115 ~4 ~39 ~118 ~4 ~39 stained_hardened_clay 0  
fill ~116 ~4 ~36 ~119 ~4 ~36 stained_hardened_clay 9  
fill ~116 ~4 ~37 ~116 ~7 ~37 stained_hardened_clay 8  
fill ~116 ~4 ~38 ~119 ~4 ~38 stained_hardened_clay 0  
fill ~117 ~4 ~34 ~119 ~4 ~34 stained_hardened_clay 9  
fill ~117 ~4 ~37 ~119 ~4 ~37 stained_hardened_clay 9  
fill ~12 ~5 ~88 ~16 ~5 ~88 stained_hardened_clay 8  
fill ~12 ~5 ~89 ~15 ~5 ~89 stained_hardened_clay 8  
fill ~13 ~5 ~85 ~13 ~5 ~89 stained_hardened_clay 8  
fill ~14 ~5 ~86 ~17 ~5 ~86 stained_hardened_clay 9 
setblock ~14 ~5 ~87 stained_hardened_clay 8  
fill ~15 ~5 ~84 ~15 ~7 ~84 stained_hardened_clay 9  
fill ~15 ~5 ~87 ~16 ~5 ~87 stained_hardened_clay 9  
fill ~50 ~5 ~-8 ~53 ~5 ~-8 nether_brick 0  
fill ~50 ~5 ~-7 ~50 ~6 ~-7 bedrock 0  
fill ~51 ~5 ~-9 ~52 ~5 ~-9 nether_brick 0  
fill ~51 ~5 ~-7 ~52 ~5 ~-7 nether_brick 0  
fill ~62 ~5 ~85 ~62 ~6 ~85 stained_hardened_clay 8  
fill ~62 ~5 ~86 ~62 ~6 ~86 stained_hardened_clay 8  
fill ~62 ~5 ~87 ~65 ~5 ~87 stained_hardened_clay 0  
fill ~63 ~5 ~84 ~66 ~5 ~84 stained_hardened_clay 9  
fill ~63 ~5 ~85 ~66 ~5 ~85 stained_hardened_clay 9  
fill ~63 ~5 ~86 ~66 ~5 ~86 stained_hardened_clay 9  
fill ~65 ~5 ~83 ~65 ~8 ~83 stained_hardened_clay 9 
setblock ~79 ~5 ~7 fire 0 
setblock ~80 ~5 ~7 soul_sand 0  
fill ~81 ~5 ~7 ~87 ~5 ~7 nether_brick 0  
fill ~81 ~5 ~8 ~83 ~5 ~8 nether_brick 0 
setblock ~84 ~5 ~6 netherrack 0  
fill ~85 ~5 ~5 ~86 ~5 ~5 soul_sand 0  
fill ~85 ~5 ~6 ~87 ~5 ~6 nether_brick 0  
fill ~86 ~5 ~4 ~87 ~5 ~4 nether_brick 0  
fill ~87 ~5 ~5 ~89 ~5 ~5 bedrock 0  
fill ~88 ~5 ~4 ~89 ~5 ~4 bedrock 0  
fill ~88 ~5 ~6 ~89 ~5 ~6 bedrock 0 
setblock ~88 ~5 ~20 stained_hardened_clay 0  
fill ~88 ~5 ~21 ~91 ~5 ~21 stained_hardened_clay 8 
setblock ~88 ~5 ~22 stained_hardened_clay 0  
fill ~89 ~5 ~18 ~91 ~5 ~18 stained_hardened_clay 0  
fill ~89 ~5 ~19 ~91 ~5 ~19 stained_hardened_clay 0  
fill ~89 ~5 ~20 ~89 ~7 ~20 stained_hardened_clay 8  
fill ~89 ~5 ~22 ~92 ~5 ~22 stained_hardened_clay 8  
fill ~90 ~5 ~20 ~91 ~5 ~20 stained_hardened_clay 0  
fill ~91 ~5 ~17 ~91 ~7 ~17 stained_hardened_clay 0  
fill ~92 ~5 ~17 ~95 ~5 ~17 stained_hardened_clay 9  
fill ~92 ~5 ~18 ~96 ~5 ~18 stained_hardened_clay 9  
fill ~92 ~5 ~19 ~96 ~5 ~19 stained_hardened_clay 9  
fill ~92 ~5 ~20 ~95 ~5 ~20 stained_hardened_clay 9  
fill ~92 ~5 ~21 ~94 ~5 ~21 stained_hardened_clay 9  
fill ~116 ~5 ~34 ~116 ~6 ~34 stained_hardened_clay 0  
fill ~116 ~5 ~35 ~116 ~5 ~34 stained_hardened_clay 0  
fill ~116 ~5 ~36 ~116 ~8 ~36 stained_hardened_clay 8  
fill ~116 ~5 ~38 ~116 ~6 ~38 stained_hardened_clay 8  
fill ~116 ~5 ~39 ~117 ~5 ~39 stained_hardened_clay 0  
fill ~117 ~5 ~34 ~120 ~5 ~34 stained_hardened_clay 9  
fill ~117 ~5 ~36 ~119 ~5 ~36 stained_hardened_clay 9  
fill ~117 ~5 ~37 ~119 ~5 ~37 stained_hardened_clay 0  
fill ~117 ~5 ~38 ~119 ~5 ~38 stained_hardened_clay 0  
fill ~118 ~5 ~33 ~119 ~5 ~33 stained_hardened_clay 9  
fill ~120 ~5 ~35 ~120 ~7 ~35 stained_hardened_clay 9 
setblock ~13 ~6 ~85 stained_hardened_clay 0 
setblock ~13 ~6 ~86 stained_hardened_clay 8  
fill ~13 ~6 ~87 ~14 ~6 ~87 stained_hardened_clay 0  
fill ~13 ~6 ~88 ~16 ~6 ~88 stained_hardened_clay 8 
setblock ~14 ~6 ~84 stained_hardened_clay 9  
fill ~14 ~6 ~86 ~17 ~6 ~86 stained_hardened_clay 9 
setblock ~14 ~6 ~89 stained_hardened_clay 8  
fill ~15 ~6 ~87 ~17 ~6 ~87 stained_hardened_clay 9  
fill ~16 ~6 ~83 ~16 ~6 ~87 stained_hardened_clay 9  
fill ~17 ~6 ~84 ~17 ~9 ~84 stained_hardened_clay 9  
fill ~17 ~6 ~85 ~18 ~6 ~85 stained_hardened_clay 9 
setblock ~49 ~6 ~-7 bedrock 0  
fill ~50 ~6 ~-8 ~51 ~6 ~-8 nether_brick 0   

KittysCommands:  
setblock ~50 ~6 ~-6 bedrock 0  
fill ~51 ~6 ~-7 ~51 ~7 ~-7 nether_brick 0  
fill ~51 ~6 ~-6 ~51 ~7 ~-6 nether_brick 0  
fill ~63 ~6 ~83 ~63 ~8 ~83 stained_hardened_clay 0  
fill ~63 ~6 ~84 ~63 ~9 ~84 stained_hardened_clay 8  
fill ~63 ~6 ~85 ~63 ~9 ~85 stained_hardened_clay 8  
fill ~63 ~6 ~86 ~63 ~8 ~86 stained_hardened_clay 8  
fill ~63 ~6 ~87 ~66 ~6 ~87 stained_hardened_clay 0  
fill ~64 ~6 ~83 ~64 ~6 ~85 stained_hardened_clay 9  
fill ~64 ~6 ~86 ~64 ~7 ~86 stained_hardened_clay 0  
fill ~65 ~6 ~84 ~67 ~6 ~84 stained_hardened_clay 9  
fill ~65 ~6 ~85 ~67 ~6 ~85 stained_hardened_clay 9  
fill ~65 ~6 ~86 ~66 ~6 ~86 stained_hardened_clay 9  
fill ~66 ~6 ~83 ~66 ~9 ~83 stained_hardened_clay 9  
fill ~85 ~6 ~6 ~88 ~6 ~6 nether_brick 0 
setblock ~86 ~6 ~5 nether_brick 0 
setblock ~86 ~6 ~7 nether_brick 0 
setblock ~87 ~6 ~4 nether_brick 0  
fill ~87 ~6 ~5 ~87 ~7 ~5 netherrack 0 
setblock ~88 ~6 ~4 soul_sand 0  
fill ~88 ~6 ~5 ~90 ~6 ~5 bedrock 0  
fill ~89 ~6 ~3 ~89 ~7 ~3 nether_brick 0  
fill ~89 ~6 ~4 ~91 ~6 ~4 bedrock 0 
setblock ~89 ~6 ~6 bedrock 0  
fill ~89 ~6 ~18 ~89 ~6 ~21 stained_hardened_clay 8  
fill ~90 ~6 ~3 ~91 ~6 ~3 bedrock 0  
fill ~90 ~6 ~18 ~92 ~6 ~18 stained_hardened_clay 0  
fill ~90 ~6 ~19 ~90 ~8 ~19 stained_hardened_clay 8  
fill ~90 ~6 ~20 ~90 ~7 ~20 stained_hardened_clay 8  
fill ~90 ~6 ~21 ~94 ~6 ~21 stained_hardened_clay 8  
fill ~91 ~6 ~19 ~92 ~6 ~19 stained_hardened_clay 0  
fill ~91 ~6 ~20 ~92 ~6 ~20 stained_hardened_clay 0 
setblock ~91 ~6 ~22 stained_hardened_clay 8  
fill ~92 ~6 ~17 ~92 ~8 ~17 stained_hardened_clay 0  
fill ~93 ~6 ~16 ~96 ~6 ~16 stained_hardened_clay 9  
fill ~93 ~6 ~17 ~97 ~6 ~17 stained_hardened_clay 9  
fill ~93 ~6 ~18 ~97 ~6 ~18 stained_hardened_clay 9  
fill ~93 ~6 ~19 ~96 ~6 ~19 stained_hardened_clay 9  
fill ~93 ~6 ~20 ~94 ~6 ~20 stained_hardened_clay 8  
fill ~95 ~6 ~20 ~96 ~6 ~20 stained_hardened_clay 9  
fill ~116 ~6 ~35 ~116 ~9 ~35 stained_hardened_clay 8  
fill ~117 ~6 ~33 ~120 ~6 ~33 stained_hardened_clay 9  
fill ~117 ~6 ~34 ~120 ~6 ~34 stained_hardened_clay 9 
setblock ~117 ~6 ~35 stained_hardened_clay 0  
fill ~117 ~6 ~36 ~117 ~8 ~36 stained_hardened_clay 8  
fill ~117 ~6 ~37 ~117 ~8 ~37 stained_hardened_clay 8  
fill ~117 ~6 ~38 ~118 ~6 ~38 stained_hardened_clay 8  
fill ~118 ~6 ~36 ~120 ~6 ~36 stained_hardened_clay 0  
fill ~118 ~6 ~37 ~119 ~6 ~37 stained_hardened_clay 0 
setblock ~119 ~6 ~38 stained_hardened_clay 0  
fill ~13 ~7 ~86 ~14 ~7 ~86 stained_hardened_clay 0  
fill ~13 ~7 ~87 ~17 ~7 ~87 stained_hardened_clay 0  
fill ~14 ~7 ~84 ~14 ~8 ~84 stained_hardened_clay 0  
fill ~14 ~7 ~85 ~14 ~9 ~85 stained_hardened_clay 0  
fill ~14 ~7 ~88 ~15 ~7 ~88 stained_hardened_clay 0  
fill ~15 ~7 ~83 ~16 ~7 ~83 stained_hardened_clay 8  
fill ~15 ~7 ~86 ~17 ~7 ~86 stained_hardened_clay 9 
setblock ~16 ~7 ~84 stained_hardened_clay 9  
fill ~17 ~7 ~82 ~17 ~9 ~82 stained_hardened_clay 9  
fill ~17 ~7 ~83 ~18 ~7 ~83 stained_hardened_clay 9  
fill ~17 ~7 ~85 ~19 ~7 ~85 stained_hardened_clay 9  
fill ~18 ~7 ~84 ~19 ~7 ~84 stained_hardened_clay 9  
fill ~18 ~7 ~86 ~18 ~11 ~86 stained_hardened_clay 0  
fill ~49 ~7 ~-8 ~49 ~7 ~-7 nether_brick 0 
setblock ~49 ~7 ~-6 bedrock 0  
fill ~50 ~7 ~-7 ~50 ~8 ~-7 nether_brick 0  
fill ~50 ~7 ~-6 ~50 ~9 ~-6 nether_brick 0  
fill ~50 ~7 ~-5 ~50 ~8 ~-5 nether_brick 0  
fill ~63 ~7 ~87 ~65 ~7 ~87 stained_hardened_clay 0  
fill ~64 ~7 ~83 ~64 ~10 ~83 stained_hardened_clay 0  
fill ~64 ~7 ~84 ~64 ~7 ~83 stained_hardened_clay 0  
fill ~64 ~7 ~85 ~64 ~11 ~85 stained_hardened_clay 8  
fill ~65 ~7 ~82 ~67 ~7 ~82 stained_hardened_clay 9  
fill ~65 ~7 ~84 ~67 ~7 ~84 stained_hardened_clay 9  
fill ~65 ~7 ~85 ~67 ~7 ~85 stained_hardened_clay 9  
fill ~65 ~7 ~86 ~66 ~7 ~86 stained_hardened_clay 0  
fill ~67 ~7 ~83 ~67 ~10 ~83 stained_hardened_clay 9 
setblock ~87 ~7 ~6 soul_sand 0  
fill ~88 ~7 ~4 ~88 ~7 ~6 netherrack 0  
fill ~89 ~7 ~4 ~90 ~7 ~4 nether_brick 0 
setblock ~89 ~7 ~5 netherrack 0 
setblock ~89 ~7 ~6 nether_brick 0 
setblock ~89 ~7 ~19 stained_hardened_clay 8 
setblock ~90 ~7 ~2 nether_brick 0  
fill ~90 ~7 ~3 ~93 ~7 ~3 bedrock 0  
fill ~90 ~7 ~5 ~91 ~7 ~5 nether_brick 0  
fill ~90 ~7 ~18 ~90 ~8 ~18 stained_hardened_clay 8  
fill ~90 ~7 ~21 ~91 ~7 ~21 stained_hardened_clay 8  
fill ~91 ~7 ~2 ~93 ~7 ~2 bedrock 0 
setblock ~91 ~7 ~4 bedrock 0  
fill ~91 ~7 ~18 ~93 ~7 ~18 stained_hardened_clay 0  
fill ~91 ~7 ~19 ~93 ~7 ~19 stained_hardened_clay 0  
fill ~91 ~7 ~20 ~93 ~7 ~20 stained_hardened_clay 0  
fill ~92 ~7 ~1 ~94 ~7 ~1 bedrock 0  
fill ~92 ~7 ~4 ~92 ~8 ~4 nether_brick 0  
fill ~92 ~7 ~16 ~93 ~7 ~16 stained_hardened_clay 0  
fill ~92 ~7 ~21 ~92 ~8 ~21 stained_hardened_clay 0 
setblock ~93 ~7 ~17 stained_hardened_clay 0  
fill ~93 ~7 ~21 ~95 ~7 ~21 stained_hardened_clay 8  
fill ~94 ~7 ~16 ~97 ~7 ~16 stained_hardened_clay 9  
fill ~94 ~7 ~17 ~98 ~7 ~17 stained_hardened_clay 9  
fill ~94 ~7 ~18 ~98 ~7 ~18 stained_hardened_clay 9  
fill ~94 ~7 ~19 ~97 ~7 ~19 stained_hardened_clay 9 
setblock ~94 ~7 ~20 stained_hardened_clay 8 
setblock ~95 ~7 ~15 stained_hardened_clay 9  
fill ~95 ~7 ~20 ~96 ~7 ~20 stained_hardened_clay 9  
fill ~116 ~7 ~34 ~117 ~7 ~34 stained_hardened_clay 8 
setblock ~117 ~7 ~33 stained_hardened_clay 0  
fill ~117 ~7 ~35 ~117 ~8 ~35 stained_hardened_clay 8  
fill ~117 ~7 ~38 ~118 ~7 ~38 stained_hardened_clay 8  
fill ~118 ~7 ~32 ~120 ~7 ~32 stained_hardened_clay 9  
fill ~118 ~7 ~33 ~121 ~7 ~33 stained_hardened_clay 9  
fill ~118 ~7 ~34 ~121 ~7 ~34 stained_hardened_clay 9  
fill ~118 ~7 ~35 ~118 ~17 ~35 stained_hardened_clay 0  
fill ~118 ~7 ~36 ~118 ~6 ~36 stained_hardened_clay 0  
fill ~118 ~7 ~37 ~119 ~7 ~37 stained_hardened_clay 8  
fill ~119 ~7 ~36 ~119 ~10 ~36 stained_hardened_clay 8 
setblock ~120 ~7 ~36 stained_hardened_clay 0 
setblock ~121 ~7 ~35 stained_hardened_clay 9  
fill ~14 ~8 ~86 ~19 ~8 ~86 stained_hardened_clay 0  
fill ~14 ~8 ~87 ~17 ~8 ~87 stained_hardened_clay 0  
fill ~15 ~8 ~83 ~16 ~8 ~83 stained_hardened_clay 0  
fill ~15 ~8 ~84 ~16 ~8 ~84 stained_hardened_clay 0  
fill ~15 ~8 ~85 ~17 ~8 ~85 stained_hardened_clay 0 
setblock ~16 ~8 ~82 stained_hardened_clay 0  
fill ~17 ~8 ~83 ~20 ~8 ~83 stained_hardened_clay 9  
fill ~18 ~8 ~82 ~19 ~8 ~82 stained_hardened_clay 9  
fill ~18 ~8 ~84 ~20 ~8 ~84 stained_hardened_clay 9  
fill ~18 ~8 ~85 ~19 ~8 ~85 stained_hardened_clay 9  
fill ~48 ~8 ~-6 ~50 ~8 ~-6 nether_brick 0  
fill ~49 ~8 ~-7 ~49 ~9 ~-7 nether_brick 0 
setblock ~49 ~8 ~-5 bedrock 0  
fill ~64 ~8 ~82 ~64 ~10 ~82 stained_hardened_clay 0  
fill ~64 ~8 ~84 ~64 ~11 ~84 stained_hardened_clay 8  
fill ~64 ~8 ~86 ~64 ~9 ~86 stained_hardened_clay 8  
fill ~65 ~8 ~81 ~65 ~12 ~81 stained_hardened_clay 0  
fill ~65 ~8 ~82 ~68 ~8 ~82 stained_hardened_clay 9  
fill ~65 ~8 ~84 ~68 ~8 ~84 stained_hardened_clay 9  
fill ~65 ~8 ~85 ~65 ~8 ~87 stained_hardened_clay 0  
fill ~66 ~8 ~81 ~67 ~8 ~81 stained_hardened_clay 9  
fill ~66 ~8 ~85 ~67 ~8 ~85 stained_hardened_clay 9  
fill ~66 ~8 ~86 ~67 ~8 ~86 stained_hardened_clay 0  
fill ~68 ~8 ~83 ~68 ~12 ~83 stained_hardened_clay 9 
setblock ~87 ~8 ~5 fire 0  
fill ~89 ~8 ~4 ~92 ~8 ~4 nether_brick 0 
setblock ~90 ~8 ~3 netherrack 0 
setblock ~91 ~8 ~2 nether_brick 0 
setblock ~91 ~8 ~3 soul_sand 0  
fill ~91 ~8 ~18 ~92 ~8 ~18 stained_hardened_clay 8  
fill ~91 ~8 ~19 ~91 ~9 ~19 stained_hardened_clay 8  
fill ~91 ~8 ~20 ~94 ~8 ~20 stained_hardened_clay 0 
setblock ~92 ~8 ~1 netherrack 0  
fill ~92 ~8 ~2 ~95 ~8 ~2 bedrock 0  
fill ~92 ~8 ~3 ~92 ~9 ~3 nether_brick 0  
fill ~92 ~8 ~19 ~94 ~8 ~19 stained_hardened_clay 0  
fill ~93 ~8 ~0 ~95 ~8 ~0 nether_brick 0  
fill ~93 ~8 ~1 ~96 ~8 ~1 bedrock 0  
fill ~93 ~8 ~3 ~94 ~8 ~3 bedrock 0  
fill ~93 ~8 ~16 ~94 ~8 ~16 stained_hardened_clay 8  
fill ~93 ~8 ~17 ~93 ~10 ~17 stained_hardened_clay 8  
fill ~93 ~8 ~18 ~94 ~8 ~18 stained_hardened_clay 0  
fill ~93 ~8 ~21 ~94 ~8 ~21 stained_hardened_clay 0  
fill ~94 ~8 ~15 ~95 ~8 ~15 stained_hardened_clay 0 
setblock ~94 ~8 ~17 stained_hardened_clay 0  
fill ~95 ~8 ~-1 ~95 ~9 ~-1 nether_brick 0  
fill ~95 ~8 ~16 ~99 ~8 ~16 stained_hardened_clay 9  
fill ~95 ~8 ~17 ~99 ~8 ~17 stained_hardened_clay 9  
fill ~95 ~8 ~18 ~98 ~8 ~18 stained_hardened_clay 9  
fill ~95 ~8 ~19 ~98 ~8 ~19 stained_hardened_clay 9  
fill ~95 ~8 ~20 ~96 ~8 ~20 stained_hardened_clay 8  
fill ~95 ~8 ~21 ~96 ~8 ~21 stained_hardened_clay 8  
fill ~96 ~8 ~-1 ~98 ~8 ~-1 bedrock 0  
fill ~96 ~8 ~0 ~97 ~8 ~0 bedrock 0  
fill ~96 ~8 ~15 ~97 ~8 ~15 stained_hardened_clay 9 
setblock ~97 ~8 ~20 stained_hardened_clay 9  
fill ~116 ~8 ~34 ~117 ~8 ~34 stained_hardened_clay 8  
fill ~117 ~8 ~32 ~118 ~8 ~32 stained_hardened_clay 0  
fill ~117 ~8 ~33 ~118 ~8 ~33 stained_hardened_clay 8 
setblock ~118 ~8 ~34 stained_hardened_clay 0  
fill ~118 ~8 ~36 ~118 ~8 ~37 stained_hardened_clay 8  
fill ~119 ~8 ~31 ~121 ~8 ~31 stained_hardened_clay 9  
fill ~119 ~8 ~32 ~121 ~8 ~32 stained_hardened_clay 9  
fill ~119 ~8 ~33 ~121 ~8 ~33 stained_hardened_clay 9  
fill ~119 ~8 ~34 ~121 ~8 ~34 stained_hardened_clay 9  
fill ~119 ~8 ~35 ~121 ~8 ~35 stained_hardened_clay 0  
fill ~119 ~8 ~37 ~120 ~8 ~37 stained_hardened_clay 8  
fill ~120 ~8 ~36 ~120 ~12 ~36 stained_hardened_clay 8  
fill ~15 ~9 ~83 ~15 ~8 ~83 stained_hardened_clay 0  
fill ~15 ~9 ~84 ~16 ~9 ~84 stained_hardened_clay 0  
fill ~15 ~9 ~85 ~17 ~9 ~85 stained_hardened_clay 0  
fill ~15 ~9 ~86 ~19 ~9 ~86 stained_hardened_clay 0  
fill ~16 ~9 ~82 ~16 ~11 ~82 stained_hardened_clay 8  
fill ~16 ~9 ~83 ~16 ~11 ~83 stained_hardened_clay 8  
fill ~16 ~9 ~87 ~18 ~9 ~87 stained_hardened_clay 0  
fill ~17 ~9 ~83 ~21 ~9 ~83 stained_hardened_clay 9  
fill ~18 ~9 ~81 ~21 ~9 ~81 stained_hardened_clay 9  
fill ~18 ~9 ~82 ~21 ~9 ~82 stained_hardened_clay 9  
fill ~18 ~9 ~84 ~20 ~9 ~84 stained_hardened_clay 9  
fill ~18 ~9 ~85 ~20 ~9 ~85 stained_hardened_clay 9  
fill ~48 ~9 ~-6 ~50 ~9 ~-6 nether_brick 0  
fill ~48 ~9 ~-5 ~48 ~9 ~-4 bedrock 0  
fill ~49 ~9 ~-5 ~49 ~10 ~-5 nether_brick 0  
fill ~49 ~9 ~-4 ~49 ~9 ~-7 nether_brick 0  
fill ~65 ~9 ~82 ~65 ~11 ~82 stained_hardened_clay 0  
fill ~65 ~9 ~83 ~65 ~10 ~83 stained_hardened_clay 0  
fill ~65 ~9 ~84 ~65 ~9 ~81 stained_hardened_clay 0  
fill ~65 ~9 ~85 ~65 ~12 ~85 stained_hardened_clay 8  
fill ~65 ~9 ~86 ~67 ~9 ~86 stained_hardened_clay 0  
fill ~66 ~9 ~81 ~68 ~9 ~81 stained_hardened_clay 9  
fill ~66 ~9 ~82 ~69 ~9 ~82 stained_hardened_clay 9  
fill ~66 ~9 ~84 ~68 ~9 ~84 stained_hardened_clay 9  
fill ~66 ~9 ~85 ~68 ~9 ~85 stained_hardened_clay 0  
fill ~67 ~9 ~80 ~67 ~12 ~80 stained_hardened_clay 9  
fill ~69 ~9 ~83 ~69 ~12 ~83 stained_hardened_clay 9 
setblock ~91 ~9 ~2 soul_sand 0 
setblock ~91 ~9 ~3 nether_brick 0  
fill ~91 ~9 ~18 ~92 ~9 ~18 stained_hardened_clay 8 
setblock ~92 ~9 ~1 soul_sand 0 
setblock ~92 ~9 ~2 netherrack 0 
setblock ~92 ~9 ~17 stained_hardened_clay 8 
setblock ~92 ~9 ~19 stained_hardened_clay 8  
fill ~92 ~9 ~20 ~95 ~9 ~20 stained_hardened_clay 0  
fill ~93 ~9 ~0 ~95 ~9 ~0 nether_brick 0  
fill ~93 ~9 ~1 ~93 ~10 ~1 netherrack 0 
setblock ~93 ~9 ~2 soul_sand 0  
fill ~93 ~9 ~3 ~94 ~9 ~3 nether_brick 0  
fill ~93 ~9 ~16 ~95 ~9 ~16 stained_hardened_clay 8  
fill ~93 ~9 ~18 ~96 ~9 ~18 stained_hardened_clay 0  
fill ~93 ~9 ~19 ~96 ~9 ~19 stained_hardened_clay 0  
fill ~94 ~9 ~-1 ~94 ~10 ~-1 nether_brick 0 
setblock ~94 ~9 ~1 nether_brick 0  
fill ~94 ~9 ~2 ~96 ~9 ~2 bedrock 0 
setblock ~94 ~9 ~17 stained_hardened_clay 8 
setblock ~94 ~9 ~21 stained_hardened_clay 0  
fill ~95 ~9 ~-2 ~98 ~9 ~-2 nether_brick 0 
setblock ~95 ~9 ~1 bedrock 0  
fill ~95 ~9 ~15 ~95 ~15 ~15 stained_hardened_clay 8  
fill ~95 ~9 ~17 ~95 ~16 ~17 stained_hardened_clay 0  
fill ~95 ~9 ~21 ~96 ~9 ~21 stained_hardened_clay 8  
fill ~96 ~9 ~-1 ~96 ~10 ~-1 nether_brick 0  
fill ~96 ~9 ~0 ~99 ~9 ~0 bedrock 0  
fill ~96 ~9 ~1 ~96 ~11 ~1 nether_brick 0  
fill ~96 ~9 ~15 ~99 ~9 ~15 stained_hardened_clay 9  
fill ~96 ~9 ~16 ~99 ~9 ~16 stained_hardened_clay 9  
fill ~96 ~9 ~17 ~100 ~9 ~17 stained_hardened_clay 9 
setblock ~96 ~9 ~20 stained_hardened_clay 8 
setblock ~97 ~9 ~-1 bedrock 0 
setblock ~97 ~9 ~1 bedrock 0  
fill ~97 ~9 ~18 ~99 ~9 ~18 stained_hardened_clay 9  
fill ~97 ~9 ~19 ~98 ~9 ~19 stained_hardened_clay 9  
fill ~97 ~9 ~20 ~98 ~9 ~20 stained_hardened_clay 0  
fill ~98 ~9 ~-1 ~98 ~12 ~-1 nether_brick 0  
fill ~99 ~9 ~-2 ~99 ~9 ~0 bedrock 0  
fill ~100 ~9 ~-1 ~100 ~10 ~-1 bedrock 0  
fill ~116 ~9 ~36 ~118 ~9 ~36 stained_hardened_clay 0  
fill ~117 ~9 ~32 ~118 ~9 ~32 stained_hardened_clay 8  
fill ~117 ~9 ~33 ~118 ~9 ~33 stained_hardened_clay 8  
fill ~117 ~9 ~34 ~118 ~9 ~34 stained_hardened_clay 8  
fill ~117 ~9 ~35 ~117 ~19 ~35 stained_hardened_clay 0 
setblock ~117 ~9 ~37 stained_hardened_clay 0  
fill ~118 ~9 ~31 ~118 ~12 ~31 stained_hardened_clay 8  
fill ~118 ~9 ~37 ~120 ~9 ~37 stained_hardened_clay 8  
fill ~119 ~9 ~31 ~121 ~9 ~31 stained_hardened_clay 9  
fill ~119 ~9 ~32 ~122 ~9 ~32 stained_hardened_clay 9  
fill ~119 ~9 ~33 ~122 ~9 ~33 stained_hardened_clay 9  
fill ~119 ~9 ~34 ~119 ~18 ~34 stained_hardened_clay 0  
fill ~119 ~9 ~35 ~121 ~9 ~35 stained_hardened_clay 0  
fill ~120 ~9 ~34 ~122 ~9 ~34 stained_hardened_clay 9 
setblock ~121 ~9 ~36 stained_hardened_clay 0 
setblock ~15 ~10 ~83 stained_hardened_clay 8  
fill ~15 ~10 ~84 ~17 ~10 ~84 stained_hardened_clay 0  
fill ~15 ~10 ~85 ~20 ~10 ~85 stained_hardened_clay 0  
fill ~16 ~10 ~86 ~19 ~10 ~86 stained_hardened_clay 0  
fill ~17 ~10 ~81 ~17 ~13 ~81 stained_hardened_clay 8  
fill ~17 ~10 ~82 ~17 ~13 ~82 stained_hardened_clay 8  
fill ~17 ~10 ~83 ~17 ~10 ~81 stained_hardened_clay 8 
setblock ~17 ~10 ~87 stained_hardened_clay 0  
fill ~18 ~10 ~81 ~22 ~10 ~81 stained_hardened_clay 9  
fill ~18 ~10 ~82 ~22 ~10 ~82 stained_hardened_clay 9  
fill ~18 ~10 ~83 ~22 ~10 ~83 stained_hardened_clay 9  
fill ~18 ~10 ~84 ~21 ~10 ~84 stained_hardened_clay 9  
fill ~19 ~10 ~80 ~22 ~10 ~80 stained_hardened_clay 9 
setblock ~47 ~10 ~-4 bedrock 0  
fill ~48 ~10 ~-6 ~49 ~10 ~-6 nether_brick 0  
fill ~48 ~10 ~-5 ~48 ~11 ~-5 nether_brick 0  
fill ~48 ~10 ~-4 ~48 ~11 ~-4 nether_brick 0  
fill ~65 ~10 ~80 ~66 ~10 ~80 stained_hardened_clay 0  
fill ~65 ~10 ~84 ~65 ~12 ~84 stained_hardened_clay 8  
fill ~65 ~10 ~86 ~67 ~10 ~86 stained_hardened_clay 8  
fill ~66 ~10 ~81 ~69 ~10 ~81 stained_hardened_clay 9  
fill ~66 ~10 ~82 ~70 ~10 ~82 stained_hardened_clay 9  
fill ~66 ~10 ~83 ~66 ~16 ~83 stained_hardened_clay 0  
fill ~66 ~10 ~84 ~66 ~10 ~83 stained_hardened_clay 0  
fill ~66 ~10 ~85 ~68 ~10 ~85 stained_hardened_clay 8  
fill ~67 ~10 ~84 ~68 ~10 ~84 stained_hardened_clay 9  
fill ~68 ~10 ~80 ~69 ~10 ~80 stained_hardened_clay 9 
setblock ~69 ~10 ~84 stained_hardened_clay 0 
setblock ~92 ~10 ~2 fire 0 
setblock ~92 ~10 ~18 stained_hardened_clay 8  
fill ~92 ~10 ~19 ~99 ~10 ~19 stained_hardened_clay 0  
fill ~93 ~10 ~0 ~95 ~10 ~0 nether_brick 0 
setblock ~93 ~10 ~2 netherrack 0  
fill ~93 ~10 ~18 ~98 ~10 ~18 stained_hardened_clay 0  
fill ~93 ~10 ~20 ~98 ~10 ~20 stained_hardened_clay 0 
setblock ~94 ~10 ~1 soul_sand 0  
fill ~94 ~10 ~2 ~96 ~10 ~2 nether_brick 0  
fill ~94 ~10 ~16 ~95 ~10 ~16 stained_hardened_clay 8  
fill ~94 ~10 ~17 ~94 ~15 ~17 stained_hardened_clay 0  
fill ~95 ~10 ~-2 ~99 ~10 ~-2 nether_brick 0 
setblock ~95 ~10 ~-1 soul_sand 0  
fill ~95 ~10 ~1 ~95 ~11 ~1 nether_brick 0  
fill ~95 ~10 ~21 ~97 ~10 ~21 stained_hardened_clay 0 
setblock ~96 ~10 ~0 netherrack 0  
fill ~96 ~10 ~15 ~96 ~17 ~15 stained_hardened_clay 8  
fill ~96 ~10 ~16 ~100 ~10 ~16 stained_hardened_clay 9  
fill ~96 ~10 ~17 ~96 ~16 ~17 stained_hardened_clay 0 
setblock ~97 ~10 ~-1 netherrack 0  
fill ~97 ~10 ~0 ~99 ~10 ~0 nether_brick 0  
fill ~97 ~10 ~1 ~99 ~10 ~1 nether_brick 0  
fill ~97 ~10 ~14 ~98 ~10 ~14 stained_hardened_clay 9  
fill ~97 ~10 ~15 ~100 ~10 ~15 stained_hardened_clay 9  
fill ~97 ~10 ~17 ~100 ~10 ~17 stained_hardened_clay 9  
fill ~98 ~10 ~-3 ~100 ~10 ~-3 nether_brick 0 
setblock ~99 ~10 ~-1 bedrock 0  
fill ~99 ~10 ~18 ~100 ~10 ~18 stained_hardened_clay 9 
setblock ~100 ~10 ~-2 bedrock 0 
setblock ~100 ~10 ~0 bedrock 0 
setblock ~101 ~10 ~-2 nether_brick 0  
fill ~101 ~10 ~-1 ~101 ~12 ~-1 bedrock 0  
fill ~117 ~10 ~33 ~119 ~10 ~33 stained_hardened_clay 8  
fill ~117 ~10 ~34 ~117 ~7 ~34 stained_hardened_clay 8  
fill ~117 ~10 ~36 ~118 ~10 ~36 stained_hardened_clay 0  
fill ~118 ~10 ~32 ~119 ~10 ~32 stained_hardened_clay 8  
fill ~118 ~10 ~34 ~118 ~19 ~34 stained_hardened_clay 0  
fill ~118 ~10 ~37 ~118 ~17 ~37 stained_hardened_clay 0 
setblock ~119 ~10 ~31 stained_hardened_clay 8  
fill ~119 ~10 ~35 ~122 ~10 ~35 stained_hardened_clay 0  
fill ~119 ~10 ~37 ~120 ~10 ~37 stained_hardened_clay 8  
fill ~120 ~10 ~30 ~120 ~14 ~30 stained_hardened_clay 9  
fill ~120 ~10 ~31 ~122 ~10 ~31 stained_hardened_clay 9  
fill ~120 ~10 ~32 ~122 ~10 ~32 stained_hardened_clay 9  
fill ~120 ~10 ~33 ~123 ~10 ~33 stained_hardened_clay 9  
fill ~120 ~10 ~34 ~121 ~10 ~34 stained_hardened_clay 0  
fill ~121 ~10 ~36 ~121 ~16 ~36 stained_hardened_clay 8  
fill ~122 ~10 ~34 ~122 ~12 ~34 stained_hardened_clay 9  
fill ~16 ~11 ~84 ~21 ~11 ~84 stained_hardened_clay 0  
fill ~16 ~11 ~85 ~20 ~11 ~85 stained_hardened_clay 0  
fill ~17 ~11 ~83 ~21 ~11 ~83 stained_hardened_clay 0 
setblock ~17 ~11 ~86 stained_hardened_clay 0  
fill ~18 ~11 ~80 ~23 ~11 ~80 stained_hardened_clay 9  
fill ~18 ~11 ~81 ~23 ~11 ~81 stained_hardened_clay 9 
setblock ~18 ~11 ~82 stained_hardened_clay 0  
fill ~19 ~11 ~82 ~23 ~11 ~82 stained_hardened_clay 9  
fill ~20 ~11 ~79 ~23 ~11 ~79 stained_hardened_clay 9  
fill ~22 ~11 ~83 ~22 ~13 ~83 stained_hardened_clay 9  
fill ~46 ~11 ~-4 ~48 ~11 ~-4 nether_brick 0 
setblock ~46 ~11 ~-3 bedrock 0 
setblock ~47 ~11 ~-5 nether_brick 0  
fill ~47 ~11 ~-3 ~47 ~12 ~-3 nether_brick 0  
fill ~64 ~11 ~82 ~64 ~12 ~82 stained_hardened_clay 8  
fill ~64 ~11 ~83 ~65 ~11 ~83 stained_hardened_clay 8  
fill ~66 ~11 ~80 ~66 ~11 ~83 stained_hardened_clay 0  
fill ~66 ~11 ~84 ~67 ~11 ~84 stained_hardened_clay 8  
fill ~66 ~11 ~85 ~68 ~11 ~85 stained_hardened_clay 8  
fill ~66 ~11 ~86 ~67 ~11 ~86 stained_hardened_clay 8  
fill ~67 ~11 ~79 ~69 ~11 ~79 stained_hardened_clay 9  
fill ~67 ~11 ~81 ~70 ~11 ~81 stained_hardened_clay 9  
fill ~67 ~11 ~82 ~70 ~11 ~82 stained_hardened_clay 9  
fill ~67 ~11 ~83 ~67 ~17 ~83 stained_hardened_clay 0  
fill ~68 ~11 ~80 ~70 ~11 ~80 stained_hardened_clay 9  
fill ~68 ~11 ~84 ~69 ~11 ~84 stained_hardened_clay 9 
setblock ~69 ~11 ~85 stained_hardened_clay 0  
fill ~70 ~11 ~83 ~70 ~12 ~83 stained_hardened_clay 9 
setblock ~70 ~11 ~84 stained_hardened_clay 0  
fill ~93 ~11 ~17 ~93 ~15 ~17 stained_hardened_clay 0  
fill ~93 ~11 ~18 ~98 ~11 ~18 stained_hardened_clay 0  
fill ~93 ~11 ~19 ~99 ~11 ~19 stained_hardened_clay 0 
setblock ~94 ~11 ~0 nether_brick 0  
fill ~94 ~11 ~15 ~94 ~13 ~15 stained_hardened_clay 8  
fill ~94 ~11 ~16 ~95 ~11 ~16 stained_hardened_clay 8  
fill ~94 ~11 ~20 ~99 ~11 ~20 stained_hardened_clay 0  
fill ~94 ~11 ~21 ~98 ~11 ~21 stained_hardened_clay 0  
fill ~95 ~11 ~-1 ~95 ~11 ~0 netherrack 0  
fill ~96 ~11 ~-2 ~96 ~11 ~-1 soul_sand 0  
fill ~96 ~11 ~0 ~100 ~11 ~0 nether_brick 0  
fill ~96 ~11 ~14 ~97 ~11 ~14 stained_hardened_clay 0  
fill ~96 ~11 ~16 ~96 ~12 ~16 stained_hardened_clay 0  
fill ~96 ~11 ~22 ~96 ~12 ~22 stained_hardened_clay 0  
fill ~97 ~11 ~-3 ~101 ~11 ~-3 nether_brick 0  
fill ~97 ~11 ~-2 ~100 ~11 ~-2 nether_brick 0 
setblock ~97 ~11 ~-1 soul_sand 0  
fill ~97 ~11 ~1 ~99 ~11 ~1 nether_brick 0  
fill ~97 ~11 ~15 ~101 ~11 ~15 stained_hardened_clay 9  
fill ~97 ~11 ~16 ~101 ~11 ~16 stained_hardened_clay 9  
fill ~97 ~11 ~17 ~97 ~15 ~17 stained_hardened_clay 0  
fill ~98 ~11 ~14 ~100 ~11 ~14 stained_hardened_clay 9  
fill ~98 ~11 ~17 ~101 ~11 ~17 stained_hardened_clay 9  
fill ~99 ~11 ~-1 ~100 ~11 ~-1 nether_brick 0  
fill ~99 ~11 ~18 ~100 ~11 ~18 stained_hardened_clay 9  
fill ~101 ~11 ~-2 ~103 ~11 ~-2 bedrock 0  
fill ~101 ~11 ~0 ~102 ~11 ~0 bedrock 0  
fill ~102 ~11 ~-1 ~103 ~11 ~-1 bedrock 0  
fill ~104 ~11 ~-2 ~104 ~13 ~-2 nether_brick 0  
fill ~104 ~11 ~-1 ~104 ~13 ~-1 nether_brick 0  
fill ~105 ~11 ~-1 ~106 ~11 ~-1 bedrock 0  
fill ~117 ~11 ~33 ~117 ~19 ~33 stained_hardened_clay 0  
fill ~117 ~11 ~34 ~117 ~19 ~34 stained_hardened_clay 0  
fill ~117 ~11 ~36 ~119 ~11 ~36 stained_hardened_clay 0  
fill ~118 ~11 ~32 ~119 ~11 ~32 stained_hardened_clay 8  
fill ~118 ~11 ~33 ~118 ~11 ~31 stained_hardened_clay 8  
fill ~119 ~11 ~31 ~122 ~11 ~31 stained_hardened_clay 9  
fill ~119 ~11 ~33 ~120 ~11 ~33 stained_hardened_clay 0  
fill ~119 ~11 ~35 ~122 ~11 ~35 stained_hardened_clay 0  
fill ~119 ~11 ~37 ~121 ~11 ~37 stained_hardened_clay 8  
fill ~120 ~11 ~32 ~123 ~11 ~32 stained_hardened_clay 9  
fill ~120 ~11 ~34 ~121 ~11 ~34 stained_hardened_clay 0  
fill ~121 ~11 ~30 ~121 ~17 ~30 stained_hardened_clay 9  
fill ~121 ~11 ~33 ~123 ~11 ~33 stained_hardened_clay 9 
setblock ~122 ~11 ~36 stained_hardened_clay 0  
fill ~123 ~11 ~34 ~123 ~12 ~34 stained_hardened_clay 9  
fill ~16 ~12 ~83 ~21 ~12 ~83 stained_hardened_clay 0  
fill ~16 ~12 ~84 ~22 ~12 ~84 stained_hardened_clay 0  
fill ~17 ~12 ~80 ~18 ~12 ~80 stained_hardened_clay 8  
fill ~17 ~12 ~85 ~20 ~12 ~85 stained_hardened_clay 0  
fill ~18 ~12 ~79 ~18 ~14 ~79 stained_hardened_clay 0  
fill ~18 ~12 ~81 ~18 ~13 ~81 stained_hardened_clay 8  
fill ~18 ~12 ~82 ~18 ~15 ~82 stained_hardened_clay 8  
fill ~19 ~12 ~79 ~24 ~12 ~79 stained_hardened_clay 9  
fill ~19 ~12 ~80 ~24 ~12 ~80 stained_hardened_clay 9  
fill ~19 ~12 ~81 ~24 ~12 ~81 stained_hardened_clay 9  
fill ~19 ~12 ~82 ~20 ~12 ~82 stained_hardened_clay 0  
fill ~21 ~12 ~78 ~24 ~12 ~78 stained_hardened_clay 9  
fill ~21 ~12 ~82 ~24 ~12 ~82 stained_hardened_clay 9  
fill ~23 ~12 ~83 ~23 ~13 ~83 stained_hardened_clay 9 
setblock ~45 ~12 ~-3 bedrock 0  
fill ~46 ~12 ~-4 ~46 ~11 ~-4 nether_brick 0  
fill ~46 ~12 ~-3 ~46 ~12 ~-2 nether_brick 0  
fill ~61 ~12 ~56 ~64 ~12 ~56 stained_glass 1  
fill ~62 ~12 ~55 ~65 ~12 ~55 stained_glass 1  
fill ~63 ~12 ~54 ~66 ~12 ~54 stained_glass 1 
setblock ~63 ~12 ~57 nether_brick 0  
fill ~64 ~12 ~51 ~67 ~12 ~51 stained_glass 1  
fill ~64 ~12 ~52 ~67 ~12 ~52 stained_glass 1  
fill ~64 ~12 ~53 ~67 ~12 ~53 stained_glass 1  
fill ~64 ~12 ~83 ~65 ~12 ~83 stained_hardened_clay 8  
fill ~65 ~12 ~48 ~65 ~16 ~48 cobblestone 0  
fill ~65 ~12 ~49 ~65 ~12 ~48 cobblestone 0  
fill ~65 ~12 ~50 ~69 ~12 ~50 stained_glass 1 
setblock ~65 ~12 ~80 stained_hardened_clay 0  
fill ~65 ~12 ~82 ~65 ~15 ~82 stained_hardened_clay 8  
fill ~66 ~12 ~47 ~70 ~12 ~47 stained_glass 1  
fill ~66 ~12 ~48 ~70 ~12 ~48 stained_glass 1  
fill ~66 ~12 ~49 ~70 ~12 ~49 stained_glass 1  
fill ~66 ~12 ~79 ~67 ~12 ~79 stained_hardened_clay 8  
fill ~66 ~12 ~80 ~66 ~14 ~80 stained_hardened_clay 8  
fill ~66 ~12 ~81 ~66 ~12 ~84 stained_hardened_clay 0  
fill ~66 ~12 ~85 ~69 ~12 ~85 stained_hardened_clay 8  
fill ~67 ~12 ~46 ~71 ~12 ~46 stained_glass 1  
fill ~67 ~12 ~81 ~71 ~12 ~81 stained_hardened_clay 9  
fill ~67 ~12 ~82 ~70 ~12 ~82 stained_hardened_clay 9  
fill ~67 ~12 ~84 ~70 ~12 ~84 stained_hardened_clay 8  
fill ~68 ~12 ~51 ~68 ~13 ~51 nether_brick 0  
fill ~68 ~12 ~52 ~68 ~12 ~51 nether_brick 0  
fill ~68 ~12 ~79 ~71 ~12 ~79 stained_hardened_clay 9  
fill ~68 ~12 ~80 ~71 ~12 ~80 stained_hardened_clay 9  
fill ~69 ~12 ~45 ~71 ~12 ~45 stained_glass 1  
fill ~69 ~12 ~51 ~69 ~13 ~51 cobblestone 0  
fill ~69 ~12 ~78 ~69 ~13 ~78 stained_hardened_clay 9  
fill ~70 ~12 ~50 ~72 ~12 ~50 cobblestone 0  
fill ~71 ~12 ~44 ~71 ~13 ~44 stained_glass 1  
fill ~71 ~12 ~47 ~72 ~12 ~47 cobblestone 0  
fill ~71 ~12 ~48 ~75 ~12 ~48 cobblestone 0  
fill ~71 ~12 ~49 ~74 ~12 ~49 cobblestone 0  
fill ~72 ~12 ~44 ~72 ~15 ~44 nether_brick 0  
fill ~72 ~12 ~45 ~72 ~15 ~45 nether_brick 0  
fill ~72 ~12 ~46 ~74 ~12 ~46 nether_brick 0  
fill ~73 ~12 ~43 ~75 ~12 ~43 cobblestone 0  
fill ~73 ~12 ~44 ~77 ~12 ~44 cobblestone 0  
fill ~73 ~12 ~45 ~77 ~12 ~45 cobblestone 0  
fill ~73 ~12 ~47 ~74 ~12 ~47 nether_brick 0 
setblock ~75 ~12 ~42 nether_brick 0  
fill ~75 ~12 ~46 ~78 ~12 ~46 cobblestone 0  
fill ~75 ~12 ~47 ~78 ~12 ~47 cobblestone 0  
fill ~76 ~12 ~42 ~77 ~12 ~42 stained_glass 1  
fill ~76 ~12 ~43 ~76 ~14 ~43 stained_glass 1  
fill ~76 ~12 ~48 ~76 ~13 ~48 nether_brick 0 
setblock ~77 ~12 ~43 cobblestone 0 
setblock ~78 ~12 ~42 cobblestone 0  
fill ~78 ~12 ~43 ~79 ~12 ~43 stained_glass 1  
fill ~78 ~12 ~44 ~81 ~12 ~44 stained_glass 1  
fill ~78 ~12 ~45 ~80 ~12 ~45 stained_glass 1  
fill ~79 ~12 ~42 ~80 ~12 ~42 stained_glass 1  
fill ~79 ~12 ~46 ~79 ~14 ~46 stained_glass 1 
setblock ~80 ~12 ~43 cobblestone 0  
fill ~81 ~12 ~43 ~81 ~13 ~43 stained_glass 1  
fill ~92 ~12 ~20 ~99 ~12 ~20 stained_hardened_clay 0  
fill ~92 ~12 ~21 ~99 ~12 ~21 stained_hardened_clay 0  
fill ~93 ~12 ~18 ~100 ~12 ~18 stained_hardened_clay 0  
fill ~93 ~12 ~19 ~100 ~12 ~19 stained_hardened_clay 0  
fill ~93 ~12 ~22 ~94 ~12 ~22 nether_brick 0  
fill ~94 ~12 ~16 ~95 ~12 ~16 stained_hardened_clay 8 
setblock ~95 ~12 ~-1 fire 0  
fill ~95 ~12 ~22 ~95 ~16 ~22 stained_hardened_clay 0  
fill ~95 ~12 ~23 ~95 ~15 ~23 nether_brick 0  
fill ~96 ~12 ~14 ~99 ~12 ~14 stained_hardened_clay 0  
fill ~97 ~12 ~-2 ~97 ~9 ~-2 nether_brick 0 
setblock ~97 ~12 ~-1 netherrack 0  
fill ~97 ~12 ~15 ~98 ~12 ~15 stained_hardened_clay 0  
fill ~97 ~12 ~16 ~98 ~12 ~16 stained_hardened_clay 0  
fill ~97 ~12 ~22 ~98 ~12 ~22 stained_hardened_clay 0  
fill ~98 ~12 ~-3 ~104 ~12 ~-3 nether_brick 0 
setblock ~98 ~12 ~-2 soul_sand 0 
setblock ~98 ~12 ~0 soul_sand 0  
fill ~98 ~12 ~17 ~98 ~16 ~17 stained_hardened_clay 0  
fill ~99 ~12 ~-2 ~100 ~12 ~-2 nether_brick 0  
fill ~99 ~12 ~-1 ~100 ~12 ~-1 soul_sand 0  
fill ~99 ~12 ~0 ~101 ~12 ~0 nether_brick 0  
fill ~99 ~12 ~15 ~103 ~12 ~15 stained_hardened_clay 9  
fill ~99 ~12 ~16 ~101 ~12 ~16 stained_hardened_clay 9  
fill ~99 ~12 ~17 ~101 ~12 ~17 stained_hardened_clay 9  
fill ~100 ~12 ~13 ~102 ~12 ~13 stained_hardened_clay 9  
fill ~100 ~12 ~14 ~103 ~12 ~14 stained_hardened_clay 9 
setblock ~101 ~12 ~-2 soul_sand 0  
fill ~102 ~12 ~-2 ~102 ~12 ~0 bedrock 0  
fill ~102 ~12 ~16 ~102 ~14 ~16 stained_hardened_clay 0  
fill ~103 ~12 ~-2 ~103 ~14 ~-2 nether_brick 0 
setblock ~103 ~12 ~-1 bedrock 0  
fill ~103 ~12 ~0 ~105 ~12 ~0 nether_brick 0  
fill ~105 ~12 ~-2 ~105 ~13 ~-2 nether_brick 0  
fill ~105 ~12 ~-1 ~109 ~12 ~-1 bedrock 0 
setblock ~106 ~12 ~-2 bedrock 0  
fill ~106 ~12 ~0 ~108 ~12 ~0 bedrock 0  
fill ~107 ~12 ~-2 ~108 ~12 ~-2 nether_brick 0  
fill ~113 ~12 ~36 ~119 ~12 ~36 stained_hardened_clay 0  
fill ~114 ~12 ~35 ~122 ~12 ~35 stained_hardened_clay 0  
fill ~114 ~12 ~37 ~119 ~12 ~37 stained_hardened_clay 0  
fill ~115 ~12 ~34 ~121 ~12 ~34 stained_hardened_clay 0  
fill ~116 ~12 ~38 ~116 ~16 ~38 stained_hardened_clay 0  
fill ~117 ~12 ~32 ~119 ~12 ~32 stained_hardened_clay 0  
fill ~118 ~12 ~33 ~120 ~12 ~33 stained_hardened_clay 0  
fill ~119 ~12 ~30 ~119 ~13 ~30 stained_hardened_clay 8  
fill ~119 ~12 ~31 ~122 ~12 ~31 stained_hardened_clay 9  
fill ~120 ~12 ~32 ~123 ~12 ~32 stained_hardened_clay 9  
fill ~120 ~12 ~37 ~121 ~12 ~37 stained_hardened_clay 8  
fill ~121 ~12 ~33 ~123 ~12 ~33 stained_hardened_clay 9  
fill ~122 ~12 ~30 ~122 ~18 ~30 stained_hardened_clay 9 
setblock ~122 ~12 ~36 stained_hardened_clay 8  
fill ~17 ~13 ~80 ~17 ~12 ~80 stained_hardened_clay 8  
fill ~17 ~13 ~83 ~19 ~13 ~83 stained_hardened_clay 8  
fill ~18 ~13 ~80 ~19 ~13 ~80 stained_hardened_clay 0  
fill ~18 ~13 ~84 ~18 ~14 ~84 stained_hardened_clay 8  
fill ~19 ~13 ~78 ~24 ~13 ~78 stained_hardened_clay 9  
fill ~19 ~13 ~79 ~25 ~13 ~79 stained_hardened_clay 9  
fill ~19 ~13 ~81 ~20 ~13 ~81 stained_hardened_clay 0  
fill ~19 ~13 ~82 ~20 ~13 ~82 stained_hardened_clay 0  
fill ~19 ~13 ~84 ~22 ~13 ~84 stained_hardened_clay 0  
fill ~20 ~13 ~80 ~25 ~13 ~80 stained_hardened_clay 9  
fill ~20 ~13 ~83 ~21 ~13 ~83 stained_hardened_clay 0  
fill ~21 ~13 ~81 ~24 ~13 ~81 stained_hardened_clay 9  
fill ~21 ~13 ~82 ~24 ~13 ~82 stained_hardened_clay 9  
fill ~22 ~13 ~77 ~23 ~13 ~77 stained_hardened_clay 9 
setblock ~24 ~13 ~83 stained_hardened_clay 9 
setblock ~44 ~13 ~-2 bedrock 0  
fill ~44 ~13 ~-1 ~44 ~15 ~-1 nether_brick 0  
fill ~45 ~13 ~-4 ~45 ~13 ~-2 nether_brick 0  
fill ~60 ~13 ~54 ~66 ~13 ~54 stained_glass 1  
fill ~60 ~13 ~55 ~67 ~13 ~55 stained_glass 1  
fill ~60 ~13 ~56 ~67 ~13 ~56 stained_glass 1  
fill ~60 ~13 ~57 ~67 ~13 ~57 stained_glass 1  
fill ~60 ~13 ~58 ~62 ~13 ~58 stained_glass 1  
fill ~61 ~13 ~53 ~67 ~13 ~53 stained_glass 1  
fill ~61 ~13 ~59 ~61 ~14 ~59 stained_glass 1  
fill ~62 ~13 ~52 ~67 ~13 ~52 stained_glass 1  
fill ~62 ~13 ~59 ~64 ~13 ~59 cobblestone 0  
fill ~63 ~13 ~49 ~63 ~15 ~49 cobblestone 0  
fill ~63 ~13 ~50 ~63 ~15 ~50 cobblestone 0  
fill ~63 ~13 ~51 ~67 ~13 ~51 stained_glass 1 
setblock ~63 ~13 ~58 nether_brick 0  
fill ~64 ~13 ~47 ~65 ~13 ~47 cobblestone 0  
fill ~64 ~13 ~48 ~64 ~17 ~48 cobblestone 0  
fill ~64 ~13 ~49 ~66 ~13 ~49 nether_brick 0  
fill ~64 ~13 ~50 ~69 ~13 ~50 stained_glass 1  
fill ~64 ~13 ~58 ~65 ~13 ~58 stained_glass 1  
fill ~65 ~13 ~46 ~66 ~13 ~46 cobblestone 0  
fill ~65 ~13 ~80 ~65 ~13 ~83 stained_hardened_clay 8  
fill ~65 ~13 ~84 ~67 ~13 ~84 stained_hardened_clay 0  
fill ~66 ~13 ~47 ~70 ~13 ~47 stained_glass 1  
fill ~66 ~13 ~48 ~70 ~13 ~48 stained_glass 1  
fill ~66 ~13 ~79 ~67 ~13 ~79 stained_hardened_clay 8  
fill ~66 ~13 ~81 ~66 ~15 ~81 stained_hardened_clay 8  
fill ~66 ~13 ~82 ~67 ~13 ~82 stained_hardened_clay 0 
setblock ~66 ~13 ~85 stained_hardened_clay 0  
fill ~67 ~13 ~45 ~71 ~13 ~45 stained_glass 1  
fill ~67 ~13 ~46 ~71 ~13 ~46 stained_glass 1  
fill ~67 ~13 ~49 ~70 ~13 ~49 stained_glass 1 
setblock ~67 ~13 ~54 nether_brick 0 
setblock ~67 ~13 ~78 stained_hardened_clay 8 
setblock ~67 ~13 ~80 stained_hardened_clay 8  
fill ~67 ~13 ~81 ~67 ~23 ~81 stained_hardened_clay 0  
fill ~67 ~13 ~85 ~69 ~13 ~85 stained_hardened_clay 8  
fill ~68 ~13 ~44 ~71 ~13 ~44 stained_glass 1  
fill ~68 ~13 ~52 ~68 ~13 ~54 cobblestone 0 
setblock ~68 ~13 ~55 nether_brick 0 
setblock ~68 ~13 ~56 cobblestone 0  
fill ~68 ~13 ~78 ~68 ~19 ~78 stained_hardened_clay 0  
fill ~68 ~13 ~79 ~68 ~23 ~79 stained_hardened_clay 0  
fill ~68 ~13 ~80 ~71 ~13 ~80 stained_hardened_clay 9  
fill ~68 ~13 ~81 ~71 ~13 ~81 stained_hardened_clay 9  
fill ~68 ~13 ~82 ~70 ~13 ~82 stained_hardened_clay 9  
fill ~68 ~13 ~83 ~70 ~13 ~83 stained_hardened_clay 8  
fill ~68 ~13 ~84 ~70 ~13 ~84 stained_hardened_clay 8  
fill ~69 ~13 ~43 ~72 ~13 ~43 stained_glass 1 
setblock ~69 ~13 ~52 nether_brick 0  
fill ~69 ~13 ~53 ~71 ~13 ~53 cobblestone 0  
fill ~69 ~13 ~54 ~70 ~13 ~54 cobblestone 0  
fill ~69 ~13 ~55 ~69 ~14 ~55 cobblestone 0  
fill ~69 ~13 ~79 ~72 ~13 ~79 stained_hardened_clay 9  
fill ~70 ~13 ~50 ~70 ~13 ~51 nether_brick 0 
setblock ~70 ~13 ~52 cobblestone 0  
fill ~70 ~13 ~78 ~71 ~13 ~78 stained_hardened_clay 9  
fill ~71 ~13 ~47 ~71 ~13 ~48 nether_brick 0  
fill ~71 ~13 ~49 ~78 ~13 ~49 cobblestone 0  
fill ~71 ~13 ~50 ~76 ~13 ~50 cobblestone 0  
fill ~71 ~13 ~51 ~73 ~13 ~51 cobblestone 0 
setblock ~71 ~13 ~52 nether_brick 0  
fill ~71 ~13 ~82 ~71 ~20 ~82 stained_hardened_clay 0  
fill ~71 ~13 ~83 ~71 ~16 ~83 stained_hardened_clay 0  
fill ~72 ~13 ~42 ~73 ~13 ~42 stained_glass 1  
fill ~72 ~13 ~46 ~75 ~13 ~46 nether_brick 0 
setblock ~72 ~13 ~47 cobblestone 0 
setblock ~72 ~13 ~48 nether_brick 0  
fill ~72 ~13 ~52 ~72 ~14 ~52 cobblestone 0  
fill ~73 ~13 ~43 ~74 ~13 ~43 nether_brick 0  
fill ~73 ~13 ~44 ~73 ~15 ~44 nether_brick 0  
fill ~73 ~13 ~45 ~73 ~12 ~45 cobblestone 0  
fill ~73 ~13 ~47 ~74 ~13 ~47 nether_brick 0  
fill ~73 ~13 ~48 ~75 ~13 ~48 cobblestone 0  
fill ~74 ~13 ~41 ~74 ~13 ~43 nether_brick 0  
fill ~74 ~13 ~44 ~75 ~13 ~44 cobblestone 0  
fill ~74 ~13 ~45 ~74 ~14 ~45 nether_brick 0  
fill ~75 ~13 ~41 ~79 ~13 ~41 stained_glass 1  
fill ~75 ~13 ~42 ~80 ~13 ~42 stained_glass 1  
fill ~75 ~13 ~43 ~75 ~15 ~43 stained_glass 1 
setblock ~75 ~13 ~45 cobblestone 0  
fill ~75 ~13 ~47 ~81 ~13 ~47 cobblestone 0  
fill ~76 ~13 ~44 ~84 ~13 ~44 stained_glass 1   

KittysCommands:  
setblock ~76 ~13 ~45 nether_brick 0  
fill ~76 ~13 ~46 ~78 ~13 ~46 cobblestone 0 
setblock ~77 ~13 ~40 cobblestone 0  
fill ~77 ~13 ~43 ~84 ~13 ~43 stained_glass 1 
setblock ~77 ~13 ~45 cobblestone 0  
fill ~77 ~13 ~48 ~79 ~13 ~48 cobblestone 0  
fill ~78 ~13 ~40 ~78 ~15 ~40 stained_glass 1  
fill ~78 ~13 ~45 ~83 ~13 ~45 stained_glass 1  
fill ~79 ~13 ~40 ~79 ~14 ~40 nether_brick 0  
fill ~80 ~13 ~39 ~81 ~13 ~39 bedrock 0  
fill ~80 ~13 ~40 ~80 ~14 ~40 bedrock 0  
fill ~80 ~13 ~41 ~81 ~13 ~41 nether_brick 0  
fill ~80 ~13 ~46 ~81 ~13 ~46 stained_glass 1  
fill ~81 ~13 ~40 ~86 ~13 ~40 cobblestone 0  
fill ~81 ~13 ~42 ~85 ~13 ~42 cobblestone 0  
fill ~82 ~13 ~38 ~83 ~13 ~38 bedrock 0  
fill ~82 ~13 ~39 ~86 ~13 ~39 cobblestone 0  
fill ~82 ~13 ~41 ~86 ~13 ~41 cobblestone 0 
setblock ~82 ~13 ~46 cobblestone 0  
fill ~84 ~13 ~38 ~85 ~13 ~38 cobblestone 0 
setblock ~85 ~13 ~43 cobblestone 0  
fill ~91 ~13 ~20 ~91 ~27 ~20 nether_brick 0  
fill ~91 ~13 ~21 ~92 ~13 ~21 nether_brick 0  
fill ~91 ~13 ~22 ~94 ~13 ~22 nether_brick 0  
fill ~92 ~13 ~18 ~101 ~13 ~18 stained_hardened_clay 0  
fill ~92 ~13 ~19 ~100 ~13 ~19 stained_hardened_clay 0  
fill ~92 ~13 ~20 ~100 ~13 ~20 stained_hardened_clay 0  
fill ~92 ~13 ~23 ~97 ~13 ~23 nether_brick 0  
fill ~92 ~13 ~24 ~96 ~13 ~24 nether_brick 0  
fill ~93 ~13 ~16 ~93 ~15 ~16 stained_hardened_clay 0  
fill ~93 ~13 ~21 ~99 ~13 ~21 stained_hardened_clay 0  
fill ~94 ~13 ~16 ~96 ~13 ~16 stained_hardened_clay 8  
fill ~96 ~13 ~22 ~98 ~13 ~22 nether_brick 0  
fill ~97 ~13 ~14 ~99 ~13 ~14 stained_hardened_clay 0  
fill ~97 ~13 ~15 ~101 ~13 ~15 stained_hardened_clay 0  
fill ~97 ~13 ~16 ~102 ~13 ~16 stained_hardened_clay 0  
fill ~99 ~13 ~-2 ~100 ~13 ~-2 nether_brick 0  
fill ~99 ~13 ~-1 ~99 ~13 ~-2 nether_brick 0  
fill ~99 ~13 ~13 ~104 ~13 ~13 stained_hardened_clay 9  
fill ~99 ~13 ~17 ~102 ~13 ~17 stained_hardened_clay 0  
fill ~99 ~13 ~22 ~99 ~15 ~22 stained_hardened_clay 0  
fill ~100 ~13 ~-3 ~107 ~13 ~-3 nether_brick 0  
fill ~100 ~13 ~-1 ~100 ~13 ~0 netherrack 0  
fill ~100 ~13 ~14 ~104 ~13 ~14 stained_hardened_clay 9  
fill ~100 ~13 ~42 ~110 ~13 ~42 nether_brick 0  
fill ~100 ~13 ~43 ~108 ~13 ~43 nether_brick 0 
setblock ~101 ~13 ~-2 netherrack 0 
setblock ~101 ~13 ~-1 soul_sand 0 
setblock ~101 ~13 ~0 nether_brick 0  
fill ~101 ~13 ~12 ~102 ~13 ~12 stained_hardened_clay 9  
fill ~101 ~13 ~40 ~114 ~13 ~40 nether_brick 0  
fill ~101 ~13 ~41 ~113 ~13 ~41 nether_brick 0  
fill ~101 ~13 ~44 ~106 ~13 ~44 nether_brick 0  
fill ~101 ~13 ~45 ~105 ~13 ~45 nether_brick 0  
fill ~102 ~13 ~-2 ~102 ~14 ~-2 nether_brick 0  
fill ~102 ~13 ~-1 ~107 ~13 ~-1 nether_brick 0 
setblock ~102 ~13 ~0 netherrack 0  
fill ~102 ~13 ~15 ~103 ~13 ~15 stained_hardened_clay 9  
fill ~103 ~13 ~0 ~106 ~13 ~0 nether_brick 0  
fill ~103 ~13 ~39 ~114 ~13 ~39 nether_brick 0  
fill ~105 ~13 ~1 ~107 ~13 ~1 nether_brick 0  
fill ~105 ~13 ~38 ~113 ~13 ~38 nether_brick 0  
fill ~106 ~13 ~-2 ~109 ~13 ~-2 nether_brick 0  
fill ~107 ~13 ~0 ~110 ~13 ~0 bedrock 0  
fill ~107 ~13 ~37 ~112 ~13 ~37 nether_brick 0  
fill ~108 ~13 ~-1 ~110 ~13 ~-1 bedrock 0 
setblock ~108 ~13 ~1 bedrock 0  
fill ~110 ~13 ~35 ~112 ~13 ~35 nether_brick 0  
fill ~110 ~13 ~36 ~112 ~13 ~36 nether_brick 0  
fill ~112 ~13 ~34 ~123 ~13 ~34 stained_hardened_clay 0  
fill ~113 ~13 ~35 ~122 ~13 ~35 stained_hardened_clay 0  
fill ~113 ~13 ~36 ~120 ~13 ~36 stained_hardened_clay 0  
fill ~113 ~13 ~37 ~119 ~13 ~37 stained_hardened_clay 0  
fill ~114 ~13 ~38 ~119 ~13 ~38 stained_hardened_clay 0  
fill ~115 ~13 ~33 ~120 ~13 ~33 stained_hardened_clay 0  
fill ~115 ~13 ~39 ~117 ~13 ~39 stained_hardened_clay 0  
fill ~116 ~13 ~32 ~119 ~13 ~32 stained_hardened_clay 0  
fill ~118 ~13 ~31 ~118 ~17 ~31 stained_hardened_clay 0  
fill ~119 ~13 ~31 ~123 ~13 ~31 stained_hardened_clay 9  
fill ~120 ~13 ~32 ~123 ~13 ~32 stained_hardened_clay 9  
fill ~120 ~13 ~37 ~121 ~13 ~37 stained_hardened_clay 8  
fill ~121 ~13 ~33 ~123 ~13 ~33 stained_hardened_clay 9 
setblock ~122 ~13 ~36 stained_hardened_clay 0  
fill ~17 ~14 ~81 ~21 ~14 ~81 stained_hardened_clay 0  
fill ~18 ~14 ~80 ~21 ~14 ~80 stained_hardened_clay 0  
fill ~18 ~14 ~83 ~19 ~14 ~83 stained_hardened_clay 8  
fill ~19 ~14 ~78 ~19 ~15 ~78 stained_hardened_clay 0  
fill ~19 ~14 ~79 ~19 ~17 ~79 stained_hardened_clay 0 
setblock ~19 ~14 ~82 stained_hardened_clay 8 
setblock ~19 ~14 ~84 stained_hardened_clay 8  
fill ~20 ~14 ~78 ~25 ~14 ~78 stained_hardened_clay 9  
fill ~20 ~14 ~79 ~25 ~14 ~79 stained_hardened_clay 9  
fill ~20 ~14 ~82 ~21 ~14 ~82 stained_hardened_clay 0  
fill ~20 ~14 ~83 ~24 ~14 ~83 stained_hardened_clay 0  
fill ~20 ~14 ~84 ~23 ~14 ~84 stained_hardened_clay 0  
fill ~21 ~14 ~77 ~25 ~14 ~77 stained_hardened_clay 9  
fill ~22 ~14 ~80 ~25 ~14 ~80 stained_hardened_clay 9  
fill ~22 ~14 ~81 ~25 ~14 ~81 stained_hardened_clay 9  
fill ~22 ~14 ~82 ~24 ~14 ~82 stained_hardened_clay 9  
fill ~43 ~14 ~-2 ~45 ~14 ~-2 nether_brick 0  
fill ~43 ~14 ~-1 ~43 ~14 ~0 bedrock 0 
setblock ~44 ~14 ~-3 nether_brick 0  
fill ~58 ~14 ~55 ~65 ~14 ~55 stained_glass 1  
fill ~58 ~14 ~56 ~66 ~14 ~56 stained_glass 1  
fill ~58 ~14 ~57 ~69 ~14 ~57 stained_glass 1  
fill ~58 ~14 ~58 ~62 ~14 ~58 stained_glass 1  
fill ~59 ~14 ~53 ~60 ~14 ~53 stained_glass 1  
fill ~59 ~14 ~54 ~60 ~14 ~54 stained_glass 1  
fill ~59 ~14 ~59 ~61 ~14 ~59 stained_glass 1  
fill ~59 ~14 ~60 ~59 ~15 ~60 stained_glass 1  
fill ~60 ~14 ~52 ~61 ~14 ~52 cobblestone 0  
fill ~60 ~14 ~60 ~60 ~15 ~60 nether_brick 0  
fill ~61 ~14 ~51 ~63 ~14 ~51 cobblestone 0  
fill ~61 ~14 ~53 ~61 ~15 ~53 lava 8  
fill ~61 ~14 ~54 ~61 ~15 ~54 lava 8  
fill ~61 ~14 ~60 ~62 ~14 ~60 cobblestone 0  
fill ~62 ~14 ~48 ~66 ~14 ~48 cobblestone 0  
fill ~62 ~14 ~49 ~62 ~14 ~51 cobblestone 0  
fill ~62 ~14 ~52 ~63 ~14 ~52 lava 8  
fill ~62 ~14 ~53 ~65 ~14 ~53 stained_glass 1  
fill ~62 ~14 ~54 ~64 ~14 ~54 stained_glass 1  
fill ~62 ~14 ~59 ~64 ~14 ~59 cobblestone 0  
fill ~62 ~14 ~61 ~62 ~15 ~61 nether_brick 0  
fill ~63 ~14 ~46 ~67 ~14 ~46 cobblestone 0  
fill ~63 ~14 ~47 ~66 ~14 ~47 cobblestone 0 
setblock ~63 ~14 ~58 cobblestone 0 
setblock ~63 ~14 ~60 nether_brick 0  
fill ~64 ~14 ~49 ~66 ~14 ~49 cobblestone 0  
fill ~64 ~14 ~50 ~64 ~14 ~46 cobblestone 0  
fill ~64 ~14 ~51 ~66 ~14 ~51 stained_glass 1  
fill ~64 ~14 ~52 ~66 ~14 ~52 stained_glass 1  
fill ~64 ~14 ~58 ~68 ~14 ~58 stained_glass 1  
fill ~64 ~14 ~60 ~65 ~14 ~60 cobblestone 0  
fill ~65 ~14 ~45 ~67 ~14 ~45 cobblestone 0  
fill ~65 ~14 ~50 ~72 ~14 ~50 lava 8  
fill ~65 ~14 ~54 ~69 ~14 ~54 lava 8  
fill ~65 ~14 ~59 ~67 ~14 ~59 stained_glass 1 
setblock ~65 ~14 ~81 stained_hardened_clay 8 
setblock ~65 ~14 ~83 stained_hardened_clay 0  
fill ~66 ~14 ~44 ~66 ~15 ~44 nether_brick 0  
fill ~66 ~14 ~53 ~68 ~14 ~53 lava 8  
fill ~66 ~14 ~55 ~68 ~14 ~55 lava 8  
fill ~66 ~14 ~79 ~67 ~14 ~79 stained_hardened_clay 8 
setblock ~66 ~14 ~82 stained_hardened_clay 8 
setblock ~66 ~14 ~84 stained_hardened_clay 0  
fill ~67 ~14 ~43 ~67 ~17 ~43 cobblestone 0  
fill ~67 ~14 ~44 ~67 ~15 ~44 cobblestone 0  
fill ~67 ~14 ~47 ~69 ~14 ~47 stained_glass 1  
fill ~67 ~14 ~48 ~69 ~14 ~48 stained_glass 1  
fill ~67 ~14 ~49 ~68 ~14 ~49 stained_glass 1  
fill ~67 ~14 ~51 ~71 ~14 ~51 lava 8  
fill ~67 ~14 ~52 ~67 ~15 ~52 lava 8  
fill ~67 ~14 ~56 ~67 ~15 ~56 lava 8  
fill ~67 ~14 ~78 ~67 ~16 ~78 stained_hardened_clay 0  
fill ~67 ~14 ~80 ~70 ~14 ~80 stained_hardened_clay 0  
fill ~67 ~14 ~82 ~71 ~14 ~82 stained_hardened_clay 0  
fill ~67 ~14 ~84 ~70 ~14 ~84 stained_hardened_clay 8  
fill ~67 ~14 ~85 ~68 ~14 ~85 stained_hardened_clay 8 
setblock ~68 ~14 ~43 nether_brick 0  
fill ~68 ~14 ~44 ~70 ~14 ~44 stained_glass 1  
fill ~68 ~14 ~45 ~70 ~14 ~45 stained_glass 1  
fill ~68 ~14 ~46 ~70 ~14 ~46 stained_glass 1 
setblock ~68 ~14 ~52 nether_brick 0 
setblock ~68 ~14 ~56 stained_glass 1  
fill ~68 ~14 ~81 ~72 ~14 ~81 stained_hardened_clay 0  
fill ~68 ~14 ~83 ~68 ~18 ~83 stained_hardened_clay 0  
fill ~69 ~14 ~42 ~78 ~14 ~42 stained_glass 1  
fill ~69 ~14 ~43 ~69 ~15 ~43 cobblestone 0  
fill ~69 ~14 ~49 ~71 ~14 ~49 lava 8  
fill ~69 ~14 ~52 ~69 ~14 ~53 cobblestone 0  
fill ~69 ~14 ~56 ~71 ~14 ~56 cobblestone 0  
fill ~69 ~14 ~78 ~69 ~21 ~78 stained_hardened_clay 0  
fill ~69 ~14 ~79 ~69 ~22 ~79 stained_hardened_clay 0 
setblock ~69 ~14 ~83 stained_hardened_clay 8  
fill ~70 ~14 ~43 ~72 ~14 ~43 stained_glass 1  
fill ~70 ~14 ~47 ~71 ~14 ~47 lava 8  
fill ~70 ~14 ~48 ~71 ~14 ~48 lava 8  
fill ~70 ~14 ~52 ~70 ~15 ~52 lava 8 
setblock ~70 ~14 ~53 nether_brick 0  
fill ~70 ~14 ~54 ~73 ~14 ~54 cobblestone 0  
fill ~70 ~14 ~55 ~72 ~14 ~55 cobblestone 0  
fill ~70 ~14 ~57 ~70 ~15 ~57 cobblestone 0  
fill ~70 ~14 ~77 ~70 ~16 ~77 stained_hardened_clay 9  
fill ~70 ~14 ~78 ~72 ~14 ~78 stained_hardened_clay 9  
fill ~70 ~14 ~79 ~72 ~14 ~79 stained_hardened_clay 9  
fill ~70 ~14 ~83 ~70 ~15 ~83 stained_hardened_clay 0  
fill ~71 ~14 ~41 ~79 ~14 ~41 stained_glass 1  
fill ~71 ~14 ~44 ~71 ~14 ~46 nether_brick 0  
fill ~71 ~14 ~52 ~71 ~14 ~56 cobblestone 0  
fill ~71 ~14 ~80 ~72 ~14 ~80 stained_hardened_clay 9  
fill ~72 ~14 ~46 ~75 ~14 ~46 nether_brick 0  
fill ~72 ~14 ~47 ~74 ~14 ~47 nether_brick 0  
fill ~72 ~14 ~48 ~72 ~14 ~49 cobblestone 0  
fill ~72 ~14 ~51 ~74 ~14 ~51 cobblestone 0  
fill ~72 ~14 ~53 ~74 ~14 ~53 cobblestone 0  
fill ~73 ~14 ~40 ~78 ~14 ~40 stained_glass 1  
fill ~73 ~14 ~43 ~74 ~14 ~43 nether_brick 0  
fill ~73 ~14 ~45 ~73 ~15 ~45 nether_brick 0  
fill ~73 ~14 ~48 ~73 ~15 ~48 nether_brick 0  
fill ~73 ~14 ~49 ~73 ~14 ~43 nether_brick 0 
setblock ~73 ~14 ~50 cobblestone 0 
setblock ~73 ~14 ~52 cobblestone 0  
fill ~74 ~14 ~39 ~74 ~16 ~39 stained_glass 1  
fill ~74 ~14 ~44 ~75 ~14 ~44 cobblestone 0  
fill ~74 ~14 ~48 ~74 ~14 ~49 cobblestone 0  
fill ~74 ~14 ~50 ~74 ~15 ~50 nether_brick 0  
fill ~74 ~14 ~52 ~75 ~14 ~52 bedrock 0 
setblock ~75 ~14 ~39 cobblestone 0 
setblock ~75 ~14 ~45 nether_brick 0  
fill ~75 ~14 ~47 ~81 ~14 ~47 cobblestone 0 
setblock ~75 ~14 ~48 nether_brick 0  
fill ~75 ~14 ~49 ~81 ~14 ~49 cobblestone 0  
fill ~75 ~14 ~50 ~75 ~15 ~50 cobblestone 0  
fill ~75 ~14 ~51 ~75 ~15 ~51 stained_hardened_clay 9  
fill ~76 ~14 ~39 ~78 ~14 ~39 nether_brick 0  
fill ~76 ~14 ~44 ~78 ~14 ~44 stained_glass 1  
fill ~76 ~14 ~45 ~76 ~14 ~49 cobblestone 0  
fill ~76 ~14 ~50 ~76 ~15 ~50 bedrock 0  
fill ~76 ~14 ~51 ~77 ~14 ~51 bedrock 0  
fill ~77 ~14 ~38 ~77 ~16 ~38 nether_brick 0  
fill ~77 ~14 ~43 ~77 ~13 ~43 stained_glass 1 
setblock ~77 ~14 ~45 nether_brick 0  
fill ~77 ~14 ~46 ~78 ~14 ~46 cobblestone 0  
fill ~77 ~14 ~48 ~78 ~14 ~48 cobblestone 0  
fill ~77 ~14 ~50 ~78 ~14 ~50 cobblestone 0  
fill ~78 ~14 ~38 ~81 ~14 ~38 bedrock 0  
fill ~78 ~14 ~43 ~85 ~14 ~43 lava 0  
fill ~78 ~14 ~45 ~79 ~14 ~45 stained_glass 1 
setblock ~78 ~14 ~51 stained_hardened_clay 9 
setblock ~79 ~14 ~39 stained_hardened_clay 9  
fill ~79 ~14 ~42 ~81 ~14 ~42 lava 0  
fill ~79 ~14 ~44 ~81 ~14 ~44 lava 0 
setblock ~79 ~14 ~48 stained_hardened_clay 9 
setblock ~79 ~14 ~50 stained_hardened_clay 9  
fill ~80 ~14 ~37 ~82 ~14 ~37 bedrock 0  
fill ~80 ~14 ~39 ~80 ~13 ~39 bedrock 0 
setblock ~80 ~14 ~41 lava 0 
setblock ~80 ~14 ~45 lava 0  
fill ~80 ~14 ~46 ~85 ~14 ~46 stained_glass 1  
fill ~80 ~14 ~48 ~82 ~14 ~48 cobblestone 0 
setblock ~81 ~14 ~39 stained_hardened_clay 9  
fill ~81 ~14 ~40 ~83 ~14 ~40 cobblestone 0  
fill ~81 ~14 ~41 ~82 ~14 ~41 cobblestone 0  
fill ~81 ~14 ~45 ~83 ~14 ~45 stained_glass 1  
fill ~82 ~14 ~38 ~82 ~15 ~38 stained_hardened_clay 9  
fill ~82 ~14 ~39 ~82 ~15 ~39 bedrock 0  
fill ~82 ~14 ~42 ~83 ~14 ~42 cobblestone 0 
setblock ~82 ~14 ~44 stained_glass 1  
fill ~82 ~14 ~47 ~83 ~14 ~47 stained_glass 1 
setblock ~83 ~14 ~37 stained_hardened_clay 9 
setblock ~83 ~14 ~38 bedrock 0  
fill ~83 ~14 ~39 ~84 ~14 ~39 cobblestone 0  
fill ~83 ~14 ~41 ~86 ~14 ~41 lava 0  
fill ~83 ~14 ~44 ~84 ~14 ~44 lava 0 
setblock ~84 ~14 ~37 bedrock 0  
fill ~84 ~14 ~38 ~86 ~14 ~38 cobblestone 0  
fill ~84 ~14 ~40 ~86 ~14 ~40 lava 0  
fill ~84 ~14 ~42 ~85 ~14 ~42 lava 0 
setblock ~84 ~14 ~45 cobblestone 0  
fill ~85 ~14 ~36 ~86 ~14 ~36 nether_brick 0  
fill ~85 ~14 ~37 ~86 ~14 ~37 nether_brick 0 
setblock ~85 ~14 ~39 lava 0  
fill ~85 ~14 ~44 ~87 ~14 ~44 stained_glass 1  
fill ~85 ~14 ~45 ~86 ~14 ~45 stained_glass 1  
fill ~86 ~14 ~39 ~90 ~14 ~39 cobblestone 0  
fill ~86 ~14 ~42 ~88 ~14 ~42 stained_glass 1  
fill ~86 ~14 ~43 ~88 ~14 ~43 stained_glass 1  
fill ~87 ~14 ~36 ~88 ~14 ~36 bedrock 0  
fill ~87 ~14 ~37 ~89 ~14 ~37 bedrock 0  
fill ~87 ~14 ~38 ~87 ~15 ~38 bedrock 0  
fill ~87 ~14 ~40 ~90 ~14 ~40 cobblestone 0  
fill ~87 ~14 ~41 ~90 ~14 ~41 cobblestone 0  
fill ~88 ~14 ~38 ~89 ~14 ~38 cobblestone 0  
fill ~89 ~14 ~24 ~97 ~14 ~24 nether_brick 0  
fill ~89 ~14 ~42 ~89 ~16 ~42 cobblestone 0  
fill ~90 ~14 ~21 ~92 ~14 ~21 nether_brick 0  
fill ~90 ~14 ~22 ~94 ~14 ~22 nether_brick 0  
fill ~90 ~14 ~23 ~98 ~14 ~23 nether_brick 0  
fill ~90 ~14 ~25 ~96 ~14 ~25 nether_brick 0  
fill ~90 ~14 ~38 ~90 ~17 ~38 bedrock 0  
fill ~91 ~14 ~19 ~100 ~14 ~19 stained_hardened_clay 0  
fill ~92 ~14 ~18 ~101 ~14 ~18 stained_hardened_clay 0  
fill ~92 ~14 ~20 ~100 ~14 ~20 stained_hardened_clay 0  
fill ~92 ~14 ~26 ~94 ~14 ~26 nether_brick 0  
fill ~93 ~14 ~21 ~100 ~14 ~21 stained_hardened_clay 0  
fill ~94 ~14 ~16 ~94 ~15 ~16 stained_hardened_clay 0  
fill ~95 ~14 ~16 ~96 ~14 ~16 stained_hardened_clay 8  
fill ~96 ~14 ~22 ~98 ~14 ~22 nether_brick 0  
fill ~97 ~14 ~15 ~97 ~16 ~15 stained_hardened_clay 8  
fill ~97 ~14 ~16 ~102 ~14 ~16 stained_hardened_clay 0  
fill ~98 ~14 ~14 ~99 ~14 ~14 stained_hardened_clay 0  
fill ~98 ~14 ~15 ~101 ~14 ~15 stained_hardened_clay 0  
fill ~99 ~14 ~17 ~101 ~14 ~17 stained_hardened_clay 0  
fill ~99 ~14 ~41 ~115 ~14 ~41 nether_brick 0  
fill ~99 ~14 ~42 ~113 ~14 ~42 nether_brick 0  
fill ~99 ~14 ~43 ~111 ~14 ~43 nether_brick 0  
fill ~99 ~14 ~44 ~109 ~14 ~44 nether_brick 0 
setblock ~100 ~14 ~0 fire 0  
fill ~100 ~14 ~13 ~104 ~14 ~13 stained_hardened_clay 9  
fill ~100 ~14 ~14 ~104 ~14 ~14 stained_hardened_clay 9  
fill ~100 ~14 ~39 ~114 ~14 ~39 nether_brick 0  
fill ~100 ~14 ~40 ~115 ~14 ~40 nether_brick 0  
fill ~100 ~14 ~45 ~107 ~14 ~45 nether_brick 0  
fill ~100 ~14 ~46 ~105 ~14 ~46 nether_brick 0  
fill ~101 ~14 ~-1 ~103 ~14 ~-1 nether_brick 0  
fill ~101 ~14 ~47 ~103 ~14 ~47 nether_brick 0  
fill ~102 ~14 ~12 ~105 ~14 ~12 stained_hardened_clay 9  
fill ~102 ~14 ~15 ~103 ~14 ~15 stained_hardened_clay 9  
fill ~102 ~14 ~38 ~113 ~14 ~38 nether_brick 0  
fill ~103 ~14 ~0 ~107 ~14 ~0 nether_brick 0 
setblock ~104 ~14 ~-3 soul_sand 0  
fill ~104 ~14 ~-2 ~105 ~14 ~-2 netherrack 0  
fill ~104 ~14 ~-1 ~104 ~14 ~-2 netherrack 0  
fill ~105 ~14 ~-3 ~108 ~14 ~-3 nether_brick 0  
fill ~105 ~14 ~-1 ~108 ~14 ~-1 nether_brick 0  
fill ~105 ~14 ~37 ~112 ~14 ~37 nether_brick 0  
fill ~106 ~14 ~-2 ~110 ~14 ~-2 nether_brick 0  
fill ~106 ~14 ~1 ~108 ~14 ~1 nether_brick 0  
fill ~107 ~14 ~36 ~112 ~14 ~36 nether_brick 0  
fill ~108 ~14 ~0 ~112 ~14 ~0 bedrock 0  
fill ~108 ~14 ~35 ~112 ~14 ~35 nether_brick 0 
setblock ~109 ~14 ~-1 bedrock 0  
fill ~109 ~14 ~1 ~111 ~14 ~1 bedrock 0  
fill ~110 ~14 ~-1 ~112 ~14 ~-1 nether_brick 0  
fill ~110 ~14 ~34 ~111 ~14 ~34 nether_brick 0  
fill ~112 ~14 ~34 ~122 ~14 ~34 stained_hardened_clay 0  
fill ~113 ~14 ~33 ~123 ~14 ~33 stained_hardened_clay 0  
fill ~113 ~14 ~35 ~122 ~14 ~35 stained_hardened_clay 0  
fill ~113 ~14 ~36 ~119 ~14 ~36 stained_hardened_clay 0  
fill ~113 ~14 ~37 ~119 ~14 ~37 stained_hardened_clay 0  
fill ~114 ~14 ~38 ~119 ~14 ~38 stained_hardened_clay 0  
fill ~115 ~14 ~32 ~120 ~14 ~32 stained_hardened_clay 0  
fill ~115 ~14 ~39 ~119 ~14 ~39 stained_hardened_clay 0  
fill ~116 ~14 ~40 ~117 ~14 ~40 stained_hardened_clay 0  
fill ~117 ~14 ~31 ~117 ~17 ~31 stained_hardened_clay 0  
fill ~119 ~14 ~30 ~119 ~14 ~39 stained_hardened_clay 0  
fill ~120 ~14 ~31 ~123 ~14 ~31 stained_hardened_clay 9  
fill ~120 ~14 ~36 ~120 ~17 ~36 stained_hardened_clay 8  
fill ~120 ~14 ~37 ~121 ~14 ~37 stained_hardened_clay 8  
fill ~120 ~14 ~38 ~120 ~16 ~38 stained_hardened_clay 8  
fill ~121 ~14 ~32 ~123 ~14 ~32 stained_hardened_clay 9  
fill ~18 ~15 ~80 ~23 ~15 ~80 stained_hardened_clay 0  
fill ~18 ~15 ~81 ~25 ~15 ~81 stained_hardened_clay 0  
fill ~18 ~15 ~83 ~21 ~15 ~83 stained_hardened_clay 8 
setblock ~19 ~15 ~82 stained_hardened_clay 0 
setblock ~19 ~15 ~84 stained_hardened_clay 0  
fill ~20 ~15 ~77 ~22 ~15 ~77 stained_hardened_clay 0  
fill ~20 ~15 ~78 ~22 ~15 ~78 stained_hardened_clay 0  
fill ~20 ~15 ~79 ~23 ~15 ~79 stained_hardened_clay 0  
fill ~20 ~15 ~82 ~20 ~17 ~82 stained_hardened_clay 8 
setblock ~20 ~15 ~84 stained_hardened_clay 8  
fill ~21 ~15 ~82 ~25 ~15 ~82 stained_hardened_clay 0  
fill ~21 ~15 ~84 ~23 ~15 ~84 stained_hardened_clay 0  
fill ~22 ~15 ~83 ~24 ~15 ~83 stained_hardened_clay 0  
fill ~23 ~15 ~77 ~26 ~15 ~77 stained_hardened_clay 9  
fill ~23 ~15 ~78 ~26 ~15 ~78 stained_hardened_clay 9  
fill ~24 ~15 ~79 ~26 ~15 ~79 stained_hardened_clay 9  
fill ~24 ~15 ~80 ~26 ~15 ~80 stained_hardened_clay 9  
fill ~25 ~15 ~76 ~25 ~19 ~76 stained_hardened_clay 9 
setblock ~42 ~15 ~0 nether_brick 0  
fill ~42 ~15 ~1 ~43 ~15 ~1 coal_block 0 
setblock ~43 ~15 ~-1 nether_brick 0  
fill ~43 ~15 ~0 ~43 ~16 ~0 coal_block 0 
setblock ~44 ~15 ~-2 nether_brick 0  
fill ~57 ~15 ~55 ~60 ~15 ~55 stained_glass 1  
fill ~57 ~15 ~56 ~61 ~15 ~56 stained_glass 1  
fill ~57 ~15 ~57 ~61 ~15 ~57 stained_glass 1  
fill ~57 ~15 ~58 ~61 ~15 ~58 stained_glass 1  
fill ~57 ~15 ~59 ~59 ~15 ~59 stained_glass 1  
fill ~57 ~15 ~60 ~59 ~15 ~60 stained_glass 1  
fill ~58 ~15 ~53 ~60 ~15 ~53 stained_glass 1  
fill ~58 ~15 ~54 ~60 ~15 ~54 stained_glass 1 
setblock ~58 ~15 ~61 stained_glass 1  
fill ~59 ~15 ~51 ~59 ~15 ~60 stained_glass 1  
fill ~59 ~15 ~61 ~60 ~15 ~61 cobblestone 0  
fill ~59 ~15 ~62 ~60 ~15 ~62 cobblestone 0  
fill ~59 ~15 ~63 ~59 ~15 ~61 cobblestone 0  
fill ~60 ~15 ~50 ~60 ~15 ~51 nether_brick 0  
fill ~60 ~15 ~52 ~72 ~15 ~52 lava 8 
setblock ~60 ~15 ~59 nether_brick 0  
fill ~61 ~15 ~48 ~65 ~15 ~48 cobblestone 0  
fill ~61 ~15 ~49 ~61 ~15 ~50 cobblestone 0  
fill ~61 ~15 ~51 ~73 ~15 ~51 lava 8  
fill ~61 ~15 ~55 ~70 ~15 ~55 lava 8  
fill ~61 ~15 ~59 ~65 ~15 ~59 lava 8  
fill ~61 ~15 ~60 ~61 ~15 ~62 nether_brick 0  
fill ~62 ~15 ~47 ~62 ~17 ~47 cobblestone 0 
setblock ~62 ~15 ~49 nether_brick 0 
setblock ~62 ~15 ~50 lava 8  
fill ~62 ~15 ~53 ~71 ~15 ~53 lava 8  
fill ~62 ~15 ~54 ~70 ~15 ~54 lava 8  
fill ~62 ~15 ~56 ~69 ~15 ~56 lava 8  
fill ~62 ~15 ~57 ~64 ~15 ~57 lava 8  
fill ~62 ~15 ~58 ~64 ~15 ~58 lava 8  
fill ~62 ~15 ~60 ~64 ~15 ~60 lava 8 
setblock ~62 ~15 ~62 bedrock 0  
fill ~63 ~15 ~46 ~64 ~15 ~46 cobblestone 0 
setblock ~63 ~15 ~47 nether_brick 0  
fill ~63 ~15 ~61 ~66 ~15 ~61 cobblestone 0  
fill ~63 ~15 ~62 ~64 ~15 ~62 cobblestone 0  
fill ~64 ~15 ~45 ~67 ~15 ~45 cobblestone 0  
fill ~64 ~15 ~47 ~65 ~15 ~47 cobblestone 0 
setblock ~64 ~15 ~49 nether_brick 0  
fill ~64 ~15 ~50 ~73 ~15 ~50 lava 8  
fill ~65 ~15 ~44 ~65 ~23 ~44 cobblestone 0 
setblock ~65 ~15 ~46 nether_brick 0 
setblock ~65 ~15 ~49 cobblestone 0  
fill ~65 ~15 ~57 ~65 ~15 ~58 stained_glass 1 
setblock ~65 ~15 ~60 cobblestone 0 
setblock ~66 ~15 ~43 bedrock 0  
fill ~66 ~15 ~46 ~66 ~17 ~46 cobblestone 0  
fill ~66 ~15 ~47 ~66 ~17 ~47 nether_brick 0  
fill ~66 ~15 ~48 ~66 ~16 ~48 nether_brick 0  
fill ~66 ~15 ~49 ~73 ~15 ~49 lava 8  
fill ~66 ~15 ~57 ~68 ~15 ~57 lava 8  
fill ~66 ~15 ~58 ~69 ~15 ~58 stained_glass 1  
fill ~66 ~15 ~59 ~69 ~15 ~59 stained_glass 1  
fill ~66 ~15 ~60 ~67 ~15 ~60 stained_glass 1  
fill ~66 ~15 ~79 ~69 ~15 ~79 stained_hardened_clay 0  
fill ~66 ~15 ~80 ~70 ~15 ~80 stained_hardened_clay 0  
fill ~66 ~15 ~82 ~72 ~15 ~82 stained_hardened_clay 0 
setblock ~67 ~15 ~42 cobblestone 0  
fill ~67 ~15 ~46 ~67 ~17 ~46 nether_brick 0  
fill ~67 ~15 ~47 ~71 ~15 ~47 lava 8  
fill ~67 ~15 ~48 ~72 ~15 ~48 lava 8 
setblock ~67 ~15 ~84 stained_hardened_clay 0  
fill ~68 ~15 ~41 ~68 ~18 ~41 cobblestone 0 
setblock ~68 ~15 ~42 bedrock 0  
fill ~68 ~15 ~43 ~68 ~17 ~43 cobblestone 0  
fill ~68 ~15 ~44 ~71 ~15 ~44 lava 8  
fill ~68 ~15 ~45 ~71 ~15 ~45 lava 8  
fill ~68 ~15 ~46 ~71 ~15 ~46 lava 8  
fill ~68 ~15 ~81 ~72 ~15 ~81 stained_hardened_clay 0 
setblock ~68 ~15 ~84 stained_hardened_clay 8  
fill ~69 ~15 ~41 ~77 ~15 ~41 stained_glass 1  
fill ~69 ~15 ~42 ~76 ~15 ~42 stained_glass 1 
setblock ~69 ~15 ~57 stained_glass 1  
fill ~69 ~15 ~77 ~69 ~16 ~77 stained_hardened_clay 0  
fill ~69 ~15 ~83 ~69 ~16 ~83 stained_hardened_clay 0  
fill ~69 ~15 ~84 ~70 ~15 ~84 stained_hardened_clay 0  
fill ~70 ~15 ~40 ~78 ~15 ~40 stained_glass 1  
fill ~70 ~15 ~43 ~75 ~15 ~43 stained_glass 1  
fill ~70 ~15 ~56 ~73 ~15 ~56 cobblestone 0 
setblock ~70 ~15 ~58 cobblestone 0  
fill ~70 ~15 ~78 ~72 ~15 ~78 stained_hardened_clay 9  
fill ~70 ~15 ~79 ~73 ~15 ~79 stained_hardened_clay 9  
fill ~71 ~15 ~54 ~74 ~15 ~54 cobblestone 0  
fill ~71 ~15 ~55 ~74 ~15 ~55 cobblestone 0  
fill ~71 ~15 ~57 ~72 ~15 ~57 cobblestone 0  
fill ~71 ~15 ~77 ~72 ~15 ~77 stained_hardened_clay 9  
fill ~71 ~15 ~80 ~72 ~15 ~80 stained_hardened_clay 9  
fill ~72 ~15 ~39 ~75 ~15 ~39 stained_glass 1  
fill ~72 ~15 ~46 ~74 ~15 ~46 nether_brick 0  
fill ~72 ~15 ~47 ~74 ~15 ~47 nether_brick 0  
fill ~72 ~15 ~53 ~73 ~15 ~53 cobblestone 0  
fill ~73 ~15 ~38 ~73 ~20 ~38 stained_glass 1  
fill ~73 ~15 ~52 ~74 ~15 ~52 bedrock 0  
fill ~74 ~15 ~38 ~76 ~15 ~38 cobblestone 0 
setblock ~74 ~15 ~44 nether_brick 0  
fill ~74 ~15 ~45 ~86 ~15 ~45 lava 8  
fill ~74 ~15 ~48 ~74 ~15 ~50 nether_brick 0 
setblock ~74 ~15 ~51 bedrock 0  
fill ~74 ~15 ~53 ~75 ~15 ~53 bedrock 0  
fill ~75 ~15 ~37 ~78 ~15 ~37 cobblestone 0  
fill ~75 ~15 ~44 ~86 ~15 ~44 lava 8  
fill ~75 ~15 ~46 ~77 ~15 ~46 lava 8  
fill ~75 ~15 ~47 ~75 ~12 ~47 cobblestone 0  
fill ~75 ~15 ~48 ~75 ~15 ~50 cobblestone 0 
setblock ~75 ~15 ~52 stained_hardened_clay 9  
fill ~75 ~15 ~54 ~75 ~16 ~54 bedrock 0  
fill ~76 ~15 ~39 ~77 ~15 ~39 cobblestone 0  
fill ~76 ~15 ~43 ~87 ~15 ~43 lava 8 
setblock ~76 ~15 ~47 lava 8 
setblock ~76 ~15 ~48 nether_brick 0  
fill ~76 ~15 ~49 ~84 ~15 ~49 cobblestone 0  
fill ~76 ~15 ~51 ~77 ~15 ~51 cobblestone 0  
fill ~76 ~15 ~52 ~77 ~15 ~52 bedrock 0 
setblock ~76 ~15 ~53 stained_hardened_clay 9  
fill ~77 ~15 ~42 ~88 ~15 ~42 lava 8  
fill ~77 ~15 ~47 ~79 ~15 ~47 cobblestone 0  
fill ~77 ~15 ~48 ~77 ~13 ~48 cobblestone 0  
fill ~77 ~15 ~50 ~79 ~15 ~50 cobblestone 0  
fill ~77 ~15 ~53 ~77 ~16 ~53 bedrock 0  
fill ~78 ~15 ~38 ~78 ~17 ~38 cobblestone 0  
fill ~78 ~15 ~39 ~78 ~17 ~39 nether_brick 0  
fill ~78 ~15 ~41 ~88 ~15 ~41 lava 8 
setblock ~78 ~15 ~46 cobblestone 0 
setblock ~78 ~15 ~48 bedrock 0 
setblock ~78 ~15 ~51 bedrock 0 
setblock ~78 ~15 ~52 stained_hardened_clay 9  
fill ~79 ~15 ~36 ~85 ~15 ~36 bedrock 0  
fill ~79 ~15 ~37 ~80 ~15 ~37 stained_hardened_clay 9  
fill ~79 ~15 ~38 ~79 ~16 ~38 stained_hardened_clay 9 
setblock ~79 ~15 ~39 bedrock 0  
fill ~79 ~15 ~40 ~88 ~15 ~40 lava 8  
fill ~79 ~15 ~46 ~84 ~15 ~46 lava 8 
setblock ~79 ~15 ~48 cobblestone 0  
fill ~79 ~15 ~51 ~81 ~15 ~51 stained_hardened_clay 9  
fill ~79 ~15 ~52 ~79 ~16 ~52 bedrock 0  
fill ~80 ~15 ~38 ~81 ~15 ~38 bedrock 0 
setblock ~80 ~15 ~39 stained_hardened_clay 9  
fill ~80 ~15 ~47 ~83 ~15 ~47 lava 8  
fill ~80 ~15 ~48 ~82 ~15 ~48 lava 8  
fill ~80 ~15 ~50 ~80 ~17 ~50 stained_hardened_clay 9 
setblock ~81 ~15 ~37 bedrock 0  
fill ~81 ~15 ~39 ~81 ~16 ~39 bedrock 0  
fill ~81 ~15 ~50 ~82 ~15 ~50 cobblestone 0  
fill ~82 ~15 ~37 ~82 ~17 ~37 stained_hardened_clay 9  
fill ~83 ~15 ~35 ~85 ~15 ~35 bedrock 0 
setblock ~83 ~15 ~37 bedrock 0 
setblock ~83 ~15 ~38 stained_hardened_clay 9  
fill ~83 ~15 ~39 ~87 ~15 ~39 lava 8  
fill ~83 ~15 ~48 ~85 ~15 ~48 cobblestone 0 
setblock ~84 ~15 ~37 stained_hardened_clay 9  
fill ~84 ~15 ~38 ~86 ~15 ~38 lava 8 
setblock ~84 ~15 ~47 stained_glass 1  
fill ~85 ~15 ~37 ~86 ~15 ~37 nether_brick 0  
fill ~85 ~15 ~46 ~88 ~15 ~46 stained_glass 1  
fill ~85 ~15 ~47 ~87 ~15 ~47 cobblestone 0  
fill ~86 ~15 ~35 ~86 ~30 ~35 nether_brick 0  
fill ~86 ~15 ~36 ~86 ~29 ~36 nether_brick 0  
fill ~87 ~15 ~35 ~92 ~15 ~35 bedrock 0  
fill ~87 ~15 ~36 ~92 ~15 ~36 bedrock 0  
fill ~87 ~15 ~37 ~93 ~15 ~37 bedrock 0  
fill ~87 ~15 ~44 ~89 ~15 ~44 stained_glass 1  
fill ~87 ~15 ~45 ~89 ~15 ~45 stained_glass 1  
fill ~88 ~15 ~24 ~98 ~15 ~24 nether_brick 0  
fill ~88 ~15 ~25 ~97 ~15 ~25 nether_brick 0  
fill ~88 ~15 ~38 ~88 ~14 ~38 cobblestone 0  
fill ~88 ~15 ~39 ~88 ~15 ~38 cobblestone 0  
fill ~88 ~15 ~43 ~89 ~15 ~43 stained_glass 1  
fill ~89 ~15 ~21 ~93 ~15 ~21 nether_brick 0  
fill ~89 ~15 ~22 ~93 ~15 ~22 nether_brick 0  
fill ~89 ~15 ~23 ~99 ~15 ~23 nether_brick 0  
fill ~89 ~15 ~26 ~96 ~15 ~26 nether_brick 0  
fill ~89 ~15 ~27 ~94 ~15 ~27 nether_brick 0  
fill ~89 ~15 ~38 ~89 ~17 ~38 bedrock 0  
fill ~89 ~15 ~39 ~89 ~17 ~39 bedrock 0  
fill ~89 ~15 ~40 ~91 ~15 ~40 cobblestone 0  
fill ~89 ~15 ~41 ~91 ~15 ~41 cobblestone 0  
fill ~90 ~15 ~19 ~91 ~15 ~19 nether_brick 0  
fill ~90 ~15 ~20 ~90 ~20 ~20 nether_brick 0  
fill ~90 ~15 ~34 ~91 ~15 ~34 bedrock 0  
fill ~90 ~15 ~39 ~90 ~16 ~39 cobblestone 0  
fill ~90 ~15 ~42 ~90 ~18 ~42 cobblestone 0  
fill ~90 ~15 ~43 ~91 ~15 ~43 cobblestone 0  
fill ~90 ~15 ~44 ~91 ~15 ~44 cobblestone 0  
fill ~90 ~15 ~45 ~90 ~18 ~45 cobblestone 0  
fill ~91 ~15 ~18 ~91 ~22 ~18 nether_brick 0  
fill ~91 ~15 ~28 ~92 ~15 ~28 nether_brick 0  
fill ~91 ~15 ~38 ~92 ~15 ~38 bedrock 0  
fill ~91 ~15 ~39 ~92 ~15 ~39 bedrock 0  
fill ~91 ~15 ~42 ~91 ~16 ~42 bedrock 0  
fill ~92 ~15 ~17 ~92 ~15 ~19 stained_hardened_clay 0  
fill ~92 ~15 ~20 ~92 ~26 ~20 nether_brick 0  
fill ~92 ~15 ~40 ~92 ~15 ~41 bedrock 0  
fill ~93 ~15 ~18 ~100 ~15 ~18 stained_hardened_clay 0  
fill ~93 ~15 ~19 ~100 ~15 ~19 stained_hardened_clay 0  
fill ~93 ~15 ~20 ~100 ~15 ~20 stained_hardened_clay 0  
fill ~94 ~15 ~21 ~100 ~15 ~21 stained_hardened_clay 0  
fill ~94 ~15 ~22 ~94 ~15 ~16 stained_hardened_clay 0  
fill ~95 ~15 ~16 ~97 ~15 ~16 stained_hardened_clay 8  
fill ~96 ~15 ~22 ~98 ~15 ~22 nether_brick 0  
fill ~98 ~15 ~15 ~102 ~15 ~15 stained_hardened_clay 0  
fill ~98 ~15 ~16 ~101 ~15 ~16 stained_hardened_clay 0  
fill ~98 ~15 ~41 ~116 ~15 ~41 nether_brick 0  
fill ~98 ~15 ~42 ~114 ~15 ~42 nether_brick 0  
fill ~98 ~15 ~43 ~113 ~15 ~43 nether_brick 0  
fill ~98 ~15 ~44 ~111 ~15 ~44 nether_brick 0  
fill ~98 ~15 ~45 ~109 ~15 ~45 nether_brick 0  
fill ~99 ~15 ~17 ~101 ~15 ~17 stained_hardened_clay 0  
fill ~99 ~15 ~39 ~114 ~15 ~39 nether_brick 0  
fill ~99 ~15 ~40 ~115 ~15 ~40 nether_brick 0  
fill ~99 ~15 ~46 ~107 ~15 ~46 nether_brick 0  
fill ~99 ~15 ~47 ~105 ~15 ~47 nether_brick 0  
fill ~100 ~15 ~38 ~113 ~15 ~38 nether_brick 0  
fill ~100 ~15 ~48 ~103 ~15 ~48 nether_brick 0  
fill ~101 ~15 ~13 ~105 ~15 ~13 stained_hardened_clay 9 
setblock ~101 ~15 ~14 stained_hardened_clay 0  
fill ~102 ~15 ~-1 ~102 ~15 ~0 stained_glass 7  
fill ~102 ~15 ~12 ~105 ~15 ~12 stained_hardened_clay 9  
fill ~102 ~15 ~14 ~104 ~15 ~14 stained_hardened_clay 9  
fill ~102 ~15 ~37 ~112 ~15 ~37 nether_brick 0 
setblock ~103 ~15 ~-2 stained_glass_pane 1 
setblock ~104 ~15 ~-2 netherrack 0  
fill ~104 ~15 ~-1 ~106 ~15 ~-1 nether_brick 0  
fill ~104 ~15 ~11 ~105 ~15 ~11 stained_hardened_clay 9  
fill ~105 ~15 ~-3 ~106 ~15 ~-3 nether_brick 0  
fill ~105 ~15 ~-2 ~107 ~15 ~-2 soul_sand 0  
fill ~105 ~15 ~0 ~110 ~15 ~0 nether_brick 0 
setblock ~105 ~15 ~1 stained_glass 7  
fill ~105 ~15 ~36 ~111 ~15 ~36 nether_brick 0  
fill ~106 ~15 ~35 ~111 ~15 ~35 nether_brick 0 
setblock ~107 ~15 ~-3 soul_sand 0  
fill ~107 ~15 ~-1 ~107 ~16 ~-1 netherrack 0  
fill ~108 ~15 ~-2 ~108 ~16 ~-2 netherrack 0  
fill ~108 ~15 ~-1 ~113 ~15 ~-1 nether_brick 0  
fill ~108 ~15 ~1 ~109 ~15 ~1 nether_brick 0  
fill ~109 ~15 ~-2 ~112 ~15 ~-2 nether_brick 0  
fill ~109 ~15 ~34 ~110 ~15 ~34 nether_brick 0  
fill ~110 ~15 ~1 ~114 ~15 ~1 bedrock 0  
fill ~111 ~15 ~0 ~114 ~15 ~0 bedrock 0  
fill ~111 ~15 ~2 ~113 ~15 ~2 bedrock 0  
fill ~111 ~15 ~33 ~123 ~15 ~33 stained_hardened_clay 0  
fill ~111 ~15 ~34 ~122 ~15 ~34 stained_hardened_clay 0  
fill ~112 ~15 ~35 ~122 ~15 ~35 stained_hardened_clay 0  
fill ~112 ~15 ~36 ~119 ~15 ~36 stained_hardened_clay 0  
fill ~113 ~15 ~32 ~121 ~15 ~32 stained_hardened_clay 0  
fill ~113 ~15 ~37 ~118 ~15 ~37 stained_hardened_clay 0  
fill ~114 ~15 ~38 ~119 ~15 ~38 stained_hardened_clay 0  
fill ~115 ~15 ~39 ~119 ~15 ~39 stained_hardened_clay 0  
fill ~116 ~15 ~31 ~116 ~18 ~31 stained_hardened_clay 0  
fill ~116 ~15 ~40 ~118 ~15 ~40 stained_hardened_clay 0  
fill ~119 ~15 ~31 ~120 ~15 ~31 stained_hardened_clay 0  
fill ~119 ~15 ~37 ~121 ~15 ~37 stained_hardened_clay 8  
fill ~120 ~15 ~30 ~120 ~16 ~30 stained_hardened_clay 0  
fill ~121 ~15 ~31 ~123 ~15 ~31 stained_hardened_clay 9  
fill ~122 ~15 ~32 ~123 ~15 ~32 stained_hardened_clay 9  
fill ~18 ~16 ~81 ~26 ~16 ~81 stained_hardened_clay 0  
fill ~19 ~16 ~80 ~25 ~16 ~80 stained_hardened_clay 0  
fill ~19 ~16 ~82 ~19 ~16 ~83 stained_hardened_clay 8  
fill ~20 ~16 ~78 ~23 ~16 ~78 stained_hardened_clay 0  
fill ~20 ~16 ~79 ~24 ~16 ~79 stained_hardened_clay 0  
fill ~20 ~16 ~83 ~21 ~16 ~83 stained_hardened_clay 8  
fill ~21 ~16 ~77 ~23 ~16 ~77 stained_hardened_clay 0 
setblock ~21 ~16 ~82 stained_hardened_clay 8 
setblock ~21 ~16 ~84 stained_hardened_clay 8  
fill ~22 ~16 ~82 ~25 ~16 ~82 stained_hardened_clay 0  
fill ~22 ~16 ~83 ~24 ~16 ~83 stained_hardened_clay 0  
fill ~22 ~16 ~84 ~22 ~16 ~77 stained_hardened_clay 0  
fill ~23 ~16 ~76 ~27 ~16 ~76 stained_hardened_clay 9  
fill ~24 ~16 ~77 ~27 ~16 ~77 stained_hardened_clay 9  
fill ~24 ~16 ~78 ~27 ~16 ~78 stained_hardened_clay 9  
fill ~25 ~16 ~79 ~27 ~16 ~79 stained_hardened_clay 9  
fill ~26 ~16 ~75 ~26 ~20 ~75 stained_hardened_clay 9  
fill ~26 ~16 ~80 ~27 ~16 ~80 stained_hardened_clay 9  
fill ~42 ~16 ~1 ~43 ~16 ~1 coal_block 0  
fill ~55 ~16 ~57 ~55 ~19 ~57 cobblestone 0  
fill ~55 ~16 ~58 ~59 ~16 ~58 stained_glass 1  
fill ~55 ~16 ~59 ~56 ~16 ~59 stained_glass 1  
fill ~56 ~16 ~54 ~59 ~16 ~54 stained_glass 1  
fill ~56 ~16 ~55 ~60 ~16 ~55 stained_glass 1  
fill ~56 ~16 ~56 ~56 ~19 ~56 cobblestone 0  
fill ~56 ~16 ~57 ~58 ~16 ~57 stained_glass 1  
fill ~56 ~16 ~60 ~56 ~16 ~62 stained_glass 1  
fill ~57 ~16 ~52 ~58 ~16 ~52 stained_glass 1  
fill ~57 ~16 ~53 ~58 ~16 ~53 stained_glass 1  
fill ~57 ~16 ~56 ~59 ~16 ~56 stained_glass 1  
fill ~57 ~16 ~59 ~66 ~16 ~59 lava 0  
fill ~57 ~16 ~60 ~66 ~16 ~60 lava 0 
setblock ~57 ~16 ~61 stained_glass 1 
setblock ~57 ~16 ~62 nether_brick 0  
fill ~57 ~16 ~63 ~58 ~16 ~63 cobblestone 0  
fill ~57 ~16 ~64 ~57 ~17 ~64 stained_glass 1  
fill ~58 ~16 ~51 ~58 ~17 ~51 stained_glass 1  
fill ~58 ~16 ~61 ~59 ~16 ~61 lava 0 
setblock ~58 ~16 ~62 cobblestone 0  
fill ~58 ~16 ~64 ~62 ~16 ~64 cobblestone 0  
fill ~59 ~16 ~49 ~60 ~16 ~49 stained_glass 1  
fill ~59 ~16 ~50 ~59 ~16 ~49 stained_glass 1  
fill ~59 ~16 ~51 ~74 ~16 ~51 lava 0  
fill ~59 ~16 ~52 ~73 ~16 ~52 lava 0  
fill ~59 ~16 ~53 ~72 ~16 ~53 lava 0  
fill ~59 ~16 ~57 ~71 ~16 ~57 lava 0  
fill ~59 ~16 ~62 ~59 ~16 ~63 nether_brick 0  
fill ~59 ~16 ~65 ~60 ~16 ~65 cobblestone 0  
fill ~60 ~16 ~48 ~61 ~16 ~48 stained_glass 1  
fill ~60 ~16 ~50 ~75 ~16 ~50 lava 0  
fill ~60 ~16 ~54 ~71 ~16 ~54 lava 0  
fill ~60 ~16 ~56 ~72 ~16 ~56 lava 0  
fill ~60 ~16 ~58 ~67 ~16 ~58 lava 0  
fill ~60 ~16 ~61 ~60 ~16 ~65 cobblestone 0  
fill ~61 ~16 ~47 ~61 ~18 ~47 stained_glass 1  
fill ~61 ~16 ~49 ~63 ~16 ~49 lava 0  
fill ~61 ~16 ~55 ~71 ~16 ~55 lava 0  
fill ~61 ~16 ~61 ~65 ~16 ~61 lava 0  
fill ~61 ~16 ~62 ~61 ~16 ~64 cobblestone 0 
setblock ~62 ~16 ~46 nether_brick 0  
fill ~62 ~16 ~48 ~65 ~16 ~48 cobblestone 0  
fill ~62 ~16 ~62 ~64 ~16 ~62 lava 0  
fill ~62 ~16 ~63 ~63 ~16 ~63 cobblestone 0  
fill ~63 ~16 ~45 ~67 ~16 ~45 cobblestone 0  
fill ~63 ~16 ~46 ~66 ~16 ~46 cobblestone 0  
fill ~63 ~16 ~47 ~65 ~16 ~47 cobblestone 0 
setblock ~64 ~16 ~44 cobblestone 0 
setblock ~64 ~16 ~49 cobblestone 0  
fill ~64 ~16 ~63 ~65 ~16 ~63 stained_hardened_clay 9   
fill ~65 ~16 ~43 ~68 ~16 ~43 cobblestone 0  
fill ~65 ~16 ~49 ~76 ~16 ~49 lava 0  
fill ~65 ~16 ~62 ~67 ~16 ~62 cobblestone 0  
fill ~66 ~16 ~44 ~66 ~22 ~44 cobblestone 0  
fill ~66 ~16 ~61 ~67 ~16 ~61 cobblestone 0  
fill ~66 ~16 ~79 ~69 ~16 ~79 stained_hardened_clay 0  
fill ~66 ~16 ~80 ~70 ~16 ~80 stained_hardened_clay 0  
fill ~66 ~16 ~81 ~66 ~23 ~81 stained_hardened_clay 0  
fill ~66 ~16 ~82 ~72 ~16 ~82 stained_hardened_clay 0 
setblock ~67 ~16 ~42 bedrock 0  
fill ~67 ~16 ~44 ~67 ~18 ~44 bedrock 0  
fill ~67 ~16 ~47 ~72 ~16 ~47 lava 0  
fill ~67 ~16 ~48 ~77 ~16 ~48 lava 0  
fill ~67 ~16 ~59 ~71 ~16 ~59 stained_glass 1  
fill ~67 ~16 ~60 ~70 ~16 ~60 stained_glass 1  
fill ~68 ~16 ~42 ~69 ~16 ~42 cobblestone 0  
fill ~68 ~16 ~44 ~87 ~16 ~44 lava 0  
fill ~68 ~16 ~45 ~86 ~16 ~45 lava 0  
fill ~68 ~16 ~46 ~86 ~16 ~46 lava 0  
fill ~68 ~16 ~58 ~69 ~16 ~58 stained_glass 1  
fill ~68 ~16 ~61 ~68 ~18 ~61 stained_glass 1  
fill ~68 ~16 ~81 ~72 ~16 ~81 stained_hardened_clay 0 
setblock ~68 ~16 ~84 stained_hardened_clay 0  
fill ~69 ~16 ~40 ~69 ~16 ~42 cobblestone 0  
fill ~69 ~16 ~43 ~72 ~16 ~43 lava 0  
fill ~69 ~16 ~84 ~70 ~16 ~84 stained_hardened_clay 8  
fill ~70 ~16 ~39 ~75 ~16 ~39 stained_glass 1  
fill ~70 ~16 ~40 ~76 ~16 ~40 stained_glass 1  
fill ~70 ~16 ~41 ~71 ~16 ~41 stained_glass 1  
fill ~70 ~16 ~42 ~70 ~16 ~39 stained_glass 1 
setblock ~70 ~16 ~58 lava 0  
fill ~70 ~16 ~78 ~73 ~16 ~78 stained_hardened_clay 9  
fill ~70 ~16 ~79 ~73 ~16 ~79 stained_hardened_clay 9  
fill ~70 ~16 ~83 ~70 ~19 ~83 stained_hardened_clay 8  
fill ~71 ~16 ~42 ~73 ~16 ~42 lava 0 
setblock ~71 ~16 ~58 stained_glass 1  
fill ~71 ~16 ~76 ~71 ~16 ~80 stained_hardened_clay 9  
fill ~72 ~16 ~38 ~72 ~17 ~38 stained_glass 1 
setblock ~72 ~16 ~41 lava 0  
fill ~72 ~16 ~54 ~72 ~16 ~55 cobblestone 0  
fill ~72 ~16 ~57 ~72 ~16 ~58 cobblestone 0  
fill ~72 ~16 ~77 ~73 ~16 ~77 stained_hardened_clay 9 
setblock ~72 ~16 ~80 stained_hardened_clay 9 
setblock ~73 ~16 ~37 cobblestone 0  
fill ~73 ~16 ~41 ~76 ~16 ~41 stained_glass 1 
setblock ~73 ~16 ~43 stained_glass 1 
setblock ~73 ~16 ~47 nether_brick 0 
setblock ~73 ~16 ~53 cobblestone 0  
fill ~73 ~16 ~54 ~77 ~16 ~54 bedrock 0  
fill ~73 ~16 ~55 ~73 ~16 ~56 cobblestone 0 
setblock ~73 ~16 ~57 nether_brick 0  
fill ~74 ~16 ~38 ~74 ~17 ~38 stained_glass 1 
setblock ~74 ~16 ~42 stained_glass 1  
fill ~74 ~16 ~43 ~88 ~16 ~43 lava 0  
fill ~74 ~16 ~47 ~85 ~16 ~47 lava 0  
fill ~74 ~16 ~52 ~81 ~16 ~52 bedrock 0  
fill ~74 ~16 ~53 ~78 ~16 ~53 bedrock 0  
fill ~74 ~16 ~55 ~76 ~16 ~55 bedrock 0  
fill ~74 ~16 ~56 ~75 ~16 ~56 cobblestone 0  
fill ~75 ~16 ~37 ~79 ~16 ~37 cobblestone 0  
fill ~75 ~16 ~38 ~76 ~16 ~38 cobblestone 0  
fill ~75 ~16 ~42 ~88 ~16 ~42 lava 0 
setblock ~75 ~16 ~51 bedrock 0  
fill ~76 ~16 ~36 ~79 ~16 ~36 cobblestone 0  
fill ~76 ~16 ~39 ~77 ~16 ~39 cobblestone 0 
setblock ~76 ~16 ~50 nether_brick 0 
setblock ~76 ~16 ~51 stained_hardened_clay 9 
setblock ~77 ~16 ~40 nether_brick 0  
fill ~77 ~16 ~41 ~89 ~16 ~41 lava 0  
fill ~77 ~16 ~49 ~78 ~16 ~49 cobblestone 0  
fill ~77 ~16 ~50 ~78 ~16 ~50 cobblestone 0 
setblock ~77 ~16 ~51 bedrock 0  
fill ~78 ~16 ~40 ~88 ~16 ~40 lava 0 
setblock ~78 ~16 ~48 cobblestone 0  
fill ~78 ~16 ~51 ~81 ~16 ~51 stained_hardened_clay 9 
setblock ~78 ~16 ~54 stained_hardened_clay 9 
setblock ~79 ~16 ~39 stained_hardened_clay 9  
fill ~79 ~16 ~48 ~83 ~16 ~48 lava 0 
setblock ~79 ~16 ~49 stained_hardened_clay 9 
setblock ~79 ~16 ~50 bedrock 0  
fill ~79 ~16 ~53 ~80 ~16 ~53 nether_brick 0  
fill ~80 ~16 ~35 ~80 ~17 ~35 stained_hardened_clay 9  
fill ~80 ~16 ~36 ~81 ~16 ~36 stained_hardened_clay 9 
setblock ~80 ~16 ~37 bedrock 0 
setblock ~80 ~16 ~38 stained_hardened_clay 9 
setblock ~80 ~16 ~39 lava 0  
fill ~80 ~16 ~49 ~82 ~16 ~49 lava 0 
setblock ~81 ~16 ~35 cobblestone 0 
setblock ~81 ~16 ~37 stained_hardened_clay 9  
fill ~81 ~16 ~38 ~82 ~16 ~38 bedrock 0 
setblock ~81 ~16 ~50 stained_hardened_clay 9  
fill ~82 ~16 ~35 ~85 ~16 ~35 stained_hardened_clay 9  
fill ~82 ~16 ~36 ~82 ~18 ~36 bedrock 0  
fill ~82 ~16 ~39 ~88 ~16 ~39 lava 0  
fill ~82 ~16 ~50 ~85 ~16 ~50 cobblestone 0  
fill ~82 ~16 ~51 ~82 ~19 ~51 nether_brick 0  
fill ~82 ~16 ~52 ~82 ~31 ~52 nether_brick 0  
fill ~83 ~16 ~34 ~84 ~16 ~34 bedrock 0  
fill ~83 ~16 ~36 ~85 ~16 ~36 stained_hardened_clay 9  
fill ~83 ~16 ~37 ~83 ~16 ~35 stained_hardened_clay 9  
fill ~83 ~16 ~38 ~87 ~16 ~38 lava 0  
fill ~83 ~16 ~49 ~83 ~18 ~49 cobblestone 0  
fill ~83 ~16 ~51 ~84 ~16 ~51 cobblestone 0 
setblock ~84 ~16 ~37 bedrock 0  
fill ~84 ~16 ~48 ~86 ~16 ~48 cobblestone 0 
setblock ~84 ~16 ~49 nether_brick 0 
setblock ~85 ~16 ~34 stained_hardened_clay 9 
