fill ~45~31~1 ~48~31~2 minecraft:stone 0
fill ~47~32~1 ~48~32~5 minecraft:stone 0
fill ~36~38~2 ~39~38~3 minecraft:leaves 2
fill ~37~37~2 ~39~37~3 minecraft:leaves 2
fill ~44~30~2 ~44~30~4 minecraft:stone 0
fill ~44~31~2 ~44~31~3 minecraft:stone 0
fill ~45~32~2 ~46~32~5 minecraft:stone 0
fill ~49~31~2 ~52~31~2 minecraft:stone 0
fill ~49~32~2 ~49~32~6 minecraft:stone 0
fill ~55~37~2 ~58~38~3 minecraft:leaves 2
fill ~35~31~3 ~37~32~3 minecraft:stone 0
fill ~36~37~3 ~36~37~6 minecraft:leaves 2
fill ~37~30~3 ~38~30~4 minecraft:stone 0
setblock ~38~35~3 minecraft:torch 4
fill ~38~39~3 ~38~40~3 minecraft:leaves 2
fill ~40~37~3 ~40~38~5 minecraft:leaves 2
fill ~41~29~3 ~41~29~4 minecraft:stone 0
fill ~41~30~3 ~43~30~3 minecraft:stone 0
fill ~42~31~3 ~43~31~3 minecraft:stone 0
setblock ~42~56~3 minecraft:stone_stairs 5
fill ~42~57~3 ~42~58~3 minecraft:stonebrick 0
setblock ~42~59~3 minecraft:stone_brick_stairs 0
setblock ~43~45~3 minecraft:torch 4
setblock ~43~57~3 minecraft:stone_stairs 5
fill ~43~58~3 ~44~59~3 minecraft:stonebrick 0
setblock ~43~60~3 minecraft:stone_block_slab 0
setblock ~44~57~3 minecraft:stone_block_slab 11
setblock ~44~60~3 minecraft:stone_brick_stairs 0
fill ~45~30~3 ~52~30~3 minecraft:stone 0
setblock ~45~39~3 minecraft:torch 4
setblock ~45~51~3 minecraft:torch 4
setblock ~45~58~3 minecraft:stone_stairs 5
fill ~45~59~3 ~46~60~3 minecraft:stonebrick 0
setblock ~45~61~3 minecraft:stone_block_slab 0
setblock ~46~58~3 minecraft:stone_block_slab 11
setblock ~46~61~3 minecraft:stone_brick_stairs 0
setblock ~47~59~3 minecraft:stone_stairs 5
fill ~47~60~3 ~48~61~3 minecraft:stonebrick 0
fill ~47~62~3 ~50~62~3 minecraft:stone_block_slab 0
setblock ~48~48~3 minecraft:torch 4
setblock ~48~56~3 minecraft:torch 4
setblock ~48~59~3 minecraft:stone_block_slab 11
setblock ~49~60~3 minecraft:stone_stairs 5
fill ~49~61~3 ~50~61~3 minecraft:stonebrick 0
fill ~50~32~3 ~51~32~4 minecraft:stone 0
fill ~50~60~3 ~50~60~4 minecraft:stone_block_slab 11
fill ~52~31~3 ~52~31~4 minecraft:stone 0
fill ~54~37~3 ~54~38~5 minecraft:leaves 2
fill ~55~33~3 ~58~33~3 minecraft:stone 0
fill ~55~39~3 ~57~39~3 minecraft:leaves 2
setblock ~56~35~3 minecraft:torch 4
fill ~56~40~3 ~56~40~5 minecraft:leaves 2
fill ~32~31~4 ~34~32~4 minecraft:stone 0
fill ~34~30~4 ~36~30~5 minecraft:stone 0
fill ~35~32~4 ~39~32~5 minecraft:stone 0
fill ~36~38~4 ~37~38~5 minecraft:leaves 2
setblock ~37~35~4 minecraft:torch 2
fill ~37~37~4 ~37~37~6 minecraft:leaves 2
fill ~37~39~4 ~37~40~4 minecraft:leaves 2
setblock ~37~53~4 minecraft:stone_stairs 5
fill ~37~54~4 ~37~55~4 minecraft:stonebrick 0
setblock ~37~56~4 minecraft:stone_brick_stairs 0
fill ~38~29~4 ~40~29~4 minecraft:stone 0
fill ~38~31~4 ~41~31~4 minecraft:stone 0
fill ~38~33~4 ~38~39~4 minecraft:log 2
fill ~38~40~4 ~39~40~4 minecraft:leaves 2
setblock ~38~54~4 minecraft:stone_stairs 5
fill ~38~55~4 ~39~56~4 minecraft:stonebrick 0
setblock ~38~57~4 minecraft:stone_block_slab 0
fill ~39~30~4 ~40~30~4 minecraft:stone 0
setblock ~39~35~4 minecraft:torch 1
fill ~39~37~4 ~39~38~6 minecraft:leaves 2
fill ~39~39~4 ~39~39~5 minecraft:leaves 2
setblock ~39~54~4 minecraft:stone_block_slab 11
setblock ~39~57~4 minecraft:stone_brick_stairs 0
setblock ~40~55~4 minecraft:stone_stairs 5
fill ~40~56~4 ~49~56~4 minecraft:stonebrick 0
fill ~40~57~4 ~41~57~4 minecraft:stonebrick 0
setblock ~40~58~4 minecraft:stone_block_slab 0
setblock ~41~55~4 minecraft:stone_block_slab 11
setblock ~41~58~4 minecraft:stone_brick_stairs 0
fill ~42~29~4 ~42~29~5 minecraft:stone 0
fill ~42~32~4 ~44~55~4 minecraft:stonebrick 0
setblock ~42~57~4 minecraft:double_wooden_slab 0
fill ~43~30~4 ~43~31~4 minecraft:stone 0
fill ~43~57~4 ~49~57~4 minecraft:stonebrick 0
setblock ~43~58~4 minecraft:wooden_slab 0
setblock ~43~59~4 minecraft:torch 3
setblock ~44~58~4 minecraft:wooden_slab 8
fill ~45~29~4 ~46~29~5 minecraft:stone 0
setblock ~45~38~4 minecraft:stone_block_slab 8
fill ~45~39~4 ~45~55~4 minecraft:stonebrick 0
fill ~45~58~4 ~49~58~4 minecraft:stonebrick 0
fill ~45~59~4 ~45~59~8 minecraft:oak_stairs 0
setblock ~45~60~4 minecraft:torch 3
setblock ~46~42~4 minecraft:stone_block_slab 8
fill ~46~43~4 ~46~55~4 minecraft:stonebrick 0
fill ~46~60~4 ~46~60~8 minecraft:oak_stairs 0
fill ~47~30~4 ~48~30~4 minecraft:stone 0
setblock ~47~45~4 minecraft:stone_block_slab 8
fill ~47~46~4 ~47~55~4 minecraft:stonebrick 0
fill ~47~59~4 ~49~59~4 minecraft:stonebrick 0
fill ~47~61~4 ~49~61~9 minecraft:wooden_slab 0
setblock ~48~47~4 minecraft:stone_block_slab 8
fill ~48~48~4 ~48~55~4 minecraft:stonebrick 0
fill ~49~29~4 ~51~29~5 minecraft:stone 0
setblock ~49~49~4 minecraft:stone_block_slab 8
fill ~49~50~4 ~49~55~4 minecraft:stonebrick 0
setblock ~49~60~4 minecraft:stonebrick 0
setblock ~50~30~4 minecraft:torch 5
fill ~50~61~4 ~52~61~4 minecraft:stonebrick 0
fill ~50~62~4 ~52~62~4 minecraft:stone_block_slab 0
fill ~51~60~4 ~52~60~4 minecraft:stone_block_slab 11
setblock ~52~30~4 minecraft:stone 0
fill ~52~32~4 ~58~32~4 minecraft:stone 0
fill ~52~33~4 ~52~33~5 minecraft:double_stone_block_slab 0
setblock ~52~34~4 minecraft:cobblestone_wall 0
setblock ~53~33~4 minecraft:stonebrick 0
setblock ~54~33~4 minecraft:stone 0
fill ~55~31~4 ~55~31~5 minecraft:stone 0
setblock ~55~33~4 minecraft:stonebrick 0
setblock ~55~35~4 minecraft:torch 2
fill ~55~37~4 ~55~38~6 minecraft:leaves 2
fill ~55~39~4 ~55~40~4 minecraft:leaves 2
fill ~56~33~4 ~56~33~7 minecraft:stone 0
fill ~56~34~4 ~56~39~4 minecraft:log 2
setblock ~57~33~4 minecraft:stonebrick 2
setblock ~57~35~4 minecraft:torch 1
fill ~57~37~4 ~58~38~5 minecraft:leaves 2
fill ~57~39~4 ~57~40~4 minecraft:leaves 2
setblock ~58~33~4 minecraft:stonebrick 0
setblock ~59~33~4 minecraft:stone 0
fill ~29~31~5 ~32~31~5 minecraft:stone 0
fill ~31~32~5 ~34~32~5 minecraft:stone 0
fill ~33~30~5 ~33~30~6 minecraft:stone 0
setblock ~33~31~5 minecraft:torch 5
setblock ~33~51~5 minecraft:stone_stairs 5
fill ~33~52~5 ~34~53~5 minecraft:stonebrick 0
setblock ~33~54~5 minecraft:stone_block_slab 0
setblock ~34~51~5 minecraft:stone_block_slab 11
setblock ~34~54~5 minecraft:stone_brick_stairs 0
setblock ~35~52~5 minecraft:stone_stairs 5
fill ~35~53~5 ~41~53~5 minecraft:stonebrick 0
fill ~35~54~5 ~36~54~5 minecraft:stonebrick 0
setblock ~35~55~5 minecraft:stone_block_slab 0
setblock ~36~52~5 minecraft:stone_block_slab 11
setblock ~36~55~5 minecraft:stone_brick_stairs 0
fill ~37~29~5 ~39~29~5 minecraft:stone 0
setblock ~37~51~5 minecraft:stone_block_slab 8
fill ~37~52~5 ~37~52~7 minecraft:stonebrick 0
setblock ~37~54~5 minecraft:oak_stairs 0
setblock ~38~35~5 minecraft:torch 3
fill ~38~37~5 ~38~38~6 minecraft:leaves 2
fill ~38~39~5 ~38~40~5 minecraft:leaves 2
fill ~38~52~5 ~39~52~5 minecraft:stone_block_slab 8
fill ~38~54~5 ~41~54~5 minecraft:stonebrick 0
setblock ~38~55~5 minecraft:wooden_slab 0
setblock ~38~56~5 minecraft:torch 3
setblock ~39~55~5 minecraft:double_wooden_slab 0
fill ~40~28~5 ~41~28~6 minecraft:stone 0
fill ~40~32~5 ~40~32~6 minecraft:stone 0
setblock ~40~51~5 minecraft:stone_block_slab 8
fill ~40~52~5 ~41~52~5 minecraft:stonebrick 0
fill ~40~55~5 ~41~55~5 minecraft:stonebrick 0
setblock ~40~56~5 minecraft:wooden_slab 0
setblock ~40~57~5 minecraft:torch 3
fill ~41~32~5 ~41~51~5 minecraft:stonebrick 0
setblock ~41~56~5 minecraft:wooden_slab 8
setblock ~42~32~5 minecraft:stone 0
setblock ~42~57~5 minecraft:wooden_slab 0
fill ~43~29~5 ~44~29~5 minecraft:stone 0
setblock ~43~34~5 minecraft:ladder 3
setblock ~43~57~5 minecraft:wooden_slab 8
fill ~44~33~5 ~44~42~5 minecraft:stonebrick 0
fill ~44~58~5 ~44~58~8 minecraft:oak_stairs 0
fill ~45~43~5 ~45~45~5 minecraft:stonebrick 0
fill ~46~46~5 ~46~48~5 minecraft:stonebrick 0
fill ~47~29~5 ~48~29~5 minecraft:stone 0
fill ~47~48~5 ~47~50~5 minecraft:stonebrick 0
fill ~48~50~5 ~48~52~5 minecraft:stonebrick 0
setblock ~49~50~5 minecraft:stone_block_slab 8
fill ~49~51~5 ~49~52~5 minecraft:stonebrick 0
fill ~50~33~5 ~51~33~7 minecraft:stone 0
setblock ~50~51~5 minecraft:stone_block_slab 8
fill ~50~52~5 ~50~60~5 minecraft:stonebrick 0
fill ~50~61~5 ~51~61~9 minecraft:wooden_slab 0
setblock ~51~52~5 minecraft:stone_block_slab 8
fill ~51~53~5 ~51~60~5 minecraft:stonebrick 0
fill ~52~29~5 ~52~29~8 minecraft:stone 0
fill ~52~34~5 ~52~34~6 minecraft:cobblestone_wall 0
setblock ~52~53~5 minecraft:torch 1
setblock ~52~59~5 minecraft:torch 1
fill ~52~60~5 ~53~60~5 minecraft:stone_block_slab 11
fill ~52~61~5 ~53~61~5 minecraft:stonebrick 0
fill ~52~62~5 ~53~62~5 minecraft:stone_block_slab 0
fill ~53~30~5 ~55~30~5 minecraft:stone 0
fill ~53~31~5 ~54~31~5 minecraft:stone 0
setblock ~53~33~5 minecraft:stonebrick 2
setblock ~54~33~5 minecraft:stone_brick_stairs 1
setblock ~55~33~5 minecraft:stone 0
fill ~56~31~5 ~57~31~5 minecraft:stone 0
setblock ~56~32~5 minecraft:torch 5
fill ~56~34~5 ~56~34~6 minecraft:oak_stairs 1
setblock ~56~35~5 minecraft:torch 3
fill ~56~37~5 ~56~38~6 minecraft:leaves 2
setblock ~56~39~5 minecraft:leaves 2
setblock ~57~33~5 minecraft:stone 0
fill ~58~32~5 ~59~32~5 minecraft:stone 0
setblock ~58~33~5 minecraft:double_stone_block_slab 0
setblock ~59~33~5 minecraft:stonebrick 0
fill ~28~31~6 ~30~31~6 minecraft:stone 0
fill ~30~32~6 ~32~32~6 minecraft:stone 0
fill ~31~30~6 ~32~30~6 minecraft:stone 0
setblock ~31~49~6 minecraft:stone_block_slab 11
fill ~31~50~6 ~31~51~6 minecraft:stonebrick 0
setblock ~31~52~6 minecraft:stone_brick_stairs 0
setblock ~32~50~6 minecraft:stone_stairs 5
fill ~32~51~6 ~36~51~6 minecraft:stonebrick 0
setblock ~32~52~6 minecraft:stonebrick 0
setblock ~32~53~6 minecraft:stone_brick_stairs 0
fill ~33~33~6 ~35~50~6 minecraft:stonebrick 0
setblock ~33~52~6 minecraft:wooden_slab 0
setblock ~33~53~6 minecraft:torch 3
fill ~34~29~6 ~38~29~6 minecraft:stone 0
setblock ~34~52~6 minecraft:double_wooden_slab 0
fill ~35~52~6 ~36~52~6 minecraft:stonebrick 0
setblock ~35~53~6 minecraft:wooden_slab 0
setblock ~35~54~6 minecraft:torch 3
fill ~36~32~6 ~39~32~6 minecraft:stone 0
setblock ~36~49~6 minecraft:stone_brick_stairs 5
fill ~36~50~6 ~36~50~10 minecraft:stonebrick 0
setblock ~36~53~6 minecraft:wooden_slab 8
setblock ~37~38~6 minecraft:leaves 2
fill ~37~54~6 ~38~54~6 minecraft:oak_stairs 3
fill ~38~53~6 ~39~53~6 minecraft:stonebrick 0
fill ~39~28~6 ~39~28~7 minecraft:stone 0
fill ~39~55~6 ~39~55~9 minecraft:wooden_slab 0
setblock ~40~37~6 minecraft:torch 2
setblock ~40~44~6 minecraft:torch 2
setblock ~40~50~6 minecraft:torch 2
fill ~40~52~6 ~40~52~7 minecraft:stonebrick 0
fill ~40~55~6 ~40~55~9 minecraft:wooden_slab 8
fill ~41~33~6 ~41~51~6 minecraft:stonebrick 0
fill ~41~56~6 ~41~56~9 minecraft:wooden_slab 0
fill ~42~28~6 ~50~28~6 minecraft:stone 0
setblock ~42~36~6 minecraft:torch 1
setblock ~42~43~6 minecraft:torch 1
fill ~42~56~6 ~42~56~8 minecraft:wooden_slab 8
setblock ~43~29~6 minecraft:torch 5
fill ~43~33~6 ~43~42~6 minecraft:stonebrick 0
fill ~43~57~6 ~43~57~8 minecraft:oak_stairs 0
fill ~44~33~6 ~48~33~6 minecraft:stone 0
fill ~44~41~6 ~44~46~6 minecraft:stonebrick 0
fill ~45~45~6 ~45~50~6 minecraft:stonebrick 0
fill ~46~49~6 ~46~51~6 minecraft:stonebrick 0
fill ~47~51~6 ~47~52~6 minecraft:stonebrick 0
fill ~48~53~6 ~50~53~6 minecraft:stonebrick 0
fill ~49~54~6 ~51~54~6 minecraft:stonebrick 0
fill ~50~55~6 ~52~55~6 minecraft:stonebrick 0
setblock ~51~29~6 minecraft:stone 0
setblock ~51~53~6 minecraft:stone_block_slab 8
fill ~52~33~6 ~53~33~6 minecraft:stone 0
setblock ~52~54~6 minecraft:stone_block_slab 8
fill ~52~56~6 ~52~56~7 minecraft:stonebrick 0
fill ~52~57~6 ~52~60~6 minecraft:stonebrick 0
fill ~52~61~6 ~52~61~9 minecraft:wooden_slab 0
fill ~53~29~6 ~53~29~9 minecraft:stone 0
setblock ~53~60~6 minecraft:stone_block_slab 11
fill ~53~61~6 ~53~61~7 minecraft:stonebrick 0
fill ~53~62~6 ~53~62~7 minecraft:stone_block_slab 0
fill ~54~30~6 ~57~30~6 minecraft:stone 0
setblock ~54~33~6 minecraft:double_stone_block_slab 0
setblock ~54~38~6 minecraft:leaves 2
setblock ~55~33~6 minecraft:stonebrick 2
fill ~56~29~6 ~56~29~7 minecraft:stone 0
fill ~57~31~6 ~57~31~7 minecraft:stone 0
setblock ~57~33~6 minecraft:stonebrick 0
fill ~57~37~6 ~57~38~6 minecraft:leaves 2
fill ~58~32~6 ~58~32~8 minecraft:stone 0
setblock ~58~33~6 minecraft:stonebrick 2
setblock ~59~33~6 minecraft:stone 0
fill ~27~31~7 ~29~31~7 minecraft:stone 0
fill ~27~32~7 ~27~32~10 minecraft:stone 0
setblock ~28~48~7 minecraft:stone_stairs 5
fill ~28~49~7 ~29~50~7 minecraft:stonebrick 0
setblock ~28~51~7 minecraft:stone_block_slab 0
setblock ~29~48~7 minecraft:stone_block_slab 11
setblock ~29~51~7 minecraft:stone_brick_stairs 0
fill ~30~30~7 ~31~30~7 minecraft:stone 0
fill ~30~32~7 ~30~32~10 minecraft:stone 0
setblock ~30~49~7 minecraft:stone_stairs 5
fill ~30~50~7 ~30~51~7 minecraft:stonebrick 0
setblock ~30~52~7 minecraft:stone_block_slab 0
fill ~31~33~7 ~32~33~8 minecraft:stone 0
setblock ~31~46~7 minecraft:stone_block_slab 8
fill ~31~47~7 ~32~49~7 minecraft:stonebrick 0
setblock ~31~50~7 minecraft:wooden_slab 8
fill ~32~29~7 ~34~29~7 minecraft:stone 0
setblock ~32~37~7 minecraft:torch 2
setblock ~32~43~7 minecraft:torch 2
setblock ~32~44~7 minecraft:stone_brick_stairs 4
fill ~32~45~7 ~32~46~7 minecraft:stonebrick 0
setblock ~32~50~7 minecraft:stonebrick 0
setblock ~32~51~7 minecraft:wooden_slab 0
fill ~33~34~7 ~33~43~8 minecraft:stonebrick 0
setblock ~33~51~7 minecraft:wooden_slab 8
setblock ~34~52~7 minecraft:wooden_slab 0
fill ~35~28~7 ~38~28~7 minecraft:stone 0
fill ~35~33~7 ~35~49~7 minecraft:stonebrick 0
setblock ~35~52~7 minecraft:wooden_slab 8
fill ~36~33~7 ~40~33~7 minecraft:stone 0
setblock ~36~36~7 minecraft:torch 1
setblock ~36~43~7 minecraft:torch 1
setblock ~36~48~7 minecraft:torch 1
setblock ~36~51~7 minecraft:stonebrick 0
fill ~36~53~7 ~36~53~10 minecraft:wooden_slab 0
fill ~37~53~7 ~37~53~9 minecraft:wooden_slab 8
fill ~38~52~7 ~39~52~7 minecraft:stonebrick 0
fill ~38~54~7 ~38~54~9 minecraft:oak_stairs 0
fill ~39~60~7 ~39~61~9 minecraft:leaves 0
fill ~40~27~7 ~41~27~7 minecraft:stone 0
fill ~40~61~7 ~40~61~9 minecraft:leaves 0
fill ~40~62~7 ~42~62~8 minecraft:leaves 0
setblock ~40~63~7 minecraft:torch 4
fill ~41~34~7 ~42~42~7 minecraft:stonebrick 0
fill ~41~43~7 ~41~51~7 minecraft:stonebrick 0
fill ~42~28~7 ~45~28~7 minecraft:stone 0
setblock ~42~50~7 minecraft:torch 4
fill ~43~33~7 ~44~33~7 minecraft:stone 0
fill ~43~43~7 ~43~46~8 minecraft:stonebrick 0
fill ~44~47~7 ~44~50~7 minecraft:stonebrick 0
fill ~45~34~7 ~46~34~8 minecraft:stone 0
setblock ~45~51~7 minecraft:stonebrick 0
fill ~46~27~7 ~48~27~7 minecraft:stone 0
fill ~46~52~7 ~46~53~7 minecraft:stonebrick 0
fill ~47~26~7 ~47~26~9 minecraft:stone 0
fill ~47~33~7 ~49~33~7 minecraft:stone 0
fill ~47~53~7 ~47~55~7 minecraft:stonebrick 0
setblock ~47~56~7 minecraft:torch 4
fill ~48~54~7 ~48~55~7 minecraft:stonebrick 0
fill ~49~28~7 ~51~28~7 minecraft:stone 0
setblock ~49~55~7 minecraft:stonebrick 0
fill ~50~56~7 ~51~56~7 minecraft:stonebrick 0
fill ~52~34~7 ~52~34~8 minecraft:double_stone_block_slab 0
setblock ~52~35~7 minecraft:cobblestone_wall 0
setblock ~52~36~7 minecraft:torch 5
setblock ~52~55~7 minecraft:stone_block_slab 8
fill ~53~34~7 ~53~34~8 minecraft:stone 0
fill ~53~56~7 ~53~56~8 minecraft:stone_block_slab 8
fill ~53~57~7 ~53~60~8 minecraft:stonebrick 0
fill ~54~30~7 ~55~30~7 minecraft:stone 0
setblock ~54~33~7 minecraft:stone 0
setblock ~54~57~7 minecraft:torch 1
fill ~54~60~7 ~54~60~13 minecraft:stone_block_slab 11
fill ~54~61~7 ~54~61~11 minecraft:stonebrick 0
fill ~54~62~7 ~54~62~10 minecraft:stone_block_slab 0
setblock ~55~33~7 minecraft:stonebrick 0
setblock ~56~34~7 minecraft:oak_stairs 2
fill ~57~30~7 ~57~30~11 minecraft:stone 0
setblock ~57~33~7 minecraft:stonebrick 2
setblock ~58~33~7 minecraft:stone 0
fill ~25~31~8 ~26~32~8 minecraft:stone 0
fill ~27~30~8 ~30~30~8 minecraft:stone 0
setblock ~27~47~8 minecraft:stone_stairs 5
fill ~27~48~8 ~30~48~8 minecraft:stonebrick 0
setblock ~27~49~8 minecraft:stonebrick 0
setblock ~27~50~8 minecraft:stone_brick_stairs 0
fill ~28~32~8 ~29~32~11 minecraft:stone 0
setblock ~28~46~8 minecraft:stone_block_slab 8
fill ~28~47~8 ~28~47~9 minecraft:stonebrick 0
setblock ~28~49~8 minecraft:wooden_slab 0
setblock ~28~50~8 minecraft:torch 3
fill ~29~47~8 ~30~47~8 minecraft:stone_block_slab 8
setblock ~29~49~8 minecraft:oak_stairs 0
setblock ~30~49~8 minecraft:stonebrick 0
fill ~30~50~8 ~31~50~8 minecraft:wooden_slab 0
setblock ~30~51~8 minecraft:torch 3
fill ~31~29~8 ~33~29~9 minecraft:stone 0
fill ~31~47~8 ~31~47~11 minecraft:stonebrick 0
fill ~32~46~8 ~32~46~11 minecraft:stonebrick 0
setblock ~32~50~8 minecraft:oak_stairs 3
fill ~33~44~8 ~33~45~11 minecraft:stonebrick 0
fill ~33~51~8 ~33~51~11 minecraft:wooden_slab 0
fill ~34~28~8 ~36~28~8 minecraft:stone 0
fill ~34~51~8 ~34~51~10 minecraft:wooden_slab 8
fill ~35~35~8 ~35~49~10 minecraft:stonebrick 0
fill ~35~52~8 ~35~52~10 minecraft:oak_stairs 0
fill ~36~34~8 ~37~34~11 minecraft:stone 0
fill ~36~59~8 ~40~59~8 minecraft:leaves 0
fill ~37~27~8 ~40~27~8 minecraft:stone 0
fill ~37~51~8 ~40~51~9 minecraft:stonebrick 0
fill ~37~60~8 ~38~60~10 minecraft:leaves 0
fill ~37~64~8 ~39~64~9 minecraft:stone 0
fill ~38~33~8 ~39~33~8 minecraft:stone 0
fill ~38~61~8 ~38~61~9 minecraft:leaves 0
fill ~38~63~8 ~40~63~8 minecraft:stone 0
setblock ~39~28~8 minecraft:torch 5
setblock ~39~37~8 minecraft:torch 2
setblock ~39~44~8 minecraft:torch 2
setblock ~39~50~8 minecraft:torch 2
setblock ~39~62~8 minecraft:leaves 0
fill ~40~34~8 ~40~50~8 minecraft:stonebrick 0
fill ~40~60~8 ~40~60~9 minecraft:leaves 0
fill ~41~26~8 ~41~26~9 minecraft:stone 0
fill ~41~36~8 ~42~37~8 minecraft:stonebrick 0
fill ~41~61~8 ~43~61~9 minecraft:leaves 0
setblock ~41~63~8 minecraft:leaves 0
fill ~42~27~8 ~45~27~8 minecraft:stone 0
setblock ~42~35~8 minecraft:stonebrick 0
fill ~42~38~8 ~42~55~8 minecraft:stonebrick 0
fill ~43~34~8 ~44~34~9 minecraft:stone 0
setblock ~43~42~8 minecraft:stone_block_slab 8
fill ~43~47~8 ~43~56~8 minecraft:stonebrick 0
setblock ~43~58~8 minecraft:torch 4
fill ~43~62~8 ~43~62~10 minecraft:leaves 0
setblock ~44~47~8 minecraft:stone_block_slab 8
fill ~44~48~8 ~44~56~8 minecraft:stonebrick 0
fill ~45~25~8 ~46~25~9 minecraft:stone 0
fill ~45~26~8 ~46~26~8 minecraft:stone 0
setblock ~45~51~8 minecraft:stone_block_slab 8
fill ~45~52~8 ~45~57~8 minecraft:stonebrick 0
setblock ~46~53~8 minecraft:stone_block_slab 8
fill ~46~54~8 ~46~58~8 minecraft:stonebrick 0
setblock ~46~61~8 minecraft:torch 4
fill ~47~34~8 ~50~34~8 minecraft:stone 0
setblock ~47~55~8 minecraft:stone_block_slab 8
fill ~47~56~8 ~50~56~8 minecraft:stonebrick 0
fill ~48~27~8 ~51~27~8 minecraft:stone 0
setblock ~51~28~8 minecraft:stone 0
setblock ~51~29~8 minecraft:torch 5
setblock ~51~33~8 minecraft:stone 0
fill ~51~57~8 ~52~57~8 minecraft:stonebrick 0
setblock ~52~35~8 minecraft:cobblestone_wall 0
fill ~53~61~8 ~53~61~10 minecraft:wooden_slab 0
fill ~54~29~8 ~55~29~10 minecraft:stone 0
fill ~54~34~8 ~54~34~9 minecraft:stone 0
setblock ~55~30~8 minecraft:torch 5
setblock ~55~33~8 minecraft:stone 0
fill ~56~30~8 ~56~30~9 minecraft:stone 0
setblock ~56~33~8 minecraft:stonebrick 2
setblock ~57~29~8 minecraft:stone 0
setblock ~57~33~8 minecraft:stone 0
fill ~58~31~8 ~58~31~10 minecraft:stone 0
fill ~24~31~9 ~25~31~9 minecraft:stone 0
fill ~25~32~9 ~26~32~9 minecraft:stone 0
fill ~25~46~9 ~26~46~9 minecraft:stone_block_slab 11
fill ~25~47~9 ~27~47~9 minecraft:stonebrick 0
fill ~25~48~9 ~26~48~9 minecraft:stonebrick 0
setblock ~25~49~9 minecraft:stone_block_slab 0
fill ~26~30~9 ~28~30~9 minecraft:stone 0
setblock ~26~31~9 minecraft:torch 5
setblock ~26~49~9 minecraft:stone_brick_stairs 0
setblock ~27~44~9 minecraft:stone_brick_stairs 6
fill ~27~45~9 ~27~45~11 minecraft:stonebrick 0
setblock ~27~46~9 minecraft:stonebrick 0
setblock ~27~48~9 minecraft:wooden_slab 0
setblock ~28~48~9 minecraft:wooden_slab 8
fill ~29~29~9 ~30~29~9 minecraft:stone 0
setblock ~29~47~9 minecraft:stone_block_slab 13
setblock ~29~49~9 minecraft:wooden_slab 0
fill ~30~48~9 ~30~48~10 minecraft:stonebrick 0
fill ~30~49~9 ~31~49~9 minecraft:wooden_slab 8
fill ~31~33~9 ~31~33~11 minecraft:stone 0
fill ~32~34~9 ~32~34~13 minecraft:stone 0
fill ~32~50~9 ~32~50~11 minecraft:oak_stairs 0
fill ~33~35~9 ~33~43~11 minecraft:stonebrick 0
fill ~34~28~9 ~35~28~9 minecraft:stone 0
setblock ~35~50~9 minecraft:wooden_slab 0
fill ~35~58~9 ~37~59~9 minecraft:leaves 0
fill ~36~27~9 ~39~27~9 minecraft:stone 0
setblock ~36~36~9 minecraft:torch 1
setblock ~36~43~9 minecraft:torch 1
setblock ~36~48~9 minecraft:torch 1
fill ~36~57~9 ~36~57~12 minecraft:leaves 0
fill ~36~60~9 ~36~60~10 minecraft:leaves 0
fill ~36~63~9 ~37~63~9 minecraft:stone 0
fill ~36~64~9 ~36~64~10 minecraft:stone 0
fill ~37~50~9 ~38~50~9 minecraft:stone_block_slab 8
fill ~37~52~9 ~41~52~9 minecraft:stonebrick 0
setblock ~37~54~9 minecraft:torch 4
fill ~37~61~9 ~37~61~10 minecraft:stone 0
fill ~37~62~9 ~41~62~9 minecraft:stone 0
fill ~38~34~9 ~39~34~10 minecraft:stone 0
setblock ~39~49~9 minecraft:stone_block_slab 8
fill ~39~50~9 ~41~50~9 minecraft:stonebrick 0
fill ~39~53~9 ~41~53~9 minecraft:stonebrick 0
fill ~39~59~9 ~40~59~10 minecraft:leaves 0
fill ~40~26~9 ~40~26~10 minecraft:stone 0
fill ~40~35~9 ~41~49~9 minecraft:stonebrick 0
fill ~40~54~9 ~41~54~9 minecraft:stonebrick 0
setblock ~40~56~9 minecraft:torch 4
setblock ~40~63~9 minecraft:torch 5
fill ~40~64~9 ~41~64~10 minecraft:stone 0
setblock ~41~51~9 minecraft:stonebrick 0
fill ~41~60~9 ~42~60~9 minecraft:leaves 0
setblock ~41~63~9 minecraft:stone 0
fill ~42~26~9 ~44~26~9 minecraft:stone 0
setblock ~42~34~9 minecraft:stone 0
setblock ~42~55~9 minecraft:stone_stairs 5
fill ~42~56~9 ~42~57~9 minecraft:stonebrick 0
setblock ~42~58~9 minecraft:stone_brick_stairs 0
setblock ~42~62~9 minecraft:leaves 0
setblock ~43~56~9 minecraft:stone_stairs 5
fill ~43~57~9 ~44~58~9 minecraft:stonebrick 0
setblock ~43~59~9 minecraft:stone_block_slab 0
fill ~43~63~9 ~43~63~10 minecraft:leaves 0
setblock ~44~56~9 minecraft:stone_block_slab 11
fill ~44~59~9 ~46~59~9 minecraft:stonebrick 0
setblock ~44~60~9 minecraft:stone_brick_stairs 0
fill ~44~61~9 ~44~62~10 minecraft:leaves 0
fill ~45~24~9 ~45~24~11 minecraft:stone 0
fill ~45~35~9 ~47~35~9 minecraft:stone 0
setblock ~45~57~9 minecraft:stone_stairs 5
setblock ~45~58~9 minecraft:stonebrick 0
fill ~45~60~9 ~46~60~9 minecraft:stonebrick 0
setblock ~45~61~9 minecraft:stone_brick_stairs 0
setblock ~46~58~9 minecraft:stone_stairs 5
fill ~46~61~9 ~46~61~11 minecraft:stonebrick 0
fill ~46~62~9 ~46~62~10 minecraft:stone_block_slab 0
setblock ~47~56~9 minecraft:stone_block_slab 8
fill ~47~57~9 ~50~57~9 minecraft:stonebrick 0
fill ~47~58~9 ~47~58~10 minecraft:stonebrick 0
fill ~48~26~9 ~49~26~9 minecraft:stone 0
fill ~48~34~9 ~52~34~9 minecraft:stone 0
fill ~50~27~9 ~51~27~9 minecraft:stone 0
fill ~50~58~9 ~53~58~9 minecraft:stonebrick 0
fill ~51~59~9 ~53~59~9 minecraft:stonebrick 0
fill ~52~28~9 ~52~28~10 minecraft:stone 0
setblock ~53~34~9 minecraft:double_stone_block_slab 0
setblock ~53~35~9 minecraft:cobblestone_wall 0
fill ~53~60~9 ~53~60~13 minecraft:stonebrick 0
setblock ~55~34~9 minecraft:stone 0
setblock ~56~33~9 minecraft:stone 0
setblock ~57~32~9 minecraft:stone 0
setblock ~57~33~9 minecraft:stonebrick 0
setblock ~23~45~10 minecraft:stone_block_slab 11
fill ~23~46~10 ~23~47~10 minecraft:stonebrick 0
setblock ~23~48~10 minecraft:stone_brick_stairs 0
fill ~24~30~10 ~25~30~10 minecraft:stone 0
fill ~24~31~10 ~24~32~10 minecraft:stone 0
setblock ~24~46~10 minecraft:stone_stairs 5
fill ~24~47~10 ~24~48~10 minecraft:stonebrick 0
setblock ~24~49~10 minecraft:stone_block_slab 0
fill ~25~33~10 ~26~46~10 minecraft:stonebrick 0
fill ~25~47~10 ~27~47~10 minecraft:wooden_slab 8
setblock ~25~48~10 minecraft:torch 3
fill ~26~29~10 ~29~29~10 minecraft:stone 0
setblock ~27~37~10 minecraft:torch 1
setblock ~27~43~10 minecraft:torch 1
fill ~27~44~10 ~27~44~11 minecraft:stonebrick 0
fill ~28~46~10 ~28~46~11 minecraft:stonebrick 0
setblock ~28~47~10 minecraft:planks 0
fill ~28~48~10 ~28~48~12 minecraft:wooden_slab 0
fill ~29~47~10 ~29~47~11 minecraft:stonebrick 0
fill ~29~48~10 ~29~48~11 minecraft:wooden_slab 8
fill ~30~28~10 ~34~28~10 minecraft:stone 0
fill ~30~49~10 ~30~49~12 minecraft:wooden_slab 0
fill ~31~49~10 ~31~49~11 minecraft:wooden_slab 8
setblock ~32~37~10 minecraft:torch 2
setblock ~32~43~10 minecraft:torch 2
fill ~34~35~10 ~34~50~10 minecraft:stonebrick 0
setblock ~34~52~10 minecraft:torch 4
fill ~34~57~10 ~34~57~13 minecraft:leaves 0
fill ~34~58~10 ~34~58~12 minecraft:leaves 0
fill ~34~59~10 ~38~59~10 minecraft:leaves 0
fill ~35~27~10 ~36~27~10 minecraft:stone 0
setblock ~35~50~10 minecraft:stonebrick 0
setblock ~35~61~10 minecraft:torch 4
fill ~35~62~10 ~36~62~10 minecraft:stone 0
setblock ~35~63~10 minecraft:stone 0
setblock ~36~49~10 minecraft:stone_block_slab 8
setblock ~36~51~10 minecraft:stonebrick 0
fill ~36~58~10 ~38~58~10 minecraft:leaves 0
setblock ~36~61~10 minecraft:stone 0
fill ~36~65~10 ~39~65~10 minecraft:double_stone_block_slab 0
fill ~36~66~10 ~39~66~10 minecraft:stone_brick_stairs 2
setblock ~36~73~10 minecraft:stone_stairs 6
setblock ~36~74~10 minecraft:cobblestone
fill ~36~75~10 ~39~75~10 minecraft:stone_block_slab 13
setblock ~36~76~10 minecraft:stone_brick_stairs 1
fill ~37~26~10 ~39~26~10 minecraft:stone 0
setblock ~37~52~10 minecraft:stone_stairs 5
fill ~37~53~10 ~38~54~10 minecraft:stonebrick 0
setblock ~37~55~10 minecraft:stone_block_slab 0
fill ~37~57~10 ~37~57~11 minecraft:leaves 0
setblock ~37~67~10 minecraft:torch 4
setblock ~37~74~10 minecraft:stone_stairs 5
setblock ~38~52~10 minecraft:stone_block_slab 11
setblock ~38~55~10 minecraft:stone_brick_stairs 0
fill ~38~61~10 ~39~61~10 minecraft:stone 0
setblock ~38~74~10 minecraft:stone_stairs 4
setblock ~38~76~10 minecraft:stone_brick_stairs 0
setblock ~39~53~10 minecraft:stone_stairs 5
fill ~39~54~10 ~39~55~10 minecraft:stonebrick 0
setblock ~39~56~10 minecraft:stone_brick_stairs 0
setblock ~39~60~10 minecraft:log 0
setblock ~39~71~10 minecraft:torch 4
setblock ~39~73~10 minecraft:stone_stairs 6
setblock ~39~74~10 minecraft:cobblestone
setblock ~39~76~10 minecraft:stonebrick 0
fill ~39~77~10 ~39~78~10 minecraft:cobblestone_wall 0
setblock ~40~34~10 minecraft:stone 0
setblock ~40~54~10 minecraft:stone_stairs 5
fill ~40~55~10 ~41~56~10 minecraft:stonebrick 0
setblock ~40~57~10 minecraft:stone_block_slab 0
fill ~40~60~10 ~41~60~10 minecraft:stone 0
fill ~40~61~10 ~41~61~10 minecraft:log 0
fill ~41~25~10 ~41~25~11 minecraft:stone 0
fill ~41~35~10 ~44~35~10 minecraft:stone 0
setblock ~41~54~10 minecraft:stone_block_slab 11
setblock ~41~57~10 minecraft:stone_brick_stairs 0
setblock ~41~62~10 minecraft:planks 0
fill ~42~26~10 ~43~26~10 minecraft:stone 0
setblock ~42~60~10 minecraft:leaves 0
setblock ~42~61~10 minecraft:stone 0
setblock ~42~62~10 minecraft:log 0
setblock ~42~63~10 minecraft:stone 0
fill ~43~36~10 ~47~36~10 minecraft:stone 0
setblock ~43~64~10 minecraft:torch 4
fill ~44~24~10 ~44~24~12 minecraft:stone 0
setblock ~44~25~10 minecraft:stone 0
setblock ~44~45~10 minecraft:torch 4
setblock ~44~60~10 minecraft:leaves 0
setblock ~45~61~10 minecraft:leaves 0
fill ~46~24~10 ~48~24~11 minecraft:stone 0
setblock ~46~59~10 minecraft:stone_stairs 7
setblock ~46~60~10 minecraft:stonebrick 0
fill ~47~25~10 ~49~25~10 minecraft:stone 0
setblock ~47~57~10 minecraft:stone_block_slab 8
setblock ~47~61~10 minecraft:wooden_slab 0
fill ~48~35~10 ~50~35~10 minecraft:stone 0
fill ~48~57~10 ~52~57~11 minecraft:leaves 0
fill ~48~58~10 ~49~58~10 minecraft:stonebrick 0
fill ~48~61~10 ~52~61~10 minecraft:log 0
fill ~49~56~10 ~51~56~10 minecraft:leaves 0
fill ~50~26~10 ~50~26~11 minecraft:stone 0
fill ~50~58~10 ~50~58~12 minecraft:leaves 0
fill ~50~59~10 ~50~59~12 minecraft:stonebrick 0
fill ~51~27~10 ~51~27~11 minecraft:stone 0
fill ~51~34~10 ~53~34~10 minecraft:stone 0
fill ~51~60~10 ~52~60~10 minecraft:stonebrick 0
fill ~53~28~10 ~53~28~11 minecraft:stone 0
setblock ~53~58~10 minecraft:stone_block_slab 8
setblock ~53~59~10 minecraft:stonebrick 0
fill ~54~34~10 ~55~34~10 minecraft:double_stone_block_slab 0
setblock ~54~35~10 minecraft:cobblestone_wall 0
setblock ~55~35~10 minecraft:cobblestone_wall 0
setblock ~55~36~10 minecraft:torch 5
fill ~56~29~10 ~56~29~12 minecraft:stone 0
setblock ~56~33~10 minecraft:stonebrick 0
setblock ~57~33~10 minecraft:double_stone_block_slab 0
fill ~58~30~10 ~58~30~12 minecraft:stone 0
fill ~58~32~10 ~58~32~11 minecraft:stone 0
setblock ~22~45~11 minecraft:stone_stairs 5
fill ~22~46~11 ~22~47~11 minecraft:stonebrick 0
setblock ~22~48~11 minecraft:stone_block_slab 0
fill ~23~30~11 ~23~32~11 minecraft:stone 0
setblock ~23~39~11 minecraft:stone_brick_stairs 4
fill ~23~40~11 ~24~45~11 minecraft:stonebrick 0
setblock ~23~46~11 minecraft:wooden_slab 8
fill ~24~29~11 ~26~29~11 minecraft:stone 0
fill ~24~33~11 ~24~39~11 minecraft:stonebrick 0
setblock ~24~46~11 minecraft:stonebrick 0
fill ~24~47~11 ~26~47~11 minecraft:wooden_slab 0
setblock ~24~48~11 minecraft:torch 3
fill ~27~28~11 ~29~28~11 minecraft:stone 0
fill ~27~33~11 ~27~43~11 minecraft:stonebrick 0
fill ~27~47~11 ~27~47~12 minecraft:wooden_slab 8
setblock ~28~47~11 minecraft:stonebrick 0
fill ~29~27~11 ~35~27~11 minecraft:stone 0
fill ~29~96~11 ~33~96~11 minecraft:log 0
fill ~30~33~11 ~30~33~12 minecraft:stone 0
fill ~30~47~11 ~30~47~12 minecraft:stonebrick 0
setblock ~31~46~11 minecraft:stone_block_slab 8
fill ~31~48~11 ~33~48~11 minecraft:stonebrick 0
setblock ~31~50~11 minecraft:torch 4
setblock ~32~45~11 minecraft:stone_block_slab 8
fill ~32~47~11 ~33~47~11 minecraft:stonebrick 0
setblock ~33~46~11 minecraft:stonebrick 0
setblock ~33~49~11 minecraft:stonebrick 0
fill ~33~56~11 ~35~56~11 minecraft:leaves 0
fill ~33~57~11 ~33~57~14 minecraft:leaves 0
fill ~33~58~11 ~33~58~12 minecraft:leaves 0
fill ~33~63~11 ~34~63~11 minecraft:stone 0
fill ~34~34~11 ~35~34~11 minecraft:stone 0
setblock ~34~50~11 minecraft:stone_stairs 5
fill ~34~51~11 ~35~52~11 minecraft:stonebrick 0
setblock ~34~53~11 minecraft:stone_block_slab 0
fill ~34~61~11 ~35~61~11 minecraft:stone 0
setblock ~34~62~11 minecraft:stone 0
fill ~34~64~11 ~35~65~11 minecraft:double_stone_block_slab 0
fill ~34~66~11 ~35~66~11 minecraft:stone_brick_stairs 2
setblock ~34~67~11 minecraft:torch 4
setblock ~34~74~11 minecraft:stone_stairs 4
fill ~34~75~11 ~35~75~11 minecraft:stone_block_slab 13
setblock ~34~76~11 minecraft:stone_brick_stairs 0
setblock ~35~50~11 minecraft:stone_block_slab 11
setblock ~35~53~11 minecraft:stone_brick_stairs 0
fill ~35~57~11 ~35~57~12 minecraft:leaves 0
fill ~35~58~11 ~37~58~11 minecraft:leaves 0
setblock ~35~59~11 minecraft:leaves 0
fill ~35~73~11 ~35~74~11 minecraft:cobblestone
setblock ~35~76~11 minecraft:stonebrick 0
fill ~35~77~11 ~35~78~11 minecraft:cobblestone_wall 0
fill ~36~26~11 ~37~26~11 minecraft:stone 0
setblock ~36~51~11 minecraft:stone_stairs 5
fill ~36~52~11 ~36~53~11 minecraft:stonebrick 0
setblock ~36~54~11 minecraft:stone_brick_stairs 0
fill ~36~59~11 ~36~60~11 minecraft:stone 0
setblock ~36~61~11 minecraft:torch 5
fill ~36~66~11 ~36~71~11 minecraft:stonebrick 0
setblock ~36~72~11 minecraft:cobblestone
fill ~36~73~11 ~39~73~11 minecraft:stonebrick 0
fill ~36~75~11 ~39~75~11 minecraft:stonebrick 0
fill ~37~59~11 ~38~59~11 minecraft:log 0
fill ~37~60~11 ~38~60~11 minecraft:stone 0
fill ~37~67~11 ~39~71~11 minecraft:stonebrick 0
fill ~37~72~11 ~38~72~11 minecraft:stonebrick 0
fill ~37~74~11 ~38~74~11 minecraft:stonebrick 0
fill ~38~25~11 ~40~25~11 minecraft:stone 0
fill ~38~35~11 ~41~35~11 minecraft:stone 0
setblock ~38~58~11 minecraft:leaves 0
fill ~39~59~11 ~46~59~11 minecraft:stone 0
setblock ~39~60~11 minecraft:torch 5
setblock ~39~66~11 minecraft:stonebrick 0
setblock ~39~72~11 minecraft:cobblestone
setblock ~39~76~11 minecraft:torch 3
setblock ~40~65~11 minecraft:double_stone_block_slab 0
setblock ~40~66~11 minecraft:stone_brick_stairs 2
setblock ~40~73~11 minecraft:stone_stairs 5
setblock ~40~74~11 minecraft:cobblestone
setblock ~40~75~11 minecraft:stone_block_slab 13
setblock ~40~76~11 minecraft:stone_brick_stairs 1
fill ~41~58~11 ~46~58~11 minecraft:stone 0
fill ~41~61~11 ~42~62~11 minecraft:leaves 0
fill ~41~64~11 ~43~64~11 minecraft:stone 0
fill ~42~25~11 ~43~25~12 minecraft:stone 0
fill ~42~36~11 ~43~36~11 minecraft:stone 0
fill ~42~43~11 ~44~43~11 minecraft:leaves 0
fill ~42~46~11 ~46~46~11 minecraft:stone 0
fill ~42~47~11 ~45~47~11 minecraft:stone 0
fill ~42~48~11 ~44~48~11 minecraft:stone 0
fill ~42~49~11 ~43~49~11 minecraft:stone 0
setblock ~42~50~11 minecraft:torch 5
fill ~42~60~11 ~45~60~11 minecraft:stone 0
fill ~43~44~11 ~44~44~11 minecraft:leaves 0
fill ~43~45~11 ~46~45~11 minecraft:stone 0
setblock ~43~50~11 minecraft:stone 0
fill ~43~55~11 ~44~57~11 minecraft:stone 0
fill ~43~61~11 ~45~61~11 minecraft:stone 0
fill ~43~62~11 ~43~63~12 minecraft:stone 0
fill ~44~37~11 ~46~37~11 minecraft:stone 0
setblock ~45~44~11 minecraft:leaves 0
fill ~45~56~11 ~45~57~11 minecraft:stone 0
fill ~46~44~11 ~51~44~11 minecraft:stone 0
setblock ~46~62~11 minecraft:cobblestone_wall 0
fill ~47~36~11 ~51~36~11 minecraft:stone 0
fill ~47~43~11 ~50~43~11 minecraft:stone 0
fill ~47~45~11 ~51~45~11 minecraft:double_stone_block_slab 0
setblock ~47~46~11 minecraft:log 0
setblock ~47~47~11 minecraft:stone_block_slab 0
setblock ~47~58~11 minecraft:stone_block_slab 8
fill ~47~59~11 ~49~59~11 minecraft:stonebrick 0
setblock ~47~61~11 minecraft:log 0
setblock ~48~42~11 minecraft:stone 0
fill ~48~46~11 ~49~46~11 minecraft:cobblestone_wall 0
fill ~48~56~11 ~49~56~11 minecraft:leaves 0
setblock ~48~61~11 minecraft:stonebrick 3
fill ~49~25~11 ~50~25~11 minecraft:stone 0
fill ~49~55~11 ~49~55~12 minecraft:leaves 0
setblock ~49~58~11 minecraft:leaves 0
fill ~49~61~11 ~51~61~18 minecraft:planks 0
setblock ~50~46~11 minecraft:cobblestone_wall 0
fill ~51~35~11 ~52~35~11 minecraft:stone 0
setblock ~51~46~11 minecraft:cobblestone_wall 0
fill ~51~55~11 ~51~56~13 minecraft:leaves 0
setblock ~51~58~11 minecraft:leaves 0
fill ~51~59~11 ~51~59~12 minecraft:stonebrick 0
fill ~52~27~11 ~52~27~13 minecraft:stone 0
fill ~52~56~11 ~52~56~13 minecraft:leaves 0
fill ~52~60~11 ~52~60~12 minecraft:stonebrick 0
setblock ~52~61~11 minecraft:stonebrick 3
fill ~53~34~11 ~56~34~11 minecraft:stone 0
fill ~53~57~11 ~53~57~14 minecraft:leaves 0
fill ~53~59~11 ~53~59~13 minecraft:stone_block_slab 8
setblock ~53~61~11 minecraft:log 0
fill ~54~28~11 ~55~28~12 minecraft:stone 0
setblock ~54~62~11 minecraft:cobblestone_wall 0
fill ~57~33~11 ~57~33~12 minecraft:stone 0
fill ~59~31~11 ~59~32~11 minecraft:stone 0
fill ~19~36~12 ~22~36~13 minecraft:leaves 2
fill ~20~35~12 ~22~35~13 minecraft:leaves 2
fill ~21~30~12 ~22~31~12 minecraft:stone 0
setblock ~21~44~12 minecraft:stone_stairs 5
fill ~21~45~12 ~22~45~12 minecraft:stonebrick 0
setblock ~21~46~12 minecraft:stonebrick 0
setblock ~21~47~12 minecraft:stone_brick_stairs 0
fill ~22~29~12 ~24~29~12 minecraft:stone 0
setblock ~22~41~12 minecraft:stone_block_slab 8
fill ~22~42~12 ~23~42~12 minecraft:stonebrick 0
fill ~22~43~12 ~22~43~15 minecraft:stonebrick 0
setblock ~22~44~12 minecraft:stonebrick 0
fill ~22~46~12 ~23~46~12 minecraft:wooden_slab 0
setblock ~22~47~12 minecraft:torch 3
fill ~23~32~12 ~24~32~14 minecraft:stone 0
setblock ~24~35~12 minecraft:torch 2
setblock ~24~39~12 minecraft:torch 2
setblock ~24~41~12 minecraft:stonebrick 0
fill ~24~46~12 ~25~46~12 minecraft:wooden_slab 8
fill ~25~28~12 ~26~28~12 minecraft:stone 0
fill ~25~33~12 ~25~40~13 minecraft:stonebrick 0
setblock ~26~47~12 minecraft:wooden_slab 0
fill ~27~26~12 ~32~26~12 minecraft:stone 0
fill ~27~27~12 ~28~27~12 minecraft:stone 0
fill ~27~96~12 ~28~96~12 minecraft:log 0
fill ~28~33~12 ~28~45~13 minecraft:stonebrick 0
fill ~28~47~12 ~28~47~13 minecraft:wooden_slab 8
fill ~29~25~12 ~30~25~12 minecraft:stone 0
setblock ~29~32~12 minecraft:stone 0
setblock ~29~37~12 minecraft:torch 1
setblock ~29~43~12 minecraft:torch 1
setblock ~29~45~12 minecraft:stone_block_slab 8
setblock ~29~46~12 minecraft:stonebrick 0
setblock ~29~48~12 minecraft:double_wooden_slab 0
setblock ~29~91~12 minecraft:stone_block_slab 13
fill ~29~92~12 ~29~95~13 minecraft:stonebrick 0
setblock ~29~97~12 minecraft:oak_stairs 0
fill ~30~34~12 ~31~34~13 minecraft:stone 0
setblock ~30~46~12 minecraft:stone_block_slab 8
fill ~30~63~12 ~30~63~13 minecraft:stone 0
fill ~30~64~12 ~30~65~12 minecraft:double_stone_block_slab 0
fill ~30~66~12 ~33~66~12 minecraft:stone_brick_stairs 2
setblock ~30~92~12 minecraft:stone_brick_stairs 2
setblock ~30~94~12 minecraft:torch 2
setblock ~30~95~12 minecraft:stone_brick_stairs 6
setblock ~30~97~12 minecraft:oak_stairs 2
setblock ~31~48~12 minecraft:stone_stairs 5
fill ~31~49~12 ~32~50~12 minecraft:stonebrick 0
setblock ~31~51~12 minecraft:stone_block_slab 0
fill ~31~64~12 ~32~64~12 minecraft:stone 0
fill ~31~65~12 ~33~65~12 minecraft:double_stone_block_slab 0
setblock ~31~67~12 minecraft:torch 4
setblock ~31~74~12 minecraft:torch 4
setblock ~31~87~12 minecraft:torch 4
setblock ~31~91~12 minecraft:stone_block_slab 13
fill ~31~92~12 ~31~95~12 minecraft:stonebrick 0
setblock ~31~97~12 minecraft:log 0
setblock ~31~98~12 minecraft:torch 4
setblock ~32~48~12 minecraft:stone_block_slab 11
setblock ~32~51~12 minecraft:stone_brick_stairs 0
fill ~32~57~12 ~32~57~14 minecraft:leaves 0
setblock ~32~63~12 minecraft:stone 0
setblock ~32~92~12 minecraft:stone_brick_stairs 2
setblock ~32~94~12 minecraft:torch 1
setblock ~32~95~12 minecraft:stone_brick_stairs 6
fill ~32~97~12 ~33~97~12 minecraft:oak_stairs 2
fill ~33~27~12 ~34~27~12 minecraft:stone 0
fill ~33~34~12 ~34~34~12 minecraft:stone 0
setblock ~33~49~12 minecraft:stone_stairs 5
fill ~33~50~12 ~33~51~12 minecraft:stonebrick 0
setblock ~33~52~12 minecraft:stone_brick_stairs 0
fill ~33~55~12 ~33~56~12 minecraft:leaves 0
setblock ~33~62~12 minecraft:stone 0
setblock ~33~64~12 minecraft:double_stone_block_slab 0
setblock ~33~74~12 minecraft:stone_stairs 6
setblock ~33~75~12 minecraft:stone_block_slab 13
setblock ~33~91~12 minecraft:stone_block_slab 13
fill ~33~92~12 ~33~95~13 minecraft:stonebrick 0
fill ~34~56~12 ~34~56~13 minecraft:leaves 0
fill ~34~59~12 ~35~60~12 minecraft:stone 0
setblock ~34~61~12 minecraft:stone 0
fill ~34~66~12 ~34~75~12 minecraft:stonebrick 0
fill ~34~96~12 ~35~96~12 minecraft:log 0
fill ~35~26~12 ~36~26~12 minecraft:stone 0
setblock ~35~27~12 minecraft:torch 5
fill ~35~35~12 ~37~35~12 minecraft:stone 0
setblock ~35~58~12 minecraft:stone 0
fill ~35~67~12 ~35~72~12 minecraft:stonebrick 0
setblock ~35~75~12 minecraft:stonebrick 0
setblock ~35~76~12 minecraft:torch 3
setblock ~36~58~12 minecraft:log 0
fill ~36~75~12 ~39~75~12 minecraft:stone_block_slab 8
fill ~37~25~12 ~38~25~12 minecraft:stone 0
fill ~37~36~12 ~42~36~12 minecraft:stone 0
fill ~37~58~12 ~40~58~12 minecraft:stone 0
setblock ~37~59~12 minecraft:torch 5
fill ~38~44~12 ~38~44~15 minecraft:leaves 0
fill ~38~57~12 ~42~57~12 minecraft:stone 0
fill ~39~24~12 ~41~24~12 minecraft:stone 0
setblock ~39~46~12 minecraft:torch 4
setblock ~40~43~12 minecraft:leaves 0
fill ~40~46~12 ~42~46~12 minecraft:stone 0
fill ~40~47~12 ~41~48~12 minecraft:stone 0
fill ~40~56~12 ~42~56~12 minecraft:stone 0
fill ~40~66~12 ~40~75~12 minecraft:stonebrick 0
fill ~41~42~12 ~43~42~13 minecraft:leaves 0
fill ~41~43~12 ~41~43~14 minecraft:leaves 0
setblock ~41~44~12 minecraft:leaves 0
setblock ~41~49~12 minecraft:stone 0
fill ~41~55~12 ~42~55~12 minecraft:stone 0
setblock ~41~58~12 minecraft:torch 5
setblock ~41~65~12 minecraft:double_stone_block_slab 0
setblock ~41~66~12 minecraft:stone_brick_stairs 2
setblock ~41~67~12 minecraft:torch 4
setblock ~41~74~12 minecraft:stone_stairs 5
setblock ~41~75~12 minecraft:stone_block_slab 13
fill ~42~44~12 ~43~44~12 minecraft:leaves 0
setblock ~42~45~12 minecraft:leaves 0
fill ~42~50~12 ~42~54~12 minecraft:stone 0
fill ~42~61~12 ~43~61~12 minecraft:leaves 0
setblock ~42~62~12 minecraft:leaves 0
fill ~42~64~12 ~43~64~12 minecraft:stone 0
fill ~43~37~12 ~44~37~12 minecraft:stone 0
fill ~43~43~12 ~44~43~12 minecraft:leaves 0
fill ~43~45~12 ~43~45~13 minecraft:stone 0
fill ~43~51~12 ~46~54~12 minecraft:stone 0
setblock ~43~55~12 minecraft:torch 5
fill ~44~23~12 ~47~23~12 minecraft:stone 0
setblock ~44~42~12 minecraft:leaves 0
fill ~44~44~12 ~45~44~12 minecraft:stone 0
fill ~44~49~12 ~45~50~12 minecraft:stone 0
fill ~44~61~12 ~45~61~12 minecraft:stone 0
fill ~45~38~12 ~46~38~12 minecraft:stone 0
fill ~45~43~12 ~46~43~12 minecraft:stone 0
fill ~45~47~12 ~45~48~13 minecraft:stone 0
fill ~45~55~12 ~48~55~12 minecraft:stone 0
setblock ~46~46~12 minecraft:stonebrick 0
setblock ~46~47~12 minecraft:torch 5
fill ~46~56~12 ~49~57~12 minecraft:stone 0
setblock ~46~61~12 minecraft:stonebrick 3
setblock ~46~62~12 minecraft:cobblestone_wall 0
setblock ~46~63~12 minecraft:cobblestone_wall 0
setblock ~46~64~12 minecraft:torch 5
fill ~47~37~12 ~49~37~12 minecraft:stone 0
setblock ~47~42~12 minecraft:stone 0
fill ~47~45~12 ~47~45~13 minecraft:stone 0
setblock ~47~46~12 minecraft:crafting_table
fill ~47~53~12 ~48~54~12 minecraft:stone 0
fill ~47~58~12 ~48~59~12 minecraft:stone 0
setblock ~47~61~12 minecraft:double_stone_block_slab 0
fill ~48~24~12 ~49~24~12 minecraft:stone 0
fill ~48~41~12 ~50~41~12 minecraft:stone 0
fill ~48~45~12 ~49~45~12 minecraft:double_stone_block_slab 0
fill ~48~46~12 ~49~46~12 minecraft:chest 3
fill ~48~61~12 ~48~61~18 minecraft:planks 0
fill ~49~42~12 ~50~42~12 minecraft:stone 0
setblock ~49~58~12 minecraft:log 0
setblock ~49~59~12 minecraft:stone 0
fill ~50~25~12 ~50~25~13 minecraft:stone 0
fill ~50~36~12 ~52~36~12 minecraft:stone 0
fill ~50~45~12 ~51~45~12 minecraft:stone 0
fill ~50~55~12 ~50~57~12 minecraft:leaves 0
fill ~51~26~12 ~51~26~13 minecraft:stone 0
fill ~51~43~12 ~52~43~12 minecraft:stone 0
setblock ~51~46~12 minecraft:cobblestone_wall 0
fill ~51~57~12 ~52~57~12 minecraft:leaves 0
fill ~52~44~12 ~52~44~13 minecraft:stone 0
fill ~52~45~12 ~52~45~13 minecraft:double_stone_block_slab 0
setblock ~52~46~12 minecraft:cobblestone_wall 0
fill ~52~55~12 ~52~55~13 minecraft:leaves 0
fill ~52~61~12 ~52~61~18 minecraft:planks 0
fill ~53~27~12 ~53~27~14 minecraft:stone 0
fill ~53~35~12 ~55~35~13 minecraft:stone 0
fill ~53~56~12 ~54~56~12 minecraft:leaves 0
fill ~53~58~12 ~53~58~14 minecraft:leaves 0
setblock ~53~61~12 minecraft:double_stone_block_slab 0
fill ~54~57~12 ~54~57~15 minecraft:leaves 0
setblock ~54~61~12 minecraft:stonebrick 3
setblock ~54~62~12 minecraft:cobblestone_wall 0
setblock ~54~63~12 minecraft:cobblestone_wall 0
setblock ~54~64~12 minecraft:torch 5
fill ~56~34~12 ~56~34~13 minecraft:stone 0
fill ~57~29~12 ~57~29~13 minecraft:stone 0
fill ~58~33~12 ~60~33~13 minecraft:stone 0
fill ~59~30~12 ~59~30~14 minecraft:stone 0
fill ~60~31~12 ~61~32~12 minecraft:stone 0
fill ~19~29~13 ~21~29~13 minecraft:stone 0
fill ~19~30~13 ~20~30~13 minecraft:stone 0
fill ~19~35~13 ~19~35~16 minecraft:leaves 2
fill ~20~31~13 ~22~31~15 minecraft:stone 0
setblock ~20~43~13 minecraft:stone_block_slab 11
fill ~20~44~13 ~21~44~13 minecraft:stonebrick 0
setblock ~20~45~13 minecraft:stonebrick 0
setblock ~20~46~13 minecraft:stone_brick_stairs 0
setblock ~21~33~13 minecraft:torch 4
fill ~21~37~13 ~22~37~13 minecraft:leaves 2
fill ~21~38~13 ~21~38~15 minecraft:leaves 2
setblock ~21~42~13 minecraft:stone_block_slab 8
fill ~21~43~13 ~21~43~15 minecraft:stonebrick 0
fill ~21~45~13 ~23~45~13 minecraft:wooden_slab 8
fill ~22~28~13 ~25~28~13 minecraft:stone 0
fill ~23~35~13 ~23~35~16 minecraft:leaves 2
fill ~23~36~13 ~23~36~15 minecraft:leaves 2
fill ~23~43~13 ~23~43~14 minecraft:stonebrick 0
fill ~24~42~13 ~24~42~15 minecraft:stonebrick 0
fill ~24~46~13 ~25~46~13 minecraft:wooden_slab 0
fill ~25~41~13 ~25~41~15 minecraft:stonebrick 0
setblock ~26~27~13 minecraft:stone 0
fill ~26~46~13 ~26~46~14 minecraft:wooden_slab 8
fill ~26~96~13 ~26~96~14 minecraft:log 0
setblock ~27~26~13 minecraft:stone 0
setblock ~27~27~13 minecraft:torch 5
fill ~27~33~13 ~27~45~13 minecraft:stonebrick 0
setblock ~27~47~13 minecraft:wooden_slab 0
setblock ~27~91~13 minecraft:stone_block_slab 13
fill ~27~92~13 ~27~95~13 minecraft:stonebrick 0
fill ~27~97~13 ~27~97~14 minecraft:oak_stairs 0
setblock ~28~25~13 minecraft:stone 0
setblock ~28~46~13 minecraft:stonebrick 0
setblock ~28~48~13 minecraft:torch 4
setblock ~28~64~13 minecraft:stone 0
fill ~28~65~13 ~29~65~13 minecraft:double_stone_block_slab 0
fill ~28~66~13 ~29~66~13 minecraft:stone_brick_stairs 2
setblock ~28~91~13 minecraft:cobblestone_wall 0
setblock ~28~92~13 minecraft:stone_brick_stairs 2
setblock ~28~95~13 minecraft:stone_brick_stairs 6
fill ~28~97~13 ~29~97~13 minecraft:oak_stairs 2
fill ~29~24~13 ~30~24~13 minecraft:stone 0
setblock ~29~33~13 minecraft:stone 0
setblock ~29~46~13 minecraft:stone_block_slab 11
fill ~29~47~13 ~29~48~13 minecraft:stonebrick 0
setblock ~29~49~13 minecraft:stone_brick_stairs 0
setblock ~29~63~13 minecraft:stone 0
setblock ~29~64~13 minecraft:double_stone_block_slab 0
setblock ~29~90~13 minecraft:cobblestone_wall 0
setblock ~29~91~13 minecraft:cobblestone_wall 0
setblock ~30~47~13 minecraft:stone_stairs 5
fill ~30~48~13 ~30~49~13 minecraft:stonebrick 0
setblock ~30~50~13 minecraft:stone_brick_stairs 0
fill ~30~55~13 ~30~55~15 minecraft:leaves 0
fill ~30~66~13 ~33~73~13 minecraft:stonebrick 0
setblock ~30~74~13 minecraft:stone_brick_stairs 0
setblock ~30~87~13 minecraft:stone_block_slab 13
fill ~30~88~13 ~32~88~13 minecraft:stone_block_slab 5
fill ~30~89~13 ~32~91~13 minecraft:stonebrick 0
setblock ~30~98~13 minecraft:oak_stairs 2
fill ~31~25~13 ~33~25~13 minecraft:stone 0
fill ~31~56~13 ~33~56~14 minecraft:leaves 0
fill ~31~57~13 ~31~57~14 minecraft:leaves 0
fill ~31~62~13 ~32~62~13 minecraft:stone 0
setblock ~31~63~13 minecraft:stone 0
fill ~31~74~13 ~33~74~13 minecraft:stonebrick 0
setblock ~31~75~13 minecraft:stone_brick_stairs 2
setblock ~31~80~13 minecraft:torch 4
setblock ~31~86~13 minecraft:stone_brick_stairs 6
setblock ~31~87~13 minecraft:stonebrick 0
setblock ~31~98~13 minecraft:log 0
setblock ~32~55~13 minecraft:leaves 0
setblock ~32~58~13 minecraft:leaves 0
fill ~32~61~13 ~33~61~13 minecraft:stone 0
fill ~32~75~13 ~33~75~13 minecraft:stonebrick 0
setblock ~32~76~13 minecraft:stone_brick_stairs 2
setblock ~32~87~13 minecraft:stone_block_slab 13
setblock ~32~98~13 minecraft:oak_stairs 2
fill ~33~26~13 ~35~26~13 minecraft:stone 0
fill ~33~35~13 ~34~35~13 minecraft:stone 0
fill ~33~59~13 ~33~59~14 minecraft:stone 0
setblock ~33~60~13 minecraft:stone 0
setblock ~33~90~13 minecraft:cobblestone_wall 0
setblock ~33~91~13 minecraft:cobblestone_wall 0
setblock ~33~97~13 minecraft:oak_stairs 1
fill ~34~36~13 ~36~36~13 minecraft:stone 0
setblock ~34~58~13 minecraft:stone 0
fill ~34~75~13 ~35~75~13 minecraft:stone_block_slab 8
setblock ~34~91~13 minecraft:cobblestone_wall 0
setblock ~34~92~13 minecraft:stone_brick_stairs 2
setblock ~34~95~13 minecraft:stone_brick_stairs 6
fill ~34~97~13 ~35~97~13 minecraft:oak_stairs 2
setblock ~35~56~13 minecraft:leaves 0
setblock ~35~57~13 minecraft:log 0
setblock ~35~91~13 minecraft:stone_block_slab 13
fill ~35~92~13 ~35~95~13 minecraft:stonebrick 0
setblock ~36~25~13 minecraft:stone 0
fill ~36~37~13 ~42~37~13 minecraft:stone 0
fill ~36~56~13 ~39~56~13 minecraft:stone 0
fill ~36~57~13 ~37~57~13 minecraft:stone 0
fill ~36~67~13 ~38~73~13 minecraft:stonebrick 0
fill ~36~75~13 ~39~75~13 minecraft:stonebrick 0
fill ~36~96~13 ~36~96~14 minecraft:log 0
fill ~37~24~13 ~38~24~13 minecraft:stone 0
fill ~37~44~13 ~37~44~16 minecraft:leaves 0
fill ~37~47~13 ~39~47~13 minecraft:stone 0
fill ~37~55~13 ~40~55~13 minecraft:stone 0
fill ~37~74~13 ~38~74~13 minecraft:stonebrick 0
fill ~38~43~13 ~40~43~13 minecraft:leaves 0
fill ~38~45~13 ~38~45~14 minecraft:leaves 0
fill ~38~48~13 ~39~49~13 minecraft:stone 0
fill ~39~23~13 ~44~23~13 minecraft:stone 0
fill ~39~42~13 ~40~42~15 minecraft:leaves 0
fill ~39~44~13 ~39~44~14 minecraft:leaves 0
setblock ~39~45~13 minecraft:leaves 0
setblock ~39~46~13 minecraft:stone 0
fill ~39~53~13 ~41~54~13 minecraft:stone 0
setblock ~40~44~13 minecraft:leaves 0
fill ~40~45~13 ~42~45~13 minecraft:stone 0
fill ~40~49~13 ~40~52~13 minecraft:stone 0
fill ~40~75~13 ~40~75~14 minecraft:stone_block_slab 8
fill ~41~38~13 ~44~38~13 minecraft:stone 0
fill ~41~44~13 ~42~44~13 minecraft:leaves 0
fill ~41~50~13 ~41~52~13 minecraft:stone 0
fill ~41~67~13 ~41~73~14 minecraft:stonebrick 0
fill ~41~74~13 ~41~75~13 minecraft:stonebrick 0
fill ~42~24~13 ~43~24~13 minecraft:stone 0
fill ~42~43~13 ~43~43~13 minecraft:leaves 0
fill ~42~46~13 ~45~46~13 minecraft:stone 0
fill ~42~47~13 ~44~47~13 minecraft:stone 0
fill ~42~65~13 ~42~65~14 minecraft:double_stone_block_slab 0
fill ~42~66~13 ~42~66~14 minecraft:stone_brick_stairs 1
setblock ~42~74~13 minecraft:stone_stairs 6
fill ~42~75~13 ~42~75~14 minecraft:stone_block_slab 13
setblock ~42~76~13 minecraft:stone_brick_stairs 2
setblock ~43~44~13 minecraft:stone 0
fill ~43~64~13 ~44~64~14 minecraft:stone 0
fill ~44~42~13 ~46~42~13 minecraft:stone 0
setblock ~44~43~13 minecraft:log 0
setblock ~44~44~13 minecraft:leaves 0
setblock ~44~45~13 minecraft:stone 0
fill ~44~62~13 ~44~63~15 minecraft:stone 0
fill ~45~22~13 ~46~22~13 minecraft:stone 0
fill ~45~39~13 ~48~39~13 minecraft:stone 0
fill ~45~41~13 ~47~41~13 minecraft:stone 0
fill ~45~43~13 ~45~44~13 minecraft:planks 0
setblock ~45~49~13 minecraft:stone 0
fill ~45~61~13 ~45~61~16 minecraft:stone 0
fill ~46~40~13 ~50~40~13 minecraft:stone 0
setblock ~46~45~13 minecraft:double_stone_block_slab 0
setblock ~46~46~13 minecraft:chest 5
fill ~46~50~13 ~46~50~14 minecraft:log 0
fill ~46~61~13 ~46~61~17 minecraft:log 0
setblock ~46~63~13 minecraft:cobblestone_wall 0
setblock ~46~64~13 minecraft:cobblestone_wall 0
fill ~47~23~13 ~48~23~13 minecraft:stone 0
fill ~47~38~13 ~49~38~13 minecraft:stone 0
fill ~47~51~13 ~47~52~13 minecraft:stone 0
fill ~47~61~13 ~47~61~18 minecraft:planks 0
setblock ~48~45~13 minecraft:stone_stairs 0
setblock ~48~52~13 minecraft:stone 0
fill ~49~24~13 ~49~24~16 minecraft:stone 0
setblock ~49~45~13 minecraft:stonebrick 2
fill ~49~53~13 ~49~55~13 minecraft:stone 0
setblock ~49~57~13 minecraft:torch 3
fill ~50~37~13 ~51~37~13 minecraft:stone 0
setblock ~50~45~13 minecraft:stonebrick 0
fill ~50~54~13 ~50~56~13 minecraft:stone 0
fill ~50~57~13 ~51~57~13 minecraft:log 0
fill ~50~58~13 ~52~59~13 minecraft:stone 0
fill ~51~41~13 ~51~42~13 minecraft:stone 0
setblock ~51~45~13 minecraft:double_stone_block_slab 0
setblock ~51~46~13 minecraft:chest 4
setblock ~52~36~13 minecraft:stone 0
setblock ~52~43~13 minecraft:stone 0
setblock ~52~46~13 minecraft:cobblestone_wall 0
setblock ~52~57~13 minecraft:leaves 0
fill ~53~55~13 ~53~56~13 minecraft:leaves 0
fill ~53~61~13 ~53~61~18 minecraft:planks 0
fill ~54~27~13 ~54~27~14 minecraft:stone 0
fill ~54~55~13 ~54~55~18 minecraft:leaves 0
fill ~54~56~13 ~55~56~16 minecraft:leaves 0
setblock ~54~58~13 minecraft:leaves 0
fill ~54~61~13 ~54~61~17 minecraft:log 0
setblock ~54~63~13 minecraft:cobblestone_wall 0
setblock ~54~64~13 minecraft:cobblestone_wall 0
fill ~55~28~13 ~56~28~13 minecraft:stone 0
fill ~55~57~13 ~55~57~14 minecraft:leaves 0
fill ~57~34~13 ~57~34~14 minecraft:stone 0
fill ~58~29~13 ~58~29~17 minecraft:stone 0
fill ~60~30~13 ~60~30~18 minecraft:stone 0
fill ~61~31~13 ~62~31~13 minecraft:stone 0
fill ~61~33~13 ~61~33~15 minecraft:stone 0
fill ~62~32~13 ~62~32~16 minecraft:stone 0
fill ~17~30~14 ~18~30~14 minecraft:stone 0
setblock ~18~29~14 minecraft:stone 0
fill ~18~31~14 ~19~31~14 minecraft:stone 0
fill ~19~28~14 ~22~28~14 minecraft:stone 0
fill ~19~36~14 ~20~36~16 minecraft:leaves 2
setblock ~19~43~14 minecraft:stone_stairs 6
fill ~19~44~14 ~19~45~14 minecraft:stonebrick 0
setblock ~19~46~14 minecraft:stone_block_slab 0
setblock ~20~33~14 minecraft:torch 2
fill ~20~35~14 ~20~35~16 minecraft:leaves 2
fill ~20~37~14 ~20~38~14 minecraft:leaves 2
setblock ~20~42~14 minecraft:stone_block_slab 8
setblock ~20~43~14 minecraft:stonebrick 0
fill ~20~45~14 ~22~45~14 minecraft:wooden_slab 0
fill ~21~32~14 ~21~37~14 minecraft:log 2
setblock ~22~33~14 minecraft:torch 1
fill ~22~35~14 ~22~36~16 minecraft:leaves 2
fill ~22~37~14 ~22~38~14 minecraft:leaves 2
fill ~23~27~14 ~23~27~15 minecraft:stone 0
fill ~23~45~14 ~24~45~14 minecraft:wooden_slab 8
setblock ~24~28~14 minecraft:stone 0
setblock ~25~27~14 minecraft:stone 0
fill ~25~32~14 ~25~32~16 minecraft:stone 0
setblock ~25~35~14 minecraft:torch 2
setblock ~25~39~14 minecraft:torch 2
setblock ~25~46~14 minecraft:wooden_slab 0
fill ~26~25~14 ~27~25~14 minecraft:stone 0
setblock ~26~26~14 minecraft:stone 0
fill ~26~33~14 ~26~44~14 minecraft:stonebrick 0
setblock ~26~47~14 minecraft:torch 2
fill ~27~33~14 ~28~33~14 minecraft:stone 0
setblock ~27~45~14 minecraft:stone_stairs 5
fill ~27~46~14 ~27~47~14 minecraft:stonebrick 0
setblock ~27~48~14 minecraft:stone_brick_stairs 0
fill ~27~64~14 ~27~64~15 minecraft:stone 0
fill ~27~65~14 ~27~65~15 minecraft:double_stone_block_slab 0
setblock ~27~66~14 minecraft:stone_brick_stairs 0
setblock ~27~91~14 minecraft:cobblestone_wall 0
setblock ~27~92~14 minecraft:stone_brick_stairs 0
setblock ~27~95~14 minecraft:stone_brick_stairs 4
fill ~28~24~14 ~28~24~15 minecraft:stone 0
setblock ~28~46~14 minecraft:stone_stairs 5
fill ~28~47~14 ~28~48~14 minecraft:stonebrick 0
setblock ~28~49~14 minecraft:stone_block_slab 0
fill ~28~63~14 ~28~63~15 minecraft:stone 0
fill ~28~66~14 ~30~71~14 minecraft:stonebrick 0
setblock ~28~72~14 minecraft:torch 5
fill ~28~88~14 ~29~88~14 minecraft:stone_block_slab 5
fill ~28~89~14 ~29~91~14 minecraft:stonebrick 0
fill ~28~98~14 ~29~98~14 minecraft:oak_stairs 2
fill ~29~23~14 ~31~23~14 minecraft:stone 0
fill ~29~34~14 ~30~34~14 minecraft:stone 0
fill ~29~55~14 ~29~55~18 minecraft:leaves 0
fill ~29~61~14 ~31~61~14 minecraft:stone 0
fill ~29~62~14 ~30~62~14 minecraft:stone 0
fill ~29~72~14 ~33~72~14 minecraft:stonebrick 0
setblock ~29~73~14 minecraft:stone_brick_stairs 0
setblock ~29~87~14 minecraft:stone_brick_stairs 4
fill ~30~56~14 ~30~56~18 minecraft:leaves 0
fill ~30~65~14 ~33~65~19 minecraft:stone_block_slab 8
fill ~30~73~14 ~33~73~14 minecraft:stonebrick 0
fill ~30~74~14 ~32~80~14 minecraft:stonebrick 0
fill ~30~81~14 ~30~87~14 minecraft:stonebrick 0
fill ~30~88~14 ~32~88~14 minecraft:cobblestone
fill ~30~91~14 ~34~91~15 minecraft:stonebrick 0
setblock ~30~98~14 minecraft:planks 0
fill ~30~99~14 ~32~99~14 minecraft:log 0
fill ~31~24~14 ~34~24~14 minecraft:stone 0
fill ~31~35~14 ~32~35~14 minecraft:stone 0
fill ~31~55~14 ~31~55~15 minecraft:leaves 0
fill ~31~71~14 ~33~71~14 minecraft:stonebrick 0
setblock ~31~81~14 minecraft:stone_brick_stairs 2
setblock ~31~84~14 minecraft:stone_brick_stairs 6
fill ~31~85~14 ~32~86~14 minecraft:stonebrick 0
fill ~32~36~14 ~33~36~14 minecraft:stone 0
setblock ~32~60~14 minecraft:stone 0
fill ~32~81~14 ~32~84~14 minecraft:stonebrick 0
setblock ~32~87~14 minecraft:stonebrick 0
setblock ~32~98~14 minecraft:planks 0
setblock ~33~55~14 minecraft:leaves 0
setblock ~33~58~14 minecraft:stone 0
setblock ~33~75~14 minecraft:stone_block_slab 8
setblock ~33~87~14 minecraft:stone_brick_stairs 5
fill ~33~88~14 ~34~88~14 minecraft:stone_block_slab 5
fill ~33~89~14 ~34~90~14 minecraft:stonebrick 0
fill ~33~98~14 ~34~98~14 minecraft:oak_stairs 2
fill ~34~25~14 ~35~25~14 minecraft:stone 0
fill ~34~37~14 ~38~37~14 minecraft:stone 0
setblock ~34~47~14 minecraft:torch 4
fill ~34~55~14 ~36~55~14 minecraft:stone 0
fill ~34~56~14 ~35~56~14 minecraft:stone 0
setblock ~34~57~14 minecraft:log 0
fill ~34~66~14 ~35~70~14 minecraft:stonebrick 0
fill ~34~75~14 ~35~75~14 minecraft:stonebrick 0
fill ~35~44~14 ~36~44~16 minecraft:leaves 0
fill ~35~48~14 ~37~49~14 minecraft:stone 0
setblock ~35~71~14 minecraft:stonebrick 0
setblock ~35~72~14 minecraft:cobblestone
setblock ~35~73~14 minecraft:stonebrick 0
setblock ~35~91~14 minecraft:cobblestone_wall 0
setblock ~35~92~14 minecraft:stone_brick_stairs 1
setblock ~35~95~14 minecraft:stone_brick_stairs 5
fill ~35~97~14 ~35~97~15 minecraft:oak_stairs 1
fill ~36~23~14 ~43~23~14 minecraft:stone 0
setblock ~36~24~14 minecraft:stone 0
fill ~36~47~14 ~36~47~15 minecraft:stone 0
fill ~36~50~14 ~39~51~14 minecraft:stone 0
fill ~36~65~14 ~37~65~14 minecraft:stone_block_slab 11
setblock ~36~66~14 minecraft:log 0
fill ~36~67~14 ~38~67~14 minecraft:stone_block_slab 0
fill ~36~70~14 ~36~70~15 minecraft:wooden_slab 8
setblock ~36~73~14 minecraft:stone_stairs 5
setblock ~36~74~14 minecraft:cobblestone
fill ~36~75~14 ~38~75~14 minecraft:stone_block_slab 13
setblock ~36~76~14 minecraft:stonebrick 0
fill ~36~77~14 ~36~78~14 minecraft:cobblestone_wall 0
fill ~37~43~14 ~37~43~16 minecraft:leaves 0
setblock ~37~45~14 minecraft:leaves 0
fill ~37~46~14 ~38~46~14 minecraft:stone 0
fill ~37~52~14 ~39~52~14 minecraft:stone 0
fill ~37~53~14 ~38~54~14 minecraft:stone 0
fill ~37~66~14 ~38~66~14 minecraft:furnace 3
fill ~37~70~14 ~37~70~15 minecraft:stone_block_slab 11
setblock ~37~74~14 minecraft:stone_stairs 5
setblock ~37~76~14 minecraft:stone_brick_stairs 1
fill ~38~70~14 ~38~70~15 minecraft:wooden_slab 8
setblock ~38~74~14 minecraft:stone_stairs 4
fill ~39~38~14 ~40~38~14 minecraft:stone 0
fill ~39~43~14 ~40~43~15 minecraft:leaves 0
fill ~39~45~14 ~39~45~15 minecraft:stone 0
fill ~39~67~14 ~39~75~14 minecraft:stonebrick 0
fill ~40~44~14 ~42~44~14 minecraft:stone 0
fill ~41~39~14 ~44~39~14 minecraft:stone 0
fill ~41~41~14 ~41~41~15 minecraft:leaves 0
fill ~41~42~14 ~42~42~14 minecraft:leaves 0
fill ~41~45~14 ~41~48~14 minecraft:stone 0
setblock ~41~75~14 minecraft:stonebrick 0
setblock ~42~41~14 minecraft:leaves 0
fill ~42~43~14 ~43~43~14 minecraft:stone 0
setblock ~42~45~14 minecraft:double_stone_block_slab 0
setblock ~42~46~14 minecraft:chest 3
fill ~42~48~14 ~44~48~14 minecraft:stone 0
setblock ~42~71~14 minecraft:torch 1
setblock ~42~73~14 minecraft:stone_stairs 6
setblock ~42~74~14 minecraft:cobblestone
setblock ~42~76~14 minecraft:stonebrick 0
fill ~42~77~14 ~42~78~14 minecraft:cobblestone_wall 0
fill ~43~40~14 ~45~40~14 minecraft:stone 0
fill ~43~41~14 ~44~41~14 minecraft:stone 0
setblock ~43~42~14 minecraft:log 0
fill ~43~44~14 ~44~44~14 minecraft:double_stone_block_slab 0
fill ~43~45~14 ~44~45~14 minecraft:chest 3
fill ~44~22~14 ~44~22~15 minecraft:stone 0
setblock ~44~23~14 minecraft:torch 5
setblock ~44~42~14 minecraft:torch 5
fill ~45~21~14 ~45~21~16 minecraft:stone 0
setblock ~45~44~14 minecraft:stone 0
fill ~45~45~14 ~45~49~14 minecraft:log 0
setblock ~45~50~14 minecraft:stone 0
fill ~46~22~14 ~47~22~14 minecraft:stone 0
setblock ~46~39~14 minecraft:torch 3
setblock ~46~45~14 minecraft:stone 0
setblock ~46~46~14 minecraft:cobblestone_wall 0
fill ~46~47~14 ~46~49~14 minecraft:cobblestone_wall 0
setblock ~46~64~14 minecraft:cobblestone_wall 0
setblock ~46~65~14 minecraft:cobblestone_wall 0
setblock ~47~45~14 minecraft:stonebrick 0
fill ~47~50~14 ~47~50~15 minecraft:log 0
fill ~48~23~14 ~48~23~17 minecraft:stone 0
setblock ~48~45~14 minecraft:stonebrick 2
fill ~48~51~14 ~48~51~15 minecraft:stone 0
fill ~49~39~14 ~51~39~14 minecraft:stone 0
fill ~49~45~14 ~50~45~14 minecraft:stone 0
setblock ~49~52~14 minecraft:stone 0
fill ~50~24~14 ~50~24~18 minecraft:stone 0
setblock ~50~25~14 minecraft:torch 5
fill ~50~38~14 ~51~38~14 minecraft:stone 0
setblock ~50~53~14 minecraft:stone 0
fill ~51~25~14 ~51~25~16 minecraft:stone 0
fill ~51~40~14 ~52~40~14 minecraft:stone 0
setblock ~51~45~14 minecraft:stonebrick 0
fill ~51~54~14 ~51~54~15 minecraft:stone 0
fill ~51~55~14 ~51~56~14 minecraft:stone 0
setblock ~51~57~14 minecraft:leaves 0
setblock ~52~26~14 minecraft:stone 0
fill ~52~37~14 ~53~37~14 minecraft:stone 0
fill ~52~41~14 ~52~41~15 minecraft:stone 0
setblock ~52~42~14 minecraft:stone 0
setblock ~52~45~14 minecraft:stone 0
setblock ~52~46~14 minecraft:cobblestone_wall 0
fill ~52~54~14 ~52~54~15 minecraft:leaves 0
setblock ~52~55~14 minecraft:leaves 0
setblock ~52~56~14 minecraft:stone 0
setblock ~52~57~14 minecraft:log 0
setblock ~52~58~14 minecraft:stone 0
setblock ~52~59~14 minecraft:torch 5
fill ~53~36~14 ~54~36~14 minecraft:stone 0
fill ~53~43~14 ~53~43~16 minecraft:stone 0
setblock ~53~44~14 minecraft:stone 0
setblock ~53~45~14 minecraft:double_stone_block_slab 0
setblock ~53~46~14 minecraft:cobblestone_wall 0
fill ~53~55~14 ~53~56~14 minecraft:leaves 0
setblock ~53~59~14 minecraft:stone 0
setblock ~54~28~14 minecraft:torch 5
fill ~54~54~14 ~54~54~22 minecraft:leaves 0
setblock ~54~59~14 minecraft:torch 1
fill ~54~60~14 ~54~60~15 minecraft:stone 0
setblock ~54~64~14 minecraft:cobblestone_wall 0
setblock ~54~65~14 minecraft:cobblestone_wall 0
fill ~55~27~14 ~55~27~15 minecraft:stone 0
fill ~55~35~14 ~56~35~14 minecraft:stone 0
fill ~55~55~14 ~55~55~23 minecraft:leaves 0
fill ~56~28~14 ~57~28~14 minecraft:stone 0
fill ~58~34~14 ~59~34~15 minecraft:stone 0
fill ~59~38~14 ~62~39~15 minecraft:leaves 2
setblock ~60~33~14 minecraft:stone 0
fill ~61~30~14 ~61~30~15 minecraft:stone 0
fill ~62~31~14 ~62~31~15 minecraft:stone 0
fill ~15~31~15 ~17~31~15 minecraft:stone 0
fill ~16~30~15 ~16~30~18 minecraft:stone 0
fill ~17~29~15 ~17~29~19 minecraft:stone 0
fill ~17~32~15 ~19~32~16 minecraft:stone 0
fill ~18~28~15 ~19~28~16 minecraft:stone 0
setblock ~18~29~15 minecraft:torch 5
setblock ~18~42~15 minecraft:stone_block_slab 11
fill ~18~43~15 ~19~43~15 minecraft:stonebrick 0
setblock ~18~44~15 minecraft:stonebrick 0
setblock ~18~45~15 minecraft:stone_brick_stairs 0
setblock ~19~41~15 minecraft:stone_block_slab 8
fill ~19~42~15 ~20~42~15 minecraft:stonebrick 0
fill ~19~44~15 ~23~44~15 minecraft:wooden_slab 8
setblock ~19~45~15 minecraft:torch 3
fill ~20~27~15 ~22~27~16 minecraft:stone 0
setblock ~21~33~15 minecraft:torch 3
fill ~21~35~15 ~21~36~16 minecraft:leaves 2
setblock ~21~37~15 minecraft:leaves 2
fill ~23~31~15 ~23~31~16 minecraft:stone 0
fill ~23~42~15 ~23~42~16 minecraft:stonebrick 0
setblock ~23~45~15 minecraft:wooden_slab 0
setblock ~24~27~15 minecraft:stone 0
fill ~24~32~15 ~24~32~18 minecraft:stone 0
setblock ~24~41~15 minecraft:stone_block_slab 8
fill ~24~43~15 ~25~43~15 minecraft:stonebrick 0
fill ~24~45~15 ~25~45~15 minecraft:wooden_slab 8
fill ~25~26~15 ~25~26~16 minecraft:stone 0
setblock ~25~40~15 minecraft:stone_block_slab 8
setblock ~25~42~15 minecraft:stonebrick 0
setblock ~25~44~15 minecraft:stonebrick 0
setblock ~25~46~15 minecraft:torch 4
fill ~25~96~15 ~25~96~19 minecraft:log 0
fill ~26~25~15 ~26~25~16 minecraft:stone 0
setblock ~26~32~15 minecraft:stone 0
setblock ~26~44~15 minecraft:stone_block_slab 11
fill ~26~45~15 ~26~46~15 minecraft:stonebrick 0
setblock ~26~47~15 minecraft:stone_brick_stairs 0
setblock ~26~91~15 minecraft:stone_block_slab 13
fill ~26~92~15 ~27~95~15 minecraft:stonebrick 0
fill ~26~97~15 ~26~97~16 minecraft:oak_stairs 0
fill ~27~24~15 ~27~24~16 minecraft:stone 0
fill ~27~33~15 ~27~33~16 minecraft:stone 0
setblock ~27~66~15 minecraft:double_stone_block_slab 0
setblock ~27~67~15 minecraft:stone_brick_stairs 0
setblock ~27~90~15 minecraft:cobblestone_wall 0
setblock ~27~91~15 minecraft:cobblestone_wall 0
setblock ~27~97~15 minecraft:oak_stairs 2
fill ~28~34~15 ~29~34~16 minecraft:stone 0
fill ~28~55~15 ~28~55~18 minecraft:leaves 0
fill ~28~62~15 ~28~62~17 minecraft:stone 0
fill ~28~66~15 ~28~72~15 minecraft:stonebrick 0
setblock ~28~73~15 minecraft:stone_brick_stairs 2
setblock ~28~87~15 minecraft:stone_brick_stairs 6
setblock ~28~88~15 minecraft:stone_block_slab 5
fill ~28~89~15 ~28~91~15 minecraft:stonebrick 0
setblock ~28~98~15 minecraft:oak_stairs 0
setblock ~29~23~15 minecraft:stone 0
fill ~29~54~15 ~30~54~15 minecraft:leaves 0
fill ~29~56~15 ~29~56~18 minecraft:leaves 0
fill ~29~61~15 ~30~61~15 minecraft:stone 0
fill ~29~65~15 ~29~65~19 minecraft:stone_block_slab 8
fill ~29~71~15 ~29~87~15 minecraft:stonebrick 0
setblock ~29~88~15 minecraft:double_stone_block_slab 3
fill ~29~91~15 ~29~91~20 minecraft:stonebrick 0
setblock ~29~98~15 minecraft:planks 0
setblock ~29~99~15 minecraft:log 0
fill ~30~22~15 ~30~22~16 minecraft:stone 0
fill ~30~35~15 ~30~35~16 minecraft:stone 0
fill ~30~57~15 ~30~57~17 minecraft:leaves 0
fill ~30~67~15 ~30~67~16 minecraft:stone_block_slab 3
fill ~30~71~15 ~30~71~16 minecraft:stone_block_slab 3
fill ~30~75~15 ~30~75~16 minecraft:stone_block_slab 3
setblock ~30~100~15 minecraft:planks 0
setblock ~30~101~15 minecraft:wooden_slab 0
fill ~31~23~15 ~37~23~15 minecraft:stone 0
fill ~31~36~15 ~31~36~16 minecraft:stone 0
fill ~31~56~15 ~32~56~15 minecraft:leaves 0
setblock ~31~58~15 minecraft:torch 2
setblock ~31~60~15 minecraft:stone 0
fill ~31~66~15 ~31~66~16 minecraft:stone_block_slab 11
fill ~31~70~15 ~31~70~16 minecraft:stone_block_slab 11
fill ~31~74~15 ~31~74~16 minecraft:stone_block_slab 11
fill ~31~100~15 ~31~101~15 minecraft:log 0
setblock ~31~102~15 minecraft:torch 5
fill ~32~37~15 ~36~37~15 minecraft:stone 0
setblock ~32~54~15 minecraft:leaves 0
fill ~32~55~15 ~33~55~15 minecraft:stone 0
setblock ~32~57~15 minecraft:leaves 0
fill ~32~58~15 ~32~58~16 minecraft:stone 0
setblock ~32~59~15 minecraft:stone 0
fill ~32~66~15 ~32~66~16 minecraft:stone_block_slab 3
fill ~32~70~15 ~32~70~16 minecraft:stone_block_slab 3
fill ~32~74~15 ~32~74~16 minecraft:stone_block_slab 3
setblock ~32~100~15 minecraft:planks 0
setblock ~32~101~15 minecraft:wooden_slab 0
fill ~33~45~15 ~35~45~15 minecraft:leaves 0
fill ~33~49~15 ~34~51~15 minecraft:stone 0
setblock ~33~56~15 minecraft:log 0
setblock ~33~57~15 minecraft:stone 0
setblock ~33~58~15 minecraft:torch 5
fill ~33~71~15 ~34~75~15 minecraft:stonebrick 0
fill ~33~76~15 ~33~87~15 minecraft:stonebrick 0
setblock ~33~88~15 minecraft:cobblestone
setblock ~33~98~15 minecraft:planks 0
setblock ~33~99~15 minecraft:log 0
fill ~34~47~15 ~35~47~16 minecraft:stone 0
setblock ~34~48~15 minecraft:stone 0
fill ~34~52~15 ~36~52~15 minecraft:stone 0
fill ~34~54~15 ~36~54~15 minecraft:stone 0
setblock ~34~56~15 minecraft:planks 0
fill ~34~65~15 ~35~65~16 minecraft:stone_block_slab 8
fill ~34~70~15 ~35~70~15 minecraft:stonebrick 0
setblock ~34~87~15 minecraft:stone_brick_stairs 6
setblock ~34~88~15 minecraft:stone_block_slab 5
fill ~34~89~15 ~34~90~15 minecraft:stonebrick 0
setblock ~34~98~15 minecraft:oak_stairs 1
setblock ~35~24~15 minecraft:stone 0
fill ~35~43~15 ~36~43~16 minecraft:leaves 0
fill ~35~50~15 ~35~51~15 minecraft:stone 0
fill ~35~53~15 ~36~53~15 minecraft:stone 0
fill ~35~68~15 ~35~68~16 minecraft:stone_brick_stairs 5
fill ~35~69~15 ~35~69~18 minecraft:stonebrick 0
setblock ~35~73~15 minecraft:stone_stairs 7
setblock ~35~74~15 minecraft:cobblestone
setblock ~35~75~15 minecraft:stone_block_slab 13
setblock ~35~76~15 minecraft:stone_brick_stairs 0
setblock ~35~90~15 minecraft:cobblestone_wall 0
setblock ~35~91~15 minecraft:cobblestone_wall 0
fill ~35~92~15 ~36~95~15 minecraft:stonebrick 0
fill ~36~45~15 ~36~45~16 minecraft:leaves 0
setblock ~36~55~15 minecraft:torch 5
setblock ~36~65~15 minecraft:stonebrick 3
setblock ~36~91~15 minecraft:stone_block_slab 13
setblock ~36~97~15 minecraft:oak_stairs 2
setblock ~37~24~15 minecraft:torch 5
fill ~37~38~15 ~38~39~15 minecraft:stone 0
fill ~37~42~15 ~38~42~15 minecraft:leaves 0
fill ~37~45~15 ~38~45~15 minecraft:stone 0
setblock ~37~46~15 minecraft:stone 0
setblock ~37~65~15 minecraft:stone 0
fill ~37~96~15 ~37~96~19 minecraft:log 0
fill ~38~22~15 ~41~22~15 minecraft:stone 0
fill ~38~43~15 ~38~43~16 minecraft:leaves 0
setblock ~38~65~15 minecraft:stonebrick 2
fill ~39~39~15 ~42~39~15 minecraft:stone 0
fill ~39~44~15 ~40~44~15 minecraft:stone 0
setblock ~39~65~15 minecraft:stone_block_slab 11
setblock ~39~66~15 minecraft:log 0
fill ~39~67~15 ~39~67~16 minecraft:stone_block_slab 0
setblock ~39~70~15 minecraft:stone_block_slab 11
setblock ~39~73~15 minecraft:stone_stairs 4
setblock ~39~74~15 minecraft:cobblestone
fill ~39~75~15 ~39~75~16 minecraft:stone_block_slab 13
setblock ~39~76~15 minecraft:stone_brick_stairs 2
setblock ~40~41~15 minecraft:leaves 0
fill ~40~45~15 ~40~47~15 minecraft:log 0
setblock ~40~48~15 minecraft:stone 0
fill ~40~67~15 ~40~71~16 minecraft:stonebrick 0
setblock ~40~72~15 minecraft:cobblestone
fill ~40~73~15 ~40~73~16 minecraft:stonebrick 0
fill ~40~75~15 ~40~75~16 minecraft:stonebrick 0
setblock ~41~42~15 minecraft:leaves 0
setblock ~41~43~15 minecraft:stone 0
setblock ~41~44~15 minecraft:double_stone_block_slab 0
setblock ~41~45~15 minecraft:chest 3
setblock ~41~48~15 minecraft:oak_stairs 5
fill ~41~49~15 ~44~49~15 minecraft:stone 0
fill ~41~75~15 ~41~75~16 minecraft:stone_block_slab 8
fill ~42~23~15 ~43~23~15 minecraft:stone 0
setblock ~42~41~15 minecraft:stone 0
setblock ~42~42~15 minecraft:log 0
setblock ~42~44~15 minecraft:stonebrick 2
fill ~42~66~15 ~42~71~16 minecraft:stonebrick 0
setblock ~42~72~15 minecraft:cobblestone
fill ~42~73~15 ~42~73~16 minecraft:stonebrick 0
fill ~42~75~15 ~42~75~16 minecraft:stonebrick 0
setblock ~42~76~15 minecraft:torch 3
setblock ~43~40~15 minecraft:stone 0
setblock ~43~42~15 minecraft:torch 3
setblock ~43~44~15 minecraft:stone_stairs 3
fill ~43~64~15 ~43~64~16 minecraft:double_stone_block_slab 0
setblock ~43~65~15 minecraft:stone_brick_stairs 1
setblock ~43~73~15 minecraft:stone_stairs 5
setblock ~43~74~15 minecraft:cobblestone
fill ~43~75~15 ~43~75~16 minecraft:stone_block_slab 13
setblock ~43~76~15 minecraft:stone_brick_stairs 3
setblock ~44~44~15 minecraft:stonebrick 2
setblock ~44~50~15 minecraft:stone 0
fill ~45~44~15 ~45~44~16 minecraft:stonebrick 0
setblock ~45~47~15 minecraft:torch 3
fill ~45~51~15 ~46~51~17 minecraft:stone 0
fill ~46~21~15 ~46~21~17 minecraft:stone 0
fill ~46~45~15 ~47~45~15 minecraft:stone_block_slab 3
setblock ~46~65~15 minecraft:cobblestone_wall 0
setblock ~46~66~15 minecraft:cobblestone_wall 0
fill ~47~22~15 ~47~22~17 minecraft:stone 0
setblock ~48~45~15 minecraft:stone 0
fill ~48~50~15 ~48~50~17 minecraft:log 0
setblock ~49~45~15 minecraft:stonebrick 0
fill ~49~51~15 ~49~51~16 minecraft:stone 0
setblock ~49~52~15 minecraft:torch 5
setblock ~50~45~15 minecraft:stone_stairs 3
fill ~50~52~15 ~50~52~16 minecraft:stone 0
setblock ~51~45~15 minecraft:stone 0
fill ~51~53~15 ~51~53~19 minecraft:stone 0
fill ~52~25~15 ~52~25~17 minecraft:stone 0
fill ~52~38~15 ~54~38~15 minecraft:stone 0
fill ~52~39~15 ~52~40~15 minecraft:stone 0
setblock ~52~42~15 minecraft:torch 5
setblock ~52~45~15 minecraft:double_stone_block_slab 0
setblock ~52~46~15 minecraft:chest 4
fill ~52~55~15 ~53~55~15 minecraft:stone 0
setblock ~52~56~15 minecraft:leaves 0
setblock ~52~57~15 minecraft:torch 2
fill ~53~26~15 ~54~26~15 minecraft:stone 0
fill ~53~42~15 ~53~42~17 minecraft:stone 0
setblock ~53~45~15 minecraft:stone 0
setblock ~53~46~15 minecraft:cobblestone_wall 0
setblock ~53~54~15 minecraft:leaves 0
fill ~53~56~15 ~53~56~16 minecraft:log 0
fill ~53~57~15 ~53~58~15 minecraft:stone 0
setblock ~54~37~15 minecraft:stone 0
fill ~54~44~15 ~54~44~18 minecraft:stone 0
fill ~54~45~15 ~54~45~17 minecraft:double_stone_block_slab 0
setblock ~54~46~15 minecraft:cobblestone_wall 0
setblock ~54~59~15 minecraft:stone 0
setblock ~54~65~15 minecraft:cobblestone_wall 0
setblock ~54~66~15 minecraft:cobblestone_wall 0
setblock ~55~36~15 minecraft:stone 0
setblock ~55~54~15 minecraft:leaves 0
fill ~56~27~15 ~56~27~18 minecraft:stone 0
fill ~56~35~15 ~57~35~15 minecraft:stone 0
fill ~56~55~15 ~56~55~18 minecraft:leaves 0
fill ~57~28~15 ~57~28~18 minecraft:stone 0
fill ~59~29~15 ~59~29~19 minecraft:stone 0
setblock ~59~30~15 minecraft:torch 5
fill ~60~34~15 ~60~34~19 minecraft:stone 0
setblock ~61~36~15 minecraft:torch 4
fill ~61~40~15 ~62~40~15 minecraft:leaves 2
fill ~61~41~15 ~61~41~17 minecraft:leaves 2
fill ~62~33~15 ~63~33~16 minecraft:stone 0
fill ~63~38~15 ~63~39~18 minecraft:leaves 2
fill ~14~31~16 ~15~31~17 minecraft:stone 0
fill ~16~32~16 ~16~32~17 minecraft:stone 0
setblock ~17~42~16 minecraft:stone_stairs 6
fill ~17~43~16 ~17~44~16 minecraft:stonebrick 0
setblock ~17~45~16 minecraft:stone_block_slab 0
setblock ~18~35~16 minecraft:torch 4
setblock ~18~38~16 minecraft:torch 4
setblock ~18~39~16 minecraft:stone_brick_stairs 6
fill ~18~40~16 ~18~42~16 minecraft:stonebrick 0
fill ~18~44~16 ~22~44~16 minecraft:wooden_slab 0
setblock ~19~41~16 minecraft:stonebrick 0
fill ~20~32~16 ~20~32~17 minecraft:stone 0
fill ~20~42~16 ~22~42~16 minecraft:stonebrick 0
fill ~21~31~16 ~22~31~17 minecraft:stone 0
fill ~23~26~16 ~24~26~16 minecraft:stone 0
setblock ~23~41~16 minecraft:stone_block_slab 8
setblock ~23~44~16 minecraft:wooden_slab 8
setblock ~24~43~16 minecraft:stone_stairs 5
fill ~24~44~16 ~24~45~16 minecraft:stonebrick 0
setblock ~24~46~16 minecraft:stone_brick_stairs 0
setblock ~25~44~16 minecraft:stone_stairs 5
fill ~25~45~16 ~25~46~16 minecraft:stonebrick 0
setblock ~25~47~16 minecraft:stone_block_slab 0
fill ~26~33~16 ~26~33~17 minecraft:stone 0
fill ~26~64~16 ~26~64~18 minecraft:stone 0
fill ~26~65~16 ~26~66~17 minecraft:double_stone_block_slab 0
fill ~26~67~16 ~26~67~18 minecraft:stone_brick_stairs 0
setblock ~26~92~16 minecraft:stone_brick_stairs 0
setblock ~26~94~16 minecraft:torch 4
setblock ~26~95~16 minecraft:stone_brick_stairs 4
fill ~27~63~16 ~27~63~18 minecraft:stone 0
fill ~27~66~16 ~27~73~18 minecraft:stonebrick 0
setblock ~27~74~16 minecraft:stone_brick_stairs 2
setblock ~27~87~16 minecraft:stone_block_slab 13
fill ~27~88~16 ~27~88~18 minecraft:stone_block_slab 5
fill ~27~89~16 ~27~91~18 minecraft:stonebrick 0
setblock ~27~98~16 minecraft:oak_stairs 0
fill ~28~23~16 ~28~23~17 minecraft:stone 0
fill ~28~56~16 ~28~56~17 minecraft:leaves 0
fill ~28~65~16 ~28~65~18 minecraft:stone_block_slab 8
fill ~28~71~16 ~28~75~19 minecraft:stonebrick 0
fill ~28~76~16 ~28~80~18 minecraft:stonebrick 0
fill ~28~81~16 ~28~87~16 minecraft:stonebrick 0
fill ~28~88~16 ~28~88~18 minecraft:double_stone_block_slab 3
fill ~28~91~16 ~28~91~20 minecraft:stonebrick 0
setblock ~28~98~16 minecraft:planks 0
fill ~28~99~16 ~28~99~18 minecraft:log 0
fill ~29~22~16 ~29~22~17 minecraft:stone 0
setblock ~29~23~16 minecraft:torch 5
fill ~29~54~16 ~29~54~18 minecraft:leaves 0
setblock ~29~57~16 minecraft:leaves 0
fill ~29~61~16 ~29~61~18 minecraft:stone 0
setblock ~29~67~16 minecraft:stone_block_slab 3
setblock ~29~71~16 minecraft:stone_block_slab 3
setblock ~29~75~16 minecraft:stone_block_slab 3
setblock ~29~100~16 minecraft:planks 0
setblock ~29~101~16 minecraft:wooden_slab 0
setblock ~30~36~16 minecraft:stone 0
setblock ~30~54~16 minecraft:leaves 0
fill ~30~60~16 ~30~60~18 minecraft:stone 0
setblock ~30~78~16 minecraft:stone_block_slab 11
setblock ~30~82~16 minecraft:stone_block_slab 11
setblock ~30~86~16 minecraft:stone_block_slab 11
setblock ~30~90~16 minecraft:stone_block_slab 11
fill ~30~101~16 ~32~101~16 minecraft:planks 0
setblock ~30~102~16 minecraft:planks 0
fill ~31~22~16 ~37~22~16 minecraft:stone 0
setblock ~31~54~16 minecraft:leaves 0
fill ~31~55~16 ~31~55~17 minecraft:log 0
fill ~31~56~16 ~31~57~16 minecraft:leaves 0
fill ~31~59~16 ~31~59~17 minecraft:stone 0
setblock ~31~72~16 minecraft:torch 4
setblock ~31~76~16 minecraft:torch 4
setblock ~31~78~16 minecraft:stone_block_slab 3
setblock ~31~80~16 minecraft:torch 4
setblock ~31~82~16 minecraft:stone_block_slab 3
setblock ~31~84~16 minecraft:torch 4
setblock ~31~86~16 minecraft:stone_block_slab 3
setblock ~31~88~16 minecraft:torch 4
setblock ~31~90~16 minecraft:stone_block_slab 3
setblock ~31~94~16 minecraft:torch 4
fill ~31~102~16 ~31~102~18 minecraft:log 0
setblock ~31~103~16 minecraft:log 0
fill ~32~37~16 ~33~37~16 minecraft:stone 0
fill ~32~45~16 ~34~45~17 minecraft:leaves 0
fill ~32~50~16 ~32~54~16 minecraft:stone 0
fill ~32~55~16 ~32~55~17 minecraft:leaves 0
setblock ~32~56~16 minecraft:log 0
setblock ~32~57~16 minecraft:stone 0
setblock ~32~77~16 minecraft:stone_block_slab 11
setblock ~32~81~16 minecraft:stone_block_slab 11
setblock ~32~85~16 minecraft:stone_block_slab 11
setblock ~32~89~16 minecraft:stone_block_slab 11
setblock ~32~102~16 minecraft:planks 0
fill ~33~44~16 ~34~44~17 minecraft:leaves 0
fill ~33~48~16 ~33~48~17 minecraft:stone 0
setblock ~33~49~16 minecraft:stone 0
fill ~33~52~16 ~33~54~16 minecraft:stone 0
setblock ~33~70~16 minecraft:stone_block_slab 3
setblock ~33~74~16 minecraft:stone_block_slab 3
fill ~33~91~16 ~35~91~18 minecraft:stonebrick 0
setblock ~33~100~16 minecraft:planks 0
setblock ~33~101~16 minecraft:wooden_slab 0
fill ~34~38~16 ~36~38~16 minecraft:stone 0
fill ~34~43~16 ~34~43~17 minecraft:leaves 0
fill ~34~46~16 ~35~46~16 minecraft:leaves 0
setblock ~34~53~16 minecraft:stone 0
fill ~34~71~16 ~35~73~18 minecraft:stonebrick 0
fill ~34~74~16 ~34~80~18 minecraft:stonebrick 0
fill ~34~81~16 ~34~87~16 minecraft:stonebrick 0
fill ~34~88~16 ~34~88~18 minecraft:cobblestone
setblock ~34~98~16 minecraft:planks 0
fill ~34~99~16 ~34~99~18 minecraft:log 0
fill ~35~39~16 ~36~39~16 minecraft:stone 0
setblock ~35~45~16 minecraft:leaves 0
fill ~35~70~16 ~35~70~18 minecraft:stonebrick 0
setblock ~35~74~16 minecraft:stone_brick_stairs 2
setblock ~35~87~16 minecraft:stone_block_slab 13
fill ~35~88~16 ~35~88~18 minecraft:stone_block_slab 5
fill ~35~89~16 ~35~90~18 minecraft:stonebrick 0
setblock ~35~98~16 minecraft:oak_stairs 1
fill ~36~21~16 ~41~21~16 minecraft:stone 0
setblock ~36~46~16 minecraft:stone 0
setblock ~36~65~16 minecraft:cobblestone
setblock ~36~70~16 minecraft:oak_stairs 3
setblock ~36~92~16 minecraft:stone_brick_stairs 1
setblock ~36~94~16 minecraft:torch 4
setblock ~36~95~16 minecraft:stone_brick_stairs 5
setblock ~36~97~16 minecraft:oak_stairs 1
fill ~37~40~16 ~42~40~16 minecraft:stone 0
setblock ~37~45~16 minecraft:log 0
setblock ~37~65~16 minecraft:stonebrick 2
setblock ~37~70~16 minecraft:stone_block_slab 3
fill ~38~41~16 ~41~41~16 minecraft:stone 0
setblock ~38~44~16 minecraft:log 0
setblock ~38~65~16 minecraft:stone 0
setblock ~38~70~16 minecraft:oak_stairs 3
setblock ~39~42~16 minecraft:stone 0
setblock ~39~43~16 minecraft:log 0
setblock ~39~44~16 minecraft:stonebrick 0
setblock ~39~45~16 minecraft:stonebrick 2
fill ~39~46~16 ~39~48~16 minecraft:stone 0
setblock ~39~66~16 minecraft:crafting_table
setblock ~39~70~16 minecraft:stone_block_slab 3
setblock ~39~74~16 minecraft:stone_stairs 7
setblock ~39~76~16 minecraft:stonebrick 0
fill ~39~77~16 ~39~78~16 minecraft:cobblestone_wall 0
fill ~40~42~16 ~41~42~16 minecraft:log 0
fill ~40~43~16 ~40~44~16 minecraft:stone 0
setblock ~40~46~16 minecraft:torch 3
setblock ~40~48~16 minecraft:oak_stairs 7
fill ~40~49~16 ~40~49~20 minecraft:stone 0
setblock ~40~72~16 minecraft:stonebrick 0
setblock ~40~74~16 minecraft:stonebrick 0
setblock ~41~44~16 minecraft:stone_block_slab 3
fill ~41~50~16 ~43~50~16 minecraft:stone 0
fill ~42~22~16 ~43~22~16 minecraft:stone 0
fill ~42~41~16 ~42~42~16 minecraft:leaves 0
setblock ~42~44~16 minecraft:stone 0
setblock ~42~72~16 minecraft:stonebrick 0
setblock ~42~74~16 minecraft:stonebrick 0
setblock ~42~79~16 minecraft:stone_brick_stairs 6
fill ~42~80~16 ~45~80~16 minecraft:stone_block_slab 5
setblock ~42~81~16 minecraft:stonebrick 0
setblock ~42~82~16 minecraft:stone_block_slab 5
setblock ~43~44~16 minecraft:stonebrick 0
setblock ~43~65~16 minecraft:stone_brick_stairs 2
setblock ~43~67~16 minecraft:torch 1
setblock ~43~74~16 minecraft:stone_stairs 7
setblock ~43~81~16 minecraft:stone_brick_stairs 1
setblock ~44~21~16 minecraft:stone 0
setblock ~44~44~16 minecraft:stone 0
fill ~44~51~16 ~44~51~18 minecraft:stone 0
fill ~44~62~16 ~44~63~16 minecraft:double_stone_block_slab 0
setblock ~44~64~16 minecraft:stone_brick_stairs 2
setblock ~44~81~16 minecraft:stone_brick_stairs 0
setblock ~45~79~16 minecraft:stone_brick_stairs 6
setblock ~45~81~16 minecraft:stonebrick 0
setblock ~45~82~16 minecraft:stone_block_slab 5
setblock ~46~44~16 minecraft:stone 0
setblock ~46~66~16 minecraft:cobblestone_wall 0
setblock ~46~67~16 minecraft:cobblestone_wall 0
setblock ~47~44~16 minecraft:stonebrick 2
fill ~47~51~16 ~47~51~18 minecraft:stone 0
fill ~48~45~16 ~48~45~18 minecraft:stone_block_slab 3
setblock ~49~45~16 minecraft:double_stone_block_slab 0
setblock ~50~45~16 minecraft:stonebrick 2
fill ~50~51~16 ~50~51~18 minecraft:stone 0
setblock ~51~45~16 minecraft:stonebrick 0
setblock ~52~40~16 minecraft:stone 0
setblock ~52~45~16 minecraft:stone 0
fill ~52~54~16 ~53~54~17 minecraft:stone 0
fill ~53~25~16 ~53~25~17 minecraft:stone 0
fill ~53~39~16 ~54~39~16 minecraft:stone 0
fill ~53~41~16 ~53~41~18 minecraft:stone 0
setblock ~53~45~16 minecraft:double_stone_block_slab 0
setblock ~53~46~16 minecraft:chest 4
setblock ~53~55~16 minecraft:stone 0
fill ~54~26~16 ~55~26~16 minecraft:stone 0
setblock ~54~38~16 minecraft:stone 0
setblock ~54~46~16 minecraft:cobblestone_wall 0
setblock ~54~53~16 minecraft:leaves 0
fill ~54~57~16 ~54~58~16 minecraft:stone 0
setblock ~54~59~16 minecraft:torch 5
setblock ~54~66~16 minecraft:cobblestone_wall 0
setblock ~54~67~16 minecraft:cobblestone_wall 0
setblock ~55~37~16 minecraft:stone 0
setblock ~55~57~16 minecraft:leaves 0
fill ~55~59~16 ~56~59~16 minecraft:stone 0
setblock ~55~60~16 minecraft:stone 0
setblock ~55~79~16 minecraft:stone_brick_stairs 6
fill ~55~80~16 ~58~80~16 minecraft:stone_block_slab 5
setblock ~55~81~16 minecraft:stonebrick 0
setblock ~55~82~16 minecraft:stone_block_slab 5
setblock ~56~36~16 minecraft:stone 0
setblock ~56~56~16 minecraft:leaves 0
fill ~56~60~16 ~56~61~16 minecraft:double_stone_block_slab 0
fill ~56~62~16 ~57~62~16 minecraft:stone_brick_stairs 2
setblock ~56~81~16 minecraft:stone_brick_stairs 1
fill ~57~35~16 ~58~35~16 minecraft:stone 0
setblock ~57~60~16 minecraft:stone 0
setblock ~57~61~16 minecraft:double_stone_block_slab 0
setblock ~57~81~16 minecraft:stone_brick_stairs 0
setblock ~58~79~16 minecraft:stone_brick_stairs 6
setblock ~58~81~16 minecraft:stonebrick 0
setblock ~58~82~16 minecraft:stone_block_slab 5
setblock ~59~34~16 minecraft:stone 0
fill ~59~38~16 ~60~38~18 minecraft:leaves 2
fill ~59~39~16 ~60~39~17 minecraft:leaves 2
setblock ~60~36~16 minecraft:torch 2
fill ~60~40~16 ~60~41~16 minecraft:leaves 2
fill ~61~31~16 ~61~31~17 minecraft:stone 0
fill ~61~34~16 ~61~34~20 minecraft:stone 0
fill ~61~35~16 ~61~40~16 minecraft:log 2
setblock ~62~36~16 minecraft:torch 1
fill ~62~38~16 ~62~39~18 minecraft:leaves 2
fill ~62~40~16 ~62~40~17 minecraft:leaves 2
setblock ~62~41~16 minecraft:leaves 2
fill ~63~32~16 ~63~32~17 minecraft:stone 0
fill ~15~32~17 ~15~32~18 minecraft:stone 0
setblock ~16~41~17 minecraft:stone_stairs 6
fill ~16~42~17 ~16~43~17 minecraft:stonebrick 0
setblock ~16~44~17 minecraft:stone_brick_stairs 3
fill ~17~33~17 ~18~38~17 minecraft:stonebrick 0
fill ~17~39~17 ~17~41~17 minecraft:stonebrick 0
setblock ~17~43~17 minecraft:wooden_slab 0
setblock ~17~44~17 minecraft:torch 3
fill ~18~29~17 ~18~29~18 minecraft:stone 0
fill ~18~43~17 ~21~43~17 minecraft:oak_stairs 3
fill ~19~28~17 ~20~28~19 minecraft:stone 0
setblock ~19~32~17 minecraft:stone 0
fill ~19~39~17 ~19~39~18 minecraft:stonebrick 0
setblock ~19~40~17 minecraft:stonebrick 0
setblock ~20~35~17 minecraft:torch 4
setblock ~20~38~17 minecraft:torch 4
fill ~20~41~17 ~22~41~17 minecraft:stonebrick 0
fill ~21~27~17 ~21~27~19 minecraft:stone 0
fill ~22~26~17 ~23~26~17 minecraft:stone 0
setblock ~22~40~17 minecraft:stone_block_slab 8
setblock ~22~43~17 minecraft:wooden_slab 8
fill ~23~32~17 ~23~32~19 minecraft:stone 0
setblock ~23~42~17 minecraft:stone_stairs 5
fill ~23~43~17 ~23~44~17 minecraft:stonebrick 0
setblock ~23~45~17 minecraft:stone_brick_stairs 0
fill ~24~25~17 ~25~25~17 minecraft:stone 0
fill ~25~24~17 ~26~24~18 minecraft:stone 0
fill ~25~33~17 ~25~33~19 minecraft:stone 0
setblock ~26~68~17 minecraft:torch 2
setblock ~26~74~17 minecraft:torch 2
setblock ~26~87~17 minecraft:torch 2
setblock ~26~91~17 minecraft:stone_block_slab 13
fill ~26~92~17 ~26~95~17 minecraft:stonebrick 0
setblock ~26~97~17 minecraft:log 0
setblock ~26~98~17 minecraft:torch 2
fill ~27~23~17 ~27~23~18 minecraft:stone 0
fill ~27~34~17 ~28~34~17 minecraft:stone 0
fill ~27~55~17 ~27~55~20 minecraft:leaves 0
setblock ~27~74~17 minecraft:stonebrick 0
setblock ~27~75~17 minecraft:stone_brick_stairs 0
setblock ~27~80~17 minecraft:torch 2
setblock ~27~86~17 minecraft:stone_brick_stairs 4
setblock ~27~87~17 minecraft:stonebrick 0
setblock ~27~98~17 minecraft:log 0
fill ~28~54~17 ~28~54~23 minecraft:leaves 0
setblock ~28~81~17 minecraft:stone_brick_stairs 0
setblock ~28~84~17 minecraft:stone_brick_stairs 4
fill ~28~85~17 ~28~86~18 minecraft:stonebrick 0
fill ~29~35~17 ~29~36~17 minecraft:stone 0
setblock ~29~53~17 minecraft:leaves 0
fill ~29~67~17 ~30~67~17 minecraft:stone_block_slab 11
fill ~29~71~17 ~30~71~17 minecraft:stone_block_slab 11
fill ~29~75~17 ~30~75~17 minecraft:stone_block_slab 11
fill ~29~100~17 ~29~101~17 minecraft:log 0
setblock ~29~102~17 minecraft:torch 5
fill ~30~21~17 ~36~21~17 minecraft:stone 0
fill ~30~37~17 ~31~38~17 minecraft:stone 0
fill ~30~51~17 ~31~54~17 minecraft:stone 0
setblock ~30~55~17 minecraft:leaves 0
setblock ~30~69~17 minecraft:torch 2
setblock ~30~73~17 minecraft:torch 2
setblock ~30~77~17 minecraft:torch 2
setblock ~30~79~17 minecraft:stone_block_slab 3
setblock ~30~81~17 minecraft:torch 2
setblock ~30~83~17 minecraft:stone_block_slab 3
setblock ~30~85~17 minecraft:torch 2
setblock ~30~87~17 minecraft:stone_block_slab 3
setblock ~30~89~17 minecraft:torch 2
setblock ~30~91~17 minecraft:stone_block_slab 3
setblock ~30~94~17 minecraft:torch 2
fill ~30~101~17 ~30~101~18 minecraft:planks 0
fill ~30~102~17 ~30~103~17 minecraft:log 0
fill ~31~45~17 ~31~45~22 minecraft:leaves 0
fill ~31~50~17 ~31~50~18 minecraft:stone 0
fill ~31~56~17 ~32~56~17 minecraft:stone 0
fill ~31~57~17 ~31~57~18 minecraft:stone 0
setblock ~31~58~17 minecraft:stone 0
fill ~31~66~17 ~31~101~17 minecraft:log 0
setblock ~31~103~17 minecraft:planks 0
fill ~31~104~17 ~31~105~17 minecraft:log 0
fill ~31~106~17 ~31~107~17 minecraft:cobblestone_wall 0
fill ~32~38~17 ~33~38~17 minecraft:stone 0
setblock ~32~44~17 minecraft:leaves 0
fill ~32~46~17 ~32~46~18 minecraft:leaves 0
setblock ~32~49~17 minecraft:stone 0
setblock ~32~67~17 minecraft:torch 1
fill ~32~69~17 ~33~69~17 minecraft:stone_block_slab 11
setblock ~32~71~17 minecraft:torch 1
fill ~32~73~17 ~33~73~17 minecraft:stone_block_slab 11
setblock ~32~75~17 minecraft:torch 1
setblock ~32~77~17 minecraft:stone_block_slab 3
setblock ~32~79~17 minecraft:torch 1
setblock ~32~81~17 minecraft:stone_block_slab 3
setblock ~32~83~17 minecraft:torch 1
setblock ~32~85~17 minecraft:stone_block_slab 3
setblock ~32~87~17 minecraft:torch 1
setblock ~32~89~17 minecraft:stone_block_slab 3
setblock ~32~91~17 minecraft:torch 1
setblock ~32~94~17 minecraft:torch 1
fill ~32~101~17 ~32~101~18 minecraft:planks 0
fill ~32~102~17 ~32~103~17 minecraft:log 0
fill ~33~43~17 ~33~43~19 minecraft:leaves 0
setblock ~33~47~17 minecraft:stone 0
fill ~33~100~17 ~33~101~17 minecraft:log 0
setblock ~33~102~17 minecraft:torch 5
fill ~34~39~17 ~35~39~17 minecraft:stone 0
fill ~34~46~17 ~35~46~17 minecraft:stone 0
fill ~34~65~17 ~34~65~18 minecraft:stone_block_slab 8
setblock ~34~81~17 minecraft:stone_brick_stairs 1
setblock ~34~84~17 minecraft:stone_brick_stairs 5
fill ~34~85~17 ~34~86~18 minecraft:stonebrick 0
fill ~35~43~17 ~35~44~17 minecraft:leaves 0
fill ~35~45~17 ~36~45~17 minecraft:log 0
fill ~35~66~17 ~35~68~18 minecraft:stonebrick 0
setblock ~35~74~17 minecraft:stonebrick 0
setblock ~35~75~17 minecraft:stone_brick_stairs 1
setblock ~35~80~17 minecraft:torch 1
setblock ~35~86~17 minecraft:stone_brick_stairs 5
setblock ~35~87~17 minecraft:stonebrick 0
setblock ~35~98~17 minecraft:log 0
fill ~36~40~17 ~36~41~17 minecraft:stone 0
fill ~36~65~17 ~36~65~18 minecraft:stone_block_slab 11
fill ~36~66~17 ~36~66~18 minecraft:log 0
fill ~36~67~17 ~36~67~18 minecraft:stone_block_slab 0
setblock ~36~69~17 minecraft:wooden_slab 8
setblock ~36~87~17 minecraft:torch 1
setblock ~36~91~17 minecraft:stone_block_slab 13
fill ~36~92~17 ~36~95~17 minecraft:stonebrick 0
setblock ~36~97~17 minecraft:log 0
setblock ~36~98~17 minecraft:torch 1
fill ~37~20~17 ~39~20~17 minecraft:stone 0
setblock ~37~41~17 minecraft:stone 0
fill ~37~43~17 ~39~43~17 minecraft:stone 0
fill ~37~44~17 ~37~47~17 minecraft:stone 0
setblock ~37~65~17 minecraft:stonebrick 3
setblock ~37~69~17 minecraft:stone_block_slab 11
setblock ~37~70~17 minecraft:torch 5
setblock ~38~42~17 minecraft:stone 0
setblock ~38~44~17 minecraft:double_stone_block_slab 0
fill ~38~45~17 ~38~48~17 minecraft:stone 0
setblock ~38~65~17 minecraft:stone_brick_stairs 2
setblock ~38~69~17 minecraft:wooden_slab 8
fill ~39~49~17 ~39~49~20 minecraft:stone 0
setblock ~39~65~17 minecraft:cobblestone
setblock ~39~69~17 minecraft:stone_block_slab 11
setblock ~39~70~17 minecraft:torch 5
fill ~40~21~17 ~43~21~17 minecraft:stone 0
setblock ~40~43~17 minecraft:stonebrick 0
setblock ~40~65~17 minecraft:stone_block_slab 11
setblock ~40~66~17 minecraft:log 0
setblock ~40~67~17 minecraft:stone_block_slab 0
setblock ~40~69~17 minecraft:wooden_slab 8
setblock ~40~74~17 minecraft:stone_stairs 4
setblock ~40~75~17 minecraft:stone_block_slab 13
setblock ~40~76~17 minecraft:stone_brick_stairs 3
setblock ~41~43~17 minecraft:stone 0
fill ~41~50~17 ~42~50~18 minecraft:stone 0
fill ~41~67~17 ~41~75~17 minecraft:stonebrick 0
setblock ~41~79~17 minecraft:stone_brick_stairs 4
fill ~41~80~17 ~41~80~20 minecraft:stone_block_slab 5
setblock ~41~81~17 minecraft:stonebrick 0
setblock ~41~82~17 minecraft:stone_block_slab 5
fill ~42~44~17 ~42~44~18 minecraft:stone_block_slab 3
setblock ~42~75~17 minecraft:stone_block_slab 8
setblock ~42~77~17 minecraft:stone_block_slab 8
fill ~42~78~17 ~45~78~20 minecraft:stonebrick 0
fill ~42~80~17 ~42~81~17 minecraft:double_stone_block_slab 0
setblock ~42~82~17 minecraft:cobblestone_wall 0
setblock ~42~83~17 minecraft:cobblestone_wall 0
fill ~43~44~17 ~43~44~18 minecraft:stone 0
fill ~43~51~17 ~43~51~18 minecraft:stone 0
fill ~43~66~17 ~44~77~17 minecraft:stonebrick 0
fill ~43~79~17 ~44~79~17 minecraft:stonebrick 0
setblock ~43~81~17 minecraft:torch 1
fill ~44~20~17 ~45~20~19 minecraft:stone 0
setblock ~44~44~17 minecraft:stone_stairs 2
fill ~44~63~17 ~44~65~17 minecraft:stonebrick 0
setblock ~44~81~17 minecraft:torch 2
fill ~45~44~17 ~45~44~18 minecraft:stone 0
setblock ~45~62~17 minecraft:double_stone_block_slab 0
setblock ~45~63~17 minecraft:stone_brick_stairs 2
setblock ~45~69~17 minecraft:torch 4
setblock ~45~75~17 minecraft:torch 4
setblock ~45~77~17 minecraft:stone_block_slab 8
fill ~45~80~17 ~45~81~17 minecraft:double_stone_block_slab 0
setblock ~45~82~17 minecraft:cobblestone_wall 0
setblock ~45~83~17 minecraft:cobblestone_wall 0
setblock ~46~44~17 minecraft:double_stone_block_slab 0
setblock ~46~67~17 minecraft:cobblestone_wall 0
setblock ~46~68~17 minecraft:cobblestone_wall 0
setblock ~46~79~17 minecraft:stone_brick_stairs 5
fill ~46~80~17 ~46~80~20 minecraft:stone_block_slab 5
setblock ~46~81~17 minecraft:stonebrick 0
setblock ~46~82~17 minecraft:stone_block_slab 5
fill ~47~44~17 ~47~44~18 minecraft:stone 0
fill ~49~23~17 ~49~23~18 minecraft:stone 0
setblock ~49~45~17 minecraft:stonebrick 0
fill ~49~50~17 ~49~50~18 minecraft:log 0
setblock ~50~45~17 minecraft:stone 0
fill ~51~24~17 ~51~24~18 minecraft:stone 0
setblock ~51~45~17 minecraft:stone_stairs 0
fill ~51~52~17 ~51~52~19 minecraft:stone 0
setblock ~52~45~17 minecraft:stonebrick 0
fill ~52~55~17 ~52~55~18 minecraft:torch 5
fill ~53~40~17 ~53~40~18 minecraft:stone 0
setblock ~53~45~17 minecraft:stone 0
setblock ~53~46~17 minecraft:cobblestone_wall 0
fill ~53~55~17 ~53~55~18 minecraft:log 0
fill ~54~25~17 ~54~25~19 minecraft:stone 0
fill ~54~39~17 ~54~39~18 minecraft:stone 0
fill ~54~43~17 ~54~43~19 minecraft:stone 0
setblock ~54~46~17 minecraft:cobblestone_wall 0
fill ~54~56~17 ~54~56~20 minecraft:stone 0
setblock ~54~67~17 minecraft:cobblestone_wall 0
setblock ~54~68~17 minecraft:cobblestone_wall 0
setblock ~54~79~17 minecraft:stone_brick_stairs 4
fill ~54~80~17 ~54~80~20 minecraft:stone_block_slab 5
setblock ~54~81~17 minecraft:stonebrick 0
setblock ~54~82~17 minecraft:stone_block_slab 5
fill ~55~26~17 ~55~26~18 minecraft:stone 0
fill ~55~38~17 ~56~38~17 minecraft:stone 0
fill ~55~53~17 ~55~54~18 minecraft:leaves 0
setblock ~55~56~17 minecraft:leaves 0
fill ~55~57~17 ~55~58~17 minecraft:stone 0
setblock ~55~61~17 minecraft:double_stone_block_slab 0
setblock ~55~62~17 minecraft:stone_brick_stairs 2
setblock ~55~69~17 minecraft:torch 4
setblock ~55~75~17 minecraft:torch 4
setblock ~55~77~17 minecraft:stone_block_slab 8
fill ~55~78~17 ~58~78~20 minecraft:stonebrick 0
fill ~55~79~17 ~58~79~17 minecraft:stonebrick 0
fill ~55~80~17 ~55~81~17 minecraft:double_stone_block_slab 0
setblock ~55~82~17 minecraft:cobblestone_wall 0
setblock ~55~83~17 minecraft:cobblestone_wall 0
setblock ~56~37~17 minecraft:stone 0
fill ~56~54~17 ~56~54~18 minecraft:leaves 0
setblock ~56~58~17 minecraft:stone 0
fill ~56~62~17 ~57~77~17 minecraft:stonebrick 0
setblock ~56~81~17 minecraft:torch 1
setblock ~57~36~17 minecraft:stone 0
setblock ~57~59~17 minecraft:stone 0
setblock ~57~81~17 minecraft:torch 2
fill ~58~35~17 ~59~35~17 minecraft:stone 0
setblock ~58~60~17 minecraft:stone 0
setblock ~58~61~17 minecraft:double_stone_block_slab 0
setblock ~58~62~17 minecraft:stone_brick_stairs 2
setblock ~58~75~17 minecraft:torch 4
setblock ~58~77~17 minecraft:stone_block_slab 8
fill ~58~80~17 ~58~81~17 minecraft:double_stone_block_slab 0
setblock ~58~82~17 minecraft:cobblestone_wall 0
setblock ~58~83~17 minecraft:cobblestone_wall 0
setblock ~59~79~17 minecraft:stone_brick_stairs 5
fill ~59~80~17 ~59~80~20 minecraft:stone_block_slab 5
setblock ~59~81~17 minecraft:stonebrick 0
setblock ~59~82~17 minecraft:stone_block_slab 5
setblock ~61~36~17 minecraft:torch 3
fill ~61~38~17 ~61~39~18 minecraft:leaves 2
setblock ~61~40~17 minecraft:leaves 2
fill ~62~31~17 ~62~31~18 minecraft:stone 0
fill ~62~34~17 ~62~34~19 minecraft:stone 0
fill ~63~33~17 ~64~33~20 minecraft:stone 0
fill ~12~30~18 ~15~30~18 minecraft:stone 0
fill ~13~31~18 ~13~32~18 minecraft:stone 0
fill ~14~32~18 ~14~32~25 minecraft:stone 0
setblock ~15~40~18 minecraft:stone_block_slab 11
fill ~15~41~18 ~16~41~18 minecraft:stonebrick 0
setblock ~15~42~18 minecraft:stonebrick 0
setblock ~15~43~18 minecraft:stone_brick_stairs 3
fill ~16~31~18 ~16~40~18 minecraft:stonebrick 0
fill ~16~42~18 ~20~42~18 minecraft:wooden_slab 8
fill ~19~33~18 ~21~38~18 minecraft:stonebrick 0
fill ~20~39~18 ~21~40~18 minecraft:stonebrick 0
setblock ~21~32~18 minecraft:stonebrick 0
fill ~21~41~18 ~21~41~19 minecraft:stonebrick 0
setblock ~21~43~18 minecraft:wooden_slab 0
setblock ~22~26~18 minecraft:stone 0
setblock ~22~27~18 minecraft:torch 5
fill ~22~32~18 ~22~32~20 minecraft:stone 0
setblock ~22~41~18 minecraft:stone_stairs 6
fill ~22~42~18 ~22~43~18 minecraft:stonebrick 0
setblock ~22~44~18 minecraft:stone_brick_stairs 3
fill ~23~25~18 ~23~25~19 minecraft:stone 0
fill ~24~24~18 ~24~24~19 minecraft:stone 0
fill ~25~65~18 ~25~65~20 minecraft:stone 0
fill ~26~34~18 ~27~34~18 minecraft:stone 0
setblock ~26~66~18 minecraft:double_stone_block_slab 0
setblock ~26~92~18 minecraft:stone_brick_stairs 0
setblock ~26~94~18 minecraft:torch 3
setblock ~26~95~18 minecraft:stone_brick_stairs 4
setblock ~26~97~18 minecraft:oak_stairs 0
fill ~27~22~18 ~28~22~18 minecraft:stone 0
fill ~27~54~18 ~27~54~21 minecraft:leaves 0
fill ~27~62~18 ~27~62~20 minecraft:stone 0
setblock ~27~74~18 minecraft:stone_brick_stairs 3
setblock ~27~87~18 minecraft:stone_block_slab 13
setblock ~27~98~18 minecraft:oak_stairs 0
fill ~28~21~18 ~31~21~18 minecraft:stone 0
fill ~28~35~18 ~28~36~18 minecraft:stone 0
fill ~28~53~18 ~28~53~34 minecraft:leaves 0
fill ~28~61~18 ~28~61~20 minecraft:stone 0
fill ~28~81~18 ~28~84~18 minecraft:stonebrick 0
setblock ~28~87~18 minecraft:stonebrick 0
setblock ~28~98~18 minecraft:planks 0
setblock ~29~37~18 minecraft:stone 0
fill ~29~52~18 ~29~53~20 minecraft:stone 0
fill ~29~68~18 ~30~68~18 minecraft:stone_block_slab 3
fill ~29~72~18 ~30~72~18 minecraft:stone_block_slab 3
fill ~29~75~18 ~29~75~20 minecraft:stonebrick 0
setblock ~29~100~18 minecraft:planks 0
setblock ~29~101~18 minecraft:wooden_slab 0
fill ~30~38~18 ~30~39~18 minecraft:stone 0
setblock ~30~45~18 minecraft:leaves 0
fill ~30~51~18 ~30~51~22 minecraft:stone 0
setblock ~30~54~18 minecraft:stone 0
setblock ~30~55~18 minecraft:log 0
fill ~30~58~18 ~30~59~18 minecraft:stone 0
setblock ~30~75~18 minecraft:stone_block_slab 13
setblock ~30~79~18 minecraft:stone_block_slab 11
setblock ~30~83~18 minecraft:stone_block_slab 11
setblock ~30~87~18 minecraft:stone_block_slab 11
fill ~30~91~18 ~31~91~18 minecraft:stone_block_slab 11
setblock ~30~102~18 minecraft:planks 0
fill ~31~39~18 ~33~39~18 minecraft:stone 0
fill ~31~44~18 ~31~44~21 minecraft:leaves 0
setblock ~31~46~18 minecraft:leaves 0
setblock ~31~47~18 minecraft:torch 2
fill ~31~49~18 ~31~49~22 minecraft:stone 0
setblock ~31~51~18 minecraft:torch 5
setblock ~31~55~18 minecraft:leaves 0
setblock ~31~56~18 minecraft:stone 0
fill ~31~68~18 ~31~68~19 minecraft:stone_block_slab 11
setblock ~31~70~18 minecraft:torch 3
fill ~31~72~18 ~31~72~19 minecraft:stone_block_slab 11
setblock ~31~74~18 minecraft:torch 3
setblock ~31~76~18 minecraft:stone_block_slab 3
setblock ~31~78~18 minecraft:torch 3
setblock ~31~80~18 minecraft:stone_block_slab 3
setblock ~31~82~18 minecraft:torch 3
setblock ~31~84~18 minecraft:stone_block_slab 3
setblock ~31~86~18 minecraft:torch 3
setblock ~31~88~18 minecraft:stone_block_slab 3
setblock ~31~90~18 minecraft:torch 3
setblock ~31~94~18 minecraft:torch 3
setblock ~31~101~18 minecraft:planks 0
setblock ~31~103~18 minecraft:log 0
fill ~32~20~18 ~36~20~18 minecraft:stone 0
fill ~32~45~18 ~33~45~18 minecraft:leaves 0
fill ~32~47~18 ~32~47~24 minecraft:stone 0
setblock ~32~48~18 minecraft:stone 0
fill ~32~69~18 ~33~69~18 minecraft:stone_block_slab 3
fill ~32~73~18 ~33~73~18 minecraft:stone_block_slab 3
setblock ~32~76~18 minecraft:stone_block_slab 11
setblock ~32~80~18 minecraft:stone_block_slab 11
setblock ~32~84~18 minecraft:stone_block_slab 11
setblock ~32~88~18 minecraft:stone_block_slab 11
setblock ~32~102~18 minecraft:planks 0
fill ~33~40~18 ~35~40~18 minecraft:stone 0
fill ~33~44~18 ~33~44~19 minecraft:leaves 0
setblock ~33~46~18 minecraft:stone 0
setblock ~33~100~18 minecraft:planks 0
setblock ~33~101~18 minecraft:wooden_slab 0
fill ~34~19~18 ~39~19~18 minecraft:stone 0
setblock ~34~45~18 minecraft:log 0
fill ~34~81~18 ~34~84~18 minecraft:stonebrick 0
setblock ~34~87~18 minecraft:stonebrick 0
setblock ~34~98~18 minecraft:planks 0
setblock ~35~41~18 minecraft:stone 0
fill ~35~45~18 ~35~45~19 minecraft:stone 0
setblock ~35~74~18 minecraft:stone_brick_stairs 3
setblock ~35~87~18 minecraft:stone_block_slab 13
setblock ~35~98~18 minecraft:oak_stairs 1
fill ~36~42~18 ~37~42~18 minecraft:stone 0
fill ~36~43~18 ~36~44~18 minecraft:stone 0
setblock ~36~45~18 minecraft:stonebrick 2
fill ~36~46~18 ~36~47~18 minecraft:stone 0
setblock ~36~69~18 minecraft:wooden_slab 0
setblock ~36~92~18 minecraft:stone_brick_stairs 1
setblock ~36~94~18 minecraft:torch 3
setblock ~36~95~18 minecraft:stone_brick_stairs 5
fill ~36~97~18 ~36~97~19 minecraft:oak_stairs 1
setblock ~37~43~18 minecraft:stonebrick 0
fill ~37~48~18 ~38~48~18 minecraft:stone 0
setblock ~37~65~18 minecraft:cobblestone
setblock ~37~66~18 minecraft:trapdoor 1
setblock ~37~69~18 minecraft:stone_stairs 3
setblock ~38~18~18 minecraft:stone 0
fill ~38~43~18 ~39~43~18 minecraft:stone_block_slab 3
setblock ~38~65~18 minecraft:stonebrick 3
fill ~38~66~18 ~39~66~18 minecraft:wooden_slab 8
setblock ~38~67~18 minecraft:stone_pressure_plate 0
setblock ~38~69~18 minecraft:wooden_slab 0
setblock ~39~20~18 minecraft:torch 5
setblock ~39~65~18 minecraft:stone 0
setblock ~39~67~18 minecraft:torch 5
setblock ~39~69~18 minecraft:stone_stairs 3
fill ~40~20~18 ~43~20~18 minecraft:stone 0
setblock ~40~43~18 minecraft:stone 0
setblock ~40~65~18 minecraft:cobblestone
setblock ~40~66~18 minecraft:oak_stairs 4
setblock ~40~67~18 minecraft:cobblestone_wall 0
setblock ~40~68~18 minecraft:cobblestone_wall 0
setblock ~40~69~18 minecraft:wooden_slab 0
setblock ~41~43~18 minecraft:stonebrick 2
fill ~41~65~18 ~41~65~19 minecraft:stone_block_slab 11
fill ~41~66~18 ~41~66~19 minecraft:log 0
fill ~41~67~18 ~41~67~19 minecraft:stone_block_slab 0
setblock ~41~73~18 minecraft:stone_stairs 4
setblock ~41~74~18 minecraft:cobblestone
setblock ~41~75~18 minecraft:stone_block_slab 13
setblock ~41~81~18 minecraft:stone_brick_stairs 3
