fill ~33~43~1 ~35~43~1 minecraft:dirt 0
fill ~33~44~1 ~36~44~1 minecraft:stained_hardened_clay 13
fill ~33~45~1 ~34~45~1 minecraft:grass
setblock ~34~42~1 minecraft:stained_hardened_clay 5
setblock ~35~42~1 minecraft:stained_hardened_clay 9
setblock ~35~45~1 minecraft:stained_hardened_clay 13
setblock ~35~46~1 minecraft:stained_hardened_clay 5
setblock ~36~42~1 minecraft:stone 5
fill ~36~43~1 ~36~43~2 minecraft:stained_hardened_clay 5
setblock ~36~45~1 minecraft:stained_hardened_clay 5
setblock ~36~46~1 minecraft:grass
fill ~37~42~1 ~37~42~3 minecraft:stained_hardened_clay 9
setblock ~37~43~1 minecraft:stained_hardened_clay 9
setblock ~37~44~1 minecraft:stained_hardened_clay 5
fill ~37~45~1 ~37~46~1 minecraft:stained_hardened_clay 13
fill ~38~43~1 ~38~44~1 minecraft:stone 5
setblock ~38~45~1 minecraft:stained_hardened_clay 5
fill ~31~43~2 ~31~44~2 minecraft:stained_hardened_clay 5
setblock ~32~41~2 minecraft:stained_hardened_clay 9
fill ~32~42~2 ~32~44~2 minecraft:stained_hardened_clay 13
fill ~32~45~2 ~32~45~3 minecraft:stained_hardened_clay 5
setblock ~32~46~2 minecraft:grass
fill ~33~40~2 ~34~40~2 minecraft:stained_hardened_clay 9
fill ~33~41~2 ~37~41~2 minecraft:stone 5
setblock ~33~42~2 minecraft:grass
fill ~33~43~2 ~33~43~5 minecraft:dirt 0
setblock ~33~44~2 minecraft:grass
fill ~33~45~2 ~34~45~3 minecraft:dirt 0
fill ~33~46~2 ~34~46~2 minecraft:dirt 0
fill ~33~47~2 ~34~47~2 minecraft:stained_hardened_clay 5
setblock ~34~42~2 minecraft:dirt 0
fill ~34~43~2 ~34~44~2 minecraft:stained_hardened_clay 13
fill ~35~42~2 ~35~43~3 minecraft:stained_hardened_clay 5
setblock ~35~44~2 minecraft:stained_hardened_clay 13
setblock ~35~45~2 minecraft:stained_hardened_clay 5
fill ~35~46~2 ~35~47~2 minecraft:grass
fill ~36~42~2 ~36~42~8 minecraft:stained_hardened_clay 9
setblock ~36~44~2 minecraft:grass
fill ~36~45~2 ~37~45~2 minecraft:dirt 0
fill ~36~46~2 ~39~46~2 minecraft:stained_hardened_clay 5
setblock ~36~47~2 minecraft:stained_hardened_clay 5
fill ~37~43~2 ~37~43~4 minecraft:stone 5
setblock ~37~44~2 minecraft:dirt 0
fill ~37~47~2 ~37~47~3 minecraft:stained_hardened_clay 13
fill ~38~41~2 ~38~41~6 minecraft:stained_hardened_clay 9
fill ~38~42~2 ~38~43~3 minecraft:stained_hardened_clay 9
fill ~38~44~2 ~38~44~3 minecraft:stained_hardened_clay 13
setblock ~38~45~2 minecraft:stained_hardened_clay 13
setblock ~38~47~2 minecraft:grass
fill ~39~42~2 ~39~42~3 minecraft:stone 5
setblock ~39~43~2 minecraft:stone 5
setblock ~39~44~2 minecraft:stained_hardened_clay 9
setblock ~39~45~2 minecraft:stained_hardened_clay 5
fill ~30~43~3 ~31~43~3 minecraft:dirt 0
setblock ~30~44~3 minecraft:grass
setblock ~31~42~3 minecraft:stained_hardened_clay 13
fill ~31~44~3 ~31~44~4 minecraft:dirt 0
setblock ~31~45~3 minecraft:stained_hardened_clay 5
fill ~32~40~3 ~32~41~4 minecraft:stone 5
fill ~32~42~3 ~32~44~3 minecraft:stained_hardened_clay 5
fill ~32~46~3 ~33~46~3 minecraft:dirt 0
fill ~32~47~3 ~33~47~3 minecraft:grass
fill ~33~40~3 ~33~41~3 minecraft:stained_hardened_clay 9
setblock ~33~42~3 minecraft:dirt 0
fill ~33~44~3 ~33~44~4 minecraft:dirt 0
fill ~34~39~3 ~34~40~3 minecraft:stone 5
fill ~34~41~3 ~35~41~3 minecraft:stained_hardened_clay 9
fill ~34~42~3 ~34~42~5 minecraft:stained_hardened_clay 5
fill ~34~43~3 ~34~44~3 minecraft:stained_hardened_clay 5
fill ~34~46~3 ~35~47~3 minecraft:stained_hardened_clay 5
setblock ~34~48~3 minecraft:stained_hardened_clay 13
fill ~35~40~3 ~36~40~3 minecraft:stone 5
fill ~35~44~3 ~36~44~3 minecraft:dirt 0
setblock ~35~45~3 minecraft:stained_hardened_clay 13
setblock ~35~48~3 minecraft:grass
setblock ~36~41~3 minecraft:stone 5
setblock ~36~43~3 minecraft:stained_hardened_clay 13
fill ~36~45~3 ~38~45~3 minecraft:stained_hardened_clay 5
fill ~36~46~3 ~37~46~3 minecraft:stained_hardened_clay 13
fill ~36~47~3 ~36~48~3 minecraft:stained_hardened_clay 13
fill ~37~40~3 ~37~40~4 minecraft:stained_hardened_clay 9
setblock ~37~41~3 minecraft:stained_hardened_clay 9
setblock ~37~44~3 minecraft:stained_hardened_clay 5
fill ~37~48~3 ~37~48~4 minecraft:stained_hardened_clay 13
setblock ~38~40~3 minecraft:stone 5
setblock ~38~46~3 minecraft:stained_hardened_clay 5
setblock ~38~47~3 minecraft:stained_hardened_clay 13
setblock ~38~48~3 minecraft:stained_hardened_clay 5
fill ~39~41~3 ~39~41~5 minecraft:stained_hardened_clay 9
fill ~39~43~3 ~40~43~4 minecraft:stained_hardened_clay 9
setblock ~39~44~3 minecraft:stained_hardened_clay 13
fill ~39~45~3 ~40~45~3 minecraft:dirt 0
fill ~39~46~3 ~40~46~3 minecraft:grass
setblock ~39~47~3 minecraft:grass
fill ~40~42~3 ~40~42~7 minecraft:stained_hardened_clay 9
setblock ~40~44~3 minecraft:stone 5
setblock ~29~43~4 minecraft:stone 5
fill ~29~44~4 ~30~44~4 minecraft:dirt 0
setblock ~29~45~4 minecraft:stained_hardened_clay 5
setblock ~29~46~4 minecraft:stained_hardened_clay 13
setblock ~30~42~4 minecraft:stone 5
setblock ~30~43~4 minecraft:stained_hardened_clay 13
fill ~30~45~4 ~30~45~7 minecraft:dirt 0
setblock ~30~46~4 minecraft:grass
setblock ~30~47~4 minecraft:stained_hardened_clay 13
fill ~31~41~4 ~31~41~5 minecraft:stained_hardened_clay 9
setblock ~31~42~4 minecraft:stained_hardened_clay 5
fill ~31~43~4 ~32~43~4 minecraft:dirt 0
fill ~31~45~4 ~31~45~6 minecraft:stained_hardened_clay 13
fill ~31~46~4 ~32~46~4 minecraft:dirt 0
fill ~31~47~4 ~37~47~4 minecraft:stained_hardened_clay 5
fill ~32~42~4 ~33~42~4 minecraft:stained_hardened_clay 13
fill ~32~44~4 ~32~45~4 minecraft:grass
setblock ~32~48~4 minecraft:stained_hardened_clay 5
fill ~33~39~4 ~35~39~5 minecraft:stained_hardened_clay 9
fill ~33~40~4 ~33~40~5 minecraft:stone 5
fill ~33~41~4 ~35~41~4 minecraft:stone 5
fill ~33~45~4 ~33~45~5 minecraft:dirt 0
fill ~33~46~4 ~33~46~6 minecraft:stained_hardened_clay 5
fill ~33~48~4 ~33~48~6 minecraft:stained_hardened_clay 13
fill ~34~40~4 ~36~40~4 minecraft:stained_hardened_clay 9
fill ~34~43~4 ~34~43~5 minecraft:stained_hardened_clay 13
fill ~34~44~4 ~34~44~5 minecraft:stained_hardened_clay 5
fill ~34~45~4 ~36~45~4 minecraft:stained_hardened_clay 5
setblock ~34~46~4 minecraft:dirt 0
fill ~34~48~4 ~34~48~5 minecraft:stained_hardened_clay 5
fill ~35~42~4 ~35~43~4 minecraft:dirt 0
fill ~35~44~4 ~35~44~5 minecraft:stained_hardened_clay 13
setblock ~35~46~4 minecraft:stained_hardened_clay 5
fill ~35~48~4 ~35~48~10 minecraft:dirt 0
fill ~35~49~4 ~36~49~4 minecraft:grass
fill ~36~39~4 ~37~39~5 minecraft:stone 5
fill ~36~41~4 ~36~41~6 minecraft:stained_hardened_clay 9
setblock ~36~43~4 minecraft:stained_hardened_clay 5
fill ~36~44~4 ~37~44~4 minecraft:grass
setblock ~36~46~4 minecraft:stained_hardened_clay 13
setblock ~36~48~4 minecraft:stained_hardened_clay 5
fill ~37~41~4 ~37~41~5 minecraft:stone 5
fill ~37~42~4 ~38~42~4 minecraft:stone 5
fill ~37~45~4 ~40~45~4 minecraft:stained_hardened_clay 13
fill ~37~46~4 ~38~46~4 minecraft:dirt 0
setblock ~37~49~4 minecraft:stained_hardened_clay 5
fill ~38~40~4 ~39~40~4 minecraft:stained_hardened_clay 9
fill ~38~43~4 ~38~43~7 minecraft:stained_hardened_clay 9
setblock ~38~44~4 minecraft:dirt 0
setblock ~38~47~4 minecraft:dirt 0
fill ~38~48~4 ~38~48~5 minecraft:stained_hardened_clay 13
fill ~39~42~4 ~39~42~5 minecraft:stained_hardened_clay 9
setblock ~39~44~4 minecraft:stained_hardened_clay 5
setblock ~39~46~4 minecraft:grass
fill ~39~47~4 ~39~48~4 minecraft:stained_hardened_clay 5
setblock ~40~41~4 minecraft:stained_hardened_clay 9
fill ~40~44~4 ~41~44~4 minecraft:stained_hardened_clay 9
setblock ~40~46~4 minecraft:dirt 0
setblock ~40~47~4 minecraft:grass
setblock ~41~43~4 minecraft:stone 5
fill ~41~45~4 ~41~45~5 minecraft:stone 5
fill ~25~55~5 ~26~55~5 minecraft:leaves 1
fill ~26~43~5 ~28~43~7 minecraft:stone 5
setblock ~26~44~5 minecraft:stained_hardened_clay 9
setblock ~26~45~5 minecraft:grass
fill ~27~41~5 ~28~41~5 minecraft:stone 5
setblock ~27~42~5 minecraft:stone 5
setblock ~27~44~5 minecraft:stone 5
fill ~27~45~5 ~27~45~7 minecraft:stained_hardened_clay 5
fill ~27~46~5 ~27~46~7 minecraft:dirt 0
setblock ~27~47~5 minecraft:stained_hardened_clay 5
setblock ~28~40~5 minecraft:stained_hardened_clay 9
setblock ~28~42~5 minecraft:stained_hardened_clay 9
fill ~28~44~5 ~28~44~6 minecraft:stained_hardened_clay 9
fill ~28~45~5 ~28~45~6 minecraft:dirt 0
setblock ~28~46~5 minecraft:stained_hardened_clay 5
setblock ~28~47~5 minecraft:grass
fill ~29~40~5 ~29~40~9 minecraft:stone 5
fill ~29~41~5 ~30~41~5 minecraft:stained_hardened_clay 9
setblock ~29~42~5 minecraft:stone 5
fill ~29~43~5 ~29~43~7 minecraft:stained_hardened_clay 9
setblock ~29~44~5 minecraft:dirt 0
setblock ~29~45~5 minecraft:stained_hardened_clay 13
setblock ~29~46~5 minecraft:grass
fill ~29~47~5 ~29~47~7 minecraft:stained_hardened_clay 13
setblock ~29~48~5 minecraft:dirt 0
setblock ~29~49~5 minecraft:stained_hardened_clay 13
setblock ~30~40~5 minecraft:stained_hardened_clay 9
fill ~30~42~5 ~30~42~6 minecraft:stained_hardened_clay 9
fill ~30~43~5 ~31~43~5 minecraft:stained_hardened_clay 5
fill ~30~44~5 ~30~44~6 minecraft:stained_hardened_clay 13
setblock ~30~46~5 minecraft:dirt 0
fill ~30~47~5 ~30~47~6 minecraft:grass
fill ~30~48~5 ~31~48~5 minecraft:stained_hardened_clay 5
fill ~31~39~5 ~31~40~5 minecraft:stone 5
fill ~31~42~5 ~31~42~6 minecraft:stone 5
setblock ~31~44~5 minecraft:stained_hardened_clay 5
setblock ~31~46~5 minecraft:stained_hardened_clay 5
fill ~31~47~5 ~32~47~5 minecraft:dirt 0
setblock ~31~49~5 minecraft:grass
fill ~32~39~5 ~32~41~5 minecraft:stained_hardened_clay 9
setblock ~32~42~5 minecraft:stained_hardened_clay 5
setblock ~32~43~5 minecraft:glass
setblock ~32~44~5 minecraft:dirt 0
fill ~32~45~5 ~32~46~5 minecraft:stained_hardened_clay 13
setblock ~32~48~5 minecraft:grass
fill ~33~41~5 ~35~41~5 minecraft:stained_hardened_clay 9
setblock ~33~42~5 minecraft:dirt 0
setblock ~33~44~5 minecraft:stained_hardened_clay 13
setblock ~33~47~5 minecraft:stained_hardened_clay 5
fill ~33~49~5 ~34~49~5 minecraft:stained_hardened_clay 5
setblock ~33~50~5 minecraft:dirt 0
fill ~33~51~5 ~33~51~6 minecraft:stained_hardened_clay 13
setblock ~34~40~5 minecraft:stone 5
setblock ~34~45~5 minecraft:stained_hardened_clay 13
fill ~34~46~5 ~35~46~5 minecraft:grass
setblock ~34~47~5 minecraft:stained_hardened_clay 13
fill ~34~50~5 ~37~50~5 minecraft:grass
setblock ~35~38~5 minecraft:stone 5
fill ~35~40~5 ~35~40~6 minecraft:stained_hardened_clay 9
setblock ~35~42~5 minecraft:stained_hardened_clay 9
setblock ~35~43~5 minecraft:stained_hardened_clay 5
setblock ~35~45~5 minecraft:stained_hardened_clay 5
setblock ~35~47~5 minecraft:dirt 0
setblock ~35~49~5 minecraft:grass
setblock ~35~51~5 minecraft:grass
fill ~36~40~5 ~37~40~6 minecraft:stone 5
setblock ~36~43~5 minecraft:stained_hardened_clay 13
fill ~36~44~5 ~38~44~5 minecraft:stained_hardened_clay 5
setblock ~36~45~5 minecraft:stained_hardened_clay 13
fill ~36~46~5 ~36~46~6 minecraft:stained_hardened_clay 5
fill ~36~47~5 ~40~47~5 minecraft:stained_hardened_clay 13
setblock ~36~48~5 minecraft:stained_hardened_clay 13
setblock ~36~49~5 minecraft:stained_hardened_clay 5
fill ~37~42~5 ~38~42~5 minecraft:stained_hardened_clay 9
setblock ~37~43~5 minecraft:stained_hardened_clay 9
fill ~37~45~5 ~38~45~6 minecraft:stained_hardened_clay 5
setblock ~37~46~5 minecraft:dirt 0
fill ~37~48~5 ~37~49~5 minecraft:dirt 0
fill ~38~39~5 ~38~40~5 minecraft:stained_hardened_clay 9
setblock ~38~46~5 minecraft:stained_hardened_clay 5
setblock ~38~49~5 minecraft:stained_hardened_clay 5
setblock ~39~40~5 minecraft:stone 5
setblock ~39~43~5 minecraft:stone 5
setblock ~39~44~5 minecraft:dirt 0
fill ~39~45~5 ~39~45~7 minecraft:stained_hardened_clay 13
fill ~39~46~5 ~39~46~6 minecraft:dirt 0
setblock ~39~48~5 minecraft:stained_hardened_clay 13
setblock ~40~41~5 minecraft:stone 5
fill ~40~43~5 ~41~43~5 minecraft:stained_hardened_clay 9
fill ~40~44~5 ~41~44~5 minecraft:stone 5
fill ~40~45~5 ~40~45~7 minecraft:stained_hardened_clay 5
fill ~40~46~5 ~41~46~5 minecraft:grass
fill ~41~42~5 ~41~42~8 minecraft:stained_hardened_clay 9
fill ~25~42~6 ~26~42~6 minecraft:stone 5
fill ~25~43~6 ~25~44~6 minecraft:stained_hardened_clay 9
setblock ~25~45~6 minecraft:dirt 0
fill ~25~46~6 ~26~46~6 minecraft:grass
fill ~25~55~6 ~25~55~7 minecraft:leaves 1
fill ~25~57~6 ~25~57~8 minecraft:leaves 1
fill ~26~41~6 ~29~41~6 minecraft:stained_hardened_clay 9
fill ~26~44~6 ~26~44~7 minecraft:stone 5
fill ~26~45~6 ~26~45~7 minecraft:stained_hardened_clay 5
setblock ~26~47~6 minecraft:stained_hardened_clay 5
fill ~26~48~6 ~26~49~6 minecraft:stained_hardened_clay 13
setblock ~26~54~6 minecraft:leaves 1
setblock ~26~55~6 minecraft:wood 1
fill ~27~40~6 ~27~40~7 minecraft:stained_hardened_clay 9
fill ~27~42~6 ~27~42~9 minecraft:stained_hardened_clay 9
fill ~27~44~6 ~27~44~9 minecraft:stained_hardened_clay 9
setblock ~27~47~6 minecraft:stained_hardened_clay 13
fill ~27~48~6 ~28~48~6 minecraft:dirt 0
fill ~27~49~6 ~30~49~6 minecraft:stained_hardened_clay 5
setblock ~28~40~6 minecraft:stone 5
setblock ~28~42~6 minecraft:stone 5
setblock ~28~46~6 minecraft:stained_hardened_clay 13
fill ~28~47~6 ~28~47~7 minecraft:stained_hardened_clay 5
setblock ~28~50~6 minecraft:stained_hardened_clay 13
fill ~29~39~6 ~29~39~7 minecraft:stained_hardened_clay 9
fill ~29~42~6 ~29~42~8 minecraft:stained_hardened_clay 9
setblock ~29~44~6 minecraft:stone 5
fill ~29~45~6 ~29~46~6 minecraft:dirt 0
setblock ~29~48~6 minecraft:stained_hardened_clay 13
fill ~30~40~6 ~30~40~7 minecraft:stone 5
fill ~30~41~6 ~31~41~6 minecraft:stone 5
fill ~30~43~6 ~30~43~7 minecraft:stained_hardened_clay 9
setblock ~30~46~6 minecraft:stained_hardened_clay 13
setblock ~30~48~6 minecraft:grass
fill ~31~39~6 ~31~39~7 minecraft:stained_hardened_clay 9
fill ~31~40~6 ~34~40~6 minecraft:stained_hardened_clay 9
fill ~31~43~6 ~32~43~6 minecraft:stained_hardened_clay 5
setblock ~31~44~6 minecraft:grass
setblock ~31~46~6 minecraft:dirt 0
fill ~31~47~6 ~33~47~6 minecraft:stained_hardened_clay 13
fill ~31~48~6 ~32~48~6 minecraft:stained_hardened_clay 13
setblock ~31~49~6 minecraft:stained_hardened_clay 13
fill ~32~39~6 ~32~39~12 minecraft:stone 5
fill ~32~41~6 ~32~42~6 minecraft:stained_hardened_clay 9
setblock ~32~44~6 minecraft:stained_hardened_clay 13
setblock ~32~45~6 minecraft:stained_hardened_clay 5
fill ~32~46~6 ~32~46~7 minecraft:stained_hardened_clay 13
fill ~32~49~6 ~32~50~6 minecraft:dirt 0
fill ~32~51~6 ~32~51~7 minecraft:stained_hardened_clay 13
fill ~33~39~6 ~34~39~6 minecraft:stained_hardened_clay 9
fill ~33~41~6 ~33~41~7 minecraft:stone 5
setblock ~33~42~6 minecraft:stained_hardened_clay 9
setblock ~33~43~6 minecraft:stained_hardened_clay 13
setblock ~33~44~6 minecraft:dirt 0
fill ~33~45~6 ~33~45~7 minecraft:stained_hardened_clay 13
fill ~33~49~6 ~33~49~7 minecraft:stained_hardened_clay 13
fill ~33~50~6 ~36~50~6 minecraft:stained_hardened_clay 5
fill ~34~38~6 ~36~38~7 minecraft:stained_hardened_clay 9
fill ~34~41~6 ~35~41~6 minecraft:stained_hardened_clay 9
fill ~34~42~6 ~35~42~6 minecraft:stone 5
setblock ~34~43~6 minecraft:grass
fill ~34~44~6 ~34~44~7 minecraft:stained_hardened_clay 13
fill ~34~45~6 ~36~45~6 minecraft:dirt 0
setblock ~34~46~6 minecraft:stained_hardened_clay 13
setblock ~34~47~6 minecraft:stained_hardened_clay 5
setblock ~34~48~6 minecraft:stained_hardened_clay 13
fill ~34~49~6 ~35~49~6 minecraft:stained_hardened_clay 5
fill ~34~51~6 ~34~51~7 minecraft:stained_hardened_clay 13
setblock ~35~39~6 minecraft:stone 5
setblock ~35~43~6 minecraft:dirt 0
fill ~35~44~6 ~35~44~7 minecraft:stained_hardened_clay 5
setblock ~35~46~6 minecraft:stained_hardened_clay 5
fill ~35~47~6 ~35~47~7 minecraft:stained_hardened_clay 13
fill ~35~51~6 ~36~51~6 minecraft:stained_hardened_clay 5
fill ~36~39~6 ~36~39~9 minecraft:stained_hardened_clay 9
fill ~36~43~6 ~36~43~8 minecraft:stained_hardened_clay 9
setblock ~36~44~6 minecraft:dirt 0
fill ~36~47~6 ~36~48~6 minecraft:dirt 0
setblock ~36~49~6 minecraft:grass
fill ~37~39~6 ~38~39~6 minecraft:stone 5
fill ~37~41~6 ~37~41~8 minecraft:stained_hardened_clay 9
fill ~37~42~6 ~37~43~6 minecraft:stone 5
setblock ~37~44~6 minecraft:grass
fill ~37~46~6 ~37~47~6 minecraft:stained_hardened_clay 13
fill ~37~48~6 ~39~48~6 minecraft:stained_hardened_clay 5
fill ~37~49~6 ~37~49~8 minecraft:stained_hardened_clay 13
setblock ~37~50~6 minecraft:stained_hardened_clay 13
fill ~38~40~6 ~39~40~6 minecraft:stained_hardened_clay 9
setblock ~38~42~6 minecraft:stained_hardened_clay 9
setblock ~38~44~6 minecraft:stained_hardened_clay 5
setblock ~38~46~6 minecraft:dirt 0
fill ~38~47~6 ~38~47~7 minecraft:stained_hardened_clay 5
fill ~38~49~6 ~38~50~6 minecraft:grass
fill ~39~41~6 ~39~41~7 minecraft:stone 5
setblock ~39~42~6 minecraft:stone 5
setblock ~39~43~6 minecraft:stained_hardened_clay 9
fill ~39~44~6 ~39~44~10 minecraft:stone 5
setblock ~39~47~6 minecraft:stained_hardened_clay 13
setblock ~39~49~6 minecraft:stained_hardened_clay 13
fill ~40~41~6 ~40~41~8 minecraft:stained_hardened_clay 9
fill ~40~43~6 ~43~43~6 minecraft:stone 5
fill ~40~44~6 ~41~44~6 minecraft:stained_hardened_clay 9
setblock ~40~46~6 minecraft:stained_hardened_clay 13
setblock ~40~47~6 minecraft:grass
fill ~41~45~6 ~41~46~7 minecraft:stained_hardened_clay 5
fill ~42~44~6 ~42~44~8 minecraft:stained_hardened_clay 5
setblock ~42~45~6 minecraft:grass
fill ~23~43~7 ~25~43~7 minecraft:stone 5
fill ~23~44~7 ~23~44~9 minecraft:stone 5
setblock ~24~42~7 minecraft:stained_hardened_clay 9
fill ~24~44~7 ~24~45~8 minecraft:stained_hardened_clay 9
setblock ~24~46~7 minecraft:stained_hardened_clay 5
fill ~25~41~7 ~27~41~7 minecraft:stone 5
fill ~25~42~7 ~25~42~8 minecraft:stone 5
setblock ~25~44~7 minecraft:stone 5
setblock ~25~45~7 minecraft:stained_hardened_clay 13
setblock ~25~46~7 minecraft:dirt 0
fill ~25~47~7 ~25~48~7 minecraft:stained_hardened_clay 5
setblock ~26~40~7 minecraft:stone 5
fill ~26~42~7 ~26~42~12 minecraft:stained_hardened_clay 9
setblock ~26~46~7 minecraft:stained_hardened_clay 5
fill ~26~47~7 ~26~48~7 minecraft:dirt 0
fill ~26~49~7 ~28~49~7 minecraft:stained_hardened_clay 5
fill ~26~50~7 ~26~50~8 minecraft:stained_hardened_clay 13
setblock ~26~55~7 minecraft:leaves 1
setblock ~26~56~7 minecraft:wood 1
fill ~26~57~7 ~26~57~8 minecraft:leaves 1
fill ~27~39~7 ~28~39~7 minecraft:stained_hardened_clay 9
setblock ~27~47~7 minecraft:fence 1
setblock ~27~48~7 minecraft:dirt 0
fill ~27~50~7 ~27~50~8 minecraft:stained_hardened_clay 5
setblock ~27~68~7 minecraft:leaves 1
fill ~28~40~7 ~28~42~7 minecraft:stained_hardened_clay 9
fill ~28~44~7 ~28~44~8 minecraft:stone 5
fill ~28~45~7 ~29~45~7 minecraft:stained_hardened_clay 13
fill ~28~46~7 ~29~46~7 minecraft:stained_hardened_clay 5
setblock ~28~48~7 minecraft:stained_hardened_clay 5
fill ~28~50~7 ~28~51~8 minecraft:grass
setblock ~28~52~7 minecraft:red_flower 3
fill ~29~41~7 ~30~41~7 minecraft:stained_hardened_clay 9
fill ~29~44~7 ~30~44~7 minecraft:stained_hardened_clay 9
fill ~29~48~7 ~29~49~7 minecraft:dirt 0
setblock ~29~50~7 minecraft:stained_hardened_clay 13
fill ~29~51~7 ~30~51~7 minecraft:grass
fill ~29~52~7 ~29~52~8 minecraft:tallgrass 2
setblock ~30~39~7 minecraft:stone 5
fill ~30~42~7 ~30~42~8 minecraft:stone 5
setblock ~30~46~7 minecraft:dirt 0
setblock ~30~47~7 minecraft:stained_hardened_clay 13
fill ~30~48~7 ~30~50~7 minecraft:stained_hardened_clay 5
setblock ~30~52~7 minecraft:tallgrass 0
setblock ~30~57~7 minecraft:wood 1
setblock ~30~58~7 minecraft:leaves 1
fill ~31~40~7 ~35~40~7 minecraft:stone 5
fill ~31~41~7 ~32~41~8 minecraft:stone 5
fill ~31~42~7 ~32~42~9 minecraft:stained_hardened_clay 9
fill ~31~43~7 ~32~43~8 minecraft:stone 5
setblock ~31~44~7 minecraft:dirt 0
setblock ~31~45~7 minecraft:grass
setblock ~31~46~7 minecraft:stained_hardened_clay 5
fill ~31~47~7 ~33~47~7 minecraft:dirt 0
setblock ~31~48~7 minecraft:dirt 0
fill ~31~49~7 ~32~49~7 minecraft:stained_hardened_clay 5
setblock ~31~50~7 minecraft:dirt 0
setblock ~31~51~7 minecraft:stained_hardened_clay 13
fill ~31~52~7 ~32~52~7 minecraft:stained_hardened_clay 5
setblock ~32~38~7 minecraft:stone 5
setblock ~32~44~7 minecraft:grass
setblock ~32~45~7 minecraft:dirt 0
fill ~32~48~7 ~33~48~7 minecraft:stained_hardened_clay 5
setblock ~32~50~7 minecraft:stained_hardened_clay 5
fill ~33~38~7 ~33~38~12 minecraft:stained_hardened_clay 9
fill ~33~39~7 ~33~39~8 minecraft:stained_hardened_clay 9
fill ~33~42~7 ~34~42~8 minecraft:stone 5
fill ~33~43~7 ~33~43~10 minecraft:stained_hardened_clay 9
setblock ~33~44~7 minecraft:stained_hardened_clay 13
setblock ~33~46~7 minecraft:stained_hardened_clay 13
fill ~33~50~7 ~33~50~9 minecraft:stained_hardened_clay 13
setblock ~33~51~7 minecraft:stained_hardened_clay 5
fill ~33~52~7 ~33~52~8 minecraft:grass
setblock ~34~39~7 minecraft:stone 5
setblock ~34~41~7 minecraft:stone 5
fill ~34~43~7 ~35~43~8 minecraft:stone 5
fill ~34~45~7 ~34~46~7 minecraft:stained_hardened_clay 5
setblock ~34~47~7 minecraft:stained_hardened_clay 13
setblock ~34~48~7 minecraft:dirt 0
setblock ~34~49~7 minecraft:stained_hardened_clay 5
setblock ~34~50~7 minecraft:dirt 0
fill ~35~37~7 ~36~37~7 minecraft:stone 5
setblock ~35~39~7 minecraft:stained_hardened_clay 9
fill ~35~41~7 ~35~41~8 minecraft:stained_hardened_clay 9
setblock ~35~42~7 minecraft:stained_hardened_clay 9
setblock ~35~45~7 minecraft:stained_hardened_clay 13
fill ~35~46~7 ~35~46~8 minecraft:dirt 0
fill ~35~49~7 ~36~49~7 minecraft:stained_hardened_clay 13
setblock ~35~50~7 minecraft:stained_hardened_clay 13
fill ~35~51~7 ~35~51~8 minecraft:grass
setblock ~35~52~7 minecraft:red_flower 3
fill ~36~40~7 ~37~40~7 minecraft:stained_hardened_clay 9
setblock ~36~41~7 minecraft:stone 5
setblock ~36~44~7 minecraft:stone 5
setblock ~36~45~7 minecraft:stained_hardened_clay 5
setblock ~36~46~7 minecraft:stained_hardened_clay 13
fill ~36~47~7 ~37~47~7 minecraft:stained_hardened_clay 5
fill ~36~48~7 ~36~48~8 minecraft:stained_hardened_clay 5
fill ~36~50~7 ~36~50~8 minecraft:stained_hardened_clay 5
fill ~36~51~7 ~36~51~8 minecraft:stained_hardened_clay 13
fill ~37~38~7 ~37~38~8 minecraft:stone 5
fill ~37~39~7 ~38~39~7 minecraft:stained_hardened_clay 9
fill ~37~42~7 ~37~42~12 minecraft:stained_hardened_clay 9
setblock ~37~43~7 minecraft:stone 5
fill ~37~44~7 ~38~44~7 minecraft:stained_hardened_clay 9
fill ~37~45~7 ~38~45~7 minecraft:stained_hardened_clay 13
setblock ~37~46~7 minecraft:dirt 0
setblock ~37~48~7 minecraft:dirt 0
setblock ~37~50~7 minecraft:dirt 0
fill ~37~51~7 ~38~51~8 minecraft:stained_hardened_clay 5
fill ~38~40~7 ~38~42~7 minecraft:stone 5
fill ~38~46~7 ~39~46~7 minecraft:stained_hardened_clay 13
setblock ~38~48~7 minecraft:stained_hardened_clay 13
fill ~38~49~7 ~39~49~7 minecraft:stained_hardened_clay 5
setblock ~38~50~7 minecraft:stained_hardened_clay 5
fill ~39~39~7 ~39~39~8 minecraft:stone 5
fill ~39~40~7 ~40~40~8 minecraft:stained_hardened_clay 9
fill ~39~42~7 ~39~42~9 minecraft:stained_hardened_clay 9
fill ~39~43~7 ~40~43~7 minecraft:stone 5
fill ~39~47~7 ~39~48~7 minecraft:dirt 0
setblock ~39~50~7 minecraft:grass
fill ~40~44~7 ~40~44~10 minecraft:stone 5
setblock ~40~46~7 minecraft:stained_hardened_clay 5
fill ~40~47~7 ~41~47~7 minecraft:stained_hardened_clay 13
fill ~41~41~7 ~42~41~7 minecraft:stone 5
fill ~41~43~7 ~42~43~7 minecraft:stained_hardened_clay 9
fill ~41~44~7 ~41~44~8 minecraft:stained_hardened_clay 5
fill ~42~42~7 ~42~42~9 minecraft:stained_hardened_clay 9
fill ~42~45~7 ~42~45~9 minecraft:dirt 0
fill ~42~46~7 ~42~47~7 minecraft:stained_hardened_clay 5
setblock ~43~41~7 minecraft:stained_hardened_clay 9
fill ~43~42~7 ~43~42~8 minecraft:stone 5
fill ~43~43~7 ~44~43~7 minecraft:stained_hardened_clay 5
setblock ~43~44~7 minecraft:stained_hardened_clay 5
setblock ~43~45~7 minecraft:grass
setblock ~43~46~7 minecraft:stained_hardened_clay 13
fill ~44~42~7 ~44~42~8 minecraft:stained_hardened_clay 9
setblock ~44~44~7 minecraft:dirt 0
fill ~44~45~7 ~44~45~8 minecraft:stained_hardened_clay 13
setblock ~44~46~7 minecraft:grass
fill ~22~43~8 ~22~43~11 minecraft:stained_hardened_clay 9
fill ~22~44~8 ~22~44~9 minecraft:stained_hardened_clay 9
setblock ~22~59~8 minecraft:leaves 1
fill ~23~42~8 ~24~42~8 minecraft:stone 5
fill ~23~43~8 ~23~43~9 minecraft:stone 5
setblock ~23~45~8 minecraft:stained_hardened_clay 9
setblock ~23~46~8 minecraft:stained_hardened_clay 5
fill ~23~47~8 ~25~47~8 minecraft:stained_hardened_clay 13
fill ~23~60~8 ~24~60~8 minecraft:leaves 1
fill ~24~40~8 ~24~40~11 minecraft:stained_hardened_clay 9
fill ~24~41~8 ~26~41~9 minecraft:stone 5
fill ~24~43~8 ~26~43~8 minecraft:stained_hardened_clay 9
setblock ~24~46~8 minecraft:dirt 0
fill ~24~48~8 ~25~49~8 minecraft:stained_hardened_clay 5
fill ~24~50~8 ~25~50~8 minecraft:grass
setblock ~24~51~8 minecraft:tallgrass 2
setblock ~25~40~8 minecraft:stone 5
fill ~25~44~8 ~26~44~8 minecraft:stained_hardened_clay 9
fill ~25~45~8 ~25~46~8 minecraft:stained_hardened_clay 5
fill ~25~51~8 ~27~51~8 minecraft:stained_hardened_clay 5
fill ~25~56~8 ~25~56~10 minecraft:leaves 1
setblock ~25~64~8 minecraft:leaves 1
setblock ~26~40~8 minecraft:stained_hardened_clay 9
setblock ~26~45~8 minecraft:grass
setblock ~26~46~8 minecraft:stained_hardened_clay 13
setblock ~26~47~8 minecraft:stained_hardened_clay 5
setblock ~26~48~8 minecraft:dirt 0
setblock ~26~49~8 minecraft:stained_hardened_clay 5
fill ~26~65~8 ~27~65~8 minecraft:leaves 1
fill ~26~69~8 ~28~69~8 minecraft:leaves 1
setblock ~27~39~8 minecraft:stained_hardened_clay 9
fill ~27~40~8 ~28~40~8 minecraft:stone 5
setblock ~27~41~8 minecraft:stained_hardened_clay 9
setblock ~27~43~8 minecraft:stone 5
fill ~27~45~8 ~27~45~9 minecraft:stained_hardened_clay 13
setblock ~27~46~8 minecraft:stained_hardened_clay 5
setblock ~27~47~8 minecraft:stained_hardened_clay 13
setblock ~27~48~8 minecraft:grass
setblock ~27~49~8 minecraft:stained_hardened_clay 13
setblock ~27~57~8 minecraft:leaves 1
fill ~28~39~8 ~29~39~9 minecraft:stone 5
fill ~28~41~8 ~29~41~8 minecraft:stone 5
setblock ~28~42~8 minecraft:stone 5
setblock ~28~43~8 minecraft:stained_hardened_clay 9
fill ~28~45~8 ~28~45~9 minecraft:dirt 0
setblock ~28~46~8 minecraft:stained_hardened_clay 13
fill ~28~47~8 ~29~47~8 minecraft:wood 1
setblock ~28~48~8 minecraft:wood 1
setblock ~28~49~8 minecraft:dirt 0
setblock ~28~52~8 minecraft:tallgrass 0
fill ~28~58~8 ~29~58~8 minecraft:leaves 1
fill ~28~61~8 ~28~62~8 minecraft:leaves 1
fill ~29~43~8 ~30~43~9 minecraft:stone 5
fill ~29~44~8 ~32~44~8 minecraft:stone 5
setblock ~29~45~8 minecraft:stained_hardened_clay 13
setblock ~29~46~8 minecraft:fence 1
fill ~29~48~8 ~29~50~8 minecraft:stained_hardened_clay 5
setblock ~29~51~8 minecraft:grass
setblock ~29~57~8 minecraft:wood 1
setblock ~29~60~8 minecraft:leaves 1
setblock ~29~74~8 minecraft:leaves 1
fill ~30~38~8 ~32~38~8 minecraft:stained_hardened_clay 9
fill ~30~39~8 ~30~40~9 minecraft:stained_hardened_clay 9
setblock ~30~41~8 minecraft:stained_hardened_clay 9
fill ~30~45~8 ~31~45~8 minecraft:stained_hardened_clay 9
fill ~30~46~8 ~31~46~8 minecraft:stained_hardened_clay 13
setblock ~30~47~8 minecraft:grass
setblock ~30~48~8 minecraft:stained_hardened_clay 13
fill ~30~49~8 ~30~50~8 minecraft:stained_hardened_clay 5
setblock ~30~51~8 minecraft:stained_hardened_clay 13
fill ~30~57~8 ~31~57~8 minecraft:leaves 1
fill ~31~39~8 ~31~40~8 minecraft:stone 5
setblock ~31~47~8 minecraft:dirt 0
setblock ~31~48~8 minecraft:stained_hardened_clay 5
fill ~31~49~8 ~31~50~8 minecraft:stained_hardened_clay 13
setblock ~31~51~8 minecraft:dirt 0
fill ~31~52~8 ~32~52~9 minecraft:stained_hardened_clay 13
fill ~32~40~8 ~33~40~9 minecraft:stone 5
setblock ~32~45~8 minecraft:stained_hardened_clay 5
setblock ~32~46~8 minecraft:grass
fill ~32~47~8 ~33~47~8 minecraft:stained_hardened_clay 13
setblock ~32~48~8 minecraft:dirt 0
fill ~32~49~8 ~33~49~8 minecraft:stained_hardened_clay 5
setblock ~32~50~8 minecraft:dirt 0
setblock ~32~51~8 minecraft:grass
fill ~33~41~8 ~34~41~8 minecraft:stained_hardened_clay 9
fill ~33~44~8 ~37~44~8 minecraft:stained_hardened_clay 9
setblock ~33~45~8 minecraft:grass
fill ~33~46~8 ~34~46~8 minecraft:dirt 0
setblock ~33~48~8 minecraft:stained_hardened_clay 5
fill ~33~51~8 ~33~51~9 minecraft:dirt 0
setblock ~33~53~8 minecraft:tallgrass 0
fill ~34~37~8 ~34~37~9 minecraft:stone 5
setblock ~34~38~8 minecraft:stone 5
fill ~34~39~8 ~34~40~9 minecraft:stained_hardened_clay 9
setblock ~34~45~8 minecraft:stained_hardened_clay 13
setblock ~34~47~8 minecraft:stained_hardened_clay 5
fill ~34~48~8 ~34~50~8 minecraft:stained_hardened_clay 13
setblock ~34~51~8 minecraft:stained_hardened_clay 5
setblock ~34~52~8 minecraft:stained_hardened_clay 13
fill ~35~37~8 ~35~37~9 minecraft:stained_hardened_clay 9
setblock ~35~38~8 minecraft:stained_hardened_clay 9
setblock ~35~39~8 minecraft:stone 5
setblock ~35~40~8 minecraft:stained_hardened_clay 9
setblock ~35~42~8 minecraft:stone 5
fill ~35~45~8 ~39~45~8 minecraft:stone 5
fill ~35~47~8 ~36~47~8 minecraft:dirt 0
setblock ~35~49~8 minecraft:dirt 0
setblock ~35~50~8 minecraft:stained_hardened_clay 5
setblock ~35~52~8 minecraft:tallgrass 0
fill ~36~37~8 ~37~37~8 minecraft:stone 5
setblock ~36~38~8 minecraft:stone 5
setblock ~36~40~8 minecraft:stone 5
fill ~36~41~8 ~36~41~10 minecraft:stained_hardened_clay 9
setblock ~36~46~8 minecraft:dirt 0
setblock ~36~49~8 minecraft:stained_hardened_clay 13
fill ~37~39~8 ~37~40~8 minecraft:stained_hardened_clay 9
setblock ~37~43~8 minecraft:stained_hardened_clay 9
fill ~37~46~8 ~37~48~8 minecraft:stained_hardened_clay 5
fill ~37~50~8 ~38~50~9 minecraft:stained_hardened_clay 13
fill ~38~37~8 ~38~37~11 minecraft:stained_hardened_clay 9
fill ~38~38~8 ~39~38~8 minecraft:stained_hardened_clay 9
fill ~38~39~8 ~38~39~9 minecraft:stone 5
fill ~38~40~8 ~38~40~9 minecraft:stained_hardened_clay 9
setblock ~38~41~8 minecraft:stone 5
setblock ~38~42~8 minecraft:stained_hardened_clay 9
fill ~38~43~8 ~38~44~8 minecraft:stone 5
fill ~38~46~8 ~38~47~8 minecraft:dirt 0
fill ~38~48~8 ~38~49~8 minecraft:stained_hardened_clay 5
setblock ~39~41~8 minecraft:stained_hardened_clay 9
fill ~39~43~8 ~39~43~9 minecraft:stained_hardened_clay 9
fill ~39~46~8 ~41~46~8 minecraft:stained_hardened_clay 13
fill ~39~47~8 ~41~47~8 minecraft:stained_hardened_clay 5
fill ~39~48~8 ~39~49~8 minecraft:stained_hardened_clay 13
setblock ~39~50~8 minecraft:stained_hardened_clay 5
setblock ~39~51~8 minecraft:grass
fill ~40~39~8 ~40~39~9 minecraft:stained_hardened_clay 9
fill ~40~42~8 ~40~42~11 minecraft:stone 5
fill ~40~43~8 ~41~43~8 minecraft:stone 5
setblock ~40~45~8 minecraft:dirt 0
setblock ~40~48~8 minecraft:stained_hardened_clay 5
setblock ~40~49~8 minecraft:grass
fill ~41~40~8 ~43~40~8 minecraft:stone 5
fill ~41~41~8 ~42~41~9 minecraft:stained_hardened_clay 9
fill ~41~45~8 ~41~45~9 minecraft:stained_hardened_clay 13
fill ~41~48~8 ~41~48~9 minecraft:stained_hardened_clay 13
setblock ~41~49~8 minecraft:stained_hardened_clay 5
fill ~42~43~8 ~43~43~8 minecraft:dirt 0
fill ~42~46~8 ~43~46~8 minecraft:dirt 0
fill ~42~47~8 ~43~47~8 minecraft:stained_hardened_clay 13
setblock ~42~48~8 minecraft:stained_hardened_clay 5
fill ~43~41~8 ~43~41~9 minecraft:stone 5
fill ~43~44~8 ~43~44~9 minecraft:dirt 0
setblock ~43~45~8 minecraft:stained_hardened_clay 13
setblock ~43~48~8 minecraft:stained_hardened_clay 13
setblock ~44~41~8 minecraft:stained_hardened_clay 9
fill ~44~43~8 ~44~43~9 minecraft:stained_hardened_clay 13
setblock ~44~44~8 minecraft:stained_hardened_clay 13
fill ~44~46~8 ~45~46~8 minecraft:stained_hardened_clay 13
setblock ~44~47~8 minecraft:stained_hardened_clay 5
setblock ~45~43~8 minecraft:stained_hardened_clay 5
setblock ~45~44~8 minecraft:dirt 0
setblock ~45~45~8 minecraft:grass
fill ~21~42~9 ~25~42~9 minecraft:stained_hardened_clay 9
setblock ~21~43~9 minecraft:stone 5
setblock ~21~44~9 minecraft:grass
fill ~22~45~9 ~23~45~9 minecraft:dirt 0
setblock ~22~46~9 minecraft:grass
setblock ~22~60~9 minecraft:leaves 1
fill ~23~41~9 ~23~41~15 minecraft:stone 5
fill ~23~46~9 ~23~46~10 minecraft:stained_hardened_clay 13
setblock ~23~47~9 minecraft:dirt 0
fill ~23~48~9 ~23~48~11 minecraft:stained_hardened_clay 5
setblock ~23~49~9 minecraft:stained_hardened_clay 13
setblock ~23~60~9 minecraft:wood 1
fill ~23~61~9 ~23~61~10 minecraft:leaves 1
fill ~24~43~9 ~25~44~9 minecraft:stone 5
fill ~24~45~9 ~25~45~10 minecraft:stained_hardened_clay 9
setblock ~24~46~9 minecraft:stained_hardened_clay 5
setblock ~24~47~9 minecraft:wood 1
fill ~24~48~9 ~25~48~9 minecraft:grass
fill ~24~49~9 ~26~49~9 minecraft:dirt 0
setblock ~24~50~9 minecraft:stained_hardened_clay 13
fill ~24~51~9 ~24~51~12 minecraft:stained_hardened_clay 5
fill ~24~57~9 ~24~57~11 minecraft:leaves 1
fill ~25~40~9 ~25~40~12 minecraft:stained_hardened_clay 9
fill ~25~46~9 ~26~46~9 minecraft:dirt 0
fill ~25~47~9 ~25~47~10 minecraft:stained_hardened_clay 13
fill ~25~50~9 ~26~50~9 minecraft:stained_hardened_clay 5
fill ~25~51~9 ~25~51~10 minecraft:stained_hardened_clay 13
fill ~25~57~9 ~26~57~10 minecraft:wood 1
fill ~25~61~9 ~25~62~10 minecraft:leaves 1
fill ~25~68~9 ~25~68~11 minecraft:leaves 1
fill ~25~73~9 ~25~73~10 minecraft:leaves 1
fill ~26~39~9 ~26~39~16 minecraft:stained_hardened_clay 9
fill ~26~40~9 ~27~40~10 minecraft:stone 5
fill ~26~43~9 ~27~43~10 minecraft:stained_hardened_clay 9
fill ~26~44~9 ~26~44~13 minecraft:stone 5
setblock ~26~45~9 minecraft:stained_hardened_clay 5
setblock ~26~47~9 minecraft:dirt 0
setblock ~26~48~9 minecraft:stained_hardened_clay 13
setblock ~26~51~9 minecraft:grass
fill ~26~58~9 ~27~58~9 minecraft:leaves 1
setblock ~26~65~9 minecraft:wood 1
fill ~26~66~9 ~27~66~9 minecraft:leaves 1
fill ~27~39~9 ~27~39~12 minecraft:stone 5
fill ~27~41~9 ~27~41~10 minecraft:stone 5
setblock ~27~46~9 minecraft:stained_hardened_clay 13
fill ~27~47~9 ~27~47~10 minecraft:stained_hardened_clay 5
fill ~27~48~9 ~27~49~9 minecraft:wood 1
setblock ~27~50~9 minecraft:dirt 0
fill ~27~51~9 ~29~51~9 minecraft:stained_hardened_clay 5
fill ~27~59~9 ~28~59~9 minecraft:leaves 1
fill ~27~61~9 ~27~62~9 minecraft:leaves 1
fill ~27~69~9 ~27~69~12 minecraft:wood 1
fill ~27~70~9 ~28~70~9 minecraft:leaves 1
fill ~27~74~9 ~27~76~10 minecraft:leaves 1
fill ~28~40~9 ~28~42~9 minecraft:stained_hardened_clay 9
setblock ~28~43~9 minecraft:stone 5
fill ~28~44~9 ~29~44~10 minecraft:stained_hardened_clay 9
setblock ~28~46~9 minecraft:dirt 0
setblock ~28~47~9 minecraft:fence 1
setblock ~28~48~9 minecraft:stained_hardened_clay 5
setblock ~28~49~9 minecraft:grass
setblock ~28~50~9 minecraft:stained_hardened_clay 13
setblock ~28~58~9 minecraft:wood 1
setblock ~28~61~9 minecraft:wood 1
fill ~28~62~9 ~29~62~10 minecraft:leaves 1
fill ~28~67~9 ~29~67~9 minecraft:leaves 1
fill ~28~69~9 ~28~69~11 minecraft:leaves 1
fill ~28~72~9 ~28~77~9 minecraft:wood 1
fill ~28~78~9 ~28~79~10 minecraft:leaves 1
fill ~28~80~9 ~28~82~9 minecraft:leaves 1
fill ~29~38~9 ~30~38~9 minecraft:stained_hardened_clay 9
setblock ~29~41~9 minecraft:stained_hardened_clay 9
setblock ~29~42~9 minecraft:stone 5
setblock ~29~45~9 minecraft:stone 5
fill ~29~46~9 ~29~46~11 minecraft:wood 1
fill ~29~47~9 ~30~47~9 minecraft:stained_hardened_clay 5
fill ~29~48~9 ~29~49~9 minecraft:stained_hardened_clay 13
fill ~29~50~9 ~30~50~9 minecraft:stained_hardened_clay 5
fill ~29~58~9 ~30~58~9 minecraft:leaves 1
setblock ~29~61~9 minecraft:leaves 1
setblock ~30~41~9 minecraft:stone 5
setblock ~30~42~9 minecraft:stained_hardened_clay 9
fill ~30~44~9 ~30~44~10 minecraft:stone 5
setblock ~30~45~9 minecraft:stained_hardened_clay 9
setblock ~30~46~9 minecraft:dirt 0
setblock ~30~48~9 minecraft:stained_hardened_clay 5
setblock ~30~49~9 minecraft:dirt 0
setblock ~30~51~9 minecraft:grass
setblock ~30~52~9 minecraft:double_plant 3
setblock ~30~57~9 minecraft:leaves 1
setblock ~31~38~9 minecraft:stone 5
setblock ~31~39~9 minecraft:stained_hardened_clay 9
setblock ~31~40~9 minecraft:stone 5
fill ~31~41~9 ~33~41~9 minecraft:stained_hardened_clay 9
fill ~31~43~9 ~31~43~10 minecraft:stained_hardened_clay 9
fill ~31~44~9 ~32~44~9 minecraft:stained_hardened_clay 9
fill ~31~45~9 ~32~45~9 minecraft:stone 5
setblock ~31~46~9 minecraft:stained_hardened_clay 9
setblock ~31~47~9 minecraft:stained_hardened_clay 13
setblock ~31~48~9 minecraft:grass
fill ~31~49~9 ~32~49~10 minecraft:stained_hardened_clay 5
fill ~31~50~9 ~31~50~11 minecraft:stained_hardened_clay 13
setblock ~31~51~9 minecraft:stained_hardened_clay 5
fill ~32~37~9 ~33~37~9 minecraft:stained_hardened_clay 9
fill ~32~38~9 ~32~38~10 minecraft:stained_hardened_clay 9
fill ~32~43~9 ~32~43~10 minecraft:stone 5
fill ~32~46~9 ~32~46~12 minecraft:stone 5
fill ~32~47~9 ~33~47~9 minecraft:stained_hardened_clay 5
fill ~32~48~9 ~32~48~10 minecraft:stained_hardened_clay 13
setblock ~32~50~9 minecraft:stained_hardened_clay 5
setblock ~32~51~9 minecraft:stained_hardened_clay 13
setblock ~33~39~9 minecraft:stone 5
setblock ~33~42~9 minecraft:stone 5
fill ~33~44~9 ~34~44~9 minecraft:stone 5
fill ~33~45~9 ~34~45~9 minecraft:stained_hardened_clay 9
fill ~33~46~9 ~33~46~10 minecraft:stained_hardened_clay 9
setblock ~33~48~9 minecraft:dirt 0
fill ~33~49~9 ~34~49~10 minecraft:stained_hardened_clay 13
setblock ~33~52~9 minecraft:stained_hardened_clay 13
setblock ~34~36~9 minecraft:stained_hardened_clay 9
setblock ~34~38~9 minecraft:stained_hardened_clay 9
fill ~34~41~9 ~35~41~9 minecraft:stone 5
fill ~34~42~9 ~35~42~9 minecraft:stained_hardened_clay 9
fill ~34~43~9 ~34~43~12 minecraft:stone 5
fill ~34~46~9 ~34~46~10 minecraft:stone 5
setblock ~34~47~9 minecraft:stained_hardened_clay 13
fill ~34~48~9 ~34~48~10 minecraft:stained_hardened_clay 5
fill ~34~50~9 ~34~51~9 minecraft:stained_hardened_clay 13
fill ~34~52~9 ~35~52~9 minecraft:grass
setblock ~34~53~9 minecraft:double_plant ["double_plant_type":"paeonia","upper_block_bit":false]
setblock ~35~36~9 minecraft:stone 5
setblock ~35~38~9 minecraft:stone 5
setblock ~35~39~9 minecraft:stained_hardened_clay 9
fill ~35~40~9 ~35~40~11 minecraft:stone 5
fill ~35~43~9 ~35~44~9 minecraft:stained_hardened_clay 9
fill ~35~45~9 ~35~45~11 minecraft:stone 5
fill ~35~46~9 ~36~46~11 minecraft:stained_hardened_clay 9
setblock ~35~47~9 minecraft:stone 5
fill ~35~49~9 ~35~50~9 minecraft:grass
fill ~35~51~9 ~37~51~9 minecraft:stained_hardened_clay 5
fill ~36~36~9 ~36~36~10 minecraft:stained_hardened_clay 9
setblock ~36~37~9 minecraft:stone 5
fill ~36~38~9 ~38~38~10 minecraft:stained_hardened_clay 9
fill ~36~40~9 ~37~40~9 minecraft:stained_hardened_clay 9
fill ~36~42~9 ~36~43~10 minecraft:stone 5
fill ~36~44~9 ~38~44~9 minecraft:stained_hardened_clay 9
fill ~36~45~9 ~37~45~10 minecraft:stained_hardened_clay 9
fill ~36~47~9 ~38~47~9 minecraft:stained_hardened_clay 5
fill ~36~48~9 ~37~48~9 minecraft:dirt 0
fill ~36~49~9 ~36~49~10 minecraft:dirt 0
setblock ~36~50~9 minecraft:dirt 0
setblock ~37~37~9 minecraft:stained_hardened_clay 9
setblock ~37~39~9 minecraft:stone 5
fill ~37~41~9 ~37~41~11 minecraft:stone 5
setblock ~37~43~9 minecraft:stone 5
fill ~37~46~9 ~38~46~9 minecraft:stone 5
fill ~37~49~9 ~39~49~10 minecraft:stained_hardened_clay 5
fill ~37~52~9 ~37~52~10 minecraft:grass
setblock ~37~53~9 minecraft:tallgrass 0
fill ~38~36~9 ~38~36~10 minecraft:stained_hardened_clay 9
fill ~38~41~9 ~38~41~10 minecraft:stained_hardened_clay 9
setblock ~38~42~9 minecraft:stone 5
setblock ~38~43~9 minecraft:stained_hardened_clay 9
fill ~38~45~9 ~38~45~11 minecraft:stone 5
setblock ~38~48~9 minecraft:fence 1
fill ~38~51~9 ~40~51~9 minecraft:stained_hardened_clay 13
fill ~38~52~9 ~39~52~10 minecraft:stained_hardened_clay 13
setblock ~39~36~9 minecraft:stone 5
setblock ~39~37~9 minecraft:stained_hardened_clay 9
fill ~39~38~9 ~40~38~9 minecraft:stone 5
setblock ~39~39~9 minecraft:stained_hardened_clay 9
fill ~39~40~9 ~40~41~9 minecraft:stone 5
fill ~39~45~9 ~39~45~10 minecraft:stained_hardened_clay 9
fill ~39~46~9 ~40~46~9 minecraft:dirt 0
setblock ~39~47~9 minecraft:dirt 0
fill ~39~48~9 ~39~48~10 minecraft:stained_hardened_clay 5
setblock ~39~50~9 minecraft:grass
setblock ~40~43~9 minecraft:stone 5
setblock ~40~45~9 minecraft:stained_hardened_clay 5
fill ~40~47~9 ~41~47~10 minecraft:stained_hardened_clay 13
setblock ~40~48~9 minecraft:dirt 0
setblock ~40~49~9 minecraft:stained_hardened_clay 13
setblock ~40~50~9 minecraft:stained_hardened_clay 5
fill ~41~39~9 ~41~39~11 minecraft:stained_hardened_clay 9
setblock ~41~40~9 minecraft:stained_hardened_clay 9
setblock ~41~42~9 minecraft:stone 5
fill ~41~43~9 ~41~43~10 minecraft:stained_hardened_clay 9
fill ~41~44~9 ~41~44~10 minecraft:dirt 0
fill ~41~46~9 ~41~46~10 minecraft:stained_hardened_clay 13
fill ~41~49~9 ~42~49~9 minecraft:grass
fill ~42~40~9 ~44~40~9 minecraft:stone 5
fill ~42~43~9 ~42~44~9 minecraft:grass
setblock ~42~46~9 minecraft:grass
setblock ~42~47~9 minecraft:dirt 0
fill ~42~48~9 ~43~48~9 minecraft:grass
fill ~43~42~9 ~43~42~11 minecraft:stained_hardened_clay 9
fill ~43~43~9 ~43~43~10 minecraft:dirt 0
setblock ~43~45~9 minecraft:grass
fill ~43~46~9 ~43~47~9 minecraft:stained_hardened_clay 13
fill ~44~41~9 ~44~41~11 minecraft:stone 5
fill ~44~42~9 ~45~42~9 minecraft:stone 5
fill ~44~44~9 ~44~45~9 minecraft:stained_hardened_clay 5
fill ~44~46~9 ~44~47~9 minecraft:dirt 0
setblock ~44~48~9 minecraft:stained_hardened_clay 13
setblock ~45~41~9 minecraft:stained_hardened_clay 9
setblock ~45~43~9 minecraft:dirt 0
fill ~45~44~9 ~45~44~10 minecraft:stained_hardened_clay 13
fill ~45~45~9 ~45~45~11 minecraft:stained_hardened_clay 5
fill ~45~46~9 ~45~47~9 minecraft:grass
fill ~46~43~9 ~46~44~9 minecraft:stained_hardened_clay 5
fill ~46~45~9 ~46~45~10 minecraft:grass
setblock ~46~46~9 minecraft:stained_hardened_clay 5
fill ~49~62~9 ~50~62~9 minecraft:stained_hardened_clay 4
fill ~49~63~9 ~50~63~9 minecraft:stained_hardened_clay 11
fill ~49~64~9 ~50~64~9 minecraft:stained_hardened_clay 3
setblock ~50~65~9 minecraft:stained_hardened_clay 3
setblock ~50~66~9 minecraft:stained_hardened_clay 11
fill ~18~43~10 ~21~43~10 minecraft:stained_hardened_clay 9
setblock ~18~44~10 minecraft:stained_hardened_clay 5
setblock ~18~45~10 minecraft:stained_hardened_clay 13
fill ~19~42~10 ~19~42~11 minecraft:stained_hardened_clay 9
fill ~19~44~10 ~20~44~10 minecraft:stained_hardened_clay 13
fill ~19~45~10 ~19~46~10 minecraft:stained_hardened_clay 5
setblock ~19~47~10 minecraft:grass
setblock ~20~41~10 minecraft:stained_hardened_clay 9
fill ~20~42~10 ~22~42~10 minecraft:stone 5
fill ~20~45~10 ~20~45~11 minecraft:stained_hardened_clay 13
setblock ~20~46~10 minecraft:dirt 0
fill ~20~47~10 ~21~47~10 minecraft:stained_hardened_clay 13
setblock ~20~48~10 minecraft:grass
setblock ~20~49~10 minecraft:double_plant 3
fill ~20~54~10 ~22~54~10 minecraft:leaves 1
fill ~21~41~10 ~21~41~13 minecraft:stone 5
fill ~21~44~10 ~21~45~10 minecraft:dirt 0
fill ~21~46~10 ~21~46~12 minecraft:stained_hardened_clay 5
fill ~21~48~10 ~22~48~10 minecraft:stained_hardened_clay 5
fill ~21~55~10 ~24~55~10 minecraft:leaves 1
fill ~22~41~10 ~22~41~11 minecraft:stained_hardened_clay 9
setblock ~22~44~10 minecraft:stained_hardened_clay 13
fill ~22~45~10 ~22~45~11 minecraft:stained_hardened_clay 5
setblock ~22~46~10 minecraft:stained_hardened_clay 13
fill ~22~47~10 ~22~47~11 minecraft:dirt 0
fill ~22~49~10 ~22~50~10 minecraft:stained_hardened_clay 13
setblock ~23~40~10 minecraft:stone 5
fill ~23~42~10 ~24~42~10 minecraft:stained_hardened_clay 9
fill ~23~43~10 ~23~44~10 minecraft:stained_hardened_clay 9
setblock ~23~45~10 minecraft:stained_hardened_clay 13
setblock ~23~47~10 minecraft:stained_hardened_clay 13
fill ~23~49~10 ~23~50~10 minecraft:stained_hardened_clay 5
fill ~23~56~10 ~24~56~10 minecraft:leaves 1
fill ~23~63~10 ~23~63~12 minecraft:leaves 1
setblock ~23~66~10 minecraft:leaves 1
fill ~24~41~10 ~26~41~10 minecraft:stained_hardened_clay 9
setblock ~24~43~10 minecraft:stone 5
setblock ~24~44~10 minecraft:stained_hardened_clay 9
fill ~24~46~10 ~24~46~11 minecraft:stained_hardened_clay 13
setblock ~24~47~10 minecraft:dirt 0
fill ~24~48~10 ~24~49~10 minecraft:wood 1
fill ~24~50~10 ~25~50~10 minecraft:stained_hardened_clay 5
setblock ~24~58~10 minecraft:leaves 1
setblock ~24~61~10 minecraft:wood 1
fill ~24~64~10 ~24~64~11 minecraft:leaves 1
setblock ~24~67~10 minecraft:wood 1
setblock ~24~68~10 minecraft:leaves 1
setblock ~24~72~10 minecraft:leaves 1
setblock ~25~42~10 minecraft:stone 5
fill ~25~43~10 ~25~43~12 minecraft:stained_hardened_clay 9
fill ~25~44~10 ~25~44~12 minecraft:stone 5
fill ~25~46~10 ~26~46~10 minecraft:stained_hardened_clay 5
fill ~25~48~10 ~25~49~10 minecraft:dirt 0
fill ~26~45~10 ~26~45~11 minecraft:stained_hardened_clay 9
fill ~26~47~10 ~26~47~11 minecraft:stained_hardened_clay 5
setblock ~26~48~10 minecraft:fence 1
fill ~26~49~10 ~27~50~10 minecraft:wood 1
fill ~26~51~10 ~26~51~13 minecraft:wood 1
fill ~26~53~10 ~26~54~10 minecraft:leaves 1
setblock ~26~58~10 minecraft:leaves 1
setblock ~26~61~10 minecraft:leaves 1
fill ~26~62~10 ~27~62~10 minecraft:wood 1
setblock ~26~65~10 minecraft:leaves 1
fill ~26~68~10 ~27~68~10 minecraft:wood 1
fill ~26~69~10 ~26~69~12 minecraft:leaves 1
setblock ~26~73~10 minecraft:wood 1
setblock ~26~74~10 minecraft:leaves 1
fill ~27~42~10 ~28~42~10 minecraft:stone 5
fill ~27~44~10 ~27~45~10 minecraft:stone 5
setblock ~27~46~10 minecraft:dirt 0
setblock ~27~48~10 minecraft:stained_hardened_clay 5
setblock ~27~51~10 minecraft:stained_hardened_clay 13
setblock ~27~58~10 minecraft:wood 1
setblock ~27~59~10 minecraft:leaves 1
fill ~27~65~10 ~27~67~10 minecraft:wood 1
fill ~27~70~10 ~27~72~10 minecraft:wood 1
fill ~27~73~10 ~29~73~10 minecraft:leaves 1
fill ~27~77~10 ~29~77~10 minecraft:leaves 1
fill ~28~38~10 ~30~38~10 minecraft:stone 5
setblock ~28~39~10 minecraft:stained_hardened_clay 9
fill ~28~40~10 ~28~40~12 minecraft:stone 5
setblock ~28~41~10 minecraft:stained_hardened_clay 9
setblock ~28~43~10 minecraft:stained_hardened_clay 9
fill ~28~45~10 ~29~45~10 minecraft:stained_hardened_clay 9
setblock ~28~46~10 minecraft:wood 1
setblock ~28~47~10 minecraft:stained_hardened_clay 13
fill ~28~48~10 ~30~48~10 minecraft:grass
fill ~28~49~10 ~28~49~11 minecraft:dirt 0
setblock ~28~50~10 minecraft:dirt 0
fill ~28~51~10 ~29~51~10 minecraft:grass
fill ~28~67~10 ~29~67~10 minecraft:wood 1
fill ~28~70~10 ~29~70~10 minecraft:leaves 1
fill ~28~74~10 ~29~76~10 minecraft:leaves 1
fill ~29~39~10 ~31~39~10 minecraft:stone 5
setblock ~29~40~10 minecraft:stained_hardened_clay 9
fill ~29~41~10 ~29~41~11 minecraft:stone 5
setblock ~29~42~10 minecraft:stained_hardened_clay 9
setblock ~29~43~10 minecraft:stone 5
setblock ~29~47~10 minecraft:dirt 0
fill ~29~49~10 ~29~50~10 minecraft:stained_hardened_clay 5
setblock ~29~52~10 minecraft:tallgrass 0
setblock ~29~69~10 minecraft:leaves 1
fill ~29~78~10 ~29~79~10 minecraft:leaves 1
setblock ~30~40~10 minecraft:stone 5
fill ~30~41~10 ~32~41~10 minecraft:stained_hardened_clay 9
fill ~30~42~10 ~32~42~10 minecraft:stone 5
setblock ~30~43~10 minecraft:stained_hardened_clay 9
setblock ~30~45~10 minecraft:stone 5
fill ~30~46~10 ~30~46~12 minecraft:fence 1
setblock ~30~47~10 minecraft:stained_hardened_clay 5
fill ~30~49~10 ~30~50~10 minecraft:stained_hardened_clay 13
setblock ~30~51~10 minecraft:stained_hardened_clay 5
setblock ~30~66~10 minecraft:wood 1
fill ~31~37~10 ~32~37~10 minecraft:stone 5
fill ~31~38~10 ~31~38~12 minecraft:stained_hardened_clay 9
fill ~31~40~10 ~32~40~10 minecraft:stained_hardened_clay 9
fill ~31~44~10 ~31~44~11 minecraft:stone 5
setblock ~31~45~10 minecraft:stained_hardened_clay 9
setblock ~31~46~10 minecraft:stone 5
setblock ~31~47~10 minecraft:stained_hardened_clay 9
setblock ~31~48~10 minecraft:stained_hardened_clay 5
setblock ~31~51~10 minecraft:stained_hardened_clay 13
setblock ~31~65~10 minecraft:leaves 1
setblock ~32~36~10 minecraft:stained_hardened_clay 9
fill ~32~44~10 ~36~44~10 minecraft:stained_hardened_clay 9
fill ~32~45~10 ~33~45~10 minecraft:stone 5
fill ~32~47~10 ~32~47~13 minecraft:stone 5
setblock ~32~50~10 minecraft:dirt 0
fill ~32~51~10 ~32~52~10 minecraft:stained_hardened_clay 5
fill ~33~36~10 ~34~36~10 minecraft:stone 5
fill ~33~37~10 ~34~37~10 minecraft:stained_hardened_clay 9
setblock ~33~39~10 minecraft:stained_hardened_clay 9
fill ~33~40~10 ~34~40~10 minecraft:stone 5
setblock ~33~41~10 minecraft:stone 5
fill ~33~42~10 ~33~42~14 minecraft:stained_hardened_clay 9
setblock ~33~47~10 minecraft:stained_hardened_clay 9
setblock ~33~48~10 minecraft:stained_hardened_clay 5
setblock ~33~50~10 minecraft:stained_hardened_clay 5
setblock ~33~51~10 minecraft:grass
fill ~34~35~10 ~35~35~10 minecraft:stained_hardened_clay 9
fill ~34~38~10 ~34~39~10 minecraft:stone 5
fill ~34~41~10 ~35~41~10 minecraft:stained_hardened_clay 9
setblock ~34~42~10 minecraft:stone 5
setblock ~34~45~10 minecraft:stained_hardened_clay 9
setblock ~34~47~10 minecraft:stone 5
setblock ~34~50~10 minecraft:grass
fill ~34~51~10 ~35~51~10 minecraft:stained_hardened_clay 5
fill ~34~52~10 ~35~52~10 minecraft:stained_hardened_clay 13
setblock ~35~36~10 minecraft:stained_hardened_clay 9
fill ~35~37~10 ~35~37~12 minecraft:stone 5
setblock ~35~38~10 minecraft:stained_hardened_clay 9
fill ~35~39~10 ~36~39~10 minecraft:stone 5
setblock ~35~42~10 minecraft:stained_hardened_clay 9
setblock ~35~43~10 minecraft:stone 5
fill ~35~47~10 ~35~47~11 minecraft:stained_hardened_clay 9
setblock ~35~49~10 minecraft:stained_hardened_clay 13
setblock ~35~50~10 minecraft:stained_hardened_clay 5
setblock ~36~35~10 minecraft:stone 5
setblock ~36~37~10 minecraft:stained_hardened_clay 9
fill ~36~40~10 ~36~40~13 minecraft:stained_hardened_clay 9
setblock ~36~47~10 minecraft:stained_hardened_clay 5
setblock ~36~48~10 minecraft:stained_hardened_clay 13
setblock ~36~50~10 minecraft:grass
setblock ~36~51~10 minecraft:dirt 0
setblock ~36~52~10 minecraft:grass
setblock ~36~53~10 minecraft:tallgrass 0
setblock ~37~35~10 minecraft:stained_hardened_clay 9
fill ~37~36~10 ~37~37~10 minecraft:stone 5
fill ~37~39~10 ~38~39~10 minecraft:stained_hardened_clay 9
fill ~37~40~10 ~38~40~10 minecraft:stone 5
setblock ~37~43~10 minecraft:stained_hardened_clay 9
fill ~37~44~10 ~38~44~10 minecraft:stone 5
setblock ~37~46~10 minecraft:stone 5
fill ~37~47~10 ~37~47~11 minecraft:fence 1
fill ~37~48~10 ~38~48~10 minecraft:wood 1
fill ~37~50~10 ~37~50~11 minecraft:stained_hardened_clay 5
setblock ~37~51~10 minecraft:grass
setblock ~37~53~10 minecraft:tallgrass 2
setblock ~37~54~10 minecraft:leaves 1
fill ~38~35~10 ~38~35~13 minecraft:stone 5
setblock ~38~42~10 minecraft:stained_hardened_clay 9
fill ~38~43~10 ~39~43~10 minecraft:stone 5
setblock ~38~46~10 minecraft:stained_hardened_clay 9
fill ~38~47~10 ~38~47~11 minecraft:stained_hardened_clay 13
setblock ~38~50~10 minecraft:dirt 0
fill ~38~51~10 ~38~51~11 minecraft:stained_hardened_clay 5
setblock ~38~55~10 minecraft:leaves 1
fill ~39~35~10 ~39~36~11 minecraft:stained_hardened_clay 9
fill ~39~37~10 ~40~37~10 minecraft:stone 5
fill ~39~38~10 ~39~38~11 minecraft:stone 5
fill ~39~39~10 ~40~39~10 minecraft:stone 5
fill ~39~40~10 ~40~40~11 minecraft:stained_hardened_clay 9
fill ~39~41~10 ~39~41~11 minecraft:stained_hardened_clay 9
setblock ~39~42~10 minecraft:stone 5
setblock ~39~46~10 minecraft:stained_hardened_clay 13
setblock ~39~47~10 minecraft:stained_hardened_clay 5
setblock ~39~50~10 minecraft:stained_hardened_clay 5
setblock ~39~51~10 minecraft:stained_hardened_clay 13
setblock ~40~36~10 minecraft:stone 5
setblock ~40~38~10 minecraft:stained_hardened_clay 9
fill ~40~41~10 ~41~41~10 minecraft:stone 5
setblock ~40~43~10 minecraft:stained_hardened_clay 9
fill ~40~45~10 ~41~45~10 minecraft:dirt 0
fill ~40~46~10 ~40~46~11 minecraft:dirt 0
setblock ~40~48~10 minecraft:stained_hardened_clay 13
fill ~40~49~10 ~41~49~10 minecraft:dirt 0
fill ~40~50~10 ~40~51~10 minecraft:grass
fill ~40~52~10 ~40~52~11 minecraft:stained_hardened_clay 13
setblock ~41~37~10 minecraft:stained_hardened_clay 9
setblock ~41~38~10 minecraft:stone 5
fill ~41~40~10 ~41~40~11 minecraft:stone 5
setblock ~41~42~10 minecraft:stained_hardened_clay 9
setblock ~41~48~10 minecraft:dirt 0
setblock ~41~50~10 minecraft:stained_hardened_clay 13
setblock ~41~60~10 minecraft:leaves 1
fill ~42~39~10 ~42~39~12 minecraft:stained_hardened_clay 9
fill ~42~40~10 ~42~41~10 minecraft:stained_hardened_clay 9
fill ~42~42~10 ~42~42~13 minecraft:stone 5
fill ~42~43~10 ~42~46~10 minecraft:stained_hardened_clay 5
setblock ~42~47~10 minecraft:grass
setblock ~42~48~10 minecraft:fence 1
setblock ~42~49~10 minecraft:grass
fill ~43~39~10 ~43~40~10 minecraft:stone 5
fill ~43~41~10 ~43~41~13 minecraft:stained_hardened_clay 9
fill ~43~44~10 ~43~45~10 minecraft:stained_hardened_clay 13
fill ~43~46~10 ~43~47~10 minecraft:stained_hardened_clay 5
fill ~43~48~10 ~43~49~10 minecraft:stained_hardened_clay 13
fill ~44~40~10 ~45~40~11 minecraft:stained_hardened_clay 9
setblock ~44~42~10 minecraft:stained_hardened_clay 9
setblock ~44~43~10 minecraft:grass
fill ~44~44~10 ~44~45~10 minecraft:dirt 0
setblock ~44~46~10 minecraft:grass
setblock ~44~47~10 minecraft:dirt 0
fill ~44~48~10 ~44~48~13 minecraft:stained_hardened_clay 5
setblock ~44~49~10 minecraft:grass
fill ~45~41~10 ~46~41~11 minecraft:stone 5
setblock ~45~42~10 minecraft:stone 5
fill ~45~43~10 ~46~43~10 minecraft:stained_hardened_clay 13
setblock ~45~46~10 minecraft:stained_hardened_clay 13
setblock ~45~47~10 minecraft:grass
setblock ~45~56~10 minecraft:leaves 1
fill ~46~42~10 ~47~42~10 minecraft:stained_hardened_clay 9
setblock ~46~44~10 minecraft:stained_hardened_clay 13
fill ~46~46~10 ~46~46~11 minecraft:dirt 0
setblock ~46~47~10 minecraft:stained_hardened_clay 5
setblock ~46~55~10 minecraft:leaves 1
fill ~47~43~10 ~48~43~10 minecraft:stained_hardened_clay 9
setblock ~47~44~10 minecraft:stained_hardened_clay 5
fill ~47~45~10 ~47~45~12 minecraft:stained_hardened_clay 13
setblock ~47~46~10 minecraft:grass
fill ~47~63~10 ~48~63~10 minecraft:stained_hardened_clay 4
fill ~47~64~10 ~48~64~10 minecraft:stained_hardened_clay 3
setblock ~48~44~10 minecraft:stained_hardened_clay 9
setblock ~48~45~10 minecraft:grass
fill ~48~65~10 ~48~65~11 minecraft:stained_hardened_clay 11
fill ~48~66~10 ~48~66~11 minecraft:stained_hardened_clay 3
fill ~49~65~10 ~49~65~11 minecraft:stained_hardened_clay 3
fill ~50~65~10 ~52~65~10 minecraft:stained_hardened_clay 11
fill ~50~66~10 ~50~66~11 minecraft:stained_hardened_clay 3
fill ~51~63~10 ~52~63~10 minecraft:stained_hardened_clay 4
setblock ~51~64~10 minecraft:stained_hardened_clay 11
fill ~51~66~10 ~51~67~10 minecraft:stained_hardened_clay 11
setblock ~52~64~10 minecraft:stained_hardened_clay 3
fill ~52~66~10 ~53~66~10 minecraft:stained_hardened_clay 3
fill ~52~67~10 ~52~67~11 minecraft:stained_hardened_clay 11
setblock ~52~68~10 minecraft:stained_hardened_clay 3
setblock ~53~64~10 minecraft:stained_hardened_clay 4
setblock ~53~65~10 minecraft:stained_hardened_clay 3
fill ~16~42~11 ~16~43~12 minecraft:stained_hardened_clay 9
setblock ~16~44~11 minecraft:stone 5
fill ~17~40~11 ~17~40~15 minecraft:stained_hardened_clay 9
fill ~17~41~11 ~17~43~11 minecraft:stone 5
setblock ~17~44~11 minecraft:dirt 0
setblock ~17~45~11 minecraft:stained_hardened_clay 5
fill ~18~40~11 ~19~40~11 minecraft:stone 5
fill ~18~41~11 ~18~41~13 minecraft:stained_hardened_clay 9
setblock ~18~42~11 minecraft:stone 5
fill ~18~43~11 ~20~43~11 minecraft:stained_hardened_clay 9
fill ~18~44~11 ~18~44~12 minecraft:stained_hardened_clay 13
setblock ~18~45~11 minecraft:dirt 0
setblock ~18~46~11 minecraft:stained_hardened_clay 5
fill ~19~41~11 ~20~41~11 minecraft:stone 5
setblock ~19~44~11 minecraft:stained_hardened_clay 5
setblock ~19~45~11 minecraft:stained_hardened_clay 13
setblock ~19~46~11 minecraft:grass
setblock ~19~47~11 minecraft:stained_hardened_clay 5
fill ~19~48~11 ~19~48~12 minecraft:stained_hardened_clay 13
setblock ~19~49~11 minecraft:stained_hardened_clay 13
setblock ~19~53~11 minecraft:leaves 1
fill ~20~40~11 ~20~40~12 minecraft:stained_hardened_clay 9
fill ~20~42~11 ~21~42~12 minecraft:stone 5
fill ~20~44~11 ~21~44~11 minecraft:stained_hardened_clay 13
setblock ~20~46~11 minecraft:stained_hardened_clay 5
setblock ~20~47~11 minecraft:dirt 0
fill ~20~48~11 ~20~48~12 minecraft:fence 1
setblock ~20~49~11 minecraft:grass
setblock ~20~50~11 minecraft:tallgrass 2
fill ~20~54~11 ~20~54~12 minecraft:leaves 1
setblock ~21~40~11 minecraft:stone 5
fill ~21~43~11 ~21~43~13 minecraft:stone 5
setblock ~21~45~11 minecraft:stained_hardened_clay 5
fill ~21~47~11 ~21~48~11 minecraft:wood 1
setblock ~21~49~11 minecraft:stained_hardened_clay 13
setblock ~21~54~11 minecraft:wood 1
fill ~22~40~11 ~23~40~12 minecraft:stained_hardened_clay 9
fill ~22~42~11 ~22~42~12 minecraft:stained_hardened_clay 9
fill ~22~44~11 ~22~44~12 minecraft:stained_hardened_clay 5
fill ~22~46~11 ~23~46~11 minecraft:dirt 0
fill ~22~48~11 ~22~49~11 minecraft:wood 1
setblock ~22~50~11 minecraft:stained_hardened_clay 5
fill ~22~51~11 ~22~51~12 minecraft:stained_hardened_clay 13
fill ~22~54~11 ~24~54~11 minecraft:leaves 1
fill ~22~55~11 ~23~55~11 minecraft:wood 1
setblock ~22~62~11 minecraft:leaves 1
fill ~23~39~11 ~23~39~12 minecraft:stone 5
fill ~23~42~11 ~24~42~12 minecraft:stone 5
fill ~23~43~11 ~23~44~11 minecraft:stone 5
setblock ~23~45~11 minecraft:dirt 0
fill ~23~47~11 ~23~47~12 minecraft:dirt 0
fill ~23~49~11 ~23~50~12 minecraft:wood 1
setblock ~23~51~11 minecraft:grass
fill ~23~56~11 ~23~56~13 minecraft:leaves 1
fill ~23~60~11 ~23~60~13 minecraft:leaves 1
fill ~24~41~11 ~24~41~14 minecraft:stained_hardened_clay 9
setblock ~24~43~11 minecraft:stained_hardened_clay 9
fill ~24~44~11 ~24~45~12 minecraft:stone 5
fill ~24~47~11 ~24~48~11 minecraft:grass
setblock ~24~49~11 minecraft:dirt 0
fill ~24~50~11 ~27~50~12 minecraft:wood 1
fill ~24~56~11 ~25~56~11 minecraft:wood 1
setblock ~24~61~11 minecraft:leaves 1
setblock ~24~63~11 minecraft:wood 1
setblock ~24~67~11 minecraft:leaves 1
setblock ~25~41~11 minecraft:stone 5
fill ~25~42~11 ~25~42~13 minecraft:stained_hardened_clay 9
fill ~25~45~11 ~25~45~13 minecraft:stone 5
fill ~25~46~11 ~28~46~11 minecraft:stained_hardened_clay 9
fill ~25~47~11 ~25~47~12 minecraft:dirt 0
setblock ~25~48~11 minecraft:stained_hardened_clay 5
setblock ~25~49~11 minecraft:wood 1
fill ~25~51~11 ~25~55~12 minecraft:wood 1
fill ~25~57~11 ~25~59~12 minecraft:wood 1
fill ~25~61~11 ~27~61~12 minecraft:wood 1
setblock ~25~63~11 minecraft:leaves 1
fill ~25~64~11 ~26~64~11 minecraft:wood 1
setblock ~25~65~11 minecraft:leaves 1
fill ~26~40~11 ~26~41~11 minecraft:stained_hardened_clay 9
fill ~26~43~11 ~28~43~11 minecraft:stone 5
setblock ~26~48~11 minecraft:dirt 0
setblock ~26~49~11 minecraft:stained_hardened_clay 13
fill ~26~52~11 ~26~55~12 minecraft:wood 1
fill ~26~58~11 ~26~58~14 minecraft:wood 1
fill ~26~59~11 ~26~60~12 minecraft:wood 1
fill ~26~62~11 ~26~62~12 minecraft:wood 1
setblock ~26~63~11 minecraft:wood 1
fill ~26~65~11 ~26~66~11 minecraft:wood 1
setblock ~26~68~11 minecraft:leaves 1
setblock ~27~40~11 minecraft:stone 5
fill ~27~41~11 ~27~41~14 minecraft:stained_hardened_clay 9
fill ~27~42~11 ~27~42~12 minecraft:stone 5
setblock ~27~44~11 minecraft:stained_hardened_clay 9
fill ~27~45~11 ~29~45~11 minecraft:stone 5
fill ~27~47~11 ~28~47~11 minecraft:dirt 0
setblock ~27~48~11 minecraft:stained_hardened_clay 13
setblock ~27~49~11 minecraft:grass
fill ~27~51~11 ~27~51~12 minecraft:wood 1
fill ~27~58~11 ~28~58~12 minecraft:leaves 1
fill ~27~62~11 ~27~62~12 minecraft:leaves 1
fill ~27~71~11 ~27~71~12 minecraft:leaves 1
fill ~28~37~11 ~30~37~12 minecraft:stone 5
fill ~28~38~11 ~30~38~12 minecraft:stained_hardened_clay 9
fill ~28~39~11 ~28~39~12 minecraft:stone 5
fill ~28~41~11 ~28~41~14 minecraft:stone 5
setblock ~28~42~11 minecraft:stained_hardened_clay 9
fill ~28~44~11 ~29~44~12 minecraft:stone 5
fill ~28~48~11 ~28~48~13 minecraft:dirt 0
fill ~28~50~11 ~29~50~11 minecraft:grass
setblock ~28~51~11 minecraft:tallgrass 2
fill ~28~67~11 ~29~67~11 minecraft:leaves 1
fill ~28~68~11 ~28~68~12 minecraft:leaves 1
setblock ~28~70~11 minecraft:leaves 1
setblock ~28~71~11 minecraft:wood 1
setblock ~28~72~11 minecraft:leaves 1
setblock ~29~39~11 minecraft:stained_hardened_clay 9
setblock ~29~40~11 minecraft:stone 5
fill ~29~42~11 ~30~42~12 minecraft:stone 5
fill ~29~43~11 ~29~43~12 minecraft:stained_hardened_clay 9
fill ~29~47~11 ~29~49~11 minecraft:stained_hardened_clay 13
setblock ~29~51~11 minecraft:double_plant ["double_plant_type":"paeonia","upper_block_bit":false]
fill ~29~61~11 ~30~61~12 minecraft:leaves 1
setblock ~29~66~11 minecraft:leaves 1
fill ~30~39~11 ~31~39~11 minecraft:stone 5
fill ~30~40~11 ~31~41~12 minecraft:stained_hardened_clay 9
fill ~30~43~11 ~31~43~11 minecraft:stone 5
fill ~30~44~11 ~30~44~13 minecraft:stained_hardened_clay 9
setblock ~30~45~11 minecraft:stained_hardened_clay 9
fill ~30~47~11 ~31~47~12 minecraft:stone 5
setblock ~30~48~11 minecraft:stained_hardened_clay 13
fill ~30~49~11 ~30~50~11 minecraft:stained_hardened_clay 5
fill ~30~56~11 ~30~56~13 minecraft:leaves 1
fill ~30~60~11 ~30~60~12 minecraft:wood 1
fill ~31~36~11 ~31~36~12 minecraft:stained_hardened_clay 9
fill ~31~37~11 ~33~37~11 minecraft:stained_hardened_clay 9
setblock ~31~42~11 minecraft:stained_hardened_clay 9
setblock ~31~45~11 minecraft:stone 5
setblock ~31~46~11 minecraft:stained_hardened_clay 9
fill ~31~48~11 ~31~48~12 minecraft:dirt 0
fill ~31~49~11 ~32~49~11 minecraft:stained_hardened_clay 13
fill ~31~60~11 ~31~60~12 minecraft:leaves 1
setblock ~31~66~11 minecraft:leaves 1
fill ~32~35~11 ~33~36~11 minecraft:stone 5
fill ~32~38~11 ~32~38~15 minecraft:stone 5
fill ~32~40~11 ~32~40~12 minecraft:stone 5
fill ~32~41~11 ~32~42~11 minecraft:stone 5
setblock ~32~43~11 minecraft:stained_hardened_clay 9
fill ~32~44~11 ~33~44~11 minecraft:stone 5
fill ~32~45~11 ~33~45~11 minecraft:stained_hardened_clay 9
fill ~32~48~11 ~32~48~14 minecraft:stained_hardened_clay 5
fill ~32~50~11 ~32~50~13 minecraft:grass
fill ~33~39~11 ~33~39~12 minecraft:stone 5
fill ~33~40~11 ~34~41~11 minecraft:stained_hardened_clay 9
setblock ~33~43~11 minecraft:stone 5
fill ~33~46~11 ~33~47~11 minecraft:stone 5
setblock ~33~48~11 minecraft:stained_hardened_clay 13
setblock ~33~49~11 minecraft:grass
fill ~33~50~11 ~33~50~12 minecraft:stained_hardened_clay 13
fill ~33~51~11 ~37~51~11 minecraft:stained_hardened_clay 13
fill ~34~34~11 ~34~34~13 minecraft:stone 5
fill ~34~35~11 ~34~36~11 minecraft:stained_hardened_clay 9
setblock ~34~37~11 minecraft:stone 5
fill ~34~38~11 ~34~38~12 minecraft:stained_hardened_clay 9
setblock ~34~39~11 minecraft:stained_hardened_clay 9
setblock ~34~42~11 minecraft:stained_hardened_clay 9
fill ~34~44~11 ~34~44~13 minecraft:stained_hardened_clay 9
fill ~34~45~11 ~34~45~12 minecraft:stone 5
fill ~34~46~11 ~34~47~12 minecraft:stained_hardened_clay 9
setblock ~34~48~11 minecraft:stone 0
fill ~34~49~11 ~34~50~11 minecraft:stained_hardened_clay 5
setblock ~34~52~11 minecraft:grass
fill ~35~35~11 ~35~36~11 minecraft:stone 5
fill ~35~38~11 ~36~38~11 minecraft:stone 5
setblock ~35~39~11 minecraft:stone 5
fill ~35~41~11 ~36~41~11 minecraft:stone 5
fill ~35~42~11 ~35~42~12 minecraft:stone 5
fill ~35~43~11 ~36~43~11 minecraft:stained_hardened_clay 9
fill ~35~44~11 ~36~44~11 minecraft:stone 5
setblock ~35~48~11 minecraft:stained_hardened_clay 13
setblock ~35~49~11 minecraft:grass
setblock ~35~50~11 minecraft:stained_hardened_clay 13
fill ~35~52~11 ~37~52~11 minecraft:stained_hardened_clay 13
fill ~36~35~11 ~36~35~14 minecraft:stained_hardened_clay 9
fill ~36~36~11 ~36~36~14 minecraft:stone 5
setblock ~36~37~11 minecraft:stone 5
fill ~36~39~11 ~37~39~11 minecraft:stained_hardened_clay 9
setblock ~36~42~11 minecraft:stained_hardened_clay 9
setblock ~36~45~11 minecraft:stone 5
fill ~36~47~11 ~36~47~12 minecraft:stained_hardened_clay 9
fill ~36~48~11 ~36~49~11 minecraft:stained_hardened_clay 5
fill ~36~50~11 ~36~50~14 minecraft:dirt 0
fill ~37~35~11 ~37~35~14 minecraft:stone 5
fill ~37~36~11 ~37~36~14 minecraft:stained_hardened_clay 9
fill ~37~37~11 ~37~38~11 minecraft:stained_hardened_clay 9
setblock ~37~40~11 minecraft:stone 5
setblock ~37~43~11 minecraft:stone 5
fill ~37~44~11 ~37~44~15 minecraft:stained_hardened_clay 9
fill ~37~45~11 ~37~45~12 minecraft:stained_hardened_clay 9
setblock ~37~46~11 minecraft:stained_hardened_clay 9
fill ~37~48~11 ~37~49~11 minecraft:fence 1
setblock ~37~55~11 minecraft:leaves 1
setblock ~38~36~11 minecraft:stone 5
fill ~38~38~11 ~38~38~15 minecraft:stone 5
fill ~38~39~11 ~38~39~14 minecraft:stone 5
fill ~38~40~11 ~38~40~13 minecraft:stained_hardened_clay 9
fill ~38~41~11 ~38~42~11 minecraft:stone 5
fill ~38~43~11 ~39~43~11 minecraft:stained_hardened_clay 9
setblock ~38~44~11 minecraft:stone 5
fill ~38~46~11 ~39~46~11 minecraft:stone 5
fill ~38~48~11 ~38~49~11 minecraft:wood 1
setblock ~38~50~11 minecraft:stained_hardened_clay 13
setblock ~38~52~11 minecraft:stained_hardened_clay 5
setblock ~38~55~11 minecraft:wood 1
fill ~39~37~11 ~39~37~13 minecraft:stone 5
fill ~39~39~11 ~40~39~11 minecraft:stained_hardened_clay 9
fill ~39~42~11 ~39~42~12 minecraft:stained_hardened_clay 9
fill ~39~44~11 ~40~44~12 minecraft:stained_hardened_clay 9
fill ~39~45~11 ~39~45~15 minecraft:stone 5
setblock ~39~47~11 minecraft:stained_hardened_clay 13
fill ~39~48~11 ~40~48~11 minecraft:dirt 0
fill ~39~49~11 ~40~49~11 minecraft:stained_hardened_clay 13
setblock ~39~50~11 minecraft:grass
setblock ~39~51~11 minecraft:stained_hardened_clay 5
setblock ~39~52~11 minecraft:stained_hardened_clay 13
fill ~39~55~11 ~39~55~13 minecraft:leaves 1
setblock ~39~56~11 minecraft:leaves 1
fill ~40~35~11 ~40~35~14 minecraft:stone 5
fill ~40~36~11 ~40~36~12 minecraft:stained_hardened_clay 9
setblock ~40~37~11 minecraft:stained_hardened_clay 9
setblock ~40~38~11 minecraft:stone 5
fill ~40~41~11 ~40~41~12 minecraft:stone 5
fill ~40~43~11 ~42~43~11 minecraft:stone 5
fill ~40~45~11 ~41~45~11 minecraft:stained_hardened_clay 5
fill ~40~47~11 ~41~47~12 minecraft:dirt 0
setblock ~40~50~11 minecraft:stained_hardened_clay 13
setblock ~40~51~11 minecraft:dirt 0
setblock ~40~61~11 minecraft:leaves 1
setblock ~41~37~11 minecraft:stone 5
setblock ~41~38~11 minecraft:stained_hardened_clay 9
fill ~41~41~11 ~41~41~15 minecraft:stained_hardened_clay 9
setblock ~41~42~11 minecraft:stone 5
fill ~41~44~11 ~42~44~11 minecraft:stained_hardened_clay 13
setblock ~41~46~11 minecraft:stained_hardened_clay 5
setblock ~41~48~11 minecraft:stained_hardened_clay 13
setblock ~41~49~11 minecraft:grass
setblock ~41~50~11 minecraft:stained_hardened_clay 5
setblock ~41~51~11 minecraft:stained_hardened_clay 13
fill ~41~61~11 ~41~61~12 minecraft:wood 1
fill ~41~62~11 ~41~62~12 minecraft:leaves 1
setblock ~42~38~11 minecraft:stone 5
fill ~42~40~11 ~42~41~11 minecraft:stone 5
fill ~42~45~11 ~42~46~13 minecraft:stained_hardened_clay 13
setblock ~42~47~11 minecraft:fence 1
fill ~42~48~11 ~42~48~12 minecraft:wood 1
setblock ~42~49~11 minecraft:stained_hardened_clay 5
fill ~42~50~11 ~42~50~12 minecraft:grass
setblock ~42~61~11 minecraft:leaves 1
fill ~43~39~11 ~44~39~11 minecraft:stained_hardened_clay 9
setblock ~43~40~11 minecraft:stained_hardened_clay 9
fill ~43~43~11 ~43~45~11 minecraft:stained_hardened_clay 5
fill ~43~46~11 ~43~46~12 minecraft:stained_hardened_clay 13
fill ~43~47~11 ~44~47~11 minecraft:stained_hardened_clay 13
setblock ~43~48~11 minecraft:dirt 0
fill ~43~49~11 ~43~49~12 minecraft:stained_hardened_clay 13
setblock ~44~42~11 minecraft:stone 5
fill ~44~43~11 ~45~43~11 minecraft:stained_hardened_clay 13
fill ~44~44~11 ~46~44~11 minecraft:stained_hardened_clay 5
fill ~44~45~11 ~44~46~11 minecraft:dirt 0
setblock ~44~49~11 minecraft:stained_hardened_clay 5
fill ~44~56~11 ~44~56~12 minecraft:leaves 1
fill ~44~58~11 ~44~58~13 minecraft:leaves 1
setblock ~45~42~11 minecraft:stained_hardened_clay 9
fill ~45~46~11 ~45~47~11 minecraft:stained_hardened_clay 5
fill ~45~48~11 ~45~49~11 minecraft:grass
setblock ~45~55~11 minecraft:leaves 1
setblock ~45~56~11 minecraft:wood 1
fill ~46~40~11 ~46~40~12 minecraft:stone 5
fill ~46~42~11 ~46~43~11 minecraft:stone 5
fill ~46~45~11 ~46~45~13 minecraft:stained_hardened_clay 5
setblock ~46~47~11 minecraft:stained_hardened_clay 13
setblock ~46~56~11 minecraft:leaves 1
setblock ~46~63~11 minecraft:stained_hardened_clay 4
setblock ~46~64~11 minecraft:stained_hardened_clay 11
setblock ~46~65~11 minecraft:stained_hardened_clay 3
fill ~47~41~11 ~48~41~11 minecraft:stained_hardened_clay 9
fill ~47~42~11 ~47~42~13 minecraft:stained_hardened_clay 9
fill ~47~43~11 ~48~43~11 minecraft:stone 5
setblock ~47~44~11 minecraft:dirt 0
fill ~47~46~11 ~48~46~11 minecraft:dirt 0
fill ~47~47~11 ~48~47~11 minecraft:stained_hardened_clay 5
setblock ~47~65~11 minecraft:stained_hardened_clay 11
fill ~47~67~11 ~48~67~11 minecraft:stained_hardened_clay 11
setblock ~48~42~11 minecraft:stone 5
fill ~48~44~11 ~48~44~12 minecraft:stone 5
setblock ~48~45~11 minecraft:stained_hardened_clay 13
fill ~49~42~11 ~49~42~12 minecraft:stained_hardened_clay 9
fill ~49~43~11 ~50~43~11 minecraft:stained_hardened_clay 9
setblock ~49~44~11 minecraft:stained_hardened_clay 9
fill ~49~45~11 ~50~45~12 minecraft:stone 5
fill ~49~46~11 ~49~46~12 minecraft:stained_hardened_clay 13
fill ~49~66~11 ~49~68~11 minecraft:stained_hardened_clay 3
setblock ~50~42~11 minecraft:stone 5
fill ~50~44~11 ~50~44~12 minecraft:stone 5
fill ~50~67~11 ~51~68~11 minecraft:stained_hardened_clay 11
fill ~50~69~11 ~51~69~11 minecraft:stained_hardened_clay 3
setblock ~51~66~11 minecraft:stained_hardened_clay 3
fill ~52~68~11 ~53~68~11 minecraft:stained_hardened_clay 11
fill ~53~66~11 ~54~66~11 minecraft:stained_hardened_clay 3
setblock ~53~67~11 minecraft:stained_hardened_clay 11
setblock ~54~64~11 minecraft:stained_hardened_clay 4
fill ~54~65~11 ~54~65~12 minecraft:stained_hardened_clay 11
fill ~16~41~12 ~16~41~15 minecraft:stone 5
setblock ~16~44~12 minecraft:stained_hardened_clay 5
fill ~16~45~12 ~17~45~12 minecraft:stained_hardened_clay 13
fill ~16~46~12 ~17~46~12 minecraft:grass
fill ~16~47~12 ~17~47~12 minecraft:tallgrass 2
fill ~17~41~12 ~17~43~12 minecraft:stained_hardened_clay 9
setblock ~17~44~12 minecraft:grass
setblock ~18~40~12 minecraft:stained_hardened_clay 9
fill ~18~42~12 ~18~42~13 minecraft:stained_hardened_clay 9
fill ~18~43~12 ~19~43~12 minecraft:stained_hardened_clay 9
setblock ~18~45~12 minecraft:grass
fill ~18~46~12 ~19~46~12 minecraft:stained_hardened_clay 13
fill ~18~47~12 ~18~47~13 minecraft:stained_hardened_clay 5
setblock ~18~48~12 minecraft:stained_hardened_clay 13
setblock ~19~40~12 minecraft:stone 5
fill ~19~41~12 ~20~41~12 minecraft:stained_hardened_clay 9
fill ~19~42~12 ~19~42~20 minecraft:stone 5
fill ~19~44~12 ~20~44~12 minecraft:stained_hardened_clay 13
setblock ~19~45~12 minecraft:dirt 0
setblock ~19~47~12 minecraft:dirt 0
fill ~19~49~12 ~21~49~12 minecraft:stained_hardened_clay 5
setblock ~20~39~12 minecraft:stone 5
fill ~20~43~12 ~20~43~14 minecraft:stone 5
setblock ~20~45~12 minecraft:stained_hardened_clay 5
setblock ~20~46~12 minecraft:grass
fill ~20~47~12 ~21~47~12 minecraft:stained_hardened_clay 13
setblock ~20~50~12 minecraft:stained_hardened_clay 5
fill ~21~39~12 ~22~39~12 minecraft:stained_hardened_clay 9
fill ~21~40~12 ~21~40~14 minecraft:stained_hardened_clay 9
fill ~21~44~12 ~21~45~12 minecraft:dirt 0
fill ~21~48~12 ~22~48~12 minecraft:stained_hardened_clay 13
fill ~21~50~12 ~21~50~14 minecraft:grass
setblock ~21~59~12 minecraft:leaves 1
setblock ~22~41~12 minecraft:stone 5
fill ~22~43~12 ~22~43~13 minecraft:stone 5
fill ~22~45~12 ~22~45~14 minecraft:dirt 0
setblock ~22~46~12 minecraft:dirt 0
setblock ~22~47~12 minecraft:grass
fill ~22~49~12 ~22~49~13 minecraft:stained_hardened_clay 13
setblock ~22~50~12 minecraft:dirt 0
setblock ~22~55~12 minecraft:leaves 1
setblock ~22~60~12 minecraft:wood 1
fill ~23~43~12 ~23~43~13 minecraft:stained_hardened_clay 9
setblock ~23~44~12 minecraft:stone 5
fill ~23~45~12 ~23~45~13 minecraft:stained_hardened_clay 5
setblock ~23~46~12 minecraft:stained_hardened_clay 5
setblock ~23~48~12 minecraft:dirt 0
fill ~23~51~12 ~23~51~13 minecraft:stained_hardened_clay 5
setblock ~23~54~12 minecraft:leaves 1
setblock ~23~55~12 minecraft:wood 1
fill ~24~39~12 ~24~39~13 minecraft:stained_hardened_clay 9
fill ~24~40~12 ~24~40~13 minecraft:stone 5
fill ~24~43~12 ~24~43~13 minecraft:stone 5
setblock ~24~46~12 minecraft:dirt 0
setblock ~24~47~12 minecraft:stained_hardened_clay 13
setblock ~24~48~12 minecraft:stained_hardened_clay 5
setblock ~24~49~12 minecraft:wood 1
setblock ~24~56~12 minecraft:leaves 1
fill ~24~58~12 ~24~58~14 minecraft:leaves 1
fill ~24~59~12 ~24~60~13 minecraft:leaves 1
setblock ~24~61~12 minecraft:wood 1
fill ~25~39~12 ~25~39~14 minecraft:stone 5
fill ~25~41~12 ~26~41~13 minecraft:stained_hardened_clay 9
fill ~25~46~12 ~26~46~13 minecraft:stained_hardened_clay 9
fill ~25~48~12 ~25~49~12 minecraft:stained_hardened_clay 13
fill ~25~56~12 ~26~56~12 minecraft:wood 1
setblock ~25~60~12 minecraft:wood 1
setblock ~25~62~12 minecraft:leaves 1
fill ~26~40~12 ~26~40~13 minecraft:stone 5
setblock ~26~43~12 minecraft:stone 5
fill ~26~45~12 ~26~45~14 minecraft:stone 5
setblock ~26~47~12 minecraft:stained_hardened_clay 9
setblock ~26~48~12 minecraft:stained_hardened_clay 5
setblock ~26~49~12 minecraft:wood 1
setblock ~26~57~12 minecraft:wood 1
fill ~26~64~12 ~26~64~13 minecraft:wood 1
fill ~26~65~12 ~26~66~12 minecraft:leaves 1
setblock ~27~40~12 minecraft:stained_hardened_clay 9
fill ~27~43~12 ~28~43~12 minecraft:stained_hardened_clay 9
setblock ~27~44~12 minecraft:stone 5
setblock ~27~45~12 minecraft:stained_hardened_clay 9
fill ~27~46~12 ~27~47~12 minecraft:stone 5
fill ~27~48~12 ~27~48~15 minecraft:dirt 0
fill ~27~49~12 ~28~49~12 minecraft:stained_hardened_clay 13
setblock ~28~42~12 minecraft:stone 5
fill ~28~45~12 ~30~45~12 minecraft:stone 5
fill ~28~46~12 ~29~47~12 minecraft:stained_hardened_clay 9
setblock ~28~50~12 minecraft:stained_hardened_clay 5
fill ~28~56~12 ~28~56~13 minecraft:leaves 1
setblock ~28~57~12 minecraft:wood 1
setblock ~28~62~12 minecraft:leaves 1
fill ~29~35~12 ~30~35~13 minecraft:stone 5
setblock ~29~36~12 minecraft:stone 5
fill ~29~39~12 ~29~39~13 minecraft:stone 5
fill ~29~40~12 ~29~41~12 minecraft:stained_hardened_clay 9
fill ~29~48~12 ~30~48~12 minecraft:dirt 0
fill ~29~49~12 ~29~49~14 minecraft:stained_hardened_clay 5
setblock ~29~55~12 minecraft:leaves 1
setblock ~29~56~12 minecraft:wood 1
fill ~29~57~12 ~29~57~13 minecraft:leaves 1
setblock ~29~70~12 minecraft:leaves 1
setblock ~30~36~12 minecraft:stained_hardened_clay 9
fill ~30~39~12 ~31~39~12 minecraft:stained_hardened_clay 9
fill ~30~43~12 ~31~43~12 minecraft:stained_hardened_clay 9
fill ~30~49~12 ~31~49~12 minecraft:stained_hardened_clay 13
setblock ~30~50~12 minecraft:stained_hardened_clay 13
fill ~31~35~12 ~32~35~12 minecraft:stained_hardened_clay 9
fill ~31~37~12 ~32~37~12 minecraft:stone 5
fill ~31~42~12 ~32~42~12 minecraft:stone 5
fill ~31~44~12 ~31~44~15 minecraft:stained_hardened_clay 9
fill ~31~45~12 ~32~45~12 minecraft:stained_hardened_clay 9
setblock ~31~46~12 minecraft:stone 5
fill ~31~50~12 ~31~50~13 minecraft:grass
setblock ~31~51~12 minecraft:tallgrass 0
setblock ~31~56~12 minecraft:wood 1
fill ~32~34~12 ~33~34~12 minecraft:stone 5
setblock ~32~36~12 minecraft:stone 5
setblock ~32~41~12 minecraft:stained_hardened_clay 9
fill ~32~43~12 ~32~44~12 minecraft:stone 5
setblock ~32~49~12 minecraft:grass
setblock ~32~51~12 minecraft:tallgrass 2
setblock ~32~55~12 minecraft:leaves 1
fill ~33~33~12 ~33~33~13 minecraft:stained_hardened_clay 9
fill ~33~35~12 ~34~35~12 minecraft:stone 5
fill ~33~36~12 ~33~37~12 minecraft:stained_hardened_clay 9
fill ~33~40~12 ~34~40~13 minecraft:stone 5
fill ~33~41~12 ~33~41~15 minecraft:stone 5
fill ~33~43~12 ~33~43~13 minecraft:stained_hardened_clay 9
setblock ~33~44~12 minecraft:stained_hardened_clay 9
fill ~33~45~12 ~33~45~14 minecraft:stone 5
fill ~33~46~12 ~33~47~12 minecraft:stained_hardened_clay 9
setblock ~33~48~12 minecraft:stained_hardened_clay 5
fill ~33~49~12 ~33~49~13 minecraft:dirt 0
setblock ~34~33~12 minecraft:stone 5
setblock ~34~36~12 minecraft:stone 5
fill ~34~37~12 ~34~37~13 minecraft:stained_hardened_clay 9
setblock ~34~39~12 minecraft:stone 5
fill ~34~41~12 ~35~41~13 minecraft:stained_hardened_clay 9
setblock ~34~42~12 minecraft:stone 5
fill ~34~48~12 ~34~48~13 minecraft:stained_hardened_clay 13
fill ~34~49~12 ~34~50~12 minecraft:grass
fill ~35~34~12 ~35~36~12 minecraft:stained_hardened_clay 9
fill ~35~38~12 ~36~38~12 minecraft:stained_hardened_clay 9
fill ~35~39~12 ~35~40~12 minecraft:stained_hardened_clay 9
fill ~35~43~12 ~35~46~12 minecraft:stained_hardened_clay 9
fill ~35~47~12 ~35~47~14 minecraft:stone 5
setblock ~35~48~12 minecraft:stone 0
fill ~35~49~12 ~36~49~12 minecraft:stained_hardened_clay 13
fill ~35~50~12 ~35~50~14 minecraft:stained_hardened_clay 5
fill ~35~51~12 ~36~51~12 minecraft:stained_hardened_clay 5
setblock ~36~37~12 minecraft:stained_hardened_clay 9
fill ~36~39~12 ~37~39~12 minecraft:stone 5
fill ~36~41~12 ~36~43~12 minecraft:stone 5
fill ~36~44~12 ~36~44~15 minecraft:stained_hardened_clay 9
setblock ~36~45~12 minecraft:stained_hardened_clay 9
fill ~36~46~12 ~38~46~12 minecraft:stone 5
setblock ~36~48~12 minecraft:dirt 0
setblock ~36~52~12 minecraft:grass
setblock ~36~53~12 minecraft:double_plant 3
setblock ~36~59~12 minecraft:leaves 1
setblock ~37~34~12 minecraft:stained_hardened_clay 9
fill ~37~37~12 ~38~37~12 minecraft:stone 5
setblock ~37~38~12 minecraft:stone 5
fill ~37~40~12 ~37~40~13 minecraft:stained_hardened_clay 9
fill ~37~41~12 ~38~41~12 minecraft:stained_hardened_clay 9
fill ~37~43~12 ~37~43~14 minecraft:stained_hardened_clay 9
setblock ~37~47~12 minecraft:stained_hardened_clay 9
setblock ~37~48~12 minecraft:grass
fill ~37~49~12 ~37~49~14 minecraft:stained_hardened_clay 5
setblock ~37~50~12 minecraft:dirt 0
fill ~37~51~12 ~38~51~12 minecraft:stained_hardened_clay 13
setblock ~37~52~12 minecraft:stained_hardened_clay 13
setblock ~37~60~12 minecraft:leaves 1
fill ~38~36~12 ~39~36~14 minecraft:stained_hardened_clay 9
fill ~38~42~12 ~38~43~12 minecraft:stone 5
fill ~38~44~12 ~38~45~12 minecraft:stained_hardened_clay 9
fill ~38~47~12 ~39~47~12 minecraft:stone 5
fill ~38~48~12 ~39~48~12 minecraft:dirt 0
fill ~38~49~12 ~39~50~12 minecraft:wood 1
fill ~38~52~12 ~39~52~12 minecraft:grass
fill ~38~55~12 ~38~56~12 minecraft:leaves 1
setblock ~38~61~12 minecraft:leaves 1
setblock ~39~35~12 minecraft:stone 5
fill ~39~38~12 ~40~38~14 minecraft:stained_hardened_clay 9
fill ~39~39~12 ~39~41~12 minecraft:stone 5
setblock ~39~43~12 minecraft:stone 5
setblock ~39~46~12 minecraft:stained_hardened_clay 9
setblock ~39~51~12 minecraft:grass
fill ~39~56~12 ~39~56~13 minecraft:wood 1
setblock ~39~63~12 minecraft:leaves 1
setblock ~40~37~12 minecraft:stone 5
fill ~40~39~12 ~40~40~12 minecraft:stained_hardened_clay 9
fill ~40~42~12 ~41~42~13 minecraft:stained_hardened_clay 9
fill ~40~43~12 ~40~43~15 minecraft:stained_hardened_clay 9
fill ~40~45~12 ~40~45~14 minecraft:stone 5
setblock ~40~46~12 minecraft:grass
fill ~40~48~12 ~40~50~12 minecraft:stained_hardened_clay 5
setblock ~40~51~12 minecraft:stained_hardened_clay 13
fill ~40~56~12 ~40~57~12 minecraft:leaves 1
fill ~40~62~12 ~40~62~14 minecraft:leaves 1
setblock ~40~64~12 minecraft:leaves 1
setblock ~40~67~12 minecraft:leaves 1
fill ~41~36~12 ~41~37~12 minecraft:stained_hardened_clay 9
fill ~41~38~12 ~41~38~13 minecraft:stone 5
setblock ~41~39~12 minecraft:stone 5
fill ~41~40~12 ~42~40~12 minecraft:stained_hardened_clay 9
fill ~41~43~12 ~42~43~12 minecraft:stone 5
setblock ~41~44~12 minecraft:stained_hardened_clay 9
setblock ~41~45~12 minecraft:stained_hardened_clay 5
setblock ~41~46~12 minecraft:stained_hardened_clay 13
fill ~41~48~12 ~41~49~12 minecraft:wood 1
setblock ~41~50~12 minecraft:stained_hardened_clay 13
fill ~41~51~12 ~41~51~13 minecraft:stained_hardened_clay 5
setblock ~41~68~12 minecraft:leaves 1
setblock ~42~38~12 minecraft:stained_hardened_clay 9
fill ~42~41~12 ~42~41~16 minecraft:stained_hardened_clay 9
setblock ~42~44~12 minecraft:stained_hardened_clay 13
setblock ~42~47~12 minecraft:stained_hardened_clay 13
setblock ~42~49~12 minecraft:grass
fill ~42~58~12 ~43~58~12 minecraft:leaves 1
fill ~43~38~12 ~43~38~14 minecraft:stone 5
setblock ~43~39~12 minecraft:stained_hardened_clay 9
fill ~43~40~12 ~43~40~13 minecraft:stone 5
setblock ~43~42~12 minecraft:stone 5
fill ~43~43~12 ~47~43~12 minecraft:stained_hardened_clay 9
setblock ~43~44~12 minecraft:dirt 0
setblock ~43~45~12 minecraft:stained_hardened_clay 5
fill ~43~47~12 ~43~47~13 minecraft:dirt 0
setblock ~43~48~12 minecraft:fence 1
setblock ~43~57~12 minecraft:leaves 1
setblock ~43~65~12 minecraft:leaves 1
fill ~44~39~12 ~45~39~12 minecraft:stone 5
fill ~44~40~12 ~44~40~13 minecraft:stained_hardened_clay 9
fill ~44~41~12 ~46~41~12 minecraft:stained_hardened_clay 9
fill ~44~42~12 ~44~42~14 minecraft:stained_hardened_clay 9
setblock ~44~44~12 minecraft:stained_hardened_clay 5
setblock ~44~45~12 minecraft:grass
fill ~44~46~12 ~44~47~12 minecraft:stained_hardened_clay 5
fill ~44~49~12 ~44~49~13 minecraft:stained_hardened_clay 13
setblock ~44~57~12 minecraft:wood 1
fill ~45~40~12 ~45~40~16 minecraft:stone 5
fill ~45~42~12 ~45~42~13 minecraft:stone 5
setblock ~45~44~12 minecraft:grass
fill ~45~45~12 ~45~46~12 minecraft:dirt 0
setblock ~45~47~12 minecraft:stained_hardened_clay 13
fill ~45~48~12 ~46~48~12 minecraft:dirt 0
setblock ~45~49~12 minecraft:stained_hardened_clay 5
fill ~45~57~12 ~45~58~12 minecraft:leaves 1
setblock ~45~63~12 minecraft:stained_hardened_clay 4
fill ~45~64~12 ~45~64~13 minecraft:stained_hardened_clay 3
fill ~45~65~12 ~45~65~13 minecraft:stained_hardened_clay 11
fill ~45~66~12 ~46~66~12 minecraft:stained_hardened_clay 3
fill ~46~42~12 ~46~42~16 minecraft:stained_hardened_clay 9
setblock ~46~44~12 minecraft:stained_hardened_clay 5
setblock ~46~46~12 minecraft:stained_hardened_clay 13
fill ~46~47~12 ~46~47~13 minecraft:stained_hardened_clay 5
setblock ~46~49~12 minecraft:grass
setblock ~46~67~12 minecraft:stained_hardened_clay 3
fill ~47~40~12 ~48~40~12 minecraft:stained_hardened_clay 9
fill ~47~41~12 ~49~41~12 minecraft:stone 5
setblock ~47~44~12 minecraft:stone 5
setblock ~47~46~12 minecraft:stained_hardened_clay 5
fill ~47~47~12 ~48~47~12 minecraft:dirt 0
setblock ~47~48~12 minecraft:grass
fill ~47~66~12 ~49~66~12 minecraft:stained_hardened_clay 11
setblock ~47~67~12 minecraft:stained_hardened_clay 11
setblock ~47~68~12 minecraft:stained_hardened_clay 3
fill ~48~42~12 ~48~42~14 minecraft:stained_hardened_clay 9
fill ~48~43~12 ~49~43~12 minecraft:stone 5
setblock ~48~45~12 minecraft:stained_hardened_clay 5
setblock ~48~46~12 minecraft:dirt 0
fill ~48~48~12 ~48~48~13 minecraft:stained_hardened_clay 5
setblock ~48~68~12 minecraft:stained_hardened_clay 11
fill ~48~69~12 ~49~69~12 minecraft:stained_hardened_clay 3
fill ~49~40~12 ~49~40~13 minecraft:stone 5
fill ~49~44~12 ~49~44~14 minecraft:stone 5
fill ~49~47~12 ~49~47~14 minecraft:stained_hardened_clay 13
setblock ~49~67~12 minecraft:stained_hardened_clay 11
setblock ~49~68~12 minecraft:stained_hardened_clay 3
fill ~50~40~12 ~50~43~12 minecraft:stained_hardened_clay 9
setblock ~50~46~12 minecraft:grass
fill ~50~68~12 ~50~69~12 minecraft:stained_hardened_clay 11
fill ~51~42~12 ~51~42~16 minecraft:stone 5
fill ~51~43~12 ~51~43~13 minecraft:stained_hardened_clay 9
fill ~51~44~12 ~51~45~12 minecraft:stone 5
setblock ~51~68~12 minecraft:stained_hardened_clay 3
setblock ~51~69~12 minecraft:stained_hardened_clay 11
setblock ~52~68~12 minecraft:stained_hardened_clay 11
fill ~52~69~12 ~53~69~12 minecraft:stained_hardened_clay 3
setblock ~54~63~12 minecraft:stained_hardened_clay 4
setblock ~54~64~12 minecraft:stained_hardened_clay 3
setblock ~54~66~12 minecraft:stained_hardened_clay 11
setblock ~54~67~12 minecraft:stained_hardened_clay 3
setblock ~54~68~12 minecraft:stained_hardened_clay 11
fill ~15~42~13 ~17~43~13 minecraft:stone 5
fill ~15~44~13 ~15~44~15 minecraft:stained_hardened_clay 9
setblock ~15~45~13 minecraft:dirt 0
fill ~15~46~13 ~15~46~14 minecraft:stained_hardened_clay 13
setblock ~16~44~13 minecraft:stained_hardened_clay 13
setblock ~16~45~13 minecraft:stained_hardened_clay 5
fill ~16~46~13 ~16~46~14 minecraft:grass
setblock ~16~47~13 minecraft:tallgrass 0
setblock ~17~41~13 minecraft:stone 5
setblock ~17~44~13 minecraft:stained_hardened_clay 5
fill ~17~45~13 ~18~45~13 minecraft:stained_hardened_clay 13
fill ~17~46~13 ~17~47~13 minecraft:stained_hardened_clay 5
fill ~18~39~13 ~19~39~13 minecraft:stone 5
fill ~18~40~13 ~18~40~14 minecraft:stone 5
fill ~18~43~13 ~19~43~14 minecraft:stone 5
fill ~18~44~13 ~19~44~14 minecraft:dirt 0
fill ~18~46~13 ~18~46~14 minecraft:dirt 0
setblock ~18~48~13 minecraft:grass
fill ~18~49~13 ~18~50~13 minecraft:stained_hardened_clay 13
fill ~19~40~13 ~19~41~15 minecraft:stained_hardened_clay 9
fill ~19~45~13 ~19~47~13 minecraft:stained_hardened_clay 5
setblock ~19~48~13 minecraft:dirt 0
fill ~19~49~13 ~19~50~14 minecraft:stained_hardened_clay 5
setblock ~20~39~13 minecraft:stained_hardened_clay 9
fill ~20~40~13 ~20~40~17 minecraft:stone 5
fill ~20~41~13 ~20~41~14 minecraft:stone 5
setblock ~20~42~13 minecraft:stained_hardened_clay 9
setblock ~20~44~13 minecraft:stained_hardened_clay 13
fill ~20~45~13 ~20~46~14 minecraft:dirt 0
setblock ~20~47~13 minecraft:dirt 0
fill ~20~48~13 ~21~48~13 minecraft:stained_hardened_clay 5
fill ~20~49~13 ~20~49~14 minecraft:stained_hardened_clay 13
setblock ~20~50~13 minecraft:grass
setblock ~20~51~13 minecraft:double_plant ["double_plant_type":"paeonia","upper_block_bit":false]
fill ~20~58~13 ~22~58~13 minecraft:leaves 1
setblock ~21~39~13 minecraft:stone 5
fill ~21~42~13 ~22~42~15 minecraft:stone 5
setblock ~21~44~13 minecraft:stained_hardened_clay 5
setblock ~21~45~13 minecraft:stained_hardened_clay 13
setblock ~21~46~13 minecraft:dirt 0
fill ~21~47~13 ~22~47~13 minecraft:stained_hardened_clay 13
setblock ~21~49~13 minecraft:dirt 0
setblock ~21~51~13 minecraft:tallgrass 2
fill ~21~59~13 ~22~59~13 minecraft:wood 1
fill ~21~60~13 ~22~60~13 minecraft:leaves 1
fill ~22~39~13 ~23~39~14 minecraft:stained_hardened_clay 9
fill ~22~40~13 ~23~40~14 minecraft:stone 5
fill ~22~41~13 ~22~41~20 minecraft:stained_hardened_clay 9
fill ~22~44~13 ~25~44~13 minecraft:stained_hardened_clay 9
fill ~22~46~13 ~24~46~13 minecraft:stained_hardened_clay 13
setblock ~22~48~13 minecraft:stained_hardened_clay 13
setblock ~22~50~13 minecraft:grass
setblock ~22~51~13 minecraft:tallgrass 0
setblock ~23~42~13 minecraft:stained_hardened_clay 9
fill ~23~47~13 ~24~47~13 minecraft:stained_hardened_clay 5
setblock ~23~48~13 minecraft:grass
setblock ~23~49~13 minecraft:fence 1
setblock ~23~50~13 minecraft:stained_hardened_clay 13
fill ~23~61~13 ~24~61~13 minecraft:leaves 1
setblock ~24~38~13 minecraft:stained_hardened_clay 9
fill ~24~42~13 ~24~42~15 minecraft:stone 5
setblock ~24~45~13 minecraft:stone 5
setblock ~24~48~13 minecraft:dirt 0
setblock ~24~49~13 minecraft:grass
setblock ~24~50~13 minecraft:wood 1
setblock ~24~51~13 minecraft:stained_hardened_clay 13
setblock ~24~57~13 minecraft:leaves 1
setblock ~25~40~13 minecraft:stone 5
fill ~25~43~13 ~25~43~14 minecraft:stone 5
setblock ~25~47~13 minecraft:stained_hardened_clay 9
setblock ~25~48~13 minecraft:grass
setblock ~25~49~13 minecraft:dirt 0
setblock ~25~50~13 minecraft:stained_hardened_clay 13
setblock ~25~51~13 minecraft:stained_hardened_clay 5
fill ~25~58~13 ~25~58~14 minecraft:wood 1
fill ~25~59~13 ~26~59~13 minecraft:leaves 1
fill ~25~64~13 ~25~64~14 minecraft:leaves 1
fill ~26~36~13 ~26~38~14 minecraft:stained_hardened_clay 9
setblock ~26~42~13 minecraft:stone 5
fill ~26~43~13 ~26~43~17 minecraft:stained_hardened_clay 9
setblock ~26~47~13 minecraft:stone 5
fill ~26~48~13 ~26~48~14 minecraft:stained_hardened_clay 13
setblock ~26~49~13 minecraft:stained_hardened_clay 13
setblock ~26~50~13 minecraft:wood 1
setblock ~26~54~13 minecraft:wood 1
setblock ~26~61~13 minecraft:leaves 1
fill ~27~35~13 ~27~35~17 minecraft:stone 5
setblock ~27~36~13 minecraft:stone 5
fill ~27~37~13 ~27~37~19 minecraft:stained_hardened_clay 9
fill ~27~38~13 ~29~38~14 minecraft:stone 5
fill ~27~39~13 ~28~39~13 minecraft:stained_hardened_clay 9
fill ~27~40~13 ~27~40~14 minecraft:stone 5
fill ~27~42~13 ~31~42~13 minecraft:stained_hardened_clay 9
fill ~27~43~13 ~29~43~13 minecraft:stone 5
fill ~27~44~13 ~28~44~16 minecraft:stained_hardened_clay 9
fill ~27~45~13 ~27~45~15 minecraft:stone 5
fill ~27~46~13 ~28~47~13 minecraft:stained_hardened_clay 9
setblock ~27~49~13 minecraft:wood 1
setblock ~27~50~13 minecraft:stained_hardened_clay 5
setblock ~27~57~13 minecraft:wood 1
setblock ~27~58~13 minecraft:leaves 1
setblock ~27~68~13 minecraft:leaves 1
setblock ~28~33~13 minecraft:stained_hardened_clay 9
fill ~28~34~13 ~30~34~13 minecraft:stone 5
fill ~28~35~13 ~28~36~13 minecraft:stained_hardened_clay 9
setblock ~28~37~13 minecraft:stone 5
fill ~28~40~13 ~28~40~14 minecraft:stained_hardened_clay 9
fill ~28~45~13 ~29~45~13 minecraft:stained_hardened_clay 9
setblock ~28~49~13 minecraft:grass
fill ~28~57~13 ~28~57~14 minecraft:leaves 1
fill ~29~32~13 ~29~32~14 minecraft:stained_hardened_clay 9
fill ~29~33~13 ~29~33~15 minecraft:stone 5
fill ~29~36~13 ~29~36~15 minecraft:stained_hardened_clay 9
fill ~29~37~13 ~30~37~13 minecraft:stained_hardened_clay 9
fill ~29~40~13 ~31~40~13 minecraft:stone 5
fill ~29~41~13 ~31~41~13 minecraft:stained_hardened_clay 9
fill ~29~44~13 ~29~44~15 minecraft:stone 5
fill ~29~46~13 ~29~47~13 minecraft:stone 5
fill ~29~48~13 ~31~48~13 minecraft:stained_hardened_clay 13
setblock ~29~56~13 minecraft:leaves 1
fill ~30~36~13 ~31~36~13 minecraft:stone 5
fill ~30~38~13 ~30~38~15 minecraft:stained_hardened_clay 9
setblock ~30~39~13 minecraft:stained_hardened_clay 9
fill ~30~43~13 ~30~43~14 minecraft:stained_hardened_clay 9
fill ~30~45~13 ~31~45~13 minecraft:stone 5
fill ~30~46~13 ~32~46~13 minecraft:stained_hardened_clay 9
fill ~30~47~13 ~31~47~13 minecraft:stained_hardened_clay 9
fill ~30~49~13 ~31~49~13 minecraft:stained_hardened_clay 5
fill ~31~31~13 ~33~31~13 minecraft:stone 5
fill ~31~32~13 ~33~32~13 minecraft:stained_hardened_clay 9
fill ~31~33~13 ~31~34~13 minecraft:stained_hardened_clay 9
fill ~31~35~13 ~32~35~13 minecraft:stone 5
fill ~31~37~13 ~31~39~13 minecraft:stone 5
fill ~31~43~13 ~31~43~15 minecraft:stone 5
setblock ~31~51~13 minecraft:red_flower 7
setblock ~31~56~13 minecraft:leaves 1
setblock ~32~30~13 minecraft:stained_hardened_clay 9
fill ~32~33~13 ~32~33~14 minecraft:stone 5
fill ~32~34~13 ~32~34~14 minecraft:stained_hardened_clay 9
fill ~32~36~13 ~32~36~18 minecraft:stained_hardened_clay 9
fill ~32~37~13 ~33~37~16 minecraft:stained_hardened_clay 9
fill ~32~39~13 ~34~39~13 minecraft:stained_hardened_clay 9
setblock ~32~40~13 minecraft:stained_hardened_clay 9
fill ~32~41~13 ~32~42~13 minecraft:stone 5
fill ~32~43~13 ~32~43~17 minecraft:stained_hardened_clay 9
fill ~32~44~13 ~32~44~14 minecraft:stained_hardened_clay 9
setblock ~32~45~13 minecraft:stained_hardened_clay 9
fill ~32~49~13 ~32~49~15 minecraft:stained_hardened_clay 13
setblock ~32~51~13 minecraft:tallgrass 0
setblock ~33~34~13 minecraft:stone 5
fill ~33~35~13 ~35~35~13 minecraft:stained_hardened_clay 9
setblock ~33~36~13 minecraft:stone 5
fill ~33~38~13 ~36~38~13 minecraft:stone 5
fill ~33~44~13 ~33~44~14 minecraft:stone 5
fill ~33~46~13 ~35~46~13 minecraft:stone 5
setblock ~33~47~13 minecraft:stone 5
setblock ~33~48~13 minecraft:stained_hardened_clay 13
setblock ~33~50~13 minecraft:grass
setblock ~33~51~13 minecraft:tallgrass 2
fill ~34~30~13 ~34~31~13 minecraft:stained_hardened_clay 9
fill ~34~32~13 ~35~32~13 minecraft:stone 5
fill ~34~33~13 ~36~33~13 minecraft:stained_hardened_clay 9
fill ~34~36~13 ~34~36~14 minecraft:stained_hardened_clay 9
fill ~34~42~13 ~35~42~13 minecraft:stained_hardened_clay 9
setblock ~34~43~13 minecraft:stained_hardened_clay 9
fill ~34~45~13 ~35~45~13 minecraft:stained_hardened_clay 9
fill ~34~47~13 ~34~47~15 minecraft:stained_hardened_clay 9
fill ~34~49~13 ~35~49~13 minecraft:stained_hardened_clay 13
setblock ~35~31~13 minecraft:stained_hardened_clay 9
fill ~35~34~13 ~35~34~14 minecraft:stone 5
fill ~35~36~13 ~35~36~16 minecraft:stone 5
setblock ~35~37~13 minecraft:stained_hardened_clay 9
fill ~35~39~13 ~35~40~13 minecraft:stone 5
fill ~35~43~13 ~35~43~17 minecraft:stone 5
setblock ~35~44~13 minecraft:stone 5
fill ~35~48~13 ~35~48~14 minecraft:dirt 0
setblock ~36~34~13 minecraft:stained_hardened_clay 9
fill ~36~37~13 ~36~37~14 minecraft:stone 5
fill ~36~39~13 ~37~39~14 minecraft:stained_hardened_clay 9
fill ~36~41~13 ~36~41~14 minecraft:stained_hardened_clay 9
fill ~36~42~13 ~37~42~14 minecraft:stone 5
fill ~36~43~13 ~36~43~14 minecraft:stained_hardened_clay 9
fill ~36~45~13 ~38~45~14 minecraft:stone 5
fill ~36~46~13 ~38~46~13 minecraft:stained_hardened_clay 9
fill ~36~47~13 ~38~47~13 minecraft:stone 5
setblock ~36~48~13 minecraft:stained_hardened_clay 5
setblock ~36~49~13 minecraft:dirt 0
fill ~36~51~13 ~37~51~13 minecraft:stained_hardened_clay 13
setblock ~36~52~13 minecraft:stained_hardened_clay 5
setblock ~36~60~13 minecraft:leaves 1
fill ~37~34~13 ~37~34~14 minecraft:stone 5
fill ~37~37~13 ~38~37~14 minecraft:stained_hardened_clay 9
fill ~37~38~13 ~37~38~14 minecraft:stained_hardened_clay 9
setblock ~37~41~13 minecraft:stone 5
setblock ~37~48~13 minecraft:dirt 0
setblock ~37~50~13 minecraft:grass
fill ~37~52~13 ~38~52~13 minecraft:grass
setblock ~37~53~13 minecraft:tallgrass 2
setblock ~37~59~13 minecraft:leaves 1
setblock ~37~60~13 minecraft:wood 1
setblock ~37~61~13 minecraft:leaves 1
setblock ~38~34~13 minecraft:stained_hardened_clay 9
fill ~38~41~13 ~38~43~13 minecraft:stained_hardened_clay 9
fill ~38~44~13 ~38~44~14 minecraft:stone 5
fill ~38~48~13 ~38~49~13 minecraft:stained_hardened_clay 13
setblock ~38~50~13 minecraft:stained_hardened_clay 5
setblock ~38~51~13 minecraft:dirt 0
setblock ~38~56~13 minecraft:leaves 1
setblock ~38~61~13 minecraft:wood 1
setblock ~39~34~13 minecraft:stone 5
setblock ~39~35~13 minecraft:stained_hardened_clay 9
setblock ~39~39~13 minecraft:stained_hardened_clay 9
fill ~39~40~13 ~39~42~13 minecraft:stone 5
fill ~39~43~13 ~39~44~15 minecraft:stained_hardened_clay 9
setblock ~39~46~13 minecraft:stone 5
setblock ~39~47~13 minecraft:stained_hardened_clay 9
fill ~39~48~13 ~39~48~14 minecraft:stained_hardened_clay 5
fill ~39~49~13 ~39~49~14 minecraft:stained_hardened_clay 13
fill ~39~50~13 ~39~51~14 minecraft:wood 1
fill ~39~57~13 ~39~57~14 minecraft:leaves 1
fill ~39~61~13 ~39~61~15 minecraft:leaves 1
setblock ~39~64~13 minecraft:leaves 1
fill ~40~36~13 ~41~36~13 minecraft:stone 5
fill ~40~37~13 ~42~37~13 minecraft:stained_hardened_clay 9
fill ~40~39~13 ~40~39~17 minecraft:stone 5
fill ~40~40~13 ~41~40~13 minecraft:stained_hardened_clay 9
fill ~40~41~13 ~40~41~14 minecraft:stained_hardened_clay 9
fill ~40~44~13 ~41~44~13 minecraft:stone 5
fill ~40~46~13 ~40~46~15 minecraft:stained_hardened_clay 9
setblock ~40~47~13 minecraft:stone 5
fill ~40~48~13 ~40~48~16 minecraft:stone 0
setblock ~40~49~13 minecraft:dirt 0
setblock ~40~50~13 minecraft:stained_hardened_clay 13
fill ~40~51~13 ~40~51~16 minecraft:wood 1
setblock ~40~55~13 minecraft:leaves 1
fill ~40~57~13 ~40~57~15 minecraft:wood 1
fill ~40~58~13 ~41~58~13 minecraft:leaves 1
setblock ~40~64~13 minecraft:wood 1
fill ~40~65~13 ~41~65~13 minecraft:leaves 1
setblock ~40~68~13 minecraft:leaves 1
setblock ~41~35~13 minecraft:stained_hardened_clay 9
fill ~41~39~13 ~41~39~14 minecraft:stained_hardened_clay 9
fill ~41~43~13 ~45~43~13 minecraft:stained_hardened_clay 9
fill ~41~45~13 ~41~45~14 minecraft:stone 5
setblock ~41~46~13 minecraft:stained_hardened_clay 5
setblock ~41~47~13 minecraft:stained_hardened_clay 13
setblock ~41~48~13 minecraft:dirt 0
fill ~41~49~13 ~41~50~13 minecraft:wood 1
fill ~41~56~13 ~41~57~13 minecraft:leaves 1
setblock ~41~59~13 minecraft:leaves 1
fill ~41~62~13 ~41~62~16 minecraft:wood 1
setblock ~41~68~13 minecraft:wood 1
fill ~41~69~13 ~42~69~13 minecraft:leaves 1
setblock ~41~73~13 minecraft:leaves 1
fill ~42~36~13 ~42~36~15 minecraft:stained_hardened_clay 9
fill ~42~38~13 ~42~40~13 minecraft:stone 5
fill ~42~44~13 ~42~44~17 minecraft:stained_hardened_clay 9
setblock ~42~47~13 minecraft:grass
setblock ~42~48~13 minecraft:stained_hardened_clay 5
setblock ~42~49~13 minecraft:stained_hardened_clay 13
setblock ~42~50~13 minecraft:stained_hardened_clay 5
setblock ~42~57~13 minecraft:leaves 1
fill ~42~58~13 ~43~58~13 minecraft:wood 1
fill ~42~62~13 ~42~62~14 minecraft:leaves 1
setblock ~42~63~13 minecraft:leaves 1
setblock ~42~74~13 minecraft:leaves 1
setblock ~43~37~13 minecraft:stone 5
fill ~43~39~13 ~44~39~15 minecraft:stone 5
setblock ~43~42~13 minecraft:stained_hardened_clay 9
fill ~43~44~13 ~44~44~13 minecraft:stone 5
setblock ~43~45~13 minecraft:grass
fill ~43~46~13 ~44~46~13 minecraft:dirt 0
setblock ~43~48~13 minecraft:stained_hardened_clay 13
setblock ~43~49~13 minecraft:grass
fill ~43~50~13 ~44~50~13 minecraft:stained_hardened_clay 13
setblock ~43~59~13 minecraft:leaves 1
setblock ~43~66~13 minecraft:wood 1
setblock ~43~67~13 minecraft:leaves 1
fill ~44~38~13 ~44~38~14 minecraft:stone 5
setblock ~44~41~13 minecraft:stone 5
setblock ~44~45~13 minecraft:stained_hardened_clay 13
fill ~44~47~13 ~45~47~13 minecraft:dirt 0
setblock ~44~66~13 minecraft:leaves 1
setblock ~44~70~13 minecraft:leaves 1
setblock ~45~39~13 minecraft:stained_hardened_clay 9
fill ~45~41~13 ~51~41~13 minecraft:stained_hardened_clay 9
setblock ~45~44~13 minecraft:stained_hardened_clay 9
setblock ~45~45~13 minecraft:grass
fill ~45~46~13 ~45~46~14 minecraft:stained_hardened_clay 13
setblock ~45~48~13 minecraft:fence 1
fill ~45~49~13 ~46~49~13 minecraft:dirt 0
fill ~45~50~13 ~45~50~14 minecraft:stained_hardened_clay 5
setblock ~45~62~13 minecraft:stained_hardened_clay 4
setblock ~45~63~13 minecraft:stained_hardened_clay 11
fill ~45~66~13 ~45~67~13 minecraft:stained_hardened_clay 11
fill ~45~68~13 ~46~68~15 minecraft:stained_hardened_clay 3
setblock ~45~69~13 minecraft:leaves 1
setblock ~46~39~13 minecraft:stone 5
fill ~46~40~13 ~47~40~14 minecraft:stained_hardened_clay 9
fill ~46~43~13 ~46~44~13 minecraft:stone 5
setblock ~46~46~13 minecraft:stained_hardened_clay 5
setblock ~46~48~13 minecraft:grass
fill ~46~50~13 ~46~50~14 minecraft:grass
setblock ~46~66~13 minecraft:stained_hardened_clay 3
fill ~46~69~13 ~47~69~13 minecraft:stained_hardened_clay 3
fill ~47~43~13 ~50~43~13 minecraft:stained_hardened_clay 9
fill ~47~44~13 ~48~44~13 minecraft:stained_hardened_clay 9
fill ~47~45~13 ~47~45~14 minecraft:stained_hardened_clay 5
fill ~47~46~13 ~47~47~13 minecraft:dirt 0
fill ~47~48~13 ~47~48~14 minecraft:stained_hardened_clay 5
fill ~47~49~13 ~48~49~13 minecraft:grass
fill ~47~68~13 ~47~68~14 minecraft:stained_hardened_clay 11
setblock ~48~40~13 minecraft:stone 5
fill ~48~45~13 ~49~45~13 minecraft:dirt 0
fill ~48~46~13 ~49~46~13 minecraft:stained_hardened_clay 5
setblock ~48~47~13 minecraft:grass
fill ~48~70~13 ~52~70~13 minecraft:stained_hardened_clay 11
fill ~49~42~13 ~50~42~14 minecraft:stone 5
setblock ~49~48~13 minecraft:stained_hardened_clay 13
fill ~50~40~13 ~50~40~15 minecraft:stone 5
fill ~50~44~13 ~51~44~13 minecraft:stained_hardened_clay 9
fill ~50~45~13 ~52~45~13 minecraft:stone 5
setblock ~50~46~13 minecraft:stained_hardened_clay 13
fill ~50~47~13 ~50~47~14 minecraft:grass
setblock ~51~46~13 minecraft:stained_hardened_clay 5
fill ~52~43~13 ~52~43~20 minecraft:stained_hardened_clay 9
fill ~52~44~13 ~52~44~14 minecraft:stone 5
fill ~53~68~13 ~53~68~14 minecraft:stained_hardened_clay 11
setblock ~53~69~13 minecraft:stained_hardened_clay 3
fill ~54~65~13 ~55~65~13 minecraft:stained_hardened_clay 3
setblock ~54~66~13 minecraft:stained_hardened_clay 3
setblock ~54~67~13 minecraft:stained_hardened_clay 11
fill ~55~62~13 ~55~62~14 minecraft:stained_hardened_clay 4
fill ~55~63~13 ~55~64~13 minecraft:stained_hardened_clay 3
fill ~14~42~14 ~14~42~17 minecraft:stone 5
fill ~14~43~14 ~17~43~14 minecraft:stained_hardened_clay 9
setblock ~14~44~14 minecraft:stained_hardened_clay 9
fill ~14~45~14 ~15~45~14 minecraft:stained_hardened_clay 5
setblock ~14~46~14 minecraft:stained_hardened_clay 13
fill ~15~41~14 ~15~41~15 minecraft:stained_hardened_clay 9
fill ~15~42~14 ~17~42~14 minecraft:stained_hardened_clay 9
setblock ~16~40~14 minecraft:stone 5
setblock ~16~44~14 minecraft:dirt 0
setblock ~16~45~14 minecraft:stained_hardened_clay 13
setblock ~17~41~14 minecraft:stained_hardened_clay 9
setblock ~17~44~14 minecraft:grass
fill ~17~45~14 ~18~45~14 minecraft:stained_hardened_clay 5
fill ~17~46~14 ~17~47~14 minecraft:stained_hardened_clay 13
