fill ~48~52~5 ~49~52~5 minecraft:nether_brick_stairs 2
setblock ~50~52~5 minecraft:nether_brick_stairs 1
fill ~46~52~6 ~47~52~6 minecraft:nether_brick_stairs 2
setblock ~47~13~6 minecraft:emerald_block
setblock ~47~14~6 minecraft:obsidian
setblock ~47~15~6 minecraft:stone 0
setblock ~47~16~6 minecraft:obsidian
fill ~47~17~6 ~51~17~18 minecraft:planks 2
fill ~48~11~6 ~49~11~6 minecraft:obsidian
fill ~48~12~6 ~48~13~6 minecraft:snow
fill ~48~14~6 ~50~14~7 minecraft:stone 0
setblock ~48~15~6 minecraft:cobblestone
fill ~48~16~6 ~51~16~7 minecraft:stone 0
setblock ~48~52~6 minecraft:nether_brick_stairs 0
fill ~49~8~6 ~49~8~9 minecraft:obsidian
fill ~49~9~6 ~49~10~6 minecraft:obsidian
fill ~49~12~6 ~49~13~6 minecraft:stone 0
fill ~49~15~6 ~51~15~6 minecraft:obsidian
fill ~49~52~6 ~49~52~7 minecraft:planks 4
fill ~50~10~6 ~51~10~6 minecraft:obsidian
setblock ~50~11~6 minecraft:snow
setblock ~50~12~6 minecraft:cobblestone
fill ~50~13~6 ~51~13~6 minecraft:stone 0
fill ~50~52~6 ~51~52~6 minecraft:nether_brick_stairs 2
setblock ~51~11~6 minecraft:obsidian
setblock ~51~12~6 minecraft:stone 0
fill ~51~14~6 ~51~14~7 minecraft:cobblestone
setblock ~52~52~6 minecraft:nether_brick_stairs 1
fill ~45~13~7 ~45~16~7 minecraft:stone 0
fill ~45~17~7 ~46~17~17 minecraft:planks 2
setblock ~45~52~7 minecraft:nether_brick_stairs 2
fill ~46~14~7 ~46~16~7 minecraft:stone 0
setblock ~46~18~7 minecraft:red_sandstone_stairs 0
setblock ~46~19~7 minecraft:nether_brick_stairs 4
setblock ~46~26~7 minecraft:nether_brick_stairs 0
setblock ~46~27~7 minecraft:red_sandstone_stairs 4
setblock ~46~28~7 minecraft:red_sandstone_stairs 0
fill ~46~29~7 ~51~29~7 minecraft:nether_brick_stairs 6
fill ~46~36~7 ~51~36~7 minecraft:nether_brick_stairs 2
fill ~46~37~7 ~51~37~7 minecraft:red_sandstone_stairs 6
fill ~46~38~7 ~51~38~7 minecraft:red_sandstone_stairs 2
fill ~46~39~7 ~51~39~7 minecraft:nether_brick_stairs 6
fill ~46~46~7 ~51~46~7 minecraft:nether_brick_stairs 2
fill ~46~47~7 ~51~47~7 minecraft:nether_brick_stairs 6
setblock ~46~52~7 minecraft:nether_brick_stairs 0
fill ~47~13~7 ~48~13~7 minecraft:obsidian
setblock ~47~14~7 minecraft:snow
fill ~47~15~7 ~48~15~7 minecraft:obsidian
setblock ~47~16~7 minecraft:stone 0
fill ~47~18~7 ~52~18~7 minecraft:red_sandstone_stairs 2
fill ~47~19~7 ~52~19~7 minecraft:nether_brick_stairs 6
fill ~47~26~7 ~52~26~7 minecraft:nether_brick_stairs 2
fill ~47~27~7 ~51~27~7 minecraft:red_sandstone_stairs 6
fill ~47~28~7 ~52~28~7 minecraft:red_sandstone_stairs 2
fill ~47~48~7 ~51~48~7 minecraft:fence 4
setblock ~47~49~7 minecraft:torch 5
fill ~47~52~7 ~48~52~7 minecraft:planks 4
fill ~48~9~7 ~48~9~8 minecraft:snow
fill ~48~10~7 ~48~10~9 minecraft:obsidian
fill ~48~11~7 ~48~11~8 minecraft:obsidian
fill ~48~12~7 ~49~12~7 minecraft:emerald_block
fill ~48~20~7 ~48~25~7 minecraft:fence 4
fill ~48~30~7 ~48~35~7 minecraft:fence 4
fill ~48~40~7 ~48~45~7 minecraft:fence 4
setblock ~49~4~7 minecraft:emerald_block
fill ~49~5~7 ~49~6~7 minecraft:obsidian
setblock ~49~7~7 minecraft:snow
setblock ~49~9~7 minecraft:emerald_block
fill ~49~10~7 ~49~11~7 minecraft:stone 0
setblock ~49~13~7 minecraft:stone 0
setblock ~49~15~7 minecraft:emerald_block
fill ~50~7~7 ~50~10~7 minecraft:obsidian
fill ~50~11~7 ~50~11~11 minecraft:stone 0
fill ~50~12~7 ~50~12~9 minecraft:stone 0
setblock ~50~13~7 minecraft:cobblestone
setblock ~50~15~7 minecraft:cobblestone
fill ~50~20~7 ~50~25~7 minecraft:fence 4
fill ~50~30~7 ~50~35~7 minecraft:fence 4
fill ~50~40~7 ~50~45~7 minecraft:fence 4
fill ~50~52~7 ~51~52~7 minecraft:planks 4
fill ~51~8~7 ~51~9~7 minecraft:obsidian
fill ~51~10~7 ~51~10~8 minecraft:stone 0
setblock ~51~11~7 minecraft:cobblestone
setblock ~51~12~7 minecraft:obsidian
fill ~51~13~7 ~52~13~7 minecraft:stone 0
setblock ~51~15~7 minecraft:stone 0
setblock ~51~49~7 minecraft:torch 5
setblock ~52~14~7 minecraft:stone 0
setblock ~52~15~7 minecraft:obsidian
fill ~52~16~7 ~53~16~11 minecraft:stone 0
fill ~52~17~7 ~53~17~17 minecraft:planks 2
setblock ~52~27~7 minecraft:red_sandstone_stairs 5
setblock ~52~29~7 minecraft:nether_brick_stairs 5
setblock ~52~36~7 minecraft:nether_brick_stairs 1
setblock ~52~37~7 minecraft:red_sandstone_stairs 5
setblock ~52~38~7 minecraft:red_sandstone_stairs 1
setblock ~52~39~7 minecraft:nether_brick_stairs 5
setblock ~52~46~7 minecraft:nether_brick_stairs 1
setblock ~52~47~7 minecraft:nether_brick_stairs 5
setblock ~52~52~7 minecraft:nether_brick_stairs 2
setblock ~53~14~7 minecraft:snow
setblock ~53~15~7 minecraft:emerald_block
setblock ~53~52~7 minecraft:nether_brick_stairs 1
setblock ~44~13~8 minecraft:obsidian
fill ~44~14~8 ~44~14~11 minecraft:stone 0
fill ~44~15~8 ~46~15~8 minecraft:stone 0
fill ~44~16~8 ~44~16~11 minecraft:stone 0
fill ~44~17~8 ~44~17~16 minecraft:planks 2
setblock ~44~52~8 minecraft:nether_brick_stairs 2
setblock ~45~10~8 minecraft:obsidian
fill ~45~11~8 ~45~12~8 minecraft:stone 0
setblock ~45~13~8 minecraft:cobblestone
setblock ~45~14~8 minecraft:obsidian
setblock ~45~16~8 minecraft:obsidian
setblock ~45~18~8 minecraft:red_sandstone_stairs 0
setblock ~45~19~8 minecraft:nether_brick_stairs 4
setblock ~45~26~8 minecraft:nether_brick_stairs 0
setblock ~45~27~8 minecraft:red_sandstone_stairs 4
setblock ~45~28~8 minecraft:red_sandstone_stairs 0
setblock ~45~29~8 minecraft:nether_brick_stairs 6
setblock ~45~36~8 minecraft:nether_brick_stairs 2
setblock ~45~37~8 minecraft:red_sandstone_stairs 6
setblock ~45~38~8 minecraft:red_sandstone_stairs 2
setblock ~45~39~8 minecraft:nether_brick_stairs 6
setblock ~45~46~8 minecraft:nether_brick_stairs 2
setblock ~45~47~8 minecraft:nether_brick_stairs 6
setblock ~45~52~8 minecraft:nether_brick_stairs 0
setblock ~46~11~8 minecraft:cobblestone
setblock ~46~12~8 minecraft:stone 0
setblock ~46~13~8 minecraft:emerald_block
setblock ~46~14~8 minecraft:cobblestone
fill ~46~16~8 ~47~16~8 minecraft:cobblestone
setblock ~46~18~8 minecraft:red_sandstone_stairs 2
setblock ~46~19~8 minecraft:nether_brick_stairs 6
fill ~46~20~8 ~46~25~8 minecraft:nether_brick_fence
setblock ~46~26~8 minecraft:nether_brick_stairs 2
setblock ~46~27~8 minecraft:red_sandstone_stairs 6
setblock ~46~28~8 minecraft:red_sandstone_stairs 2
setblock ~46~29~8 minecraft:nether_brick_stairs 4
fill ~46~30~8 ~46~35~8 minecraft:nether_brick_fence
setblock ~46~36~8 minecraft:nether_brick_stairs 0
setblock ~46~37~8 minecraft:red_sandstone_stairs 4
setblock ~46~38~8 minecraft:red_sandstone_stairs 0
setblock ~46~39~8 minecraft:nether_brick_stairs 4
fill ~46~40~8 ~46~45~8 minecraft:nether_brick_fence
setblock ~46~46~8 minecraft:nether_brick_stairs 0
setblock ~46~47~8 minecraft:nether_brick_stairs 4
fill ~46~48~8 ~46~51~8 minecraft:nether_brick_fence
fill ~46~52~8 ~47~52~8 minecraft:planks 4
fill ~47~11~8 ~47~12~8 minecraft:obsidian
setblock ~47~13~8 minecraft:cobblestone
fill ~47~14~8 ~47~14~9 minecraft:stone 0
setblock ~47~15~8 minecraft:emerald_block
fill ~47~18~8 ~47~20~8 minecraft:stained_hardened_clay 15
fill ~47~21~8 ~47~22~8 minecraft:snow
setblock ~47~23~8 minecraft:stained_hardened_clay 15
setblock ~47~24~8 minecraft:emerald_block
setblock ~47~25~8 minecraft:snow
fill ~47~26~8 ~47~27~8 minecraft:stained_hardened_clay 13
fill ~47~28~8 ~51~28~8 minecraft:stained_hardened_clay 15
setblock ~47~29~8 minecraft:stained_hardened_clay 15
fill ~47~30~8 ~47~31~8 minecraft:snow
setblock ~47~32~8 minecraft:emerald_block
fill ~47~33~8 ~48~33~8 minecraft:stained_hardened_clay 13
fill ~47~34~8 ~48~34~8 minecraft:stained_hardened_clay 15
setblock ~47~35~8 minecraft:stained_hardened_clay 13
fill ~47~36~8 ~50~36~8 minecraft:stained_hardened_clay 15
setblock ~47~37~8 minecraft:stained_hardened_clay 15
fill ~47~38~8 ~47~39~8 minecraft:emerald_block
setblock ~47~40~8 minecraft:stained_hardened_clay 13
setblock ~47~41~8 minecraft:stained_hardened_clay 15
setblock ~47~42~8 minecraft:emerald_block
fill ~47~43~8 ~47~45~8 minecraft:stained_hardened_clay 13
fill ~47~46~8 ~48~46~8 minecraft:emerald_block
setblock ~47~47~8 minecraft:snow
fill ~47~48~8 ~47~51~8 minecraft:red_sandstone 1
fill ~48~12~8 ~49~12~8 minecraft:cobblestone
fill ~48~13~8 ~48~13~14 minecraft:stone 0
setblock ~48~14~8 minecraft:obsidian
fill ~48~15~8 ~50~15~8 minecraft:stone 0
setblock ~48~16~8 minecraft:obsidian
fill ~48~18~8 ~51~18~8 minecraft:stained_hardened_clay 13
fill ~48~19~8 ~50~19~8 minecraft:stained_hardened_clay 13
fill ~48~20~8 ~51~20~8 minecraft:stained_hardened_clay 15
fill ~48~21~8 ~48~22~8 minecraft:stained_hardened_clay 15
setblock ~48~23~8 minecraft:stained_hardened_clay 13
fill ~48~24~8 ~48~27~8 minecraft:stained_hardened_clay 15
fill ~48~29~8 ~48~30~8 minecraft:stained_hardened_clay 13
setblock ~48~31~8 minecraft:stained_hardened_clay 15
setblock ~48~32~8 minecraft:snow
setblock ~48~35~8 minecraft:stained_hardened_clay 15
fill ~48~37~8 ~48~39~8 minecraft:stained_hardened_clay 13
setblock ~48~40~8 minecraft:snow
fill ~48~41~8 ~48~42~8 minecraft:stained_hardened_clay 13
fill ~48~43~8 ~48~44~8 minecraft:stained_hardened_clay 15
setblock ~48~45~8 minecraft:stained_hardened_clay 13
setblock ~48~47~8 minecraft:stained_hardened_clay 13
fill ~48~51~8 ~48~52~8 minecraft:red_sandstone 1
fill ~48~53~8 ~50~53~8 minecraft:planks 4
setblock ~49~7~8 minecraft:obsidian
fill ~49~9~8 ~50~9~9 minecraft:obsidian
setblock ~49~10~8 minecraft:obsidian
setblock ~49~11~8 minecraft:cobblestone
setblock ~49~13~8 minecraft:cobblestone
setblock ~49~14~8 minecraft:stone 0
fill ~49~16~8 ~51~16~10 minecraft:stone 0
fill ~49~21~8 ~49~24~8 minecraft:fence 4
fill ~49~25~8 ~49~27~8 minecraft:stained_hardened_clay 15
fill ~49~29~8 ~50~29~8 minecraft:stained_hardened_clay 15
setblock ~49~30~8 minecraft:stained_hardened_clay 15
fill ~49~31~8 ~49~34~8 minecraft:fence 4
setblock ~49~35~8 minecraft:snow
setblock ~49~37~8 minecraft:stained_hardened_clay 15
setblock ~49~38~8 minecraft:stained_hardened_clay 13
setblock ~49~39~8 minecraft:emerald_block
fill ~49~40~8 ~50~40~8 minecraft:stained_hardened_clay 15
fill ~49~41~8 ~49~45~8 minecraft:fence 4
fill ~49~46~8 ~49~47~8 minecraft:stained_hardened_clay 15
fill ~49~52~8 ~50~52~8 minecraft:red_sandstone 1
setblock ~50~8~8 minecraft:snow
setblock ~50~10~8 minecraft:stone 0
fill ~50~13~8 ~50~13~9 minecraft:stone 0
setblock ~50~14~8 minecraft:cobblestone
fill ~50~21~8 ~51~21~8 minecraft:snow
fill ~50~22~8 ~51~22~8 minecraft:stained_hardened_clay 15
setblock ~50~23~8 minecraft:stained_hardened_clay 15
fill ~50~24~8 ~50~26~8 minecraft:stained_hardened_clay 13
setblock ~50~27~8 minecraft:stained_hardened_clay 15
fill ~50~30~8 ~51~30~8 minecraft:emerald_block
setblock ~50~31~8 minecraft:stained_hardened_clay 15
setblock ~50~32~8 minecraft:emerald_block
setblock ~50~33~8 minecraft:stained_hardened_clay 15
setblock ~50~34~8 minecraft:stained_hardened_clay 13
fill ~50~35~8 ~51~35~8 minecraft:stained_hardened_clay 15
setblock ~50~37~8 minecraft:stained_hardened_clay 13
fill ~50~38~8 ~51~38~8 minecraft:stained_hardened_clay 15
fill ~50~39~8 ~51~39~8 minecraft:stained_hardened_clay 13
fill ~50~41~8 ~50~42~8 minecraft:stained_hardened_clay 15
setblock ~50~43~8 minecraft:emerald_block
fill ~50~44~8 ~51~45~8 minecraft:stained_hardened_clay 15
setblock ~50~46~8 minecraft:emerald_block
fill ~50~47~8 ~51~47~8 minecraft:stained_hardened_clay 15
fill ~50~51~8 ~51~51~8 minecraft:red_sandstone 1
setblock ~51~6~8 minecraft:obsidian
setblock ~51~7~8 minecraft:emerald_block
setblock ~51~8~8 minecraft:cobblestone
setblock ~51~9~8 minecraft:stone 0
fill ~51~11~8 ~51~12~9 minecraft:stone 0
fill ~51~13~8 ~53~13~8 minecraft:obsidian
setblock ~51~14~8 minecraft:stone 0
setblock ~51~15~8 minecraft:obsidian
setblock ~51~19~8 minecraft:stained_hardened_clay 15
setblock ~51~23~8 minecraft:stained_hardened_clay 13
setblock ~51~24~8 minecraft:emerald_block
setblock ~51~25~8 minecraft:stained_hardened_clay 13
setblock ~51~26~8 minecraft:stained_hardened_clay 15
setblock ~51~27~8 minecraft:stained_hardened_clay 13
setblock ~51~29~8 minecraft:snow
setblock ~51~31~8 minecraft:stained_hardened_clay 13
setblock ~51~32~8 minecraft:stained_hardened_clay 15
fill ~51~33~8 ~51~34~8 minecraft:snow
setblock ~51~36~8 minecraft:snow
setblock ~51~37~8 minecraft:stained_hardened_clay 15
setblock ~51~40~8 minecraft:snow
setblock ~51~41~8 minecraft:emerald_block
setblock ~51~42~8 minecraft:stained_hardened_clay 15
setblock ~51~43~8 minecraft:stained_hardened_clay 13
setblock ~51~46~8 minecraft:stained_hardened_clay 15
fill ~51~48~8 ~51~50~8 minecraft:red_sandstone 1
fill ~51~52~8 ~52~52~8 minecraft:planks 4
fill ~52~10~8 ~52~11~8 minecraft:obsidian
setblock ~52~12~8 minecraft:stone 0
fill ~52~14~8 ~52~15~8 minecraft:emerald_block
setblock ~52~18~8 minecraft:red_sandstone_stairs 1
setblock ~52~19~8 minecraft:nether_brick_stairs 5
fill ~52~20~8 ~52~25~8 minecraft:nether_brick_fence
setblock ~52~26~8 minecraft:nether_brick_stairs 1
setblock ~52~27~8 minecraft:red_sandstone_stairs 6
setblock ~52~28~8 minecraft:red_sandstone_stairs 1
setblock ~52~29~8 minecraft:nether_brick_stairs 6
fill ~52~30~8 ~52~35~8 minecraft:nether_brick_fence
setblock ~52~36~8 minecraft:nether_brick_stairs 2
setblock ~52~37~8 minecraft:red_sandstone_stairs 6
setblock ~52~38~8 minecraft:red_sandstone_stairs 2
setblock ~52~39~8 minecraft:nether_brick_stairs 6
fill ~52~40~8 ~52~45~8 minecraft:nether_brick_fence
setblock ~52~46~8 minecraft:nether_brick_stairs 2
setblock ~52~47~8 minecraft:nether_brick_stairs 6
fill ~52~48~8 ~52~51~8 minecraft:nether_brick_fence
fill ~53~12~8 ~53~12~9 minecraft:obsidian
setblock ~53~14~8 minecraft:cobblestone
setblock ~53~15~8 minecraft:obsidian
setblock ~53~18~8 minecraft:red_sandstone_stairs 2
setblock ~53~19~8 minecraft:nether_brick_stairs 6
fill ~53~20~8 ~59~25~8 minecraft:air
setblock ~53~26~8 minecraft:nether_brick_stairs 2
setblock ~53~27~8 minecraft:red_sandstone_stairs 5
setblock ~53~28~8 minecraft:red_sandstone_stairs 2
setblock ~53~29~8 minecraft:nether_brick_stairs 5
setblock ~53~36~8 minecraft:nether_brick_stairs 1
setblock ~53~37~8 minecraft:red_sandstone_stairs 5
setblock ~53~38~8 minecraft:red_sandstone_stairs 1
setblock ~53~39~8 minecraft:nether_brick_stairs 5
fill ~53~40~8 ~99~45~8 minecraft:air
setblock ~53~46~8 minecraft:nether_brick_stairs 1
setblock ~53~47~8 minecraft:nether_brick_stairs 5
setblock ~53~52~8 minecraft:nether_brick_stairs 2
fill ~54~14~8 ~55~14~8 minecraft:obsidian
setblock ~54~15~8 minecraft:emerald_block
fill ~54~16~8 ~54~16~11 minecraft:stone 0
fill ~54~17~8 ~54~17~16 minecraft:planks 2
setblock ~54~52~8 minecraft:nether_brick_stairs 1
setblock ~55~15~8 minecraft:obsidian
setblock ~55~16~8 minecraft:snow
fill ~55~17~8 ~57~17~8 minecraft:stone 0
setblock ~56~16~8 minecraft:stone 0
fill ~57~14~8 ~57~14~9 minecraft:snow
fill ~57~15~8 ~58~15~8 minecraft:snow
setblock ~57~16~8 minecraft:cobblestone
fill ~57~18~8 ~60~18~8 minecraft:stained_hardened_clay 15
fill ~58~13~8 ~59~14~8 minecraft:obsidian
fill ~58~16~8 ~58~16~9 minecraft:obsidian
setblock ~58~17~8 minecraft:emerald_block
fill ~59~8~8 ~59~9~8 minecraft:obsidian
setblock ~59~10~8 minecraft:emerald_block
fill ~59~11~8 ~59~12~8 minecraft:obsidian
fill ~59~15~8 ~60~15~8 minecraft:obsidian
fill ~59~16~8 ~59~17~8 minecraft:stone 0
fill ~60~12~8 ~60~13~8 minecraft:emerald_block
setblock ~60~14~8 minecraft:snow
setblock ~60~16~8 minecraft:cobblestone
fill ~60~17~8 ~61~17~9 minecraft:stone 0
fill ~60~19~8 ~63~19~8 minecraft:stained_hardened_clay 15
fill ~60~20~8 ~60~28~8 minecraft:fence 4
fill ~61~13~8 ~62~13~8 minecraft:obsidian
fill ~61~14~8 ~61~14~9 minecraft:obsidian
setblock ~61~15~8 minecraft:emerald_block
setblock ~61~16~8 minecraft:obsidian
setblock ~61~18~8 minecraft:stone 0
fill ~61~20~8 ~99~28~8 minecraft:air
fill ~62~8~8 ~62~9~8 minecraft:obsidian
setblock ~62~10~8 minecraft:emerald_block
fill ~62~11~8 ~62~12~8 minecraft:obsidian
fill ~62~14~8 ~62~15~8 minecraft:snow
setblock ~62~16~8 minecraft:stone 0
setblock ~62~17~8 minecraft:emerald_block
setblock ~62~18~8 minecraft:snow
setblock ~63~13~8 minecraft:snow
fill ~63~14~8 ~63~16~8 minecraft:obsidian
fill ~63~17~8 ~63~18~8 minecraft:stone 0
setblock ~43~52~9 minecraft:nether_brick_stairs 2
fill ~44~13~9 ~47~13~9 minecraft:stone 0
setblock ~44~15~9 minecraft:cobblestone
fill ~44~18~9 ~44~18~14 minecraft:red_sandstone_stairs 0
fill ~44~19~9 ~44~19~14 minecraft:nether_brick_stairs 4
fill ~44~26~9 ~44~26~14 minecraft:nether_brick_stairs 0
fill ~44~27~9 ~44~27~14 minecraft:red_sandstone_stairs 4
fill ~44~28~9 ~44~28~14 minecraft:red_sandstone_stairs 0
setblock ~44~29~9 minecraft:nether_brick_stairs 6
setblock ~44~36~9 minecraft:nether_brick_stairs 2
setblock ~44~37~9 minecraft:red_sandstone_stairs 6
setblock ~44~38~9 minecraft:red_sandstone_stairs 2
setblock ~44~39~9 minecraft:nether_brick_stairs 6
setblock ~44~46~9 minecraft:nether_brick_stairs 2
setblock ~44~47~9 minecraft:nether_brick_stairs 6
setblock ~44~52~9 minecraft:nether_brick_stairs 0
setblock ~45~10~9 minecraft:snow
setblock ~45~11~9 minecraft:emerald_block
setblock ~45~12~9 minecraft:obsidian
fill ~45~14~9 ~46~15~10 minecraft:stone 0
setblock ~45~16~9 minecraft:emerald_block
setblock ~45~18~9 minecraft:red_sandstone_stairs 2
setblock ~45~19~9 minecraft:nether_brick_stairs 6
fill ~45~20~9 ~45~25~9 minecraft:nether_brick_fence
setblock ~45~26~9 minecraft:nether_brick_stairs 2
setblock ~45~27~9 minecraft:red_sandstone_stairs 6
setblock ~45~28~9 minecraft:red_sandstone_stairs 2
setblock ~45~29~9 minecraft:nether_brick_stairs 4
fill ~45~30~9 ~45~35~9 minecraft:nether_brick_fence
setblock ~45~36~9 minecraft:nether_brick_stairs 0
setblock ~45~37~9 minecraft:red_sandstone_stairs 4
setblock ~45~38~9 minecraft:red_sandstone_stairs 0
setblock ~45~39~9 minecraft:nether_brick_stairs 4
fill ~45~40~9 ~45~45~9 minecraft:nether_brick_fence
setblock ~45~46~9 minecraft:nether_brick_stairs 0
setblock ~45~47~9 minecraft:nether_brick_stairs 4
fill ~45~48~9 ~45~51~9 minecraft:nether_brick_fence
fill ~45~52~9 ~46~52~9 minecraft:planks 4
fill ~46~10~9 ~46~11~9 minecraft:stone 0
setblock ~46~12~9 minecraft:snow
fill ~46~16~9 ~46~16~10 minecraft:stone 0
setblock ~46~18~9 minecraft:stained_hardened_clay 15
setblock ~46~19~9 minecraft:snow
fill ~46~20~9 ~46~25~9 minecraft:stained_hardened_clay 15
setblock ~46~26~9 minecraft:emerald_block
setblock ~46~27~9 minecraft:stained_hardened_clay 15
setblock ~46~28~9 minecraft:stained_hardened_clay 13
setblock ~46~29~9 minecraft:stained_hardened_clay 15
setblock ~46~30~9 minecraft:stained_hardened_clay 13
fill ~46~31~9 ~46~34~9 minecraft:stained_hardened_clay 15
fill ~46~35~9 ~46~36~9 minecraft:stained_hardened_clay 13
fill ~46~37~9 ~46~38~9 minecraft:emerald_block
setblock ~46~39~9 minecraft:stained_hardened_clay 15
setblock ~46~40~9 minecraft:stained_hardened_clay 13
setblock ~46~41~9 minecraft:stained_hardened_clay 15
fill ~46~42~9 ~46~43~9 minecraft:snow
setblock ~46~44~9 minecraft:stained_hardened_clay 15
setblock ~46~45~9 minecraft:stained_hardened_clay 13
fill ~46~46~9 ~46~47~9 minecraft:stained_hardened_clay 15
fill ~46~48~9 ~46~51~9 minecraft:red_sandstone 1
fill ~47~8~9 ~47~10~9 minecraft:obsidian
setblock ~47~11~9 minecraft:cobblestone
setblock ~47~12~9 minecraft:obsidian
fill ~47~15~9 ~47~15~11 minecraft:stone 0
fill ~47~16~9 ~48~16~9 minecraft:cobblestone
fill ~47~23~9 ~48~23~9 minecraft:wooden_slab 4
fill ~47~29~9 ~47~29~10 minecraft:wooden_slab 12
setblock ~47~30~9 minecraft:torch 1
fill ~47~35~9 ~47~35~10 minecraft:wooden_slab 4
setblock ~47~37~9 minecraft:torch 1
fill ~47~41~9 ~47~41~10 minecraft:wooden_slab 4
setblock ~47~44~9 minecraft:torch 1
fill ~47~47~9 ~51~47~14 minecraft:wooden_slab 12
setblock ~47~53~9 minecraft:planks 4
setblock ~48~11~9 minecraft:emerald_block
fill ~48~12~9 ~49~12~9 minecraft:stone 0
setblock ~48~14~9 minecraft:stone 0
setblock ~48~15~9 minecraft:cobblestone
fill ~48~30~9 ~49~30~9 minecraft:wooden_slab 4
setblock ~48~35~9 minecraft:wooden_slab 12
setblock ~48~41~9 minecraft:wooden_slab 12
fill ~48~54~9 ~50~54~9 minecraft:planks 4
fill ~49~10~9 ~49~11~9 minecraft:stone 0
fill ~49~13~9 ~49~13~11 minecraft:stone 0
setblock ~49~14~9 minecraft:cobblestone
setblock ~49~15~9 minecraft:emerald_block
setblock ~49~23~9 minecraft:wooden_slab 12
fill ~49~36~9 ~50~36~9 minecraft:wooden_slab 4
fill ~49~42~9 ~51~42~9 minecraft:wooden_slab 4
setblock ~49~52~9 minecraft:torch 3
setblock ~50~10~9 minecraft:obsidian
fill ~50~14~9 ~50~15~9 minecraft:stone 0
fill ~50~24~9 ~51~24~9 minecraft:wooden_slab 4
setblock ~50~30~9 minecraft:wooden_slab 12
setblock ~51~9~9 minecraft:obsidian
fill ~51~10~9 ~52~10~9 minecraft:snow
setblock ~51~13~9 minecraft:stone 0
setblock ~51~14~9 minecraft:emerald_block
fill ~51~15~9 ~53~15~9 minecraft:stone 0
fill ~51~31~9 ~51~31~10 minecraft:wooden_slab 4
setblock ~51~36~9 minecraft:wooden_slab 12
setblock ~51~53~9 minecraft:planks 4
setblock ~52~11~9 minecraft:snow
setblock ~52~12~9 minecraft:emerald_block
setblock ~52~13~9 minecraft:cobblestone
setblock ~52~14~9 minecraft:snow
fill ~52~18~9 ~52~22~9 minecraft:stained_hardened_clay 15
fill ~52~23~9 ~52~24~9 minecraft:emerald_block
setblock ~52~25~9 minecraft:stained_hardened_clay 13
fill ~52~26~9 ~52~29~9 minecraft:stained_hardened_clay 15
setblock ~52~30~9 minecraft:stained_hardened_clay 13
setblock ~52~31~9 minecraft:stained_hardened_clay 15
setblock ~52~32~9 minecraft:stained_hardened_clay 13
setblock ~52~33~9 minecraft:snow
setblock ~52~34~9 minecraft:emerald_block
setblock ~52~35~9 minecraft:stained_hardened_clay 13
setblock ~52~36~9 minecraft:stained_hardened_clay 15
fill ~52~37~9 ~52~38~9 minecraft:stained_hardened_clay 13
setblock ~52~39~9 minecraft:stained_hardened_clay 15
setblock ~52~40~9 minecraft:stained_hardened_clay 13
setblock ~52~41~9 minecraft:stained_hardened_clay 15
setblock ~52~42~9 minecraft:snow
setblock ~52~43~9 minecraft:stained_hardened_clay 15
fill ~52~44~9 ~52~46~9 minecraft:stained_hardened_clay 13
setblock ~52~47~9 minecraft:stained_hardened_clay 15
fill ~52~48~9 ~52~51~9 minecraft:red_sandstone 1
fill ~52~52~9 ~53~52~9 minecraft:planks 4
fill ~53~10~9 ~53~10~11 minecraft:obsidian
setblock ~53~11~9 minecraft:obsidian
setblock ~53~13~9 minecraft:obsidian
fill ~53~14~9 ~53~14~12 minecraft:stone 0
setblock ~53~18~9 minecraft:red_sandstone_stairs 1
setblock ~53~19~9 minecraft:nether_brick_stairs 5
fill ~53~20~9 ~53~25~9 minecraft:nether_brick_fence
setblock ~53~26~9 minecraft:nether_brick_stairs 1
setblock ~53~27~9 minecraft:red_sandstone_stairs 6
setblock ~53~28~9 minecraft:red_sandstone_stairs 1
setblock ~53~29~9 minecraft:nether_brick_stairs 6
fill ~53~30~9 ~53~35~9 minecraft:nether_brick_fence
setblock ~53~36~9 minecraft:nether_brick_stairs 2
setblock ~53~37~9 minecraft:red_sandstone_stairs 6
setblock ~53~38~9 minecraft:red_sandstone_stairs 2
setblock ~53~39~9 minecraft:nether_brick_stairs 6
fill ~53~40~9 ~53~45~9 minecraft:nether_brick_fence
setblock ~53~46~9 minecraft:nether_brick_stairs 2
setblock ~53~47~9 minecraft:nether_brick_stairs 6
fill ~53~48~9 ~53~51~9 minecraft:nether_brick_fence
setblock ~54~14~9 minecraft:emerald_block
setblock ~54~15~9 minecraft:obsidian
setblock ~54~18~9 minecraft:red_sandstone_stairs 2
setblock ~54~19~9 minecraft:nether_brick_stairs 6
setblock ~54~26~9 minecraft:nether_brick_stairs 2
fill ~54~27~9 ~54~27~15 minecraft:red_sandstone_stairs 5
setblock ~54~28~9 minecraft:red_sandstone_stairs 2
fill ~54~29~9 ~54~29~14 minecraft:nether_brick_stairs 5
fill ~54~30~9 ~99~35~9 minecraft:air
fill ~54~36~9 ~54~36~14 minecraft:nether_brick_stairs 1
fill ~54~37~9 ~54~37~14 minecraft:red_sandstone_stairs 5
fill ~54~38~9 ~54~38~14 minecraft:red_sandstone_stairs 1
fill ~54~39~9 ~54~39~14 minecraft:nether_brick_stairs 5
fill ~54~46~9 ~54~46~14 minecraft:nether_brick_stairs 1
fill ~54~47~9 ~54~47~14 minecraft:nether_brick_stairs 5
setblock ~54~52~9 minecraft:nether_brick_stairs 2
fill ~55~13~9 ~55~14~9 minecraft:snow
fill ~55~15~9 ~56~15~9 minecraft:stone 0
fill ~55~16~9 ~55~16~10 minecraft:cobblestone
fill ~55~17~9 ~57~17~9 minecraft:planks 0
fill ~55~52~9 ~55~52~10 minecraft:nether_brick_stairs 1
fill ~56~13~9 ~56~14~9 minecraft:stone 0
setblock ~56~16~9 minecraft:snow
setblock ~57~13~9 minecraft:emerald_block
setblock ~57~15~9 minecraft:cobblestone
setblock ~57~16~9 minecraft:stone 0
fill ~57~18~9 ~57~18~15 minecraft:wooden_slab 0
setblock ~58~17~9 minecraft:snow
fill ~58~18~9 ~61~18~15 minecraft:planks 0
setblock ~59~14~9 minecraft:emerald_block
fill ~59~15~9 ~59~15~10 minecraft:obsidian
setblock ~59~16~9 minecraft:emerald_block
fill ~59~17~9 ~59~17~10 minecraft:obsidian
fill ~60~12~9 ~61~13~9 minecraft:obsidian
fill ~60~14~9 ~60~14~14 minecraft:stone 0
fill ~60~15~9 ~60~15~10 minecraft:cobblestone
fill ~60~16~9 ~61~16~9 minecraft:stone 0
fill ~60~25~9 ~60~27~9 minecraft:fence 4
setblock ~61~11~9 minecraft:snow
fill ~61~15~9 ~61~15~13 minecraft:stone 0
fill ~61~19~9 ~61~19~15 minecraft:wooden_slab 0
setblock ~62~15~9 minecraft:obsidian
setblock ~62~16~9 minecraft:snow
fill ~62~17~9 ~62~17~10 minecraft:obsidian
setblock ~62~18~9 minecraft:emerald_block
fill ~62~19~9 ~63~19~16 minecraft:planks 0
fill ~63~17~9 ~63~18~9 minecraft:snow
fill ~64~14~9 ~64~14~10 minecraft:snow
setblock ~64~15~9 minecraft:snow
fill ~64~16~9 ~64~18~9 minecraft:stone 0
fill ~64~19~9 ~64~20~9 minecraft:stained_hardened_clay 15
fill ~65~17~9 ~65~18~9 minecraft:stone 0
setblock ~65~19~9 minecraft:cobblestone
fill ~65~20~9 ~66~20~9 minecraft:stained_hardened_clay 15
setblock ~66~18~9 minecraft:cobblestone
fill ~66~19~9 ~66~19~10 minecraft:snow
fill ~43~14~10 ~43~16~10 minecraft:stone 0
fill ~43~17~10 ~43~17~14 minecraft:planks 2
fill ~43~52~10 ~43~52~11 minecraft:nether_brick_stairs 0
fill ~44~15~10 ~44~15~14 minecraft:stone 0
fill ~44~29~10 ~44~29~15 minecraft:nether_brick_stairs 4
fill ~44~36~10 ~44~36~14 minecraft:nether_brick_stairs 0
fill ~44~37~10 ~44~37~15 minecraft:red_sandstone_stairs 4
fill ~44~38~10 ~44~38~15 minecraft:red_sandstone_stairs 0
fill ~44~39~10 ~44~39~15 minecraft:nether_brick_stairs 4
fill ~44~46~10 ~44~46~14 minecraft:nether_brick_stairs 0
fill ~44~47~10 ~44~47~15 minecraft:nether_brick_stairs 4
fill ~44~48~10 ~44~48~14 minecraft:fence 4
setblock ~44~49~10 minecraft:torch 5
fill ~44~52~10 ~45~52~10 minecraft:planks 4
fill ~45~11~10 ~49~11~10 minecraft:stone 0
fill ~45~12~10 ~46~12~10 minecraft:cobblestone
fill ~45~13~10 ~47~13~11 minecraft:stone 0
setblock ~45~16~10 minecraft:cobblestone
fill ~45~18~10 ~45~21~10 minecraft:stained_hardened_clay 13
setblock ~45~22~10 minecraft:stained_hardened_clay 15
setblock ~45~23~10 minecraft:stained_hardened_clay 13
fill ~45~24~10 ~45~24~11 minecraft:stained_hardened_clay 15
fill ~45~25~10 ~45~27~10 minecraft:stained_hardened_clay 15
fill ~45~28~10 ~45~28~11 minecraft:stained_hardened_clay 13
fill ~45~29~10 ~45~30~10 minecraft:stained_hardened_clay 15
fill ~45~31~10 ~45~35~10 minecraft:stained_hardened_clay 13
setblock ~45~36~10 minecraft:snow
fill ~45~37~10 ~45~39~10 minecraft:stained_hardened_clay 15
setblock ~45~40~10 minecraft:stained_hardened_clay 13
fill ~45~41~10 ~45~42~11 minecraft:stained_hardened_clay 15
setblock ~45~43~10 minecraft:stained_hardened_clay 15
setblock ~45~44~10 minecraft:emerald_block
fill ~45~45~10 ~45~46~11 minecraft:stained_hardened_clay 15
setblock ~45~47~10 minecraft:stained_hardened_clay 15
fill ~45~48~10 ~45~51~10 minecraft:red_sandstone 1
setblock ~46~8~10 minecraft:cobblestone
setblock ~46~9~10 minecraft:stone 0
setblock ~46~10~10 minecraft:cobblestone
setblock ~46~22~10 minecraft:wooden_slab 12
fill ~46~29~10 ~46~29~11 minecraft:wooden_slab 4
fill ~46~35~10 ~46~35~11 minecraft:wooden_slab 4
setblock ~46~41~10 minecraft:wooden_slab 4
fill ~46~47~10 ~46~47~14 minecraft:wooden_slab 12
setblock ~46~53~10 minecraft:planks 4
setblock ~47~3~10 minecraft:cobblestone
setblock ~47~4~10 minecraft:stone 0
fill ~47~5~10 ~47~7~10 minecraft:cobblestone
setblock ~47~10~10 minecraft:emerald_block
setblock ~47~12~10 minecraft:stone 0
fill ~47~14~10 ~48~14~10 minecraft:obsidian
fill ~47~16~10 ~48~16~10 minecraft:stone 0
setblock ~47~23~10 minecraft:wooden_slab 4
setblock ~47~54~10 minecraft:planks 4
fill ~48~12~10 ~48~12~11 minecraft:cobblestone
fill ~48~15~10 ~50~15~11 minecraft:stone 0
fill ~48~24~10 ~49~24~10 minecraft:fence 4
fill ~48~30~10 ~48~30~11 minecraft:fence 4
fill ~48~31~10 ~50~31~10 minecraft:fence 4
fill ~48~36~10 ~48~36~11 minecraft:fence 4
fill ~48~37~10 ~50~37~10 minecraft:fence 4
fill ~48~42~10 ~49~42~10 minecraft:fence 4
fill ~48~55~10 ~50~55~10 minecraft:planks 4
setblock ~49~7~10 minecraft:stone 0
setblock ~49~8~10 minecraft:cobblestone
fill ~49~9~10 ~49~9~11 minecraft:stone 0
setblock ~49~10~10 minecraft:cobblestone
fill ~49~12~10 ~49~12~13 minecraft:stone 0
fill ~49~14~10 ~49~14~14 minecraft:stone 0
fill ~49~25~10 ~50~25~10 minecraft:fence 4
fill ~49~43~10 ~50~43~10 minecraft:fence 4
setblock ~49~56~10 minecraft:planks 4
setblock ~50~12~10 minecraft:obsidian
fill ~50~13~10 ~50~13~11 minecraft:cobblestone
setblock ~50~14~10 minecraft:obsidian
fill ~50~32~10 ~50~32~11 minecraft:fence 4
fill ~50~38~10 ~50~38~11 minecraft:fence 4
fill ~50~44~10 ~50~44~11 minecraft:fence 4
fill ~51~10~10 ~52~11~10 minecraft:obsidian
setblock ~51~12~10 minecraft:snow
setblock ~51~13~10 minecraft:obsidian
fill ~51~14~10 ~52~14~11 minecraft:stone 0
fill ~51~15~10 ~52~15~10 minecraft:obsidian
fill ~51~24~10 ~52~24~10 minecraft:wooden_slab 12
fill ~51~37~10 ~52~37~10 minecraft:wooden_slab 4
fill ~51~42~10 ~52~42~10 minecraft:wooden_slab 12
setblock ~51~54~10 minecraft:planks 4
fill ~52~9~10 ~52~9~11 minecraft:obsidian
setblock ~52~12~10 minecraft:obsidian
fill ~52~13~10 ~53~13~11 minecraft:stone 0
setblock ~52~25~10 minecraft:torch 3
setblock ~52~30~10 minecraft:torch 3
setblock ~52~31~10 minecraft:wooden_slab 4
setblock ~52~39~10 minecraft:torch 3
fill ~52~47~10 ~52~47~14 minecraft:wooden_slab 12
setblock ~52~53~10 minecraft:planks 4
fill ~53~4~10 ~53~7~10 minecraft:obsidian
setblock ~53~8~10 minecraft:snow
fill ~53~9~10 ~53~9~11 minecraft:emerald_block
fill ~53~11~10 ~53~12~12 minecraft:stone 0
fill ~53~18~10 ~53~20~10 minecraft:stained_hardened_clay 15
setblock ~53~21~10 minecraft:stained_hardened_clay 13
fill ~53~22~10 ~53~22~13 minecraft:stained_hardened_clay 15
fill ~53~23~10 ~53~25~10 minecraft:stained_hardened_clay 15
setblock ~53~26~10 minecraft:emerald_block
setblock ~53~27~10 minecraft:stained_hardened_clay 13
fill ~53~28~10 ~53~29~11 minecraft:stained_hardened_clay 15
fill ~53~30~10 ~53~30~11 minecraft:stained_hardened_clay 13
fill ~53~31~10 ~53~34~10 minecraft:stained_hardened_clay 15
setblock ~53~35~10 minecraft:emerald_block
setblock ~53~36~10 minecraft:stained_hardened_clay 13
setblock ~53~37~10 minecraft:stained_hardened_clay 15
setblock ~53~38~10 minecraft:snow
fill ~53~39~10 ~53~39~12 minecraft:stained_hardened_clay 15
setblock ~53~40~10 minecraft:stained_hardened_clay 15
fill ~53~41~10 ~53~42~10 minecraft:stained_hardened_clay 13
fill ~53~43~10 ~53~43~11 minecraft:stained_hardened_clay 15
fill ~53~44~10 ~53~46~10 minecraft:stained_hardened_clay 15
setblock ~53~47~10 minecraft:stained_hardened_clay 13
fill ~53~48~10 ~53~51~10 minecraft:red_sandstone 1
fill ~53~52~10 ~54~52~10 minecraft:planks 4
fill ~54~10~10 ~54~11~10 minecraft:emerald_block
fill ~54~12~10 ~54~13~10 minecraft:snow
fill ~54~14~10 ~55~14~11 minecraft:stone 0
setblock ~54~18~10 minecraft:red_sandstone_stairs 1
setblock ~54~19~10 minecraft:nether_brick_stairs 5
fill ~54~26~10 ~54~26~15 minecraft:nether_brick_stairs 1
fill ~54~28~10 ~54~28~15 minecraft:red_sandstone_stairs 1
fill ~54~48~10 ~54~48~14 minecraft:fence 4
setblock ~54~49~10 minecraft:torch 5
fill ~55~10~10 ~55~11~11 minecraft:obsidian
fill ~55~12~10 ~55~13~10 minecraft:obsidian
fill ~55~15~10 ~56~15~10 minecraft:obsidian
fill ~55~17~10 ~55~17~14 minecraft:planks 2
setblock ~56~9~10 minecraft:snow
setblock ~56~10~10 minecraft:cobblestone
fill ~56~11~10 ~56~12~10 minecraft:stone 0
setblock ~56~13~10 minecraft:obsidian
fill ~56~14~10 ~56~14~11 minecraft:cobblestone
setblock ~56~16~10 minecraft:obsidian
fill ~56~17~10 ~57~17~15 minecraft:planks 0
fill ~57~9~10 ~58~9~11 minecraft:air
fill ~57~10~10 ~57~10~13 minecraft:emerald_block
fill ~57~11~10 ~57~11~11 minecraft:obsidian
fill ~57~12~10 ~57~15~10 minecraft:stone 0
fill ~57~16~10 ~57~16~11 minecraft:cobblestone
fill ~58~10~10 ~59~11~11 minecraft:air
fill ~58~12~10 ~58~12~99 minecraft:air
setblock ~58~15~10 minecraft:obsidian
setblock ~58~16~10 minecraft:emerald_block
setblock ~58~17~10 minecraft:obsidian
fill ~59~14~10 ~59~14~11 minecraft:air
fill ~59~16~10 ~59~16~11 minecraft:obsidian
setblock ~60~10~10 minecraft:stone 0
fill ~60~11~10 ~60~12~10 minecraft:cobblestone
fill ~60~13~10 ~60~13~11 minecraft:stone 0
fill ~60~16~10 ~60~16~11 minecraft:stone 0
setblock ~60~17~10 minecraft:snow
fill ~60~25~10 ~67~25~10 minecraft:air
fill ~60~26~10 ~60~26~11 minecraft:fence 4
fill ~60~27~10 ~67~27~39 minecraft:air
fill ~60~28~10 ~67~29~38 minecraft:air
fill ~61~10~10 ~61~10~13 minecraft:air
setblock ~61~11~10 minecraft:emerald_block
setblock ~61~12~10 minecraft:obsidian
setblock ~61~13~10 minecraft:snow
fill ~61~14~10 ~61~14~11 minecraft:stone 0
fill ~61~16~10 ~61~16~11 minecraft:cobblestone
setblock ~61~17~10 minecraft:stone 0
fill ~61~26~10 ~67~26~40 minecraft:air
fill ~62~15~10 ~62~15~99 minecraft:air
fill ~62~16~10 ~62~16~74 minecraft:air
fill ~62~18~10 ~63~18~10 minecraft:obsidian
setblock ~63~10~10 minecraft:emerald_block
setblock ~63~11~10 minecraft:snow
setblock ~63~12~10 minecraft:stone 0
setblock ~63~13~10 minecraft:snow
setblock ~63~14~10 minecraft:stone 0
fill ~63~15~10 ~64~15~10 minecraft:cobblestone
setblock ~63~16~10 minecraft:obsidian
fill ~63~17~10 ~64~17~10 minecraft:stone 0
fill ~64~10~10 ~99~12~10 minecraft:air
setblock ~64~13~10 minecraft:emerald_block
setblock ~64~16~10 minecraft:cobblestone
setblock ~64~18~10 minecraft:stone 0
fill ~64~19~10 ~65~19~13 minecraft:planks 0
fill ~64~20~10 ~64~20~12 minecraft:air
fill ~65~13~10 ~99~13~10 minecraft:air
fill ~65~14~10 ~65~15~10 minecraft:snow
setblock ~65~16~10 minecraft:stone 0
setblock ~65~17~10 minecraft:emerald_block
setblock ~65~18~10 minecraft:cobblestone
fill ~65~20~10 ~65~20~13 minecraft:wooden_slab 0
fill ~66~14~10 ~66~15~15 minecraft:air
fill ~66~16~10 ~66~16~11 minecraft:air
setblock ~66~17~10 minecraft:air
setblock ~66~18~10 minecraft:snow
fill ~66~20~10 ~66~20~16 minecraft:planks 0
setblock ~67~14~10 minecraft:obsidian
setblock ~67~15~10 minecraft:dirt 0
fill ~67~16~10 ~67~19~10 minecraft:stone 0
fill ~67~20~10 ~68~20~10 minecraft:stained_hardened_clay 15
fill ~68~14~10 ~99~14~12 minecraft:air
fill ~68~15~10 ~99~17~10 minecraft:air
fill ~68~18~10 ~68~18~11 minecraft:stone 0
setblock ~68~19~10 minecraft:stone 0
setblock ~68~21~10 minecraft:stained_hardened_clay 15
fill ~68~22~10 ~68~30~10 minecraft:fence 4
fill ~68~31~10 ~99~35~12 minecraft:air
fill ~69~18~10 ~99~30~10 minecraft:air
fill ~0~9~11 ~44~9~12 minecraft:air
fill ~0~25~11 ~23~69~11 minecraft:air
fill ~24~25~11 ~26~25~11 minecraft:stained_hardened_clay 15
fill ~24~26~11 ~25~30~43 minecraft:air
fill ~24~31~11 ~29~31~42 minecraft:air
fill ~24~32~11 ~29~69~41 minecraft:air
fill ~26~26~11 ~30~26~11 minecraft:stained_hardened_clay 15
fill ~26~27~11 ~29~30~42 minecraft:air
fill ~27~25~11 ~43~25~11 minecraft:air
fill ~30~27~11 ~32~27~11 minecraft:stained_hardened_clay 15
fill ~30~28~11 ~30~36~11 minecraft:fence 4
fill ~30~37~11 ~43~51~13 minecraft:air
fill ~30~52~11 ~41~69~72 minecraft:air
fill ~31~26~11 ~43~26~11 minecraft:air
fill ~31~28~11 ~43~36~11 minecraft:air
fill ~33~27~11 ~43~27~11 minecraft:air
setblock ~42~52~11 minecraft:nether_brick_stairs 2
fill ~42~53~11 ~42~69~75 minecraft:air
setblock ~43~14~11 minecraft:air
fill ~43~15~11 ~43~15~12 minecraft:cobblestone
setblock ~43~16~11 minecraft:cobblestone
setblock ~44~13~11 minecraft:stone 0
fill ~44~20~11 ~44~25~11 minecraft:fence 4
fill ~44~30~11 ~44~35~11 minecraft:fence 4
fill ~44~40~11 ~44~45~11 minecraft:fence 4
fill ~44~49~11 ~45~49~13 minecraft:air
fill ~44~52~11 ~44~52~14 minecraft:planks 4
setblock ~45~9~11 minecraft:stone 0
setblock ~45~10~11 minecraft:cobblestone
fill ~45~11~11 ~47~11~11 minecraft:stone 0
fill ~45~12~11 ~46~12~12 minecraft:stone 0
fill ~45~14~11 ~46~14~11 minecraft:obsidian
setblock ~45~15~11 minecraft:stone 0
fill ~45~16~11 ~47~16~11 minecraft:obsidian
setblock ~45~18~11 minecraft:snow
setblock ~45~19~11 minecraft:stained_hardened_clay 15
setblock ~45~20~11 minecraft:stained_hardened_clay 13
fill ~45~21~11 ~45~22~11 minecraft:snow
setblock ~45~23~11 minecraft:stained_hardened_clay 15
fill ~45~25~11 ~45~26~11 minecraft:stained_hardened_clay 13
fill ~45~27~11 ~45~27~12 minecraft:stained_hardened_clay 15
setblock ~45~29~11 minecraft:snow
setblock ~45~30~11 minecraft:emerald_block
setblock ~45~31~11 minecraft:snow
setblock ~45~32~11 minecraft:stained_hardened_clay 15
setblock ~45~33~11 minecraft:emerald_block
setblock ~45~34~11 minecraft:stained_hardened_clay 15
setblock ~45~35~11 minecraft:stained_hardened_clay 13
setblock ~45~36~11 minecraft:stained_hardened_clay 15
setblock ~45~37~11 minecraft:emerald_block
fill ~45~38~11 ~45~38~14 minecraft:stained_hardened_clay 15
fill ~45~39~11 ~45~39~12 minecraft:stained_hardened_clay 13
setblock ~45~40~11 minecraft:stained_hardened_clay 15
setblock ~45~43~11 minecraft:snow
setblock ~45~44~11 minecraft:stained_hardened_clay 15
setblock ~45~47~11 minecraft:emerald_block
fill ~45~48~11 ~45~48~13 minecraft:air
fill ~45~50~11 ~45~50~13 minecraft:air
fill ~45~51~11 ~45~52~11 minecraft:red_sandstone 1
fill ~45~53~11 ~45~53~13 minecraft:planks 4
fill ~45~54~11 ~45~69~99 minecraft:air
setblock ~46~8~11 minecraft:stone 0
fill ~46~9~11 ~47~9~11 minecraft:obsidian
fill ~46~10~11 ~49~10~11 minecraft:stone 0
setblock ~46~15~11 minecraft:cobblestone
fill ~46~22~11 ~46~22~12 minecraft:wooden_slab 4
fill ~46~30~11 ~46~33~14 minecraft:air
fill ~46~34~11 ~47~34~11 minecraft:air
fill ~46~36~11 ~46~39~13 minecraft:air
setblock ~46~40~11 minecraft:wooden_slab 12
fill ~46~41~11 ~46~41~14 minecraft:air
fill ~46~42~11 ~46~44~13 minecraft:air
fill ~46~53~11 ~46~53~13 minecraft:air
fill ~46~54~11 ~46~54~13 minecraft:planks 4
fill ~46~55~11 ~46~69~99 minecraft:air
fill ~47~3~11 ~47~4~16 minecraft:air
setblock ~47~5~11 minecraft:stone 0
setblock ~47~6~11 minecraft:obsidian
setblock ~47~7~11 minecraft:stone 0
setblock ~47~8~11 minecraft:obsidian
setblock ~47~12~11 minecraft:cobblestone
fill ~47~14~11 ~47~14~13 minecraft:stone 0
fill ~47~23~11 ~47~23~12 minecraft:fence 4
fill ~47~24~11 ~48~24~11 minecraft:fence 4
fill ~47~25~11 ~47~26~15 minecraft:air
fill ~47~27~11 ~47~27~14 minecraft:air
fill ~47~29~11 ~47~29~13 minecraft:fence 4
setblock ~47~30~11 minecraft:fence 4
fill ~47~31~11 ~51~31~15 minecraft:air
fill ~47~32~11 ~47~33~15 minecraft:air
setblock ~47~35~11 minecraft:air
fill ~47~36~11 ~47~36~12 minecraft:fence 4
fill ~47~37~11 ~51~37~15 minecraft:air
fill ~47~38~11 ~47~38~15 minecraft:air
fill ~47~39~11 ~47~40~13 minecraft:air
fill ~47~41~11 ~47~41~13 minecraft:fence 4
fill ~47~42~11 ~48~42~11 minecraft:fence 4
fill ~47~43~11 ~47~44~15 minecraft:air
fill ~47~54~11 ~47~54~13 minecraft:air
fill ~47~55~11 ~47~55~13 minecraft:planks 4
fill ~47~56~11 ~47~69~11 minecraft:air
setblock ~48~11~11 minecraft:cobblestone
setblock ~48~14~11 minecraft:emerald_block
fill ~48~16~11 ~49~16~11 minecraft:cobblestone
fill ~48~55~11 ~50~55~13 minecraft:air
setblock ~48~56~11 minecraft:planks 4
fill ~48~57~11 ~48~69~11 minecraft:air
setblock ~49~7~11 minecraft:air
setblock ~49~8~11 minecraft:stone 0
fill ~49~11~11 ~49~11~13 minecraft:stone 0
fill ~49~24~11 ~49~26~15 minecraft:air
fill ~49~42~11 ~49~43~15 minecraft:air
fill ~49~56~11 ~49~56~13 minecraft:air
fill ~49~57~11 ~49~59~11 minecraft:planks 4
fill ~49~60~11 ~99~69~11 minecraft:air
fill ~50~8~11 ~50~8~99 minecraft:air
setblock ~50~9~11 minecraft:air
fill ~50~12~11 ~52~12~11 minecraft:stone 0
fill ~50~14~11 ~50~14~15 minecraft:stone 0
fill ~50~16~11 ~51~16~11 minecraft:stone 0
fill ~50~25~11 ~51~25~11 minecraft:fence 4
fill ~50~26~11 ~50~26~14 minecraft:air
fill ~50~43~11 ~51~43~15 minecraft:air
setblock ~50~56~11 minecraft:planks 4
fill ~50~57~11 ~99~59~11 minecraft:air
setblock ~51~6~11 minecraft:snow
fill ~51~7~11 ~51~9~11 minecraft:cobblestone
setblock ~51~10~11 minecraft:stone 0
setblock ~51~11~11 minecraft:emerald_block
fill ~51~13~11 ~51~13~13 minecraft:stone 0
setblock ~51~15~11 minecraft:obsidian
fill ~51~24~11 ~52~24~14 minecraft:air
fill ~51~26~11 ~51~26~13 minecraft:fence 4
fill ~51~32~11 ~51~32~12 minecraft:fence 4
fill ~51~33~11 ~51~34~11 minecraft:air
fill ~51~38~11 ~51~38~13 minecraft:fence 4
fill ~51~42~11 ~52~42~14 minecraft:air
fill ~51~44~11 ~51~44~13 minecraft:fence 4
fill ~51~54~11 ~51~54~13 minecraft:air
fill ~51~55~11 ~51~55~13 minecraft:planks 4
fill ~51~56~11 ~99~56~11 minecraft:air
fill ~52~7~11 ~53~8~11 minecraft:obsidian
fill ~52~10~11 ~52~11~11 minecraft:cobblestone
fill ~52~15~11 ~55~15~11 minecraft:stone 0
fill ~52~25~11 ~52~25~12 minecraft:wooden_slab 4
fill ~52~26~11 ~52~26~13 minecraft:air
fill ~52~30~11 ~52~30~14 minecraft:air
setblock ~52~31~11 minecraft:wooden_slab 12
fill ~52~37~11 ~52~37~12 minecraft:wooden_slab 4
fill ~52~38~11 ~52~39~13 minecraft:air
fill ~52~43~11 ~52~43~12 minecraft:wooden_slab 4
fill ~52~44~11 ~52~44~13 minecraft:air
fill ~52~53~11 ~52~53~13 minecraft:air
fill ~52~54~11 ~52~54~13 minecraft:planks 4
fill ~52~55~11 ~99~55~47 minecraft:air
fill ~53~4~11 ~53~6~99 minecraft:air
fill ~53~18~11 ~54~19~13 minecraft:air
fill ~53~20~11 ~53~20~13 minecraft:air
setblock ~53~21~11 minecraft:stained_hardened_clay 15
setblock ~53~23~11 minecraft:emerald_block
setblock ~53~24~11 minecraft:stained_hardened_clay 13
fill ~53~25~11 ~53~26~11 minecraft:stained_hardened_clay 15
fill ~53~27~11 ~53~27~12 minecraft:emerald_block
setblock ~53~31~11 minecraft:snow
setblock ~53~32~11 minecraft:stained_hardened_clay 15
fill ~53~33~11 ~53~34~11 minecraft:emerald_block
setblock ~53~35~11 minecraft:snow
fill ~53~36~11 ~53~36~12 minecraft:stained_hardened_clay 15
fill ~53~37~11 ~53~37~14 minecraft:stained_hardened_clay 13
setblock ~53~38~11 minecraft:stained_hardened_clay 15
setblock ~53~40~11 minecraft:stained_hardened_clay 13
setblock ~53~41~11 minecraft:snow
setblock ~53~42~11 minecraft:stained_hardened_clay 13
setblock ~53~44~11 minecraft:emerald_block
fill ~53~45~11 ~53~45~13 minecraft:stained_hardened_clay 15
setblock ~53~46~11 minecraft:emerald_block
setblock ~53~47~11 minecraft:snow
fill ~53~48~11 ~53~50~13 minecraft:air
fill ~53~51~11 ~53~52~11 minecraft:red_sandstone 1
fill ~53~53~11 ~53~53~13 minecraft:planks 4
fill ~53~54~11 ~99~54~46 minecraft:air
setblock ~54~9~11 minecraft:snow
setblock ~54~10~11 minecraft:obsidian
setblock ~54~11~11 minecraft:emerald_block
fill ~54~12~11 ~54~13~11 minecraft:stone 0
setblock ~54~21~11 minecraft:nether_brick_stairs 5
fill ~54~22~11 ~54~25~11 minecraft:fence 4
fill ~54~30~11 ~54~35~11 minecraft:fence 4
fill ~54~40~11 ~54~45~11 minecraft:fence 4
fill ~54~49~11 ~54~49~13 minecraft:air
fill ~54~52~11 ~54~52~14 minecraft:planks 4
fill ~54~53~11 ~99~53~45 minecraft:air
setblock ~55~9~11 minecraft:obsidian
setblock ~55~12~11 minecraft:snow
fill ~55~13~11 ~56~13~11 minecraft:stone 0
fill ~55~16~11 ~56~16~11 minecraft:stone 0
fill ~55~21~11 ~68~24~13 minecraft:air
fill ~55~25~11 ~59~25~42 minecraft:air
fill ~55~30~11 ~99~30~12 minecraft:air
fill ~55~31~11 ~67~35~39 minecraft:air
fill ~55~40~11 ~99~45~44 minecraft:air
setblock ~55~52~11 minecraft:nether_brick_stairs 2
setblock ~56~9~11 minecraft:air
setblock ~56~10~11 minecraft:obsidian
setblock ~56~11~11 minecraft:snow
fill ~56~12~11 ~56~12~13 minecraft:obsidian
fill ~56~15~11 ~57~15~11 minecraft:snow
fill ~56~52~11 ~56~52~12 minecraft:nether_brick_stairs 1
fill ~57~12~11 ~57~13~11 minecraft:emerald_block
setblock ~57~14~11 minecraft:obsidian
fill ~57~52~11 ~99~52~42 minecraft:air
fill ~58~15~11 ~59~15~11 minecraft:air
fill ~58~16~11 ~58~16~14 minecraft:obsidian
fill ~58~17~11 ~59~17~11 minecraft:snow
fill ~60~10~11 ~60~12~99 minecraft:air
setblock ~60~15~11 minecraft:stone 0
fill ~60~17~11 ~61~17~11 minecraft:cobblestone
setblock ~60~25~11 minecraft:glowstone
fill ~61~11~11 ~61~11~13 minecraft:air
fill ~61~12~11 ~61~13~12 minecraft:air
fill ~61~25~11 ~99~25~12 minecraft:air
fill ~62~17~11 ~62~18~73 minecraft:air
fill ~63~10~11 ~66~11~11 minecraft:air
fill ~63~12~11 ~63~16~12 minecraft:air
fill ~63~17~11 ~63~18~11 minecraft:snow
fill ~64~12~11 ~65~12~12 minecraft:obsidian
setblock ~64~13~11 minecraft:obsidian
setblock ~64~14~11 minecraft:emerald_block
setblock ~64~15~11 minecraft:stone 0
setblock ~64~16~11 minecraft:snow
fill ~64~17~11 ~65~17~11 minecraft:cobblestone
fill ~64~18~11 ~64~18~12 minecraft:obsidian
fill ~65~13~11 ~65~13~13 minecraft:snow
fill ~65~14~11 ~65~15~11 minecraft:obsidian
setblock ~65~16~11 minecraft:cobblestone
setblock ~65~18~11 minecraft:stone 0
fill ~66~12~11 ~66~13~15 minecraft:air
setblock ~66~17~11 minecraft:snow
fill ~66~18~11 ~66~19~11 minecraft:obsidian
fill ~67~10~11 ~67~11~11 minecraft:obsidian
setblock ~67~12~11 minecraft:stone 0
fill ~67~13~11 ~67~15~11 minecraft:cobblestone
setblock ~67~16~11 minecraft:obsidian
fill ~67~17~11 ~68~17~11 minecraft:stone 0
setblock ~67~18~11 minecraft:cobblestone
setblock ~67~19~11 minecraft:emerald_block
fill ~67~20~11 ~68~20~15 minecraft:planks 0
fill ~68~10~11 ~99~11~16 minecraft:air
fill ~68~12~11 ~99~12~14 minecraft:air
fill ~68~13~11 ~99~13~12 minecraft:air
fill ~68~15~11 ~68~16~11 minecraft:stone 0
setblock ~68~19~11 minecraft:cobblestone
fill ~68~26~11 ~99~26~12 minecraft:air
fill ~68~27~11 ~68~29~11 minecraft:fence 4
fill ~69~15~11 ~99~15~12 minecraft:air
fill ~69~16~11 ~99~17~11 minecraft:air
setblock ~69~18~11 minecraft:obsidian
fill ~69~19~11 ~69~20~11 minecraft:stone 0
fill ~69~21~11 ~70~21~11 minecraft:stained_hardened_clay 15
fill ~69~22~11 ~99~24~12 minecraft:air
fill ~69~27~11 ~99~29~12 minecraft:air
fill ~70~18~11 ~99~18~11 minecraft:air
setblock ~70~19~11 minecraft:emerald_block
setblock ~70~20~11 minecraft:stone 0
fill ~71~19~11 ~99~21~11 minecraft:air
fill ~0~2~12 ~48~2~16 minecraft:air
fill ~0~13~12 ~42~13~12 minecraft:air
fill ~0~16~12 ~24~16~13 minecraft:air
fill ~0~17~12 ~24~17~12 minecraft:air
fill ~0~18~12 ~23~23~12 minecraft:air
fill ~0~24~12 ~20~69~12 minecraft:air
fill ~21~24~12 ~22~24~12 minecraft:stained_hardened_clay 15
fill ~21~25~12 ~21~29~45 minecraft:air
fill ~21~30~12 ~21~69~44 minecraft:air
fill ~22~25~12 ~23~25~12 minecraft:stained_hardened_clay 15
fill ~22~26~12 ~22~34~12 minecraft:fence 4
fill ~22~35~12 ~23~69~99 minecraft:air
setblock ~23~24~12 minecraft:air
fill ~23~26~12 ~23~30~44 minecraft:air
fill ~23~31~12 ~23~34~43 minecraft:air
fill ~24~18~12 ~25~18~12 minecraft:obsidian
fill ~24~19~12 ~25~19~12 minecraft:emerald_block
setblock ~24~20~12 minecraft:cobblestone
fill ~24~21~12 ~25~22~12 minecraft:stone 0
setblock ~24~23~12 minecraft:cobblestone
fill ~24~24~12 ~25~24~16 minecraft:planks 0
fill ~24~25~12 ~24~25~43 minecraft:air
fill ~25~16~12 ~25~17~12 minecraft:obsidian
fill ~25~20~12 ~26~20~12 minecraft:obsidian
setblock ~25~23~12 minecraft:stone 0
fill ~25~25~12 ~25~25~15 minecraft:wooden_slab 0
setblock ~26~16~12 minecraft:emerald_block
setblock ~26~17~12 minecraft:obsidian
setblock ~26~18~12 minecraft:emerald_block
fill ~26~19~12 ~31~19~12 minecraft:obsidian
setblock ~26~21~12 minecraft:dirt 0
fill ~26~22~12 ~26~24~12 minecraft:air
fill ~26~25~12 ~29~25~14 minecraft:planks 0
fill ~26~26~12 ~28~26~19 minecraft:air
fill ~27~16~12 ~42~16~16 minecraft:air
setblock ~27~17~12 minecraft:emerald_block
setblock ~27~18~12 minecraft:obsidian
fill ~27~20~12 ~27~21~12 minecraft:snow
setblock ~27~22~12 minecraft:obsidian
fill ~27~23~12 ~27~23~13 minecraft:emerald_block
setblock ~27~24~12 minecraft:snow
fill ~28~17~12 ~42~17~12 minecraft:air
fill ~28~18~12 ~30~18~12 minecraft:air
fill ~28~20~12 ~28~20~14 minecraft:obsidian
fill ~28~21~12 ~30~21~12 minecraft:obsidian
setblock ~28~22~12 minecraft:emerald_block
fill ~28~23~12 ~28~23~16 minecraft:stone 0
fill ~28~24~12 ~29~24~12 minecraft:stone 0
setblock ~29~20~12 minecraft:snow
setblock ~29~22~12 minecraft:obsidian
fill ~29~23~12 ~30~23~12 minecraft:dirt 0
fill ~29~26~12 ~29~26~19 minecraft:wooden_slab 0
setblock ~30~20~12 minecraft:obsidian
setblock ~30~22~12 minecraft:emerald_block
fill ~30~24~12 ~30~25~12 minecraft:air
fill ~30~26~12 ~32~26~19 minecraft:planks 0
fill ~30~27~12 ~32~32~19 minecraft:air
fill ~30~33~12 ~30~35~12 minecraft:fence 4
fill ~30~36~12 ~43~36~13 minecraft:air
setblock ~31~18~12 minecraft:snow
setblock ~31~20~12 minecraft:snow
setblock ~31~21~12 minecraft:emerald_block
fill ~31~22~12 ~31~22~13 minecraft:obsidian
fill ~31~23~12 ~31~23~13 minecraft:emerald_block
fill ~31~24~12 ~31~24~15 minecraft:obsidian
fill ~31~25~12 ~32~25~12 minecraft:snow
fill ~31~33~12 ~44~35~12 minecraft:air
fill ~32~18~12 ~42~19~14 minecraft:air
fill ~32~20~12 ~42~21~12 minecraft:air
setblock ~32~22~12 minecraft:snow
fill ~32~23~12 ~32~23~13 minecraft:obsidian
setblock ~32~24~12 minecraft:emerald_block
fill ~33~22~12 ~42~26~12 minecraft:air
fill ~33~27~12 ~34~27~12 minecraft:stained_hardened_clay 15
fill ~33~28~12 ~33~32~42 minecraft:air
fill ~34~28~12 ~35~28~12 minecraft:stained_hardened_clay 15
fill ~34~29~12 ~43~32~13 minecraft:air
fill ~35~27~12 ~43~27~12 minecraft:air
fill ~36~28~12 ~43~28~12 minecraft:air
fill ~42~52~12 ~42~52~13 minecraft:nether_brick_stairs 0
fill ~43~13~12 ~44~13~12 minecraft:obsidian
setblock ~43~14~12 minecraft:obsidian
setblock ~43~16~12 minecraft:stone 0
fill ~43~25~12 ~44~25~12 minecraft:air
fill ~43~26~12 ~43~26~17 minecraft:air
setblock ~43~52~12 minecraft:planks 4
setblock ~44~14~12 minecraft:snow
fill ~44~16~12 ~44~16~14 minecraft:obsidian
fill ~44~20~12 ~44~24~12 minecraft:air
fill ~44~30~12 ~44~32~12 minecraft:air
fill ~44~40~12 ~44~45~12 minecraft:air
setblock ~45~9~12 minecraft:emerald_block
fill ~45~10~12 ~46~10~12 minecraft:obsidian
fill ~45~11~12 ~47~11~12 minecraft:cobblestone
fill ~45~13~12 ~45~14~12 minecraft:stone 0
fill ~45~15~12 ~45~16~12 minecraft:cobblestone
fill ~45~18~12 ~45~19~13 minecraft:stained_hardened_clay 13
setblock ~45~20~12 minecraft:snow
fill ~45~21~12 ~45~24~12 minecraft:fence 4
setblock ~45~25~12 minecraft:stained_hardened_clay 15
setblock ~45~26~12 minecraft:emerald_block
fill ~45~28~12 ~45~30~12 minecraft:stained_hardened_clay 15
fill ~45~31~12 ~45~34~12 minecraft:fence 4
setblock ~45~35~12 minecraft:emerald_block
setblock ~45~36~12 minecraft:snow
fill ~45~37~12 ~45~37~13 minecraft:stained_hardened_clay 15
setblock ~45~40~12 minecraft:stained_hardened_clay 13
fill ~45~41~12 ~45~44~12 minecraft:fence 4
setblock ~45~45~12 minecraft:stained_hardened_clay 13
fill ~45~46~12 ~45~47~12 minecraft:stained_hardened_clay 15
setblock ~45~51~12 minecraft:air
fill ~45~52~12 ~45~52~13 minecraft:red_sandstone 1
fill ~46~8~12 ~46~8~14 minecraft:air
setblock ~46~9~12 minecraft:obsidian
setblock ~46~13~12 minecraft:cobblestone
fill ~46~14~12 ~46~15~14 minecraft:stone 0
setblock ~46~16~12 minecraft:obsidian
setblock ~46~28~12 minecraft:wooden_slab 12
fill ~46~29~12 ~46~29~13 minecraft:air
setblock ~46~34~12 minecraft:wooden_slab 12
fill ~46~35~12 ~46~35~14 minecraft:air
fill ~46~40~12 ~46~40~13 minecraft:wooden_slab 4
setblock ~46~52~12 minecraft:torch 1
fill ~47~5~12 ~47~7~16 minecraft:air
fill ~47~8~12 ~48~10~12 minecraft:stone 0
fill ~47~12~12 ~47~12~14 minecraft:stone 0
setblock ~47~13~12 minecraft:obsidian
fill ~47~15~12 ~47~16~12 minecraft:cobblestone
fill ~47~22~12 ~47~22~13 minecraft:fence 4
fill ~47~24~12 ~48~24~15 minecraft:air
fill ~47~28~12 ~52~28~13 minecraft:air
fill ~47~30~12 ~48~30~15 minecraft:air
fill ~47~34~12 ~47~34~13 minecraft:air
fill ~47~35~12 ~47~35~13 minecraft:fence 4
fill ~47~42~12 ~48~42~15 minecraft:air
setblock ~47~56~12 minecraft:planks 4
fill ~47~57~12 ~47~69~99 minecraft:air
fill ~48~3~12 ~48~3~99 minecraft:air
setblock ~48~11~12 minecraft:stone 0
setblock ~48~12~12 minecraft:obsidian
fill ~48~14~12 ~48~16~13 minecraft:stone 0
fill ~48~22~12 ~51~22~12 minecraft:air
fill ~48~36~12 ~48~36~15 minecraft:air
setblock ~48~56~12 minecraft:air
fill ~48~57~12 ~48~59~12 minecraft:planks 4
fill ~48~60~12 ~48~69~99 minecraft:air
setblock ~49~2~12 minecraft:stone 0
setblock ~49~3~12 minecraft:snow
setblock ~49~4~12 minecraft:cobblestone
fill ~49~5~12 ~49~7~12 minecraft:stone 0
setblock ~49~8~12 minecraft:obsidian
setblock ~49~9~12 minecraft:cobblestone
fill ~49~10~12 ~50~10~12 minecraft:stone 0
setblock ~49~13~12 minecraft:cobblestone
fill ~49~15~12 ~49~15~13 minecraft:obsidian
setblock ~49~16~12 minecraft:obsidian
fill ~49~57~12 ~49~59~12 minecraft:air
fill ~49~60~12 ~49~63~12 minecraft:planks 4
fill ~49~64~12 ~99~69~99 minecraft:air
fill ~50~2~12 ~99~3~45 minecraft:air
setblock ~50~9~12 minecraft:stone 0
setblock ~50~11~12 minecraft:cobblestone
fill ~50~12~12 ~50~13~12 minecraft:stone 0
fill ~50~15~12 ~53~15~13 minecraft:stone 0
setblock ~50~16~12 minecraft:stone 0
fill ~50~25~12 ~51~25~15 minecraft:air
fill ~50~32~12 ~50~32~15 minecraft:air
fill ~50~38~12 ~50~38~14 minecraft:air
fill ~50~44~12 ~50~44~14 minecraft:air
setblock ~50~56~12 minecraft:air
fill ~50~57~12 ~50~59~12 minecraft:planks 4
fill ~50~60~12 ~99~63~49 minecraft:air
fill ~51~6~12 ~51~9~99 minecraft:air
setblock ~51~10~12 minecraft:snow
setblock ~51~11~12 minecraft:stone 0
setblock ~51~12~12 minecraft:cobblestone
fill ~51~14~12 ~51~14~13 minecraft:stone 0
fill ~51~16~12 ~52~16~12 minecraft:cobblestone
fill ~51~33~12 ~51~33~13 minecraft:fence 4
fill ~51~34~12 ~52~34~12 minecraft:air
setblock ~51~56~12 minecraft:planks 4
fill ~51~57~12 ~99~59~48 minecraft:air
fill ~52~7~12 ~54~8~99 minecraft:air
fill ~52~9~12 ~52~11~13 minecraft:air
setblock ~52~12~12 minecraft:snow
fill ~52~13~12 ~52~14~13 minecraft:obsidian
fill ~52~31~12 ~52~31~14 minecraft:air
fill ~52~32~12 ~52~32~13 minecraft:wooden_slab 4
fill ~52~33~12 ~52~33~14 minecraft:air
fill ~52~35~12 ~52~35~14 minecraft:air
setblock ~52~52~12 minecraft:torch 2
fill ~52~56~12 ~99~56~47 minecraft:air
setblock ~53~9~12 minecraft:obsidian
setblock ~53~10~12 minecraft:snow
setblock ~53~13~12 minecraft:stone 0
setblock ~53~16~12 minecraft:stone 0
fill ~53~21~12 ~54~21~12 minecraft:air
fill ~53~23~12 ~53~24~12 minecraft:fence 4
setblock ~53~25~12 minecraft:emerald_block
fill ~53~26~12 ~53~26~13 minecraft:stained_hardened_clay 13
fill ~53~28~12 ~53~29~12 minecraft:stained_hardened_clay 13
setblock ~53~30~12 minecraft:snow
fill ~53~31~12 ~53~34~12 minecraft:fence 4
fill ~53~35~12 ~53~35~13 minecraft:stained_hardened_clay 15
setblock ~53~38~12 minecraft:emerald_block
fill ~53~40~12 ~53~40~14 minecraft:stained_hardened_clay 15
fill ~53~41~12 ~53~44~12 minecraft:fence 4
setblock ~53~46~12 minecraft:stained_hardened_clay 15
setblock ~53~47~12 minecraft:stained_hardened_clay 13
setblock ~53~51~12 minecraft:air
fill ~53~52~12 ~53~52~13 minecraft:red_sandstone 1
fill ~54~9~12 ~54~14~99 minecraft:air
setblock ~54~15~12 minecraft:emerald_block
fill ~54~16~12 ~55~16~12 minecraft:snow
setblock ~54~22~12 minecraft:nether_brick_stairs 5
fill ~54~23~12 ~54~25~12 minecraft:air
fill ~54~30~12 ~54~35~12 minecraft:air
fill ~54~40~12 ~54~45~12 minecraft:air
setblock ~55~7~12 minecraft:snow
setblock ~55~8~12 minecraft:obsidian
setblock ~55~9~12 minecraft:emerald_block
setblock ~55~10~12 minecraft:cobblestone
setblock ~55~11~12 minecraft:stone 0
fill ~55~12~12 ~55~12~13 minecraft:obsidian
fill ~55~13~12 ~55~15~12 minecraft:stone 0
setblock ~55~52~12 minecraft:planks 4
fill ~56~7~12 ~56~8~99 minecraft:air
setblock ~56~9~12 minecraft:obsidian
fill ~56~10~12 ~56~11~12 minecraft:emerald_block
setblock ~56~13~12 minecraft:cobblestone
fill ~56~14~12 ~57~15~13 minecraft:stone 0
fill ~56~16~12 ~57~16~12 minecraft:stone 0
setblock ~57~7~12 minecraft:snow
fill ~57~8~12 ~57~8~13 minecraft:obsidian
setblock ~57~9~12 minecraft:emerald_block
fill ~57~11~12 ~57~12~12 minecraft:snow
fill ~57~13~12 ~57~13~13 minecraft:stone 0
fill ~58~7~12 ~99~7~23 minecraft:air
fill ~58~8~12 ~58~11~99 minecraft:air
fill ~58~13~12 ~58~13~99 minecraft:air
fill ~58~14~12 ~58~15~12 minecraft:obsidian
fill ~58~17~12 ~58~17~13 minecraft:snow
setblock ~59~9~12 minecraft:emerald_block
setblock ~59~10~12 minecraft:obsidian
setblock ~59~11~12 minecraft:snow
setblock ~59~12~12 minecraft:stone 0
setblock ~59~13~12 minecraft:cobblestone
setblock ~59~14~12 minecraft:stone 0
setblock ~59~15~12 minecraft:obsidian
setblock ~59~16~12 minecraft:cobblestone
fill ~59~17~12 ~59~17~13 minecraft:obsidian
fill ~60~13~12 ~60~13~13 minecraft:air
fill ~60~15~12 ~60~16~12 minecraft:snow
fill ~60~17~12 ~61~17~12 minecraft:stone 0
fill ~60~25~12 ~60~26~41 minecraft:air
fill ~61~14~12 ~61~14~13 minecraft:obsidian
setblock ~61~16~12 minecraft:snow
fill ~63~8~12 ~64~9~99 minecraft:air
fill ~63~10~12 ~64~11~12 minecraft:air
fill ~63~17~12 ~63~18~12 minecraft:obsidian
setblock ~64~13~12 minecraft:emerald_block
setblock ~64~14~12 minecraft:obsidian
setblock ~64~15~12 minecraft:emerald_block
setblock ~64~16~12 minecraft:cobblestone
setblock ~64~17~12 minecraft:stone 0
setblock ~65~8~12 minecraft:emerald_block
setblock ~65~9~12 minecraft:obsidian
setblock ~65~10~12 minecraft:snow
setblock ~65~11~12 minecraft:obsidian
fill ~65~14~12 ~65~15~12 minecraft:snow
setblock ~65~16~12 minecraft:stone 0
setblock ~65~17~12 minecraft:emerald_block
setblock ~65~18~12 minecraft:obsidian
fill ~66~8~12 ~99~8~16 minecraft:air
fill ~66~9~12 ~99~9~15 minecraft:air
fill ~66~10~12 ~67~10~15 minecraft:air
fill ~66~11~12 ~67~11~14 minecraft:air
fill ~66~16~12 ~66~17~12 minecraft:obsidian
fill ~66~18~12 ~66~18~13 minecraft:snow
setblock ~66~19~12 minecraft:snow
fill ~67~12~12 ~67~16~14 minecraft:air
fill ~67~17~12 ~67~17~13 minecraft:air
fill ~67~18~12 ~67~18~14 minecraft:emerald_block
setblock ~67~19~12 minecraft:obsidian
fill ~68~15~12 ~68~15~13 minecraft:air
setblock ~68~16~12 minecraft:cobblestone
fill ~68~17~12 ~69~17~12 minecraft:stone 0
setblock ~68~18~12 minecraft:obsidian
setblock ~68~19~12 minecraft:stone 0
setblock ~68~27~12 minecraft:air
fill ~68~28~12 ~68~28~13 minecraft:fence 4
fill ~68~29~12 ~68~29~37 minecraft:air
setblock ~69~16~12 minecraft:stone 0
fill ~69~18~12 ~69~19~12 minecraft:cobblestone
fill ~69~20~12 ~69~20~14 minecraft:planks 0
fill ~69~21~12 ~69~21~14 minecraft:wooden_slab 0
fill ~70~16~12 ~99~16~13 minecraft:air
fill ~70~17~12 ~70~18~15 minecraft:air
fill ~70~19~12 ~70~20~14 minecraft:air
fill ~70~21~12 ~70~21~17 minecraft:planks 0
setblock ~71~17~12 minecraft:stone 0
setblock ~71~18~12 minecraft:cobblestone
setblock ~71~19~12 minecraft:stone 0
setblock ~71~20~12 minecraft:cobblestone
setblock ~71~21~12 minecraft:stained_hardened_clay 15
fill ~72~17~12 ~99~21~12 minecraft:air
fill ~0~9~13 ~43~11~13 minecraft:air
fill ~0~12~13 ~24~12~18 minecraft:air
fill ~0~13~13 ~24~13~17 minecraft:air
fill ~0~14~13 ~24~15~15 minecraft:air
fill ~0~17~13 ~20~17~15 minecraft:air
fill ~0~18~13 ~20~18~14 minecraft:air
fill ~0~19~13 ~20~23~13 minecraft:air
fill ~0~24~13 ~18~69~13 minecraft:air
fill ~19~24~13 ~20~24~13 minecraft:stained_hardened_clay 15
fill ~19~25~13 ~20~29~45 minecraft:air
fill ~19~30~13 ~20~69~44 minecraft:air
fill ~21~17~13 ~21~17~14 minecraft:obsidian
setblock ~21~18~13 minecraft:emerald_block
fill ~21~19~13 ~21~20~13 minecraft:obsidian
setblock ~21~21~13 minecraft:snow
setblock ~21~22~13 minecraft:obsidian
fill ~21~23~13 ~21~23~21 minecraft:planks 0
fill ~21~24~13 ~21~24~14 minecraft:wooden_slab 0
fill ~22~17~13 ~24~19~13 minecraft:air
fill ~22~20~13 ~23~20~13 minecraft:snow
fill ~22~21~13 ~23~21~13 minecraft:emerald_block
fill ~22~22~13 ~22~22~14 minecraft:snow
setblock ~22~23~13 minecraft:emerald_block
fill ~22~24~13 ~23~24~13 minecraft:planks 0
fill ~22~25~13 ~23~25~44 minecraft:air
fill ~22~26~13 ~22~26~45 minecraft:air
fill ~22~27~13 ~22~30~44 minecraft:air
fill ~22~31~13 ~22~33~13 minecraft:fence 4
fill ~22~34~13 ~22~34~99 minecraft:air
fill ~23~22~13 ~23~23~13 minecraft:obsidian
fill ~24~20~13 ~24~21~13 minecraft:air
setblock ~24~22~13 minecraft:snow
fill ~24~23~13 ~24~23~15 minecraft:obsidian
fill ~25~12~13 ~25~13~14 minecraft:obsidian
fill ~25~14~13 ~25~14~15 minecraft:emerald_block
setblock ~25~15~13 minecraft:emerald_block
setblock ~25~16~13 minecraft:snow
fill ~25~17~13 ~25~17~14 minecraft:cobblestone
fill ~25~18~13 ~25~22~13 minecraft:stone 0
setblock ~25~23~13 minecraft:snow
fill ~26~12~13 ~42~15~13 minecraft:air
fill ~26~16~13 ~26~18~13 minecraft:air
setblock ~26~19~13 minecraft:snow
fill ~26~20~13 ~27~21~13 minecraft:obsidian
fill ~26~22~13 ~26~23~13 minecraft:emerald_block
setblock ~26~24~13 minecraft:snow
fill ~27~17~13 ~28~17~16 minecraft:air
fill ~27~18~13 ~28~18~15 minecraft:air
fill ~27~19~13 ~28~19~13 minecraft:air
setblock ~27~22~13 minecraft:snow
setblock ~27~24~13 minecraft:obsidian
setblock ~28~21~13 minecraft:obsidian
setblock ~28~22~13 minecraft:stone 0
fill ~28~24~13 ~28~24~14 minecraft:stone 0
fill ~29~17~13 ~29~20~13 minecraft:obsidian
setblock ~29~21~13 minecraft:stone 0
fill ~29~22~13 ~29~22~15 minecraft:cobblestone
fill ~29~23~13 ~29~23~15 minecraft:stone 0
fill ~29~24~13 ~30~24~13 minecraft:emerald_block
fill ~30~17~13 ~42~17~14 minecraft:air
fill ~30~18~13 ~31~21~15 minecraft:air
fill ~30~22~13 ~30~22~16 minecraft:air
setblock ~30~23~13 minecraft:obsidian
fill ~30~25~13 ~30~25~14 minecraft:emerald_block
fill ~30~33~13 ~43~33~13 minecraft:air
fill ~30~34~13 ~30~34~14 minecraft:fence 4
fill ~30~35~13 ~43~35~13 minecraft:air
fill ~31~25~13 ~31~25~14 minecraft:obsidian
fill ~31~34~13 ~43~34~13 minecraft:air
setblock ~32~20~13 minecraft:air
fill ~32~21~13 ~33~21~14 minecraft:obsidian
setblock ~32~22~13 minecraft:emerald_block
fill ~32~24~13 ~32~24~14 minecraft:cobblestone
fill ~32~25~13 ~33~25~13 minecraft:stone 0
setblock ~33~20~13 minecraft:obsidian
setblock ~33~22~13 minecraft:snow
setblock ~33~23~13 minecraft:emerald_block
fill ~33~24~13 ~33~24~14 minecraft:stone 0
fill ~33~26~13 ~33~26~20 minecraft:planks 0
fill ~33~27~13 ~33~27~20 minecraft:wooden_slab 0
fill ~34~20~13 ~34~22~16 minecraft:air
fill ~34~23~13 ~35~23~13 minecraft:obsidian
setblock ~34~24~13 minecraft:emerald_block
fill ~34~25~13 ~35~25~14 minecraft:obsidian
fill ~34~26~13 ~34~26~14 minecraft:obsidian
fill ~34~27~13 ~35~27~20 minecraft:planks 0
fill ~34~28~13 ~35~28~18 minecraft:air
setblock ~35~20~13 minecraft:obsidian
setblock ~35~21~13 minecraft:emerald_block
setblock ~35~22~13 minecraft:snow
setblock ~35~24~13 minecraft:obsidian
setblock ~35~26~13 minecraft:emerald_block
fill ~36~20~13 ~42~20~15 minecraft:air
fill ~36~21~13 ~42~22~14 minecraft:air
fill ~36~23~13 ~42~27~13 minecraft:air
fill ~36~28~13 ~37~28~13 minecraft:stained_hardened_clay 15
fill ~38~28~13 ~43~28~13 minecraft:air
fill ~43~12~13 ~44~12~13 minecraft:snow
setblock ~43~13~13 minecraft:obsidian
setblock ~43~14~13 minecraft:snow
setblock ~43~15~13 minecraft:stone 0
setblock ~43~16~13 minecraft:cobblestone
fill ~43~25~13 ~43~25~17 minecraft:air
fill ~43~27~13 ~43~27~17 minecraft:air
setblock ~43~52~13 minecraft:nether_brick_stairs 3
fill ~44~9~13 ~44~10~14 minecraft:obsidian
fill ~44~11~13 ~47~11~13 minecraft:obsidian
fill ~44~13~13 ~44~13~15 minecraft:stone 0
fill ~44~14~13 ~45~14~14 minecraft:stone 0
fill ~44~20~13 ~44~25~13 minecraft:fence 4
fill ~44~30~13 ~44~35~13 minecraft:fence 4
fill ~44~40~13 ~44~45~13 minecraft:fence 4
fill ~45~9~13 ~46~10~13 minecraft:air
setblock ~45~12~13 minecraft:obsidian
setblock ~45~13~13 minecraft:cobblestone
fill ~45~15~13 ~45~15~14 minecraft:stone 0
fill ~45~16~13 ~46~16~13 minecraft:cobblestone
setblock ~45~20~13 minecraft:stained_hardened_clay 13
fill ~45~21~13 ~45~22~14 minecraft:stained_hardened_clay 15
setblock ~45~23~13 minecraft:stained_hardened_clay 15
fill ~45~24~13 ~45~25~13 minecraft:stained_hardened_clay 13
fill ~45~26~13 ~45~26~14 minecraft:stained_hardened_clay 15
fill ~45~27~13 ~45~28~13 minecraft:stained_hardened_clay 13
setblock ~45~29~13 minecraft:emerald_block
fill ~45~30~13 ~45~30~14 minecraft:stained_hardened_clay 13
fill ~45~31~13 ~45~32~13 minecraft:stained_hardened_clay 15
setblock ~45~33~13 minecraft:stained_hardened_clay 13
fill ~45~34~13 ~45~34~14 minecraft:stained_hardened_clay 15
setblock ~45~35~13 minecraft:stained_hardened_clay 15
setblock ~45~36~13 minecraft:stained_hardened_clay 13
fill ~45~39~13 ~45~41~13 minecraft:stained_hardened_clay 15
setblock ~45~42~13 minecraft:stained_hardened_clay 13
setblock ~45~43~13 minecraft:emerald_block
fill ~45~44~13 ~45~44~14 minecraft:stained_hardened_clay 13
fill ~45~45~13 ~45~45~14 minecraft:stained_hardened_clay 15
setblock ~45~46~13 minecraft:snow
fill ~45~47~13 ~45~47~14 minecraft:stained_hardened_clay 15
fill ~45~51~13 ~45~51~14 minecraft:red_sandstone 1
setblock ~46~12~13 minecraft:snow
fill ~46~13~13 ~47~13~15 minecraft:stone 0
setblock ~46~21~13 minecraft:wooden_slab 12
fill ~46~22~13 ~46~22~14 minecraft:air
fill ~46~28~13 ~46~28~14 minecraft:wooden_slab 4
fill ~46~34~13 ~46~34~14 minecraft:wooden_slab 4
fill ~46~52~13 ~46~52~14 minecraft:air
fill ~47~8~13 ~49~8~13 minecraft:air
fill ~47~9~13 ~47~10~14 minecraft:stone 0
fill ~47~15~13 ~47~16~13 minecraft:stone 0
setblock ~47~21~13 minecraft:air
fill ~47~23~13 ~47~23~15 minecraft:air
fill ~47~36~13 ~47~36~15 minecraft:air
fill ~47~45~13 ~49~46~13 minecraft:air
fill ~47~56~13 ~47~56~99 minecraft:air
fill ~48~9~13 ~48~10~16 minecraft:air
setblock ~48~11~13 minecraft:air
setblock ~48~12~13 minecraft:cobblestone
fill ~48~21~13 ~48~21~14 minecraft:fence 4
setblock ~48~22~13 minecraft:fence 4
fill ~48~27~13 ~49~27~13 minecraft:air
fill ~48~29~13 ~48~29~14 minecraft:fence 4
fill ~48~34~13 ~49~34~14 minecraft:air
fill ~48~35~13 ~48~35~14 minecraft:fence 4
fill ~48~39~13 ~49~40~13 minecraft:air
fill ~48~41~13 ~48~41~14 minecraft:fence 4
setblock ~48~56~13 minecraft:planks 4
fill ~48~57~13 ~48~59~99 minecraft:air
fill ~49~2~13 ~49~7~99 minecraft:air
fill ~49~9~13 ~49~10~13 minecraft:stone 0
fill ~49~13~13 ~50~13~14 minecraft:stone 0
fill ~49~16~13 ~49~16~14 minecraft:cobblestone
fill ~49~21~13 ~51~22~13 minecraft:air
fill ~49~29~13 ~51~29~15 minecraft:air
fill ~49~57~13 ~49~59~13 minecraft:planks 4
fill ~49~60~13 ~49~63~99 minecraft:air
fill ~50~9~13 ~50~11~99 minecraft:air
fill ~50~12~13 ~50~12~14 minecraft:air
setblock ~50~16~13 minecraft:snow
fill ~50~27~13 ~51~27~13 minecraft:fence 4
fill ~50~34~13 ~51~34~13 minecraft:fence 4
fill ~50~39~13 ~51~39~13 minecraft:fence 4
fill ~50~40~13 ~51~40~14 minecraft:air
fill ~50~45~13 ~51~45~13 minecraft:fence 4
fill ~50~46~13 ~51~46~14 minecraft:air
setblock ~50~56~13 minecraft:planks 4
fill ~50~57~13 ~50~59~99 minecraft:air
fill ~51~10~13 ~51~11~17 minecraft:air
setblock ~51~12~13 minecraft:stone 0
fill ~51~16~13 ~52~16~13 minecraft:stone 0
fill ~51~32~13 ~51~32~15 minecraft:air
fill ~51~56~13 ~51~56~99 minecraft:air
fill ~52~12~13 ~53~12~13 minecraft:air
setblock ~52~25~13 minecraft:wooden_slab 12
fill ~52~27~13 ~52~27~14 minecraft:air
fill ~52~34~13 ~52~34~14 minecraft:air
setblock ~52~37~13 minecraft:wooden_slab 12
setblock ~52~43~13 minecraft:wooden_slab 12
fill ~52~52~13 ~52~52~14 minecraft:air
fill ~53~9~13 ~53~11~99 minecraft:air
fill ~53~13~13 ~53~14~13 minecraft:air
setblock ~53~16~13 minecraft:emerald_block
fill ~53~21~13 ~53~21~14 minecraft:stained_hardened_clay 15
fill ~53~23~13 ~53~24~13 minecraft:stained_hardened_clay 15
fill ~53~25~13 ~53~25~14 minecraft:stained_hardened_clay 13
fill ~53~27~13 ~53~27~14 minecraft:stained_hardened_clay 13
fill ~53~28~13 ~53~28~14 minecraft:stained_hardened_clay 15
fill ~53~29~13 ~53~29~14 minecraft:stained_hardened_clay 13
fill ~53~30~13 ~53~30~14 minecraft:stained_hardened_clay 15
setblock ~53~31~13 minecraft:snow
setblock ~53~32~13 minecraft:stained_hardened_clay 15
fill ~53~33~13 ~53~33~14 minecraft:emerald_block
setblock ~53~34~13 minecraft:stained_hardened_clay 13
setblock ~53~36~13 minecraft:stained_hardened_clay 13
fill ~53~38~13 ~53~38~14 minecraft:stained_hardened_clay 15
setblock ~53~39~13 minecraft:stained_hardened_clay 13
setblock ~53~41~13 minecraft:stained_hardened_clay 13
fill ~53~42~13 ~53~43~14 minecraft:stained_hardened_clay 15
setblock ~53~44~13 minecraft:emerald_block
fill ~53~46~13 ~53~47~13 minecraft:emerald_block
fill ~53~51~13 ~53~51~14 minecraft:red_sandstone 1
fill ~54~15~13 ~54~15~14 minecraft:cobblestone
fill ~54~16~13 ~55~16~13 minecraft:cobblestone
setblock ~54~21~13 minecraft:nether_brick_stairs 5
fill ~54~22~13 ~54~25~13 minecraft:fence 4
fill ~54~30~13 ~54~35~13 minecraft:fence 4
fill ~54~40~13 ~54~45~13 minecraft:fence 4
fill ~55~7~13 ~55~10~99 minecraft:air
setblock ~55~11~13 minecraft:obsidian
fill ~55~13~13 ~56~13~13 minecraft:obsidian
setblock ~55~14~13 minecraft:obsidian
setblock ~55~15~13 minecraft:stone 0
fill ~55~30~13 ~71~30~37 minecraft:air
fill ~55~52~13 ~55~52~14 minecraft:nether_brick_stairs 1
fill ~56~9~13 ~56~9~99 minecraft:air
fill ~56~10~13 ~56~11~13 minecraft:air
setblock ~56~16~13 minecraft:stone 0
setblock ~56~52~13 minecraft:nether_brick_stairs 3
setblock ~57~7~13 minecraft:obsidian
setblock ~57~9~13 minecraft:obsidian
setblock ~57~11~13 minecraft:cobblestone
setblock ~57~12~13 minecraft:snow
fill ~57~16~13 ~57~16~14 minecraft:obsidian
fill ~58~14~13 ~59~14~99 minecraft:air
setblock ~58~15~13 minecraft:obsidian
fill ~59~9~13 ~59~13~99 minecraft:air
fill ~59~15~13 ~59~15~99 minecraft:air
setblock ~59~16~13 minecraft:snow
fill ~60~15~13 ~60~16~13 minecraft:stone 0
fill ~60~17~13 ~60~17~14 minecraft:cobblestone
fill ~61~12~13 ~61~12~14 minecraft:stone 0
setblock ~61~13~13 minecraft:cobblestone
fill ~61~16~13 ~61~16~15 minecraft:stone 0
fill ~61~17~13 ~61~17~14 minecraft:obsidian
fill ~61~25~13 ~71~25~26 minecraft:air
fill ~63~10~13 ~63~11~13 minecraft:obsidian
fill ~63~12~13 ~63~15~13 minecraft:stone 0
setblock ~63~16~13 minecraft:cobblestone
fill ~63~17~13 ~63~17~15 minecraft:stone 0
setblock ~63~18~13 minecraft:obsidian
fill ~64~10~13 ~65~12~99 minecraft:air
setblock ~64~13~13 minecraft:obsidian
setblock ~64~14~13 minecraft:emerald_block
fill ~64~15~13 ~64~16~13 minecraft:stone 0
setblock ~64~17~13 minecraft:cobblestone
fill ~64~18~13 ~64~18~14 minecraft:stone 0
fill ~64~20~13 ~64~20~14 minecraft:wooden_slab 0
fill ~65~8~13 ~65~9~99 minecraft:air
fill ~65~14~13 ~65~16~13 minecraft:obsidian
setblock ~65~17~13 minecraft:snow
setblock ~65~18~13 minecraft:cobblestone
fill ~66~16~13 ~66~16~14 minecraft:air
setblock ~66~17~13 minecraft:air
fill ~66~19~13 ~66~19~14 minecraft:emerald_block
fill ~67~19~13 ~67~19~14 minecraft:snow
fill ~68~13~13 ~68~14~14 minecraft:air
setblock ~68~16~13 minecraft:stone 0
fill ~68~17~13 ~69~17~13 minecraft:obsidian
fill ~68~18~13 ~68~19~13 minecraft:cobblestone
fill ~68~26~13 ~71~26~28 minecraft:air
setblock ~68~27~13 minecraft:glowstone
fill ~68~31~13 ~71~35~46 minecraft:air
setblock ~69~13~13 minecraft:stone 0
setblock ~69~14~13 minecraft:cobblestone
setblock ~69~15~13 minecraft:stone 0
setblock ~69~16~13 minecraft:obsidian
fill ~69~18~13 ~69~18~14 minecraft:stone 0
setblock ~69~19~13 minecraft:emerald_block
fill ~69~22~13 ~71~24~14 minecraft:air
fill ~69~27~13 ~71~29~31 minecraft:air
fill ~70~13~13 ~99~13~14 minecraft:air
fill ~70~14~13 ~99~15~13 minecraft:air
fill ~71~17~13 ~71~20~13 minecraft:air
fill ~71~21~13 ~71~21~16 minecraft:planks 0
fill ~72~17~13 ~72~18~13 minecraft:stone 0
setblock ~72~19~13 minecraft:cobblestone
setblock ~72~20~13 minecraft:stone 0
fill ~72~21~13 ~72~22~13 minecraft:stained_hardened_clay 15
fill ~72~23~13 ~72~31~13 minecraft:fence 4
fill ~72~32~13 ~99~35~18 minecraft:air
fill ~73~17~13 ~99~31~13 minecraft:air
fill ~0~5~14 ~43~6~35 minecraft:air
fill ~0~7~14 ~43~7~24 minecraft:air
fill ~0~8~14 ~43~8~16 minecraft:air
fill ~0~9~14 ~42~10~16 minecraft:air
fill ~0~11~14 ~24~11~20 minecraft:air
fill ~0~16~14 ~22~16~15 minecraft:air
fill ~0~19~14 ~18~22~14 minecraft:air
fill ~0~23~14 ~16~69~14 minecraft:air
fill ~17~23~14 ~18~23~14 minecraft:stained_hardened_clay 15
fill ~17~24~14 ~17~51~47 minecraft:air
fill ~17~52~14 ~18~69~38 minecraft:air
setblock ~18~24~14 minecraft:stained_hardened_clay 15
fill ~18~25~14 ~18~51~46 minecraft:air
fill ~19~19~14 ~19~20~14 minecraft:obsidian
setblock ~19~21~14 minecraft:emerald_block
fill ~19~22~14 ~19~22~15 minecraft:obsidian
fill ~19~23~14 ~20~23~17 minecraft:planks 0
fill ~19~24~14 ~20~24~45 minecraft:air
setblock ~20~19~14 minecraft:air
fill ~20~20~14 ~20~20~15 minecraft:emerald_block
setblock ~20~21~14 minecraft:obsidian
fill ~20~22~14 ~20~22~15 minecraft:stone 0
setblock ~21~18~14 minecraft:obsidian
fill ~21~19~14 ~21~19~15 minecraft:emerald_block
fill ~21~20~14 ~21~20~16 minecraft:obsidian
setblock ~21~21~14 minecraft:emerald_block
setblock ~21~22~14 minecraft:cobblestone
fill ~22~17~14 ~22~17~15 minecraft:air
setblock ~22~18~14 minecraft:air
fill ~22~19~14 ~23~19~14 minecraft:obsidian
setblock ~22~20~14 minecraft:emerald_block
fill ~22~21~14 ~23~21~20 minecraft:stone 0
fill ~22~23~14 ~23~23~20 minecraft:planks 0
fill ~22~24~14 ~23~24~14 minecraft:wooden_slab 0
setblock ~22~31~14 minecraft:air
fill ~22~32~14 ~22~32~15 minecraft:fence 4
fill ~22~33~14 ~22~33~99 minecraft:air
setblock ~23~16~14 minecraft:emerald_block
fill ~23~17~14 ~23~18~15 minecraft:obsidian
setblock ~23~20~14 minecraft:obsidian
setblock ~23~22~14 minecraft:stone 0
fill ~24~16~14 ~24~16~17 minecraft:air
fill ~24~17~14 ~24~18~16 minecraft:air
setblock ~24~19~14 minecraft:air
fill ~24~20~14 ~24~21~14 minecraft:emerald_block
fill ~24~22~14 ~24~22~16 minecraft:obsidian
setblock ~25~11~14 minecraft:snow
fill ~25~15~14 ~25~16~15 minecraft:obsidian
setblock ~25~18~14 minecraft:cobblestone
fill ~25~19~14 ~26~20~14 minecraft:stone 0
setblock ~25~21~14 minecraft:cobblestone
fill ~25~22~14 ~26~22~15 minecraft:stone 0
setblock ~25~23~14 minecraft:obsidian
fill ~26~11~14 ~42~11~16 minecraft:air
setblock ~26~12~14 minecraft:obsidian
setblock ~26~13~14 minecraft:emerald_block
fill ~26~14~14 ~26~14~15 minecraft:obsidian
setblock ~26~15~14 minecraft:snow
setblock ~26~16~14 minecraft:obsidian
fill ~26~17~14 ~26~18~14 minecraft:stone 0
fill ~26~21~14 ~26~21~15 minecraft:stone 0
fill ~26~23~14 ~26~23~16 minecraft:stone 0
setblock ~26~24~14 minecraft:obsidian
fill ~27~12~14 ~42~14~73 minecraft:air
fill ~27~15~14 ~42~15~18 minecraft:air
fill ~27~19~14 ~27~19~75 minecraft:air
fill ~27~20~14 ~27~20~15 minecraft:air
fill ~27~21~14 ~27~23~14 minecraft:obsidian
fill ~27~24~14 ~27~24~15 minecraft:snow
setblock ~28~19~14 minecraft:snow
setblock ~28~21~14 minecraft:stone 0
setblock ~28~22~14 minecraft:snow
fill ~29~17~14 ~29~17~76 minecraft:air
setblock ~29~18~14 minecraft:obsidian
setblock ~29~19~14 minecraft:stone 0
fill ~29~20~14 ~29~21~14 minecraft:obsidian
setblock ~29~24~14 minecraft:emerald_block
fill ~30~23~14 ~31~23~16 minecraft:air
setblock ~30~24~14 minecraft:snow
setblock ~30~33~14 minecraft:glowstone
fill ~30~35~14 ~37~51~37 minecraft:air
fill ~31~22~14 ~31~22~15 minecraft:air
fill ~31~33~14 ~37~34~39 minecraft:air
setblock ~32~20~14 minecraft:emerald_block
fill ~32~22~14 ~32~22~16 minecraft:stone 0
fill ~32~23~14 ~33~23~14 minecraft:stone 0
setblock ~32~25~14 minecraft:cobblestone
setblock ~33~20~14 minecraft:snow
setblock ~33~22~14 minecraft:obsidian
setblock ~33~25~14 minecraft:stone 0
setblock ~34~23~14 minecraft:air
fill ~34~24~14 ~34~24~16 minecraft:obsidian
fill ~34~29~14 ~37~32~20 minecraft:air
fill ~35~20~14 ~35~20~15 minecraft:air
setblock ~35~21~14 minecraft:snow
setblock ~35~22~14 minecraft:emerald_block
fill ~35~23~14 ~37~23~14 minecraft:obsidian
fill ~35~24~14 ~37~24~14 minecraft:snow
fill ~35~26~14 ~35~26~17 minecraft:stone 0
fill ~36~25~14 ~37~25~15 minecraft:stone 0
setblock ~36~26~14 minecraft:cobblestone
fill ~36~27~14 ~37~27~19 minecraft:planks 0
fill ~36~28~14 ~36~28~18 minecraft:air
fill ~37~26~14 ~37~26~15 minecraft:stone 0
fill ~37~28~14 ~37~28~16 minecraft:wooden_slab 0
fill ~38~23~14 ~42~27~14 minecraft:air
fill ~38~28~14 ~38~29~14 minecraft:stained_hardened_clay 15
fill ~38~30~14 ~38~38~14 minecraft:fence 4
fill ~38~39~14 ~43~51~36 minecraft:air
fill ~39~28~14 ~43~28~14 minecraft:air
setblock ~39~29~14 minecraft:stained_hardened_clay 15
fill ~39~30~14 ~44~35~18 minecraft:air
fill ~39~36~14 ~43~38~19 minecraft:air
fill ~40~29~14 ~43~29~14 minecraft:air
fill ~42~52~14 ~42~52~72 minecraft:air
fill ~43~9~14 ~43~12~14 minecraft:obsidian
fill ~43~13~14 ~43~14~14 minecraft:stone 0
setblock ~43~15~14 minecraft:cobblestone
setblock ~43~16~14 minecraft:obsidian
fill ~43~52~14 ~43~52~15 minecraft:nether_brick_stairs 0
fill ~44~5~14 ~44~6~14 minecraft:obsidian
setblock ~44~7~14 minecraft:snow
setblock ~44~8~14 minecraft:obsidian
setblock ~44~11~14 minecraft:cobblestone
setblock ~44~12~14 minecraft:stone 0
fill ~44~20~14 ~44~22~24 minecraft:air
fill ~44~23~14 ~44~25~18 minecraft:air
fill ~44~40~14 ~44~40~61 minecraft:air
fill ~44~41~14 ~44~45~36 minecraft:air
setblock ~44~49~14 minecraft:torch 5
fill ~45~5~14 ~46~5~99 minecraft:air
fill ~45~6~14 ~46~7~75 minecraft:air
fill ~45~8~14 ~45~8~75 minecraft:air
fill ~45~9~14 ~46~9~14 minecraft:obsidian
fill ~45~10~14 ~46~10~14 minecraft:snow
setblock ~45~11~14 minecraft:obsidian
setblock ~45~12~14 minecraft:emerald_block
setblock ~45~13~14 minecraft:obsidian
fill ~45~16~14 ~46~16~14 minecraft:stone 0
fill ~45~18~14 ~45~19~14 minecraft:stained_hardened_clay 15
setblock ~45~20~14 minecraft:emerald_block
setblock ~45~23~14 minecraft:snow
setblock ~45~24~14 minecraft:stained_hardened_clay 15
setblock ~45~25~14 minecraft:stained_hardened_clay 13
fill ~45~27~14 ~45~29~14 minecraft:stained_hardened_clay 15
setblock ~45~31~14 minecraft:emerald_block
setblock ~45~32~14 minecraft:snow
setblock ~45~33~14 minecraft:stained_hardened_clay 15
setblock ~45~35~14 minecraft:stained_hardened_clay 13
setblock ~45~36~14 minecraft:stained_hardened_clay 15
setblock ~45~37~14 minecraft:stained_hardened_clay 13
setblock ~45~39~14 minecraft:stained_hardened_clay 13
fill ~45~40~14 ~45~41~14 minecraft:stained_hardened_clay 15
setblock ~45~42~14 minecraft:snow
setblock ~45~43~14 minecraft:stained_hardened_clay 15
setblock ~45~46~14 minecraft:stained_hardened_clay 15
fill ~45~48~14 ~45~50~14 minecraft:red_sandstone 1
fill ~45~52~14 ~45~52~15 minecraft:planks 4
fill ~45~53~14 ~45~53~78 minecraft:air
fill ~46~11~14 ~46~12~14 minecraft:stone 0
fill ~46~21~14 ~47~21~14 minecraft:wooden_slab 4
setblock ~46~29~14 minecraft:torch 4
setblock ~46~36~14 minecraft:torch 4
fill ~46~37~14 ~46~38~14 minecraft:air
fill ~46~39~14 ~47~39~14 minecraft:wooden_slab 12
fill ~46~40~14 ~47~40~14 minecraft:air
setblock ~46~42~14 minecraft:torch 4
fill ~46~43~14 ~46~44~14 minecraft:air
fill ~46~46~14 ~49~46~14 minecraft:fence 4
setblock ~46~53~14 minecraft:planks 4
fill ~46~54~14 ~46~54~99 minecraft:air
setblock ~47~8~14 minecraft:stone 0
setblock ~47~11~14 minecraft:cobblestone
fill ~47~14~14 ~48~14~14 minecraft:cobblestone
setblock ~47~15~14 minecraft:cobblestone
setblock ~47~16~14 minecraft:obsidian
fill ~47~18~14 ~49~18~15 minecraft:air
fill ~47~19~14 ~48~19~15 minecraft:air
fill ~47~20~14 ~48~20~14 minecraft:air
fill ~47~22~14 ~51~22~15 minecraft:air
setblock ~47~28~14 minecraft:wooden_slab 4
fill ~47~29~14 ~47~29~15 minecraft:air
fill ~47~34~14 ~47~34~15 minecraft:wooden_slab 4
fill ~47~35~14 ~47~35~15 minecraft:air
fill ~47~41~14 ~47~41~15 minecraft:air
fill ~47~45~14 ~48~45~14 minecraft:air
setblock ~47~54~14 minecraft:planks 4
fill ~47~55~14 ~47~55~99 minecraft:air
fill ~48~8~14 ~49~8~99 minecraft:air
setblock ~48~11~14 minecraft:stone 0
setblock ~48~12~14 minecraft:obsidian
fill ~48~15~14 ~49~15~15 minecraft:stone 0
fill ~48~16~14 ~48~16~18 minecraft:stone 0
setblock ~48~27~14 minecraft:air
fill ~48~28~14 ~49~28~14 minecraft:fence 4
setblock ~48~39~14 minecraft:air
fill ~48~40~14 ~49~40~14 minecraft:fence 4
fill ~48~55~14 ~50~55~14 minecraft:planks 4
fill ~48~56~14 ~48~56~99 minecraft:air
fill ~49~9~14 ~49~10~99 minecraft:air
fill ~49~11~14 ~49~11~16 minecraft:air
fill ~49~12~14 ~49~12~15 minecraft:air
fill ~49~19~14 ~50~20~14 minecraft:fence 4
setblock ~49~21~14 minecraft:fence 4
fill ~49~27~14 ~50~27~14 minecraft:fence 4
fill ~49~35~14 ~50~35~14 minecraft:fence 4
fill ~49~39~14 ~50~39~14 minecraft:fence 4
fill ~49~45~14 ~50~45~14 minecraft:fence 4
setblock ~49~56~14 minecraft:planks 4
fill ~49~57~14 ~49~59~99 minecraft:air
setblock ~50~15~14 minecraft:cobblestone
fill ~50~16~14 ~51~16~14 minecraft:stone 0
setblock ~50~18~14 minecraft:fence 4
fill ~50~21~14 ~51~21~15 minecraft:air
fill ~50~28~14 ~52~28~14 minecraft:air
setblock ~50~34~14 minecraft:fence 4
fill ~50~56~14 ~50~56~99 minecraft:air
fill ~51~12~14 ~51~12~17 minecraft:air
setblock ~51~13~14 minecraft:emerald_block
fill ~51~14~14 ~52~14~14 minecraft:cobblestone
fill ~51~15~14 ~52~15~14 minecraft:stone 0
fill ~51~18~14 ~51~20~15 minecraft:air
fill ~51~26~14 ~52~26~14 minecraft:wooden_slab 4
fill ~51~27~14 ~51~27~15 minecraft:air
fill ~51~33~14 ~51~33~15 minecraft:wooden_slab 4
fill ~51~34~14 ~51~35~15 minecraft:air
fill ~51~38~14 ~52~38~14 minecraft:wooden_slab 4
fill ~51~39~14 ~52~39~14 minecraft:air
fill ~51~44~14 ~52~44~14 minecraft:wooden_slab 4
fill ~51~45~14 ~51~45~15 minecraft:air
setblock ~51~54~14 minecraft:planks 4
fill ~51~55~14 ~51~55~99 minecraft:air
fill ~52~9~14 ~52~11~14 minecraft:stone 0
setblock ~52~12~14 minecraft:cobblestone
fill ~52~13~14 ~52~13~15 minecraft:stone 0
setblock ~52~16~14 minecraft:emerald_block
setblock ~52~25~14 minecraft:air
setblock ~52~32~14 minecraft:wooden_slab 12
setblock ~52~37~14 minecraft:air
setblock ~52~43~14 minecraft:air
setblock ~52~53~14 minecraft:planks 4
fill ~52~54~14 ~52~54~99 minecraft:air
fill ~53~12~14 ~53~12~99 minecraft:air
setblock ~53~13~14 minecraft:cobblestone
setblock ~53~14~14 minecraft:stone 0
setblock ~53~15~14 minecraft:snow
setblock ~53~16~14 minecraft:obsidian
setblock ~53~18~14 minecraft:stained_hardened_clay 15
setblock ~53~19~14 minecraft:stained_hardened_clay 13
setblock ~53~20~14 minecraft:snow
fill ~53~22~14 ~53~23~14 minecraft:stained_hardened_clay 13
setblock ~53~24~14 minecraft:stained_hardened_clay 15
setblock ~53~26~14 minecraft:emerald_block
fill ~53~31~14 ~53~32~14 minecraft:stained_hardened_clay 13
setblock ~53~34~14 minecraft:snow
fill ~53~35~14 ~53~36~14 minecraft:emerald_block
setblock ~53~39~14 minecraft:emerald_block
setblock ~53~41~14 minecraft:stained_hardened_clay 15
setblock ~53~44~14 minecraft:stained_hardened_clay 15
setblock ~53~45~14 minecraft:emerald_block
fill ~53~46~14 ~53~47~14 minecraft:stained_hardened_clay 13
fill ~53~48~14 ~53~50~14 minecraft:red_sandstone 1
fill ~53~52~14 ~53~52~15 minecraft:planks 4
fill ~53~53~14 ~53~53~99 minecraft:air
fill ~54~16~14 ~55~16~14 minecraft:stone 0
fill ~54~18~14 ~54~18~15 minecraft:red_sandstone_stairs 1
fill ~54~19~14 ~54~19~15 minecraft:nether_brick_stairs 5
fill ~54~20~14 ~62~21~44 minecraft:air
fill ~54~22~14 ~68~24~17 minecraft:air
fill ~54~25~14 ~54~25~46 minecraft:air
fill ~54~30~14 ~54~35~40 minecraft:air
fill ~54~40~14 ~54~45~41 minecraft:air
setblock ~54~49~14 minecraft:torch 5
fill ~55~11~14 ~55~12~99 minecraft:air
setblock ~55~13~14 minecraft:obsidian
fill ~55~14~14 ~56~14~14 minecraft:cobblestone
setblock ~55~15~14 minecraft:obsidian
fill ~56~10~14 ~56~11~14 minecraft:emerald_block
fill ~56~12~14 ~57~12~14 minecraft:stone 0
setblock ~56~13~14 minecraft:stone 0
setblock ~56~15~14 minecraft:cobblestone
setblock ~56~16~14 minecraft:obsidian
fill ~56~52~14 ~56~52~99 minecraft:air
fill ~57~7~14 ~57~8~99 minecraft:air
fill ~57~9~14 ~57~10~14 minecraft:stone 0
setblock ~57~11~14 minecraft:emerald_block
setblock ~57~13~14 minecraft:snow
fill ~57~14~14 ~57~14~15 minecraft:stone 0
setblock ~57~15~14 minecraft:stone 0
fill ~58~15~14 ~58~15~15 minecraft:air
setblock ~58~17~14 minecraft:obsidian
fill ~59~16~14 ~59~16~99 minecraft:air
setblock ~59~17~14 minecraft:emerald_block
fill ~60~13~14 ~61~13~14 minecraft:stone 0
setblock ~60~15~14 minecraft:cobblestone
fill ~60~16~14 ~60~16~15 minecraft:stone 0
setblock ~61~10~14 minecraft:stone 0
setblock ~61~11~14 minecraft:obsidian
setblock ~61~14~14 minecraft:stone 0
setblock ~61~15~14 minecraft:snow
fill ~63~10~14 ~63~11~99 minecraft:air
fill ~63~12~14 ~63~13~14 minecraft:obsidian
setblock ~63~14~14 minecraft:dirt 0
fill ~63~15~14 ~63~16~15 minecraft:stone 0
fill ~63~18~14 ~63~18~15 minecraft:stone 0
fill ~63~20~14 ~63~20~16 minecraft:wooden_slab 0
fill ~63~21~14 ~67~21~14 minecraft:air
fill ~64~13~14 ~65~13~73 minecraft:air
setblock ~64~14~14 minecraft:obsidian
setblock ~64~15~14 minecraft:emerald_block
setblock ~64~16~14 minecraft:snow
setblock ~64~17~14 minecraft:dirt 0
fill ~64~19~14 ~64~19~15 minecraft:planks 0
fill ~65~14~14 ~65~15~78 minecraft:air
fill ~65~16~14 ~65~16~15 minecraft:air
setblock ~65~17~14 minecraft:obsidian
setblock ~65~18~14 minecraft:snow
fill ~65~19~14 ~65~19~15 minecraft:obsidian
fill ~65~20~14 ~65~20~17 minecraft:planks 0
setblock ~66~17~14 minecraft:snow
fill ~66~18~14 ~66~18~15 minecraft:obsidian
setblock ~67~17~14 minecraft:obsidian
fill ~68~15~14 ~68~16~14 minecraft:obsidian
fill ~68~17~14 ~69~17~14 minecraft:stone 0
setblock ~68~18~14 minecraft:snow
setblock ~68~19~14 minecraft:cobblestone
fill ~68~21~14 ~68~21~15 minecraft:wooden_slab 0
fill ~68~27~14 ~68~28~37 minecraft:air
fill ~69~13~14 ~69~15~16 minecraft:air
setblock ~69~16~14 minecraft:stone 0
setblock ~69~19~14 minecraft:stone 0
fill ~70~14~14 ~71~14~16 minecraft:air
fill ~70~15~14 ~71~16~15 minecraft:air
fill ~71~17~14 ~71~20~14 minecraft:stone 0
fill ~72~14~14 ~72~14~15 minecraft:obsidian
setblock ~72~15~14 minecraft:cobblestone
setblock ~72~16~14 minecraft:stone 0
setblock ~72~17~14 minecraft:snow
setblock ~72~18~14 minecraft:cobblestone
fill ~72~19~14 ~73~19~14 minecraft:stone 0
setblock ~72~20~14 minecraft:snow
fill ~72~21~14 ~72~21~15 minecraft:planks 0
fill ~72~22~14 ~72~22~15 minecraft:wooden_slab 0
fill ~72~23~14 ~99~27~16 minecraft:air
fill ~72~28~14 ~72~30~14 minecraft:fence 4
fill ~72~31~14 ~99~31~18 minecraft:air
fill ~73~14~14 ~99~14~14 minecraft:air
setblock ~73~15~14 minecraft:emerald_block
fill ~73~16~14 ~73~16~15 minecraft:snow
fill ~73~17~14 ~73~17~15 minecraft:obsidian
setblock ~73~18~14 minecraft:stone 0
fill ~73~20~14 ~73~21~14 minecraft:cobblestone
setblock ~73~22~14 minecraft:stained_hardened_clay 15
fill ~73~28~14 ~99~30~18 minecraft:air
fill ~74~15~14 ~99~22~14 minecraft:air
fill ~0~18~15 ~16~22~15 minecraft:air
fill ~0~23~15 ~15~69~15 minecraft:air
setblock ~16~23~15 minecraft:stained_hardened_clay 15
fill ~16~24~15 ~16~32~15 minecraft:fence 4
fill ~16~33~15 ~16~35~40 minecraft:air
fill ~16~36~15 ~16~51~38 minecraft:air
fill ~16~52~15 ~16~69~37 minecraft:air
fill ~17~18~15 ~17~18~16 minecraft:obsidian
fill ~17~19~15 ~17~21~15 minecraft:obsidian
fill ~17~22~15 ~17~22~21 minecraft:planks 0
fill ~17~23~15 ~17~23~16 minecraft:wooden_slab 0
fill ~18~18~15 ~21~18~15 minecraft:air
fill ~18~19~15 ~19~20~15 minecraft:air
fill ~18~21~15 ~19~21~15 minecraft:obsidian
setblock ~18~22~15 minecraft:obsidian
setblock ~18~23~15 minecraft:planks 0
fill ~18~24~15 ~18~24~46 minecraft:air
setblock ~20~19~15 minecraft:emerald_block
fill ~20~21~15 ~20~21~16 minecraft:stone 0
fill ~21~17~15 ~21~17~16 minecraft:air
fill ~21~21~15 ~21~21~16 minecraft:obsidian
fill ~21~22~15 ~22~22~15 minecraft:stone 0
fill ~21~24~15 ~22~24~20 minecraft:air
setblock ~22~18~15 minecraft:obsidian
fill ~22~19~15 ~22~20~18 minecraft:stone 0
setblock ~22~31~15 minecraft:glowstone
fill ~23~16~15 ~23~16~17 minecraft:air
setblock ~23~19~15 minecraft:snow
fill ~23~20~15 ~23~20~18 minecraft:stone 0
setblock ~23~22~15 minecraft:cobblestone
fill ~23~24~15 ~23~24~17 minecraft:wooden_slab 0
fill ~24~19~15 ~24~21~15 minecraft:obsidian
fill ~25~11~15 ~25~11~80 minecraft:air
fill ~25~12~15 ~26~12~15 minecraft:air
setblock ~25~13~15 minecraft:obsidian
setblock ~25~17~15 minecraft:emerald_block
setblock ~25~18~15 minecraft:stone 0
setblock ~25~19~15 minecraft:emerald_block
fill ~25~20~15 ~26~20~15 minecraft:stone 0
setblock ~25~21~15 minecraft:stone 0
setblock ~25~23~15 minecraft:snow
setblock ~26~13~15 minecraft:air
fill ~26~15~15 ~26~15~16 minecraft:obsidian
setblock ~26~16~15 minecraft:snow
fill ~26~17~15 ~26~18~15 minecraft:obsidian
fill ~26~19~15 ~26~19~16 minecraft:cobblestone
fill ~26~24~15 ~26~24~19 minecraft:planks 0
fill ~26~25~15 ~26~25~19 minecraft:wooden_slab 0
fill ~27~21~15 ~27~22~15 minecraft:emerald_block
setblock ~27~23~15 minecraft:snow
fill ~27~25~15 ~29~25~19 minecraft:planks 0
fill ~28~19~15 ~29~19~15 minecraft:air
setblock ~28~20~15 minecraft:air
setblock ~28~21~15 minecraft:obsidian
setblock ~28~22~15 minecraft:stone 0
fill ~28~24~15 ~29~24~15 minecraft:cobblestone
fill ~29~18~15 ~29~18~76 minecraft:air
setblock ~29~20~15 minecraft:emerald_block
setblock ~29~21~15 minecraft:stone 0
fill ~30~17~15 ~31~17~76 minecraft:air
setblock ~30~24~15 minecraft:emerald_block
setblock ~30~25~15 minecraft:snow
fill ~30~33~15 ~30~34~41 minecraft:air
fill ~31~25~15 ~32~25~15 minecraft:emerald_block
fill ~32~17~15 ~32~17~16 minecraft:obsidian
fill ~32~18~15 ~33~18~15 minecraft:obsidian
fill ~32~19~15 ~32~21~15 minecraft:stone 0
fill ~32~23~15 ~32~24~15 minecraft:stone 0
fill ~33~17~15 ~43~17~15 minecraft:air
fill ~33~19~15 ~33~19~19 minecraft:obsidian
fill ~33~20~15 ~33~20~17 minecraft:obsidian
setblock ~33~21~15 minecraft:emerald_block
setblock ~33~22~15 minecraft:stone 0
setblock ~33~23~15 minecraft:emerald_block
fill ~33~24~15 ~33~24~16 minecraft:obsidian
fill ~33~25~15 ~34~25~15 minecraft:obsidian
fill ~34~18~15 ~42~19~15 minecraft:air
setblock ~34~23~15 minecraft:snow
setblock ~34~26~15 minecraft:emerald_block
fill ~35~21~15 ~36~21~15 minecraft:obsidian
fill ~35~22~15 ~35~23~15 minecraft:obsidian
fill ~35~24~15 ~35~24~17 minecraft:snow
fill ~35~25~15 ~35~25~16 minecraft:stone 0
setblock ~36~22~15 minecraft:snow
setblock ~36~23~15 minecraft:obsidian
fill ~36~24~15 ~37~24~16 minecraft:stone 0
setblock ~36~26~15 minecraft:emerald_block
fill ~37~22~15 ~37~23~15 minecraft:emerald_block
fill ~38~26~15 ~38~27~15 minecraft:emerald_block
fill ~38~28~15 ~39~28~15 minecraft:planks 0
fill ~38~35~15 ~38~37~15 minecraft:fence 4
fill ~38~38~15 ~38~38~37 minecraft:air
fill ~39~23~15 ~39~24~15 minecraft:obsidian
setblock ~39~25~15 minecraft:emerald_block
setblock ~39~26~15 minecraft:dirt 0
setblock ~40~29~15 minecraft:stained_hardened_clay 15
fill ~44~9~15 ~45~9~15 minecraft:emerald_block
fill ~44~10~15 ~45~10~15 minecraft:obsidian
fill ~44~11~15 ~44~12~15 minecraft:obsidian
setblock ~44~14~15 minecraft:emerald_block
fill ~44~15~15 ~45~15~15 minecraft:cobblestone
setblock ~44~16~15 minecraft:snow
setblock ~44~18~15 minecraft:red_sandstone_stairs 3
setblock ~44~19~15 minecraft:nether_brick_stairs 7
setblock ~44~26~15 minecraft:nether_brick_stairs 3
setblock ~44~27~15 minecraft:red_sandstone_stairs 7
setblock ~44~28~15 minecraft:red_sandstone_stairs 3
setblock ~44~36~15 minecraft:nether_brick_stairs 3
setblock ~44~46~15 minecraft:nether_brick_stairs 3
fill ~44~48~15 ~44~49~75 minecraft:air
setblock ~44~52~15 minecraft:nether_brick_stairs 3
setblock ~45~11~15 minecraft:snow
fill ~45~12~15 ~45~12~16 minecraft:obsidian
fill ~45~13~15 ~45~14~15 minecraft:stone 0
setblock ~45~16~15 minecraft:cobblestone
setblock ~45~18~15 minecraft:red_sandstone_stairs 0
setblock ~45~19~15 minecraft:nether_brick_stairs 4
fill ~45~20~15 ~45~25~15 minecraft:nether_brick_fence
setblock ~45~26~15 minecraft:nether_brick_stairs 0
setblock ~45~27~15 minecraft:red_sandstone_stairs 4
setblock ~45~28~15 minecraft:red_sandstone_stairs 0
setblock ~45~29~15 minecraft:nether_brick_stairs 7
fill ~45~30~15 ~45~35~15 minecraft:nether_brick_fence
fill ~45~36~15 ~45~36~16 minecraft:nether_brick_stairs 0
setblock ~45~37~15 minecraft:red_sandstone_stairs 7
setblock ~45~38~15 minecraft:red_sandstone_stairs 3
setblock ~45~39~15 minecraft:nether_brick_stairs 7
fill ~45~40~15 ~45~45~15 minecraft:nether_brick_fence
fill ~45~46~15 ~45~46~16 minecraft:nether_brick_stairs 0
setblock ~45~47~15 minecraft:nether_brick_stairs 7
fill ~45~48~15 ~45~51~15 minecraft:nether_brick_fence
setblock ~46~8~15 minecraft:obsidian
setblock ~46~9~15 minecraft:snow
setblock ~46~10~15 minecraft:emerald_block
fill ~46~11~15 ~47~11~15 minecraft:obsidian
setblock ~46~12~15 minecraft:stone 0
setblock ~46~14~15 minecraft:snow
fill ~46~15~15 ~47~15~15 minecraft:stone 0
setblock ~46~16~15 minecraft:emerald_block
setblock ~46~18~15 minecraft:emerald_block
setblock ~46~19~15 minecraft:stained_hardened_clay 15
setblock ~46~20~15 minecraft:snow
setblock ~46~21~15 minecraft:stained_hardened_clay 15
setblock ~46~22~15 minecraft:stained_hardened_clay 13
fill ~46~23~15 ~46~24~15 minecraft:stained_hardened_clay 15
setblock ~46~25~15 minecraft:stained_hardened_clay 13
setblock ~46~26~15 minecraft:snow
setblock ~46~27~15 minecraft:emerald_block
fill ~46~28~15 ~46~34~15 minecraft:stained_hardened_clay 15
fill ~46~35~15 ~46~36~15 minecraft:stained_hardened_clay 13
setblock ~46~37~15 minecraft:emerald_block
fill ~46~38~15 ~46~39~15 minecraft:snow
fill ~46~40~15 ~46~41~15 minecraft:stained_hardened_clay 15
setblock ~46~42~15 minecraft:snow
setblock ~46~43~15 minecraft:emerald_block
setblock ~46~44~15 minecraft:stained_hardened_clay 13
setblock ~46~45~15 minecraft:stained_hardened_clay 15
setblock ~46~46~15 minecraft:stained_hardened_clay 13
setblock ~46~47~15 minecraft:stained_hardened_clay 15
fill ~46~48~15 ~46~51~15 minecraft:red_sandstone 1
fill ~46~52~15 ~46~52~16 minecraft:planks 4
fill ~47~12~15 ~47~12~16 minecraft:obsidian
setblock ~47~14~15 minecraft:cobblestone
setblock ~47~16~15 minecraft:cobblestone
setblock ~47~20~15 minecraft:wooden_slab 12
setblock ~47~27~15 minecraft:wooden_slab 12
fill ~47~39~15 ~48~39~15 minecraft:wooden_slab 4
fill ~47~40~15 ~50~40~15 minecraft:air
fill ~47~45~15 ~48~45~15 minecraft:wooden_slab 4
fill ~47~46~15 ~47~47~15 minecraft:ladder 2
setblock ~47~53~15 minecraft:planks 4
setblock ~48~12~15 minecraft:emerald_block
fill ~48~13~15 ~48~13~16 minecraft:obsidian
setblock ~48~14~15 minecraft:stone 0
setblock ~48~20~15 minecraft:wooden_slab 4
fill ~48~27~15 ~49~27~15 minecraft:wooden_slab 4
fill ~48~34~15 ~49~34~15 minecraft:wooden_slab 4
fill ~48~47~15 ~51~47~15 minecraft:wooden_slab 12
fill ~48~54~15 ~50~54~15 minecraft:planks 4
fill ~49~13~15 ~49~14~15 minecraft:emerald_block
fill ~49~16~15 ~50~16~15 minecraft:stone 0
setblock ~49~19~15 minecraft:red_sandstone_stairs 1
setblock ~49~38~15 minecraft:wooden_slab 12
fill ~49~39~15 ~51~39~15 minecraft:air
setblock ~49~44~15 minecraft:wooden_slab 12
fill ~49~45~15 ~50~45~15 minecraft:air
setblock ~49~52~15 minecraft:torch 4
fill ~49~56~15 ~49~56~99 minecraft:air
setblock ~50~12~15 minecraft:obsidian
setblock ~50~13~15 minecraft:stone 0
fill ~50~15~15 ~50~15~16 minecraft:stone 0
setblock ~50~18~15 minecraft:red_sandstone_stairs 1
setblock ~50~19~15 minecraft:air
setblock ~50~26~15 minecraft:wooden_slab 12
setblock ~50~27~15 minecraft:air
setblock ~50~33~15 minecraft:wooden_slab 12
setblock ~50~34~15 minecraft:air
fill ~50~38~15 ~51~38~15 minecraft:wooden_slab 4
fill ~50~44~15 ~51~44~15 minecraft:wooden_slab 4
fill ~51~13~15 ~51~14~15 minecraft:air
fill ~51~15~15 ~51~15~16 minecraft:cobblestone
fill ~51~16~15 ~51~16~16 minecraft:obsidian
setblock ~51~24~15 minecraft:air
setblock ~51~26~15 minecraft:wooden_slab 4
setblock ~51~28~15 minecraft:torch 2
setblock ~51~40~15 minecraft:torch 2
setblock ~51~42~15 minecraft:air
setblock ~51~46~15 minecraft:torch 2
setblock ~51~53~15 minecraft:planks 4
fill ~51~54~15 ~51~54~99 minecraft:air
fill ~52~9~15 ~52~11~99 minecraft:air
setblock ~52~12~15 minecraft:air
setblock ~52~14~15 minecraft:cobblestone
setblock ~52~15~15 minecraft:obsidian
setblock ~52~16~15 minecraft:stone 0
fill ~52~18~15 ~52~20~15 minecraft:stained_hardened_clay 13
fill ~52~21~15 ~52~22~15 minecraft:stained_hardened_clay 15
fill ~52~23~15 ~52~24~15 minecraft:stained_hardened_clay 13
fill ~52~25~15 ~52~27~15 minecraft:stained_hardened_clay 15
setblock ~52~28~15 minecraft:stained_hardened_clay 13
setblock ~52~29~15 minecraft:emerald_block
setblock ~52~30~15 minecraft:stained_hardened_clay 15
setblock ~52~31~15 minecraft:stained_hardened_clay 13
setblock ~52~32~15 minecraft:emerald_block
fill ~52~33~15 ~52~34~15 minecraft:stained_hardened_clay 15
fill ~52~35~15 ~52~36~15 minecraft:stained_hardened_clay 13
setblock ~52~37~15 minecraft:stained_hardened_clay 15
setblock ~52~38~15 minecraft:snow
setblock ~52~39~15 minecraft:emerald_block
setblock ~52~40~15 minecraft:snow
fill ~52~41~15 ~52~42~15 minecraft:stained_hardened_clay 15
setblock ~52~43~15 minecraft:emerald_block
setblock ~52~44~15 minecraft:stained_hardened_clay 15
fill ~52~45~15 ~52~46~15 minecraft:stained_hardened_clay 13
setblock ~52~47~15 minecraft:emerald_block
fill ~52~48~15 ~52~51~15 minecraft:red_sandstone 1
fill ~52~52~15 ~52~52~16 minecraft:planks 4
fill ~52~53~15 ~52~53~99 minecraft:air
setblock ~53~13~15 minecraft:air
fill ~53~14~15 ~53~14~16 minecraft:obsidian
fill ~53~15~15 ~56~15~15 minecraft:stone 0
fill ~53~16~15 ~53~16~16 minecraft:cobblestone
setblock ~53~18~15 minecraft:red_sandstone_stairs 3
setblock ~53~19~15 minecraft:nether_brick_stairs 7
fill ~53~20~15 ~53~25~15 minecraft:nether_brick_fence
setblock ~53~26~15 minecraft:nether_brick_stairs 3
setblock ~53~27~15 minecraft:red_sandstone_stairs 7
setblock ~53~28~15 minecraft:red_sandstone_stairs 3
setblock ~53~29~15 minecraft:nether_brick_stairs 5
fill ~53~30~15 ~53~35~15 minecraft:nether_brick_fence
setblock ~53~36~15 minecraft:nether_brick_stairs 1
setblock ~53~37~15 minecraft:red_sandstone_stairs 5
setblock ~53~38~15 minecraft:red_sandstone_stairs 1
setblock ~53~39~15 minecraft:nether_brick_stairs 5
fill ~53~40~15 ~53~45~15 minecraft:nether_brick_fence
setblock ~53~46~15 minecraft:nether_brick_stairs 1
setblock ~53~47~15 minecraft:nether_brick_stairs 5
fill ~53~48~15 ~53~51~15 minecraft:nether_brick_fence
setblock ~54~16~15 minecraft:obsidian
setblock ~54~29~15 minecraft:nether_brick_stairs 7
setblock ~54~36~15 minecraft:nether_brick_stairs 3
setblock ~54~37~15 minecraft:red_sandstone_stairs 7
setblock ~54~38~15 minecraft:red_sandstone_stairs 3
setblock ~54~39~15 minecraft:nether_brick_stairs 7
setblock ~54~46~15 minecraft:nether_brick_stairs 3
setblock ~54~47~15 minecraft:nether_brick_stairs 7
fill ~54~48~15 ~54~49~99 minecraft:air
setblock ~54~52~15 minecraft:nether_brick_stairs 1
fill ~55~16~15 ~57~16~15 minecraft:stone 0
setblock ~55~17~15 minecraft:planks 0
setblock ~55~52~15 minecraft:nether_brick_stairs 3
fill ~56~10~15 ~57~12~99 minecraft:air
setblock ~56~14~15 minecraft:stone 0
fill ~57~9~15 ~57~9~99 minecraft:air
setblock ~57~13~15 minecraft:stone 0
setblock ~57~15~15 minecraft:obsidian
setblock ~60~17~15 minecraft:obsidian
fill ~61~10~15 ~61~12~99 minecraft:air
fill ~61~14~15 ~61~15~15 minecraft:obsidian
setblock ~61~17~15 minecraft:stone 0
setblock ~64~15~15 minecraft:snow
setblock ~64~16~15 minecraft:emerald_block
setblock ~64~17~15 minecraft:stone 0
setblock ~64~18~15 minecraft:cobblestone
setblock ~64~20~15 minecraft:double_wooden_slab 0
setblock ~65~17~15 minecraft:air
setblock ~65~18~15 minecraft:emerald_block
setblock ~66~11~15 minecraft:air
setblock ~66~16~15 minecraft:snow
fill ~66~17~15 ~67~17~15 minecraft:emerald_block
fill ~66~19~15 ~67~19~15 minecraft:obsidian
setblock ~67~11~15 minecraft:obsidian
setblock ~67~12~15 minecraft:snow
fill ~67~13~15 ~68~13~15 minecraft:obsidian
fill ~67~14~15 ~67~14~16 minecraft:emerald_block
fill ~67~15~15 ~68~15~15 minecraft:stone 0
fill ~67~16~15 ~67~16~16 minecraft:stone 0
setblock ~67~18~15 minecraft:cobblestone
fill ~67~21~15 ~67~21~16 minecraft:wooden_slab 0
setblock ~68~12~15 minecraft:obsidian
setblock ~68~14~15 minecraft:snow
setblock ~68~16~15 minecraft:cobblestone
fill ~68~17~15 ~68~19~15 minecraft:stone 0
setblock ~69~19~15 minecraft:obsidian
fill ~69~20~15 ~70~20~15 minecraft:emerald_block
fill ~69~21~15 ~69~21~18 minecraft:planks 0
setblock ~70~19~15 minecraft:snow
setblock ~71~17~15 minecraft:air
setblock ~71~18~15 minecraft:cobblestone
fill ~71~19~15 ~71~19~16 minecraft:stone 0
setblock ~71~20~15 minecraft:cobblestone
fill ~71~22~15 ~71~22~16 minecraft:wooden_slab 0
fill ~72~15~15 ~73~15~15 minecraft:snow
fill ~72~16~15 ~72~17~15 minecraft:obsidian
setblock ~72~18~15 minecraft:stone 0
setblock ~72~19~15 minecraft:cobblestone
