fill ~20~50~1 ~20~52~2 minecraft:concrete 7
fill ~24~50~1 ~24~51~2 minecraft:concrete 7
fill ~19~50~2 ~19~52~2 minecraft:quartz_block 1
fill ~20~48~2 ~20~49~3 minecraft:concrete 7
fill ~20~53~2 ~20~54~3 minecraft:concrete 7
fill ~21~50~2 ~21~52~2 minecraft:quartz_block 1
fill ~22~50~2 ~22~52~2 minecraft:stained_glass 3
fill ~23~50~2 ~23~52~2 minecraft:quartz_block 1
fill ~24~48~2 ~24~49~3 minecraft:concrete 7
setblock ~24~52~2 minecraft:concrete 7
fill ~18~47~3 ~25~47~3 minecraft:concrete 7
fill ~18~50~3 ~18~52~3 minecraft:stained_glass 3
fill ~19~48~3 ~19~49~3 minecraft:quartz_block 1
fill ~19~53~3 ~19~54~3 minecraft:quartz_block 1
fill ~20~56~3 ~25~56~3 minecraft:stone_block_slab 0
fill ~21~48~3 ~23~48~3 minecraft:quartz_block 1
setblock ~21~49~3 minecraft:quartz_block 1
fill ~21~53~3 ~21~54~3 minecraft:quartz_block 1
setblock ~22~49~3 minecraft:stained_glass 3
setblock ~22~53~3 minecraft:stained_glass 3
fill ~22~54~3 ~23~54~3 minecraft:quartz_block 1
setblock ~23~49~3 minecraft:quartz_block 1
setblock ~23~53~3 minecraft:quartz_block 1
fill ~24~50~3 ~25~51~4 minecraft:quartz_block 1
fill ~24~52~3 ~24~52~4 minecraft:quartz_block 1
fill ~24~53~3 ~24~54~3 minecraft:concrete 7
setblock ~25~52~3 minecraft:stained_glass 3
fill ~16~48~4 ~16~54~5 minecraft:concrete 7
setblock ~17~47~4 minecraft:concrete 7
fill ~17~49~4 ~18~49~4 minecraft:quartz_block 1
fill ~17~50~4 ~17~52~4 minecraft:quartz_block 1
fill ~17~56~4 ~19~56~4 minecraft:stone_block_slab 0
fill ~18~47~4 ~25~47~4 minecraft:quartz_block 1
setblock ~18~48~4 minecraft:quartz_block 1
setblock ~18~53~4 minecraft:stained_glass 3
setblock ~18~54~4 minecraft:quartz_block 1
setblock ~19~55~4 minecraft:concrete 7
fill ~20~45~4 ~26~45~4 minecraft:stone_block_slab 8
fill ~20~46~4 ~26~46~4 minecraft:wool 7
fill ~20~55~4 ~25~55~4 minecraft:wool 7
fill ~20~56~4 ~25~56~4 minecraft:concrete 7
fill ~20~57~4 ~25~57~4 minecraft:anvil 3
fill ~20~58~4 ~25~58~4 minecraft:stone_block_slab 0
fill ~24~48~4 ~25~49~4 minecraft:quartz_block 1
fill ~24~53~4 ~24~54~4 minecraft:quartz_block 1
fill ~25~52~4 ~26~52~5 minecraft:quartz_block 1
setblock ~25~53~4 minecraft:stained_glass 3
fill ~25~54~4 ~25~54~5 minecraft:quartz_block 1
setblock ~26~47~4 minecraft:concrete 7
fill ~26~49~4 ~26~49~6 minecraft:quartz_block 1
fill ~26~50~4 ~26~51~4 minecraft:stained_glass 3
setblock ~26~55~4 minecraft:concrete 7
fill ~26~56~4 ~29~56~4 minecraft:stone_block_slab 0
fill ~27~52~4 ~28~52~4 minecraft:concrete 7
fill ~27~53~4 ~27~54~5 minecraft:concrete 7
fill ~28~51~4 ~28~51~5 minecraft:concrete 7
fill ~15~49~5 ~15~52~5 minecraft:concrete 7
setblock ~16~47~5 minecraft:concrete 7
setblock ~16~55~5 minecraft:concrete 7
setblock ~16~56~5 minecraft:stone_block_slab 0
fill ~17~47~5 ~17~49~5 minecraft:quartz_block 1
fill ~17~53~5 ~17~54~5 minecraft:quartz_block 1
fill ~17~55~5 ~20~55~5 minecraft:wool 7
fill ~17~56~5 ~19~56~5 minecraft:concrete 7
fill ~17~57~5 ~19~57~5 minecraft:anvil 3
fill ~17~58~5 ~19~58~5 minecraft:stone_block_slab 0
fill ~18~45~5 ~20~45~5 minecraft:stone_block_slab 8
fill ~18~46~5 ~20~46~5 minecraft:wool 7
fill ~18~47~5 ~25~47~26 minecraft:concrete 0
fill ~20~56~5 ~25~56~26 minecraft:concrete 0
fill ~21~44~5 ~26~44~5 minecraft:concrete 4
fill ~21~45~5 ~25~45~8 minecraft:concrete 7
fill ~24~46~5 ~27~46~5 minecraft:wool 7
fill ~25~48~5 ~26~48~5 minecraft:quartz_block 1
fill ~25~49~5 ~25~51~5 minecraft:quartz_block 1
fill ~25~53~5 ~26~53~5 minecraft:quartz_block 1
fill ~25~55~5 ~29~55~5 minecraft:wool 7
fill ~26~45~5 ~29~45~5 minecraft:stone_block_slab 8
setblock ~26~47~5 minecraft:quartz_block 1
fill ~26~50~5 ~27~51~6 minecraft:quartz_block 1
fill ~26~54~5 ~26~54~6 minecraft:quartz_block 1
fill ~26~56~5 ~29~56~5 minecraft:concrete 7
fill ~26~57~5 ~29~57~5 minecraft:anvil 3
fill ~26~58~5 ~29~58~5 minecraft:stone_block_slab 0
setblock ~27~47~5 minecraft:concrete 7
fill ~27~49~5 ~27~49~6 minecraft:quartz_block 1
fill ~27~52~5 ~27~52~6 minecraft:quartz_block 1
fill ~28~49~5 ~28~50~6 minecraft:concrete 7
setblock ~28~52~5 minecraft:concrete 7
fill ~28~53~5 ~28~54~6 minecraft:quartz_block 1
setblock ~29~53~5 minecraft:stained_glass 3
fill ~29~54~5 ~29~54~7 minecraft:quartz_block 1
setblock ~30~55~5 minecraft:concrete 7
fill ~30~56~5 ~32~56~5 minecraft:stone_block_slab 0
fill ~31~52~5 ~31~54~6 minecraft:concrete 7
fill ~14~47~6 ~15~47~6 minecraft:concrete 7
fill ~14~52~6 ~15~54~6 minecraft:quartz_block 1
fill ~14~56~6 ~15~56~6 minecraft:stone_block_slab 0
fill ~15~49~6 ~16~49~7 minecraft:quartz_block 1
fill ~15~50~6 ~15~51~6 minecraft:quartz_block 1
setblock ~15~55~6 minecraft:concrete 7
fill ~16~47~6 ~16~48~6 minecraft:quartz_block 1
setblock ~16~54~6 minecraft:quartz_block 1
fill ~16~55~6 ~17~55~6 minecraft:wool 7
setblock ~16~56~6 minecraft:concrete 7
setblock ~16~57~6 minecraft:anvil 3
setblock ~16~58~6 minecraft:stone_block_slab 0
fill ~17~45~6 ~18~45~6 minecraft:stone_block_slab 8
fill ~17~46~6 ~19~46~6 minecraft:wool 7
fill ~17~47~6 ~17~47~26 minecraft:concrete 0
fill ~17~56~6 ~19~56~26 minecraft:concrete 0
fill ~20~44~6 ~22~44~6 minecraft:concrete 4
fill ~20~45~6 ~20~45~8 minecraft:concrete 7
fill ~23~44~6 ~25~44~8 minecraft:concrete 7
fill ~25~46~6 ~29~46~6 minecraft:wool 7
fill ~26~44~6 ~27~44~6 minecraft:concrete 4
fill ~26~45~6 ~26~45~7 minecraft:concrete 7
fill ~26~47~6 ~26~47~26 minecraft:concrete 0
fill ~26~48~6 ~27~48~6 minecraft:quartz_block 1
fill ~26~52~6 ~26~53~6 minecraft:quartz_block 1
fill ~26~56~6 ~29~56~26 minecraft:concrete 0
fill ~27~45~6 ~28~45~7 minecraft:stained_hardened_clay 1
setblock ~27~47~6 minecraft:quartz_block 1
fill ~27~53~6 ~27~54~6 minecraft:quartz_block 1
fill ~28~43~6 ~29~43~6 minecraft:concrete 4
fill ~28~44~6 ~28~44~7 minecraft:stained_hardened_clay 1
fill ~28~47~6 ~29~47~6 minecraft:concrete 7
fill ~28~48~6 ~28~48~7 minecraft:concrete 7
fill ~28~51~6 ~28~52~6 minecraft:quartz_block 1
fill ~29~42~6 ~30~42~6 minecraft:concrete 4
fill ~29~44~6 ~30~44~6 minecraft:hardened_clay
setblock ~29~45~6 minecraft:concrete 7
fill ~29~51~6 ~29~52~6 minecraft:stained_glass 3
fill ~29~53~6 ~30~53~7 minecraft:quartz_block 1
fill ~29~55~6 ~32~55~6 minecraft:wool 7
fill ~30~41~6 ~31~41~6 minecraft:concrete 4
fill ~30~43~6 ~31~43~6 minecraft:hardened_clay
fill ~30~45~6 ~31~45~6 minecraft:wool 7
fill ~30~52~6 ~30~52~7 minecraft:quartz_block 1
fill ~30~54~6 ~30~54~7 minecraft:quartz_block 1
fill ~30~56~6 ~32~56~6 minecraft:concrete 7
fill ~30~57~6 ~32~57~6 minecraft:anvil 3
fill ~30~58~6 ~32~58~6 minecraft:stone_block_slab 0
setblock ~31~42~6 minecraft:hardened_clay
fill ~31~51~6 ~32~51~6 minecraft:concrete 7
fill ~32~41~6 ~32~42~7 minecraft:stained_hardened_clay 1
fill ~32~50~6 ~32~50~7 minecraft:concrete 7
setblock ~33~55~6 minecraft:concrete 7
fill ~33~56~6 ~34~56~6 minecraft:stone_block_slab 0
fill ~12~51~7 ~12~52~8 minecraft:concrete 7
fill ~13~47~7 ~13~47~11 minecraft:concrete 7
fill ~13~50~7 ~14~52~7 minecraft:quartz_block 1
fill ~13~53~7 ~13~54~7 minecraft:quartz_block 1
setblock ~13~55~7 minecraft:concrete 7
setblock ~13~56~7 minecraft:stone_block_slab 0
fill ~14~47~7 ~15~47~8 minecraft:quartz_block 1
fill ~14~48~7 ~16~48~7 minecraft:quartz_block 1
setblock ~14~49~7 minecraft:quartz_block 1
fill ~14~55~7 ~16~55~7 minecraft:wool 7
fill ~14~56~7 ~15~56~7 minecraft:concrete 7
fill ~14~57~7 ~15~57~7 minecraft:anvil 3
fill ~14~58~7 ~15~58~7 minecraft:stone_block_slab 0
fill ~16~45~7 ~17~45~7 minecraft:stone_block_slab 8
fill ~16~46~7 ~17~46~7 minecraft:wool 7
fill ~16~47~7 ~16~47~26 minecraft:concrete 0
fill ~16~56~7 ~16~56~26 minecraft:concrete 0
fill ~18~44~7 ~20~44~7 minecraft:concrete 4
fill ~18~45~7 ~19~45~8 minecraft:concrete 7
fill ~21~43~7 ~22~43~7 minecraft:concrete 4
fill ~21~44~7 ~22~44~10 minecraft:concrete 7
fill ~21~57~7 ~21~60~7 minecraft:stained_glass 7
fill ~21~63~7 ~26~63~8 minecraft:wool 7
fill ~21~64~7 ~26~64~7 minecraft:anvil 3
fill ~21~65~7 ~26~65~7 minecraft:stone_block_slab 0
fill ~22~42~7 ~22~42~9 minecraft:concrete 4
fill ~22~60~7 ~22~61~7 minecraft:stained_glass 7
fill ~23~61~7 ~25~61~7 minecraft:stained_glass 7
fill ~24~43~7 ~29~43~8 minecraft:concrete 7
fill ~25~60~7 ~26~60~7 minecraft:stained_glass 7
fill ~26~42~7 ~30~42~8 minecraft:concrete 7
fill ~26~44~7 ~27~44~8 minecraft:concrete 7
setblock ~26~46~7 minecraft:concrete 0
fill ~26~57~7 ~26~59~7 minecraft:stained_glass 7
fill ~27~46~7 ~28~46~8 minecraft:concrete 7
setblock ~27~47~7 minecraft:concrete 7
setblock ~27~48~7 minecraft:quartz_block 1
fill ~28~41~7 ~31~41~8 minecraft:concrete 7
fill ~28~47~7 ~29~47~7 minecraft:quartz_block 1
fill ~28~49~7 ~30~49~7 minecraft:quartz_block 1
fill ~28~50~7 ~29~50~7 minecraft:quartz_block 1
fill ~29~44~7 ~30~44~7 minecraft:stained_hardened_clay 1
fill ~29~45~7 ~29~45~9 minecraft:concrete 0
fill ~29~46~7 ~32~46~7 minecraft:wool 7
fill ~29~48~7 ~30~48~8 minecraft:quartz_block 1
fill ~29~51~7 ~29~51~8 minecraft:quartz_block 1
setblock ~29~52~7 minecraft:quartz_block 1
fill ~30~40~7 ~33~40~7 minecraft:concrete 4
fill ~30~43~7 ~31~43~7 minecraft:stained_hardened_clay 1
fill ~30~45~7 ~31~45~7 minecraft:concrete 7
fill ~30~47~7 ~32~47~7 minecraft:concrete 7
fill ~30~50~7 ~30~51~7 minecraft:stained_glass 3
fill ~30~56~7 ~32~56~26 minecraft:concrete 0
setblock ~31~42~7 minecraft:stained_hardened_clay 1
setblock ~31~44~7 minecraft:concrete 7
fill ~31~50~7 ~31~51~8 minecraft:quartz_block 1
fill ~31~52~7 ~32~54~7 minecraft:quartz_block 1
fill ~31~55~7 ~34~55~7 minecraft:wool 7
fill ~32~39~7 ~33~39~7 minecraft:concrete 4
fill ~32~48~7 ~32~49~8 minecraft:concrete 7
setblock ~32~51~7 minecraft:concrete 7
setblock ~33~41~7 minecraft:stained_hardened_clay 1
fill ~33~52~7 ~33~53~7 minecraft:stained_glass 3
fill ~33~54~7 ~34~54~8 minecraft:quartz_block 1
fill ~33~56~7 ~34~56~7 minecraft:concrete 7
fill ~33~57~7 ~34~57~7 minecraft:anvil 3
fill ~33~58~7 ~34~58~7 minecraft:stone_block_slab 0
fill ~35~53~7 ~35~55~7 minecraft:concrete 7
fill ~35~56~7 ~36~56~7 minecraft:stone_block_slab 0
fill ~11~51~8 ~11~52~8 minecraft:concrete 7
fill ~12~49~8 ~13~50~8 minecraft:concrete 7
fill ~12~53~8 ~12~55~8 minecraft:concrete 7
setblock ~12~56~8 minecraft:stone_block_slab 0
setblock ~13~48~8 minecraft:concrete 7
fill ~13~55~8 ~14~55~8 minecraft:wool 7
setblock ~13~56~8 minecraft:concrete 7
setblock ~13~57~8 minecraft:anvil 3
setblock ~13~58~8 minecraft:stone_block_slab 0
fill ~14~56~8 ~15~56~26 minecraft:concrete 0
fill ~15~45~8 ~16~45~9 minecraft:stone_block_slab 8
setblock ~15~48~8 minecraft:quartz_block 1
fill ~16~46~8 ~16~46~9 minecraft:wool 7
fill ~17~44~8 ~18~44~8 minecraft:concrete 4
fill ~17~45~8 ~17~45~10 minecraft:concrete 7
fill ~17~63~8 ~20~63~9 minecraft:wool 7
fill ~17~64~8 ~20~64~8 minecraft:anvil 3
fill ~17~65~8 ~20~65~8 minecraft:stone_block_slab 0
fill ~19~44~8 ~20~44~13 minecraft:concrete 7
fill ~20~43~8 ~23~43~10 minecraft:concrete 7
fill ~21~42~8 ~21~42~9 minecraft:concrete 4
fill ~21~57~8 ~21~62~8 minecraft:concrete 0
fill ~22~60~8 ~22~62~8 minecraft:concrete 0
setblock ~23~42~8 minecraft:concrete 4
fill ~23~61~8 ~26~62~8 minecraft:concrete 0
fill ~24~42~8 ~25~42~9 minecraft:concrete 7
fill ~25~41~8 ~27~41~8 minecraft:concrete 7
fill ~25~60~8 ~26~60~8 minecraft:concrete 0
setblock ~26~45~8 minecraft:concrete 0
fill ~26~57~8 ~26~59~8 minecraft:concrete 0
fill ~27~47~8 ~29~47~26 minecraft:concrete 0
fill ~27~63~8 ~28~63~9 minecraft:wool 7
fill ~27~64~8 ~28~64~8 minecraft:anvil 3
fill ~27~65~8 ~28~65~8 minecraft:stone_block_slab 0
fill ~28~40~8 ~33~40~9 minecraft:concrete 7
setblock ~28~44~8 minecraft:concrete 7
setblock ~28~48~8 minecraft:quartz_block 1
fill ~29~44~8 ~30~44~8 minecraft:concrete 1
fill ~29~46~8 ~29~46~9 minecraft:concrete 7
fill ~29~49~8 ~31~49~8 minecraft:quartz_block 1
fill ~29~50~8 ~30~50~8 minecraft:quartz_block 1
fill ~30~39~8 ~33~39~10 minecraft:concrete 7
fill ~30~43~8 ~31~43~8 minecraft:concrete 1
fill ~30~45~8 ~31~45~8 minecraft:concrete 0
fill ~30~46~8 ~32~46~8 minecraft:wool 7
fill ~30~47~8 ~31~47~8 minecraft:quartz_block 1
setblock ~30~51~8 minecraft:quartz_block 1
fill ~31~42~8 ~32~42~8 minecraft:concrete 1
fill ~31~44~8 ~31~44~9 minecraft:concrete 0
fill ~31~48~8 ~31~48~9 minecraft:quartz_block 1
fill ~32~38~8 ~36~38~8 minecraft:concrete 4
fill ~32~41~8 ~32~41~9 minecraft:concrete 1
fill ~32~43~8 ~34~43~8 minecraft:concrete 7
setblock ~32~44~8 minecraft:concrete 7
fill ~32~45~8 ~33~45~8 minecraft:wool 7
setblock ~32~47~8 minecraft:concrete 7
fill ~32~50~8 ~32~54~8 minecraft:quartz_block 1
setblock ~33~41~8 minecraft:hardened_clay
fill ~33~42~8 ~34~42~8 minecraft:concrete 7
setblock ~33~44~8 minecraft:wool 7
fill ~33~51~8 ~33~51~9 minecraft:quartz_block 1
fill ~33~52~8 ~34~53~8 minecraft:quartz_block 1
fill ~33~56~8 ~34~56~26 minecraft:concrete 0
fill ~34~39~8 ~35~39~9 minecraft:stained_hardened_clay 1
fill ~34~40~8 ~34~40~9 minecraft:stained_hardened_clay 1
setblock ~34~51~8 minecraft:stained_glass 3
fill ~34~55~8 ~36~55~8 minecraft:wool 7
setblock ~35~52~8 minecraft:concrete 7
fill ~35~53~8 ~35~54~8 minecraft:quartz_block 1
fill ~35~56~8 ~36~56~8 minecraft:concrete 7
fill ~35~57~8 ~36~57~8 minecraft:anvil 3
fill ~35~58~8 ~36~58~8 minecraft:stone_block_slab 0
setblock ~36~39~8 minecraft:hardened_clay
fill ~36~51~8 ~36~51~9 minecraft:concrete 7
setblock ~37~37~8 minecraft:concrete 4
setblock ~37~55~8 minecraft:concrete 7
fill ~37~56~8 ~38~56~8 minecraft:stone_block_slab 0
fill ~11~53~9 ~12~53~10 minecraft:quartz_block 1
fill ~11~54~9 ~11~54~10 minecraft:quartz_block 1
setblock ~11~55~9 minecraft:concrete 7
setblock ~11~56~9 minecraft:stone_block_slab 0
fill ~12~51~9 ~13~51~10 minecraft:quartz_block 1
fill ~12~52~9 ~12~52~10 minecraft:quartz_block 1
fill ~12~55~9 ~13~55~9 minecraft:wool 7
setblock ~12~56~9 minecraft:concrete 7
setblock ~12~57~9 minecraft:anvil 3
setblock ~12~58~9 minecraft:stone_block_slab 0
fill ~13~48~9 ~14~48~10 minecraft:quartz_block 1
fill ~13~49~9 ~13~50~10 minecraft:quartz_block 1
fill ~13~56~9 ~13~56~26 minecraft:concrete 0
fill ~14~47~9 ~14~47~11 minecraft:quartz_block 1
fill ~15~46~9 ~15~46~12 minecraft:wool 7
fill ~15~47~9 ~15~47~26 minecraft:concrete 0
fill ~15~63~9 ~16~63~12 minecraft:wool 7
fill ~15~64~9 ~16~64~9 minecraft:anvil 3
fill ~15~65~9 ~16~65~9 minecraft:stone_block_slab 0
fill ~16~44~9 ~17~44~9 minecraft:concrete 4
fill ~17~61~9 ~17~62~9 minecraft:concrete 0
fill ~18~44~9 ~18~44~15 minecraft:concrete 7
fill ~18~62~9 ~20~62~9 minecraft:concrete 0
fill ~19~43~9 ~19~43~15 minecraft:concrete 7
fill ~19~61~9 ~20~61~9 minecraft:concrete 0
setblock ~20~60~9 minecraft:concrete 0
fill ~21~57~9 ~26~57~9 minecraft:stone 4
fill ~21~58~9 ~22~59~9 minecraft:stone 4
setblock ~21~60~9 minecraft:stone 4
fill ~21~63~9 ~25~63~45 minecraft:planks 2
fill ~22~41~9 ~24~41~9 minecraft:concrete 4
fill ~22~45~9 ~24~45~11 minecraft:concrete 7
fill ~23~42~9 ~23~42~10 minecraft:concrete 7
fill ~23~44~9 ~24~44~9 minecraft:concrete 7
fill ~23~58~9 ~24~59~9 minecraft:stained_glass 3
fill ~23~60~9 ~24~60~9 minecraft:stone 4
fill ~24~40~9 ~25~40~9 minecraft:concrete 4
fill ~24~43~9 ~25~43~9 minecraft:concrete 7
fill ~25~41~9 ~26~41~9 minecraft:concrete 7
setblock ~25~45~9 minecraft:concrete 0
fill ~25~58~9 ~26~59~9 minecraft:stone 4
fill ~26~40~9 ~27~40~10 minecraft:concrete 7
setblock ~26~45~9 minecraft:concrete 7
fill ~26~62~9 ~28~62~9 minecraft:concrete 0
setblock ~26~63~9 minecraft:wool 7
fill ~27~39~9 ~29~39~10 minecraft:concrete 7
fill ~27~60~9 ~27~61~9 minecraft:concrete 0
setblock ~28~61~9 minecraft:concrete 0
fill ~29~38~9 ~36~38~10 minecraft:concrete 7
fill ~29~44~9 ~30~44~9 minecraft:concrete 0
fill ~29~63~9 ~31~63~10 minecraft:wool 7
fill ~29~64~9 ~31~64~9 minecraft:anvil 3
fill ~29~65~9 ~31~65~9 minecraft:stone_block_slab 0
fill ~30~37~9 ~37~37~9 minecraft:concrete 7
fill ~30~46~9 ~31~46~9 minecraft:concrete 7
fill ~30~47~9 ~31~47~26 minecraft:concrete 0
fill ~31~36~9 ~38~36~11 minecraft:concrete 7
setblock ~31~43~9 minecraft:concrete 0
fill ~31~45~9 ~33~45~9 minecraft:concrete 0
fill ~31~49~9 ~32~49~9 minecraft:quartz_block 1
fill ~32~35~9 ~38~35~10 minecraft:concrete 7
fill ~32~44~9 ~33~44~9 minecraft:concrete 0
fill ~32~46~9 ~34~46~9 minecraft:wool 7
fill ~32~47~9 ~32~48~9 minecraft:quartz_block 1
fill ~33~34~9 ~38~34~10 minecraft:concrete 7
fill ~33~41~9 ~33~41~10 minecraft:concrete 1
fill ~33~42~9 ~34~43~9 minecraft:concrete 0
fill ~33~47~9 ~34~47~9 minecraft:concrete 7
fill ~33~50~9 ~33~50~10 minecraft:quartz_block 1
fill ~34~41~9 ~37~41~9 minecraft:concrete 7
fill ~34~44~9 ~36~45~9 minecraft:wool 7
setblock ~34~50~9 minecraft:stained_glass 3
fill ~34~51~9 ~35~51~9 minecraft:quartz_block 1
fill ~35~40~9 ~36~40~9 minecraft:concrete 7
setblock ~35~42~9 minecraft:concrete 7
fill ~35~43~9 ~35~43~10 minecraft:concrete 0
setblock ~35~52~9 minecraft:quartz_block 1
fill ~35~56~9 ~36~56~26 minecraft:concrete 0
fill ~36~33~9 ~38~33~10 minecraft:concrete 7
setblock ~36~39~9 minecraft:stained_hardened_clay 1
fill ~36~50~9 ~36~50~10 minecraft:concrete 7
fill ~36~52~9 ~36~53~9 minecraft:stained_glass 3
setblock ~36~54~9 minecraft:quartz_block 1
fill ~36~55~9 ~38~55~9 minecraft:wool 7
fill ~37~38~9 ~39~38~9 minecraft:hardened_clay
fill ~37~56~9 ~38~56~9 minecraft:concrete 7
fill ~37~57~9 ~38~57~9 minecraft:anvil 3
fill ~37~58~9 ~38~58~9 minecraft:stone_block_slab 0
setblock ~38~26~9 minecraft:stone_block_slab 8
fill ~38~28~9 ~38~29~10 minecraft:concrete 4
fill ~38~37~9 ~39~37~9 minecraft:concrete 4
fill ~39~27~9 ~40~27~9 minecraft:wool 7
fill ~39~28~9 ~41~28~9 minecraft:stone_block_slab 0
fill ~39~29~9 ~39~30~10 minecraft:concrete 4
setblock ~39~56~9 minecraft:stone_block_slab 0
fill ~40~30~9 ~40~30~10 minecraft:concrete 4
fill ~41~31~9 ~41~32~10 minecraft:concrete 4
fill ~42~29~9 ~42~29~10 minecraft:stone_block_slab 0
fill ~10~53~10 ~10~54~10 minecraft:quartz_block 1
setblock ~10~55~10 minecraft:concrete 7
setblock ~10~56~10 minecraft:stone_block_slab 0
fill ~11~51~10 ~11~52~10 minecraft:quartz_block 1
fill ~11~55~10 ~12~55~10 minecraft:wool 7
setblock ~11~56~10 minecraft:concrete 7
setblock ~11~57~10 minecraft:anvil 3
setblock ~11~58~10 minecraft:stone_block_slab 0
setblock ~12~50~10 minecraft:quartz_block 1
fill ~12~56~10 ~12~56~26 minecraft:concrete 0
setblock ~13~52~10 minecraft:quartz_block 1
fill ~15~44~10 ~16~44~11 minecraft:concrete 4
fill ~15~45~10 ~15~45~12 minecraft:stone_block_slab 8
setblock ~15~48~10 minecraft:quartz_block 1
setblock ~15~64~10 minecraft:anvil 3
setblock ~15~65~10 minecraft:stone_block_slab 0
fill ~16~45~10 ~16~45~26 minecraft:concrete 7
fill ~16~57~10 ~16~62~10 minecraft:concrete 0
fill ~17~44~10 ~17~44~26 minecraft:concrete 7
fill ~17~61~10 ~19~61~11 minecraft:stone 4
fill ~17~63~10 ~18~63~10 minecraft:wool 7
fill ~18~57~10 ~20~57~10 minecraft:stone 4
fill ~18~58~10 ~19~59~10 minecraft:stained_glass 3
setblock ~18~60~10 minecraft:stained_glass 3
fill ~18~62~10 ~19~62~10 minecraft:concrete 0
fill ~19~60~10 ~20~60~10 minecraft:stone 4
fill ~19~63~10 ~20~63~44 minecraft:planks 2
fill ~20~42~10 ~22~42~10 minecraft:concrete 7
fill ~20~58~10 ~20~59~10 minecraft:stone 4
fill ~21~41~10 ~25~41~10 minecraft:concrete 7
fill ~23~40~10 ~24~40~10 minecraft:concrete 4
setblock ~23~44~10 minecraft:concrete 7
fill ~24~39~10 ~25~39~10 minecraft:concrete 4
fill ~24~42~10 ~24~43~10 minecraft:concrete 7
fill ~25~38~10 ~26~38~10 minecraft:concrete 4
fill ~25~40~10 ~25~40~11 minecraft:concrete 7
setblock ~25~45~10 minecraft:concrete 7
fill ~26~37~10 ~27~37~10 minecraft:concrete 4
fill ~26~39~10 ~26~39~11 minecraft:concrete 7
fill ~26~63~10 ~28~63~44 minecraft:planks 2
fill ~27~36~10 ~28~36~11 minecraft:concrete 4
fill ~27~38~10 ~28~38~10 minecraft:concrete 7
setblock ~27~57~10 minecraft:stone 4
fill ~27~58~10 ~27~59~10 minecraft:stained_glass 3
setblock ~27~60~10 minecraft:stone 4
fill ~28~37~10 ~34~37~11 minecraft:concrete 7
setblock ~28~61~10 minecraft:stone 4
fill ~28~62~10 ~31~62~10 minecraft:concrete 0
fill ~29~35~10 ~29~35~11 minecraft:concrete 4
fill ~29~36~10 ~30~36~10 minecraft:concrete 7
fill ~29~61~10 ~30~61~10 minecraft:concrete 0
fill ~30~35~10 ~31~35~12 minecraft:concrete 7
setblock ~30~60~10 minecraft:concrete 0
fill ~31~34~10 ~32~34~11 minecraft:concrete 7
fill ~32~33~10 ~35~33~10 minecraft:concrete 7
fill ~32~47~10 ~32~47~26 minecraft:concrete 0
fill ~32~63~10 ~32~63~11 minecraft:wool 7
setblock ~32~64~10 minecraft:anvil 3
setblock ~32~65~10 minecraft:stone_block_slab 0
fill ~33~40~10 ~34~40~10 minecraft:concrete 1
fill ~33~45~10 ~35~45~10 minecraft:concrete 0
setblock ~33~46~10 minecraft:concrete 7
fill ~33~47~10 ~34~49~10 minecraft:quartz_block 1
fill ~34~32~10 ~40~32~10 minecraft:concrete 7
fill ~34~39~10 ~36~39~10 minecraft:concrete 1
fill ~34~41~10 ~37~41~10 minecraft:concrete 0
fill ~34~44~10 ~36~44~10 minecraft:concrete 0
fill ~34~46~10 ~36~46~10 minecraft:wool 7
fill ~34~50~10 ~35~50~10 minecraft:quartz_block 1
fill ~35~31~10 ~40~31~11 minecraft:concrete 7
fill ~35~40~10 ~36~40~10 minecraft:concrete 0
fill ~35~42~10 ~37~42~10 minecraft:concrete 0
fill ~35~47~10 ~36~47~10 minecraft:concrete 7
fill ~35~51~10 ~36~51~10 minecraft:quartz_block 1
fill ~36~37~10 ~39~37~11 minecraft:concrete 7
fill ~36~43~10 ~37~43~10 minecraft:concrete 0
fill ~36~45~10 ~38~45~10 minecraft:wool 7
fill ~36~48~10 ~36~49~11 minecraft:concrete 7
fill ~36~52~10 ~36~53~11 minecraft:quartz_block 1
fill ~37~28~10 ~37~28~12 minecraft:concrete 4
fill ~37~38~10 ~39~38~10 minecraft:stained_hardened_clay 1
fill ~37~39~10 ~38~40~10 minecraft:concrete 7
fill ~37~44~10 ~38~44~10 minecraft:wool 7
setblock ~37~52~10 minecraft:stained_glass 3
fill ~37~53~10 ~37~53~11 minecraft:quartz_block 1
fill ~37~54~10 ~38~54~10 minecraft:concrete 7
fill ~37~56~10 ~38~56~26 minecraft:concrete 0
fill ~38~26~10 ~39~26~10 minecraft:wool 7
setblock ~38~27~10 minecraft:stained_hardened_clay 1
fill ~38~30~10 ~38~30~12 minecraft:concrete 7
fill ~38~52~10 ~39~52~10 minecraft:concrete 7
setblock ~38~53~10 minecraft:concrete 7
fill ~38~55~10 ~39~55~10 minecraft:wool 7
fill ~39~27~10 ~42~27~10 minecraft:concrete 0
fill ~39~28~10 ~39~28~11 minecraft:stained_hardened_clay 1
fill ~39~33~10 ~40~36~11 minecraft:concrete 7
setblock ~39~40~10 minecraft:concrete 7
setblock ~39~56~10 minecraft:concrete 7
setblock ~39~57~10 minecraft:anvil 0
setblock ~39~58~10 minecraft:stone_block_slab 0
fill ~40~26~10 ~43~26~11 minecraft:concrete 0
fill ~40~28~10 ~42~28~10 minecraft:wool 7
fill ~40~29~10 ~41~29~10 minecraft:hardened_clay
setblock ~40~37~10 minecraft:concrete 4
fill ~40~38~10 ~41~38~10 minecraft:hardened_clay
setblock ~40~56~10 minecraft:stone_block_slab 0
fill ~42~25~10 ~43~25~12 minecraft:concrete 0
setblock ~43~29~10 minecraft:double_stone_block_slab 0
setblock ~44~30~10 minecraft:double_stone_block_slab 0
fill ~8~53~11 ~9~54~11 minecraft:concrete 7
fill ~9~51~11 ~10~51~11 minecraft:concrete 7
setblock ~9~52~11 minecraft:concrete 7
setblock ~9~55~11 minecraft:concrete 7
setblock ~9~56~11 minecraft:stone_block_slab 0
fill ~10~50~11 ~11~50~11 minecraft:concrete 7
setblock ~10~52~11 minecraft:quartz_block 1
fill ~10~55~11 ~11~55~11 minecraft:wool 7
setblock ~10~56~11 minecraft:concrete 7
setblock ~10~57~11 minecraft:anvil 2
setblock ~10~58~11 minecraft:stone_block_slab 0
fill ~11~49~11 ~12~49~11 minecraft:concrete 7
fill ~11~56~11 ~11~56~26 minecraft:concrete 0
fill ~12~48~11 ~13~48~11 minecraft:concrete 7
fill ~14~63~11 ~14~63~17 minecraft:wool 7
setblock ~14~64~11 minecraft:anvil 3
setblock ~14~65~11 minecraft:stone_block_slab 0
fill ~15~61~11 ~15~62~11 minecraft:concrete 0
fill ~16~62~11 ~18~62~11 minecraft:concrete 0
fill ~17~57~11 ~19~57~11 minecraft:stone 4
fill ~17~58~11 ~17~60~11 minecraft:stone 4
setblock ~17~63~11 minecraft:wool 7
fill ~18~60~11 ~19~60~11 minecraft:stone 4
fill ~18~63~11 ~18~63~43 minecraft:planks 2
fill ~20~41~11 ~23~41~11 minecraft:concrete 7
fill ~20~42~11 ~21~43~11 minecraft:concrete 7
setblock ~21~44~11 minecraft:concrete 7
fill ~23~40~11 ~24~40~12 minecraft:concrete 7
fill ~24~38~11 ~24~39~11 minecraft:concrete 4
fill ~25~37~11 ~26~37~11 minecraft:concrete 4
fill ~25~38~11 ~27~38~11 minecraft:concrete 7
fill ~25~39~11 ~25~39~12 minecraft:concrete 7
fill ~27~37~11 ~27~37~13 minecraft:concrete 7
fill ~28~35~11 ~28~35~12 minecraft:concrete 4
fill ~28~57~11 ~30~57~11 minecraft:stone 4
fill ~28~58~11 ~29~59~11 minecraft:stained_glass 3
setblock ~28~60~11 minecraft:stained_glass 3
fill ~29~34~11 ~30~34~11 minecraft:concrete 4
setblock ~29~36~11 minecraft:concrete 4
fill ~29~38~11 ~35~38~11 minecraft:concrete 7
setblock ~29~60~11 minecraft:stone 4
fill ~29~63~11 ~31~63~13 minecraft:planks 2
fill ~30~33~11 ~31~33~11 minecraft:concrete 4
fill ~30~36~11 ~30~36~12 minecraft:concrete 7
fill ~30~58~11 ~30~59~11 minecraft:stone 4
fill ~31~57~11 ~31~62~11 minecraft:concrete 0
fill ~32~32~11 ~32~32~12 minecraft:concrete 4
fill ~32~33~11 ~34~33~11 minecraft:concrete 7
fill ~32~35~11 ~34~35~11 minecraft:concrete 7
fill ~32~61~11 ~32~62~12 minecraft:concrete 0
fill ~33~32~11 ~36~32~11 minecraft:concrete 7
fill ~33~34~11 ~34~34~11 minecraft:concrete 7
fill ~33~47~11 ~34~47~26 minecraft:concrete 0
fill ~33~63~11 ~33~63~13 minecraft:wool 7
setblock ~33~64~11 minecraft:anvil 3
setblock ~33~65~11 minecraft:stone_block_slab 0
fill ~34~31~11 ~34~31~13 minecraft:concrete 7
fill ~34~46~11 ~35~46~11 minecraft:concrete 7
fill ~34~48~11 ~35~49~11 minecraft:quartz_block 1
setblock ~35~37~11 minecraft:concrete 7
fill ~35~45~11 ~37~45~11 minecraft:concrete 0
setblock ~35~47~11 minecraft:quartz_block 1
fill ~35~50~11 ~36~50~11 minecraft:quartz_block 1
fill ~36~26~11 ~37~26~11 minecraft:stone_block_slab 8
fill ~36~28~11 ~36~28~12 minecraft:concrete 4
fill ~36~30~11 ~37~30~13 minecraft:concrete 7
fill ~36~38~11 ~39~38~11 minecraft:concrete 1
setblock ~36~39~11 minecraft:concrete 1
fill ~36~40~11 ~39~40~11 minecraft:concrete 0
fill ~36~44~11 ~38~44~11 minecraft:concrete 0
fill ~36~46~11 ~40~46~11 minecraft:wool 7
fill ~36~47~11 ~41~47~11 minecraft:concrete 7
setblock ~36~51~11 minecraft:quartz_block 1
setblock ~37~27~11 minecraft:stained_hardened_clay 1
fill ~37~29~11 ~39~29~11 minecraft:concrete 7
fill ~37~39~11 ~38~39~11 minecraft:concrete 0
fill ~37~41~11 ~39~41~11 minecraft:concrete 0
fill ~37~48~11 ~37~49~11 minecraft:quartz_block 1
fill ~37~50~11 ~37~51~11 minecraft:stained_glass 3
fill ~37~52~11 ~38~52~11 minecraft:quartz_block 1
setblock ~38~26~11 minecraft:wool 7
fill ~38~27~11 ~39~27~11 minecraft:concrete 0
fill ~38~28~11 ~38~28~12 minecraft:concrete 7
fill ~38~42~11 ~39~43~11 minecraft:concrete 0
fill ~38~45~11 ~40~45~11 minecraft:wool 7
fill ~38~49~11 ~38~51~12 minecraft:quartz_block 1
fill ~38~53~11 ~39~53~12 minecraft:quartz_block 1
setblock ~39~26~11 minecraft:concrete 0
fill ~39~30~11 ~40~30~11 minecraft:concrete 7
fill ~39~32~11 ~40~32~11 minecraft:concrete 7
fill ~39~39~11 ~41~39~11 minecraft:concrete 7
fill ~39~44~11 ~40~44~11 minecraft:wool 7
fill ~39~49~11 ~40~49~11 minecraft:concrete 7
fill ~39~50~11 ~39~51~12 minecraft:concrete 7
setblock ~39~52~11 minecraft:concrete 7
setblock ~39~54~11 minecraft:concrete 7
fill ~39~55~11 ~40~55~11 minecraft:wool 7
fill ~39~56~11 ~39~56~26 minecraft:concrete 0
fill ~40~27~11 ~41~27~11 minecraft:concrete 7
fill ~40~28~11 ~44~28~11 minecraft:concrete 0
setblock ~40~29~11 minecraft:concrete 1
fill ~40~37~11 ~40~37~12 minecraft:concrete 7
fill ~40~38~11 ~42~38~11 minecraft:stained_hardened_clay 1
fill ~40~40~11 ~42~40~11 minecraft:concrete 7
fill ~40~48~11 ~40~48~12 minecraft:concrete 7
fill ~40~56~11 ~40~56~13 minecraft:concrete 7
fill ~40~57~11 ~40~57~12 minecraft:anvil 0
setblock ~40~58~11 minecraft:stone_block_slab 0
fill ~41~25~11 ~41~25~13 minecraft:concrete 0
fill ~41~29~11 ~41~30~11 minecraft:stained_hardened_clay 1
fill ~41~31~11 ~41~31~12 minecraft:concrete 7
fill ~41~32~11 ~41~34~11 minecraft:concrete 4
fill ~41~35~11 ~41~36~13 minecraft:concrete 7
setblock ~41~37~11 minecraft:concrete 4
fill ~41~55~11 ~42~55~11 minecraft:stone_block_slab 8
fill ~42~22~11 ~42~24~12 minecraft:concrete 0
fill ~42~27~11 ~44~27~11 minecraft:concrete 0
fill ~42~29~11 ~43~29~11 minecraft:wool 7
fill ~42~30~11 ~42~31~11 minecraft:hardened_clay
fill ~43~23~11 ~43~24~12 minecraft:concrete 0
fill ~43~30~11 ~44~30~11 minecraft:wool 7
fill ~43~32~11 ~44~32~11 minecraft:stone_block_slab 8
fill ~44~25~11 ~44~26~13 minecraft:concrete 0
fill ~44~29~11 ~44~29~12 minecraft:concrete 0
setblock ~44~31~11 minecraft:wool 7
setblock ~45~31~11 minecraft:double_stone_block_slab 0
fill ~8~56~12 ~8~56~15 minecraft:stone_block_slab 0
fill ~9~52~12 ~9~54~12 minecraft:quartz_block 1
fill ~9~55~12 ~10~55~12 minecraft:wool 7
fill ~9~56~12 ~9~56~15 minecraft:concrete 7
fill ~9~57~12 ~9~57~15 minecraft:anvil 2
fill ~9~58~12 ~9~58~15 minecraft:stone_block_slab 0
setblock ~10~51~12 minecraft:quartz_block 1
setblock ~10~54~12 minecraft:quartz_block 1
fill ~10~56~12 ~10~56~26 minecraft:concrete 0
setblock ~11~50~12 minecraft:quartz_block 1
fill ~12~47~12 ~12~47~15 minecraft:concrete 7
setblock ~12~49~12 minecraft:quartz_block 1
fill ~13~47~12 ~13~47~15 minecraft:quartz_block 1
setblock ~13~48~12 minecraft:quartz_block 1
fill ~13~63~12 ~13~63~21 minecraft:wool 7
setblock ~13~64~12 minecraft:anvil 2
setblock ~13~65~12 minecraft:stone_block_slab 0
fill ~14~44~12 ~15~44~14 minecraft:concrete 4
fill ~14~45~12 ~14~45~16 minecraft:stone_block_slab 8
fill ~14~46~12 ~14~46~16 minecraft:wool 7
fill ~14~47~12 ~14~47~26 minecraft:concrete 0
fill ~14~60~12 ~14~62~12 minecraft:concrete 0
fill ~15~62~12 ~17~62~12 minecraft:concrete 0
fill ~16~44~12 ~16~44~26 minecraft:concrete 7
setblock ~16~57~12 minecraft:stone 4
fill ~16~58~12 ~16~60~12 minecraft:stained_glass 3
setblock ~16~61~12 minecraft:stone 4
fill ~17~43~12 ~18~43~15 minecraft:concrete 7
fill ~17~63~12 ~17~63~42 minecraft:planks 2
fill ~19~42~12 ~20~42~14 minecraft:concrete 7
fill ~20~41~12 ~21~41~13 minecraft:concrete 7
fill ~20~43~12 ~20~43~13 minecraft:concrete 7
fill ~21~45~12 ~23~45~13 minecraft:concrete 7
fill ~22~40~12 ~22~40~13 minecraft:concrete 7
fill ~24~38~12 ~25~38~12 minecraft:concrete 7
setblock ~24~39~12 minecraft:concrete 7
fill ~25~37~12 ~26~37~14 minecraft:concrete 7
setblock ~28~36~12 minecraft:concrete 4
fill ~28~37~12 ~31~38~12 minecraft:concrete 7
setblock ~29~34~12 minecraft:concrete 4
fill ~29~35~12 ~29~35~15 minecraft:concrete 7
fill ~29~36~12 ~29~36~14 minecraft:concrete 7
setblock ~30~33~12 minecraft:concrete 4
fill ~30~34~12 ~30~34~13 minecraft:concrete 7
fill ~31~31~12 ~32~31~12 minecraft:concrete 4
setblock ~31~32~12 minecraft:concrete 4
fill ~31~33~12 ~32~33~12 minecraft:concrete 7
setblock ~31~36~12 minecraft:concrete 7
fill ~32~30~12 ~33~30~13 minecraft:concrete 4
fill ~32~57~12 ~32~58~12 minecraft:stone 4
setblock ~32~59~12 minecraft:stained_glass 3
setblock ~32~60~12 minecraft:stone 4
fill ~32~63~12 ~32~63~13 minecraft:planks 2
fill ~33~31~12 ~33~31~14 minecraft:concrete 7
fill ~33~32~12 ~35~32~12 minecraft:concrete 7
fill ~33~60~12 ~33~62~12 minecraft:concrete 0
fill ~34~63~12 ~35~63~13 minecraft:concrete 7
setblock ~34~64~12 minecraft:anvil 0
setblock ~34~65~12 minecraft:stone_block_slab 0
fill ~35~26~12 ~35~26~13 minecraft:stone_block_slab 8
fill ~35~28~12 ~35~28~14 minecraft:concrete 4
fill ~35~30~12 ~35~30~15 minecraft:concrete 7
fill ~35~31~12 ~35~31~13 minecraft:concrete 7
fill ~35~47~12 ~37~47~26 minecraft:concrete 0
fill ~35~62~12 ~36~62~13 minecraft:concrete 7
fill ~36~26~12 ~37~26~12 minecraft:wool 7
setblock ~36~27~12 minecraft:stained_hardened_clay 1
fill ~36~29~12 ~38~29~12 minecraft:concrete 7
setblock ~36~40~12 minecraft:concrete 0
fill ~37~27~12 ~38~27~12 minecraft:concrete 0
fill ~37~61~12 ~37~61~13 minecraft:concrete 7
fill ~38~26~12 ~38~26~13 minecraft:concrete 0
fill ~38~39~12 ~41~41~12 minecraft:concrete 0
fill ~38~45~12 ~39~45~12 minecraft:concrete 0
setblock ~38~46~12 minecraft:concrete 7
fill ~38~47~12 ~39~48~12 minecraft:quartz_block 1
fill ~38~52~12 ~39~52~12 minecraft:quartz_block 1
fill ~38~60~12 ~38~60~13 minecraft:concrete 7
fill ~39~25~12 ~40~25~14 minecraft:concrete 0
fill ~39~42~12 ~42~43~12 minecraft:concrete 0
fill ~39~44~12 ~40~44~12 minecraft:concrete 0
fill ~39~46~12 ~41~46~12 minecraft:wool 7
setblock ~39~49~12 minecraft:quartz_block 1
fill ~39~59~12 ~39~59~13 minecraft:concrete 7
fill ~40~24~12 ~41~24~13 minecraft:concrete 0
fill ~40~30~12 ~40~36~12 minecraft:concrete 7
fill ~40~38~12 ~41~38~12 minecraft:concrete 1
fill ~40~45~12 ~41~45~12 minecraft:wool 7
setblock ~40~47~12 minecraft:concrete 7
setblock ~40~49~12 minecraft:concrete 7
setblock ~40~50~12 minecraft:quartz_block 1
fill ~40~51~12 ~41~51~12 minecraft:stained_glass 3
setblock ~40~52~12 minecraft:stained_glass 3
setblock ~40~53~12 minecraft:quartz_block 1
fill ~40~54~12 ~40~54~13 minecraft:concrete 7
setblock ~40~55~12 minecraft:wool 7
fill ~40~58~12 ~40~58~13 minecraft:concrete 7
fill ~41~23~12 ~41~23~13 minecraft:concrete 0
setblock ~41~28~12 minecraft:concrete 7
fill ~41~29~12 ~43~29~12 minecraft:concrete 0
fill ~41~30~12 ~42~30~12 minecraft:concrete 1
fill ~41~32~12 ~41~34~13 minecraft:concrete 7
setblock ~41~37~12 minecraft:concrete 7
setblock ~41~44~12 minecraft:wool 7
fill ~41~47~12 ~41~49~13 minecraft:quartz_block 1
fill ~41~50~12 ~42~50~12 minecraft:stained_glass 3
setblock ~41~52~12 minecraft:quartz_block 1
fill ~41~53~12 ~41~53~13 minecraft:concrete 7
fill ~41~55~12 ~41~55~14 minecraft:concrete 7
fill ~42~21~12 ~42~21~21 minecraft:concrete 0
fill ~42~28~12 ~45~28~12 minecraft:concrete 0
setblock ~42~31~12 minecraft:concrete 1
fill ~42~32~12 ~42~33~12 minecraft:hardened_clay
fill ~42~34~12 ~42~35~12 minecraft:concrete 4
fill ~42~37~12 ~43~37~12 minecraft:concrete 4
fill ~42~38~12 ~44~38~12 minecraft:stained_hardened_clay 1
fill ~42~39~12 ~43~39~12 minecraft:concrete 7
fill ~42~40~12 ~42~41~13 minecraft:concrete 0
fill ~42~44~12 ~42~44~13 minecraft:concrete 0
setblock ~42~47~12 minecraft:concrete 7
fill ~42~49~12 ~42~49~14 minecraft:quartz_block 1
fill ~42~51~12 ~42~51~13 minecraft:quartz_block 1
fill ~42~52~12 ~42~52~13 minecraft:concrete 7
fill ~42~55~12 ~43~55~12 minecraft:wool 7
setblock ~43~22~12 minecraft:concrete 0
fill ~43~27~12 ~45~27~12 minecraft:concrete 0
fill ~43~30~12 ~45~30~12 minecraft:concrete 0
setblock ~43~31~12 minecraft:hardened_clay
fill ~43~32~12 ~44~32~12 minecraft:wool 7
setblock ~43~40~12 minecraft:concrete 7
fill ~43~51~12 ~43~51~13 minecraft:concrete 7
fill ~43~54~12 ~44~54~12 minecraft:wool 7
fill ~44~23~12 ~44~23~13 minecraft:concrete 0
setblock ~44~24~12 minecraft:concrete 0
fill ~44~31~12 ~44~31~13 minecraft:concrete 0
fill ~44~49~12 ~45~49~12 minecraft:concrete 7
setblock ~44~50~12 minecraft:concrete 7
fill ~45~25~12 ~45~26~15 minecraft:concrete 0
setblock ~45~29~12 minecraft:concrete 0
fill ~8~54~13 ~9~54~14 minecraft:quartz_block 1
fill ~9~51~13 ~9~52~13 minecraft:stained_glass 3
setblock ~9~53~13 minecraft:quartz_block 1
fill ~9~55~13 ~9~55~16 minecraft:wool 7
setblock ~10~50~13 minecraft:stained_glass 3
setblock ~11~49~13 minecraft:stained_glass 3
fill ~12~48~13 ~12~48~14 minecraft:quartz_block 1
fill ~12~63~13 ~12~63~23 minecraft:wool 7
fill ~12~64~13 ~12~64~15 minecraft:anvil 2
fill ~12~65~13 ~12~65~15 minecraft:stone_block_slab 0
fill ~13~57~13 ~13~62~13 minecraft:concrete 0
setblock ~14~62~13 minecraft:concrete 0
fill ~15~45~13 ~15~45~24 minecraft:concrete 7
setblock ~15~57~13 minecraft:stone 4
fill ~15~58~13 ~15~59~13 minecraft:stained_glass 3
fill ~15~60~13 ~15~62~13 minecraft:stone 4
fill ~15~63~13 ~15~63~14 minecraft:wool 7
fill ~16~62~13 ~17~62~13 minecraft:concrete 0
fill ~16~63~13 ~16~63~41 minecraft:planks 2
fill ~18~42~13 ~18~42~26 minecraft:concrete 7
fill ~19~41~13 ~19~41~15 minecraft:concrete 7
fill ~20~45~13 ~20~45~18 minecraft:concrete 7
fill ~22~39~13 ~23~39~14 minecraft:concrete 7
fill ~23~38~13 ~24~38~13 minecraft:concrete 7
setblock ~23~40~13 minecraft:concrete 7
fill ~28~35~13 ~28~35~17 minecraft:concrete 7
fill ~28~36~13 ~28~36~15 minecraft:concrete 7
setblock ~28~37~13 minecraft:concrete 7
fill ~29~34~13 ~29~34~15 minecraft:concrete 7
fill ~30~33~13 ~31~33~14 minecraft:concrete 7
setblock ~30~35~13 minecraft:concrete 7
fill ~31~64~13 ~33~64~13 minecraft:anvil 3
fill ~31~65~13 ~33~65~13 minecraft:stone_block_slab 0
fill ~32~31~13 ~32~31~17 minecraft:concrete 7
fill ~32~32~13 ~32~32~14 minecraft:concrete 7
fill ~32~62~13 ~32~62~17 minecraft:stone_block_slab 14
fill ~33~57~13 ~33~59~13 minecraft:stone 4
fill ~33~61~13 ~35~61~13 minecraft:concrete 0
fill ~33~62~13 ~34~62~13 minecraft:concrete 0
fill ~34~28~13 ~34~28~15 minecraft:concrete 4
fill ~34~29~13 ~35~29~13 minecraft:concrete 4
setblock ~34~30~13 minecraft:concrete 4
fill ~34~57~13 ~34~60~13 minecraft:concrete 0
setblock ~35~27~13 minecraft:hardened_clay
fill ~35~60~13 ~35~60~14 minecraft:concrete 0
setblock ~36~26~13 minecraft:wool 7
fill ~36~27~13 ~37~27~13 minecraft:concrete 0
fill ~36~28~13 ~37~29~13 minecraft:concrete 7
fill ~36~59~13 ~36~59~14 minecraft:concrete 0
setblock ~36~61~13 minecraft:concrete 7
setblock ~37~26~13 minecraft:concrete 0
setblock ~37~60~13 minecraft:concrete 7
fill ~38~25~13 ~38~25~15 minecraft:concrete 0
fill ~38~47~13 ~39~47~26 minecraft:concrete 0
setblock ~38~59~13 minecraft:concrete 7
fill ~39~24~13 ~39~24~15 minecraft:concrete 0
setblock ~39~58~13 minecraft:concrete 7
fill ~40~22~13 ~41~22~13 minecraft:concrete 0
fill ~40~23~13 ~40~23~14 minecraft:concrete 0
fill ~40~45~13 ~41~45~13 minecraft:concrete 0
setblock ~40~46~13 minecraft:concrete 7
setblock ~40~47~13 minecraft:quartz_block 1
setblock ~40~53~13 minecraft:concrete 7
fill ~40~55~13 ~40~55~14 minecraft:concrete 7
setblock ~40~57~13 minecraft:concrete 7
setblock ~41~40~13 minecraft:concrete 0
setblock ~41~44~13 minecraft:concrete 0
fill ~41~46~13 ~44~46~13 minecraft:wool 7
setblock ~41~52~13 minecraft:concrete 7
fill ~41~54~13 ~42~54~13 minecraft:concrete 7
fill ~41~56~13 ~41~56~14 minecraft:concrete 7
setblock ~41~57~13 minecraft:anvil 3
setblock ~41~58~13 minecraft:stone_block_slab 0
setblock ~42~29~13 minecraft:concrete 7
fill ~42~30~13 ~42~31~13 minecraft:concrete 0
fill ~42~32~13 ~42~33~13 minecraft:concrete 1
fill ~42~34~13 ~42~36~14 minecraft:concrete 7
fill ~42~37~13 ~43~37~13 minecraft:concrete 7
fill ~42~38~13 ~43~38~13 minecraft:concrete 1
fill ~42~39~13 ~43~39~13 minecraft:concrete 0
fill ~42~42~13 ~43~43~13 minecraft:concrete 0
fill ~42~45~13 ~44~45~13 minecraft:wool 7
setblock ~42~47~13 minecraft:wool 7
fill ~42~50~13 ~44~50~13 minecraft:quartz_block 1
fill ~42~53~13 ~44~53~13 minecraft:concrete 7
fill ~42~55~13 ~43~55~14 minecraft:concrete 0
fill ~43~21~13 ~43~21~20 minecraft:concrete 0
fill ~43~31~13 ~43~32~13 minecraft:concrete 0
fill ~43~33~13 ~43~34~13 minecraft:hardened_clay
setblock ~43~35~13 minecraft:stained_hardened_clay 1
setblock ~43~36~13 minecraft:concrete 4
fill ~43~40~13 ~44~40~13 minecraft:concrete 0
setblock ~43~41~13 minecraft:concrete 0
fill ~43~44~13 ~44~44~13 minecraft:wool 7
fill ~43~47~13 ~45~47~13 minecraft:concrete 7
fill ~43~49~13 ~44~49~14 minecraft:quartz_block 1
fill ~43~52~13 ~44~52~13 minecraft:concrete 7
fill ~43~54~13 ~44~54~14 minecraft:concrete 0
fill ~44~22~13 ~44~22~18 minecraft:concrete 0
fill ~44~27~13 ~46~27~14 minecraft:concrete 0
fill ~44~30~13 ~46~30~13 minecraft:concrete 0
fill ~44~32~13 ~45~32~13 minecraft:concrete 0
fill ~44~33~13 ~44~34~13 minecraft:concrete 7
setblock ~44~35~13 minecraft:hardened_clay
fill ~44~36~13 ~45~36~14 minecraft:stained_hardened_clay 1
setblock ~44~37~13 minecraft:concrete 4
setblock ~44~38~13 minecraft:stained_hardened_clay 1
fill ~44~39~13 ~45~39~13 minecraft:concrete 7
fill ~44~51~13 ~45~51~13 minecraft:concrete 7
setblock ~44~55~13 minecraft:wool 7
fill ~45~24~13 ~45~24~15 minecraft:concrete 0
fill ~45~31~13 ~45~31~14 minecraft:concrete 0
fill ~45~33~13 ~45~33~15 minecraft:concrete 0
setblock ~45~37~13 minecraft:stained_hardened_clay 1
setblock ~45~38~13 minecraft:concrete 7
fill ~45~48~13 ~45~50~14 minecraft:concrete 7
fill ~45~52~13 ~46~52~13 minecraft:wool 7
setblock ~45~53~13 minecraft:wool 7
fill ~46~25~13 ~46~26~15 minecraft:concrete 0
fill ~46~28~13 ~47~29~13 minecraft:concrete 0
setblock ~46~34~13 minecraft:concrete 7
fill ~46~45~13 ~46~45~14 minecraft:wool 7
fill ~47~46~13 ~47~46~14 minecraft:wool 7
fill ~48~47~13 ~48~47~14 minecraft:wool 7
setblock ~8~53~14 minecraft:quartz_block 1
fill ~9~51~14 ~9~52~14 minecraft:quartz_block 1
setblock ~10~50~14 minecraft:quartz_block 1
setblock ~11~49~14 minecraft:quartz_block 1
fill ~13~60~14 ~13~62~14 minecraft:concrete 0
fill ~14~57~14 ~14~57~17 minecraft:stone 4
fill ~14~58~14 ~14~60~15 minecraft:stone 4
setblock ~14~61~14 minecraft:stone 4
fill ~14~62~14 ~14~62~15 minecraft:stone 3
fill ~15~42~14 ~16~42~14 minecraft:concrete 4
fill ~15~43~14 ~15~43~15 minecraft:concrete 4
fill ~15~62~14 ~16~62~14 minecraft:concrete 0
fill ~16~43~14 ~16~43~26 minecraft:concrete 7
fill ~17~41~14 ~17~41~15 minecraft:concrete 4
fill ~17~42~14 ~17~42~26 minecraft:concrete 7
fill ~18~41~14 ~18~41~26 minecraft:concrete 7
setblock ~19~44~14 minecraft:concrete 7
setblock ~20~41~14 minecraft:concrete 7
fill ~21~39~14 ~21~39~15 minecraft:concrete 7
setblock ~21~40~14 minecraft:concrete 7
fill ~21~45~14 ~22~45~14 minecraft:concrete 7
fill ~22~38~14 ~23~38~15 minecraft:concrete 7
fill ~24~37~14 ~24~37~18 minecraft:concrete 7
fill ~26~36~14 ~27~36~18 minecraft:concrete 7
fill ~27~35~14 ~27~35~18 minecraft:concrete 7
fill ~28~34~14 ~28~34~19 minecraft:concrete 7
fill ~29~63~14 ~30~63~43 minecraft:planks 2
fill ~31~31~14 ~31~31~23 minecraft:concrete 7
fill ~31~32~14 ~31~32~17 minecraft:concrete 7
fill ~31~63~14 ~31~63~16 minecraft:stone_block_slab 6
fill ~33~28~14 ~33~28~18 minecraft:concrete 4
fill ~33~29~14 ~34~29~14 minecraft:concrete 4
setblock ~33~30~14 minecraft:concrete 4
fill ~33~58~14 ~33~58~17 minecraft:concrete 0
fill ~33~60~14 ~34~61~14 minecraft:concrete 0
fill ~33~62~14 ~33~62~16 minecraft:stone_block_slab 6
setblock ~34~26~14 minecraft:stone_block_slab 8
setblock ~34~27~14 minecraft:stained_hardened_clay 1
fill ~34~30~14 ~34~30~16 minecraft:concrete 7
fill ~34~57~14 ~34~59~15 minecraft:stone 4
setblock ~35~26~14 minecraft:wool 7
fill ~35~27~14 ~35~27~17 minecraft:concrete 7
fill ~35~29~14 ~36~29~15 minecraft:concrete 7
fill ~35~61~14 ~36~61~14 minecraft:stone_block_slab 6
fill ~36~26~14 ~36~26~15 minecraft:concrete 0
setblock ~36~27~14 minecraft:concrete 0
setblock ~36~28~14 minecraft:concrete 7
setblock ~36~30~14 minecraft:concrete 7
setblock ~36~60~14 minecraft:concrete 0
fill ~37~24~14 ~38~24~15 minecraft:concrete 0
fill ~37~25~14 ~37~25~15 minecraft:concrete 0
fill ~37~58~14 ~38~58~14 minecraft:concrete 0
setblock ~37~59~14 minecraft:concrete 0
setblock ~37~60~14 minecraft:double_stone_block_slab 6
fill ~38~23~14 ~39~23~15 minecraft:concrete 0
fill ~38~57~14 ~39~57~14 minecraft:concrete 0
fill ~38~59~14 ~39~59~14 minecraft:stone_block_slab 14
setblock ~38~60~14 minecraft:stone_block_slab 6
fill ~39~22~14 ~40~22~14 minecraft:concrete 0
fill ~40~21~14 ~41~21~20 minecraft:concrete 0
setblock ~40~24~14 minecraft:concrete 0
fill ~40~47~14 ~40~47~26 minecraft:concrete 0
fill ~40~56~14 ~40~56~26 minecraft:concrete 0
fill ~40~59~14 ~40~59~15 minecraft:stone_block_slab 6
fill ~41~46~14 ~42~46~14 minecraft:concrete 7
setblock ~41~47~14 minecraft:concrete 7
setblock ~41~54~14 minecraft:concrete 7
setblock ~41~57~14 minecraft:concrete 0
fill ~41~58~14 ~42~58~14 minecraft:concrete 7
setblock ~41~59~14 minecraft:concrete 7
fill ~42~45~14 ~43~45~14 minecraft:concrete 0
fill ~42~47~14 ~44~48~14 minecraft:quartz_block 1
fill ~42~56~14 ~43~56~15 minecraft:concrete 7
fill ~42~57~14 ~43~57~14 minecraft:anvil 3
setblock ~43~32~14 minecraft:concrete 7
fill ~43~33~14 ~44~33~14 minecraft:concrete 0
fill ~43~34~14 ~43~35~14 minecraft:concrete 1
setblock ~43~36~14 minecraft:concrete 7
fill ~43~43~14 ~45~43~14 minecraft:concrete 0
fill ~43~44~14 ~44~44~14 minecraft:concrete 0
fill ~43~46~14 ~46~46~14 minecraft:wool 7
fill ~43~50~14 ~44~50~14 minecraft:quartz_block 1
setblock ~43~58~14 minecraft:stone_block_slab 0
fill ~44~21~14 ~44~21~18 minecraft:concrete 0
setblock ~44~34~14 minecraft:concrete 0
setblock ~44~35~14 minecraft:concrete 1
fill ~44~37~14 ~46~37~14 minecraft:concrete 7
fill ~44~38~14 ~45~42~14 minecraft:concrete 0
fill ~44~45~14 ~45~45~14 minecraft:wool 7
fill ~44~53~14 ~46~53~14 minecraft:concrete 0
fill ~44~55~14 ~44~55~15 minecraft:concrete 0
fill ~45~23~14 ~45~23~17 minecraft:concrete 0
fill ~45~30~14 ~50~30~14 minecraft:concrete 0
fill ~45~32~14 ~49~32~14 minecraft:concrete 0
setblock ~45~34~14 minecraft:concrete 7
setblock ~45~35~14 minecraft:stained_hardened_clay 1
fill ~45~44~14 ~46~44~14 minecraft:wool 7
setblock ~45~47~14 minecraft:concrete 7
fill ~45~51~14 ~46~51~14 minecraft:concrete 7
fill ~45~52~14 ~46~52~14 minecraft:concrete 0
fill ~45~55~14 ~45~55~15 minecraft:wool 7
fill ~46~31~14 ~50~31~14 minecraft:concrete 0
fill ~46~33~14 ~47~33~15 minecraft:concrete 0
fill ~46~34~14 ~46~34~15 minecraft:concrete 0
fill ~46~35~14 ~46~36~14 minecraft:concrete 7
setblock ~46~38~14 minecraft:concrete 7
fill ~46~39~14 ~46~42~14 minecraft:concrete 0
fill ~46~49~14 ~47~49~14 minecraft:concrete 7
setblock ~46~50~14 minecraft:concrete 7
fill ~47~23~14 ~50~23~14 minecraft:stone_block_slab 8
fill ~47~25~14 ~50~27~14 minecraft:concrete 0
setblock ~47~36~14 minecraft:concrete 7
fill ~47~45~14 ~47~45~15 minecraft:wool 7
fill ~47~48~14 ~48~48~14 minecraft:concrete 7
fill ~47~50~14 ~47~51~14 minecraft:wool 7
fill ~48~28~14 ~50~29~14 minecraft:concrete 0
setblock ~48~46~14 minecraft:wool 7
setblock ~48~49~14 minecraft:wool 7
fill ~49~47~14 ~49~48~14 minecraft:wool 7
fill ~7~52~15 ~9~52~15 minecraft:concrete 7
fill ~7~53~15 ~8~54~15 minecraft:concrete 7
fill ~8~51~15 ~9~51~15 minecraft:concrete 7
setblock ~8~55~15 minecraft:concrete 7
fill ~9~50~15 ~10~50~15 minecraft:concrete 7
fill ~10~49~15 ~11~49~15 minecraft:concrete 7
fill ~11~48~15 ~12~48~15 minecraft:concrete 7
fill ~13~44~15 ~14~44~20 minecraft:concrete 4
fill ~13~61~15 ~13~62~15 minecraft:concrete 0
setblock ~14~43~15 minecraft:concrete 4
setblock ~14~61~15 minecraft:stone 3
fill ~15~41~15 ~16~41~15 minecraft:concrete 4
setblock ~15~42~15 minecraft:concrete 4
fill ~15~44~15 ~15~44~26 minecraft:concrete 7
fill ~15~63~15 ~15~63~39 minecraft:planks 2
fill ~16~40~15 ~19~40~15 minecraft:concrete 4
fill ~16~42~15 ~16~42~26 minecraft:concrete 7
setblock ~16~62~15 minecraft:concrete 0
setblock ~19~39~15 minecraft:concrete 4
setblock ~19~42~15 minecraft:concrete 7
fill ~19~45~15 ~19~45~20 minecraft:concrete 7
setblock ~20~38~15 minecraft:concrete 4
fill ~20~39~15 ~20~40~16 minecraft:concrete 7
fill ~21~37~15 ~23~37~15 minecraft:concrete 4
fill ~21~38~15 ~21~38~26 minecraft:concrete 7
fill ~21~45~15 ~21~45~16 minecraft:concrete 7
fill ~25~36~15 ~25~36~26 minecraft:concrete 7
fill ~25~37~15 ~25~37~17 minecraft:concrete 7
setblock ~26~35~15 minecraft:concrete 7
fill ~30~33~15 ~30~33~17 minecraft:concrete 7
fill ~32~28~15 ~32~28~19 minecraft:concrete 4
fill ~33~30~15 ~33~30~19 minecraft:concrete 7
fill ~33~57~15 ~33~57~17 minecraft:concrete 0
fill ~33~59~15 ~33~61~17 minecraft:concrete 0
setblock ~34~26~15 minecraft:wool 7
setblock ~34~27~15 minecraft:hardened_clay
fill ~34~61~15 ~34~61~16 minecraft:stone_block_slab 14
fill ~35~25~15 ~36~25~16 minecraft:concrete 0
fill ~35~26~15 ~35~26~20 minecraft:concrete 0
fill ~35~28~15 ~35~28~16 minecraft:concrete 7
fill ~35~57~15 ~36~57~15 minecraft:stone 4
fill ~35~58~15 ~35~59~15 minecraft:stained_glass 3
fill ~35~61~15 ~35~61~16 minecraft:stone_block_slab 6
fill ~36~24~15 ~36~24~16 minecraft:concrete 0
setblock ~36~58~15 minecraft:stone 4
fill ~36~60~15 ~36~60~16 minecraft:stone_block_slab 14
fill ~37~23~15 ~37~23~16 minecraft:concrete 0
setblock ~37~57~15 minecraft:concrete 0
fill ~37~59~15 ~38~59~15 minecraft:stone_block_slab 14
fill ~37~60~15 ~37~60~16 minecraft:stone_block_slab 6
fill ~38~22~15 ~39~22~15 minecraft:concrete 0
fill ~39~21~15 ~39~21~22 minecraft:concrete 0
setblock ~39~25~15 minecraft:concrete 0
setblock ~39~59~15 minecraft:double_stone_block_slab 6
setblock ~40~58~15 minecraft:stone_block_slab 14
fill ~41~47~15 ~43~47~26 minecraft:concrete 0
fill ~41~56~15 ~41~56~26 minecraft:concrete 0
fill ~41~57~15 ~41~57~17 minecraft:double_stone_block_slab 6
setblock ~41~58~15 minecraft:double_stone_block_slab 6
fill ~42~57~15 ~43~57~15 minecraft:concrete 0
setblock ~42~58~15 minecraft:stone_block_slab 6
setblock ~43~55~15 minecraft:concrete 0
setblock ~43~58~15 minecraft:concrete 7
setblock ~44~34~15 minecraft:concrete 7
fill ~44~35~15 ~48~35~15 minecraft:concrete 0
setblock ~44~36~15 minecraft:concrete 1
fill ~44~45~15 ~46~45~15 minecraft:concrete 0
fill ~44~46~15 ~44~47~15 minecraft:concrete 7
fill ~44~54~15 ~46~54~15 minecraft:concrete 0
fill ~44~56~15 ~44~56~16 minecraft:concrete 7
setblock ~44~57~15 minecraft:anvil 3
setblock ~44~58~15 minecraft:stone_block_slab 0
fill ~45~22~15 ~46~22~15 minecraft:stone_block_slab 8
setblock ~45~34~15 minecraft:concrete 0
fill ~45~36~15 ~47~36~15 minecraft:concrete 0
setblock ~45~37~15 minecraft:concrete 7
fill ~45~43~15 ~48~44~15 minecraft:concrete 0
fill ~45~46~15 ~46~46~15 minecraft:wool 7
fill ~45~47~15 ~47~47~15 minecraft:quartz_block 1
fill ~45~48~15 ~46~48~15 minecraft:quartz_block 1
fill ~46~23~15 ~46~23~16 minecraft:concrete 0
fill ~46~24~15 ~50~24~15 minecraft:concrete 0
fill ~46~32~15 ~53~32~15 minecraft:concrete 0
fill ~46~37~15 ~46~38~15 minecraft:concrete 0
fill ~46~41~15 ~47~42~15 minecraft:concrete 0
fill ~46~50~15 ~48~50~15 minecraft:concrete 0
fill ~46~51~15 ~47~51~15 minecraft:concrete 0
fill ~46~53~15 ~46~53~16 minecraft:concrete 0
fill ~46~55~15 ~46~55~16 minecraft:wool 7
fill ~47~23~15 ~50~23~15 minecraft:wool 7
fill ~47~34~15 ~50~34~15 minecraft:concrete 0
fill ~47~37~15 ~49~37~15 minecraft:concrete 7
fill ~47~38~15 ~47~38~16 minecraft:concrete 0
fill ~47~39~15 ~47~40~15 minecraft:concrete 0
fill ~47~46~15 ~49~46~15 minecraft:concrete 0
fill ~47~49~15 ~48~49~15 minecraft:concrete 0
fill ~47~52~15 ~47~52~17 minecraft:concrete 0
fill ~48~33~15 ~52~33~15 minecraft:concrete 0
fill ~48~36~15 ~50~36~15 minecraft:concrete 7
setblock ~48~38~15 minecraft:concrete 7
fill ~48~42~15 ~48~42~16 minecraft:concrete 0
fill ~48~45~15 ~49~45~15 minecraft:concrete 0
fill ~48~47~15 ~48~48~15 minecraft:concrete 7
fill ~49~31~15 ~53~31~15 minecraft:concrete 0
fill ~49~44~15 ~49~44~16 minecraft:concrete 0
fill ~49~47~15 ~49~47~26 minecraft:concrete 0
fill ~49~48~15 ~49~48~17 minecraft:concrete 0
fill ~51~25~15 ~51~25~16 minecraft:concrete 0
fill ~51~26~15 ~51~30~15 minecraft:concrete 0
fill ~52~28~15 ~52~28~16 minecraft:concrete 0
fill ~52~29~15 ~53~30~15 minecraft:concrete 0
fill ~7~56~16 ~7~56~20 minecraft:stone_block_slab 0
fill ~8~53~16 ~8~54~19 minecraft:quartz_block 1
fill ~8~55~16 ~8~55~21 minecraft:wool 7
fill ~8~56~16 ~8~56~20 minecraft:concrete 7
fill ~8~57~16 ~8~57~20 minecraft:anvil 2
fill ~8~58~16 ~8~58~20 minecraft:stone_block_slab 0
fill ~9~51~16 ~9~52~16 minecraft:quartz_block 1
fill ~9~56~16 ~9~56~26 minecraft:concrete 0
setblock ~10~50~16 minecraft:quartz_block 1
fill ~11~47~16 ~11~47~18 minecraft:concrete 7
setblock ~11~49~16 minecraft:quartz_block 1
fill ~11~63~16 ~11~63~38 minecraft:wool 7
fill ~11~64~16 ~11~64~17 minecraft:anvil 2
fill ~11~65~16 ~11~65~17 minecraft:stone_block_slab 0
fill ~12~47~16 ~12~48~18 minecraft:quartz_block 1
fill ~12~62~16 ~12~62~18 minecraft:concrete 0
fill ~13~45~16 ~13~45~19 minecraft:stone_block_slab 8
fill ~13~46~16 ~13~46~19 minecraft:wool 7
fill ~13~47~16 ~13~47~26 minecraft:concrete 0
setblock ~13~62~16 minecraft:wool 7
fill ~14~58~16 ~14~60~17 minecraft:stained_glass 3
fill ~14~61~16 ~14~62~16 minecraft:stone 4
fill ~15~43~16 ~15~43~26 minecraft:concrete 7
fill ~17~40~16 ~18~40~16 minecraft:concrete 4
fill ~17~41~16 ~17~41~26 minecraft:concrete 7
fill ~17~43~16 ~17~43~26 minecraft:concrete 7
setblock ~18~39~16 minecraft:concrete 4
fill ~18~45~16 ~18~45~22 minecraft:concrete 7
setblock ~19~38~16 minecraft:concrete 4
fill ~19~39~16 ~19~40~26 minecraft:concrete 7
fill ~20~37~16 ~22~37~16 minecraft:concrete 4
fill ~20~38~16 ~20~38~26 minecraft:concrete 7
fill ~22~36~16 ~24~36~16 minecraft:concrete 4
fill ~22~38~16 ~22~38~17 minecraft:concrete 7
fill ~23~37~16 ~23~37~26 minecraft:concrete 7
fill ~25~35~16 ~26~35~16 minecraft:concrete 4
fill ~26~34~16 ~27~34~17 minecraft:concrete 4
fill ~28~33~16 ~28~33~19 minecraft:concrete 4
fill ~29~33~16 ~29~33~20 minecraft:concrete 7
fill ~30~32~16 ~30~32~18 minecraft:concrete 7
setblock ~32~26~16 minecraft:stone_block_slab 8
setblock ~33~26~16 minecraft:wool 7
fill ~34~25~16 ~34~26~16 minecraft:hardened_clay
fill ~34~27~16 ~34~27~17 minecraft:stained_hardened_clay 1
fill ~34~28~16 ~34~29~19 minecraft:concrete 7
fill ~35~24~16 ~35~24~17 minecraft:concrete 0
setblock ~35~29~16 minecraft:concrete 7
fill ~36~23~16 ~36~23~17 minecraft:concrete 0
fill ~37~22~16 ~38~22~16 minecraft:concrete 0
setblock ~37~24~16 minecraft:concrete 0
fill ~37~59~16 ~37~59~17 minecraft:stone_block_slab 14
setblock ~38~23~16 minecraft:concrete 0
setblock ~38~59~16 minecraft:double_stone_block_slab 6
setblock ~39~58~16 minecraft:stone_block_slab 14
setblock ~39~59~16 minecraft:stone_block_slab 6
setblock ~40~58~16 minecraft:double_stone_block_slab 6
setblock ~41~58~16 minecraft:stone_block_slab 6
fill ~42~56~16 ~42~56~26 minecraft:concrete 0
setblock ~42~57~16 minecraft:double_stone_block_slab 6
setblock ~43~56~16 minecraft:concrete 7
setblock ~43~57~16 minecraft:stone_block_slab 6
setblock ~44~20~16 minecraft:wool 7
fill ~44~47~16 ~48~47~26 minecraft:concrete 0
setblock ~44~57~16 minecraft:concrete 7
fill ~45~22~16 ~46~22~16 minecraft:wool 7
fill ~45~35~16 ~45~36~16 minecraft:concrete 7
setblock ~45~55~16 minecraft:concrete 0
fill ~45~56~16 ~45~56~17 minecraft:concrete 7
setblock ~45~57~16 minecraft:anvil 3
setblock ~45~58~16 minecraft:stone_block_slab 0
setblock ~46~36~16 minecraft:concrete 7
fill ~46~54~16 ~47~54~16 minecraft:concrete 0
setblock ~47~23~16 minecraft:concrete 7
fill ~47~34~16 ~47~37~16 minecraft:concrete 0
fill ~47~43~16 ~49~43~16 minecraft:concrete 0
fill ~47~44~16 ~48~45~16 minecraft:concrete 0
setblock ~47~46~16 minecraft:concrete 7
fill ~47~51~16 ~48~51~16 minecraft:concrete 0
fill ~47~53~16 ~47~53~17 minecraft:concrete 0
fill ~47~55~16 ~48~55~16 minecraft:wool 7
fill ~48~23~16 ~50~24~16 minecraft:concrete 0
fill ~48~35~16 ~51~35~16 minecraft:concrete 0
fill ~48~36~16 ~50~36~16 minecraft:concrete 0
fill ~48~37~16 ~49~37~16 minecraft:concrete 0
fill ~48~38~16 ~48~41~16 minecraft:concrete 0
fill ~48~48~16 ~48~50~16 minecraft:concrete 0
fill ~48~52~16 ~48~52~17 minecraft:concrete 0
fill ~49~34~16 ~53~34~16 minecraft:concrete 0
fill ~49~38~16 ~50~38~16 minecraft:concrete 7
fill ~49~41~16 ~49~42~16 minecraft:concrete 0
fill ~49~49~16 ~49~50~17 minecraft:concrete 0
setblock ~50~33~16 minecraft:concrete 0
fill ~50~37~16 ~51~37~16 minecraft:concrete 7
fill ~50~44~16 ~50~48~16 minecraft:concrete 0
fill ~51~23~16 ~52~23~16 minecraft:stone_block_slab 8
fill ~51~36~16 ~52~36~16 minecraft:concrete 7
fill ~51~45~16 ~51~47~17 minecraft:concrete 0
fill ~52~26~16 ~52~27~16 minecraft:concrete 0
fill ~52~33~16 ~55~33~16 minecraft:concrete 0
fill ~53~24~16 ~55~24~16 minecraft:stone_block_slab 8
fill ~53~28~16 ~53~29~16 minecraft:concrete 0
fill ~53~32~16 ~55~32~16 minecraft:concrete 0
fill ~54~29~16 ~54~29~17 minecraft:concrete 0
fill ~54~30~16 ~55~31~16 minecraft:concrete 0
fill ~8~52~17 ~8~52~18 minecraft:stained_glass 3
fill ~9~51~17 ~9~51~18 minecraft:stained_glass 3
fill ~10~50~17 ~10~50~18 minecraft:stained_glass 3
fill ~11~49~17 ~11~49~18 minecraft:stained_glass 3
setblock ~12~61~17 minecraft:concrete 0
fill ~14~45~17 ~14~45~24 minecraft:concrete 7
setblock ~14~61~17 minecraft:stained_glass 3
setblock ~14~62~17 minecraft:stone 4
fill ~18~40~17 ~18~40~26 minecraft:concrete 7
setblock ~18~43~17 minecraft:concrete 7
setblock ~23~36~17 minecraft:concrete 4
fill ~24~35~17 ~25~35~17 minecraft:concrete 4
fill ~24~36~17 ~24~36~26 minecraft:concrete 7
setblock ~25~34~17 minecraft:concrete 4
fill ~26~33~17 ~27~33~17 minecraft:concrete 4
fill ~26~35~17 ~26~35~22 minecraft:concrete 7
fill ~28~32~17 ~29~32~17 minecraft:concrete 4
fill ~29~31~17 ~29~31~20 minecraft:concrete 4
fill ~30~30~17 ~32~30~17 minecraft:concrete 4
fill ~30~31~17 ~30~31~26 minecraft:concrete 7
fill ~31~63~17 ~32~63~22 minecraft:planks 2
fill ~31~64~17 ~32~64~17 minecraft:anvil 1
fill ~31~65~17 ~32~65~17 minecraft:stone_block_slab 0
fill ~33~25~17 ~33~26~17 minecraft:hardened_clay
fill ~33~27~17 ~33~27~23 minecraft:stained_hardened_clay 1
fill ~33~62~17 ~35~62~17 minecraft:concrete 0
fill ~33~63~17 ~35~63~17 minecraft:concrete 7
fill ~34~24~17 ~34~26~21 minecraft:concrete 0
fill ~34~57~17 ~36~61~17 minecraft:concrete 0
fill ~35~22~17 ~36~22~17 minecraft:concrete 0
setblock ~35~23~17 minecraft:concrete 0
setblock ~35~25~17 minecraft:concrete 0
setblock ~36~62~17 minecraft:concrete 7
fill ~37~21~17 ~38~21~23 minecraft:concrete 0
fill ~38~58~17 ~38~58~18 minecraft:stone_block_slab 14
setblock ~38~59~17 minecraft:stone_block_slab 6
setblock ~39~58~17 minecraft:double_stone_block_slab 6
setblock ~40~57~17 minecraft:stone_block_slab 14
setblock ~40~58~17 minecraft:stone_block_slab 6
setblock ~42~57~17 minecraft:stone_block_slab 6
setblock ~43~20~17 minecraft:wool 7
fill ~43~56~17 ~44~56~37 minecraft:concrete 0
fill ~44~20~17 ~44~20~18 minecraft:concrete 0
setblock ~44~23~17 minecraft:concrete 0
fill ~45~17~17 ~45~17~21 minecraft:concrete 0
fill ~45~18~17 ~46~19~17 minecraft:concrete 0
fill ~45~20~17 ~45~21~17 minecraft:concrete 7
setblock ~45~22~17 minecraft:concrete 0
fill ~46~20~17 ~50~20~17 minecraft:concrete 0
fill ~46~21~17 ~47~22~17 minecraft:concrete 7
fill ~46~55~17 ~47~55~17 minecraft:concrete 0
fill ~46~56~17 ~48~56~17 minecraft:concrete 7
fill ~46~57~17 ~48~57~17 minecraft:anvil 3
fill ~46~58~17 ~48~58~17 minecraft:stone_block_slab 0
fill ~47~19~17 ~47~19~19 minecraft:concrete 0
fill ~47~54~17 ~48~54~17 minecraft:concrete 0
fill ~48~21~17 ~51~21~17 minecraft:concrete 0
fill ~48~22~17 ~51~22~17 minecraft:concrete 7
fill ~48~49~17 ~48~51~17 minecraft:concrete 0
setblock ~48~53~17 minecraft:concrete 0
fill ~48~55~17 ~49~55~17 minecraft:wool 7
fill ~49~36~17 ~52~36~17 minecraft:concrete 0
fill ~49~37~17 ~51~37~17 minecraft:concrete 0
fill ~49~38~17 ~50~40~17 minecraft:concrete 0
fill ~49~51~17 ~49~52~17 minecraft:concrete 0
fill ~50~23~17 ~51~23~17 minecraft:concrete 7
fill ~50~35~17 ~54~35~17 minecraft:concrete 0
fill ~50~41~17 ~51~43~17 minecraft:concrete 0
fill ~50~47~17 ~50~47~26 minecraft:concrete 0
fill ~50~48~17 ~51~48~17 minecraft:concrete 0
fill ~50~49~17 ~50~49~18 minecraft:concrete 0
setblock ~51~24~17 minecraft:concrete 7
fill ~51~44~17 ~53~44~17 minecraft:concrete 0
setblock ~52~23~17 minecraft:wool 7
fill ~52~25~17 ~54~25~17 minecraft:concrete 0
fill ~52~34~17 ~56~34~17 minecraft:concrete 0
fill ~52~37~17 ~53~37~17 minecraft:concrete 7
fill ~52~42~17 ~52~42~18 minecraft:concrete 0
setblock ~52~43~17 minecraft:concrete 0
fill ~52~45~17 ~53~45~17 minecraft:concrete 0
fill ~52~46~17 ~52~46~18 minecraft:concrete 0
fill ~53~24~17 ~55~24~17 minecraft:wool 7
fill ~53~26~17 ~55~27~17 minecraft:concrete 0
fill ~53~36~17 ~54~36~17 minecraft:concrete 7
fill ~54~28~17 ~57~28~17 minecraft:concrete 0
fill ~54~32~17 ~58~32~17 minecraft:concrete 0
fill ~55~29~17 ~58~30~17 minecraft:concrete 0
fill ~55~33~17 ~58~33~17 minecraft:concrete 0
setblock ~56~25~17 minecraft:stone_block_slab 0
fill ~56~31~17 ~58~31~17 minecraft:concrete 0
fill ~57~25~17 ~58~25~17 minecraft:stone_block_slab 8
fill ~66~45~17 ~75~45~17 minecraft:stone_block_slab 8
fill ~10~63~18 ~10~63~36 minecraft:wool 7
fill ~10~64~18 ~10~64~20 minecraft:anvil 2
fill ~10~65~18 ~10~65~20 minecraft:stone_block_slab 0
fill ~11~48~18 ~11~48~22 minecraft:quartz_block 1
fill ~11~57~18 ~11~62~18 minecraft:concrete 0
setblock ~13~57~18 minecraft:stone 4
fill ~13~58~18 ~13~59~18 minecraft:stained_glass 3
fill ~13~60~18 ~13~62~18 minecraft:stone 4
setblock ~14~62~18 minecraft:stone 3
fill ~14~63~18 ~14~63~36 minecraft:planks 2
fill ~22~37~18 ~22~37~26 minecraft:concrete 7
fill ~23~36~18 ~23~36~26 minecraft:concrete 7
fill ~25~35~18 ~25~35~26 minecraft:concrete 7
fill ~27~34~18 ~27~34~20 minecraft:concrete 7
fill ~28~32~18 ~28~32~20 minecraft:concrete 4
fill ~29~32~18 ~29~32~23 minecraft:concrete 7
fill ~30~30~18 ~31~30~19 minecraft:concrete 4
fill ~31~29~18 ~33~29~18 minecraft:concrete 4
fill ~32~30~18 ~32~30~24 minecraft:concrete 7
fill ~32~57~18 ~32~62~19 minecraft:concrete 0
setblock ~33~62~18 minecraft:concrete 0
fill ~33~63~18 ~34~63~18 minecraft:concrete 7
fill ~33~64~18 ~33~64~23 minecraft:anvil 0
fill ~33~65~18 ~33~65~23 minecraft:stone_block_slab 0
fill ~34~22~18 ~34~23~21 minecraft:concrete 0
fill ~34~27~18 ~34~27~26 minecraft:concrete 7
fill ~35~21~18 ~36~21~25 minecraft:concrete 0
fill ~37~57~18 ~37~60~18 minecraft:concrete 0
setblock ~37~61~18 minecraft:concrete 7
setblock ~39~57~18 minecraft:stone_block_slab 14
setblock ~39~58~18 minecraft:stone_block_slab 6
setblock ~40~57~18 minecraft:double_stone_block_slab 6
fill ~41~20~18 ~42~20~18 minecraft:wool 7
setblock ~41~57~18 minecraft:stone_block_slab 6
fill ~43~19~18 ~44~19~18 minecraft:concrete 0
fill ~43~20~18 ~43~20~19 minecraft:concrete 0
fill ~43~22~18 ~43~22~19 minecraft:concrete 0
fill ~44~17~18 ~44~17~20 minecraft:concrete 0
setblock ~44~18~18 minecraft:concrete 0
fill ~45~56~18 ~46~56~36 minecraft:concrete 0
fill ~46~17~18 ~46~17~21 minecraft:concrete 0
fill ~46~18~18 ~47~18~19 minecraft:concrete 0
fill ~47~56~18 ~49~56~18 minecraft:concrete 7
fill ~48~19~18 ~49~19~19 minecraft:concrete 0
fill ~48~55~18 ~49~55~18 minecraft:concrete 0
fill ~49~53~18 ~49~54~18 minecraft:concrete 0
setblock ~49~57~18 minecraft:anvil 3
setblock ~49~58~18 minecraft:stone_block_slab 0
fill ~50~20~18 ~52~20~19 minecraft:concrete 0
fill ~50~36~18 ~55~36~18 minecraft:concrete 0
fill ~50~50~18 ~50~52~18 minecraft:concrete 0
fill ~50~55~18 ~51~55~18 minecraft:wool 7
fill ~51~37~18 ~53~37~18 minecraft:concrete 0
fill ~51~38~18 ~52~40~18 minecraft:concrete 0
fill ~51~47~18 ~53~47~18 minecraft:concrete 0
fill ~51~48~18 ~52~48~18 minecraft:concrete 0
setblock ~51~49~18 minecraft:concrete 0
fill ~51~50~18 ~52~51~18 minecraft:wool 7
fill ~51~52~18 ~51~54~18 minecraft:wool 7
fill ~52~21~18 ~53~21~18 minecraft:concrete 0
fill ~52~22~18 ~53~24~18 minecraft:concrete 7
fill ~52~41~18 ~53~41~18 minecraft:concrete 0
fill ~52~49~18 ~53~49~18 minecraft:wool 7
setblock ~53~40~18 minecraft:concrete 0
fill ~53~42~18 ~53~44~18 minecraft:concrete 0
fill ~53~46~18 ~54~46~18 minecraft:concrete 0
setblock ~53~48~18 minecraft:wool 7
fill ~54~22~18 ~55~22~18 minecraft:concrete 0
fill ~54~23~18 ~55~24~18 minecraft:concrete 7
fill ~54~35~18 ~58~35~18 minecraft:concrete 0
fill ~54~37~18 ~55~37~18 minecraft:concrete 7
fill ~54~43~18 ~54~45~18 minecraft:concrete 0
setblock ~54~47~18 minecraft:wool 7
setblock ~55~25~18 minecraft:concrete 7
fill ~55~34~18 ~60~34~18 minecraft:concrete 0
setblock ~55~46~18 minecraft:wool 7
fill ~56~25~18 ~58~25~18 minecraft:wool 7
fill ~56~26~18 ~58~27~18 minecraft:concrete 0
fill ~56~33~18 ~60~33~18 minecraft:concrete 0
fill ~56~36~18 ~58~36~18 minecraft:concrete 7
setblock ~56~45~18 minecraft:wool 7
fill ~58~28~18 ~59~28~18 minecraft:concrete 0
setblock ~59~26~18 minecraft:stone_block_slab 0
fill ~59~27~18 ~59~27~19 minecraft:concrete 0
fill ~59~29~18 ~59~32~18 minecraft:concrete 0
fill ~59~35~18 ~60~35~18 minecraft:concrete 7
fill ~60~26~18 ~61~26~18 minecraft:stone_block_slab 8
fill ~60~30~18 ~60~31~19 minecraft:concrete 0
setblock ~60~32~18 minecraft:concrete 0
fill ~61~45~18 ~65~45~18 minecraft:stone_block_slab 8
fill ~66~45~18 ~75~45~19 minecraft:wool 7
fill ~72~35~18 ~73~35~18 minecraft:stone_block_slab 0
fill ~76~45~18 ~83~45~18 minecraft:stone_block_slab 8
setblock ~111~33~18 minecraft:stone_block_slab 8
setblock ~112~34~18 minecraft:stone_block_slab 8
setblock ~112~35~18 minecraft:double_stone_block_slab 0
setblock ~8~52~19 minecraft:quartz_block 1
fill ~9~50~19 ~10~51~19 minecraft:quartz_block 1
fill ~10~47~19 ~10~47~22 minecraft:concrete 7
fill ~10~49~19 ~11~49~19 minecraft:quartz_block 1
fill ~11~47~19 ~11~47~22 minecraft:quartz_block 1
fill ~11~61~19 ~11~62~19 minecraft:concrete 0
fill ~12~45~19 ~12~45~23 minecraft:stone_block_slab 8
fill ~12~46~19 ~12~46~23 minecraft:wool 7
fill ~12~47~19 ~12~47~26 minecraft:concrete 0
fill ~12~57~19 ~12~57~22 minecraft:stone 4
fill ~12~58~19 ~12~60~21 minecraft:stone 4
fill ~17~45~19 ~17~45~26 minecraft:concrete 7
fill ~22~36~19 ~22~36~26 minecraft:concrete 7
fill ~24~34~19 ~26~34~19 minecraft:concrete 4
fill ~24~35~19 ~24~35~26 minecraft:concrete 7
fill ~26~36~19 ~26~36~21 minecraft:concrete 7
setblock ~27~33~19 minecraft:concrete 4
fill ~31~28~19 ~31~28~35 minecraft:concrete 4
setblock ~32~25~19 minecraft:hardened_clay
fill ~32~27~19 ~32~27~20 minecraft:hardened_clay
setblock ~32~29~19 minecraft:concrete 4
setblock ~33~24~19 minecraft:hardened_clay
fill ~33~25~19 ~33~25~35 minecraft:concrete 0
setblock ~33~26~19 minecraft:hardened_clay
fill ~33~28~19 ~33~29~26 minecraft:concrete 7
fill ~33~63~19 ~33~63~37 minecraft:concrete 7
fill ~34~21~19 ~34~21~35 minecraft:concrete 0
fill ~38~57~19 ~38~59~19 minecraft:concrete 0
setblock ~38~60~19 minecraft:concrete 7
setblock ~39~57~19 minecraft:double_stone_block_slab 6
setblock ~40~57~19 minecraft:stone_block_slab 6
setblock ~41~20~19 minecraft:wool 7
fill ~42~19~19 ~43~19~19 minecraft:concrete 0
fill ~42~20~19 ~42~20~21 minecraft:concrete 0
fill ~43~17~19 ~43~17~20 minecraft:concrete 0
setblock ~43~18~19 minecraft:concrete 0
fill ~47~17~19 ~47~17~21 minecraft:concrete 0
fill ~47~56~19 ~48~56~35 minecraft:concrete 0
fill ~48~18~19 ~48~18~20 minecraft:concrete 0
fill ~49~56~19 ~51~56~19 minecraft:concrete 7
fill ~50~19~19 ~50~19~21 minecraft:concrete 0
fill ~50~52~19 ~51~55~19 minecraft:concrete 0
fill ~50~57~19 ~51~57~19 minecraft:anvil 3
fill ~50~58~19 ~51~58~19 minecraft:stone_block_slab 0
fill ~51~47~19 ~52~47~19 minecraft:concrete 0
fill ~51~51~19 ~52~51~19 minecraft:concrete 0
setblock ~52~50~19 minecraft:concrete 0
fill ~52~52~19 ~53~52~20 minecraft:concrete 7
fill ~52~53~19 ~52~53~21 minecraft:concrete 7
setblock ~52~54~19 minecraft:concrete 7
setblock ~52~55~19 minecraft:wool 7
fill ~53~20~19 ~53~20~20 minecraft:concrete 0
fill ~53~38~19 ~57~39~19 minecraft:concrete 0
fill ~53~47~19 ~56~47~19 minecraft:concrete 7
fill ~53~48~19 ~53~49~19 minecraft:concrete 0
fill ~53~50~19 ~54~50~19 minecraft:concrete 7
fill ~53~51~19 ~53~51~20 minecraft:concrete 7
fill ~54~21~19 ~55~21~20 minecraft:concrete 0
fill ~54~36~19 ~60~36~19 minecraft:concrete 0
fill ~54~37~19 ~58~37~19 minecraft:concrete 0
fill ~54~40~19 ~57~40~19 minecraft:concrete 0
fill ~54~41~19 ~56~42~19 minecraft:concrete 0
fill ~54~46~19 ~54~46~25 minecraft:concrete 7
fill ~54~48~19 ~55~49~19 minecraft:concrete 7
fill ~55~43~19 ~56~45~19 minecraft:concrete 0
setblock ~55~46~19 minecraft:concrete 0
fill ~56~22~19 ~56~22~21 minecraft:concrete 0
fill ~56~23~19 ~58~23~19 minecraft:concrete 0
fill ~56~24~19 ~58~25~19 minecraft:concrete 7
fill ~56~48~19 ~59~48~19 minecraft:anvil 3
fill ~57~35~19 ~62~35~19 minecraft:concrete 0
fill ~57~45~19 ~57~45~20 minecraft:wool 7
fill ~58~26~19 ~59~26~19 minecraft:concrete 7
fill ~58~45~19 ~60~45~19 minecraft:stone_block_slab 8
setblock ~59~24~19 minecraft:concrete 0
setblock ~59~25~19 minecraft:concrete 7
fill ~59~28~19 ~61~28~19 minecraft:concrete 0
fill ~59~34~19 ~63~34~19 minecraft:concrete 0
fill ~59~41~19 ~62~41~19 minecraft:concrete 0
fill ~59~42~19 ~61~43~19 minecraft:concrete 0
fill ~60~26~19 ~61~26~19 minecraft:wool 7
fill ~60~27~19 ~60~27~20 minecraft:concrete 0
fill ~60~29~19 ~63~29~19 minecraft:concrete 0
fill ~60~39~19 ~62~40~19 minecraft:concrete 0
fill ~60~44~19 ~63~44~19 minecraft:concrete 0
fill ~61~30~19 ~64~31~20 minecraft:concrete 0
fill ~61~32~19 ~66~32~19 minecraft:concrete 0
fill ~61~33~19 ~63~33~19 minecraft:concrete 0
setblock ~61~38~19 minecraft:concrete 0
fill ~61~45~19 ~65~45~19 minecraft:wool 7
fill ~61~46~19 ~77~46~19 minecraft:concrete 7
fill ~61~47~19 ~71~47~19 minecraft:anvil 3
fill ~61~48~19 ~72~48~19 minecraft:stone_block_slab 0
setblock ~62~27~19 minecraft:stone_block_slab 0
fill ~62~43~19 ~62~43~20 minecraft:concrete 0
fill ~63~27~19 ~64~27~19 minecraft:stone_block_slab 8
fill ~65~31~19 ~65~31~21 minecraft:concrete 0
fill ~65~33~19 ~68~33~21 minecraft:concrete 0
fill ~66~34~19 ~69~34~20 minecraft:concrete 0
setblock ~67~32~19 minecraft:stone_block_slab 8
fill ~68~35~19 ~73~35~21 minecraft:concrete 0
setblock ~72~47~19 minecraft:anvil 1
fill ~73~47~19 ~75~47~19 minecraft:fence 5
fill ~73~48~19 ~75~48~19 minecraft:trapdoor 2
fill ~74~34~19 ~77~34~19 minecraft:stone_block_slab 8
fill ~76~45~19 ~83~45~19 minecraft:wool 7
fill ~76~47~19 ~77~47~19 minecraft:anvil 3
fill ~76~48~19 ~77~48~19 minecraft:stone_block_slab 0
setblock ~78~34~19 minecraft:stone_block_slab 0
fill ~79~33~19 ~80~33~19 minecraft:stone_block_slab 8
fill ~81~32~19 ~82~32~19 minecraft:stone_block_slab 8
setblock ~83~33~19 minecraft:double_stone_block_slab 0
setblock ~84~33~19 minecraft:stone_block_slab 8
setblock ~84~34~19 minecraft:stone_block_slab 0
fill ~84~45~19 ~91~45~19 minecraft:stone_block_slab 8
setblock ~85~34~19 minecraft:double_stone_block_slab 0
fill ~86~35~19 ~87~35~19 minecraft:stone_block_slab 0
setblock ~88~35~19 minecraft:stone_block_slab 8
fill ~89~36~19 ~91~36~19 minecraft:stone_block_slab 0
fill ~91~46~19 ~94~46~19 minecraft:stone_block_slab 0
setblock ~92~36~19 minecraft:stone_block_slab 8
fill ~92~37~19 ~97~37~19 minecraft:stone_block_slab 0
setblock ~95~46~19 minecraft:double_stone_block_slab 0
fill ~96~46~19 ~98~46~19 minecraft:stone_block_slab 8
setblock ~98~36~19 minecraft:double_stone_block_slab 0
setblock ~99~35~19 minecraft:double_stone_block_slab 0
setblock ~99~36~19 minecraft:stone_block_slab 0
setblock ~99~46~19 minecraft:double_stone_block_slab 0
setblock ~100~34~19 minecraft:double_stone_block_slab 0
fill ~100~46~19 ~102~46~19 minecraft:stone_block_slab 0
setblock ~101~35~19 minecraft:double_stone_block_slab 0
setblock ~102~36~19 minecraft:double_stone_block_slab 0
setblock ~103~37~19 minecraft:double_stone_block_slab 0
setblock ~104~38~19 minecraft:stone_block_slab 0
setblock ~105~38~19 minecraft:stone_block_slab 8
fill ~106~39~19 ~107~39~19 minecraft:stone_block_slab 8
setblock ~108~39~19 minecraft:double_stone_block_slab 0
setblock ~109~38~19 minecraft:stone_block_slab 8
fill ~109~39~19 ~109~39~20 minecraft:stone_block_slab 0
fill ~110~32~19 ~110~33~19 minecraft:concrete 4
setblock ~110~37~19 minecraft:stone_block_slab 8
fill ~110~38~19 ~110~38~20 minecraft:stone_block_slab 0
setblock ~111~33~19 minecraft:concrete 7
setblock ~111~36~19 minecraft:double_stone_block_slab 0
fill ~111~37~19 ~111~37~20 minecraft:stone_block_slab 0
fill ~112~34~19 ~112~35~19 minecraft:concrete 7
fill ~112~36~19 ~112~36~20 minecraft:stone_block_slab 0
fill ~7~52~20 ~8~52~20 minecraft:concrete 7
fill ~7~53~20 ~7~55~20 minecraft:concrete 7
fill ~8~50~20 ~9~50~20 minecraft:concrete 7
setblock ~8~51~20 minecraft:concrete 7
fill ~9~48~20 ~10~49~20 minecraft:concrete 7
fill ~10~50~20 ~10~50~24 minecraft:quartz_block 1
fill ~10~51~20 ~10~51~21 minecraft:quartz_block 1
fill ~11~49~20 ~11~49~22 minecraft:quartz_block 1
setblock ~11~62~20 minecraft:concrete 0
fill ~12~44~20 ~12~44~34 minecraft:concrete 4
fill ~12~61~20 ~12~61~21 minecraft:stone 4
fill ~13~45~20 ~13~45~25 minecraft:concrete 7
fill ~26~34~20 ~26~34~26 minecraft:concrete 7
fill ~28~33~20 ~28~33~22 minecraft:concrete 7
setblock ~30~32~20 minecraft:concrete 7
setblock ~31~30~20 minecraft:concrete 4
fill ~32~57~20 ~32~59~20 minecraft:concrete 7
fill ~32~60~20 ~32~62~20 minecraft:concrete 0
fill ~33~24~20 ~33~24~23 minecraft:concrete 0
fill ~39~57~20 ~40~57~20 minecraft:concrete 0
setblock ~39~58~20 minecraft:concrete 0
setblock ~39~59~20 minecraft:concrete 7
fill ~40~20~20 ~40~20~21 minecraft:wool 7
setblock ~40~58~20 minecraft:concrete 7
fill ~42~16~20 ~42~16~22 minecraft:concrete 0
fill ~42~17~20 ~42~19~20 minecraft:concrete 0
fill ~48~17~20 ~48~17~26 minecraft:concrete 0
fill ~49~18~20 ~50~18~21 minecraft:concrete 0
fill ~49~56~20 ~50~56~34 minecraft:concrete 0
setblock ~50~20~20 minecraft:concrete 0
fill ~51~19~20 ~52~19~21 minecraft:concrete 0
fill ~51~47~20 ~51~47~26 minecraft:concrete 0
fill ~51~51~20 ~51~54~20 minecraft:concrete 0
fill ~51~55~20 ~53~55~20 minecraft:concrete 7
fill ~51~56~20 ~52~56~20 minecraft:concrete 7
setblock ~52~20~20 minecraft:concrete 0
fill ~52~47~20 ~52~49~22 minecraft:wool 7
fill ~52~50~20 ~53~50~20 minecraft:wool 7
setblock ~52~51~20 minecraft:wool 7
setblock ~52~54~20 minecraft:concrete 0
setblock ~52~57~20 minecraft:anvil 3
setblock ~52~58~20 minecraft:stone_block_slab 0
fill ~53~47~20 ~53~47~22 minecraft:concrete 7
fill ~53~53~20 ~55~53~20 minecraft:concrete 7
fill ~53~54~20 ~54~54~20 minecraft:concrete 7
setblock ~53~56~20 minecraft:anvil 3
setblock ~53~57~20 minecraft:stone_block_slab 0
fill ~54~20~20 ~55~20~21 minecraft:concrete 0
fill ~54~49~20 ~59~49~20 minecraft:concrete 7
fill ~54~50~20 ~58~50~20 minecraft:concrete 7
fill ~54~51~20 ~57~51~20 minecraft:concrete 7
fill ~54~52~20 ~56~52~20 minecraft:concrete 7
setblock ~54~55~20 minecraft:anvil 3
setblock ~54~56~20 minecraft:stone_block_slab 0
fill ~55~46~20 ~56~46~21 minecraft:concrete 7
setblock ~55~54~20 minecraft:anvil 3
setblock ~55~55~20 minecraft:stone_block_slab 0
fill ~56~21~20 ~56~21~21 minecraft:concrete 0
fill ~56~39~20 ~59~40~20 minecraft:concrete 0
fill ~56~41~20 ~58~41~20 minecraft:concrete 0
setblock ~56~45~20 minecraft:concrete 0
fill ~56~47~20 ~61~47~20 minecraft:concrete 7
fill ~56~48~20 ~58~48~20 minecraft:wool 7
setblock ~56~53~20 minecraft:anvil 3
setblock ~56~54~20 minecraft:stone_block_slab 0
fill ~57~22~20 ~58~22~21 minecraft:concrete 0
fill ~57~37~20 ~66~37~20 minecraft:concrete 0
fill ~57~38~20 ~60~38~20 minecraft:concrete 0
fill ~57~42~20 ~58~44~20 minecraft:concrete 0
setblock ~57~52~20 minecraft:anvil 3
setblock ~57~53~20 minecraft:stone_block_slab 0
fill ~58~45~20 ~61~45~20 minecraft:wool 7
fill ~58~46~20 ~61~46~20 minecraft:concrete 7
setblock ~58~51~20 minecraft:anvil 3
setblock ~58~52~20 minecraft:stone_block_slab 0
setblock ~59~23~20 minecraft:concrete 0
fill ~59~26~20 ~60~26~20 minecraft:concrete 7
setblock ~59~44~20 minecraft:concrete 0
fill ~59~48~20 ~60~48~20 minecraft:concrete 7
setblock ~59~50~20 minecraft:anvil 3
setblock ~59~51~20 minecraft:stone_block_slab 0
setblock ~60~24~20 minecraft:concrete 0
setblock ~60~25~20 minecraft:concrete 7
fill ~60~28~20 ~63~28~20 minecraft:concrete 0
setblock ~60~49~20 minecraft:anvil 3
setblock ~60~50~20 minecraft:stone_block_slab 0
fill ~61~27~20 ~62~27~20 minecraft:concrete 0
fill ~61~29~20 ~64~29~20 minecraft:concrete 0
fill ~61~36~20 ~67~36~20 minecraft:concrete 0
setblock ~61~48~20 minecraft:anvil 3
setblock ~61~49~20 minecraft:stone_block_slab 0
fill ~62~32~20 ~67~32~20 minecraft:concrete 0
fill ~62~35~20 ~67~35~20 minecraft:concrete 0
fill ~62~38~20 ~65~39~20 minecraft:concrete 0
fill ~62~41~20 ~66~42~20 minecraft:concrete 0
fill ~62~44~20 ~71~45~20 minecraft:concrete 0
fill ~62~46~20 ~77~46~23 minecraft:planks 2
fill ~63~27~20 ~64~27~20 minecraft:wool 7
fill ~63~33~20 ~64~33~20 minecraft:concrete 0
fill ~63~40~20 ~66~40~21 minecraft:concrete 0
fill ~63~43~20 ~69~43~20 minecraft:concrete 0
fill ~63~47~20 ~63~49~20 minecraft:fence 5
fill ~64~34~20 ~65~34~20 minecraft:concrete 0
fill ~64~49~20 ~64~52~20 minecraft:fence 5
setblock ~65~28~20 minecraft:double_stone_block_slab 0
fill ~65~29~20 ~66~29~20 minecraft:concrete 7
fill ~65~30~20 ~65~30~21 minecraft:concrete 0
fill ~66~28~20 ~69~28~20 minecraft:stone_block_slab 8
fill ~66~30~20 ~67~30~20 minecraft:concrete 7
fill ~66~31~20 ~66~31~21 minecraft:concrete 0
fill ~67~31~20 ~68~31~20 minecraft:concrete 7
fill ~67~42~20 ~67~42~23 minecraft:concrete 0
fill ~68~32~20 ~69~32~20 minecraft:concrete 7
fill ~69~33~20 ~70~33~20 minecraft:concrete 7
setblock ~70~29~20 minecraft:stone_block_slab 8
fill ~70~34~20 ~73~34~20 minecraft:concrete 7
fill ~70~36~20 ~73~36~22 minecraft:concrete 0
fill ~70~47~20 ~72~47~20 minecraft:log 0
fill ~70~48~20 ~70~49~20 minecraft:fence 5
setblock ~71~30~20 minecraft:stone_block_slab 0
fill ~71~48~20 ~72~48~20 minecraft:stone_pressure_plate 0
fill ~71~49~20 ~71~51~20 minecraft:fence 5
setblock ~72~31~20 minecraft:stone_block_slab 0
fill ~72~45~20 ~83~45~21 minecraft:concrete 0
fill ~74~34~20 ~78~34~21 minecraft:concrete 0
fill ~74~35~20 ~75~35~23 minecraft:concrete 0
fill ~74~47~20 ~77~47~21 minecraft:noteblock
fill ~75~48~20 ~76~48~21 minecraft:noteblock
fill ~75~49~20 ~76~49~20 minecraft:noteblock
setblock ~76~50~20 minecraft:noteblock
fill ~78~46~20 ~83~46~20 minecraft:concrete 7
fill ~78~47~20 ~83~47~20 minecraft:anvil 3
fill ~78~48~20 ~83~48~20 minecraft:stone_block_slab 0
fill ~79~33~20 ~80~33~21 minecraft:concrete 0
fill ~81~29~20 ~81~30~20 minecraft:double_stone_block_slab 0
setblock ~81~31~20 minecraft:stone_block_slab 0
fill ~81~32~20 ~82~32~20 minecraft:concrete 7
setblock ~82~31~20 minecraft:double_stone_block_slab 0
fill ~83~33~20 ~83~33~23 minecraft:concrete 7
fill ~84~34~20 ~85~34~21 minecraft:concrete 7
fill ~84~45~20 ~91~45~20 minecraft:wool 7
fill ~86~35~20 ~88~35~20 minecraft:concrete 7
fill ~89~36~20 ~91~36~20 minecraft:concrete 7
setblock ~91~25~20 minecraft:stone_block_slab 0
fill ~91~46~20 ~102~46~20 minecraft:wool 7
setblock ~92~25~20 minecraft:stone_block_slab 8
setblock ~92~26~20 minecraft:stone_block_slab 0
fill ~92~37~20 ~98~37~20 minecraft:concrete 7
setblock ~93~26~20 minecraft:stone_block_slab 8
fill ~93~27~20 ~93~27~21 minecraft:stone_block_slab 0
setblock ~94~27~20 minecraft:double_stone_block_slab 0
fill ~94~38~20 ~94~38~24 minecraft:concrete 0
setblock ~95~27~20 minecraft:stone_block_slab 8
setblock ~95~36~20 minecraft:stone_block_slab 8
setblock ~96~28~20 minecraft:stone_block_slab 0
setblock ~96~29~20 minecraft:double_stone_block_slab 0
fill ~96~36~20 ~97~36~20 minecraft:concrete 7
setblock ~97~29~20 minecraft:stone_block_slab 8
setblock ~98~30~20 minecraft:double_stone_block_slab 0
fill ~98~35~20 ~101~35~20 minecraft:concrete 7
fill ~98~36~20 ~98~36~21 minecraft:concrete 0
setblock ~99~31~20 minecraft:stone_block_slab 0
setblock ~99~32~20 minecraft:double_stone_block_slab 0
setblock ~99~36~20 minecraft:concrete 7
setblock ~100~32~20 minecraft:stone_block_slab 0
setblock ~100~33~20 minecraft:double_stone_block_slab 0
fill ~100~34~20 ~100~34~21 minecraft:concrete 7
setblock ~101~34~20 minecraft:double_stone_block_slab 0
setblock ~102~35~20 minecraft:stone_block_slab 8
fill ~102~36~20 ~102~36~23 minecraft:concrete 7
fill ~103~32~20 ~103~33~20 minecraft:wool 4
setblock ~103~36~20 minecraft:stone_block_slab 8
setblock ~103~37~20 minecraft:concrete 7
fill ~103~46~20 ~105~46~20 minecraft:stone_block_slab 0
fill ~104~31~20 ~105~31~20 minecraft:wool 4
fill ~104~33~20 ~104~34~20 minecraft:wool 4
fill ~104~38~20 ~109~38~20 minecraft:concrete 7
setblock ~105~34~20 minecraft:wool 4
fill ~106~30~20 ~107~30~20 minecraft:wool 4
setblock ~106~33~20 minecraft:wool 4
fill ~106~39~20 ~108~39~20 minecraft:concrete 7
fill ~106~46~20 ~107~46~20 minecraft:stone_block_slab 8
setblock ~108~31~20 minecraft:wool 4
fill ~108~37~20 ~108~37~21 minecraft:concrete 4
setblock ~109~32~20 minecraft:wool 4
fill ~109~36~20 ~109~36~21 minecraft:concrete 4
fill ~109~37~20 ~110~37~20 minecraft:concrete 7
fill ~110~32~20 ~112~32~20 minecraft:concrete 7
fill ~110~33~20 ~110~33~21 minecraft:concrete 4
fill ~110~35~20 ~110~35~21 minecraft:concrete 4
setblock ~110~36~20 minecraft:concrete 7
setblock ~111~33~20 minecraft:quartz_block 0
fill ~111~34~20 ~111~34~22 minecraft:concrete 4
setblock ~111~35~20 minecraft:concrete 7
fill ~111~36~20 ~111~36~21 minecraft:concrete 0
fill ~112~33~20 ~112~33~22 minecraft:concrete 0
setblock ~112~34~20 minecraft:quartz_block 0
fill ~112~35~20 ~112~35~22 minecraft:concrete 0
fill ~113~33~20 ~113~34~20 minecraft:concrete 7
fill ~6~56~21 ~6~56~33 minecraft:stone_block_slab 0
fill ~7~54~21 ~8~54~22 minecraft:quartz_block 1
fill ~7~55~21 ~7~55~33 minecraft:wool 7
fill ~7~56~21 ~7~56~33 minecraft:concrete 7
fill ~7~57~21 ~7~57~27 minecraft:anvil 2
fill ~7~58~21 ~7~58~33 minecraft:stone_block_slab 0
fill ~8~52~21 ~9~52~21 minecraft:quartz_block 1
fill ~8~53~21 ~8~53~33 minecraft:quartz_block 1
fill ~8~56~21 ~8~56~26 minecraft:concrete 0
fill ~9~50~21 ~9~51~21 minecraft:quartz_block 1
fill ~9~63~21 ~9~63~33 minecraft:wool 7
fill ~9~64~21 ~9~64~24 minecraft:anvil 2
fill ~9~65~21 ~9~65~24 minecraft:stone_block_slab 0
fill ~10~48~21 ~10~48~24 minecraft:quartz_block 1
setblock ~10~49~21 minecraft:quartz_block 1
fill ~10~62~21 ~10~62~24 minecraft:concrete 0
setblock ~11~62~21 minecraft:stone 4
fill ~13~44~21 ~13~44~23 minecraft:concrete 4
fill ~14~44~21 ~14~44~26 minecraft:concrete 7
fill ~27~33~21 ~27~33~26 minecraft:concrete 7
fill ~32~27~21 ~32~27~24 minecraft:stained_hardened_clay 1
fill ~32~28~21 ~32~28~24 minecraft:concrete 4
fill ~32~60~21 ~32~60~23 minecraft:concrete 7
fill ~32~61~21 ~32~62~36 minecraft:concrete 0
fill ~33~23~21 ~33~23~23 minecraft:concrete 0
fill ~33~26~21 ~33~26~33 minecraft:concrete 0
setblock ~33~30~21 minecraft:concrete 7
fill ~38~20~21 ~38~20~23 minecraft:wool 7
fill ~40~21~21 ~40~21~22 minecraft:concrete 0
fill ~41~16~21 ~41~16~23 minecraft:concrete 0
fill ~41~17~21 ~41~20~21 minecraft:concrete 0
setblock ~41~57~21 minecraft:concrete 7
setblock ~42~19~21 minecraft:concrete 0
fill ~43~16~21 ~45~16~22 minecraft:concrete 0
fill ~49~17~21 ~50~17~26 minecraft:concrete 0
fill ~51~18~21 ~52~18~24 minecraft:concrete 0
fill ~51~56~21 ~51~56~33 minecraft:concrete 0
setblock ~52~50~21 minecraft:wool 7
setblock ~52~52~21 minecraft:concrete 7
setblock ~52~54~21 minecraft:concrete 7
fill ~52~55~21 ~52~55~23 minecraft:planks 1
fill ~52~56~21 ~52~56~23 minecraft:spruce_stairs 1
fill ~53~19~21 ~54~19~23 minecraft:concrete 0
fill ~53~49~21 ~58~49~21 minecraft:planks 1
fill ~53~50~21 ~57~50~21 minecraft:planks 1
fill ~53~51~21 ~53~52~22 minecraft:wool 7
setblock ~53~53~21 minecraft:wool 7
fill ~53~54~21 ~53~54~23 minecraft:planks 1
fill ~53~55~21 ~53~55~23 minecraft:spruce_stairs 1
fill ~54~51~21 ~56~51~22 minecraft:planks 1
fill ~54~52~21 ~55~52~22 minecraft:planks 1
fill ~54~53~21 ~54~53~23 minecraft:planks 1
fill ~54~54~21 ~54~54~23 minecraft:spruce_stairs 1
fill ~55~47~21 ~60~47~23 minecraft:planks 1
fill ~55~48~21 ~59~48~23 minecraft:planks 1
fill ~55~53~21 ~55~53~23 minecraft:spruce_stairs 1
fill ~56~20~21 ~56~20~22 minecraft:concrete 0
fill ~56~52~21 ~56~52~23 minecraft:spruce_stairs 1
fill ~57~21~21 ~58~21~22 minecraft:concrete 0
setblock ~57~46~21 minecraft:concrete 7
fill ~57~51~21 ~57~51~23 minecraft:spruce_stairs 1
fill ~58~46~21 ~61~46~33 minecraft:planks 2
fill ~58~50~21 ~58~50~23 minecraft:spruce_stairs 1
fill ~59~22~21 ~59~22~22 minecraft:concrete 0
fill ~59~49~21 ~59~49~23 minecraft:spruce_stairs 1
fill ~60~13~21 ~60~13~23 minecraft:concrete 7
setblock ~60~23~21 minecraft:concrete 0
fill ~60~26~21 ~63~26~21 minecraft:concrete 7
fill ~60~48~21 ~60~48~23 minecraft:spruce_stairs 1
fill ~61~14~21 ~61~15~21 minecraft:concrete 7
fill ~61~24~21 ~62~24~21 minecraft:concrete 0
fill ~61~25~21 ~63~25~21 minecraft:concrete 7
fill ~61~47~21 ~61~47~23 minecraft:spruce_stairs 1
fill ~62~16~21 ~64~16~21 minecraft:concrete 7
fill ~63~27~21 ~64~27~21 minecraft:concrete 7
fill ~63~28~21 ~65~29~21 minecraft:concrete 0
fill ~63~30~21 ~64~31~21 minecraft:concrete 0
fill ~63~38~21 ~74~39~21 minecraft:concrete 0
fill ~63~41~21 ~80~41~22 minecraft:concrete 0
fill ~63~42~21 ~66~42~22 minecraft:concrete 0
fill ~64~13~21 ~64~15~21 minecraft:concrete 7
fill ~64~32~21 ~72~32~21 minecraft:concrete 0
setblock ~64~33~21 minecraft:concrete 0
fill ~64~36~21 ~69~37~21 minecraft:concrete 0
fill ~64~52~21 ~64~53~21 minecraft:fence 5
fill ~65~43~21 ~87~44~21 minecraft:concrete 0
fill ~65~45~21 ~71~45~21 minecraft:concrete 0
fill ~65~53~21 ~65~58~21 minecraft:fence 5
fill ~66~28~21 ~69~28~21 minecraft:wool 7
fill ~66~29~21 ~69~30~21 minecraft:concrete 0
fill ~66~58~21 ~66~60~21 minecraft:fence 5
fill ~67~31~21 ~71~31~22 minecraft:concrete 0
fill ~67~34~21 ~73~34~21 minecraft:concrete 0
setblock ~67~35~21 minecraft:concrete 0
fill ~67~40~21 ~77~40~23 minecraft:concrete 0
fill ~68~42~21 ~83~42~23 minecraft:concrete 0
fill ~69~33~21 ~72~33~22 minecraft:concrete 0
setblock ~70~29~21 minecraft:wool 7
setblock ~70~30~21 minecraft:concrete 0
fill ~70~37~21 ~75~37~22 minecraft:concrete 0
setblock ~71~30~21 minecraft:wool 7
setblock ~71~47~21 minecraft:log 0
setblock ~71~48~21 minecraft:stone_pressure_plate 0
fill ~71~51~21 ~71~52~21 minecraft:fence 5
setblock ~72~31~21 minecraft:wool 7
setblock ~72~47~21 minecraft:log 0
fill ~72~52~21 ~72~55~21 minecraft:fence 5
fill ~73~31~21 ~76~31~21 minecraft:stone_block_slab 0
fill ~73~33~21 ~78~33~21 minecraft:concrete 7
setblock ~73~47~21 minecraft:noteblock
fill ~73~55~21 ~73~57~21 minecraft:fence 5
fill ~74~36~21 ~75~36~22 minecraft:concrete 0
setblock ~74~48~21 minecraft:noteblock
fill ~75~39~21 ~76~39~23 minecraft:concrete 0
fill ~76~35~21 ~78~35~23 minecraft:concrete 0
setblock ~76~49~21 minecraft:noteblock
fill ~78~32~21 ~80~32~21 minecraft:concrete 7
fill ~78~46~21 ~83~46~33 minecraft:planks 2
fill ~79~34~21 ~80~34~21 minecraft:concrete 0
fill ~81~28~21 ~81~30~24 minecraft:concrete 7
fill ~81~32~21 ~81~33~21 minecraft:concrete 0
fill ~82~27~21 ~82~27~25 minecraft:concrete 7
fill ~82~31~21 ~82~32~24 minecraft:concrete 7
setblock ~82~33~21 minecraft:concrete 7
setblock ~83~34~21 minecraft:concrete 7
fill ~84~45~21 ~101~45~21 minecraft:concrete 0
fill ~84~46~21 ~90~46~21 minecraft:concrete 7
fill ~84~47~21 ~90~47~21 minecraft:anvil 3
fill ~84~48~21 ~90~48~21 minecraft:stone_block_slab 0
fill ~85~29~21 ~85~30~21 minecraft:wool 4
fill ~85~35~21 ~88~35~21 minecraft:concrete 0
fill ~86~31~21 ~86~32~21 minecraft:wool 4
fill ~86~34~21 ~87~34~21 minecraft:concrete 7
fill ~86~36~21 ~91~36~21 minecraft:concrete 0
setblock ~87~33~21 minecraft:wool 4
setblock ~88~30~21 minecraft:wool 4
fill ~88~34~21 ~89~34~21 minecraft:wool 4
fill ~88~37~21 ~98~37~21 minecraft:concrete 0
fill ~88~44~21 ~91~44~22 minecraft:concrete 0
fill ~89~24~21 ~91~24~21 minecraft:wool 4
fill ~89~31~21 ~90~31~21 minecraft:wool 4
fill ~89~35~21 ~92~35~21 minecraft:concrete 7
setblock ~90~27~21 minecraft:wool 4
setblock ~90~29~21 minecraft:wool 4
fill ~91~25~21 ~92~25~21 minecraft:wool 4
setblock ~91~28~21 minecraft:wool 4
fill ~91~33~21 ~92~33~22 minecraft:concrete 4
fill ~91~46~21 ~102~46~21 minecraft:concrete 0
fill ~91~47~21 ~103~47~21 minecraft:concrete 7
fill ~91~48~21 ~103~48~21 minecraft:anvil 3
fill ~91~49~21 ~103~49~21 minecraft:stone_block_slab 0
fill ~92~26~21 ~93~26~21 minecraft:wool 4
setblock ~92~27~21 minecraft:stone_block_slab 8
fill ~92~36~21 ~96~36~21 minecraft:concrete 7
fill ~93~32~21 ~93~32~22 minecraft:concrete 4
fill ~93~38~21 ~93~38~22 minecraft:concrete 0
fill ~94~27~21 ~95~27~23 minecraft:concrete 7
fill ~94~30~21 ~94~31~22 minecraft:concrete 4
fill ~94~33~21 ~97~33~22 minecraft:concrete 4
fill ~95~28~21 ~96~28~21 minecraft:concrete 7
fill ~95~34~21 ~98~34~22 minecraft:concrete 4
fill ~95~38~21 ~97~38~22 minecraft:concrete 0
fill ~96~29~21 ~96~29~24 minecraft:concrete 7
fill ~96~30~21 ~97~30~23 minecraft:concrete 7
fill ~96~32~21 ~97~32~22 minecraft:concrete 4
fill ~96~35~21 ~97~35~22 minecraft:concrete 4
setblock ~97~36~21 minecraft:concrete 0
setblock ~98~30~21 minecraft:concrete 0
fill ~98~31~21 ~99~31~21 minecraft:concrete 7
setblock ~98~35~21 minecraft:concrete 0
fill ~99~32~21 ~99~33~21 minecraft:concrete 7
setblock ~99~35~21 minecraft:concrete 7
fill ~99~36~21 ~101~36~21 minecraft:concrete 0
fill ~100~33~21 ~100~33~23 minecraft:concrete 7
setblock ~100~35~21 minecraft:concrete 0
setblock ~101~31~21 minecraft:concrete 4
fill ~101~35~21 ~101~35~23 minecraft:concrete 7
fill ~101~37~21 ~103~37~21 minecraft:concrete 0
setblock ~102~30~21 minecraft:concrete 4
setblock ~102~31~21 minecraft:hardened_clay
fill ~102~32~21 ~102~33~21 minecraft:concrete 4
fill ~102~38~21 ~111~38~21 minecraft:concrete 0
fill ~103~29~21 ~104~29~21 minecraft:concrete 4
setblock ~103~30~21 minecraft:hardened_clay
setblock ~103~34~21 minecraft:concrete 4
fill ~103~36~21 ~103~36~22 minecraft:concrete 7
fill ~103~46~21 ~107~46~21 minecraft:wool 7
fill ~104~35~21 ~105~35~21 minecraft:concrete 4
fill ~104~37~21 ~105~37~21 minecraft:concrete 7
fill ~105~30~21 ~107~30~21 minecraft:concrete 4
fill ~105~31~21 ~105~31~22 minecraft:stained_hardened_clay 1
fill ~105~39~21 ~110~39~22 minecraft:concrete 0
setblock ~106~34~21 minecraft:concrete 4
fill ~106~36~21 ~107~36~21 minecraft:hardened_clay
fill ~106~37~21 ~107~37~21 minecraft:concrete 4
fill ~107~31~21 ~108~31~21 minecraft:concrete 4
fill ~108~30~21 ~108~30~25 minecraft:concrete 7
fill ~108~32~21 ~108~33~21 minecraft:hardened_clay
setblock ~108~35~21 minecraft:hardened_clay
setblock ~108~36~21 minecraft:concrete 4
fill ~108~40~21 ~109~40~22 minecraft:concrete 0
fill ~108~46~21 ~111~46~21 minecraft:stone_block_slab 8
setblock ~109~32~21 minecraft:concrete 4
fill ~109~33~21 ~109~34~21 minecraft:hardened_clay
setblock ~109~35~21 minecraft:concrete 4
fill ~109~37~21 ~112~37~21 minecraft:concrete 0
fill ~110~31~21 ~111~31~21 minecraft:concrete 7
fill ~110~32~21 ~110~32~26 minecraft:concrete 7
setblock ~110~34~21 minecraft:concrete 4
setblock ~110~36~21 minecraft:concrete 0
fill ~111~32~21 ~111~33~21 minecraft:concrete 0
setblock ~111~35~21 minecraft:concrete 0
fill ~112~32~21 ~113~32~21 minecraft:concrete 7
fill ~112~34~21 ~113~34~21 minecraft:concrete 0
fill ~112~36~21 ~113~36~21 minecraft:concrete 0
setblock ~113~33~21 minecraft:concrete 0
setblock ~113~35~21 minecraft:concrete 0
fill ~114~33~21 ~114~35~21 minecraft:concrete 7
fill ~8~52~22 ~8~52~23 minecraft:stained_glass 3
fill ~9~50~22 ~9~51~23 minecraft:stained_glass 3
fill ~9~52~22 ~9~52~26 minecraft:quartz_block 1
fill ~10~49~22 ~10~49~23 minecraft:stained_glass 3
fill ~10~61~22 ~10~61~23 minecraft:concrete 0
fill ~11~57~22 ~11~61~22 minecraft:stone 4
fill ~13~63~22 ~13~63~32 minecraft:planks 2
setblock ~27~34~22 minecraft:concrete 7
fill ~28~32~22 ~28~32~26 minecraft:concrete 7
fill ~31~25~22 ~32~25~22 minecraft:hardened_clay
setblock ~32~24~22 minecraft:hardened_clay
fill ~32~26~22 ~32~26~23 minecraft:hardened_clay
fill ~33~21~22 ~33~22~32 minecraft:concrete 0
fill ~34~25~22 ~34~25~24 minecraft:concrete 0
fill ~34~26~22 ~34~26~23 minecraft:concrete 0
fill ~39~18~22 ~40~18~23 minecraft:concrete 0
setblock ~39~20~22 minecraft:wool 7
fill ~40~16~22 ~40~16~24 minecraft:concrete 0
fill ~40~17~22 ~40~17~23 minecraft:concrete 0
fill ~40~19~22 ~41~19~22 minecraft:concrete 0
fill ~41~20~22 ~41~20~23 minecraft:concrete 0
fill ~46~16~22 ~48~16~23 minecraft:concrete 0
setblock ~50~18~22 minecraft:concrete 0
fill ~51~17~22 ~51~17~32 minecraft:concrete 0
setblock ~52~19~22 minecraft:concrete 0
fill ~53~18~22 ~53~18~25 minecraft:concrete 0
setblock ~53~50~22 minecraft:wool 7
fill ~54~50~22 ~57~50~22 minecraft:planks 1
fill ~55~19~22 ~55~19~26 minecraft:concrete 0
setblock ~55~20~22 minecraft:concrete 0
fill ~55~46~22 ~57~46~32 minecraft:planks 2
fill ~55~49~22 ~58~49~23 minecraft:planks 1
fill ~57~20~22 ~57~20~32 minecraft:concrete 0
fill ~59~9~22 ~59~9~23 minecraft:concrete 7
fill ~59~10~22 ~59~12~22 minecraft:concrete 7
fill ~59~21~22 ~59~21~26 minecraft:concrete 0
fill ~60~22~22 ~61~22~23 minecraft:concrete 0
fill ~61~9~22 ~61~9~24 minecraft:concrete 7
fill ~61~13~22 ~62~13~22 minecraft:concrete 4
fill ~61~14~22 ~63~14~23 minecraft:stained_hardened_clay 1
fill ~61~23~22 ~62~23~22 minecraft:concrete 0
fill ~62~10~22 ~62~12~23 minecraft:concrete 7
fill ~62~15~22 ~63~15~22 minecraft:concrete 4
setblock ~63~13~22 minecraft:concrete 7
setblock ~63~24~22 minecraft:concrete 0
fill ~64~13~22 ~66~13~23 minecraft:concrete 0
fill ~64~14~22 ~64~14~23 minecraft:concrete 7
setblock ~64~15~22 minecraft:concrete 7
fill ~64~25~22 ~65~25~22 minecraft:concrete 0
fill ~64~26~22 ~65~27~22 minecraft:concrete 7
fill ~65~14~22 ~65~15~23 minecraft:concrete 0
fill ~65~28~22 ~71~28~22 minecraft:concrete 7
fill ~65~39~22 ~74~39~22 minecraft:concrete 0
fill ~65~40~22 ~66~40~22 minecraft:concrete 0
fill ~66~26~22 ~68~26~22 minecraft:concrete 0
fill ~66~27~22 ~70~27~22 minecraft:concrete 7
fill ~66~47~22 ~67~47~24 minecraft:noteblock
fill ~66~48~22 ~67~48~22 minecraft:noteblock
setblock ~66~49~22 minecraft:noteblock
fill ~66~60~22 ~66~62~22 minecraft:fence 5
fill ~67~30~22 ~69~30~22 minecraft:concrete 0
setblock ~67~36~22 minecraft:concrete 0
fill ~67~43~22 ~95~43~22 minecraft:concrete 0
fill ~67~44~22 ~87~44~22 minecraft:concrete 0
fill ~67~62~22 ~67~68~22 minecraft:fence 5
fill ~68~32~22 ~75~32~22 minecraft:concrete 0
setblock ~68~33~22 minecraft:concrete 0
fill ~68~37~22 ~69~37~22 minecraft:concrete 0
setblock ~68~47~22 minecraft:log 0
setblock ~68~48~22 minecraft:stone_pressure_plate 0
fill ~68~68~22 ~68~69~22 minecraft:fence 5
fill ~69~34~22 ~77~34~22 minecraft:concrete 0
fill ~69~35~22 ~73~35~22 minecraft:concrete 0
setblock ~69~36~22 minecraft:concrete 0
fill ~69~38~22 ~81~38~22 minecraft:concrete 0
fill ~70~29~22 ~71~30~22 minecraft:concrete 7
fill ~72~31~22 ~76~31~22 minecraft:concrete 0
fill ~73~33~22 ~76~33~23 minecraft:concrete 0
fill ~73~57~22 ~73~58~22 minecraft:fence 5
fill ~74~30~22 ~76~30~22 minecraft:stone_block_slab 8
fill ~74~47~22 ~76~47~22 minecraft:noteblock
fill ~74~58~22 ~74~62~22 minecraft:fence 5
fill ~75~62~22 ~75~63~22 minecraft:fence 5
fill ~76~36~22 ~79~36~23 minecraft:concrete 0
fill ~76~37~22 ~80~37~22 minecraft:concrete 0
setblock ~77~31~22 minecraft:stone_block_slab 0
setblock ~77~33~22 minecraft:concrete 7
fill ~77~39~22 ~81~39~23 minecraft:concrete 0
fill ~78~31~22 ~78~31~23 minecraft:double_stone_block_slab 0
fill ~78~40~22 ~82~40~23 minecraft:concrete 0
fill ~80~28~22 ~80~28~32 minecraft:concrete 7
fill ~80~29~22 ~80~29~25 minecraft:concrete 7
fill ~80~30~22 ~80~30~24 minecraft:concrete 7
fill ~81~27~22 ~81~27~24 minecraft:concrete 7
fill ~81~31~22 ~81~31~24 minecraft:concrete 7
fill ~81~32~22 ~81~32~23 minecraft:concrete 7
setblock ~81~33~22 minecraft:concrete 7
fill ~81~34~22 ~84~34~22 minecraft:concrete 0
fill ~81~41~22 ~87~41~23 minecraft:concrete 0
fill ~82~26~22 ~83~26~24 minecraft:concrete 7
fill ~82~28~22 ~82~30~24 minecraft:concrete 7
fill ~83~25~22 ~84~25~23 minecraft:concrete 7
fill ~83~31~22 ~83~32~24 minecraft:concrete 7
fill ~84~24~22 ~85~24~24 minecraft:concrete 7
fill ~84~28~22 ~85~31~22 minecraft:concrete 4
fill ~84~33~22 ~84~33~24 minecraft:concrete 7
fill ~84~42~22 ~90~42~23 minecraft:concrete 0
fill ~84~46~22 ~90~46~32 minecraft:planks 2
setblock ~84~47~22 minecraft:rail 5
fill ~85~26~22 ~86~26~22 minecraft:concrete 4
setblock ~85~27~22 minecraft:concrete 4
fill ~85~32~22 ~87~32~22 minecraft:concrete 4
fill ~85~34~22 ~85~34~24 minecraft:concrete 7
fill ~85~35~22 ~85~36~25 minecraft:concrete 0
fill ~86~23~22 ~89~23~24 minecraft:concrete 7
fill ~86~25~22 ~87~25~22 minecraft:concrete 4
fill ~86~27~22 ~86~28~22 minecraft:hardened_clay
fill ~86~30~22 ~86~31~22 minecraft:concrete 4
fill ~86~33~22 ~90~34~22 minecraft:concrete 4
fill ~86~36~22 ~90~36~22 minecraft:concrete 0
fill ~87~24~22 ~91~24~22 minecraft:concrete 4
fill ~87~40~22 ~92~40~23 minecraft:concrete 0
setblock ~87~47~22 minecraft:rail 5
fill ~88~28~22 ~88~30~22 minecraft:concrete 4
fill ~88~35~22 ~95~35~22 minecraft:concrete 4
fill ~88~37~22 ~92~37~22 minecraft:concrete 0
fill ~89~25~22 ~90~25~22 minecraft:hardened_clay
fill ~89~27~22 ~90~27~22 minecraft:concrete 4
fill ~89~30~22 ~89~31~22 minecraft:concrete 4
fill ~89~47~22 ~90~47~24 minecraft:wooden_slab 2
setblock ~90~29~22 minecraft:concrete 4
fill ~90~31~22 ~91~31~22 minecraft:concrete 4
fill ~91~25~22 ~92~25~22 minecraft:concrete 4
setblock ~91~28~22 minecraft:concrete 4
fill ~91~34~22 ~94~34~22 minecraft:concrete 4
fill ~91~36~22 ~96~36~22 minecraft:concrete 4
fill ~91~38~22 ~92~38~22 minecraft:concrete 0
fill ~91~47~22 ~103~47~22 minecraft:planks 2
fill ~92~26~22 ~93~26~22 minecraft:concrete 4
fill ~92~29~22 ~95~29~22 minecraft:concrete 4
setblock ~92~30~22 minecraft:concrete 4
fill ~92~44~22 ~102~44~22 minecraft:concrete 0
fill ~93~27~22 ~93~28~22 minecraft:concrete 4
setblock ~93~30~22 minecraft:hardened_clay
setblock ~93~33~22 minecraft:concrete 4
fill ~93~37~22 ~95~37~22 minecraft:concrete 4
fill ~93~39~22 ~96~39~23 minecraft:concrete 0
setblock ~94~28~22 minecraft:concrete 4
fill ~94~32~22 ~95~32~22 minecraft:concrete 4
fill ~94~50~22 ~95~50~22 minecraft:fence 5
fill ~94~51~22 ~94~54~22 minecraft:fence 5
fill ~95~28~22 ~95~28~24 minecraft:concrete 7
fill ~95~30~22 ~95~31~22 minecraft:concrete 4
fill ~95~48~22 ~95~49~22 minecraft:fence 5
fill ~96~31~22 ~97~31~22 minecraft:concrete 4
fill ~96~37~22 ~100~37~22 minecraft:concrete 0
fill ~97~36~22 ~98~36~22 minecraft:concrete 7
fill ~98~31~22 ~98~31~23 minecraft:concrete 7
fill ~98~32~22 ~98~33~22 minecraft:concrete 4
setblock ~98~35~22 minecraft:stained_hardened_clay 1
fill ~98~38~22 ~98~38~23 minecraft:concrete 0
fill ~99~33~22 ~99~35~22 minecraft:concrete 4
setblock ~99~36~22 minecraft:concrete 0
fill ~100~30~22 ~101~31~22 minecraft:concrete 7
fill ~100~34~22 ~100~35~22 minecraft:concrete 4
fill ~101~32~22 ~102~34~22 minecraft:concrete 7
fill ~101~36~22 ~101~36~23 minecraft:concrete 7
fill ~101~38~22 ~108~38~22 minecraft:concrete 0
fill ~102~29~22 ~108~29~22 minecraft:concrete 7
fill ~102~30~22 ~104~31~22 minecraft:stained_hardened_clay 1
fill ~102~35~22 ~105~35~22 minecraft:concrete 7
fill ~102~45~22 ~107~45~22 minecraft:concrete 0
fill ~103~32~22 ~108~33~22 minecraft:stained_hardened_clay 1
setblock ~103~34~22 minecraft:concrete 7
fill ~103~46~22 ~107~46~22 minecraft:concrete 0
fill ~104~34~22 ~105~34~22 minecraft:stained_hardened_clay 1
fill ~104~36~22 ~107~36~22 minecraft:stained_hardened_clay 1
fill ~104~37~22 ~106~37~22 minecraft:concrete 0
fill ~104~39~22 ~104~39~23 minecraft:concrete 0
fill ~104~47~22 ~108~47~22 minecraft:concrete 7
fill ~104~48~22 ~108~48~22 minecraft:anvil 3
fill ~104~49~22 ~108~49~22 minecraft:stone_block_slab 0
fill ~105~28~22 ~105~28~32 minecraft:concrete 7
fill ~105~30~22 ~107~30~22 minecraft:concrete 7
setblock ~106~31~22 minecraft:stained_hardened_clay 1
setblock ~106~34~22 minecraft:concrete 7
fill ~106~35~22 ~108~35~22 minecraft:stained_hardened_clay 1
fill ~106~40~22 ~107~40~22 minecraft:concrete 0
fill ~107~31~22 ~109~31~22 minecraft:concrete 7
fill ~107~34~22 ~109~34~22 minecraft:stained_hardened_clay 1
fill ~107~37~22 ~110~37~22 minecraft:concrete 7
fill ~108~36~22 ~111~36~22 minecraft:concrete 7
fill ~108~41~22 ~110~41~24 minecraft:concrete 0
fill ~108~46~22 ~111~46~22 minecraft:wool 7
fill ~108~61~22 ~109~61~22 minecraft:concrete 4
setblock ~109~32~22 minecraft:concrete 7
setblock ~109~33~22 minecraft:stained_hardened_clay 1
setblock ~109~35~22 minecraft:concrete 7
fill ~109~42~22 ~111~42~23 minecraft:concrete 0
fill ~110~33~22 ~110~34~22 minecraft:concrete 7
fill ~111~32~22 ~112~32~22 minecraft:concrete 7
setblock ~111~33~22 minecraft:concrete 0
fill ~111~35~22 ~111~35~24 minecraft:concrete 7
fill ~111~37~22 ~112~37~22 minecraft:concrete 0
fill ~111~38~22 ~111~38~23 minecraft:concrete 0
fill ~111~43~22 ~111~43~24 minecraft:concrete 0
setblock ~112~34~22 minecraft:concrete 0
fill ~112~46~22 ~113~46~22 minecraft:stone_block_slab 8
fill ~113~33~22 ~113~34~22 minecraft:concrete 7
setblock ~113~36~22 minecraft:concrete 0
fill ~114~35~22 ~114~36~22 minecraft:concrete 7
fill ~115~36~22 ~115~38~22 minecraft:concrete 7
fill ~7~54~23 ~7~54~24 minecraft:quartz_block 1
fill ~9~47~23 ~9~47~31 minecraft:concrete 7
setblock ~9~61~23 minecraft:concrete 0
fill ~10~47~23 ~10~47~31 minecraft:quartz_block 1
fill ~10~57~23 ~10~60~23 minecraft:concrete 0
fill ~11~45~23 ~11~45~31 minecraft:stone_block_slab 8
fill ~11~46~23 ~11~46~31 minecraft:wool 7
fill ~11~47~23 ~11~47~31 minecraft:concrete 0
fill ~29~31~23 ~29~31~26 minecraft:concrete 7
fill ~31~63~23 ~31~63~37 minecraft:planks 2
fill ~32~23~23 ~32~23~31 minecraft:concrete 0
fill ~32~63~23 ~32~63~31 minecraft:concrete 7
fill ~39~16~23 ~39~17~24 minecraft:concrete 0
fill ~39~19~23 ~40~20~24 minecraft:concrete 0
