setblock ~4~89~5 minecraft:lantern
setblock ~4~90~5 minecraft:concrete 14
fill ~38~38~5 ~38~38~9 minecraft:polished_basalt
fill ~45~38~5 ~45~38~9 minecraft:polished_basalt
fill ~52~38~5 ~52~38~9 minecraft:polished_basalt
fill ~59~38~5 ~59~38~9 minecraft:polished_basalt
fill ~66~38~5 ~66~38~9 minecraft:polished_basalt
setblock ~84~28~5 minecraft:polished_blackstone_stairs 7
setblock ~84~29~5 minecraft:polished_blackstone
setblock ~84~30~5 minecraft:polished_blackstone_stairs 2
fill ~85~28~5 ~86~28~5 minecraft:smooth_red_sandstone_stairs 7
fill ~85~29~5 ~86~29~5 minecraft:smooth_stone
fill ~85~30~5 ~86~30~5 minecraft:smooth_red_sandstone_stairs 2
setblock ~87~28~5 minecraft:polished_blackstone_stairs 7
setblock ~87~29~5 minecraft:polished_blackstone
setblock ~87~30~5 minecraft:polished_blackstone_stairs 2
fill ~88~28~5 ~90~28~5 minecraft:smooth_red_sandstone_stairs 7
fill ~88~29~5 ~90~29~5 minecraft:smooth_stone
fill ~88~30~5 ~90~30~5 minecraft:smooth_red_sandstone_stairs 2
setblock ~91~28~5 minecraft:polished_blackstone_stairs 7
setblock ~91~29~5 minecraft:polished_blackstone
setblock ~91~30~5 minecraft:polished_blackstone_stairs 2
setblock ~38~37~6 minecraft:spruce_trapdoor 3
setblock ~38~39~6 minecraft:spruce_trapdoor3
fill ~38~43~6 ~38~43~10 minecraft:polished_basalt
setblock ~45~37~6 minecraft:spruce_trapdoor 3
setblock ~45~39~6 minecraft:spruce_trapdoor3
fill ~45~43~6 ~45~43~10 minecraft:polished_basalt
setblock ~52~37~6 minecraft:spruce_trapdoor 3
setblock ~52~39~6 minecraft:spruce_trapdoor3
fill ~52~43~6 ~52~43~10 minecraft:polished_basalt
setblock ~59~37~6 minecraft:spruce_trapdoor 3
setblock ~59~39~6 minecraft:spruce_trapdoor3
fill ~59~43~6 ~59~43~10 minecraft:polished_basalt
setblock ~66~37~6 minecraft:spruce_trapdoor 3
setblock ~66~39~6 minecraft:spruce_trapdoor3
fill ~66~43~6 ~66~43~10 minecraft:polished_basalt
setblock ~84~27~6 minecraft:polished_blackstone_slab 9
fill ~84~28~6 ~84~30~6 minecraft:iron_bars
setblock ~84~31~6 minecraft:polished_blackstone_slab
fill ~85~27~6 ~86~27~6 minecraft:stone_block_slab3 9
fill ~85~31~6 ~86~31~6 minecraft:stone_block_slab3
fill ~86~28~6 ~86~30~6 minecraft:iron_bars
setblock ~87~27~6 minecraft:polished_blackstone_slab 9
setblock ~87~31~6 minecraft:polished_blackstone_slab
fill ~88~27~6 ~90~27~6 minecraft:stone_block_slab3 9
fill ~88~28~6 ~89~30~6 minecraft:iron_bars
fill ~88~31~6 ~90~31~6 minecraft:stone_block_slab3
setblock ~91~27~6 minecraft:polished_blackstone_slab 9
setblock ~91~31~6 minecraft:polished_blackstone_slab
setblock ~92~28~6 minecraft:smooth_red_sandstone_stairs 6
setblock ~92~29~6 minecraft:smooth_stone
setblock ~92~30~6 minecraft:smooth_red_sandstone_stairs 1
setblock ~94~27~6 minecraft:polished_granite_stairs 7
fill ~94~28~6 ~94~30~6 minecraft:stone
setblock ~94~31~6 minecraft:polished_granite_stairs 2
setblock ~96~27~6 minecraft:polished_granite_stairs 7
fill ~96~28~6 ~96~30~6 minecraft:stone
setblock ~96~31~6 minecraft:polished_granite_stairs 2
setblock ~98~27~6 minecraft:polished_granite_stairs 7
fill ~98~28~6 ~98~30~6 minecraft:stone
setblock ~98~31~6 minecraft:polished_granite_stairs 2
setblock ~34~34~7 minecraft:smooth_quartz_stairs 7
setblock ~34~35~7 minecraft:quartz_block
fill ~34~36~7 ~70~36~7 minecraft:concrete 8
fill ~34~37~7 ~34~39~8 minecraft:quartz_block
fill ~34~40~7 ~70~40~7 minecraft:concrete 8
setblock ~35~34~7 minecraft:normal_stone_stairs 7
setblock ~35~35~7 minecraft:stone
fill ~35~37~7 ~35~39~7 minecraft:stone
fill ~36~34~7 ~40~34~7 minecraft:smooth_quartz_stairs 7
fill ~36~35~7 ~40~35~7 minecraft:quartz_block
fill ~36~37~7 ~37~39~7 minecraft:quartz_block
setblock ~38~37~7 minecraft:stone_block_slab3
setblock ~38~39~7 minecraft:stone_block_slab3 9
setblock ~38~42~7 minecraft:spruce_trapdoor 3
setblock ~38~44~7 minecraft:spruce_trapdoor3
fill ~39~37~7 ~40~39~7 minecraft:quartz_block
setblock ~41~34~7 minecraft:normal_stone_stairs 7
setblock ~41~35~7 minecraft:stone
fill ~41~37~7 ~41~39~7 minecraft:stone
fill ~42~34~7 ~47~34~7 minecraft:smooth_quartz_stairs 7
fill ~42~35~7 ~47~35~7 minecraft:quartz_block
fill ~42~37~7 ~44~39~7 minecraft:quartz_block
setblock ~45~37~7 minecraft:stone_block_slab3
setblock ~45~39~7 minecraft:stone_block_slab3 9
setblock ~45~42~7 minecraft:spruce_trapdoor 3
setblock ~45~44~7 minecraft:spruce_trapdoor3
fill ~46~37~7 ~47~39~7 minecraft:quartz_block
setblock ~48~34~7 minecraft:normal_stone_stairs 7
setblock ~48~35~7 minecraft:stone
fill ~48~37~7 ~48~39~7 minecraft:stone
fill ~49~34~7 ~55~34~7 minecraft:smooth_quartz_stairs 7
fill ~49~35~7 ~55~35~7 minecraft:quartz_block
fill ~49~37~7 ~51~39~7 minecraft:quartz_block
setblock ~49~52~7 minecraft:spruce_trapdoor 9
setblock ~52~37~7 minecraft:stone_block_slab3
setblock ~52~39~7 minecraft:stone_block_slab3 9
setblock ~52~42~7 minecraft:spruce_trapdoor 3
setblock ~52~44~7 minecraft:spruce_trapdoor3
fill ~53~37~7 ~55~39~7 minecraft:quartz_block
setblock ~55~52~7 minecraft:spruce_trapdoor 9
setblock ~56~34~7 minecraft:normal_stone_stairs 7
setblock ~56~35~7 minecraft:stone
fill ~56~37~7 ~56~39~7 minecraft:stone
fill ~57~34~7 ~62~34~7 minecraft:smooth_quartz_stairs 7
fill ~57~35~7 ~62~35~7 minecraft:quartz_block
fill ~57~37~7 ~58~39~7 minecraft:quartz_block
setblock ~59~37~7 minecraft:stone_block_slab3
setblock ~59~39~7 minecraft:stone_block_slab3 9
setblock ~59~42~7 minecraft:spruce_trapdoor 3
setblock ~59~44~7 minecraft:spruce_trapdoor3
fill ~60~37~7 ~62~39~7 minecraft:quartz_block
setblock ~63~34~7 minecraft:normal_stone_stairs 7
setblock ~63~35~7 minecraft:stone
fill ~63~37~7 ~63~39~7 minecraft:stone
fill ~64~34~7 ~68~34~7 minecraft:smooth_quartz_stairs 7
fill ~64~35~7 ~68~35~7 minecraft:quartz_block
fill ~64~37~7 ~65~39~7 minecraft:quartz_block
setblock ~66~37~7 minecraft:stone_block_slab3
setblock ~66~39~7 minecraft:stone_block_slab3 9
setblock ~66~42~7 minecraft:spruce_trapdoor 3
setblock ~66~44~7 minecraft:spruce_trapdoor3
fill ~67~37~7 ~68~39~7 minecraft:quartz_block
setblock ~69~34~7 minecraft:normal_stone_stairs 7
setblock ~69~35~7 minecraft:stone
fill ~69~37~7 ~69~39~7 minecraft:stone
setblock ~70~34~7 minecraft:smooth_quartz_stairs 7
setblock ~70~35~7 minecraft:quartz_block
fill ~70~37~7 ~70~39~7 minecraft:quartz_block
setblock ~82~26~7 minecraft:polished_blackstone_stairs 7
fill ~82~27~7 ~82~31~7 minecraft:polished_blackstone
setblock ~82~32~7 minecraft:polished_blackstone_stairs 2
fill ~83~26~7 ~89~26~7 minecraft:polished_andesite_stairs 7
fill ~83~27~7 ~89~31~7 minecraft:stone
fill ~83~32~7 ~89~32~7 minecraft:polished_andesite_stairs 2
setblock ~90~26~7 minecraft:polished_blackstone_stairs 7
fill ~90~27~7 ~90~31~7 minecraft:polished_blackstone
setblock ~90~32~7 minecraft:polished_blackstone_stairs 2
setblock ~91~26~7 minecraft:polished_andesite_stairs 7
setblock ~91~27~7 minecraft:stone
setblock ~91~31~7 minecraft:stone
setblock ~91~32~7 minecraft:polished_andesite_stairs 2
setblock ~92~26~7 minecraft:polished_blackstone_stairs 7
fill ~92~27~7 ~92~31~7 minecraft:polished_blackstone
setblock ~92~32~7 minecraft:polished_blackstone_stairs 2
fill ~93~26~7 ~99~26~7 minecraft:polished_andesite_stairs 7
fill ~93~27~7 ~99~31~7 minecraft:stone
fill ~93~32~7 ~99~32~7 minecraft:polished_andesite_stairs 2
fill ~32~34~8 ~33~34~8 minecraft:smooth_quartz_stairs 7
fill ~32~35~8 ~33~35~8 minecraft:quartz_block
fill ~32~36~8 ~33~36~8 minecraft:concrete 8
fill ~32~37~8 ~32~37~9 minecraft:stone_block_slab4
fill ~33~37~8 ~33~39~9 minecraft:quartz_block
fill ~33~40~8 ~34~41~8 minecraft:concrete 8
fill ~33~42~8 ~34~44~8 minecraft:quartz_block
fill ~33~45~8 ~71~45~8 minecraft:concrete 8
fill ~33~46~8 ~34~46~8 minecraft:quartz_block
fill ~33~47~8 ~34~47~8 minecraft:smooth_quartz_stairs 2
setblock ~34~32~8 minecraft:smooth_quartz_stairs 7
fill ~34~33~8 ~34~34~8 minecraft:quartz_block
fill ~34~35~8 ~34~35~15 minecraft:concrete 8
fill ~34~36~8 ~70~36~13 minecraft:stone
setblock ~35~32~8 minecraft:normal_stone_stairs 7
setblock ~35~33~8 minecraft:stone
fill ~35~34~8 ~35~35~8 minecraft:stone
fill ~35~37~8 ~35~40~8 minecraft:stone
fill ~35~41~8 ~71~41~8 minecraft:concrete 8
fill ~35~42~8 ~35~44~8 minecraft:stone
fill ~35~46~8 ~35~46~30 minecraft:stone
setblock ~35~47~8 minecraft:normal_stone_stairs 2
fill ~36~32~8 ~40~32~8 minecraft:smooth_quartz_stairs 7
fill ~36~33~8 ~40~33~8 minecraft:quartz_block
fill ~36~34~8 ~40~34~10 minecraft:coal_block
fill ~36~35~8 ~40~35~8 minecraft:coal_block
setblock ~36~37~8 minecraft:barrel
setblock ~36~40~8 minecraft:wool 8
fill ~36~42~8 ~37~44~8 minecraft:quartz_block
fill ~36~46~8 ~40~46~8 minecraft:quartz_block
fill ~36~47~8 ~40~47~8 minecraft:smooth_quartz_stairs 2
setblock ~37~37~8 minecraft:grindstone 2
setblock ~37~38~8 minecraft:cobblestone_wall
fill ~37~39~8 ~39~39~8 minecraft:carpet 8
fill ~38~37~8 ~38~37~10 minecraft:stone_block_slab3 9
setblock ~38~40~8 minecraft:wool 8
setblock ~38~42~8 minecraft:stone_block_slab3
setblock ~38~44~8 minecraft:stone_block_slab3 9
setblock ~39~37~8 minecraft:grindstone 2
setblock ~39~38~8 minecraft:cobblestone_wall
fill ~39~42~8 ~40~44~8 minecraft:quartz_block
setblock ~39~61~8 minecraft:jungle_fence_gate 1
setblock ~40~37~8 minecraft:barrel 1
setblock ~40~40~8 minecraft:wool 8
setblock ~41~32~8 minecraft:normal_stone_stairs 7
setblock ~41~33~8 minecraft:stone
fill ~41~34~8 ~41~35~8 minecraft:stone
fill ~41~37~8 ~41~40~8 minecraft:stone
fill ~41~42~8 ~41~44~8 minecraft:stone
fill ~41~46~8 ~41~46~30 minecraft:stone
setblock ~41~47~8 minecraft:normal_stone_stairs 2
fill ~42~32~8 ~47~32~8 minecraft:smooth_quartz_stairs 7
fill ~42~33~8 ~47~33~8 minecraft:quartz_block
fill ~42~34~8 ~47~34~9 minecraft:coal_block
fill ~42~35~8 ~47~35~8 minecraft:coal_block
fill ~42~42~8 ~44~44~8 minecraft:quartz_block
fill ~42~46~8 ~47~46~8 minecraft:quartz_block
fill ~42~47~8 ~47~47~8 minecraft:smooth_quartz_stairs 2
setblock ~43~37~8 minecraft:barrel
setblock ~43~40~8 minecraft:wool 8
fill ~44~24~8 ~46~24~8 minecraft:wooden_slab 9
setblock ~44~37~8 minecraft:grindstone 2
setblock ~44~38~8 minecraft:cobblestone_wall
fill ~44~39~8 ~46~39~8 minecraft:carpet 8
fill ~45~37~8 ~45~37~10 minecraft:stone_block_slab3 9
setblock ~45~40~8 minecraft:wool 8
setblock ~45~42~8 minecraft:stone_block_slab3
setblock ~45~44~8 minecraft:stone_block_slab3 9
setblock ~46~37~8 minecraft:grindstone 2
setblock ~46~38~8 minecraft:cobblestone_wall
fill ~46~42~8 ~47~44~8 minecraft:quartz_block
fill ~47~26~8 ~48~26~8 minecraft:grindstone 2
setblock ~47~37~8 minecraft:barrel 1
setblock ~47~40~8 minecraft:wool 8
setblock ~48~32~8 minecraft:normal_stone_stairs 7
setblock ~48~33~8 minecraft:stone
fill ~48~34~8 ~48~35~8 minecraft:stone
fill ~48~37~8 ~48~40~8 minecraft:stone
fill ~48~42~8 ~48~44~8 minecraft:stone
fill ~48~46~8 ~48~46~15 minecraft:stone
setblock ~48~47~8 minecraft:normal_stone_stairs 2
fill ~48~51~8 ~56~51~8 minecraft:oak_stairs 7
setblock ~48~52~8 minecraft:wood
fill ~48~53~8 ~49~53~8 minecraft:stone_block_slab3
setblock ~49~25~8 minecraft:wooden_slab
setblock ~49~27~8 minecraft:wooden_slab 9
fill ~49~32~8 ~55~32~8 minecraft:smooth_quartz_stairs 7
fill ~49~33~8 ~55~33~8 minecraft:quartz_block
fill ~49~34~8 ~55~35~8 minecraft:coal_block
fill ~49~42~8 ~51~44~8 minecraft:quartz_block
fill ~49~46~8 ~55~46~8 minecraft:quartz_block
fill ~49~47~8 ~55~47~8 minecraft:smooth_quartz_stairs 2
setblock ~50~37~8 minecraft:barrel
setblock ~50~40~8 minecraft:wool 8
setblock ~50~52~8 minecraft:wood
fill ~50~53~8 ~54~53~8 minecraft:smooth_red_sandstone_stairs 2
setblock ~51~37~8 minecraft:grindstone 2
setblock ~51~38~8 minecraft:cobblestone_wall
fill ~51~39~8 ~53~39~8 minecraft:carpet 8
setblock ~51~52~8 minecraft:stone_block_slab
fill ~52~37~8 ~52~37~10 minecraft:stone_block_slab3 9
setblock ~52~40~8 minecraft:wool 8
setblock ~52~42~8 minecraft:stone_block_slab3
setblock ~52~44~8 minecraft:stone_block_slab3 9
setblock ~52~52~8 minecraft:wood
setblock ~53~37~8 minecraft:grindstone 2
setblock ~53~38~8 minecraft:cobblestone_wall
fill ~53~42~8 ~55~44~8 minecraft:quartz_block
setblock ~53~52~8 minecraft:stone_block_slab
setblock ~54~37~8 minecraft:barrel 1
setblock ~54~40~8 minecraft:wool 8
setblock ~54~52~8 minecraft:wood
fill ~55~53~8 ~56~53~8 minecraft:stone_block_slab3
fill ~56~24~8 ~58~24~8 minecraft:wooden_slab 9
setblock ~56~32~8 minecraft:normal_stone_stairs 7
setblock ~56~33~8 minecraft:stone
fill ~56~34~8 ~56~35~8 minecraft:stone
fill ~56~37~8 ~56~40~8 minecraft:stone
fill ~56~42~8 ~56~44~8 minecraft:stone
fill ~56~46~8 ~56~46~15 minecraft:stone
setblock ~56~47~8 minecraft:normal_stone_stairs 2
setblock ~56~52~8 minecraft:wood
fill ~57~32~8 ~62~32~8 minecraft:smooth_quartz_stairs 7
fill ~57~33~8 ~62~33~8 minecraft:quartz_block
fill ~57~34~8 ~62~34~10 minecraft:coal_block
fill ~57~35~8 ~62~35~8 minecraft:coal_block
setblock ~57~37~8 minecraft:barrel
setblock ~57~40~8 minecraft:wool 8
fill ~57~42~8 ~58~44~8 minecraft:quartz_block
fill ~57~46~8 ~62~46~8 minecraft:quartz_block
fill ~57~47~8 ~62~47~8 minecraft:smooth_quartz_stairs 2
setblock ~57~52~8 minecraft:grindstone 3
setblock ~58~37~8 minecraft:grindstone 2
setblock ~58~38~8 minecraft:cobblestone_wall
fill ~58~39~8 ~60~39~8 minecraft:carpet 8
fill ~59~26~8 ~60~26~8 minecraft:grindstone 2
fill ~59~37~8 ~59~37~10 minecraft:stone_block_slab3 9
setblock ~59~40~8 minecraft:wool 8
setblock ~59~42~8 minecraft:stone_block_slab3
setblock ~59~44~8 minecraft:stone_block_slab3 9
setblock ~60~37~8 minecraft:grindstone 2
setblock ~60~38~8 minecraft:cobblestone_wall
fill ~60~42~8 ~62~44~8 minecraft:quartz_block
setblock ~61~25~8 minecraft:wooden_slab
setblock ~61~27~8 minecraft:wooden_slab 9
setblock ~61~37~8 minecraft:barrel 1
setblock ~61~40~8 minecraft:wool 8
setblock ~63~32~8 minecraft:normal_stone_stairs 7
setblock ~63~33~8 minecraft:stone
fill ~63~34~8 ~63~35~8 minecraft:stone
fill ~63~37~8 ~63~40~8 minecraft:stone
fill ~63~42~8 ~63~44~8 minecraft:stone
fill ~63~46~8 ~63~46~30 minecraft:stone
setblock ~63~47~8 minecraft:normal_stone_stairs 2
fill ~64~32~8 ~68~32~8 minecraft:smooth_quartz_stairs 7
fill ~64~33~8 ~68~33~8 minecraft:quartz_block
fill ~64~34~8 ~68~34~10 minecraft:coal_block
fill ~64~35~8 ~68~35~9 minecraft:coal_block
setblock ~64~37~8 minecraft:barrel
setblock ~64~40~8 minecraft:wool 8
fill ~64~42~8 ~65~44~8 minecraft:quartz_block
fill ~64~46~8 ~68~46~8 minecraft:quartz_block
fill ~64~47~8 ~68~47~8 minecraft:smooth_quartz_stairs 2
setblock ~65~37~8 minecraft:grindstone 2
setblock ~65~38~8 minecraft:cobblestone_wall
fill ~65~39~8 ~67~39~8 minecraft:carpet 8
setblock ~65~61~8 minecraft:jungle_fence_gate 3
fill ~66~37~8 ~66~37~10 minecraft:stone_block_slab3 9
setblock ~66~40~8 minecraft:wool 8
setblock ~66~42~8 minecraft:stone_block_slab3
setblock ~66~44~8 minecraft:stone_block_slab3 9
setblock ~67~37~8 minecraft:grindstone 2
setblock ~67~38~8 minecraft:cobblestone_wall
fill ~67~42~8 ~68~44~8 minecraft:quartz_block
setblock ~68~37~8 minecraft:barrel 1
setblock ~68~40~8 minecraft:wool 8
setblock ~69~32~8 minecraft:normal_stone_stairs 7
setblock ~69~33~8 minecraft:stone
fill ~69~34~8 ~69~35~8 minecraft:stone
fill ~69~37~8 ~69~40~8 minecraft:stone
fill ~69~42~8 ~69~44~8 minecraft:stone
fill ~69~46~8 ~69~46~30 minecraft:stone
setblock ~69~47~8 minecraft:normal_stone_stairs 2
setblock ~70~32~8 minecraft:smooth_quartz_stairs 7
fill ~70~33~8 ~70~34~8 minecraft:quartz_block
setblock ~70~35~8 minecraft:coal_block
fill ~70~42~8 ~71~44~8 minecraft:quartz_block
fill ~70~46~8 ~71~46~8 minecraft:quartz_block
fill ~70~47~8 ~71~47~8 minecraft:smooth_quartz_stairs 2
setblock ~71~34~8 minecraft:smooth_quartz_stairs 6
setblock ~71~35~8 minecraft:quartz_block
setblock ~71~36~8 minecraft:concrete 8
fill ~71~37~8 ~71~39~9 minecraft:quartz_block
fill ~71~40~8 ~71~40~9 minecraft:concrete 8
setblock ~82~25~8 minecraft:polished_blackstone_stairs 7
setblock ~82~26~8 minecraft:polished_blackstone_stairs 3
setblock ~82~32~8 minecraft:polished_blackstone_stairs 8
setblock ~82~33~8 minecraft:polished_blackstone_stairs 2
fill ~83~25~8 ~89~25~8 minecraft:polished_andesite_stairs 7
setblock ~83~26~8 minecraft:polished_andesite_stairs 3
setblock ~83~32~8 minecraft:polished_andesite_stairs 8
fill ~83~33~8 ~89~33~8 minecraft:polished_andesite_stairs 2
setblock ~84~26~8 minecraft:stone
fill ~84~27~8 ~84~28~14 minecraft:iron_bars
fill ~84~29~8 ~84~31~10 minecraft:iron_bars
setblock ~84~32~8 minecraft:stone
fill ~85~26~8 ~89~26~8 minecraft:polished_andesite_stairs 3
fill ~85~29~8 ~85~29~10 minecraft:stone
fill ~85~32~8 ~89~32~8 minecraft:polished_andesite_stairs 8
fill ~88~29~8 ~88~29~10 minecraft:stone
setblock ~90~25~8 minecraft:polished_blackstone_stairs 7
setblock ~90~26~8 minecraft:polished_blackstone_stairs 3
setblock ~90~27~8 minecraft:cobblestone_wall
setblock ~90~28~8 minecraft:end_rod
setblock ~90~29~8 minecraft:cobblestone_wall
setblock ~90~30~8 minecraft:end_rod 1
setblock ~90~31~8 minecraft:cobblestone_wall
setblock ~90~32~8 minecraft:polished_blackstone_stairs 8
setblock ~90~33~8 minecraft:polished_blackstone_stairs 2
setblock ~91~25~8 minecraft:polished_andesite_stairs 7
setblock ~91~26~8 minecraft:polished_andesite_stairs 3
setblock ~91~32~8 minecraft:polished_andesite_stairs 8
setblock ~91~33~8 minecraft:polished_andesite_stairs 2
setblock ~92~25~8 minecraft:polished_blackstone_stairs 7
setblock ~92~26~8 minecraft:polished_blackstone_stairs 3
setblock ~92~27~8 minecraft:cobblestone_wall
setblock ~92~28~8 minecraft:end_rod
setblock ~92~29~8 minecraft:cobblestone_wall
setblock ~92~30~8 minecraft:end_rod 1
setblock ~92~31~8 minecraft:cobblestone_wall
setblock ~92~32~8 minecraft:polished_blackstone_stairs 8
setblock ~92~33~8 minecraft:polished_blackstone_stairs 2
fill ~93~25~8 ~99~25~8 minecraft:polished_andesite_stairs 7
fill ~93~26~8 ~97~26~8 minecraft:polished_andesite_stairs 3
fill ~93~32~8 ~97~32~8 minecraft:polished_andesite_stairs 8
fill ~93~33~8 ~99~33~8 minecraft:polished_andesite_stairs 2
fill ~94~29~8 ~94~29~14 minecraft:stone
fill ~97~29~8 ~97~29~10 minecraft:stone
setblock ~98~26~8 minecraft:stone
fill ~98~27~8 ~98~28~14 minecraft:iron_bars
fill ~98~29~8 ~98~31~10 minecraft:iron_bars
setblock ~98~32~8 minecraft:stone
setblock ~99~26~8 minecraft:polished_andesite_stairs 3
setblock ~99~32~8 minecraft:polished_andesite_stairs 8
fill ~30~34~9 ~31~34~9 minecraft:smooth_quartz_stairs 7
fill ~30~35~9 ~31~35~9 minecraft:quartz_block
fill ~30~36~9 ~31~36~9 minecraft:concrete 8
fill ~30~37~9 ~31~37~9 minecraft:stone_block_slab4
fill ~30~39~9 ~32~39~9 minecraft:stone_block_slab4 9
fill ~30~40~9 ~33~40~9 minecraft:concrete 8
fill ~30~41~9 ~32~41~9 minecraft:concrete 8
fill ~30~42~9 ~32~42~9 minecraft:stone_block_slab4
fill ~30~44~9 ~32~44~9 minecraft:stone_block_slab4 9
fill ~30~45~9 ~33~45~9 minecraft:concrete 8
fill ~30~46~9 ~32~46~9 minecraft:quartz_block
fill ~30~47~9 ~32~47~9 minecraft:smooth_quartz_stairs 2
fill ~32~32~9 ~33~32~9 minecraft:smooth_quartz_stairs 7
fill ~32~33~9 ~33~33~9 minecraft:quartz_block
setblock ~32~34~9 minecraft:quartz_block
fill ~32~36~9 ~33~36~29 minecraft:stone
fill ~33~41~9 ~71~41~13 minecraft:stone
fill ~33~42~9 ~33~44~9 minecraft:quartz_block
fill ~33~46~9 ~34~46~17 minecraft:stone
fill ~33~47~9 ~33~48~9 minecraft:quartz_block
fill ~33~49~9 ~34~49~9 minecraft:smooth_quartz_stairs 2
setblock ~34~32~9 minecraft:quartz_block
fill ~34~33~9 ~34~34~13 minecraft:concrete 8
setblock ~34~47~9 minecraft:wood
setblock ~34~48~9 minecraft:quartz_block
setblock ~35~32~9 minecraft:stone
setblock ~35~33~9 minecraft:stone
fill ~35~35~9 ~35~35~10 minecraft:stone_block_slab3 9
setblock ~35~39~9 minecraft:lantern
setblock ~35~40~9 minecraft:stone
fill ~35~42~9 ~35~45~9 minecraft:stone
fill ~35~47~9 ~35~47~12 minecraft:wood
setblock ~35~48~9 minecraft:stone
setblock ~35~49~9 minecraft:normal_stone_stairs 2
fill ~36~32~9 ~40~32~9 minecraft:quartz_block
fill ~36~33~9 ~40~33~11 minecraft:coal_block
setblock ~36~40~9 minecraft:polished_blackstone_button 3
setblock ~36~42~9 minecraft:barrel
setblock ~36~45~9 minecraft:wool 8
fill ~36~46~9 ~40~46~29 minecraft:stone
fill ~36~47~9 ~40~47~9 minecraft:concrete 8
fill ~36~48~9 ~40~48~9 minecraft:quartz_block
fill ~36~49~9 ~40~49~9 minecraft:smooth_quartz_stairs 2
fill ~37~35~9 ~39~35~10 minecraft:coal_block
setblock ~37~37~9 minecraft:grindstone
setblock ~37~38~9 minecraft:carpet 8
setblock ~37~42~9 minecraft:grindstone 2
setblock ~37~43~9 minecraft:cobblestone_wall
fill ~37~44~9 ~39~44~9 minecraft:carpet 8
fill ~37~54~9 ~41~54~9 minecraft:stone_block_slab4 9
fill ~37~55~9 ~41~55~10 minecraft:quartz_block
fill ~37~56~9 ~41~56~10 minecraft:stone_block_slab4
fill ~37~61~9 ~38~61~9 minecraft:iron_bars
setblock ~38~40~9 minecraft:polished_blackstone_button 3
fill ~38~42~9 ~38~42~11 minecraft:stone_block_slab3 9
setblock ~38~45~9 minecraft:wool 8
fill ~38~60~9 ~40~60~9 minecraft:concrete 8
setblock ~39~37~9 minecraft:grindstone
setblock ~39~38~9 minecraft:carpet 8
setblock ~39~42~9 minecraft:grindstone 2
setblock ~39~43~9 minecraft:cobblestone_wall
setblock ~39~61~9 minecraft:anvil
setblock ~40~40~9 minecraft:polished_blackstone_button 3
setblock ~40~42~9 minecraft:barrel 1
setblock ~40~45~9 minecraft:wool 8
fill ~40~61~9 ~41~61~9 minecraft:iron_bars
setblock ~41~32~9 minecraft:stone
setblock ~41~33~9 minecraft:stone
fill ~41~35~9 ~41~35~10 minecraft:stone_block_slab3 9
setblock ~41~39~9 minecraft:lantern
setblock ~41~40~9 minecraft:stone
fill ~41~42~9 ~41~45~9 minecraft:stone
fill ~41~47~9 ~68~47~9 minecraft:wood
setblock ~41~48~9 minecraft:stone
setblock ~41~49~9 minecraft:normal_stone_stairs 2
fill ~42~25~9 ~43~25~9 minecraft:oak_stairs 7
setblock ~42~26~9 minecraft:stripped_oak_log
fill ~42~27~9 ~48~27~9 minecraft:smooth_red_sandstone_stairs 2
fill ~42~32~9 ~47~32~9 minecraft:quartz_block
fill ~42~33~9 ~47~33~11 minecraft:coal_block
fill ~42~46~9 ~47~46~15 minecraft:stone
fill ~42~48~9 ~47~48~9 minecraft:quartz_block
fill ~42~49~9 ~47~49~9 minecraft:smooth_quartz_stairs 2
setblock ~43~26~9 minecraft:stained_glass 15
fill ~43~35~9 ~46~35~9 minecraft:coal_block
setblock ~43~40~9 minecraft:polished_blackstone_button 3
setblock ~43~42~9 minecraft:barrel
setblock ~43~45~9 minecraft:wool 8
fill ~44~25~9 ~46~25~9 minecraft:planks 
setblock ~44~26~9 minecraft:stripped_oak_log
setblock ~44~37~9 minecraft:grindstone
setblock ~44~38~9 minecraft:carpet 8
setblock ~44~42~9 minecraft:grindstone 2
setblock ~44~43~9 minecraft:cobblestone_wall
fill ~44~44~9 ~46~44~9 minecraft:carpet 8
setblock ~45~26~9 minecraft:stained_glass 15
setblock ~45~40~9 minecraft:polished_blackstone_button 3
fill ~45~42~9 ~45~42~11 minecraft:stone_block_slab3 9
setblock ~45~45~9 minecraft:wool 8
setblock ~46~26~9 minecraft:stripped_oak_log
setblock ~46~37~9 minecraft:grindstone
setblock ~46~38~9 minecraft:carpet 8
setblock ~46~42~9 minecraft:grindstone 2
setblock ~46~43~9 minecraft:cobblestone_wall
fill ~47~25~9 ~48~25~9 minecraft:oak_stairs 7
setblock ~47~26~9 minecraft:dispenser 5
setblock ~47~40~9 minecraft:polished_blackstone_button 3
setblock ~47~42~9 minecraft:barrel 1
setblock ~47~45~9 minecraft:wool 8
setblock ~47~51~9 minecraft:oak_stairs 5
setblock ~47~52~9 minecraft:stained_glass 15
setblock ~47~53~9 minecraft:stone_block_slab3
setblock ~48~26~9 minecraft:dispenser 4
setblock ~48~32~9 minecraft:stone
setblock ~48~33~9 minecraft:stone
fill ~48~35~9 ~48~35~10 minecraft:stone_block_slab3 9
setblock ~48~39~9 minecraft:lantern
setblock ~48~40~9 minecraft:stone
fill ~48~42~9 ~48~45~9 minecraft:stone
setblock ~48~48~9 minecraft:stone
setblock ~48~49~9 minecraft:normal_stone_stairs 2
fill ~48~51~9 ~55~51~9 minecraft:stone_block_slab
setblock ~48~52~9 minecraft:dark_oak_fence_gate 3
fill ~48~53~9 ~54~53~9 minecraft:stone_block_slab3 9
setblock ~48~54~9 minecraft:chain
setblock ~48~55~9 minecraft:cobblestone_wall
setblock ~49~25~9 minecraft:wooden_slab 9
setblock ~49~26~9 minecraft:lantern
setblock ~49~27~9 minecraft:wooden_slab
fill ~49~32~9 ~55~32~9 minecraft:quartz_block
fill ~49~33~9 ~55~33~11 minecraft:coal_block
fill ~49~46~9 ~55~46~15 minecraft:stone
fill ~49~48~9 ~55~48~9 minecraft:quartz_block
fill ~49~49~9 ~55~49~9 minecraft:smooth_quartz_stairs 2
fill ~50~34~9 ~54~34~10 minecraft:coal_block
fill ~50~35~9 ~54~35~9 minecraft:coal_block
setblock ~50~40~9 minecraft:polished_blackstone_button 3
setblock ~50~42~9 minecraft:barrel
setblock ~50~45~9 minecraft:wool 8
setblock ~51~37~9 minecraft:grindstone
setblock ~51~38~9 minecraft:carpet 8
setblock ~51~42~9 minecraft:grindstone 2
setblock ~51~43~9 minecraft:cobblestone_wall
fill ~51~44~9 ~53~44~9 minecraft:carpet 8
setblock ~52~40~9 minecraft:polished_blackstone_button 3
fill ~52~42~9 ~52~42~11 minecraft:stone_block_slab3 9
setblock ~52~45~9 minecraft:wool 8
setblock ~53~37~9 minecraft:grindstone
setblock ~53~38~9 minecraft:carpet 8
setblock ~53~42~9 minecraft:grindstone 2
setblock ~53~43~9 minecraft:cobblestone_wall
fill ~54~25~9 ~55~25~9 minecraft:oak_stairs 7
setblock ~54~26~9 minecraft:stripped_oak_log
fill ~54~27~9 ~60~27~9 minecraft:smooth_red_sandstone_stairs 2
setblock ~54~40~9 minecraft:polished_blackstone_button 3
setblock ~54~42~9 minecraft:barrel 1
setblock ~54~45~9 minecraft:wool 8
setblock ~55~26~9 minecraft:stained_glass 15
setblock ~55~53~9 minecraft:concrete 8
setblock ~55~54~9 minecraft:polished_blackstone_wall
setblock ~55~55~9 minecraft:flower_pot
fill ~56~25~9 ~58~25~9 minecraft:planks 
setblock ~56~26~9 minecraft:stripped_oak_log
setblock ~56~32~9 minecraft:stone
setblock ~56~33~9 minecraft:stone
fill ~56~35~9 ~56~35~10 minecraft:stone_block_slab3 9
setblock ~56~39~9 minecraft:lantern
setblock ~56~40~9 minecraft:stone
fill ~56~42~9 ~56~45~9 minecraft:stone
setblock ~56~48~9 minecraft:stone
setblock ~56~49~9 minecraft:normal_stone_stairs 2
setblock ~56~51~9 minecraft:double_stone_block_slab
setblock ~56~52~9 minecraft:blast_furnace 4
setblock ~56~53~9 minecraft:stone_block_slab3 9
setblock ~56~54~9 minecraft:chain
setblock ~56~55~9 minecraft:cobblestone_wall
setblock ~57~26~9 minecraft:stained_glass 15
fill ~57~32~9 ~62~32~9 minecraft:quartz_block
fill ~57~33~9 ~62~33~11 minecraft:coal_block
setblock ~57~40~9 minecraft:polished_blackstone_button 3
setblock ~57~42~9 minecraft:barrel
setblock ~57~45~9 minecraft:wool 8
fill ~57~46~9 ~62~46~15 minecraft:stone
fill ~57~48~9 ~62~48~9 minecraft:quartz_block
fill ~57~49~9 ~62~49~9 minecraft:smooth_quartz_stairs 2
fill ~57~51~9 ~57~53~9 minecraft:stone
setblock ~58~26~9 minecraft:stripped_oak_log
fill ~58~35~9 ~61~35~10 minecraft:coal_block
setblock ~58~37~9 minecraft:grindstone
setblock ~58~38~9 minecraft:carpet 8
setblock ~58~42~9 minecraft:grindstone 2
setblock ~58~43~9 minecraft:cobblestone_wall
fill ~58~44~9 ~60~44~9 minecraft:carpet 8
setblock ~58~51~9 minecraft:polished_andesite_stairs 6
setblock ~58~52~9 minecraft:stone
setblock ~58~53~9 minecraft:polished_andesite_stairs 1
fill ~59~25~9 ~60~25~9 minecraft:oak_stairs 7
setblock ~59~26~9 minecraft:dispenser 5
setblock ~59~40~9 minecraft:polished_blackstone_button 3
fill ~59~42~9 ~59~42~11 minecraft:stone_block_slab3 9
setblock ~59~45~9 minecraft:wool 8
setblock ~60~26~9 minecraft:dispenser 4
setblock ~60~37~9 minecraft:grindstone
setblock ~60~38~9 minecraft:carpet 8
setblock ~60~42~9 minecraft:grindstone 2
setblock ~60~43~9 minecraft:cobblestone_wall
setblock ~61~25~9 minecraft:wooden_slab 9
setblock ~61~26~9 minecraft:lantern
setblock ~61~27~9 minecraft:wooden_slab
setblock ~61~40~9 minecraft:polished_blackstone_button 3
setblock ~61~42~9 minecraft:barrel 1
setblock ~61~45~9 minecraft:wool 8
setblock ~63~32~9 minecraft:stone
setblock ~63~33~9 minecraft:stone
fill ~63~35~9 ~63~35~10 minecraft:stone_block_slab3 9
setblock ~63~39~9 minecraft:lantern
setblock ~63~40~9 minecraft:stone
fill ~63~42~9 ~63~45~9 minecraft:stone
setblock ~63~48~9 minecraft:stone
setblock ~63~49~9 minecraft:normal_stone_stairs 2
fill ~63~54~9 ~67~54~9 minecraft:stone_block_slab4 9
fill ~63~55~9 ~67~55~10 minecraft:quartz_block
fill ~63~56~9 ~67~56~10 minecraft:stone_block_slab4
fill ~63~61~9 ~64~61~9 minecraft:iron_bars
fill ~64~32~9 ~68~32~9 minecraft:quartz_block
fill ~64~33~9 ~68~33~11 minecraft:coal_block
setblock ~64~40~9 minecraft:polished_blackstone_button 3
setblock ~64~42~9 minecraft:barrel
setblock ~64~45~9 minecraft:wool 8
fill ~64~46~9 ~68~46~29 minecraft:stone
fill ~64~48~9 ~68~48~9 minecraft:quartz_block
fill ~64~49~9 ~68~49~9 minecraft:smooth_quartz_stairs 2
fill ~64~60~9 ~66~60~9 minecraft:concrete 8
setblock ~65~37~9 minecraft:grindstone
setblock ~65~38~9 minecraft:carpet 8
setblock ~65~42~9 minecraft:grindstone 2
setblock ~65~43~9 minecraft:cobblestone_wall
fill ~65~44~9 ~67~44~9 minecraft:carpet 8
setblock ~65~61~9 minecraft:anvil 2
setblock ~66~40~9 minecraft:polished_blackstone_button 3
fill ~66~42~9 ~66~42~11 minecraft:stone_block_slab3 9
setblock ~66~45~9 minecraft:wool 8
fill ~66~61~9 ~67~61~9 minecraft:iron_bars
setblock ~67~37~9 minecraft:grindstone
setblock ~67~38~9 minecraft:carpet 8
setblock ~67~42~9 minecraft:grindstone 2
setblock ~67~43~9 minecraft:cobblestone_wall
setblock ~68~40~9 minecraft:polished_blackstone_button 3
setblock ~68~42~9 minecraft:barrel 1
setblock ~68~45~9 minecraft:wool 8
setblock ~69~32~9 minecraft:stone
setblock ~69~33~9 minecraft:stone
fill ~69~35~9 ~69~35~10 minecraft:stone_block_slab3 9
setblock ~69~39~9 minecraft:lantern
setblock ~69~40~9 minecraft:stone
fill ~69~42~9 ~69~45~9 minecraft:stone
fill ~69~47~9 ~70~47~9 minecraft:concrete 8
setblock ~69~48~9 minecraft:stone
setblock ~69~49~9 minecraft:normal_stone_stairs 2
setblock ~70~32~9 minecraft:quartz_block
fill ~70~33~9 ~70~33~11 minecraft:coal_block
setblock ~70~34~9 minecraft:coal_block
fill ~70~46~9 ~71~46~29 minecraft:stone
fill ~70~48~9 ~71~48~9 minecraft:quartz_block
fill ~70~49~9 ~71~49~9 minecraft:smooth_quartz_stairs 2
fill ~71~32~9 ~72~32~9 minecraft:smooth_quartz_stairs 7
fill ~71~33~9 ~72~34~9 minecraft:quartz_block
setblock ~71~35~9 minecraft:coal_block
fill ~71~36~9 ~71~36~29 minecraft:stone
fill ~71~42~9 ~71~44~9 minecraft:quartz_block
fill ~71~45~9 ~74~45~9 minecraft:concrete 8
setblock ~71~47~9 minecraft:quartz_block
fill ~72~35~9 ~74~35~9 minecraft:quartz_block
fill ~72~36~9 ~74~36~9 minecraft:concrete 8
fill ~72~37~9 ~74~37~9 minecraft:stone_block_slab4
fill ~72~39~9 ~74~39~9 minecraft:stone_block_slab4 9
fill ~72~40~9 ~74~41~9 minecraft:concrete 8
fill ~72~42~9 ~74~42~9 minecraft:stone_block_slab4
fill ~72~44~9 ~74~44~9 minecraft:stone_block_slab4 9
fill ~72~46~9 ~74~46~9 minecraft:quartz_block
fill ~72~47~9 ~74~47~9 minecraft:smooth_quartz_stairs 2
setblock ~73~33~9 minecraft:smooth_quartz_stairs 6
setblock ~73~34~9 minecraft:quartz_block
setblock ~74~34~9 minecraft:smooth_quartz_stairs 6
fill ~82~25~9 ~82~25~13 minecraft:polished_blackstone
fill ~82~33~9 ~82~33~13 minecraft:polished_blackstone
fill ~83~25~9 ~89~25~13 minecraft:stone
setblock ~83~27~9 minecraft:quartz_block
setblock ~83~30~9 minecraft:smooth_quartz_stairs 7
setblock ~83~31~9 minecraft:quartz_block
fill ~83~33~9 ~89~33~13 minecraft:stone
fill ~84~24~9 ~84~24~10 minecraft:smooth_red_sandstone_stairs
fill ~84~26~9 ~84~26~13 minecraft:iron_bars
fill ~84~32~9 ~84~32~13 minecraft:iron_bars
fill ~84~34~9 ~84~34~10 minecraft:smooth_red_sandstone_stairs 5
fill ~85~24~9 ~90~24~10 minecraft:red_sandstone 
fill ~85~34~9 ~90~34~10 minecraft:red_sandstone 
setblock ~89~27~9 minecraft:quartz_block
setblock ~89~28~9 minecraft:smooth_quartz_stairs 2
setblock ~89~31~9 minecraft:quartz_block
fill ~90~25~9 ~90~25~13 minecraft:polished_blackstone
fill ~90~33~9 ~90~33~13 minecraft:polished_blackstone
fill ~91~24~9 ~91~24~10 minecraft:smooth_red_sandstone_stairs 6
fill ~91~25~9 ~91~25~13 minecraft:stone
fill ~91~33~9 ~91~33~13 minecraft:stone
fill ~91~34~9 ~91~34~10 minecraft:smooth_red_sandstone_stairs 1
fill ~92~25~9 ~92~25~13 minecraft:polished_blackstone
fill ~92~33~9 ~92~33~13 minecraft:polished_blackstone
fill ~93~25~9 ~99~25~13 minecraft:stone
setblock ~93~27~9 minecraft:quartz_block
setblock ~93~30~9 minecraft:smooth_quartz_stairs 7
setblock ~93~31~9 minecraft:quartz_block
fill ~93~33~9 ~99~33~13 minecraft:stone
setblock ~94~24~9 minecraft:polished_granite_stairs 7
setblock ~94~34~9 minecraft:polished_granite_stairs 2
setblock ~96~24~9 minecraft:polished_granite_stairs 7
setblock ~96~34~9 minecraft:polished_granite_stairs 2
setblock ~98~24~9 minecraft:polished_granite_stairs 7
fill ~98~26~9 ~98~26~13 minecraft:iron_bars
fill ~98~32~9 ~98~32~13 minecraft:iron_bars
setblock ~98~34~9 minecraft:polished_granite_stairs 2
setblock ~99~27~9 minecraft:quartz_block
setblock ~99~28~9 minecraft:smooth_quartz_stairs 2
setblock ~99~31~9 minecraft:quartz_block
fill ~28~34~10 ~29~34~10 minecraft:smooth_quartz_stairs 7
fill ~28~35~10 ~29~35~10 minecraft:quartz_block
fill ~28~36~10 ~29~36~10 minecraft:concrete 8
fill ~28~37~10 ~29~37~12 minecraft:stone_block_slab4
fill ~28~39~10 ~29~39~12 minecraft:stone_block_slab4 9
fill ~28~40~10 ~29~41~10 minecraft:concrete 8
fill ~28~42~10 ~29~42~12 minecraft:stone_block_slab4
fill ~28~44~10 ~29~44~12 minecraft:stone_block_slab4 9
fill ~28~45~10 ~29~45~10 minecraft:concrete 8
fill ~28~46~10 ~29~46~10 minecraft:quartz_block
fill ~28~47~10 ~29~47~10 minecraft:smooth_quartz_stairs 2
setblock ~29~38~10 minecraft:spruce_trapdoor 9
setblock ~29~43~10 minecraft:spruce_trapdoor 9
fill ~30~32~10 ~31~32~10 minecraft:smooth_quartz_stairs 7
fill ~30~33~10 ~31~33~10 minecraft:quartz_block
setblock ~30~34~10 minecraft:quartz_block
fill ~30~36~10 ~31~36~28 minecraft:stone
fill ~30~37~10 ~32~40~10 minecraft:stone
fill ~30~41~10 ~32~41~28 minecraft:stone
fill ~30~42~10 ~32~45~10 minecraft:stone
fill ~30~46~10 ~32~46~17 minecraft:stone
fill ~30~47~10 ~30~48~10 minecraft:quartz_block
fill ~30~49~10 ~32~49~10 minecraft:smooth_quartz_stairs 2
fill ~31~47~10 ~32~47~10 minecraft:wood
fill ~31~48~10 ~32~48~10 minecraft:quartz_block
fill ~32~31~10 ~34~31~10 minecraft:smooth_quartz_stairs 7
setblock ~32~32~10 minecraft:quartz_block
fill ~32~33~10 ~33~35~10 minecraft:concrete 8
fill ~33~32~10 ~34~32~10 minecraft:stained_hardened_clay 8
setblock ~33~37~10 minecraft:barrel 1
setblock ~33~42~10 minecraft:barrel 1
setblock ~33~47~10 minecraft:cauldron
setblock ~33~48~10 minecraft:tripwire_hook
setblock ~33~49~10 minecraft:quartz_block
fill ~33~50~10 ~34~50~10 minecraft:smooth_quartz_stairs 2
setblock ~34~28~10 minecraft:chain
setblock ~34~29~10 minecraft:cobblestone_wall
setblock ~34~47~10 minecraft:cobblestone_wall
setblock ~34~48~10 minecraft:cobblestone_wall
setblock ~34~49~10 minecraft:lantern
setblock ~35~31~10 minecraft:normal_stone_stairs 7
fill ~35~32~10 ~35~32~11 minecraft:stone
fill ~35~40~10 ~35~40~15 minecraft:stone_block_slab3 9
setblock ~35~44~10 minecraft:lantern
setblock ~35~45~10 minecraft:stone
fill ~35~48~10 ~35~49~13 minecraft:quartz_block
setblock ~35~50~10 minecraft:normal_stone_stairs 2
fill ~36~31~10 ~40~31~10 minecraft:smooth_quartz_stairs 7
fill ~36~32~10 ~40~32~12 minecraft:coal_block
setblock ~36~45~10 minecraft:polished_blackstone_button 3
fill ~36~47~10 ~36~49~10 minecraft:stone_block_slab3 9
fill ~36~50~10 ~40~50~10 minecraft:smooth_quartz_stairs 2
fill ~36~54~10 ~36~54~11 minecraft:stone_block_slab4 9
fill ~36~55~10 ~36~55~12 minecraft:quartz_block
fill ~36~56~10 ~36~56~14 minecraft:stone_block_slab4
fill ~36~61~10 ~37~61~10 minecraft:iron_bars
setblock ~37~42~10 minecraft:grindstone
setblock ~37~43~10 minecraft:carpet 8
setblock ~37~47~10 minecraft:double_stone_block_slab3 
fill ~37~48~10 ~37~49~10 minecraft:stone_block_slab3 9
fill ~37~53~10 ~41~53~10 minecraft:polished_blackstone_stairs 7
fill ~37~54~10 ~41~54~10 minecraft:polished_blackstone
setblock ~37~60~10 minecraft:concrete 8
setblock ~38~38~10 minecraft:polished_blackstone_button 3
setblock ~38~45~10 minecraft:polished_blackstone_button 3
fill ~38~57~10 ~40~59~10 minecraft:quartz_block
fill ~38~60~10 ~40~60~14 minecraft:planks
setblock ~39~42~10 minecraft:grindstone
setblock ~39~43~10 minecraft:carpet 8
fill ~39~47~10 ~40~47~10 minecraft:double_stone_block_slab3 
fill ~39~48~10 ~40~49~10 minecraft:stone_block_slab3 9
setblock ~39~61~10 minecraft:dark_oak_fence_gate 2
setblock ~40~45~10 minecraft:polished_blackstone_button 3
setblock ~41~25~10 minecraft:oak_stairs 5
setblock ~41~26~10 minecraft:stained_glass 15
setblock ~41~27~10 minecraft:smooth_red_sandstone_stairs
setblock ~41~31~10 minecraft:normal_stone_stairs 7
fill ~41~32~10 ~41~32~11 minecraft:stone
fill ~41~40~10 ~41~40~12 minecraft:stone_block_slab3 9
setblock ~41~44~10 minecraft:lantern
setblock ~41~45~10 minecraft:stone
fill ~41~47~10 ~41~47~13 minecraft:wood
fill ~41~48~10 ~41~49~13 minecraft:quartz_block
setblock ~41~50~10 minecraft:normal_stone_stairs 2
fill ~41~60~10 ~42~60~10 minecraft:concrete 8
fill ~41~61~10 ~43~61~10 minecraft:iron_bars
fill ~42~25~10 ~47~25~10 minecraft:stone_block_slab
fill ~42~27~10 ~48~27~10 minecraft:stone_block_slab3 9
setblock ~42~28~10 minecraft:chain
setblock ~42~29~10 minecraft:cobblestone_wall
fill ~42~31~10 ~47~31~10 minecraft:smooth_quartz_stairs 7
fill ~42~32~10 ~47~32~12 minecraft:coal_block
setblock ~42~47~10 minecraft:bed 2
fill ~42~50~10 ~47~50~10 minecraft:smooth_quartz_stairs 2
fill ~42~54~10 ~42~54~11 minecraft:stone_block_slab4 9
fill ~42~55~10 ~42~55~12 minecraft:quartz_block
fill ~42~56~10 ~42~56~14 minecraft:stone_block_slab4
setblock ~43~28~10 minecraft:wooden_slab
fill ~43~34~10 ~47~34~10 minecraft:coal_block
setblock ~43~45~10 minecraft:polished_blackstone_button 3
fill ~43~49~10 ~43~49~11 minecraft:acacia_button 4
setblock ~44~28~10 minecraft:double_wooden_slab
fill ~44~35~10 ~45~35~10 minecraft:coal_block
setblock ~44~42~10 minecraft:grindstone
setblock ~44~43~10 minecraft:carpet 8
fill ~44~47~10 ~44~47~11 minecraft:barrel 1
fill ~44~48~10 ~44~49~11 minecraft:stained_hardened_clay 9
setblock ~45~28~10 minecraft:planks
setblock ~45~38~10 minecraft:polished_blackstone_button 3
setblock ~45~45~10 minecraft:polished_blackstone_button 3
fill ~45~47~10 ~45~47~11 minecraft:wood
fill ~45~48~10 ~45~49~11 minecraft:quartz_block
setblock ~46~28~10 minecraft:spruce_stairs 1
setblock ~46~42~10 minecraft:grindstone
setblock ~46~43~10 minecraft:carpet 8
setblock ~46~47~10 minecraft:cauldron
setblock ~46~48~10 minecraft:tripwire_hook
setblock ~46~49~10 minecraft:wall_banner 3
setblock ~47~28~10 minecraft:cobblestone_wall
setblock ~47~29~10 minecraft:flower_pot
setblock ~47~45~10 minecraft:polished_blackstone_button 3
setblock ~47~47~10 minecraft:barrel
setblock ~47~49~10 minecraft:lantern
setblock ~48~25~10 minecraft:double_stone_block_slab
setblock ~48~26~10 minecraft:blast_furnace 4
setblock ~48~28~10 minecraft:chain
setblock ~48~29~10 minecraft:cobblestone_wall
setblock ~48~31~10 minecraft:normal_stone_stairs 7
fill ~48~32~10 ~48~32~11 minecraft:stone
fill ~48~40~10 ~48~40~12 minecraft:stone_block_slab3 9
setblock ~48~44~10 minecraft:lantern
setblock ~48~45~10 minecraft:stone
fill ~48~47~10 ~48~47~13 minecraft:wood
fill ~48~48~10 ~48~49~13 minecraft:quartz_block
setblock ~48~50~10 minecraft:normal_stone_stairs 2
fill ~48~51~10 ~56~51~10 minecraft:oak_stairs 8
setblock ~48~52~10 minecraft:wood
fill ~48~53~10 ~49~53~10 minecraft:stone_block_slab3
fill ~48~55~10 ~48~55~11 minecraft:cobblestone_wall
setblock ~49~25~10 minecraft:oak_stairs 6
setblock ~49~26~10 minecraft:stripped_oak_log
setblock ~49~27~10 minecraft:smooth_red_sandstone_stairs 1
setblock ~49~28~10 minecraft:spruce_stairs
fill ~49~31~10 ~55~31~10 minecraft:smooth_quartz_stairs 7
fill ~49~32~10 ~55~32~12 minecraft:coal_block
fill ~49~47~10 ~52~47~10 minecraft:barrel
fill ~49~48~10 ~50~49~10 minecraft:stained_hardened_clay 9
fill ~49~50~10 ~55~50~10 minecraft:smooth_quartz_stairs 2
setblock ~50~45~10 minecraft:polished_blackstone_button 3
setblock ~50~52~10 minecraft:wood
fill ~50~53~10 ~54~53~10 minecraft:smooth_red_sandstone_stairs 3
fill ~51~35~10 ~53~35~10 minecraft:coal_block
setblock ~51~42~10 minecraft:grindstone
setblock ~51~43~10 minecraft:carpet 8
setblock ~51~49~10 minecraft:lantern
setblock ~51~52~10 minecraft:stone_block_slab
setblock ~52~38~10 minecraft:polished_blackstone_button 3
setblock ~52~45~10 minecraft:polished_blackstone_button 3
fill ~52~48~10 ~52~49~10 minecraft:bookshelf
setblock ~52~52~10 minecraft:wood
setblock ~53~25~10 minecraft:oak_stairs 5
setblock ~53~26~10 minecraft:stained_glass 15
setblock ~53~27~10 minecraft:smooth_red_sandstone_stairs
setblock ~53~42~10 minecraft:grindstone
setblock ~53~43~10 minecraft:carpet 8
setblock ~53~47~10 minecraft:wood
fill ~53~48~10 ~53~49~10 minecraft:quartz_block
setblock ~53~52~10 minecraft:stone_block_slab
fill ~54~25~10 ~59~25~10 minecraft:stone_block_slab
fill ~54~27~10 ~60~27~10 minecraft:stone_block_slab3 9
setblock ~54~28~10 minecraft:chain
setblock ~54~29~10 minecraft:cobblestone_wall
setblock ~54~45~10 minecraft:polished_blackstone_button 3
setblock ~54~47~10 minecraft:cauldron
setblock ~54~48~10 minecraft:tripwire_hook
setblock ~54~49~10 minecraft:wall_banner 3
setblock ~54~52~10 minecraft:wood
setblock ~55~28~10 minecraft:wooden_slab
setblock ~55~49~10 minecraft:lantern
fill ~55~53~10 ~56~53~10 minecraft:stone_block_slab3
setblock ~56~28~10 minecraft:double_wooden_slab
setblock ~56~31~10 minecraft:normal_stone_stairs 7
fill ~56~32~10 ~56~32~11 minecraft:stone
fill ~56~40~10 ~56~40~12 minecraft:stone_block_slab3 9
setblock ~56~44~10 minecraft:lantern
setblock ~56~45~10 minecraft:stone
fill ~56~47~10 ~56~47~13 minecraft:wood
fill ~56~48~10 ~56~49~13 minecraft:quartz_block
setblock ~56~50~10 minecraft:normal_stone_stairs 2
setblock ~56~52~10 minecraft:wood
fill ~56~55~10 ~56~55~11 minecraft:cobblestone_wall
setblock ~57~28~10 minecraft:planks
fill ~57~31~10 ~62~31~10 minecraft:smooth_quartz_stairs 7
fill ~57~32~10 ~62~32~12 minecraft:coal_block
setblock ~57~45~10 minecraft:polished_blackstone_button 3
setblock ~57~47~10 minecraft:barrel
setblock ~57~49~10 minecraft:lantern
fill ~57~50~10 ~62~50~10 minecraft:smooth_quartz_stairs 2
setblock ~57~52~10 minecraft:grindstone 3
setblock ~58~28~10 minecraft:spruce_stairs 1
setblock ~58~42~10 minecraft:grindstone
setblock ~58~43~10 minecraft:carpet 8
setblock ~58~47~10 minecraft:cauldron
setblock ~58~48~10 minecraft:tripwire_hook
setblock ~58~49~10 minecraft:wall_banner 3
setblock ~59~28~10 minecraft:cobblestone_wall
setblock ~59~29~10 minecraft:flower_pot
setblock ~59~38~10 minecraft:polished_blackstone_button 3
setblock ~59~45~10 minecraft:polished_blackstone_button 3
fill ~59~47~10 ~59~47~11 minecraft:wood
fill ~59~48~10 ~59~49~11 minecraft:quartz_block
setblock ~60~25~10 minecraft:double_stone_block_slab
setblock ~60~26~10 minecraft:blast_furnace 4
setblock ~60~28~10 minecraft:chain
setblock ~60~29~10 minecraft:cobblestone_wall
setblock ~60~42~10 minecraft:grindstone
setblock ~60~43~10 minecraft:carpet 8
fill ~60~47~10 ~60~47~11 minecraft:barrel 3
fill ~60~48~10 ~60~49~11 minecraft:stained_hardened_clay 9
setblock ~61~25~10 minecraft:oak_stairs 6
setblock ~61~26~10 minecraft:stripped_oak_log
setblock ~61~27~10 minecraft:smooth_red_sandstone_stairs 1
setblock ~61~28~10 minecraft:spruce_stairs
setblock ~61~45~10 minecraft:polished_blackstone_button 3
fill ~61~49~10 ~61~49~11 minecraft:acacia_button 5
setblock ~62~47~10 minecraft:bed 2
fill ~62~54~10 ~62~54~11 minecraft:stone_block_slab4 9
fill ~62~55~10 ~62~55~12 minecraft:quartz_block
fill ~62~56~10 ~62~56~14 minecraft:stone_block_slab4
fill ~62~61~10 ~63~61~10 minecraft:iron_bars
setblock ~63~31~10 minecraft:normal_stone_stairs 7
fill ~63~32~10 ~63~32~11 minecraft:stone
fill ~63~40~10 ~63~40~15 minecraft:stone_block_slab3 9
setblock ~63~44~10 minecraft:lantern
setblock ~63~45~10 minecraft:stone
fill ~63~47~10 ~63~47~13 minecraft:wood
fill ~63~48~10 ~63~49~13 minecraft:quartz_block
setblock ~63~50~10 minecraft:normal_stone_stairs 2
fill ~63~53~10 ~67~53~10 minecraft:polished_blackstone_stairs 7
fill ~63~54~10 ~67~54~10 minecraft:polished_blackstone
setblock ~63~60~10 minecraft:concrete 8
fill ~64~31~10 ~68~31~10 minecraft:smooth_quartz_stairs 7
fill ~64~32~10 ~68~32~12 minecraft:coal_block
setblock ~64~45~10 minecraft:polished_blackstone_button 3
fill ~64~47~10 ~65~47~10 minecraft:barrel
fill ~64~48~10 ~65~49~10 minecraft:stained_hardened_clay 9
fill ~64~50~10 ~68~50~10 minecraft:smooth_quartz_stairs 2
fill ~64~57~10 ~66~59~10 minecraft:quartz_block
fill ~64~60~10 ~66~60~28 minecraft:planks
fill ~65~35~10 ~67~35~10 minecraft:coal_block
setblock ~65~42~10 minecraft:grindstone
setblock ~65~43~10 minecraft:carpet 8
setblock ~65~61~10 minecraft:dark_oak_fence_gate 2
setblock ~66~38~10 minecraft:polished_blackstone_button 3
setblock ~66~45~10 minecraft:polished_blackstone_button 3
setblock ~66~47~10 minecraft:wood
fill ~66~48~10 ~66~49~10 minecraft:quartz_block
setblock ~67~42~10 minecraft:grindstone
setblock ~67~43~10 minecraft:carpet 8
fill ~67~60~10 ~68~60~10 minecraft:concrete 8
fill ~67~61~10 ~69~61~10 minecraft:iron_bars
setblock ~68~45~10 minecraft:polished_blackstone_button 3
setblock ~68~47~10 minecraft:cauldron
setblock ~68~48~10 minecraft:tripwire_hook
setblock ~68~49~10 minecraft:wall_banner 3
fill ~68~54~10 ~68~54~11 minecraft:stone_block_slab4 9
fill ~68~55~10 ~68~55~12 minecraft:quartz_block
fill ~68~56~10 ~68~56~14 minecraft:stone_block_slab4
setblock ~69~31~10 minecraft:normal_stone_stairs 7
fill ~69~32~10 ~69~32~11 minecraft:stone
fill ~69~40~10 ~69~40~15 minecraft:stone_block_slab3 9
setblock ~69~44~10 minecraft:lantern
setblock ~69~45~10 minecraft:stone
fill ~69~47~10 ~69~47~13 minecraft:wood
fill ~69~48~10 ~69~49~13 minecraft:quartz_block
setblock ~69~50~10 minecraft:normal_stone_stairs 2
setblock ~70~31~10 minecraft:smooth_quartz_stairs 7
fill ~70~32~10 ~70~32~12 minecraft:coal_block
setblock ~70~47~10 minecraft:barrel
fill ~70~48~10 ~70~49~10 minecraft:wood
fill ~70~50~10 ~71~50~10 minecraft:smooth_quartz_stairs 2
fill ~71~32~10 ~72~32~10 minecraft:quartz_block
fill ~71~33~10 ~72~33~12 minecraft:coal_block
fill ~71~34~10 ~73~34~10 minecraft:coal_block
setblock ~71~37~10 minecraft:barrel 1
setblock ~71~42~10 minecraft:barrel 1
fill ~71~47~10 ~73~47~10 minecraft:concrete 8
fill ~71~48~10 ~74~48~10 minecraft:quartz_block
setblock ~71~49~10 minecraft:quartz_block
fill ~72~35~10 ~74~35~10 minecraft:coal_block
fill ~72~36~10 ~74~36~28 minecraft:stone
fill ~72~37~10 ~74~40~10 minecraft:stone
fill ~72~41~10 ~74~41~28 minecraft:stone
fill ~72~42~10 ~74~45~10 minecraft:stone
fill ~72~46~10 ~73~46~28 minecraft:stone
fill ~72~49~10 ~74~49~10 minecraft:smooth_quartz_stairs 2
fill ~73~32~10 ~74~32~10 minecraft:smooth_quartz_stairs 7
fill ~73~33~10 ~74~33~10 minecraft:quartz_block
fill ~74~34~10 ~75~34~10 minecraft:quartz_block
setblock ~74~46~10 minecraft:concrete 14
setblock ~74~47~10 minecraft:quartz_block
setblock ~75~33~10 minecraft:smooth_quartz_stairs 6
fill ~75~35~10 ~76~35~10 minecraft:quartz_block
fill ~75~36~10 ~76~36~10 minecraft:concrete 8
fill ~75~37~10 ~76~37~12 minecraft:stone_block_slab4
setblock ~75~38~10 minecraft:spruce_trapdoor 9
fill ~75~39~10 ~76~39~12 minecraft:stone_block_slab4 9
fill ~75~40~10 ~76~41~10 minecraft:concrete 8
fill ~75~42~10 ~76~42~12 minecraft:stone_block_slab4
setblock ~75~43~10 minecraft:spruce_trapdoor 9
fill ~75~44~10 ~76~44~12 minecraft:stone_block_slab4 9
fill ~75~45~10 ~76~45~10 minecraft:concrete 8
fill ~75~46~10 ~76~46~10 minecraft:quartz_block
fill ~75~47~10 ~76~47~10 minecraft:smooth_quartz_stairs 2
setblock ~76~34~10 minecraft:smooth_quartz_stairs 6
setblock ~83~27~10 minecraft:smooth_quartz_stairs 8
setblock ~83~28~10 minecraft:quartz_block
setblock ~83~29~10 minecraft:spruce_trapdoor 9
setblock ~83~30~10 minecraft:quartz_block
setblock ~85~26~10 minecraft:polished_blackstone_stairs 2
fill ~86~28~10 ~87~28~10 minecraft:polished_blackstone_stairs 7
fill ~86~29~10 ~87~29~10 minecraft:polished_blackstone
fill ~86~30~10 ~87~30~10 minecraft:polished_blackstone_stairs 2
fill ~86~31~10 ~87~32~12 minecraft:stained_hardened_clay 14
setblock ~88~26~10 minecraft:polished_blackstone_stairs 2
setblock ~89~28~10 minecraft:quartz_block
setblock ~89~29~10 minecraft:spruce_trapdoor 9
setblock ~89~30~10 minecraft:quartz_block
setblock ~89~31~10 minecraft:smooth_quartz_stairs 3
setblock ~93~27~10 minecraft:smooth_quartz_stairs 8
setblock ~93~28~10 minecraft:quartz_block
setblock ~93~29~10 minecraft:spruce_trapdoor 9
setblock ~93~30~10 minecraft:quartz_block
fill ~94~24~10 ~94~24~12 minecraft:stone
setblock ~94~26~10 minecraft:polished_blackstone_stairs 2
fill ~94~34~10 ~94~34~12 minecraft:stone
fill ~95~28~10 ~96~28~10 minecraft:polished_blackstone_stairs 7
fill ~95~29~10 ~96~29~10 minecraft:polished_blackstone
fill ~95~30~10 ~96~30~10 minecraft:polished_blackstone_stairs 2
fill ~95~31~10 ~96~32~12 minecraft:stained_hardened_clay 14
fill ~96~24~10 ~96~24~12 minecraft:stone
fill ~96~34~10 ~96~34~12 minecraft:stone
setblock ~97~26~10 minecraft:polished_blackstone_stairs 2
fill ~98~24~10 ~98~24~12 minecraft:stone
fill ~98~34~10 ~98~34~12 minecraft:stone
setblock ~99~28~10 minecraft:quartz_block
setblock ~99~29~10 minecraft:spruce_trapdoor 9
setblock ~99~30~10 minecraft:quartz_block
setblock ~99~31~10 minecraft:smooth_quartz_stairs 3
fill ~26~34~11 ~27~34~11 minecraft:smooth_quartz_stairs 7
fill ~26~35~11 ~27~35~11 minecraft:quartz_block
fill ~26~36~11 ~27~36~11 minecraft:concrete 8
fill ~26~37~11 ~27~37~12 minecraft:stone_block_slab4
fill ~26~39~11 ~27~39~12 minecraft:stone_block_slab4 9
fill ~26~40~11 ~27~41~11 minecraft:concrete 8
fill ~26~42~11 ~27~42~12 minecraft:stone_block_slab4
fill ~26~44~11 ~27~44~12 minecraft:stone_block_slab4 9
fill ~26~45~11 ~27~45~11 minecraft:concrete 8
fill ~26~46~11 ~27~46~11 minecraft:quartz_block
fill ~26~47~11 ~27~47~11 minecraft:smooth_quartz_stairs 2
fill ~28~33~11 ~29~33~11 minecraft:quartz_block
fill ~28~34~11 ~28~34~13 minecraft:quartz_block
fill ~28~35~11 ~28~35~13 minecraft:double_stone_block_slab3
fill ~28~36~11 ~29~36~27 minecraft:stone
fill ~28~38~11 ~33~38~11 minecraft:polished_basalt
fill ~28~41~11 ~29~41~16 minecraft:stone
fill ~28~43~11 ~33~43~11 minecraft:polished_basalt
fill ~28~45~11 ~29~45~12 minecraft:quartz_block
fill ~28~46~11 ~29~46~17 minecraft:stone
fill ~28~47~11 ~28~48~11 minecraft:quartz_block
fill ~28~49~11 ~29~49~11 minecraft:smooth_quartz_stairs 2
setblock ~29~32~11 minecraft:smooth_quartz_stairs 7
fill ~29~34~11 ~32~35~11 minecraft:concrete 8
fill ~29~47~11 ~30~47~11 minecraft:wood
fill ~29~48~11 ~30~48~12 minecraft:quartz_block
fill ~30~31~11 ~31~31~11 minecraft:smooth_quartz_stairs 7
setblock ~30~32~11 minecraft:quartz_block
fill ~30~33~11 ~32~33~11 minecraft:concrete 8
fill ~30~37~11 ~30~37~12 minecraft:stone
fill ~30~39~11 ~30~40~12 minecraft:stone
fill ~30~42~11 ~30~42~12 minecraft:stone
fill ~30~44~11 ~30~45~12 minecraft:stone
fill ~30~49~11 ~30~49~12 minecraft:quartz_block
fill ~30~50~11 ~32~50~11 minecraft:smooth_quartz_stairs 2
fill ~31~32~11 ~32~32~12 minecraft:stained_hardened_clay 8
fill ~31~37~11 ~34~37~11 minecraft:stone_block_slab3 9
setblock ~31~39~11 minecraft:cobblestone_wall
fill ~31~40~11 ~32~40~12 minecraft:stone
fill ~31~42~11 ~34~42~11 minecraft:stone_block_slab3 9
setblock ~31~44~11 minecraft:cobblestone_wall
fill ~31~45~11 ~32~45~12 minecraft:stone
setblock ~31~47~11 minecraft:hopper 4
setblock ~31~48~11 minecraft:spruce_trapdoor
setblock ~31~49~11 minecraft:air
fill ~32~31~11 ~34~31~12 minecraft:quartz_block
setblock ~32~39~11 minecraft:carpet 8
setblock ~32~44~11 minecraft:carpet 8
setblock ~33~32~11 minecraft:hopper 2
setblock ~33~33~11 minecraft:spruce_trapdoor 2
setblock ~33~35~11 minecraft:lantern
fill ~33~50~11 ~33~50~12 minecraft:quartz_block
fill ~33~51~11 ~34~51~11 minecraft:stone_block_slab4
fill ~34~29~11 ~34~29~14 minecraft:cobblestone_wall
fill ~34~32~11 ~34~32~13 minecraft:stained_hardened_clay 8
setblock ~34~38~11 minecraft:polished_blackstone_button 5
setblock ~34~43~11 minecraft:polished_blackstone_button 5
setblock ~34~47~11 minecraft:iron_trapdoor 1
setblock ~34~50~11 minecraft:dispenser
setblock ~35~31~11 minecraft:stone
setblock ~35~33~11 minecraft:cobblestone_wall
setblock ~35~34~11 minecraft:cobblestone_wall
setblock ~35~35~11 minecraft:double_stone_block_slab3
fill ~35~45~11 ~35~45~27 minecraft:stone_block_slab3 9
fill ~35~50~11 ~35~50~13 minecraft:quartz_block
setblock ~35~51~11 minecraft:stone_block_slab4
fill ~36~31~11 ~40~31~12 minecraft:quartz_block
fill ~36~47~11 ~37~49~11 minecraft:stone_block_slab3 
fill ~36~50~11 ~37~50~13 minecraft:concrete 8
fill ~36~51~11 ~40~51~11 minecraft:stone_block_slab4
setblock ~36~58~11 minecraft:spruce_trapdoor 9
fill ~36~60~11 ~36~60~13 minecraft:concrete 8
setblock ~36~61~11 minecraft:iron_bars
fill ~37~34~11 ~39~34~11 minecraft:coal_block
setblock ~37~53~11 minecraft:polished_blackstone_stairs 5
setblock ~37~54~11 minecraft:polished_blackstone
fill ~37~55~11 ~37~55~14 minecraft:quartz_block
fill ~37~56~11 ~37~56~15 minecraft:stone_block_slab4
fill ~37~57~11 ~37~59~11 minecraft:quartz_block
fill ~37~60~11 ~37~60~17 minecraft:planks
setblock ~38~43~11 minecraft:polished_blackstone_button 3
setblock ~38~50~11 minecraft:stone_block_slab 9
setblock ~38~52~11 minecraft:polished_blackstone_stairs 5
fill ~38~55~11 ~40~56~13 minecraft:concrete 8
setblock ~38~57~11 minecraft:cobblestone_wall
setblock ~38~58~11 minecraft:cobblestone_wall
fill ~38~59~11 ~40~59~13 minecraft:stone_block_slab4 9
fill ~39~47~11 ~40~49~11 minecraft:stone_block_slab3 
fill ~39~50~11 ~40~50~13 minecraft:concrete 8
setblock ~39~52~11 minecraft:polished_blackstone_stairs 7
setblock ~39~57~11 minecraft:barrel 5
setblock ~39~58~11 minecraft:torch
setblock ~40~52~11 minecraft:polished_blackstone_stairs 6
setblock ~41~31~11 minecraft:double_stone_block_slab4
setblock ~41~33~11 minecraft:cobblestone_wall
setblock ~41~34~11 minecraft:cobblestone_wall
setblock ~41~35~11 minecraft:double_stone_block_slab3
fill ~41~45~11 ~41~45~12 minecraft:stone_block_slab3 9
fill ~41~50~11 ~41~50~13 minecraft:quartz_block
setblock ~41~51~11 minecraft:stone_block_slab4
setblock ~41~53~11 minecraft:polished_blackstone_stairs 6
setblock ~41~54~11 minecraft:polished_blackstone
fill ~41~55~11 ~41~55~14 minecraft:quartz_block
fill ~41~56~11 ~41~56~15 minecraft:stone_block_slab4
setblock ~41~59~11 minecraft:smooth_quartz_stairs 6
fill ~41~60~11 ~42~60~27 minecraft:planks
fill ~42~25~11 ~43~25~11 minecraft:oak_stairs 8
setblock ~42~26~11 minecraft:stripped_oak_log
setblock ~42~27~11 minecraft:smooth_red_sandstone_stairs 3
fill ~42~29~11 ~42~29~14 minecraft:cobblestone_wall
fill ~42~31~11 ~47~31~12 minecraft:quartz_block
fill ~42~50~11 ~44~50~12 minecraft:wooden_slab 9
fill ~42~51~11 ~47~51~11 minecraft:stone_block_slab4
fill ~43~28~11 ~45~28~11 minecraft:smooth_red_sandstone_stairs 2
fill ~43~34~11 ~46~34~11 minecraft:coal_block
fill ~43~60~11 ~44~60~11 minecraft:concrete 8
fill ~43~61~11 ~45~61~11 minecraft:iron_bars
fill ~44~25~11 ~46~25~11 minecraft:planks 
setblock ~45~43~11 minecraft:polished_blackstone_button 3
fill ~45~50~11 ~45~50~14 minecraft:quartz_block
setblock ~46~26~11 minecraft:stripped_oak_log
fill ~46~27~11 ~48~27~11 minecraft:smooth_red_sandstone_stairs 3
fill ~46~50~11 ~47~50~12 minecraft:wooden_slab 9
fill ~47~25~11 ~48~25~11 minecraft:oak_stairs 8
setblock ~47~26~11 minecraft:dispenser 5
setblock ~48~26~11 minecraft:dispenser 4
setblock ~48~29~11 minecraft:cobblestone_wall
setblock ~48~31~11 minecraft:stone
setblock ~48~33~11 minecraft:cobblestone_wall
setblock ~48~34~11 minecraft:cobblestone_wall
setblock ~48~35~11 minecraft:double_stone_block_slab3
fill ~48~45~11 ~48~45~12 minecraft:stone_block_slab3 9
fill ~48~50~11 ~48~50~13 minecraft:double_wooden_slab
setblock ~48~51~11 minecraft:stone_block_slab4
setblock ~49~25~11 minecraft:wooden_slab 9
setblock ~49~26~11 minecraft:lantern
setblock ~49~27~11 minecraft:wooden_slab
fill ~49~31~11 ~55~31~12 minecraft:quartz_block
fill ~49~48~11 ~50~48~11 minecraft:acacia_button 3
fill ~49~50~11 ~52~50~13 minecraft:wooden_slab 9
fill ~49~51~11 ~55~51~11 minecraft:stone_block_slab4
setblock ~49~52~11 minecraft:spruce_trapdoor 7
fill ~50~14~11 ~52~14~11 minecraft:wooden_slab
fill ~50~34~11 ~53~34~11 minecraft:coal_block
setblock ~52~43~11 minecraft:polished_blackstone_button 3
fill ~52~52~11 ~52~54~11 minecraft:ladder 2
fill ~53~14~11 ~54~14~11 minecraft:polished_andesite_stairs 7
fill ~53~15~11 ~54~15~11 minecraft:polished_andesite_stairs 2
setblock ~53~47~11 minecraft:dark_oak_door
fill ~53~49~11 ~53~49~14 minecraft:quartz_block
fill ~53~50~11 ~53~50~13 minecraft:double_wooden_slab
fill ~54~25~11 ~55~25~11 minecraft:oak_stairs 8
setblock ~54~26~11 minecraft:stripped_oak_log
setblock ~54~27~11 minecraft:smooth_red_sandstone_stairs 3
fill ~54~29~11 ~54~29~12 minecraft:cobblestone_wall
fill ~54~50~11 ~55~50~12 minecraft:wooden_slab 9
fill ~55~28~11 ~57~28~11 minecraft:smooth_red_sandstone_stairs 2
setblock ~55~52~11 minecraft:spruce_trapdoor 7
fill ~56~25~11 ~58~25~11 minecraft:planks 
setblock ~56~31~11 minecraft:stone
setblock ~56~33~11 minecraft:cobblestone_wall
setblock ~56~34~11 minecraft:cobblestone_wall
setblock ~56~35~11 minecraft:double_stone_block_slab3
fill ~56~45~11 ~56~45~12 minecraft:stone_block_slab3 9
fill ~56~50~11 ~56~50~13 minecraft:quartz_block
setblock ~56~51~11 minecraft:stone_block_slab4
fill ~57~31~11 ~62~31~12 minecraft:quartz_block
fill ~57~50~11 ~58~50~12 minecraft:wooden_slab 9
fill ~57~51~11 ~62~51~11 minecraft:stone_block_slab4
setblock ~58~26~11 minecraft:stripped_oak_log
fill ~58~27~11 ~60~27~11 minecraft:smooth_red_sandstone_stairs 3
fill ~58~34~11 ~61~34~11 minecraft:coal_block
fill ~59~25~11 ~60~25~11 minecraft:oak_stairs 8
setblock ~59~26~11 minecraft:dispenser 5
setblock ~59~43~11 minecraft:polished_blackstone_button 3
fill ~59~50~11 ~59~50~14 minecraft:quartz_block
setblock ~60~26~11 minecraft:dispenser 4
fill ~60~29~11 ~60~29~14 minecraft:cobblestone_wall
fill ~60~50~11 ~62~50~12 minecraft:wooden_slab 9
setblock ~61~25~11 minecraft:wooden_slab 9
setblock ~61~26~11 minecraft:lantern
setblock ~61~27~11 minecraft:wooden_slab
setblock ~61~61~11 minecraft:jungle_fence_gate
fill ~62~60~11 ~62~60~13 minecraft:concrete 8
setblock ~62~61~11 minecraft:anvil 1
setblock ~63~31~11 minecraft:double_stone_block_slab4
setblock ~63~33~11 minecraft:cobblestone_wall
setblock ~63~34~11 minecraft:cobblestone_wall
setblock ~63~35~11 minecraft:double_stone_block_slab3
fill ~63~45~11 ~63~45~13 minecraft:stone_block_slab3 9
fill ~63~50~11 ~63~50~13 minecraft:quartz_block
setblock ~63~51~11 minecraft:stone_block_slab4
setblock ~63~53~11 minecraft:polished_blackstone_stairs 5
setblock ~63~54~11 minecraft:polished_blackstone
fill ~63~55~11 ~63~55~14 minecraft:quartz_block
fill ~63~56~11 ~63~56~15 minecraft:stone_block_slab4
setblock ~63~59~11 minecraft:smooth_quartz_stairs 5
fill ~63~60~11 ~63~60~27 minecraft:planks
setblock ~63~61~11 minecraft:dark_oak_fence_gate 1
fill ~64~31~11 ~68~31~12 minecraft:quartz_block
setblock ~64~47~11 minecraft:bed 2
fill ~64~48~11 ~65~48~11 minecraft:acacia_button 3
fill ~64~50~11 ~65~50~12 minecraft:wooden_slab 9
fill ~64~51~11 ~68~51~11 minecraft:stone_block_slab4
setblock ~64~52~11 minecraft:polished_blackstone_stairs 5
fill ~64~55~11 ~66~56~13 minecraft:concrete 8
fill ~64~59~11 ~66~59~13 minecraft:stone_block_slab4 9
fill ~65~34~11 ~67~34~11 minecraft:coal_block
setblock ~65~52~11 minecraft:polished_blackstone_stairs 7
setblock ~65~57~11 minecraft:barrel 1
setblock ~65~58~11 minecraft:torch
setblock ~66~43~11 minecraft:polished_blackstone_button 3
setblock ~66~47~11 minecraft:dark_oak_door
fill ~66~49~11 ~66~49~14 minecraft:quartz_block
fill ~66~50~11 ~66~50~13 minecraft:double_wooden_slab
setblock ~66~52~11 minecraft:polished_blackstone_stairs 6
setblock ~66~57~11 minecraft:cobblestone_wall
setblock ~66~58~11 minecraft:cobblestone_wall
fill ~67~50~11 ~67~50~12 minecraft:wooden_slab 9
setblock ~67~53~11 minecraft:polished_blackstone_stairs 6
setblock ~67~54~11 minecraft:polished_blackstone
fill ~67~55~11 ~67~55~14 minecraft:quartz_block
fill ~67~56~11 ~67~56~15 minecraft:stone_block_slab4
fill ~67~57~11 ~67~59~11 minecraft:quartz_block
fill ~67~60~11 ~68~60~27 minecraft:planks
setblock ~68~49~11 minecraft:lantern
setblock ~68~50~11 minecraft:double_wooden_slab
setblock ~68~58~11 minecraft:spruce_trapdoor 9
fill ~69~31~11 ~69~31~12 minecraft:stone
setblock ~69~33~11 minecraft:cobblestone_wall
setblock ~69~34~11 minecraft:cobblestone_wall
setblock ~69~35~11 minecraft:double_stone_block_slab3
fill ~69~45~11 ~69~45~16 minecraft:stone_block_slab3 9
fill ~69~50~11 ~69~50~13 minecraft:quartz_block
setblock ~69~51~11 minecraft:stone_block_slab4
fill ~69~60~11 ~70~60~11 minecraft:concrete 8
fill ~69~61~11 ~71~61~11 minecraft:iron_bars
fill ~70~31~11 ~70~31~12 minecraft:quartz_block
fill ~70~37~11 ~73~37~11 minecraft:stone_block_slab3 9
setblock ~70~38~11 minecraft:polished_blackstone_button 4
fill ~70~42~11 ~72~42~11 minecraft:stone_block_slab3 9
setblock ~70~43~11 minecraft:polished_blackstone_button 4
fill ~70~50~11 ~70~50~13 minecraft:wooden_slab 9
fill ~70~51~11 ~71~51~11 minecraft:stone_block_slab4
fill ~71~31~11 ~73~31~11 minecraft:smooth_quartz_stairs 7
fill ~71~32~11 ~73~32~12 minecraft:coal_block
fill ~71~34~11 ~72~34~11 minecraft:coal_block
fill ~71~38~11 ~76~38~11 minecraft:polished_basalt
fill ~71~43~11 ~72~43~11 minecraft:polished_basalt
setblock ~71~49~11 minecraft:lantern
setblock ~71~50~11 minecraft:quartz_block
fill ~72~40~11 ~74~40~12 minecraft:stone
setblock ~72~44~11 minecraft:carpet 8
fill ~72~45~11 ~74~45~12 minecraft:stone
setblock ~72~47~11 minecraft:wood
fill ~72~48~11 ~72~49~11 minecraft:quartz_block
fill ~72~50~11 ~74~50~11 minecraft:smooth_quartz_stairs 2
fill ~73~33~11 ~74~33~11 minecraft:coal_block
setblock ~73~47~11 minecraft:cauldron
setblock ~73~48~11 minecraft:tripwire_hook
fill ~73~49~11 ~74~49~11 minecraft:smooth_quartz_stairs 8
setblock ~74~31~11 minecraft:stone_block_slab4 9
setblock ~74~32~11 minecraft:quartz_block
fill ~74~34~11 ~75~34~11 minecraft:coal_block
fill ~74~37~11 ~74~37~12 minecraft:stone
fill ~74~39~11 ~74~39~12 minecraft:stone
fill ~74~42~11 ~74~44~12 minecraft:stone
fill ~74~46~11 ~76~46~12 minecraft:stone
setblock ~74~47~11 minecraft:barrel
fill ~75~32~11 ~76~32~11 minecraft:smooth_quartz_stairs 7
fill ~75~33~11 ~76~33~11 minecraft:quartz_block
fill ~75~35~11 ~76~35~11 minecraft:coal_block
fill ~75~36~11 ~76~36~12 minecraft:stone
fill ~75~40~11 ~76~40~13 minecraft:quartz_block
fill ~75~41~11 ~76~41~17 minecraft:stone
fill ~75~43~11 ~76~43~11 minecraft:polished_basalt
setblock ~75~47~11 minecraft:concrete 8
fill ~75~48~11 ~76~48~11 minecraft:quartz_block
fill ~75~49~11 ~76~49~11 minecraft:smooth_quartz_stairs 2
fill ~76~34~11 ~77~34~11 minecraft:quartz_block
setblock ~76~47~11 minecraft:quartz_block
setblock ~77~33~11 minecraft:smooth_quartz_stairs 6
fill ~77~35~11 ~78~35~11 minecraft:quartz_block
fill ~77~36~11 ~78~36~11 minecraft:concrete 8
fill ~77~37~11 ~78~37~12 minecraft:stone_block_slab4
fill ~77~39~11 ~78~39~12 minecraft:stone_block_slab4 9
fill ~77~40~11 ~78~41~11 minecraft:concrete 8
fill ~77~42~11 ~78~42~12 minecraft:stone_block_slab4
fill ~77~44~11 ~78~44~12 minecraft:stone_block_slab4 9
fill ~77~45~11 ~78~45~11 minecraft:concrete 8
fill ~77~46~11 ~78~46~11 minecraft:quartz_block
fill ~77~47~11 ~78~47~11 minecraft:smooth_quartz_stairs 2
setblock ~78~34~11 minecraft:smooth_quartz_stairs 6
setblock ~82~29~11 minecraft:polished_blackstone_button 4
setblock ~83~28~11 minecraft:spruce_trapdoor 7
fill ~83~29~11 ~89~29~11 minecraft:stone
setblock ~83~30~11 minecraft:spruce_trapdoor3
fill ~84~30~11 ~84~31~14 minecraft:iron_bars
fill ~85~26~11 ~85~28~11 minecraft:stone
fill ~85~30~11 ~85~32~11 minecraft:stone
fill ~86~26~11 ~87~26~11 minecraft:blast_furnace 2
fill ~86~27~11 ~87~27~11 minecraft:cobblestone_wall
fill ~86~28~11 ~87~28~11 minecraft:polished_blackstone
fill ~86~30~11 ~87~30~11 minecraft:polished_blackstone
fill ~88~26~11 ~88~28~11 minecraft:stone
fill ~88~30~11 ~88~32~11 minecraft:stone
setblock ~89~28~11 minecraft:spruce_trapdoor 7
setblock ~89~30~11 minecraft:spruce_trapdoor3
setblock ~90~29~11 minecraft:polished_blackstone_button 5
setblock ~92~29~11 minecraft:polished_blackstone_button 4
setblock ~93~28~11 minecraft:spruce_trapdoor 7
setblock ~93~29~11 minecraft:stone
setblock ~93~30~11 minecraft:spruce_trapdoor 2
fill ~94~26~11 ~94~28~11 minecraft:stone
fill ~94~30~11 ~94~32~11 minecraft:stone
fill ~95~26~11 ~96~26~11 minecraft:blast_furnace 2
fill ~95~27~11 ~96~27~11 minecraft:cobblestone_wall
fill ~95~28~11 ~96~28~11 minecraft:polished_blackstone
fill ~95~29~11 ~99~29~11 minecraft:stone
fill ~95~30~11 ~96~30~11 minecraft:polished_blackstone
fill ~97~26~11 ~97~28~11 minecraft:stone
fill ~97~30~11 ~97~32~11 minecraft:stone
fill ~98~30~11 ~98~31~14 minecraft:iron_bars
setblock ~99~28~11 minecraft:spruce_trapdoor 3
setblock ~99~30~11 minecraft:spruce_trapdoor 2
setblock ~25~34~12 minecraft:smooth_quartz_stairs 5
fill ~25~35~12 ~25~35~13 minecraft:quartz_block
setblock ~25~36~12 minecraft:concrete 8
setblock ~25~37~12 minecraft:stone_block_slab4
setblock ~25~39~12 minecraft:stone_block_slab4 9
fill ~25~40~12 ~25~41~12 minecraft:concrete 8
setblock ~25~42~12 minecraft:stone_block_slab4
setblock ~25~44~12 minecraft:stone_block_slab4 9
fill ~25~45~12 ~25~45~13 minecraft:concrete 8
fill ~25~46~12 ~25~46~13 minecraft:quartz_block
setblock ~25~47~12 minecraft:smooth_quartz_stairs
setblock ~26~33~12 minecraft:smooth_quartz_stairs 5
fill ~26~34~12 ~27~34~13 minecraft:quartz_block
fill ~26~35~12 ~27~35~13 minecraft:double_stone_block_slab3
fill ~26~36~12 ~27~36~17 minecraft:stone
fill ~26~41~12 ~27~41~16 minecraft:stone
fill ~26~45~12 ~27~45~12 minecraft:quartz_block
fill ~26~46~12 ~27~46~26 minecraft:stone
fill ~26~47~12 ~26~48~12 minecraft:quartz_block
setblock ~26~49~12 minecraft:smooth_quartz_stairs
setblock ~27~32~12 minecraft:smooth_quartz_stairs 5
fill ~27~33~12 ~28~33~13 minecraft:quartz_block
fill ~27~47~12 ~32~47~12 minecraft:wood
fill ~27~48~12 ~28~49~12 minecraft:quartz_block
fill ~28~32~12 ~28~32~13 minecraft:quartz_block
setblock ~28~50~12 minecraft:smooth_quartz_stairs
setblock ~29~31~12 minecraft:stone_block_slab4 9
fill ~29~32~12 ~29~32~13 minecraft:stained_hardened_clay 8
fill ~29~33~12 ~29~35~13 minecraft:concrete 8
setblock ~29~38~12 minecraft:spruce_trapdoor 7
setblock ~29~43~12 minecraft:spruce_trapdoor 7
fill ~29~49~12 ~29~50~12 minecraft:quartz_block
fill ~29~56~12 ~35~56~12 minecraft:iron_bars
fill ~30~31~12 ~31~31~12 minecraft:quartz_block
setblock ~30~32~12 minecraft:cauldron
setblock ~30~33~12 minecraft:tripwire_hook
fill ~30~38~12 ~32~38~12 minecraft:stone
fill ~30~43~12 ~32~43~12 minecraft:stone
fill ~30~50~12 ~32~50~12 minecraft:quartz_block
fill ~30~51~12 ~76~51~12 minecraft:concrete 8
fill ~30~52~12 ~56~52~12 minecraft:quartz_block
fill ~30~53~12 ~30~54~12 minecraft:quartz_block
fill ~30~55~12 ~35~55~12 minecraft:concrete 8
fill ~31~33~12 ~32~35~12 minecraft:concrete 8
fill ~31~37~12 ~32~37~12 minecraft:stone
fill ~31~39~12 ~32~39~12 minecraft:stone
fill ~31~42~12 ~32~42~12 minecraft:stone
fill ~31~44~12 ~32~44~12 minecraft:stone
fill ~31~48~12 ~32~49~12 minecraft:quartz_block
setblock ~31~53~12 minecraft:stained_glass_pane 15
fill ~31~54~12 ~76~54~12 minecraft:quartz_block
fill ~32~30~12 ~34~30~14 minecraft:stone_block_slab4 9
setblock ~32~53~12 minecraft:quartz_block
setblock ~33~32~12 minecraft:spruce_door 3
setblock ~33~34~12 minecraft:spruce_trapdoor 9
setblock ~33~35~12 minecraft:concrete 8
setblock ~33~37~12 minecraft:barrel 3
setblock ~33~42~12 minecraft:barrel 3
setblock ~33~47~12 minecraft:dark_oak_door 3
fill ~33~49~12 ~34~49~12 minecraft:quartz_block
setblock ~33~53~12 minecraft:stained_glass_pane 15
fill ~33~80~12 ~33~80~17 minecraft:polished_blackstone_slab 9
setblock ~34~26~12 minecraft:jungle_fence_gate 3
setblock ~34~47~12 minecraft:wood
setblock ~34~48~12 minecraft:quartz_block
setblock ~34~50~12 minecraft:quartz_block
fill ~34~53~12 ~43~53~12 minecraft:quartz_block
fill ~34~58~12 ~39~58~12 minecraft:polished_basalt
fill ~35~30~12 ~35~30~14 minecraft:smooth_quartz_stairs 5
setblock ~35~31~12 minecraft:quartz_block
setblock ~35~32~12 minecraft:polished_andesite_stairs 3
setblock ~35~34~12 minecraft:lantern
setblock ~35~35~12 minecraft:fence
setblock ~35~61~12 minecraft:jungle_fence_gate
fill ~36~28~12 ~38~28~12 minecraft:smooth_quartz_stairs 7
fill ~36~29~12 ~38~30~13 minecraft:quartz_block
fill ~36~47~12 ~36~49~12 minecraft:stone_block_slab3 9
setblock ~36~57~12 minecraft:spruce_trapdoor 1
setblock ~36~59~12 minecraft:spruce_trapdoor 1
setblock ~36~61~12 minecraft:anvil 3
fill ~37~33~12 ~39~33~12 minecraft:coal_block
setblock ~37~47~12 minecraft:double_stone_block_slab3 
fill ~37~48~12 ~37~49~12 minecraft:stone_block_slab3 9
setblock ~37~57~12 minecraft:stone_block_slab4
setblock ~37~59~12 minecraft:stone_block_slab4 9
setblock ~37~61~12 minecraft:dark_oak_fence_gate 1
setblock ~38~50~12 minecraft:lantern
setblock ~38~57~12 minecraft:concrete 8
fill ~39~30~12 ~39~30~14 minecraft:smooth_quartz_stairs 6
fill ~39~47~12 ~40~47~12 minecraft:double_stone_block_slab3 
fill ~39~48~12 ~40~49~12 minecraft:stone_block_slab3 9
fill ~39~57~12 ~40~57~12 minecraft:stone_block_slab3 9
fill ~40~30~12 ~45~30~14 minecraft:stone_block_slab4 9
setblock ~40~58~12 minecraft:polished_blackstone_button 5
setblock ~41~31~12 minecraft:quartz_block
kill @e[type=item,r=4]
setblock ~41~32~12 minecraft:polished_andesite_stairs 3
setblock ~41~34~12 minecraft:lantern
setblock ~41~35~12 minecraft:fence
setblock ~41~59~12 minecraft:stone_block_slab4 9
fill ~42~47~12 ~43~47~13 minecraft:carpet 8
setblock ~43~28~12 minecraft:stained_glass 15
fill ~43~33~12 ~46~33~12 minecraft:coal_block
fill ~43~55~12 ~61~55~12 minecraft:concrete 8
fill ~43~56~12 ~61~56~12 minecraft:iron_bars
fill ~43~60~12 ~44~60~26 minecraft:planks
fill ~44~24~12 ~46~24~12 minecraft:wooden_slab 9
setblock ~44~28~12 minecraft:wood
setblock ~44~53~12 minecraft:stained_glass_pane 15
setblock ~45~28~12 minecraft:stained_glass 15
setblock ~45~47~12 minecraft:dark_oak_door
fill ~45~49~12 ~45~49~14 minecraft:quartz_block
fill ~45~53~12 ~46~53~12 minecraft:quartz_block
fill ~45~60~12 ~46~60~12 minecraft:concrete 8
fill ~45~61~12 ~47~61~12 minecraft:iron_bars
fill ~46~13~12 ~52~13~12 minecraft:oak_stairs 7
fill ~46~14~12 ~52~14~12 minecraft:wood
setblock ~46~15~12 minecraft:red_sandstone 
setblock ~46~16~12 minecraft:smooth_red_sandstone_stairs
fill ~46~30~12 ~46~30~14 minecraft:smooth_quartz_stairs 5
setblock ~47~15~12 minecraft:stained_glass 15
fill ~47~16~12 ~51~16~12 minecraft:smooth_red_sandstone_stairs 2
fill ~47~26~12 ~48~26~12 minecraft:grindstone
setblock ~47~28~12 minecraft:smooth_quartz_stairs 7
fill ~47~29~12 ~47~30~13 minecraft:quartz_block
setblock ~47~53~12 minecraft:stained_glass_pane 15
setblock ~48~15~12 minecraft:red_sandstone 
fill ~48~29~12 ~48~29~13 minecraft:cobblestone_wall
fill ~48~30~12 ~48~30~14 minecraft:smooth_quartz_stairs 6
setblock ~48~31~12 minecraft:quartz_block
setblock ~48~32~12 minecraft:polished_andesite_stairs 3
setblock ~48~34~12 minecraft:lantern
setblock ~48~35~12 minecraft:fence
fill ~48~53~12 ~49~53~12 minecraft:quartz_block
setblock ~49~15~12 minecraft:stained_glass 15
setblock ~49~25~12 minecraft:wooden_slab
setblock ~49~27~12 minecraft:wooden_slab 9
fill ~49~30~12 ~53~30~14 minecraft:stone_block_slab4 9
fill ~49~47~12 ~49~47~13 minecraft:bed 1
setblock ~50~15~12 minecraft:red_sandstone 
fill ~50~33~12 ~54~33~12 minecraft:coal_block
setblock ~50~53~12 minecraft:stained_glass_pane 15
setblock ~51~15~12 minecraft:stained_glass 15
fill ~51~47~12 ~52~47~13 minecraft:carpet 8
fill ~51~53~12 ~53~53~12 minecraft:quartz_block
setblock ~52~15~12 minecraft:red_sandstone 
setblock ~52~16~12 minecraft:smooth_red_sandstone_stairs 1
fill ~53~13~12 ~54~13~12 minecraft:stone_block_slab 9
fill ~53~14~12 ~54~15~12 minecraft:dispenser 5
fill ~53~16~12 ~54~16~12 minecraft:stone_block_slab
fill ~53~47~12 ~53~47~14 minecraft:wood
fill ~53~48~12 ~53~48~14 minecraft:quartz_block
fill ~54~30~12 ~54~30~14 minecraft:smooth_quartz_stairs 5
setblock ~54~53~12 minecraft:stained_glass_pane 15
fill ~55~14~12 ~55~15~12 minecraft:jungle_trapdoor
setblock ~55~28~12 minecraft:stained_glass 15
fill ~55~30~12 ~55~30~14 minecraft:quartz_block
fill ~55~53~12 ~56~53~12 minecraft:quartz_block
fill ~56~24~12 ~58~24~12 minecraft:wooden_slab 9
setblock ~56~28~12 minecraft:wood
fill ~56~30~12 ~56~30~14 minecraft:smooth_quartz_stairs 6
setblock ~56~31~12 minecraft:quartz_block
setblock ~56~32~12 minecraft:polished_andesite_stairs 3
setblock ~56~34~12 minecraft:lantern
setblock ~56~35~12 minecraft:fence
setblock ~57~28~12 minecraft:stained_glass 15
fill ~57~30~12 ~62~30~14 minecraft:stone_block_slab4 9
setblock ~57~52~12 minecraft:jungle_door 1
fill ~58~33~12 ~61~33~12 minecraft:coal_block
fill ~58~52~12 ~76~52~12 minecraft:quartz_block
fill ~58~53~12 ~59~53~12 minecraft:quartz_block
fill ~59~26~12 ~60~26~12 minecraft:grindstone
setblock ~59~47~12 minecraft:dark_oak_door 2
fill ~59~49~12 ~59~49~14 minecraft:quartz_block
setblock ~60~53~12 minecraft:stained_glass_pane 15
setblock ~61~25~12 minecraft:wooden_slab
setblock ~61~27~12 minecraft:wooden_slab 9
fill ~61~47~12 ~62~47~13 minecraft:carpet 8
fill ~61~53~12 ~70~53~12 minecraft:quartz_block
fill ~62~61~12 ~62~61~13 minecraft:iron_bars
fill ~63~30~12 ~63~30~13 minecraft:smooth_quartz_stairs 5
setblock ~63~31~12 minecraft:quartz_block
setblock ~63~32~12 minecraft:polished_andesite_stairs 3
setblock ~63~34~12 minecraft:lantern
setblock ~63~35~12 minecraft:fence
setblock ~63~59~12 minecraft:stone_block_slab4 9
fill ~63~64~12 ~66~64~12 minecraft:stone_block_slab3 9
setblock ~63~65~12 minecraft:cobblestone_wall
setblock ~63~66~12 minecraft:lantern
fill ~64~28~12 ~67~28~12 minecraft:smooth_quartz_stairs 7
fill ~64~29~12 ~67~30~13 minecraft:quartz_block
fill ~64~57~12 ~65~57~12 minecraft:stone_block_slab3 9
setblock ~64~58~12 minecraft:polished_blackstone_button 4
fill ~64~65~12 ~65~65~12 minecraft:iron_bars
fill ~65~33~12 ~67~33~12 minecraft:coal_block
fill ~65~58~12 ~70~58~12 minecraft:polished_basalt
setblock ~66~40~12 minecraft:lantern
fill ~66~47~12 ~66~47~14 minecraft:wood
fill ~66~48~12 ~66~48~14 minecraft:quartz_block
setblock ~66~57~12 minecraft:concrete 8
setblock ~66~65~12 minecraft:cobblestone_wall
setblock ~66~66~12 minecraft:lantern
setblock ~67~57~12 minecraft:stone_block_slab4
setblock ~67~59~12 minecraft:stone_block_slab4 9
fill ~67~77~12 ~67~77~17 minecraft:polished_blackstone_slab 9
fill ~68~50~12 ~68~50~13 minecraft:wooden_slab 9
setblock ~68~57~12 minecraft:spruce_trapdoor
setblock ~68~59~12 minecraft:spruce_trapdoor
setblock ~69~32~12 minecraft:polished_andesite_stairs 3
setblock ~69~34~12 minecraft:lantern
setblock ~69~35~12 minecraft:fence
fill ~69~55~12 ~76~55~12 minecraft:concrete 8
fill ~69~56~12 ~77~56~12 minecraft:iron_bars
fill ~69~60~12 ~70~60~26 minecraft:planks
fill ~71~31~12 ~74~31~12 minecraft:quartz_block
setblock ~71~37~12 minecraft:barrel 1
setblock ~71~42~12 minecraft:barrel 1
fill ~71~50~12 ~71~50~13 minecraft:wooden_slab 9
setblock ~71~53~12 minecraft:stained_glass_pane 15
fill ~71~60~12 ~72~60~12 minecraft:concrete 8
fill ~71~61~12 ~73~61~12 minecraft:iron_bars
fill ~72~37~12 ~73~39~12 minecraft:stone
fill ~72~42~12 ~73~44~12 minecraft:stone
setblock ~72~47~12 minecraft:dark_oak_door
fill ~72~49~12 ~72~50~14 minecraft:quartz_block
fill ~72~53~12 ~73~53~12 minecraft:quartz_block
setblock ~73~49~12 minecraft:lantern
fill ~73~50~12 ~74~50~12 minecraft:planks
setblock ~74~32~12 minecraft:coal_block
setblock ~74~38~12 minecraft:stone
setblock ~74~53~12 minecraft:stained_glass_pane 15
fill ~75~32~12 ~76~32~12 minecraft:quartz_block
fill ~75~33~12 ~76~33~12 minecraft:coal_block
setblock ~75~38~12 minecraft:spruce_trapdoor 7
setblock ~75~43~12 minecraft:spruce_trapdoor 7
setblock ~75~47~12 minecraft:hopper 5
setblock ~75~48~12 minecraft:spruce_trapdoor 1
fill ~75~50~12 ~76~50~13 minecraft:quartz_block
fill ~75~53~12 ~76~53~12 minecraft:quartz_block
fill ~76~34~12 ~77~34~12 minecraft:coal_block
fill ~76~47~12 ~78~47~12 minecraft:concrete 8
fill ~76~48~12 ~76~49~13 minecraft:quartz_block
fill ~77~32~12 ~77~32~13 minecraft:smooth_quartz_stairs 6
fill ~77~33~12 ~77~33~13 minecraft:quartz_block
fill ~77~35~12 ~78~35~12 minecraft:coal_block
fill ~77~36~12 ~78~36~12 minecraft:stone
fill ~77~40~12 ~78~40~13 minecraft:quartz_block
fill ~77~41~12 ~78~41~17 minecraft:stone
fill ~77~46~12 ~78~46~12 minecraft:stone
setblock ~77~48~12 minecraft:smooth_quartz_stairs 2
setblock ~78~33~12 minecraft:smooth_quartz_stairs 6
setblock ~78~34~12 minecraft:quartz_block
setblock ~78~48~12 minecraft:smooth_quartz_stairs 1
fill ~79~34~12 ~79~34~13 minecraft:smooth_quartz_stairs 6
fill ~79~35~12 ~79~35~13 minecraft:quartz_block
setblock ~79~36~12 minecraft:concrete 8
setblock ~79~37~12 minecraft:stone_block_slab4
setblock ~79~39~12 minecraft:stone_block_slab4 9
fill ~79~40~12 ~79~41~12 minecraft:concrete 8
setblock ~79~42~12 minecraft:stone_block_slab4
setblock ~79~44~12 minecraft:stone_block_slab4 9
setblock ~79~45~12 minecraft:concrete 8
setblock ~79~46~12 minecraft:quartz_block
setblock ~79~47~12 minecraft:smooth_quartz_stairs 1
setblock ~81~56~12 minecraft:jungle_fence_gate 1
setblock ~83~28~12 minecraft:quartz_block
setblock ~83~29~12 minecraft:spruce_trapdoor 7
setblock ~83~30~12 minecraft:quartz_block
setblock ~83~31~12 minecraft:smooth_quartz_stairs 2
fill ~84~24~12 ~84~24~13 minecraft:smooth_red_sandstone_stairs
fill ~84~29~12 ~84~29~14 minecraft:iron_bars
fill ~84~34~12 ~84~34~13 minecraft:smooth_red_sandstone_stairs 5
fill ~85~24~12 ~90~24~13 minecraft:red_sandstone 
setblock ~85~26~12 minecraft:polished_blackstone_stairs 3
fill ~85~29~12 ~85~29~14 minecraft:stone
fill ~85~34~12 ~90~34~13 minecraft:red_sandstone 
fill ~86~26~12 ~87~26~13 minecraft:stained_hardened_clay 13
fill ~86~28~12 ~87~28~12 minecraft:polished_blackstone_stairs 8
fill ~86~29~12 ~87~29~12 minecraft:polished_blackstone
fill ~86~30~12 ~87~30~12 minecraft:polished_blackstone_stairs 3
setblock ~88~26~12 minecraft:polished_blackstone_stairs 3
fill ~88~29~12 ~88~29~14 minecraft:stone
setblock ~89~27~12 minecraft:smooth_quartz_stairs 7
setblock ~89~28~12 minecraft:quartz_block
setblock ~89~29~12 minecraft:spruce_trapdoor 7
setblock ~89~30~12 minecraft:quartz_block
fill ~91~24~12 ~91~24~13 minecraft:smooth_red_sandstone_stairs 6
fill ~91~34~12 ~91~34~13 minecraft:smooth_red_sandstone_stairs 1
setblock ~93~28~12 minecraft:quartz_block
setblock ~93~29~12 minecraft:spruce_trapdoor 7
setblock ~93~30~12 minecraft:quartz_block
setblock ~93~31~12 minecraft:smooth_quartz_stairs 2
setblock ~94~26~12 minecraft:polished_blackstone_stairs 3
fill ~95~26~12 ~96~26~13 minecraft:stained_hardened_clay 13
fill ~95~28~12 ~96~28~12 minecraft:polished_blackstone_stairs 8
fill ~95~29~12 ~96~29~12 minecraft:polished_blackstone
fill ~95~30~12 ~96~30~12 minecraft:polished_blackstone_stairs 3
setblock ~97~26~12 minecraft:polished_blackstone_stairs 3
fill ~97~29~12 ~97~29~14 minecraft:stone
fill ~98~29~12 ~98~29~14 minecraft:iron_bars
setblock ~99~27~12 minecraft:smooth_quartz_stairs 7
setblock ~99~28~12 minecraft:quartz_block
setblock ~99~29~12 minecraft:spruce_trapdoor 7
setblock ~99~30~12 minecraft:quartz_block
setblock ~19~32~13 minecraft:polished_blackstone_slab 9
setblock ~19~33~13 minecraft:polished_blackstone_slab
fill ~19~45~13 ~21~46~13 minecraft:polished_blackstone
fill ~19~47~13 ~20~47~13 minecraft:polished_blackstone
setblock ~19~48~13 minecraft:polished_blackstone_stairs 2
setblock ~20~33~13 minecraft:polished_blackstone
setblock ~20~34~13 minecraft:polished_blackstone_slab
setblock ~20~35~13 minecraft:polished_blackstone_slab 9
setblock ~20~48~13 minecraft:polished_blackstone_stairs 1
setblock ~21~33~13 minecraft:polished_blackstone_slab 9
setblock ~21~34~13 minecraft:polished_blackstone
setblock ~21~35~13 minecraft:polished_blackstone_stairs 1
setblock ~21~47~13 minecraft:polished_blackstone_stairs 1
fill ~23~56~13 ~29~56~13 minecraft:iron_bars
fill ~24~31~13 ~29~31~13 minecraft:quartz_block
fill ~24~32~13 ~27~32~13 minecraft:quartz_block
fill ~24~33~13 ~26~33~13 minecraft:quartz_block
fill ~24~34~13 ~25~34~13 minecraft:quartz_block
setblock ~24~35~13 minecraft:quartz_block
setblock ~24~36~13 minecraft:concrete 8
fill ~24~37~13 ~29~39~13 minecraft:quartz_block
fill ~24~40~13 ~24~41~13 minecraft:concrete 8
fill ~24~42~13 ~29~44~13 minecraft:quartz_block
setblock ~24~45~13 minecraft:concrete 8
fill ~24~46~13 ~24~50~13 minecraft:quartz_block
fill ~24~51~13 ~29~51~13 minecraft:concrete 8
fill ~24~52~13 ~29~52~13 minecraft:quartz_block
fill ~24~53~13 ~25~54~13 minecraft:quartz_block
fill ~24~55~13 ~29~55~13 minecraft:concrete 8
setblock ~25~36~13 minecraft:quartz_block
fill ~25~40~13 ~29~40~13 minecraft:quartz_block
setblock ~25~41~13 minecraft:quartz_block
fill ~25~47~13 ~25~50~13 minecraft:quartz_block
fill ~26~45~13 ~28~45~13 minecraft:concrete 8
setblock ~26~47~13 minecraft:wood
fill ~26~48~13 ~26~50~13 minecraft:quartz_block
setblock ~26~53~13 minecraft:stained_glass_pane 15
fill ~26~54~13 ~29~54~13 minecraft:quartz_block
setblock ~27~49~13 minecraft:smooth_quartz_stairs 6
setblock ~27~50~13 minecraft:quartz_block
setblock ~27~53~13 minecraft:quartz_block
setblock ~28~50~13 minecraft:smooth_quartz_stairs 6
setblock ~28~53~13 minecraft:stained_glass_pane 15
fill ~29~45~13 ~29~45~27 minecraft:quartz_block
fill ~29~50~13 ~34~50~13 minecraft:wooden_slab 9
setblock ~29~53~13 minecraft:quartz_block
fill ~30~30~13 ~31~30~14 minecraft:stone_block_slab4 9
fill ~30~31~13 ~40~31~13 minecraft:stone
setblock ~30~37~13 minecraft:dark_oak_trapdoor
setblock ~30~42~13 minecraft:dark_oak_trapdoor
fill ~30~51~13 ~76~51~16 minecraft:stone
setblock ~30~52~13 minecraft:barrel 3
fill ~30~53~13 ~30~54~13 minecraft:bookshelf
fill ~30~55~13 ~35~55~13 minecraft:double_wooden_slab
fill ~31~25~13 ~67~25~13 minecraft:smooth_quartz_stairs 7
fill ~31~26~13 ~33~26~13 minecraft:iron_bars
setblock ~31~52~13 minecraft:nether_brick_stairs 3
setblock ~32~52~13 minecraft:nether_brick_stairs
fill ~33~52~13 ~34~52~13 minecraft:barrel
setblock ~34~26~13 minecraft:anvil 2
setblock ~34~53~13 minecraft:flower_pot
setblock ~35~26~13 minecraft:iron_bars
fill ~35~35~13 ~35~35~25 minecraft:stone_block_slab3 9
setblock ~35~47~13 minecraft:barrel 1
fill ~35~52~13 ~35~52~15 minecraft:wood
fill ~35~53~13 ~35~54~15 minecraft:quartz_block
fill ~35~61~13 ~36~61~13 minecraft:iron_bars
fill ~36~26~13 ~38~28~13 minecraft:quartz_block
fill ~36~32~13 ~40~32~13 minecraft:trapdoor 7
fill ~36~47~13 ~37~49~13 minecraft:stone_block_slab3 
fill ~36~54~13 ~36~54~14 minecraft:stone_block_slab3 9
fill ~36~55~13 ~36~55~14 minecraft:concrete 8
setblock ~36~58~13 minecraft:spruce_trapdoor 7
fill ~37~52~13 ~37~52~14 minecraft:netherite_block
fill ~37~53~13 ~37~54~13 minecraft:netherite_block
fill ~37~57~13 ~37~59~13 minecraft:quartz_block
setblock ~38~49~13 minecraft:polished_blackstone_button 2
setblock ~38~50~13 minecraft:stone_block_slab 9
setblock ~38~57~13 minecraft:cobblestone_wall
setblock ~38~58~13 minecraft:cobblestone_wall
setblock ~38~61~13 minecraft:spruce_trapdoor 1
fill ~39~26~13 ~41~26~13 minecraft:dark_oak_fence_gate 2
fill ~39~47~13 ~40~49~13 minecraft:stone_block_slab3 
setblock ~39~57~13 minecraft:barrel 3
setblock ~39~58~13 minecraft:air
fill ~39~61~13 ~41~61~13 minecraft:smooth_sandstone_stairs 2
setblock ~40~40~13 minecraft:lantern
fill ~41~31~13 ~41~31~16 minecraft:polished_basalt
setblock ~41~35~13 minecraft:double_stone_block_slab3
fill ~41~40~13 ~62~40~13 minecraft:stone_block_slab 9
fill ~41~45~13 ~62~45~13 minecraft:stone_block_slab 9
fill ~41~52~13 ~41~52~14 minecraft:netherite_block
fill ~41~53~13 ~41~54~13 minecraft:netherite_block
setblock ~41~59~13 minecraft:smooth_quartz_stairs 6
setblock ~42~26~13 minecraft:dark_oak_fence_gate
setblock ~42~31~13 minecraft:stone
fill ~42~32~13 ~47~32~13 minecraft:trapdoor 7
setblock ~42~49~13 minecraft:lantern
setblock ~42~50~13 minecraft:double_wooden_slab
fill ~42~54~13 ~42~54~14 minecraft:stone_block_slab3 9
fill ~42~55~13 ~42~55~14 minecraft:concrete 8
setblock ~42~61~13 minecraft:spruce_trapdoor
fill ~43~26~13 ~46~26~13 minecraft:dark_oak_fence_gate 2
fill ~43~31~13 ~44~31~13 minecraft:coal_ore
fill ~43~50~13 ~44~50~13 minecraft:wooden_slab 9
fill ~43~52~13 ~43~52~15 minecraft:wood
fill ~43~53~13 ~43~54~15 minecraft:quartz_block
fill ~43~55~13 ~53~55~13 minecraft:double_wooden_slab
fill ~44~13~13 ~45~13~13 minecraft:oak_stairs 7
fill ~44~14~13 ~45~14~13 minecraft:wood
setblock ~44~15~13 minecraft:stained_glass 15
fill ~44~16~13 ~45~16~13 minecraft:smooth_red_sandstone_stairs 2
setblock ~44~47~13 minecraft:bookshelf
setblock ~44~48~13 minecraft:flower_pot
fill ~44~52~13 ~45~52~13 minecraft:bed 2
setblock ~45~15~13 minecraft:red_sandstone 
fill ~45~31~13 ~47~31~13 minecraft:stone
fill ~45~47~13 ~45~47~14 minecraft:wood
fill ~45~48~13 ~45~48~14 minecraft:quartz_block
setblock ~45~54~13 minecraft:lantern
fill ~45~60~13 ~46~60~25 minecraft:planks
setblock ~46~13~13 minecraft:planks 
fill ~46~16~13 ~51~16~15 minecraft:stone_block_slab3 9
setblock ~46~38~13 minecraft:polished_blackstone_button 2
setblock ~46~47~13 minecraft:iron_trapdoor3
setblock ~46~50~13 minecraft:dispenser
fill ~46~52~13 ~46~52~14 minecraft:wood
fill ~46~53~13 ~46~54~14 minecraft:quartz_block
fill ~47~13~13 ~47~13~14 minecraft:stone_block_slab
fill ~47~26~13 ~47~28~13 minecraft:quartz_block
setblock ~47~47~13 minecraft:hopper 3
setblock ~47~48~13 minecraft:spruce_trapdoor3
setblock ~47~50~13 minecraft:wooden_slab 9
setblock ~47~52~13 minecraft:barrel
setblock ~47~53~13 minecraft:flower_pot
fill ~47~60~13 ~61~60~13 minecraft:concrete 8
fill ~47~61~13 ~61~61~13 minecraft:iron_bars
fill ~48~13~13 ~51~13~13 minecraft:double_stone_block_slab
fill ~48~14~13 ~51~14~13 minecraft:barrel 3
fill ~48~26~13 ~54~26~13 minecraft:dark_oak_fence_gate 2
fill ~48~31~13 ~48~31~15 minecraft:polished_basalt
setblock ~48~35~13 minecraft:double_stone_block_slab3
fill ~48~52~13 ~49~52~13 minecraft:bookshelf
setblock ~48~56~13 minecraft:cobblestone_wall
fill ~48~57~13 ~48~59~13 minecraft:cobblestone_wall
fill ~49~31~13 ~49~31~14 minecraft:coal_ore
fill ~49~32~13 ~55~32~13 minecraft:trapdoor 7
setblock ~49~53~13 minecraft:flower_pot
fill ~50~31~13 ~50~31~22 minecraft:stone
kill @e[type=item,r=4]
fill ~50~52~13 ~51~52~13 minecraft:barrel
setblock ~51~31~13 minecraft:coal_ore
setblock ~51~53~13 minecraft:flower_pot
fill ~51~59~13 ~52~59~13 minecraft:trapdoor 3
setblock ~52~13~13 minecraft:planks 
fill ~52~16~13 ~53~16~13 minecraft:red_sandstone 
fill ~52~31~13 ~54~31~13 minecraft:stone
setblock ~52~52~13 minecraft:wood
fill ~52~53~13 ~52~54~13 minecraft:quartz_block
fill ~52~58~13 ~53~58~13 minecraft:trapdoor 3
fill ~53~13~13 ~54~13~13 minecraft:oak_stairs 7
fill ~53~14~13 ~54~14~13 minecraft:wood
fill ~53~15~13 ~54~15~13 minecraft:red_sandstone 
setblock ~53~17~13 minecraft:polished_blackstone_wall
setblock ~53~18~13 minecraft:flower_pot
setblock ~53~43~13 minecraft:polished_blackstone_button 2
setblock ~53~54~13 minecraft:lantern
fill ~53~57~13 ~54~57~13 minecraft:trapdoor 3
setblock ~54~16~13 minecraft:smooth_red_sandstone_stairs 2
setblock ~54~29~13 minecraft:cobblestone_wall
setblock ~54~47~13 minecraft:iron_trapdoor3
setblock ~54~50~13 minecraft:dispenser
fill ~54~55~13 ~55~55~14 minecraft:wooden_slab 9
setblock ~54~56~13 minecraft:trapdoor 3
fill ~55~26~13 ~55~29~13 minecraft:quartz_block
setblock ~55~31~13 minecraft:coal_ore
setblock ~55~47~13 minecraft:hopper 3
setblock ~55~48~13 minecraft:spruce_trapdoor 3
setblock ~55~50~13 minecraft:wooden_slab 9
setblock ~55~52~13 minecraft:cauldron
setblock ~55~53~13 minecraft:tripwire_hook 1
setblock ~55~54~13 minecraft:wall_banner 4
fill ~56~26~13 ~63~26~13 minecraft:dark_oak_fence_gate 2
fill ~56~31~13 ~56~31~15 minecraft:polished_basalt
setblock ~56~35~13 minecraft:double_stone_block_slab3
fill ~56~52~13 ~56~52~14 minecraft:wood
fill ~56~53~13 ~56~54~14 minecraft:quartz_block
fill ~56~55~13 ~61~55~13 minecraft:double_wooden_slab
setblock ~56~56~13 minecraft:cobblestone_wall
fill ~56~57~13 ~56~59~13 minecraft:cobblestone_wall
fill ~57~31~13 ~60~31~13 minecraft:stone
fill ~57~32~13 ~62~32~13 minecraft:trapdoor 2
setblock ~57~47~13 minecraft:hopper 3
setblock ~57~48~13 minecraft:spruce_trapdoor3
setblock ~57~50~13 minecraft:wooden_slab 9
fill ~57~52~13 ~57~54~13 minecraft:dark_oak_trapdoor
setblock ~58~47~13 minecraft:iron_trapdoor3
setblock ~58~50~13 minecraft:dispenser
fill ~59~47~13 ~59~47~14 minecraft:wood
fill ~59~48~13 ~59~48~14 minecraft:quartz_block
fill ~59~52~13 ~62~52~13 minecraft:barrel 3
fill ~59~62~13 ~60~62~13 minecraft:trapdoor 3
setblock ~60~38~13 minecraft:polished_blackstone_button 2
setblock ~60~47~13 minecraft:bookshelf
setblock ~60~48~13 minecraft:flower_pot
fill ~60~50~13 ~61~50~13 minecraft:wooden_slab 9
fill ~60~63~13 ~61~63~13 minecraft:trapdoor 3
setblock ~61~31~13 minecraft:coal_ore
fill ~61~64~13 ~62~64~13 minecraft:trapdoor 3
setblock ~62~31~13 minecraft:stone
setblock ~62~49~13 minecraft:lantern
setblock ~62~50~13 minecraft:double_wooden_slab
fill ~62~54~13 ~62~54~14 minecraft:stone_block_slab3 9
fill ~62~55~13 ~62~55~14 minecraft:concrete 8
setblock ~62~65~13 minecraft:trapdoor 3
fill ~63~31~13 ~63~31~16 minecraft:polished_basalt
setblock ~63~35~13 minecraft:double_stone_block_slab3
fill ~63~52~13 ~63~52~14 minecraft:netherite_block
fill ~63~53~13 ~63~54~13 minecraft:netherite_block
setblock ~63~59~13 minecraft:smooth_quartz_stairs 5
setblock ~63~64~13 minecraft:stone_block_slab3 9
setblock ~63~65~13 minecraft:iron_bars
fill ~64~26~13 ~67~28~13 minecraft:quartz_block
fill ~64~31~13 ~68~31~14 minecraft:stone
fill ~64~32~13 ~68~32~13 minecraft:trapdoor 2
setblock ~64~50~13 minecraft:wooden_slab 9
fill ~64~61~13 ~65~64~13 minecraft:concrete 8
fill ~64~65~13 ~65~65~13 minecraft:carpet 8
setblock ~65~49~13 minecraft:lantern
setblock ~65~50~13 minecraft:double_wooden_slab
setblock ~65~57~13 minecraft:barrel 4
setblock ~65~58~13 minecraft:air
setblock ~66~57~13 minecraft:cobblestone_wall
setblock ~66~58~13 minecraft:cobblestone_wall
fill ~66~61~13 ~68~61~13 minecraft:smooth_sandstone_stairs 2
fill ~66~64~13 ~66~64~18 minecraft:stone_block_slab3 9
fill ~66~65~13 ~66~65~17 minecraft:iron_bars
setblock ~67~47~13 minecraft:hopper 3
setblock ~67~48~13 minecraft:spruce_trapdoor 3
setblock ~67~50~13 minecraft:dispenser
fill ~67~52~13 ~67~52~14 minecraft:netherite_block
fill ~67~53~13 ~67~54~13 minecraft:netherite_block
fill ~67~57~13 ~67~59~13 minecraft:quartz_block
fill ~68~28~13 ~71~28~13 minecraft:smooth_quartz_stairs 7
fill ~68~29~13 ~71~30~14 minecraft:quartz_block
setblock ~68~47~13 minecraft:iron_trapdoor3
fill ~68~54~13 ~68~54~14 minecraft:stone_block_slab3 9
fill ~68~55~13 ~68~55~14 minecraft:concrete 8
setblock ~68~58~13 minecraft:spruce_trapdoor 7
fill ~69~31~13 ~69~31~15 minecraft:polished_basalt
setblock ~69~35~13 minecraft:double_stone_block_slab3
fill ~69~52~13 ~69~52~16 minecraft:wood
fill ~69~53~13 ~69~54~16 minecraft:quartz_block
fill ~69~55~13 ~73~55~17 minecraft:double_wooden_slab
setblock ~69~61~13 minecraft:spruce_trapdoor
fill ~70~31~13 ~74~31~15 minecraft:stone
fill ~70~32~13 ~74~32~13 minecraft:trapdoor 2
setblock ~70~47~13 minecraft:bed
setblock ~70~52~13 minecraft:bed 2
fill ~71~52~13 ~72~52~14 minecraft:carpet 8
fill ~71~60~13 ~72~60~16 minecraft:planks
fill ~72~30~13 ~74~30~13 minecraft:stone_block_slab4 9
fill ~72~47~13 ~72~47~14 minecraft:wood
fill ~72~48~13 ~72~48~14 minecraft:quartz_block
setblock ~73~47~13 minecraft:iron_trapdoor3
setblock ~73~50~13 minecraft:dispenser
setblock ~73~52~13 minecraft:dark_oak_door
fill ~73~54~13 ~73~54~16 minecraft:quartz_block
fill ~73~60~13 ~74~60~13 minecraft:concrete 8
fill ~73~61~13 ~75~61~13 minecraft:iron_bars
setblock ~74~37~13 minecraft:dark_oak_trapdoor 1
fill ~74~46~13 ~79~46~13 minecraft:wood
fill ~74~47~13 ~78~47~13 minecraft:wood
fill ~74~48~13 ~75~49~13 minecraft:quartz_block
fill ~74~50~13 ~74~50~14 minecraft:quartz_block
fill ~74~55~13 ~76~55~13 minecraft:wooden_slab 9
fill ~75~31~13 ~76~31~13 minecraft:quartz_block
setblock ~75~32~13 minecraft:wood
fill ~75~33~13 ~75~34~13 minecraft:fence 
setblock ~75~35~13 minecraft:lantern
fill ~75~36~13 ~79~36~13 minecraft:wood
fill ~75~37~13 ~80~39~13 minecraft:quartz_block
fill ~75~42~13 ~80~44~13 minecraft:quartz_block
fill ~75~45~13 ~79~45~13 minecraft:quartz_block
setblock ~76~32~13 minecraft:quartz_block
setblock ~76~33~13 minecraft:wood
fill ~76~34~13 ~76~35~13 minecraft:fence 
setblock ~76~52~13 minecraft:hopper 5
setblock ~76~53~13 minecraft:spruce_trapdoor 1
setblock ~77~34~13 minecraft:wood
setblock ~77~35~13 minecraft:fence 
fill ~77~48~13 ~80~50~13 minecraft:quartz_block
fill ~77~51~13 ~82~51~13 minecraft:concrete 8
fill ~77~52~13 ~82~52~13 minecraft:quartz_block
fill ~77~53~13 ~77~54~13 minecraft:quartz_block
fill ~77~55~13 ~82~55~13 minecraft:concrete 8
fill ~77~56~13 ~80~56~13 minecraft:iron_bars
setblock ~78~32~13 minecraft:smooth_quartz_stairs 7
fill ~78~33~13 ~78~33~14 minecraft:quartz_block
setblock ~78~35~13 minecraft:wood
setblock ~78~53~13 minecraft:stained_glass_pane 15
fill ~78~54~13 ~82~54~13 minecraft:quartz_block
fill ~79~40~13 ~79~41~13 minecraft:quartz_block
fill ~79~47~13 ~80~47~13 minecraft:quartz_block
setblock ~79~53~13 minecraft:quartz_block
setblock ~80~35~13 minecraft:quartz_block
fill ~80~36~13 ~82~36~13 minecraft:concrete 8
fill ~80~40~13 ~82~41~13 minecraft:concrete 8
fill ~80~45~13 ~82~45~13 minecraft:concrete 8
setblock ~80~46~13 minecraft:quartz_block
setblock ~80~53~13 minecraft:stained_glass_pane 15
fill ~81~35~13 ~82~35~13 minecraft:smooth_quartz_stairs 7
fill ~81~37~13 ~81~39~13 minecraft:stone
fill ~81~42~13 ~81~44~13 minecraft:stone
fill ~81~46~13 ~81~46~25 minecraft:stone
fill ~81~47~13 ~81~50~13 minecraft:stone
fill ~81~53~13 ~82~53~13 minecraft:quartz_block
setblock ~81~56~13 minecraft:anvil 2
fill ~82~37~13 ~82~39~13 minecraft:quartz_block
fill ~82~42~13 ~82~44~13 minecraft:quartz_block
fill ~82~46~13 ~82~50~13 minecraft:quartz_block
fill ~82~56~13 ~83~56~13 minecraft:iron_bars
setblock ~83~27~13 minecraft:quartz_block
setblock ~83~28~13 minecraft:smooth_quartz_stairs 3
setblock ~83~31~13 minecraft:quartz_block
fill ~87~47~13 ~88~47~13 minecraft:iron_bars
fill ~88~46~13 ~91~46~13 minecraft:stone_block_slab3 9
setblock ~89~27~13 minecraft:quartz_block
setblock ~89~30~13 minecraft:smooth_quartz_stairs 8
setblock ~89~31~13 minecraft:quartz_block
setblock ~89~47~13 minecraft:cobblestone_wall
fill ~89~48~13 ~89~50~13 minecraft:cobblestone_wall
fill ~89~51~13 ~91~51~13 minecraft:stone_block_slab3
fill ~90~47~13 ~90~50~13 minecraft:stained_glass_pane 15
fill ~91~47~13 ~91~50~13 minecraft:cobblestone_wall
setblock ~93~27~13 minecraft:quartz_block
setblock ~93~28~13 minecraft:smooth_quartz_stairs 3
setblock ~93~31~13 minecraft:quartz_block
setblock ~94~24~13 minecraft:polished_granite_stairs 8
setblock ~94~34~13 minecraft:polished_granite_stairs 3
setblock ~96~24~13 minecraft:polished_granite_stairs 8
setblock ~96~34~13 minecraft:polished_granite_stairs 3
setblock ~98~24~13 minecraft:polished_granite_stairs 8
setblock ~98~34~13 minecraft:polished_granite_stairs 3
setblock ~99~27~13 minecraft:quartz_block
setblock ~99~30~13 minecraft:smooth_quartz_stairs 8
setblock ~99~31~13 minecraft:quartz_block
setblock ~15~31~14 minecraft:polished_blackstone
setblock ~15~33~14 minecraft:polished_blackstone_slab 9
setblock ~15~34~14 minecraft:polished_blackstone_slab
fill ~15~43~14 ~15~47~14 minecraft:polished_blackstone
fill ~15~48~14 ~18~48~14 minecraft:polished_blackstone_stairs 2
fill ~16~31~14 ~17~31~14 minecraft:polished_blackstone_slab 9
fill ~16~32~14 ~17~32~14 minecraft:polished_blackstone_slab
setblock ~16~34~14 minecraft:polished_blackstone
fill ~16~44~14 ~17~47~14 minecraft:polished_blackstone
setblock ~17~34~14 minecraft:polished_blackstone_slab 9
setblock ~17~35~14 minecraft:polished_blackstone_slab
setblock ~17~37~14 minecraft:polished_blackstone_stairs
setblock ~18~32~14 minecraft:polished_blackstone
setblock ~18~35~14 minecraft:polished_blackstone_stairs 6
setblock ~18~36~14 minecraft:polished_blackstone
setblock ~18~37~14 minecraft:polished_blackstone_stairs 1
fill ~18~45~14 ~18~47~14 minecraft:polished_blackstone
fill ~18~56~14 ~23~56~14 minecraft:iron_bars
fill ~19~31~14 ~23~35~14 minecraft:quartz_block
fill ~19~36~14 ~23~36~14 minecraft:concrete 8
fill ~19~37~14 ~23~39~14 minecraft:quartz_block
fill ~19~40~14 ~23~41~14 minecraft:concrete 8
fill ~19~42~14 ~23~44~14 minecraft:quartz_block
fill ~19~45~14 ~23~45~14 minecraft:concrete 8
fill ~19~46~14 ~23~47~14 minecraft:quartz_block
setblock ~19~48~14 minecraft:polished_blackstone
fill ~19~49~14 ~23~50~14 minecraft:quartz_block
fill ~19~51~14 ~23~51~14 minecraft:concrete 8
fill ~19~52~14 ~23~54~14 minecraft:quartz_block
fill ~19~55~14 ~23~55~14 minecraft:concrete 8
fill ~20~48~14 ~23~48~14 minecraft:quartz_block
fill ~24~30~14 ~29~30~14 minecraft:stone_block_slab4 9
fill ~24~31~14 ~36~31~16 minecraft:stone
setblock ~24~32~14 minecraft:barrel
fill ~24~35~14 ~28~35~16 minecraft:stone_block_slab3 9
fill ~24~36~14 ~25~36~17 minecraft:stone
setblock ~24~37~14 minecraft:wood
fill ~24~38~14 ~24~40~15 minecraft:quartz_block
fill ~24~41~14 ~25~41~16 minecraft:stone
fill ~24~45~14 ~28~45~14 minecraft:wooden_slab 9
fill ~24~46~14 ~25~46~24 minecraft:stone
fill ~24~47~14 ~25~47~14 minecraft:barrel
fill ~24~48~14 ~25~50~14 minecraft:stained_hardened_clay 9
fill ~24~51~14 ~29~51~24 minecraft:stone
setblock ~24~52~14 minecraft:wood
fill ~24~53~14 ~24~54~14 minecraft:quartz_block
fill ~24~55~14 ~31~55~14 minecraft:double_wooden_slab
fill ~25~32~14 ~25~34~14 minecraft:bed 2
setblock ~25~37~14 minecraft:hopper 2
setblock ~25~38~14 minecraft:spruce_trapdoor 2
setblock ~25~40~14 minecraft:lantern
setblock ~25~52~14 minecraft:nether_brick_stairs 1
setblock ~26~32~14 minecraft:barrel
fill ~26~37~14 ~26~37~15 minecraft:wood
fill ~26~38~14 ~26~40~15 minecraft:quartz_block
fill ~26~42~14 ~28~42~14 minecraft:carpet 8
fill ~26~50~14 ~26~50~17 minecraft:wooden_slab 9
setblock ~26~52~14 minecraft:fence 
setblock ~26~53~14 minecraft:wooden_pressure_plate
fill ~26~65~14 ~26~65~24 minecraft:stone_block_slab
fill ~27~25~14 ~30~25~14 minecraft:smooth_quartz_stairs 7
fill ~27~26~14 ~31~26~14 minecraft:iron_bars
fill ~27~32~14 ~27~34~14 minecraft:bed 2
setblock ~27~37~14 minecraft:hopper 2
setblock ~27~38~14 minecraft:spruce_trapdoor 2
setblock ~27~40~14 minecraft:lantern
fill ~27~49~14 ~27~49~15 minecraft:stained_glass_pane 9
setblock ~27~50~14 minecraft:stained_glass_pane 9
setblock ~27~52~14 minecraft:nether_brick_stairs
fill ~28~37~14 ~29~37~15 minecraft:wood
fill ~28~38~14 ~29~40~15 minecraft:quartz_block
setblock ~28~50~14 minecraft:wooden_slab 9
setblock ~29~32~14 minecraft:jungle_door
fill ~29~34~14 ~29~35~27 minecraft:concrete 8
setblock ~29~42~14 minecraft:wood
fill ~29~43~14 ~29~44~14 minecraft:quartz_block
setblock ~29~50~14 minecraft:lantern
setblock ~29~52~14 minecraft:bookshelf
setblock ~29~53~14 minecraft:flower_pot
fill ~30~50~14 ~32~50~14 minecraft:wooden_slab 9
fill ~30~52~14 ~30~54~14 minecraft:dark_oak_trapdoor
setblock ~31~25~14 minecraft:quartz_block
fill ~31~52~14 ~32~52~15 minecraft:carpet 8
setblock ~31~54~14 minecraft:lantern
setblock ~32~24~14 minecraft:smooth_quartz_stairs 7
fill ~32~25~14 ~63~25~17 minecraft:planks
fill ~32~55~14 ~34~55~14 minecraft:wooden_slab 9
fill ~33~23~14 ~34~23~14 minecraft:smooth_quartz_stairs 7
fill ~33~24~14 ~66~24~15 minecraft:quartz_block
fill ~33~41~14 ~42~41~14 minecraft:stone
setblock ~33~50~14 minecraft:lantern
setblock ~34~26~14 minecraft:dark_oak_fence_gate 2
fill ~34~34~14 ~34~34~15 minecraft:concrete 8
fill ~34~36~14 ~42~36~14 minecraft:stone
setblock ~34~50~14 minecraft:wooden_slab 9
fill ~34~52~14 ~34~52~15 minecraft:bed 3
fill ~34~61~14 ~35~61~14 minecraft:iron_bars
setblock ~35~32~14 minecraft:wooden_door
fill ~35~47~14 ~35~50~14 minecraft:stone
fill ~35~55~14 ~35~55~16 minecraft:double_wooden_slab
setblock ~35~60~14 minecraft:concrete 8
setblock ~36~23~14 minecraft:smooth_quartz_stairs 7
fill ~36~30~14 ~38~30~14 minecraft:quartz_block
setblock ~36~40~14 minecraft:lantern
