fill ~1 ~0 ~35 ~1 ~19 ~35 wool 0  
fill ~1 ~0 ~36 ~1 ~19 ~36 wool 0  
fill ~1 ~0 ~37 ~1 ~19 ~37 wool 0  
fill ~1 ~0 ~38 ~1 ~19 ~38 wool 0  
fill ~1 ~0 ~39 ~1 ~21 ~39 wool 0  
fill ~1 ~0 ~40 ~1 ~19 ~40 wool 0  
fill ~1 ~0 ~41 ~1 ~19 ~41 wool 0  
fill ~1 ~0 ~42 ~1 ~19 ~42 wool 0  
fill ~1 ~0 ~43 ~1 ~19 ~43 wool 0  
fill ~1 ~0 ~44 ~1 ~19 ~44 wool 0  
fill ~1 ~0 ~45 ~1 ~19 ~45 wool 0  
fill ~1 ~0 ~46 ~1 ~19 ~46 wool 0  
fill ~1 ~0 ~47 ~1 ~19 ~47 wool 0  
fill ~1 ~0 ~48 ~1 ~19 ~48 wool 0  
fill ~1 ~0 ~49 ~1 ~19 ~49 wool 0  
fill ~1 ~0 ~50 ~1 ~19 ~50 wool 0  
fill ~1 ~0 ~51 ~1 ~19 ~51 wool 0  
fill ~1 ~0 ~52 ~1 ~19 ~52 wool 0  
fill ~1 ~0 ~53 ~1 ~19 ~53 wool 0  
fill ~1 ~0 ~54 ~1 ~19 ~54 wool 0  
fill ~1 ~0 ~55 ~1 ~19 ~55 wool 0  
fill ~1 ~0 ~56 ~1 ~19 ~56 wool 0  
fill ~1 ~0 ~57 ~1 ~19 ~57 wool 0  
fill ~1 ~0 ~58 ~1 ~19 ~58 wool 0  
fill ~1 ~0 ~59 ~1 ~19 ~59 wool 0  
fill ~1 ~0 ~60 ~1 ~19 ~60 wool 0  
fill ~1 ~0 ~61 ~1 ~19 ~61 wool 0  
fill ~1 ~0 ~62 ~1 ~19 ~62 wool 0  
fill ~1 ~0 ~63 ~1 ~19 ~63 wool 0  
fill ~1 ~0 ~64 ~1 ~19 ~64 wool 0  
fill ~1 ~0 ~65 ~1 ~19 ~65 wool 0  
fill ~1 ~0 ~66 ~1 ~19 ~66 wool 0  
fill ~1 ~0 ~67 ~1 ~19 ~67 wool 0  
fill ~1 ~0 ~68 ~1 ~19 ~68 wool 0  
fill ~1 ~0 ~69 ~1 ~19 ~69 wool 0  
fill ~1 ~0 ~70 ~1 ~19 ~70 wool 0  
fill ~1 ~0 ~71 ~1 ~19 ~71 wool 0  
fill ~1 ~0 ~72 ~1 ~19 ~72 wool 0  
fill ~1 ~0 ~73 ~1 ~19 ~73 wool 0  
fill ~1 ~0 ~74 ~1 ~19 ~74 wool 0  
fill ~1 ~0 ~75 ~1 ~19 ~75 wool 0  
fill ~1 ~0 ~76 ~1 ~19 ~76 wool 0  
fill ~1 ~0 ~77 ~1 ~19 ~77 wool 0  
fill ~1 ~0 ~78 ~1 ~19 ~78 wool 0  
fill ~1 ~0 ~79 ~1 ~19 ~79 wool 0  
fill ~1 ~0 ~80 ~1 ~19 ~80 wool 0  
fill ~1 ~0 ~81 ~1 ~19 ~81 wool 0  
fill ~1 ~0 ~82 ~1 ~19 ~82 wool 0  
fill ~1 ~0 ~83 ~1 ~19 ~83 wool 0  
fill ~1 ~0 ~84 ~1 ~19 ~84 wool 0  
fill ~1 ~0 ~85 ~1 ~19 ~85 wool 0  
fill ~1 ~0 ~86 ~1 ~19 ~86 wool 0  
fill ~1 ~0 ~87 ~1 ~19 ~87 wool 0  
fill ~1 ~0 ~88 ~1 ~19 ~88 wool 0  
fill ~1 ~0 ~89 ~1 ~19 ~89 wool 0  
fill ~1 ~0 ~90 ~1 ~19 ~90 wool 0  
fill ~1 ~0 ~91 ~1 ~19 ~91 wool 0  
fill ~1 ~0 ~92 ~1 ~19 ~92 wool 0  
fill ~1 ~0 ~93 ~1 ~19 ~93 wool 0  
fill ~1 ~0 ~94 ~1 ~19 ~94 wool 0  
fill ~1 ~0 ~95 ~1 ~19 ~95 wool 0  
fill ~1 ~0 ~96 ~1 ~19 ~96 wool 0  
fill ~1 ~0 ~97 ~1 ~19 ~97 wool 0  
fill ~1 ~0 ~98 ~1 ~19 ~98 wool 0  
fill ~1 ~0 ~99 ~1 ~19 ~99 wool 0  
fill ~1 ~0 ~100 ~1 ~19 ~100 wool 0  
fill ~1 ~0 ~101 ~1 ~19 ~101 wool 0  
fill ~1 ~0 ~102 ~1 ~19 ~102 wool 0  
fill ~1 ~0 ~103 ~1 ~19 ~103 wool 0  
fill ~1 ~0 ~104 ~1 ~19 ~104 wool 0  
fill ~1 ~0 ~105 ~1 ~19 ~105 wool 0  
fill ~1 ~0 ~106 ~1 ~19 ~106 wool 0  
fill ~1 ~0 ~107 ~1 ~19 ~107 wool 0  
fill ~1 ~0 ~108 ~1 ~19 ~108 wool 0  
fill ~1 ~0 ~109 ~1 ~19 ~109 wool 0  
fill ~1 ~0 ~110 ~1 ~19 ~110 wool 0  
fill ~1 ~0 ~111 ~1 ~19 ~111 wool 0  
fill ~1 ~0 ~112 ~1 ~19 ~112 wool 0  
fill ~1 ~0 ~113 ~1 ~19 ~113 wool 0  
fill ~1 ~0 ~114 ~1 ~19 ~114 wool 0  
fill ~1 ~0 ~115 ~1 ~19 ~115 wool 0  
fill ~1 ~0 ~116 ~1 ~19 ~116 wool 0  
fill ~1 ~0 ~117 ~1 ~19 ~117 wool 0  
fill ~1 ~0 ~118 ~1 ~19 ~118 wool 0  
fill ~1 ~0 ~119 ~1 ~19 ~119 wool 0  
fill ~1 ~0 ~120 ~1 ~19 ~120 wool 0  
fill ~1 ~0 ~121 ~1 ~19 ~121 wool 0  
fill ~1 ~0 ~122 ~1 ~19 ~122 wool 0  
fill ~1 ~0 ~123 ~1 ~19 ~123 wool 0  
fill ~1 ~0 ~124 ~1 ~19 ~124 wool 0  
fill ~1 ~0 ~125 ~1 ~19 ~125 wool 0  
fill ~1 ~0 ~126 ~1 ~19 ~126 wool 0  
fill ~1 ~0 ~127 ~1 ~19 ~127 wool 0  
fill ~1 ~0 ~128 ~1 ~19 ~128 wool 0  
fill ~2 ~0 ~34 ~2 ~19 ~34 wool 0  
fill ~2 ~0 ~129 ~2 ~19 ~129 wool 0  
fill ~3 ~0 ~33 ~3 ~19 ~33 wool 0  
fill ~3 ~0 ~130 ~3 ~19 ~130 wool 0  
fill ~4 ~0 ~32 ~4 ~19 ~32 wool 0  
fill ~4 ~0 ~131 ~4 ~19 ~131 wool 0  
fill ~5 ~0 ~31 ~5 ~19 ~31 wool 0  
fill ~5 ~0 ~132 ~5 ~19 ~132 wool 0  
fill ~6 ~0 ~30 ~6 ~19 ~30 wool 0  
fill ~6 ~0 ~133 ~6 ~19 ~133 wool 0  
fill ~7 ~0 ~29 ~7 ~19 ~29 wool 0  
fill ~7 ~0 ~134 ~7 ~19 ~134 wool 0  
fill ~8 ~0 ~28 ~8 ~19 ~28 wool 0  
fill ~8 ~0 ~135 ~8 ~19 ~135 wool 0  
fill ~9 ~0 ~27 ~9 ~19 ~27 wool 0  
fill ~9 ~0 ~136 ~9 ~19 ~136 wool 0  
fill ~10 ~0 ~26 ~10 ~19 ~26 wool 0  
fill ~10 ~0 ~137 ~10 ~19 ~137 wool 0  
fill ~11 ~0 ~25 ~11 ~19 ~25 wool 0  
fill ~11 ~0 ~45 ~12 ~0 ~45 wool 0  
fill ~11 ~0 ~46 ~12 ~0 ~46 wool 0  
fill ~11 ~0 ~49 ~12 ~0 ~49 wool 0  
fill ~11 ~0 ~50 ~12 ~0 ~50 wool 0  
fill ~11 ~0 ~65 ~12 ~0 ~65 wool 0  
fill ~11 ~0 ~66 ~12 ~0 ~66 wool 0  
fill ~11 ~0 ~69 ~12 ~0 ~69 wool 0  
fill ~11 ~0 ~70 ~12 ~0 ~70 wool 0  
fill ~11 ~0 ~86 ~12 ~0 ~86 wool 0  
fill ~11 ~0 ~87 ~12 ~0 ~87 wool 0  
fill ~11 ~0 ~90 ~12 ~0 ~90 wool 0  
fill ~11 ~0 ~91 ~12 ~0 ~91 wool 0  
fill ~11 ~0 ~108 ~12 ~0 ~108 wool 0  
fill ~11 ~0 ~109 ~12 ~0 ~109 wool 0  
fill ~11 ~0 ~112 ~12 ~0 ~112 wool 0  
fill ~11 ~0 ~113 ~12 ~0 ~113 wool 0  
fill ~11 ~0 ~138 ~11 ~19 ~138 wool 0  
fill ~12 ~0 ~24 ~12 ~19 ~24 wool 0  
fill ~12 ~0 ~139 ~12 ~19 ~139 wool 0  
fill ~13 ~0 ~23 ~13 ~19 ~23 wool 0  
fill ~13 ~0 ~140 ~13 ~19 ~140 wool 0  
fill ~14 ~0 ~22 ~14 ~19 ~22 wool 0  
fill ~14 ~0 ~141 ~14 ~19 ~141 wool 0  
fill ~15 ~0 ~21 ~15 ~19 ~21 wool 0  
fill ~15 ~0 ~142 ~15 ~19 ~142 wool 0  
fill ~16 ~0 ~20 ~16 ~19 ~20 wool 0  
fill ~16 ~0 ~143 ~16 ~19 ~143 wool 0  
fill ~17 ~0 ~19 ~17 ~19 ~19 wool 0  
fill ~17 ~0 ~144 ~17 ~19 ~144 wool 0  
fill ~18 ~0 ~18 ~18 ~19 ~18 wool 0  
fill ~18 ~0 ~145 ~18 ~19 ~145 wool 0  
fill ~19 ~0 ~17 ~19 ~19 ~17 wool 0  
fill ~19 ~0 ~146 ~19 ~19 ~146 wool 0  
fill ~20 ~0 ~16 ~20 ~19 ~16 wool 0  
fill ~20 ~0 ~147 ~20 ~19 ~147 wool 0  
fill ~21 ~0 ~15 ~21 ~19 ~15 wool 0  
fill ~21 ~0 ~148 ~21 ~19 ~148 wool 0  
fill ~22 ~0 ~14 ~22 ~19 ~14 wool 0  
fill ~22 ~0 ~149 ~22 ~19 ~149 wool 0  
fill ~23 ~0 ~13 ~23 ~19 ~13 wool 0  
fill ~23 ~0 ~150 ~23 ~19 ~150 wool 0  
fill ~24 ~0 ~12 ~24 ~19 ~12 wool 0  
fill ~24 ~0 ~151 ~24 ~19 ~151 wool 0  
fill ~25 ~0 ~11 ~25 ~19 ~11 wool 0  
fill ~25 ~0 ~152 ~25 ~19 ~152 wool 0  
fill ~26 ~0 ~10 ~26 ~19 ~10 wool 0  
fill ~26 ~0 ~153 ~26 ~19 ~153 wool 0  
fill ~27 ~0 ~9 ~27 ~19 ~9 wool 0  
fill ~27 ~0 ~46 ~28 ~0 ~46 wool 0  
fill ~27 ~0 ~47 ~28 ~0 ~47 wool 0  
fill ~27 ~0 ~48 ~28 ~0 ~48 wool 0  
fill ~27 ~0 ~66 ~28 ~0 ~66 wool 0  
fill ~27 ~0 ~67 ~28 ~0 ~67 wool 0  
fill ~27 ~0 ~68 ~28 ~0 ~68 wool 0  
fill ~27 ~0 ~87 ~28 ~0 ~87 wool 0  
fill ~27 ~0 ~88 ~28 ~0 ~88 wool 0  
fill ~27 ~0 ~89 ~28 ~0 ~89 wool 0  
fill ~27 ~0 ~109 ~28 ~0 ~109 wool 0  
fill ~27 ~0 ~110 ~28 ~0 ~110 wool 0  
fill ~27 ~0 ~111 ~28 ~0 ~111 wool 0  
fill ~27 ~0 ~154 ~27 ~19 ~154 wool 0  
fill ~28 ~0 ~8 ~28 ~19 ~8 wool 0  
fill ~28 ~0 ~155 ~28 ~19 ~155 wool 0  
fill ~29 ~0 ~7 ~29 ~19 ~7 wool 0  
fill ~29 ~0 ~156 ~29 ~19 ~156 wool 0  
fill ~30 ~0 ~6 ~30 ~19 ~6 wool 0  
fill ~30 ~0 ~157 ~30 ~19 ~157 wool 0  
fill ~31 ~0 ~5 ~31 ~19 ~5 wool 0  
fill ~31 ~0 ~158 ~31 ~19 ~158 wool 0  
fill ~32 ~0 ~4 ~32 ~19 ~4 wool 0  
fill ~32 ~0 ~159 ~32 ~19 ~159 wool 0  
fill ~33 ~0 ~3 ~33 ~19 ~3 wool 0 
setblock ~33 ~0 ~113 torch 2  
fill ~33 ~0 ~124 ~35 ~0 ~124 wool 14  
fill ~33 ~0 ~160 ~33 ~19 ~160 wool 0  
fill ~34 ~0 ~2 ~34 ~19 ~2 wool 0  
fill ~34 ~0 ~40 ~34 ~0 ~123 brick_block 0  
fill ~34 ~0 ~125 ~36 ~0 ~125 wool 14  
fill ~34 ~0 ~161 ~34 ~19 ~161 wool 0  
fill ~35 ~0 ~1 ~69 ~0 ~1 wool 0  
fill ~35 ~0 ~40 ~35 ~3 ~40 wool 0 
setblock ~35 ~0 ~123 brick_block 0  
fill ~35 ~0 ~126 ~36 ~0 ~126 wool 14  
fill ~35 ~0 ~162 ~69 ~0 ~162 wool 0 
setblock ~36 ~0 ~124 brick_block 0  
fill ~36 ~0 ~127 ~36 ~1 ~127 wool 14  
fill ~37 ~0 ~37 ~67 ~0 ~37 brick_block 0  
fill ~37 ~0 ~38 ~37 ~3 ~38 wool 0  
fill ~37 ~0 ~125 ~37 ~0 ~126 brick_block 0  
fill ~38 ~0 ~126 ~38 ~0 ~127 brick_block 0  
fill ~39 ~0 ~12 ~40 ~0 ~12 wool 0  
fill ~39 ~0 ~13 ~40 ~0 ~13 wool 0  
fill ~39 ~0 ~127 ~66 ~0 ~127 brick_block 0  
fill ~40 ~0 ~151 ~41 ~0 ~151 wool 0  
fill ~40 ~0 ~152 ~41 ~0 ~152 wool 0  
fill ~41 ~0 ~30 ~43 ~0 ~30 wool 0  
fill ~41 ~0 ~31 ~43 ~0 ~31 wool 0  
fill ~41 ~0 ~133 ~43 ~0 ~133 wool 0  
fill ~41 ~0 ~134 ~43 ~0 ~134 wool 0  
fill ~43 ~0 ~12 ~44 ~0 ~12 wool 0  
fill ~43 ~0 ~13 ~44 ~0 ~13 wool 0  
fill ~44 ~0 ~151 ~45 ~0 ~151 wool 0  
fill ~44 ~0 ~152 ~45 ~0 ~152 wool 0  
fill ~52 ~0 ~41 ~52 ~3 ~41 wool 4  
fill ~52 ~0 ~122 ~52 ~3 ~122 wool 4  
fill ~60 ~0 ~12 ~61 ~0 ~12 wool 0  
fill ~60 ~0 ~13 ~61 ~0 ~13 wool 0  
fill ~60 ~0 ~151 ~61 ~0 ~151 wool 0  
fill ~60 ~0 ~152 ~61 ~0 ~152 wool 0  
fill ~61 ~0 ~30 ~63 ~0 ~30 wool 0  
fill ~61 ~0 ~31 ~63 ~0 ~31 wool 0  
fill ~61 ~0 ~133 ~63 ~0 ~133 wool 0  
fill ~61 ~0 ~134 ~63 ~0 ~134 wool 0  
fill ~64 ~0 ~12 ~65 ~0 ~12 wool 0  
fill ~64 ~0 ~13 ~65 ~0 ~13 wool 0  
fill ~64 ~0 ~151 ~65 ~0 ~151 wool 0  
fill ~64 ~0 ~152 ~65 ~0 ~152 wool 0  
fill ~67 ~0 ~38 ~68 ~0 ~38 brick_block 0  
fill ~67 ~0 ~126 ~67 ~3 ~126 wool 0  
fill ~67 ~0 ~127 ~67 ~1 ~127 wool 14  
fill ~67 ~0 ~128 ~67 ~1 ~128 wool 14  
fill ~68 ~0 ~39 ~69 ~0 ~39 brick_block 0  
fill ~69 ~0 ~40 ~70 ~0 ~40 brick_block 0  
fill ~69 ~0 ~123 ~69 ~3 ~123 wool 0  
fill ~70 ~0 ~2 ~70 ~19 ~2 wool 0  
fill ~70 ~0 ~41 ~70 ~0 ~123 brick_block 0  
fill ~70 ~0 ~161 ~70 ~19 ~161 wool 0  
fill ~71 ~0 ~3 ~71 ~19 ~3 wool 0  
fill ~71 ~0 ~160 ~71 ~19 ~160 wool 0  
fill ~72 ~0 ~4 ~72 ~19 ~4 wool 0  
fill ~72 ~0 ~159 ~72 ~19 ~159 wool 0  
fill ~73 ~0 ~5 ~73 ~19 ~5 wool 0  
fill ~73 ~0 ~158 ~73 ~19 ~158 wool 0  
fill ~74 ~0 ~6 ~74 ~19 ~6 wool 0  
fill ~74 ~0 ~157 ~74 ~19 ~157 wool 0  
fill ~75 ~0 ~7 ~75 ~19 ~7 wool 0  
fill ~75 ~0 ~156 ~75 ~19 ~156 wool 0  
fill ~76 ~0 ~8 ~76 ~19 ~8 wool 0  
fill ~76 ~0 ~46 ~77 ~0 ~46 wool 0  
fill ~76 ~0 ~47 ~77 ~0 ~47 wool 0  
fill ~76 ~0 ~48 ~77 ~0 ~48 wool 0  
fill ~76 ~0 ~66 ~77 ~0 ~66 wool 0  
fill ~76 ~0 ~67 ~77 ~0 ~67 wool 0  
fill ~76 ~0 ~68 ~77 ~0 ~68 wool 0  
fill ~76 ~0 ~87 ~77 ~0 ~87 wool 0  
fill ~76 ~0 ~88 ~77 ~0 ~88 wool 0  
fill ~76 ~0 ~89 ~77 ~0 ~89 wool 0  
fill ~76 ~0 ~109 ~77 ~0 ~109 wool 0  
fill ~76 ~0 ~110 ~77 ~0 ~110 wool 0  
fill ~76 ~0 ~111 ~77 ~0 ~111 wool 0  
fill ~76 ~0 ~155 ~76 ~19 ~155 wool 0  
fill ~77 ~0 ~9 ~77 ~19 ~9 wool 0  
fill ~77 ~0 ~154 ~77 ~19 ~154 wool 0  
fill ~78 ~0 ~10 ~78 ~19 ~10 wool 0  
fill ~78 ~0 ~153 ~78 ~19 ~153 wool 0  
fill ~79 ~0 ~11 ~79 ~19 ~11 wool 0  
fill ~79 ~0 ~152 ~79 ~19 ~152 wool 0  
fill ~80 ~0 ~12 ~80 ~19 ~12 wool 0  
fill ~80 ~0 ~151 ~80 ~19 ~151 wool 0  
fill ~81 ~0 ~13 ~81 ~19 ~13 wool 0  
fill ~81 ~0 ~150 ~81 ~19 ~150 wool 0  
fill ~82 ~0 ~14 ~82 ~19 ~14 wool 0  
fill ~82 ~0 ~149 ~82 ~19 ~149 wool 0  
fill ~83 ~0 ~15 ~83 ~19 ~15 wool 0  
fill ~83 ~0 ~148 ~83 ~19 ~148 wool 0  
fill ~84 ~0 ~16 ~84 ~19 ~16 wool 0  
fill ~84 ~0 ~147 ~84 ~19 ~147 wool 0  
fill ~85 ~0 ~17 ~85 ~19 ~17 wool 0  
fill ~85 ~0 ~146 ~85 ~19 ~146 wool 0  
fill ~86 ~0 ~18 ~86 ~19 ~18 wool 0  
fill ~86 ~0 ~145 ~86 ~19 ~145 wool 0  
fill ~87 ~0 ~19 ~87 ~19 ~19 wool 0  
fill ~87 ~0 ~144 ~87 ~19 ~144 wool 0  
fill ~88 ~0 ~20 ~88 ~19 ~20 wool 0  
fill ~88 ~0 ~143 ~88 ~19 ~143 wool 0  
fill ~89 ~0 ~21 ~89 ~19 ~21 wool 0  
fill ~89 ~0 ~64 ~90 ~0 ~64 wool 0  
fill ~89 ~0 ~65 ~89 ~0 ~64 wool 0  
fill ~89 ~0 ~142 ~89 ~19 ~142 wool 0  
fill ~90 ~0 ~22 ~90 ~19 ~22 wool 0  
fill ~90 ~0 ~48 ~91 ~0 ~48 wool 0  
fill ~90 ~0 ~49 ~91 ~0 ~49 wool 0  
fill ~90 ~0 ~68 ~91 ~0 ~68 wool 0  
fill ~90 ~0 ~69 ~91 ~0 ~69 wool 0  
fill ~90 ~0 ~85 ~91 ~0 ~85 wool 0  
fill ~90 ~0 ~86 ~91 ~0 ~86 wool 0  
fill ~90 ~0 ~89 ~91 ~0 ~89 wool 0  
fill ~90 ~0 ~90 ~91 ~0 ~90 wool 0  
fill ~90 ~0 ~141 ~90 ~19 ~141 wool 0  
fill ~91 ~0 ~23 ~91 ~19 ~23 wool 0  
fill ~91 ~0 ~44 ~92 ~0 ~44 wool 0  
fill ~91 ~0 ~45 ~92 ~0 ~45 wool 0  
fill ~91 ~0 ~140 ~91 ~19 ~140 wool 0  
fill ~92 ~0 ~24 ~92 ~19 ~24 wool 0  
fill ~92 ~0 ~107 ~93 ~0 ~107 wool 0  
fill ~92 ~0 ~108 ~93 ~0 ~108 wool 0  
fill ~92 ~0 ~111 ~93 ~0 ~111 wool 0  
fill ~92 ~0 ~112 ~93 ~0 ~112 wool 0  
fill ~92 ~0 ~139 ~92 ~19 ~139 wool 0  
fill ~93 ~0 ~25 ~93 ~19 ~25 wool 0  
fill ~93 ~0 ~138 ~93 ~19 ~138 wool 0  
fill ~94 ~0 ~26 ~94 ~19 ~26 wool 0  
fill ~94 ~0 ~137 ~94 ~19 ~137 wool 0  
fill ~95 ~0 ~27 ~95 ~19 ~27 wool 0  
fill ~95 ~0 ~136 ~95 ~19 ~136 wool 0  
fill ~96 ~0 ~28 ~96 ~19 ~28 wool 0  
fill ~96 ~0 ~135 ~96 ~19 ~135 wool 0  
fill ~97 ~0 ~29 ~97 ~19 ~29 wool 0  
fill ~97 ~0 ~134 ~97 ~19 ~134 wool 0  
fill ~98 ~0 ~30 ~98 ~19 ~30 wool 0  
fill ~98 ~0 ~133 ~98 ~19 ~133 wool 0  
fill ~99 ~0 ~31 ~99 ~19 ~31 wool 0  
fill ~99 ~0 ~132 ~99 ~19 ~132 wool 0  
fill ~100 ~0 ~32 ~100 ~19 ~32 wool 0  
fill ~100 ~0 ~131 ~100 ~19 ~131 wool 0  
fill ~101 ~0 ~33 ~101 ~19 ~33 wool 0  
fill ~101 ~0 ~130 ~101 ~19 ~130 wool 0  
fill ~102 ~0 ~34 ~102 ~19 ~34 wool 0  
fill ~102 ~0 ~129 ~102 ~19 ~129 wool 0  
fill ~103 ~0 ~35 ~103 ~19 ~35 wool 0  
fill ~103 ~0 ~36 ~103 ~19 ~36 wool 0  
fill ~103 ~0 ~37 ~103 ~19 ~37 wool 0  
fill ~103 ~0 ~38 ~103 ~19 ~38 wool 0  
fill ~103 ~0 ~39 ~103 ~19 ~39 wool 0  
fill ~103 ~0 ~40 ~103 ~19 ~40 wool 0  
fill ~103 ~0 ~41 ~103 ~19 ~41 wool 0  
fill ~103 ~0 ~42 ~103 ~19 ~42 wool 0  
fill ~103 ~0 ~43 ~103 ~19 ~43 wool 0  
fill ~103 ~0 ~44 ~103 ~19 ~44 wool 0  
fill ~103 ~0 ~45 ~103 ~19 ~45 wool 0  
fill ~103 ~0 ~46 ~103 ~19 ~46 wool 0  
fill ~103 ~0 ~47 ~103 ~19 ~47 wool 0  
fill ~103 ~0 ~48 ~103 ~19 ~48 wool 0  
fill ~103 ~0 ~49 ~103 ~19 ~49 wool 0  
fill ~103 ~0 ~50 ~103 ~19 ~50 wool 0  
fill ~103 ~0 ~51 ~103 ~19 ~51 wool 0  
fill ~103 ~0 ~52 ~103 ~19 ~52 wool 0  
fill ~103 ~0 ~53 ~103 ~19 ~53 wool 0  
fill ~103 ~0 ~54 ~103 ~19 ~54 wool 0  
fill ~103 ~0 ~55 ~103 ~19 ~55 wool 0  
fill ~103 ~0 ~56 ~103 ~19 ~56 wool 0  
fill ~103 ~0 ~57 ~103 ~19 ~57 wool 0  
fill ~103 ~0 ~58 ~103 ~19 ~58 wool 0  
fill ~103 ~0 ~59 ~103 ~19 ~59 wool 0  
fill ~103 ~0 ~60 ~103 ~19 ~60 wool 0  
fill ~103 ~0 ~61 ~103 ~19 ~61 wool 0  
fill ~103 ~0 ~62 ~103 ~19 ~62 wool 0  
fill ~103 ~0 ~63 ~103 ~19 ~63 wool 0  
fill ~103 ~0 ~64 ~103 ~19 ~64 wool 0  
fill ~103 ~0 ~65 ~103 ~19 ~65 wool 0  
fill ~103 ~0 ~66 ~103 ~19 ~66 wool 0  
fill ~103 ~0 ~67 ~103 ~19 ~67 wool 0  
fill ~103 ~0 ~68 ~103 ~19 ~68 wool 0  
fill ~103 ~0 ~69 ~103 ~19 ~69 wool 0  
fill ~103 ~0 ~70 ~103 ~19 ~70 wool 0  
fill ~103 ~0 ~71 ~103 ~19 ~71 wool 0  
fill ~103 ~0 ~72 ~103 ~19 ~72 wool 0  
fill ~103 ~0 ~73 ~103 ~19 ~73 wool 0  
fill ~103 ~0 ~74 ~103 ~19 ~74 wool 0  
fill ~103 ~0 ~75 ~103 ~19 ~75 wool 0  
fill ~103 ~0 ~76 ~103 ~19 ~76 wool 0  
fill ~103 ~0 ~77 ~103 ~19 ~77 wool 0  
fill ~103 ~0 ~78 ~103 ~19 ~78 wool 0  
fill ~103 ~0 ~79 ~103 ~19 ~79 wool 0  
fill ~103 ~0 ~80 ~103 ~19 ~80 wool 0  
fill ~103 ~0 ~81 ~103 ~19 ~81 wool 0  
fill ~103 ~0 ~82 ~103 ~19 ~82 wool 0  
fill ~103 ~0 ~83 ~103 ~19 ~83 wool 0  
fill ~103 ~0 ~84 ~103 ~19 ~84 wool 0  
fill ~103 ~0 ~85 ~103 ~19 ~85 wool 0  
fill ~103 ~0 ~86 ~103 ~19 ~86 wool 0  
fill ~103 ~0 ~87 ~103 ~19 ~87 wool 0  
fill ~103 ~0 ~88 ~103 ~19 ~88 wool 0  
fill ~103 ~0 ~89 ~103 ~19 ~89 wool 0  
fill ~103 ~0 ~90 ~103 ~19 ~90 wool 0  
fill ~103 ~0 ~91 ~103 ~19 ~91 wool 0  
fill ~103 ~0 ~92 ~103 ~19 ~92 wool 0  
fill ~103 ~0 ~93 ~103 ~19 ~93 wool 0  
fill ~103 ~0 ~94 ~103 ~19 ~94 wool 0  
fill ~103 ~0 ~95 ~103 ~19 ~95 wool 0  
fill ~103 ~0 ~96 ~103 ~19 ~96 wool 0  
fill ~103 ~0 ~97 ~103 ~19 ~97 wool 0  
fill ~103 ~0 ~98 ~103 ~19 ~98 wool 0  
fill ~103 ~0 ~99 ~103 ~19 ~99 wool 0  
fill ~103 ~0 ~100 ~103 ~19 ~100 wool 0  
fill ~103 ~0 ~101 ~103 ~19 ~101 wool 0  
fill ~103 ~0 ~102 ~103 ~19 ~102 wool 0  
fill ~103 ~0 ~103 ~103 ~19 ~103 wool 0  
fill ~103 ~0 ~104 ~103 ~19 ~104 wool 0  
fill ~103 ~0 ~105 ~103 ~19 ~105 wool 0  
fill ~103 ~0 ~106 ~103 ~19 ~106 wool 0  
fill ~103 ~0 ~107 ~103 ~19 ~107 wool 0  
fill ~103 ~0 ~108 ~103 ~19 ~108 wool 0  
fill ~103 ~0 ~109 ~103 ~19 ~109 wool 0  
fill ~103 ~0 ~110 ~103 ~19 ~110 wool 0  
fill ~103 ~0 ~111 ~103 ~19 ~111 wool 0  
fill ~103 ~0 ~112 ~103 ~19 ~112 wool 0  
fill ~103 ~0 ~113 ~103 ~19 ~113 wool 0  
fill ~103 ~0 ~114 ~103 ~19 ~114 wool 0  
fill ~103 ~0 ~115 ~103 ~19 ~115 wool 0  
fill ~103 ~0 ~116 ~103 ~19 ~116 wool 0  
fill ~103 ~0 ~117 ~103 ~19 ~117 wool 0  
fill ~103 ~0 ~118 ~103 ~19 ~118 wool 0  
fill ~103 ~0 ~119 ~103 ~19 ~119 wool 0  
fill ~103 ~0 ~120 ~103 ~19 ~120 wool 0  
fill ~103 ~0 ~121 ~103 ~19 ~121 wool 0  
fill ~103 ~0 ~122 ~103 ~19 ~122 wool 0  
fill ~103 ~0 ~123 ~103 ~19 ~123 wool 0  
fill ~103 ~0 ~124 ~103 ~19 ~124 wool 0  
fill ~103 ~0 ~125 ~103 ~19 ~125 wool 0  
fill ~103 ~0 ~126 ~103 ~19 ~126 wool 0  
fill ~103 ~0 ~127 ~103 ~19 ~127 wool 0  
fill ~103 ~0 ~128 ~103 ~19 ~128 wool 0  
fill ~107 ~0 ~78 ~107 ~28 ~78 wool 0  
fill ~107 ~0 ~79 ~107 ~28 ~79 wool 0  
fill ~107 ~0 ~80 ~107 ~28 ~80 wool 0  
fill ~107 ~0 ~81 ~107 ~28 ~81 wool 0  
fill ~107 ~0 ~82 ~107 ~28 ~82 wool 0  
fill ~107 ~0 ~83 ~107 ~28 ~83 wool 0  
fill ~107 ~0 ~84 ~107 ~28 ~84 wool 0  
fill ~107 ~0 ~85 ~107 ~28 ~85 wool 0  
fill ~107 ~0 ~86 ~107 ~28 ~86 wool 0  
fill ~107 ~0 ~87 ~107 ~28 ~87 wool 0  
fill ~107 ~0 ~88 ~107 ~28 ~88 wool 0  
fill ~107 ~0 ~89 ~107 ~28 ~89 wool 0  
fill ~107 ~0 ~90 ~107 ~28 ~90 wool 0  
fill ~107 ~0 ~91 ~107 ~28 ~91 wool 0 
setblock ~4 ~1 ~130 torch 1  
fill ~10 ~1 ~45 ~11 ~1 ~45 wool 0  
fill ~10 ~1 ~46 ~11 ~1 ~46 wool 0  
fill ~10 ~1 ~49 ~11 ~1 ~49 wool 0  
fill ~10 ~1 ~50 ~11 ~1 ~50 wool 0  
fill ~10 ~1 ~65 ~11 ~1 ~65 wool 0  
fill ~10 ~1 ~66 ~11 ~1 ~66 wool 0  
fill ~10 ~1 ~69 ~11 ~1 ~69 wool 0  
fill ~10 ~1 ~70 ~11 ~1 ~70 wool 0  
fill ~10 ~1 ~86 ~11 ~1 ~86 wool 0  
fill ~10 ~1 ~87 ~11 ~1 ~87 wool 0  
fill ~10 ~1 ~90 ~11 ~1 ~90 wool 0  
fill ~10 ~1 ~91 ~11 ~1 ~91 wool 0  
fill ~10 ~1 ~108 ~11 ~1 ~108 wool 0  
fill ~10 ~1 ~109 ~11 ~1 ~109 wool 0  
fill ~10 ~1 ~112 ~11 ~1 ~112 wool 0  
fill ~10 ~1 ~113 ~11 ~1 ~113 wool 0 
setblock ~11 ~1 ~26 torch 1  
fill ~28 ~1 ~46 ~29 ~1 ~46 wool 0  
fill ~28 ~1 ~47 ~29 ~1 ~47 wool 0  
fill ~28 ~1 ~48 ~29 ~1 ~48 wool 0  
fill ~28 ~1 ~66 ~29 ~1 ~66 wool 0  
fill ~28 ~1 ~67 ~29 ~1 ~67 wool 0  
fill ~28 ~1 ~68 ~29 ~1 ~68 wool 0  
fill ~28 ~1 ~87 ~29 ~1 ~87 wool 0  
fill ~28 ~1 ~88 ~29 ~1 ~88 wool 0  
fill ~28 ~1 ~89 ~29 ~1 ~89 wool 0  
fill ~28 ~1 ~109 ~29 ~1 ~109 wool 0  
fill ~28 ~1 ~110 ~29 ~1 ~110 wool 0  
fill ~28 ~1 ~111 ~29 ~1 ~111 wool 0  
fill ~31 ~1 ~40 ~33 ~1 ~40 wool 14  
fill ~31 ~1 ~41 ~33 ~1 ~41 wool 14  
fill ~31 ~1 ~42 ~33 ~1 ~42 wool 14  
fill ~31 ~1 ~43 ~33 ~1 ~43 wool 14  
fill ~31 ~1 ~44 ~33 ~1 ~44 wool 14  
fill ~31 ~1 ~45 ~33 ~1 ~45 wool 14  
fill ~31 ~1 ~46 ~33 ~1 ~46 wool 14  
fill ~31 ~1 ~47 ~31 ~1 ~124 wool 14  
fill ~32 ~1 ~38 ~32 ~1 ~46 wool 14  
fill ~32 ~1 ~47 ~34 ~1 ~47 wool 0  
fill ~32 ~1 ~48 ~33 ~1 ~48 wool 14  
fill ~32 ~1 ~49 ~33 ~1 ~49 wool 14  
fill ~32 ~1 ~50 ~33 ~1 ~50 wool 14  
fill ~32 ~1 ~51 ~33 ~1 ~51 wool 14  
fill ~32 ~1 ~52 ~33 ~1 ~52 wool 14  
fill ~32 ~1 ~53 ~33 ~1 ~53 wool 14  
fill ~32 ~1 ~54 ~33 ~1 ~54 wool 14  
fill ~32 ~1 ~55 ~33 ~1 ~55 wool 14  
fill ~32 ~1 ~56 ~33 ~1 ~56 wool 14  
fill ~32 ~1 ~57 ~33 ~1 ~57 wool 14  
fill ~32 ~1 ~58 ~33 ~1 ~58 wool 14  
fill ~32 ~1 ~59 ~33 ~1 ~59 wool 14  
fill ~32 ~1 ~60 ~33 ~1 ~60 wool 14  
fill ~32 ~1 ~61 ~33 ~1 ~61 wool 14  
fill ~32 ~1 ~62 ~33 ~1 ~62 wool 14  
fill ~32 ~1 ~63 ~33 ~1 ~63 wool 14  
fill ~32 ~1 ~64 ~33 ~1 ~64 wool 14  
fill ~32 ~1 ~65 ~33 ~1 ~65 wool 14  
fill ~32 ~1 ~66 ~33 ~1 ~66 wool 14  
fill ~32 ~1 ~67 ~34 ~1 ~67 wool 0  
fill ~32 ~1 ~68 ~33 ~1 ~68 wool 14  
fill ~32 ~1 ~69 ~33 ~1 ~69 wool 14  
fill ~32 ~1 ~70 ~33 ~1 ~70 wool 14  
fill ~32 ~1 ~71 ~33 ~1 ~71 wool 14  
fill ~32 ~1 ~72 ~33 ~1 ~72 wool 14  
fill ~32 ~1 ~73 ~33 ~1 ~73 wool 14  
fill ~32 ~1 ~74 ~33 ~1 ~74 wool 14  
fill ~32 ~1 ~75 ~33 ~1 ~75 wool 14  
fill ~32 ~1 ~76 ~33 ~1 ~76 wool 14  
fill ~32 ~1 ~77 ~33 ~1 ~77 wool 14  
fill ~32 ~1 ~78 ~33 ~1 ~78 wool 14  
fill ~32 ~1 ~79 ~33 ~1 ~79 wool 14  
fill ~32 ~1 ~80 ~33 ~1 ~80 wool 14  
fill ~32 ~1 ~81 ~33 ~1 ~81 wool 14  
fill ~32 ~1 ~82 ~33 ~1 ~82 wool 14  
fill ~32 ~1 ~83 ~33 ~1 ~83 wool 14  
fill ~32 ~1 ~84 ~33 ~1 ~84 wool 14  
fill ~32 ~1 ~85 ~33 ~1 ~85 wool 14  
fill ~32 ~1 ~86 ~33 ~1 ~86 wool 14  
fill ~32 ~1 ~87 ~33 ~1 ~87 wool 14  
fill ~32 ~1 ~88 ~34 ~1 ~88 wool 0  
fill ~32 ~1 ~89 ~33 ~1 ~89 wool 14  
fill ~32 ~1 ~90 ~33 ~1 ~90 wool 14  
fill ~32 ~1 ~91 ~33 ~1 ~91 wool 14  
fill ~32 ~1 ~92 ~33 ~1 ~92 wool 14  
fill ~32 ~1 ~93 ~33 ~1 ~93 wool 14  
fill ~32 ~1 ~94 ~33 ~1 ~94 wool 14  
fill ~32 ~1 ~95 ~33 ~1 ~95 wool 14  
fill ~32 ~1 ~96 ~33 ~1 ~96 wool 14  
fill ~32 ~1 ~97 ~33 ~1 ~97 wool 14  
fill ~32 ~1 ~98 ~33 ~1 ~98 wool 14  
fill ~32 ~1 ~99 ~33 ~1 ~99 wool 14  
fill ~32 ~1 ~100 ~33 ~1 ~100 wool 14  
fill ~32 ~1 ~101 ~33 ~1 ~101 wool 14  
fill ~32 ~1 ~102 ~33 ~1 ~102 wool 14  
fill ~32 ~1 ~103 ~33 ~1 ~103 wool 14  
fill ~32 ~1 ~104 ~33 ~1 ~104 wool 14  
fill ~32 ~1 ~105 ~33 ~1 ~105 wool 14  
fill ~32 ~1 ~106 ~33 ~1 ~106 wool 14  
fill ~32 ~1 ~107 ~33 ~1 ~107 wool 14  
fill ~32 ~1 ~108 ~33 ~1 ~108 wool 14  
fill ~32 ~1 ~109 ~33 ~1 ~109 wool 14  
fill ~32 ~1 ~110 ~34 ~1 ~110 wool 0  
fill ~32 ~1 ~111 ~33 ~1 ~111 wool 14  
fill ~32 ~1 ~112 ~33 ~1 ~112 wool 14  
fill ~32 ~1 ~113 ~33 ~1 ~113 wool 14  
fill ~32 ~1 ~114 ~33 ~1 ~114 wool 14  
fill ~32 ~1 ~115 ~33 ~1 ~115 wool 14  
fill ~32 ~1 ~116 ~33 ~1 ~116 wool 14  
fill ~32 ~1 ~117 ~33 ~1 ~117 wool 14  
fill ~32 ~1 ~118 ~33 ~1 ~118 wool 14  
fill ~32 ~1 ~119 ~33 ~1 ~119 wool 14  
fill ~32 ~1 ~120 ~33 ~1 ~120 wool 14  
fill ~32 ~1 ~121 ~33 ~1 ~121 wool 14  
fill ~32 ~1 ~122 ~33 ~1 ~122 wool 14  
fill ~32 ~1 ~123 ~33 ~1 ~123 wool 14  
fill ~32 ~1 ~124 ~34 ~1 ~124 wool 14  
fill ~32 ~1 ~125 ~35 ~1 ~125 wool 14  
fill ~33 ~1 ~39 ~34 ~1 ~39 wool 14  
fill ~33 ~1 ~126 ~36 ~1 ~126 wool 14  
fill ~34 ~1 ~40 ~34 ~3 ~40 wool 0  
fill ~34 ~1 ~41 ~34 ~1 ~123 wool 0  
fill ~34 ~1 ~127 ~37 ~1 ~127 wool 14  
fill ~35 ~1 ~1 ~69 ~1 ~1 wool 0  
fill ~35 ~1 ~35 ~41 ~1 ~35 wool 14 
setblock ~35 ~1 ~43 torch 1 
setblock ~35 ~1 ~52 torch 1 
setblock ~35 ~1 ~61 torch 1 
setblock ~35 ~1 ~71 torch 1 
setblock ~35 ~1 ~82 torch 1 
setblock ~35 ~1 ~93 torch 1 
setblock ~35 ~1 ~104 torch 1 
setblock ~35 ~1 ~114 torch 1  
fill ~35 ~1 ~123 ~35 ~1 ~124 wool 0  
fill ~35 ~1 ~128 ~41 ~1 ~128 wool 14  
fill ~35 ~1 ~162 ~69 ~1 ~162 wool 0  
fill ~36 ~1 ~34 ~38 ~1 ~34 wool 14  
fill ~36 ~1 ~36 ~41 ~1 ~36 wool 14 
setblock ~36 ~1 ~123 torch 4  
fill ~36 ~1 ~124 ~36 ~1 ~125 wool 0  
fill ~36 ~1 ~129 ~41 ~1 ~129 wool 14  
fill ~37 ~1 ~37 ~67 ~1 ~37 wool 0  
fill ~37 ~1 ~125 ~37 ~1 ~126 wool 0  
fill ~38 ~1 ~126 ~38 ~1 ~127 wool 0  
fill ~38 ~1 ~130 ~38 ~2 ~130 wool 14  
fill ~39 ~1 ~11 ~40 ~1 ~11 wool 0  
fill ~39 ~1 ~12 ~40 ~1 ~12 wool 0  
fill ~39 ~1 ~127 ~66 ~1 ~127 wool 0  
fill ~40 ~1 ~152 ~41 ~1 ~152 wool 0  
fill ~40 ~1 ~153 ~41 ~1 ~153 wool 0  
fill ~41 ~1 ~31 ~43 ~1 ~31 wool 0  
fill ~41 ~1 ~32 ~43 ~1 ~32 wool 0 
setblock ~41 ~1 ~38 torch 3  
fill ~41 ~1 ~132 ~43 ~1 ~132 wool 0  
fill ~41 ~1 ~133 ~43 ~1 ~133 wool 0  
fill ~42 ~1 ~35 ~42 ~1 ~37 wool 0  
fill ~42 ~1 ~128 ~42 ~1 ~129 wool 0  
fill ~43 ~1 ~11 ~44 ~1 ~11 wool 0  
fill ~43 ~1 ~12 ~44 ~1 ~12 wool 0  
fill ~43 ~1 ~35 ~61 ~1 ~35 wool 14  
fill ~43 ~1 ~36 ~61 ~1 ~36 wool 14 
setblock ~43 ~1 ~126 torch 4  
fill ~43 ~1 ~128 ~61 ~1 ~128 wool 14  
fill ~43 ~1 ~129 ~61 ~1 ~129 wool 14  
fill ~44 ~1 ~152 ~45 ~1 ~152 wool 0  
fill ~44 ~1 ~153 ~45 ~1 ~153 wool 0 
setblock ~52 ~1 ~38 torch 3 
setblock ~52 ~1 ~126 torch 4  
fill ~60 ~1 ~11 ~61 ~1 ~11 wool 0  
fill ~60 ~1 ~12 ~61 ~1 ~12 wool 0 
setblock ~60 ~1 ~126 torch 4  
fill ~60 ~1 ~152 ~61 ~1 ~152 wool 0  
fill ~60 ~1 ~153 ~61 ~1 ~153 wool 0  
fill ~61 ~1 ~31 ~63 ~1 ~31 wool 0  
fill ~61 ~1 ~32 ~63 ~1 ~32 wool 0  
fill ~61 ~1 ~132 ~63 ~1 ~132 wool 0  
fill ~61 ~1 ~133 ~63 ~1 ~133 wool 0  
fill ~62 ~1 ~35 ~62 ~1 ~37 wool 0 
setblock ~62 ~1 ~38 torch 3  
fill ~62 ~1 ~128 ~62 ~1 ~129 wool 0  
fill ~63 ~1 ~35 ~69 ~1 ~35 wool 14  
fill ~63 ~1 ~36 ~70 ~1 ~36 wool 14  
fill ~63 ~1 ~128 ~68 ~1 ~128 wool 14  
fill ~63 ~1 ~129 ~68 ~1 ~129 wool 14  
fill ~64 ~1 ~11 ~65 ~1 ~11 wool 0  
fill ~64 ~1 ~12 ~65 ~1 ~12 wool 0  
fill ~64 ~1 ~152 ~65 ~1 ~152 wool 0  
fill ~64 ~1 ~153 ~65 ~1 ~153 wool 0  
fill ~66 ~1 ~34 ~68 ~1 ~34 wool 14  
fill ~66 ~1 ~130 ~67 ~1 ~130 wool 14  
fill ~67 ~1 ~38 ~68 ~1 ~38 wool 0  
fill ~68 ~1 ~37 ~71 ~1 ~37 wool 14  
fill ~68 ~1 ~39 ~69 ~1 ~39 wool 0  
fill ~69 ~1 ~38 ~72 ~1 ~38 wool 14  
fill ~69 ~1 ~40 ~70 ~1 ~40 wool 0 
setblock ~69 ~1 ~50 torch 2 
setblock ~69 ~1 ~60 torch 2 
setblock ~69 ~1 ~66 torch 2 
setblock ~69 ~1 ~78 torch 2 
setblock ~69 ~1 ~88 torch 2 
setblock ~69 ~1 ~98 torch 2 
setblock ~69 ~1 ~108 torch 2 
setblock ~69 ~1 ~117 torch 2  
fill ~70 ~1 ~39 ~73 ~1 ~39 wool 14  
fill ~70 ~1 ~41 ~70 ~1 ~123 wool 0  
fill ~71 ~1 ~40 ~73 ~1 ~40 wool 14  
fill ~71 ~1 ~41 ~73 ~1 ~41 wool 14  
fill ~71 ~1 ~42 ~73 ~1 ~42 wool 14  
fill ~71 ~1 ~43 ~73 ~1 ~43 wool 14  
fill ~71 ~1 ~44 ~73 ~1 ~44 wool 14  
fill ~71 ~1 ~45 ~73 ~1 ~45 wool 14  
fill ~71 ~1 ~46 ~73 ~1 ~46 wool 14  
fill ~71 ~1 ~47 ~72 ~1 ~47 wool 0  
fill ~71 ~1 ~48 ~73 ~1 ~48 wool 14  
fill ~71 ~1 ~49 ~73 ~1 ~49 wool 14  
fill ~71 ~1 ~50 ~73 ~1 ~50 wool 14  
fill ~71 ~1 ~51 ~73 ~1 ~51 wool 14  
fill ~71 ~1 ~52 ~73 ~1 ~52 wool 14  
fill ~71 ~1 ~53 ~73 ~1 ~53 wool 14  
fill ~71 ~1 ~54 ~73 ~1 ~54 wool 14  
fill ~71 ~1 ~55 ~73 ~1 ~55 wool 14  
fill ~71 ~1 ~56 ~73 ~1 ~56 wool 14  
fill ~71 ~1 ~57 ~73 ~1 ~57 wool 14  
fill ~71 ~1 ~58 ~73 ~1 ~58 wool 14  
fill ~71 ~1 ~59 ~73 ~1 ~59 wool 14  
fill ~71 ~1 ~60 ~73 ~1 ~60 wool 14  
fill ~71 ~1 ~61 ~73 ~1 ~61 wool 14  
fill ~71 ~1 ~62 ~73 ~1 ~62 wool 14  
fill ~71 ~1 ~63 ~73 ~1 ~63 wool 14  
fill ~71 ~1 ~64 ~73 ~1 ~64 wool 14  
fill ~71 ~1 ~65 ~73 ~1 ~65 wool 14  
fill ~71 ~1 ~66 ~73 ~1 ~66 wool 14  
fill ~71 ~1 ~67 ~73 ~1 ~67 wool 0  
fill ~71 ~1 ~68 ~73 ~1 ~68 wool 14  
fill ~71 ~1 ~69 ~73 ~1 ~69 wool 14  
fill ~71 ~1 ~70 ~73 ~1 ~70 wool 14  
fill ~71 ~1 ~71 ~73 ~1 ~71 wool 14  
fill ~71 ~1 ~72 ~73 ~1 ~72 wool 14  
fill ~71 ~1 ~73 ~73 ~1 ~73 wool 14  
fill ~71 ~1 ~74 ~73 ~1 ~74 wool 14  
fill ~71 ~1 ~75 ~73 ~1 ~75 wool 14  
fill ~71 ~1 ~76 ~73 ~1 ~76 wool 14  
fill ~71 ~1 ~77 ~73 ~1 ~77 wool 14  
fill ~71 ~1 ~78 ~73 ~1 ~78 wool 14  
fill ~71 ~1 ~79 ~73 ~1 ~79 wool 14  
fill ~71 ~1 ~80 ~73 ~1 ~80 wool 14  
fill ~71 ~1 ~81 ~73 ~1 ~81 wool 14  
fill ~71 ~1 ~82 ~73 ~1 ~82 wool 14  
fill ~71 ~1 ~83 ~73 ~1 ~83 wool 14  
fill ~71 ~1 ~84 ~73 ~1 ~84 wool 14  
fill ~71 ~1 ~85 ~73 ~1 ~85 wool 14  
fill ~71 ~1 ~86 ~73 ~1 ~86 wool 14  
fill ~71 ~1 ~87 ~73 ~1 ~87 wool 14  
fill ~71 ~1 ~88 ~72 ~1 ~88 wool 0  
fill ~71 ~1 ~89 ~73 ~1 ~89 wool 14  
fill ~71 ~1 ~90 ~73 ~1 ~90 wool 14  
fill ~71 ~1 ~91 ~73 ~1 ~91 wool 14  
fill ~71 ~1 ~92 ~73 ~1 ~92 wool 14  
fill ~71 ~1 ~93 ~73 ~1 ~93 wool 14  
fill ~71 ~1 ~94 ~73 ~1 ~94 wool 14  
fill ~71 ~1 ~95 ~73 ~1 ~95 wool 14  
fill ~71 ~1 ~96 ~73 ~1 ~96 wool 14  
fill ~71 ~1 ~97 ~73 ~1 ~97 wool 14  
fill ~71 ~1 ~98 ~73 ~1 ~98 wool 14  
fill ~71 ~1 ~99 ~73 ~1 ~99 wool 14  
fill ~71 ~1 ~100 ~73 ~1 ~100 wool 14  
fill ~71 ~1 ~101 ~73 ~1 ~101 wool 14  
fill ~71 ~1 ~102 ~73 ~1 ~102 wool 14  
fill ~71 ~1 ~103 ~73 ~1 ~103 wool 14  
fill ~71 ~1 ~104 ~73 ~1 ~104 wool 14  
fill ~71 ~1 ~105 ~73 ~1 ~105 wool 14  
fill ~71 ~1 ~106 ~73 ~1 ~106 wool 14  
fill ~71 ~1 ~107 ~73 ~1 ~107 wool 14  
fill ~71 ~1 ~108 ~73 ~1 ~108 wool 14  
fill ~71 ~1 ~109 ~73 ~1 ~109 wool 14  
fill ~71 ~1 ~110 ~72 ~1 ~110 wool 0  
fill ~71 ~1 ~111 ~73 ~1 ~111 wool 14  
fill ~71 ~1 ~112 ~72 ~1 ~112 wool 14  
fill ~71 ~1 ~113 ~73 ~1 ~113 wool 14  
fill ~71 ~1 ~114 ~73 ~1 ~114 wool 14  
fill ~71 ~1 ~115 ~73 ~1 ~115 wool 14  
fill ~71 ~1 ~116 ~73 ~1 ~116 wool 14  
fill ~71 ~1 ~117 ~73 ~1 ~117 wool 14  
fill ~71 ~1 ~118 ~73 ~1 ~118 wool 14  
fill ~71 ~1 ~119 ~73 ~1 ~119 wool 14  
fill ~71 ~1 ~120 ~73 ~1 ~120 wool 14  
fill ~71 ~1 ~121 ~73 ~1 ~121 wool 14  
fill ~71 ~1 ~122 ~73 ~1 ~122 wool 14  
fill ~71 ~1 ~123 ~73 ~1 ~123 wool 14  
fill ~71 ~1 ~124 ~72 ~1 ~124 wool 14 
setblock ~72 ~1 ~125 wool 14 
setblock ~73 ~1 ~47 wool 14 
setblock ~73 ~1 ~88 wool 14 
setblock ~73 ~1 ~110 wool 14 
setblock ~74 ~1 ~112 wool 0  
fill ~75 ~1 ~46 ~76 ~1 ~46 wool 0  
fill ~75 ~1 ~47 ~76 ~1 ~47 wool 0  
fill ~75 ~1 ~48 ~76 ~1 ~48 wool 0  
fill ~75 ~1 ~66 ~76 ~1 ~66 wool 0  
fill ~75 ~1 ~67 ~76 ~1 ~67 wool 0  
fill ~75 ~1 ~68 ~76 ~1 ~68 wool 0  
fill ~75 ~1 ~87 ~76 ~1 ~87 wool 0  
fill ~75 ~1 ~88 ~76 ~1 ~88 wool 0  
fill ~75 ~1 ~89 ~76 ~1 ~89 wool 0  
fill ~75 ~1 ~109 ~76 ~1 ~109 wool 0  
fill ~75 ~1 ~110 ~76 ~1 ~110 wool 0  
fill ~75 ~1 ~111 ~76 ~1 ~111 wool 0 
setblock ~89 ~1 ~22 torch 3  
fill ~90 ~1 ~64 ~91 ~1 ~64 wool 0  
fill ~90 ~1 ~65 ~91 ~1 ~65 wool 0  
fill ~91 ~1 ~48 ~92 ~1 ~48 wool 0  
fill ~91 ~1 ~49 ~92 ~1 ~49 wool 0  
fill ~91 ~1 ~68 ~92 ~1 ~68 wool 0  
fill ~91 ~1 ~69 ~92 ~1 ~69 wool 0  
fill ~91 ~1 ~85 ~92 ~1 ~85 wool 0  
fill ~91 ~1 ~86 ~92 ~1 ~86 wool 0  
fill ~91 ~1 ~89 ~92 ~1 ~89 wool 0  
fill ~91 ~1 ~90 ~92 ~1 ~90 wool 0  
fill ~92 ~1 ~44 ~93 ~1 ~44 wool 0  
fill ~92 ~1 ~45 ~93 ~1 ~45 wool 0  
fill ~93 ~1 ~107 ~94 ~1 ~107 wool 0  
fill ~93 ~1 ~108 ~94 ~1 ~108 wool 0  
fill ~93 ~1 ~111 ~94 ~1 ~111 wool 0  
fill ~93 ~1 ~112 ~94 ~1 ~112 wool 0 
setblock ~2 ~2 ~57 torch 1 
setblock ~2 ~2 ~78 torch 1 
setblock ~2 ~2 ~93 torch 1 
setblock ~2 ~2 ~119 torch 1  
fill ~9 ~2 ~45 ~10 ~2 ~45 wool 0  
fill ~9 ~2 ~46 ~10 ~2 ~46 wool 0  
fill ~9 ~2 ~49 ~10 ~2 ~49 wool 0  
fill ~9 ~2 ~50 ~10 ~2 ~50 wool 0  
fill ~9 ~2 ~65 ~10 ~2 ~65 wool 0  
fill ~9 ~2 ~66 ~10 ~2 ~66 wool 0  
fill ~9 ~2 ~69 ~10 ~2 ~69 wool 0  
fill ~9 ~2 ~70 ~10 ~2 ~70 wool 0  
fill ~9 ~2 ~86 ~10 ~2 ~86 wool 0  
fill ~9 ~2 ~87 ~10 ~2 ~87 wool 0  
fill ~9 ~2 ~90 ~10 ~2 ~90 wool 0  
fill ~9 ~2 ~91 ~10 ~2 ~91 wool 0  
fill ~9 ~2 ~108 ~10 ~2 ~108 wool 0  
fill ~9 ~2 ~109 ~10 ~2 ~109 wool 0  
fill ~9 ~2 ~112 ~10 ~2 ~112 wool 0  
fill ~9 ~2 ~113 ~10 ~2 ~113 wool 0 
setblock ~27 ~2 ~10 torch 1  
fill ~29 ~2 ~40 ~31 ~2 ~40 wool 14  
fill ~29 ~2 ~46 ~29 ~2 ~48 wool 0  
fill ~29 ~2 ~66 ~29 ~2 ~68 wool 0  
fill ~29 ~2 ~87 ~29 ~2 ~89 wool 0  
fill ~29 ~2 ~109 ~29 ~2 ~111 wool 0  
fill ~29 ~2 ~123 ~31 ~2 ~123 wool 14  
fill ~29 ~2 ~124 ~31 ~2 ~124 wool 14  
fill ~30 ~2 ~38 ~31 ~2 ~38 wool 14  
fill ~30 ~2 ~39 ~31 ~2 ~39 wool 14  
fill ~30 ~2 ~41 ~31 ~2 ~41 wool 14  
fill ~30 ~2 ~42 ~31 ~2 ~42 wool 14  
fill ~30 ~2 ~43 ~31 ~2 ~43 wool 14  
fill ~30 ~2 ~44 ~31 ~2 ~44 wool 14  
fill ~30 ~2 ~45 ~31 ~2 ~45 wool 14  
fill ~30 ~2 ~46 ~31 ~2 ~46 wool 14  
fill ~30 ~2 ~47 ~31 ~2 ~47 wool 0  
fill ~30 ~2 ~48 ~31 ~2 ~48 wool 14  
fill ~30 ~2 ~49 ~31 ~2 ~49 wool 14  
fill ~30 ~2 ~50 ~31 ~2 ~50 wool 14  
fill ~30 ~2 ~51 ~31 ~2 ~51 wool 14  
fill ~30 ~2 ~52 ~31 ~2 ~52 wool 14  
fill ~30 ~2 ~53 ~31 ~2 ~53 wool 14  
fill ~30 ~2 ~54 ~31 ~2 ~54 wool 14  
fill ~30 ~2 ~55 ~31 ~2 ~55 wool 14  
fill ~30 ~2 ~56 ~31 ~2 ~56 wool 14  
fill ~30 ~2 ~57 ~31 ~2 ~57 wool 14  
fill ~30 ~2 ~58 ~31 ~2 ~58 wool 14  
fill ~30 ~2 ~59 ~31 ~2 ~59 wool 14  
fill ~30 ~2 ~60 ~31 ~2 ~60 wool 14  
fill ~30 ~2 ~61 ~31 ~2 ~61 wool 14  
fill ~30 ~2 ~62 ~31 ~2 ~62 wool 14  
fill ~30 ~2 ~63 ~31 ~2 ~63 wool 14  
fill ~30 ~2 ~64 ~31 ~2 ~64 wool 14  
fill ~30 ~2 ~65 ~31 ~2 ~65 wool 14  
fill ~30 ~2 ~66 ~31 ~2 ~66 wool 14  
fill ~30 ~2 ~67 ~31 ~2 ~67 wool 0  
fill ~30 ~2 ~68 ~31 ~2 ~68 wool 14  
fill ~30 ~2 ~69 ~31 ~2 ~69 wool 14  
fill ~30 ~2 ~70 ~31 ~2 ~70 wool 14  
fill ~30 ~2 ~71 ~31 ~2 ~71 wool 14  
fill ~30 ~2 ~72 ~31 ~2 ~72 wool 14  
fill ~30 ~2 ~73 ~31 ~2 ~73 wool 14  
fill ~30 ~2 ~74 ~31 ~2 ~74 wool 14  
fill ~30 ~2 ~75 ~31 ~2 ~75 wool 14  
fill ~30 ~2 ~76 ~31 ~2 ~76 wool 14  
fill ~30 ~2 ~77 ~31 ~2 ~77 wool 14  
fill ~30 ~2 ~78 ~31 ~2 ~78 wool 14  
fill ~30 ~2 ~79 ~31 ~2 ~79 wool 14  
fill ~30 ~2 ~80 ~31 ~2 ~80 wool 14  
fill ~30 ~2 ~81 ~31 ~2 ~81 wool 14  
fill ~30 ~2 ~82 ~31 ~2 ~82 wool 14  
fill ~30 ~2 ~83 ~31 ~2 ~83 wool 14  
fill ~30 ~2 ~84 ~31 ~2 ~84 wool 14  
fill ~30 ~2 ~85 ~31 ~2 ~85 wool 14  
fill ~30 ~2 ~86 ~31 ~2 ~86 wool 14  
fill ~30 ~2 ~87 ~31 ~2 ~87 wool 14  
fill ~30 ~2 ~88 ~31 ~2 ~88 wool 0  
fill ~30 ~2 ~89 ~31 ~2 ~89 wool 14  
fill ~30 ~2 ~90 ~31 ~2 ~90 wool 14  
fill ~30 ~2 ~91 ~31 ~2 ~91 wool 14  
fill ~30 ~2 ~92 ~31 ~2 ~92 wool 14  
fill ~30 ~2 ~93 ~31 ~2 ~93 wool 14  
fill ~30 ~2 ~94 ~31 ~2 ~94 wool 14  
fill ~30 ~2 ~95 ~31 ~2 ~95 wool 14  
fill ~30 ~2 ~96 ~31 ~2 ~96 wool 14  
fill ~30 ~2 ~97 ~31 ~2 ~97 wool 14  
fill ~30 ~2 ~98 ~31 ~2 ~98 wool 14  
fill ~30 ~2 ~99 ~31 ~2 ~99 wool 14  
fill ~30 ~2 ~100 ~31 ~2 ~100 wool 14  
fill ~30 ~2 ~101 ~31 ~2 ~101 wool 14  
fill ~30 ~2 ~102 ~31 ~2 ~102 wool 14  
fill ~30 ~2 ~103 ~31 ~2 ~103 wool 14  
summon Boar ~3.64588196939 ~0.0 ~162.35178278 
summon Chicken ~47.5970092939 ~0.0 ~45.6939670744 
summon Chicken ~50.4376645044 ~0.0 ~53.0325213283 
summon Chicken ~49.7442127101 ~0.0 ~55.5390550383 
summon Chicken ~58.4699054594 ~0.0 ~63.3441827366 
summon Deer ~68.5 ~0.0 ~48.5 
summon Deer ~68.1819936862 ~0.0 ~53.619799879 
summon Deer ~69.5 ~0.0 ~52.5 
summon Item ~72.7352155546 ~2.125 ~76.9885937558  
fill ~30 ~2 ~104 ~31 ~2 ~104 wool 14  
fill ~30 ~2 ~105 ~31 ~2 ~105 wool 14  
fill ~30 ~2 ~106 ~31 ~2 ~106 wool 14  
fill ~30 ~2 ~107 ~31 ~2 ~107 wool 14  
fill ~30 ~2 ~108 ~31 ~2 ~108 wool 14  
fill ~30 ~2 ~109 ~31 ~2 ~109 wool 14  
fill ~30 ~2 ~110 ~31 ~2 ~110 wool 0  
fill ~30 ~2 ~111 ~31 ~2 ~111 wool 14  
fill ~30 ~2 ~112 ~31 ~2 ~112 wool 14  
fill ~30 ~2 ~113 ~31 ~2 ~113 wool 14  
fill ~30 ~2 ~114 ~31 ~2 ~114 wool 14  
fill ~30 ~2 ~115 ~31 ~2 ~115 wool 14  
fill ~30 ~2 ~116 ~31 ~2 ~116 wool 14  
fill ~30 ~2 ~117 ~31 ~2 ~117 wool 14  
fill ~30 ~2 ~118 ~31 ~2 ~118 wool 14  
fill ~30 ~2 ~119 ~31 ~2 ~119 wool 14  
fill ~30 ~2 ~120 ~31 ~2 ~120 wool 14  
fill ~30 ~2 ~121 ~31 ~2 ~121 wool 14  
fill ~30 ~2 ~122 ~31 ~2 ~122 wool 14  
fill ~30 ~2 ~125 ~31 ~2 ~125 wool 14  
fill ~31 ~2 ~37 ~32 ~2 ~37 wool 14  
fill ~31 ~2 ~126 ~32 ~2 ~126 wool 14 
setblock ~32 ~2 ~36 wool 14  
fill ~32 ~2 ~38 ~32 ~3 ~38 wool 0  
fill ~32 ~2 ~127 ~33 ~2 ~127 wool 14  
fill ~33 ~2 ~35 ~34 ~2 ~35 wool 14  
fill ~33 ~2 ~39 ~33 ~3 ~39 wool 0  
fill ~33 ~2 ~128 ~34 ~2 ~128 wool 14  
fill ~34 ~2 ~34 ~41 ~2 ~34 wool 14  
fill ~34 ~2 ~41 ~34 ~2 ~123 iron_bars 0  
fill ~34 ~2 ~129 ~35 ~2 ~129 wool 14  
fill ~35 ~2 ~1 ~69 ~2 ~1 wool 0  
fill ~35 ~2 ~33 ~41 ~2 ~33 wool 14  
fill ~35 ~2 ~35 ~35 ~3 ~35 wool 0  
fill ~35 ~2 ~123 ~35 ~2 ~124 iron_bars 0  
fill ~35 ~2 ~130 ~41 ~2 ~130 wool 14  
fill ~35 ~2 ~162 ~69 ~2 ~162 wool 0 
setblock ~36 ~2 ~2 torch 3  
fill ~36 ~2 ~32 ~38 ~2 ~32 wool 14  
fill ~36 ~2 ~36 ~36 ~3 ~36 wool 0  
fill ~36 ~2 ~124 ~36 ~2 ~125 iron_bars 0  
fill ~36 ~2 ~131 ~41 ~2 ~131 wool 14  
fill ~37 ~2 ~37 ~37 ~3 ~37 wool 0  
fill ~37 ~2 ~125 ~37 ~2 ~126 iron_bars 0  
fill ~38 ~2 ~37 ~67 ~2 ~37 iron_bars 0  
fill ~38 ~2 ~126 ~38 ~2 ~127 iron_bars 0  
fill ~38 ~2 ~132 ~38 ~3 ~132 wool 14  
fill ~39 ~2 ~10 ~40 ~2 ~10 wool 0  
fill ~39 ~2 ~11 ~40 ~2 ~11 wool 0  
fill ~39 ~2 ~127 ~66 ~2 ~127 iron_bars 0  
fill ~40 ~2 ~153 ~41 ~2 ~153 wool 0  
fill ~40 ~2 ~154 ~41 ~2 ~154 wool 0  
fill ~41 ~2 ~32 ~43 ~2 ~32 wool 0  
fill ~41 ~2 ~132 ~43 ~2 ~132 wool 0  
fill ~42 ~2 ~33 ~42 ~2 ~34 wool 0  
fill ~42 ~2 ~130 ~42 ~2 ~132 wool 0  
fill ~43 ~2 ~10 ~44 ~2 ~10 wool 0  
fill ~43 ~2 ~11 ~44 ~2 ~11 wool 0  
fill ~43 ~2 ~33 ~61 ~2 ~33 wool 14  
fill ~43 ~2 ~34 ~61 ~2 ~34 wool 14  
fill ~43 ~2 ~130 ~61 ~2 ~130 wool 14  
fill ~43 ~2 ~131 ~61 ~2 ~131 wool 14  
fill ~44 ~2 ~153 ~45 ~2 ~153 wool 0  
fill ~44 ~2 ~154 ~45 ~2 ~154 wool 0  
fill ~60 ~2 ~10 ~61 ~2 ~10 wool 0  
fill ~60 ~2 ~11 ~61 ~2 ~11 wool 0  
fill ~60 ~2 ~153 ~61 ~2 ~153 wool 0  
fill ~60 ~2 ~154 ~61 ~2 ~154 wool 0  
fill ~61 ~2 ~32 ~63 ~2 ~32 wool 0  
fill ~61 ~2 ~132 ~63 ~2 ~132 wool 0  
fill ~62 ~2 ~33 ~62 ~2 ~34 wool 0  
fill ~62 ~2 ~130 ~62 ~2 ~132 wool 0  
fill ~63 ~2 ~33 ~69 ~2 ~33 wool 14  
fill ~63 ~2 ~34 ~70 ~2 ~34 wool 14  
fill ~63 ~2 ~130 ~69 ~2 ~130 wool 14  
fill ~63 ~2 ~131 ~68 ~2 ~131 wool 14  
fill ~64 ~2 ~10 ~65 ~2 ~10 wool 0  
fill ~64 ~2 ~11 ~65 ~2 ~11 wool 0  
fill ~64 ~2 ~153 ~65 ~2 ~153 wool 0  
fill ~64 ~2 ~154 ~65 ~2 ~154 wool 0  
fill ~66 ~2 ~32 ~68 ~2 ~32 wool 14 
setblock ~66 ~2 ~126 iron_bars 0  
fill ~66 ~2 ~132 ~67 ~2 ~132 wool 14  
fill ~67 ~2 ~38 ~68 ~2 ~38 iron_bars 0 
setblock ~68 ~2 ~2 torch 3  
fill ~68 ~2 ~39 ~69 ~2 ~39 iron_bars 0  
fill ~69 ~2 ~40 ~70 ~2 ~40 iron_bars 0  
fill ~69 ~2 ~129 ~70 ~2 ~129 wool 14  
fill ~70 ~2 ~35 ~71 ~2 ~35 wool 14  
fill ~70 ~2 ~41 ~70 ~2 ~123 iron_bars 0  
fill ~71 ~2 ~36 ~72 ~2 ~36 wool 14 
setblock ~71 ~2 ~128 wool 14  
fill ~72 ~2 ~37 ~73 ~2 ~37 wool 14  
fill ~72 ~2 ~126 ~73 ~2 ~126 wool 14  
fill ~72 ~2 ~127 ~72 ~2 ~126 wool 14  
fill ~73 ~2 ~38 ~74 ~2 ~38 wool 14  
fill ~73 ~2 ~39 ~75 ~2 ~39 wool 14  
fill ~73 ~2 ~40 ~75 ~2 ~40 wool 14  
fill ~73 ~2 ~41 ~74 ~2 ~41 wool 14  
fill ~73 ~2 ~42 ~74 ~2 ~42 wool 14  
fill ~73 ~2 ~43 ~74 ~2 ~43 wool 14  
fill ~73 ~2 ~44 ~74 ~2 ~44 wool 14  
fill ~73 ~2 ~45 ~74 ~2 ~45 wool 14  
fill ~73 ~2 ~46 ~74 ~2 ~46 wool 14  
fill ~73 ~2 ~47 ~75 ~2 ~47 wool 0  
fill ~73 ~2 ~48 ~74 ~2 ~48 wool 14  
fill ~73 ~2 ~49 ~74 ~2 ~49 wool 14  
fill ~73 ~2 ~50 ~74 ~2 ~50 wool 14  
fill ~73 ~2 ~51 ~74 ~2 ~51 wool 14  
fill ~73 ~2 ~52 ~74 ~2 ~52 wool 14  
fill ~73 ~2 ~53 ~74 ~2 ~53 wool 14  
fill ~73 ~2 ~54 ~74 ~2 ~54 wool 14  
fill ~73 ~2 ~55 ~74 ~2 ~55 wool 14  
fill ~73 ~2 ~56 ~74 ~2 ~56 wool 14  
fill ~73 ~2 ~57 ~74 ~2 ~57 wool 14  
fill ~73 ~2 ~58 ~74 ~2 ~58 wool 14  
fill ~73 ~2 ~59 ~74 ~2 ~59 wool 14  
fill ~73 ~2 ~60 ~74 ~2 ~60 wool 14  
fill ~73 ~2 ~61 ~74 ~2 ~61 wool 14  
fill ~73 ~2 ~62 ~74 ~2 ~62 wool 14  
fill ~73 ~2 ~63 ~74 ~2 ~63 wool 14  
fill ~73 ~2 ~64 ~74 ~2 ~64 wool 14  
fill ~73 ~2 ~65 ~74 ~2 ~65 wool 14  
fill ~73 ~2 ~66 ~74 ~2 ~66 wool 14  
fill ~73 ~2 ~67 ~75 ~2 ~67 wool 0  
fill ~73 ~2 ~68 ~74 ~2 ~68 wool 14  
fill ~73 ~2 ~69 ~74 ~2 ~69 wool 14  
fill ~73 ~2 ~70 ~74 ~2 ~70 wool 14  
fill ~73 ~2 ~71 ~74 ~2 ~71 wool 14  
fill ~73 ~2 ~72 ~74 ~2 ~72 wool 14  
fill ~73 ~2 ~73 ~74 ~2 ~73 wool 14  
fill ~73 ~2 ~74 ~74 ~2 ~74 wool 14  
fill ~73 ~2 ~75 ~74 ~2 ~75 wool 14  
fill ~73 ~2 ~76 ~74 ~2 ~76 wool 14  
fill ~73 ~2 ~77 ~74 ~2 ~77 wool 14  
fill ~73 ~2 ~78 ~74 ~2 ~78 wool 14  
fill ~73 ~2 ~79 ~74 ~2 ~79 wool 14  
fill ~73 ~2 ~80 ~74 ~2 ~80 wool 14  
fill ~73 ~2 ~81 ~74 ~2 ~81 wool 14  
fill ~73 ~2 ~82 ~74 ~2 ~82 wool 14  
fill ~73 ~2 ~83 ~74 ~2 ~83 wool 14  
fill ~73 ~2 ~84 ~74 ~2 ~84 wool 14  
fill ~73 ~2 ~85 ~74 ~2 ~85 wool 14  
fill ~73 ~2 ~86 ~74 ~2 ~86 wool 14  
fill ~73 ~2 ~87 ~74 ~2 ~87 wool 14  
fill ~73 ~2 ~88 ~75 ~2 ~88 wool 0  
fill ~73 ~2 ~89 ~74 ~2 ~89 wool 14  
fill ~73 ~2 ~90 ~74 ~2 ~90 wool 14  
fill ~73 ~2 ~91 ~74 ~2 ~91 wool 14  
fill ~73 ~2 ~92 ~74 ~2 ~92 wool 14  
fill ~73 ~2 ~93 ~74 ~2 ~93 wool 14  
fill ~73 ~2 ~94 ~74 ~2 ~94 wool 14  
fill ~73 ~2 ~95 ~74 ~2 ~95 wool 14  
fill ~73 ~2 ~96 ~74 ~2 ~96 wool 14  
fill ~73 ~2 ~97 ~74 ~2 ~97 wool 14  
fill ~73 ~2 ~98 ~74 ~2 ~98 wool 14  
fill ~73 ~2 ~99 ~74 ~2 ~99 wool 14  
fill ~73 ~2 ~100 ~74 ~2 ~100 wool 14  
fill ~73 ~2 ~101 ~74 ~2 ~101 wool 14  
fill ~73 ~2 ~102 ~74 ~2 ~102 wool 14  
fill ~73 ~2 ~103 ~74 ~2 ~103 wool 14  
fill ~73 ~2 ~104 ~74 ~2 ~104 wool 14  
fill ~73 ~2 ~105 ~74 ~2 ~105 wool 14  
fill ~73 ~2 ~106 ~74 ~2 ~106 wool 14  
fill ~73 ~2 ~107 ~74 ~2 ~107 wool 14  
fill ~73 ~2 ~108 ~74 ~2 ~108 wool 14  
fill ~73 ~2 ~109 ~74 ~2 ~109 wool 14  
fill ~73 ~2 ~110 ~75 ~2 ~110 wool 0  
fill ~73 ~2 ~111 ~74 ~2 ~111 wool 14  
fill ~73 ~2 ~112 ~74 ~2 ~112 wool 14  
fill ~73 ~2 ~113 ~74 ~2 ~113 wool 14  
fill ~73 ~2 ~114 ~74 ~2 ~114 wool 14  
fill ~73 ~2 ~115 ~74 ~2 ~115 wool 14  
fill ~73 ~2 ~116 ~74 ~2 ~116 wool 14  
fill ~73 ~2 ~117 ~74 ~2 ~117 wool 14  
fill ~73 ~2 ~118 ~74 ~2 ~118 wool 14  
fill ~73 ~2 ~119 ~74 ~2 ~119 wool 14  
fill ~73 ~2 ~120 ~74 ~2 ~120 wool 14  
fill ~73 ~2 ~121 ~74 ~2 ~121 wool 14  
fill ~73 ~2 ~122 ~74 ~2 ~122 wool 14  
fill ~73 ~2 ~123 ~75 ~2 ~123 wool 14  
fill ~73 ~2 ~124 ~74 ~2 ~124 wool 14  
fill ~73 ~2 ~125 ~74 ~2 ~125 wool 14  
fill ~75 ~2 ~46 ~75 ~1 ~46 wool 0  
fill ~75 ~2 ~48 ~75 ~1 ~48 wool 0  
fill ~75 ~2 ~66 ~75 ~1 ~66 wool 0  
fill ~75 ~2 ~68 ~75 ~1 ~68 wool 0  
fill ~75 ~2 ~87 ~75 ~1 ~87 wool 0  
fill ~75 ~2 ~89 ~75 ~1 ~89 wool 0  
fill ~75 ~2 ~109 ~75 ~1 ~109 wool 0  
fill ~75 ~2 ~111 ~75 ~1 ~111 wool 0 
setblock ~80 ~2 ~150 torch 2  
fill ~91 ~2 ~64 ~92 ~2 ~64 wool 0  
fill ~91 ~2 ~65 ~92 ~2 ~65 wool 0  
fill ~92 ~2 ~48 ~93 ~2 ~48 wool 0  
fill ~92 ~2 ~49 ~93 ~2 ~49 wool 0  
fill ~92 ~2 ~68 ~93 ~2 ~68 wool 0  
fill ~92 ~2 ~69 ~93 ~2 ~69 wool 0  
fill ~92 ~2 ~85 ~93 ~2 ~85 wool 0  
fill ~92 ~2 ~86 ~93 ~2 ~86 wool 0  
fill ~92 ~2 ~89 ~93 ~2 ~89 wool 0  
fill ~92 ~2 ~90 ~93 ~2 ~90 wool 0  
fill ~93 ~2 ~44 ~94 ~2 ~44 wool 0  
fill ~93 ~2 ~45 ~94 ~2 ~45 wool 0  
fill ~94 ~2 ~107 ~95 ~2 ~107 wool 0  
fill ~94 ~2 ~108 ~95 ~2 ~108 wool 0  
fill ~94 ~2 ~111 ~95 ~2 ~111 wool 0  
fill ~94 ~2 ~112 ~95 ~2 ~112 wool 0 
setblock ~97 ~2 ~30 torch 2 
setblock ~102 ~2 ~48 torch 2 
setblock ~102 ~2 ~69 torch 2 
setblock ~102 ~2 ~84 torch 2 
setblock ~102 ~2 ~114 torch 2 
setblock ~2 ~3 ~106 torch 1  
fill ~8 ~3 ~45 ~9 ~3 ~45 wool 0  
fill ~8 ~3 ~46 ~9 ~3 ~46 wool 0  
fill ~8 ~3 ~49 ~9 ~3 ~49 wool 0  
fill ~8 ~3 ~50 ~9 ~3 ~50 wool 0  
fill ~8 ~3 ~65 ~9 ~3 ~65 wool 0  
fill ~8 ~3 ~66 ~9 ~3 ~66 wool 0  
fill ~8 ~3 ~69 ~9 ~3 ~69 wool 0  
fill ~8 ~3 ~70 ~9 ~3 ~70 wool 0  
fill ~8 ~3 ~86 ~9 ~3 ~86 wool 0  
fill ~8 ~3 ~87 ~9 ~3 ~87 wool 0  
fill ~8 ~3 ~90 ~9 ~3 ~90 wool 0  
fill ~8 ~3 ~91 ~9 ~3 ~91 wool 0  
fill ~8 ~3 ~108 ~9 ~3 ~108 wool 0  
fill ~8 ~3 ~109 ~9 ~3 ~109 wool 0  
fill ~8 ~3 ~112 ~9 ~3 ~112 wool 0  
fill ~8 ~3 ~113 ~9 ~3 ~113 wool 0 
setblock ~13 ~3 ~139 torch 4  
fill ~27 ~3 ~40 ~29 ~3 ~40 wool 14  
fill ~27 ~3 ~41 ~29 ~3 ~41 wool 14  
fill ~27 ~3 ~42 ~29 ~3 ~42 wool 14  
fill ~27 ~3 ~43 ~29 ~3 ~43 wool 14  
fill ~27 ~3 ~44 ~29 ~3 ~44 wool 14  
fill ~27 ~3 ~45 ~29 ~3 ~45 wool 14  
fill ~27 ~3 ~46 ~29 ~3 ~46 wool 14  
fill ~27 ~3 ~48 ~29 ~3 ~48 wool 14  
fill ~27 ~3 ~49 ~29 ~3 ~49 wool 14  
fill ~27 ~3 ~50 ~29 ~3 ~50 wool 14  
fill ~27 ~3 ~51 ~29 ~3 ~51 wool 14  
fill ~27 ~3 ~52 ~29 ~3 ~52 wool 14  
fill ~27 ~3 ~53 ~29 ~3 ~53 wool 14  
fill ~27 ~3 ~54 ~29 ~3 ~54 wool 14  
fill ~27 ~3 ~55 ~29 ~3 ~55 wool 14  
fill ~27 ~3 ~56 ~29 ~3 ~56 wool 14  
fill ~27 ~3 ~57 ~29 ~3 ~57 wool 14  
fill ~27 ~3 ~58 ~29 ~3 ~58 wool 14  
fill ~27 ~3 ~59 ~29 ~3 ~59 wool 14  
fill ~27 ~3 ~60 ~29 ~3 ~60 wool 14  
fill ~27 ~3 ~61 ~29 ~3 ~61 wool 14  
fill ~27 ~3 ~62 ~29 ~3 ~62 wool 14  
fill ~27 ~3 ~63 ~29 ~3 ~63 wool 14  
fill ~27 ~3 ~64 ~29 ~3 ~64 wool 14  
fill ~27 ~3 ~65 ~29 ~3 ~65 wool 14  
fill ~27 ~3 ~66 ~29 ~3 ~66 wool 14  
fill ~27 ~3 ~68 ~29 ~3 ~68 wool 14  
fill ~27 ~3 ~69 ~29 ~3 ~69 wool 14  
fill ~27 ~3 ~70 ~29 ~3 ~70 wool 14  
fill ~27 ~3 ~71 ~29 ~3 ~71 wool 14  
fill ~27 ~3 ~72 ~29 ~3 ~72 wool 14  
fill ~27 ~3 ~73 ~29 ~3 ~73 wool 14  
fill ~27 ~3 ~74 ~29 ~3 ~74 wool 14  
fill ~27 ~3 ~75 ~29 ~3 ~75 wool 14  
fill ~27 ~3 ~76 ~29 ~3 ~76 wool 14  
fill ~27 ~3 ~77 ~29 ~3 ~77 wool 14  
fill ~27 ~3 ~78 ~29 ~3 ~78 wool 14  
fill ~27 ~3 ~79 ~29 ~3 ~79 wool 14  
fill ~27 ~3 ~80 ~29 ~3 ~80 wool 14  
fill ~27 ~3 ~81 ~29 ~3 ~81 wool 14  
fill ~27 ~3 ~82 ~29 ~3 ~82 wool 14  
fill ~27 ~3 ~83 ~29 ~3 ~83 wool 14  
fill ~27 ~3 ~84 ~29 ~3 ~84 wool 14  
fill ~27 ~3 ~85 ~29 ~3 ~85 wool 14  
fill ~27 ~3 ~86 ~29 ~3 ~86 wool 14  
fill ~27 ~3 ~87 ~29 ~3 ~87 wool 14  
fill ~27 ~3 ~89 ~29 ~3 ~89 wool 14  
fill ~27 ~3 ~90 ~29 ~3 ~90 wool 14  
fill ~27 ~3 ~91 ~29 ~3 ~91 wool 14  
fill ~27 ~3 ~92 ~29 ~3 ~92 wool 14  
fill ~27 ~3 ~93 ~29 ~3 ~93 wool 14  
fill ~27 ~3 ~94 ~29 ~3 ~94 wool 14  
fill ~27 ~3 ~95 ~29 ~3 ~95 wool 14  
fill ~27 ~3 ~96 ~29 ~3 ~96 wool 14  
fill ~27 ~3 ~97 ~29 ~3 ~97 wool 14  
fill ~27 ~3 ~98 ~29 ~3 ~98 wool 14  
fill ~27 ~3 ~99 ~29 ~3 ~99 wool 14  
fill ~27 ~3 ~100 ~29 ~3 ~100 wool 14  
fill ~27 ~3 ~101 ~29 ~3 ~101 wool 14  
fill ~27 ~3 ~102 ~29 ~3 ~102 wool 14  
fill ~27 ~3 ~103 ~29 ~3 ~103 wool 14  
fill ~27 ~3 ~104 ~29 ~3 ~104 wool 14  
fill ~27 ~3 ~105 ~29 ~3 ~105 wool 14  
fill ~27 ~3 ~106 ~29 ~3 ~106 wool 14  
fill ~27 ~3 ~107 ~29 ~3 ~107 wool 14  
fill ~27 ~3 ~108 ~29 ~3 ~108 wool 14  
fill ~27 ~3 ~109 ~29 ~3 ~109 wool 14  
fill ~27 ~3 ~111 ~29 ~3 ~111 wool 14  
fill ~27 ~3 ~112 ~29 ~3 ~112 wool 14  
fill ~27 ~3 ~113 ~29 ~3 ~113 wool 14  
fill ~27 ~3 ~114 ~29 ~3 ~114 wool 14  
fill ~27 ~3 ~115 ~29 ~3 ~115 wool 14  
fill ~27 ~3 ~116 ~29 ~3 ~116 wool 14  
fill ~27 ~3 ~117 ~29 ~3 ~117 wool 14  
fill ~27 ~3 ~118 ~29 ~3 ~118 wool 14  
fill ~27 ~3 ~119 ~29 ~3 ~119 wool 14  
fill ~27 ~3 ~120 ~29 ~3 ~120 wool 14  
fill ~27 ~3 ~121 ~29 ~3 ~121 wool 14  
fill ~27 ~3 ~122 ~29 ~3 ~122 wool 14  
fill ~27 ~3 ~123 ~29 ~3 ~123 wool 14  
fill ~27 ~3 ~124 ~29 ~3 ~124 wool 14  
fill ~28 ~3 ~38 ~29 ~3 ~38 wool 14  
fill ~28 ~3 ~39 ~29 ~3 ~39 wool 14  
fill ~28 ~3 ~125 ~29 ~3 ~125 wool 14  
fill ~29 ~3 ~37 ~30 ~3 ~37 wool 14  
fill ~29 ~3 ~126 ~30 ~3 ~126 wool 14  
fill ~30 ~3 ~36 ~31 ~3 ~36 wool 14  
fill ~30 ~3 ~46 ~30 ~5 ~46 wool 0  
fill ~30 ~3 ~48 ~30 ~5 ~48 wool 0  
fill ~30 ~3 ~66 ~30 ~5 ~66 wool 0  
fill ~30 ~3 ~68 ~30 ~5 ~68 wool 0  
fill ~30 ~3 ~87 ~30 ~5 ~87 wool 0  
fill ~30 ~3 ~89 ~30 ~5 ~89 wool 0  
fill ~30 ~3 ~109 ~30 ~5 ~109 wool 0  
fill ~30 ~3 ~111 ~30 ~5 ~111 wool 0  
fill ~30 ~3 ~127 ~31 ~3 ~127 wool 14  
fill ~31 ~3 ~35 ~32 ~3 ~35 wool 14  
fill ~31 ~3 ~37 ~37 ~3 ~37 wool 0 
setblock ~31 ~3 ~38 torch 3  
fill ~31 ~3 ~128 ~32 ~3 ~128 wool 14  
fill ~32 ~3 ~34 ~33 ~3 ~34 wool 14  
fill ~32 ~3 ~36 ~36 ~3 ~36 wool 0  
fill ~32 ~3 ~129 ~33 ~3 ~129 wool 14  
fill ~33 ~3 ~33 ~34 ~3 ~33 wool 14  
fill ~33 ~3 ~35 ~35 ~3 ~35 wool 0  
fill ~33 ~3 ~38 ~37 ~3 ~38 wool 0  
fill ~33 ~3 ~130 ~34 ~3 ~130 wool 14  
fill ~34 ~3 ~32 ~41 ~3 ~32 wool 14 
setblock ~34 ~3 ~34 wool 0  
fill ~34 ~3 ~39 ~36 ~3 ~39 wool 0  
fill ~34 ~3 ~131 ~35 ~3 ~131 wool 14  
fill ~35 ~3 ~1 ~69 ~3 ~1 wool 0  
fill ~35 ~3 ~31 ~41 ~3 ~31 wool 14 
setblock ~35 ~3 ~34 torch 1  
fill ~35 ~3 ~132 ~41 ~3 ~132 wool 14  
fill ~35 ~3 ~162 ~69 ~3 ~162 wool 0  
fill ~36 ~3 ~30 ~38 ~3 ~30 wool 14  
fill ~36 ~3 ~133 ~41 ~3 ~133 wool 14  
fill ~38 ~3 ~134 ~38 ~4 ~134 wool 14  
fill ~39 ~3 ~9 ~40 ~3 ~9 wool 0  
fill ~39 ~3 ~10 ~40 ~3 ~10 wool 0  
fill ~40 ~3 ~154 ~41 ~3 ~154 wool 0  
fill ~40 ~3 ~155 ~41 ~3 ~155 wool 0  
fill ~41 ~3 ~33 ~41 ~5 ~33 wool 0  
fill ~41 ~3 ~131 ~41 ~5 ~131 wool 0  
fill ~43 ~3 ~9 ~44 ~3 ~9 wool 0  
fill ~43 ~3 ~10 ~44 ~3 ~10 wool 0  
fill ~43 ~3 ~31 ~61 ~3 ~31 wool 14  
fill ~43 ~3 ~32 ~61 ~3 ~32 wool 14  
fill ~43 ~3 ~33 ~43 ~5 ~33 wool 0  
fill ~43 ~3 ~131 ~43 ~5 ~131 wool 0  
fill ~43 ~3 ~132 ~61 ~3 ~132 wool 14  
fill ~43 ~3 ~133 ~61 ~3 ~133 wool 14  
fill ~44 ~3 ~154 ~45 ~3 ~154 wool 0  
fill ~44 ~3 ~155 ~45 ~3 ~155 wool 0 
setblock ~51 ~3 ~2 torch 3  
fill ~52 ~3 ~42 ~52 ~4 ~42 wool 4  
fill ~52 ~3 ~121 ~52 ~4 ~121 wool 4 
setblock ~54 ~3 ~161 torch 4  
fill ~60 ~3 ~9 ~61 ~3 ~9 wool 0  
fill ~60 ~3 ~10 ~61 ~3 ~10 wool 0  
fill ~60 ~3 ~154 ~61 ~3 ~154 wool 0  
fill ~60 ~3 ~155 ~61 ~3 ~155 wool 0  
fill ~61 ~3 ~33 ~61 ~5 ~33 wool 0  
fill ~61 ~3 ~131 ~61 ~5 ~131 wool 0  
fill ~63 ~3 ~31 ~69 ~3 ~31 wool 14  
fill ~63 ~3 ~32 ~70 ~3 ~32 wool 14  
fill ~63 ~3 ~33 ~63 ~5 ~33 wool 0  
fill ~63 ~3 ~131 ~63 ~5 ~131 wool 0  
fill ~63 ~3 ~132 ~69 ~3 ~132 wool 14  
fill ~63 ~3 ~133 ~68 ~3 ~133 wool 14  
fill ~64 ~3 ~9 ~65 ~3 ~9 wool 0  
fill ~64 ~3 ~10 ~65 ~3 ~10 wool 0  
fill ~64 ~3 ~154 ~65 ~3 ~154 wool 0  
fill ~64 ~3 ~155 ~65 ~3 ~155 wool 0  
fill ~66 ~3 ~30 ~68 ~3 ~30 wool 14  
fill ~66 ~3 ~134 ~67 ~3 ~134 wool 14  
fill ~68 ~3 ~125 ~71 ~3 ~125 wool 0  
fill ~68 ~3 ~126 ~72 ~3 ~126 wool 0  
fill ~68 ~3 ~127 ~72 ~3 ~127 wool 0  
fill ~69 ~3 ~124 ~70 ~3 ~124 wool 0  
fill ~69 ~3 ~128 ~71 ~3 ~128 wool 0 
setblock ~69 ~3 ~130 torch 4  
fill ~69 ~3 ~131 ~70 ~3 ~131 wool 14 
setblock ~69 ~3 ~161 torch 2  
fill ~70 ~3 ~33 ~71 ~3 ~33 wool 14 
setblock ~70 ~3 ~129 wool 0  
fill ~70 ~3 ~130 ~71 ~3 ~130 wool 14  
fill ~71 ~3 ~34 ~72 ~3 ~34 wool 14  
fill ~71 ~3 ~129 ~72 ~3 ~129 wool 14  
fill ~72 ~3 ~35 ~73 ~3 ~35 wool 14 
setblock ~72 ~3 ~125 torch 4  
fill ~72 ~3 ~128 ~73 ~3 ~128 wool 14  
fill ~73 ~3 ~36 ~74 ~3 ~36 wool 14  
fill ~73 ~3 ~127 ~74 ~3 ~127 wool 14  
fill ~74 ~3 ~37 ~75 ~3 ~37 wool 14  
fill ~74 ~3 ~46 ~74 ~5 ~46 wool 0  
fill ~74 ~3 ~48 ~74 ~5 ~48 wool 0  
fill ~74 ~3 ~66 ~74 ~5 ~66 wool 0  
fill ~74 ~3 ~68 ~74 ~5 ~68 wool 0  
fill ~74 ~3 ~87 ~74 ~5 ~87 wool 0  
fill ~74 ~3 ~89 ~74 ~5 ~89 wool 0  
fill ~74 ~3 ~109 ~74 ~5 ~109 wool 0  
fill ~74 ~3 ~111 ~74 ~5 ~111 wool 0  
fill ~74 ~3 ~126 ~75 ~3 ~126 wool 14 
setblock ~74 ~3 ~156 torch 2  
fill ~75 ~3 ~38 ~76 ~3 ~38 wool 14  
fill ~75 ~3 ~39 ~77 ~3 ~39 wool 14  
fill ~75 ~3 ~40 ~77 ~3 ~40 wool 14  
fill ~75 ~3 ~41 ~77 ~3 ~41 wool 14  
fill ~75 ~3 ~42 ~77 ~3 ~42 wool 14  
fill ~75 ~3 ~43 ~77 ~3 ~43 wool 14  
fill ~75 ~3 ~44 ~77 ~3 ~44 wool 14  
fill ~75 ~3 ~45 ~77 ~3 ~45 wool 14  
fill ~75 ~3 ~46 ~77 ~3 ~46 wool 14  
fill ~75 ~3 ~48 ~77 ~3 ~48 wool 14  
fill ~75 ~3 ~49 ~77 ~3 ~49 wool 14  
fill ~75 ~3 ~50 ~77 ~3 ~50 wool 14  
fill ~75 ~3 ~51 ~77 ~3 ~51 wool 14  
fill ~75 ~3 ~52 ~77 ~3 ~52 wool 14  
fill ~75 ~3 ~53 ~77 ~3 ~53 wool 14  
fill ~75 ~3 ~54 ~77 ~3 ~54 wool 14  
fill ~75 ~3 ~55 ~77 ~3 ~55 wool 14  
fill ~75 ~3 ~56 ~77 ~3 ~56 wool 14  
fill ~75 ~3 ~57 ~77 ~3 ~57 wool 14  
fill ~75 ~3 ~58 ~77 ~3 ~58 wool 14  
fill ~75 ~3 ~59 ~77 ~3 ~59 wool 14  
fill ~75 ~3 ~60 ~77 ~3 ~60 wool 14  
fill ~75 ~3 ~61 ~77 ~3 ~61 wool 14  
fill ~75 ~3 ~62 ~77 ~3 ~62 wool 14  
fill ~75 ~3 ~63 ~77 ~3 ~63 wool 14  
fill ~75 ~3 ~64 ~77 ~3 ~64 wool 14  
fill ~75 ~3 ~65 ~77 ~3 ~65 wool 14  
fill ~75 ~3 ~66 ~77 ~3 ~66 wool 14  
fill ~75 ~3 ~68 ~77 ~3 ~68 wool 14  
fill ~75 ~3 ~69 ~77 ~3 ~69 wool 14  
fill ~75 ~3 ~70 ~77 ~3 ~70 wool 14  
fill ~75 ~3 ~71 ~77 ~3 ~71 wool 14  
fill ~75 ~3 ~72 ~77 ~3 ~72 wool 14  
fill ~75 ~3 ~73 ~77 ~3 ~73 wool 14  
fill ~75 ~3 ~74 ~77 ~3 ~74 wool 14  
fill ~75 ~3 ~75 ~77 ~3 ~75 wool 14  
fill ~75 ~3 ~76 ~77 ~3 ~76 wool 14  
fill ~75 ~3 ~77 ~77 ~3 ~77 wool 14  
fill ~75 ~3 ~78 ~77 ~3 ~78 wool 14  
fill ~75 ~3 ~79 ~77 ~3 ~79 wool 14  
fill ~75 ~3 ~80 ~77 ~3 ~80 wool 14  
fill ~75 ~3 ~81 ~77 ~3 ~81 wool 14  
fill ~75 ~3 ~82 ~77 ~3 ~82 wool 14  
fill ~75 ~3 ~83 ~77 ~3 ~83 wool 14  
fill ~75 ~3 ~84 ~77 ~3 ~84 wool 14  
fill ~75 ~3 ~85 ~77 ~3 ~85 wool 14  
fill ~75 ~3 ~86 ~77 ~3 ~86 wool 14  
fill ~75 ~3 ~87 ~77 ~3 ~87 wool 14  
fill ~75 ~3 ~89 ~77 ~3 ~89 wool 14  
fill ~75 ~3 ~90 ~77 ~3 ~90 wool 14  
fill ~75 ~3 ~91 ~77 ~3 ~91 wool 14  
fill ~75 ~3 ~92 ~77 ~3 ~92 wool 14  
fill ~75 ~3 ~93 ~77 ~3 ~93 wool 14  
fill ~75 ~3 ~94 ~77 ~3 ~94 wool 14  
fill ~75 ~3 ~95 ~77 ~3 ~95 wool 14  
fill ~75 ~3 ~96 ~77 ~3 ~96 wool 14  
fill ~75 ~3 ~97 ~77 ~3 ~97 wool 14  
fill ~75 ~3 ~98 ~77 ~3 ~98 wool 14  
fill ~75 ~3 ~99 ~77 ~3 ~99 wool 14  
fill ~75 ~3 ~100 ~77 ~3 ~100 wool 14  
fill ~75 ~3 ~101 ~77 ~3 ~101 wool 14  
fill ~75 ~3 ~102 ~77 ~3 ~102 wool 14  
fill ~75 ~3 ~103 ~77 ~3 ~103 wool 14  
fill ~75 ~3 ~104 ~77 ~3 ~104 wool 14  
fill ~75 ~3 ~105 ~77 ~3 ~105 wool 14  
fill ~75 ~3 ~106 ~77 ~3 ~106 wool 14  
fill ~75 ~3 ~107 ~77 ~3 ~107 wool 14  
fill ~75 ~3 ~108 ~77 ~3 ~108 wool 14  
fill ~75 ~3 ~109 ~77 ~3 ~109 wool 14  
fill ~75 ~3 ~111 ~77 ~3 ~111 wool 14  
fill ~75 ~3 ~112 ~76 ~3 ~112 wool 14  
fill ~75 ~3 ~113 ~77 ~3 ~113 wool 14  
fill ~75 ~3 ~114 ~77 ~3 ~114 wool 14  
fill ~75 ~3 ~115 ~77 ~3 ~115 wool 14  
fill ~75 ~3 ~116 ~77 ~3 ~116 wool 14  
fill ~75 ~3 ~117 ~77 ~3 ~117 wool 14  
fill ~75 ~3 ~118 ~77 ~3 ~118 wool 14  
fill ~75 ~3 ~119 ~77 ~3 ~119 wool 14  
fill ~75 ~3 ~120 ~77 ~3 ~120 wool 14  
fill ~75 ~3 ~121 ~77 ~3 ~121 wool 14  
fill ~75 ~3 ~122 ~77 ~3 ~122 wool 14  
fill ~75 ~3 ~123 ~77 ~3 ~123 wool 14  
fill ~75 ~3 ~124 ~76 ~3 ~124 wool 14  
fill ~75 ~3 ~125 ~76 ~3 ~125 wool 14 
setblock ~76 ~3 ~9 torch 2 
setblock ~84 ~3 ~146 torch 2 
setblock ~91 ~3 ~139 torch 2  
fill ~92 ~3 ~64 ~93 ~3 ~64 wool 0  
fill ~92 ~3 ~65 ~93 ~3 ~65 wool 0  
fill ~93 ~3 ~48 ~94 ~3 ~48 wool 0  
fill ~93 ~3 ~49 ~94 ~3 ~49 wool 0  
fill ~93 ~3 ~68 ~94 ~3 ~68 wool 0  
fill ~93 ~3 ~69 ~94 ~3 ~69 wool 0  
fill ~93 ~3 ~85 ~94 ~3 ~85 wool 0  
fill ~93 ~3 ~86 ~94 ~3 ~86 wool 0  
fill ~93 ~3 ~89 ~94 ~3 ~89 wool 0  
fill ~93 ~3 ~90 ~94 ~3 ~90 wool 0  
fill ~94 ~3 ~44 ~95 ~3 ~44 wool 0  
fill ~94 ~3 ~45 ~95 ~3 ~45 wool 0  
fill ~95 ~3 ~107 ~96 ~3 ~107 wool 0  
fill ~95 ~3 ~108 ~96 ~3 ~108 wool 0  
fill ~95 ~3 ~111 ~96 ~3 ~111 wool 0  
fill ~95 ~3 ~112 ~96 ~3 ~112 wool 0 
setblock ~97 ~3 ~133 torch 2 
setblock ~102 ~3 ~57 torch 2 
setblock ~102 ~3 ~99 torch 2  
fill ~7 ~4 ~45 ~8 ~4 ~45 wool 0  
fill ~7 ~4 ~46 ~8 ~4 ~46 wool 0  
fill ~7 ~4 ~47 ~7 ~5 ~47 wool 0  
fill ~7 ~4 ~48 ~7 ~5 ~48 wool 0  
fill ~7 ~4 ~49 ~8 ~4 ~49 wool 0  
fill ~7 ~4 ~50 ~8 ~4 ~50 wool 0  
fill ~7 ~4 ~65 ~8 ~4 ~65 wool 0  
fill ~7 ~4 ~66 ~8 ~4 ~66 wool 0  
fill ~7 ~4 ~67 ~7 ~5 ~67 wool 0  
fill ~7 ~4 ~68 ~7 ~5 ~68 wool 0  
fill ~7 ~4 ~69 ~8 ~4 ~69 wool 0  
fill ~7 ~4 ~70 ~8 ~4 ~70 wool 0  
fill ~7 ~4 ~86 ~8 ~4 ~86 wool 0  
fill ~7 ~4 ~87 ~8 ~4 ~87 wool 0  
fill ~7 ~4 ~88 ~7 ~5 ~88 wool 0  
fill ~7 ~4 ~89 ~7 ~5 ~89 wool 0  
fill ~7 ~4 ~90 ~8 ~4 ~90 wool 0  
fill ~7 ~4 ~91 ~8 ~4 ~91 wool 0  
fill ~7 ~4 ~108 ~8 ~4 ~108 wool 0  
fill ~7 ~4 ~109 ~8 ~4 ~109 wool 0  
fill ~7 ~4 ~110 ~7 ~5 ~110 wool 0  
fill ~7 ~4 ~111 ~7 ~5 ~111 wool 0  
fill ~7 ~4 ~112 ~8 ~4 ~112 wool 0  
fill ~7 ~4 ~113 ~8 ~4 ~113 wool 0 
setblock ~8 ~4 ~47 torch 1 
setblock ~8 ~4 ~67 torch 1 
setblock ~8 ~4 ~88 torch 1 
setblock ~8 ~4 ~110 torch 1 
setblock ~17 ~4 ~143 torch 4 
setblock ~22 ~4 ~148 torch 4  
fill ~25 ~4 ~40 ~27 ~4 ~40 wool 14  
fill ~25 ~4 ~123 ~27 ~4 ~123 wool 14  
fill ~25 ~4 ~124 ~27 ~4 ~124 wool 14  
fill ~25 ~4 ~125 ~27 ~4 ~125 wool 14  
fill ~26 ~4 ~38 ~27 ~4 ~38 wool 14  
fill ~26 ~4 ~39 ~27 ~4 ~39 wool 14  
fill ~26 ~4 ~41 ~27 ~4 ~41 wool 14  
fill ~26 ~4 ~42 ~27 ~4 ~42 wool 14  
fill ~26 ~4 ~43 ~27 ~4 ~43 wool 14  
fill ~26 ~4 ~44 ~27 ~4 ~44 wool 14  
fill ~26 ~4 ~45 ~27 ~4 ~45 wool 14  
fill ~26 ~4 ~46 ~27 ~4 ~46 wool 14  
fill ~26 ~4 ~47 ~26 ~4 ~125 wool 14  
fill ~27 ~4 ~37 ~28 ~4 ~37 wool 14  
fill ~27 ~4 ~48 ~27 ~3 ~48 wool 14  
fill ~27 ~4 ~49 ~27 ~3 ~49 wool 14  
fill ~27 ~4 ~50 ~27 ~3 ~50 wool 14  
fill ~27 ~4 ~51 ~27 ~3 ~51 wool 14  
fill ~27 ~4 ~52 ~27 ~3 ~52 wool 14  
fill ~27 ~4 ~53 ~27 ~3 ~53 wool 14  
fill ~27 ~4 ~54 ~27 ~3 ~54 wool 14  
fill ~27 ~4 ~55 ~27 ~3 ~55 wool 14  
fill ~27 ~4 ~56 ~27 ~3 ~56 wool 14  
fill ~27 ~4 ~57 ~27 ~3 ~57 wool 14  
fill ~27 ~4 ~58 ~27 ~3 ~58 wool 14  
fill ~27 ~4 ~59 ~27 ~3 ~59 wool 14  
fill ~27 ~4 ~60 ~27 ~3 ~60 wool 14  
fill ~27 ~4 ~61 ~27 ~3 ~61 wool 14  
fill ~27 ~4 ~62 ~27 ~3 ~62 wool 14  
fill ~27 ~4 ~63 ~27 ~3 ~63 wool 14  
fill ~27 ~4 ~64 ~27 ~3 ~64 wool 14  
fill ~27 ~4 ~65 ~27 ~3 ~65 wool 14  
fill ~27 ~4 ~66 ~27 ~3 ~66 wool 14  
fill ~27 ~4 ~67 ~27 ~4 ~87 wool 14  
fill ~27 ~4 ~89 ~27 ~3 ~89 wool 14  
fill ~27 ~4 ~90 ~27 ~3 ~90 wool 14  
fill ~27 ~4 ~91 ~27 ~3 ~91 wool 14  
fill ~27 ~4 ~92 ~27 ~3 ~92 wool 14  
fill ~27 ~4 ~93 ~27 ~3 ~93 wool 14  
fill ~27 ~4 ~94 ~27 ~3 ~94 wool 14  
fill ~27 ~4 ~95 ~27 ~3 ~95 wool 14  
fill ~27 ~4 ~96 ~27 ~3 ~96 wool 14  
fill ~27 ~4 ~97 ~27 ~3 ~97 wool 14  
fill ~27 ~4 ~98 ~27 ~3 ~98 wool 14  
fill ~27 ~4 ~99 ~27 ~3 ~99 wool 14  
fill ~27 ~4 ~100 ~27 ~3 ~100 wool 14  
fill ~27 ~4 ~101 ~27 ~3 ~101 wool 14  
fill ~27 ~4 ~102 ~27 ~3 ~102 wool 14  
fill ~27 ~4 ~103 ~27 ~3 ~103 wool 14  
fill ~27 ~4 ~104 ~27 ~3 ~104 wool 14  
fill ~27 ~4 ~105 ~27 ~3 ~105 wool 14  
fill ~27 ~4 ~106 ~27 ~3 ~106 wool 14  
fill ~27 ~4 ~107 ~27 ~3 ~107 wool 14  
fill ~27 ~4 ~108 ~27 ~3 ~108 wool 14  
fill ~27 ~4 ~109 ~27 ~3 ~109 wool 14  
fill ~27 ~4 ~111 ~27 ~3 ~111 wool 14  
fill ~27 ~4 ~112 ~27 ~3 ~112 wool 14  
fill ~27 ~4 ~113 ~27 ~3 ~113 wool 14  
fill ~27 ~4 ~114 ~27 ~3 ~114 wool 14  
fill ~27 ~4 ~115 ~27 ~3 ~115 wool 14  
fill ~27 ~4 ~116 ~27 ~3 ~116 wool 14  
fill ~27 ~4 ~117 ~27 ~3 ~117 wool 14  
fill ~27 ~4 ~118 ~27 ~3 ~118 wool 14  
fill ~27 ~4 ~119 ~27 ~3 ~119 wool 14  
fill ~27 ~4 ~120 ~27 ~3 ~120 wool 14  
fill ~27 ~4 ~121 ~27 ~3 ~121 wool 14  
fill ~27 ~4 ~122 ~27 ~3 ~122 wool 14  
fill ~27 ~4 ~126 ~28 ~4 ~126 wool 14  
fill ~28 ~4 ~36 ~29 ~4 ~36 wool 14  
fill ~28 ~4 ~46 ~30 ~4 ~46 wool 0  
fill ~28 ~4 ~48 ~30 ~4 ~48 wool 0  
fill ~28 ~4 ~66 ~30 ~4 ~66 wool 0  
fill ~28 ~4 ~68 ~30 ~4 ~68 wool 0  
fill ~28 ~4 ~87 ~30 ~4 ~87 wool 0  
fill ~28 ~4 ~89 ~30 ~4 ~89 wool 0  
fill ~28 ~4 ~109 ~30 ~4 ~109 wool 0  
fill ~28 ~4 ~111 ~30 ~4 ~111 wool 0  
fill ~28 ~4 ~127 ~29 ~4 ~127 wool 14  
fill ~29 ~4 ~35 ~30 ~4 ~35 wool 14  
fill ~29 ~4 ~128 ~30 ~4 ~128 wool 14 
setblock ~29 ~4 ~155 torch 4  
fill ~30 ~4 ~34 ~31 ~4 ~34 wool 14  
fill ~30 ~4 ~129 ~31 ~4 ~129 wool 14  
fill ~31 ~4 ~33 ~32 ~4 ~33 wool 14  
fill ~31 ~4 ~130 ~32 ~4 ~130 wool 14  
fill ~32 ~4 ~32 ~33 ~4 ~32 wool 14  
fill ~32 ~4 ~131 ~33 ~4 ~131 wool 14  
fill ~33 ~4 ~31 ~34 ~4 ~31 wool 14  
fill ~33 ~4 ~132 ~34 ~4 ~132 wool 14  
fill ~34 ~4 ~30 ~41 ~4 ~30 wool 14  
fill ~34 ~4 ~133 ~35 ~4 ~133 wool 14  
fill ~35 ~4 ~1 ~69 ~4 ~1 wool 0  
fill ~35 ~4 ~29 ~69 ~4 ~29 wool 14  
fill ~35 ~4 ~134 ~69 ~4 ~134 wool 14  
fill ~35 ~4 ~162 ~69 ~4 ~162 wool 0  
fill ~36 ~4 ~28 ~38 ~4 ~28 wool 14  
fill ~36 ~4 ~135 ~68 ~4 ~135 wool 14  
fill ~38 ~4 ~136 ~38 ~5 ~136 wool 14  
fill ~39 ~4 ~8 ~44 ~4 ~8 wool 0  
fill ~39 ~4 ~9 ~40 ~4 ~9 wool 0  
fill ~40 ~4 ~155 ~41 ~4 ~155 wool 0  
fill ~40 ~4 ~156 ~45 ~4 ~156 wool 0  
fill ~41 ~4 ~31 ~41 ~5 ~31 wool 0  
fill ~41 ~4 ~32 ~41 ~5 ~32 wool 0  
fill ~41 ~4 ~132 ~41 ~5 ~132 wool 0  
fill ~41 ~4 ~133 ~41 ~5 ~133 wool 0 
setblock ~42 ~4 ~9 torch 3 
setblock ~42 ~4 ~155 torch 4 
setblock ~42 ~4 ~161 torch 4  
fill ~43 ~4 ~9 ~44 ~4 ~9 wool 0  
fill ~43 ~4 ~30 ~61 ~4 ~30 wool 14  
fill ~43 ~4 ~31 ~43 ~5 ~31 wool 0  
fill ~43 ~4 ~32 ~43 ~5 ~32 wool 0  
fill ~43 ~4 ~132 ~43 ~5 ~132 wool 0  
fill ~43 ~4 ~133 ~43 ~5 ~133 wool 0  
fill ~44 ~4 ~155 ~45 ~4 ~155 wool 0  
fill ~49 ~4 ~44 ~55 ~4 ~44 wool 4  
fill ~49 ~4 ~119 ~55 ~4 ~119 wool 4 
setblock ~52 ~4 ~43 wool 4 
setblock ~52 ~4 ~120 wool 4  
fill ~60 ~4 ~8 ~65 ~4 ~8 wool 0  
fill ~60 ~4 ~9 ~61 ~4 ~9 wool 0  
fill ~60 ~4 ~155 ~61 ~4 ~155 wool 0  
fill ~60 ~4 ~156 ~65 ~4 ~156 wool 0  
fill ~61 ~4 ~31 ~61 ~5 ~31 wool 0  
fill ~61 ~4 ~32 ~61 ~5 ~32 wool 0  
fill ~61 ~4 ~132 ~61 ~5 ~132 wool 0  
fill ~61 ~4 ~133 ~61 ~5 ~133 wool 0 
setblock ~62 ~4 ~9 torch 3 
setblock ~62 ~4 ~155 torch 4  
fill ~63 ~4 ~30 ~70 ~4 ~30 wool 14  
fill ~63 ~4 ~31 ~63 ~5 ~31 wool 0  
fill ~63 ~4 ~32 ~63 ~5 ~32 wool 0  
fill ~63 ~4 ~132 ~63 ~5 ~132 wool 0  
fill ~63 ~4 ~133 ~63 ~5 ~133 wool 0  
fill ~64 ~4 ~9 ~65 ~4 ~9 wool 0  
fill ~64 ~4 ~155 ~65 ~4 ~155 wool 0  
fill ~66 ~4 ~28 ~68 ~4 ~28 wool 14  
fill ~66 ~4 ~136 ~68 ~4 ~136 wool 14  
fill ~69 ~4 ~133 ~70 ~4 ~133 wool 14  
fill ~70 ~4 ~31 ~71 ~4 ~31 wool 14  
fill ~70 ~4 ~132 ~71 ~4 ~132 wool 14  
fill ~71 ~4 ~32 ~72 ~4 ~32 wool 14  
fill ~71 ~4 ~131 ~72 ~4 ~131 wool 14  
fill ~72 ~4 ~33 ~73 ~4 ~33 wool 14  
fill ~72 ~4 ~130 ~73 ~4 ~130 wool 14  
fill ~73 ~4 ~34 ~74 ~4 ~34 wool 14  
fill ~73 ~4 ~129 ~74 ~4 ~129 wool 14  
fill ~74 ~4 ~35 ~75 ~4 ~35 wool 14  
fill ~74 ~4 ~128 ~75 ~4 ~128 wool 14  
fill ~75 ~4 ~36 ~76 ~4 ~36 wool 14  
fill ~75 ~4 ~46 ~76 ~4 ~46 wool 0  
fill ~75 ~4 ~48 ~76 ~4 ~48 wool 0  
fill ~75 ~4 ~66 ~76 ~4 ~66 wool 0  
fill ~75 ~4 ~68 ~76 ~4 ~68 wool 0  
fill ~75 ~4 ~87 ~76 ~4 ~87 wool 0  
fill ~75 ~4 ~89 ~76 ~4 ~89 wool 0  
fill ~75 ~4 ~109 ~76 ~4 ~109 wool 0  
fill ~75 ~4 ~111 ~76 ~4 ~111 wool 0  
fill ~75 ~4 ~127 ~76 ~4 ~127 wool 14  
fill ~76 ~4 ~37 ~77 ~4 ~37 wool 14  
fill ~76 ~4 ~126 ~77 ~4 ~126 wool 14  
fill ~77 ~4 ~38 ~78 ~4 ~38 wool 14  
fill ~77 ~4 ~39 ~79 ~4 ~39 wool 14  
fill ~77 ~4 ~40 ~79 ~4 ~40 wool 14  
fill ~77 ~4 ~41 ~78 ~4 ~41 wool 14  
fill ~77 ~4 ~42 ~78 ~4 ~42 wool 14  
fill ~77 ~4 ~43 ~78 ~4 ~43 wool 14  
fill ~77 ~4 ~44 ~78 ~4 ~44 wool 14  
fill ~77 ~4 ~45 ~78 ~4 ~45 wool 14  
fill ~77 ~4 ~46 ~78 ~4 ~46 wool 14  
fill ~77 ~4 ~47 ~78 ~4 ~47 wool 14  
fill ~77 ~4 ~48 ~78 ~4 ~48 wool 14  
fill ~77 ~4 ~49 ~78 ~4 ~49 wool 14  
fill ~77 ~4 ~50 ~78 ~4 ~50 wool 14  
fill ~77 ~4 ~51 ~78 ~4 ~51 wool 14  
fill ~77 ~4 ~52 ~78 ~4 ~52 wool 14  
fill ~77 ~4 ~53 ~78 ~4 ~53 wool 14  
fill ~77 ~4 ~54 ~78 ~4 ~54 wool 14  
fill ~77 ~4 ~55 ~78 ~4 ~55 wool 14  
fill ~77 ~4 ~56 ~78 ~4 ~56 wool 14  
fill ~77 ~4 ~57 ~78 ~4 ~57 wool 14  
fill ~77 ~4 ~58 ~78 ~4 ~58 wool 14  
fill ~77 ~4 ~59 ~78 ~4 ~59 wool 14  
fill ~77 ~4 ~60 ~78 ~4 ~60 wool 14  
fill ~77 ~4 ~61 ~78 ~4 ~61 wool 14  
fill ~77 ~4 ~62 ~78 ~4 ~62 wool 14  
fill ~77 ~4 ~63 ~78 ~4 ~63 wool 14  
fill ~77 ~4 ~64 ~78 ~4 ~64 wool 14  
fill ~77 ~4 ~65 ~78 ~4 ~65 wool 14  
fill ~77 ~4 ~66 ~78 ~4 ~66 wool 14  
fill ~77 ~4 ~68 ~78 ~4 ~68 wool 14  
fill ~77 ~4 ~69 ~78 ~4 ~69 wool 14  
fill ~77 ~4 ~70 ~78 ~4 ~70 wool 14  
fill ~77 ~4 ~71 ~78 ~4 ~71 wool 14  
fill ~77 ~4 ~72 ~78 ~4 ~72 wool 14  
fill ~77 ~4 ~73 ~78 ~4 ~73 wool 14  
fill ~77 ~4 ~74 ~78 ~4 ~74 wool 14  
fill ~77 ~4 ~75 ~78 ~4 ~75 wool 14  
fill ~77 ~4 ~76 ~78 ~4 ~76 wool 14  
fill ~77 ~4 ~77 ~78 ~4 ~77 wool 14  
fill ~77 ~4 ~78 ~78 ~4 ~78 wool 14  
fill ~77 ~4 ~79 ~78 ~4 ~79 wool 14  
fill ~77 ~4 ~80 ~78 ~4 ~80 wool 14  
fill ~77 ~4 ~81 ~78 ~4 ~81 wool 14  
fill ~77 ~4 ~82 ~78 ~4 ~82 wool 14  
fill ~77 ~4 ~83 ~78 ~4 ~83 wool 14  
fill ~77 ~4 ~84 ~78 ~4 ~84 wool 14  
fill ~77 ~4 ~85 ~78 ~4 ~85 wool 14  
fill ~77 ~4 ~86 ~78 ~4 ~86 wool 14  
fill ~77 ~4 ~87 ~78 ~4 ~87 wool 14  
fill ~77 ~4 ~89 ~78 ~4 ~89 wool 14  
fill ~77 ~4 ~90 ~78 ~4 ~90 wool 14  
fill ~77 ~4 ~91 ~78 ~4 ~91 wool 14  
fill ~77 ~4 ~92 ~78 ~4 ~92 wool 14  
fill ~77 ~4 ~93 ~78 ~4 ~93 wool 14  
fill ~77 ~4 ~94 ~78 ~4 ~94 wool 14  
fill ~77 ~4 ~95 ~78 ~4 ~95 wool 14  
fill ~77 ~4 ~96 ~78 ~4 ~96 wool 14  
fill ~77 ~4 ~97 ~78 ~4 ~97 wool 14  
fill ~77 ~4 ~98 ~78 ~4 ~98 wool 14  
fill ~77 ~4 ~99 ~78 ~4 ~99 wool 14  
fill ~77 ~4 ~100 ~78 ~4 ~100 wool 14  
fill ~77 ~4 ~101 ~78 ~4 ~101 wool 14  
fill ~77 ~4 ~102 ~78 ~4 ~102 wool 14  
fill ~77 ~4 ~103 ~78 ~4 ~103 wool 14  
fill ~77 ~4 ~104 ~78 ~4 ~104 wool 14  
fill ~77 ~4 ~105 ~78 ~4 ~105 wool 14  
fill ~77 ~4 ~106 ~78 ~4 ~106 wool 14  
fill ~77 ~4 ~107 ~78 ~4 ~107 wool 14  
fill ~77 ~4 ~108 ~78 ~4 ~108 wool 14  
fill ~77 ~4 ~109 ~78 ~4 ~109 wool 14  
fill ~77 ~4 ~110 ~78 ~4 ~110 wool 14  
fill ~77 ~4 ~111 ~78 ~4 ~111 wool 14  
fill ~77 ~4 ~112 ~78 ~4 ~112 wool 14  
fill ~77 ~4 ~113 ~78 ~4 ~113 wool 14  
fill ~77 ~4 ~114 ~78 ~4 ~114 wool 14  
fill ~77 ~4 ~115 ~78 ~4 ~115 wool 14  
fill ~77 ~4 ~116 ~78 ~4 ~116 wool 14  
fill ~77 ~4 ~117 ~78 ~4 ~117 wool 14  
fill ~77 ~4 ~118 ~78 ~4 ~118 wool 14  
fill ~77 ~4 ~119 ~78 ~4 ~119 wool 14  
fill ~77 ~4 ~120 ~78 ~4 ~120 wool 14  
fill ~77 ~4 ~121 ~78 ~4 ~121 wool 14  
fill ~77 ~4 ~122 ~78 ~4 ~122 wool 14  
fill ~77 ~4 ~123 ~79 ~4 ~123 wool 14  
fill ~77 ~4 ~124 ~78 ~4 ~124 wool 14  
fill ~77 ~4 ~125 ~78 ~4 ~125 wool 14 
setblock ~78 ~4 ~67 wool 14 
setblock ~78 ~4 ~88 wool 14 
setblock ~84 ~4 ~17 torch 3  
fill ~93 ~4 ~64 ~94 ~4 ~64 wool 0  
fill ~93 ~4 ~65 ~94 ~4 ~65 wool 0  
fill ~94 ~4 ~48 ~95 ~4 ~48 wool 0  
fill ~94 ~4 ~49 ~95 ~4 ~49 wool 0  
fill ~94 ~4 ~68 ~95 ~4 ~68 wool 0  
fill ~94 ~4 ~69 ~95 ~4 ~69 wool 0  
fill ~94 ~4 ~85 ~95 ~4 ~85 wool 0  
fill ~94 ~4 ~86 ~95 ~4 ~86 wool 0  
fill ~94 ~4 ~89 ~95 ~4 ~89 wool 0  
fill ~94 ~4 ~90 ~95 ~4 ~90 wool 0  
fill ~95 ~4 ~44 ~96 ~4 ~44 wool 0  
fill ~95 ~4 ~45 ~96 ~4 ~45 wool 0  
fill ~96 ~4 ~107 ~97 ~4 ~107 wool 0  
fill ~96 ~4 ~108 ~97 ~4 ~108 wool 0 
setblock ~96 ~4 ~110 torch 2  
fill ~96 ~4 ~111 ~97 ~4 ~111 wool 0  
fill ~96 ~4 ~112 ~97 ~4 ~112 wool 0  
fill ~97 ~4 ~109 ~97 ~5 ~109 wool 0  
fill ~97 ~4 ~110 ~97 ~5 ~110 wool 0 
setblock ~102 ~4 ~108 torch 2 
setblock ~102 ~4 ~124 torch 2  
fill ~2 ~5 ~35 ~7 ~5 ~35 wool 0  
fill ~2 ~5 ~36 ~6 ~5 ~36 wool 0  
fill ~2 ~5 ~37 ~6 ~5 ~37 wool 0  
fill ~2 ~5 ~38 ~6 ~5 ~38 wool 0  
fill ~2 ~5 ~39 ~6 ~5 ~39 wool 0  
fill ~2 ~5 ~40 ~6 ~5 ~40 wool 0  
fill ~2 ~5 ~41 ~6 ~5 ~41 wool 0  
fill ~2 ~5 ~42 ~6 ~5 ~42 wool 0  
fill ~2 ~5 ~43 ~6 ~5 ~43 wool 0  
fill ~2 ~5 ~44 ~6 ~5 ~44 wool 0  
fill ~2 ~5 ~45 ~7 ~5 ~45 wool 0  
fill ~2 ~5 ~46 ~7 ~5 ~46 wool 0  
fill ~2 ~5 ~47 ~8 ~5 ~47 wool 0  
fill ~2 ~5 ~48 ~8 ~5 ~48 wool 0  
fill ~2 ~5 ~49 ~7 ~5 ~49 wool 0  
fill ~2 ~5 ~50 ~7 ~5 ~50 wool 0  
fill ~2 ~5 ~51 ~6 ~5 ~51 wool 0  
fill ~2 ~5 ~52 ~6 ~5 ~52 wool 0  
fill ~2 ~5 ~53 ~6 ~5 ~53 wool 0  
fill ~2 ~5 ~54 ~6 ~5 ~54 wool 0  
fill ~2 ~5 ~55 ~6 ~5 ~55 wool 0  
fill ~2 ~5 ~56 ~6 ~5 ~56 wool 0  
fill ~2 ~5 ~57 ~6 ~5 ~57 wool 0  
fill ~2 ~5 ~58 ~6 ~5 ~58 wool 0  
fill ~2 ~5 ~59 ~6 ~5 ~59 wool 0  
fill ~2 ~5 ~60 ~6 ~5 ~60 wool 0  
fill ~2 ~5 ~61 ~6 ~5 ~61 wool 0  
fill ~2 ~5 ~62 ~6 ~5 ~62 wool 0  
fill ~2 ~5 ~63 ~6 ~5 ~63 wool 0  
fill ~2 ~5 ~64 ~6 ~5 ~64 wool 0  
fill ~2 ~5 ~65 ~7 ~5 ~65 wool 0  
fill ~2 ~5 ~66 ~7 ~5 ~66 wool 0  
fill ~2 ~5 ~67 ~8 ~5 ~67 wool 0  
fill ~2 ~5 ~68 ~8 ~5 ~68 wool 0  
fill ~2 ~5 ~69 ~7 ~5 ~69 wool 0  
fill ~2 ~5 ~70 ~7 ~5 ~70 wool 0  
fill ~2 ~5 ~71 ~6 ~5 ~71 wool 0  
fill ~2 ~5 ~72 ~6 ~5 ~72 wool 0  
fill ~2 ~5 ~73 ~6 ~5 ~73 wool 0   
fill ~2 ~5 ~74 ~6 ~5 ~74 wool 0  
fill ~2 ~5 ~75 ~6 ~5 ~75 wool 0  
fill ~2 ~5 ~76 ~6 ~5 ~76 wool 0  
fill ~2 ~5 ~77 ~6 ~5 ~77 wool 0  
fill ~2 ~5 ~78 ~6 ~5 ~78 wool 0  
fill ~2 ~5 ~79 ~6 ~5 ~79 wool 0  
fill ~2 ~5 ~80 ~6 ~5 ~80 wool 0  
fill ~2 ~5 ~81 ~6 ~5 ~81 wool 0  
fill ~2 ~5 ~82 ~6 ~5 ~82 wool 0  
fill ~2 ~5 ~83 ~6 ~5 ~83 wool 0  
fill ~2 ~5 ~84 ~6 ~5 ~84 wool 0  
fill ~2 ~5 ~85 ~6 ~5 ~85 wool 0  
fill ~2 ~5 ~86 ~7 ~5 ~86 wool 0  
fill ~2 ~5 ~87 ~7 ~5 ~87 wool 0  
fill ~2 ~5 ~88 ~8 ~5 ~88 wool 0  
fill ~2 ~5 ~89 ~8 ~5 ~89 wool 0  
fill ~2 ~5 ~90 ~7 ~5 ~90 wool 0  
fill ~2 ~5 ~91 ~7 ~5 ~91 wool 0  
fill ~2 ~5 ~92 ~6 ~5 ~92 wool 0  
fill ~2 ~5 ~93 ~6 ~5 ~93 wool 0  
fill ~2 ~5 ~94 ~6 ~5 ~94 wool 0  
fill ~2 ~5 ~95 ~6 ~5 ~95 wool 0  
fill ~2 ~5 ~96 ~6 ~5 ~96 wool 0  
fill ~2 ~5 ~97 ~6 ~5 ~97 wool 0  
fill ~2 ~5 ~98 ~6 ~5 ~98 wool 0  
fill ~2 ~5 ~99 ~6 ~5 ~99 wool 0  
fill ~2 ~5 ~100 ~6 ~5 ~100 wool 0  
fill ~2 ~5 ~101 ~6 ~5 ~101 wool 0  
fill ~2 ~5 ~102 ~6 ~5 ~102 wool 0  
fill ~2 ~5 ~103 ~6 ~5 ~103 wool 0  
fill ~2 ~5 ~104 ~6 ~5 ~104 wool 0  
fill ~2 ~5 ~105 ~6 ~5 ~105 wool 0  
fill ~2 ~5 ~106 ~6 ~5 ~106 wool 0  
fill ~2 ~5 ~107 ~6 ~5 ~107 wool 0  
fill ~2 ~5 ~108 ~7 ~5 ~108 wool 0  
fill ~2 ~5 ~109 ~7 ~5 ~109 wool 0  
fill ~2 ~5 ~110 ~8 ~5 ~110 wool 0  
fill ~2 ~5 ~111 ~8 ~5 ~111 wool 0  
fill ~2 ~5 ~112 ~7 ~5 ~112 wool 0  
fill ~2 ~5 ~113 ~7 ~5 ~113 wool 0  
fill ~2 ~5 ~114 ~6 ~5 ~114 wool 0  
fill ~2 ~5 ~115 ~6 ~5 ~115 wool 0  
fill ~2 ~5 ~116 ~6 ~5 ~116 wool 0  
fill ~2 ~5 ~117 ~6 ~5 ~117 wool 0  
fill ~2 ~5 ~118 ~6 ~5 ~118 wool 0  
fill ~2 ~5 ~119 ~6 ~5 ~119 wool 0  
fill ~2 ~5 ~120 ~6 ~5 ~120 wool 0  
fill ~2 ~5 ~121 ~6 ~5 ~121 wool 0  
fill ~2 ~5 ~122 ~6 ~5 ~122 wool 0  
fill ~2 ~5 ~123 ~6 ~5 ~123 wool 0  
fill ~2 ~5 ~124 ~6 ~5 ~124 wool 0  
fill ~2 ~5 ~125 ~6 ~5 ~125 wool 0  
fill ~2 ~5 ~126 ~6 ~5 ~126 wool 0  
fill ~2 ~5 ~127 ~6 ~5 ~127 wool 0  
fill ~2 ~5 ~128 ~7 ~5 ~128 wool 0  
fill ~3 ~5 ~34 ~8 ~5 ~34 wool 0  
fill ~3 ~5 ~129 ~8 ~5 ~129 wool 0  
fill ~4 ~5 ~33 ~9 ~5 ~33 wool 0  
fill ~4 ~5 ~130 ~9 ~5 ~130 wool 0  
fill ~5 ~5 ~32 ~10 ~5 ~32 wool 0  
fill ~5 ~5 ~131 ~10 ~5 ~131 wool 0  
fill ~6 ~5 ~31 ~11 ~5 ~31 wool 0  
fill ~6 ~5 ~132 ~11 ~5 ~132 wool 0  
fill ~7 ~5 ~30 ~12 ~5 ~30 wool 0 
setblock ~7 ~5 ~43 torch 1 
setblock ~7 ~5 ~57 torch 1 
setblock ~7 ~5 ~98 torch 1  
fill ~7 ~5 ~133 ~12 ~5 ~133 wool 0  
fill ~8 ~5 ~29 ~13 ~5 ~29 wool 0  
fill ~8 ~5 ~134 ~13 ~5 ~134 wool 0  
fill ~9 ~5 ~28 ~14 ~5 ~28 wool 0  
fill ~9 ~5 ~135 ~14 ~5 ~135 wool 0  
fill ~10 ~5 ~27 ~15 ~5 ~27 wool 0 
setblock ~10 ~5 ~130 torch 4  
fill ~10 ~5 ~136 ~15 ~5 ~136 wool 0  
fill ~11 ~5 ~26 ~16 ~5 ~26 wool 0  
fill ~11 ~5 ~137 ~16 ~5 ~137 wool 0  
fill ~12 ~5 ~25 ~17 ~5 ~25 wool 0  
fill ~12 ~5 ~138 ~17 ~5 ~138 wool 0  
fill ~13 ~5 ~24 ~18 ~5 ~24 wool 0  
fill ~13 ~5 ~139 ~18 ~5 ~139 wool 0  
fill ~14 ~5 ~23 ~19 ~5 ~23 wool 0  
fill ~14 ~5 ~140 ~19 ~5 ~140 wool 0  
fill ~15 ~5 ~22 ~20 ~5 ~22 wool 0  
fill ~15 ~5 ~141 ~20 ~5 ~141 wool 0  
fill ~16 ~5 ~21 ~21 ~5 ~21 wool 0  
fill ~16 ~5 ~142 ~21 ~5 ~142 wool 0  
fill ~17 ~5 ~20 ~22 ~5 ~20 wool 0 
setblock ~17 ~5 ~26 torch 1  
fill ~17 ~5 ~143 ~22 ~5 ~143 wool 0  
fill ~18 ~5 ~19 ~23 ~5 ~19 wool 0  
fill ~18 ~5 ~144 ~23 ~5 ~144 wool 0  
fill ~19 ~5 ~18 ~24 ~5 ~18 wool 0 
setblock ~19 ~5 ~139 torch 4  
fill ~19 ~5 ~145 ~24 ~5 ~145 wool 0  
fill ~20 ~5 ~17 ~25 ~5 ~17 wool 0  
fill ~20 ~5 ~146 ~25 ~5 ~146 wool 0  
fill ~21 ~5 ~16 ~26 ~5 ~16 wool 0  
fill ~21 ~5 ~147 ~26 ~5 ~147 wool 0  
fill ~22 ~5 ~15 ~27 ~5 ~15 wool 0  
fill ~22 ~5 ~148 ~27 ~5 ~148 wool 0  
fill ~23 ~5 ~14 ~28 ~5 ~14 wool 0  
fill ~23 ~5 ~40 ~25 ~5 ~40 wool 14  
fill ~23 ~5 ~123 ~25 ~5 ~123 wool 14  
fill ~23 ~5 ~149 ~28 ~5 ~149 wool 0  
fill ~24 ~5 ~13 ~29 ~5 ~13 wool 0  
fill ~24 ~5 ~38 ~25 ~5 ~38 wool 14  
fill ~24 ~5 ~39 ~25 ~5 ~39 wool 14  
fill ~24 ~5 ~41 ~25 ~5 ~41 wool 14  
fill ~24 ~5 ~42 ~25 ~5 ~42 wool 14  
fill ~24 ~5 ~43 ~25 ~5 ~43 wool 14  
fill ~24 ~5 ~44 ~25 ~5 ~44 wool 14  
fill ~24 ~5 ~45 ~25 ~5 ~45 wool 14  
fill ~24 ~5 ~46 ~25 ~5 ~46 wool 14  
fill ~24 ~5 ~47 ~30 ~5 ~47 wool 0  
fill ~24 ~5 ~48 ~25 ~5 ~48 wool 14  
fill ~24 ~5 ~49 ~25 ~5 ~49 wool 14  
fill ~24 ~5 ~50 ~25 ~5 ~50 wool 14  
fill ~24 ~5 ~51 ~25 ~5 ~51 wool 14  
fill ~24 ~5 ~52 ~25 ~5 ~52 wool 14  
fill ~24 ~5 ~53 ~25 ~5 ~53 wool 14  
fill ~24 ~5 ~54 ~25 ~5 ~54 wool 14  
fill ~24 ~5 ~55 ~25 ~5 ~55 wool 14  
fill ~24 ~5 ~56 ~25 ~5 ~56 wool 14  
fill ~24 ~5 ~57 ~25 ~5 ~57 wool 14  
fill ~24 ~5 ~58 ~25 ~5 ~58 wool 14  
fill ~24 ~5 ~59 ~25 ~5 ~59 wool 14  
fill ~24 ~5 ~60 ~25 ~5 ~60 wool 14  
fill ~24 ~5 ~61 ~25 ~5 ~61 wool 14  
fill ~24 ~5 ~62 ~25 ~5 ~62 wool 14  
fill ~24 ~5 ~63 ~25 ~5 ~63 wool 14  
fill ~24 ~5 ~64 ~25 ~5 ~64 wool 14  
fill ~24 ~5 ~65 ~25 ~5 ~65 wool 14  
fill ~24 ~5 ~66 ~25 ~5 ~66 wool 14  
fill ~24 ~5 ~67 ~30 ~5 ~67 wool 0  
fill ~24 ~5 ~68 ~25 ~5 ~68 wool 14  
fill ~24 ~5 ~69 ~25 ~5 ~69 wool 14  
fill ~24 ~5 ~70 ~25 ~5 ~70 wool 14  
fill ~24 ~5 ~71 ~25 ~5 ~71 wool 14  
fill ~24 ~5 ~72 ~25 ~5 ~72 wool 14  
fill ~24 ~5 ~73 ~25 ~5 ~73 wool 14  
fill ~24 ~5 ~74 ~25 ~5 ~74 wool 14  
fill ~24 ~5 ~75 ~25 ~5 ~75 wool 14  
fill ~24 ~5 ~76 ~25 ~5 ~76 wool 14  
fill ~24 ~5 ~77 ~25 ~5 ~77 wool 14  
fill ~24 ~5 ~78 ~25 ~5 ~78 wool 14  
fill ~24 ~5 ~79 ~25 ~5 ~79 wool 14  
fill ~24 ~5 ~80 ~25 ~5 ~80 wool 14  
fill ~24 ~5 ~81 ~25 ~5 ~81 wool 14  
fill ~24 ~5 ~82 ~25 ~5 ~82 wool 14  
fill ~24 ~5 ~83 ~25 ~5 ~83 wool 14  
fill ~24 ~5 ~84 ~25 ~5 ~84 wool 14  
fill ~24 ~5 ~85 ~25 ~5 ~85 wool 14  
fill ~24 ~5 ~86 ~25 ~5 ~86 wool 14  
fill ~24 ~5 ~87 ~25 ~5 ~87 wool 14  
fill ~24 ~5 ~88 ~30 ~5 ~88 wool 0  
fill ~24 ~5 ~89 ~25 ~5 ~89 wool 14  
fill ~24 ~5 ~90 ~25 ~5 ~90 wool 14  
fill ~24 ~5 ~91 ~25 ~5 ~91 wool 14  
fill ~24 ~5 ~92 ~25 ~5 ~92 wool 14  
fill ~24 ~5 ~93 ~25 ~5 ~93 wool 14  
fill ~24 ~5 ~94 ~25 ~5 ~94 wool 14  
fill ~24 ~5 ~95 ~25 ~5 ~95 wool 14  
fill ~24 ~5 ~96 ~25 ~5 ~96 wool 14  
fill ~24 ~5 ~97 ~25 ~5 ~97 wool 14  
fill ~24 ~5 ~98 ~25 ~5 ~98 wool 14  
fill ~24 ~5 ~99 ~25 ~5 ~99 wool 14  
fill ~24 ~5 ~100 ~25 ~5 ~100 wool 14  
fill ~24 ~5 ~101 ~25 ~5 ~101 wool 14  
fill ~24 ~5 ~102 ~25 ~5 ~102 wool 14  
fill ~24 ~5 ~103 ~25 ~5 ~103 wool 14  
fill ~24 ~5 ~104 ~25 ~5 ~104 wool 14  
fill ~24 ~5 ~105 ~25 ~5 ~105 wool 14  
fill ~24 ~5 ~106 ~25 ~5 ~106 wool 14  
fill ~24 ~5 ~107 ~25 ~5 ~107 wool 14  
fill ~24 ~5 ~108 ~25 ~5 ~108 wool 14  
fill ~24 ~5 ~109 ~25 ~5 ~109 wool 14  
fill ~24 ~5 ~110 ~30 ~5 ~110 wool 0  
fill ~24 ~5 ~111 ~25 ~5 ~111 wool 14  
fill ~24 ~5 ~112 ~25 ~5 ~112 wool 14  
fill ~24 ~5 ~113 ~25 ~5 ~113 wool 14  
fill ~24 ~5 ~114 ~25 ~5 ~114 wool 14  
fill ~24 ~5 ~115 ~25 ~5 ~115 wool 14  
fill ~24 ~5 ~116 ~25 ~5 ~116 wool 14  
fill ~24 ~5 ~117 ~25 ~5 ~117 wool 14  
fill ~24 ~5 ~118 ~25 ~5 ~118 wool 14  
fill ~24 ~5 ~119 ~25 ~5 ~119 wool 14  
fill ~24 ~5 ~120 ~25 ~5 ~120 wool 14  
fill ~24 ~5 ~121 ~25 ~5 ~121 wool 14  
fill ~24 ~5 ~122 ~25 ~5 ~122 wool 14  
fill ~24 ~5 ~124 ~25 ~5 ~124 wool 14  
fill ~24 ~5 ~125 ~25 ~5 ~125 wool 14 
setblock ~24 ~5 ~144 torch 4  
fill ~24 ~5 ~150 ~29 ~5 ~150 wool 0  
fill ~25 ~5 ~12 ~30 ~5 ~12 wool 0 
setblock ~25 ~5 ~18 torch 1  
fill ~25 ~5 ~37 ~26 ~5 ~37 wool 14  
fill ~25 ~5 ~126 ~26 ~5 ~126 wool 14  
fill ~25 ~5 ~151 ~30 ~5 ~151 wool 0  
fill ~26 ~5 ~11 ~31 ~5 ~11 wool 0  
fill ~26 ~5 ~36 ~27 ~5 ~36 wool 14 
setblock ~26 ~5 ~45 torch 5  
fill ~26 ~5 ~46 ~30 ~5 ~46 wool 0  
fill ~26 ~5 ~48 ~30 ~5 ~48 wool 0 
setblock ~26 ~5 ~49 torch 5 
setblock ~26 ~5 ~65 torch 4  
fill ~26 ~5 ~66 ~30 ~5 ~66 wool 0  
fill ~26 ~5 ~68 ~30 ~5 ~68 wool 0 
setblock ~26 ~5 ~69 torch 3 
setblock ~26 ~5 ~86 torch 4  
fill ~26 ~5 ~87 ~30 ~5 ~87 wool 0  
fill ~26 ~5 ~89 ~30 ~5 ~89 wool 0 
setblock ~26 ~5 ~90 torch 3 
setblock ~26 ~5 ~108 torch 4  
fill ~26 ~5 ~109 ~30 ~5 ~109 wool 0  
fill ~26 ~5 ~111 ~30 ~5 ~111 wool 0 
setblock ~26 ~5 ~112 torch 3  
fill ~26 ~5 ~127 ~27 ~5 ~127 wool 14  
fill ~26 ~5 ~152 ~31 ~5 ~152 wool 0  
fill ~27 ~5 ~10 ~32 ~5 ~10 wool 0  
fill ~27 ~5 ~35 ~28 ~5 ~35 wool 14  
fill ~27 ~5 ~128 ~28 ~5 ~128 wool 14  
fill ~27 ~5 ~153 ~32 ~5 ~153 wool 0  
fill ~28 ~5 ~9 ~33 ~5 ~9 wool 0  
fill ~28 ~5 ~34 ~29 ~5 ~34 wool 14  
fill ~28 ~5 ~129 ~29 ~5 ~129 wool 14  
fill ~28 ~5 ~154 ~33 ~5 ~154 wool 0  
fill ~29 ~5 ~8 ~34 ~5 ~8 wool 0  
fill ~29 ~5 ~33 ~30 ~5 ~33 wool 14  
fill ~29 ~5 ~130 ~30 ~5 ~130 wool 14  
fill ~29 ~5 ~155 ~34 ~5 ~155 wool 0  
fill ~30 ~5 ~7 ~75 ~5 ~7 wool 0 
setblock ~30 ~5 ~13 torch 3  
fill ~30 ~5 ~32 ~31 ~5 ~32 wool 14  
fill ~30 ~5 ~131 ~31 ~5 ~131 wool 14 
setblock ~30 ~5 ~150 torch 4  
fill ~30 ~5 ~156 ~35 ~5 ~156 wool 0  
fill ~31 ~5 ~6 ~74 ~5 ~6 wool 0  
fill ~31 ~5 ~31 ~32 ~5 ~31 wool 14  
fill ~31 ~5 ~132 ~32 ~5 ~132 wool 14  
fill ~31 ~5 ~157 ~74 ~5 ~157 wool 0  
fill ~32 ~5 ~5 ~73 ~5 ~5 wool 0  
fill ~32 ~5 ~30 ~33 ~5 ~30 wool 14  
fill ~32 ~5 ~133 ~33 ~5 ~133 wool 14  
fill ~32 ~5 ~158 ~73 ~5 ~158 wool 0  
fill ~33 ~5 ~4 ~72 ~5 ~4 wool 0  
fill ~33 ~5 ~29 ~34 ~5 ~29 wool 14  
fill ~33 ~5 ~134 ~34 ~5 ~134 wool 14  
fill ~33 ~5 ~159 ~72 ~5 ~159 wool 0  
fill ~34 ~5 ~3 ~71 ~5 ~3 wool 0  
fill ~34 ~5 ~28 ~41 ~5 ~28 wool 14  
fill ~34 ~5 ~135 ~35 ~5 ~135 wool 14 
setblock ~34 ~5 ~154 torch 4  
fill ~34 ~5 ~160 ~71 ~5 ~160 wool 0  
fill ~35 ~5 ~1 ~69 ~5 ~1 wool 0  
fill ~35 ~5 ~2 ~70 ~5 ~2 wool 0  
fill ~35 ~5 ~26 ~38 ~5 ~26 wool 14  
fill ~35 ~5 ~27 ~41 ~5 ~27 wool 14  
fill ~35 ~5 ~136 ~41 ~5 ~136 wool 14  
fill ~35 ~5 ~161 ~70 ~5 ~161 wool 0  
fill ~35 ~5 ~162 ~69 ~5 ~162 wool 0  
fill ~36 ~5 ~137 ~41 ~5 ~137 wool 14  
fill ~38 ~5 ~138 ~38 ~6 ~138 wool 14  
fill ~39 ~5 ~8 ~44 ~5 ~8 wool 0 
setblock ~40 ~5 ~29 torch 3 
setblock ~40 ~5 ~135 torch 2  
fill ~40 ~5 ~156 ~45 ~5 ~156 wool 0  
fill ~41 ~5 ~9 ~42 ~5 ~9 wool 0  
fill ~41 ~5 ~29 ~43 ~5 ~29 wool 0  
fill ~41 ~5 ~30 ~43 ~5 ~30 wool 0  
fill ~41 ~5 ~134 ~43 ~5 ~134 wool 0  
fill ~41 ~5 ~135 ~43 ~5 ~135 wool 0  
fill ~42 ~5 ~27 ~42 ~5 ~33 wool 0  
fill ~42 ~5 ~131 ~42 ~5 ~137 wool 0  
fill ~42 ~5 ~155 ~43 ~5 ~155 wool 0  
fill ~43 ~5 ~27 ~61 ~5 ~27 wool 14  
fill ~43 ~5 ~28 ~61 ~5 ~28 wool 14  
fill ~43 ~5 ~136 ~61 ~5 ~136 wool 14  
fill ~43 ~5 ~137 ~61 ~5 ~137 wool 14 
setblock ~44 ~5 ~29 torch 3 
setblock ~44 ~5 ~135 torch 1  
fill ~49 ~5 ~44 ~49 ~9 ~44 wool 4  
fill ~49 ~5 ~119 ~49 ~9 ~119 wool 4 
setblock ~52 ~5 ~8 torch 3  
fill ~55 ~5 ~44 ~55 ~9 ~44 wool 4  
fill ~55 ~5 ~119 ~55 ~9 ~119 wool 4  
fill ~60 ~5 ~8 ~65 ~5 ~8 wool 0 
setblock ~60 ~5 ~29 torch 2 
setblock ~60 ~5 ~135 torch 2  
fill ~60 ~5 ~156 ~65 ~5 ~156 wool 0  
fill ~61 ~5 ~29 ~63 ~5 ~29 wool 0  
fill ~61 ~5 ~30 ~63 ~5 ~30 wool 0  
fill ~61 ~5 ~134 ~63 ~5 ~134 wool 0  
fill ~61 ~5 ~135 ~63 ~5 ~135 wool 0  
fill ~62 ~5 ~9 ~63 ~5 ~9 wool 0  
fill ~62 ~5 ~27 ~62 ~5 ~33 wool 0  
fill ~62 ~5 ~131 ~62 ~5 ~137 wool 0  
fill ~62 ~5 ~155 ~63 ~5 ~155 wool 0  
fill ~63 ~5 ~27 ~69 ~5 ~27 wool 14  
fill ~63 ~5 ~28 ~70 ~5 ~28 wool 14  
fill ~63 ~5 ~136 ~69 ~5 ~136 wool 14  
fill ~63 ~5 ~137 ~68 ~5 ~137 wool 14 
setblock ~64 ~5 ~29 torch 1 
setblock ~64 ~5 ~135 torch 1  
fill ~66 ~5 ~26 ~68 ~5 ~26 wool 14  
fill ~66 ~5 ~138 ~66 ~6 ~138 wool 14  
fill ~69 ~5 ~135 ~70 ~5 ~135 wool 14  
fill ~69 ~5 ~156 ~75 ~5 ~156 wool 0  
fill ~70 ~5 ~8 ~76 ~5 ~8 wool 0  
fill ~70 ~5 ~29 ~71 ~5 ~29 wool 14  
fill ~70 ~5 ~134 ~71 ~5 ~134 wool 14  
fill ~70 ~5 ~155 ~76 ~5 ~155 wool 0  
fill ~71 ~5 ~9 ~77 ~5 ~9 wool 0  
fill ~71 ~5 ~30 ~72 ~5 ~30 wool 14  
fill ~71 ~5 ~133 ~72 ~5 ~133 wool 14  
fill ~71 ~5 ~154 ~77 ~5 ~154 wool 0  
fill ~72 ~5 ~10 ~78 ~5 ~10 wool 0  
fill ~72 ~5 ~31 ~73 ~5 ~31 wool 14  
fill ~72 ~5 ~132 ~73 ~5 ~132 wool 14 
setblock ~72 ~5 ~152 torch 2  
fill ~72 ~5 ~153 ~78 ~5 ~153 wool 0  
fill ~73 ~5 ~11 ~79 ~5 ~11 wool 0  
fill ~73 ~5 ~32 ~74 ~5 ~32 wool 14  
fill ~73 ~5 ~131 ~74 ~5 ~131 wool 14  
fill ~73 ~5 ~152 ~79 ~5 ~152 wool 0  
fill ~74 ~5 ~12 ~80 ~5 ~12 wool 0  
fill ~74 ~5 ~33 ~75 ~5 ~33 wool 14  
fill ~74 ~5 ~47 ~80 ~5 ~47 wool 0  
fill ~74 ~5 ~67 ~80 ~5 ~67 wool 0  
fill ~74 ~5 ~88 ~81 ~5 ~88 wool 0  
fill ~74 ~5 ~110 ~80 ~5 ~110 wool 0  
fill ~74 ~5 ~130 ~75 ~5 ~130 wool 14  
fill ~74 ~5 ~151 ~80 ~5 ~151 wool 0  
fill ~75 ~5 ~13 ~81 ~5 ~13 wool 0  
fill ~75 ~5 ~34 ~76 ~5 ~34 wool 14  
fill ~75 ~5 ~46 ~78 ~5 ~46 wool 0  
fill ~75 ~5 ~48 ~78 ~5 ~48 wool 0  
fill ~75 ~5 ~66 ~78 ~5 ~66 wool 0  
fill ~75 ~5 ~68 ~78 ~5 ~68 wool 0  
fill ~75 ~5 ~87 ~78 ~5 ~87 wool 0  
fill ~75 ~5 ~89 ~78 ~5 ~89 wool 0  
fill ~75 ~5 ~109 ~78 ~5 ~109 wool 0  
fill ~75 ~5 ~111 ~78 ~5 ~111 wool 0  
fill ~75 ~5 ~129 ~76 ~5 ~129 wool 14  
fill ~75 ~5 ~150 ~81 ~5 ~150 wool 0  
fill ~76 ~5 ~14 ~82 ~5 ~14 wool 0  
fill ~76 ~5 ~35 ~77 ~5 ~35 wool 14  
fill ~76 ~5 ~128 ~77 ~5 ~128 wool 14  
fill ~76 ~5 ~149 ~82 ~5 ~149 wool 0  
fill ~77 ~5 ~15 ~83 ~5 ~15 wool 0  
fill ~77 ~5 ~36 ~78 ~5 ~36 wool 14  
fill ~77 ~5 ~127 ~78 ~5 ~127 wool 14  
fill ~77 ~5 ~148 ~83 ~5 ~148 wool 0  
fill ~78 ~5 ~16 ~84 ~5 ~16 wool 0  
fill ~78 ~5 ~37 ~79 ~5 ~37 wool 14 
setblock ~78 ~5 ~45 torch 2 
setblock ~78 ~5 ~49 torch 3 
setblock ~78 ~5 ~65 torch 4 
setblock ~78 ~5 ~69 torch 3 
setblock ~78 ~5 ~86 torch 4 
setblock ~78 ~5 ~90 torch 3 
setblock ~78 ~5 ~108 torch 4 
setblock ~78 ~5 ~112 torch 3  
fill ~78 ~5 ~126 ~79 ~5 ~126 wool 14  
fill ~78 ~5 ~147 ~84 ~5 ~147 wool 0  
fill ~79 ~5 ~17 ~85 ~5 ~17 wool 0  
fill ~79 ~5 ~38 ~81 ~5 ~38 wool 14  
fill ~79 ~5 ~39 ~81 ~5 ~39 wool 14  
fill ~79 ~5 ~40 ~81 ~5 ~40 wool 14  
fill ~79 ~5 ~41 ~80 ~5 ~41 wool 14  
fill ~79 ~5 ~42 ~80 ~5 ~42 wool 14  
fill ~79 ~5 ~43 ~80 ~5 ~43 wool 14  
fill ~79 ~5 ~44 ~80 ~5 ~44 wool 14  
fill ~79 ~5 ~45 ~80 ~5 ~45 wool 14  
fill ~79 ~5 ~46 ~80 ~5 ~46 wool 14  
fill ~79 ~5 ~48 ~80 ~5 ~48 wool 14  
fill ~79 ~5 ~49 ~80 ~5 ~49 wool 14  
fill ~79 ~5 ~50 ~80 ~5 ~50 wool 14  
fill ~79 ~5 ~51 ~80 ~5 ~51 wool 14  
fill ~79 ~5 ~52 ~80 ~5 ~52 wool 14  
fill ~79 ~5 ~53 ~80 ~5 ~53 wool 14  
fill ~79 ~5 ~54 ~80 ~5 ~54 wool 14  
fill ~79 ~5 ~55 ~80 ~5 ~55 wool 14  
fill ~79 ~5 ~56 ~80 ~5 ~56 wool 14  
fill ~79 ~5 ~57 ~80 ~5 ~57 wool 14  
fill ~79 ~5 ~58 ~80 ~5 ~58 wool 14  
fill ~79 ~5 ~59 ~80 ~5 ~59 wool 14  
fill ~79 ~5 ~60 ~80 ~5 ~60 wool 14  
fill ~79 ~5 ~61 ~80 ~5 ~61 wool 14  
fill ~79 ~5 ~62 ~80 ~5 ~62 wool 14  
fill ~79 ~5 ~63 ~80 ~5 ~63 wool 14  
fill ~79 ~5 ~64 ~80 ~5 ~64 wool 14  
fill ~79 ~5 ~65 ~80 ~5 ~65 wool 14  
fill ~79 ~5 ~66 ~80 ~5 ~66 wool 14  
fill ~79 ~5 ~68 ~80 ~5 ~68 wool 14  
fill ~79 ~5 ~69 ~80 ~5 ~69 wool 14  
fill ~79 ~5 ~70 ~80 ~5 ~70 wool 14  
fill ~79 ~5 ~71 ~80 ~5 ~71 wool 14  
fill ~79 ~5 ~72 ~80 ~5 ~72 wool 14  
fill ~79 ~5 ~73 ~80 ~5 ~73 wool 14  
fill ~79 ~5 ~74 ~80 ~5 ~74 wool 14  
fill ~79 ~5 ~75 ~80 ~5 ~75 wool 14  
fill ~79 ~5 ~76 ~80 ~5 ~76 wool 14  
fill ~79 ~5 ~77 ~80 ~5 ~77 wool 14  
fill ~79 ~5 ~78 ~80 ~5 ~78 wool 14  
fill ~79 ~5 ~79 ~80 ~5 ~79 wool 14  
fill ~79 ~5 ~80 ~80 ~5 ~80 wool 14  
fill ~79 ~5 ~81 ~80 ~5 ~81 wool 14  
fill ~79 ~5 ~82 ~80 ~5 ~82 wool 14  
fill ~79 ~5 ~83 ~80 ~5 ~83 wool 14  
fill ~79 ~5 ~84 ~80 ~5 ~84 wool 14  
fill ~79 ~5 ~85 ~80 ~5 ~85 wool 14  
fill ~79 ~5 ~86 ~80 ~5 ~86 wool 14  
fill ~79 ~5 ~87 ~80 ~5 ~87 wool 14  
fill ~79 ~5 ~89 ~80 ~5 ~89 wool 14  
fill ~79 ~5 ~90 ~80 ~5 ~90 wool 14  
fill ~79 ~5 ~91 ~80 ~5 ~91 wool 14  
fill ~79 ~5 ~92 ~80 ~5 ~92 wool 14  
fill ~79 ~5 ~93 ~80 ~5 ~93 wool 14  
fill ~79 ~5 ~94 ~80 ~5 ~94 wool 14  
fill ~79 ~5 ~95 ~80 ~5 ~95 wool 14  
fill ~79 ~5 ~96 ~80 ~5 ~96 wool 14  
fill ~79 ~5 ~97 ~80 ~5 ~97 wool 14  
fill ~79 ~5 ~98 ~80 ~5 ~98 wool 14  
fill ~79 ~5 ~99 ~80 ~5 ~99 wool 14  
fill ~79 ~5 ~100 ~80 ~5 ~100 wool 14  
fill ~79 ~5 ~101 ~80 ~5 ~101 wool 14  
fill ~79 ~5 ~102 ~80 ~5 ~102 wool 14  
fill ~79 ~5 ~103 ~80 ~5 ~103 wool 14  
fill ~79 ~5 ~104 ~80 ~5 ~104 wool 14  
fill ~79 ~5 ~105 ~80 ~5 ~105 wool 14  
fill ~79 ~5 ~106 ~80 ~5 ~106 wool 14  
fill ~79 ~5 ~107 ~80 ~5 ~107 wool 14  
fill ~79 ~5 ~108 ~80 ~5 ~108 wool 14  
fill ~79 ~5 ~109 ~80 ~5 ~109 wool 14  
fill ~79 ~5 ~111 ~80 ~5 ~111 wool 14  
fill ~79 ~5 ~112 ~80 ~5 ~112 wool 14  
fill ~79 ~5 ~113 ~80 ~5 ~113 wool 14  
fill ~79 ~5 ~114 ~80 ~5 ~114 wool 14  
fill ~79 ~5 ~115 ~80 ~5 ~115 wool 14  
fill ~79 ~5 ~116 ~80 ~5 ~116 wool 14  
fill ~79 ~5 ~117 ~80 ~5 ~117 wool 14  
fill ~79 ~5 ~118 ~80 ~5 ~118 wool 14  
fill ~79 ~5 ~119 ~80 ~5 ~119 wool 14  
fill ~79 ~5 ~120 ~80 ~5 ~120 wool 14  
fill ~79 ~5 ~121 ~80 ~5 ~121 wool 14  
fill ~79 ~5 ~122 ~80 ~5 ~122 wool 14  
fill ~79 ~5 ~123 ~81 ~5 ~123 wool 14  
fill ~79 ~5 ~124 ~80 ~5 ~124 wool 14  
fill ~79 ~5 ~125 ~80 ~5 ~125 wool 14 
setblock ~79 ~5 ~145 torch 2  
fill ~79 ~5 ~146 ~85 ~5 ~146 wool 0  
fill ~80 ~5 ~18 ~86 ~5 ~18 wool 0  
fill ~80 ~5 ~145 ~86 ~5 ~145 wool 0  
fill ~81 ~5 ~19 ~87 ~5 ~19 wool 0  
fill ~81 ~5 ~144 ~87 ~5 ~144 wool 0  
fill ~82 ~5 ~20 ~88 ~5 ~20 wool 0  
fill ~82 ~5 ~143 ~88 ~5 ~143 wool 0  
fill ~83 ~5 ~21 ~89 ~5 ~21 wool 0  
fill ~83 ~5 ~142 ~89 ~5 ~142 wool 0  
fill ~84 ~5 ~22 ~90 ~5 ~22 wool 0  
fill ~84 ~5 ~141 ~90 ~5 ~141 wool 0  
fill ~85 ~5 ~23 ~91 ~5 ~23 wool 0 
setblock ~85 ~5 ~139 torch 2  
fill ~85 ~5 ~140 ~91 ~5 ~140 wool 0  
fill ~86 ~5 ~24 ~92 ~5 ~24 wool 0  
fill ~86 ~5 ~139 ~92 ~5 ~139 wool 0  
fill ~87 ~5 ~25 ~93 ~5 ~25 wool 0  
fill ~87 ~5 ~138 ~93 ~5 ~138 wool 0  
fill ~88 ~5 ~26 ~94 ~5 ~26 wool 0  
fill ~88 ~5 ~137 ~94 ~5 ~137 wool 0  
fill ~89 ~5 ~27 ~95 ~5 ~27 wool 0  
fill ~89 ~5 ~136 ~95 ~5 ~136 wool 0  
fill ~90 ~5 ~28 ~96 ~5 ~28 wool 0  
fill ~90 ~5 ~135 ~96 ~5 ~135 wool 0  
fill ~91 ~5 ~29 ~97 ~5 ~29 wool 0  
fill ~91 ~5 ~134 ~97 ~5 ~134 wool 0  
fill ~92 ~5 ~30 ~98 ~5 ~30 wool 0  
fill ~92 ~5 ~133 ~98 ~5 ~133 wool 0  
fill ~93 ~5 ~31 ~99 ~5 ~31 wool 0  
fill ~93 ~5 ~132 ~99 ~5 ~132 wool 0  
fill ~94 ~5 ~32 ~100 ~5 ~32 wool 0  
fill ~94 ~5 ~64 ~95 ~5 ~64 wool 0  
fill ~94 ~5 ~65 ~95 ~5 ~65 wool 0  
fill ~94 ~5 ~131 ~100 ~5 ~131 wool 0  
fill ~95 ~5 ~33 ~101 ~5 ~33 wool 0 
setblock ~95 ~5 ~47 torch 2  
fill ~95 ~5 ~48 ~96 ~5 ~48 wool 0  
fill ~95 ~5 ~49 ~96 ~5 ~49 wool 0 
setblock ~95 ~5 ~67 torch 2  
fill ~95 ~5 ~68 ~103 ~5 ~68 wool 0  
fill ~95 ~5 ~69 ~96 ~5 ~69 wool 0  
fill ~95 ~5 ~85 ~96 ~5 ~85 wool 0  
fill ~95 ~5 ~86 ~96 ~5 ~86 wool 0 
setblock ~95 ~5 ~88 torch 2  
fill ~95 ~5 ~89 ~103 ~5 ~89 wool 0  
fill ~95 ~5 ~90 ~96 ~5 ~90 wool 0  
fill ~95 ~5 ~130 ~101 ~5 ~130 wool 0  
fill ~96 ~5 ~34 ~102 ~5 ~34 wool 0  
fill ~96 ~5 ~44 ~103 ~5 ~44 wool 0  
fill ~96 ~5 ~45 ~103 ~5 ~45 wool 0  
fill ~96 ~5 ~46 ~103 ~5 ~46 wool 0  
fill ~96 ~5 ~47 ~96 ~6 ~47 wool 0  
fill ~96 ~5 ~67 ~103 ~5 ~67 wool 0  
fill ~96 ~5 ~87 ~103 ~5 ~87 wool 0  
fill ~96 ~5 ~88 ~103 ~5 ~88 wool 0  
fill ~96 ~5 ~109 ~96 ~6 ~109 wool 0  
fill ~96 ~5 ~110 ~96 ~6 ~110 wool 0  
fill ~96 ~5 ~129 ~102 ~5 ~129 wool 0  
fill ~97 ~5 ~35 ~103 ~5 ~35 wool 0  
fill ~97 ~5 ~66 ~103 ~5 ~66 wool 0 
setblock ~97 ~5 ~78 torch 2 
setblock ~97 ~5 ~98 torch 2  
fill ~97 ~5 ~107 ~103 ~5 ~107 wool 0  
fill ~97 ~5 ~108 ~103 ~5 ~108 wool 0  
fill ~97 ~5 ~111 ~103 ~5 ~111 wool 0  
fill ~97 ~5 ~112 ~103 ~5 ~112 wool 0 
setblock ~97 ~5 ~121 torch 2  
fill ~97 ~5 ~128 ~103 ~5 ~128 wool 0  
fill ~98 ~5 ~36 ~103 ~5 ~36 wool 0  
fill ~98 ~5 ~37 ~103 ~5 ~37 wool 0  
fill ~98 ~5 ~38 ~103 ~5 ~38 wool 0  
fill ~98 ~5 ~39 ~103 ~5 ~39 wool 0  
fill ~98 ~5 ~40 ~103 ~5 ~40 wool 0  
fill ~98 ~5 ~41 ~103 ~5 ~41 wool 0  
fill ~98 ~5 ~42 ~103 ~5 ~42 wool 0  
fill ~98 ~5 ~43 ~103 ~5 ~43 wool 0  
fill ~98 ~5 ~47 ~103 ~5 ~47 wool 0  
fill ~98 ~5 ~48 ~103 ~5 ~48 wool 0  
fill ~98 ~5 ~49 ~103 ~5 ~49 wool 0  
fill ~98 ~5 ~50 ~103 ~5 ~50 wool 0  
fill ~98 ~5 ~51 ~103 ~5 ~51 wool 0  
fill ~98 ~5 ~52 ~103 ~5 ~52 wool 0  
fill ~98 ~5 ~53 ~103 ~5 ~53 wool 0  
fill ~98 ~5 ~54 ~103 ~5 ~54 wool 0  
fill ~98 ~5 ~55 ~103 ~5 ~55 wool 0  
fill ~98 ~5 ~56 ~103 ~5 ~56 wool 0  
fill ~98 ~5 ~57 ~103 ~5 ~57 wool 0  
fill ~98 ~5 ~58 ~103 ~5 ~58 wool 0  
fill ~98 ~5 ~59 ~103 ~5 ~59 wool 0  
fill ~98 ~5 ~60 ~103 ~5 ~60 wool 0  
fill ~98 ~5 ~61 ~103 ~5 ~61 wool 0  
fill ~98 ~5 ~62 ~103 ~5 ~62 wool 0  
fill ~98 ~5 ~63 ~103 ~5 ~63 wool 0  
fill ~98 ~5 ~64 ~103 ~5 ~64 wool 0  
fill ~98 ~5 ~65 ~103 ~5 ~65 wool 0  
fill ~98 ~5 ~69 ~103 ~5 ~69 wool 0  
fill ~98 ~5 ~70 ~103 ~5 ~70 wool 0  
fill ~98 ~5 ~71 ~103 ~5 ~71 wool 0  
fill ~98 ~5 ~72 ~103 ~5 ~72 wool 0  
fill ~98 ~5 ~73 ~103 ~5 ~73 wool 0  
fill ~98 ~5 ~74 ~103 ~5 ~74 wool 0  
fill ~98 ~5 ~75 ~103 ~5 ~75 wool 0  
fill ~98 ~5 ~76 ~103 ~5 ~76 wool 0  
fill ~98 ~5 ~77 ~103 ~5 ~77 wool 0  
fill ~98 ~5 ~78 ~103 ~5 ~78 wool 0  
fill ~98 ~5 ~79 ~103 ~5 ~79 wool 0  
fill ~98 ~5 ~80 ~103 ~5 ~80 wool 0  
fill ~98 ~5 ~81 ~103 ~5 ~81 wool 0  
fill ~98 ~5 ~82 ~103 ~5 ~82 wool 0  
fill ~98 ~5 ~83 ~103 ~5 ~83 wool 0  
fill ~98 ~5 ~84 ~103 ~5 ~84 wool 0  
fill ~98 ~5 ~85 ~103 ~5 ~85 wool 0  
fill ~98 ~5 ~86 ~103 ~5 ~86 wool 0  
fill ~98 ~5 ~90 ~103 ~5 ~90 wool 0  
fill ~98 ~5 ~91 ~103 ~5 ~91 wool 0  
fill ~98 ~5 ~92 ~103 ~5 ~92 wool 0  
fill ~98 ~5 ~93 ~103 ~5 ~93 wool 0  
fill ~98 ~5 ~94 ~103 ~5 ~94 wool 0  
fill ~98 ~5 ~95 ~103 ~5 ~95 wool 0  
fill ~98 ~5 ~96 ~103 ~5 ~96 wool 0  
fill ~98 ~5 ~97 ~103 ~5 ~97 wool 0  
fill ~98 ~5 ~98 ~103 ~5 ~98 wool 0  
fill ~98 ~5 ~99 ~103 ~5 ~99 wool 0  
fill ~98 ~5 ~100 ~103 ~5 ~100 wool 0  
fill ~98 ~5 ~101 ~103 ~5 ~101 wool 0  
fill ~98 ~5 ~102 ~103 ~5 ~102 wool 0  
fill ~98 ~5 ~103 ~103 ~5 ~103 wool 0  
fill ~98 ~5 ~104 ~103 ~5 ~104 wool 0  
fill ~98 ~5 ~105 ~103 ~5 ~105 wool 0  
fill ~98 ~5 ~106 ~103 ~5 ~106 wool 0  
fill ~98 ~5 ~109 ~103 ~5 ~109 wool 0  
fill ~98 ~5 ~110 ~103 ~5 ~110 wool 0  
fill ~98 ~5 ~113 ~103 ~5 ~113 wool 0  
fill ~98 ~5 ~114 ~103 ~5 ~114 wool 0  
fill ~98 ~5 ~115 ~103 ~5 ~115 wool 0  
fill ~98 ~5 ~116 ~103 ~5 ~116 wool 0  
fill ~98 ~5 ~117 ~103 ~5 ~117 wool 0  
fill ~98 ~5 ~118 ~103 ~5 ~118 wool 0  
fill ~98 ~5 ~119 ~103 ~5 ~119 wool 0  
fill ~98 ~5 ~120 ~103 ~5 ~120 wool 0  
fill ~98 ~5 ~121 ~103 ~5 ~121 wool 0  
fill ~98 ~5 ~122 ~103 ~5 ~122 wool 0  
fill ~98 ~5 ~123 ~103 ~5 ~123 wool 0  
fill ~98 ~5 ~124 ~103 ~5 ~124 wool 0  
fill ~98 ~5 ~125 ~103 ~5 ~125 wool 0  
fill ~98 ~5 ~126 ~103 ~5 ~126 wool 0  
fill ~98 ~5 ~127 ~103 ~5 ~127 wool 0  
fill ~6 ~6 ~36 ~6 ~6 ~44 wool 0  
fill ~6 ~6 ~51 ~6 ~6 ~64 wool 0  
fill ~6 ~6 ~71 ~6 ~6 ~85 wool 0  
fill ~6 ~6 ~92 ~6 ~6 ~107 wool 0  
fill ~6 ~6 ~114 ~6 ~6 ~127 wool 0 
setblock ~7 ~6 ~35 wool 0 
setblock ~7 ~6 ~77 torch 1 
setblock ~7 ~6 ~120 torch 1 
setblock ~7 ~6 ~128 wool 0 
setblock ~8 ~6 ~34 wool 0  
fill ~8 ~6 ~46 ~8 ~6 ~48 wool 0  
fill ~8 ~6 ~66 ~8 ~6 ~68 wool 0  
fill ~8 ~6 ~87 ~8 ~6 ~89 wool 0  
fill ~8 ~6 ~109 ~8 ~6 ~111 wool 0 
setblock ~8 ~6 ~129 wool 0 
setblock ~9 ~6 ~33 wool 0  
fill ~9 ~6 ~47 ~9 ~7 ~47 wool 0  
fill ~9 ~6 ~67 ~9 ~7 ~67 wool 0  
fill ~9 ~6 ~88 ~9 ~7 ~88 wool 0  
fill ~9 ~6 ~110 ~9 ~7 ~110 wool 0 
setblock ~9 ~6 ~130 wool 0 
setblock ~10 ~6 ~32 wool 0 
setblock ~10 ~6 ~131 wool 0 
setblock ~11 ~6 ~31 wool 0 
setblock ~11 ~6 ~132 wool 0 
setblock ~12 ~6 ~30 wool 0 
setblock ~12 ~6 ~133 wool 0 
setblock ~13 ~6 ~29 wool 0 
setblock ~13 ~6 ~134 wool 0 
setblock ~13 ~6 ~139 torch 1 
setblock ~14 ~6 ~28 wool 0 
setblock ~14 ~6 ~135 wool 0 
setblock ~15 ~6 ~27 wool 0 
setblock ~15 ~6 ~136 wool 0 
setblock ~16 ~6 ~26 wool 0 
setblock ~16 ~6 ~137 wool 0 
setblock ~17 ~6 ~25 wool 0 
setblock ~17 ~6 ~138 wool 0 
setblock ~18 ~6 ~24 wool 0 
setblock ~18 ~6 ~139 wool 0 
setblock ~18 ~6 ~144 torch 4 
setblock ~19 ~6 ~23 wool 0 
setblock ~19 ~6 ~140 wool 0 
setblock ~20 ~6 ~22 wool 0 
setblock ~20 ~6 ~141 wool 0 
setblock ~21 ~6 ~21 wool 0  
fill ~21 ~6 ~40 ~23 ~6 ~40 wool 14 
setblock ~21 ~6 ~57 torch 2 
setblock ~21 ~6 ~69 torch 2 
setblock ~21 ~6 ~78 torch 2 
setblock ~21 ~6 ~90 torch 2 
setblock ~21 ~6 ~101 torch 2 
setblock ~21 ~6 ~108 torch 2 
setblock ~21 ~6 ~117 torch 2  
fill ~21 ~6 ~123 ~23 ~6 ~123 wool 14  
fill ~21 ~6 ~124 ~23 ~6 ~124 wool 14 
setblock ~21 ~6 ~142 wool 0 
setblock ~22 ~6 ~20 wool 0 
setblock ~22 ~6 ~37 torch 4  
fill ~22 ~6 ~38 ~23 ~6 ~38 wool 14  
fill ~22 ~6 ~39 ~23 ~6 ~39 wool 14  
fill ~22 ~6 ~41 ~23 ~6 ~41 wool 14  
fill ~22 ~6 ~42 ~23 ~6 ~42 wool 14  
fill ~22 ~6 ~43 ~23 ~6 ~43 wool 14  
fill ~22 ~6 ~44 ~23 ~6 ~44 wool 14  
fill ~22 ~6 ~45 ~23 ~6 ~45 wool 14  
fill ~22 ~6 ~46 ~23 ~6 ~46 wool 14  
fill ~22 ~6 ~47 ~23 ~6 ~47 wool 0  
fill ~22 ~6 ~48 ~23 ~6 ~48 wool 14  
fill ~22 ~6 ~49 ~23 ~6 ~49 wool 14  
fill ~22 ~6 ~50 ~23 ~6 ~50 wool 14  
fill ~22 ~6 ~51 ~23 ~6 ~51 wool 14  
fill ~22 ~6 ~52 ~23 ~6 ~52 wool 14  
fill ~22 ~6 ~53 ~23 ~6 ~53 wool 14  
fill ~22 ~6 ~54 ~23 ~6 ~54 wool 14  
fill ~22 ~6 ~55 ~23 ~6 ~55 wool 14  
fill ~22 ~6 ~56 ~23 ~6 ~56 wool 14  
fill ~22 ~6 ~57 ~23 ~6 ~57 wool 14  
fill ~22 ~6 ~58 ~23 ~6 ~58 wool 14  
fill ~22 ~6 ~59 ~23 ~6 ~59 wool 14  
fill ~22 ~6 ~60 ~23 ~6 ~60 wool 14  
fill ~22 ~6 ~61 ~23 ~6 ~61 wool 14  
fill ~22 ~6 ~62 ~23 ~6 ~62 wool 14  
fill ~22 ~6 ~63 ~23 ~6 ~63 wool 14  
fill ~22 ~6 ~64 ~23 ~6 ~64 wool 14  
fill ~22 ~6 ~65 ~23 ~6 ~65 wool 14  
fill ~22 ~6 ~66 ~23 ~6 ~66 wool 14  
fill ~22 ~6 ~67 ~23 ~6 ~67 wool 0  
fill ~22 ~6 ~68 ~23 ~6 ~68 wool 14  
fill ~22 ~6 ~69 ~23 ~6 ~69 wool 14  
fill ~22 ~6 ~70 ~23 ~6 ~70 wool 14  
fill ~22 ~6 ~71 ~23 ~6 ~71 wool 14  
fill ~22 ~6 ~72 ~23 ~6 ~72 wool 14  
fill ~22 ~6 ~73 ~23 ~6 ~73 wool 14  
fill ~22 ~6 ~74 ~23 ~6 ~74 wool 14  
fill ~22 ~6 ~75 ~23 ~6 ~75 wool 14  
fill ~22 ~6 ~76 ~23 ~6 ~76 wool 14  
fill ~22 ~6 ~77 ~23 ~6 ~77 wool 14  
fill ~22 ~6 ~78 ~23 ~6 ~78 wool 14  
fill ~22 ~6 ~79 ~23 ~6 ~79 wool 14  
fill ~22 ~6 ~80 ~23 ~6 ~80 wool 14  
fill ~22 ~6 ~81 ~23 ~6 ~81 wool 14  
fill ~22 ~6 ~82 ~23 ~6 ~82 wool 14  
fill ~22 ~6 ~83 ~23 ~6 ~83 wool 14  
fill ~22 ~6 ~84 ~23 ~6 ~84 wool 14  
fill ~22 ~6 ~85 ~23 ~6 ~85 wool 14  
fill ~22 ~6 ~86 ~23 ~6 ~86 wool 14  
fill ~22 ~6 ~87 ~23 ~6 ~87 wool 14  
fill ~22 ~6 ~88 ~23 ~6 ~88 wool 0  
fill ~22 ~6 ~89 ~23 ~6 ~89 wool 14  
fill ~22 ~6 ~90 ~23 ~6 ~90 wool 14  
fill ~22 ~6 ~91 ~23 ~6 ~91 wool 14  
fill ~22 ~6 ~92 ~23 ~6 ~92 wool 14  
fill ~22 ~6 ~93 ~23 ~6 ~93 wool 14  
fill ~22 ~6 ~94 ~23 ~6 ~94 wool 14  
fill ~22 ~6 ~95 ~23 ~6 ~95 wool 14  
fill ~22 ~6 ~96 ~23 ~6 ~96 wool 14  
fill ~22 ~6 ~97 ~23 ~6 ~97 wool 14  
fill ~22 ~6 ~98 ~23 ~6 ~98 wool 14  
fill ~22 ~6 ~99 ~23 ~6 ~99 wool 14  
fill ~22 ~6 ~100 ~23 ~6 ~100 wool 14  
fill ~22 ~6 ~101 ~23 ~6 ~101 wool 14  
fill ~22 ~6 ~102 ~23 ~6 ~102 wool 14  
fill ~22 ~6 ~103 ~23 ~6 ~103 wool 14  
fill ~22 ~6 ~104 ~23 ~6 ~104 wool 14  
fill ~22 ~6 ~105 ~23 ~6 ~105 wool 14  
fill ~22 ~6 ~106 ~23 ~6 ~106 wool 14  
fill ~22 ~6 ~107 ~23 ~6 ~107 wool 14  
fill ~22 ~6 ~108 ~23 ~6 ~108 wool 14  
fill ~22 ~6 ~109 ~23 ~6 ~109 wool 14  
fill ~22 ~6 ~110 ~23 ~6 ~110 wool 0  
fill ~22 ~6 ~111 ~23 ~6 ~111 wool 14  
fill ~22 ~6 ~112 ~23 ~6 ~112 wool 14  
fill ~22 ~6 ~113 ~23 ~6 ~113 wool 14  
fill ~22 ~6 ~114 ~23 ~6 ~114 wool 14  
fill ~22 ~6 ~115 ~23 ~6 ~115 wool 14  
fill ~22 ~6 ~116 ~23 ~6 ~116 wool 14  
fill ~22 ~6 ~117 ~23 ~6 ~117 wool 14  
fill ~22 ~6 ~118 ~23 ~6 ~118 wool 14  
fill ~22 ~6 ~119 ~23 ~6 ~119 wool 14  
fill ~22 ~6 ~120 ~23 ~6 ~120 wool 14  
fill ~22 ~6 ~121 ~23 ~6 ~121 wool 14  
fill ~22 ~6 ~122 ~23 ~6 ~122 wool 14  
fill ~22 ~6 ~125 ~23 ~6 ~125 wool 14 
setblock ~22 ~6 ~143 wool 0 
setblock ~23 ~6 ~19 wool 0  
fill ~23 ~6 ~37 ~24 ~6 ~37 wool 14  
fill ~23 ~6 ~126 ~24 ~6 ~126 wool 14 
setblock ~23 ~6 ~127 torch 2 
setblock ~23 ~6 ~144 wool 0 
setblock ~24 ~6 ~18 wool 0  
fill ~24 ~6 ~36 ~25 ~6 ~36 wool 14  
fill ~24 ~6 ~127 ~25 ~6 ~127 wool 14 
setblock ~24 ~6 ~145 wool 0 
setblock ~25 ~6 ~17 wool 0  
fill ~25 ~6 ~35 ~26 ~6 ~35 wool 14  
fill ~25 ~6 ~128 ~26 ~6 ~128 wool 14 
setblock ~25 ~6 ~129 torch 2 
setblock ~25 ~6 ~146 wool 0 
setblock ~26 ~6 ~16 wool 0  
fill ~26 ~6 ~34 ~27 ~6 ~34 wool 14  
fill ~26 ~6 ~129 ~27 ~6 ~129 wool 14 
setblock ~26 ~6 ~147 wool 0 
setblock ~27 ~6 ~15 wool 0 
setblock ~27 ~6 ~32 torch 4  
fill ~27 ~6 ~33 ~28 ~6 ~33 wool 14  
fill ~27 ~6 ~130 ~28 ~6 ~130 wool 14 
setblock ~27 ~6 ~131 torch 2 
setblock ~27 ~6 ~148 wool 0 
setblock ~28 ~6 ~14 wool 0  
fill ~28 ~6 ~32 ~29 ~6 ~32 wool 14  
fill ~28 ~6 ~131 ~29 ~6 ~131 wool 14 
setblock ~28 ~6 ~149 wool 0 
setblock ~28 ~6 ~154 torch 4 
setblock ~29 ~6 ~13 wool 0  
fill ~29 ~6 ~31 ~30 ~6 ~31 wool 14  
fill ~29 ~6 ~132 ~30 ~6 ~132 wool 14 
setblock ~29 ~6 ~150 wool 0 
setblock ~30 ~6 ~12 wool 0  
fill ~30 ~6 ~30 ~31 ~6 ~30 wool 14  
fill ~30 ~6 ~133 ~31 ~6 ~133 wool 14 
setblock ~30 ~6 ~151 wool 0 
setblock ~31 ~6 ~11 wool 0  
fill ~31 ~6 ~29 ~32 ~6 ~29 wool 14  
fill ~31 ~6 ~134 ~32 ~6 ~134 wool 14 
setblock ~31 ~6 ~152 wool 0 
setblock ~32 ~6 ~10 wool 0  
fill ~32 ~6 ~28 ~33 ~6 ~28 wool 14  
fill ~32 ~6 ~135 ~33 ~6 ~135 wool 14 
setblock ~32 ~6 ~136 torch 2 
setblock ~32 ~6 ~153 wool 0 
setblock ~33 ~6 ~9 wool 0 
setblock ~33 ~6 ~26 torch 4  
fill ~33 ~6 ~27 ~34 ~6 ~27 wool 14  
fill ~33 ~6 ~136 ~34 ~6 ~136 wool 14 
setblock ~33 ~6 ~154 wool 0 
setblock ~34 ~6 ~8 wool 0 
setblock ~34 ~6 ~25 torch 4  
fill ~34 ~6 ~26 ~41 ~6 ~26 wool 14  
fill ~34 ~6 ~137 ~35 ~6 ~137 wool 14 
setblock ~34 ~6 ~155 wool 0  
fill ~35 ~6 ~1 ~69 ~6 ~1 wool 0  
fill ~35 ~6 ~7 ~38 ~6 ~7 wool 0  
fill ~35 ~6 ~25 ~41 ~6 ~25 wool 14  
fill ~35 ~6 ~138 ~41 ~6 ~138 wool 14 
setblock ~35 ~6 ~156 wool 0  
fill ~35 ~6 ~162 ~69 ~6 ~162 wool 0  
fill ~36 ~6 ~139 ~41 ~6 ~139 wool 14  
fill ~36 ~6 ~157 ~39 ~6 ~157 wool 0  
fill ~37 ~6 ~24 ~38 ~6 ~24 wool 14 
setblock ~37 ~6 ~140 torch 2  
fill ~38 ~6 ~140 ~38 ~7 ~140 wool 14  
fill ~41 ~6 ~9 ~43 ~6 ~9 wool 0  
fill ~41 ~6 ~155 ~43 ~6 ~155 wool 0  
fill ~42 ~6 ~10 ~42 ~7 ~10 wool 0  
fill ~42 ~6 ~25 ~42 ~6 ~26 wool 0  
fill ~42 ~6 ~138 ~42 ~6 ~139 wool 0  
fill ~42 ~6 ~154 ~42 ~7 ~154 wool 0  
fill ~43 ~6 ~25 ~61 ~6 ~25 wool 14  
fill ~43 ~6 ~26 ~61 ~6 ~26 wool 14  
fill ~43 ~6 ~138 ~61 ~6 ~138 wool 14  
fill ~43 ~6 ~139 ~61 ~6 ~139 wool 14 
setblock ~44 ~6 ~24 torch 4  
fill ~45 ~6 ~7 ~59 ~6 ~7 wool 0  
fill ~46 ~6 ~157 ~59 ~6 ~157 wool 0 
setblock ~48 ~6 ~140 torch 3 
setblock ~50 ~6 ~156 torch 4 
setblock ~56 ~6 ~24 torch 4 
setblock ~58 ~6 ~140 torch 3  
fill ~61 ~6 ~9 ~63 ~6 ~9 wool 0  
fill ~61 ~6 ~155 ~63 ~6 ~155 wool 0  
fill ~62 ~6 ~10 ~62 ~7 ~10 wool 0  
fill ~62 ~6 ~25 ~62 ~6 ~26 wool 0  
fill ~62 ~6 ~138 ~62 ~6 ~139 wool 0  
fill ~62 ~6 ~154 ~62 ~7 ~154 wool 0  
fill ~63 ~6 ~25 ~69 ~6 ~25 wool 14  
fill ~63 ~6 ~26 ~70 ~6 ~26 wool 14  
fill ~63 ~6 ~138 ~69 ~6 ~138 wool 14  
fill ~63 ~6 ~139 ~68 ~6 ~139 wool 14 
setblock ~65 ~6 ~140 torch 2  
fill ~66 ~6 ~7 ~69 ~6 ~7 wool 0 
setblock ~66 ~6 ~23 torch 4  
fill ~66 ~6 ~24 ~67 ~6 ~24 wool 14  
fill ~66 ~6 ~140 ~67 ~6 ~140 wool 14  
fill ~66 ~6 ~157 ~68 ~6 ~157 wool 0  
fill ~69 ~6 ~137 ~70 ~6 ~137 wool 14 
setblock ~69 ~6 ~139 torch 3  
fill ~69 ~6 ~156 ~69 ~5 ~156 wool 0  
fill ~70 ~6 ~8 ~70 ~5 ~8 wool 0  
fill ~70 ~6 ~27 ~71 ~6 ~27 wool 14  
fill ~70 ~6 ~136 ~71 ~6 ~136 wool 14  
fill ~70 ~6 ~155 ~70 ~5 ~155 wool 0  
fill ~71 ~6 ~9 ~71 ~5 ~9 wool 0  
fill ~71 ~6 ~28 ~72 ~6 ~28 wool 14  
fill ~71 ~6 ~135 ~72 ~6 ~135 wool 14  
fill ~71 ~6 ~154 ~71 ~5 ~154 wool 0  
fill ~72 ~6 ~10 ~72 ~5 ~10 wool 0  
fill ~72 ~6 ~29 ~73 ~6 ~29 wool 14  
fill ~72 ~6 ~134 ~73 ~6 ~134 wool 14  
fill ~72 ~6 ~153 ~72 ~5 ~153 wool 0  
fill ~73 ~6 ~11 ~73 ~5 ~11 wool 0 
setblock ~73 ~6 ~28 torch 1  
fill ~73 ~6 ~30 ~74 ~6 ~30 wool 14  
fill ~73 ~6 ~133 ~74 ~6 ~133 wool 14 
setblock ~73 ~6 ~135 torch 3  
fill ~73 ~6 ~152 ~73 ~5 ~152 wool 0  
fill ~74 ~6 ~12 ~74 ~5 ~12 wool 0  
fill ~74 ~6 ~31 ~75 ~6 ~31 wool 14  
fill ~74 ~6 ~132 ~75 ~6 ~132 wool 14  
fill ~74 ~6 ~151 ~74 ~5 ~151 wool 0  
fill ~75 ~6 ~13 ~75 ~5 ~13 wool 0  
fill ~75 ~6 ~32 ~76 ~6 ~32 wool 14  
fill ~75 ~6 ~131 ~76 ~6 ~131 wool 14  
fill ~75 ~6 ~150 ~75 ~5 ~150 wool 0  
fill ~76 ~6 ~14 ~76 ~5 ~14 wool 0  
fill ~76 ~6 ~33 ~77 ~6 ~33 wool 14  
fill ~76 ~6 ~130 ~77 ~6 ~130 wool 14 
setblock ~76 ~6 ~132 torch 3  
fill ~76 ~6 ~149 ~76 ~5 ~149 wool 0  
fill ~77 ~6 ~15 ~77 ~5 ~15 wool 0  
fill ~77 ~6 ~34 ~78 ~6 ~34 wool 14  
fill ~77 ~6 ~129 ~78 ~6 ~129 wool 14  
fill ~77 ~6 ~148 ~77 ~5 ~148 wool 0  
fill ~78 ~6 ~16 ~78 ~5 ~16 wool 0  
fill ~78 ~6 ~35 ~79 ~6 ~35 wool 14  
fill ~78 ~6 ~128 ~79 ~6 ~128 wool 14   
fill ~78 ~6 ~147 ~78 ~5 ~147 wool 0  
fill ~79 ~6 ~17 ~79 ~5 ~17 wool 0  
fill ~79 ~6 ~36 ~80 ~6 ~36 wool 14  
fill ~79 ~6 ~127 ~80 ~6 ~127 wool 14 
setblock ~79 ~6 ~129 torch 3  
fill ~79 ~6 ~146 ~79 ~5 ~146 wool 0  
fill ~80 ~6 ~18 ~80 ~5 ~18 wool 0 
setblock ~80 ~6 ~35 torch 1  
fill ~80 ~6 ~37 ~81 ~6 ~37 wool 14  
fill ~80 ~6 ~126 ~81 ~6 ~126 wool 14  
fill ~80 ~6 ~145 ~80 ~5 ~145 wool 0  
fill ~81 ~6 ~19 ~81 ~5 ~19 wool 0  
fill ~81 ~6 ~38 ~82 ~6 ~38 wool 14  
fill ~81 ~6 ~39 ~82 ~6 ~39 wool 14  
fill ~81 ~6 ~40 ~83 ~6 ~40 wool 14  
fill ~81 ~6 ~41 ~82 ~6 ~41 wool 14  
fill ~81 ~6 ~42 ~82 ~6 ~42 wool 14  
fill ~81 ~6 ~43 ~82 ~6 ~43 wool 14  
fill ~81 ~6 ~44 ~82 ~6 ~44 wool 14  
fill ~81 ~6 ~45 ~82 ~6 ~45 wool 14  
fill ~81 ~6 ~46 ~82 ~6 ~46 wool 14  
fill ~81 ~6 ~47 ~82 ~6 ~47 wool 0  
fill ~81 ~6 ~48 ~82 ~6 ~48 wool 14  
fill ~81 ~6 ~49 ~82 ~6 ~49 wool 14  
fill ~81 ~6 ~50 ~82 ~6 ~50 wool 14  
fill ~81 ~6 ~51 ~82 ~6 ~51 wool 14  
fill ~81 ~6 ~52 ~82 ~6 ~52 wool 14  
fill ~81 ~6 ~53 ~82 ~6 ~53 wool 14  
fill ~81 ~6 ~54 ~82 ~6 ~54 wool 14  
fill ~81 ~6 ~55 ~82 ~6 ~55 wool 14  
fill ~81 ~6 ~56 ~82 ~6 ~56 wool 14  
fill ~81 ~6 ~57 ~82 ~6 ~57 wool 14  
fill ~81 ~6 ~58 ~82 ~6 ~58 wool 14  
fill ~81 ~6 ~59 ~82 ~6 ~59 wool 14  
fill ~81 ~6 ~60 ~82 ~6 ~60 wool 14  
fill ~81 ~6 ~61 ~82 ~6 ~61 wool 14  
fill ~81 ~6 ~62 ~82 ~6 ~62 wool 14  
fill ~81 ~6 ~63 ~82 ~6 ~63 wool 14  
fill ~81 ~6 ~64 ~82 ~6 ~64 wool 14  
fill ~81 ~6 ~65 ~82 ~6 ~65 wool 14  
fill ~81 ~6 ~66 ~82 ~6 ~66 wool 14  
fill ~81 ~6 ~67 ~82 ~6 ~67 wool 0  
fill ~81 ~6 ~68 ~82 ~6 ~68 wool 14  
fill ~81 ~6 ~69 ~82 ~6 ~69 wool 14  
fill ~81 ~6 ~70 ~82 ~6 ~70 wool 14  
fill ~81 ~6 ~71 ~82 ~6 ~71 wool 14  
fill ~81 ~6 ~72 ~82 ~6 ~72 wool 14  
fill ~81 ~6 ~73 ~82 ~6 ~73 wool 14  
fill ~81 ~6 ~74 ~82 ~6 ~74 wool 14  
fill ~81 ~6 ~75 ~82 ~6 ~75 wool 14  
fill ~81 ~6 ~76 ~82 ~6 ~76 wool 14  
fill ~81 ~6 ~77 ~82 ~6 ~77 wool 14  
fill ~81 ~6 ~78 ~82 ~6 ~78 wool 14  
fill ~81 ~6 ~79 ~82 ~6 ~79 wool 14  
fill ~81 ~6 ~80 ~82 ~6 ~80 wool 14  
fill ~81 ~6 ~81 ~82 ~6 ~81 wool 14  
fill ~81 ~6 ~82 ~82 ~6 ~82 wool 14  
fill ~81 ~6 ~83 ~82 ~6 ~83 wool 14  
fill ~81 ~6 ~84 ~82 ~6 ~84 wool 14  
fill ~81 ~6 ~85 ~82 ~6 ~85 wool 14  
fill ~81 ~6 ~86 ~82 ~6 ~86 wool 14  
fill ~81 ~6 ~87 ~82 ~6 ~87 wool 14  
fill ~81 ~6 ~88 ~83 ~6 ~88 wool 0  
fill ~81 ~6 ~89 ~82 ~6 ~89 wool 14  
fill ~81 ~6 ~90 ~82 ~6 ~90 wool 14  
fill ~81 ~6 ~91 ~82 ~6 ~91 wool 14  
fill ~81 ~6 ~92 ~82 ~6 ~92 wool 14  
fill ~81 ~6 ~93 ~82 ~6 ~93 wool 14  
fill ~81 ~6 ~94 ~82 ~6 ~94 wool 14  
fill ~81 ~6 ~95 ~82 ~6 ~95 wool 14  
fill ~81 ~6 ~96 ~82 ~6 ~96 wool 14  
fill ~81 ~6 ~97 ~82 ~6 ~97 wool 14  
fill ~81 ~6 ~98 ~82 ~6 ~98 wool 14  
fill ~81 ~6 ~99 ~82 ~6 ~99 wool 14  
fill ~81 ~6 ~100 ~82 ~6 ~100 wool 14  
fill ~81 ~6 ~101 ~82 ~6 ~101 wool 14  
fill ~81 ~6 ~102 ~82 ~6 ~102 wool 14  
fill ~81 ~6 ~103 ~82 ~6 ~103 wool 14  
fill ~81 ~6 ~104 ~82 ~6 ~104 wool 14  
fill ~81 ~6 ~105 ~82 ~6 ~105 wool 14  
fill ~81 ~6 ~106 ~82 ~6 ~106 wool 14  
fill ~81 ~6 ~107 ~82 ~6 ~107 wool 14  
fill ~81 ~6 ~108 ~82 ~6 ~108 wool 14  
fill ~81 ~6 ~109 ~82 ~6 ~109 wool 14  
fill ~81 ~6 ~110 ~82 ~6 ~110 wool 0  
fill ~81 ~6 ~111 ~82 ~6 ~111 wool 14  
fill ~81 ~6 ~112 ~82 ~6 ~112 wool 14  
fill ~81 ~6 ~113 ~82 ~6 ~113 wool 14  
fill ~81 ~6 ~114 ~82 ~6 ~114 wool 14  
fill ~81 ~6 ~115 ~82 ~6 ~115 wool 14  
fill ~81 ~6 ~116 ~82 ~6 ~116 wool 14  
fill ~81 ~6 ~117 ~82 ~6 ~117 wool 14  
fill ~81 ~6 ~118 ~82 ~6 ~118 wool 14  
fill ~81 ~6 ~119 ~82 ~6 ~119 wool 14  
fill ~81 ~6 ~120 ~82 ~6 ~120 wool 14  
fill ~81 ~6 ~121 ~82 ~6 ~121 wool 14  
fill ~81 ~6 ~122 ~82 ~6 ~122 wool 14  
fill ~81 ~6 ~123 ~83 ~6 ~123 wool 14  
fill ~81 ~6 ~124 ~82 ~6 ~124 wool 14  
fill ~81 ~6 ~125 ~82 ~6 ~125 wool 14  
fill ~81 ~6 ~144 ~81 ~5 ~144 wool 0  
fill ~82 ~6 ~20 ~82 ~5 ~20 wool 0  
fill ~82 ~6 ~143 ~82 ~5 ~143 wool 0  
fill ~83 ~6 ~21 ~83 ~5 ~21 wool 0 
setblock ~83 ~6 ~45 torch 1 
setblock ~83 ~6 ~52 torch 1 
setblock ~83 ~6 ~61 torch 1 
setblock ~83 ~6 ~71 torch 1 
setblock ~83 ~6 ~82 torch 1 
setblock ~83 ~6 ~90 torch 1 
setblock ~83 ~6 ~100 torch 1 
setblock ~83 ~6 ~111 torch 1 
setblock ~83 ~6 ~121 torch 1  
fill ~83 ~6 ~142 ~83 ~5 ~142 wool 0  
fill ~84 ~6 ~22 ~84 ~5 ~22 wool 0  
fill ~84 ~6 ~141 ~84 ~5 ~141 wool 0  
fill ~85 ~6 ~23 ~85 ~5 ~23 wool 0  
