fill ~13 ~0 ~14 ~25 ~0 ~14 stone_brick_stairs 6  
fill ~13 ~0 ~15 ~25 ~0 ~15 stone 0  
fill ~13 ~0 ~16 ~25 ~0 ~16 stone 0  
fill ~15 ~0 ~25 ~23 ~0 ~25 stone_brick_stairs 6  
fill ~15 ~0 ~26 ~23 ~0 ~26 stone 0  
fill ~13 ~1 ~13 ~25 ~1 ~13 stone_brick_stairs 6  
fill ~13 ~1 ~14 ~25 ~1 ~14 stone 0  
fill ~13 ~1 ~16 ~13 ~4 ~16 stone 0  
fill ~14 ~1 ~15 ~14 ~3 ~15 stonebrick 3 
setblock ~15 ~1 ~24 stone_brick_stairs 6 
setblock ~15 ~1 ~25 stone 0 
setblock ~15 ~1 ~26 stone_brick_stairs 3 
setblock ~23 ~1 ~24 stone_brick_stairs 6 
setblock ~23 ~1 ~25 stone 0 
setblock ~23 ~1 ~26 stone_brick_stairs 3  
fill ~24 ~1 ~15 ~24 ~3 ~15 stonebrick 3  
fill ~25 ~1 ~16 ~25 ~4 ~16 stone 0  
fill ~13 ~2 ~12 ~25 ~2 ~12 stone_brick_stairs 6  
fill ~13 ~2 ~13 ~25 ~2 ~13 stone 0 
setblock ~14 ~2 ~14 stonebrick 3 
setblock ~15 ~2 ~23 stone_brick_stairs 6 
setblock ~15 ~2 ~24 stone 0 
setblock ~15 ~2 ~25 stone_brick_stairs 3 
setblock ~23 ~2 ~23 stone_brick_stairs 6 
setblock ~23 ~2 ~24 stone 0 
setblock ~23 ~2 ~25 stone_brick_stairs 3 
setblock ~24 ~2 ~14 stonebrick 3  
fill ~13 ~3 ~12 ~25 ~3 ~12 stone 0  
fill ~14 ~3 ~11 ~24 ~3 ~11 stone_brick_stairs 6  
fill ~14 ~3 ~13 ~14 ~5 ~13 stonebrick 3  
fill ~14 ~3 ~14 ~14 ~5 ~14 glowstone 0  
fill ~14 ~3 ~27 ~24 ~3 ~27 stone 0  
fill ~14 ~3 ~28 ~24 ~3 ~28 stone 0  
fill ~14 ~3 ~29 ~24 ~3 ~29 stone 0  
fill ~14 ~3 ~30 ~24 ~3 ~30 stone 0  
fill ~14 ~3 ~31 ~24 ~3 ~31 stone_brick_stairs 7  
fill ~15 ~3 ~23 ~15 ~8 ~23 stone 0 
setblock ~15 ~3 ~24 stone_brick_stairs 3  
fill ~23 ~3 ~23 ~23 ~8 ~23 stone 0 
setblock ~23 ~3 ~24 stone_brick_stairs 3  
fill ~24 ~3 ~13 ~24 ~5 ~13 stonebrick 3  
fill ~24 ~3 ~14 ~24 ~5 ~14 glowstone 0  
fill ~13 ~4 ~12 ~14 ~4 ~12 stone 0  
fill ~13 ~4 ~15 ~14 ~4 ~15 stone 0  
fill ~14 ~4 ~11 ~24 ~4 ~11 stone 0  
fill ~14 ~4 ~27 ~24 ~4 ~27 stone 0  
fill ~14 ~4 ~28 ~24 ~4 ~28 stone 0  
fill ~14 ~4 ~29 ~24 ~4 ~29 stone 0  
fill ~14 ~4 ~30 ~24 ~4 ~30 stone 0  
fill ~14 ~4 ~31 ~24 ~4 ~31 stone 0  
fill ~15 ~4 ~10 ~23 ~4 ~10 stone_brick_stairs 6 
setblock ~15 ~4 ~22 stone_brick_stairs 6  
fill ~15 ~4 ~32 ~23 ~4 ~32 stone_brick_stairs 7 
setblock ~18 ~4 ~20 end_rod 0 
setblock ~18 ~4 ~22 end_rod 0 
setblock ~20 ~4 ~20 end_rod 0 
setblock ~20 ~4 ~22 end_rod 0 
setblock ~23 ~4 ~22 stone_brick_stairs 6  
fill ~24 ~4 ~12 ~25 ~4 ~12 stone 0  
fill ~24 ~4 ~15 ~25 ~4 ~15 stone 0  
fill ~13 ~5 ~12 ~14 ~5 ~12 stone 0  
fill ~13 ~5 ~14 ~13 ~6 ~14 stone 0  
fill ~13 ~5 ~15 ~13 ~4 ~15 stone 0 
setblock ~13 ~5 ~16 stone_brick_stairs 3  
fill ~14 ~5 ~11 ~15 ~5 ~11 stone 0  
fill ~14 ~5 ~27 ~24 ~5 ~27 stone 0  
fill ~14 ~5 ~28 ~24 ~5 ~28 stone 0  
fill ~14 ~5 ~29 ~24 ~5 ~29 stone 0  
fill ~14 ~5 ~30 ~24 ~5 ~30 stone 0  
fill ~14 ~5 ~31 ~24 ~5 ~31 stone 0  
fill ~15 ~5 ~10 ~23 ~5 ~10 stone 0 
setblock ~15 ~5 ~21 stone_button 2  
fill ~15 ~5 ~22 ~17 ~5 ~22 stone 0  
fill ~15 ~5 ~32 ~23 ~5 ~32 stone 0  
fill ~16 ~5 ~9 ~22 ~5 ~9 stone_brick_stairs 6  
fill ~16 ~5 ~21 ~17 ~5 ~21 stone 0  
fill ~16 ~5 ~23 ~23 ~5 ~23 stone 0  
fill ~16 ~5 ~24 ~22 ~5 ~24 stone 0  
fill ~16 ~5 ~33 ~22 ~5 ~33 stone_brick_stairs 7  
fill ~17 ~5 ~19 ~21 ~5 ~19 stone 0  
fill ~17 ~5 ~20 ~17 ~5 ~19 stone 0 
setblock ~18 ~5 ~20 quartz_block 1 
setblock ~18 ~5 ~22 quartz_block 1 
setblock ~20 ~5 ~20 quartz_block 1 
setblock ~20 ~5 ~22 quartz_block 1  
fill ~21 ~5 ~20 ~21 ~5 ~24 stone 0  
fill ~22 ~5 ~21 ~22 ~9 ~21 stone 0  
fill ~22 ~5 ~22 ~23 ~5 ~22 stone 0  
fill ~23 ~5 ~11 ~24 ~5 ~11 stone 0 
setblock ~23 ~5 ~21 stone_button 1  
fill ~24 ~5 ~12 ~25 ~5 ~12 stone 0  
fill ~25 ~5 ~14 ~25 ~6 ~14 stone 0  
fill ~25 ~5 ~15 ~25 ~5 ~14 stone 0 
setblock ~25 ~5 ~16 stone_brick_stairs 3  
fill ~13 ~6 ~12 ~14 ~6 ~12 stone 0  
fill ~13 ~6 ~13 ~13 ~10 ~13 stone 0 
setblock ~13 ~6 ~15 stone_brick_stairs 3  
fill ~14 ~6 ~11 ~15 ~6 ~11 stone 0 
setblock ~14 ~6 ~13 glowstone 0  
fill ~14 ~6 ~21 ~14 ~7 ~21 stone_button 2  
fill ~14 ~6 ~27 ~24 ~6 ~27 stone 0  
fill ~14 ~6 ~28 ~24 ~6 ~28 stone 0  
fill ~14 ~6 ~29 ~14 ~3 ~29 stone 0  
fill ~14 ~6 ~31 ~24 ~6 ~31 stone 0  
fill ~15 ~6 ~10 ~16 ~6 ~10 stone 0  
fill ~15 ~6 ~21 ~17 ~6 ~21 stone 0  
fill ~15 ~6 ~22 ~15 ~7 ~22 wool 1 
setblock ~15 ~6 ~26 lever 10  
fill ~15 ~6 ~29 ~16 ~6 ~29 stonebrick 3  
fill ~15 ~6 ~32 ~23 ~6 ~32 stone 0  
fill ~16 ~6 ~9 ~18 ~6 ~9 stone 0  
fill ~16 ~6 ~22 ~17 ~6 ~22 stone 0  
fill ~16 ~6 ~23 ~23 ~6 ~23 stone 0  
fill ~16 ~6 ~24 ~22 ~6 ~24 stone 0  
fill ~16 ~6 ~25 ~22 ~6 ~25 stone 0  
fill ~16 ~6 ~26 ~22 ~6 ~26 stone 0  
fill ~16 ~6 ~33 ~22 ~6 ~33 stone 0  
fill ~17 ~6 ~8 ~21 ~6 ~8 stone_brick_stairs 6  
fill ~17 ~6 ~19 ~21 ~6 ~19 stone 0  
fill ~17 ~6 ~20 ~17 ~8 ~20 wool 1  
fill ~17 ~6 ~29 ~21 ~6 ~29 stone 0  
fill ~17 ~6 ~30 ~17 ~13 ~30 stonebrick 3  
fill ~17 ~6 ~34 ~21 ~6 ~34 stone_brick_stairs 7  
fill ~18 ~6 ~20 ~18 ~7 ~20 glowstone 0 
setblock ~18 ~6 ~21 quartz_block 1 
setblock ~18 ~6 ~22 glowstone 0  
fill ~18 ~6 ~30 ~20 ~6 ~30 stone 0 
setblock ~19 ~6 ~20 quartz_block 1 
setblock ~19 ~6 ~21 glowstone 0 
setblock ~19 ~6 ~22 quartz_block 1  
fill ~20 ~6 ~9 ~22 ~6 ~9 stone 0  
fill ~20 ~6 ~20 ~20 ~7 ~20 glowstone 0 
setblock ~20 ~6 ~21 quartz_block 1 
setblock ~20 ~6 ~22 glowstone 0  
fill ~21 ~6 ~20 ~21 ~8 ~20 wool 1  
fill ~21 ~6 ~21 ~21 ~9 ~21 stone 0  
fill ~21 ~6 ~22 ~22 ~6 ~22 stone 0  
fill ~21 ~6 ~30 ~21 ~13 ~30 stonebrick 3  
fill ~22 ~6 ~10 ~23 ~6 ~10 stone 0  
fill ~22 ~6 ~29 ~23 ~6 ~29 stonebrick 3  
fill ~23 ~6 ~11 ~24 ~6 ~11 stone 0  
fill ~23 ~6 ~21 ~23 ~7 ~21 stone 0  
fill ~23 ~6 ~22 ~23 ~7 ~22 wool 1 
setblock ~23 ~6 ~26 lever 9  
fill ~24 ~6 ~12 ~25 ~6 ~12 stone 0 
setblock ~24 ~6 ~13 glowstone 0  
fill ~24 ~6 ~21 ~24 ~7 ~21 stone_button 1 
setblock ~24 ~6 ~29 stone 0  
fill ~25 ~6 ~13 ~25 ~10 ~13 stone 0 
setblock ~25 ~6 ~15 stone_brick_stairs 3  
fill ~13 ~7 ~12 ~13 ~11 ~12 stone 0 
setblock ~13 ~7 ~14 stone_brick_stairs 3  
fill ~14 ~7 ~11 ~15 ~7 ~11 stone 0  
fill ~14 ~7 ~12 ~14 ~10 ~12 glowstone 0 
setblock ~14 ~7 ~24 lever 2  
fill ~14 ~7 ~26 ~15 ~7 ~26 stone_brick_stairs 6  
fill ~14 ~7 ~27 ~24 ~7 ~27 stone 0  
fill ~14 ~7 ~28 ~24 ~7 ~28 stone 0  
fill ~14 ~7 ~31 ~24 ~7 ~31 stone 0  
fill ~15 ~7 ~10 ~16 ~7 ~10 stone 0  
fill ~15 ~7 ~21 ~23 ~7 ~21 stone 0  
fill ~15 ~7 ~24 ~23 ~7 ~24 stone 0  
fill ~15 ~7 ~29 ~16 ~7 ~29 stonebrick 3  
fill ~15 ~7 ~32 ~23 ~7 ~32 stone 0  
fill ~16 ~7 ~9 ~18 ~7 ~9 stone 0  
fill ~16 ~7 ~22 ~22 ~7 ~22 stone 0  
fill ~16 ~7 ~23 ~23 ~7 ~23 stone 0  
fill ~16 ~7 ~25 ~22 ~7 ~25 stone 0  
fill ~16 ~7 ~26 ~22 ~7 ~26 stone 0 
setblock ~16 ~7 ~30 stone_button 2  
fill ~16 ~7 ~33 ~22 ~7 ~33 stone 0  
fill ~17 ~7 ~8 ~18 ~7 ~8 stone 0  
fill ~17 ~7 ~29 ~21 ~7 ~29 stone 0  
fill ~17 ~7 ~34 ~21 ~7 ~34 stone 0  
fill ~18 ~7 ~7 ~20 ~7 ~7 stone_brick_stairs 6  
fill ~18 ~7 ~30 ~20 ~7 ~30 stone 0  
fill ~18 ~7 ~35 ~20 ~7 ~35 stone_brick_stairs 7  
fill ~19 ~7 ~8 ~19 ~11 ~8 redstone_block 0  
fill ~19 ~7 ~9 ~19 ~12 ~9 lit_redstone_lamp 0 
setblock ~19 ~7 ~20 piston 2  
fill ~20 ~7 ~8 ~21 ~7 ~8 stone 0  
fill ~20 ~7 ~9 ~22 ~7 ~9 stone 0  
fill ~22 ~7 ~10 ~23 ~7 ~10 stone 0  
fill ~22 ~7 ~29 ~23 ~7 ~29 stonebrick 3 
setblock ~22 ~7 ~30 stone_button 1  
fill ~23 ~7 ~11 ~24 ~7 ~11 stone 0  
fill ~23 ~7 ~26 ~24 ~7 ~26 stone_brick_stairs 6  
fill ~24 ~7 ~12 ~24 ~10 ~12 glowstone 0 
setblock ~24 ~7 ~24 lever 1  
fill ~25 ~7 ~12 ~25 ~11 ~12 stone 0 
setblock ~25 ~7 ~14 stone_brick_stairs 3  
fill ~14 ~8 ~11 ~15 ~8 ~11 stone 0  
fill ~14 ~8 ~25 ~15 ~8 ~25 stone_brick_stairs 6  
fill ~14 ~8 ~26 ~24 ~8 ~26 stone 0  
fill ~14 ~8 ~27 ~24 ~8 ~27 stone 0  
fill ~14 ~8 ~28 ~24 ~8 ~28 stone 0  
fill ~14 ~8 ~31 ~24 ~8 ~31 stone 0  
fill ~15 ~8 ~10 ~16 ~8 ~10 stone 0  
fill ~15 ~8 ~21 ~15 ~9 ~21 stone_button 2 
setblock ~15 ~8 ~22 stone 0  
fill ~15 ~8 ~29 ~16 ~8 ~29 stonebrick 3  
fill ~15 ~8 ~32 ~23 ~8 ~32 stone 0  
fill ~16 ~8 ~9 ~18 ~8 ~9 stone 0  
fill ~16 ~8 ~21 ~22 ~8 ~21 stone 0 
setblock ~16 ~8 ~22 lever 4  
fill ~16 ~8 ~23 ~23 ~8 ~23 stone 0  
fill ~16 ~8 ~24 ~22 ~8 ~24 stone 0  
fill ~16 ~8 ~25 ~22 ~8 ~25 stone 0  
fill ~16 ~8 ~33 ~22 ~8 ~33 stone 0  
fill ~17 ~8 ~8 ~18 ~8 ~8 stone 0  
fill ~17 ~8 ~19 ~21 ~8 ~19 stone 0  
fill ~17 ~8 ~22 ~21 ~8 ~22 stone 0  
fill ~17 ~8 ~29 ~21 ~8 ~29 stone 0  
fill ~17 ~8 ~34 ~21 ~8 ~34 stone 0  
fill ~18 ~8 ~7 ~18 ~12 ~7 stone 0  
fill ~18 ~8 ~20 ~20 ~8 ~20 stone 0  
fill ~18 ~8 ~30 ~20 ~8 ~30 stone 0  
fill ~18 ~8 ~35 ~20 ~8 ~35 stone 0  
fill ~19 ~8 ~7 ~19 ~12 ~7 lit_redstone_lamp 0  
fill ~20 ~8 ~7 ~20 ~12 ~7 stone 0  
fill ~20 ~8 ~8 ~21 ~8 ~8 stone 0  
fill ~20 ~8 ~9 ~22 ~8 ~9 stone 0  
fill ~22 ~8 ~10 ~23 ~8 ~10 stone 0 
setblock ~22 ~8 ~22 lever 4  
fill ~22 ~8 ~29 ~23 ~8 ~29 stonebrick 3  
fill ~23 ~8 ~11 ~24 ~8 ~11 stone 0  
fill ~23 ~8 ~21 ~23 ~9 ~21 stone_button 1 
setblock ~23 ~8 ~22 stone 0  
fill ~23 ~8 ~25 ~24 ~8 ~25 stone_brick_stairs 6  
fill ~14 ~9 ~11 ~15 ~9 ~11 stone 0  
fill ~14 ~9 ~24 ~24 ~9 ~24 stone_brick_stairs 6  
fill ~14 ~9 ~25 ~24 ~9 ~25 stone 0  
fill ~14 ~9 ~26 ~24 ~9 ~26 stone 0  
fill ~14 ~9 ~27 ~24 ~9 ~27 stone 0  
fill ~14 ~9 ~31 ~24 ~9 ~31 stone 0  
fill ~15 ~9 ~10 ~16 ~9 ~10 stone 0  
fill ~15 ~9 ~28 ~16 ~9 ~28 stonebrick 3  
fill ~15 ~9 ~32 ~23 ~9 ~32 stone 0  
fill ~16 ~9 ~9 ~18 ~9 ~9 stone 0  
fill ~16 ~9 ~21 ~22 ~9 ~21 stone 0  
fill ~16 ~9 ~22 ~22 ~9 ~22 stone 0 
setblock ~16 ~9 ~30 stone_button 2  
fill ~16 ~9 ~33 ~22 ~9 ~33 stone 0  
fill ~17 ~9 ~8 ~18 ~9 ~8 stone 0  
fill ~17 ~9 ~19 ~21 ~9 ~19 stone 0  
fill ~17 ~9 ~20 ~21 ~9 ~20 stone 0  
fill ~17 ~9 ~28 ~21 ~9 ~28 stone 0  
fill ~17 ~9 ~29 ~17 ~16 ~29 lit_redstone_lamp 0  
fill ~17 ~9 ~34 ~21 ~9 ~34 stone 0  
fill ~18 ~9 ~18 ~20 ~9 ~18 stone_brick_stairs 6  
fill ~18 ~9 ~29 ~18 ~16 ~29 redstone_block 0  
fill ~18 ~9 ~30 ~20 ~9 ~30 stone 0  
fill ~18 ~9 ~35 ~20 ~9 ~35 stone 0  
fill ~19 ~9 ~29 ~19 ~28 ~29 stone 0  
fill ~20 ~9 ~8 ~21 ~9 ~8 stone 0  
fill ~20 ~9 ~9 ~22 ~9 ~9 stone 0  
fill ~20 ~9 ~29 ~20 ~16 ~29 redstone_block 0  
fill ~21 ~9 ~29 ~21 ~16 ~29 lit_redstone_lamp 0  
fill ~22 ~9 ~10 ~23 ~9 ~10 stone 0  
fill ~22 ~9 ~28 ~23 ~9 ~28 stonebrick 3 
setblock ~22 ~9 ~30 stone_button 1  
fill ~23 ~9 ~11 ~24 ~9 ~11 stone 0  
fill ~14 ~10 ~11 ~15 ~10 ~11 stone 0  
fill ~14 ~10 ~23 ~24 ~10 ~23 stone_brick_stairs 6  
fill ~14 ~10 ~24 ~24 ~10 ~24 stone 0  
fill ~14 ~10 ~25 ~24 ~10 ~25 stone 0  
fill ~14 ~10 ~26 ~24 ~10 ~26 stone 0  
fill ~14 ~10 ~27 ~24 ~10 ~27 stone 0  
fill ~14 ~10 ~31 ~24 ~10 ~31 stone 0  
fill ~15 ~10 ~10 ~16 ~10 ~10 stone 0  
fill ~15 ~10 ~28 ~17 ~10 ~28 stonebrick 3  
fill ~15 ~10 ~32 ~23 ~10 ~32 stone 0  
fill ~16 ~10 ~9 ~18 ~10 ~9 stone 0  
fill ~16 ~10 ~33 ~22 ~10 ~33 stone 0  
fill ~17 ~10 ~8 ~18 ~10 ~8 stone 0  
fill ~17 ~10 ~34 ~21 ~10 ~34 stone 0  
fill ~18 ~10 ~17 ~20 ~10 ~17 stone_brick_stairs 6  
fill ~18 ~10 ~18 ~20 ~10 ~18 stone 0  
fill ~18 ~10 ~19 ~20 ~10 ~19 stone 0  
fill ~18 ~10 ~28 ~20 ~10 ~28 stone 0  
fill ~18 ~10 ~30 ~20 ~10 ~30 stone 0  
fill ~18 ~10 ~35 ~20 ~10 ~35 stone 0  
fill ~20 ~10 ~8 ~21 ~10 ~8 stone 0  
fill ~20 ~10 ~9 ~22 ~10 ~9 stone 0  
fill ~21 ~10 ~28 ~23 ~10 ~28 stonebrick 3  
fill ~22 ~10 ~10 ~23 ~10 ~10 stone 0  
fill ~23 ~10 ~11 ~24 ~10 ~11 stone 0  
fill ~12 ~11 ~39 ~12 ~20 ~39 stone 0  
fill ~14 ~11 ~11 ~15 ~11 ~11 stone 0  
fill ~14 ~11 ~22 ~24 ~11 ~22 stone_brick_stairs 6  
fill ~14 ~11 ~23 ~24 ~11 ~23 stone 0  
fill ~14 ~11 ~24 ~24 ~11 ~24 stone 0  
fill ~14 ~11 ~25 ~24 ~11 ~25 stone 0  
fill ~14 ~11 ~26 ~24 ~11 ~26 stone 0  
fill ~14 ~11 ~31 ~24 ~11 ~31 stone 0  
fill ~15 ~11 ~10 ~16 ~11 ~10 stone 0  
fill ~15 ~11 ~27 ~16 ~11 ~27 stonebrick 3  
fill ~15 ~11 ~32 ~23 ~11 ~32 stone 0  
fill ~16 ~11 ~9 ~18 ~11 ~9 stone 0 
setblock ~16 ~11 ~28 stone_button 2 
setblock ~16 ~11 ~30 stone_button 2  
fill ~16 ~11 ~33 ~22 ~11 ~33 stone 0  
fill ~17 ~11 ~8 ~18 ~11 ~8 stone 0  
fill ~17 ~11 ~27 ~21 ~11 ~27 stone 0  
fill ~17 ~11 ~28 ~17 ~28 ~28 stonebrick 3  
fill ~17 ~11 ~34 ~21 ~11 ~34 stone 0  
fill ~18 ~11 ~17 ~20 ~11 ~17 stone 0  
fill ~18 ~11 ~18 ~20 ~11 ~18 stone 0  
fill ~18 ~11 ~28 ~20 ~11 ~28 stone 0  
fill ~18 ~11 ~30 ~20 ~11 ~30 stone 0  
fill ~18 ~11 ~35 ~20 ~11 ~35 stone 0  
fill ~20 ~11 ~8 ~21 ~11 ~8 stone 0  
fill ~20 ~11 ~9 ~22 ~11 ~9 stone 0  
fill ~21 ~11 ~28 ~21 ~28 ~28 stonebrick 3  
fill ~22 ~11 ~10 ~23 ~11 ~10 stone 0  
fill ~22 ~11 ~27 ~23 ~11 ~27 stonebrick 3 
setblock ~22 ~11 ~28 stone_button 1 
setblock ~22 ~11 ~30 stone_button 1  
fill ~23 ~11 ~11 ~24 ~11 ~11 stone 0  
fill ~11 ~12 ~39 ~11 ~21 ~39 stone 0  
fill ~14 ~12 ~11 ~15 ~12 ~11 stone 0  
fill ~14 ~12 ~22 ~24 ~12 ~22 stone 0  
fill ~14 ~12 ~23 ~24 ~12 ~23 stone 0  
fill ~14 ~12 ~24 ~24 ~12 ~24 stone 0  
fill ~14 ~12 ~25 ~24 ~12 ~25 stone 0  
fill ~14 ~12 ~26 ~24 ~12 ~26 stone 0  
fill ~14 ~12 ~31 ~24 ~12 ~31 stone 0  
fill ~15 ~12 ~10 ~16 ~12 ~10 stone 0  
fill ~15 ~12 ~27 ~16 ~12 ~27 stonebrick 3  
fill ~15 ~12 ~32 ~23 ~12 ~32 stone 0  
fill ~16 ~12 ~9 ~18 ~12 ~9 stone 0  
fill ~16 ~12 ~33 ~22 ~12 ~33 stone 0  
fill ~17 ~12 ~8 ~18 ~12 ~8 stone 0  
fill ~17 ~12 ~27 ~21 ~12 ~27 stone 0  
fill ~17 ~12 ~34 ~21 ~12 ~34 stone 0  
fill ~18 ~12 ~28 ~20 ~12 ~28 stone 0  
fill ~18 ~12 ~30 ~20 ~12 ~30 stone 0  
fill ~18 ~12 ~35 ~20 ~12 ~35 stone 0 
setblock ~19 ~12 ~8 lit_redstone_lamp 0  
fill ~20 ~12 ~8 ~21 ~12 ~8 stone 0  
fill ~20 ~12 ~9 ~22 ~12 ~9 stone 0  
fill ~22 ~12 ~10 ~23 ~12 ~10 stone 0  
fill ~22 ~12 ~27 ~23 ~12 ~27 stonebrick 3  
fill ~23 ~12 ~11 ~24 ~12 ~11 stone 0  
fill ~33 ~12 ~14 ~33 ~18 ~14 stone 0  
fill ~12 ~13 ~40 ~12 ~20 ~40 stone 0  
fill ~13 ~13 ~39 ~13 ~20 ~39 stone 0  
fill ~14 ~13 ~17 ~24 ~13 ~17 stone 0  
fill ~14 ~13 ~18 ~24 ~13 ~18 stone 0  
fill ~14 ~13 ~19 ~24 ~13 ~19 stone 0  
fill ~14 ~13 ~20 ~24 ~13 ~20 stone 0  
fill ~14 ~13 ~21 ~24 ~13 ~21 stone 0  
fill ~14 ~13 ~22 ~24 ~13 ~22 stone 0  
fill ~14 ~13 ~23 ~24 ~13 ~23 stone 0  
fill ~14 ~13 ~24 ~24 ~13 ~24 stone 0  
fill ~14 ~13 ~25 ~24 ~13 ~25 stone 0  
fill ~14 ~13 ~31 ~24 ~13 ~31 stone 0  
fill ~15 ~13 ~16 ~23 ~13 ~16 stone_brick_stairs 6  
fill ~15 ~13 ~26 ~16 ~13 ~26 stonebrick 3  
fill ~15 ~13 ~32 ~23 ~13 ~32 stone 0 
setblock ~16 ~13 ~28 stone_button 2 
setblock ~16 ~13 ~30 stone_button 2  
fill ~16 ~13 ~33 ~22 ~13 ~33 stone 0  
fill ~17 ~13 ~26 ~21 ~13 ~26 stone 0  
fill ~17 ~13 ~27 ~17 ~28 ~27 stonebrick 3  
fill ~17 ~13 ~34 ~21 ~13 ~34 stone 0  
fill ~18 ~13 ~27 ~20 ~13 ~27 stone 0  
fill ~18 ~13 ~28 ~20 ~13 ~28 stone 0  
fill ~18 ~13 ~30 ~20 ~13 ~30 stone 0  
fill ~18 ~13 ~35 ~20 ~13 ~35 stone 0  
fill ~21 ~13 ~27 ~21 ~28 ~27 stonebrick 3  
fill ~22 ~13 ~26 ~23 ~13 ~26 stonebrick 3 
setblock ~22 ~13 ~28 stone_button 1 
setblock ~22 ~13 ~30 stone_button 1  
fill ~34 ~13 ~14 ~34 ~24 ~14 stone 0  
fill ~12 ~14 ~38 ~12 ~21 ~38 stone 0  
fill ~14 ~14 ~17 ~24 ~14 ~17 stone 0  
fill ~14 ~14 ~18 ~24 ~14 ~18 stone 0  
fill ~14 ~14 ~19 ~24 ~14 ~19 stone 0  
fill ~14 ~14 ~20 ~24 ~14 ~20 stone 0  
fill ~14 ~14 ~21 ~24 ~14 ~21 stone 0  
fill ~14 ~14 ~22 ~24 ~14 ~22 stone 0  
fill ~14 ~14 ~23 ~24 ~14 ~23 stone 0  
fill ~14 ~14 ~24 ~24 ~14 ~24 stone 0  
fill ~14 ~14 ~30 ~24 ~14 ~30 stone 0  
fill ~14 ~14 ~31 ~24 ~14 ~31 stone 0  
fill ~15 ~14 ~15 ~23 ~14 ~15 stone_brick_stairs 6  
fill ~15 ~14 ~16 ~23 ~14 ~16 stone 0  
fill ~15 ~14 ~25 ~16 ~14 ~25 stonebrick 3  
fill ~15 ~14 ~32 ~23 ~14 ~32 stone 0  
fill ~16 ~14 ~33 ~22 ~14 ~33 stone 0  
fill ~17 ~14 ~25 ~21 ~14 ~25 stone 0  
fill ~17 ~14 ~26 ~17 ~28 ~26 stonebrick 3  
fill ~17 ~14 ~34 ~21 ~14 ~34 stone 0  
fill ~18 ~14 ~26 ~20 ~14 ~26 stone 0  
fill ~18 ~14 ~27 ~20 ~14 ~27 stone 0  
fill ~18 ~14 ~28 ~20 ~14 ~28 stone 0  
fill ~18 ~14 ~35 ~20 ~14 ~35 stone 0  
fill ~21 ~14 ~26 ~21 ~28 ~26 stonebrick 3  
fill ~22 ~14 ~25 ~23 ~14 ~25 stonebrick 3  
fill ~34 ~14 ~15 ~34 ~21 ~15 stone 0  
fill ~11 ~15 ~38 ~11 ~20 ~38 stone 0  
fill ~14 ~15 ~17 ~24 ~15 ~17 stone 0  
fill ~14 ~15 ~18 ~24 ~15 ~18 stone 0  
fill ~14 ~15 ~19 ~24 ~15 ~19 stone 0  
fill ~14 ~15 ~20 ~24 ~15 ~20 stone 0  
fill ~14 ~15 ~21 ~24 ~15 ~21 stone 0  
fill ~14 ~15 ~22 ~15 ~15 ~22 stone 0  
fill ~14 ~15 ~24 ~15 ~15 ~24 stone 0  
fill ~14 ~15 ~30 ~24 ~15 ~30 stone 0  
fill ~14 ~15 ~31 ~24 ~15 ~31 stone 0  
fill ~15 ~15 ~14 ~23 ~15 ~14 stone_brick_stairs 6  
fill ~15 ~15 ~15 ~23 ~15 ~15 stone 0  
fill ~15 ~15 ~16 ~23 ~15 ~16 stone 0  
fill ~15 ~15 ~23 ~16 ~15 ~23 stonebrick 3  
fill ~15 ~15 ~32 ~23 ~15 ~32 stone 0 
setblock ~16 ~15 ~22 stonebrick 3 
setblock ~16 ~15 ~24 stonebrick 3 
setblock ~16 ~15 ~28 stone_button 2  
fill ~16 ~15 ~33 ~22 ~15 ~33 stone 0  
fill ~17 ~15 ~22 ~21 ~15 ~22 stone 0  
fill ~17 ~15 ~23 ~21 ~15 ~23 stone 0  
fill ~17 ~15 ~24 ~21 ~15 ~24 stone 0  
fill ~17 ~15 ~25 ~17 ~27 ~25 stonebrick 3  
fill ~17 ~15 ~34 ~21 ~15 ~34 stone 0  
fill ~18 ~15 ~25 ~20 ~15 ~25 stone 0  
fill ~18 ~15 ~26 ~20 ~15 ~26 stone 0  
fill ~18 ~15 ~27 ~20 ~15 ~27 stone 0  
fill ~18 ~15 ~28 ~20 ~15 ~28 stone 0  
fill ~18 ~15 ~35 ~20 ~15 ~35 stone 0  
fill ~21 ~15 ~25 ~21 ~27 ~25 stonebrick 3  
fill ~22 ~15 ~22 ~22 ~15 ~24 stonebrick 3 
setblock ~22 ~15 ~28 stone_button 1  
fill ~23 ~15 ~22 ~24 ~15 ~22 stone 0 
setblock ~23 ~15 ~23 stonebrick 3  
fill ~23 ~15 ~24 ~24 ~15 ~24 stone 0  
fill ~33 ~15 ~15 ~33 ~17 ~15 stone 0  
fill ~5 ~16 ~15 ~5 ~31 ~15 stone 0  
fill ~6 ~16 ~34 ~7 ~16 ~34 stone 0 
setblock ~7 ~16 ~35 stone 0  
fill ~14 ~16 ~17 ~24 ~16 ~17 stone 0  
fill ~14 ~16 ~18 ~24 ~16 ~18 stone 0  
fill ~14 ~16 ~19 ~24 ~16 ~19 stone 0  
fill ~14 ~16 ~20 ~24 ~16 ~20 stone 0  
fill ~14 ~16 ~21 ~14 ~19 ~21 stone 0  
fill ~14 ~16 ~25 ~14 ~17 ~25 stone 0  
fill ~14 ~16 ~30 ~24 ~16 ~30 stone 0  
fill ~14 ~16 ~31 ~24 ~16 ~31 stone 0  
fill ~15 ~16 ~14 ~23 ~16 ~14 stone 0  
fill ~15 ~16 ~15 ~23 ~16 ~15 stone 0  
fill ~15 ~16 ~16 ~23 ~16 ~16 stone 0  
fill ~15 ~16 ~21 ~16 ~16 ~21 stonebrick 3  
fill ~15 ~16 ~22 ~15 ~19 ~22 stone 0  
fill ~15 ~16 ~24 ~15 ~18 ~24 stone 0  
fill ~15 ~16 ~32 ~23 ~16 ~32 stone 0  
fill ~16 ~16 ~13 ~22 ~16 ~13 stone_brick_stairs 6  
fill ~16 ~16 ~22 ~16 ~24 ~22 stone_button 2  
fill ~16 ~16 ~24 ~16 ~26 ~24 stone_button 2  
fill ~16 ~16 ~33 ~22 ~16 ~33 stone 0  
fill ~17 ~16 ~21 ~21 ~16 ~21 stone 0  
fill ~17 ~16 ~22 ~17 ~24 ~22 stonebrick 3  
fill ~17 ~16 ~23 ~17 ~25 ~23 lit_redstone_lamp 0  
fill ~17 ~16 ~24 ~17 ~26 ~24 stonebrick 3  
fill ~17 ~16 ~34 ~21 ~16 ~34 stone 0  
fill ~18 ~16 ~22 ~20 ~16 ~22 stone 0  
fill ~18 ~16 ~23 ~18 ~25 ~23 redstone_block 0  
fill ~18 ~16 ~24 ~20 ~16 ~24 stone 0  
fill ~18 ~16 ~25 ~20 ~16 ~25 stone 0  
fill ~18 ~16 ~26 ~20 ~16 ~26 stone 0  
fill ~18 ~16 ~27 ~20 ~16 ~27 stone 0  
fill ~18 ~16 ~28 ~20 ~16 ~28 stone 0  
fill ~18 ~16 ~35 ~20 ~16 ~35 stone 0  
fill ~19 ~16 ~23 ~19 ~28 ~23 stone 0  
fill ~20 ~16 ~23 ~20 ~25 ~23 redstone_block 0  
fill ~21 ~16 ~22 ~21 ~24 ~22 stonebrick 3  
fill ~21 ~16 ~23 ~21 ~25 ~23 lit_redstone_lamp 0  
fill ~21 ~16 ~24 ~21 ~26 ~24 stonebrick 3  
fill ~22 ~16 ~21 ~23 ~16 ~21 stonebrick 3  
fill ~22 ~16 ~22 ~22 ~24 ~22 stone_button 1  
fill ~22 ~16 ~24 ~22 ~26 ~24 stone_button 1  
fill ~23 ~16 ~22 ~23 ~19 ~22 stone 0  
fill ~23 ~16 ~24 ~23 ~18 ~24 stone 0  
fill ~24 ~16 ~21 ~24 ~19 ~21 stone 0  
fill ~24 ~16 ~25 ~24 ~17 ~25 stone 0  
fill ~32 ~16 ~15 ~32 ~19 ~15 stone 0  
fill ~4 ~17 ~15 ~4 ~34 ~15 stone 0  
fill ~7 ~17 ~34 ~7 ~18 ~34 stone 0  
fill ~14 ~17 ~17 ~14 ~178 ~17 stone 0  
fill ~14 ~17 ~29 ~24 ~17 ~29 stone 0  
fill ~14 ~17 ~30 ~24 ~17 ~30 stone 0  
fill ~14 ~17 ~31 ~24 ~17 ~31 stone 0  
fill ~15 ~17 ~14 ~17 ~17 ~14 stone 0  
fill ~15 ~17 ~15 ~16 ~17 ~15 stone 0  
fill ~15 ~17 ~16 ~15 ~69 ~16 stone 0  
fill ~15 ~17 ~17 ~15 ~17 ~20 stonebrick 3  
fill ~15 ~17 ~32 ~23 ~17 ~32 stone 0  
fill ~16 ~17 ~13 ~22 ~17 ~13 stone 0 
setblock ~16 ~17 ~16 stonebrick 3  
fill ~16 ~17 ~17 ~22 ~17 ~17 stone 0  
fill ~16 ~17 ~18 ~22 ~17 ~18 stone 0  
fill ~16 ~17 ~19 ~16 ~17 ~20 stonebrick 3  
fill ~16 ~17 ~33 ~22 ~17 ~33 stone 0  
fill ~17 ~17 ~12 ~21 ~17 ~12 stone_brick_stairs 6 
setblock ~17 ~17 ~15 stonebrick 3  
fill ~17 ~17 ~16 ~21 ~17 ~16 stone 0  
fill ~17 ~17 ~19 ~21 ~17 ~19 stone 0  
fill ~17 ~17 ~20 ~21 ~17 ~20 stone 0  
fill ~17 ~17 ~21 ~17 ~22 ~21 stonebrick 3  
fill ~17 ~17 ~34 ~21 ~17 ~34 stone 0  
fill ~18 ~17 ~14 ~20 ~17 ~14 stonebrick 3  
fill ~18 ~17 ~15 ~20 ~17 ~15 stone 0  
fill ~18 ~17 ~21 ~20 ~17 ~21 stone 0  
fill ~18 ~17 ~22 ~20 ~17 ~22 stone 0  
fill ~18 ~17 ~24 ~20 ~17 ~24 stone 0  
fill ~18 ~17 ~25 ~20 ~17 ~25 stone 0  
fill ~18 ~17 ~26 ~20 ~17 ~26 stone 0  
fill ~18 ~17 ~27 ~20 ~17 ~27 stone 0  
fill ~18 ~17 ~28 ~20 ~17 ~28 stone 0  
fill ~18 ~17 ~35 ~20 ~17 ~35 stone 0  
fill ~21 ~17 ~14 ~23 ~17 ~14 stone 0 
setblock ~21 ~17 ~15 stonebrick 3  
fill ~21 ~17 ~21 ~21 ~22 ~21 stonebrick 3  
fill ~22 ~17 ~15 ~23 ~17 ~15 stone 0 
setblock ~22 ~17 ~16 stonebrick 3  
fill ~22 ~17 ~19 ~23 ~17 ~19 stonebrick 3  
fill ~22 ~17 ~20 ~23 ~17 ~20 stonebrick 3  
fill ~23 ~17 ~16 ~23 ~178 ~16 stone 0  
fill ~23 ~17 ~17 ~23 ~17 ~20 stonebrick 3  
fill ~24 ~17 ~17 ~24 ~178 ~17 stone 0  
fill ~31 ~17 ~15 ~31 ~21 ~15 stone 0  
fill ~32 ~17 ~16 ~32 ~22 ~16 stone 0  
fill ~32 ~17 ~30 ~32 ~20 ~30 stone 0 
setblock ~3 ~18 ~15 stone 0  
fill ~4 ~18 ~14 ~5 ~18 ~14 stone 0  
fill ~4 ~18 ~16 ~4 ~37 ~16 stone 0  
fill ~4 ~18 ~22 ~4 ~19 ~22 stone 0  
fill ~14 ~18 ~26 ~14 ~19 ~26 stone 0  
fill ~14 ~18 ~29 ~24 ~18 ~29 stone 0  
fill ~14 ~18 ~30 ~24 ~18 ~30 stone 0  
fill ~14 ~18 ~31 ~24 ~18 ~31 stone 0  
fill ~15 ~18 ~14 ~23 ~18 ~14 stone 0  
fill ~15 ~18 ~15 ~23 ~18 ~15 stone 0  
fill ~15 ~18 ~17 ~24 ~18 ~17 stone 0  
fill ~15 ~18 ~18 ~16 ~18 ~18 stonebrick 3  
fill ~16 ~18 ~13 ~22 ~18 ~13 stone 0  
fill ~16 ~18 ~16 ~23 ~18 ~16 stone 0  
fill ~16 ~18 ~19 ~16 ~18 ~20 stone_button 2  
fill ~16 ~18 ~32 ~22 ~18 ~32 stone 0  
fill ~16 ~18 ~33 ~22 ~18 ~33 stone 0  
fill ~17 ~18 ~12 ~21 ~18 ~12 stone 0  
fill ~17 ~18 ~18 ~21 ~18 ~18 stone 0  
fill ~17 ~18 ~19 ~17 ~18 ~22 stonebrick 3  
fill ~17 ~18 ~34 ~21 ~18 ~34 stone 0  
fill ~18 ~18 ~11 ~20 ~18 ~11 stone_brick_stairs 6  
fill ~18 ~18 ~19 ~20 ~18 ~19 stone 0  
fill ~18 ~18 ~20 ~20 ~18 ~20 stone 0  
fill ~18 ~18 ~21 ~20 ~18 ~21 stone 0  
fill ~18 ~18 ~22 ~20 ~18 ~22 stone 0  
fill ~18 ~18 ~24 ~20 ~18 ~24 stone 0  
fill ~18 ~18 ~25 ~20 ~18 ~25 stone 0  
fill ~18 ~18 ~26 ~20 ~18 ~26 stone 0  
fill ~18 ~18 ~27 ~20 ~18 ~27 stone 0  
fill ~18 ~18 ~28 ~20 ~18 ~28 stone 0  
fill ~18 ~18 ~35 ~20 ~18 ~35 stone 0  
fill ~21 ~18 ~19 ~21 ~18 ~22 stonebrick 3  
fill ~22 ~18 ~18 ~23 ~18 ~18 stonebrick 3  
fill ~22 ~18 ~19 ~22 ~18 ~20 stone_button 1  
fill ~24 ~18 ~26 ~24 ~19 ~26 stone 0  
fill ~31 ~18 ~31 ~32 ~18 ~31 stone 0  
fill ~33 ~18 ~13 ~33 ~21 ~13 stone 0  
fill ~33 ~18 ~15 ~33 ~20 ~15 diamond_block 0  
fill ~34 ~18 ~35 ~34 ~19 ~35 stone 0  
fill ~3 ~19 ~14 ~4 ~19 ~14 stone 0  
fill ~3 ~19 ~15 ~3 ~20 ~15 diamond_block 0  
fill ~3 ~19 ~16 ~3 ~22 ~16 stone 0  
fill ~4 ~19 ~13 ~4 ~21 ~13 stone 0 
setblock ~5 ~19 ~14 diamond_block 0  
fill ~5 ~19 ~16 ~5 ~32 ~16 stone 0  
fill ~6 ~19 ~14 ~6 ~28 ~14 stone 0  
fill ~6 ~19 ~15 ~6 ~20 ~15 stone 0  
fill ~14 ~19 ~18 ~24 ~19 ~18 stone 0  
fill ~14 ~19 ~29 ~24 ~19 ~29 stone 0  
fill ~14 ~19 ~30 ~24 ~19 ~30 stone 0  
fill ~15 ~19 ~14 ~23 ~19 ~14 stone 0  
fill ~15 ~19 ~15 ~23 ~19 ~15 stone 0  
fill ~15 ~19 ~17 ~24 ~19 ~17 stone 0  
fill ~15 ~19 ~19 ~16 ~19 ~19 stonebrick 3  
fill ~15 ~19 ~25 ~15 ~21 ~25 stone 0  
fill ~15 ~19 ~31 ~23 ~19 ~31 stone 0  
fill ~16 ~19 ~13 ~22 ~19 ~13 stone 0  
fill ~16 ~19 ~16 ~23 ~19 ~16 stone 0  
fill ~16 ~19 ~32 ~22 ~19 ~32 stone 0  
fill ~16 ~19 ~33 ~22 ~19 ~33 stone 0  
fill ~17 ~19 ~12 ~21 ~19 ~12 stone 0  
fill ~17 ~19 ~19 ~21 ~19 ~19 stone 0  
fill ~17 ~19 ~20 ~17 ~20 ~20 stonebrick 3  
fill ~17 ~19 ~34 ~21 ~19 ~34 stone 0  
fill ~18 ~19 ~11 ~18 ~30 ~11 stone 0  
fill ~18 ~19 ~20 ~20 ~19 ~20 stone 0  
fill ~18 ~19 ~21 ~20 ~19 ~21 stone 0  
fill ~18 ~19 ~22 ~20 ~19 ~22 stone 0  
fill ~18 ~19 ~24 ~20 ~19 ~24 stone 0  
fill ~18 ~19 ~25 ~20 ~19 ~25 stone 0  
fill ~18 ~19 ~26 ~20 ~19 ~26 stone 0  
fill ~18 ~19 ~27 ~20 ~19 ~27 stone 0  
fill ~18 ~19 ~28 ~20 ~19 ~28 stone 0  
fill ~18 ~19 ~35 ~20 ~19 ~35 stone 0  
fill ~19 ~19 ~10 ~19 ~30 ~10 stone_button 4  
fill ~19 ~19 ~11 ~19 ~30 ~11 wool 1  
fill ~20 ~19 ~11 ~20 ~30 ~11 stone 0  
fill ~21 ~19 ~20 ~21 ~20 ~20 stonebrick 3  
fill ~22 ~19 ~19 ~23 ~19 ~19 stonebrick 3  
fill ~23 ~19 ~25 ~23 ~21 ~25 stone 0  
fill ~33 ~19 ~14 ~33 ~20 ~14 diamond_block 0  
fill ~3 ~20 ~14 ~7 ~20 ~14 stone 0  
fill ~4 ~20 ~17 ~5 ~20 ~17 stone 0  
fill ~5 ~20 ~13 ~5 ~21 ~13 stone 0 
setblock ~6 ~20 ~16 stone 0 
setblock ~7 ~20 ~15 diamond_block 0 
setblock ~8 ~20 ~15 stone 0  
fill ~14 ~20 ~18 ~24 ~20 ~18 stone 0  
fill ~14 ~20 ~22 ~14 ~22 ~22 stone 0  
fill ~14 ~20 ~27 ~14 ~26 ~27 stone 0  
fill ~14 ~20 ~29 ~24 ~20 ~29 stone 0  
fill ~14 ~20 ~30 ~24 ~20 ~30 stone 0  
fill ~15 ~20 ~14 ~23 ~20 ~14 stone 0  
fill ~15 ~20 ~15 ~23 ~20 ~15 stone 0  
fill ~15 ~20 ~17 ~24 ~20 ~17 stone 0  
fill ~15 ~20 ~19 ~16 ~20 ~19 stonebrick 3  
fill ~15 ~20 ~23 ~15 ~22 ~23 stone 0  
fill ~15 ~20 ~31 ~23 ~20 ~31 stone 0  
fill ~16 ~20 ~13 ~22 ~20 ~13 stone 0  
fill ~16 ~20 ~16 ~23 ~20 ~16 stone 0  
fill ~16 ~20 ~32 ~22 ~20 ~32 stone 0  
fill ~16 ~20 ~33 ~22 ~20 ~33 stone 0  
fill ~17 ~20 ~12 ~21 ~20 ~12 stone 0  
fill ~17 ~20 ~19 ~21 ~20 ~19 stone 0  
fill ~17 ~20 ~34 ~21 ~20 ~34 stone 0  
fill ~18 ~20 ~2 ~18 ~24 ~2 stone 0  
fill ~18 ~20 ~20 ~20 ~20 ~20 stone 0  
fill ~18 ~20 ~21 ~20 ~20 ~21 stone 0  
fill ~18 ~20 ~22 ~20 ~20 ~22 stone 0  
fill ~18 ~20 ~24 ~20 ~20 ~24 stone 0  
fill ~18 ~20 ~25 ~20 ~20 ~25 stone 0  
fill ~18 ~20 ~26 ~20 ~20 ~26 stone 0  
fill ~18 ~20 ~27 ~20 ~20 ~27 stone 0  
fill ~18 ~20 ~28 ~20 ~20 ~28 stone 0  
fill ~18 ~20 ~35 ~20 ~20 ~35 stone 0  
fill ~22 ~20 ~19 ~23 ~20 ~19 stonebrick 3  
fill ~23 ~20 ~23 ~23 ~22 ~23 stone 0  
fill ~24 ~20 ~22 ~24 ~22 ~22 stone 0  
fill ~24 ~20 ~27 ~24 ~26 ~27 stone 0  
fill ~32 ~20 ~15 ~32 ~21 ~15 diamond_block 0  
fill ~3 ~21 ~15 ~3 ~34 ~15 stone 0  
fill ~4 ~21 ~14 ~6 ~21 ~14 stone 0  
fill ~4 ~21 ~17 ~4 ~22 ~17 stone 0  
fill ~6 ~21 ~15 ~6 ~23 ~15 diamond_block 0  
fill ~7 ~21 ~15 ~7 ~25 ~15 stone 0 
setblock ~12 ~21 ~39 diamond_block 0  
fill ~14 ~21 ~18 ~24 ~21 ~18 stone 0  
fill ~14 ~21 ~19 ~24 ~21 ~19 stone 0  
fill ~14 ~21 ~29 ~24 ~21 ~29 stone 0  
fill ~14 ~21 ~30 ~24 ~21 ~30 stone 0  
fill ~15 ~21 ~14 ~23 ~21 ~14 stone 0  
fill ~15 ~21 ~15 ~23 ~21 ~15 stone 0  
fill ~15 ~21 ~17 ~24 ~21 ~17 stone 0  
fill ~15 ~21 ~20 ~16 ~21 ~20 stonebrick 3  
fill ~15 ~21 ~31 ~23 ~21 ~31 stone 0  
fill ~16 ~21 ~13 ~22 ~21 ~13 stone 0  
fill ~16 ~21 ~16 ~23 ~21 ~16 stone 0  
fill ~16 ~21 ~32 ~22 ~21 ~32 stone 0  
fill ~16 ~21 ~33 ~22 ~21 ~33 stone 0  
fill ~17 ~21 ~12 ~21 ~21 ~12 stone 0  
fill ~17 ~21 ~20 ~21 ~21 ~20 stone 0  
fill ~17 ~21 ~34 ~21 ~21 ~34 stone 0  
fill ~18 ~21 ~21 ~20 ~21 ~21 stone 0  
fill ~18 ~21 ~22 ~20 ~21 ~22 stone 0  
fill ~18 ~21 ~24 ~20 ~21 ~24 stone 0  
fill ~18 ~21 ~25 ~20 ~21 ~25 stone 0  
fill ~18 ~21 ~26 ~20 ~21 ~26 stone 0  
fill ~18 ~21 ~27 ~20 ~21 ~27 stone 0  
fill ~18 ~21 ~28 ~20 ~21 ~28 stone 0  
fill ~18 ~21 ~35 ~20 ~21 ~35 stone 0  
fill ~22 ~21 ~20 ~23 ~21 ~20 stonebrick 3  
fill ~33 ~21 ~14 ~33 ~24 ~14 stone 0  
fill ~33 ~21 ~15 ~33 ~24 ~15 stone 0  
fill ~34 ~21 ~13 ~34 ~23 ~13 stone 0  
fill ~4 ~22 ~14 ~6 ~22 ~14 stone 0  
fill ~14 ~22 ~18 ~24 ~22 ~18 stone 0  
fill ~14 ~22 ~19 ~24 ~22 ~19 stone 0  
fill ~14 ~22 ~29 ~24 ~22 ~29 stone 0  
fill ~14 ~22 ~30 ~24 ~22 ~30 stone 0  
fill ~15 ~22 ~14 ~23 ~22 ~14 stone 0  
fill ~15 ~22 ~15 ~23 ~22 ~15 stone 0  
fill ~15 ~22 ~17 ~24 ~22 ~17 stone 0  
fill ~15 ~22 ~20 ~16 ~22 ~20 stonebrick 3  
fill ~15 ~22 ~26 ~15 ~24 ~26 stone 0  
fill ~15 ~22 ~31 ~23 ~22 ~31 stone 0  
fill ~16 ~22 ~13 ~22 ~22 ~13 stone 0  
fill ~16 ~22 ~16 ~23 ~22 ~16 stone 0  
fill ~16 ~22 ~32 ~22 ~22 ~32 stone 0  
fill ~16 ~22 ~33 ~22 ~22 ~33 stone 0  
fill ~17 ~22 ~12 ~21 ~22 ~12 stone 0  
fill ~17 ~22 ~20 ~21 ~22 ~20 stone 0  
fill ~17 ~22 ~34 ~21 ~22 ~34 stone 0  
fill ~18 ~22 ~3 ~18 ~26 ~3 stone 0  
fill ~18 ~22 ~21 ~20 ~22 ~21 stone 0  
fill ~18 ~22 ~22 ~20 ~22 ~22 stone 0  
fill ~18 ~22 ~24 ~20 ~22 ~24 stone 0  
fill ~18 ~22 ~25 ~20 ~22 ~25 stone 0  
fill ~18 ~22 ~26 ~20 ~22 ~26 stone 0  
fill ~18 ~22 ~27 ~20 ~22 ~27 stone 0  
fill ~18 ~22 ~28 ~20 ~22 ~28 stone 0  
fill ~18 ~22 ~35 ~20 ~22 ~35 stone 0  
fill ~19 ~22 ~2 ~19 ~23 ~2 stone 0  
fill ~22 ~22 ~20 ~23 ~22 ~20 stonebrick 3  
fill ~23 ~22 ~26 ~23 ~24 ~26 stone 0  
fill ~32 ~22 ~15 ~32 ~23 ~15 stone 0  
fill ~4 ~23 ~14 ~6 ~23 ~14 stone 0  
fill ~8 ~23 ~18 ~9 ~23 ~18 stone 0 
setblock ~9 ~23 ~19 stone 0  
fill ~14 ~23 ~18 ~24 ~23 ~18 stone 0  
fill ~14 ~23 ~19 ~24 ~23 ~19 stone 0  
fill ~14 ~23 ~20 ~24 ~23 ~20 stone 0  
fill ~14 ~23 ~23 ~14 ~24 ~23 stone 0  
fill ~14 ~23 ~29 ~24 ~23 ~29 stone 0  
fill ~14 ~23 ~30 ~24 ~23 ~30 stone 0  
fill ~15 ~23 ~14 ~23 ~23 ~14 stone 0  
fill ~15 ~23 ~15 ~23 ~23 ~15 stone 0  
fill ~15 ~23 ~17 ~24 ~23 ~17 stone 0  
fill ~15 ~23 ~21 ~16 ~23 ~21 stonebrick 3 
setblock ~15 ~23 ~24 stone 0  
fill ~15 ~23 ~31 ~23 ~23 ~31 stone 0  
fill ~16 ~23 ~13 ~22 ~23 ~13 stone 0  
fill ~16 ~23 ~16 ~23 ~23 ~16 stone 0  
fill ~16 ~23 ~32 ~22 ~23 ~32 stone 0  
fill ~16 ~23 ~33 ~22 ~23 ~33 stone 0  
fill ~17 ~23 ~12 ~21 ~23 ~12 stone 0  
fill ~17 ~23 ~21 ~21 ~23 ~21 stone 0  
fill ~17 ~23 ~34 ~21 ~23 ~34 stone 0 
setblock ~18 ~23 ~1 stone 0  
fill ~18 ~23 ~22 ~20 ~23 ~22 stone 0  
fill ~18 ~23 ~24 ~20 ~23 ~24 stone 0  
fill ~18 ~23 ~25 ~20 ~23 ~25 stone 0  
fill ~18 ~23 ~26 ~20 ~23 ~26 stone 0  
fill ~18 ~23 ~27 ~20 ~23 ~27 stone 0  
fill ~18 ~23 ~28 ~20 ~23 ~28 stone 0  
fill ~18 ~23 ~35 ~20 ~23 ~35 stone 0  
fill ~22 ~23 ~21 ~23 ~23 ~21 stonebrick 3 
setblock ~23 ~23 ~24 stone 0  
fill ~24 ~23 ~23 ~24 ~24 ~23 stone 0  
fill ~4 ~24 ~14 ~6 ~24 ~14 stone 0  
fill ~6 ~24 ~15 ~6 ~35 ~15 stone 0  
fill ~8 ~24 ~18 ~9 ~24 ~18 stone 0  
fill ~14 ~24 ~18 ~24 ~24 ~18 stone 0  
fill ~14 ~24 ~19 ~24 ~24 ~19 stone 0  
fill ~14 ~24 ~20 ~24 ~24 ~20 stone 0  
fill ~14 ~24 ~29 ~24 ~24 ~29 stone 0  
fill ~15 ~24 ~14 ~23 ~24 ~14 stone 0  
fill ~15 ~24 ~15 ~23 ~24 ~15 stone 0  
fill ~15 ~24 ~17 ~24 ~24 ~17 stone 0  
fill ~15 ~24 ~21 ~16 ~24 ~21 stonebrick 3 
setblock ~15 ~24 ~25 stone 0  
fill ~15 ~24 ~30 ~23 ~24 ~30 stone 0  
fill ~15 ~24 ~31 ~23 ~24 ~31 stone 0  
fill ~16 ~24 ~13 ~22 ~24 ~13 stone 0  
fill ~16 ~24 ~16 ~23 ~24 ~16 stone 0  
fill ~16 ~24 ~32 ~22 ~24 ~32 stone 0  
fill ~16 ~24 ~33 ~22 ~24 ~33 stone 0  
fill ~17 ~24 ~12 ~21 ~24 ~12 stone 0  
fill ~17 ~24 ~21 ~21 ~24 ~21 stone 0  
fill ~17 ~24 ~34 ~21 ~24 ~34 stone 0  
fill ~18 ~24 ~22 ~20 ~24 ~22 stone 0  
fill ~18 ~24 ~24 ~20 ~24 ~24 stone 0  
fill ~18 ~24 ~25 ~20 ~24 ~25 stone 0  
fill ~18 ~24 ~26 ~20 ~24 ~26 stone 0  
fill ~18 ~24 ~27 ~20 ~24 ~27 stone 0  
fill ~18 ~24 ~28 ~20 ~24 ~28 stone 0  
fill ~18 ~24 ~35 ~20 ~24 ~35 stone 0  
fill ~22 ~24 ~21 ~23 ~24 ~21 stonebrick 3 
setblock ~23 ~24 ~25 stone 0  
fill ~4 ~25 ~14 ~6 ~25 ~14 stone 0  
fill ~9 ~25 ~18 ~9 ~26 ~18 stone 0  
fill ~14 ~25 ~18 ~14 ~27 ~18 quartz_block 1  
fill ~14 ~25 ~19 ~14 ~25 ~18 quartz_block 1  
fill ~14 ~25 ~20 ~24 ~25 ~20 stone 0  
fill ~14 ~25 ~21 ~24 ~25 ~21 stone 0 
setblock ~14 ~25 ~24 stone 0  
fill ~14 ~25 ~29 ~24 ~25 ~29 stone 0  
fill ~15 ~25 ~14 ~23 ~25 ~14 stone 0  
fill ~15 ~25 ~15 ~23 ~25 ~15 stone 0  
fill ~15 ~25 ~17 ~24 ~25 ~17 stone 0  
fill ~15 ~25 ~18 ~23 ~25 ~18 stone 0  
fill ~15 ~25 ~19 ~23 ~25 ~19 stone 0  
fill ~15 ~25 ~22 ~16 ~25 ~22 stonebrick 3  
fill ~15 ~25 ~30 ~23 ~25 ~30 stone 0  
fill ~15 ~25 ~31 ~23 ~25 ~31 stone 0  
fill ~16 ~25 ~13 ~22 ~25 ~13 stone 0  
fill ~16 ~25 ~16 ~23 ~25 ~16 stone 0  
fill ~16 ~25 ~32 ~22 ~25 ~32 stone 0  
fill ~16 ~25 ~33 ~22 ~25 ~33 stone 0  
fill ~17 ~25 ~12 ~21 ~25 ~12 stone 0  
fill ~17 ~25 ~22 ~21 ~25 ~22 stone 0  
fill ~17 ~25 ~34 ~21 ~25 ~34 stone 0  
fill ~18 ~25 ~24 ~20 ~25 ~24 stone 0  
fill ~18 ~25 ~25 ~20 ~25 ~25 stone 0  
fill ~18 ~25 ~26 ~20 ~25 ~26 stone 0  
fill ~18 ~25 ~27 ~20 ~25 ~27 stone 0  
fill ~18 ~25 ~28 ~20 ~25 ~28 stone 0  
fill ~18 ~25 ~35 ~20 ~25 ~35 stone 0  
fill ~22 ~25 ~22 ~23 ~25 ~22 stonebrick 3  
summon minecraft:ender_crystal ~19.5 ~0.0 ~21.5  
fill ~24 ~25 ~18 ~24 ~27 ~18 quartz_block 1  
fill ~24 ~25 ~19 ~24 ~25 ~18 quartz_block 1 
setblock ~24 ~25 ~24 stone 0  
fill ~28 ~25 ~15 ~28 ~30 ~15 stone 0  
fill ~4 ~26 ~14 ~6 ~26 ~14 stone 0  
fill ~14 ~26 ~19 ~14 ~27 ~19 diamond_block 0  
fill ~14 ~26 ~20 ~14 ~27 ~20 quartz_block 1  
fill ~14 ~26 ~21 ~24 ~26 ~21 stone 0  
fill ~14 ~26 ~22 ~24 ~26 ~22 stone 0 
setblock ~14 ~26 ~25 stone 0  
fill ~14 ~26 ~29 ~24 ~26 ~29 stone 0  
fill ~14 ~26 ~30 ~24 ~26 ~30 stone 0  
fill ~15 ~26 ~14 ~23 ~26 ~14 stone 0  
fill ~15 ~26 ~15 ~23 ~26 ~15 stone 0  
fill ~15 ~26 ~17 ~24 ~26 ~17 stone 0  
fill ~15 ~26 ~18 ~23 ~26 ~18 stone 0  
fill ~15 ~26 ~19 ~23 ~26 ~19 stone 0  
fill ~15 ~26 ~20 ~23 ~26 ~20 stone 0  
fill ~15 ~26 ~23 ~16 ~26 ~23 stonebrick 3  
fill ~15 ~26 ~31 ~23 ~26 ~31 stone 0  
fill ~16 ~26 ~13 ~22 ~26 ~13 stone 0  
fill ~16 ~26 ~16 ~23 ~26 ~16 stone 0  
fill ~16 ~26 ~32 ~22 ~26 ~32 stone 0  
fill ~16 ~26 ~33 ~22 ~26 ~33 stone 0  
fill ~17 ~26 ~12 ~21 ~26 ~12 stone 0  
fill ~17 ~26 ~23 ~21 ~26 ~23 stone 0  
fill ~17 ~26 ~34 ~21 ~26 ~34 stone 0  
fill ~18 ~26 ~24 ~20 ~26 ~24 stone 0  
fill ~18 ~26 ~25 ~20 ~26 ~25 stone 0  
fill ~18 ~26 ~26 ~20 ~26 ~26 stone 0  
fill ~18 ~26 ~27 ~20 ~26 ~27 stone 0  
fill ~18 ~26 ~28 ~20 ~26 ~28 stone 0  
fill ~18 ~26 ~35 ~20 ~26 ~35 stone 0  
fill ~22 ~26 ~23 ~23 ~26 ~23 stonebrick 3  
fill ~24 ~26 ~19 ~24 ~27 ~19 diamond_block 0  
fill ~24 ~26 ~20 ~24 ~27 ~20 quartz_block 1 
setblock ~24 ~26 ~25 stone 0 
setblock ~27 ~26 ~15 stone 0  
fill ~28 ~26 ~16 ~28 ~28 ~16 stone 0  
fill ~4 ~27 ~14 ~6 ~27 ~14 stone 0  
fill ~14 ~27 ~21 ~24 ~27 ~21 stone 0  
fill ~14 ~27 ~22 ~24 ~27 ~22 stone 0  
fill ~14 ~27 ~23 ~24 ~27 ~23 stone 0 
setblock ~14 ~27 ~26 stone 0  
fill ~14 ~27 ~29 ~24 ~27 ~29 stone 0  
fill ~14 ~27 ~30 ~24 ~27 ~30 stone 0  
fill ~15 ~27 ~14 ~23 ~27 ~14 stone 0  
fill ~15 ~27 ~15 ~23 ~27 ~15 stone 0  
fill ~15 ~27 ~17 ~24 ~27 ~17 stone 0  
fill ~15 ~27 ~18 ~23 ~27 ~18 stone 0  
fill ~15 ~27 ~19 ~23 ~27 ~19 stone 0  
fill ~15 ~27 ~20 ~23 ~27 ~20 stone 0  
fill ~15 ~27 ~24 ~16 ~27 ~24 stonebrick 3  
fill ~15 ~27 ~31 ~23 ~27 ~31 stone 0  
fill ~16 ~27 ~13 ~22 ~27 ~13 stone 0  
fill ~16 ~27 ~16 ~23 ~27 ~16 stone 0  
fill ~16 ~27 ~32 ~22 ~27 ~32 stone 0  
fill ~16 ~27 ~33 ~22 ~27 ~33 stone 0  
fill ~17 ~27 ~12 ~21 ~27 ~12 stone 0  
fill ~17 ~27 ~24 ~21 ~27 ~24 stone 0  
fill ~17 ~27 ~34 ~21 ~27 ~34 stone 0  
fill ~18 ~27 ~25 ~20 ~27 ~25 stone 0  
fill ~18 ~27 ~26 ~20 ~27 ~26 stone 0  
fill ~18 ~27 ~27 ~20 ~27 ~27 stone 0  
fill ~18 ~27 ~28 ~20 ~27 ~28 stone 0  
fill ~18 ~27 ~35 ~20 ~27 ~35 stone 0  
fill ~22 ~27 ~24 ~23 ~27 ~24 stonebrick 3 
setblock ~24 ~27 ~26 stone 0  
fill ~1 ~28 ~20 ~1 ~30 ~20 stone 0  
fill ~4 ~28 ~14 ~6 ~28 ~14 stone 0  
fill ~14 ~28 ~18 ~24 ~28 ~18 stone 0  
fill ~14 ~28 ~19 ~14 ~29 ~19 quartz_block 1  
fill ~14 ~28 ~20 ~14 ~29 ~20 diamond_block 0  
fill ~14 ~28 ~21 ~14 ~29 ~21 quartz_block 1  
fill ~14 ~28 ~22 ~24 ~28 ~22 stone 0  
fill ~14 ~28 ~23 ~24 ~28 ~23 stone 0  
fill ~14 ~28 ~24 ~24 ~28 ~24 stone 0  
fill ~14 ~28 ~29 ~24 ~28 ~29 stone 0  
fill ~14 ~28 ~30 ~24 ~28 ~30 stone 0  
fill ~15 ~28 ~14 ~23 ~28 ~14 stone 0  
fill ~15 ~28 ~15 ~23 ~28 ~15 stone 0  
fill ~15 ~28 ~17 ~24 ~28 ~17 stone 0  
fill ~15 ~28 ~19 ~23 ~28 ~19 stone 0  
fill ~15 ~28 ~20 ~23 ~28 ~20 stone 0  
fill ~15 ~28 ~21 ~23 ~28 ~21 stone 0  
fill ~15 ~28 ~25 ~15 ~30 ~25 stonebrick 3  
fill ~15 ~28 ~31 ~23 ~28 ~31 stone 0  
fill ~16 ~28 ~13 ~22 ~28 ~13 stone 0  
fill ~16 ~28 ~16 ~23 ~28 ~16 stone 0  
fill ~16 ~28 ~25 ~22 ~28 ~25 stone 0  
fill ~16 ~28 ~26 ~16 ~42 ~26 stonebrick 3  
fill ~16 ~28 ~32 ~22 ~28 ~32 stone 0  
fill ~16 ~28 ~33 ~22 ~28 ~33 stone 0  
fill ~17 ~28 ~12 ~21 ~28 ~12 stone 0  
fill ~17 ~28 ~34 ~21 ~28 ~34 stone 0  
fill ~18 ~28 ~26 ~20 ~28 ~26 stone 0  
fill ~18 ~28 ~27 ~20 ~28 ~27 stone 0  
fill ~18 ~28 ~28 ~20 ~28 ~28 stone 0  
fill ~18 ~28 ~35 ~20 ~28 ~35 stone 0  
fill ~22 ~28 ~26 ~22 ~42 ~26 stonebrick 3  
fill ~23 ~28 ~25 ~23 ~30 ~25 stonebrick 3  
fill ~24 ~28 ~19 ~24 ~29 ~19 quartz_block 1  
fill ~24 ~28 ~20 ~24 ~29 ~20 diamond_block 0  
fill ~24 ~28 ~21 ~24 ~29 ~21 quartz_block 1  
fill ~2 ~29 ~19 ~2 ~30 ~19 stone 0  
fill ~2 ~29 ~20 ~2 ~32 ~20 stone 0  
fill ~4 ~29 ~14 ~5 ~29 ~14 stone 0  
fill ~14 ~29 ~18 ~24 ~29 ~18 stone 0  
fill ~14 ~29 ~22 ~16 ~29 ~22 stone 0  
fill ~14 ~29 ~23 ~16 ~29 ~23 stone 0  
fill ~14 ~29 ~24 ~16 ~29 ~24 stone 0  
fill ~14 ~29 ~29 ~15 ~29 ~29 stone 0  
fill ~14 ~29 ~30 ~24 ~29 ~30 stone 0  
fill ~14 ~29 ~31 ~24 ~29 ~31 stone 0  
fill ~15 ~29 ~14 ~23 ~29 ~14 stone 0  
fill ~15 ~29 ~15 ~23 ~29 ~15 stone 0  
fill ~15 ~29 ~17 ~24 ~29 ~17 stone 0  
fill ~15 ~29 ~19 ~16 ~29 ~19 stone 0  
fill ~15 ~29 ~20 ~16 ~29 ~20 stone 0  
fill ~15 ~29 ~21 ~16 ~29 ~21 stone 0  
fill ~16 ~29 ~13 ~22 ~29 ~13 stone 0  
fill ~16 ~29 ~16 ~23 ~29 ~16 stone 0  
fill ~16 ~29 ~25 ~16 ~30 ~25 stone 0  
fill ~16 ~29 ~27 ~16 ~43 ~27 stonebrick 3  
fill ~16 ~29 ~28 ~16 ~29 ~26 stonebrick 3  
fill ~16 ~29 ~32 ~22 ~29 ~32 stone 0  
fill ~16 ~29 ~33 ~22 ~29 ~33 stone 0  
fill ~17 ~29 ~12 ~21 ~29 ~12 stone 0  
fill ~17 ~29 ~23 ~17 ~66 ~23 redstone_block 0  
fill ~17 ~29 ~24 ~17 ~66 ~24 redstone_block 0  
fill ~17 ~29 ~34 ~21 ~29 ~34 stone 0  
fill ~18 ~29 ~23 ~18 ~66 ~23 stone 0  
fill ~18 ~29 ~24 ~18 ~66 ~24 stone 0  
fill ~18 ~29 ~35 ~20 ~29 ~35 stone 0  
fill ~20 ~29 ~23 ~20 ~66 ~23 stone 0  
fill ~20 ~29 ~24 ~20 ~66 ~24 stone 0  
fill ~21 ~29 ~23 ~21 ~66 ~23 redstone_block 0  
fill ~21 ~29 ~24 ~21 ~66 ~24 redstone_block 0  
fill ~22 ~29 ~19 ~23 ~29 ~19 stone 0  
fill ~22 ~29 ~20 ~23 ~29 ~20 stone 0  
fill ~22 ~29 ~21 ~23 ~29 ~21 stone 0  
fill ~22 ~29 ~22 ~24 ~29 ~22 stone 0  
fill ~22 ~29 ~23 ~24 ~29 ~23 stone 0  
fill ~22 ~29 ~24 ~24 ~29 ~24 stone 0  
fill ~22 ~29 ~25 ~22 ~30 ~25 stone 0  
fill ~22 ~29 ~27 ~22 ~43 ~27 stonebrick 3  
fill ~22 ~29 ~28 ~22 ~29 ~26 stonebrick 3  
fill ~23 ~29 ~29 ~24 ~29 ~29 stone 0  
fill ~5 ~30 ~14 ~5 ~31 ~14 stone 0  
fill ~14 ~30 ~18 ~24 ~30 ~18 stone 0  
fill ~14 ~30 ~19 ~16 ~30 ~19 stone 0  
fill ~14 ~30 ~20 ~14 ~31 ~20 quartz_block 1  
fill ~14 ~30 ~21 ~14 ~31 ~21 diamond_block 0  
fill ~14 ~30 ~22 ~14 ~31 ~22 quartz_block 1  
fill ~14 ~30 ~23 ~16 ~30 ~23 stone 0  
fill ~14 ~30 ~24 ~16 ~30 ~24 stone 0  
fill ~14 ~30 ~29 ~15 ~30 ~29 stone 0  
fill ~14 ~30 ~30 ~24 ~30 ~30 stone 0  
fill ~14 ~30 ~31 ~24 ~30 ~31 stone 0  
fill ~15 ~30 ~14 ~23 ~30 ~14 stone 0  
fill ~15 ~30 ~15 ~23 ~30 ~15 stone 0  
fill ~15 ~30 ~17 ~24 ~30 ~17 stone 0  
fill ~15 ~30 ~20 ~16 ~30 ~20 stone 0  
fill ~15 ~30 ~21 ~16 ~30 ~21 stone 0  
fill ~15 ~30 ~22 ~16 ~30 ~22 stone 0  
fill ~15 ~30 ~32 ~23 ~30 ~32 stone 0  
fill ~16 ~30 ~13 ~22 ~30 ~13 stone 0  
fill ~16 ~30 ~16 ~23 ~30 ~16 stone 0  
fill ~16 ~30 ~28 ~16 ~32 ~28 glowstone 0  
fill ~16 ~30 ~33 ~22 ~30 ~33 stone 0  
fill ~17 ~30 ~12 ~21 ~30 ~12 stone 0  
fill ~17 ~30 ~34 ~21 ~30 ~34 stone 0  
fill ~18 ~30 ~35 ~20 ~30 ~35 stone 0  
fill ~22 ~30 ~19 ~24 ~30 ~19 stone 0  
fill ~22 ~30 ~20 ~23 ~30 ~20 stone 0  
fill ~22 ~30 ~21 ~23 ~30 ~21 stone 0  
fill ~22 ~30 ~22 ~23 ~30 ~22 stone 0  
fill ~22 ~30 ~23 ~24 ~30 ~23 stone 0  
fill ~22 ~30 ~24 ~24 ~30 ~24 stone 0  
fill ~22 ~30 ~28 ~22 ~32 ~28 glowstone 0  
fill ~23 ~30 ~29 ~24 ~30 ~29 stone 0  
fill ~24 ~30 ~20 ~24 ~31 ~20 quartz_block 1  
fill ~24 ~30 ~21 ~24 ~31 ~21 diamond_block 0  
fill ~24 ~30 ~22 ~24 ~31 ~22 quartz_block 1  
fill ~14 ~31 ~18 ~24 ~31 ~18 stone 0  
fill ~14 ~31 ~19 ~16 ~31 ~19 stone 0  
fill ~14 ~31 ~23 ~16 ~31 ~23 stone 0  
fill ~14 ~31 ~29 ~15 ~31 ~29 stone 0  
fill ~14 ~31 ~30 ~24 ~31 ~30 stone 0  
fill ~14 ~31 ~31 ~24 ~31 ~31 stone 0 
setblock ~15 ~31 ~14 stone_brick_stairs 2  
fill ~15 ~31 ~15 ~23 ~31 ~15 stone 0  
fill ~15 ~31 ~17 ~24 ~31 ~17 stone 0  
fill ~15 ~31 ~20 ~16 ~31 ~20 stone 0  
fill ~15 ~31 ~21 ~16 ~31 ~21 stone 0  
fill ~15 ~31 ~22 ~16 ~31 ~22 stone 0 
setblock ~15 ~31 ~24 stonebrick 3  
fill ~15 ~31 ~32 ~23 ~31 ~32 stone 0 
setblock ~16 ~31 ~13 stone_brick_stairs 2  
fill ~16 ~31 ~14 ~22 ~31 ~14 stone 0  
fill ~16 ~31 ~16 ~23 ~31 ~16 stone 0 
setblock ~16 ~31 ~24 stone 0  
fill ~16 ~31 ~25 ~16 ~41 ~25 stonebrick 3  
fill ~16 ~31 ~33 ~22 ~31 ~33 stone 0 
setblock ~17 ~31 ~12 stone_brick_stairs 2  
fill ~17 ~31 ~13 ~21 ~31 ~13 stone 0  
fill ~17 ~31 ~34 ~21 ~31 ~34 stone 0  
fill ~18 ~31 ~11 ~20 ~31 ~11 stone_brick_stairs 2  
fill ~18 ~31 ~12 ~20 ~31 ~12 stone 0  
fill ~18 ~31 ~35 ~20 ~31 ~35 stone 0 
setblock ~21 ~31 ~12 stone_brick_stairs 2 
setblock ~22 ~31 ~13 stone_brick_stairs 2  
fill ~22 ~31 ~19 ~24 ~31 ~19 stone 0  
fill ~22 ~31 ~20 ~23 ~31 ~20 stone 0  
fill ~22 ~31 ~21 ~23 ~31 ~21 stone 0  
fill ~22 ~31 ~22 ~23 ~31 ~22 stone 0  
fill ~22 ~31 ~23 ~24 ~31 ~23 stone 0  
fill ~22 ~31 ~24 ~22 ~28 ~24 stone 0  
fill ~22 ~31 ~25 ~22 ~41 ~25 stonebrick 3 
setblock ~23 ~31 ~14 stone_brick_stairs 2 
setblock ~23 ~31 ~24 stonebrick 3  
fill ~23 ~31 ~29 ~24 ~31 ~29 stone 0  
fill ~5 ~32 ~15 ~5 ~33 ~15 diamond_block 0  
fill ~14 ~32 ~18 ~24 ~32 ~18 stone 0  
fill ~14 ~32 ~19 ~16 ~32 ~19 stone 0  
fill ~14 ~32 ~20 ~16 ~32 ~20 stone 0  
fill ~14 ~32 ~21 ~14 ~33 ~21 quartz_block 1  
fill ~14 ~32 ~22 ~16 ~32 ~22 stone 0  
fill ~14 ~32 ~29 ~15 ~32 ~29 stone 0 
setblock ~15 ~32 ~15 stone_brick_stairs 2  
fill ~15 ~32 ~17 ~24 ~32 ~17 stone 0  
fill ~15 ~32 ~21 ~16 ~32 ~21 stone 0  
fill ~15 ~32 ~23 ~15 ~33 ~23 stonebrick 3  
fill ~15 ~32 ~30 ~16 ~32 ~30 stonebrick 3  
fill ~15 ~32 ~31 ~16 ~32 ~31 stonebrick 3 
setblock ~16 ~32 ~14 stone_brick_stairs 2  
fill ~16 ~32 ~15 ~22 ~32 ~15 stone 0  
fill ~16 ~32 ~16 ~23 ~32 ~16 stone 0  
fill ~16 ~32 ~23 ~16 ~33 ~23 stone 0  
fill ~16 ~32 ~24 ~16 ~66 ~24 lit_redstone_lamp 0  
fill ~16 ~32 ~32 ~17 ~32 ~32 stonebrick 3 
setblock ~17 ~32 ~13 stone_brick_stairs 2  
fill ~17 ~32 ~14 ~21 ~32 ~14 stone 0  
fill ~17 ~32 ~30 ~21 ~32 ~30 stone 0  
fill ~17 ~32 ~31 ~21 ~32 ~31 stone 0  
fill ~17 ~32 ~33 ~18 ~32 ~33 stonebrick 3  
fill ~18 ~32 ~12 ~20 ~32 ~12 stone_brick_stairs 2  
fill ~18 ~32 ~13 ~20 ~32 ~13 stone 0  
fill ~18 ~32 ~32 ~20 ~32 ~32 stone 0  
fill ~18 ~32 ~34 ~20 ~32 ~34 stonebrick 3  
fill ~19 ~32 ~33 ~19 ~115 ~33 stone 0  
fill ~20 ~32 ~33 ~21 ~32 ~33 stonebrick 3 
setblock ~21 ~32 ~13 stone_brick_stairs 2  
fill ~21 ~32 ~32 ~22 ~32 ~32 stonebrick 3 
setblock ~22 ~32 ~14 stone_brick_stairs 2  
fill ~22 ~32 ~19 ~24 ~32 ~19 stone 0  
fill ~22 ~32 ~20 ~24 ~32 ~20 stone 0  
fill ~22 ~32 ~21 ~23 ~32 ~21 stone 0  
fill ~22 ~32 ~22 ~24 ~32 ~22 stone 0  
fill ~22 ~32 ~23 ~22 ~33 ~23 stone 0  
fill ~22 ~32 ~24 ~22 ~66 ~24 lit_redstone_lamp 0  
fill ~22 ~32 ~30 ~23 ~32 ~30 stonebrick 3  
fill ~22 ~32 ~31 ~23 ~32 ~31 stonebrick 3 
setblock ~23 ~32 ~15 stone_brick_stairs 2  
fill ~23 ~32 ~23 ~23 ~33 ~23 stonebrick 3  
fill ~23 ~32 ~29 ~24 ~32 ~29 stone 0  
fill ~24 ~32 ~21 ~24 ~33 ~21 quartz_block 1  
fill ~14 ~33 ~18 ~24 ~33 ~18 stone 0  
fill ~14 ~33 ~19 ~16 ~33 ~19 stone 0  
fill ~14 ~33 ~20 ~16 ~33 ~20 stone 0  
fill ~14 ~33 ~22 ~16 ~33 ~22 stone 0  
fill ~14 ~33 ~28 ~15 ~33 ~28 stone 0  
fill ~14 ~33 ~29 ~15 ~33 ~29 stone 0  
fill ~14 ~33 ~31 ~24 ~33 ~31 stone 0  
fill ~15 ~33 ~17 ~24 ~33 ~17 stone 0  
fill ~15 ~33 ~21 ~16 ~33 ~21 stone 0  
fill ~15 ~33 ~30 ~15 ~34 ~30 stonebrick 3  
fill ~15 ~33 ~32 ~23 ~33 ~32 stone 0  
fill ~16 ~33 ~15 ~22 ~33 ~15 stone 0  
fill ~16 ~33 ~16 ~23 ~33 ~16 stone 0  
fill ~16 ~33 ~28 ~16 ~42 ~28 stonebrick 3  
fill ~16 ~33 ~30 ~22 ~33 ~30 stone 0  
fill ~16 ~33 ~33 ~22 ~33 ~33 stone 0  
fill ~17 ~33 ~14 ~21 ~33 ~14 stone 0  
fill ~17 ~33 ~34 ~21 ~33 ~34 stone 0  
fill ~18 ~33 ~13 ~20 ~33 ~13 stone 0  
fill ~18 ~33 ~35 ~20 ~33 ~35 stone 0  
fill ~22 ~33 ~19 ~24 ~33 ~19 stone 0  
fill ~22 ~33 ~20 ~24 ~33 ~20 stone 0  
fill ~22 ~33 ~21 ~23 ~33 ~21 stone 0  
fill ~22 ~33 ~22 ~24 ~33 ~22 stone 0  
fill ~22 ~33 ~28 ~22 ~42 ~28 stonebrick 3  
fill ~23 ~33 ~28 ~24 ~33 ~28 stone 0  
fill ~23 ~33 ~29 ~24 ~33 ~29 stone 0  
fill ~23 ~33 ~30 ~23 ~34 ~30 stonebrick 3  
fill ~5 ~34 ~15 ~5 ~38 ~15 stone 0  
fill ~14 ~34 ~18 ~24 ~34 ~18 stone 0  
fill ~14 ~34 ~19 ~16 ~34 ~19 stone 0  
fill ~14 ~34 ~20 ~16 ~34 ~20 stone 0  
fill ~14 ~34 ~21 ~16 ~34 ~21 stone 0  
fill ~14 ~34 ~31 ~24 ~34 ~31 stone 0  
fill ~15 ~34 ~17 ~24 ~34 ~17 stone 0  
fill ~15 ~34 ~22 ~15 ~35 ~22 stonebrick 3  
fill ~15 ~34 ~28 ~15 ~41 ~28 stonebrick 3  
fill ~15 ~34 ~29 ~16 ~34 ~29 stonebrick 3  
fill ~15 ~34 ~32 ~23 ~34 ~32 stone 0  
fill ~16 ~34 ~15 ~22 ~34 ~15 stone 0  
fill ~16 ~34 ~16 ~23 ~34 ~16 stone 0  
fill ~16 ~34 ~22 ~16 ~35 ~22 stone 0  
fill ~16 ~34 ~23 ~16 ~64 ~23 lit_redstone_lamp 0 
setblock ~16 ~34 ~30 stonebrick 3  
fill ~16 ~34 ~33 ~22 ~34 ~33 stone 0  
fill ~17 ~34 ~14 ~21 ~34 ~14 stone 0  
fill ~17 ~34 ~30 ~21 ~34 ~30 stone 0  
fill ~17 ~34 ~34 ~21 ~34 ~34 stone 0  
fill ~18 ~34 ~13 ~20 ~34 ~13 stone 0  
fill ~18 ~34 ~35 ~20 ~34 ~35 stone 0  
fill ~22 ~34 ~19 ~24 ~34 ~19 stone 0  
fill ~22 ~34 ~20 ~24 ~34 ~20 stone 0  
fill ~22 ~34 ~21 ~24 ~34 ~21 stone 0  
fill ~22 ~34 ~22 ~22 ~35 ~22 stone 0  
fill ~22 ~34 ~23 ~22 ~64 ~23 lit_redstone_lamp 0  
fill ~22 ~34 ~29 ~23 ~34 ~29 stonebrick 3  
fill ~22 ~34 ~30 ~22 ~34 ~25 stonebrick 3  
fill ~23 ~34 ~22 ~23 ~35 ~22 stonebrick 3  
fill ~23 ~34 ~28 ~23 ~41 ~28 stonebrick 3  
fill ~4 ~35 ~15 ~4 ~36 ~15 diamond_block 0  
fill ~14 ~35 ~18 ~24 ~35 ~18 stone 0  
fill ~14 ~35 ~19 ~16 ~35 ~19 stone 0  
fill ~14 ~35 ~20 ~16 ~35 ~20 stone 0  
fill ~14 ~35 ~21 ~16 ~35 ~21 stone 0  
fill ~14 ~35 ~29 ~15 ~35 ~29 stone 0  
fill ~14 ~35 ~30 ~24 ~35 ~30 stone 0  
fill ~14 ~35 ~31 ~24 ~35 ~31 stone 0  
fill ~15 ~35 ~17 ~24 ~35 ~17 stone 0  
fill ~15 ~35 ~32 ~23 ~35 ~32 stone 0  
fill ~16 ~35 ~15 ~22 ~35 ~15 stone 0  
fill ~16 ~35 ~16 ~23 ~35 ~16 stone 0  
fill ~16 ~35 ~33 ~22 ~35 ~33 stone 0  
fill ~17 ~35 ~14 ~21 ~35 ~14 stone 0  
fill ~17 ~35 ~34 ~21 ~35 ~34 stone 0  
fill ~18 ~35 ~13 ~20 ~35 ~13 stone 0  
fill ~18 ~35 ~35 ~20 ~35 ~35 stone 0  
fill ~22 ~35 ~19 ~24 ~35 ~19 stone 0  
fill ~22 ~35 ~20 ~24 ~35 ~20 stone 0  
fill ~22 ~35 ~21 ~24 ~35 ~21 stone 0  
fill ~23 ~35 ~29 ~24 ~35 ~29 stone 0  
fill ~14 ~36 ~18 ~24 ~36 ~18 stone 0  
fill ~14 ~36 ~19 ~16 ~36 ~19 stone 0  
fill ~14 ~36 ~20 ~16 ~36 ~20 stone 0  
fill ~14 ~36 ~29 ~15 ~36 ~29 stone 0  
fill ~14 ~36 ~30 ~24 ~36 ~30 stone 0  
fill ~14 ~36 ~31 ~24 ~36 ~31 stone 0  
fill ~15 ~36 ~17 ~24 ~36 ~17 stone 0  
fill ~15 ~36 ~21 ~15 ~37 ~21 stonebrick 3  
fill ~15 ~36 ~32 ~23 ~36 ~32 stone 0  
fill ~16 ~36 ~15 ~22 ~36 ~15 stone 0  
fill ~16 ~36 ~16 ~23 ~36 ~16 stone 0  
fill ~16 ~36 ~21 ~16 ~37 ~21 stone 0  
fill ~16 ~36 ~22 ~16 ~49 ~22 stonebrick 3  
fill ~16 ~36 ~33 ~22 ~36 ~33 stone 0  
fill ~17 ~36 ~14 ~21 ~36 ~14 stone 0  
fill ~17 ~36 ~34 ~21 ~36 ~34 stone 0  
fill ~18 ~36 ~13 ~20 ~36 ~13 stone 0  
fill ~18 ~36 ~35 ~20 ~36 ~35 stone 0  
fill ~22 ~36 ~19 ~24 ~36 ~19 stone 0  
fill ~22 ~36 ~20 ~24 ~36 ~20 stone 0  
fill ~22 ~36 ~21 ~22 ~37 ~21 stone 0  
fill ~22 ~36 ~22 ~22 ~49 ~22 stonebrick 3  
fill ~23 ~36 ~21 ~23 ~37 ~21 stonebrick 3  
fill ~23 ~36 ~29 ~24 ~36 ~29 stone 0  
fill ~31 ~36 ~34 ~32 ~36 ~34 stone 0  
fill ~4 ~37 ~15 ~4 ~40 ~15 stone 0  
fill ~14 ~37 ~18 ~24 ~37 ~18 stone 0  
fill ~14 ~37 ~19 ~16 ~37 ~19 stone 0  
fill ~14 ~37 ~20 ~16 ~37 ~20 stone 0  
fill ~14 ~37 ~29 ~15 ~37 ~29 stone 0  
fill ~14 ~37 ~30 ~24 ~37 ~30 stone 0  
fill ~14 ~37 ~31 ~24 ~37 ~31 stone 0  
fill ~15 ~37 ~17 ~24 ~37 ~17 stone 0  
fill ~15 ~37 ~32 ~23 ~37 ~32 stone 0  
fill ~16 ~37 ~15 ~22 ~37 ~15 stone 0  
fill ~16 ~37 ~16 ~23 ~37 ~16 stone 0  
fill ~16 ~37 ~33 ~22 ~37 ~33 stone 0  
fill ~17 ~37 ~14 ~21 ~37 ~14 stone 0  
fill ~17 ~37 ~34 ~21 ~37 ~34 stone 0  
fill ~18 ~37 ~13 ~20 ~37 ~13 stone 0  
fill ~18 ~37 ~35 ~20 ~37 ~35 stone 0  
fill ~22 ~37 ~19 ~24 ~37 ~19 stone 0  
fill ~22 ~37 ~20 ~24 ~37 ~20 stone 0  
fill ~23 ~37 ~29 ~24 ~37 ~29 stone 0  
fill ~30 ~37 ~35 ~32 ~37 ~35 stone 0  
fill ~31 ~37 ~34 ~32 ~37 ~34 stone 0  
fill ~14 ~38 ~18 ~24 ~38 ~18 stone 0  
fill ~14 ~38 ~19 ~16 ~38 ~19 stone 0  
fill ~14 ~38 ~29 ~15 ~38 ~29 stone 0  
fill ~14 ~38 ~30 ~24 ~38 ~30 stone 0  
fill ~14 ~38 ~31 ~24 ~38 ~31 stone 0  
fill ~15 ~38 ~17 ~24 ~38 ~17 stone 0  
fill ~15 ~38 ~20 ~15 ~41 ~20 stonebrick 3  
fill ~15 ~38 ~21 ~15 ~41 ~21 stone_button 2  
fill ~15 ~38 ~32 ~23 ~38 ~32 stone 0  
fill ~16 ~38 ~15 ~22 ~38 ~15 stone 0  
fill ~16 ~38 ~16 ~23 ~38 ~16 stone 0  
fill ~16 ~38 ~20 ~16 ~62 ~20 stone 0  
fill ~16 ~38 ~21 ~16 ~41 ~21 wool 1  
fill ~16 ~38 ~33 ~22 ~38 ~33 stone 0  
fill ~17 ~38 ~14 ~21 ~38 ~14 stone 0  
fill ~17 ~38 ~34 ~21 ~38 ~34 stone 0  
fill ~18 ~38 ~13 ~20 ~38 ~13 stone 0  
fill ~18 ~38 ~35 ~20 ~38 ~35 stone 0  
fill ~22 ~38 ~19 ~24 ~38 ~19 stone 0  
fill ~22 ~38 ~20 ~22 ~62 ~20 stone 0  
fill ~22 ~38 ~21 ~22 ~41 ~21 wool 1  
fill ~23 ~38 ~20 ~23 ~41 ~20 stonebrick 3  
fill ~23 ~38 ~21 ~23 ~41 ~21 stone_button 1  
fill ~23 ~38 ~29 ~24 ~38 ~29 stone 0  
fill ~30 ~38 ~35 ~31 ~38 ~35 stone 0  
fill ~30 ~38 ~36 ~32 ~38 ~36 stone 0  
fill ~31 ~38 ~34 ~32 ~38 ~34 stone 0 
setblock ~32 ~38 ~35 diamond_block 0  
fill ~14 ~39 ~18 ~24 ~39 ~18 stone 0  
fill ~14 ~39 ~19 ~16 ~39 ~19 stone 0  
fill ~14 ~39 ~29 ~15 ~39 ~29 stone 0  
fill ~14 ~39 ~30 ~24 ~39 ~30 stone 0  
fill ~14 ~39 ~31 ~24 ~39 ~31 stone 0  
fill ~15 ~39 ~17 ~24 ~39 ~17 stone 0  
fill ~15 ~39 ~32 ~23 ~39 ~32 stone 0  
fill ~16 ~39 ~15 ~22 ~39 ~15 stone 0  
fill ~16 ~39 ~16 ~23 ~39 ~16 stone 0  
fill ~16 ~39 ~33 ~22 ~39 ~33 stone 0  
fill ~17 ~39 ~14 ~21 ~39 ~14 stone 0  
fill ~17 ~39 ~34 ~21 ~39 ~34 stone 0  
fill ~18 ~39 ~13 ~20 ~39 ~13 stone 0  
fill ~18 ~39 ~35 ~20 ~39 ~35 stone 0  
fill ~22 ~39 ~19 ~24 ~39 ~19 stone 0  
fill ~23 ~39 ~29 ~24 ~39 ~29 stone 0  
fill ~30 ~39 ~36 ~32 ~39 ~36 stone 0  
fill ~30 ~39 ~37 ~31 ~39 ~37 stone 0  
fill ~31 ~39 ~35 ~32 ~39 ~35 stone 0  
fill ~14 ~40 ~18 ~24 ~40 ~18 stone 0  
fill ~14 ~40 ~19 ~16 ~40 ~19 stone 0  
fill ~14 ~40 ~29 ~15 ~40 ~29 stone 0  
fill ~14 ~40 ~30 ~24 ~40 ~30 stone 0  
fill ~14 ~40 ~31 ~24 ~40 ~31 stone 0  
fill ~15 ~40 ~17 ~24 ~40 ~17 stone 0  
fill ~15 ~40 ~32 ~23 ~40 ~32 stone 0  
fill ~16 ~40 ~15 ~22 ~40 ~15 stone 0  
fill ~16 ~40 ~16 ~23 ~40 ~16 stone 0  
fill ~16 ~40 ~33 ~22 ~40 ~33 stone 0  
fill ~17 ~40 ~14 ~21 ~40 ~14 stone 0  
fill ~17 ~40 ~34 ~21 ~40 ~34 stone 0  
fill ~18 ~40 ~13 ~20 ~40 ~13 stone 0  
fill ~18 ~40 ~35 ~20 ~40 ~35 stone 0  
fill ~22 ~40 ~19 ~24 ~40 ~19 stone 0  
fill ~23 ~40 ~29 ~24 ~40 ~29 stone 0  
fill ~30 ~40 ~37 ~31 ~40 ~37 stone 0  
fill ~31 ~40 ~35 ~32 ~40 ~35 stone 0  
fill ~31 ~40 ~36 ~31 ~42 ~36 diamond_block 0  
fill ~32 ~40 ~36 ~32 ~47 ~36 stone 0  
fill ~14 ~41 ~18 ~24 ~41 ~18 stone 0  
fill ~14 ~41 ~19 ~24 ~41 ~19 stone 0  
fill ~14 ~41 ~29 ~24 ~41 ~29 stone 0  
fill ~14 ~41 ~30 ~24 ~41 ~30 stone 0  
fill ~14 ~41 ~31 ~24 ~41 ~31 stone 0  
fill ~15 ~41 ~17 ~24 ~41 ~17 stone 0  
fill ~15 ~41 ~32 ~23 ~41 ~32 stone 0  
fill ~16 ~41 ~15 ~22 ~41 ~15 stone 0  
fill ~16 ~41 ~16 ~23 ~41 ~16 stone 0  
fill ~16 ~41 ~33 ~22 ~41 ~33 stone 0  
fill ~17 ~41 ~14 ~21 ~41 ~14 stone 0  
fill ~17 ~41 ~20 ~22 ~41 ~20 stone 0  
fill ~17 ~41 ~21 ~21 ~41 ~21 stone 0  
fill ~17 ~41 ~22 ~21 ~41 ~22 stone 0  
fill ~17 ~41 ~26 ~21 ~41 ~26 stone 0  
fill ~17 ~41 ~27 ~21 ~41 ~27 stone 0  
fill ~17 ~41 ~28 ~21 ~41 ~28 stone 0  
fill ~17 ~41 ~34 ~21 ~41 ~34 stone 0  
fill ~18 ~41 ~13 ~20 ~41 ~13 stone 0  
fill ~18 ~41 ~25 ~20 ~41 ~25 stone 0  
fill ~18 ~41 ~35 ~20 ~41 ~35 stone 0  
fill ~19 ~41 ~23 ~19 ~43 ~23 stone 0  
fill ~19 ~41 ~24 ~19 ~43 ~24 stone 0  
fill ~30 ~41 ~37 ~31 ~41 ~37 stone 0  
fill ~31 ~41 ~35 ~32 ~41 ~35 stone 0  
fill ~14 ~42 ~18 ~24 ~42 ~18 stone 0  
fill ~14 ~42 ~19 ~24 ~42 ~19 stone 0  
fill ~14 ~42 ~20 ~24 ~42 ~20 stone 0  
fill ~14 ~42 ~21 ~24 ~42 ~21 stone 0  
fill ~14 ~42 ~22 ~14 ~42 ~31 stone 0  
fill ~15 ~42 ~17 ~24 ~42 ~17 stone 0  
fill ~15 ~42 ~27 ~15 ~42 ~32 stone 0  
fill ~16 ~42 ~15 ~22 ~42 ~15 stone 0  
fill ~16 ~42 ~16 ~23 ~42 ~16 stone 0 
setblock ~16 ~42 ~25 glowstone 0  
fill ~16 ~42 ~29 ~24 ~42 ~29 stone 0  
fill ~16 ~42 ~30 ~24 ~42 ~30 stone 0  
fill ~16 ~42 ~31 ~24 ~42 ~31 stone 0  
fill ~16 ~42 ~32 ~23 ~42 ~32 stone 0  
fill ~16 ~42 ~33 ~22 ~42 ~33 stone 0  
fill ~17 ~42 ~14 ~21 ~42 ~14 stone 0  
fill ~17 ~42 ~22 ~21 ~42 ~22 stone 0  
fill ~17 ~42 ~25 ~21 ~42 ~25 stone 0  
fill ~17 ~42 ~26 ~21 ~42 ~26 stone 0  
fill ~17 ~42 ~27 ~21 ~42 ~27 stone 0  
fill ~17 ~42 ~28 ~21 ~42 ~28 stone 0  
fill ~17 ~42 ~34 ~21 ~42 ~34 stone 0  
fill ~18 ~42 ~13 ~20 ~42 ~13 stone 0  
fill ~18 ~42 ~35 ~20 ~42 ~35 stone 0 
setblock ~22 ~42 ~25 glowstone 0  
fill ~23 ~42 ~27 ~24 ~42 ~27 stone 0  
fill ~23 ~42 ~28 ~24 ~42 ~28 stone 0  
fill ~24 ~42 ~22 ~24 ~42 ~31 stone 0  
fill ~30 ~42 ~37 ~31 ~42 ~37 stone 0  
fill ~31 ~42 ~35 ~32 ~42 ~35 stone 0  
fill ~14 ~43 ~18 ~24 ~43 ~18 stone 0  
fill ~14 ~43 ~19 ~24 ~43 ~19 stone 0  
fill ~14 ~43 ~30 ~24 ~43 ~30 stone 0  
fill ~14 ~43 ~31 ~24 ~43 ~31 stone 0  
fill ~15 ~43 ~17 ~24 ~43 ~17 stone 0  
fill ~15 ~43 ~20 ~15 ~45 ~20 stonebrick 3  
fill ~15 ~43 ~21 ~15 ~45 ~21 stone_button 2 
setblock ~15 ~43 ~27 lever 2  
fill ~15 ~43 ~28 ~15 ~45 ~28 stone_button 2  
fill ~15 ~43 ~29 ~16 ~43 ~29 stonebrick 3  
fill ~15 ~43 ~32 ~23 ~43 ~32 stone 0  
fill ~16 ~43 ~15 ~22 ~43 ~15 stone 0  
fill ~16 ~43 ~16 ~23 ~43 ~16 stone 0  
fill ~16 ~43 ~21 ~16 ~45 ~21 wool 1  
fill ~16 ~43 ~25 ~16 ~49 ~25 stonebrick 3 
setblock ~16 ~43 ~26 glowstone 0  
fill ~16 ~43 ~28 ~16 ~45 ~28 wool 1  
fill ~16 ~43 ~33 ~22 ~43 ~33 stone 0  
fill ~17 ~43 ~14 ~21 ~43 ~14 stone 0  
fill ~17 ~43 ~20 ~22 ~43 ~20 stone 0  
fill ~17 ~43 ~21 ~21 ~43 ~21 stone 0  
fill ~17 ~43 ~22 ~21 ~43 ~22 stone 0  
fill ~17 ~43 ~25 ~21 ~43 ~25 stone 0  
fill ~17 ~43 ~26 ~21 ~43 ~26 stone 0  
fill ~17 ~43 ~27 ~21 ~43 ~27 stone 0  
fill ~17 ~43 ~28 ~21 ~43 ~28 stone 0  
fill ~17 ~43 ~29 ~21 ~43 ~29 stone 0  
fill ~17 ~43 ~34 ~21 ~43 ~34 stone 0  
fill ~18 ~43 ~13 ~20 ~43 ~13 stone 0  
fill ~18 ~43 ~35 ~20 ~43 ~35 stone 0  
fill ~22 ~43 ~21 ~22 ~45 ~21 wool 1 
setblock ~22 ~43 ~25 stonebrick 3 
setblock ~22 ~43 ~26 glowstone 0  
fill ~22 ~43 ~28 ~22 ~45 ~28 wool 1  
fill ~22 ~43 ~29 ~23 ~43 ~29 stonebrick 3  
fill ~23 ~43 ~20 ~23 ~45 ~20 stonebrick 3  
fill ~23 ~43 ~21 ~23 ~45 ~21 stone_button 1 
setblock ~23 ~43 ~27 lever 1  
fill ~23 ~43 ~28 ~23 ~45 ~28 stone_button 1  
fill ~26 ~43 ~9 ~26 ~49 ~9 stone 0  
fill ~30 ~43 ~37 ~31 ~43 ~37 stone 0  
fill ~31 ~43 ~35 ~32 ~43 ~35 stone 0  
fill ~31 ~43 ~36 ~31 ~47 ~36 stone 0  
fill ~14 ~44 ~18 ~15 ~44 ~18 stone 0  
fill ~14 ~44 ~19 ~16 ~44 ~19 stone 0  
fill ~15 ~44 ~27 ~23 ~44 ~27 stone 0  
fill ~15 ~44 ~29 ~16 ~44 ~29 stonebrick 3  
fill ~15 ~44 ~30 ~16 ~44 ~30 stonebrick 3  
fill ~15 ~44 ~31 ~16 ~44 ~31 stonebrick 3  
fill ~16 ~44 ~15 ~16 ~68 ~15 stone 0  
fill ~16 ~44 ~26 ~16 ~47 ~26 stonebrick 3  
fill ~16 ~44 ~32 ~17 ~44 ~32 stonebrick 3  
fill ~17 ~44 ~14 ~17 ~73 ~14 stone 0  
fill ~17 ~44 ~26 ~21 ~44 ~26 stone 0  
fill ~17 ~44 ~28 ~21 ~44 ~28 stone 0  
fill ~17 ~44 ~29 ~21 ~44 ~29 stone 0  
fill ~17 ~44 ~30 ~21 ~44 ~30 stone 0  
fill ~17 ~44 ~31 ~21 ~44 ~31 stone 0  
fill ~17 ~44 ~33 ~18 ~44 ~33 stonebrick 3  
fill ~18 ~44 ~13 ~20 ~44 ~13 stone 0  
fill ~18 ~44 ~32 ~20 ~44 ~32 stone 0  
fill ~18 ~44 ~34 ~20 ~44 ~34 stonebrick 3  
fill ~20 ~44 ~33 ~21 ~44 ~33 stonebrick 3  
fill ~21 ~44 ~14 ~21 ~178 ~14 stone 0  
fill ~21 ~44 ~32 ~22 ~44 ~32 stonebrick 3  
fill ~22 ~44 ~15 ~22 ~178 ~15 stone 0  
fill ~22 ~44 ~19 ~24 ~44 ~19 stone 0 
setblock ~22 ~44 ~25 diamond_block 0  
fill ~22 ~44 ~26 ~22 ~47 ~26 stonebrick 3  
fill ~22 ~44 ~29 ~23 ~44 ~29 stonebrick 3  
fill ~22 ~44 ~30 ~23 ~44 ~30 stonebrick 3  
fill ~22 ~44 ~31 ~23 ~44 ~31 stonebrick 3  
fill ~23 ~44 ~18 ~24 ~44 ~18 stone 0  
fill ~25 ~44 ~9 ~25 ~48 ~9 stone 0  
fill ~26 ~44 ~8 ~26 ~49 ~8 stone 0  
fill ~27 ~44 ~9 ~27 ~49 ~9 stone 0  
fill ~30 ~44 ~37 ~31 ~44 ~37 stone 0  
fill ~31 ~44 ~35 ~32 ~44 ~35 stone 0  
fill ~14 ~45 ~18 ~15 ~45 ~18 stone 0  
fill ~14 ~45 ~19 ~16 ~45 ~19 stone 0 
setblock ~15 ~45 ~27 lever 10  
fill ~15 ~45 ~29 ~16 ~45 ~29 stonebrick 3  
fill ~15 ~45 ~30 ~16 ~45 ~30 stonebrick 3  
fill ~15 ~45 ~31 ~16 ~45 ~31 stonebrick 3 
setblock ~16 ~45 ~27 stonebrick 3  
fill ~16 ~45 ~32 ~17 ~45 ~32 stonebrick 3  
fill ~17 ~45 ~26 ~21 ~45 ~26 stone 0  
fill ~17 ~45 ~27 ~21 ~45 ~27 stone 0  
fill ~17 ~45 ~28 ~21 ~45 ~28 stone 0  
fill ~17 ~45 ~29 ~21 ~45 ~29 stone 0  
fill ~17 ~45 ~30 ~21 ~45 ~30 stone 0  
fill ~17 ~45 ~31 ~21 ~45 ~31 stone 0  
fill ~17 ~45 ~33 ~18 ~45 ~33 stonebrick 3  
fill ~18 ~45 ~13 ~20 ~45 ~13 stone 0  
fill ~18 ~45 ~32 ~20 ~45 ~32 stone 0  
fill ~18 ~45 ~34 ~20 ~45 ~34 stonebrick 3  
fill ~20 ~45 ~33 ~21 ~45 ~33 stonebrick 3  
fill ~21 ~45 ~32 ~22 ~45 ~32 stonebrick 3  
fill ~22 ~45 ~19 ~24 ~45 ~19 stone 0  
fill ~22 ~45 ~25 ~22 ~49 ~25 stonebrick 3 
setblock ~22 ~45 ~27 stonebrick 3  
fill ~22 ~45 ~29 ~23 ~45 ~29 stonebrick 3  
fill ~22 ~45 ~30 ~23 ~45 ~30 stonebrick 3  
fill ~22 ~45 ~31 ~23 ~45 ~31 stonebrick 3  
fill ~23 ~45 ~18 ~24 ~45 ~18 stone 0 
setblock ~23 ~45 ~27 lever 9  
fill ~30 ~45 ~37 ~31 ~45 ~37 stone 0  
fill ~31 ~45 ~35 ~32 ~45 ~35 stone 0  
fill ~14 ~46 ~18 ~15 ~46 ~18 stone 0  
fill ~14 ~46 ~19 ~16 ~46 ~19 stone 0  
fill ~14 ~46 ~20 ~16 ~46 ~20 stone 0  
fill ~14 ~46 ~21 ~16 ~46 ~21 stone 0  
fill ~14 ~46 ~22 ~14 ~46 ~32 stone 0  
fill ~15 ~46 ~27 ~24 ~46 ~27 stone 0  
fill ~15 ~46 ~28 ~24 ~46 ~28 stone 0  
fill ~15 ~46 ~29 ~24 ~46 ~29 stone 0  
fill ~15 ~46 ~30 ~24 ~46 ~30 stone 0  
fill ~15 ~46 ~31 ~24 ~46 ~31 stone 0  
fill ~15 ~46 ~32 ~24 ~46 ~32 stone 0  
fill ~15 ~46 ~33 ~23 ~46 ~33 stone 0  
fill ~16 ~46 ~34 ~21 ~46 ~34 stone 0  
fill ~17 ~46 ~26 ~21 ~46 ~26 stone 0  
fill ~17 ~46 ~35 ~19 ~46 ~35 stone 0  
fill ~18 ~46 ~13 ~20 ~46 ~13 stone 0  
fill ~18 ~46 ~36 ~18 ~70 ~36 stone 0  
fill ~22 ~46 ~19 ~24 ~46 ~19 stone 0  
fill ~22 ~46 ~21 ~24 ~46 ~21 stone 0  
fill ~23 ~46 ~18 ~24 ~46 ~18 stone 0  
fill ~23 ~46 ~20 ~24 ~46 ~20 stone 0  
fill ~24 ~46 ~22 ~24 ~46 ~32 stone 0  
fill ~30 ~46 ~37 ~31 ~46 ~37 stone 0 
setblock ~32 ~46 ~35 stone 0  
fill ~14 ~47 ~18 ~15 ~47 ~18 stone 0  
fill ~14 ~47 ~19 ~16 ~47 ~19 stone 0  
fill ~14 ~47 ~28 ~24 ~47 ~28 stone 0  
fill ~14 ~47 ~29 ~24 ~47 ~29 stone 0  
fill ~14 ~47 ~30 ~24 ~47 ~30 stone 0  
fill ~14 ~47 ~31 ~24 ~47 ~31 stone 0  
fill ~14 ~47 ~32 ~24 ~47 ~32 stone 0  
fill ~15 ~47 ~20 ~15 ~49 ~20 stonebrick 3  
fill ~15 ~47 ~21 ~15 ~49 ~21 stone_button 2 
setblock ~15 ~47 ~27 stonebrick 3  
fill ~15 ~47 ~33 ~23 ~47 ~33 stone 0  
fill ~16 ~47 ~21 ~16 ~49 ~21 wool 1  
fill ~16 ~47 ~27 ~22 ~47 ~27 stone 0  
fill ~16 ~47 ~34 ~21 ~47 ~34 stone 0  
fill ~17 ~47 ~26 ~21 ~47 ~26 stone 0  
fill ~17 ~47 ~35 ~19 ~47 ~35 stone 0  
fill ~18 ~47 ~13 ~20 ~47 ~13 stone 0  
fill ~22 ~47 ~19 ~24 ~47 ~19 stone 0  
fill ~22 ~47 ~21 ~22 ~49 ~21 wool 1  
fill ~23 ~47 ~18 ~24 ~47 ~18 stone 0  
fill ~23 ~47 ~20 ~23 ~49 ~20 stonebrick 3  
fill ~23 ~47 ~21 ~23 ~49 ~21 stone_button 1 
setblock ~23 ~47 ~27 stonebrick 3  
fill ~30 ~47 ~37 ~31 ~47 ~37 stone 0  
fill ~6 ~48 ~28 ~6 ~49 ~28 stone 0  
fill ~14 ~48 ~18 ~15 ~48 ~18 stone 0  
fill ~14 ~48 ~19 ~16 ~48 ~19 stone 0  
fill ~14 ~48 ~27 ~24 ~48 ~27 stone 0  
fill ~14 ~48 ~28 ~24 ~48 ~28 stone 0  
fill ~14 ~48 ~29 ~24 ~48 ~29 stone 0  
fill ~14 ~48 ~30 ~24 ~48 ~30 stone 0  
fill ~14 ~48 ~31 ~24 ~48 ~31 stone 0  
fill ~14 ~48 ~32 ~24 ~48 ~32 stone 0 
setblock ~15 ~48 ~26 stonebrick 3  
fill ~15 ~48 ~33 ~23 ~48 ~33 stone 0  
fill ~16 ~48 ~26 ~22 ~48 ~26 stone 0  
fill ~16 ~48 ~34 ~21 ~48 ~34 stone 0  
fill ~17 ~48 ~35 ~19 ~48 ~35 stone 0  
fill ~18 ~48 ~13 ~20 ~48 ~13 stone 0  
fill ~22 ~48 ~19 ~24 ~48 ~19 stone 0  
fill ~23 ~48 ~18 ~24 ~48 ~18 stone 0 
setblock ~23 ~48 ~26 stonebrick 3  
fill ~14 ~49 ~18 ~15 ~49 ~18 stone 0  
fill ~14 ~49 ~19 ~16 ~49 ~19 stone 0  
fill ~14 ~49 ~26 ~24 ~49 ~26 stone 0  
fill ~14 ~49 ~27 ~24 ~49 ~27 stone 0  
fill ~14 ~49 ~28 ~24 ~49 ~28 stone 0  
fill ~14 ~49 ~29 ~24 ~49 ~29 stone 0  
fill ~14 ~49 ~30 ~24 ~49 ~30 stone 0  
fill ~14 ~49 ~31 ~24 ~49 ~31 stone 0  
fill ~14 ~49 ~32 ~24 ~49 ~32 stone 0  
fill ~15 ~49 ~33 ~23 ~49 ~33 stone 0  
fill ~16 ~49 ~34 ~21 ~49 ~34 stone 0  
fill ~17 ~49 ~35 ~19 ~49 ~35 stone 0  
fill ~18 ~49 ~13 ~20 ~49 ~13 stone 0  
fill ~22 ~49 ~19 ~24 ~49 ~19 stone 0  
fill ~23 ~49 ~18 ~24 ~49 ~18 stone 0  
fill ~9 ~50 ~30 ~9 ~51 ~30 stone 0  
fill ~14 ~50 ~18 ~15 ~50 ~18 stone 0  
fill ~14 ~50 ~19 ~16 ~50 ~19 stone 0  
fill ~14 ~50 ~20 ~16 ~50 ~20 stone 0  
fill ~14 ~50 ~21 ~16 ~50 ~21 stone 0  
fill ~14 ~50 ~22 ~14 ~50 ~30 stone 0  
fill ~14 ~50 ~31 ~14 ~57 ~31 quartz_block 1  
fill ~14 ~50 ~32 ~24 ~50 ~32 stone 0  
fill ~15 ~50 ~25 ~16 ~50 ~25 stone 0  
fill ~15 ~50 ~26 ~24 ~50 ~26 stone 0  
fill ~15 ~50 ~27 ~24 ~50 ~27 stone 0  
fill ~15 ~50 ~28 ~24 ~50 ~28 stone 0  
fill ~15 ~50 ~29 ~24 ~50 ~29 stone 0  
fill ~15 ~50 ~30 ~24 ~50 ~30 stone 0  
fill ~15 ~50 ~31 ~23 ~50 ~31 stone 0  
fill ~15 ~50 ~33 ~23 ~50 ~33 stone 0 
setblock ~16 ~50 ~22 stone 0  
fill ~16 ~50 ~34 ~21 ~50 ~34 stone 0  
fill ~17 ~50 ~35 ~19 ~50 ~35 stone 0  
fill ~18 ~50 ~13 ~20 ~50 ~13 stone 0  
fill ~22 ~50 ~19 ~24 ~50 ~19 stone 0  
fill ~22 ~50 ~21 ~24 ~50 ~21 stone 0  
fill ~22 ~50 ~22 ~22 ~50 ~19 stone 0  
fill ~22 ~50 ~25 ~24 ~50 ~25 stone 0  
fill ~23 ~50 ~18 ~24 ~50 ~18 stone 0  
fill ~23 ~50 ~20 ~24 ~50 ~20 stone 0  
fill ~24 ~50 ~22 ~24 ~50 ~30 stone 0  
fill ~14 ~51 ~18 ~15 ~51 ~18 stone 0  
fill ~14 ~51 ~19 ~16 ~51 ~19 stone 0  
fill ~14 ~51 ~26 ~24 ~51 ~26 stone 0  
fill ~14 ~51 ~27 ~24 ~51 ~27 stone 0  
fill ~14 ~51 ~28 ~24 ~51 ~28 stone 0  
fill ~14 ~51 ~29 ~24 ~51 ~29 stone 0  
fill ~14 ~51 ~30 ~24 ~51 ~30 stone 0  
fill ~14 ~51 ~32 ~24 ~51 ~32 stone 0  
fill ~15 ~51 ~20 ~15 ~62 ~20 stone 0  
fill ~15 ~51 ~31 ~23 ~51 ~31 stone 0  
fill ~15 ~51 ~33 ~23 ~51 ~33 stone 0  
fill ~16 ~51 ~21 ~16 ~51 ~22 glowstone 0  
fill ~16 ~51 ~25 ~16 ~60 ~25 stonebrick 3  
fill ~16 ~51 ~34 ~21 ~51 ~34 stone 0  
fill ~17 ~51 ~35 ~19 ~51 ~35 stone 0  
fill ~18 ~51 ~13 ~20 ~51 ~13 stone 0  
fill ~20 ~51 ~36 ~20 ~70 ~36 stone 0  
fill ~22 ~51 ~19 ~24 ~51 ~19 stone 0  
fill ~22 ~51 ~21 ~22 ~51 ~22 glowstone 0  
fill ~22 ~51 ~25 ~22 ~60 ~25 stonebrick 3  
fill ~23 ~51 ~18 ~24 ~51 ~18 stone 0  
fill ~23 ~51 ~20 ~23 ~62 ~20 stone 0  
fill ~24 ~51 ~31 ~24 ~57 ~31 quartz_block 1  
fill ~14 ~52 ~18 ~15 ~52 ~18 stone 0  
fill ~14 ~52 ~26 ~24 ~52 ~26 stone 0  
fill ~14 ~52 ~27 ~24 ~52 ~27 stone 0  
fill ~14 ~52 ~28 ~24 ~52 ~28 stone 0  
fill ~14 ~52 ~29 ~24 ~52 ~29 stone 0  
fill ~14 ~52 ~30 ~24 ~52 ~30 stone 0  
fill ~14 ~52 ~32 ~24 ~52 ~32 stone 0  
fill ~15 ~52 ~21 ~15 ~55 ~21 stone_button 2  
fill ~15 ~52 ~31 ~23 ~52 ~31 stone 0  
fill ~15 ~52 ~33 ~23 ~52 ~33 stone 0  
fill ~16 ~52 ~19 ~16 ~60 ~19 stonebrick 3  
fill ~16 ~52 ~21 ~16 ~55 ~21 wool 1  
fill ~16 ~52 ~22 ~16 ~56 ~22 stonebrick 3  
fill ~16 ~52 ~34 ~21 ~52 ~34 stone 0  
fill ~17 ~52 ~35 ~19 ~52 ~35 stone 0  
fill ~18 ~52 ~13 ~20 ~52 ~13 stone 0 
setblock ~22 ~52 ~19 stonebrick 3  
fill ~22 ~52 ~21 ~22 ~55 ~21 wool 1  
fill ~22 ~52 ~22 ~22 ~56 ~22 stonebrick 3  
fill ~23 ~52 ~18 ~24 ~52 ~18 stone 0  
fill ~23 ~52 ~21 ~23 ~55 ~21 stone_button 1  
fill ~14 ~53 ~26 ~24 ~53 ~26 stone 0  
fill ~14 ~53 ~27 ~24 ~53 ~27 stone 0  
fill ~14 ~53 ~28 ~24 ~53 ~28 stone 0  
fill ~14 ~53 ~29 ~24 ~53 ~29 stone 0  
fill ~14 ~53 ~30 ~24 ~53 ~30 stone 0  
fill ~14 ~53 ~32 ~24 ~53 ~32 stone 0  
fill ~15 ~53 ~18 ~15 ~64 ~18 stonebrick 3  
fill ~15 ~53 ~31 ~23 ~53 ~31 stone 0  
fill ~15 ~53 ~33 ~23 ~53 ~33 stone 0  
fill ~16 ~53 ~34 ~21 ~53 ~34 stone 0  
fill ~17 ~53 ~35 ~19 ~53 ~35 stone 0  
fill ~18 ~53 ~13 ~20 ~53 ~13 stone 0  
fill ~19 ~53 ~36 ~19 ~63 ~36 stone 0  
fill ~22 ~53 ~19 ~22 ~54 ~19 diamond_block 0  
fill ~23 ~53 ~18 ~23 ~64 ~18 stonebrick 3  
fill ~14 ~54 ~26 ~24 ~54 ~26 stone 0  
fill ~14 ~54 ~27 ~24 ~54 ~27 stone 0  
fill ~14 ~54 ~28 ~24 ~54 ~28 stone 0  
fill ~14 ~54 ~29 ~15 ~54 ~29 stone 0  
fill ~14 ~54 ~30 ~24 ~54 ~30 stone 0  
fill ~14 ~54 ~32 ~24 ~54 ~32 stone 0  
fill ~15 ~54 ~31 ~23 ~54 ~31 stone 0  
fill ~15 ~54 ~33 ~23 ~54 ~33 stone 0   
fill ~16 ~54 ~34 ~21 ~54 ~34 stone 0  
fill ~17 ~54 ~35 ~19 ~54 ~35 stone 0  
fill ~18 ~54 ~13 ~20 ~54 ~13 stone 0  
fill ~23 ~54 ~29 ~24 ~54 ~29 stone 0  
fill ~14 ~55 ~26 ~24 ~55 ~26 stone 0  
fill ~14 ~55 ~27 ~24 ~55 ~27 stone 0  
fill ~14 ~55 ~28 ~24 ~55 ~28 stone 0  
fill ~14 ~55 ~29 ~14 ~57 ~29 stone 0  
fill ~14 ~55 ~30 ~24 ~55 ~30 stone 0  
fill ~14 ~55 ~32 ~24 ~55 ~32 stone 0  
fill ~15 ~55 ~31 ~23 ~55 ~31 stone 0  
fill ~15 ~55 ~33 ~23 ~55 ~33 stone 0  
fill ~16 ~55 ~34 ~21 ~55 ~34 stone 0  
fill ~17 ~55 ~35 ~19 ~55 ~35 stone 0  
fill ~18 ~55 ~13 ~20 ~55 ~13 stone 0  
fill ~22 ~55 ~19 ~22 ~60 ~19 stonebrick 3  
fill ~24 ~55 ~29 ~24 ~57 ~29 stone 0  
fill ~14 ~56 ~26 ~24 ~56 ~26 stone 0  
fill ~14 ~56 ~27 ~24 ~56 ~27 stone 0  
fill ~14 ~56 ~28 ~24 ~56 ~28 stone 0  
fill ~14 ~56 ~30 ~24 ~56 ~30 stone 0  
fill ~14 ~56 ~32 ~24 ~56 ~32 stone 0  
fill ~15 ~56 ~21 ~16 ~56 ~21 stone 0  
fill ~15 ~56 ~29 ~24 ~56 ~29 stone 0  
fill ~15 ~56 ~31 ~23 ~56 ~31 stone 0  
fill ~15 ~56 ~33 ~23 ~56 ~33 stone 0  
fill ~16 ~56 ~34 ~21 ~56 ~34 stone 0  
fill ~17 ~56 ~35 ~19 ~56 ~35 stone 0  
fill ~18 ~56 ~13 ~20 ~56 ~13 stone 0  
fill ~22 ~56 ~21 ~23 ~56 ~21 stone 0  
fill ~14 ~57 ~26 ~24 ~57 ~26 stone 0  
fill ~14 ~57 ~27 ~24 ~57 ~27 stone 0  
fill ~14 ~57 ~28 ~24 ~57 ~28 stone 0  
fill ~14 ~57 ~30 ~14 ~58 ~30 quartz_block 1  
fill ~14 ~57 ~32 ~24 ~57 ~32 stone 0  
fill ~15 ~57 ~21 ~16 ~57 ~21 stone 0  
fill ~15 ~57 ~22 ~16 ~57 ~22 stone 0  
fill ~15 ~57 ~29 ~24 ~57 ~29 stone 0  
fill ~15 ~57 ~30 ~23 ~57 ~30 stone 0  
fill ~15 ~57 ~31 ~23 ~57 ~31 stone 0  
fill ~15 ~57 ~33 ~23 ~57 ~33 stone 0  
fill ~16 ~57 ~34 ~22 ~57 ~34 stone 0  
fill ~17 ~57 ~35 ~19 ~57 ~35 stone 0  
fill ~18 ~57 ~13 ~20 ~57 ~13 stone 0  
fill ~22 ~57 ~21 ~23 ~57 ~21 stone 0  
fill ~22 ~57 ~22 ~23 ~57 ~22 stone 0  
fill ~24 ~57 ~30 ~24 ~58 ~30 quartz_block 1  
fill ~14 ~58 ~26 ~24 ~58 ~26 stone 0  
fill ~14 ~58 ~27 ~24 ~58 ~27 stone 0  
fill ~14 ~58 ~28 ~24 ~58 ~28 stone 0  
fill ~14 ~58 ~29 ~14 ~59 ~29 quartz_block 1  
fill ~14 ~58 ~31 ~24 ~58 ~31 stone 0  
fill ~14 ~58 ~32 ~24 ~58 ~32 stone 0  
fill ~15 ~58 ~22 ~16 ~58 ~22 stone 0  
fill ~15 ~58 ~29 ~23 ~58 ~29 stone 0  
fill ~15 ~58 ~30 ~23 ~58 ~30 stone 0  
fill ~15 ~58 ~33 ~23 ~58 ~33 stone 0  
fill ~16 ~58 ~21 ~16 ~60 ~21 stonebrick 3  
fill ~16 ~58 ~34 ~22 ~58 ~34 stone 0  
fill ~17 ~58 ~35 ~19 ~58 ~35 stone 0  
fill ~18 ~58 ~13 ~20 ~58 ~13 stone 0  
fill ~22 ~58 ~21 ~22 ~60 ~21 stonebrick 3  
fill ~22 ~58 ~22 ~23 ~58 ~22 stone 0  
fill ~24 ~58 ~29 ~24 ~59 ~29 quartz_block 1  
fill ~14 ~59 ~26 ~24 ~59 ~26 stone 0  
fill ~14 ~59 ~27 ~24 ~59 ~27 stone 0  
fill ~14 ~59 ~28 ~14 ~60 ~28 quartz_block 1  
fill ~14 ~59 ~30 ~24 ~59 ~30 stone 0  
fill ~14 ~59 ~31 ~24 ~59 ~31 stone 0  
fill ~14 ~59 ~32 ~24 ~59 ~32 stone 0  
fill ~15 ~59 ~22 ~16 ~59 ~22 stone 0  
fill ~15 ~59 ~23 ~15 ~61 ~23 stone 0  
fill ~15 ~59 ~28 ~23 ~59 ~28 stone 0  
fill ~15 ~59 ~29 ~23 ~59 ~29 stone 0  
fill ~15 ~59 ~33 ~23 ~59 ~33 stone 0  
fill ~16 ~59 ~34 ~22 ~59 ~34 stone 0  
fill ~17 ~59 ~35 ~19 ~59 ~35 stone 0  
fill ~18 ~59 ~13 ~20 ~59 ~13 stone 0  
fill ~21 ~59 ~35 ~21 ~70 ~35 stone 0  
fill ~22 ~59 ~22 ~23 ~59 ~22 stone 0  
fill ~23 ~59 ~23 ~23 ~61 ~23 stone 0  
fill ~24 ~59 ~28 ~24 ~60 ~28 quartz_block 1  
fill ~14 ~60 ~27 ~24 ~60 ~27 stone 0  
fill ~14 ~60 ~29 ~24 ~60 ~29 stone 0  
fill ~14 ~60 ~30 ~24 ~60 ~30 stone 0  
fill ~14 ~60 ~31 ~24 ~60 ~31 stone 0  
fill ~14 ~60 ~32 ~24 ~60 ~32 stone 0  
fill ~15 ~60 ~26 ~23 ~60 ~26 stone 0  
fill ~15 ~60 ~28 ~23 ~60 ~28 stone 0  
fill ~15 ~60 ~33 ~23 ~60 ~33 stone 0  
fill ~16 ~60 ~22 ~16 ~62 ~22 stonebrick 3  
fill ~16 ~60 ~34 ~22 ~60 ~34 stone 0  
fill ~17 ~60 ~35 ~19 ~60 ~35 stone 0  
fill ~18 ~60 ~13 ~20 ~60 ~13 stone 0  
fill ~22 ~60 ~22 ~22 ~62 ~22 stonebrick 3  
fill ~14 ~61 ~28 ~24 ~61 ~28 stone 0  
fill ~14 ~61 ~29 ~24 ~61 ~29 stone 0  
fill ~14 ~61 ~30 ~24 ~61 ~30 stone 0  
fill ~14 ~61 ~31 ~24 ~61 ~31 stone 0  
fill ~14 ~61 ~32 ~24 ~61 ~32 stone 0  
fill ~15 ~61 ~21 ~16 ~61 ~21 stone 0  
fill ~15 ~61 ~24 ~15 ~62 ~24 stone 0  
fill ~15 ~61 ~25 ~16 ~61 ~25 stone 0  
fill ~15 ~61 ~26 ~23 ~61 ~26 stone 0  
fill ~15 ~61 ~27 ~23 ~61 ~27 stone 0  
fill ~15 ~61 ~33 ~23 ~61 ~33 stone 0 
setblock ~16 ~61 ~19 glowstone 0  
fill ~16 ~61 ~34 ~22 ~61 ~34 stone 0  
fill ~17 ~61 ~35 ~19 ~61 ~35 stone 0  
fill ~18 ~61 ~13 ~20 ~61 ~13 stone 0 
setblock ~22 ~61 ~19 glowstone 0  
fill ~22 ~61 ~21 ~23 ~61 ~21 stone 0  
fill ~22 ~61 ~25 ~23 ~61 ~25 stone 0  
fill ~23 ~61 ~24 ~23 ~62 ~24 stone 0  
fill ~14 ~62 ~29 ~24 ~62 ~29 stone 0  
fill ~14 ~62 ~30 ~24 ~62 ~30 stone 0  
fill ~14 ~62 ~31 ~24 ~62 ~31 stone 0  
fill ~14 ~62 ~32 ~24 ~62 ~32 stone 0  
fill ~15 ~62 ~21 ~16 ~62 ~21 stone 0  
fill ~15 ~62 ~25 ~16 ~62 ~25 stone 0  
fill ~15 ~62 ~26 ~23 ~62 ~26 stone 0  
fill ~15 ~62 ~27 ~23 ~62 ~27 stone 0  
fill ~15 ~62 ~28 ~23 ~62 ~28 stone 0  
fill ~15 ~62 ~33 ~23 ~62 ~33 stone 0  
fill ~16 ~62 ~19 ~16 ~85 ~19 stonebrick 3  
fill ~16 ~62 ~34 ~22 ~62 ~34 stone 0  
fill ~17 ~62 ~35 ~19 ~62 ~35 stone 0  
fill ~18 ~62 ~13 ~20 ~62 ~13 stone 0  
fill ~22 ~62 ~19 ~22 ~85 ~19 stonebrick 3  
fill ~22 ~62 ~21 ~23 ~62 ~21 stone 0  
fill ~22 ~62 ~25 ~23 ~62 ~25 stone 0  
fill ~14 ~63 ~29 ~24 ~63 ~29 stone 0  
fill ~14 ~63 ~30 ~24 ~63 ~30 stone 0  
fill ~14 ~63 ~31 ~24 ~63 ~31 stone 0  
fill ~14 ~63 ~32 ~24 ~63 ~32 stone 0  
fill ~15 ~63 ~21 ~16 ~63 ~21 stone 0  
fill ~15 ~63 ~22 ~16 ~63 ~22 stone 0  
fill ~15 ~63 ~28 ~23 ~63 ~28 stone 0  
fill ~15 ~63 ~33 ~23 ~63 ~33 stone 0  
fill ~16 ~63 ~20 ~16 ~65 ~20 stonebrick 3  
fill ~16 ~63 ~25 ~16 ~68 ~25 stonebrick 3  
fill ~16 ~63 ~26 ~16 ~69 ~26 stonebrick 3  
fill ~16 ~63 ~27 ~16 ~71 ~27 stonebrick 3  
fill ~16 ~63 ~34 ~22 ~63 ~34 stone 0  
fill ~17 ~63 ~26 ~21 ~63 ~26 stone 0  
fill ~17 ~63 ~27 ~21 ~63 ~27 stone 0  
fill ~17 ~63 ~35 ~21 ~63 ~35 stone 0  
fill ~18 ~63 ~13 ~20 ~63 ~13 stone 0  
fill ~22 ~63 ~20 ~22 ~65 ~20 stonebrick 3  
fill ~22 ~63 ~21 ~23 ~63 ~21 stone 0  
fill ~22 ~63 ~22 ~23 ~63 ~22 stone 0  
fill ~22 ~63 ~25 ~22 ~68 ~25 stonebrick 3  
fill ~22 ~63 ~26 ~22 ~69 ~26 stonebrick 3  
fill ~22 ~63 ~27 ~22 ~68 ~27 stonebrick 3  
fill ~14 ~64 ~29 ~24 ~64 ~29 stone 0  
fill ~14 ~64 ~30 ~24 ~64 ~30 stone 0  
fill ~14 ~64 ~31 ~24 ~64 ~31 stone 0  
fill ~14 ~64 ~32 ~24 ~64 ~32 stone 0  
fill ~15 ~64 ~21 ~16 ~64 ~21 stone 0  
fill ~15 ~64 ~22 ~16 ~64 ~22 stone 0  
fill ~15 ~64 ~28 ~23 ~64 ~28 stone 0  
fill ~15 ~64 ~33 ~23 ~64 ~33 stone 0  
fill ~16 ~64 ~34 ~22 ~64 ~34 stone 0  
fill ~17 ~64 ~26 ~21 ~64 ~26 stone 0  
fill ~17 ~64 ~27 ~21 ~64 ~27 stone 0  
fill ~17 ~64 ~35 ~21 ~64 ~35 stone 0  
fill ~18 ~64 ~13 ~20 ~64 ~13 stone 0  
fill ~19 ~64 ~36 ~19 ~69 ~36 wool 1  
fill ~22 ~64 ~21 ~23 ~64 ~21 stone 0  
fill ~22 ~64 ~22 ~23 ~64 ~22 stone 0  
fill ~14 ~65 ~18 ~15 ~65 ~18 stone 0  
fill ~14 ~65 ~29 ~24 ~65 ~29 stone 0  
fill ~14 ~65 ~30 ~24 ~65 ~30 stone 0  
fill ~14 ~65 ~31 ~24 ~65 ~31 stone 0  
fill ~14 ~65 ~32 ~24 ~65 ~32 stone 0  
fill ~15 ~65 ~22 ~16 ~65 ~22 stone 0  
fill ~15 ~65 ~23 ~16 ~65 ~23 stone 0  
fill ~15 ~65 ~28 ~23 ~65 ~28 stone 0  
fill ~15 ~65 ~33 ~23 ~65 ~33 stone 0  
fill ~16 ~65 ~21 ~16 ~67 ~21 stonebrick 3  
fill ~16 ~65 ~34 ~22 ~65 ~34 stone 0  
fill ~17 ~65 ~26 ~21 ~65 ~26 stone 0  
fill ~17 ~65 ~27 ~21 ~65 ~27 stone 0  
fill ~17 ~65 ~35 ~21 ~65 ~35 stone 0  
fill ~18 ~65 ~13 ~20 ~65 ~13 stone 0  
fill ~22 ~65 ~21 ~22 ~67 ~21 stonebrick 3  
fill ~22 ~65 ~22 ~23 ~65 ~22 stone 0  
fill ~22 ~65 ~23 ~23 ~65 ~23 stone 0  
fill ~23 ~65 ~18 ~24 ~65 ~18 stone 0  
fill ~14 ~66 ~18 ~15 ~66 ~18 stone 0  
fill ~14 ~66 ~29 ~24 ~66 ~29 stone 0  
fill ~14 ~66 ~30 ~24 ~66 ~30 stone 0  
fill ~14 ~66 ~31 ~24 ~66 ~31 stone 0  
fill ~14 ~66 ~32 ~24 ~66 ~32 stone 0  
fill ~15 ~66 ~22 ~16 ~66 ~22 stone 0  
fill ~15 ~66 ~23 ~16 ~66 ~23 stone 0  
fill ~15 ~66 ~28 ~23 ~66 ~28 stone 0  
fill ~15 ~66 ~33 ~23 ~66 ~33 stone 0  
fill ~16 ~66 ~34 ~22 ~66 ~34 stone 0  
fill ~17 ~66 ~20 ~17 ~70 ~20 stonebrick 3  
fill ~17 ~66 ~26 ~21 ~66 ~26 stone 0  
fill ~17 ~66 ~27 ~21 ~66 ~27 stone 0  
fill ~17 ~66 ~35 ~21 ~66 ~35 stone 0  
fill ~18 ~66 ~13 ~20 ~66 ~13 stone 0  
fill ~21 ~66 ~20 ~21 ~70 ~20 stonebrick 3  
fill ~22 ~66 ~22 ~23 ~66 ~22 stone 0  
fill ~22 ~66 ~23 ~23 ~66 ~23 stone 0  
fill ~23 ~66 ~18 ~24 ~66 ~18 stone 0  
fill ~14 ~67 ~18 ~15 ~67 ~18 stone 0  
fill ~14 ~67 ~19 ~14 ~71 ~19 stone 0  
fill ~14 ~67 ~29 ~24 ~67 ~29 stone 0  
fill ~14 ~67 ~30 ~24 ~67 ~30 stone 0  
fill ~14 ~67 ~31 ~24 ~67 ~31 stone 0  
fill ~14 ~67 ~32 ~24 ~67 ~32 stone 0  
fill ~15 ~67 ~23 ~17 ~67 ~23 stone 0  
fill ~15 ~67 ~24 ~17 ~67 ~24 stone 0  
fill ~15 ~67 ~28 ~23 ~67 ~28 stone 0  
fill ~15 ~67 ~33 ~23 ~67 ~33 stone 0  
fill ~16 ~67 ~22 ~16 ~69 ~22 stonebrick 3  
fill ~16 ~67 ~34 ~22 ~67 ~34 stone 0  
fill ~17 ~67 ~15 ~17 ~117 ~15 stone 0  
fill ~17 ~67 ~16 ~17 ~117 ~16 stone 0  
fill ~17 ~67 ~17 ~17 ~117 ~17 stone 0  
fill ~17 ~67 ~18 ~17 ~117 ~18 stone 0  
fill ~17 ~67 ~19 ~17 ~178 ~19 stone 0  
fill ~17 ~67 ~21 ~17 ~67 ~35 stone 0  
fill ~18 ~67 ~13 ~20 ~67 ~13 stone 0  
fill ~18 ~67 ~26 ~21 ~67 ~26 stone 0  
fill ~18 ~67 ~27 ~21 ~67 ~27 stone 0  
fill ~18 ~67 ~35 ~21 ~67 ~35 stone 0  
fill ~21 ~67 ~15 ~21 ~117 ~15 stone 0  
fill ~21 ~67 ~16 ~21 ~83 ~16 stone 0  
fill ~21 ~67 ~17 ~21 ~117 ~17 stone 0  
fill ~21 ~67 ~18 ~21 ~117 ~18 stone 0  
fill ~21 ~67 ~19 ~21 ~178 ~19 stone 0  
fill ~21 ~67 ~21 ~21 ~67 ~35 stone 0  
fill ~22 ~67 ~22 ~22 ~69 ~22 stonebrick 3  
fill ~22 ~67 ~23 ~23 ~67 ~23 stone 0  
fill ~22 ~67 ~24 ~23 ~67 ~24 stone 0  
fill ~23 ~67 ~18 ~24 ~67 ~18 stone 0  
fill ~24 ~67 ~19 ~24 ~71 ~19 stone 0  
fill ~14 ~68 ~18 ~15 ~68 ~18 stone 0  
fill ~14 ~68 ~29 ~24 ~68 ~29 stone 0  
fill ~14 ~68 ~30 ~24 ~68 ~30 stone 0  
fill ~14 ~68 ~31 ~24 ~68 ~31 stone 0  
fill ~14 ~68 ~32 ~24 ~68 ~32 stone 0  
fill ~15 ~68 ~23 ~17 ~68 ~23 stone 0  
fill ~15 ~68 ~24 ~17 ~68 ~24 stone 0  
fill ~15 ~68 ~28 ~23 ~68 ~28 stone 0  
fill ~15 ~68 ~33 ~23 ~68 ~33 stone 0  
fill ~16 ~68 ~16 ~16 ~68 ~17 stone 0  
fill ~16 ~68 ~34 ~22 ~68 ~34 stone 0  
fill ~17 ~68 ~21 ~17 ~87 ~21 stonebrick 3  
fill ~17 ~68 ~22 ~17 ~69 ~22 stone 0  
fill ~17 ~68 ~25 ~17 ~176 ~25 stone 0  
fill ~17 ~68 ~26 ~21 ~68 ~26 stone 0  
fill ~17 ~68 ~27 ~21 ~68 ~27 stone 0  
fill ~17 ~68 ~35 ~21 ~68 ~35 stone 0  
fill ~18 ~68 ~13 ~20 ~68 ~13 stone 0  
fill ~21 ~68 ~21 ~21 ~88 ~21 stonebrick 3  
fill ~21 ~68 ~22 ~21 ~69 ~22 stone 0  
fill ~21 ~68 ~23 ~23 ~68 ~23 stone 0  
fill ~21 ~68 ~24 ~23 ~68 ~24 stone 0  
fill ~21 ~68 ~25 ~21 ~176 ~25 stone 0  
fill ~23 ~68 ~18 ~24 ~68 ~18 stone 0  
fill ~14 ~69 ~18 ~15 ~69 ~18 stone 0  
fill ~14 ~69 ~20 ~14 ~73 ~20 stone 0  
fill ~14 ~69 ~29 ~24 ~69 ~29 stone 0  
fill ~14 ~69 ~30 ~24 ~69 ~30 stone 0  
fill ~14 ~69 ~31 ~24 ~69 ~31 stone 0  
fill ~14 ~69 ~32 ~24 ~69 ~32 stone 0  
fill ~15 ~69 ~24 ~17 ~69 ~24 stone 0  
fill ~15 ~69 ~25 ~17 ~69 ~25 stone 0  
fill ~15 ~69 ~28 ~23 ~69 ~28 stone 0  
fill ~15 ~69 ~33 ~23 ~69 ~33 stone 0  
fill ~16 ~69 ~17 ~16 ~90 ~17 stone 0  
fill ~16 ~69 ~23 ~16 ~72 ~23 stonebrick 3  
fill ~16 ~69 ~34 ~22 ~69 ~34 stone 0  
fill ~17 ~69 ~23 ~17 ~72 ~23 stone 0  
fill ~17 ~69 ~26 ~21 ~69 ~26 stone 0  
fill ~17 ~69 ~27 ~21 ~69 ~27 stone 0  
fill ~17 ~69 ~35 ~21 ~69 ~35 stone 0  
fill ~18 ~69 ~13 ~20 ~69 ~13 stone 0  
fill ~21 ~69 ~23 ~21 ~72 ~23 stone 0  
fill ~21 ~69 ~24 ~23 ~69 ~24 stone 0  
fill ~22 ~69 ~23 ~22 ~72 ~23 stonebrick 3  
fill ~22 ~69 ~25 ~23 ~69 ~25 stone 0 
setblock ~22 ~69 ~27 glowstone 0  
fill ~23 ~69 ~18 ~24 ~69 ~18 stone 0  
fill ~24 ~69 ~20 ~24 ~73 ~20 stone 0  
fill ~14 ~70 ~29 ~24 ~70 ~29 stone 0  
fill ~14 ~70 ~30 ~24 ~70 ~30 stone 0  
fill ~14 ~70 ~31 ~24 ~70 ~31 stone 0  
fill ~14 ~70 ~32 ~24 ~70 ~32 stone 0  
fill ~15 ~70 ~18 ~15 ~86 ~18 stonebrick 3  
fill ~15 ~70 ~24 ~17 ~70 ~24 stone 0  
fill ~15 ~70 ~25 ~17 ~70 ~25 stone 0  
fill ~15 ~70 ~26 ~23 ~70 ~26 stone 0  
fill ~15 ~70 ~28 ~23 ~70 ~28 stone 0  
fill ~15 ~70 ~33 ~23 ~70 ~33 stone 0  
fill ~16 ~70 ~22 ~16 ~90 ~22 stone_button 2  
fill ~16 ~70 ~34 ~22 ~70 ~34 stone 0  
fill ~17 ~70 ~22 ~17 ~90 ~22 stonebrick 3  
fill ~17 ~70 ~27 ~21 ~70 ~27 stone 0  
fill ~17 ~70 ~35 ~21 ~70 ~35 stone 0  
fill ~18 ~70 ~13 ~20 ~70 ~13 stone 0 
setblock ~19 ~70 ~36 stone 0  
fill ~21 ~70 ~22 ~21 ~90 ~22 stonebrick 3  
fill ~21 ~70 ~24 ~23 ~70 ~24 stone 0  
fill ~22 ~70 ~22 ~22 ~90 ~22 stone_button 1  
fill ~22 ~70 ~25 ~23 ~70 ~25 stone 0  
fill ~22 ~70 ~27 ~22 ~71 ~27 stonebrick 3  
fill ~23 ~70 ~18 ~23 ~86 ~18 stonebrick 3  
fill ~14 ~71 ~21 ~14 ~75 ~21 stone 0  
fill ~15 ~71 ~25 ~17 ~71 ~25 stone 0  
fill ~15 ~71 ~26 ~23 ~71 ~26 stone 0  
fill ~15 ~71 ~28 ~23 ~71 ~28 stone 0  
fill ~15 ~71 ~29 ~23 ~71 ~29 stone 0  
fill ~15 ~71 ~30 ~23 ~71 ~30 stone 0  
fill ~15 ~71 ~31 ~23 ~71 ~31 stone 0  
fill ~16 ~71 ~24 ~16 ~73 ~24 stonebrick 3  
fill ~16 ~71 ~32 ~22 ~71 ~32 stone 0 
setblock ~17 ~71 ~20 glowstone 0  
fill ~17 ~71 ~24 ~17 ~73 ~24 stone 0  
fill ~17 ~71 ~27 ~21 ~71 ~27 stone 0  
fill ~17 ~71 ~33 ~21 ~71 ~33 stone 0  
fill ~18 ~71 ~13 ~20 ~71 ~13 stone 0  
fill ~18 ~71 ~34 ~20 ~71 ~34 stone 0 
setblock ~21 ~71 ~20 glowstone 0  
fill ~21 ~71 ~24 ~21 ~73 ~24 stone 0  
fill ~22 ~71 ~24 ~22 ~73 ~24 stonebrick 3  
fill ~22 ~71 ~25 ~23 ~71 ~25 stone 0  
fill ~24 ~71 ~21 ~24 ~75 ~21 stone 0  
fill ~14 ~72 ~29 ~24 ~72 ~29 stone 0  
fill ~14 ~72 ~30 ~24 ~72 ~30 stone 0  
fill ~14 ~72 ~31 ~24 ~72 ~31 stone 0  
fill ~15 ~72 ~26 ~23 ~72 ~26 stone 0  
fill ~15 ~72 ~27 ~23 ~72 ~27 stone 0  
fill ~15 ~72 ~28 ~23 ~72 ~28 stone 0  
fill ~15 ~72 ~32 ~23 ~72 ~32 stone 0  
fill ~16 ~72 ~25 ~16 ~107 ~25 stonebrick 3  
fill ~16 ~72 ~33 ~22 ~72 ~33 stone 0  
fill ~17 ~72 ~20 ~17 ~85 ~20 stonebrick 3  
fill ~17 ~72 ~34 ~21 ~72 ~34 stone 0  
fill ~18 ~72 ~13 ~20 ~72 ~13 stone 0  
fill ~18 ~72 ~23 ~18 ~92 ~23 redstone_block 0  
fill ~18 ~72 ~35 ~20 ~72 ~35 stone 0  
fill ~19 ~72 ~23 ~19 ~92 ~23 stone 0  
fill ~20 ~72 ~23 ~20 ~92 ~23 redstone_block 0  
fill ~21 ~72 ~20 ~21 ~85 ~20 stonebrick 3  
fill ~22 ~72 ~25 ~22 ~112 ~25 stonebrick 3  
fill ~14 ~73 ~22 ~14 ~77 ~22 stone 0  
fill ~14 ~73 ~29 ~24 ~73 ~29 stone 0  
fill ~14 ~73 ~30 ~24 ~73 ~30 stone 0  
fill ~14 ~73 ~31 ~24 ~73 ~31 stone 0  
fill ~15 ~73 ~26 ~23 ~73 ~26 stone 0  
fill ~15 ~73 ~27 ~23 ~73 ~27 stone 0  
fill ~15 ~73 ~28 ~23 ~73 ~28 stone 0  
fill ~15 ~73 ~32 ~23 ~73 ~32 stone 0  
fill ~16 ~73 ~33 ~22 ~73 ~33 stone 0  
fill ~17 ~73 ~23 ~17 ~92 ~23 lit_redstone_lamp 0  
fill ~17 ~73 ~34 ~21 ~73 ~34 stone 0  
fill ~18 ~73 ~14 ~18 ~87 ~14 stone 0  
fill ~18 ~73 ~35 ~20 ~73 ~35 stone 0  
fill ~19 ~73 ~13 ~20 ~73 ~13 stone 0  
fill ~21 ~73 ~23 ~21 ~92 ~23 lit_redstone_lamp 0  
fill ~24 ~73 ~22 ~24 ~77 ~22 stone 0  
fill ~14 ~74 ~18 ~14 ~178 ~18 stone 0  
fill ~14 ~74 ~29 ~24 ~74 ~29 stone 0  
fill ~14 ~74 ~30 ~24 ~74 ~30 stone 0  
fill ~14 ~74 ~31 ~24 ~74 ~31 stone 0  
fill ~15 ~74 ~27 ~23 ~74 ~27 stone 0  
fill ~15 ~74 ~28 ~23 ~74 ~28 stone 0  
fill ~15 ~74 ~32 ~23 ~74 ~32 stone 0  
fill ~16 ~74 ~24 ~16 ~93 ~24 stone_button 2  
fill ~16 ~74 ~26 ~16 ~92 ~26 stonebrick 3  
fill ~16 ~74 ~33 ~22 ~74 ~33 stone 0  
fill ~17 ~74 ~24 ~17 ~93 ~24 stonebrick 3  
fill ~17 ~74 ~26 ~21 ~74 ~26 stone 0  
fill ~17 ~74 ~34 ~21 ~74 ~34 stone 0  
fill ~18 ~74 ~35 ~20 ~74 ~35 stone 0  
fill ~19 ~74 ~13 ~20 ~74 ~13 stone 0  
fill ~21 ~74 ~24 ~21 ~93 ~24 stonebrick 3  
fill ~22 ~74 ~24 ~22 ~93 ~24 stone_button 1  
fill ~22 ~74 ~26 ~22 ~87 ~26 stonebrick 3  
fill ~24 ~74 ~18 ~24 ~178 ~18 stone 0  
fill ~14 ~75 ~23 ~14 ~79 ~23 stone 0  
fill ~14 ~75 ~29 ~24 ~75 ~29 stone 0  
fill ~14 ~75 ~30 ~24 ~75 ~30 stone 0  
fill ~14 ~75 ~31 ~24 ~75 ~31 stone 0  
fill ~15 ~75 ~27 ~23 ~75 ~27 stone 0  
fill ~15 ~75 ~28 ~23 ~75 ~28 stone 0  
fill ~15 ~75 ~32 ~23 ~75 ~32 stone 0  
fill ~16 ~75 ~33 ~22 ~75 ~33 stone 0  
fill ~17 ~75 ~26 ~21 ~75 ~26 stone 0  
fill ~17 ~75 ~34 ~21 ~75 ~34 stone 0  
fill ~18 ~75 ~35 ~20 ~75 ~35 stone 0  
fill ~19 ~75 ~13 ~20 ~75 ~13 stone 0  
fill ~24 ~75 ~23 ~24 ~79 ~23 stone 0  
fill ~14 ~76 ~19 ~14 ~86 ~19 stone 0  
fill ~14 ~76 ~29 ~24 ~76 ~29 stone 0  
fill ~14 ~76 ~30 ~24 ~76 ~30 stone 0  
fill ~14 ~76 ~31 ~24 ~76 ~31 stone 0  
fill ~15 ~76 ~28 ~23 ~76 ~28 stone 0  
fill ~15 ~76 ~32 ~23 ~76 ~32 stone 0  
fill ~16 ~76 ~27 ~16 ~87 ~27 stonebrick 3  
fill ~16 ~76 ~33 ~22 ~76 ~33 stone 0  
fill ~17 ~76 ~26 ~21 ~76 ~26 stone 0  
fill ~17 ~76 ~27 ~21 ~76 ~27 stone 0  
fill ~17 ~76 ~34 ~21 ~76 ~34 stone 0  
fill ~18 ~76 ~35 ~20 ~76 ~35 stone 0  
fill ~19 ~76 ~13 ~20 ~76 ~13 stone 0  
fill ~22 ~76 ~27 ~22 ~92 ~27 stonebrick 3  
fill ~24 ~76 ~19 ~24 ~86 ~19 stone 0  
fill ~14 ~77 ~24 ~14 ~81 ~24 stone 0  
fill ~14 ~77 ~29 ~24 ~77 ~29 stone 0  
fill ~14 ~77 ~30 ~24 ~77 ~30 stone 0  
fill ~14 ~77 ~31 ~24 ~77 ~31 stone 0  
fill ~15 ~77 ~28 ~23 ~77 ~28 stone 0  
fill ~15 ~77 ~32 ~23 ~77 ~32 stone 0  
fill ~16 ~77 ~33 ~22 ~77 ~33 stone 0  
fill ~17 ~77 ~26 ~21 ~77 ~26 stone 0  
fill ~17 ~77 ~27 ~21 ~77 ~27 stone 0  
fill ~17 ~77 ~34 ~21 ~77 ~34 stone 0  
fill ~18 ~77 ~35 ~20 ~77 ~35 stone 0  
fill ~19 ~77 ~13 ~20 ~77 ~13 stone 0  
fill ~24 ~77 ~24 ~24 ~81 ~24 stone 0  
fill ~14 ~78 ~20 ~14 ~88 ~20 stone 0  
fill ~14 ~78 ~29 ~24 ~78 ~29 stone 0  
fill ~14 ~78 ~30 ~24 ~78 ~30 stone 0  
fill ~14 ~78 ~31 ~24 ~78 ~31 stone 0  
fill ~15 ~78 ~28 ~23 ~78 ~28 stone 0  
fill ~15 ~78 ~32 ~23 ~78 ~32 stone 0  
fill ~16 ~78 ~33 ~22 ~78 ~33 stone 0  
fill ~17 ~78 ~26 ~21 ~78 ~26 stone 0  
fill ~17 ~78 ~27 ~21 ~78 ~27 stone 0  
fill ~17 ~78 ~34 ~21 ~78 ~34 stone 0  
fill ~18 ~78 ~35 ~20 ~78 ~35 stone 0  
fill ~19 ~78 ~13 ~20 ~78 ~13 stone 0  
fill ~24 ~78 ~20 ~24 ~88 ~20 stone 0  
fill ~14 ~79 ~25 ~14 ~83 ~25 stone 0  
fill ~14 ~79 ~29 ~24 ~79 ~29 stone 0  
fill ~14 ~79 ~30 ~24 ~79 ~30 stone 0  
fill ~14 ~79 ~31 ~24 ~79 ~31 stone 0  
fill ~15 ~79 ~28 ~23 ~79 ~28 stone 0  
fill ~15 ~79 ~32 ~23 ~79 ~32 stone 0  
fill ~16 ~79 ~33 ~22 ~79 ~33 stone 0  
fill ~17 ~79 ~26 ~21 ~79 ~26 stone 0  
fill ~17 ~79 ~27 ~21 ~79 ~27 stone 0  
fill ~17 ~79 ~34 ~21 ~79 ~34 stone 0  
fill ~18 ~79 ~35 ~20 ~79 ~35 stone 0  
fill ~19 ~79 ~13 ~20 ~79 ~13 stone 0  
fill ~24 ~79 ~25 ~24 ~83 ~25 stone 0  
fill ~14 ~80 ~29 ~24 ~80 ~29 stone 0  
fill ~14 ~80 ~30 ~24 ~80 ~30 stone 0  
fill ~14 ~80 ~31 ~24 ~80 ~31 stone 0  
fill ~15 ~80 ~16 ~15 ~178 ~16 stone 0  
fill ~15 ~80 ~28 ~23 ~80 ~28 stone 0  
fill ~15 ~80 ~32 ~23 ~80 ~32 stone 0 
setblock ~16 ~80 ~20 lever 2  
fill ~16 ~80 ~33 ~22 ~80 ~33 stone 0  
fill ~17 ~80 ~26 ~21 ~80 ~26 stone 0  
fill ~17 ~80 ~27 ~21 ~80 ~27 stone 0  
fill ~17 ~80 ~34 ~21 ~80 ~34 stone 0  
fill ~18 ~80 ~35 ~20 ~80 ~35 stone 0  
fill ~19 ~80 ~13 ~20 ~80 ~13 stone 0 
setblock ~22 ~80 ~20 lever 1  
fill ~14 ~81 ~26 ~14 ~85 ~26 stone 0  
fill ~14 ~81 ~29 ~24 ~81 ~29 stone 0  
fill ~14 ~81 ~30 ~24 ~81 ~30 stone 0  
fill ~14 ~81 ~31 ~24 ~81 ~31 stone 0  
fill ~15 ~81 ~28 ~23 ~81 ~28 stone 0  
fill ~15 ~81 ~32 ~23 ~81 ~32 stone 0 
setblock ~16 ~81 ~20 glowstone 0  
fill ~16 ~81 ~33 ~22 ~81 ~33 stone 0  
fill ~17 ~81 ~26 ~21 ~81 ~26 stone 0  
fill ~17 ~81 ~27 ~21 ~81 ~27 stone 0  
fill ~17 ~81 ~34 ~21 ~81 ~34 stone 0  
fill ~18 ~81 ~35 ~20 ~81 ~35 stone 0  
fill ~19 ~81 ~13 ~20 ~81 ~13 stone 0 
setblock ~22 ~81 ~20 glowstone 0  
fill ~24 ~81 ~26 ~24 ~85 ~26 stone 0  
fill ~14 ~82 ~29 ~24 ~82 ~29 stone 0  
fill ~14 ~82 ~30 ~24 ~82 ~30 stone 0  
fill ~14 ~82 ~31 ~24 ~82 ~31 stone 0  
fill ~15 ~82 ~28 ~23 ~82 ~28 stone 0  
fill ~15 ~82 ~32 ~23 ~82 ~32 stone 0 
setblock ~16 ~82 ~20 lever 10  
fill ~16 ~82 ~33 ~22 ~82 ~33 stone 0  
fill ~17 ~82 ~26 ~21 ~82 ~26 stone 0  
fill ~17 ~82 ~27 ~21 ~82 ~27 stone 0  
fill ~17 ~82 ~34 ~21 ~82 ~34 stone 0  
fill ~18 ~82 ~35 ~20 ~82 ~35 stone 0  
fill ~19 ~82 ~13 ~20 ~82 ~13 stone 0 
setblock ~22 ~82 ~20 lever 9  
fill ~14 ~83 ~27 ~14 ~91 ~27 stone 0  
fill ~14 ~83 ~29 ~24 ~83 ~29 stone 0  
fill ~14 ~83 ~30 ~24 ~83 ~30 stone 0  
fill ~14 ~83 ~31 ~24 ~83 ~31 stone 0  
fill ~15 ~83 ~28 ~23 ~83 ~28 stone 0  
fill ~15 ~83 ~32 ~23 ~83 ~32 stone 0  
fill ~16 ~83 ~33 ~22 ~83 ~33 stone 0  
fill ~17 ~83 ~26 ~21 ~83 ~26 stone 0  
fill ~17 ~83 ~27 ~21 ~83 ~27 stone 0  
fill ~17 ~83 ~34 ~21 ~83 ~34 stone 0  
fill ~18 ~83 ~35 ~20 ~83 ~35 stone 0  
fill ~19 ~83 ~13 ~20 ~83 ~13 stone 0  
fill ~24 ~83 ~27 ~24 ~91 ~27 stone 0  
fill ~14 ~84 ~21 ~14 ~85 ~21 stone 0  
fill ~14 ~84 ~29 ~24 ~84 ~29 stone 0  
fill ~14 ~84 ~30 ~24 ~84 ~30 stone 0  
fill ~14 ~84 ~31 ~24 ~84 ~31 stone 0 
setblock ~15 ~84 ~17 glowstone 0  
fill ~15 ~84 ~28 ~23 ~84 ~28 stone 0  
fill ~15 ~84 ~32 ~23 ~84 ~32 stone 0  
fill ~16 ~84 ~33 ~22 ~84 ~33 stone 0  
fill ~17 ~84 ~26 ~21 ~84 ~26 stone 0  
fill ~17 ~84 ~27 ~21 ~84 ~27 stone 0  
fill ~17 ~84 ~34 ~21 ~84 ~34 stone 0  
fill ~18 ~84 ~35 ~20 ~84 ~35 stone 0  
fill ~19 ~84 ~13 ~20 ~84 ~13 stone 0  
fill ~24 ~84 ~21 ~24 ~85 ~21 stone 0  
fill ~14 ~85 ~22 ~14 ~87 ~22 stone 0  
fill ~14 ~85 ~29 ~24 ~85 ~29 stone 0  
fill ~14 ~85 ~30 ~24 ~85 ~30 stone 0  
fill ~14 ~85 ~31 ~24 ~85 ~31 stone 0  
fill ~15 ~85 ~17 ~15 ~90 ~17 stone 0  
fill ~15 ~85 ~28 ~23 ~85 ~28 stone 0  
fill ~15 ~85 ~32 ~23 ~85 ~32 stone 0  
fill ~16 ~85 ~15 ~16 ~178 ~15 stone 0  
fill ~16 ~85 ~33 ~22 ~85 ~33 stone 0  
fill ~17 ~85 ~26 ~21 ~85 ~26 stone 0  
fill ~17 ~85 ~27 ~21 ~85 ~27 stone 0  
fill ~17 ~85 ~34 ~21 ~85 ~34 stone 0  
fill ~18 ~85 ~35 ~20 ~85 ~35 stone 0  
fill ~19 ~85 ~13 ~20 ~85 ~13 stone 0  
fill ~21 ~85 ~16 ~21 ~117 ~16 stone 0  
fill ~24 ~85 ~22 ~24 ~87 ~22 stone 0  
fill ~14 ~86 ~29 ~24 ~86 ~29 stone 0  
fill ~14 ~86 ~30 ~24 ~86 ~30 stone 0  
fill ~14 ~86 ~31 ~24 ~86 ~31 stone 0  
fill ~15 ~86 ~28 ~23 ~86 ~28 stone 0  
fill ~15 ~86 ~32 ~23 ~86 ~32 stone 0  
fill ~16 ~86 ~19 ~16 ~178 ~19 stone 0  
fill ~16 ~86 ~20 ~16 ~88 ~20 stonebrick 3  
fill ~16 ~86 ~33 ~22 ~86 ~33 stone 0  
fill ~17 ~86 ~20 ~17 ~178 ~20 stone 0  
fill ~17 ~86 ~26 ~21 ~86 ~26 stone 0  
fill ~17 ~86 ~27 ~21 ~86 ~27 stone 0  
fill ~17 ~86 ~34 ~21 ~86 ~34 stone 0  
fill ~18 ~86 ~35 ~20 ~86 ~35 stone 0  
fill ~19 ~86 ~13 ~20 ~86 ~13 stone 0  
fill ~21 ~86 ~20 ~21 ~178 ~20 stone 0  
fill ~22 ~86 ~19 ~22 ~178 ~19 stone 0  
fill ~22 ~86 ~20 ~22 ~88 ~20 stonebrick 3  
fill ~14 ~87 ~23 ~14 ~89 ~23 stone 0  
fill ~14 ~87 ~29 ~24 ~87 ~29 stone 0  
fill ~14 ~87 ~30 ~24 ~87 ~30 stone 0  
fill ~14 ~87 ~31 ~24 ~87 ~31 stone 0  
fill ~15 ~87 ~18 ~15 ~87 ~19 stone 0  
fill ~15 ~87 ~28 ~23 ~87 ~28 stone 0  
fill ~15 ~87 ~32 ~23 ~87 ~32 stone 0  
fill ~16 ~87 ~33 ~22 ~87 ~33 stone 0  
fill ~17 ~87 ~14 ~17 ~178 ~14 stone 0  
fill ~17 ~87 ~26 ~21 ~87 ~26 stone 0  
fill ~17 ~87 ~27 ~21 ~87 ~27 stone 0  
fill ~17 ~87 ~34 ~21 ~87 ~34 stone 0  
fill ~18 ~87 ~13 ~20 ~87 ~13 stone 0  
fill ~18 ~87 ~35 ~20 ~87 ~35 stone 0  
fill ~23 ~87 ~18 ~23 ~87 ~19 stone 0  
fill ~24 ~87 ~23 ~24 ~89 ~23 stone 0  
fill ~14 ~88 ~29 ~24 ~88 ~29 stone 0  
fill ~14 ~88 ~30 ~24 ~88 ~30 stone 0  
fill ~14 ~88 ~31 ~24 ~88 ~31 stone 0  
fill ~15 ~88 ~19 ~15 ~89 ~19 stone 0  
fill ~15 ~88 ~28 ~23 ~88 ~28 stone 0  
fill ~15 ~88 ~32 ~23 ~88 ~32 stone 0 
setblock ~16 ~88 ~27 glowstone 0  
fill ~16 ~88 ~33 ~22 ~88 ~33 stone 0 
setblock ~17 ~88 ~21 glowstone 0  
fill ~17 ~88 ~26 ~21 ~88 ~26 stone 0  
fill ~17 ~88 ~27 ~21 ~88 ~27 stone 0  
fill ~17 ~88 ~34 ~21 ~88 ~34 stone 0  
fill ~18 ~88 ~13 ~20 ~88 ~13 stone 0  
fill ~18 ~88 ~35 ~20 ~88 ~35 stone 0 
setblock ~22 ~88 ~26 glowstone 0  
fill ~23 ~88 ~19 ~23 ~89 ~19 stone 0  
fill ~14 ~89 ~19 ~14 ~178 ~19 stone 0  
fill ~14 ~89 ~21 ~14 ~90 ~21 stone 0  
fill ~14 ~89 ~24 ~14 ~91 ~24 stone 0  
fill ~14 ~89 ~29 ~24 ~89 ~29 stone 0  
fill ~14 ~89 ~30 ~24 ~89 ~30 stone 0  
fill ~14 ~89 ~31 ~24 ~89 ~31 stone 0  
fill ~15 ~89 ~20 ~17 ~89 ~20 stone 0  
fill ~15 ~89 ~28 ~23 ~89 ~28 stone 0  
fill ~15 ~89 ~32 ~23 ~89 ~32 stone 0  
fill ~16 ~89 ~21 ~16 ~90 ~21 stonebrick 3  
fill ~16 ~89 ~27 ~16 ~92 ~27 stonebrick 3  
fill ~16 ~89 ~33 ~22 ~89 ~33 stone 0  
fill ~17 ~89 ~21 ~17 ~178 ~21 stone 0  
fill ~17 ~89 ~26 ~21 ~89 ~26 stone 0  
fill ~17 ~89 ~27 ~21 ~89 ~27 stone 0  
fill ~17 ~89 ~34 ~21 ~89 ~34 stone 0  
fill ~18 ~89 ~13 ~20 ~89 ~13 stone 0  
fill ~18 ~89 ~35 ~20 ~89 ~35 stone 0  
fill ~21 ~89 ~21 ~21 ~178 ~21 stone 0  
fill ~22 ~89 ~20 ~23 ~89 ~20 stone 0  
fill ~22 ~89 ~21 ~22 ~90 ~21 stonebrick 3  
fill ~22 ~89 ~26 ~22 ~91 ~26 stonebrick 3  
fill ~24 ~89 ~19 ~24 ~178 ~19 stone 0  
fill ~24 ~89 ~21 ~24 ~90 ~21 stone 0  
fill ~24 ~89 ~24 ~24 ~91 ~24 stone 0  
fill ~14 ~90 ~29 ~24 ~90 ~29 stone 0  
fill ~14 ~90 ~30 ~24 ~90 ~30 stone 0  
fill ~14 ~90 ~31 ~24 ~90 ~31 stone 0  
fill ~15 ~90 ~20 ~17 ~90 ~20 stone 0  
fill ~15 ~90 ~28 ~23 ~90 ~28 stone 0  
fill ~15 ~90 ~32 ~23 ~90 ~32 stone 0 
setblock ~16 ~90 ~16 glowstone 0  
fill ~16 ~90 ~33 ~22 ~90 ~33 stone 0  
fill ~17 ~90 ~26 ~21 ~90 ~26 stone 0  
fill ~17 ~90 ~27 ~21 ~90 ~27 stone 0  
fill ~17 ~90 ~34 ~21 ~90 ~34 stone 0  
fill ~18 ~90 ~13 ~20 ~90 ~13 stone 0  
fill ~18 ~90 ~35 ~20 ~90 ~35 stone 0  
fill ~22 ~90 ~20 ~23 ~90 ~20 stone 0  
fill ~14 ~91 ~20 ~17 ~91 ~20 stone 0  
fill ~14 ~91 ~22 ~14 ~92 ~22 stone 0  
fill ~14 ~91 ~25 ~14 ~94 ~25 stone 0  
fill ~14 ~91 ~26 ~14 ~93 ~26 stone 0  
fill ~14 ~91 ~29 ~24 ~91 ~29 stone 0  
fill ~14 ~91 ~30 ~24 ~91 ~30 stone 0  
fill ~14 ~91 ~31 ~24 ~91 ~31 stone 0  
fill ~15 ~91 ~21 ~17 ~91 ~21 stone 0  
fill ~15 ~91 ~28 ~23 ~91 ~28 stone 0  
fill ~15 ~91 ~32 ~23 ~91 ~32 stone 0  
fill ~16 ~91 ~22 ~16 ~92 ~22 stonebrick 3  
fill ~16 ~91 ~33 ~22 ~91 ~33 stone 0  
fill ~17 ~91 ~22 ~17 ~178 ~22 stone 0  
fill ~17 ~91 ~26 ~21 ~91 ~26 stone 0  
fill ~17 ~91 ~27 ~21 ~91 ~27 stone 0  
fill ~17 ~91 ~34 ~21 ~91 ~34 stone 0  
fill ~18 ~91 ~13 ~20 ~91 ~13 stone 0  
fill ~18 ~91 ~35 ~20 ~91 ~35 stone 0  
fill ~21 ~91 ~22 ~21 ~178 ~22 stone 0  
fill ~22 ~91 ~20 ~24 ~91 ~20 stone 0  
fill ~22 ~91 ~21 ~23 ~91 ~21 stone 0  
fill ~22 ~91 ~22 ~22 ~92 ~22 stonebrick 3  
fill ~24 ~91 ~22 ~24 ~92 ~22 stone 0  
fill ~24 ~91 ~25 ~24 ~94 ~25 stone 0  
fill ~24 ~91 ~26 ~24 ~93 ~26 stone 0  
fill ~14 ~92 ~20 ~14 ~178 ~20 stone 0  
fill ~14 ~92 ~29 ~24 ~92 ~29 stone 0  
fill ~14 ~92 ~30 ~24 ~92 ~30 stone 0  
fill ~14 ~92 ~31 ~24 ~92 ~31 stone 0  
fill ~15 ~92 ~21 ~17 ~92 ~21 stone 0  
fill ~15 ~92 ~28 ~23 ~92 ~28 stone 0  
fill ~15 ~92 ~32 ~23 ~92 ~32 stone 0  
fill ~16 ~92 ~20 ~16 ~178 ~20 stone 0  
fill ~16 ~92 ~33 ~22 ~92 ~33 stone 0  
fill ~17 ~92 ~26 ~21 ~92 ~26 stone 0  
fill ~17 ~92 ~27 ~21 ~92 ~27 stone 0  
fill ~17 ~92 ~34 ~21 ~92 ~34 stone 0  
fill ~18 ~92 ~13 ~20 ~92 ~13 stone 0  
fill ~18 ~92 ~35 ~20 ~92 ~35 stone 0  
fill ~22 ~92 ~20 ~22 ~178 ~20 stone 0  
fill ~22 ~92 ~21 ~23 ~92 ~21 stone 0 
setblock ~22 ~92 ~26 glowstone 0  
fill ~24 ~92 ~20 ~24 ~178 ~20 stone 0  
fill ~14 ~93 ~21 ~17 ~93 ~21 stone 0  
fill ~14 ~93 ~23 ~14 ~94 ~23 stone 0  
fill ~14 ~93 ~28 ~24 ~93 ~28 stone 0  
fill ~14 ~93 ~29 ~24 ~93 ~29 stone 0  
fill ~14 ~93 ~30 ~24 ~93 ~30 stone 0  
fill ~14 ~93 ~31 ~24 ~93 ~31 stone 0  
fill ~15 ~93 ~22 ~17 ~93 ~22 stone 0  
fill ~15 ~93 ~26 ~24 ~93 ~26 stone 0  
fill ~15 ~93 ~27 ~23 ~93 ~27 stone 0  
fill ~15 ~93 ~32 ~23 ~93 ~32 stone 0  
fill ~16 ~93 ~23 ~16 ~95 ~23 stonebrick 3  
fill ~16 ~93 ~33 ~22 ~93 ~33 stone 0  
fill ~17 ~93 ~23 ~17 ~178 ~23 stone 0  
fill ~17 ~93 ~34 ~21 ~93 ~34 stone 0  
fill ~18 ~93 ~13 ~20 ~93 ~13 stone 0  
fill ~18 ~93 ~35 ~20 ~93 ~35 stone 0  
fill ~21 ~93 ~23 ~21 ~178 ~23 stone 0  
fill ~22 ~93 ~21 ~24 ~93 ~21 stone 0  
fill ~22 ~93 ~22 ~23 ~93 ~22 stone 0  
fill ~22 ~93 ~23 ~22 ~95 ~23 stonebrick 3  
fill ~24 ~93 ~23 ~24 ~94 ~23 stone 0  
fill ~14 ~94 ~21 ~14 ~178 ~21 stone 0 
setblock ~14 ~94 ~24 stone 0  
fill ~14 ~94 ~28 ~24 ~94 ~28 stone 0  
fill ~14 ~94 ~29 ~24 ~94 ~29 stone 0  
fill ~14 ~94 ~30 ~24 ~94 ~30 stone 0  
fill ~14 ~94 ~31 ~24 ~94 ~31 stone 0  
fill ~15 ~94 ~22 ~17 ~94 ~22 stone 0  
fill ~15 ~94 ~26 ~23 ~94 ~26 stone 0  
fill ~15 ~94 ~27 ~23 ~94 ~27 stone 0  
fill ~15 ~94 ~32 ~23 ~94 ~32 stone 0  
fill ~16 ~94 ~21 ~16 ~178 ~21 stone 0  
fill ~16 ~94 ~24 ~16 ~112 ~24 stonebrick 3  
fill ~16 ~94 ~33 ~22 ~94 ~33 stone 0  
fill ~17 ~94 ~24 ~17 ~178 ~24 stone 0  
fill ~17 ~94 ~34 ~21 ~94 ~34 stone 0  
fill ~18 ~94 ~13 ~20 ~94 ~13 stone 0  
fill ~18 ~94 ~35 ~20 ~94 ~35 stone 0  
fill ~21 ~94 ~24 ~21 ~178 ~24 stone 0  
fill ~22 ~94 ~21 ~22 ~178 ~21 stone 0  
fill ~22 ~94 ~22 ~23 ~94 ~22 stone 0  
fill ~22 ~94 ~24 ~22 ~108 ~24 stonebrick 3  
fill ~24 ~94 ~21 ~24 ~178 ~21 stone 0 
setblock ~24 ~94 ~24 stone 0  
fill ~13 ~95 ~30 ~25 ~95 ~30 stone 0  
fill ~14 ~95 ~22 ~17 ~95 ~22 stone 0  
fill ~14 ~95 ~27 ~24 ~95 ~27 stone 0  
fill ~14 ~95 ~28 ~24 ~95 ~28 stone 0  
fill ~14 ~95 ~29 ~24 ~95 ~29 stone 0  
fill ~14 ~95 ~31 ~24 ~95 ~31 stone 0  
fill ~15 ~95 ~23 ~15 ~178 ~23 stone 0  
fill ~15 ~95 ~26 ~23 ~95 ~26 stone 0  
fill ~15 ~95 ~32 ~23 ~95 ~32 stone 0  
fill ~16 ~95 ~33 ~22 ~95 ~33 stone 0  
fill ~17 ~95 ~34 ~21 ~95 ~34 stone 0  
fill ~18 ~95 ~13 ~20 ~95 ~13 stone 0  
fill ~18 ~95 ~35 ~20 ~95 ~35 stone 0  
fill ~22 ~95 ~22 ~24 ~95 ~22 stone 0  
fill ~23 ~95 ~23 ~23 ~178 ~23 stone 0  
fill ~13 ~96 ~29 ~25 ~96 ~29 stone 0  
fill ~13 ~96 ~30 ~25 ~96 ~30 stone 0  
fill ~14 ~96 ~22 ~14 ~178 ~22 stone 0  
fill ~14 ~96 ~26 ~24 ~96 ~26 stone 0  
fill ~14 ~96 ~27 ~24 ~96 ~27 stone 0  
fill ~14 ~96 ~28 ~24 ~96 ~28 stone 0  
fill ~14 ~96 ~31 ~24 ~96 ~31 stone 0  
fill ~15 ~96 ~32 ~23 ~96 ~32 stone 0  
fill ~16 ~96 ~22 ~16 ~178 ~22 stone 0  
fill ~16 ~96 ~23 ~16 ~178 ~23 stone 0  
fill ~16 ~96 ~33 ~22 ~96 ~33 stone 0  
fill ~17 ~96 ~34 ~21 ~96 ~34 stone 0  
fill ~18 ~96 ~13 ~20 ~96 ~13 stone 0  
fill ~18 ~96 ~35 ~20 ~96 ~35 stone 0  
fill ~22 ~96 ~22 ~22 ~178 ~22 stone 0  
fill ~22 ~96 ~23 ~22 ~178 ~23 stone 0  
fill ~24 ~96 ~22 ~24 ~178 ~22 stone 0  
fill ~13 ~97 ~29 ~25 ~97 ~29 stone 0  
fill ~13 ~97 ~30 ~25 ~97 ~30 stone 0  
fill ~14 ~97 ~26 ~24 ~97 ~26 stone 0  
fill ~14 ~97 ~27 ~24 ~97 ~27 stone 0  
fill ~14 ~97 ~28 ~24 ~97 ~28 stone 0  
fill ~14 ~97 ~31 ~24 ~97 ~31 stone 0  
fill ~15 ~97 ~32 ~23 ~97 ~32 stone 0  
fill ~16 ~97 ~33 ~22 ~97 ~33 stone 0  
fill ~17 ~97 ~34 ~21 ~97 ~34 stone 0  
fill ~18 ~97 ~13 ~20 ~97 ~13 stone 0  
fill ~18 ~97 ~35 ~20 ~97 ~35 stone 0  
fill ~13 ~98 ~28 ~25 ~98 ~28 stone 0  
fill ~13 ~98 ~29 ~25 ~98 ~29 stone 0  
fill ~13 ~98 ~30 ~25 ~98 ~30 stone 0  
fill ~14 ~98 ~26 ~24 ~98 ~26 stone 0  
fill ~14 ~98 ~27 ~24 ~98 ~27 stone 0  
fill ~14 ~98 ~31 ~24 ~98 ~31 stone 0  
fill ~15 ~98 ~32 ~23 ~98 ~32 stone 0  
fill ~16 ~98 ~33 ~22 ~98 ~33 stone 0  
fill ~17 ~98 ~34 ~21 ~98 ~34 stone 0  
fill ~18 ~98 ~13 ~20 ~98 ~13 stone 0  
fill ~18 ~98 ~35 ~20 ~98 ~35 stone 0  
fill ~13 ~99 ~28 ~25 ~99 ~28 stone 0  
fill ~13 ~99 ~29 ~25 ~99 ~29 stone 0  
fill ~13 ~99 ~30 ~25 ~99 ~30 stone 0  
fill ~14 ~99 ~26 ~24 ~99 ~26 stone 0  
fill ~14 ~99 ~27 ~24 ~99 ~27 stone 0  
fill ~14 ~99 ~31 ~24 ~99 ~31 stone 0  
fill ~15 ~99 ~32 ~23 ~99 ~32 stone 0  
fill ~16 ~99 ~33 ~22 ~99 ~33 stone 0  
fill ~17 ~99 ~34 ~21 ~99 ~34 stone 0  
fill ~18 ~99 ~13 ~20 ~99 ~13 stone 0  
fill ~18 ~99 ~35 ~20 ~99 ~35 stone 0  
fill ~13 ~100 ~27 ~25 ~100 ~27 stone 0  
fill ~13 ~100 ~28 ~25 ~100 ~28 stone 0  
fill ~13 ~100 ~29 ~25 ~100 ~29 stone 0  
fill ~13 ~100 ~30 ~25 ~100 ~30 stone 0  
fill ~14 ~100 ~26 ~24 ~100 ~26 stone 0  
fill ~14 ~100 ~31 ~24 ~100 ~31 stone 0  
fill ~15 ~100 ~32 ~23 ~100 ~32 stone 0  
fill ~16 ~100 ~33 ~22 ~100 ~33 stone 0  
fill ~17 ~100 ~34 ~21 ~100 ~34 stone 0  
fill ~18 ~100 ~13 ~20 ~100 ~13 stone 0  
fill ~18 ~100 ~35 ~20 ~100 ~35 stone 0  
fill ~13 ~101 ~27 ~25 ~101 ~27 stone 0  
fill ~13 ~101 ~28 ~25 ~101 ~28 stone 0  
fill ~13 ~101 ~29 ~25 ~101 ~29 stone 0  
fill ~13 ~101 ~30 ~25 ~101 ~30 stone 0  
fill ~14 ~101 ~26 ~24 ~101 ~26 stone 0  
fill ~14 ~101 ~31 ~24 ~101 ~31 stone 0  
fill ~15 ~101 ~32 ~23 ~101 ~32 stone 0  
fill ~16 ~101 ~33 ~22 ~101 ~33 stone 0  
fill ~17 ~101 ~34 ~21 ~101 ~34 stone 0  
fill ~18 ~101 ~13 ~20 ~101 ~13 stone 0  
fill ~18 ~101 ~35 ~20 ~101 ~35 stone 0  
fill ~13 ~102 ~26 ~25 ~102 ~26 stone 0  
fill ~13 ~102 ~27 ~25 ~102 ~27 stone 0  
fill ~13 ~102 ~28 ~25 ~102 ~28 stone 0  
fill ~13 ~102 ~29 ~25 ~102 ~29 stone 0  
fill ~13 ~102 ~30 ~25 ~102 ~30 stone 0   
fill ~14 ~102 ~31 ~24 ~102 ~31 stone 0  
fill ~15 ~102 ~32 ~23 ~102 ~32 stone 0  
fill ~16 ~102 ~33 ~22 ~102 ~33 stone 0  
fill ~17 ~102 ~34 ~21 ~102 ~34 stone 0  
fill ~18 ~102 ~13 ~20 ~102 ~13 stone 0  
fill ~18 ~102 ~35 ~20 ~102 ~35 stone 0  
fill ~13 ~103 ~26 ~25 ~103 ~26 stone 0  
fill ~13 ~103 ~27 ~25 ~103 ~27 stone 0  
fill ~13 ~103 ~28 ~25 ~103 ~28 stone 0  
fill ~13 ~103 ~29 ~25 ~103 ~29 stone 0  
fill ~13 ~103 ~30 ~25 ~103 ~30 stone 0  
fill ~14 ~103 ~31 ~24 ~103 ~31 stone 0  
fill ~15 ~103 ~32 ~23 ~103 ~32 stone 0  
fill ~16 ~103 ~33 ~22 ~103 ~33 stone 0  
fill ~17 ~103 ~34 ~21 ~103 ~34 stone 0  
fill ~18 ~103 ~13 ~20 ~103 ~13 stone 0  
fill ~18 ~103 ~35 ~20 ~103 ~35 stone 0  
fill ~13 ~104 ~25 ~13 ~114 ~25 stone 0  
fill ~13 ~104 ~26 ~25 ~104 ~26 stone 0  
fill ~13 ~104 ~27 ~25 ~104 ~27 stone 0  
fill ~13 ~104 ~28 ~25 ~104 ~28 stone 0  
fill ~13 ~104 ~29 ~25 ~104 ~29 stone 0  
fill ~13 ~104 ~30 ~25 ~104 ~30 stone 0  
fill ~14 ~104 ~31 ~24 ~104 ~31 stone 0  
fill ~15 ~104 ~32 ~23 ~104 ~32 stone 0  
fill ~16 ~104 ~33 ~22 ~104 ~33 stone 0  
fill ~17 ~104 ~34 ~21 ~104 ~34 stone 0  
fill ~18 ~104 ~13 ~20 ~104 ~13 stone 0  
fill ~18 ~104 ~35 ~20 ~104 ~35 stone 0  
fill ~25 ~104 ~25 ~25 ~114 ~25 stone 0  
fill ~13 ~105 ~26 ~25 ~105 ~26 stone 0  
fill ~13 ~105 ~27 ~25 ~105 ~27 stone 0  
fill ~13 ~105 ~28 ~25 ~105 ~28 stone 0  
fill ~13 ~105 ~29 ~25 ~105 ~29 stone 0  
fill ~14 ~105 ~31 ~24 ~105 ~31 stone 0  
fill ~15 ~105 ~30 ~15 ~139 ~30 stonebrick 3  
fill ~15 ~105 ~32 ~23 ~105 ~32 stone 0  
fill ~16 ~105 ~30 ~22 ~105 ~30 stone 0  
fill ~16 ~105 ~33 ~22 ~105 ~33 stone 0  
fill ~17 ~105 ~34 ~21 ~105 ~34 stone 0  
fill ~18 ~105 ~13 ~20 ~105 ~13 stone 0  
fill ~18 ~105 ~35 ~20 ~105 ~35 stone 0  
fill ~23 ~105 ~30 ~23 ~139 ~30 stonebrick 3  
fill ~13 ~106 ~24 ~13 ~116 ~24 stone 0  
fill ~13 ~106 ~26 ~25 ~106 ~26 stone 0  
fill ~13 ~106 ~27 ~25 ~106 ~27 stone 0  
fill ~13 ~106 ~28 ~25 ~106 ~28 stone 0  
fill ~13 ~106 ~29 ~25 ~106 ~29 stone 0  
fill ~14 ~106 ~31 ~24 ~106 ~31 stone 0  
fill ~15 ~106 ~32 ~23 ~106 ~32 stone 0  
fill ~16 ~106 ~30 ~22 ~106 ~30 stone 0  
fill ~16 ~106 ~33 ~22 ~106 ~33 stone 0  
fill ~17 ~106 ~34 ~21 ~106 ~34 stone 0  
fill ~18 ~106 ~13 ~20 ~106 ~13 stone 0  
fill ~18 ~106 ~35 ~20 ~106 ~35 stone 0  
fill ~25 ~106 ~24 ~25 ~116 ~24 stone 0  
fill ~13 ~107 ~26 ~25 ~107 ~26 stone 0  
fill ~13 ~107 ~27 ~25 ~107 ~27 stone 0  
fill ~13 ~107 ~28 ~25 ~107 ~28 stone 0  
fill ~14 ~107 ~31 ~24 ~107 ~31 stone 0  
fill ~15 ~107 ~29 ~15 ~141 ~29 stonebrick 3  
fill ~15 ~107 ~32 ~23 ~107 ~32 stone 0  
fill ~16 ~107 ~29 ~22 ~107 ~29 stone 0  
fill ~16 ~107 ~30 ~22 ~107 ~30 stone 0  
fill ~16 ~107 ~33 ~22 ~107 ~33 stone 0  
fill ~17 ~107 ~34 ~21 ~107 ~34 stone 0  
fill ~18 ~107 ~13 ~20 ~107 ~13 stone 0  
fill ~18 ~107 ~35 ~20 ~107 ~35 stone 0  
fill ~23 ~107 ~29 ~23 ~141 ~29 stonebrick 3  
fill ~13 ~108 ~23 ~13 ~118 ~23 stone 0  
fill ~13 ~108 ~26 ~25 ~108 ~26 stone 0  
fill ~13 ~108 ~27 ~15 ~108 ~27 stone 0  
fill ~13 ~108 ~28 ~15 ~108 ~28 stone 0  
fill ~14 ~108 ~31 ~24 ~108 ~31 stone 0  
fill ~15 ~108 ~32 ~23 ~108 ~32 stone 0 
setblock ~16 ~108 ~25 glowstone 0  
fill ~16 ~108 ~30 ~22 ~108 ~30 stone 0  
fill ~16 ~108 ~33 ~22 ~108 ~33 stone 0  
fill ~17 ~108 ~27 ~25 ~108 ~27 stone 0  
fill ~17 ~108 ~28 ~25 ~108 ~28 stone 0  
fill ~17 ~108 ~29 ~22 ~108 ~29 stone 0  
fill ~17 ~108 ~34 ~21 ~108 ~34 stone 0  
fill ~18 ~108 ~13 ~20 ~108 ~13 stone 0  
fill ~18 ~108 ~35 ~20 ~108 ~35 stone 0  
fill ~25 ~108 ~23 ~25 ~118 ~23 stone 0  
fill ~13 ~109 ~26 ~25 ~109 ~26 stone 0  
fill ~13 ~109 ~27 ~25 ~109 ~27 stone 0  
fill ~14 ~109 ~31 ~24 ~109 ~31 stone 0  
fill ~15 ~109 ~28 ~15 ~143 ~28 lit_redstone_lamp 0  
fill ~15 ~109 ~32 ~23 ~109 ~32 stone 0  
fill ~16 ~109 ~25 ~16 ~176 ~25 stonebrick 3  
fill ~16 ~109 ~28 ~16 ~143 ~28 redstone_block 0  
fill ~16 ~109 ~30 ~22 ~109 ~30 stone 0  
fill ~16 ~109 ~33 ~22 ~109 ~33 stone 0  
fill ~17 ~109 ~28 ~21 ~109 ~28 stone 0  
fill ~17 ~109 ~29 ~21 ~109 ~29 stone 0  
fill ~17 ~109 ~34 ~21 ~109 ~34 stone 0  
fill ~18 ~109 ~13 ~20 ~109 ~13 stone 0  
fill ~18 ~109 ~35 ~20 ~109 ~35 stone 0 
setblock ~22 ~109 ~24 glowstone 0  
fill ~22 ~109 ~28 ~22 ~143 ~28 redstone_block 0  
fill ~23 ~109 ~28 ~23 ~143 ~28 lit_redstone_lamp 0  
fill ~13 ~110 ~22 ~13 ~120 ~22 stone 0  
fill ~13 ~110 ~26 ~25 ~110 ~26 stone 0  
fill ~13 ~110 ~27 ~25 ~110 ~27 stone 0  
fill ~14 ~110 ~31 ~24 ~110 ~31 stone 0  
fill ~15 ~110 ~32 ~23 ~110 ~32 stone 0  
fill ~16 ~110 ~29 ~21 ~110 ~29 stone 0  
fill ~16 ~110 ~30 ~22 ~110 ~30 stone 0  
fill ~16 ~110 ~33 ~22 ~110 ~33 stone 0  
fill ~17 ~110 ~28 ~21 ~110 ~28 stone 0  
fill ~17 ~110 ~34 ~21 ~110 ~34 stone 0  
fill ~18 ~110 ~13 ~20 ~110 ~13 stone 0  
