setblock ~15~4~3 minecraft:stained_glass 0
setblock ~16~3~3 minecraft:stained_glass 0
setblock ~17~5~3 minecraft:stained_glass 0
setblock ~15~5~4 minecraft:stained_glass 0
setblock ~16~4~4 minecraft:stained_glass 0
fill ~16~6~4 ~17~6~4 minecraft:stained_glass 0
setblock ~16~7~4 minecraft:stained_glass 0
setblock ~18~8~4 minecraft:stained_glass 0
setblock ~15~4~5 minecraft:stained_glass 0
fill ~15~6~5 ~15~7~5 minecraft:stained_glass 0
fill ~16~5~5 ~16~8~5 minecraft:snow
fill ~17~6~5 ~17~8~5 minecraft:snow
fill ~17~9~5 ~18~9~5 minecraft:stained_glass 0
fill ~18~5~5 ~18~7~5 minecraft:stained_glass 0
setblock ~19~4~5 minecraft:stained_glass 0
setblock ~13~5~6 minecraft:stained_glass 0
setblock ~13~7~6 minecraft:stained_glass 0
setblock ~15~5~6 minecraft:stained_glass 0
setblock ~15~6~6 minecraft:wool 0
setblock ~15~7~6 minecraft:snow
fill ~15~8~6 ~15~9~6 minecraft:stained_glass 0
setblock ~16~4~6 minecraft:stained_glass 0
setblock ~16~5~6 minecraft:wool 0
fill ~16~8~6 ~16~10~6 minecraft:snow
setblock ~17~5~6 minecraft:stained_glass 0
setblock ~17~6~6 minecraft:wool 0
fill ~17~9~6 ~18~9~6 minecraft:wool 0
setblock ~17~10~6 minecraft:snow
fill ~18~7~6 ~18~8~6 minecraft:snow
setblock ~18~10~6 minecraft:stained_glass 0
fill ~19~5~6 ~19~6~6 minecraft:stained_glass 0
setblock ~19~8~6 minecraft:stained_glass 0
setblock ~13~6~7 minecraft:stained_glass 0
setblock ~13~8~7 minecraft:stained_glass 0
setblock ~14~4~7 minecraft:stained_glass 0
fill ~14~6~7 ~14~6~8 minecraft:wool 0
fill ~14~7~7 ~14~8~7 minecraft:snow
setblock ~14~9~7 minecraft:stained_glass 0
setblock ~15~3~7 minecraft:stained_glass 0
fill ~15~5~7 ~16~5~8 minecraft:calcite
fill ~15~8~7 ~15~9~7 minecraft:wool 0
fill ~15~10~7 ~15~11~7 minecraft:snow
fill ~16~11~7 ~18~11~7 minecraft:snow
fill ~17~5~7 ~17~5~8 minecraft:wool 0
setblock ~17~12~7 minecraft:snow
fill ~18~6~7 ~19~6~7 minecraft:snow
setblock ~18~10~7 minecraft:wool 0
fill ~19~7~7 ~19~9~7 minecraft:snow
setblock ~19~10~7 minecraft:stained_glass 0
setblock ~20~6~7 minecraft:stained_glass 0
setblock ~12~9~8 minecraft:stained_glass 0
fill ~14~5~8 ~14~5~9 minecraft:wool 0
fill ~14~7~8 ~14~9~8 minecraft:wool 0
fill ~14~10~8 ~14~11~8 minecraft:snow
setblock ~15~4~8 minecraft:stained_glass 0
fill ~15~12~8 ~16~12~8 minecraft:snow
setblock ~16~3~8 minecraft:stained_glass 0
fill ~17~13~8 ~17~13~9 minecraft:snow
fill ~18~6~8 ~18~6~11 minecraft:calcite
fill ~18~12~8 ~19~12~8 minecraft:snow
fill ~19~6~8 ~19~6~9 minecraft:wool 0
fill ~19~9~8 ~19~10~8 minecraft:wool 0
setblock ~19~11~8 minecraft:snow
fill ~20~7~8 ~20~8~8 minecraft:snow
setblock ~20~9~8 minecraft:stained_glass 0
setblock ~12~7~9 minecraft:stained_glass 0
setblock ~12~10~9 minecraft:stained_glass 0
setblock ~13~4~9 minecraft:stained_glass 0
fill ~13~6~9 ~13~10~10 minecraft:snow
setblock ~14~11~9 minecraft:wool 0
setblock ~15~3~9 minecraft:stained_glass 0
setblock ~15~5~9 minecraft:wool 8
setblock ~15~12~9 minecraft:wool 0
setblock ~16~4~9 minecraft:stained_glass 0
fill ~16~5~9 ~16~5~10 minecraft:calcite
setblock ~16~13~9 minecraft:snow
setblock ~17~5~9 minecraft:wool 8
setblock ~18~4~9 minecraft:stained_glass 0
fill ~18~13~9 ~19~13~9 minecraft:snow
fill ~19~7~9 ~19~7~12 minecraft:wool 0
setblock ~20~6~9 minecraft:stained_glass 0
fill ~20~8~9 ~20~8~11 minecraft:wool 0
fill ~20~9~9 ~20~12~9 minecraft:snow
setblock ~12~8~10 minecraft:stained_glass 0
fill ~13~11~10 ~13~11~11 minecraft:snow
fill ~14~6~10 ~14~6~11 minecraft:calcite
fill ~14~12~10 ~14~12~11 minecraft:calcite
setblock ~15~4~10 minecraft:stained_glass 0
fill ~15~5~10 ~15~5~11 minecraft:calcite
setblock ~15~13~10 minecraft:snow
setblock ~16~13~10 minecraft:wool 0
setblock ~17~6~10 minecraft:wool 8
fill ~17~14~10 ~19~14~10 minecraft:wool 8
setblock ~18~5~10 minecraft:stained_glass 0
fill ~19~13~10 ~20~13~10 minecraft:snow
setblock ~20~7~10 minecraft:stained_glass 0
setblock ~20~11~10 minecraft:wool 8
setblock ~20~12~10 minecraft:snow
fill ~21~9~10 ~21~10~10 minecraft:wool 0
setblock ~11~8~11 minecraft:stained_glass 0
setblock ~13~6~11 minecraft:stained_glass 0
fill ~13~7~11 ~13~10~11 minecraft:wool 0
setblock ~15~13~11 minecraft:wool 8
setblock ~16~5~11 minecraft:wool 8
setblock ~16~14~11 minecraft:planks 5
fill ~17~6~11 ~17~6~14 minecraft:calcite
fill ~17~15~11 ~18~15~11 minecraft:planks 5
fill ~19~15~11 ~19~15~12 minecraft:planks 4
fill ~20~9~11 ~20~9~12 minecraft:calcite
fill ~20~13~11 ~20~14~11 minecraft:wool 8
fill ~21~10~11 ~21~10~12 minecraft:wool 0
fill ~21~11~11 ~21~11~12 minecraft:wool 8
setblock ~21~12~11 minecraft:wool 8
setblock ~11~9~12 minecraft:stained_glass 0
fill ~12~7~12 ~13~7~12 minecraft:stained_glass 0
fill ~12~9~12 ~13~9~12 minecraft:snow
fill ~12~10~12 ~12~10~13 minecraft:snow
fill ~13~8~12 ~13~8~13 minecraft:wool 0
setblock ~13~11~12 minecraft:wool 0
setblock ~13~12~12 minecraft:wool 8
setblock ~14~5~12 minecraft:stained_glass 0
fill ~14~6~12 ~14~7~12 minecraft:wool 0
setblock ~14~13~12 minecraft:planks 5
fill ~15~6~12 ~15~6~13 minecraft:calcite
setblock ~15~14~12 minecraft:planks 4
setblock ~16~6~12 minecraft:wool 8
fill ~16~15~12 ~17~15~12 minecraft:red_sandstone 3
setblock ~17~16~12 minecraft:stained_glass 1
setblock ~18~5~12 minecraft:stained_glass 0
fill ~18~7~12 ~18~7~14 minecraft:calcite
setblock ~18~16~12 minecraft:red_sandstone 3
fill ~19~8~12 ~19~8~13 minecraft:calcite
setblock ~19~16~12 minecraft:wool 1
setblock ~20~15~12 minecraft:planks 4
setblock ~20~16~12 minecraft:stained_glass 1
setblock ~21~12~12 minecraft:planks 5
fill ~21~13~12 ~21~14~12 minecraft:wool 12
setblock ~12~8~13 minecraft:stained_glass 0
setblock ~12~9~13 minecraft:snow
fill ~12~11~13 ~12~12~13 minecraft:snow
setblock ~13~13~13 minecraft:planks 5
setblock ~14~6~13 minecraft:stained_glass 0
setblock ~14~7~13 minecraft:wool 0
setblock ~14~14~13 minecraft:planks 4
setblock ~15~15~13 minecraft:wool 1
setblock ~15~16~13 minecraft:stained_glass 1
fill ~16~6~13 ~16~6~15 minecraft:calcite
setblock ~16~16~13 minecraft:wool 1
setblock ~17~4~13 minecraft:stained_glass 0
setblock ~17~16~13 minecraft:red_sandstone 3
setblock ~18~6~13 minecraft:stained_glass 0
setblock ~18~16~13 minecraft:wool 1
fill ~18~17~13 ~18~17~14 minecraft:stained_glass 1
fill ~19~16~13 ~19~16~14 minecraft:concrete 1
fill ~20~9~13 ~20~9~14 minecraft:wool 8
setblock ~20~15~13 minecraft:concrete 1
fill ~20~16~13 ~20~16~14 minecraft:wool 1
setblock ~21~10~13 minecraft:wool 8
setblock ~21~11~13 minecraft:planks 5
setblock ~21~13~13 minecraft:planks 4
setblock ~21~14~13 minecraft:wool 1
setblock ~21~15~13 minecraft:stained_glass 1
fill ~22~12~13 ~22~12~15 minecraft:wool 12
fill ~12~10~14 ~12~11~14 minecraft:wool 0
setblock ~12~12~14 minecraft:snow
setblock ~12~13~14 minecraft:planks 5
fill ~13~9~14 ~13~9~15 minecraft:wool 0
setblock ~13~14~14 minecraft:planks 4
fill ~14~8~14 ~14~8~15 minecraft:wool 0
setblock ~14~15~14 minecraft:planks 4
fill ~14~16~14 ~15~16~14 minecraft:wool 1
fill ~15~7~14 ~15~7~17 minecraft:calcite
fill ~16~16~14 ~18~16~14 minecraft:concrete 1
fill ~16~17~14 ~17~17~14 minecraft:stained_glass 1
setblock ~17~5~14 minecraft:stained_glass 0
fill ~19~8~14 ~19~8~15 minecraft:wool 8
setblock ~19~17~14 minecraft:stained_glass 1
setblock ~20~10~14 minecraft:planks 5
fill ~21~11~14 ~21~11~16 minecraft:wool 12
setblock ~21~14~14 minecraft:concrete 1
setblock ~21~15~14 minecraft:wool 1
setblock ~21~16~14 minecraft:stained_glass 1
fill ~22~13~14 ~22~13~15 minecraft:wool 12
setblock ~12~10~15 minecraft:wool 8
setblock ~12~11~15 minecraft:wool 0
setblock ~12~12~15 minecraft:wool 8
setblock ~12~13~15 minecraft:planks 4
fill ~12~14~15 ~12~14~16 minecraft:wool 1
setblock ~13~15~15 minecraft:planks 4
setblock ~14~16~15 minecraft:planks 4
setblock ~15~5~15 minecraft:stained_glass 0
fill ~15~17~15 ~20~17~15 minecraft:wool 1
setblock ~17~6~15 minecraft:wool 8
fill ~18~7~15 ~18~7~16 minecraft:wool 8
setblock ~19~9~15 minecraft:planks 5
fill ~20~10~15 ~20~10~16 minecraft:wool 12
setblock ~21~15~15 minecraft:concrete 1
setblock ~21~16~15 minecraft:wool 1
fill ~22~14~15 ~22~14~16 minecraft:wool 12
fill ~11~12~16 ~11~13~16 minecraft:wool 12
fill ~12~11~16 ~12~11~17 minecraft:planks 5
setblock ~12~15~16 minecraft:stained_glass 1
setblock ~13~9~16 minecraft:calcite
fill ~13~10~16 ~13~10~17 minecraft:wool 8
setblock ~13~15~16 minecraft:red_sandstone 3
fill ~13~16~16 ~14~16~16 minecraft:wool 1
fill ~14~8~16 ~14~8~17 minecraft:calcite
setblock ~14~17~16 minecraft:wool 1
setblock ~15~6~16 minecraft:stained_glass 0
fill ~15~17~16 ~19~17~16 minecraft:concrete 1
fill ~16~7~16 ~17~7~16 minecraft:calcite
fill ~16~18~16 ~18~18~16 minecraft:stained_glass 1
fill ~18~8~16 ~18~8~18 minecraft:wool 8
setblock ~19~9~16 minecraft:wool 8
setblock ~20~17~16 minecraft:wool 1
fill ~21~12~16 ~21~12~17 minecraft:wool 12
setblock ~21~16~16 minecraft:concrete 1
setblock ~21~17~16 minecraft:stained_glass 1
fill ~22~13~16 ~22~13~18 minecraft:wool 1
fill ~22~15~16 ~22~15~21 minecraft:wool 1
setblock ~22~16~16 minecraft:stained_glass 1
fill ~35~0~16 ~35~0~24 minecraft:stained_hardened_clay 1
fill ~11~13~17 ~11~13~18 minecraft:wool 12
fill ~12~12~17 ~12~12~18 minecraft:planks 4
setblock ~12~14~17 minecraft:planks 4
setblock ~12~15~17 minecraft:wool 1
setblock ~13~16~17 minecraft:wool 1
setblock ~13~17~17 minecraft:stained_glass 1
fill ~14~9~17 ~14~9~18 minecraft:wool 8
setblock ~14~17~17 minecraft:concrete 1
fill ~14~18~17 ~19~18~17 minecraft:wool 1
setblock ~16~5~17 minecraft:stained_glass 0
fill ~16~7~17 ~16~7~18 minecraft:calcite
fill ~17~7~17 ~17~7~18 minecraft:wool 8
setblock ~19~9~17 minecraft:wool 12
fill ~20~10~17 ~20~11~17 minecraft:planks 4
fill ~20~17~17 ~20~17~18 minecraft:concrete 1
fill ~20~18~17 ~20~18~18 minecraft:stained_glass 1
fill ~21~17~17 ~21~17~18 minecraft:wool 1
fill ~22~14~17 ~22~14~20 minecraft:wool 1
fill ~22~16~17 ~22~16~21 minecraft:wool 1
fill ~33~0~17 ~34~0~24 minecraft:stained_hardened_clay 1
fill ~36~0~17 ~36~0~24 minecraft:stained_hardened_clay 1
setblock ~11~14~18 minecraft:wool 12
fill ~12~15~18 ~12~15~19 minecraft:planks 4
setblock ~13~10~18 minecraft:planks 5
fill ~13~11~18 ~13~11~19 minecraft:red_sandstone 3
setblock ~13~16~18 minecraft:concrete 1
setblock ~13~17~18 minecraft:wool 1
setblock ~14~18~18 minecraft:concrete 1
setblock ~14~19~18 minecraft:stained_glass 1
fill ~15~8~18 ~15~8~19 minecraft:wool 8
setblock ~15~9~18 minecraft:wool 8
fill ~15~19~18 ~18~19~18 minecraft:wool 1
setblock ~16~6~18 minecraft:stained_glass 0
fill ~19~9~18 ~19~9~19 minecraft:planks 5
setblock ~19~18~18 minecraft:concrete 1
setblock ~19~19~18 minecraft:stained_glass 1
setblock ~20~10~18 minecraft:wool 12
fill ~20~11~18 ~20~11~19 minecraft:red_sandstone 3
fill ~21~12~18 ~21~12~19 minecraft:concrete 1
fill ~32~0~18 ~32~0~24 minecraft:stained_hardened_clay 1
fill ~37~0~18 ~37~0~24 minecraft:stained_hardened_clay 1
fill ~11~14~19 ~11~14~20 minecraft:red_sandstone 3
setblock ~11~15~19 minecraft:stained_glass 1
setblock ~12~12~19 minecraft:stained_glass 1
fill ~12~13~19 ~12~13~20 minecraft:planks 4
setblock ~12~16~19 minecraft:wool 1
setblock ~12~17~19 minecraft:stained_glass 1
setblock ~13~12~19 minecraft:stained_hardened_clay 1
setblock ~13~17~19 minecraft:concrete 1
setblock ~13~18~19 minecraft:wool 1
setblock ~13~19~19 minecraft:stained_glass 1
setblock ~14~9~19 minecraft:planks 5
fill ~14~10~19 ~14~10~20 minecraft:stained_hardened_clay 1
setblock ~14~19~19 minecraft:wool 1
setblock ~15~19~19 minecraft:concrete 1
setblock ~15~20~19 minecraft:stained_glass 1
setblock ~16~8~19 minecraft:wool 8
fill ~16~20~19 ~17~20~19 minecraft:wool 1
fill ~17~8~19 ~18~8~19 minecraft:planks 5
fill ~18~9~19 ~18~9~21 minecraft:planks 4
setblock ~18~19~19 minecraft:concrete 1
setblock ~18~20~19 minecraft:stained_glass 1
setblock ~19~10~19 minecraft:stained_hardened_clay 1
setblock ~19~19~19 minecraft:wool 1
setblock ~20~18~19 minecraft:concrete 1
setblock ~20~19~19 minecraft:stained_glass 1
fill ~21~13~19 ~21~13~21 minecraft:concrete 1
setblock ~21~17~19 minecraft:concrete 1
setblock ~21~18~19 minecraft:wool 1
setblock ~22~13~19 minecraft:stained_glass 1
setblock ~22~17~19 minecraft:stained_glass 1
fill ~31~0~19 ~31~0~24 minecraft:stained_hardened_clay 1
fill ~11~15~20 ~11~15~21 minecraft:red_sandstone 3
setblock ~11~16~20 minecraft:stained_glass 1
setblock ~12~16~20 minecraft:planks 4
setblock ~12~17~20 minecraft:wool 1
setblock ~12~18~20 minecraft:stained_glass 1
fill ~13~12~20 ~13~12~22 minecraft:red_sandstone 3
setblock ~13~18~20 minecraft:concrete 1
setblock ~13~19~20 minecraft:wool 1
setblock ~13~20~20 minecraft:stained_glass 1
fill ~14~11~20 ~14~11~22 minecraft:stained_hardened_clay 1
fill ~14~20~20 ~17~20~20 minecraft:concrete 1
setblock ~15~8~20 minecraft:planks 5
fill ~15~9~20 ~15~9~21 minecraft:planks 4
setblock ~16~8~20 minecraft:calcite
setblock ~17~8~20 minecraft:wool 8
setblock ~18~8~20 minecraft:planks 5
setblock ~18~20~20 minecraft:wool 1
setblock ~19~10~20 minecraft:red_sandstone 3
fill ~19~11~20 ~19~11~22 minecraft:stained_hardened_clay 1
setblock ~19~19~20 minecraft:concrete 1
setblock ~19~20~20 minecraft:stained_glass 1
fill ~20~12~20 ~20~12~22 minecraft:red_sandstone 3
setblock ~20~19~20 minecraft:wool 1
setblock ~21~12~20 minecraft:stained_glass 1
setblock ~21~18~20 minecraft:concrete 1
setblock ~21~19~20 minecraft:stained_glass 1
fill ~22~0~20 ~24~0~25 minecraft:stained_hardened_clay 1
fill ~22~17~20 ~22~17~22 minecraft:wool 1
setblock ~22~18~20 minecraft:stained_glass 1
fill ~29~0~20 ~29~0~25 minecraft:stained_hardened_clay 1
setblock ~11~14~21 minecraft:stained_glass 1
fill ~11~16~21 ~11~16~22 minecraft:red_sandstone 3
setblock ~11~17~21 minecraft:stained_glass 1
setblock ~12~13~21 minecraft:concrete 1
setblock ~12~14~21 minecraft:red_sandstone 3
setblock ~12~17~21 minecraft:concrete 1
setblock ~12~18~21 minecraft:wool 1
fill ~13~19~21 ~13~20~21 minecraft:concrete 1
setblock ~14~10~21 minecraft:stained_glass 1
setblock ~14~20~21 minecraft:concrete 1
setblock ~14~21~21 minecraft:stained_glass 1
setblock ~15~10~21 minecraft:stained_hardened_clay 1
fill ~15~21~21 ~16~21~21 minecraft:wool 1
fill ~16~8~21 ~17~8~21 minecraft:planks 5
fill ~17~20~21 ~18~20~21 minecraft:concrete 1
setblock ~17~21~21 minecraft:stained_glass 1
setblock ~18~8~21 minecraft:stained_glass 12
fill ~18~10~21 ~18~10~23 minecraft:stained_hardened_clay 1
fill ~19~0~21 ~21~0~27 minecraft:stained_hardened_clay 1
setblock ~19~20~21 minecraft:wool 1
setblock ~20~19~21 minecraft:concrete 1
setblock ~20~20~21 minecraft:stained_glass 1
fill ~21~14~21 ~21~14~22 minecraft:concrete 1
setblock ~21~19~21 minecraft:wool 1
setblock ~22~14~21 minecraft:stained_glass 1
setblock ~22~18~21 minecraft:wool 1
fill ~25~0~21 ~28~0~25 minecraft:stained_hardened_clay 1
fill ~30~0~21 ~30~0~25 minecraft:stained_hardened_clay 1
setblock ~11~15~22 minecraft:stained_glass 1
fill ~11~17~22 ~11~17~24 minecraft:wool 1
setblock ~12~13~22 minecraft:stained_glass 1
setblock ~12~14~22 minecraft:concrete 1
setblock ~12~15~22 minecraft:red_sandstone 3
setblock ~12~18~22 minecraft:concrete 1
setblock ~12~19~22 minecraft:wool 1
setblock ~13~13~22 minecraft:stained_hardened_clay 1
setblock ~13~20~22 minecraft:concrete 1
fill ~13~21~22 ~14~21~22 minecraft:wool 1
setblock ~15~10~22 minecraft:planks 4
fill ~15~21~22 ~16~21~22 minecraft:red_sandstone 3
fill ~15~22~22 ~16~22~22 minecraft:stained_glass 1
setblock ~16~9~22 minecraft:wool 8
setblock ~17~8~22 minecraft:stained_glass 12
setblock ~17~9~22 minecraft:planks 5
fill ~17~21~22 ~19~21~22 minecraft:wool 1
fill ~18~0~22 ~18~0~31 minecraft:stained_hardened_clay 1
fill ~20~13~22 ~20~13~23 minecraft:red_sandstone 3
setblock ~20~20~22 minecraft:wool 1
setblock ~21~13~22 minecraft:stained_glass 1
fill ~21~15~22 ~21~16~22 minecraft:concrete 1
fill ~21~18~22 ~21~19~25 minecraft:concrete 1
setblock ~22~16~22 minecraft:stained_glass 1
setblock ~22~18~22 minecraft:stained_glass 1
setblock ~11~16~23 minecraft:wool 1
fill ~11~18~23 ~11~18~24 minecraft:wool 1
setblock ~12~14~23 minecraft:stained_glass 1
setblock ~12~15~23 minecraft:concrete 1
fill ~12~19~23 ~12~20~23 minecraft:concrete 1
setblock ~12~21~23 minecraft:wool 1
setblock ~12~22~23 minecraft:stained_glass 1
setblock ~13~12~23 minecraft:stained_glass 1
fill ~13~13~23 ~13~13~24 minecraft:red_sandstone 3
setblock ~13~14~23 minecraft:stained_hardened_clay 1
fill ~13~22~23 ~18~22~23 minecraft:red_sandstone 3
setblock ~14~11~23 minecraft:stained_glass 1
fill ~14~12~23 ~14~12~24 minecraft:stained_hardened_clay 1
setblock ~14~23~23 minecraft:stained_glass 1
setblock ~15~10~23 minecraft:stained_glass 12
fill ~15~11~23 ~15~11~24 minecraft:stained_hardened_clay 1
fill ~15~23~23 ~16~23~23 minecraft:wool 1
setblock ~15~24~23 minecraft:stained_glass 1
fill ~16~10~23 ~16~10~24 minecraft:planks 5
fill ~17~0~23 ~17~0~32 minecraft:stained_hardened_clay 1
fill ~17~9~23 ~17~9~24 minecraft:stained_glass 12
setblock ~17~10~23 minecraft:wool 8
setblock ~17~23~23 minecraft:stained_glass 1
setblock ~19~11~23 minecraft:red_sandstone 3
setblock ~19~12~23 minecraft:stained_hardened_clay 1
setblock ~19~22~23 minecraft:planks 4
fill ~20~14~23 ~20~15~23 minecraft:red_sandstone 3
setblock ~20~20~23 minecraft:red_sandstone 3
setblock ~20~21~23 minecraft:wool 1
fill ~21~16~23 ~21~17~23 minecraft:concrete 1
setblock ~21~20~23 minecraft:stained_glass 1
setblock ~38~0~23 minecraft:stained_hardened_clay 1
setblock ~11~16~24 minecraft:stained_glass 1
fill ~11~19~24 ~11~19~25 minecraft:wool 1
setblock ~12~15~24 minecraft:stained_glass 1
fill ~12~16~24 ~12~16~25 minecraft:concrete 1
fill ~12~20~24 ~12~21~24 minecraft:concrete 1
setblock ~12~22~24 minecraft:wool 1
setblock ~12~23~24 minecraft:stained_glass 1
fill ~13~14~24 ~13~15~24 minecraft:red_sandstone 3
setblock ~13~23~24 minecraft:wool 1
setblock ~13~24~24 minecraft:stained_glass 1
setblock ~14~23~24 minecraft:red_sandstone 3
fill ~14~24~24 ~17~24~24 minecraft:wool 1
fill ~15~25~24 ~16~25~24 minecraft:stained_glass 1
setblock ~17~10~24 minecraft:planks 5
fill ~17~23~24 ~18~23~24 minecraft:red_sandstone 3
setblock ~18~10~24 minecraft:stained_glass 12
setblock ~18~11~24 minecraft:stained_hardened_clay 1
setblock ~18~24~24 minecraft:stained_glass 1
setblock ~19~12~24 minecraft:red_sandstone 3
fill ~19~13~24 ~19~13~25 minecraft:wool 1
setblock ~19~14~24 minecraft:red_sandstone 3
setblock ~19~23~24 minecraft:planks 4
setblock ~20~14~24 minecraft:stained_glass 1
fill ~20~15~24 ~20~16~24 minecraft:red_sandstone 3
fill ~20~21~24 ~20~22~24 minecraft:red_sandstone 3
setblock ~21~17~24 minecraft:concrete 1
fill ~21~20~24 ~21~20~26 minecraft:concrete 1
setblock ~21~21~24 minecraft:stained_glass 1
setblock ~11~18~25 minecraft:stained_glass 1
fill ~11~20~25 ~11~21~26 minecraft:wool 1
fill ~12~17~25 ~12~18~25 minecraft:concrete 1
setblock ~12~22~25 minecraft:concrete 1
setblock ~12~23~25 minecraft:wool 1
setblock ~12~24~25 minecraft:stained_glass 1
setblock ~13~14~25 minecraft:stained_glass 1
fill ~13~15~25 ~13~15~26 minecraft:red_sandstone 3
setblock ~13~24~25 minecraft:stained_hardened_clay 1
fill ~13~25~25 ~13~25~26 minecraft:red_sandstone 3
setblock ~14~12~25 minecraft:stained_glass 1
fill ~14~13~25 ~14~14~25 minecraft:stained_hardened_clay 1
fill ~14~25~25 ~16~25~25 minecraft:stained_hardened_clay 1
setblock ~14~26~25 minecraft:stained_glass 1
setblock ~15~11~25 minecraft:stained_glass 12
setblock ~15~12~25 minecraft:stained_hardened_clay 1
setblock ~15~26~25 minecraft:red_sandstone 3
fill ~16~11~25 ~17~11~25 minecraft:planks 5
setblock ~16~26~25 minecraft:planks 4
setblock ~17~10~25 minecraft:stained_glass 12
setblock ~17~25~25 minecraft:red_sandstone 3
setblock ~17~26~25 minecraft:stained_glass 1
setblock ~18~11~25 minecraft:stained_glass 12
setblock ~18~12~25 minecraft:stained_hardened_clay 1
setblock ~18~24~25 minecraft:red_sandstone 3
setblock ~18~25~25 minecraft:planks 4
fill ~19~14~25 ~19~14~26 minecraft:wool 1
setblock ~19~15~25 minecraft:red_sandstone 3
setblock ~19~23~25 minecraft:stained_hardened_clay 1
setblock ~19~24~25 minecraft:planks 4
setblock ~20~15~25 minecraft:stained_glass 1
fill ~20~16~25 ~20~17~25 minecraft:red_sandstone 3
fill ~20~22~25 ~20~22~26 minecraft:red_sandstone 3
setblock ~21~21~25 minecraft:concrete 1
fill ~31~0~25 ~33~0~25 minecraft:wool 12
setblock ~34~0~25 minecraft:stained_hardened_clay 1
setblock ~11~19~26 minecraft:stained_glass 1
fill ~11~22~26 ~11~22~27 minecraft:wool 1
setblock ~11~23~26 minecraft:stained_glass 1
setblock ~12~16~26 minecraft:stained_glass 1
setblock ~12~17~26 minecraft:wool 1
fill ~12~18~26 ~12~19~26 minecraft:concrete 1
setblock ~12~23~26 minecraft:concrete 1
setblock ~12~24~26 minecraft:red_sandstone 3
setblock ~12~25~26 minecraft:stained_glass 1
fill ~13~16~26 ~13~16~27 minecraft:red_sandstone 3
fill ~13~26~26 ~14~26~26 minecraft:stained_hardened_clay 1
setblock ~14~14~26 minecraft:stained_hardened_clay 1
fill ~14~27~26 ~16~27~26 minecraft:planks 4
setblock ~15~12~26 minecraft:stained_glass 12
setblock ~15~13~26 minecraft:planks 5
fill ~16~0~26 ~16~0~28 minecraft:stained_hardened_clay 1
fill ~16~11~26 ~17~11~26 minecraft:stained_glass 12
fill ~16~12~26 ~17~12~26 minecraft:planks 5
fill ~17~26~26 ~18~26~26 minecraft:stained_hardened_clay 1
setblock ~18~12~26 minecraft:stained_glass 12
setblock ~18~13~26 minecraft:red_sandstone 3
fill ~19~15~26 ~19~15~27 minecraft:wool 1
setblock ~19~16~26 minecraft:red_sandstone 3
setblock ~19~24~26 minecraft:stained_hardened_clay 1
setblock ~19~25~26 minecraft:planks 4
setblock ~20~16~26 minecraft:stained_glass 1
setblock ~20~17~26 minecraft:red_sandstone 3
setblock ~20~18~26 minecraft:concrete 1
fill ~20~21~26 ~20~21~29 minecraft:concrete 1
setblock ~20~23~26 minecraft:planks 4
setblock ~21~18~26 minecraft:stained_glass 1
setblock ~21~19~26 minecraft:concrete 1
fill ~21~21~26 ~21~21~27 minecraft:stained_glass 1
setblock ~22~0~26 minecraft:stained_hardened_clay 1
fill ~23~0~26 ~25~0~31 minecraft:wool 12
setblock ~26~0~26 minecraft:stained_hardened_clay 1
fill ~27~0~26 ~32~0~29 minecraft:wool 12
setblock ~11~21~27 minecraft:stained_glass 1
fill ~11~23~27 ~11~23~28 minecraft:wool 1
setblock ~11~24~27 minecraft:stained_glass 1
setblock ~12~18~27 minecraft:stained_glass 1
setblock ~12~19~27 minecraft:wool 1
fill ~12~20~27 ~12~21~27 minecraft:concrete 1
setblock ~12~24~27 minecraft:concrete 1
setblock ~12~25~27 minecraft:wool 1
setblock ~12~26~27 minecraft:stained_glass 1
setblock ~13~15~27 minecraft:stained_glass 1
fill ~13~17~27 ~13~18~27 minecraft:red_sandstone 3
setblock ~13~26~27 minecraft:stained_hardened_clay 1
setblock ~13~27~27 minecraft:red_sandstone 3
setblock ~14~14~27 minecraft:planks 4
setblock ~14~15~27 minecraft:stained_hardened_clay 1
fill ~14~28~27 ~17~28~27 minecraft:red_sandstone 3
setblock ~15~13~27 minecraft:planks 4
fill ~16~12~27 ~17~12~27 minecraft:stained_glass 12
setblock ~16~13~27 minecraft:planks 5
setblock ~17~13~27 minecraft:planks 4
setblock ~17~27~27 minecraft:stained_hardened_clay 1
setblock ~18~13~27 minecraft:stained_glass 12
setblock ~18~14~27 minecraft:red_sandstone 3
setblock ~18~27~27 minecraft:planks 4
setblock ~19~16~27 minecraft:wool 1
setblock ~19~17~27 minecraft:red_sandstone 3
setblock ~19~25~27 minecraft:stained_hardened_clay 1
setblock ~19~26~27 minecraft:planks 4
setblock ~20~17~27 minecraft:stained_glass 1
setblock ~20~18~27 minecraft:red_sandstone 3
fill ~20~19~27 ~20~20~28 minecraft:concrete 1
fill ~20~22~27 ~20~22~29 minecraft:concrete 1
fill ~20~23~27 ~20~24~28 minecraft:red_sandstone 3
setblock ~20~25~27 minecraft:stained_glass 1
setblock ~21~20~27 minecraft:stained_glass 1
fill ~22~0~27 ~22~0~35 minecraft:wool 12
fill ~26~0~27 ~26~0~29 minecraft:wool 12
setblock ~11~22~28 minecraft:stained_glass 1
fill ~11~24~28 ~11~24~29 minecraft:wool 1
setblock ~11~25~28 minecraft:stained_glass 1
setblock ~12~20~28 minecraft:stained_glass 1
setblock ~12~21~28 minecraft:wool 1
setblock ~12~22~28 minecraft:concrete 1
setblock ~12~25~28 minecraft:concrete 1
setblock ~12~26~28 minecraft:wool 1
setblock ~12~27~28 minecraft:stained_glass 1
setblock ~13~18~28 minecraft:stained_glass 1
fill ~13~19~28 ~13~20~28 minecraft:red_sandstone 3
setblock ~13~27~28 minecraft:stained_hardened_clay 1
setblock ~13~28~28 minecraft:red_sandstone 3
setblock ~14~14~28 minecraft:stained_glass 1
setblock ~14~15~28 minecraft:planks 4
fill ~14~16~28 ~14~18~28 minecraft:stained_hardened_clay 1
setblock ~14~29~28 minecraft:planks 4
fill ~15~13~28 ~17~13~28 minecraft:stained_glass 12
fill ~15~14~28 ~17~14~28 minecraft:planks 5
fill ~15~29~28 ~16~29~28 minecraft:red_sandstone 3
setblock ~17~29~28 minecraft:planks 4
setblock ~18~14~28 minecraft:stained_glass 12
setblock ~18~15~28 minecraft:planks 5
setblock ~18~16~28 minecraft:red_sandstone 3
setblock ~18~28~28 minecraft:stained_hardened_clay 1
fill ~19~0~28 ~20~0~28 minecraft:stained_hardened_clay 1
setblock ~19~17~28 minecraft:wool 1
setblock ~19~18~28 minecraft:red_sandstone 3
setblock ~19~26~28 minecraft:red_sandstone 3
setblock ~19~27~28 minecraft:planks 4
setblock ~20~18~28 minecraft:stained_glass 1
setblock ~20~25~28 minecraft:planks 4
fill ~21~0~28 ~21~0~35 minecraft:wool 12
setblock ~11~23~29 minecraft:stained_glass 1
fill ~11~25~29 ~11~25~30 minecraft:wool 1
fill ~11~26~29 ~11~26~30 minecraft:stained_glass 1
setblock ~12~21~29 minecraft:stained_glass 1
setblock ~12~22~29 minecraft:wool 1
setblock ~12~23~29 minecraft:concrete 1
fill ~12~26~29 ~12~26~32 minecraft:concrete 1
setblock ~12~27~29 minecraft:wool 1
setblock ~12~28~29 minecraft:stained_glass 1
setblock ~13~19~29 minecraft:stained_glass 1
fill ~13~20~29 ~13~21~29 minecraft:red_sandstone 3
setblock ~13~28~29 minecraft:concrete 1
setblock ~13~29~29 minecraft:red_sandstone 3
setblock ~14~17~29 minecraft:stained_glass 1
fill ~14~18~29 ~14~19~29 minecraft:stained_hardened_clay 1
setblock ~14~30~29 minecraft:planks 4
fill ~15~14~29 ~16~14~29 minecraft:stained_glass 12
fill ~15~15~29 ~15~16~29 minecraft:planks 4
setblock ~15~17~29 minecraft:stained_hardened_clay 1
fill ~15~30~29 ~16~30~29 minecraft:red_sandstone 3
fill ~15~31~29 ~16~31~29 minecraft:planks 4
fill ~16~15~29 ~17~15~29 minecraft:planks 5
setblock ~17~30~29 minecraft:planks 4
setblock ~18~15~29 minecraft:stained_glass 12
setblock ~18~16~29 minecraft:planks 4
fill ~18~17~29 ~18~17~30 minecraft:red_sandstone 3
setblock ~18~29~29 minecraft:planks 4
setblock ~19~0~29 minecraft:stained_hardened_clay 1
fill ~19~18~29 ~19~19~29 minecraft:wool 1
setblock ~19~20~29 minecraft:red_sandstone 3
fill ~19~26~29 ~19~26~31 minecraft:concrete 1
setblock ~19~27~29 minecraft:red_sandstone 3
setblock ~19~28~29 minecraft:planks 4
fill ~20~0~29 ~20~0~36 minecraft:wool 12
fill ~20~23~29 ~20~23~30 minecraft:concrete 1
fill ~20~24~29 ~20~25~29 minecraft:red_sandstone 3
fill ~20~26~29 ~20~26~30 minecraft:stained_glass 1
setblock ~11~24~30 minecraft:stained_glass 1
setblock ~12~22~30 minecraft:stained_glass 1
setblock ~12~23~30 minecraft:wool 1
fill ~12~24~30 ~12~24~32 minecraft:concrete 1
fill ~12~27~30 ~12~27~32 minecraft:concrete 1
setblock ~12~28~30 minecraft:wool 1
setblock ~12~29~30 minecraft:stained_glass 1
setblock ~13~20~30 minecraft:stained_glass 1
fill ~13~21~30 ~13~22~30 minecraft:red_sandstone 3
setblock ~13~29~30 minecraft:concrete 1
setblock ~13~30~30 minecraft:planks 4
setblock ~14~18~30 minecraft:stained_glass 1
fill ~14~19~30 ~14~20~30 minecraft:stained_hardened_clay 1
setblock ~14~31~30 minecraft:red_sandstone 3
setblock ~15~16~30 minecraft:stained_glass 12
fill ~15~17~30 ~15~18~30 minecraft:planks 4
fill ~15~32~30 ~17~32~30 minecraft:red_sandstone 3
fill ~16~15~30 ~17~15~30 minecraft:stained_glass 12
fill ~16~16~30 ~17~16~30 minecraft:planks 5
setblock ~17~31~30 minecraft:red_sandstone 3
setblock ~18~16~30 minecraft:stained_glass 12
fill ~18~18~30 ~18~19~30 minecraft:red_sandstone 3
setblock ~18~30~30 minecraft:planks 4
fill ~19~0~30 ~19~0~36 minecraft:wool 12
fill ~19~20~30 ~19~22~30 minecraft:wool 1
fill ~19~27~30 ~19~27~32 minecraft:concrete 1
setblock ~19~28~30 minecraft:red_sandstone 3
setblock ~19~29~30 minecraft:planks 4
fill ~20~24~30 ~20~25~30 minecraft:concrete 1
fill ~26~0~30 ~27~1~38 minecraft:stained_hardened_clay 1
setblock ~28~0~30 minecraft:wool 12
fill ~29~0~30 ~31~0~31 minecraft:concrete 12
setblock ~12~23~31 minecraft:stained_glass 1
fill ~12~25~31 ~12~25~32 minecraft:concrete 1
fill ~12~28~31 ~12~28~32 minecraft:concrete 1
setblock ~12~29~31 minecraft:wool 1
setblock ~13~21~31 minecraft:stained_glass 1
fill ~13~22~31 ~13~23~32 minecraft:red_sandstone 3
setblock ~13~30~31 minecraft:concrete 1
setblock ~13~31~31 minecraft:planks 4
setblock ~14~18~31 minecraft:stained_glass 12
setblock ~14~19~31 minecraft:stained_glass 1
fill ~14~20~31 ~14~21~31 minecraft:stained_hardened_clay 1
setblock ~14~32~31 minecraft:planks 4
setblock ~15~17~31 minecraft:stained_glass 12
setblock ~15~18~31 minecraft:planks 5
setblock ~15~19~31 minecraft:stained_hardened_clay 1
setblock ~15~33~31 minecraft:concrete 1
setblock ~16~16~31 minecraft:stained_glass 12
setblock ~16~17~31 minecraft:planks 5
fill ~16~18~31 ~17~18~31 minecraft:planks 4
setblock ~16~33~31 minecraft:planks 4
setblock ~17~17~31 minecraft:planks 4
setblock ~17~33~31 minecraft:concrete 1
setblock ~18~18~31 minecraft:stained_glass 12
fill ~18~19~31 ~18~22~31 minecraft:red_sandstone 3
setblock ~18~31~31 minecraft:red_sandstone 3
setblock ~18~32~31 minecraft:planks 4
fill ~19~23~31 ~19~25~31 minecraft:wool 1
fill ~19~28~31 ~19~28~32 minecraft:concrete 1
setblock ~19~29~31 minecraft:red_sandstone 3
setblock ~19~30~31 minecraft:planks 4
setblock ~28~0~31 minecraft:concrete 12
setblock ~12~29~32 minecraft:concrete 1
fill ~12~30~32 ~12~30~33 minecraft:wool 1
fill ~13~31~32 ~13~32~33 minecraft:concrete 1
setblock ~14~19~32 minecraft:stained_glass 12
setblock ~14~20~32 minecraft:planks 4
setblock ~14~21~32 minecraft:stained_hardened_clay 1
setblock ~14~33~32 minecraft:concrete 1
setblock ~15~19~32 minecraft:planks 4
fill ~15~34~32 ~16~34~32 minecraft:planks 4
fill ~16~17~32 ~16~18~32 minecraft:stained_glass 12
fill ~16~19~32 ~17~19~32 minecraft:planks 5
fill ~17~20~32 ~17~21~32 minecraft:planks 4
setblock ~17~22~32 minecraft:red_sandstone 3
setblock ~17~34~32 minecraft:concrete 1
fill ~18~0~32 ~18~0~35 minecraft:wool 12
setblock ~18~22~32 minecraft:stained_glass 12
fill ~18~23~32 ~18~25~32 minecraft:red_sandstone 3
setblock ~18~33~32 minecraft:concrete 1
setblock ~18~34~32 minecraft:planks 4
setblock ~19~25~32 minecraft:stained_glass 1
setblock ~19~26~32 minecraft:wool 1
setblock ~19~29~32 minecraft:concrete 1
fill ~19~30~32 ~19~30~33 minecraft:red_sandstone 3
setblock ~19~31~32 minecraft:red_sandstone 3
setblock ~19~32~32 minecraft:concrete 1
fill ~19~33~32 ~19~33~33 minecraft:planks 4
fill ~20~31~32 ~20~32~32 minecraft:stained_glass 1
fill ~23~0~32 ~24~0~33 minecraft:wool 12
fill ~25~0~32 ~25~1~37 minecraft:stained_hardened_clay 1
fill ~28~0~32 ~29~1~39 minecraft:stained_hardened_clay 1
fill ~30~0~32 ~31~0~33 minecraft:concrete 12
setblock ~12~25~33 minecraft:stained_glass 1
fill ~12~26~33 ~12~29~33 minecraft:wool 1
setblock ~13~22~33 minecraft:stained_glass 1
fill ~13~23~33 ~13~25~33 minecraft:red_sandstone 3
fill ~13~33~33 ~13~33~35 minecraft:concrete 1
fill ~14~20~33 ~14~21~33 minecraft:stained_glass 12
fill ~14~22~33 ~14~23~33 minecraft:stained_hardened_clay 1
setblock ~14~34~33 minecraft:planks 4
setblock ~15~20~33 minecraft:planks 4
setblock ~15~21~33 minecraft:planks 5
setblock ~15~22~33 minecraft:planks 4
fill ~15~35~33 ~18~35~33 minecraft:concrete 1
setblock ~16~19~33 minecraft:stained_glass 12
setblock ~16~20~33 minecraft:planks 5
setblock ~16~21~33 minecraft:planks 4
fill ~16~22~33 ~16~23~33 minecraft:planks 5
setblock ~17~20~33 minecraft:stained_glass 12
setblock ~17~21~33 minecraft:planks 5
fill ~17~22~33 ~17~24~33 minecraft:planks 4
setblock ~17~25~33 minecraft:red_sandstone 3
setblock ~18~26~33 minecraft:red_sandstone 3
setblock ~19~26~33 minecraft:stained_glass 1
fill ~19~27~33 ~19~28~33 minecraft:wool 1
setblock ~19~29~33 minecraft:red_sandstone 3
setblock ~19~34~33 minecraft:planks 4
setblock ~20~30~33 minecraft:stained_glass 1
fill ~20~31~33 ~20~32~33 minecraft:wool 1
setblock ~20~33~33 minecraft:stained_glass 1
setblock ~13~24~34 minecraft:stained_glass 1
fill ~13~25~34 ~13~29~34 minecraft:red_sandstone 3
fill ~13~30~34 ~13~31~34 minecraft:stained_hardened_clay 1
setblock ~13~32~34 minecraft:concrete 1
setblock ~14~24~34 minecraft:stained_hardened_clay 1
setblock ~14~34~34 minecraft:concrete 1
setblock ~14~35~34 minecraft:wool 1
setblock ~15~22~34 minecraft:stained_glass 12
fill ~15~23~34 ~15~25~34 minecraft:planks 5
fill ~15~36~34 ~17~36~34 minecraft:wool 1
setblock ~16~21~34 minecraft:stained_glass 12
setblock ~16~23~34 minecraft:stained_glass 12
fill ~16~24~34 ~16~25~34 minecraft:planks 5
setblock ~16~26~34 minecraft:planks 4
setblock ~17~26~34 minecraft:red_sandstone 3
setblock ~17~27~34 minecraft:planks 4
setblock ~18~27~34 minecraft:red_sandstone 3
setblock ~18~35~34 minecraft:planks 4
setblock ~18~36~34 minecraft:stained_glass 1
setblock ~19~27~34 minecraft:stained_glass 1
fill ~19~28~34 ~19~29~34 minecraft:wool 1
fill ~19~35~34 ~19~35~35 minecraft:concrete 1
setblock ~20~29~34 minecraft:stained_glass 1
setblock ~20~30~34 minecraft:wool 1
fill ~20~31~34 ~20~32~34 minecraft:concrete 1
fill ~20~33~34 ~20~34~34 minecraft:wool 1
fill ~23~0~34 ~24~1~35 minecraft:stained_hardened_clay 1
fill ~30~0~34 ~30~1~41 minecraft:stained_hardened_clay 1
fill ~31~0~34 ~31~0~36 minecraft:concrete 12
fill ~11~0~35 ~11~0~41 minecraft:wool 12
fill ~12~32~35 ~12~32~36 minecraft:wool 1
setblock ~12~33~35 minecraft:stained_glass 1
fill ~13~29~35 ~13~31~35 minecraft:red_sandstone 3
fill ~13~34~35 ~13~34~36 minecraft:concrete 1
setblock ~13~35~35 minecraft:stained_glass 1
fill ~14~25~35 ~14~26~35 minecraft:stained_hardened_clay 1
fill ~14~27~35 ~14~28~35 minecraft:planks 4
setblock ~14~35~35 minecraft:concrete 1
setblock ~14~36~35 minecraft:stained_glass 1
setblock ~15~23~35 minecraft:stained_glass 12
fill ~15~26~35 ~15~28~35 minecraft:planks 5
setblock ~15~36~35 minecraft:concrete 1
fill ~15~37~35 ~17~37~35 minecraft:wool 1
setblock ~16~25~35 minecraft:stained_glass 12
fill ~16~27~35 ~16~28~35 minecraft:planks 5
fill ~17~27~35 ~17~27~36 minecraft:stained_glass 12
fill ~17~28~35 ~18~28~38 minecraft:planks 5
setblock ~18~36~35 minecraft:wool 1
setblock ~18~37~35 minecraft:stained_glass 1
setblock ~19~28~35 minecraft:stained_glass 1
setblock ~19~29~35 minecraft:wool 1
setblock ~19~36~35 minecraft:stained_glass 1
setblock ~20~30~35 minecraft:concrete 1
setblock ~20~34~35 minecraft:concrete 1
setblock ~20~35~35 minecraft:stained_glass 1
setblock ~21~30~35 minecraft:stained_glass 1
fill ~21~31~35 ~21~32~35 minecraft:wool 1
setblock ~21~33~35 minecraft:concrete 1
setblock ~21~34~35 minecraft:stained_glass 1
fill ~6~0~36 ~7~0~39 minecraft:stained_hardened_clay 1
fill ~8~0~36 ~10~0~36 minecraft:wool 12
fill ~12~0~36 ~12~0~40 minecraft:wool 12
setblock ~12~31~36 minecraft:concrete 1
setblock ~12~33~36 minecraft:wool 1
setblock ~12~34~36 minecraft:stained_glass 1
setblock ~13~30~36 minecraft:red_sandstone 3
setblock ~13~35~36 minecraft:wool 1
setblock ~13~36~36 minecraft:stained_glass 1
fill ~14~29~36 ~15~29~37 minecraft:stained_hardened_clay 1
setblock ~14~36~36 minecraft:concrete 1
setblock ~14~37~36 minecraft:wool 1
fill ~15~38~36 ~17~38~36 minecraft:wool 1
setblock ~16~27~36 minecraft:stained_glass 12
fill ~16~29~36 ~16~29~37 minecraft:planks 5
fill ~18~37~36 ~18~37~37 minecraft:wool 1
setblock ~19~28~36 minecraft:stained_glass 12
fill ~19~29~36 ~19~29~37 minecraft:planks 5
fill ~19~36~36 ~19~36~37 minecraft:wool 1
setblock ~20~29~36 minecraft:concrete 1
fill ~20~35~36 ~20~35~37 minecraft:concrete 1
fill ~21~0~36 ~23~0~41 minecraft:concrete 12
setblock ~21~29~36 minecraft:wool 1
setblock ~21~30~36 minecraft:concrete 1
setblock ~21~34~36 minecraft:wool 1
setblock ~21~35~36 minecraft:stained_glass 1
fill ~22~1~36 ~23~1~41 minecraft:concrete 12
fill ~22~28~36 ~22~29~36 minecraft:stained_glass 1
fill ~22~30~36 ~22~31~36 minecraft:wool 1
fill ~22~32~36 ~22~33~36 minecraft:concrete 1
setblock ~22~34~36 minecraft:stained_glass 1
fill ~24~0~36 ~24~1~36 minecraft:stained_hardened_clay 1
fill ~32~0~36 ~32~0~41 minecraft:concrete 12
fill ~4~0~37 ~5~0~41 minecraft:stained_hardened_clay 1
fill ~8~0~37 ~8~0~38 minecraft:stained_hardened_clay 1
fill ~9~0~37 ~10~0~42 minecraft:wool 12
fill ~9~14~37 ~11~15~37 minecraft:wool 15
setblock ~10~10~37 minecraft:stained_glass 1
setblock ~10~11~37 minecraft:wool 1
setblock ~10~12~37 minecraft:planks 4
setblock ~10~13~37 minecraft:wool 15
setblock ~10~31~37 minecraft:wool 1
fill ~11~30~37 ~12~30~37 minecraft:wool 1
fill ~11~31~37 ~11~32~37 minecraft:concrete 1
setblock ~11~33~37 minecraft:wool 1
setblock ~11~34~37 minecraft:stained_glass 1
setblock ~12~34~37 minecraft:concrete 1
setblock ~12~35~37 minecraft:stained_glass 1
setblock ~13~30~37 minecraft:stained_hardened_clay 1
setblock ~13~35~37 minecraft:concrete 1
setblock ~13~36~37 minecraft:wool 1
setblock ~13~37~37 minecraft:stained_glass 1
setblock ~14~37~37 minecraft:concrete 1
setblock ~14~38~37 minecraft:stained_glass 1
setblock ~15~38~37 minecraft:concrete 1
setblock ~15~39~37 minecraft:stained_glass 1
fill ~16~39~37 ~16~39~38 minecraft:wool 1
fill ~17~0~37 ~20~0~41 minecraft:concrete 12
fill ~17~38~37 ~17~38~39 minecraft:concrete 1
setblock ~18~27~37 minecraft:stained_glass 12
setblock ~20~27~37 minecraft:stained_glass 1
setblock ~20~28~37 minecraft:wool 1
setblock ~20~36~37 minecraft:stained_glass 1
fill ~21~1~37 ~21~1~41 minecraft:concrete 12
setblock ~21~26~37 minecraft:stained_glass 1
fill ~21~27~37 ~23~27~37 minecraft:wool 1
fill ~21~28~37 ~22~28~37 minecraft:red_sandstone 3
fill ~21~35~37 ~21~35~38 minecraft:concrete 1
fill ~22~25~37 ~23~25~37 minecraft:stained_glass 1
fill ~22~26~37 ~23~26~37 minecraft:wool 1
setblock ~22~29~37 minecraft:red_sandstone 3
setblock ~22~34~37 minecraft:wool 1
setblock ~22~35~37 minecraft:stained_glass 1
fill ~23~28~37 ~23~33~37 minecraft:wool 1
setblock ~23~34~37 minecraft:stained_glass 1
fill ~24~0~37 ~24~1~40 minecraft:concrete 12
fill ~24~27~37 ~24~30~37 minecraft:stained_glass 1
fill ~31~0~37 ~31~1~42 minecraft:stained_hardened_clay 1
fill ~33~0~37 ~33~0~42 minecraft:concrete 12
fill ~3~0~38 ~3~0~46 minecraft:stained_hardened_clay 1
setblock ~8~14~38 minecraft:planks 5
setblock ~9~10~38 minecraft:stained_glass 1
setblock ~9~11~38 minecraft:red_sandstone 3
setblock ~9~12~38 minecraft:wool 15
setblock ~9~13~38 minecraft:planks 5
setblock ~9~15~38 minecraft:planks 5
fill ~9~30~38 ~9~32~38 minecraft:wool 1
setblock ~9~33~38 minecraft:stained_glass 1
setblock ~10~8~38 minecraft:stained_glass 1
fill ~10~9~38 ~10~10~38 minecraft:wool 1
setblock ~10~16~38 minecraft:planks 5
setblock ~10~27~38 minecraft:stained_glass 1
fill ~10~28~38 ~12~29~38 minecraft:wool 1
setblock ~10~30~38 minecraft:concrete 1
setblock ~10~32~38 minecraft:concrete 1
setblock ~10~33~38 minecraft:wool 1
setblock ~10~34~38 minecraft:stained_glass 1
setblock ~11~10~38 minecraft:stained_glass 1
setblock ~11~11~38 minecraft:wool 1
fill ~11~12~38 ~11~13~38 minecraft:red_sandstone 3
setblock ~11~15~38 minecraft:planks 5
setblock ~11~25~38 minecraft:stained_glass 1
fill ~11~26~38 ~11~27~38 minecraft:wool 1
setblock ~11~34~38 minecraft:wool 1
setblock ~11~35~38 minecraft:stained_glass 1
fill ~12~14~38 ~12~14~41 minecraft:planks 5
setblock ~12~27~38 minecraft:stained_glass 1
setblock ~12~35~38 minecraft:concrete 1
setblock ~12~36~38 minecraft:stained_glass 1
fill ~13~0~38 ~13~0~40 minecraft:wool 12
setblock ~13~28~38 minecraft:stained_glass 1
setblock ~13~29~38 minecraft:wool 1
setblock ~13~36~38 minecraft:concrete 1
setblock ~13~37~38 minecraft:wool 1
setblock ~14~29~38 minecraft:stained_hardened_clay 1
setblock ~14~38~38 minecraft:wool 1
setblock ~14~39~38 minecraft:stained_glass 1
fill ~15~28~38 ~16~28~38 minecraft:stained_hardened_clay 1
setblock ~15~39~38 minecraft:wool 1
fill ~16~0~38 ~16~0~49 minecraft:concrete 12
setblock ~16~40~38 minecraft:stained_glass 1
setblock ~17~27~38 minecraft:stained_glass 12
fill ~17~39~38 ~17~39~39 minecraft:wool 1
fill ~18~37~38 ~18~37~39 minecraft:concrete 1
setblock ~19~28~38 minecraft:red_sandstone 3
setblock ~19~36~38 minecraft:concrete 1
setblock ~19~37~38 minecraft:stained_glass 1
fill ~20~1~38 ~20~1~41 minecraft:concrete 12
setblock ~20~25~38 minecraft:stained_glass 1
fill ~20~26~38 ~20~27~38 minecraft:wool 1
setblock ~20~36~38 minecraft:wool 1
fill ~21~13~38 ~23~14~38 minecraft:wool 15
setblock ~21~24~38 minecraft:stained_glass 1
setblock ~21~25~38 minecraft:wool 1
setblock ~21~26~38 minecraft:red_sandstone 3
setblock ~21~36~38 minecraft:stained_glass 1
fill ~22~9~38 ~22~10~38 minecraft:stained_glass 1
setblock ~22~11~38 minecraft:wool 1
fill ~22~12~38 ~22~12~39 minecraft:wool 15
fill ~22~24~38 ~23~24~38 minecraft:wool 1
fill ~22~25~38 ~23~25~38 minecraft:red_sandstone 3
setblock ~22~35~38 minecraft:concrete 1
setblock ~23~34~38 minecraft:wool 1
setblock ~23~35~38 minecraft:stained_glass 1
setblock ~24~24~38 minecraft:stained_glass 1
fill ~24~25~38 ~24~28~38 minecraft:wool 1
fill ~24~29~38 ~24~33~38 minecraft:red_sandstone 3
fill ~25~0~38 ~25~1~40 minecraft:concrete 12
setblock ~25~12~38 minecraft:stained_glass 1
fill ~25~28~38 ~25~30~38 minecraft:stained_glass 1
fill ~34~0~38 ~35~0~39 minecraft:concrete 12
fill ~2~0~39 ~2~0~45 minecraft:stained_hardened_clay 1
fill ~8~0~39 ~8~0~47 minecraft:wool 12
fill ~8~11~39 ~8~11~40 minecraft:wool 15
setblock ~8~12~39 minecraft:planks 5
setblock ~8~13~39 minecraft:wool 1
setblock ~8~14~39 minecraft:red_sandstone 3
setblock ~8~15~39 minecraft:wool 1
fill ~8~30~39 ~8~32~39 minecraft:wool 1
setblock ~8~33~39 minecraft:stained_glass 1
fill ~9~9~39 ~9~10~39 minecraft:wool 15
setblock ~9~16~39 minecraft:planks 4
setblock ~9~17~39 minecraft:stained_hardened_clay 1
setblock ~9~27~39 minecraft:stained_glass 1
setblock ~9~28~39 minecraft:wool 1
setblock ~9~29~39 minecraft:concrete 1
setblock ~9~33~39 minecraft:concrete 1
setblock ~9~34~39 minecraft:wool 1
setblock ~9~35~39 minecraft:stained_glass 1
setblock ~10~7~39 minecraft:stained_glass 1
setblock ~10~8~39 minecraft:wool 1
setblock ~10~17~39 minecraft:planks 4
setblock ~10~23~39 minecraft:stained_glass 1
fill ~10~24~39 ~10~27~39 minecraft:wool 1
setblock ~10~34~39 minecraft:concrete 1
setblock ~10~35~39 minecraft:wool 1
setblock ~10~36~39 minecraft:stained_glass 1
setblock ~11~8~39 minecraft:stained_glass 1
setblock ~11~9~39 minecraft:wool 1
setblock ~11~10~39 minecraft:red_sandstone 3
setblock ~11~16~39 minecraft:planks 5
setblock ~11~25~39 minecraft:wool 1
setblock ~11~35~39 minecraft:concrete 1
setblock ~11~36~39 minecraft:wool 1
fill ~12~11~39 ~12~11~40 minecraft:wool 15
setblock ~12~12~39 minecraft:wool 15
fill ~12~13~39 ~12~13~40 minecraft:planks 5
setblock ~12~15~39 minecraft:planks 5
setblock ~12~25~39 minecraft:stained_glass 1
setblock ~12~26~39 minecraft:wool 1
fill ~12~27~39 ~13~27~39 minecraft:concrete 1
fill ~12~36~39 ~12~37~39 minecraft:concrete 1
setblock ~12~38~39 minecraft:stained_glass 1
setblock ~13~26~39 minecraft:stained_glass 1
fill ~13~28~39 ~14~28~39 minecraft:concrete 1
setblock ~13~38~39 minecraft:wool 1
setblock ~13~39~39 minecraft:stained_glass 1
fill ~14~0~39 ~15~0~47 minecraft:concrete 12
fill ~14~39~39 ~14~39~40 minecraft:wool 1
fill ~15~28~39 ~16~28~39 minecraft:planks 5
fill ~15~40~39 ~16~40~39 minecraft:wool 1
setblock ~16~41~39 minecraft:stained_glass 1
fill ~17~28~39 ~17~28~40 minecraft:red_sandstone 3
fill ~18~1~39 ~19~1~42 minecraft:concrete 12
fill ~18~28~39 ~18~28~40 minecraft:planks 5
setblock ~18~38~39 minecraft:stained_glass 1
setblock ~19~27~39 minecraft:red_sandstone 3
fill ~19~37~39 ~20~37~39 minecraft:wool 1
fill ~20~24~39 ~21~24~39 minecraft:red_sandstone 3
fill ~20~25~39 ~20~25~40 minecraft:red_sandstone 3
setblock ~20~26~39 minecraft:red_sandstone 3
fill ~21~9~39 ~21~10~39 minecraft:stained_glass 1
setblock ~21~13~39 minecraft:wool 15
fill ~21~14~39 ~21~15~39 minecraft:planks 5
setblock ~21~16~39 minecraft:stained_hardened_clay 1
fill ~21~36~39 ~22~36~39 minecraft:wool 1
setblock ~21~37~39 minecraft:stained_glass 1
setblock ~22~7~39 minecraft:stained_glass 1
fill ~22~8~39 ~22~10~39 minecraft:wool 1
setblock ~22~11~39 minecraft:stained_hardened_clay 1
fill ~22~15~39 ~23~15~39 minecraft:planks 5
setblock ~22~16~39 minecraft:planks 5
setblock ~22~21~39 minecraft:stained_glass 1
fill ~22~22~39 ~22~23~39 minecraft:wool 1
setblock ~23~12~39 minecraft:wool 15
setblock ~23~16~39 minecraft:stained_hardened_clay 1
setblock ~23~24~39 minecraft:red_sandstone 3
setblock ~23~35~39 minecraft:wool 1
setblock ~23~36~39 minecraft:stained_glass 1
fill ~24~13~39 ~24~14~39 minecraft:stained_hardened_clay 1
setblock ~24~24~39 minecraft:wool 1
setblock ~24~34~39 minecraft:wool 1
setblock ~24~35~39 minecraft:stained_glass 1
setblock ~25~13~39 minecraft:stained_glass 1
setblock ~25~14~39 minecraft:red_sandstone 3
setblock ~25~24~39 minecraft:stained_glass 1
fill ~25~25~39 ~25~33~39 minecraft:wool 1
setblock ~25~34~39 minecraft:stained_glass 1
fill ~26~0~39 ~27~1~42 minecraft:concrete 12
setblock ~6~0~40 minecraft:stained_hardened_clay 1
fill ~7~0~40 ~7~0~48 minecraft:wool 12
fill ~8~9~40 ~8~10~40 minecraft:wool 15
setblock ~8~12~40 minecraft:wool 15
setblock ~8~13~40 minecraft:planks 5
setblock ~8~14~40 minecraft:wool 1
fill ~8~15~40 ~8~15~41 minecraft:red_sandstone 3
setblock ~8~16~40 minecraft:wool 1
setblock ~8~27~40 minecraft:stained_glass 1
fill ~8~28~40 ~8~29~40 minecraft:wool 1
fill ~8~30~40 ~8~33~40 minecraft:concrete 1
setblock ~8~34~40 minecraft:wool 1
setblock ~8~35~40 minecraft:stained_glass 1
setblock ~9~8~40 minecraft:wool 15
fill ~9~17~40 ~9~18~40 minecraft:planks 4
setblock ~9~22~40 minecraft:stained_glass 1
fill ~9~23~40 ~9~24~40 minecraft:wool 1
fill ~9~25~40 ~9~27~40 minecraft:concrete 1
setblock ~9~35~40 minecraft:wool 1
setblock ~9~36~40 minecraft:stained_glass 1
setblock ~10~6~40 minecraft:stained_glass 1
setblock ~10~7~40 minecraft:wool 1
setblock ~10~18~40 minecraft:stained_hardened_clay 1
setblock ~10~19~40 minecraft:red_sandstone 3
fill ~10~20~40 ~10~22~40 minecraft:wool 1
setblock ~10~23~40 minecraft:concrete 1
setblock ~10~36~40 minecraft:wool 1
setblock ~10~37~40 minecraft:stained_glass 1
setblock ~11~7~40 minecraft:stained_glass 1
setblock ~11~8~40 minecraft:red_sandstone 3
setblock ~11~17~40 minecraft:planks 4
setblock ~11~18~40 minecraft:red_sandstone 3
setblock ~11~23~40 minecraft:stained_glass 1
setblock ~11~24~40 minecraft:wool 1
setblock ~11~37~40 minecraft:concrete 1
fill ~12~9~40 ~12~9~41 minecraft:wool 15
setblock ~12~10~40 minecraft:wool 15
setblock ~12~12~40 minecraft:planks 5
fill ~12~15~40 ~12~16~41 minecraft:red_sandstone 3
setblock ~12~24~40 minecraft:stained_glass 1
setblock ~12~25~40 minecraft:concrete 1
setblock ~12~38~40 minecraft:concrete 1
setblock ~12~39~40 minecraft:stained_glass 1
setblock ~13~26~40 minecraft:concrete 1
setblock ~13~39~40 minecraft:wool 1
setblock ~14~27~40 minecraft:red_sandstone 3
setblock ~14~40~40 minecraft:stained_glass 1
fill ~15~27~40 ~15~27~41 minecraft:calcite
fill ~15~40~40 ~15~41~40 minecraft:wool 1
setblock ~16~28~40 minecraft:planks 5
fill ~16~41~40 ~16~41~41 minecraft:wool 1
setblock ~17~39~40 minecraft:concrete 1
fill ~17~40~40 ~17~40~41 minecraft:wool 1
setblock ~18~38~40 minecraft:concrete 1
setblock ~18~39~40 minecraft:stained_glass 1
fill ~19~26~40 ~19~26~41 minecraft:red_sandstone 3
setblock ~19~27~40 minecraft:planks 5
fill ~19~38~40 ~20~38~40 minecraft:wool 1
fill ~20~2~40 ~23~2~41 minecraft:concrete 12
setblock ~20~14~40 minecraft:planks 5
fill ~20~15~40 ~20~15~41 minecraft:red_sandstone 3
setblock ~20~16~40 minecraft:red_sandstone 3
setblock ~20~17~40 minecraft:stained_hardened_clay 1
setblock ~20~24~40 minecraft:red_sandstone 3
fill ~21~7~40 ~21~7~42 minecraft:wool 15
setblock ~21~8~40 minecraft:wool 15
fill ~21~9~40 ~22~10~40 minecraft:stained_hardened_clay 1
fill ~21~11~40 ~23~11~40 minecraft:wool 15
setblock ~21~12~40 minecraft:wool 15
setblock ~21~13~40 minecraft:planks 5
fill ~21~17~40 ~23~17~40 minecraft:red_sandstone 3
fill ~21~18~40 ~24~18~40 minecraft:stained_hardened_clay 1
fill ~21~22~40 ~21~23~40 minecraft:wool 1
fill ~21~37~40 ~22~37~40 minecraft:wool 1
setblock ~21~38~40 minecraft:stained_glass 1
setblock ~22~6~40 minecraft:wool 15
fill ~22~7~40 ~22~8~40 minecraft:stained_hardened_clay 1
setblock ~22~20~40 minecraft:stained_glass 1
setblock ~22~21~40 minecraft:wool 1
fill ~23~7~40 ~23~10~40 minecraft:wool 15
setblock ~23~21~40 minecraft:stained_glass 1
setblock ~23~22~40 minecraft:wool 1
setblock ~23~23~40 minecraft:red_sandstone 3
setblock ~23~36~40 minecraft:wool 1
fill ~24~12~40 ~24~12~41 minecraft:wool 15
setblock ~24~13~40 minecraft:planks 5
setblock ~24~14~40 minecraft:stained_hardened_clay 1
fill ~24~15~40 ~25~15~40 minecraft:red_sandstone 3
setblock ~24~16~40 minecraft:red_sandstone 3
setblock ~24~17~40 minecraft:stained_hardened_clay 1
setblock ~24~22~40 minecraft:stained_glass 1
setblock ~24~23~40 minecraft:wool 1
setblock ~24~35~40 minecraft:wool 1
setblock ~25~14~40 minecraft:stained_glass 1
setblock ~25~23~40 minecraft:stained_glass 1
fill ~25~24~40 ~25~26~40 minecraft:planks 4
setblock ~25~34~40 minecraft:wool 1
setblock ~25~35~40 minecraft:stained_glass 1
setblock ~26~26~40 minecraft:stained_glass 1
fill ~26~27~40 ~26~33~40 minecraft:wool 1
setblock ~26~34~40 minecraft:stained_glass 1
fill ~28~0~40 ~28~1~44 minecraft:concrete 12
fill ~29~0~40 ~29~1~40 minecraft:stained_hardened_clay 1
fill ~34~0~40 ~34~0~42 minecraft:concrete 12
fill ~6~0~41 ~6~0~48 minecraft:wool 12
setblock ~7~28~41 minecraft:stained_glass 1
fill ~7~29~41 ~7~33~41 minecraft:wool 1
setblock ~7~34~41 minecraft:stained_glass 1
fill ~8~8~41 ~8~8~42 minecraft:wool 15
fill ~8~13~41 ~9~13~41 minecraft:wool 15
setblock ~8~14~41 minecraft:planks 5
fill ~8~16~41 ~8~16~42 minecraft:red_sandstone 3
setblock ~8~17~41 minecraft:planks 4
setblock ~8~18~41 minecraft:stained_hardened_clay 1
setblock ~8~19~41 minecraft:red_sandstone 3
setblock ~8~20~41 minecraft:stained_glass 1
setblock ~8~23~41 minecraft:stained_glass 1
fill ~8~24~41 ~8~25~41 minecraft:wool 1
fill ~8~26~41 ~8~28~41 minecraft:concrete 1
setblock ~8~34~41 minecraft:concrete 1
setblock ~8~35~41 minecraft:wool 1
setblock ~8~36~41 minecraft:stained_glass 1
fill ~9~7~41 ~9~7~42 minecraft:wool 15
fill ~9~9~41 ~9~9~42 minecraft:wool 15
fill ~9~10~41 ~9~12~41 minecraft:wool 15
setblock ~9~17~41 minecraft:red_sandstone 3
setblock ~9~19~41 minecraft:stained_hardened_clay 1
fill ~9~20~41 ~9~23~41 minecraft:concrete 1
setblock ~9~36~41 minecraft:wool 1
setblock ~9~37~41 minecraft:stained_glass 1
setblock ~10~6~41 minecraft:red_sandstone 3
fill ~10~11~41 ~11~12~41 minecraft:wool 15
fill ~10~21~41 ~10~22~41 minecraft:red_sandstone 3
setblock ~10~37~41 minecraft:wool 1
setblock ~10~38~41 minecraft:stained_glass 1
setblock ~11~6~41 minecraft:stained_glass 1
setblock ~11~7~41 minecraft:red_sandstone 3
setblock ~11~10~41 minecraft:planks 5
setblock ~11~13~41 minecraft:planks 5
fill ~11~19~41 ~11~20~41 minecraft:concrete 1
setblock ~11~23~41 minecraft:concrete 1
setblock ~11~38~41 minecraft:wool 1
setblock ~11~39~41 minecraft:stained_glass 1
fill ~12~0~41 ~13~0~45 minecraft:concrete 12
fill ~12~8~41 ~12~8~42 minecraft:wool 15
setblock ~12~13~41 minecraft:stained_glass 12
setblock ~12~17~41 minecraft:stained_hardened_clay 1
setblock ~12~18~41 minecraft:red_sandstone 3
setblock ~12~24~41 minecraft:concrete 1
setblock ~12~25~41 minecraft:red_sandstone 3
setblock ~12~39~41 minecraft:wool 1
fill ~13~26~41 ~14~26~41 minecraft:red_sandstone 3
fill ~13~39~41 ~13~39~42 minecraft:concrete 1
fill ~14~40~41 ~14~40~43 minecraft:wool 1
fill ~15~26~41 ~15~26~42 minecraft:calcite
fill ~15~41~41 ~15~41~43 minecraft:wool 1
fill ~16~26~41 ~16~27~41 minecraft:planks 5
setblock ~17~27~41 minecraft:red_sandstone 3
setblock ~17~41~41 minecraft:stained_glass 1
setblock ~18~27~41 minecraft:planks 5
setblock ~18~39~41 minecraft:concrete 1
setblock ~18~40~41 minecraft:stained_glass 1
fill ~19~2~41 ~19~2~42 minecraft:concrete 12
setblock ~19~8~41 minecraft:cobblestone_wall 4
fill ~19~9~41 ~20~10~41 minecraft:wool 15
setblock ~19~24~41 minecraft:stained_glass 0
setblock ~19~25~41 minecraft:wool 0
fill ~19~39~41 ~20~39~41 minecraft:wool 1
setblock ~20~8~41 minecraft:wool 15
setblock ~20~11~41 minecraft:wool 15
fill ~20~12~41 ~20~13~41 minecraft:planks 5
setblock ~20~14~41 minecraft:red_sandstone 3
fill ~20~16~41 ~20~18~41 minecraft:wool 0
setblock ~20~22~41 minecraft:red_sandstone 3
fill ~20~23~41 ~20~23~42 minecraft:wool 0
setblock ~20~24~41 minecraft:wool 0
fill ~21~5~41 ~23~5~41 minecraft:wool 15
setblock ~21~6~41 minecraft:wool 15
fill ~21~19~41 ~24~19~41 minecraft:red_sandstone 3
setblock ~21~21~41 minecraft:red_sandstone 3
setblock ~21~38~41 minecraft:wool 1
setblock ~22~4~41 minecraft:wool 15
fill ~22~20~41 ~23~20~41 minecraft:red_sandstone 3
setblock ~22~37~41 minecraft:wool 1
setblock ~22~38~41 minecraft:stained_glass 1
setblock ~23~6~41 minecraft:wool 15
setblock ~23~21~41 minecraft:red_sandstone 3
setblock ~23~36~41 minecraft:concrete 1
setblock ~23~37~41 minecraft:stained_glass 1
fill ~24~0~41 ~25~2~42 minecraft:stained_hardened_clay 1
fill ~24~7~41 ~24~11~41 minecraft:wool 15
setblock ~24~13~41 minecraft:wool 15
setblock ~24~14~41 minecraft:planks 5
setblock ~24~15~41 minecraft:stained_hardened_clay 1
fill ~24~21~41 ~24~22~41 minecraft:stained_hardened_clay 1
setblock ~24~35~41 minecraft:concrete 1
setblock ~24~36~41 minecraft:stained_glass 1
setblock ~25~15~41 minecraft:stained_glass 1
fill ~25~16~41 ~25~18~41 minecraft:red_sandstone 3
setblock ~25~22~41 minecraft:stained_glass 1
setblock ~25~23~41 minecraft:planks 4
setblock ~25~35~41 minecraft:wool 1
setblock ~26~23~41 minecraft:stained_glass 1
fill ~26~24~41 ~26~26~41 minecraft:wool 1
fill ~26~27~41 ~26~28~41 minecraft:concrete 1
fill ~26~33~41 ~26~34~41 minecraft:wool 1
setblock ~27~28~41 minecraft:stained_glass 1
fill ~27~29~41 ~27~32~41 minecraft:wool 1
setblock ~27~33~41 minecraft:stained_glass 1
fill ~29~0~41 ~29~1~45 minecraft:concrete 12
fill ~35~0~41 ~35~0~42 minecraft:concrete 12
fill ~1~0~42 ~1~0~44 minecraft:stained_hardened_clay 1
fill ~4~0~42 ~4~0~45 minecraft:stained_hardened_clay 1
fill ~5~0~42 ~5~0~48 minecraft:wool 12
setblock ~7~18~42 minecraft:stained_glass 1
fill ~7~19~42 ~7~19~43 minecraft:concrete 1
fill ~7~20~42 ~8~21~42 minecraft:concrete 1
fill ~7~22~42 ~7~28~42 minecraft:wool 1
fill ~7~29~42 ~7~30~43 minecraft:concrete 1
fill ~7~31~42 ~7~33~42 minecraft:concrete 1
fill ~7~34~42 ~7~34~43 minecraft:wool 1
setblock ~8~15~42 minecraft:wool 15
setblock ~8~17~42 minecraft:stained_hardened_clay 1
setblock ~8~18~42 minecraft:planks 4
fill ~8~22~42 ~8~23~42 minecraft:concrete 1
fill ~8~35~42 ~8~35~43 minecraft:concrete 1
setblock ~8~36~42 minecraft:wool 1
setblock ~8~37~42 minecraft:stained_glass 1
fill ~9~14~42 ~10~14~42 minecraft:wool 15
setblock ~9~37~42 minecraft:concrete 1
setblock ~10~5~42 minecraft:red_sandstone 3
setblock ~10~6~42 minecraft:wool 15
fill ~10~10~42 ~11~10~42 minecraft:wool 15
setblock ~10~13~42 minecraft:wool 15
setblock ~10~38~42 minecraft:wool 1
fill ~11~0~42 ~11~0~46 minecraft:concrete 12
setblock ~11~5~42 minecraft:stained_glass 1
setblock ~11~6~42 minecraft:red_sandstone 3
setblock ~11~9~42 minecraft:planks 5
setblock ~11~13~42 minecraft:stained_glass 12
setblock ~11~14~42 minecraft:planks 5
setblock ~11~15~42 minecraft:wool 15
fill ~11~20~42 ~11~22~42 minecraft:red_sandstone 3
setblock ~11~39~42 minecraft:wool 1
setblock ~12~7~42 minecraft:wool 15
fill ~12~16~42 ~12~16~43 minecraft:red_sandstone 3
fill ~12~17~42 ~12~19~42 minecraft:wool 0
setblock ~12~23~42 minecraft:wool 0
fill ~12~39~42 ~12~39~43 minecraft:concrete 1
setblock ~13~7~42 minecraft:cobblestone_wall 4
setblock ~13~8~42 minecraft:wool 15
setblock ~13~23~42 minecraft:stained_glass 0
fill ~13~24~42 ~13~24~43 minecraft:wool 0
setblock ~13~25~42 minecraft:wool 0
setblock ~13~40~42 minecraft:stained_glass 1
setblock ~14~25~42 minecraft:stained_glass 0
setblock ~14~26~42 minecraft:wool 0
fill ~16~26~42 ~16~26~43 minecraft:calcite
fill ~16~41~42 ~16~41~43 minecraft:concrete 1
fill ~17~0~42 ~19~0~42 minecraft:concrete 12
fill ~17~26~42 ~18~26~42 minecraft:planks 5
setblock ~17~41~42 minecraft:wool 1
setblock ~18~25~42 minecraft:planks 5
setblock ~18~40~42 minecraft:concrete 1
setblock ~18~41~42 minecraft:stained_glass 1
setblock ~19~23~42 minecraft:stained_glass 0
setblock ~19~24~42 minecraft:wool 0
fill ~19~40~42 ~19~40~43 minecraft:wool 1
fill ~20~0~42 ~23~1~43 minecraft:dirt 0
fill ~20~2~42 ~23~2~42 minecraft:dirt 0
fill ~20~3~42 ~23~3~42 minecraft:wool 15
fill ~20~4~42 ~21~5~42 minecraft:wool 15
fill ~20~6~42 ~20~7~42 minecraft:wool 15
setblock ~20~16~42 minecraft:red_sandstone 3
fill ~20~17~42 ~20~18~43 minecraft:wool 0
setblock ~20~19~42 minecraft:wool 0
setblock ~20~20~42 minecraft:stained_glass 0
fill ~20~21~42 ~20~21~43 minecraft:wool 0
setblock ~20~22~42 minecraft:wool 0
setblock ~20~39~42 minecraft:wool 1
fill ~21~8~42 ~23~11~42 minecraft:wool 15
fill ~21~12~42 ~21~14~42 minecraft:wool 15
fill ~21~15~42 ~21~15~43 minecraft:planks 5
setblock ~21~20~42 minecraft:red_sandstone 3
setblock ~21~38~42 minecraft:concrete 1
setblock ~21~39~42 minecraft:stained_glass 1
setblock ~22~38~42 minecraft:wool 1
setblock ~23~4~42 minecraft:wool 15
setblock ~23~7~42 minecraft:wool 15
fill ~23~12~42 ~23~14~42 minecraft:wool 15
setblock ~23~37~42 minecraft:wool 1
setblock ~23~38~42 minecraft:stained_glass 1
fill ~24~5~42 ~24~5~44 minecraft:wool 15
setblock ~24~6~42 minecraft:wool 15
setblock ~24~14~42 minecraft:stained_glass 12
setblock ~24~15~42 minecraft:planks 5
setblock ~24~16~42 minecraft:stained_hardened_clay 1
setblock ~24~20~42 minecraft:red_sandstone 3
setblock ~24~36~42 minecraft:wool 1
setblock ~24~37~42 minecraft:stained_glass 1
setblock ~25~16~42 minecraft:stained_glass 1
setblock ~25~17~42 minecraft:red_sandstone 3
setblock ~25~18~42 minecraft:stained_hardened_clay 1
setblock ~25~19~42 minecraft:red_sandstone 3
fill ~25~20~42 ~25~22~42 minecraft:stained_hardened_clay 1
setblock ~25~35~42 minecraft:concrete 1
setblock ~25~36~42 minecraft:stained_glass 1
fill ~26~22~42 ~26~23~42 minecraft:planks 4
fill ~26~24~42 ~26~25~42 minecraft:concrete 1
setblock ~26~34~42 minecraft:wool 1
setblock ~27~25~42 minecraft:stained_glass 1
fill ~27~26~42 ~27~27~43 minecraft:concrete 1
fill ~27~28~42 ~27~32~42 minecraft:concrete 1
setblock ~27~33~42 minecraft:wool 1
fill ~30~0~42 ~30~1~45 minecraft:concrete 12
fill ~32~0~42 ~32~1~56 minecraft:stained_hardened_clay 1
fill ~36~0~42 ~37~0~43 minecraft:concrete 12
setblock ~6~20~43 minecraft:stained_glass 1
fill ~6~21~43 ~6~27~43 minecraft:wool 1
fill ~6~28~43 ~6~30~43 minecraft:stained_glass 1
fill ~6~31~43 ~6~33~43 minecraft:wool 1
setblock ~7~17~43 minecraft:stained_glass 1
setblock ~7~18~43 minecraft:concrete 1
setblock ~7~20~43 minecraft:red_sandstone 3
setblock ~7~28~43 minecraft:concrete 1
setblock ~7~35~43 minecraft:stained_glass 1
setblock ~8~7~43 minecraft:wool 15
setblock ~8~16~43 minecraft:stained_hardened_clay 1
setblock ~8~17~43 minecraft:planks 4
fill ~8~36~43 ~8~36~44 minecraft:concrete 1
fill ~8~37~43 ~8~37~45 minecraft:wool 1
fill ~9~0~43 ~9~0~47 minecraft:wool 12
setblock ~9~5~43 minecraft:red_sandstone 3
setblock ~9~6~43 minecraft:wool 15
setblock ~9~8~43 minecraft:wool 15
fill ~9~15~43 ~10~15~43 minecraft:wool 15
setblock ~9~38~43 minecraft:wool 1
fill ~10~0~43 ~10~0~45 minecraft:concrete 12
setblock ~10~4~43 minecraft:red_sandstone 3
fill ~10~9~43 ~11~9~43 minecraft:wool 15
fill ~10~39~43 ~10~39~46 minecraft:wool 1
setblock ~11~5~43 minecraft:red_sandstone 3
fill ~11~7~43 ~11~7~44 minecraft:planks 5
setblock ~11~8~43 minecraft:planks 5
setblock ~11~15~43 minecraft:stained_glass 12
setblock ~11~16~43 minecraft:red_sandstone 3
fill ~11~39~43 ~11~39~44 minecraft:concrete 1
fill ~12~6~43 ~12~6~44 minecraft:wool 15
setblock ~12~17~43 minecraft:red_sandstone 3
fill ~12~18~43 ~12~19~43 minecraft:calcite
fill ~12~20~43 ~12~22~43 minecraft:wool 0
setblock ~12~40~43 minecraft:stained_glass 1
setblock ~13~22~43 minecraft:stained_glass 0
setblock ~13~23~43 minecraft:wool 0
setblock ~13~40~43 minecraft:wool 1
setblock ~14~24~43 minecraft:stained_glass 0
fill ~14~25~43 ~15~25~43 minecraft:calcite
fill ~15~42~43 ~16~42~43 minecraft:stained_glass 1
setblock ~16~25~43 minecraft:stained_glass 0
fill ~17~0~43 ~18~0~50 minecraft:concrete 12
fill ~17~25~43 ~18~25~43 minecraft:wool 0
fill ~17~41~43 ~17~41~44 minecraft:concrete 1
fill ~18~1~43 ~18~1~49 minecraft:concrete 12
setblock ~18~24~43 minecraft:stained_glass 0
fill ~18~41~43 ~18~41~44 minecraft:wool 1
fill ~19~0~43 ~19~0~48 minecraft:dirt 0
fill ~19~1~43 ~19~2~47 minecraft:dirt 0
fill ~19~3~43 ~19~4~47 minecraft:wool 15
fill ~19~5~43 ~20~5~44 minecraft:wool 15
setblock ~19~21~43 minecraft:stained_glass 0
setblock ~19~22~43 minecraft:wool 0
fill ~19~23~43 ~19~24~43 minecraft:calcite
fill ~20~2~43 ~20~2~45 minecraft:dirt 0
setblock ~20~16~43 minecraft:stained_glass 0
fill ~20~19~43 ~20~19~44 minecraft:calcite
setblock ~20~20~43 minecraft:wool 0
fill ~20~39~43 ~21~39~43 minecraft:concrete 1
setblock ~20~40~43 minecraft:stained_glass 1
setblock ~21~6~43 minecraft:wool 15
setblock ~21~16~43 minecraft:red_sandstone 3
setblock ~22~7~43 minecraft:wool 15
fill ~22~12~43 ~22~14~43 minecraft:wool 15
setblock ~22~39~43 minecraft:wool 1
setblock ~23~6~43 minecraft:wool 15
setblock ~23~15~43 minecraft:wool 15
setblock ~23~38~43 minecraft:wool 1
fill ~24~0~43 ~24~0~48 minecraft:dirt 0
fill ~24~1~43 ~24~2~47 minecraft:dirt 0
fill ~24~3~43 ~24~4~47 minecraft:wool 15
setblock ~24~15~43 minecraft:stained_glass 12
setblock ~24~16~43 minecraft:planks 5
fill ~24~17~43 ~24~17~44 minecraft:stained_hardened_clay 1
setblock ~24~37~43 minecraft:wool 1
setblock ~24~38~43 minecraft:stained_glass 1
fill ~25~0~43 ~26~1~58 minecraft:stained_hardened_clay 1
fill ~25~2~43 ~26~2~57 minecraft:stained_hardened_clay 1
setblock ~25~17~43 minecraft:stained_glass 1
setblock ~25~18~43 minecraft:red_sandstone 3
setblock ~25~19~43 minecraft:stained_hardened_clay 1
setblock ~25~36~43 minecraft:wool 1
setblock ~25~37~43 minecraft:stained_glass 1
fill ~26~20~43 ~26~21~43 minecraft:planks 4
fill ~26~22~43 ~26~22~44 minecraft:red_sandstone 3
setblock ~26~34~43 minecraft:concrete 1
setblock ~26~35~43 minecraft:wool 1
fill ~27~0~43 ~27~1~43 minecraft:concrete 12
setblock ~27~22~43 minecraft:stained_glass 1
fill ~27~23~43 ~27~23~44 minecraft:wool 1
setblock ~27~24~43 minecraft:wool 1
setblock ~27~25~43 minecraft:concrete 1
fill ~27~32~43 ~27~33~43 minecraft:concrete 1
setblock ~27~34~43 minecraft:stained_glass 1
setblock ~28~27~43 minecraft:stained_glass 1
fill ~28~28~43 ~28~28~47 minecraft:wool 1
fill ~28~29~43 ~28~29~46 minecraft:wool 1
fill ~28~30~43 ~28~31~45 minecraft:wool 1
setblock ~28~32~43 minecraft:stained_glass 1
fill ~31~0~43 ~31~1~44 minecraft:concrete 12
fill ~33~0~43 ~35~1~52 minecraft:stained_hardened_clay 1
fill ~38~0~43 ~38~0~45 minecraft:concrete 12
setblock ~5~21~44 minecraft:stained_glass 1
fill ~5~22~44 ~5~22~45 minecraft:wool 1
setblock ~5~23~44 minecraft:wool 1
setblock ~5~24~44 minecraft:stained_glass 1
setblock ~6~19~44 minecraft:stained_glass 1
fill ~6~20~44 ~6~20~45 minecraft:wool 1
fill ~6~21~44 ~6~21~45 minecraft:concrete 1
fill ~6~24~44 ~6~32~44 minecraft:concrete 1
setblock ~6~33~44 minecraft:wool 1
setblock ~6~34~44 minecraft:stained_glass 1
fill ~7~19~44 ~7~19~45 minecraft:red_sandstone 3
setblock ~7~34~44 minecraft:concrete 1
setblock ~7~35~44 minecraft:wool 1
setblock ~7~36~44 minecraft:stained_glass 1
fill ~8~5~44 ~9~5~44 minecraft:wool 15
setblock ~8~6~44 minecraft:wool 15
setblock ~8~16~44 minecraft:stained_glass 12
setblock ~8~17~44 minecraft:stained_hardened_clay 1
setblock ~8~18~44 minecraft:planks 4
setblock ~9~4~44 minecraft:wool 15
setblock ~9~7~44 minecraft:wool 15
setblock ~9~16~44 minecraft:planks 5
fill ~9~38~44 ~9~38~46 minecraft:concrete 1
fill ~10~3~44 ~10~3~45 minecraft:wool 15
fill ~10~8~44 ~11~8~44 minecraft:wool 15
setblock ~10~16~44 minecraft:wool 15
setblock ~11~4~44 minecraft:red_sandstone 3
fill ~11~16~44 ~11~17~44 minecraft:planks 5
setblock ~11~40~44 minecraft:stained_glass 1
fill ~12~5~44 ~12~5~46 minecraft:wool 15
setblock ~12~17~44 minecraft:stained_glass 0
setblock ~12~18~44 minecraft:wool 0
fill ~12~19~44 ~12~20~44 minecraft:calcite
setblock ~12~40~44 minecraft:wool 1
setblock ~13~20~44 minecraft:stained_glass 0
setblock ~13~21~44 minecraft:wool 0
fill ~13~22~44 ~13~22~46 minecraft:calcite
setblock ~13~40~44 minecraft:concrete 1
setblock ~13~41~44 minecraft:stained_glass 1
setblock ~14~23~44 minecraft:wool 0
setblock ~14~24~44 minecraft:calcite
setblock ~14~41~44 minecraft:wool 1
fill ~15~25~44 ~17~25~44 minecraft:calcite
fill ~15~42~44 ~16~42~44 minecraft:wool 1
fill ~17~1~44 ~17~1~47 minecraft:concrete 12
setblock ~17~42~44 minecraft:stained_glass 1
setblock ~18~2~44 minecraft:concrete 12
setblock ~18~22~44 minecraft:stained_glass 0
fill ~18~23~44 ~18~24~44 minecraft:calcite
setblock ~19~20~44 minecraft:stained_glass 0
fill ~19~21~44 ~19~22~44 minecraft:calcite
setblock ~19~40~44 minecraft:concrete 1
setblock ~19~41~44 minecraft:stained_glass 1
fill ~20~0~44 ~20~1~45 minecraft:dirt 0
setblock ~20~17~44 minecraft:stained_glass 0
fill ~20~18~44 ~20~18~45 minecraft:wool 0
fill ~20~20~44 ~20~20~45 minecraft:calcite
fill ~20~40~44 ~21~40~44 minecraft:wool 1
fill ~21~0~44 ~21~2~44 minecraft:concrete 12
fill ~21~5~44 ~21~5~48 minecraft:wool 15
setblock ~21~17~44 minecraft:red_sandstone 3
fill ~22~0~44 ~23~0~49 minecraft:dirt 0
fill ~22~1~44 ~23~2~45 minecraft:dirt 0
setblock ~22~6~44 minecraft:wool 15
setblock ~22~15~44 minecraft:wool 15
setblock ~22~16~44 minecraft:planks 5
setblock ~22~39~44 minecraft:concrete 1
setblock ~22~40~44 minecraft:stained_glass 1
fill ~23~5~44 ~23~5~47 minecraft:wool 15
setblock ~23~16~44 minecraft:wool 15
fill ~23~39~44 ~23~39~47 minecraft:wool 1
setblock ~24~18~44 minecraft:stained_hardened_clay 1
fill ~24~38~44 ~24~38~45 minecraft:wool 1
setblock ~25~18~44 minecraft:stained_glass 1
setblock ~25~19~44 minecraft:red_sandstone 3
setblock ~25~20~44 minecraft:stained_hardened_clay 1
setblock ~25~37~44 minecraft:wool 1
setblock ~26~20~44 minecraft:stained_glass 1
setblock ~26~21~44 minecraft:planks 4
setblock ~26~35~44 minecraft:concrete 1
setblock ~26~36~44 minecraft:wool 1
fill ~27~0~44 ~27~1~60 minecraft:stained_hardened_clay 1
fill ~27~2~44 ~27~2~58 minecraft:stained_hardened_clay 1
fill ~27~24~44 ~27~24~45 minecraft:concrete 1
fill ~27~33~44 ~27~33~45 minecraft:concrete 1
setblock ~27~34~44 minecraft:wool 1
setblock ~27~35~44 minecraft:stained_glass 1
setblock ~28~24~44 minecraft:stained_glass 1
fill ~28~25~44 ~28~27~44 minecraft:wool 1
fill ~28~32~44 ~28~32~45 minecraft:wool 1
fill ~36~0~44 ~36~1~51 minecraft:stained_hardened_clay 1
setblock ~37~0~44 minecraft:concrete 12
fill ~39~0~44 ~39~0~46 minecraft:concrete 12
setblock ~5~23~45 minecraft:concrete 1
fill ~5~24~45 ~5~31~45 minecraft:wool 1
setblock ~5~32~45 minecraft:stained_glass 1
fill ~6~32~45 ~6~33~45 minecraft:concrete 1
fill ~6~34~45 ~6~34~46 minecraft:wool 1
setblock ~6~35~45 minecraft:stained_glass 1
setblock ~7~35~45 minecraft:concrete 1
setblock ~7~36~45 minecraft:wool 1
setblock ~7~37~45 minecraft:stained_glass 1
fill ~8~4~45 ~8~4~46 minecraft:wool 15
setblock ~8~5~45 minecraft:wool 15
setblock ~8~17~45 minecraft:stained_glass 12
setblock ~8~18~45 minecraft:stained_hardened_clay 1
setblock ~8~38~45 minecraft:stained_glass 1
setblock ~9~3~45 minecraft:wool 15
setblock ~9~6~45 minecraft:wool 15
setblock ~9~16~45 minecraft:stained_glass 12
setblock ~9~17~45 minecraft:planks 5
fill ~10~7~45 ~11~7~45 minecraft:wool 15
setblock ~10~17~45 minecraft:wool 15
setblock ~11~3~45 minecraft:wool 15
fill ~11~6~45 ~11~6~46 minecraft:wool 15
setblock ~11~18~45 minecraft:planks 5
setblock ~11~40~45 minecraft:wool 1
fill ~12~4~45 ~12~4~47 minecraft:wool 15
setblock ~12~18~45 minecraft:stained_glass 0
fill ~12~19~45 ~12~20~45 minecraft:wool 0
fill ~12~21~45 ~12~21~46 minecraft:calcite
setblock ~12~40~45 minecraft:concrete 1
setblock ~12~41~45 minecraft:stained_glass 1
setblock ~13~21~45 minecraft:stained_glass 0
setblock ~13~41~45 minecraft:wool 1
fill ~14~23~45 ~14~23~46 minecraft:calcite
fill ~14~42~45 ~14~42~48 minecraft:wool 1
fill ~15~23~45 ~15~23~46 minecraft:stained_glass 0
fill ~15~24~45 ~18~24~57 minecraft:calcite
fill ~15~42~45 ~15~42~47 minecraft:concrete 1
fill ~16~42~45 ~17~42~46 minecraft:wool 1
setblock ~18~23~45 minecraft:stained_glass 0
setblock ~18~41~45 minecraft:concrete 1
setblock ~19~21~45 minecraft:stained_glass 0
fill ~19~22~45 ~19~23~45 minecraft:calcite
setblock ~19~41~45 minecraft:wool 1
fill ~20~5~45 ~20~5~47 minecraft:wool 15
setblock ~20~19~45 minecraft:wool 0
fill ~20~21~45 ~20~21~46 minecraft:calcite
setblock ~20~40~45 minecraft:concrete 1
setblock ~20~41~45 minecraft:stained_glass 1
fill ~21~0~45 ~21~0~49 minecraft:dirt 0
fill ~21~1~45 ~21~2~45 minecraft:dirt 0
setblock ~21~17~45 minecraft:planks 5
fill ~21~40~45 ~22~40~45 minecraft:wool 1
fill ~22~5~45 ~22~5~48 minecraft:wool 15
setblock ~22~16~45 minecraft:wool 15
setblock ~23~16~45 minecraft:stained_glass 12
setblock ~23~17~45 minecraft:planks 5
setblock ~24~18~45 minecraft:planks 5
setblock ~24~19~45 minecraft:stained_hardened_clay 1
setblock ~25~19~45 minecraft:stained_glass 1
fill ~25~20~45 ~25~20~46 minecraft:red_sandstone 3
setblock ~25~21~45 minecraft:stained_hardened_clay 1
fill ~25~37~45 ~25~37~46 minecraft:concrete 1
setblock ~26~21~45 minecraft:stained_glass 1
fill ~26~22~45 ~26~22~46 minecraft:planks 4
setblock ~26~23~45 minecraft:stained_hardened_clay 1
fill ~26~36~45 ~26~36~47 minecraft:concrete 1
setblock ~27~23~45 minecraft:stained_glass 1
fill ~27~25~45 ~27~26~46 minecraft:concrete 1
fill ~27~34~45 ~27~34~46 minecraft:concrete 1
setblock ~27~35~45 minecraft:wool 1
fill ~28~0~45 ~28~1~61 minecraft:stained_hardened_clay 1
fill ~28~2~45 ~28~2~59 minecraft:stained_hardened_clay 1
setblock ~28~26~45 minecraft:stained_glass 1
setblock ~28~27~45 minecraft:wool 1
setblock ~28~33~45 minecraft:stained_glass 1
fill ~31~0~45 ~31~2~57 minecraft:stained_hardened_clay 1
fill ~32~2~45 ~32~2~56 minecraft:stained_hardened_clay 1
fill ~37~0~45 ~37~1~51 minecraft:stained_hardened_clay 1
fill ~40~0~45 ~40~0~52 minecraft:concrete 12
fill ~4~0~46 ~4~0~47 minecraft:wool 12
setblock ~4~24~46 minecraft:stained_glass 1
fill ~4~25~46 ~4~25~47 minecraft:wool 1
fill ~4~26~46 ~4~27~46 minecraft:stained_glass 1
fill ~4~28~46 ~4~29~50 minecraft:wool 1
fill ~4~30~46 ~4~30~48 minecraft:wool 1
setblock ~4~31~46 minecraft:stained_glass 1
setblock ~5~22~46 minecraft:stained_glass 1
setblock ~5~23~46 minecraft:wool 1
fill ~5~24~46 ~5~24~47 minecraft:concrete 1
fill ~5~26~46 ~5~27~46 minecraft:concrete 1
setblock ~5~31~46 minecraft:concrete 1
setblock ~5~32~46 minecraft:wool 1
setblock ~5~33~46 minecraft:stained_glass 1
setblock ~6~20~46 minecraft:stained_glass 1
setblock ~6~21~46 minecraft:wool 1
setblock ~6~22~46 minecraft:concrete 1
setblock ~6~33~46 minecraft:concrete 1
fill ~6~35~46 ~6~35~47 minecraft:wool 1
setblock ~7~20~46 minecraft:red_sandstone 3
fill ~7~36~46 ~7~36~47 minecraft:concrete 1
setblock ~7~37~46 minecraft:wool 1
fill ~8~3~46 ~8~3~47 minecraft:wool 15
setblock ~8~18~46 minecraft:stained_glass 12
setblock ~8~19~46 minecraft:stained_hardened_clay 1
fill ~8~38~46 ~8~38~48 minecraft:wool 1
fill ~9~2~46 ~11~2~46 minecraft:wool 15
setblock ~9~5~46 minecraft:wool 15
setblock ~9~17~46 minecraft:stained_glass 12
setblock ~9~18~46 minecraft:planks 5
setblock ~9~39~46 minecraft:stained_glass 1
setblock ~10~0~46 minecraft:wool 12
setblock ~10~6~46 minecraft:wool 15
setblock ~10~18~46 minecraft:wool 15
setblock ~11~5~46 minecraft:wool 15
setblock ~11~19~46 minecraft:planks 5
setblock ~11~20~46 minecraft:stained_hardened_clay 1
fill ~11~40~46 ~11~40~49 minecraft:concrete 1
fill ~12~3~46 ~12~3~49 minecraft:wool 15
setblock ~12~20~46 minecraft:stained_glass 0
fill ~12~41~46 ~12~41~48 minecraft:wool 1
setblock ~13~0~46 minecraft:concrete 12
fill ~13~41~46 ~13~41~51 minecraft:concrete 1
setblock ~18~2~46 minecraft:concrete 12
fill ~18~41~46 ~18~41~48 minecraft:red_sandstone 3
fill ~19~23~46 ~19~23~47 minecraft:calcite
fill ~19~41~46 ~19~41~48 minecraft:concrete 1
fill ~20~0~46 ~20~1~46 minecraft:concrete 12
setblock ~20~19~46 minecraft:stained_glass 0
setblock ~20~20~46 minecraft:wool 0
fill ~20~22~46 ~20~22~47 minecraft:calcite
setblock ~20~41~46 minecraft:wool 1
fill ~21~1~46 ~22~1~47 minecraft:grass
setblock ~21~18~46 minecraft:red_sandstone 3
setblock ~21~19~46 minecraft:wool 0
setblock ~21~40~46 minecraft:concrete 1
setblock ~21~41~46 minecraft:stained_glass 1
setblock ~22~17~46 minecraft:wool 15
fill ~22~40~46 ~22~40~47 minecraft:wool 1
fill ~23~1~46 ~23~2~48 minecraft:dirt 0
setblock ~23~18~46 minecraft:wool 15
setblock ~24~18~46 minecraft:stained_glass 12
setblock ~24~19~46 minecraft:planks 5
setblock ~24~38~46 minecraft:concrete 1
setblock ~24~39~46 minecraft:stained_glass 1
fill ~25~21~46 ~25~21~48 minecraft:red_sandstone 3
setblock ~25~38~46 minecraft:stained_glass 1
fill ~26~23~46 ~26~23~47 minecraft:planks 4
setblock ~26~24~46 minecraft:red_sandstone 3
setblock ~26~37~46 minecraft:stained_glass 1
setblock ~27~24~46 minecraft:stained_glass 1
fill ~27~27~46 ~27~27~49 minecraft:concrete 1
fill ~27~35~46 ~27~35~48 minecraft:concrete 1
fill ~28~27~46 ~28~27~48 minecraft:stained_glass 1
fill ~28~30~46 ~28~32~49 minecraft:concrete 1
setblock ~28~33~46 minecraft:wool 1
setblock ~28~34~46 minecraft:stained_glass 1
fill ~29~0~46 ~30~1~61 minecraft:stained_hardened_clay 1
fill ~29~2~46 ~30~2~60 minecraft:stained_hardened_clay 1
fill ~33~2~46 ~33~2~55 minecraft:stained_hardened_clay 1
fill ~38~0~46 ~38~1~48 minecraft:stained_hardened_clay 1
fill ~4~26~47 ~4~27~49 minecraft:wool 1
fill ~4~31~47 ~4~31~48 minecraft:wool 1
setblock ~4~32~47 minecraft:stained_glass 1
setblock ~5~23~47 minecraft:stained_glass 1
setblock ~5~32~47 minecraft:concrete 1
setblock ~5~33~47 minecraft:wool 1
setblock ~5~34~47 minecraft:stained_glass 1
setblock ~6~21~47 minecraft:stained_glass 1
setblock ~6~22~47 minecraft:wool 1
fill ~6~23~47 ~6~23~49 minecraft:concrete 1
setblock ~6~34~47 minecraft:concrete 1
setblock ~6~36~47 minecraft:stained_glass 1
setblock ~7~21~47 minecraft:planks 4
fill ~7~37~47 ~7~37~52 minecraft:concrete 1
fill ~8~2~47 ~8~2~52 minecraft:wool 15
setblock ~8~19~47 minecraft:stained_glass 12
setblock ~8~20~47 minecraft:stained_hardened_clay 1
setblock ~9~4~47 minecraft:wool 15
setblock ~9~18~47 minecraft:stained_glass 12
setblock ~9~19~47 minecraft:planks 5
setblock ~9~39~47 minecraft:wool 1
setblock ~10~0~47 minecraft:dirt 0
fill ~10~1~47 ~12~1~47 minecraft:wool 15
setblock ~10~5~47 minecraft:wool 15
setblock ~10~19~47 minecraft:wool 15
setblock ~10~20~47 minecraft:planks 5
setblock ~10~39~47 minecraft:concrete 1
setblock ~10~40~47 minecraft:stained_glass 1
fill ~11~0~47 ~11~0~48 minecraft:wool 15
fill ~11~4~47 ~11~4~48 minecraft:wool 15
setblock ~11~21~47 minecraft:stained_hardened_clay 1
fill ~12~2~47 ~12~2~50 minecraft:wool 15
setblock ~12~21~47 minecraft:stained_glass 0
setblock ~12~22~47 minecraft:calcite
setblock ~13~22~47 minecraft:stained_glass 0
setblock ~13~23~47 minecraft:calcite
setblock ~14~23~47 minecraft:stained_glass 0
fill ~14~24~47 ~14~24~59 minecraft:calcite
setblock ~16~42~47 minecraft:wool 1
setblock ~17~42~47 minecraft:concrete 1
setblock ~19~22~47 minecraft:stained_glass 0
fill ~20~0~47 ~20~0~49 minecraft:dirt 0
setblock ~20~1~47 minecraft:grass
setblock ~20~21~47 minecraft:stained_glass 0
fill ~20~41~47 ~20~41~50 minecraft:concrete 1
setblock ~21~19~47 minecraft:planks 4
setblock ~21~20~47 minecraft:planks 5
setblock ~21~21~47 minecraft:wool 0
fill ~21~41~47 ~21~41~48 minecraft:wool 1
setblock ~22~18~47 minecraft:wool 15
setblock ~23~19~47 minecraft:wool 15
setblock ~23~40~47 minecraft:stained_glass 1
setblock ~24~20~47 minecraft:stained_hardened_clay 1
setblock ~24~39~47 minecraft:wool 1
setblock ~25~22~47 minecraft:stained_hardened_clay 1
fill ~25~38~47 ~25~38~50 minecraft:wool 1
setblock ~26~22~47 minecraft:stained_glass 1
fill ~26~24~47 ~26~25~47 minecraft:planks 4
fill ~26~37~47 ~26~37~50 minecraft:wool 1
setblock ~27~25~47 minecraft:stained_glass 1
fill ~27~26~47 ~27~26~48 minecraft:concrete 1
setblock ~27~36~47 minecraft:stained_glass 1
fill ~28~29~47 ~28~29~48 minecraft:concrete 1
fill ~28~33~47 ~28~33~50 minecraft:concrete 1
setblock ~28~34~47 minecraft:wool 1
fill ~34~2~47 ~34~2~53 minecraft:stained_hardened_clay 1
fill ~39~0~47 ~39~1~47 minecraft:stained_hardened_clay 1
setblock ~4~25~48 minecraft:stained_glass 1
fill ~4~32~48 ~4~32~52 minecraft:wool 1
setblock ~4~33~48 minecraft:stained_glass 1
fill ~5~24~48 ~5~24~49 minecraft:wool 1
fill ~5~25~48 ~5~25~49 minecraft:concrete 1
setblock ~5~33~48 minecraft:concrete 1
setblock ~5~34~48 minecraft:wool 1
setblock ~5~35~48 minecraft:stained_glass 1
setblock ~6~22~48 minecraft:stained_glass 1
setblock ~6~35~48 minecraft:concrete 1
fill ~6~36~48 ~6~36~49 minecraft:wool 1
setblock ~7~21~48 minecraft:red_sandstone 3
setblock ~7~22~48 minecraft:planks 4
fill ~8~0~48 ~9~0~48 minecraft:dirt 0
fill ~8~1~48 ~9~1~48 minecraft:wool 15
setblock ~8~20~48 minecraft:stained_glass 12
setblock ~8~21~48 minecraft:stained_hardened_clay 1
fill ~9~3~48 ~9~3~52 minecraft:wool 15
setblock ~9~19~48 minecraft:stained_glass 12
setblock ~9~20~48 minecraft:wool 15
fill ~9~39~48 ~9~39~50 minecraft:concrete 1
setblock ~10~4~48 minecraft:wool 15
setblock ~10~20~48 minecraft:stained_glass 12
setblock ~10~21~48 minecraft:planks 5
setblock ~10~40~48 minecraft:wool 1
setblock ~11~22~48 minecraft:red_sandstone 3
fill ~12~0~48 ~12~1~52 minecraft:wool 15
setblock ~12~22~48 minecraft:stained_glass 0
setblock ~12~23~48 minecraft:calcite
setblock ~13~23~48 minecraft:stained_glass 0
fill ~13~24~48 ~13~24~50 minecraft:calcite
setblock ~15~0~48 minecraft:concrete 12
fill ~15~42~48 ~15~42~50 minecraft:red_sandstone 3
setblock ~16~42~48 minecraft:concrete 1
setblock ~17~42~48 minecraft:red_sandstone 3
fill ~19~1~48 ~19~1~50 minecraft:concrete 12
fill ~19~2~48 ~19~2~49 minecraft:concrete 12
setblock ~19~3~48 minecraft:cobblestone_wall 4
fill ~19~24~48 ~19~24~51 minecraft:calcite
fill ~20~1~48 ~21~2~48 minecraft:dirt 0
fill ~20~3~48 ~20~4~48 minecraft:wool 15
setblock ~20~23~48 minecraft:planks 5
fill ~21~21~48 ~21~22~48 minecraft:planks 4
setblock ~22~1~48 minecraft:grass
fill ~22~19~48 ~22~20~48 minecraft:wool 15
setblock ~22~21~48 minecraft:planks 5
setblock ~22~40~48 minecraft:concrete 1
setblock ~22~41~48 minecraft:stained_glass 1
fill ~23~3~48 ~23~4~48 minecraft:wool 15
setblock ~23~20~48 minecraft:wool 15
setblock ~23~40~48 minecraft:wool 1
fill ~24~1~48 ~24~1~57 minecraft:stained_hardened_clay 1
fill ~24~2~48 ~24~2~56 minecraft:stained_hardened_clay 1
setblock ~24~3~48 minecraft:cobblestone_wall 4
setblock ~24~20~48 minecraft:planks 5
fill ~24~39~48 ~24~39~50 minecraft:concrete 1
setblock ~25~22~48 minecraft:red_sandstone 3
fill ~25~23~48 ~25~24~48 minecraft:stained_hardened_clay 1
setblock ~26~25~48 minecraft:planks 4
fill ~27~36~48 ~27~36~49 minecraft:concrete 1
setblock ~28~28~48 minecraft:concrete 1
fill ~28~34~48 ~28~34~49 minecraft:concrete 1
setblock ~28~35~48 minecraft:stained_glass 1
fill ~35~2~48 ~35~2~52 minecraft:stained_hardened_clay 1
fill ~39~0~48 ~39~0~58 minecraft:concrete 12
fill ~41~0~48 ~41~0~52 minecraft:concrete 12
fill ~4~30~49 ~4~31~49 minecraft:concrete 1
fill ~4~33~49 ~4~33~52 minecraft:wool 1
fill ~5~34~49 ~5~34~54 minecraft:concrete 1
setblock ~5~35~49 minecraft:wool 1
setblock ~7~22~49 minecraft:red_sandstone 3
fill ~8~0~49 ~8~1~49 minecraft:wool 15
setblock ~8~21~49 minecraft:planks 5
fill ~8~38~49 ~8~38~51 minecraft:concrete 1
setblock ~9~21~49 minecraft:wool 15
fill ~10~3~49 ~11~3~50 minecraft:wool 15
setblock ~10~22~49 minecraft:planks 5
fill ~10~40~49 ~10~40~51 minecraft:concrete 1
setblock ~11~23~49 minecraft:red_sandstone 3
setblock ~11~41~49 minecraft:stained_glass 1
setblock ~12~23~49 minecraft:stained_glass 0
setblock ~12~24~49 minecraft:calcite
fill ~12~41~49 ~12~41~52 minecraft:concrete 1
setblock ~13~42~49 minecraft:stained_glass 1
fill ~14~23~49 ~14~23~50 minecraft:stained_glass 0
setblock ~14~42~49 minecraft:concrete 1
fill ~16~42~49 ~17~42~50 minecraft:planks 4
fill ~18~41~49 ~18~41~51 minecraft:planks 4
fill ~19~0~49 ~19~0~52 minecraft:concrete 12
fill ~19~41~49 ~19~41~50 minecraft:red_sandstone 3
fill ~20~1~49 ~20~1~51 minecraft:concrete 12
setblock ~20~2~49 minecraft:concrete 12
setblock ~20~3~49 minecraft:cobblestone_wall 4
fill ~20~24~49 ~20~24~50 minecraft:calcite
fill ~21~1~49 ~22~2~49 minecraft:dirt 0
fill ~21~3~49 ~22~4~49 minecraft:wool 15
fill ~21~23~49 ~22~23~49 minecraft:planks 5
fill ~21~41~49 ~21~41~50 minecraft:concrete 1
fill ~22~22~49 ~23~22~49 minecraft:planks 5
setblock ~22~41~49 minecraft:wool 1
fill ~23~1~49 ~23~1~56 minecraft:stained_hardened_clay 1
fill ~23~2~49 ~23~2~51 minecraft:stained_hardened_clay 1
setblock ~23~3~49 minecraft:cobblestone_wall 4
setblock ~23~21~49 minecraft:wool 15
setblock ~23~40~49 minecraft:concrete 1
fill ~24~0~49 ~24~0~57 minecraft:stained_hardened_clay 1
setblock ~24~20~49 minecraft:stained_glass 12
setblock ~24~21~49 minecraft:planks 5
setblock ~24~22~49 minecraft:planks 4
setblock ~25~23~49 minecraft:red_sandstone 3
setblock ~25~24~49 minecraft:stained_hardened_clay 1
fill ~26~25~49 ~26~25~50 minecraft:wool 1
setblock ~26~26~49 minecraft:concrete 1
setblock ~27~26~49 minecraft:stained_glass 1
fill ~27~28~49 ~27~29~49 minecraft:concrete 1
setblock ~28~35~49 minecraft:wool 1
fill ~36~2~49 ~36~2~51 minecraft:stained_hardened_clay 1
fill ~38~0~49 ~38~1~50 minecraft:concrete 12
setblock ~39~1~49 minecraft:stained_hardened_clay 1
setblock ~4~26~50 minecraft:stained_glass 1
setblock ~4~27~50 minecraft:wool 1
fill ~4~30~50 ~4~31~51 minecraft:wool 1
setblock ~5~24~50 minecraft:stained_glass 1
setblock ~5~25~50 minecraft:wool 1
setblock ~5~26~50 minecraft:concrete 1
fill ~5~35~50 ~5~35~59 minecraft:concrete 1
setblock ~6~23~50 minecraft:stained_glass 1
setblock ~6~24~50 minecraft:concrete 1
fill ~6~36~50 ~6~36~54 minecraft:concrete 1
fill ~7~0~50 ~7~1~52 minecraft:wool 15
setblock ~7~22~50 minecraft:stained_glass 12
setblock ~7~23~50 minecraft:red_sandstone 3
setblock ~8~21~50 minecraft:stained_glass 12
setblock ~8~22~50 minecraft:planks 5
setblock ~8~39~50 minecraft:stained_glass 1
setblock ~9~22~50 minecraft:wool 15
fill ~9~23~50 ~10~23~50 minecraft:planks 5
setblock ~9~40~50 minecraft:stained_glass 1
setblock ~11~24~50 minecraft:red_sandstone 3
setblock ~11~41~50 minecraft:wool 1
setblock ~12~24~50 minecraft:planks 5
fill ~14~42~50 ~14~42~51 minecraft:red_sandstone 3
fill ~15~23~50 ~15~23~51 minecraft:stained_glass 0
fill ~17~23~50 ~17~23~57 minecraft:stained_glass 0
fill ~20~0~50 ~22~0~50 minecraft:concrete 12
fill ~21~1~50 ~22~2~50 minecraft:concrete 12
fill ~21~24~50 ~22~24~50 minecraft:planks 5
setblock ~22~23~50 minecraft:stained_glass 12
fill ~22~40~50 ~22~40~59 minecraft:concrete 1
setblock ~22~41~50 minecraft:stained_glass 1
fill ~23~0~50 ~23~0~56 minecraft:stained_hardened_clay 1
setblock ~23~22~50 minecraft:stained_glass 12
setblock ~23~23~50 minecraft:planks 5
setblock ~23~40~50 minecraft:wool 1
setblock ~24~23~50 minecraft:planks 4
setblock ~25~24~50 minecraft:red_sandstone 3
fill ~26~26~50 ~26~27~51 minecraft:wool 1
setblock ~27~27~50 minecraft:stained_glass 1
fill ~27~28~50 ~27~31~50 minecraft:wool 1
setblock ~27~35~50 minecraft:concrete 1
setblock ~27~36~50 minecraft:wool 1
setblock ~28~32~50 minecraft:concrete 1
setblock ~28~34~50 minecraft:wool 1
setblock ~28~35~50 minecraft:stained_glass 1
fill ~37~2~50 ~37~2~51 minecraft:stained_hardened_clay 1
fill ~39~1~50 ~39~1~55 minecraft:concrete 12
setblock ~4~28~51 minecraft:stained_glass 1
setblock ~4~29~51 minecraft:wool 1
setblock ~5~25~51 minecraft:stained_glass 1
setblock ~5~26~51 minecraft:wool 1
fill ~5~27~51 ~5~28~51 minecraft:concrete 1
setblock ~6~24~51 minecraft:stained_glass 1
setblock ~6~25~51 minecraft:concrete 1
setblock ~7~23~51 minecraft:stained_glass 12
setblock ~7~24~51 minecraft:red_sandstone 3
setblock ~7~38~51 minecraft:stained_glass 1
setblock ~8~22~51 minecraft:stained_glass 12
setblock ~8~23~51 minecraft:planks 5
setblock ~8~39~51 minecraft:wool 1
fill ~9~24~51 ~11~24~51 minecraft:planks 5
fill ~9~40~51 ~9~40~52 minecraft:wool 1
fill ~10~3~51 ~10~3~52 minecraft:wool 15
setblock ~10~41~51 minecraft:stained_glass 1
fill ~11~2~51 ~11~2~52 minecraft:wool 15
fill ~11~41~51 ~11~41~53 minecraft:concrete 1
fill ~12~25~51 ~12~25~52 minecraft:planks 5
setblock ~13~24~51 minecraft:planks 5
setblock ~15~42~51 minecraft:planks 4
fill ~16~23~51 ~16~23~57 minecraft:stained_glass 0
fill ~16~42~51 ~17~42~52 minecraft:stained_hardened_clay 1
fill ~18~0~51 ~18~0~52 minecraft:concrete 12
setblock ~18~42~51 minecraft:stained_glass 1
fill ~19~41~51 ~19~41~53 minecraft:planks 4
fill ~20~0~51 ~21~0~51 minecraft:concrete 12
setblock ~20~24~51 minecraft:planks 5
setblock ~20~41~51 minecraft:red_sandstone 3
setblock ~21~1~51 minecraft:concrete 12
setblock ~21~24~51 minecraft:stained_glass 12
fill ~21~25~51 ~21~25~54 minecraft:planks 5
fill ~21~41~51 ~21~41~55 minecraft:wool 1
fill ~22~0~51 ~22~1~53 minecraft:stained_hardened_clay 1
fill ~22~24~51 ~23~24~51 minecraft:planks 5
fill ~23~39~51 ~23~39~59 minecraft:concrete 1
setblock ~23~40~51 minecraft:stained_glass 1
setblock ~24~24~51 minecraft:planks 4
setblock ~24~38~51 minecraft:concrete 1
setblock ~24~39~51 minecraft:wool 1
setblock ~25~25~51 minecraft:red_sandstone 3
fill ~25~37~51 ~25~37~58 minecraft:concrete 1
setblock ~25~38~51 minecraft:stained_glass 1
setblock ~26~25~51 minecraft:stained_glass 1
fill ~26~28~51 ~26~30~51 minecraft:wool 1
setblock ~26~36~51 minecraft:concrete 1
setblock ~26~37~51 minecraft:stained_glass 1
setblock ~27~30~51 minecraft:stained_glass 1
fill ~27~31~51 ~27~32~51 minecraft:wool 1
fill ~27~34~51 ~27~34~56 minecraft:concrete 1
setblock ~27~35~51 minecraft:wool 1
setblock ~28~33~51 minecraft:wool 1
setblock ~28~34~51 minecraft:stained_glass 1
fill ~38~0~51 ~38~2~51 minecraft:stained_hardened_clay 1
fill ~4~30~52 ~4~31~52 minecraft:stained_glass 1
fill ~5~26~52 ~5~27~52 minecraft:stained_glass 1
setblock ~5~28~52 minecraft:wool 1
fill ~5~29~52 ~5~31~52 minecraft:concrete 1
setblock ~6~25~52 minecraft:stained_glass 1
setblock ~6~26~52 minecraft:concrete 1
setblock ~6~27~52 minecraft:planks 4
setblock ~6~37~52 minecraft:stained_glass 1
setblock ~7~24~52 minecraft:stained_glass 12
setblock ~7~25~52 minecraft:red_sandstone 3
setblock ~7~38~52 minecraft:wool 1
setblock ~8~23~52 minecraft:stained_glass 12
fill ~8~24~52 ~9~24~52 minecraft:planks 5
fill ~8~39~52 ~8~39~55 minecraft:concrete 1
setblock ~10~25~52 minecraft:stained_hardened_clay 1
setblock ~10~41~52 minecraft:wool 1
fill ~11~25~52 ~11~25~54 minecraft:planks 5
fill ~13~25~52 ~13~25~56 minecraft:stained_hardened_clay 1
setblock ~13~42~52 minecraft:concrete 1
fill ~14~42~52 ~14~42~53 minecraft:planks 4
fill ~15~42~52 ~15~42~54 minecraft:stained_hardened_clay 1
fill ~17~0~52 ~17~0~83 minecraft:wool 12
setblock ~18~42~52 minecraft:concrete 1
fill ~19~24~52 ~19~24~55 minecraft:planks 5
setblock ~20~0~52 minecraft:concrete 12
fill ~20~25~52 ~20~25~55 minecraft:planks 5
fill ~20~41~52 ~20~41~53 minecraft:concrete 1
fill ~21~0~52 ~21~0~73 minecraft:wool 12
setblock ~22~25~52 minecraft:planks 5
setblock ~23~25~52 minecraft:planks 4
fill ~23~26~52 ~24~26~52 minecraft:stained_hardened_clay 1
setblock ~24~25~52 minecraft:red_sandstone 3
setblock ~24~27~52 minecraft:stained_hardened_clay 1
fill ~24~38~52 ~24~38~54 minecraft:wool 1
setblock ~24~39~52 minecraft:stained_glass 1
fill ~25~26~52 ~25~29~52 minecraft:red_sandstone 3
fill ~26~30~52 ~26~31~52 minecraft:red_sandstone 3
fill ~26~35~52 ~26~35~55 minecraft:concrete 1
setblock ~26~36~52 minecraft:wool 1
setblock ~27~31~52 minecraft:stained_glass 1
setblock ~27~32~52 minecraft:wool 1
fill ~27~33~52 ~27~33~56 minecraft:concrete 1
setblock ~27~35~52 minecraft:stained_glass 1
fill ~36~0~52 ~38~0~60 minecraft:concrete 12
fill ~36~1~52 ~38~1~56 minecraft:concrete 12
fill ~36~2~52 ~38~2~54 minecraft:concrete 12
setblock ~5~28~53 minecraft:stained_glass 1
fill ~5~29~53 ~5~30~53 minecraft:wool 1
fill ~5~31~53 ~5~33~53 minecraft:concrete 1
setblock ~6~26~53 minecraft:stained_glass 1
setblock ~6~27~53 minecraft:concrete 1
setblock ~6~28~53 minecraft:planks 4
fill ~6~37~53 ~6~37~54 minecraft:wool 1
setblock ~7~0~53 minecraft:cobblestone_wall 4
fill ~7~26~53 ~7~26~54 minecraft:red_sandstone 3
fill ~7~38~53 ~7~38~56 minecraft:concrete 1
fill ~8~0~53 ~8~1~53 minecraft:wool 15
setblock ~8~24~53 minecraft:stained_glass 12
fill ~8~25~53 ~10~25~53 minecraft:planks 5
fill ~9~2~53 ~10~2~53 minecraft:wool 15
fill ~9~40~53 ~9~40~55 minecraft:concrete 1
fill ~10~41~53 ~10~41~54 minecraft:concrete 1
fill ~11~0~53 ~11~1~53 minecraft:wool 15
setblock ~12~0~53 minecraft:cobblestone_wall 4
fill ~12~25~53 ~12~25~54 minecraft:stained_hardened_clay 1
fill ~12~42~53 ~12~42~54 minecraft:concrete 1
fill ~13~42~53 ~13~42~57 minecraft:red_sandstone 3
fill ~16~0~53 ~16~0~81 minecraft:wool 12
fill ~16~42~53 ~16~42~55 minecraft:planks 4
fill ~17~42~53 ~18~42~53 minecraft:stained_hardened_clay 1
fill ~18~0~53 ~20~0~74 minecraft:wool 12
setblock ~19~42~53 minecraft:stained_glass 1
setblock ~22~25~53 minecraft:stained_glass 12
fill ~22~26~53 ~22~26~54 minecraft:planks 5
setblock ~23~26~53 minecraft:stained_glass 12
setblock ~23~27~53 minecraft:planks 5
fill ~24~27~53 ~24~27~54 minecraft:stained_glass 12
setblock ~24~28~53 minecraft:planks 5
fill ~25~29~53 ~25~30~53 minecraft:red_sandstone 3
fill ~25~36~53 ~25~36~54 minecraft:concrete 1
fill ~26~31~53 ~26~31~54 minecraft:red_sandstone 3
setblock ~26~32~53 minecraft:red_sandstone 3
fill ~33~0~53 ~34~1~53 minecraft:stained_hardened_clay 1
fill ~35~0~53 ~35~0~62 minecraft:concrete 12
fill ~35~1~53 ~35~1~59 minecraft:concrete 12
fill ~35~2~53 ~35~2~58 minecraft:concrete 12
fill ~40~0~53 ~41~0~53 minecraft:stained_hardened_clay 1
setblock ~5~31~54 minecraft:stained_glass 1
setblock ~5~32~54 minecraft:wool 1
setblock ~5~33~54 minecraft:concrete 1
setblock ~5~36~54 minecraft:stained_glass 1
setblock ~6~27~54 minecraft:red_sandstone 3
fill ~6~28~54 ~6~29~54 minecraft:concrete 1
fill ~6~30~54 ~6~31~54 minecraft:red_sandstone 3
fill ~7~27~54 ~8~27~54 minecraft:stained_hardened_clay 1
setblock ~8~0~54 minecraft:cobblestone_wall 4
fill ~8~26~54 ~10~26~54 minecraft:planks 5
fill ~9~0~54 ~10~1~54 minecraft:wool 15
setblock ~10~25~54 minecraft:stained_glass 12
setblock ~11~0~54 minecraft:cobblestone_wall 4
fill ~11~42~54 ~11~42~56 minecraft:concrete 1
setblock ~14~42~54 minecraft:red_sandstone 3
fill ~17~42~54 ~17~42~61 minecraft:stained_hardened_clay 1
setblock ~18~42~54 minecraft:planks 4
fill ~19~42~54 ~19~42~55 minecraft:concrete 1
setblock ~20~41~54 minecraft:red_sandstone 3
fill ~22~0~54 ~22~0~73 minecraft:wool 12
setblock ~23~27~54 minecraft:stained_hardened_clay 1
fill ~24~28~54 ~24~28~55 minecraft:stained_hardened_clay 1
setblock ~24~29~54 minecraft:stained_hardened_clay 1
fill ~25~30~54 ~25~30~55 minecraft:red_sandstone 3
fill ~26~32~54 ~26~32~55 minecraft:concrete 1
setblock ~26~36~54 minecraft:stained_glass 1
fill ~33~0~54 ~33~1~55 minecraft:stained_hardened_clay 1
fill ~34~0~54 ~34~0~62 minecraft:concrete 12
fill ~34~1~54 ~34~1~60 minecraft:concrete 12
fill ~34~2~54 ~34~2~59 minecraft:concrete 12
fill ~40~0~54 ~40~0~56 minecraft:concrete 12
setblock ~41~0~54 minecraft:stained_hardened_clay 1
setblock ~5~32~55 minecraft:stained_glass 1
fill ~5~33~55 ~5~34~55 minecraft:wool 1
fill ~5~36~55 ~5~36~57 minecraft:wool 1
setblock ~6~30~55 minecraft:stained_glass 1
fill ~6~31~55 ~6~32~55 minecraft:red_sandstone 3
fill ~6~37~55 ~6~37~57 minecraft:concrete 1
fill ~7~28~55 ~8~28~55 minecraft:stained_hardened_clay 1
setblock ~7~29~55 minecraft:stained_hardened_clay 1
setblock ~7~30~55 minecraft:planks 4
setblock ~7~39~55 minecraft:stained_glass 1
fill ~9~27~55 ~9~27~56 minecraft:planks 5
fill ~10~26~55 ~11~26~55 minecraft:planks 5
fill ~10~41~55 ~10~41~66 minecraft:stained_hardened_clay 1
fill ~11~25~55 ~11~25~56 minecraft:stained_glass 12
setblock ~12~25~55 minecraft:planks 5
fill ~12~42~55 ~12~42~57 minecraft:red_sandstone 3
fill ~14~42~55 ~14~42~59 minecraft:stained_hardened_clay 1
setblock ~15~42~55 minecraft:red_sandstone 3
fill ~16~43~55 ~16~43~57 minecraft:stained_glass 1
setblock ~18~42~55 minecraft:stained_hardened_clay 1
setblock ~20~24~55 minecraft:stained_glass 1
setblock ~20~41~55 minecraft:wool 1
setblock ~21~25~55 minecraft:stained_hardened_clay 1
setblock ~22~25~55 minecraft:stained_glass 12
setblock ~22~26~55 minecraft:stained_hardened_clay 1
setblock ~23~26~55 minecraft:stained_glass 12
fill ~23~27~55 ~23~27~56 minecraft:red_sandstone 3
setblock ~24~27~55 minecraft:stained_glass 1
fill ~24~38~55 ~24~38~58 minecraft:concrete 1
fill ~25~29~55 ~25~29~56 minecraft:red_sandstone 3
setblock ~26~30~55 minecraft:stained_glass 1
fill ~26~31~55 ~26~31~56 minecraft:concrete 1
setblock ~26~36~55 minecraft:wool 1
setblock ~27~32~55 minecraft:stained_glass 1
setblock ~27~35~55 minecraft:stained_glass 1
fill ~36~2~55 ~37~2~55 minecraft:concrete 12
setblock ~5~34~56 minecraft:stained_glass 1
fill ~6~32~56 ~6~34~56 minecraft:red_sandstone 3
setblock ~6~38~56 minecraft:stained_glass 1
fill ~7~31~56 ~7~31~57 minecraft:planks 4
fill ~7~39~56 ~7~39~57 minecraft:concrete 1
fill ~8~28~56 ~8~30~56 minecraft:planks 5
fill ~8~39~56 ~8~39~58 minecraft:red_sandstone 3
fill ~9~40~56 ~9~40~66 minecraft:stained_hardened_clay 1
fill ~10~26~56 ~11~26~56 minecraft:red_sandstone 3
fill ~12~25~56 ~12~25~58 minecraft:stained_hardened_clay 1
fill ~15~42~56 ~16~42~57 minecraft:stained_hardened_clay 1
fill ~18~42~56 ~19~42~56 minecraft:planks 4
fill ~19~24~56 ~19~24~65 minecraft:calcite
fill ~20~24~56 ~20~24~65 minecraft:red_sandstone 3
fill ~20~41~56 ~21~41~56 minecraft:concrete 1
fill ~21~25~56 ~21~25~66 minecraft:red_sandstone 3
setblock ~22~25~56 minecraft:stained_glass 1
setblock ~22~26~56 minecraft:red_sandstone 3
setblock ~23~26~56 minecraft:stained_glass 1
fill ~24~27~56 ~24~27~57 minecraft:red_sandstone 3
setblock ~25~28~56 minecraft:red_sandstone 3
setblock ~26~29~56 minecraft:stained_glass 1
fill ~26~30~56 ~26~30~57 minecraft:concrete 1
fill ~26~36~56 ~26~36~58 minecraft:concrete 1
setblock ~27~31~56 minecraft:stained_glass 1
fill ~27~32~56 ~27~32~57 minecraft:concrete 1
setblock ~27~35~56 minecraft:wool 1
fill ~33~0~56 ~33~0~62 minecraft:concrete 12
fill ~33~1~56 ~33~1~61 minecraft:concrete 12
fill ~33~2~56 ~33~2~60 minecraft:concrete 12
fill ~36~2~56 ~36~2~57 minecraft:concrete 12
fill ~5~34~57 ~5~34~58 minecraft:wool 1
setblock ~5~37~57 minecraft:stained_glass 1
setblock ~6~31~57 minecraft:stained_glass 1
fill ~6~32~57 ~6~32~58 minecraft:concrete 1
setblock ~6~33~57 minecraft:concrete 1
fill ~6~38~57 ~6~38~58 minecraft:wool 1
setblock ~7~28~57 minecraft:stained_hardened_clay 1
fill ~7~29~57 ~7~29~58 minecraft:planks 4
setblock ~7~30~57 minecraft:red_sandstone 3
fill ~8~28~57 ~8~28~58 minecraft:red_sandstone 3
setblock ~9~27~57 minecraft:stained_hardened_clay 1
fill ~10~26~57 ~10~26~59 minecraft:stained_hardened_clay 1
setblock ~11~25~57 minecraft:red_sandstone 3
fill ~11~42~57 ~11~42~60 minecraft:red_sandstone 3
fill ~13~24~57 ~13~24~58 minecraft:stained_hardened_clay 1
setblock ~15~23~57 minecraft:stained_glass 0
setblock ~15~43~57 minecraft:stained_glass 1
setblock ~18~42~57 minecraft:planks 4
setblock ~19~42~57 minecraft:red_sandstone 3
fill ~20~41~57 ~20~41~60 minecraft:red_sandstone 3
fill ~21~24~57 ~21~24~60 minecraft:stained_glass 1
fill ~21~41~57 ~21~41~58 minecraft:concrete 1
setblock ~22~25~57 minecraft:red_sandstone 3
fill ~23~0~57 ~23~0~73 minecraft:wool 12
fill ~23~26~57 ~23~26~58 minecraft:red_sandstone 3
fill ~25~27~57 ~25~27~59 minecraft:stained_glass 1
fill ~25~28~57 ~25~28~66 minecraft:concrete 1
fill ~26~29~57 ~26~29~67 minecraft:concrete 1
setblock ~27~30~57 minecraft:stained_glass 1
fill ~27~31~57 ~27~31~58 minecraft:concrete 1
fill ~27~35~57 ~27~35~58 minecraft:concrete 1
setblock ~27~36~57 minecraft:stained_glass 1
setblock ~28~32~57 minecraft:stained_glass 1
fill ~28~33~57 ~28~33~67 minecraft:wool 1
fill ~28~34~57 ~28~34~59 minecraft:wool 1
fill ~32~0~57 ~32~1~61 minecraft:concrete 12
fill ~32~2~57 ~32~2~60 minecraft:concrete 12
fill ~36~1~57 ~37~1~57 minecraft:concrete 12
setblock ~5~33~58 minecraft:stained_glass 1
fill ~5~36~58 ~5~36~60 minecraft:concrete 1
setblock ~5~37~58 minecraft:wool 1
setblock ~6~29~58 minecraft:stained_glass 1
setblock ~6~30~58 minecraft:wool 1
setblock ~6~31~58 minecraft:concrete 1
setblock ~6~33~58 minecraft:red_sandstone 3
fill ~7~28~58 ~7~28~59 minecraft:planks 4
fill ~7~39~58 ~7~39~70 minecraft:red_sandstone 3
setblock ~8~40~58 minecraft:stained_glass 1
fill ~9~27~58 ~9~27~59 minecraft:red_sandstone 3
fill ~11~25~58 ~11~25~59 minecraft:stained_hardened_clay 1
fill ~12~42~58 ~13~42~58 minecraft:planks 4
fill ~15~23~58 ~17~23~58 minecraft:wool 0
fill ~15~43~58 ~16~43~63 minecraft:wool 1
fill ~16~22~58 ~16~22~62 minecraft:stained_glass 0
fill ~18~24~58 ~18~24~59 minecraft:calcite
fill ~18~42~58 ~18~42~59 minecraft:stained_hardened_clay 1
fill ~19~42~58 ~19~42~61 minecraft:planks 4
fill ~22~25~58 ~22~25~61 minecraft:concrete 1
fill ~24~0~58 ~24~0~73 minecraft:wool 12
fill ~24~27~58 ~24~27~65 minecraft:concrete 1
setblock ~24~39~58 minecraft:stained_glass 1
setblock ~25~38~58 minecraft:stained_glass 1
setblock ~26~37~58 minecraft:stained_glass 1
fill ~27~30~58 ~27~30~65 minecraft:concrete 1
setblock ~27~36~58 minecraft:wool 1
setblock ~28~31~58 minecraft:stained_glass 1
fill ~28~32~58 ~28~32~65 minecraft:wool 1
setblock ~28~35~58 minecraft:stained_glass 1
fill ~31~0~58 ~31~2~60 minecraft:concrete 12
setblock ~36~1~58 minecraft:concrete 12
setblock ~5~31~59 minecraft:stained_glass 1
fill ~5~32~59 ~5~32~60 minecraft:wool 1
setblock ~5~33~59 minecraft:wool 1
setblock ~5~34~59 minecraft:concrete 1
fill ~5~37~59 ~5~37~65 minecraft:concrete 1
fill ~6~29~59 ~6~29~60 minecraft:wool 1
setblock ~6~30~59 minecraft:concrete 1
setblock ~6~31~59 minecraft:red_sandstone 3
fill ~6~38~59 ~6~38~66 minecraft:concrete 1
fill ~8~28~59 ~8~28~66 minecraft:concrete 1
fill ~8~40~59 ~8~40~63 minecraft:concrete 1
fill ~12~24~59 ~12~24~70 minecraft:stained_hardened_clay 1
setblock ~12~42~59 minecraft:planks 4
fill ~13~24~59 ~13~24~60 minecraft:calcite
fill ~13~42~59 ~13~42~63 minecraft:stained_hardened_clay 1
setblock ~14~23~59 minecraft:stained_glass 0
setblock ~14~43~59 minecraft:stained_glass 1
setblock ~15~23~59 minecraft:wool 0
fill ~16~23~59 ~17~23~62 minecraft:calcite
setblock ~16~42~59 minecraft:stained_hardened_clay 1
setblock ~18~23~59 minecraft:stained_glass 0
fill ~21~41~59 ~21~41~64 minecraft:red_sandstone 3
fill ~23~26~59 ~23~26~63 minecraft:concrete 1
setblock ~23~40~59 minecraft:stained_glass 1
setblock ~24~39~59 minecraft:wool 1
fill ~25~0~59 ~25~0~74 minecraft:wool 12
setblock ~25~38~59 minecraft:wool 1
fill ~26~0~59 ~26~1~59 minecraft:stained_hardened_clay 1
fill ~26~37~59 ~26~37~62 minecraft:concrete 1
fill ~27~36~59 ~27~36~67 minecraft:concrete 1
fill ~28~31~59 ~28~31~63 minecraft:wool 1
fill ~28~35~59 ~28~35~64 minecraft:concrete 1
setblock ~4~33~60 minecraft:stained_glass 1
fill ~4~34~60 ~4~34~63 minecraft:wool 1
fill ~4~35~60 ~4~35~62 minecraft:wool 1
setblock ~4~36~60 minecraft:stained_glass 1
setblock ~5~30~60 minecraft:stained_glass 1
fill ~5~31~60 ~5~31~61 minecraft:wool 1
setblock ~5~33~60 minecraft:concrete 1
setblock ~6~30~60 minecraft:red_sandstone 3
fill ~7~28~60 ~7~28~67 minecraft:concrete 1
fill ~9~27~60 ~9~27~64 minecraft:concrete 1
fill ~10~26~60 ~10~26~66 minecraft:red_sandstone 3
fill ~11~25~60 ~11~25~65 minecraft:red_sandstone 3
setblock ~12~42~60 minecraft:red_sandstone 3
setblock ~13~23~60 minecraft:stained_glass 0
setblock ~14~23~60 minecraft:wool 0
fill ~14~43~60 ~14~43~65 minecraft:wool 1
fill ~15~22~60 ~15~22~62 minecraft:stained_glass 0
fill ~15~23~60 ~15~23~62 minecraft:calcite
fill ~18~23~60 ~18~23~61 minecraft:wool 0
