fill ~2~1~0 ~32~1~0 minecraft:wool 7
setblock ~16~9~0 minecraft:quartz_block 0
setblock ~16~10~0 minecraft:wool 7
setblock ~17~11~0 minecraft:wool 7
setblock ~18~12~0 minecraft:wool 7
setblock ~19~13~0 minecraft:wool 7
setblock ~20~14~0 minecraft:wool 7
fill ~21~15~0 ~26~15~0 minecraft:wool 7
fill ~26~12~0 ~26~14~0 minecraft:wool 7
fill ~26~16~0 ~26~17~0 minecraft:wool 7
fill ~27~10~0 ~27~11~0 minecraft:wool 7
fill ~27~18~0 ~27~19~0 minecraft:wool 7
setblock ~28~9~0 minecraft:wool 7
setblock ~28~20~0 minecraft:wool 7
setblock ~29~8~0 minecraft:wool 7
setblock ~29~21~0 minecraft:wool 7
fill ~30~7~0 ~31~7~0 minecraft:wool 7
fill ~30~22~0 ~31~22~0 minecraft:wool 7
fill ~32~6~0 ~37~6~0 minecraft:wool 7
fill ~32~23~0 ~37~23~0 minecraft:wool 7
fill ~33~1~0 ~36~1~2 minecraft:quartz_block 0
fill ~34~0~0 ~35~0~0 minecraft:quartz_block 0
fill ~36~0~0 ~67~0~1 minecraft:dirt 0
fill ~37~1~0 ~67~1~0 minecraft:wool 7
fill ~38~7~0 ~39~7~0 minecraft:wool 7
fill ~38~22~0 ~39~22~0 minecraft:wool 7
setblock ~40~8~0 minecraft:wool 7
setblock ~40~21~0 minecraft:wool 7
setblock ~41~9~0 minecraft:wool 7
setblock ~41~20~0 minecraft:wool 7
fill ~42~10~0 ~42~11~0 minecraft:wool 7
fill ~42~18~0 ~42~19~0 minecraft:wool 7
fill ~43~12~0 ~43~17~0 minecraft:wool 7
fill ~44~15~0 ~48~15~0 minecraft:wool 7
setblock ~49~14~0 minecraft:wool 7
setblock ~50~13~0 minecraft:wool 7
setblock ~51~12~0 minecraft:wool 7
setblock ~52~11~0 minecraft:wool 7
setblock ~53~9~0 minecraft:quartz_block 0
setblock ~53~10~0 minecraft:wool 7
fill ~2~1~1 ~2~1~30 minecraft:wool 7
fill ~3~1~1 ~20~1~1 minecraft:wool 15
fill ~9~3~1 ~9~9~1 minecraft:quartz_block 0
fill ~10~2~1 ~15~2~1 minecraft:quartz_block 0
setblock ~10~4~1 minecraft:wool 7
fill ~10~5~1 ~10~6~1 minecraft:wool 15
fill ~10~7~1 ~10~7~3 minecraft:wool 7
fill ~10~9~1 ~10~10~1 minecraft:quartz_block 0
setblock ~11~3~1 minecraft:wool 7
setblock ~11~4~1 minecraft:wool 15
setblock ~11~7~1 minecraft:wool 15
fill ~11~8~1 ~11~8~3 minecraft:wool 7
fill ~11~10~1 ~15~10~1 minecraft:quartz_block 0
fill ~12~3~1 ~13~3~1 minecraft:wool 15
fill ~12~8~1 ~13~8~1 minecraft:wool 15
fill ~12~9~1 ~13~9~1 minecraft:quartz_block 0
setblock ~14~3~1 minecraft:wool 7
setblock ~14~4~1 minecraft:wool 15
setblock ~14~7~1 minecraft:wool 15
setblock ~14~8~1 minecraft:wool 7
setblock ~15~4~1 minecraft:wool 7
fill ~15~5~1 ~15~6~1 minecraft:wool 15
setblock ~15~7~1 minecraft:wool 7
setblock ~15~9~1 minecraft:quartz_block 0
fill ~16~3~1 ~16~8~1 minecraft:quartz_block 0
fill ~16~9~1 ~16~9~3 minecraft:wool 7
setblock ~16~10~1 minecraft:stained_glass 8
fill ~17~4~1 ~18~4~1 minecraft:quartz_block 0
setblock ~17~11~1 minecraft:stained_glass 8
setblock ~18~12~1 minecraft:stained_glass 8
setblock ~19~3~1 minecraft:quartz_block 0
setblock ~19~13~1 minecraft:stained_glass 8
setblock ~20~2~1 minecraft:quartz_block 0
setblock ~20~14~1 minecraft:stained_glass 8
fill ~21~1~1 ~31~1~1 minecraft:quartz_block 0
fill ~21~15~1 ~26~15~1 minecraft:stained_glass 8
fill ~26~12~1 ~26~14~1 minecraft:stained_glass 8
fill ~26~16~1 ~26~17~1 minecraft:stained_glass 8
fill ~27~10~1 ~27~11~1 minecraft:stained_glass 8
fill ~27~18~1 ~27~19~1 minecraft:stained_glass 8
setblock ~28~9~1 minecraft:stained_glass 8
setblock ~28~20~1 minecraft:stained_glass 8
setblock ~29~8~1 minecraft:stained_glass 8
setblock ~29~21~1 minecraft:stained_glass 8
fill ~30~7~1 ~31~7~1 minecraft:stained_glass 8
fill ~30~15~1 ~30~15~3 minecraft:glowstone
fill ~30~22~1 ~31~22~1 minecraft:stained_glass 8
fill ~32~1~1 ~32~1~30 minecraft:wool 7
fill ~32~6~1 ~37~6~1 minecraft:stained_glass 8
fill ~32~23~1 ~37~23~1 minecraft:stained_glass 8
fill ~33~12~1 ~33~12~3 minecraft:glowstone
fill ~33~17~1 ~33~17~3 minecraft:glowstone
fill ~34~0~1 ~35~0~2 minecraft:dirt 0
fill ~36~12~1 ~36~12~3 minecraft:glowstone
fill ~36~17~1 ~36~17~3 minecraft:glowstone
fill ~37~1~1 ~37~1~30 minecraft:wool 7
fill ~38~1~1 ~48~1~1 minecraft:quartz_block 0
fill ~38~7~1 ~39~7~1 minecraft:stained_glass 8
fill ~38~22~1 ~39~22~1 minecraft:stained_glass 8
fill ~39~15~1 ~39~15~3 minecraft:glowstone
setblock ~40~8~1 minecraft:stained_glass 8
setblock ~40~21~1 minecraft:stained_glass 8
setblock ~41~9~1 minecraft:stained_glass 8
setblock ~41~20~1 minecraft:stained_glass 8
fill ~42~10~1 ~42~11~1 minecraft:stained_glass 8
fill ~42~18~1 ~42~19~1 minecraft:stained_glass 8
fill ~43~12~1 ~43~17~1 minecraft:stained_glass 8
fill ~44~15~1 ~48~15~1 minecraft:stained_glass 8
fill ~49~1~1 ~66~1~1 minecraft:wool 15
setblock ~49~2~1 minecraft:quartz_block 0
setblock ~49~14~1 minecraft:stained_glass 8
setblock ~50~3~1 minecraft:quartz_block 0
setblock ~50~13~1 minecraft:stained_glass 8
fill ~51~4~1 ~53~4~1 minecraft:quartz_block 0
setblock ~51~12~1 minecraft:stained_glass 8
setblock ~52~11~1 minecraft:stained_glass 8
setblock ~53~3~1 minecraft:quartz_block 0
fill ~53~5~1 ~53~8~1 minecraft:quartz_block 0
fill ~53~9~1 ~53~9~3 minecraft:wool 7
setblock ~53~10~1 minecraft:stained_glass 8
fill ~54~2~1 ~59~2~1 minecraft:quartz_block 0
setblock ~54~4~1 minecraft:wool 7
fill ~54~5~1 ~54~6~1 minecraft:wool 15
setblock ~54~7~1 minecraft:wool 7
fill ~54~9~1 ~54~10~1 minecraft:quartz_block 0
setblock ~55~3~1 minecraft:wool 7
setblock ~55~4~1 minecraft:wool 15
setblock ~55~7~1 minecraft:wool 15
setblock ~55~8~1 minecraft:wool 7
fill ~55~10~1 ~59~10~1 minecraft:quartz_block 0
fill ~56~3~1 ~57~3~1 minecraft:wool 15
fill ~56~8~1 ~57~8~1 minecraft:wool 15
fill ~56~9~1 ~57~9~1 minecraft:quartz_block 0
setblock ~58~3~1 minecraft:wool 7
setblock ~58~4~1 minecraft:wool 15
setblock ~58~7~1 minecraft:wool 15
fill ~58~8~1 ~58~8~3 minecraft:wool 7
setblock ~59~4~1 minecraft:wool 7
fill ~59~5~1 ~59~6~1 minecraft:wool 15
fill ~59~7~1 ~59~7~3 minecraft:wool 7
fill ~59~9~1 ~60~9~1 minecraft:quartz_block 0
fill ~60~3~1 ~60~8~1 minecraft:quartz_block 0
fill ~67~1~1 ~67~1~30 minecraft:wool 7
fill ~2~0~2 ~3~0~31 minecraft:dirt 0
fill ~3~1~2 ~3~1~18 minecraft:wool 15
setblock ~4~0~2 minecraft:grass
setblock ~4~1~2 minecraft:glowstone
fill ~5~0~2 ~18~0~3 minecraft:dirt 0
setblock ~5~1~2 minecraft:wool 15
setblock ~6~1~2 minecraft:wool 7
fill ~7~1~2 ~7~1~4 minecraft:wool 15
setblock ~8~1~2 minecraft:wool 7
fill ~9~1~2 ~9~1~6 minecraft:wool 15
fill ~9~3~2 ~9~9~2 minecraft:wool 7
setblock ~10~1~2 minecraft:wool 7
fill ~10~2~2 ~11~2~2 minecraft:glowstone
fill ~10~5~2 ~10~6~2 minecraft:diamond_block
fill ~10~9~2 ~10~10~2 minecraft:wool 7
fill ~11~1~2 ~11~1~8 minecraft:wool 15
setblock ~11~4~2 minecraft:diamond_block
setblock ~11~7~2 minecraft:diamond_block
fill ~11~10~2 ~15~10~2 minecraft:wool 7
setblock ~12~1~2 minecraft:wool 7
fill ~12~3~2 ~13~3~2 minecraft:diamond_block
fill ~12~8~2 ~13~8~2 minecraft:diamond_block
fill ~12~9~2 ~13~9~2 minecraft:glowstone
fill ~13~1~2 ~13~1~10 minecraft:wool 15
setblock ~14~1~2 minecraft:wool 7
fill ~14~2~2 ~15~2~2 minecraft:glowstone
setblock ~14~4~2 minecraft:diamond_block
setblock ~14~7~2 minecraft:diamond_block
fill ~15~1~2 ~15~1~12 minecraft:wool 15
fill ~15~5~2 ~15~6~2 minecraft:diamond_block
setblock ~15~9~2 minecraft:wool 7
setblock ~16~1~2 minecraft:wool 7
fill ~16~3~2 ~16~8~2 minecraft:wool 7
setblock ~16~10~2 minecraft:diamond_block
fill ~17~1~2 ~17~1~14 minecraft:wool 15
setblock ~17~3~2 minecraft:quartz_block 0
setblock ~17~11~2 minecraft:diamond_block
setblock ~18~1~2 minecraft:wool 7
setblock ~18~2~2 minecraft:quartz_block 0
setblock ~18~12~2 minecraft:diamond_block
fill ~19~0~2 ~30~0~2 minecraft:glowstone
fill ~19~1~2 ~30~1~2 minecraft:stained_glass 8
setblock ~19~13~2 minecraft:diamond_block
setblock ~20~14~2 minecraft:diamond_block
fill ~21~15~2 ~26~15~2 minecraft:diamond_block
fill ~26~12~2 ~26~14~2 minecraft:diamond_block
fill ~26~16~2 ~26~17~2 minecraft:diamond_block
fill ~27~10~2 ~27~11~2 minecraft:diamond_block
fill ~27~18~2 ~27~19~2 minecraft:diamond_block
setblock ~28~9~2 minecraft:diamond_block
setblock ~28~20~2 minecraft:diamond_block
setblock ~29~8~2 minecraft:diamond_block
setblock ~29~21~2 minecraft:diamond_block
fill ~30~7~2 ~31~7~2 minecraft:diamond_block
setblock ~30~14~2 minecraft:glowstone
fill ~30~22~2 ~31~22~2 minecraft:diamond_block
fill ~31~0~2 ~33~0~31 minecraft:dirt 0
fill ~31~1~2 ~31~1~3 minecraft:quartz_block 0
fill ~31~15~2 ~33~15~2 minecraft:glowstone
fill ~32~6~2 ~37~6~2 minecraft:diamond_block
setblock ~32~12~2 minecraft:glowstone
setblock ~32~17~2 minecraft:glowstone
fill ~32~23~2 ~37~23~2 minecraft:diamond_block
fill ~33~7~2 ~33~10~2 minecraft:nether_brick_fence
setblock ~33~11~2 minecraft:glowstone
fill ~33~13~2 ~33~14~2 minecraft:glowstone
setblock ~33~16~2 minecraft:glowstone
setblock ~33~18~2 minecraft:glowstone
fill ~33~19~2 ~33~22~2 minecraft:nether_brick_fence
fill ~34~12~2 ~35~12~2 minecraft:glowstone
fill ~34~17~2 ~35~17~2 minecraft:glowstone
fill ~36~0~2 ~38~0~31 minecraft:dirt 0
fill ~36~7~2 ~36~10~2 minecraft:nether_brick_fence
setblock ~36~11~2 minecraft:glowstone
fill ~36~13~2 ~36~16~2 minecraft:glowstone
setblock ~36~18~2 minecraft:glowstone
fill ~36~19~2 ~36~22~2 minecraft:nether_brick_fence
setblock ~37~12~2 minecraft:glowstone
fill ~37~15~2 ~38~15~2 minecraft:glowstone
setblock ~37~17~2 minecraft:glowstone
fill ~38~1~2 ~38~1~3 minecraft:quartz_block 0
fill ~38~7~2 ~39~7~2 minecraft:diamond_block
fill ~38~22~2 ~39~22~2 minecraft:diamond_block
fill ~39~0~2 ~50~0~2 minecraft:glowstone
fill ~39~1~2 ~50~1~2 minecraft:stained_glass 8
setblock ~39~14~2 minecraft:glowstone
setblock ~40~8~2 minecraft:diamond_block
setblock ~40~21~2 minecraft:diamond_block
setblock ~41~9~2 minecraft:diamond_block
setblock ~41~20~2 minecraft:diamond_block
fill ~42~10~2 ~42~11~2 minecraft:diamond_block
fill ~42~18~2 ~42~19~2 minecraft:diamond_block
fill ~43~12~2 ~43~17~2 minecraft:diamond_block
fill ~44~15~2 ~48~15~2 minecraft:diamond_block
setblock ~49~14~2 minecraft:diamond_block
setblock ~50~13~2 minecraft:diamond_block
fill ~51~0~2 ~64~0~3 minecraft:dirt 0
setblock ~51~1~2 minecraft:wool 7
setblock ~51~2~2 minecraft:quartz_block 0
setblock ~51~12~2 minecraft:diamond_block
fill ~52~1~2 ~52~1~14 minecraft:wool 15
setblock ~52~3~2 minecraft:quartz_block 0
setblock ~52~11~2 minecraft:diamond_block
setblock ~53~1~2 minecraft:wool 7
fill ~53~3~2 ~53~8~2 minecraft:wool 7
setblock ~53~10~2 minecraft:diamond_block
fill ~54~1~2 ~54~1~12 minecraft:wool 15
fill ~54~2~2 ~55~2~2 minecraft:glowstone
fill ~54~5~2 ~54~6~2 minecraft:diamond_block
fill ~54~9~2 ~54~10~2 minecraft:wool 7
setblock ~55~1~2 minecraft:wool 7
setblock ~55~4~2 minecraft:diamond_block
setblock ~55~7~2 minecraft:diamond_block
fill ~55~10~2 ~59~10~2 minecraft:wool 7
fill ~56~1~2 ~56~1~10 minecraft:wool 15
fill ~56~3~2 ~57~3~2 minecraft:diamond_block
fill ~56~8~2 ~57~8~2 minecraft:diamond_block
fill ~56~9~2 ~57~9~2 minecraft:glowstone
setblock ~57~1~2 minecraft:wool 7
fill ~58~1~2 ~58~1~8 minecraft:wool 15
fill ~58~2~2 ~59~2~2 minecraft:glowstone
setblock ~58~4~2 minecraft:diamond_block
setblock ~58~7~2 minecraft:diamond_block
setblock ~59~1~2 minecraft:wool 7
fill ~59~5~2 ~59~6~2 minecraft:diamond_block
fill ~59~9~2 ~60~9~2 minecraft:wool 7
fill ~60~1~2 ~60~1~6 minecraft:wool 15
fill ~60~3~2 ~60~8~2 minecraft:wool 7
setblock ~61~1~2 minecraft:wool 7
fill ~62~1~2 ~62~1~4 minecraft:wool 15
setblock ~63~1~2 minecraft:wool 7
setblock ~64~1~2 minecraft:wool 15
setblock ~65~0~2 minecraft:grass
setblock ~65~1~2 minecraft:glowstone
fill ~66~0~2 ~67~0~31 minecraft:dirt 0
fill ~66~1~2 ~66~1~18 minecraft:wool 15
fill ~4~0~3 ~4~0~16 minecraft:dirt 0
setblock ~4~1~3 minecraft:wool 15
setblock ~5~1~3 minecraft:glowstone
setblock ~6~1~3 minecraft:wool 15
setblock ~8~1~3 minecraft:wool 15
fill ~9~3~3 ~9~9~3 minecraft:quartz_block 0
setblock ~10~1~3 minecraft:wool 15
fill ~10~2~3 ~15~2~3 minecraft:quartz_block 0
setblock ~10~4~3 minecraft:wool 7
fill ~10~5~3 ~10~6~3 minecraft:wool 15
fill ~10~9~3 ~10~10~3 minecraft:quartz_block 0
setblock ~11~3~3 minecraft:wool 7
setblock ~11~4~3 minecraft:wool 15
setblock ~11~7~3 minecraft:wool 15
fill ~11~10~3 ~15~10~3 minecraft:quartz_block 0
setblock ~12~1~3 minecraft:wool 15
fill ~12~3~3 ~13~3~3 minecraft:wool 15
fill ~12~8~3 ~13~8~3 minecraft:wool 15
fill ~12~9~3 ~13~9~3 minecraft:quartz_block 0
setblock ~14~1~3 minecraft:wool 15
setblock ~14~3~3 minecraft:wool 7
setblock ~14~4~3 minecraft:wool 15
setblock ~14~7~3 minecraft:wool 15
setblock ~14~8~3 minecraft:wool 7
setblock ~15~4~3 minecraft:wool 7
fill ~15~5~3 ~15~6~3 minecraft:wool 15
setblock ~15~7~3 minecraft:wool 7
setblock ~15~9~3 minecraft:quartz_block 0
setblock ~16~1~3 minecraft:wool 15
fill ~16~3~3 ~16~8~3 minecraft:quartz_block 0
setblock ~16~10~3 minecraft:stained_glass 8
fill ~17~4~3 ~18~4~3 minecraft:quartz_block 0
setblock ~17~11~3 minecraft:stained_glass 8
fill ~18~1~3 ~20~1~3 minecraft:wool 15
setblock ~18~12~3 minecraft:stained_glass 8
fill ~19~0~3 ~30~0~16 minecraft:dirt 0
setblock ~19~3~3 minecraft:quartz_block 0
setblock ~19~13~3 minecraft:stained_glass 8
setblock ~20~2~3 minecraft:quartz_block 0
setblock ~20~14~3 minecraft:stained_glass 8
fill ~21~1~3 ~30~1~3 minecraft:quartz_block 0
fill ~21~15~3 ~26~15~3 minecraft:stained_glass 8
fill ~26~12~3 ~26~14~3 minecraft:stained_glass 8
fill ~26~16~3 ~26~17~3 minecraft:stained_glass 8
fill ~27~10~3 ~27~11~3 minecraft:stained_glass 8
fill ~27~18~3 ~27~19~3 minecraft:stained_glass 8
setblock ~28~9~3 minecraft:stained_glass 8
setblock ~28~20~3 minecraft:stained_glass 8
setblock ~29~8~3 minecraft:stained_glass 8
setblock ~29~21~3 minecraft:stained_glass 8
fill ~30~7~3 ~31~7~3 minecraft:stained_glass 8
fill ~30~22~3 ~31~22~3 minecraft:stained_glass 8
fill ~32~6~3 ~37~6~3 minecraft:stained_glass 8
fill ~32~23~3 ~37~23~3 minecraft:stained_glass 8
fill ~33~1~3 ~33~1~25 minecraft:quartz_block 0
fill ~34~0~3 ~35~0~4 minecraft:glowstone
fill ~34~1~3 ~35~1~4 minecraft:stained_glass 8
fill ~36~1~3 ~36~1~25 minecraft:quartz_block 0
fill ~38~7~3 ~39~7~3 minecraft:stained_glass 8
fill ~38~22~3 ~39~22~3 minecraft:stained_glass 8
fill ~39~0~3 ~50~0~16 minecraft:dirt 0
fill ~39~1~3 ~48~1~3 minecraft:quartz_block 0
setblock ~40~8~3 minecraft:stained_glass 8
setblock ~40~21~3 minecraft:stained_glass 8
setblock ~41~9~3 minecraft:stained_glass 8
setblock ~41~20~3 minecraft:stained_glass 8
fill ~42~10~3 ~42~11~3 minecraft:stained_glass 8
fill ~42~18~3 ~42~19~3 minecraft:stained_glass 8
fill ~43~12~3 ~43~17~3 minecraft:stained_glass 8
fill ~44~15~3 ~48~15~3 minecraft:stained_glass 8
fill ~49~1~3 ~51~1~3 minecraft:wool 15
setblock ~49~2~3 minecraft:quartz_block 0
setblock ~49~14~3 minecraft:stained_glass 8
setblock ~50~3~3 minecraft:quartz_block 0
setblock ~50~13~3 minecraft:stained_glass 8
fill ~51~4~3 ~53~4~3 minecraft:quartz_block 0
setblock ~51~12~3 minecraft:stained_glass 8
setblock ~52~11~3 minecraft:stained_glass 8
setblock ~53~1~3 minecraft:wool 15
setblock ~53~3~3 minecraft:quartz_block 0
fill ~53~5~3 ~53~8~3 minecraft:quartz_block 0
setblock ~53~10~3 minecraft:stained_glass 8
fill ~54~2~3 ~59~2~3 minecraft:quartz_block 0
setblock ~54~4~3 minecraft:wool 7
fill ~54~5~3 ~54~6~3 minecraft:wool 15
setblock ~54~7~3 minecraft:wool 7
fill ~54~9~3 ~54~10~3 minecraft:quartz_block 0
setblock ~55~1~3 minecraft:wool 15
setblock ~55~3~3 minecraft:wool 7
setblock ~55~4~3 minecraft:wool 15
setblock ~55~7~3 minecraft:wool 15
setblock ~55~8~3 minecraft:wool 7
fill ~55~10~3 ~59~10~3 minecraft:quartz_block 0
fill ~56~3~3 ~57~3~3 minecraft:wool 15
fill ~56~8~3 ~57~8~3 minecraft:wool 15
fill ~56~9~3 ~57~9~3 minecraft:quartz_block 0
setblock ~57~1~3 minecraft:wool 15
setblock ~58~3~3 minecraft:wool 7
setblock ~58~4~3 minecraft:wool 15
setblock ~58~7~3 minecraft:wool 15
setblock ~59~1~3 minecraft:wool 15
setblock ~59~4~3 minecraft:wool 7
fill ~59~5~3 ~59~6~3 minecraft:wool 15
fill ~59~9~3 ~60~9~3 minecraft:quartz_block 0
fill ~60~3~3 ~60~8~3 minecraft:quartz_block 0
setblock ~61~1~3 minecraft:wool 15
setblock ~63~1~3 minecraft:wool 15
setblock ~64~1~3 minecraft:glowstone
fill ~65~0~3 ~65~0~16 minecraft:dirt 0
setblock ~65~1~3 minecraft:wool 15
setblock ~4~1~4 minecraft:wool 7
fill ~5~0~4 ~5~0~31 minecraft:dirt 0
fill ~5~1~4 ~5~1~18 minecraft:wool 15
setblock ~6~0~4 minecraft:grass
setblock ~6~1~4 minecraft:glowstone
fill ~7~0~4 ~18~0~5 minecraft:dirt 0
setblock ~8~1~4 minecraft:wool 7
setblock ~10~1~4 minecraft:wool 7
setblock ~12~1~4 minecraft:wool 7
setblock ~14~1~4 minecraft:wool 7
setblock ~16~1~4 minecraft:wool 7
setblock ~16~9~4 minecraft:quartz_block 0
setblock ~16~10~4 minecraft:wool 7
setblock ~17~11~4 minecraft:wool 7
setblock ~18~1~4 minecraft:wool 7
setblock ~18~12~4 minecraft:wool 7
fill ~19~1~4 ~19~1~16 minecraft:wool 15
setblock ~19~13~4 minecraft:wool 7
setblock ~20~1~4 minecraft:wool 7
setblock ~20~14~4 minecraft:wool 7
fill ~21~1~4 ~21~1~18 minecraft:wool 15
fill ~21~15~4 ~26~15~4 minecraft:wool 7
setblock ~22~1~4 minecraft:wool 7
fill ~23~1~4 ~23~1~20 minecraft:wool 15
setblock ~24~1~4 minecraft:wool 7
fill ~25~1~4 ~25~1~22 minecraft:wool 15
setblock ~26~1~4 minecraft:wool 7
fill ~26~12~4 ~26~14~4 minecraft:wool 7
fill ~26~16~4 ~26~17~4 minecraft:wool 7
fill ~27~1~4 ~27~1~24 minecraft:wool 15
fill ~27~10~4 ~27~11~4 minecraft:wool 7
fill ~27~18~4 ~27~19~4 minecraft:wool 7
setblock ~28~1~4 minecraft:wool 7
setblock ~28~9~4 minecraft:wool 7
setblock ~28~20~4 minecraft:wool 7
fill ~29~1~4 ~29~1~25 minecraft:wool 15
setblock ~29~8~4 minecraft:wool 7
setblock ~29~21~4 minecraft:wool 7
setblock ~30~1~4 minecraft:wool 7
fill ~30~7~4 ~31~7~4 minecraft:wool 7
fill ~30~22~4 ~31~22~4 minecraft:wool 7
fill ~31~1~4 ~31~1~29 minecraft:wool 15
fill ~32~6~4 ~37~6~4 minecraft:wool 7
fill ~32~23~4 ~37~23~4 minecraft:wool 7
fill ~38~1~4 ~38~1~29 minecraft:wool 15
fill ~38~7~4 ~39~7~4 minecraft:wool 7
fill ~38~22~4 ~39~22~4 minecraft:wool 7
setblock ~39~1~4 minecraft:wool 7
fill ~40~1~4 ~40~1~25 minecraft:wool 15
setblock ~40~8~4 minecraft:wool 7
setblock ~40~21~4 minecraft:wool 7
setblock ~41~1~4 minecraft:wool 7
setblock ~41~9~4 minecraft:wool 7
setblock ~41~20~4 minecraft:wool 7
fill ~42~1~4 ~42~1~24 minecraft:wool 15
fill ~42~10~4 ~42~11~4 minecraft:wool 7
fill ~42~18~4 ~42~19~4 minecraft:wool 7
setblock ~43~1~4 minecraft:wool 7
fill ~43~12~4 ~43~17~4 minecraft:wool 7
fill ~44~1~4 ~44~1~22 minecraft:wool 15
fill ~44~15~4 ~48~15~4 minecraft:wool 7
setblock ~45~1~4 minecraft:wool 7
fill ~46~1~4 ~46~1~20 minecraft:wool 15
setblock ~47~1~4 minecraft:wool 7
fill ~48~1~4 ~48~1~18 minecraft:wool 15
setblock ~49~1~4 minecraft:wool 7
setblock ~49~14~4 minecraft:wool 7
fill ~50~1~4 ~50~1~16 minecraft:wool 15
setblock ~50~13~4 minecraft:wool 7
fill ~51~0~4 ~62~0~5 minecraft:dirt 0
setblock ~51~1~4 minecraft:wool 7
setblock ~51~12~4 minecraft:wool 7
setblock ~52~11~4 minecraft:wool 7
setblock ~53~1~4 minecraft:wool 7
setblock ~53~9~4 minecraft:quartz_block 0
setblock ~53~10~4 minecraft:wool 7
setblock ~55~1~4 minecraft:wool 7
setblock ~57~1~4 minecraft:wool 7
setblock ~59~1~4 minecraft:wool 7
setblock ~61~1~4 minecraft:wool 7
setblock ~63~0~4 minecraft:grass
setblock ~63~1~4 minecraft:glowstone
fill ~64~0~4 ~64~0~31 minecraft:dirt 0
fill ~64~1~4 ~64~1~18 minecraft:wool 15
setblock ~65~1~4 minecraft:wool 7
setblock ~4~1~5 minecraft:wool 15
fill ~6~0~5 ~6~0~31 minecraft:dirt 0
setblock ~6~1~5 minecraft:wool 15
setblock ~7~1~5 minecraft:glowstone
setblock ~8~1~5 minecraft:wool 15
setblock ~10~1~5 minecraft:wool 15
setblock ~12~1~5 minecraft:wool 15
setblock ~14~1~5 minecraft:wool 15
setblock ~16~1~5 minecraft:wool 15
setblock ~16~10~5 minecraft:quartz_block 0
setblock ~17~11~5 minecraft:quartz_block 0
setblock ~18~1~5 minecraft:wool 15
setblock ~18~12~5 minecraft:quartz_block 0
setblock ~19~13~5 minecraft:quartz_block 0
setblock ~20~1~5 minecraft:wool 15
setblock ~20~14~5 minecraft:quartz_block 0
fill ~21~15~5 ~26~15~5 minecraft:quartz_block 0
setblock ~22~1~5 minecraft:wool 15
setblock ~24~1~5 minecraft:wool 15
setblock ~24~14~5 minecraft:quartz_block 0
fill ~25~13~5 ~26~13~5 minecraft:quartz_block 0
setblock ~26~1~5 minecraft:wool 15
setblock ~26~12~5 minecraft:quartz_block 0
setblock ~26~14~5 minecraft:quartz_block 0
fill ~26~16~5 ~26~17~5 minecraft:quartz_block 0
fill ~27~10~5 ~27~11~5 minecraft:quartz_block 0
fill ~27~18~5 ~27~19~5 minecraft:quartz_block 0
setblock ~28~1~5 minecraft:wool 15
setblock ~28~9~5 minecraft:quartz_block 0
setblock ~28~20~5 minecraft:quartz_block 0
setblock ~29~8~5 minecraft:quartz_block 0
setblock ~29~21~5 minecraft:quartz_block 0
setblock ~30~1~5 minecraft:wool 15
fill ~30~7~5 ~31~7~5 minecraft:quartz_block 0
fill ~30~22~5 ~31~22~5 minecraft:quartz_block 0
fill ~32~6~5 ~37~6~5 minecraft:quartz_block 0
fill ~32~23~5 ~37~23~5 minecraft:quartz_block 0
fill ~34~0~5 ~35~1~5 minecraft:quartz_block 0
fill ~38~7~5 ~39~7~5 minecraft:quartz_block 0
fill ~38~22~5 ~39~22~5 minecraft:quartz_block 0
setblock ~39~1~5 minecraft:wool 15
setblock ~40~8~5 minecraft:quartz_block 0
setblock ~40~21~5 minecraft:quartz_block 0
setblock ~41~1~5 minecraft:wool 15
setblock ~41~9~5 minecraft:quartz_block 0
setblock ~41~20~5 minecraft:quartz_block 0
fill ~42~10~5 ~42~11~5 minecraft:quartz_block 0
fill ~42~18~5 ~42~19~5 minecraft:quartz_block 0
setblock ~43~1~5 minecraft:wool 15
fill ~43~12~5 ~43~17~5 minecraft:quartz_block 0
setblock ~44~13~5 minecraft:quartz_block 0
fill ~44~15~5 ~48~15~5 minecraft:quartz_block 0
setblock ~45~1~5 minecraft:wool 15
setblock ~45~14~5 minecraft:quartz_block 0
setblock ~47~1~5 minecraft:wool 15
setblock ~49~1~5 minecraft:wool 15
setblock ~49~14~5 minecraft:quartz_block 0
setblock ~50~13~5 minecraft:quartz_block 0
setblock ~51~1~5 minecraft:wool 15
setblock ~51~12~5 minecraft:quartz_block 0
setblock ~52~11~5 minecraft:quartz_block 0
setblock ~53~1~5 minecraft:wool 15
setblock ~53~10~5 minecraft:quartz_block 0
setblock ~55~1~5 minecraft:wool 15
setblock ~57~1~5 minecraft:wool 15
setblock ~59~1~5 minecraft:wool 15
setblock ~61~1~5 minecraft:wool 15
setblock ~62~1~5 minecraft:glowstone
fill ~63~0~5 ~63~0~31 minecraft:dirt 0
setblock ~63~1~5 minecraft:wool 15
setblock ~65~1~5 minecraft:wool 15
setblock ~4~1~6 minecraft:wool 7
setblock ~6~1~6 minecraft:wool 7
fill ~7~0~6 ~7~0~31 minecraft:dirt 0
fill ~7~1~6 ~7~1~29 minecraft:wool 15
setblock ~8~0~6 minecraft:grass
setblock ~8~1~6 minecraft:glowstone
fill ~9~0~6 ~18~0~6 minecraft:dirt 0
setblock ~10~1~6 minecraft:wool 7
setblock ~12~1~6 minecraft:wool 7
setblock ~14~1~6 minecraft:wool 7
setblock ~16~1~6 minecraft:wool 7
setblock ~18~1~6 minecraft:wool 7
setblock ~20~1~6 minecraft:wool 7
setblock ~22~1~6 minecraft:wool 7
setblock ~24~1~6 minecraft:wool 7
setblock ~26~1~6 minecraft:wool 7
setblock ~28~1~6 minecraft:wool 7
setblock ~30~1~6 minecraft:wool 7
fill ~34~0~6 ~35~0~7 minecraft:dirt 0
fill ~34~1~6 ~35~1~7 minecraft:quartz_block 0
setblock ~39~1~6 minecraft:wool 7
setblock ~41~1~6 minecraft:wool 7
setblock ~43~1~6 minecraft:wool 7
setblock ~45~1~6 minecraft:wool 7
setblock ~47~1~6 minecraft:wool 7
setblock ~49~1~6 minecraft:wool 7
fill ~51~0~6 ~60~0~6 minecraft:dirt 0
setblock ~51~1~6 minecraft:wool 7
setblock ~53~1~6 minecraft:wool 7
setblock ~55~1~6 minecraft:wool 7
setblock ~57~1~6 minecraft:wool 7
setblock ~59~1~6 minecraft:wool 7
setblock ~61~0~6 minecraft:grass
setblock ~61~1~6 minecraft:glowstone
fill ~62~0~6 ~62~0~31 minecraft:dirt 0
fill ~62~1~6 ~62~1~29 minecraft:wool 15
setblock ~63~1~6 minecraft:wool 7
setblock ~65~1~6 minecraft:wool 7
fill ~3~3~7 ~3~9~7 minecraft:quartz_block 0
setblock ~4~1~7 minecraft:wool 15
fill ~4~3~7 ~4~9~7 minecraft:wool 7
fill ~5~3~7 ~5~9~7 minecraft:quartz_block 0
setblock ~6~1~7 minecraft:wool 15
fill ~8~0~7 ~8~0~58 minecraft:dirt 0
setblock ~8~1~7 minecraft:wool 15
setblock ~9~0~7 minecraft:grass
setblock ~9~1~7 minecraft:glowstone
fill ~10~0~7 ~18~0~7 minecraft:dirt 0
setblock ~10~1~7 minecraft:wool 15
setblock ~12~1~7 minecraft:wool 15
setblock ~14~1~7 minecraft:wool 15
setblock ~16~1~7 minecraft:wool 15
setblock ~18~1~7 minecraft:wool 15
setblock ~20~1~7 minecraft:wool 15
setblock ~22~1~7 minecraft:wool 15
setblock ~24~1~7 minecraft:wool 15
setblock ~26~1~7 minecraft:wool 15
setblock ~28~1~7 minecraft:wool 15
setblock ~30~1~7 minecraft:wool 15
setblock ~39~1~7 minecraft:wool 15
setblock ~41~1~7 minecraft:wool 15
setblock ~43~1~7 minecraft:wool 15
setblock ~45~1~7 minecraft:wool 15
setblock ~47~1~7 minecraft:wool 15
setblock ~49~1~7 minecraft:wool 15
fill ~51~0~7 ~59~0~7 minecraft:dirt 0
setblock ~51~1~7 minecraft:wool 15
setblock ~53~1~7 minecraft:wool 15
setblock ~55~1~7 minecraft:wool 15
setblock ~57~1~7 minecraft:wool 15
setblock ~59~1~7 minecraft:wool 15
setblock ~60~0~7 minecraft:grass
setblock ~60~1~7 minecraft:glowstone
fill ~61~0~7 ~61~0~58 minecraft:dirt 0
setblock ~61~1~7 minecraft:wool 15
setblock ~63~1~7 minecraft:wool 15
fill ~64~3~7 ~64~9~7 minecraft:quartz_block 0
setblock ~65~1~7 minecraft:wool 15
fill ~65~3~7 ~65~9~7 minecraft:wool 7
fill ~66~3~7 ~66~9~7 minecraft:quartz_block 0
fill ~3~2~8 ~3~2~13 minecraft:quartz_block 0
setblock ~3~4~8 minecraft:wool 7
fill ~3~5~8 ~3~6~8 minecraft:wool 15
fill ~3~7~8 ~5~7~8 minecraft:wool 7
fill ~3~9~8 ~3~10~8 minecraft:quartz_block 0
setblock ~4~1~8 minecraft:wool 7
fill ~4~2~8 ~4~2~9 minecraft:glowstone
fill ~4~5~8 ~4~6~8 minecraft:diamond_block
fill ~4~9~8 ~4~10~8 minecraft:wool 7
fill ~5~2~8 ~5~2~13 minecraft:quartz_block 0
setblock ~5~4~8 minecraft:wool 7
fill ~5~5~8 ~5~6~8 minecraft:wool 15
fill ~5~9~8 ~5~10~8 minecraft:quartz_block 0
setblock ~6~1~8 minecraft:wool 7
setblock ~8~1~8 minecraft:wool 7
fill ~9~0~8 ~9~0~57 minecraft:dirt 0
fill ~9~1~8 ~9~1~29 minecraft:wool 15
setblock ~10~0~8 minecraft:grass
setblock ~10~1~8 minecraft:glowstone
fill ~11~0~8 ~18~0~8 minecraft:dirt 0
setblock ~12~1~8 minecraft:wool 7
setblock ~14~1~8 minecraft:wool 7
setblock ~16~1~8 minecraft:wool 7
setblock ~18~1~8 minecraft:wool 7
setblock ~20~1~8 minecraft:wool 7
setblock ~22~1~8 minecraft:wool 7
setblock ~24~1~8 minecraft:wool 7
setblock ~26~1~8 minecraft:wool 7
setblock ~28~1~8 minecraft:wool 7
setblock ~30~1~8 minecraft:wool 7
fill ~34~0~8 ~35~0~9 minecraft:glowstone
fill ~34~1~8 ~35~1~9 minecraft:stained_glass 8
setblock ~39~1~8 minecraft:wool 7
setblock ~41~1~8 minecraft:wool 7
setblock ~43~1~8 minecraft:wool 7
setblock ~45~1~8 minecraft:wool 7
setblock ~47~1~8 minecraft:wool 7
setblock ~49~1~8 minecraft:wool 7
fill ~51~0~8 ~58~0~8 minecraft:dirt 0
setblock ~51~1~8 minecraft:wool 7
setblock ~53~1~8 minecraft:wool 7
setblock ~55~1~8 minecraft:wool 7
setblock ~57~1~8 minecraft:wool 7
setblock ~59~0~8 minecraft:grass
setblock ~59~1~8 minecraft:glowstone
fill ~60~0~8 ~60~0~57 minecraft:dirt 0
fill ~60~1~8 ~60~1~29 minecraft:wool 15
setblock ~61~1~8 minecraft:wool 7
setblock ~63~1~8 minecraft:wool 7
fill ~64~2~8 ~64~2~13 minecraft:quartz_block 0
setblock ~64~4~8 minecraft:wool 7
fill ~64~5~8 ~64~6~8 minecraft:wool 15
fill ~64~7~8 ~66~7~8 minecraft:wool 7
fill ~64~9~8 ~64~10~8 minecraft:quartz_block 0
setblock ~65~1~8 minecraft:wool 7
fill ~65~2~8 ~65~2~9 minecraft:glowstone
fill ~65~5~8 ~65~6~8 minecraft:diamond_block
fill ~65~9~8 ~65~10~8 minecraft:wool 7
fill ~66~2~8 ~66~2~13 minecraft:quartz_block 0
setblock ~66~4~8 minecraft:wool 7
fill ~66~5~8 ~66~6~8 minecraft:wool 15
fill ~66~9~8 ~66~10~8 minecraft:quartz_block 0
setblock ~3~3~9 minecraft:wool 7
setblock ~3~4~9 minecraft:wool 15
setblock ~3~7~9 minecraft:wool 15
fill ~3~8~9 ~5~8~9 minecraft:wool 7
fill ~3~10~9 ~3~10~13 minecraft:quartz_block 0
setblock ~4~1~9 minecraft:wool 15
setblock ~4~4~9 minecraft:diamond_block
setblock ~4~7~9 minecraft:diamond_block
fill ~4~10~9 ~4~10~13 minecraft:wool 7
setblock ~5~3~9 minecraft:wool 7
setblock ~5~4~9 minecraft:wool 15
setblock ~5~7~9 minecraft:wool 15
fill ~5~10~9 ~5~10~13 minecraft:quartz_block 0
setblock ~6~1~9 minecraft:wool 15
setblock ~8~1~9 minecraft:wool 15
fill ~10~0~9 ~10~0~31 minecraft:dirt 0
setblock ~10~1~9 minecraft:wool 15
setblock ~11~0~9 minecraft:grass
setblock ~11~1~9 minecraft:glowstone
fill ~12~0~9 ~18~0~12 minecraft:dirt 0
setblock ~12~1~9 minecraft:wool 15
setblock ~14~1~9 minecraft:wool 15
setblock ~16~1~9 minecraft:wool 15
setblock ~18~1~9 minecraft:wool 15
setblock ~20~1~9 minecraft:wool 15
setblock ~22~1~9 minecraft:wool 15
setblock ~24~1~9 minecraft:wool 15
setblock ~26~1~9 minecraft:wool 15
setblock ~28~1~9 minecraft:wool 15
setblock ~30~1~9 minecraft:wool 15
setblock ~39~1~9 minecraft:wool 15
setblock ~41~1~9 minecraft:wool 15
setblock ~43~1~9 minecraft:wool 15
setblock ~45~1~9 minecraft:wool 15
setblock ~47~1~9 minecraft:wool 15
setblock ~49~1~9 minecraft:wool 15
fill ~51~0~9 ~57~0~12 minecraft:dirt 0
setblock ~51~1~9 minecraft:wool 15
setblock ~53~1~9 minecraft:wool 15
setblock ~55~1~9 minecraft:wool 15
setblock ~57~1~9 minecraft:wool 15
setblock ~58~0~9 minecraft:grass
setblock ~58~1~9 minecraft:glowstone
fill ~59~0~9 ~59~0~31 minecraft:dirt 0
setblock ~59~1~9 minecraft:wool 15
setblock ~61~1~9 minecraft:wool 15
setblock ~63~1~9 minecraft:wool 15
setblock ~64~3~9 minecraft:wool 7
setblock ~64~4~9 minecraft:wool 15
setblock ~64~7~9 minecraft:wool 15
fill ~64~8~9 ~66~8~9 minecraft:wool 7
fill ~64~10~9 ~64~10~13 minecraft:quartz_block 0
setblock ~65~1~9 minecraft:wool 15
setblock ~65~4~9 minecraft:diamond_block
setblock ~65~7~9 minecraft:diamond_block
fill ~65~10~9 ~65~10~13 minecraft:wool 7
setblock ~66~3~9 minecraft:wool 7
setblock ~66~4~9 minecraft:wool 15
setblock ~66~7~9 minecraft:wool 15
fill ~66~10~9 ~66~10~13 minecraft:quartz_block 0
fill ~3~3~10 ~3~3~11 minecraft:wool 15
fill ~3~8~10 ~3~8~11 minecraft:wool 15
fill ~3~9~10 ~3~9~11 minecraft:quartz_block 0
setblock ~4~1~10 minecraft:wool 7
fill ~4~3~10 ~4~3~11 minecraft:diamond_block
fill ~4~8~10 ~4~8~11 minecraft:diamond_block
fill ~4~9~10 ~4~9~11 minecraft:glowstone
fill ~5~3~10 ~5~3~11 minecraft:wool 15
fill ~5~8~10 ~5~8~11 minecraft:wool 15
fill ~5~9~10 ~5~9~11 minecraft:quartz_block 0
setblock ~6~1~10 minecraft:wool 7
setblock ~8~1~10 minecraft:wool 7
setblock ~10~1~10 minecraft:wool 7
fill ~11~0~10 ~11~0~31 minecraft:dirt 0
fill ~11~1~10 ~11~1~29 minecraft:wool 15
setblock ~12~1~10 minecraft:glowstone
setblock ~14~1~10 minecraft:wool 7
setblock ~16~1~10 minecraft:wool 7
setblock ~18~1~10 minecraft:wool 7
setblock ~20~1~10 minecraft:wool 7
setblock ~22~1~10 minecraft:wool 7
setblock ~24~1~10 minecraft:wool 7
setblock ~26~1~10 minecraft:wool 7
setblock ~28~1~10 minecraft:wool 7
setblock ~30~1~10 minecraft:wool 7
fill ~34~0~10 ~35~1~10 minecraft:quartz_block 0
setblock ~39~1~10 minecraft:wool 7
setblock ~41~1~10 minecraft:wool 7
setblock ~43~1~10 minecraft:wool 7
setblock ~45~1~10 minecraft:wool 7
setblock ~47~1~10 minecraft:wool 7
setblock ~49~1~10 minecraft:wool 7
setblock ~51~1~10 minecraft:wool 7
setblock ~53~1~10 minecraft:wool 7
setblock ~55~1~10 minecraft:wool 7
setblock ~57~1~10 minecraft:glowstone
fill ~58~0~10 ~58~0~31 minecraft:dirt 0
fill ~58~1~10 ~58~1~29 minecraft:wool 15
setblock ~59~1~10 minecraft:wool 7
setblock ~61~1~10 minecraft:wool 7
setblock ~63~1~10 minecraft:wool 7
fill ~64~3~10 ~64~3~11 minecraft:wool 15
fill ~64~8~10 ~64~8~11 minecraft:wool 15
fill ~64~9~10 ~64~9~11 minecraft:quartz_block 0
setblock ~65~1~10 minecraft:wool 7
fill ~65~3~10 ~65~3~11 minecraft:diamond_block
fill ~65~8~10 ~65~8~11 minecraft:diamond_block
fill ~65~9~10 ~65~9~11 minecraft:glowstone
fill ~66~3~10 ~66~3~11 minecraft:wool 15
fill ~66~8~10 ~66~8~11 minecraft:wool 15
fill ~66~9~10 ~66~9~11 minecraft:quartz_block 0
setblock ~4~1~11 minecraft:wool 15
setblock ~6~1~11 minecraft:wool 15
setblock ~8~1~11 minecraft:wool 15
setblock ~10~1~11 minecraft:wool 15
setblock ~12~1~11 minecraft:wool 15
setblock ~13~1~11 minecraft:glowstone
setblock ~14~1~11 minecraft:wool 15
setblock ~16~1~11 minecraft:wool 15
setblock ~18~1~11 minecraft:wool 15
setblock ~20~1~11 minecraft:wool 15
setblock ~22~1~11 minecraft:wool 15
setblock ~24~1~11 minecraft:wool 15
setblock ~26~1~11 minecraft:wool 15
setblock ~28~1~11 minecraft:wool 15
setblock ~30~1~11 minecraft:wool 15
fill ~34~0~11 ~35~0~12 minecraft:dirt 0
fill ~34~1~11 ~35~1~12 minecraft:quartz_block 0
setblock ~39~1~11 minecraft:wool 15
setblock ~41~1~11 minecraft:wool 15
setblock ~43~1~11 minecraft:wool 15
setblock ~45~1~11 minecraft:wool 15
setblock ~47~1~11 minecraft:wool 15
setblock ~49~1~11 minecraft:wool 15
setblock ~51~1~11 minecraft:wool 15
setblock ~53~1~11 minecraft:wool 15
setblock ~55~1~11 minecraft:wool 15
setblock ~56~1~11 minecraft:glowstone
setblock ~57~1~11 minecraft:wool 15
setblock ~59~1~11 minecraft:wool 15
setblock ~61~1~11 minecraft:wool 15
setblock ~63~1~11 minecraft:wool 15
setblock ~65~1~11 minecraft:wool 15
setblock ~3~3~12 minecraft:wool 7
setblock ~3~4~12 minecraft:wool 15
setblock ~3~7~12 minecraft:wool 15
setblock ~3~8~12 minecraft:wool 7
setblock ~4~1~12 minecraft:wool 7
fill ~4~2~12 ~4~2~13 minecraft:glowstone
setblock ~4~4~12 minecraft:diamond_block
setblock ~4~7~12 minecraft:diamond_block
setblock ~5~3~12 minecraft:wool 7
setblock ~5~4~12 minecraft:wool 15
setblock ~5~7~12 minecraft:wool 15
setblock ~5~8~12 minecraft:wool 7
setblock ~6~1~12 minecraft:wool 7
setblock ~8~1~12 minecraft:wool 7
setblock ~10~1~12 minecraft:wool 7
setblock ~12~1~12 minecraft:wool 7
fill ~13~1~12 ~13~1~29 minecraft:wool 15
setblock ~14~1~12 minecraft:glowstone
setblock ~16~1~12 minecraft:wool 7
setblock ~18~1~12 minecraft:wool 7
setblock ~20~1~12 minecraft:wool 7
setblock ~22~1~12 minecraft:wool 7
setblock ~24~1~12 minecraft:wool 7
setblock ~26~1~12 minecraft:wool 7
setblock ~28~1~12 minecraft:wool 7
setblock ~30~1~12 minecraft:wool 7
setblock ~39~1~12 minecraft:wool 7
setblock ~41~1~12 minecraft:wool 7
setblock ~43~1~12 minecraft:wool 7
setblock ~45~1~12 minecraft:wool 7
setblock ~47~1~12 minecraft:wool 7
setblock ~49~1~12 minecraft:wool 7
setblock ~51~1~12 minecraft:wool 7
setblock ~53~1~12 minecraft:wool 7
setblock ~55~1~12 minecraft:glowstone
fill ~56~1~12 ~56~1~29 minecraft:wool 15
setblock ~57~1~12 minecraft:wool 7
setblock ~59~1~12 minecraft:wool 7
setblock ~61~1~12 minecraft:wool 7
setblock ~63~1~12 minecraft:wool 7
setblock ~64~3~12 minecraft:wool 7
setblock ~64~4~12 minecraft:wool 15
setblock ~64~7~12 minecraft:wool 15
setblock ~64~8~12 minecraft:wool 7
setblock ~65~1~12 minecraft:wool 7
fill ~65~2~12 ~65~2~13 minecraft:glowstone
setblock ~65~4~12 minecraft:diamond_block
setblock ~65~7~12 minecraft:diamond_block
setblock ~66~3~12 minecraft:wool 7
setblock ~66~4~12 minecraft:wool 15
setblock ~66~7~12 minecraft:wool 15
setblock ~66~8~12 minecraft:wool 7
setblock ~3~4~13 minecraft:wool 7
fill ~3~5~13 ~3~6~13 minecraft:wool 15
setblock ~3~7~13 minecraft:wool 7
setblock ~3~9~13 minecraft:quartz_block 0
setblock ~4~1~13 minecraft:wool 15
fill ~4~5~13 ~4~6~13 minecraft:diamond_block
fill ~4~9~13 ~4~9~14 minecraft:wool 7
setblock ~5~4~13 minecraft:wool 7
fill ~5~5~13 ~5~6~13 minecraft:wool 15
setblock ~5~7~13 minecraft:wool 7
setblock ~5~9~13 minecraft:quartz_block 0
setblock ~6~1~13 minecraft:wool 15
setblock ~8~1~13 minecraft:wool 15
setblock ~10~1~13 minecraft:wool 15
fill ~12~0~13 ~14~0~31 minecraft:dirt 0
setblock ~12~1~13 minecraft:wool 15
setblock ~14~1~13 minecraft:wool 15
setblock ~15~0~13 minecraft:grass
setblock ~15~1~13 minecraft:glowstone
fill ~16~0~13 ~18~0~13 minecraft:dirt 0
setblock ~16~1~13 minecraft:wool 15
setblock ~18~1~13 minecraft:wool 15
setblock ~20~1~13 minecraft:wool 15
setblock ~22~1~13 minecraft:wool 15
setblock ~24~1~13 minecraft:wool 15
setblock ~26~1~13 minecraft:wool 15
setblock ~28~1~13 minecraft:wool 15
setblock ~30~1~13 minecraft:wool 15
fill ~34~0~13 ~35~0~14 minecraft:glowstone
fill ~34~1~13 ~35~1~14 minecraft:stained_glass 8
setblock ~39~1~13 minecraft:wool 15
setblock ~41~1~13 minecraft:wool 15
setblock ~43~1~13 minecraft:wool 15
setblock ~45~1~13 minecraft:wool 15
setblock ~47~1~13 minecraft:wool 15
setblock ~49~1~13 minecraft:wool 15
fill ~51~0~13 ~53~0~13 minecraft:dirt 0
setblock ~51~1~13 minecraft:wool 15
setblock ~53~1~13 minecraft:wool 15
setblock ~54~0~13 minecraft:grass
setblock ~54~1~13 minecraft:glowstone
fill ~55~0~13 ~57~0~31 minecraft:dirt 0
setblock ~55~1~13 minecraft:wool 15
setblock ~57~1~13 minecraft:wool 15
setblock ~59~1~13 minecraft:wool 15
setblock ~61~1~13 minecraft:wool 15
setblock ~63~1~13 minecraft:wool 15
setblock ~64~4~13 minecraft:wool 7
fill ~64~5~13 ~64~6~13 minecraft:wool 15
setblock ~64~7~13 minecraft:wool 7
setblock ~64~9~13 minecraft:quartz_block 0
setblock ~65~1~13 minecraft:wool 15
fill ~65~5~13 ~65~6~13 minecraft:diamond_block
fill ~65~9~13 ~65~9~14 minecraft:wool 7
setblock ~66~4~13 minecraft:wool 7
fill ~66~5~13 ~66~6~13 minecraft:wool 15
setblock ~66~7~13 minecraft:wool 7
setblock ~66~9~13 minecraft:quartz_block 0
setblock ~2~9~14 minecraft:quartz_block 0
setblock ~2~10~14 minecraft:wool 7
fill ~3~3~14 ~3~8~14 minecraft:quartz_block 0
setblock ~3~9~14 minecraft:wool 7
setblock ~3~10~14 minecraft:stained_glass 8
setblock ~4~1~14 minecraft:wool 7
fill ~4~3~14 ~4~8~14 minecraft:wool 7
setblock ~4~10~14 minecraft:diamond_block
fill ~5~3~14 ~5~8~14 minecraft:quartz_block 0
setblock ~5~9~14 minecraft:wool 7
setblock ~5~10~14 minecraft:stained_glass 8
setblock ~6~1~14 minecraft:wool 7
setblock ~6~9~14 minecraft:quartz_block 0
setblock ~6~10~14 minecraft:wool 7
setblock ~7~10~14 minecraft:quartz_block 0
setblock ~8~1~14 minecraft:wool 7
setblock ~10~1~14 minecraft:wool 7
setblock ~12~1~14 minecraft:wool 7
setblock ~14~1~14 minecraft:wool 7
fill ~15~0~14 ~15~0~31 minecraft:dirt 0
fill ~15~1~14 ~15~1~29 minecraft:wool 15
setblock ~16~0~14 minecraft:grass
setblock ~16~1~14 minecraft:glowstone
fill ~17~0~14 ~18~0~14 minecraft:dirt 0
setblock ~18~1~14 minecraft:wool 7
setblock ~20~1~14 minecraft:wool 7
setblock ~22~1~14 minecraft:wool 7
setblock ~24~1~14 minecraft:wool 7
setblock ~26~1~14 minecraft:wool 7
setblock ~28~1~14 minecraft:wool 7
setblock ~30~1~14 minecraft:wool 7
setblock ~39~1~14 minecraft:wool 7
setblock ~41~1~14 minecraft:wool 7
setblock ~43~1~14 minecraft:wool 7
setblock ~45~1~14 minecraft:wool 7
setblock ~47~1~14 minecraft:wool 7
setblock ~49~1~14 minecraft:wool 7
fill ~51~0~14 ~52~0~14 minecraft:dirt 0
setblock ~51~1~14 minecraft:wool 7
setblock ~53~0~14 minecraft:grass
setblock ~53~1~14 minecraft:glowstone
fill ~54~0~14 ~54~0~31 minecraft:dirt 0
fill ~54~1~14 ~54~1~29 minecraft:wool 15
setblock ~55~1~14 minecraft:wool 7
setblock ~57~1~14 minecraft:wool 7
setblock ~59~1~14 minecraft:wool 7
setblock ~61~1~14 minecraft:wool 7
setblock ~62~10~14 minecraft:quartz_block 0
setblock ~63~1~14 minecraft:wool 7
setblock ~63~9~14 minecraft:quartz_block 0
setblock ~63~10~14 minecraft:wool 7
fill ~64~3~14 ~64~8~14 minecraft:quartz_block 0
setblock ~64~9~14 minecraft:wool 7
setblock ~64~10~14 minecraft:stained_glass 8
setblock ~65~1~14 minecraft:wool 7
fill ~65~3~14 ~65~8~14 minecraft:wool 7
setblock ~65~10~14 minecraft:diamond_block
fill ~66~3~14 ~66~8~14 minecraft:quartz_block 0
setblock ~66~9~14 minecraft:wool 7
setblock ~66~10~14 minecraft:stained_glass 8
setblock ~67~9~14 minecraft:quartz_block 0
setblock ~67~10~14 minecraft:wool 7
setblock ~2~11~15 minecraft:wool 7
fill ~3~4~15 ~3~4~16 minecraft:quartz_block 0
setblock ~3~11~15 minecraft:stained_glass 8
setblock ~4~1~15 minecraft:wool 15
setblock ~4~3~15 minecraft:quartz_block 0
setblock ~4~11~15 minecraft:diamond_block
fill ~5~4~15 ~5~4~16 minecraft:quartz_block 0
setblock ~5~11~15 minecraft:stained_glass 8
setblock ~6~1~15 minecraft:wool 15
setblock ~6~11~15 minecraft:wool 7
setblock ~7~11~15 minecraft:quartz_block 0
setblock ~8~1~15 minecraft:wool 15
setblock ~10~1~15 minecraft:wool 15
setblock ~12~1~15 minecraft:wool 15
setblock ~14~1~15 minecraft:wool 15
fill ~16~0~15 ~16~0~31 minecraft:dirt 0
setblock ~16~1~15 minecraft:wool 15
setblock ~17~0~15 minecraft:grass
setblock ~17~1~15 minecraft:glowstone
setblock ~18~0~15 minecraft:dirt 0
setblock ~18~1~15 minecraft:wool 15
setblock ~20~1~15 minecraft:wool 15
setblock ~22~1~15 minecraft:wool 15
setblock ~24~1~15 minecraft:wool 15
setblock ~26~1~15 minecraft:wool 15
setblock ~28~1~15 minecraft:wool 15
setblock ~30~1~15 minecraft:wool 15
fill ~34~0~15 ~35~1~15 minecraft:quartz_block 0
setblock ~39~1~15 minecraft:wool 15
setblock ~41~1~15 minecraft:wool 15
setblock ~43~1~15 minecraft:wool 15
setblock ~45~1~15 minecraft:wool 15
setblock ~47~1~15 minecraft:wool 15
setblock ~49~1~15 minecraft:wool 15
setblock ~51~0~15 minecraft:dirt 0
setblock ~51~1~15 minecraft:wool 15
setblock ~52~0~15 minecraft:grass
setblock ~52~1~15 minecraft:glowstone
fill ~53~0~15 ~53~0~31 minecraft:dirt 0
setblock ~53~1~15 minecraft:wool 15
setblock ~55~1~15 minecraft:wool 15
setblock ~57~1~15 minecraft:wool 15
setblock ~59~1~15 minecraft:wool 15
setblock ~61~1~15 minecraft:wool 15
setblock ~62~11~15 minecraft:quartz_block 0
setblock ~63~1~15 minecraft:wool 15
setblock ~63~11~15 minecraft:wool 7
fill ~64~4~15 ~64~4~16 minecraft:quartz_block 0
setblock ~64~11~15 minecraft:stained_glass 8
setblock ~65~1~15 minecraft:wool 15
setblock ~65~3~15 minecraft:quartz_block 0
setblock ~65~11~15 minecraft:diamond_block
fill ~66~4~15 ~66~4~16 minecraft:quartz_block 0
setblock ~66~11~15 minecraft:stained_glass 8
setblock ~67~11~15 minecraft:wool 7
setblock ~2~12~16 minecraft:wool 7
setblock ~3~12~16 minecraft:stained_glass 8
setblock ~4~1~16 minecraft:wool 7
setblock ~4~2~16 minecraft:quartz_block 0
setblock ~4~12~16 minecraft:diamond_block
setblock ~5~12~16 minecraft:stained_glass 8
setblock ~6~1~16 minecraft:wool 7
setblock ~6~12~16 minecraft:wool 7
setblock ~7~12~16 minecraft:quartz_block 0
setblock ~8~1~16 minecraft:wool 7
setblock ~10~1~16 minecraft:wool 7
setblock ~12~1~16 minecraft:wool 7
setblock ~14~1~16 minecraft:wool 7
setblock ~16~1~16 minecraft:wool 7
fill ~17~0~16 ~17~0~31 minecraft:dirt 0
fill ~17~1~16 ~17~1~29 minecraft:wool 15
setblock ~18~0~16 minecraft:grass
setblock ~18~1~16 minecraft:glowstone
setblock ~20~1~16 minecraft:wool 7
setblock ~22~1~16 minecraft:wool 7
setblock ~24~1~16 minecraft:wool 7
setblock ~26~1~16 minecraft:wool 7
setblock ~28~1~16 minecraft:wool 7
setblock ~30~1~16 minecraft:wool 7
fill ~34~0~16 ~35~0~17 minecraft:dirt 0
fill ~34~1~16 ~35~1~17 minecraft:quartz_block 0
setblock ~39~1~16 minecraft:wool 7
setblock ~41~1~16 minecraft:wool 7
setblock ~43~1~16 minecraft:wool 7
setblock ~45~1~16 minecraft:wool 7
setblock ~47~1~16 minecraft:wool 7
setblock ~49~1~16 minecraft:wool 7
setblock ~51~0~16 minecraft:grass
setblock ~51~1~16 minecraft:glowstone
fill ~52~0~16 ~52~0~31 minecraft:dirt 0
fill ~52~1~16 ~52~1~29 minecraft:wool 15
setblock ~53~1~16 minecraft:wool 7
setblock ~55~1~16 minecraft:wool 7
setblock ~57~1~16 minecraft:wool 7
setblock ~59~1~16 minecraft:wool 7
setblock ~61~1~16 minecraft:wool 7
setblock ~62~12~16 minecraft:quartz_block 0
setblock ~63~1~16 minecraft:wool 7
setblock ~63~12~16 minecraft:wool 7
setblock ~64~12~16 minecraft:stained_glass 8
setblock ~65~1~16 minecraft:wool 7
setblock ~65~2~16 minecraft:quartz_block 0
setblock ~65~12~16 minecraft:diamond_block
setblock ~66~12~16 minecraft:stained_glass 8
setblock ~67~12~16 minecraft:wool 7
setblock ~2~13~17 minecraft:wool 7
setblock ~3~3~17 minecraft:quartz_block 0
setblock ~3~13~17 minecraft:stained_glass 8
fill ~4~0~17 ~4~0~28 minecraft:glowstone
fill ~4~1~17 ~4~1~28 minecraft:stained_glass 8
setblock ~4~13~17 minecraft:diamond_block
setblock ~5~3~17 minecraft:quartz_block 0
setblock ~5~13~17 minecraft:stained_glass 8
setblock ~6~1~17 minecraft:wool 15
setblock ~6~13~17 minecraft:wool 7
setblock ~7~13~17 minecraft:quartz_block 0
setblock ~8~1~17 minecraft:wool 15
setblock ~10~1~17 minecraft:wool 15
setblock ~12~1~17 minecraft:wool 15
setblock ~14~1~17 minecraft:wool 15
setblock ~16~1~17 minecraft:wool 15
fill ~18~0~17 ~18~0~48 minecraft:dirt 0
setblock ~18~1~17 minecraft:wool 15
setblock ~19~0~17 minecraft:grass
setblock ~19~1~17 minecraft:glowstone
fill ~20~0~17 ~30~0~17 minecraft:dirt 0
setblock ~20~1~17 minecraft:wool 15
setblock ~22~1~17 minecraft:wool 15
setblock ~24~1~17 minecraft:wool 15
setblock ~26~1~17 minecraft:wool 15
setblock ~28~1~17 minecraft:wool 15
setblock ~30~1~17 minecraft:wool 15
fill ~39~0~17 ~49~0~17 minecraft:dirt 0
setblock ~39~1~17 minecraft:wool 15
setblock ~41~1~17 minecraft:wool 15
setblock ~43~1~17 minecraft:wool 15
setblock ~45~1~17 minecraft:wool 15
setblock ~47~1~17 minecraft:wool 15
setblock ~49~1~17 minecraft:wool 15
setblock ~50~0~17 minecraft:grass
setblock ~50~1~17 minecraft:glowstone
fill ~51~0~17 ~51~0~48 minecraft:dirt 0
setblock ~51~1~17 minecraft:wool 15
setblock ~53~1~17 minecraft:wool 15
setblock ~55~1~17 minecraft:wool 15
setblock ~57~1~17 minecraft:wool 15
setblock ~59~1~17 minecraft:wool 15
setblock ~61~1~17 minecraft:wool 15
setblock ~62~13~17 minecraft:quartz_block 0
setblock ~63~1~17 minecraft:wool 15
setblock ~63~13~17 minecraft:wool 7
setblock ~64~3~17 minecraft:quartz_block 0
setblock ~64~13~17 minecraft:stained_glass 8
fill ~65~0~17 ~65~0~28 minecraft:glowstone
fill ~65~1~17 ~65~1~28 minecraft:stained_glass 8
setblock ~65~13~17 minecraft:diamond_block
setblock ~66~3~17 minecraft:quartz_block 0
setblock ~66~13~17 minecraft:stained_glass 8
setblock ~67~13~17 minecraft:wool 7
setblock ~2~14~18 minecraft:wool 7
setblock ~3~2~18 minecraft:quartz_block 0
setblock ~3~14~18 minecraft:stained_glass 8
setblock ~4~14~18 minecraft:diamond_block
setblock ~5~2~18 minecraft:quartz_block 0
setblock ~5~14~18 minecraft:stained_glass 8
setblock ~6~1~18 minecraft:wool 7
setblock ~6~14~18 minecraft:wool 7
setblock ~7~14~18 minecraft:quartz_block 0
setblock ~8~1~18 minecraft:wool 7
setblock ~10~1~18 minecraft:wool 7
setblock ~12~1~18 minecraft:wool 7
setblock ~14~1~18 minecraft:wool 7
setblock ~16~1~18 minecraft:wool 7
setblock ~18~1~18 minecraft:wool 7
fill ~19~0~18 ~19~0~47 minecraft:dirt 0
fill ~19~1~18 ~19~1~29 minecraft:wool 15
setblock ~20~0~18 minecraft:grass
setblock ~20~1~18 minecraft:glowstone
fill ~20~5~18 ~29~5~18 minecraft:quartz_block 0
fill ~21~0~18 ~30~0~18 minecraft:dirt 0
setblock ~22~1~18 minecraft:wool 7
setblock ~24~1~18 minecraft:wool 7
setblock ~26~1~18 minecraft:wool 7
setblock ~28~1~18 minecraft:wool 7
fill ~29~4~18 ~30~4~18 minecraft:quartz_block 0
setblock ~30~1~18 minecraft:wool 7
fill ~30~3~18 ~31~3~18 minecraft:quartz_block 0
setblock ~31~2~18 minecraft:quartz_block 0
fill ~32~2~18 ~32~2~21 minecraft:quartz_stairs 1
fill ~34~0~18 ~35~0~19 minecraft:glowstone
fill ~34~1~18 ~35~1~19 minecraft:stained_glass 8
fill ~37~2~18 ~37~2~21 minecraft:quartz_stairs 0
fill ~38~2~18 ~38~3~18 minecraft:quartz_block 0
fill ~39~0~18 ~48~0~18 minecraft:dirt 0
setblock ~39~1~18 minecraft:wool 7
fill ~39~3~18 ~39~4~18 minecraft:quartz_block 0
fill ~40~4~18 ~40~5~18 minecraft:quartz_block 0
setblock ~41~1~18 minecraft:wool 7
fill ~41~5~18 ~49~5~18 minecraft:quartz_block 0
setblock ~43~1~18 minecraft:wool 7
setblock ~45~1~18 minecraft:wool 7
setblock ~47~1~18 minecraft:wool 7
setblock ~49~0~18 minecraft:grass
setblock ~49~1~18 minecraft:glowstone
fill ~50~0~18 ~50~0~47 minecraft:dirt 0
fill ~50~1~18 ~50~1~29 minecraft:wool 15
setblock ~51~1~18 minecraft:wool 7
setblock ~53~1~18 minecraft:wool 7
setblock ~55~1~18 minecraft:wool 7
setblock ~57~1~18 minecraft:wool 7
setblock ~59~1~18 minecraft:wool 7
setblock ~61~1~18 minecraft:wool 7
setblock ~62~14~18 minecraft:quartz_block 0
setblock ~63~1~18 minecraft:wool 7
setblock ~63~14~18 minecraft:wool 7
setblock ~64~2~18 minecraft:quartz_block 0
setblock ~64~14~18 minecraft:stained_glass 8
setblock ~65~14~18 minecraft:diamond_block
setblock ~66~2~18 minecraft:quartz_block 0
setblock ~66~14~18 minecraft:stained_glass 8
setblock ~67~14~18 minecraft:wool 7
fill ~2~15~19 ~2~15~24 minecraft:wool 7
fill ~3~1~19 ~3~1~29 minecraft:quartz_block 0
fill ~3~15~19 ~3~15~24 minecraft:stained_glass 8
fill ~4~15~19 ~4~15~24 minecraft:diamond_block
fill ~5~1~19 ~5~1~29 minecraft:quartz_block 0
fill ~5~15~19 ~5~15~24 minecraft:stained_glass 8
setblock ~6~1~19 minecraft:wool 15
fill ~6~15~19 ~6~15~24 minecraft:wool 7
fill ~7~15~19 ~7~15~24 minecraft:quartz_block 0
setblock ~8~1~19 minecraft:wool 15
setblock ~10~1~19 minecraft:wool 15
setblock ~12~1~19 minecraft:wool 15
setblock ~14~1~19 minecraft:wool 15
setblock ~16~1~19 minecraft:wool 15
setblock ~18~1~19 minecraft:wool 15
fill ~20~0~19 ~20~0~31 minecraft:dirt 0
setblock ~20~1~19 minecraft:wool 15
fill ~20~5~19 ~20~5~27 minecraft:quartz_block 0
setblock ~21~0~19 minecraft:grass
setblock ~21~1~19 minecraft:glowstone
fill ~21~4~19 ~29~4~20 minecraft:stained_glass 8
fill ~22~0~19 ~30~0~19 minecraft:dirt 0
setblock ~22~1~19 minecraft:wool 15
setblock ~24~1~19 minecraft:wool 15
setblock ~26~1~19 minecraft:wool 15
setblock ~28~1~19 minecraft:wool 15
setblock ~30~1~19 minecraft:wool 15
fill ~30~4~19 ~30~4~20 minecraft:quartz_stairs 1
fill ~31~2~19 ~31~2~20 minecraft:glowstone
fill ~31~3~19 ~31~3~20 minecraft:quartz_stairs 1
fill ~38~2~19 ~38~2~20 minecraft:glowstone
fill ~38~3~19 ~38~3~20 minecraft:quartz_stairs 0
fill ~39~0~19 ~47~0~19 minecraft:dirt 0
setblock ~39~1~19 minecraft:wool 15
fill ~39~4~19 ~39~4~20 minecraft:quartz_stairs 0
fill ~40~4~19 ~48~4~20 minecraft:stained_glass 8
setblock ~41~1~19 minecraft:wool 15
setblock ~43~1~19 minecraft:wool 15
setblock ~45~1~19 minecraft:wool 15
setblock ~47~1~19 minecraft:wool 15
setblock ~48~0~19 minecraft:grass
setblock ~48~1~19 minecraft:glowstone
fill ~49~0~19 ~49~0~31 minecraft:dirt 0
setblock ~49~1~19 minecraft:wool 15
fill ~49~5~19 ~49~5~27 minecraft:quartz_block 0
setblock ~51~1~19 minecraft:wool 15
setblock ~53~1~19 minecraft:wool 15
setblock ~55~1~19 minecraft:wool 15
setblock ~57~1~19 minecraft:wool 15
setblock ~59~1~19 minecraft:wool 15
setblock ~61~1~19 minecraft:wool 15
fill ~62~15~19 ~62~15~24 minecraft:quartz_block 0
setblock ~63~1~19 minecraft:wool 15
fill ~63~15~19 ~63~15~24 minecraft:wool 7
fill ~64~1~19 ~64~1~29 minecraft:quartz_block 0
fill ~64~15~19 ~64~15~24 minecraft:stained_glass 8
fill ~65~15~19 ~65~15~24 minecraft:diamond_block
fill ~66~1~19 ~66~1~29 minecraft:quartz_block 0
fill ~66~15~19 ~66~15~24 minecraft:stained_glass 8
fill ~67~15~19 ~67~15~24 minecraft:wool 7
setblock ~6~1~20 minecraft:wool 7
setblock ~8~1~20 minecraft:wool 7
setblock ~10~1~20 minecraft:wool 7
setblock ~12~1~20 minecraft:wool 7
setblock ~14~1~20 minecraft:wool 7
setblock ~16~1~20 minecraft:wool 7
setblock ~18~1~20 minecraft:wool 7
setblock ~20~1~20 minecraft:wool 7
fill ~21~0~20 ~21~0~31 minecraft:dirt 0
fill ~21~1~20 ~21~1~29 minecraft:wool 15
setblock ~22~0~20 minecraft:grass
setblock ~22~1~20 minecraft:glowstone
fill ~23~0~20 ~30~0~20 minecraft:dirt 0
setblock ~24~1~20 minecraft:wool 7
setblock ~26~1~20 minecraft:wool 7
setblock ~28~1~20 minecraft:wool 7
setblock ~30~1~20 minecraft:wool 7
fill ~34~0~20 ~35~1~20 minecraft:quartz_block 0
fill ~39~0~20 ~46~0~20 minecraft:dirt 0
setblock ~39~1~20 minecraft:wool 7
setblock ~41~1~20 minecraft:wool 7
setblock ~43~1~20 minecraft:wool 7
setblock ~45~1~20 minecraft:wool 7
setblock ~47~0~20 minecraft:grass
setblock ~47~1~20 minecraft:glowstone
fill ~48~0~20 ~48~0~31 minecraft:dirt 0
fill ~48~1~20 ~48~1~29 minecraft:wool 15
setblock ~49~1~20 minecraft:wool 7
setblock ~51~1~20 minecraft:wool 7
setblock ~53~1~20 minecraft:wool 7
setblock ~55~1~20 minecraft:wool 7
setblock ~57~1~20 minecraft:wool 7
setblock ~59~1~20 minecraft:wool 7
setblock ~61~1~20 minecraft:wool 7
setblock ~63~1~20 minecraft:wool 7
setblock ~6~1~21 minecraft:wool 15
setblock ~8~1~21 minecraft:wool 15
setblock ~10~1~21 minecraft:wool 15
setblock ~12~1~21 minecraft:wool 15
setblock ~14~1~21 minecraft:wool 15
setblock ~16~1~21 minecraft:wool 15
setblock ~18~1~21 minecraft:wool 15
setblock ~20~1~21 minecraft:wool 15
fill ~21~4~21 ~22~4~27 minecraft:stained_glass 8
fill ~22~0~21 ~22~0~31 minecraft:dirt 0
setblock ~22~1~21 minecraft:wool 15
setblock ~23~0~21 minecraft:grass
setblock ~23~1~21 minecraft:glowstone
fill ~23~5~21 ~29~5~21 minecraft:quartz_block 0
fill ~24~0~21 ~30~0~21 minecraft:dirt 0
setblock ~24~1~21 minecraft:wool 15
setblock ~26~1~21 minecraft:wool 15
setblock ~28~1~21 minecraft:wool 15
fill ~29~4~21 ~30~4~21 minecraft:quartz_block 0
setblock ~30~1~21 minecraft:wool 15
fill ~30~3~21 ~31~3~21 minecraft:quartz_block 0
setblock ~31~2~21 minecraft:quartz_block 0
fill ~34~0~21 ~35~0~22 minecraft:dirt 0
fill ~34~1~21 ~35~1~22 minecraft:quartz_block 0
fill ~38~2~21 ~38~3~21 minecraft:quartz_block 0
fill ~39~0~21 ~45~0~21 minecraft:dirt 0
setblock ~39~1~21 minecraft:wool 15
fill ~39~3~21 ~39~4~21 minecraft:quartz_block 0
fill ~40~4~21 ~40~5~21 minecraft:quartz_block 0
setblock ~41~1~21 minecraft:wool 15
fill ~41~5~21 ~46~5~21 minecraft:quartz_block 0
setblock ~43~1~21 minecraft:wool 15
setblock ~45~1~21 minecraft:wool 15
setblock ~46~0~21 minecraft:grass
setblock ~46~1~21 minecraft:glowstone
fill ~47~0~21 ~47~0~31 minecraft:dirt 0
setblock ~47~1~21 minecraft:wool 15
fill ~47~4~21 ~48~4~27 minecraft:stained_glass 8
setblock ~49~1~21 minecraft:wool 15
setblock ~51~1~21 minecraft:wool 15
setblock ~53~1~21 minecraft:wool 15
setblock ~55~1~21 minecraft:wool 15
setblock ~57~1~21 minecraft:wool 15
setblock ~59~1~21 minecraft:wool 15
setblock ~61~1~21 minecraft:wool 15
setblock ~63~1~21 minecraft:wool 15
setblock ~6~1~22 minecraft:wool 7
setblock ~7~14~22 minecraft:quartz_block 0
setblock ~8~1~22 minecraft:wool 7
setblock ~10~1~22 minecraft:wool 7
setblock ~12~1~22 minecraft:wool 7
setblock ~14~1~22 minecraft:wool 7
setblock ~16~1~22 minecraft:wool 7
setblock ~18~1~22 minecraft:wool 7
setblock ~20~1~22 minecraft:wool 7
setblock ~22~1~22 minecraft:wool 7
fill ~23~0~22 ~23~0~43 minecraft:dirt 0
fill ~23~1~22 ~23~1~29 minecraft:wool 15
fill ~23~5~22 ~23~5~27 minecraft:quartz_block 0
setblock ~24~0~22 minecraft:grass
setblock ~24~1~22 minecraft:glowstone
fill ~25~0~22 ~30~0~22 minecraft:dirt 0
setblock ~26~1~22 minecraft:wool 7
setblock ~28~1~22 minecraft:wool 7
setblock ~30~1~22 minecraft:wool 7
fill ~39~0~22 ~44~0~22 minecraft:dirt 0
setblock ~39~1~22 minecraft:wool 7
setblock ~41~1~22 minecraft:wool 7
setblock ~43~1~22 minecraft:wool 7
setblock ~45~0~22 minecraft:grass
setblock ~45~1~22 minecraft:glowstone
fill ~46~0~22 ~46~0~43 minecraft:dirt 0
fill ~46~1~22 ~46~1~29 minecraft:wool 15
fill ~46~5~22 ~46~5~27 minecraft:quartz_block 0
setblock ~47~1~22 minecraft:wool 7
setblock ~49~1~22 minecraft:wool 7
setblock ~51~1~22 minecraft:wool 7
setblock ~53~1~22 minecraft:wool 7
setblock ~55~1~22 minecraft:wool 7
setblock ~57~1~22 minecraft:wool 7
setblock ~59~1~22 minecraft:wool 7
setblock ~61~1~22 minecraft:wool 7
setblock ~62~14~22 minecraft:quartz_block 0
setblock ~63~1~22 minecraft:wool 7
setblock ~6~1~23 minecraft:wool 15
fill ~7~13~23 ~7~13~24 minecraft:quartz_block 0
setblock ~8~1~23 minecraft:wool 15
setblock ~10~1~23 minecraft:wool 15
setblock ~12~1~23 minecraft:wool 15
setblock ~14~1~23 minecraft:wool 15
setblock ~16~1~23 minecraft:wool 15
setblock ~18~1~23 minecraft:wool 15
setblock ~20~1~23 minecraft:wool 15
setblock ~22~1~23 minecraft:wool 15
fill ~24~0~23 ~24~0~42 minecraft:dirt 0
setblock ~24~1~23 minecraft:wool 15
setblock ~25~0~23 minecraft:grass
setblock ~25~1~23 minecraft:glowstone
fill ~26~0~23 ~30~0~23 minecraft:dirt 0
setblock ~26~1~23 minecraft:wool 15
setblock ~28~1~23 minecraft:wool 15
setblock ~30~1~23 minecraft:wool 15
fill ~34~0~23 ~35~0~24 minecraft:glowstone
fill ~34~1~23 ~35~1~24 minecraft:stained_glass 8
fill ~39~0~23 ~43~0~23 minecraft:dirt 0
setblock ~39~1~23 minecraft:wool 15
setblock ~41~1~23 minecraft:wool 15
setblock ~43~1~23 minecraft:wool 15
setblock ~44~0~23 minecraft:grass
setblock ~44~1~23 minecraft:glowstone
fill ~45~0~23 ~45~0~42 minecraft:dirt 0
setblock ~45~1~23 minecraft:wool 15
setblock ~47~1~23 minecraft:wool 15
setblock ~49~1~23 minecraft:wool 15
setblock ~51~1~23 minecraft:wool 15
setblock ~53~1~23 minecraft:wool 15
setblock ~55~1~23 minecraft:wool 15
setblock ~57~1~23 minecraft:wool 15
setblock ~59~1~23 minecraft:wool 15
setblock ~61~1~23 minecraft:wool 15
fill ~62~13~23 ~62~13~24 minecraft:quartz_block 0
setblock ~63~1~23 minecraft:wool 15
fill ~2~12~24 ~2~14~24 minecraft:wool 7
fill ~2~16~24 ~2~17~24 minecraft:wool 7
fill ~3~12~24 ~3~14~24 minecraft:stained_glass 8
fill ~3~16~24 ~3~17~24 minecraft:stained_glass 8
fill ~4~12~24 ~4~14~24 minecraft:diamond_block
fill ~4~16~24 ~4~17~24 minecraft:diamond_block
fill ~5~12~24 ~5~14~24 minecraft:stained_glass 8
fill ~5~16~24 ~5~17~24 minecraft:stained_glass 8
setblock ~6~1~24 minecraft:wool 7
fill ~6~12~24 ~6~14~24 minecraft:wool 7
fill ~6~16~24 ~6~17~24 minecraft:wool 7
setblock ~7~12~24 minecraft:quartz_block 0
setblock ~7~14~24 minecraft:quartz_block 0
fill ~7~16~24 ~7~17~24 minecraft:quartz_block 0
setblock ~8~1~24 minecraft:wool 7
setblock ~10~1~24 minecraft:wool 7
setblock ~12~1~24 minecraft:wool 7
setblock ~14~1~24 minecraft:wool 7
setblock ~16~1~24 minecraft:wool 7
setblock ~18~1~24 minecraft:wool 7
setblock ~20~1~24 minecraft:wool 7
setblock ~22~1~24 minecraft:wool 7
setblock ~24~1~24 minecraft:wool 7
fill ~25~0~24 ~25~0~31 minecraft:dirt 0
fill ~25~1~24 ~25~1~29 minecraft:wool 15
setblock ~26~0~24 minecraft:grass
setblock ~26~1~24 minecraft:glowstone
fill ~27~0~24 ~30~0~24 minecraft:dirt 0
setblock ~28~1~24 minecraft:wool 7
setblock ~30~1~24 minecraft:wool 7
fill ~39~0~24 ~42~0~24 minecraft:dirt 0
setblock ~39~1~24 minecraft:wool 7
setblock ~41~1~24 minecraft:wool 7
setblock ~43~0~24 minecraft:grass
setblock ~43~1~24 minecraft:glowstone
fill ~44~0~24 ~44~0~31 minecraft:dirt 0
fill ~44~1~24 ~44~1~29 minecraft:wool 15
setblock ~45~1~24 minecraft:wool 7
setblock ~47~1~24 minecraft:wool 7
setblock ~49~1~24 minecraft:wool 7
setblock ~51~1~24 minecraft:wool 7
setblock ~53~1~24 minecraft:wool 7
setblock ~55~1~24 minecraft:wool 7
setblock ~57~1~24 minecraft:wool 7
setblock ~59~1~24 minecraft:wool 7
setblock ~61~1~24 minecraft:wool 7
setblock ~62~12~24 minecraft:quartz_block 0
setblock ~62~14~24 minecraft:quartz_block 0
fill ~62~16~24 ~62~17~24 minecraft:quartz_block 0
setblock ~63~1~24 minecraft:wool 7
fill ~63~12~24 ~63~14~24 minecraft:wool 7
fill ~63~16~24 ~63~17~24 minecraft:wool 7
fill ~64~12~24 ~64~14~24 minecraft:stained_glass 8
fill ~64~16~24 ~64~17~24 minecraft:stained_glass 8
fill ~65~12~24 ~65~14~24 minecraft:diamond_block
fill ~65~16~24 ~65~17~24 minecraft:diamond_block
fill ~66~12~24 ~66~14~24 minecraft:stained_glass 8
fill ~66~16~24 ~66~17~24 minecraft:stained_glass 8
fill ~67~12~24 ~67~14~24 minecraft:wool 7
fill ~67~16~24 ~67~17~24 minecraft:wool 7
fill ~2~10~25 ~2~11~25 minecraft:wool 7
fill ~2~18~25 ~2~19~25 minecraft:wool 7
fill ~3~10~25 ~3~11~25 minecraft:stained_glass 8
fill ~3~18~25 ~3~19~25 minecraft:stained_glass 8
fill ~4~10~25 ~4~11~25 minecraft:diamond_block
fill ~4~18~25 ~4~19~25 minecraft:diamond_block
fill ~5~10~25 ~5~11~25 minecraft:stained_glass 8
fill ~5~18~25 ~5~19~25 minecraft:stained_glass 8
setblock ~6~1~25 minecraft:wool 15
fill ~6~10~25 ~6~11~25 minecraft:wool 7
fill ~6~18~25 ~6~19~25 minecraft:wool 7
fill ~7~10~25 ~7~11~25 minecraft:quartz_block 0
fill ~7~18~25 ~7~19~25 minecraft:quartz_block 0
setblock ~8~1~25 minecraft:wool 15
setblock ~10~1~25 minecraft:wool 15
setblock ~12~1~25 minecraft:wool 15
setblock ~14~1~25 minecraft:wool 15
setblock ~16~1~25 minecraft:wool 15
setblock ~18~1~25 minecraft:wool 15
setblock ~20~1~25 minecraft:wool 15
setblock ~22~1~25 minecraft:wool 15
setblock ~24~1~25 minecraft:wool 15
fill ~26~0~25 ~26~0~31 minecraft:dirt 0
setblock ~26~1~25 minecraft:wool 15
setblock ~27~0~25 minecraft:grass
setblock ~27~1~25 minecraft:glowstone
fill ~28~0~25 ~30~0~26 minecraft:dirt 0
setblock ~28~1~25 minecraft:wool 15
setblock ~30~1~25 minecraft:wool 15
fill ~34~0~25 ~35~1~25 minecraft:quartz_block 0
fill ~39~0~25 ~41~0~26 minecraft:dirt 0
setblock ~39~1~25 minecraft:wool 15
setblock ~41~1~25 minecraft:wool 15
setblock ~42~0~25 minecraft:grass
setblock ~42~1~25 minecraft:glowstone
fill ~43~0~25 ~43~0~31 minecraft:dirt 0
setblock ~43~1~25 minecraft:wool 15
setblock ~45~1~25 minecraft:wool 15
setblock ~47~1~25 minecraft:wool 15
setblock ~49~1~25 minecraft:wool 15
setblock ~51~1~25 minecraft:wool 15
setblock ~53~1~25 minecraft:wool 15
setblock ~55~1~25 minecraft:wool 15
setblock ~57~1~25 minecraft:wool 15
setblock ~59~1~25 minecraft:wool 15
setblock ~61~1~25 minecraft:wool 15
fill ~62~10~25 ~62~11~25 minecraft:quartz_block 0
fill ~62~18~25 ~62~19~25 minecraft:quartz_block 0
setblock ~63~1~25 minecraft:wool 15
fill ~63~10~25 ~63~11~25 minecraft:wool 7
fill ~63~18~25 ~63~19~25 minecraft:wool 7
fill ~64~10~25 ~64~11~25 minecraft:stained_glass 8
fill ~64~18~25 ~64~19~25 minecraft:stained_glass 8
fill ~65~10~25 ~65~11~25 minecraft:diamond_block
fill ~65~18~25 ~65~19~25 minecraft:diamond_block
fill ~66~10~25 ~66~11~25 minecraft:stained_glass 8
fill ~66~18~25 ~66~19~25 minecraft:stained_glass 8
fill ~67~10~25 ~67~11~25 minecraft:wool 7
fill ~67~18~25 ~67~19~25 minecraft:wool 7
setblock ~2~9~26 minecraft:wool 7
setblock ~2~20~26 minecraft:wool 7
setblock ~3~9~26 minecraft:stained_glass 8
setblock ~3~20~26 minecraft:stained_glass 8
setblock ~4~9~26 minecraft:diamond_block
setblock ~4~20~26 minecraft:diamond_block
setblock ~5~9~26 minecraft:stained_glass 8
setblock ~5~20~26 minecraft:stained_glass 8
setblock ~6~1~26 minecraft:wool 7
setblock ~6~9~26 minecraft:wool 7
setblock ~6~20~26 minecraft:wool 7
setblock ~7~9~26 minecraft:quartz_block 0
setblock ~7~20~26 minecraft:quartz_block 0
setblock ~8~1~26 minecraft:wool 7
setblock ~10~1~26 minecraft:wool 7
setblock ~12~1~26 minecraft:wool 7
setblock ~14~1~26 minecraft:wool 7
setblock ~16~1~26 minecraft:wool 7
setblock ~18~1~26 minecraft:wool 7
setblock ~20~1~26 minecraft:wool 7
setblock ~22~1~26 minecraft:wool 7
setblock ~24~1~26 minecraft:wool 7
setblock ~26~1~26 minecraft:wool 7
fill ~27~0~26 ~27~0~31 minecraft:dirt 0
fill ~27~1~26 ~27~1~29 minecraft:wool 15
fill ~28~1~26 ~30~1~26 minecraft:diamond_block
setblock ~33~1~26 minecraft:diamond_block
fill ~34~0~26 ~35~0~27 minecraft:dirt 0
fill ~34~1~26 ~35~1~27 minecraft:quartz_block 0
setblock ~36~1~26 minecraft:diamond_block
fill ~39~1~26 ~41~1~26 minecraft:diamond_block
fill ~42~0~26 ~42~0~31 minecraft:dirt 0
fill ~42~1~26 ~42~1~29 minecraft:wool 15
setblock ~43~1~26 minecraft:wool 7
setblock ~45~1~26 minecraft:wool 7
setblock ~47~1~26 minecraft:wool 7
setblock ~49~1~26 minecraft:wool 7
setblock ~51~1~26 minecraft:wool 7
setblock ~53~1~26 minecraft:wool 7
setblock ~55~1~26 minecraft:wool 7
setblock ~57~1~26 minecraft:wool 7
setblock ~59~1~26 minecraft:wool 7
setblock ~61~1~26 minecraft:wool 7
setblock ~62~9~26 minecraft:quartz_block 0
setblock ~62~20~26 minecraft:quartz_block 0
setblock ~63~1~26 minecraft:wool 7
setblock ~63~9~26 minecraft:wool 7
setblock ~63~20~26 minecraft:wool 7
setblock ~64~9~26 minecraft:stained_glass 8
setblock ~64~20~26 minecraft:stained_glass 8
setblock ~65~9~26 minecraft:diamond_block
setblock ~65~20~26 minecraft:diamond_block
setblock ~66~9~26 minecraft:stained_glass 8
setblock ~66~20~26 minecraft:stained_glass 8
setblock ~67~9~26 minecraft:wool 7
setblock ~67~20~26 minecraft:wool 7
setblock ~2~8~27 minecraft:wool 7
setblock ~2~21~27 minecraft:wool 7
setblock ~3~8~27 minecraft:stained_glass 8
setblock ~3~21~27 minecraft:stained_glass 8
setblock ~4~8~27 minecraft:diamond_block
setblock ~4~21~27 minecraft:diamond_block
setblock ~5~8~27 minecraft:stained_glass 8
setblock ~5~21~27 minecraft:stained_glass 8
setblock ~6~1~27 minecraft:wool 15
setblock ~6~8~27 minecraft:wool 7
setblock ~6~21~27 minecraft:wool 7
setblock ~7~8~27 minecraft:quartz_block 0
setblock ~7~21~27 minecraft:quartz_block 0
setblock ~8~1~27 minecraft:wool 15
setblock ~10~1~27 minecraft:wool 15
setblock ~12~1~27 minecraft:wool 15
setblock ~14~1~27 minecraft:wool 15
setblock ~16~1~27 minecraft:wool 15
setblock ~18~1~27 minecraft:wool 15
setblock ~20~1~27 minecraft:wool 15
fill ~20~4~27 ~20~4~28 minecraft:quartz_block 0
setblock ~22~1~27 minecraft:wool 15
fill ~23~4~27 ~23~4~28 minecraft:quartz_block 0
setblock ~24~1~27 minecraft:wool 15
setblock ~26~1~27 minecraft:wool 15
fill ~28~0~27 ~28~0~62 minecraft:dirt 0
fill ~28~1~27 ~28~1~28 minecraft:diamond_block
fill ~29~0~27 ~30~0~28 minecraft:glowstone
fill ~29~1~27 ~30~1~28 minecraft:stained_glass 8
fill ~33~1~27 ~33~1~30 minecraft:quartz_block 0
fill ~36~1~27 ~36~1~30 minecraft:quartz_block 0
fill ~39~0~27 ~40~0~28 minecraft:glowstone
fill ~39~1~27 ~40~1~28 minecraft:stained_glass 8
fill ~41~0~27 ~41~0~62 minecraft:dirt 0
fill ~41~1~27 ~41~1~28 minecraft:diamond_block
setblock ~43~1~27 minecraft:wool 15
setblock ~45~1~27 minecraft:wool 15
fill ~46~4~27 ~46~4~28 minecraft:quartz_block 0
setblock ~47~1~27 minecraft:wool 15
setblock ~49~1~27 minecraft:wool 15
fill ~49~4~27 ~49~4~28 minecraft:quartz_block 0
setblock ~51~1~27 minecraft:wool 15
setblock ~53~1~27 minecraft:wool 15
setblock ~55~1~27 minecraft:wool 15
setblock ~57~1~27 minecraft:wool 15
setblock ~59~1~27 minecraft:wool 15
setblock ~61~1~27 minecraft:wool 15
setblock ~62~8~27 minecraft:quartz_block 0
setblock ~62~21~27 minecraft:quartz_block 0
setblock ~63~1~27 minecraft:wool 15
setblock ~63~8~27 minecraft:wool 7
setblock ~63~21~27 minecraft:wool 7
setblock ~64~8~27 minecraft:stained_glass 8
setblock ~64~21~27 minecraft:stained_glass 8
setblock ~65~8~27 minecraft:diamond_block
setblock ~65~21~27 minecraft:diamond_block
setblock ~66~8~27 minecraft:stained_glass 8
setblock ~66~21~27 minecraft:stained_glass 8
setblock ~67~8~27 minecraft:wool 7
setblock ~67~21~27 minecraft:wool 7
fill ~2~7~28 ~2~7~29 minecraft:wool 7
fill ~2~22~28 ~2~22~29 minecraft:wool 7
fill ~3~7~28 ~3~7~29 minecraft:stained_glass 8
fill ~3~15~28 ~5~15~28 minecraft:glowstone
fill ~3~22~28 ~3~22~29 minecraft:stained_glass 8
fill ~4~7~28 ~4~7~29 minecraft:diamond_block
setblock ~4~14~28 minecraft:glowstone
fill ~4~22~28 ~4~22~29 minecraft:diamond_block
fill ~5~7~28 ~5~7~29 minecraft:stained_glass 8
fill ~5~22~28 ~5~22~29 minecraft:stained_glass 8
setblock ~6~1~28 minecraft:wool 7
fill ~6~7~28 ~6~7~29 minecraft:wool 7
fill ~6~22~28 ~6~22~29 minecraft:wool 7
fill ~7~7~28 ~7~7~29 minecraft:quartz_block 0
fill ~7~22~28 ~7~22~29 minecraft:quartz_block 0
setblock ~8~1~28 minecraft:wool 7
setblock ~10~1~28 minecraft:wool 7
setblock ~12~1~28 minecraft:wool 7
setblock ~14~1~28 minecraft:wool 7
setblock ~16~1~28 minecraft:wool 7
setblock ~18~1~28 minecraft:wool 7
setblock ~20~1~28 minecraft:wool 7
fill ~20~3~28 ~20~3~29 minecraft:quartz_block 0
fill ~21~4~28 ~22~4~28 minecraft:quartz_stairs 3
setblock ~22~1~28 minecraft:wool 7
fill ~23~3~28 ~23~3~29 minecraft:quartz_block 0
setblock ~24~1~28 minecraft:wool 7
setblock ~26~1~28 minecraft:wool 7
fill ~34~0~28 ~35~0~29 minecraft:glowstone
fill ~34~1~28 ~35~1~29 minecraft:stained_glass 8
setblock ~43~1~28 minecraft:wool 7
setblock ~45~1~28 minecraft:wool 7
fill ~46~3~28 ~46~3~29 minecraft:quartz_block 0
setblock ~47~1~28 minecraft:wool 7
fill ~47~4~28 ~48~4~28 minecraft:quartz_stairs 3
setblock ~49~1~28 minecraft:wool 7
fill ~49~3~28 ~49~3~29 minecraft:quartz_block 0
setblock ~51~1~28 minecraft:wool 7
setblock ~53~1~28 minecraft:wool 7
setblock ~55~1~28 minecraft:wool 7
setblock ~57~1~28 minecraft:wool 7
setblock ~59~1~28 minecraft:wool 7
setblock ~61~1~28 minecraft:wool 7
fill ~62~7~28 ~62~7~29 minecraft:quartz_block 0
fill ~62~22~28 ~62~22~29 minecraft:quartz_block 0
setblock ~63~1~28 minecraft:wool 7
fill ~63~7~28 ~63~7~29 minecraft:wool 7
fill ~63~22~28 ~63~22~29 minecraft:wool 7
fill ~64~7~28 ~64~7~29 minecraft:stained_glass 8
fill ~64~15~28 ~66~15~28 minecraft:glowstone
fill ~64~22~28 ~64~22~29 minecraft:stained_glass 8
fill ~65~7~28 ~65~7~29 minecraft:diamond_block
setblock ~65~14~28 minecraft:glowstone
fill ~65~22~28 ~65~22~29 minecraft:diamond_block
fill ~66~7~28 ~66~7~29 minecraft:stained_glass 8
fill ~66~22~28 ~66~22~29 minecraft:stained_glass 8
fill ~67~7~28 ~67~7~29 minecraft:wool 7
fill ~67~22~28 ~67~22~29 minecraft:wool 7
fill ~4~0~29 ~4~0~36 minecraft:dirt 0
setblock ~4~1~29 minecraft:quartz_block 0
fill ~4~15~29 ~4~15~31 minecraft:glowstone
setblock ~6~1~29 minecraft:wool 15
setblock ~8~1~29 minecraft:wool 15
setblock ~10~1~29 minecraft:wool 15
setblock ~12~1~29 minecraft:wool 15
setblock ~14~1~29 minecraft:wool 15
setblock ~16~1~29 minecraft:wool 15
setblock ~18~1~29 minecraft:wool 15
setblock ~20~1~29 minecraft:wool 15
setblock ~20~2~29 minecraft:quartz_block 0
fill ~21~2~29 ~22~2~29 minecraft:glowstone
fill ~21~3~29 ~22~3~29 minecraft:quartz_stairs 3
setblock ~22~1~29 minecraft:wool 15
setblock ~23~2~29 minecraft:quartz_block 0
setblock ~24~1~29 minecraft:wool 15
setblock ~26~1~29 minecraft:wool 15
fill ~28~1~29 ~30~1~29 minecraft:wool 15
fill ~29~0~29 ~30~0~31 minecraft:dirt 0
fill ~39~0~29 ~40~0~31 minecraft:dirt 0
fill ~39~1~29 ~41~1~29 minecraft:wool 15
setblock ~43~1~29 minecraft:wool 15
setblock ~45~1~29 minecraft:wool 15
setblock ~46~2~29 minecraft:quartz_block 0
setblock ~47~1~29 minecraft:wool 15
fill ~47~2~29 ~48~2~29 minecraft:glowstone
fill ~47~3~29 ~48~3~29 minecraft:quartz_stairs 3
setblock ~49~1~29 minecraft:wool 15
setblock ~49~2~29 minecraft:quartz_block 0
setblock ~51~1~29 minecraft:wool 15
setblock ~53~1~29 minecraft:wool 15
setblock ~55~1~29 minecraft:wool 15
setblock ~57~1~29 minecraft:wool 15
setblock ~59~1~29 minecraft:wool 15
setblock ~61~1~29 minecraft:wool 15
setblock ~63~1~29 minecraft:wool 15
fill ~65~0~29 ~65~0~36 minecraft:dirt 0
setblock ~65~1~29 minecraft:quartz_block 0
fill ~65~15~29 ~65~15~31 minecraft:glowstone
fill ~2~6~30 ~2~6~35 minecraft:wool 7
fill ~2~23~30 ~2~23~35 minecraft:wool 7
fill ~3~1~30 ~31~1~30 minecraft:wool 7
fill ~3~6~30 ~3~6~35 minecraft:stained_glass 8
fill ~3~23~30 ~3~23~35 minecraft:stained_glass 8
fill ~4~6~30 ~4~6~35 minecraft:diamond_block
fill ~4~12~30 ~4~12~35 minecraft:glowstone
fill ~4~17~30 ~4~17~35 minecraft:glowstone
fill ~4~23~30 ~4~23~35 minecraft:diamond_block
fill ~5~6~30 ~5~6~35 minecraft:stained_glass 8
fill ~5~23~30 ~5~23~35 minecraft:stained_glass 8
fill ~6~6~30 ~6~6~35 minecraft:wool 7
fill ~6~23~30 ~6~23~35 minecraft:wool 7
fill ~7~6~30 ~7~6~35 minecraft:quartz_block 0
fill ~7~23~30 ~7~23~35 minecraft:quartz_block 0
fill ~20~2~30 ~23~2~30 minecraft:quartz_stairs 3
fill ~34~0~30 ~35~0~35 minecraft:dirt 0
fill ~34~1~30 ~35~1~31 minecraft:quartz_block 0
fill ~38~1~30 ~66~1~30 minecraft:wool 7
fill ~46~2~30 ~49~2~30 minecraft:quartz_stairs 3
fill ~62~6~30 ~62~6~35 minecraft:quartz_block 0
fill ~62~23~30 ~62~23~35 minecraft:quartz_block 0
fill ~63~6~30 ~63~6~35 minecraft:wool 7
fill ~63~23~30 ~63~23~35 minecraft:wool 7
fill ~64~6~30 ~64~6~35 minecraft:stained_glass 8
fill ~64~23~30 ~64~23~35 minecraft:stained_glass 8
fill ~65~6~30 ~65~6~35 minecraft:diamond_block
fill ~65~12~30 ~65~12~35 minecraft:glowstone
fill ~65~17~30 ~65~17~35 minecraft:glowstone
fill ~65~23~30 ~65~23~35 minecraft:diamond_block
fill ~66~6~30 ~66~6~35 minecraft:stained_glass 8
fill ~66~23~30 ~66~23~35 minecraft:stained_glass 8
fill ~67~6~30 ~67~6~35 minecraft:wool 7
fill ~67~23~30 ~67~23~35 minecraft:wool 7
fill ~2~1~31 ~27~1~31 minecraft:quartz_block 0
setblock ~3~12~31 minecraft:glowstone
setblock ~3~17~31 minecraft:glowstone
fill ~4~7~31 ~4~10~31 minecraft:nether_brick_fence
setblock ~4~11~31 minecraft:glowstone
fill ~4~13~31 ~4~14~31 minecraft:glowstone
setblock ~4~16~31 minecraft:glowstone
setblock ~4~18~31 minecraft:glowstone
fill ~4~19~31 ~4~22~31 minecraft:nether_brick_fence
setblock ~5~12~31 minecraft:glowstone
setblock ~5~17~31 minecraft:glowstone
setblock ~28~1~31 minecraft:diamond_block
fill ~29~1~31 ~32~1~31 minecraft:quartz_block 0
setblock ~33~1~31 minecraft:diamond_block
fill ~34~2~31 ~35~2~31 minecraft:quartz_stairs 2
setblock ~36~1~31 minecraft:diamond_block
fill ~37~1~31 ~40~1~31 minecraft:quartz_block 0
setblock ~41~1~31 minecraft:diamond_block
fill ~42~1~31 ~67~1~31 minecraft:quartz_block 0
setblock ~64~12~31 minecraft:glowstone
setblock ~64~17~31 minecraft:glowstone
fill ~65~7~31 ~65~10~31 minecraft:nether_brick_fence
setblock ~65~11~31 minecraft:glowstone
fill ~65~13~31 ~65~14~31 minecraft:glowstone
setblock ~65~16~31 minecraft:glowstone
setblock ~65~18~31 minecraft:glowstone
fill ~65~19~31 ~65~22~31 minecraft:nether_brick_fence
setblock ~66~12~31 minecraft:glowstone
setblock ~66~17~31 minecraft:glowstone
fill ~2~0~32 ~2~1~33 minecraft:quartz_block 0
fill ~3~0~32 ~3~0~65 minecraft:dirt 0
fill ~3~1~32 ~4~1~34 minecraft:quartz_block 0
fill ~5~0~32 ~6~0~33 minecraft:glowstone
fill ~5~1~32 ~6~1~33 minecraft:stained_glass 8
fill ~7~0~32 ~7~1~33 minecraft:quartz_block 0
fill ~8~1~32 ~9~1~34 minecraft:quartz_block 0
fill ~10~0~32 ~11~0~33 minecraft:glowstone
fill ~10~1~32 ~11~1~33 minecraft:stained_glass 8
fill ~12~0~32 ~12~1~33 minecraft:quartz_block 0
fill ~13~0~32 ~14~0~65 minecraft:dirt 0
fill ~13~1~32 ~14~1~34 minecraft:quartz_block 0
fill ~15~0~32 ~16~0~33 minecraft:glowstone
fill ~15~1~32 ~16~1~33 minecraft:stained_glass 8
fill ~17~0~32 ~17~1~33 minecraft:quartz_block 0
fill ~18~1~32 ~19~1~34 minecraft:quartz_block 0
fill ~20~0~32 ~21~0~33 minecraft:glowstone
fill ~20~1~32 ~21~1~33 minecraft:stained_glass 8
fill ~22~0~32 ~22~1~33 minecraft:quartz_block 0
fill ~23~1~32 ~24~1~34 minecraft:quartz_block 0
fill ~25~0~32 ~26~0~33 minecraft:glowstone
fill ~25~1~32 ~26~1~33 minecraft:stained_glass 8
fill ~27~0~32 ~27~1~33 minecraft:quartz_block 0
fill ~28~1~32 ~29~1~33 minecraft:quartz_block 0
fill ~29~0~32 ~29~0~36 minecraft:dirt 0
fill ~30~0~32 ~31~0~33 minecraft:glowstone
fill ~30~1~32 ~31~1~33 minecraft:stained_glass 8
fill ~32~0~32 ~33~0~65 minecraft:dirt 0
fill ~32~1~32 ~33~1~33 minecraft:quartz_block 0
fill ~33~2~32 ~33~2~33 minecraft:quartz_stairs 0
fill ~34~1~32 ~35~2~33 minecraft:diamond_block
fill ~36~0~32 ~37~0~65 minecraft:dirt 0
fill ~36~1~32 ~37~1~33 minecraft:quartz_block 0
fill ~36~2~32 ~36~2~33 minecraft:quartz_stairs 1
fill ~38~0~32 ~39~0~33 minecraft:glowstone
fill ~38~1~32 ~39~1~33 minecraft:stained_glass 8
fill ~40~0~32 ~40~0~36 minecraft:dirt 0
fill ~40~1~32 ~42~1~33 minecraft:quartz_block 0
fill ~42~0~32 ~42~0~33 minecraft:quartz_block 0
fill ~43~0~32 ~44~0~33 minecraft:glowstone
fill ~43~1~32 ~44~1~33 minecraft:stained_glass 8
fill ~45~1~32 ~47~1~34 minecraft:quartz_block 0
fill ~47~0~32 ~47~0~33 minecraft:quartz_block 0
fill ~48~0~32 ~49~0~33 minecraft:glowstone
fill ~48~1~32 ~49~1~33 minecraft:stained_glass 8
fill ~50~1~32 ~52~1~34 minecraft:quartz_block 0
fill ~52~0~32 ~52~0~33 minecraft:quartz_block 0
fill ~53~0~32 ~54~0~33 minecraft:glowstone
fill ~53~1~32 ~54~1~33 minecraft:stained_glass 8
fill ~55~0~32 ~56~0~65 minecraft:dirt 0
fill ~55~1~32 ~57~1~34 minecraft:quartz_block 0
fill ~57~0~32 ~57~0~33 minecraft:quartz_block 0
fill ~58~0~32 ~59~0~33 minecraft:glowstone
fill ~58~1~32 ~59~1~33 minecraft:stained_glass 8
fill ~60~1~32 ~62~1~34 minecraft:quartz_block 0
fill ~62~0~32 ~62~0~33 minecraft:quartz_block 0
fill ~63~0~32 ~64~0~33 minecraft:glowstone
fill ~63~1~32 ~64~1~33 minecraft:stained_glass 8
fill ~65~1~32 ~67~1~34 minecraft:quartz_block 0
fill ~66~0~32 ~66~0~65 minecraft:dirt 0
fill ~67~0~32 ~67~0~33 minecraft:quartz_block 0
fill ~2~0~34 ~2~0~65 minecraft:dirt 0
setblock ~2~1~34 minecraft:quartz_block 0
setblock ~3~12~34 minecraft:glowstone
setblock ~3~17~34 minecraft:glowstone
fill ~4~7~34 ~4~10~34 minecraft:nether_brick_fence
setblock ~4~11~34 minecraft:glowstone
fill ~4~13~34 ~4~16~34 minecraft:glowstone
setblock ~4~18~34 minecraft:glowstone
fill ~4~19~34 ~4~22~34 minecraft:nether_brick_fence
fill ~5~0~34 ~7~0~60 minecraft:dirt 0
fill ~5~1~34 ~7~1~34 minecraft:quartz_block 0
setblock ~5~12~34 minecraft:glowstone
setblock ~5~17~34 minecraft:glowstone
fill ~10~0~34 ~12~0~55 minecraft:dirt 0
fill ~10~1~34 ~12~1~34 minecraft:quartz_block 0
fill ~15~0~34 ~17~0~49 minecraft:dirt 0
fill ~15~1~34 ~17~1~34 minecraft:quartz_block 0
fill ~20~0~34 ~22~0~44 minecraft:dirt 0
fill ~20~1~34 ~22~1~34 minecraft:quartz_block 0
fill ~25~0~34 ~27~0~39 minecraft:dirt 0
fill ~25~1~34 ~27~1~34 minecraft:quartz_block 0
setblock ~28~1~34 minecraft:diamond_block
fill ~29~1~34 ~32~1~34 minecraft:quartz_block 0
fill ~30~0~34 ~31~0~36 minecraft:dirt 0
setblock ~33~1~34 minecraft:diamond_block
fill ~34~1~34 ~35~1~35 minecraft:quartz_block 0
fill ~34~2~34 ~35~2~34 minecraft:quartz_stairs 3
setblock ~36~1~34 minecraft:diamond_block
fill ~37~1~34 ~40~1~34 minecraft:quartz_block 0
fill ~38~0~34 ~39~0~36 minecraft:dirt 0
setblock ~41~1~34 minecraft:diamond_block
fill ~42~0~34 ~44~0~39 minecraft:dirt 0
fill ~42~1~34 ~44~1~34 minecraft:quartz_block 0
fill ~47~0~34 ~49~0~44 minecraft:dirt 0
fill ~48~1~34 ~49~1~34 minecraft:quartz_block 0
fill ~52~0~34 ~54~0~49 minecraft:dirt 0
fill ~53~1~34 ~54~1~34 minecraft:quartz_block 0
fill ~57~0~34 ~59~0~55 minecraft:dirt 0
fill ~58~1~34 ~59~1~34 minecraft:quartz_block 0
fill ~62~0~34 ~64~0~60 minecraft:dirt 0
fill ~63~1~34 ~64~1~34 minecraft:quartz_block 0
setblock ~64~12~34 minecraft:glowstone
setblock ~64~17~34 minecraft:glowstone
fill ~65~7~34 ~65~10~34 minecraft:nether_brick_fence
setblock ~65~11~34 minecraft:glowstone
fill ~65~13~34 ~65~16~34 minecraft:glowstone
setblock ~65~18~34 minecraft:glowstone
fill ~65~19~34 ~65~22~34 minecraft:nether_brick_fence
setblock ~66~12~34 minecraft:glowstone
setblock ~66~17~34 minecraft:glowstone
fill ~67~0~34 ~67~0~65 minecraft:dirt 0
fill ~2~1~35 ~32~1~35 minecraft:wool 7
fill ~4~15~35 ~4~15~37 minecraft:glowstone
fill ~20~2~35 ~23~2~35 minecraft:quartz_stairs 2
fill ~33~1~35 ~33~1~38 minecraft:quartz_block 0
fill ~36~1~35 ~36~1~38 minecraft:quartz_block 0
fill ~37~1~35 ~67~1~35 minecraft:wool 7
fill ~46~2~35 ~49~2~35 minecraft:quartz_stairs 2
fill ~65~15~35 ~65~15~37 minecraft:glowstone
fill ~2~1~36 ~2~1~65 minecraft:wool 7
fill ~2~7~36 ~2~7~37 minecraft:wool 7
fill ~2~22~36 ~2~22~37 minecraft:wool 7
fill ~3~1~36 ~5~1~36 minecraft:quartz_block 0
fill ~3~7~36 ~3~7~37 minecraft:stained_glass 8
fill ~3~22~36 ~3~22~37 minecraft:stained_glass 8
fill ~4~7~36 ~4~7~37 minecraft:diamond_block
fill ~4~22~36 ~4~22~37 minecraft:diamond_block
fill ~5~7~36 ~5~7~37 minecraft:stained_glass 8
fill ~5~22~36 ~5~22~37 minecraft:stained_glass 8
fill ~6~1~36 ~31~1~36 minecraft:wool 15
fill ~6~7~36 ~6~7~37 minecraft:wool 7
fill ~6~22~36 ~6~22~37 minecraft:wool 7
fill ~7~7~36 ~7~7~37 minecraft:quartz_block 0
fill ~7~22~36 ~7~22~37 minecraft:quartz_block 0
fill ~20~2~36 ~20~3~36 minecraft:quartz_block 0
fill ~21~2~36 ~22~2~36 minecraft:glowstone
fill ~21~3~36 ~22~3~36 minecraft:quartz_stairs 2
fill ~23~2~36 ~23~3~36 minecraft:quartz_block 0
fill ~32~1~36 ~32~1~65 minecraft:wool 7
fill ~34~0~36 ~35~0~37 minecraft:glowstone
fill ~34~1~36 ~35~1~37 minecraft:stained_glass 8
fill ~37~1~36 ~37~1~65 minecraft:wool 7
fill ~38~1~36 ~63~1~36 minecraft:wool 15
fill ~46~2~36 ~46~3~36 minecraft:quartz_block 0
fill ~47~2~36 ~48~2~36 minecraft:glowstone
fill ~47~3~36 ~48~3~36 minecraft:quartz_stairs 2
fill ~49~2~36 ~49~3~36 minecraft:quartz_block 0
fill ~62~7~36 ~62~7~37 minecraft:quartz_block 0
fill ~62~22~36 ~62~22~37 minecraft:quartz_block 0
fill ~63~7~36 ~63~7~37 minecraft:wool 7
fill ~63~22~36 ~63~22~37 minecraft:wool 7
fill ~64~1~36 ~66~1~36 minecraft:quartz_block 0
fill ~64~7~36 ~64~7~37 minecraft:stained_glass 8
fill ~64~22~36 ~64~22~37 minecraft:stained_glass 8
fill ~65~7~36 ~65~7~37 minecraft:diamond_block
fill ~65~22~36 ~65~22~37 minecraft:diamond_block
fill ~66~7~36 ~66~7~37 minecraft:stained_glass 8
fill ~66~22~36 ~66~22~37 minecraft:stained_glass 8
fill ~67~1~36 ~67~1~65 minecraft:wool 7
fill ~67~7~36 ~67~7~37 minecraft:wool 7
fill ~67~22~36 ~67~22~37 minecraft:wool 7
fill ~3~1~37 ~3~1~46 minecraft:quartz_block 0
setblock ~3~15~37 minecraft:glowstone
fill ~4~0~37 ~4~0~48 minecraft:glowstone
fill ~4~1~37 ~4~1~48 minecraft:stained_glass 8
setblock ~4~14~37 minecraft:glowstone
fill ~5~1~37 ~5~1~46 minecraft:quartz_block 0
setblock ~5~15~37 minecraft:glowstone
setblock ~6~1~37 minecraft:wool 7
fill ~7~1~37 ~7~1~59 minecraft:wool 15
setblock ~8~1~37 minecraft:wool 7
fill ~9~1~37 ~9~1~57 minecraft:wool 15
setblock ~10~1~37 minecraft:wool 7
fill ~11~1~37 ~11~1~55 minecraft:wool 15
setblock ~12~1~37 minecraft:wool 7
fill ~13~1~37 ~13~1~53 minecraft:wool 15
setblock ~14~1~37 minecraft:wool 7
fill ~15~1~37 ~15~1~51 minecraft:wool 15
setblock ~16~1~37 minecraft:wool 7
fill ~17~1~37 ~17~1~49 minecraft:wool 15
setblock ~18~1~37 minecraft:wool 7
fill ~19~1~37 ~19~1~47 minecraft:wool 15
setblock ~20~1~37 minecraft:wool 7
fill ~20~3~37 ~20~4~37 minecraft:quartz_block 0
fill ~21~1~37 ~21~1~45 minecraft:wool 15
fill ~21~4~37 ~22~4~37 minecraft:quartz_stairs 2
setblock ~22~1~37 minecraft:wool 7
fill ~23~1~37 ~23~1~43 minecraft:wool 15
fill ~23~3~37 ~23~4~37 minecraft:quartz_block 0
setblock ~24~1~37 minecraft:wool 7
fill ~25~1~37 ~25~1~41 minecraft:wool 15
setblock ~26~1~37 minecraft:wool 7
fill ~27~1~37 ~27~1~39 minecraft:wool 15
fill ~28~1~37 ~28~1~39 minecraft:diamond_block
fill ~29~0~37 ~30~0~38 minecraft:glowstone
fill ~29~1~37 ~30~1~38 minecraft:stained_glass 8
fill ~31~0~37 ~31~0~65 minecraft:dirt 0
fill ~31~1~37 ~31~1~61 minecraft:wool 15
fill ~38~0~37 ~38~0~65 minecraft:dirt 0
fill ~38~1~37 ~38~1~61 minecraft:wool 15
fill ~39~0~37 ~40~0~38 minecraft:glowstone
fill ~39~1~37 ~40~1~38 minecraft:stained_glass 8
fill ~41~1~37 ~41~1~39 minecraft:diamond_block
fill ~42~1~37 ~42~1~39 minecraft:wool 15
setblock ~43~1~37 minecraft:wool 7
fill ~44~1~37 ~44~1~41 minecraft:wool 15
setblock ~45~1~37 minecraft:wool 7
fill ~46~1~37 ~46~1~43 minecraft:wool 15
fill ~46~3~37 ~46~4~37 minecraft:quartz_block 0
setblock ~47~1~37 minecraft:wool 7
fill ~47~4~37 ~48~4~37 minecraft:quartz_stairs 2
fill ~48~1~37 ~48~1~45 minecraft:wool 15
setblock ~49~1~37 minecraft:wool 7
fill ~49~3~37 ~49~4~37 minecraft:quartz_block 0
fill ~50~1~37 ~50~1~47 minecraft:wool 15
setblock ~51~1~37 minecraft:wool 7
fill ~52~1~37 ~52~1~49 minecraft:wool 15
setblock ~53~1~37 minecraft:wool 7
fill ~54~1~37 ~54~1~51 minecraft:wool 15
setblock ~55~1~37 minecraft:wool 7
fill ~56~1~37 ~56~1~53 minecraft:wool 15
setblock ~57~1~37 minecraft:wool 7
fill ~58~1~37 ~58~1~55 minecraft:wool 15
setblock ~59~1~37 minecraft:wool 7
fill ~60~1~37 ~60~1~57 minecraft:wool 15
setblock ~61~1~37 minecraft:wool 7
fill ~62~1~37 ~62~1~59 minecraft:wool 15
setblock ~63~1~37 minecraft:wool 7
fill ~64~1~37 ~64~1~46 minecraft:quartz_block 0
setblock ~64~15~37 minecraft:glowstone
fill ~65~0~37 ~65~0~48 minecraft:glowstone
fill ~65~1~37 ~65~1~48 minecraft:stained_glass 8
setblock ~65~14~37 minecraft:glowstone
fill ~66~1~37 ~66~1~46 minecraft:quartz_block 0
setblock ~66~15~37 minecraft:glowstone
setblock ~2~8~38 minecraft:wool 7
setblock ~2~21~38 minecraft:wool 7
setblock ~3~8~38 minecraft:stained_glass 8
setblock ~3~21~38 minecraft:stained_glass 8
setblock ~4~8~38 minecraft:diamond_block
setblock ~4~21~38 minecraft:diamond_block
setblock ~5~8~38 minecraft:stained_glass 8
setblock ~5~21~38 minecraft:stained_glass 8
setblock ~6~1~38 minecraft:wool 15
setblock ~6~8~38 minecraft:wool 7
setblock ~6~21~38 minecraft:wool 7
setblock ~7~8~38 minecraft:quartz_block 0
setblock ~7~21~38 minecraft:quartz_block 0
setblock ~8~1~38 minecraft:wool 15
setblock ~10~1~38 minecraft:wool 15
setblock ~12~1~38 minecraft:wool 15
setblock ~14~1~38 minecraft:wool 15
setblock ~16~1~38 minecraft:wool 15
setblock ~18~1~38 minecraft:wool 15
setblock ~20~1~38 minecraft:wool 15
fill ~20~4~38 ~20~5~38 minecraft:quartz_block 0
fill ~21~4~38 ~22~4~46 minecraft:stained_glass 8
setblock ~22~1~38 minecraft:wool 15
fill ~23~4~38 ~23~5~38 minecraft:quartz_block 0
setblock ~24~1~38 minecraft:wool 15
setblock ~26~1~38 minecraft:wool 15
fill ~34~0~38 ~35~0~39 minecraft:dirt 0
fill ~34~1~38 ~35~1~40 minecraft:quartz_block 0
setblock ~43~1~38 minecraft:wool 15
setblock ~45~1~38 minecraft:wool 15
fill ~46~4~38 ~46~5~38 minecraft:quartz_block 0
setblock ~47~1~38 minecraft:wool 15
fill ~47~4~38 ~48~4~46 minecraft:stained_glass 8
setblock ~49~1~38 minecraft:wool 15
fill ~49~4~38 ~49~5~38 minecraft:quartz_block 0
setblock ~51~1~38 minecraft:wool 15
setblock ~53~1~38 minecraft:wool 15
setblock ~55~1~38 minecraft:wool 15
setblock ~57~1~38 minecraft:wool 15
setblock ~59~1~38 minecraft:wool 15
setblock ~61~1~38 minecraft:wool 15
setblock ~62~8~38 minecraft:quartz_block 0
setblock ~62~21~38 minecraft:quartz_block 0
setblock ~63~1~38 minecraft:wool 15
setblock ~63~8~38 minecraft:wool 7
setblock ~63~21~38 minecraft:wool 7
setblock ~64~8~38 minecraft:stained_glass 8
setblock ~64~21~38 minecraft:stained_glass 8
setblock ~65~8~38 minecraft:diamond_block
setblock ~65~21~38 minecraft:diamond_block
setblock ~66~8~38 minecraft:stained_glass 8
setblock ~66~21~38 minecraft:stained_glass 8
setblock ~67~8~38 minecraft:wool 7
setblock ~67~21~38 minecraft:wool 7
setblock ~2~9~39 minecraft:wool 7
setblock ~2~20~39 minecraft:wool 7
setblock ~3~9~39 minecraft:stained_glass 8
setblock ~3~20~39 minecraft:stained_glass 8
setblock ~4~9~39 minecraft:diamond_block
setblock ~4~20~39 minecraft:diamond_block
setblock ~5~9~39 minecraft:stained_glass 8
setblock ~5~20~39 minecraft:stained_glass 8
setblock ~6~1~39 minecraft:wool 7
setblock ~6~9~39 minecraft:wool 7
setblock ~6~20~39 minecraft:wool 7
setblock ~7~9~39 minecraft:quartz_block 0
setblock ~7~20~39 minecraft:quartz_block 0
setblock ~8~1~39 minecraft:wool 7
setblock ~10~1~39 minecraft:wool 7
setblock ~12~1~39 minecraft:wool 7
setblock ~14~1~39 minecraft:wool 7
setblock ~16~1~39 minecraft:wool 7
setblock ~18~1~39 minecraft:wool 7
setblock ~20~1~39 minecraft:wool 7
fill ~20~5~39 ~20~5~47 minecraft:quartz_block 0
setblock ~22~1~39 minecraft:wool 7
fill ~23~5~39 ~23~5~44 minecraft:quartz_block 0
setblock ~24~1~39 minecraft:wool 7
setblock ~26~1~39 minecraft:wool 7
fill ~29~0~39 ~30~0~62 minecraft:dirt 0
fill ~29~1~39 ~30~1~39 minecraft:diamond_block
setblock ~33~1~39 minecraft:diamond_block
setblock ~36~1~39 minecraft:diamond_block
fill ~39~0~39 ~40~0~62 minecraft:dirt 0
fill ~39~1~39 ~40~1~39 minecraft:diamond_block
setblock ~43~1~39 minecraft:wool 7
setblock ~45~1~39 minecraft:wool 7
fill ~46~5~39 ~46~5~44 minecraft:quartz_block 0
setblock ~47~1~39 minecraft:wool 7
setblock ~49~1~39 minecraft:wool 7
fill ~49~5~39 ~49~5~47 minecraft:quartz_block 0
setblock ~51~1~39 minecraft:wool 7
setblock ~53~1~39 minecraft:wool 7
setblock ~55~1~39 minecraft:wool 7
setblock ~57~1~39 minecraft:wool 7
setblock ~59~1~39 minecraft:wool 7
setblock ~61~1~39 minecraft:wool 7
setblock ~62~9~39 minecraft:quartz_block 0
setblock ~62~20~39 minecraft:quartz_block 0
setblock ~63~1~39 minecraft:wool 7
setblock ~63~9~39 minecraft:wool 7
setblock ~63~20~39 minecraft:wool 7
setblock ~64~9~39 minecraft:stained_glass 8
setblock ~64~20~39 minecraft:stained_glass 8
setblock ~65~9~39 minecraft:diamond_block
setblock ~65~20~39 minecraft:diamond_block
setblock ~66~9~39 minecraft:stained_glass 8
setblock ~66~20~39 minecraft:stained_glass 8
setblock ~67~9~39 minecraft:wool 7
setblock ~67~20~39 minecraft:wool 7
fill ~2~10~40 ~2~11~40 minecraft:wool 7
fill ~2~18~40 ~2~19~40 minecraft:wool 7
fill ~3~10~40 ~3~11~40 minecraft:stained_glass 8
fill ~3~18~40 ~3~19~40 minecraft:stained_glass 8
fill ~4~10~40 ~4~11~40 minecraft:diamond_block
fill ~4~18~40 ~4~19~40 minecraft:diamond_block
fill ~5~10~40 ~5~11~40 minecraft:stained_glass 8
fill ~5~18~40 ~5~19~40 minecraft:stained_glass 8
setblock ~6~1~40 minecraft:wool 15
fill ~6~10~40 ~6~11~40 minecraft:wool 7
fill ~6~18~40 ~6~19~40 minecraft:wool 7
fill ~7~10~40 ~7~11~40 minecraft:quartz_block 0
fill ~7~18~40 ~7~19~40 minecraft:quartz_block 0
setblock ~8~1~40 minecraft:wool 15
setblock ~10~1~40 minecraft:wool 15
setblock ~12~1~40 minecraft:wool 15
setblock ~14~1~40 minecraft:wool 15
setblock ~16~1~40 minecraft:wool 15
setblock ~18~1~40 minecraft:wool 15
setblock ~20~1~40 minecraft:wool 15
setblock ~22~1~40 minecraft:wool 15
setblock ~24~1~40 minecraft:wool 15
fill ~25~0~40 ~26~0~40 minecraft:dirt 0
setblock ~26~1~40 minecraft:wool 15
setblock ~27~0~40 minecraft:grass
setblock ~27~1~40 minecraft:glowstone
fill ~28~1~40 ~30~1~40 minecraft:wool 15
fill ~33~1~40 ~33~1~65 minecraft:quartz_block 0
fill ~34~0~40 ~35~0~40 minecraft:quartz_block 0
fill ~36~1~40 ~36~1~65 minecraft:quartz_block 0
fill ~39~1~40 ~41~1~40 minecraft:wool 15
setblock ~42~0~40 minecraft:grass
setblock ~42~1~40 minecraft:glowstone
fill ~43~0~40 ~44~0~40 minecraft:dirt 0
setblock ~43~1~40 minecraft:wool 15
setblock ~45~1~40 minecraft:wool 15
setblock ~47~1~40 minecraft:wool 15
setblock ~49~1~40 minecraft:wool 15
setblock ~51~1~40 minecraft:wool 15
setblock ~53~1~40 minecraft:wool 15
setblock ~55~1~40 minecraft:wool 15
setblock ~57~1~40 minecraft:wool 15
setblock ~59~1~40 minecraft:wool 15
setblock ~61~1~40 minecraft:wool 15
fill ~62~10~40 ~62~11~40 minecraft:quartz_block 0
fill ~62~18~40 ~62~19~40 minecraft:quartz_block 0
setblock ~63~1~40 minecraft:wool 15
fill ~63~10~40 ~63~11~40 minecraft:wool 7
fill ~63~18~40 ~63~19~40 minecraft:wool 7
fill ~64~10~40 ~64~11~40 minecraft:stained_glass 8
fill ~64~18~40 ~64~19~40 minecraft:stained_glass 8
fill ~65~10~40 ~65~11~40 minecraft:diamond_block
fill ~65~18~40 ~65~19~40 minecraft:diamond_block
fill ~66~10~40 ~66~11~40 minecraft:stained_glass 8
fill ~66~18~40 ~66~19~40 minecraft:stained_glass 8
fill ~67~10~40 ~67~11~40 minecraft:wool 7
fill ~67~18~40 ~67~19~40 minecraft:wool 7
fill ~2~12~41 ~2~17~41 minecraft:wool 7
fill ~3~12~41 ~3~17~41 minecraft:stained_glass 8
fill ~4~12~41 ~4~17~41 minecraft:diamond_block
fill ~5~12~41 ~5~17~41 minecraft:stained_glass 8
setblock ~6~1~41 minecraft:wool 7
fill ~6~12~41 ~6~17~41 minecraft:wool 7
fill ~7~12~41 ~7~17~41 minecraft:quartz_block 0
setblock ~8~1~41 minecraft:wool 7
setblock ~10~1~41 minecraft:wool 7
setblock ~12~1~41 minecraft:wool 7
setblock ~14~1~41 minecraft:wool 7
setblock ~16~1~41 minecraft:wool 7
setblock ~18~1~41 minecraft:wool 7
setblock ~20~1~41 minecraft:wool 7
setblock ~22~1~41 minecraft:wool 7
setblock ~24~1~41 minecraft:wool 7
setblock ~25~0~41 minecraft:dirt 0
setblock ~26~0~41 minecraft:grass
setblock ~26~1~41 minecraft:glowstone
fill ~27~0~41 ~27~0~62 minecraft:dirt 0
fill ~27~1~41 ~27~1~61 minecraft:wool 15
setblock ~28~1~41 minecraft:wool 7
fill ~29~1~41 ~29~1~61 minecraft:wool 15
setblock ~30~1~41 minecraft:wool 7
fill ~34~0~41 ~35~0~42 minecraft:glowstone
fill ~34~1~41 ~35~1~42 minecraft:stained_glass 8
setblock ~39~1~41 minecraft:wool 7
fill ~40~1~41 ~40~1~61 minecraft:wool 15
setblock ~41~1~41 minecraft:wool 7
fill ~42~0~41 ~42~0~62 minecraft:dirt 0
fill ~42~1~41 ~42~1~61 minecraft:wool 15
setblock ~43~0~41 minecraft:grass
setblock ~43~1~41 minecraft:glowstone
setblock ~44~0~41 minecraft:dirt 0
setblock ~45~1~41 minecraft:wool 7
setblock ~47~1~41 minecraft:wool 7
setblock ~49~1~41 minecraft:wool 7
setblock ~51~1~41 minecraft:wool 7
setblock ~53~1~41 minecraft:wool 7
setblock ~55~1~41 minecraft:wool 7
setblock ~57~1~41 minecraft:wool 7
setblock ~59~1~41 minecraft:wool 7
setblock ~61~1~41 minecraft:wool 7
fill ~62~12~41 ~62~17~41 minecraft:quartz_block 0
setblock ~63~1~41 minecraft:wool 7
fill ~63~12~41 ~63~17~41 minecraft:wool 7
fill ~64~12~41 ~64~17~41 minecraft:stained_glass 8
fill ~65~12~41 ~65~17~41 minecraft:diamond_block
fill ~66~12~41 ~66~17~41 minecraft:stained_glass 8
fill ~67~12~41 ~67~17~41 minecraft:wool 7
fill ~2~15~42 ~2~15~46 minecraft:wool 7
fill ~3~15~42 ~3~15~46 minecraft:stained_glass 8
fill ~4~15~42 ~4~15~46 minecraft:diamond_block
fill ~5~15~42 ~5~15~46 minecraft:stained_glass 8
setblock ~6~1~42 minecraft:wool 15
fill ~6~15~42 ~6~15~46 minecraft:wool 7
setblock ~7~13~42 minecraft:quartz_block 0
fill ~7~15~42 ~7~15~46 minecraft:quartz_block 0
setblock ~8~1~42 minecraft:wool 15
setblock ~10~1~42 minecraft:wool 15
setblock ~12~1~42 minecraft:wool 15
setblock ~14~1~42 minecraft:wool 15
setblock ~16~1~42 minecraft:wool 15
setblock ~18~1~42 minecraft:wool 15
setblock ~20~1~42 minecraft:wool 15
setblock ~22~1~42 minecraft:wool 15
setblock ~24~1~42 minecraft:wool 15
setblock ~25~0~42 minecraft:grass
setblock ~25~1~42 minecraft:glowstone
fill ~26~0~42 ~26~0~62 minecraft:dirt 0
setblock ~26~1~42 minecraft:wool 15
setblock ~28~1~42 minecraft:wool 15
setblock ~30~1~42 minecraft:wool 15
setblock ~39~1~42 minecraft:wool 15
setblock ~41~1~42 minecraft:wool 15
fill ~43~0~42 ~43~0~62 minecraft:dirt 0
setblock ~43~1~42 minecraft:wool 15
setblock ~44~0~42 minecraft:grass
setblock ~44~1~42 minecraft:glowstone
setblock ~45~1~42 minecraft:wool 15
setblock ~47~1~42 minecraft:wool 15
setblock ~49~1~42 minecraft:wool 15
setblock ~51~1~42 minecraft:wool 15
setblock ~53~1~42 minecraft:wool 15
setblock ~55~1~42 minecraft:wool 15
setblock ~57~1~42 minecraft:wool 15
setblock ~59~1~42 minecraft:wool 15
setblock ~61~1~42 minecraft:wool 15
setblock ~62~13~42 minecraft:quartz_block 0
fill ~62~15~42 ~62~15~46 minecraft:quartz_block 0
setblock ~63~1~42 minecraft:wool 15
fill ~63~15~42 ~63~15~46 minecraft:wool 7
fill ~64~15~42 ~64~15~46 minecraft:stained_glass 8
fill ~65~15~42 ~65~15~46 minecraft:diamond_block
fill ~66~15~42 ~66~15~46 minecraft:stained_glass 8
fill ~67~15~42 ~67~15~46 minecraft:wool 7
setblock ~6~1~43 minecraft:wool 7
setblock ~7~14~43 minecraft:quartz_block 0
setblock ~8~1~43 minecraft:wool 7
setblock ~10~1~43 minecraft:wool 7
setblock ~12~1~43 minecraft:wool 7
setblock ~14~1~43 minecraft:wool 7
setblock ~16~1~43 minecraft:wool 7
setblock ~18~1~43 minecraft:wool 7
setblock ~20~1~43 minecraft:wool 7
setblock ~22~1~43 minecraft:wool 7
setblock ~24~0~43 minecraft:grass
setblock ~24~1~43 minecraft:glowstone
fill ~25~0~43 ~25~0~62 minecraft:dirt 0
fill ~25~1~43 ~25~1~61 minecraft:wool 15
setblock ~26~1~43 minecraft:wool 7
setblock ~28~1~43 minecraft:wool 7
setblock ~30~1~43 minecraft:wool 7
fill ~34~0~43 ~35~0~44 minecraft:dirt 0
fill ~34~1~43 ~35~1~45 minecraft:quartz_block 0
setblock ~39~1~43 minecraft:wool 7
setblock ~41~1~43 minecraft:wool 7
setblock ~43~1~43 minecraft:wool 7
fill ~44~0~43 ~44~0~62 minecraft:dirt 0
fill ~44~1~43 ~44~1~61 minecraft:wool 15
setblock ~45~0~43 minecraft:grass
setblock ~45~1~43 minecraft:glowstone
setblock ~47~1~43 minecraft:wool 7
setblock ~49~1~43 minecraft:wool 7
setblock ~51~1~43 minecraft:wool 7
setblock ~53~1~43 minecraft:wool 7
setblock ~55~1~43 minecraft:wool 7
setblock ~57~1~43 minecraft:wool 7
setblock ~59~1~43 minecraft:wool 7
setblock ~61~1~43 minecraft:wool 7
setblock ~62~14~43 minecraft:quartz_block 0
setblock ~63~1~43 minecraft:wool 7
setblock ~6~1~44 minecraft:wool 15
setblock ~8~1~44 minecraft:wool 15
setblock ~10~1~44 minecraft:wool 15
setblock ~12~1~44 minecraft:wool 15
setblock ~14~1~44 minecraft:wool 15
setblock ~16~1~44 minecraft:wool 15
setblock ~18~1~44 minecraft:wool 15
setblock ~20~1~44 minecraft:wool 15
setblock ~22~1~44 minecraft:wool 15
setblock ~23~0~44 minecraft:grass
setblock ~23~1~44 minecraft:glowstone
fill ~24~0~44 ~24~0~62 minecraft:dirt 0
setblock ~24~1~44 minecraft:wool 15
fill ~24~5~44 ~29~5~44 minecraft:quartz_block 0
setblock ~26~1~44 minecraft:wool 15
setblock ~28~1~44 minecraft:wool 15
fill ~29~4~44 ~30~4~44 minecraft:quartz_block 0
setblock ~30~1~44 minecraft:wool 15
fill ~30~3~44 ~31~3~44 minecraft:quartz_block 0
setblock ~31~2~44 minecraft:quartz_block 0
fill ~32~2~44 ~32~2~47 minecraft:quartz_stairs 1
fill ~37~2~44 ~37~2~47 minecraft:quartz_stairs 0
fill ~38~2~44 ~38~3~44 minecraft:quartz_block 0
setblock ~39~1~44 minecraft:wool 15
fill ~39~3~44 ~39~4~44 minecraft:quartz_block 0
fill ~40~4~44 ~40~5~44 minecraft:quartz_block 0
setblock ~41~1~44 minecraft:wool 15
fill ~41~5~44 ~45~5~44 minecraft:quartz_block 0
setblock ~43~1~44 minecraft:wool 15
fill ~45~0~44 ~45~0~62 minecraft:dirt 0
setblock ~45~1~44 minecraft:wool 15
setblock ~46~0~44 minecraft:grass
setblock ~46~1~44 minecraft:glowstone
setblock ~47~1~44 minecraft:wool 15
setblock ~49~1~44 minecraft:wool 15
setblock ~51~1~44 minecraft:wool 15
setblock ~53~1~44 minecraft:wool 15
setblock ~55~1~44 minecraft:wool 15
setblock ~57~1~44 minecraft:wool 15
setblock ~59~1~44 minecraft:wool 15
setblock ~61~1~44 minecraft:wool 15
setblock ~63~1~44 minecraft:wool 15
setblock ~6~1~45 minecraft:wool 7
setblock ~8~1~45 minecraft:wool 7
setblock ~10~1~45 minecraft:wool 7
setblock ~12~1~45 minecraft:wool 7
setblock ~14~1~45 minecraft:wool 7
setblock ~16~1~45 minecraft:wool 7
setblock ~18~1~45 minecraft:wool 7
fill ~20~0~45 ~21~0~45 minecraft:dirt 0
setblock ~20~1~45 minecraft:wool 7
setblock ~22~0~45 minecraft:grass
setblock ~22~1~45 minecraft:glowstone
fill ~23~0~45 ~23~0~62 minecraft:dirt 0
fill ~23~1~45 ~23~1~61 minecraft:wool 15
fill ~23~4~45 ~29~4~46 minecraft:stained_glass 8
setblock ~24~1~45 minecraft:wool 7
setblock ~26~1~45 minecraft:wool 7
setblock ~28~1~45 minecraft:wool 7
setblock ~30~1~45 minecraft:wool 7
fill ~30~4~45 ~30~4~46 minecraft:quartz_stairs 1
fill ~31~2~45 ~31~2~46 minecraft:glowstone
fill ~31~3~45 ~31~3~46 minecraft:quartz_stairs 1
fill ~34~0~45 ~35~0~45 minecraft:quartz_block 0
fill ~38~2~45 ~38~2~46 minecraft:glowstone
fill ~38~3~45 ~38~3~46 minecraft:quartz_stairs 0
setblock ~39~1~45 minecraft:wool 7
fill ~39~4~45 ~39~4~46 minecraft:quartz_stairs 0
fill ~40~4~45 ~46~4~46 minecraft:stained_glass 8
setblock ~41~1~45 minecraft:wool 7
setblock ~43~1~45 minecraft:wool 7
setblock ~45~1~45 minecraft:wool 7
fill ~46~0~45 ~46~0~62 minecraft:dirt 0
fill ~46~1~45 ~46~1~61 minecraft:wool 15
setblock ~47~0~45 minecraft:grass
setblock ~47~1~45 minecraft:glowstone
fill ~48~0~45 ~49~0~45 minecraft:dirt 0
setblock ~49~1~45 minecraft:wool 7
setblock ~51~1~45 minecraft:wool 7
setblock ~53~1~45 minecraft:wool 7
setblock ~55~1~45 minecraft:wool 7
setblock ~57~1~45 minecraft:wool 7
setblock ~59~1~45 minecraft:wool 7
setblock ~61~1~45 minecraft:wool 7
setblock ~63~1~45 minecraft:wool 7
setblock ~6~1~46 minecraft:wool 15
setblock ~8~1~46 minecraft:wool 15
setblock ~10~1~46 minecraft:wool 15
setblock ~12~1~46 minecraft:wool 15
setblock ~14~1~46 minecraft:wool 15
setblock ~16~1~46 minecraft:wool 15
setblock ~18~1~46 minecraft:wool 15
setblock ~20~0~46 minecraft:dirt 0
setblock ~20~1~46 minecraft:wool 15
setblock ~21~0~46 minecraft:grass
setblock ~21~1~46 minecraft:glowstone
fill ~22~0~46 ~22~0~62 minecraft:dirt 0
setblock ~22~1~46 minecraft:wool 15
setblock ~24~1~46 minecraft:wool 15
setblock ~26~1~46 minecraft:wool 15
setblock ~28~1~46 minecraft:wool 15
setblock ~30~1~46 minecraft:wool 15
fill ~34~0~46 ~35~0~47 minecraft:glowstone
fill ~34~1~46 ~35~1~47 minecraft:stained_glass 8
setblock ~39~1~46 minecraft:wool 15
setblock ~41~1~46 minecraft:wool 15
setblock ~43~1~46 minecraft:wool 15
setblock ~45~1~46 minecraft:wool 15
fill ~47~0~46 ~47~0~62 minecraft:dirt 0
setblock ~47~1~46 minecraft:wool 15
setblock ~48~0~46 minecraft:grass
setblock ~48~1~46 minecraft:glowstone
setblock ~49~0~46 minecraft:dirt 0
setblock ~49~1~46 minecraft:wool 15
setblock ~51~1~46 minecraft:wool 15
setblock ~53~1~46 minecraft:wool 15
setblock ~55~1~46 minecraft:wool 15
setblock ~57~1~46 minecraft:wool 15
setblock ~59~1~46 minecraft:wool 15
setblock ~61~1~46 minecraft:wool 15
setblock ~63~1~46 minecraft:wool 15
setblock ~2~14~47 minecraft:wool 7
fill ~3~1~47 ~3~1~64 minecraft:wool 15
setblock ~3~2~47 minecraft:quartz_block 0
setblock ~3~14~47 minecraft:stained_glass 8
setblock ~4~14~47 minecraft:diamond_block
fill ~5~1~47 ~5~1~61 minecraft:wool 15
setblock ~5~2~47 minecraft:quartz_block 0
setblock ~5~14~47 minecraft:stained_glass 8
setblock ~6~1~47 minecraft:wool 7
setblock ~6~14~47 minecraft:wool 7
setblock ~7~14~47 minecraft:quartz_block 0
setblock ~8~1~47 minecraft:wool 7
setblock ~10~1~47 minecraft:wool 7
setblock ~12~1~47 minecraft:wool 7
setblock ~14~1~47 minecraft:wool 7
setblock ~16~1~47 minecraft:wool 7
setblock ~18~1~47 minecraft:wool 7
setblock ~20~0~47 minecraft:grass
setblock ~20~1~47 minecraft:glowstone
fill ~21~0~47 ~21~0~62 minecraft:dirt 0
fill ~21~1~47 ~21~1~61 minecraft:wool 15
fill ~21~5~47 ~29~5~47 minecraft:quartz_block 0
setblock ~22~1~47 minecraft:wool 7
setblock ~24~1~47 minecraft:wool 7
setblock ~26~1~47 minecraft:wool 7
setblock ~28~1~47 minecraft:wool 7
fill ~29~4~47 ~30~4~47 minecraft:quartz_block 0
setblock ~30~1~47 minecraft:wool 7
fill ~30~3~47 ~31~3~47 minecraft:quartz_block 0
setblock ~31~2~47 minecraft:quartz_block 0
fill ~38~2~47 ~38~3~47 minecraft:quartz_block 0
setblock ~39~1~47 minecraft:wool 7
fill ~39~3~47 ~39~4~47 minecraft:quartz_block 0
fill ~40~4~47 ~40~5~47 minecraft:quartz_block 0
setblock ~41~1~47 minecraft:wool 7
fill ~41~5~47 ~48~5~47 minecraft:quartz_block 0
setblock ~43~1~47 minecraft:wool 7
setblock ~45~1~47 minecraft:wool 7
setblock ~47~1~47 minecraft:wool 7
fill ~48~0~47 ~48~0~62 minecraft:dirt 0
