setblock ~68 ~1 ~98 concrete 4 
setblock ~68 ~2 ~98 sea_lantern 0 
setblock ~68 ~3 ~98 stained_hardened_clay 9 
setblock ~70 ~3 ~98 concrete 4  
fill ~68 ~4 ~98 ~68 ~8 ~98 stained_hardened_clay 0 
setblock ~70 ~4 ~98 sea_lantern 0 
setblock ~70 ~5 ~98 stained_hardened_clay 9  
fill ~70 ~6 ~98 ~70 ~8 ~98 stained_hardened_clay 0 
setblock ~60 ~8 ~89 stained_hardened_clay 9 
setblock ~60 ~8 ~107 stained_hardened_clay 9 
setblock ~61 ~8 ~90 stained_hardened_clay 9 
setblock ~61 ~8 ~106 stained_hardened_clay 9 
setblock ~77 ~8 ~90 stained_hardened_clay 9 
setblock ~77 ~8 ~106 stained_hardened_clay 9 
setblock ~78 ~8 ~89 stained_hardened_clay 9 
setblock ~78 ~8 ~107 stained_hardened_clay 9 
setblock ~58 ~9 ~87 stained_hardened_clay 9 
setblock ~58 ~9 ~109 stained_hardened_clay 9 
setblock ~59 ~9 ~88 stained_hardened_clay 9 
setblock ~59 ~9 ~108 stained_hardened_clay 9 
setblock ~60 ~9 ~89 stained_hardened_clay 0 
setblock ~60 ~9 ~107 stained_hardened_clay 0 
setblock ~61 ~9 ~90 stained_hardened_clay 0 
setblock ~61 ~9 ~106 stained_hardened_clay 0 
setblock ~62 ~9 ~91 stained_hardened_clay 9 
setblock ~62 ~9 ~105 stained_hardened_clay 9 
setblock ~63 ~9 ~92 stained_hardened_clay 9 
setblock ~63 ~9 ~104 stained_hardened_clay 9  
fill ~68 ~9 ~97 ~70 ~9 ~97 stained_glass 3 
setblock ~68 ~9 ~98 stained_hardened_clay 9  
fill ~68 ~9 ~99 ~70 ~9 ~99 stained_glass 3 
setblock ~69 ~9 ~98 stained_glass 3 
setblock ~70 ~9 ~98 stained_hardened_clay 9 
setblock ~75 ~9 ~92 stained_hardened_clay 9 
setblock ~75 ~9 ~104 stained_hardened_clay 9 
setblock ~76 ~9 ~91 stained_hardened_clay 9 
setblock ~76 ~9 ~105 stained_hardened_clay 9 
setblock ~77 ~9 ~90 stained_hardened_clay 0 
setblock ~77 ~9 ~106 stained_hardened_clay 0 
setblock ~78 ~9 ~89 stained_hardened_clay 0 
setblock ~78 ~9 ~107 stained_hardened_clay 0 
setblock ~79 ~9 ~88 stained_hardened_clay 9 
setblock ~79 ~9 ~108 stained_hardened_clay 9 
setblock ~80 ~9 ~87 stained_hardened_clay 9 
setblock ~80 ~9 ~109 stained_hardened_clay 9 
setblock ~56 ~10 ~85 stained_hardened_clay 9 
setblock ~56 ~10 ~111 stained_hardened_clay 9 
setblock ~57 ~10 ~86 stained_hardened_clay 9 
setblock ~57 ~10 ~110 stained_hardened_clay 9 
setblock ~58 ~10 ~87 stained_hardened_clay 0 
setblock ~58 ~10 ~109 stained_hardened_clay 0 
setblock ~59 ~10 ~88 stained_hardened_clay 0 
setblock ~59 ~10 ~108 stained_hardened_clay 0  
fill ~60 ~10 ~89 ~60 ~14 ~89 stained_glass 3  
fill ~60 ~10 ~107 ~60 ~14 ~107 stained_glass 3  
fill ~61 ~10 ~90 ~61 ~14 ~90 stained_glass 3  
fill ~61 ~10 ~106 ~61 ~14 ~106 stained_glass 3 
setblock ~62 ~10 ~91 stained_hardened_clay 0 
setblock ~62 ~10 ~105 stained_hardened_clay 0 
setblock ~63 ~10 ~92 stained_hardened_clay 0 
setblock ~63 ~10 ~104 stained_hardened_clay 0 
setblock ~64 ~10 ~93 stained_hardened_clay 9 
setblock ~64 ~10 ~103 stained_hardened_clay 9 
setblock ~65 ~10 ~94 stained_hardened_clay 9 
setblock ~65 ~10 ~102 stained_hardened_clay 9  
fill ~67 ~10 ~97 ~67 ~10 ~99 stained_hardened_clay 9  
fill ~68 ~10 ~96 ~70 ~10 ~96 stained_hardened_clay 9  
fill ~68 ~10 ~97 ~70 ~10 ~97 sea_lantern 0  
fill ~68 ~10 ~98 ~70 ~10 ~98 sea_lantern 0  
fill ~68 ~10 ~99 ~70 ~10 ~99 sea_lantern 0  
fill ~68 ~10 ~100 ~70 ~10 ~100 stained_hardened_clay 9  
fill ~71 ~10 ~97 ~71 ~10 ~99 stained_hardened_clay 9 
setblock ~73 ~10 ~94 stained_hardened_clay 9 
setblock ~73 ~10 ~102 stained_hardened_clay 9 
setblock ~74 ~10 ~93 stained_hardened_clay 9 
setblock ~74 ~10 ~103 stained_hardened_clay 9 
setblock ~75 ~10 ~92 stained_hardened_clay 0 
setblock ~75 ~10 ~104 stained_hardened_clay 0 
setblock ~76 ~10 ~91 stained_hardened_clay 0 
setblock ~76 ~10 ~105 stained_hardened_clay 0  
fill ~77 ~10 ~90 ~77 ~14 ~90 stained_glass 3  
fill ~77 ~10 ~106 ~77 ~14 ~106 stained_glass 3  
fill ~78 ~10 ~89 ~78 ~14 ~89 stained_glass 3  
fill ~78 ~10 ~107 ~78 ~14 ~107 stained_glass 3 
setblock ~79 ~10 ~88 stained_hardened_clay 0 
setblock ~79 ~10 ~108 stained_hardened_clay 0 
setblock ~80 ~10 ~87 stained_hardened_clay 0 
setblock ~80 ~10 ~109 stained_hardened_clay 0 
setblock ~81 ~10 ~86 stained_hardened_clay 9 
setblock ~81 ~10 ~110 stained_hardened_clay 9 
setblock ~82 ~10 ~85 stained_hardened_clay 9 
setblock ~82 ~10 ~111 stained_hardened_clay 9  
fill ~54 ~11 ~83 ~54 ~19 ~83 stained_hardened_clay 9  
fill ~54 ~11 ~113 ~54 ~19 ~113 stained_hardened_clay 9 
setblock ~55 ~11 ~84 stained_hardened_clay 9 
setblock ~55 ~11 ~112 stained_hardened_clay 9 
setblock ~56 ~11 ~85 stained_hardened_clay 0 
setblock ~56 ~11 ~111 stained_hardened_clay 0 
setblock ~57 ~11 ~86 stained_hardened_clay 0 
setblock ~57 ~11 ~110 stained_hardened_clay 0  
fill ~58 ~11 ~87 ~58 ~14 ~87 stained_glass 3  
fill ~58 ~11 ~109 ~58 ~14 ~109 stained_glass 3  
fill ~59 ~11 ~88 ~59 ~14 ~88 stained_glass 3  
fill ~59 ~11 ~108 ~59 ~14 ~108 stained_glass 3  
fill ~62 ~11 ~91 ~62 ~14 ~91 stained_glass 3  
fill ~62 ~11 ~105 ~62 ~14 ~105 stained_glass 3  
fill ~63 ~11 ~92 ~63 ~14 ~92 stained_glass 3  
fill ~63 ~11 ~104 ~63 ~14 ~104 stained_glass 3 
setblock ~64 ~11 ~93 stained_hardened_clay 0 
setblock ~64 ~11 ~103 stained_hardened_clay 0 
setblock ~65 ~11 ~94 stained_hardened_clay 0 
setblock ~65 ~11 ~102 stained_hardened_clay 0 
setblock ~66 ~11 ~95 stained_hardened_clay 9 
setblock ~66 ~11 ~101 stained_hardened_clay 9  
fill ~67 ~11 ~96 ~67 ~12 ~96 stained_hardened_clay 9  
fill ~67 ~11 ~97 ~71 ~11 ~97 concrete 4  
fill ~67 ~11 ~98 ~71 ~11 ~98 concrete 4  
fill ~67 ~11 ~99 ~71 ~11 ~99 concrete 4  
fill ~67 ~11 ~100 ~67 ~12 ~100 stained_hardened_clay 9  
fill ~68 ~11 ~96 ~70 ~11 ~96 concrete 4  
fill ~68 ~11 ~100 ~70 ~11 ~100 concrete 4  
fill ~71 ~11 ~96 ~71 ~12 ~96 stained_hardened_clay 9  
fill ~71 ~11 ~100 ~71 ~12 ~100 stained_hardened_clay 9 
setblock ~72 ~11 ~95 stained_hardened_clay 9 
setblock ~72 ~11 ~101 stained_hardened_clay 9 
setblock ~73 ~11 ~94 stained_hardened_clay 0 
setblock ~73 ~11 ~102 stained_hardened_clay 0 
setblock ~74 ~11 ~93 stained_hardened_clay 0 
setblock ~74 ~11 ~103 stained_hardened_clay 0  
fill ~75 ~11 ~92 ~75 ~14 ~92 stained_glass 3  
fill ~75 ~11 ~104 ~75 ~14 ~104 stained_glass 3  
fill ~76 ~11 ~91 ~76 ~14 ~91 stained_glass 3  
fill ~76 ~11 ~105 ~76 ~14 ~105 stained_glass 3  
fill ~79 ~11 ~88 ~79 ~14 ~88 stained_glass 3  
fill ~79 ~11 ~108 ~79 ~14 ~108 stained_glass 3  
fill ~80 ~11 ~87 ~80 ~14 ~87 stained_glass 3  
fill ~80 ~11 ~109 ~80 ~14 ~109 stained_glass 3 
setblock ~81 ~11 ~86 stained_hardened_clay 0 
setblock ~81 ~11 ~110 stained_hardened_clay 0 
setblock ~82 ~11 ~85 stained_hardened_clay 0 
setblock ~82 ~11 ~111 stained_hardened_clay 0 
setblock ~83 ~11 ~84 stained_hardened_clay 9 
setblock ~83 ~11 ~112 stained_hardened_clay 9  
fill ~84 ~11 ~83 ~84 ~19 ~83 stained_hardened_clay 9  
fill ~84 ~11 ~113 ~84 ~19 ~113 stained_hardened_clay 9  
fill ~55 ~12 ~84 ~55 ~14 ~84 stained_hardened_clay 0  
fill ~55 ~12 ~112 ~55 ~14 ~112 stained_hardened_clay 0  
fill ~56 ~12 ~85 ~56 ~14 ~85 stained_glass 3  
fill ~56 ~12 ~111 ~56 ~14 ~111 stained_glass 3  
fill ~57 ~12 ~86 ~57 ~14 ~86 stained_glass 3  
fill ~57 ~12 ~110 ~57 ~14 ~110 stained_glass 3  
fill ~64 ~12 ~93 ~64 ~14 ~93 stained_glass 3  
fill ~64 ~12 ~103 ~64 ~14 ~103 stained_glass 3  
fill ~65 ~12 ~94 ~65 ~14 ~94 stained_glass 3  
fill ~65 ~12 ~102 ~65 ~14 ~102 stained_glass 3  
fill ~66 ~12 ~95 ~66 ~14 ~95 stained_hardened_clay 0  
fill ~66 ~12 ~101 ~66 ~14 ~101 stained_hardened_clay 0  
fill ~67 ~12 ~97 ~71 ~12 ~97 concrete 4  
fill ~67 ~12 ~98 ~71 ~12 ~98 concrete 4  
fill ~67 ~12 ~99 ~71 ~12 ~99 concrete 4  
fill ~68 ~12 ~96 ~70 ~12 ~96 concrete 4  
fill ~68 ~12 ~100 ~70 ~12 ~100 concrete 4  
fill ~72 ~12 ~95 ~72 ~14 ~95 stained_hardened_clay 0  
fill ~72 ~12 ~101 ~72 ~14 ~101 stained_hardened_clay 0  
fill ~73 ~12 ~94 ~73 ~14 ~94 stained_glass 3  
fill ~73 ~12 ~102 ~73 ~14 ~102 stained_glass 3  
fill ~74 ~12 ~93 ~74 ~14 ~93 stained_glass 3  
fill ~74 ~12 ~103 ~74 ~14 ~103 stained_glass 3  
fill ~81 ~12 ~86 ~81 ~14 ~86 stained_glass 3  
fill ~81 ~12 ~110 ~81 ~14 ~110 stained_glass 3  
fill ~82 ~12 ~85 ~82 ~14 ~85 stained_glass 3  
fill ~82 ~12 ~111 ~82 ~14 ~111 stained_glass 3  
fill ~83 ~12 ~84 ~83 ~14 ~84 stained_hardened_clay 0  
fill ~83 ~12 ~112 ~83 ~14 ~112 stained_hardened_clay 0  
fill ~66 ~13 ~96 ~66 ~14 ~96 stained_hardened_clay 9  
fill ~66 ~13 ~97 ~66 ~14 ~97 stained_hardened_clay 9  
fill ~66 ~13 ~98 ~66 ~14 ~98 stained_hardened_clay 9  
fill ~66 ~13 ~99 ~66 ~14 ~99 stained_hardened_clay 9  
fill ~66 ~13 ~100 ~66 ~14 ~100 stained_hardened_clay 9  
fill ~67 ~13 ~95 ~71 ~13 ~95 stained_hardened_clay 9  
fill ~67 ~13 ~96 ~71 ~13 ~96 concrete 4  
fill ~67 ~13 ~97 ~71 ~13 ~97 concrete 4  
fill ~67 ~13 ~98 ~71 ~13 ~98 concrete 4  
fill ~67 ~13 ~99 ~71 ~13 ~99 concrete 4  
fill ~67 ~13 ~100 ~71 ~13 ~100 concrete 4  
fill ~67 ~13 ~101 ~71 ~13 ~101 stained_hardened_clay 9  
fill ~72 ~13 ~96 ~72 ~14 ~96 stained_hardened_clay 9  
fill ~72 ~13 ~97 ~72 ~14 ~97 stained_hardened_clay 9  
fill ~72 ~13 ~98 ~72 ~14 ~98 stained_hardened_clay 9  
fill ~72 ~13 ~99 ~72 ~14 ~99 stained_hardened_clay 9  
fill ~72 ~13 ~100 ~72 ~14 ~100 stained_hardened_clay 9  
fill ~67 ~14 ~95 ~71 ~14 ~95 stained_hardened_clay 9  
fill ~67 ~14 ~96 ~71 ~14 ~96 concrete 4  
fill ~67 ~14 ~97 ~71 ~14 ~97 concrete 4  
fill ~67 ~14 ~98 ~71 ~14 ~98 concrete 4  
fill ~67 ~14 ~99 ~71 ~14 ~99 concrete 4  
fill ~67 ~14 ~100 ~71 ~14 ~100 concrete 4  
fill ~67 ~14 ~101 ~71 ~14 ~101 stained_hardened_clay 9 
setblock ~55 ~15 ~84 sea_lantern 0 
setblock ~55 ~15 ~112 sea_lantern 0 
setblock ~56 ~15 ~85 stained_hardened_clay 0 
setblock ~56 ~15 ~111 stained_hardened_clay 0 
setblock ~57 ~15 ~86 stained_hardened_clay 0 
setblock ~57 ~15 ~110 stained_hardened_clay 0 
setblock ~58 ~15 ~87 stained_hardened_clay 0 
setblock ~58 ~15 ~109 stained_hardened_clay 0 
setblock ~59 ~15 ~88 stained_hardened_clay 0 
setblock ~59 ~15 ~108 stained_hardened_clay 0 
setblock ~60 ~15 ~89 stained_hardened_clay 0 
setblock ~60 ~15 ~107 stained_hardened_clay 0 
setblock ~61 ~15 ~90 stained_hardened_clay 0 
setblock ~61 ~15 ~106 stained_hardened_clay 0 
setblock ~62 ~15 ~91 stained_hardened_clay 0 
setblock ~62 ~15 ~105 stained_hardened_clay 0 
setblock ~63 ~15 ~92 stained_hardened_clay 0 
setblock ~63 ~15 ~104 stained_hardened_clay 0 
setblock ~64 ~15 ~93 stained_hardened_clay 0 
setblock ~64 ~15 ~103 stained_hardened_clay 0 
setblock ~65 ~15 ~94 stained_hardened_clay 0 
setblock ~65 ~15 ~102 stained_hardened_clay 0 
setblock ~66 ~15 ~95 sea_lantern 0 
setblock ~66 ~15 ~101 sea_lantern 0 
setblock ~67 ~15 ~96 stained_hardened_clay 9  
fill ~67 ~15 ~97 ~71 ~15 ~97 concrete 4  
fill ~67 ~15 ~98 ~71 ~15 ~98 concrete 4  
fill ~67 ~15 ~99 ~71 ~15 ~99 concrete 4 
setblock ~67 ~15 ~100 stained_hardened_clay 9  
fill ~68 ~15 ~96 ~70 ~15 ~96 concrete 4  
fill ~68 ~15 ~100 ~70 ~15 ~100 concrete 4 
setblock ~71 ~15 ~96 stained_hardened_clay 9 
setblock ~71 ~15 ~100 stained_hardened_clay 9 
setblock ~72 ~15 ~95 sea_lantern 0 
setblock ~72 ~15 ~101 sea_lantern 0 
setblock ~73 ~15 ~94 stained_hardened_clay 0 
setblock ~73 ~15 ~102 stained_hardened_clay 0 
setblock ~74 ~15 ~93 stained_hardened_clay 0 
setblock ~74 ~15 ~103 stained_hardened_clay 0 
setblock ~75 ~15 ~92 stained_hardened_clay 0 
setblock ~75 ~15 ~104 stained_hardened_clay 0 
setblock ~76 ~15 ~91 stained_hardened_clay 0 
setblock ~76 ~15 ~105 stained_hardened_clay 0 
setblock ~77 ~15 ~90 stained_hardened_clay 0 
setblock ~77 ~15 ~106 stained_hardened_clay 0 
setblock ~78 ~15 ~89 stained_hardened_clay 0 
setblock ~78 ~15 ~107 stained_hardened_clay 0 
setblock ~79 ~15 ~88 stained_hardened_clay 0 
setblock ~79 ~15 ~108 stained_hardened_clay 0 
setblock ~80 ~15 ~87 stained_hardened_clay 0 
setblock ~80 ~15 ~109 stained_hardened_clay 0 
setblock ~81 ~15 ~86 stained_hardened_clay 0 
setblock ~81 ~15 ~110 stained_hardened_clay 0 
setblock ~82 ~15 ~85 stained_hardened_clay 0 
setblock ~82 ~15 ~111 stained_hardened_clay 0 
setblock ~83 ~15 ~84 sea_lantern 0 
setblock ~83 ~15 ~112 sea_lantern 0  
fill ~55 ~16 ~84 ~55 ~18 ~84 stained_hardened_clay 0  
fill ~55 ~16 ~112 ~55 ~18 ~112 stained_hardened_clay 0  
fill ~56 ~16 ~85 ~56 ~18 ~85 stained_glass 3  
fill ~56 ~16 ~111 ~56 ~18 ~111 stained_glass 3  
fill ~57 ~16 ~86 ~57 ~18 ~86 stained_glass 3  
fill ~57 ~16 ~110 ~57 ~18 ~110 stained_glass 3  
fill ~58 ~16 ~87 ~58 ~19 ~87 stained_glass 3  
fill ~58 ~16 ~109 ~58 ~19 ~109 stained_glass 3  
fill ~59 ~16 ~88 ~59 ~19 ~88 stained_glass 3  
fill ~59 ~16 ~108 ~59 ~19 ~108 stained_glass 3  
fill ~60 ~16 ~89 ~60 ~20 ~89 stained_glass 3  
fill ~60 ~16 ~107 ~60 ~20 ~107 stained_glass 3  
fill ~61 ~16 ~90 ~61 ~20 ~90 stained_glass 3  
fill ~61 ~16 ~106 ~61 ~20 ~106 stained_glass 3  
fill ~62 ~16 ~91 ~62 ~19 ~91 stained_glass 3  
fill ~62 ~16 ~105 ~62 ~19 ~105 stained_glass 3  
fill ~63 ~16 ~92 ~63 ~19 ~92 stained_glass 3  
fill ~63 ~16 ~104 ~63 ~19 ~104 stained_glass 3  
fill ~64 ~16 ~93 ~64 ~18 ~93 stained_glass 3  
fill ~64 ~16 ~103 ~64 ~18 ~103 stained_glass 3  
fill ~65 ~16 ~94 ~65 ~18 ~94 stained_glass 3  
fill ~65 ~16 ~102 ~65 ~18 ~102 stained_glass 3  
fill ~66 ~16 ~95 ~66 ~18 ~95 stained_hardened_clay 0  
fill ~66 ~16 ~96 ~66 ~17 ~96 stained_hardened_clay 9  
fill ~66 ~16 ~97 ~66 ~17 ~97 stained_hardened_clay 9  
fill ~66 ~16 ~98 ~66 ~17 ~98 stained_hardened_clay 9  
fill ~66 ~16 ~99 ~66 ~17 ~99 stained_hardened_clay 9  
fill ~66 ~16 ~100 ~66 ~17 ~100 stained_hardened_clay 9  
fill ~66 ~16 ~101 ~66 ~18 ~101 stained_hardened_clay 0  
fill ~67 ~16 ~95 ~71 ~16 ~95 stained_hardened_clay 9  
fill ~67 ~16 ~96 ~71 ~16 ~96 concrete 4  
fill ~67 ~16 ~97 ~71 ~16 ~97 concrete 4  
fill ~67 ~16 ~98 ~71 ~16 ~98 concrete 4  
fill ~67 ~16 ~99 ~71 ~16 ~99 concrete 4  
fill ~67 ~16 ~100 ~71 ~16 ~100 concrete 4  
fill ~67 ~16 ~101 ~71 ~16 ~101 stained_hardened_clay 9  
fill ~72 ~16 ~95 ~72 ~18 ~95 stained_hardened_clay 0  
fill ~72 ~16 ~96 ~72 ~17 ~96 stained_hardened_clay 9  
fill ~72 ~16 ~97 ~72 ~17 ~97 stained_hardened_clay 9  
fill ~72 ~16 ~98 ~72 ~17 ~98 stained_hardened_clay 9  
fill ~72 ~16 ~99 ~72 ~17 ~99 stained_hardened_clay 9  
fill ~72 ~16 ~100 ~72 ~17 ~100 stained_hardened_clay 9  
fill ~72 ~16 ~101 ~72 ~18 ~101 stained_hardened_clay 0  
fill ~73 ~16 ~94 ~73 ~18 ~94 stained_glass 3  
fill ~73 ~16 ~102 ~73 ~18 ~102 stained_glass 3  
fill ~74 ~16 ~93 ~74 ~18 ~93 stained_glass 3  
fill ~74 ~16 ~103 ~74 ~18 ~103 stained_glass 3  
fill ~75 ~16 ~92 ~75 ~19 ~92 stained_glass 3  
fill ~75 ~16 ~104 ~75 ~19 ~104 stained_glass 3  
fill ~76 ~16 ~91 ~76 ~19 ~91 stained_glass 3  
fill ~76 ~16 ~105 ~76 ~19 ~105 stained_glass 3  
fill ~77 ~16 ~90 ~77 ~20 ~90 stained_glass 3  
fill ~77 ~16 ~106 ~77 ~20 ~106 stained_glass 3  
fill ~78 ~16 ~89 ~78 ~20 ~89 stained_glass 3  
fill ~78 ~16 ~107 ~78 ~20 ~107 stained_glass 3  
fill ~79 ~16 ~88 ~79 ~19 ~88 stained_glass 3  
fill ~79 ~16 ~108 ~79 ~19 ~108 stained_glass 3  
fill ~80 ~16 ~87 ~80 ~19 ~87 stained_glass 3  
fill ~80 ~16 ~109 ~80 ~19 ~109 stained_glass 3  
fill ~81 ~16 ~86 ~81 ~18 ~86 stained_glass 3  
fill ~81 ~16 ~110 ~81 ~18 ~110 stained_glass 3  
fill ~82 ~16 ~85 ~82 ~18 ~85 stained_glass 3  
fill ~82 ~16 ~111 ~82 ~18 ~111 stained_glass 3  
fill ~83 ~16 ~84 ~83 ~18 ~84 stained_hardened_clay 0  
fill ~83 ~16 ~112 ~83 ~18 ~112 stained_hardened_clay 0  
fill ~67 ~17 ~95 ~71 ~17 ~95 stained_hardened_clay 9  
fill ~67 ~17 ~96 ~71 ~17 ~96 concrete 4  
fill ~67 ~17 ~97 ~71 ~17 ~97 concrete 4  
fill ~67 ~17 ~98 ~71 ~17 ~98 concrete 4  
fill ~67 ~17 ~99 ~71 ~17 ~99 concrete 4  
fill ~67 ~17 ~100 ~71 ~17 ~100 concrete 4  
fill ~67 ~17 ~101 ~71 ~17 ~101 stained_hardened_clay 9  
fill ~67 ~18 ~96 ~67 ~19 ~96 stained_hardened_clay 9  
fill ~67 ~18 ~97 ~71 ~18 ~97 concrete 4  
fill ~67 ~18 ~98 ~71 ~18 ~98 concrete 4  
fill ~67 ~18 ~99 ~71 ~18 ~99 concrete 4  
fill ~67 ~18 ~100 ~67 ~19 ~100 stained_hardened_clay 9  
fill ~68 ~18 ~96 ~70 ~18 ~96 concrete 4  
fill ~68 ~18 ~100 ~70 ~18 ~100 concrete 4  
fill ~71 ~18 ~96 ~71 ~19 ~96 stained_hardened_clay 9  
fill ~71 ~18 ~100 ~71 ~19 ~100 stained_hardened_clay 9 
setblock ~55 ~19 ~84 stained_hardened_clay 9 
setblock ~55 ~19 ~112 stained_hardened_clay 9 
setblock ~56 ~19 ~85 stained_hardened_clay 0 
setblock ~56 ~19 ~111 stained_hardened_clay 0 
setblock ~57 ~19 ~86 stained_hardened_clay 0 
setblock ~57 ~19 ~110 stained_hardened_clay 0 
setblock ~64 ~19 ~93 stained_hardened_clay 0 
setblock ~64 ~19 ~103 stained_hardened_clay 0 
setblock ~65 ~19 ~94 stained_hardened_clay 0 
setblock ~65 ~19 ~102 stained_hardened_clay 0 
setblock ~66 ~19 ~95 stained_hardened_clay 9 
setblock ~66 ~19 ~101 stained_hardened_clay 9  
fill ~67 ~19 ~97 ~71 ~19 ~97 concrete 4  
fill ~67 ~19 ~98 ~71 ~19 ~98 concrete 4  
fill ~67 ~19 ~99 ~71 ~19 ~99 concrete 4  
fill ~68 ~19 ~96 ~70 ~19 ~96 concrete 4  
fill ~68 ~19 ~100 ~70 ~19 ~100 concrete 4 
setblock ~72 ~19 ~95 stained_hardened_clay 9 
setblock ~72 ~19 ~101 stained_hardened_clay 9 
setblock ~73 ~19 ~94 stained_hardened_clay 0 
setblock ~73 ~19 ~102 stained_hardened_clay 0 
setblock ~74 ~19 ~93 stained_hardened_clay 0 
setblock ~74 ~19 ~103 stained_hardened_clay 0 
setblock ~81 ~19 ~86 stained_hardened_clay 0 
setblock ~81 ~19 ~110 stained_hardened_clay 0 
setblock ~82 ~19 ~85 stained_hardened_clay 0 
setblock ~82 ~19 ~111 stained_hardened_clay 0 
setblock ~83 ~19 ~84 stained_hardened_clay 9 
setblock ~83 ~19 ~112 stained_hardened_clay 9 
setblock ~56 ~20 ~85 stained_hardened_clay 9 
setblock ~56 ~20 ~111 stained_hardened_clay 9 
setblock ~57 ~20 ~86 stained_hardened_clay 9 
setblock ~57 ~20 ~110 stained_hardened_clay 9 
setblock ~58 ~20 ~87 stained_hardened_clay 0 
setblock ~58 ~20 ~109 stained_hardened_clay 0 
setblock ~59 ~20 ~88 stained_hardened_clay 0 
setblock ~59 ~20 ~108 stained_hardened_clay 0 
setblock ~62 ~20 ~91 stained_hardened_clay 0 
setblock ~62 ~20 ~105 stained_hardened_clay 0 
setblock ~63 ~20 ~92 stained_hardened_clay 0 
setblock ~63 ~20 ~104 stained_hardened_clay 0 
setblock ~64 ~20 ~93 stained_hardened_clay 9 
setblock ~64 ~20 ~103 stained_hardened_clay 9 
setblock ~65 ~20 ~94 stained_hardened_clay 9 
setblock ~65 ~20 ~102 stained_hardened_clay 9  
fill ~67 ~20 ~97 ~71 ~20 ~97 concrete 4  
fill ~67 ~20 ~98 ~71 ~20 ~98 concrete 4  
fill ~67 ~20 ~99 ~71 ~20 ~99 concrete 4  
fill ~68 ~20 ~96 ~70 ~20 ~96 concrete 4  
fill ~68 ~20 ~100 ~70 ~20 ~100 concrete 4 
setblock ~73 ~20 ~94 stained_hardened_clay 9 
setblock ~73 ~20 ~102 stained_hardened_clay 9 
setblock ~74 ~20 ~93 stained_hardened_clay 9 
setblock ~74 ~20 ~103 stained_hardened_clay 9 
setblock ~75 ~20 ~92 stained_hardened_clay 0 
setblock ~75 ~20 ~104 stained_hardened_clay 0 
setblock ~76 ~20 ~91 stained_hardened_clay 0 
setblock ~76 ~20 ~105 stained_hardened_clay 0 
setblock ~79 ~20 ~88 stained_hardened_clay 0 
setblock ~79 ~20 ~108 stained_hardened_clay 0 
setblock ~80 ~20 ~87 stained_hardened_clay 0 
setblock ~80 ~20 ~109 stained_hardened_clay 0 
setblock ~81 ~20 ~86 stained_hardened_clay 9 
setblock ~81 ~20 ~110 stained_hardened_clay 9 
setblock ~82 ~20 ~85 stained_hardened_clay 9 
setblock ~82 ~20 ~111 stained_hardened_clay 9 
setblock ~58 ~21 ~87 stained_hardened_clay 9 
setblock ~58 ~21 ~109 stained_hardened_clay 9 
setblock ~59 ~21 ~88 stained_hardened_clay 9 
setblock ~59 ~21 ~108 stained_hardened_clay 9 
setblock ~60 ~21 ~89 stained_hardened_clay 0 
setblock ~60 ~21 ~107 stained_hardened_clay 0 
setblock ~61 ~21 ~90 stained_hardened_clay 0 
setblock ~61 ~21 ~106 stained_hardened_clay 0 
setblock ~62 ~21 ~91 stained_hardened_clay 9 
setblock ~62 ~21 ~105 stained_hardened_clay 9 
setblock ~63 ~21 ~92 stained_hardened_clay 9 
setblock ~63 ~21 ~104 stained_hardened_clay 9  
fill ~67 ~21 ~97 ~71 ~21 ~97 concrete 4  
fill ~67 ~21 ~98 ~71 ~21 ~98 concrete 4  
fill ~67 ~21 ~99 ~71 ~21 ~99 concrete 4  
fill ~68 ~21 ~96 ~70 ~21 ~96 concrete 4  
fill ~68 ~21 ~100 ~70 ~21 ~100 concrete 4 
setblock ~75 ~21 ~92 stained_hardened_clay 9 
setblock ~75 ~21 ~104 stained_hardened_clay 9 
setblock ~76 ~21 ~91 stained_hardened_clay 9 
setblock ~76 ~21 ~105 stained_hardened_clay 9 
setblock ~77 ~21 ~90 stained_hardened_clay 0 
setblock ~77 ~21 ~106 stained_hardened_clay 0 
setblock ~78 ~21 ~89 stained_hardened_clay 0 
setblock ~78 ~21 ~107 stained_hardened_clay 0 
setblock ~79 ~21 ~88 stained_hardened_clay 9 
setblock ~79 ~21 ~108 stained_hardened_clay 9 
setblock ~80 ~21 ~87 stained_hardened_clay 9 
setblock ~80 ~21 ~109 stained_hardened_clay 9 
setblock ~60 ~22 ~89 stained_hardened_clay 9 
setblock ~60 ~22 ~107 stained_hardened_clay 9 
setblock ~61 ~22 ~90 stained_hardened_clay 9 
setblock ~61 ~22 ~106 stained_hardened_clay 9  
fill ~67 ~22 ~97 ~71 ~22 ~97 concrete 4  
fill ~67 ~22 ~98 ~71 ~22 ~98 concrete 4  
fill ~67 ~22 ~99 ~71 ~22 ~99 concrete 4  
fill ~68 ~22 ~96 ~70 ~22 ~96 concrete 4  
fill ~68 ~22 ~100 ~70 ~22 ~100 concrete 4 
setblock ~77 ~22 ~90 stained_hardened_clay 9 
setblock ~77 ~22 ~106 stained_hardened_clay 9 
setblock ~78 ~22 ~89 stained_hardened_clay 9 
setblock ~78 ~22 ~107 stained_hardened_clay 9  
fill ~63 ~23 ~96 ~65 ~23 ~96 stained_hardened_clay 9  
fill ~63 ~23 ~97 ~64 ~23 ~97 stained_hardened_clay 9  
fill ~63 ~23 ~98 ~63 ~27 ~98 stained_hardened_clay 9  
fill ~63 ~23 ~99 ~64 ~23 ~99 stained_hardened_clay 9  
fill ~63 ~23 ~100 ~65 ~23 ~100 stained_hardened_clay 9  
fill ~64 ~23 ~94 ~67 ~23 ~94 stained_hardened_clay 9  
fill ~64 ~23 ~95 ~66 ~23 ~95 stained_hardened_clay 9 
setblock ~64 ~23 ~98 stained_glass 3  
fill ~64 ~23 ~101 ~66 ~23 ~101 stained_hardened_clay 9  
fill ~64 ~23 ~102 ~67 ~23 ~102 stained_hardened_clay 9  
fill ~65 ~23 ~93 ~68 ~23 ~93 stained_hardened_clay 9  
fill ~65 ~23 ~97 ~65 ~23 ~99 concrete 4  
fill ~65 ~23 ~103 ~68 ~23 ~103 stained_hardened_clay 9 
setblock ~66 ~23 ~96 concrete 4  
fill ~66 ~23 ~97 ~72 ~23 ~97 stained_hardened_clay 9  
fill ~66 ~23 ~98 ~72 ~23 ~98 stained_hardened_clay 9  
fill ~66 ~23 ~99 ~72 ~23 ~99 stained_hardened_clay 9 
setblock ~66 ~23 ~100 concrete 4  
fill ~67 ~23 ~92 ~71 ~23 ~92 stained_hardened_clay 9 
setblock ~67 ~23 ~95 concrete 4  
fill ~67 ~23 ~96 ~71 ~23 ~96 stained_hardened_clay 9  
fill ~67 ~23 ~100 ~71 ~23 ~100 stained_hardened_clay 9 
setblock ~67 ~23 ~101 concrete 4  
fill ~67 ~23 ~104 ~71 ~23 ~104 stained_hardened_clay 9  
fill ~68 ~23 ~94 ~70 ~23 ~94 concrete 4  
fill ~68 ~23 ~95 ~70 ~23 ~95 stained_hardened_clay 9  
fill ~68 ~23 ~101 ~70 ~23 ~101 stained_hardened_clay 9  
fill ~68 ~23 ~102 ~70 ~23 ~102 concrete 4 
setblock ~69 ~23 ~93 stained_glass 3 
setblock ~69 ~23 ~103 stained_glass 3  
fill ~70 ~23 ~93 ~73 ~23 ~93 stained_hardened_clay 9  
fill ~70 ~23 ~103 ~73 ~23 ~103 stained_hardened_clay 9  
fill ~71 ~23 ~94 ~74 ~23 ~94 stained_hardened_clay 9 
setblock ~71 ~23 ~95 concrete 4 
setblock ~71 ~23 ~101 concrete 4  
fill ~71 ~23 ~102 ~74 ~23 ~102 stained_hardened_clay 9  
fill ~72 ~23 ~95 ~74 ~23 ~95 stained_hardened_clay 9 
setblock ~72 ~23 ~96 concrete 4 
setblock ~72 ~23 ~100 concrete 4  
fill ~72 ~23 ~101 ~74 ~23 ~101 stained_hardened_clay 9  
fill ~73 ~23 ~96 ~75 ~23 ~96 stained_hardened_clay 9  
fill ~73 ~23 ~97 ~73 ~23 ~99 concrete 4  
fill ~73 ~23 ~100 ~75 ~23 ~100 stained_hardened_clay 9  
fill ~74 ~23 ~97 ~75 ~23 ~97 stained_hardened_clay 9 
setblock ~74 ~23 ~98 stained_glass 3  
fill ~74 ~23 ~99 ~75 ~23 ~99 stained_hardened_clay 9  
fill ~75 ~23 ~98 ~75 ~27 ~98 stained_hardened_clay 9  
fill ~55 ~24 ~98 ~57 ~24 ~98 stained_hardened_clay 9  
fill ~59 ~24 ~94 ~63 ~24 ~94 stained_hardened_clay 0  
fill ~59 ~24 ~95 ~63 ~24 ~95 stained_hardened_clay 0  
fill ~59 ~24 ~96 ~62 ~24 ~96 stained_hardened_clay 0  
fill ~59 ~24 ~97 ~62 ~24 ~97 stained_hardened_clay 0  
fill ~59 ~24 ~98 ~62 ~24 ~98 stained_hardened_clay 0  
fill ~59 ~24 ~99 ~62 ~24 ~99 stained_hardened_clay 0  
fill ~59 ~24 ~100 ~62 ~24 ~100 stained_hardened_clay 0  
fill ~59 ~24 ~101 ~63 ~24 ~101 stained_hardened_clay 0  
fill ~59 ~24 ~102 ~63 ~24 ~102 stained_hardened_clay 0  
fill ~60 ~24 ~92 ~66 ~24 ~92 stained_hardened_clay 0  
fill ~60 ~24 ~93 ~64 ~24 ~93 stained_hardened_clay 0  
fill ~60 ~24 ~103 ~64 ~24 ~103 stained_hardened_clay 0  
fill ~60 ~24 ~104 ~66 ~24 ~104 stained_hardened_clay 0  
fill ~61 ~24 ~91 ~77 ~24 ~91 stained_hardened_clay 0  
fill ~61 ~24 ~105 ~77 ~24 ~105 stained_hardened_clay 0  
fill ~62 ~24 ~90 ~76 ~24 ~90 stained_hardened_clay 0  
fill ~62 ~24 ~106 ~76 ~24 ~106 stained_hardened_clay 0  
fill ~63 ~24 ~89 ~75 ~24 ~89 stained_hardened_clay 0  
fill ~63 ~24 ~96 ~75 ~24 ~96 stained_hardened_clay 9  
fill ~63 ~24 ~97 ~75 ~24 ~97 stained_hardened_clay 9  
fill ~63 ~24 ~99 ~75 ~24 ~99 stained_hardened_clay 9  
fill ~63 ~24 ~100 ~75 ~24 ~100 stained_hardened_clay 9  
fill ~63 ~24 ~107 ~75 ~24 ~107 stained_hardened_clay 0  
fill ~64 ~24 ~94 ~74 ~24 ~94 stained_hardened_clay 9  
fill ~64 ~24 ~95 ~74 ~24 ~95 stained_hardened_clay 9 
setblock ~64 ~24 ~98 sea_lantern 0  
fill ~64 ~24 ~101 ~74 ~24 ~101 stained_hardened_clay 9  
fill ~64 ~24 ~102 ~74 ~24 ~102 stained_hardened_clay 9  
fill ~65 ~24 ~88 ~73 ~24 ~88 stained_hardened_clay 0  
fill ~65 ~24 ~93 ~68 ~24 ~93 stained_hardened_clay 9  
fill ~65 ~24 ~98 ~73 ~24 ~98 stained_hardened_clay 9  
fill ~65 ~24 ~103 ~68 ~24 ~103 stained_hardened_clay 9  
fill ~65 ~24 ~108 ~73 ~24 ~108 stained_hardened_clay 0  
fill ~67 ~24 ~92 ~71 ~24 ~92 stained_hardened_clay 9  
fill ~67 ~24 ~104 ~71 ~24 ~104 stained_hardened_clay 9 
setblock ~69 ~24 ~93 sea_lantern 0 
setblock ~69 ~24 ~103 sea_lantern 0  
fill ~70 ~24 ~93 ~73 ~24 ~93 stained_hardened_clay 9  
fill ~70 ~24 ~103 ~73 ~24 ~103 stained_hardened_clay 9  
fill ~72 ~24 ~92 ~78 ~24 ~92 stained_hardened_clay 0  
fill ~72 ~24 ~104 ~78 ~24 ~104 stained_hardened_clay 0  
fill ~74 ~24 ~93 ~78 ~24 ~93 stained_hardened_clay 0 
setblock ~74 ~24 ~98 sea_lantern 0  
fill ~74 ~24 ~103 ~78 ~24 ~103 stained_hardened_clay 0  
fill ~75 ~24 ~94 ~79 ~24 ~94 stained_hardened_clay 0  
fill ~75 ~24 ~95 ~79 ~24 ~95 stained_hardened_clay 0  
fill ~75 ~24 ~101 ~79 ~24 ~101 stained_hardened_clay 0  
fill ~75 ~24 ~102 ~79 ~24 ~102 stained_hardened_clay 0  
fill ~76 ~24 ~96 ~79 ~24 ~96 stained_hardened_clay 0  
fill ~76 ~24 ~97 ~79 ~24 ~97 stained_hardened_clay 0  
fill ~76 ~24 ~98 ~79 ~24 ~98 stained_hardened_clay 0  
fill ~76 ~24 ~99 ~79 ~24 ~99 stained_hardened_clay 0  
fill ~76 ~24 ~100 ~79 ~24 ~100 stained_hardened_clay 0  
fill ~81 ~24 ~98 ~83 ~24 ~98 stained_hardened_clay 9 
setblock ~55 ~25 ~97 stained_hardened_clay 9 
setblock ~55 ~25 ~98 stained_glass 3 
setblock ~55 ~25 ~99 stained_hardened_clay 9  
fill ~56 ~25 ~95 ~58 ~25 ~95 stained_hardened_clay 0  
fill ~56 ~25 ~96 ~58 ~25 ~96 stained_hardened_clay 0  
fill ~56 ~25 ~97 ~58 ~25 ~97 stained_hardened_clay 0 
setblock ~56 ~25 ~98 sea_lantern 0  
fill ~56 ~25 ~99 ~58 ~25 ~99 stained_hardened_clay 0  
fill ~56 ~25 ~100 ~58 ~25 ~100 stained_hardened_clay 0  
fill ~56 ~25 ~101 ~58 ~25 ~101 stained_hardened_clay 0  
fill ~57 ~25 ~93 ~64 ~25 ~93 stained_hardened_clay 0  
fill ~57 ~25 ~94 ~58 ~25 ~94 stained_hardened_clay 0  
fill ~57 ~25 ~98 ~58 ~25 ~98 stained_hardened_clay 0  
fill ~57 ~25 ~102 ~58 ~25 ~102 stained_hardened_clay 0  
fill ~57 ~25 ~103 ~64 ~25 ~103 stained_hardened_clay 0  
fill ~58 ~25 ~91 ~64 ~25 ~91 stained_hardened_clay 0  
fill ~58 ~25 ~92 ~64 ~25 ~92 stained_hardened_clay 0  
fill ~58 ~25 ~104 ~64 ~25 ~104 stained_hardened_clay 0  
fill ~58 ~25 ~105 ~64 ~25 ~105 stained_hardened_clay 0  
fill ~59 ~25 ~90 ~64 ~25 ~90 stained_hardened_clay 0  
fill ~59 ~25 ~94 ~79 ~25 ~94 stained_hardened_clay 9  
fill ~59 ~25 ~95 ~79 ~25 ~95 stained_hardened_clay 9  
fill ~59 ~25 ~96 ~79 ~25 ~96 stained_hardened_clay 9  
fill ~59 ~25 ~97 ~79 ~25 ~97 stained_hardened_clay 9  
fill ~59 ~25 ~98 ~79 ~25 ~98 stained_hardened_clay 9  
fill ~59 ~25 ~99 ~79 ~25 ~99 stained_hardened_clay 9  
fill ~59 ~25 ~100 ~79 ~25 ~100 stained_hardened_clay 9  
fill ~59 ~25 ~101 ~79 ~25 ~101 stained_hardened_clay 9  
fill ~59 ~25 ~102 ~79 ~25 ~102 stained_hardened_clay 9  
fill ~59 ~25 ~106 ~64 ~25 ~106 stained_hardened_clay 0  
fill ~60 ~25 ~89 ~64 ~25 ~89 stained_hardened_clay 0  
fill ~60 ~25 ~107 ~64 ~25 ~107 stained_hardened_clay 0  
fill ~61 ~25 ~88 ~64 ~25 ~88 stained_hardened_clay 0  
fill ~61 ~25 ~108 ~64 ~25 ~108 stained_hardened_clay 0  
fill ~62 ~25 ~87 ~76 ~25 ~87 stained_hardened_clay 0  
fill ~62 ~25 ~109 ~76 ~25 ~109 stained_hardened_clay 0  
fill ~64 ~25 ~86 ~74 ~25 ~86 stained_hardened_clay 0  
fill ~64 ~25 ~110 ~74 ~25 ~110 stained_hardened_clay 0  
fill ~65 ~25 ~88 ~73 ~25 ~88 stained_hardened_clay 9  
fill ~65 ~25 ~89 ~73 ~25 ~89 stained_hardened_clay 9  
fill ~65 ~25 ~90 ~73 ~25 ~90 stained_hardened_clay 9  
fill ~65 ~25 ~91 ~73 ~25 ~91 stained_hardened_clay 9  
fill ~65 ~25 ~92 ~73 ~25 ~92 stained_hardened_clay 9  
fill ~65 ~25 ~93 ~73 ~25 ~93 stained_hardened_clay 9  
fill ~65 ~25 ~103 ~73 ~25 ~103 stained_hardened_clay 9  
fill ~65 ~25 ~104 ~73 ~25 ~104 stained_hardened_clay 9  
fill ~65 ~25 ~105 ~73 ~25 ~105 stained_hardened_clay 9  
fill ~65 ~25 ~106 ~73 ~25 ~106 stained_hardened_clay 9  
fill ~65 ~25 ~107 ~73 ~25 ~107 stained_hardened_clay 9  
fill ~65 ~25 ~108 ~73 ~25 ~108 stained_hardened_clay 9  
fill ~66 ~25 ~85 ~72 ~25 ~85 stained_hardened_clay 0  
fill ~66 ~25 ~111 ~72 ~25 ~111 stained_hardened_clay 0  
fill ~74 ~25 ~88 ~77 ~25 ~88 stained_hardened_clay 0  
fill ~74 ~25 ~89 ~78 ~25 ~89 stained_hardened_clay 0  
fill ~74 ~25 ~90 ~79 ~25 ~90 stained_hardened_clay 0  
fill ~74 ~25 ~91 ~80 ~25 ~91 stained_hardened_clay 0  
fill ~74 ~25 ~92 ~80 ~25 ~92 stained_hardened_clay 0  
fill ~74 ~25 ~93 ~81 ~25 ~93 stained_hardened_clay 0  
fill ~74 ~25 ~103 ~81 ~25 ~103 stained_hardened_clay 0  
fill ~74 ~25 ~104 ~80 ~25 ~104 stained_hardened_clay 0  
fill ~74 ~25 ~105 ~80 ~25 ~105 stained_hardened_clay 0  
fill ~74 ~25 ~106 ~79 ~25 ~106 stained_hardened_clay 0  
fill ~74 ~25 ~107 ~78 ~25 ~107 stained_hardened_clay 0  
fill ~74 ~25 ~108 ~77 ~25 ~108 stained_hardened_clay 0  
fill ~80 ~25 ~94 ~81 ~25 ~94 stained_hardened_clay 0  
fill ~80 ~25 ~95 ~82 ~25 ~95 stained_hardened_clay 0  
fill ~80 ~25 ~96 ~82 ~25 ~96 stained_hardened_clay 0  
fill ~80 ~25 ~97 ~82 ~25 ~97 stained_hardened_clay 0  
fill ~80 ~25 ~98 ~81 ~25 ~98 stained_hardened_clay 0  
fill ~80 ~25 ~99 ~82 ~25 ~99 stained_hardened_clay 0  
fill ~80 ~25 ~100 ~82 ~25 ~100 stained_hardened_clay 0  
fill ~80 ~25 ~101 ~82 ~25 ~101 stained_hardened_clay 0  
fill ~80 ~25 ~102 ~81 ~25 ~102 stained_hardened_clay 0 
setblock ~82 ~25 ~98 sea_lantern 0 
setblock ~83 ~25 ~97 stained_hardened_clay 9 
setblock ~83 ~25 ~98 stained_glass 3 
setblock ~83 ~25 ~99 stained_hardened_clay 9  
fill ~55 ~26 ~93 ~55 ~27 ~93 stained_hardened_clay 9  
fill ~55 ~26 ~94 ~56 ~26 ~94 stained_hardened_clay 0  
fill ~55 ~26 ~95 ~55 ~26 ~102 stained_hardened_clay 0  
fill ~55 ~26 ~103 ~55 ~27 ~103 stained_hardened_clay 9  
fill ~56 ~26 ~91 ~57 ~26 ~91 stained_hardened_clay 0  
fill ~56 ~26 ~92 ~56 ~27 ~92 stained_hardened_clay 9 
setblock ~56 ~26 ~93 stained_glass 3  
fill ~56 ~26 ~95 ~82 ~26 ~95 stained_hardened_clay 9  
fill ~56 ~26 ~96 ~82 ~26 ~96 stained_hardened_clay 9  
fill ~56 ~26 ~97 ~82 ~26 ~97 stained_hardened_clay 9  
fill ~56 ~26 ~98 ~82 ~26 ~98 stained_hardened_clay 9  
fill ~56 ~26 ~99 ~82 ~26 ~99 stained_hardened_clay 9  
fill ~56 ~26 ~100 ~82 ~26 ~100 stained_hardened_clay 9  
fill ~56 ~26 ~101 ~82 ~26 ~101 stained_hardened_clay 9 
setblock ~56 ~26 ~102 stained_hardened_clay 0 
setblock ~56 ~26 ~103 stained_glass 3  
fill ~56 ~26 ~104 ~56 ~27 ~104 stained_hardened_clay 9  
fill ~56 ~26 ~105 ~57 ~26 ~105 stained_hardened_clay 0  
fill ~57 ~26 ~90 ~58 ~26 ~90 stained_hardened_clay 0  
fill ~57 ~26 ~92 ~57 ~26 ~93 stained_hardened_clay 0  
fill ~57 ~26 ~94 ~81 ~26 ~94 stained_hardened_clay 9  
fill ~57 ~26 ~102 ~81 ~26 ~102 stained_hardened_clay 9  
fill ~57 ~26 ~103 ~57 ~25 ~103 stained_hardened_clay 0  
fill ~57 ~26 ~104 ~57 ~26 ~103 stained_hardened_clay 0  
fill ~57 ~26 ~106 ~58 ~26 ~106 stained_hardened_clay 0   
fill ~58 ~26 ~88 ~60 ~26 ~88 stained_hardened_clay 0  
fill ~58 ~26 ~89 ~60 ~26 ~89 stained_hardened_clay 0  
fill ~58 ~26 ~91 ~80 ~26 ~91 stained_hardened_clay 9  
fill ~58 ~26 ~92 ~80 ~26 ~92 stained_hardened_clay 9  
fill ~58 ~26 ~93 ~80 ~26 ~93 stained_hardened_clay 9  
fill ~58 ~26 ~103 ~80 ~26 ~103 stained_hardened_clay 9  
fill ~58 ~26 ~104 ~80 ~26 ~104 stained_hardened_clay 9  
fill ~58 ~26 ~105 ~80 ~26 ~105 stained_hardened_clay 9  
fill ~58 ~26 ~107 ~60 ~26 ~107 stained_hardened_clay 0  
fill ~58 ~26 ~108 ~60 ~26 ~108 stained_hardened_clay 0  
fill ~59 ~26 ~87 ~61 ~26 ~87 stained_hardened_clay 0  
fill ~59 ~26 ~90 ~79 ~26 ~90 stained_hardened_clay 9  
fill ~59 ~26 ~106 ~79 ~26 ~106 stained_hardened_clay 9  
fill ~59 ~26 ~109 ~61 ~26 ~109 stained_hardened_clay 0  
fill ~61 ~26 ~86 ~64 ~26 ~86 stained_hardened_clay 0  
fill ~61 ~26 ~88 ~77 ~26 ~88 stained_hardened_clay 9  
fill ~61 ~26 ~89 ~77 ~26 ~89 stained_hardened_clay 9  
fill ~61 ~26 ~107 ~77 ~26 ~107 stained_hardened_clay 9  
fill ~61 ~26 ~108 ~77 ~26 ~108 stained_hardened_clay 9  
fill ~61 ~26 ~110 ~64 ~26 ~110 stained_hardened_clay 0 
setblock ~62 ~26 ~85 stained_hardened_clay 0  
fill ~62 ~26 ~87 ~76 ~26 ~87 stained_hardened_clay 9  
fill ~62 ~26 ~109 ~76 ~26 ~109 stained_hardened_clay 9 
setblock ~62 ~26 ~111 stained_hardened_clay 0  
fill ~63 ~26 ~85 ~63 ~27 ~85 stained_hardened_clay 9  
fill ~63 ~26 ~111 ~63 ~27 ~111 stained_hardened_clay 9  
fill ~64 ~26 ~84 ~64 ~27 ~84 stained_hardened_clay 9 
setblock ~64 ~26 ~85 stained_glass 3 
setblock ~64 ~26 ~111 stained_glass 3  
fill ~64 ~26 ~112 ~64 ~27 ~112 stained_hardened_clay 9  
fill ~65 ~26 ~84 ~73 ~26 ~84 stained_hardened_clay 0  
fill ~65 ~26 ~85 ~65 ~26 ~84 stained_hardened_clay 0  
fill ~65 ~26 ~86 ~73 ~26 ~86 stained_hardened_clay 9  
fill ~65 ~26 ~110 ~73 ~26 ~110 stained_hardened_clay 9  
fill ~65 ~26 ~111 ~65 ~26 ~112 stained_hardened_clay 0  
fill ~66 ~26 ~85 ~72 ~26 ~85 stained_hardened_clay 9  
fill ~66 ~26 ~111 ~72 ~26 ~111 stained_hardened_clay 9  
fill ~66 ~26 ~112 ~73 ~26 ~112 stained_hardened_clay 0 
setblock ~73 ~26 ~85 stained_hardened_clay 0 
setblock ~73 ~26 ~111 stained_hardened_clay 0  
fill ~74 ~26 ~84 ~74 ~27 ~84 stained_hardened_clay 9 
setblock ~74 ~26 ~85 stained_glass 3  
fill ~74 ~26 ~86 ~77 ~26 ~86 stained_hardened_clay 0  
fill ~74 ~26 ~110 ~77 ~26 ~110 stained_hardened_clay 0 
setblock ~74 ~26 ~111 stained_glass 3  
fill ~74 ~26 ~112 ~74 ~27 ~112 stained_hardened_clay 9  
fill ~75 ~26 ~85 ~75 ~27 ~85 stained_hardened_clay 9  
fill ~75 ~26 ~111 ~75 ~27 ~111 stained_hardened_clay 9 
setblock ~76 ~26 ~85 stained_hardened_clay 0 
setblock ~76 ~26 ~111 stained_hardened_clay 0  
fill ~77 ~26 ~87 ~79 ~26 ~87 stained_hardened_clay 0  
fill ~77 ~26 ~109 ~79 ~26 ~109 stained_hardened_clay 0  
fill ~78 ~26 ~88 ~80 ~26 ~88 stained_hardened_clay 0  
fill ~78 ~26 ~89 ~80 ~26 ~89 stained_hardened_clay 0  
fill ~78 ~26 ~107 ~80 ~26 ~107 stained_hardened_clay 0  
fill ~78 ~26 ~108 ~80 ~26 ~108 stained_hardened_clay 0  
fill ~80 ~26 ~90 ~81 ~26 ~90 stained_hardened_clay 0  
fill ~80 ~26 ~106 ~81 ~26 ~106 stained_hardened_clay 0  
fill ~81 ~26 ~91 ~82 ~26 ~91 stained_hardened_clay 0  
fill ~81 ~26 ~92 ~81 ~26 ~93 stained_hardened_clay 0  
fill ~81 ~26 ~103 ~81 ~26 ~106 stained_hardened_clay 0  
fill ~82 ~26 ~92 ~82 ~27 ~92 stained_hardened_clay 9 
setblock ~82 ~26 ~93 stained_glass 3  
fill ~82 ~26 ~94 ~83 ~26 ~94 stained_hardened_clay 0  
fill ~82 ~26 ~102 ~83 ~26 ~102 stained_hardened_clay 0 
setblock ~82 ~26 ~103 stained_glass 3  
fill ~82 ~26 ~104 ~82 ~27 ~104 stained_hardened_clay 9 
setblock ~82 ~26 ~105 stained_hardened_clay 0  
fill ~83 ~26 ~93 ~83 ~27 ~93 stained_hardened_clay 9  
fill ~83 ~26 ~95 ~83 ~26 ~102 stained_hardened_clay 0  
fill ~83 ~26 ~103 ~83 ~27 ~103 stained_hardened_clay 9  
fill ~54 ~27 ~93 ~54 ~30 ~93 stained_hardened_clay 9  
fill ~54 ~27 ~94 ~84 ~27 ~94 stained_hardened_clay 9  
fill ~54 ~27 ~95 ~54 ~28 ~95 stained_hardened_clay 0  
fill ~54 ~27 ~96 ~54 ~28 ~96 stained_hardened_clay 0  
fill ~54 ~27 ~97 ~54 ~28 ~97 stained_hardened_clay 0  
fill ~54 ~27 ~98 ~54 ~28 ~98 stained_hardened_clay 0  
fill ~54 ~27 ~99 ~54 ~28 ~99 stained_hardened_clay 0  
fill ~54 ~27 ~100 ~54 ~28 ~100 stained_hardened_clay 0  
fill ~54 ~27 ~101 ~54 ~28 ~101 stained_hardened_clay 0  
fill ~54 ~27 ~102 ~84 ~27 ~102 stained_hardened_clay 9  
fill ~54 ~27 ~103 ~54 ~30 ~103 stained_hardened_clay 9  
fill ~55 ~27 ~91 ~83 ~27 ~91 stained_hardened_clay 9  
fill ~55 ~27 ~92 ~55 ~27 ~91 stained_hardened_clay 9  
fill ~55 ~27 ~95 ~83 ~27 ~95 stained_hardened_clay 9  
fill ~55 ~27 ~96 ~83 ~27 ~96 stained_hardened_clay 9  
fill ~55 ~27 ~97 ~83 ~27 ~97 stained_hardened_clay 9  
fill ~55 ~27 ~98 ~83 ~27 ~98 stained_hardened_clay 9  
fill ~55 ~27 ~99 ~83 ~27 ~99 stained_hardened_clay 9  
fill ~55 ~27 ~100 ~83 ~27 ~100 stained_hardened_clay 9  
fill ~55 ~27 ~101 ~83 ~27 ~101 stained_hardened_clay 9  
fill ~55 ~27 ~104 ~55 ~27 ~105 stained_hardened_clay 9  
fill ~56 ~27 ~89 ~57 ~27 ~89 stained_hardened_clay 0  
fill ~56 ~27 ~90 ~56 ~28 ~90 stained_hardened_clay 0 
setblock ~56 ~27 ~93 sea_lantern 0 
setblock ~56 ~27 ~103 sea_lantern 0  
fill ~56 ~27 ~105 ~83 ~27 ~105 stained_hardened_clay 9  
fill ~56 ~27 ~106 ~56 ~28 ~106 stained_hardened_clay 0  
fill ~56 ~27 ~107 ~57 ~27 ~107 stained_hardened_clay 0  
fill ~57 ~27 ~88 ~57 ~28 ~88 stained_hardened_clay 0  
fill ~57 ~27 ~90 ~81 ~27 ~90 stained_hardened_clay 9  
fill ~57 ~27 ~92 ~83 ~27 ~92 stained_hardened_clay 9  
fill ~57 ~27 ~93 ~81 ~27 ~93 stained_hardened_clay 9  
fill ~57 ~27 ~103 ~81 ~27 ~103 stained_hardened_clay 9  
fill ~57 ~27 ~104 ~83 ~27 ~104 stained_hardened_clay 9  
fill ~57 ~27 ~106 ~81 ~27 ~106 stained_hardened_clay 9  
fill ~57 ~27 ~108 ~57 ~28 ~108 stained_hardened_clay 0  
fill ~58 ~27 ~87 ~58 ~28 ~87 stained_hardened_clay 0  
fill ~58 ~27 ~88 ~80 ~27 ~88 stained_hardened_clay 9  
fill ~58 ~27 ~89 ~80 ~27 ~89 stained_hardened_clay 9  
fill ~58 ~27 ~107 ~80 ~27 ~107 stained_hardened_clay 9  
fill ~58 ~27 ~108 ~80 ~27 ~108 stained_hardened_clay 9  
fill ~58 ~27 ~109 ~58 ~28 ~109 stained_hardened_clay 0  
fill ~59 ~27 ~86 ~60 ~27 ~86 stained_hardened_clay 0  
fill ~59 ~27 ~87 ~79 ~27 ~87 stained_hardened_clay 9  
fill ~59 ~27 ~109 ~79 ~27 ~109 stained_hardened_clay 9  
fill ~59 ~27 ~110 ~60 ~27 ~110 stained_hardened_clay 0  
fill ~60 ~27 ~85 ~61 ~27 ~85 stained_hardened_clay 0  
fill ~60 ~27 ~111 ~61 ~27 ~111 stained_hardened_clay 0  
fill ~61 ~27 ~86 ~77 ~27 ~86 stained_hardened_clay 9  
fill ~61 ~27 ~110 ~77 ~27 ~110 stained_hardened_clay 9  
fill ~62 ~27 ~84 ~76 ~27 ~84 stained_hardened_clay 9  
fill ~62 ~27 ~85 ~62 ~27 ~84 stained_hardened_clay 9  
fill ~62 ~27 ~111 ~62 ~27 ~112 stained_hardened_clay 9 
setblock ~63 ~27 ~112 stained_hardened_clay 9  
fill ~64 ~27 ~83 ~65 ~27 ~83 stained_hardened_clay 9 
setblock ~64 ~27 ~85 sea_lantern 0 
setblock ~64 ~27 ~111 sea_lantern 0  
fill ~64 ~27 ~113 ~65 ~27 ~113 stained_hardened_clay 9  
fill ~65 ~27 ~85 ~73 ~27 ~85 stained_hardened_clay 9  
fill ~65 ~27 ~111 ~73 ~27 ~111 stained_hardened_clay 9  
fill ~65 ~27 ~112 ~76 ~27 ~112 stained_hardened_clay 9  
fill ~66 ~27 ~83 ~72 ~27 ~83 stained_hardened_clay 0  
fill ~66 ~27 ~113 ~72 ~27 ~113 stained_hardened_clay 0  
fill ~73 ~27 ~83 ~74 ~27 ~83 stained_hardened_clay 9  
fill ~73 ~27 ~113 ~74 ~27 ~113 stained_hardened_clay 9 
setblock ~74 ~27 ~85 sea_lantern 0 
setblock ~74 ~27 ~111 sea_lantern 0 
setblock ~76 ~27 ~85 stained_hardened_clay 9 
setblock ~76 ~27 ~111 stained_hardened_clay 9  
fill ~77 ~27 ~85 ~78 ~27 ~85 stained_hardened_clay 0  
fill ~77 ~27 ~111 ~78 ~27 ~111 stained_hardened_clay 0  
fill ~78 ~27 ~86 ~79 ~27 ~86 stained_hardened_clay 0  
fill ~78 ~27 ~110 ~79 ~27 ~110 stained_hardened_clay 0  
fill ~80 ~27 ~87 ~80 ~28 ~87 stained_hardened_clay 0  
fill ~80 ~27 ~109 ~80 ~28 ~109 stained_hardened_clay 0  
fill ~81 ~27 ~88 ~81 ~28 ~88 stained_hardened_clay 0  
fill ~81 ~27 ~89 ~82 ~27 ~89 stained_hardened_clay 0  
fill ~81 ~27 ~107 ~82 ~27 ~107 stained_hardened_clay 0  
fill ~81 ~27 ~108 ~81 ~28 ~108 stained_hardened_clay 0  
fill ~82 ~27 ~90 ~82 ~28 ~90 stained_hardened_clay 0 
setblock ~82 ~27 ~93 sea_lantern 0 
setblock ~82 ~27 ~103 sea_lantern 0  
fill ~82 ~27 ~106 ~82 ~28 ~106 stained_hardened_clay 0  
fill ~84 ~27 ~93 ~84 ~30 ~93 stained_hardened_clay 9  
fill ~84 ~27 ~95 ~84 ~28 ~95 stained_hardened_clay 0  
fill ~84 ~27 ~96 ~84 ~28 ~96 stained_hardened_clay 0  
fill ~84 ~27 ~97 ~84 ~28 ~97 stained_hardened_clay 0  
fill ~84 ~27 ~98 ~84 ~28 ~98 stained_hardened_clay 0  
fill ~84 ~27 ~99 ~84 ~28 ~99 stained_hardened_clay 0  
fill ~84 ~27 ~100 ~84 ~28 ~100 stained_hardened_clay 0  
fill ~84 ~27 ~101 ~84 ~28 ~101 stained_hardened_clay 0  
fill ~84 ~27 ~103 ~84 ~30 ~103 stained_hardened_clay 9  
fill ~53 ~28 ~95 ~53 ~28 ~101 stained_hardened_clay 0  
fill ~54 ~28 ~92 ~54 ~30 ~92 stained_hardened_clay 9  
fill ~54 ~28 ~94 ~54 ~32 ~94 stained_hardened_clay 9  
fill ~54 ~28 ~102 ~54 ~32 ~102 stained_hardened_clay 9  
fill ~54 ~28 ~104 ~54 ~30 ~104 stained_hardened_clay 9  
fill ~55 ~28 ~90 ~55 ~30 ~90 stained_hardened_clay 9  
fill ~55 ~28 ~91 ~55 ~30 ~91 stained_hardened_clay 9  
fill ~55 ~28 ~92 ~83 ~28 ~92 stained_hardened_clay 0  
fill ~55 ~28 ~93 ~83 ~28 ~93 stained_hardened_clay 0  
fill ~55 ~28 ~94 ~83 ~28 ~94 stained_hardened_clay 0  
fill ~55 ~28 ~95 ~85 ~28 ~95 stained_hardened_clay 0  
fill ~55 ~28 ~96 ~85 ~28 ~96 stained_hardened_clay 0  
fill ~55 ~28 ~97 ~85 ~28 ~97 stained_hardened_clay 0  
fill ~55 ~28 ~98 ~85 ~28 ~98 stained_hardened_clay 0  
fill ~55 ~28 ~99 ~85 ~28 ~99 stained_hardened_clay 0  
fill ~55 ~28 ~100 ~85 ~28 ~100 stained_hardened_clay 0  
fill ~55 ~28 ~101 ~85 ~28 ~101 stained_hardened_clay 0  
fill ~55 ~28 ~102 ~83 ~28 ~102 stained_hardened_clay 0  
fill ~55 ~28 ~103 ~83 ~28 ~103 stained_hardened_clay 0  
fill ~55 ~28 ~104 ~83 ~28 ~104 stained_hardened_clay 0  
fill ~55 ~28 ~105 ~55 ~30 ~105 stained_hardened_clay 9  
fill ~55 ~28 ~106 ~55 ~30 ~106 stained_hardened_clay 9  
fill ~56 ~28 ~88 ~56 ~28 ~108 stained_hardened_clay 0 
setblock ~57 ~28 ~87 stained_hardened_clay 0  
fill ~57 ~28 ~89 ~82 ~28 ~89 stained_hardened_clay 0  
fill ~57 ~28 ~90 ~82 ~28 ~90 stained_hardened_clay 0  
fill ~57 ~28 ~91 ~82 ~28 ~91 stained_hardened_clay 0  
fill ~57 ~28 ~105 ~82 ~28 ~105 stained_hardened_clay 0  
fill ~57 ~28 ~106 ~82 ~28 ~106 stained_hardened_clay 0  
fill ~57 ~28 ~107 ~82 ~28 ~107 stained_hardened_clay 0 
setblock ~57 ~28 ~109 stained_hardened_clay 0  
fill ~58 ~28 ~86 ~80 ~28 ~86 stained_hardened_clay 0  
fill ~58 ~28 ~88 ~82 ~28 ~88 stained_hardened_clay 0  
fill ~58 ~28 ~108 ~82 ~28 ~108 stained_hardened_clay 0  
fill ~58 ~28 ~110 ~80 ~28 ~110 stained_hardened_clay 0  
fill ~59 ~28 ~85 ~79 ~28 ~85 stained_hardened_clay 0  
fill ~59 ~28 ~87 ~81 ~28 ~87 stained_hardened_clay 0  
fill ~59 ~28 ~109 ~81 ~28 ~109 stained_hardened_clay 0  
fill ~59 ~28 ~111 ~79 ~28 ~111 stained_hardened_clay 0  
fill ~61 ~28 ~84 ~62 ~28 ~84 stained_hardened_clay 9  
fill ~61 ~28 ~112 ~62 ~28 ~112 stained_hardened_clay 9  
fill ~63 ~28 ~83 ~65 ~28 ~83 stained_hardened_clay 9  
fill ~63 ~28 ~84 ~75 ~28 ~84 stained_hardened_clay 0  
fill ~63 ~28 ~112 ~75 ~28 ~112 stained_hardened_clay 0  
fill ~63 ~28 ~113 ~65 ~28 ~113 stained_hardened_clay 9  
fill ~66 ~28 ~82 ~72 ~28 ~82 stained_hardened_clay 0  
fill ~66 ~28 ~83 ~72 ~28 ~83 stained_hardened_clay 0  
fill ~66 ~28 ~113 ~72 ~28 ~113 stained_hardened_clay 0  
fill ~66 ~28 ~114 ~72 ~28 ~114 stained_hardened_clay 0  
fill ~73 ~28 ~83 ~75 ~28 ~83 stained_hardened_clay 9  
fill ~73 ~28 ~113 ~75 ~28 ~113 stained_hardened_clay 9  
fill ~76 ~28 ~84 ~77 ~28 ~84 stained_hardened_clay 9  
fill ~76 ~28 ~112 ~77 ~28 ~112 stained_hardened_clay 9  
fill ~83 ~28 ~90 ~83 ~30 ~90 stained_hardened_clay 9  
fill ~83 ~28 ~91 ~83 ~30 ~91 stained_hardened_clay 9  
fill ~83 ~28 ~105 ~83 ~30 ~105 stained_hardened_clay 9  
fill ~83 ~28 ~106 ~83 ~30 ~106 stained_hardened_clay 9  
fill ~84 ~28 ~92 ~84 ~30 ~92 stained_hardened_clay 9  
fill ~84 ~28 ~94 ~84 ~32 ~94 stained_hardened_clay 9  
fill ~84 ~28 ~102 ~84 ~32 ~102 stained_hardened_clay 9  
fill ~84 ~28 ~104 ~84 ~30 ~104 stained_hardened_clay 9  
fill ~53 ~29 ~94 ~53 ~30 ~94 stained_hardened_clay 9  
fill ~53 ~29 ~95 ~85 ~29 ~95 stained_hardened_clay 9  
fill ~53 ~29 ~96 ~85 ~29 ~96 stained_hardened_clay 9  
fill ~53 ~29 ~97 ~85 ~29 ~97 stained_hardened_clay 9  
fill ~53 ~29 ~98 ~85 ~29 ~98 stained_hardened_clay 9  
fill ~53 ~29 ~99 ~85 ~29 ~99 stained_hardened_clay 9  
fill ~53 ~29 ~100 ~85 ~29 ~100 stained_hardened_clay 9  
fill ~53 ~29 ~101 ~85 ~29 ~101 stained_hardened_clay 9  
fill ~53 ~29 ~102 ~53 ~30 ~102 stained_hardened_clay 9  
fill ~55 ~29 ~92 ~84 ~29 ~92 stained_hardened_clay 9  
fill ~55 ~29 ~93 ~84 ~29 ~93 stained_hardened_clay 9  
fill ~55 ~29 ~94 ~85 ~29 ~94 stained_hardened_clay 9  
fill ~55 ~29 ~102 ~85 ~29 ~102 stained_hardened_clay 9  
fill ~55 ~29 ~103 ~84 ~29 ~103 stained_hardened_clay 9  
fill ~55 ~29 ~104 ~84 ~29 ~104 stained_hardened_clay 9  
fill ~56 ~29 ~88 ~82 ~29 ~88 stained_hardened_clay 9  
fill ~56 ~29 ~89 ~82 ~29 ~89 stained_hardened_clay 9  
fill ~56 ~29 ~90 ~83 ~29 ~90 stained_hardened_clay 9  
fill ~56 ~29 ~91 ~83 ~29 ~91 stained_hardened_clay 9  
fill ~56 ~29 ~105 ~83 ~29 ~105 stained_hardened_clay 9  
fill ~56 ~29 ~106 ~83 ~29 ~106 stained_hardened_clay 9  
fill ~56 ~29 ~107 ~82 ~29 ~107 stained_hardened_clay 9  
fill ~56 ~29 ~108 ~82 ~29 ~108 stained_hardened_clay 9  
fill ~57 ~29 ~87 ~81 ~29 ~87 stained_hardened_clay 9  
fill ~57 ~29 ~109 ~81 ~29 ~109 stained_hardened_clay 9  
fill ~58 ~29 ~86 ~80 ~29 ~86 stained_hardened_clay 9  
fill ~58 ~29 ~110 ~80 ~29 ~110 stained_hardened_clay 9  
fill ~59 ~29 ~85 ~79 ~29 ~85 stained_hardened_clay 9  
fill ~59 ~29 ~111 ~79 ~29 ~111 stained_hardened_clay 9  
fill ~61 ~29 ~84 ~77 ~29 ~84 stained_hardened_clay 9  
fill ~61 ~29 ~112 ~77 ~29 ~112 stained_hardened_clay 9  
fill ~63 ~29 ~83 ~75 ~29 ~83 stained_hardened_clay 9  
fill ~63 ~29 ~113 ~75 ~29 ~113 stained_hardened_clay 9  
fill ~65 ~29 ~82 ~73 ~29 ~82 stained_hardened_clay 9  
fill ~65 ~29 ~114 ~73 ~29 ~114 stained_hardened_clay 9 
setblock ~49 ~30 ~95 stained_glass_pane 3 
setblock ~49 ~30 ~96 stained_glass 3 
setblock ~49 ~30 ~97 stained_glass_pane 3 
setblock ~49 ~30 ~99 stained_glass_pane 3 
setblock ~49 ~30 ~100 stained_glass 3 
setblock ~49 ~30 ~101 stained_glass_pane 3  
fill ~51 ~30 ~94 ~52 ~30 ~94 concrete 1  
fill ~51 ~30 ~95 ~52 ~30 ~95 concrete 1  
fill ~51 ~30 ~96 ~52 ~30 ~96 concrete 1  
fill ~51 ~30 ~97 ~52 ~30 ~97 concrete 1  
fill ~51 ~30 ~98 ~63 ~30 ~98 stained_hardened_clay 9  
fill ~51 ~30 ~99 ~52 ~30 ~99 concrete 1  
fill ~51 ~30 ~100 ~52 ~30 ~100 concrete 1  
fill ~51 ~30 ~101 ~52 ~30 ~101 concrete 1  
fill ~51 ~30 ~102 ~52 ~30 ~102 concrete 1  
fill ~53 ~30 ~95 ~63 ~30 ~95 stained_hardened_clay 9  
fill ~53 ~30 ~96 ~63 ~30 ~96 stained_hardened_clay 9  
fill ~53 ~30 ~97 ~63 ~30 ~97 stained_hardened_clay 9  
fill ~53 ~30 ~99 ~63 ~30 ~99 stained_hardened_clay 9  
fill ~53 ~30 ~100 ~63 ~30 ~100 stained_hardened_clay 9  
fill ~53 ~30 ~101 ~63 ~30 ~101 stained_hardened_clay 9  
fill ~55 ~30 ~92 ~63 ~30 ~92 stained_hardened_clay 9  
fill ~55 ~30 ~93 ~55 ~32 ~93 stained_hardened_clay 9  
fill ~55 ~30 ~94 ~63 ~30 ~94 stained_hardened_clay 9  
fill ~55 ~30 ~102 ~63 ~30 ~102 stained_hardened_clay 9  
fill ~55 ~30 ~103 ~55 ~32 ~103 stained_hardened_clay 9  
fill ~55 ~30 ~104 ~63 ~30 ~104 stained_hardened_clay 9  
fill ~56 ~30 ~88 ~63 ~30 ~88 stained_hardened_clay 9  
fill ~56 ~30 ~89 ~63 ~30 ~89 stained_hardened_clay 9  
fill ~56 ~30 ~90 ~63 ~30 ~90 stained_hardened_clay 9  
fill ~56 ~30 ~91 ~63 ~30 ~91 stained_hardened_clay 9  
fill ~56 ~30 ~93 ~82 ~30 ~93 sea_lantern 0  
fill ~56 ~30 ~103 ~82 ~30 ~103 sea_lantern 0  
fill ~56 ~30 ~105 ~63 ~30 ~105 stained_hardened_clay 9  
fill ~56 ~30 ~106 ~63 ~30 ~106 stained_hardened_clay 9  
fill ~56 ~30 ~107 ~63 ~30 ~107 stained_hardened_clay 9  
fill ~56 ~30 ~108 ~63 ~30 ~108 stained_hardened_clay 9  
fill ~57 ~30 ~87 ~63 ~30 ~87 stained_hardened_clay 9  
fill ~57 ~30 ~109 ~63 ~30 ~109 stained_hardened_clay 9  
fill ~58 ~30 ~86 ~63 ~30 ~86 stained_hardened_clay 9  
fill ~58 ~30 ~110 ~63 ~30 ~110 stained_hardened_clay 9  
fill ~59 ~30 ~85 ~63 ~30 ~85 stained_hardened_clay 9  
fill ~59 ~30 ~111 ~63 ~30 ~111 stained_hardened_clay 9  
fill ~61 ~30 ~84 ~77 ~30 ~84 stained_hardened_clay 9  
fill ~61 ~30 ~112 ~77 ~30 ~112 stained_hardened_clay 9  
fill ~63 ~30 ~83 ~75 ~30 ~83 stained_hardened_clay 9  
fill ~63 ~30 ~113 ~75 ~30 ~113 stained_hardened_clay 9  
fill ~64 ~30 ~85 ~64 ~30 ~111 sea_lantern 0  
fill ~65 ~30 ~80 ~68 ~30 ~80 concrete 1  
fill ~65 ~30 ~81 ~68 ~30 ~81 concrete 1  
fill ~65 ~30 ~82 ~73 ~30 ~82 stained_hardened_clay 9  
fill ~65 ~30 ~85 ~73 ~30 ~85 stained_hardened_clay 9  
fill ~65 ~30 ~86 ~73 ~30 ~86 stained_hardened_clay 9  
fill ~65 ~30 ~87 ~73 ~30 ~87 stained_hardened_clay 9  
fill ~65 ~30 ~88 ~73 ~30 ~88 stained_hardened_clay 9  
fill ~65 ~30 ~89 ~73 ~30 ~89 stained_hardened_clay 9  
fill ~65 ~30 ~90 ~73 ~30 ~90 stained_hardened_clay 9  
fill ~65 ~30 ~91 ~73 ~30 ~91 stained_hardened_clay 9  
fill ~65 ~30 ~92 ~73 ~30 ~92 stained_hardened_clay 9  
fill ~65 ~30 ~94 ~73 ~30 ~94 stained_hardened_clay 9  
fill ~65 ~30 ~95 ~73 ~30 ~95 stained_hardened_clay 9  
fill ~65 ~30 ~96 ~73 ~30 ~96 stained_hardened_clay 9  
fill ~65 ~30 ~97 ~73 ~30 ~97 stained_hardened_clay 9  
fill ~65 ~30 ~98 ~73 ~30 ~98 stained_hardened_clay 9  
fill ~65 ~30 ~99 ~73 ~30 ~99 stained_hardened_clay 9  
fill ~65 ~30 ~100 ~73 ~30 ~100 stained_hardened_clay 9  
fill ~65 ~30 ~101 ~73 ~30 ~101 stained_hardened_clay 9  
fill ~65 ~30 ~102 ~73 ~30 ~102 stained_hardened_clay 9  
fill ~65 ~30 ~104 ~73 ~30 ~104 stained_hardened_clay 9  
fill ~65 ~30 ~105 ~73 ~30 ~105 stained_hardened_clay 9  
fill ~65 ~30 ~106 ~73 ~30 ~106 stained_hardened_clay 9  
fill ~65 ~30 ~107 ~73 ~30 ~107 stained_hardened_clay 9  
fill ~65 ~30 ~108 ~73 ~30 ~108 stained_hardened_clay 9  
fill ~65 ~30 ~109 ~73 ~30 ~109 stained_hardened_clay 9  
fill ~65 ~30 ~110 ~73 ~30 ~110 stained_hardened_clay 9  
fill ~65 ~30 ~111 ~73 ~30 ~111 stained_hardened_clay 9  
fill ~65 ~30 ~114 ~73 ~30 ~114 stained_hardened_clay 9  
fill ~65 ~30 ~115 ~68 ~30 ~115 concrete 1  
fill ~65 ~30 ~116 ~68 ~30 ~116 concrete 1 
setblock ~66 ~30 ~78 stained_glass_pane 3 
setblock ~66 ~30 ~118 stained_glass_pane 3 
setblock ~67 ~30 ~78 stained_glass 3 
setblock ~67 ~30 ~118 stained_glass 3 
setblock ~68 ~30 ~78 stained_glass_pane 3 
setblock ~68 ~30 ~118 stained_glass_pane 3  
fill ~69 ~30 ~80 ~69 ~30 ~92 stained_hardened_clay 9  
fill ~69 ~30 ~115 ~69 ~31 ~115 stained_hardened_clay 9  
fill ~69 ~30 ~116 ~69 ~30 ~104 stained_hardened_clay 9 
setblock ~70 ~30 ~78 stained_glass_pane 3  
fill ~70 ~30 ~80 ~73 ~30 ~80 concrete 1  
fill ~70 ~30 ~81 ~73 ~30 ~81 concrete 1  
fill ~70 ~30 ~115 ~73 ~30 ~115 concrete 1  
fill ~70 ~30 ~116 ~73 ~30 ~116 concrete 1 
setblock ~70 ~30 ~118 stained_glass_pane 3 
setblock ~71 ~30 ~78 stained_glass 3 
setblock ~71 ~30 ~118 stained_glass 3 
setblock ~72 ~30 ~78 stained_glass_pane 3 
setblock ~72 ~30 ~118 stained_glass_pane 3  
fill ~74 ~30 ~85 ~74 ~30 ~111 sea_lantern 0  
fill ~75 ~30 ~85 ~79 ~30 ~85 stained_hardened_clay 9  
fill ~75 ~30 ~86 ~80 ~30 ~86 stained_hardened_clay 9  
fill ~75 ~30 ~87 ~81 ~30 ~87 stained_hardened_clay 9  
fill ~75 ~30 ~88 ~82 ~30 ~88 stained_hardened_clay 9  
fill ~75 ~30 ~89 ~82 ~30 ~89 stained_hardened_clay 9  
fill ~75 ~30 ~90 ~83 ~30 ~90 stained_hardened_clay 9  
fill ~75 ~30 ~91 ~83 ~30 ~91 stained_hardened_clay 9  
fill ~75 ~30 ~92 ~84 ~30 ~92 stained_hardened_clay 9  
fill ~75 ~30 ~94 ~85 ~30 ~94 stained_hardened_clay 9  
fill ~75 ~30 ~95 ~85 ~30 ~95 stained_hardened_clay 9  
fill ~75 ~30 ~96 ~85 ~30 ~96 stained_hardened_clay 9  
fill ~75 ~30 ~97 ~85 ~30 ~97 stained_hardened_clay 9  
fill ~75 ~30 ~98 ~87 ~30 ~98 stained_hardened_clay 9  
fill ~75 ~30 ~99 ~85 ~30 ~99 stained_hardened_clay 9  
fill ~75 ~30 ~100 ~85 ~30 ~100 stained_hardened_clay 9  
fill ~75 ~30 ~101 ~85 ~30 ~101 stained_hardened_clay 9  
fill ~75 ~30 ~102 ~85 ~30 ~102 stained_hardened_clay 9  
fill ~75 ~30 ~104 ~84 ~30 ~104 stained_hardened_clay 9  
fill ~75 ~30 ~105 ~83 ~30 ~105 stained_hardened_clay 9  
fill ~75 ~30 ~106 ~83 ~30 ~106 stained_hardened_clay 9  
fill ~75 ~30 ~107 ~82 ~30 ~107 stained_hardened_clay 9  
fill ~75 ~30 ~108 ~82 ~30 ~108 stained_hardened_clay 9  
fill ~75 ~30 ~109 ~81 ~30 ~109 stained_hardened_clay 9  
fill ~75 ~30 ~110 ~80 ~30 ~110 stained_hardened_clay 9  
fill ~75 ~30 ~111 ~79 ~30 ~111 stained_hardened_clay 9  
fill ~83 ~30 ~93 ~83 ~32 ~93 stained_hardened_clay 9  
fill ~83 ~30 ~103 ~83 ~32 ~103 stained_hardened_clay 9  
fill ~86 ~30 ~94 ~87 ~30 ~94 concrete 1  
fill ~86 ~30 ~95 ~87 ~30 ~95 concrete 1  
fill ~86 ~30 ~96 ~87 ~30 ~96 concrete 1  
fill ~86 ~30 ~97 ~87 ~30 ~97 concrete 1  
fill ~86 ~30 ~99 ~87 ~30 ~99 concrete 1  
fill ~86 ~30 ~100 ~87 ~30 ~100 concrete 1  
fill ~86 ~30 ~101 ~87 ~30 ~101 concrete 1  
fill ~86 ~30 ~102 ~87 ~30 ~102 concrete 1 
setblock ~89 ~30 ~95 stained_glass_pane 3 
setblock ~89 ~30 ~96 stained_glass 3 
setblock ~89 ~30 ~97 stained_glass_pane 3 
setblock ~89 ~30 ~99 stained_glass_pane 3 
setblock ~89 ~30 ~100 stained_glass 3 
setblock ~89 ~30 ~101 stained_glass_pane 3  
fill ~48 ~31 ~95 ~48 ~32 ~95 stained_hardened_clay 0  
fill ~48 ~31 ~96 ~48 ~32 ~96 stained_hardened_clay 0  
fill ~48 ~31 ~97 ~48 ~32 ~97 stained_hardened_clay 0  
fill ~48 ~31 ~98 ~50 ~31 ~98 stained_hardened_clay 9  
fill ~48 ~31 ~99 ~48 ~32 ~99 stained_hardened_clay 0  
fill ~48 ~31 ~100 ~48 ~32 ~100 stained_hardened_clay 0  
fill ~48 ~31 ~101 ~48 ~32 ~101 stained_hardened_clay 0  
fill ~49 ~31 ~95 ~50 ~31 ~95 stained_hardened_clay 9 
setblock ~49 ~31 ~96 sea_lantern 0  
fill ~49 ~31 ~97 ~50 ~31 ~97 stained_hardened_clay 9  
fill ~49 ~31 ~99 ~50 ~31 ~99 stained_hardened_clay 9 
setblock ~49 ~31 ~100 sea_lantern 0  
fill ~49 ~31 ~101 ~50 ~31 ~101 stained_hardened_clay 9 
setblock ~50 ~31 ~96 stained_hardened_clay 9 
setblock ~50 ~31 ~100 stained_hardened_clay 9  
fill ~51 ~31 ~93 ~52 ~31 ~93 concrete 1  
fill ~51 ~31 ~94 ~52 ~31 ~94 concrete 1  
fill ~51 ~31 ~95 ~52 ~31 ~95 concrete 1  
fill ~51 ~31 ~96 ~52 ~31 ~96 concrete 1  
fill ~51 ~31 ~97 ~52 ~31 ~97 concrete 1  
fill ~51 ~31 ~98 ~51 ~31 ~103 concrete 1 
setblock ~52 ~31 ~98 stained_hardened_clay 9  
fill ~52 ~31 ~99 ~52 ~31 ~103 concrete 1  
fill ~53 ~31 ~94 ~53 ~31 ~102 stained_hardened_clay 0  
fill ~54 ~31 ~92 ~54 ~31 ~93 stained_hardened_clay 0  
fill ~54 ~31 ~95 ~54 ~32 ~95 stained_hardened_clay 9  
fill ~54 ~31 ~96 ~54 ~32 ~96 stained_hardened_clay 9  
fill ~54 ~31 ~97 ~54 ~32 ~97 stained_hardened_clay 9  
fill ~54 ~31 ~98 ~54 ~32 ~98 stained_hardened_clay 9  
fill ~54 ~31 ~99 ~54 ~32 ~99 stained_hardened_clay 9  
fill ~54 ~31 ~100 ~54 ~32 ~100 stained_hardened_clay 9  
fill ~54 ~31 ~101 ~54 ~32 ~101 stained_hardened_clay 9  
fill ~54 ~31 ~103 ~54 ~31 ~104 stained_hardened_clay 0  
fill ~55 ~31 ~90 ~55 ~31 ~91 stained_hardened_clay 0  
fill ~55 ~31 ~92 ~63 ~31 ~92 stained_hardened_clay 9  
fill ~55 ~31 ~94 ~63 ~31 ~94 stained_hardened_clay 9  
fill ~55 ~31 ~95 ~58 ~31 ~95 obsidian 0  
fill ~55 ~31 ~96 ~58 ~31 ~96 obsidian 0  
fill ~55 ~31 ~97 ~58 ~31 ~97 obsidian 0  
fill ~55 ~31 ~98 ~58 ~31 ~98 obsidian 0  
fill ~55 ~31 ~99 ~58 ~31 ~99 obsidian 0  
fill ~55 ~31 ~100 ~58 ~31 ~100 obsidian 0  
fill ~55 ~31 ~101 ~58 ~31 ~101 obsidian 0  
fill ~55 ~31 ~102 ~63 ~31 ~102 stained_hardened_clay 9  
fill ~55 ~31 ~104 ~63 ~31 ~104 stained_hardened_clay 9  
fill ~55 ~31 ~105 ~55 ~31 ~106 stained_hardened_clay 0  
fill ~56 ~31 ~88 ~56 ~31 ~89 stained_hardened_clay 0  
fill ~56 ~31 ~90 ~57 ~31 ~90 stained_hardened_clay 9  
fill ~56 ~31 ~91 ~56 ~32 ~91 stained_hardened_clay 9  
fill ~56 ~31 ~93 ~82 ~31 ~93 stained_glass 3  
fill ~56 ~31 ~103 ~82 ~31 ~103 stained_glass 3  
fill ~56 ~31 ~105 ~56 ~32 ~105 stained_hardened_clay 9  
fill ~56 ~31 ~106 ~57 ~31 ~106 stained_hardened_clay 9  
fill ~56 ~31 ~107 ~56 ~31 ~108 stained_hardened_clay 0 
setblock ~57 ~31 ~87 stained_hardened_clay 0  
fill ~57 ~31 ~88 ~59 ~31 ~88 stained_hardened_clay 9  
fill ~57 ~31 ~89 ~58 ~31 ~89 stained_hardened_clay 9  
fill ~57 ~31 ~91 ~62 ~31 ~91 obsidian 0  
fill ~57 ~31 ~105 ~62 ~31 ~105 obsidian 0  
fill ~57 ~31 ~107 ~58 ~31 ~107 stained_hardened_clay 9  
fill ~57 ~31 ~108 ~59 ~31 ~108 stained_hardened_clay 9 
setblock ~57 ~31 ~109 stained_hardened_clay 0 
setblock ~58 ~31 ~86 stained_hardened_clay 0  
fill ~58 ~31 ~87 ~60 ~31 ~87 stained_hardened_clay 9  
fill ~58 ~31 ~90 ~62 ~31 ~90 obsidian 0  
fill ~58 ~31 ~106 ~62 ~31 ~106 obsidian 0  
fill ~58 ~31 ~109 ~60 ~31 ~109 stained_hardened_clay 9 
setblock ~58 ~31 ~110 stained_hardened_clay 0  
fill ~59 ~31 ~85 ~60 ~31 ~85 stained_hardened_clay 0  
fill ~59 ~31 ~86 ~61 ~31 ~86 stained_hardened_clay 9  
fill ~59 ~31 ~89 ~62 ~31 ~89 obsidian 0  
fill ~59 ~31 ~95 ~63 ~31 ~95 stained_hardened_clay 9  
fill ~59 ~31 ~96 ~63 ~31 ~96 stained_hardened_clay 9  
fill ~59 ~31 ~97 ~63 ~31 ~97 stained_hardened_clay 9  
fill ~59 ~31 ~98 ~63 ~31 ~98 stained_hardened_clay 9  
fill ~59 ~31 ~99 ~63 ~31 ~99 stained_hardened_clay 9  
fill ~59 ~31 ~100 ~63 ~31 ~100 stained_hardened_clay 9  
fill ~59 ~31 ~101 ~63 ~31 ~101 stained_hardened_clay 9  
fill ~59 ~31 ~107 ~62 ~31 ~107 obsidian 0  
fill ~59 ~31 ~110 ~61 ~31 ~110 stained_hardened_clay 9  
fill ~59 ~31 ~111 ~60 ~31 ~111 stained_hardened_clay 0  
fill ~60 ~31 ~88 ~62 ~31 ~88 obsidian 0  
fill ~60 ~31 ~108 ~62 ~31 ~108 obsidian 0  
fill ~61 ~31 ~84 ~62 ~31 ~84 stained_hardened_clay 0  
fill ~61 ~31 ~85 ~63 ~31 ~85 stained_hardened_clay 9  
fill ~61 ~31 ~87 ~62 ~31 ~87 obsidian 0  
fill ~61 ~31 ~109 ~62 ~31 ~109 obsidian 0  
fill ~61 ~31 ~111 ~63 ~31 ~111 stained_hardened_clay 9  
fill ~61 ~31 ~112 ~62 ~31 ~112 stained_hardened_clay 0 
setblock ~62 ~31 ~86 obsidian 0 
setblock ~62 ~31 ~110 obsidian 0  
fill ~63 ~31 ~83 ~64 ~31 ~83 stained_hardened_clay 0  
fill ~63 ~31 ~84 ~65 ~31 ~84 stained_hardened_clay 9  
fill ~63 ~31 ~86 ~63 ~31 ~92 stained_hardened_clay 9  
fill ~63 ~31 ~105 ~63 ~31 ~112 stained_hardened_clay 9  
fill ~63 ~31 ~113 ~64 ~31 ~113 stained_hardened_clay 0  
fill ~64 ~31 ~80 ~74 ~31 ~80 concrete 1  
fill ~64 ~31 ~81 ~68 ~31 ~81 concrete 1  
fill ~64 ~31 ~85 ~64 ~31 ~111 stained_glass 3  
fill ~64 ~31 ~112 ~65 ~31 ~112 stained_hardened_clay 9  
fill ~64 ~31 ~115 ~68 ~31 ~115 concrete 1  
fill ~64 ~31 ~116 ~74 ~31 ~116 concrete 1  
fill ~65 ~31 ~82 ~73 ~31 ~82 stained_hardened_clay 0  
fill ~65 ~31 ~83 ~73 ~31 ~83 stained_hardened_clay 9  
fill ~65 ~31 ~85 ~65 ~29 ~85 stained_hardened_clay 9  
fill ~65 ~31 ~86 ~65 ~29 ~86 stained_hardened_clay 9  
fill ~65 ~31 ~87 ~65 ~29 ~87 stained_hardened_clay 9  
fill ~65 ~31 ~88 ~73 ~31 ~88 stained_hardened_clay 9  
fill ~65 ~31 ~89 ~73 ~31 ~89 stained_hardened_clay 9  
fill ~65 ~31 ~90 ~73 ~31 ~90 stained_hardened_clay 9  
fill ~65 ~31 ~91 ~73 ~31 ~91 stained_hardened_clay 9  
fill ~65 ~31 ~92 ~73 ~31 ~92 stained_hardened_clay 9  
fill ~65 ~31 ~94 ~73 ~31 ~94 stained_hardened_clay 9  
fill ~65 ~31 ~95 ~65 ~29 ~95 stained_hardened_clay 9  
fill ~65 ~31 ~96 ~65 ~29 ~96 stained_hardened_clay 9  
fill ~65 ~31 ~97 ~65 ~29 ~97 stained_hardened_clay 9  
fill ~65 ~31 ~98 ~65 ~29 ~98 stained_hardened_clay 9  
fill ~65 ~31 ~99 ~65 ~29 ~99 stained_hardened_clay 9  
fill ~65 ~31 ~100 ~65 ~29 ~100 stained_hardened_clay 9  
fill ~65 ~31 ~101 ~65 ~29 ~101 stained_hardened_clay 9  
fill ~65 ~31 ~102 ~73 ~31 ~102 stained_hardened_clay 9  
fill ~65 ~31 ~104 ~73 ~31 ~104 stained_hardened_clay 9  
fill ~65 ~31 ~105 ~73 ~31 ~105 stained_hardened_clay 9  
fill ~65 ~31 ~106 ~73 ~31 ~106 stained_hardened_clay 9  
fill ~65 ~31 ~107 ~73 ~31 ~107 stained_hardened_clay 9  
fill ~65 ~31 ~108 ~73 ~31 ~108 stained_hardened_clay 9  
fill ~65 ~31 ~109 ~65 ~29 ~109 stained_hardened_clay 9  
fill ~65 ~31 ~110 ~65 ~29 ~110 stained_hardened_clay 9  
fill ~65 ~31 ~111 ~65 ~29 ~111 stained_hardened_clay 9  
fill ~65 ~31 ~113 ~73 ~31 ~113 stained_hardened_clay 9  
fill ~65 ~31 ~114 ~73 ~31 ~114 stained_hardened_clay 0  
fill ~66 ~31 ~77 ~68 ~31 ~77 stained_hardened_clay 0  
fill ~66 ~31 ~78 ~66 ~31 ~79 stained_hardened_clay 9  
fill ~66 ~31 ~84 ~72 ~31 ~84 obsidian 0  
fill ~66 ~31 ~85 ~72 ~31 ~85 obsidian 0  
fill ~66 ~31 ~86 ~72 ~31 ~86 obsidian 0  
fill ~66 ~31 ~87 ~72 ~31 ~87 obsidian 0  
fill ~66 ~31 ~95 ~72 ~31 ~95 obsidian 0  
fill ~66 ~31 ~96 ~72 ~31 ~96 obsidian 0  
fill ~66 ~31 ~97 ~72 ~31 ~97 obsidian 0  
fill ~66 ~31 ~98 ~72 ~31 ~98 obsidian 0  
fill ~66 ~31 ~99 ~72 ~31 ~99 obsidian 0  
fill ~66 ~31 ~100 ~72 ~31 ~100 obsidian 0  
fill ~66 ~31 ~101 ~72 ~31 ~101 obsidian 0  
fill ~66 ~31 ~109 ~72 ~31 ~109 obsidian 0  
fill ~66 ~31 ~110 ~72 ~31 ~110 obsidian 0  
fill ~66 ~31 ~111 ~72 ~31 ~111 obsidian 0  
fill ~66 ~31 ~112 ~72 ~31 ~112 obsidian 0  
fill ~66 ~31 ~117 ~72 ~31 ~117 stained_hardened_clay 9  
fill ~66 ~31 ~118 ~66 ~31 ~117 stained_hardened_clay 9  
fill ~66 ~31 ~119 ~68 ~31 ~119 stained_hardened_clay 0 
setblock ~67 ~31 ~78 sea_lantern 0  
fill ~67 ~31 ~79 ~72 ~31 ~79 stained_hardened_clay 9 
setblock ~67 ~31 ~118 sea_lantern 0  
fill ~68 ~31 ~78 ~70 ~31 ~78 stained_hardened_clay 9  
fill ~68 ~31 ~118 ~70 ~31 ~118 stained_hardened_clay 9 
setblock ~69 ~31 ~77 stained_hardened_clay 9 
setblock ~69 ~31 ~81 stained_hardened_clay 9 
setblock ~69 ~31 ~119 stained_hardened_clay 9  
fill ~70 ~31 ~77 ~72 ~31 ~77 stained_hardened_clay 0  
fill ~70 ~31 ~81 ~74 ~31 ~81 concrete 1  
fill ~70 ~31 ~115 ~74 ~31 ~115 concrete 1  
fill ~70 ~31 ~119 ~72 ~31 ~119 stained_hardened_clay 0 
setblock ~71 ~31 ~78 sea_lantern 0 
setblock ~71 ~31 ~118 sea_lantern 0 
setblock ~72 ~31 ~78 stained_hardened_clay 9 
setblock ~72 ~31 ~118 stained_hardened_clay 9  
fill ~73 ~31 ~84 ~75 ~31 ~84 stained_hardened_clay 9  
fill ~73 ~31 ~85 ~73 ~31 ~92 stained_hardened_clay 9  
fill ~73 ~31 ~95 ~73 ~31 ~102 stained_hardened_clay 9  
fill ~73 ~31 ~109 ~73 ~31 ~113 stained_hardened_clay 9  
fill ~74 ~31 ~83 ~75 ~31 ~83 stained_hardened_clay 0  
fill ~74 ~31 ~85 ~74 ~31 ~111 stained_glass 3  
fill ~74 ~31 ~112 ~75 ~31 ~112 stained_hardened_clay 9  
fill ~74 ~31 ~113 ~75 ~31 ~113 stained_hardened_clay 0  
fill ~75 ~31 ~85 ~77 ~31 ~85 stained_hardened_clay 9  
fill ~75 ~31 ~86 ~75 ~29 ~86 stained_hardened_clay 9  
fill ~75 ~31 ~87 ~75 ~29 ~87 stained_hardened_clay 9  
fill ~75 ~31 ~88 ~75 ~29 ~88 stained_hardened_clay 9  
fill ~75 ~31 ~89 ~75 ~29 ~89 stained_hardened_clay 9  
fill ~75 ~31 ~90 ~75 ~29 ~90 stained_hardened_clay 9  
fill ~75 ~31 ~91 ~75 ~29 ~91 stained_hardened_clay 9  
fill ~75 ~31 ~92 ~83 ~31 ~92 stained_hardened_clay 9  
fill ~75 ~31 ~94 ~84 ~31 ~94 stained_hardened_clay 9  
fill ~75 ~31 ~95 ~79 ~31 ~95 stained_hardened_clay 9  
fill ~75 ~31 ~96 ~79 ~31 ~96 stained_hardened_clay 9  
fill ~75 ~31 ~97 ~79 ~31 ~97 stained_hardened_clay 9  
fill ~75 ~31 ~98 ~79 ~31 ~98 stained_hardened_clay 9  
fill ~75 ~31 ~99 ~79 ~31 ~99 stained_hardened_clay 9  
fill ~75 ~31 ~100 ~79 ~31 ~100 stained_hardened_clay 9  
fill ~75 ~31 ~101 ~79 ~31 ~101 stained_hardened_clay 9  
fill ~75 ~31 ~102 ~84 ~31 ~102 stained_hardened_clay 9  
fill ~75 ~31 ~104 ~83 ~31 ~104 stained_hardened_clay 9  
fill ~75 ~31 ~105 ~75 ~29 ~105 stained_hardened_clay 9  
fill ~75 ~31 ~106 ~75 ~29 ~106 stained_hardened_clay 9  
fill ~75 ~31 ~107 ~75 ~29 ~107 stained_hardened_clay 9  
fill ~75 ~31 ~108 ~75 ~29 ~108 stained_hardened_clay 9  
fill ~75 ~31 ~109 ~75 ~29 ~109 stained_hardened_clay 9  
fill ~75 ~31 ~110 ~75 ~29 ~110 stained_hardened_clay 9  
fill ~75 ~31 ~111 ~77 ~31 ~111 stained_hardened_clay 9  
fill ~76 ~31 ~84 ~77 ~31 ~84 stained_hardened_clay 0  
fill ~76 ~31 ~86 ~76 ~31 ~91 obsidian 0  
fill ~76 ~31 ~105 ~81 ~31 ~105 obsidian 0  
fill ~76 ~31 ~106 ~80 ~31 ~106 obsidian 0  
fill ~76 ~31 ~107 ~79 ~31 ~107 obsidian 0   
fill ~76 ~31 ~108 ~78 ~31 ~108 obsidian 0  
fill ~76 ~31 ~109 ~77 ~31 ~109 obsidian 0  
fill ~76 ~31 ~110 ~76 ~31 ~105 obsidian 0  
fill ~76 ~31 ~112 ~77 ~31 ~112 stained_hardened_clay 0  
fill ~77 ~31 ~86 ~79 ~31 ~86 stained_hardened_clay 9  
fill ~77 ~31 ~87 ~77 ~31 ~91 obsidian 0  
fill ~77 ~31 ~110 ~79 ~31 ~110 stained_hardened_clay 9  
fill ~78 ~31 ~85 ~79 ~31 ~85 stained_hardened_clay 0  
fill ~78 ~31 ~87 ~80 ~31 ~87 stained_hardened_clay 9  
fill ~78 ~31 ~88 ~78 ~31 ~91 obsidian 0  
fill ~78 ~31 ~109 ~80 ~31 ~109 stained_hardened_clay 9  
fill ~78 ~31 ~111 ~79 ~31 ~111 stained_hardened_clay 0  
fill ~79 ~31 ~88 ~81 ~31 ~88 stained_hardened_clay 9  
fill ~79 ~31 ~89 ~79 ~31 ~91 obsidian 0  
fill ~79 ~31 ~108 ~81 ~31 ~108 stained_hardened_clay 9 
setblock ~80 ~31 ~86 stained_hardened_clay 0  
fill ~80 ~31 ~89 ~81 ~31 ~89 stained_hardened_clay 9  
fill ~80 ~31 ~90 ~80 ~31 ~91 obsidian 0  
fill ~80 ~31 ~95 ~83 ~31 ~95 obsidian 0  
fill ~80 ~31 ~96 ~83 ~31 ~96 obsidian 0  
fill ~80 ~31 ~97 ~83 ~31 ~97 obsidian 0  
fill ~80 ~31 ~98 ~83 ~31 ~98 obsidian 0  
fill ~80 ~31 ~99 ~83 ~31 ~99 obsidian 0  
fill ~80 ~31 ~100 ~83 ~31 ~100 obsidian 0  
fill ~80 ~31 ~101 ~83 ~31 ~101 obsidian 0  
fill ~80 ~31 ~107 ~81 ~31 ~107 stained_hardened_clay 9 
setblock ~80 ~31 ~110 stained_hardened_clay 0 
setblock ~81 ~31 ~87 stained_hardened_clay 0  
fill ~81 ~31 ~90 ~82 ~31 ~90 stained_hardened_clay 9 
setblock ~81 ~31 ~91 obsidian 0  
fill ~81 ~31 ~106 ~82 ~31 ~106 stained_hardened_clay 9 
setblock ~81 ~31 ~109 stained_hardened_clay 0  
fill ~82 ~31 ~88 ~82 ~31 ~89 stained_hardened_clay 0  
fill ~82 ~31 ~91 ~82 ~32 ~91 stained_hardened_clay 9  
fill ~82 ~31 ~105 ~82 ~32 ~105 stained_hardened_clay 9  
fill ~82 ~31 ~107 ~82 ~31 ~108 stained_hardened_clay 0  
fill ~83 ~31 ~90 ~83 ~31 ~91 stained_hardened_clay 0  
fill ~83 ~31 ~105 ~83 ~31 ~106 stained_hardened_clay 0  
fill ~84 ~31 ~92 ~84 ~31 ~93 stained_hardened_clay 0  
fill ~84 ~31 ~95 ~84 ~32 ~95 stained_hardened_clay 9  
fill ~84 ~31 ~96 ~84 ~32 ~96 stained_hardened_clay 9  
fill ~84 ~31 ~97 ~84 ~32 ~97 stained_hardened_clay 9  
fill ~84 ~31 ~98 ~84 ~32 ~98 stained_hardened_clay 9  
fill ~84 ~31 ~99 ~84 ~32 ~99 stained_hardened_clay 9  
fill ~84 ~31 ~100 ~84 ~32 ~100 stained_hardened_clay 9  
fill ~84 ~31 ~101 ~84 ~32 ~101 stained_hardened_clay 9  
fill ~84 ~31 ~103 ~84 ~31 ~104 stained_hardened_clay 0  
fill ~85 ~31 ~94 ~85 ~31 ~102 stained_hardened_clay 0  
fill ~86 ~31 ~93 ~87 ~31 ~93 concrete 1  
fill ~86 ~31 ~94 ~87 ~31 ~94 concrete 1  
fill ~86 ~31 ~95 ~87 ~31 ~95 concrete 1  
fill ~86 ~31 ~96 ~87 ~31 ~96 concrete 1  
fill ~86 ~31 ~97 ~87 ~31 ~97 concrete 1 
setblock ~86 ~31 ~98 stained_hardened_clay 9  
fill ~86 ~31 ~99 ~87 ~31 ~99 concrete 1  
fill ~86 ~31 ~100 ~87 ~31 ~100 concrete 1  
fill ~86 ~31 ~101 ~87 ~31 ~101 concrete 1  
fill ~86 ~31 ~102 ~87 ~31 ~102 concrete 1  
fill ~86 ~31 ~103 ~87 ~31 ~103 concrete 1 
setblock ~87 ~31 ~98 concrete 1  
fill ~88 ~31 ~95 ~89 ~31 ~95 stained_hardened_clay 9  
fill ~88 ~31 ~96 ~88 ~31 ~101 stained_hardened_clay 9 
setblock ~89 ~31 ~96 sea_lantern 0  
fill ~89 ~31 ~97 ~89 ~31 ~99 stained_hardened_clay 9 
setblock ~89 ~31 ~100 sea_lantern 0 
setblock ~89 ~31 ~101 stained_hardened_clay 9  
fill ~90 ~31 ~95 ~90 ~32 ~95 stained_hardened_clay 0  
fill ~90 ~31 ~96 ~90 ~32 ~96 stained_hardened_clay 0  
fill ~90 ~31 ~97 ~90 ~32 ~97 stained_hardened_clay 0 
setblock ~90 ~31 ~98 stained_hardened_clay 9  
fill ~90 ~31 ~99 ~90 ~32 ~99 stained_hardened_clay 0  
fill ~90 ~31 ~100 ~90 ~32 ~100 stained_hardened_clay 0  
fill ~90 ~31 ~101 ~90 ~32 ~101 stained_hardened_clay 0  
fill ~47 ~32 ~95 ~47 ~36 ~95 stained_hardened_clay 0  
fill ~47 ~32 ~96 ~47 ~33 ~96 stained_hardened_clay 0  
fill ~47 ~32 ~97 ~47 ~32 ~95 stained_hardened_clay 0 
setblock ~47 ~32 ~98 stained_hardened_clay 9  
fill ~47 ~32 ~99 ~47 ~32 ~101 stained_hardened_clay 0  
fill ~48 ~32 ~94 ~49 ~32 ~94 stained_hardened_clay 0 
setblock ~48 ~32 ~98 stained_hardened_clay 0  
fill ~48 ~32 ~102 ~49 ~32 ~102 stained_hardened_clay 0  
fill ~49 ~32 ~95 ~50 ~32 ~95 stained_hardened_clay 0  
fill ~49 ~32 ~96 ~50 ~32 ~96 stained_glass_pane 3 
setblock ~49 ~32 ~98 end_rod 5  
fill ~49 ~32 ~100 ~50 ~32 ~100 stained_glass_pane 3  
fill ~49 ~32 ~101 ~50 ~32 ~101 stained_hardened_clay 0 
setblock ~50 ~32 ~94 stained_hardened_clay 9 
setblock ~50 ~32 ~98 end_rod 4 
setblock ~50 ~32 ~102 stained_hardened_clay 9  
fill ~51 ~32 ~92 ~52 ~32 ~92 concrete 1  
fill ~51 ~32 ~93 ~52 ~32 ~93 concrete 1  
fill ~51 ~32 ~94 ~51 ~30 ~94 concrete 1  
fill ~51 ~32 ~95 ~51 ~32 ~101 stained_hardened_clay 9  
fill ~51 ~32 ~102 ~51 ~32 ~104 concrete 1  
fill ~52 ~32 ~103 ~52 ~33 ~103 concrete 1  
fill ~52 ~32 ~104 ~52 ~33 ~104 concrete 1  
fill ~53 ~32 ~94 ~53 ~32 ~102 stained_hardened_clay 9  
fill ~54 ~32 ~92 ~56 ~32 ~92 stained_hardened_clay 9  
fill ~54 ~32 ~93 ~54 ~32 ~92 stained_hardened_clay 9  
fill ~54 ~32 ~103 ~54 ~32 ~104 stained_hardened_clay 9  
fill ~55 ~32 ~90 ~58 ~32 ~90 stained_hardened_clay 9  
fill ~55 ~32 ~91 ~55 ~32 ~90 stained_hardened_clay 9  
fill ~55 ~32 ~94 ~55 ~29 ~94 stained_hardened_clay 9  
fill ~55 ~32 ~95 ~55 ~32 ~106 stained_hardened_clay 9  
fill ~56 ~32 ~88 ~60 ~32 ~88 stained_hardened_clay 9  
fill ~56 ~32 ~89 ~59 ~32 ~89 stained_hardened_clay 9 
setblock ~56 ~32 ~104 stained_hardened_clay 9  
fill ~56 ~32 ~106 ~58 ~32 ~106 stained_hardened_clay 9  
fill ~56 ~32 ~107 ~59 ~32 ~107 stained_hardened_clay 9  
fill ~56 ~32 ~108 ~60 ~32 ~108 stained_hardened_clay 9  
fill ~57 ~32 ~87 ~61 ~32 ~87 stained_hardened_clay 9 
setblock ~57 ~32 ~91 stained_hardened_clay 9 
setblock ~57 ~32 ~105 stained_hardened_clay 9  
fill ~57 ~32 ~109 ~61 ~32 ~109 stained_hardened_clay 9  
fill ~58 ~32 ~86 ~62 ~32 ~86 stained_hardened_clay 9  
fill ~58 ~32 ~110 ~62 ~32 ~110 stained_hardened_clay 9  
fill ~59 ~32 ~85 ~63 ~32 ~85 stained_hardened_clay 9  
fill ~59 ~32 ~111 ~63 ~32 ~111 stained_hardened_clay 9  
fill ~61 ~32 ~84 ~77 ~32 ~84 stained_hardened_clay 9  
fill ~61 ~32 ~112 ~77 ~32 ~112 stained_hardened_clay 9  
fill ~63 ~32 ~80 ~65 ~32 ~80 concrete 1  
fill ~63 ~32 ~81 ~64 ~32 ~81 concrete 1  
fill ~63 ~32 ~83 ~75 ~32 ~83 stained_hardened_clay 9  
fill ~63 ~32 ~113 ~75 ~32 ~113 stained_hardened_clay 9  
fill ~63 ~32 ~115 ~64 ~32 ~115 concrete 1  
fill ~63 ~32 ~116 ~65 ~32 ~116 concrete 1  
fill ~65 ~32 ~77 ~73 ~32 ~77 stained_hardened_clay 0  
fill ~65 ~32 ~78 ~66 ~32 ~78 stained_hardened_clay 0 
setblock ~65 ~32 ~79 stained_hardened_clay 9  
fill ~65 ~32 ~82 ~73 ~32 ~82 stained_hardened_clay 9  
fill ~65 ~32 ~114 ~73 ~32 ~114 stained_hardened_clay 9 
setblock ~65 ~32 ~117 stained_hardened_clay 9  
fill ~65 ~32 ~118 ~66 ~32 ~118 stained_hardened_clay 0  
fill ~65 ~32 ~119 ~73 ~32 ~119 stained_hardened_clay 0  
fill ~66 ~32 ~76 ~68 ~32 ~76 stained_hardened_clay 0 
setblock ~66 ~32 ~79 stained_hardened_clay 0  
fill ~66 ~32 ~80 ~72 ~32 ~80 stained_hardened_clay 9  
fill ~66 ~32 ~116 ~72 ~32 ~116 stained_hardened_clay 9 
setblock ~66 ~32 ~117 stained_hardened_clay 0  
fill ~66 ~32 ~120 ~68 ~32 ~120 stained_hardened_clay 0  
fill ~67 ~32 ~78 ~67 ~32 ~79 stained_glass_pane 3  
fill ~67 ~32 ~117 ~67 ~32 ~118 stained_glass_pane 3 
setblock ~69 ~32 ~76 stained_hardened_clay 9 
setblock ~69 ~32 ~78 end_rod 3 
setblock ~69 ~32 ~79 end_rod 2 
setblock ~69 ~32 ~117 end_rod 3 
setblock ~69 ~32 ~118 end_rod 2 
setblock ~69 ~32 ~120 stained_hardened_clay 9  
fill ~70 ~32 ~76 ~72 ~32 ~76 stained_hardened_clay 0  
fill ~70 ~32 ~120 ~72 ~32 ~120 stained_hardened_clay 0  
fill ~71 ~32 ~78 ~71 ~32 ~79 stained_glass_pane 3  
fill ~71 ~32 ~117 ~71 ~32 ~118 stained_glass_pane 3  
fill ~72 ~32 ~78 ~73 ~32 ~78 stained_hardened_clay 0  
fill ~72 ~32 ~79 ~72 ~32 ~76 stained_hardened_clay 0  
fill ~72 ~32 ~117 ~72 ~32 ~120 stained_hardened_clay 0 
setblock ~73 ~32 ~79 stained_hardened_clay 9  
fill ~73 ~32 ~80 ~75 ~32 ~80 concrete 1  
fill ~73 ~32 ~116 ~75 ~32 ~116 concrete 1 
setblock ~73 ~32 ~117 stained_hardened_clay 9 
setblock ~73 ~32 ~118 stained_hardened_clay 0  
fill ~74 ~32 ~81 ~75 ~32 ~81 concrete 1  
fill ~74 ~32 ~115 ~75 ~32 ~115 concrete 1  
fill ~75 ~32 ~85 ~79 ~32 ~85 stained_hardened_clay 9  
fill ~75 ~32 ~111 ~79 ~32 ~111 stained_hardened_clay 9  
fill ~76 ~32 ~86 ~80 ~32 ~86 stained_hardened_clay 9  
fill ~76 ~32 ~110 ~80 ~32 ~110 stained_hardened_clay 9  
fill ~77 ~32 ~87 ~81 ~32 ~87 stained_hardened_clay 9  
fill ~77 ~32 ~109 ~81 ~32 ~109 stained_hardened_clay 9  
fill ~78 ~32 ~88 ~82 ~32 ~88 stained_hardened_clay 9  
fill ~78 ~32 ~108 ~82 ~32 ~108 stained_hardened_clay 9  
fill ~79 ~32 ~89 ~82 ~32 ~89 stained_hardened_clay 9  
fill ~79 ~32 ~107 ~82 ~32 ~107 stained_hardened_clay 9  
fill ~80 ~32 ~90 ~83 ~32 ~90 stained_hardened_clay 9  
fill ~80 ~32 ~106 ~83 ~32 ~106 stained_hardened_clay 9 
setblock ~81 ~32 ~91 stained_hardened_clay 9 
setblock ~81 ~32 ~105 stained_hardened_clay 9  
fill ~82 ~32 ~92 ~84 ~32 ~92 stained_hardened_clay 9  
fill ~82 ~32 ~104 ~84 ~32 ~104 stained_hardened_clay 9 
setblock ~83 ~32 ~91 stained_hardened_clay 9  
fill ~83 ~32 ~94 ~83 ~32 ~106 stained_hardened_clay 9 
setblock ~84 ~32 ~93 stained_hardened_clay 9 
setblock ~84 ~32 ~103 stained_hardened_clay 9  
fill ~85 ~32 ~94 ~85 ~32 ~102 stained_hardened_clay 9  
fill ~86 ~32 ~92 ~87 ~32 ~92 concrete 1  
fill ~86 ~32 ~93 ~87 ~32 ~93 concrete 1  
fill ~86 ~32 ~103 ~87 ~32 ~103 concrete 1  
fill ~86 ~32 ~104 ~87 ~32 ~104 concrete 1 
setblock ~87 ~32 ~94 concrete 1  
fill ~87 ~32 ~95 ~87 ~32 ~101 stained_hardened_clay 9 
setblock ~87 ~32 ~102 concrete 1 
setblock ~88 ~32 ~94 stained_hardened_clay 9  
fill ~88 ~32 ~95 ~91 ~32 ~95 stained_hardened_clay 0  
fill ~88 ~32 ~96 ~89 ~32 ~96 stained_glass_pane 3 
setblock ~88 ~32 ~98 end_rod 5  
fill ~88 ~32 ~100 ~89 ~32 ~100 stained_glass_pane 3  
fill ~88 ~32 ~101 ~91 ~32 ~101 stained_hardened_clay 0 
setblock ~88 ~32 ~102 stained_hardened_clay 9  
fill ~89 ~32 ~94 ~90 ~32 ~94 stained_hardened_clay 0 
setblock ~89 ~32 ~98 end_rod 4  
fill ~89 ~32 ~102 ~90 ~32 ~102 stained_hardened_clay 0 
setblock ~90 ~32 ~98 stained_hardened_clay 0  
fill ~91 ~32 ~96 ~91 ~33 ~96 stained_hardened_clay 0  
fill ~91 ~32 ~97 ~91 ~32 ~95 stained_hardened_clay 0 
setblock ~91 ~32 ~98 stained_hardened_clay 9  
fill ~91 ~32 ~99 ~91 ~32 ~101 stained_hardened_clay 0 
setblock ~15 ~33 ~98 concrete 4  
fill ~26 ~33 ~-4 ~27 ~33 ~-4 stained_hardened_clay 9  
fill ~26 ~33 ~-3 ~27 ~33 ~-3 stained_hardened_clay 9  
fill ~26 ~33 ~-2 ~27 ~33 ~-2 stained_hardened_clay 9  
fill ~26 ~33 ~-1 ~27 ~33 ~-1 stained_hardened_clay 9  
fill ~26 ~33 ~0 ~27 ~33 ~0 stained_hardened_clay 9  
fill ~26 ~33 ~1 ~27 ~33 ~1 stained_hardened_clay 9  
fill ~26 ~33 ~2 ~27 ~33 ~2 stained_hardened_clay 9  
fill ~26 ~33 ~3 ~27 ~33 ~3 stained_hardened_clay 9  
fill ~26 ~33 ~4 ~27 ~33 ~4 stained_hardened_clay 9  
fill ~26 ~33 ~5 ~27 ~33 ~5 stained_hardened_clay 9  
fill ~26 ~33 ~6 ~27 ~33 ~6 stained_hardened_clay 9  
fill ~26 ~33 ~7 ~27 ~33 ~7 stained_hardened_clay 9  
fill ~26 ~33 ~8 ~27 ~33 ~8 stained_hardened_clay 9  
fill ~26 ~33 ~9 ~27 ~33 ~9 stained_hardened_clay 9  
fill ~26 ~33 ~10 ~27 ~33 ~10 stained_hardened_clay 9  
fill ~26 ~33 ~11 ~27 ~33 ~11 stained_hardened_clay 9  
fill ~26 ~33 ~12 ~27 ~33 ~12 stained_hardened_clay 9  
fill ~26 ~33 ~13 ~27 ~33 ~13 stained_hardened_clay 9  
fill ~26 ~33 ~14 ~27 ~33 ~14 stained_hardened_clay 9  
fill ~26 ~33 ~15 ~27 ~33 ~15 stained_hardened_clay 9  
fill ~26 ~33 ~16 ~27 ~33 ~16 stained_hardened_clay 9  
fill ~26 ~33 ~17 ~27 ~33 ~17 stained_hardened_clay 9  
fill ~26 ~33 ~18 ~27 ~33 ~18 stained_hardened_clay 9  
fill ~26 ~33 ~19 ~27 ~33 ~19 stained_hardened_clay 9  
fill ~26 ~33 ~20 ~27 ~33 ~20 stained_hardened_clay 9  
fill ~26 ~33 ~21 ~27 ~33 ~21 stained_hardened_clay 9  
fill ~26 ~33 ~22 ~27 ~33 ~22 stained_hardened_clay 9  
fill ~26 ~33 ~23 ~27 ~33 ~23 stained_hardened_clay 9  
fill ~26 ~33 ~24 ~27 ~33 ~24 stained_hardened_clay 9  
fill ~26 ~33 ~172 ~27 ~33 ~172 stained_hardened_clay 9  
fill ~26 ~33 ~173 ~27 ~33 ~173 stained_hardened_clay 9  
fill ~26 ~33 ~174 ~27 ~33 ~174 stained_hardened_clay 9  
fill ~26 ~33 ~175 ~27 ~33 ~175 stained_hardened_clay 9  
fill ~26 ~33 ~176 ~27 ~33 ~176 stained_hardened_clay 9  
fill ~26 ~33 ~177 ~27 ~33 ~177 stained_hardened_clay 9  
fill ~26 ~33 ~178 ~27 ~33 ~178 stained_hardened_clay 9  
fill ~26 ~33 ~179 ~27 ~33 ~179 stained_hardened_clay 9  
fill ~26 ~33 ~180 ~27 ~33 ~180 stained_hardened_clay 9  
fill ~26 ~33 ~181 ~27 ~33 ~181 stained_hardened_clay 9  
fill ~26 ~33 ~182 ~27 ~33 ~182 stained_hardened_clay 9  
fill ~26 ~33 ~183 ~27 ~33 ~183 stained_hardened_clay 9  
fill ~26 ~33 ~184 ~27 ~33 ~184 stained_hardened_clay 9  
fill ~26 ~33 ~185 ~27 ~33 ~185 stained_hardened_clay 9  
fill ~26 ~33 ~186 ~27 ~33 ~186 stained_hardened_clay 9  
fill ~26 ~33 ~187 ~27 ~33 ~187 stained_hardened_clay 9  
fill ~26 ~33 ~188 ~27 ~33 ~188 stained_hardened_clay 9  
fill ~26 ~33 ~189 ~27 ~33 ~189 stained_hardened_clay 9  
fill ~26 ~33 ~190 ~27 ~33 ~190 stained_hardened_clay 9  
fill ~26 ~33 ~191 ~27 ~33 ~191 stained_hardened_clay 9  
fill ~26 ~33 ~192 ~27 ~33 ~192 stained_hardened_clay 9  
fill ~26 ~33 ~193 ~27 ~33 ~193 stained_hardened_clay 9  
fill ~26 ~33 ~194 ~27 ~33 ~194 stained_hardened_clay 9  
fill ~26 ~33 ~195 ~27 ~33 ~195 stained_hardened_clay 9  
fill ~26 ~33 ~196 ~27 ~33 ~196 stained_hardened_clay 9  
fill ~26 ~33 ~197 ~27 ~33 ~197 stained_hardened_clay 9  
fill ~26 ~33 ~198 ~27 ~33 ~198 stained_hardened_clay 9  
fill ~26 ~33 ~199 ~27 ~33 ~199 stained_hardened_clay 9  
fill ~26 ~33 ~200 ~27 ~33 ~200 stained_hardened_clay 9 
setblock ~45 ~33 ~98 stained_glass_pane 3  
fill ~46 ~33 ~95 ~46 ~33 ~97 stained_hardened_clay 0 
setblock ~46 ~33 ~98 stained_hardened_clay 9  
fill ~46 ~33 ~99 ~46 ~33 ~101 stained_hardened_clay 0  
fill ~47 ~33 ~94 ~48 ~33 ~94 stained_hardened_clay 0  
fill ~47 ~33 ~100 ~47 ~33 ~102 stained_hardened_clay 0  
fill ~48 ~33 ~93 ~48 ~35 ~93 stained_hardened_clay 0  
fill ~48 ~33 ~102 ~48 ~36 ~102 stained_hardened_clay 0  
fill ~48 ~33 ~103 ~48 ~35 ~103 stained_hardened_clay 0  
fill ~49 ~33 ~93 ~50 ~33 ~93 stained_hardened_clay 9  
fill ~49 ~33 ~94 ~50 ~33 ~94 stained_glass_pane 3  
fill ~49 ~33 ~102 ~50 ~33 ~102 stained_glass_pane 3  
fill ~49 ~33 ~103 ~50 ~33 ~103 stained_hardened_clay 9  
fill ~51 ~33 ~92 ~52 ~33 ~92 concrete 1  
fill ~51 ~33 ~93 ~52 ~33 ~93 concrete 1  
fill ~51 ~33 ~94 ~51 ~35 ~94 stained_hardened_clay 9  
fill ~51 ~33 ~102 ~51 ~35 ~102 stained_hardened_clay 9  
fill ~51 ~33 ~103 ~51 ~33 ~104 concrete 1  
fill ~52 ~33 ~95 ~52 ~35 ~95 stained_hardened_clay 9  
fill ~52 ~33 ~96 ~52 ~35 ~96 stained_hardened_clay 9  
fill ~52 ~33 ~97 ~52 ~35 ~97 stained_hardened_clay 9  
fill ~52 ~33 ~98 ~52 ~33 ~101 stained_hardened_clay 9  
fill ~53 ~33 ~94 ~54 ~33 ~94 obsidian 0  
fill ~53 ~33 ~95 ~54 ~33 ~95 obsidian 0  
fill ~53 ~33 ~96 ~54 ~33 ~96 obsidian 0  
fill ~53 ~33 ~97 ~54 ~33 ~97 obsidian 0  
fill ~53 ~33 ~98 ~54 ~33 ~98 obsidian 0  
fill ~53 ~33 ~99 ~54 ~33 ~99 obsidian 0  
fill ~53 ~33 ~100 ~54 ~33 ~100 obsidian 0  
fill ~53 ~33 ~101 ~54 ~33 ~101 obsidian 0  
fill ~53 ~33 ~102 ~54 ~33 ~102 obsidian 0  
fill ~54 ~33 ~92 ~55 ~33 ~92 stained_hardened_clay 0  
fill ~54 ~33 ~93 ~54 ~37 ~93 stained_hardened_clay 0  
fill ~54 ~33 ~103 ~54 ~37 ~103 stained_hardened_clay 0  
fill ~54 ~33 ~104 ~55 ~33 ~104 stained_hardened_clay 0  
fill ~55 ~33 ~90 ~55 ~37 ~90 obsidian 0  
fill ~55 ~33 ~91 ~55 ~37 ~91 stained_hardened_clay 0  
fill ~55 ~33 ~105 ~55 ~37 ~105 stained_hardened_clay 0  
fill ~55 ~33 ~106 ~55 ~37 ~106 obsidian 0  
fill ~56 ~33 ~88 ~56 ~34 ~88 obsidian 0  
fill ~56 ~33 ~89 ~56 ~33 ~88 obsidian 0  
fill ~56 ~33 ~90 ~56 ~37 ~90 stained_hardened_clay 0  
fill ~56 ~33 ~91 ~56 ~37 ~91 obsidian 0  
fill ~56 ~33 ~105 ~56 ~37 ~105 obsidian 0  
fill ~56 ~33 ~106 ~56 ~37 ~106 stained_hardened_clay 0  
fill ~56 ~33 ~107 ~56 ~33 ~108 obsidian 0 
setblock ~57 ~33 ~87 obsidian 0  
fill ~57 ~33 ~88 ~58 ~33 ~88 stained_hardened_clay 0  
fill ~57 ~33 ~89 ~57 ~37 ~89 stained_hardened_clay 0 
setblock ~57 ~33 ~90 obsidian 0 
setblock ~57 ~33 ~106 obsidian 0  
fill ~57 ~33 ~107 ~57 ~37 ~107 stained_hardened_clay 0  
fill ~57 ~33 ~108 ~58 ~33 ~108 stained_hardened_clay 0 
setblock ~57 ~33 ~109 obsidian 0 
setblock ~58 ~33 ~86 obsidian 0  
fill ~58 ~33 ~87 ~59 ~33 ~87 stained_hardened_clay 0  
fill ~58 ~33 ~89 ~58 ~34 ~89 obsidian 0  
fill ~58 ~33 ~107 ~58 ~34 ~107 obsidian 0  
fill ~58 ~33 ~109 ~59 ~33 ~109 stained_hardened_clay 0 
setblock ~58 ~33 ~110 obsidian 0  
fill ~59 ~33 ~85 ~60 ~33 ~85 obsidian 0  
fill ~59 ~33 ~86 ~60 ~33 ~86 stained_hardened_clay 0 
setblock ~59 ~33 ~88 obsidian 0 
setblock ~59 ~33 ~108 obsidian 0  
fill ~59 ~33 ~110 ~60 ~33 ~110 stained_hardened_clay 0  
fill ~59 ~33 ~111 ~60 ~33 ~111 obsidian 0  
fill ~60 ~33 ~87 ~60 ~34 ~87 obsidian 0  
fill ~60 ~33 ~109 ~60 ~34 ~109 obsidian 0  
fill ~61 ~33 ~84 ~61 ~37 ~84 obsidian 0  
fill ~61 ~33 ~85 ~61 ~37 ~85 stained_hardened_clay 0 
setblock ~61 ~33 ~86 obsidian 0 
setblock ~61 ~33 ~110 obsidian 0  
fill ~61 ~33 ~111 ~61 ~37 ~111 stained_hardened_clay 0  
fill ~61 ~33 ~112 ~61 ~37 ~112 obsidian 0  
fill ~62 ~33 ~84 ~63 ~33 ~84 stained_hardened_clay 0  
fill ~62 ~33 ~85 ~62 ~37 ~85 obsidian 0  
fill ~62 ~33 ~111 ~62 ~37 ~111 obsidian 0  
fill ~62 ~33 ~112 ~63 ~33 ~112 stained_hardened_clay 0  
fill ~63 ~33 ~80 ~64 ~33 ~80 concrete 1  
fill ~63 ~33 ~81 ~64 ~33 ~81 concrete 1  
fill ~63 ~33 ~83 ~64 ~33 ~83 stained_hardened_clay 0  
fill ~63 ~33 ~113 ~64 ~33 ~113 stained_hardened_clay 0  
fill ~63 ~33 ~115 ~64 ~33 ~115 concrete 1  
fill ~63 ~33 ~116 ~64 ~33 ~116 concrete 1  
fill ~64 ~33 ~77 ~65 ~33 ~77 stained_hardened_clay 0  
fill ~64 ~33 ~78 ~64 ~35 ~78 stained_hardened_clay 9  
fill ~64 ~33 ~79 ~64 ~35 ~79 stained_hardened_clay 9  
fill ~64 ~33 ~117 ~64 ~35 ~117 stained_hardened_clay 9  
fill ~64 ~33 ~118 ~64 ~35 ~118 stained_hardened_clay 9  
fill ~64 ~33 ~119 ~65 ~33 ~119 stained_hardened_clay 0  
fill ~65 ~33 ~76 ~67 ~33 ~76 stained_hardened_clay 0  
fill ~65 ~33 ~78 ~65 ~35 ~78 stained_glass_pane 3  
fill ~65 ~33 ~79 ~65 ~35 ~79 stained_glass_pane 3  
fill ~65 ~33 ~80 ~65 ~35 ~80 stained_hardened_clay 9  
fill ~65 ~33 ~82 ~73 ~33 ~82 obsidian 0  
fill ~65 ~33 ~83 ~73 ~33 ~83 obsidian 0  
fill ~65 ~33 ~113 ~73 ~33 ~113 obsidian 0  
fill ~65 ~33 ~114 ~73 ~33 ~114 obsidian 0  
fill ~65 ~33 ~116 ~65 ~35 ~116 stained_hardened_clay 9  
fill ~65 ~33 ~117 ~65 ~35 ~117 stained_glass_pane 3  
fill ~65 ~33 ~118 ~65 ~35 ~118 stained_glass_pane 3  
fill ~65 ~33 ~120 ~67 ~33 ~120 stained_hardened_clay 0  
fill ~66 ~33 ~75 ~68 ~33 ~75 stained_hardened_clay 0  
fill ~66 ~33 ~81 ~72 ~33 ~81 stained_hardened_clay 9  
fill ~66 ~33 ~115 ~72 ~33 ~115 stained_hardened_clay 9  
fill ~66 ~33 ~121 ~68 ~33 ~121 stained_hardened_clay 0 
setblock ~69 ~33 ~44 concrete 4 
setblock ~69 ~33 ~74 stained_glass_pane 3 
setblock ~69 ~33 ~75 stained_hardened_clay 9 
setblock ~69 ~33 ~121 stained_hardened_clay 9 
setblock ~69 ~33 ~122 stained_glass_pane 3 
setblock ~69 ~33 ~152 concrete 4  
fill ~70 ~33 ~75 ~72 ~33 ~75 stained_hardened_clay 0  
fill ~70 ~33 ~121 ~72 ~33 ~121 stained_hardened_clay 0  
fill ~71 ~33 ~76 ~73 ~33 ~76 stained_hardened_clay 0  
fill ~71 ~33 ~120 ~73 ~33 ~120 stained_hardened_clay 0  
fill ~73 ~33 ~77 ~74 ~33 ~77 stained_hardened_clay 0  
fill ~73 ~33 ~78 ~73 ~35 ~78 stained_glass_pane 3  
fill ~73 ~33 ~79 ~73 ~35 ~79 stained_glass_pane 3  
fill ~73 ~33 ~80 ~73 ~35 ~80 stained_hardened_clay 9  
fill ~73 ~33 ~116 ~73 ~35 ~116 stained_hardened_clay 9  
fill ~73 ~33 ~117 ~73 ~35 ~117 stained_glass_pane 3  
fill ~73 ~33 ~118 ~73 ~35 ~118 stained_glass_pane 3  
fill ~73 ~33 ~119 ~74 ~33 ~119 stained_hardened_clay 0  
fill ~74 ~33 ~78 ~74 ~35 ~78 stained_hardened_clay 9  
fill ~74 ~33 ~79 ~74 ~35 ~79 stained_hardened_clay 9  
fill ~74 ~33 ~80 ~75 ~33 ~80 concrete 1  
fill ~74 ~33 ~81 ~75 ~33 ~81 concrete 1  
fill ~74 ~33 ~83 ~75 ~33 ~83 stained_hardened_clay 0  
fill ~74 ~33 ~113 ~75 ~33 ~113 stained_hardened_clay 0  
fill ~74 ~33 ~115 ~75 ~33 ~115 concrete 1  
fill ~74 ~33 ~116 ~75 ~33 ~116 concrete 1  
fill ~74 ~33 ~117 ~74 ~35 ~117 stained_hardened_clay 9  
fill ~74 ~33 ~118 ~74 ~35 ~118 stained_hardened_clay 9  
fill ~75 ~33 ~84 ~76 ~33 ~84 stained_hardened_clay 0  
fill ~75 ~33 ~112 ~76 ~33 ~112 stained_hardened_clay 0  
fill ~76 ~33 ~85 ~76 ~37 ~85 obsidian 0  
fill ~76 ~33 ~111 ~76 ~37 ~111 obsidian 0  
fill ~77 ~33 ~84 ~77 ~37 ~84 obsidian 0  
fill ~77 ~33 ~85 ~77 ~37 ~85 stained_hardened_clay 0 
setblock ~77 ~33 ~86 obsidian 0 
setblock ~77 ~33 ~110 obsidian 0  
fill ~77 ~33 ~111 ~77 ~37 ~111 stained_hardened_clay 0  
fill ~77 ~33 ~112 ~77 ~37 ~112 obsidian 0  
fill ~78 ~33 ~85 ~79 ~33 ~85 obsidian 0  
fill ~78 ~33 ~86 ~79 ~33 ~86 stained_hardened_clay 0  
fill ~78 ~33 ~87 ~78 ~34 ~87 obsidian 0  
fill ~78 ~33 ~109 ~78 ~34 ~109 obsidian 0  
fill ~78 ~33 ~110 ~79 ~33 ~110 stained_hardened_clay 0  
fill ~78 ~33 ~111 ~79 ~33 ~111 obsidian 0  
fill ~79 ~33 ~87 ~80 ~33 ~87 stained_hardened_clay 0 
setblock ~79 ~33 ~88 obsidian 0 
setblock ~79 ~33 ~108 obsidian 0  
fill ~79 ~33 ~109 ~80 ~33 ~109 stained_hardened_clay 0 
setblock ~80 ~33 ~86 obsidian 0  
fill ~80 ~33 ~88 ~81 ~33 ~88 stained_hardened_clay 0  
fill ~80 ~33 ~89 ~80 ~34 ~89 obsidian 0  
fill ~80 ~33 ~107 ~80 ~34 ~107 obsidian 0  
fill ~80 ~33 ~108 ~81 ~33 ~108 stained_hardened_clay 0 
setblock ~80 ~33 ~110 obsidian 0 
setblock ~81 ~33 ~87 obsidian 0  
fill ~81 ~33 ~89 ~81 ~37 ~89 stained_hardened_clay 0 
setblock ~81 ~33 ~90 obsidian 0 
setblock ~81 ~33 ~106 obsidian 0  
fill ~81 ~33 ~107 ~81 ~37 ~107 stained_hardened_clay 0 
setblock ~81 ~33 ~109 obsidian 0  
fill ~82 ~33 ~88 ~82 ~34 ~88 obsidian 0  
fill ~82 ~33 ~89 ~82 ~33 ~88 obsidian 0  
fill ~82 ~33 ~90 ~82 ~37 ~90 stained_hardened_clay 0  
fill ~82 ~33 ~91 ~82 ~37 ~91 obsidian 0  
fill ~82 ~33 ~105 ~82 ~37 ~105 obsidian 0  
fill ~82 ~33 ~106 ~82 ~37 ~106 stained_hardened_clay 0  
fill ~82 ~33 ~107 ~82 ~33 ~108 obsidian 0  
fill ~83 ~33 ~90 ~83 ~37 ~90 obsidian 0  
fill ~83 ~33 ~91 ~83 ~37 ~91 stained_hardened_clay 0  
fill ~83 ~33 ~92 ~84 ~33 ~92 stained_hardened_clay 0  
fill ~83 ~33 ~104 ~84 ~33 ~104 stained_hardened_clay 0  
fill ~83 ~33 ~105 ~83 ~37 ~105 stained_hardened_clay 0  
fill ~83 ~33 ~106 ~83 ~37 ~106 obsidian 0  
fill ~84 ~33 ~93 ~84 ~37 ~93 stained_hardened_clay 0  
fill ~84 ~33 ~94 ~85 ~33 ~94 obsidian 0  
fill ~84 ~33 ~95 ~85 ~33 ~95 obsidian 0  
fill ~84 ~33 ~96 ~85 ~33 ~96 obsidian 0  
fill ~84 ~33 ~97 ~85 ~33 ~97 obsidian 0  
fill ~84 ~33 ~98 ~85 ~33 ~98 obsidian 0  
fill ~84 ~33 ~99 ~85 ~33 ~99 obsidian 0  
fill ~84 ~33 ~100 ~85 ~33 ~100 obsidian 0  
fill ~84 ~33 ~101 ~85 ~33 ~101 obsidian 0  
fill ~84 ~33 ~102 ~85 ~33 ~102 obsidian 0  
fill ~84 ~33 ~103 ~84 ~37 ~103 stained_hardened_clay 0  
fill ~86 ~33 ~92 ~87 ~33 ~92 concrete 1  
fill ~86 ~33 ~93 ~87 ~33 ~93 concrete 1  
fill ~86 ~33 ~95 ~86 ~35 ~95 stained_hardened_clay 9  
fill ~86 ~33 ~96 ~86 ~35 ~96 stained_hardened_clay 9  
fill ~86 ~33 ~97 ~86 ~35 ~97 stained_hardened_clay 9  
fill ~86 ~33 ~98 ~86 ~33 ~101 stained_hardened_clay 9  
fill ~86 ~33 ~103 ~87 ~33 ~103 concrete 1  
fill ~86 ~33 ~104 ~87 ~33 ~104 concrete 1  
fill ~87 ~33 ~94 ~87 ~35 ~94 stained_hardened_clay 9  
fill ~87 ~33 ~102 ~87 ~35 ~102 stained_hardened_clay 9  
fill ~88 ~33 ~93 ~89 ~33 ~93 stained_hardened_clay 9  
fill ~88 ~33 ~94 ~89 ~33 ~94 stained_glass_pane 3  
fill ~88 ~33 ~102 ~89 ~33 ~102 stained_glass_pane 3  
fill ~88 ~33 ~103 ~89 ~33 ~103 stained_hardened_clay 9  
fill ~90 ~33 ~93 ~90 ~35 ~93 stained_hardened_clay 0  
fill ~90 ~33 ~94 ~91 ~33 ~94 stained_hardened_clay 0  
fill ~90 ~33 ~102 ~91 ~33 ~102 stained_hardened_clay 0  
fill ~90 ~33 ~103 ~90 ~35 ~103 stained_hardened_clay 0  
fill ~91 ~33 ~95 ~92 ~33 ~95 stained_hardened_clay 0  
fill ~91 ~33 ~100 ~92 ~33 ~100 stained_hardened_clay 0  
fill ~91 ~33 ~101 ~92 ~33 ~101 stained_hardened_clay 0  
fill ~92 ~33 ~96 ~92 ~35 ~96 stained_hardened_clay 0  
fill ~92 ~33 ~97 ~92 ~33 ~95 stained_hardened_clay 0 
setblock ~92 ~33 ~98 stained_hardened_clay 9 
setblock ~92 ~33 ~99 stained_hardened_clay 0 
setblock ~93 ~33 ~98 stained_glass_pane 3 
setblock ~123 ~33 ~98 concrete 4 
setblock ~15 ~34 ~98 sea_lantern 0  
fill ~28 ~34 ~-5 ~29 ~34 ~-5 stained_hardened_clay 9  
fill ~28 ~34 ~-4 ~29 ~34 ~-4 stained_hardened_clay 9  
fill ~28 ~34 ~-3 ~29 ~34 ~-3 concrete 4  
fill ~28 ~34 ~-2 ~28 ~34 ~23 concrete 4  
fill ~28 ~34 ~24 ~29 ~34 ~24 stained_hardened_clay 9  
fill ~28 ~34 ~25 ~29 ~34 ~25 stained_hardened_clay 9  
fill ~28 ~34 ~171 ~29 ~34 ~171 stained_hardened_clay 9  
fill ~28 ~34 ~172 ~29 ~34 ~172 stained_hardened_clay 9  
fill ~28 ~34 ~173 ~29 ~34 ~173 concrete 4  
fill ~28 ~34 ~174 ~28 ~34 ~199 concrete 4  
fill ~28 ~34 ~200 ~29 ~34 ~200 stained_hardened_clay 9  
fill ~28 ~34 ~201 ~29 ~34 ~201 stained_hardened_clay 9  
fill ~29 ~34 ~-2 ~29 ~34 ~-1 sea_lantern 0  
fill ~29 ~34 ~0 ~29 ~34 ~20 stained_hardened_clay 0  
fill ~29 ~34 ~21 ~29 ~34 ~22 sea_lantern 0 
setblock ~29 ~34 ~23 concrete 4  
fill ~29 ~34 ~174 ~29 ~34 ~175 sea_lantern 0  
fill ~29 ~34 ~176 ~29 ~34 ~196 stained_hardened_clay 0  
fill ~29 ~34 ~197 ~29 ~34 ~198 sea_lantern 0 
setblock ~29 ~34 ~199 concrete 4 
setblock ~45 ~34 ~97 stained_glass_pane 3 
setblock ~45 ~34 ~98 stained_glass 3 
setblock ~45 ~34 ~99 stained_glass_pane 3 
setblock ~46 ~34 ~95 concrete 1  
fill ~46 ~34 ~96 ~46 ~35 ~96 stained_hardened_clay 0 
setblock ~46 ~34 ~97 stained_hardened_clay 9 
setblock ~46 ~34 ~98 sea_lantern 0 
setblock ~46 ~34 ~99 stained_hardened_clay 9  
fill ~46 ~34 ~100 ~46 ~35 ~100 stained_hardened_clay 0 
setblock ~46 ~34 ~101 concrete 1 
setblock ~47 ~34 ~94 concrete 1  
fill ~47 ~34 ~101 ~47 ~36 ~101 stained_hardened_clay 0 
setblock ~47 ~34 ~102 concrete 1  
fill ~48 ~34 ~94 ~48 ~36 ~94 stained_hardened_clay 0  
fill ~49 ~34 ~93 ~50 ~34 ~93 stained_hardened_clay 9  
fill ~49 ~34 ~94 ~50 ~34 ~94 stained_glass_pane 3  
fill ~49 ~34 ~102 ~50 ~34 ~102 stained_glass_pane 3  
fill ~49 ~34 ~103 ~50 ~34 ~103 stained_hardened_clay 9 
setblock ~52 ~34 ~98 stained_hardened_clay 0  
fill ~52 ~34 ~99 ~54 ~34 ~99 stained_hardened_clay 9  
fill ~52 ~34 ~100 ~52 ~35 ~100 stained_hardened_clay 9  
fill ~52 ~34 ~101 ~54 ~34 ~101 stained_hardened_clay 9  
fill ~53 ~34 ~94 ~54 ~34 ~94 obsidian 0  
fill ~53 ~34 ~95 ~54 ~34 ~95 stained_hardened_clay 9  
fill ~53 ~34 ~96 ~54 ~34 ~96 obsidian 0  
fill ~53 ~34 ~97 ~54 ~34 ~97 stained_hardened_clay 9  
fill ~53 ~34 ~98 ~54 ~34 ~98 stained_hardened_clay 9  
fill ~53 ~34 ~100 ~54 ~34 ~100 obsidian 0  
fill ~53 ~34 ~102 ~54 ~34 ~102 obsidian 0  
fill ~54 ~34 ~92 ~55 ~34 ~92 stained_hardened_clay 0  
fill ~54 ~34 ~104 ~55 ~34 ~104 stained_hardened_clay 0  
fill ~56 ~34 ~89 ~56 ~36 ~89 stained_hardened_clay 9  
fill ~56 ~34 ~107 ~56 ~36 ~107 stained_hardened_clay 9 
setblock ~56 ~34 ~108 obsidian 0 
setblock ~57 ~34 ~87 stained_hardened_clay 9  
fill ~57 ~34 ~88 ~58 ~34 ~88 stained_hardened_clay 0  
fill ~57 ~34 ~90 ~57 ~36 ~90 stained_hardened_clay 9  
fill ~57 ~34 ~106 ~57 ~36 ~106 stained_hardened_clay 9  
fill ~57 ~34 ~108 ~58 ~34 ~108 stained_hardened_clay 0 
setblock ~57 ~34 ~109 stained_hardened_clay 9 
setblock ~58 ~34 ~86 stained_hardened_clay 9  
fill ~58 ~34 ~87 ~59 ~34 ~87 stained_hardened_clay 0  
fill ~58 ~34 ~109 ~59 ~34 ~109 stained_hardened_clay 0 
setblock ~58 ~34 ~110 stained_hardened_clay 9  
fill ~59 ~34 ~85 ~59 ~33 ~85 obsidian 0  
fill ~59 ~34 ~86 ~60 ~34 ~86 stained_hardened_clay 0 
setblock ~59 ~34 ~88 stained_hardened_clay 9 
setblock ~59 ~34 ~108 stained_hardened_clay 9  
fill ~59 ~34 ~110 ~60 ~34 ~110 stained_hardened_clay 0  
fill ~59 ~34 ~111 ~59 ~33 ~111 obsidian 0  
fill ~60 ~34 ~85 ~60 ~36 ~85 stained_hardened_clay 9  
fill ~60 ~34 ~111 ~60 ~36 ~111 stained_hardened_clay 9  
fill ~61 ~34 ~86 ~61 ~36 ~86 stained_hardened_clay 9  
fill ~61 ~34 ~110 ~61 ~36 ~110 stained_hardened_clay 9  
fill ~62 ~34 ~84 ~63 ~34 ~84 stained_hardened_clay 0  
fill ~62 ~34 ~112 ~63 ~34 ~112 stained_hardened_clay 0  
fill ~63 ~34 ~83 ~64 ~34 ~83 stained_hardened_clay 0  
fill ~63 ~34 ~113 ~64 ~34 ~113 stained_hardened_clay 0  
fill ~64 ~34 ~77 ~65 ~34 ~77 stained_hardened_clay 0  
fill ~64 ~34 ~119 ~65 ~34 ~119 stained_hardened_clay 0 
setblock ~65 ~34 ~76 concrete 1  
fill ~65 ~34 ~82 ~65 ~37 ~82 obsidian 0  
fill ~65 ~34 ~83 ~65 ~37 ~83 obsidian 0  
fill ~65 ~34 ~113 ~65 ~37 ~113 obsidian 0  
fill ~65 ~34 ~114 ~65 ~37 ~114 obsidian 0 
setblock ~65 ~34 ~120 concrete 1 
setblock ~66 ~34 ~75 concrete 1  
fill ~66 ~34 ~76 ~66 ~36 ~76 stained_hardened_clay 0  
fill ~66 ~34 ~81 ~68 ~34 ~81 stained_hardened_clay 9  
fill ~66 ~34 ~82 ~66 ~36 ~82 stained_hardened_clay 9  
fill ~66 ~34 ~83 ~66 ~36 ~83 stained_hardened_clay 9  
fill ~66 ~34 ~113 ~66 ~36 ~113 stained_hardened_clay 9  
fill ~66 ~34 ~114 ~66 ~36 ~114 stained_hardened_clay 9  
fill ~66 ~34 ~115 ~68 ~34 ~115 stained_hardened_clay 9  
fill ~66 ~34 ~120 ~66 ~36 ~120 stained_hardened_clay 0 
setblock ~66 ~34 ~121 concrete 1  
fill ~67 ~34 ~75 ~67 ~35 ~75 stained_hardened_clay 0  
fill ~67 ~34 ~82 ~67 ~34 ~83 obsidian 0  
fill ~67 ~34 ~113 ~67 ~34 ~114 obsidian 0  
fill ~67 ~34 ~121 ~67 ~35 ~121 stained_hardened_clay 0 
setblock ~68 ~34 ~74 stained_glass_pane 3 
setblock ~68 ~34 ~75 stained_hardened_clay 9  
fill ~68 ~34 ~82 ~70 ~34 ~82 stained_hardened_clay 9  
fill ~68 ~34 ~83 ~70 ~34 ~83 stained_hardened_clay 9  
fill ~68 ~34 ~113 ~70 ~34 ~113 stained_hardened_clay 9  
fill ~68 ~34 ~114 ~70 ~34 ~114 stained_hardened_clay 9 
setblock ~68 ~34 ~121 stained_hardened_clay 9 
setblock ~68 ~34 ~122 stained_glass_pane 3 
setblock ~69 ~34 ~44 sea_lantern 0 
setblock ~69 ~34 ~74 stained_glass 3 
setblock ~69 ~34 ~75 sea_lantern 0 
setblock ~69 ~34 ~81 stained_hardened_clay 0 
setblock ~69 ~34 ~115 stained_hardened_clay 0 
setblock ~69 ~34 ~121 sea_lantern 0 
setblock ~69 ~34 ~122 stained_glass 3 
setblock ~69 ~34 ~152 sea_lantern 0 
setblock ~70 ~34 ~74 stained_glass_pane 3 
setblock ~70 ~34 ~75 stained_hardened_clay 9  
fill ~70 ~34 ~81 ~72 ~34 ~81 stained_hardened_clay 9  
fill ~70 ~34 ~115 ~72 ~34 ~115 stained_hardened_clay 9 
setblock ~70 ~34 ~121 stained_hardened_clay 9 
setblock ~70 ~34 ~122 stained_glass_pane 3  
fill ~71 ~34 ~75 ~71 ~35 ~75 stained_hardened_clay 0  
fill ~71 ~34 ~82 ~71 ~34 ~83 obsidian 0  
fill ~71 ~34 ~113 ~71 ~34 ~114 obsidian 0  
fill ~71 ~34 ~121 ~71 ~35 ~121 stained_hardened_clay 0 
setblock ~72 ~34 ~75 concrete 1  
fill ~72 ~34 ~76 ~72 ~36 ~76 stained_hardened_clay 0  
fill ~72 ~34 ~82 ~72 ~36 ~82 stained_hardened_clay 9  
fill ~72 ~34 ~83 ~72 ~36 ~83 stained_hardened_clay 9  
fill ~72 ~34 ~113 ~72 ~36 ~113 stained_hardened_clay 9  
fill ~72 ~34 ~114 ~72 ~36 ~114 stained_hardened_clay 9  
fill ~72 ~34 ~120 ~72 ~36 ~120 stained_hardened_clay 0 
setblock ~72 ~34 ~121 concrete 1 
setblock ~73 ~34 ~76 concrete 1  
fill ~73 ~34 ~77 ~74 ~34 ~77 stained_hardened_clay 0  
fill ~73 ~34 ~82 ~73 ~37 ~82 obsidian 0  
fill ~73 ~34 ~83 ~73 ~37 ~83 obsidian 0  
fill ~73 ~34 ~113 ~73 ~37 ~113 obsidian 0  
fill ~73 ~34 ~114 ~73 ~37 ~114 obsidian 0  
fill ~73 ~34 ~119 ~74 ~34 ~119 stained_hardened_clay 0 
setblock ~73 ~34 ~120 concrete 1  
fill ~74 ~34 ~83 ~75 ~34 ~83 stained_hardened_clay 0  
fill ~74 ~34 ~113 ~75 ~34 ~113 stained_hardened_clay 0  
fill ~75 ~34 ~84 ~76 ~34 ~84 stained_hardened_clay 0  
fill ~75 ~34 ~112 ~76 ~34 ~112 stained_hardened_clay 0  
fill ~77 ~34 ~86 ~77 ~36 ~86 stained_hardened_clay 9  
fill ~77 ~34 ~110 ~77 ~36 ~110 stained_hardened_clay 9  
fill ~78 ~34 ~85 ~78 ~36 ~85 stained_hardened_clay 9  
fill ~78 ~34 ~86 ~79 ~34 ~86 stained_hardened_clay 0  
fill ~78 ~34 ~110 ~79 ~34 ~110 stained_hardened_clay 0  
fill ~78 ~34 ~111 ~78 ~36 ~111 stained_hardened_clay 9 
setblock ~79 ~34 ~85 obsidian 0  
fill ~79 ~34 ~87 ~80 ~34 ~87 stained_hardened_clay 0 
setblock ~79 ~34 ~88 stained_hardened_clay 9 
setblock ~79 ~34 ~108 stained_hardened_clay 9   
fill ~79 ~34 ~109 ~80 ~34 ~109 stained_hardened_clay 0 
setblock ~79 ~34 ~111 obsidian 0 
setblock ~80 ~34 ~86 stained_hardened_clay 9  
fill ~80 ~34 ~88 ~81 ~34 ~88 stained_hardened_clay 0  
fill ~80 ~34 ~108 ~81 ~34 ~108 stained_hardened_clay 0 
setblock ~80 ~34 ~110 stained_hardened_clay 9 
setblock ~81 ~34 ~87 stained_hardened_clay 9  
fill ~81 ~34 ~90 ~81 ~36 ~90 stained_hardened_clay 9  
fill ~81 ~34 ~106 ~81 ~36 ~106 stained_hardened_clay 9 
setblock ~81 ~34 ~109 stained_hardened_clay 9  
fill ~82 ~34 ~89 ~82 ~36 ~89 stained_hardened_clay 9  
fill ~82 ~34 ~107 ~82 ~36 ~107 stained_hardened_clay 9 
setblock ~82 ~34 ~108 obsidian 0  
fill ~83 ~34 ~92 ~84 ~34 ~92 stained_hardened_clay 0  
fill ~83 ~34 ~104 ~84 ~34 ~104 stained_hardened_clay 0  
fill ~84 ~34 ~94 ~85 ~34 ~94 obsidian 0  
fill ~84 ~34 ~95 ~86 ~34 ~95 stained_hardened_clay 9  
fill ~84 ~34 ~96 ~85 ~34 ~96 obsidian 0  
fill ~84 ~34 ~97 ~86 ~34 ~97 stained_hardened_clay 9  
fill ~84 ~34 ~98 ~85 ~34 ~98 stained_hardened_clay 9  
fill ~84 ~34 ~99 ~86 ~34 ~99 stained_hardened_clay 9  
fill ~84 ~34 ~100 ~85 ~34 ~100 obsidian 0  
fill ~84 ~34 ~101 ~86 ~34 ~101 stained_hardened_clay 9  
fill ~84 ~34 ~102 ~85 ~34 ~102 obsidian 0 
setblock ~86 ~34 ~98 stained_hardened_clay 0  
fill ~86 ~34 ~100 ~86 ~35 ~100 stained_hardened_clay 9  
fill ~88 ~34 ~93 ~89 ~34 ~93 stained_hardened_clay 9  
fill ~88 ~34 ~94 ~89 ~34 ~94 stained_glass_pane 3  
fill ~88 ~34 ~102 ~89 ~34 ~102 stained_glass_pane 3  
fill ~88 ~34 ~103 ~89 ~34 ~103 stained_hardened_clay 9  
fill ~90 ~34 ~94 ~90 ~36 ~94 stained_hardened_clay 0  
fill ~90 ~34 ~102 ~90 ~36 ~102 stained_hardened_clay 0 
setblock ~91 ~34 ~94 concrete 1  
fill ~91 ~34 ~95 ~91 ~36 ~95 stained_hardened_clay 0  
fill ~91 ~34 ~101 ~91 ~36 ~101 stained_hardened_clay 0 
setblock ~91 ~34 ~102 concrete 1 
setblock ~92 ~34 ~95 concrete 1 
setblock ~92 ~34 ~97 stained_hardened_clay 9 
setblock ~92 ~34 ~98 sea_lantern 0 
setblock ~92 ~34 ~99 stained_hardened_clay 9  
fill ~92 ~34 ~100 ~92 ~35 ~100 stained_hardened_clay 0 
setblock ~92 ~34 ~101 concrete 1 
setblock ~93 ~34 ~97 stained_glass_pane 3 
setblock ~93 ~34 ~98 stained_glass 3 
setblock ~93 ~34 ~99 stained_glass_pane 3 
setblock ~123 ~34 ~98 sea_lantern 0  
fill ~15 ~35 ~98 ~15 ~40 ~98 stained_hardened_clay 9  
fill ~30 ~35 ~-6 ~31 ~35 ~-6 stained_hardened_clay 9  
fill ~30 ~35 ~-5 ~31 ~35 ~-5 stained_hardened_clay 9  
fill ~30 ~35 ~-4 ~31 ~35 ~-4 concrete 4  
fill ~30 ~35 ~-3 ~31 ~35 ~-3 stained_hardened_clay 0  
fill ~30 ~35 ~-2 ~31 ~35 ~-2 stained_hardened_clay 0  
fill ~30 ~35 ~-1 ~31 ~35 ~-1 stained_hardened_clay 0  
fill ~30 ~35 ~0 ~31 ~35 ~0 stained_hardened_clay 0  
fill ~30 ~35 ~1 ~31 ~35 ~1 stained_hardened_clay 0  
fill ~30 ~35 ~2 ~31 ~35 ~2 stained_hardened_clay 0  
fill ~30 ~35 ~3 ~31 ~35 ~3 stained_hardened_clay 0  
fill ~30 ~35 ~4 ~31 ~35 ~4 stained_hardened_clay 0  
fill ~30 ~35 ~5 ~31 ~35 ~5 stained_hardened_clay 0  
fill ~30 ~35 ~6 ~31 ~35 ~6 stained_hardened_clay 0  
fill ~30 ~35 ~7 ~31 ~35 ~7 stained_hardened_clay 0  
fill ~30 ~35 ~8 ~31 ~35 ~8 stained_hardened_clay 0  
fill ~30 ~35 ~9 ~31 ~35 ~9 stained_hardened_clay 0  
fill ~30 ~35 ~10 ~31 ~35 ~10 stained_hardened_clay 0  
fill ~30 ~35 ~11 ~31 ~35 ~11 stained_hardened_clay 0  
fill ~30 ~35 ~12 ~31 ~35 ~12 stained_hardened_clay 0  
fill ~30 ~35 ~13 ~31 ~35 ~13 stained_hardened_clay 0  
fill ~30 ~35 ~14 ~31 ~35 ~14 stained_hardened_clay 0  
fill ~30 ~35 ~15 ~31 ~35 ~15 stained_hardened_clay 0  
fill ~30 ~35 ~16 ~31 ~35 ~16 stained_hardened_clay 0  
fill ~30 ~35 ~17 ~31 ~35 ~17 stained_hardened_clay 0  
fill ~30 ~35 ~18 ~31 ~35 ~18 stained_hardened_clay 0  
fill ~30 ~35 ~19 ~31 ~35 ~19 stained_hardened_clay 0  
fill ~30 ~35 ~20 ~31 ~35 ~20 stained_hardened_clay 0  
fill ~30 ~35 ~21 ~31 ~35 ~21 stained_hardened_clay 0  
fill ~30 ~35 ~22 ~31 ~35 ~22 stained_hardened_clay 0  
fill ~30 ~35 ~23 ~31 ~35 ~23 stained_hardened_clay 0  
fill ~30 ~35 ~24 ~31 ~35 ~24 concrete 4  
fill ~30 ~35 ~25 ~31 ~35 ~25 stained_hardened_clay 9  
fill ~30 ~35 ~26 ~31 ~35 ~26 stained_hardened_clay 9  
fill ~30 ~35 ~170 ~31 ~35 ~170 stained_hardened_clay 9  
fill ~30 ~35 ~171 ~31 ~35 ~171 stained_hardened_clay 9  
fill ~30 ~35 ~172 ~31 ~35 ~172 concrete 4  
fill ~30 ~35 ~173 ~31 ~35 ~173 stained_hardened_clay 0  
fill ~30 ~35 ~174 ~31 ~35 ~174 stained_hardened_clay 0  
fill ~30 ~35 ~175 ~31 ~35 ~175 stained_hardened_clay 0  
fill ~30 ~35 ~176 ~31 ~35 ~176 stained_hardened_clay 0  
fill ~30 ~35 ~177 ~31 ~35 ~177 stained_hardened_clay 0  
fill ~30 ~35 ~178 ~31 ~35 ~178 stained_hardened_clay 0  
fill ~30 ~35 ~179 ~31 ~35 ~179 stained_hardened_clay 0  
fill ~30 ~35 ~180 ~31 ~35 ~180 stained_hardened_clay 0  
