fill ~1 ~0 ~8 ~3 ~0 ~8 tallgrass 1 
setblock ~1 ~0 ~10 tallgrass 2 
setblock ~1 ~0 ~12 tallgrass 2 
setblock ~1 ~0 ~14 double_plant 2  
fill ~1 ~0 ~16 ~1 ~0 ~17 double_plant 2 
setblock ~1 ~0 ~21 tallgrass 1 
setblock ~1 ~0 ~23 double_plant 2  
fill ~1 ~0 ~24 ~1 ~0 ~26 leaves 7 
setblock ~1 ~0 ~28 tallgrass 2 
setblock ~1 ~0 ~36 tallgrass 1 
setblock ~1 ~0 ~39 tallgrass 1 
setblock ~1 ~0 ~47 tallgrass 1  
fill ~1 ~0 ~50 ~1 ~0 ~51 tallgrass 2 
setblock ~1 ~0 ~53 double_plant 2 
setblock ~1 ~0 ~54 double_plant 3 
setblock ~1 ~0 ~56 double_plant 2 
setblock ~1 ~0 ~57 tallgrass 2 
setblock ~1 ~0 ~60 tallgrass 1 
setblock ~1 ~0 ~62 tallgrass 1 
setblock ~2 ~0 ~11 double_plant 2 
setblock ~2 ~0 ~12 stone_stairs 0 
setblock ~2 ~0 ~13 double_plant 3 
setblock ~2 ~0 ~16 double_plant 3 
setblock ~2 ~0 ~18 double_plant 2 
setblock ~2 ~0 ~20 tallgrass 1 
setblock ~2 ~0 ~22 double_plant 3  
fill ~2 ~0 ~23 ~2 ~0 ~24 leaves 15  
fill ~2 ~0 ~25 ~2 ~1 ~25 leaves 7 
setblock ~2 ~0 ~26 stone_stairs 0 
setblock ~2 ~0 ~35 tallgrass 1 
setblock ~2 ~0 ~40 tallgrass 2 
setblock ~2 ~0 ~42 tallgrass 1  
fill ~2 ~0 ~44 ~2 ~0 ~45 tallgrass 1  
fill ~2 ~0 ~48 ~2 ~0 ~49 tallgrass 1  
fill ~2 ~0 ~51 ~2 ~0 ~52 double_plant 2  
fill ~2 ~0 ~53 ~2 ~0 ~57 cobblestone 0 
setblock ~2 ~0 ~58 double_plant 3 
setblock ~2 ~0 ~59 double_plant 2 
setblock ~2 ~0 ~60 tallgrass 2 
setblock ~3 ~0 ~6 tallgrass 1 
setblock ~3 ~0 ~9 double_plant 2 
setblock ~3 ~0 ~11 stone_stairs 2  
fill ~3 ~0 ~12 ~7 ~0 ~12 cobblestone 0  
fill ~3 ~0 ~13 ~3 ~0 ~16 cobblestone 0  
fill ~3 ~0 ~17 ~3 ~0 ~18 stone_stairs 0 
setblock ~3 ~0 ~19 cobblestone 0  
fill ~3 ~0 ~20 ~3 ~0 ~21 stone_stairs 0  
fill ~3 ~0 ~22 ~3 ~0 ~26 cobblestone 0 
setblock ~3 ~0 ~27 stone_stairs 3 
setblock ~3 ~0 ~36 tallgrass 2 
setblock ~3 ~0 ~39 tallgrass 1 
setblock ~3 ~0 ~41 tallgrass 1 
setblock ~3 ~0 ~48 tallgrass 2 
setblock ~3 ~0 ~51 double_plant 3 
setblock ~3 ~0 ~52 cobblestone 0  
fill ~3 ~0 ~53 ~4 ~0 ~53 stone 0  
fill ~3 ~0 ~54 ~4 ~0 ~54 stone 0  
fill ~3 ~0 ~55 ~4 ~0 ~55 stone 0  
fill ~3 ~0 ~56 ~4 ~0 ~56 stone 0  
fill ~3 ~0 ~57 ~4 ~0 ~57 stone 0 
setblock ~3 ~0 ~58 cobblestone 0 
setblock ~3 ~0 ~60 double_plant 2 
setblock ~3 ~0 ~61 double_plant 3  
fill ~4 ~0 ~7 ~5 ~0 ~7 tallgrass 1 
setblock ~4 ~0 ~10 tallgrass 2  
fill ~4 ~0 ~13 ~16 ~0 ~13 stone 0  
fill ~4 ~0 ~14 ~4 ~13 ~14 stone 0  
fill ~4 ~0 ~15 ~4 ~4 ~15 stone 0  
fill ~4 ~0 ~16 ~4 ~2 ~16 stone 0  
fill ~4 ~0 ~17 ~4 ~2 ~17 stone 0  
fill ~4 ~0 ~18 ~4 ~2 ~18 stone 0  
fill ~4 ~0 ~19 ~4 ~2 ~19 stone 0  
fill ~4 ~0 ~20 ~4 ~2 ~20 stone 0  
fill ~4 ~0 ~21 ~4 ~2 ~21 stone 0  
fill ~4 ~0 ~22 ~4 ~2 ~22 stone 0  
fill ~4 ~0 ~23 ~4 ~4 ~23 stone 0  
fill ~4 ~0 ~24 ~4 ~13 ~24 stone 0  
fill ~4 ~0 ~25 ~16 ~0 ~25 stone 0  
fill ~4 ~0 ~26 ~5 ~0 ~26 cobblestone 0 
setblock ~4 ~0 ~37 tallgrass 2  
fill ~4 ~0 ~38 ~4 ~0 ~39 double_plant 2 
setblock ~4 ~0 ~43 tallgrass 1  
fill ~4 ~0 ~46 ~5 ~0 ~46 double_plant 2  
fill ~4 ~0 ~47 ~4 ~0 ~46 double_plant 2 
setblock ~4 ~0 ~49 double_plant 2 
setblock ~4 ~0 ~51 mossy_cobblestone 0  
fill ~4 ~0 ~52 ~5 ~0 ~52 stone 0  
fill ~4 ~0 ~58 ~5 ~0 ~58 stone 0 
setblock ~4 ~0 ~59 cobblestone 0 
setblock ~5 ~0 ~6 tallgrass 1 
setblock ~5 ~0 ~9 tallgrass 1 
setblock ~5 ~0 ~27 tallgrass 2 
setblock ~5 ~0 ~35 tallgrass 1 
setblock ~5 ~0 ~37 double_plant 3  
fill ~5 ~0 ~39 ~5 ~1 ~39 leaves 7  
fill ~5 ~0 ~40 ~5 ~0 ~41 leaves 7 
setblock ~5 ~0 ~42 tallgrass 2 
setblock ~5 ~0 ~44 tallgrass 2 
setblock ~5 ~0 ~48 double_plant 3 
setblock ~5 ~0 ~50 cobblestone 0  
fill ~5 ~0 ~51 ~10 ~0 ~51 stone 0  
fill ~5 ~0 ~59 ~11 ~0 ~59 stone 0 
setblock ~5 ~0 ~60 cobblestone 0 
setblock ~5 ~0 ~61 double_plant 2 
setblock ~6 ~0 ~3 tallgrass 1  
fill ~6 ~0 ~5 ~7 ~0 ~5 tallgrass 1 
setblock ~6 ~0 ~8 tallgrass 2 
setblock ~6 ~0 ~11 double_plant 2 
setblock ~6 ~0 ~26 mossy_cobblestone 0 
setblock ~6 ~0 ~28 double_plant 2 
setblock ~6 ~0 ~35 stone_stairs 0 
setblock ~6 ~0 ~36 double_plant 3 
setblock ~6 ~0 ~38 leaves 7 
setblock ~6 ~0 ~40 double_plant 3 
setblock ~6 ~0 ~42 double_plant 2  
fill ~6 ~0 ~44 ~6 ~0 ~45 double_plant 2 
setblock ~6 ~0 ~46 double_plant 3 
setblock ~6 ~0 ~47 double_plant 2  
fill ~6 ~0 ~49 ~7 ~0 ~49 cobblestone 0  
fill ~6 ~0 ~50 ~8 ~0 ~50 stone 0  
fill ~6 ~0 ~60 ~10 ~0 ~60 stone 0  
fill ~6 ~0 ~61 ~10 ~0 ~61 cobblestone 0 
setblock ~6 ~0 ~62 double_plant 2 
setblock ~7 ~0 ~4 tallgrass 1  
fill ~7 ~0 ~9 ~8 ~0 ~9 tallgrass 1 
setblock ~7 ~0 ~11 double_plant 3 
setblock ~7 ~0 ~26 cobblestone 0 
setblock ~7 ~0 ~27 double_plant 3 
setblock ~7 ~0 ~34 stone_stairs 2  
fill ~7 ~0 ~35 ~7 ~6 ~35 cobblestone 0  
fill ~7 ~0 ~36 ~7 ~0 ~39 cobblestone 0 
setblock ~7 ~0 ~40 mossy_cobblestone 0  
fill ~7 ~0 ~41 ~7 ~0 ~47 cobblestone 0 
setblock ~7 ~0 ~48 mossy_cobblestone 0 
setblock ~8 ~0 ~1 tallgrass 1 
setblock ~8 ~0 ~6 tallgrass 1 
setblock ~8 ~0 ~10 double_plant 2  
fill ~8 ~0 ~12 ~9 ~0 ~12 stone_stairs 2  
fill ~8 ~0 ~26 ~9 ~0 ~26 stone_stairs 3  
fill ~8 ~0 ~34 ~9 ~0 ~34 double_plant 2  
fill ~8 ~0 ~35 ~8 ~1 ~35 stone_stairs 1  
fill ~8 ~0 ~36 ~16 ~0 ~36 stone 0  
fill ~8 ~0 ~37 ~8 ~20 ~37 stone 0  
fill ~8 ~0 ~38 ~8 ~2 ~38 stone 0  
fill ~8 ~0 ~39 ~8 ~2 ~39 stone 0  
fill ~8 ~0 ~40 ~8 ~2 ~40 stone 0  
fill ~8 ~0 ~41 ~8 ~2 ~41 stone 0  
fill ~8 ~0 ~42 ~8 ~14 ~42 stone 0  
fill ~8 ~0 ~43 ~8 ~14 ~43 stone 0  
fill ~8 ~0 ~44 ~8 ~2 ~44 stone 0  
fill ~8 ~0 ~45 ~8 ~2 ~45 stone 0  
fill ~8 ~0 ~46 ~8 ~2 ~46 stone 0  
fill ~8 ~0 ~47 ~8 ~2 ~47 stone 0  
fill ~8 ~0 ~48 ~8 ~20 ~48 stone 0  
fill ~8 ~0 ~49 ~8 ~20 ~49 stone 0 
setblock ~8 ~0 ~62 double_plant 2 
setblock ~9 ~0 ~2 tallgrass 1 
setblock ~9 ~0 ~9 tallgrass 2 
setblock ~9 ~0 ~11 double_plant 2 
setblock ~9 ~0 ~27 double_plant 3 
setblock ~9 ~0 ~28 double_plant 2 
setblock ~9 ~0 ~33 double_plant 2 
setblock ~9 ~0 ~35 stone_stairs 0 
setblock ~10 ~0 ~5 tallgrass 1 
setblock ~10 ~0 ~7 tallgrass 1  
fill ~10 ~0 ~10 ~11 ~0 ~10 double_plant 2 
setblock ~10 ~0 ~11 double_plant 3 
setblock ~10 ~0 ~12 cobblestone 0 
setblock ~10 ~0 ~26 cobblestone 0 
setblock ~10 ~0 ~27 double_plant 2  
fill ~10 ~0 ~35 ~11 ~0 ~35 cobblestone 0 
setblock ~10 ~0 ~62 double_plant 3  
fill ~11 ~0 ~4 ~12 ~0 ~4 tallgrass 1 
setblock ~11 ~0 ~8 tallgrass 1 
setblock ~11 ~0 ~9 tallgrass 2  
fill ~11 ~0 ~12 ~12 ~0 ~12 stone_stairs 2  
fill ~11 ~0 ~26 ~12 ~0 ~26 stone_stairs 3  
fill ~11 ~0 ~27 ~14 ~0 ~27 double_plant 3 
setblock ~11 ~0 ~28 cobblestone_wall 0 
setblock ~11 ~0 ~33 cobblestone_wall 0 
setblock ~11 ~0 ~34 double_plant 3  
fill ~11 ~0 ~52 ~11 ~1 ~52 stone 0  
fill ~11 ~0 ~58 ~12 ~0 ~58 stone 0 
setblock ~11 ~0 ~60 cobblestone 0 
setblock ~11 ~0 ~62 double_plant 2 
setblock ~12 ~0 ~6 tallgrass 2 
setblock ~12 ~0 ~9 double_plant 2 
setblock ~12 ~0 ~11 double_plant 3 
setblock ~12 ~0 ~28 stone 4 
setblock ~12 ~0 ~29 stone_brick_stairs 0  
fill ~12 ~0 ~30 ~12 ~0 ~31 spruce_stairs 0 
setblock ~12 ~0 ~32 stone_brick_stairs 0 
setblock ~12 ~0 ~33 stone 4 
setblock ~12 ~0 ~35 stone_stairs 1  
fill ~12 ~0 ~53 ~12 ~1 ~53 stone 0  
fill ~12 ~0 ~54 ~12 ~1 ~54 stone 0  
fill ~12 ~0 ~55 ~33 ~0 ~55 stone 0  
fill ~12 ~0 ~56 ~33 ~0 ~56 stone 0  
fill ~12 ~0 ~57 ~13 ~0 ~57 stone 0 
setblock ~12 ~0 ~59 cobblestone 0 
setblock ~12 ~0 ~60 double_plant 3 
setblock ~12 ~0 ~62 double_plant 3 
setblock ~13 ~0 ~2 tallgrass 1 
setblock ~13 ~0 ~9 leaves 15 
setblock ~13 ~0 ~11 double_plant 2  
fill ~13 ~0 ~12 ~15 ~0 ~12 cobblestone 0  
fill ~13 ~0 ~26 ~15 ~0 ~26 cobblestone 0  
fill ~13 ~0 ~29 ~15 ~0 ~29 stonebrick 0  
fill ~13 ~0 ~30 ~13 ~0 ~31 planks 1  
fill ~13 ~0 ~32 ~15 ~0 ~32 stonebrick 0  
fill ~13 ~0 ~34 ~14 ~0 ~34 double_plant 3 
setblock ~13 ~0 ~35 stone_stairs 0 
setblock ~13 ~0 ~58 cobblestone 0 
setblock ~13 ~0 ~61 double_plant 2 
setblock ~14 ~0 ~1 tallgrass 1 
setblock ~14 ~0 ~5 tallgrass 1  
fill ~14 ~0 ~8 ~14 ~1 ~8 leaves 7 
setblock ~14 ~0 ~10 leaves 15 
setblock ~14 ~0 ~11 double_plant 3  
fill ~14 ~0 ~35 ~15 ~0 ~35 cobblestone 0  
fill ~14 ~0 ~57 ~15 ~0 ~57 cobblestone 0  
fill ~14 ~0 ~58 ~14 ~0 ~60 leaves 7 
setblock ~15 ~0 ~3 tallgrass 2 
setblock ~15 ~0 ~4 double_plant 2 
setblock ~15 ~0 ~5 stone_stairs 2  
fill ~15 ~0 ~6 ~17 ~0 ~6 cobblestone 0  
fill ~15 ~0 ~7 ~15 ~0 ~11 stone_stairs 0  
fill ~15 ~0 ~27 ~15 ~2 ~27 cobblestone 0 
setblock ~15 ~0 ~28 stone_stairs 3  
fill ~15 ~0 ~30 ~15 ~1 ~30 cobblestone 0  
fill ~15 ~0 ~31 ~15 ~1 ~31 cobblestone 0 
setblock ~15 ~0 ~33 stone_stairs 2  
fill ~15 ~0 ~34 ~15 ~2 ~34 cobblestone 0 
setblock ~15 ~0 ~58 double_plant 3  
fill ~15 ~0 ~59 ~18 ~0 ~59 double_plant 2 
setblock ~15 ~0 ~61 double_plant 2 
setblock ~15 ~0 ~62 tallgrass 2  
fill ~16 ~0 ~0 ~17 ~0 ~0 tallgrass 1  
fill ~16 ~0 ~2 ~17 ~0 ~2 tallgrass 2  
fill ~16 ~0 ~3 ~16 ~0 ~4 double_plant 3  
fill ~16 ~0 ~7 ~45 ~0 ~7 stone 0  
fill ~16 ~0 ~8 ~16 ~26 ~8 stone 0  
fill ~16 ~0 ~9 ~16 ~26 ~9 stone 0  
fill ~16 ~0 ~10 ~16 ~26 ~10 stone 0  
fill ~16 ~0 ~11 ~16 ~26 ~11 stone 0  
fill ~16 ~0 ~12 ~16 ~26 ~12 stone 0  
fill ~16 ~0 ~26 ~16 ~7 ~26 stone 0  
fill ~16 ~0 ~27 ~16 ~26 ~27 stone 0  
fill ~16 ~0 ~28 ~16 ~15 ~28 stone 0  
fill ~16 ~0 ~29 ~16 ~1 ~29 stone 0  
fill ~16 ~0 ~30 ~16 ~1 ~30 stone 0  
fill ~16 ~0 ~31 ~16 ~1 ~31 stone 0  
fill ~16 ~0 ~32 ~16 ~1 ~32 stone 0  
fill ~16 ~0 ~33 ~16 ~15 ~33 stone 0  
fill ~16 ~0 ~34 ~16 ~26 ~34 stone 0  
fill ~16 ~0 ~35 ~16 ~26 ~35 stone 0 
setblock ~16 ~0 ~57 mossy_cobblestone 0 
setblock ~17 ~0 ~5 double_plant 3 
setblock ~17 ~0 ~8 stonebrick 2  
fill ~17 ~0 ~46 ~17 ~1 ~46 stonebrick 0  
fill ~17 ~0 ~57 ~22 ~0 ~57 cobblestone 0 
setblock ~17 ~0 ~60 double_plant 2 
setblock ~17 ~0 ~61 tallgrass 2 
setblock ~18 ~0 ~2 tallgrass 1 
setblock ~18 ~0 ~3 mossy_cobblestone 0  
fill ~18 ~0 ~4 ~18 ~2 ~4 cobblestone 0  
fill ~18 ~0 ~5 ~18 ~4 ~5 cobblestone 0 
setblock ~18 ~0 ~6 mossy_cobblestone 0  
fill ~18 ~0 ~61 ~19 ~0 ~61 tallgrass 1  
fill ~19 ~0 ~0 ~20 ~0 ~0 tallgrass 1 
setblock ~19 ~0 ~2 tallgrass 2 
setblock ~19 ~0 ~4 leaves 7  
fill ~19 ~0 ~6 ~20 ~0 ~6 cobblestone 0  
fill ~19 ~0 ~58 ~20 ~0 ~58 double_plant 2 
setblock ~20 ~0 ~2 double_plant 2  
fill ~20 ~0 ~3 ~20 ~1 ~3 leaves 7 
setblock ~21 ~0 ~1 tallgrass 1 
setblock ~21 ~0 ~2 tallgrass 2  
fill ~21 ~0 ~5 ~22 ~0 ~5 leaves 7 
setblock ~21 ~0 ~6 mossy_cobblestone 0 
setblock ~21 ~0 ~58 double_plant 3 
setblock ~21 ~0 ~60 tallgrass 1 
setblock ~21 ~0 ~61 tallgrass 2  
fill ~21 ~0 ~62 ~22 ~0 ~62 tallgrass 1 
setblock ~22 ~0 ~1 tallgrass 2 
setblock ~22 ~0 ~2 double_plant 2  
fill ~22 ~0 ~3 ~23 ~0 ~3 double_plant 3 
setblock ~22 ~0 ~4 leaves 7  
fill ~22 ~0 ~6 ~33 ~0 ~6 cobblestone 0 
setblock ~22 ~0 ~59 double_plant 2  
fill ~22 ~0 ~60 ~23 ~0 ~60 tallgrass 2 
setblock ~23 ~0 ~0 tallgrass 1 
setblock ~23 ~0 ~5 double_plant 3 
setblock ~23 ~0 ~57 mossy_cobblestone 0 
setblock ~23 ~0 ~58 double_plant 3 
setblock ~24 ~0 ~2 tallgrass 2  
fill ~24 ~0 ~3 ~24 ~0 ~6 cobblestone 0  
fill ~24 ~0 ~35 ~24 ~1 ~35 cobblestone 0  
fill ~24 ~0 ~57 ~30 ~0 ~57 cobblestone 0  
fill ~24 ~0 ~59 ~24 ~0 ~60 double_plant 2 
setblock ~24 ~0 ~61 tallgrass 1 
setblock ~25 ~0 ~5 double_plant 3  
fill ~25 ~0 ~58 ~29 ~0 ~58 leaves 7 
setblock ~26 ~0 ~3 tallgrass 2  
fill ~26 ~0 ~59 ~29 ~0 ~59 leaves 7 
setblock ~26 ~0 ~60 tallgrass 1 
setblock ~26 ~0 ~62 tallgrass 1  
fill ~27 ~0 ~0 ~30 ~0 ~0 tallgrass 1  
fill ~27 ~0 ~1 ~27 ~0 ~2 tallgrass 1 
setblock ~27 ~0 ~5 double_plant 2 
setblock ~28 ~0 ~1 tallgrass 2 
setblock ~28 ~0 ~3 tallgrass 1 
setblock ~28 ~0 ~4 double_plant 2  
fill ~28 ~0 ~22 ~31 ~0 ~22 planks 1  
fill ~28 ~0 ~23 ~29 ~0 ~23 planks 5  
fill ~28 ~0 ~24 ~29 ~0 ~24 planks 5  
fill ~28 ~0 ~25 ~29 ~0 ~25 planks 5  
fill ~28 ~0 ~26 ~29 ~0 ~26 planks 5 
setblock ~28 ~0 ~61 tallgrass 2 
setblock ~28 ~0 ~62 tallgrass 1 
setblock ~29 ~0 ~3 double_plant 2 
setblock ~29 ~0 ~4 double_plant 3  
fill ~29 ~0 ~27 ~31 ~0 ~27 planks 1 
setblock ~29 ~0 ~60 double_plant 2 
setblock ~30 ~0 ~2 double_plant 3  
fill ~30 ~0 ~3 ~30 ~6 ~3 cobblestone 0  
fill ~30 ~0 ~4 ~30 ~11 ~4 cobblestone 0  
fill ~30 ~0 ~5 ~30 ~8 ~5 cobblestone 0 
setblock ~30 ~0 ~23 stone_stairs 1  
fill ~30 ~0 ~24 ~30 ~0 ~25 spruce_stairs 1 
setblock ~30 ~0 ~26 stone_stairs 1 
setblock ~30 ~0 ~59 double_plant 3 
setblock ~31 ~0 ~1 tallgrass 1 
setblock ~31 ~0 ~3 tallgrass 2 
setblock ~31 ~0 ~57 mossy_cobblestone 0 
setblock ~31 ~0 ~58 double_plant 3 
setblock ~31 ~0 ~59 double_plant 2  
fill ~31 ~0 ~62 ~32 ~0 ~62 tallgrass 1 
setblock ~32 ~0 ~0 tallgrass 1  
fill ~32 ~0 ~2 ~32 ~0 ~3 tallgrass 1  
fill ~32 ~0 ~4 ~32 ~0 ~5 double_plant 2  
fill ~32 ~0 ~22 ~32 ~7 ~22 planks 5  
fill ~32 ~0 ~27 ~32 ~7 ~27 planks 5 
setblock ~32 ~0 ~57 cobblestone 0 
setblock ~32 ~0 ~61 tallgrass 1  
fill ~33 ~0 ~22 ~34 ~0 ~22 planks 1  
fill ~33 ~0 ~27 ~34 ~0 ~27 planks 1  
fill ~33 ~0 ~47 ~55 ~0 ~47 stone 0  
fill ~33 ~0 ~48 ~33 ~26 ~48 stone 0  
fill ~33 ~0 ~49 ~33 ~14 ~49 stone 0  
fill ~33 ~0 ~50 ~33 ~2 ~50 stone 0  
fill ~33 ~0 ~51 ~33 ~14 ~51 stone 0  
fill ~33 ~0 ~52 ~33 ~26 ~52 stone 0  
fill ~33 ~0 ~53 ~33 ~14 ~53 stone 0  
fill ~33 ~0 ~54 ~33 ~2 ~54 stone 0 
setblock ~33 ~0 ~57 mossy_cobblestone 0 
setblock ~33 ~0 ~58 double_plant 3 
setblock ~33 ~0 ~59 tallgrass 2 
setblock ~34 ~0 ~3 double_plant 2 
setblock ~34 ~0 ~5 double_plant 3 
setblock ~34 ~0 ~6 mossy_cobblestone 0 
setblock ~34 ~0 ~48 mossy_cobblestone 0 
setblock ~34 ~0 ~49 stone_stairs 3 
setblock ~34 ~0 ~50 cobblestone 0 
setblock ~34 ~0 ~51 stone_stairs 2  
fill ~34 ~0 ~52 ~37 ~0 ~52 cobblestone 0 
setblock ~34 ~0 ~53 stone_stairs 3 
setblock ~34 ~0 ~54 cobblestone 0 
setblock ~34 ~0 ~55 stone_stairs 2  
fill ~34 ~0 ~56 ~34 ~5 ~56 cobblestone 0  
fill ~34 ~0 ~57 ~37 ~0 ~57 cobblestone 0 
setblock ~34 ~0 ~60 double_plant 2 
setblock ~34 ~0 ~61 tallgrass 1 
setblock ~35 ~0 ~1 tallgrass 1 
setblock ~35 ~0 ~2 tallgrass 2 
setblock ~35 ~0 ~4 double_plant 3  
fill ~35 ~0 ~6 ~37 ~0 ~6 cobblestone 0  
fill ~35 ~0 ~22 ~35 ~0 ~22 log 1 
setblock ~35 ~0 ~23 log 1 
setblock ~35 ~0 ~24 spruce_stairs 7 
setblock ~35 ~0 ~25 spruce_stairs 6  
fill ~35 ~0 ~26 ~35 ~0 ~27 log 1  
fill ~35 ~0 ~48 ~37 ~0 ~48 cobblestone 0  
fill ~35 ~0 ~49 ~35 ~1 ~49 cobblestone 0 
setblock ~35 ~0 ~50 stone_stairs 3  
fill ~35 ~0 ~51 ~37 ~0 ~51 double_plant 3  
fill ~35 ~0 ~53 ~36 ~0 ~53 leaves 7  
fill ~35 ~0 ~54 ~37 ~0 ~54 leaves 7 
setblock ~35 ~0 ~56 double_plant 3 
setblock ~35 ~0 ~58 double_plant 2 
setblock ~36 ~0 ~0 tallgrass 1 
setblock ~36 ~0 ~2 double_plant 2  
fill ~36 ~0 ~3 ~36 ~6 ~3 cobblestone 0 
setblock ~36 ~0 ~4 mossy_cobblestone 0  
fill ~36 ~0 ~5 ~36 ~14 ~5 cobblestone 0  
fill ~36 ~0 ~22 ~37 ~0 ~22 planks 1  
fill ~36 ~0 ~23 ~36 ~0 ~26 stone_brick_stairs 4  
fill ~36 ~0 ~27 ~36 ~0 ~27 planks 1 
setblock ~36 ~0 ~49 double_plant 3 
setblock ~36 ~0 ~55 leaves 15 
setblock ~36 ~0 ~58 double_plant 3 
setblock ~36 ~0 ~59 tallgrass 2 
setblock ~37 ~0 ~5 double_plant 3  
fill ~37 ~0 ~23 ~37 ~0 ~26 planks 1 
setblock ~37 ~0 ~55 double_plant 3 
setblock ~37 ~0 ~60 tallgrass 2  
fill ~37 ~0 ~61 ~37 ~0 ~62 tallgrass 1 
setblock ~38 ~0 ~2 double_plant 2 
setblock ~38 ~0 ~5 tallgrass 2 
setblock ~38 ~0 ~6 mossy_cobblestone 0 
setblock ~38 ~0 ~48 mossy_cobblestone 0  
fill ~38 ~0 ~50 ~39 ~0 ~50 double_plant 2 
setblock ~38 ~0 ~52 double_plant 2 
setblock ~38 ~0 ~55 double_plant 2 
setblock ~38 ~0 ~58 double_plant 2 
setblock ~38 ~0 ~60 tallgrass 1 
setblock ~39 ~0 ~2 double_plant 3  
fill ~39 ~0 ~3 ~39 ~0 ~4 leaves 7  
fill ~39 ~0 ~5 ~41 ~0 ~5 leaves 15  
fill ~39 ~0 ~6 ~44 ~0 ~6 cobblestone 0 
setblock ~39 ~0 ~48 cobblestone 0 
setblock ~39 ~0 ~51 tallgrass 2 
setblock ~39 ~0 ~57 double_plant 2 
setblock ~39 ~0 ~59 tallgrass 2 
setblock ~40 ~0 ~0 tallgrass 1  
fill ~40 ~0 ~1 ~41 ~0 ~1 tallgrass 2 
setblock ~40 ~0 ~3 double_plant 3  
fill ~40 ~0 ~4 ~41 ~0 ~4 leaves 7 
setblock ~40 ~0 ~48 mossy_cobblestone 0  
fill ~40 ~0 ~49 ~40 ~1 ~49 cobblestone 0 
setblock ~40 ~0 ~50 stone_stairs 3 
setblock ~40 ~0 ~51 double_plant 2  
fill ~40 ~0 ~52 ~41 ~0 ~52 tallgrass 1  
fill ~40 ~0 ~53 ~40 ~0 ~52 tallgrass 1 
setblock ~40 ~0 ~55 tallgrass 2  
fill ~40 ~0 ~59 ~41 ~0 ~59 tallgrass 1 
setblock ~41 ~0 ~2 double_plant 3  
fill ~41 ~0 ~48 ~43 ~0 ~48 cobblestone 0 
setblock ~41 ~0 ~49 double_plant 2  
fill ~41 ~0 ~51 ~42 ~0 ~51 tallgrass 2 
setblock ~41 ~0 ~55 tallgrass 1 
setblock ~41 ~0 ~57 tallgrass 1  
fill ~42 ~0 ~1 ~43 ~0 ~1 double_plant 2  
fill ~42 ~0 ~3 ~42 ~6 ~3 cobblestone 0  
fill ~42 ~0 ~4 ~42 ~4 ~4 cobblestone 0  
fill ~42 ~0 ~5 ~42 ~7 ~5 cobblestone 0 
setblock ~42 ~0 ~49 double_plant 3 
setblock ~42 ~0 ~50 double_plant 2 
setblock ~43 ~0 ~52 tallgrass 1  
fill ~44 ~0 ~1 ~45 ~0 ~1 cobblestone 0  
fill ~44 ~0 ~2 ~44 ~0 ~1 cobblestone 0  
fill ~44 ~0 ~3 ~44 ~0 ~5 stone_stairs 0 
setblock ~44 ~0 ~48 mossy_cobblestone 0 
setblock ~44 ~0 ~49 double_plant 3 
setblock ~44 ~0 ~50 tallgrass 2  
fill ~45 ~0 ~2 ~46 ~0 ~2 stone 0  
fill ~45 ~0 ~3 ~54 ~0 ~3 stone 0  
fill ~45 ~0 ~4 ~45 ~13 ~4 stone 0  
fill ~45 ~0 ~5 ~45 ~13 ~5 stone 0  
fill ~45 ~0 ~6 ~45 ~13 ~6 stone 0  
fill ~45 ~0 ~26 ~45 ~1 ~26 purpur_pillar 0  
fill ~45 ~0 ~48 ~53 ~0 ~48 cobblestone 0  
fill ~45 ~0 ~49 ~45 ~3 ~49 cobblestone 0 
setblock ~45 ~0 ~50 stone_stairs 3 
setblock ~45 ~0 ~53 tallgrass 1 
setblock ~45 ~0 ~61 tallgrass 1 
setblock ~46 ~0 ~1 stone_stairs 1  
fill ~46 ~0 ~27 ~46 ~1 ~27 stone 4 
setblock ~46 ~0 ~49 double_plant 2 
setblock ~46 ~0 ~51 tallgrass 2 
setblock ~46 ~0 ~56 tallgrass 1 
setblock ~46 ~0 ~60 tallgrass 1 
setblock ~47 ~0 ~0 double_plant 2  
fill ~47 ~0 ~2 ~47 ~1 ~2 cobblestone 0  
fill ~47 ~0 ~49 ~48 ~0 ~49 double_plant 3  
fill ~47 ~0 ~52 ~47 ~0 ~53 tallgrass 1 
setblock ~48 ~0 ~0 tallgrass 2 
setblock ~48 ~0 ~1 double_plant 3 
setblock ~48 ~0 ~2 stone_stairs 1 
setblock ~48 ~0 ~8 stonebrick 2  
fill ~48 ~0 ~46 ~48 ~1 ~46 stonebrick 0 
setblock ~48 ~0 ~56 tallgrass 1  
fill ~49 ~0 ~1 ~49 ~0 ~2 leaves 7  
fill ~49 ~0 ~49 ~49 ~0 ~51 double_plant 2 
setblock ~49 ~0 ~52 tallgrass 2 
setblock ~50 ~0 ~0 leaves 7 
setblock ~50 ~0 ~1 leaves 15  
fill ~50 ~0 ~12 ~55 ~0 ~12 stone 0  
fill ~50 ~0 ~13 ~50 ~27 ~13 stone 0  
fill ~50 ~0 ~14 ~50 ~3 ~14 stone 0  
fill ~50 ~0 ~15 ~50 ~3 ~15 stone 0  
fill ~50 ~0 ~16 ~50 ~3 ~16 stone 0  
fill ~50 ~0 ~17 ~50 ~3 ~17 stone 0  
fill ~50 ~0 ~18 ~50 ~3 ~18 stone 0  
fill ~50 ~0 ~19 ~50 ~26 ~19 stone 0  
fill ~50 ~0 ~20 ~53 ~0 ~20 stone 0  
fill ~50 ~0 ~29 ~53 ~0 ~29 stone 0  
fill ~50 ~0 ~30 ~50 ~26 ~30 stone 0  
fill ~50 ~0 ~31 ~50 ~3 ~31 stone 0  
fill ~50 ~0 ~32 ~50 ~3 ~32 stone 0  
fill ~50 ~0 ~33 ~50 ~3 ~33 stone 0  
fill ~50 ~0 ~34 ~50 ~3 ~34 stone 0  
fill ~50 ~0 ~35 ~50 ~3 ~35 stone 0  
fill ~50 ~0 ~36 ~50 ~27 ~36 stone 0  
fill ~50 ~0 ~37 ~55 ~0 ~37 stone 0 
setblock ~50 ~0 ~49 cobblestone 0 
setblock ~50 ~0 ~50 stone_stairs 3 
setblock ~50 ~0 ~57 tallgrass 1  
fill ~51 ~0 ~1 ~51 ~0 ~2 leaves 7  
fill ~51 ~0 ~13 ~54 ~0 ~13 stone_stairs 3  
fill ~51 ~0 ~14 ~51 ~0 ~19 stone_stairs 1  
fill ~51 ~0 ~30 ~52 ~0 ~30 stone_stairs 3  
fill ~51 ~0 ~31 ~51 ~0 ~36 stone_stairs 1 
setblock ~51 ~0 ~51 double_plant 2 
setblock ~51 ~0 ~52 tallgrass 2  
fill ~52 ~0 ~1 ~53 ~0 ~1 leaves 15 
setblock ~52 ~0 ~2 stone_stairs 0  
fill ~52 ~0 ~14 ~54 ~0 ~14 double_plant 2  
fill ~52 ~0 ~15 ~52 ~0 ~16 double_plant 3 
setblock ~52 ~0 ~18 double_plant 3 
setblock ~52 ~0 ~19 stone_stairs 2  
fill ~52 ~0 ~31 ~53 ~0 ~31 leaves 7  
fill ~52 ~0 ~32 ~52 ~1 ~32 leaves 7 
setblock ~52 ~0 ~33 double_plant 3  
fill ~52 ~0 ~35 ~54 ~0 ~35 double_plant 3  
fill ~52 ~0 ~36 ~54 ~0 ~36 stone_stairs 2 
setblock ~52 ~0 ~49 double_plant 3 
setblock ~52 ~0 ~51 tallgrass 1 
setblock ~52 ~0 ~53 tallgrass 1 
setblock ~53 ~0 ~0 double_plant 2  
fill ~53 ~0 ~2 ~53 ~1 ~2 cobblestone 0 
setblock ~53 ~0 ~16 double_plant 2 
setblock ~53 ~0 ~18 double_plant 2  
fill ~53 ~0 ~19 ~54 ~0 ~19 cobblestone 0  
fill ~53 ~0 ~21 ~53 ~12 ~21 stone 0  
fill ~53 ~0 ~22 ~58 ~0 ~22 stone 0  
fill ~53 ~0 ~23 ~58 ~0 ~23 stone 0  
fill ~53 ~0 ~26 ~58 ~0 ~26 stone 0  
fill ~53 ~0 ~27 ~58 ~0 ~27 stone 0  
fill ~53 ~0 ~28 ~53 ~12 ~28 stone 0  
fill ~53 ~0 ~30 ~54 ~0 ~30 cobblestone 0 
setblock ~53 ~0 ~33 leaves 7 
setblock ~53 ~0 ~49 double_plant 2 
setblock ~53 ~0 ~56 tallgrass 1 
setblock ~54 ~0 ~1 stone_stairs 0  
fill ~54 ~0 ~2 ~55 ~0 ~2 stone 0  
fill ~54 ~0 ~4 ~54 ~15 ~4 stone 0  
fill ~54 ~0 ~5 ~54 ~2 ~5 stone 0  
fill ~54 ~0 ~6 ~54 ~2 ~6 stone 0  
fill ~54 ~0 ~7 ~54 ~2 ~7 stone 0  
fill ~54 ~0 ~8 ~54 ~2 ~8 stone 0  
fill ~54 ~0 ~9 ~54 ~2 ~9 stone 0  
fill ~54 ~0 ~10 ~54 ~15 ~10 stone 0  
fill ~54 ~0 ~11 ~54 ~27 ~11 stone 0  
fill ~54 ~0 ~16 ~55 ~0 ~16 tallgrass 2 
setblock ~54 ~0 ~18 tallgrass 1 
setblock ~54 ~0 ~20 stone_stairs 3 
setblock ~54 ~0 ~28 double_plant 3 
setblock ~54 ~0 ~29 stone_stairs 2  
fill ~54 ~0 ~33 ~55 ~0 ~33 double_plant 2 
setblock ~54 ~0 ~48 mossy_cobblestone 0 
setblock ~54 ~0 ~49 double_plant 3 
setblock ~54 ~0 ~50 tallgrass 2 
setblock ~54 ~0 ~53 tallgrass 1 
setblock ~55 ~0 ~1 cobblestone 0  
fill ~55 ~0 ~3 ~55 ~0 ~4 cobblestone 0 
setblock ~55 ~0 ~5 stone_stairs 3 
setblock ~55 ~0 ~8 double_plant 3 
setblock ~55 ~0 ~9 stone_stairs 2  
fill ~55 ~0 ~10 ~55 ~1 ~10 cobblestone 0 
setblock ~55 ~0 ~11 mossy_cobblestone 0  
fill ~55 ~0 ~13 ~56 ~0 ~13 cobblestone 0 
setblock ~55 ~0 ~14 double_plant 3  
fill ~55 ~0 ~19 ~55 ~0 ~20 double_plant 2  
fill ~55 ~0 ~21 ~56 ~0 ~21 double_plant 3  
fill ~55 ~0 ~29 ~55 ~0 ~31 double_plant 2  
fill ~55 ~0 ~36 ~56 ~0 ~36 cobblestone 0  
fill ~55 ~0 ~38 ~55 ~27 ~38 stone 0  
fill ~55 ~0 ~39 ~55 ~0 ~47 stone 0  
fill ~55 ~0 ~48 ~55 ~0 ~49 cobblestone 0 
setblock ~55 ~0 ~50 stone_stairs 3 
setblock ~55 ~0 ~51 tallgrass 2 
setblock ~55 ~0 ~52 tallgrass 1 
setblock ~56 ~0 ~1 mossy_cobblestone 0 
setblock ~56 ~0 ~2 cobblestone 0 
setblock ~56 ~0 ~3 stone_stairs 3 
setblock ~56 ~0 ~4 double_plant 2 
setblock ~56 ~0 ~5 double_plant 3 
setblock ~56 ~0 ~8 double_plant 2 
setblock ~56 ~0 ~9 tallgrass 1 
setblock ~56 ~0 ~10 double_plant 3 
setblock ~56 ~0 ~11 stone_stairs 2 
setblock ~56 ~0 ~12 cobblestone 0 
setblock ~56 ~0 ~16 tallgrass 1 
setblock ~56 ~0 ~18 tallgrass 1 
setblock ~56 ~0 ~28 double_plant 3  
fill ~56 ~0 ~29 ~56 ~0 ~31 tallgrass 2 
setblock ~56 ~0 ~34 double_plant 2 
setblock ~56 ~0 ~35 double_plant 3 
setblock ~56 ~0 ~37 cobblestone 0  
fill ~56 ~0 ~38 ~56 ~0 ~41 stone_stairs 1 
setblock ~56 ~0 ~42 cobblestone 0  
fill ~56 ~0 ~43 ~56 ~0 ~46 stone_stairs 1  
fill ~56 ~0 ~47 ~56 ~0 ~48 mossy_cobblestone 0 
setblock ~56 ~0 ~54 tallgrass 1 
setblock ~57 ~0 ~3 double_plant 2 
setblock ~57 ~0 ~5 double_plant 2 
setblock ~57 ~0 ~6 tallgrass 2 
setblock ~57 ~0 ~8 tallgrass 1 
setblock ~57 ~0 ~10 tallgrass 1 
setblock ~57 ~0 ~11 double_plant 2  
fill ~57 ~0 ~13 ~57 ~2 ~13 leaves 7  
fill ~57 ~0 ~19 ~58 ~0 ~19 tallgrass 1  
fill ~57 ~0 ~24 ~58 ~0 ~24 stone 0  
fill ~57 ~0 ~25 ~58 ~0 ~25 stone 0 
setblock ~57 ~0 ~28 double_plant 2 
setblock ~57 ~0 ~31 tallgrass 2 
setblock ~57 ~0 ~33 tallgrass 1 
setblock ~57 ~0 ~36 stone_stairs 1 
setblock ~57 ~0 ~37 double_plant 3 
setblock ~57 ~0 ~39 double_plant 3 
setblock ~57 ~0 ~40 double_plant 2 
setblock ~57 ~0 ~41 double_plant 3  
fill ~57 ~0 ~42 ~58 ~0 ~42 leaves 7  
fill ~57 ~0 ~44 ~58 ~0 ~44 leaves 15 
setblock ~57 ~0 ~46 leaves 15 
setblock ~57 ~0 ~48 stone_stairs 1 
setblock ~57 ~0 ~50 tallgrass 2  
fill ~58 ~0 ~1 ~59 ~0 ~1 tallgrass 1  
fill ~58 ~0 ~3 ~58 ~0 ~5 tallgrass 1 
setblock ~58 ~0 ~11 tallgrass 1 
setblock ~58 ~0 ~12 tallgrass 2 
setblock ~58 ~0 ~15 tallgrass 1 
setblock ~58 ~0 ~20 double_plant 2 
setblock ~58 ~0 ~29 tallgrass 2  
fill ~58 ~0 ~32 ~59 ~0 ~32 tallgrass 1 
setblock ~58 ~0 ~34 tallgrass 1 
setblock ~58 ~0 ~36 tallgrass 2 
setblock ~58 ~0 ~38 double_plant 2 
setblock ~58 ~0 ~45 leaves 15  
fill ~58 ~0 ~47 ~58 ~0 ~48 double_plant 3  
fill ~58 ~0 ~49 ~59 ~0 ~49 double_plant 2  
fill ~58 ~0 ~50 ~58 ~0 ~51 tallgrass 1 
setblock ~58 ~0 ~54 tallgrass 1 
setblock ~59 ~0 ~6 tallgrass 1  
fill ~59 ~0 ~8 ~60 ~0 ~8 tallgrass 1  
fill ~59 ~0 ~22 ~60 ~0 ~22 stone_stairs 5 
setblock ~59 ~0 ~23 stone_brick_stairs 1  
fill ~59 ~0 ~24 ~59 ~0 ~25 spruce_stairs 1 
setblock ~59 ~0 ~26 stone_brick_stairs 1  
fill ~59 ~0 ~27 ~60 ~0 ~27 stone_stairs 5 
setblock ~59 ~0 ~28 double_plant 2 
setblock ~59 ~0 ~39 tallgrass 2 
setblock ~59 ~0 ~41 double_plant 2 
setblock ~59 ~0 ~43 double_plant 2 
setblock ~59 ~0 ~46 double_plant 2 
setblock ~59 ~0 ~47 tallgrass 1 
setblock ~59 ~0 ~48 double_plant 2 
setblock ~59 ~0 ~51 tallgrass 1 
setblock ~60 ~0 ~2 tallgrass 1 
setblock ~60 ~0 ~12 tallgrass 1 
setblock ~60 ~0 ~16 tallgrass 1 
setblock ~60 ~0 ~18 tallgrass 1  
fill ~60 ~0 ~21 ~60 ~1 ~21 purpur_pillar 0  
fill ~60 ~0 ~28 ~60 ~1 ~28 purpur_pillar 0 
setblock ~60 ~0 ~29 tallgrass 2 
setblock ~60 ~0 ~35 tallgrass 1 
setblock ~60 ~0 ~39 tallgrass 1 
setblock ~60 ~0 ~41 tallgrass 2 
setblock ~60 ~0 ~46 tallgrass 2 
setblock ~60 ~0 ~48 tallgrass 1 
setblock ~61 ~0 ~5 tallgrass 1  
fill ~61 ~0 ~14 ~61 ~0 ~15 tallgrass 1  
fill ~61 ~0 ~20 ~61 ~1 ~20 cobblestone_wall 0  
fill ~61 ~0 ~27 ~62 ~0 ~27 tallgrass 1  
fill ~61 ~0 ~29 ~61 ~1 ~29 cobblestone_wall 0 
setblock ~61 ~0 ~30 double_plant 2 
setblock ~61 ~0 ~31 tallgrass 2 
setblock ~61 ~0 ~33 tallgrass 1  
fill ~61 ~0 ~42 ~61 ~0 ~43 tallgrass 1 
setblock ~61 ~0 ~44 tallgrass 2 
setblock ~61 ~0 ~47 tallgrass 1 
setblock ~62 ~0 ~4 tallgrass 1 
setblock ~62 ~0 ~10 tallgrass 1 
setblock ~62 ~0 ~18 tallgrass 1  
fill ~62 ~0 ~19 ~62 ~1 ~19 cobblestone_wall 0  
fill ~62 ~0 ~20 ~62 ~4 ~20 cobblestone 0  
fill ~62 ~0 ~21 ~62 ~1 ~21 cobblestone_wall 0  
fill ~62 ~0 ~28 ~62 ~1 ~28 cobblestone_wall 0  
fill ~62 ~0 ~29 ~62 ~4 ~29 cobblestone 0  
fill ~62 ~0 ~30 ~62 ~1 ~30 cobblestone_wall 0 
setblock ~62 ~0 ~32 tallgrass 1 
setblock ~62 ~0 ~34 tallgrass 1 
setblock ~62 ~0 ~41 tallgrass 1  
fill ~62 ~0 ~44 ~62 ~0 ~45 tallgrass 1 
setblock ~62 ~0 ~52 tallgrass 1 
setblock ~63 ~0 ~17 tallgrass 1  
fill ~63 ~0 ~19 ~63 ~0 ~19 tallgrass 1  
fill ~63 ~0 ~20 ~63 ~1 ~20 cobblestone_wall 0  
fill ~63 ~0 ~29 ~63 ~1 ~29 cobblestone_wall 0  
fill ~63 ~0 ~30 ~63 ~0 ~30 tallgrass 1 
setblock ~63 ~0 ~33 tallgrass 1 
setblock ~63 ~0 ~36 tallgrass 1  
fill ~63 ~0 ~39 ~63 ~0 ~40 tallgrass 1 
setblock ~63 ~0 ~43 tallgrass 1 
setblock ~63 ~0 ~50 tallgrass 1 
setblock ~1 ~1 ~14 double_plant 10  
fill ~1 ~1 ~16 ~2 ~1 ~16 double_plant 10  
fill ~1 ~1 ~17 ~1 ~1 ~16 double_plant 10 
setblock ~1 ~1 ~23 double_plant 10  
fill ~1 ~1 ~53 ~1 ~1 ~54 double_plant 10 
setblock ~1 ~1 ~56 double_plant 10 
setblock ~2 ~1 ~11 double_plant 10 
setblock ~2 ~1 ~13 double_plant 10 
setblock ~2 ~1 ~18 double_plant 10 
setblock ~2 ~1 ~22 double_plant 10  
fill ~2 ~1 ~51 ~3 ~1 ~51 double_plant 10  
fill ~2 ~1 ~52 ~2 ~1 ~51 double_plant 10  
fill ~2 ~1 ~53 ~2 ~1 ~57 stone_stairs 0  
fill ~2 ~1 ~58 ~2 ~1 ~59 double_plant 10 
setblock ~3 ~1 ~9 double_plant 10 
setblock ~3 ~1 ~12 mossy_cobblestone 0  
fill ~3 ~1 ~13 ~3 ~1 ~15 stone_stairs 0 
setblock ~3 ~1 ~16 stone_stairs 3 
setblock ~3 ~1 ~19 stone_stairs 0 
setblock ~3 ~1 ~22 stone_stairs 2  
fill ~3 ~1 ~23 ~3 ~1 ~25 stone_stairs 0  
fill ~3 ~1 ~26 ~4 ~1 ~26 cobblestone 0 
setblock ~3 ~1 ~52 stone_stairs 0  
fill ~3 ~1 ~53 ~4 ~1 ~53 stone 0  
fill ~3 ~1 ~54 ~4 ~1 ~54 stone 0  
fill ~3 ~1 ~55 ~4 ~1 ~55 stone 0  
fill ~3 ~1 ~56 ~4 ~1 ~56 stone 0  
fill ~3 ~1 ~57 ~4 ~1 ~57 stone 0 
setblock ~3 ~1 ~58 stone_stairs 0  
fill ~3 ~1 ~60 ~3 ~1 ~61 double_plant 10  
fill ~4 ~1 ~12 ~4 ~13 ~12 cobblestone 0  
fill ~4 ~1 ~13 ~16 ~1 ~13 stone 0  
fill ~4 ~1 ~25 ~16 ~1 ~25 stone 0  
fill ~4 ~1 ~38 ~4 ~1 ~39 double_plant 10  
fill ~4 ~1 ~46 ~6 ~1 ~46 double_plant 10  
fill ~4 ~1 ~47 ~4 ~1 ~46 double_plant 10 
setblock ~4 ~1 ~49 double_plant 10 
setblock ~4 ~1 ~51 stone_stairs 0  
fill ~4 ~1 ~52 ~5 ~1 ~52 stone 0  
fill ~4 ~1 ~58 ~5 ~1 ~58 stone 0 
setblock ~4 ~1 ~59 stone_stairs 0  
fill ~5 ~1 ~12 ~6 ~1 ~12 stone_stairs 2  
fill ~5 ~1 ~26 ~6 ~1 ~26 stone_stairs 3 
setblock ~5 ~1 ~37 double_plant 10 
setblock ~5 ~1 ~48 double_plant 10 
setblock ~5 ~1 ~50 stone_stairs 0  
fill ~5 ~1 ~51 ~10 ~1 ~51 stone 0  
fill ~5 ~1 ~59 ~11 ~1 ~59 stone 0 
setblock ~5 ~1 ~60 stone_stairs 0 
setblock ~5 ~1 ~61 double_plant 10  
fill ~6 ~1 ~11 ~7 ~1 ~11 double_plant 10 
setblock ~6 ~1 ~28 double_plant 10 
setblock ~6 ~1 ~36 double_plant 10 
setblock ~6 ~1 ~40 double_plant 10 
setblock ~6 ~1 ~42 double_plant 10  
fill ~6 ~1 ~44 ~6 ~1 ~47 double_plant 10  
fill ~6 ~1 ~49 ~7 ~1 ~49 stone_stairs 2  
fill ~6 ~1 ~50 ~8 ~1 ~50 stone 0  
fill ~6 ~1 ~60 ~10 ~1 ~60 stone 0  
fill ~6 ~1 ~61 ~10 ~1 ~61 stone_stairs 3 
setblock ~6 ~1 ~62 double_plant 10 
setblock ~7 ~1 ~12 stone_stairs 1 
setblock ~7 ~1 ~26 stone_stairs 1 
setblock ~7 ~1 ~27 double_plant 10 
setblock ~7 ~1 ~36 stone_stairs 3  
fill ~7 ~1 ~37 ~7 ~1 ~38 leaves 7 
setblock ~8 ~1 ~10 double_plant 10  
fill ~8 ~1 ~34 ~9 ~1 ~34 double_plant 10  
fill ~8 ~1 ~36 ~16 ~1 ~36 stone 0 
setblock ~8 ~1 ~62 double_plant 10  
fill ~9 ~1 ~11 ~10 ~1 ~11 double_plant 10  
fill ~9 ~1 ~27 ~14 ~1 ~27 double_plant 10  
fill ~9 ~1 ~28 ~9 ~1 ~27 double_plant 10 
setblock ~9 ~1 ~33 double_plant 10  
fill ~10 ~1 ~10 ~11 ~1 ~10 double_plant 10 
setblock ~10 ~1 ~12 stone_stairs 2 
setblock ~10 ~1 ~26 stone_stairs 3  
fill ~10 ~1 ~62 ~12 ~1 ~62 double_plant 10  
fill ~11 ~1 ~28 ~12 ~1 ~28 stone_slab 0  
fill ~11 ~1 ~33 ~12 ~1 ~33 stone_slab 0 
setblock ~11 ~1 ~34 double_plant 10  
fill ~11 ~1 ~58 ~12 ~1 ~58 stone 0 
setblock ~11 ~1 ~60 stone_stairs 3 
setblock ~12 ~1 ~9 double_plant 10  
fill ~12 ~1 ~11 ~14 ~1 ~11 double_plant 10  
fill ~12 ~1 ~55 ~33 ~1 ~55 stone 0  
fill ~12 ~1 ~56 ~33 ~1 ~56 stone 0  
fill ~12 ~1 ~57 ~13 ~1 ~57 stone 0 
setblock ~12 ~1 ~59 stone_stairs 3 
setblock ~12 ~1 ~60 double_plant 10 
setblock ~13 ~1 ~12 stone_stairs 0 
setblock ~13 ~1 ~26 stone_stairs 0 
setblock ~13 ~1 ~28 stone 4 
setblock ~13 ~1 ~29 stone_brick_stairs 0  
fill ~13 ~1 ~30 ~13 ~1 ~31 spruce_stairs 0 
setblock ~13 ~1 ~32 stone_brick_stairs 0 
setblock ~13 ~1 ~33 stone 4  
fill ~13 ~1 ~34 ~14 ~1 ~34 double_plant 10 
setblock ~13 ~1 ~58 stone_stairs 3  
fill ~13 ~1 ~59 ~13 ~1 ~60 leaves 15 
setblock ~13 ~1 ~61 double_plant 10  
fill ~14 ~1 ~12 ~15 ~1 ~12 stone_stairs 2  
fill ~14 ~1 ~26 ~15 ~1 ~26 cobblestone 0 
setblock ~14 ~1 ~29 stonebrick 2 
setblock ~14 ~1 ~32 stonebrick 0  
fill ~14 ~1 ~35 ~15 ~1 ~35 cobblestone 0  
fill ~14 ~1 ~57 ~14 ~0 ~57 cobblestone 0  
fill ~15 ~1 ~4 ~16 ~1 ~4 double_plant 10  
fill ~15 ~1 ~6 ~15 ~3 ~6 cobblestone 0  
fill ~15 ~1 ~7 ~15 ~2 ~7 stone_stairs 3  
fill ~15 ~1 ~8 ~15 ~1 ~7 stone_stairs 3  
fill ~15 ~1 ~10 ~15 ~2 ~10 leaves 7  
fill ~15 ~1 ~29 ~15 ~2 ~29 stonebrick 0 
setblock ~15 ~1 ~32 stonebrick 2 
setblock ~15 ~1 ~57 stone_stairs 1  
fill ~15 ~1 ~58 ~15 ~1 ~59 double_plant 10 
setblock ~15 ~1 ~61 double_plant 10 
setblock ~16 ~1 ~3 double_plant 10 
setblock ~16 ~1 ~6 stone_stairs 0  
fill ~16 ~1 ~7 ~45 ~1 ~7 stone 0  
fill ~16 ~1 ~59 ~18 ~1 ~59 double_plant 10 
setblock ~17 ~1 ~5 double_plant 10  
fill ~17 ~1 ~6 ~18 ~1 ~6 cobblestone 0 
setblock ~17 ~1 ~8 stonebrick 0 
setblock ~17 ~1 ~60 double_plant 10  
fill ~18 ~1 ~3 ~18 ~6 ~3 cobblestone 0  
fill ~19 ~1 ~5 ~19 ~2 ~5 leaves 7 
setblock ~19 ~1 ~6 stone_stairs 1  
fill ~19 ~1 ~58 ~21 ~1 ~58 double_plant 10 
setblock ~20 ~1 ~2 double_plant 10 
setblock ~21 ~1 ~6 cobblestone_wall 0  
fill ~21 ~1 ~57 ~21 ~6 ~57 stone_stairs 3  
fill ~22 ~1 ~2 ~22 ~1 ~3 double_plant 10 
setblock ~22 ~1 ~59 double_plant 10 
setblock ~23 ~1 ~3 double_plant 10 
setblock ~23 ~1 ~5 double_plant 10 
setblock ~23 ~1 ~6 stone_stairs 0 
setblock ~23 ~1 ~58 double_plant 10 
setblock ~24 ~1 ~3 mossy_cobblestone 0  
fill ~24 ~1 ~4 ~24 ~3 ~4 cobblestone 0  
fill ~24 ~1 ~5 ~24 ~1 ~4 cobblestone 0 
setblock ~24 ~1 ~6 mossy_cobblestone 0  
fill ~24 ~1 ~59 ~24 ~1 ~60 double_plant 10 
setblock ~25 ~1 ~5 double_plant 10 
setblock ~25 ~1 ~6 stone_stairs 1 
setblock ~27 ~1 ~5 double_plant 10 
setblock ~27 ~1 ~6 cobblestone_wall 0  
fill ~27 ~1 ~57 ~27 ~6 ~57 stone_stairs 3 
setblock ~27 ~1 ~58 leaves 7  
fill ~28 ~1 ~4 ~29 ~1 ~4 double_plant 10  
fill ~28 ~1 ~23 ~28 ~0 ~23 planks 5
fill ~28 ~1 ~24 ~28 ~0 ~24 planks 5  
fill ~28 ~1 ~25 ~28 ~0 ~25 planks 5  
fill ~28 ~1 ~26 ~28 ~0 ~26 planks 5 
setblock ~29 ~1 ~3 double_plant 10 
setblock ~29 ~1 ~6 stone_stairs 0  
fill ~29 ~1 ~22 ~29 ~7 ~22 planks 5 
setblock ~29 ~1 ~23 stone_stairs 1  
fill ~29 ~1 ~24 ~29 ~1 ~25 spruce_stairs 1 
setblock ~29 ~1 ~26 stone_stairs 1  
fill ~29 ~1 ~27 ~29 ~8 ~27 planks 5 
setblock ~29 ~1 ~57 leaves 7 
setblock ~29 ~1 ~60 double_plant 10 
setblock ~30 ~1 ~2 double_plant 10  
fill ~30 ~1 ~6 ~30 ~10 ~6 cobblestone 0  
fill ~30 ~1 ~22 ~31 ~1 ~22 planks 1  
fill ~30 ~1 ~27 ~31 ~1 ~27 planks 1  
fill ~30 ~1 ~59 ~31 ~1 ~59 double_plant 10 
setblock ~31 ~1 ~6 stone_stairs 1 
setblock ~31 ~1 ~58 double_plant 10  
fill ~32 ~1 ~4 ~32 ~1 ~5 double_plant 10 
setblock ~32 ~1 ~23 dark_oak_fence 0 
setblock ~32 ~1 ~26 dark_oak_fence 0 
setblock ~33 ~1 ~6 cobblestone_wall 0  
fill ~33 ~1 ~22 ~35 ~1 ~22 planks 1  
fill ~33 ~1 ~27 ~35 ~1 ~27 planks 1  
fill ~33 ~1 ~47 ~55 ~1 ~47 stone 0 
setblock ~33 ~1 ~57 stone_stairs 0 
setblock ~33 ~1 ~58 double_plant 10 
setblock ~34 ~1 ~3 double_plant 10 
setblock ~34 ~1 ~5 double_plant 10  
fill ~34 ~1 ~48 ~35 ~1 ~48 cobblestone 0 
setblock ~34 ~1 ~50 cobblestone_wall 0  
fill ~34 ~1 ~52 ~37 ~1 ~52 cobblestone 0 
setblock ~34 ~1 ~54 cobblestone_wall 0  
fill ~34 ~1 ~57 ~34 ~6 ~57 cobblestone 0 
setblock ~34 ~1 ~60 double_plant 10 
setblock ~35 ~1 ~4 double_plant 10 
setblock ~35 ~1 ~6 stone_stairs 0  
fill ~35 ~1 ~23 ~35 ~1 ~26 log 9  
fill ~35 ~1 ~51 ~37 ~1 ~51 double_plant 10  
fill ~35 ~1 ~53 ~35 ~2 ~53 leaves 7 
setblock ~35 ~1 ~56 double_plant 10 
setblock ~35 ~1 ~57 mossy_cobblestone 0  
fill ~35 ~1 ~58 ~36 ~1 ~58 double_plant 10 
setblock ~36 ~1 ~2 double_plant 10  
fill ~36 ~1 ~4 ~36 ~2 ~4 cobblestone 0  
fill ~36 ~1 ~6 ~36 ~5 ~6 cobblestone 0  
fill ~36 ~1 ~23 ~36 ~1 ~26 planks 1 
setblock ~36 ~1 ~49 double_plant 10  
fill ~36 ~1 ~57 ~37 ~1 ~57 cobblestone 0 
setblock ~37 ~1 ~5 double_plant 10 
setblock ~37 ~1 ~6 stone_stairs 1  
fill ~37 ~1 ~55 ~38 ~1 ~55 double_plant 10  
fill ~38 ~1 ~2 ~39 ~1 ~2 double_plant 10  
fill ~38 ~1 ~50 ~39 ~1 ~50 double_plant 10 
setblock ~38 ~1 ~52 double_plant 10 
setblock ~38 ~1 ~58 double_plant 10 
setblock ~39 ~1 ~6 cobblestone_wall 0 
setblock ~39 ~1 ~57 double_plant 10 
setblock ~40 ~1 ~3 double_plant 10  
fill ~40 ~1 ~5 ~41 ~1 ~5 leaves 15  
fill ~40 ~1 ~48 ~40 ~9 ~48 cobblestone 0 
setblock ~40 ~1 ~51 double_plant 10 
setblock ~41 ~1 ~2 double_plant 10 
setblock ~41 ~1 ~6 stone_stairs 0  
fill ~41 ~1 ~49 ~42 ~1 ~49 double_plant 10  
fill ~42 ~1 ~1 ~43 ~1 ~1 double_plant 10  
fill ~42 ~1 ~6 ~42 ~3 ~6 cobblestone 0 
setblock ~42 ~1 ~50 double_plant 10 
setblock ~43 ~1 ~6 stone_stairs 1  
fill ~44 ~1 ~1 ~44 ~2 ~1 cobblestone 0 
setblock ~44 ~1 ~49 double_plant 10  
fill ~45 ~1 ~2 ~46 ~1 ~2 stone 0  
fill ~45 ~1 ~3 ~55 ~1 ~3 stone 0  
fill ~45 ~1 ~48 ~45 ~6 ~48 cobblestone 0  
fill ~46 ~1 ~49 ~49 ~1 ~49 double_plant 10 
setblock ~47 ~1 ~0 double_plant 10 
setblock ~48 ~1 ~1 double_plant 10 
setblock ~48 ~1 ~8 stonebrick 0  
fill ~49 ~1 ~50 ~49 ~1 ~51 double_plant 10  
fill ~50 ~1 ~12 ~55 ~1 ~12 stone 0  
fill ~50 ~1 ~20 ~53 ~1 ~20 stone 0  
fill ~50 ~1 ~29 ~53 ~1 ~29 stone 0  
fill ~50 ~1 ~37 ~55 ~1 ~37 stone 0  
fill ~50 ~1 ~48 ~50 ~10 ~48 cobblestone 0  
fill ~50 ~1 ~49 ~50 ~2 ~49 mossy_cobblestone 0  
fill ~51 ~1 ~2 ~52 ~1 ~2 leaves 7 
setblock ~51 ~1 ~32 leaves 7 
setblock ~51 ~1 ~51 double_plant 10  
fill ~52 ~1 ~14 ~55 ~1 ~14 double_plant 10  
fill ~52 ~1 ~15 ~52 ~1 ~16 double_plant 10  
fill ~52 ~1 ~18 ~53 ~1 ~18 double_plant 10 
setblock ~52 ~1 ~33 double_plant 10  
fill ~52 ~1 ~35 ~54 ~1 ~35 double_plant 10  
fill ~52 ~1 ~49 ~54 ~1 ~49 double_plant 10 
setblock ~53 ~1 ~0 double_plant 10 
setblock ~53 ~1 ~1 leaves 15 
setblock ~53 ~1 ~16 double_plant 10 
setblock ~53 ~1 ~19 stone_stairs 0  
fill ~53 ~1 ~22 ~57 ~1 ~22 stone 0  
fill ~53 ~1 ~23 ~57 ~1 ~23 stone 0  
fill ~53 ~1 ~26 ~57 ~1 ~26 stone 0  
fill ~53 ~1 ~27 ~57 ~1 ~27 stone 0 
setblock ~54 ~1 ~1 leaves 7  
fill ~54 ~1 ~2 ~55 ~1 ~2 stone 0  
fill ~54 ~1 ~19 ~54 ~7 ~19 cobblestone 0 
setblock ~54 ~1 ~28 double_plant 10  
fill ~54 ~1 ~30 ~54 ~7 ~30 cobblestone 0  
fill ~54 ~1 ~33 ~55 ~1 ~33 double_plant 10  
fill ~54 ~1 ~38 ~54 ~2 ~38 stone 0  
fill ~54 ~1 ~39 ~54 ~1 ~47 stone 0 
setblock ~55 ~1 ~4 cobblestone 0  
fill ~55 ~1 ~8 ~56 ~1 ~8 double_plant 10  
fill ~55 ~1 ~11 ~55 ~8 ~11 stone 0  
fill ~55 ~1 ~19 ~55 ~1 ~21 double_plant 10  
fill ~55 ~1 ~29 ~55 ~1 ~31 double_plant 10  
fill ~55 ~1 ~39 ~55 ~1 ~41 stone_stairs 5 
setblock ~55 ~1 ~42 mossy_cobblestone 0  
fill ~55 ~1 ~43 ~55 ~1 ~45 stone_stairs 5  
fill ~55 ~1 ~46 ~55 ~27 ~46 stone 0  
fill ~55 ~1 ~48 ~55 ~2 ~48 mossy_cobblestone 0  
fill ~55 ~1 ~49 ~55 ~3 ~49 cobblestone 0  
fill ~56 ~1 ~1 ~56 ~6 ~1 cobblestone 0  
fill ~56 ~1 ~4 ~56 ~1 ~5 double_plant 10 
setblock ~56 ~1 ~10 double_plant 10 
setblock ~56 ~1 ~13 cobblestone 0 
setblock ~56 ~1 ~21 double_plant 10  
fill ~56 ~1 ~28 ~57 ~1 ~28 double_plant 10  
fill ~56 ~1 ~34 ~56 ~1 ~35 double_plant 10  
fill ~56 ~1 ~36 ~56 ~13 ~36 cobblestone 0 
setblock ~56 ~1 ~37 stone_stairs 3  
fill ~56 ~1 ~42 ~56 ~10 ~42 cobblestone_wall 0  
fill ~56 ~1 ~43 ~56 ~1 ~45 leaves 7 
setblock ~56 ~1 ~47 stone_stairs 2 
setblock ~56 ~1 ~48 cobblestone 0 
setblock ~57 ~1 ~3 double_plant 10 
setblock ~57 ~1 ~5 double_plant 10 
setblock ~57 ~1 ~11 double_plant 10  
fill ~57 ~1 ~24 ~57 ~0 ~24 stone 0  
fill ~57 ~1 ~25 ~57 ~0 ~25 stone 0 
setblock ~57 ~1 ~37 double_plant 10  
fill ~57 ~1 ~39 ~57 ~1 ~41 double_plant 10 
setblock ~57 ~1 ~45 leaves 7 
setblock ~58 ~1 ~20 double_plant 10  
fill ~58 ~1 ~22 ~59 ~1 ~22 stone_stairs 5 
setblock ~58 ~1 ~23 stone_brick_stairs 1  
fill ~58 ~1 ~24 ~58 ~1 ~25 spruce_stairs 1 
setblock ~58 ~1 ~26 stone_brick_stairs 1  
fill ~58 ~1 ~27 ~59 ~1 ~27 stone_stairs 5 
setblock ~58 ~1 ~38 double_plant 10 
setblock ~58 ~1 ~44 leaves 15  
fill ~58 ~1 ~47 ~58 ~1 ~49 double_plant 10 
setblock ~59 ~1 ~28 double_plant 10 
setblock ~59 ~1 ~41 double_plant 10 
setblock ~59 ~1 ~43 double_plant 10 
setblock ~59 ~1 ~46 double_plant 10  
fill ~59 ~1 ~48 ~59 ~1 ~49 double_plant 10 
setblock ~61 ~1 ~30 double_plant 10 
setblock ~3 ~2 ~12 cobblestone 0 
setblock ~3 ~2 ~13 stone_stairs 7 
setblock ~3 ~2 ~16 stone_stairs 4  
fill ~3 ~2 ~17 ~3 ~2 ~18 stone_slab 11 
setblock ~3 ~2 ~19 stone_stairs 4  
fill ~3 ~2 ~20 ~3 ~2 ~21 stone_slab 11 
setblock ~3 ~2 ~22 stone_stairs 4  
fill ~3 ~2 ~23 ~3 ~3 ~23 leaves 7  
fill ~3 ~2 ~24 ~3 ~2 ~23 leaves 7 
setblock ~3 ~2 ~25 stone_stairs 6  
fill ~3 ~2 ~26 ~4 ~2 ~26 cobblestone 0  
fill ~3 ~2 ~52 ~3 ~14 ~52 cobblestone_wall 0  
fill ~3 ~2 ~53 ~4 ~2 ~53 stone 0  
fill ~3 ~2 ~54 ~4 ~2 ~54 stone 0  
fill ~3 ~2 ~55 ~4 ~2 ~55 stone 0  
fill ~3 ~2 ~56 ~4 ~2 ~56 stone 0  
fill ~3 ~2 ~57 ~4 ~2 ~57 stone 0  
fill ~3 ~2 ~58 ~3 ~14 ~58 cobblestone_wall 0  
fill ~4 ~2 ~13 ~16 ~2 ~13 stone 0  
fill ~4 ~2 ~25 ~16 ~2 ~25 stone 0  
fill ~4 ~2 ~51 ~4 ~14 ~51 cobblestone_wall 0  
fill ~4 ~2 ~52 ~5 ~2 ~52 stone 0  
fill ~4 ~2 ~58 ~5 ~2 ~58 stone 0  
fill ~4 ~2 ~59 ~4 ~14 ~59 cobblestone_wall 0  
fill ~5 ~2 ~14 ~7 ~2 ~14 stonebrick 0  
fill ~5 ~2 ~15 ~5 ~3 ~15 stonebrick 0  
fill ~5 ~2 ~16 ~13 ~2 ~16 stonebrick 0  
fill ~5 ~2 ~17 ~5 ~2 ~23 stonebrick 0 
setblock ~5 ~2 ~24 stonebrick 2  
fill ~5 ~2 ~50 ~5 ~14 ~50 cobblestone_wall 0  
fill ~5 ~2 ~51 ~8 ~2 ~51 stone 0 
setblock ~5 ~2 ~53 stonebrick 2  
fill ~5 ~2 ~54 ~10 ~2 ~54 stonebrick 0  
fill ~5 ~2 ~55 ~8 ~2 ~55 stonebrick 0  
fill ~5 ~2 ~56 ~6 ~2 ~56 stonebrick 0 
setblock ~5 ~2 ~57 stonebrick 2  
fill ~5 ~2 ~59 ~11 ~2 ~59 stone 0  
fill ~5 ~2 ~60 ~5 ~14 ~60 cobblestone_wall 0 
setblock ~6 ~2 ~15 stonebrick 2 
setblock ~6 ~2 ~17 stonebrick 2  
fill ~6 ~2 ~18 ~8 ~2 ~18 stonebrick 0  
fill ~6 ~2 ~19 ~6 ~2 ~21 stonebrick 0 
setblock ~6 ~2 ~22 stonebrick 2  
fill ~6 ~2 ~23 ~7 ~2 ~23 stonebrick 0  
fill ~6 ~2 ~24 ~16 ~2 ~24 stonebrick 0 
setblock ~6 ~2 ~38 leaves 7  
fill ~6 ~2 ~50 ~8 ~2 ~50 stone 0  
fill ~6 ~2 ~52 ~9 ~2 ~52 stonebrick 0  
fill ~6 ~2 ~53 ~7 ~2 ~53 stonebrick 0  
fill ~6 ~2 ~57 ~6 ~2 ~58 stonebrick 0  
fill ~6 ~2 ~60 ~10 ~2 ~60 stone 0 
setblock ~7 ~2 ~12 stone_stairs 6  
fill ~7 ~2 ~15 ~13 ~2 ~15 stonebrick 0  
fill ~7 ~2 ~17 ~10 ~2 ~17 stonebrick 0 
setblock ~7 ~2 ~19 stonebrick 2  
fill ~7 ~2 ~20 ~8 ~2 ~20 stonebrick 0  
fill ~7 ~2 ~21 ~7 ~2 ~24 stonebrick 0 
setblock ~7 ~2 ~26 stone_stairs 7 
setblock ~7 ~2 ~36 leaves 7 
setblock ~7 ~2 ~38 stone_stairs 4  
fill ~7 ~2 ~39 ~7 ~2 ~40 stone_slab 11 
setblock ~7 ~2 ~41 stone_stairs 4 
setblock ~7 ~2 ~44 stone_stairs 4  
fill ~7 ~2 ~45 ~7 ~2 ~46 stone_slab 11 
setblock ~7 ~2 ~47 stone_stairs 4 
setblock ~7 ~2 ~56 stonebrick 2 
setblock ~7 ~2 ~57 stonebrick 1 
setblock ~7 ~2 ~58 stonebrick 0  
fill ~8 ~2 ~12 ~9 ~2 ~12 stone_slab 11  
fill ~8 ~2 ~14 ~9 ~2 ~14 stonebrick 2  
fill ~8 ~2 ~19 ~13 ~2 ~19 stonebrick 0 
setblock ~8 ~2 ~21 stonebrick 2  
fill ~8 ~2 ~22 ~16 ~2 ~22 stonebrick 0  
fill ~8 ~2 ~23 ~11 ~2 ~23 stonebrick 2  
fill ~8 ~2 ~26 ~9 ~2 ~26 stone_slab 11 
setblock ~8 ~2 ~35 stone_slab 11  
fill ~8 ~2 ~36 ~16 ~2 ~36 stone 0  
fill ~8 ~2 ~53 ~9 ~2 ~53 stonebrick 2  
fill ~8 ~2 ~56 ~8 ~2 ~57 stonebrick 0  
fill ~8 ~2 ~58 ~9 ~2 ~58 stonebrick 2 
setblock ~9 ~2 ~18 stonebrick 2 
setblock ~9 ~2 ~20 stonebrick 2  
fill ~9 ~2 ~21 ~11 ~2 ~21 stonebrick 0 
setblock ~9 ~2 ~35 stone_slab 3  
fill ~9 ~2 ~37 ~39 ~2 ~37 planks 5  
fill ~9 ~2 ~38 ~38 ~2 ~38 planks 5  
fill ~9 ~2 ~39 ~20 ~2 ~39 planks 5  
fill ~9 ~2 ~40 ~28 ~2 ~40 planks 5  
fill ~9 ~2 ~41 ~28 ~2 ~41 planks 5  
fill ~9 ~2 ~42 ~28 ~2 ~42 planks 5  
fill ~9 ~2 ~43 ~28 ~2 ~43 planks 5  
fill ~9 ~2 ~44 ~28 ~2 ~44 planks 5  
fill ~9 ~2 ~45 ~28 ~2 ~45 planks 5  
fill ~9 ~2 ~46 ~28 ~2 ~46 planks 5  
fill ~9 ~2 ~47 ~10 ~2 ~47 planks 1  
fill ~9 ~2 ~48 ~10 ~2 ~48 planks 1  
fill ~9 ~2 ~49 ~10 ~2 ~49 planks 1  
fill ~9 ~2 ~50 ~10 ~2 ~50 planks 1  
fill ~9 ~2 ~51 ~9 ~2 ~47 planks 1  
fill ~9 ~2 ~55 ~9 ~2 ~56 stonebrick 2  
fill ~9 ~2 ~57 ~10 ~2 ~57 stonebrick 0 
setblock ~10 ~2 ~12 stone_stairs 6  
fill ~10 ~2 ~14 ~16 ~2 ~14 stonebrick 0  
fill ~10 ~2 ~18 ~15 ~2 ~18 stonebrick 0 
setblock ~10 ~2 ~20 stonebrick 1 
setblock ~10 ~2 ~26 stone_stairs 7  
fill ~10 ~2 ~35 ~11 ~2 ~35 stone_stairs 6 
setblock ~10 ~2 ~51 stonebrick 0 
setblock ~10 ~2 ~52 stonebrick 2  
fill ~10 ~2 ~53 ~12 ~2 ~53 stonebrick 0  
fill ~10 ~2 ~55 ~11 ~2 ~55 stonebrick 0  
fill ~10 ~2 ~56 ~11 ~2 ~56 stonebrick 0 
setblock ~10 ~2 ~58 stonebrick 0  
fill ~11 ~2 ~12 ~12 ~2 ~12 stone_slab 11 
setblock ~11 ~2 ~17 stonebrick 1 
setblock ~11 ~2 ~20 stonebrick 0  
fill ~11 ~2 ~26 ~12 ~2 ~26 stone_slab 11  
fill ~11 ~2 ~47 ~32 ~2 ~47 planks 5  
fill ~11 ~2 ~48 ~32 ~2 ~48 planks 5  
fill ~11 ~2 ~49 ~32 ~2 ~49 planks 5  
fill ~11 ~2 ~50 ~32 ~2 ~50 planks 5  
fill ~11 ~2 ~51 ~32 ~2 ~51 planks 5 
setblock ~11 ~2 ~52 stonebrick 0 
setblock ~11 ~2 ~54 stonebrick 2 
setblock ~11 ~2 ~57 stonebrick 1  
fill ~11 ~2 ~58 ~12 ~2 ~58 stone 0  
fill ~11 ~2 ~60 ~11 ~14 ~60 cobblestone_wall 0 
setblock ~11 ~2 ~61 leaves 7 
setblock ~12 ~2 ~17 stonebrick 0  
fill ~12 ~2 ~20 ~12 ~2 ~21 stonebrick 2  
fill ~12 ~2 ~23 ~16 ~2 ~23 stonebrick 0  
fill ~12 ~2 ~28 ~13 ~2 ~28 stone_slab 0  
fill ~12 ~2 ~33 ~13 ~2 ~33 stone_slab 0 
setblock ~12 ~2 ~35 stone_slab 3  
fill ~12 ~2 ~52 ~32 ~2 ~52 planks 5  
fill ~12 ~2 ~54 ~13 ~2 ~54 planks 1  
fill ~12 ~2 ~55 ~33 ~2 ~55 stone 0  
fill ~12 ~2 ~56 ~33 ~2 ~56 stone 0  
fill ~12 ~2 ~57 ~13 ~2 ~57 stone 0  
fill ~12 ~2 ~59 ~12 ~14 ~59 cobblestone_wall 0 
setblock ~12 ~2 ~60 leaves 7 
setblock ~13 ~2 ~12 stone_stairs 6 
setblock ~13 ~2 ~17 stonebrick 2  
fill ~13 ~2 ~20 ~14 ~2 ~20 stonebrick 0  
fill ~13 ~2 ~21 ~16 ~2 ~21 stonebrick 0 
setblock ~13 ~2 ~26 stone_stairs 7 
setblock ~13 ~2 ~35 stone_slab 11 
setblock ~13 ~2 ~53 planks 1  
fill ~13 ~2 ~58 ~13 ~14 ~58 cobblestone_wall 0 
setblock ~14 ~2 ~10 leaves 7  
fill ~14 ~2 ~15 ~14 ~2 ~16 stonebrick 2  
fill ~14 ~2 ~17 ~16 ~2 ~17 stonebrick 0 
setblock ~14 ~2 ~19 stonebrick 2  
fill ~14 ~2 ~26 ~15 ~2 ~26 cobblestone 0 
setblock ~14 ~2 ~28 stone 4 
setblock ~14 ~2 ~29 stone_brick_stairs 0  
fill ~14 ~2 ~30 ~14 ~2 ~31 spruce_stairs 0 
setblock ~14 ~2 ~32 stone_brick_stairs 0 
setblock ~14 ~2 ~33 stone 4  
fill ~14 ~2 ~35 ~15 ~2 ~35 cobblestone 0  
fill ~14 ~2 ~53 ~32 ~2 ~53 planks 5  
fill ~14 ~2 ~54 ~32 ~2 ~54 planks 5 
setblock ~14 ~2 ~57 mossy_cobblestone 0 
setblock ~15 ~2 ~5 stone_stairs 2 
setblock ~15 ~2 ~8 stone_slab 11  
fill ~15 ~2 ~15 ~16 ~2 ~15 stonebrick 0  
fill ~15 ~2 ~16 ~16 ~2 ~16 stonebrick 0  
fill ~15 ~2 ~19 ~16 ~2 ~19 stonebrick 0 
setblock ~15 ~2 ~20 stonebrick 2 
setblock ~15 ~2 ~28 stone_stairs 4  
fill ~15 ~2 ~30 ~16 ~2 ~30 planks 1  
fill ~15 ~2 ~31 ~16 ~2 ~31 planks 1  
fill ~15 ~2 ~32 ~16 ~2 ~32 stonebrick 0 
setblock ~15 ~2 ~33 stone_stairs 4 
setblock ~16 ~2 ~6 stone_stairs 1  
fill ~16 ~2 ~7 ~45 ~2 ~7 stone 0 
setblock ~16 ~2 ~18 stonebrick 2 
setblock ~16 ~2 ~20 stonebrick 0 
setblock ~16 ~2 ~29 stonebrick 0  
fill ~17 ~2 ~6 ~19 ~2 ~6 cobblestone 0  
fill ~17 ~2 ~8 ~53 ~2 ~8 planks 5  
fill ~17 ~2 ~9 ~53 ~2 ~9 planks 5  
fill ~17 ~2 ~10 ~53 ~2 ~10 planks 5  
fill ~17 ~2 ~11 ~53 ~2 ~11 planks 5  
fill ~17 ~2 ~12 ~49 ~2 ~12 planks 5  
fill ~17 ~2 ~13 ~23 ~2 ~13 planks 5  
fill ~17 ~2 ~14 ~49 ~2 ~14 planks 5  
fill ~17 ~2 ~15 ~49 ~2 ~15 planks 5  
fill ~17 ~2 ~16 ~41 ~2 ~16 planks 5  
fill ~17 ~2 ~17 ~26 ~2 ~17 planks 5  
fill ~17 ~2 ~18 ~24 ~2 ~18 planks 5  
fill ~17 ~2 ~19 ~24 ~2 ~19 planks 5  
fill ~17 ~2 ~20 ~24 ~2 ~20 planks 5  
fill ~17 ~2 ~21 ~24 ~2 ~21 planks 5  
fill ~17 ~2 ~22 ~27 ~2 ~22 planks 5  
fill ~17 ~2 ~23 ~25 ~2 ~23 planks 5  
fill ~17 ~2 ~24 ~24 ~2 ~24 planks 5  
fill ~17 ~2 ~25 ~24 ~2 ~25 planks 5  
fill ~17 ~2 ~26 ~25 ~2 ~26 planks 5  
fill ~17 ~2 ~27 ~27 ~2 ~27 planks 5  
fill ~17 ~2 ~28 ~28 ~2 ~28 planks 5  
fill ~17 ~2 ~29 ~29 ~2 ~29 planks 5  
fill ~17 ~2 ~30 ~29 ~2 ~30 planks 5  
fill ~17 ~2 ~31 ~26 ~2 ~31 planks 5  
fill ~17 ~2 ~32 ~49 ~2 ~32 planks 5  
fill ~17 ~2 ~33 ~49 ~2 ~33 planks 5  
fill ~17 ~2 ~34 ~23 ~2 ~34 planks 5  
fill ~17 ~2 ~35 ~39 ~2 ~35 planks 5  
fill ~17 ~2 ~36 ~39 ~2 ~36 planks 5 
setblock ~17 ~2 ~57 stone_stairs 7 
setblock ~18 ~2 ~57 stone_slab 11 
setblock ~19 ~2 ~57 stone_stairs 7 
setblock ~20 ~2 ~6 stone_stairs 6 
setblock ~21 ~2 ~6 stone_slab 11 
setblock ~21 ~2 ~39 glowstone 0 
setblock ~22 ~2 ~6 stone_stairs 6  
fill ~22 ~2 ~39 ~26 ~2 ~39 planks 5 
setblock ~22 ~2 ~57 stone_stairs 7  
fill ~23 ~2 ~6 ~24 ~2 ~6 cobblestone 0 
setblock ~23 ~2 ~57 stone_slab 11  
fill ~24 ~2 ~3 ~24 ~6 ~3 cobblestone 0 
setblock ~24 ~2 ~5 mossy_cobblestone 0 
setblock ~24 ~2 ~13 glowstone 0 
setblock ~24 ~2 ~34 glowstone 0 
setblock ~24 ~2 ~57 stone_stairs 7 
setblock ~25 ~2 ~6 mossy_cobblestone 0  
fill ~25 ~2 ~13 ~49 ~2 ~13 planks 5  
fill ~25 ~2 ~18 ~25 ~2 ~20 stone_slab 8 
setblock ~25 ~2 ~21 double_stone_slab 0  
fill ~25 ~2 ~24 ~27 ~2 ~24 planks 1  
fill ~25 ~2 ~25 ~27 ~2 ~25 planks 1  
fill ~25 ~2 ~34 ~39 ~2 ~34 planks 5 
setblock ~25 ~2 ~57 stone_slab 11 
setblock ~26 ~2 ~6 stone_stairs 6  
fill ~26 ~2 ~18 ~29 ~2 ~18 stone 6  
fill ~26 ~2 ~19 ~29 ~2 ~19 cobblestone 0  
fill ~26 ~2 ~20 ~26 ~2 ~21 cobblestone 0  
fill ~26 ~2 ~23 ~27 ~2 ~23 cobblestone 0  
fill ~26 ~2 ~26 ~27 ~2 ~26 cobblestone 0 
setblock ~26 ~2 ~57 stone_stairs 7 
setblock ~27 ~2 ~6 stone_slab 11 
setblock ~27 ~2 ~17 glowstone 0  
fill ~27 ~2 ~20 ~29 ~2 ~20 netherrack 0  
fill ~27 ~2 ~21 ~29 ~2 ~21 brick_block 0 
setblock ~27 ~2 ~31 glowstone 0 
setblock ~27 ~2 ~39 glowstone 0 
setblock ~28 ~2 ~6 stone_stairs 6  
fill ~28 ~2 ~17 ~49 ~2 ~17 planks 5  
fill ~28 ~2 ~22 ~28 ~4 ~22 planks 1 
setblock ~28 ~2 ~23 stone_stairs 1  
fill ~28 ~2 ~24 ~28 ~2 ~25 spruce_stairs 1 
setblock ~28 ~2 ~26 stone_stairs 1  
fill ~28 ~2 ~27 ~28 ~4 ~27 planks 1  
fill ~28 ~2 ~31 ~49 ~2 ~31 planks 5  
fill ~28 ~2 ~39 ~33 ~2 ~39 planks 5  
fill ~29 ~2 ~6 ~29 ~10 ~6 cobblestone 0  
fill ~29 ~2 ~40 ~31 ~2 ~40 stone_slab 8  
fill ~29 ~2 ~41 ~29 ~2 ~40 stone_slab 8  
fill ~29 ~2 ~42 ~29 ~2 ~44 stone 6  
fill ~29 ~2 ~45 ~29 ~2 ~46 stone_slab 8 
setblock ~29 ~2 ~57 stone_stairs 7 
setblock ~29 ~2 ~58 leaves 7  
fill ~30 ~2 ~18 ~30 ~2 ~20 stone_slab 8 
setblock ~30 ~2 ~21 double_stone_slab 0  
fill ~30 ~2 ~22 ~31 ~2 ~22 planks 1  
fill ~30 ~2 ~27 ~31 ~2 ~27 planks 1  
fill ~30 ~2 ~41 ~32 ~2 ~41 cobblestone 0  
fill ~30 ~2 ~42 ~30 ~2 ~45 cobblestone 0  
fill ~30 ~2 ~46 ~32 ~2 ~46 stone_slab 8 
setblock ~30 ~2 ~57 stone_slab 11  
fill ~31 ~2 ~6 ~31 ~11 ~6 cobblestone 0  
fill ~31 ~2 ~18 ~49 ~2 ~18 planks 5  
fill ~31 ~2 ~19 ~49 ~2 ~19 planks 5  
fill ~31 ~2 ~20 ~49 ~2 ~20 planks 5  
fill ~31 ~2 ~21 ~49 ~2 ~21 planks 5  
fill ~31 ~2 ~28 ~49 ~2 ~28 planks 5  
fill ~31 ~2 ~29 ~49 ~2 ~29 planks 5  
fill ~31 ~2 ~30 ~49 ~2 ~30 planks 5  
fill ~31 ~2 ~42 ~31 ~2 ~44 netherrack 0  
fill ~31 ~2 ~45 ~32 ~2 ~45 cobblestone 0 
setblock ~31 ~2 ~57 stone_stairs 7 
setblock ~32 ~2 ~6 stone_stairs 6 
setblock ~32 ~2 ~23 redstone_torch 5 
setblock ~32 ~2 ~26 redstone_torch 5 
setblock ~32 ~2 ~40 double_stone_slab 0  
fill ~32 ~2 ~42 ~32 ~2 ~44 brick_block 0 
setblock ~33 ~2 ~6 stone_slab 11  
fill ~33 ~2 ~22 ~34 ~2 ~22 planks 1 
setblock ~33 ~2 ~23 stone_brick_stairs 7  
fill ~33 ~2 ~24 ~33 ~2 ~25 stone_slab 13 
setblock ~33 ~2 ~26 stone_brick_stairs 6  
fill ~33 ~2 ~27 ~34 ~2 ~27 planks 1  
fill ~33 ~2 ~40 ~33 ~2 ~46 planks 5  
fill ~33 ~2 ~47 ~55 ~2 ~47 stone 0 
setblock ~34 ~2 ~6 stone_stairs 6  
fill ~34 ~2 ~23 ~34 ~2 ~26 stone_brick_stairs 4 
setblock ~34 ~2 ~39 double_stone_slab 0  
fill ~34 ~2 ~40 ~36 ~2 ~40 cobblestone 0  
fill ~34 ~2 ~41 ~34 ~2 ~43 brick_block 0 
setblock ~34 ~2 ~44 double_stone_slab 0 
setblock ~34 ~2 ~45 stone_slab 8  
fill ~34 ~2 ~46 ~53 ~2 ~46 planks 5  
fill ~34 ~2 ~48 ~34 ~13 ~48 cobblestone 0 
setblock ~34 ~2 ~49 stone_stairs 5 
setblock ~34 ~2 ~50 stone_slab 11 
setblock ~34 ~2 ~51 stone_stairs 5  
fill ~34 ~2 ~52 ~37 ~2 ~52 cobblestone 0 
setblock ~34 ~2 ~53 stone_stairs 5 
setblock ~34 ~2 ~54 stone_slab 11 
setblock ~34 ~2 ~55 stone_stairs 5  
fill ~35 ~2 ~6 ~35 ~9 ~6 cobblestone 0  
fill ~35 ~2 ~22 ~49 ~2 ~22 planks 5  
fill ~35 ~2 ~23 ~49 ~2 ~23 planks 5  
fill ~35 ~2 ~24 ~38 ~2 ~24 planks 5  
fill ~35 ~2 ~25 ~38 ~2 ~25 planks 5  
fill ~35 ~2 ~26 ~49 ~2 ~26 planks 5  
fill ~35 ~2 ~27 ~49 ~2 ~27 planks 5  
fill ~35 ~2 ~39 ~37 ~2 ~39 stone_slab 8  
fill ~35 ~2 ~41 ~35 ~2 ~43 netherrack 0  
fill ~35 ~2 ~44 ~37 ~2 ~44 stone_slab 8  
fill ~35 ~2 ~45 ~53 ~2 ~45 planks 5  
fill ~35 ~2 ~48 ~35 ~3 ~48 mossy_cobblestone 0  
fill ~35 ~2 ~49 ~35 ~2 ~48 mossy_cobblestone 0  
fill ~35 ~2 ~57 ~37 ~2 ~57 cobblestone 0  
fill ~36 ~2 ~41 ~36 ~2 ~43 cobblestone 0  
fill ~37 ~2 ~6 ~37 ~11 ~6 cobblestone 0  
fill ~37 ~2 ~40 ~37 ~2 ~43 stone 6  
fill ~37 ~2 ~48 ~38 ~2 ~48 stone_stairs 7 
setblock ~38 ~2 ~6 stone_stairs 6  
fill ~38 ~2 ~39 ~53 ~2 ~39 planks 5  
fill ~38 ~2 ~40 ~53 ~2 ~40 planks 5  
fill ~38 ~2 ~41 ~53 ~2 ~41 planks 5  
fill ~38 ~2 ~42 ~53 ~2 ~42 planks 5  
fill ~38 ~2 ~43 ~53 ~2 ~43 planks 5  
fill ~38 ~2 ~44 ~53 ~2 ~44 planks 5 
setblock ~39 ~2 ~6 stone_slab 11  
fill ~39 ~2 ~24 ~39 ~2 ~25 glowstone 0 
setblock ~39 ~2 ~38 glowstone 0 
setblock ~40 ~2 ~6 stone_stairs 6  
fill ~40 ~2 ~24 ~48 ~2 ~24 planks 5  
fill ~40 ~2 ~25 ~48 ~2 ~25 planks 5  
fill ~40 ~2 ~34 ~43 ~2 ~34 wool 14  
fill ~40 ~2 ~35 ~43 ~2 ~35 wool 14  
fill ~40 ~2 ~36 ~43 ~2 ~36 wool 14  
fill ~40 ~2 ~37 ~43 ~2 ~37 wool 14  
fill ~40 ~2 ~38 ~53 ~2 ~38 planks 5 
setblock ~40 ~2 ~49 mossy_cobblestone 0  
fill ~41 ~2 ~3 ~41 ~3 ~3 leaves 7  
fill ~41 ~2 ~4 ~41 ~2 ~3 leaves 7  
fill ~41 ~2 ~6 ~41 ~6 ~6 cobblestone 0 
setblock ~42 ~2 ~16 bedrock 0  
fill ~42 ~2 ~48 ~43 ~2 ~48 stone_stairs 7  
fill ~43 ~2 ~6 ~43 ~7 ~6 cobblestone 0  
fill ~43 ~2 ~16 ~49 ~2 ~16 planks 5 
setblock ~44 ~2 ~2 stone_stairs 3  
fill ~44 ~2 ~34 ~49 ~2 ~34 planks 5  
fill ~44 ~2 ~35 ~49 ~2 ~35 planks 5  
fill ~44 ~2 ~36 ~49 ~2 ~36 planks 5  
fill ~44 ~2 ~37 ~49 ~2 ~37 planks 5 
setblock ~45 ~2 ~1 stone_stairs 1  
fill ~45 ~2 ~2 ~46 ~2 ~2 stone 0  
fill ~45 ~2 ~3 ~55 ~2 ~3 stone 0  
fill ~46 ~2 ~4 ~47 ~2 ~4 planks 1  
fill ~46 ~2 ~5 ~53 ~2 ~5 planks 5  
fill ~46 ~2 ~6 ~53 ~2 ~6 planks 5  
fill ~46 ~2 ~7 ~53 ~2 ~7 planks 5  
fill ~47 ~2 ~2 ~47 ~7 ~2 cobblestone_wall 0  
fill ~47 ~2 ~48 ~48 ~2 ~48 stone_stairs 7 
setblock ~48 ~2 ~2 stone_stairs 6  
fill ~48 ~2 ~4 ~52 ~2 ~4 planks 5 
setblock ~49 ~2 ~2 stone_slab 11  
fill ~49 ~2 ~24 ~56 ~2 ~24 planks 1  
fill ~49 ~2 ~25 ~56 ~2 ~25 planks 1 
setblock ~50 ~2 ~2 stone_stairs 6  
fill ~50 ~2 ~12 ~55 ~2 ~12 stone 0  
fill ~50 ~2 ~20 ~53 ~2 ~20 stone 0  
fill ~50 ~2 ~21 ~53 ~2 ~21 stone 0  
fill ~50 ~2 ~22 ~56 ~2 ~22 stone 0  
fill ~50 ~2 ~23 ~56 ~2 ~23 stone 0  
fill ~50 ~2 ~26 ~56 ~2 ~26 stone 0  
fill ~50 ~2 ~27 ~56 ~2 ~27 stone 0  
fill ~50 ~2 ~28 ~53 ~2 ~28 stone 0  
fill ~50 ~2 ~29 ~53 ~2 ~29 stone 0  
fill ~50 ~2 ~37 ~55 ~2 ~37 stone 0 
setblock ~51 ~2 ~2 stone_slab 11  
fill ~51 ~2 ~33 ~51 ~2 ~34 leaves 7 
setblock ~52 ~2 ~2 stone_stairs 6  
fill ~52 ~2 ~34 ~52 ~3 ~34 leaves 7  
fill ~52 ~2 ~48 ~53 ~2 ~48 stone_stairs 7  
fill ~53 ~2 ~2 ~53 ~7 ~2 cobblestone_wall 0 
setblock ~53 ~2 ~4 planks 1 
setblock ~53 ~2 ~30 stone_stairs 0 
setblock ~54 ~2 ~1 leaves 15  
fill ~54 ~2 ~2 ~55 ~2 ~2 stone 0 
setblock ~54 ~2 ~20 stone_stairs 3 
setblock ~54 ~2 ~29 stone_stairs 2  
fill ~54 ~2 ~39 ~54 ~3 ~39 stonebrick 0  
fill ~54 ~2 ~40 ~54 ~2 ~41 stonebrick 0 
setblock ~54 ~2 ~42 stone 0 
setblock ~54 ~2 ~43 stonebrick 2  
fill ~54 ~2 ~44 ~54 ~2 ~45 stonebrick 0 
setblock ~54 ~2 ~46 stone 0 
setblock ~55 ~2 ~1 stone_stairs 0  
fill ~55 ~2 ~4 ~55 ~7 ~4 cobblestone_wall 0 
setblock ~55 ~2 ~5 stone_stairs 5 
setblock ~55 ~2 ~6 stone_slab 11 
setblock ~55 ~2 ~7 stone_stairs 5 
setblock ~55 ~2 ~8 stone_slab 11 
setblock ~55 ~2 ~9 stone_stairs 5  
fill ~55 ~2 ~10 ~55 ~7 ~10 cobblestone_wall 0 
setblock ~55 ~2 ~13 stone_stairs 0 
setblock ~55 ~2 ~36 stone_stairs 0  
fill ~55 ~2 ~42 ~55 ~3 ~42 cobblestone 0 
setblock ~56 ~2 ~2 stone_stairs 3 
setblock ~56 ~2 ~12 stone_stairs 2 
setblock ~56 ~2 ~13 mossy_cobblestone 0 
setblock ~56 ~2 ~37 cobblestone 0 
setblock ~56 ~2 ~45 leaves 7 
setblock ~56 ~2 ~47 cobblestone 0 
setblock ~56 ~2 ~48 mossy_cobblestone 0  
fill ~57 ~2 ~22 ~58 ~2 ~22 stone_stairs 5 
setblock ~57 ~2 ~23 stone_brick_stairs 1  
fill ~57 ~2 ~24 ~57 ~2 ~25 spruce_stairs 1 
setblock ~57 ~2 ~26 stone_brick_stairs 1  
fill ~57 ~2 ~27 ~58 ~2 ~27 stone_stairs 5 
setblock ~57 ~2 ~36 stone_stairs 1 
setblock ~57 ~2 ~48 stone_stairs 1 
setblock ~60 ~2 ~21 cobblestone_wall 0 
setblock ~60 ~2 ~28 cobblestone_wall 0 
setblock ~3 ~3 ~12 mossy_cobblestone 0  
fill ~3 ~3 ~26 ~4 ~3 ~26 cobblestone 0  
fill ~3 ~3 ~53 ~4 ~3 ~53 stone 0  
fill ~3 ~3 ~54 ~4 ~3 ~54 stone 0  
fill ~3 ~3 ~55 ~4 ~3 ~55 stone 0  
fill ~3 ~3 ~56 ~4 ~3 ~56 stone 0  
fill ~3 ~3 ~57 ~4 ~3 ~57 stone 0  
fill ~4 ~3 ~13 ~6 ~3 ~13 stone 0  
fill ~4 ~3 ~16 ~4 ~5 ~16 cobblestone_wall 0 
setblock ~4 ~3 ~19 mossy_cobblestone 0  
fill ~4 ~3 ~22 ~4 ~5 ~22 cobblestone_wall 0  
fill ~4 ~3 ~25 ~6 ~3 ~25 stone 0  
fill ~4 ~3 ~52 ~5 ~3 ~52 stone 0  
fill ~4 ~3 ~58 ~5 ~3 ~58 stone 0  
fill ~5 ~3 ~16 ~5 ~6 ~16 stained_glass_pane 15  
fill ~5 ~3 ~17 ~5 ~8 ~17 stained_glass_pane 15  
fill ~5 ~3 ~18 ~5 ~9 ~18 stained_glass_pane 15  
fill ~5 ~3 ~19 ~5 ~10 ~19 stained_glass_pane 15  
fill ~5 ~3 ~20 ~5 ~9 ~20 stained_glass_pane 15  
fill ~5 ~3 ~21 ~5 ~8 ~21 stained_glass_pane 15  
fill ~5 ~3 ~22 ~5 ~6 ~22 stained_glass_pane 15  
fill ~5 ~3 ~23 ~5 ~5 ~23 stonebrick 0  
fill ~5 ~3 ~51 ~8 ~3 ~51 stone 0  
fill ~5 ~3 ~53 ~7 ~3 ~53 planks 1  
fill ~5 ~3 ~54 ~7 ~3 ~54 planks 1  
fill ~5 ~3 ~55 ~7 ~3 ~55 planks 1  
fill ~5 ~3 ~56 ~6 ~3 ~56 planks 1  
fill ~5 ~3 ~57 ~6 ~3 ~57 planks 1  
fill ~5 ~3 ~59 ~11 ~3 ~59 stone 0  
fill ~6 ~3 ~14 ~6 ~6 ~14 stonebrick 0  
fill ~6 ~3 ~15 ~6 ~6 ~15 log 1  
fill ~6 ~3 ~19 ~6 ~8 ~19 log 1  
fill ~6 ~3 ~23 ~6 ~9 ~23 log 1 
setblock ~6 ~3 ~24 stonebrick 2  
fill ~6 ~3 ~50 ~8 ~3 ~50 stone 0  
fill ~6 ~3 ~52 ~7 ~3 ~52 planks 1  
fill ~6 ~3 ~58 ~6 ~6 ~58 planks 1  
fill ~6 ~3 ~60 ~10 ~3 ~60 stone 0  
fill ~7 ~3 ~13 ~7 ~5 ~13 cobblestone_wall 0  
fill ~7 ~3 ~14 ~13 ~3 ~14 stained_glass_pane 15  
fill ~7 ~3 ~24 ~13 ~3 ~24 stained_glass_pane 15  
fill ~7 ~3 ~25 ~7 ~5 ~25 cobblestone_wall 0 
setblock ~7 ~3 ~36 stone_stairs 3  
fill ~7 ~3 ~37 ~7 ~4 ~37 leaves 7 
setblock ~7 ~3 ~49 stone_stairs 2 
setblock ~8 ~3 ~35 stone_stairs 1  
fill ~8 ~3 ~36 ~8 ~26 ~36 stone 0  
fill ~8 ~3 ~52 ~8 ~3 ~54 spruce_stairs 1  
fill ~8 ~3 ~55 ~8 ~13 ~55 cobblestone 0  
fill ~9 ~3 ~37 ~9 ~19 ~37 stonebrick 0  
fill ~9 ~3 ~38 ~9 ~3 ~37 stonebrick 0  
fill ~9 ~3 ~39 ~9 ~10 ~39 stained_glass_pane 15  
fill ~9 ~3 ~40 ~9 ~10 ~40 stained_glass_pane 15  
fill ~9 ~3 ~41 ~9 ~5 ~41 stonebrick 0  
fill ~9 ~3 ~42 ~9 ~8 ~42 planks 1  
fill ~9 ~3 ~43 ~9 ~3 ~42 planks 1  
fill ~9 ~3 ~44 ~9 ~4 ~44 stonebrick 0  
fill ~9 ~3 ~45 ~9 ~10 ~45 stained_glass_pane 15  
fill ~9 ~3 ~46 ~9 ~10 ~46 stained_glass_pane 15  
fill ~9 ~3 ~47 ~9 ~6 ~47 stonebrick 0  
fill ~9 ~3 ~48 ~9 ~12 ~48 planks 5  
fill ~9 ~3 ~49 ~9 ~3 ~48 planks 5  
fill ~9 ~3 ~50 ~9 ~8 ~50 stonebrick 0 
setblock ~9 ~3 ~51 cobblestone 0 
setblock ~10 ~3 ~13 cobblestone 0 
setblock ~10 ~3 ~16 bedrock 0  
fill ~10 ~3 ~19 ~10 ~40 ~19 log 1 
setblock ~10 ~3 ~25 mossy_cobblestone 0  
fill ~10 ~3 ~37 ~11 ~3 ~37 stained_glass_pane 15 
setblock ~10 ~3 ~41 stone_brick_stairs 2  
fill ~10 ~3 ~42 ~10 ~3 ~43 stone_brick_stairs 1 
setblock ~10 ~3 ~44 stone_brick_stairs 3 
setblock ~10 ~3 ~47 stone_brick_stairs 2  
fill ~10 ~3 ~48 ~10 ~3 ~49 stone_brick_stairs 1 
setblock ~10 ~3 ~50 stone_brick_stairs 3 
setblock ~11 ~3 ~15 bedrock 0 
setblock ~11 ~3 ~18 bedrock 0  
fill ~11 ~3 ~19 ~13 ~3 ~19 cobblestone 0  
fill ~11 ~3 ~58 ~12 ~3 ~58 stone 0 
setblock ~12 ~3 ~15 redstone_wire 0  
fill ~12 ~3 ~16 ~12 ~3 ~17 bedrock 0  
fill ~12 ~3 ~36 ~16 ~3 ~36 stone 0  
fill ~12 ~3 ~37 ~12 ~4 ~37 stonebrick 0 
setblock ~12 ~3 ~38 stone_brick_stairs 0 
setblock ~12 ~3 ~54 cobblestone 0  
fill ~12 ~3 ~55 ~12 ~26 ~55 stone 0  
fill ~12 ~3 ~56 ~16 ~3 ~56 stone 0  
fill ~12 ~3 ~57 ~13 ~3 ~57 stone 0 
setblock ~12 ~3 ~60 leaves 15  
fill ~13 ~3 ~13 ~13 ~5 ~13 cobblestone_wall 0  
fill ~13 ~3 ~15 ~14 ~3 ~15 stone 4  
fill ~13 ~3 ~16 ~13 ~3 ~18 planks 1  
fill ~13 ~3 ~25 ~13 ~5 ~25 cobblestone_wall 0  
fill ~13 ~3 ~28 ~14 ~3 ~28 stone_slab 0  
fill ~13 ~3 ~33 ~14 ~3 ~33 stone_slab 0 
setblock ~13 ~3 ~35 stone_stairs 0  
fill ~13 ~3 ~37 ~17 ~3 ~37 planks 1 
setblock ~13 ~3 ~38 stone_brick_stairs 3 
setblock ~13 ~3 ~53 stone_brick_stairs 0  
fill ~13 ~3 ~54 ~13 ~7 ~54 stonebrick 0  
fill ~13 ~3 ~55 ~13 ~7 ~55 stonebrick 0 
setblock ~13 ~3 ~59 leaves 15  
fill ~14 ~3 ~13 ~16 ~3 ~13 stone 0  
fill ~14 ~3 ~14 ~14 ~12 ~14 stonebrick 0  
fill ~14 ~3 ~16 ~14 ~3 ~18 spruce_stairs 1 
setblock ~14 ~3 ~19 stone 4  
fill ~14 ~3 ~23 ~14 ~10 ~23 log 1  
fill ~14 ~3 ~24 ~14 ~5 ~24 stonebrick 0  
fill ~14 ~3 ~25 ~16 ~3 ~25 stone 0  
fill ~14 ~3 ~26 ~14 ~8 ~26 cobblestone 0  
fill ~14 ~3 ~35 ~15 ~3 ~35 cobblestone 0  
fill ~14 ~3 ~38 ~15 ~3 ~38 wooden_slab 8  
fill ~14 ~3 ~39 ~15 ~3 ~39 oak_stairs 7  
fill ~14 ~3 ~46 ~14 ~4 ~46 trapdoor 6  
fill ~14 ~3 ~53 ~16 ~3 ~53 stone_brick_stairs 2  
fill ~14 ~3 ~54 ~16 ~3 ~54 planks 1  
fill ~14 ~3 ~57 ~14 ~14 ~57 cobblestone 0  
fill ~15 ~3 ~11 ~15 ~3 ~12 leaves 7  
fill ~15 ~3 ~14 ~16 ~3 ~14 cobblestone 0  
fill ~15 ~3 ~15 ~16 ~3 ~15 cobblestone 0  
fill ~15 ~3 ~16 ~16 ~3 ~16 cobblestone_wall 0 
setblock ~15 ~3 ~19 cobblestone_wall 0  
fill ~15 ~3 ~22 ~16 ~3 ~22 cobblestone_wall 0  
fill ~15 ~3 ~23 ~16 ~3 ~23 cobblestone 0  
fill ~15 ~3 ~24 ~16 ~3 ~24 cobblestone 0  
fill ~15 ~3 ~26 ~15 ~4 ~26 stone 0 
setblock ~15 ~3 ~27 stone_stairs 3 
setblock ~15 ~3 ~28 stone 4 
setblock ~15 ~3 ~33 stone 4 
setblock ~15 ~3 ~34 stone_stairs 2 
setblock ~15 ~3 ~45 trapdoor 4 
setblock ~15 ~3 ~46 spruce_stairs 1 
setblock ~15 ~3 ~47 trapdoor 5 
setblock ~15 ~3 ~57 stone_stairs 1  
fill ~16 ~3 ~7 ~20 ~3 ~7 stone 0 
setblock ~16 ~3 ~29 cobblestone 0 
setblock ~16 ~3 ~32 cobblestone 0  
fill ~16 ~3 ~38 ~17 ~3 ~38 stone_brick_stairs 3 
setblock ~16 ~3 ~43 trapdoor 6 
setblock ~16 ~3 ~44 spruce_stairs 6  
fill ~16 ~3 ~45 ~24 ~3 ~45 wooden_slab 9  
fill ~16 ~3 ~46 ~24 ~3 ~46 wooden_slab 9  
fill ~16 ~3 ~47 ~24 ~3 ~47 wooden_slab 9 
setblock ~16 ~3 ~48 spruce_stairs 7 
setblock ~16 ~3 ~49 trapdoor 6  
fill ~17 ~3 ~6 ~19 ~3 ~6 cobblestone 0  
fill ~17 ~3 ~8 ~19 ~3 ~8 planks 1  
fill ~17 ~3 ~9 ~17 ~12 ~9 planks 1  
fill ~17 ~3 ~10 ~17 ~12 ~10 planks 1  
fill ~17 ~3 ~11 ~17 ~12 ~11 planks 1  
fill ~17 ~3 ~12 ~17 ~12 ~12 planks 1  
fill ~17 ~3 ~13 ~18 ~3 ~13 planks 1  
fill ~17 ~3 ~14 ~17 ~12 ~14 planks 1  
fill ~17 ~3 ~15 ~17 ~12 ~15 planks 1  
fill ~17 ~3 ~16 ~18 ~3 ~16 stone_brick_stairs 3 
setblock ~17 ~3 ~22 stone_brick_stairs 2  
fill ~17 ~3 ~23 ~17 ~12 ~23 planks 1  
fill ~17 ~3 ~24 ~17 ~12 ~24 planks 1  
fill ~17 ~3 ~25 ~17 ~6 ~25 planks 1  
fill ~17 ~3 ~26 ~17 ~3 ~27 planks 1  
fill ~17 ~3 ~28 ~17 ~8 ~28 stonebrick 0  
fill ~17 ~3 ~29 ~17 ~10 ~29 stonebrick 0  
fill ~17 ~3 ~30 ~17 ~3 ~31 birch_door 4  
fill ~17 ~3 ~32 ~17 ~9 ~32 stonebrick 0 
setblock ~17 ~3 ~33 stonebrick 2  
fill ~17 ~3 ~34 ~17 ~8 ~34 planks 1  
fill ~17 ~3 ~35 ~17 ~8 ~35 planks 1  
fill ~17 ~3 ~36 ~17 ~8 ~36 planks 1 
setblock ~17 ~3 ~42 trapdoor 4 
setblock ~17 ~3 ~43 spruce_stairs 3  
fill ~17 ~3 ~44 ~23 ~3 ~44 wooden_slab 9  
fill ~17 ~3 ~48 ~23 ~3 ~48 wooden_slab 9 
setblock ~17 ~3 ~49 spruce_stairs 2  
fill ~17 ~3 ~50 ~17 ~4 ~50 trapdoor 13 
setblock ~17 ~3 ~53 stone_brick_stairs 1 
setblock ~17 ~3 ~54 stonebrick 2  
fill ~17 ~3 ~55 ~17 ~6 ~55 stone 0 
setblock ~18 ~3 ~4 mossy_cobblestone 0 
setblock ~18 ~3 ~9 planks 0  
fill ~18 ~3 ~10 ~18 ~3 ~12 wooden_slab 8  
fill ~18 ~3 ~14 ~18 ~10 ~14 log 1 
setblock ~18 ~3 ~15 stone_brick_stairs 1  
fill ~18 ~3 ~22 ~18 ~3 ~23 stone_brick_stairs 1  
fill ~18 ~3 ~24 ~18 ~10 ~24 log 1  
fill ~18 ~3 ~25 ~18 ~3 ~27 stone_brick_stairs 1  
fill ~18 ~3 ~28 ~18 ~10 ~28 log 1 
setblock ~18 ~3 ~29 cobblestone 0 
setblock ~18 ~3 ~32 cobblestone 0  
fill ~18 ~3 ~33 ~18 ~10 ~33 log 1 
setblock ~18 ~3 ~34 stone_brick_stairs 1  
fill ~18 ~3 ~35 ~18 ~3 ~36 planks 0  
fill ~18 ~3 ~37 ~18 ~6 ~37 cobblestone 0 
setblock ~18 ~3 ~38 stone_brick_stairs 1 
setblock ~18 ~3 ~43 trapdoor 7 
setblock ~18 ~3 ~49 trapdoor 7  
fill ~18 ~3 ~55 ~18 ~5 ~55 stained_glass_pane 15 
setblock ~19 ~3 ~4 leaves 7 
setblock ~19 ~3 ~9 planks 1 
setblock ~19 ~3 ~10 planks 0  
fill ~19 ~3 ~11 ~19 ~3 ~13 oak_stairs 1 
setblock ~19 ~3 ~14 stone_brick_stairs 1 
setblock ~19 ~3 ~15 stone_brick_stairs 3 
setblock ~19 ~3 ~27 stone_brick_stairs 2 
setblock ~19 ~3 ~28 stone_brick_stairs 1 
setblock ~19 ~3 ~29 stone_brick_stairs 3 
setblock ~19 ~3 ~32 stone_brick_stairs 2 
setblock ~19 ~3 ~33 stone_brick_stairs 1 
setblock ~19 ~3 ~34 stone_brick_stairs 3  
fill ~19 ~3 ~35 ~19 ~3 ~36 oak_stairs 5 
setblock ~19 ~3 ~43 trapdoor 6 
setblock ~19 ~3 ~49 trapdoor 6 
setblock ~19 ~3 ~53 stone_brick_stairs 0  
fill ~19 ~3 ~54 ~19 ~6 ~54 stonebrick 0  
fill ~19 ~3 ~55 ~19 ~6 ~55 stone 0  
fill ~20 ~3 ~8 ~20 ~9 ~8 stonebrick 0 
setblock ~20 ~3 ~9 planks 0 
setblock ~20 ~3 ~10 oak_stairs 3  
fill ~20 ~3 ~42 ~20 ~4 ~42 trapdoor 12 
setblock ~20 ~3 ~43 spruce_stairs 3 
setblock ~20 ~3 ~49 spruce_stairs 2 
setblock ~20 ~3 ~50 trapdoor 13  
fill ~20 ~3 ~53 ~21 ~3 ~53 stone_brick_stairs 2  
fill ~20 ~3 ~54 ~21 ~3 ~54 planks 1  
fill ~20 ~3 ~56 ~21 ~3 ~56 stone 0  
fill ~21 ~3 ~8 ~21 ~9 ~8 stained_glass_pane 15 
setblock ~21 ~3 ~9 bedrock 0  
fill ~21 ~3 ~14 ~21 ~3 ~16 wool 15  
fill ~21 ~3 ~31 ~27 ~3 ~31 carpet 15  
fill ~21 ~3 ~32 ~21 ~3 ~39 carpet 15 
setblock ~21 ~3 ~43 trapdoor 7 
setblock ~21 ~3 ~49 trapdoor 7  
fill ~22 ~3 ~7 ~26 ~3 ~7 stone 0 
setblock ~22 ~3 ~8 stonebrick 2  
fill ~22 ~3 ~9 ~26 ~3 ~9 oak_stairs 3  
fill ~22 ~3 ~12 ~22 ~3 ~13 carpet 15 
setblock ~22 ~3 ~14 spruce_stairs 3 
setblock ~22 ~3 ~15 wooden_slab 1  
setblock ~22 ~3 ~16 spruce_stairs 2  
fill ~22 ~3 ~17 ~29 ~3 ~17 carpet 15  
fill ~22 ~3 ~32 ~26 ~3 ~32 carpet 14  
fill ~22 ~3 ~33 ~26 ~3 ~33 carpet 14  
fill ~22 ~3 ~34 ~26 ~3 ~34 carpet 14  
fill ~22 ~3 ~35 ~26 ~3 ~35 carpet 14  
fill ~22 ~3 ~36 ~26 ~3 ~36 carpet 14  
fill ~22 ~3 ~37 ~26 ~3 ~37 carpet 14  
fill ~22 ~3 ~38 ~26 ~3 ~38 carpet 14  
fill ~22 ~3 ~39 ~27 ~3 ~39 carpet 15 
setblock ~22 ~3 ~43 trapdoor 6 
setblock ~22 ~3 ~49 trapdoor 6 
setblock ~22 ~3 ~53 stone_brick_stairs 1  
fill ~22 ~3 ~54 ~22 ~6 ~54 stonebrick 0  
fill ~22 ~3 ~55 ~22 ~8 ~55 stone 0  
fill ~23 ~3 ~6 ~25 ~3 ~6 cobblestone 0  
fill ~23 ~3 ~8 ~25 ~3 ~8 planks 1  
fill ~23 ~3 ~11 ~26 ~3 ~11 wool 15 
setblock ~23 ~3 ~12 spruce_stairs 1  
fill ~23 ~3 ~13 ~28 ~3 ~13 carpet 14  
fill ~23 ~3 ~14 ~28 ~3 ~14 carpet 14  
fill ~23 ~3 ~15 ~28 ~3 ~15 carpet 14  
fill ~23 ~3 ~16 ~28 ~3 ~16 carpet 14  
fill ~23 ~3 ~42 ~23 ~4 ~42 trapdoor 4 
setblock ~23 ~3 ~43 spruce_stairs 3 
setblock ~23 ~3 ~49 spruce_stairs 2  
fill ~23 ~3 ~50 ~23 ~4 ~50 trapdoor 5  
fill ~23 ~3 ~54 ~25 ~3 ~54 stained_glass_pane 15  
fill ~24 ~3 ~5 ~24 ~9 ~5 cobblestone 0  
fill ~24 ~3 ~12 ~25 ~3 ~12 wooden_slab 1  
fill ~24 ~3 ~21 ~24 ~10 ~21 log 1  
fill ~24 ~3 ~22 ~25 ~3 ~22 planks 1  
fill ~24 ~3 ~27 ~25 ~3 ~27 planks 1  
fill ~24 ~3 ~28 ~24 ~10 ~28 log 1 
setblock ~24 ~3 ~43 trapdoor 15 
setblock ~24 ~3 ~44 spruce_stairs 6 
setblock ~24 ~3 ~48 spruce_stairs 7 
setblock ~24 ~3 ~49 trapdoor 7 
setblock ~24 ~3 ~55 cobblestone 0 
setblock ~25 ~3 ~21 stone_brick_stairs 2  
fill ~25 ~3 ~23 ~25 ~9 ~23 planks 5  
fill ~25 ~3 ~24 ~25 ~3 ~25 spruce_door 4  
fill ~25 ~3 ~26 ~25 ~9 ~26 planks 5  
fill ~25 ~3 ~28 ~26 ~3 ~28 stone_brick_stairs 3 
setblock ~25 ~3 ~45 trapdoor 4 
setblock ~25 ~3 ~46 spruce_stairs 0 
setblock ~25 ~3 ~47 trapdoor 5  
fill ~26 ~3 ~8 ~26 ~9 ~8 stonebrick 0 
setblock ~26 ~3 ~12 spruce_stairs 0 
setblock ~26 ~3 ~18 stone_slab 5 
setblock ~26 ~3 ~19 stone_brick_stairs 2  
fill ~26 ~3 ~20 ~26 ~4 ~20 stonebrick 0  
fill ~26 ~3 ~21 ~26 ~4 ~21 stonebrick 0  
fill ~26 ~3 ~22 ~26 ~8 ~22 planks 5  
fill ~26 ~3 ~27 ~26 ~8 ~27 planks 5 
setblock ~26 ~3 ~46 trapdoor 15 
setblock ~26 ~3 ~53 stone_brick_stairs 0  
fill ~26 ~3 ~54 ~26 ~7 ~54 stonebrick 0  
fill ~26 ~3 ~55 ~26 ~8 ~55 stone 0  
fill ~27 ~3 ~8 ~27 ~9 ~8 stained_glass_pane 15 
setblock ~27 ~3 ~9 bedrock 0  
fill ~27 ~3 ~12 ~29 ~3 ~12 carpet 15  
fill ~27 ~3 ~19 ~28 ~3 ~19 dark_oak_fence 0 
setblock ~27 ~3 ~20 fire 15  
fill ~27 ~3 ~21 ~28 ~3 ~21 bedrock 0  
fill ~27 ~3 ~22 ~27 ~4 ~22 planks 1  
fill ~27 ~3 ~27 ~27 ~4 ~27 planks 1  
fill ~27 ~3 ~28 ~28 ~3 ~28 planks 0  
fill ~27 ~3 ~29 ~28 ~3 ~29 oak_stairs 7  
fill ~27 ~3 ~32 ~27 ~3 ~39 carpet 15  
fill ~27 ~3 ~53 ~28 ~3 ~53 stone_brick_stairs 2  
fill ~27 ~3 ~54 ~28 ~3 ~54 planks 1  
fill ~27 ~3 ~56 ~28 ~3 ~56 stone 0  
fill ~28 ~3 ~7 ~32 ~3 ~7 stone 0  
fill ~28 ~3 ~8 ~28 ~5 ~8 stonebrick 0 
setblock ~28 ~3 ~9 planks 0  
fill ~28 ~3 ~10 ~29 ~3 ~10 oak_stairs 3  
fill ~28 ~3 ~50 ~29 ~3 ~50 oak_stairs 6 
setblock ~28 ~3 ~51 oak_stairs 4  
fill ~28 ~3 ~57 ~28 ~6 ~57 leaves 7  
fill ~29 ~3 ~8 ~31 ~3 ~8 planks 1  
fill ~29 ~3 ~9 ~31 ~3 ~9 planks 1 
setblock ~29 ~3 ~11 oak_stairs 0  
fill ~29 ~3 ~13 ~29 ~3 ~17 carpet 15 
setblock ~29 ~3 ~18 stone_slab 5 
setblock ~29 ~3 ~19 stone_brick_stairs 2  
fill ~29 ~3 ~20 ~29 ~4 ~20 stonebrick 0  
fill ~29 ~3 ~21 ~29 ~5 ~21 stonebrick 0 
setblock ~29 ~3 ~28 stone_brick_stairs 3 
setblock ~29 ~3 ~41 stone_slab 5 
setblock ~29 ~3 ~45 stone_slab 5 
setblock ~29 ~3 ~51 oak_stairs 7 
setblock ~29 ~3 ~53 stone_brick_stairs 1  
fill ~29 ~3 ~54 ~29 ~6 ~54 stonebrick 0  
fill ~29 ~3 ~55 ~29 ~6 ~55 stone 0  
fill ~30 ~3 ~10 ~31 ~3 ~10 planks 1 
setblock ~30 ~3 ~11 planks 0 
setblock ~30 ~3 ~21 stone_brick_stairs 2  
fill ~30 ~3 ~22 ~31 ~3 ~22 planks 1  
fill ~30 ~3 ~27 ~31 ~3 ~27 planks 1  
fill ~30 ~3 ~28 ~30 ~3 ~30 stone_brick_stairs 0 
setblock ~30 ~3 ~31 stone_brick_stairs 3 
setblock ~30 ~3 ~36 stone_brick_stairs 2  
fill ~30 ~3 ~37 ~30 ~6 ~37 cobblestone 0 
setblock ~30 ~3 ~38 stone_brick_stairs 0 
setblock ~30 ~3 ~39 stone_brick_stairs 3 
setblock ~30 ~3 ~41 stone_brick_stairs 0  
fill ~30 ~3 ~42 ~30 ~3 ~44 dark_oak_fence 0 
setblock ~30 ~3 ~45 stone_brick_stairs 0  
fill ~30 ~3 ~55 ~30 ~5 ~55 stained_glass_pane 15  
fill ~31 ~3 ~11 ~31 ~8 ~11 planks 1  
fill ~31 ~3 ~12 ~31 ~7 ~12 cobblestone 0  
fill ~31 ~3 ~17 ~31 ~7 ~17 cobblestone 0  
fill ~31 ~3 ~18 ~31 ~8 ~18 planks 1  
fill ~31 ~3 ~19 ~31 ~3 ~20 planks 1  
fill ~31 ~3 ~21 ~31 ~10 ~21 log 1 
setblock ~31 ~3 ~28 stone 4  
fill ~31 ~3 ~29 ~31 ~3 ~30 planks 1  
fill ~31 ~3 ~31 ~31 ~7 ~31 cobblestone 0  
fill ~31 ~3 ~36 ~31 ~7 ~36 cobblestone 0  
fill ~31 ~3 ~37 ~31 ~8 ~37 planks 1  
fill ~31 ~3 ~38 ~31 ~3 ~39 planks 1  
fill ~31 ~3 ~41 ~32 ~3 ~41 stonebrick 0  
fill ~31 ~3 ~42 ~31 ~3 ~44 fire 15 
setblock ~31 ~3 ~45 stonebrick 2 
setblock ~31 ~3 ~47 stone_brick_stairs 2 
setblock ~31 ~3 ~48 stone_brick_stairs 0 
setblock ~31 ~3 ~49 stone_brick_stairs 3 
setblock ~31 ~3 ~51 stone_brick_stairs 2  
fill ~31 ~3 ~52 ~31 ~3 ~53 stone_brick_stairs 0  
fill ~31 ~3 ~54 ~31 ~6 ~54 stonebrick 0  
fill ~31 ~3 ~55 ~31 ~6 ~55 stone 0  
fill ~32 ~3 ~8 ~32 ~9 ~8 stonebrick 0  
fill ~32 ~3 ~9 ~32 ~3 ~11 stone_brick_stairs 1 
setblock ~32 ~3 ~12 stone_brick_stairs 3 
setblock ~32 ~3 ~17 stone_brick_stairs 2  
fill ~32 ~3 ~18 ~32 ~3 ~20 stone_brick_stairs 1  
fill ~32 ~3 ~21 ~33 ~3 ~21 stone_brick_stairs 2  
fill ~32 ~3 ~28 ~32 ~3 ~30 stone_brick_stairs 1 
setblock ~32 ~3 ~31 stone_brick_stairs 3 
setblock ~32 ~3 ~36 stone_brick_stairs 2 
setblock ~32 ~3 ~37 stone_brick_stairs 1  
fill ~32 ~3 ~38 ~33 ~3 ~38 stone_brick_stairs 2  
fill ~32 ~3 ~39 ~33 ~3 ~39 planks 1 
setblock ~32 ~3 ~40 stone_brick_stairs 0  
fill ~32 ~3 ~42 ~32 ~3 ~44 bedrock 0  
fill ~32 ~3 ~45 ~32 ~4 ~45 stonebrick 0 
setblock ~32 ~3 ~46 stone_brick_stairs 0  
fill ~32 ~3 ~47 ~32 ~8 ~47 planks 1  
fill ~32 ~3 ~48 ~32 ~3 ~47 planks 1 
setblock ~32 ~3 ~49 stonebrick 2  
fill ~32 ~3 ~50 ~32 ~10 ~50 stained_glass_pane 15 
setblock ~32 ~3 ~51 stonebrick 0  
fill ~32 ~3 ~52 ~32 ~8 ~52 planks 1  
fill ~32 ~3 ~53 ~32 ~8 ~53 planks 1  
fill ~32 ~3 ~54 ~32 ~10 ~54 stained_glass_pane 15  
fill ~32 ~3 ~55 ~32 ~5 ~55 stonebrick 0  
fill ~32 ~3 ~56 ~33 ~3 ~56 stone 0  
fill ~33 ~3 ~8 ~33 ~9 ~8 stained_glass_pane 15  
fill ~33 ~3 ~9 ~33 ~5 ~9 bedrock 0  
fill ~33 ~3 ~22 ~35 ~3 ~22 planks 1  
fill ~33 ~3 ~23 ~35 ~3 ~23 planks 1  
fill ~33 ~3 ~24 ~34 ~3 ~24 planks 1  
fill ~33 ~3 ~25 ~34 ~3 ~25 planks 1  
fill ~33 ~3 ~26 ~35 ~3 ~26 planks 1  
fill ~33 ~3 ~27 ~35 ~3 ~27 planks 1 
setblock ~33 ~3 ~28 stone_brick_stairs 3  
fill ~33 ~3 ~40 ~33 ~3 ~46 planks 1  
fill ~33 ~3 ~47 ~36 ~3 ~47 stone 0  
fill ~33 ~3 ~55 ~33 ~14 ~55 stone 0 
setblock ~33 ~3 ~57 stone_stairs 0  
fill ~34 ~3 ~7 ~38 ~3 ~7 stone 0  
fill ~34 ~3 ~8 ~34 ~6 ~8 stonebrick 0 
setblock ~34 ~3 ~9 planks 0  
fill ~34 ~3 ~10 ~37 ~3 ~10 oak_stairs 3  
fill ~34 ~3 ~19 ~35 ~3 ~19 oak_stairs 6  
fill ~34 ~3 ~20 ~35 ~3 ~20 planks 0  
fill ~34 ~3 ~21 ~35 ~3 ~21 planks 1  
fill ~34 ~3 ~28 ~35 ~3 ~28 planks 1  
fill ~34 ~3 ~29 ~35 ~3 ~29 planks 0  
fill ~34 ~3 ~30 ~35 ~3 ~30 oak_stairs 7  
fill ~34 ~3 ~38 ~34 ~12 ~38 log 1 
setblock ~34 ~3 ~39 stone_brick_stairs 1  
fill ~34 ~3 ~40 ~35 ~3 ~40 stonebrick 0  
fill ~34 ~3 ~41 ~34 ~3 ~42 bedrock 0  
fill ~34 ~3 ~43 ~35 ~3 ~43 stonebrick 0 
setblock ~34 ~3 ~44 stone_brick_stairs 1  
fill ~34 ~3 ~45 ~34 ~11 ~45 log 1  
fill ~34 ~3 ~46 ~35 ~3 ~46 planks 1  
fill ~34 ~3 ~52 ~37 ~3 ~52 cobblestone 0  
fill ~35 ~3 ~8 ~37 ~3 ~8 planks 1  
fill ~35 ~3 ~9 ~37 ~3 ~9 oak_stairs 7  
fill ~35 ~3 ~24 ~35 ~2 ~24 planks 5  
fill ~35 ~3 ~25 ~35 ~2 ~25 planks 5  
fill ~35 ~3 ~38 ~35 ~7 ~38 cobblestone 0  
fill ~35 ~3 ~41 ~35 ~3 ~42 fire 15 
setblock ~35 ~3 ~45 stone_brick_stairs 2 
setblock ~35 ~3 ~49 cobblestone 0 
setblock ~35 ~3 ~57 mossy_cobblestone 0  
fill ~36 ~3 ~4 ~36 ~4 ~4 mossy_cobblestone 0 
setblock ~36 ~3 ~20 planks 1  
fill ~36 ~3 ~24 ~36 ~3 ~25 glowstone 0 
setblock ~36 ~3 ~29 planks 1 
setblock ~36 ~3 ~40 stone_brick_stairs 1  
fill ~36 ~3 ~41 ~36 ~3 ~42 dark_oak_fence 0 
setblock ~36 ~3 ~43 stone_brick_stairs 1 
setblock ~36 ~3 ~45 stone_brick_stairs 1  
fill ~36 ~3 ~46 ~36 ~8 ~46 stonebrick 0  
fill ~36 ~3 ~53 ~37 ~3 ~53 leaves 7  
fill ~36 ~3 ~57 ~37 ~3 ~57 cobblestone 0 
setblock ~37 ~3 ~11 stone_brick_stairs 0 
setblock ~37 ~3 ~20 stone 4 
setblock ~37 ~3 ~21 stone_brick_stairs 1  
fill ~37 ~3 ~22 ~37 ~3 ~27 spruce_stairs 1 
setblock ~37 ~3 ~28 stone_brick_stairs 1 
setblock ~37 ~3 ~29 stone 4  
fill ~37 ~3 ~35 ~37 ~3 ~36 wool 15 
setblock ~37 ~3 ~40 stone_slab 5 
setblock ~37 ~3 ~43 stone_slab 5  
fill ~37 ~3 ~46 ~38 ~3 ~46 stained_glass_pane 15  
fill ~38 ~3 ~8 ~38 ~9 ~8 stonebrick 0  
fill ~38 ~3 ~9 ~45 ~3 ~9 planks 1  
fill ~38 ~3 ~10 ~38 ~3 ~9 planks 1  
fill ~38 ~3 ~11 ~39 ~3 ~11 stone_brick_stairs 3  
fill ~38 ~3 ~19 ~38 ~4 ~19 purpur_pillar 0 
setblock ~38 ~3 ~20 stone_brick_stairs 3  
fill ~38 ~3 ~23 ~46 ~3 ~23 carpet 15  
fill ~38 ~3 ~24 ~48 ~3 ~24 carpet 14  
fill ~38 ~3 ~25 ~48 ~3 ~25 carpet 14  
fill ~38 ~3 ~26 ~46 ~3 ~26 carpet 15 
setblock ~38 ~3 ~29 stone_brick_stairs 2  
fill ~38 ~3 ~30 ~38 ~4 ~30 purpur_pillar 0  
fill ~38 ~3 ~32 ~40 ~3 ~32 carpet 15  
fill ~38 ~3 ~33 ~38 ~3 ~34 carpet 15 
setblock ~38 ~3 ~35 spruce_stairs 3 
setblock ~38 ~3 ~36 spruce_stairs 2  
fill ~38 ~3 ~37 ~38 ~3 ~39 carpet 15  
fill ~39 ~3 ~8 ~39 ~9 ~8 stained_glass_pane 15 
setblock ~39 ~3 ~10 log 1  
fill ~39 ~3 ~33 ~44 ~3 ~33 carpet 14  
fill ~39 ~3 ~34 ~39 ~3 ~38 carpet 14  
fill ~39 ~3 ~39 ~40 ~3 ~39 carpet 15 
setblock ~39 ~3 ~45 stone_brick_stairs 0  
fill ~39 ~3 ~46 ~39 ~7 ~46 stonebrick 0  
fill ~39 ~3 ~47 ~41 ~3 ~47 stone 0  
fill ~40 ~3 ~7 ~45 ~3 ~7 stone 0  
fill ~40 ~3 ~8 ~40 ~9 ~8 stonebrick 0  
fill ~40 ~3 ~10 ~40 ~3 ~11 stone_brick_stairs 1 
setblock ~40 ~3 ~34 oak_stairs 4  
fill ~40 ~3 ~35 ~40 ~3 ~36 wooden_slab 9 
setblock ~40 ~3 ~37 oak_stairs 4  
fill ~40 ~3 ~38 ~44 ~3 ~38 carpet 14 
setblock ~40 ~3 ~45 stone_brick_stairs 2  
fill ~40 ~3 ~46 ~40 ~12 ~46 planks 1 
setblock ~40 ~3 ~49 cobblestone 0  
fill ~41 ~3 ~8 ~45 ~3 ~8 planks 1 
setblock ~41 ~3 ~10 stone_brick_stairs 3  
fill ~41 ~3 ~31 ~42 ~3 ~31 wool 15 
setblock ~41 ~3 ~32 spruce_stairs 1  
fill ~41 ~3 ~34 ~42 ~3 ~34 wooden_slab 9  
fill ~41 ~3 ~35 ~42 ~3 ~35 wooden_slab 8  
fill ~41 ~3 ~36 ~42 ~3 ~36 wooden_slab 8  
fill ~41 ~3 ~37 ~42 ~3 ~37 wooden_slab 9 
setblock ~41 ~3 ~39 spruce_stairs 1  
fill ~41 ~3 ~40 ~42 ~3 ~40 wool 15 
setblock ~41 ~3 ~45 stone_brick_stairs 1  
fill ~41 ~3 ~46 ~41 ~9 ~46 stonebrick 0  
fill ~42 ~3 ~2 ~42 ~5 ~2 leaves 7  
fill ~42 ~3 ~10 ~43 ~3 ~10 planks 0  
fill ~42 ~3 ~11 ~43 ~3 ~11 oak_stairs 7 
setblock ~42 ~3 ~16 anvil 0 
setblock ~42 ~3 ~32 spruce_stairs 0 
setblock ~42 ~3 ~39 spruce_stairs 0  
fill ~42 ~3 ~46 ~43 ~3 ~46 stained_glass_pane 15 
setblock ~43 ~3 ~15 dark_oak_fence 0 
setblock ~43 ~3 ~17 dark_oak_fence 0  
fill ~43 ~3 ~32 ~45 ~3 ~32 carpet 15 
setblock ~43 ~3 ~34 oak_stairs 5  
fill ~43 ~3 ~35 ~43 ~3 ~36 wooden_slab 9 
setblock ~43 ~3 ~37 oak_stairs 5  
fill ~43 ~3 ~39 ~45 ~3 ~39 carpet 15 
setblock ~44 ~3 ~1 mossy_cobblestone 0 
setblock ~44 ~3 ~10 stone_brick_stairs 3  
fill ~44 ~3 ~34 ~44 ~3 ~38 carpet 14 
setblock ~44 ~3 ~45 stone_brick_stairs 0  
fill ~44 ~3 ~46 ~44 ~10 ~46 stonebrick 0  
fill ~44 ~3 ~47 ~46 ~3 ~47 stone 0  
fill ~45 ~3 ~2 ~46 ~3 ~2 stone 0  
fill ~45 ~3 ~3 ~47 ~3 ~3 stone 0  
fill ~45 ~3 ~10 ~45 ~3 ~11 stone_brick_stairs 0  
fill ~45 ~3 ~33 ~45 ~3 ~34 carpet 15 
setblock ~45 ~3 ~35 spruce_stairs 3 
setblock ~45 ~3 ~36 spruce_stairs 2  
fill ~45 ~3 ~37 ~45 ~3 ~39 carpet 15 
setblock ~45 ~3 ~45 stone_brick_stairs 2  
fill ~45 ~3 ~46 ~45 ~12 ~46 planks 1  
fill ~46 ~3 ~4 ~46 ~12 ~4 planks 5  
fill ~46 ~3 ~5 ~46 ~3 ~9 stonebrick 0  
fill ~46 ~3 ~10 ~46 ~12 ~10 planks 1  
fill ~46 ~3 ~11 ~47 ~3 ~11 stone_brick_stairs 3 
setblock ~46 ~3 ~15 dark_oak_fence 0 
setblock ~46 ~3 ~20 stone_brick_stairs 2 
setblock ~46 ~3 ~21 stone_brick_stairs 0 
setblock ~46 ~3 ~22 stone_brick_stairs 3 
setblock ~46 ~3 ~27 stone_brick_stairs 2 
setblock ~46 ~3 ~28 stone_brick_stairs 0 
setblock ~46 ~3 ~29 stone_brick_stairs 3  
fill ~46 ~3 ~35 ~46 ~3 ~36 wool 15 
setblock ~46 ~3 ~37 stone_brick_stairs 0  
fill ~46 ~3 ~38 ~46 ~7 ~38 cobblestone 0 
setblock ~46 ~3 ~39 stone_brick_stairs 0 
setblock ~46 ~3 ~45 stone_brick_stairs 1  
fill ~46 ~3 ~46 ~46 ~9 ~46 stonebrick 0  
fill ~47 ~3 ~4 ~47 ~7 ~4 stonebrick 0 
setblock ~47 ~3 ~10 stone 4  
fill ~47 ~3 ~12 ~47 ~3 ~20 stone_brick_stairs 0  
fill ~47 ~3 ~21 ~47 ~11 ~21 log 1 
setblock ~47 ~3 ~22 planks 5 
setblock ~47 ~3 ~23 cobblestone 0 
setblock ~47 ~3 ~26 cobblestone 0 
setblock ~47 ~3 ~27 planks 5  
fill ~47 ~3 ~28 ~47 ~11 ~28 log 1  
fill ~47 ~3 ~29 ~47 ~3 ~36 stone_brick_stairs 0 
setblock ~47 ~3 ~37 stone_brick_stairs 2  
fill ~47 ~3 ~38 ~47 ~12 ~38 log 1  
fill ~47 ~3 ~39 ~53 ~3 ~39 stone_brick_stairs 3  
fill ~47 ~3 ~46 ~48 ~3 ~46 stained_glass_pane 15  
fill ~48 ~3 ~4 ~52 ~3 ~4 stained_glass_pane 15  
fill ~48 ~3 ~11 ~48 ~8 ~11 planks 1  
fill ~48 ~3 ~12 ~50 ~3 ~12 planks 1  
fill ~48 ~3 ~13 ~48 ~8 ~13 planks 1  
fill ~48 ~3 ~14 ~48 ~5 ~14 stonebrick 0  
fill ~48 ~3 ~15 ~48 ~3 ~18 stonebrick 0  
fill ~48 ~3 ~19 ~48 ~8 ~19 planks 1  
fill ~48 ~3 ~20 ~49 ~3 ~20 planks 1  
fill ~48 ~3 ~21 ~49 ~3 ~21 planks 1  
fill ~48 ~3 ~22 ~48 ~12 ~22 planks 1  
fill ~48 ~3 ~23 ~48 ~5 ~23 stonebrick 0  
fill ~48 ~3 ~26 ~48 ~5 ~26 stonebrick 2  
fill ~48 ~3 ~27 ~48 ~12 ~27 planks 1  
fill ~48 ~3 ~28 ~49 ~3 ~28 planks 1  
fill ~48 ~3 ~29 ~49 ~3 ~29 planks 1  
fill ~48 ~3 ~30 ~48 ~8 ~30 planks 1  
fill ~48 ~3 ~31 ~48 ~4 ~31 stonebrick 0  
fill ~48 ~3 ~32 ~49 ~3 ~32 stonebrick 0  
fill ~48 ~3 ~33 ~48 ~3 ~35 stonebrick 0  
fill ~48 ~3 ~36 ~48 ~8 ~36 planks 1  
fill ~48 ~3 ~37 ~49 ~3 ~37 planks 1  
fill ~48 ~3 ~38 ~51 ~3 ~38 planks 1 
setblock ~49 ~3 ~3 cobblestone 0  
fill ~49 ~3 ~11 ~50 ~3 ~11 stonebrick 0  
fill ~49 ~3 ~13 ~49 ~4 ~13 stonebrick 2  
fill ~49 ~3 ~14 ~49 ~3 ~15 stonebrick 2  
fill ~49 ~3 ~16 ~49 ~3 ~19 stonebrick 0  
fill ~49 ~3 ~22 ~52 ~3 ~22 stone 0  
fill ~49 ~3 ~23 ~49 ~8 ~23 stone 0  
fill ~49 ~3 ~24 ~49 ~3 ~25 birch_door 6  
fill ~49 ~3 ~26 ~49 ~8 ~26 stone 0  
fill ~49 ~3 ~27 ~52 ~3 ~27 stone 0  
fill ~49 ~3 ~30 ~49 ~7 ~30 stonebrick 0  
fill ~49 ~3 ~31 ~49 ~4 ~31 stonebrick 2 
setblock ~49 ~3 ~33 stonebrick 2  
fill ~49 ~3 ~34 ~49 ~3 ~36 stonebrick 0 
setblock ~49 ~3 ~45 stone_brick_stairs 0  
fill ~49 ~3 ~46 ~49 ~10 ~46 stonebrick 0  
fill ~49 ~3 ~47 ~51 ~3 ~47 stone 0  
fill ~50 ~3 ~20 ~53 ~3 ~20 stone 0 
setblock ~50 ~3 ~23 cobblestone 0 
setblock ~50 ~3 ~26 cobblestone 0  
fill ~50 ~3 ~29 ~53 ~3 ~29 stone 0  
fill ~50 ~3 ~37 ~55 ~3 ~37 stone 0 
setblock ~50 ~3 ~45 stone_brick_stairs 2  
fill ~50 ~3 ~46 ~50 ~12 ~46 planks 1 
setblock ~50 ~3 ~49 cobblestone 0 
setblock ~51 ~3 ~3 cobblestone 0 
setblock ~51 ~3 ~11 stonebrick 2  
fill ~51 ~3 ~12 ~55 ~3 ~12 stone 0 
setblock ~51 ~3 ~14 stone_stairs 5 
setblock ~51 ~3 ~15 stone_slab 11 
setblock ~51 ~3 ~16 stone_stairs 5 
setblock ~51 ~3 ~17 stone_slab 11 
setblock ~51 ~3 ~18 stone_stairs 5 
setblock ~51 ~3 ~31 stone_stairs 5 
setblock ~51 ~3 ~32 stone_slab 11 
setblock ~51 ~3 ~33 stone_stairs 5 
setblock ~51 ~3 ~34 stone_slab 11 
setblock ~51 ~3 ~35 stone_stairs 5  
fill ~51 ~3 ~40 ~52 ~3 ~40 spruce_stairs 7  
fill ~51 ~3 ~41 ~52 ~3 ~41 wooden_slab 9  
fill ~51 ~3 ~42 ~52 ~3 ~42 wooden_slab 9  
fill ~51 ~3 ~43 ~52 ~3 ~43 wooden_slab 9  
fill ~51 ~3 ~44 ~52 ~3 ~44 spruce_stairs 6 
setblock ~51 ~3 ~45 stone_brick_stairs 1 
setblock ~51 ~3 ~46 stonebrick 2 
setblock ~52 ~3 ~11 stonebrick 0  
fill ~52 ~3 ~38 ~52 ~11 ~38 planks 5  
fill ~52 ~3 ~46 ~53 ~3 ~46 stained_glass_pane 15  
fill ~53 ~3 ~3 ~55 ~3 ~3 stone 0  
fill ~53 ~3 ~4 ~53 ~8 ~4 stonebrick 0  
fill ~53 ~3 ~5 ~53 ~7 ~5 stained_glass_pane 15  
fill ~53 ~3 ~6 ~53 ~7 ~6 stained_glass_pane 15  
fill ~53 ~3 ~7 ~53 ~8 ~7 stained_glass_pane 15  
fill ~53 ~3 ~8 ~53 ~7 ~8 stained_glass_pane 15  
fill ~53 ~3 ~9 ~53 ~7 ~9 stained_glass_pane 15  
fill ~53 ~3 ~10 ~53 ~4 ~10 stonebrick 0  
fill ~53 ~3 ~11 ~53 ~12 ~11 planks 1 
setblock ~53 ~3 ~19 stone_stairs 0  
fill ~53 ~3 ~22 ~53 ~4 ~22 cobblestone 0  
fill ~53 ~3 ~27 ~53 ~4 ~27 cobblestone 0  
fill ~53 ~3 ~38 ~54 ~3 ~38 planks 1 
setblock ~53 ~3 ~41 stone_brick_stairs 2 
setblock ~53 ~3 ~42 stone_brick_stairs 0 
setblock ~53 ~3 ~43 stone_brick_stairs 3  
fill ~54 ~3 ~2 ~55 ~3 ~2 stone 0 
setblock ~54 ~3 ~6 cobblestone 0 
setblock ~54 ~3 ~8 cobblestone 0  
fill ~54 ~3 ~22 ~57 ~3 ~22 stone_stairs 5  
fill ~54 ~3 ~27 ~57 ~3 ~27 stone_stairs 5  
fill ~54 ~3 ~40 ~54 ~9 ~40 stained_glass_pane 15 
setblock ~54 ~3 ~41 stonebrick 2  
fill ~54 ~3 ~42 ~54 ~12 ~42 planks 1  
fill ~54 ~3 ~43 ~54 ~10 ~43 stonebrick 0  
fill ~54 ~3 ~44 ~54 ~9 ~44 stained_glass_pane 15  
fill ~54 ~3 ~45 ~54 ~5 ~45 stonebrick 0  
fill ~54 ~3 ~46 ~54 ~11 ~46 stonebrick 0  
fill ~54 ~3 ~47 ~55 ~3 ~47 stone 0 
setblock ~55 ~3 ~1 leaves 7  
fill ~55 ~3 ~48 ~56 ~3 ~48 cobblestone 0  
fill ~56 ~3 ~11 ~56 ~3 ~12 leaves 15 
setblock ~56 ~3 ~13 cobblestone 0 
setblock ~56 ~3 ~46 leaves 15 
setblock ~57 ~3 ~12 leaves 15 
setblock ~57 ~3 ~46 leaves 7 
setblock ~60 ~3 ~21 torch 5 
setblock ~60 ~3 ~28 torch 5 
setblock ~2 ~4 ~25 leaves 7  
fill ~3 ~4 ~12 ~3 ~12 ~12 cobblestone 0 
setblock ~3 ~4 ~13 cobblestone_wall 0 
setblock ~3 ~4 ~24 leaves 7 
setblock ~3 ~4 ~25 cobblestone_wall 0  
fill ~3 ~4 ~26 ~4 ~4 ~26 cobblestone 0  
fill ~3 ~4 ~53 ~4 ~4 ~53 stone 0  
fill ~3 ~4 ~54 ~4 ~4 ~54 stone 0  
fill ~3 ~4 ~55 ~4 ~4 ~55 stone 0  
fill ~3 ~4 ~56 ~4 ~4 ~56 stone 0  
fill ~3 ~4 ~57 ~4 ~4 ~57 stone 0  
fill ~4 ~4 ~13 ~6 ~4 ~13 stone 0  
fill ~4 ~4 ~19 ~4 ~5 ~19 cobblestone_wall 0  
fill ~4 ~4 ~25 ~6 ~4 ~25 stone 0  
fill ~4 ~4 ~52 ~5 ~4 ~52 stone 0  
fill ~4 ~4 ~58 ~5 ~4 ~58 stone 0 
setblock ~5 ~4 ~15 stonebrick 2  
fill ~5 ~4 ~51 ~8 ~4 ~51 stone 0  
fill ~5 ~4 ~53 ~6 ~4 ~53 planks 1  
fill ~5 ~4 ~54 ~6 ~4 ~54 planks 1  
fill ~5 ~4 ~55 ~7 ~4 ~55 planks 1  
fill ~5 ~4 ~56 ~6 ~4 ~56 planks 1  
fill ~5 ~4 ~57 ~6 ~4 ~57 planks 1  
fill ~5 ~4 ~59 ~11 ~4 ~59 stone 0  
fill ~6 ~4 ~24 ~6 ~6 ~24 stonebrick 0  
fill ~6 ~4 ~50 ~8 ~4 ~50 stone 0  
fill ~6 ~4 ~52 ~6 ~3 ~52 planks 1  
fill ~6 ~4 ~60 ~10 ~4 ~60 stone 0  
fill ~7 ~4 ~14 ~13 ~4 ~14 stained_glass_pane 15  
fill ~7 ~4 ~24 ~13 ~4 ~24 stained_glass_pane 15  
fill ~7 ~4 ~52 ~7 ~4 ~54 spruce_stairs 1  
fill ~9 ~4 ~38 ~9 ~5 ~38 stonebrick 2  
fill ~9 ~4 ~43 ~9 ~11 ~43 planks 5  
fill ~9 ~4 ~49 ~9 ~8 ~49 planks 1  
fill ~9 ~4 ~51 ~9 ~6 ~51 cobblestone_wall 0  
fill ~10 ~4 ~13 ~10 ~5 ~13 cobblestone_wall 0  
fill ~10 ~4 ~25 ~10 ~5 ~25 cobblestone_wall 0  
fill ~10 ~4 ~37 ~11 ~4 ~37 stained_glass_pane 15  
fill ~11 ~4 ~19 ~12 ~4 ~19 cobblestone 0  
fill ~11 ~4 ~58 ~12 ~4 ~58 stone 0 
setblock ~11 ~4 ~61 leaves 15  
fill ~12 ~4 ~36 ~16 ~4 ~36 stone 0  
fill ~12 ~4 ~54 ~12 ~6 ~54 cobblestone_wall 0  
fill ~12 ~4 ~56 ~16 ~4 ~56 stone 0  
fill ~12 ~4 ~57 ~13 ~4 ~57 stone 0  
fill ~13 ~4 ~15 ~14 ~4 ~15 stone 4  
fill ~13 ~4 ~16 ~13 ~4 ~18 spruce_stairs 1 
setblock ~13 ~4 ~19 stone 4  
fill ~13 ~4 ~37 ~13 ~11 ~37 planks 5  
fill ~14 ~4 ~13 ~16 ~4 ~13 stone 0  
fill ~14 ~4 ~19 ~15 ~4 ~19 stone_slab 0  
fill ~14 ~4 ~25 ~16 ~4 ~25 stone 0  
fill ~14 ~4 ~28 ~15 ~4 ~28 stone_slab 0  
fill ~14 ~4 ~33 ~15 ~4 ~33 stone_slab 0  
fill ~14 ~4 ~35 ~15 ~4 ~35 cobblestone 0  
fill ~14 ~4 ~37 ~15 ~4 ~37 planks 1 
setblock ~14 ~4 ~38 redstone_torch 5  
fill ~14 ~4 ~54 ~14 ~11 ~54 planks 1 
setblock ~15 ~4 ~5 stone_stairs 2 
setblock ~15 ~4 ~6 mossy_cobblestone 0 
setblock ~15 ~4 ~7 stone_stairs 3 
setblock ~15 ~4 ~8 stone_slab 11  
fill ~15 ~4 ~12 ~15 ~7 ~12 leaves 7  
fill ~15 ~4 ~14 ~15 ~10 ~14 cobblestone 0  
fill ~15 ~4 ~15 ~16 ~4 ~15 cobblestone 0  
fill ~15 ~4 ~16 ~16 ~4 ~16 cobblestone_wall 0  
fill ~15 ~4 ~22 ~16 ~4 ~22 cobblestone_wall 0  
fill ~15 ~4 ~23 ~16 ~4 ~23 cobblestone 0  
fill ~15 ~4 ~24 ~16 ~4 ~24 cobblestone 0 
setblock ~15 ~4 ~27 cobblestone 0 
setblock ~15 ~4 ~34 cobblestone 0 
setblock ~15 ~4 ~38 bedrock 0  
fill ~15 ~4 ~54 ~15 ~9 ~54 planks 5 
setblock ~16 ~4 ~6 stone_stairs 1  
fill ~16 ~4 ~7 ~20 ~4 ~7 stone 0 
setblock ~16 ~4 ~14 mossy_cobblestone 0  
fill ~16 ~4 ~29 ~16 ~5 ~29 cobblestone_wall 0  
fill ~16 ~4 ~32 ~16 ~5 ~32 cobblestone_wall 0  
fill ~16 ~4 ~37 ~16 ~10 ~37 planks 5 
setblock ~16 ~4 ~44 bedrock 0 
setblock ~16 ~4 ~46 carpet 0 
setblock ~16 ~4 ~47 bedrock 0  
fill ~16 ~4 ~54 ~16 ~8 ~54 planks 1 
setblock ~17 ~4 ~6 mossy_cobblestone 0  
fill ~17 ~4 ~8 ~19 ~4 ~8 planks 1  
fill ~17 ~4 ~13 ~17 ~12 ~13 planks 1  
fill ~17 ~4 ~26 ~17 ~9 ~26 planks 5  
fill ~17 ~4 ~27 ~17 ~6 ~27 planks 1 
setblock ~17 ~4 ~30 birch_door 8 
setblock ~17 ~4 ~31 birch_door 9  
fill ~17 ~4 ~33 ~17 ~10 ~33 stonebrick 0  
fill ~17 ~4 ~37 ~17 ~10 ~37 log 1 
setblock ~17 ~4 ~42 trapdoor 12 
setblock ~17 ~4 ~44 carpet 0 
setblock ~17 ~4 ~48 carpet 0  
fill ~17 ~4 ~54 ~17 ~6 ~54 stonebrick 0  
fill ~18 ~4 ~4 ~18 ~11 ~4 cobblestone 0  
fill ~18 ~4 ~6 ~18 ~11 ~6 cobblestone 0  
fill ~18 ~4 ~10 ~18 ~7 ~10 bookshelf 0  
fill ~18 ~4 ~11 ~18 ~7 ~11 bookshelf 0  
fill ~18 ~4 ~12 ~18 ~7 ~12 bookshelf 0 
setblock ~18 ~4 ~13 oak_stairs 1  
fill ~18 ~4 ~29 ~18 ~5 ~29 cobblestone_wall 0  
fill ~18 ~4 ~32 ~18 ~5 ~32 cobblestone_wall 0  
fill ~18 ~4 ~35 ~18 ~4 ~36 bedrock 0 
setblock ~18 ~4 ~46 redstone_torch 5 
setblock ~18 ~4 ~48 bedrock 0  
fill ~19 ~4 ~4 ~19 ~5 ~4 leaves 15 
setblock ~19 ~4 ~6 mossy_cobblestone 0  
fill ~19 ~4 ~9 ~19 ~7 ~9 bookshelf 0 
setblock ~19 ~4 ~44 bedrock 0 
setblock ~20 ~4 ~9 oak_stairs 3 
setblock ~20 ~4 ~44 carpet 0 
setblock ~20 ~4 ~46 bedrock 0 
setblock ~20 ~4 ~48 carpet 0 
setblock ~20 ~4 ~50 trapdoor 5  
fill ~20 ~4 ~54 ~20 ~8 ~54 planks 1  
fill ~20 ~4 ~56 ~21 ~4 ~56 stone 0  
fill ~21 ~4 ~14 ~21 ~4 ~16 wooden_slab 1 
setblock ~21 ~4 ~48 bedrock 0  
fill ~21 ~4 ~54 ~21 ~10 ~54 planks 5  
fill ~22 ~4 ~7 ~26 ~4 ~7 stone 0  
fill ~22 ~4 ~8 ~22 ~8 ~8 stonebrick 0 
setblock ~22 ~4 ~9 oak_stairs 7 
setblock ~22 ~4 ~44 bedrock 0 
setblock ~22 ~4 ~46 redstone_torch 5  
fill ~23 ~4 ~6 ~25 ~4 ~6 cobblestone 0  
fill ~23 ~4 ~8 ~25 ~4 ~8 planks 1  
fill ~23 ~4 ~9 ~25 ~4 ~9 bookshelf 0  
fill ~23 ~4 ~11 ~26 ~4 ~11 wooden_slab 1 
setblock ~23 ~4 ~44 carpet 0 
setblock ~23 ~4 ~48 carpet 0  
fill ~23 ~4 ~54 ~25 ~4 ~54 stained_glass_pane 15 
setblock ~24 ~4 ~4 mossy_cobblestone 0  
fill ~24 ~4 ~22 ~25 ~4 ~22 planks 1 
setblock ~24 ~4 ~23 dark_oak_fence 0 
setblock ~24 ~4 ~26 dark_oak_fence 0  
fill ~24 ~4 ~27 ~25 ~4 ~27 planks 1 
setblock ~24 ~4 ~45 bedrock 0 
setblock ~24 ~4 ~46 carpet 0 
setblock ~24 ~4 ~48 bedrock 0  
fill ~24 ~4 ~55 ~24 ~8 ~55 cobblestone_wall 0 
setblock ~25 ~4 ~24 spruce_door 8 
setblock ~25 ~4 ~25 spruce_door 9 
setblock ~26 ~4 ~9 oak_stairs 7 
setblock ~26 ~4 ~19 cobblestone_wall 0 
setblock ~26 ~4 ~46 trapdoor 7  
fill ~27 ~4 ~21 ~29 ~4 ~21 stonebrick 0  
fill ~27 ~4 ~28 ~28 ~4 ~28 bedrock 0  
fill ~27 ~4 ~54 ~27 ~10 ~54 planks 5  
fill ~27 ~4 ~56 ~28 ~4 ~56 stone 0  
fill ~28 ~4 ~7 ~32 ~4 ~7 stone 0 
setblock ~28 ~4 ~9 oak_stairs 3 
setblock ~28 ~4 ~50 bedrock 0  
fill ~28 ~4 ~54 ~28 ~8 ~54 planks 1 
setblock ~28 ~4 ~58 leaves 7  
fill ~29 ~4 ~8 ~31 ~4 ~8 planks 1  
fill ~29 ~4 ~9 ~29 ~7 ~9 bookshelf 0 
setblock ~29 ~4 ~19 cobblestone_wall 0 
setblock ~29 ~4 ~51 bedrock 0  
fill ~30 ~4 ~10 ~30 ~7 ~10 bookshelf 0 
setblock ~30 ~4 ~11 oak_stairs 0  
fill ~30 ~4 ~22 ~31 ~4 ~22 planks 1  
fill ~30 ~4 ~27 ~31 ~4 ~27 planks 1 
setblock ~30 ~4 ~41 cobblestone_wall 0 
setblock ~30 ~4 ~45 cobblestone_wall 0  
fill ~31 ~4 ~9 ~31 ~8 ~9 planks 1  
fill ~31 ~4 ~10 ~31 ~13 ~10 planks 5  
fill ~31 ~4 ~19 ~31 ~12 ~19 planks 5  
fill ~31 ~4 ~20 ~31 ~8 ~20 planks 1  
fill ~31 ~4 ~28 ~31 ~10 ~28 log 1  
fill ~31 ~4 ~29 ~31 ~11 ~29 planks 5  
fill ~31 ~4 ~30 ~31 ~8 ~30 planks 1  
fill ~31 ~4 ~38 ~31 ~11 ~38 planks 5  
fill ~31 ~4 ~39 ~32 ~4 ~39 planks 1  
fill ~31 ~4 ~41 ~31 ~3 ~41 stonebrick 0 
setblock ~31 ~4 ~45 stonebrick 0  
fill ~32 ~4 ~41 ~32 ~4 ~42 stonebrick 2  
fill ~32 ~4 ~43 ~32 ~4 ~45 stonebrick 0  
fill ~32 ~4 ~48 ~32 ~12 ~48 planks 5  
fill ~32 ~4 ~49 ~32 ~5 ~49 stonebrick 0 
setblock ~32 ~4 ~51 stonebrick 2  
fill ~32 ~4 ~56 ~33 ~4 ~56 stone 0  
fill ~33 ~4 ~22 ~34 ~4 ~22 planks 1  
fill ~33 ~4 ~23 ~34 ~4 ~23 planks 1  
fill ~33 ~4 ~24 ~34 ~4 ~24 planks 1  
fill ~33 ~4 ~25 ~34 ~4 ~25 planks 1  
fill ~33 ~4 ~26 ~34 ~4 ~26 planks 1  
fill ~33 ~4 ~27 ~34 ~4 ~27 planks 1  
fill ~33 ~4 ~39 ~33 ~6 ~39 cobblestone 0  
fill ~33 ~4 ~40 ~33 ~6 ~40 log 1  
fill ~33 ~4 ~41 ~33 ~6 ~41 cobblestone 0  
fill ~33 ~4 ~42 ~33 ~6 ~42 cobblestone 0  
fill ~33 ~4 ~43 ~33 ~6 ~43 log 1  
fill ~33 ~4 ~44 ~33 ~6 ~44 cobblestone 0 
setblock ~33 ~4 ~45 mossy_cobblestone 0  
fill ~33 ~4 ~46 ~33 ~6 ~46 log 1  
fill ~33 ~4 ~47 ~36 ~4 ~47 stone 0  
fill ~34 ~4 ~7 ~38 ~4 ~7 stone 0 
setblock ~34 ~4 ~9 oak_stairs 7  
fill ~34 ~4 ~20 ~35 ~4 ~20 bedrock 0  
fill ~34 ~4 ~21 ~35 ~4 ~21 planks 1  
fill ~34 ~4 ~28 ~35 ~4 ~28 planks 1  
fill ~34 ~4 ~29 ~35 ~4 ~29 bedrock 0  
fill ~34 ~4 ~40 ~35 ~4 ~40 stonebrick 0  
fill ~34 ~4 ~41 ~34 ~7 ~41 stonebrick 0 
setblock ~34 ~4 ~42 stonebrick 2  
fill ~34 ~4 ~43 ~34 ~5 ~43 stonebrick 0  
fill ~34 ~4 ~46 ~35 ~4 ~46 planks 1  
fill ~34 ~4 ~52 ~35 ~4 ~52 cobblestone 0  
fill ~35 ~4 ~8 ~37 ~4 ~8 planks 1  
fill ~35 ~4 ~9 ~37 ~4 ~9 bookshelf 0 
setblock ~35 ~4 ~22 planks 5  
fill ~35 ~4 ~24 ~36 ~4 ~24 spruce_stairs 1 
setblock ~35 ~4 ~25 spruce_stairs 5 
setblock ~35 ~4 ~27 planks 5 
setblock ~35 ~4 ~43 stonebrick 2 
setblock ~35 ~4 ~48 cobblestone 0 
setblock ~35 ~4 ~49 stone_stairs 3  
fill ~35 ~4 ~57 ~37 ~4 ~57 cobblestone 0 
setblock ~36 ~4 ~20 stone 4  
fill ~36 ~4 ~21 ~36 ~4 ~22 stone_brick_stairs 1 
setblock ~36 ~4 ~23 spruce_stairs 1  
fill ~36 ~4 ~25 ~36 ~4 ~26 spruce_stairs 1  
fill ~36 ~4 ~27 ~36 ~4 ~28 stone_brick_stairs 1 
setblock ~36 ~4 ~29 stone 4 
setblock ~36 ~4 ~40 cobblestone_wall 0 
setblock ~36 ~4 ~43 cobblestone_wall 0 
setblock ~36 ~4 ~52 mossy_cobblestone 0  
fill ~37 ~4 ~20 ~39 ~4 ~20 stone_slab 0  
fill ~37 ~4 ~29 ~39 ~4 ~29 stone_slab 0  
fill ~37 ~4 ~35 ~37 ~4 ~36 wooden_slab 1  
fill ~37 ~4 ~46 ~38 ~4 ~46 stained_glass_pane 15  
fill ~37 ~4 ~52 ~37 ~7 ~52 cobblestone 0  
fill ~37 ~4 ~53 ~37 ~5 ~53 leaves 7  
fill ~38 ~4 ~9 ~39 ~4 ~9 planks 1  
fill ~38 ~4 ~10 ~38 ~11 ~10 log 1  
fill ~39 ~4 ~10 ~39 ~12 ~10 planks 1  
fill ~39 ~4 ~47 ~41 ~4 ~47 stone 0  
fill ~40 ~4 ~7 ~45 ~4 ~7 stone 0  
fill ~40 ~4 ~9 ~40 ~9 ~9 cobblestone 0 
setblock ~40 ~4 ~49 stone_stairs 3  
fill ~41 ~4 ~8 ~46 ~4 ~8 planks 1  
fill ~41 ~4 ~9 ~41 ~10 ~9 log 1  
fill ~41 ~4 ~31 ~42 ~4 ~31 wooden_slab 1 
setblock ~41 ~4 ~35 bedrock 0  
fill ~41 ~4 ~40 ~42 ~4 ~40 wooden_slab 1 
setblock ~42 ~4 ~6 mossy_cobblestone 0  
fill ~42 ~4 ~9 ~43 ~4 ~9 cobblestone 0 
setblock ~42 ~4 ~10 bedrock 0  
fill ~42 ~4 ~46 ~43 ~4 ~46 stained_glass_pane 15 
setblock ~43 ~4 ~10 redstone_torch 5  
fill ~43 ~4 ~15 ~43 ~4 ~17 stone_slab 0  
fill ~44 ~4 ~1 ~44 ~9 ~1 cobblestone 0 
setblock ~44 ~4 ~2 stone_stairs 3  
fill ~44 ~4 ~9 ~44 ~10 ~9 log 1  
fill ~44 ~4 ~15 ~46 ~4 ~15 stained_hardened_clay 15  
fill ~44 ~4 ~16 ~46 ~4 ~16 stained_hardened_clay 15  
fill ~44 ~4 ~17 ~45 ~4 ~17 stained_hardened_clay 15  
fill ~44 ~4 ~47 ~46 ~4 ~47 stone 0 
setblock ~45 ~4 ~1 stone_stairs 1  
fill ~45 ~4 ~2 ~46 ~4 ~2 stone 0  
fill ~45 ~4 ~3 ~47 ~4 ~3 stone 0  
fill ~45 ~4 ~9 ~45 ~9 ~9 cobblestone 0 
setblock ~45 ~4 ~49 stone_stairs 3  
fill ~46 ~4 ~5 ~46 ~12 ~5 planks 1  
fill ~46 ~4 ~6 ~46 ~12 ~6 planks 1  
fill ~46 ~4 ~7 ~46 ~12 ~7 planks 1  
fill ~46 ~4 ~9 ~46 ~12 ~9 planks 1  
fill ~46 ~4 ~35 ~46 ~4 ~36 wooden_slab 1  
fill ~47 ~4 ~10 ~47 ~11 ~10 log 1  
fill ~47 ~4 ~22 ~47 ~10 ~22 log 1  
fill ~47 ~4 ~23 ~47 ~5 ~23 cobblestone_wall 0  
fill ~47 ~4 ~26 ~47 ~5 ~26 cobblestone_wall 0  
fill ~47 ~4 ~27 ~47 ~10 ~27 log 1  
fill ~47 ~4 ~46 ~48 ~4 ~46 stained_glass_pane 15  
fill ~48 ~4 ~4 ~52 ~4 ~4 stained_glass_pane 15  
fill ~48 ~4 ~12 ~48 ~11 ~12 planks 5  
fill ~48 ~4 ~18 ~49 ~4 ~18 stonebrick 2  
fill ~48 ~4 ~20 ~48 ~11 ~20 planks 5  
fill ~48 ~4 ~21 ~49 ~4 ~21 planks 1  
fill ~48 ~4 ~28 ~49 ~4 ~28 planks 1  
fill ~48 ~4 ~29 ~48 ~11 ~29 planks 5  
fill ~48 ~4 ~35 ~49 ~4 ~35 stonebrick 0  
fill ~48 ~4 ~37 ~48 ~11 ~37 planks 5  
fill ~48 ~4 ~38 ~48 ~8 ~38 planks 1  
fill ~49 ~4 ~3 ~49 ~6 ~3 cobblestone_wall 0  
fill ~49 ~4 ~11 ~53 ~4 ~11 planks 1  
fill ~49 ~4 ~12 ~50 ~4 ~12 planks 1  
fill ~49 ~4 ~14 ~49 ~9 ~14 stonebrick 0  
fill ~49 ~4 ~15 ~49 ~7 ~15 stained_glass_pane 15  
fill ~49 ~4 ~16 ~49 ~7 ~16 stained_glass_pane 15  
fill ~49 ~4 ~17 ~49 ~7 ~17 stained_glass_pane 15 
setblock ~49 ~4 ~19 stonebrick 2  
fill ~49 ~4 ~20 ~49 ~12 ~20 planks 1  
fill ~49 ~4 ~22 ~52 ~4 ~22 stone 0 
setblock ~49 ~4 ~24 birch_door 9 
setblock ~49 ~4 ~25 birch_door 8  
fill ~49 ~4 ~27 ~52 ~4 ~27 stone 0  
fill ~49 ~4 ~29 ~49 ~12 ~29 planks 1  
fill ~49 ~4 ~32 ~49 ~7 ~32 stained_glass_pane 15  
fill ~49 ~4 ~33 ~49 ~7 ~33 stained_glass_pane 15  
fill ~49 ~4 ~34 ~49 ~7 ~34 stained_glass_pane 15  
fill ~49 ~4 ~36 ~49 ~9 ~36 stonebrick 0  
fill ~49 ~4 ~37 ~49 ~12 ~37 planks 1  
fill ~49 ~4 ~38 ~49 ~11 ~38 planks 5  
fill ~49 ~4 ~47 ~51 ~4 ~47 stone 0 
setblock ~50 ~4 ~16 cobblestone 0  
fill ~50 ~4 ~20 ~53 ~4 ~20 stone 0  
fill ~50 ~4 ~23 ~50 ~5 ~23 cobblestone_wall 0  
fill ~50 ~4 ~26 ~50 ~5 ~26 cobblestone_wall 0  
fill ~50 ~4 ~29 ~53 ~4 ~29 stone 0 
setblock ~50 ~4 ~33 cobblestone 0  
fill ~50 ~4 ~37 ~55 ~4 ~37 stone 0  
fill ~50 ~4 ~38 ~51 ~4 ~38 planks 1 
setblock ~50 ~4 ~49 stone_stairs 3  
fill ~51 ~4 ~3 ~51 ~6 ~3 cobblestone_wall 0  
fill ~51 ~4 ~12 ~55 ~4 ~12 stone 0  
fill ~51 ~4 ~35 ~51 ~5 ~35 leaves 7  
fill ~51 ~4 ~40 ~51 ~6 ~40 spruce_stairs 4  
fill ~51 ~4 ~41 ~51 ~4 ~42 bedrock 0 
setblock ~51 ~4 ~43 redstone_torch 5  
fill ~51 ~4 ~44 ~51 ~6 ~44 spruce_stairs 4  
fill ~51 ~4 ~46 ~51 ~10 ~46 stonebrick 0  
fill ~52 ~4 ~40 ~52 ~7 ~40 planks 1  
fill ~52 ~4 ~41 ~52 ~7 ~41 planks 1  
fill ~52 ~4 ~42 ~52 ~4 ~44 planks 1  
fill ~52 ~4 ~46 ~53 ~4 ~46 stained_glass_pane 15  
fill ~53 ~4 ~1 ~54 ~4 ~1 leaves 15  
fill ~53 ~4 ~3 ~55 ~4 ~3 stone 0 
setblock ~53 ~4 ~30 stone_stairs 0  
fill ~53 ~4 ~38 ~54 ~4 ~38 planks 1  
fill ~54 ~4 ~2 ~55 ~4 ~2 stone 0  
fill ~54 ~4 ~6 ~54 ~6 ~6 cobblestone_wall 0  
fill ~54 ~4 ~8 ~54 ~6 ~8 cobblestone_wall 0 
setblock ~54 ~4 ~20 stone_stairs 3 
setblock ~54 ~4 ~29 stone_stairs 2 
setblock ~54 ~4 ~39 stonebrick 2  
fill ~54 ~4 ~41 ~54 ~7 ~41 stonebrick 0  
fill ~54 ~4 ~47 ~55 ~4 ~47 stone 0 
setblock ~55 ~4 ~0 leaves 15 
setblock ~55 ~4 ~1 stone_stairs 0 
setblock ~55 ~4 ~13 stone_stairs 0 
setblock ~55 ~4 ~36 stone_stairs 0 
setblock ~55 ~4 ~42 mossy_cobblestone 0  
fill ~55 ~4 ~48 ~56 ~4 ~48 cobblestone 0 
setblock ~55 ~4 ~49 stone_stairs 3 
setblock ~56 ~4 ~2 stone_stairs 3 
setblock ~56 ~4 ~11 leaves 7 
setblock ~56 ~4 ~12 stone_stairs 2 
setblock ~56 ~4 ~13 mossy_cobblestone 0 
setblock ~56 ~4 ~37 stone_stairs 3 
setblock ~56 ~4 ~46 leaves 7 
setblock ~56 ~4 ~47 stone_stairs 2 
setblock ~57 ~4 ~36 stone_stairs 1 
setblock ~57 ~4 ~48 stone_stairs 1 
setblock ~3 ~5 ~25 leaves 7  
fill ~3 ~5 ~26 ~3 ~10 ~26 cobblestone 0  
fill ~3 ~5 ~53 ~4 ~5 ~53 stone 0  
fill ~3 ~5 ~54 ~4 ~5 ~54 stone 0  
fill ~3 ~5 ~55 ~4 ~5 ~55 stone 0  
fill ~3 ~5 ~56 ~4 ~5 ~56 stone 0  
fill ~3 ~5 ~57 ~4 ~5 ~57 stone 0  
fill ~4 ~5 ~13 ~5 ~5 ~13 stone 0 
setblock ~4 ~5 ~15 stone_stairs 7 
setblock ~4 ~5 ~23 stone_stairs 6  
fill ~4 ~5 ~25 ~5 ~5 ~25 stone 0 
setblock ~4 ~5 ~26 mossy_cobblestone 0  
fill ~4 ~5 ~52 ~5 ~5 ~52 stone 0  
fill ~4 ~5 ~58 ~5 ~5 ~58 stone 0  
fill ~5 ~5 ~15 ~5 ~6 ~15 stonebrick 0  
fill ~5 ~5 ~51 ~8 ~5 ~51 stone 0 
setblock ~5 ~5 ~54 spruce_stairs 2  
fill ~5 ~5 ~55 ~6 ~5 ~55 planks 1  
fill ~5 ~5 ~56 ~6 ~5 ~56 planks 1  
fill ~5 ~5 ~57 ~6 ~5 ~57 planks 1  
fill ~5 ~5 ~59 ~11 ~5 ~59 stone 0 
setblock ~6 ~5 ~13 stone_stairs 5 
setblock ~6 ~5 ~18 dark_oak_fence 0  
setblock ~6 ~5 ~25 stone_stairs 5 
setblock ~6 ~5 ~36 leaves 7  
fill ~6 ~5 ~50 ~8 ~5 ~50 stone 0 
setblock ~6 ~5 ~54 spruce_stairs 1  
fill ~6 ~5 ~60 ~10 ~5 ~60 stone 0  
fill ~7 ~5 ~14 ~13 ~5 ~14 stained_glass_pane 15  
fill ~7 ~5 ~24 ~13 ~5 ~24 stained_glass_pane 15 
setblock ~7 ~5 ~36 stone_stairs 3 
setblock ~7 ~5 ~49 stone_stairs 2 
setblock ~7 ~5 ~55 spruce_stairs 2 
setblock ~7 ~5 ~57 bedrock 0 
setblock ~8 ~5 ~35 stone_stairs 1  
fill ~8 ~5 ~61 ~8 ~7 ~61 leaves 15 
setblock ~9 ~5 ~44 stonebrick 2 
setblock ~10 ~5 ~18 dark_oak_fence 0  
fill ~10 ~5 ~37 ~11 ~5 ~37 stained_glass_pane 15  
fill ~10 ~5 ~61 ~10 ~5 ~62 leaves 15  
fill ~11 ~5 ~19 ~11 ~3 ~19 cobblestone 0  
fill ~11 ~5 ~58 ~12 ~5 ~58 stone 0  
fill ~12 ~5 ~15 ~13 ~5 ~15 stone 4  
fill ~12 ~5 ~16 ~12 ~5 ~18 spruce_stairs 1 
setblock ~12 ~5 ~19 stone 4  
fill ~12 ~5 ~36 ~16 ~5 ~36 stone 0 
setblock ~12 ~5 ~37 stonebrick 2  
fill ~12 ~5 ~56 ~16 ~5 ~56 stone 0  
fill ~12 ~5 ~57 ~13 ~5 ~57 stone 0 
setblock ~13 ~5 ~19 stone_slab 0 
setblock ~13 ~5 ~35 stone_stairs 0 
setblock ~14 ~5 ~13 stone_stairs 4  
fill ~14 ~5 ~15 ~14 ~12 ~15 stonebrick 0 
setblock ~14 ~5 ~25 stone_stairs 4  
fill ~14 ~5 ~35 ~15 ~5 ~35 cobblestone 0  
fill ~14 ~5 ~37 ~15 ~5 ~37 planks 1  
fill ~15 ~5 ~6 ~15 ~7 ~6 cobblestone 0  
fill ~15 ~5 ~13 ~16 ~5 ~13 stone 0  
fill ~15 ~5 ~15 ~16 ~5 ~15 cobblestone 0  
fill ~15 ~5 ~16 ~16 ~5 ~16 cobblestone_wall 0  
fill ~15 ~5 ~22 ~16 ~5 ~22 cobblestone_wall 0  
fill ~15 ~5 ~23 ~16 ~5 ~23 cobblestone 0 
setblock ~15 ~5 ~24 mossy_cobblestone 0  
fill ~15 ~5 ~25 ~16 ~5 ~25 stone 0  
fill ~15 ~5 ~26 ~15 ~13 ~26 cobblestone 0 
setblock ~15 ~5 ~27 stone_stairs 3 
setblock ~15 ~5 ~34 stone_stairs 2 
setblock ~15 ~5 ~57 stone_stairs 1  
fill ~16 ~5 ~7 ~20 ~5 ~7 stone 0  
fill ~16 ~5 ~14 ~16 ~12 ~14 cobblestone 0  
fill ~16 ~5 ~24 ~16 ~11 ~24 cobblestone 0  
fill ~17 ~5 ~6 ~17 ~8 ~6 cobblestone 0  
fill ~17 ~5 ~8 ~19 ~5 ~8 planks 1  
fill ~17 ~5 ~30 ~17 ~10 ~30 stonebrick 0  
fill ~17 ~5 ~31 ~17 ~5 ~28 stonebrick 0 
setblock ~18 ~5 ~5 mossy_cobblestone 0 
setblock ~18 ~5 ~13 oak_stairs 5  
fill ~19 ~5 ~6 ~19 ~11 ~6 cobblestone 0 
setblock ~20 ~5 ~9 oak_stairs 7  
fill ~20 ~5 ~56 ~21 ~5 ~56 stone 0  
fill ~21 ~5 ~55 ~21 ~8 ~55 planks 5  
fill ~22 ~5 ~7 ~26 ~5 ~7 stone 0 
setblock ~22 ~5 ~9 planks 0  
fill ~23 ~5 ~6 ~25 ~5 ~6 cobblestone 0  
fill ~23 ~5 ~8 ~25 ~5 ~8 planks 1  
fill ~23 ~5 ~9 ~25 ~5 ~9 bookshelf 0  
fill ~23 ~5 ~54 ~25 ~5 ~54 stained_glass_pane 15  
fill ~24 ~5 ~4 ~24 ~8 ~4 cobblestone 0  
fill ~24 ~5 ~22 ~25 ~5 ~22 planks 1 
setblock ~24 ~5 ~23 redstone_torch 5 
setblock ~24 ~5 ~26 redstone_torch 5  
fill ~24 ~5 ~27 ~24 ~6 ~27 planks 1  
fill ~25 ~5 ~24 ~25 ~11 ~24 planks 1  
fill ~25 ~5 ~25 ~25 ~11 ~25 planks 1 
setblock ~25 ~5 ~27 planks 5 
setblock ~26 ~5 ~9 planks 0  
fill ~26 ~5 ~19 ~29 ~5 ~19 stone_brick_stairs 2  
fill ~26 ~5 ~20 ~26 ~5 ~21 double_stone_slab 0  
fill ~27 ~5 ~20 ~29 ~5 ~20 stone_slab 8  
fill ~27 ~5 ~21 ~29 ~5 ~21 stonebrick 0  
fill ~27 ~5 ~22 ~32 ~5 ~22 planks 5  
fill ~27 ~5 ~27 ~32 ~5 ~27 planks 5  
fill ~27 ~5 ~56 ~28 ~5 ~56 stone 0 
setblock ~27 ~5 ~58 leaves 7  
fill ~28 ~5 ~7 ~32 ~5 ~7 stone 0 
setblock ~28 ~5 ~9 oak_stairs 7  
fill ~29 ~5 ~8 ~31 ~5 ~8 planks 1 
setblock ~29 ~5 ~23 dark_oak_fence 0 
setblock ~29 ~5 ~26 dark_oak_fence 0 
setblock ~30 ~5 ~11 oak_stairs 4  
fill ~30 ~5 ~41 ~30 ~5 ~45 stone_brick_stairs 0  
fill ~31 ~5 ~39 ~32 ~5 ~39 planks 1  
fill ~31 ~5 ~41 ~32 ~5 ~41 double_stone_slab 0  
fill ~31 ~5 ~42 ~31 ~5 ~44 stone_slab 8  
fill ~31 ~5 ~45 ~32 ~5 ~45 double_stone_slab 0 
setblock ~32 ~5 ~23 dark_oak_stairs 7  
fill ~32 ~5 ~24 ~32 ~6 ~24 dark_oak_stairs 4  
fill ~32 ~5 ~25 ~32 ~6 ~25 dark_oak_stairs 4 
setblock ~32 ~5 ~26 dark_oak_stairs 6  
fill ~32 ~5 ~42 ~32 ~6 ~42 stonebrick 0 
setblock ~32 ~5 ~43 stonebrick 2  
fill ~32 ~5 ~44 ~32 ~6 ~44 stonebrick 0  
fill ~32 ~5 ~51 ~32 ~9 ~51 stonebrick 0  
fill ~32 ~5 ~56 ~33 ~5 ~56 stone 0  
fill ~33 ~5 ~22 ~33 ~6 ~22 planks 1  
fill ~33 ~5 ~23 ~33 ~3 ~23 planks 1  
fill ~33 ~5 ~24 ~33 ~3 ~24 planks 1  
fill ~33 ~5 ~25 ~33 ~3 ~25 planks 1  
fill ~33 ~5 ~26 ~33 ~3 ~26 planks 1  
fill ~33 ~5 ~27 ~33 ~6 ~27 planks 1  
fill ~33 ~5 ~45 ~33 ~6 ~45 cobblestone 0  
fill ~33 ~5 ~47 ~36 ~5 ~47 stone 0 
setblock ~33 ~5 ~57 stone_stairs 0  
fill ~34 ~5 ~7 ~38 ~5 ~7 stone 0 
setblock ~34 ~5 ~9 oak_stairs 3  
fill ~34 ~5 ~21 ~34 ~3 ~21 planks 1 
setblock ~34 ~5 ~24 glowstone 0  
fill ~34 ~5 ~28 ~34 ~3 ~28 planks 1  
fill ~34 ~5 ~40 ~35 ~5 ~40 double_stone_slab 0  
fill ~34 ~5 ~42 ~34 ~11 ~42 stonebrick 0  
fill ~34 ~5 ~46 ~35 ~5 ~46 planks 1  
fill ~34 ~5 ~52 ~37 ~5 ~52 cobblestone 0  
fill ~35 ~5 ~8 ~37 ~5 ~8 planks 1  
fill ~35 ~5 ~9 ~37 ~5 ~9 bookshelf 0 
