setblock ~16 ~28 ~12 chest 5  
setblock ~16 ~28 ~13 chest 5  
setblock ~16 ~21 ~24 chest 5  
setblock ~16 ~28 ~22 chest 5  
setblock ~16 ~28 ~23 chest 5  
setblock ~21 ~42 ~26 dropper 2  
setblock ~16 ~21 ~112 chest 5  
setblock ~16 ~28 ~113 chest 5  
setblock ~16 ~28 ~114 chest 5  
setblock ~16 ~28 ~123 chest 5  
setblock ~16 ~28 ~124 chest 5  
setblock ~16 ~42 ~114 chest 2  
setblock ~20 ~42 ~114 chest 2  
setblock ~20 ~42 ~125 chest 4  
setblock ~20 ~42 ~126 chest 4  
setblock ~26 ~21 ~9 chest 4  
setblock ~26 ~21 ~10 chest 4  
setblock ~28 ~21 ~12 chest 5  
setblock ~28 ~21 ~13 chest 5  
setblock ~28 ~42 ~13 dropper 2  
setblock ~31 ~28 ~12 chest 5  
setblock ~31 ~28 ~13 chest 5  
setblock ~37 ~21 ~9 chest 3  
setblock ~22 ~42 ~26 dropper 2  
setblock ~23 ~35 ~22 chest 3  
setblock ~23 ~42 ~26 dropper 2  
setblock ~24 ~35 ~22 chest 3  
setblock ~25 ~14 ~26 chest 2  
setblock ~26 ~14 ~26 chest 2  
setblock ~26 ~28 ~22 chest 4  
setblock ~26 ~28 ~23 chest 4  
setblock ~27 ~14 ~26 furnace 2  
setblock ~27 ~35 ~22 chest 3  
setblock ~28 ~14 ~26 chest 2  
setblock ~28 ~21 ~24 chest 5  
setblock ~28 ~35 ~22 chest 3  
setblock ~29 ~14 ~26 chest 2  
setblock ~30 ~35 ~22 chest 3  
setblock ~31 ~14 ~26 chest 2  
setblock ~31 ~35 ~22 chest 3  
setblock ~32 ~14 ~26 chest 2  
setblock ~33 ~35 ~22 chest 3  
setblock ~34 ~14 ~26 chest 2  
setblock ~34 ~35 ~22 chest 3  
setblock ~35 ~14 ~26 chest 2  
setblock ~35 ~21 ~26 chest 4  
setblock ~35 ~28 ~22 chest 4  
setblock ~35 ~28 ~23 chest 4  
setblock ~37 ~14 ~26 chest 2  
setblock ~37 ~28 ~25 chest 5  
setblock ~37 ~28 ~26 chest 5  
setblock ~37 ~42 ~22 dropper 3  
setblock ~25 ~14 ~110 chest 3  
setblock ~26 ~14 ~110 chest 3  
setblock ~26 ~28 ~113 chest 4  
setblock ~27 ~14 ~110 furnace 3  
setblock ~28 ~14 ~110 chest 3  
setblock ~28 ~21 ~112 chest 5  
setblock ~28 ~42 ~110 chest 5  
setblock ~28 ~42 ~112 chest 5  
setblock ~29 ~14 ~110 chest 3  
setblock ~22 ~42 ~123 chest 5  
setblock ~22 ~42 ~125 chest 5  
setblock ~23 ~35 ~114 chest 2  
setblock ~24 ~35 ~114 chest 2  
setblock ~26 ~28 ~114 chest 4  
setblock ~27 ~35 ~114 chest 2  
setblock ~28 ~21 ~123 chest 5  
setblock ~28 ~21 ~124 chest 5  
setblock ~28 ~35 ~114 chest 2  
setblock ~30 ~35 ~114 chest 2  
setblock ~31 ~14 ~110 chest 3  
setblock ~32 ~14 ~110 chest 3  
setblock ~34 ~14 ~110 chest 3  
setblock ~35 ~14 ~110 chest 3  
setblock ~35 ~21 ~110 chest 4  
setblock ~35 ~28 ~113 chest 4  
setblock ~37 ~14 ~110 chest 3  
setblock ~37 ~28 ~110 chest 5  
setblock ~37 ~28 ~111 chest 5  
setblock ~37 ~42 ~113 chest 5  
setblock ~31 ~28 ~123 chest 5  
setblock ~31 ~28 ~124 chest 5  
setblock ~31 ~35 ~114 chest 2  
setblock ~33 ~35 ~114 chest 2  
setblock ~34 ~35 ~114 chest 2  
setblock ~35 ~28 ~114 chest 4  
setblock ~37 ~42 ~114 chest 5  
setblock ~22 ~42 ~127 chest 5  
setblock ~26 ~21 ~126 chest 4  
setblock ~26 ~21 ~127 chest 4  
setblock ~37 ~21 ~127 chest 2  
setblock ~38 ~21 ~9 chest 3  
setblock ~38 ~42 ~13 dropper 2  
setblock ~44 ~21 ~12 chest 5  
setblock ~44 ~21 ~13 chest 5  
setblock ~51 ~14 ~9 chest 4  
setblock ~51 ~14 ~10 chest 4  
setblock ~51 ~28 ~9 chest 4  
setblock ~51 ~28 ~10 chest 4  
setblock ~51 ~35 ~9 chest 4  
setblock ~51 ~35 ~10 chest 4  
setblock ~51 ~42 ~9 chest 4  
setblock ~51 ~42 ~10 chest 4  
setblock ~53 ~21 ~12 chest 5  
setblock ~53 ~21 ~13 chest 5  
setblock ~38 ~14 ~26 chest 2  
setblock ~44 ~14 ~25 chest 5  
setblock ~44 ~14 ~26 chest 5  
setblock ~44 ~21 ~25 chest 5  
setblock ~44 ~21 ~26 chest 5  
setblock ~44 ~28 ~25 chest 5  
setblock ~44 ~28 ~26 chest 5  
setblock ~44 ~35 ~25 chest 5  
setblock ~44 ~35 ~26 chest 5  
setblock ~44 ~42 ~25 chest 5  
setblock ~44 ~42 ~26 chest 5  
setblock ~53 ~14 ~25 chest 5  
setblock ~53 ~14 ~26 chest 5  
setblock ~53 ~21 ~25 chest 5  
setblock ~53 ~21 ~26 chest 5  
setblock ~53 ~28 ~22 chest 5  
setblock ~53 ~28 ~23 chest 5  
setblock ~53 ~35 ~25 chest 5  
setblock ~53 ~35 ~26 chest 5  
setblock ~53 ~42 ~25 chest 5  
setblock ~53 ~42 ~26 chest 5  
setblock ~38 ~14 ~110 chest 3  
setblock ~44 ~14 ~110 chest 5  
setblock ~44 ~14 ~111 chest 5  
setblock ~44 ~21 ~110 chest 5  
setblock ~44 ~21 ~111 chest 5  
setblock ~44 ~28 ~110 chest 5  
setblock ~44 ~28 ~111 chest 5  
setblock ~44 ~35 ~110 chest 5  
setblock ~44 ~35 ~111 chest 5  
setblock ~44 ~42 ~110 chest 5  
setblock ~44 ~42 ~111 chest 5  
setblock ~44 ~21 ~123 chest 5  
setblock ~44 ~21 ~124 chest 5  
setblock ~53 ~0 ~110 furnace 3  
setblock ~53 ~0 ~112 furnace 5  
setblock ~53 ~14 ~110 chest 5  
setblock ~53 ~14 ~111 chest 5  
setblock ~53 ~21 ~110 chest 5  
setblock ~53 ~21 ~111 chest 5  
setblock ~53 ~28 ~113 chest 5  
setblock ~53 ~35 ~110 chest 5  
setblock ~53 ~35 ~111 chest 5  
setblock ~53 ~42 ~110 chest 5  
setblock ~53 ~42 ~111 chest 5  
setblock ~53 ~21 ~123 chest 5  
setblock ~53 ~21 ~124 chest 5  
setblock ~53 ~28 ~114 chest 5  
setblock ~38 ~21 ~127 chest 2  
setblock ~39 ~42 ~127 chest 2  
setblock ~40 ~42 ~127 chest 2  
setblock ~51 ~14 ~126 chest 4  
setblock ~51 ~14 ~127 chest 4  
setblock ~51 ~28 ~126 chest 4  
setblock ~51 ~28 ~127 chest 4  
setblock ~51 ~35 ~126 chest 4  
setblock ~51 ~35 ~127 chest 4  
setblock ~51 ~42 ~126 chest 4  
setblock ~51 ~42 ~127 chest 4  
setblock ~60 ~14 ~9 chest 4  
setblock ~60 ~14 ~10 chest 4  
setblock ~60 ~28 ~9 chest 4  
setblock ~60 ~28 ~10 chest 4  
setblock ~60 ~35 ~9 chest 4  
setblock ~60 ~35 ~10 chest 4  
setblock ~60 ~35 ~12 chest 4  
setblock ~60 ~35 ~13 chest 4  
setblock ~60 ~42 ~9 chest 4  
setblock ~60 ~42 ~10 chest 4  
setblock ~62 ~21 ~12 chest 5  
setblock ~62 ~21 ~13 chest 5  
setblock ~66 ~35 ~13 chest 2  
setblock ~67 ~35 ~13 chest 2  
setblock ~69 ~14 ~9 chest 4  
setblock ~69 ~14 ~10 chest 4  
setblock ~69 ~28 ~9 chest 4  
setblock ~69 ~28 ~10 chest 4  
setblock ~69 ~42 ~9 chest 4  
setblock ~69 ~42 ~10 chest 4  
setblock ~62 ~14 ~25 chest 5  
setblock ~62 ~14 ~26 chest 5  
setblock ~62 ~21 ~25 chest 5  
setblock ~62 ~21 ~26 chest 5  
setblock ~62 ~28 ~22 chest 5  
setblock ~62 ~28 ~23 chest 5  
setblock ~62 ~35 ~25 chest 5  
setblock ~62 ~35 ~26 chest 5  
setblock ~62 ~42 ~25 chest 5  
setblock ~62 ~42 ~26 chest 5  
setblock ~54 ~0 ~110 furnace 3  
setblock ~55 ~0 ~110 furnace 3  
setblock ~55 ~1 ~110 furnace 3  
setblock ~56 ~0 ~110 furnace 3  
setblock ~57 ~0 ~110 furnace 3  
setblock ~57 ~0 ~112 furnace 4  
setblock ~59 ~0 ~110 chest 3  
setblock ~59 ~0 ~112 chest 5  
setblock ~60 ~0 ~110 chest 3  
setblock ~61 ~1 ~110 chest 3  
setblock ~62 ~0 ~110 chest 3  
setblock ~62 ~14 ~110 chest 5  
setblock ~62 ~14 ~111 chest 5  
setblock ~62 ~21 ~110 chest 5  
setblock ~62 ~21 ~111 chest 5  
setblock ~62 ~28 ~113 chest 5  
setblock ~62 ~35 ~110 chest 5  
setblock ~62 ~35 ~111 chest 5  
setblock ~62 ~42 ~110 chest 5  
setblock ~62 ~42 ~111 chest 5  
setblock ~60 ~35 ~123 chest 4  
setblock ~60 ~35 ~124 chest 4  
setblock ~62 ~21 ~123 chest 5  
setblock ~62 ~21 ~124 chest 5  
setblock ~62 ~28 ~114 chest 5  
setblock ~63 ~0 ~110 chest 3  
setblock ~63 ~0 ~112 chest 4  
setblock ~66 ~35 ~123 chest 3  
setblock ~67 ~35 ~123 chest 3  
setblock ~60 ~14 ~126 chest 4  
setblock ~60 ~14 ~127 chest 4  
setblock ~60 ~28 ~126 chest 4  
setblock ~60 ~28 ~127 chest 4  
setblock ~60 ~35 ~126 chest 4  
setblock ~60 ~35 ~127 chest 4  
setblock ~60 ~42 ~126 chest 4  
setblock ~60 ~42 ~127 chest 4  
setblock ~69 ~14 ~126 chest 4  
setblock ~69 ~14 ~127 chest 4  
setblock ~69 ~28 ~126 chest 4  
setblock ~69 ~28 ~127 chest 4  
setblock ~69 ~42 ~126 chest 4  
setblock ~69 ~42 ~127 chest 4  
setblock ~71 ~21 ~12 chest 5  
setblock ~71 ~21 ~13 chest 5  
setblock ~77 ~35 ~13 chest 2  
setblock ~78 ~14 ~9 chest 4  
setblock ~78 ~14 ~10 chest 4  
setblock ~78 ~28 ~12 chest 4  
setblock ~78 ~28 ~13 chest 4  
setblock ~78 ~35 ~9 chest 4  
setblock ~78 ~35 ~10 chest 4  
setblock ~78 ~35 ~13 chest 2  
setblock ~78 ~42 ~9 chest 4  
setblock ~78 ~42 ~10 chest 4  
setblock ~80 ~21 ~12 chest 5  
setblock ~80 ~21 ~13 chest 5  
setblock ~71 ~29 ~24 lit_furnace 5  
setblock ~71 ~29 ~26 lit_furnace 5  
setblock ~71 ~31 ~25 chest 5  
setblock ~71 ~42 ~23 chest 5  
setblock ~71 ~42 ~24 chest 5  
setblock ~71 ~42 ~27 chest 5  
setblock ~71 ~42 ~28 chest 5  
setblock ~72 ~29 ~22 furnace 3  
setblock ~72 ~42 ~29 chest 2  
setblock ~73 ~42 ~29 chest 2  
setblock ~74 ~29 ~22 chest 3  
setblock ~74 ~31 ~22 chest 3  
setblock ~75 ~31 ~22 chest 3  
setblock ~76 ~35 ~29 chest 3  
setblock ~76 ~42 ~29 chest 2  
setblock ~77 ~35 ~29 chest 3  
setblock ~77 ~42 ~29 chest 2  
setblock ~83 ~21 ~25 chest 5  
setblock ~83 ~21 ~26 chest 5  
setblock ~71 ~21 ~33 furnace 5  
setblock ~71 ~42 ~32 chest 5  
setblock ~71 ~42 ~33 chest 5  
setblock ~74 ~21 ~33 chest 4  
setblock ~71 ~42 ~36 chest 5  
setblock ~71 ~42 ~37 chest 5  
setblock ~76 ~35 ~34 chest 2  
setblock ~77 ~35 ~34 chest 2  
setblock ~82 ~14 ~30 chest 2  
setblock ~82 ~28 ~32 chest 4  
setblock ~83 ~14 ~30 chest 2  
setblock ~71 ~21 ~103 furnace 5  
setblock ~71 ~42 ~99 chest 5  
setblock ~71 ~42 ~100 chest 5  
setblock ~71 ~42 ~103 chest 5  
setblock ~71 ~42 ~104 chest 5  
setblock ~71 ~42 ~108 chest 5  
setblock ~71 ~42 ~109 chest 5  
setblock ~72 ~42 ~107 chest 3  
setblock ~73 ~42 ~107 chest 3  
setblock ~74 ~21 ~103 chest 4  
setblock ~76 ~35 ~102 chest 3  
setblock ~76 ~35 ~107 chest 2  
setblock ~76 ~42 ~107 chest 3  
setblock ~77 ~35 ~102 chest 3  
setblock ~77 ~35 ~107 chest 2  
setblock ~77 ~42 ~107 chest 3  
setblock ~82 ~14 ~106 chest 3  
setblock ~82 ~28 ~104 chest 4  
setblock ~83 ~14 ~106 chest 3  
setblock ~71 ~29 ~110 lit_furnace 5  
setblock ~71 ~29 ~112 lit_furnace 5  
setblock ~71 ~31 ~111 chest 5  
setblock ~71 ~42 ~112 chest 5  
setblock ~71 ~42 ~113 chest 5  
setblock ~71 ~21 ~123 chest 5  
setblock ~71 ~21 ~124 chest 5  
setblock ~72 ~29 ~114 furnace 2  
setblock ~74 ~29 ~114 chest 2  
setblock ~74 ~31 ~114 chest 2  
setblock ~75 ~31 ~114 chest 2  
setblock ~77 ~35 ~123 chest 3  
setblock ~78 ~28 ~123 chest 4  
setblock ~78 ~28 ~124 chest 4  
setblock ~78 ~35 ~123 chest 3  
setblock ~83 ~21 ~110 chest 5  
setblock ~83 ~21 ~111 chest 5  
setblock ~80 ~21 ~123 chest 5  
setblock ~80 ~21 ~124 chest 5  
setblock ~77 ~0 ~127 chest 2  
setblock ~78 ~0 ~127 chest 2  
setblock ~78 ~14 ~126 chest 4  
setblock ~78 ~14 ~127 chest 4  
setblock ~78 ~35 ~126 chest 4  
setblock ~78 ~35 ~127 chest 4  
setblock ~78 ~42 ~126 chest 4  
setblock ~78 ~42 ~127 chest 4  
setblock ~80 ~0 ~127 chest 2  
setblock ~81 ~0 ~127 chest 2  
setblock ~87 ~14 ~9 chest 4  
setblock ~87 ~14 ~10 chest 4  
setblock ~87 ~28 ~9 chest 4  
setblock ~87 ~28 ~10 chest 4  
setblock ~87 ~35 ~9 chest 4  
setblock ~87 ~35 ~10 chest 4  
setblock ~87 ~42 ~9 chest 4  
setblock ~87 ~42 ~10 chest 4  
setblock ~89 ~28 ~12 chest 5  
setblock ~89 ~28 ~13 chest 5  
setblock ~91 ~35 ~9 chest 3  
setblock ~92 ~35 ~9 chest 3  
setblock ~93 ~42 ~12 chest 4  
setblock ~93 ~42 ~13 chest 4  
setblock ~94 ~35 ~9 chest 3  
setblock ~95 ~21 ~9 chest 3  
setblock ~95 ~35 ~9 chest 3  
setblock ~98 ~14 ~9 chest 4  
setblock ~98 ~14 ~10 chest 4  
setblock ~98 ~35 ~9 chest 4  
setblock ~98 ~35 ~10 chest 4  
setblock ~87 ~35 ~22 chest 4  
setblock ~87 ~35 ~23 chest 4  
setblock ~87 ~35 ~26 chest 4  
setblock ~87 ~35 ~27 chest 4  
setblock ~87 ~35 ~29 chest 4  
setblock ~93 ~28 ~22 chest 4  
setblock ~93 ~28 ~23 chest 4  
setblock ~98 ~21 ~15 chest 4  
setblock ~98 ~21 ~16 chest 4  
setblock ~98 ~42 ~22 chest 4  
setblock ~98 ~42 ~23 chest 4  
setblock ~98 ~42 ~28 chest 4  
setblock ~98 ~42 ~29 chest 4  
setblock ~87 ~35 ~30 chest 4  
setblock ~87 ~35 ~33 chest 4  
setblock ~89 ~14 ~30 chest 2  
setblock ~89 ~42 ~32 furnace 5  
setblock ~89 ~43 ~31 chest 5  
setblock ~89 ~43 ~32 chest 5  
setblock ~90 ~14 ~30 chest 2  
setblock ~87 ~35 ~34 chest 4  
setblock ~89 ~35 ~38 chest 2  
setblock ~90 ~35 ~38 chest 2  
setblock ~92 ~35 ~35 furnace 2  
setblock ~96 ~14 ~30 chest 2  
setblock ~97 ~14 ~30 chest 2  
setblock ~98 ~42 ~31 chest 4  
setblock ~98 ~42 ~32 chest 4  
setblock ~95 ~35 ~35 furnace 2  
setblock ~97 ~35 ~38 chest 2  
setblock ~98 ~35 ~38 chest 2  
setblock ~98 ~42 ~37 chest 4  
setblock ~98 ~42 ~38 chest 4  
setblock ~87 ~35 ~102 chest 4  
setblock ~87 ~35 ~103 chest 4  
setblock ~87 ~35 ~106 chest 4  
setblock ~87 ~35 ~107 chest 4  
setblock ~87 ~35 ~109 chest 4  
setblock ~89 ~14 ~106 chest 3  
setblock ~89 ~35 ~98 chest 3  
setblock ~89 ~42 ~104 furnace 5  
setblock ~89 ~43 ~104 chest 5  
setblock ~89 ~43 ~105 chest 5  
setblock ~90 ~14 ~106 chest 3  
setblock ~90 ~35 ~98 chest 3  
setblock ~92 ~35 ~101 furnace 3  
setblock ~95 ~35 ~101 furnace 3  
setblock ~96 ~14 ~106 chest 3  
setblock ~97 ~14 ~106 chest 3  
setblock ~97 ~35 ~98 chest 3  
setblock ~98 ~35 ~98 chest 3  
setblock ~98 ~42 ~98 chest 4  
setblock ~98 ~42 ~99 chest 4  
setblock ~98 ~42 ~104 chest 4  
setblock ~98 ~42 ~105 chest 4  
setblock ~98 ~42 ~107 chest 4  
setblock ~98 ~42 ~108 chest 4  
setblock ~87 ~35 ~110 chest 4  
setblock ~87 ~35 ~113 chest 4  
setblock ~93 ~28 ~113 chest 4  
setblock ~87 ~35 ~114 chest 4  
setblock ~89 ~28 ~123 chest 5  
setblock ~89 ~28 ~124 chest 5  
setblock ~93 ~28 ~114 chest 4  
setblock ~93 ~42 ~123 chest 4  
setblock ~93 ~42 ~124 chest 4  
setblock ~98 ~0 ~112 furnace 4  
setblock ~98 ~42 ~113 chest 4  
setblock ~98 ~0 ~114 furnace 4  
setblock ~98 ~0 ~115 furnace 4  
setblock ~98 ~0 ~117 furnace 4  
setblock ~98 ~0 ~118 furnace 4  
setblock ~98 ~0 ~120 furnace 4  
setblock ~98 ~1 ~114 furnace 4  
setblock ~98 ~1 ~117 furnace 4  
setblock ~98 ~21 ~120 chest 4  
setblock ~98 ~21 ~121 chest 4  
setblock ~98 ~42 ~114 chest 4  
setblock ~87 ~14 ~126 chest 4  
setblock ~87 ~14 ~127 chest 4  
setblock ~87 ~28 ~126 chest 4  
setblock ~87 ~28 ~127 chest 4  
setblock ~87 ~35 ~126 chest 4  
setblock ~87 ~35 ~127 chest 4  
setblock ~87 ~42 ~126 chest 4  
setblock ~87 ~42 ~127 chest 4  
setblock ~88 ~0 ~127 furnace 2  
setblock ~89 ~0 ~127 furnace 2  
setblock ~90 ~0 ~127 furnace 2  
setblock ~91 ~35 ~127 chest 2  
setblock ~92 ~35 ~127 chest 2  
setblock ~94 ~35 ~127 chest 2  
setblock ~95 ~21 ~127 chest 2  
setblock ~95 ~35 ~127 chest 2  
setblock ~98 ~14 ~126 chest 4  
setblock ~98 ~14 ~127 chest 4  
setblock ~98 ~35 ~126 chest 4  
setblock ~98 ~35 ~127 chest 4  
fill ~1 ~-2 ~1 ~32 ~-2 ~1 dirt 0  
fill ~1 ~-2 ~2 ~106 ~-2 ~2 dirt 0  
fill ~1 ~-2 ~3 ~106 ~-2 ~3 dirt 0  
fill ~1 ~-2 ~4 ~106 ~-2 ~4 dirt 0  
fill ~1 ~-2 ~5 ~106 ~-2 ~5 dirt 0  
fill ~1 ~-2 ~6 ~106 ~-2 ~6 dirt 0  
fill ~1 ~-2 ~7 ~44 ~-2 ~7 dirt 0  
fill ~1 ~-2 ~8 ~106 ~-2 ~8 dirt 0  
fill ~1 ~-2 ~9 ~106 ~-2 ~9 dirt 0  
fill ~1 ~-2 ~10 ~99 ~-2 ~10 dirt 0  
fill ~1 ~-2 ~11 ~106 ~-2 ~11 dirt 0  
fill ~1 ~-2 ~12 ~106 ~-2 ~12 dirt 0  
fill ~1 ~-2 ~13 ~47 ~-2 ~13 dirt 0  
fill ~1 ~-2 ~14 ~47 ~-2 ~14 dirt 0  
fill ~1 ~-2 ~15 ~47 ~-2 ~15 dirt 0  
fill ~1 ~-2 ~16 ~47 ~-2 ~16 dirt 0  
fill ~1 ~-2 ~17 ~47 ~-2 ~17 dirt 0  
fill ~1 ~-2 ~18 ~47 ~-2 ~18 dirt 0  
fill ~1 ~-2 ~19 ~47 ~-2 ~19 dirt 0  
fill ~1 ~-2 ~20 ~47 ~-2 ~20 dirt 0  
fill ~1 ~-2 ~21 ~47 ~-2 ~21 dirt 0  
fill ~1 ~-2 ~22 ~9 ~-2 ~22 dirt 0  
fill ~1 ~-2 ~23 ~106 ~-2 ~23 dirt 0  
fill ~1 ~-2 ~24 ~106 ~-2 ~24 dirt 0  
fill ~1 ~-2 ~25 ~106 ~-2 ~25 dirt 0  
fill ~1 ~-2 ~26 ~106 ~-2 ~26 dirt 0  
fill ~1 ~-2 ~27 ~106 ~-2 ~27 dirt 0  
fill ~1 ~-2 ~28 ~106 ~-2 ~28 dirt 0  
fill ~1 ~-2 ~29 ~106 ~-2 ~29 dirt 0  
fill ~1 ~-2 ~30 ~106 ~-2 ~30 dirt 0  
fill ~1 ~-2 ~31 ~17 ~-2 ~31 dirt 0  
fill ~1 ~-2 ~32 ~17 ~-2 ~32 dirt 0  
fill ~1 ~-2 ~33 ~17 ~-2 ~33 dirt 0  
fill ~1 ~-2 ~34 ~17 ~-2 ~34 dirt 0  
fill ~1 ~-2 ~35 ~17 ~-2 ~35 dirt 0  
fill ~1 ~-2 ~36 ~17 ~-2 ~36 dirt 0  
fill ~1 ~-2 ~37 ~17 ~-2 ~37 dirt 0  
fill ~1 ~-2 ~38 ~17 ~-2 ~38 dirt 0  
fill ~1 ~-2 ~39 ~17 ~-2 ~39 dirt 0  
fill ~1 ~-2 ~40 ~17 ~-2 ~40 dirt 0  
fill ~1 ~-2 ~41 ~17 ~-2 ~41 dirt 0  
fill ~1 ~-2 ~42 ~17 ~-2 ~42 dirt 0  
fill ~1 ~-2 ~43 ~17 ~-2 ~43 dirt 0  
fill ~1 ~-2 ~44 ~17 ~-2 ~44 dirt 0  
fill ~1 ~-2 ~45 ~17 ~-2 ~45 dirt 0  
fill ~1 ~-2 ~46 ~17 ~-2 ~46 dirt 0  
fill ~1 ~-2 ~47 ~17 ~-2 ~47 dirt 0  
fill ~1 ~-2 ~48 ~9 ~-2 ~48 dirt 0  
fill ~1 ~-2 ~49 ~17 ~-2 ~49 dirt 0  
fill ~1 ~-2 ~50 ~17 ~-2 ~50 dirt 0  
fill ~1 ~-2 ~51 ~74 ~-2 ~51 dirt 0  
fill ~1 ~-2 ~52 ~83 ~-2 ~52 dirt 0  
fill ~1 ~-2 ~53 ~73 ~-2 ~53 dirt 0  
fill ~1 ~-2 ~54 ~83 ~-2 ~54 dirt 0  
fill ~1 ~-2 ~55 ~72 ~-2 ~55 dirt 0  
fill ~1 ~-2 ~56 ~71 ~-2 ~56 dirt 0  
fill ~1 ~-2 ~57 ~72 ~-2 ~57 dirt 0  
fill ~1 ~-2 ~58 ~62 ~-2 ~58 dirt 0  
fill ~1 ~-2 ~59 ~62 ~-2 ~59 dirt 0  
fill ~1 ~-2 ~60 ~62 ~-2 ~60 dirt 0  
fill ~1 ~-2 ~61 ~62 ~-2 ~61 dirt 0  
fill ~1 ~-2 ~62 ~19 ~-2 ~62 dirt 0  
fill ~1 ~-2 ~63 ~19 ~-2 ~63 dirt 0  
fill ~1 ~-2 ~64 ~62 ~-2 ~64 dirt 0  
fill ~1 ~-2 ~65 ~62 ~-2 ~65 dirt 0  
fill ~1 ~-2 ~66 ~83 ~-2 ~66 dirt 0  
fill ~1 ~-2 ~67 ~106 ~-2 ~67 dirt 0  
fill ~1 ~-2 ~68 ~39 ~-2 ~68 dirt 0  
fill ~1 ~-2 ~69 ~15 ~-2 ~69 dirt 0  
fill ~1 ~-2 ~70 ~83 ~-2 ~70 dirt 0  
fill ~1 ~-2 ~71 ~62 ~-2 ~71 dirt 0  
fill ~1 ~-2 ~72 ~62 ~-2 ~72 dirt 0  
fill ~1 ~-2 ~73 ~19 ~-2 ~73 dirt 0  
fill ~1 ~-2 ~74 ~34 ~-2 ~74 dirt 0  
fill ~1 ~-2 ~75 ~34 ~-2 ~75 dirt 0  
fill ~1 ~-2 ~76 ~34 ~-2 ~76 dirt 0  
fill ~1 ~-2 ~77 ~34 ~-2 ~77 dirt 0  
fill ~1 ~-2 ~78 ~34 ~-2 ~78 dirt 0  
fill ~1 ~-2 ~79 ~34 ~-2 ~79 dirt 0  
fill ~1 ~-2 ~80 ~34 ~-2 ~80 dirt 0  
fill ~1 ~-2 ~81 ~34 ~-2 ~81 dirt 0  
fill ~1 ~-2 ~82 ~34 ~-2 ~82 dirt 0  
fill ~1 ~-2 ~83 ~34 ~-2 ~83 dirt 0  
fill ~1 ~-2 ~84 ~83 ~-2 ~84 dirt 0  
fill ~1 ~-2 ~85 ~74 ~-2 ~85 dirt 0  
fill ~1 ~-2 ~86 ~17 ~-2 ~86 dirt 0  
fill ~1 ~-2 ~87 ~17 ~-2 ~87 dirt 0  
fill ~1 ~-2 ~88 ~17 ~-2 ~88 dirt 0  
fill ~1 ~-2 ~89 ~17 ~-2 ~89 dirt 0  
fill ~1 ~-2 ~90 ~17 ~-2 ~90 dirt 0  
fill ~1 ~-2 ~91 ~17 ~-2 ~91 dirt 0  
fill ~1 ~-2 ~92 ~17 ~-2 ~92 dirt 0  
fill ~1 ~-2 ~93 ~17 ~-2 ~93 dirt 0  
fill ~1 ~-2 ~94 ~17 ~-2 ~94 dirt 0  
fill ~1 ~-2 ~95 ~17 ~-2 ~95 dirt 0  
fill ~1 ~-2 ~96 ~17 ~-2 ~96 dirt 0  
fill ~1 ~-2 ~97 ~17 ~-2 ~97 dirt 0  
fill ~1 ~-2 ~98 ~17 ~-2 ~98 dirt 0  
fill ~1 ~-2 ~99 ~17 ~-2 ~99 dirt 0  
fill ~1 ~-2 ~100 ~17 ~-2 ~100 dirt 0  
fill ~1 ~-2 ~101 ~17 ~-2 ~101 dirt 0  
fill ~1 ~-2 ~102 ~17 ~-2 ~102 dirt 0  
fill ~1 ~-2 ~103 ~17 ~-2 ~103 dirt 0  
fill ~1 ~-2 ~104 ~17 ~-2 ~104 dirt 0  
fill ~1 ~-2 ~105 ~17 ~-2 ~105 dirt 0  
fill ~1 ~-2 ~106 ~70 ~-2 ~106 dirt 0  
fill ~1 ~-2 ~107 ~70 ~-2 ~107 dirt 0  
fill ~1 ~-2 ~108 ~70 ~-2 ~108 dirt 0  
fill ~1 ~-2 ~109 ~70 ~-2 ~109 dirt 0  
fill ~1 ~-2 ~110 ~38 ~-2 ~110 dirt 0  
fill ~1 ~-2 ~111 ~38 ~-2 ~111 dirt 0  
fill ~1 ~-2 ~112 ~43 ~-2 ~112 dirt 0  
fill ~1 ~-2 ~113 ~43 ~-2 ~113 dirt 0  
fill ~1 ~-2 ~114 ~43 ~-2 ~114 dirt 0  
fill ~1 ~-2 ~115 ~43 ~-2 ~115 dirt 0  
fill ~1 ~-2 ~116 ~15 ~-2 ~116 dirt 0  
fill ~1 ~-2 ~117 ~15 ~-2 ~117 dirt 0  
fill ~1 ~-2 ~118 ~15 ~-2 ~118 dirt 0  
fill ~1 ~-2 ~119 ~15 ~-2 ~119 dirt 0  
fill ~1 ~-2 ~120 ~15 ~-2 ~120 dirt 0  
fill ~1 ~-2 ~121 ~15 ~-2 ~121 dirt 0  
fill ~1 ~-2 ~122 ~43 ~-2 ~122 dirt 0  
fill ~1 ~-2 ~123 ~43 ~-2 ~123 dirt 0  
fill ~1 ~-2 ~124 ~43 ~-2 ~124 dirt 0  
fill ~1 ~-2 ~125 ~43 ~-2 ~125 dirt 0  
fill ~1 ~-2 ~126 ~38 ~-2 ~126 dirt 0  
fill ~1 ~-2 ~127 ~38 ~-2 ~127 dirt 0  
fill ~1 ~-2 ~128 ~106 ~-2 ~128 dirt 0 
setblock ~10 ~-2 ~22 grass 0 
setblock ~10 ~-2 ~48 grass 0  
fill ~11 ~-2 ~22 ~47 ~-2 ~22 dirt 0  
fill ~11 ~-2 ~48 ~17 ~-2 ~48 dirt 0  
fill ~16 ~-2 ~69 ~16 ~1 ~69 sandstone 2  
fill ~16 ~-2 ~116 ~42 ~-2 ~116 grass 0  
fill ~16 ~-2 ~117 ~42 ~-2 ~117 grass 0  
fill ~16 ~-2 ~118 ~70 ~-2 ~118 grass 0  
fill ~16 ~-2 ~119 ~70 ~-2 ~119 grass 0  
fill ~16 ~-2 ~120 ~42 ~-2 ~120 grass 0  
fill ~16 ~-2 ~121 ~42 ~-2 ~121 grass 0  
fill ~17 ~-2 ~69 ~106 ~-2 ~69 dirt 0 
setblock ~18 ~-2 ~31 glowstone 0  
fill ~18 ~-2 ~32 ~38 ~-2 ~32 iron_block 0  
fill ~18 ~-2 ~33 ~38 ~-2 ~33 iron_block 0  
fill ~18 ~-2 ~34 ~38 ~-2 ~34 iron_block 0  
fill ~18 ~-2 ~35 ~38 ~-2 ~35 iron_block 0  
fill ~18 ~-2 ~36 ~38 ~-2 ~36 iron_block 0  
fill ~18 ~-2 ~37 ~38 ~-2 ~37 iron_block 0  
fill ~18 ~-2 ~38 ~38 ~-2 ~38 iron_block 0  
fill ~18 ~-2 ~39 ~38 ~-2 ~39 iron_block 0  
fill ~18 ~-2 ~40 ~38 ~-2 ~40 iron_block 0  
fill ~18 ~-2 ~41 ~38 ~-2 ~41 iron_block 0  
fill ~18 ~-2 ~42 ~38 ~-2 ~42 iron_block 0  
fill ~18 ~-2 ~43 ~38 ~-2 ~43 iron_block 0  
fill ~18 ~-2 ~44 ~38 ~-2 ~44 iron_block 0  
fill ~18 ~-2 ~45 ~38 ~-2 ~45 iron_block 0  
fill ~18 ~-2 ~46 ~38 ~-2 ~46 iron_block 0  
fill ~18 ~-2 ~47 ~38 ~-2 ~47 iron_block 0  
fill ~18 ~-2 ~48 ~38 ~-2 ~48 iron_block 0  
fill ~18 ~-2 ~49 ~38 ~-2 ~49 iron_block 0 
setblock ~18 ~-2 ~50 glowstone 0 
setblock ~18 ~-2 ~86 glowstone 0  
fill ~18 ~-2 ~87 ~38 ~-2 ~87 iron_block 0  
fill ~18 ~-2 ~88 ~38 ~-2 ~88 iron_block 0  
fill ~18 ~-2 ~89 ~38 ~-2 ~89 iron_block 0  
fill ~18 ~-2 ~90 ~38 ~-2 ~90 iron_block 0  
fill ~18 ~-2 ~91 ~38 ~-2 ~91 iron_block 0  
fill ~18 ~-2 ~92 ~38 ~-2 ~92 iron_block 0  
fill ~18 ~-2 ~93 ~38 ~-2 ~93 iron_block 0  
fill ~18 ~-2 ~94 ~38 ~-2 ~94 iron_block 0  
fill ~18 ~-2 ~95 ~38 ~-2 ~95 iron_block 0  
fill ~18 ~-2 ~96 ~38 ~-2 ~96 iron_block 0  
fill ~18 ~-2 ~97 ~38 ~-2 ~97 iron_block 0  
fill ~18 ~-2 ~98 ~38 ~-2 ~98 iron_block 0  
fill ~18 ~-2 ~99 ~38 ~-2 ~99 iron_block 0  
fill ~18 ~-2 ~100 ~38 ~-2 ~100 iron_block 0  
fill ~18 ~-2 ~101 ~38 ~-2 ~101 iron_block 0  
fill ~18 ~-2 ~102 ~38 ~-2 ~102 iron_block 0  
fill ~18 ~-2 ~103 ~38 ~-2 ~103 iron_block 0  
fill ~18 ~-2 ~104 ~38 ~-2 ~104 iron_block 0 
setblock ~18 ~-2 ~105 glowstone 0  
fill ~19 ~-2 ~31 ~37 ~-2 ~31 iron_block 0  
fill ~19 ~-2 ~50 ~37 ~-2 ~50 iron_block 0  
fill ~19 ~-2 ~86 ~37 ~-2 ~86 iron_block 0  
fill ~19 ~-2 ~105 ~37 ~-2 ~105 iron_block 0  
fill ~20 ~-2 ~62 ~20 ~-2 ~63 grass 0 
setblock ~20 ~-2 ~73 grass 0  
fill ~21 ~-2 ~62 ~62 ~-2 ~62 dirt 0  
fill ~21 ~-2 ~63 ~62 ~-2 ~63 dirt 0  
fill ~21 ~-2 ~73 ~62 ~-2 ~73 dirt 0 
setblock ~33 ~-2 ~1 grass 0  
fill ~34 ~-2 ~1 ~44 ~-2 ~1 dirt 0  
fill ~35 ~-2 ~74 ~35 ~-2 ~83 grass 0  
fill ~36 ~-2 ~74 ~62 ~-2 ~74 dirt 0  
fill ~36 ~-2 ~75 ~62 ~-2 ~75 dirt 0  
fill ~36 ~-2 ~76 ~62 ~-2 ~76 dirt 0  
fill ~36 ~-2 ~77 ~62 ~-2 ~77 dirt 0  
fill ~36 ~-2 ~78 ~62 ~-2 ~78 dirt 0  
fill ~36 ~-2 ~79 ~72 ~-2 ~79 dirt 0  
fill ~36 ~-2 ~80 ~83 ~-2 ~80 dirt 0  
fill ~36 ~-2 ~81 ~72 ~-2 ~81 dirt 0  
fill ~36 ~-2 ~82 ~83 ~-2 ~82 dirt 0  
fill ~36 ~-2 ~83 ~73 ~-2 ~83 dirt 0 
setblock ~38 ~-2 ~31 glowstone 0 
setblock ~38 ~-2 ~50 glowstone 0 
setblock ~38 ~-2 ~86 glowstone 0 
setblock ~38 ~-2 ~105 glowstone 0  
fill ~39 ~-2 ~31 ~45 ~-2 ~31 dirt 0  
fill ~39 ~-2 ~32 ~45 ~-2 ~32 dirt 0  
fill ~39 ~-2 ~33 ~45 ~-2 ~33 dirt 0  
fill ~39 ~-2 ~34 ~45 ~-2 ~34 dirt 0  
fill ~39 ~-2 ~35 ~45 ~-2 ~35 dirt 0  
fill ~39 ~-2 ~36 ~45 ~-2 ~36 dirt 0  
fill ~39 ~-2 ~37 ~45 ~-2 ~37 dirt 0  
fill ~39 ~-2 ~38 ~45 ~-2 ~38 dirt 0  
fill ~39 ~-2 ~39 ~45 ~-2 ~39 dirt 0  
fill ~39 ~-2 ~40 ~45 ~-2 ~40 dirt 0  
fill ~39 ~-2 ~41 ~45 ~-2 ~41 dirt 0  
fill ~39 ~-2 ~42 ~45 ~-2 ~42 dirt 0  
fill ~39 ~-2 ~43 ~45 ~-2 ~43 dirt 0  
fill ~39 ~-2 ~44 ~45 ~-2 ~44 dirt 0  
fill ~39 ~-2 ~45 ~45 ~-2 ~45 dirt 0  
fill ~39 ~-2 ~46 ~45 ~-2 ~46 dirt 0  
fill ~39 ~-2 ~47 ~45 ~-2 ~47 dirt 0  
fill ~39 ~-2 ~48 ~45 ~-2 ~48 dirt 0  
fill ~39 ~-2 ~49 ~45 ~-2 ~49 dirt 0  
fill ~39 ~-2 ~50 ~45 ~-2 ~50 dirt 0  
fill ~39 ~-2 ~86 ~45 ~-2 ~86 dirt 0  
fill ~39 ~-2 ~87 ~45 ~-2 ~87 dirt 0  
fill ~39 ~-2 ~88 ~45 ~-2 ~88 dirt 0  
fill ~39 ~-2 ~89 ~45 ~-2 ~89 dirt 0  
fill ~39 ~-2 ~90 ~45 ~-2 ~90 dirt 0  
fill ~39 ~-2 ~91 ~45 ~-2 ~91 dirt 0  
fill ~39 ~-2 ~92 ~45 ~-2 ~92 dirt 0  
fill ~39 ~-2 ~93 ~45 ~-2 ~93 dirt 0  
fill ~39 ~-2 ~94 ~45 ~-2 ~94 dirt 0  
fill ~39 ~-2 ~95 ~45 ~-2 ~95 dirt 0  
fill ~39 ~-2 ~96 ~45 ~-2 ~96 dirt 0  
fill ~39 ~-2 ~97 ~45 ~-2 ~97 dirt 0  
fill ~39 ~-2 ~98 ~45 ~-2 ~98 dirt 0  
fill ~39 ~-2 ~99 ~45 ~-2 ~99 dirt 0  
fill ~39 ~-2 ~100 ~45 ~-2 ~100 dirt 0  
fill ~39 ~-2 ~101 ~45 ~-2 ~101 dirt 0  
fill ~39 ~-2 ~102 ~45 ~-2 ~102 dirt 0  
fill ~39 ~-2 ~103 ~45 ~-2 ~103 dirt 0  
fill ~39 ~-2 ~104 ~45 ~-2 ~104 dirt 0  
fill ~39 ~-2 ~105 ~45 ~-2 ~105 dirt 0  
fill ~39 ~-2 ~110 ~42 ~-2 ~110 grass 0  
fill ~39 ~-2 ~111 ~39 ~-2 ~110 grass 0  
fill ~39 ~-2 ~126 ~39 ~-2 ~127 grass 0 
setblock ~40 ~-2 ~68 sandstone 2  
fill ~40 ~-2 ~111 ~43 ~-2 ~111 dirt 0  
fill ~40 ~-2 ~126 ~43 ~-2 ~126 dirt 0  
fill ~40 ~-2 ~127 ~42 ~-2 ~127 grass 0  
fill ~41 ~-2 ~68 ~45 ~-2 ~68 dirt 0 
setblock ~43 ~-2 ~110 dirt 0  
fill ~43 ~-2 ~116 ~43 ~-2 ~117 dirt 0  
fill ~43 ~-2 ~120 ~43 ~-2 ~128 dirt 0  
fill ~44 ~-2 ~110 ~71 ~-2 ~110 grass 0  
fill ~44 ~-2 ~111 ~44 ~-2 ~127 grass 0 
setblock ~45 ~-2 ~1 grass 0 
setblock ~45 ~-2 ~7 grass 0  
fill ~45 ~-2 ~111 ~48 ~-2 ~111 dirt 0  
fill ~45 ~-2 ~112 ~97 ~-2 ~112 dirt 0  
fill ~45 ~-2 ~113 ~81 ~-2 ~113 dirt 0  
fill ~45 ~-2 ~114 ~94 ~-2 ~114 dirt 0  
fill ~45 ~-2 ~115 ~97 ~-2 ~115 dirt 0  
fill ~45 ~-2 ~116 ~47 ~-2 ~116 dirt 0  
fill ~45 ~-2 ~117 ~47 ~-2 ~117 dirt 0  
fill ~45 ~-2 ~120 ~47 ~-2 ~120 dirt 0  
fill ~45 ~-2 ~121 ~47 ~-2 ~121 dirt 0  
fill ~45 ~-2 ~122 ~97 ~-2 ~122 dirt 0  
fill ~45 ~-2 ~123 ~96 ~-2 ~123 dirt 0  
fill ~45 ~-2 ~124 ~97 ~-2 ~124 dirt 0  
fill ~45 ~-2 ~125 ~97 ~-2 ~125 dirt 0  
fill ~45 ~-2 ~126 ~48 ~-2 ~126 dirt 0  
fill ~45 ~-2 ~127 ~98 ~-2 ~127 grass 0  
fill ~46 ~-2 ~1 ~96 ~-2 ~1 dirt 0  
fill ~46 ~-2 ~7 ~106 ~-2 ~7 dirt 0 
setblock ~46 ~-2 ~31 glowstone 0  
fill ~46 ~-2 ~32 ~66 ~-2 ~32 double_stone_slab 0  
fill ~46 ~-2 ~33 ~66 ~-2 ~33 double_stone_slab 0  
fill ~46 ~-2 ~34 ~66 ~-2 ~34 double_stone_slab 0  
fill ~46 ~-2 ~35 ~66 ~-2 ~35 double_stone_slab 0  
fill ~46 ~-2 ~36 ~66 ~-2 ~36 double_stone_slab 0  
fill ~46 ~-2 ~37 ~66 ~-2 ~37 double_stone_slab 0  
fill ~46 ~-2 ~38 ~66 ~-2 ~38 double_stone_slab 0  
fill ~46 ~-2 ~39 ~66 ~-2 ~39 double_stone_slab 0  
fill ~46 ~-2 ~40 ~66 ~-2 ~40 double_stone_slab 0  
fill ~46 ~-2 ~41 ~66 ~-2 ~41 double_stone_slab 0  
fill ~46 ~-2 ~42 ~66 ~-2 ~42 double_stone_slab 0  
fill ~46 ~-2 ~43 ~66 ~-2 ~43 double_stone_slab 0  
fill ~46 ~-2 ~44 ~66 ~-2 ~44 double_stone_slab 0  
fill ~46 ~-2 ~45 ~66 ~-2 ~45 double_stone_slab 0  
fill ~46 ~-2 ~46 ~66 ~-2 ~46 double_stone_slab 0  
fill ~46 ~-2 ~47 ~66 ~-2 ~47 double_stone_slab 0  
fill ~46 ~-2 ~48 ~66 ~-2 ~48 double_stone_slab 0  
fill ~46 ~-2 ~49 ~66 ~-2 ~49 double_stone_slab 0 
setblock ~46 ~-2 ~50 glowstone 0 
setblock ~46 ~-2 ~68 sandstone 2 
setblock ~46 ~-2 ~86 glowstone 0  
fill ~46 ~-2 ~87 ~66 ~-2 ~87 double_stone_slab 0  
fill ~46 ~-2 ~88 ~66 ~-2 ~88 double_stone_slab 0  
fill ~46 ~-2 ~89 ~66 ~-2 ~89 double_stone_slab 0  
fill ~46 ~-2 ~90 ~66 ~-2 ~90 double_stone_slab 0  
fill ~46 ~-2 ~91 ~66 ~-2 ~91 double_stone_slab 0  
fill ~46 ~-2 ~92 ~66 ~-2 ~92 double_stone_slab 0  
fill ~46 ~-2 ~93 ~66 ~-2 ~93 double_stone_slab 0  
fill ~46 ~-2 ~94 ~66 ~-2 ~94 double_stone_slab 0  
fill ~46 ~-2 ~95 ~66 ~-2 ~95 double_stone_slab 0  
fill ~46 ~-2 ~96 ~66 ~-2 ~96 double_stone_slab 0  
fill ~46 ~-2 ~97 ~66 ~-2 ~97 double_stone_slab 0  
fill ~46 ~-2 ~98 ~66 ~-2 ~98 double_stone_slab 0  
fill ~46 ~-2 ~99 ~66 ~-2 ~99 double_stone_slab 0  
fill ~46 ~-2 ~100 ~66 ~-2 ~100 double_stone_slab 0  
fill ~46 ~-2 ~101 ~66 ~-2 ~101 double_stone_slab 0  
fill ~46 ~-2 ~102 ~66 ~-2 ~102 double_stone_slab 0  
fill ~46 ~-2 ~103 ~64 ~-2 ~103 double_stone_slab 0  
fill ~46 ~-2 ~104 ~66 ~-2 ~104 double_stone_slab 0 
setblock ~46 ~-2 ~105 glowstone 0  
fill ~47 ~-2 ~31 ~65 ~-2 ~31 double_stone_slab 0  
fill ~47 ~-2 ~50 ~65 ~-2 ~50 double_stone_slab 0  
fill ~47 ~-2 ~68 ~51 ~-2 ~68 dirt 0  
fill ~47 ~-2 ~86 ~65 ~-2 ~86 double_stone_slab 0  
fill ~47 ~-2 ~105 ~65 ~-2 ~105 double_stone_slab 0  
fill ~48 ~-2 ~13 ~67 ~-2 ~13 beacon 0  
fill ~48 ~-2 ~14 ~48 ~-2 ~22 beacon 0  
fill ~48 ~-2 ~116 ~70 ~-2 ~116 grass 0  
fill ~48 ~-2 ~117 ~70 ~-2 ~117 grass 0  
fill ~48 ~-2 ~120 ~70 ~-2 ~120 grass 0  
fill ~48 ~-2 ~121 ~70 ~-2 ~121 grass 0  
fill ~49 ~-2 ~14 ~66 ~-2 ~14 iron_block 0  
fill ~49 ~-2 ~15 ~49 ~-2 ~21 iron_block 0  
fill ~49 ~-2 ~22 ~67 ~-2 ~22 beacon 0 
setblock ~49 ~-2 ~111 grass 0 
setblock ~49 ~-2 ~126 grass 0  
fill ~50 ~-2 ~21 ~66 ~-2 ~21 iron_block 0  
fill ~50 ~-2 ~111 ~54 ~-2 ~111 dirt 0  
fill ~50 ~-2 ~126 ~54 ~-2 ~126 dirt 0 
setblock ~52 ~-2 ~68 sandstone 2  
fill ~53 ~-2 ~68 ~57 ~-2 ~68 dirt 0 
setblock ~55 ~-2 ~111 grass 0 
setblock ~55 ~-2 ~126 grass 0  
fill ~56 ~-2 ~111 ~60 ~-2 ~111 dirt 0  
fill ~56 ~-2 ~126 ~60 ~-2 ~126 dirt 0 
setblock ~58 ~-2 ~68 sandstone 2 
setblock ~59 ~-2 ~68 dirt 0 
setblock ~60 ~-2 ~68 glowstone 0  
fill ~61 ~-2 ~68 ~62 ~-2 ~68 dirt 0 
setblock ~61 ~-2 ~111 grass 0 
setblock ~61 ~-2 ~126 grass 0  
fill ~62 ~-2 ~111 ~66 ~-2 ~111 dirt 0  
fill ~62 ~-2 ~126 ~66 ~-2 ~126 dirt 0  
fill ~63 ~-2 ~58 ~63 ~-2 ~65 sandstone 2 
setblock ~63 ~-2 ~68 sandstone 2  
fill ~63 ~-2 ~71 ~63 ~-2 ~78 sandstone 2  
fill ~64 ~-2 ~58 ~72 ~-2 ~58 dirt 0  
fill ~64 ~-2 ~59 ~72 ~-2 ~59 dirt 0  
fill ~64 ~-2 ~60 ~71 ~-2 ~60 dirt 0  
fill ~64 ~-2 ~61 ~83 ~-2 ~61 dirt 0  
fill ~64 ~-2 ~62 ~83 ~-2 ~62 dirt 0  
fill ~64 ~-2 ~63 ~106 ~-2 ~63 dirt 0  
fill ~64 ~-2 ~64 ~83 ~-2 ~64 dirt 0  
fill ~64 ~-2 ~65 ~106 ~-2 ~65 dirt 0  
fill ~64 ~-2 ~68 ~68 ~-2 ~68 dirt 0  
fill ~64 ~-2 ~71 ~106 ~-2 ~71 dirt 0  
fill ~64 ~-2 ~72 ~83 ~-2 ~72 dirt 0  
fill ~64 ~-2 ~73 ~106 ~-2 ~73 dirt 0  
fill ~64 ~-2 ~74 ~83 ~-2 ~74 dirt 0  
fill ~64 ~-2 ~75 ~106 ~-2 ~75 dirt 0  
fill ~64 ~-2 ~76 ~78 ~-2 ~76 dirt 0  
fill ~64 ~-2 ~77 ~72 ~-2 ~77 dirt 0  
fill ~64 ~-2 ~78 ~72 ~-2 ~78 dirt 0 
setblock ~65 ~-2 ~103 stone_slab 8  
fill ~66 ~-2 ~15 ~66 ~-2 ~21 iron_block 0 
setblock ~66 ~-2 ~31 glowstone 0 
setblock ~66 ~-2 ~50 glowstone 0 
setblock ~66 ~-2 ~86 glowstone 0 
setblock ~66 ~-2 ~103 double_stone_slab 0 
setblock ~66 ~-2 ~105 glowstone 0  
fill ~67 ~-2 ~14 ~67 ~-2 ~22 beacon 0  
fill ~67 ~-2 ~31 ~106 ~-2 ~31 dirt 0  
fill ~67 ~-2 ~32 ~106 ~-2 ~32 dirt 0  
fill ~67 ~-2 ~33 ~106 ~-2 ~33 dirt 0  
fill ~67 ~-2 ~34 ~106 ~-2 ~34 dirt 0  
fill ~67 ~-2 ~35 ~106 ~-2 ~35 dirt 0  
fill ~67 ~-2 ~36 ~106 ~-2 ~36 dirt 0  
fill ~67 ~-2 ~37 ~106 ~-2 ~37 dirt 0  
fill ~67 ~-2 ~38 ~106 ~-2 ~38 dirt 0  
fill ~67 ~-2 ~39 ~106 ~-2 ~39 dirt 0  
fill ~67 ~-2 ~40 ~99 ~-2 ~40 dirt 0  
fill ~67 ~-2 ~41 ~106 ~-2 ~41 dirt 0  
fill ~67 ~-2 ~42 ~80 ~-2 ~42 dirt 0  
fill ~67 ~-2 ~43 ~78 ~-2 ~43 dirt 0  
fill ~67 ~-2 ~44 ~76 ~-2 ~44 dirt 0  
fill ~67 ~-2 ~45 ~89 ~-2 ~45 dirt 0  
fill ~67 ~-2 ~46 ~75 ~-2 ~46 dirt 0  
fill ~67 ~-2 ~47 ~106 ~-2 ~47 dirt 0  
fill ~67 ~-2 ~48 ~74 ~-2 ~48 dirt 0  
fill ~67 ~-2 ~49 ~106 ~-2 ~49 dirt 0  
fill ~67 ~-2 ~50 ~83 ~-2 ~50 dirt 0  
fill ~67 ~-2 ~86 ~83 ~-2 ~86 dirt 0  
fill ~67 ~-2 ~87 ~106 ~-2 ~87 dirt 0  
fill ~67 ~-2 ~88 ~74 ~-2 ~88 dirt 0  
fill ~67 ~-2 ~89 ~106 ~-2 ~89 dirt 0  
fill ~67 ~-2 ~90 ~75 ~-2 ~90 dirt 0  
fill ~67 ~-2 ~91 ~89 ~-2 ~91 dirt 0  
fill ~67 ~-2 ~92 ~76 ~-2 ~92 dirt 0  
fill ~67 ~-2 ~93 ~78 ~-2 ~93 dirt 0  
fill ~67 ~-2 ~94 ~80 ~-2 ~94 dirt 0  
fill ~67 ~-2 ~95 ~106 ~-2 ~95 dirt 0  
fill ~67 ~-2 ~96 ~106 ~-2 ~96 dirt 0  
fill ~67 ~-2 ~97 ~106 ~-2 ~97 dirt 0  
fill ~67 ~-2 ~98 ~106 ~-2 ~98 dirt 0  
fill ~67 ~-2 ~99 ~106 ~-2 ~99 dirt 0  
fill ~67 ~-2 ~100 ~106 ~-2 ~100 dirt 0  
fill ~67 ~-2 ~101 ~106 ~-2 ~101 dirt 0  
fill ~67 ~-2 ~102 ~92 ~-2 ~102 dirt 0  
fill ~67 ~-2 ~103 ~106 ~-2 ~103 dirt 0  
fill ~67 ~-2 ~104 ~106 ~-2 ~104 dirt 0  
fill ~67 ~-2 ~105 ~70 ~-2 ~105 dirt 0 
setblock ~67 ~-2 ~111 grass 0 
setblock ~67 ~-2 ~126 grass 0  
fill ~68 ~-2 ~13 ~106 ~-2 ~13 dirt 0  
fill ~68 ~-2 ~14 ~106 ~-2 ~14 dirt 0  
fill ~68 ~-2 ~15 ~106 ~-2 ~15 dirt 0  
fill ~68 ~-2 ~16 ~106 ~-2 ~16 dirt 0  
fill ~68 ~-2 ~17 ~106 ~-2 ~17 dirt 0  
fill ~68 ~-2 ~18 ~106 ~-2 ~18 dirt 0  
fill ~68 ~-2 ~19 ~106 ~-2 ~19 dirt 0  
fill ~68 ~-2 ~20 ~106 ~-2 ~20 dirt 0  
fill ~68 ~-2 ~21 ~106 ~-2 ~21 dirt 0  
fill ~68 ~-2 ~22 ~106 ~-2 ~22 dirt 0  
fill ~68 ~-2 ~111 ~96 ~-2 ~111 dirt 0  
fill ~68 ~-2 ~126 ~84 ~-2 ~126 dirt 0 
setblock ~69 ~-2 ~68 sandstone 2  
fill ~70 ~-2 ~68 ~71 ~-2 ~68 dirt 0  
fill ~71 ~-2 ~106 ~71 ~-2 ~110 grass 0  
fill ~71 ~-2 ~116 ~97 ~-2 ~116 dirt 0  
fill ~71 ~-2 ~117 ~96 ~-2 ~117 dirt 0  
fill ~71 ~-2 ~118 ~97 ~-2 ~118 dirt 0  
fill ~71 ~-2 ~119 ~97 ~-2 ~119 dirt 0  
fill ~71 ~-2 ~120 ~96 ~-2 ~120 dirt 0  
fill ~71 ~-2 ~121 ~97 ~-2 ~121 dirt 0   
fill ~72 ~-2 ~56 ~78 ~-2 ~56 sandstone 2  
fill ~72 ~-2 ~60 ~76 ~-2 ~60 sandstone 2 
setblock ~72 ~-2 ~68 glowstone 0  
fill ~72 ~-2 ~106 ~86 ~-2 ~106 dirt 0  
fill ~72 ~-2 ~107 ~106 ~-2 ~107 dirt 0  
fill ~72 ~-2 ~108 ~106 ~-2 ~108 dirt 0  
fill ~72 ~-2 ~109 ~106 ~-2 ~109 dirt 0  
fill ~72 ~-2 ~110 ~106 ~-2 ~110 dirt 0 
setblock ~73 ~-2 ~55 torch 5  
fill ~73 ~-2 ~57 ~73 ~-2 ~59 stone_brick_stairs 1 
setblock ~73 ~-2 ~68 dirt 0 
setblock ~73 ~-2 ~81 torch 5 
setblock ~73 ~-2 ~105 dirt 0 
setblock ~74 ~-2 ~53 torch 5  
fill ~74 ~-2 ~55 ~106 ~-2 ~55 dirt 0 
setblock ~74 ~-2 ~68 glowstone 0  
fill ~74 ~-2 ~81 ~106 ~-2 ~81 dirt 0 
setblock ~74 ~-2 ~83 torch 5 
setblock ~75 ~-2 ~48 torch 5 
setblock ~75 ~-2 ~51 torch 5  
fill ~75 ~-2 ~53 ~96 ~-2 ~53 dirt 0 
setblock ~75 ~-2 ~68 dirt 0  
fill ~75 ~-2 ~77 ~77 ~-2 ~77 dirt 0  
fill ~75 ~-2 ~78 ~83 ~-2 ~78 dirt 0  
fill ~75 ~-2 ~79 ~106 ~-2 ~79 dirt 0  
fill ~75 ~-2 ~83 ~96 ~-2 ~83 dirt 0 
setblock ~75 ~-2 ~85 torch 5 
setblock ~75 ~-2 ~88 torch 5 
setblock ~76 ~-2 ~46 torch 5  
fill ~76 ~-2 ~48 ~83 ~-2 ~48 dirt 0  
fill ~76 ~-2 ~51 ~106 ~-2 ~51 dirt 0 
setblock ~76 ~-2 ~68 glowstone 0  
fill ~76 ~-2 ~85 ~106 ~-2 ~85 dirt 0  
fill ~76 ~-2 ~88 ~83 ~-2 ~88 dirt 0 
setblock ~76 ~-2 ~90 torch 5  
fill ~76 ~-2 ~105 ~86 ~-2 ~105 dirt 0 
setblock ~77 ~-2 ~44 torch 5  
fill ~77 ~-2 ~46 ~91 ~-2 ~46 dirt 0  
fill ~77 ~-2 ~57 ~78 ~-2 ~57 sandstone 2  
fill ~77 ~-2 ~58 ~78 ~-2 ~58 sandstone 2  
fill ~77 ~-2 ~59 ~78 ~-2 ~59 sandstone 2  
fill ~77 ~-2 ~60 ~83 ~-2 ~60 dirt 0 
setblock ~77 ~-2 ~68 dirt 0  
fill ~77 ~-2 ~90 ~91 ~-2 ~90 dirt 0 
setblock ~77 ~-2 ~92 torch 5  
fill ~78 ~-2 ~44 ~87 ~-2 ~44 dirt 0 
setblock ~78 ~-2 ~68 glowstone 0  
fill ~78 ~-2 ~77 ~78 ~-1 ~77 double_stone_slab 0  
fill ~78 ~-2 ~92 ~84 ~-2 ~92 dirt 0 
setblock ~79 ~-2 ~43 torch 5  
fill ~79 ~-2 ~56 ~83 ~-2 ~56 dirt 0  
fill ~79 ~-2 ~57 ~106 ~-2 ~57 dirt 0  
fill ~79 ~-2 ~58 ~83 ~-2 ~58 dirt 0  
fill ~79 ~-2 ~59 ~106 ~-2 ~59 dirt 0 
setblock ~79 ~-2 ~68 dirt 0  
fill ~79 ~-2 ~77 ~106 ~-2 ~77 dirt 0 
setblock ~79 ~-2 ~93 torch 5  
fill ~80 ~-2 ~43 ~85 ~-2 ~43 dirt 0 
setblock ~80 ~-2 ~68 glowstone 0  
fill ~80 ~-2 ~76 ~83 ~-2 ~76 dirt 0  
fill ~80 ~-2 ~93 ~85 ~-2 ~93 dirt 0 
setblock ~81 ~-2 ~42 torch 5 
setblock ~81 ~-2 ~68 dirt 0  
fill ~82 ~-2 ~42 ~83 ~-2 ~42 dirt 0 
setblock ~82 ~-2 ~68 glowstone 0  
fill ~82 ~-2 ~94 ~83 ~-2 ~94 dirt 0 
setblock ~83 ~-2 ~68 dirt 0  
fill ~83 ~-2 ~113 ~97 ~-2 ~113 dirt 0 
setblock ~84 ~-2 ~42 torch 5 
setblock ~84 ~-2 ~48 glowstone 0 
setblock ~84 ~-2 ~50 glowstone 0 
setblock ~84 ~-2 ~52 glowstone 0 
setblock ~84 ~-2 ~54 glowstone 0 
setblock ~84 ~-2 ~56 glowstone 0 
setblock ~84 ~-2 ~58 glowstone 0 
setblock ~84 ~-2 ~60 glowstone 0  
fill ~84 ~-2 ~61 ~84 ~-1 ~61 double_stone_slab 0 
setblock ~84 ~-2 ~62 glowstone 0 
setblock ~84 ~-2 ~64 glowstone 0 
setblock ~84 ~-2 ~66 glowstone 0 
setblock ~84 ~-2 ~68 glowstone 0 
setblock ~84 ~-2 ~70 glowstone 0 
setblock ~84 ~-2 ~72 glowstone 0 
setblock ~84 ~-2 ~74 glowstone 0 
setblock ~84 ~-2 ~76 glowstone 0 
setblock ~84 ~-2 ~78 glowstone 0 
setblock ~84 ~-2 ~80 glowstone 0 
setblock ~84 ~-2 ~82 glowstone 0 
setblock ~84 ~-2 ~84 glowstone 0 
setblock ~84 ~-2 ~86 glowstone 0 
setblock ~84 ~-2 ~88 glowstone 0 
setblock ~84 ~-2 ~94 torch 5  
fill ~85 ~-2 ~42 ~106 ~-2 ~42 dirt 0  
fill ~85 ~-2 ~48 ~92 ~-2 ~48 dirt 0  
fill ~85 ~-2 ~50 ~93 ~-2 ~50 dirt 0  
fill ~85 ~-2 ~52 ~94 ~-2 ~52 dirt 0  
fill ~85 ~-2 ~54 ~106 ~-2 ~54 dirt 0  
fill ~85 ~-2 ~56 ~90 ~-2 ~56 dirt 0  
fill ~85 ~-2 ~58 ~90 ~-2 ~58 dirt 0  
fill ~85 ~-2 ~60 ~85 ~-1 ~60 double_stone_slab 0  
fill ~85 ~-2 ~61 ~106 ~-2 ~61 dirt 0  
fill ~85 ~-2 ~62 ~89 ~-2 ~62 dirt 0  
fill ~85 ~-2 ~64 ~89 ~-2 ~64 dirt 0  
fill ~85 ~-2 ~66 ~89 ~-2 ~66 dirt 0 
setblock ~85 ~-2 ~68 dirt 0  
fill ~85 ~-2 ~70 ~89 ~-2 ~70 dirt 0  
fill ~85 ~-2 ~72 ~89 ~-2 ~72 dirt 0  
fill ~85 ~-2 ~74 ~89 ~-2 ~74 dirt 0  
fill ~85 ~-2 ~76 ~89 ~-2 ~76 dirt 0  
fill ~85 ~-2 ~78 ~90 ~-2 ~78 dirt 0  
fill ~85 ~-2 ~80 ~90 ~-2 ~80 dirt 0  
fill ~85 ~-2 ~82 ~106 ~-2 ~82 dirt 0  
fill ~85 ~-2 ~84 ~94 ~-2 ~84 dirt 0  
fill ~85 ~-2 ~86 ~93 ~-2 ~86 dirt 0  
fill ~85 ~-2 ~88 ~92 ~-2 ~88 dirt 0  
fill ~85 ~-2 ~92 ~85 ~-1 ~92 double_stone_slab 0  
fill ~85 ~-2 ~94 ~106 ~-2 ~94 dirt 0 
setblock ~85 ~-2 ~126 grass 0 
setblock ~86 ~-2 ~43 torch 5 
setblock ~86 ~-2 ~68 glowstone 0  
fill ~86 ~-2 ~92 ~87 ~-2 ~92 dirt 0 
setblock ~86 ~-2 ~93 torch 5  
fill ~86 ~-2 ~126 ~87 ~-2 ~126 dirt 0  
fill ~87 ~-2 ~43 ~106 ~-2 ~43 dirt 0  
fill ~87 ~-2 ~60 ~89 ~-2 ~60 dirt 0 
setblock ~87 ~-2 ~68 dirt 0  
fill ~87 ~-2 ~93 ~106 ~-2 ~93 dirt 0 
setblock ~88 ~-2 ~44 torch 5 
setblock ~88 ~-2 ~68 glowstone 0 
setblock ~88 ~-2 ~92 torch 5  
fill ~88 ~-2 ~105 ~106 ~-2 ~105 dirt 0  
fill ~88 ~-2 ~106 ~106 ~-2 ~106 dirt 0 
setblock ~88 ~-2 ~126 grass 0  
fill ~89 ~-2 ~44 ~106 ~-2 ~44 dirt 0 
setblock ~89 ~-2 ~68 dirt 0  
fill ~89 ~-2 ~92 ~106 ~-2 ~92 dirt 0  
fill ~89 ~-2 ~126 ~90 ~-2 ~126 dirt 0 
setblock ~90 ~-2 ~45 torch 5 
setblock ~90 ~-2 ~60 glowstone 0 
setblock ~90 ~-2 ~62 glowstone 0 
setblock ~90 ~-2 ~64 glowstone 0 
setblock ~90 ~-2 ~66 glowstone 0 
setblock ~90 ~-2 ~68 glowstone 0 
setblock ~90 ~-2 ~70 glowstone 0 
setblock ~90 ~-2 ~72 glowstone 0 
setblock ~90 ~-2 ~74 glowstone 0 
setblock ~90 ~-2 ~76 glowstone 0 
setblock ~90 ~-2 ~91 torch 5  
fill ~91 ~-2 ~45 ~106 ~-2 ~45 dirt 0 
setblock ~91 ~-2 ~56 glowstone 0 
setblock ~91 ~-2 ~58 glowstone 0  
fill ~91 ~-2 ~60 ~106 ~-2 ~60 dirt 0  
fill ~91 ~-2 ~62 ~105 ~-2 ~62 dirt 0  
fill ~91 ~-2 ~64 ~106 ~-2 ~64 dirt 0  
fill ~91 ~-2 ~66 ~106 ~-2 ~66 dirt 0  
fill ~91 ~-2 ~68 ~106 ~-2 ~68 dirt 0  
fill ~91 ~-2 ~70 ~106 ~-2 ~70 dirt 0  
fill ~91 ~-2 ~72 ~106 ~-2 ~72 dirt 0  
fill ~91 ~-2 ~74 ~99 ~-2 ~74 dirt 0  
fill ~91 ~-2 ~76 ~106 ~-2 ~76 dirt 0 
setblock ~91 ~-2 ~78 glowstone 0 
setblock ~91 ~-2 ~80 glowstone 0  
fill ~91 ~-2 ~91 ~106 ~-2 ~91 dirt 0 
setblock ~91 ~-2 ~126 grass 0 
setblock ~92 ~-2 ~46 torch 5  
fill ~92 ~-2 ~56 ~106 ~-2 ~56 dirt 0  
fill ~92 ~-2 ~58 ~106 ~-2 ~58 dirt 0  
fill ~92 ~-2 ~78 ~106 ~-2 ~78 dirt 0  
fill ~92 ~-2 ~80 ~106 ~-2 ~80 dirt 0 
setblock ~92 ~-2 ~90 torch 5  
fill ~92 ~-2 ~126 ~93 ~-2 ~126 dirt 0  
fill ~93 ~-2 ~46 ~106 ~-2 ~46 dirt 0 
setblock ~93 ~-2 ~48 torch 5 
setblock ~93 ~-2 ~88 torch 5  
fill ~93 ~-2 ~90 ~106 ~-2 ~90 dirt 0  
fill ~94 ~-2 ~48 ~106 ~-2 ~48 dirt 0 
setblock ~94 ~-2 ~50 torch 5 
setblock ~94 ~-2 ~86 torch 5  
fill ~94 ~-2 ~88 ~106 ~-2 ~88 dirt 0  
fill ~94 ~-2 ~102 ~106 ~-2 ~102 dirt 0 
setblock ~94 ~-2 ~126 grass 0  
fill ~95 ~-2 ~50 ~106 ~-2 ~50 dirt 0 
setblock ~95 ~-2 ~52 torch 5 
setblock ~95 ~-2 ~84 torch 5  
fill ~95 ~-2 ~86 ~106 ~-2 ~86 dirt 0 
setblock ~95 ~-2 ~114 cobblestone 0  
fill ~95 ~-2 ~126 ~96 ~-2 ~126 dirt 0  
fill ~96 ~-2 ~52 ~106 ~-2 ~52 dirt 0  
fill ~96 ~-2 ~84 ~106 ~-2 ~84 dirt 0 
setblock ~96 ~-2 ~114 dirt 0 
setblock ~97 ~-2 ~1 grass 0 
setblock ~97 ~-2 ~53 torch 5 
setblock ~97 ~-2 ~83 torch 5  
fill ~97 ~-2 ~111 ~98 ~-2 ~111 grass 0  
fill ~97 ~-2 ~114 ~98 ~-2 ~114 grass 0  
fill ~97 ~-2 ~117 ~98 ~-2 ~117 grass 0  
fill ~97 ~-2 ~120 ~98 ~-2 ~120 grass 0  
fill ~97 ~-2 ~123 ~98 ~-2 ~123 grass 0  
fill ~97 ~-2 ~126 ~98 ~-2 ~126 grass 0  
fill ~98 ~-2 ~1 ~106 ~-2 ~1 dirt 0  
fill ~98 ~-2 ~53 ~106 ~-2 ~53 dirt 0  
fill ~98 ~-2 ~83 ~106 ~-2 ~83 dirt 0  
fill ~98 ~-2 ~112 ~98 ~-2 ~127 grass 0  
fill ~98 ~-2 ~129 ~106 ~-2 ~129 dirt 0  
fill ~98 ~-2 ~130 ~106 ~-2 ~130 dirt 0  
fill ~98 ~-2 ~131 ~106 ~-2 ~131 dirt 0  
fill ~98 ~-2 ~132 ~106 ~-2 ~132 dirt 0  
fill ~98 ~-2 ~133 ~106 ~-2 ~133 dirt 0  
fill ~98 ~-2 ~134 ~106 ~-2 ~134 dirt 0  
fill ~98 ~-2 ~135 ~106 ~-2 ~135 dirt 0  
fill ~99 ~-2 ~111 ~106 ~-2 ~111 dirt 0  
fill ~99 ~-2 ~112 ~106 ~-2 ~112 dirt 0  
fill ~99 ~-2 ~113 ~106 ~-2 ~113 dirt 0  
fill ~99 ~-2 ~114 ~106 ~-2 ~114 dirt 0  
fill ~99 ~-2 ~115 ~106 ~-2 ~115 dirt 0  
fill ~99 ~-2 ~116 ~106 ~-2 ~116 dirt 0  
fill ~99 ~-2 ~117 ~106 ~-2 ~117 dirt 0  
fill ~99 ~-2 ~118 ~106 ~-2 ~118 dirt 0  
fill ~99 ~-2 ~119 ~106 ~-2 ~119 dirt 0  
fill ~99 ~-2 ~120 ~106 ~-2 ~120 dirt 0  
fill ~99 ~-2 ~121 ~106 ~-2 ~121 dirt 0  
fill ~99 ~-2 ~122 ~106 ~-2 ~122 dirt 0  
fill ~99 ~-2 ~123 ~106 ~-2 ~123 dirt 0  
fill ~99 ~-2 ~124 ~106 ~-2 ~124 dirt 0  
fill ~99 ~-2 ~125 ~106 ~-2 ~125 dirt 0  
fill ~99 ~-2 ~126 ~105 ~-2 ~126 dirt 0  
fill ~99 ~-2 ~127 ~106 ~-2 ~127 dirt 0 
setblock ~100 ~-2 ~10 grass 0 
setblock ~100 ~-2 ~74 grass 0  
fill ~101 ~-2 ~10 ~105 ~-2 ~10 dirt 0  
fill ~101 ~-2 ~40 ~106 ~-2 ~40 dirt 0  
fill ~101 ~-2 ~74 ~105 ~-2 ~74 dirt 0 
setblock ~106 ~-2 ~10 grass 0 
setblock ~106 ~-2 ~62 grass 0 
setblock ~106 ~-2 ~74 grass 0 
setblock ~106 ~-2 ~126 grass 0  
fill ~1 ~-1 ~1 ~32 ~-1 ~1 stonebrick 0  
fill ~1 ~-1 ~2 ~32 ~-1 ~2 stone_slab 0  
fill ~1 ~-1 ~3 ~106 ~-1 ~3 stone_slab 0  
fill ~1 ~-1 ~4 ~106 ~-1 ~4 stone_slab 0  
fill ~1 ~-1 ~5 ~106 ~-1 ~5 stone_slab 0  
fill ~1 ~-1 ~6 ~32 ~-1 ~6 stone_slab 0  
fill ~1 ~-1 ~7 ~16 ~-1 ~7 stonebrick 0  
fill ~1 ~-1 ~8 ~4 ~-1 ~8 grass 0  
fill ~1 ~-1 ~9 ~4 ~-1 ~9 grass 0  
fill ~1 ~-1 ~10 ~4 ~-1 ~10 grass 0  
fill ~1 ~-1 ~11 ~4 ~-1 ~11 grass 0  
fill ~1 ~-1 ~12 ~4 ~-1 ~12 grass 0  
fill ~1 ~-1 ~13 ~4 ~-1 ~13 grass 0  
fill ~1 ~-1 ~14 ~4 ~-1 ~14 grass 0  
fill ~1 ~-1 ~15 ~4 ~-1 ~15 grass 0  
fill ~1 ~-1 ~16 ~4 ~-1 ~16 grass 0  
fill ~1 ~-1 ~17 ~4 ~-1 ~17 grass 0  
fill ~1 ~-1 ~18 ~4 ~-1 ~18 grass 0  
fill ~1 ~-1 ~19 ~4 ~-1 ~19 grass 0  
fill ~1 ~-1 ~20 ~4 ~-1 ~20 grass 0  
fill ~1 ~-1 ~21 ~4 ~-1 ~21 grass 0  
fill ~1 ~-1 ~22 ~4 ~-1 ~22 grass 0  
fill ~1 ~-1 ~23 ~4 ~-1 ~23 grass 0  
fill ~1 ~-1 ~24 ~4 ~-1 ~24 grass 0  
fill ~1 ~-1 ~25 ~4 ~-1 ~25 grass 0  
fill ~1 ~-1 ~26 ~4 ~-1 ~26 grass 0  
fill ~1 ~-1 ~27 ~4 ~-1 ~27 grass 0  
fill ~1 ~-1 ~28 ~4 ~-1 ~28 grass 0  
fill ~1 ~-1 ~29 ~4 ~-1 ~29 grass 0  
fill ~1 ~-1 ~30 ~4 ~-1 ~30 grass 0  
fill ~1 ~-1 ~31 ~4 ~-1 ~31 grass 0  
fill ~1 ~-1 ~32 ~4 ~-1 ~32 grass 0  
fill ~1 ~-1 ~33 ~4 ~-1 ~33 grass 0  
fill ~1 ~-1 ~34 ~4 ~-1 ~34 grass 0  
fill ~1 ~-1 ~35 ~4 ~-1 ~35 grass 0  
fill ~1 ~-1 ~36 ~4 ~-1 ~36 grass 0  
fill ~1 ~-1 ~37 ~4 ~-1 ~37 grass 0  
fill ~1 ~-1 ~38 ~4 ~-1 ~38 grass 0  
fill ~1 ~-1 ~39 ~4 ~-1 ~39 grass 0  
fill ~1 ~-1 ~40 ~4 ~-1 ~40 grass 0  
fill ~1 ~-1 ~41 ~4 ~-1 ~41 grass 0  
fill ~1 ~-1 ~42 ~4 ~-1 ~42 grass 0  
fill ~1 ~-1 ~43 ~4 ~-1 ~43 grass 0  
fill ~1 ~-1 ~44 ~4 ~-1 ~44 grass 0  
fill ~1 ~-1 ~45 ~4 ~-1 ~45 grass 0  
fill ~1 ~-1 ~46 ~4 ~-1 ~46 grass 0  
fill ~1 ~-1 ~47 ~4 ~-1 ~47 grass 0  
fill ~1 ~-1 ~48 ~4 ~-1 ~48 grass 0  
fill ~1 ~-1 ~49 ~4 ~-1 ~49 grass 0  
fill ~1 ~-1 ~50 ~4 ~-1 ~50 grass 0  
fill ~1 ~-1 ~51 ~4 ~-1 ~51 grass 0  
fill ~1 ~-1 ~52 ~4 ~-1 ~52 grass 0  
fill ~1 ~-1 ~53 ~4 ~-1 ~53 grass 0  
fill ~1 ~-1 ~54 ~4 ~-1 ~54 grass 0  
fill ~1 ~-1 ~55 ~4 ~-1 ~55 grass 0  
fill ~1 ~-1 ~56 ~4 ~-1 ~56 grass 0  
fill ~1 ~-1 ~57 ~4 ~-1 ~57 grass 0  
fill ~1 ~-1 ~58 ~4 ~-1 ~58 grass 0  
fill ~1 ~-1 ~59 ~4 ~-1 ~59 grass 0  
fill ~1 ~-1 ~60 ~32 ~-1 ~60 grass 0  
fill ~1 ~-1 ~61 ~32 ~-1 ~61 grass 0  
fill ~1 ~-1 ~62 ~17 ~-1 ~62 grass 0  
fill ~1 ~-1 ~63 ~1 ~-1 ~63 grass 0  
fill ~1 ~-1 ~64 ~1 ~-1 ~64 grass 0 
setblock ~1 ~-1 ~65 stonebrick 0  
fill ~1 ~-1 ~66 ~1 ~-1 ~70 stone_slab 0 
setblock ~1 ~-1 ~71 stonebrick 0  
fill ~1 ~-1 ~72 ~2 ~-1 ~72 grass 0  
fill ~1 ~-1 ~73 ~2 ~-1 ~73 grass 0  
fill ~1 ~-1 ~74 ~17 ~-1 ~74 grass 0  
fill ~1 ~-1 ~75 ~32 ~-1 ~75 grass 0  
fill ~1 ~-1 ~76 ~9 ~-1 ~76 grass 0  
fill ~1 ~-1 ~77 ~4 ~-1 ~77 grass 0  
fill ~1 ~-1 ~78 ~4 ~-1 ~78 grass 0  
fill ~1 ~-1 ~79 ~4 ~-1 ~79 grass 0  
fill ~1 ~-1 ~80 ~4 ~-1 ~80 grass 0  
fill ~1 ~-1 ~81 ~4 ~-1 ~81 grass 0  
fill ~1 ~-1 ~82 ~4 ~-1 ~82 grass 0  
fill ~1 ~-1 ~83 ~4 ~-1 ~83 grass 0  
fill ~1 ~-1 ~84 ~4 ~-1 ~84 grass 0  
fill ~1 ~-1 ~85 ~4 ~-1 ~85 grass 0  
fill ~1 ~-1 ~86 ~4 ~-1 ~86 grass 0  
fill ~1 ~-1 ~87 ~4 ~-1 ~87 grass 0  
fill ~1 ~-1 ~88 ~4 ~-1 ~88 grass 0  
fill ~1 ~-1 ~89 ~4 ~-1 ~89 grass 0  
fill ~1 ~-1 ~90 ~4 ~-1 ~90 grass 0  
fill ~1 ~-1 ~91 ~4 ~-1 ~91 grass 0  
fill ~1 ~-1 ~92 ~4 ~-1 ~92 grass 0  
fill ~1 ~-1 ~93 ~4 ~-1 ~93 grass 0  
fill ~1 ~-1 ~94 ~4 ~-1 ~94 grass 0  
fill ~1 ~-1 ~95 ~4 ~-1 ~95 grass 0  
fill ~1 ~-1 ~96 ~4 ~-1 ~96 grass 0  
fill ~1 ~-1 ~97 ~4 ~-1 ~97 grass 0  
fill ~1 ~-1 ~98 ~4 ~-1 ~98 grass 0  
fill ~1 ~-1 ~99 ~4 ~-1 ~99 grass 0  
fill ~1 ~-1 ~100 ~4 ~-1 ~100 grass 0  
fill ~1 ~-1 ~101 ~4 ~-1 ~101 grass 0  
fill ~1 ~-1 ~102 ~4 ~-1 ~102 grass 0  
fill ~1 ~-1 ~103 ~4 ~-1 ~103 grass 0  
fill ~1 ~-1 ~104 ~4 ~-1 ~104 grass 0  
fill ~1 ~-1 ~105 ~4 ~-1 ~105 grass 0  
fill ~1 ~-1 ~106 ~4 ~-1 ~106 grass 0  
fill ~1 ~-1 ~107 ~4 ~-1 ~107 grass 0  
fill ~1 ~-1 ~108 ~4 ~-1 ~108 grass 0  
fill ~1 ~-1 ~109 ~4 ~-1 ~109 grass 0  
fill ~1 ~-1 ~110 ~4 ~-1 ~110 grass 0  
fill ~1 ~-1 ~111 ~4 ~-1 ~111 grass 0  
fill ~1 ~-1 ~112 ~4 ~-1 ~112 grass 0  
fill ~1 ~-1 ~113 ~4 ~-1 ~113 grass 0  
fill ~1 ~-1 ~114 ~4 ~-1 ~114 grass 0  
fill ~1 ~-1 ~115 ~4 ~-1 ~115 grass 0  
fill ~1 ~-1 ~116 ~4 ~-1 ~116 grass 0  
fill ~1 ~-1 ~117 ~4 ~-1 ~117 grass 0  
fill ~1 ~-1 ~118 ~4 ~-1 ~118 grass 0  
fill ~1 ~-1 ~119 ~4 ~-1 ~119 grass 0  
fill ~1 ~-1 ~120 ~4 ~-1 ~120 grass 0  
fill ~1 ~-1 ~121 ~4 ~-1 ~121 grass 0  
fill ~1 ~-1 ~122 ~4 ~-1 ~122 grass 0  
fill ~1 ~-1 ~123 ~4 ~-1 ~123 grass 0  
fill ~1 ~-1 ~124 ~4 ~-1 ~124 grass 0  
fill ~1 ~-1 ~125 ~4 ~-1 ~125 grass 0  
fill ~1 ~-1 ~126 ~4 ~-1 ~126 grass 0  
fill ~1 ~-1 ~127 ~4 ~-1 ~127 grass 0  
fill ~1 ~-1 ~128 ~4 ~-1 ~128 grass 0  
fill ~1 ~-1 ~129 ~97 ~-1 ~129 grass 0  
fill ~1 ~-1 ~130 ~97 ~-1 ~130 grass 0  
fill ~1 ~-1 ~131 ~97 ~-1 ~131 grass 0  
fill ~1 ~-1 ~132 ~97 ~-1 ~132 grass 0  
fill ~1 ~-1 ~133 ~97 ~-1 ~133 grass 0  
fill ~1 ~-1 ~134 ~97 ~-1 ~134 grass 0  
fill ~1 ~-1 ~135 ~97 ~-1 ~135 grass 0  
fill ~2 ~-1 ~63 ~2 ~0 ~63 sandstone 2  
fill ~2 ~-1 ~64 ~2 ~0 ~64 sandstone 2  
fill ~2 ~-1 ~65 ~2 ~0 ~65 sandstone 2  
fill ~2 ~-1 ~66 ~2 ~0 ~66 sandstone 2  
fill ~2 ~-1 ~67 ~2 ~0 ~67 sandstone 2  
fill ~2 ~-1 ~68 ~2 ~0 ~68 sandstone 2  
fill ~2 ~-1 ~69 ~2 ~0 ~69 sandstone 2  
fill ~2 ~-1 ~70 ~2 ~0 ~70 sandstone 2  
fill ~2 ~-1 ~71 ~2 ~0 ~71 sandstone 2  
fill ~4 ~-1 ~64 ~9 ~-1 ~64 grass 0  
fill ~4 ~-1 ~65 ~4 ~-1 ~72 grass 0  
fill ~5 ~-1 ~8 ~14 ~-1 ~8 sandstone 2  
fill ~5 ~-1 ~9 ~5 ~-1 ~59 sandstone 2  
fill ~5 ~-1 ~72 ~9 ~-1 ~72 grass 0  
fill ~5 ~-1 ~77 ~5 ~-1 ~128 sandstone 2  
fill ~6 ~-1 ~9 ~14 ~-1 ~9 grass 0  
fill ~6 ~-1 ~10 ~14 ~-1 ~10 grass 0  
fill ~6 ~-1 ~11 ~14 ~-1 ~11 grass 0  
fill ~6 ~-1 ~12 ~14 ~-1 ~12 grass 0  
fill ~6 ~-1 ~13 ~9 ~-1 ~13 grass 0  
fill ~6 ~-1 ~14 ~9 ~-1 ~14 grass 0  
fill ~6 ~-1 ~15 ~9 ~-1 ~15 grass 0  
fill ~6 ~-1 ~16 ~9 ~-1 ~16 grass 0  
fill ~6 ~-1 ~17 ~9 ~-1 ~17 grass 0  
fill ~6 ~-1 ~18 ~9 ~-1 ~18 grass 0  
fill ~6 ~-1 ~19 ~9 ~-1 ~19 grass 0  
fill ~6 ~-1 ~20 ~9 ~-1 ~20 grass 0  
fill ~6 ~-1 ~21 ~9 ~-1 ~21 grass 0  
fill ~6 ~-1 ~22 ~9 ~-1 ~22 grass 0  
fill ~6 ~-1 ~23 ~9 ~-1 ~23 grass 0  
fill ~6 ~-1 ~24 ~9 ~-1 ~24 grass 0  
fill ~6 ~-1 ~25 ~9 ~-1 ~25 grass 0  
fill ~6 ~-1 ~26 ~9 ~-1 ~26 grass 0  
fill ~6 ~-1 ~27 ~9 ~-1 ~27 grass 0  
fill ~6 ~-1 ~28 ~9 ~-1 ~28 grass 0  
fill ~6 ~-1 ~29 ~9 ~-1 ~29 grass 0  
fill ~6 ~-1 ~30 ~9 ~-1 ~30 grass 0  
fill ~6 ~-1 ~31 ~9 ~-1 ~31 grass 0  
fill ~6 ~-1 ~32 ~9 ~-1 ~32 grass 0  
fill ~6 ~-1 ~33 ~9 ~-1 ~33 grass 0  
fill ~6 ~-1 ~34 ~9 ~-1 ~34 grass 0  
fill ~6 ~-1 ~35 ~9 ~-1 ~35 grass 0  
fill ~6 ~-1 ~36 ~9 ~-1 ~36 grass 0  
fill ~6 ~-1 ~37 ~9 ~-1 ~37 grass 0  
fill ~6 ~-1 ~38 ~9 ~-1 ~38 grass 0  
fill ~6 ~-1 ~39 ~9 ~-1 ~39 grass 0  
fill ~6 ~-1 ~40 ~9 ~-1 ~40 grass 0  
fill ~6 ~-1 ~41 ~9 ~-1 ~41 grass 0  
fill ~6 ~-1 ~42 ~9 ~-1 ~42 grass 0  
fill ~6 ~-1 ~43 ~9 ~-1 ~43 grass 0  
fill ~6 ~-1 ~44 ~9 ~-1 ~44 grass 0  
fill ~6 ~-1 ~45 ~9 ~-1 ~45 grass 0  
fill ~6 ~-1 ~46 ~9 ~-1 ~46 grass 0  
fill ~6 ~-1 ~47 ~9 ~-1 ~47 grass 0  
fill ~6 ~-1 ~48 ~9 ~-1 ~48 grass 0  
fill ~6 ~-1 ~49 ~9 ~-1 ~49 grass 0  
fill ~6 ~-1 ~50 ~9 ~-1 ~50 grass 0  
fill ~6 ~-1 ~51 ~9 ~-1 ~51 grass 0  
fill ~6 ~-1 ~52 ~9 ~-1 ~52 grass 0  
fill ~6 ~-1 ~53 ~9 ~-1 ~53 grass 0  
fill ~6 ~-1 ~54 ~9 ~-1 ~54 grass 0  
fill ~6 ~-1 ~55 ~9 ~-1 ~55 grass 0  
fill ~6 ~-1 ~56 ~9 ~-1 ~56 grass 0  
fill ~6 ~-1 ~57 ~9 ~-1 ~57 grass 0  
fill ~6 ~-1 ~58 ~9 ~-1 ~58 grass 0  
fill ~6 ~-1 ~59 ~9 ~-1 ~59 grass 0  
fill ~6 ~-1 ~66 ~7 ~-1 ~66 grass 0  
fill ~6 ~-1 ~67 ~7 ~-1 ~67 grass 0  
fill ~6 ~-1 ~68 ~7 ~-1 ~68 grass 0  
fill ~6 ~-1 ~69 ~7 ~-1 ~69 grass 0  
fill ~6 ~-1 ~70 ~7 ~-1 ~70 grass 0  
fill ~6 ~-1 ~77 ~9 ~-1 ~77 grass 0  
fill ~6 ~-1 ~78 ~9 ~-1 ~78 grass 0  
fill ~6 ~-1 ~79 ~9 ~-1 ~79 grass 0  
fill ~6 ~-1 ~80 ~9 ~-1 ~80 grass 0  
fill ~6 ~-1 ~81 ~9 ~-1 ~81 grass 0  
fill ~6 ~-1 ~82 ~9 ~-1 ~82 grass 0  
fill ~6 ~-1 ~83 ~9 ~-1 ~83 grass 0  
fill ~6 ~-1 ~84 ~9 ~-1 ~84 grass 0  
fill ~6 ~-1 ~85 ~9 ~-1 ~85 grass 0  
fill ~6 ~-1 ~86 ~9 ~-1 ~86 grass 0  
fill ~6 ~-1 ~87 ~9 ~-1 ~87 grass 0  
fill ~6 ~-1 ~88 ~9 ~-1 ~88 grass 0  
fill ~6 ~-1 ~89 ~9 ~-1 ~89 grass 0  
fill ~6 ~-1 ~90 ~9 ~-1 ~90 grass 0  
fill ~6 ~-1 ~91 ~9 ~-1 ~91 grass 0  
fill ~6 ~-1 ~92 ~9 ~-1 ~92 grass 0  
fill ~6 ~-1 ~93 ~9 ~-1 ~93 grass 0  
fill ~6 ~-1 ~94 ~9 ~-1 ~94 grass 0  
fill ~6 ~-1 ~95 ~9 ~-1 ~95 grass 0  
fill ~6 ~-1 ~96 ~9 ~-1 ~96 grass 0  
fill ~6 ~-1 ~97 ~9 ~-1 ~97 grass 0  
fill ~6 ~-1 ~98 ~9 ~-1 ~98 grass 0  
fill ~6 ~-1 ~99 ~9 ~-1 ~99 grass 0  
fill ~6 ~-1 ~100 ~9 ~-1 ~100 grass 0  
fill ~6 ~-1 ~101 ~9 ~-1 ~101 grass 0  
fill ~6 ~-1 ~102 ~9 ~-1 ~102 grass 0  
fill ~6 ~-1 ~103 ~9 ~-1 ~103 grass 0  
fill ~6 ~-1 ~104 ~9 ~-1 ~104 grass 0  
fill ~6 ~-1 ~105 ~9 ~-1 ~105 grass 0  
fill ~6 ~-1 ~106 ~9 ~-1 ~106 grass 0  
fill ~6 ~-1 ~107 ~9 ~-1 ~107 grass 0  
fill ~6 ~-1 ~108 ~9 ~-1 ~108 grass 0  
fill ~6 ~-1 ~109 ~9 ~-1 ~109 grass 0  
fill ~6 ~-1 ~110 ~9 ~-1 ~110 grass 0  
fill ~6 ~-1 ~111 ~9 ~-1 ~111 grass 0  
fill ~6 ~-1 ~112 ~9 ~-1 ~112 grass 0  
fill ~6 ~-1 ~113 ~9 ~-1 ~113 grass 0  
fill ~6 ~-1 ~114 ~9 ~-1 ~114 grass 0  
fill ~6 ~-1 ~115 ~9 ~-1 ~115 grass 0  
fill ~6 ~-1 ~116 ~9 ~-1 ~116 grass 0  
fill ~6 ~-1 ~117 ~9 ~-1 ~117 grass 0  
fill ~6 ~-1 ~118 ~9 ~-1 ~118 grass 0  
fill ~6 ~-1 ~119 ~9 ~-1 ~119 grass 0  
fill ~6 ~-1 ~120 ~9 ~-1 ~120 grass 0  
fill ~6 ~-1 ~121 ~9 ~-1 ~121 grass 0  
fill ~6 ~-1 ~122 ~9 ~-1 ~122 grass 0  
fill ~6 ~-1 ~123 ~9 ~-1 ~123 grass 0  
fill ~6 ~-1 ~124 ~14 ~-1 ~124 grass 0  
fill ~6 ~-1 ~125 ~14 ~-1 ~125 grass 0  
fill ~6 ~-1 ~126 ~14 ~-1 ~126 grass 0  
fill ~6 ~-1 ~127 ~14 ~-1 ~127 grass 0  
fill ~6 ~-1 ~128 ~29 ~-1 ~128 sandstone 2  
fill ~9 ~-1 ~65 ~9 ~-1 ~72 grass 0  
fill ~10 ~-1 ~76 ~10 ~8 ~76 sandstone 2  
fill ~11 ~-1 ~14 ~14 ~-1 ~14 grass 0  
fill ~11 ~-1 ~15 ~14 ~-1 ~15 grass 0  
fill ~11 ~-1 ~16 ~14 ~-1 ~16 grass 0  
fill ~11 ~-1 ~17 ~14 ~-1 ~17 grass 0  
fill ~11 ~-1 ~18 ~14 ~-1 ~18 grass 0  
fill ~11 ~-1 ~19 ~14 ~-1 ~19 grass 0  
fill ~11 ~-1 ~20 ~14 ~-1 ~20 grass 0  
fill ~11 ~-1 ~21 ~14 ~-1 ~21 grass 0  
fill ~11 ~-1 ~22 ~14 ~-1 ~22 grass 0  
fill ~11 ~-1 ~23 ~14 ~-1 ~23 grass 0  
fill ~11 ~-1 ~24 ~14 ~-1 ~24 grass 0  
fill ~11 ~-1 ~25 ~14 ~-1 ~25 grass 0  
fill ~11 ~-1 ~26 ~14 ~-1 ~26 grass 0  
fill ~11 ~-1 ~27 ~14 ~-1 ~27 grass 0  
fill ~11 ~-1 ~28 ~69 ~-1 ~28 grass 0  
fill ~11 ~-1 ~29 ~69 ~-1 ~29 grass 0  
fill ~11 ~-1 ~30 ~16 ~-1 ~30 grass 0  
fill ~11 ~-1 ~31 ~16 ~-1 ~31 grass 0  
fill ~11 ~-1 ~32 ~16 ~-1 ~32 grass 0  
fill ~11 ~-1 ~33 ~16 ~-1 ~33 grass 0  
fill ~11 ~-1 ~34 ~16 ~-1 ~34 grass 0  
fill ~11 ~-1 ~35 ~16 ~-1 ~35 grass 0  
fill ~11 ~-1 ~36 ~16 ~-1 ~36 grass 0  
fill ~11 ~-1 ~37 ~16 ~-1 ~37 grass 0  
fill ~11 ~-1 ~38 ~16 ~-1 ~38 grass 0  
fill ~11 ~-1 ~39 ~16 ~-1 ~39 grass 0  
fill ~11 ~-1 ~40 ~16 ~-1 ~40 grass 0  
fill ~11 ~-1 ~41 ~16 ~-1 ~41 grass 0  
fill ~11 ~-1 ~42 ~16 ~-1 ~42 grass 0  
fill ~11 ~-1 ~43 ~16 ~-1 ~43 grass 0  
fill ~11 ~-1 ~44 ~16 ~-1 ~44 grass 0  
fill ~11 ~-1 ~45 ~16 ~-1 ~45 grass 0  
fill ~11 ~-1 ~46 ~16 ~-1 ~46 grass 0  
fill ~11 ~-1 ~47 ~16 ~-1 ~47 grass 0  
fill ~11 ~-1 ~48 ~16 ~-1 ~48 grass 0  
fill ~11 ~-1 ~49 ~16 ~-1 ~49 grass 0  
fill ~11 ~-1 ~50 ~16 ~-1 ~50 grass 0  
fill ~11 ~-1 ~51 ~16 ~-1 ~51 grass 0  
fill ~11 ~-1 ~52 ~32 ~-1 ~52 grass 0  
fill ~11 ~-1 ~53 ~32 ~-1 ~53 grass 0  
fill ~11 ~-1 ~54 ~32 ~-1 ~54 grass 0  
fill ~11 ~-1 ~55 ~32 ~-1 ~55 grass 0  
fill ~11 ~-1 ~56 ~32 ~-1 ~56 grass 0  
fill ~11 ~-1 ~57 ~32 ~-1 ~57 grass 0  
fill ~11 ~-1 ~58 ~32 ~-1 ~58 grass 0  
fill ~11 ~-1 ~59 ~32 ~-1 ~59 grass 0  
fill ~11 ~-1 ~63 ~11 ~-1 ~122 grass 0  
fill ~12 ~-1 ~76 ~32 ~-1 ~76 grass 0  
fill ~12 ~-1 ~77 ~32 ~-1 ~77 grass 0  
fill ~12 ~-1 ~78 ~32 ~-1 ~78 grass 0  
fill ~12 ~-1 ~79 ~32 ~-1 ~79 grass 0  
fill ~12 ~-1 ~80 ~32 ~-1 ~80 grass 0  
fill ~12 ~-1 ~81 ~32 ~-1 ~81 grass 0  
fill ~12 ~-1 ~82 ~32 ~-1 ~82 grass 0  
fill ~12 ~-1 ~83 ~32 ~-1 ~83 grass 0  
fill ~12 ~-1 ~84 ~32 ~-1 ~84 grass 0  
fill ~12 ~-1 ~85 ~16 ~-1 ~85 grass 0  
fill ~12 ~-1 ~86 ~16 ~-1 ~86 grass 0  
fill ~12 ~-1 ~87 ~16 ~-1 ~87 grass 0  
fill ~12 ~-1 ~88 ~16 ~-1 ~88 grass 0  
fill ~12 ~-1 ~89 ~16 ~-1 ~89 grass 0  
fill ~12 ~-1 ~90 ~16 ~-1 ~90 grass 0  
fill ~12 ~-1 ~91 ~16 ~-1 ~91 grass 0  
fill ~12 ~-1 ~92 ~16 ~-1 ~92 grass 0  
fill ~12 ~-1 ~93 ~16 ~-1 ~93 grass 0  
fill ~12 ~-1 ~94 ~16 ~-1 ~94 grass 0  
fill ~12 ~-1 ~95 ~16 ~-1 ~95 grass 0  
fill ~12 ~-1 ~96 ~16 ~-1 ~96 grass 0  
fill ~12 ~-1 ~97 ~16 ~-1 ~97 grass 0  
fill ~12 ~-1 ~98 ~16 ~-1 ~98 grass 0  
fill ~12 ~-1 ~99 ~16 ~-1 ~99 grass 0  
fill ~12 ~-1 ~100 ~16 ~-1 ~100 grass 0  
fill ~12 ~-1 ~101 ~16 ~-1 ~101 grass 0  
fill ~12 ~-1 ~102 ~16 ~-1 ~102 grass 0  
fill ~12 ~-1 ~103 ~16 ~-1 ~103 grass 0  
fill ~12 ~-1 ~104 ~16 ~-1 ~104 grass 0  
fill ~12 ~-1 ~105 ~16 ~-1 ~105 grass 0  
fill ~12 ~-1 ~106 ~16 ~-1 ~106 grass 0  
fill ~12 ~-1 ~107 ~69 ~-1 ~107 grass 0  
fill ~12 ~-1 ~108 ~69 ~-1 ~108 grass 0  
fill ~12 ~-1 ~109 ~38 ~-1 ~109 grass 0  
fill ~12 ~-1 ~110 ~15 ~-1 ~110 grass 0  
fill ~12 ~-1 ~111 ~14 ~-1 ~111 grass 0  
fill ~12 ~-1 ~112 ~14 ~-1 ~112 grass 0  
fill ~12 ~-1 ~113 ~14 ~-1 ~113 grass 0  
fill ~12 ~-1 ~114 ~14 ~-1 ~114 grass 0  
fill ~12 ~-1 ~115 ~14 ~-1 ~115 grass 0  
fill ~12 ~-1 ~116 ~14 ~-1 ~116 grass 0  
fill ~12 ~-1 ~117 ~14 ~-1 ~117 grass 0  
fill ~12 ~-1 ~118 ~14 ~-1 ~118 grass 0  
fill ~12 ~-1 ~119 ~14 ~-1 ~119 grass 0  
fill ~12 ~-1 ~120 ~14 ~-1 ~120 grass 0  
fill ~12 ~-1 ~121 ~14 ~-1 ~121 grass 0  
fill ~12 ~-1 ~122 ~14 ~-1 ~122 grass 0  
fill ~13 ~-1 ~63 ~17 ~-1 ~63 grass 0  
fill ~13 ~-1 ~64 ~32 ~-1 ~64 grass 0  
fill ~13 ~-1 ~65 ~13 ~-1 ~71 sandstone 2  
fill ~13 ~-1 ~72 ~32 ~-1 ~72 grass 0  
fill ~13 ~-1 ~73 ~17 ~-1 ~73 grass 0  
fill ~14 ~-1 ~65 ~18 ~-1 ~65 double_stone_slab 0  
fill ~14 ~-1 ~66 ~18 ~-1 ~66 double_stone_slab 0  
fill ~14 ~-1 ~67 ~14 ~-1 ~70 double_stone_slab 0  
fill ~14 ~-1 ~71 ~15 ~-1 ~71 stone_slab 8  
fill ~15 ~-1 ~8 ~99 ~-1 ~8 double_stone_slab 0  
fill ~15 ~-1 ~9 ~15 ~-1 ~27 double_stone_slab 0 
setblock ~15 ~-1 ~67 stone_slab 8  
fill ~15 ~-1 ~68 ~15 ~-1 ~70 double_stone_slab 0  
fill ~15 ~-1 ~111 ~15 ~-1 ~112 sandstone 2  
fill ~15 ~-1 ~113 ~15 ~-1 ~127 sandstone 0  
fill ~16 ~-1 ~9 ~42 ~-1 ~9 beacon 0  
fill ~16 ~-1 ~10 ~16 ~-1 ~26 beacon 0  
fill ~16 ~-1 ~27 ~70 ~-1 ~27 double_stone_slab 0  
fill ~16 ~-1 ~67 ~70 ~-1 ~67 sandstone 2  
fill ~16 ~-1 ~68 ~19 ~-1 ~68 sandstone 2  
fill ~16 ~-1 ~70 ~19 ~-1 ~70 sandstone 2  
fill ~16 ~-1 ~71 ~19 ~-1 ~71 sandstone 2  
fill ~16 ~-1 ~110 ~38 ~-1 ~110 stone_slab 8  
fill ~16 ~-1 ~111 ~38 ~-1 ~111 stone_slab 8  
fill ~16 ~-1 ~112 ~38 ~-1 ~112 stone_slab 8  
fill ~16 ~-1 ~113 ~38 ~-1 ~113 stone_slab 8  
fill ~16 ~-1 ~114 ~38 ~-1 ~114 stone_slab 8  
fill ~16 ~-1 ~115 ~38 ~-1 ~115 stone_slab 8  
fill ~16 ~-1 ~116 ~42 ~-1 ~116 beacon 0  
fill ~16 ~-1 ~117 ~42 ~-1 ~117 beacon 0  
fill ~16 ~-1 ~118 ~70 ~-1 ~118 beacon 0  
fill ~16 ~-1 ~119 ~70 ~-1 ~119 beacon 0  
fill ~16 ~-1 ~120 ~42 ~-1 ~120 beacon 0  
fill ~16 ~-1 ~121 ~42 ~-1 ~121 beacon 0  
fill ~16 ~-1 ~122 ~38 ~-1 ~122 stone_slab 8  
fill ~16 ~-1 ~123 ~38 ~-1 ~123 stone_slab 8  
fill ~16 ~-1 ~124 ~38 ~-1 ~124 stone_slab 8  
fill ~16 ~-1 ~125 ~38 ~-1 ~125 stone_slab 8  
fill ~16 ~-1 ~126 ~38 ~-1 ~126 stone_slab 8  
fill ~16 ~-1 ~127 ~38 ~-1 ~127 stone_slab 8 
setblock ~17 ~-1 ~7 redstone_torch 1  
fill ~17 ~-1 ~10 ~43 ~-1 ~10 double_stone_slab 0  
fill ~17 ~-1 ~11 ~43 ~-1 ~11 double_stone_slab 0  
fill ~17 ~-1 ~12 ~18 ~-1 ~12 double_stone_slab 0  
fill ~17 ~-1 ~13 ~18 ~-1 ~13 double_stone_slab 0  
fill ~17 ~-1 ~14 ~18 ~-1 ~14 double_stone_slab 0  
fill ~17 ~-1 ~15 ~18 ~-1 ~15 double_stone_slab 0  
fill ~17 ~-1 ~16 ~18 ~-1 ~16 double_stone_slab 0  
fill ~17 ~-1 ~17 ~18 ~-1 ~17 double_stone_slab 0  
fill ~17 ~-1 ~18 ~18 ~-1 ~18 double_stone_slab 0  
fill ~17 ~-1 ~19 ~18 ~-1 ~19 double_stone_slab 0  
fill ~17 ~-1 ~20 ~18 ~-1 ~20 double_stone_slab 0  
fill ~17 ~-1 ~21 ~18 ~-1 ~21 double_stone_slab 0  
fill ~17 ~-1 ~22 ~18 ~-1 ~22 double_stone_slab 0  
fill ~17 ~-1 ~23 ~18 ~-1 ~23 double_stone_slab 0  
fill ~17 ~-1 ~24 ~43 ~-1 ~24 double_stone_slab 0  
fill ~17 ~-1 ~25 ~43 ~-1 ~25 double_stone_slab 0  
fill ~17 ~-1 ~26 ~42 ~-1 ~26 beacon 0  
fill ~17 ~-1 ~30 ~39 ~-1 ~30 sandstone 2  
fill ~17 ~-1 ~31 ~17 ~-1 ~51 sandstone 2  
fill ~17 ~-1 ~69 ~70 ~-1 ~69 sandstone 2  
fill ~17 ~-1 ~85 ~39 ~-1 ~85 sandstone 2  
fill ~17 ~-1 ~86 ~17 ~-1 ~106 sandstone 2  
fill ~18 ~-1 ~7 ~44 ~-1 ~7 stonebrick 0  
fill ~18 ~-1 ~51 ~39 ~-1 ~51 sandstone 2  
fill ~18 ~-1 ~106 ~39 ~-1 ~106 sandstone 2  
fill ~19 ~-1 ~12 ~40 ~-1 ~12 stone_slab 0  
fill ~19 ~-1 ~13 ~19 ~-1 ~23 stone_slab 0  
fill ~19 ~-1 ~65 ~19 ~-1 ~71 sandstone 2  
fill ~20 ~-1 ~23 ~40 ~-1 ~23 stone_slab 0  
fill ~20 ~-1 ~65 ~24 ~-1 ~65 stone_slab 8  
fill ~20 ~-1 ~66 ~20 ~-1 ~65 stone_slab 8  
fill ~20 ~-1 ~68 ~21 ~-1 ~68 double_stone_slab 0  
fill ~20 ~-1 ~70 ~24 ~-1 ~70 double_stone_slab 0  
fill ~20 ~-1 ~71 ~24 ~-1 ~71 double_stone_slab 0  
fill ~21 ~-1 ~62 ~23 ~-1 ~62 grass 0  
fill ~21 ~-1 ~63 ~23 ~-1 ~63 grass 0 
setblock ~21 ~-1 ~66 double_stone_slab 8  
fill ~21 ~-1 ~73 ~23 ~-1 ~73 grass 0  
fill ~21 ~-1 ~74 ~23 ~-1 ~74 grass 0  
fill ~22 ~-1 ~66 ~23 ~-1 ~66 double_stone_slab 0 
setblock ~22 ~-1 ~68 beacon 0  
fill ~23 ~-1 ~68 ~27 ~-1 ~68 double_stone_slab 0 
setblock ~24 ~-1 ~66 stone_slab 8  
fill ~25 ~-1 ~65 ~25 ~-1 ~67 sandstone 2  
fill ~25 ~-1 ~70 ~25 ~-1 ~71 sandstone 2  
fill ~26 ~-1 ~65 ~30 ~-1 ~65 double_stone_slab 0  
fill ~26 ~-1 ~66 ~30 ~-1 ~66 double_stone_slab 0  
fill ~26 ~-1 ~70 ~30 ~-1 ~70 double_stone_slab 0  
fill ~26 ~-1 ~71 ~30 ~-1 ~71 double_stone_slab 0  
fill ~27 ~-1 ~62 ~29 ~-1 ~62 grass 0  
fill ~27 ~-1 ~63 ~29 ~-1 ~63 grass 0  
fill ~27 ~-1 ~73 ~29 ~-1 ~73 grass 0  
fill ~27 ~-1 ~74 ~29 ~-1 ~74 grass 0 
setblock ~28 ~-1 ~68 beacon 0  
fill ~29 ~-1 ~68 ~33 ~-1 ~68 double_stone_slab 0  
fill ~30 ~-1 ~128 ~38 ~-1 ~128 grass 0  
fill ~31 ~-1 ~65 ~31 ~-1 ~67 sandstone 2  
fill ~31 ~-1 ~70 ~31 ~-1 ~71 sandstone 2  
fill ~32 ~-1 ~65 ~36 ~-1 ~65 double_stone_slab 0  
fill ~32 ~-1 ~66 ~36 ~-1 ~66 double_stone_slab 0  
fill ~32 ~-1 ~70 ~36 ~-1 ~70 double_stone_slab 0  
fill ~32 ~-1 ~71 ~36 ~-1 ~71 double_stone_slab 0 
setblock ~33 ~-1 ~1 redstone_torch 0  
fill ~33 ~-1 ~2 ~37 ~-1 ~2 double_stone_slab 0  
fill ~33 ~-1 ~6 ~37 ~-1 ~6 double_stone_slab 0  
fill ~33 ~-1 ~52 ~33 ~-1 ~64 sandstone 2  
fill ~33 ~-1 ~72 ~34 ~-1 ~72 sandstone 2  
fill ~33 ~-1 ~73 ~33 ~-1 ~85 sandstone 2  
fill ~34 ~-1 ~1 ~36 ~-1 ~1 stonebrick 0  
fill ~34 ~-1 ~52 ~36 ~-1 ~52 double_stone_slab 0  
fill ~34 ~-1 ~53 ~34 ~-1 ~63 double_stone_slab 0 
setblock ~34 ~-1 ~64 sandstone 2 
setblock ~34 ~-1 ~68 beacon 0  
fill ~34 ~-1 ~73 ~36 ~-1 ~73 double_stone_slab 0  
fill ~34 ~-1 ~74 ~34 ~-1 ~84 double_stone_slab 0  
fill ~35 ~-1 ~53 ~35 ~-1 ~62 beacon 0  
fill ~35 ~-1 ~63 ~36 ~-1 ~63 double_stone_slab 0 
setblock ~35 ~-1 ~64 stone_slab 8  
fill ~35 ~-1 ~68 ~39 ~-1 ~68 double_stone_slab 0 
setblock ~35 ~-1 ~72 double_stone_slab 0  
fill ~35 ~-1 ~74 ~35 ~-1 ~83 beacon 0  
fill ~35 ~-1 ~84 ~36 ~-1 ~84 double_stone_slab 0  
fill ~36 ~-1 ~53 ~36 ~-1 ~63 double_stone_slab 0  
fill ~36 ~-1 ~64 ~37 ~-1 ~64 sandstone 2  
fill ~36 ~-1 ~72 ~37 ~-1 ~72 sandstone 2  
fill ~36 ~-1 ~74 ~36 ~-1 ~84 double_stone_slab 0  
fill ~37 ~-1 ~1 ~37 ~-1 ~1 double_stone_slab 0  
fill ~37 ~-1 ~52 ~37 ~-1 ~67 sandstone 2  
fill ~37 ~-1 ~70 ~37 ~-1 ~85 sandstone 2  
fill ~38 ~-1 ~1 ~40 ~-1 ~1 stone_slab 0  
fill ~38 ~-1 ~2 ~40 ~-1 ~2 stone_slab 0  
fill ~38 ~-1 ~6 ~40 ~-1 ~6 stone_slab 0  
fill ~38 ~-1 ~52 ~49 ~-1 ~52 grass 0  
fill ~38 ~-1 ~53 ~49 ~-1 ~53 grass 0  
fill ~38 ~-1 ~54 ~49 ~-1 ~54 grass 0  
fill ~38 ~-1 ~55 ~49 ~-1 ~55 grass 0  
fill ~38 ~-1 ~56 ~49 ~-1 ~56 grass 0  
fill ~38 ~-1 ~57 ~49 ~-1 ~57 grass 0  
fill ~38 ~-1 ~58 ~49 ~-1 ~58 grass 0  
fill ~38 ~-1 ~59 ~49 ~-1 ~59 grass 0  
fill ~38 ~-1 ~60 ~49 ~-1 ~60 grass 0  
fill ~38 ~-1 ~61 ~49 ~-1 ~61 grass 0  
fill ~38 ~-1 ~62 ~49 ~-1 ~62 grass 0  
fill ~38 ~-1 ~63 ~49 ~-1 ~63 grass 0  
fill ~38 ~-1 ~64 ~49 ~-1 ~64 grass 0  
fill ~38 ~-1 ~65 ~42 ~-1 ~65 double_stone_slab 0  
fill ~38 ~-1 ~66 ~42 ~-1 ~66 double_stone_slab 0  
fill ~38 ~-1 ~70 ~42 ~-1 ~70 double_stone_slab 0  
fill ~38 ~-1 ~71 ~42 ~-1 ~71 double_stone_slab 0  
fill ~38 ~-1 ~72 ~49 ~-1 ~72 grass 0  
fill ~38 ~-1 ~73 ~49 ~-1 ~73 grass 0  
fill ~38 ~-1 ~74 ~49 ~-1 ~74 grass 0  
fill ~38 ~-1 ~75 ~49 ~-1 ~75 grass 0  
fill ~38 ~-1 ~76 ~49 ~-1 ~76 grass 0  
fill ~38 ~-1 ~77 ~49 ~-1 ~77 grass 0  
fill ~38 ~-1 ~78 ~49 ~-1 ~78 grass 0  
fill ~38 ~-1 ~79 ~49 ~-1 ~79 grass 0  
fill ~38 ~-1 ~80 ~49 ~-1 ~80 grass 0  
fill ~38 ~-1 ~81 ~49 ~-1 ~81 grass 0  
fill ~38 ~-1 ~82 ~49 ~-1 ~82 grass 0  
fill ~38 ~-1 ~83 ~49 ~-1 ~83 grass 0  
fill ~38 ~-1 ~84 ~49 ~-1 ~84 grass 0  
fill ~39 ~-1 ~31 ~39 ~-1 ~51 sandstone 2  
fill ~39 ~-1 ~86 ~39 ~-1 ~106 sandstone 2  
fill ~39 ~-1 ~109 ~70 ~-1 ~109 double_stone_slab 0  
fill ~39 ~-1 ~110 ~42 ~-1 ~110 beacon 0  
fill ~39 ~-1 ~111 ~39 ~-1 ~110 beacon 0  
fill ~39 ~-1 ~112 ~43 ~-1 ~112 double_stone_slab 0  
fill ~39 ~-1 ~113 ~43 ~-1 ~113 double_stone_slab 0  
fill ~39 ~-1 ~114 ~43 ~-1 ~114 double_stone_slab 0  
fill ~39 ~-1 ~115 ~43 ~-1 ~115 double_stone_slab 0  
fill ~39 ~-1 ~122 ~43 ~-1 ~122 double_stone_slab 0  
fill ~39 ~-1 ~123 ~43 ~-1 ~123 double_stone_slab 0  
fill ~39 ~-1 ~124 ~43 ~-1 ~124 double_stone_slab 0  
fill ~39 ~-1 ~125 ~43 ~-1 ~125 double_stone_slab 0  
fill ~39 ~-1 ~126 ~39 ~-1 ~127 beacon 0  
fill ~39 ~-1 ~128 ~99 ~-1 ~128 double_stone_slab 0  
fill ~40 ~-1 ~13 ~40 ~-1 ~23 stone_slab 0  
fill ~40 ~-1 ~30 ~44 ~-1 ~30 grass 0  
fill ~40 ~-1 ~31 ~44 ~-1 ~31 grass 0  
fill ~40 ~-1 ~32 ~44 ~-1 ~32 grass 0  
fill ~40 ~-1 ~33 ~44 ~-1 ~33 grass 0  
fill ~40 ~-1 ~34 ~44 ~-1 ~34 grass 0  
fill ~40 ~-1 ~35 ~44 ~-1 ~35 grass 0  
fill ~40 ~-1 ~36 ~44 ~-1 ~36 grass 0  
fill ~40 ~-1 ~37 ~44 ~-1 ~37 grass 0  
fill ~40 ~-1 ~38 ~44 ~-1 ~38 grass 0  
fill ~40 ~-1 ~39 ~44 ~-1 ~39 grass 0  
fill ~40 ~-1 ~40 ~44 ~-1 ~40 grass 0  
fill ~40 ~-1 ~41 ~44 ~-1 ~41 grass 0  
fill ~40 ~-1 ~42 ~44 ~-1 ~42 grass 0  
fill ~40 ~-1 ~43 ~44 ~-1 ~43 grass 0  
fill ~40 ~-1 ~44 ~44 ~-1 ~44 grass 0  
fill ~40 ~-1 ~45 ~44 ~-1 ~45 grass 0  
fill ~40 ~-1 ~46 ~44 ~-1 ~46 grass 0  
fill ~40 ~-1 ~47 ~44 ~-1 ~47 grass 0  
fill ~40 ~-1 ~48 ~44 ~-1 ~48 grass 0  
fill ~40 ~-1 ~49 ~44 ~-1 ~49 grass 0  
fill ~40 ~-1 ~50 ~44 ~-1 ~50 grass 0  
fill ~40 ~-1 ~51 ~44 ~-1 ~51 grass 0 
setblock ~40 ~-1 ~68 beacon 0  
fill ~40 ~-1 ~85 ~44 ~-1 ~85 grass 0  
fill ~40 ~-1 ~86 ~44 ~-1 ~86 grass 0  
fill ~40 ~-1 ~87 ~44 ~-1 ~87 grass 0  
fill ~40 ~-1 ~88 ~44 ~-1 ~88 grass 0  
fill ~40 ~-1 ~89 ~44 ~-1 ~89 grass 0  
fill ~40 ~-1 ~90 ~44 ~-1 ~90 grass 0  
fill ~40 ~-1 ~91 ~44 ~-1 ~91 grass 0  
fill ~40 ~-1 ~92 ~44 ~-1 ~92 grass 0  
fill ~40 ~-1 ~93 ~44 ~-1 ~93 grass 0  
fill ~40 ~-1 ~94 ~44 ~-1 ~94 grass 0  
fill ~40 ~-1 ~95 ~44 ~-1 ~95 grass 0  
fill ~40 ~-1 ~96 ~44 ~-1 ~96 grass 0  
fill ~40 ~-1 ~97 ~44 ~-1 ~97 grass 0  
fill ~40 ~-1 ~98 ~44 ~-1 ~98 grass 0  
fill ~40 ~-1 ~99 ~44 ~-1 ~99 grass 0  
fill ~40 ~-1 ~100 ~44 ~-1 ~100 grass 0  
fill ~40 ~-1 ~101 ~44 ~-1 ~101 grass 0  
fill ~40 ~-1 ~102 ~44 ~-1 ~102 grass 0  
fill ~40 ~-1 ~103 ~44 ~-1 ~103 grass 0  
fill ~40 ~-1 ~104 ~44 ~-1 ~104 grass 0  
fill ~40 ~-1 ~105 ~44 ~-1 ~105 grass 0   
fill ~40 ~-1 ~106 ~44 ~-1 ~106 grass 0  
fill ~40 ~-1 ~111 ~43 ~-1 ~111 double_stone_slab 0 
setblock ~40 ~-1 ~126 double_stone_slab 0  
fill ~40 ~-1 ~127 ~42 ~-1 ~127 beacon 0  
fill ~41 ~-1 ~1 ~41 ~-1 ~2 double_stone_slab 0  
fill ~41 ~-1 ~6 ~45 ~-1 ~6 double_stone_slab 0  
fill ~41 ~-1 ~12 ~43 ~-1 ~12 double_stone_slab 0  
fill ~41 ~-1 ~13 ~43 ~-1 ~13 double_stone_slab 0  
fill ~41 ~-1 ~14 ~43 ~-1 ~14 double_stone_slab 0  
fill ~41 ~-1 ~15 ~43 ~-1 ~15 double_stone_slab 0  
fill ~41 ~-1 ~16 ~43 ~-1 ~16 double_stone_slab 0  
fill ~41 ~-1 ~17 ~43 ~-1 ~17 double_stone_slab 0  
fill ~41 ~-1 ~18 ~43 ~-1 ~18 double_stone_slab 0  
fill ~41 ~-1 ~19 ~43 ~-1 ~19 double_stone_slab 0  
fill ~41 ~-1 ~20 ~43 ~-1 ~20 double_stone_slab 0  
fill ~41 ~-1 ~21 ~43 ~-1 ~21 double_stone_slab 0  
fill ~41 ~-1 ~22 ~43 ~-1 ~22 double_stone_slab 0  
fill ~41 ~-1 ~23 ~43 ~-1 ~23 double_stone_slab 0  
fill ~41 ~-1 ~68 ~45 ~-1 ~68 double_stone_slab 0 
setblock ~41 ~-1 ~126 stone_slab 8  
fill ~42 ~-1 ~1 ~44 ~-1 ~1 stonebrick 0  
fill ~42 ~-1 ~2 ~45 ~-1 ~2 double_stone_slab 0  
fill ~42 ~-1 ~126 ~43 ~-1 ~126 double_stone_slab 0 
setblock ~43 ~-1 ~9 double_stone_slab 0 
setblock ~43 ~-1 ~26 double_stone_slab 0  
fill ~43 ~-1 ~65 ~43 ~-1 ~67 sandstone 2  
fill ~43 ~-1 ~70 ~43 ~-1 ~71 sandstone 2 
setblock ~43 ~-1 ~110 double_stone_slab 0  
fill ~43 ~-1 ~116 ~43 ~-1 ~117 double_stone_slab 0  
fill ~43 ~-1 ~120 ~43 ~-1 ~128 double_stone_slab 0  
fill ~44 ~-1 ~9 ~98 ~-1 ~9 beacon 0  
fill ~44 ~-1 ~10 ~44 ~-1 ~26 beacon 0  
fill ~44 ~-1 ~65 ~48 ~-1 ~65 double_stone_slab 0  
fill ~44 ~-1 ~66 ~48 ~-1 ~66 double_stone_slab 0  
fill ~44 ~-1 ~70 ~48 ~-1 ~70 double_stone_slab 0  
fill ~44 ~-1 ~71 ~48 ~-1 ~71 double_stone_slab 0  
fill ~44 ~-1 ~110 ~71 ~-1 ~110 beacon 0  
fill ~44 ~-1 ~111 ~44 ~-1 ~127 beacon 0 
setblock ~45 ~-1 ~1 redstone_torch 0 
setblock ~45 ~-1 ~7 redstone_torch 1  
fill ~45 ~-1 ~10 ~97 ~-1 ~10 double_stone_slab 0  
fill ~45 ~-1 ~11 ~72 ~-1 ~11 double_stone_slab 0  
fill ~45 ~-1 ~12 ~46 ~-1 ~12 double_stone_slab 0  
fill ~45 ~-1 ~13 ~46 ~-1 ~13 double_stone_slab 0  
fill ~45 ~-1 ~14 ~46 ~-1 ~14 double_stone_slab 0  
fill ~45 ~-1 ~15 ~46 ~-1 ~15 double_stone_slab 0  
fill ~45 ~-1 ~16 ~46 ~-1 ~16 double_stone_slab 0  
fill ~45 ~-1 ~17 ~46 ~-1 ~17 double_stone_slab 0  
fill ~45 ~-1 ~18 ~46 ~-1 ~18 double_stone_slab 0  
fill ~45 ~-1 ~19 ~46 ~-1 ~19 double_stone_slab 0  
fill ~45 ~-1 ~20 ~46 ~-1 ~20 double_stone_slab 0  
fill ~45 ~-1 ~21 ~46 ~-1 ~21 double_stone_slab 0  
fill ~45 ~-1 ~22 ~46 ~-1 ~22 double_stone_slab 0  
fill ~45 ~-1 ~23 ~46 ~-1 ~23 double_stone_slab 0  
fill ~45 ~-1 ~24 ~72 ~-1 ~24 double_stone_slab 0  
fill ~45 ~-1 ~25 ~72 ~-1 ~25 double_stone_slab 0  
fill ~45 ~-1 ~26 ~71 ~-1 ~26 beacon 0  
fill ~45 ~-1 ~30 ~67 ~-1 ~30 sandstone 2  
fill ~45 ~-1 ~31 ~45 ~-1 ~51 sandstone 2  
fill ~45 ~-1 ~85 ~50 ~-1 ~85 sandstone 2  
fill ~45 ~-1 ~86 ~45 ~-1 ~106 sandstone 2  
fill ~45 ~-1 ~111 ~48 ~-1 ~111 double_stone_slab 0  
fill ~45 ~-1 ~112 ~54 ~-1 ~112 double_stone_slab 0  
fill ~45 ~-1 ~113 ~79 ~-1 ~113 double_stone_slab 0  
fill ~45 ~-1 ~114 ~79 ~-1 ~114 double_stone_slab 0  
fill ~45 ~-1 ~115 ~79 ~-1 ~115 double_stone_slab 0  
fill ~45 ~-1 ~116 ~47 ~-1 ~116 double_stone_slab 0  
fill ~45 ~-1 ~117 ~47 ~-1 ~117 double_stone_slab 0  
fill ~45 ~-1 ~120 ~47 ~-1 ~120 double_stone_slab 0  
fill ~45 ~-1 ~121 ~47 ~-1 ~121 double_stone_slab 0  
fill ~45 ~-1 ~122 ~85 ~-1 ~122 double_stone_slab 0  
fill ~45 ~-1 ~123 ~96 ~-1 ~123 double_stone_slab 0  
fill ~45 ~-1 ~124 ~97 ~-1 ~124 double_stone_slab 0  
fill ~45 ~-1 ~125 ~97 ~-1 ~125 double_stone_slab 0  
fill ~45 ~-1 ~126 ~48 ~-1 ~126 double_stone_slab 0  
fill ~45 ~-1 ~127 ~98 ~-1 ~127 beacon 0  
fill ~46 ~-1 ~1 ~96 ~-1 ~1 stonebrick 0  
fill ~46 ~-1 ~2 ~96 ~-1 ~2 stone_slab 0  
fill ~46 ~-1 ~6 ~96 ~-1 ~6 stone_slab 0  
fill ~46 ~-1 ~7 ~96 ~-1 ~7 stonebrick 0  
fill ~46 ~-1 ~51 ~50 ~-1 ~51 sandstone 2 
setblock ~46 ~-1 ~68 beacon 0  
fill ~46 ~-1 ~106 ~67 ~-1 ~106 sandstone 2  
fill ~47 ~-1 ~12 ~68 ~-1 ~12 stone_slab 0  
fill ~47 ~-1 ~13 ~47 ~-1 ~23 stone_slab 0  
fill ~47 ~-1 ~68 ~51 ~-1 ~68 double_stone_slab 0  
fill ~48 ~-1 ~23 ~68 ~-1 ~23 stone_slab 0  
fill ~48 ~-1 ~116 ~70 ~-1 ~116 beacon 0  
fill ~48 ~-1 ~117 ~70 ~-1 ~117 beacon 0  
fill ~48 ~-1 ~120 ~70 ~-1 ~120 beacon 0  
fill ~48 ~-1 ~121 ~70 ~-1 ~121 beacon 0  
fill ~49 ~-1 ~65 ~49 ~-1 ~67 sandstone 2  
fill ~49 ~-1 ~70 ~49 ~-1 ~71 sandstone 2 
setblock ~49 ~-1 ~111 beacon 0 
setblock ~49 ~-1 ~126 beacon 0  
fill ~50 ~-1 ~52 ~50 ~-1 ~64 sandstone 2  
fill ~50 ~-1 ~65 ~54 ~-1 ~65 double_stone_slab 0  
fill ~50 ~-1 ~66 ~54 ~-1 ~66 double_stone_slab 0  
fill ~50 ~-1 ~70 ~54 ~-1 ~70 double_stone_slab 0  
fill ~50 ~-1 ~71 ~54 ~-1 ~71 double_stone_slab 0  
fill ~50 ~-1 ~72 ~51 ~-1 ~72 sandstone 2  
fill ~50 ~-1 ~73 ~50 ~-1 ~85 sandstone 2  
fill ~50 ~-1 ~111 ~54 ~-1 ~111 double_stone_slab 0  
fill ~50 ~-1 ~126 ~54 ~-1 ~126 double_stone_slab 0  
fill ~51 ~-1 ~51 ~53 ~-1 ~51 stone_brick_stairs 2  
fill ~51 ~-1 ~52 ~53 ~-1 ~52 double_stone_slab 0  
fill ~51 ~-1 ~53 ~51 ~-1 ~63 double_stone_slab 0 
setblock ~51 ~-1 ~64 sandstone 2  
fill ~51 ~-1 ~73 ~53 ~-1 ~73 double_stone_slab 0  
fill ~51 ~-1 ~74 ~51 ~-1 ~84 double_stone_slab 0  
fill ~51 ~-1 ~85 ~53 ~-1 ~85 stone_brick_stairs 3  
fill ~52 ~-1 ~53 ~52 ~-1 ~62 beacon 0  
fill ~52 ~-1 ~63 ~53 ~-1 ~63 double_stone_slab 0  
fill ~52 ~-1 ~64 ~52 ~-1 ~63 double_stone_slab 0 
setblock ~52 ~-1 ~68 beacon 0 
setblock ~52 ~-1 ~72 double_stone_slab 0  
fill ~52 ~-1 ~74 ~52 ~-1 ~83 beacon 0  
fill ~52 ~-1 ~84 ~53 ~-1 ~84 double_stone_slab 0  
fill ~53 ~-1 ~53 ~53 ~-1 ~63 double_stone_slab 0  
fill ~53 ~-1 ~64 ~61 ~-1 ~64 sandstone 2  
fill ~53 ~-1 ~68 ~57 ~-1 ~68 double_stone_slab 0  
fill ~53 ~-1 ~72 ~61 ~-1 ~72 sandstone 2  
fill ~53 ~-1 ~74 ~53 ~-1 ~84 double_stone_slab 0  
fill ~54 ~-1 ~51 ~67 ~-1 ~51 sandstone 2  
fill ~54 ~-1 ~52 ~54 ~-1 ~64 sandstone 2  
fill ~54 ~-1 ~73 ~54 ~-1 ~85 sandstone 2  
fill ~55 ~-1 ~52 ~69 ~-1 ~52 grass 0  
fill ~55 ~-1 ~53 ~69 ~-1 ~53 grass 0  
fill ~55 ~-1 ~54 ~69 ~-1 ~54 grass 0  
fill ~55 ~-1 ~55 ~69 ~-1 ~55 grass 0  
fill ~55 ~-1 ~56 ~60 ~-1 ~56 grass 0  
fill ~55 ~-1 ~57 ~60 ~-1 ~57 grass 0  
fill ~55 ~-1 ~58 ~60 ~-1 ~58 grass 0  
fill ~55 ~-1 ~59 ~60 ~-1 ~59 grass 0  
fill ~55 ~-1 ~60 ~60 ~-1 ~60 grass 0  
fill ~55 ~-1 ~61 ~60 ~-1 ~61 grass 0  
fill ~55 ~-1 ~62 ~60 ~-1 ~62 grass 0  
fill ~55 ~-1 ~63 ~60 ~-1 ~63 grass 0  
fill ~55 ~-1 ~65 ~55 ~-1 ~67 sandstone 2  
fill ~55 ~-1 ~70 ~55 ~-1 ~72 sandstone 2  
fill ~55 ~-1 ~73 ~60 ~-1 ~73 grass 0  
fill ~55 ~-1 ~74 ~60 ~-1 ~74 grass 0  
fill ~55 ~-1 ~75 ~60 ~-1 ~75 grass 0  
fill ~55 ~-1 ~76 ~60 ~-1 ~76 grass 0  
fill ~55 ~-1 ~77 ~60 ~-1 ~77 grass 0  
fill ~55 ~-1 ~78 ~60 ~-1 ~78 grass 0  
fill ~55 ~-1 ~79 ~60 ~-1 ~79 grass 0  
fill ~55 ~-1 ~80 ~60 ~-1 ~80 grass 0  
fill ~55 ~-1 ~81 ~69 ~-1 ~81 grass 0  
fill ~55 ~-1 ~82 ~69 ~-1 ~82 grass 0  
fill ~55 ~-1 ~83 ~69 ~-1 ~83 grass 0  
fill ~55 ~-1 ~84 ~69 ~-1 ~84 grass 0  
fill ~55 ~-1 ~85 ~67 ~-1 ~85 sandstone 2 
setblock ~55 ~-1 ~111 beacon 0 
setblock ~55 ~-1 ~112 stone_slab 8 
setblock ~55 ~-1 ~126 beacon 0  
fill ~56 ~-1 ~65 ~60 ~-1 ~65 double_stone_slab 0  
fill ~56 ~-1 ~66 ~60 ~-1 ~66 double_stone_slab 0  
fill ~56 ~-1 ~70 ~60 ~-1 ~70 double_stone_slab 0  
fill ~56 ~-1 ~71 ~60 ~-1 ~71 double_stone_slab 0  
fill ~56 ~-1 ~111 ~60 ~-1 ~111 double_stone_slab 0  
fill ~56 ~-1 ~112 ~79 ~-1 ~112 double_stone_slab 0  
fill ~56 ~-1 ~126 ~60 ~-1 ~126 double_stone_slab 0 
setblock ~58 ~-1 ~68 beacon 0 
setblock ~59 ~-1 ~68 double_stone_slab 0 
setblock ~60 ~-1 ~68 stone_slab 8  
fill ~61 ~-1 ~56 ~69 ~-1 ~56 sandstone 2  
fill ~61 ~-1 ~57 ~61 ~-1 ~67 sandstone 2  
fill ~61 ~-1 ~68 ~62 ~-1 ~68 double_stone_slab 0  
fill ~61 ~-1 ~70 ~61 ~-1 ~80 sandstone 2 
setblock ~61 ~-1 ~111 beacon 0 
setblock ~61 ~-1 ~126 beacon 0 
setblock ~62 ~-1 ~57 glowstone 0  
fill ~62 ~-1 ~58 ~62 ~-1 ~66 double_stone_slab 0  
fill ~62 ~-1 ~70 ~64 ~-1 ~70 double_stone_slab 0  
fill ~62 ~-1 ~71 ~62 ~-1 ~78 double_stone_slab 0 
setblock ~62 ~-1 ~79 glowstone 0  
fill ~62 ~-1 ~80 ~69 ~-1 ~80 sandstone 2  
fill ~62 ~-1 ~111 ~66 ~-1 ~111 double_stone_slab 0  
fill ~62 ~-1 ~126 ~66 ~-1 ~126 double_stone_slab 0  
fill ~63 ~-1 ~57 ~68 ~-1 ~57 double_stone_slab 0  
fill ~63 ~-1 ~58 ~63 ~-1 ~65 beacon 0  
fill ~63 ~-1 ~66 ~64 ~-1 ~66 double_stone_slab 0 
setblock ~63 ~-1 ~68 beacon 0  
fill ~63 ~-1 ~71 ~63 ~-1 ~78 beacon 0  
fill ~63 ~-1 ~79 ~68 ~-1 ~79 double_stone_slab 0  
fill ~64 ~-1 ~58 ~70 ~-1 ~58 double_stone_slab 0  
fill ~64 ~-1 ~59 ~71 ~-1 ~59 double_stone_slab 0  
fill ~64 ~-1 ~60 ~64 ~-1 ~66 double_stone_slab 0  
fill ~64 ~-1 ~68 ~68 ~-1 ~68 double_stone_slab 0  
fill ~64 ~-1 ~71 ~64 ~-1 ~79 double_stone_slab 0  
fill ~65 ~-1 ~60 ~69 ~-1 ~60 sandstone 2  
fill ~65 ~-1 ~61 ~65 ~-1 ~67 sandstone 2  
fill ~65 ~-1 ~70 ~65 ~-1 ~76 sandstone 2  
fill ~65 ~-1 ~77 ~84 ~-1 ~77 double_stone_slab 0  
fill ~65 ~-1 ~78 ~83 ~-1 ~78 double_stone_slab 0  
fill ~66 ~-1 ~61 ~69 ~-1 ~61 grass 0  
fill ~66 ~-1 ~62 ~69 ~-1 ~62 grass 0  
fill ~66 ~-1 ~63 ~69 ~-1 ~63 grass 0  
fill ~66 ~-1 ~64 ~69 ~-1 ~64 grass 0  
fill ~66 ~-1 ~65 ~70 ~-1 ~65 sandstone 2  
fill ~66 ~-1 ~66 ~83 ~-1 ~66 double_stone_slab 0  
fill ~66 ~-1 ~70 ~83 ~-1 ~70 double_stone_slab 0  
fill ~66 ~-1 ~71 ~70 ~-1 ~71 sandstone 2  
fill ~66 ~-1 ~72 ~69 ~-1 ~72 grass 0  
fill ~66 ~-1 ~73 ~69 ~-1 ~73 grass 0  
fill ~66 ~-1 ~74 ~69 ~-1 ~74 grass 0  
fill ~66 ~-1 ~75 ~69 ~-1 ~75 grass 0  
fill ~66 ~-1 ~76 ~69 ~-1 ~76 sandstone 2  
fill ~67 ~-1 ~31 ~67 ~-1 ~51 sandstone 2  
fill ~67 ~-1 ~86 ~67 ~-1 ~106 sandstone 2 
setblock ~67 ~-1 ~111 beacon 0 
setblock ~67 ~-1 ~126 beacon 0  
fill ~68 ~-1 ~13 ~68 ~-1 ~23 stone_slab 0  
fill ~68 ~-1 ~30 ~69 ~-1 ~30 grass 0  
fill ~68 ~-1 ~31 ~69 ~-1 ~31 grass 0  
fill ~68 ~-1 ~32 ~69 ~-1 ~32 grass 0  
fill ~68 ~-1 ~33 ~69 ~-1 ~33 grass 0  
fill ~68 ~-1 ~34 ~69 ~-1 ~34 grass 0  
fill ~68 ~-1 ~35 ~69 ~-1 ~35 grass 0  
fill ~68 ~-1 ~36 ~69 ~-1 ~36 grass 0  
fill ~68 ~-1 ~37 ~69 ~-1 ~37 grass 0  
fill ~68 ~-1 ~38 ~69 ~-1 ~38 grass 0  
fill ~68 ~-1 ~39 ~69 ~-1 ~39 grass 0  
fill ~68 ~-1 ~40 ~69 ~-1 ~40 grass 0  
fill ~68 ~-1 ~41 ~69 ~-1 ~41 grass 0  
fill ~68 ~-1 ~42 ~69 ~-1 ~42 grass 0  
fill ~68 ~-1 ~43 ~69 ~-1 ~43 grass 0  
fill ~68 ~-1 ~44 ~69 ~-1 ~44 grass 0  
fill ~68 ~-1 ~45 ~69 ~-1 ~45 grass 0  
fill ~68 ~-1 ~46 ~69 ~-1 ~46 grass 0  
fill ~68 ~-1 ~47 ~69 ~-1 ~47 grass 0  
fill ~68 ~-1 ~48 ~69 ~-1 ~48 grass 0  
fill ~68 ~-1 ~49 ~69 ~-1 ~49 grass 0  
fill ~68 ~-1 ~50 ~69 ~-1 ~50 grass 0  
fill ~68 ~-1 ~51 ~69 ~-1 ~51 grass 0  
fill ~68 ~-1 ~85 ~69 ~-1 ~85 grass 0  
fill ~68 ~-1 ~86 ~69 ~-1 ~86 grass 0  
fill ~68 ~-1 ~87 ~69 ~-1 ~87 grass 0  
fill ~68 ~-1 ~88 ~69 ~-1 ~88 grass 0  
fill ~68 ~-1 ~89 ~69 ~-1 ~89 grass 0  
fill ~68 ~-1 ~90 ~69 ~-1 ~90 grass 0  
fill ~68 ~-1 ~91 ~69 ~-1 ~91 grass 0  
fill ~68 ~-1 ~92 ~69 ~-1 ~92 grass 0  
fill ~68 ~-1 ~93 ~69 ~-1 ~93 grass 0  
fill ~68 ~-1 ~94 ~69 ~-1 ~94 grass 0  
fill ~68 ~-1 ~95 ~69 ~-1 ~95 grass 0  
fill ~68 ~-1 ~96 ~69 ~-1 ~96 grass 0  
fill ~68 ~-1 ~97 ~69 ~-1 ~97 grass 0  
fill ~68 ~-1 ~98 ~69 ~-1 ~98 grass 0  
fill ~68 ~-1 ~99 ~69 ~-1 ~99 grass 0  
fill ~68 ~-1 ~100 ~69 ~-1 ~100 grass 0  
fill ~68 ~-1 ~101 ~69 ~-1 ~101 grass 0  
fill ~68 ~-1 ~102 ~69 ~-1 ~102 grass 0  
fill ~68 ~-1 ~103 ~69 ~-1 ~103 grass 0  
fill ~68 ~-1 ~104 ~69 ~-1 ~104 grass 0  
fill ~68 ~-1 ~105 ~69 ~-1 ~105 grass 0  
fill ~68 ~-1 ~106 ~69 ~-1 ~106 grass 0  
fill ~68 ~-1 ~111 ~79 ~-1 ~111 double_stone_slab 0 
setblock ~68 ~-1 ~126 double_stone_slab 0  
fill ~69 ~-1 ~12 ~72 ~-1 ~12 double_stone_slab 0  
fill ~69 ~-1 ~13 ~72 ~-1 ~13 double_stone_slab 0  
fill ~69 ~-1 ~14 ~72 ~-1 ~14 double_stone_slab 0  
fill ~69 ~-1 ~15 ~72 ~-1 ~15 double_stone_slab 0  
fill ~69 ~-1 ~16 ~72 ~-1 ~16 double_stone_slab 0  
fill ~69 ~-1 ~17 ~72 ~-1 ~17 double_stone_slab 0  
fill ~69 ~-1 ~18 ~73 ~-1 ~18 double_stone_slab 0  
fill ~69 ~-1 ~19 ~74 ~-1 ~19 double_stone_slab 0  
fill ~69 ~-1 ~20 ~72 ~-1 ~20 double_stone_slab 0  
fill ~69 ~-1 ~21 ~72 ~-1 ~21 double_stone_slab 0  
fill ~69 ~-1 ~22 ~72 ~-1 ~22 double_stone_slab 0  
fill ~69 ~-1 ~23 ~72 ~-1 ~23 double_stone_slab 0 
setblock ~69 ~-1 ~57 glowstone 0 
setblock ~69 ~-1 ~68 beacon 0 
setblock ~69 ~-1 ~79 glowstone 0 
setblock ~69 ~-1 ~126 stone_slab 8  
fill ~70 ~-1 ~28 ~70 ~-1 ~64 double_stone_slab 0 
setblock ~70 ~-1 ~68 sandstone 2  
fill ~70 ~-1 ~72 ~72 ~-1 ~72 double_stone_slab 0  
fill ~70 ~-1 ~73 ~72 ~-1 ~73 double_stone_slab 0  
fill ~70 ~-1 ~74 ~83 ~-1 ~74 double_stone_slab 0  
fill ~70 ~-1 ~75 ~78 ~-1 ~75 double_stone_slab 0  
fill ~70 ~-1 ~76 ~78 ~-1 ~76 double_stone_slab 0  
fill ~70 ~-1 ~79 ~85 ~-1 ~79 double_stone_slab 0  
fill ~70 ~-1 ~80 ~83 ~-1 ~80 double_stone_slab 0  
fill ~70 ~-1 ~81 ~85 ~-1 ~81 double_stone_slab 0  
fill ~70 ~-1 ~82 ~83 ~-1 ~82 double_stone_slab 0  
fill ~70 ~-1 ~83 ~85 ~-1 ~83 double_stone_slab 0  
fill ~70 ~-1 ~84 ~83 ~-1 ~84 double_stone_slab 0  
fill ~70 ~-1 ~85 ~79 ~-1 ~85 double_stone_slab 0  
fill ~70 ~-1 ~86 ~83 ~-1 ~86 double_stone_slab 0  
fill ~70 ~-1 ~87 ~97 ~-1 ~87 double_stone_slab 0  
fill ~70 ~-1 ~88 ~83 ~-1 ~88 double_stone_slab 0  
fill ~70 ~-1 ~89 ~97 ~-1 ~89 double_stone_slab 0  
fill ~70 ~-1 ~90 ~97 ~-1 ~90 double_stone_slab 0  
fill ~70 ~-1 ~91 ~97 ~-1 ~91 double_stone_slab 0  
fill ~70 ~-1 ~92 ~80 ~-1 ~92 double_stone_slab 0  
fill ~70 ~-1 ~93 ~80 ~-1 ~93 double_stone_slab 0  
fill ~70 ~-1 ~94 ~80 ~-1 ~94 double_stone_slab 0  
fill ~70 ~-1 ~95 ~80 ~-1 ~95 double_stone_slab 0  
fill ~70 ~-1 ~96 ~76 ~-1 ~96 double_stone_slab 0  
fill ~70 ~-1 ~97 ~99 ~-1 ~97 double_stone_slab 0  
fill ~70 ~-1 ~98 ~99 ~-1 ~98 double_stone_slab 0  
fill ~70 ~-1 ~99 ~70 ~-1 ~102 double_stone_slab 0  
fill ~70 ~-1 ~103 ~70 ~-1 ~105 stone 0  
fill ~70 ~-1 ~106 ~70 ~-1 ~109 double_stone_slab 0  
fill ~70 ~-1 ~126 ~84 ~-1 ~126 double_stone_slab 0  
fill ~71 ~-1 ~27 ~71 ~-1 ~37 beacon 0  
fill ~71 ~-1 ~38 ~99 ~-1 ~38 double_stone_slab 0  
fill ~71 ~-1 ~39 ~99 ~-1 ~39 double_stone_slab 0  
fill ~71 ~-1 ~40 ~99 ~-1 ~40 double_stone_slab 0  
fill ~71 ~-1 ~41 ~80 ~-1 ~41 double_stone_slab 0  
fill ~71 ~-1 ~42 ~80 ~-1 ~42 double_stone_slab 0  
fill ~71 ~-1 ~43 ~80 ~-1 ~43 double_stone_slab 0  
fill ~71 ~-1 ~44 ~80 ~-1 ~44 double_stone_slab 0  
fill ~71 ~-1 ~45 ~97 ~-1 ~45 double_stone_slab 0  
fill ~71 ~-1 ~46 ~97 ~-1 ~46 double_stone_slab 0  
fill ~71 ~-1 ~47 ~97 ~-1 ~47 double_stone_slab 0  
fill ~71 ~-1 ~48 ~83 ~-1 ~48 double_stone_slab 0  
fill ~71 ~-1 ~49 ~97 ~-1 ~49 double_stone_slab 0  
fill ~71 ~-1 ~50 ~83 ~-1 ~50 double_stone_slab 0  
fill ~71 ~-1 ~51 ~85 ~-1 ~51 double_stone_slab 0  
fill ~71 ~-1 ~52 ~83 ~-1 ~52 double_stone_slab 0  
fill ~71 ~-1 ~53 ~73 ~-1 ~53 double_stone_slab 0  
fill ~71 ~-1 ~54 ~83 ~-1 ~54 double_stone_slab 0  
fill ~71 ~-1 ~55 ~72 ~-1 ~55 double_stone_slab 0  
fill ~71 ~-1 ~56 ~71 ~-1 ~57 double_stone_slab 0 
setblock ~71 ~-1 ~58 stone_slab 8  
fill ~71 ~-1 ~60 ~71 ~-1 ~64 double_stone_slab 0  
fill ~71 ~-1 ~65 ~73 ~-1 ~65 grass 0  
fill ~71 ~-1 ~67 ~99 ~-1 ~67 double_stone_slab 0  
fill ~71 ~-1 ~68 ~71 ~-1 ~70 double_stone_slab 0  
fill ~71 ~-1 ~71 ~73 ~-1 ~71 grass 0  
fill ~71 ~-1 ~99 ~98 ~-1 ~99 beacon 0  
fill ~71 ~-1 ~100 ~71 ~-1 ~110 beacon 0  
fill ~71 ~-1 ~116 ~79 ~-1 ~116 double_stone_slab 0  
fill ~71 ~-1 ~117 ~79 ~-1 ~117 double_stone_slab 0  
fill ~71 ~-1 ~118 ~79 ~-1 ~118 double_stone_slab 0  
fill ~71 ~-1 ~119 ~79 ~-1 ~119 double_stone_slab 0  
fill ~71 ~-1 ~120 ~88 ~-1 ~120 double_stone_slab 0  
fill ~71 ~-1 ~121 ~88 ~-1 ~121 double_stone_slab 0  
fill ~72 ~-1 ~26 ~72 ~-1 ~36 double_stone_slab 0  
fill ~72 ~-1 ~37 ~98 ~-1 ~37 beacon 0  
fill ~72 ~-1 ~56 ~78 ~-1 ~56 sandstone 2  
fill ~72 ~-1 ~57 ~72 ~-1 ~59 stone_brick_stairs 1  
fill ~72 ~-1 ~60 ~76 ~-1 ~60 sandstone 2  
fill ~72 ~-1 ~61 ~85 ~-1 ~61 double_stone_slab 0  
fill ~72 ~-1 ~62 ~83 ~-1 ~62 double_stone_slab 0  
fill ~72 ~-1 ~63 ~72 ~-1 ~64 double_stone_slab 0 
setblock ~72 ~-1 ~68 glass_pane 0  
fill ~72 ~-1 ~69 ~99 ~-1 ~69 double_stone_slab 0  
fill ~72 ~-1 ~100 ~97 ~-1 ~100 double_stone_slab 0  
fill ~72 ~-1 ~101 ~97 ~-1 ~101 double_stone_slab 0  
fill ~72 ~-1 ~102 ~84 ~-1 ~102 double_stone_slab 0  
fill ~72 ~-1 ~103 ~85 ~-1 ~103 double_stone_slab 0  
fill ~72 ~-1 ~104 ~85 ~-1 ~104 double_stone_slab 0  
fill ~72 ~-1 ~105 ~88 ~-1 ~105 double_stone_slab 0  
fill ~72 ~-1 ~106 ~88 ~-1 ~106 double_stone_slab 0  
fill ~72 ~-1 ~107 ~79 ~-1 ~107 double_stone_slab 0  
fill ~72 ~-1 ~108 ~79 ~-1 ~108 double_stone_slab 0  
fill ~72 ~-1 ~109 ~79 ~-1 ~109 double_stone_slab 0  
fill ~72 ~-1 ~110 ~79 ~-1 ~110 double_stone_slab 0  
fill ~73 ~-1 ~11 ~96 ~-1 ~11 sand 0  
fill ~73 ~-1 ~12 ~96 ~-1 ~12 sand 0  
fill ~73 ~-1 ~13 ~96 ~-1 ~13 sand 0  
fill ~73 ~-1 ~14 ~96 ~-1 ~14 sand 0  
fill ~73 ~-1 ~15 ~96 ~-1 ~15 sand 0  
fill ~73 ~-1 ~16 ~96 ~-1 ~16 sand 0 
setblock ~73 ~-1 ~17 beacon 0  
fill ~73 ~-1 ~20 ~76 ~-1 ~20 stone_slab 8  
fill ~73 ~-1 ~21 ~74 ~-1 ~21 sand 0  
fill ~73 ~-1 ~22 ~73 ~-1 ~35 sand 0  
fill ~73 ~-1 ~36 ~97 ~-1 ~36 double_stone_slab 0 
setblock ~73 ~-1 ~55 stone_slab 8 
setblock ~73 ~-1 ~57 sandstone 2  
fill ~73 ~-1 ~63 ~73 ~-1 ~65 grass 0 
setblock ~73 ~-1 ~68 double_stone_slab 0  
fill ~73 ~-1 ~72 ~73 ~-1 ~73 grass 0  
fill ~74 ~-1 ~17 ~96 ~-1 ~17 sand 0  
fill ~74 ~-1 ~18 ~75 ~-1 ~18 stone_slab 8 
setblock ~74 ~-1 ~22 beacon 0  
fill ~74 ~-1 ~23 ~75 ~-1 ~23 sand 0  
fill ~74 ~-1 ~24 ~75 ~-1 ~24 sand 0  
fill ~74 ~-1 ~25 ~75 ~-1 ~25 sand 0  
fill ~74 ~-1 ~26 ~76 ~-1 ~26 sand 0  
fill ~74 ~-1 ~27 ~76 ~-1 ~27 sand 0  
fill ~74 ~-1 ~28 ~77 ~-1 ~28 sand 0  
fill ~74 ~-1 ~29 ~76 ~-1 ~29 sand 0  
fill ~74 ~-1 ~30 ~77 ~-1 ~30 sand 0  
fill ~74 ~-1 ~31 ~77 ~-1 ~31 sand 0  
fill ~74 ~-1 ~32 ~76 ~-1 ~32 sand 0  
fill ~74 ~-1 ~33 ~76 ~-1 ~33 sand 0  
fill ~74 ~-1 ~34 ~76 ~-1 ~34 sand 0  
fill ~74 ~-1 ~35 ~76 ~-1 ~35 sand 0 
setblock ~74 ~-1 ~53 stone_slab 8  
fill ~74 ~-1 ~55 ~85 ~-1 ~55 double_stone_slab 0  
fill ~74 ~-1 ~63 ~78 ~-1 ~63 double_stone_slab 0  
fill ~74 ~-1 ~64 ~78 ~-1 ~64 double_stone_slab 0  
fill ~74 ~-1 ~65 ~78 ~-1 ~65 double_stone_slab 0 
setblock ~74 ~-1 ~68 glass_pane 0  
fill ~74 ~-1 ~71 ~78 ~-1 ~71 double_stone_slab 0  
fill ~74 ~-1 ~72 ~78 ~-1 ~72 double_stone_slab 0  
fill ~74 ~-1 ~73 ~78 ~-1 ~73 double_stone_slab 0 
setblock ~75 ~-1 ~19 stone_slab 8  
fill ~75 ~-1 ~21 ~77 ~-1 ~21 stone_slab 8  
fill ~75 ~-1 ~22 ~78 ~-1 ~22 stone_slab 8  
fill ~75 ~-1 ~53 ~85 ~-1 ~53 double_stone_slab 0 
setblock ~75 ~-1 ~68 double_stone_slab 0  
fill ~76 ~-1 ~18 ~96 ~-1 ~18 sand 0  
fill ~76 ~-1 ~19 ~96 ~-1 ~19 sand 0  
fill ~76 ~-1 ~23 ~76 ~-1 ~25 double_stone_slab 0 
setblock ~76 ~-1 ~68 glass_pane 0  
fill ~77 ~-1 ~20 ~96 ~-1 ~20 sand 0  
fill ~77 ~-1 ~23 ~78 ~-1 ~23 stone_slab 8  
fill ~77 ~-1 ~24 ~79 ~-1 ~24 double_stone_slab 0  
fill ~77 ~-1 ~25 ~79 ~-1 ~25 double_stone_slab 0  
fill ~77 ~-1 ~26 ~79 ~-1 ~26 double_stone_slab 0  
fill ~77 ~-1 ~27 ~79 ~-1 ~27 double_stone_slab 0 
setblock ~77 ~-1 ~29 beacon 0  
fill ~77 ~-1 ~32 ~79 ~-1 ~32 double_stone_slab 0  
fill ~77 ~-1 ~33 ~79 ~-1 ~33 double_stone_slab 0  
fill ~77 ~-1 ~34 ~80 ~-1 ~34 double_stone_slab 0  
fill ~77 ~-1 ~35 ~80 ~-1 ~35 double_stone_slab 0  
fill ~77 ~-1 ~57 ~78 ~-1 ~57 sandstone 2  
fill ~77 ~-1 ~58 ~78 ~-1 ~58 sandstone 2  
fill ~77 ~-1 ~59 ~78 ~-1 ~59 sandstone 2  
fill ~77 ~-1 ~60 ~83 ~-1 ~60 double_stone_slab 0 
setblock ~77 ~-1 ~68 double_stone_slab 0 
setblock ~77 ~-1 ~96 stone_slab 8  
fill ~78 ~-1 ~21 ~96 ~-1 ~21 sand 0  
fill ~78 ~-1 ~28 ~79 ~-1 ~28 double_stone_slab 0  
fill ~78 ~-1 ~29 ~79 ~-1 ~29 double_stone_slab 0  
fill ~78 ~-1 ~30 ~79 ~-1 ~30 double_stone_slab 0  
fill ~78 ~-1 ~31 ~79 ~-1 ~31 double_stone_slab 0 
setblock ~78 ~-1 ~68 glass_pane 0  
fill ~78 ~-1 ~96 ~95 ~-1 ~96 double_stone_slab 0 
setblock ~79 ~-1 ~22 beacon 0  
fill ~79 ~-1 ~23 ~96 ~-1 ~23 sand 0  
fill ~79 ~-1 ~56 ~83 ~-1 ~56 double_stone_slab 0  
fill ~79 ~-1 ~57 ~85 ~-1 ~57 double_stone_slab 0  
fill ~79 ~-1 ~58 ~83 ~-1 ~58 double_stone_slab 0  
fill ~79 ~-1 ~59 ~81 ~-1 ~59 double_stone_slab 0  
fill ~79 ~-1 ~63 ~80 ~-1 ~63 grass 0  
fill ~79 ~-1 ~64 ~80 ~-1 ~64 grass 0  
fill ~79 ~-1 ~65 ~80 ~-1 ~65 grass 0 
setblock ~79 ~-1 ~68 double_stone_slab 0  
fill ~79 ~-1 ~71 ~80 ~-1 ~71 grass 0  
fill ~79 ~-1 ~72 ~80 ~-1 ~72 grass 0  
fill ~79 ~-1 ~73 ~80 ~-1 ~73 grass 0  
fill ~80 ~-1 ~22 ~96 ~-1 ~22 sand 0  
fill ~80 ~-1 ~24 ~96 ~-1 ~24 sand 0  
fill ~80 ~-1 ~25 ~96 ~-1 ~25 sand 0  
fill ~80 ~-1 ~26 ~96 ~-1 ~26 sand 0  
fill ~80 ~-1 ~27 ~96 ~-1 ~27 sand 0  
fill ~80 ~-1 ~28 ~80 ~-1 ~33 stone_slab 8 
setblock ~80 ~-1 ~68 glass_pane 0  
fill ~80 ~-1 ~75 ~85 ~-1 ~75 double_stone_slab 0  
fill ~80 ~-1 ~76 ~83 ~-1 ~76 double_stone_slab 0  
fill ~80 ~-1 ~85 ~80 ~8 ~85 sandstone 2  
fill ~80 ~-1 ~107 ~92 ~-1 ~107 beacon 0  
fill ~80 ~-1 ~108 ~80 ~-1 ~119 beacon 0  
fill ~81 ~-1 ~28 ~96 ~-1 ~28 sand 0 
setblock ~81 ~-1 ~29 beacon 0  
fill ~81 ~-1 ~30 ~96 ~-1 ~30 sand 0  
fill ~81 ~-1 ~31 ~96 ~-1 ~31 sand 0  
fill ~81 ~-1 ~32 ~96 ~-1 ~32 sand 0  
fill ~81 ~-1 ~33 ~96 ~-1 ~33 sand 0  
fill ~81 ~-1 ~34 ~96 ~-1 ~34 sand 0  
fill ~81 ~-1 ~35 ~96 ~-1 ~35 sand 0  
fill ~81 ~-1 ~41 ~81 ~-1 ~44 glowstone 0  
fill ~81 ~-1 ~63 ~85 ~-1 ~63 double_stone_slab 0  
fill ~81 ~-1 ~64 ~83 ~-1 ~64 double_stone_slab 0  
fill ~81 ~-1 ~65 ~84 ~-1 ~65 double_stone_slab 0 
setblock ~81 ~-1 ~68 double_stone_slab 0  
fill ~81 ~-1 ~71 ~87 ~-1 ~71 double_stone_slab 0  
fill ~81 ~-1 ~72 ~83 ~-1 ~72 double_stone_slab 0  
fill ~81 ~-1 ~73 ~84 ~-1 ~73 double_stone_slab 0  
fill ~81 ~-1 ~85 ~85 ~-1 ~85 double_stone_slab 0  
fill ~81 ~-1 ~92 ~81 ~-1 ~95 glowstone 0  
fill ~81 ~-1 ~108 ~88 ~-1 ~108 double_stone_slab 0  
fill ~81 ~-1 ~109 ~88 ~-1 ~109 double_stone_slab 0  
fill ~81 ~-1 ~110 ~85 ~-1 ~110 double_stone_slab 0  
fill ~81 ~-1 ~111 ~88 ~-1 ~111 double_stone_slab 0  
fill ~81 ~-1 ~112 ~88 ~-1 ~112 double_stone_slab 0  
fill ~81 ~-1 ~113 ~81 ~-1 ~118 double_stone_slab 0 
setblock ~81 ~-1 ~119 beacon 0  
fill ~82 ~-1 ~29 ~96 ~-1 ~29 sand 0  
fill ~82 ~-1 ~41 ~87 ~-1 ~41 double_stone_slab 0  
fill ~82 ~-1 ~42 ~87 ~-1 ~42 double_stone_slab 0  
fill ~82 ~-1 ~43 ~87 ~-1 ~43 double_stone_slab 0  
fill ~82 ~-1 ~44 ~87 ~-1 ~44 double_stone_slab 0  
fill ~82 ~-1 ~59 ~83 ~-1 ~59 stone_slab 8 
setblock ~82 ~-1 ~68 glass_pane 0  
fill ~82 ~-1 ~92 ~87 ~-1 ~92 double_stone_slab 0  
fill ~82 ~-1 ~94 ~87 ~-1 ~94 double_stone_slab 0  
fill ~82 ~-1 ~95 ~87 ~-1 ~95 double_stone_slab 0 
setblock ~82 ~-1 ~113 stone_slab 8  
fill ~82 ~-1 ~114 ~88 ~-1 ~114 double_stone_slab 0  
fill ~82 ~-1 ~115 ~88 ~-1 ~115 double_stone_slab 0  
fill ~82 ~-1 ~116 ~85 ~-1 ~116 double_stone_slab 0  
fill ~82 ~-1 ~117 ~88 ~-1 ~117 double_stone_slab 0  
fill ~82 ~-1 ~118 ~88 ~-1 ~118 double_stone_slab 0  
fill ~82 ~-1 ~119 ~85 ~-1 ~119 double_stone_slab 0 
setblock ~83 ~-1 ~68 double_stone_slab 0  
fill ~83 ~-1 ~93 ~87 ~-1 ~93 double_stone_slab 0  
fill ~83 ~-1 ~113 ~85 ~-1 ~113 double_stone_slab 0 
setblock ~84 ~-1 ~48 glass_pane 0 
setblock ~84 ~-1 ~50 glass_pane 0 
setblock ~84 ~-1 ~52 glass_pane 0 
setblock ~84 ~-1 ~54 glass_pane 0 
setblock ~84 ~-1 ~56 glass_pane 0 
setblock ~84 ~-1 ~58 glass_pane 0  
fill ~84 ~-1 ~59 ~85 ~-1 ~59 double_stone_slab 0 
setblock ~84 ~-1 ~60 glass_pane 0 
setblock ~84 ~-1 ~62 glass_pane 0 
setblock ~84 ~-1 ~64 glass_pane 0 
setblock ~84 ~-1 ~66 glass_pane 0 
setblock ~84 ~-1 ~68 glass_pane 0 
setblock ~84 ~-1 ~70 glass_pane 0 
setblock ~84 ~-1 ~72 glass_pane 0 
setblock ~84 ~-1 ~74 glass_pane 0 
setblock ~84 ~-1 ~76 glass_pane 0 
setblock ~84 ~-1 ~78 glass_pane 0 
setblock ~84 ~-1 ~80 glass_pane 0 
setblock ~84 ~-1 ~82 glass_pane 0 
setblock ~84 ~-1 ~84 glass_pane 0 
setblock ~84 ~-1 ~86 glass_pane 0 
setblock ~84 ~-1 ~88 glass_pane 0  
fill ~85 ~-1 ~48 ~97 ~-1 ~48 double_stone_slab 0 
setblock ~85 ~-1 ~50 double_stone_slab 0 
setblock ~85 ~-1 ~52 double_stone_slab 0 
setblock ~85 ~-1 ~54 double_stone_slab 0 
setblock ~85 ~-1 ~56 double_stone_slab 0 
setblock ~85 ~-1 ~58 double_stone_slab 0 
setblock ~85 ~-1 ~62 double_stone_slab 0 
setblock ~85 ~-1 ~64 double_stone_slab 0 
setblock ~85 ~-1 ~65 stone_slab 8  
fill ~85 ~-1 ~66 ~89 ~-1 ~66 double_stone_slab 0 
setblock ~85 ~-1 ~68 double_stone_slab 0  
fill ~85 ~-1 ~70 ~89 ~-1 ~70 double_stone_slab 0 
setblock ~85 ~-1 ~72 double_stone_slab 0 
setblock ~85 ~-1 ~73 stone_slab 8 
setblock ~85 ~-1 ~74 double_stone_slab 0 
setblock ~85 ~-1 ~76 double_stone_slab 0 
setblock ~85 ~-1 ~77 stone_slab 8 
setblock ~85 ~-1 ~78 double_stone_slab 0 
setblock ~85 ~-1 ~80 double_stone_slab 0 
setblock ~85 ~-1 ~82 double_stone_slab 0 
setblock ~85 ~-1 ~84 double_stone_slab 0 
setblock ~85 ~-1 ~86 double_stone_slab 0  
fill ~85 ~-1 ~88 ~97 ~-1 ~88 double_stone_slab 0 
setblock ~85 ~-1 ~102 stone_slab 8 
setblock ~85 ~-1 ~126 beacon 0  
fill ~86 ~-1 ~50 ~86 ~-1 ~65 beacon 0 
setblock ~86 ~-1 ~68 glass_pane 0  
fill ~86 ~-1 ~72 ~86 ~-1 ~86 beacon 0  
fill ~86 ~-1 ~102 ~96 ~-1 ~102 double_stone_slab 0  
fill ~86 ~-1 ~104 ~92 ~-1 ~104 beacon 0  
fill ~86 ~-1 ~110 ~92 ~-1 ~110 beacon 0  
fill ~86 ~-1 ~113 ~92 ~-1 ~113 beacon 0  
fill ~86 ~-1 ~116 ~92 ~-1 ~116 beacon 0  
fill ~86 ~-1 ~119 ~92 ~-1 ~119 beacon 0  
fill ~86 ~-1 ~122 ~92 ~-1 ~122 beacon 0  
fill ~86 ~-1 ~126 ~87 ~-1 ~126 double_stone_slab 0  
fill ~87 ~-1 ~50 ~97 ~-1 ~50 double_stone_slab 0  
fill ~87 ~-1 ~51 ~89 ~-1 ~51 double_stone_slab 0  
fill ~87 ~-1 ~52 ~94 ~-1 ~52 double_stone_slab 0  
fill ~87 ~-1 ~53 ~87 ~-1 ~81 double_stone_slab 0  
fill ~87 ~-1 ~83 ~87 ~-1 ~98 double_stone_slab 0  
fill ~87 ~-1 ~103 ~97 ~-1 ~103 double_stone_slab 0  
fill ~88 ~-1 ~41 ~88 ~-1 ~44 glowstone 0 
setblock ~88 ~-1 ~53 glowstone 0  
fill ~88 ~-1 ~54 ~99 ~-1 ~54 double_stone_slab 0  
fill ~88 ~-1 ~55 ~99 ~-1 ~55 double_stone_slab 0  
fill ~88 ~-1 ~56 ~90 ~-1 ~56 double_stone_slab 0 
setblock ~88 ~-1 ~57 glowstone 0  
fill ~88 ~-1 ~58 ~90 ~-1 ~58 double_stone_slab 0  
fill ~88 ~-1 ~59 ~99 ~-1 ~59 double_stone_slab 0  
fill ~88 ~-1 ~60 ~89 ~-1 ~60 double_stone_slab 0 
setblock ~88 ~-1 ~61 glowstone 0  
fill ~88 ~-1 ~62 ~89 ~-1 ~62 double_stone_slab 0  
fill ~88 ~-1 ~63 ~90 ~-1 ~63 double_stone_slab 0  
fill ~88 ~-1 ~64 ~89 ~-1 ~64 double_stone_slab 0 
setblock ~88 ~-1 ~65 glowstone 0 
setblock ~88 ~-1 ~68 glass_pane 0 
setblock ~88 ~-1 ~71 glowstone 0  
fill ~88 ~-1 ~72 ~89 ~-1 ~72 double_stone_slab 0  
fill ~88 ~-1 ~73 ~99 ~-1 ~73 double_stone_slab 0  
fill ~88 ~-1 ~74 ~89 ~-1 ~74 double_stone_slab 0 
setblock ~88 ~-1 ~75 glowstone 0  
fill ~88 ~-1 ~76 ~89 ~-1 ~76 double_stone_slab 0  
fill ~88 ~-1 ~77 ~99 ~-1 ~77 double_stone_slab 0  
fill ~88 ~-1 ~78 ~90 ~-1 ~78 double_stone_slab 0 
setblock ~88 ~-1 ~79 glowstone 0  
fill ~88 ~-1 ~80 ~90 ~-1 ~80 double_stone_slab 0  
fill ~88 ~-1 ~81 ~99 ~-1 ~81 double_stone_slab 0  
fill ~88 ~-1 ~82 ~99 ~-1 ~82 double_stone_slab 0 
setblock ~88 ~-1 ~83 glowstone 0  
fill ~88 ~-1 ~84 ~94 ~-1 ~84 double_stone_slab 0  
fill ~88 ~-1 ~85 ~89 ~-1 ~85 double_stone_slab 0  
fill ~88 ~-1 ~86 ~97 ~-1 ~86 double_stone_slab 0  
fill ~88 ~-1 ~92 ~88 ~-1 ~95 glowstone 0 
setblock ~88 ~-1 ~126 beacon 0  
fill ~89 ~-1 ~41 ~97 ~-1 ~41 double_stone_slab 0  
fill ~89 ~-1 ~42 ~97 ~-1 ~42 double_stone_slab 0  
fill ~89 ~-1 ~43 ~97 ~-1 ~43 double_stone_slab 0  
fill ~89 ~-1 ~44 ~97 ~-1 ~44 double_stone_slab 0  
fill ~89 ~-1 ~53 ~96 ~-1 ~53 double_stone_slab 0  
fill ~89 ~-1 ~57 ~99 ~-1 ~57 double_stone_slab 0  
fill ~89 ~-1 ~61 ~99 ~-1 ~61 double_stone_slab 0  
fill ~89 ~-1 ~65 ~99 ~-1 ~65 double_stone_slab 0 
setblock ~89 ~-1 ~68 double_stone_slab 0  
fill ~89 ~-1 ~71 ~91 ~-1 ~71 double_stone_slab 0  
fill ~89 ~-1 ~75 ~99 ~-1 ~75 double_stone_slab 0  
fill ~89 ~-1 ~79 ~99 ~-1 ~79 double_stone_slab 0  
fill ~89 ~-1 ~83 ~96 ~-1 ~83 double_stone_slab 0  
fill ~89 ~-1 ~92 ~97 ~-1 ~92 double_stone_slab 0  
fill ~89 ~-1 ~93 ~97 ~-1 ~93 double_stone_slab 0  
fill ~89 ~-1 ~94 ~97 ~-1 ~94 double_stone_slab 0  
fill ~89 ~-1 ~95 ~97 ~-1 ~95 double_stone_slab 0  
fill ~89 ~-1 ~105 ~89 ~-1 ~122 beacon 0  
fill ~89 ~-1 ~126 ~90 ~-1 ~126 double_stone_slab 0 
setblock ~90 ~-1 ~51 glowstone 0 
setblock ~90 ~-1 ~60 glass_pane 0 
setblock ~90 ~-1 ~62 glass_pane 0 
setblock ~90 ~-1 ~64 glass_pane 0 
setblock ~90 ~-1 ~66 glass_pane 0 
setblock ~90 ~-1 ~68 glass_pane 0 
setblock ~90 ~-1 ~70 glass_pane 0 
setblock ~90 ~-1 ~72 glass_pane 0 
setblock ~90 ~-1 ~74 glass_pane 0 
setblock ~90 ~-1 ~76 glass_pane 0 
setblock ~90 ~-1 ~85 glowstone 0  
fill ~90 ~-1 ~105 ~96 ~-1 ~105 double_stone_slab 0  
fill ~90 ~-1 ~106 ~97 ~-1 ~106 double_stone_slab 0  
fill ~90 ~-1 ~108 ~96 ~-1 ~108 double_stone_slab 0  
fill ~90 ~-1 ~109 ~97 ~-1 ~109 double_stone_slab 0  
fill ~90 ~-1 ~111 ~96 ~-1 ~111 double_stone_slab 0  
fill ~90 ~-1 ~112 ~97 ~-1 ~112 double_stone_slab 0  
fill ~90 ~-1 ~114 ~94 ~-1 ~114 double_stone_slab 0  
fill ~90 ~-1 ~115 ~97 ~-1 ~115 double_stone_slab 0  
fill ~90 ~-1 ~117 ~96 ~-1 ~117 double_stone_slab 0  
fill ~90 ~-1 ~118 ~97 ~-1 ~118 double_stone_slab 0  
fill ~90 ~-1 ~120 ~96 ~-1 ~120 double_stone_slab 0  
fill ~90 ~-1 ~121 ~97 ~-1 ~121 double_stone_slab 0  
fill ~91 ~-1 ~51 ~93 ~-1 ~51 double_stone_slab 0 
setblock ~91 ~-1 ~56 glass_pane 0 
setblock ~91 ~-1 ~58 glass_pane 0  
fill ~91 ~-1 ~60 ~99 ~-1 ~60 double_stone_slab 0  
fill ~91 ~-1 ~62 ~99 ~-1 ~62 double_stone_slab 0 
setblock ~91 ~-1 ~63 stone_slab 8  
fill ~91 ~-1 ~64 ~99 ~-1 ~64 double_stone_slab 0  
fill ~91 ~-1 ~66 ~101 ~-1 ~66 double_stone_slab 0  
fill ~91 ~-1 ~68 ~99 ~-1 ~68 double_stone_slab 0  
fill ~91 ~-1 ~70 ~101 ~-1 ~70 double_stone_slab 0  
fill ~91 ~-1 ~72 ~99 ~-1 ~72 double_stone_slab 0  
fill ~91 ~-1 ~74 ~99 ~-1 ~74 double_stone_slab 0  
fill ~91 ~-1 ~76 ~99 ~-1 ~76 double_stone_slab 0 
setblock ~91 ~-1 ~78 glass_pane 0 
setblock ~91 ~-1 ~80 glass_pane 0  
fill ~91 ~-1 ~85 ~93 ~-1 ~85 double_stone_slab 0 
setblock ~91 ~-1 ~126 beacon 0  
fill ~92 ~-1 ~56 ~99 ~-1 ~56 double_stone_slab 0  
fill ~92 ~-1 ~58 ~99 ~-1 ~58 double_stone_slab 0  
fill ~92 ~-1 ~63 ~99 ~-1 ~63 double_stone_slab 0 
setblock ~92 ~-1 ~71 stone_slab 8  
fill ~92 ~-1 ~78 ~99 ~-1 ~78 double_stone_slab 0  
fill ~92 ~-1 ~80 ~99 ~-1 ~80 double_stone_slab 0  
fill ~92 ~-1 ~126 ~93 ~-1 ~126 double_stone_slab 0  
fill ~93 ~-1 ~71 ~99 ~-1 ~71 double_stone_slab 0  
fill ~93 ~-1 ~104 ~97 ~-1 ~104 double_stone_slab 0 
setblock ~93 ~-1 ~107 stone_slab 8  
fill ~93 ~-1 ~110 ~97 ~-1 ~110 double_stone_slab 0  
fill ~93 ~-1 ~113 ~97 ~-1 ~113 double_stone_slab 0  
fill ~93 ~-1 ~116 ~97 ~-1 ~116 double_stone_slab 0  
fill ~93 ~-1 ~119 ~97 ~-1 ~119 double_stone_slab 0  
fill ~93 ~-1 ~122 ~97 ~-1 ~122 double_stone_slab 0 
setblock ~94 ~-1 ~51 glowstone 0 
setblock ~94 ~-1 ~85 glowstone 0  
fill ~94 ~-1 ~107 ~97 ~-1 ~107 double_stone_slab 0 
setblock ~94 ~-1 ~126 beacon 0  
fill ~95 ~-1 ~51 ~97 ~-1 ~51 double_stone_slab 0 
setblock ~95 ~-1 ~52 stone_slab 8 
setblock ~95 ~-1 ~84 stone_slab 8  
fill ~95 ~-1 ~85 ~97 ~-1 ~85 double_stone_slab 0 
setblock ~95 ~-1 ~114 stone_slab 0  
fill ~95 ~-1 ~126 ~96 ~-1 ~126 double_stone_slab 0  
fill ~96 ~-1 ~52 ~97 ~-1 ~52 double_stone_slab 0  
fill ~96 ~-1 ~84 ~99 ~-1 ~84 double_stone_slab 0 
setblock ~96 ~-1 ~114 double_stone_slab 0 
setblock ~97 ~-1 ~1 redstone_torch 0  
fill ~97 ~-1 ~2 ~101 ~-1 ~2 double_stone_slab 0  
fill ~97 ~-1 ~6 ~101 ~-1 ~6 double_stone_slab 0 
setblock ~97 ~-1 ~7 redstone_torch 1  
fill ~97 ~-1 ~11 ~97 ~-1 ~36 double_stone_slab 0 
setblock ~97 ~-1 ~53 stone_slab 8 
setblock ~97 ~-1 ~83 stone_slab 8  
fill ~97 ~-1 ~102 ~98 ~-1 ~102 beacon 0  
fill ~97 ~-1 ~105 ~98 ~-1 ~105 beacon 0  
fill ~97 ~-1 ~108 ~98 ~-1 ~108 beacon 0  
fill ~97 ~-1 ~111 ~98 ~-1 ~111 beacon 0  
fill ~97 ~-1 ~114 ~98 ~-1 ~114 beacon 0  
fill ~97 ~-1 ~117 ~98 ~-1 ~117 beacon 0  
fill ~97 ~-1 ~120 ~98 ~-1 ~120 beacon 0  
fill ~97 ~-1 ~123 ~98 ~-1 ~123 beacon 0  
fill ~97 ~-1 ~126 ~98 ~-1 ~126 beacon 0  
fill ~98 ~-1 ~1 ~100 ~-1 ~1 stonebrick 0  
fill ~98 ~-1 ~7 ~100 ~-1 ~7 stonebrick 0   
fill ~98 ~-1 ~10 ~98 ~-1 ~37 beacon 0  
fill ~98 ~-1 ~41 ~98 ~-1 ~52 beacon 0  
fill ~98 ~-1 ~53 ~99 ~-1 ~53 double_stone_slab 0  
fill ~98 ~-1 ~83 ~99 ~-1 ~83 double_stone_slab 0  
fill ~98 ~-1 ~85 ~98 ~-1 ~95 beacon 0  
fill ~98 ~-1 ~100 ~98 ~-1 ~127 beacon 0  
fill ~98 ~-1 ~129 ~100 ~-1 ~129 stonebrick 0  
fill ~98 ~-1 ~130 ~101 ~-1 ~130 double_stone_slab 0  
fill ~98 ~-1 ~131 ~106 ~-1 ~131 stone_slab 0  
fill ~98 ~-1 ~132 ~106 ~-1 ~132 stone_slab 0  
fill ~98 ~-1 ~133 ~106 ~-1 ~133 stone_slab 0  
fill ~98 ~-1 ~134 ~101 ~-1 ~134 double_stone_slab 0  
fill ~98 ~-1 ~135 ~100 ~-1 ~135 stonebrick 0  
fill ~99 ~-1 ~9 ~99 ~-1 ~128 double_stone_slab 0  
fill ~100 ~-1 ~8 ~100 ~-1 ~9 stonebrick 0 
setblock ~100 ~-1 ~10 redstone_torch 0  
fill ~100 ~-1 ~11 ~100 ~-1 ~39 stonebrick 0  
fill ~100 ~-1 ~41 ~100 ~-1 ~61 stonebrick 0 
setblock ~100 ~-1 ~62 redstone_torch 0  
fill ~100 ~-1 ~63 ~100 ~-1 ~65 stonebrick 0  
fill ~100 ~-1 ~67 ~106 ~-1 ~67 stone_slab 0  
fill ~100 ~-1 ~68 ~106 ~-1 ~68 stone_slab 0  
fill ~100 ~-1 ~69 ~106 ~-1 ~69 stone_slab 0  
fill ~100 ~-1 ~71 ~100 ~-1 ~73 stonebrick 0 
setblock ~100 ~-1 ~74 redstone_torch 0  
fill ~100 ~-1 ~75 ~100 ~-1 ~125 stonebrick 0 
setblock ~100 ~-1 ~126 redstone_torch 0  
fill ~100 ~-1 ~127 ~100 ~-1 ~129 stonebrick 0  
fill ~101 ~-1 ~1 ~101 ~-1 ~1 double_stone_slab 0  
fill ~101 ~-1 ~7 ~101 ~-1 ~10 double_stone_slab 0  
fill ~101 ~-1 ~11 ~105 ~-1 ~11 stone_slab 0  
fill ~101 ~-1 ~12 ~105 ~-1 ~12 stone_slab 0  
fill ~101 ~-1 ~13 ~105 ~-1 ~13 stone_slab 0  
fill ~101 ~-1 ~14 ~105 ~-1 ~14 stone_slab 0  
fill ~101 ~-1 ~15 ~105 ~-1 ~15 stone_slab 0  
fill ~101 ~-1 ~16 ~105 ~-1 ~16 stone_slab 0  
fill ~101 ~-1 ~17 ~105 ~-1 ~17 stone_slab 0  
fill ~101 ~-1 ~18 ~105 ~-1 ~18 stone_slab 0  
fill ~101 ~-1 ~19 ~105 ~-1 ~19 stone_slab 0  
fill ~101 ~-1 ~20 ~105 ~-1 ~20 stone_slab 0  
fill ~101 ~-1 ~21 ~105 ~-1 ~21 stone_slab 0  
fill ~101 ~-1 ~22 ~105 ~-1 ~22 stone_slab 0  
fill ~101 ~-1 ~23 ~105 ~-1 ~23 stone_slab 0  
fill ~101 ~-1 ~24 ~105 ~-1 ~24 stone_slab 0  
fill ~101 ~-1 ~25 ~105 ~-1 ~25 stone_slab 0  
fill ~101 ~-1 ~26 ~105 ~-1 ~26 stone_slab 0  
fill ~101 ~-1 ~27 ~105 ~-1 ~27 stone_slab 0  
fill ~101 ~-1 ~28 ~105 ~-1 ~28 stone_slab 0  
fill ~101 ~-1 ~29 ~105 ~-1 ~29 stone_slab 0  
fill ~101 ~-1 ~30 ~105 ~-1 ~30 stone_slab 0  
fill ~101 ~-1 ~31 ~105 ~-1 ~31 stone_slab 0  
fill ~101 ~-1 ~32 ~105 ~-1 ~32 stone_slab 0  
fill ~101 ~-1 ~33 ~105 ~-1 ~33 stone_slab 0  
fill ~101 ~-1 ~34 ~105 ~-1 ~34 stone_slab 0  
fill ~101 ~-1 ~35 ~105 ~-1 ~35 stone_slab 0  
fill ~101 ~-1 ~36 ~105 ~-1 ~36 stone_slab 0  
fill ~101 ~-1 ~37 ~105 ~-1 ~37 stone_slab 0  
fill ~101 ~-1 ~38 ~105 ~-1 ~38 stone_slab 0  
fill ~101 ~-1 ~39 ~105 ~-1 ~39 stone_slab 0  
fill ~101 ~-1 ~40 ~105 ~-1 ~40 stone_slab 0  
fill ~101 ~-1 ~41 ~105 ~-1 ~41 stone_slab 0  
fill ~101 ~-1 ~42 ~105 ~-1 ~42 stone_slab 0  
fill ~101 ~-1 ~43 ~105 ~-1 ~43 stone_slab 0  
fill ~101 ~-1 ~44 ~105 ~-1 ~44 stone_slab 0  
fill ~101 ~-1 ~45 ~105 ~-1 ~45 stone_slab 0  
fill ~101 ~-1 ~46 ~105 ~-1 ~46 stone_slab 0  
fill ~101 ~-1 ~47 ~105 ~-1 ~47 stone_slab 0  
fill ~101 ~-1 ~48 ~105 ~-1 ~48 stone_slab 0  
fill ~101 ~-1 ~49 ~105 ~-1 ~49 stone_slab 0  
fill ~101 ~-1 ~50 ~105 ~-1 ~50 stone_slab 0  
fill ~101 ~-1 ~51 ~105 ~-1 ~51 stone_slab 0  
fill ~101 ~-1 ~52 ~105 ~-1 ~52 stone_slab 0  
fill ~101 ~-1 ~53 ~105 ~-1 ~53 stone_slab 0  
fill ~101 ~-1 ~54 ~105 ~-1 ~54 stone_slab 0  
fill ~101 ~-1 ~55 ~105 ~-1 ~55 stone_slab 0  
fill ~101 ~-1 ~56 ~105 ~-1 ~56 stone_slab 0  
fill ~101 ~-1 ~57 ~105 ~-1 ~57 stone_slab 0  
fill ~101 ~-1 ~58 ~105 ~-1 ~58 stone_slab 0  
fill ~101 ~-1 ~59 ~105 ~-1 ~59 stone_slab 0  
fill ~101 ~-1 ~60 ~105 ~-1 ~60 stone_slab 0  
fill ~101 ~-1 ~61 ~105 ~-1 ~61 stone_slab 0  
fill ~101 ~-1 ~62 ~101 ~-1 ~66 double_stone_slab 0  
fill ~101 ~-1 ~71 ~101 ~-1 ~74 double_stone_slab 0  
fill ~101 ~-1 ~75 ~105 ~-1 ~75 stone_slab 0  
fill ~101 ~-1 ~76 ~105 ~-1 ~76 stone_slab 0  
fill ~101 ~-1 ~77 ~105 ~-1 ~77 stone_slab 0  
fill ~101 ~-1 ~78 ~105 ~-1 ~78 stone_slab 0  
fill ~101 ~-1 ~79 ~105 ~-1 ~79 stone_slab 0  
fill ~101 ~-1 ~80 ~105 ~-1 ~80 stone_slab 0  
fill ~101 ~-1 ~81 ~105 ~-1 ~81 stone_slab 0  
fill ~101 ~-1 ~82 ~105 ~-1 ~82 stone_slab 0  
fill ~101 ~-1 ~83 ~105 ~-1 ~83 stone_slab 0  
fill ~101 ~-1 ~84 ~105 ~-1 ~84 stone_slab 0  
fill ~101 ~-1 ~85 ~105 ~-1 ~85 stone_slab 0  
fill ~101 ~-1 ~86 ~105 ~-1 ~86 stone_slab 0  
fill ~101 ~-1 ~87 ~105 ~-1 ~87 stone_slab 0  
fill ~101 ~-1 ~88 ~105 ~-1 ~88 stone_slab 0  
fill ~101 ~-1 ~89 ~105 ~-1 ~89 stone_slab 0  
fill ~101 ~-1 ~90 ~105 ~-1 ~90 stone_slab 0  
fill ~101 ~-1 ~91 ~105 ~-1 ~91 stone_slab 0  
fill ~101 ~-1 ~92 ~105 ~-1 ~92 stone_slab 0  
fill ~101 ~-1 ~93 ~105 ~-1 ~93 stone_slab 0  
