fill ~1 ~-2 ~1 ~16 ~-2 ~1 dirt 0  
fill ~1 ~-2 ~2 ~17 ~-2 ~2 dirt 0  
fill ~1 ~-2 ~3 ~17 ~-2 ~3 dirt 0  
fill ~1 ~-2 ~4 ~18 ~-2 ~4 dirt 0  
fill ~1 ~-2 ~5 ~18 ~-2 ~5 dirt 0  
fill ~1 ~-2 ~6 ~19 ~-2 ~6 dirt 0  
fill ~1 ~-2 ~7 ~19 ~-2 ~7 dirt 0  
fill ~1 ~-2 ~8 ~7 ~-2 ~8 redstone_block 0  
fill ~1 ~-2 ~9 ~12 ~-2 ~9 redstone_block 0  
fill ~1 ~-2 ~10 ~15 ~-2 ~10 redstone_block 0  
fill ~1 ~-2 ~11 ~18 ~-2 ~11 redstone_block 0  
fill ~1 ~-2 ~12 ~20 ~-2 ~12 redstone_block 0  
fill ~1 ~-2 ~13 ~22 ~-2 ~13 redstone_block 0  
fill ~1 ~-2 ~14 ~118 ~-2 ~14 redstone_block 0  
fill ~1 ~-2 ~15 ~118 ~-2 ~15 redstone_block 0  
fill ~1 ~-2 ~16 ~117 ~-2 ~16 redstone_block 0  
fill ~1 ~-2 ~17 ~117 ~-2 ~17 redstone_block 0  
fill ~1 ~-2 ~18 ~117 ~-2 ~18 redstone_block 0  
fill ~1 ~-2 ~19 ~116 ~-2 ~19 redstone_block 0  
fill ~1 ~-2 ~20 ~116 ~-2 ~20 redstone_block 0  
fill ~1 ~-2 ~21 ~115 ~-2 ~21 redstone_block 0  
fill ~1 ~-2 ~22 ~115 ~-2 ~22 redstone_block 0  
fill ~1 ~-2 ~23 ~114 ~-2 ~23 redstone_block 0  
fill ~1 ~-2 ~24 ~127 ~-2 ~24 redstone_block 0  
fill ~1 ~-2 ~25 ~127 ~-2 ~25 redstone_block 0  
fill ~1 ~-2 ~26 ~127 ~-2 ~26 redstone_block 0  
fill ~1 ~-2 ~27 ~127 ~-2 ~27 redstone_block 0  
fill ~1 ~-2 ~28 ~40 ~-2 ~28 redstone_block 0  
fill ~1 ~-2 ~29 ~41 ~-2 ~29 redstone_block 0  
fill ~1 ~-2 ~30 ~42 ~-2 ~30 redstone_block 0  
fill ~1 ~-2 ~31 ~42 ~-2 ~31 redstone_block 0  
fill ~1 ~-2 ~32 ~43 ~-2 ~32 redstone_block 0  
fill ~1 ~-2 ~33 ~43 ~-2 ~33 redstone_block 0  
fill ~1 ~-2 ~34 ~44 ~-2 ~34 redstone_block 0  
fill ~1 ~-2 ~35 ~44 ~-2 ~35 redstone_block 0  
fill ~1 ~-2 ~36 ~45 ~-2 ~36 redstone_block 0  
fill ~1 ~-2 ~37 ~45 ~-2 ~37 redstone_block 0  
fill ~1 ~-2 ~38 ~46 ~-2 ~38 redstone_block 0  
fill ~1 ~-2 ~39 ~46 ~-2 ~39 redstone_block 0  
fill ~1 ~-2 ~40 ~47 ~-2 ~40 redstone_block 0  
fill ~1 ~-2 ~41 ~47 ~-2 ~41 redstone_block 0  
fill ~1 ~-2 ~42 ~47 ~-2 ~42 redstone_block 0  
fill ~1 ~-2 ~43 ~48 ~-2 ~43 redstone_block 0  
fill ~1 ~-2 ~44 ~48 ~-2 ~44 redstone_block 0  
fill ~1 ~-2 ~45 ~48 ~-2 ~45 redstone_block 0  
fill ~1 ~-2 ~46 ~49 ~-2 ~46 redstone_block 0  
fill ~1 ~-2 ~47 ~49 ~-2 ~47 redstone_block 0  
fill ~1 ~-2 ~48 ~49 ~-2 ~48 redstone_block 0  
fill ~1 ~-2 ~49 ~49 ~-2 ~49 redstone_block 0  
fill ~1 ~-2 ~50 ~49 ~-2 ~50 redstone_block 0  
fill ~1 ~-2 ~51 ~50 ~-2 ~51 redstone_block 0  
fill ~1 ~-2 ~52 ~50 ~-2 ~52 redstone_block 0  
fill ~1 ~-2 ~53 ~50 ~-2 ~53 redstone_block 0  
fill ~1 ~-2 ~54 ~50 ~-2 ~54 redstone_block 0  
fill ~1 ~-2 ~55 ~50 ~-2 ~55 redstone_block 0  
fill ~1 ~-2 ~56 ~50 ~-2 ~56 redstone_block 0  
fill ~1 ~-2 ~57 ~50 ~-2 ~57 redstone_block 0  
fill ~1 ~-2 ~58 ~50 ~-2 ~58 redstone_block 0  
fill ~1 ~-2 ~59 ~50 ~-2 ~59 redstone_block 0  
fill ~1 ~-2 ~60 ~50 ~-2 ~60 redstone_block 0  
fill ~1 ~-2 ~61 ~50 ~-2 ~61 redstone_block 0  
fill ~1 ~-2 ~62 ~50 ~-2 ~62 redstone_block 0  
fill ~1 ~-2 ~63 ~50 ~-2 ~63 redstone_block 0  
fill ~1 ~-2 ~64 ~50 ~-2 ~64 redstone_block 0  
fill ~1 ~-2 ~65 ~33 ~-2 ~65 redstone_block 0  
fill ~1 ~-2 ~66 ~33 ~-2 ~66 redstone_block 0  
fill ~1 ~-2 ~67 ~33 ~-2 ~67 redstone_block 0  
fill ~1 ~-2 ~68 ~33 ~-2 ~68 redstone_block 0  
fill ~1 ~-2 ~69 ~33 ~-2 ~69 redstone_block 0  
fill ~1 ~-2 ~70 ~33 ~-2 ~70 redstone_block 0  
fill ~1 ~-2 ~71 ~33 ~-2 ~71 redstone_block 0  
fill ~1 ~-2 ~72 ~32 ~-2 ~72 redstone_block 0  
fill ~1 ~-2 ~73 ~32 ~-2 ~73 redstone_block 0  
fill ~1 ~-2 ~74 ~32 ~-2 ~74 redstone_block 0  
fill ~1 ~-2 ~75 ~32 ~-2 ~75 redstone_block 0  
fill ~1 ~-2 ~76 ~32 ~-2 ~76 redstone_block 0  
fill ~1 ~-2 ~77 ~31 ~-2 ~77 redstone_block 0  
fill ~1 ~-2 ~78 ~31 ~-2 ~78 redstone_block 0  
fill ~1 ~-2 ~79 ~31 ~-2 ~79 redstone_block 0  
fill ~1 ~-2 ~80 ~30 ~-2 ~80 redstone_block 0  
fill ~1 ~-2 ~81 ~30 ~-2 ~81 redstone_block 0  
fill ~1 ~-2 ~82 ~30 ~-2 ~82 redstone_block 0  
fill ~1 ~-2 ~83 ~29 ~-2 ~83 redstone_block 0  
fill ~1 ~-2 ~84 ~29 ~-2 ~84 redstone_block 0  
fill ~1 ~-2 ~85 ~28 ~-2 ~85 redstone_block 0  
fill ~1 ~-2 ~86 ~28 ~-2 ~86 redstone_block 0  
fill ~1 ~-2 ~87 ~27 ~-2 ~87 redstone_block 0  
fill ~1 ~-2 ~88 ~63 ~-2 ~88 redstone_block 0  
fill ~1 ~-2 ~89 ~63 ~-2 ~89 redstone_block 0  
fill ~1 ~-2 ~90 ~63 ~-2 ~90 redstone_block 0  
fill ~1 ~-2 ~91 ~63 ~-2 ~91 redstone_block 0  
fill ~1 ~-2 ~92 ~63 ~-2 ~92 redstone_block 0  
fill ~1 ~-2 ~93 ~63 ~-2 ~93 redstone_block 0  
fill ~1 ~-2 ~94 ~63 ~-2 ~94 redstone_block 0  
fill ~1 ~-2 ~95 ~71 ~-2 ~95 redstone_block 0  
fill ~1 ~-2 ~96 ~76 ~-2 ~96 redstone_block 0  
fill ~1 ~-2 ~97 ~79 ~-2 ~97 redstone_block 0  
fill ~1 ~-2 ~98 ~82 ~-2 ~98 redstone_block 0  
fill ~1 ~-2 ~99 ~84 ~-2 ~99 redstone_block 0  
fill ~1 ~-2 ~100 ~86 ~-2 ~100 redstone_block 0  
fill ~1 ~-2 ~101 ~127 ~-2 ~101 redstone_block 0  
fill ~1 ~-2 ~102 ~127 ~-2 ~102 redstone_block 0  
fill ~1 ~-2 ~103 ~127 ~-2 ~103 redstone_block 0  
fill ~1 ~-2 ~104 ~127 ~-2 ~104 redstone_block 0  
fill ~1 ~-2 ~105 ~12 ~-2 ~105 redstone_block 0  
fill ~1 ~-2 ~106 ~11 ~-2 ~106 redstone_block 0  
fill ~1 ~-2 ~107 ~9 ~-2 ~107 redstone_block 0  
fill ~1 ~-2 ~108 ~7 ~-2 ~108 redstone_block 0  
fill ~1 ~-2 ~109 ~5 ~-2 ~109 redstone_block 0  
fill ~1 ~-2 ~110 ~3 ~-2 ~110 redstone_block 0  
fill ~1 ~-2 ~111 ~1 ~-2 ~111 redstone_block 0  
fill ~1 ~-2 ~112 ~10 ~-2 ~112 dirt 0  
fill ~1 ~-2 ~113 ~9 ~-2 ~113 dirt 0  
fill ~1 ~-2 ~114 ~9 ~-2 ~114 dirt 0  
fill ~1 ~-2 ~115 ~9 ~-2 ~115 dirt 0  
fill ~1 ~-2 ~116 ~8 ~-2 ~116 dirt 0  
fill ~1 ~-2 ~117 ~8 ~-2 ~117 dirt 0  
fill ~1 ~-2 ~118 ~8 ~-2 ~118 dirt 0  
fill ~1 ~-2 ~119 ~8 ~-2 ~119 dirt 0  
fill ~1 ~-2 ~120 ~8 ~-2 ~120 dirt 0  
fill ~1 ~-2 ~121 ~7 ~-2 ~121 dirt 0  
fill ~1 ~-2 ~122 ~7 ~-2 ~122 dirt 0  
fill ~1 ~-2 ~123 ~7 ~-2 ~123 dirt 0  
fill ~1 ~-2 ~124 ~7 ~-2 ~124 dirt 0  
fill ~1 ~-2 ~125 ~7 ~-2 ~125 dirt 0  
fill ~1 ~-2 ~126 ~7 ~-2 ~126 dirt 0  
fill ~1 ~-2 ~127 ~7 ~-2 ~127 dirt 0  
fill ~2 ~-2 ~111 ~10 ~-2 ~111 dirt 0  
fill ~4 ~-2 ~110 ~10 ~-2 ~110 dirt 0  
fill ~6 ~-2 ~109 ~11 ~-2 ~109 dirt 0  
fill ~8 ~-2 ~8 ~20 ~-2 ~8 dirt 0  
fill ~8 ~-2 ~108 ~11 ~-2 ~108 dirt 0  
fill ~8 ~-2 ~121 ~108 ~-2 ~121 redstone_block 0  
fill ~8 ~-2 ~122 ~108 ~-2 ~122 redstone_block 0  
fill ~8 ~-2 ~123 ~109 ~-2 ~123 redstone_block 0  
fill ~8 ~-2 ~124 ~109 ~-2 ~124 redstone_block 0  
fill ~8 ~-2 ~125 ~110 ~-2 ~125 redstone_block 0  
fill ~8 ~-2 ~126 ~110 ~-2 ~126 redstone_block 0  
fill ~8 ~-2 ~127 ~111 ~-2 ~127 redstone_block 0  
fill ~9 ~-2 ~116 ~105 ~-2 ~116 redstone_block 0  
fill ~9 ~-2 ~117 ~106 ~-2 ~117 redstone_block 0  
fill ~9 ~-2 ~118 ~106 ~-2 ~118 redstone_block 0  
fill ~9 ~-2 ~119 ~107 ~-2 ~119 redstone_block 0  
fill ~9 ~-2 ~120 ~107 ~-2 ~120 redstone_block 0  
fill ~10 ~-2 ~107 ~12 ~-2 ~107 dirt 0  
fill ~10 ~-2 ~113 ~127 ~-2 ~113 redstone_block 0  
fill ~10 ~-2 ~114 ~127 ~-2 ~114 redstone_block 0  
fill ~10 ~-2 ~115 ~104 ~-2 ~115 redstone_block 0  
fill ~11 ~-2 ~110 ~127 ~-2 ~110 redstone_block 0  
fill ~11 ~-2 ~111 ~127 ~-2 ~111 redstone_block 0  
fill ~11 ~-2 ~112 ~127 ~-2 ~112 redstone_block 0  
fill ~12 ~-2 ~106 ~12 ~-1 ~106 dirt 0  
fill ~12 ~-2 ~108 ~127 ~-2 ~108 redstone_block 0  
fill ~12 ~-2 ~109 ~127 ~-2 ~109 redstone_block 0  
fill ~13 ~-2 ~9 ~20 ~-2 ~9 dirt 0  
fill ~13 ~-2 ~105 ~13 ~-1 ~105 dirt 0  
fill ~13 ~-2 ~106 ~127 ~-2 ~106 redstone_block 0  
fill ~13 ~-2 ~107 ~127 ~-2 ~107 redstone_block 0  
fill ~14 ~-2 ~105 ~127 ~-2 ~105 redstone_block 0  
fill ~16 ~-2 ~10 ~21 ~-2 ~10 dirt 0  
fill ~17 ~-2 ~1 ~120 ~-2 ~1 redstone_block 0  
fill ~18 ~-2 ~2 ~120 ~-2 ~2 redstone_block 0  
fill ~18 ~-2 ~3 ~120 ~-2 ~3 redstone_block 0  
fill ~19 ~-2 ~4 ~120 ~-2 ~4 redstone_block 0  
fill ~19 ~-2 ~5 ~120 ~-2 ~5 redstone_block 0  
fill ~19 ~-2 ~11 ~21 ~-2 ~11 dirt 0  
fill ~20 ~-2 ~6 ~120 ~-2 ~6 redstone_block 0  
fill ~20 ~-2 ~7 ~120 ~-2 ~7 redstone_block 0  
fill ~21 ~-2 ~8 ~119 ~-2 ~8 redstone_block 0  
fill ~21 ~-2 ~9 ~119 ~-2 ~9 redstone_block 0  
fill ~21 ~-2 ~12 ~22 ~-2 ~12 dirt 0  
fill ~22 ~-2 ~10 ~119 ~-2 ~10 redstone_block 0  
fill ~22 ~-2 ~11 ~119 ~-2 ~11 redstone_block 0  
fill ~23 ~-2 ~12 ~119 ~-2 ~12 redstone_block 0  
fill ~23 ~-2 ~13 ~23 ~-1 ~13 dirt 0  
fill ~24 ~-2 ~13 ~118 ~-2 ~13 redstone_block 0  
fill ~28 ~-2 ~87 ~28 ~-1 ~87 dirt 0  
fill ~29 ~-2 ~85 ~31 ~-2 ~85 dirt 0  
fill ~29 ~-2 ~86 ~29 ~-1 ~86 dirt 0  
fill ~29 ~-2 ~87 ~63 ~-2 ~87 redstone_block 0  
fill ~30 ~-2 ~83 ~35 ~-2 ~83 dirt 0  
fill ~30 ~-2 ~84 ~33 ~-2 ~84 dirt 0  
fill ~30 ~-2 ~86 ~63 ~-2 ~86 redstone_block 0  
fill ~31 ~-2 ~80 ~42 ~-2 ~80 dirt 0  
fill ~31 ~-2 ~81 ~39 ~-2 ~81 dirt 0  
fill ~31 ~-2 ~82 ~37 ~-2 ~82 dirt 0  
fill ~32 ~-2 ~77 ~77 ~-2 ~77 dirt 0  
fill ~32 ~-2 ~78 ~50 ~-2 ~78 dirt 0  
fill ~32 ~-2 ~79 ~45 ~-2 ~79 dirt 0  
fill ~32 ~-2 ~85 ~63 ~-2 ~85 redstone_block 0  
fill ~33 ~-2 ~72 ~77 ~-2 ~72 dirt 0  
fill ~33 ~-2 ~73 ~77 ~-2 ~73 dirt 0  
fill ~33 ~-2 ~74 ~77 ~-2 ~74 dirt 0  
fill ~33 ~-2 ~75 ~77 ~-2 ~75 dirt 0  
fill ~33 ~-2 ~76 ~77 ~-2 ~76 dirt 0  
fill ~34 ~-2 ~65 ~77 ~-2 ~65 dirt 0  
fill ~34 ~-2 ~66 ~77 ~-2 ~66 dirt 0  
fill ~34 ~-2 ~67 ~77 ~-2 ~67 dirt 0  
fill ~34 ~-2 ~68 ~77 ~-2 ~68 dirt 0  
fill ~34 ~-2 ~69 ~77 ~-2 ~69 dirt 0  
fill ~34 ~-2 ~70 ~77 ~-2 ~70 dirt 0  
fill ~34 ~-2 ~71 ~77 ~-2 ~71 dirt 0  
fill ~34 ~-2 ~84 ~63 ~-2 ~84 redstone_block 0  
fill ~36 ~-2 ~83 ~63 ~-2 ~83 redstone_block 0  
fill ~38 ~-2 ~82 ~63 ~-2 ~82 redstone_block 0  
fill ~40 ~-2 ~81 ~63 ~-2 ~81 redstone_block 0  
fill ~41 ~-2 ~28 ~41 ~-1 ~28 dirt 0  
fill ~42 ~-2 ~28 ~127 ~-2 ~28 redstone_block 0  
fill ~42 ~-2 ~29 ~43 ~-2 ~29 dirt 0  
fill ~43 ~-2 ~30 ~45 ~-2 ~30 dirt 0  
fill ~43 ~-2 ~31 ~48 ~-2 ~31 dirt 0  
fill ~43 ~-2 ~80 ~63 ~-2 ~80 redstone_block 0  
fill ~44 ~-2 ~29 ~127 ~-2 ~29 redstone_block 0  
fill ~44 ~-2 ~32 ~51 ~-2 ~32 dirt 0  
fill ~44 ~-2 ~33 ~56 ~-2 ~33 dirt 0  
fill ~45 ~-2 ~34 ~63 ~-2 ~34 dirt 0  
fill ~45 ~-2 ~35 ~63 ~-2 ~35 dirt 0  
fill ~46 ~-2 ~30 ~127 ~-2 ~30 redstone_block 0  
fill ~46 ~-2 ~36 ~63 ~-2 ~36 dirt 0  
fill ~46 ~-2 ~37 ~63 ~-2 ~37 dirt 0  
fill ~46 ~-2 ~79 ~63 ~-2 ~79 redstone_block 0  
fill ~47 ~-2 ~38 ~63 ~-2 ~38 dirt 0  
fill ~47 ~-2 ~39 ~63 ~-2 ~39 dirt 0  
fill ~48 ~-2 ~40 ~63 ~-2 ~40 dirt 0  
fill ~48 ~-2 ~41 ~63 ~-2 ~41 dirt 0  
fill ~48 ~-2 ~42 ~63 ~-2 ~42 dirt 0  
fill ~49 ~-2 ~31 ~127 ~-2 ~31 redstone_block 0  
fill ~49 ~-2 ~43 ~63 ~-2 ~43 dirt 0  
fill ~49 ~-2 ~44 ~63 ~-2 ~44 dirt 0  
fill ~49 ~-2 ~45 ~63 ~-2 ~45 dirt 0  
fill ~50 ~-2 ~46 ~63 ~-2 ~46 dirt 0  
fill ~50 ~-2 ~47 ~63 ~-2 ~47 dirt 0  
fill ~50 ~-2 ~48 ~63 ~-2 ~48 dirt 0  
fill ~50 ~-2 ~49 ~63 ~-2 ~49 dirt 0  
fill ~50 ~-2 ~50 ~63 ~-2 ~50 dirt 0  
fill ~51 ~-2 ~51 ~96 ~-2 ~51 dirt 0  
fill ~51 ~-2 ~52 ~95 ~-2 ~52 dirt 0  
fill ~51 ~-2 ~53 ~95 ~-2 ~53 dirt 0  
fill ~51 ~-2 ~54 ~95 ~-2 ~54 dirt 0  
fill ~51 ~-2 ~55 ~95 ~-2 ~55 dirt 0  
fill ~51 ~-2 ~56 ~95 ~-2 ~56 dirt 0  
fill ~51 ~-2 ~57 ~94 ~-2 ~57 dirt 0  
fill ~51 ~-2 ~58 ~94 ~-2 ~58 dirt 0  
fill ~51 ~-2 ~59 ~94 ~-2 ~59 dirt 0  
fill ~51 ~-2 ~60 ~94 ~-2 ~60 dirt 0  
fill ~51 ~-2 ~61 ~94 ~-2 ~61 dirt 0  
fill ~51 ~-2 ~62 ~94 ~-2 ~62 dirt 0  
fill ~51 ~-2 ~63 ~94 ~-2 ~63 dirt 0  
fill ~51 ~-2 ~64 ~63 ~-2 ~64 dirt 0  
fill ~51 ~-2 ~78 ~63 ~-2 ~78 redstone_block 0  
fill ~52 ~-2 ~32 ~127 ~-2 ~32 redstone_block 0  
fill ~57 ~-2 ~33 ~127 ~-2 ~33 redstone_block 0  
fill ~64 ~-2 ~34 ~127 ~-2 ~34 redstone_block 0  
fill ~64 ~-2 ~35 ~127 ~-2 ~35 redstone_block 0  
fill ~64 ~-2 ~36 ~127 ~-2 ~36 redstone_block 0  
fill ~64 ~-2 ~37 ~127 ~-2 ~37 redstone_block 0  
fill ~64 ~-2 ~38 ~127 ~-2 ~38 redstone_block 0  
fill ~64 ~-2 ~39 ~127 ~-2 ~39 redstone_block 0  
fill ~64 ~-2 ~40 ~127 ~-2 ~40 redstone_block 0  
fill ~64 ~-2 ~41 ~99 ~-2 ~41 redstone_block 0  
fill ~64 ~-2 ~42 ~98 ~-2 ~42 redstone_block 0  
fill ~64 ~-2 ~43 ~96 ~-2 ~43 redstone_block 0  
fill ~64 ~-2 ~44 ~94 ~-2 ~44 redstone_block 0  
fill ~64 ~-2 ~45 ~92 ~-2 ~45 redstone_block 0  
fill ~64 ~-2 ~46 ~90 ~-2 ~46 redstone_block 0  
fill ~64 ~-2 ~47 ~88 ~-2 ~47 redstone_block 0  
fill ~64 ~-2 ~48 ~85 ~-2 ~48 redstone_block 0  
fill ~64 ~-2 ~49 ~82 ~-2 ~49 redstone_block 0  
fill ~64 ~-2 ~50 ~77 ~-2 ~50 redstone_block 0  
fill ~64 ~-2 ~78 ~78 ~-2 ~78 dirt 0  
fill ~64 ~-2 ~79 ~78 ~-2 ~79 dirt 0  
fill ~64 ~-2 ~80 ~78 ~-2 ~80 dirt 0  
fill ~64 ~-2 ~81 ~78 ~-2 ~81 dirt 0  
fill ~64 ~-2 ~82 ~78 ~-2 ~82 dirt 0  
fill ~64 ~-2 ~83 ~79 ~-2 ~83 dirt 0  
fill ~64 ~-2 ~84 ~79 ~-2 ~84 dirt 0  
fill ~64 ~-2 ~85 ~79 ~-2 ~85 dirt 0  
fill ~64 ~-2 ~86 ~80 ~-2 ~86 dirt 0  
fill ~64 ~-2 ~87 ~80 ~-2 ~87 dirt 0  
fill ~64 ~-2 ~88 ~80 ~-2 ~88 dirt 0  
fill ~64 ~-2 ~89 ~81 ~-2 ~89 dirt 0  
fill ~64 ~-2 ~90 ~81 ~-2 ~90 dirt 0  
fill ~64 ~-2 ~91 ~82 ~-2 ~91 dirt 0  
fill ~64 ~-2 ~92 ~82 ~-2 ~92 dirt 0  
fill ~64 ~-2 ~93 ~83 ~-2 ~93 dirt 0  
fill ~64 ~-2 ~94 ~83 ~-2 ~94 dirt 0  
fill ~65 ~-2 ~64 ~77 ~-2 ~64 dirt 0  
fill ~72 ~-2 ~95 ~84 ~-2 ~95 dirt 0  
fill ~77 ~-2 ~96 ~84 ~-2 ~96 dirt 0  
fill ~78 ~-2 ~50 ~96 ~-2 ~50 dirt 0  
fill ~78 ~-2 ~64 ~127 ~-2 ~64 redstone_block 0  
fill ~78 ~-2 ~65 ~127 ~-2 ~65 redstone_block 0  
fill ~78 ~-2 ~66 ~127 ~-2 ~66 redstone_block 0  
fill ~78 ~-2 ~67 ~127 ~-2 ~67 redstone_block 0  
fill ~78 ~-2 ~68 ~127 ~-2 ~68 redstone_block 0  
fill ~78 ~-2 ~69 ~127 ~-2 ~69 redstone_block 0  
fill ~78 ~-2 ~70 ~127 ~-2 ~70 redstone_block 0  
fill ~78 ~-2 ~71 ~127 ~-2 ~71 redstone_block 0  
fill ~78 ~-2 ~72 ~127 ~-2 ~72 redstone_block 0  
fill ~78 ~-2 ~73 ~127 ~-2 ~73 redstone_block 0  
fill ~78 ~-2 ~74 ~127 ~-2 ~74 redstone_block 0  
fill ~78 ~-2 ~75 ~127 ~-2 ~75 redstone_block 0  
fill ~78 ~-2 ~76 ~127 ~-2 ~76 redstone_block 0  
fill ~78 ~-2 ~77 ~127 ~-2 ~77 redstone_block 0  
fill ~79 ~-2 ~78 ~127 ~-2 ~78 redstone_block 0  
fill ~79 ~-2 ~79 ~127 ~-2 ~79 redstone_block 0  
fill ~79 ~-2 ~80 ~127 ~-2 ~80 redstone_block 0  
fill ~79 ~-2 ~81 ~127 ~-2 ~81 redstone_block 0  
fill ~79 ~-2 ~82 ~127 ~-2 ~82 redstone_block 0  
fill ~80 ~-2 ~83 ~127 ~-2 ~83 redstone_block 0  
fill ~80 ~-2 ~84 ~127 ~-2 ~84 redstone_block 0  
fill ~80 ~-2 ~85 ~127 ~-2 ~85 redstone_block 0  
fill ~80 ~-2 ~97 ~85 ~-2 ~97 dirt 0  
fill ~81 ~-2 ~86 ~127 ~-2 ~86 redstone_block 0  
fill ~81 ~-2 ~87 ~127 ~-2 ~87 redstone_block 0  
fill ~81 ~-2 ~88 ~127 ~-2 ~88 redstone_block 0  
fill ~82 ~-2 ~89 ~127 ~-2 ~89 redstone_block 0  
fill ~82 ~-2 ~90 ~127 ~-2 ~90 redstone_block 0  
fill ~83 ~-2 ~49 ~96 ~-2 ~49 dirt 0  
fill ~83 ~-2 ~91 ~127 ~-2 ~91 redstone_block 0  
fill ~83 ~-2 ~92 ~127 ~-2 ~92 redstone_block 0  
fill ~83 ~-2 ~98 ~85 ~-2 ~98 dirt 0  
fill ~84 ~-2 ~93 ~127 ~-2 ~93 redstone_block 0  
fill ~84 ~-2 ~94 ~127 ~-2 ~94 redstone_block 0  
fill ~85 ~-2 ~95 ~127 ~-2 ~95 redstone_block 0  
fill ~85 ~-2 ~96 ~127 ~-2 ~96 redstone_block 0  
fill ~85 ~-2 ~99 ~86 ~-2 ~99 dirt 0  
fill ~86 ~-2 ~48 ~97 ~-2 ~48 dirt 0  
fill ~86 ~-2 ~97 ~127 ~-2 ~97 redstone_block 0  
fill ~86 ~-2 ~98 ~127 ~-2 ~98 redstone_block 0  
fill ~87 ~-2 ~99 ~127 ~-2 ~99 redstone_block 0  
fill ~87 ~-2 ~100 ~87 ~-1 ~100 dirt 0  
fill ~88 ~-2 ~100 ~127 ~-2 ~100 redstone_block 0  
fill ~89 ~-2 ~47 ~97 ~-2 ~47 dirt 0  
fill ~91 ~-2 ~46 ~97 ~-2 ~46 dirt 0  
fill ~93 ~-2 ~45 ~98 ~-2 ~45 dirt 0  
fill ~95 ~-2 ~44 ~98 ~-2 ~44 dirt 0  
fill ~95 ~-2 ~57 ~127 ~-2 ~57 redstone_block 0  
fill ~95 ~-2 ~58 ~127 ~-2 ~58 redstone_block 0  
fill ~95 ~-2 ~59 ~127 ~-2 ~59 redstone_block 0  
fill ~95 ~-2 ~60 ~127 ~-2 ~60 redstone_block 0  
fill ~95 ~-2 ~61 ~127 ~-2 ~61 redstone_block 0  
fill ~95 ~-2 ~62 ~127 ~-2 ~62 redstone_block 0  
fill ~95 ~-2 ~63 ~127 ~-2 ~63 redstone_block 0  
fill ~96 ~-2 ~52 ~127 ~-2 ~52 redstone_block 0  
fill ~96 ~-2 ~53 ~127 ~-2 ~53 redstone_block 0  
fill ~96 ~-2 ~54 ~127 ~-2 ~54 redstone_block 0  
fill ~96 ~-2 ~55 ~127 ~-2 ~55 redstone_block 0  
fill ~96 ~-2 ~56 ~127 ~-2 ~56 redstone_block 0  
fill ~97 ~-2 ~43 ~99 ~-2 ~43 dirt 0  
fill ~97 ~-2 ~49 ~127 ~-2 ~49 redstone_block 0  
fill ~97 ~-2 ~50 ~127 ~-2 ~50 redstone_block 0  
fill ~97 ~-2 ~51 ~127 ~-2 ~51 redstone_block 0  
fill ~98 ~-2 ~46 ~127 ~-2 ~46 redstone_block 0  
fill ~98 ~-2 ~47 ~127 ~-2 ~47 redstone_block 0  
fill ~98 ~-2 ~48 ~127 ~-2 ~48 redstone_block 0  
fill ~99 ~-2 ~42 ~99 ~-1 ~42 dirt 0  
fill ~99 ~-2 ~44 ~127 ~-2 ~44 redstone_block 0  
fill ~99 ~-2 ~45 ~127 ~-2 ~45 redstone_block 0  
fill ~100 ~-2 ~41 ~100 ~-1 ~41 dirt 0  
fill ~100 ~-2 ~42 ~127 ~-2 ~42 redstone_block 0  
fill ~100 ~-2 ~43 ~127 ~-2 ~43 redstone_block 0  
fill ~101 ~-2 ~41 ~127 ~-2 ~41 redstone_block 0  
fill ~105 ~-2 ~115 ~105 ~-1 ~115 dirt 0  
fill ~106 ~-2 ~115 ~127 ~-2 ~115 redstone_block 0  
fill ~106 ~-2 ~116 ~107 ~-2 ~116 dirt 0  
fill ~107 ~-2 ~117 ~109 ~-2 ~117 dirt 0  
fill ~107 ~-2 ~118 ~112 ~-2 ~118 dirt 0  
fill ~108 ~-2 ~116 ~127 ~-2 ~116 redstone_block 0  
fill ~108 ~-2 ~119 ~115 ~-2 ~119 dirt 0  
fill ~108 ~-2 ~120 ~120 ~-2 ~120 dirt 0  
fill ~109 ~-2 ~121 ~127 ~-2 ~121 dirt 0  
fill ~109 ~-2 ~122 ~127 ~-2 ~122 dirt 0  
fill ~110 ~-2 ~117 ~127 ~-2 ~117 redstone_block 0  
fill ~110 ~-2 ~123 ~127 ~-2 ~123 dirt 0  
fill ~110 ~-2 ~124 ~127 ~-2 ~124 dirt 0  
fill ~111 ~-2 ~125 ~127 ~-2 ~125 dirt 0  
fill ~111 ~-2 ~126 ~127 ~-2 ~126 dirt 0  
fill ~112 ~-2 ~127 ~127 ~-2 ~127 dirt 0  
fill ~113 ~-2 ~118 ~127 ~-2 ~118 redstone_block 0  
fill ~115 ~-2 ~23 ~115 ~-1 ~23 dirt 0  
fill ~116 ~-2 ~21 ~118 ~-2 ~21 dirt 0  
fill ~116 ~-2 ~22 ~116 ~-1 ~22 dirt 0  
fill ~116 ~-2 ~23 ~127 ~-2 ~23 redstone_block 0  
fill ~116 ~-2 ~119 ~127 ~-2 ~119 redstone_block 0  
fill ~117 ~-2 ~19 ~122 ~-2 ~19 dirt 0  
fill ~117 ~-2 ~20 ~120 ~-2 ~20 dirt 0  
fill ~117 ~-2 ~22 ~127 ~-2 ~22 redstone_block 0  
fill ~118 ~-2 ~16 ~127 ~-2 ~16 dirt 0  
fill ~118 ~-2 ~17 ~126 ~-2 ~17 dirt 0  
fill ~118 ~-2 ~18 ~124 ~-2 ~18 dirt 0  
fill ~119 ~-2 ~13 ~127 ~-2 ~13 dirt 0  
fill ~119 ~-2 ~14 ~127 ~-2 ~14 dirt 0  
fill ~119 ~-2 ~15 ~127 ~-2 ~15 dirt 0  
fill ~119 ~-2 ~21 ~127 ~-2 ~21 redstone_block 0  
fill ~120 ~-2 ~8 ~127 ~-2 ~8 dirt 0  
fill ~120 ~-2 ~9 ~127 ~-2 ~9 dirt 0  
fill ~120 ~-2 ~10 ~127 ~-2 ~10 dirt 0  
fill ~120 ~-2 ~11 ~127 ~-2 ~11 dirt 0  
fill ~120 ~-2 ~12 ~127 ~-2 ~12 dirt 0  
fill ~121 ~-2 ~1 ~127 ~-2 ~1 dirt 0  
fill ~121 ~-2 ~2 ~127 ~-2 ~2 dirt 0  
fill ~121 ~-2 ~3 ~127 ~-2 ~3 dirt 0  
fill ~121 ~-2 ~4 ~127 ~-2 ~4 dirt 0  
fill ~121 ~-2 ~5 ~127 ~-2 ~5 dirt 0  
fill ~121 ~-2 ~6 ~127 ~-2 ~6 dirt 0  
fill ~121 ~-2 ~7 ~127 ~-2 ~7 dirt 0  
fill ~121 ~-2 ~20 ~127 ~-2 ~20 redstone_block 0  
fill ~121 ~-2 ~120 ~127 ~-2 ~120 redstone_block 0  
fill ~123 ~-2 ~19 ~127 ~-2 ~19 redstone_block 0  
fill ~125 ~-2 ~18 ~127 ~-2 ~18 redstone_block 0  
fill ~127 ~-2 ~17 ~127 ~-2 ~17 redstone_block 0  
fill ~1 ~-1 ~1 ~1 ~-2 ~1 dirt 0  
fill ~1 ~-1 ~2 ~1 ~-1 ~2 grass 0  
fill ~1 ~-1 ~3 ~1 ~-1 ~3 grass 0  
fill ~1 ~-1 ~4 ~127 ~-1 ~4 dirt 0  
fill ~1 ~-1 ~5 ~1 ~-1 ~5 grass 0  
fill ~1 ~-1 ~6 ~1 ~-1 ~6 grass 0  
fill ~1 ~-1 ~7 ~127 ~-1 ~7 dirt 0  
fill ~1 ~-1 ~8 ~1 ~-1 ~8 grass 0  
fill ~1 ~-1 ~9 ~1 ~-1 ~9 grass 0  
fill ~1 ~-1 ~10 ~127 ~-1 ~10 dirt 0  
fill ~1 ~-1 ~11 ~1 ~-1 ~11 grass 0  
fill ~1 ~-1 ~12 ~1 ~-1 ~12 grass 0  
fill ~1 ~-1 ~13 ~127 ~-1 ~13 dirt 0  
fill ~1 ~-1 ~14 ~1 ~-1 ~14 grass 0  
fill ~1 ~-1 ~15 ~1 ~-1 ~15 grass 0  
fill ~1 ~-1 ~16 ~127 ~-1 ~16 dirt 0  
fill ~1 ~-1 ~17 ~1 ~-1 ~17 grass 0 
setblock ~1 ~-1 ~18 grass 0  
fill ~1 ~-1 ~19 ~127 ~-1 ~19 dirt 0  
fill ~1 ~-1 ~20 ~1 ~-1 ~20 grass 0  
fill ~1 ~-1 ~21 ~1 ~-1 ~21 grass 0  
fill ~1 ~-1 ~22 ~127 ~-1 ~22 dirt 0  
fill ~1 ~-1 ~23 ~1 ~-1 ~23 grass 0 
setblock ~1 ~-1 ~24 grass 0  
fill ~1 ~-1 ~25 ~127 ~-1 ~25 dirt 0  
fill ~1 ~-1 ~26 ~1 ~-1 ~27 grass 0  
fill ~1 ~-1 ~28 ~127 ~-1 ~28 dirt 0  
fill ~1 ~-1 ~29 ~1 ~-1 ~30 grass 0  
fill ~1 ~-1 ~31 ~127 ~-1 ~31 dirt 0  
fill ~1 ~-1 ~32 ~1 ~-1 ~33 grass 0  
fill ~1 ~-1 ~34 ~127 ~-1 ~34 dirt 0  
fill ~1 ~-1 ~35 ~1 ~-1 ~35 grass 0  
fill ~1 ~-1 ~36 ~1 ~-1 ~36 grass 0  
fill ~1 ~-1 ~37 ~127 ~-1 ~37 dirt 0  
fill ~1 ~-1 ~38 ~1 ~-1 ~38 grass 0  
fill ~1 ~-1 ~39 ~1 ~-1 ~39 grass 0  
fill ~1 ~-1 ~40 ~75 ~-1 ~40 dirt 0  
fill ~1 ~-1 ~41 ~1 ~-1 ~41 grass 0  
fill ~1 ~-1 ~42 ~1 ~-1 ~42 grass 0  
fill ~1 ~-1 ~43 ~127 ~-1 ~43 dirt 0  
fill ~1 ~-1 ~44 ~1 ~-1 ~44 grass 0  
fill ~1 ~-1 ~45 ~1 ~-1 ~45 grass 0  
fill ~1 ~-1 ~46 ~41 ~-1 ~46 dirt 0  
fill ~1 ~-1 ~47 ~1 ~-1 ~47 grass 0  
fill ~1 ~-1 ~48 ~1 ~-1 ~48 grass 0  
fill ~1 ~-1 ~49 ~45 ~-1 ~49 dirt 0  
fill ~1 ~-1 ~50 ~1 ~-1 ~51 grass 0  
fill ~1 ~-1 ~52 ~39 ~-1 ~52 dirt 0  
fill ~1 ~-1 ~53 ~1 ~-1 ~53 grass 0 
setblock ~1 ~-1 ~54 grass 0  
fill ~1 ~-1 ~55 ~127 ~-1 ~55 dirt 0  
fill ~1 ~-1 ~56 ~1 ~-1 ~56 grass 0  
fill ~1 ~-1 ~57 ~1 ~-1 ~57 grass 0  
fill ~1 ~-1 ~58 ~127 ~-1 ~58 dirt 0  
fill ~1 ~-1 ~59 ~1 ~-1 ~59 grass 0 
setblock ~1 ~-1 ~60 grass 0  
fill ~1 ~-1 ~61 ~127 ~-1 ~61 dirt 0  
fill ~1 ~-1 ~62 ~1 ~-1 ~62 grass 0  
fill ~1 ~-1 ~63 ~1 ~-1 ~63 grass 0  
fill ~1 ~-1 ~64 ~63 ~-1 ~64 dirt 0  
fill ~1 ~-1 ~65 ~1 ~-1 ~65 grass 0  
fill ~1 ~-1 ~66 ~1 ~-1 ~66 grass 0  
fill ~1 ~-1 ~67 ~127 ~-1 ~67 dirt 0  
fill ~1 ~-1 ~68 ~1 ~-1 ~68 grass 0  
fill ~1 ~-1 ~69 ~1 ~-1 ~69 grass 0  
fill ~1 ~-1 ~70 ~127 ~-1 ~70 dirt 0  
fill ~1 ~-1 ~71 ~1 ~-1 ~71 grass 0 
setblock ~1 ~-1 ~72 stained_hardened_clay 5  
fill ~1 ~-1 ~73 ~127 ~-1 ~73 dirt 0  
fill ~1 ~-1 ~74 ~1 ~-1 ~74 grass 0  
fill ~1 ~-1 ~75 ~1 ~-1 ~75 grass 0  
fill ~1 ~-1 ~76 ~41 ~-1 ~76 dirt 0  
fill ~1 ~-1 ~77 ~1 ~-1 ~77 grass 0  
fill ~1 ~-1 ~78 ~1 ~-1 ~78 grass 0  
fill ~1 ~-1 ~79 ~76 ~-1 ~79 dirt 0  
fill ~1 ~-1 ~80 ~1 ~-1 ~80 grass 0 
setblock ~1 ~-1 ~81 stained_hardened_clay 5  
fill ~1 ~-1 ~82 ~40 ~-1 ~82 dirt 0  
fill ~1 ~-1 ~83 ~1 ~-1 ~83 grass 0 
setblock ~1 ~-1 ~84 grass 0  
fill ~1 ~-1 ~85 ~127 ~-1 ~85 dirt 0  
fill ~1 ~-1 ~86 ~1 ~-1 ~86 grass 0  
fill ~1 ~-1 ~87 ~1 ~-1 ~87 grass 0  
fill ~1 ~-1 ~88 ~51 ~-1 ~88 dirt 0  
fill ~1 ~-1 ~89 ~1 ~-1 ~89 grass 0  
fill ~1 ~-1 ~90 ~1 ~-1 ~90 grass 0  
fill ~1 ~-1 ~91 ~127 ~-1 ~91 dirt 0  
fill ~1 ~-1 ~92 ~1 ~-1 ~92 grass 0  
fill ~1 ~-1 ~93 ~1 ~-1 ~93 grass 0  
fill ~1 ~-1 ~94 ~127 ~-1 ~94 dirt 0  
fill ~1 ~-1 ~95 ~1 ~-1 ~95 grass 0  
fill ~1 ~-1 ~96 ~1 ~-1 ~96 grass 0  
fill ~1 ~-1 ~97 ~127 ~-1 ~97 dirt 0  
fill ~1 ~-1 ~98 ~1 ~-1 ~98 grass 0  
fill ~1 ~-1 ~99 ~1 ~-1 ~99 grass 0  
fill ~1 ~-1 ~100 ~127 ~-1 ~100 dirt 0  
fill ~1 ~-1 ~101 ~1 ~-1 ~101 grass 0  
fill ~1 ~-1 ~102 ~1 ~-1 ~102 grass 0  
fill ~1 ~-1 ~103 ~127 ~-1 ~103 dirt 0  
fill ~1 ~-1 ~104 ~1 ~-1 ~104 grass 0  
fill ~1 ~-1 ~105 ~1 ~-1 ~105 grass 0  
fill ~1 ~-1 ~106 ~127 ~-1 ~106 dirt 0  
fill ~1 ~-1 ~107 ~1 ~-1 ~107 grass 0  
fill ~1 ~-1 ~108 ~1 ~-1 ~108 grass 0  
fill ~1 ~-1 ~109 ~127 ~-1 ~109 dirt 0  
fill ~1 ~-1 ~110 ~1 ~-1 ~111 grass 0  
fill ~1 ~-1 ~112 ~127 ~-1 ~112 dirt 0  
fill ~1 ~-1 ~113 ~1 ~-1 ~114 grass 0  
fill ~1 ~-1 ~115 ~127 ~-1 ~115 dirt 0  
fill ~1 ~-1 ~116 ~1 ~-1 ~117 grass 0  
fill ~1 ~-1 ~118 ~127 ~-1 ~118 dirt 0  
fill ~1 ~-1 ~119 ~1 ~-1 ~119 grass 0  
fill ~1 ~-1 ~120 ~1 ~-1 ~120 grass 0  
fill ~1 ~-1 ~121 ~127 ~-1 ~121 dirt 0  
fill ~1 ~-1 ~122 ~1 ~-1 ~122 grass 0  
fill ~1 ~-1 ~123 ~1 ~-1 ~123 grass 0  
fill ~1 ~-1 ~124 ~127 ~-1 ~124 dirt 0  
fill ~1 ~-1 ~125 ~1 ~-1 ~125 grass 0  
fill ~1 ~-1 ~126 ~1 ~-1 ~126 grass 0  
fill ~1 ~-1 ~127 ~1 ~-2 ~127 dirt 0  
fill ~2 ~-1 ~1 ~3 ~-1 ~1 grass 0  
fill ~2 ~-1 ~2 ~126 ~-1 ~2 dirt 0  
fill ~2 ~-1 ~3 ~126 ~-1 ~3 dirt 0  
fill ~2 ~-1 ~5 ~126 ~-1 ~5 dirt 0  
fill ~2 ~-1 ~6 ~126 ~-1 ~6 dirt 0  
fill ~2 ~-1 ~8 ~126 ~-1 ~8 dirt 0  
fill ~2 ~-1 ~9 ~126 ~-1 ~9 dirt 0  
fill ~2 ~-1 ~11 ~126 ~-1 ~11 dirt 0  
fill ~2 ~-1 ~12 ~126 ~-1 ~12 dirt 0  
fill ~2 ~-1 ~14 ~126 ~-1 ~14 dirt 0  
fill ~2 ~-1 ~15 ~126 ~-1 ~15 dirt 0  
fill ~2 ~-1 ~17 ~126 ~-1 ~17 dirt 0  
fill ~2 ~-1 ~18 ~126 ~-1 ~18 dirt 0  
fill ~2 ~-1 ~20 ~126 ~-1 ~20 dirt 0  
fill ~2 ~-1 ~21 ~126 ~-1 ~21 dirt 0  
fill ~2 ~-1 ~23 ~126 ~-1 ~23 dirt 0  
fill ~2 ~-1 ~24 ~126 ~-1 ~24 dirt 0  
fill ~2 ~-1 ~26 ~126 ~-1 ~26 dirt 0  
fill ~2 ~-1 ~27 ~126 ~-1 ~27 dirt 0  
fill ~2 ~-1 ~29 ~126 ~-1 ~29 dirt 0  
fill ~2 ~-1 ~30 ~126 ~-1 ~30 dirt 0  
fill ~2 ~-1 ~32 ~126 ~-1 ~32 dirt 0  
fill ~2 ~-1 ~33 ~126 ~-1 ~33 dirt 0  
fill ~2 ~-1 ~35 ~126 ~-1 ~35 dirt 0  
fill ~2 ~-1 ~36 ~126 ~-1 ~36 dirt 0  
fill ~2 ~-1 ~38 ~126 ~-1 ~38 dirt 0  
fill ~2 ~-1 ~39 ~126 ~-1 ~39 dirt 0  
fill ~2 ~-1 ~41 ~45 ~-1 ~41 dirt 0  
fill ~2 ~-1 ~42 ~51 ~-1 ~42 dirt 0  
fill ~2 ~-1 ~44 ~126 ~-1 ~44 dirt 0  
fill ~2 ~-1 ~45 ~126 ~-1 ~45 dirt 0  
fill ~2 ~-1 ~47 ~126 ~-1 ~47 dirt 0  
fill ~2 ~-1 ~48 ~126 ~-1 ~48 dirt 0  
fill ~2 ~-1 ~50 ~75 ~-1 ~50 dirt 0  
fill ~2 ~-1 ~51 ~78 ~-1 ~51 dirt 0  
fill ~2 ~-1 ~53 ~126 ~-1 ~53 dirt 0  
fill ~2 ~-1 ~54 ~126 ~-1 ~54 dirt 0  
fill ~2 ~-1 ~56 ~126 ~-1 ~56 dirt 0  
fill ~2 ~-1 ~57 ~126 ~-1 ~57 dirt 0  
fill ~2 ~-1 ~59 ~126 ~-1 ~59 dirt 0  
fill ~2 ~-1 ~60 ~126 ~-1 ~60 dirt 0  
fill ~2 ~-1 ~62 ~126 ~-1 ~62 dirt 0  
fill ~2 ~-1 ~63 ~126 ~-1 ~63 dirt 0  
fill ~2 ~-1 ~65 ~126 ~-1 ~65 dirt 0  
fill ~2 ~-1 ~66 ~126 ~-1 ~66 dirt 0  
fill ~2 ~-1 ~68 ~126 ~-1 ~68 dirt 0  
fill ~2 ~-1 ~69 ~126 ~-1 ~69 dirt 0  
fill ~2 ~-1 ~71 ~126 ~-1 ~71 dirt 0  
fill ~2 ~-1 ~72 ~126 ~-1 ~72 dirt 0  
fill ~2 ~-1 ~74 ~126 ~-1 ~74 dirt 0  
fill ~2 ~-1 ~75 ~126 ~-1 ~75 dirt 0  
fill ~2 ~-1 ~77 ~48 ~-1 ~77 dirt 0  
fill ~2 ~-1 ~78 ~51 ~-1 ~78 dirt 0  
fill ~2 ~-1 ~80 ~126 ~-1 ~80 dirt 0  
fill ~2 ~-1 ~81 ~126 ~-1 ~81 dirt 0  
fill ~2 ~-1 ~83 ~126 ~-1 ~83 dirt 0  
fill ~2 ~-1 ~84 ~126 ~-1 ~84 dirt 0  
fill ~2 ~-1 ~86 ~45 ~-1 ~86 dirt 0  
fill ~2 ~-1 ~87 ~81 ~-1 ~87 dirt 0  
fill ~2 ~-1 ~89 ~126 ~-1 ~89 dirt 0  
fill ~2 ~-1 ~90 ~126 ~-1 ~90 dirt 0  
fill ~2 ~-1 ~92 ~126 ~-1 ~92 dirt 0  
fill ~2 ~-1 ~93 ~126 ~-1 ~93 dirt 0  
fill ~2 ~-1 ~95 ~126 ~-1 ~95 dirt 0  
fill ~2 ~-1 ~96 ~126 ~-1 ~96 dirt 0  
fill ~2 ~-1 ~98 ~126 ~-1 ~98 dirt 0  
fill ~2 ~-1 ~99 ~126 ~-1 ~99 dirt 0  
fill ~2 ~-1 ~101 ~126 ~-1 ~101 dirt 0  
fill ~2 ~-1 ~102 ~126 ~-1 ~102 dirt 0  
fill ~2 ~-1 ~104 ~126 ~-1 ~104 dirt 0  
fill ~2 ~-1 ~105 ~126 ~-1 ~105 dirt 0  
fill ~2 ~-1 ~107 ~126 ~-1 ~107 dirt 0  
fill ~2 ~-1 ~108 ~126 ~-1 ~108 dirt 0  
fill ~2 ~-1 ~110 ~126 ~-1 ~110 dirt 0  
fill ~2 ~-1 ~111 ~126 ~-1 ~111 dirt 0  
fill ~2 ~-1 ~113 ~126 ~-1 ~113 dirt 0  
fill ~2 ~-1 ~114 ~126 ~-1 ~114 dirt 0  
fill ~2 ~-1 ~116 ~126 ~-1 ~116 dirt 0  
fill ~2 ~-1 ~117 ~126 ~-1 ~117 dirt 0  
fill ~2 ~-1 ~119 ~126 ~-1 ~119 dirt 0  
fill ~2 ~-1 ~120 ~126 ~-1 ~120 dirt 0  
fill ~2 ~-1 ~122 ~126 ~-1 ~122 dirt 0  
fill ~2 ~-1 ~123 ~126 ~-1 ~123 dirt 0  
fill ~2 ~-1 ~125 ~126 ~-1 ~125 dirt 0  
fill ~2 ~-1 ~126 ~126 ~-1 ~126 dirt 0  
fill ~2 ~-1 ~127 ~3 ~-1 ~127 grass 0 
setblock ~4 ~-1 ~1 dirt 0 
setblock ~4 ~-1 ~127 dirt 0  
fill ~5 ~-1 ~1 ~6 ~-1 ~1 grass 0  
fill ~5 ~-1 ~127 ~6 ~-1 ~127 grass 0 
setblock ~7 ~-1 ~1 dirt 0 
setblock ~7 ~-1 ~127 dirt 0  
fill ~8 ~-1 ~1 ~9 ~-1 ~1 grass 0  
fill ~8 ~-1 ~127 ~9 ~-1 ~127 grass 0 
setblock ~10 ~-1 ~1 dirt 0 
setblock ~10 ~-1 ~127 dirt 0  
fill ~11 ~-1 ~1 ~12 ~-1 ~1 grass 0  
fill ~11 ~-1 ~127 ~12 ~-1 ~127 grass 0 
setblock ~13 ~-1 ~1 dirt 0 
setblock ~13 ~-1 ~127 dirt 0  
fill ~14 ~-1 ~1 ~15 ~-1 ~1 grass 0  
fill ~14 ~-1 ~127 ~15 ~-1 ~127 grass 0 
setblock ~16 ~-1 ~1 dirt 0 
setblock ~16 ~-1 ~127 dirt 0  
fill ~17 ~-1 ~1 ~18 ~-1 ~1 grass 0  
fill ~17 ~-1 ~127 ~18 ~-1 ~127 grass 0 
setblock ~19 ~-1 ~1 dirt 0 
setblock ~19 ~-1 ~127 dirt 0  
fill ~20 ~-1 ~1 ~21 ~-1 ~1 grass 0  
fill ~20 ~-1 ~127 ~21 ~-1 ~127 grass 0 
setblock ~22 ~-1 ~1 dirt 0 
setblock ~22 ~-1 ~127 dirt 0  
fill ~23 ~-1 ~1 ~24 ~-1 ~1 grass 0  
fill ~23 ~-1 ~127 ~24 ~-1 ~127 grass 0 
setblock ~25 ~-1 ~1 dirt 0 
setblock ~25 ~-1 ~127 dirt 0  
fill ~26 ~-1 ~1 ~27 ~-1 ~1 grass 0  
fill ~26 ~-1 ~127 ~27 ~-1 ~127 grass 0 
setblock ~28 ~-1 ~1 dirt 0 
setblock ~28 ~-1 ~127 dirt 0  
fill ~29 ~-1 ~1 ~30 ~-1 ~1 grass 0  
fill ~29 ~-1 ~127 ~30 ~-1 ~127 grass 0 
setblock ~31 ~-1 ~1 dirt 0 
setblock ~31 ~-1 ~127 dirt 0  
fill ~32 ~-1 ~1 ~33 ~-1 ~1 grass 0  
fill ~32 ~-1 ~127 ~33 ~-1 ~127 grass 0 
setblock ~34 ~-1 ~1 dirt 0 
setblock ~34 ~-1 ~127 dirt 0  
fill ~35 ~-1 ~1 ~36 ~-1 ~1 grass 0  
fill ~35 ~-1 ~127 ~36 ~-1 ~127 grass 0 
setblock ~37 ~-1 ~1 dirt 0 
setblock ~37 ~-1 ~127 dirt 0  
fill ~38 ~-1 ~1 ~39 ~-1 ~1 grass 0  
fill ~38 ~-1 ~127 ~39 ~-1 ~127 grass 0 
setblock ~40 ~-1 ~1 dirt 0 
setblock ~40 ~-1 ~52 redstone_block 0 
setblock ~40 ~-1 ~127 dirt 0  
fill ~41 ~-1 ~1 ~42 ~-1 ~1 grass 0  
fill ~41 ~-1 ~52 ~49 ~-1 ~52 dirt 0 
setblock ~41 ~-1 ~82 redstone_block 0  
fill ~41 ~-1 ~127 ~42 ~-1 ~127 grass 0 
setblock ~42 ~-1 ~46 redstone_block 0 
setblock ~42 ~-1 ~76 redstone_block 0  
fill ~42 ~-1 ~82 ~48 ~-1 ~82 dirt 0 
setblock ~43 ~-1 ~1 dirt 0  
fill ~43 ~-1 ~46 ~78 ~-1 ~46 dirt 0  
fill ~43 ~-1 ~76 ~77 ~-1 ~76 dirt 0 
setblock ~43 ~-1 ~127 dirt 0  
fill ~44 ~-1 ~1 ~45 ~-1 ~1 grass 0  
fill ~44 ~-1 ~127 ~45 ~-1 ~127 grass 0 
setblock ~46 ~-1 ~1 dirt 0 
setblock ~46 ~-1 ~41 redstone_block 0 
setblock ~46 ~-1 ~49 redstone_block 0 
setblock ~46 ~-1 ~86 redstone_block 0 
setblock ~46 ~-1 ~127 dirt 0 
setblock ~47 ~-1 ~1 stained_hardened_clay 5  
fill ~47 ~-1 ~41 ~126 ~-1 ~41 dirt 0  
fill ~47 ~-1 ~49 ~50 ~-1 ~49 dirt 0  
fill ~47 ~-1 ~86 ~75 ~-1 ~86 dirt 0  
fill ~47 ~-1 ~127 ~48 ~-1 ~127 grass 0  
fill ~48 ~-1 ~1 ~48 ~-1 ~1 grass 0 
setblock ~49 ~-1 ~1 dirt 0 
setblock ~49 ~-1 ~77 redstone_block 0 
setblock ~49 ~-1 ~82 redstone_block 0 
setblock ~49 ~-1 ~127 dirt 0  
fill ~50 ~-1 ~1 ~51 ~-1 ~1 grass 0 
setblock ~50 ~-1 ~52 redstone_block 0  
fill ~50 ~-1 ~77 ~126 ~-1 ~77 dirt 0  
fill ~50 ~-1 ~82 ~85 ~-1 ~82 dirt 0  
fill ~50 ~-1 ~127 ~51 ~-1 ~127 grass 0 
setblock ~51 ~-1 ~49 redstone_block 0  
fill ~51 ~-1 ~52 ~85 ~-1 ~52 dirt 0 
setblock ~52 ~-1 ~1 dirt 0 
setblock ~52 ~-1 ~42 redstone_block 0  
fill ~52 ~-1 ~49 ~127 ~-1 ~49 dirt 0 
setblock ~52 ~-1 ~78 redstone_block 0 
setblock ~52 ~-1 ~88 redstone_block 0 
setblock ~52 ~-1 ~127 dirt 0  
fill ~53 ~-1 ~1 ~54 ~-1 ~1 grass 0  
fill ~53 ~-1 ~42 ~81 ~-1 ~42 dirt 0  
fill ~53 ~-1 ~78 ~126 ~-1 ~78 dirt 0  
fill ~53 ~-1 ~88 ~127 ~-1 ~88 dirt 0  
fill ~53 ~-1 ~127 ~54 ~-1 ~127 grass 0 
setblock ~55 ~-1 ~1 dirt 0 
setblock ~55 ~-1 ~127 dirt 0 
setblock ~56 ~-1 ~1 stained_hardened_clay 5  
fill ~56 ~-1 ~127 ~57 ~-1 ~127 grass 0  
fill ~57 ~-1 ~1 ~57 ~-1 ~1 grass 0 
setblock ~58 ~-1 ~1 dirt 0 
setblock ~58 ~-1 ~127 dirt 0  
fill ~59 ~-1 ~1 ~60 ~-1 ~1 grass 0  
fill ~59 ~-1 ~127 ~60 ~-1 ~127 grass 0 
setblock ~61 ~-1 ~1 dirt 0 
setblock ~61 ~-1 ~127 dirt 0  
fill ~62 ~-1 ~1 ~63 ~-1 ~1 grass 0  
fill ~62 ~-1 ~127 ~63 ~-1 ~127 grass 0 
setblock ~64 ~-1 ~1 dirt 0 
setblock ~64 ~-1 ~127 dirt 0  
fill ~65 ~-1 ~1 ~66 ~-1 ~1 grass 0  
fill ~65 ~-1 ~64 ~127 ~-1 ~64 dirt 0  
fill ~65 ~-1 ~127 ~66 ~-1 ~127 grass 0 
setblock ~67 ~-1 ~1 dirt 0 
setblock ~67 ~-1 ~127 dirt 0  
fill ~68 ~-1 ~1 ~69 ~-1 ~1 grass 0  
fill ~68 ~-1 ~127 ~69 ~-1 ~127 grass 0 
setblock ~70 ~-1 ~1 dirt 0 
setblock ~70 ~-1 ~127 dirt 0  
fill ~71 ~-1 ~1 ~72 ~-1 ~1 grass 0 
setblock ~71 ~-1 ~127 grass 0 
setblock ~72 ~-1 ~127 stained_hardened_clay 5 
setblock ~73 ~-1 ~1 dirt 0 
setblock ~73 ~-1 ~127 dirt 0  
fill ~74 ~-1 ~1 ~75 ~-1 ~1 grass 0  
fill ~74 ~-1 ~127 ~75 ~-1 ~127 grass 0 
setblock ~76 ~-1 ~1 dirt 0 
setblock ~76 ~-1 ~40 redstone_block 0 
setblock ~76 ~-1 ~50 redstone_block 0 
setblock ~76 ~-1 ~86 redstone_block 0 
setblock ~76 ~-1 ~127 dirt 0  
fill ~77 ~-1 ~1 ~78 ~-1 ~1 grass 0  
fill ~77 ~-1 ~40 ~127 ~-1 ~40 dirt 0  
fill ~77 ~-1 ~50 ~126 ~-1 ~50 dirt 0 
setblock ~77 ~-1 ~79 redstone_block 0  
fill ~77 ~-1 ~86 ~126 ~-1 ~86 dirt 0  
fill ~77 ~-1 ~127 ~78 ~-1 ~127 grass 0  
fill ~78 ~-1 ~76 ~78 ~-2 ~76 redstone_block 0  
fill ~78 ~-1 ~79 ~81 ~-1 ~79 dirt 0 
setblock ~79 ~-1 ~1 dirt 0 
setblock ~79 ~-1 ~46 redstone_block 0 
setblock ~79 ~-1 ~51 redstone_block 0  
fill ~79 ~-1 ~76 ~87 ~-1 ~76 dirt 0 
setblock ~79 ~-1 ~127 dirt 0  
fill ~80 ~-1 ~1 ~81 ~-1 ~1 grass 0  
fill ~80 ~-1 ~46 ~86 ~-1 ~46 dirt 0  
fill ~80 ~-1 ~51 ~126 ~-1 ~51 dirt 0  
fill ~80 ~-1 ~127 ~80 ~-1 ~127 grass 0 
setblock ~81 ~-1 ~127 stained_hardened_clay 5 
setblock ~82 ~-1 ~1 dirt 0 
setblock ~82 ~-1 ~42 redstone_block 0 
setblock ~82 ~-1 ~79 redstone_block 0 
setblock ~82 ~-1 ~87 redstone_block 0 
setblock ~82 ~-1 ~127 dirt 0  
fill ~83 ~-1 ~1 ~84 ~-1 ~1 grass 0  
fill ~83 ~-1 ~42 ~126 ~-1 ~42 dirt 0  
fill ~83 ~-1 ~79 ~127 ~-1 ~79 dirt 0  
fill ~83 ~-1 ~87 ~126 ~-1 ~87 dirt 0   
fill ~83 ~-1 ~127 ~84 ~-1 ~127 grass 0 
setblock ~85 ~-1 ~1 dirt 0 
setblock ~85 ~-1 ~127 dirt 0  
fill ~86 ~-1 ~1 ~87 ~-1 ~1 grass 0 
setblock ~86 ~-1 ~52 redstone_block 0 
setblock ~86 ~-1 ~82 redstone_block 0  
fill ~86 ~-1 ~127 ~87 ~-1 ~127 grass 0 
setblock ~87 ~-1 ~46 redstone_block 0  
fill ~87 ~-1 ~52 ~127 ~-1 ~52 dirt 0  
fill ~87 ~-1 ~82 ~127 ~-1 ~82 dirt 0 
setblock ~88 ~-1 ~1 dirt 0  
fill ~88 ~-1 ~46 ~127 ~-1 ~46 dirt 0 
setblock ~88 ~-1 ~76 redstone_block 0 
setblock ~88 ~-1 ~127 dirt 0  
fill ~89 ~-1 ~1 ~90 ~-1 ~1 grass 0  
fill ~89 ~-1 ~76 ~127 ~-1 ~76 dirt 0  
fill ~89 ~-1 ~127 ~90 ~-1 ~127 grass 0 
setblock ~91 ~-1 ~1 dirt 0 
setblock ~91 ~-1 ~127 dirt 0  
fill ~92 ~-1 ~1 ~93 ~-1 ~1 grass 0  
fill ~92 ~-1 ~127 ~93 ~-1 ~127 grass 0 
setblock ~94 ~-1 ~1 dirt 0 
setblock ~94 ~-1 ~127 dirt 0  
fill ~95 ~-1 ~1 ~96 ~-1 ~1 grass 0  
fill ~95 ~-1 ~127 ~96 ~-1 ~127 grass 0 
setblock ~97 ~-1 ~1 dirt 0 
setblock ~97 ~-1 ~127 dirt 0  
fill ~98 ~-1 ~1 ~99 ~-1 ~1 grass 0  
fill ~98 ~-1 ~127 ~99 ~-1 ~127 grass 0 
setblock ~100 ~-1 ~1 dirt 0 
setblock ~100 ~-1 ~127 dirt 0  
fill ~101 ~-1 ~1 ~102 ~-1 ~1 grass 0  
fill ~101 ~-1 ~127 ~102 ~-1 ~127 grass 0 
setblock ~103 ~-1 ~1 dirt 0 
setblock ~103 ~-1 ~127 dirt 0  
fill ~104 ~-1 ~1 ~105 ~-1 ~1 grass 0  
fill ~104 ~-1 ~127 ~105 ~-1 ~127 grass 0 
setblock ~106 ~-1 ~1 dirt 0 
setblock ~106 ~-1 ~127 dirt 0  
fill ~107 ~-1 ~1 ~108 ~-1 ~1 grass 0  
fill ~107 ~-1 ~127 ~108 ~-1 ~127 grass 0 
setblock ~109 ~-1 ~1 dirt 0 
setblock ~109 ~-1 ~127 dirt 0  
fill ~110 ~-1 ~1 ~111 ~-1 ~1 grass 0  
fill ~110 ~-1 ~127 ~111 ~-1 ~127 grass 0 
setblock ~112 ~-1 ~1 dirt 0  
fill ~112 ~-1 ~127 ~112 ~-2 ~127 dirt 0  
fill ~113 ~-1 ~1 ~114 ~-1 ~1 grass 0  
fill ~113 ~-1 ~127 ~114 ~-1 ~127 grass 0 
setblock ~115 ~-1 ~1 dirt 0 
setblock ~115 ~-1 ~127 dirt 0  
fill ~116 ~-1 ~1 ~117 ~-1 ~1 grass 0  
fill ~116 ~-1 ~127 ~117 ~-1 ~127 grass 0 
setblock ~118 ~-1 ~1 dirt 0 
setblock ~118 ~-1 ~127 dirt 0  
fill ~119 ~-1 ~1 ~120 ~-1 ~1 grass 0  
fill ~119 ~-1 ~127 ~120 ~-1 ~127 grass 0  
fill ~121 ~-1 ~1 ~121 ~-2 ~1 dirt 0 
setblock ~121 ~-1 ~127 dirt 0  
fill ~122 ~-1 ~1 ~123 ~-1 ~1 grass 0  
fill ~122 ~-1 ~127 ~123 ~-1 ~127 grass 0 
setblock ~124 ~-1 ~1 dirt 0 
setblock ~124 ~-1 ~127 dirt 0  
fill ~125 ~-1 ~1 ~126 ~-1 ~1 grass 0  
fill ~125 ~-1 ~127 ~126 ~-1 ~127 grass 0 
setblock ~127 ~-1 ~1 dirt 0  
fill ~127 ~-1 ~2 ~127 ~-1 ~2 grass 0  
fill ~127 ~-1 ~3 ~127 ~-1 ~3 grass 0  
fill ~127 ~-1 ~5 ~127 ~-1 ~5 grass 0  
fill ~127 ~-1 ~6 ~127 ~-1 ~6 grass 0  
fill ~127 ~-1 ~8 ~127 ~-1 ~8 grass 0  
fill ~127 ~-1 ~9 ~127 ~-1 ~9 grass 0  
fill ~127 ~-1 ~11 ~127 ~-1 ~11 grass 0 
setblock ~127 ~-1 ~12 grass 0  
fill ~127 ~-1 ~14 ~127 ~-1 ~15 grass 0  
fill ~127 ~-1 ~17 ~127 ~-1 ~18 grass 0  
fill ~127 ~-1 ~20 ~127 ~-1 ~21 grass 0  
fill ~127 ~-1 ~23 ~127 ~-1 ~23 grass 0  
fill ~127 ~-1 ~24 ~127 ~-1 ~24 grass 0  
fill ~127 ~-1 ~26 ~127 ~-1 ~26 grass 0  
fill ~127 ~-1 ~27 ~127 ~-1 ~27 grass 0  
fill ~127 ~-1 ~29 ~127 ~-1 ~29 grass 0  
fill ~127 ~-1 ~30 ~127 ~-1 ~30 grass 0  
fill ~127 ~-1 ~32 ~127 ~-1 ~32 grass 0  
fill ~127 ~-1 ~33 ~127 ~-1 ~33 grass 0  
fill ~127 ~-1 ~35 ~127 ~-1 ~35 grass 0  
fill ~127 ~-1 ~36 ~127 ~-1 ~36 grass 0  
fill ~127 ~-1 ~38 ~127 ~-1 ~39 grass 0  
fill ~127 ~-1 ~41 ~127 ~-1 ~42 grass 0  
fill ~127 ~-1 ~44 ~127 ~-1 ~45 grass 0 
setblock ~127 ~-1 ~47 stained_hardened_clay 5  
fill ~127 ~-1 ~48 ~127 ~-1 ~48 grass 0  
fill ~127 ~-1 ~50 ~127 ~-1 ~50 grass 0  
fill ~127 ~-1 ~51 ~127 ~-1 ~51 grass 0  
fill ~127 ~-1 ~53 ~127 ~-1 ~53 grass 0  
fill ~127 ~-1 ~54 ~127 ~-1 ~54 grass 0 
setblock ~127 ~-1 ~56 stained_hardened_clay 5  
fill ~127 ~-1 ~57 ~127 ~-1 ~57 grass 0  
fill ~127 ~-1 ~59 ~127 ~-1 ~59 grass 0  
fill ~127 ~-1 ~60 ~127 ~-1 ~60 grass 0  
fill ~127 ~-1 ~62 ~127 ~-1 ~62 grass 0  
fill ~127 ~-1 ~63 ~127 ~-1 ~63 grass 0  
fill ~127 ~-1 ~65 ~127 ~-1 ~65 grass 0  
fill ~127 ~-1 ~66 ~127 ~-1 ~66 grass 0  
fill ~127 ~-1 ~68 ~127 ~-1 ~68 grass 0  
fill ~127 ~-1 ~69 ~127 ~-1 ~69 grass 0  
fill ~127 ~-1 ~71 ~127 ~-1 ~71 grass 0  
fill ~127 ~-1 ~72 ~127 ~-1 ~72 grass 0  
fill ~127 ~-1 ~74 ~127 ~-1 ~74 grass 0  
fill ~127 ~-1 ~75 ~127 ~-1 ~75 grass 0  
fill ~127 ~-1 ~77 ~127 ~-1 ~77 grass 0  
fill ~127 ~-1 ~78 ~127 ~-1 ~78 grass 0  
fill ~127 ~-1 ~80 ~127 ~-1 ~80 grass 0  
fill ~127 ~-1 ~81 ~127 ~-1 ~81 grass 0  
fill ~127 ~-1 ~83 ~127 ~-1 ~83 grass 0  
fill ~127 ~-1 ~84 ~127 ~-1 ~84 grass 0  
fill ~127 ~-1 ~86 ~127 ~-1 ~86 grass 0  
fill ~127 ~-1 ~87 ~127 ~-1 ~87 grass 0  
fill ~127 ~-1 ~89 ~127 ~-1 ~89 grass 0  
fill ~127 ~-1 ~90 ~127 ~-1 ~90 grass 0  
fill ~127 ~-1 ~92 ~127 ~-1 ~92 grass 0  
fill ~127 ~-1 ~93 ~127 ~-1 ~93 grass 0  
fill ~127 ~-1 ~95 ~127 ~-1 ~95 grass 0  
fill ~127 ~-1 ~96 ~127 ~-1 ~96 grass 0  
fill ~127 ~-1 ~98 ~127 ~-1 ~98 grass 0  
fill ~127 ~-1 ~99 ~127 ~-1 ~99 grass 0  
fill ~127 ~-1 ~101 ~127 ~-1 ~101 grass 0  
fill ~127 ~-1 ~102 ~127 ~-1 ~102 grass 0  
fill ~127 ~-1 ~104 ~127 ~-1 ~104 grass 0  
fill ~127 ~-1 ~105 ~127 ~-1 ~105 grass 0  
fill ~127 ~-1 ~107 ~127 ~-1 ~108 grass 0  
fill ~127 ~-1 ~110 ~127 ~-1 ~111 grass 0  
fill ~127 ~-1 ~113 ~127 ~-1 ~114 grass 0  
fill ~127 ~-1 ~116 ~127 ~-1 ~117 grass 0  
fill ~127 ~-1 ~119 ~127 ~-1 ~119 grass 0  
fill ~127 ~-1 ~120 ~127 ~-1 ~120 grass 0  
fill ~127 ~-1 ~122 ~127 ~-1 ~122 grass 0  
fill ~127 ~-1 ~123 ~127 ~-1 ~123 grass 0  
fill ~127 ~-1 ~125 ~127 ~-1 ~125 grass 0  
fill ~127 ~-1 ~126 ~127 ~-1 ~126 grass 0 
setblock ~127 ~-1 ~127 dirt 0  
fill ~1 ~0 ~1 ~1 ~4 ~1 log 12  
fill ~1 ~0 ~2 ~1 ~0 ~3 stone_slab 5  
fill ~1 ~0 ~4 ~1 ~4 ~4 log 12 
setblock ~1 ~0 ~5 stone_stairs 0 
setblock ~1 ~0 ~6 stone_slab 5 
setblock ~1 ~0 ~7 stonebrick 3 
setblock ~1 ~0 ~8 stone_slab 5 
setblock ~1 ~0 ~9 stone_stairs 0  
fill ~1 ~0 ~10 ~1 ~4 ~10 log 12 
setblock ~1 ~0 ~11 stone_stairs 0 
setblock ~1 ~0 ~12 stone_slab 5 
setblock ~1 ~0 ~13 stonebrick 3 
setblock ~1 ~0 ~14 stone_slab 5 
setblock ~1 ~0 ~15 stone_stairs 0  
fill ~1 ~0 ~16 ~1 ~4 ~16 log 12 
setblock ~1 ~0 ~17 stone_stairs 0 
setblock ~1 ~0 ~18 stone_slab 5 
setblock ~1 ~0 ~19 stonebrick 3 
setblock ~1 ~0 ~20 stone_slab 5 
setblock ~1 ~0 ~21 stone_stairs 0  
fill ~1 ~0 ~22 ~1 ~4 ~22 log 12 
setblock ~1 ~0 ~23 stone_stairs 0 
setblock ~1 ~0 ~24 stone_slab 5 
setblock ~1 ~0 ~25 stonebrick 3 
setblock ~1 ~0 ~26 stone_slab 5 
setblock ~1 ~0 ~27 stone_stairs 0  
fill ~1 ~0 ~28 ~1 ~4 ~28 log 12 
setblock ~1 ~0 ~29 stone_stairs 0 
setblock ~1 ~0 ~30 stone_slab 5 
setblock ~1 ~0 ~31 stonebrick 3 
setblock ~1 ~0 ~32 stone_slab 5 
setblock ~1 ~0 ~33 stone_stairs 0  
fill ~1 ~0 ~34 ~1 ~4 ~34 log 12 
setblock ~1 ~0 ~35 stone_stairs 0 
setblock ~1 ~0 ~36 stone_slab 5 
setblock ~1 ~0 ~37 stonebrick 3 
setblock ~1 ~0 ~38 stone_slab 5 
setblock ~1 ~0 ~39 stone_stairs 0  
fill ~1 ~0 ~40 ~1 ~4 ~40 log 12 
setblock ~1 ~0 ~41 stone_stairs 0 
setblock ~1 ~0 ~42 stone_slab 5 
setblock ~1 ~0 ~43 stonebrick 3 
setblock ~1 ~0 ~44 stone_slab 5 
setblock ~1 ~0 ~45 stone_stairs 0  
fill ~1 ~0 ~46 ~1 ~4 ~46 log 12 
setblock ~1 ~0 ~47 stone_stairs 0 
setblock ~1 ~0 ~48 stone_slab 5 
setblock ~1 ~0 ~49 stonebrick 3 
setblock ~1 ~0 ~50 stone_slab 5 
setblock ~1 ~0 ~51 stone_stairs 0  
fill ~1 ~0 ~52 ~1 ~4 ~52 log 12 
setblock ~1 ~0 ~53 stone_stairs 0 
setblock ~1 ~0 ~54 stone_slab 5 
setblock ~1 ~0 ~55 stonebrick 3 
setblock ~1 ~0 ~56 stone_slab 5 
setblock ~1 ~0 ~57 stone_stairs 0  
fill ~1 ~0 ~58 ~1 ~4 ~58 log 12 
setblock ~1 ~0 ~59 stone_stairs 0 
setblock ~1 ~0 ~60 stone_slab 5 
setblock ~1 ~0 ~61 stonebrick 3 
setblock ~1 ~0 ~62 stone_slab 5 
setblock ~1 ~0 ~63 stone_stairs 0  
fill ~1 ~0 ~64 ~1 ~4 ~64 log 12 
setblock ~1 ~0 ~65 stone_stairs 0 
setblock ~1 ~0 ~66 stone_slab 5 
setblock ~1 ~0 ~67 stonebrick 3 
setblock ~1 ~0 ~68 stone_slab 5 
setblock ~1 ~0 ~69 stone_stairs 0  
fill ~1 ~0 ~70 ~1 ~4 ~70 log 12 
setblock ~1 ~0 ~71 stone_stairs 0 
setblock ~1 ~0 ~72 stone_slab 5 
setblock ~1 ~0 ~73 stonebrick 3 
setblock ~1 ~0 ~74 stone_slab 5 
setblock ~1 ~0 ~75 stone_stairs 0  
fill ~1 ~0 ~76 ~1 ~4 ~76 log 12 
setblock ~1 ~0 ~77 stone_stairs 0 
setblock ~1 ~0 ~78 stone_slab 5 
setblock ~1 ~0 ~79 stonebrick 3 
setblock ~1 ~0 ~80 stone_slab 5 
setblock ~1 ~0 ~81 stone_stairs 0  
fill ~1 ~0 ~82 ~1 ~4 ~82 log 12 
setblock ~1 ~0 ~83 stone_stairs 0 
setblock ~1 ~0 ~84 stone_slab 5 
setblock ~1 ~0 ~85 stonebrick 3 
setblock ~1 ~0 ~86 stone_slab 5 
setblock ~1 ~0 ~87 stone_stairs 0  
fill ~1 ~0 ~88 ~1 ~4 ~88 log 12 
setblock ~1 ~0 ~89 stone_stairs 0 
setblock ~1 ~0 ~90 stone_slab 5 
setblock ~1 ~0 ~91 stonebrick 3 
setblock ~1 ~0 ~92 stone_slab 5 
setblock ~1 ~0 ~93 stone_stairs 0  
fill ~1 ~0 ~94 ~1 ~4 ~94 log 12 
setblock ~1 ~0 ~95 stone_stairs 0 
setblock ~1 ~0 ~96 stone_slab 5 
setblock ~1 ~0 ~97 stonebrick 3 
setblock ~1 ~0 ~98 stone_slab 5 
setblock ~1 ~0 ~99 stone_stairs 0  
fill ~1 ~0 ~100 ~1 ~4 ~100 log 12 
setblock ~1 ~0 ~101 stone_stairs 0 
setblock ~1 ~0 ~102 stone_slab 5 
setblock ~1 ~0 ~103 stonebrick 3 
setblock ~1 ~0 ~104 stone_slab 5 
setblock ~1 ~0 ~105 stone_stairs 0  
fill ~1 ~0 ~106 ~1 ~4 ~106 log 12 
setblock ~1 ~0 ~107 stone_stairs 0 
setblock ~1 ~0 ~108 stone_slab 5 
setblock ~1 ~0 ~109 stonebrick 3 
setblock ~1 ~0 ~110 stone_slab 5 
setblock ~1 ~0 ~111 stone_stairs 0  
fill ~1 ~0 ~112 ~1 ~4 ~112 log 12 
setblock ~1 ~0 ~113 stone_stairs 0 
setblock ~1 ~0 ~114 stone_slab 5 
setblock ~1 ~0 ~115 stonebrick 3 
setblock ~1 ~0 ~116 stone_slab 5 
setblock ~1 ~0 ~117 stone_stairs 0  
fill ~1 ~0 ~118 ~1 ~4 ~118 log 12 
setblock ~1 ~0 ~119 stone_stairs 0 
setblock ~1 ~0 ~120 stone_slab 5 
setblock ~1 ~0 ~121 stonebrick 3 
setblock ~1 ~0 ~122 stone_slab 5 
setblock ~1 ~0 ~123 stone_stairs 0  
fill ~1 ~0 ~124 ~1 ~4 ~124 log 12  
fill ~1 ~0 ~125 ~1 ~0 ~126 stone_slab 5  
fill ~1 ~0 ~127 ~1 ~4 ~127 log 12  
fill ~2 ~0 ~1 ~3 ~0 ~1 stone_slab 5  
fill ~2 ~0 ~2 ~3 ~0 ~2 stained_hardened_clay 13  
fill ~2 ~0 ~3 ~2 ~0 ~4 stained_hardened_clay 13 
setblock ~2 ~0 ~5 stained_hardened_clay 5  
fill ~2 ~0 ~6 ~2 ~0 ~8 stonebrick 0 
setblock ~2 ~0 ~9 stained_hardened_clay 5  
fill ~2 ~0 ~10 ~2 ~2 ~10 stained_hardened_clay 13 
setblock ~2 ~0 ~11 stained_hardened_clay 5  
fill ~2 ~0 ~12 ~2 ~0 ~14 stonebrick 0 
setblock ~2 ~0 ~15 stained_hardened_clay 5  
fill ~2 ~0 ~16 ~2 ~2 ~16 stained_hardened_clay 13 
setblock ~2 ~0 ~17 stained_hardened_clay 5  
fill ~2 ~0 ~18 ~2 ~0 ~20 stonebrick 0 
setblock ~2 ~0 ~21 stained_hardened_clay 5  
fill ~2 ~0 ~22 ~2 ~2 ~22 stained_hardened_clay 13 
setblock ~2 ~0 ~23 stained_hardened_clay 5  
fill ~2 ~0 ~24 ~2 ~0 ~26 stonebrick 0 
setblock ~2 ~0 ~27 stained_hardened_clay 5  
fill ~2 ~0 ~28 ~2 ~2 ~28 stained_hardened_clay 13 
setblock ~2 ~0 ~29 stained_hardened_clay 5  
fill ~2 ~0 ~30 ~2 ~0 ~32 stonebrick 0 
setblock ~2 ~0 ~33 stained_hardened_clay 5  
fill ~2 ~0 ~34 ~2 ~2 ~34 stained_hardened_clay 13 
setblock ~2 ~0 ~35 stained_hardened_clay 5  
fill ~2 ~0 ~36 ~2 ~0 ~38 stonebrick 0 
setblock ~2 ~0 ~39 stained_hardened_clay 5  
fill ~2 ~0 ~40 ~2 ~2 ~40 stained_hardened_clay 13 
setblock ~2 ~0 ~41 stained_hardened_clay 5  
fill ~2 ~0 ~42 ~2 ~0 ~44 stonebrick 0 
setblock ~2 ~0 ~45 stained_hardened_clay 5  
fill ~2 ~0 ~46 ~2 ~2 ~46 stained_hardened_clay 13 
setblock ~2 ~0 ~47 stained_hardened_clay 5  
fill ~2 ~0 ~48 ~2 ~0 ~50 stonebrick 0 
setblock ~2 ~0 ~51 stained_hardened_clay 5  
fill ~2 ~0 ~52 ~2 ~2 ~52 stained_hardened_clay 13 
setblock ~2 ~0 ~53 stained_hardened_clay 5  
fill ~2 ~0 ~54 ~2 ~0 ~56 stonebrick 0 
setblock ~2 ~0 ~57 stained_hardened_clay 5  
fill ~2 ~0 ~58 ~2 ~2 ~58 stained_hardened_clay 13 
setblock ~2 ~0 ~59 stained_hardened_clay 5  
fill ~2 ~0 ~60 ~2 ~0 ~62 stonebrick 0 
setblock ~2 ~0 ~63 stained_hardened_clay 5  
fill ~2 ~0 ~64 ~2 ~2 ~64 stained_hardened_clay 13 
setblock ~2 ~0 ~65 stained_hardened_clay 5  
fill ~2 ~0 ~66 ~2 ~0 ~68 stonebrick 0 
setblock ~2 ~0 ~69 stained_hardened_clay 5  
fill ~2 ~0 ~70 ~2 ~2 ~70 stained_hardened_clay 13 
setblock ~2 ~0 ~71 stained_hardened_clay 5  
fill ~2 ~0 ~72 ~2 ~0 ~74 stonebrick 0 
setblock ~2 ~0 ~75 stained_hardened_clay 5  
fill ~2 ~0 ~76 ~2 ~2 ~76 stained_hardened_clay 13 
setblock ~2 ~0 ~77 stained_hardened_clay 5  
fill ~2 ~0 ~78 ~2 ~0 ~80 stonebrick 0 
setblock ~2 ~0 ~81 stained_hardened_clay 5  
fill ~2 ~0 ~82 ~2 ~2 ~82 stained_hardened_clay 13 
setblock ~2 ~0 ~83 stained_hardened_clay 5  
fill ~2 ~0 ~84 ~2 ~0 ~86 stonebrick 0 
setblock ~2 ~0 ~87 stained_hardened_clay 5  
fill ~2 ~0 ~88 ~2 ~2 ~88 stained_hardened_clay 13 
setblock ~2 ~0 ~89 stained_hardened_clay 5  
fill ~2 ~0 ~90 ~2 ~0 ~92 stonebrick 0 
setblock ~2 ~0 ~93 stained_hardened_clay 5  
fill ~2 ~0 ~94 ~2 ~2 ~94 stained_hardened_clay 13 
setblock ~2 ~0 ~95 stained_hardened_clay 5  
fill ~2 ~0 ~96 ~2 ~0 ~98 stonebrick 0 
setblock ~2 ~0 ~99 stained_hardened_clay 5  
fill ~2 ~0 ~100 ~2 ~2 ~100 stained_hardened_clay 13 
setblock ~2 ~0 ~101 stained_hardened_clay 5  
fill ~2 ~0 ~102 ~2 ~0 ~104 stonebrick 0 
setblock ~2 ~0 ~105 stained_hardened_clay 5  
fill ~2 ~0 ~106 ~2 ~2 ~106 stained_hardened_clay 13 
setblock ~2 ~0 ~107 stained_hardened_clay 5  
fill ~2 ~0 ~108 ~2 ~0 ~110 stonebrick 0 
setblock ~2 ~0 ~111 stained_hardened_clay 5  
fill ~2 ~0 ~112 ~2 ~2 ~112 stained_hardened_clay 13 
setblock ~2 ~0 ~113 stained_hardened_clay 5  
fill ~2 ~0 ~114 ~2 ~0 ~116 stonebrick 0 
setblock ~2 ~0 ~117 stained_hardened_clay 5  
fill ~2 ~0 ~118 ~2 ~2 ~118 stained_hardened_clay 13 
setblock ~2 ~0 ~119 stained_hardened_clay 5  
fill ~2 ~0 ~120 ~2 ~0 ~122 stonebrick 0 
setblock ~2 ~0 ~123 stained_hardened_clay 5  
fill ~2 ~0 ~124 ~125 ~0 ~124 stonebrick 0  
fill ~2 ~0 ~125 ~2 ~0 ~126 stained_hardened_clay 13  
fill ~2 ~0 ~127 ~3 ~0 ~127 stone_slab 5  
fill ~3 ~0 ~3 ~5 ~0 ~3 stonebrick 0  
fill ~3 ~0 ~4 ~126 ~0 ~4 stonebrick 0  
fill ~3 ~0 ~5 ~125 ~0 ~5 stonebrick 0 
setblock ~3 ~0 ~6 stained_hardened_clay 13  
fill ~3 ~0 ~7 ~3 ~4 ~7 log 12 
setblock ~3 ~0 ~8 stained_hardened_clay 13  
fill ~3 ~0 ~9 ~125 ~0 ~9 stonebrick 0  
fill ~3 ~0 ~10 ~125 ~0 ~10 stonebrick 0  
fill ~3 ~0 ~11 ~125 ~0 ~11 stonebrick 0 
setblock ~3 ~0 ~12 stained_hardened_clay 13  
fill ~3 ~0 ~13 ~3 ~4 ~13 log 12 
setblock ~3 ~0 ~14 stained_hardened_clay 13  
fill ~3 ~0 ~15 ~125 ~0 ~15 stonebrick 0  
fill ~3 ~0 ~16 ~125 ~0 ~16 stonebrick 0  
fill ~3 ~0 ~17 ~125 ~0 ~17 stonebrick 0 
setblock ~3 ~0 ~18 stained_hardened_clay 13  
fill ~3 ~0 ~19 ~3 ~4 ~19 log 12 
setblock ~3 ~0 ~20 stained_hardened_clay 13  
fill ~3 ~0 ~21 ~125 ~0 ~21 stonebrick 0  
fill ~3 ~0 ~22 ~125 ~0 ~22 stonebrick 0  
fill ~3 ~0 ~23 ~125 ~0 ~23 stonebrick 0 
setblock ~3 ~0 ~24 stained_hardened_clay 13  
fill ~3 ~0 ~25 ~3 ~4 ~25 log 12 
setblock ~3 ~0 ~26 stained_hardened_clay 13  
fill ~3 ~0 ~27 ~125 ~0 ~27 stonebrick 0  
fill ~3 ~0 ~28 ~125 ~0 ~28 stonebrick 0  
fill ~3 ~0 ~29 ~125 ~0 ~29 stonebrick 0 
setblock ~3 ~0 ~30 stained_hardened_clay 13  
fill ~3 ~0 ~31 ~3 ~4 ~31 log 12 
setblock ~3 ~0 ~32 stained_hardened_clay 13  
fill ~3 ~0 ~33 ~63 ~0 ~33 stonebrick 0  
fill ~3 ~0 ~34 ~125 ~0 ~34 stonebrick 0  
fill ~3 ~0 ~35 ~125 ~0 ~35 stonebrick 0 
setblock ~3 ~0 ~36 stained_hardened_clay 13  
fill ~3 ~0 ~37 ~3 ~4 ~37 log 12 
setblock ~3 ~0 ~38 stained_hardened_clay 13  
fill ~3 ~0 ~39 ~56 ~0 ~39 stonebrick 0  
fill ~3 ~0 ~40 ~75 ~0 ~40 stonebrick 0  
fill ~3 ~0 ~41 ~45 ~0 ~41 stonebrick 0 
setblock ~3 ~0 ~42 stained_hardened_clay 13  
fill ~3 ~0 ~43 ~3 ~4 ~43 log 12 
setblock ~3 ~0 ~44 stained_hardened_clay 13  
fill ~3 ~0 ~45 ~36 ~0 ~45 stonebrick 0  
fill ~3 ~0 ~46 ~41 ~0 ~46 stonebrick 0  
fill ~3 ~0 ~47 ~56 ~0 ~47 stonebrick 0 
setblock ~3 ~0 ~48 stained_hardened_clay 13  
fill ~3 ~0 ~49 ~3 ~4 ~49 log 12 
setblock ~3 ~0 ~50 stained_hardened_clay 13  
fill ~3 ~0 ~51 ~35 ~0 ~51 stonebrick 0  
fill ~3 ~0 ~52 ~39 ~0 ~52 stonebrick 0  
fill ~3 ~0 ~53 ~52 ~0 ~53 stonebrick 0 
setblock ~3 ~0 ~54 stained_hardened_clay 13  
fill ~3 ~0 ~55 ~3 ~4 ~55 log 12 
setblock ~3 ~0 ~56 stained_hardened_clay 13  
fill ~3 ~0 ~57 ~38 ~0 ~57 stonebrick 0  
fill ~3 ~0 ~58 ~125 ~0 ~58 stonebrick 0  
fill ~3 ~0 ~59 ~125 ~0 ~59 stonebrick 0 
setblock ~3 ~0 ~60 stained_hardened_clay 13  
fill ~3 ~0 ~61 ~3 ~4 ~61 log 12 
setblock ~3 ~0 ~62 stained_hardened_clay 13  
fill ~3 ~0 ~63 ~125 ~0 ~63 stonebrick 0  
fill ~3 ~0 ~64 ~32 ~0 ~64 stonebrick 0  
fill ~3 ~0 ~65 ~125 ~0 ~65 stonebrick 0 
setblock ~3 ~0 ~66 stained_hardened_clay 13  
fill ~3 ~0 ~67 ~3 ~4 ~67 log 12 
setblock ~3 ~0 ~68 stained_hardened_clay 13  
fill ~3 ~0 ~69 ~125 ~0 ~69 stonebrick 0  
fill ~3 ~0 ~70 ~125 ~0 ~70 stonebrick 0  
fill ~3 ~0 ~71 ~38 ~0 ~71 stonebrick 0 
setblock ~3 ~0 ~72 stained_hardened_clay 13  
fill ~3 ~0 ~73 ~3 ~4 ~73 log 12 
setblock ~3 ~0 ~74 stained_hardened_clay 13  
fill ~3 ~0 ~75 ~52 ~0 ~75 stonebrick 0  
fill ~3 ~0 ~76 ~41 ~0 ~76 stonebrick 0  
fill ~3 ~0 ~77 ~35 ~0 ~77 stonebrick 0 
setblock ~3 ~0 ~78 stained_hardened_clay 13  
fill ~3 ~0 ~79 ~3 ~4 ~79 log 12 
setblock ~3 ~0 ~80 stained_hardened_clay 13  
fill ~3 ~0 ~81 ~56 ~0 ~81 stonebrick 0  
fill ~3 ~0 ~82 ~40 ~0 ~82 stonebrick 0  
fill ~3 ~0 ~83 ~36 ~0 ~83 stonebrick 0 
setblock ~3 ~0 ~84 stained_hardened_clay 13  
fill ~3 ~0 ~85 ~3 ~4 ~85 log 12 
setblock ~3 ~0 ~86 stained_hardened_clay 13  
fill ~3 ~0 ~87 ~81 ~0 ~87 stonebrick 0  
fill ~3 ~0 ~88 ~51 ~0 ~88 stonebrick 0  
fill ~3 ~0 ~89 ~56 ~0 ~89 stonebrick 0 
setblock ~3 ~0 ~90 stained_hardened_clay 13  
fill ~3 ~0 ~91 ~3 ~4 ~91 log 12 
setblock ~3 ~0 ~92 stained_hardened_clay 13  
fill ~3 ~0 ~93 ~125 ~0 ~93 stonebrick 0  
fill ~3 ~0 ~94 ~125 ~0 ~94 stonebrick 0  
fill ~3 ~0 ~95 ~63 ~0 ~95 stonebrick 0 
setblock ~3 ~0 ~96 stained_hardened_clay 13  
fill ~3 ~0 ~97 ~3 ~4 ~97 log 12 
setblock ~3 ~0 ~98 stained_hardened_clay 13  
fill ~3 ~0 ~99 ~125 ~0 ~99 stonebrick 0  
fill ~3 ~0 ~100 ~125 ~0 ~100 stonebrick 0  
fill ~3 ~0 ~101 ~125 ~0 ~101 stonebrick 0 
setblock ~3 ~0 ~102 stained_hardened_clay 13  
fill ~3 ~0 ~103 ~3 ~4 ~103 log 12 
setblock ~3 ~0 ~104 stained_hardened_clay 13  
fill ~3 ~0 ~105 ~125 ~0 ~105 stonebrick 0  
fill ~3 ~0 ~106 ~125 ~0 ~106 stonebrick 0  
fill ~3 ~0 ~107 ~125 ~0 ~107 stonebrick 0 
setblock ~3 ~0 ~108 stained_hardened_clay 13  
fill ~3 ~0 ~109 ~3 ~4 ~109 log 12 
setblock ~3 ~0 ~110 stained_hardened_clay 13  
fill ~3 ~0 ~111 ~125 ~0 ~111 stonebrick 0  
fill ~3 ~0 ~112 ~125 ~0 ~112 stonebrick 0  
fill ~3 ~0 ~113 ~125 ~0 ~113 stonebrick 0 
setblock ~3 ~0 ~114 stained_hardened_clay 13  
fill ~3 ~0 ~115 ~3 ~4 ~115 log 12 
setblock ~3 ~0 ~116 stained_hardened_clay 13  
fill ~3 ~0 ~117 ~125 ~0 ~117 stonebrick 0  
fill ~3 ~0 ~118 ~125 ~0 ~118 stonebrick 0  
fill ~3 ~0 ~119 ~125 ~0 ~119 stonebrick 0 
setblock ~3 ~0 ~120 stained_hardened_clay 13  
fill ~3 ~0 ~121 ~3 ~4 ~121 log 12 
setblock ~3 ~0 ~122 stained_hardened_clay 13  
fill ~3 ~0 ~123 ~125 ~0 ~123 stonebrick 0  
fill ~3 ~0 ~125 ~5 ~0 ~125 stonebrick 0  
fill ~3 ~0 ~126 ~4 ~0 ~126 stained_hardened_clay 13  
fill ~4 ~0 ~1 ~4 ~4 ~1 log 12  
fill ~4 ~0 ~2 ~4 ~2 ~2 stonebrick 0  
fill ~4 ~0 ~6 ~124 ~0 ~6 stonebrick 0  
fill ~4 ~0 ~7 ~124 ~0 ~7 stonebrick 0  
fill ~4 ~0 ~8 ~124 ~0 ~8 stonebrick 0  
fill ~4 ~0 ~12 ~124 ~0 ~12 stonebrick 0  
fill ~4 ~0 ~13 ~124 ~0 ~13 stonebrick 0  
fill ~4 ~0 ~14 ~124 ~0 ~14 stonebrick 0  
fill ~4 ~0 ~18 ~124 ~0 ~18 stonebrick 0  
fill ~4 ~0 ~19 ~124 ~0 ~19 stonebrick 0  
fill ~4 ~0 ~20 ~124 ~0 ~20 stonebrick 0  
fill ~4 ~0 ~24 ~124 ~0 ~24 stonebrick 0  
fill ~4 ~0 ~25 ~124 ~0 ~25 stonebrick 0  
fill ~4 ~0 ~26 ~124 ~0 ~26 stonebrick 0  
fill ~4 ~0 ~30 ~124 ~0 ~30 stonebrick 0  
fill ~4 ~0 ~31 ~124 ~0 ~31 stonebrick 0  
fill ~4 ~0 ~32 ~124 ~0 ~32 stonebrick 0  
fill ~4 ~0 ~36 ~50 ~0 ~36 stonebrick 0  
fill ~4 ~0 ~37 ~44 ~0 ~37 stonebrick 0  
fill ~4 ~0 ~38 ~124 ~0 ~38 stonebrick 0  
fill ~4 ~0 ~42 ~51 ~0 ~42 stonebrick 0  
fill ~4 ~0 ~43 ~124 ~0 ~43 stonebrick 0  
fill ~4 ~0 ~44 ~124 ~0 ~44 stonebrick 0  
fill ~4 ~0 ~48 ~124 ~0 ~48 stonebrick 0  
fill ~4 ~0 ~49 ~45 ~0 ~49 stonebrick 0  
fill ~4 ~0 ~50 ~75 ~0 ~50 stonebrick 0  
fill ~4 ~0 ~54 ~51 ~0 ~54 stonebrick 0  
fill ~4 ~0 ~55 ~54 ~0 ~55 stonebrick 0  
fill ~4 ~0 ~56 ~124 ~0 ~56 stonebrick 0  
fill ~4 ~0 ~60 ~124 ~0 ~60 stonebrick 0  
fill ~4 ~0 ~61 ~124 ~0 ~61 stonebrick 0  
fill ~4 ~0 ~62 ~124 ~0 ~62 stonebrick 0  
fill ~4 ~0 ~66 ~124 ~0 ~66 stonebrick 0  
fill ~4 ~0 ~67 ~124 ~0 ~67 stonebrick 0  
fill ~4 ~0 ~68 ~124 ~0 ~68 stonebrick 0  
fill ~4 ~0 ~72 ~124 ~0 ~72 stonebrick 0  
fill ~4 ~0 ~73 ~54 ~0 ~73 stonebrick 0  
fill ~4 ~0 ~74 ~75 ~0 ~74 stonebrick 0  
fill ~4 ~0 ~78 ~51 ~0 ~78 stonebrick 0  
fill ~4 ~0 ~79 ~76 ~0 ~79 stonebrick 0  
fill ~4 ~0 ~80 ~124 ~0 ~80 stonebrick 0  
fill ~4 ~0 ~84 ~124 ~0 ~84 stonebrick 0  
fill ~4 ~0 ~85 ~124 ~0 ~85 stonebrick 0  
fill ~4 ~0 ~86 ~45 ~0 ~86 stonebrick 0  
fill ~4 ~0 ~90 ~124 ~0 ~90 stonebrick 0  
fill ~4 ~0 ~91 ~44 ~0 ~91 stonebrick 0  
fill ~4 ~0 ~92 ~50 ~0 ~92 stonebrick 0  
fill ~4 ~0 ~96 ~124 ~0 ~96 stonebrick 0  
fill ~4 ~0 ~97 ~124 ~0 ~97 stonebrick 0  
fill ~4 ~0 ~98 ~124 ~0 ~98 stonebrick 0  
fill ~4 ~0 ~102 ~124 ~0 ~102 stonebrick 0  
fill ~4 ~0 ~103 ~124 ~0 ~103 stonebrick 0  
fill ~4 ~0 ~104 ~124 ~0 ~104 stonebrick 0  
fill ~4 ~0 ~108 ~124 ~0 ~108 stonebrick 0  
fill ~4 ~0 ~109 ~124 ~0 ~109 stonebrick 0  
fill ~4 ~0 ~110 ~124 ~0 ~110 stonebrick 0  
fill ~4 ~0 ~114 ~124 ~0 ~114 stonebrick 0  
fill ~4 ~0 ~115 ~124 ~0 ~115 stonebrick 0  
fill ~4 ~0 ~116 ~124 ~0 ~116 stonebrick 0  
fill ~4 ~0 ~120 ~124 ~0 ~120 stonebrick 0  
fill ~4 ~0 ~121 ~124 ~0 ~121 stonebrick 0  
fill ~4 ~0 ~122 ~124 ~0 ~122 stonebrick 0  
fill ~4 ~0 ~127 ~4 ~4 ~127 log 12 
setblock ~5 ~0 ~1 stone_stairs 2 
setblock ~5 ~0 ~2 stained_hardened_clay 5 
setblock ~5 ~0 ~126 stained_hardened_clay 5 
setblock ~5 ~0 ~127 stone_stairs 3 
setblock ~6 ~0 ~1 stone_slab 5  
fill ~6 ~0 ~2 ~8 ~0 ~2 stonebrick 0 
setblock ~6 ~0 ~3 stained_hardened_clay 13 
setblock ~6 ~0 ~125 stained_hardened_clay 13  
fill ~6 ~0 ~126 ~8 ~0 ~126 stonebrick 0 
setblock ~6 ~0 ~127 stone_slab 5 
setblock ~7 ~0 ~1 stonebrick 3  
fill ~7 ~0 ~3 ~7 ~4 ~3 log 12  
fill ~7 ~0 ~125 ~7 ~4 ~125 log 12 
setblock ~7 ~0 ~127 stonebrick 3 
setblock ~8 ~0 ~1 stone_slab 5 
setblock ~8 ~0 ~3 stained_hardened_clay 13 
setblock ~8 ~0 ~125 stained_hardened_clay 13 
setblock ~8 ~0 ~127 stone_slab 5 
setblock ~9 ~0 ~1 stone_stairs 2 
setblock ~9 ~0 ~2 stained_hardened_clay 5  
fill ~9 ~0 ~3 ~11 ~0 ~3 stonebrick 0  
fill ~9 ~0 ~125 ~11 ~0 ~125 stonebrick 0 
setblock ~9 ~0 ~126 stained_hardened_clay 5 
setblock ~9 ~0 ~127 stone_stairs 3  
fill ~10 ~0 ~1 ~10 ~4 ~1 log 12  
fill ~10 ~0 ~2 ~10 ~2 ~2 stained_hardened_clay 13  
fill ~10 ~0 ~126 ~10 ~2 ~126 stained_hardened_clay 13  
fill ~10 ~0 ~127 ~10 ~4 ~127 log 12 
setblock ~11 ~0 ~1 stone_stairs 2 
setblock ~11 ~0 ~2 stained_hardened_clay 5 
setblock ~11 ~0 ~126 stained_hardened_clay 5 
setblock ~11 ~0 ~127 stone_stairs 3 
setblock ~12 ~0 ~1 stone_slab 5  
fill ~12 ~0 ~2 ~14 ~0 ~2 stonebrick 0 
setblock ~12 ~0 ~3 stained_hardened_clay 13 
setblock ~12 ~0 ~125 stained_hardened_clay 13  
fill ~12 ~0 ~126 ~14 ~0 ~126 stonebrick 0 
setblock ~12 ~0 ~127 stone_slab 5 
setblock ~13 ~0 ~1 stonebrick 3  
fill ~13 ~0 ~3 ~13 ~4 ~3 log 12  
fill ~13 ~0 ~125 ~13 ~4 ~125 log 12 
setblock ~13 ~0 ~127 stonebrick 3 
setblock ~14 ~0 ~1 stone_slab 5 
setblock ~14 ~0 ~3 stained_hardened_clay 13 
setblock ~14 ~0 ~125 stained_hardened_clay 13 
setblock ~14 ~0 ~127 stone_slab 5 
setblock ~15 ~0 ~1 stone_stairs 2 
setblock ~15 ~0 ~2 stained_hardened_clay 5  
fill ~15 ~0 ~3 ~17 ~0 ~3 stonebrick 0  
fill ~15 ~0 ~125 ~17 ~0 ~125 stonebrick 0 
setblock ~15 ~0 ~126 stained_hardened_clay 5 
setblock ~15 ~0 ~127 stone_stairs 3  
fill ~16 ~0 ~1 ~16 ~4 ~1 log 12  
fill ~16 ~0 ~2 ~16 ~2 ~2 stained_hardened_clay 13  
fill ~16 ~0 ~126 ~16 ~2 ~126 stained_hardened_clay 13  
fill ~16 ~0 ~127 ~16 ~4 ~127 log 12 
setblock ~17 ~0 ~1 stone_stairs 2 
setblock ~17 ~0 ~2 stained_hardened_clay 5 
setblock ~17 ~0 ~126 stained_hardened_clay 5 
setblock ~17 ~0 ~127 stone_stairs 3 
setblock ~18 ~0 ~1 stone_slab 5  
fill ~18 ~0 ~2 ~20 ~0 ~2 stonebrick 0 
setblock ~18 ~0 ~3 stained_hardened_clay 13 
setblock ~18 ~0 ~125 stained_hardened_clay 13  
fill ~18 ~0 ~126 ~20 ~0 ~126 stonebrick 0 
setblock ~18 ~0 ~127 stone_slab 5 
setblock ~19 ~0 ~1 stonebrick 3  
fill ~19 ~0 ~3 ~19 ~4 ~3 log 12  
fill ~19 ~0 ~125 ~19 ~4 ~125 log 12 
setblock ~19 ~0 ~127 stonebrick 3 
setblock ~20 ~0 ~1 stone_slab 5 
setblock ~20 ~0 ~3 stained_hardened_clay 13 
setblock ~20 ~0 ~125 stained_hardened_clay 13 
setblock ~20 ~0 ~127 stone_slab 5 
setblock ~21 ~0 ~1 stone_stairs 2 
setblock ~21 ~0 ~2 stained_hardened_clay 5  
fill ~21 ~0 ~3 ~23 ~0 ~3 stonebrick 0  
fill ~21 ~0 ~125 ~23 ~0 ~125 stonebrick 0 
setblock ~21 ~0 ~126 stained_hardened_clay 5 
setblock ~21 ~0 ~127 stone_stairs 3  
fill ~22 ~0 ~1 ~22 ~4 ~1 log 12  
fill ~22 ~0 ~2 ~22 ~2 ~2 stained_hardened_clay 13  
fill ~22 ~0 ~126 ~22 ~2 ~126 stained_hardened_clay 13  
fill ~22 ~0 ~127 ~22 ~4 ~127 log 12 
setblock ~23 ~0 ~1 stone_stairs 2 
setblock ~23 ~0 ~2 stained_hardened_clay 5 
setblock ~23 ~0 ~126 stained_hardened_clay 5 
setblock ~23 ~0 ~127 stone_stairs 3 
setblock ~24 ~0 ~1 stone_slab 5  
fill ~24 ~0 ~2 ~26 ~0 ~2 stonebrick 0 
setblock ~24 ~0 ~3 stained_hardened_clay 13 
setblock ~24 ~0 ~125 stained_hardened_clay 13  
fill ~24 ~0 ~126 ~26 ~0 ~126 stonebrick 0 
setblock ~24 ~0 ~127 stone_slab 5 
setblock ~25 ~0 ~1 stonebrick 3  
fill ~25 ~0 ~3 ~25 ~4 ~3 log 12  
fill ~25 ~0 ~125 ~25 ~4 ~125 log 12 
setblock ~25 ~0 ~127 stonebrick 3 
setblock ~26 ~0 ~1 stone_slab 5 
setblock ~26 ~0 ~3 stained_hardened_clay 13 
setblock ~26 ~0 ~125 stained_hardened_clay 13 
setblock ~26 ~0 ~127 stone_slab 5 
setblock ~27 ~0 ~1 stone_stairs 2 
setblock ~27 ~0 ~2 stained_hardened_clay 5  
fill ~27 ~0 ~3 ~29 ~0 ~3 stonebrick 0  
fill ~27 ~0 ~125 ~29 ~0 ~125 stonebrick 0 
setblock ~27 ~0 ~126 stained_hardened_clay 5 
setblock ~27 ~0 ~127 stone_stairs 3  
fill ~28 ~0 ~1 ~28 ~4 ~1 log 12  
fill ~28 ~0 ~2 ~28 ~2 ~2 stained_hardened_clay 13  
fill ~28 ~0 ~126 ~28 ~2 ~126 stained_hardened_clay 13  
fill ~28 ~0 ~127 ~28 ~4 ~127 log 12 
setblock ~29 ~0 ~1 stone_stairs 2 
setblock ~29 ~0 ~2 stained_hardened_clay 5 
setblock ~29 ~0 ~126 stained_hardened_clay 5 
setblock ~29 ~0 ~127 stone_stairs 3 
setblock ~30 ~0 ~1 stone_slab 5  
fill ~30 ~0 ~2 ~32 ~0 ~2 stonebrick 0 
setblock ~30 ~0 ~3 stained_hardened_clay 13 
setblock ~30 ~0 ~125 stained_hardened_clay 13  
fill ~30 ~0 ~126 ~32 ~0 ~126 stonebrick 0 
setblock ~30 ~0 ~127 stone_slab 5 
setblock ~31 ~0 ~1 stonebrick 3  
fill ~31 ~0 ~3 ~31 ~4 ~3 log 12  
fill ~31 ~0 ~125 ~31 ~4 ~125 log 12 
setblock ~31 ~0 ~127 stonebrick 3 
setblock ~32 ~0 ~1 stone_slab 5 
setblock ~32 ~0 ~3 stained_hardened_clay 13 
setblock ~32 ~0 ~125 stained_hardened_clay 13 
setblock ~32 ~0 ~127 stone_slab 5 
setblock ~33 ~0 ~1 stone_stairs 2 
setblock ~33 ~0 ~2 stained_hardened_clay 5  
fill ~33 ~0 ~3 ~35 ~0 ~3 stonebrick 0 
setblock ~33 ~0 ~64 redstone_block 0  
fill ~33 ~0 ~125 ~35 ~0 ~125 stonebrick 0 
setblock ~33 ~0 ~126 stained_hardened_clay 5 
setblock ~33 ~0 ~127 stone_stairs 3  
fill ~34 ~0 ~1 ~34 ~4 ~1 log 12  
fill ~34 ~0 ~2 ~34 ~2 ~2 stained_hardened_clay 13  
fill ~34 ~0 ~64 ~38 ~0 ~64 stonebrick 0  
fill ~34 ~0 ~126 ~34 ~2 ~126 stained_hardened_clay 13  
fill ~34 ~0 ~127 ~34 ~4 ~127 log 12 
setblock ~35 ~0 ~1 stone_stairs 2 
setblock ~35 ~0 ~2 stained_hardened_clay 5 
setblock ~35 ~0 ~126 stained_hardened_clay 5 
setblock ~35 ~0 ~127 stone_stairs 3 
setblock ~36 ~0 ~1 stone_slab 5  
fill ~36 ~0 ~2 ~38 ~0 ~2 stonebrick 0 
setblock ~36 ~0 ~3 stained_hardened_clay 13 
setblock ~36 ~0 ~51 redstone_block 0 
setblock ~36 ~0 ~77 redstone_block 0 
setblock ~36 ~0 ~125 stained_hardened_clay 13  
fill ~36 ~0 ~126 ~38 ~0 ~126 stonebrick 0 
setblock ~36 ~0 ~127 stone_slab 5 
setblock ~37 ~0 ~1 stonebrick 3  
fill ~37 ~0 ~3 ~37 ~4 ~3 log 12 
setblock ~37 ~0 ~45 redstone_block 0  
fill ~37 ~0 ~51 ~56 ~0 ~51 stonebrick 0  
fill ~37 ~0 ~77 ~48 ~0 ~77 stonebrick 0 
setblock ~37 ~0 ~83 redstone_block 0  
fill ~37 ~0 ~125 ~37 ~4 ~125 log 12 
setblock ~37 ~0 ~127 stonebrick 3 
setblock ~38 ~0 ~1 stone_slab 5 
setblock ~38 ~0 ~3 stained_hardened_clay 13  
fill ~38 ~0 ~45 ~63 ~0 ~45 stonebrick 0  
fill ~38 ~0 ~83 ~63 ~0 ~83 stonebrick 0 
setblock ~38 ~0 ~125 stained_hardened_clay 13 
setblock ~38 ~0 ~127 stone_slab 5 
setblock ~39 ~0 ~1 stone_stairs 2 
setblock ~39 ~0 ~2 stained_hardened_clay 5  
fill ~39 ~0 ~3 ~41 ~0 ~3 stonebrick 0 
setblock ~39 ~0 ~57 redstone_block 0 
setblock ~39 ~0 ~64 redstone_block 0 
setblock ~39 ~0 ~71 redstone_block 0  
fill ~39 ~0 ~125 ~41 ~0 ~125 stonebrick 0 
setblock ~39 ~0 ~126 stained_hardened_clay 5 
setblock ~39 ~0 ~127 stone_stairs 3  
fill ~40 ~0 ~1 ~40 ~4 ~1 log 12  
fill ~40 ~0 ~2 ~40 ~2 ~2 stained_hardened_clay 13 
setblock ~40 ~0 ~52 lit_redstone_lamp 0  
fill ~40 ~0 ~57 ~46 ~0 ~57 stonebrick 0  
fill ~40 ~0 ~64 ~44 ~0 ~64 stonebrick 0  
fill ~40 ~0 ~71 ~46 ~0 ~71 stonebrick 0  
fill ~40 ~0 ~126 ~40 ~2 ~126 stained_hardened_clay 13  
fill ~40 ~0 ~127 ~40 ~4 ~127 log 12 
setblock ~41 ~0 ~1 stone_stairs 2 
setblock ~41 ~0 ~2 stained_hardened_clay 5  
fill ~41 ~0 ~52 ~49 ~0 ~52 stonebrick 0 
setblock ~41 ~0 ~82 lit_redstone_lamp 0 
setblock ~41 ~0 ~126 stained_hardened_clay 5 
setblock ~41 ~0 ~127 stone_stairs 3 
setblock ~42 ~0 ~1 stone_slab 5  
fill ~42 ~0 ~2 ~44 ~0 ~2 stonebrick 0 
setblock ~42 ~0 ~3 stained_hardened_clay 13 
setblock ~42 ~0 ~46 lit_redstone_lamp 0 
setblock ~42 ~0 ~76 lit_redstone_lamp 0  
fill ~42 ~0 ~82 ~48 ~0 ~82 stonebrick 0 
setblock ~42 ~0 ~125 stained_hardened_clay 13  
fill ~42 ~0 ~126 ~44 ~0 ~126 stonebrick 0 
setblock ~42 ~0 ~127 stone_slab 5 
setblock ~43 ~0 ~1 stonebrick 3  
fill ~43 ~0 ~3 ~43 ~4 ~3 log 12  
fill ~43 ~0 ~46 ~78 ~0 ~46 stonebrick 0  
fill ~43 ~0 ~76 ~53 ~0 ~76 stonebrick 0  
fill ~43 ~0 ~125 ~43 ~4 ~125 log 12 
setblock ~43 ~0 ~127 stonebrick 3 
setblock ~44 ~0 ~1 stone_slab 5 
setblock ~44 ~0 ~3 stained_hardened_clay 13 
setblock ~44 ~0 ~125 stained_hardened_clay 13 
setblock ~44 ~0 ~127 stone_slab 5 
setblock ~45 ~0 ~1 stone_stairs 2 
setblock ~45 ~0 ~2 stained_hardened_clay 5  
fill ~45 ~0 ~3 ~47 ~0 ~3 stonebrick 0 
setblock ~45 ~0 ~37 redstone_block 0 
setblock ~45 ~0 ~64 redstone_block 0 
setblock ~45 ~0 ~91 redstone_block 0  
fill ~45 ~0 ~125 ~47 ~0 ~125 stonebrick 0 
setblock ~45 ~0 ~126 stained_hardened_clay 5 
setblock ~45 ~0 ~127 stone_stairs 3  
fill ~46 ~0 ~1 ~46 ~4 ~1 log 12  
fill ~46 ~0 ~2 ~46 ~2 ~2 stained_hardened_clay 13  
fill ~46 ~0 ~37 ~82 ~0 ~37 stonebrick 0 
setblock ~46 ~0 ~41 lit_redstone_lamp 0 
setblock ~46 ~0 ~49 lit_redstone_lamp 0  
fill ~46 ~0 ~64 ~50 ~0 ~64 stonebrick 0 
setblock ~46 ~0 ~86 lit_redstone_lamp 0  
fill ~46 ~0 ~91 ~82 ~0 ~91 stonebrick 0  
fill ~46 ~0 ~126 ~46 ~2 ~126 stained_hardened_clay 13  
fill ~46 ~0 ~127 ~46 ~4 ~127 log 12 
setblock ~47 ~0 ~1 stone_stairs 2 
setblock ~47 ~0 ~2 stained_hardened_clay 5  
fill ~47 ~0 ~41 ~125 ~0 ~41 stonebrick 0  
fill ~47 ~0 ~49 ~50 ~0 ~49 stonebrick 0 
setblock ~47 ~0 ~57 redstone_block 0 
setblock ~47 ~0 ~71 redstone_block 0  
fill ~47 ~0 ~86 ~75 ~0 ~86 stonebrick 0 
setblock ~47 ~0 ~126 stained_hardened_clay 5 
setblock ~47 ~0 ~127 stone_stairs 3 
setblock ~48 ~0 ~1 stone_slab 5  
fill ~48 ~0 ~2 ~50 ~0 ~2 stonebrick 0 
setblock ~48 ~0 ~3 stained_hardened_clay 13  
fill ~48 ~0 ~57 ~76 ~0 ~57 stonebrick 0  
fill ~48 ~0 ~71 ~50 ~0 ~71 stonebrick 0 
setblock ~48 ~0 ~125 stained_hardened_clay 13  
fill ~48 ~0 ~126 ~50 ~0 ~126 stonebrick 0 
setblock ~48 ~0 ~127 stone_slab 5 
setblock ~49 ~0 ~1 stonebrick 3  
fill ~49 ~0 ~3 ~49 ~4 ~3 log 12 
setblock ~49 ~0 ~77 lit_redstone_lamp 0 
setblock ~49 ~0 ~82 lit_redstone_lamp 0  
fill ~49 ~0 ~125 ~49 ~4 ~125 log 12 
setblock ~49 ~0 ~127 stonebrick 3 
setblock ~50 ~0 ~1 stone_slab 5 
setblock ~50 ~0 ~3 stained_hardened_clay 13 
setblock ~50 ~0 ~52 lit_redstone_lamp 0  
fill ~50 ~0 ~77 ~63 ~0 ~77 stonebrick 0  
fill ~50 ~0 ~82 ~85 ~0 ~82 stonebrick 0 
setblock ~50 ~0 ~125 stained_hardened_clay 13 
setblock ~50 ~0 ~127 stone_slab 5   

KittysCommands:  
setblock ~51 ~0 ~1 stone_stairs 2 
setblock ~51 ~0 ~2 stained_hardened_clay 5  
fill ~51 ~0 ~3 ~53 ~0 ~3 stonebrick 0 
setblock ~51 ~0 ~36 redstone_block 0 
setblock ~51 ~0 ~49 lit_redstone_lamp 0  
fill ~51 ~0 ~52 ~73 ~0 ~52 stonebrick 0 
setblock ~51 ~0 ~64 redstone_block 0 
setblock ~51 ~0 ~71 redstone_block 0 
setblock ~51 ~0 ~92 redstone_block 0  
fill ~51 ~0 ~125 ~53 ~0 ~125 stonebrick 0 
setblock ~51 ~0 ~126 stained_hardened_clay 5 
setblock ~51 ~0 ~127 stone_stairs 3  
fill ~52 ~0 ~1 ~52 ~4 ~1 log 12  
fill ~52 ~0 ~2 ~52 ~2 ~2 stained_hardened_clay 13  
fill ~52 ~0 ~36 ~76 ~0 ~36 stonebrick 0 
setblock ~52 ~0 ~42 lit_redstone_lamp 0  
fill ~52 ~0 ~49 ~124 ~0 ~49 stonebrick 0 
setblock ~52 ~0 ~54 redstone_block 0  
fill ~52 ~0 ~64 ~63 ~0 ~64 stonebrick 0  
fill ~52 ~0 ~71 ~80 ~0 ~71 stonebrick 0 
setblock ~52 ~0 ~78 lit_redstone_lamp 0 
setblock ~52 ~0 ~88 lit_redstone_lamp 0  
fill ~52 ~0 ~92 ~76 ~0 ~92 stonebrick 0  
fill ~52 ~0 ~126 ~52 ~2 ~126 stained_hardened_clay 13  
fill ~52 ~0 ~127 ~52 ~4 ~127 log 12 
setblock ~53 ~0 ~1 stone_stairs 2 
setblock ~53 ~0 ~2 stained_hardened_clay 5  
fill ~53 ~0 ~42 ~81 ~0 ~42 stonebrick 0 
setblock ~53 ~0 ~53 redstone_block 0  
fill ~53 ~0 ~54 ~124 ~0 ~54 stonebrick 0 
setblock ~53 ~0 ~75 redstone_block 0  
fill ~53 ~0 ~78 ~124 ~0 ~78 stonebrick 0  
fill ~53 ~0 ~88 ~125 ~0 ~88 stonebrick 0 
setblock ~53 ~0 ~126 stained_hardened_clay 5 
setblock ~53 ~0 ~127 stone_stairs 3 
setblock ~54 ~0 ~1 stone_slab 5  
fill ~54 ~0 ~2 ~56 ~0 ~2 stonebrick 0 
setblock ~54 ~0 ~3 stained_hardened_clay 13  
fill ~54 ~0 ~53 ~74 ~0 ~53 stonebrick 0  
fill ~54 ~0 ~75 ~74 ~0 ~75 stonebrick 0 
setblock ~54 ~0 ~76 redstone_block 0 
setblock ~54 ~0 ~125 stained_hardened_clay 13  
fill ~54 ~0 ~126 ~56 ~0 ~126 stonebrick 0 
setblock ~54 ~0 ~127 stone_slab 5 
setblock ~55 ~0 ~1 stonebrick 3  
fill ~55 ~0 ~3 ~55 ~4 ~3 log 12 
setblock ~55 ~0 ~55 redstone_block 0 
setblock ~55 ~0 ~73 redstone_block 0  
fill ~55 ~0 ~76 ~77 ~0 ~76 stonebrick 0  
fill ~55 ~0 ~125 ~55 ~4 ~125 log 12 
setblock ~55 ~0 ~127 stonebrick 3 
setblock ~56 ~0 ~1 stone_slab 5 
setblock ~56 ~0 ~3 stained_hardened_clay 13  
fill ~56 ~0 ~55 ~72 ~0 ~55 stonebrick 0  
fill ~56 ~0 ~73 ~72 ~0 ~73 stonebrick 0 
setblock ~56 ~0 ~125 stained_hardened_clay 13 
setblock ~56 ~0 ~127 stone_slab 5 
setblock ~57 ~0 ~1 stone_stairs 2 
setblock ~57 ~0 ~2 stained_hardened_clay 5  
fill ~57 ~0 ~3 ~59 ~0 ~3 stonebrick 0 
setblock ~57 ~0 ~39 redstone_block 0 
setblock ~57 ~0 ~47 redstone_block 0 
setblock ~57 ~0 ~51 redstone_block 0 
setblock ~57 ~0 ~81 redstone_block 0 
setblock ~57 ~0 ~89 redstone_block 0  
fill ~57 ~0 ~125 ~59 ~0 ~125 stonebrick 0 
setblock ~57 ~0 ~126 stained_hardened_clay 5 
setblock ~57 ~0 ~127 stone_stairs 3  
fill ~58 ~0 ~1 ~58 ~4 ~1 log 12  
fill ~58 ~0 ~2 ~58 ~2 ~2 stained_hardened_clay 13  
fill ~58 ~0 ~39 ~63 ~0 ~39 stonebrick 0  
fill ~58 ~0 ~47 ~70 ~0 ~47 stonebrick 0  
fill ~58 ~0 ~51 ~63 ~0 ~51 stonebrick 0  
fill ~58 ~0 ~81 ~70 ~0 ~81 stonebrick 0  
fill ~58 ~0 ~89 ~63 ~0 ~89 stonebrick 0  
fill ~58 ~0 ~126 ~58 ~2 ~126 stained_hardened_clay 13  
fill ~58 ~0 ~127 ~58 ~4 ~127 log 12 
setblock ~59 ~0 ~1 stone_stairs 2 
setblock ~59 ~0 ~2 stained_hardened_clay 5 
setblock ~59 ~0 ~126 stained_hardened_clay 5 
setblock ~59 ~0 ~127 stone_stairs 3 
setblock ~60 ~0 ~1 stone_slab 5  
fill ~60 ~0 ~2 ~62 ~0 ~2 stonebrick 0 
setblock ~60 ~0 ~3 stained_hardened_clay 13 
setblock ~60 ~0 ~125 stained_hardened_clay 13  
fill ~60 ~0 ~126 ~62 ~0 ~126 stonebrick 0 
setblock ~60 ~0 ~127 stone_slab 5 
setblock ~61 ~0 ~1 stonebrick 3  
fill ~61 ~0 ~3 ~61 ~4 ~3 log 12  
fill ~61 ~0 ~125 ~61 ~4 ~125 log 12 
setblock ~61 ~0 ~127 stonebrick 3 
setblock ~62 ~0 ~1 stone_slab 5 
setblock ~62 ~0 ~3 stained_hardened_clay 13 
setblock ~62 ~0 ~125 stained_hardened_clay 13 
setblock ~62 ~0 ~127 stone_slab 5 
setblock ~63 ~0 ~1 stone_stairs 2 
setblock ~63 ~0 ~2 stained_hardened_clay 5  
fill ~63 ~0 ~3 ~65 ~0 ~3 stonebrick 0  
fill ~63 ~0 ~125 ~65 ~0 ~125 stonebrick 0 
setblock ~63 ~0 ~126 stained_hardened_clay 5 
setblock ~63 ~0 ~127 stone_stairs 3  
fill ~64 ~0 ~1 ~64 ~4 ~1 log 12  
fill ~64 ~0 ~2 ~64 ~2 ~2 stained_hardened_clay 13 
setblock ~64 ~0 ~33 redstone_block 0 
setblock ~64 ~0 ~39 redstone_block 0 
setblock ~64 ~0 ~45 redstone_block 0 
setblock ~64 ~0 ~51 redstone_block 0 
setblock ~64 ~0 ~77 redstone_block 0 
setblock ~64 ~0 ~83 redstone_block 0 
setblock ~64 ~0 ~89 redstone_block 0 
setblock ~64 ~0 ~95 redstone_block 0  
fill ~64 ~0 ~126 ~64 ~2 ~126 stained_hardened_clay 13  
fill ~64 ~0 ~127 ~64 ~4 ~127 log 12 
setblock ~65 ~0 ~1 stone_stairs 2 
setblock ~65 ~0 ~2 stained_hardened_clay 5  
fill ~65 ~0 ~33 ~125 ~0 ~33 stonebrick 0  
fill ~65 ~0 ~39 ~70 ~0 ~39 stonebrick 0  
fill ~65 ~0 ~45 ~90 ~0 ~45 stonebrick 0  
fill ~65 ~0 ~51 ~78 ~0 ~51 stonebrick 0  
fill ~65 ~0 ~64 ~76 ~0 ~64 stonebrick 0  
fill ~65 ~0 ~77 ~70 ~0 ~77 stonebrick 0  
fill ~65 ~0 ~83 ~90 ~0 ~83 stonebrick 0  
fill ~65 ~0 ~89 ~70 ~0 ~89 stonebrick 0  
fill ~65 ~0 ~95 ~125 ~0 ~95 stonebrick 0 
setblock ~65 ~0 ~126 stained_hardened_clay 5 
setblock ~65 ~0 ~127 stone_stairs 3 
setblock ~66 ~0 ~1 stone_slab 5  
fill ~66 ~0 ~2 ~68 ~0 ~2 stonebrick 0 
setblock ~66 ~0 ~3 stained_hardened_clay 13 
setblock ~66 ~0 ~125 stained_hardened_clay 13  
fill ~66 ~0 ~126 ~68 ~0 ~126 stonebrick 0 
setblock ~66 ~0 ~127 stone_slab 5 
setblock ~67 ~0 ~1 stonebrick 3  
fill ~67 ~0 ~3 ~67 ~4 ~3 log 12  
fill ~67 ~0 ~125 ~67 ~4 ~125 log 12 
setblock ~67 ~0 ~127 stonebrick 3 
setblock ~68 ~0 ~1 stone_slab 5 
setblock ~68 ~0 ~3 stained_hardened_clay 13 
setblock ~68 ~0 ~125 stained_hardened_clay 13 
setblock ~68 ~0 ~127 stone_slab 5 
setblock ~69 ~0 ~1 stone_stairs 2 
setblock ~69 ~0 ~2 stained_hardened_clay 5  
fill ~69 ~0 ~3 ~71 ~0 ~3 stonebrick 0  
fill ~69 ~0 ~125 ~71 ~0 ~125 stonebrick 0 
setblock ~69 ~0 ~126 stained_hardened_clay 5 
setblock ~69 ~0 ~127 stone_stairs 3  
fill ~70 ~0 ~1 ~70 ~4 ~1 log 12  
fill ~70 ~0 ~2 ~70 ~2 ~2 stained_hardened_clay 13  
fill ~70 ~0 ~126 ~70 ~2 ~126 stained_hardened_clay 13  
fill ~70 ~0 ~127 ~70 ~4 ~127 log 12 
setblock ~71 ~0 ~1 stone_stairs 2 
setblock ~71 ~0 ~2 stained_hardened_clay 5 
setblock ~71 ~0 ~39 redstone_block 0 
setblock ~71 ~0 ~47 redstone_block 0 
setblock ~71 ~0 ~77 redstone_block 0 
setblock ~71 ~0 ~81 redstone_block 0 
setblock ~71 ~0 ~89 redstone_block 0 
setblock ~71 ~0 ~126 stained_hardened_clay 5 
setblock ~71 ~0 ~127 stone_stairs 3 
setblock ~72 ~0 ~1 stone_slab 5  
fill ~72 ~0 ~2 ~74 ~0 ~2 stonebrick 0 
setblock ~72 ~0 ~3 stained_hardened_clay 13  
fill ~72 ~0 ~39 ~125 ~0 ~39 stonebrick 0  
fill ~72 ~0 ~47 ~125 ~0 ~47 stonebrick 0  
fill ~72 ~0 ~77 ~91 ~0 ~77 stonebrick 0  
fill ~72 ~0 ~81 ~125 ~0 ~81 stonebrick 0  
fill ~72 ~0 ~89 ~125 ~0 ~89 stonebrick 0 
setblock ~72 ~0 ~125 stained_hardened_clay 13  
fill ~72 ~0 ~126 ~74 ~0 ~126 stonebrick 0 
setblock ~72 ~0 ~127 stone_slab 5 
setblock ~73 ~0 ~1 stonebrick 3  
fill ~73 ~0 ~3 ~73 ~4 ~3 log 12 
setblock ~73 ~0 ~55 redstone_block 0 
setblock ~73 ~0 ~73 redstone_block 0  
fill ~73 ~0 ~125 ~73 ~4 ~125 log 12 
setblock ~73 ~0 ~127 stonebrick 3 
setblock ~74 ~0 ~1 stone_slab 5 
setblock ~74 ~0 ~3 stained_hardened_clay 13 
setblock ~74 ~0 ~52 redstone_block 0  
fill ~74 ~0 ~55 ~124 ~0 ~55 stonebrick 0  
fill ~74 ~0 ~73 ~124 ~0 ~73 stonebrick 0 
setblock ~74 ~0 ~125 stained_hardened_clay 13 
setblock ~74 ~0 ~127 stone_slab 5 
setblock ~75 ~0 ~1 stone_stairs 2 
setblock ~75 ~0 ~2 stained_hardened_clay 5  
fill ~75 ~0 ~3 ~77 ~0 ~3 stonebrick 0  
fill ~75 ~0 ~52 ~85 ~0 ~52 stonebrick 0 
setblock ~75 ~0 ~53 redstone_block 0 
setblock ~75 ~0 ~75 redstone_block 0  
fill ~75 ~0 ~125 ~77 ~0 ~125 stonebrick 0 
setblock ~75 ~0 ~126 stained_hardened_clay 5 
setblock ~75 ~0 ~127 stone_stairs 3  
fill ~76 ~0 ~1 ~76 ~4 ~1 log 12  
fill ~76 ~0 ~2 ~76 ~2 ~2 stained_hardened_clay 13 
setblock ~76 ~0 ~40 lit_redstone_lamp 0 
setblock ~76 ~0 ~50 lit_redstone_lamp 0  
fill ~76 ~0 ~53 ~125 ~0 ~53 stonebrick 0 
setblock ~76 ~0 ~74 redstone_block 0  
fill ~76 ~0 ~75 ~125 ~0 ~75 stonebrick 0 
setblock ~76 ~0 ~86 lit_redstone_lamp 0  
fill ~76 ~0 ~126 ~76 ~2 ~126 stained_hardened_clay 13  
fill ~76 ~0 ~127 ~76 ~4 ~127 log 12 
setblock ~77 ~0 ~1 stone_stairs 2 
setblock ~77 ~0 ~2 stained_hardened_clay 5 
setblock ~77 ~0 ~36 redstone_block 0  
fill ~77 ~0 ~40 ~125 ~0 ~40 stonebrick 0  
fill ~77 ~0 ~50 ~124 ~0 ~50 stonebrick 0 
setblock ~77 ~0 ~57 redstone_block 0 
setblock ~77 ~0 ~64 redstone_block 0  
fill ~77 ~0 ~74 ~124 ~0 ~74 stonebrick 0 
setblock ~77 ~0 ~79 lit_redstone_lamp 0  
fill ~77 ~0 ~86 ~124 ~0 ~86 stonebrick 0 
setblock ~77 ~0 ~92 redstone_block 0 
setblock ~77 ~0 ~126 stained_hardened_clay 5 
setblock ~77 ~0 ~127 stone_stairs 3 
setblock ~78 ~0 ~1 stone_slab 5  
fill ~78 ~0 ~2 ~80 ~0 ~2 stonebrick 0 
setblock ~78 ~0 ~3 stained_hardened_clay 13  
fill ~78 ~0 ~36 ~124 ~0 ~36 stonebrick 0  
fill ~78 ~0 ~57 ~80 ~0 ~57 stonebrick 0  
fill ~78 ~0 ~64 ~82 ~0 ~64 stonebrick 0 
setblock ~78 ~0 ~76 lit_redstone_lamp 0  
fill ~78 ~0 ~79 ~81 ~0 ~79 stonebrick 0  
fill ~78 ~0 ~92 ~124 ~0 ~92 stonebrick 0 
setblock ~78 ~0 ~125 stained_hardened_clay 13  
fill ~78 ~0 ~126 ~80 ~0 ~126 stonebrick 0 
setblock ~78 ~0 ~127 stone_slab 5 
setblock ~79 ~0 ~1 stonebrick 3  
fill ~79 ~0 ~3 ~79 ~4 ~3 log 12 
setblock ~79 ~0 ~46 lit_redstone_lamp 0 
setblock ~79 ~0 ~51 lit_redstone_lamp 0  
fill ~79 ~0 ~76 ~87 ~0 ~76 stonebrick 0  
fill ~79 ~0 ~125 ~79 ~4 ~125 log 12 
setblock ~79 ~0 ~127 stonebrick 3 
setblock ~80 ~0 ~1 stone_slab 5 
setblock ~80 ~0 ~3 stained_hardened_clay 13  
fill ~80 ~0 ~46 ~86 ~0 ~46 stonebrick 0  
fill ~80 ~0 ~51 ~91 ~0 ~51 stonebrick 0 
setblock ~80 ~0 ~125 stained_hardened_clay 13 
setblock ~80 ~0 ~127 stone_slab 5 
setblock ~81 ~0 ~1 stone_stairs 2 
setblock ~81 ~0 ~2 stained_hardened_clay 5  
fill ~81 ~0 ~3 ~83 ~0 ~3 stonebrick 0 
setblock ~81 ~0 ~57 redstone_block 0 
setblock ~81 ~0 ~71 redstone_block 0  
fill ~81 ~0 ~125 ~83 ~0 ~125 stonebrick 0 
setblock ~81 ~0 ~126 stained_hardened_clay 5 
setblock ~81 ~0 ~127 stone_stairs 3  
fill ~82 ~0 ~1 ~82 ~4 ~1 log 12  
fill ~82 ~0 ~2 ~82 ~2 ~2 stained_hardened_clay 13 
setblock ~82 ~0 ~42 lit_redstone_lamp 0  
fill ~82 ~0 ~57 ~88 ~0 ~57 stonebrick 0  
fill ~82 ~0 ~71 ~88 ~0 ~71 stonebrick 0 
setblock ~82 ~0 ~79 lit_redstone_lamp 0 
setblock ~82 ~0 ~87 lit_redstone_lamp 0  
fill ~82 ~0 ~126 ~82 ~2 ~126 stained_hardened_clay 13  
fill ~82 ~0 ~127 ~82 ~4 ~127 log 12 
setblock ~83 ~0 ~1 stone_stairs 2 
setblock ~83 ~0 ~2 stained_hardened_clay 5 
setblock ~83 ~0 ~37 redstone_block 0  
fill ~83 ~0 ~42 ~124 ~0 ~42 stonebrick 0 
setblock ~83 ~0 ~64 redstone_block 0  
fill ~83 ~0 ~79 ~124 ~0 ~79 stonebrick 0  
fill ~83 ~0 ~87 ~125 ~0 ~87 stonebrick 0 
setblock ~83 ~0 ~91 redstone_block 0 
setblock ~83 ~0 ~126 stained_hardened_clay 5 
setblock ~83 ~0 ~127 stone_stairs 3 
setblock ~84 ~0 ~1 stone_slab 5  
fill ~84 ~0 ~2 ~86 ~0 ~2 stonebrick 0 
setblock ~84 ~0 ~3 stained_hardened_clay 13  
fill ~84 ~0 ~37 ~124 ~0 ~37 stonebrick 0  
fill ~84 ~0 ~64 ~88 ~0 ~64 stonebrick 0  
fill ~84 ~0 ~91 ~124 ~0 ~91 stonebrick 0 
setblock ~84 ~0 ~125 stained_hardened_clay 13  
fill ~84 ~0 ~126 ~86 ~0 ~126 stonebrick 0 
setblock ~84 ~0 ~127 stone_slab 5 
setblock ~85 ~0 ~1 stonebrick 3  
fill ~85 ~0 ~3 ~85 ~4 ~3 log 12  
fill ~85 ~0 ~125 ~85 ~4 ~125 log 12 
setblock ~85 ~0 ~127 stonebrick 3 
setblock ~86 ~0 ~1 stone_slab 5 
setblock ~86 ~0 ~3 stained_hardened_clay 13 
setblock ~86 ~0 ~52 lit_redstone_lamp 0 
setblock ~86 ~0 ~82 lit_redstone_lamp 0 
setblock ~86 ~0 ~125 stained_hardened_clay 13 
setblock ~86 ~0 ~127 stone_slab 5 
setblock ~87 ~0 ~1 stone_stairs 2 
setblock ~87 ~0 ~2 stained_hardened_clay 5  
fill ~87 ~0 ~3 ~89 ~0 ~3 stonebrick 0 
setblock ~87 ~0 ~46 lit_redstone_lamp 0  
fill ~87 ~0 ~52 ~125 ~0 ~52 stonebrick 0  
fill ~87 ~0 ~82 ~125 ~0 ~82 stonebrick 0  
fill ~87 ~0 ~125 ~89 ~0 ~125 stonebrick 0 
setblock ~87 ~0 ~126 stained_hardened_clay 5 
setblock ~87 ~0 ~127 stone_stairs 3  
fill ~88 ~0 ~1 ~88 ~4 ~1 log 12  
fill ~88 ~0 ~2 ~88 ~2 ~2 stained_hardened_clay 13  
fill ~88 ~0 ~46 ~125 ~0 ~46 stonebrick 0 
setblock ~88 ~0 ~76 lit_redstone_lamp 0  
fill ~88 ~0 ~126 ~88 ~2 ~126 stained_hardened_clay 13  
fill ~88 ~0 ~127 ~88 ~4 ~127 log 12 
setblock ~89 ~0 ~1 stone_stairs 2 
setblock ~89 ~0 ~2 stained_hardened_clay 5 
setblock ~89 ~0 ~57 redstone_block 0 
setblock ~89 ~0 ~64 redstone_block 0 
setblock ~89 ~0 ~71 redstone_block 0  
fill ~89 ~0 ~76 ~125 ~0 ~76 stonebrick 0 
setblock ~89 ~0 ~126 stained_hardened_clay 5 
setblock ~89 ~0 ~127 stone_stairs 3 
setblock ~90 ~0 ~1 stone_slab 5  
fill ~90 ~0 ~2 ~92 ~0 ~2 stonebrick 0 
setblock ~90 ~0 ~3 stained_hardened_clay 13  
fill ~90 ~0 ~57 ~125 ~0 ~57 stonebrick 0  
fill ~90 ~0 ~64 ~94 ~0 ~64 stonebrick 0  
fill ~90 ~0 ~71 ~125 ~0 ~71 stonebrick 0 
setblock ~90 ~0 ~125 stained_hardened_clay 13  
fill ~90 ~0 ~126 ~92 ~0 ~126 stonebrick 0 
setblock ~90 ~0 ~127 stone_slab 5 
setblock ~91 ~0 ~1 stonebrick 3  
fill ~91 ~0 ~3 ~91 ~4 ~3 log 12 
setblock ~91 ~0 ~45 redstone_block 0 
setblock ~91 ~0 ~83 redstone_block 0  
fill ~91 ~0 ~125 ~91 ~4 ~125 log 12 
setblock ~91 ~0 ~127 stonebrick 3 
setblock ~92 ~0 ~1 stone_slab 5 
setblock ~92 ~0 ~3 stained_hardened_clay 13  
fill ~92 ~0 ~45 ~125 ~0 ~45 stonebrick 0 
setblock ~92 ~0 ~51 redstone_block 0 
setblock ~92 ~0 ~77 redstone_block 0  
fill ~92 ~0 ~83 ~125 ~0 ~83 stonebrick 0 
setblock ~92 ~0 ~125 stained_hardened_clay 13 
setblock ~92 ~0 ~127 stone_slab 5 
setblock ~93 ~0 ~1 stone_stairs 2 
setblock ~93 ~0 ~2 stained_hardened_clay 5  
fill ~93 ~0 ~3 ~95 ~0 ~3 stonebrick 0  
fill ~93 ~0 ~51 ~125 ~0 ~51 stonebrick 0  
fill ~93 ~0 ~77 ~125 ~0 ~77 stonebrick 0  
fill ~93 ~0 ~125 ~95 ~0 ~125 stonebrick 0 
setblock ~93 ~0 ~126 stained_hardened_clay 5 
setblock ~93 ~0 ~127 stone_stairs 3  
fill ~94 ~0 ~1 ~94 ~4 ~1 log 12  
fill ~94 ~0 ~2 ~94 ~2 ~2 stained_hardened_clay 13  
fill ~94 ~0 ~126 ~94 ~2 ~126 stained_hardened_clay 13  
fill ~94 ~0 ~127 ~94 ~4 ~127 log 12 
setblock ~95 ~0 ~1 stone_stairs 2 
setblock ~95 ~0 ~2 stained_hardened_clay 5 
setblock ~95 ~0 ~64 redstone_block 0 
setblock ~95 ~0 ~126 stained_hardened_clay 5 
setblock ~95 ~0 ~127 stone_stairs 3 
setblock ~96 ~0 ~1 stone_slab 5  
fill ~96 ~0 ~2 ~98 ~0 ~2 stonebrick 0 
setblock ~96 ~0 ~3 stained_hardened_clay 13  
fill ~96 ~0 ~64 ~125 ~0 ~64 stonebrick 0 
setblock ~96 ~0 ~125 stained_hardened_clay 13  
fill ~96 ~0 ~126 ~98 ~0 ~126 stonebrick 0 
setblock ~96 ~0 ~127 stone_slab 5 
setblock ~97 ~0 ~1 stonebrick 3  
fill ~97 ~0 ~3 ~97 ~4 ~3 log 12  
fill ~97 ~0 ~125 ~97 ~4 ~125 log 12 
setblock ~97 ~0 ~127 stonebrick 3 
setblock ~98 ~0 ~1 stone_slab 5 
setblock ~98 ~0 ~3 stained_hardened_clay 13 
setblock ~98 ~0 ~125 stained_hardened_clay 13 
setblock ~98 ~0 ~127 stone_slab 5 
setblock ~99 ~0 ~1 stone_stairs 2 
setblock ~99 ~0 ~2 stained_hardened_clay 5  
fill ~99 ~0 ~3 ~101 ~0 ~3 stonebrick 0  
fill ~99 ~0 ~125 ~101 ~0 ~125 stonebrick 0 
setblock ~99 ~0 ~126 stained_hardened_clay 5 
setblock ~99 ~0 ~127 stone_stairs 3  
fill ~100 ~0 ~1 ~100 ~4 ~1 log 12  
fill ~100 ~0 ~2 ~100 ~2 ~2 stained_hardened_clay 13  
fill ~100 ~0 ~126 ~100 ~2 ~126 stained_hardened_clay 13  
fill ~100 ~0 ~127 ~100 ~4 ~127 log 12 
setblock ~101 ~0 ~1 stone_stairs 2 
setblock ~101 ~0 ~2 stained_hardened_clay 5 
setblock ~101 ~0 ~126 stained_hardened_clay 5 
setblock ~101 ~0 ~127 stone_stairs 3 
setblock ~102 ~0 ~1 stone_slab 5  
fill ~102 ~0 ~2 ~104 ~0 ~2 stonebrick 0 
setblock ~102 ~0 ~3 stained_hardened_clay 13 
setblock ~102 ~0 ~125 stained_hardened_clay 13  
fill ~102 ~0 ~126 ~104 ~0 ~126 stonebrick 0 
setblock ~102 ~0 ~127 stone_slab 5 
setblock ~103 ~0 ~1 stonebrick 3  
fill ~103 ~0 ~3 ~103 ~4 ~3 log 12  
fill ~103 ~0 ~125 ~103 ~4 ~125 log 12 
setblock ~103 ~0 ~127 stonebrick 3 
setblock ~104 ~0 ~1 stone_slab 5 
setblock ~104 ~0 ~3 stained_hardened_clay 13 
setblock ~104 ~0 ~125 stained_hardened_clay 13 
setblock ~104 ~0 ~127 stone_slab 5 
setblock ~105 ~0 ~1 stone_stairs 2 
setblock ~105 ~0 ~2 stained_hardened_clay 5  
fill ~105 ~0 ~3 ~107 ~0 ~3 stonebrick 0  
fill ~105 ~0 ~125 ~107 ~0 ~125 stonebrick 0 
setblock ~105 ~0 ~126 stained_hardened_clay 5 
setblock ~105 ~0 ~127 stone_stairs 3  
fill ~106 ~0 ~1 ~106 ~4 ~1 log 12  
fill ~106 ~0 ~2 ~106 ~2 ~2 stained_hardened_clay 13  
fill ~106 ~0 ~126 ~106 ~2 ~126 stained_hardened_clay 13  
fill ~106 ~0 ~127 ~106 ~4 ~127 log 12 
setblock ~107 ~0 ~1 stone_stairs 2 
setblock ~107 ~0 ~2 stained_hardened_clay 5 
setblock ~107 ~0 ~126 stained_hardened_clay 5 
setblock ~107 ~0 ~127 stone_stairs 3 
setblock ~108 ~0 ~1 stone_slab 5  
fill ~108 ~0 ~2 ~110 ~0 ~2 stonebrick 0 
setblock ~108 ~0 ~3 stained_hardened_clay 13 
setblock ~108 ~0 ~125 stained_hardened_clay 13  
fill ~108 ~0 ~126 ~110 ~0 ~126 stonebrick 0 
setblock ~108 ~0 ~127 stone_slab 5 
setblock ~109 ~0 ~1 stonebrick 3  
fill ~109 ~0 ~3 ~109 ~4 ~3 log 12  
fill ~109 ~0 ~125 ~109 ~4 ~125 log 12 
setblock ~109 ~0 ~127 stonebrick 3 
setblock ~110 ~0 ~1 stone_slab 5 
setblock ~110 ~0 ~3 stained_hardened_clay 13 
setblock ~110 ~0 ~125 stained_hardened_clay 13 
setblock ~110 ~0 ~127 stone_slab 5 
setblock ~111 ~0 ~1 stone_stairs 2 
setblock ~111 ~0 ~2 stained_hardened_clay 5  
fill ~111 ~0 ~3 ~113 ~0 ~3 stonebrick 0  
fill ~111 ~0 ~125 ~113 ~0 ~125 stonebrick 0 
setblock ~111 ~0 ~126 stained_hardened_clay 5 
setblock ~111 ~0 ~127 stone_stairs 3  
fill ~112 ~0 ~1 ~112 ~4 ~1 log 12  
fill ~112 ~0 ~2 ~112 ~2 ~2 stained_hardened_clay 13  
fill ~112 ~0 ~126 ~112 ~2 ~126 stained_hardened_clay 13  
fill ~112 ~0 ~127 ~112 ~4 ~127 log 12 
setblock ~113 ~0 ~1 stone_stairs 2 
setblock ~113 ~0 ~2 stained_hardened_clay 5 
setblock ~113 ~0 ~126 stained_hardened_clay 5 
setblock ~113 ~0 ~127 stone_stairs 3 
setblock ~114 ~0 ~1 stone_slab 5  
fill ~114 ~0 ~2 ~116 ~0 ~2 stonebrick 0 
setblock ~114 ~0 ~3 stained_hardened_clay 13 
setblock ~114 ~0 ~125 stained_hardened_clay 13  
fill ~114 ~0 ~126 ~116 ~0 ~126 stonebrick 0 
setblock ~114 ~0 ~127 stone_slab 5 
setblock ~115 ~0 ~1 stonebrick 3  
fill ~115 ~0 ~3 ~115 ~4 ~3 log 12  
fill ~115 ~0 ~125 ~115 ~4 ~125 log 12 
setblock ~115 ~0 ~127 stonebrick 3 
setblock ~116 ~0 ~1 stone_slab 5 
setblock ~116 ~0 ~3 stained_hardened_clay 13 
setblock ~116 ~0 ~125 stained_hardened_clay 13 
setblock ~116 ~0 ~127 stone_slab 5 
setblock ~117 ~0 ~1 stone_stairs 2 
setblock ~117 ~0 ~2 stained_hardened_clay 5  
fill ~117 ~0 ~3 ~119 ~0 ~3 stonebrick 0  
fill ~117 ~0 ~125 ~119 ~0 ~125 stonebrick 0 
setblock ~117 ~0 ~126 stained_hardened_clay 5 
setblock ~117 ~0 ~127 stone_stairs 3  
fill ~118 ~0 ~1 ~118 ~4 ~1 log 12  
fill ~118 ~0 ~2 ~118 ~2 ~2 stained_hardened_clay 13  
fill ~118 ~0 ~126 ~118 ~2 ~126 stained_hardened_clay 13  
fill ~118 ~0 ~127 ~118 ~4 ~127 log 12 
setblock ~119 ~0 ~1 stone_stairs 2 
setblock ~119 ~0 ~2 stained_hardened_clay 5 
setblock ~119 ~0 ~126 stained_hardened_clay 5 
setblock ~119 ~0 ~127 stone_stairs 3 
setblock ~120 ~0 ~1 stone_slab 5  
fill ~120 ~0 ~2 ~122 ~0 ~2 stonebrick 0 
setblock ~120 ~0 ~3 stained_hardened_clay 13 
setblock ~120 ~0 ~125 stained_hardened_clay 13  
fill ~120 ~0 ~126 ~122 ~0 ~126 stonebrick 0 
setblock ~120 ~0 ~127 stone_slab 5 
setblock ~121 ~0 ~1 stonebrick 3  
fill ~121 ~0 ~3 ~121 ~4 ~3 log 12  
fill ~121 ~0 ~125 ~121 ~4 ~125 log 12 
setblock ~121 ~0 ~127 stonebrick 3 
setblock ~122 ~0 ~1 stone_slab 5 
setblock ~122 ~0 ~3 stained_hardened_clay 13 
setblock ~122 ~0 ~125 stained_hardened_clay 13 
setblock ~122 ~0 ~127 stone_slab 5 
setblock ~123 ~0 ~1 stone_stairs 2 
setblock ~123 ~0 ~2 stained_hardened_clay 5  
fill ~123 ~0 ~3 ~125 ~0 ~3 stonebrick 0  
fill ~123 ~0 ~125 ~125 ~0 ~125 stonebrick 0 
setblock ~123 ~0 ~126 stained_hardened_clay 5 
setblock ~123 ~0 ~127 stone_stairs 3  
fill ~124 ~0 ~1 ~124 ~4 ~1 log 12  
fill ~124 ~0 ~2 ~126 ~0 ~2 stained_hardened_clay 13  
fill ~124 ~0 ~126 ~124 ~2 ~126 stonebrick 0  
fill ~124 ~0 ~127 ~124 ~4 ~127 log 12  
fill ~125 ~0 ~1 ~126 ~0 ~1 stone_slab 5 
setblock ~125 ~0 ~6 stained_hardened_clay 13  
fill ~125 ~0 ~7 ~125 ~4 ~7 log 12 
setblock ~125 ~0 ~8 stained_hardened_clay 13 
setblock ~125 ~0 ~12 stained_hardened_clay 13  
fill ~125 ~0 ~13 ~125 ~4 ~13 log 12 
setblock ~125 ~0 ~14 stained_hardened_clay 13 
setblock ~125 ~0 ~18 stained_hardened_clay 13  
fill ~125 ~0 ~19 ~125 ~4 ~19 log 12 
setblock ~125 ~0 ~20 stained_hardened_clay 13 
setblock ~125 ~0 ~24 stained_hardened_clay 13  
fill ~125 ~0 ~25 ~125 ~4 ~25 log 12 
setblock ~125 ~0 ~26 stained_hardened_clay 13 
setblock ~125 ~0 ~30 stained_hardened_clay 13  
fill ~125 ~0 ~31 ~125 ~4 ~31 log 12 
setblock ~125 ~0 ~32 stained_hardened_clay 13 
setblock ~125 ~0 ~36 stained_hardened_clay 13  
fill ~125 ~0 ~37 ~125 ~4 ~37 log 12 
setblock ~125 ~0 ~38 stained_hardened_clay 13 
setblock ~125 ~0 ~42 stained_hardened_clay 13  
fill ~125 ~0 ~43 ~125 ~4 ~43 log 12 
setblock ~125 ~0 ~44 stained_hardened_clay 13 
setblock ~125 ~0 ~48 stained_hardened_clay 13  
fill ~125 ~0 ~49 ~125 ~4 ~49 log 12 
setblock ~125 ~0 ~50 stained_hardened_clay 13 
setblock ~125 ~0 ~54 stained_hardened_clay 13  
fill ~125 ~0 ~55 ~125 ~4 ~55 log 12 
setblock ~125 ~0 ~56 stained_hardened_clay 13 
setblock ~125 ~0 ~60 stained_hardened_clay 13  
fill ~125 ~0 ~61 ~125 ~4 ~61 log 12 
setblock ~125 ~0 ~62 stained_hardened_clay 13 
setblock ~125 ~0 ~66 stained_hardened_clay 13  
fill ~125 ~0 ~67 ~125 ~4 ~67 log 12 
setblock ~125 ~0 ~68 stained_hardened_clay 13 
setblock ~125 ~0 ~72 stained_hardened_clay 13  
fill ~125 ~0 ~73 ~125 ~4 ~73 log 12 
setblock ~125 ~0 ~74 stained_hardened_clay 13 
setblock ~125 ~0 ~78 stained_hardened_clay 13  
fill ~125 ~0 ~79 ~125 ~4 ~79 log 12 
setblock ~125 ~0 ~80 stained_hardened_clay 13 
setblock ~125 ~0 ~84 stained_hardened_clay 13  
fill ~125 ~0 ~85 ~125 ~4 ~85 log 12 
setblock ~125 ~0 ~86 stained_hardened_clay 13 
setblock ~125 ~0 ~90 stained_hardened_clay 13  
fill ~125 ~0 ~91 ~125 ~4 ~91 log 12 
setblock ~125 ~0 ~92 stained_hardened_clay 13 
setblock ~125 ~0 ~96 stained_hardened_clay 13  
fill ~125 ~0 ~97 ~125 ~4 ~97 log 12 
setblock ~125 ~0 ~98 stained_hardened_clay 13 
setblock ~125 ~0 ~102 stained_hardened_clay 13  
fill ~125 ~0 ~103 ~125 ~4 ~103 log 12 
setblock ~125 ~0 ~104 stained_hardened_clay 13 
setblock ~125 ~0 ~108 stained_hardened_clay 13  
fill ~125 ~0 ~109 ~125 ~4 ~109 log 12 
setblock ~125 ~0 ~110 stained_hardened_clay 13 
setblock ~125 ~0 ~114 stained_hardened_clay 13  
fill ~125 ~0 ~115 ~125 ~4 ~115 log 12 
setblock ~125 ~0 ~116 stained_hardened_clay 13 
setblock ~125 ~0 ~120 stained_hardened_clay 13  
fill ~125 ~0 ~121 ~125 ~4 ~121 log 12 
setblock ~125 ~0 ~122 stained_hardened_clay 13  
fill ~125 ~0 ~126 ~126 ~0 ~126 stained_hardened_clay 13  
fill ~125 ~0 ~127 ~126 ~0 ~127 stone_slab 5 
setblock ~126 ~0 ~3 stained_hardened_clay 13 
setblock ~126 ~0 ~5 stained_hardened_clay 5  
fill ~126 ~0 ~6 ~126 ~0 ~8 stonebrick 0 
setblock ~126 ~0 ~9 stained_hardened_clay 5  
fill ~126 ~0 ~10 ~126 ~2 ~10 stained_hardened_clay 13 
setblock ~126 ~0 ~11 stained_hardened_clay 5  
fill ~126 ~0 ~12 ~126 ~0 ~14 stonebrick 0 
setblock ~126 ~0 ~15 stained_hardened_clay 5  
fill ~126 ~0 ~16 ~126 ~2 ~16 stained_hardened_clay 13 
setblock ~126 ~0 ~17 stained_hardened_clay 5  
fill ~126 ~0 ~18 ~126 ~0 ~20 stonebrick 0 
setblock ~126 ~0 ~21 stained_hardened_clay 5  
fill ~126 ~0 ~22 ~126 ~2 ~22 stained_hardened_clay 13 
setblock ~126 ~0 ~23 stained_hardened_clay 5  
fill ~126 ~0 ~24 ~126 ~0 ~26 stonebrick 0 
setblock ~126 ~0 ~27 stained_hardened_clay 5  
fill ~126 ~0 ~28 ~126 ~2 ~28 stained_hardened_clay 13 
setblock ~126 ~0 ~29 stained_hardened_clay 5  
fill ~126 ~0 ~30 ~126 ~0 ~32 stonebrick 0 
setblock ~126 ~0 ~33 stained_hardened_clay 5  
fill ~126 ~0 ~34 ~126 ~2 ~34 stained_hardened_clay 13 
setblock ~126 ~0 ~35 stained_hardened_clay 5  
fill ~126 ~0 ~36 ~126 ~0 ~38 stonebrick 0 
setblock ~126 ~0 ~39 stained_hardened_clay 5  
fill ~126 ~0 ~40 ~126 ~2 ~40 stained_hardened_clay 13 
setblock ~126 ~0 ~41 stained_hardened_clay 5  
fill ~126 ~0 ~42 ~126 ~0 ~44 stonebrick 0 
setblock ~126 ~0 ~45 stained_hardened_clay 5  
fill ~126 ~0 ~46 ~126 ~2 ~46 stained_hardened_clay 13 
setblock ~126 ~0 ~47 stained_hardened_clay 5  
fill ~126 ~0 ~48 ~126 ~0 ~50 stonebrick 0 
setblock ~126 ~0 ~51 stained_hardened_clay 5  
fill ~126 ~0 ~52 ~126 ~2 ~52 stained_hardened_clay 13 
setblock ~126 ~0 ~53 stained_hardened_clay 5  
fill ~126 ~0 ~54 ~126 ~0 ~56 stonebrick 0 
setblock ~126 ~0 ~57 stained_hardened_clay 5  
fill ~126 ~0 ~58 ~126 ~2 ~58 stained_hardened_clay 13 
setblock ~126 ~0 ~59 stained_hardened_clay 5  
fill ~126 ~0 ~60 ~126 ~0 ~62 stonebrick 0 
setblock ~126 ~0 ~63 stained_hardened_clay 5  
fill ~126 ~0 ~64 ~126 ~2 ~64 stained_hardened_clay 13 
setblock ~126 ~0 ~65 stained_hardened_clay 5  
fill ~126 ~0 ~66 ~126 ~0 ~68 stonebrick 0 
setblock ~126 ~0 ~69 stained_hardened_clay 5  
fill ~126 ~0 ~70 ~126 ~2 ~70 stained_hardened_clay 13 
setblock ~126 ~0 ~71 stained_hardened_clay 5  
fill ~126 ~0 ~72 ~126 ~0 ~74 stonebrick 0 
setblock ~126 ~0 ~75 stained_hardened_clay 5  
fill ~126 ~0 ~76 ~126 ~2 ~76 stained_hardened_clay 13 
setblock ~126 ~0 ~77 stained_hardened_clay 5  
fill ~126 ~0 ~78 ~126 ~0 ~80 stonebrick 0 
setblock ~126 ~0 ~81 stained_hardened_clay 5  
fill ~126 ~0 ~82 ~126 ~2 ~82 stained_hardened_clay 13 
setblock ~126 ~0 ~83 stained_hardened_clay 5  
fill ~126 ~0 ~84 ~126 ~0 ~86 stonebrick 0 
setblock ~126 ~0 ~87 stained_hardened_clay 5  
fill ~126 ~0 ~88 ~126 ~2 ~88 stained_hardened_clay 13 
setblock ~126 ~0 ~89 stained_hardened_clay 5  
fill ~126 ~0 ~90 ~126 ~0 ~92 stonebrick 0 
setblock ~126 ~0 ~93 stained_hardened_clay 5  
fill ~126 ~0 ~94 ~126 ~2 ~94 stained_hardened_clay 13 
setblock ~126 ~0 ~95 stained_hardened_clay 5  
fill ~126 ~0 ~96 ~126 ~0 ~98 stonebrick 0 
setblock ~126 ~0 ~99 stained_hardened_clay 5  
fill ~126 ~0 ~100 ~126 ~2 ~100 stained_hardened_clay 13 
setblock ~126 ~0 ~101 stained_hardened_clay 5  
fill ~126 ~0 ~102 ~126 ~0 ~104 stonebrick 0 
setblock ~126 ~0 ~105 stained_hardened_clay 5  
fill ~126 ~0 ~106 ~126 ~2 ~106 stained_hardened_clay 13 
setblock ~126 ~0 ~107 stained_hardened_clay 5  
fill ~126 ~0 ~108 ~126 ~0 ~110 stonebrick 0 
setblock ~126 ~0 ~111 stained_hardened_clay 5  
fill ~126 ~0 ~112 ~126 ~2 ~112 stained_hardened_clay 13 
setblock ~126 ~0 ~113 stained_hardened_clay 5  
fill ~126 ~0 ~114 ~126 ~0 ~116 stonebrick 0 
setblock ~126 ~0 ~117 stained_hardened_clay 5  
fill ~126 ~0 ~118 ~126 ~2 ~118 stained_hardened_clay 13 
setblock ~126 ~0 ~119 stained_hardened_clay 5  
fill ~126 ~0 ~120 ~126 ~0 ~122 stonebrick 0 
setblock ~126 ~0 ~123 stained_hardened_clay 5  
fill ~126 ~0 ~124 ~126 ~2 ~124 stained_hardened_clay 13  
fill ~126 ~0 ~125 ~126 ~0 ~124 stained_hardened_clay 13  
fill ~127 ~0 ~1 ~127 ~4 ~1 log 12  
fill ~127 ~0 ~2 ~127 ~0 ~3 stone_slab 5  
fill ~127 ~0 ~4 ~127 ~4 ~4 log 12 
setblock ~127 ~0 ~5 stone_stairs 1 
setblock ~127 ~0 ~6 stone_slab 5 
setblock ~127 ~0 ~7 stonebrick 3 
setblock ~127 ~0 ~8 stone_slab 5 
setblock ~127 ~0 ~9 stone_stairs 1  
fill ~127 ~0 ~10 ~127 ~4 ~10 log 12 
setblock ~127 ~0 ~11 stone_stairs 1 
setblock ~127 ~0 ~12 stone_slab 5 
setblock ~127 ~0 ~13 stonebrick 3 
setblock ~127 ~0 ~14 stone_slab 5 
setblock ~127 ~0 ~15 stone_stairs 1  
fill ~127 ~0 ~16 ~127 ~4 ~16 log 12 
setblock ~127 ~0 ~17 stone_stairs 1 
setblock ~127 ~0 ~18 stone_slab 5 
setblock ~127 ~0 ~19 stonebrick 3 
setblock ~127 ~0 ~20 stone_slab 5 
setblock ~127 ~0 ~21 stone_stairs 1  
fill ~127 ~0 ~22 ~127 ~4 ~22 log 12 
setblock ~127 ~0 ~23 stone_stairs 1 
setblock ~127 ~0 ~24 stone_slab 5 
setblock ~127 ~0 ~25 stonebrick 3 
setblock ~127 ~0 ~26 stone_slab 5 
setblock ~127 ~0 ~27 stone_stairs 1  
fill ~127 ~0 ~28 ~127 ~4 ~28 log 12 
setblock ~127 ~0 ~29 stone_stairs 1 
setblock ~127 ~0 ~30 stone_slab 5 
setblock ~127 ~0 ~31 stonebrick 3 
setblock ~127 ~0 ~32 stone_slab 5 
setblock ~127 ~0 ~33 stone_stairs 1  
fill ~127 ~0 ~34 ~127 ~4 ~34 log 12 
setblock ~127 ~0 ~35 stone_stairs 1 
setblock ~127 ~0 ~36 stone_slab 5 
setblock ~127 ~0 ~37 stonebrick 3 
setblock ~127 ~0 ~38 stone_slab 5 
setblock ~127 ~0 ~39 stone_stairs 1  
fill ~127 ~0 ~40 ~127 ~4 ~40 log 12 
setblock ~127 ~0 ~41 stone_stairs 1 
setblock ~127 ~0 ~42 stone_slab 5 
setblock ~127 ~0 ~43 stonebrick 3 
setblock ~127 ~0 ~44 stone_slab 5 
setblock ~127 ~0 ~45 stone_stairs 1  
fill ~127 ~0 ~46 ~127 ~4 ~46 log 12 
setblock ~127 ~0 ~47 stone_stairs 1 
setblock ~127 ~0 ~48 stone_slab 5 
setblock ~127 ~0 ~49 stonebrick 3 
setblock ~127 ~0 ~50 stone_slab 5 
setblock ~127 ~0 ~51 stone_stairs 1  
fill ~127 ~0 ~52 ~127 ~4 ~52 log 12 
setblock ~127 ~0 ~53 stone_stairs 1 
setblock ~127 ~0 ~54 stone_slab 5 
setblock ~127 ~0 ~55 stonebrick 3 
setblock ~127 ~0 ~56 stone_slab 5 
setblock ~127 ~0 ~57 stone_stairs 1  
fill ~127 ~0 ~58 ~127 ~4 ~58 log 12 
setblock ~127 ~0 ~59 stone_stairs 1 
setblock ~127 ~0 ~60 stone_slab 5 
setblock ~127 ~0 ~61 stonebrick 3 
setblock ~127 ~0 ~62 stone_slab 5 
setblock ~127 ~0 ~63 stone_stairs 1  
fill ~127 ~0 ~64 ~127 ~4 ~64 log 12 
setblock ~127 ~0 ~65 stone_stairs 1 
setblock ~127 ~0 ~66 stone_slab 5 
setblock ~127 ~0 ~67 stonebrick 3 
setblock ~127 ~0 ~68 stone_slab 5 
setblock ~127 ~0 ~69 stone_stairs 1  
fill ~127 ~0 ~70 ~127 ~4 ~70 log 12 
setblock ~127 ~0 ~71 stone_stairs 1 
setblock ~127 ~0 ~72 stone_slab 5 
setblock ~127 ~0 ~73 stonebrick 3 
setblock ~127 ~0 ~74 stone_slab 5 
setblock ~127 ~0 ~75 stone_stairs 1  
fill ~127 ~0 ~76 ~127 ~4 ~76 log 12 
setblock ~127 ~0 ~77 stone_stairs 1 
setblock ~127 ~0 ~78 stone_slab 5 
setblock ~127 ~0 ~79 stonebrick 3 
setblock ~127 ~0 ~80 stone_slab 5 
setblock ~127 ~0 ~81 stone_stairs 1  
fill ~127 ~0 ~82 ~127 ~4 ~82 log 12 
setblock ~127 ~0 ~83 stone_stairs 1 
setblock ~127 ~0 ~84 stone_slab 5 
setblock ~127 ~0 ~85 stonebrick 3 
setblock ~127 ~0 ~86 stone_slab 5 
setblock ~127 ~0 ~87 stone_stairs 1  
fill ~127 ~0 ~88 ~127 ~4 ~88 log 12 
setblock ~127 ~0 ~89 stone_stairs 1 
setblock ~127 ~0 ~90 stone_slab 5 
setblock ~127 ~0 ~91 stonebrick 3 
setblock ~127 ~0 ~92 stone_slab 5 
setblock ~127 ~0 ~93 stone_stairs 1  
fill ~127 ~0 ~94 ~127 ~4 ~94 log 12 
setblock ~127 ~0 ~95 stone_stairs 1 
setblock ~127 ~0 ~96 stone_slab 5 
setblock ~127 ~0 ~97 stonebrick 3 
setblock ~127 ~0 ~98 stone_slab 5 
setblock ~127 ~0 ~99 stone_stairs 1  
fill ~127 ~0 ~100 ~127 ~4 ~100 log 12 
setblock ~127 ~0 ~101 stone_stairs 1 
setblock ~127 ~0 ~102 stone_slab 5 
setblock ~127 ~0 ~103 stonebrick 3 
setblock ~127 ~0 ~104 stone_slab 5 
setblock ~127 ~0 ~105 stone_stairs 1  
fill ~127 ~0 ~106 ~127 ~4 ~106 log 12 
setblock ~127 ~0 ~107 stone_stairs 1 
setblock ~127 ~0 ~108 stone_slab 5 
setblock ~127 ~0 ~109 stonebrick 3 
setblock ~127 ~0 ~110 stone_slab 5 
setblock ~127 ~0 ~111 stone_stairs 1  
fill ~127 ~0 ~112 ~127 ~4 ~112 log 12 
setblock ~127 ~0 ~113 stone_stairs 1 
setblock ~127 ~0 ~114 stone_slab 5 
setblock ~127 ~0 ~115 stonebrick 3 
setblock ~127 ~0 ~116 stone_slab 5 
setblock ~127 ~0 ~117 stone_stairs 1  
fill ~127 ~0 ~118 ~127 ~4 ~118 log 12 
setblock ~127 ~0 ~119 stone_stairs 1 
setblock ~127 ~0 ~120 stone_slab 5 
setblock ~127 ~0 ~121 stonebrick 3 
setblock ~127 ~0 ~122 stone_slab 5 
setblock ~127 ~0 ~123 stone_stairs 1  
fill ~127 ~0 ~124 ~127 ~4 ~124 log 12  
fill ~127 ~0 ~125 ~127 ~0 ~126 stone_slab 5  
fill ~127 ~0 ~127 ~127 ~4 ~127 log 12  
fill ~1 ~1 ~2 ~1 ~3 ~2 barrier 0  
fill ~1 ~1 ~3 ~1 ~3 ~3 barrier 0  
fill ~1 ~1 ~5 ~1 ~3 ~5 barrier 0  
fill ~1 ~1 ~6 ~1 ~3 ~6 barrier 0  
fill ~1 ~1 ~7 ~1 ~3 ~7 cobblestone_wall 0  
fill ~1 ~1 ~8 ~1 ~3 ~8 barrier 0  
fill ~1 ~1 ~9 ~1 ~3 ~9 barrier 0  
fill ~1 ~1 ~11 ~1 ~3 ~11 barrier 0  
fill ~1 ~1 ~12 ~1 ~3 ~12 barrier 0  
fill ~1 ~1 ~13 ~1 ~3 ~13 cobblestone_wall 0  
fill ~1 ~1 ~14 ~1 ~3 ~14 barrier 0  
fill ~1 ~1 ~15 ~1 ~3 ~15 barrier 0  
fill ~1 ~1 ~17 ~1 ~3 ~17 barrier 0  
fill ~1 ~1 ~18 ~1 ~3 ~18 barrier 0  
fill ~1 ~1 ~19 ~1 ~3 ~19 cobblestone_wall 0   
fill ~1 ~1 ~20 ~1 ~3 ~20 barrier 0  
fill ~1 ~1 ~21 ~1 ~3 ~21 barrier 0  
fill ~1 ~1 ~23 ~1 ~3 ~23 barrier 0  
fill ~1 ~1 ~24 ~1 ~3 ~24 barrier 0  
fill ~1 ~1 ~25 ~1 ~3 ~25 cobblestone_wall 0  
fill ~1 ~1 ~26 ~1 ~3 ~26 barrier 0  
fill ~1 ~1 ~27 ~1 ~3 ~27 barrier 0  
fill ~1 ~1 ~29 ~1 ~3 ~29 barrier 0  
fill ~1 ~1 ~30 ~1 ~3 ~30 barrier 0  
fill ~1 ~1 ~31 ~1 ~3 ~31 cobblestone_wall 0  
fill ~1 ~1 ~32 ~1 ~3 ~32 barrier 0  
fill ~1 ~1 ~33 ~1 ~3 ~33 barrier 0  
fill ~1 ~1 ~35 ~1 ~3 ~35 barrier 0  
fill ~1 ~1 ~36 ~1 ~3 ~36 barrier 0  
fill ~1 ~1 ~37 ~1 ~3 ~37 cobblestone_wall 0  
fill ~1 ~1 ~38 ~1 ~3 ~38 barrier 0  
fill ~1 ~1 ~39 ~1 ~3 ~39 barrier 0  
fill ~1 ~1 ~41 ~1 ~3 ~41 barrier 0  
fill ~1 ~1 ~42 ~1 ~3 ~42 barrier 0  
fill ~1 ~1 ~43 ~1 ~3 ~43 cobblestone_wall 0  
fill ~1 ~1 ~44 ~1 ~3 ~44 barrier 0  
fill ~1 ~1 ~45 ~1 ~3 ~45 barrier 0  
fill ~1 ~1 ~47 ~1 ~3 ~47 barrier 0  
fill ~1 ~1 ~48 ~1 ~3 ~48 barrier 0  
fill ~1 ~1 ~49 ~1 ~3 ~49 cobblestone_wall 0  
fill ~1 ~1 ~50 ~1 ~3 ~50 barrier 0  
fill ~1 ~1 ~51 ~1 ~3 ~51 barrier 0  
fill ~1 ~1 ~53 ~1 ~3 ~53 barrier 0  
fill ~1 ~1 ~54 ~1 ~3 ~54 barrier 0  
fill ~1 ~1 ~55 ~1 ~3 ~55 cobblestone_wall 0  
fill ~1 ~1 ~56 ~1 ~3 ~56 barrier 0  
fill ~1 ~1 ~57 ~1 ~3 ~57 barrier 0  
fill ~1 ~1 ~59 ~1 ~3 ~59 barrier 0  
fill ~1 ~1 ~60 ~1 ~3 ~60 barrier 0  
fill ~1 ~1 ~61 ~1 ~3 ~61 cobblestone_wall 0  
fill ~1 ~1 ~62 ~1 ~3 ~62 barrier 0  
fill ~1 ~1 ~63 ~1 ~3 ~63 barrier 0  
fill ~1 ~1 ~65 ~1 ~3 ~65 barrier 0  
fill ~1 ~1 ~66 ~1 ~3 ~66 barrier 0  
fill ~1 ~1 ~67 ~1 ~3 ~67 cobblestone_wall 0  
fill ~1 ~1 ~68 ~1 ~3 ~68 barrier 0  
fill ~1 ~1 ~69 ~1 ~3 ~69 barrier 0  
fill ~1 ~1 ~71 ~1 ~3 ~71 barrier 0  
fill ~1 ~1 ~72 ~1 ~3 ~72 barrier 0  
fill ~1 ~1 ~73 ~1 ~3 ~73 cobblestone_wall 0  
fill ~1 ~1 ~74 ~1 ~3 ~74 barrier 0  
fill ~1 ~1 ~75 ~1 ~3 ~75 barrier 0  
fill ~1 ~1 ~77 ~1 ~3 ~77 barrier 0  
fill ~1 ~1 ~78 ~1 ~3 ~78 barrier 0  
fill ~1 ~1 ~79 ~1 ~3 ~79 cobblestone_wall 0  
fill ~1 ~1 ~80 ~1 ~3 ~80 barrier 0  
fill ~1 ~1 ~81 ~1 ~3 ~81 barrier 0  
fill ~1 ~1 ~83 ~1 ~3 ~83 barrier 0  
fill ~1 ~1 ~84 ~1 ~3 ~84 barrier 0  
fill ~1 ~1 ~85 ~1 ~3 ~85 cobblestone_wall 0  
fill ~1 ~1 ~86 ~1 ~3 ~86 barrier 0  
fill ~1 ~1 ~87 ~1 ~3 ~87 barrier 0  
fill ~1 ~1 ~89 ~1 ~3 ~89 barrier 0  
fill ~1 ~1 ~90 ~1 ~3 ~90 barrier 0  
fill ~1 ~1 ~91 ~1 ~3 ~91 cobblestone_wall 0  
fill ~1 ~1 ~92 ~1 ~3 ~92 barrier 0  
fill ~1 ~1 ~93 ~1 ~3 ~93 barrier 0  
fill ~1 ~1 ~95 ~1 ~3 ~95 barrier 0  
fill ~1 ~1 ~96 ~1 ~3 ~96 barrier 0  
fill ~1 ~1 ~97 ~1 ~3 ~97 cobblestone_wall 0  
fill ~1 ~1 ~98 ~1 ~3 ~98 barrier 0  
fill ~1 ~1 ~99 ~1 ~3 ~99 barrier 0  
fill ~1 ~1 ~101 ~1 ~3 ~101 barrier 0  
fill ~1 ~1 ~102 ~1 ~3 ~102 barrier 0  
fill ~1 ~1 ~103 ~1 ~3 ~103 cobblestone_wall 0  
fill ~1 ~1 ~104 ~1 ~3 ~104 barrier 0  
fill ~1 ~1 ~105 ~1 ~3 ~105 barrier 0  
fill ~1 ~1 ~107 ~1 ~3 ~107 barrier 0  
fill ~1 ~1 ~108 ~1 ~3 ~108 barrier 0  
fill ~1 ~1 ~109 ~1 ~3 ~109 cobblestone_wall 0  
fill ~1 ~1 ~110 ~1 ~3 ~110 barrier 0  
fill ~1 ~1 ~111 ~1 ~3 ~111 barrier 0  
fill ~1 ~1 ~113 ~1 ~3 ~113 barrier 0  
fill ~1 ~1 ~114 ~1 ~3 ~114 barrier 0  
fill ~1 ~1 ~115 ~1 ~3 ~115 cobblestone_wall 0  
fill ~1 ~1 ~116 ~1 ~3 ~116 barrier 0  
fill ~1 ~1 ~117 ~1 ~3 ~117 barrier 0  
fill ~1 ~1 ~119 ~1 ~3 ~119 barrier 0  
fill ~1 ~1 ~120 ~1 ~3 ~120 barrier 0  
fill ~1 ~1 ~121 ~1 ~3 ~121 cobblestone_wall 0  
fill ~1 ~1 ~122 ~1 ~3 ~122 barrier 0  
fill ~1 ~1 ~123 ~1 ~3 ~123 barrier 0  
fill ~1 ~1 ~125 ~1 ~3 ~125 barrier 0  
fill ~1 ~1 ~126 ~1 ~3 ~126 barrier 0  
fill ~2 ~1 ~1 ~3 ~1 ~1 barrier 0  
fill ~2 ~1 ~2 ~2 ~0 ~2 stained_hardened_clay 13  
fill ~2 ~1 ~3 ~2 ~2 ~3 stained_hardened_clay 5  
fill ~2 ~1 ~4 ~2 ~2 ~4 stained_hardened_clay 13  
fill ~2 ~1 ~5 ~3 ~1 ~5 stained_hardened_clay 13  
fill ~2 ~1 ~6 ~2 ~2 ~6 stained_glass_pane 13  
fill ~2 ~1 ~7 ~2 ~3 ~7 log 12  
fill ~2 ~1 ~8 ~2 ~2 ~8 stained_glass_pane 13  
fill ~2 ~1 ~9 ~3 ~1 ~9 stained_hardened_clay 13  
fill ~2 ~1 ~11 ~3 ~1 ~11 stained_hardened_clay 13  
fill ~2 ~1 ~12 ~2 ~2 ~12 stained_glass_pane 13  
fill ~2 ~1 ~13 ~2 ~3 ~13 log 12  
fill ~2 ~1 ~14 ~2 ~2 ~14 stained_glass_pane 13  
fill ~2 ~1 ~15 ~3 ~1 ~15 stained_hardened_clay 13  
fill ~2 ~1 ~17 ~3 ~1 ~17 stained_hardened_clay 13  
fill ~2 ~1 ~18 ~2 ~2 ~18 stained_glass_pane 13  
fill ~2 ~1 ~19 ~2 ~3 ~19 log 12  
fill ~2 ~1 ~20 ~2 ~2 ~20 stained_glass_pane 13  
fill ~2 ~1 ~21 ~3 ~1 ~21 stained_hardened_clay 13  
fill ~2 ~1 ~23 ~3 ~1 ~23 stained_hardened_clay 13  
fill ~2 ~1 ~24 ~2 ~2 ~24 stained_glass_pane 13  
fill ~2 ~1 ~25 ~2 ~3 ~25 log 12  
fill ~2 ~1 ~26 ~2 ~2 ~26 stained_glass_pane 13  
fill ~2 ~1 ~27 ~3 ~1 ~27 stained_hardened_clay 13  
fill ~2 ~1 ~29 ~3 ~1 ~29 stained_hardened_clay 13  
fill ~2 ~1 ~30 ~2 ~2 ~30 stained_glass_pane 13  
