setblock ~57~12~3 minecraft:spruce_stairs 6
fill ~57~13~3 ~57~13~5 minecraft:fence 1
fill ~58~10~3 ~58~10~4 minecraft:wool 13
fill ~57~11~4 ~57~11~5 minecraft:fence 1
setblock ~57~12~4 minecraft:spruce_stairs 5
setblock ~57~10~5 minecraft:fence 1
fill ~57~12~5 ~57~12~9 minecraft:planks 1
fill ~57~14~5 ~57~14~8 minecraft:fence 1
fill ~58~11~5 ~58~11~10 minecraft:wool 13
fill ~59~10~5 ~59~10~12 minecraft:wool 13
setblock ~56~12~6 minecraft:stone_button 4
fill ~57~9~6 ~57~11~6 minecraft:planks 1
setblock ~57~13~6 minecraft:trapdoor 3
fill ~58~8~6 ~59~8~6 minecraft:fence 1
setblock ~58~9~6 minecraft:fence 1
fill ~58~12~6 ~58~12~9 minecraft:wall_sign 5
fill ~59~9~6 ~59~9~7 minecraft:wool 13
setblock ~57~11~7 minecraft:spruce_stairs 4
setblock ~57~13~7 minecraft:wooden_slab 1
setblock ~58~8~7 minecraft:wool 13
setblock ~57~11~8 minecraft:spruce_stairs 7
setblock ~57~13~8 minecraft:spruce_stairs 2
fill ~57~15~8 ~57~15~11 minecraft:fence 1
fill ~59~8~8 ~59~8~10 minecraft:wool 13
fill ~60~9~8 ~60~9~10 minecraft:wool 13
setblock ~57~11~9 minecraft:wooden_slab 9
setblock ~57~13~9 minecraft:spruce_stairs 1
setblock ~57~12~10 minecraft:spruce_stairs 7
fill ~57~13~10 ~57~13~13 minecraft:planks 1
setblock ~57~14~10 minecraft:trapdoor 3
fill ~58~12~10 ~58~12~15 minecraft:wool 13
fill ~58~13~10 ~58~13~14 minecraft:wall_sign 5
fill ~19~7~11 ~22~7~11 minecraft:wooden_slab 1
setblock ~57~12~11 minecraft:spruce_stairs 6
setblock ~57~14~11 minecraft:wooden_slab 1
fill ~57~16~11 ~57~16~14 minecraft:fence 1
setblock ~58~8~11 minecraft:wool 13
fill ~59~9~11 ~59~9~12 minecraft:wool 13
fill ~59~11~11 ~59~11~15 minecraft:wool 13
fill ~16~7~12 ~18~7~12 minecraft:wooden_slab 1
fill ~19~7~12 ~22~7~12 minecraft:wool 13
setblock ~23~7~12 minecraft:wooden_slab 1
setblock ~43~28~12 minecraft:wooden_slab 1
fill ~57~8~12 ~58~8~12 minecraft:fence 1
fill ~57~9~12 ~57~10~12 minecraft:fence 1
setblock ~57~12~12 minecraft:spruce_stairs 4
setblock ~57~14~12 minecraft:spruce_stairs 2
fill ~58~7~12 ~59~7~12 minecraft:fence 1
fill ~59~8~12 ~59~8~13 minecraft:wool 13
setblock ~15~7~13 minecraft:wooden_slab 1
fill ~16~7~13 ~19~7~13 minecraft:wool 13
fill ~20~8~13 ~23~8~13 minecraft:wool 13
setblock ~23~7~13 minecraft:wooden_slab 9
setblock ~24~8~13 minecraft:wooden_slab 1
setblock ~36~19~13 minecraft:cobblestone_wall 0
fill ~36~20~13 ~36~21~13 minecraft:fence 1
setblock ~37~18~13 minecraft:stone_brick_stairs 6
fill ~37~19~13 ~37~19~15 minecraft:stonebrick 0
setblock ~37~20~13 minecraft:stone_brick_stairs 2
fill ~37~21~13 ~38~21~15 minecraft:fence 1
setblock ~38~19~13 minecraft:cobblestone_wall 0
setblock ~38~20~13 minecraft:fence 1
fill ~39~24~13 ~41~24~13 minecraft:wool 13
fill ~42~25~13 ~42~25~14 minecraft:wool 13
fill ~43~26~13 ~43~26~14 minecraft:wool 13
fill ~43~27~13 ~43~27~14 minecraft:fence 1
setblock ~43~28~13 minecraft:spruce_stairs 2
setblock ~48~19~13 minecraft:cobblestone_wall 0
fill ~48~20~13 ~48~21~13 minecraft:fence 1
setblock ~49~18~13 minecraft:stone_brick_stairs 6
fill ~49~19~13 ~49~19~15 minecraft:stonebrick 0
setblock ~49~20~13 minecraft:stone_brick_stairs 2
fill ~49~21~13 ~50~21~15 minecraft:fence 1
setblock ~50~19~13 minecraft:cobblestone_wall 0
setblock ~50~20~13 minecraft:fence 1
setblock ~56~13~13 minecraft:stone_button 4
fill ~57~10~13 ~57~12~13 minecraft:planks 1
setblock ~57~14~13 minecraft:spruce_stairs 1
setblock ~58~28~13 minecraft:wooden_slab 1
fill ~60~9~13 ~60~10~14 minecraft:wool 13
setblock ~15~7~14 minecraft:wooden_slab 9
setblock ~16~8~14 minecraft:wooden_slab 1
fill ~17~8~14 ~20~8~14 minecraft:wool 13
fill ~21~9~14 ~24~9~14 minecraft:wool 13
setblock ~24~8~14 minecraft:wooden_slab 9
setblock ~25~9~14 minecraft:wooden_slab 1
setblock ~36~18~14 minecraft:stone_brick_stairs 4
setblock ~36~19~14 minecraft:stonebrick 0
setblock ~36~20~14 minecraft:stone_brick_stairs 0
fill ~36~21~14 ~36~21~15 minecraft:fence 1
setblock ~37~18~14 minecraft:stonebrick 0
setblock ~37~20~14 minecraft:stonebrick 0
setblock ~37~22~14 minecraft:cobblestone_wall 0
setblock ~37~23~14 minecraft:fence 1
setblock ~37~24~14 minecraft:cobblestone_wall 0
setblock ~37~25~14 minecraft:fence 1
setblock ~37~26~14 minecraft:cobblestone_wall 0
setblock ~37~27~14 minecraft:fence 1
setblock ~37~28~14 minecraft:cobblestone_wall 0
setblock ~37~29~14 minecraft:stone_brick_stairs 2
setblock ~38~18~14 minecraft:stone_brick_stairs 5
setblock ~38~19~14 minecraft:stonebrick 0
setblock ~38~20~14 minecraft:stone_brick_stairs 1
fill ~40~25~14 ~41~25~14 minecraft:wool 13
setblock ~43~18~14 minecraft:stone_button 2
setblock ~43~28~14 minecraft:spruce_stairs 0
setblock ~48~18~14 minecraft:stone_brick_stairs 4
setblock ~48~19~14 minecraft:stonebrick 0
setblock ~48~20~14 minecraft:stone_brick_stairs 0
fill ~48~21~14 ~48~21~15 minecraft:fence 1
setblock ~49~18~14 minecraft:stonebrick 0
setblock ~49~20~14 minecraft:stonebrick 0
setblock ~49~22~14 minecraft:cobblestone_wall 0
setblock ~49~23~14 minecraft:fence 1
setblock ~49~24~14 minecraft:cobblestone_wall 0
setblock ~49~25~14 minecraft:fence 1
setblock ~49~26~14 minecraft:cobblestone_wall 0
setblock ~49~27~14 minecraft:fence 1
setblock ~49~28~14 minecraft:cobblestone_wall 0
setblock ~49~29~14 minecraft:stone_brick_stairs 2
setblock ~50~18~14 minecraft:stone_brick_stairs 5
setblock ~50~19~14 minecraft:stonebrick 0
setblock ~50~20~14 minecraft:stone_brick_stairs 1
fill ~54~24~14 ~56~24~14 minecraft:wool 13
fill ~57~8~14 ~58~8~14 minecraft:fence 1
fill ~57~9~14 ~57~10~14 minecraft:fence 1
setblock ~57~13~14 minecraft:spruce_stairs 4
fill ~57~14~14 ~57~14~20 minecraft:planks 1
setblock ~57~15~14 minecraft:trapdoor 3
fill ~57~17~14 ~57~17~17 minecraft:fence 1
fill ~57~25~14 ~57~25~15 minecraft:wool 13
fill ~58~7~14 ~60~7~14 minecraft:fence 1
fill ~58~26~14 ~58~26~15 minecraft:wool 13
fill ~58~27~14 ~58~27~15 minecraft:fence 1
setblock ~58~28~14 minecraft:spruce_stairs 2
fill ~60~8~14 ~60~8~17 minecraft:wool 13
setblock ~16~8~15 minecraft:wooden_slab 9
setblock ~17~9~15 minecraft:wooden_slab 1
fill ~18~9~15 ~20~9~15 minecraft:wool 13
fill ~21~10~15 ~25~10~15 minecraft:wool 13
setblock ~25~9~15 minecraft:wooden_slab 9
setblock ~26~10~15 minecraft:wooden_slab 1
setblock ~31~18~15 minecraft:stone_button 2
setblock ~36~19~15 minecraft:cobblestone_wall 0
setblock ~36~20~15 minecraft:fence 1
setblock ~36~29~15 minecraft:cobblestone_wall 0
setblock ~37~18~15 minecraft:stone_brick_stairs 7
setblock ~37~20~15 minecraft:stone_brick_stairs 3
setblock ~37~28~15 minecraft:stone_brick_stairs 6
fill ~37~29~15 ~37~29~16 minecraft:stonebrick 0
setblock ~37~30~15 minecraft:stone_brick_stairs 2
setblock ~38~19~15 minecraft:cobblestone_wall 0
setblock ~38~20~15 minecraft:fence 1
setblock ~38~29~15 minecraft:cobblestone_wall 0
fill ~43~18~15 ~43~18~19 minecraft:iron_block
fill ~43~28~15 ~43~28~17 minecraft:planks 1
setblock ~48~19~15 minecraft:cobblestone_wall 0
setblock ~48~20~15 minecraft:fence 1
setblock ~48~29~15 minecraft:cobblestone_wall 0
setblock ~49~18~15 minecraft:stone_brick_stairs 7
setblock ~49~20~15 minecraft:stone_brick_stairs 3
setblock ~49~28~15 minecraft:stone_brick_stairs 6
fill ~49~29~15 ~49~29~16 minecraft:stonebrick 0
setblock ~49~30~15 minecraft:stone_brick_stairs 2
setblock ~50~19~15 minecraft:cobblestone_wall 0
setblock ~50~20~15 minecraft:fence 1
setblock ~50~29~15 minecraft:cobblestone_wall 0
setblock ~55~18~15 minecraft:stone_button 2
fill ~55~25~15 ~56~25~15 minecraft:wool 13
setblock ~57~13~15 minecraft:spruce_stairs 7
setblock ~57~15~15 minecraft:wooden_slab 1
fill ~58~13~15 ~58~13~20 minecraft:wool 13
fill ~58~14~15 ~58~14~19 minecraft:wall_sign 5
setblock ~58~28~15 minecraft:spruce_stairs 0
fill ~60~10~15 ~60~10~16 minecraft:wool 13
fill ~61~9~15 ~61~9~17 minecraft:wool 13
setblock ~17~9~16 minecraft:wooden_slab 9
setblock ~18~10~16 minecraft:wooden_slab 1
setblock ~18~19~16 minecraft:cobblestone_wall 0
fill ~18~20~16 ~18~21~16 minecraft:fence 1
fill ~19~10~16 ~20~10~16 minecraft:wool 13
setblock ~19~18~16 minecraft:stone_brick_stairs 6
fill ~19~19~16 ~19~19~18 minecraft:stonebrick 0
setblock ~19~20~16 minecraft:stone_brick_stairs 2
fill ~19~21~16 ~20~21~18 minecraft:fence 1
setblock ~20~19~16 minecraft:cobblestone_wall 0
setblock ~20~20~16 minecraft:fence 1
fill ~21~11~16 ~26~11~16 minecraft:wool 13
setblock ~24~18~16 minecraft:stone_button 2
setblock ~26~10~16 minecraft:wooden_slab 9
setblock ~27~11~16 minecraft:wooden_slab 1
fill ~31~18~16 ~31~18~20 minecraft:iron_block
setblock ~35~12~16 minecraft:cobblestone_wall 0
fill ~35~28~16 ~36~28~16 minecraft:fence 1
fill ~35~29~16 ~35~29~17 minecraft:fence 1
setblock ~36~12~16 minecraft:cobblestone_wall 0
fill ~36~27~16 ~36~27~17 minecraft:fence 1
setblock ~36~29~16 minecraft:stonebrick 0
setblock ~36~30~16 minecraft:wool 13
setblock ~37~12~16 minecraft:furnace 3
fill ~37~27~16 ~37~27~17 minecraft:stone_block_slab 13
setblock ~37~28~16 minecraft:stonebrick 0
setblock ~37~30~16 minecraft:stonebrick 0
setblock ~37~31~16 minecraft:stone_brick_stairs 2
setblock ~38~12~16 minecraft:cobblestone_wall 0
fill ~38~27~16 ~38~27~17 minecraft:fence 1
fill ~38~28~16 ~39~28~16 minecraft:fence 1
setblock ~38~29~16 minecraft:stonebrick 0
fill ~38~30~16 ~39~30~16 minecraft:wool 13
setblock ~39~12~16 minecraft:cobblestone_wall 0
fill ~39~29~16 ~40~29~16 minecraft:fence 1
setblock ~40~12~16 minecraft:cobblestone_wall 0
fill ~40~30~16 ~41~30~16 minecraft:fence 1
setblock ~41~12~16 minecraft:furnace 3
fill ~41~31~16 ~41~31~17 minecraft:fence 1
setblock ~42~12~16 minecraft:cobblestone_wall 0
setblock ~42~16~16 minecraft:stone_brick_stairs 6
setblock ~42~17~16 minecraft:stone_brick_stairs 1
setblock ~43~12~16 minecraft:cobblestone_wall 0
setblock ~44~12~16 minecraft:cobblestone_wall 0
setblock ~44~16~16 minecraft:stone_brick_stairs 6
setblock ~44~17~16 minecraft:stone_brick_stairs 0
setblock ~45~12~16 minecraft:furnace 3
fill ~45~30~16 ~46~30~16 minecraft:fence 1
fill ~45~31~16 ~45~31~17 minecraft:fence 1
setblock ~46~12~16 minecraft:cobblestone_wall 0
fill ~46~29~16 ~47~29~16 minecraft:fence 1
setblock ~47~12~16 minecraft:cobblestone_wall 0
fill ~47~28~16 ~48~28~16 minecraft:fence 1
fill ~47~30~16 ~48~30~16 minecraft:wool 13
setblock ~48~12~16 minecraft:cobblestone_wall 0
fill ~48~27~16 ~48~27~17 minecraft:fence 1
setblock ~48~29~16 minecraft:stonebrick 0
setblock ~49~12~16 minecraft:furnace 3
fill ~49~27~16 ~49~27~17 minecraft:stone_block_slab 13
setblock ~49~28~16 minecraft:stonebrick 0
setblock ~49~30~16 minecraft:stonebrick 0
setblock ~49~31~16 minecraft:stone_brick_stairs 2
setblock ~50~12~16 minecraft:cobblestone_wall 0
fill ~50~27~16 ~50~27~17 minecraft:fence 1
fill ~50~28~16 ~51~28~16 minecraft:fence 1
setblock ~50~29~16 minecraft:stonebrick 0
setblock ~50~30~16 minecraft:wool 13
setblock ~51~12~16 minecraft:cobblestone_wall 0
fill ~51~29~16 ~51~29~17 minecraft:fence 1
fill ~55~18~16 ~55~18~20 minecraft:iron_block
fill ~57~13~16 ~57~13~20 minecraft:wooden_slab 9
setblock ~57~15~16 minecraft:spruce_stairs 2
fill ~58~28~16 ~58~28~18 minecraft:planks 1
setblock ~59~12~16 minecraft:wool 13
setblock ~60~11~16 minecraft:wool 13
fill ~61~10~16 ~61~10~19 minecraft:wool 13
setblock ~62~18~16 minecraft:stone_button 2
setblock ~66~19~16 minecraft:cobblestone_wall 0
fill ~66~20~16 ~66~21~16 minecraft:fence 1
setblock ~67~18~16 minecraft:stone_brick_stairs 6
fill ~67~19~16 ~67~19~18 minecraft:stonebrick 0
setblock ~67~20~16 minecraft:stone_brick_stairs 2
fill ~67~21~16 ~68~21~18 minecraft:fence 1
setblock ~68~19~16 minecraft:cobblestone_wall 0
setblock ~68~20~16 minecraft:fence 1
setblock ~18~10~17 minecraft:wooden_slab 9
setblock ~18~18~17 minecraft:stone_brick_stairs 4
setblock ~18~19~17 minecraft:stonebrick 0
setblock ~18~20~17 minecraft:stone_brick_stairs 0
fill ~18~21~17 ~18~21~18 minecraft:fence 1
setblock ~19~11~17 minecraft:wooden_slab 1
setblock ~19~18~17 minecraft:stonebrick 0
setblock ~19~20~17 minecraft:stonebrick 0
setblock ~19~22~17 minecraft:cobblestone_wall 0
setblock ~19~23~17 minecraft:fence 1
setblock ~19~24~17 minecraft:cobblestone_wall 0
setblock ~19~25~17 minecraft:fence 1
setblock ~19~26~17 minecraft:cobblestone_wall 0
setblock ~19~27~17 minecraft:fence 1
setblock ~19~28~17 minecraft:cobblestone_wall 0
setblock ~19~29~17 minecraft:stone_brick_stairs 2
setblock ~20~11~17 minecraft:wool 13
setblock ~20~18~17 minecraft:stone_brick_stairs 5
setblock ~20~19~17 minecraft:stonebrick 0
setblock ~20~20~17 minecraft:stone_brick_stairs 1
fill ~21~12~17 ~21~12~18 minecraft:wool 13
fill ~22~11~17 ~22~11~18 minecraft:wool 13
fill ~23~12~17 ~23~12~18 minecraft:wool 13
fill ~24~11~17 ~24~11~18 minecraft:wool 13
fill ~24~18~17 ~24~18~21 minecraft:iron_block
fill ~25~12~17 ~25~12~18 minecraft:wool 13
fill ~26~11~17 ~26~11~18 minecraft:wool 13
setblock ~27~11~17 minecraft:wooden_slab 9
setblock ~30~16~17 minecraft:stone_brick_stairs 6
setblock ~30~17~17 minecraft:stone_brick_stairs 1
setblock ~32~16~17 minecraft:stone_brick_stairs 6
setblock ~32~17~17 minecraft:stone_brick_stairs 0
fill ~33~30~17 ~34~30~17 minecraft:fence 1
fill ~33~31~17 ~33~31~18 minecraft:fence 1
setblock ~34~16~17 minecraft:spruce_stairs 4
setblock ~34~17~17 minecraft:stonebrick 0
fill ~34~18~17 ~34~20~17 minecraft:fence 1
setblock ~34~29~17 minecraft:fence 1
setblock ~35~11~17 minecraft:spruce_stairs 6
setblock ~35~12~17 minecraft:cobblestone_wall 0
fill ~35~13~17 ~35~15~17 minecraft:cobblestone_wall 0
fill ~35~16~17 ~51~16~17 minecraft:log 1
fill ~35~17~17 ~35~18~17 minecraft:log 1
setblock ~35~19~17 minecraft:stone_brick_stairs 0
fill ~35~20~17 ~35~22~17 minecraft:fence 1
setblock ~35~30~17 minecraft:wool 13
setblock ~36~11~17 minecraft:trapdoor 3
setblock ~36~13~17 minecraft:lever 4
setblock ~36~14~17 minecraft:lever 4
setblock ~36~15~17 minecraft:stone_brick_stairs 6
setblock ~36~17~17 minecraft:spruce_stairs 5
fill ~36~18~17 ~36~20~17 minecraft:log 1
setblock ~36~21~17 minecraft:stone_brick_stairs 0
fill ~36~22~17 ~36~26~17 minecraft:fence 1
fill ~36~28~17 ~42~28~17 minecraft:planks 1
fill ~36~29~17 ~42~29~17 minecraft:wool 13
fill ~36~30~17 ~50~30~17 minecraft:planks 1
fill ~36~31~17 ~39~31~17 minecraft:wool 13
setblock ~37~11~17 minecraft:spruce_stairs 6
setblock ~37~15~17 minecraft:torch 4
fill ~37~17~17 ~37~18~17 minecraft:fence 1
setblock ~37~19~17 minecraft:wooden_slab 9
fill ~37~20~17 ~38~20~17 minecraft:log 1
fill ~37~21~17 ~37~22~17 minecraft:log 1
setblock ~37~23~17 minecraft:stone_block_slab 5
fill ~37~24~17 ~38~26~17 minecraft:fence 1
setblock ~38~11~17 minecraft:trapdoor 3
setblock ~38~13~17 minecraft:lever 4
setblock ~38~14~17 minecraft:lever 4
setblock ~38~15~17 minecraft:stone_brick_stairs 6
setblock ~38~17~17 minecraft:spruce_stairs 4
fill ~38~18~17 ~39~18~17 minecraft:log 1
setblock ~38~19~17 minecraft:log 1
setblock ~38~21~17 minecraft:stone_brick_stairs 1
fill ~38~22~17 ~39~22~17 minecraft:fence 1
setblock ~38~23~17 minecraft:fence 1
setblock ~39~11~17 minecraft:spruce_stairs 6
setblock ~39~12~17 minecraft:cobblestone_wall 0
fill ~39~13~17 ~39~15~17 minecraft:cobblestone_wall 0
setblock ~39~17~17 minecraft:log 1
setblock ~39~19~17 minecraft:stone_brick_stairs 1
fill ~39~20~17 ~40~20~17 minecraft:fence 1
setblock ~39~21~17 minecraft:fence 1
setblock ~40~11~17 minecraft:trapdoor 3
setblock ~40~13~17 minecraft:lever 4
setblock ~40~14~17 minecraft:lever 4
setblock ~40~15~17 minecraft:stone_brick_stairs 6
fill ~40~17~17 ~46~17~17 minecraft:stonebrick 0
fill ~40~18~17 ~40~19~17 minecraft:fence 1
setblock ~41~11~17 minecraft:spruce_stairs 6
setblock ~41~15~17 minecraft:torch 4
setblock ~41~18~17 minecraft:cobblestone_wall 0
setblock ~42~11~17 minecraft:trapdoor 3
setblock ~42~13~17 minecraft:lever 4
setblock ~42~14~17 minecraft:lever 4
setblock ~42~15~17 minecraft:stone_brick_stairs 6
setblock ~42~18~17 minecraft:stone_brick_stairs 2
fill ~42~31~17 ~42~32~17 minecraft:fence 1
setblock ~43~11~17 minecraft:spruce_stairs 6
setblock ~43~12~17 minecraft:cobblestone_wall 0
fill ~43~13~17 ~43~15~17 minecraft:cobblestone_wall 0
setblock ~43~29~17 minecraft:planks 1
setblock ~44~11~17 minecraft:trapdoor 3
setblock ~44~13~17 minecraft:lever 4
setblock ~44~14~17 minecraft:lever 4
setblock ~44~15~17 minecraft:stone_brick_stairs 6
setblock ~44~18~17 minecraft:stone_brick_stairs 2
fill ~44~28~17 ~50~28~17 minecraft:planks 1
fill ~44~29~17 ~50~29~17 minecraft:wool 13
fill ~44~31~17 ~44~32~17 minecraft:fence 1
setblock ~45~11~17 minecraft:spruce_stairs 6
setblock ~45~15~17 minecraft:torch 4
setblock ~45~18~17 minecraft:cobblestone_wall 0
setblock ~46~11~17 minecraft:trapdoor 3
setblock ~46~13~17 minecraft:lever 4
setblock ~46~14~17 minecraft:lever 4
setblock ~46~15~17 minecraft:stone_brick_stairs 6
fill ~46~18~17 ~46~20~17 minecraft:fence 1
fill ~46~31~17 ~50~31~17 minecraft:wool 13
setblock ~47~11~17 minecraft:spruce_stairs 6
setblock ~47~12~17 minecraft:cobblestone_wall 0
fill ~47~13~17 ~47~15~17 minecraft:cobblestone_wall 0
fill ~47~17~17 ~47~18~17 minecraft:log 1
setblock ~47~19~17 minecraft:stone_brick_stairs 0
fill ~47~20~17 ~47~22~17 minecraft:fence 1
setblock ~48~11~17 minecraft:trapdoor 3
setblock ~48~13~17 minecraft:lever 4
setblock ~48~14~17 minecraft:lever 4
setblock ~48~15~17 minecraft:stone_brick_stairs 6
setblock ~48~17~17 minecraft:spruce_stairs 5
fill ~48~18~17 ~48~20~17 minecraft:log 1
setblock ~48~21~17 minecraft:stone_brick_stairs 0
fill ~48~22~17 ~48~26~17 minecraft:fence 1
setblock ~49~11~17 minecraft:spruce_stairs 6
setblock ~49~15~17 minecraft:torch 4
fill ~49~17~17 ~49~18~17 minecraft:fence 1
setblock ~49~19~17 minecraft:wooden_slab 9
fill ~49~20~17 ~50~20~17 minecraft:log 1
fill ~49~21~17 ~49~22~17 minecraft:log 1
setblock ~49~23~17 minecraft:stone_block_slab 5
fill ~49~24~17 ~50~26~17 minecraft:fence 1
setblock ~50~11~17 minecraft:trapdoor 3
setblock ~50~13~17 minecraft:lever 4
setblock ~50~14~17 minecraft:lever 4
setblock ~50~15~17 minecraft:stone_brick_stairs 6
setblock ~50~17~17 minecraft:spruce_stairs 4
fill ~50~18~17 ~51~18~17 minecraft:log 1
setblock ~50~19~17 minecraft:log 1
setblock ~50~21~17 minecraft:stone_brick_stairs 1
fill ~50~22~17 ~51~22~17 minecraft:fence 1
setblock ~50~23~17 minecraft:fence 1
setblock ~51~11~17 minecraft:spruce_stairs 6
setblock ~51~12~17 minecraft:cobblestone_wall 0
fill ~51~13~17 ~51~15~17 minecraft:cobblestone_wall 0
setblock ~51~17~17 minecraft:log 1
setblock ~51~19~17 minecraft:stone_brick_stairs 1
fill ~51~20~17 ~52~20~17 minecraft:fence 1
setblock ~51~21~17 minecraft:fence 1
setblock ~51~30~17 minecraft:wool 13
setblock ~52~16~17 minecraft:spruce_stairs 5
setblock ~52~17~17 minecraft:stonebrick 0
fill ~52~18~17 ~52~19~17 minecraft:fence 1
fill ~52~29~17 ~52~30~17 minecraft:fence 1
fill ~53~30~17 ~53~31~17 minecraft:fence 1
setblock ~54~16~17 minecraft:stone_brick_stairs 6
setblock ~54~17~17 minecraft:stone_brick_stairs 1
setblock ~56~16~17 minecraft:stone_brick_stairs 6
setblock ~56~17~17 minecraft:stone_brick_stairs 0
setblock ~57~15~17 minecraft:planks 1
fill ~59~13~17 ~59~13~18 minecraft:wool 13
fill ~60~12~17 ~60~12~18 minecraft:wool 13
fill ~61~11~17 ~61~11~18 minecraft:wool 13
fill ~62~18~17 ~62~18~21 minecraft:iron_block
setblock ~66~18~17 minecraft:stone_brick_stairs 4
setblock ~66~19~17 minecraft:stonebrick 0
setblock ~66~20~17 minecraft:stone_brick_stairs 0
fill ~66~21~17 ~66~21~18 minecraft:fence 1
setblock ~67~18~17 minecraft:stonebrick 0
setblock ~67~20~17 minecraft:stonebrick 0
setblock ~67~22~17 minecraft:cobblestone_wall 0
setblock ~67~23~17 minecraft:fence 1
setblock ~67~24~17 minecraft:cobblestone_wall 0
setblock ~67~25~17 minecraft:fence 1
setblock ~67~26~17 minecraft:cobblestone_wall 0
setblock ~67~27~17 minecraft:fence 1
setblock ~67~28~17 minecraft:cobblestone_wall 0
setblock ~67~29~17 minecraft:stone_brick_stairs 2
setblock ~68~18~17 minecraft:stone_brick_stairs 5
setblock ~68~19~17 minecraft:stonebrick 0
setblock ~68~20~17 minecraft:stone_brick_stairs 1
fill ~11~16~18 ~13~16~18 minecraft:spruce_stairs 6
fill ~11~17~18 ~13~17~18 minecraft:stonebrick 0
fill ~11~18~18 ~13~18~18 minecraft:fence 1
fill ~11~21~18 ~13~21~18 minecraft:spruce_stairs 6
fill ~11~22~18 ~13~22~18 minecraft:stonebrick 0
fill ~11~23~18 ~13~23~18 minecraft:fence 1
setblock ~18~19~18 minecraft:cobblestone_wall 0
setblock ~18~20~18 minecraft:fence 1
setblock ~18~29~18 minecraft:cobblestone_wall 0
setblock ~19~11~18 minecraft:wooden_slab 9
setblock ~19~18~18 minecraft:stone_brick_stairs 7
setblock ~19~20~18 minecraft:stone_brick_stairs 3
setblock ~19~28~18 minecraft:stone_brick_stairs 6
fill ~19~29~18 ~19~29~19 minecraft:stonebrick 0
setblock ~19~30~18 minecraft:stone_brick_stairs 2
setblock ~20~12~18 minecraft:wooden_slab 1
setblock ~20~19~18 minecraft:cobblestone_wall 0
setblock ~20~20~18 minecraft:fence 1
setblock ~20~29~18 minecraft:cobblestone_wall 0
fill ~21~29~18 ~22~29~18 minecraft:fence 1
setblock ~22~12~18 minecraft:stone_block_slab 13
fill ~22~30~18 ~23~30~18 minecraft:fence 1
setblock ~23~16~18 minecraft:stone_brick_stairs 6
setblock ~23~17~18 minecraft:stone_brick_stairs 1
fill ~23~31~18 ~23~31~19 minecraft:fence 1
setblock ~24~12~18 minecraft:stone_block_slab 13
setblock ~25~16~18 minecraft:stone_brick_stairs 6
setblock ~25~17~18 minecraft:stone_brick_stairs 0
setblock ~26~12~18 minecraft:stone_block_slab 13
setblock ~27~12~18 minecraft:wool 13
setblock ~27~16~18 minecraft:spruce_stairs 4
fill ~27~17~18 ~33~17~18 minecraft:stonebrick 0
fill ~27~18~18 ~29~18~18 minecraft:fence 1
setblock ~28~12~18 minecraft:wooden_slab 1
fill ~28~16~18 ~34~16~18 minecraft:log 1
fill ~28~28~18 ~35~28~18 minecraft:planks 1
fill ~28~29~18 ~35~29~18 minecraft:wool 13
fill ~28~30~18 ~35~30~18 minecraft:planks 1
setblock ~30~18~18 minecraft:stone_brick_stairs 2
setblock ~32~18~18 minecraft:stone_brick_stairs 2
fill ~32~31~18 ~32~32~18 minecraft:fence 1
setblock ~33~15~18 minecraft:spruce_stairs 4
setblock ~33~18~18 minecraft:fence 1
fill ~34~11~18 ~34~15~18 minecraft:planks 1
setblock ~34~17~18 minecraft:stone_brick_stairs 3
fill ~34~31~18 ~35~31~18 minecraft:wool 13
setblock ~35~10~18 minecraft:stone_block_slab 13
fill ~35~11~18 ~35~15~18 minecraft:log 1
fill ~35~16~18 ~51~16~30 minecraft:planks 1
setblock ~35~17~18 minecraft:stone_brick_stairs 1
fill ~36~11~18 ~38~11~18 minecraft:log 1
fill ~36~12~18 ~38~12~18 minecraft:planks 1
fill ~36~13~18 ~36~15~18 minecraft:planks 1
fill ~36~27~18 ~42~27~18 minecraft:spruce_stairs 6
fill ~36~28~18 ~50~28~19 minecraft:snow
fill ~36~29~18 ~50~30~18 minecraft:snow
fill ~36~31~18 ~50~31~18 minecraft:spruce_stairs 2
fill ~36~32~18 ~39~32~18 minecraft:wool 13
fill ~37~13~18 ~37~14~18 minecraft:fence 1
fill ~37~15~18 ~38~15~18 minecraft:planks 1
fill ~38~13~18 ~38~14~18 minecraft:planks 1
setblock ~39~10~18 minecraft:stone_block_slab 13
fill ~39~11~18 ~39~15~18 minecraft:log 1
setblock ~39~17~18 minecraft:stone_brick_stairs 0
fill ~40~11~18 ~42~11~18 minecraft:log 1
fill ~40~12~18 ~42~12~18 minecraft:planks 1
fill ~40~13~18 ~40~15~18 minecraft:planks 1
fill ~40~17~18 ~41~17~18 minecraft:stone_brick_stairs 3
fill ~41~13~18 ~41~14~18 minecraft:fence 1
fill ~41~15~18 ~42~15~18 minecraft:planks 1
setblock ~41~18~18 minecraft:wooden_button 4
setblock ~41~32~18 minecraft:wool 13
fill ~42~13~18 ~42~14~18 minecraft:planks 1
fill ~42~17~18 ~44~17~19 minecraft:stonebrick 0
setblock ~42~18~18 minecraft:stonebrick 0
setblock ~42~32~18 minecraft:fence 1
setblock ~43~10~18 minecraft:stone_block_slab 13
fill ~43~11~18 ~43~15~18 minecraft:log 1
setblock ~43~19~18 minecraft:stone_block_slab 5
fill ~43~26~18 ~43~27~18 minecraft:planks 1
fill ~43~32~18 ~43~33~18 minecraft:planks 1
fill ~43~34~18 ~43~36~18 minecraft:fence 1
fill ~44~11~18 ~46~11~18 minecraft:log 1
fill ~44~12~18 ~46~12~18 minecraft:planks 1
fill ~44~13~18 ~44~15~18 minecraft:planks 1
setblock ~44~18~18 minecraft:stonebrick 0
fill ~44~27~18 ~50~27~18 minecraft:spruce_stairs 6
setblock ~44~32~18 minecraft:fence 1
fill ~45~13~18 ~45~14~18 minecraft:fence 1
fill ~45~15~18 ~46~15~18 minecraft:planks 1
fill ~45~17~18 ~46~17~18 minecraft:stone_brick_stairs 3
setblock ~45~18~18 minecraft:wooden_button 5
fill ~45~32~18 ~50~32~18 minecraft:wool 13
fill ~46~13~18 ~46~14~18 minecraft:planks 1
setblock ~47~10~18 minecraft:stone_block_slab 13
fill ~47~11~18 ~47~15~18 minecraft:log 1
setblock ~47~17~18 minecraft:stone_brick_stairs 1
fill ~48~11~18 ~50~11~18 minecraft:log 1
fill ~48~12~18 ~50~12~18 minecraft:planks 1
fill ~48~13~18 ~48~15~18 minecraft:planks 1
fill ~49~13~18 ~49~14~18 minecraft:fence 1
fill ~49~15~18 ~50~15~18 minecraft:planks 1
fill ~50~13~18 ~50~14~18 minecraft:planks 1
setblock ~51~10~18 minecraft:stone_block_slab 13
fill ~51~11~18 ~51~15~18 minecraft:log 1
setblock ~51~17~18 minecraft:stone_brick_stairs 0
fill ~51~28~18 ~57~28~18 minecraft:planks 1
fill ~51~29~18 ~58~29~18 minecraft:wool 13
fill ~51~30~18 ~58~30~18 minecraft:planks 1
fill ~51~31~18 ~52~31~18 minecraft:wool 13
fill ~52~11~18 ~52~15~18 minecraft:planks 1
fill ~52~16~18 ~58~16~18 minecraft:log 1
setblock ~52~17~18 minecraft:stone_brick_stairs 3
setblock ~53~15~18 minecraft:spruce_stairs 5
fill ~53~17~18 ~59~17~18 minecraft:stonebrick 0
setblock ~53~18~18 minecraft:fence 1
fill ~53~31~18 ~54~31~18 minecraft:fence 1
setblock ~54~18~18 minecraft:stone_brick_stairs 2
fill ~54~32~18 ~54~32~19 minecraft:fence 1
setblock ~56~18~18 minecraft:stone_brick_stairs 2
setblock ~57~15~18 minecraft:stonebrick 0
fill ~57~18~18 ~59~18~18 minecraft:fence 1
setblock ~59~8~18 minecraft:wool 13
setblock ~59~16~18 minecraft:spruce_stairs 5
fill ~60~9~18 ~60~9~19 minecraft:wool 13
setblock ~61~16~18 minecraft:stone_brick_stairs 6
setblock ~61~17~18 minecraft:stone_brick_stairs 1
setblock ~63~16~18 minecraft:stone_brick_stairs 6
setblock ~63~17~18 minecraft:stone_brick_stairs 0
fill ~63~30~18 ~64~30~18 minecraft:fence 1
fill ~63~31~18 ~63~31~19 minecraft:fence 1
fill ~64~29~18 ~65~29~18 minecraft:fence 1
setblock ~66~19~18 minecraft:cobblestone_wall 0
setblock ~66~20~18 minecraft:fence 1
setblock ~66~29~18 minecraft:cobblestone_wall 0
setblock ~67~18~18 minecraft:stone_brick_stairs 7
setblock ~67~20~18 minecraft:stone_brick_stairs 3
setblock ~67~28~18 minecraft:stone_brick_stairs 6
fill ~67~29~18 ~67~29~19 minecraft:stonebrick 0
setblock ~67~30~18 minecraft:stone_brick_stairs 2
fill ~67~31~18 ~67~33~18 minecraft:fence 1
setblock ~68~19~18 minecraft:cobblestone_wall 0
setblock ~68~20~18 minecraft:fence 1
setblock ~68~29~18 minecraft:cobblestone_wall 0
fill ~9~16~19 ~10~16~19 minecraft:spruce_stairs 6
fill ~9~17~19 ~10~17~19 minecraft:stonebrick 0
fill ~9~18~19 ~10~18~19 minecraft:fence 1
fill ~9~21~19 ~10~21~19 minecraft:spruce_stairs 6
fill ~9~22~19 ~10~22~19 minecraft:stonebrick 0
fill ~9~23~19 ~10~23~19 minecraft:fence 1
fill ~11~15~19 ~13~15~19 minecraft:spruce_stairs 6
fill ~11~16~19 ~13~16~19 minecraft:planks 1
setblock ~11~20~19 minecraft:spruce_stairs 6
fill ~11~21~19 ~13~21~29 minecraft:planks 1
fill ~11~22~19 ~13~22~19 minecraft:planks 1
fill ~11~23~19 ~13~23~19 minecraft:stone_block_slab 5
setblock ~13~20~19 minecraft:spruce_stairs 6
fill ~14~16~19 ~15~16~19 minecraft:spruce_stairs 6
fill ~14~17~19 ~15~17~19 minecraft:stonebrick 0
fill ~14~18~19 ~15~18~19 minecraft:fence 1
fill ~14~21~19 ~15~21~19 minecraft:spruce_stairs 6
fill ~14~22~19 ~15~22~19 minecraft:stonebrick 0
fill ~14~23~19 ~15~23~19 minecraft:fence 1
fill ~16~29~19 ~17~29~19 minecraft:fence 1
fill ~17~28~19 ~18~28~19 minecraft:fence 1
fill ~17~30~19 ~18~30~19 minecraft:wool 13
fill ~18~27~19 ~18~27~20 minecraft:fence 1
setblock ~18~29~19 minecraft:stonebrick 0
fill ~19~27~19 ~19~27~20 minecraft:stone_block_slab 13
setblock ~19~28~19 minecraft:stonebrick 0
setblock ~19~30~19 minecraft:stonebrick 0
setblock ~19~31~19 minecraft:stone_brick_stairs 2
fill ~20~27~19 ~20~27~20 minecraft:fence 1
fill ~20~28~19 ~21~28~19 minecraft:fence 1
setblock ~20~29~19 minecraft:stonebrick 0
fill ~20~30~19 ~21~30~19 minecraft:wool 13
setblock ~21~12~19 minecraft:wooden_slab 9
setblock ~21~16~19 minecraft:spruce_stairs 4
fill ~21~17~19 ~26~17~19 minecraft:stonebrick 0
setblock ~21~29~19 minecraft:fence 1
setblock ~22~12~19 minecraft:wool 13
setblock ~22~13~19 minecraft:stone_brick_stairs 2
fill ~22~16~19 ~27~16~19 minecraft:log 1
fill ~22~28~19 ~27~28~19 minecraft:planks 1
fill ~22~29~19 ~27~29~19 minecraft:wool 13
fill ~22~30~19 ~27~30~19 minecraft:planks 1
setblock ~22~31~19 minecraft:wool 13
setblock ~23~13~19 minecraft:wooden_slab 1
setblock ~23~18~19 minecraft:stone_brick_stairs 2
setblock ~24~12~19 minecraft:wool 13
setblock ~24~13~19 minecraft:stone_brick_stairs 2
fill ~24~31~19 ~24~32~19 minecraft:fence 1
setblock ~25~13~19 minecraft:wooden_slab 1
setblock ~25~18~19 minecraft:stone_brick_stairs 2
setblock ~26~12~19 minecraft:wool 13
setblock ~26~13~19 minecraft:stone_brick_stairs 2
setblock ~26~18~19 minecraft:fence 1
setblock ~27~12~19 minecraft:wooden_slab 1
setblock ~27~15~19 minecraft:spruce_stairs 4
fill ~27~17~19 ~28~17~19 minecraft:stone_brick_stairs 3
fill ~27~32~19 ~32~32~19 minecraft:fence 1
fill ~28~15~19 ~33~16~19 minecraft:planks 1
fill ~28~27~19 ~34~27~19 minecraft:spruce_stairs 6
fill ~28~28~19 ~35~28~20 minecraft:snow
fill ~28~29~19 ~35~30~19 minecraft:snow
fill ~28~31~19 ~34~31~19 minecraft:spruce_stairs 2
fill ~29~17~19 ~33~17~19 minecraft:stonebrick 0
setblock ~29~18~19 minecraft:wooden_button 4
setblock ~30~18~19 minecraft:stonebrick 0
setblock ~31~19~19 minecraft:stone_block_slab 5
setblock ~32~14~19 minecraft:spruce_stairs 4
setblock ~32~18~19 minecraft:stonebrick 0
setblock ~33~10~19 minecraft:spruce_stairs 4
fill ~33~11~19 ~33~14~19 minecraft:planks 1
setblock ~33~18~19 minecraft:wooden_button 5
fill ~33~32~19 ~35~32~19 minecraft:wool 13
setblock ~34~10~19 minecraft:planks 1
fill ~34~11~19 ~52~11~23 minecraft:wooden_slab 9
fill ~34~16~19 ~34~16~29 minecraft:planks 1
setblock ~34~17~19 minecraft:stone_brick_stairs 1
setblock ~35~9~19 minecraft:stone_block_slab 13
setblock ~35~10~19 minecraft:log 1
setblock ~35~27~19 minecraft:planks 1
setblock ~35~31~19 minecraft:planks 1
fill ~36~10~19 ~38~10~19 minecraft:planks 1
fill ~36~26~19 ~50~26~20 minecraft:snow
fill ~36~27~19 ~50~27~19 minecraft:snow
fill ~36~30~19 ~58~30~19 minecraft:snow
fill ~36~31~19 ~50~32~19 minecraft:snow
fill ~36~33~19 ~50~33~19 minecraft:wool 13
setblock ~39~9~19 minecraft:stone_block_slab 13
setblock ~39~10~19 minecraft:log 1
fill ~40~10~19 ~42~10~19 minecraft:planks 1
setblock ~42~18~19 minecraft:stone_brick_stairs 3
setblock ~43~9~19 minecraft:stone_block_slab 13
setblock ~43~10~19 minecraft:log 1
setblock ~43~25~19 minecraft:spruce_stairs 6
setblock ~43~34~19 minecraft:spruce_stairs 2
fill ~43~35~19 ~43~37~19 minecraft:fence 1
fill ~44~10~19 ~46~10~19 minecraft:planks 1
setblock ~44~18~19 minecraft:stone_brick_stairs 3
setblock ~47~9~19 minecraft:stone_block_slab 13
setblock ~47~10~19 minecraft:log 1
fill ~48~10~19 ~50~10~19 minecraft:planks 1
setblock ~51~9~19 minecraft:stone_block_slab 13
setblock ~51~10~19 minecraft:log 1
setblock ~51~27~19 minecraft:planks 1
fill ~51~28~19 ~58~28~20 minecraft:snow
fill ~51~29~19 ~58~29~19 minecraft:snow
setblock ~51~31~19 minecraft:planks 1
fill ~51~32~19 ~53~32~19 minecraft:wool 13
setblock ~52~10~19 minecraft:planks 1
fill ~52~16~19 ~58~16~29 minecraft:planks 1
setblock ~52~17~19 minecraft:stone_brick_stairs 0
fill ~52~27~19 ~58~27~19 minecraft:spruce_stairs 6
fill ~52~31~19 ~58~31~19 minecraft:spruce_stairs 2
setblock ~53~10~19 minecraft:spruce_stairs 5
fill ~53~11~19 ~53~15~19 minecraft:planks 1
setblock ~53~17~19 minecraft:stone_brick_stairs 3
setblock ~53~18~19 minecraft:wooden_button 4
setblock ~54~14~19 minecraft:spruce_stairs 5
fill ~54~15~19 ~58~15~19 minecraft:planks 1
fill ~54~17~19 ~56~17~20 minecraft:stonebrick 0
setblock ~54~18~19 minecraft:stonebrick 0
setblock ~55~19~19 minecraft:stone_block_slab 5
fill ~55~32~19 ~59~32~19 minecraft:fence 1
setblock ~56~18~19 minecraft:stonebrick 0
fill ~57~17~19 ~59~17~19 minecraft:stone_brick_stairs 3
setblock ~57~18~19 minecraft:wooden_button 5
fill ~59~12~19 ~59~12~20 minecraft:wool 13
setblock ~59~15~19 minecraft:spruce_stairs 5
fill ~59~16~19 ~64~16~19 minecraft:log 1
fill ~59~28~19 ~64~28~19 minecraft:planks 1
fill ~59~29~19 ~64~29~19 minecraft:wool 13
fill ~59~30~19 ~64~30~19 minecraft:planks 1
fill ~60~11~19 ~60~11~20 minecraft:wool 13
fill ~60~17~19 ~65~17~19 minecraft:stonebrick 0
setblock ~60~18~19 minecraft:fence 1
setblock ~61~18~19 minecraft:stone_brick_stairs 2
fill ~62~31~19 ~62~32~19 minecraft:fence 1
setblock ~63~18~19 minecraft:stone_brick_stairs 2
setblock ~64~31~19 minecraft:wool 13
setblock ~65~16~19 minecraft:spruce_stairs 5
fill ~65~28~19 ~66~28~19 minecraft:fence 1
setblock ~65~29~19 minecraft:fence 1
fill ~65~30~19 ~66~30~19 minecraft:wool 13
fill ~66~27~19 ~66~27~20 minecraft:fence 1
setblock ~66~29~19 minecraft:stonebrick 0
fill ~67~27~19 ~67~27~20 minecraft:stone_block_slab 13
setblock ~67~28~19 minecraft:stonebrick 0
setblock ~67~30~19 minecraft:stonebrick 0
setblock ~67~31~19 minecraft:stone_brick_stairs 2
fill ~67~32~19 ~67~36~19 minecraft:fence 1
fill ~68~27~19 ~68~27~20 minecraft:fence 1
fill ~68~28~19 ~69~28~19 minecraft:fence 1
setblock ~68~29~19 minecraft:stonebrick 0
fill ~68~30~19 ~69~30~19 minecraft:wool 13
fill ~69~29~19 ~70~29~19 minecraft:fence 1
setblock ~8~16~20 minecraft:spruce_stairs 4
fill ~8~17~20 ~8~21~20 minecraft:log 1
setblock ~8~22~20 minecraft:stonebrick 0
setblock ~8~23~20 minecraft:fence 1
setblock ~9~15~20 minecraft:spruce_stairs 4
fill ~9~16~20 ~21~16~20 minecraft:log 1
fill ~9~17~20 ~11~17~20 minecraft:planks 1
fill ~9~18~20 ~9~21~20 minecraft:planks 1
setblock ~10~14~20 minecraft:spruce_stairs 4
setblock ~10~15~20 minecraft:planks 1
fill ~10~18~20 ~10~19~20 minecraft:fence 1
fill ~10~20~20 ~11~20~20 minecraft:planks 1
fill ~10~21~20 ~10~21~28 minecraft:planks 1
setblock ~10~22~20 minecraft:wall_sign 4
fill ~11~14~20 ~15~14~20 minecraft:planks 1
fill ~11~18~20 ~11~19~20 minecraft:planks 1
fill ~11~22~20 ~13~22~20 minecraft:spruce_stairs 3
setblock ~12~17~20 minecraft:spruce_door 1
fill ~12~19~20 ~14~19~20 minecraft:planks 1
setblock ~12~20~20 minecraft:fence 1
fill ~13~17~20 ~14~18~20 minecraft:planks 1
fill ~13~20~20 ~14~20~20 minecraft:planks 1
fill ~14~15~20 ~16~15~20 minecraft:planks 1
fill ~14~21~20 ~14~21~28 minecraft:planks 1
setblock ~14~22~20 minecraft:wall_sign 5
fill ~15~17~20 ~15~20~20 minecraft:log 1
fill ~15~21~20 ~15~21~22 minecraft:stonebrick 0
fill ~15~22~20 ~15~22~22 minecraft:fence 1
fill ~15~30~20 ~16~30~20 minecraft:fence 1
fill ~15~31~20 ~15~31~21 minecraft:fence 1
setblock ~16~14~20 minecraft:spruce_stairs 5
setblock ~16~17~20 minecraft:stonebrick 0
fill ~16~18~20 ~16~20~20 minecraft:fence 1
setblock ~16~29~20 minecraft:fence 1
setblock ~17~15~20 minecraft:spruce_stairs 5
fill ~17~17~20 ~17~18~20 minecraft:log 1
setblock ~17~19~20 minecraft:stone_brick_stairs 0
fill ~17~20~20 ~17~22~20 minecraft:fence 1
fill ~17~28~20 ~21~28~20 minecraft:planks 1
fill ~17~29~20 ~21~29~20 minecraft:wool 13
fill ~17~30~20 ~21~30~20 minecraft:planks 1
fill ~17~31~20 ~21~31~20 minecraft:wool 13
setblock ~18~17~20 minecraft:spruce_stairs 5
fill ~18~18~20 ~18~20~20 minecraft:log 1
setblock ~18~21~20 minecraft:stone_brick_stairs 0
fill ~18~22~20 ~18~26~20 minecraft:fence 1
fill ~19~17~20 ~19~18~20 minecraft:fence 1
setblock ~19~19~20 minecraft:wooden_slab 9
fill ~19~20~20 ~20~20~20 minecraft:log 1
fill ~19~21~20 ~19~22~20 minecraft:log 1
setblock ~19~23~20 minecraft:stone_block_slab 5
fill ~19~24~20 ~20~26~20 minecraft:fence 1
setblock ~20~17~20 minecraft:spruce_stairs 4
fill ~20~18~20 ~21~18~20 minecraft:log 1
setblock ~20~19~20 minecraft:log 1
setblock ~20~21~20 minecraft:stone_brick_stairs 1
fill ~20~22~20 ~21~22~20 minecraft:fence 1
setblock ~20~23~20 minecraft:fence 1
setblock ~21~15~20 minecraft:spruce_stairs 4
setblock ~21~17~20 minecraft:log 1
setblock ~21~19~20 minecraft:stone_brick_stairs 1
fill ~21~20~20 ~22~20~20 minecraft:fence 1
setblock ~21~21~20 minecraft:fence 1
setblock ~22~13~20 minecraft:stonebrick 0
setblock ~22~14~20 minecraft:stone_brick_stairs 2
fill ~22~15~20 ~28~16~20 minecraft:planks 1
fill ~22~17~20 ~22~19~20 minecraft:fence 1
fill ~22~27~20 ~26~27~20 minecraft:spruce_stairs 6
fill ~22~28~20 ~27~28~21 minecraft:snow
fill ~22~29~20 ~27~30~20 minecraft:snow
fill ~22~31~20 ~26~31~20 minecraft:spruce_stairs 2
fill ~22~32~20 ~23~32~20 minecraft:wool 13
setblock ~23~13~20 minecraft:log 1
fill ~23~17~20 ~25~17~21 minecraft:stonebrick 0
setblock ~23~18~20 minecraft:stonebrick 0
setblock ~24~13~20 minecraft:stonebrick 0
setblock ~24~14~20 minecraft:stone_brick_stairs 2
setblock ~24~19~20 minecraft:stone_block_slab 5
fill ~24~32~20 ~27~32~20 minecraft:fence 1
setblock ~25~13~20 minecraft:log 1
setblock ~25~18~20 minecraft:stonebrick 0
setblock ~26~13~20 minecraft:stonebrick 0
setblock ~26~14~20 minecraft:stone_brick_stairs 2
setblock ~26~17~20 minecraft:stone_brick_stairs 3
setblock ~26~18~20 minecraft:wooden_button 5
setblock ~27~14~20 minecraft:spruce_stairs 4
setblock ~27~17~20 minecraft:stone_brick_stairs 1
setblock ~27~27~20 minecraft:planks 1
setblock ~27~31~20 minecraft:planks 1
fill ~27~33~20 ~35~33~20 minecraft:wool 13
fill ~28~14~20 ~32~14~20 minecraft:planks 1
fill ~28~26~20 ~35~26~21 minecraft:snow
fill ~28~27~20 ~35~27~20 minecraft:snow
fill ~28~30~20 ~35~32~20 minecraft:snow
fill ~29~16~20 ~33~16~29 minecraft:planks 1
fill ~30~17~20 ~32~17~20 minecraft:stonebrick 0
setblock ~30~18~20 minecraft:stone_brick_stairs 3
setblock ~31~13~20 minecraft:spruce_stairs 4
fill ~32~10~20 ~32~10~21 minecraft:spruce_stairs 4
fill ~32~11~20 ~32~11~21 minecraft:planks 1
fill ~32~12~20 ~32~13~20 minecraft:planks 1
setblock ~32~18~20 minecraft:stone_brick_stairs 3
fill ~33~9~20 ~33~9~21 minecraft:spruce_stairs 4
fill ~33~10~20 ~33~10~21 minecraft:planks 1
fill ~33~11~20 ~33~11~23 minecraft:wooden_slab 9
fill ~34~9~20 ~34~9~21 minecraft:planks 1
setblock ~35~8~20 minecraft:stone_block_slab 13
setblock ~35~9~20 minecraft:log 1
fill ~36~9~20 ~38~9~21 minecraft:planks 1
fill ~36~25~20 ~50~25~21 minecraft:snow
fill ~36~32~20 ~58~32~20 minecraft:snow
fill ~36~33~20 ~50~33~21 minecraft:snow
fill ~36~34~20 ~50~34~20 minecraft:wool 13
setblock ~39~8~20 minecraft:stone_block_slab 13
setblock ~39~9~20 minecraft:log 1
fill ~40~9~20 ~42~9~21 minecraft:planks 1
fill ~42~17~20 ~44~17~20 minecraft:stone_brick_stairs 3
setblock ~43~8~20 minecraft:stone_block_slab 13
setblock ~43~9~20 minecraft:log 1
setblock ~43~18~20 minecraft:lever 3
setblock ~43~24~20 minecraft:spruce_stairs 6
setblock ~43~35~20 minecraft:spruce_stairs 2
fill ~43~36~20 ~43~38~20 minecraft:fence 1
fill ~44~9~20 ~46~9~21 minecraft:planks 1
setblock ~47~8~20 minecraft:stone_block_slab 13
setblock ~47~9~20 minecraft:log 1
fill ~48~9~20 ~50~9~21 minecraft:planks 1
setblock ~51~8~20 minecraft:stone_block_slab 13
setblock ~51~9~20 minecraft:log 1
fill ~51~26~20 ~58~26~21 minecraft:snow
fill ~51~27~20 ~58~27~20 minecraft:snow
fill ~51~30~20 ~64~30~20 minecraft:snow
fill ~51~31~20 ~58~31~20 minecraft:snow
fill ~51~33~20 ~58~33~20 minecraft:wool 13
fill ~52~9~20 ~52~9~21 minecraft:planks 1
fill ~53~9~20 ~53~9~21 minecraft:spruce_stairs 5
fill ~53~10~20 ~53~10~21 minecraft:planks 1
fill ~53~11~20 ~53~11~23 minecraft:wooden_slab 9
fill ~54~10~20 ~54~10~21 minecraft:spruce_stairs 5
fill ~54~11~20 ~54~11~21 minecraft:planks 1
fill ~54~12~20 ~54~14~20 minecraft:planks 1
setblock ~54~18~20 minecraft:stone_brick_stairs 3
setblock ~55~13~20 minecraft:spruce_stairs 5
fill ~55~14~20 ~56~14~20 minecraft:planks 1
setblock ~56~18~20 minecraft:stone_brick_stairs 3
fill ~58~14~20 ~58~14~21 minecraft:planks 1
fill ~58~15~20 ~64~15~20 minecraft:planks 1
setblock ~59~14~20 minecraft:spruce_stairs 5
fill ~59~16~20 ~64~16~21 minecraft:planks 1
setblock ~59~17~20 minecraft:stone_brick_stairs 0
setblock ~59~27~20 minecraft:planks 1
fill ~59~28~20 ~64~28~21 minecraft:snow
fill ~59~29~20 ~64~29~20 minecraft:snow
setblock ~59~31~20 minecraft:planks 1
fill ~59~32~20 ~62~32~20 minecraft:fence 1
setblock ~60~10~20 minecraft:wool 13
setblock ~60~17~20 minecraft:stone_brick_stairs 3
setblock ~60~18~20 minecraft:wooden_button 4
fill ~60~27~20 ~64~27~20 minecraft:spruce_stairs 6
fill ~60~31~20 ~64~31~20 minecraft:spruce_stairs 2
fill ~61~17~20 ~63~17~21 minecraft:stonebrick 0
setblock ~61~18~20 minecraft:stonebrick 0
setblock ~62~19~20 minecraft:stone_block_slab 5
setblock ~63~18~20 minecraft:stonebrick 0
fill ~63~32~20 ~64~32~20 minecraft:wool 13
fill ~64~17~20 ~64~20~20 minecraft:fence 1
fill ~65~16~20 ~69~16~20 minecraft:log 1
fill ~65~17~20 ~65~18~20 minecraft:log 1
setblock ~65~19~20 minecraft:stone_brick_stairs 0
fill ~65~20~20 ~65~22~20 minecraft:fence 1
fill ~65~28~20 ~69~28~20 minecraft:planks 1
fill ~65~29~20 ~69~29~20 minecraft:wool 13
fill ~65~30~20 ~69~30~20 minecraft:planks 1
fill ~65~31~20 ~69~31~20 minecraft:wool 13
setblock ~66~17~20 minecraft:spruce_stairs 5
fill ~66~18~20 ~66~20~20 minecraft:log 1
setblock ~66~21~20 minecraft:stone_brick_stairs 0
fill ~66~22~20 ~66~26~20 minecraft:fence 1
fill ~67~17~20 ~67~18~20 minecraft:fence 1
setblock ~67~19~20 minecraft:wooden_slab 9
fill ~67~20~20 ~68~20~20 minecraft:log 1
fill ~67~21~20 ~67~22~20 minecraft:log 1
setblock ~67~23~20 minecraft:stone_block_slab 5
fill ~67~24~20 ~68~26~20 minecraft:fence 1
setblock ~67~32~20 minecraft:spruce_stairs 2
fill ~67~35~20 ~67~39~20 minecraft:fence 1
setblock ~68~17~20 minecraft:spruce_stairs 4
fill ~68~18~20 ~69~18~20 minecraft:log 1
setblock ~68~19~20 minecraft:log 1
setblock ~68~21~20 minecraft:stone_brick_stairs 1
fill ~68~22~20 ~69~22~20 minecraft:fence 1
setblock ~68~23~20 minecraft:fence 1
setblock ~69~17~20 minecraft:log 1
setblock ~69~19~20 minecraft:stone_brick_stairs 1
fill ~69~20~20 ~70~20~20 minecraft:fence 1
setblock ~69~21~20 minecraft:fence 1
setblock ~70~16~20 minecraft:spruce_stairs 5
setblock ~70~17~20 minecraft:stonebrick 0
fill ~70~18~20 ~70~19~20 minecraft:fence 1
fill ~70~29~20 ~70~31~20 minecraft:fence 1
setblock ~71~17~20 minecraft:stone_brick_stairs 5
setblock ~71~18~20 minecraft:cobblestone_wall 0
fill ~71~31~20 ~71~31~21 minecraft:fence 1
fill ~7~16~21 ~7~16~22 minecraft:spruce_stairs 4
fill ~7~17~21 ~7~17~22 minecraft:stonebrick 0
fill ~7~18~21 ~7~18~22 minecraft:fence 1
fill ~7~21~21 ~7~21~22 minecraft:spruce_stairs 4
fill ~7~22~21 ~7~22~22 minecraft:stonebrick 0
fill ~7~23~21 ~7~23~22 minecraft:fence 1
fill ~8~15~21 ~8~15~22 minecraft:spruce_stairs 4
fill ~8~16~21 ~8~16~27 minecraft:planks 1
fill ~8~17~21 ~8~17~23 minecraft:planks 1
fill ~8~18~21 ~8~21~21 minecraft:planks 1
fill ~9~14~21 ~9~14~22 minecraft:spruce_stairs 4
setblock ~9~15~21 minecraft:planks 1
fill ~9~16~21 ~9~16~27 minecraft:log 1
setblock ~9~17~21 minecraft:chest 5
fill ~9~21~21 ~9~21~28 minecraft:planks 1
fill ~10~13~21 ~10~13~22 minecraft:spruce_stairs 4
setblock ~10~14~21 minecraft:planks 1
fill ~10~16~21 ~28~16~22 minecraft:planks 1
fill ~11~13~21 ~14~13~21 minecraft:planks 1
fill ~12~31~21 ~14~31~21 minecraft:fence 1
fill ~13~28~21 ~16~28~21 minecraft:planks 1
fill ~13~29~21 ~16~29~21 minecraft:wool 13
fill ~13~30~21 ~16~30~21 minecraft:planks 1
fill ~14~17~21 ~14~17~22 minecraft:furnace 4
fill ~14~18~21 ~14~18~22 minecraft:wooden_pressure_plate 0
setblock ~15~13~21 minecraft:spruce_stairs 5
fill ~15~17~21 ~15~20~23 minecraft:planks 1
setblock ~16~14~21 minecraft:planks 1
setblock ~16~31~21 minecraft:wool 13
setblock ~17~14~21 minecraft:spruce_stairs 5
fill ~17~15~21 ~22~15~21 minecraft:planks 1
fill ~17~27~21 ~20~27~21 minecraft:spruce_stairs 6
fill ~17~28~21 ~21~28~22 minecraft:snow
fill ~17~29~21 ~21~30~21 minecraft:snow
fill ~17~31~21 ~20~31~21 minecraft:spruce_stairs 2
fill ~17~32~21 ~21~32~22 minecraft:wool 13
setblock ~21~14~21 minecraft:spruce_stairs 4
setblock ~21~27~21 minecraft:planks 1
setblock ~21~31~21 minecraft:planks 1
fill ~22~14~21 ~28~14~21 minecraft:planks 1
fill ~22~26~21 ~27~26~23 minecraft:snow
fill ~22~27~21 ~27~27~21 minecraft:snow
fill ~22~30~21 ~27~32~21 minecraft:snow
fill ~22~33~21 ~27~33~22 minecraft:wool 13
setblock ~23~18~21 minecraft:stone_brick_stairs 3
setblock ~25~18~21 minecraft:stone_brick_stairs 3
setblock ~27~13~21 minecraft:spruce_stairs 4
fill ~28~13~21 ~31~13~21 minecraft:planks 1
fill ~28~25~21 ~35~25~23 minecraft:snow
fill ~28~32~21 ~35~33~21 minecraft:snow
fill ~28~34~21 ~35~34~22 minecraft:wool 13
setblock ~30~12~21 minecraft:spruce_stairs 4
fill ~30~17~21 ~32~17~21 minecraft:stone_brick_stairs 3
setblock ~31~11~21 minecraft:spruce_stairs 4
setblock ~31~12~21 minecraft:planks 1
setblock ~31~18~21 minecraft:lever 3
setblock ~35~9~21 minecraft:log 1
fill ~36~24~21 ~50~24~23 minecraft:snow
fill ~36~34~21 ~50~34~23 minecraft:snow
fill ~36~35~21 ~50~35~22 minecraft:wool 13
setblock ~39~9~21 minecraft:log 1
setblock ~43~9~21 minecraft:log 1
setblock ~43~23~21 minecraft:wooden_slab 9
setblock ~43~36~21 minecraft:wooden_slab 1
fill ~43~37~21 ~43~40~21 minecraft:fence 1
setblock ~47~9~21 minecraft:log 1
setblock ~51~9~21 minecraft:log 1
fill ~51~25~21 ~58~25~23 minecraft:snow
fill ~51~32~21 ~64~32~21 minecraft:snow
fill ~51~33~21 ~58~33~23 minecraft:snow
fill ~51~34~21 ~58~34~22 minecraft:wool 13
fill ~54~17~21 ~56~17~21 minecraft:stone_brick_stairs 3
setblock ~55~11~21 minecraft:spruce_stairs 5
fill ~55~12~21 ~55~13~21 minecraft:planks 1
setblock ~55~18~21 minecraft:lever 3
setblock ~56~12~21 minecraft:spruce_stairs 5
fill ~56~13~21 ~58~13~21 minecraft:planks 1
setblock ~59~13~21 minecraft:spruce_stairs 5
setblock ~59~14~21 minecraft:planks 1
fill ~59~26~21 ~64~26~23 minecraft:snow
fill ~59~27~21 ~64~27~21 minecraft:snow
fill ~59~30~21 ~69~30~21 minecraft:snow
fill ~59~31~21 ~64~31~21 minecraft:snow
fill ~59~33~21 ~64~33~22 minecraft:wool 13
setblock ~60~14~21 minecraft:stonebrick 0
setblock ~61~14~21 minecraft:stone_brick_stairs 6
setblock ~61~18~21 minecraft:stone_brick_stairs 3
fill ~62~14~21 ~63~14~21 minecraft:spruce_stairs 6
setblock ~63~18~21 minecraft:stone_brick_stairs 3
setblock ~64~14~21 minecraft:stone_brick_stairs 6
fill ~64~15~21 ~69~15~21 minecraft:planks 1
setblock ~65~14~21 minecraft:stonebrick 0
fill ~65~16~21 ~69~16~21 minecraft:planks 1
setblock ~65~27~21 minecraft:planks 1
fill ~65~28~21 ~69~28~22 minecraft:snow
fill ~65~29~21 ~69~29~21 minecraft:snow
setblock ~65~31~21 minecraft:planks 1
fill ~65~32~21 ~69~32~22 minecraft:wool 13
fill ~66~27~21 ~69~27~21 minecraft:spruce_stairs 6
fill ~66~31~21 ~69~31~21 minecraft:spruce_stairs 2
setblock ~67~33~21 minecraft:wooden_slab 1
fill ~67~38~21 ~67~42~21 minecraft:fence 1
setblock ~69~17~21 minecraft:stone_brick_stairs 0
setblock ~70~15~21 minecraft:spruce_stairs 5
fill ~70~16~21 ~76~16~21 minecraft:log 1
setblock ~70~17~21 minecraft:stone_brick_stairs 3
fill ~70~28~21 ~73~28~21 minecraft:planks 1
fill ~70~29~21 ~73~29~21 minecraft:wool 13
fill ~70~30~21 ~73~30~21 minecraft:planks 1
setblock ~70~31~21 minecraft:wool 13
fill ~71~17~21 ~77~17~21 minecraft:stonebrick 0
fill ~72~18~21 ~78~18~21 minecraft:fence 1
fill ~72~31~21 ~74~31~21 minecraft:fence 1
setblock ~77~16~21 minecraft:spruce_stairs 5
setblock ~78~17~21 minecraft:stone_brick_stairs 5
fill ~8~18~22 ~8~19~22 minecraft:fence 1
fill ~8~20~22 ~8~21~23 minecraft:planks 1
setblock ~8~22~22 minecraft:spruce_stairs 7
setblock ~8~23~22 minecraft:flower_pot 0
fill ~9~31~22 ~12~31~22 minecraft:fence 1
fill ~10~28~22 ~12~28~22 minecraft:planks 1
fill ~10~29~22 ~12~29~22 minecraft:wool 13
fill ~10~30~22 ~12~30~22 minecraft:planks 1
setblock ~11~12~22 minecraft:spruce_stairs 4
setblock ~11~17~22 minecraft:fence 1
setblock ~11~18~22 minecraft:wooden_pressure_plate 0
fill ~12~12~22 ~14~12~26 minecraft:planks 1
fill ~13~27~22 ~15~27~22 minecraft:spruce_stairs 6
fill ~13~28~22 ~16~28~23 minecraft:snow
fill ~13~29~22 ~16~30~22 minecraft:snow
fill ~13~31~22 ~15~31~22 minecraft:spruce_stairs 2
setblock ~15~12~22 minecraft:spruce_stairs 5
fill ~15~13~22 ~16~13~22 minecraft:planks 1
fill ~15~32~22 ~16~32~26 minecraft:wool 13
fill ~16~17~22 ~16~19~22 minecraft:planks 1
setblock ~16~20~22 minecraft:stonebrick 0
setblock ~16~27~22 minecraft:planks 1
setblock ~16~31~22 minecraft:planks 1
setblock ~17~13~22 minecraft:spruce_stairs 5
fill ~17~14~22 ~22~14~22 minecraft:planks 1
setblock ~17~17~22 minecraft:spruce_door 1
setblock ~17~19~22 minecraft:stonebrick 0
fill ~17~27~22 ~21~27~23 minecraft:snow
fill ~17~30~22 ~21~31~22 minecraft:snow
setblock ~18~17~22 minecraft:planks 1
setblock ~18~18~22 minecraft:stonebrick 0
setblock ~19~17~22 minecraft:stonebrick 0
setblock ~21~13~22 minecraft:spruce_stairs 4
fill ~22~13~22 ~28~13~22 minecraft:planks 1
fill ~22~32~22 ~27~32~23 minecraft:snow
fill ~23~17~22 ~25~17~22 minecraft:stone_brick_stairs 3
setblock ~24~18~22 minecraft:lever 3
setblock ~27~12~22 minecraft:spruce_stairs 4
fill ~28~12~22 ~30~12~22 minecraft:planks 1
fill ~28~33~22 ~35~33~23 minecraft:snow
setblock ~30~11~22 minecraft:spruce_stairs 4
setblock ~31~10~22 minecraft:spruce_stairs 4
setblock ~31~11~22 minecraft:planks 1
setblock ~32~9~22 minecraft:spruce_stairs 4
setblock ~32~10~22 minecraft:planks 1
fill ~32~11~22 ~32~11~23 minecraft:wooden_slab 9
setblock ~33~8~22 minecraft:spruce_stairs 4
setblock ~33~9~22 minecraft:planks 1
setblock ~34~7~22 minecraft:spruce_stairs 4
setblock ~34~8~22 minecraft:planks 1
setblock ~35~7~22 minecraft:stone_brick_stairs 6
setblock ~35~8~22 minecraft:log 1
fill ~36~8~22 ~38~8~22 minecraft:planks 1
setblock ~37~7~22 minecraft:stone_brick_stairs 6
setblock ~39~7~22 minecraft:stone_brick_stairs 6
setblock ~39~8~22 minecraft:log 1
fill ~40~8~22 ~42~8~22 minecraft:planks 1
setblock ~41~7~22 minecraft:stone_brick_stairs 6
setblock ~43~7~22 minecraft:stone_brick_stairs 6
setblock ~43~8~22 minecraft:log 1
setblock ~43~23~22 minecraft:spruce_stairs 6
setblock ~43~36~22 minecraft:spruce_stairs 2
fill ~43~39~22 ~43~42~22 minecraft:fence 1
fill ~44~8~22 ~46~8~22 minecraft:planks 1
setblock ~45~7~22 minecraft:stone_brick_stairs 6
setblock ~47~7~22 minecraft:stone_brick_stairs 6
setblock ~47~8~22 minecraft:log 1
fill ~48~8~22 ~50~8~22 minecraft:planks 1
setblock ~49~7~22 minecraft:stone_brick_stairs 6
setblock ~51~7~22 minecraft:stone_brick_stairs 6
setblock ~51~8~22 minecraft:log 1
setblock ~52~7~22 minecraft:spruce_stairs 5
setblock ~52~8~22 minecraft:planks 1
setblock ~53~8~22 minecraft:spruce_stairs 5
setblock ~53~9~22 minecraft:planks 1
setblock ~54~9~22 minecraft:spruce_stairs 5
setblock ~54~10~22 minecraft:planks 1
fill ~54~11~22 ~54~11~23 minecraft:wooden_slab 9
setblock ~55~10~22 minecraft:spruce_stairs 5
setblock ~55~11~22 minecraft:planks 1
setblock ~56~11~22 minecraft:spruce_stairs 5
fill ~56~12~22 ~58~12~22 minecraft:planks 1
fill ~58~13~22 ~59~13~22 minecraft:planks 1
setblock ~59~12~22 minecraft:spruce_stairs 5
fill ~59~16~22 ~59~16~28 minecraft:planks 1
fill ~59~32~22 ~64~32~23 minecraft:snow
setblock ~60~13~22 minecraft:stonebrick 0
fill ~60~16~22 ~65~16~22 minecraft:stonebrick 0
fill ~61~12~22 ~64~13~22 minecraft:planks 1
setblock ~61~14~22 minecraft:stone_brick_stairs 3
fill ~61~17~22 ~63~17~22 minecraft:stone_brick_stairs 3
setblock ~62~11~22 minecraft:spruce_stairs 6
setblock ~62~18~22 minecraft:lever 3
setblock ~64~11~22 minecraft:spruce_stairs 6
setblock ~64~14~22 minecraft:stone_brick_stairs 3
setblock ~65~13~22 minecraft:stonebrick 0
fill ~65~27~22 ~69~27~23 minecraft:snow
fill ~65~30~22 ~73~30~22 minecraft:snow
fill ~65~31~22 ~69~31~23 minecraft:snow
fill ~66~14~22 ~69~14~22 minecraft:planks 1
fill ~66~16~22 ~76~16~26 minecraft:planks 1
fill ~67~13~22 ~69~13~22 minecraft:spruce_stairs 6
setblock ~67~33~22 minecraft:spruce_stairs 2
fill ~67~41~22 ~67~45~22 minecraft:fence 1
setblock ~68~17~22 minecraft:stone_block_slab 5
fill ~69~15~22 ~76~15~22 minecraft:planks 1
setblock ~70~14~22 minecraft:spruce_stairs 5
setblock ~70~17~22 minecraft:stone_brick_stairs 0
setblock ~70~27~22 minecraft:planks 1
fill ~70~28~22 ~73~28~23 minecraft:snow
fill ~70~29~22 ~73~29~22 minecraft:snow
setblock ~70~31~22 minecraft:planks 1
fill ~70~32~22 ~71~32~26 minecraft:wool 13
fill ~71~17~22 ~77~17~22 minecraft:stone_brick_stairs 3
fill ~71~27~22 ~73~27~22 minecraft:spruce_stairs 6
fill ~71~31~22 ~73~31~22 minecraft:spruce_stairs 2
fill ~74~28~22 ~76~28~22 minecraft:planks 1
fill ~74~29~22 ~76~29~22 minecraft:wool 13
fill ~74~30~22 ~76~30~22 minecraft:planks 1
fill ~74~31~22 ~77~31~22 minecraft:fence 1
setblock ~77~15~22 minecraft:spruce_stairs 5
fill ~77~16~22 ~79~16~22 minecraft:log 1
fill ~78~17~22 ~80~17~22 minecraft:stonebrick 0
fill ~79~18~22 ~81~18~22 minecraft:fence 1
setblock ~80~16~22 minecraft:spruce_stairs 5
setblock ~81~17~22 minecraft:stone_brick_stairs 5
fill ~6~16~23 ~6~16~25 minecraft:spruce_stairs 4
fill ~6~17~23 ~6~17~25 minecraft:stonebrick 0
fill ~6~18~23 ~6~18~25 minecraft:fence 1
fill ~6~21~23 ~6~21~25 minecraft:spruce_stairs 4
fill ~6~22~23 ~6~22~25 minecraft:stonebrick 0
fill ~6~23~23 ~6~23~25 minecraft:fence 1
fill ~7~15~23 ~7~15~25 minecraft:spruce_stairs 4
fill ~7~16~23 ~7~16~25 minecraft:planks 1
setblock ~7~20~23 minecraft:spruce_stairs 4
fill ~7~21~23 ~7~21~25 minecraft:planks 1
fill ~7~22~23 ~7~22~25 minecraft:spruce_stairs 5
fill ~8~14~23 ~8~14~25 minecraft:spruce_stairs 4
setblock ~8~15~23 minecraft:planks 1
fill ~8~18~23 ~8~19~23 minecraft:planks 1
fill ~9~13~23 ~9~13~25 minecraft:spruce_stairs 4
setblock ~9~14~23 minecraft:planks 1
fill ~9~28~23 ~9~28~25 minecraft:planks 1
fill ~9~29~23 ~9~29~25 minecraft:wool 13
fill ~9~30~23 ~9~30~25 minecraft:planks 1
setblock ~9~31~23 minecraft:fence 1
fill ~10~12~23 ~10~12~25 minecraft:spruce_stairs 4
setblock ~10~13~23 minecraft:planks 1
fill ~10~16~23 ~15~16~27 minecraft:planks 1
fill ~10~17~23 ~10~17~25 minecraft:planks 1
fill ~10~18~23 ~10~18~25 minecraft:fence 1
setblock ~10~23~23 minecraft:lever 4
fill ~10~28~23 ~12~28~25 minecraft:snow
fill ~10~29~23 ~12~30~23 minecraft:snow
fill ~10~31~23 ~11~31~25 minecraft:wool 13
fill ~11~12~23 ~11~12~25 minecraft:planks 1
fill ~11~17~23 ~11~17~25 minecraft:bed 1
fill ~12~27~23 ~12~27~25 minecraft:planks 1
fill ~12~31~23 ~12~31~25 minecraft:planks 1
fill ~12~32~23 ~14~32~25 minecraft:wool 13
setblock ~13~11~23 minecraft:stone_brick_stairs 6
fill ~13~27~23 ~16~27~25 minecraft:snow
fill ~13~30~23 ~16~31~23 minecraft:snow
fill ~15~12~23 ~28~12~23 minecraft:planks 1
fill ~15~13~23 ~15~15~23 minecraft:planks 1
fill ~15~21~23 ~15~21~25 minecraft:stone_brick_stairs 1
fill ~16~13~23 ~16~15~23 minecraft:ladder 5
setblock ~16~16~23 minecraft:trapdoor 1
fill ~16~20~23 ~16~20~25 minecraft:stone_brick_stairs 1
fill ~17~13~23 ~22~13~23 minecraft:planks 1
fill ~17~16~23 ~28~16~27 minecraft:planks 1
fill ~17~19~23 ~17~19~25 minecraft:stone_brick_stairs 1
fill ~17~26~23 ~21~26~25 minecraft:snow
fill ~17~31~23 ~21~32~23 minecraft:snow
fill ~17~33~23 ~21~33~25 minecraft:wool 13
fill ~18~18~23 ~18~18~25 minecraft:stone_brick_stairs 1
fill ~19~17~23 ~19~17~25 minecraft:stone_brick_stairs 1
setblock ~21~11~23 minecraft:stone_brick_stairs 6
fill ~22~25~23 ~27~25~25 minecraft:snow
fill ~22~33~23 ~27~33~25 minecraft:snow
fill ~22~34~23 ~27~34~25 minecraft:wool 13
setblock ~27~11~23 minecraft:spruce_stairs 4
fill ~28~11~23 ~30~11~25 minecraft:planks 1
fill ~28~24~23 ~35~24~25 minecraft:snow
fill ~28~34~23 ~35~34~25 minecraft:snow
fill ~28~35~23 ~35~35~25 minecraft:wool 13
setblock ~30~10~23 minecraft:spruce_stairs 4
fill ~31~9~23 ~31~9~25 minecraft:spruce_stairs 4
fill ~31~10~23 ~31~10~25 minecraft:planks 1
setblock ~31~11~23 minecraft:wooden_slab 9
fill ~32~8~23 ~32~8~25 minecraft:spruce_stairs 4
fill ~32~9~23 ~32~9~25 minecraft:planks 1
fill ~33~7~23 ~33~7~25 minecraft:spruce_stairs 4
fill ~33~8~23 ~33~8~25 minecraft:planks 1
fill ~34~7~23 ~34~7~25 minecraft:planks 1
fill ~34~12~23 ~35~12~23 minecraft:fence 1
fill ~35~7~23 ~51~7~23 minecraft:log 1
fill ~36~23~23 ~50~23~25 minecraft:snow
fill ~36~35~23 ~50~35~25 minecraft:snow
fill ~36~36~23 ~50~36~25 minecraft:wool 13
fill ~42~37~23 ~44~37~23 minecraft:spruce_stairs 2
fill ~43~22~23 ~43~22~25 minecraft:wooden_slab 9
fill ~43~41~23 ~43~44~23 minecraft:fence 1
fill ~51~12~23 ~52~12~23 minecraft:fence 1
fill ~51~24~23 ~58~24~25 minecraft:snow
fill ~51~34~23 ~58~34~25 minecraft:snow
fill ~51~35~23 ~58~35~25 minecraft:wool 13
fill ~52~7~23 ~52~7~25 minecraft:planks 1
fill ~53~7~23 ~53~7~25 minecraft:spruce_stairs 5
fill ~53~8~23 ~53~8~25 minecraft:planks 1
fill ~54~8~23 ~54~8~25 minecraft:spruce_stairs 5
fill ~54~9~23 ~54~9~25 minecraft:planks 1
fill ~55~9~23 ~55~9~25 minecraft:spruce_stairs 5
fill ~55~10~23 ~55~10~25 minecraft:planks 1
setblock ~55~11~23 minecraft:wooden_slab 9
setblock ~56~10~23 minecraft:spruce_stairs 5
fill ~56~11~23 ~58~11~25 minecraft:planks 1
fill ~58~12~23 ~59~12~23 minecraft:planks 1
setblock ~59~11~23 minecraft:spruce_stairs 5
fill ~59~25~23 ~64~25~25 minecraft:snow
fill ~59~33~23 ~64~33~25 minecraft:snow
fill ~59~34~23 ~64~34~25 minecraft:wool 13
setblock ~60~12~23 minecraft:stonebrick 0
fill ~60~16~23 ~60~16~26 minecraft:stonebrick 0
setblock ~61~0~23 minecraft:stone_brick_stairs 4
setblock ~61~1~23 minecraft:stone_brick_stairs 2
fill ~61~12~23 ~64~12~23 minecraft:stained_glass 13
fill ~61~16~23 ~64~16~23 minecraft:stained_glass 13
fill ~61~21~23 ~61~23~23 minecraft:cobblestone_wall 0
setblock ~61~24~23 minecraft:cobblestone_wall 0
fill ~62~1~23 ~63~1~25 minecraft:stonebrick 0
fill ~62~21~23 ~64~21~23 minecraft:cobblestone_wall 0
fill ~62~22~23 ~63~22~23 minecraft:spruce_stairs 6
fill ~62~23~23 ~63~23~23 minecraft:spruce_stairs 2
setblock ~64~0~23 minecraft:stone_brick_stairs 5
setblock ~64~1~23 minecraft:stone_brick_stairs 2
fill ~64~22~23 ~64~23~23 minecraft:cobblestone_wall 0
setblock ~64~24~23 minecraft:cobblestone_wall 0
setblock ~65~12~23 minecraft:stonebrick 0
fill ~65~16~23 ~65~16~26 minecraft:stonebrick 0
setblock ~65~21~23 minecraft:stone_brick_stairs 6
fill ~65~22~23 ~65~22~25 minecraft:stonebrick 0
setblock ~65~23~23 minecraft:stone_brick_stairs 2
fill ~65~26~23 ~69~26~25 minecraft:snow
fill ~65~32~23 ~69~32~25 minecraft:snow
fill ~65~33~23 ~69~33~25 minecraft:wool 13
fill ~66~13~23 ~69~13~23 minecraft:planks 1
fill ~66~34~23 ~68~34~23 minecraft:spruce_stairs 2
fill ~67~12~23 ~69~12~25 minecraft:planks 1
setblock ~67~17~23 minecraft:stone_brick_stairs 0
fill ~67~44~23 ~67~47~23 minecraft:fence 1
fill ~68~11~23 ~69~11~25 minecraft:planks 1
setblock ~68~17~23 minecraft:stonebrick 0
setblock ~68~18~23 minecraft:cobblestone_wall 0
fill ~68~19~23 ~68~21~23 minecraft:cobblestone_wall 0
setblock ~68~22~23 minecraft:cobblestone_wall 0
fill ~69~10~23 ~70~10~25 minecraft:planks 1
fill ~69~14~23 ~76~14~23 minecraft:planks 1
setblock ~69~17~23 minecraft:stone_brick_stairs 1
setblock ~70~9~23 minecraft:wooden_slab 9
fill ~70~11~23 ~70~12~23 minecraft:wooden_slab 1
setblock ~70~13~23 minecraft:spruce_stairs 5
setblock ~70~18~23 minecraft:lever 4
fill ~70~27~23 ~73~27~25 minecraft:snow
fill ~70~30~23 ~76~30~23 minecraft:snow
fill ~70~31~23 ~73~31~25 minecraft:snow
setblock ~71~10~23 minecraft:wooden_slab 1
fill ~72~32~23 ~74~32~25 minecraft:wool 13
fill ~74~27~23 ~74~27~25 minecraft:planks 1
fill ~74~28~23 ~76~28~25 minecraft:snow
fill ~74~29~23 ~76~29~23 minecraft:snow
fill ~74~31~23 ~74~31~25 minecraft:planks 1
fill ~75~31~23 ~76~31~25 minecraft:wool 13
fill ~76~15~23 ~79~15~23 minecraft:planks 1
setblock ~77~14~23 minecraft:spruce_stairs 5
fill ~77~16~23 ~79~16~25 minecraft:planks 1
fill ~77~28~23 ~77~28~25 minecraft:planks 1
fill ~77~29~23 ~77~29~25 minecraft:wool 13
fill ~77~30~23 ~77~30~25 minecraft:planks 1
setblock ~77~31~23 minecraft:fence 1
fill ~78~17~23 ~80~17~23 minecraft:stone_brick_stairs 3
setblock ~80~15~23 minecraft:spruce_stairs 5
fill ~80~16~23 ~82~16~23 minecraft:log 1
fill ~81~17~23 ~83~17~23 minecraft:stonebrick 0
fill ~82~18~23 ~84~18~23 minecraft:fence 1
setblock ~83~16~23 minecraft:spruce_stairs 5
setblock ~84~17~23 minecraft:stone_brick_stairs 5
setblock ~8~17~24 minecraft:spruce_door 0
fill ~8~19~24 ~8~19~25 minecraft:planks 1
setblock ~8~20~24 minecraft:fence 1
fill ~8~21~24 ~8~21~27 minecraft:planks 1
setblock ~9~23~24 minecraft:stone_button 4
setblock ~9~31~24 minecraft:planks 1
setblock ~10~22~24 minecraft:lever 7
setblock ~10~23~24 minecraft:log 1
setblock ~10~24~24 minecraft:lever 5
fill ~10~29~24 ~10~30~25 minecraft:snow
setblock ~10~32~24 minecraft:wooden_slab 1
setblock ~11~22~24 minecraft:cobblestone_wall 0
setblock ~11~23~24 minecraft:fence 1
fill ~11~30~24 ~12~30~25 minecraft:snow
setblock ~11~32~24 minecraft:spruce_stairs 0
setblock ~12~11~24 minecraft:stone_brick_stairs 4
setblock ~12~22~24 minecraft:spruce_stairs 1
fill ~12~33~24 ~15~33~24 minecraft:wooden_slab 1
setblock ~13~8~24 minecraft:stone_brick_stairs 4
setblock ~13~9~24 minecraft:cobblestone_wall 0
fill ~13~10~24 ~13~11~24 minecraft:stonebrick 0
fill ~13~31~24 ~16~31~25 minecraft:snow
fill ~14~8~24 ~20~8~24 minecraft:iron_block
setblock ~14~11~24 minecraft:stone_brick_stairs 5
fill ~15~0~24 ~15~5~24 minecraft:fence 1
setblock ~15~6~24 minecraft:cobblestone_wall 0
setblock ~15~7~24 minecraft:fence 1
fill ~15~9~24 ~15~11~24 minecraft:fence 1
fill ~15~12~24 ~22~12~25 minecraft:planks 1
setblock ~15~17~24 minecraft:spruce_door 2
fill ~15~19~24 ~15~20~27 minecraft:planks 1
fill ~16~6~24 ~18~6~24 minecraft:cobblestone_wall 0
setblock ~16~9~24 minecraft:torch 5
setblock ~16~16~24 minecraft:planks 1
setblock ~16~33~24 minecraft:spruce_stairs 0
setblock ~17~1~24 minecraft:fence 1
setblock ~17~2~24 minecraft:cobblestone_wall 0
setblock ~17~3~24 minecraft:fence 1
setblock ~17~4~24 minecraft:cobblestone_wall 0
setblock ~17~5~24 minecraft:fence 1
setblock ~17~7~24 minecraft:fence 1
fill ~17~9~24 ~17~11~24 minecraft:fence 1
fill ~17~32~24 ~21~32~25 minecraft:snow
fill ~17~34~24 ~20~34~24 minecraft:wooden_slab 1
setblock ~18~9~24 minecraft:torch 5
fill ~19~3~24 ~19~5~24 minecraft:fence 1
setblock ~19~6~24 minecraft:cobblestone_wall 0
setblock ~19~7~24 minecraft:fence 1
fill ~19~9~24 ~19~11~24 minecraft:fence 1
setblock ~20~11~24 minecraft:stone_brick_stairs 4
setblock ~21~8~24 minecraft:stone_brick_stairs 5
setblock ~21~9~24 minecraft:cobblestone_wall 0
fill ~21~10~24 ~21~11~24 minecraft:stonebrick 0
setblock ~21~34~24 minecraft:spruce_stairs 0
setblock ~22~11~24 minecraft:stone_brick_stairs 5
fill ~22~35~24 ~26~35~24 minecraft:wooden_slab 1
setblock ~23~11~24 minecraft:spruce_stairs 4
setblock ~23~12~24 minecraft:spruce_stairs 1
fill ~24~11~24 ~27~11~24 minecraft:planks 1
setblock ~25~10~24 minecraft:spruce_stairs 4
setblock ~26~9~24 minecraft:stone_brick_stairs 4
fill ~26~10~24 ~30~10~24 minecraft:planks 1
setblock ~27~4~24 minecraft:fence 1
setblock ~27~5~24 minecraft:cobblestone_wall 0
setblock ~27~6~24 minecraft:fence 1
setblock ~27~7~24 minecraft:cobblestone_wall 0
fill ~27~8~24 ~27~9~24 minecraft:fence 1
setblock ~27~35~24 minecraft:spruce_stairs 0
setblock ~28~7~24 minecraft:cobblestone_wall 0
setblock ~28~8~24 minecraft:torch 5
fill ~28~36~24 ~31~36~24 minecraft:wooden_slab 1
setblock ~29~6~24 minecraft:fence 1
setblock ~29~7~24 minecraft:cobblestone_wall 0
fill ~29~8~24 ~29~9~24 minecraft:fence 1
setblock ~30~9~24 minecraft:stone_brick_stairs 5
setblock ~31~11~24 minecraft:spruce_stairs 1
setblock ~32~10~24 minecraft:spruce_stairs 1
setblock ~32~36~24 minecraft:planks 1
setblock ~32~37~24 minecraft:fence 1
setblock ~33~9~24 minecraft:spruce_stairs 1
fill ~33~36~24 ~34~36~24 minecraft:wooden_slab 1
fill ~33~37~24 ~34~37~24 minecraft:wool 13
setblock ~34~8~24 minecraft:spruce_stairs 1
fill ~34~38~24 ~35~38~24 minecraft:wool 13
fill ~35~7~24 ~51~7~24 minecraft:planks 1
fill ~35~11~24 ~51~11~29 minecraft:wooden_slab 9
fill ~35~12~24 ~35~12~25 minecraft:fence 1
setblock ~35~36~24 minecraft:spruce_stairs 0
fill ~35~39~24 ~41~39~24 minecraft:wool 13
fill ~36~37~24 ~41~37~24 minecraft:wooden_slab 1
fill ~36~40~24 ~37~40~24 minecraft:wool 13
fill ~37~41~24 ~38~41~24 minecraft:wool 13
fill ~38~42~24 ~41~42~24 minecraft:wool 13
fill ~40~40~24 ~40~40~25 minecraft:wool 13
setblock ~40~41~24 minecraft:wool 13
setblock ~41~38~24 minecraft:wool 13
setblock ~42~37~24 minecraft:spruce_stairs 0
setblock ~42~38~24 minecraft:fence 1
setblock ~42~42~24 minecraft:fence 1
fill ~43~37~24 ~43~44~24 minecraft:log 1
setblock ~43~45~24 minecraft:stonebrick 0
setblock ~43~46~24 minecraft:cobblestone_wall 0
setblock ~43~47~24 minecraft:fence 1
setblock ~44~37~24 minecraft:spruce_stairs 1
setblock ~44~38~24 minecraft:fence 1
setblock ~44~42~24 minecraft:fence 1
fill ~44~44~24 ~48~44~24 minecraft:fence 1
fill ~45~37~24 ~50~37~24 minecraft:wooden_slab 1
fill ~45~38~24 ~46~38~24 minecraft:wool 13
fill ~45~42~24 ~50~42~24 minecraft:wool 13
fill ~46~39~24 ~48~39~24 minecraft:wool 13
fill ~46~41~24 ~47~41~24 minecraft:wool 13
fill ~47~40~24 ~57~40~24 minecraft:wool 13
fill ~48~45~24 ~53~45~24 minecraft:fence 1
fill ~50~43~24 ~55~43~24 minecraft:wool 13
fill ~51~12~24 ~51~12~25 minecraft:fence 1
setblock ~51~36~24 minecraft:spruce_stairs 1
setblock ~52~8~24 minecraft:spruce_stairs 0
fill ~52~36~24 ~58~36~24 minecraft:wooden_slab 1
setblock ~53~9~24 minecraft:spruce_stairs 0
fill ~53~46~24 ~58~46~24 minecraft:fence 1
setblock ~54~10~24 minecraft:spruce_stairs 0
fill ~54~39~24 ~59~39~24 minecraft:wool 13
setblock ~55~11~24 minecraft:spruce_stairs 0
fill ~55~44~24 ~60~44~24 minecraft:wool 13
fill ~56~10~24 ~58~10~24 minecraft:planks 1
fill ~58~38~24 ~63~38~24 minecraft:wool 13
fill ~58~47~24 ~66~47~24 minecraft:fence 1
setblock ~59~10~24 minecraft:spruce_stairs 5
setblock ~59~11~24 minecraft:planks 1
setblock ~59~35~24 minecraft:spruce_stairs 1
setblock ~60~11~24 minecraft:stonebrick 0
fill ~60~35~24 ~64~35~24 minecraft:wooden_slab 1
fill ~60~45~24 ~65~45~24 minecraft:wool 13
setblock ~61~1~24 minecraft:stone_brick_stairs 0
setblock ~61~11~24 minecraft:stained_glass 13
fill ~61~16~24 ~61~16~25 minecraft:stained_glass 13
setblock ~61~21~24 minecraft:cobblestone_wall 0
setblock ~61~22~24 minecraft:spruce_stairs 4
setblock ~61~23~24 minecraft:spruce_stairs 0
fill ~61~37~24 ~64~37~24 minecraft:wool 13
fill ~61~40~24 ~62~40~24 minecraft:wool 13
fill ~61~41~24 ~61~42~25 minecraft:wool 13
setblock ~62~2~24 minecraft:cobblestone_wall 0
fill ~62~3~24 ~63~5~24 minecraft:fence 1
setblock ~62~6~24 minecraft:cobblestone_wall 0
fill ~62~7~24 ~63~9~24 minecraft:fence 1
setblock ~62~10~24 minecraft:cobblestone_wall 0
fill ~62~11~24 ~63~22~24 minecraft:fence 1
fill ~62~23~24 ~63~23~24 minecraft:planks 1
fill ~62~39~24 ~63~39~24 minecraft:wool 13
fill ~62~42~24 ~62~43~24 minecraft:wool 13
setblock ~63~2~24 minecraft:cobblestone_wall 0
setblock ~63~6~24 minecraft:cobblestone_wall 0
setblock ~63~10~24 minecraft:cobblestone_wall 0
fill ~63~36~24 ~65~36~24 minecraft:wool 13
fill ~63~43~24 ~63~44~24 minecraft:wool 13
setblock ~64~1~24 minecraft:stone_brick_stairs 1
setblock ~64~11~24 minecraft:stained_glass 13
fill ~64~16~24 ~64~16~25 minecraft:stained_glass 13
setblock ~64~21~24 minecraft:cobblestone_wall 0
setblock ~64~22~24 minecraft:spruce_stairs 5
setblock ~64~23~24 minecraft:spruce_stairs 1
setblock ~64~44~24 minecraft:wool 13
setblock ~65~11~24 minecraft:stonebrick 0
setblock ~65~21~24 minecraft:stonebrick 0
setblock ~65~23~24 minecraft:stonebrick 0
setblock ~65~34~24 minecraft:spruce_stairs 1
setblock ~65~35~24 minecraft:wool 13
setblock ~66~11~24 minecraft:spruce_stairs 4
setblock ~66~12~24 minecraft:planks 1
fill ~66~22~24 ~67~22~24 minecraft:iron_bars
setblock ~66~34~24 minecraft:spruce_stairs 0
setblock ~66~35~24 minecraft:fence 1
setblock ~66~45~24 minecraft:fence 1
setblock ~67~10~24 minecraft:spruce_stairs 4
setblock ~67~11~24 minecraft:planks 1
fill ~67~34~24 ~67~47~24 minecraft:log 1
setblock ~67~48~24 minecraft:stonebrick 0
setblock ~67~49~24 minecraft:cobblestone_wall 0
setblock ~67~50~24 minecraft:fence 1
setblock ~68~10~24 minecraft:planks 1
setblock ~68~17~24 minecraft:stone_block_slab 5
setblock ~68~18~24 minecraft:stonebrick 0
setblock ~68~22~24 minecraft:stonebrick 0
setblock ~68~34~24 minecraft:spruce_stairs 1
setblock ~68~36~24 minecraft:fence 1
setblock ~68~45~24 minecraft:fence 1
setblock ~69~9~24 minecraft:spruce_stairs 4
fill ~69~13~24 ~76~13~24 minecraft:planks 1
setblock ~69~18~24 minecraft:cobblestone_wall 0
setblock ~69~34~24 minecraft:wooden_slab 1
fill ~69~36~24 ~69~38~24 minecraft:wool 13
fill ~69~42~24 ~70~43~24 minecraft:wool 13
fill ~69~44~24 ~69~45~24 minecraft:wool 13
fill ~70~9~24 ~73~9~24 minecraft:planks 1
fill ~70~11~24 ~70~12~24 minecraft:planks 1
setblock ~70~17~24 minecraft:lever 7
setblock ~70~18~24 minecraft:log 1
setblock ~70~19~24 minecraft:lever 5
setblock ~70~33~24 minecraft:spruce_stairs 1
fill ~70~37~24 ~72~37~24 minecraft:wool 13
fill ~70~38~24 ~71~41~24 minecraft:wool 13
setblock ~71~10~24 minecraft:planks 1
setblock ~71~11~24 minecraft:spruce_stairs 1
setblock ~71~18~24 minecraft:stone_button 5
fill ~71~33~24 ~72~33~24 minecraft:wooden_slab 1
fill ~71~36~24 ~72~36~24 minecraft:wool 13
setblock ~72~10~24 minecraft:wooden_slab 1
fill ~72~35~24 ~73~35~24 minecraft:wool 13
fill ~73~8~24 ~76~8~24 minecraft:wooden_slab 9
setblock ~73~33~24 minecraft:planks 1
setblock ~73~34~24 minecraft:fence 1
setblock ~74~9~24 minecraft:spruce_stairs 1
fill ~74~30~24 ~76~30~25 minecraft:snow
setblock ~74~33~24 minecraft:wooden_slab 1
setblock ~75~32~24 minecraft:spruce_stairs 1
fill ~76~14~24 ~79~14~24 minecraft:planks 1
fill ~76~29~24 ~76~29~25 minecraft:snow
setblock ~76~32~24 minecraft:wooden_slab 1
setblock ~77~13~24 minecraft:spruce_stairs 5
setblock ~77~31~24 minecraft:planks 1
fill ~79~15~24 ~82~15~24 minecraft:planks 1
setblock ~80~14~24 minecraft:spruce_stairs 5
fill ~80~16~24 ~82~16~24 minecraft:planks 1
fill ~81~17~24 ~82~17~24 minecraft:stone_block_slab 5
setblock ~83~15~24 minecraft:spruce_stairs 5
fill ~83~16~24 ~85~16~24 minecraft:log 1
setblock ~83~17~24 minecraft:stone_brick_stairs 0
fill ~84~17~24 ~86~17~24 minecraft:stonebrick 0
fill ~85~18~24 ~87~18~24 minecraft:fence 1
setblock ~86~16~24 minecraft:spruce_stairs 5
setblock ~87~17~24 minecraft:stone_brick_stairs 5
setblock ~7~20~25 minecraft:spruce_stairs 4
setblock ~7~23~25 minecraft:lever 6
setblock ~8~15~25 minecraft:planks 1
fill ~8~17~25 ~8~17~27 minecraft:planks 1
setblock ~8~18~25 minecraft:planks 1
fill ~8~20~25 ~8~20~27 minecraft:planks 1
setblock ~9~14~25 minecraft:planks 1
fill ~9~31~25 ~9~31~26 minecraft:fence 1
setblock ~10~13~25 minecraft:planks 1
setblock ~10~23~25 minecraft:lever 3
fill ~11~29~25 ~12~29~25 minecraft:snow
setblock ~13~11~25 minecraft:stone_brick_stairs 7
fill ~13~28~25 ~16~28~26 minecraft:snow
fill ~13~30~25 ~16~30~26 minecraft:snow
fill ~15~13~25 ~15~13~27 minecraft:planks 1
fill ~15~14~25 ~15~15~25 minecraft:planks 1
fill ~15~17~25 ~15~18~27 minecraft:planks 1
fill ~16~13~25 ~16~15~25 minecraft:ladder 5
setblock ~16~16~25 minecraft:trapdoor 1
fill ~17~13~25 ~22~13~25 minecraft:planks 1
fill ~17~27~25 ~21~27~26 minecraft:snow
fill ~17~31~25 ~21~31~26 minecraft:snow
setblock ~21~11~25 minecraft:stone_brick_stairs 7
fill ~22~26~25 ~27~26~27 minecraft:snow
fill ~22~32~25 ~27~32~27 minecraft:snow
fill ~23~12~25 ~28~12~25 minecraft:planks 1
setblock ~27~11~25 minecraft:spruce_stairs 4
fill ~28~25~25 ~35~25~27 minecraft:snow
fill ~28~33~25 ~35~33~27 minecraft:snow
setblock ~30~10~25 minecraft:spruce_stairs 4
fill ~31~11~25 ~34~11~25 minecraft:wooden_slab 9
setblock ~34~12~25 minecraft:fence 1
fill ~35~7~25 ~51~7~25 minecraft:log 1
fill ~36~24~25 ~50~24~27 minecraft:snow
fill ~36~34~25 ~50~34~27 minecraft:snow
fill ~37~40~25 ~39~40~25 minecraft:wool 13
setblock ~39~41~25 minecraft:wool 13
fill ~42~37~25 ~44~37~25 minecraft:spruce_stairs 3
fill ~43~41~25 ~43~42~26 minecraft:fence 1
fill ~43~43~25 ~43~44~25 minecraft:fence 1
fill ~47~41~25 ~58~41~25 minecraft:wool 13
fill ~50~42~25 ~56~42~25 minecraft:wool 13
fill ~51~25~25 ~58~25~27 minecraft:snow
fill ~51~33~25 ~58~33~27 minecraft:snow
fill ~52~11~25 ~55~11~25 minecraft:wooden_slab 9
setblock ~52~12~25 minecraft:fence 1
fill ~55~43~25 ~62~43~25 minecraft:wool 13
setblock ~56~10~25 minecraft:spruce_stairs 5
fill ~57~40~25 ~61~40~25 minecraft:wool 13
fill ~58~12~25 ~59~12~25 minecraft:planks 1
setblock ~59~11~25 minecraft:spruce_stairs 5
fill ~59~26~25 ~64~26~27 minecraft:snow
fill ~59~32~25 ~64~32~27 minecraft:snow
setblock ~60~12~25 minecraft:stonebrick 0
fill ~60~39~25 ~62~39~25 minecraft:wool 13
fill ~60~41~25 ~60~42~26 minecraft:wool 13
setblock ~61~0~25 minecraft:stone_brick_stairs 4
setblock ~61~1~25 minecraft:stone_brick_stairs 3
fill ~61~12~25 ~64~12~25 minecraft:stained_glass 13
fill ~61~21~25 ~61~23~25 minecraft:cobblestone_wall 0
setblock ~61~24~25 minecraft:cobblestone_wall 0
fill ~61~44~25 ~63~44~25 minecraft:wool 13
fill ~62~16~25 ~63~16~25 minecraft:stained_glass 13
fill ~62~21~25 ~64~21~25 minecraft:cobblestone_wall 0
fill ~62~22~25 ~63~22~25 minecraft:spruce_stairs 7
fill ~62~23~25 ~63~23~25 minecraft:spruce_stairs 3
setblock ~64~0~25 minecraft:stone_brick_stairs 5
setblock ~64~1~25 minecraft:stone_brick_stairs 3
fill ~64~22~25 ~64~23~25 minecraft:cobblestone_wall 0
setblock ~64~24~25 minecraft:cobblestone_wall 0
setblock ~65~12~25 minecraft:stonebrick 0
setblock ~65~21~25 minecraft:stone_brick_stairs 7
setblock ~65~23~25 minecraft:stone_brick_stairs 3
fill ~65~27~25 ~69~27~26 minecraft:snow
fill ~65~31~25 ~69~31~26 minecraft:snow
fill ~66~13~25 ~69~13~25 minecraft:planks 1
fill ~66~34~25 ~68~34~25 minecraft:spruce_stairs 3
setblock ~67~17~25 minecraft:stone_brick_stairs 0
fill ~67~44~25 ~67~45~26 minecraft:fence 1
fill ~67~46~25 ~67~47~25 minecraft:fence 1
setblock ~68~17~25 minecraft:stonebrick 0
setblock ~68~18~25 minecraft:cobblestone_wall 0
fill ~68~19~25 ~68~21~25 minecraft:cobblestone_wall 0
setblock ~68~22~25 minecraft:cobblestone_wall 0
fill ~69~14~25 ~76~14~25 minecraft:planks 1
setblock ~69~17~25 minecraft:stone_brick_stairs 1
setblock ~70~9~25 minecraft:wooden_slab 9
fill ~70~11~25 ~70~12~25 minecraft:wooden_slab 1
setblock ~70~13~25 minecraft:spruce_stairs 5
setblock ~70~18~25 minecraft:lever 3
fill ~70~28~25 ~73~28~26 minecraft:snow
fill ~70~30~25 ~73~30~26 minecraft:snow
setblock ~71~10~25 minecraft:wooden_slab 1
fill ~74~29~25 ~75~29~25 minecraft:snow
fill ~76~15~25 ~79~15~25 minecraft:planks 1
setblock ~77~14~25 minecraft:spruce_stairs 5
fill ~77~31~25 ~77~31~26 minecraft:fence 1
fill ~78~17~25 ~80~17~25 minecraft:stone_brick_stairs 2
setblock ~80~15~25 minecraft:spruce_stairs 5
fill ~80~16~25 ~82~16~25 minecraft:log 1
fill ~81~17~25 ~83~17~25 minecraft:stonebrick 0
fill ~82~18~25 ~84~18~25 minecraft:fence 1
setblock ~83~16~25 minecraft:spruce_stairs 5
setblock ~84~17~25 minecraft:stone_brick_stairs 5
fill ~7~16~26 ~7~16~27 minecraft:spruce_stairs 4
fill ~7~17~26 ~7~17~27 minecraft:stonebrick 0
fill ~7~18~26 ~8~18~26 minecraft:fence 1
fill ~7~21~26 ~7~21~27 minecraft:spruce_stairs 4
fill ~7~22~26 ~7~22~27 minecraft:stonebrick 0
fill ~7~23~26 ~7~23~27 minecraft:fence 1
fill ~8~15~26 ~8~15~27 minecraft:spruce_stairs 4
setblock ~8~19~26 minecraft:fence 1
setblock ~8~22~26 minecraft:spruce_stairs 6
setblock ~8~23~26 minecraft:heavy_weighted_pressure_plate 0
fill ~9~14~26 ~9~14~27 minecraft:spruce_stairs 4
fill ~10~13~26 ~10~13~27 minecraft:spruce_stairs 4
fill ~10~28~26 ~12~28~26 minecraft:planks 1
fill ~10~29~26 ~12~29~26 minecraft:wool 13
fill ~10~30~26 ~12~30~26 minecraft:planks 1
fill ~10~31~26 ~12~31~26 minecraft:fence 1
setblock ~11~12~26 minecraft:spruce_stairs 4
setblock ~11~17~26 minecraft:fence 1
setblock ~11~18~26 minecraft:wooden_pressure_plate 0
fill ~13~27~26 ~15~27~26 minecraft:spruce_stairs 7
fill ~13~29~26 ~16~29~26 minecraft:snow
fill ~13~31~26 ~15~31~26 minecraft:spruce_stairs 3
fill ~14~17~26 ~14~17~27 minecraft:furnace 4
fill ~14~18~26 ~14~18~27 minecraft:wooden_pressure_plate 0
setblock ~14~20~26 minecraft:fence 1
setblock ~15~12~26 minecraft:spruce_stairs 5
fill ~15~21~26 ~15~21~28 minecraft:stonebrick 0
fill ~15~22~26 ~15~22~28 minecraft:fence 1
setblock ~16~13~26 minecraft:planks 1
fill ~16~16~26 ~16~16~27 minecraft:planks 1
fill ~16~17~26 ~16~19~26 minecraft:planks 1
setblock ~16~20~26 minecraft:stonebrick 0
setblock ~16~27~26 minecraft:planks 1
setblock ~16~31~26 minecraft:planks 1
setblock ~17~13~26 minecraft:spruce_stairs 5
fill ~17~14~26 ~22~14~26 minecraft:planks 1
setblock ~17~17~26 minecraft:spruce_door 3
setblock ~17~19~26 minecraft:stonebrick 0
fill ~17~28~26 ~21~28~27 minecraft:snow
fill ~17~30~26 ~21~30~27 minecraft:snow
fill ~17~32~26 ~21~32~27 minecraft:wool 13
setblock ~18~17~26 minecraft:planks 1
setblock ~18~18~26 minecraft:stonebrick 0
setblock ~19~17~26 minecraft:stonebrick 0
setblock ~21~13~26 minecraft:spruce_stairs 4
fill ~22~13~26 ~28~13~26 minecraft:planks 1
fill ~22~33~26 ~27~33~27 minecraft:wool 13
fill ~23~17~26 ~25~17~26 minecraft:stone_brick_stairs 2
setblock ~24~18~26 minecraft:lever 4
setblock ~27~12~26 minecraft:spruce_stairs 4
fill ~28~12~26 ~30~12~26 minecraft:planks 1
fill ~28~34~26 ~35~34~27 minecraft:wool 13
setblock ~30~11~26 minecraft:spruce_stairs 4
setblock ~31~10~26 minecraft:spruce_stairs 4
setblock ~31~11~26 minecraft:planks 1
setblock ~32~9~26 minecraft:spruce_stairs 4
setblock ~32~10~26 minecraft:planks 1
fill ~32~11~26 ~34~11~26 minecraft:wooden_slab 9
setblock ~33~8~26 minecraft:spruce_stairs 4
setblock ~33~9~26 minecraft:planks 1
setblock ~34~7~26 minecraft:spruce_stairs 4
setblock ~34~8~26 minecraft:planks 1
setblock ~35~7~26 minecraft:stone_brick_stairs 7
setblock ~35~8~26 minecraft:log 1
fill ~36~8~26 ~38~8~26 minecraft:planks 1
fill ~36~35~26 ~50~35~27 minecraft:wool 13
setblock ~37~7~26 minecraft:stone_brick_stairs 7
setblock ~39~7~26 minecraft:stone_brick_stairs 7
setblock ~39~8~26 minecraft:log 1
fill ~40~8~26 ~42~8~26 minecraft:planks 1
setblock ~41~7~26 minecraft:stone_brick_stairs 7
setblock ~43~7~26 minecraft:stone_brick_stairs 7
setblock ~43~8~26 minecraft:log 1
setblock ~43~23~26 minecraft:spruce_stairs 7
setblock ~43~36~26 minecraft:spruce_stairs 3
fill ~43~39~26 ~43~40~27 minecraft:fence 1
fill ~44~8~26 ~46~8~26 minecraft:planks 1
setblock ~45~7~26 minecraft:stone_brick_stairs 7
setblock ~47~7~26 minecraft:stone_brick_stairs 7
setblock ~47~8~26 minecraft:log 1
fill ~48~8~26 ~50~8~26 minecraft:planks 1
setblock ~49~7~26 minecraft:stone_brick_stairs 7
setblock ~51~7~26 minecraft:stone_brick_stairs 7
setblock ~51~8~26 minecraft:log 1
fill ~51~34~26 ~58~34~27 minecraft:wool 13
setblock ~52~7~26 minecraft:spruce_stairs 5
setblock ~52~8~26 minecraft:planks 1
fill ~52~11~26 ~54~11~26 minecraft:wooden_slab 9
setblock ~53~8~26 minecraft:spruce_stairs 5
setblock ~53~9~26 minecraft:planks 1
setblock ~54~9~26 minecraft:spruce_stairs 5
setblock ~54~10~26 minecraft:planks 1
setblock ~55~10~26 minecraft:spruce_stairs 5
setblock ~55~11~26 minecraft:planks 1
setblock ~56~11~26 minecraft:spruce_stairs 5
fill ~56~12~26 ~58~12~26 minecraft:planks 1
fill ~56~42~26 ~59~42~26 minecraft:wool 13
fill ~58~13~26 ~59~13~26 minecraft:planks 1
fill ~58~41~26 ~59~41~26 minecraft:wool 13
setblock ~59~12~26 minecraft:spruce_stairs 5
fill ~59~33~26 ~64~33~27 minecraft:wool 13
setblock ~60~13~26 minecraft:stonebrick 0
setblock ~61~11~26 minecraft:spruce_stairs 7
fill ~61~12~26 ~64~13~26 minecraft:planks 1
setblock ~61~14~26 minecraft:stone_brick_stairs 2
fill ~61~16~26 ~64~16~26 minecraft:stonebrick 0
fill ~61~17~26 ~63~17~26 minecraft:stone_brick_stairs 2
setblock ~62~18~26 minecraft:lever 4
setblock ~63~11~26 minecraft:spruce_stairs 7
setblock ~64~14~26 minecraft:stone_brick_stairs 2
setblock ~65~13~26 minecraft:stonebrick 0
fill ~65~28~26 ~69~28~27 minecraft:snow
fill ~65~30~26 ~69~30~27 minecraft:snow
fill ~65~32~26 ~69~32~27 minecraft:wool 13
fill ~66~14~26 ~69~14~26 minecraft:planks 1
fill ~67~13~26 ~69~13~26 minecraft:spruce_stairs 7
setblock ~67~33~26 minecraft:spruce_stairs 3
fill ~67~41~26 ~67~42~27 minecraft:fence 1
setblock ~67~43~26 minecraft:fence 1
setblock ~68~17~26 minecraft:stone_block_slab 5
fill ~69~15~26 ~76~15~26 minecraft:planks 1
setblock ~70~14~26 minecraft:spruce_stairs 5
setblock ~70~17~26 minecraft:stone_brick_stairs 0
setblock ~70~27~26 minecraft:planks 1
fill ~70~29~26 ~73~29~26 minecraft:snow
setblock ~70~31~26 minecraft:planks 1
fill ~71~17~26 ~77~17~26 minecraft:stone_brick_stairs 2
fill ~71~27~26 ~73~27~26 minecraft:spruce_stairs 7
fill ~71~31~26 ~73~31~26 minecraft:spruce_stairs 3
fill ~74~28~26 ~76~28~26 minecraft:planks 1
fill ~74~29~26 ~76~29~26 minecraft:wool 13
fill ~74~30~26 ~76~30~26 minecraft:planks 1
fill ~74~31~26 ~76~31~26 minecraft:fence 1
setblock ~77~15~26 minecraft:spruce_stairs 5
fill ~77~16~26 ~79~16~26 minecraft:log 1
fill ~78~17~26 ~80~17~26 minecraft:stonebrick 0
fill ~79~18~26 ~81~18~26 minecraft:fence 1
setblock ~80~16~26 minecraft:spruce_stairs 5
setblock ~81~17~26 minecraft:stone_brick_stairs 5
setblock ~7~18~27 minecraft:fence 1
fill ~8~18~27 ~8~19~27 minecraft:planks 1
setblock ~9~15~27 minecraft:planks 1
setblock ~9~17~27 minecraft:crafting_table
setblock ~10~14~27 minecraft:planks 1
fill ~11~13~27 ~14~13~27 minecraft:planks 1
fill ~12~31~27 ~15~31~27 minecraft:fence 1
fill ~13~28~27 ~16~28~27 minecraft:planks 1
fill ~13~29~27 ~16~29~27 minecraft:wool 13
fill ~13~30~27 ~16~30~27 minecraft:planks 1
setblock ~14~19~27 minecraft:fence 1
setblock ~16~13~27 minecraft:spruce_stairs 5
setblock ~16~14~27 minecraft:planks 1
setblock ~16~31~27 minecraft:wool 13
setblock ~17~14~27 minecraft:spruce_stairs 5
fill ~17~15~27 ~22~15~27 minecraft:planks 1
fill ~17~27~27 ~20~27~27 minecraft:spruce_stairs 7
fill ~17~29~27 ~21~29~27 minecraft:snow
fill ~17~31~27 ~20~31~27 minecraft:spruce_stairs 3
setblock ~21~14~27 minecraft:spruce_stairs 4
setblock ~21~27~27 minecraft:planks 1
setblock ~21~31~27 minecraft:planks 1
fill ~22~14~27 ~28~14~27 minecraft:planks 1
fill ~22~27~27 ~27~28~27 minecraft:snow
fill ~22~30~27 ~27~30~28 minecraft:snow
fill ~22~31~27 ~27~31~27 minecraft:snow
fill ~23~17~27 ~25~17~29 minecraft:stonebrick 0
setblock ~23~18~27 minecraft:stone_brick_stairs 2
fill ~24~18~27 ~24~18~31 minecraft:iron_block
setblock ~25~18~27 minecraft:stone_brick_stairs 2
setblock ~27~13~27 minecraft:spruce_stairs 4
fill ~28~13~27 ~31~13~27 minecraft:planks 1
fill ~28~26~27 ~35~26~28 minecraft:snow
fill ~28~32~27 ~35~32~28 minecraft:snow
setblock ~30~12~27 minecraft:spruce_stairs 4
fill ~30~17~27 ~32~17~27 minecraft:stone_brick_stairs 2
setblock ~31~12~27 minecraft:planks 1
setblock ~31~18~27 minecraft:lever 4
fill ~32~10~27 ~32~10~28 minecraft:spruce_stairs 4
fill ~32~11~27 ~32~11~28 minecraft:planks 1
fill ~33~9~27 ~33~9~28 minecraft:spruce_stairs 4
fill ~33~10~27 ~33~10~28 minecraft:planks 1
fill ~33~11~27 ~34~11~28 minecraft:wooden_slab 9
fill ~34~9~27 ~34~9~28 minecraft:planks 1
setblock ~35~9~27 minecraft:log 1
fill ~36~9~27 ~38~9~28 minecraft:planks 1
fill ~36~25~27 ~50~25~28 minecraft:snow
fill ~36~33~27 ~50~33~28 minecraft:snow
setblock ~39~9~27 minecraft:log 1
fill ~40~9~27 ~42~9~28 minecraft:planks 1
setblock ~43~9~27 minecraft:log 1
setblock ~43~23~27 minecraft:wooden_slab 9
setblock ~43~36~27 minecraft:wooden_slab 1
fill ~43~37~27 ~43~37~29 minecraft:fence 1
fill ~43~38~27 ~43~38~28 minecraft:fence 1
fill ~44~9~27 ~46~9~28 minecraft:planks 1
setblock ~47~9~27 minecraft:log 1
fill ~48~9~27 ~50~9~28 minecraft:planks 1
setblock ~51~9~27 minecraft:log 1
fill ~51~26~27 ~58~26~28 minecraft:snow
fill ~51~32~27 ~58~32~28 minecraft:snow
fill ~52~9~27 ~52~9~28 minecraft:planks 1
fill ~52~11~27 ~53~11~28 minecraft:wooden_slab 9
fill ~53~9~27 ~53~9~28 minecraft:spruce_stairs 5
fill ~53~10~27 ~53~10~28 minecraft:planks 1
fill ~54~10~27 ~54~10~28 minecraft:spruce_stairs 5
fill ~54~11~27 ~54~11~28 minecraft:planks 1
fill ~54~17~27 ~56~17~27 minecraft:stone_brick_stairs 2
setblock ~55~11~27 minecraft:spruce_stairs 5
fill ~55~12~27 ~55~13~27 minecraft:planks 1
setblock ~55~18~27 minecraft:lever 4
setblock ~56~12~27 minecraft:spruce_stairs 5
fill ~56~13~27 ~58~13~27 minecraft:planks 1
fill ~58~14~27 ~59~14~27 minecraft:planks 1
setblock ~59~13~27 minecraft:spruce_stairs 5
fill ~59~27~27 ~64~28~27 minecraft:snow
fill ~59~30~27 ~64~30~28 minecraft:snow
fill ~59~31~27 ~64~31~27 minecraft:snow
setblock ~60~14~27 minecraft:stonebrick 0
fill ~60~16~27 ~69~16~27 minecraft:planks 1
setblock ~61~14~27 minecraft:stone_brick_stairs 7
fill ~61~17~27 ~63~17~29 minecraft:stonebrick 0
setblock ~61~18~27 minecraft:stone_brick_stairs 2
fill ~62~14~27 ~63~14~27 minecraft:spruce_stairs 7
fill ~62~18~27 ~62~18~31 minecraft:iron_block
setblock ~63~18~27 minecraft:stone_brick_stairs 2
setblock ~64~14~27 minecraft:stone_brick_stairs 7
fill ~64~15~27 ~69~15~27 minecraft:planks 1
setblock ~65~14~27 minecraft:stonebrick 0
setblock ~65~27~27 minecraft:planks 1
fill ~65~29~27 ~69~29~27 minecraft:snow
setblock ~65~31~27 minecraft:planks 1
fill ~66~27~27 ~69~27~27 minecraft:spruce_stairs 7
fill ~66~31~27 ~69~31~27 minecraft:spruce_stairs 3
setblock ~67~33~27 minecraft:wooden_slab 1
fill ~67~38~27 ~67~39~28 minecraft:fence 1
setblock ~67~40~27 minecraft:fence 1
setblock ~69~17~27 minecraft:stone_brick_stairs 0
setblock ~70~15~27 minecraft:spruce_stairs 5
fill ~70~16~27 ~76~16~27 minecraft:log 1
setblock ~70~17~27 minecraft:stone_brick_stairs 2
fill ~70~28~27 ~73~28~27 minecraft:planks 1
fill ~70~29~27 ~73~29~27 minecraft:wool 13
fill ~70~30~27 ~73~30~27 minecraft:planks 1
setblock ~70~31~27 minecraft:wool 13
fill ~71~17~27 ~77~17~27 minecraft:stonebrick 0
fill ~71~31~27 ~74~31~27 minecraft:fence 1
fill ~72~18~27 ~78~18~27 minecraft:fence 1
setblock ~77~16~27 minecraft:spruce_stairs 5
setblock ~78~17~27 minecraft:stone_brick_stairs 5
setblock ~8~16~28 minecraft:spruce_stairs 4
fill ~8~17~28 ~8~21~28 minecraft:log 1
setblock ~8~22~28 minecraft:stonebrick 0
setblock ~8~23~28 minecraft:fence 1
setblock ~9~15~28 minecraft:spruce_stairs 4
fill ~9~16~28 ~21~16~28 minecraft:log 1
fill ~9~17~28 ~11~17~28 minecraft:planks 1
fill ~9~18~28 ~9~20~28 minecraft:planks 1
setblock ~10~14~28 minecraft:spruce_stairs 4
setblock ~10~15~28 minecraft:planks 1
fill ~10~18~28 ~10~18~29 minecraft:fence 1
setblock ~10~19~28 minecraft:fence 1
fill ~10~20~28 ~11~20~28 minecraft:planks 1
setblock ~10~22~28 minecraft:wall_sign 4
fill ~11~14~28 ~15~14~28 minecraft:planks 1
fill ~11~18~28 ~11~19~28 minecraft:planks 1
fill ~11~22~28 ~13~22~28 minecraft:spruce_stairs 2
setblock ~12~17~28 minecraft:spruce_door 3
fill ~12~19~28 ~14~19~28 minecraft:planks 1
setblock ~12~20~28 minecraft:fence 1
fill ~13~17~28 ~14~18~28 minecraft:planks 1
fill ~13~20~28 ~14~20~28 minecraft:planks 1
fill ~14~15~28 ~16~15~28 minecraft:planks 1
setblock ~14~22~28 minecraft:wall_sign 5
fill ~15~17~28 ~15~20~28 minecraft:log 1
fill ~15~31~28 ~16~31~28 minecraft:fence 1
setblock ~16~14~28 minecraft:spruce_stairs 5
setblock ~16~17~28 minecraft:stonebrick 0
fill ~16~18~28 ~16~20~28 minecraft:fence 1
fill ~16~29~28 ~16~29~29 minecraft:fence 1
setblock ~16~30~28 minecraft:fence 1
setblock ~17~15~28 minecraft:spruce_stairs 5
fill ~17~17~28 ~17~18~28 minecraft:log 1
setblock ~17~19~28 minecraft:stone_brick_stairs 0
fill ~17~20~28 ~17~22~28 minecraft:fence 1
fill ~17~28~28 ~21~28~28 minecraft:planks 1
fill ~17~29~28 ~21~29~28 minecraft:wool 13
fill ~17~30~28 ~21~30~28 minecraft:planks 1
fill ~17~31~28 ~21~31~28 minecraft:wool 13
setblock ~18~17~28 minecraft:spruce_stairs 5
fill ~18~18~28 ~18~20~28 minecraft:log 1
setblock ~18~21~28 minecraft:stone_brick_stairs 0
fill ~18~22~28 ~18~27~28 minecraft:fence 1
fill ~19~17~28 ~19~18~28 minecraft:fence 1
setblock ~19~19~28 minecraft:wooden_slab 9
fill ~19~20~28 ~20~20~28 minecraft:log 1
fill ~19~21~28 ~19~22~28 minecraft:log 1
setblock ~19~23~28 minecraft:stone_block_slab 5
fill ~19~24~28 ~20~26~28 minecraft:fence 1
fill ~19~27~28 ~19~27~29 minecraft:stone_block_slab 13
setblock ~20~17~28 minecraft:spruce_stairs 4
fill ~20~18~28 ~21~18~28 minecraft:log 1
setblock ~20~19~28 minecraft:log 1
setblock ~20~21~28 minecraft:stone_brick_stairs 1
fill ~20~22~28 ~21~22~28 minecraft:fence 1
setblock ~20~23~28 minecraft:fence 1
fill ~20~27~28 ~20~27~29 minecraft:fence 1
setblock ~21~15~28 minecraft:spruce_stairs 4
setblock ~21~17~28 minecraft:log 1
setblock ~21~19~28 minecraft:stone_brick_stairs 1
fill ~21~20~28 ~22~20~28 minecraft:fence 1
setblock ~21~21~28 minecraft:fence 1
setblock ~22~13~28 minecraft:stonebrick 0
setblock ~22~14~28 minecraft:stone_brick_stairs 3
fill ~22~15~28 ~28~16~28 minecraft:planks 1
fill ~22~17~28 ~22~19~28 minecraft:fence 1
fill ~22~27~28 ~26~27~28 minecraft:spruce_stairs 7
fill ~22~28~28 ~35~28~28 minecraft:snow
fill ~22~29~28 ~27~29~28 minecraft:snow
fill ~22~31~28 ~26~31~28 minecraft:spruce_stairs 3
fill ~22~32~28 ~23~32~28 minecraft:wool 13
setblock ~23~13~28 minecraft:log 1
setblock ~23~18~28 minecraft:stonebrick 0
setblock ~24~13~28 minecraft:stonebrick 0
setblock ~24~14~28 minecraft:stone_brick_stairs 3
setblock ~24~19~28 minecraft:stone_block_slab 5
fill ~24~32~28 ~27~32~28 minecraft:fence 1
setblock ~25~13~28 minecraft:log 1
setblock ~25~18~28 minecraft:stonebrick 0
setblock ~26~13~28 minecraft:stonebrick 0
setblock ~26~14~28 minecraft:stone_brick_stairs 3
setblock ~26~17~28 minecraft:stone_brick_stairs 2
setblock ~26~18~28 minecraft:wooden_button 5
setblock ~27~14~28 minecraft:spruce_stairs 4
setblock ~27~17~28 minecraft:stone_brick_stairs 1
setblock ~27~27~28 minecraft:planks 1
setblock ~27~31~28 minecraft:planks 1
fill ~28~14~28 ~32~14~28 minecraft:planks 1
fill ~28~27~28 ~35~27~28 minecraft:snow
fill ~28~30~28 ~35~30~29 minecraft:snow
fill ~28~31~28 ~35~31~28 minecraft:snow
fill ~28~33~28 ~35~33~28 minecraft:wool 13
fill ~30~17~28 ~32~17~30 minecraft:stonebrick 0
setblock ~30~18~28 minecraft:stone_brick_stairs 2
setblock ~31~13~28 minecraft:spruce_stairs 4
fill ~31~18~28 ~31~18~32 minecraft:iron_block
fill ~32~12~28 ~32~13~28 minecraft:planks 1
setblock ~32~18~28 minecraft:stone_brick_stairs 2
setblock ~35~8~28 minecraft:stone_block_slab 13
setblock ~35~9~28 minecraft:log 1
fill ~36~26~28 ~50~26~29 minecraft:snow
fill ~36~32~28 ~50~32~29 minecraft:snow
fill ~36~34~28 ~50~34~28 minecraft:wool 13
setblock ~39~8~28 minecraft:stone_block_slab 13
setblock ~39~9~28 minecraft:log 1
fill ~42~17~28 ~44~17~28 minecraft:stone_brick_stairs 2
setblock ~43~8~28 minecraft:stone_block_slab 13
setblock ~43~9~28 minecraft:log 1
setblock ~43~18~28 minecraft:lever 4
setblock ~43~24~28 minecraft:spruce_stairs 7
setblock ~43~35~28 minecraft:spruce_stairs 3
fill ~43~36~28 ~43~36~30 minecraft:fence 1
setblock ~47~8~28 minecraft:stone_block_slab 13
setblock ~47~9~28 minecraft:log 1
setblock ~51~8~28 minecraft:stone_block_slab 13
setblock ~51~9~28 minecraft:log 1
fill ~51~27~28 ~58~28~28 minecraft:snow
fill ~51~30~28 ~58~30~29 minecraft:snow
fill ~51~31~28 ~58~31~28 minecraft:snow
fill ~51~33~28 ~58~33~28 minecraft:wool 13
fill ~54~12~28 ~54~14~28 minecraft:planks 1
fill ~54~17~28 ~56~17~30 minecraft:stonebrick 0
setblock ~54~18~28 minecraft:stone_brick_stairs 2
setblock ~55~13~28 minecraft:spruce_stairs 5
fill ~55~14~28 ~58~14~28 minecraft:planks 1
fill ~55~18~28 ~55~18~32 minecraft:iron_block
setblock ~56~18~28 minecraft:stone_brick_stairs 2
fill ~57~13~28 ~57~13~32 minecraft:wooden_slab 9
fill ~58~13~28 ~58~13~33 minecraft:wool 13
fill ~58~15~28 ~64~15~28 minecraft:planks 1
fill ~59~12~28 ~59~12~29 minecraft:wool 13
setblock ~59~14~28 minecraft:spruce_stairs 5
fill ~59~17~28 ~59~17~29 minecraft:stone_brick_stairs 0
setblock ~59~27~28 minecraft:planks 1
fill ~59~28~28 ~64~29~28 minecraft:snow
setblock ~59~31~28 minecraft:planks 1
fill ~59~32~28 ~62~32~28 minecraft:fence 1
fill ~60~10~28 ~60~11~28 minecraft:wool 13
fill ~60~16~28 ~64~16~28 minecraft:planks 1
setblock ~60~17~28 minecraft:stone_brick_stairs 2
setblock ~60~18~28 minecraft:wooden_button 4
fill ~60~27~28 ~64~27~28 minecraft:spruce_stairs 7
fill ~60~31~28 ~64~31~28 minecraft:spruce_stairs 3
setblock ~61~18~28 minecraft:stonebrick 0
setblock ~62~19~28 minecraft:stone_block_slab 5
setblock ~63~18~28 minecraft:stonebrick 0
fill ~63~32~28 ~64~32~28 minecraft:wool 13
fill ~64~17~28 ~64~20~28 minecraft:fence 1
fill ~65~16~28 ~69~16~28 minecraft:log 1
fill ~65~17~28 ~65~18~28 minecraft:log 1
setblock ~65~19~28 minecraft:stone_brick_stairs 0
fill ~65~20~28 ~65~22~28 minecraft:fence 1
fill ~65~28~28 ~69~28~28 minecraft:planks 1
fill ~65~29~28 ~69~29~28 minecraft:wool 13
fill ~65~30~28 ~69~30~28 minecraft:planks 1
fill ~65~31~28 ~69~31~28 minecraft:wool 13
setblock ~66~17~28 minecraft:spruce_stairs 5
fill ~66~18~28 ~66~20~28 minecraft:log 1
setblock ~66~21~28 minecraft:stone_brick_stairs 0
fill ~66~22~28 ~66~27~28 minecraft:fence 1
fill ~67~17~28 ~67~18~28 minecraft:fence 1
setblock ~67~19~28 minecraft:wooden_slab 9
fill ~67~20~28 ~68~20~28 minecraft:log 1
fill ~67~21~28 ~67~22~28 minecraft:log 1
setblock ~67~23~28 minecraft:stone_block_slab 5
fill ~67~24~28 ~68~26~28 minecraft:fence 1
fill ~67~27~28 ~67~27~29 minecraft:stone_block_slab 13
setblock ~67~32~28 minecraft:spruce_stairs 3
fill ~67~35~28 ~67~36~29 minecraft:fence 1
setblock ~67~37~28 minecraft:fence 1
setblock ~68~17~28 minecraft:spruce_stairs 4
fill ~68~18~28 ~69~18~28 minecraft:log 1
setblock ~68~19~28 minecraft:log 1
setblock ~68~21~28 minecraft:stone_brick_stairs 1
fill ~68~22~28 ~69~22~28 minecraft:fence 1
setblock ~68~23~28 minecraft:fence 1
fill ~68~27~28 ~68~27~29 minecraft:fence 1
setblock ~69~17~28 minecraft:log 1
setblock ~69~19~28 minecraft:stone_brick_stairs 1
fill ~69~20~28 ~70~20~28 minecraft:fence 1
setblock ~69~21~28 minecraft:fence 1
setblock ~70~16~28 minecraft:spruce_stairs 5
setblock ~70~17~28 minecraft:stonebrick 0
fill ~70~18~28 ~70~19~28 minecraft:fence 1
fill ~70~29~28 ~70~29~29 minecraft:fence 1
fill ~70~30~28 ~71~30~28 minecraft:fence 1
setblock ~71~17~28 minecraft:stone_brick_stairs 5
setblock ~71~18~28 minecraft:cobblestone_wall 0
setblock ~71~31~28 minecraft:fence 1
fill ~9~16~29 ~10~16~29 minecraft:spruce_stairs 7
fill ~9~17~29 ~10~17~29 minecraft:stonebrick 0
setblock ~9~18~29 minecraft:fence 1
fill ~9~21~29 ~10~21~29 minecraft:spruce_stairs 7
fill ~9~22~29 ~10~22~29 minecraft:stonebrick 0
fill ~9~23~29 ~10~23~29 minecraft:fence 1
fill ~11~15~29 ~13~15~29 minecraft:spruce_stairs 7
fill ~11~16~29 ~13~16~29 minecraft:planks 1
setblock ~11~20~29 minecraft:spruce_stairs 7
fill ~11~22~29 ~13~22~29 minecraft:planks 1
fill ~11~23~29 ~13~23~29 minecraft:stone_block_slab 5
setblock ~13~20~29 minecraft:spruce_stairs 7
fill ~14~16~29 ~15~16~29 minecraft:spruce_stairs 7
fill ~14~17~29 ~15~17~29 minecraft:stonebrick 0
fill ~14~18~29 ~15~18~29 minecraft:fence 1
fill ~14~21~29 ~15~21~29 minecraft:spruce_stairs 7
fill ~14~22~29 ~15~22~29 minecraft:stonebrick 0
fill ~14~23~29 ~15~23~29 minecraft:fence 1
fill ~17~28~29 ~18~28~29 minecraft:fence 1
setblock ~17~29~29 minecraft:fence 1
fill ~17~30~29 ~18~30~29 minecraft:wool 13
setblock ~18~27~29 minecraft:fence 1
fill ~18~29~29 ~20~29~29 minecraft:stonebrick 0
setblock ~19~28~29 minecraft:stonebrick 0
setblock ~19~30~29 minecraft:stonebrick 0
setblock ~19~31~29 minecraft:stone_brick_stairs 3
fill ~20~28~29 ~21~28~29 minecraft:fence 1
fill ~20~30~29 ~21~30~29 minecraft:wool 13
setblock ~21~12~29 minecraft:wooden_slab 9
setblock ~21~16~29 minecraft:spruce_stairs 4
fill ~21~17~29 ~22~17~29 minecraft:stonebrick 0
fill ~21~29~29 ~21~29~30 minecraft:fence 1
setblock ~22~12~29 minecraft:wool 13
setblock ~22~13~29 minecraft:stone_brick_stairs 3
fill ~22~16~29 ~27~16~29 minecraft:log 1
fill ~22~28~29 ~27~28~29 minecraft:planks 1
fill ~22~29~29 ~27~29~29 minecraft:wool 13
fill ~22~30~29 ~27~30~29 minecraft:planks 1
setblock ~22~31~29 minecraft:wool 13
setblock ~23~13~29 minecraft:wooden_slab 1
setblock ~23~18~29 minecraft:stone_brick_stairs 3
fill ~23~31~29 ~24~31~29 minecraft:fence 1
setblock ~24~12~29 minecraft:wool 13
setblock ~24~13~29 minecraft:stone_brick_stairs 3
setblock ~24~32~29 minecraft:fence 1
setblock ~25~13~29 minecraft:wooden_slab 1
setblock ~25~18~29 minecraft:stone_brick_stairs 3
setblock ~26~12~29 minecraft:wool 13
setblock ~26~13~29 minecraft:stone_brick_stairs 3
setblock ~26~17~29 minecraft:stonebrick 0
setblock ~26~18~29 minecraft:fence 1
setblock ~27~12~29 minecraft:wooden_slab 1
setblock ~27~15~29 minecraft:spruce_stairs 4
fill ~27~17~29 ~29~17~29 minecraft:stone_brick_stairs 2
fill ~27~32~29 ~32~32~29 minecraft:fence 1
fill ~28~15~29 ~33~15~29 minecraft:planks 1
setblock ~28~16~29 minecraft:planks 1
fill ~28~27~29 ~34~27~29 minecraft:spruce_stairs 7
fill ~28~28~29 ~58~28~29 minecraft:snow
fill ~28~29~29 ~35~29~29 minecraft:snow
fill ~28~31~29 ~34~31~29 minecraft:spruce_stairs 3
setblock ~29~18~29 minecraft:wooden_button 4
setblock ~30~18~29 minecraft:stonebrick 0
setblock ~31~19~29 minecraft:stone_block_slab 5
setblock ~32~14~29 minecraft:spruce_stairs 4
setblock ~32~18~29 minecraft:stonebrick 0
setblock ~33~10~29 minecraft:spruce_stairs 4
fill ~33~11~29 ~33~14~29 minecraft:planks 1
setblock ~33~17~29 minecraft:stone_brick_stairs 2
setblock ~33~18~29 minecraft:wooden_button 5
fill ~33~32~29 ~35~32~29 minecraft:wool 13
setblock ~34~10~29 minecraft:planks 1
setblock ~34~11~29 minecraft:wooden_slab 9
setblock ~34~17~29 minecraft:stone_brick_stairs 1
setblock ~35~9~29 minecraft:stone_block_slab 13
setblock ~35~10~29 minecraft:log 1
setblock ~35~27~29 minecraft:planks 1
setblock ~35~31~29 minecraft:planks 1
fill ~36~10~29 ~38~10~29 minecraft:planks 1
fill ~36~27~29 ~50~27~29 minecraft:snow
fill ~36~30~29 ~50~30~30 minecraft:snow
fill ~36~31~29 ~50~31~29 minecraft:snow
fill ~36~33~29 ~50~33~29 minecraft:wool 13
setblock ~39~9~29 minecraft:stone_block_slab 13
setblock ~39~10~29 minecraft:log 1
fill ~40~10~29 ~42~10~29 minecraft:planks 1
fill ~42~17~29 ~44~17~31 minecraft:stonebrick 0
setblock ~42~18~29 minecraft:stone_brick_stairs 2
setblock ~43~9~29 minecraft:stone_block_slab 13
setblock ~43~10~29 minecraft:log 1
fill ~43~18~29 ~43~18~33 minecraft:iron_block
setblock ~43~25~29 minecraft:spruce_stairs 7
setblock ~43~34~29 minecraft:spruce_stairs 3
fill ~43~35~29 ~43~35~30 minecraft:fence 1
fill ~44~10~29 ~46~10~29 minecraft:planks 1
setblock ~44~18~29 minecraft:stone_brick_stairs 2
setblock ~47~9~29 minecraft:stone_block_slab 13
setblock ~47~10~29 minecraft:log 1
fill ~48~10~29 ~50~10~29 minecraft:planks 1
setblock ~51~9~29 minecraft:stone_block_slab 13
setblock ~51~10~29 minecraft:log 1
setblock ~51~27~29 minecraft:planks 1
fill ~51~29~29 ~58~29~29 minecraft:snow
setblock ~51~31~29 minecraft:planks 1
fill ~51~32~29 ~53~32~29 minecraft:wool 13
setblock ~52~10~29 minecraft:planks 1
setblock ~52~11~29 minecraft:wooden_slab 9
setblock ~52~17~29 minecraft:stone_brick_stairs 0
fill ~52~27~29 ~58~27~29 minecraft:spruce_stairs 7
fill ~52~31~29 ~58~31~29 minecraft:spruce_stairs 3
setblock ~53~10~29 minecraft:spruce_stairs 5
fill ~53~11~29 ~53~15~29 minecraft:planks 1
setblock ~53~17~29 minecraft:stone_brick_stairs 2
setblock ~53~18~29 minecraft:wooden_button 4
setblock ~54~14~29 minecraft:spruce_stairs 5
fill ~54~15~29 ~58~15~29 minecraft:planks 1
setblock ~54~18~29 minecraft:stonebrick 0
fill ~54~32~29 ~59~32~29 minecraft:fence 1
setblock ~55~19~29 minecraft:stone_block_slab 5
setblock ~56~18~29 minecraft:stonebrick 0
fill ~57~14~29 ~57~14~34 minecraft:planks 1
fill ~57~17~29 ~58~17~29 minecraft:stone_brick_stairs 2
setblock ~57~18~29 minecraft:wooden_button 5
fill ~58~14~29 ~58~14~33 minecraft:wall_sign 5
setblock ~59~15~29 minecraft:spruce_stairs 5
fill ~59~16~29 ~64~16~29 minecraft:log 1
fill ~59~28~29 ~64~28~29 minecraft:planks 1
fill ~59~29~29 ~64~29~29 minecraft:wool 13
fill ~59~30~29 ~64~30~29 minecraft:planks 1
fill ~60~9~29 ~60~9~30 minecraft:wool 13
setblock ~60~11~29 minecraft:wool 13
setblock ~60~17~29 minecraft:stonebrick 0
setblock ~60~18~29 minecraft:fence 1
fill ~61~10~29 ~61~10~32 minecraft:wool 13
setblock ~61~18~29 minecraft:stone_brick_stairs 3
fill ~62~31~29 ~63~31~29 minecraft:fence 1
setblock ~62~32~29 minecraft:fence 1
setblock ~63~18~29 minecraft:stone_brick_stairs 3
fill ~64~17~29 ~65~17~29 minecraft:stonebrick 0
setblock ~64~31~29 minecraft:wool 13
setblock ~65~16~29 minecraft:spruce_stairs 5
fill ~65~28~29 ~66~28~29 minecraft:fence 1
fill ~65~29~29 ~65~29~30 minecraft:fence 1
fill ~65~30~29 ~66~30~29 minecraft:wool 13
setblock ~66~27~29 minecraft:fence 1
fill ~66~29~29 ~68~29~29 minecraft:stonebrick 0
setblock ~67~28~29 minecraft:stonebrick 0
setblock ~67~30~29 minecraft:stonebrick 0
setblock ~67~31~29 minecraft:stone_brick_stairs 3
