fill ~4~193~6 ~8~195~6 minecraft:obsidian
fill ~4~196~6 ~6~196~6 minecraft:obsidian
fill ~5~192~6 ~8~192~6 minecraft:obsidian
fill ~9~194~6 ~14~195~6 minecraft:obsidian
fill ~9~196~6 ~13~196~6 minecraft:obsidian
fill ~11~193~6 ~13~193~9 minecraft:obsidian
fill ~11~197~6 ~13~197~6 minecraft:obsidian
fill ~12~192~6 ~12~192~7 minecraft:obsidian
fill ~12~198~6 ~12~198~8 minecraft:obsidian
fill ~4~193~7 ~5~193~8 minecraft:obsidian
fill ~4~194~7 ~4~195~7 minecraft:obsidian
fill ~5~192~7 ~6~192~8 minecraft:obsidian
setblock ~5~195~7 minecraft:obsidian
fill ~6~191~7 ~8~191~8 minecraft:obsidian
setblock ~6~196~7 minecraft:obsidian
fill ~7~187~7 ~8~187~9 minecraft:obsidian
fill ~7~189~7 ~10~189~7 minecraft:obsidian
fill ~7~195~7 ~8~195~7 minecraft:obsidian
fill ~8~188~7 ~9~188~7 minecraft:obsidian
fill ~8~190~7 ~8~190~9 minecraft:obsidian
fill ~9~192~7 ~9~192~8 minecraft:obsidian
fill ~9~193~7 ~9~194~7 minecraft:obsidian
setblock ~9~196~7 minecraft:obsidian
fill ~10~197~7 ~10~197~8 minecraft:obsidian
fill ~11~194~7 ~11~194~8 minecraft:obsidian
fill ~13~197~7 ~13~197~8 minecraft:obsidian
fill ~14~194~7 ~14~195~9 minecraft:obsidian
fill ~5~194~8 ~9~194~8 minecraft:obsidian
fill ~6~188~8 ~7~188~9 minecraft:obsidian
fill ~6~193~8 ~8~193~8 minecraft:obsidian
fill ~6~195~8 ~7~195~8 minecraft:obsidian
fill ~7~189~8 ~8~189~9 minecraft:obsidian
fill ~7~192~8 ~8~192~8 minecraft:obsidian
fill ~7~196~8 ~8~196~8 minecraft:carved_pumpkin 1
setblock ~7~197~8 minecraft:redstone_block
fill ~8~186~8 ~12~186~8 minecraft:obsidian
fill ~8~197~8 ~9~197~8 minecraft:carved_pumpkin 1
setblock ~8~198~8 minecraft:red_mushroom_block 0
fill ~9~185~8 ~9~185~10 minecraft:obsidian
fill ~9~187~8 ~11~187~8 minecraft:obsidian
fill ~9~190~8 ~9~190~9 minecraft:obsidian
fill ~9~198~8 ~10~198~8 minecraft:carved_pumpkin 1
setblock ~9~199~8 minecraft:redstone_block
fill ~9~201~8 ~9~202~11 minecraft:obsidian
fill ~10~188~8 ~12~188~8 minecraft:obsidian
fill ~10~199~8 ~11~199~8 minecraft:carved_pumpkin 1
setblock ~10~200~8 minecraft:red_mushroom_block 0
fill ~10~201~8 ~10~202~8 minecraft:red_nether_brick
fill ~10~203~8 ~10~205~8 minecraft:obsidian
fill ~11~189~8 ~17~190~8 minecraft:obsidian
fill ~11~200~8 ~12~200~8 minecraft:carved_pumpkin 1
setblock ~11~201~8 minecraft:carved_pumpkin 1
fill ~11~202~8 ~14~202~8 minecraft:red_mushroom_block 0
fill ~11~203~8 ~13~203~8 minecraft:red_mushroom_block 0
setblock ~11~204~8 minecraft:red_mushroom_block 0
fill ~11~205~8 ~11~205~11 minecraft:obsidian
fill ~12~191~8 ~17~191~8 minecraft:obsidian
fill ~12~201~8 ~13~201~8 minecraft:red_mushroom_block 0
setblock ~12~204~8 minecraft:nether_wart_block
fill ~14~188~8 ~17~188~8 minecraft:obsidian
fill ~14~192~8 ~16~192~9 minecraft:obsidian
fill ~15~186~8 ~15~187~9 minecraft:obsidian
fill ~15~193~8 ~15~193~9 minecraft:obsidian
fill ~16~187~8 ~16~187~11 minecraft:obsidian
fill ~7~196~9 ~7~196~12 minecraft:obsidian
fill ~7~197~9 ~7~197~10 minecraft:obsidian
fill ~8~186~9 ~9~186~10 minecraft:obsidian
setblock ~8~188~9 minecraft:obsidian
setblock ~8~195~9 minecraft:red_nether_brick
fill ~8~198~9 ~8~198~10 minecraft:obsidian
setblock ~9~189~9 minecraft:obsidian
setblock ~9~193~9 minecraft:redstone_block
fill ~9~199~9 ~9~200~9 minecraft:obsidian
fill ~9~204~9 ~10~204~11 minecraft:obsidian
fill ~10~182~9 ~14~182~9 minecraft:obsidian
fill ~10~183~9 ~13~183~9 minecraft:obsidian
fill ~10~184~9 ~12~184~9 minecraft:obsidian
fill ~10~185~9 ~11~185~9 minecraft:obsidian
setblock ~10~193~9 minecraft:carved_pumpkin 1
fill ~10~205~9 ~10~205~11 minecraft:obsidian
fill ~11~181~9 ~14~181~9 minecraft:obsidian
fill ~11~186~9 ~12~186~10 minecraft:obsidian
setblock ~11~190~9 minecraft:obsidian
setblock ~11~198~9 minecraft:carved_pumpkin 1
fill ~12~188~9 ~12~188~10 minecraft:obsidian
fill ~12~191~9 ~14~191~9 minecraft:obsidian
fill ~12~199~9 ~13~199~9 minecraft:carved_pumpkin 1
fill ~12~204~9 ~12~204~11 minecraft:obsidian
fill ~13~198~9 ~14~198~9 minecraft:carved_pumpkin 1
fill ~13~200~9 ~15~200~9 minecraft:red_mushroom_block 0
fill ~13~203~9 ~13~203~12 minecraft:obsidian
fill ~14~188~9 ~14~188~10 minecraft:obsidian
setblock ~14~197~9 minecraft:carved_pumpkin 1
fill ~14~199~9 ~16~199~9 minecraft:red_mushroom_block 0
setblock ~14~201~9 minecraft:red_mushroom_block 0
fill ~14~202~9 ~14~202~12 minecraft:obsidian
fill ~15~184~9 ~19~184~9 minecraft:obsidian
setblock ~15~198~9 minecraft:red_mushroom_block 0
fill ~15~201~9 ~15~201~12 minecraft:obsidian
fill ~16~183~9 ~19~183~9 minecraft:obsidian
fill ~16~185~9 ~17~185~9 minecraft:obsidian
fill ~16~188~9 ~17~188~11 minecraft:obsidian
fill ~16~191~9 ~17~191~10 minecraft:obsidian
setblock ~16~200~9 minecraft:red_nether_brick
fill ~17~182~9 ~18~182~9 minecraft:obsidian
fill ~17~189~9 ~17~189~11 minecraft:obsidian
setblock ~17~190~9 minecraft:obsidian
fill ~8~187~10 ~11~187~10 minecraft:obsidian
fill ~8~194~10 ~8~195~12 minecraft:obsidian
fill ~8~199~10 ~8~200~11 minecraft:obsidian
fill ~9~188~10 ~11~188~10 minecraft:obsidian
fill ~9~193~10 ~9~193~13 minecraft:obsidian
fill ~9~200~10 ~9~200~11 minecraft:obsidian
fill ~10~182~10 ~10~182~11 minecraft:obsidian
setblock ~10~183~10 minecraft:obsidian
setblock ~10~186~10 minecraft:obsidian
setblock ~10~189~10 minecraft:obsidian
setblock ~10~190~10 minecraft:red_nether_brick
setblock ~10~192~10 minecraft:red_nether_brick
fill ~11~181~10 ~11~181~11 minecraft:obsidian
fill ~11~184~10 ~12~184~10 minecraft:obsidian
setblock ~11~185~10 minecraft:obsidian
setblock ~11~191~10 minecraft:red_mushroom_block 0
fill ~11~192~10 ~13~192~10 minecraft:carved_pumpkin 1
fill ~12~180~10 ~14~180~11 minecraft:obsidian
fill ~13~179~10 ~13~179~11 minecraft:obsidian
fill ~14~182~10 ~15~182~11 minecraft:obsidian
fill ~14~183~10 ~15~183~10 minecraft:obsidian
fill ~14~184~10 ~14~184~15 minecraft:obsidian
setblock ~14~193~10 minecraft:carved_pumpkin 1
fill ~14~196~10 ~16~196~10 minecraft:carved_pumpkin 1
fill ~15~194~10 ~16~195~10 minecraft:carved_pumpkin 1
setblock ~15~197~10 minecraft:carved_pumpkin 1
fill ~16~185~10 ~16~185~11 minecraft:obsidian
setblock ~16~192~10 minecraft:obsidian
setblock ~16~193~10 minecraft:carved_pumpkin 1
setblock ~16~197~10 minecraft:red_mushroom_block 0
fill ~16~198~10 ~17~198~10 minecraft:red_nether_brick
fill ~16~199~10 ~16~199~13 minecraft:obsidian
fill ~16~200~10 ~16~200~12 minecraft:obsidian
fill ~17~182~10 ~17~182~12 minecraft:obsidian
fill ~17~186~10 ~19~186~11 minecraft:obsidian
fill ~17~194~10 ~17~196~10 minecraft:red_mushroom_block 0
setblock ~17~197~10 minecraft:redstone_block
fill ~18~181~10 ~19~181~10 minecraft:obsidian
fill ~18~185~10 ~20~185~10 minecraft:obsidian
fill ~18~187~10 ~18~187~11 minecraft:obsidian
fill ~18~195~10 ~18~197~10 minecraft:red_mushroom_block 0
fill ~19~182~10 ~20~182~11 minecraft:obsidian
setblock ~19~196~10 minecraft:red_mushroom_block 0
fill ~20~183~10 ~20~184~12 minecraft:obsidian
fill ~6~198~11 ~7~198~11 minecraft:obsidian
setblock ~7~199~11 minecraft:obsidian
fill ~10~190~11 ~10~190~14 minecraft:obsidian
fill ~10~192~11 ~10~192~13 minecraft:obsidian
fill ~10~201~11 ~10~203~11 minecraft:obsidian
fill ~11~182~11 ~13~183~11 minecraft:obsidian
fill ~11~189~11 ~12~189~14 minecraft:obsidian
setblock ~11~202~11 minecraft:obsidian
fill ~11~203~11 ~12~203~11 minecraft:coal_block
setblock ~11~204~11 minecraft:snow
fill ~12~181~11 ~14~181~11 minecraft:obsidian
setblock ~12~184~11 minecraft:obsidian
fill ~12~187~11 ~12~187~15 minecraft:obsidian
setblock ~12~188~11 minecraft:nether_wart_block
fill ~13~177~11 ~22~178~11 minecraft:obsidian
setblock ~13~186~11 minecraft:carved_pumpkin 1
fill ~13~187~11 ~13~188~11 minecraft:red_mushroom_block 0
fill ~14~175~11 ~16~176~11 minecraft:obsidian
fill ~14~179~11 ~14~179~12 minecraft:obsidian
setblock ~14~187~11 minecraft:carved_pumpkin 1
fill ~15~174~11 ~15~174~13 minecraft:obsidian
setblock ~15~183~11 minecraft:obsidian
fill ~16~179~11 ~16~179~12 minecraft:obsidian
fill ~16~198~11 ~17~198~13 minecraft:obsidian
setblock ~17~176~11 minecraft:obsidian
setblock ~17~190~11 minecraft:carved_pumpkin 1
fill ~17~192~11 ~18~192~11 minecraft:carved_pumpkin 1
setblock ~17~193~11 minecraft:carved_pumpkin 1
fill ~17~197~11 ~18~197~14 minecraft:obsidian
fill ~18~179~11 ~23~179~11 minecraft:obsidian
setblock ~18~181~11 minecraft:obsidian
setblock ~18~191~11 minecraft:carved_pumpkin 1
fill ~18~193~11 ~20~193~11 minecraft:red_mushroom_block 0
fill ~18~194~11 ~19~194~11 minecraft:red_mushroom_block 0
fill ~18~196~11 ~19~196~14 minecraft:obsidian
fill ~19~180~11 ~19~180~12 minecraft:obsidian
fill ~19~185~11 ~20~185~12 minecraft:obsidian
setblock ~19~192~11 minecraft:red_mushroom_block 0
setblock ~19~195~11 minecraft:red_nether_brick
fill ~20~194~11 ~20~195~11 minecraft:redstone_block
fill ~21~176~11 ~21~176~14 minecraft:obsidian
fill ~21~180~11 ~22~180~11 minecraft:obsidian
setblock ~21~194~11 minecraft:red_mushroom_block 0
setblock ~23~178~11 minecraft:obsidian
fill ~132~54~11 ~165~54~11 minecraft:obsidian
fill ~132~55~11 ~164~55~11 minecraft:obsidian
fill ~133~53~11 ~166~53~11 minecraft:obsidian
fill ~133~56~11 ~163~56~11 minecraft:obsidian
fill ~134~52~11 ~167~52~11 minecraft:obsidian
fill ~134~57~11 ~162~57~11 minecraft:obsidian
fill ~135~51~11 ~168~51~11 minecraft:obsidian
fill ~135~58~11 ~161~58~11 minecraft:obsidian
fill ~136~50~11 ~169~50~11 minecraft:obsidian
fill ~136~59~11 ~160~59~11 minecraft:obsidian
fill ~137~49~11 ~170~49~11 minecraft:obsidian
fill ~137~60~11 ~159~60~11 minecraft:obsidian
fill ~138~48~11 ~171~48~11 minecraft:obsidian
fill ~138~61~11 ~158~61~11 minecraft:obsidian
fill ~139~47~11 ~172~47~11 minecraft:obsidian
fill ~139~62~11 ~157~62~11 minecraft:obsidian
fill ~140~46~11 ~173~46~11 minecraft:obsidian
fill ~140~63~11 ~156~63~11 minecraft:obsidian
fill ~141~45~11 ~173~45~11 minecraft:obsidian
fill ~141~64~11 ~155~64~11 minecraft:obsidian
fill ~142~44~11 ~173~44~11 minecraft:obsidian
fill ~142~65~11 ~154~65~11 minecraft:obsidian
fill ~143~43~11 ~173~43~11 minecraft:obsidian
fill ~143~66~11 ~153~66~11 minecraft:obsidian
fill ~144~42~11 ~172~42~11 minecraft:obsidian
fill ~144~67~11 ~152~67~11 minecraft:obsidian
fill ~145~41~11 ~171~41~11 minecraft:obsidian
fill ~145~68~11 ~151~68~11 minecraft:obsidian
fill ~146~40~11 ~170~40~11 minecraft:obsidian
fill ~146~69~11 ~150~69~11 minecraft:obsidian
fill ~147~39~11 ~169~39~11 minecraft:obsidian
fill ~148~38~11 ~168~38~11 minecraft:obsidian
fill ~149~37~11 ~167~37~11 minecraft:obsidian
fill ~150~36~11 ~166~36~11 minecraft:obsidian
fill ~151~35~11 ~165~35~11 minecraft:obsidian
fill ~152~34~11 ~164~34~11 minecraft:obsidian
fill ~153~33~11 ~163~33~11 minecraft:obsidian
fill ~154~32~11 ~162~32~11 minecraft:obsidian
fill ~155~31~11 ~161~31~11 minecraft:obsidian
fill ~156~30~11 ~160~30~11 minecraft:obsidian
fill ~157~29~11 ~159~29~11 minecraft:obsidian
setblock ~158~28~11 minecraft:obsidian
fill ~7~197~12 ~9~197~12 minecraft:obsidian
fill ~8~196~12 ~9~196~12 minecraft:obsidian
fill ~8~198~12 ~10~198~12 minecraft:obsidian
fill ~9~199~12 ~11~199~12 minecraft:obsidian
fill ~10~200~12 ~13~200~12 minecraft:obsidian
fill ~11~201~12 ~14~201~12 minecraft:obsidian
setblock ~12~188~12 minecraft:obsidian
setblock ~12~199~12 minecraft:brown_mushroom_block 0
fill ~12~202~12 ~13~202~12 minecraft:obsidian
fill ~13~176~12 ~13~178~12 minecraft:obsidian
fill ~13~186~12 ~13~186~15 minecraft:obsidian
fill ~14~175~12 ~14~175~13 minecraft:obsidian
fill ~14~177~12 ~14~178~12 minecraft:obsidian
setblock ~14~183~12 minecraft:redstone_block
fill ~14~185~12 ~14~185~15 minecraft:obsidian
fill ~14~186~12 ~16~186~12 minecraft:carved_pumpkin 1
fill ~15~178~12 ~16~178~12 minecraft:obsidian
fill ~15~182~12 ~15~183~12 minecraft:yellow_glazed_terracotta 4
setblock ~15~185~12 minecraft:carved_pumpkin 1
setblock ~15~187~12 minecraft:carved_pumpkin 1
fill ~16~171~12 ~19~171~12 minecraft:obsidian
fill ~16~173~12 ~16~174~13 minecraft:obsidian
fill ~17~169~12 ~17~169~15 minecraft:obsidian
fill ~17~170~12 ~18~170~12 minecraft:obsidian
fill ~17~172~12 ~19~172~12 minecraft:obsidian
fill ~17~174~12 ~17~175~13 minecraft:obsidian
setblock ~17~187~12 minecraft:carved_pumpkin 1
fill ~18~173~12 ~18~173~14 minecraft:obsidian
fill ~18~175~12 ~18~175~13 minecraft:obsidian
fill ~18~177~12 ~19~177~13 minecraft:obsidian
fill ~18~178~12 ~18~179~12 minecraft:obsidian
fill ~18~188~12 ~21~189~12 minecraft:carved_pumpkin 1
fill ~18~190~12 ~20~190~12 minecraft:carved_pumpkin 1
setblock ~19~179~12 minecraft:obsidian
setblock ~19~182~12 minecraft:obsidian
fill ~19~187~12 ~20~187~12 minecraft:carved_pumpkin 1
setblock ~19~191~12 minecraft:carved_pumpkin 1
fill ~19~195~12 ~20~195~14 minecraft:obsidian
fill ~20~180~12 ~20~181~13 minecraft:obsidian
fill ~20~191~12 ~24~191~12 minecraft:red_mushroom_block 0
fill ~20~192~12 ~21~192~12 minecraft:red_mushroom_block 0
fill ~20~194~12 ~21~194~15 minecraft:obsidian
fill ~21~177~12 ~21~177~13 minecraft:obsidian
fill ~21~190~12 ~23~190~12 minecraft:red_mushroom_block 0
fill ~21~193~12 ~22~193~15 minecraft:obsidian
fill ~22~175~12 ~22~176~13 minecraft:obsidian
fill ~22~180~12 ~22~180~13 minecraft:obsidian
setblock ~22~189~12 minecraft:red_mushroom_block 0
fill ~22~192~12 ~22~192~15 minecraft:obsidian
fill ~23~176~12 ~23~177~13 minecraft:obsidian
fill ~23~179~12 ~23~179~14 minecraft:obsidian
setblock ~23~192~12 minecraft:redstone_block
setblock ~24~173~12 minecraft:obsidian
fill ~24~177~12 ~24~177~13 minecraft:obsidian
fill ~81~75~12 ~89~75~12 minecraft:obsidian
fill ~81~77~12 ~87~77~12 minecraft:obsidian
fill ~81~78~12 ~86~78~12 minecraft:obsidian
fill ~81~79~12 ~85~79~12 minecraft:obsidian
fill ~82~73~12 ~92~73~12 minecraft:obsidian
fill ~82~74~12 ~90~74~12 minecraft:obsidian
fill ~82~76~12 ~88~76~12 minecraft:obsidian
fill ~82~80~12 ~84~80~12 minecraft:obsidian
fill ~82~81~12 ~83~81~12 minecraft:obsidian
fill ~83~70~12 ~97~70~12 minecraft:obsidian
fill ~83~71~12 ~94~71~12 minecraft:obsidian
fill ~83~72~12 ~93~72~12 minecraft:obsidian
fill ~84~69~12 ~99~69~12 minecraft:obsidian
fill ~85~67~12 ~143~67~12 minecraft:obsidian
fill ~85~68~12 ~125~68~12 minecraft:obsidian
fill ~86~66~12 ~142~66~12 minecraft:obsidian
fill ~88~65~12 ~141~65~12 minecraft:obsidian
fill ~96~71~12 ~96~71~23 minecraft:obsidian
fill ~98~64~12 ~99~64~12 minecraft:obsidian
fill ~101~64~12 ~140~64~12 minecraft:obsidian
fill ~102~69~12 ~102~69~23 minecraft:obsidian
fill ~105~63~12 ~139~63~12 minecraft:obsidian
fill ~106~69~12 ~106~69~23 minecraft:obsidian
fill ~107~62~12 ~108~62~12 minecraft:obsidian
fill ~109~69~12 ~125~69~12 minecraft:obsidian
fill ~110~62~12 ~138~62~12 minecraft:obsidian
fill ~110~70~12 ~125~70~12 minecraft:obsidian
fill ~111~71~12 ~126~72~12 minecraft:obsidian
fill ~112~61~12 ~112~61~23 minecraft:obsidian
fill ~112~73~12 ~178~73~12 minecraft:obsidian
fill ~112~74~12 ~176~74~12 minecraft:obsidian
fill ~112~75~12 ~131~76~12 minecraft:obsidian
fill ~113~77~12 ~167~77~12 minecraft:obsidian
fill ~113~78~12 ~115~81~12 minecraft:obsidian
fill ~113~83~12 ~133~83~12 minecraft:obsidian
fill ~114~61~12 ~137~61~12 minecraft:obsidian
fill ~114~82~12 ~158~82~12 minecraft:obsidian
fill ~114~84~12 ~131~84~12 minecraft:obsidian
fill ~115~85~12 ~128~85~12 minecraft:obsidian
fill ~116~60~12 ~136~60~12 minecraft:obsidian
fill ~116~80~12 ~116~80~14 minecraft:obsidian
fill ~116~81~12 ~126~81~12 minecraft:obsidian
fill ~116~86~12 ~116~86~16 minecraft:obsidian
fill ~117~78~12 ~125~78~12 minecraft:obsidian
fill ~118~59~12 ~135~59~12 minecraft:obsidian
fill ~118~86~12 ~126~86~12 minecraft:obsidian
fill ~119~58~12 ~134~58~12 minecraft:obsidian
fill ~119~79~12 ~124~80~12 minecraft:obsidian
fill ~122~57~12 ~133~57~12 minecraft:obsidian
fill ~123~56~12 ~132~56~12 minecraft:obsidian
fill ~124~53~12 ~132~53~12 minecraft:obsidian
fill ~124~55~12 ~131~55~12 minecraft:obsidian
fill ~125~52~12 ~133~52~12 minecraft:obsidian
fill ~125~54~12 ~131~54~12 minecraft:obsidian
fill ~125~80~12 ~125~80~14 minecraft:obsidian
fill ~126~51~12 ~134~51~12 minecraft:obsidian
fill ~127~49~12 ~136~49~12 minecraft:obsidian
fill ~127~50~12 ~135~50~12 minecraft:obsidian
fill ~127~68~12 ~144~68~12 minecraft:obsidian
fill ~127~72~12 ~181~72~12 minecraft:obsidian
fill ~127~78~12 ~165~78~12 minecraft:obsidian
fill ~128~47~12 ~138~47~12 minecraft:obsidian
fill ~128~48~12 ~137~48~12 minecraft:obsidian
fill ~128~69~12 ~145~69~12 minecraft:obsidian
fill ~128~71~12 ~183~71~12 minecraft:obsidian
fill ~128~79~12 ~163~79~12 minecraft:obsidian
fill ~128~81~12 ~159~81~12 minecraft:obsidian
fill ~129~44~12 ~141~44~12 minecraft:obsidian
fill ~129~46~12 ~139~46~12 minecraft:obsidian
fill ~129~70~12 ~186~70~12 minecraft:obsidian
fill ~129~80~12 ~160~80~12 minecraft:obsidian
fill ~130~42~12 ~143~42~12 minecraft:obsidian
fill ~130~43~12 ~142~43~12 minecraft:obsidian
fill ~130~45~12 ~140~45~12 minecraft:obsidian
fill ~131~39~12 ~146~39~12 minecraft:obsidian
fill ~131~40~12 ~145~40~12 minecraft:obsidian
fill ~131~41~12 ~144~41~12 minecraft:obsidian
fill ~132~37~12 ~148~37~12 minecraft:obsidian
fill ~132~38~12 ~147~38~12 minecraft:obsidian
fill ~133~33~12 ~152~33~12 minecraft:obsidian
fill ~133~35~12 ~150~35~12 minecraft:obsidian
fill ~133~36~12 ~149~36~12 minecraft:obsidian
fill ~134~26~12 ~188~26~12 minecraft:obsidian
fill ~134~29~12 ~156~29~12 minecraft:obsidian
fill ~134~31~12 ~154~31~12 minecraft:obsidian
fill ~134~32~12 ~153~32~12 minecraft:obsidian
fill ~134~34~12 ~151~34~12 minecraft:obsidian
fill ~134~75~12 ~174~75~12 minecraft:obsidian
fill ~134~76~12 ~171~76~12 minecraft:obsidian
fill ~134~110~12 ~137~110~12 minecraft:obsidian
fill ~135~21~12 ~185~21~12 minecraft:obsidian
fill ~135~23~12 ~187~25~12 minecraft:obsidian
fill ~135~27~12 ~189~27~12 minecraft:obsidian
fill ~135~28~12 ~157~28~12 minecraft:obsidian
fill ~135~30~12 ~155~30~12 minecraft:obsidian
fill ~135~109~12 ~141~109~12 minecraft:obsidian
fill ~136~8~12 ~170~20~12 minecraft:obsidian
fill ~136~22~12 ~186~22~12 minecraft:obsidian
fill ~136~83~12 ~137~83~23 minecraft:obsidian
fill ~136~108~12 ~142~108~12 minecraft:obsidian
fill ~137~7~12 ~169~7~12 minecraft:obsidian
fill ~137~107~12 ~143~107~12 minecraft:obsidian
fill ~138~6~12 ~168~6~12 minecraft:obsidian
fill ~138~106~12 ~144~106~12 minecraft:obsidian
fill ~139~5~12 ~166~5~12 minecraft:obsidian
fill ~139~83~12 ~157~83~12 minecraft:obsidian
fill ~139~105~12 ~145~105~12 minecraft:obsidian
fill ~139~110~12 ~139~110~23 minecraft:obsidian
fill ~140~104~12 ~146~104~12 minecraft:obsidian
fill ~141~4~12 ~163~4~12 minecraft:obsidian
fill ~141~84~12 ~156~84~12 minecraft:obsidian
fill ~141~102~12 ~148~102~12 minecraft:obsidian
fill ~141~103~12 ~147~103~12 minecraft:obsidian
fill ~142~3~12 ~162~3~12 minecraft:obsidian
fill ~142~85~12 ~155~86~12 minecraft:obsidian
fill ~142~99~12 ~150~99~12 minecraft:obsidian
fill ~142~101~12 ~148~101~12 minecraft:obsidian
fill ~143~87~12 ~155~87~12 minecraft:obsidian
fill ~143~88~12 ~154~89~12 minecraft:obsidian
fill ~143~95~12 ~151~96~12 minecraft:obsidian
fill ~143~97~12 ~150~98~12 minecraft:obsidian
fill ~143~100~12 ~149~100~12 minecraft:obsidian
fill ~144~2~12 ~144~2~19 minecraft:obsidian
fill ~144~90~12 ~153~91~12 minecraft:obsidian
fill ~144~92~12 ~152~94~12 minecraft:obsidian
fill ~146~2~12 ~160~2~12 minecraft:obsidian
fill ~148~1~12 ~148~1~20 minecraft:obsidian
fill ~151~1~12 ~152~1~12 minecraft:obsidian
fill ~151~69~12 ~187~69~12 minecraft:obsidian
fill ~152~68~12 ~189~68~12 minecraft:obsidian
fill ~153~67~12 ~190~67~12 minecraft:obsidian
fill ~154~66~12 ~191~66~12 minecraft:obsidian
fill ~155~1~12 ~155~1~20 minecraft:obsidian
fill ~155~65~12 ~192~65~12 minecraft:obsidian
fill ~156~64~12 ~193~64~12 minecraft:obsidian
fill ~156~86~12 ~156~86~23 minecraft:obsidian
fill ~157~63~12 ~194~63~12 minecraft:obsidian
fill ~158~62~12 ~195~62~12 minecraft:obsidian
fill ~159~28~12 ~190~28~12 minecraft:obsidian
fill ~159~61~12 ~196~61~12 minecraft:obsidian
fill ~160~29~12 ~191~29~12 minecraft:obsidian
fill ~160~60~12 ~196~60~12 minecraft:obsidian
fill ~161~30~12 ~192~30~12 minecraft:obsidian
fill ~161~59~12 ~197~59~12 minecraft:obsidian
fill ~162~31~12 ~193~31~12 minecraft:obsidian
fill ~162~58~12 ~198~58~12 minecraft:obsidian
fill ~163~32~12 ~194~32~12 minecraft:obsidian
fill ~163~57~12 ~199~57~12 minecraft:obsidian
fill ~164~33~12 ~195~33~12 minecraft:obsidian
fill ~164~56~12 ~198~56~12 minecraft:obsidian
fill ~165~4~12 ~165~4~21 minecraft:obsidian
fill ~165~34~12 ~196~34~12 minecraft:obsidian
fill ~165~55~12 ~199~55~12 minecraft:obsidian
fill ~166~35~12 ~197~35~12 minecraft:obsidian
fill ~166~54~12 ~200~54~12 minecraft:obsidian
fill ~167~36~12 ~197~36~12 minecraft:obsidian
fill ~167~53~12 ~200~53~12 minecraft:obsidian
fill ~168~37~12 ~198~37~12 minecraft:obsidian
fill ~168~52~12 ~200~52~12 minecraft:obsidian
fill ~169~38~12 ~198~38~12 minecraft:obsidian
fill ~169~51~12 ~200~51~12 minecraft:obsidian
fill ~170~39~12 ~198~39~12 minecraft:obsidian
fill ~170~50~12 ~201~50~12 minecraft:obsidian
fill ~171~9~12 ~171~20~12 minecraft:obsidian
fill ~171~40~12 ~199~40~12 minecraft:obsidian
fill ~171~49~12 ~201~49~12 minecraft:obsidian
fill ~172~10~12 ~172~20~12 minecraft:obsidian
fill ~172~41~12 ~199~41~12 minecraft:obsidian
fill ~172~48~12 ~201~48~12 minecraft:obsidian
fill ~173~11~12 ~173~20~12 minecraft:obsidian
fill ~173~42~12 ~200~42~12 minecraft:obsidian
fill ~173~47~12 ~201~47~12 minecraft:obsidian
fill ~174~12~12 ~174~20~12 minecraft:obsidian
fill ~174~43~12 ~200~46~12 minecraft:obsidian
fill ~175~13~12 ~175~20~12 minecraft:obsidian
fill ~176~14~12 ~176~20~12 minecraft:obsidian
fill ~177~15~12 ~177~20~12 minecraft:obsidian
fill ~178~16~12 ~180~20~12 minecraft:obsidian
fill ~179~15~12 ~179~15~23 minecraft:obsidian
fill ~180~73~12 ~180~73~23 minecraft:obsidian
fill ~181~17~12 ~181~17~23 minecraft:obsidian
fill ~181~19~12 ~181~20~12 minecraft:obsidian
fill ~182~20~12 ~184~20~12 minecraft:obsidian
fill ~188~24~12 ~188~25~23 minecraft:obsidian
fill ~201~46~12 ~201~46~23 minecraft:obsidian
fill ~9~191~13 ~10~191~13 minecraft:obsidian
fill ~9~194~13 ~9~195~13 minecraft:obsidian
fill ~10~193~13 ~12~193~13 minecraft:obsidian
setblock ~10~197~13 minecraft:obsidian
setblock ~11~192~13 minecraft:obsidian
fill ~11~194~13 ~13~194~13 minecraft:obsidian
fill ~11~198~13 ~15~198~13 minecraft:obsidian
fill ~13~195~13 ~14~195~13 minecraft:obsidian
fill ~13~197~13 ~16~197~13 minecraft:obsidian
fill ~13~199~13 ~15~199~13 minecraft:obsidian
fill ~14~176~13 ~17~176~13 minecraft:obsidian
fill ~14~183~13 ~15~183~16 minecraft:obsidian
setblock ~14~196~13 minecraft:brown_mushroom_block 0
fill ~14~200~13 ~15~200~13 minecraft:obsidian
fill ~15~175~13 ~16~175~13 minecraft:obsidian
fill ~15~177~13 ~17~177~13 minecraft:obsidian
fill ~15~182~13 ~15~182~16 minecraft:obsidian
setblock ~15~196~13 minecraft:obsidian
fill ~16~170~13 ~16~171~14 minecraft:obsidian
setblock ~16~172~13 minecraft:obsidian
fill ~16~180~13 ~16~180~16 minecraft:obsidian
fill ~16~181~13 ~19~181~13 minecraft:carved_pumpkin 1
setblock ~16~182~13 minecraft:red_nether_brick
fill ~17~178~13 ~17~178~17 minecraft:obsidian
fill ~17~179~13 ~17~180~13 minecraft:yellow_glazed_terracotta 4
fill ~18~168~13 ~19~169~13 minecraft:obsidian
setblock ~18~180~13 minecraft:yellow_glazed_terracotta 4
fill ~19~170~13 ~21~170~13 minecraft:obsidian
fill ~19~173~13 ~19~173~14 minecraft:obsidian
setblock ~20~169~13 minecraft:obsidian
fill ~20~171~13 ~26~172~13 minecraft:obsidian
setblock ~20~182~13 minecraft:carved_pumpkin 1
fill ~20~186~13 ~23~186~13 minecraft:carved_pumpkin 1
fill ~21~173~13 ~23~173~13 minecraft:obsidian
fill ~21~183~13 ~21~185~13 minecraft:carved_pumpkin 1
fill ~21~187~13 ~22~187~13 minecraft:carved_pumpkin 1
fill ~22~174~13 ~25~174~13 minecraft:obsidian
fill ~22~184~13 ~22~185~13 minecraft:carved_pumpkin 1
setblock ~22~188~13 minecraft:carved_pumpkin 1
setblock ~23~185~13 minecraft:carved_pumpkin 1
fill ~23~187~13 ~25~188~13 minecraft:red_mushroom_block 0
fill ~23~189~13 ~24~189~13 minecraft:red_mushroom_block 0
fill ~23~191~13 ~24~191~16 minecraft:obsidian
fill ~23~192~13 ~23~192~16 minecraft:obsidian
fill ~24~170~13 ~25~170~15 minecraft:obsidian
fill ~24~175~13 ~24~175~14 minecraft:obsidian
setblock ~24~186~13 minecraft:red_mushroom_block 0
fill ~24~190~13 ~24~190~16 minecraft:obsidian
fill ~25~173~13 ~26~173~13 minecraft:obsidian
fill ~25~189~13 ~25~190~13 minecraft:red_nether_brick
setblock ~26~188~13 minecraft:red_mushroom_block 0
setblock ~26~189~13 minecraft:redstone_block
fill ~81~75~13 ~82~75~23 minecraft:obsidian
fill ~81~76~13 ~81~77~23 minecraft:obsidian
fill ~81~80~13 ~81~80~16 minecraft:obsidian
fill ~82~71~13 ~83~71~23 minecraft:obsidian
fill ~82~73~13 ~82~73~23 minecraft:obsidian
fill ~82~81~13 ~82~81~15 minecraft:obsidian
fill ~83~70~13 ~84~70~23 minecraft:obsidian
fill ~84~68~13 ~84~69~23 minecraft:obsidian
fill ~84~81~13 ~84~81~16 minecraft:obsidian
fill ~85~67~13 ~85~67~23 minecraft:obsidian
fill ~85~80~13 ~85~80~23 minecraft:obsidian
fill ~86~66~13 ~86~66~23 minecraft:obsidian
fill ~86~79~13 ~86~79~23 minecraft:obsidian
fill ~87~65~13 ~87~65~23 minecraft:obsidian
fill ~87~76~13 ~87~76~23 minecraft:obsidian
fill ~87~78~13 ~87~78~23 minecraft:obsidian
fill ~88~64~13 ~97~64~13 minecraft:obsidian
fill ~89~76~13 ~89~76~23 minecraft:obsidian
setblock ~90~63~13 minecraft:obsidian
fill ~90~75~13 ~90~75~23 minecraft:obsidian
fill ~91~74~13 ~91~74~23 minecraft:obsidian
fill ~92~73~13 ~92~73~23 minecraft:obsidian
fill ~93~63~13 ~104~63~13 minecraft:obsidian
fill ~93~72~13 ~93~72~23 minecraft:obsidian
fill ~95~71~13 ~95~72~23 minecraft:obsidian
fill ~96~70~13 ~98~70~23 minecraft:obsidian
fill ~100~62~13 ~101~62~13 minecraft:obsidian
setblock ~100~64~13 minecraft:obsidian
fill ~100~69~13 ~100~69~23 minecraft:obsidian
fill ~102~68~13 ~102~68~23 minecraft:obsidian
fill ~103~62~13 ~106~62~13 minecraft:obsidian
fill ~105~61~13 ~109~61~13 minecraft:obsidian
fill ~105~69~13 ~105~69~23 minecraft:obsidian
fill ~108~69~13 ~108~69~23 minecraft:obsidian
fill ~109~62~13 ~109~62~23 minecraft:obsidian
fill ~109~70~13 ~109~70~23 minecraft:obsidian
fill ~110~71~13 ~110~71~23 minecraft:obsidian
fill ~111~72~13 ~111~72~23 minecraft:obsidian
fill ~111~74~13 ~112~74~23 minecraft:obsidian
fill ~112~62~13 ~112~62~23 minecraft:obsidian
fill ~112~76~13 ~112~79~23 minecraft:obsidian
fill ~112~80~13 ~112~80~16 minecraft:obsidian
fill ~112~82~13 ~113~82~16 minecraft:obsidian
fill ~113~83~13 ~114~83~16 minecraft:obsidian
fill ~114~61~13 ~115~61~23 minecraft:obsidian
fill ~114~84~13 ~115~84~16 minecraft:obsidian
fill ~115~78~13 ~115~79~14 minecraft:obsidian
fill ~115~85~13 ~116~85~16 minecraft:obsidian
fill ~116~60~13 ~118~60~23 minecraft:obsidian
fill ~117~78~13 ~119~78~14 minecraft:obsidian
fill ~117~81~13 ~118~81~14 minecraft:obsidian
fill ~117~86~13 ~118~86~16 minecraft:obsidian
fill ~118~59~13 ~119~59~23 minecraft:obsidian
fill ~119~58~13 ~120~58~23 minecraft:obsidian
fill ~119~79~13 ~119~80~14 minecraft:obsidian
fill ~119~87~13 ~123~87~16 minecraft:obsidian
fill ~120~57~13 ~120~57~14 minecraft:obsidian
fill ~122~57~13 ~122~57~23 minecraft:obsidian
fill ~123~56~13 ~123~56~23 minecraft:obsidian
fill ~124~53~13 ~125~53~23 minecraft:obsidian
fill ~124~55~13 ~124~55~23 minecraft:obsidian
fill ~124~80~13 ~124~80~14 minecraft:obsidian
fill ~124~86~13 ~126~86~16 minecraft:obsidian
fill ~125~52~13 ~126~52~23 minecraft:obsidian
fill ~125~68~13 ~125~69~14 minecraft:obsidian
fill ~125~71~13 ~126~71~14 minecraft:obsidian
fill ~125~78~13 ~125~78~14 minecraft:obsidian
fill ~125~81~13 ~126~81~14 minecraft:obsidian
fill ~126~51~13 ~127~51~23 minecraft:obsidian
fill ~126~72~13 ~126~72~14 minecraft:obsidian
fill ~126~82~13 ~126~82~14 minecraft:obsidian
fill ~126~85~13 ~126~85~25 minecraft:obsidian
fill ~127~43~13 ~129~43~13 minecraft:obsidian
fill ~127~45~13 ~129~45~13 minecraft:obsidian
fill ~127~46~13 ~128~46~23 minecraft:obsidian
fill ~127~49~13 ~127~49~23 minecraft:obsidian
fill ~127~68~13 ~128~68~14 minecraft:obsidian
fill ~127~78~13 ~127~78~14 minecraft:obsidian
fill ~128~42~13 ~129~42~13 minecraft:obsidian
setblock ~128~44~13 minecraft:obsidian
fill ~128~69~13 ~128~69~14 minecraft:obsidian
fill ~128~71~13 ~128~71~14 minecraft:obsidian
fill ~128~79~13 ~128~79~14 minecraft:obsidian
fill ~128~81~13 ~128~81~14 minecraft:obsidian
fill ~128~85~13 ~130~85~23 minecraft:obsidian
fill ~129~40~13 ~130~41~13 minecraft:obsidian
fill ~130~36~13 ~132~36~13 minecraft:obsidian
fill ~130~38~13 ~131~38~13 minecraft:obsidian
setblock ~130~39~13 minecraft:obsidian
fill ~130~84~13 ~131~84~23 minecraft:obsidian
fill ~131~34~13 ~133~34~13 minecraft:obsidian
fill ~131~35~13 ~132~35~13 minecraft:obsidian
setblock ~131~37~13 minecraft:obsidian
fill ~131~75~13 ~131~77~14 minecraft:obsidian
fill ~131~83~13 ~131~83~23 minecraft:obsidian
fill ~132~27~13 ~134~28~13 minecraft:obsidian
fill ~132~30~13 ~134~30~13 minecraft:obsidian
fill ~132~31~13 ~133~32~13 minecraft:obsidian
setblock ~132~33~13 minecraft:obsidian
fill ~132~74~13 ~133~74~14 minecraft:obsidian
fill ~132~77~13 ~133~77~14 minecraft:obsidian
fill ~133~23~13 ~134~23~13 minecraft:obsidian
fill ~133~25~13 ~134~25~13 minecraft:obsidian
setblock ~133~26~13 minecraft:obsidian
setblock ~133~29~13 minecraft:obsidian
fill ~133~110~13 ~134~110~23 minecraft:obsidian
fill ~134~12~13 ~135~12~13 minecraft:obsidian
fill ~134~15~13 ~135~15~13 minecraft:obsidian
fill ~134~18~13 ~135~20~13 minecraft:obsidian
fill ~134~21~13 ~134~22~13 minecraft:obsidian
setblock ~134~24~13 minecraft:obsidian
fill ~134~75~13 ~134~76~14 minecraft:obsidian
fill ~134~83~13 ~134~83~23 minecraft:obsidian
fill ~134~109~13 ~134~109~23 minecraft:obsidian
fill ~134~111~13 ~136~111~23 minecraft:obsidian
fill ~135~9~13 ~135~9~22 minecraft:obsidian
fill ~135~10~13 ~135~11~13 minecraft:obsidian
fill ~135~13~13 ~135~14~13 minecraft:obsidian
fill ~135~16~13 ~135~17~13 minecraft:obsidian
setblock ~135~22~13 minecraft:obsidian
fill ~135~108~13 ~135~108~23 minecraft:obsidian
fill ~136~8~13 ~136~8~21 minecraft:obsidian
fill ~136~107~13 ~137~107~23 minecraft:obsidian
fill ~137~7~13 ~137~7~21 minecraft:obsidian
fill ~137~110~13 ~138~110~23 minecraft:obsidian
fill ~138~6~13 ~138~6~20 minecraft:obsidian
fill ~138~106~13 ~138~106~23 minecraft:obsidian
fill ~139~5~13 ~139~5~20 minecraft:obsidian
fill ~139~83~13 ~139~83~23 minecraft:obsidian
fill ~139~105~13 ~139~105~23 minecraft:obsidian
fill ~140~4~13 ~140~4~14 minecraft:obsidian
fill ~140~84~13 ~140~84~23 minecraft:obsidian
fill ~140~103~13 ~140~103~23 minecraft:obsidian
fill ~140~110~13 ~140~110~23 minecraft:obsidian
fill ~141~85~13 ~141~85~23 minecraft:obsidian
fill ~141~102~13 ~141~102~23 minecraft:obsidian
fill ~141~109~13 ~141~109~23 minecraft:obsidian
fill ~142~3~13 ~142~3~20 minecraft:obsidian
fill ~142~86~13 ~142~86~23 minecraft:obsidian
fill ~142~88~13 ~143~88~23 minecraft:obsidian
fill ~142~98~13 ~142~101~23 minecraft:obsidian
fill ~142~108~13 ~142~108~23 minecraft:obsidian
fill ~143~2~13 ~143~2~15 minecraft:obsidian
fill ~143~89~13 ~143~97~23 minecraft:obsidian
fill ~143~107~13 ~143~107~23 minecraft:obsidian
fill ~144~106~13 ~144~106~23 minecraft:obsidian
fill ~145~105~13 ~145~105~23 minecraft:obsidian
fill ~146~2~13 ~146~2~20 minecraft:obsidian
fill ~146~104~13 ~146~104~23 minecraft:obsidian
fill ~147~103~13 ~147~103~23 minecraft:obsidian
fill ~148~2~13 ~148~2~20 minecraft:obsidian
fill ~148~102~13 ~148~102~23 minecraft:obsidian
fill ~149~1~13 ~150~1~17 minecraft:obsidian
fill ~149~99~13 ~150~99~23 minecraft:obsidian
fill ~149~101~13 ~149~101~23 minecraft:obsidian
fill ~150~98~13 ~151~98~23 minecraft:obsidian
fill ~151~96~13 ~151~96~23 minecraft:obsidian
fill ~152~93~13 ~153~93~23 minecraft:obsidian
fill ~152~95~13 ~152~95~23 minecraft:obsidian
fill ~153~1~13 ~154~1~19 minecraft:obsidian
fill ~153~91~13 ~153~91~23 minecraft:obsidian
fill ~154~89~13 ~154~89~23 minecraft:obsidian
fill ~155~2~13 ~155~2~20 minecraft:obsidian
fill ~155~86~13 ~155~86~23 minecraft:obsidian
fill ~155~88~13 ~155~88~23 minecraft:obsidian
fill ~156~85~13 ~157~85~23 minecraft:obsidian
fill ~157~84~13 ~158~84~23 minecraft:obsidian
fill ~158~1~13 ~158~2~19 minecraft:obsidian
fill ~158~83~13 ~159~83~23 minecraft:obsidian
fill ~159~2~13 ~161~2~19 minecraft:obsidian
fill ~159~81~13 ~159~81~23 minecraft:obsidian
fill ~160~80~13 ~162~80~23 minecraft:obsidian
fill ~162~3~13 ~162~3~20 minecraft:obsidian
fill ~162~79~13 ~164~79~23 minecraft:obsidian
fill ~163~4~13 ~164~4~20 minecraft:obsidian
fill ~165~5~13 ~167~5~20 minecraft:obsidian
fill ~165~78~13 ~166~78~23 minecraft:obsidian
fill ~167~77~13 ~169~77~23 minecraft:obsidian
fill ~168~6~13 ~168~6~21 minecraft:obsidian
fill ~169~7~13 ~169~7~22 minecraft:obsidian
fill ~169~76~13 ~169~76~23 minecraft:obsidian
fill ~170~8~13 ~170~8~22 minecraft:obsidian
fill ~171~76~13 ~171~76~23 minecraft:obsidian
fill ~172~8~13 ~172~9~21 minecraft:obsidian
fill ~173~9~13 ~173~10~21 minecraft:obsidian
fill ~173~75~13 ~176~75~23 minecraft:obsidian
fill ~173~76~13 ~173~76~23 minecraft:obsidian
fill ~174~10~13 ~174~11~22 minecraft:obsidian
fill ~175~11~13 ~175~12~22 minecraft:obsidian
fill ~176~12~13 ~176~13~22 minecraft:obsidian
fill ~177~13~13 ~177~14~23 minecraft:obsidian
fill ~177~74~13 ~177~74~23 minecraft:obsidian
fill ~178~14~13 ~178~15~23 minecraft:obsidian
fill ~179~16~13 ~180~16~23 minecraft:obsidian
fill ~179~73~13 ~179~74~23 minecraft:obsidian
fill ~180~17~13 ~180~17~23 minecraft:obsidian
fill ~180~72~13 ~182~72~13 minecraft:obsidian
fill ~181~18~13 ~182~18~15 minecraft:obsidian
fill ~182~19~13 ~183~19~15 minecraft:obsidian
fill ~183~20~13 ~184~20~15 minecraft:obsidian
fill ~184~21~13 ~185~21~16 minecraft:obsidian
fill ~184~71~13 ~185~71~23 minecraft:obsidian
fill ~184~72~13 ~184~72~23 minecraft:obsidian
fill ~185~22~13 ~186~22~23 minecraft:obsidian
fill ~185~70~13 ~186~70~23 minecraft:obsidian
fill ~186~23~13 ~187~23~23 minecraft:obsidian
fill ~186~69~13 ~188~69~13 minecraft:obsidian
fill ~187~24~13 ~187~24~23 minecraft:obsidian
fill ~189~25~13 ~189~26~23 minecraft:obsidian
fill ~189~68~13 ~189~68~23 minecraft:obsidian
fill ~190~26~13 ~190~26~17 minecraft:obsidian
fill ~190~27~13 ~191~27~16 minecraft:obsidian
fill ~190~67~13 ~190~67~23 minecraft:obsidian
fill ~191~28~13 ~192~28~16 minecraft:obsidian
fill ~191~66~13 ~191~66~23 minecraft:obsidian
fill ~192~29~13 ~193~29~16 minecraft:obsidian
fill ~192~65~13 ~192~65~23 minecraft:obsidian
fill ~193~30~13 ~194~30~17 minecraft:obsidian
fill ~193~64~13 ~193~64~23 minecraft:obsidian
fill ~194~31~13 ~195~31~23 minecraft:obsidian
fill ~194~63~13 ~194~63~23 minecraft:obsidian
fill ~195~32~13 ~195~33~23 minecraft:obsidian
fill ~195~62~13 ~195~62~23 minecraft:obsidian
fill ~196~34~13 ~196~34~23 minecraft:obsidian
fill ~196~61~13 ~196~61~23 minecraft:obsidian
fill ~197~35~13 ~197~35~23 minecraft:obsidian
fill ~197~60~13 ~197~60~23 minecraft:obsidian
fill ~198~36~13 ~198~38~23 minecraft:obsidian
fill ~198~57~13 ~199~57~23 minecraft:obsidian
fill ~198~59~13 ~198~59~23 minecraft:obsidian
fill ~199~38~13 ~199~38~23 minecraft:obsidian
fill ~199~40~13 ~199~40~23 minecraft:obsidian
fill ~199~56~13 ~200~56~23 minecraft:obsidian
fill ~200~42~13 ~200~42~23 minecraft:obsidian
fill ~200~44~13 ~201~44~23 minecraft:obsidian
fill ~200~54~13 ~200~54~23 minecraft:obsidian
fill ~201~45~13 ~201~45~23 minecraft:obsidian
fill ~201~47~13 ~202~47~13 minecraft:obsidian
fill ~201~48~13 ~201~53~13 minecraft:obsidian
fill ~9~195~14 ~10~195~14 minecraft:obsidian
setblock ~10~194~14 minecraft:obsidian
fill ~10~196~14 ~10~196~16 minecraft:obsidian
fill ~11~190~14 ~11~191~14 minecraft:obsidian
fill ~11~197~14 ~12~197~14 minecraft:obsidian
setblock ~12~188~14 minecraft:obsidian
fill ~12~191~14 ~12~192~14 minecraft:obsidian
fill ~12~195~14 ~12~195~15 minecraft:obsidian
fill ~13~192~14 ~13~193~14 minecraft:obsidian
fill ~13~196~14 ~13~196~15 minecraft:obsidian
fill ~14~194~14 ~14~194~15 minecraft:obsidian
setblock ~15~195~14 minecraft:wool 0
setblock ~16~182~14 minecraft:obsidian
fill ~16~194~14 ~18~195~14 minecraft:obsidian
fill ~16~196~14 ~17~196~14 minecraft:obsidian
fill ~17~170~14 ~17~172~14 minecraft:obsidian
fill ~17~177~14 ~18~177~17 minecraft:obsidian
fill ~17~179~14 ~17~179~17 minecraft:obsidian
setblock ~17~193~14 minecraft:obsidian
fill ~18~168~14 ~18~168~15 minecraft:obsidian
fill ~18~171~14 ~18~172~14 minecraft:obsidian
fill ~18~176~14 ~19~176~14 minecraft:carved_pumpkin 1
fill ~19~172~14 ~20~172~14 minecraft:obsidian
setblock ~19~175~14 minecraft:yellow_glazed_terracotta 4
fill ~20~163~14 ~21~163~16 minecraft:obsidian
fill ~20~164~14 ~22~167~14 minecraft:obsidian
fill ~20~168~14 ~21~168~14 minecraft:obsidian
setblock ~20~176~14 minecraft:yellow_glazed_terracotta 4
fill ~21~170~14 ~21~170~15 minecraft:obsidian
setblock ~21~173~14 minecraft:obsidian
fill ~21~181~14 ~25~182~14 minecraft:carved_pumpkin 1
fill ~22~171~14 ~24~171~15 minecraft:obsidian
setblock ~22~174~14 minecraft:obsidian
setblock ~22~177~14 minecraft:obsidian
fill ~22~183~14 ~26~183~14 minecraft:carved_pumpkin 1
fill ~23~165~14 ~23~166~14 minecraft:obsidian
setblock ~23~175~14 minecraft:obsidian
setblock ~23~178~14 minecraft:obsidian
fill ~23~180~14 ~24~180~14 minecraft:carved_pumpkin 1
fill ~23~184~14 ~25~184~14 minecraft:carved_pumpkin 1
setblock ~24~166~14 minecraft:obsidian
fill ~24~185~14 ~25~185~14 minecraft:carved_pumpkin 1
fill ~25~167~14 ~29~167~14 minecraft:obsidian
fill ~25~174~14 ~25~174~15 minecraft:obsidian
fill ~25~186~14 ~29~186~14 minecraft:red_mushroom_block 0
fill ~25~189~14 ~26~189~17 minecraft:obsidian
fill ~25~190~14 ~25~190~17 minecraft:obsidian
fill ~26~166~14 ~28~166~14 minecraft:obsidian
fill ~26~171~14 ~26~171~16 minecraft:obsidian
fill ~26~173~14 ~26~173~15 minecraft:obsidian
setblock ~26~182~14 minecraft:carved_pumpkin 1
fill ~26~184~14 ~28~185~14 minecraft:red_mushroom_block 0
setblock ~26~187~14 minecraft:red_mushroom_block 0
fill ~26~188~14 ~27~188~17 minecraft:obsidian
fill ~27~165~14 ~27~165~17 minecraft:obsidian
setblock ~27~168~14 minecraft:obsidian
setblock ~27~183~14 minecraft:red_mushroom_block 0
fill ~27~187~14 ~27~187~17 minecraft:obsidian
setblock ~28~187~14 minecraft:red_nether_brick
setblock ~29~185~14 minecraft:red_mushroom_block 0
fill ~88~64~14 ~88~64~23 minecraft:obsidian
fill ~89~63~14 ~89~63~23 minecraft:obsidian
fill ~90~62~14 ~99~62~14 minecraft:obsidian
fill ~91~63~14 ~92~63~14 minecraft:obsidian
setblock ~92~61~14 minecraft:obsidian
setblock ~95~61~14 minecraft:obsidian
fill ~97~61~14 ~104~61~14 minecraft:obsidian
fill ~100~60~14 ~108~60~14 minecraft:obsidian
setblock ~102~62~14 minecraft:obsidian
setblock ~104~59~14 minecraft:obsidian
fill ~106~59~14 ~107~59~14 minecraft:obsidian
fill ~108~61~14 ~109~61~23 minecraft:obsidian
fill ~125~44~14 ~127~44~14 minecraft:obsidian
fill ~126~42~14 ~127~42~14 minecraft:obsidian
setblock ~126~43~14 minecraft:obsidian
fill ~126~45~14 ~127~45~23 minecraft:obsidian
fill ~127~39~14 ~129~39~14 minecraft:obsidian
fill ~127~40~14 ~128~41~14 minecraft:obsidian
fill ~128~35~14 ~130~35~14 minecraft:obsidian
fill ~128~37~14 ~130~37~14 minecraft:obsidian
fill ~128~38~14 ~129~38~14 minecraft:obsidian
fill ~129~31~14 ~131~31~14 minecraft:obsidian
fill ~129~33~14 ~131~33~14 minecraft:obsidian
fill ~129~34~14 ~130~34~14 minecraft:obsidian
setblock ~129~36~14 minecraft:obsidian
fill ~130~28~14 ~131~30~14 minecraft:obsidian
fill ~130~32~14 ~131~32~14 minecraft:obsidian
fill ~131~24~14 ~133~24~14 minecraft:obsidian
fill ~131~25~14 ~132~26~14 minecraft:obsidian
setblock ~131~27~14 minecraft:obsidian
fill ~132~14~14 ~134~14~14 minecraft:obsidian
fill ~132~17~14 ~134~17~14 minecraft:obsidian
fill ~132~20~14 ~133~22~14 minecraft:obsidian
setblock ~132~23~14 minecraft:obsidian
setblock ~132~29~14 minecraft:obsidian
fill ~133~11~14 ~134~11~14 minecraft:obsidian
fill ~133~12~14 ~133~13~14 minecraft:obsidian
fill ~133~15~14 ~133~16~14 minecraft:obsidian
fill ~133~18~14 ~133~19~14 minecraft:obsidian
fill ~134~10~14 ~134~10~22 minecraft:obsidian
setblock ~134~13~14 minecraft:obsidian
setblock ~134~16~14 minecraft:obsidian
fill ~181~73~14 ~181~73~15 minecraft:obsidian
fill ~182~72~14 ~182~72~23 minecraft:obsidian
fill ~186~69~14 ~186~69~23 minecraft:obsidian
fill ~188~69~14 ~188~69~23 minecraft:obsidian
fill ~201~49~14 ~201~53~23 minecraft:obsidian
fill ~202~47~14 ~202~48~23 minecraft:obsidian
fill ~10~197~15 ~10~197~16 minecraft:obsidian
fill ~11~195~15 ~11~195~16 minecraft:obsidian
fill ~12~190~15 ~13~190~15 minecraft:obsidian
fill ~12~197~15 ~12~197~16 minecraft:obsidian
fill ~13~187~15 ~17~188~15 minecraft:obsidian
setblock ~13~189~15 minecraft:obsidian
fill ~13~191~15 ~14~191~18 minecraft:obsidian
fill ~13~194~15 ~13~195~15 minecraft:obsidian
fill ~14~186~15 ~15~186~15 minecraft:obsidian
fill ~14~192~15 ~14~192~18 minecraft:obsidian
fill ~14~193~15 ~14~193~16 minecraft:obsidian
setblock ~14~195~15 minecraft:obsidian
fill ~15~181~15 ~15~181~16 minecraft:obsidian
setblock ~15~185~15 minecraft:obsidian
fill ~15~194~15 ~15~194~16 minecraft:obsidian
fill ~16~189~15 ~17~189~15 minecraft:obsidian
fill ~16~192~15 ~19~192~15 minecraft:obsidian
fill ~16~193~15 ~16~193~16 minecraft:obsidian
fill ~18~169~15 ~20~170~15 minecraft:obsidian
fill ~18~176~15 ~19~176~18 minecraft:obsidian
setblock ~18~188~15 minecraft:obsidian
fill ~18~193~15 ~20~193~15 minecraft:obsidian
fill ~19~164~15 ~20~164~16 minecraft:obsidian
setblock ~19~168~15 minecraft:obsidian
fill ~19~171~15 ~21~171~15 minecraft:obsidian
fill ~19~174~15 ~19~174~18 minecraft:obsidian
fill ~19~175~15 ~19~175~16 minecraft:obsidian
setblock ~19~189~15 minecraft:obsidian
setblock ~19~191~15 minecraft:brown_mushroom_block 0
setblock ~19~194~15 minecraft:obsidian
setblock ~20~166~15 minecraft:obsidian
setblock ~20~173~15 minecraft:redstone_block
fill ~20~174~15 ~21~174~15 minecraft:yellow_glazed_terracotta 4
setblock ~20~175~15 minecraft:carved_pumpkin 1
fill ~20~190~15 ~20~192~15 minecraft:snow
setblock ~20~195~15 minecraft:obsidian
fill ~21~162~15 ~23~162~16 minecraft:obsidian
fill ~21~167~15 ~24~167~15 minecraft:obsidian
fill ~21~175~15 ~22~175~15 minecraft:yellow_glazed_terracotta 4
setblock ~21~191~15 minecraft:snow
setblock ~21~192~15 minecraft:iron_block
fill ~22~163~15 ~24~163~16 minecraft:obsidian
setblock ~22~176~15 minecraft:yellow_glazed_terracotta 4
fill ~23~164~15 ~24~164~16 minecraft:obsidian
fill ~23~176~15 ~25~177~15 minecraft:carved_pumpkin 1
fill ~24~165~15 ~25~165~16 minecraft:obsidian
fill ~24~168~15 ~26~168~16 minecraft:obsidian
fill ~24~178~15 ~26~179~15 minecraft:carved_pumpkin 1
fill ~25~166~15 ~25~166~16 minecraft:obsidian
setblock ~25~175~15 minecraft:carved_pumpkin 1
fill ~25~180~15 ~28~180~15 minecraft:carved_pumpkin 1
setblock ~26~177~15 minecraft:carved_pumpkin 1
fill ~26~181~15 ~29~181~15 minecraft:carved_pumpkin 1
fill ~27~169~15 ~29~169~16 minecraft:obsidian
setblock ~27~179~15 minecraft:carved_pumpkin 1
fill ~27~182~15 ~28~182~15 minecraft:carved_pumpkin 1
fill ~28~164~15 ~28~165~17 minecraft:obsidian
setblock ~28~168~15 minecraft:obsidian
fill ~28~170~15 ~28~170~16 minecraft:obsidian
fill ~28~183~15 ~31~183~15 minecraft:red_mushroom_block 0
fill ~28~186~15 ~29~186~18 minecraft:obsidian
fill ~28~187~15 ~28~187~18 minecraft:obsidian
fill ~29~165~15 ~29~167~17 minecraft:obsidian
fill ~29~182~15 ~30~182~15 minecraft:red_mushroom_block 0
setblock ~29~184~15 minecraft:red_mushroom_block 0
fill ~29~185~15 ~29~185~18 minecraft:obsidian
fill ~30~166~15 ~30~166~16 minecraft:obsidian
fill ~30~184~15 ~31~184~15 minecraft:redstone_block
setblock ~30~185~15 minecraft:red_nether_brick
fill ~90~62~15 ~90~62~23 minecraft:obsidian
setblock ~91~61~15 minecraft:obsidian
fill ~93~60~15 ~99~60~15 minecraft:obsidian
fill ~93~61~15 ~94~61~15 minecraft:obsidian
fill ~94~59~15 ~94~59~23 minecraft:obsidian
setblock ~96~61~15 minecraft:obsidian
fill ~97~59~15 ~103~59~15 minecraft:obsidian
fill ~100~58~15 ~107~58~15 minecraft:obsidian
setblock ~103~57~15 minecraft:obsidian
fill ~105~57~15 ~108~57~15 minecraft:obsidian
setblock ~105~59~15 minecraft:obsidian
setblock ~107~56~15 minecraft:obsidian
fill ~107~59~15 ~107~60~23 minecraft:obsidian
fill ~108~60~15 ~108~60~23 minecraft:obsidian
fill ~111~55~15 ~113~55~15 minecraft:obsidian
fill ~112~54~15 ~113~54~15 minecraft:obsidian
fill ~112~56~15 ~112~56~23 minecraft:obsidian
fill ~116~52~15 ~117~52~15 minecraft:obsidian
fill ~116~78~15 ~116~79~15 minecraft:obsidian
setblock ~117~51~15 minecraft:obsidian
fill ~117~79~15 ~118~80~15 minecraft:obsidian
fill ~121~47~15 ~121~48~15 minecraft:obsidian
fill ~121~58~15 ~121~58~17 minecraft:obsidian
fill ~123~43~15 ~125~43~15 minecraft:obsidian
fill ~124~39~15 ~126~39~15 minecraft:obsidian
fill ~124~41~15 ~126~41~15 minecraft:obsidian
fill ~124~42~15 ~125~42~15 minecraft:obsidian
fill ~124~44~15 ~126~44~23 minecraft:obsidian
fill ~125~37~15 ~127~38~15 minecraft:obsidian
fill ~125~40~15 ~126~40~15 minecraft:obsidian
fill ~125~79~15 ~127~79~15 minecraft:obsidian
fill ~126~36~15 ~128~36~15 minecraft:obsidian
fill ~126~68~15 ~126~70~15 minecraft:obsidian
setblock ~126~78~15 minecraft:obsidian
fill ~126~80~15 ~128~80~15 minecraft:obsidian
fill ~127~32~15 ~129~32~15 minecraft:obsidian
fill ~127~33~15 ~128~34~15 minecraft:obsidian
setblock ~127~35~15 minecraft:obsidian
fill ~127~69~15 ~127~71~15 minecraft:obsidian
setblock ~127~81~15 minecraft:obsidian
fill ~128~28~15 ~129~28~15 minecraft:obsidian
fill ~128~30~15 ~129~30~15 minecraft:obsidian
setblock ~128~31~15 minecraft:obsidian
setblock ~128~70~15 minecraft:obsidian
fill ~129~24~15 ~130~27~15 minecraft:obsidian
setblock ~129~29~15 minecraft:obsidian
fill ~130~18~15 ~132~19~15 minecraft:obsidian
fill ~130~21~15 ~131~23~15 minecraft:obsidian
fill ~131~13~15 ~132~13~15 minecraft:obsidian
fill ~131~14~15 ~131~14~23 minecraft:obsidian
fill ~131~15~15 ~132~16~15 minecraft:obsidian
setblock ~131~17~15 minecraft:obsidian
setblock ~131~20~15 minecraft:obsidian
fill ~132~12~15 ~132~12~22 minecraft:obsidian
fill ~132~75~15 ~133~76~15 minecraft:obsidian
fill ~133~11~15 ~133~11~22 minecraft:obsidian
fill ~141~4~15 ~141~4~21 minecraft:obsidian
fill ~11~196~16 ~12~196~16 minecraft:obsidian
setblock ~11~197~16 minecraft:obsidian
fill ~13~190~16 ~13~190~18 minecraft:obsidian
fill ~14~189~16 ~15~189~16 minecraft:obsidian
setblock ~15~184~16 minecraft:obsidian
fill ~15~190~16 ~15~190~17 minecraft:obsidian
fill ~15~192~16 ~17~192~16 minecraft:obsidian
setblock ~15~193~16 minecraft:obsidian
fill ~16~181~16 ~17~181~16 minecraft:obsidian
setblock ~16~182~16 minecraft:obsidian
fill ~16~185~16 ~16~185~19 minecraft:obsidian
fill ~16~186~16 ~22~186~16 minecraft:obsidian
fill ~16~191~16 ~18~191~16 minecraft:obsidian
setblock ~18~187~16 minecraft:obsidian
fill ~18~189~16 ~18~190~17 minecraft:obsidian
fill ~19~185~16 ~21~185~16 minecraft:obsidian
fill ~19~188~16 ~20~188~16 minecraft:obsidian
fill ~19~190~16 ~19~190~17 minecraft:obsidian
fill ~20~165~16 ~23~165~16 minecraft:obsidian
fill ~20~173~16 ~20~173~19 minecraft:obsidian
setblock ~20~184~16 minecraft:obsidian
fill ~20~187~16 ~21~187~16 minecraft:obsidian
fill ~20~189~16 ~20~189~17 minecraft:obsidian
fill ~21~164~16 ~22~164~16 minecraft:obsidian
fill ~21~166~16 ~23~166~16 minecraft:obsidian
fill ~21~171~16 ~21~171~19 minecraft:obsidian
fill ~21~189~16 ~23~189~16 minecraft:snow
fill ~21~190~16 ~22~190~16 minecraft:snow
fill ~22~167~16 ~24~167~16 minecraft:obsidian
setblock ~22~170~16 minecraft:red_mushroom_block 0
setblock ~22~188~16 minecraft:snow
setblock ~22~191~16 minecraft:obsidian
setblock ~23~169~16 minecraft:carved_pumpkin 1
setblock ~23~170~16 minecraft:yellow_glazed_terracotta 4
setblock ~23~190~16 minecraft:obsidian
setblock ~24~170~16 minecraft:obsidian
fill ~26~174~16 ~28~176~16 minecraft:carved_pumpkin 1
setblock ~27~173~16 minecraft:carved_pumpkin 1
fill ~27~177~16 ~31~178~16 minecraft:carved_pumpkin 1
fill ~28~179~16 ~31~179~16 minecraft:carved_pumpkin 1
fill ~29~175~16 ~29~176~16 minecraft:carved_pumpkin 1
fill ~29~180~16 ~30~180~16 minecraft:carved_pumpkin 1
setblock ~30~176~16 minecraft:carved_pumpkin 1
fill ~30~181~16 ~35~181~16 minecraft:red_mushroom_block 0
fill ~30~184~16 ~31~184~19 minecraft:obsidian
fill ~30~185~16 ~30~185~18 minecraft:obsidian
fill ~31~180~16 ~34~180~16 minecraft:red_mushroom_block 0
setblock ~31~182~16 minecraft:red_mushroom_block 0
fill ~31~183~16 ~31~183~17 minecraft:obsidian
fill ~32~178~16 ~32~179~16 minecraft:red_mushroom_block 0
fill ~32~182~16 ~32~183~16 minecraft:red_nether_brick
setblock ~33~179~16 minecraft:red_mushroom_block 0
setblock ~33~182~16 minecraft:red_mushroom_block 0
fill ~33~183~16 ~33~183~19 minecraft:obsidian
setblock ~34~182~16 minecraft:red_nether_brick
fill ~80~83~16 ~83~83~16 minecraft:obsidian
fill ~80~84~16 ~80~84~19 minecraft:obsidian
fill ~81~81~16 ~81~82~16 minecraft:obsidian
fill ~82~82~16 ~84~82~16 minecraft:obsidian
fill ~82~84~16 ~84~84~16 minecraft:obsidian
fill ~92~61~16 ~93~61~23 minecraft:obsidian
fill ~92~62~16 ~92~62~23 minecraft:obsidian
fill ~93~60~16 ~94~60~23 minecraft:obsidian
fill ~95~58~16 ~99~58~16 minecraft:obsidian
fill ~95~59~16 ~96~59~16 minecraft:obsidian
fill ~96~57~16 ~96~57~17 minecraft:obsidian
fill ~98~57~16 ~102~57~16 minecraft:obsidian
fill ~100~56~16 ~106~56~16 minecraft:obsidian
fill ~104~55~16 ~110~55~16 minecraft:obsidian
setblock ~104~57~16 minecraft:obsidian
fill ~105~54~16 ~111~54~16 minecraft:obsidian
fill ~107~58~16 ~107~58~23 minecraft:obsidian
fill ~108~56~16 ~111~56~16 minecraft:obsidian
fill ~108~57~16 ~108~57~23 minecraft:obsidian
fill ~109~53~16 ~115~53~16 minecraft:obsidian
fill ~110~52~16 ~115~52~16 minecraft:obsidian
fill ~112~51~16 ~116~51~16 minecraft:obsidian
fill ~113~50~16 ~118~50~16 minecraft:obsidian
fill ~113~54~16 ~113~55~23 minecraft:obsidian
fill ~114~49~16 ~120~49~16 minecraft:obsidian
fill ~117~48~16 ~121~48~16 minecraft:obsidian
fill ~117~52~16 ~117~52~23 minecraft:obsidian
fill ~118~47~16 ~120~47~16 minecraft:obsidian
fill ~119~44~16 ~123~45~16 minecraft:obsidian
fill ~119~46~16 ~122~46~16 minecraft:obsidian
fill ~120~43~16 ~122~43~16 minecraft:obsidian
fill ~121~41~16 ~123~42~16 minecraft:obsidian
fill ~122~40~16 ~124~40~16 minecraft:obsidian
fill ~122~47~16 ~122~47~23 minecraft:obsidian
fill ~123~37~16 ~124~38~16 minecraft:obsidian
setblock ~123~39~16 minecraft:obsidian
fill ~124~35~16 ~126~35~16 minecraft:obsidian
fill ~124~36~16 ~125~36~16 minecraft:obsidian
fill ~125~31~16 ~127~31~16 minecraft:obsidian
fill ~125~33~16 ~126~34~16 minecraft:obsidian
fill ~126~29~16 ~128~29~16 minecraft:obsidian
fill ~126~30~16 ~127~30~16 minecraft:obsidian
setblock ~126~32~16 minecraft:obsidian
fill ~127~25~16 ~128~27~16 minecraft:obsidian
setblock ~127~28~16 minecraft:obsidian
fill ~128~18~16 ~129~18~23 minecraft:obsidian
fill ~128~20~16 ~130~20~16 minecraft:obsidian
fill ~128~21~16 ~129~21~16 minecraft:obsidian
fill ~128~23~16 ~129~23~16 minecraft:obsidian
setblock ~128~24~16 minecraft:obsidian
fill ~129~16~16 ~130~17~16 minecraft:obsidian
setblock ~129~19~16 minecraft:obsidian
setblock ~129~22~16 minecraft:obsidian
fill ~130~15~16 ~130~15~23 minecraft:obsidian
fill ~131~13~16 ~131~13~18 minecraft:obsidian
fill ~144~3~16 ~144~3~20 minecraft:obsidian
fill ~180~72~16 ~181~72~16 minecraft:obsidian
fill ~182~17~16 ~184~17~19 minecraft:obsidian
fill ~183~16~16 ~183~16~20 minecraft:obsidian
fill ~183~18~16 ~185~18~16 minecraft:obsidian
fill ~184~19~16 ~184~20~16 minecraft:obsidian
setblock ~187~69~16 minecraft:obsidian
setblock ~190~28~16 minecraft:obsidian
fill ~190~30~16 ~191~31~16 minecraft:obsidian
setblock ~191~29~16 minecraft:obsidian
setblock ~191~32~16 minecraft:obsidian
setblock ~15~189~17 minecraft:obsidian
fill ~15~191~17 ~15~191~18 minecraft:obsidian
setblock ~16~183~17 minecraft:obsidian
fill ~16~190~17 ~17~190~17 minecraft:obsidian
fill ~17~180~17 ~18~180~17 minecraft:obsidian
fill ~17~182~17 ~22~182~17 minecraft:obsidian
fill ~17~186~17 ~17~186~19 minecraft:obsidian
setblock ~17~189~17 minecraft:obsidian
setblock ~18~178~17 minecraft:obsidian
fill ~18~181~17 ~19~181~17 minecraft:obsidian
fill ~18~183~17 ~19~183~17 minecraft:obsidian
fill ~18~185~17 ~18~185~19 minecraft:obsidian
fill ~18~188~17 ~19~188~17 minecraft:obsidian
setblock ~18~191~17 minecraft:obsidian
fill ~19~184~17 ~19~184~19 minecraft:obsidian
fill ~19~187~17 ~19~187~18 minecraft:obsidian
setblock ~19~189~17 minecraft:obsidian
fill ~21~183~17 ~23~183~17 minecraft:obsidian
setblock ~21~184~17 minecraft:obsidian
fill ~21~188~17 ~21~188~18 minecraft:obsidian
fill ~22~170~17 ~22~170~20 minecraft:obsidian
fill ~22~185~17 ~23~185~17 minecraft:obsidian
setblock ~22~187~17 minecraft:coal_block
fill ~23~167~17 ~24~167~17 minecraft:nether_wart_block
fill ~23~168~17 ~23~168~20 minecraft:obsidian
setblock ~23~169~17 minecraft:obsidian
fill ~23~184~17 ~24~184~17 minecraft:snow
fill ~23~187~17 ~23~188~17 minecraft:snow
setblock ~24~166~17 minecraft:red_mushroom_block 0
setblock ~24~169~17 minecraft:carved_pumpkin 1
setblock ~24~186~17 minecraft:snow
fill ~24~187~17 ~26~187~17 minecraft:obsidian
setblock ~24~188~17 minecraft:snow
setblock ~24~189~17 minecraft:obsidian
fill ~25~165~17 ~25~166~17 minecraft:carved_pumpkin 1
fill ~25~169~17 ~26~170~17 minecraft:yellow_glazed_terracotta 4
setblock ~25~185~17 minecraft:snow
fill ~25~186~17 ~26~186~17 minecraft:obsidian
setblock ~25~188~17 minecraft:obsidian
fill ~27~170~17 ~27~171~17 minecraft:yellow_glazed_terracotta 4
setblock ~27~172~17 minecraft:planks 0
fill ~28~169~17 ~29~169~17 minecraft:yellow_glazed_terracotta 4
setblock ~28~171~17 minecraft:planks 0
fill ~28~172~17 ~32~173~17 minecraft:carved_pumpkin 1
setblock ~29~170~17 minecraft:yellow_glazed_terracotta 4
fill ~29~171~17 ~31~171~17 minecraft:carved_pumpkin 1
fill ~29~174~17 ~34~174~17 minecraft:carved_pumpkin 1
setblock ~30~170~17 minecraft:carved_pumpkin 1
fill ~30~175~17 ~34~175~17 minecraft:carved_pumpkin 1
fill ~31~176~17 ~33~176~17 minecraft:carved_pumpkin 1
setblock ~32~177~17 minecraft:carved_pumpkin 1
setblock ~33~173~17 minecraft:carved_pumpkin 1
fill ~33~177~17 ~37~178~17 minecraft:red_mushroom_block 0
fill ~34~176~17 ~36~176~17 minecraft:red_mushroom_block 0
fill ~34~179~17 ~36~179~17 minecraft:red_mushroom_block 0
fill ~34~182~17 ~34~182~20 minecraft:obsidian
setblock ~35~175~17 minecraft:red_mushroom_block 0
setblock ~35~180~17 minecraft:red_mushroom_block 0
fill ~35~181~17 ~35~181~20 minecraft:obsidian
setblock ~36~180~17 minecraft:red_nether_brick
setblock ~37~179~17 minecraft:redstone_block
setblock ~38~178~17 minecraft:red_mushroom_block 0
fill ~79~83~17 ~80~83~19 minecraft:obsidian
fill ~80~79~17 ~80~82~18 minecraft:obsidian
fill ~82~84~17 ~82~84~20 minecraft:obsidian
fill ~84~82~17 ~85~82~18 minecraft:obsidian
fill ~84~83~17 ~84~84~17 minecraft:obsidian
fill ~85~81~17 ~85~81~18 minecraft:obsidian
fill ~95~58~17 ~96~58~23 minecraft:obsidian
fill ~95~59~17 ~95~59~23 minecraft:obsidian
fill ~98~57~17 ~98~57~23 minecraft:obsidian
fill ~99~56~17 ~101~56~23 minecraft:obsidian
fill ~101~55~17 ~103~55~17 minecraft:obsidian
fill ~102~54~17 ~104~54~20 minecraft:obsidian
fill ~105~53~17 ~108~53~17 minecraft:obsidian
fill ~107~52~17 ~109~52~17 minecraft:obsidian
fill ~108~51~17 ~111~51~17 minecraft:obsidian
fill ~109~50~17 ~112~50~17 minecraft:obsidian
fill ~109~56~17 ~111~56~23 minecraft:obsidian
fill ~111~49~17 ~113~49~17 minecraft:obsidian
fill ~111~81~17 ~112~81~17 minecraft:yellow_glazed_terracotta 4
fill ~112~48~17 ~116~48~17 minecraft:obsidian
setblock ~112~80~17 minecraft:red_sandstone 0
fill ~112~83~17 ~112~84~17 minecraft:yellow_glazed_terracotta 4
fill ~113~47~17 ~117~47~17 minecraft:obsidian
fill ~113~53~17 ~113~53~23 minecraft:obsidian
fill ~113~84~17 ~113~85~17 minecraft:yellow_glazed_terracotta 4
fill ~113~86~17 ~115~87~17 minecraft:carved_pumpkin 1
fill ~114~46~17 ~118~46~17 minecraft:obsidian
setblock ~114~85~17 minecraft:carved_pumpkin 1
fill ~114~88~17 ~119~88~17 minecraft:carved_pumpkin 1
fill ~115~53~17 ~115~53~23 minecraft:obsidian
fill ~116~44~17 ~118~45~17 minecraft:obsidian
fill ~116~87~17 ~118~87~17 minecraft:carved_pumpkin 1
fill ~117~43~17 ~119~43~17 minecraft:obsidian
fill ~118~42~17 ~120~42~17 minecraft:obsidian
fill ~118~50~17 ~118~50~23 minecraft:obsidian
fill ~119~41~17 ~120~41~17 minecraft:obsidian
fill ~119~49~17 ~120~49~23 minecraft:obsidian
setblock ~119~89~17 minecraft:carved_pumpkin 1
fill ~120~39~17 ~122~39~17 minecraft:obsidian
fill ~120~40~17 ~121~40~17 minecraft:obsidian
setblock ~120~88~17 minecraft:red_mushroom_block 0
fill ~121~37~17 ~122~38~17 minecraft:obsidian
fill ~121~48~17 ~121~48~23 minecraft:obsidian
fill ~121~88~17 ~124~88~17 minecraft:carved_pumpkin 1
fill ~122~34~17 ~124~34~17 minecraft:obsidian
fill ~122~35~17 ~123~36~17 minecraft:obsidian
fill ~122~45~17 ~123~45~23 minecraft:obsidian
fill ~122~46~17 ~122~46~23 minecraft:obsidian
fill ~123~30~17 ~125~30~17 minecraft:obsidian
fill ~123~32~17 ~125~32~17 minecraft:obsidian
fill ~123~33~17 ~124~33~17 minecraft:obsidian
fill ~124~28~17 ~126~28~17 minecraft:obsidian
fill ~124~29~17 ~125~29~17 minecraft:obsidian
setblock ~124~31~17 minecraft:obsidian
fill ~124~87~17 ~125~87~19 minecraft:carved_pumpkin 1
fill ~125~26~17 ~126~27~17 minecraft:obsidian
fill ~125~86~17 ~126~86~23 minecraft:obsidian
fill ~126~23~17 ~127~23~23 minecraft:obsidian
fill ~126~24~17 ~127~24~17 minecraft:obsidian
setblock ~126~25~17 minecraft:obsidian
fill ~127~21~17 ~127~21~23 minecraft:obsidian
fill ~127~22~17 ~128~22~17 minecraft:obsidian
fill ~128~20~17 ~128~20~23 minecraft:obsidian
fill ~129~16~17 ~129~16~19 minecraft:obsidian
fill ~181~73~17 ~181~73~23 minecraft:obsidian
fill ~184~18~17 ~185~18~20 minecraft:obsidian
fill ~185~19~17 ~186~19~19 minecraft:obsidian
fill ~185~20~17 ~185~21~19 minecraft:obsidian
fill ~189~29~17 ~190~29~17 minecraft:obsidian
fill ~189~30~17 ~189~30~19 minecraft:obsidian
setblock ~189~31~17 minecraft:obsidian
setblock ~190~32~17 minecraft:obsidian
fill ~192~30~17 ~192~31~17 minecraft:obsidian
fill ~192~33~17 ~192~33~19 minecraft:obsidian
setblock ~14~190~18 minecraft:obsidian
fill ~16~184~18 ~18~184~19 minecraft:obsidian
fill ~17~183~18 ~17~183~19 minecraft:obsidian
fill ~18~177~18 ~19~177~18 minecraft:obsidian
fill ~18~179~18 ~19~179~18 minecraft:obsidian
fill ~19~175~18 ~20~175~18 minecraft:obsidian
fill ~19~180~18 ~20~180~21 minecraft:obsidian
fill ~20~176~18 ~21~176~18 minecraft:obsidian
fill ~20~181~18 ~22~181~18 minecraft:obsidian
fill ~20~183~18 ~20~183~19 minecraft:obsidian
setblock ~20~186~18 minecraft:obsidian
setblock ~21~185~18 minecraft:obsidian
fill ~22~168~18 ~22~168~20 minecraft:obsidian
setblock ~22~177~18 minecraft:obsidian
fill ~22~184~18 ~22~184~19 minecraft:obsidian
setblock ~22~187~18 minecraft:obsidian
fill ~23~167~18 ~24~167~20 minecraft:obsidian
fill ~23~178~18 ~23~179~18 minecraft:obsidian
fill ~23~181~18 ~24~181~18 minecraft:coal_block
setblock ~23~182~18 minecraft:obsidian
setblock ~23~186~18 minecraft:obsidian
fill ~24~165~18 ~24~165~21 minecraft:obsidian
setblock ~24~166~18 minecraft:obsidian
fill ~24~179~18 ~24~180~18 minecraft:snow
setblock ~24~183~18 minecraft:wool 0
setblock ~24~185~18 minecraft:obsidian
fill ~25~162~18 ~26~162~18 minecraft:redstone_block
fill ~25~164~18 ~25~164~21 minecraft:obsidian
setblock ~25~180~18 minecraft:snow
fill ~25~182~18 ~26~182~18 minecraft:snow
setblock ~25~183~18 minecraft:snow
setblock ~26~161~18 minecraft:carved_pumpkin 1
fill ~26~163~18 ~28~163~18 minecraft:carved_pumpkin 1
fill ~26~164~18 ~27~164~18 minecraft:carved_pumpkin 1
setblock ~26~165~18 minecraft:carved_pumpkin 1
setblock ~26~181~18 minecraft:snow
fill ~26~184~18 ~26~185~18 minecraft:obsidian
setblock ~27~162~18 minecraft:carved_pumpkin 1
setblock ~27~183~18 minecraft:obsidian
fill ~27~184~18 ~27~185~18 minecraft:brown_mushroom_block 0
setblock ~27~186~18 minecraft:obsidian
setblock ~28~183~18 minecraft:double_stone_block_slab 0
setblock ~28~184~18 minecraft:iron_block
setblock ~28~185~18 minecraft:obsidian
setblock ~29~164~18 minecraft:carved_pumpkin 1
fill ~29~168~18 ~31~168~18 minecraft:yellow_glazed_terracotta 4
setblock ~29~184~18 minecraft:obsidian
fill ~30~165~18 ~30~167~18 minecraft:yellow_glazed_terracotta 4
setblock ~30~169~18 minecraft:yellow_glazed_terracotta 4
fill ~31~166~18 ~31~167~18 minecraft:yellow_glazed_terracotta 4
fill ~31~169~18 ~34~170~18 minecraft:carved_pumpkin 1
setblock ~32~167~18 minecraft:yellow_glazed_terracotta 4
fill ~32~168~18 ~33~168~18 minecraft:carved_pumpkin 1
fill ~32~171~18 ~36~171~18 minecraft:carved_pumpkin 1
fill ~32~184~18 ~32~184~19 minecraft:obsidian
fill ~33~172~18 ~37~172~18 minecraft:carved_pumpkin 1
fill ~34~173~18 ~37~173~18 minecraft:carved_pumpkin 1
setblock ~35~170~18 minecraft:carved_pumpkin 1
fill ~35~174~18 ~36~174~18 minecraft:carved_pumpkin 1
fill ~36~175~18 ~38~175~18 minecraft:red_mushroom_block 0
fill ~36~180~18 ~36~180~20 minecraft:obsidian
fill ~37~174~18 ~39~174~18 minecraft:red_mushroom_block 0
fill ~37~176~18 ~38~176~18 minecraft:red_mushroom_block 0
setblock ~38~173~18 minecraft:red_mushroom_block 0
setblock ~38~177~18 minecraft:red_mushroom_block 0
fill ~38~179~18 ~38~179~21 minecraft:obsidian
fill ~39~175~18 ~39~176~18 minecraft:redstone_block
fill ~39~177~18 ~39~177~21 minecraft:obsidian
fill ~39~178~18 ~39~178~19 minecraft:obsidian
fill ~84~84~18 ~84~84~19 minecraft:obsidian
fill ~97~58~18 ~97~58~23 minecraft:obsidian
fill ~101~55~18 ~102~55~23 minecraft:obsidian
fill ~105~53~18 ~105~53~23 minecraft:obsidian
fill ~107~52~18 ~107~52~23 minecraft:obsidian
fill ~108~51~18 ~108~51~23 minecraft:obsidian
fill ~109~50~18 ~111~50~20 minecraft:obsidian
fill ~110~84~18 ~111~84~18 minecraft:yellow_glazed_terracotta 4
fill ~110~86~18 ~112~86~18 minecraft:yellow_glazed_terracotta 4
fill ~110~87~18 ~111~87~18 minecraft:yellow_glazed_terracotta 4
fill ~111~49~18 ~112~49~23 minecraft:obsidian
setblock ~111~81~18 minecraft:sand 0
fill ~111~82~18 ~111~83~18 minecraft:yellow_glazed_terracotta 4
fill ~111~85~18 ~112~85~18 minecraft:yellow_glazed_terracotta 4
setblock ~111~88~18 minecraft:yellow_glazed_terracotta 4
fill ~111~89~18 ~118~89~18 minecraft:carved_pumpkin 1
fill ~112~48~18 ~113~48~23 minecraft:obsidian
setblock ~112~80~18 minecraft:red_nether_brick
fill ~112~87~18 ~112~88~18 minecraft:carved_pumpkin 1
fill ~112~90~18 ~120~90~18 minecraft:carved_pumpkin 1
fill ~113~47~18 ~114~47~19 minecraft:obsidian
setblock ~113~88~18 minecraft:carved_pumpkin 1
fill ~113~91~18 ~115~91~18 minecraft:carved_pumpkin 1
fill ~114~46~18 ~115~46~19 minecraft:obsidian
fill ~115~45~18 ~116~45~21 minecraft:obsidian
fill ~116~44~18 ~117~44~23 minecraft:obsidian
fill ~117~43~18 ~118~43~23 minecraft:obsidian
setblock ~117~91~18 minecraft:carved_pumpkin 1
fill ~118~41~18 ~118~42~23 minecraft:obsidian
fill ~119~40~18 ~119~40~23 minecraft:obsidian
fill ~120~38~18 ~120~38~20 minecraft:obsidian
setblock ~120~57~18 minecraft:obsidian
fill ~120~89~18 ~123~89~18 minecraft:carved_pumpkin 1
fill ~121~35~18 ~122~35~23 minecraft:obsidian
fill ~121~36~18 ~121~37~23 minecraft:obsidian
fill ~122~33~18 ~122~33~23 minecraft:obsidian
fill ~122~90~18 ~122~90~20 minecraft:carved_pumpkin 1
fill ~123~30~18 ~124~30~23 minecraft:obsidian
fill ~123~32~18 ~123~32~23 minecraft:obsidian
fill ~123~88~18 ~124~88~21 minecraft:carved_pumpkin 1
fill ~124~28~18 ~124~28~23 minecraft:obsidian
fill ~125~24~18 ~126~24~18 minecraft:obsidian
fill ~125~26~18 ~125~26~23 minecraft:obsidian
fill ~150~1~18 ~150~1~19 minecraft:obsidian
setblock ~188~30~18 minecraft:obsidian
fill ~188~32~18 ~189~32~18 minecraft:obsidian
fill ~189~27~18 ~189~28~18 minecraft:obsidian
fill ~189~33~18 ~191~33~18 minecraft:obsidian
fill ~192~32~18 ~193~32~18 minecraft:obsidian
fill ~194~30~18 ~194~30~23 minecraft:obsidian
setblock ~17~185~19 minecraft:obsidian
fill ~19~178~19 ~20~178~21 minecraft:obsidian
fill ~20~174~19 ~21~174~19 minecraft:obsidian
fill ~20~177~19 ~21~177~19 minecraft:obsidian
fill ~20~181~19 ~20~181~21 minecraft:obsidian
fill ~21~172~19 ~21~173~19 minecraft:obsidian
fill ~21~175~19 ~22~175~19 minecraft:obsidian
fill ~21~180~19 ~23~180~19 minecraft:obsidian
setblock ~21~182~19 minecraft:obsidian
fill ~22~176~19 ~23~176~19 minecraft:obsidian
fill ~22~178~19 ~22~178~20 minecraft:obsidian
setblock ~22~181~19 minecraft:obsidian
fill ~23~177~19 ~25~177~19 minecraft:obsidian
setblock ~23~183~19 minecraft:obsidian
fill ~24~178~19 ~27~178~19 minecraft:obsidian
setblock ~24~182~19 minecraft:coal_block
setblock ~24~185~19 minecraft:brown_mushroom_block 0
fill ~25~162~19 ~26~162~22 minecraft:obsidian
fill ~25~163~19 ~25~163~21 minecraft:obsidian
fill ~25~175~19 ~26~176~19 minecraft:obsidian
fill ~25~179~19 ~26~179~19 minecraft:brown_mushroom_block 0
fill ~25~181~19 ~25~181~20 minecraft:obsidian
setblock ~25~184~19 minecraft:obsidian
fill ~26~161~19 ~26~161~22 minecraft:obsidian
setblock ~26~183~19 minecraft:brown_mushroom_block 0
fill ~27~176~19 ~27~177~19 minecraft:obsidian
fill ~27~180~19 ~27~181~19 minecraft:snow
fill ~27~182~19 ~30~182~19 minecraft:obsidian
fill ~28~161~19 ~28~161~21 minecraft:obsidian
fill ~28~162~19 ~29~162~19 minecraft:red_mushroom_block 0
setblock ~28~177~19 minecraft:obsidian
fill ~28~179~19 ~29~179~19 minecraft:obsidian
setblock ~28~180~19 minecraft:double_stone_block_slab 0
setblock ~29~161~19 minecraft:nether_wart_block
fill ~29~163~19 ~30~163~19 minecraft:carved_pumpkin 1
setblock ~29~178~19 minecraft:obsidian
setblock ~29~181~19 minecraft:purpur_block 0
fill ~29~183~19 ~32~183~19 minecraft:obsidian
fill ~30~162~19 ~31~162~19 minecraft:carved_pumpkin 1
fill ~30~164~19 ~35~164~19 minecraft:yellow_glazed_terracotta 4
fill ~30~180~19 ~31~180~19 minecraft:obsidian
fill ~30~181~19 ~31~181~19 minecraft:snow
fill ~31~161~19 ~32~161~19 minecraft:carved_pumpkin 1
fill ~31~163~19 ~34~163~19 minecraft:yellow_glazed_terracotta 4
fill ~31~165~19 ~34~165~19 minecraft:yellow_glazed_terracotta 4
setblock ~31~182~19 minecraft:snow
fill ~32~162~19 ~33~162~19 minecraft:yellow_glazed_terracotta 4
fill ~32~166~19 ~33~166~19 minecraft:yellow_glazed_terracotta 4
setblock ~32~181~19 minecraft:brown_mushroom_block 0
fill ~32~182~19 ~33~182~19 minecraft:obsidian
fill ~33~167~19 ~38~167~19 minecraft:carved_pumpkin 1
fill ~34~166~19 ~37~166~19 minecraft:carved_pumpkin 1
fill ~34~168~19 ~39~168~19 minecraft:carved_pumpkin 1
fill ~35~165~19 ~36~165~19 minecraft:carved_pumpkin 1
fill ~35~169~19 ~40~169~19 minecraft:carved_pumpkin 1
fill ~36~170~19 ~39~170~19 minecraft:carved_pumpkin 1
fill ~37~171~19 ~38~171~19 minecraft:carved_pumpkin 1
setblock ~38~172~19 minecraft:carved_pumpkin 1
setblock ~39~171~19 minecraft:red_mushroom_block 0
fill ~39~172~19 ~40~172~21 minecraft:obsidian
fill ~39~173~19 ~39~174~22 minecraft:obsidian
fill ~39~175~19 ~39~176~21 minecraft:obsidian
setblock ~40~170~19 minecraft:red_mushroom_block 0
fill ~80~80~19 ~81~80~19 minecraft:obsidian
fill ~80~81~19 ~80~82~19 minecraft:obsidian
fill ~84~81~19 ~84~81~23 minecraft:obsidian
fill ~84~82~19 ~84~83~19 minecraft:obsidian
fill ~94~105~19 ~97~106~19 minecraft:carved_pumpkin 1
fill ~95~104~19 ~98~104~19 minecraft:carved_pumpkin 1
fill ~95~107~19 ~96~107~19 minecraft:carved_pumpkin 1
fill ~96~103~19 ~98~103~19 minecraft:carved_pumpkin 1
fill ~96~108~19 ~97~108~19 minecraft:red_mushroom_block 0
fill ~97~102~19 ~99~102~19 minecraft:carved_pumpkin 1
fill ~97~107~19 ~98~107~19 minecraft:red_mushroom_block 0
fill ~98~101~19 ~100~101~19 minecraft:carved_pumpkin 1
fill ~98~105~19 ~100~105~19 minecraft:red_mushroom_block 0
fill ~98~106~19 ~99~106~19 minecraft:red_mushroom_block 0
fill ~99~100~19 ~101~100~19 minecraft:carved_pumpkin 1
fill ~99~103~19 ~102~103~19 minecraft:red_mushroom_block 0
fill ~99~104~19 ~101~104~19 minecraft:red_mushroom_block 0
fill ~100~99~19 ~101~99~19 minecraft:carved_pumpkin 1
fill ~100~102~19 ~103~102~19 minecraft:red_mushroom_block 0
fill ~101~98~19 ~104~98~19 minecraft:carved_pumpkin 1
fill ~101~101~19 ~104~101~19 minecraft:red_mushroom_block 0
fill ~102~97~19 ~106~97~19 minecraft:carved_pumpkin 1
fill ~102~99~19 ~106~99~19 minecraft:red_mushroom_block 0
fill ~102~100~19 ~105~100~19 minecraft:red_mushroom_block 0
fill ~103~96~19 ~107~96~19 minecraft:carved_pumpkin 1
fill ~104~95~19 ~108~95~19 minecraft:carved_pumpkin 1
fill ~105~92~19 ~107~92~19 minecraft:yellow_glazed_terracotta 4
fill ~105~93~19 ~106~93~19 minecraft:yellow_glazed_terracotta 4
setblock ~105~94~19 minecraft:yellow_glazed_terracotta 4
fill ~105~98~19 ~107~98~19 minecraft:red_mushroom_block 0
fill ~106~91~19 ~108~91~19 minecraft:yellow_glazed_terracotta 4
fill ~106~94~19 ~112~94~19 minecraft:carved_pumpkin 1
fill ~107~90~19 ~109~90~19 minecraft:yellow_glazed_terracotta 4
fill ~107~93~19 ~113~93~19 minecraft:carved_pumpkin 1
fill ~107~97~19 ~108~97~19 minecraft:red_mushroom_block 0
fill ~108~86~19 ~109~86~19 minecraft:yellow_glazed_terracotta 4
fill ~108~88~19 ~110~89~19 minecraft:yellow_glazed_terracotta 4
fill ~108~92~19 ~118~92~19 minecraft:carved_pumpkin 1
fill ~108~96~19 ~109~96~19 minecraft:red_mushroom_block 0
fill ~109~84~19 ~109~84~20 minecraft:yellow_glazed_terracotta 4
fill ~109~85~19 ~110~85~19 minecraft:yellow_glazed_terracotta 4
setblock ~109~87~19 minecraft:yellow_glazed_terracotta 4
fill ~109~91~19 ~112~91~19 minecraft:carved_pumpkin 1
setblock ~109~95~19 minecraft:red_mushroom_block 0
fill ~110~82~19 ~110~82~20 minecraft:yellow_glazed_terracotta 4
setblock ~110~83~19 minecraft:yellow_glazed_terracotta 4
fill ~110~90~19 ~111~90~19 minecraft:carved_pumpkin 1
setblock ~110~95~19 minecraft:carved_pumpkin 1
setblock ~111~81~19 minecraft:yellow_glazed_terracotta 4
fill ~112~80~19 ~112~80~21 minecraft:obsidian
setblock ~115~93~19 minecraft:carved_pumpkin 1
setblock ~116~91~19 minecraft:carved_pumpkin 1
fill ~118~91~19 ~119~91~19 minecraft:carved_pumpkin 1
fill ~121~58~19 ~121~58~21 minecraft:obsidian
fill ~121~90~19 ~121~91~19 minecraft:carved_pumpkin 1
fill ~122~89~19 ~123~89~19 minecraft:carved_pumpkin 1
fill ~126~24~19 ~126~25~23 minecraft:obsidian
fill ~140~5~19 ~140~5~21 minecraft:obsidian
fill ~171~8~19 ~171~8~20 minecraft:obsidian
setblock ~189~28~19 minecraft:obsidian
setblock ~189~31~19 minecraft:obsidian
fill ~190~26~19 ~190~26~23 minecraft:obsidian
setblock ~190~32~19 minecraft:obsidian
setblock ~192~31~19 minecraft:obsidian
fill ~193~30~19 ~193~30~23 minecraft:obsidian
fill ~18~179~20 ~19~179~21 minecraft:obsidian
fill ~20~177~20 ~20~177~21 minecraft:obsidian
fill ~21~178~20 ~21~180~21 minecraft:obsidian
fill ~22~171~20 ~22~174~20 minecraft:obsidian
fill ~22~179~20 ~22~179~21 minecraft:obsidian
fill ~23~169~20 ~24~170~20 minecraft:obsidian
fill ~23~175~20 ~24~175~20 minecraft:obsidian
fill ~23~177~20 ~24~177~21 minecraft:obsidian
setblock ~23~178~20 minecraft:obsidian
setblock ~23~180~20 minecraft:obsidian
fill ~24~176~20 ~24~176~21 minecraft:obsidian
setblock ~24~179~20 minecraft:obsidian
fill ~25~170~20 ~27~171~20 minecraft:obsidian
fill ~25~174~20 ~28~174~20 minecraft:obsidian
setblock ~25~178~20 minecraft:obsidian
setblock ~26~173~20 minecraft:obsidian
fill ~26~177~20 ~26~177~21 minecraft:obsidian
setblock ~26~180~20 minecraft:obsidian
setblock ~27~172~20 minecraft:obsidian
fill ~27~175~20 ~29~175~20 minecraft:obsidian
setblock ~27~179~20 minecraft:obsidian
setblock ~27~182~20 minecraft:obsidian
fill ~28~176~20 ~29~176~20 minecraft:obsidian
fill ~28~178~20 ~28~178~21 minecraft:obsidian
setblock ~28~181~20 minecraft:obsidian
fill ~29~161~20 ~29~161~21 minecraft:obsidian
setblock ~29~180~20 minecraft:obsidian
fill ~30~177~20 ~31~177~20 minecraft:obsidian
fill ~30~178~20 ~30~179~20 minecraft:obsidian
fill ~31~161~20 ~31~161~22 minecraft:obsidian
fill ~31~176~20 ~32~176~20 minecraft:obsidian
fill ~31~179~20 ~36~179~20 minecraft:obsidian
setblock ~32~161~20 minecraft:red_nether_brick
setblock ~32~175~20 minecraft:obsidian
fill ~32~178~20 ~35~178~20 minecraft:obsidian
fill ~32~180~20 ~35~180~20 minecraft:obsidian
setblock ~33~160~20 minecraft:carved_pumpkin 1
fill ~33~161~20 ~38~161~20 minecraft:yellow_glazed_terracotta 4
fill ~33~177~20 ~34~177~20 minecraft:obsidian
fill ~33~181~20 ~34~181~20 minecraft:obsidian
fill ~34~160~20 ~38~160~20 minecraft:yellow_glazed_terracotta 4
fill ~34~162~20 ~37~162~20 minecraft:yellow_glazed_terracotta 4
fill ~35~159~20 ~39~159~20 minecraft:yellow_glazed_terracotta 4
fill ~35~163~20 ~36~163~20 minecraft:yellow_glazed_terracotta 4
fill ~36~164~20 ~44~164~20 minecraft:carved_pumpkin 1
fill ~37~163~20 ~44~163~20 minecraft:carved_pumpkin 1
fill ~37~165~20 ~43~165~20 minecraft:carved_pumpkin 1
fill ~38~158~20 ~40~158~20 minecraft:yellow_glazed_terracotta 4
fill ~38~162~20 ~44~162~20 minecraft:carved_pumpkin 1
fill ~38~166~20 ~43~166~20 minecraft:carved_pumpkin 1
setblock ~39~160~20 minecraft:planks 0
fill ~39~161~20 ~45~161~20 minecraft:carved_pumpkin 1
fill ~39~167~20 ~42~167~20 minecraft:carved_pumpkin 1
fill ~40~157~20 ~41~157~20 minecraft:yellow_glazed_terracotta 4
fill ~40~159~20 ~47~159~20 minecraft:carved_pumpkin 1
fill ~40~160~20 ~46~160~20 minecraft:carved_pumpkin 1
fill ~40~168~20 ~41~168~20 minecraft:carved_pumpkin 1
fill ~40~170~20 ~40~170~23 minecraft:obsidian
fill ~41~156~20 ~42~156~20 minecraft:yellow_glazed_terracotta 4
fill ~41~158~20 ~43~158~20 minecraft:carved_pumpkin 1
fill ~41~169~20 ~41~169~23 minecraft:obsidian
fill ~42~155~20 ~43~155~20 minecraft:yellow_glazed_terracotta 4
fill ~42~157~20 ~45~157~20 minecraft:carved_pumpkin 1
setblock ~42~168~20 minecraft:red_nether_brick
fill ~43~154~20 ~44~154~20 minecraft:yellow_glazed_terracotta 4
fill ~43~156~20 ~46~156~20 minecraft:carved_pumpkin 1
fill ~44~153~20 ~45~153~20 minecraft:yellow_glazed_terracotta 4
fill ~44~155~20 ~48~155~20 minecraft:carved_pumpkin 1
setblock ~44~158~20 minecraft:red_mushroom_block 0
fill ~45~152~20 ~46~152~20 minecraft:yellow_glazed_terracotta 4
fill ~45~154~20 ~52~154~20 minecraft:carved_pumpkin 1
fill ~45~158~20 ~48~158~20 minecraft:carved_pumpkin 1
fill ~46~151~20 ~47~151~20 minecraft:yellow_glazed_terracotta 4
fill ~46~153~20 ~53~153~20 minecraft:carved_pumpkin 1
fill ~46~157~20 ~48~157~20 minecraft:red_mushroom_block 0
fill ~47~150~20 ~48~150~20 minecraft:yellow_glazed_terracotta 4
fill ~47~152~20 ~53~152~20 minecraft:carved_pumpkin 1
fill ~47~156~20 ~49~156~20 minecraft:red_mushroom_block 0
fill ~48~149~20 ~49~149~20 minecraft:yellow_glazed_terracotta 4
setblock ~48~151~20 minecraft:planks 0
fill ~49~148~20 ~50~148~20 minecraft:yellow_glazed_terracotta 4
setblock ~49~150~20 minecraft:planks 0
fill ~49~151~20 ~54~151~20 minecraft:carved_pumpkin 1
fill ~49~155~20 ~50~155~20 minecraft:red_mushroom_block 0
setblock ~49~157~20 minecraft:carved_pumpkin 1
fill ~50~147~20 ~51~147~20 minecraft:yellow_glazed_terracotta 4
setblock ~50~149~20 minecraft:planks 0
fill ~50~150~20 ~55~150~20 minecraft:carved_pumpkin 1
setblock ~50~156~20 minecraft:carved_pumpkin 1
fill ~51~146~20 ~52~146~20 minecraft:yellow_glazed_terracotta 4
setblock ~51~148~20 minecraft:planks 0
setblock ~51~149~20 minecraft:yellow_glazed_terracotta 4
setblock ~51~155~20 minecraft:carved_pumpkin 1
fill ~52~145~20 ~53~145~20 minecraft:yellow_glazed_terracotta 4
fill ~52~147~20 ~58~147~20 minecraft:carved_pumpkin 1
fill ~52~148~20 ~57~148~20 minecraft:carved_pumpkin 1
setblock ~52~149~20 minecraft:planks 0
fill ~53~144~20 ~54~144~20 minecraft:yellow_glazed_terracotta 4
fill ~53~146~20 ~57~146~20 minecraft:carved_pumpkin 1
fill ~53~149~20 ~56~149~20 minecraft:carved_pumpkin 1
fill ~54~143~20 ~55~143~20 minecraft:yellow_glazed_terracotta 4
fill ~54~145~20 ~56~145~20 minecraft:carved_pumpkin 1
setblock ~54~152~20 minecraft:red_mushroom_block 0
fill ~55~142~20 ~56~142~20 minecraft:yellow_glazed_terracotta 4
fill ~55~144~20 ~61~144~20 minecraft:carved_pumpkin 1
setblock ~55~151~20 minecraft:red_mushroom_block 0
fill ~56~141~20 ~57~141~20 minecraft:yellow_glazed_terracotta 4
fill ~56~143~20 ~62~143~20 minecraft:carved_pumpkin 1
setblock ~56~150~20 minecraft:red_mushroom_block 0
fill ~57~140~20 ~58~140~20 minecraft:yellow_glazed_terracotta 4
fill ~57~142~20 ~63~142~20 minecraft:carved_pumpkin 1
setblock ~57~145~20 minecraft:red_mushroom_block 0
setblock ~57~149~20 minecraft:red_mushroom_block 0
fill ~58~138~20 ~64~139~20 minecraft:carved_pumpkin 1
fill ~58~141~20 ~64~141~20 minecraft:carved_pumpkin 1
setblock ~58~145~20 minecraft:carved_pumpkin 1
fill ~58~146~20 ~60~146~20 minecraft:red_mushroom_block 0
setblock ~58~148~20 minecraft:red_mushroom_block 0
fill ~59~137~20 ~65~137~20 minecraft:carved_pumpkin 1
fill ~59~140~20 ~65~140~20 minecraft:carved_pumpkin 1
fill ~59~145~20 ~60~145~20 minecraft:red_mushroom_block 0
setblock ~59~147~20 minecraft:red_mushroom_block 0
fill ~60~136~20 ~67~136~20 minecraft:carved_pumpkin 1
fill ~61~135~20 ~73~135~20 minecraft:carved_pumpkin 1
setblock ~61~145~20 minecraft:carved_pumpkin 1
fill ~62~134~20 ~74~134~20 minecraft:carved_pumpkin 1
fill ~62~144~20 ~63~144~20 minecraft:red_mushroom_block 0
fill ~63~133~20 ~75~133~20 minecraft:carved_pumpkin 1
fill ~63~143~20 ~65~143~20 minecraft:red_mushroom_block 0
fill ~64~132~20 ~76~132~20 minecraft:carved_pumpkin 1
setblock ~64~142~20 minecraft:red_mushroom_block 0
setblock ~64~144~20 minecraft:carved_pumpkin 1
fill ~65~131~20 ~77~131~20 minecraft:carved_pumpkin 1
fill ~65~138~20 ~68~138~20 minecraft:red_mushroom_block 0
setblock ~65~139~20 minecraft:carved_pumpkin 1
fill ~65~141~20 ~66~141~20 minecraft:red_mushroom_block 0
setblock ~65~142~20 minecraft:carved_pumpkin 1
setblock ~66~130~20 minecraft:carved_pumpkin 1
setblock ~66~137~20 minecraft:red_mushroom_block 0
fill ~66~139~20 ~67~140~20 minecraft:red_mushroom_block 0
setblock ~66~142~20 minecraft:red_mushroom_block 0
fill ~67~129~20 ~68~129~20 minecraft:carved_pumpkin 1
setblock ~67~130~20 minecraft:yellow_glazed_terracotta 4
setblock ~67~137~20 minecraft:carved_pumpkin 1
setblock ~67~141~20 minecraft:carved_pumpkin 1
setblock ~68~128~20 minecraft:carved_pumpkin 1
fill ~68~130~20 ~78~130~20 minecraft:carved_pumpkin 1
fill ~68~136~20 ~68~137~20 minecraft:red_mushroom_block 0
fill ~68~139~20 ~69~139~20 minecraft:carved_pumpkin 1
setblock ~68~140~20 minecraft:red_mushroom_block 0
setblock ~69~127~20 minecraft:carved_pumpkin 1
fill ~69~128~20 ~70~128~20 minecraft:planks 0
setblock ~69~129~20 minecraft:yellow_glazed_terracotta 4
fill ~69~136~20 ~72~136~20 minecraft:carved_pumpkin 1
fill ~69~137~20 ~71~137~20 minecraft:carved_pumpkin 1
fill ~69~138~20 ~70~138~20 minecraft:carved_pumpkin 1
fill ~70~126~20 ~82~126~20 minecraft:carved_pumpkin 1
fill ~70~127~20 ~71~127~20 minecraft:yellow_glazed_terracotta 4
fill ~70~129~20 ~79~129~20 minecraft:carved_pumpkin 1
setblock ~71~125~20 minecraft:carved_pumpkin 1
fill ~71~128~20 ~80~128~20 minecraft:carved_pumpkin 1
setblock ~72~124~20 minecraft:carved_pumpkin 1
setblock ~72~125~20 minecraft:planks 0
fill ~72~127~20 ~81~127~20 minecraft:carved_pumpkin 1
setblock ~73~123~20 minecraft:carved_pumpkin 1
fill ~73~124~20 ~74~124~20 minecraft:yellow_glazed_terracotta 4
setblock ~73~125~20 minecraft:yellow_glazed_terracotta 4
setblock ~74~122~20 minecraft:carved_pumpkin 1
fill ~74~123~20 ~75~123~20 minecraft:yellow_glazed_terracotta 4
fill ~74~125~20 ~83~125~20 minecraft:carved_pumpkin 1
fill ~75~121~20 ~77~121~20 minecraft:yellow_glazed_terracotta 4
fill ~75~122~20 ~76~122~20 minecraft:yellow_glazed_terracotta 4
fill ~75~124~20 ~84~124~20 minecraft:carved_pumpkin 1
setblock ~76~120~20 minecraft:carved_pumpkin 1
fill ~76~123~20 ~80~123~20 minecraft:carved_pumpkin 1
setblock ~77~119~20 minecraft:carved_pumpkin 1
fill ~77~120~20 ~78~120~20 minecraft:yellow_glazed_terracotta 4
fill ~77~122~20 ~81~122~20 minecraft:carved_pumpkin 1
setblock ~78~118~20 minecraft:carved_pumpkin 1
fill ~78~119~20 ~79~119~20 minecraft:yellow_glazed_terracotta 4
fill ~78~121~20 ~82~121~20 minecraft:carved_pumpkin 1
setblock ~79~117~20 minecraft:planks 0
fill ~79~118~20 ~80~118~20 minecraft:yellow_glazed_terracotta 4
fill ~79~120~20 ~82~120~20 minecraft:carved_pumpkin 1
fill ~80~116~20 ~82~116~20 minecraft:yellow_glazed_terracotta 4
fill ~80~117~20 ~81~117~20 minecraft:yellow_glazed_terracotta 4
fill ~80~119~20 ~84~119~20 minecraft:carved_pumpkin 1
fill ~81~80~20 ~81~80~23 minecraft:obsidian
fill ~81~81~20 ~81~83~20 minecraft:obsidian
fill ~81~115~20 ~83~115~20 minecraft:yellow_glazed_terracotta 4
fill ~81~118~20 ~85~118~20 minecraft:carved_pumpkin 1
fill ~81~123~20 ~82~123~20 minecraft:red_mushroom_block 0
fill ~82~82~20 ~83~83~20 minecraft:obsidian
fill ~82~114~20 ~84~114~20 minecraft:yellow_glazed_terracotta 4
fill ~82~117~20 ~86~117~20 minecraft:carved_pumpkin 1
setblock ~82~122~20 minecraft:red_mushroom_block 0
setblock ~83~84~20 minecraft:obsidian
setblock ~83~113~20 minecraft:carved_pumpkin 1
fill ~83~116~20 ~86~116~20 minecraft:carved_pumpkin 1
fill ~83~120~20 ~86~120~20 minecraft:red_mushroom_block 0
fill ~83~121~20 ~84~121~20 minecraft:red_mushroom_block 0
fill ~83~122~20 ~86~122~20 minecraft:carved_pumpkin 1
fill ~83~123~20 ~85~123~20 minecraft:carved_pumpkin 1
setblock ~84~112~20 minecraft:carved_pumpkin 1
fill ~84~113~20 ~85~113~20 minecraft:yellow_glazed_terracotta 4
fill ~84~115~20 ~88~115~20 minecraft:carved_pumpkin 1
fill ~85~111~20 ~87~111~20 minecraft:yellow_glazed_terracotta 4
fill ~85~112~20 ~86~112~20 minecraft:yellow_glazed_terracotta 4
fill ~85~114~20 ~88~114~20 minecraft:carved_pumpkin 1
fill ~85~119~20 ~87~119~20 minecraft:red_mushroom_block 0
fill ~85~121~20 ~87~121~20 minecraft:carved_pumpkin 1
fill ~86~110~20 ~87~110~20 minecraft:yellow_glazed_terracotta 4
fill ~86~113~20 ~89~113~20 minecraft:carved_pumpkin 1
fill ~86~118~20 ~88~118~20 minecraft:red_mushroom_block 0
fill ~87~109~20 ~89~109~20 minecraft:yellow_glazed_terracotta 4
fill ~87~112~20 ~90~112~20 minecraft:carved_pumpkin 1
fill ~87~116~20 ~90~117~20 minecraft:red_mushroom_block 0
fill ~87~120~20 ~88~120~20 minecraft:carved_pumpkin 1
fill ~88~108~20 ~89~108~20 minecraft:yellow_glazed_terracotta 4
fill ~88~110~20 ~90~111~20 minecraft:carved_pumpkin 1
fill ~88~119~20 ~89~119~20 minecraft:carved_pumpkin 1
setblock ~89~107~20 minecraft:yellow_glazed_terracotta 4
fill ~89~114~20 ~94~114~20 minecraft:red_mushroom_block 0
fill ~89~115~20 ~93~115~20 minecraft:red_mushroom_block 0
setblock ~89~118~20 minecraft:carved_pumpkin 1
setblock ~90~106~20 minecraft:yellow_glazed_terracotta 4
fill ~90~107~20 ~90~109~20 minecraft:carved_pumpkin 1
fill ~90~113~20 ~95~113~20 minecraft:red_mushroom_block 0
setblock ~90~118~20 minecraft:red_mushroom_block 0
setblock ~91~105~20 minecraft:yellow_glazed_terracotta 4
fill ~91~106~20 ~93~106~20 minecraft:carved_pumpkin 1
setblock ~91~107~20 minecraft:yellow_glazed_terracotta 4
fill ~91~108~20 ~94~108~20 minecraft:carved_pumpkin 1
fill ~91~109~20 ~92~109~20 minecraft:carved_pumpkin 1
fill ~91~110~20 ~96~110~20 minecraft:red_mushroom_block 0
setblock ~91~111~20 minecraft:carved_pumpkin 1
fill ~91~112~20 ~95~112~20 minecraft:red_mushroom_block 0
fill ~91~116~20 ~92~116~20 minecraft:carved_pumpkin 1
setblock ~91~117~20 minecraft:red_mushroom_block 0
setblock ~92~104~20 minecraft:yellow_glazed_terracotta 4
fill ~92~105~20 ~93~105~20 minecraft:carved_pumpkin 1
fill ~92~107~20 ~94~107~20 minecraft:carved_pumpkin 1
fill ~92~111~20 ~95~111~20 minecraft:red_mushroom_block 0
setblock ~93~103~20 minecraft:yellow_glazed_terracotta 4
fill ~93~104~20 ~94~104~20 minecraft:carved_pumpkin 1
fill ~93~109~20 ~96~109~20 minecraft:red_mushroom_block 0
fill ~94~102~20 ~95~102~20 minecraft:yellow_glazed_terracotta 4
setblock ~94~103~20 minecraft:carved_pumpkin 1
setblock ~95~101~20 minecraft:yellow_glazed_terracotta 4
setblock ~95~103~20 minecraft:yellow_glazed_terracotta 4
setblock ~95~108~20 minecraft:red_mushroom_block 0
setblock ~96~100~20 minecraft:yellow_glazed_terracotta 4
fill ~96~101~20 ~96~102~20 minecraft:planks 0
fill ~96~111~20 ~97~111~20 minecraft:carved_pumpkin 1
setblock ~96~112~20 minecraft:carved_pumpkin 1
setblock ~97~99~20 minecraft:yellow_glazed_terracotta 4
fill ~97~100~20 ~98~100~20 minecraft:carved_pumpkin 1
setblock ~97~101~20 minecraft:carved_pumpkin 1
fill ~97~109~20 ~99~109~20 minecraft:carved_pumpkin 1
fill ~97~110~20 ~98~110~20 minecraft:carved_pumpkin 1
setblock ~98~98~20 minecraft:yellow_glazed_terracotta 4
fill ~98~99~20 ~99~99~20 minecraft:carved_pumpkin 1
fill ~98~108~20 ~100~108~20 minecraft:carved_pumpkin 1
setblock ~99~97~20 minecraft:yellow_glazed_terracotta 4
fill ~99~98~20 ~100~98~20 minecraft:carved_pumpkin 1
setblock ~99~107~20 minecraft:red_mushroom_block 0
setblock ~100~96~20 minecraft:yellow_glazed_terracotta 4
fill ~100~97~20 ~101~97~20 minecraft:carved_pumpkin 1
fill ~100~106~20 ~100~107~20 minecraft:carved_pumpkin 1
fill ~101~95~20 ~102~95~20 minecraft:yellow_glazed_terracotta 4
setblock ~101~96~20 minecraft:carved_pumpkin 1
fill ~101~105~20 ~102~106~20 minecraft:red_mushroom_block 0
setblock ~101~107~20 minecraft:carved_pumpkin 1
fill ~102~94~20 ~104~94~20 minecraft:yellow_glazed_terracotta 4
setblock ~102~96~20 minecraft:yellow_glazed_terracotta 4
setblock ~102~104~20 minecraft:red_mushroom_block 0
fill ~103~93~20 ~104~93~20 minecraft:yellow_glazed_terracotta 4
setblock ~103~95~20 minecraft:carved_pumpkin 1
setblock ~103~103~20 minecraft:red_mushroom_block 0
fill ~103~104~20 ~104~104~20 minecraft:carved_pumpkin 1
setblock ~103~105~20 minecraft:carved_pumpkin 1
setblock ~104~92~20 minecraft:yellow_glazed_terracotta 4
setblock ~104~102~20 minecraft:red_mushroom_block 0
fill ~104~103~20 ~105~103~20 minecraft:carved_pumpkin 1
setblock ~105~91~20 minecraft:yellow_glazed_terracotta 4
fill ~105~101~20 ~107~101~20 minecraft:carved_pumpkin 1
fill ~105~102~20 ~106~102~20 minecraft:carved_pumpkin 1
fill ~106~88~20 ~107~88~20 minecraft:yellow_glazed_terracotta 4
setblock ~106~90~20 minecraft:yellow_glazed_terracotta 4
setblock ~106~100~20 minecraft:red_mushroom_block 0
fill ~107~87~20 ~108~87~20 minecraft:yellow_glazed_terracotta 4
setblock ~107~89~20 minecraft:yellow_glazed_terracotta 4
setblock ~107~99~20 minecraft:red_mushroom_block 0
fill ~107~100~20 ~108~100~20 minecraft:carved_pumpkin 1
setblock ~108~85~20 minecraft:sand 0
setblock ~108~98~20 minecraft:red_mushroom_block 0
fill ~108~99~20 ~109~99~20 minecraft:carved_pumpkin 1
setblock ~109~83~20 minecraft:planks 0
setblock ~109~97~20 minecraft:red_mushroom_block 0
fill ~109~98~20 ~111~98~20 minecraft:carved_pumpkin 1
fill ~110~96~20 ~113~96~20 minecraft:carved_pumpkin 1
fill ~110~97~20 ~111~97~20 minecraft:carved_pumpkin 1
fill ~111~81~20 ~111~81~23 minecraft:carved_pumpkin 1
fill ~111~95~20 ~114~95~20 minecraft:carved_pumpkin 1
fill ~113~47~20 ~113~47~21 minecraft:obsidian
fill ~113~94~20 ~115~94~20 minecraft:carved_pumpkin 1
setblock ~114~93~20 minecraft:carved_pumpkin 1
fill ~115~46~20 ~115~47~20 minecraft:obsidian
setblock ~116~93~20 minecraft:carved_pumpkin 1
setblock ~118~92~20 minecraft:carved_pumpkin 1
fill ~120~91~20 ~120~92~20 minecraft:carved_pumpkin 1
fill ~121~90~20 ~121~91~23 minecraft:red_mushroom_block 0
fill ~122~89~20 ~123~89~20 minecraft:red_mushroom_block 0
fill ~124~87~20 ~125~87~20 minecraft:red_mushroom_block 0
fill ~129~17~20 ~130~17~20 minecraft:obsidian
fill ~143~3~20 ~143~4~20 minecraft:obsidian
fill ~145~3~20 ~149~3~20 minecraft:obsidian
fill ~146~4~20 ~147~4~20 minecraft:obsidian
setblock ~147~2~20 minecraft:obsidian
fill ~149~2~20 ~154~2~20 minecraft:obsidian
fill ~151~1~20 ~152~1~20 minecraft:obsidian
fill ~151~3~20 ~152~3~20 minecraft:obsidian
fill ~154~3~20 ~156~3~20 minecraft:obsidian
fill ~156~2~20 ~160~2~20 minecraft:obsidian
fill ~158~3~20 ~159~3~20 minecraft:obsidian
fill ~159~31~20 ~169~32~20 minecraft:obsidian
fill ~160~30~20 ~168~30~20 minecraft:obsidian
fill ~160~33~20 ~171~33~20 minecraft:obsidian
setblock ~161~3~20 minecraft:obsidian
fill ~161~29~20 ~162~29~20 minecraft:obsidian
fill ~161~34~20 ~174~34~20 minecraft:obsidian
fill ~162~35~20 ~173~35~20 minecraft:obsidian
fill ~163~36~20 ~174~36~20 minecraft:obsidian
fill ~164~29~20 ~169~29~20 minecraft:obsidian
fill ~164~37~20 ~173~37~20 minecraft:obsidian
fill ~165~28~20 ~166~28~20 minecraft:obsidian
fill ~165~38~20 ~172~38~20 minecraft:obsidian
fill ~166~39~20 ~172~39~20 minecraft:obsidian
fill ~167~40~20 ~173~40~20 minecraft:obsidian
fill ~168~41~20 ~172~41~20 minecraft:obsidian
fill ~169~42~20 ~171~42~20 minecraft:obsidian
setblock ~170~32~20 minecraft:obsidian
setblock ~170~43~20 minecraft:obsidian
fill ~181~18~20 ~181~18~23 minecraft:obsidian
fill ~183~17~20 ~184~17~20 minecraft:obsidian
setblock ~183~18~20 minecraft:obsidian
fill ~184~19~20 ~184~21~20 minecraft:obsidian
fill ~185~21~20 ~185~21~23 minecraft:obsidian
fill ~189~29~20 ~193~29~20 minecraft:obsidian
fill ~190~27~20 ~191~27~23 minecraft:obsidian
fill ~190~28~20 ~192~28~20 minecraft:obsidian
fill ~190~30~20 ~192~30~20 minecraft:obsidian
fill ~190~31~20 ~191~31~20 minecraft:obsidian
setblock ~191~32~20 minecraft:obsidian
setblock ~20~179~21 minecraft:obsidian
fill ~22~172~21 ~26~172~21 minecraft:obsidian
fill ~22~173~21 ~22~173~23 minecraft:obsidian
fill ~22~174~21 ~24~174~22 minecraft:obsidian
fill ~23~171~21 ~24~171~21 minecraft:obsidian
fill ~23~175~21 ~23~175~22 minecraft:obsidian
fill ~24~166~21 ~25~166~21 minecraft:obsidian
fill ~24~168~21 ~25~168~21 minecraft:obsidian
fill ~24~173~21 ~25~173~22 minecraft:obsidian
fill ~25~165~21 ~26~165~21 minecraft:obsidian
fill ~25~169~21 ~27~169~21 minecraft:obsidian
fill ~25~175~21 ~25~176~21 minecraft:obsidian
fill ~26~174~21 ~27~174~21 minecraft:obsidian
fill ~27~173~21 ~29~173~21 minecraft:obsidian
setblock ~27~176~21 minecraft:obsidian
fill ~28~170~21 ~29~170~21 minecraft:obsidian
setblock ~28~171~21 minecraft:obsidian
setblock ~28~175~21 minecraft:obsidian
setblock ~29~177~21 minecraft:obsidian
fill ~30~171~21 ~31~171~21 minecraft:obsidian
setblock ~30~172~21 minecraft:obsidian
fill ~30~174~21 ~31~175~21 minecraft:obsidian
setblock ~30~176~21 minecraft:obsidian
setblock ~30~179~21 minecraft:obsidian
fill ~31~173~21 ~32~173~21 minecraft:obsidian
setblock ~31~178~21 minecraft:obsidian
fill ~32~161~21 ~32~161~23 minecraft:obsidian
setblock ~32~172~21 minecraft:obsidian
setblock ~32~177~21 minecraft:obsidian
fill ~33~160~21 ~33~160~24 minecraft:obsidian
fill ~33~174~21 ~34~174~21 minecraft:obsidian
fill ~33~175~21 ~33~176~21 minecraft:obsidian
fill ~34~159~21 ~34~159~26 minecraft:obsidian
setblock ~34~173~21 minecraft:obsidian
fill ~34~176~21 ~38~176~21 minecraft:obsidian
fill ~35~158~21 ~35~158~25 minecraft:obsidian
fill ~35~175~21 ~36~175~21 minecraft:obsidian
fill ~35~177~21 ~38~177~21 minecraft:obsidian
fill ~36~158~21 ~37~158~21 minecraft:yellow_glazed_terracotta 4
fill ~36~178~21 ~38~178~21 minecraft:obsidian
fill ~37~157~21 ~39~157~21 minecraft:yellow_glazed_terracotta 4
setblock ~37~179~21 minecraft:obsidian
fill ~38~156~21 ~40~156~21 minecraft:yellow_glazed_terracotta 4
fill ~39~155~21 ~41~155~21 minecraft:yellow_glazed_terracotta 4
fill ~40~154~21 ~42~154~21 minecraft:yellow_glazed_terracotta 4
setblock ~41~153~21 minecraft:yellow_glazed_terracotta 4
fill ~42~168~21 ~42~168~23 minecraft:obsidian
setblock ~43~153~21 minecraft:yellow_glazed_terracotta 4
fill ~43~167~21 ~43~167~25 minecraft:obsidian
setblock ~44~152~21 minecraft:yellow_glazed_terracotta 4
setblock ~44~165~21 minecraft:carved_pumpkin 1
fill ~44~166~21 ~44~166~25 minecraft:obsidian
setblock ~45~149~21 minecraft:yellow_glazed_terracotta 4
fill ~45~150~21 ~45~150~22 minecraft:carved_pumpkin 1
setblock ~45~151~21 minecraft:yellow_glazed_terracotta 4
fill ~45~162~21 ~47~162~21 minecraft:carved_pumpkin 1
fill ~45~163~21 ~46~163~21 minecraft:carved_pumpkin 1
setblock ~45~164~21 minecraft:carved_pumpkin 1
fill ~46~148~21 ~46~149~21 minecraft:carved_pumpkin 1
setblock ~46~150~21 minecraft:yellow_glazed_terracotta 4
fill ~46~161~21 ~48~161~21 minecraft:carved_pumpkin 1
fill ~47~147~21 ~49~147~21 minecraft:yellow_glazed_terracotta 4
fill ~47~148~21 ~48~148~21 minecraft:yellow_glazed_terracotta 4
setblock ~47~149~21 minecraft:carved_pumpkin 1
fill ~47~160~21 ~48~160~21 minecraft:carved_pumpkin 1
fill ~48~146~21 ~50~146~21 minecraft:carved_pumpkin 1
fill ~48~159~21 ~49~159~21 minecraft:carved_pumpkin 1
fill ~49~145~21 ~51~145~21 minecraft:carved_pumpkin 1
fill ~49~158~21 ~51~158~21 minecraft:carved_pumpkin 1
fill ~50~144~21 ~52~144~21 minecraft:carved_pumpkin 1
fill ~50~157~21 ~52~157~21 minecraft:carved_pumpkin 1
fill ~51~143~21 ~52~143~21 minecraft:carved_pumpkin 1
fill ~51~156~21 ~53~156~21 minecraft:carved_pumpkin 1
fill ~52~142~21 ~53~142~21 minecraft:carved_pumpkin 1
fill ~52~155~21 ~54~155~21 minecraft:carved_pumpkin 1
setblock ~53~141~21 minecraft:carved_pumpkin 1
setblock ~53~143~21 minecraft:yellow_glazed_terracotta 4
fill ~53~154~21 ~55~154~21 minecraft:carved_pumpkin 1
fill ~54~140~21 ~55~140~21 minecraft:carved_pumpkin 1
setblock ~54~141~21 minecraft:planks 0
setblock ~54~142~21 minecraft:yellow_glazed_terracotta 4
fill ~54~153~21 ~56~153~21 minecraft:carved_pumpkin 1
fill ~55~139~21 ~57~139~21 minecraft:carved_pumpkin 1
setblock ~55~141~21 minecraft:carved_pumpkin 1
fill ~55~152~21 ~57~152~21 minecraft:carved_pumpkin 1
fill ~56~138~21 ~57~138~21 minecraft:carved_pumpkin 1
setblock ~56~140~21 minecraft:yellow_glazed_terracotta 4
fill ~56~151~21 ~58~151~21 minecraft:carved_pumpkin 1
fill ~57~137~21 ~58~137~21 minecraft:carved_pumpkin 1
fill ~57~150~21 ~59~150~21 minecraft:carved_pumpkin 1
fill ~58~136~21 ~59~136~21 minecraft:carved_pumpkin 1
fill ~58~149~21 ~60~149~21 minecraft:carved_pumpkin 1
fill ~59~135~21 ~60~135~21 minecraft:carved_pumpkin 1
fill ~59~148~21 ~61~148~21 minecraft:carved_pumpkin 1
fill ~60~134~21 ~61~134~21 minecraft:carved_pumpkin 1
fill ~60~147~21 ~62~147~21 minecraft:carved_pumpkin 1
fill ~61~133~21 ~62~133~21 minecraft:carved_pumpkin 1
fill ~61~146~21 ~63~146~21 minecraft:carved_pumpkin 1
fill ~62~132~21 ~63~132~21 minecraft:carved_pumpkin 1
fill ~62~145~21 ~64~145~21 minecraft:carved_pumpkin 1
fill ~63~131~21 ~64~131~21 minecraft:carved_pumpkin 1
fill ~64~130~21 ~65~130~21 minecraft:carved_pumpkin 1
fill ~65~129~21 ~66~129~21 minecraft:carved_pumpkin 1
setblock ~65~144~21 minecraft:carved_pumpkin 1
fill ~66~128~21 ~67~128~21 minecraft:carved_pumpkin 1
setblock ~66~143~21 minecraft:carved_pumpkin 1
fill ~67~127~21 ~68~127~21 minecraft:carved_pumpkin 1
setblock ~67~142~21 minecraft:carved_pumpkin 1
fill ~68~126~21 ~69~126~21 minecraft:carved_pumpkin 1
setblock ~68~141~21 minecraft:carved_pumpkin 1
fill ~69~125~21 ~70~125~21 minecraft:carved_pumpkin 1
setblock ~69~140~21 minecraft:carved_pumpkin 1
fill ~70~124~21 ~71~124~21 minecraft:carved_pumpkin 1
setblock ~70~139~21 minecraft:carved_pumpkin 1
fill ~71~123~21 ~72~123~21 minecraft:carved_pumpkin 1
setblock ~71~138~21 minecraft:carved_pumpkin 1
fill ~72~122~21 ~73~122~21 minecraft:carved_pumpkin 1
setblock ~72~137~21 minecraft:carved_pumpkin 1
fill ~73~121~21 ~74~121~21 minecraft:carved_pumpkin 1
setblock ~73~136~21 minecraft:carved_pumpkin 1
setblock ~74~120~21 minecraft:yellow_glazed_terracotta 4
setblock ~74~135~21 minecraft:carved_pumpkin 1
fill ~75~119~21 ~75~120~21 minecraft:planks 0
setblock ~75~134~21 minecraft:carved_pumpkin 1
fill ~76~118~21 ~77~118~21 minecraft:yellow_glazed_terracotta 4
setblock ~76~119~21 minecraft:yellow_glazed_terracotta 4
setblock ~76~133~21 minecraft:carved_pumpkin 1
setblock ~77~117~21 minecraft:yellow_glazed_terracotta 4
setblock ~77~132~21 minecraft:carved_pumpkin 1
fill ~78~116~21 ~79~116~21 minecraft:yellow_glazed_terracotta 4
setblock ~78~117~21 minecraft:carved_pumpkin 1
setblock ~78~131~21 minecraft:carved_pumpkin 1
fill ~79~115~21 ~80~115~21 minecraft:yellow_glazed_terracotta 4
setblock ~79~130~21 minecraft:carved_pumpkin 1
fill ~80~114~21 ~81~114~21 minecraft:yellow_glazed_terracotta 4
setblock ~80~129~21 minecraft:carved_pumpkin 1
fill ~81~113~21 ~82~113~21 minecraft:yellow_glazed_terracotta 4
setblock ~81~128~21 minecraft:carved_pumpkin 1
fill ~82~81~21 ~82~81~23 minecraft:obsidian
fill ~82~112~21 ~83~112~21 minecraft:yellow_glazed_terracotta 4
setblock ~82~127~21 minecraft:carved_pumpkin 1
fill ~83~111~21 ~84~111~21 minecraft:yellow_glazed_terracotta 4
setblock ~83~126~21 minecraft:carved_pumpkin 1
fill ~84~110~21 ~85~110~21 minecraft:yellow_glazed_terracotta 4
setblock ~84~125~21 minecraft:carved_pumpkin 1
fill ~85~109~21 ~86~109~21 minecraft:yellow_glazed_terracotta 4
setblock ~85~124~21 minecraft:carved_pumpkin 1
fill ~86~108~21 ~87~108~21 minecraft:yellow_glazed_terracotta 4
setblock ~86~123~21 minecraft:carved_pumpkin 1
fill ~87~107~21 ~88~107~21 minecraft:yellow_glazed_terracotta 4
setblock ~87~122~21 minecraft:carved_pumpkin 1
fill ~88~106~21 ~89~106~21 minecraft:yellow_glazed_terracotta 4
setblock ~88~121~21 minecraft:carved_pumpkin 1
fill ~89~105~21 ~90~105~21 minecraft:yellow_glazed_terracotta 4
setblock ~89~120~21 minecraft:carved_pumpkin 1
fill ~90~104~21 ~91~104~21 minecraft:yellow_glazed_terracotta 4
setblock ~90~119~21 minecraft:carved_pumpkin 1
fill ~91~62~21 ~91~62~23 minecraft:obsidian
fill ~91~103~21 ~92~103~21 minecraft:yellow_glazed_terracotta 4
setblock ~91~118~21 minecraft:carved_pumpkin 1
fill ~92~102~21 ~93~102~21 minecraft:yellow_glazed_terracotta 4
setblock ~92~117~21 minecraft:carved_pumpkin 1
fill ~93~101~21 ~94~101~21 minecraft:yellow_glazed_terracotta 4
setblock ~93~116~21 minecraft:carved_pumpkin 1
fill ~94~99~21 ~96~99~21 minecraft:yellow_glazed_terracotta 4
fill ~94~100~21 ~95~100~21 minecraft:yellow_glazed_terracotta 4
setblock ~94~115~21 minecraft:carved_pumpkin 1
fill ~95~98~21 ~97~98~21 minecraft:yellow_glazed_terracotta 4
setblock ~95~114~21 minecraft:carved_pumpkin 1
fill ~96~97~21 ~96~97~22 minecraft:carved_pumpkin 1
setblock ~96~113~21 minecraft:carved_pumpkin 1
fill ~97~96~21 ~97~96~22 minecraft:carved_pumpkin 1
fill ~97~97~21 ~98~97~21 minecraft:yellow_glazed_terracotta 4
setblock ~97~112~21 minecraft:carved_pumpkin 1
fill ~98~95~21 ~98~95~22 minecraft:carved_pumpkin 1
fill ~98~96~21 ~99~96~21 minecraft:yellow_glazed_terracotta 4
setblock ~98~111~21 minecraft:carved_pumpkin 1
fill ~99~94~21 ~99~94~22 minecraft:carved_pumpkin 1
fill ~99~95~21 ~100~95~21 minecraft:yellow_glazed_terracotta 4
setblock ~99~110~21 minecraft:carved_pumpkin 1
fill ~100~93~21 ~100~93~22 minecraft:carved_pumpkin 1
fill ~100~94~21 ~101~94~21 minecraft:yellow_glazed_terracotta 4
setblock ~100~109~21 minecraft:carved_pumpkin 1
fill ~101~92~21 ~103~92~21 minecraft:yellow_glazed_terracotta 4
fill ~101~93~21 ~102~93~21 minecraft:yellow_glazed_terracotta 4
fill ~101~108~21 ~102~108~21 minecraft:carved_pumpkin 1
fill ~102~54~21 ~102~54~23 minecraft:obsidian
fill ~102~91~21 ~104~91~21 minecraft:yellow_glazed_terracotta 4
fill ~102~107~21 ~103~107~21 minecraft:carved_pumpkin 1
fill ~103~90~21 ~105~90~21 minecraft:yellow_glazed_terracotta 4
fill ~103~106~21 ~104~106~21 minecraft:carved_pumpkin 1
fill ~104~54~21 ~104~54~23 minecraft:obsidian
fill ~104~89~21 ~106~89~21 minecraft:yellow_glazed_terracotta 4
fill ~104~105~21 ~105~105~21 minecraft:carved_pumpkin 1
setblock ~105~88~21 minecraft:yellow_glazed_terracotta 4
setblock ~105~104~21 minecraft:carved_pumpkin 1
setblock ~106~87~21 minecraft:yellow_glazed_terracotta 4
setblock ~106~103~21 minecraft:carved_pumpkin 1
fill ~106~104~21 ~106~104~22 minecraft:red_mushroom_block 0
setblock ~107~86~21 minecraft:yellow_glazed_terracotta 4
setblock ~107~102~21 minecraft:carved_pumpkin 1
fill ~107~103~21 ~107~103~22 minecraft:red_mushroom_block 0
setblock ~108~85~21 minecraft:yellow_glazed_terracotta 4
setblock ~108~101~21 minecraft:carved_pumpkin 1
fill ~108~102~21 ~108~102~22 minecraft:red_mushroom_block 0
fill ~109~83~21 ~109~83~23 minecraft:carved_pumpkin 1
fill ~109~100~21 ~110~100~21 minecraft:carved_pumpkin 1
fill ~109~101~21 ~109~101~22 minecraft:red_mushroom_block 0
fill ~110~50~21 ~111~50~23 minecraft:obsidian
fill ~110~51~21 ~110~51~23 minecraft:obsidian
fill ~110~82~21 ~110~82~23 minecraft:carved_pumpkin 1
fill ~110~99~21 ~111~99~21 minecraft:carved_pumpkin 1
fill ~112~97~21 ~113~97~21 minecraft:carved_pumpkin 1
setblock ~112~98~21 minecraft:carved_pumpkin 1
setblock ~114~96~21 minecraft:carved_pumpkin 1
fill ~115~47~21 ~115~47~23 minecraft:obsidian
setblock ~115~95~21 minecraft:carved_pumpkin 1
setblock ~116~94~21 minecraft:red_mushroom_block 0
setblock ~117~93~21 minecraft:red_mushroom_block 0
fill ~119~92~21 ~120~92~23 minecraft:red_mushroom_block 0
fill ~119~93~21 ~119~93~23 minecraft:red_mushroom_block 0
fill ~120~39~21 ~120~39~23 minecraft:obsidian
fill ~120~91~21 ~120~91~23 minecraft:red_mushroom_block 0
