fill ~80~0~0 ~82~0~2 minecraft:stained_hardened_clay 10
fill ~81~1~0 ~83~2~2 minecraft:stained_hardened_clay 10
fill ~82~3~0 ~83~3~4 minecraft:stained_hardened_clay 10
fill ~83~4~0 ~83~4~3 minecraft:stained_hardened_clay 10
fill ~79~0~1 ~79~0~3 minecraft:stained_hardened_clay 10
fill ~80~1~1 ~80~1~4 minecraft:stained_hardened_clay 10
fill ~80~2~1 ~80~2~3 minecraft:stained_hardened_clay 10
fill ~81~3~1 ~81~4~4 minecraft:stained_hardened_clay 10
fill ~82~4~1 ~82~5~4 minecraft:stained_hardened_clay 10
setblock ~83~0~1 minecraft:purple_glazed_terracotta 3
fill ~83~5~1 ~84~6~3 minecraft:stained_hardened_clay 10
fill ~83~7~1 ~83~7~5 minecraft:stained_hardened_clay 10
fill ~84~2~1 ~84~4~1 minecraft:stained_hardened_clay 10
setblock ~79~1~2 minecraft:stained_hardened_clay 10
fill ~80~3~2 ~80~3~3 minecraft:stained_hardened_clay 10
fill ~81~5~2 ~81~5~3 minecraft:stained_hardened_clay 10
fill ~82~6~2 ~82~7~5 minecraft:stained_hardened_clay 10
fill ~83~0~2 ~83~0~3 minecraft:pink_glazed_terracotta 3
fill ~83~8~2 ~85~9~4 minecraft:stained_hardened_clay 10
fill ~83~10~2 ~84~10~5 minecraft:stained_hardened_clay 10
setblock ~84~0~2 minecraft:purple_glazed_terracotta 3
fill ~84~1~2 ~84~2~2 minecraft:concrete 10
fill ~84~3~2 ~84~4~3 minecraft:stained_hardened_clay 10
fill ~84~7~2 ~85~7~4 minecraft:stained_hardened_clay 10
fill ~85~4~2 ~85~6~2 minecraft:stained_hardened_clay 10
fill ~80~0~3 ~81~0~3 minecraft:stained_hardened_clay 10
fill ~81~1~3 ~82~2~3 minecraft:stained_hardened_clay 10
setblock ~81~6~3 minecraft:stained_hardened_clay 10
fill ~82~0~3 ~82~0~4 minecraft:pink_glazed_terracotta 3
fill ~82~8~3 ~82~11~5 minecraft:stained_hardened_clay 10
fill ~83~1~3 ~83~1~4 minecraft:pink_glazed_terracotta 3
setblock ~83~2~3 minecraft:stained_hardened_clay 10
fill ~83~11~3 ~85~11~5 minecraft:stained_hardened_clay 10
fill ~83~12~3 ~84~12~6 minecraft:stained_hardened_clay 10
setblock ~84~0~3 minecraft:pink_glazed_terracotta 3
setblock ~84~1~3 minecraft:wool 6
fill ~84~2~3 ~84~2~4 minecraft:pink_glazed_terracotta 3
setblock ~85~2~3 minecraft:wool 6
setblock ~85~3~3 minecraft:purple_glazed_terracotta 3
setblock ~85~4~3 minecraft:concrete 10
setblock ~85~5~3 minecraft:purple_glazed_terracotta 3
fill ~85~6~3 ~85~6~4 minecraft:stained_hardened_clay 10
fill ~85~10~3 ~85~10~4 minecraft:stained_hardened_clay 10
setblock ~86~6~3 minecraft:concrete 10
fill ~86~7~3 ~86~9~3 minecraft:stained_hardened_clay 10
setblock ~80~0~4 minecraft:stained_hardened_clay 10
fill ~80~11~4 ~81~12~7 minecraft:stained_hardened_clay 10
fill ~81~0~4 ~81~1~4 minecraft:concrete 10
setblock ~81~2~4 minecraft:purple_glazed_terracotta 3
fill ~81~8~4 ~81~10~5 minecraft:stained_hardened_clay 10
fill ~81~13~4 ~83~13~7 minecraft:stained_hardened_clay 10
fill ~82~1~4 ~82~2~4 minecraft:stained_hardened_clay 10
fill ~82~12~4 ~82~12~8 minecraft:stained_hardened_clay 10
setblock ~83~0~4 minecraft:wool 6
fill ~83~2~4 ~83~2~5 minecraft:pink_glazed_terracotta 3
fill ~83~4~4 ~85~4~4 minecraft:pink_glazed_terracotta 3
fill ~83~5~4 ~83~6~4 minecraft:stained_hardened_clay 10
setblock ~84~1~4 minecraft:stained_hardened_clay 2
fill ~84~3~4 ~85~3~4 minecraft:pink_glazed_terracotta 3
fill ~84~5~4 ~84~5~6 minecraft:pink_glazed_terracotta 3
setblock ~84~6~4 minecraft:stained_hardened_clay 10
setblock ~85~5~4 minecraft:stained_hardened_clay 10
fill ~85~12~4 ~85~12~5 minecraft:stained_hardened_clay 10
setblock ~86~5~4 minecraft:wool 6
setblock ~86~6~4 minecraft:pink_glazed_terracotta 3
setblock ~86~7~4 minecraft:concrete 10
setblock ~86~8~4 minecraft:purple_glazed_terracotta 3
fill ~86~9~4 ~86~10~4 minecraft:stained_hardened_clay 10
setblock ~62~17~5 minecraft:purple_glazed_terracotta 3
setblock ~62~18~5 minecraft:concrete 10
setblock ~63~16~5 minecraft:concrete 10
fill ~63~17~5 ~65~17~9 minecraft:stained_hardened_clay 10
fill ~63~18~5 ~64~18~9 minecraft:stained_hardened_clay 10
setblock ~64~15~5 minecraft:purple_glazed_terracotta 3
fill ~64~16~5 ~67~16~9 minecraft:stained_hardened_clay 10
setblock ~65~15~5 minecraft:concrete 10
setblock ~66~15~5 minecraft:purple_glazed_terracotta 3
fill ~79~12~5 ~79~13~11 minecraft:stained_hardened_clay 10
fill ~80~9~5 ~80~10~5 minecraft:stained_hardened_clay 10
fill ~80~13~5 ~80~14~12 minecraft:stained_hardened_clay 10
setblock ~81~7~5 minecraft:stained_hardened_clay 10
fill ~81~14~5 ~81~14~25 minecraft:stained_hardened_clay 10
fill ~82~1~5 ~82~2~5 minecraft:pink_glazed_terracotta 3
setblock ~82~3~5 minecraft:concrete 10
setblock ~82~4~5 minecraft:purple_glazed_terracotta 3
setblock ~82~5~5 minecraft:stained_hardened_clay 10
setblock ~83~3~5 minecraft:wool 6
fill ~83~4~5 ~83~5~5 minecraft:pink_glazed_terracotta 3
setblock ~83~6~5 minecraft:stained_hardened_clay 10
fill ~83~8~5 ~83~9~5 minecraft:stained_hardened_clay 10
setblock ~84~3~5 minecraft:stained_hardened_clay 2
setblock ~84~4~5 minecraft:wool 6
fill ~84~6~5 ~84~6~6 minecraft:pink_glazed_terracotta 3
setblock ~84~7~5 minecraft:stained_hardened_clay 10
fill ~84~8~5 ~86~8~5 minecraft:pink_glazed_terracotta 3
setblock ~84~9~5 minecraft:stained_hardened_clay 10
fill ~84~13~5 ~84~13~6 minecraft:stained_hardened_clay 10
setblock ~85~5~5 minecraft:stained_hardened_clay 2
fill ~85~6~5 ~85~6~6 minecraft:wool 6
fill ~85~7~5 ~86~7~5 minecraft:pink_glazed_terracotta 3
fill ~85~9~5 ~85~9~6 minecraft:pink_glazed_terracotta 3
setblock ~85~10~5 minecraft:purple_glazed_terracotta 3
setblock ~86~9~5 minecraft:concrete 10
fill ~60~17~6 ~62~17~6 minecraft:pink_glazed_terracotta 3
setblock ~60~18~6 minecraft:wool 6
fill ~60~19~6 ~60~20~8 minecraft:pink_glazed_terracotta 3
fill ~61~16~6 ~63~16~6 minecraft:pink_glazed_terracotta 3
fill ~61~18~6 ~61~18~7 minecraft:pink_glazed_terracotta 3
setblock ~61~19~6 minecraft:concrete 10
fill ~62~15~6 ~64~15~8 minecraft:pink_glazed_terracotta 3
fill ~62~18~6 ~62~19~10 minecraft:stained_hardened_clay 10
setblock ~63~14~6 minecraft:pink_glazed_terracotta 2
fill ~64~14~6 ~67~14~8 minecraft:pink_glazed_terracotta 3
fill ~65~13~6 ~65~13~7 minecraft:wool 6
fill ~65~15~6 ~66~15~6 minecraft:stained_hardened_clay 10
fill ~65~18~6 ~66~18~8 minecraft:stained_hardened_clay 10
fill ~66~13~6 ~66~13~9 minecraft:pink_glazed_terracotta 3
fill ~66~17~6 ~67~17~9 minecraft:stained_hardened_clay 10
setblock ~67~15~6 minecraft:concrete 10
setblock ~68~14~6 minecraft:concrete 10
fill ~68~15~6 ~70~15~12 minecraft:stained_hardened_clay 10
fill ~68~16~6 ~69~16~11 minecraft:stained_hardened_clay 10
fill ~79~11~6 ~79~11~8 minecraft:stained_hardened_clay 10
fill ~79~14~6 ~79~14~15 minecraft:stained_hardened_clay 10
fill ~80~10~6 ~82~10~6 minecraft:stained_hardened_clay 10
setblock ~81~9~6 minecraft:purple_glazed_terracotta 3
setblock ~82~7~6 minecraft:stained_hardened_clay 10
setblock ~82~8~6 minecraft:purple_glazed_terracotta 3
fill ~82~9~6 ~84~9~6 minecraft:pink_glazed_terracotta 3
fill ~82~11~6 ~84~11~6 minecraft:stained_hardened_clay 10
fill ~82~14~6 ~82~14~21 minecraft:stained_hardened_clay 10
fill ~83~5~6 ~83~7~6 minecraft:concrete 10
fill ~83~8~6 ~84~8~6 minecraft:pink_glazed_terracotta 3
fill ~83~10~6 ~83~10~7 minecraft:pink_glazed_terracotta 3
setblock ~84~7~6 minecraft:pink_glazed_terracotta 3
setblock ~84~10~6 minecraft:stained_hardened_clay 10
setblock ~85~7~6 minecraft:stained_hardened_clay 2
setblock ~85~8~6 minecraft:wool 6
setblock ~85~10~6 minecraft:pink_glazed_terracotta 3
setblock ~85~11~6 minecraft:concrete 10
setblock ~58~18~7 minecraft:stained_hardened_clay 2
setblock ~59~18~7 minecraft:pink_glazed_terracotta 2
fill ~59~19~7 ~59~20~8 minecraft:pink_glazed_terracotta 3
setblock ~60~16~7 minecraft:stained_hardened_clay 2
setblock ~60~17~7 minecraft:wool 6
fill ~60~18~7 ~60~18~8 minecraft:pink_glazed_terracotta 3
fill ~60~21~7 ~60~21~10 minecraft:pink_glazed_terracotta 3
fill ~61~15~7 ~61~15~8 minecraft:pink_glazed_terracotta 3
fill ~61~16~7 ~62~16~7 minecraft:pink_glazed_terracotta 3
fill ~61~17~7 ~61~17~8 minecraft:pink_glazed_terracotta 3
fill ~61~19~7 ~61~19~10 minecraft:stained_hardened_clay 10
setblock ~61~20~7 minecraft:purple_glazed_terracotta 3
setblock ~61~21~7 minecraft:concrete 10
setblock ~62~14~7 minecraft:stained_hardened_clay 2
fill ~62~17~7 ~62~17~10 minecraft:stained_hardened_clay 10
fill ~62~20~7 ~62~20~11 minecraft:stained_hardened_clay 10
fill ~63~14~7 ~63~14~8 minecraft:wool 6
fill ~63~16~7 ~63~16~9 minecraft:stained_hardened_clay 10
fill ~63~19~7 ~64~19~8 minecraft:stained_hardened_clay 10
setblock ~64~13~7 minecraft:stained_hardened_clay 2
setblock ~65~15~7 minecraft:pink_glazed_terracotta 3
setblock ~66~12~7 minecraft:stained_hardened_clay 2
fill ~66~15~7 ~67~15~9 minecraft:stained_hardened_clay 10
fill ~67~12~7 ~68~13~7 minecraft:pink_glazed_terracotta 3
setblock ~68~14~7 minecraft:stained_hardened_clay 10
fill ~68~17~7 ~69~17~8 minecraft:stained_hardened_clay 10
fill ~69~13~7 ~69~13~11 minecraft:pink_glazed_terracotta 3
fill ~69~14~7 ~70~14~7 minecraft:purple_glazed_terracotta 3
fill ~70~16~7 ~70~16~22 minecraft:stained_hardened_clay 10
fill ~71~14~7 ~71~15~11 minecraft:stained_hardened_clay 10
fill ~78~12~7 ~78~13~9 minecraft:stained_hardened_clay 10
setblock ~80~10~7 minecraft:purple_glazed_terracotta 3
fill ~80~15~7 ~81~15~26 minecraft:stained_hardened_clay 10
fill ~81~10~7 ~82~10~7 minecraft:pink_glazed_terracotta 3
setblock ~82~9~7 minecraft:pink_glazed_terracotta 3
fill ~82~11~7 ~82~11~8 minecraft:pink_glazed_terracotta 3
setblock ~83~8~7 minecraft:pink_glazed_terracotta 3
setblock ~83~9~7 minecraft:wool 6
fill ~83~11~7 ~83~12~7 minecraft:stained_hardened_clay 10
setblock ~84~9~7 minecraft:stained_hardened_clay 2
setblock ~84~10~7 minecraft:wool 6
setblock ~84~11~7 minecraft:pink_glazed_terracotta 3
setblock ~84~12~7 minecraft:concrete 10
fill ~58~18~8 ~59~18~8 minecraft:pink_glazed_terracotta 3
setblock ~58~19~8 minecraft:wool 6
setblock ~58~20~8 minecraft:stained_hardened_clay 2
fill ~59~17~8 ~60~17~8 minecraft:pink_glazed_terracotta 3
setblock ~59~21~8 minecraft:pink_glazed_terracotta 4
setblock ~60~16~8 minecraft:wool 6
fill ~60~22~8 ~60~22~9 minecraft:wool 6
fill ~61~16~8 ~62~16~8 minecraft:stained_hardened_clay 10
fill ~61~18~8 ~61~18~10 minecraft:stained_hardened_clay 10
fill ~61~20~8 ~61~20~11 minecraft:stained_hardened_clay 10
fill ~61~21~8 ~62~21~8 minecraft:stained_hardened_clay 10
fill ~61~22~8 ~61~22~10 minecraft:pink_glazed_terracotta 3
setblock ~62~14~8 minecraft:pink_glazed_terracotta 3
setblock ~62~22~8 minecraft:purple_glazed_terracotta 3
fill ~64~13~8 ~65~13~8 minecraft:pink_glazed_terracotta 3
fill ~65~15~8 ~65~15~9 minecraft:stained_hardened_clay 10
setblock ~66~12~8 minecraft:pink_glazed_terracotta 3
setblock ~67~12~8 minecraft:wool 6
fill ~67~13~8 ~68~13~9 minecraft:pink_glazed_terracotta 3
setblock ~67~18~8 minecraft:stained_hardened_clay 10
setblock ~68~11~8 minecraft:stained_hardened_clay 2
fill ~68~12~8 ~70~12~8 minecraft:pink_glazed_terracotta 3
setblock ~68~14~8 minecraft:pink_glazed_terracotta 3
fill ~69~14~8 ~70~14~11 minecraft:stained_hardened_clay 10
fill ~70~13~8 ~70~13~13 minecraft:pink_glazed_terracotta 3
setblock ~70~17~8 minecraft:stained_hardened_clay 10
setblock ~71~13~8 minecraft:concrete 10
fill ~71~16~8 ~71~16~25 minecraft:stained_hardened_clay 10
setblock ~78~11~8 minecraft:stained_hardened_clay 10
fill ~78~14~8 ~78~14~13 minecraft:stained_hardened_clay 10
setblock ~79~10~8 minecraft:purple_glazed_terracotta 3
fill ~79~15~8 ~79~15~15 minecraft:stained_hardened_clay 10
fill ~80~10~8 ~81~10~8 minecraft:pink_glazed_terracotta 3
fill ~80~11~8 ~80~12~8 minecraft:stained_hardened_clay 10
fill ~81~11~8 ~81~11~9 minecraft:pink_glazed_terracotta 3
fill ~81~12~8 ~81~13~8 minecraft:stained_hardened_clay 10
setblock ~82~10~8 minecraft:stained_hardened_clay 2
setblock ~82~13~8 minecraft:stained_hardened_clay 10
setblock ~83~11~8 minecraft:pink_glazed_terracotta 3
setblock ~83~12~8 minecraft:concrete 10
setblock ~58~19~9 minecraft:pink_glazed_terracotta 3
setblock ~58~20~9 minecraft:wool 6
fill ~58~21~9 ~59~21~9 minecraft:pink_glazed_terracotta 3
setblock ~59~18~9 minecraft:pink_glazed_terracotta 4
fill ~59~19~9 ~60~19~9 minecraft:stained_hardened_clay 10
fill ~59~20~9 ~60~20~9 minecraft:pink_glazed_terracotta 3
setblock ~59~22~9 minecraft:stained_hardened_clay 2
setblock ~60~17~9 minecraft:purple_glazed_terracotta 3
setblock ~60~18~9 minecraft:stained_hardened_clay 10
setblock ~61~16~9 minecraft:concrete 10
fill ~61~17~9 ~61~17~10 minecraft:stained_hardened_clay 10
setblock ~61~21~9 minecraft:pink_glazed_terracotta 3
fill ~61~23~9 ~62~23~11 minecraft:pink_glazed_terracotta 3
setblock ~62~16~9 minecraft:purple_glazed_terracotta 3
fill ~62~21~9 ~63~21~11 minecraft:stained_hardened_clay 10
setblock ~62~22~9 minecraft:stained_hardened_clay 10
fill ~63~15~9 ~64~15~9 minecraft:concrete 10
setblock ~63~19~9 minecraft:stained_hardened_clay 10
setblock ~63~22~9 minecraft:concrete 10
fill ~64~14~9 ~65~14~9 minecraft:pink_glazed_terracotta 3
setblock ~65~13~9 minecraft:pink_glazed_terracotta 4
setblock ~65~18~9 minecraft:stained_hardened_clay 10
setblock ~66~14~9 minecraft:stained_hardened_clay 10
setblock ~67~12~9 minecraft:pink_glazed_terracotta 4
setblock ~67~14~9 minecraft:pink_glazed_terracotta 3
setblock ~68~12~9 minecraft:wool 6
fill ~68~14~9 ~68~14~10 minecraft:stained_hardened_clay 10
setblock ~68~17~9 minecraft:stained_hardened_clay 10
setblock ~69~11~9 minecraft:wool 6
fill ~69~12~9 ~71~12~11 minecraft:pink_glazed_terracotta 3
setblock ~70~11~9 minecraft:pink_glazed_terracotta 3
fill ~71~13~9 ~71~13~13 minecraft:pink_glazed_terracotta 3
setblock ~72~14~9 minecraft:purple_glazed_terracotta 3
fill ~72~15~9 ~72~15~13 minecraft:stained_hardened_clay 10
fill ~77~13~9 ~77~13~11 minecraft:stained_hardened_clay 10
fill ~78~11~9 ~79~11~9 minecraft:concrete 10
fill ~80~10~9 ~80~11~9 minecraft:pink_glazed_terracotta 3
setblock ~80~12~9 minecraft:stained_hardened_clay 10
setblock ~81~10~9 minecraft:wool 6
fill ~81~12~9 ~82~12~12 minecraft:pink_glazed_terracotta 3
fill ~81~13~9 ~81~13~11 minecraft:stained_hardened_clay 10
setblock ~82~11~9 minecraft:wool 6
fill ~82~13~9 ~82~13~10 minecraft:concrete 10
setblock ~58~20~10 minecraft:pink_glazed_terracotta 4
setblock ~59~19~10 minecraft:concrete 10
setblock ~59~20~10 minecraft:purple_glazed_terracotta 3
setblock ~59~21~10 minecraft:pink_glazed_terracotta 4
fill ~59~22~10 ~60~22~10 minecraft:pink_glazed_terracotta 3
setblock ~60~18~10 minecraft:concrete 10
fill ~60~19~10 ~60~20~10 minecraft:stained_hardened_clay 10
setblock ~60~23~10 minecraft:pink_glazed_terracotta 3
fill ~61~21~10 ~61~21~11 minecraft:stained_hardened_clay 10
setblock ~61~24~10 minecraft:stained_hardened_clay 2
setblock ~62~22~10 minecraft:pink_glazed_terracotta 3
fill ~62~24~10 ~63~24~11 minecraft:pink_glazed_terracotta 3
setblock ~63~18~10 minecraft:stained_hardened_clay 10
setblock ~63~20~10 minecraft:stained_hardened_clay 10
fill ~63~22~10 ~64~22~12 minecraft:stained_hardened_clay 10
fill ~63~23~10 ~63~23~11 minecraft:pink_glazed_terracotta 3
setblock ~64~23~10 minecraft:concrete 10
setblock ~65~15~10 minecraft:purple_glazed_terracotta 3
setblock ~66~14~10 minecraft:pink_glazed_terracotta 3
setblock ~66~15~10 minecraft:concrete 10
fill ~66~16~10 ~67~16~10 minecraft:stained_hardened_clay 10
setblock ~67~13~10 minecraft:pink_glazed_terracotta 4
setblock ~67~14~10 minecraft:concrete 10
fill ~67~15~10 ~67~15~11 minecraft:stained_hardened_clay 10
fill ~68~12~10 ~68~13~10 minecraft:pink_glazed_terracotta 3
setblock ~69~11~10 minecraft:pink_glazed_terracotta 4
setblock ~70~11~10 minecraft:stained_hardened_clay 2
fill ~70~17~10 ~71~17~11 minecraft:stained_hardened_clay 10
setblock ~72~13~10 minecraft:purple_glazed_terracotta 3
setblock ~72~14~10 minecraft:stained_hardened_clay 10
fill ~72~16~10 ~72~16~25 minecraft:stained_hardened_clay 10
setblock ~77~12~10 minecraft:stained_hardened_clay 10
fill ~77~14~10 ~77~14~13 minecraft:stained_hardened_clay 10
fill ~78~12~10 ~78~12~11 minecraft:concrete 10
fill ~78~13~10 ~78~13~11 minecraft:stained_hardened_clay 10
fill ~79~11~10 ~79~11~11 minecraft:pink_glazed_terracotta 3
setblock ~80~11~10 minecraft:wool 6
setblock ~80~12~10 minecraft:pink_glazed_terracotta 3
setblock ~81~11~10 minecraft:stained_hardened_clay 2
fill ~82~15~10 ~82~15~25 minecraft:stained_hardened_clay 10
setblock ~60~21~11 minecraft:concrete 10
setblock ~60~22~11 minecraft:purple_glazed_terracotta 3
fill ~61~22~11 ~62~22~11 minecraft:stained_hardened_clay 10
setblock ~61~24~11 minecraft:wool 6
setblock ~63~25~11 minecraft:pink_glazed_terracotta 2
setblock ~64~21~11 minecraft:stained_hardened_clay 10
fill ~64~23~11 ~64~25~11 minecraft:pink_glazed_terracotta 3
fill ~65~23~11 ~65~23~12 minecraft:stained_hardened_clay 10
setblock ~65~24~11 minecraft:concrete 10
setblock ~67~14~11 minecraft:purple_glazed_terracotta 3
setblock ~68~13~11 minecraft:pink_glazed_terracotta 3
setblock ~68~14~11 minecraft:purple_glazed_terracotta 4
setblock ~70~11~11 minecraft:wool 6
fill ~72~13~11 ~72~13~13 minecraft:pink_glazed_terracotta 3
setblock ~72~14~11 minecraft:purple_glazed_terracotta 3
fill ~72~17~11 ~72~17~26 minecraft:stained_hardened_clay 10
fill ~73~15~11 ~73~16~14 minecraft:stained_hardened_clay 10
fill ~78~15~11 ~78~15~15 minecraft:stained_hardened_clay 10
fill ~80~11~11 ~81~11~11 minecraft:pink_glazed_terracotta 3
setblock ~80~12~11 minecraft:stained_hardened_clay 10
fill ~80~16~11 ~81~16~26 minecraft:stained_hardened_clay 10
fill ~82~13~11 ~82~13~12 minecraft:stained_hardened_clay 10
fill ~83~13~11 ~83~13~13 minecraft:pink_glazed_terracotta 3
fill ~83~14~11 ~83~14~12 minecraft:purple_glazed_terracotta 3
setblock ~61~23~12 minecraft:purple_glazed_terracotta 3
fill ~62~22~12 ~62~23~12 minecraft:stained_hardened_clay 10
setblock ~62~24~12 minecraft:purple_glazed_terracotta 3
setblock ~62~25~12 minecraft:pink_glazed_terracotta 3
setblock ~63~21~12 minecraft:stained_hardened_clay 10
fill ~63~23~12 ~64~23~12 minecraft:stained_hardened_clay 10
fill ~63~24~12 ~64~24~12 minecraft:pink_glazed_terracotta 3
setblock ~63~25~12 minecraft:stained_hardened_clay 2
setblock ~64~25~12 minecraft:wool 6
fill ~65~24~12 ~65~24~13 minecraft:stained_hardened_clay 10
setblock ~65~25~12 minecraft:purple_glazed_terracotta 3
fill ~68~14~12 ~69~14~12 minecraft:concrete 10
setblock ~69~13~12 minecraft:pink_glazed_terracotta 4
fill ~69~16~12 ~69~16~13 minecraft:stained_hardened_clay 10
setblock ~70~12~12 minecraft:pink_glazed_terracotta 3
setblock ~70~14~12 minecraft:stained_hardened_clay 10
setblock ~71~12~12 minecraft:stained_hardened_clay 2
fill ~71~14~12 ~71~14~14 minecraft:pink_glazed_terracotta 3
fill ~71~15~12 ~71~15~13 minecraft:stained_hardened_clay 10
fill ~71~17~12 ~71~17~26 minecraft:stained_hardened_clay 10
setblock ~72~12~12 minecraft:wool 6
setblock ~72~14~12 minecraft:stained_hardened_clay 10
fill ~73~14~12 ~73~14~13 minecraft:purple_glazed_terracotta 3
fill ~73~17~12 ~73~17~26 minecraft:stained_hardened_clay 10
setblock ~74~15~12 minecraft:stained_hardened_clay 2
setblock ~78~13~12 minecraft:purple_glazed_terracotta 3
fill ~79~12~12 ~80~12~13 minecraft:pink_glazed_terracotta 3
fill ~79~13~12 ~79~13~13 minecraft:stained_hardened_clay 10
setblock ~80~11~12 minecraft:wool 6
setblock ~81~11~12 minecraft:stained_hardened_clay 2
fill ~81~13~12 ~81~13~16 minecraft:pink_glazed_terracotta 3
fill ~82~16~12 ~82~16~25 minecraft:stained_hardened_clay 10
fill ~83~15~12 ~83~15~21 minecraft:stained_hardened_clay 10
setblock ~62~24~13 minecraft:concrete 10
fill ~63~24~13 ~64~24~13 minecraft:stained_hardened_clay 10
setblock ~63~25~13 minecraft:concrete 10
setblock ~64~23~13 minecraft:stained_hardened_clay 10
fill ~64~25~13 ~66~25~13 minecraft:stained_hardened_clay 10
setblock ~64~26~13 minecraft:wool 6
setblock ~65~26~13 minecraft:pink_glazed_terracotta 3
setblock ~66~26~13 minecraft:purple_glazed_terracotta 3
setblock ~69~14~13 minecraft:purple_glazed_terracotta 3
fill ~69~15~13 ~70~15~13 minecraft:stained_hardened_clay 10
fill ~70~14~13 ~70~14~15 minecraft:pink_glazed_terracotta 3
fill ~70~17~13 ~70~17~25 minecraft:stained_hardened_clay 10
setblock ~71~12~13 minecraft:pink_glazed_terracotta 3
fill ~72~14~13 ~72~14~14 minecraft:pink_glazed_terracotta 3
fill ~72~18~13 ~72~18~26 minecraft:stained_hardened_clay 10
fill ~74~15~13 ~74~16~13 minecraft:stained_hardened_clay 10
fill ~75~15~13 ~75~15~14 minecraft:stained_hardened_clay 2
setblock ~78~13~13 minecraft:concrete 10
setblock ~80~13~13 minecraft:pink_glazed_terracotta 3
fill ~80~14~13 ~80~14~25 minecraft:stained_hardened_clay 10
setblock ~81~12~13 minecraft:wool 6
fill ~82~12~13 ~82~13~13 minecraft:pink_glazed_terracotta 3
setblock ~83~14~13 minecraft:concrete 10
setblock ~64~26~14 minecraft:concrete 10
fill ~65~25~14 ~66~25~14 minecraft:stained_hardened_clay 10
setblock ~65~26~14 minecraft:purple_glazed_terracotta 3
fill ~66~26~14 ~67~26~14 minecraft:stained_hardened_clay 10
setblock ~66~27~14 minecraft:pink_glazed_terracotta 3
setblock ~67~27~14 minecraft:concrete 10
fill ~69~15~14 ~69~15~15 minecraft:purple_glazed_terracotta 3
fill ~69~16~14 ~69~16~15 minecraft:stained_hardened_clay 2
setblock ~70~15~14 minecraft:stained_hardened_clay 10
setblock ~71~13~14 minecraft:stained_hardened_clay 2
fill ~71~15~14 ~72~15~15 minecraft:pink_glazed_terracotta 3
fill ~71~18~14 ~71~18~26 minecraft:stained_hardened_clay 10
setblock ~72~13~14 minecraft:wool 6
fill ~73~14~14 ~73~14~15 minecraft:pink_glazed_terracotta 3
fill ~73~18~14 ~73~18~26 minecraft:stained_hardened_clay 10
fill ~74~15~14 ~74~15~15 minecraft:purple_glazed_terracotta 3
fill ~74~16~14 ~74~17~22 minecraft:stained_hardened_clay 10
fill ~77~15~14 ~77~15~16 minecraft:stained_hardened_clay 2
fill ~78~14~14 ~78~14~15 minecraft:purple_glazed_terracotta 3
fill ~79~13~14 ~79~13~15 minecraft:pink_glazed_terracotta 3
fill ~79~16~14 ~79~16~26 minecraft:stained_hardened_clay 10
fill ~80~12~14 ~81~12~15 minecraft:pink_glazed_terracotta 3
setblock ~80~13~14 minecraft:stained_hardened_clay 10
fill ~80~17~14 ~81~17~26 minecraft:stained_hardened_clay 10
setblock ~82~12~14 minecraft:stained_hardened_clay 2
setblock ~82~13~14 minecraft:stained_hardened_clay 10
setblock ~83~13~14 minecraft:wool 6
setblock ~83~14~14 minecraft:purple_glazed_terracotta 3
fill ~65~27~15 ~67~27~15 minecraft:stained_hardened_clay 10
setblock ~70~15~15 minecraft:pink_glazed_terracotta 3
fill ~71~14~15 ~72~14~15 minecraft:wool 6
fill ~72~19~15 ~73~19~26 minecraft:stained_hardened_clay 10
setblock ~73~15~15 minecraft:pink_glazed_terracotta 3
fill ~73~16~15 ~73~16~25 minecraft:stained_hardened_clay 10
fill ~74~18~15 ~74~18~25 minecraft:stained_hardened_clay 10
setblock ~75~16~15 minecraft:stained_hardened_clay 2
setblock ~76~15~15 minecraft:stained_hardened_clay 2
setblock ~80~13~15 minecraft:pink_glazed_terracotta 3
fill ~82~12~15 ~83~12~15 minecraft:wool 6
setblock ~82~13~15 minecraft:pink_glazed_terracotta 3
fill ~82~17~15 ~82~17~25 minecraft:stained_hardened_clay 10
fill ~83~13~15 ~83~14~21 minecraft:stained_hardened_clay 10
fill ~83~16~15 ~83~16~21 minecraft:stained_hardened_clay 10
fill ~84~13~15 ~84~13~20 minecraft:pink_glazed_terracotta 3
setblock ~84~14~15 minecraft:purple_glazed_terracotta 3
fill ~8~29~16 ~9~29~16 minecraft:wool 15
fill ~8~30~16 ~9~30~16 minecraft:coal_block
setblock ~10~29~16 minecraft:coal_block
fill ~10~30~16 ~11~30~16 minecraft:obsidian
fill ~11~29~16 ~12~29~16 minecraft:wool 15
setblock ~12~28~16 minecraft:wool 15
setblock ~12~30~16 minecraft:wool 15
fill ~13~28~16 ~13~28~18 minecraft:coal_block
setblock ~13~29~16 minecraft:coal_block
setblock ~14~28~16 minecraft:wool 15
fill ~14~29~16 ~14~29~18 minecraft:obsidian
setblock ~15~28~16 minecraft:obsidian
fill ~15~29~16 ~16~29~16 minecraft:coal_block
fill ~16~27~16 ~16~27~18 minecraft:wool 15
setblock ~16~28~16 minecraft:wool 15
setblock ~17~27~16 minecraft:obsidian
fill ~17~28~16 ~18~28~16 minecraft:coal_block
fill ~18~27~16 ~18~27~17 minecraft:coal_block
fill ~19~27~16 ~19~27~18 minecraft:wool 15
setblock ~19~28~16 minecraft:obsidian
fill ~20~26~16 ~20~28~16 minecraft:coal_block
fill ~21~26~16 ~21~26~17 minecraft:wool 15
fill ~21~27~16 ~23~27~16 minecraft:obsidian
setblock ~22~26~16 minecraft:coal_block
setblock ~23~26~16 minecraft:wool 15
setblock ~24~25~16 minecraft:wool 15
setblock ~24~26~16 minecraft:obsidian
setblock ~24~27~16 minecraft:wool 15
setblock ~25~25~16 minecraft:obsidian
fill ~25~26~16 ~28~26~16 minecraft:wool 15
setblock ~26~25~16 minecraft:coal_block
setblock ~27~25~16 minecraft:wool 15
fill ~28~24~16 ~30~24~17 minecraft:coal_block
setblock ~28~25~16 minecraft:obsidian
setblock ~29~25~16 minecraft:coal_block
fill ~30~25~16 ~30~25~17 minecraft:obsidian
fill ~31~24~16 ~32~25~16 minecraft:wool 15
setblock ~32~23~16 minecraft:wool 15
fill ~33~23~16 ~33~23~17 minecraft:obsidian
setblock ~33~24~16 minecraft:obsidian
setblock ~34~23~16 minecraft:coal_block
setblock ~34~24~16 minecraft:wool 15
setblock ~35~23~16 minecraft:wool 15
setblock ~35~24~16 minecraft:coal_block
fill ~36~22~16 ~36~24~17 minecraft:obsidian
setblock ~37~22~16 minecraft:coal_block
setblock ~37~23~16 minecraft:obsidian
fill ~38~22~16 ~38~23~16 minecraft:wool 15
fill ~39~22~16 ~39~23~16 minecraft:obsidian
fill ~40~21~16 ~40~21~17 minecraft:coal_block
setblock ~40~22~16 minecraft:coal_block
setblock ~40~23~16 minecraft:wool 15
fill ~41~21~16 ~42~21~16 minecraft:wool 15
setblock ~41~22~16 minecraft:obsidian
setblock ~42~22~16 minecraft:coal_block
fill ~43~21~16 ~43~21~17 minecraft:obsidian
fill ~43~22~16 ~44~22~16 minecraft:wool 15
fill ~44~20~16 ~46~20~16 minecraft:coal_block
setblock ~44~21~16 minecraft:coal_block
fill ~45~21~16 ~46~21~16 minecraft:wool 15
fill ~47~20~16 ~47~21~16 minecraft:obsidian
setblock ~48~19~16 minecraft:obsidian
fill ~48~20~16 ~49~20~16 minecraft:coal_block
setblock ~48~21~16 minecraft:wool 15
fill ~49~19~16 ~51~19~16 minecraft:wool 15
setblock ~50~20~16 minecraft:obsidian
setblock ~51~20~16 minecraft:wool 15
fill ~52~18~16 ~52~18~17 minecraft:wool 15
fill ~52~19~16 ~52~19~17 minecraft:obsidian
setblock ~52~20~16 minecraft:obsidian
setblock ~53~18~16 minecraft:obsidian
setblock ~53~19~16 minecraft:wool 15
fill ~54~18~16 ~55~18~16 minecraft:coal_block
fill ~54~19~16 ~54~19~18 minecraft:obsidian
setblock ~55~19~16 minecraft:wool 15
fill ~56~17~16 ~56~19~16 minecraft:obsidian
fill ~57~17~16 ~57~17~17 minecraft:wool 15
fill ~57~18~16 ~59~18~16 minecraft:coal_block
setblock ~58~17~16 minecraft:coal_block
fill ~59~17~16 ~59~17~17 minecraft:obsidian
fill ~60~16~16 ~61~16~17 minecraft:wool 15
fill ~60~17~16 ~61~17~16 minecraft:wool 15
fill ~60~18~16 ~60~18~17 minecraft:obsidian
fill ~62~16~16 ~62~16~17 minecraft:obsidian
setblock ~62~17~16 minecraft:obsidian
fill ~63~16~16 ~67~16~16 minecraft:wool 15
setblock ~63~17~16 minecraft:coal_block
setblock ~64~15~16 minecraft:coal_block
setblock ~64~17~16 minecraft:obsidian
fill ~65~15~16 ~67~15~16 minecraft:wool 15
fill ~68~14~16 ~69~14~16 minecraft:coal_block
fill ~68~15~16 ~69~15~18 minecraft:obsidian
fill ~68~16~16 ~68~16~17 minecraft:stained_hardened_clay 2
setblock ~69~16~16 minecraft:stained_hardened_clay 10
fill ~69~17~16 ~69~17~18 minecraft:stained_hardened_clay 2
fill ~70~14~16 ~70~14~19 minecraft:obsidian
fill ~70~15~16 ~71~15~16 minecraft:wool 15
fill ~70~18~16 ~70~18~25 minecraft:stained_hardened_clay 10
setblock ~71~14~16 minecraft:wool 15
fill ~71~19~16 ~71~19~26 minecraft:stained_hardened_clay 10
setblock ~72~13~16 minecraft:wool 15
fill ~72~14~16 ~72~15~16 minecraft:obsidian
fill ~73~13~16 ~74~13~17 minecraft:obsidian
setblock ~73~14~16 minecraft:wool 15
fill ~73~15~16 ~74~15~21 minecraft:stained_hardened_clay 10
fill ~74~14~16 ~75~14~16 minecraft:coal_block
fill ~74~19~16 ~74~19~25 minecraft:stained_hardened_clay 10
fill ~75~13~16 ~75~13~18 minecraft:coal_block
fill ~75~16~16 ~75~17~20 minecraft:stained_hardened_clay 10
setblock ~76~12~16 minecraft:coal_block
fill ~76~13~16 ~76~14~17 minecraft:obsidian
fill ~76~16~16 ~76~16~18 minecraft:stained_hardened_clay 2
setblock ~77~12~16 minecraft:obsidian
setblock ~77~13~16 minecraft:coal_block
setblock ~78~12~16 minecraft:wool 15
setblock ~78~13~16 minecraft:obsidian
fill ~78~16~16 ~78~16~25 minecraft:stained_hardened_clay 10
setblock ~79~12~16 minecraft:obsidian
fill ~79~13~16 ~80~13~16 minecraft:coal_block
fill ~79~14~16 ~79~14~21 minecraft:pink_glazed_terracotta 3
fill ~79~15~16 ~79~15~17 minecraft:concrete 10
fill ~79~17~16 ~79~17~26 minecraft:stained_hardened_clay 10
fill ~80~11~16 ~80~11~18 minecraft:obsidian
fill ~80~12~16 ~80~12~18 minecraft:coal_block
setblock ~81~11~16 minecraft:wool 15
fill ~81~12~16 ~83~12~16 minecraft:obsidian
setblock ~82~11~16 minecraft:coal_block
fill ~82~13~16 ~82~13~21 minecraft:stained_hardened_clay 10
setblock ~83~11~16 minecraft:wool 15
fill ~84~10~16 ~84~11~16 minecraft:coal_block
fill ~84~12~16 ~84~12~17 minecraft:wool 15
setblock ~84~14~16 minecraft:concrete 10
fill ~84~15~16 ~84~15~21 minecraft:stained_hardened_clay 10
setblock ~85~10~16 minecraft:obsidian
setblock ~85~11~16 minecraft:wool 15
fill ~86~10~16 ~86~11~17 minecraft:coal_block
setblock ~87~10~16 minecraft:obsidian
fill ~87~11~16 ~88~11~16 minecraft:wool 15
setblock ~87~12~16 minecraft:wool 15
fill ~88~12~16 ~88~12~17 minecraft:coal_block
fill ~89~10~16 ~89~10~17 minecraft:coal_block
fill ~89~11~16 ~89~11~18 minecraft:obsidian
setblock ~89~12~16 minecraft:wool 15
fill ~90~9~16 ~92~9~16 minecraft:obsidian
setblock ~90~10~16 minecraft:obsidian
setblock ~90~11~16 minecraft:coal_block
fill ~91~10~16 ~92~10~16 minecraft:wool 15
setblock ~92~8~16 minecraft:obsidian
fill ~93~8~16 ~94~8~16 minecraft:coal_block
fill ~93~9~16 ~93~9~18 minecraft:wool 15
setblock ~94~9~16 minecraft:coal_block
fill ~95~7~16 ~95~7~17 minecraft:wool 15
fill ~95~8~16 ~97~8~16 minecraft:wool 15
fill ~95~9~16 ~95~9~18 minecraft:obsidian
fill ~96~7~16 ~96~7~17 minecraft:coal_block
fill ~97~7~16 ~98~7~16 minecraft:wool 15
setblock ~98~6~16 minecraft:coal_block
setblock ~98~8~16 minecraft:obsidian
setblock ~99~6~16 minecraft:wool 15
setblock ~99~7~16 minecraft:obsidian
fill ~100~6~16 ~101~6~16 minecraft:obsidian
fill ~100~7~16 ~101~7~16 minecraft:wool 15
setblock ~102~5~16 minecraft:coal_block
fill ~102~6~16 ~103~6~16 minecraft:wool 15
fill ~102~7~16 ~102~7~19 minecraft:obsidian
setblock ~103~5~16 minecraft:wool 15
fill ~104~5~16 ~105~5~16 minecraft:obsidian
setblock ~104~6~16 minecraft:coal_block
setblock ~105~6~16 minecraft:obsidian
fill ~106~5~16 ~107~5~16 minecraft:coal_block
setblock ~106~6~16 minecraft:coal_block
fill ~107~6~16 ~107~6~17 minecraft:obsidian
setblock ~108~5~16 minecraft:obsidian
fill ~108~6~16 ~111~6~16 minecraft:coal_block
setblock ~109~5~16 minecraft:coal_block
setblock ~109~7~16 minecraft:obsidian
setblock ~110~7~16 minecraft:wool 15
fill ~111~7~16 ~111~7~17 minecraft:coal_block
setblock ~112~6~16 minecraft:obsidian
setblock ~112~7~16 minecraft:wool 15
fill ~113~6~16 ~114~6~16 minecraft:coal_block
fill ~113~7~16 ~113~7~17 minecraft:coal_block
fill ~114~7~16 ~114~7~17 minecraft:obsidian
fill ~114~8~16 ~115~8~16 minecraft:coal_block
setblock ~115~7~16 minecraft:coal_block
setblock ~116~7~16 minecraft:wool 15
fill ~116~8~16 ~117~8~16 minecraft:obsidian
fill ~117~7~16 ~117~7~17 minecraft:obsidian
fill ~117~9~16 ~118~9~16 minecraft:obsidian
setblock ~118~8~16 minecraft:wool 15
fill ~119~8~16 ~119~9~16 minecraft:coal_block
fill ~119~10~16 ~119~11~16 minecraft:obsidian
fill ~120~9~16 ~120~10~18 minecraft:coal_block
setblock ~120~11~16 minecraft:wool 15
fill ~120~12~16 ~121~12~16 minecraft:coal_block
fill ~121~11~16 ~122~11~16 minecraft:obsidian
fill ~122~10~16 ~123~10~17 minecraft:wool 15
setblock ~122~12~16 minecraft:obsidian
fill ~123~11~16 ~123~11~17 minecraft:wool 15
fill ~124~10~16 ~125~11~16 minecraft:coal_block
fill ~126~10~16 ~127~10~16 minecraft:obsidian
setblock ~126~11~16 minecraft:wool 15
setblock ~127~11~16 minecraft:coal_block
setblock ~128~10~16 minecraft:wool 15
setblock ~128~11~16 minecraft:obsidian
setblock ~129~10~16 minecraft:coal_block
fill ~129~11~16 ~130~11~16 minecraft:wool 15
setblock ~129~12~16 minecraft:obsidian
fill ~130~12~16 ~131~12~16 minecraft:coal_block
setblock ~131~11~16 minecraft:obsidian
fill ~132~11~16 ~133~11~16 minecraft:wool 15
fill ~132~12~16 ~133~12~16 minecraft:obsidian
setblock ~134~11~16 minecraft:obsidian
setblock ~134~12~16 minecraft:coal_block
fill ~135~11~16 ~135~11~17 minecraft:wool 15
fill ~135~12~16 ~136~12~16 minecraft:obsidian
fill ~136~11~16 ~137~11~17 minecraft:coal_block
fill ~137~12~16 ~139~12~16 minecraft:wool 15
fill ~138~11~16 ~139~11~16 minecraft:obsidian
setblock ~140~11~16 minecraft:coal_block
fill ~140~12~16 ~141~12~16 minecraft:obsidian
fill ~141~11~16 ~141~11~17 minecraft:obsidian
setblock ~142~11~16 minecraft:coal_block
setblock ~142~12~16 minecraft:wool 15
fill ~143~11~16 ~143~11~18 minecraft:wool 15
fill ~143~12~16 ~143~12~17 minecraft:coal_block
fill ~143~13~16 ~146~13~16 minecraft:wool 15
setblock ~144~12~16 minecraft:obsidian
fill ~145~12~16 ~145~12~18 minecraft:wool 15
setblock ~146~12~16 minecraft:obsidian
fill ~147~12~16 ~148~13~16 minecraft:coal_block
setblock ~149~12~16 minecraft:wool 15
setblock ~149~13~16 minecraft:coal_block
fill ~150~12~16 ~150~12~17 minecraft:obsidian
setblock ~150~13~16 minecraft:wool 15
setblock ~151~12~16 minecraft:wool 15
setblock ~151~13~16 minecraft:obsidian
fill ~152~12~16 ~152~13~16 minecraft:coal_block
fill ~153~12~16 ~153~12~17 minecraft:obsidian
fill ~153~13~16 ~153~13~17 minecraft:wool 15
setblock ~154~12~16 minecraft:wool 15
fill ~154~13~16 ~154~13~17 minecraft:coal_block
setblock ~155~12~16 minecraft:coal_block
setblock ~155~13~16 minecraft:obsidian
setblock ~156~12~16 minecraft:obsidian
fill ~156~13~16 ~157~13~16 minecraft:wool 15
fill ~156~14~16 ~160~14~16 minecraft:obsidian
setblock ~158~13~16 minecraft:coal_block
setblock ~159~13~16 minecraft:obsidian
setblock ~160~13~16 minecraft:wool 15
setblock ~161~13~16 minecraft:obsidian
fill ~161~14~16 ~162~14~16 minecraft:wool 15
setblock ~162~13~16 minecraft:coal_block
fill ~163~13~16 ~166~13~16 minecraft:wool 15
fill ~163~14~16 ~163~14~17 minecraft:coal_block
setblock ~164~14~16 minecraft:wool 15
fill ~165~14~16 ~166~14~16 minecraft:obsidian
fill ~167~13~16 ~167~13~20 minecraft:obsidian
fill ~167~14~16 ~167~14~17 minecraft:wool 15
fill ~168~13~16 ~168~14~17 minecraft:coal_block
setblock ~169~13~16 minecraft:obsidian
setblock ~169~14~16 minecraft:coal_block
fill ~8~29~17 ~8~30~17 minecraft:obsidian
fill ~9~29~17 ~9~29~21 minecraft:coal_block
setblock ~9~30~17 minecraft:coal_block
fill ~10~29~17 ~11~29~17 minecraft:wool 15
fill ~10~30~17 ~10~30~21 minecraft:wool 15
fill ~11~30~17 ~12~30~17 minecraft:obsidian
fill ~12~28~17 ~12~29~17 minecraft:coal_block
setblock ~13~29~17 minecraft:obsidian
setblock ~14~28~17 minecraft:obsidian
fill ~15~28~17 ~15~29~17 minecraft:wool 15
setblock ~16~28~17 minecraft:obsidian
setblock ~16~29~17 minecraft:coal_block
setblock ~17~27~17 minecraft:coal_block
fill ~17~28~17 ~17~28~18 minecraft:wool 15
setblock ~18~28~17 minecraft:obsidian
setblock ~19~28~17 minecraft:wool 15
fill ~20~26~17 ~20~27~18 minecraft:obsidian
setblock ~20~28~17 minecraft:obsidian
setblock ~21~27~17 minecraft:wool 15
fill ~22~26~17 ~22~26~18 minecraft:wool 15
setblock ~22~27~17 minecraft:coal_block
fill ~23~26~17 ~24~26~17 minecraft:coal_block
fill ~23~27~17 ~24~27~17 minecraft:obsidian
fill ~24~25~17 ~25~25~17 minecraft:coal_block
setblock ~25~26~17 minecraft:wool 15
fill ~26~25~17 ~26~26~17 minecraft:obsidian
fill ~27~25~17 ~28~25~17 minecraft:coal_block
setblock ~27~26~17 minecraft:obsidian
setblock ~28~26~17 minecraft:coal_block
fill ~29~25~17 ~29~25~19 minecraft:wool 15
fill ~31~24~17 ~31~24~18 minecraft:obsidian
setblock ~31~25~17 minecraft:obsidian
fill ~32~23~17 ~32~25~17 minecraft:coal_block
setblock ~33~24~17 minecraft:coal_block
setblock ~34~23~17 minecraft:wool 15
setblock ~34~24~17 minecraft:obsidian
fill ~35~23~17 ~35~23~18 minecraft:coal_block
setblock ~35~24~17 minecraft:wool 15
setblock ~37~22~17 minecraft:wool 15
setblock ~37~23~17 minecraft:coal_block
fill ~38~22~17 ~39~22~17 minecraft:coal_block
setblock ~38~23~17 minecraft:obsidian
fill ~39~23~17 ~40~23~17 minecraft:coal_block
setblock ~40~22~17 minecraft:wool 15
fill ~41~21~17 ~41~21~18 minecraft:obsidian
setblock ~41~22~17 minecraft:coal_block
setblock ~42~21~17 minecraft:coal_block
fill ~42~22~17 ~44~22~17 minecraft:obsidian
setblock ~44~20~17 minecraft:wool 15
setblock ~44~21~17 minecraft:obsidian
fill ~45~20~17 ~45~20~18 minecraft:coal_block
setblock ~45~21~17 minecraft:wool 15
fill ~46~20~17 ~47~20~17 minecraft:wool 15
fill ~46~21~17 ~47~21~17 minecraft:coal_block
fill ~48~19~17 ~49~19~17 minecraft:coal_block
fill ~48~20~17 ~48~20~19 minecraft:coal_block
setblock ~48~21~17 minecraft:obsidian
setblock ~49~20~17 minecraft:obsidian
fill ~50~19~17 ~51~19~17 minecraft:obsidian
setblock ~50~20~17 minecraft:coal_block
fill ~51~20~17 ~51~20~19 minecraft:obsidian
setblock ~52~20~17 minecraft:wool 15
fill ~53~18~17 ~54~18~18 minecraft:coal_block
setblock ~53~19~17 minecraft:coal_block
setblock ~55~18~17 minecraft:obsidian
fill ~55~19~17 ~56~19~17 minecraft:coal_block
setblock ~56~17~17 minecraft:coal_block
setblock ~56~18~17 minecraft:wool 15
fill ~57~18~17 ~58~18~17 minecraft:coal_block
setblock ~58~17~17 minecraft:obsidian
setblock ~59~18~17 minecraft:wool 15
setblock ~60~17~17 minecraft:wool 15
setblock ~61~17~17 minecraft:obsidian
fill ~62~17~17 ~64~17~17 minecraft:wool 15
fill ~63~16~17 ~66~16~17 minecraft:obsidian
fill ~64~15~17 ~67~15~17 minecraft:obsidian
setblock ~67~16~17 minecraft:wool 15
setblock ~68~14~17 minecraft:obsidian
setblock ~69~14~17 minecraft:wool 15
setblock ~70~15~17 minecraft:obsidian
setblock ~71~14~17 minecraft:coal_block
setblock ~71~15~17 minecraft:wool 15
setblock ~72~13~17 minecraft:coal_block
setblock ~72~14~17 minecraft:wool 15
setblock ~72~15~17 minecraft:obsidian
fill ~72~20~17 ~73~20~25 minecraft:stained_hardened_clay 10
fill ~73~14~17 ~73~14~18 minecraft:obsidian
setblock ~74~14~17 minecraft:coal_block
fill ~75~14~17 ~75~14~18 minecraft:obsidian
fill ~75~18~17 ~75~18~23 minecraft:stained_hardened_clay 10
setblock ~76~12~17 minecraft:obsidian
fill ~77~12~17 ~77~12~18 minecraft:wool 15
fill ~77~13~17 ~77~13~18 minecraft:obsidian
fill ~77~16~17 ~77~16~19 minecraft:stained_hardened_clay 2
setblock ~78~12~17 minecraft:obsidian
fill ~78~13~17 ~79~13~18 minecraft:wool 15
setblock ~79~12~17 minecraft:wool 15
fill ~80~13~17 ~80~13~18 minecraft:coal_block
fill ~80~18~17 ~81~18~25 minecraft:stained_hardened_clay 10
setblock ~81~11~17 minecraft:coal_block
setblock ~81~12~17 minecraft:wool 15
fill ~81~13~17 ~81~13~22 minecraft:stained_hardened_clay 10
fill ~82~11~17 ~83~11~17 minecraft:obsidian
setblock ~82~12~17 minecraft:obsidian
setblock ~83~12~17 minecraft:wool 15
fill ~84~10~17 ~84~10~18 minecraft:obsidian
fill ~84~11~17 ~85~11~17 minecraft:coal_block
fill ~84~14~17 ~84~14~19 minecraft:purple_glazed_terracotta 3
setblock ~85~10~17 minecraft:wool 15
fill ~85~14~17 ~85~14~19 minecraft:stained_hardened_clay 2
fill ~87~10~17 ~87~10~21 minecraft:wool 15
setblock ~87~11~17 minecraft:wool 15
setblock ~87~12~17 minecraft:coal_block
setblock ~88~11~17 minecraft:coal_block
setblock ~89~12~17 minecraft:coal_block
fill ~90~9~17 ~91~9~17 minecraft:coal_block
fill ~90~10~17 ~90~10~18 minecraft:wool 15
setblock ~90~11~17 minecraft:obsidian
fill ~91~10~17 ~92~10~17 minecraft:obsidian
fill ~91~11~17 ~92~11~159 minecraft:nether_brick
setblock ~92~8~17 minecraft:coal_block
fill ~92~9~17 ~92~9~18 minecraft:obsidian
setblock ~93~8~17 minecraft:obsidian
fill ~93~12~17 ~94~12~159 minecraft:nether_brick
setblock ~94~8~17 minecraft:coal_block
setblock ~94~9~17 minecraft:obsidian
fill ~95~8~17 ~96~8~17 minecraft:obsidian
fill ~95~13~17 ~97~13~159 minecraft:nether_brick
setblock ~97~7~17 minecraft:coal_block
fill ~97~8~17 ~98~8~17 minecraft:wool 15
fill ~98~6~17 ~98~7~17 minecraft:obsidian
fill ~98~14~17 ~100~14~159 minecraft:nether_brick
setblock ~99~6~17 minecraft:coal_block
fill ~99~7~17 ~100~7~17 minecraft:wool 15
setblock ~100~6~17 minecraft:obsidian
fill ~101~6~17 ~102~6~17 minecraft:coal_block
setblock ~101~7~17 minecraft:obsidian
fill ~101~15~17 ~107~15~159 minecraft:nether_brick
fill ~102~5~17 ~102~5~18 minecraft:wool 15
fill ~103~5~17 ~105~5~17 minecraft:coal_block
setblock ~103~6~17 minecraft:wool 15
setblock ~104~6~17 minecraft:obsidian
setblock ~105~6~17 minecraft:wool 15
setblock ~106~5~17 minecraft:wool 15
setblock ~106~6~17 minecraft:obsidian
fill ~107~5~17 ~107~5~18 minecraft:obsidian
fill ~108~5~17 ~108~5~18 minecraft:coal_block
fill ~108~6~17 ~110~6~17 minecraft:obsidian
fill ~108~14~17 ~109~14~159 minecraft:nether_brick
fill ~109~5~17 ~109~5~18 minecraft:wool 15
fill ~109~7~17 ~109~7~18 minecraft:coal_block
setblock ~110~7~17 minecraft:obsidian
fill ~110~13~17 ~111~13~159 minecraft:nether_brick
fill ~111~6~17 ~111~6~20 minecraft:coal_block
fill ~111~12~17 ~113~12~159 minecraft:nether_brick
fill ~112~6~17 ~113~6~17 minecraft:wool 15
fill ~112~7~17 ~112~7~18 minecraft:coal_block
fill ~114~6~17 ~114~6~18 minecraft:coal_block
fill ~114~8~17 ~114~8~18 minecraft:wool 15
fill ~114~11~17 ~115~11~159 minecraft:nether_brick
setblock ~115~7~17 minecraft:wool 15
setblock ~115~8~17 minecraft:obsidian
fill ~116~7~17 ~116~8~17 minecraft:coal_block
fill ~116~10~17 ~118~10~159 minecraft:nether_brick
setblock ~117~8~17 minecraft:wool 15
fill ~117~9~17 ~117~9~19 minecraft:coal_block
setblock ~118~8~17 minecraft:coal_block
fill ~118~9~17 ~118~9~18 minecraft:wool 15
setblock ~119~8~17 minecraft:wool 15
setblock ~119~9~17 minecraft:coal_block
fill ~119~10~17 ~119~10~18 minecraft:wool 15
fill ~119~11~17 ~120~11~17 minecraft:coal_block
fill ~120~12~17 ~121~12~17 minecraft:obsidian
fill ~121~11~17 ~122~11~17 minecraft:wool 15
setblock ~122~12~17 minecraft:coal_block
setblock ~124~10~17 minecraft:obsidian
setblock ~124~11~17 minecraft:wool 15
setblock ~125~10~17 minecraft:coal_block
fill ~125~11~17 ~127~11~17 minecraft:obsidian
setblock ~126~10~17 minecraft:obsidian
setblock ~127~10~17 minecraft:wool 15
setblock ~128~10~17 minecraft:obsidian
setblock ~128~11~17 minecraft:coal_block
fill ~129~10~17 ~129~10~22 minecraft:wool 15
fill ~129~11~17 ~129~12~17 minecraft:wool 15
fill ~130~11~17 ~130~12~17 minecraft:obsidian
setblock ~131~11~17 minecraft:wool 15
setblock ~131~12~17 minecraft:obsidian
setblock ~132~11~17 minecraft:obsidian
fill ~132~12~17 ~134~12~17 minecraft:wool 15
fill ~133~11~17 ~134~11~18 minecraft:wool 15
setblock ~135~12~17 minecraft:coal_block
setblock ~136~12~17 minecraft:wool 15
fill ~137~12~17 ~137~12~19 minecraft:obsidian
fill ~138~11~17 ~139~11~17 minecraft:wool 15
setblock ~138~12~17 minecraft:coal_block
setblock ~139~12~17 minecraft:wool 15
setblock ~140~11~17 minecraft:obsidian
setblock ~140~12~17 minecraft:coal_block
setblock ~141~12~17 minecraft:wool 15
fill ~142~11~17 ~142~11~18 minecraft:wool 15
fill ~142~12~17 ~142~12~18 minecraft:obsidian
fill ~143~13~17 ~143~13~20 minecraft:obsidian
setblock ~144~12~17 minecraft:wool 15
fill ~144~13~17 ~144~13~18 minecraft:coal_block
fill ~145~13~17 ~145~13~18 minecraft:obsidian
fill ~146~12~17 ~147~12~17 minecraft:coal_block
fill ~146~13~17 ~147~13~17 minecraft:wool 15
fill ~148~12~17 ~149~12~17 minecraft:obsidian
fill ~148~13~17 ~148~13~22 minecraft:obsidian
fill ~149~13~17 ~149~13~18 minecraft:wool 15
setblock ~150~13~17 minecraft:coal_block
fill ~151~12~17 ~151~12~18 minecraft:obsidian
fill ~151~13~17 ~152~13~17 minecraft:wool 15
setblock ~152~12~17 minecraft:wool 15
fill ~154~12~17 ~155~12~17 minecraft:obsidian
fill ~155~13~17 ~156~13~17 minecraft:wool 15
fill ~156~12~17 ~156~12~19 minecraft:wool 15
setblock ~156~14~17 minecraft:coal_block
fill ~157~13~17 ~158~14~17 minecraft:obsidian
fill ~159~13~17 ~159~13~18 minecraft:coal_block
fill ~159~14~17 ~160~14~17 minecraft:wool 15
setblock ~160~13~17 minecraft:obsidian
fill ~161~13~17 ~163~13~17 minecraft:wool 15
setblock ~161~14~17 minecraft:obsidian
fill ~162~14~17 ~162~14~18 minecraft:coal_block
fill ~164~13~17 ~164~13~20 minecraft:obsidian
setblock ~164~14~17 minecraft:obsidian
fill ~165~13~17 ~166~13~18 minecraft:wool 15
fill ~165~14~17 ~166~14~17 minecraft:wool 15
fill ~169~13~17 ~169~14~18 minecraft:wool 15
fill ~8~29~18 ~8~30~18 minecraft:wool 15
setblock ~9~30~18 minecraft:obsidian
fill ~10~29~18 ~12~29~18 minecraft:obsidian
setblock ~11~30~18 minecraft:obsidian
fill ~11~31~18 ~14~31~18 minecraft:wood 1
setblock ~12~28~18 minecraft:wool 15
setblock ~12~30~18 minecraft:coal_block
setblock ~13~29~18 minecraft:wool 15
setblock ~13~30~18 minecraft:wood 1
fill ~14~28~18 ~16~28~18 minecraft:coal_block
fill ~14~30~18 ~15~30~18 minecraft:wool 12
setblock ~15~29~18 minecraft:obsidian
setblock ~16~29~18 minecraft:wool 15
setblock ~16~30~18 minecraft:concrete 12
setblock ~16~32~18 minecraft:wool 12
setblock ~17~27~18 minecraft:obsidian
setblock ~17~29~18 minecraft:wood 3
setblock ~17~32~18 minecraft:stained_hardened_clay 12
setblock ~18~27~18 minecraft:wool 15
fill ~18~28~18 ~18~28~19 minecraft:coal_block
setblock ~18~29~18 minecraft:wool 12
fill ~18~31~18 ~18~32~18 minecraft:planks 5
setblock ~19~28~18 minecraft:obsidian
fill ~19~29~18 ~19~30~18 minecraft:soul_sand
setblock ~19~31~18 minecraft:wood 5
setblock ~19~32~18 minecraft:planks 5
fill ~19~34~18 ~19~34~19 minecraft:wood 3
fill ~20~28~18 ~20~28~20 minecraft:coal_block
fill ~20~29~18 ~20~30~18 minecraft:concrete 12
fill ~20~32~18 ~20~32~19 minecraft:wood 5
fill ~20~34~18 ~22~34~18 minecraft:wood 0
fill ~21~26~18 ~21~27~18 minecraft:obsidian
fill ~21~28~18 ~22~28~18 minecraft:wool 12
setblock ~21~30~18 minecraft:soul_sand
setblock ~21~32~18 minecraft:planks 5
setblock ~22~27~18 minecraft:wool 15
setblock ~22~30~18 minecraft:planks 5
fill ~22~35~18 ~22~35~19 minecraft:wood 0
fill ~23~26~18 ~24~26~18 minecraft:wool 15
fill ~23~27~18 ~23~27~19 minecraft:coal_block
fill ~23~28~18 ~24~28~18 minecraft:soul_sand
setblock ~23~30~18 minecraft:stained_hardened_clay 12
setblock ~23~31~18 minecraft:planks 5
fill ~23~33~18 ~24~33~19 minecraft:wood 1
setblock ~23~35~18 minecraft:planks 1
fill ~24~25~18 ~24~25~20 minecraft:obsidian
setblock ~24~27~18 minecraft:wool 15
setblock ~24~30~18 minecraft:planks 5
setblock ~24~31~18 minecraft:stained_hardened_clay 12
fill ~24~37~18 ~25~37~18 minecraft:stained_hardened_clay 12
fill ~25~25~18 ~26~25~18 minecraft:coal_block
setblock ~25~26~18 minecraft:obsidian
setblock ~25~27~18 minecraft:soul_sand
setblock ~25~29~18 minecraft:soul_sand
setblock ~25~31~18 minecraft:planks 5
setblock ~25~33~18 minecraft:wood 0
fill ~25~36~18 ~25~36~19 minecraft:planks 5
setblock ~26~26~18 minecraft:coal_block
setblock ~26~27~18 minecraft:concrete 12
setblock ~26~29~18 minecraft:wood 5
fill ~26~31~18 ~26~31~19 minecraft:wood 5
fill ~26~33~18 ~27~33~19 minecraft:planks 1
fill ~26~35~18 ~27~35~18 minecraft:wood 3
fill ~26~37~18 ~26~37~19 minecraft:wood 5
setblock ~26~39~18 minecraft:concrete 12
fill ~27~25~18 ~28~25~18 minecraft:wool 15
setblock ~27~26~18 minecraft:wool 15
setblock ~27~27~18 minecraft:wood 3
setblock ~27~29~18 minecraft:planks 5
fill ~27~30~18 ~28~30~18 minecraft:wood 5
fill ~27~31~18 ~28~31~18 minecraft:wood 1
fill ~27~38~18 ~27~38~20 minecraft:wood 5
setblock ~27~39~18 minecraft:soul_sand
fill ~28~24~18 ~28~24~21 minecraft:obsidian
setblock ~28~26~18 minecraft:obsidian
setblock ~28~27~18 minecraft:wool 12
fill ~28~28~18 ~28~28~19 minecraft:planks 5
fill ~28~32~18 ~29~32~19 minecraft:wood 1
setblock ~28~35~18 minecraft:soul_sand
fill ~28~37~18 ~29~37~18 minecraft:wood 5
setblock ~28~39~18 minecraft:wood 3
fill ~29~24~18 ~30~24~18 minecraft:wool 15
setblock ~29~26~18 minecraft:wood 3
fill ~29~28~18 ~30~28~18 minecraft:wood 5
setblock ~29~30~18 minecraft:concrete 12
fill ~29~34~18 ~29~34~19 minecraft:wood 0
setblock ~29~39~18 minecraft:wool 12
fill ~30~25~18 ~31~25~18 minecraft:coal_block
setblock ~30~26~18 minecraft:stained_hardened_clay 12
fill ~30~30~18 ~30~30~19 minecraft:wood 1
fill ~30~32~18 ~31~32~18 minecraft:wood 0
setblock ~30~34~18 minecraft:wood 3
fill ~30~36~18 ~31~36~18 minecraft:wood 5
setblock ~30~38~18 minecraft:wool 12
fill ~31~26~18 ~32~26~18 minecraft:planks 5
fill ~31~28~18 ~31~28~19 minecraft:planks 5
setblock ~31~29~18 minecraft:concrete 12
setblock ~31~34~18 minecraft:stained_hardened_clay 12
setblock ~31~38~18 minecraft:soul_sand
setblock ~32~23~18 minecraft:obsidian
fill ~32~24~18 ~32~25~18 minecraft:wool 15
setblock ~32~29~18 minecraft:stained_hardened_clay 12
fill ~32~31~18 ~34~31~19 minecraft:wood 1
setblock ~32~33~18 minecraft:wood 0
fill ~32~34~18 ~32~34~19 minecraft:wood 5
fill ~32~36~18 ~33~36~18 minecraft:planks 5
fill ~32~38~18 ~32~38~19 minecraft:concrete 12
setblock ~33~23~18 minecraft:coal_block
setblock ~33~24~18 minecraft:obsidian
setblock ~33~25~18 minecraft:stained_hardened_clay 12
setblock ~33~27~18 minecraft:wool 12
fill ~33~29~18 ~37~29~18 minecraft:wood 1
fill ~33~33~18 ~33~33~19 minecraft:planks 1
setblock ~33~35~18 minecraft:wood 5
setblock ~33~38~18 minecraft:soul_sand
setblock ~34~23~18 minecraft:obsidian
setblock ~34~24~18 minecraft:coal_block
setblock ~34~25~18 minecraft:wood 5
setblock ~34~27~18 minecraft:wood 3
setblock ~34~33~18 minecraft:wood 3
setblock ~34~35~18 minecraft:planks 5
setblock ~34~37~18 minecraft:wood 3
setblock ~35~24~18 minecraft:obsidian
setblock ~35~25~18 minecraft:planks 5
setblock ~35~27~18 minecraft:soul_sand
fill ~35~31~18 ~36~31~18 minecraft:wood 0
setblock ~35~33~18 minecraft:stained_hardened_clay 12
setblock ~35~35~18 minecraft:wood 5
setblock ~35~37~18 minecraft:soul_sand
fill ~36~22~18 ~38~22~19 minecraft:coal_block
setblock ~36~23~18 minecraft:coal_block
setblock ~36~24~18 minecraft:wool 15
setblock ~36~25~18 minecraft:stained_hardened_clay 12
setblock ~36~27~18 minecraft:concrete 12
fill ~36~33~18 ~37~33~18 minecraft:wood 5
fill ~36~35~18 ~37~35~18 minecraft:soul_sand
setblock ~36~37~18 minecraft:wool 12
setblock ~37~23~18 minecraft:obsidian
setblock ~37~24~18 minecraft:stained_hardened_clay 12
fill ~37~26~18 ~37~27~18 minecraft:wool 12
setblock ~37~31~18 minecraft:concrete 12
setblock ~37~37~18 minecraft:wood 0
fill ~38~23~18 ~39~23~18 minecraft:coal_block
setblock ~38~24~18 minecraft:planks 5
fill ~38~26~18 ~39~26~18 minecraft:wood 3
fill ~38~28~18 ~41~28~19 minecraft:wood 1
fill ~38~30~18 ~38~30~19 minecraft:planks 1
setblock ~38~31~18 minecraft:wood 5
fill ~38~32~18 ~39~32~18 minecraft:stained_hardened_clay 12
setblock ~38~34~18 minecraft:planks 5
setblock ~38~35~18 minecraft:concrete 12
setblock ~38~37~18 minecraft:planks 1
fill ~39~22~18 ~41~22~18 minecraft:obsidian
setblock ~39~24~18 minecraft:stained_hardened_clay 12
setblock ~39~30~18 minecraft:soul_sand
setblock ~39~34~18 minecraft:concrete 12
setblock ~39~36~18 minecraft:planks 1
setblock ~40~21~18 minecraft:obsidian
fill ~40~23~18 ~40~23~19 minecraft:wool 15
setblock ~40~24~18 minecraft:soul_sand
setblock ~40~26~18 minecraft:wool 12
fill ~40~30~18 ~41~30~18 minecraft:concrete 12
fill ~40~32~18 ~41~32~19 minecraft:wood 5
setblock ~40~34~18 minecraft:wood 3
fill ~40~36~18 ~41~36~18 minecraft:wood 0
fill ~41~23~18 ~41~23~19 minecraft:wood 5
setblock ~41~25~18 minecraft:wool 12
fill ~41~26~18 ~41~26~19 minecraft:wood 3
setblock ~41~34~18 minecraft:concrete 12
setblock ~42~21~18 minecraft:obsidian
setblock ~42~22~18 minecraft:wool 15
setblock ~42~23~18 minecraft:stained_hardened_clay 12
setblock ~42~25~18 minecraft:concrete 12
fill ~42~27~18 ~44~27~19 minecraft:wood 1
setblock ~42~30~18 minecraft:wood 5
fill ~42~32~18 ~43~32~18 minecraft:stained_hardened_clay 12
setblock ~42~34~18 minecraft:wood 3
fill ~42~36~18 ~43~36~18 minecraft:planks 1
fill ~43~21~18 ~43~21~19 minecraft:coal_block
fill ~43~22~18 ~44~22~19 minecraft:obsidian
fill ~43~23~18 ~44~23~18 minecraft:wood 5
setblock ~43~25~18 minecraft:wood 3
fill ~43~29~18 ~43~29~19 minecraft:concrete 12
fill ~43~31~18 ~45~31~18 minecraft:planks 5
fill ~43~34~18 ~43~34~19 minecraft:wool 12
fill ~44~20~18 ~44~20~19 minecraft:obsidian
setblock ~44~21~18 minecraft:wool 15
setblock ~44~24~18 minecraft:wood 5
fill ~44~26~18 ~44~26~19 minecraft:concrete 12
setblock ~44~29~18 minecraft:wool 12
setblock ~44~33~18 minecraft:soul_sand
setblock ~44~34~18 minecraft:wood 0
setblock ~44~35~18 minecraft:planks 1
fill ~45~21~18 ~46~21~18 minecraft:coal_block
setblock ~45~22~18 minecraft:wool 12
setblock ~45~24~18 minecraft:wood 3
fill ~45~26~18 ~45~26~19 minecraft:wood 3
setblock ~45~28~18 minecraft:wood 3
setblock ~45~29~18 minecraft:soul_sand
fill ~45~33~18 ~51~33~19 minecraft:wood 1
fill ~45~35~18 ~47~35~18 minecraft:wood 0
setblock ~46~20~18 minecraft:wool 15
fill ~46~22~18 ~47~22~18 minecraft:stained_hardened_clay 12
setblock ~46~24~18 minecraft:stained_hardened_clay 12
fill ~46~26~18 ~46~26~19 minecraft:wood 1
setblock ~46~28~18 minecraft:soul_sand
setblock ~46~29~18 minecraft:wood 3
fill ~46~31~18 ~46~31~19 minecraft:stained_hardened_clay 12
fill ~47~20~18 ~47~21~18 minecraft:obsidian
setblock ~47~24~18 minecraft:wood 3
fill ~47~25~18 ~50~25~19 minecraft:wood 1
fill ~47~27~18 ~47~27~19 minecraft:wood 1
setblock ~47~28~18 minecraft:concrete 12
fill ~47~29~18 ~47~29~19 minecraft:wood 5
setblock ~47~31~18 minecraft:planks 5
setblock ~48~19~18 minecraft:obsidian
setblock ~48~21~18 minecraft:wool 15
fill ~48~22~18 ~48~22~19 minecraft:wood 5
fill ~48~23~18 ~49~23~18 minecraft:planks 5
fill ~48~27~18 ~48~27~19 minecraft:soul_sand
setblock ~48~29~18 minecraft:soul_sand
fill ~48~31~18 ~50~31~18 minecraft:concrete 12
fill ~48~35~18 ~49~35~18 minecraft:planks 1
fill ~49~19~18 ~49~20~18 minecraft:wool 15
setblock ~49~21~18 minecraft:planks 5
fill ~49~27~18 ~49~27~19 minecraft:wood 3
setblock ~49~29~18 minecraft:wool 12
setblock ~50~19~18 minecraft:coal_block
setblock ~50~20~18 minecraft:wool 15
setblock ~50~21~18 minecraft:wool 12
setblock ~50~23~18 minecraft:soul_sand
setblock ~50~27~18 minecraft:concrete 12
setblock ~50~29~18 minecraft:wood 3
fill ~50~35~18 ~50~35~19 minecraft:wood 0
fill ~51~19~18 ~52~19~18 minecraft:wool 15
fill ~51~21~18 ~52~21~18 minecraft:concrete 12
fill ~51~23~18 ~51~23~19 minecraft:concrete 12
setblock ~51~24~18 minecraft:concrete 12
fill ~51~26~18 ~53~26~19 minecraft:wood 1
fill ~51~29~18 ~51~29~19 minecraft:wood 5
setblock ~51~31~18 minecraft:stained_hardened_clay 12
fill ~51~34~18 ~54~34~18 minecraft:wood 0
setblock ~52~18~18 minecraft:obsidian
setblock ~52~20~18 minecraft:obsidian
setblock ~52~22~18 minecraft:wool 12
fill ~52~24~18 ~53~24~18 minecraft:wood 3
setblock ~52~28~18 minecraft:concrete 12
setblock ~52~31~18 minecraft:soul_sand
fill ~52~32~18 ~60~32~19 minecraft:wood 1
setblock ~53~19~18 minecraft:obsidian
fill ~53~20~18 ~54~20~18 minecraft:wool 12
fill ~53~22~18 ~55~22~18 minecraft:wood 5
setblock ~53~28~18 minecraft:wood 5
setblock ~53~30~18 minecraft:planks 5
setblock ~54~24~18 minecraft:wool 12
setblock ~54~26~18 minecraft:wood 3
setblock ~54~28~18 minecraft:wood 3
setblock ~54~30~18 minecraft:wool 12
setblock ~55~18~18 minecraft:wool 15
setblock ~55~19~18 minecraft:obsidian
fill ~55~20~18 ~56~20~18 minecraft:wood 5
setblock ~55~24~18 minecraft:wood 3
fill ~55~26~18 ~55~26~19 minecraft:concrete 12
setblock ~55~28~18 minecraft:soul_sand
setblock ~55~30~18 minecraft:wood 3
fill ~55~34~18 ~57~34~18 minecraft:planks 1
fill ~56~17~18 ~57~17~18 minecraft:obsidian
setblock ~56~18~18 minecraft:coal_block
setblock ~56~19~18 minecraft:wool 15
setblock ~56~21~18 minecraft:planks 5
setblock ~56~22~18 minecraft:stained_hardened_clay 12
fill ~56~24~18 ~56~24~19 minecraft:concrete 12
fill ~56~25~18 ~58~25~18 minecraft:concrete 12
setblock ~56~28~18 minecraft:wool 12
setblock ~56~30~18 minecraft:concrete 12
fill ~57~18~18 ~58~18~18 minecraft:wool 15
fill ~57~19~18 ~62~19~18 minecraft:concrete 12
setblock ~57~21~18 minecraft:wood 5
setblock ~57~23~18 minecraft:concrete 12
fill ~57~28~18 ~57~28~19 minecraft:stained_hardened_clay 12
fill ~57~30~18 ~57~30~19 minecraft:wood 5
fill ~58~17~18 ~58~17~20 minecraft:wool 15
fill ~58~21~18 ~59~21~18 minecraft:stained_hardened_clay 12
fill ~58~23~18 ~59~23~18 minecraft:wool 12
setblock ~58~28~18 minecraft:wool 12
fill ~58~30~18 ~59~30~18 minecraft:wood 3
fill ~58~34~18 ~58~34~19 minecraft:wood 0
fill ~59~17~18 ~59~18~18 minecraft:coal_block
fill ~59~25~18 ~60~25~18 minecraft:wool 12
fill ~59~27~18 ~61~27~18 minecraft:soul_sand
setblock ~59~28~18 minecraft:wood 3
fill ~59~33~18 ~63~33~18 minecraft:wood 1
setblock ~60~16~18 minecraft:coal_block
setblock ~60~17~18 minecraft:obsidian
fill ~60~18~18 ~60~18~19 minecraft:wool 15
fill ~60~21~18 ~61~21~18 minecraft:planks 5
setblock ~60~23~18 minecraft:soul_sand
setblock ~60~28~18 minecraft:soul_sand
fill ~60~30~18 ~60~30~19 minecraft:concrete 12
fill ~60~31~18 ~61~31~19 minecraft:wood 1
fill ~61~16~18 ~61~16~19 minecraft:obsidian
fill ~61~17~18 ~62~17~18 minecraft:wool 15
setblock ~61~23~18 minecraft:wood 5
setblock ~61~24~18 minecraft:wool 12
fill ~61~29~18 ~62~29~18 minecraft:wood 5
setblock ~62~16~18 minecraft:coal_block
setblock ~62~20~18 minecraft:stained_hardened_clay 12
fill ~62~22~18 ~62~22~19 minecraft:wood 5
setblock ~62~24~18 minecraft:soul_sand
fill ~62~27~18 ~62~27~19 minecraft:concrete 12
setblock ~62~31~18 minecraft:wool 12
fill ~63~16~18 ~65~16~18 minecraft:wool 15
fill ~63~17~18 ~64~17~18 minecraft:coal_block
setblock ~63~20~18 minecraft:wool 12
setblock ~63~22~18 minecraft:planks 5
fill ~63~24~18 ~64~24~18 minecraft:wood 3
fill ~63~27~18 ~64~27~18 minecraft:soul_sand
setblock ~63~29~18 minecraft:planks 5
setblock ~63~31~18 minecraft:soul_sand
fill ~64~15~18 ~65~15~18 minecraft:coal_block
setblock ~64~20~18 minecraft:soul_sand
setblock ~64~22~18 minecraft:stained_hardened_clay 12
setblock ~64~29~18 minecraft:concrete 12
setblock ~64~31~18 minecraft:concrete 12
fill ~64~33~18 ~65~33~18 minecraft:planks 1
fill ~65~20~18 ~65~20~19 minecraft:wood 3
setblock ~65~22~18 minecraft:wood 5
setblock ~65~24~18 minecraft:concrete 12
fill ~65~27~18 ~66~27~18 minecraft:concrete 12
setblock ~65~29~18 minecraft:soul_sand
fill ~65~31~18 ~67~31~18 minecraft:planks 1
setblock ~66~15~18 minecraft:obsidian
fill ~66~16~18 ~66~16~19 minecraft:coal_block
setblock ~66~20~18 minecraft:concrete 12
fill ~66~22~18 ~66~23~18 minecraft:planks 5
fill ~66~25~18 ~67~25~18 minecraft:soul_sand
fill ~66~29~18 ~66~29~19 minecraft:wood 1
setblock ~66~33~18 minecraft:wood 0
setblock ~67~15~18 minecraft:wool 15
setblock ~67~16~18 minecraft:obsidian
setblock ~67~20~18 minecraft:wool 12
fill ~67~21~18 ~68~21~18 minecraft:soul_sand
fill ~67~23~18 ~68~23~18 minecraft:planks 5
setblock ~67~27~18 minecraft:wood 3
fill ~67~29~18 ~67~29~19 minecraft:wood 5
fill ~67~33~18 ~67~33~19 minecraft:planks 1
fill ~68~14~18 ~68~14~24 minecraft:wool 15
setblock ~68~16~18 minecraft:coal_block
fill ~68~17~18 ~68~17~19 minecraft:stained_hardened_clay 2
setblock ~68~25~18 minecraft:concrete 12
fill ~68~27~18 ~68~27~19 minecraft:concrete 12
fill ~68~28~18 ~69~28~18 minecraft:wood 5
setblock ~68~29~18 minecraft:planks 5
fill ~68~31~18 ~69~31~18 minecraft:soul_sand
fill ~68~33~18 ~70~33~18 minecraft:wood 0
setblock ~69~14~18 minecraft:obsidian
fill ~69~16~18 ~69~16~22 minecraft:stained_hardened_clay 10
fill ~69~18~18 ~69~18~19 minecraft:stained_hardened_clay 2
fill ~69~21~18 ~69~21~19 minecraft:wool 12
setblock ~69~23~18 minecraft:stained_hardened_clay 12
fill ~69~25~18 ~70~25~18 minecraft:wool 12
fill ~69~29~18 ~69~29~19 minecraft:wood 5
setblock ~70~15~18 minecraft:wool 15
fill ~70~19~18 ~70~19~25 minecraft:stained_hardened_clay 10
fill ~70~21~18 ~72~21~18 minecraft:wood 3
setblock ~70~23~18 minecraft:planks 5
setblock ~70~28~18 minecraft:stained_hardened_clay 12
fill ~70~29~18 ~70~29~19 minecraft:planks 5
setblock ~70~31~18 minecraft:wool 12
fill ~71~14~18 ~72~14~18 minecraft:obsidian
setblock ~71~15~18 minecraft:obsidian
fill ~71~20~18 ~71~20~25 minecraft:stained_hardened_clay 10
fill ~71~23~18 ~72~23~18 minecraft:stained_hardened_clay 12
fill ~71~25~18 ~72~25~18 minecraft:wood 3
setblock ~71~28~18 minecraft:planks 5
fill ~71~29~18 ~73~29~18 minecraft:wood 5
setblock ~71~31~18 minecraft:soul_sand
setblock ~71~33~18 minecraft:planks 1
setblock ~72~13~18 minecraft:wool 15
setblock ~72~15~18 minecraft:coal_block
setblock ~72~27~18 minecraft:concrete 12
setblock ~72~31~18 minecraft:concrete 12
setblock ~72~34~18 minecraft:planks 1
setblock ~73~13~18 minecraft:obsidian
setblock ~73~21~18 minecraft:wool 12
fill ~73~22~18 ~73~23~18 minecraft:wood 5
fill ~73~25~18 ~73~25~19 minecraft:concrete 12
setblock ~73~27~18 minecraft:wood 3
setblock ~73~31~18 minecraft:planks 5
setblock ~73~32~18 minecraft:soul_sand
setblock ~73~34~18 minecraft:wood 0
setblock ~74~13~18 minecraft:wool 15
fill ~74~14~18 ~74~14~19 minecraft:obsidian
fill ~74~20~18 ~74~20~23 minecraft:stained_hardened_clay 10
setblock ~74~22~18 minecraft:wood 3
setblock ~74~24~18 minecraft:soul_sand
setblock ~74~25~18 minecraft:wood 3
setblock ~74~27~18 minecraft:wool 12
setblock ~74~29~18 minecraft:stained_hardened_clay 12
fill ~74~30~18 ~75~30~18 minecraft:planks 5
setblock ~74~32~18 minecraft:wood 3
setblock ~74~34~18 minecraft:planks 1
fill ~75~19~18 ~75~19~23 minecraft:stained_hardened_clay 10
setblock ~75~22~18 minecraft:wood 5
fill ~75~24~18 ~75~24~19 minecraft:stained_hardened_clay 12
fill ~75~26~18 ~75~26~19 minecraft:wood 3
fill ~75~27~18 ~75~27~19 minecraft:concrete 12
setblock ~75~28~18 minecraft:wool 12
fill ~75~32~18 ~75~32~19 minecraft:wool 12
setblock ~75~34~18 minecraft:wood 0
fill ~76~12~18 ~76~12~20 minecraft:coal_block
fill ~76~13~18 ~76~13~20 minecraft:wool 15
fill ~76~14~18 ~76~14~21 minecraft:obsidian
setblock ~76~22~18 minecraft:concrete 12
setblock ~76~24~18 minecraft:wood 3
setblock ~76~26~18 minecraft:wool 12
fill ~76~28~18 ~77~28~18 minecraft:concrete 12
fill ~76~30~18 ~76~30~19 minecraft:stained_hardened_clay 12
setblock ~76~32~18 minecraft:concrete 12
setblock ~76~34~18 minecraft:planks 1
fill ~77~22~18 ~78~22~18 minecraft:wood 5
setblock ~77~24~18 minecraft:planks 5
fill ~77~26~18 ~78~26~18 minecraft:wood 3
fill ~77~30~18 ~77~30~19 minecraft:planks 5
setblock ~77~32~18 minecraft:stained_hardened_clay 12
fill ~77~34~18 ~79~34~18 minecraft:wood 0
fill ~78~12~18 ~78~12~19 minecraft:wool 15
setblock ~78~24~18 minecraft:wood 5
setblock ~78~28~18 minecraft:soul_sand
setblock ~78~30~18 minecraft:soul_sand
setblock ~78~32~18 minecraft:wool 12
setblock ~79~12~18 minecraft:coal_block
setblock ~79~15~18 minecraft:purple_glazed_terracotta 3
setblock ~79~22~18 minecraft:soul_sand
setblock ~79~24~18 minecraft:soul_sand
fill ~79~26~18 ~80~26~18 minecraft:wool 12
setblock ~79~28~18 minecraft:wood 3
fill ~79~30~18 ~79~30~19 minecraft:wood 5
fill ~79~32~18 ~79~32~19 minecraft:wood 5
fill ~80~21~18 ~80~21~19 minecraft:wood 5
fill ~80~24~18 ~81~24~18 minecraft:wood 5
setblock ~80~28~18 minecraft:soul_sand
setblock ~80~30~18 minecraft:soul_sand
setblock ~80~32~18 minecraft:wood 3
setblock ~80~34~18 minecraft:planks 1
setblock ~81~11~18 minecraft:obsidian
setblock ~81~12~18 minecraft:coal_block
setblock ~81~21~18 minecraft:planks 5
fill ~81~23~18 ~82~23~18 minecraft:wood 5
fill ~81~26~18 ~81~26~19 minecraft:concrete 12
fill ~81~28~18 ~82~28~19 minecraft:wood 1
fill ~81~30~18 ~82~30~19 minecraft:wood 5
setblock ~81~32~18 minecraft:soul_sand
setblock ~81~34~18 minecraft:wood 0
setblock ~82~11~18 minecraft:coal_block
setblock ~82~12~18 minecraft:wool 15
fill ~82~18~18 ~82~18~21 minecraft:stained_hardened_clay 10
setblock ~82~21~18 minecraft:stained_hardened_clay 12
setblock ~82~25~18 minecraft:soul_sand
fill ~82~27~18 ~83~27~18 minecraft:wood 3
fill ~82~32~18 ~82~32~19 minecraft:wood 5
fill ~82~34~18 ~83~34~18 minecraft:soul_sand
fill ~83~11~18 ~84~11~18 minecraft:wool 15
fill ~83~12~18 ~84~12~18 minecraft:coal_block
fill ~83~17~18 ~83~17~21 minecraft:stained_hardened_clay 10
setblock ~83~20~18 minecraft:wool 12
setblock ~83~23~18 minecraft:stained_hardened_clay 12
setblock ~83~25~18 minecraft:concrete 12
setblock ~83~30~18 minecraft:planks 5
fill ~83~32~18 ~83~32~19 minecraft:wool 12
setblock ~84~20~18 minecraft:wood 5
setblock ~84~22~18 minecraft:stained_hardened_clay 12
setblock ~84~24~18 minecraft:stained_hardened_clay 12
setblock ~84~27~18 minecraft:wool 12
fill ~84~30~18 ~85~30~18 minecraft:stained_hardened_clay 12
setblock ~84~32~18 minecraft:wood 5
fill ~84~34~18 ~87~34~18 minecraft:wood 5
fill ~85~10~18 ~86~10~18 minecraft:obsidian
setblock ~85~11~18 minecraft:coal_block
setblock ~85~19~18 minecraft:concrete 12
fill ~85~22~18 ~85~22~19 minecraft:wood 1
fill ~85~24~18 ~86~24~19 minecraft:wood 1
setblock ~85~26~18 minecraft:wool 12
setblock ~85~27~18 minecraft:wood 5
fill ~85~28~18 ~85~28~19 minecraft:stained_hardened_clay 12
setblock ~85~32~18 minecraft:wool 12
setblock ~86~11~18 minecraft:wool 15
setblock ~86~19~18 minecraft:stained_hardened_clay 12
fill ~86~21~18 ~86~21~19 minecraft:wood 5
fill ~86~23~18 ~87~23~19 minecraft:wood 1
setblock ~86~25~18 minecraft:planks 5
fill ~86~26~18 ~87~26~19 minecraft:concrete 12
fill ~86~28~18 ~87~28~19 minecraft:wood 5
fill ~86~30~18 ~87~30~18 minecraft:wood 5
fill ~86~32~18 ~86~32~19 minecraft:planks 5
fill ~87~11~18 ~87~12~19 minecraft:obsidian
setblock ~87~18~18 minecraft:wood 5
setblock ~87~21~18 minecraft:stained_hardened_clay 12
setblock ~87~25~18 minecraft:wood 3
fill ~87~31~18 ~88~31~18 minecraft:wood 1
setblock ~87~33~18 minecraft:stained_hardened_clay 12
fill ~88~11~18 ~88~12~19 minecraft:wool 15
fill ~88~17~18 ~88~17~19 minecraft:planks 5
setblock ~88~20~18 minecraft:planks 5
fill ~88~22~18 ~88~22~19 minecraft:stained_hardened_clay 12
setblock ~88~23~18 minecraft:planks 5
fill ~88~25~18 ~88~25~19 minecraft:concrete 12
fill ~88~27~18 ~90~27~18 minecraft:wood 5
fill ~88~28~18 ~88~29~18 minecraft:stained_hardened_clay 12
setblock ~88~33~18 minecraft:planks 5
setblock ~89~10~18 minecraft:obsidian
setblock ~89~12~18 minecraft:wool 15
fill ~89~16~18 ~89~16~20 minecraft:wood 5
setblock ~89~19~18 minecraft:wood 5
fill ~89~20~18 ~90~20~18 minecraft:wood 1
fill ~89~21~18 ~89~21~19 minecraft:wood 5
fill ~89~22~18 ~91~22~18 minecraft:concrete 12
setblock ~89~24~18 minecraft:wool 12
setblock ~89~25~18 minecraft:wood 3
fill ~89~29~18 ~89~29~19 minecraft:soul_sand
setblock ~89~31~18 minecraft:soul_sand
fill ~89~33~18 ~89~33~19 minecraft:wood 5
setblock ~90~9~18 minecraft:obsidian
setblock ~90~11~18 minecraft:coal_block
setblock ~90~14~18 minecraft:planks 5
fill ~90~15~18 ~90~15~19 minecraft:stained_hardened_clay 12
setblock ~90~17~18 minecraft:concrete 12
fill ~90~18~18 ~90~18~19 minecraft:wood 5
setblock ~90~19~18 minecraft:wood 1
setblock ~90~21~18 minecraft:wood 1
fill ~90~23~18 ~90~23~19 minecraft:soul_sand
fill ~90~24~18 ~90~24~19 minecraft:wood 3
fill ~90~26~18 ~90~26~19 minecraft:wood 5
setblock ~90~29~18 minecraft:stained_hardened_clay 12
setblock ~90~31~18 minecraft:wood 5
setblock ~90~33~18 minecraft:stained_hardened_clay 12
fill ~91~9~18 ~91~9~21 minecraft:wool 15
fill ~91~10~18 ~92~10~18 minecraft:coal_block
setblock ~91~13~18 minecraft:wood 5
setblock ~91~14~18 minecraft:stained_hardened_clay 12
setblock ~91~15~18 minecraft:concrete 12
fill ~91~16~18 ~92~16~18 minecraft:planks 5
fill ~91~17~18 ~91~18~18 minecraft:stained_hardened_clay 12
setblock ~91~19~18 minecraft:concrete 12
fill ~91~20~18 ~91~21~18 minecraft:planks 5
setblock ~91~25~18 minecraft:stained_hardened_clay 12
fill ~91~26~18 ~91~26~19 minecraft:planks 5
setblock ~91~27~18 minecraft:wool 12
setblock ~91~29~18 minecraft:wood 3
fill ~91~30~18 ~93~30~18 minecraft:wood 5
fill ~91~32~18 ~92~32~18 minecraft:planks 5
setblock ~91~33~18 minecraft:wood 5
fill ~92~8~18 ~92~8~19 minecraft:obsidian
fill ~92~12~18 ~92~12~19 minecraft:planks 5
fill ~92~13~18 ~93~13~18 minecraft:stained_hardened_clay 12
setblock ~92~14~18 minecraft:planks 5
fill ~92~15~18 ~92~15~19 minecraft:wood 5
fill ~92~17~18 ~92~18~18 minecraft:wood 1
fill ~92~19~18 ~93~19~18 minecraft:stained_hardened_clay 12
setblock ~92~20~18 minecraft:concrete 12
setblock ~92~21~18 minecraft:soul_sand
setblock ~92~22~18 minecraft:wool 12
setblock ~92~24~18 minecraft:planks 5
setblock ~92~25~18 minecraft:wood 5
setblock ~92~26~18 minecraft:stained_hardened_clay 12
setblock ~92~28~18 minecraft:wood 3
fill ~93~8~18 ~93~8~19 minecraft:coal_block
fill ~93~14~18 ~94~14~18 minecraft:wood 1
setblock ~93~15~18 minecraft:planks 5
fill ~93~16~18 ~96~16~18 minecraft:wood 1
fill ~93~17~18 ~93~18~18 minecraft:wood 5
fill ~93~20~18 ~94~20~18 minecraft:soul_sand
setblock ~93~21~18 minecraft:wood 3
setblock ~93~23~18 minecraft:wood 5
setblock ~93~24~18 minecraft:stained_hardened_clay 12
setblock ~93~27~18 minecraft:soul_sand
setblock ~93~28~18 minecraft:wool 12
setblock ~93~32~18 minecraft:wood 3
setblock ~94~8~18 minecraft:obsidian
setblock ~94~9~18 minecraft:coal_block
setblock ~94~13~18 minecraft:wood 1
fill ~94~15~18 ~95~15~18 minecraft:wood 1
setblock ~94~17~18 minecraft:stained_hardened_clay 12
setblock ~94~18~18 minecraft:wood 5
setblock ~94~19~18 minecraft:soul_sand
setblock ~94~21~18 minecraft:planks 5
setblock ~94~22~18 minecraft:wool 12
fill ~94~23~18 ~96~23~18 minecraft:wood 1
setblock ~94~24~18 minecraft:wood 5
fill ~94~25~18 ~94~26~18 minecraft:soul_sand
fill ~94~29~18 ~94~29~19 minecraft:planks 5
setblock ~94~31~18 minecraft:wool 12
setblock ~95~7~18 minecraft:obsidian
setblock ~95~8~18 minecraft:wool 15
setblock ~95~14~18 minecraft:planks 5
fill ~95~17~18 ~95~18~18 minecraft:wood 1
setblock ~95~19~18 minecraft:concrete 12
setblock ~95~20~18 minecraft:wood 1
fill ~95~21~18 ~96~21~18 minecraft:stained_hardened_clay 12
setblock ~95~22~18 minecraft:planks 5
fill ~95~24~18 ~95~24~19 minecraft:wood 1
setblock ~95~25~18 minecraft:wood 3
setblock ~95~28~18 minecraft:wood 1
fill ~95~29~18 ~95~29~19 minecraft:wool 12
setblock ~95~31~18 minecraft:wood 3
setblock ~96~7~18 minecraft:wool 15
setblock ~96~8~18 minecraft:coal_block
fill ~96~14~18 ~96~14~19 minecraft:wood 1
fill ~96~15~18 ~96~15~19 minecraft:wood 5
setblock ~96~17~18 minecraft:planks 5
setblock ~96~18~18 minecraft:stained_hardened_clay 12
setblock ~96~19~18 minecraft:planks 5
setblock ~96~20~18 minecraft:soul_sand
setblock ~96~22~18 minecraft:wood 1
fill ~96~25~18 ~98~25~19 minecraft:wood 5
setblock ~96~26~18 minecraft:stained_hardened_clay 12
fill ~96~27~18 ~96~27~19 minecraft:wood 1
setblock ~96~28~18 minecraft:wood 5
setblock ~96~30~18 minecraft:concrete 12
fill ~97~7~18 ~97~7~20 minecraft:obsidian
setblock ~97~8~18 minecraft:obsidian
fill ~97~14~18 ~97~14~19 minecraft:wood 5
fill ~97~15~18 ~97~15~19 minecraft:stained_hardened_clay 12
fill ~97~16~18 ~97~17~18 minecraft:wood 5
fill ~97~18~18 ~97~18~19 minecraft:planks 5
fill ~97~19~18 ~97~19~19 minecraft:stained_hardened_clay 12
setblock ~97~20~18 minecraft:stained_hardened_clay 12
setblock ~97~24~18 minecraft:planks 5
setblock ~97~29~18 minecraft:wood 1
setblock ~98~6~18 minecraft:coal_block
fill ~98~7~18 ~98~7~20 minecraft:wool 15
fill ~98~8~18 ~98~8~19 minecraft:wool 15
fill ~98~15~18 ~98~15~19 minecraft:planks 5
fill ~98~16~18 ~99~16~18 minecraft:wood 1
fill ~98~17~18 ~98~17~19 minecraft:wood 1
setblock ~98~18~18 minecraft:wood 1
setblock ~98~21~18 minecraft:stained_hardened_clay 12
fill ~98~22~18 ~99~22~18 minecraft:wood 5
fill ~98~23~18 ~98~23~19 minecraft:stained_hardened_clay 12
setblock ~98~24~18 minecraft:wood 5
setblock ~98~26~18 minecraft:wood 1
setblock ~98~27~18 minecraft:planks 5
setblock ~98~28~18 minecraft:wood 5
fill ~99~6~18 ~99~7~18 minecraft:obsidian
setblock ~99~15~18 minecraft:stained_hardened_clay 12
fill ~99~17~18 ~100~17~18 minecraft:planks 5
setblock ~99~18~18 minecraft:stained_hardened_clay 12
fill ~99~19~18 ~99~21~18 minecraft:wood 5
fill ~99~23~18 ~99~23~20 minecraft:wood 5
fill ~99~24~18 ~99~24~19 minecraft:wood 1
setblock ~99~25~18 minecraft:wood 1
setblock ~99~26~18 minecraft:planks 5
fill ~100~6~18 ~101~6~18 minecraft:wool 15
fill ~100~7~18 ~101~7~18 minecraft:coal_block
setblock ~100~15~18 minecraft:wood 5
fill ~100~16~18 ~100~16~19 minecraft:stained_hardened_clay 12
setblock ~100~18~18 minecraft:wool 12
setblock ~100~19~18 minecraft:concrete 12
setblock ~100~20~18 minecraft:wood 5
setblock ~100~21~18 minecraft:wood 3
setblock ~101~16~18 minecraft:concrete 12
fill ~102~6~18 ~103~6~18 minecraft:obsidian
fill ~102~16~18 ~102~16~19 minecraft:planks 5
fill ~102~17~18 ~102~17~24 minecraft:wood 5
setblock ~102~18~18 minecraft:planks 5
fill ~102~19~18 ~103~19~18 minecraft:stained_hardened_clay 12
fill ~103~5~18 ~103~5~19 minecraft:wool 15
setblock ~103~16~18 minecraft:wood 5
fill ~103~17~18 ~103~17~19 minecraft:planks 5
setblock ~103~18~18 minecraft:stained_hardened_clay 12
setblock ~103~20~18 minecraft:stained_hardened_clay 12
setblock ~103~21~18 minecraft:wood 3
setblock ~103~22~18 minecraft:wool 12
setblock ~104~5~18 minecraft:obsidian
fill ~104~6~18 ~104~6~19 minecraft:wool 15
fill ~104~16~18 ~105~16~18 minecraft:stained_hardened_clay 12
fill ~104~17~18 ~104~18~18 minecraft:wood 5
fill ~104~19~18 ~104~20~18 minecraft:planks 5
setblock ~104~21~18 minecraft:concrete 12
fill ~104~22~18 ~104~23~18 minecraft:wood 5
setblock ~104~24~18 minecraft:wood 3
setblock ~104~25~18 minecraft:stained_hardened_clay 12
setblock ~105~5~18 minecraft:wool 15
setblock ~105~6~18 minecraft:obsidian
setblock ~105~17~18 minecraft:planks 5
fill ~105~18~18 ~105~18~19 minecraft:wood 1
setblock ~105~19~18 minecraft:wood 1
setblock ~105~23~18 minecraft:wood 5
setblock ~105~24~18 minecraft:concrete 12
setblock ~105~25~18 minecraft:wood 5
fill ~105~26~18 ~106~26~18 minecraft:stained_hardened_clay 12
setblock ~105~27~18 minecraft:wood 5
fill ~106~5~18 ~106~5~20 minecraft:obsidian
fill ~106~6~18 ~107~6~18 minecraft:wool 15
setblock ~106~16~18 minecraft:planks 5
fill ~106~17~18 ~106~17~19 minecraft:wood 5
setblock ~106~20~18 minecraft:stained_hardened_clay 12
fill ~106~21~18 ~106~21~19 minecraft:wood 5
setblock ~106~22~18 minecraft:planks 5
setblock ~106~23~18 minecraft:stained_hardened_clay 12
fill ~106~24~18 ~107~24~18 minecraft:wood 1
setblock ~106~25~18 minecraft:wool 12
fill ~106~28~18 ~107~28~18 minecraft:wood 5
setblock ~106~29~18 minecraft:concrete 12
fill ~107~16~18 ~108~16~18 minecraft:wood 1
setblock ~107~17~18 minecraft:planks 5
fill ~107~18~18 ~107~19~18 minecraft:wood 5
fill ~107~20~18 ~111~20~18 minecraft:wood 1
setblock ~107~22~18 minecraft:wood 1
setblock ~107~23~18 minecraft:wood 5
fill ~107~25~18 ~109~25~18 minecraft:stained_hardened_clay 12
setblock ~107~27~18 minecraft:wool 12
setblock ~107~30~18 minecraft:wood 5
setblock ~108~6~18 minecraft:obsidian
setblock ~108~15~18 minecraft:stained_hardened_clay 12
fill ~108~17~18 ~111~17~18 minecraft:wood 1
setblock ~108~18~18 minecraft:stained_hardened_clay 12
fill ~108~19~18 ~108~19~19 minecraft:wood 5
fill ~108~21~18 ~109~21~18 minecraft:wood 5
setblock ~108~22~18 minecraft:planks 5
setblock ~108~26~18 minecraft:wood 5
setblock ~108~28~18 minecraft:wood 1
setblock ~108~31~18 minecraft:wood 5
setblock ~109~6~18 minecraft:wool 15
setblock ~109~15~18 minecraft:concrete 12
setblock ~109~16~18 minecraft:stained_hardened_clay 12
setblock ~109~18~18 minecraft:concrete 12
setblock ~109~19~18 minecraft:planks 5
setblock ~109~22~18 minecraft:stained_hardened_clay 12
fill ~109~23~18 ~111~23~18 minecraft:wood 5
setblock ~109~24~18 minecraft:concrete 12
fill ~109~26~18 ~110~27~18 minecraft:wood 1
fill ~109~29~18 ~109~30~19 minecraft:wood 5
fill ~109~32~18 ~110~32~19 minecraft:soul_sand
setblock ~110~6~18 minecraft:obsidian
setblock ~110~7~18 minecraft:coal_block
fill ~110~14~18 ~111~15~18 minecraft:wood 5
fill ~110~16~18 ~110~16~19 minecraft:wood 5
fill ~110~18~18 ~110~18~19 minecraft:wood 1
setblock ~110~19~18 minecraft:wood 5
fill ~110~21~18 ~111~21~19 minecraft:wood 1
fill ~110~22~18 ~112~22~18 minecraft:wood 1
setblock ~110~25~18 minecraft:soul_sand
fill ~110~28~18 ~111~28~19 minecraft:wood 1
fill ~110~30~18 ~110~30~19 minecraft:wood 5
fill ~111~7~18 ~111~7~20 minecraft:wool 15
setblock ~111~16~18 minecraft:stained_hardened_clay 12
setblock ~111~18~18 minecraft:wood 5
fill ~111~19~18 ~112~19~18 minecraft:wood 1
fill ~111~24~18 ~113~24~18 minecraft:wood 1
setblock ~111~26~18 minecraft:concrete 12
setblock ~111~29~18 minecraft:wood 1
setblock ~111~31~18 minecraft:wood 5
fill ~111~33~18 ~113~33~18 minecraft:wood 0
setblock ~112~6~18 minecraft:coal_block
setblock ~112~13~18 minecraft:stained_hardened_clay 12
setblock ~112~14~18 minecraft:wood 1
fill ~112~15~18 ~113~15~18 minecraft:stained_hardened_clay 12
setblock ~112~16~18 minecraft:wood 1
setblock ~112~17~18 minecraft:wood 5
setblock ~112~18~18 minecraft:stained_hardened_clay 12
fill ~112~20~18 ~112~20~19 minecraft:planks 5
setblock ~112~23~18 minecraft:wood 1
setblock ~112~26~18 minecraft:wood 3
setblock ~112~27~18 minecraft:wood 1
setblock ~112~29~18 minecraft:wood 5
fill ~112~30~18 ~112~30~19 minecraft:wood 1
setblock ~112~31~18 minecraft:wood 3
fill ~113~6~18 ~113~7~18 minecraft:wool 15
fill ~113~13~18 ~113~13~19 minecraft:planks 5
setblock ~113~14~18 minecraft:planks 5
fill ~113~17~18 ~113~17~19 minecraft:wood 1
fill ~113~18~18 ~113~19~19 minecraft:planks 5
fill ~113~21~18 ~113~21~19 minecraft:planks 5
setblock ~113~22~18 minecraft:wood 5
fill ~113~25~18 ~113~25~19 minecraft:wood 1
fill ~113~26~18 ~114~26~18 minecraft:wood 5
fill ~113~28~18 ~113~28~19 minecraft:wood 5
setblock ~113~29~18 minecraft:soul_sand
setblock ~113~30~18 minecraft:wool 12
fill ~113~32~18 ~114~32~18 minecraft:wood 0
fill ~114~7~18 ~115~7~18 minecraft:coal_block
fill ~114~12~18 ~115~12~18 minecraft:wood 5
setblock ~114~13~18 minecraft:wood 5
setblock ~114~14~18 minecraft:wood 1
setblock ~114~16~18 minecraft:wood 1
fill ~114~17~18 ~115~17~18 minecraft:concrete 12
fill ~114~18~18 ~114~18~19 minecraft:wood 1
fill ~114~19~18 ~114~19~19 minecraft:wood 5
fill ~114~20~18 ~115~20~18 minecraft:stained_hardened_clay 12
setblock ~114~23~18 minecraft:wood 1
setblock ~114~25~18 minecraft:wood 5
setblock ~114~27~18 minecraft:soul_sand
setblock ~114~28~18 minecraft:stained_hardened_clay 12
setblock ~114~30~18 minecraft:wood 3
setblock ~114~34~18 minecraft:wood 0
setblock ~115~8~18 minecraft:wool 15
setblock ~115~13~18 minecraft:stained_hardened_clay 12
fill ~115~14~18 ~115~15~19 minecraft:wood 5
setblock ~115~18~18 minecraft:soul_sand
fill ~115~21~18 ~115~21~19 minecraft:wood 5
setblock ~115~22~18 minecraft:planks 5
setblock ~115~24~18 minecraft:stained_hardened_clay 12
setblock ~115~26~18 minecraft:planks 5
setblock ~115~27~18 minecraft:concrete 12
setblock ~115~29~18 minecraft:concrete 12
setblock ~115~30~18 minecraft:stained_hardened_clay 12
setblock ~115~32~18 minecraft:wood 5
setblock ~115~34~18 minecraft:planks 1
fill ~116~7~18 ~116~7~19 minecraft:obsidian
fill ~116~8~18 ~116~8~20 minecraft:coal_block
fill ~116~11~18 ~117~11~19 minecraft:wood 1
fill ~116~12~18 ~116~13~18 minecraft:wood 1
setblock ~116~15~18 minecraft:wood 1
fill ~116~16~18 ~117~16~18 minecraft:wood 5
fill ~116~19~18 ~116~19~19 minecraft:wood 5
setblock ~116~21~18 minecraft:planks 5
setblock ~116~22~18 minecraft:wood 5
fill ~116~24~18 ~117~24~18 minecraft:wood 5
fill ~116~26~18 ~118~26~18 minecraft:wood 1
setblock ~116~27~18 minecraft:planks 5
fill ~116~29~18 ~116~29~19 minecraft:wood 5
fill ~116~31~18 ~116~31~19 minecraft:stained_hardened_clay 12
setblock ~116~32~18 minecraft:planks 5
fill ~116~34~18 ~116~34~19 minecraft:wool 12
setblock ~117~7~18 minecraft:coal_block
fill ~117~8~18 ~119~8~18 minecraft:obsidian
setblock ~117~13~18 minecraft:wood 1
setblock ~117~14~18 minecraft:stained_hardened_clay 12
setblock ~117~15~18 minecraft:planks 5
fill ~117~17~18 ~117~17~19 minecraft:wood 5
setblock ~117~19~18 minecraft:concrete 12
fill ~117~20~18 ~117~21~18 minecraft:wood 5
fill ~117~23~18 ~118~23~18 minecraft:stained_hardened_clay 12
fill ~117~27~18 ~117~27~19 minecraft:wood 5
setblock ~117~29~18 minecraft:wool 12
setblock ~117~31~18 minecraft:planks 5
setblock ~117~33~18 minecraft:stained_hardened_clay 12
fill ~117~34~18 ~117~34~19 minecraft:wood 3
fill ~118~12~18 ~119~12~18 minecraft:wood 1
setblock ~118~14~18 minecraft:wool 12
setblock ~118~15~18 minecraft:wood 3
fill ~118~18~18 ~118~18~19 minecraft:wood 5
setblock ~118~20~18 minecraft:concrete 12
setblock ~118~21~18 minecraft:wood 3
fill ~118~25~18 ~119~25~18 minecraft:planks 5
fill ~118~29~18 ~119~29~18 minecraft:wood 3
setblock ~118~31~18 minecraft:stained_hardened_clay 12
fill ~118~33~18 ~118~33~19 minecraft:wood 5
fill ~118~34~18 ~119~34~18 minecraft:wool 12
fill ~119~9~18 ~119~9~21 minecraft:obsidian
setblock ~119~11~18 minecraft:coal_block
fill ~119~13~18 ~119~13~20 minecraft:wood 1
fill ~119~16~18 ~119~16~23 minecraft:wood 5
fill ~119~19~18 ~119~19~19 minecraft:stained_hardened_clay 12
fill ~119~21~18 ~119~21~19 minecraft:wool 12
setblock ~119~23~18 minecraft:soul_sand
setblock ~119~27~18 minecraft:wood 3
setblock ~119~31~18 minecraft:soul_sand
setblock ~119~33~18 minecraft:wood 3
setblock ~120~11~18 minecraft:obsidian
setblock ~120~12~18 minecraft:wool 15
setblock ~120~14~18 minecraft:planks 5
setblock ~120~15~18 minecraft:concrete 12
setblock ~120~17~18 minecraft:wood 1
fill ~120~19~18 ~121~19~18 minecraft:wood 1
setblock ~120~21~18 minecraft:planks 5
fill ~120~24~18 ~120~24~19 minecraft:soul_sand
fill ~120~25~18 ~120~25~19 minecraft:wool 12
fill ~120~27~18 ~121~27~18 minecraft:planks 5
fill ~120~29~18 ~121~29~18 minecraft:soul_sand
setblock ~120~31~18 minecraft:wool 12
setblock ~120~33~18 minecraft:soul_sand
fill ~120~34~18 ~123~34~18 minecraft:wood 0
setblock ~121~11~18 minecraft:wool 15
setblock ~121~12~18 minecraft:coal_block
setblock ~121~15~18 minecraft:wood 5
setblock ~121~17~18 minecraft:wood 5
fill ~121~18~18 ~122~18~19 minecraft:wood 1
setblock ~121~22~18 minecraft:wool 12
setblock ~121~24~18 minecraft:wood 3
setblock ~121~26~18 minecraft:stained_hardened_clay 12
fill ~121~31~18 ~123~31~18 minecraft:planks 1
setblock ~121~33~18 minecraft:planks 1
fill ~122~10~18 ~122~12~18 minecraft:obsidian
setblock ~122~16~18 minecraft:wood 5
setblock ~122~20~18 minecraft:wood 1
setblock ~122~22~18 minecraft:planks 5
setblock ~122~24~18 minecraft:concrete 12
fill ~122~26~18 ~123~26~18 minecraft:planks 5
fill ~122~27~18 ~123~27~18 minecraft:wood 3
fill ~122~29~18 ~123~29~18 minecraft:planks 5
setblock ~122~33~18 minecraft:wood 0
setblock ~123~10~18 minecraft:wool 15
fill ~123~11~18 ~124~11~18 minecraft:coal_block
fill ~123~16~18 ~123~16~19 minecraft:stained_hardened_clay 12
fill ~123~17~18 ~126~17~18 minecraft:wood 5
fill ~123~18~18 ~123~18~19 minecraft:wood 5
setblock ~123~20~18 minecraft:stained_hardened_clay 12
setblock ~123~22~18 minecraft:wood 5
fill ~123~24~18 ~123~24~19 minecraft:wool 12
fill ~123~33~18 ~123~33~19 minecraft:planks 1
setblock ~124~10~18 minecraft:coal_block
setblock ~124~19~18 minecraft:wood 1
setblock ~124~21~18 minecraft:planks 5
setblock ~124~22~18 minecraft:wood 0
fill ~124~23~18 ~125~23~18 minecraft:planks 1
setblock ~124~25~18 minecraft:wool 12
fill ~124~27~18 ~125~27~18 minecraft:concrete 12
fill ~124~29~18 ~127~29~18 minecraft:stained_hardened_clay 12
setblock ~124~31~18 minecraft:wood 3
fill ~124~32~18 ~126~32~18 minecraft:wood 0
fill ~124~34~18 ~126~34~18 minecraft:planks 1
fill ~125~10~18 ~125~10~20 minecraft:obsidian
fill ~125~11~18 ~126~11~18 minecraft:wool 15
fill ~125~19~18 ~126~19~18 minecraft:wood 5
setblock ~125~21~18 minecraft:stained_hardened_clay 12
fill ~125~25~18 ~125~25~19 minecraft:soul_sand
setblock ~125~31~18 minecraft:concrete 12
setblock ~126~10~18 minecraft:wool 15
fill ~126~21~18 ~127~21~18 minecraft:wood 5
setblock ~126~23~18 minecraft:wood 5
setblock ~126~25~18 minecraft:wood 3
setblock ~126~27~18 minecraft:soul_sand
setblock ~126~31~18 minecraft:planks 5
fill ~127~10~18 ~127~11~18 minecraft:obsidian
setblock ~127~17~18 minecraft:planks 5
setblock ~127~19~18 minecraft:planks 5
setblock ~127~22~18 minecraft:planks 5
setblock ~127~25~18 minecraft:concrete 12
fill ~127~27~18 ~129~27~19 minecraft:wood 1
setblock ~127~31~18 minecraft:wood 5
fill ~127~32~18 ~128~32~18 minecraft:soul_sand
setblock ~127~34~18 minecraft:wood 0
fill ~128~10~18 ~128~11~18 minecraft:wool 15
fill ~128~18~18 ~129~18~18 minecraft:wood 5
fill ~128~19~18 ~128~19~19 minecraft:stained_hardened_clay 12
fill ~128~20~18 ~130~20~18 minecraft:planks 5
setblock ~128~22~18 minecraft:wood 5
setblock ~128~25~18 minecraft:soul_sand
fill ~128~29~18 ~128~29~19 minecraft:wood 5
setblock ~128~30~18 minecraft:planks 5
fill ~128~34~18 ~128~34~19 minecraft:planks 1
fill ~129~11~18 ~129~11~22 minecraft:coal_block
fill ~129~12~18 ~129~12~19 minecraft:coal_block
fill ~129~22~18 ~129~22~19 minecraft:wood 1
fill ~129~25~18 ~129~25~19 minecraft:concrete 12
setblock ~129~29~18 minecraft:planks 5
fill ~129~30~18 ~130~30~18 minecraft:wood 5
fill ~129~32~18 ~129~32~19 minecraft:wood 3
setblock ~129~33~18 minecraft:wood 0
fill ~130~11~18 ~130~12~18 minecraft:wool 15
setblock ~130~18~18 minecraft:planks 5
setblock ~130~22~18 minecraft:wood 3
setblock ~130~25~18 minecraft:wool 12
fill ~130~26~18 ~131~26~18 minecraft:wood 3
fill ~130~28~18 ~137~28~19 minecraft:wood 1
fill ~130~32~18 ~130~32~19 minecraft:wool 12
fill ~130~33~18 ~130~33~19 minecraft:soul_sand
setblock ~131~11~18 minecraft:obsidian
fill ~131~12~18 ~132~12~18 minecraft:wool 15
fill ~131~18~18 ~131~18~19 minecraft:wood 5
fill ~131~20~18 ~132~20~18 minecraft:wood 3
fill ~131~22~18 ~133~22~18 minecraft:soul_sand
fill ~131~25~18 ~132~25~18 minecraft:wood 3
setblock ~131~30~18 minecraft:concrete 12
fill ~131~32~18 ~133~32~18 minecraft:wood 5
setblock ~131~33~18 minecraft:wood 5
setblock ~132~11~18 minecraft:wool 15
setblock ~132~18~18 minecraft:planks 5
setblock ~132~26~18 minecraft:concrete 12
setblock ~132~30~18 minecraft:stained_hardened_clay 12
setblock ~132~33~18 minecraft:stained_hardened_clay 12
setblock ~133~12~18 minecraft:coal_block
setblock ~133~18~18 minecraft:wood 5
setblock ~133~20~18 minecraft:soul_sand
fill ~133~24~18 ~133~24~19 minecraft:concrete 12
setblock ~133~26~18 minecraft:wool 12
fill ~133~30~18 ~133~31~18 minecraft:planks 5
setblock ~133~33~18 minecraft:planks 5
fill ~134~12~18 ~134~12~19 minecraft:obsidian
setblock ~134~18~18 minecraft:planks 5
setblock ~134~19~18 minecraft:stained_hardened_clay 12
setblock ~134~21~18 minecraft:wood 3
setblock ~134~23~18 minecraft:wool 12
setblock ~134~24~18 minecraft:soul_sand
setblock ~134~26~18 minecraft:wood 3
setblock ~134~30~18 minecraft:stained_hardened_clay 12
fill ~134~31~18 ~134~31~19 minecraft:wood 5
setblock ~134~33~18 minecraft:wool 12
setblock ~135~11~18 minecraft:obsidian
setblock ~135~12~18 minecraft:wool 15
fill ~135~17~18 ~136~17~18 minecraft:wood 5
setblock ~135~18~18 minecraft:stained_hardened_clay 12
setblock ~135~19~18 minecraft:wood 5
setblock ~135~21~18 minecraft:wool 12
setblock ~135~23~18 minecraft:stained_hardened_clay 12
setblock ~135~24~18 minecraft:concrete 12
fill ~135~26~18 ~136~26~18 minecraft:wool 12
fill ~135~30~18 ~135~30~19 minecraft:wool 12
setblock ~135~31~18 minecraft:planks 5
setblock ~135~33~18 minecraft:planks 5
fill ~136~11~18 ~137~11~18 minecraft:wool 15
fill ~136~12~18 ~136~12~21 minecraft:obsidian
setblock ~136~19~18 minecraft:planks 5
fill ~136~21~18 ~136~21~19 minecraft:soul_sand
fill ~136~24~18 ~136~24~19 minecraft:wood 5
setblock ~136~30~18 minecraft:stained_hardened_clay 12
fill ~136~31~18 ~141~31~18 minecraft:wood 5
setblock ~136~33~18 minecraft:wool 12
fill ~137~17~18 ~137~17~19 minecraft:soul_sand
setblock ~137~19~18 minecraft:wood 3
setblock ~137~21~18 minecraft:wool 12
fill ~137~23~18 ~137~24~18 minecraft:stained_hardened_clay 12
fill ~137~26~18 ~137~26~19 minecraft:wood 3
fill ~137~29~18 ~140~29~19 minecraft:wood 1
setblock ~137~33~18 minecraft:wood 5
fill ~138~11~18 ~138~11~20 minecraft:coal_block
fill ~138~12~18 ~139~12~18 minecraft:obsidian
fill ~138~17~18 ~138~17~19 minecraft:concrete 12
fill ~138~19~18 ~142~19~18 minecraft:wool 12
fill ~138~21~18 ~139~21~18 minecraft:concrete 12
fill ~138~23~18 ~139~23~19 minecraft:wood 5
fill ~138~24~18 ~139~24~18 minecraft:wood 5
setblock ~138~26~18 minecraft:wool 12
setblock ~138~28~18 minecraft:wool 12
setblock ~138~33~18 minecraft:wool 12
fill ~139~11~18 ~141~11~18 minecraft:wool 15
fill ~139~17~18 ~140~17~18 minecraft:wood 3
setblock ~139~26~18 minecraft:concrete 12
fill ~139~27~18 ~140~27~18 minecraft:wool 12
setblock ~139~33~18 minecraft:wood 5
fill ~140~12~18 ~140~12~19 minecraft:wool 15
setblock ~140~21~18 minecraft:wood 3
fill ~140~22~18 ~140~22~19 minecraft:soul_sand
setblock ~140~24~18 minecraft:planks 5
fill ~140~25~18 ~142~25~18 minecraft:wood 5
setblock ~140~33~18 minecraft:stained_hardened_clay 12
fill ~141~12~18 ~141~12~19 minecraft:obsidian
fill ~141~17~18 ~143~17~18 minecraft:planks 5
fill ~141~20~18 ~141~20~19 minecraft:concrete 12
fill ~141~22~18 ~142~22~18 minecraft:concrete 12
setblock ~141~24~18 minecraft:stained_hardened_clay 12
fill ~141~27~18 ~141~27~19 minecraft:concrete 12
fill ~141~29~18 ~141~29~19 minecraft:concrete 12
setblock ~141~32~18 minecraft:planks 5
fill ~142~18~18 ~144~18~18 minecraft:wood 5
fill ~142~20~18 ~142~20~19 minecraft:wood 3
setblock ~142~24~18 minecraft:planks 5
setblock ~142~27~18 minecraft:wood 3
fill ~142~29~18 ~142~29~19 minecraft:wool 12
setblock ~142~31~18 minecraft:stained_hardened_clay 12
setblock ~142~32~18 minecraft:wood 5
setblock ~143~12~18 minecraft:wool 15
setblock ~143~16~18 minecraft:wood 5
fill ~143~20~18 ~143~20~19 minecraft:wool 12
fill ~143~22~18 ~143~22~19 minecraft:wood 1
setblock ~143~23~18 minecraft:wool 12
setblock ~143~25~18 minecraft:wood 3
fill ~143~27~18 ~144~27~18 minecraft:wool 12
setblock ~143~29~18 minecraft:concrete 12
fill ~143~31~18 ~143~32~18 minecraft:planks 5
setblock ~144~12~18 minecraft:obsidian
fill ~144~16~18 ~145~16~18 minecraft:planks 5
setblock ~144~20~18 minecraft:wood 3
setblock ~144~23~18 minecraft:soul_sand
setblock ~144~25~18 minecraft:wood 5
fill ~144~29~18 ~145~29~18 minecraft:wood 3
fill ~144~31~18 ~144~32~18 minecraft:wood 5
fill ~145~18~18 ~146~18~18 minecraft:wood 3
fill ~145~20~18 ~149~20~18 minecraft:wool 12
fill ~145~23~18 ~147~23~18 minecraft:concrete 12
setblock ~145~25~18 minecraft:planks 5
setblock ~145~27~18 minecraft:soul_sand
setblock ~145~30~18 minecraft:wood 5
setblock ~145~32~18 minecraft:wood 5
setblock ~146~12~18 minecraft:coal_block
fill ~146~13~18 ~147~13~19 minecraft:obsidian
fill ~146~16~18 ~147~16~18 minecraft:stained_hardened_clay 12
fill ~146~25~18 ~146~25~19 minecraft:stained_hardened_clay 12
fill ~146~27~18 ~146~27~19 minecraft:concrete 12
setblock ~146~29~18 minecraft:wool 12
setblock ~146~30~18 minecraft:wood 3
setblock ~146~32~18 minecraft:wood 3
fill ~147~12~18 ~148~12~18 minecraft:obsidian
setblock ~147~18~18 minecraft:wool 12
fill ~147~25~18 ~147~25~19 minecraft:planks 5
setblock ~147~27~18 minecraft:wood 3
fill ~147~28~18 ~148~28~18 minecraft:wool 12
setblock ~147~30~18 minecraft:wood 5
fill ~147~32~18 ~147~32~19 minecraft:wood 5
setblock ~148~16~18 minecraft:concrete 12
setblock ~148~18~18 minecraft:soul_sand
setblock ~148~23~18 minecraft:wool 12
fill ~148~25~18 ~148~25~19 minecraft:wood 5
setblock ~148~26~18 minecraft:planks 5
setblock ~148~30~18 minecraft:soul_sand
setblock ~148~32~18 minecraft:wool 12
fill ~149~12~18 ~150~12~18 minecraft:coal_block
fill ~149~16~18 ~152~16~18 minecraft:wood 5
fill ~149~18~18 ~150~18~18 minecraft:concrete 12
setblock ~149~23~18 minecraft:soul_sand
setblock ~149~25~18 minecraft:wood 3
fill ~149~26~18 ~150~26~18 minecraft:concrete 12
fill ~149~28~18 ~149~28~19 minecraft:concrete 12
setblock ~149~30~18 minecraft:wool 12
setblock ~149~32~18 minecraft:wood 3
setblock ~150~13~18 minecraft:wool 15
fill ~150~19~18 ~150~19~19 minecraft:wood 3
fill ~150~21~18 ~152~21~18 minecraft:wood 3
fill ~150~23~18 ~150~23~19 minecraft:stained_hardened_clay 12
fill ~150~25~18 ~150~25~19 minecraft:wood 5
setblock ~150~28~18 minecraft:wood 3
setblock ~150~30~18 minecraft:planks 5
setblock ~150~32~18 minecraft:planks 5
setblock ~151~13~18 minecraft:obsidian
setblock ~151~17~18 minecraft:stained_hardened_clay 12
setblock ~151~19~18 minecraft:concrete 12
setblock ~151~23~18 minecraft:wood 5
fill ~151~25~18 ~151~25~19 minecraft:planks 5
setblock ~151~26~18 minecraft:soul_sand
setblock ~151~28~18 minecraft:wool 12
setblock ~151~30~18 minecraft:wool 12
setblock ~151~32~18 minecraft:wood 3
fill ~152~12~18 ~152~12~19 minecraft:obsidian
fill ~152~13~18 ~153~13~19 minecraft:coal_block
fill ~152~15~18 ~153~15~18 minecraft:planks 5
setblock ~152~17~18 minecraft:wood 3
setblock ~152~19~18 minecraft:wood 3
setblock ~152~23~18 minecraft:planks 5
fill ~152~24~18 ~154~24~18 minecraft:wood 5
fill ~152~26~18 ~155~26~18 minecraft:concrete 12
setblock ~152~28~18 minecraft:wood 5
setblock ~152~30~18 minecraft:stained_hardened_clay 12
setblock ~152~31~18 minecraft:soul_sand
setblock ~153~12~18 minecraft:wool 15
setblock ~153~17~18 minecraft:concrete 12
fill ~153~19~18 ~153~19~19 minecraft:concrete 12
setblock ~153~21~18 minecraft:wool 12
setblock ~153~23~18 minecraft:wood 5
fill ~153~28~18 ~154~28~18 minecraft:stained_hardened_clay 12
setblock ~153~29~18 minecraft:planks 5
setblock ~153~31~18 minecraft:wood 3
fill ~154~12~18 ~154~12~19 minecraft:obsidian
fill ~154~13~18 ~156~13~18 minecraft:obsidian
setblock ~154~15~18 minecraft:stained_hardened_clay 12
setblock ~154~17~18 minecraft:wood 3
setblock ~154~19~18 minecraft:wool 12
setblock ~154~21~18 minecraft:soul_sand
setblock ~154~22~18 minecraft:wood 5
setblock ~154~29~18 minecraft:stained_hardened_clay 12
setblock ~154~31~18 minecraft:wool 12
fill ~155~12~18 ~155~12~19 minecraft:coal_block
setblock ~155~15~18 minecraft:planks 5
setblock ~155~17~18 minecraft:wool 12
fill ~155~19~18 ~156~19~19 minecraft:concrete 12
setblock ~155~22~18 minecraft:planks 5
setblock ~155~24~18 minecraft:planks 5
setblock ~155~28~18 minecraft:wool 12
setblock ~155~29~18 minecraft:concrete 12
setblock ~155~31~18 minecraft:concrete 12
fill ~156~14~18 ~156~14~20 minecraft:obsidian
fill ~156~15~18 ~157~15~18 minecraft:soul_sand
fill ~156~17~18 ~157~17~18 minecraft:soul_sand
fill ~156~22~18 ~157~22~18 minecraft:stained_hardened_clay 12
fill ~156~24~18 ~158~24~18 minecraft:concrete 12
setblock ~156~25~18 minecraft:concrete 12
fill ~156~27~18 ~157~27~18 minecraft:wood 3
fill ~156~29~18 ~156~29~19 minecraft:soul_sand
setblock ~156~31~18 minecraft:wood 3
fill ~157~13~18 ~157~13~22 minecraft:wool 15
setblock ~157~14~18 minecraft:coal_block
setblock ~157~19~18 minecraft:wool 12
fill ~157~25~18 ~157~25~19 minecraft:wool 12
setblock ~157~29~18 minecraft:concrete 12
setblock ~157~31~18 minecraft:wool 12
setblock ~158~13~18 minecraft:coal_block
setblock ~158~14~18 minecraft:obsidian
setblock ~158~15~18 minecraft:stained_hardened_clay 12
fill ~158~17~18 ~158~17~19 minecraft:wool 12
setblock ~158~19~18 minecraft:concrete 12
fill ~158~22~18 ~158~22~19 minecraft:soul_sand
fill ~158~25~18 ~162~25~18 minecraft:wood 3
fill ~158~27~18 ~159~27~18 minecraft:soul_sand
fill ~158~29~18 ~158~29~19 minecraft:stained_hardened_clay 12
setblock ~158~31~18 minecraft:concrete 12
fill ~159~14~18 ~159~14~19 minecraft:wool 15
fill ~159~15~18 ~160~15~18 minecraft:concrete 12
fill ~159~17~18 ~160~17~18 minecraft:soul_sand
fill ~159~19~18 ~159~19~19 minecraft:wool 12
fill ~159~21~18 ~159~21~19 minecraft:wood 1
setblock ~159~22~18 minecraft:wood 3
fill ~159~23~18 ~159~23~19 minecraft:concrete 12
setblock ~159~29~18 minecraft:planks 5
setblock ~159~30~18 minecraft:stained_hardened_clay 12
fill ~160~13~18 ~160~14~19 minecraft:coal_block
setblock ~160~16~18 minecraft:wool 12
fill ~160~18~18 ~161~18~18 minecraft:wood 3
setblock ~160~20~18 minecraft:wool 12
fill ~160~22~18 ~160~22~19 minecraft:concrete 12
fill ~160~23~18 ~162~23~18 minecraft:wool 12
fill ~160~27~18 ~161~27~18 minecraft:wood 0
setblock ~160~29~18 minecraft:stained_hardened_clay 12
setblock ~160~30~18 minecraft:wood 5
setblock ~161~13~18 minecraft:obsidian
setblock ~161~14~18 minecraft:wool 15
setblock ~161~15~18 minecraft:planks 5
setblock ~161~16~18 minecraft:wood 3
fill ~161~20~18 ~162~20~18 minecraft:wood 3
fill ~161~22~18 ~161~22~19 minecraft:wool 12
setblock ~161~28~18 minecraft:wood 0
setblock ~161~30~18 minecraft:planks 1
setblock ~162~13~18 minecraft:wool 15
fill ~162~15~18 ~162~16~18 minecraft:stained_hardened_clay 12
fill ~162~18~18 ~162~18~19 minecraft:concrete 12
fill ~162~21~18 ~164~21~19 minecraft:wood 1
fill ~162~26~18 ~165~26~18 minecraft:wool 12
setblock ~162~28~18 minecraft:soul_sand
setblock ~162~30~18 minecraft:wood 3
fill ~163~13~18 ~163~13~19 minecraft:coal_block
fill ~163~14~18 ~163~14~19 minecraft:obsidian
fill ~163~15~18 ~164~15~18 minecraft:wood 5
fill ~163~16~18 ~163~16~19 minecraft:planks 5
fill ~163~18~18 ~163~18~19 minecraft:soul_sand
setblock ~163~23~18 minecraft:concrete 12
setblock ~163~24~18 minecraft:wool 12
setblock ~163~28~18 minecraft:concrete 12
setblock ~163~30~18 minecraft:soul_sand
fill ~164~14~18 ~164~14~19 minecraft:coal_block
setblock ~164~16~18 minecraft:wood 5
fill ~164~18~18 ~164~18~19 minecraft:concrete 12
fill ~164~19~18 ~166~19~18 minecraft:wool 12
fill ~164~23~18 ~164~23~19 minecraft:wool 12
fill ~164~24~18 ~166~24~18 minecraft:concrete 12
setblock ~164~28~18 minecraft:planks 5
setblock ~164~29~18 minecraft:wool 12
fill ~165~14~18 ~165~14~20 minecraft:wool 15
fill ~165~15~18 ~166~15~18 minecraft:stained_hardened_clay 12
fill ~165~17~18 ~165~17~19 minecraft:soul_sand
setblock ~165~21~18 minecraft:wool 12
setblock ~165~23~18 minecraft:soul_sand
setblock ~165~27~18 minecraft:planks 5
setblock ~165~29~18 minecraft:wood 5
fill ~166~14~18 ~168~14~18 minecraft:obsidian
fill ~166~17~18 ~166~17~19 minecraft:wool 12
fill ~166~21~18 ~166~21~19 minecraft:soul_sand
setblock ~166~22~18 minecraft:soul_sand
setblock ~166~26~18 minecraft:concrete 12
setblock ~166~27~18 minecraft:wood 0
setblock ~166~29~18 minecraft:concrete 12
fill ~167~15~18 ~168~15~18 minecraft:wood 5
fill ~167~17~18 ~169~17~18 minecraft:soul_sand
setblock ~167~19~18 minecraft:soul_sand
setblock ~167~21~18 minecraft:wood 5
fill ~167~22~18 ~168~22~18 minecraft:stained_hardened_clay 12
setblock ~167~24~18 minecraft:wood 3
fill ~167~25~18 ~167~25~19 minecraft:concrete 12
setblock ~167~27~18 minecraft:wool 12
fill ~167~29~18 ~167~29~19 minecraft:planks 1
setblock ~168~13~18 minecraft:wool 15
fill ~168~19~18 ~168~20~18 minecraft:wool 12
setblock ~168~23~18 minecraft:stained_hardened_clay 12
setblock ~168~25~18 minecraft:wool 12
setblock ~168~27~18 minecraft:concrete 12
fill ~168~28~18 ~168~28~20 minecraft:wood 0
setblock ~169~15~18 minecraft:stained_hardened_clay 12
setblock ~169~20~18 minecraft:wool 12
fill ~169~22~18 ~169~23~18 minecraft:planks 5
setblock ~169~25~18 minecraft:wood 3
fill ~169~27~18 ~169~27~19 minecraft:wood 3
setblock ~169~28~18 minecraft:planks 1
setblock ~8~29~19 minecraft:obsidian
fill ~8~30~19 ~8~30~23 minecraft:wool 15
setblock ~9~30~19 minecraft:coal_block
setblock ~10~29~19 minecraft:coal_block
fill ~11~29~19 ~11~29~21 minecraft:wool 15
fill ~11~30~19 ~11~30~20 minecraft:wool 15
fill ~11~31~19 ~13~31~26 minecraft:wood 1
fill ~12~28~19 ~14~28~19 minecraft:obsidian
setblock ~12~29~19 minecraft:coal_block
fill ~12~30~19 ~12~30~20 minecraft:obsidian
setblock ~13~29~19 minecraft:obsidian
setblock ~14~29~19 minecraft:wool 15
fill ~14~32~19 ~15~32~37 minecraft:wood 1
fill ~15~28~19 ~15~29~19 minecraft:coal_block
fill ~15~31~19 ~15~31~24 minecraft:wood 1
fill ~16~27~19 ~19~27~19 minecraft:coal_block
fill ~16~28~19 ~16~28~23 minecraft:obsidian
fill ~16~29~19 ~16~29~20 minecraft:coal_block
fill ~16~31~19 ~17~31~19 minecraft:wood 3
fill ~16~33~19 ~16~33~20 minecraft:planks 5
setblock ~17~28~19 minecraft:coal_block
setblock ~17~30~19 minecraft:soul_sand
fill ~17~33~19 ~17~33~20 minecraft:wood 5
setblock ~18~30~19 minecraft:wool 12
setblock ~18~33~19 minecraft:planks 5
setblock ~19~28~19 minecraft:wool 15
setblock ~19~30~19 minecraft:wood 3
setblock ~19~31~19 minecraft:concrete 12
setblock ~19~32~19 minecraft:wood 5
fill ~19~33~19 ~19~33~20 minecraft:wool 12
fill ~20~26~19 ~20~26~21 minecraft:wool 15
setblock ~20~27~19 minecraft:wool 15
setblock ~20~30~19 minecraft:wool 12
setblock ~20~31~19 minecraft:planks 5
setblock ~20~33~19 minecraft:wood 5
fill ~20~35~19 ~21~35~19 minecraft:planks 1
fill ~21~26~19 ~22~26~19 minecraft:coal_block
fill ~21~27~19 ~22~27~19 minecraft:obsidian
setblock ~21~29~19 minecraft:soul_sand
fill ~21~30~19 ~22~30~19 minecraft:concrete 12
