fill ~38 ~0 ~46 ~38 ~13 ~46 dirt 1 
setblock ~39 ~0 ~46 dirt 0  
fill ~40 ~0 ~46 ~40 ~14 ~46 dirt 1  
fill ~33 ~1 ~33 ~35 ~1 ~33 dirt 0  
fill ~33 ~1 ~34 ~35 ~1 ~34 dirt 0  
fill ~34 ~1 ~44 ~35 ~1 ~44 grass 0  
fill ~35 ~1 ~43 ~36 ~1 ~43 grass 0  
fill ~35 ~1 ~45 ~35 ~1 ~46 grass 0  
fill ~36 ~1 ~26 ~36 ~3 ~26 dirt 1 
setblock ~36 ~1 ~27 dirt 0  
fill ~36 ~1 ~44 ~36 ~1 ~47 dirt 0  
fill ~37 ~1 ~44 ~38 ~1 ~44 dirt 1  
fill ~37 ~1 ~45 ~39 ~1 ~45 dirt 1  
fill ~37 ~1 ~46 ~37 ~13 ~46 dirt 1  
fill ~37 ~1 ~47 ~40 ~1 ~47 dirt 1  
fill ~39 ~1 ~46 ~39 ~14 ~46 dirt 1  
fill ~49 ~1 ~16 ~49 ~1 ~18 grass 0  
fill ~50 ~1 ~16 ~50 ~17 ~16 wool 7  
fill ~50 ~1 ~17 ~50 ~1 ~18 grass 0  
fill ~50 ~1 ~19 ~52 ~1 ~19 wool 7  
fill ~51 ~1 ~17 ~51 ~7 ~17 wool 7 
setblock ~51 ~1 ~18 grass 0  
fill ~52 ~1 ~18 ~52 ~5 ~18 wool 7  
fill ~29 ~2 ~32 ~36 ~2 ~32 dirt 0  
fill ~29 ~2 ~33 ~32 ~2 ~33 dirt 0  
fill ~29 ~2 ~34 ~32 ~2 ~34 dirt 0  
fill ~29 ~2 ~35 ~33 ~2 ~35 dirt 0  
fill ~31 ~2 ~41 ~33 ~2 ~41 stained_hardened_clay 7  
fill ~31 ~2 ~42 ~33 ~2 ~42 stained_hardened_clay 7  
fill ~31 ~2 ~43 ~34 ~2 ~43 grass 0  
fill ~32 ~2 ~31 ~36 ~2 ~31 dirt 0  
fill ~32 ~2 ~36 ~33 ~2 ~36 dirt 1  
fill ~32 ~2 ~40 ~36 ~2 ~40 grass 0  
fill ~32 ~2 ~44 ~33 ~2 ~44 grass 0  
fill ~32 ~2 ~45 ~34 ~2 ~45 grass 0  
fill ~32 ~2 ~46 ~34 ~2 ~46 grass 0  
fill ~33 ~2 ~30 ~36 ~2 ~30 dirt 0  
fill ~33 ~2 ~33 ~35 ~2 ~33 dirt 1  
fill ~33 ~2 ~34 ~36 ~2 ~34 dirt 1  
fill ~33 ~2 ~47 ~35 ~2 ~47 grass 0  
fill ~34 ~2 ~26 ~37 ~2 ~26 dirt 1  
fill ~34 ~2 ~27 ~35 ~2 ~27 dirt 0  
fill ~34 ~2 ~28 ~36 ~2 ~28 dirt 0  
fill ~34 ~2 ~29 ~36 ~2 ~29 dirt 0  
fill ~34 ~2 ~35 ~35 ~2 ~35 dirt 1  
fill ~34 ~2 ~39 ~36 ~2 ~39 grass 0  
fill ~34 ~2 ~41 ~37 ~2 ~41 wool 7  
fill ~34 ~2 ~42 ~36 ~2 ~42 wool 7  
fill ~34 ~2 ~44 ~35 ~2 ~44 wool 7  
fill ~34 ~2 ~48 ~35 ~2 ~48 grass 0  
fill ~35 ~2 ~37 ~36 ~2 ~37 grass 0  
fill ~35 ~2 ~38 ~36 ~2 ~38 grass 0  
fill ~35 ~2 ~43 ~36 ~2 ~43 wool 7  
fill ~35 ~2 ~45 ~35 ~6 ~45 wool 7  
fill ~35 ~2 ~46 ~35 ~6 ~46 wool 7 
setblock ~36 ~2 ~25 dirt 1  
fill ~36 ~2 ~27 ~38 ~2 ~27 dirt 1 
setblock ~36 ~2 ~33 dirt 0  
fill ~36 ~2 ~44 ~39 ~2 ~44 dirt 1  
fill ~36 ~2 ~45 ~40 ~2 ~45 dirt 1  
fill ~36 ~2 ~46 ~36 ~13 ~46 dirt 1  
fill ~36 ~2 ~47 ~40 ~2 ~47 dirt 1 
setblock ~36 ~2 ~48 dirt 0 
setblock ~36 ~2 ~49 grass 0  
fill ~37 ~2 ~25 ~37 ~19 ~25 wool 7 
setblock ~37 ~2 ~28 dirt 1  
fill ~37 ~2 ~33 ~37 ~25 ~33 wool 7  
fill ~37 ~2 ~36 ~38 ~2 ~36 wool 7  
fill ~37 ~2 ~37 ~38 ~2 ~37 wool 7  
fill ~37 ~2 ~38 ~38 ~2 ~38 wool 7  
fill ~37 ~2 ~39 ~38 ~2 ~39 wool 7  
fill ~37 ~2 ~40 ~38 ~2 ~40 wool 7  
fill ~37 ~2 ~42 ~39 ~2 ~42 dirt 1  
fill ~37 ~2 ~43 ~38 ~2 ~43 dirt 1  
fill ~37 ~2 ~48 ~39 ~2 ~48 dirt 1  
fill ~37 ~2 ~49 ~37 ~3 ~49 dirt 1  
fill ~38 ~2 ~26 ~38 ~10 ~26 wool 7  
fill ~38 ~2 ~28 ~38 ~10 ~28 wool 7  
fill ~38 ~2 ~41 ~39 ~2 ~41 dirt 1  
fill ~39 ~2 ~36 ~41 ~2 ~36 grass 0  
fill ~39 ~2 ~37 ~42 ~2 ~37 grass 0  
fill ~39 ~2 ~38 ~43 ~2 ~38 grass 0  
fill ~39 ~2 ~39 ~41 ~2 ~39 grass 0  
fill ~39 ~2 ~40 ~40 ~2 ~40 grass 0 
setblock ~39 ~2 ~43 dirt 0  
fill ~46 ~2 ~24 ~46 ~8 ~24 dirt 1  
fill ~46 ~2 ~25 ~48 ~2 ~25 dirt 1  
fill ~47 ~2 ~15 ~48 ~2 ~15 grass 0  
fill ~47 ~2 ~16 ~48 ~2 ~16 grass 0  
fill ~47 ~2 ~17 ~48 ~2 ~17 grass 0  
fill ~47 ~2 ~23 ~49 ~2 ~23 dirt 1 
setblock ~47 ~2 ~24 dirt 0  
fill ~48 ~2 ~18 ~52 ~2 ~18 wool 7  
fill ~48 ~2 ~24 ~48 ~8 ~24 dirt 1  
fill ~49 ~2 ~15 ~49 ~16 ~15 wool 7  
fill ~49 ~2 ~16 ~49 ~17 ~16 wool 7  
fill ~49 ~2 ~17 ~52 ~2 ~17 wool 7  
fill ~49 ~2 ~19 ~52 ~2 ~19 wool 7  
fill ~51 ~2 ~16 ~51 ~6 ~16 wool 7  
fill ~27 ~3 ~31 ~31 ~3 ~31 dirt 0  
fill ~27 ~3 ~32 ~28 ~3 ~32 dirt 0  
fill ~27 ~3 ~33 ~27 ~3 ~35 grass 0  
fill ~28 ~3 ~30 ~32 ~3 ~30 dirt 0 
setblock ~28 ~3 ~33 dirt 0  
fill ~28 ~3 ~34 ~28 ~3 ~36 grass 0  
fill ~29 ~3 ~32 ~36 ~3 ~32 dirt 1  
fill ~29 ~3 ~33 ~36 ~3 ~33 dirt 1  
fill ~29 ~3 ~34 ~35 ~3 ~34 dirt 1  
fill ~29 ~3 ~35 ~35 ~3 ~35 dirt 1  
fill ~29 ~3 ~36 ~31 ~3 ~36 grass 0  
fill ~29 ~3 ~37 ~31 ~3 ~37 grass 0  
fill ~29 ~3 ~39 ~33 ~3 ~39 grass 0  
fill ~29 ~3 ~40 ~31 ~3 ~40 grass 0  
fill ~29 ~3 ~41 ~33 ~3 ~41 stained_hardened_clay 7  
fill ~29 ~3 ~42 ~33 ~3 ~42 stained_hardened_clay 7  
fill ~30 ~3 ~38 ~34 ~3 ~38 grass 0  
fill ~30 ~3 ~43 ~33 ~3 ~43 stained_hardened_clay 7  
fill ~30 ~3 ~44 ~31 ~3 ~44 grass 0  
fill ~30 ~3 ~45 ~31 ~3 ~45 grass 0  
fill ~31 ~3 ~29 ~33 ~3 ~29 dirt 0  
fill ~31 ~3 ~46 ~35 ~3 ~46 wool 7  
fill ~31 ~3 ~47 ~32 ~3 ~47 grass 0  
fill ~32 ~3 ~28 ~33 ~3 ~28 dirt 0  
fill ~32 ~3 ~31 ~36 ~3 ~31 dirt 1  
fill ~32 ~3 ~36 ~33 ~3 ~36 wool 7  
fill ~32 ~3 ~40 ~33 ~3 ~40 stained_hardened_clay 7  
fill ~32 ~3 ~44 ~33 ~3 ~44 stained_hardened_clay 7  
fill ~32 ~3 ~45 ~32 ~3 ~40 stained_hardened_clay 7  
fill ~32 ~3 ~48 ~33 ~3 ~48 dirt 0  
fill ~32 ~3 ~49 ~34 ~3 ~49 dirt 0  
fill ~33 ~3 ~26 ~36 ~3 ~26 dirt 1  
fill ~33 ~3 ~27 ~36 ~3 ~27 dirt 1  
fill ~33 ~3 ~30 ~36 ~3 ~30 dirt 1  
fill ~33 ~3 ~45 ~35 ~3 ~45 wool 7  
fill ~33 ~3 ~47 ~35 ~3 ~47 wool 7  
fill ~33 ~3 ~50 ~34 ~3 ~50 dirt 0  
fill ~34 ~3 ~25 ~35 ~3 ~25 dirt 1  
fill ~34 ~3 ~28 ~36 ~3 ~28 dirt 1  
fill ~34 ~3 ~29 ~36 ~3 ~29 dirt 1  
fill ~34 ~3 ~36 ~36 ~3 ~36 grass 0  
fill ~34 ~3 ~37 ~38 ~3 ~37 wool 7  
fill ~34 ~3 ~39 ~41 ~3 ~39 wool 7  
fill ~34 ~3 ~40 ~40 ~3 ~40 wool 7  
fill ~34 ~3 ~41 ~37 ~3 ~41 wool 7  
fill ~34 ~3 ~42 ~36 ~3 ~42 wool 7  
fill ~34 ~3 ~43 ~36 ~3 ~43 wool 7  
fill ~34 ~3 ~44 ~35 ~3 ~44 wool 7  
fill ~34 ~3 ~48 ~35 ~3 ~48 wool 7  
fill ~35 ~3 ~38 ~40 ~3 ~38 wool 7  
fill ~35 ~3 ~49 ~35 ~3 ~50 grass 0  
fill ~36 ~3 ~24 ~37 ~3 ~24 wool 7  
fill ~36 ~3 ~25 ~36 ~19 ~25 wool 7  
fill ~36 ~3 ~34 ~38 ~3 ~34 wool 7 
setblock ~36 ~3 ~35 grass 0  
fill ~36 ~3 ~44 ~40 ~3 ~44 dirt 1  
fill ~36 ~3 ~45 ~40 ~3 ~45 dirt 1  
fill ~36 ~3 ~47 ~39 ~3 ~47 dirt 1  
fill ~36 ~3 ~48 ~39 ~3 ~48 dirt 1  
fill ~36 ~3 ~49 ~36 ~10 ~49 wool 7  
fill ~36 ~3 ~50 ~37 ~3 ~50 wool 7  
fill ~37 ~3 ~26 ~37 ~19 ~26 wool 7  
fill ~37 ~3 ~27 ~38 ~3 ~27 wool 7  
fill ~37 ~3 ~28 ~37 ~20 ~28 wool 7  
fill ~37 ~3 ~29 ~38 ~3 ~29 wool 7  
fill ~37 ~3 ~30 ~37 ~21 ~30 wool 7  
fill ~37 ~3 ~31 ~37 ~22 ~31 wool 7  
fill ~37 ~3 ~32 ~37 ~25 ~32 wool 7  
fill ~37 ~3 ~35 ~38 ~3 ~35 wool 7  
fill ~37 ~3 ~36 ~38 ~3 ~36 wool 7  
fill ~37 ~3 ~42 ~41 ~3 ~42 dirt 1  
fill ~37 ~3 ~43 ~40 ~3 ~43 dirt 1  
fill ~38 ~3 ~25 ~40 ~3 ~25 wool 7  
fill ~38 ~3 ~33 ~38 ~15 ~33 wool 7  
fill ~38 ~3 ~41 ~41 ~3 ~41 dirt 1 
setblock ~38 ~3 ~49 dirt 1  
fill ~39 ~3 ~26 ~42 ~3 ~26 wool 7  
fill ~39 ~3 ~27 ~42 ~3 ~27 grass 0  
fill ~39 ~3 ~28 ~40 ~3 ~28 grass 0  
fill ~39 ~3 ~34 ~43 ~3 ~34 grass 0  
fill ~39 ~3 ~35 ~44 ~3 ~35 grass 0  
fill ~39 ~3 ~36 ~41 ~3 ~36 stained_hardened_clay 7  
fill ~39 ~3 ~37 ~42 ~3 ~37 stained_hardened_clay 7  
fill ~41 ~3 ~38 ~44 ~3 ~38 stained_hardened_clay 7  
fill ~41 ~3 ~40 ~43 ~3 ~40 grass 0  
fill ~42 ~3 ~36 ~44 ~3 ~36 grass 0  
fill ~42 ~3 ~39 ~43 ~3 ~39 grass 0  
fill ~43 ~3 ~26 ~47 ~3 ~26 dirt 1  
fill ~43 ~3 ~27 ~45 ~3 ~27 dirt 0  
fill ~43 ~3 ~37 ~44 ~3 ~37 grass 0  
fill ~44 ~3 ~16 ~46 ~3 ~16 grass 0  
fill ~44 ~3 ~17 ~46 ~3 ~17 grass 0  
fill ~44 ~3 ~25 ~48 ~3 ~25 dirt 1  
fill ~45 ~3 ~15 ~46 ~3 ~15 grass 0  
fill ~45 ~3 ~18 ~47 ~3 ~18 grass 0  
fill ~45 ~3 ~24 ~45 ~5 ~24 dirt 1 
setblock ~46 ~3 ~14 grass 0  
fill ~46 ~3 ~23 ~49 ~3 ~23 dirt 1  
fill ~47 ~3 ~14 ~48 ~3 ~14 wool 7  
fill ~47 ~3 ~15 ~48 ~3 ~15 stained_hardened_clay 7  
fill ~47 ~3 ~16 ~48 ~3 ~16 stained_hardened_clay 7  
fill ~47 ~3 ~17 ~48 ~3 ~17 stained_hardened_clay 7 
setblock ~47 ~3 ~19 grass 0  
fill ~47 ~3 ~24 ~47 ~8 ~24 dirt 1  
fill ~48 ~3 ~18 ~52 ~3 ~18 wool 7  
fill ~48 ~3 ~19 ~50 ~3 ~19 wool 7  
fill ~48 ~3 ~22 ~49 ~3 ~22 dirt 1  
fill ~49 ~3 ~17 ~52 ~3 ~17 wool 7  
fill ~49 ~3 ~24 ~49 ~4 ~24 dirt 1  
fill ~50 ~3 ~15 ~50 ~15 ~15 wool 7  
fill ~51 ~3 ~19 ~51 ~5 ~19 dirt 1  
fill ~52 ~3 ~19 ~52 ~4 ~19 wool 7  
fill ~22 ~4 ~33 ~22 ~6 ~33 wool 7  
fill ~22 ~4 ~34 ~22 ~6 ~34 wool 7  
fill ~22 ~4 ~35 ~22 ~6 ~35 wool 7  
fill ~23 ~4 ~32 ~26 ~4 ~32 grass 0  
fill ~23 ~4 ~33 ~26 ~4 ~33 grass 0  
fill ~23 ~4 ~34 ~26 ~4 ~34 grass 0  
fill ~23 ~4 ~35 ~26 ~4 ~35 grass 0  
fill ~24 ~4 ~31 ~26 ~4 ~31 grass 0  
fill ~25 ~4 ~30 ~27 ~4 ~30 grass 0  
fill ~26 ~4 ~29 ~28 ~4 ~29 grass 0  
fill ~26 ~4 ~36 ~26 ~16 ~36 wool 7  
fill ~27 ~4 ~24 ~28 ~4 ~24 grass 0  
fill ~27 ~4 ~25 ~27 ~8 ~25 wool 7  
fill ~27 ~4 ~26 ~27 ~7 ~26 wool 7  
fill ~27 ~4 ~27 ~28 ~4 ~27 grass 0  
fill ~27 ~4 ~28 ~28 ~4 ~28 grass 0  
fill ~27 ~4 ~31 ~36 ~4 ~31 dirt 1  
fill ~27 ~4 ~32 ~36 ~4 ~32 dirt 1  
fill ~27 ~4 ~33 ~27 ~16 ~33 wool 7  
fill ~27 ~4 ~34 ~28 ~4 ~34 wool 7  
fill ~27 ~4 ~35 ~38 ~4 ~35 wool 7 
setblock ~27 ~4 ~36 grass 0  
fill ~27 ~4 ~37 ~27 ~6 ~37 wool 7 
setblock ~28 ~4 ~23 grass 0  
fill ~28 ~4 ~25 ~35 ~4 ~25 dirt 1  
fill ~28 ~4 ~26 ~35 ~4 ~26 dirt 1  
fill ~28 ~4 ~30 ~36 ~4 ~30 dirt 1  
fill ~28 ~4 ~33 ~35 ~4 ~33 dirt 1  
fill ~28 ~4 ~36 ~38 ~4 ~36 wool 7  
fill ~28 ~4 ~37 ~28 ~4 ~38 grass 0  
fill ~28 ~4 ~39 ~35 ~4 ~39 stained_hardened_clay 7  
fill ~28 ~4 ~40 ~34 ~4 ~40 stained_hardened_clay 7  
fill ~28 ~4 ~41 ~34 ~4 ~41 stained_hardened_clay 7  
fill ~28 ~4 ~42 ~33 ~4 ~42 stained_hardened_clay 7  
fill ~29 ~4 ~23 ~29 ~4 ~24 dirt 0  
fill ~29 ~4 ~27 ~32 ~4 ~27 dirt 0  
fill ~29 ~4 ~28 ~31 ~4 ~28 dirt 0  
fill ~29 ~4 ~29 ~30 ~4 ~29 dirt 0  
fill ~29 ~4 ~34 ~35 ~4 ~34 dirt 1  
fill ~29 ~4 ~37 ~31 ~4 ~37 wool 7 
setblock ~29 ~4 ~38 grass 0  
fill ~29 ~4 ~43 ~33 ~4 ~43 stained_hardened_clay 7  
fill ~29 ~4 ~44 ~32 ~4 ~44 stained_hardened_clay 7  
fill ~29 ~4 ~45 ~35 ~4 ~45 wool 7  
fill ~29 ~4 ~46 ~29 ~9 ~46 wool 7  
fill ~30 ~4 ~24 ~31 ~4 ~24 dirt 0  
fill ~30 ~4 ~38 ~34 ~4 ~38 stained_hardened_clay 7 
setblock ~30 ~4 ~46 grass 0  
fill ~30 ~4 ~47 ~35 ~4 ~47 wool 7  
fill ~30 ~4 ~48 ~30 ~8 ~48 dirt 1  
fill ~31 ~4 ~29 ~36 ~4 ~29 dirt 1  
fill ~31 ~4 ~46 ~35 ~4 ~46 wool 7 
setblock ~31 ~4 ~48 dirt 0  
fill ~31 ~4 ~49 ~34 ~4 ~49 dirt 1  
fill ~32 ~4 ~28 ~36 ~4 ~28 dirt 1  
fill ~32 ~4 ~37 ~33 ~4 ~37 grass 0  
fill ~32 ~4 ~48 ~33 ~4 ~48 dirt 1  
fill ~32 ~4 ~50 ~34 ~4 ~50 dirt 1 
setblock ~33 ~4 ~24 dirt 0  
fill ~33 ~4 ~27 ~36 ~4 ~27 dirt 1  
fill ~33 ~4 ~44 ~35 ~4 ~44 wool 7  
fill ~33 ~4 ~51 ~33 ~11 ~51 dirt 1  
fill ~34 ~4 ~24 ~34 ~11 ~24 dirt 1  
fill ~34 ~4 ~37 ~38 ~4 ~37 wool 7  
fill ~34 ~4 ~42 ~36 ~4 ~42 wool 7  
fill ~34 ~4 ~43 ~36 ~4 ~43 wool 7  
fill ~34 ~4 ~48 ~35 ~4 ~48 wool 7 
setblock ~34 ~4 ~51 dirt 0  
fill ~34 ~4 ~52 ~35 ~4 ~52 grass 0  
fill ~35 ~4 ~24 ~38 ~4 ~24 wool 7  
fill ~35 ~4 ~38 ~40 ~4 ~38 wool 7  
fill ~35 ~4 ~40 ~44 ~4 ~40 wool 7  
fill ~35 ~4 ~41 ~37 ~4 ~41 wool 7  
fill ~35 ~4 ~49 ~35 ~10 ~49 wool 7  
fill ~35 ~4 ~50 ~37 ~4 ~50 wool 7 
setblock ~35 ~4 ~51 grass 0  
fill ~36 ~4 ~26 ~36 ~5 ~26 wool 7  
fill ~36 ~4 ~33 ~36 ~25 ~33 wool 7  
fill ~36 ~4 ~34 ~38 ~4 ~34 wool 7  
fill ~36 ~4 ~39 ~44 ~4 ~39 wool 7  
fill ~36 ~4 ~44 ~41 ~4 ~44 dirt 1  
fill ~36 ~4 ~45 ~40 ~4 ~45 dirt 1  
fill ~36 ~4 ~47 ~39 ~4 ~47 dirt 1  
fill ~36 ~4 ~48 ~39 ~4 ~48 dirt 1  
fill ~36 ~4 ~51 ~37 ~4 ~51 wool 7 
setblock ~37 ~4 ~23 wool 7  
fill ~37 ~4 ~27 ~42 ~4 ~27 wool 7  
fill ~37 ~4 ~29 ~40 ~4 ~29 wool 7  
fill ~37 ~4 ~42 ~42 ~4 ~42 dirt 1  
fill ~37 ~4 ~43 ~41 ~4 ~43 dirt 1  
fill ~37 ~4 ~49 ~38 ~4 ~49 wool 7  
fill ~38 ~4 ~23 ~38 ~12 ~23 stained_hardened_clay 7  
fill ~38 ~4 ~25 ~43 ~4 ~25 wool 7  
fill ~38 ~4 ~30 ~39 ~4 ~30 wool 7  
fill ~38 ~4 ~31 ~38 ~17 ~31 wool 7  
fill ~38 ~4 ~32 ~38 ~16 ~32 wool 7  
fill ~38 ~4 ~41 ~42 ~4 ~41 dirt 1  
fill ~39 ~4 ~23 ~39 ~4 ~24 grass 0  
fill ~39 ~4 ~26 ~43 ~4 ~26 wool 7  
fill ~39 ~4 ~28 ~40 ~4 ~28 wool 7 
setblock ~39 ~4 ~32 stained_hardened_clay 7 
setblock ~39 ~4 ~33 grass 0  
fill ~39 ~4 ~34 ~43 ~4 ~34 stained_hardened_clay 7  
fill ~39 ~4 ~35 ~44 ~4 ~35 stained_hardened_clay 7  
fill ~39 ~4 ~36 ~44 ~4 ~36 stained_hardened_clay 7  
fill ~39 ~4 ~37 ~44 ~4 ~37 stained_hardened_clay 7 
setblock ~40 ~4 ~24 wool 7  
fill ~40 ~4 ~33 ~43 ~4 ~33 stained_hardened_clay 7  
fill ~41 ~4 ~16 ~43 ~4 ~16 grass 0  
fill ~41 ~4 ~17 ~43 ~4 ~17 grass 0  
fill ~41 ~4 ~24 ~43 ~4 ~24 grass 0  
fill ~41 ~4 ~28 ~42 ~4 ~28 grass 0  
fill ~41 ~4 ~29 ~43 ~4 ~29 grass 0  
fill ~41 ~4 ~38 ~45 ~4 ~38 stained_hardened_clay 7  
fill ~42 ~4 ~14 ~45 ~4 ~14 grass 0  
fill ~42 ~4 ~15 ~44 ~4 ~15 grass 0  
fill ~42 ~4 ~18 ~44 ~4 ~18 grass 0  
fill ~42 ~4 ~19 ~46 ~4 ~19 grass 0  
fill ~43 ~4 ~13 ~45 ~4 ~13 grass 0  
fill ~43 ~4 ~27 ~46 ~4 ~27 dirt 1 
setblock ~43 ~4 ~28 dirt 0  
fill ~43 ~4 ~41 ~43 ~12 ~41 wool 7  
fill ~44 ~4 ~16 ~48 ~4 ~16 stained_hardened_clay 7  
fill ~44 ~4 ~17 ~48 ~4 ~17 stained_hardened_clay 7  
fill ~44 ~4 ~20 ~46 ~4 ~20 grass 0  
fill ~44 ~4 ~24 ~44 ~24 ~24 wool 7  
fill ~44 ~4 ~25 ~48 ~4 ~25 dirt 1  
fill ~44 ~4 ~26 ~47 ~4 ~26 dirt 1  
fill ~44 ~4 ~28 ~45 ~4 ~28 dirt 1  
fill ~44 ~4 ~33 ~46 ~4 ~33 grass 0  
fill ~44 ~4 ~34 ~46 ~4 ~34 grass 0  
fill ~45 ~4 ~15 ~48 ~4 ~15 stained_hardened_clay 7  
fill ~45 ~4 ~18 ~47 ~4 ~18 stained_hardened_clay 7  
fill ~45 ~4 ~35 ~46 ~4 ~35 grass 0  
fill ~45 ~4 ~36 ~46 ~4 ~36 grass 0  
fill ~45 ~4 ~37 ~46 ~4 ~37 grass 0 
setblock ~45 ~4 ~39 stained_hardened_clay 7  
fill ~46 ~4 ~13 ~47 ~4 ~13 wool 7  
fill ~46 ~4 ~14 ~46 ~6 ~14 stained_hardened_clay 7  
fill ~46 ~4 ~23 ~49 ~4 ~23 dirt 1  
fill ~47 ~4 ~14 ~49 ~4 ~14 wool 7  
fill ~47 ~4 ~19 ~49 ~4 ~19 wool 7  
fill ~47 ~4 ~20 ~47 ~11 ~20 wool 7  
fill ~48 ~4 ~18 ~52 ~4 ~18 wool 7  
fill ~48 ~4 ~22 ~48 ~3 ~22 dirt 1  
fill ~49 ~4 ~17 ~52 ~4 ~17 wool 7  
fill ~50 ~4 ~19 ~50 ~7 ~19 dirt 1  
fill ~21 ~5 ~33 ~21 ~6 ~33 wool 7  
fill ~21 ~5 ~34 ~21 ~6 ~34 wool 7  
fill ~21 ~5 ~35 ~21 ~5 ~33 wool 7  
fill ~22 ~5 ~28 ~22 ~6 ~28 wool 7  
fill ~22 ~5 ~29 ~22 ~6 ~29 wool 7  
fill ~22 ~5 ~30 ~22 ~7 ~30 wool 7  
fill ~22 ~5 ~31 ~22 ~18 ~31 wool 7  
fill ~22 ~5 ~32 ~27 ~5 ~32 wool 7  
fill ~22 ~5 ~36 ~38 ~5 ~36 wool 7  
fill ~23 ~5 ~26 ~28 ~5 ~26 wool 7  
fill ~23 ~5 ~27 ~26 ~5 ~27 grass 0  
fill ~23 ~5 ~28 ~26 ~5 ~28 grass 0  
fill ~23 ~5 ~29 ~25 ~5 ~29 grass 0  
fill ~23 ~5 ~30 ~24 ~5 ~30 grass 0  
fill ~23 ~5 ~31 ~23 ~5 ~27 grass 0  
fill ~23 ~5 ~33 ~28 ~5 ~33 wool 7  
fill ~23 ~5 ~34 ~38 ~5 ~34 wool 7  
fill ~23 ~5 ~35 ~38 ~5 ~35 wool 7  
fill ~24 ~5 ~25 ~28 ~5 ~25 wool 7  
fill ~24 ~5 ~31 ~27 ~5 ~31 wool 7  
fill ~25 ~5 ~24 ~26 ~5 ~24 grass 0  
fill ~25 ~5 ~30 ~27 ~5 ~30 wool 7  
fill ~26 ~5 ~23 ~27 ~5 ~23 grass 0  
fill ~26 ~5 ~29 ~28 ~5 ~29 wool 7  
fill ~26 ~5 ~37 ~26 ~16 ~37 wool 7 
setblock ~27 ~5 ~22 grass 0  
fill ~27 ~5 ~24 ~28 ~5 ~24 wool 7  
fill ~27 ~5 ~27 ~28 ~5 ~27 wool 7  
fill ~27 ~5 ~28 ~28 ~5 ~28 wool 7  
fill ~27 ~5 ~38 ~36 ~5 ~38 stained_hardened_clay 7  
fill ~27 ~5 ~39 ~35 ~5 ~39 stained_hardened_clay 7  
fill ~27 ~5 ~40 ~35 ~5 ~40 stained_hardened_clay 7  
fill ~27 ~5 ~41 ~34 ~5 ~41 stained_hardened_clay 7  
fill ~27 ~5 ~43 ~29 ~5 ~43 wool 7  
fill ~28 ~5 ~22 ~28 ~18 ~22 wool 7  
fill ~28 ~5 ~23 ~28 ~18 ~23 wool 7  
fill ~28 ~5 ~30 ~36 ~5 ~30 dirt 1  
fill ~28 ~5 ~31 ~36 ~5 ~31 dirt 1  
fill ~28 ~5 ~32 ~35 ~5 ~32 dirt 1 
setblock ~28 ~5 ~37 wool 7  
fill ~28 ~5 ~42 ~33 ~5 ~42 stained_hardened_clay 7  
fill ~28 ~5 ~44 ~35 ~5 ~44 wool 7  
fill ~28 ~5 ~45 ~35 ~5 ~45 wool 7  
fill ~29 ~5 ~21 ~31 ~5 ~21 dirt 0  
fill ~29 ~5 ~22 ~32 ~5 ~22 dirt 0  
fill ~29 ~5 ~23 ~29 ~9 ~23 dirt 1  
fill ~29 ~5 ~24 ~31 ~5 ~24 dirt 1  
fill ~29 ~5 ~25 ~35 ~5 ~25 dirt 1  
fill ~29 ~5 ~26 ~35 ~5 ~26 dirt 1  
fill ~29 ~5 ~27 ~36 ~5 ~27 dirt 1  
fill ~29 ~5 ~28 ~36 ~5 ~28 dirt 1  
fill ~29 ~5 ~29 ~36 ~5 ~29 dirt 1  
fill ~29 ~5 ~33 ~35 ~5 ~33 dirt 1  
fill ~29 ~5 ~37 ~35 ~5 ~37 stained_hardened_clay 7  
fill ~29 ~5 ~47 ~32 ~5 ~47 dirt 1  
fill ~30 ~5 ~23 ~33 ~5 ~23 dirt 0  
fill ~30 ~5 ~43 ~32 ~5 ~43 stained_hardened_clay 7  
fill ~30 ~5 ~46 ~35 ~5 ~46 wool 7  
fill ~30 ~5 ~49 ~34 ~5 ~49 dirt 1  
fill ~31 ~5 ~20 ~34 ~5 ~20 grass 0  
fill ~31 ~5 ~48 ~34 ~5 ~48 dirt 1  
fill ~31 ~5 ~50 ~34 ~5 ~50 dirt 1  
fill ~32 ~5 ~21 ~34 ~5 ~21 grass 0 
setblock ~32 ~5 ~24 dirt 0  
fill ~32 ~5 ~51 ~32 ~10 ~51 dirt 1  
fill ~33 ~5 ~19 ~34 ~5 ~19 grass 0  
fill ~33 ~5 ~22 ~34 ~5 ~22 grass 0  
fill ~33 ~5 ~24 ~33 ~12 ~24 dirt 1  
fill ~33 ~5 ~43 ~36 ~5 ~43 wool 7  
fill ~33 ~5 ~47 ~35 ~5 ~47 wool 7  
fill ~33 ~5 ~52 ~33 ~10 ~52 dirt 1 
setblock ~34 ~5 ~23 grass 0  
fill ~34 ~5 ~42 ~36 ~5 ~42 wool 7 
setblock ~34 ~5 ~51 dirt 1  
fill ~34 ~5 ~52 ~36 ~5 ~52 wool 7  
fill ~34 ~5 ~53 ~35 ~5 ~53 wool 7  
fill ~35 ~5 ~23 ~36 ~5 ~23 wool 7  
fill ~35 ~5 ~24 ~38 ~5 ~24 wool 7  
fill ~35 ~5 ~41 ~37 ~5 ~41 wool 7  
fill ~35 ~5 ~48 ~37 ~5 ~48 wool 7  
fill ~35 ~5 ~50 ~38 ~5 ~50 wool 7  
fill ~35 ~5 ~51 ~37 ~5 ~51 wool 7  
fill ~36 ~5 ~32 ~36 ~25 ~32 wool 7  
fill ~36 ~5 ~37 ~38 ~5 ~37 wool 7  
fill ~36 ~5 ~39 ~45 ~5 ~39 wool 7  
fill ~36 ~5 ~40 ~45 ~5 ~40 wool 7  
fill ~36 ~5 ~44 ~42 ~5 ~44 dirt 1  
fill ~36 ~5 ~45 ~41 ~5 ~45 dirt 1  
fill ~36 ~5 ~47 ~40 ~5 ~47 dirt 1  
fill ~37 ~5 ~22 ~39 ~5 ~22 stained_hardened_clay 7  
fill ~37 ~5 ~23 ~37 ~11 ~23 stained_hardened_clay 7  
fill ~37 ~5 ~27 ~42 ~5 ~27 wool 7  
fill ~37 ~5 ~29 ~43 ~5 ~29 wool 7  
fill ~37 ~5 ~38 ~40 ~5 ~38 wool 7  
fill ~37 ~5 ~42 ~43 ~5 ~42 dirt 1  
fill ~37 ~5 ~43 ~43 ~5 ~43 dirt 1  
fill ~37 ~5 ~49 ~38 ~5 ~49 wool 7  
fill ~37 ~5 ~52 ~37 ~8 ~52 stained_hardened_clay 7  
fill ~38 ~5 ~25 ~44 ~5 ~25 wool 7  
fill ~38 ~5 ~30 ~42 ~5 ~30 wool 7  
fill ~38 ~5 ~41 ~42 ~5 ~41 dirt 1  
fill ~38 ~5 ~48 ~39 ~5 ~48 dirt 1  
fill ~39 ~5 ~23 ~39 ~12 ~23 stained_hardened_clay 7  
fill ~39 ~5 ~24 ~40 ~5 ~24 stained_hardened_clay 7  
fill ~39 ~5 ~26 ~43 ~5 ~26 wool 7  
fill ~39 ~5 ~28 ~42 ~5 ~28 wool 7  
fill ~39 ~5 ~31 ~39 ~9 ~31 wool 7  
fill ~39 ~5 ~32 ~39 ~14 ~32 wool 7  
fill ~39 ~5 ~33 ~43 ~5 ~33 stained_hardened_clay 7  
fill ~39 ~5 ~34 ~44 ~5 ~34 stained_hardened_clay 7  
fill ~39 ~5 ~35 ~45 ~5 ~35 stained_hardened_clay 7  
fill ~39 ~5 ~36 ~46 ~5 ~36 stained_hardened_clay 7  
fill ~39 ~5 ~37 ~47 ~5 ~37 stained_hardened_clay 7  
fill ~40 ~5 ~13 ~42 ~5 ~13 grass 0  
fill ~40 ~5 ~14 ~41 ~5 ~14 grass 0  
fill ~40 ~5 ~15 ~41 ~5 ~15 grass 0 
setblock ~40 ~5 ~16 wool 7  
fill ~40 ~5 ~17 ~48 ~5 ~17 stained_hardened_clay 7  
fill ~40 ~5 ~18 ~41 ~5 ~18 grass 0  
fill ~40 ~5 ~22 ~44 ~5 ~22 grass 0  
fill ~40 ~5 ~23 ~44 ~5 ~23 grass 0  
fill ~40 ~5 ~32 ~42 ~5 ~32 stained_hardened_clay 7  
fill ~41 ~5 ~16 ~48 ~5 ~16 stained_hardened_clay 7  
fill ~41 ~5 ~19 ~46 ~5 ~19 stained_hardened_clay 7  
fill ~41 ~5 ~20 ~43 ~5 ~20 grass 0  
fill ~41 ~5 ~24 ~44 ~5 ~24 wool 7  
fill ~41 ~5 ~38 ~46 ~5 ~38 stained_hardened_clay 7 
setblock ~42 ~5 ~12 grass 0  
fill ~42 ~5 ~14 ~43 ~5 ~14 wool 7  
fill ~42 ~5 ~15 ~48 ~5 ~15 stained_hardened_clay 7  
fill ~42 ~5 ~18 ~47 ~5 ~18 stained_hardened_clay 7  
fill ~42 ~5 ~21 ~44 ~5 ~21 grass 0  
fill ~43 ~5 ~12 ~46 ~5 ~12 wool 7  
fill ~43 ~5 ~13 ~48 ~5 ~13 wool 7  
fill ~43 ~5 ~27 ~47 ~5 ~27 dirt 1  
fill ~43 ~5 ~28 ~46 ~5 ~28 dirt 1  
fill ~43 ~5 ~30 ~44 ~5 ~30 grass 0  
fill ~43 ~5 ~31 ~45 ~5 ~31 grass 0  
fill ~43 ~5 ~32 ~45 ~5 ~32 grass 0  
fill ~44 ~5 ~14 ~46 ~5 ~14 stained_hardened_clay 7  
fill ~44 ~5 ~20 ~45 ~5 ~20 stained_hardened_clay 7  
fill ~44 ~5 ~26 ~47 ~5 ~26 dirt 1 
setblock ~44 ~5 ~29 dirt 0  
fill ~44 ~5 ~33 ~46 ~5 ~33 wool 7  
fill ~44 ~5 ~41 ~45 ~5 ~41 wool 7  
fill ~44 ~5 ~42 ~44 ~14 ~42 wool 7  
fill ~45 ~5 ~21 ~46 ~5 ~21 wool 7  
fill ~45 ~5 ~23 ~45 ~14 ~23 wool 7  
fill ~45 ~5 ~25 ~48 ~5 ~25 dirt 1  
fill ~45 ~5 ~29 ~45 ~6 ~29 dirt 1  
fill ~45 ~5 ~34 ~46 ~5 ~34 wool 7  
fill ~46 ~5 ~20 ~46 ~11 ~20 wool 7  
fill ~46 ~5 ~23 ~48 ~5 ~23 dirt 1  
fill ~46 ~5 ~30 ~48 ~5 ~30 dirt 0  
fill ~46 ~5 ~31 ~48 ~5 ~31 dirt 0  
fill ~46 ~5 ~32 ~48 ~5 ~32 dirt 0  
fill ~46 ~5 ~35 ~46 ~19 ~35 wool 7 
setblock ~46 ~5 ~39 stained_hardened_clay 7  
fill ~47 ~5 ~14 ~49 ~5 ~14 wool 7  
fill ~47 ~5 ~19 ~49 ~5 ~19 wool 7  
fill ~47 ~5 ~33 ~48 ~5 ~33 grass 0  
fill ~47 ~5 ~34 ~48 ~5 ~34 grass 0  
fill ~47 ~5 ~35 ~47 ~5 ~33 grass 0 
setblock ~47 ~5 ~36 wool 7  
fill ~48 ~5 ~18 ~52 ~5 ~18 wool 7  
fill ~48 ~5 ~20 ~48 ~11 ~20 wool 7  
fill ~48 ~5 ~35 ~48 ~7 ~35 wool 7  
fill ~49 ~5 ~17 ~51 ~5 ~17 wool 7  
fill ~49 ~5 ~20 ~49 ~8 ~20 dirt 1  
fill ~21 ~6 ~24 ~22 ~6 ~24 wool 7  
fill ~21 ~6 ~25 ~28 ~6 ~25 wool 7  
fill ~21 ~6 ~26 ~24 ~6 ~26 wool 7  
fill ~21 ~6 ~27 ~23 ~6 ~27 wool 7  
fill ~21 ~6 ~28 ~21 ~8 ~28 wool 7  
fill ~21 ~6 ~29 ~21 ~8 ~29 wool 7  
fill ~21 ~6 ~30 ~21 ~20 ~30 wool 7  
fill ~21 ~6 ~31 ~21 ~18 ~31 wool 7  
fill ~21 ~6 ~32 ~29 ~6 ~32 wool 7 
setblock ~22 ~6 ~23 wool 7  
fill ~23 ~6 ~22 ~26 ~6 ~22 grass 0  
fill ~23 ~6 ~23 ~25 ~6 ~23 grass 0  
fill ~23 ~6 ~24 ~24 ~6 ~24 grass 0  
fill ~23 ~6 ~28 ~25 ~6 ~28 stained_hardened_clay 7  
fill ~23 ~6 ~29 ~25 ~6 ~29 stained_hardened_clay 7  
fill ~23 ~6 ~30 ~28 ~6 ~30 wool 7  
fill ~23 ~6 ~31 ~28 ~6 ~31 wool 7  
fill ~23 ~6 ~33 ~38 ~6 ~33 wool 7  
fill ~23 ~6 ~34 ~38 ~6 ~34 wool 7  
fill ~23 ~6 ~35 ~38 ~6 ~35 wool 7  
fill ~23 ~6 ~36 ~28 ~6 ~36 wool 7  
fill ~24 ~6 ~27 ~26 ~6 ~27 stained_hardened_clay 7  
fill ~25 ~6 ~21 ~26 ~6 ~21 grass 0  
fill ~25 ~6 ~24 ~28 ~6 ~24 wool 7  
fill ~25 ~6 ~26 ~25 ~14 ~26 stained_hardened_clay 7  
fill ~26 ~6 ~23 ~28 ~6 ~23 wool 7 
setblock ~26 ~6 ~26 wool 7  
fill ~26 ~6 ~28 ~29 ~6 ~28 wool 7  
fill ~26 ~6 ~29 ~29 ~6 ~29 wool 7  
fill ~27 ~6 ~21 ~27 ~20 ~21 wool 7  
fill ~27 ~6 ~22 ~27 ~19 ~22 wool 7  
fill ~27 ~6 ~27 ~28 ~6 ~27 wool 7  
fill ~27 ~6 ~38 ~36 ~6 ~38 stained_hardened_clay 7  
fill ~27 ~6 ~39 ~36 ~6 ~39 stained_hardened_clay 7  
fill ~27 ~6 ~40 ~35 ~6 ~40 stained_hardened_clay 7  
fill ~27 ~6 ~41 ~27 ~13 ~41 wool 7  
fill ~27 ~6 ~42 ~28 ~6 ~42 wool 7  
fill ~27 ~6 ~43 ~36 ~6 ~43 wool 7  
fill ~27 ~6 ~44 ~35 ~6 ~44 wool 7  
fill ~28 ~6 ~20 ~30 ~6 ~20 grass 0  
fill ~28 ~6 ~21 ~28 ~6 ~20 grass 0  
fill ~28 ~6 ~26 ~28 ~10 ~26 wool 7  
fill ~28 ~6 ~37 ~37 ~6 ~37 stained_hardened_clay 7  
fill ~28 ~6 ~41 ~34 ~6 ~41 stained_hardened_clay 7  
fill ~28 ~6 ~45 ~35 ~6 ~45 wool 7  
fill ~28 ~6 ~46 ~28 ~9 ~46 wool 7  
fill ~28 ~6 ~47 ~33 ~6 ~47 dirt 1  
fill ~29 ~6 ~19 ~32 ~6 ~19 grass 0  
fill ~29 ~6 ~21 ~31 ~6 ~21 dirt 1  
fill ~29 ~6 ~22 ~32 ~6 ~22 dirt 1  
fill ~29 ~6 ~24 ~34 ~6 ~24 dirt 1  
fill ~29 ~6 ~25 ~35 ~6 ~25 dirt 1  
fill ~29 ~6 ~26 ~36 ~6 ~26 dirt 1  
fill ~29 ~6 ~27 ~36 ~6 ~27 dirt 1  
fill ~29 ~6 ~30 ~36 ~6 ~30 dirt 1  
fill ~29 ~6 ~31 ~35 ~6 ~31 dirt 1  
fill ~29 ~6 ~36 ~36 ~6 ~36 stained_hardened_clay 7  
fill ~29 ~6 ~42 ~33 ~6 ~42 stained_hardened_clay 7  
fill ~29 ~6 ~48 ~29 ~8 ~48 dirt 1  
fill ~30 ~6 ~23 ~33 ~6 ~23 dirt 1  
fill ~30 ~6 ~28 ~36 ~6 ~28 dirt 1  
fill ~30 ~6 ~29 ~36 ~6 ~29 dirt 1  
fill ~30 ~6 ~32 ~34 ~6 ~32 dirt 1  
fill ~30 ~6 ~46 ~35 ~6 ~46 wool 7  
fill ~30 ~6 ~49 ~34 ~6 ~49 dirt 1  
fill ~30 ~6 ~50 ~34 ~6 ~50 dirt 1  
fill ~31 ~6 ~18 ~32 ~6 ~18 grass 0  
fill ~31 ~6 ~20 ~33 ~6 ~20 wool 7  
fill ~31 ~6 ~48 ~34 ~6 ~48 dirt 1  
fill ~31 ~6 ~51 ~31 ~8 ~51 dirt 1  
fill ~32 ~6 ~21 ~34 ~6 ~21 wool 7  
fill ~32 ~6 ~52 ~32 ~9 ~52 dirt 1  
fill ~33 ~6 ~18 ~33 ~6 ~22 wool 7  
fill ~33 ~6 ~53 ~35 ~6 ~53 wool 7  
fill ~34 ~6 ~18 ~34 ~11 ~18 stained_hardened_clay 7  
fill ~34 ~6 ~19 ~35 ~6 ~19 stained_hardened_clay 7  
fill ~34 ~6 ~20 ~35 ~6 ~20 stained_hardened_clay 7  
fill ~34 ~6 ~22 ~34 ~19 ~22 wool 7  
fill ~34 ~6 ~23 ~36 ~6 ~23 wool 7  
fill ~34 ~6 ~42 ~36 ~6 ~42 wool 7  
fill ~34 ~6 ~47 ~36 ~6 ~47 wool 7  
fill ~34 ~6 ~51 ~37 ~6 ~51 wool 7  
fill ~34 ~6 ~52 ~36 ~6 ~52 wool 7 
setblock ~35 ~6 ~18 grass 0  
fill ~35 ~6 ~21 ~36 ~6 ~21 grass 0  
fill ~35 ~6 ~22 ~36 ~6 ~22 grass 0  
fill ~35 ~6 ~24 ~38 ~6 ~24 wool 7  
fill ~35 ~6 ~32 ~35 ~11 ~32 wool 7  
fill ~35 ~6 ~41 ~37 ~6 ~41 wool 7  
fill ~35 ~6 ~48 ~38 ~6 ~48 wool 7  
fill ~35 ~6 ~50 ~38 ~6 ~50 wool 7  
fill ~36 ~6 ~31 ~36 ~22 ~31 wool 7  
fill ~36 ~6 ~40 ~46 ~6 ~40 wool 7  
fill ~36 ~6 ~44 ~43 ~6 ~44 dirt 1  
fill ~36 ~6 ~45 ~42 ~6 ~45 dirt 1  
fill ~36 ~6 ~53 ~37 ~6 ~53 stained_hardened_clay 7  
fill ~37 ~6 ~21 ~38 ~6 ~21 stained_hardened_clay 7  
fill ~37 ~6 ~22 ~43 ~6 ~22 stained_hardened_clay 7  
fill ~37 ~6 ~27 ~43 ~6 ~27 wool 7  
fill ~37 ~6 ~29 ~43 ~6 ~29 wool 7  
fill ~37 ~6 ~36 ~38 ~6 ~36 wool 7  
fill ~37 ~6 ~38 ~42 ~6 ~38 wool 7  
fill ~37 ~6 ~39 ~46 ~6 ~39 wool 7  
fill ~37 ~6 ~42 ~43 ~6 ~42 dirt 1  
fill ~37 ~6 ~43 ~44 ~6 ~43 dirt 1  
fill ~37 ~6 ~47 ~40 ~6 ~47 dirt 1  
fill ~37 ~6 ~49 ~38 ~6 ~49 wool 7  
fill ~38 ~6 ~14 ~38 ~14 ~14 stained_hardened_clay 7  
fill ~38 ~6 ~15 ~38 ~13 ~15 stained_hardened_clay 7  
fill ~38 ~6 ~16 ~38 ~13 ~16 stained_hardened_clay 7  
fill ~38 ~6 ~17 ~38 ~12 ~17 stained_hardened_clay 7  
fill ~38 ~6 ~18 ~38 ~12 ~18 stained_hardened_clay 7  
fill ~38 ~6 ~19 ~38 ~12 ~19 stained_hardened_clay 7  
fill ~38 ~6 ~20 ~38 ~12 ~20 stained_hardened_clay 7  
fill ~38 ~6 ~25 ~44 ~6 ~25 wool 7  
fill ~38 ~6 ~30 ~44 ~6 ~30 wool 7  
fill ~38 ~6 ~37 ~39 ~6 ~37 wool 7  
fill ~38 ~6 ~41 ~42 ~6 ~41 dirt 1  
fill ~38 ~6 ~51 ~38 ~8 ~51 stained_hardened_clay 7  
fill ~39 ~6 ~12 ~40 ~6 ~12 stained_hardened_clay 7  
fill ~39 ~6 ~13 ~42 ~6 ~13 stained_hardened_clay 7  
fill ~39 ~6 ~14 ~39 ~6 ~21 grass 0  
fill ~39 ~6 ~24 ~40 ~6 ~24 stained_hardened_clay 7  
fill ~39 ~6 ~26 ~43 ~6 ~26 wool 7  
fill ~39 ~6 ~28 ~43 ~6 ~28 wool 7  
fill ~39 ~6 ~33 ~43 ~6 ~33 stained_hardened_clay 7  
fill ~39 ~6 ~34 ~44 ~6 ~34 stained_hardened_clay 7  
fill ~39 ~6 ~35 ~45 ~6 ~35 stained_hardened_clay 7  
fill ~39 ~6 ~36 ~48 ~6 ~36 stained_hardened_clay 7  
fill ~39 ~6 ~48 ~39 ~14 ~48 dirt 1  
fill ~40 ~6 ~14 ~46 ~6 ~14 stained_hardened_clay 7  
fill ~40 ~6 ~15 ~48 ~6 ~15 stained_hardened_clay 7  
fill ~40 ~6 ~16 ~48 ~6 ~16 stained_hardened_clay 7  
fill ~40 ~6 ~17 ~48 ~6 ~17 stained_hardened_clay 7  
fill ~40 ~6 ~18 ~47 ~6 ~18 stained_hardened_clay 7  
fill ~40 ~6 ~19 ~40 ~6 ~21 grass 0  
fill ~40 ~6 ~23 ~42 ~6 ~23 stained_hardened_clay 7  
fill ~40 ~6 ~31 ~42 ~6 ~31 grass 0  
fill ~40 ~6 ~32 ~42 ~6 ~32 stained_hardened_clay 7  
fill ~40 ~6 ~37 ~48 ~6 ~37 stained_hardened_clay 7  
fill ~41 ~6 ~11 ~41 ~6 ~12 grass 0  
fill ~41 ~6 ~19 ~46 ~6 ~19 stained_hardened_clay 7  
fill ~41 ~6 ~20 ~45 ~6 ~20 stained_hardened_clay 7 
setblock ~41 ~6 ~21 grass 0  
fill ~41 ~6 ~24 ~45 ~6 ~24 wool 7  
fill ~41 ~6 ~46 ~41 ~13 ~46 dirt 1  
fill ~42 ~6 ~11 ~44 ~6 ~11 wool 7  
fill ~42 ~6 ~12 ~47 ~6 ~12 wool 7  
fill ~42 ~6 ~21 ~44 ~6 ~21 stained_hardened_clay 7  
fill ~43 ~6 ~13 ~48 ~6 ~13 wool 7  
fill ~43 ~6 ~23 ~45 ~6 ~23 wool 7  
fill ~43 ~6 ~31 ~45 ~6 ~31 wool 7  
fill ~43 ~6 ~32 ~45 ~6 ~32 wool 7  
fill ~43 ~6 ~38 ~47 ~6 ~38 stained_hardened_clay 7  
fill ~44 ~6 ~22 ~44 ~12 ~22 wool 7  
fill ~44 ~6 ~26 ~48 ~6 ~26 dirt 1  
fill ~44 ~6 ~27 ~48 ~6 ~27 dirt 1  
fill ~44 ~6 ~28 ~46 ~6 ~28 dirt 1  
fill ~44 ~6 ~29 ~44 ~6 ~26 dirt 1  
fill ~44 ~6 ~33 ~49 ~6 ~33 wool 7  
fill ~44 ~6 ~41 ~45 ~6 ~41 wool 7  
fill ~45 ~6 ~21 ~47 ~6 ~21 wool 7 
setblock ~45 ~6 ~22 grass 0  
fill ~45 ~6 ~25 ~48 ~6 ~25 dirt 1 
setblock ~45 ~6 ~30 grass 0  
fill ~45 ~6 ~34 ~49 ~6 ~34 wool 7  
fill ~45 ~6 ~42 ~45 ~22 ~42 wool 7  
fill ~46 ~6 ~22 ~46 ~11 ~22 wool 7  
fill ~46 ~6 ~23 ~47 ~6 ~23 dirt 1  
fill ~46 ~6 ~29 ~48 ~6 ~29 dirt 0  
fill ~46 ~6 ~30 ~49 ~6 ~30 dirt 1  
fill ~46 ~6 ~31 ~49 ~6 ~31 dirt 1  
fill ~46 ~6 ~32 ~49 ~6 ~32 dirt 1  
fill ~47 ~6 ~14 ~49 ~6 ~14 wool 7  
fill ~47 ~6 ~19 ~49 ~6 ~19 wool 7  
fill ~47 ~6 ~28 ~48 ~6 ~28 dirt 0  
fill ~47 ~6 ~35 ~47 ~17 ~35 wool 7  
fill ~47 ~6 ~39 ~47 ~7 ~39 stained_hardened_clay 7  
fill ~48 ~6 ~18 ~51 ~6 ~18 wool 7  
fill ~49 ~6 ~17 ~51 ~6 ~17 wool 7  
fill ~49 ~6 ~28 ~49 ~6 ~32 dirt 1  
fill ~57 ~6 ~17 ~57 ~6 ~20 grass 0  
fill ~58 ~6 ~18 ~58 ~6 ~19 dirt 0 
setblock ~58 ~6 ~20 grass 0  
fill ~20 ~7 ~22 ~20 ~7 ~23 dirt 0  
fill ~20 ~7 ~24 ~21 ~7 ~24 dirt 1  
fill ~20 ~7 ~25 ~20 ~13 ~25 dirt 1  
fill ~20 ~7 ~26 ~22 ~7 ~26 wool 7  
fill ~20 ~7 ~27 ~21 ~7 ~27 wool 7  
fill ~20 ~7 ~28 ~20 ~29 ~28 wool 7  
fill ~21 ~7 ~21 ~22 ~7 ~21 dirt 1  
fill ~21 ~7 ~22 ~22 ~7 ~22 dirt 1  
fill ~21 ~7 ~23 ~22 ~7 ~23 dirt 1  
fill ~21 ~7 ~25 ~23 ~7 ~25 wool 7  
fill ~21 ~7 ~32 ~40 ~7 ~32 wool 7  
fill ~22 ~7 ~24 ~28 ~7 ~24 wool 7  
fill ~22 ~7 ~27 ~27 ~7 ~27 stained_hardened_clay 7  
fill ~22 ~7 ~28 ~27 ~7 ~28 stained_hardened_clay 7  
fill ~22 ~7 ~29 ~26 ~7 ~29 stained_hardened_clay 7  
fill ~22 ~7 ~33 ~22 ~11 ~33 dirt 1  
fill ~22 ~7 ~34 ~22 ~8 ~34 dirt 1  
fill ~23 ~7 ~20 ~23 ~7 ~21 dirt 0  
fill ~23 ~7 ~22 ~28 ~7 ~22 wool 7  
fill ~23 ~7 ~23 ~28 ~7 ~23 wool 7  
fill ~23 ~7 ~26 ~26 ~7 ~26 stained_hardened_clay 7  
fill ~23 ~7 ~30 ~25 ~7 ~30 stained_hardened_clay 7  
fill ~23 ~7 ~31 ~30 ~7 ~31 wool 7  
fill ~23 ~7 ~33 ~39 ~7 ~33 wool 7  
fill ~23 ~7 ~34 ~39 ~7 ~34 wool 7 
setblock ~23 ~7 ~35 grass 0  
fill ~24 ~7 ~20 ~24 ~7 ~21 grass 0  
fill ~24 ~7 ~25 ~26 ~7 ~25 stained_hardened_clay 7  
fill ~24 ~7 ~35 ~28 ~7 ~35 wool 7  
fill ~24 ~7 ~36 ~27 ~7 ~36 wool 7  
fill ~25 ~7 ~20 ~25 ~18 ~20 wool 7  
fill ~25 ~7 ~21 ~28 ~7 ~21 wool 7  
fill ~26 ~7 ~19 ~27 ~7 ~19 grass 0  
fill ~26 ~7 ~20 ~27 ~7 ~20 grass 0  
fill ~26 ~7 ~30 ~29 ~7 ~30 wool 7  
fill ~26 ~7 ~41 ~26 ~13 ~41 wool 7  
fill ~27 ~7 ~29 ~29 ~7 ~29 wool 7  
fill ~27 ~7 ~37 ~37 ~7 ~37 stained_hardened_clay 7  
fill ~27 ~7 ~38 ~37 ~7 ~38 stained_hardened_clay 7  
fill ~27 ~7 ~39 ~36 ~7 ~39 stained_hardened_clay 7  
fill ~27 ~7 ~40 ~35 ~7 ~40 stained_hardened_clay 7  
fill ~27 ~7 ~42 ~29 ~7 ~42 wool 7  
fill ~27 ~7 ~43 ~35 ~7 ~43 wool 7  
fill ~27 ~7 ~44 ~35 ~7 ~44 wool 7  
fill ~27 ~7 ~45 ~34 ~7 ~45 wool 7  
fill ~28 ~7 ~19 ~32 ~7 ~19 wool 7  
fill ~28 ~7 ~20 ~33 ~7 ~20 wool 7  
fill ~28 ~7 ~25 ~28 ~19 ~25 wool 7  
fill ~28 ~7 ~27 ~29 ~7 ~27 wool 7  
fill ~28 ~7 ~28 ~29 ~7 ~28 wool 7  
fill ~28 ~7 ~36 ~37 ~7 ~36 stained_hardened_clay 7  
fill ~28 ~7 ~41 ~34 ~7 ~41 stained_hardened_clay 7  
fill ~28 ~7 ~47 ~34 ~7 ~47 dirt 1  
fill ~29 ~7 ~18 ~32 ~7 ~18 wool 7  
fill ~29 ~7 ~21 ~31 ~7 ~21 dirt 1  
fill ~29 ~7 ~22 ~32 ~7 ~22 dirt 1  
fill ~29 ~7 ~24 ~34 ~7 ~24 dirt 1  
fill ~29 ~7 ~25 ~35 ~7 ~25 dirt 1  
fill ~29 ~7 ~26 ~36 ~7 ~26 dirt 1  
fill ~29 ~7 ~35 ~35 ~7 ~35 stained_hardened_clay 7  
fill ~29 ~7 ~49 ~34 ~7 ~49 dirt 1  
fill ~30 ~7 ~23 ~33 ~7 ~23 dirt 1  
fill ~30 ~7 ~27 ~36 ~7 ~27 dirt 1  
fill ~30 ~7 ~28 ~36 ~7 ~28 dirt 1  
fill ~30 ~7 ~29 ~36 ~7 ~29 dirt 1  
fill ~30 ~7 ~30 ~35 ~7 ~30 dirt 1  
fill ~30 ~7 ~42 ~32 ~7 ~42 stained_hardened_clay 7  
fill ~30 ~7 ~46 ~34 ~7 ~46 wool 7  
fill ~30 ~7 ~50 ~34 ~7 ~50 dirt 1  
fill ~31 ~7 ~17 ~32 ~7 ~17 wool 7  
fill ~31 ~7 ~31 ~34 ~7 ~31 dirt 1  
fill ~31 ~7 ~48 ~34 ~7 ~48 dirt 1  
fill ~32 ~7 ~21 ~34 ~7 ~21 wool 7  
fill ~33 ~7 ~17 ~35 ~7 ~17 stained_hardened_clay 7  
fill ~33 ~7 ~18 ~33 ~10 ~18 stained_hardened_clay 7  
fill ~33 ~7 ~19 ~35 ~7 ~19 stained_hardened_clay 7  
fill ~33 ~7 ~22 ~33 ~19 ~22 wool 7  
fill ~33 ~7 ~42 ~36 ~7 ~42 wool 7  
fill ~33 ~7 ~53 ~36 ~7 ~53 wool 7  
fill ~34 ~7 ~20 ~35 ~7 ~20 stained_hardened_clay 7  
fill ~34 ~7 ~23 ~36 ~7 ~23 wool 7  
fill ~34 ~7 ~51 ~37 ~7 ~51 wool 7  
fill ~34 ~7 ~52 ~36 ~7 ~52 wool 7  
fill ~34 ~7 ~54 ~35 ~7 ~54 wool 7  
fill ~35 ~7 ~18 ~35 ~11 ~18 stained_hardened_clay 7  
fill ~35 ~7 ~21 ~44 ~7 ~21 stained_hardened_clay 7  
fill ~35 ~7 ~22 ~35 ~19 ~22 wool 7  
fill ~35 ~7 ~24 ~37 ~7 ~24 wool 7  
fill ~35 ~7 ~31 ~35 ~12 ~31 wool 7  
fill ~35 ~7 ~41 ~37 ~7 ~41 wool 7  
fill ~35 ~7 ~45 ~43 ~7 ~45 dirt 1  
fill ~35 ~7 ~46 ~35 ~11 ~46 dirt 1  
fill ~35 ~7 ~47 ~35 ~7 ~54 wool 7  
fill ~36 ~7 ~16 ~36 ~7 ~20 grass 0  
fill ~36 ~7 ~22 ~43 ~7 ~22 stained_hardened_clay 7  
fill ~36 ~7 ~30 ~36 ~21 ~30 wool 7  
fill ~36 ~7 ~35 ~38 ~7 ~35 wool 7  
fill ~36 ~7 ~40 ~47 ~7 ~40 wool 7  
fill ~36 ~7 ~43 ~44 ~7 ~43 dirt 1  
fill ~36 ~7 ~44 ~44 ~7 ~44 dirt 1  
fill ~36 ~7 ~47 ~40 ~7 ~47 dirt 1  
fill ~36 ~7 ~48 ~38 ~7 ~48 wool 7  
fill ~36 ~7 ~50 ~38 ~7 ~50 wool 7 
setblock ~36 ~7 ~54 stained_hardened_clay 7  
fill ~37 ~7 ~14 ~37 ~14 ~14 stained_hardened_clay 7  
fill ~37 ~7 ~15 ~37 ~13 ~15 stained_hardened_clay 7  
fill ~37 ~7 ~16 ~37 ~13 ~16 stained_hardened_clay 7  
fill ~37 ~7 ~17 ~37 ~12 ~17 stained_hardened_clay 7  
fill ~37 ~7 ~18 ~37 ~12 ~18 stained_hardened_clay 7  
fill ~37 ~7 ~19 ~37 ~12 ~19 stained_hardened_clay 7  
fill ~37 ~7 ~20 ~37 ~12 ~20 stained_hardened_clay 7   
fill ~37 ~7 ~27 ~45 ~7 ~27 wool 7  
fill ~37 ~7 ~29 ~45 ~7 ~29 wool 7  
fill ~37 ~7 ~39 ~46 ~7 ~39 wool 7  
fill ~37 ~7 ~42 ~43 ~7 ~42 dirt 1  
fill ~37 ~7 ~49 ~38 ~7 ~49 wool 7  
fill ~37 ~7 ~53 ~37 ~8 ~53 stained_hardened_clay 7  
fill ~38 ~7 ~12 ~42 ~7 ~12 stained_hardened_clay 7  
fill ~38 ~7 ~13 ~43 ~7 ~13 stained_hardened_clay 7  
fill ~38 ~7 ~24 ~41 ~7 ~24 stained_hardened_clay 7  
fill ~38 ~7 ~25 ~45 ~7 ~25 wool 7  
fill ~38 ~7 ~30 ~45 ~7 ~30 wool 7  
fill ~38 ~7 ~36 ~39 ~7 ~36 wool 7  
fill ~38 ~7 ~37 ~41 ~7 ~37 wool 7  
fill ~38 ~7 ~38 ~45 ~7 ~38 wool 7  
fill ~38 ~7 ~41 ~42 ~7 ~41 dirt 1  
fill ~38 ~7 ~52 ~38 ~9 ~52 stained_hardened_clay 7  
fill ~39 ~7 ~11 ~39 ~14 ~11 stained_hardened_clay 7  
fill ~39 ~7 ~14 ~45 ~7 ~14 stained_hardened_clay 7  
fill ~39 ~7 ~15 ~48 ~7 ~15 stained_hardened_clay 7  
fill ~39 ~7 ~16 ~48 ~7 ~16 stained_hardened_clay 7  
fill ~39 ~7 ~17 ~48 ~7 ~17 stained_hardened_clay 7  
fill ~39 ~7 ~18 ~47 ~7 ~18 stained_hardened_clay 7  
fill ~39 ~7 ~19 ~46 ~7 ~19 stained_hardened_clay 7  
fill ~39 ~7 ~20 ~45 ~7 ~20 stained_hardened_clay 7  
fill ~39 ~7 ~26 ~44 ~7 ~26 wool 7  
fill ~39 ~7 ~28 ~45 ~7 ~28 wool 7  
fill ~39 ~7 ~35 ~44 ~7 ~35 stained_hardened_clay 7  
fill ~40 ~7 ~10 ~41 ~7 ~10 stained_hardened_clay 7 
setblock ~40 ~7 ~11 grass 0  
fill ~40 ~7 ~23 ~42 ~7 ~23 stained_hardened_clay 7  
fill ~40 ~7 ~31 ~46 ~7 ~31 wool 7  
fill ~40 ~7 ~33 ~42 ~7 ~33 stained_hardened_clay 7  
fill ~40 ~7 ~34 ~43 ~7 ~34 stained_hardened_clay 7  
fill ~40 ~7 ~36 ~49 ~7 ~36 stained_hardened_clay 7  
fill ~41 ~7 ~11 ~42 ~7 ~11 stained_hardened_clay 7  
fill ~41 ~7 ~32 ~41 ~10 ~32 stained_hardened_clay 7  
fill ~42 ~7 ~10 ~43 ~7 ~10 wool 7  
fill ~42 ~7 ~24 ~45 ~7 ~24 wool 7  
fill ~42 ~7 ~32 ~50 ~7 ~32 wool 7  
fill ~42 ~7 ~37 ~48 ~7 ~37 stained_hardened_clay 7  
fill ~43 ~7 ~11 ~45 ~7 ~11 wool 7  
fill ~43 ~7 ~12 ~47 ~7 ~12 wool 7  
fill ~43 ~7 ~23 ~45 ~7 ~23 wool 7  
fill ~43 ~7 ~33 ~50 ~7 ~33 wool 7  
fill ~44 ~7 ~13 ~48 ~7 ~13 wool 7  
fill ~44 ~7 ~34 ~49 ~7 ~34 wool 7  
fill ~44 ~7 ~41 ~46 ~7 ~41 wool 7  
fill ~45 ~7 ~21 ~47 ~7 ~21 wool 7  
fill ~45 ~7 ~22 ~45 ~11 ~22 wool 7  
fill ~45 ~7 ~26 ~49 ~7 ~26 dirt 1  
fill ~45 ~7 ~35 ~45 ~14 ~35 wool 7  
fill ~45 ~7 ~43 ~45 ~15 ~43 wool 7 
setblock ~46 ~7 ~11 dirt 1  
fill ~46 ~7 ~14 ~49 ~7 ~14 wool 7  
fill ~46 ~7 ~23 ~48 ~7 ~23 dirt 1  
fill ~46 ~7 ~25 ~49 ~7 ~25 dirt 1  
fill ~46 ~7 ~27 ~48 ~7 ~27 dirt 1  
fill ~46 ~7 ~28 ~48 ~7 ~28 dirt 1  
fill ~46 ~7 ~29 ~48 ~7 ~29 dirt 1  
fill ~46 ~7 ~30 ~48 ~7 ~30 dirt 1  
fill ~46 ~7 ~38 ~48 ~7 ~38 stained_hardened_clay 7  
fill ~47 ~7 ~19 ~49 ~7 ~19 wool 7  
fill ~47 ~7 ~22 ~47 ~8 ~22 dirt 1  
fill ~47 ~7 ~31 ~48 ~7 ~31 dirt 1  
fill ~48 ~7 ~18 ~50 ~7 ~18 wool 7  
fill ~48 ~7 ~21 ~48 ~8 ~21 dirt 1  
fill ~49 ~7 ~17 ~51 ~7 ~17 wool 7  
fill ~49 ~7 ~27 ~49 ~23 ~27 wool 7  
fill ~49 ~7 ~28 ~49 ~24 ~28 wool 7  
fill ~49 ~7 ~29 ~50 ~7 ~29 wool 7  
fill ~49 ~7 ~30 ~50 ~7 ~30 wool 7  
fill ~49 ~7 ~31 ~50 ~7 ~31 wool 7  
fill ~49 ~7 ~35 ~49 ~10 ~35 stained_hardened_clay 7  
fill ~54 ~7 ~16 ~54 ~12 ~16 wool 7  
fill ~54 ~7 ~17 ~54 ~20 ~17 wool 7  
fill ~54 ~7 ~18 ~54 ~23 ~18 wool 7  
fill ~55 ~7 ~15 ~55 ~7 ~20 grass 0  
fill ~56 ~7 ~15 ~57 ~7 ~15 wool 7  
fill ~56 ~7 ~16 ~57 ~7 ~16 grass 0  
fill ~56 ~7 ~17 ~56 ~7 ~20 grass 0  
fill ~56 ~7 ~21 ~58 ~7 ~21 wool 7  
fill ~57 ~7 ~17 ~57 ~10 ~17 wool 7  
fill ~57 ~7 ~18 ~57 ~8 ~18 wool 7  
fill ~57 ~7 ~19 ~57 ~10 ~19 wool 7  
fill ~57 ~7 ~20 ~58 ~7 ~20 wool 7  
fill ~58 ~7 ~16 ~58 ~13 ~16 dirt 1  
fill ~58 ~7 ~17 ~59 ~7 ~17 dirt 1  
fill ~58 ~7 ~18 ~59 ~7 ~18 dirt 1  
fill ~58 ~7 ~19 ~59 ~7 ~19 dirt 1  
fill ~59 ~7 ~20 ~59 ~9 ~20 dirt 1  
fill ~19 ~8 ~22 ~23 ~8 ~22 dirt 1  
fill ~19 ~8 ~23 ~22 ~8 ~23 dirt 1  
fill ~19 ~8 ~24 ~21 ~8 ~24 dirt 1  
fill ~19 ~8 ~25 ~19 ~13 ~25 dirt 1 
setblock ~20 ~8 ~18 grass 0  
fill ~20 ~8 ~19 ~20 ~8 ~20 dirt 0  
fill ~20 ~8 ~21 ~23 ~8 ~21 dirt 1  
fill ~20 ~8 ~26 ~22 ~8 ~26 wool 7  
fill ~20 ~8 ~27 ~21 ~8 ~27 wool 7  
fill ~20 ~8 ~29 ~20 ~28 ~29 wool 7  
fill ~20 ~8 ~30 ~20 ~19 ~30 wool 7  
fill ~21 ~8 ~18 ~21 ~15 ~18 wool 7  
fill ~21 ~8 ~19 ~21 ~12 ~19 dirt 1  
fill ~21 ~8 ~20 ~23 ~8 ~20 dirt 1  
fill ~21 ~8 ~25 ~23 ~8 ~25 wool 7  
fill ~21 ~8 ~32 ~40 ~8 ~32 wool 7  
fill ~22 ~8 ~24 ~28 ~8 ~24 wool 7  
fill ~22 ~8 ~27 ~27 ~8 ~27 stained_hardened_clay 7  
fill ~22 ~8 ~28 ~27 ~8 ~28 stained_hardened_clay 7  
fill ~22 ~8 ~29 ~27 ~8 ~29 stained_hardened_clay 7  
fill ~22 ~8 ~30 ~26 ~8 ~30 stained_hardened_clay 7  
fill ~23 ~8 ~19 ~24 ~8 ~19 dirt 1  
fill ~23 ~8 ~23 ~28 ~8 ~23 wool 7  
fill ~23 ~8 ~26 ~27 ~8 ~26 stained_hardened_clay 7  
fill ~23 ~8 ~31 ~40 ~8 ~31 wool 7  
fill ~23 ~8 ~33 ~40 ~8 ~33 wool 7 
setblock ~23 ~8 ~34 dirt 1 
setblock ~23 ~8 ~35 tallgrass 2  
fill ~24 ~8 ~20 ~24 ~8 ~24 wool 7  
fill ~24 ~8 ~25 ~26 ~8 ~25 stained_hardened_clay 7  
fill ~24 ~8 ~34 ~29 ~8 ~34 wool 7  
fill ~24 ~8 ~35 ~27 ~8 ~35 wool 7  
fill ~25 ~8 ~19 ~32 ~8 ~19 wool 7  
fill ~25 ~8 ~21 ~29 ~8 ~21 wool 7  
fill ~25 ~8 ~22 ~28 ~8 ~22 wool 7  
fill ~25 ~8 ~36 ~25 ~16 ~36 wool 7  
fill ~26 ~8 ~18 ~28 ~8 ~18 dirt 1  
fill ~26 ~8 ~20 ~33 ~8 ~20 wool 7  
fill ~26 ~8 ~38 ~26 ~14 ~38 wool 7  
fill ~26 ~8 ~40 ~27 ~8 ~40 wool 7  
fill ~26 ~8 ~42 ~36 ~8 ~42 wool 7  
fill ~26 ~8 ~43 ~35 ~8 ~43 wool 7  
fill ~27 ~8 ~30 ~31 ~8 ~30 wool 7  
fill ~27 ~8 ~36 ~27 ~16 ~36 wool 7  
fill ~27 ~8 ~37 ~37 ~8 ~37 stained_hardened_clay 7  
fill ~27 ~8 ~38 ~37 ~8 ~38 stained_hardened_clay 7  
fill ~27 ~8 ~39 ~36 ~8 ~39 stained_hardened_clay 7  
fill ~27 ~8 ~44 ~34 ~8 ~44 wool 7  
fill ~27 ~8 ~45 ~34 ~8 ~45 wool 7  
fill ~28 ~8 ~27 ~29 ~8 ~27 wool 7  
fill ~28 ~8 ~28 ~29 ~8 ~28 wool 7  
fill ~28 ~8 ~29 ~30 ~8 ~29 wool 7  
fill ~28 ~8 ~35 ~36 ~8 ~35 stained_hardened_clay 7  
fill ~28 ~8 ~36 ~37 ~8 ~36 stained_hardened_clay 7  
fill ~28 ~8 ~40 ~35 ~8 ~40 stained_hardened_clay 7  
fill ~28 ~8 ~41 ~28 ~13 ~41 wool 7  
fill ~28 ~8 ~47 ~32 ~8 ~47 wool 7  
fill ~29 ~8 ~17 ~29 ~20 ~17 dirt 1  
fill ~29 ~8 ~18 ~32 ~8 ~18 wool 7  
fill ~29 ~8 ~22 ~32 ~8 ~22 dirt 1  
fill ~29 ~8 ~24 ~34 ~8 ~24 dirt 1  
fill ~29 ~8 ~25 ~35 ~8 ~25 dirt 1  
fill ~29 ~8 ~26 ~29 ~19 ~26 wool 7  
fill ~29 ~8 ~41 ~33 ~8 ~41 stained_hardened_clay 7  
fill ~30 ~8 ~17 ~32 ~8 ~17 wool 7  
fill ~30 ~8 ~21 ~31 ~8 ~21 dirt 1  
fill ~30 ~8 ~23 ~33 ~8 ~23 dirt 1  
fill ~30 ~8 ~26 ~36 ~8 ~26 dirt 1  
fill ~30 ~8 ~27 ~36 ~8 ~27 dirt 1  
fill ~30 ~8 ~28 ~36 ~8 ~28 dirt 1  
fill ~30 ~8 ~34 ~34 ~8 ~34 stained_hardened_clay 7  
fill ~30 ~8 ~46 ~34 ~8 ~46 wool 7  
fill ~30 ~8 ~49 ~34 ~8 ~49 dirt 1  
fill ~30 ~8 ~50 ~33 ~8 ~50 dirt 1  
fill ~31 ~8 ~16 ~33 ~8 ~16 wool 7  
fill ~31 ~8 ~29 ~35 ~8 ~29 dirt 1  
fill ~31 ~8 ~48 ~34 ~8 ~48 dirt 1  
fill ~32 ~8 ~21 ~34 ~8 ~21 wool 7  
fill ~32 ~8 ~30 ~34 ~8 ~30 dirt 1  
fill ~33 ~8 ~17 ~47 ~8 ~17 stained_hardened_clay 7  
fill ~33 ~8 ~19 ~46 ~8 ~19 stained_hardened_clay 7  
fill ~33 ~8 ~47 ~40 ~8 ~47 dirt 1  
fill ~33 ~8 ~53 ~33 ~10 ~53 dirt 1  
fill ~34 ~8 ~15 ~36 ~8 ~15 grass 0  
fill ~34 ~8 ~16 ~35 ~8 ~16 grass 0  
fill ~34 ~8 ~20 ~45 ~8 ~20 stained_hardened_clay 7  
fill ~34 ~8 ~23 ~36 ~8 ~23 wool 7  
fill ~34 ~8 ~41 ~38 ~8 ~41 wool 7  
fill ~34 ~8 ~50 ~38 ~8 ~50 wool 7  
fill ~34 ~8 ~51 ~37 ~8 ~51 wool 7  
fill ~34 ~8 ~52 ~36 ~8 ~52 wool 7  
fill ~34 ~8 ~53 ~36 ~8 ~53 wool 7  
fill ~34 ~8 ~54 ~36 ~8 ~54 wool 7  
fill ~35 ~8 ~21 ~43 ~8 ~21 stained_hardened_clay 7  
fill ~35 ~8 ~24 ~37 ~8 ~24 wool 7  
fill ~35 ~8 ~30 ~35 ~12 ~30 wool 7  
fill ~35 ~8 ~34 ~40 ~8 ~34 wool 7  
fill ~35 ~8 ~44 ~44 ~8 ~44 dirt 1  
fill ~35 ~8 ~45 ~43 ~8 ~45 dirt 1  
fill ~35 ~8 ~48 ~38 ~8 ~48 wool 7  
fill ~36 ~8 ~14 ~36 ~13 ~14 stained_hardened_clay 7  
fill ~36 ~8 ~16 ~36 ~12 ~16 stained_hardened_clay 7  
fill ~36 ~8 ~18 ~36 ~12 ~18 stained_hardened_clay 7  
fill ~36 ~8 ~22 ~42 ~8 ~22 stained_hardened_clay 7  
fill ~36 ~8 ~29 ~50 ~8 ~29 wool 7  
fill ~36 ~8 ~40 ~48 ~8 ~40 wool 7  
fill ~36 ~8 ~43 ~44 ~8 ~43 dirt 1  
fill ~37 ~8 ~12 ~43 ~8 ~12 stained_hardened_clay 7  
fill ~37 ~8 ~13 ~43 ~8 ~13 stained_hardened_clay 7  
fill ~37 ~8 ~27 ~50 ~8 ~27 wool 7  
fill ~37 ~8 ~35 ~41 ~8 ~35 wool 7  
fill ~37 ~8 ~39 ~47 ~8 ~39 wool 7  
fill ~37 ~8 ~42 ~43 ~8 ~42 dirt 1  
fill ~37 ~8 ~49 ~39 ~8 ~49 wool 7 
setblock ~37 ~8 ~54 stained_hardened_clay 7  
fill ~38 ~8 ~10 ~38 ~16 ~10 wool 7  
fill ~38 ~8 ~11 ~38 ~13 ~11 stained_hardened_clay 7  
fill ~38 ~8 ~24 ~41 ~8 ~24 stained_hardened_clay 7  
fill ~38 ~8 ~25 ~39 ~8 ~25 wool 7  
fill ~38 ~8 ~30 ~40 ~8 ~30 wool 7  
fill ~38 ~8 ~36 ~46 ~8 ~36 wool 7  
fill ~38 ~8 ~37 ~45 ~8 ~37 wool 7  
fill ~38 ~8 ~38 ~46 ~8 ~38 wool 7  
fill ~38 ~8 ~53 ~38 ~9 ~53 stained_hardened_clay 7  
fill ~39 ~8 ~10 ~42 ~8 ~10 stained_hardened_clay 7  
fill ~39 ~8 ~14 ~45 ~8 ~14 stained_hardened_clay 7  
fill ~39 ~8 ~15 ~47 ~8 ~15 stained_hardened_clay 7  
fill ~39 ~8 ~16 ~48 ~8 ~16 stained_hardened_clay 7  
fill ~39 ~8 ~18 ~47 ~8 ~18 stained_hardened_clay 7  
fill ~39 ~8 ~26 ~50 ~8 ~26 wool 7  
fill ~39 ~8 ~28 ~50 ~8 ~28 wool 7  
fill ~39 ~8 ~41 ~42 ~8 ~41 dirt 1 
setblock ~40 ~8 ~9 wool 7  
fill ~40 ~8 ~11 ~42 ~8 ~11 stained_hardened_clay 7  
fill ~40 ~8 ~23 ~42 ~8 ~23 stained_hardened_clay 7  
fill ~40 ~8 ~25 ~40 ~15 ~25 stained_hardened_clay 7  
fill ~40 ~8 ~48 ~40 ~14 ~48 dirt 1  
fill ~41 ~8 ~9 ~41 ~13 ~9 stained_hardened_clay 7  
fill ~41 ~8 ~25 ~46 ~8 ~25 wool 7  
fill ~41 ~8 ~30 ~41 ~13 ~30 stained_hardened_clay 7  
fill ~41 ~8 ~31 ~41 ~12 ~31 stained_hardened_clay 7  
fill ~41 ~8 ~33 ~42 ~8 ~33 stained_hardened_clay 7  
fill ~41 ~8 ~34 ~42 ~8 ~34 stained_hardened_clay 7  
fill ~42 ~8 ~24 ~45 ~8 ~24 wool 7  
fill ~42 ~8 ~30 ~50 ~8 ~30 wool 7  
fill ~42 ~8 ~31 ~50 ~8 ~31 wool 7  
fill ~42 ~8 ~32 ~42 ~10 ~32 stained_hardened_clay 7 
setblock ~42 ~8 ~35 stained_hardened_clay 7 
setblock ~42 ~8 ~46 dirt 1  
fill ~43 ~8 ~10 ~45 ~8 ~10 wool 7  
fill ~43 ~8 ~11 ~47 ~8 ~11 wool 7  
fill ~43 ~8 ~22 ~43 ~12 ~22 wool 7  
fill ~43 ~8 ~23 ~46 ~8 ~23 wool 7  
fill ~43 ~8 ~32 ~50 ~8 ~32 wool 7  
fill ~43 ~8 ~33 ~50 ~8 ~33 wool 7  
fill ~43 ~8 ~34 ~49 ~8 ~34 wool 7  
fill ~43 ~8 ~35 ~47 ~8 ~35 wool 7  
fill ~44 ~8 ~12 ~48 ~8 ~12 wool 7  
fill ~44 ~8 ~13 ~49 ~8 ~13 wool 7  
fill ~44 ~8 ~21 ~47 ~8 ~21 wool 7  
fill ~44 ~8 ~41 ~47 ~8 ~41 wool 7  
fill ~46 ~8 ~14 ~49 ~8 ~14 wool 7  
fill ~46 ~8 ~37 ~49 ~8 ~37 stained_hardened_clay 7  
fill ~46 ~8 ~42 ~46 ~22 ~42 wool 7  
fill ~47 ~8 ~19 ~50 ~8 ~19 wool 7  
fill ~47 ~8 ~23 ~48 ~8 ~23 dirt 1  
fill ~47 ~8 ~25 ~48 ~8 ~25 dirt 1  
fill ~47 ~8 ~36 ~49 ~8 ~36 stained_hardened_clay 7  
fill ~47 ~8 ~38 ~48 ~8 ~38 stained_hardened_clay 7  
fill ~48 ~8 ~15 ~48 ~16 ~15 wool 7  
fill ~48 ~8 ~17 ~50 ~8 ~17 wool 7  
fill ~48 ~8 ~18 ~51 ~8 ~18 wool 7  
fill ~48 ~8 ~35 ~48 ~9 ~35 stained_hardened_clay 7 
setblock ~48 ~8 ~39 stained_hardened_clay 7  
fill ~49 ~8 ~21 ~50 ~8 ~21 dirt 1 
setblock ~49 ~8 ~22 dirt 0 
setblock ~49 ~8 ~24 dirt 1  
fill ~49 ~8 ~25 ~49 ~23 ~25 wool 7  
fill ~49 ~8 ~38 ~51 ~8 ~38 grass 0  
fill ~49 ~8 ~39 ~50 ~8 ~39 grass 0  
fill ~49 ~8 ~40 ~49 ~8 ~38 grass 0  
fill ~50 ~8 ~20 ~51 ~8 ~20 dirt 1  
fill ~50 ~8 ~22 ~52 ~8 ~22 grass 0  
fill ~50 ~8 ~23 ~52 ~8 ~23 grass 0  
fill ~50 ~8 ~34 ~50 ~9 ~34 stained_hardened_clay 7  
fill ~50 ~8 ~35 ~50 ~11 ~35 stained_hardened_clay 7 
setblock ~50 ~8 ~37 grass 0 
setblock ~51 ~8 ~19 dirt 1  
fill ~51 ~8 ~21 ~52 ~8 ~21 grass 0  
fill ~52 ~8 ~16 ~52 ~8 ~23 grass 0  
fill ~53 ~8 ~15 ~58 ~8 ~15 wool 7  
fill ~53 ~8 ~16 ~53 ~11 ~16 wool 7  
fill ~53 ~8 ~17 ~53 ~21 ~17 wool 7  
fill ~53 ~8 ~18 ~53 ~24 ~18 wool 7  
fill ~53 ~8 ~19 ~57 ~8 ~19 wool 7  
fill ~53 ~8 ~20 ~58 ~8 ~20 wool 7  
fill ~53 ~8 ~21 ~59 ~8 ~21 wool 7  
fill ~53 ~8 ~22 ~54 ~8 ~22 wool 7  
fill ~55 ~8 ~14 ~56 ~8 ~14 wool 7  
fill ~55 ~8 ~16 ~57 ~8 ~16 wool 7  
fill ~55 ~8 ~17 ~57 ~8 ~17 wool 7  
fill ~55 ~8 ~18 ~57 ~8 ~18 wool 7  
fill ~58 ~8 ~17 ~59 ~8 ~17 dirt 1  
fill ~58 ~8 ~18 ~59 ~8 ~18 dirt 1  
fill ~58 ~8 ~19 ~60 ~8 ~19 dirt 1  
fill ~18 ~9 ~19 ~18 ~10 ~19 wool 7  
fill ~18 ~9 ~20 ~19 ~9 ~20 dirt 0  
fill ~18 ~9 ~22 ~23 ~9 ~22 dirt 1  
fill ~18 ~9 ~23 ~22 ~9 ~23 dirt 1  
fill ~18 ~9 ~25 ~18 ~14 ~25 dirt 1  
fill ~19 ~9 ~17 ~19 ~24 ~17 wool 7  
fill ~19 ~9 ~18 ~22 ~9 ~18 wool 7 
setblock ~19 ~9 ~19 dirt 0  
fill ~19 ~9 ~21 ~23 ~9 ~21 dirt 1  
fill ~19 ~9 ~24 ~21 ~9 ~24 dirt 1  
fill ~19 ~9 ~26 ~19 ~12 ~26 dirt 1  
fill ~19 ~9 ~27 ~21 ~9 ~27 wool 7  
fill ~19 ~9 ~28 ~19 ~22 ~28 wool 7  
fill ~20 ~9 ~16 ~22 ~9 ~16 wool 7 
setblock ~20 ~9 ~17 grass 0  
fill ~20 ~9 ~19 ~20 ~12 ~19 dirt 1  
fill ~20 ~9 ~20 ~24 ~9 ~20 dirt 1  
fill ~20 ~9 ~26 ~22 ~9 ~26 wool 7  
fill ~20 ~9 ~31 ~20 ~18 ~31 wool 7  
fill ~21 ~9 ~15 ~22 ~9 ~15 wool 7  
fill ~21 ~9 ~17 ~22 ~9 ~17 wool 7  
fill ~21 ~9 ~25 ~23 ~9 ~25 wool 7  
fill ~21 ~9 ~28 ~27 ~9 ~28 stained_hardened_clay 7  
fill ~21 ~9 ~29 ~27 ~9 ~29 stained_hardened_clay 7 
setblock ~21 ~9 ~32 dirt 1  
fill ~22 ~9 ~19 ~24 ~9 ~19 dirt 1  
fill ~22 ~9 ~24 ~24 ~9 ~24 wool 7  
fill ~22 ~9 ~27 ~27 ~9 ~27 stained_hardened_clay 7  
fill ~22 ~9 ~30 ~27 ~9 ~30 stained_hardened_clay 7  
fill ~22 ~9 ~32 ~40 ~9 ~32 wool 7  
fill ~23 ~9 ~16 ~23 ~9 ~18 grass 0  
fill ~23 ~9 ~23 ~28 ~9 ~23 wool 7  
fill ~23 ~9 ~26 ~27 ~9 ~26 stained_hardened_clay 7  
fill ~23 ~9 ~31 ~23 ~10 ~31 wool 7  
fill ~23 ~9 ~33 ~29 ~9 ~33 wool 7  
fill ~24 ~9 ~18 ~27 ~9 ~18 dirt 1  
fill ~24 ~9 ~21 ~29 ~9 ~21 wool 7  
fill ~24 ~9 ~22 ~28 ~9 ~22 wool 7  
fill ~24 ~9 ~25 ~27 ~9 ~25 stained_hardened_clay 7  
fill ~24 ~9 ~31 ~26 ~9 ~31 stained_hardened_clay 7  
fill ~24 ~9 ~34 ~24 ~10 ~34 dirt 1  
fill ~24 ~9 ~35 ~24 ~12 ~35 dirt 1  
fill ~25 ~9 ~19 ~33 ~9 ~19 wool 7  
fill ~25 ~9 ~24 ~26 ~9 ~24 stained_hardened_clay 7  
fill ~25 ~9 ~34 ~28 ~9 ~34 wool 7  
fill ~25 ~9 ~35 ~27 ~9 ~35 wool 7  
fill ~26 ~9 ~20 ~33 ~9 ~20 wool 7  
fill ~26 ~9 ~39 ~27 ~9 ~39 wool 7  
fill ~26 ~9 ~40 ~28 ~9 ~40 wool 7  
fill ~26 ~9 ~42 ~36 ~9 ~42 wool 7  
fill ~26 ~9 ~43 ~35 ~9 ~43 wool 7  
fill ~27 ~9 ~17 ~29 ~9 ~17 dirt 1  
fill ~27 ~9 ~24 ~28 ~9 ~24 wool 7  
fill ~27 ~9 ~31 ~39 ~9 ~31 wool 7  
fill ~27 ~9 ~37 ~27 ~16 ~37 wool 7  
fill ~27 ~9 ~38 ~27 ~15 ~38 wool 7  
fill ~27 ~9 ~44 ~34 ~9 ~44 wool 7 
setblock ~27 ~9 ~45 stained_hardened_clay 7  
fill ~28 ~9 ~18 ~32 ~9 ~18 wool 7  
fill ~28 ~9 ~27 ~29 ~9 ~27 wool 7  
fill ~28 ~9 ~28 ~30 ~9 ~28 wool 7  
fill ~28 ~9 ~29 ~31 ~9 ~29 wool 7  
fill ~28 ~9 ~30 ~39 ~9 ~30 wool 7  
fill ~28 ~9 ~35 ~36 ~9 ~35 stained_hardened_clay 7  
fill ~28 ~9 ~36 ~37 ~9 ~36 stained_hardened_clay 7  
fill ~28 ~9 ~37 ~37 ~9 ~37 stained_hardened_clay 7  
fill ~28 ~9 ~38 ~37 ~9 ~38 stained_hardened_clay 7  
fill ~28 ~9 ~39 ~36 ~9 ~39 stained_hardened_clay 7  
fill ~28 ~9 ~45 ~34 ~9 ~45 wool 7  
fill ~29 ~9 ~16 ~29 ~21 ~16 dirt 1  
fill ~29 ~9 ~22 ~32 ~9 ~22 dirt 1  
fill ~29 ~9 ~24 ~34 ~9 ~24 dirt 1  
fill ~29 ~9 ~25 ~29 ~18 ~25 wool 7  
fill ~29 ~9 ~34 ~35 ~9 ~34 stained_hardened_clay 7  
fill ~29 ~9 ~40 ~34 ~9 ~40 stained_hardened_clay 7  
fill ~29 ~9 ~41 ~29 ~13 ~41 wool 7  
fill ~29 ~9 ~47 ~34 ~9 ~47 wool 7  
fill ~29 ~9 ~48 ~35 ~9 ~48 wool 7  
fill ~30 ~9 ~16 ~33 ~9 ~16 wool 7  
fill ~30 ~9 ~17 ~32 ~9 ~17 wool 7  
fill ~30 ~9 ~21 ~30 ~6 ~21 dirt 1  
fill ~30 ~9 ~23 ~33 ~9 ~23 dirt 1  
fill ~30 ~9 ~25 ~35 ~9 ~25 dirt 1  
fill ~30 ~9 ~26 ~35 ~9 ~26 dirt 1  
fill ~30 ~9 ~27 ~35 ~9 ~27 dirt 1  
fill ~30 ~9 ~33 ~33 ~9 ~33 stained_hardened_clay 7  
fill ~30 ~9 ~41 ~32 ~9 ~41 stained_hardened_clay 7  
fill ~30 ~9 ~46 ~34 ~9 ~46 wool 7  
fill ~30 ~9 ~49 ~31 ~9 ~49 wool 7  
fill ~31 ~9 ~15 ~31 ~10 ~15 wool 7  
fill ~31 ~9 ~21 ~34 ~9 ~21 wool 7  
fill ~31 ~9 ~28 ~35 ~9 ~28 dirt 1  
fill ~31 ~9 ~50 ~33 ~9 ~50 dirt 1  
fill ~32 ~9 ~14 ~33 ~9 ~14 grass 0  
fill ~32 ~9 ~15 ~33 ~9 ~15 grass 0  
fill ~32 ~9 ~29 ~35 ~9 ~29 dirt 1  
fill ~32 ~9 ~49 ~33 ~9 ~49 dirt 1  
fill ~33 ~9 ~17 ~46 ~9 ~17 stained_hardened_clay 7  
fill ~33 ~9 ~41 ~38 ~9 ~41 wool 7  
fill ~33 ~9 ~54 ~34 ~9 ~54 dirt 1  
fill ~34 ~9 ~14 ~34 ~15 ~14 wool 7  
fill ~34 ~9 ~15 ~45 ~9 ~15 stained_hardened_clay 7  
fill ~34 ~9 ~16 ~46 ~9 ~16 stained_hardened_clay 7  
fill ~34 ~9 ~19 ~44 ~9 ~19 stained_hardened_clay 7  
fill ~34 ~9 ~20 ~43 ~9 ~20 stained_hardened_clay 7  
fill ~34 ~9 ~23 ~36 ~9 ~23 wool 7  
fill ~34 ~9 ~33 ~51 ~9 ~33 wool 7  
fill ~34 ~9 ~49 ~34 ~20 ~49 wool 7  
fill ~34 ~9 ~50 ~39 ~9 ~50 wool 7  
fill ~34 ~9 ~51 ~34 ~19 ~51 dirt 1  
fill ~34 ~9 ~52 ~34 ~12 ~52 dirt 1  
fill ~34 ~9 ~53 ~34 ~15 ~53 dirt 1  
fill ~35 ~9 ~14 ~35 ~10 ~14 stained_hardened_clay 7  
fill ~35 ~9 ~21 ~42 ~9 ~21 stained_hardened_clay 7  
fill ~35 ~9 ~24 ~37 ~9 ~24 wool 7  
fill ~35 ~9 ~40 ~49 ~9 ~40 wool 7  
fill ~35 ~9 ~44 ~44 ~9 ~44 dirt 1  
fill ~35 ~9 ~45 ~43 ~9 ~45 dirt 1  
fill ~35 ~9 ~47 ~41 ~9 ~47 dirt 1  
fill ~35 ~9 ~51 ~38 ~9 ~51 wool 7  
fill ~35 ~9 ~52 ~37 ~9 ~52 wool 7  
fill ~35 ~9 ~53 ~37 ~9 ~53 wool 7  
fill ~35 ~9 ~54 ~37 ~9 ~54 wool 7  
fill ~35 ~9 ~55 ~36 ~9 ~55 wool 7  
fill ~36 ~9 ~13 ~43 ~9 ~13 stained_hardened_clay 7  
fill ~36 ~9 ~22 ~42 ~9 ~22 stained_hardened_clay 7  
fill ~36 ~9 ~26 ~36 ~19 ~26 wool 7  
fill ~36 ~9 ~27 ~39 ~9 ~27 wool 7  
fill ~36 ~9 ~28 ~36 ~20 ~28 wool 7  
fill ~36 ~9 ~29 ~38 ~9 ~29 wool 7  
fill ~36 ~9 ~34 ~49 ~9 ~34 wool 7  
fill ~36 ~9 ~43 ~44 ~9 ~43 dirt 1  
fill ~36 ~9 ~48 ~41 ~9 ~48 dirt 1  
fill ~37 ~9 ~10 ~37 ~14 ~10 wool 7  
fill ~37 ~9 ~11 ~37 ~17 ~11 wool 7  
fill ~37 ~9 ~12 ~43 ~9 ~12 stained_hardened_clay 7  
fill ~37 ~9 ~35 ~47 ~9 ~35 wool 7  
fill ~37 ~9 ~39 ~48 ~9 ~39 wool 7  
fill ~37 ~9 ~42 ~43 ~9 ~42 dirt 1  
fill ~37 ~9 ~49 ~40 ~9 ~49 wool 7  
fill ~38 ~9 ~24 ~42 ~9 ~24 stained_hardened_clay 7  
fill ~38 ~9 ~25 ~38 ~10 ~25 wool 7  
fill ~38 ~9 ~36 ~46 ~9 ~36 wool 7  
fill ~38 ~9 ~37 ~46 ~9 ~37 wool 7  
fill ~38 ~9 ~38 ~47 ~9 ~38 wool 7  
fill ~39 ~9 ~9 ~39 ~16 ~9 wool 7  
fill ~39 ~9 ~10 ~42 ~9 ~10 stained_hardened_clay 7  
fill ~39 ~9 ~14 ~44 ~9 ~14 stained_hardened_clay 7  
fill ~39 ~9 ~18 ~45 ~9 ~18 stained_hardened_clay 7  
fill ~39 ~9 ~25 ~39 ~15 ~25 stained_hardened_clay 7  
fill ~39 ~9 ~26 ~43 ~9 ~26 stained_hardened_clay 7  
fill ~39 ~9 ~28 ~39 ~4 ~28 wool 7  
fill ~39 ~9 ~29 ~44 ~9 ~29 stained_hardened_clay 7  
fill ~39 ~9 ~41 ~41 ~9 ~41 dirt 1 
setblock ~39 ~9 ~51 stained_hardened_clay 7  
fill ~40 ~9 ~9 ~40 ~12 ~9 stained_hardened_clay 7  
fill ~40 ~9 ~11 ~43 ~9 ~11 stained_hardened_clay 7  
fill ~40 ~9 ~23 ~42 ~9 ~23 stained_hardened_clay 7  
fill ~40 ~9 ~27 ~43 ~9 ~27 stained_hardened_clay 7  
fill ~40 ~9 ~28 ~44 ~9 ~28 stained_hardened_clay 7  
fill ~40 ~9 ~30 ~40 ~13 ~30 stained_hardened_clay 7  
fill ~40 ~9 ~31 ~40 ~12 ~31 stained_hardened_clay 7 
setblock ~40 ~9 ~50 grass 0  
fill ~41 ~9 ~25 ~42 ~9 ~25 stained_hardened_clay 7 
setblock ~41 ~9 ~49 grass 0  
fill ~42 ~9 ~9 ~43 ~9 ~9 wool 7  
fill ~42 ~9 ~30 ~43 ~9 ~30 stained_hardened_clay 7  
fill ~42 ~9 ~31 ~43 ~9 ~31 stained_hardened_clay 7  
fill ~42 ~9 ~41 ~42 ~12 ~41 wool 7  
fill ~43 ~9 ~10 ~46 ~9 ~10 wool 7  
fill ~43 ~9 ~21 ~48 ~9 ~21 wool 7  
fill ~43 ~9 ~23 ~46 ~9 ~23 wool 7  
fill ~43 ~9 ~24 ~43 ~10 ~24 wool 7  
fill ~43 ~9 ~25 ~51 ~9 ~25 wool 7  
fill ~43 ~9 ~32 ~51 ~9 ~32 wool 7  
fill ~44 ~9 ~11 ~47 ~9 ~11 wool 7  
fill ~44 ~9 ~12 ~48 ~9 ~12 wool 7  
fill ~44 ~9 ~13 ~49 ~9 ~13 wool 7  
fill ~44 ~9 ~20 ~58 ~9 ~20 wool 7  
fill ~44 ~9 ~26 ~50 ~9 ~26 wool 7  
fill ~44 ~9 ~27 ~50 ~9 ~27 wool 7  
fill ~44 ~9 ~30 ~51 ~9 ~30 wool 7  
fill ~44 ~9 ~31 ~50 ~9 ~31 wool 7  
fill ~44 ~9 ~41 ~51 ~9 ~41 wool 7  
fill ~45 ~9 ~14 ~49 ~9 ~14 wool 7  
fill ~45 ~9 ~19 ~57 ~9 ~19 wool 7  
fill ~45 ~9 ~24 ~49 ~9 ~24 wool 7  
fill ~45 ~9 ~28 ~50 ~9 ~28 wool 7  
fill ~45 ~9 ~29 ~51 ~9 ~29 wool 7  
fill ~45 ~9 ~44 ~46 ~9 ~44 wool 7  
fill ~45 ~9 ~45 ~45 ~14 ~45 wool 7  
fill ~46 ~9 ~15 ~58 ~9 ~15 wool 7  
fill ~46 ~9 ~18 ~56 ~9 ~18 wool 7  
fill ~46 ~9 ~43 ~46 ~16 ~43 wool 7  
fill ~47 ~9 ~16 ~57 ~9 ~16 wool 7  
fill ~47 ~9 ~17 ~57 ~9 ~17 wool 7  
fill ~47 ~9 ~22 ~47 ~11 ~22 wool 7  
fill ~47 ~9 ~23 ~49 ~9 ~23 dirt 1  
fill ~47 ~9 ~36 ~50 ~9 ~36 stained_hardened_clay 7  
fill ~47 ~9 ~37 ~50 ~9 ~37 stained_hardened_clay 7  
fill ~47 ~9 ~42 ~49 ~9 ~42 wool 7  
fill ~47 ~9 ~43 ~47 ~9 ~44 grass 0  
fill ~48 ~9 ~22 ~49 ~9 ~22 dirt 1  
fill ~48 ~9 ~38 ~51 ~9 ~38 stained_hardened_clay 7 
setblock ~48 ~9 ~43 dirt 0  
fill ~49 ~9 ~21 ~50 ~9 ~21 dirt 1  
fill ~49 ~9 ~39 ~50 ~9 ~39 stained_hardened_clay 7  
fill ~50 ~9 ~22 ~53 ~9 ~22 wool 7  
fill ~50 ~9 ~23 ~52 ~9 ~23 wool 7  
fill ~50 ~9 ~24 ~52 ~9 ~24 grass 0  
fill ~50 ~9 ~40 ~52 ~9 ~40 grass 0  
fill ~51 ~9 ~21 ~58 ~9 ~21 wool 7 
setblock ~51 ~9 ~28 stained_hardened_clay 7  
fill ~51 ~9 ~35 ~52 ~9 ~35 grass 0  
fill ~51 ~9 ~36 ~52 ~9 ~36 grass 0  
fill ~51 ~9 ~37 ~52 ~9 ~37 grass 0  
fill ~51 ~9 ~39 ~52 ~9 ~39 grass 0  
fill ~52 ~9 ~25 ~52 ~13 ~25 stained_hardened_clay 7 
setblock ~52 ~9 ~38 grass 0  
fill ~53 ~9 ~14 ~53 ~17 ~14 stained_hardened_clay 7  
fill ~53 ~9 ~23 ~54 ~9 ~23 stained_hardened_clay 7  
fill ~53 ~9 ~24 ~53 ~13 ~24 stained_hardened_clay 7  
fill ~53 ~9 ~35 ~53 ~10 ~35 stained_hardened_clay 7  
fill ~53 ~9 ~36 ~54 ~9 ~36 stained_hardened_clay 7  
fill ~53 ~9 ~37 ~54 ~9 ~37 stained_hardened_clay 7  
fill ~53 ~9 ~38 ~54 ~9 ~38 stained_hardened_clay 7  
fill ~53 ~9 ~39 ~53 ~9 ~35 stained_hardened_clay 7  
fill ~54 ~9 ~14 ~56 ~9 ~14 wool 7  
fill ~54 ~9 ~22 ~56 ~9 ~22 stained_hardened_clay 7  
fill ~57 ~9 ~18 ~60 ~9 ~18 dirt 1  
fill ~58 ~9 ~17 ~59 ~9 ~17 dirt 1  
fill ~58 ~9 ~19 ~60 ~9 ~19 dirt 1  
fill ~59 ~9 ~16 ~59 ~11 ~16 dirt 1  
fill ~59 ~9 ~45 ~59 ~9 ~46 grass 0  
fill ~60 ~9 ~45 ~60 ~14 ~45 wool 7  
fill ~60 ~9 ~46 ~60 ~9 ~47 grass 0  
fill ~61 ~9 ~46 ~61 ~13 ~46 wool 7  
fill ~61 ~9 ~47 ~61 ~12 ~47 wool 7  
fill ~15 ~10 ~22 ~17 ~10 ~22 dirt 0  
fill ~15 ~10 ~23 ~17 ~10 ~23 dirt 0  
fill ~15 ~10 ~24 ~17 ~10 ~24 dirt 0  
fill ~16 ~10 ~20 ~17 ~10 ~20 dirt 0  
fill ~16 ~10 ~21 ~18 ~10 ~21 dirt 0  
fill ~16 ~10 ~25 ~20 ~10 ~25 dirt 1  
fill ~17 ~10 ~26 ~19 ~10 ~26 dirt 1  
fill ~18 ~10 ~18 ~23 ~10 ~18 wool 7  
fill ~18 ~10 ~20 ~24 ~10 ~20 dirt 1  
fill ~18 ~10 ~22 ~23 ~10 ~22 dirt 1  
fill ~18 ~10 ~23 ~22 ~10 ~23 dirt 1  
fill ~18 ~10 ~24 ~21 ~10 ~24 dirt 1  
fill ~18 ~10 ~27 ~21 ~10 ~27 wool 7  
fill ~19 ~10 ~16 ~23 ~10 ~16 wool 7  
fill ~19 ~10 ~19 ~19 ~13 ~19 dirt 1  
fill ~19 ~10 ~21 ~23 ~10 ~21 dirt 1  
fill ~19 ~10 ~29 ~19 ~20 ~29 wool 7  
fill ~19 ~10 ~30 ~19 ~18 ~30 wool 7  
fill ~20 ~10 ~15 ~22 ~10 ~15 wool 7  
fill ~20 ~10 ~17 ~23 ~10 ~17 wool 7  
fill ~20 ~10 ~26 ~22 ~10 ~26 wool 7  
fill ~20 ~10 ~32 ~20 ~11 ~32 dirt 1  
fill ~21 ~10 ~14 ~22 ~10 ~14 wool 7  
fill ~21 ~10 ~25 ~23 ~10 ~25 wool 7  
fill ~21 ~10 ~28 ~28 ~10 ~28 stained_hardened_clay 7  
fill ~21 ~10 ~29 ~28 ~10 ~29 stained_hardened_clay 7  
fill ~21 ~10 ~32 ~28 ~10 ~32 wool 7  
fill ~21 ~10 ~33 ~21 ~12 ~33 dirt 1  
fill ~22 ~10 ~19 ~24 ~10 ~19 dirt 1  
fill ~22 ~10 ~24 ~24 ~10 ~24 wool 7  
fill ~22 ~10 ~27 ~28 ~10 ~27 stained_hardened_clay 7  
fill ~22 ~10 ~30 ~28 ~10 ~30 stained_hardened_clay 7  
fill ~23 ~10 ~13 ~23 ~10 ~15 grass 0  
fill ~23 ~10 ~23 ~29 ~10 ~23 wool 7  
fill ~23 ~10 ~26 ~27 ~10 ~26 stained_hardened_clay 7  
fill ~23 ~10 ~33 ~27 ~10 ~33 wool 7  
fill ~23 ~10 ~34 ~23 ~12 ~34 dirt 1  
fill ~24 ~10 ~14 ~24 ~10 ~17 grass 0  
fill ~24 ~10 ~18 ~27 ~10 ~18 dirt 1  
fill ~24 ~10 ~21 ~34 ~10 ~21 wool 7  
fill ~24 ~10 ~22 ~29 ~10 ~22 wool 7  
fill ~24 ~10 ~25 ~27 ~10 ~25 stained_hardened_clay 7  
fill ~24 ~10 ~31 ~28 ~10 ~31 stained_hardened_clay 7  
fill ~25 ~10 ~14 ~25 ~10 ~16 dirt 0 
setblock ~25 ~10 ~17 grass 0  
fill ~25 ~10 ~19 ~33 ~10 ~19 wool 7  
fill ~25 ~10 ~24 ~26 ~10 ~24 stained_hardened_clay 7  
fill ~25 ~10 ~34 ~27 ~10 ~34 wool 7  
fill ~25 ~10 ~35 ~27 ~10 ~35 wool 7  
fill ~25 ~10 ~37 ~25 ~16 ~37 wool 7  
fill ~25 ~10 ~40 ~29 ~10 ~40 wool 7  
fill ~25 ~10 ~41 ~25 ~13 ~41 wool 7  
fill ~26 ~10 ~20 ~33 ~10 ~20 wool 7  
fill ~26 ~10 ~39 ~28 ~10 ~39 wool 7  
fill ~26 ~10 ~42 ~36 ~10 ~42 wool 7  
fill ~27 ~10 ~17 ~29 ~10 ~17 dirt 1  
fill ~27 ~10 ~24 ~29 ~10 ~24 wool 7  
fill ~27 ~10 ~43 ~35 ~10 ~43 wool 7  
fill ~27 ~10 ~44 ~29 ~10 ~44 stained_hardened_clay 7  
fill ~28 ~10 ~18 ~32 ~10 ~18 wool 7  
fill ~28 ~10 ~33 ~34 ~10 ~33 stained_hardened_clay 7  
fill ~28 ~10 ~34 ~35 ~10 ~34 stained_hardened_clay 7  
fill ~28 ~10 ~35 ~36 ~10 ~35 stained_hardened_clay 7  
fill ~28 ~10 ~36 ~37 ~10 ~36 stained_hardened_clay 7  
fill ~28 ~10 ~37 ~38 ~10 ~37 stained_hardened_clay 7  
fill ~28 ~10 ~38 ~28 ~16 ~38 wool 7  
fill ~28 ~10 ~45 ~29 ~10 ~45 stained_hardened_clay 7  
fill ~28 ~10 ~46 ~29 ~10 ~46 stained_hardened_clay 7  
fill ~29 ~10 ~27 ~30 ~10 ~27 wool 7  
fill ~29 ~10 ~28 ~31 ~10 ~28 wool 7  
fill ~29 ~10 ~29 ~38 ~10 ~29 wool 7  
fill ~29 ~10 ~30 ~38 ~10 ~30 wool 7  
fill ~29 ~10 ~31 ~38 ~10 ~31 wool 7  
fill ~29 ~10 ~32 ~32 ~10 ~32 stained_hardened_clay 7  
fill ~29 ~10 ~38 ~37 ~10 ~38 stained_hardened_clay 7  
fill ~29 ~10 ~39 ~36 ~10 ~39 stained_hardened_clay 7 
setblock ~29 ~10 ~47 stained_hardened_clay 7  
fill ~30 ~10 ~15 ~30 ~21 ~15 dirt 1  
fill ~30 ~10 ~16 ~30 ~21 ~16 dirt 1  
fill ~30 ~10 ~17 ~33 ~10 ~17 wool 7  
fill ~30 ~10 ~22 ~32 ~10 ~22 dirt 1  
fill ~30 ~10 ~23 ~33 ~10 ~23 dirt 1  
fill ~30 ~10 ~24 ~34 ~10 ~24 dirt 1  
fill ~30 ~10 ~25 ~35 ~10 ~25 dirt 1  
fill ~30 ~10 ~26 ~35 ~10 ~26 dirt 1  
fill ~30 ~10 ~40 ~34 ~10 ~40 stained_hardened_clay 7  
fill ~30 ~10 ~41 ~53 ~10 ~41 wool 7  
fill ~30 ~10 ~44 ~34 ~10 ~44 wool 7  
fill ~30 ~10 ~45 ~34 ~10 ~45 wool 7  
fill ~30 ~10 ~46 ~34 ~10 ~46 wool 7  
fill ~30 ~10 ~47 ~34 ~10 ~47 wool 7  
fill ~30 ~10 ~48 ~34 ~10 ~48 wool 7  
fill ~31 ~10 ~12 ~32 ~10 ~12 dirt 0  
fill ~31 ~10 ~13 ~32 ~10 ~13 dirt 0  
fill ~31 ~10 ~14 ~31 ~22 ~14 dirt 1  
fill ~31 ~10 ~16 ~33 ~10 ~16 wool 7  
fill ~31 ~10 ~27 ~35 ~10 ~27 dirt 1  
fill ~31 ~10 ~49 ~42 ~10 ~49 wool 7  
fill ~32 ~10 ~14 ~34 ~10 ~14 wool 7  
fill ~32 ~10 ~15 ~34 ~10 ~15 wool 7  
fill ~32 ~10 ~28 ~34 ~10 ~28 dirt 1  
fill ~32 ~10 ~50 ~33 ~10 ~50 wool 7  
fill ~33 ~10 ~13 ~35 ~10 ~13 wool 7  
fill ~33 ~10 ~32 ~40 ~10 ~32 wool 7  
fill ~33 ~10 ~54 ~35 ~10 ~54 dirt 1  
fill ~34 ~10 ~16 ~41 ~10 ~16 stained_hardened_clay 7  
fill ~34 ~10 ~17 ~41 ~10 ~17 stained_hardened_clay 7  
fill ~34 ~10 ~19 ~40 ~10 ~19 stained_hardened_clay 7  
fill ~34 ~10 ~20 ~41 ~10 ~20 stained_hardened_clay 7  
fill ~34 ~10 ~23 ~36 ~10 ~23 wool 7  
fill ~34 ~10 ~50 ~34 ~13 ~50 dirt 1  
fill ~35 ~10 ~12 ~36 ~10 ~12 wool 7  
fill ~35 ~10 ~15 ~43 ~10 ~15 stained_hardened_clay 7  
fill ~35 ~10 ~21 ~41 ~10 ~21 stained_hardened_clay 7  
fill ~35 ~10 ~24 ~37 ~10 ~24 wool 7  
fill ~35 ~10 ~28 ~35 ~20 ~28 wool 7 
setblock ~35 ~10 ~33 wool 7  
fill ~35 ~10 ~40 ~54 ~10 ~40 wool 7  
fill ~35 ~10 ~44 ~45 ~10 ~44 dirt 1  
fill ~35 ~10 ~45 ~44 ~10 ~45 dirt 1  
fill ~35 ~10 ~47 ~42 ~10 ~47 dirt 1  
fill ~35 ~10 ~48 ~42 ~10 ~48 dirt 1  
fill ~35 ~10 ~50 ~40 ~10 ~50 wool 7  
fill ~35 ~10 ~51 ~40 ~10 ~51 wool 7  
fill ~35 ~10 ~52 ~35 ~20 ~52 dirt 1  
fill ~35 ~10 ~53 ~35 ~15 ~53 dirt 1  
fill ~35 ~10 ~55 ~35 ~15 ~55 dirt 1  
fill ~36 ~10 ~11 ~36 ~17 ~11 wool 7  
fill ~36 ~10 ~13 ~43 ~10 ~13 stained_hardened_clay 7  
fill ~36 ~10 ~22 ~41 ~10 ~22 stained_hardened_clay 7  
fill ~36 ~10 ~27 ~38 ~10 ~27 wool 7  
fill ~36 ~10 ~34 ~50 ~10 ~34 wool 7  
fill ~36 ~10 ~43 ~44 ~10 ~43 dirt 1  
fill ~36 ~10 ~52 ~38 ~10 ~52 wool 7  
fill ~36 ~10 ~53 ~38 ~10 ~53 wool 7  
fill ~36 ~10 ~54 ~38 ~10 ~54 wool 7  
fill ~36 ~10 ~55 ~37 ~10 ~55 wool 7  
fill ~37 ~10 ~12 ~43 ~10 ~12 stained_hardened_clay 7  
fill ~37 ~10 ~35 ~48 ~10 ~35 wool 7  
fill ~37 ~10 ~39 ~55 ~10 ~39 wool 7  
fill ~37 ~10 ~42 ~42 ~10 ~42 dirt 1  
fill ~38 ~10 ~9 ~38 ~14 ~9 wool 7  
fill ~38 ~10 ~24 ~42 ~10 ~24 stained_hardened_clay 7  
fill ~38 ~10 ~36 ~47 ~10 ~36 wool 7  
fill ~38 ~10 ~38 ~48 ~10 ~38 wool 7  
fill ~39 ~10 ~8 ~41 ~10 ~8 wool 7  
fill ~39 ~10 ~10 ~43 ~10 ~10 stained_hardened_clay 7  
fill ~39 ~10 ~14 ~43 ~10 ~14 stained_hardened_clay 7  
fill ~39 ~10 ~18 ~40 ~10 ~18 stained_hardened_clay 7  
fill ~39 ~10 ~26 ~44 ~10 ~26 stained_hardened_clay 7  
fill ~39 ~10 ~27 ~45 ~10 ~27 stained_hardened_clay 7  
fill ~39 ~10 ~28 ~45 ~10 ~28 stained_hardened_clay 7  
fill ~39 ~10 ~29 ~45 ~10 ~29 stained_hardened_clay 7  
fill ~39 ~10 ~30 ~39 ~13 ~30 stained_hardened_clay 7  
fill ~39 ~10 ~31 ~39 ~11 ~31 stained_hardened_clay 7  
fill ~39 ~10 ~33 ~52 ~10 ~33 wool 7  
fill ~39 ~10 ~37 ~47 ~10 ~37 wool 7 
setblock ~39 ~10 ~52 stained_hardened_clay 7  
fill ~40 ~10 ~11 ~43 ~10 ~11 stained_hardened_clay 7  
fill ~40 ~10 ~23 ~41 ~10 ~23 stained_hardened_clay 7  
fill ~41 ~10 ~18 ~56 ~10 ~18 wool 7  
fill ~41 ~10 ~19 ~57 ~10 ~19 wool 7  
fill ~41 ~10 ~25 ~43 ~10 ~25 stained_hardened_clay 7 
setblock ~41 ~10 ~50 grass 0 
setblock ~41 ~10 ~51 stained_hardened_clay 7  
fill ~42 ~10 ~9 ~42 ~19 ~9 stained_hardened_clay 7  
fill ~42 ~10 ~16 ~57 ~10 ~16 wool 7  
fill ~42 ~10 ~17 ~57 ~10 ~17 wool 7  
fill ~42 ~10 ~20 ~59 ~10 ~20 wool 7  
fill ~42 ~10 ~21 ~58 ~10 ~21 wool 7  
fill ~42 ~10 ~22 ~42 ~13 ~22 wool 7  
fill ~42 ~10 ~23 ~51 ~10 ~23 wool 7  
fill ~42 ~10 ~30 ~45 ~10 ~30 stained_hardened_clay 7  
fill ~42 ~10 ~31 ~44 ~10 ~31 stained_hardened_clay 7  
fill ~42 ~10 ~46 ~44 ~10 ~46 dirt 1  
fill ~42 ~10 ~50 ~42 ~20 ~50 wool 7  
fill ~43 ~10 ~9 ~45 ~10 ~9 wool 7  
fill ~43 ~10 ~32 ~51 ~10 ~32 wool 7  
fill ~43 ~10 ~42 ~43 ~13 ~42 wool 7 
setblock ~43 ~10 ~47 dirt 0  
fill ~44 ~10 ~10 ~47 ~10 ~10 wool 7  
fill ~44 ~10 ~11 ~48 ~10 ~11 wool 7  
fill ~44 ~10 ~12 ~48 ~10 ~12 wool 7  
fill ~44 ~10 ~13 ~49 ~10 ~13 wool 7  
fill ~44 ~10 ~14 ~50 ~10 ~14 wool 7  
fill ~44 ~10 ~15 ~58 ~10 ~15 wool 7  
fill ~44 ~10 ~25 ~50 ~10 ~25 wool 7  
fill ~44 ~10 ~47 ~46 ~10 ~47 grass 0  
fill ~45 ~10 ~24 ~50 ~10 ~24 wool 7  
fill ~45 ~10 ~26 ~50 ~10 ~26 wool 7  
fill ~45 ~10 ~31 ~51 ~10 ~31 wool 7  
fill ~45 ~10 ~46 ~47 ~10 ~46 grass 0  
fill ~46 ~10 ~27 ~50 ~10 ~27 wool 7  
fill ~46 ~10 ~28 ~51 ~10 ~28 wool 7  
fill ~46 ~10 ~29 ~52 ~10 ~29 wool 7  
fill ~46 ~10 ~30 ~52 ~10 ~30 wool 7  
fill ~46 ~10 ~44 ~47 ~10 ~44 wool 7  
fill ~46 ~10 ~45 ~48 ~10 ~45 grass 0  
fill ~47 ~10 ~42 ~48 ~10 ~42 wool 7  
fill ~47 ~10 ~43 ~47 ~10 ~10 wool 7  
fill ~48 ~10 ~22 ~52 ~10 ~22 wool 7  
fill ~48 ~10 ~36 ~54 ~10 ~36 stained_hardened_clay 7  
fill ~48 ~10 ~37 ~54 ~10 ~37 stained_hardened_clay 7  
fill ~48 ~10 ~43 ~48 ~14 ~43 dirt 1  
fill ~48 ~10 ~44 ~49 ~10 ~44 dirt 0  
fill ~49 ~10 ~38 ~55 ~10 ~38 stained_hardened_clay 7  
fill ~49 ~10 ~42 ~52 ~10 ~42 dirt 1  
fill ~49 ~10 ~43 ~50 ~10 ~43 dirt 0  
fill ~51 ~10 ~14 ~55 ~10 ~14 stained_hardened_clay 7  
fill ~51 ~10 ~24 ~54 ~10 ~24 stained_hardened_clay 7  
fill ~51 ~10 ~25 ~51 ~12 ~25 stained_hardened_clay 7  
fill ~51 ~10 ~26 ~52 ~10 ~26 stained_hardened_clay 7  
fill ~51 ~10 ~27 ~51 ~11 ~27 stained_hardened_clay 7  
fill ~51 ~10 ~34 ~51 ~10 ~38 stained_hardened_clay 7  
fill ~52 ~10 ~23 ~55 ~10 ~23 stained_hardened_clay 7 
setblock ~52 ~10 ~28 stained_hardened_clay 7 
setblock ~52 ~10 ~31 grass 0 
setblock ~52 ~10 ~34 grass 0  
fill ~52 ~10 ~35 ~52 ~11 ~35 stained_hardened_clay 7  
fill ~53 ~10 ~13 ~54 ~10 ~13 stained_hardened_clay 7  
fill ~53 ~10 ~22 ~56 ~10 ~22 stained_hardened_clay 7  
fill ~53 ~10 ~25 ~53 ~13 ~25 stained_hardened_clay 7  
fill ~53 ~10 ~34 ~54 ~10 ~34 wool 7 
setblock ~54 ~10 ~35 stained_hardened_clay 7  
fill ~55 ~10 ~34 ~55 ~10 ~37 grass 0  
fill ~55 ~10 ~45 ~57 ~10 ~45 dirt 0  
fill ~56 ~10 ~14 ~57 ~10 ~14 wool 7  
fill ~56 ~10 ~35 ~56 ~10 ~37 grass 0  
fill ~56 ~10 ~44 ~57 ~10 ~44 dirt 0  
fill ~56 ~10 ~46 ~57 ~10 ~46 dirt 0  
fill ~57 ~10 ~18 ~60 ~10 ~18 dirt 1  
fill ~58 ~10 ~17 ~59 ~10 ~17 dirt 1  
fill ~58 ~10 ~19 ~60 ~10 ~19 dirt 1  
fill ~58 ~10 ~44 ~58 ~10 ~47 grass 0  
fill ~59 ~10 ~44 ~60 ~10 ~44 wool 7  
fill ~59 ~10 ~45 ~59 ~16 ~45 wool 7  
fill ~59 ~10 ~46 ~62 ~10 ~46 wool 7  
fill ~59 ~10 ~47 ~62 ~10 ~47 wool 7  
fill ~60 ~10 ~48 ~61 ~10 ~48 wool 7  
fill ~61 ~10 ~45 ~61 ~13 ~45 wool 7  
fill ~12 ~11 ~28 ~15 ~11 ~28 grass 0  
fill ~12 ~11 ~29 ~14 ~11 ~29 grass 0  
fill ~12 ~11 ~30 ~12 ~11 ~28 grass 0  
fill ~13 ~11 ~25 ~14 ~11 ~25 wool 7  
fill ~13 ~11 ~26 ~15 ~11 ~26 wool 7  
fill ~13 ~11 ~27 ~16 ~11 ~27 grass 0   
fill ~14 ~11 ~21 ~15 ~11 ~21 dirt 0  
fill ~14 ~11 ~22 ~23 ~11 ~22 dirt 1  
fill ~14 ~11 ~23 ~22 ~11 ~23 dirt 1  
fill ~14 ~11 ~24 ~21 ~11 ~24 dirt 1 
setblock ~15 ~11 ~19 dirt 0  
fill ~15 ~11 ~20 ~23 ~11 ~20 dirt 1  
fill ~15 ~11 ~25 ~20 ~11 ~25 dirt 1  
fill ~16 ~11 ~19 ~23 ~11 ~19 dirt 1  
fill ~16 ~11 ~21 ~23 ~11 ~21 dirt 1  
fill ~16 ~11 ~26 ~19 ~11 ~26 dirt 1  
fill ~17 ~11 ~18 ~33 ~11 ~18 wool 7  
fill ~17 ~11 ~27 ~21 ~11 ~27 wool 7  
fill ~18 ~11 ~28 ~18 ~21 ~28 wool 7  
fill ~18 ~11 ~29 ~18 ~19 ~29 wool 7  
fill ~19 ~11 ~16 ~24 ~11 ~16 wool 7  
fill ~19 ~11 ~31 ~19 ~18 ~31 wool 7  
fill ~20 ~11 ~14 ~20 ~19 ~14 stained_hardened_clay 7  
fill ~20 ~11 ~15 ~24 ~11 ~15 wool 7  
fill ~20 ~11 ~17 ~25 ~11 ~17 wool 7  
fill ~20 ~11 ~26 ~22 ~11 ~26 wool 7  
fill ~20 ~11 ~33 ~20 ~12 ~33 dirt 1  
fill ~20 ~11 ~34 ~23 ~11 ~34 dirt 1  
fill ~21 ~11 ~13 ~21 ~21 ~13 stained_hardened_clay 7  
fill ~21 ~11 ~14 ~24 ~11 ~14 wool 7  
fill ~21 ~11 ~25 ~23 ~11 ~25 wool 7  
fill ~21 ~11 ~28 ~28 ~11 ~28 stained_hardened_clay 7  
fill ~21 ~11 ~29 ~29 ~11 ~29 stained_hardened_clay 7  
fill ~21 ~11 ~32 ~26 ~11 ~32 wool 7  
fill ~22 ~11 ~12 ~23 ~11 ~12 wool 7  
fill ~22 ~11 ~13 ~23 ~11 ~13 wool 7  
fill ~22 ~11 ~24 ~24 ~11 ~24 wool 7  
fill ~22 ~11 ~27 ~28 ~11 ~27 stained_hardened_clay 7  
fill ~22 ~11 ~30 ~30 ~11 ~30 stained_hardened_clay 7  
fill ~23 ~11 ~23 ~29 ~11 ~23 wool 7  
fill ~23 ~11 ~26 ~28 ~11 ~26 stained_hardened_clay 7  
fill ~23 ~11 ~31 ~33 ~11 ~31 stained_hardened_clay 7  
fill ~23 ~11 ~33 ~27 ~11 ~33 wool 7  
fill ~23 ~11 ~38 ~24 ~11 ~38 dirt 0  
fill ~23 ~11 ~39 ~24 ~11 ~39 grass 0  
fill ~23 ~11 ~40 ~24 ~11 ~40 grass 0  
fill ~24 ~11 ~11 ~25 ~11 ~11 grass 0  
fill ~24 ~11 ~12 ~25 ~11 ~12 grass 0  
fill ~24 ~11 ~13 ~25 ~11 ~13 grass 0  
fill ~24 ~11 ~19 ~33 ~11 ~19 wool 7  
fill ~24 ~11 ~20 ~24 ~17 ~20 wool 7  
fill ~24 ~11 ~21 ~35 ~11 ~21 wool 7  
fill ~24 ~11 ~22 ~30 ~11 ~22 wool 7  
fill ~24 ~11 ~25 ~27 ~11 ~25 stained_hardened_clay 7  
fill ~24 ~11 ~34 ~27 ~11 ~34 wool 7  
fill ~24 ~11 ~36 ~24 ~12 ~36 dirt 1  
fill ~24 ~11 ~37 ~24 ~12 ~37 dirt 1  
fill ~24 ~11 ~41 ~24 ~13 ~41 wool 7  
fill ~24 ~11 ~42 ~47 ~11 ~42 wool 7  
fill ~25 ~11 ~14 ~25 ~11 ~16 dirt 1  
fill ~25 ~11 ~24 ~26 ~11 ~24 stained_hardened_clay 7  
fill ~25 ~11 ~35 ~27 ~11 ~35 wool 7  
fill ~25 ~11 ~38 ~25 ~14 ~38 wool 7  
fill ~25 ~11 ~39 ~30 ~11 ~39 wool 7  
fill ~25 ~11 ~40 ~55 ~11 ~40 wool 7  
fill ~26 ~11 ~11 ~26 ~11 ~16 dirt 0 
setblock ~26 ~11 ~17 dirt 1  
fill ~26 ~11 ~20 ~34 ~11 ~20 wool 7  
fill ~27 ~11 ~13 ~27 ~11 ~16 dirt 0  
fill ~27 ~11 ~24 ~29 ~11 ~24 wool 7  
fill ~27 ~11 ~32 ~34 ~11 ~32 stained_hardened_clay 7  
fill ~27 ~11 ~43 ~35 ~11 ~43 wool 7  
fill ~27 ~11 ~44 ~29 ~11 ~44 stained_hardened_clay 7  
fill ~28 ~11 ~14 ~30 ~11 ~14 dirt 0  
fill ~28 ~11 ~15 ~28 ~11 ~14 dirt 0  
fill ~28 ~11 ~16 ~28 ~19 ~16 dirt 1  
fill ~28 ~11 ~17 ~28 ~20 ~17 dirt 1  
fill ~28 ~11 ~33 ~35 ~11 ~33 stained_hardened_clay 7  
fill ~28 ~11 ~34 ~35 ~11 ~34 stained_hardened_clay 7  
fill ~28 ~11 ~35 ~36 ~11 ~35 stained_hardened_clay 7  
fill ~28 ~11 ~36 ~37 ~11 ~36 stained_hardened_clay 7  
fill ~28 ~11 ~37 ~28 ~17 ~37 wool 7  
fill ~28 ~11 ~45 ~30 ~11 ~45 stained_hardened_clay 7  
fill ~29 ~11 ~12 ~30 ~11 ~12 dirt 0  
fill ~29 ~11 ~13 ~30 ~11 ~13 dirt 0  
fill ~29 ~11 ~15 ~29 ~20 ~15 dirt 1  
fill ~29 ~11 ~27 ~31 ~11 ~27 wool 7  
fill ~29 ~11 ~28 ~37 ~11 ~28 wool 7  
fill ~29 ~11 ~37 ~39 ~11 ~37 stained_hardened_clay 7  
fill ~29 ~11 ~38 ~41 ~11 ~38 stained_hardened_clay 7  
fill ~29 ~11 ~46 ~31 ~11 ~46 stained_hardened_clay 7 
setblock ~30 ~11 ~11 dirt 0  
fill ~30 ~11 ~17 ~33 ~11 ~17 wool 7  
fill ~30 ~11 ~23 ~33 ~11 ~23 dirt 1  
fill ~30 ~11 ~24 ~34 ~11 ~24 dirt 1  
fill ~30 ~11 ~25 ~30 ~18 ~25 wool 7  
fill ~30 ~11 ~26 ~30 ~18 ~26 wool 7  
fill ~30 ~11 ~29 ~37 ~11 ~29 wool 7  
fill ~30 ~11 ~41 ~48 ~11 ~41 wool 7  
fill ~30 ~11 ~44 ~34 ~11 ~44 wool 7  
fill ~30 ~11 ~47 ~31 ~11 ~47 stained_hardened_clay 7  
fill ~31 ~11 ~11 ~32 ~11 ~11 dirt 1  
fill ~31 ~11 ~12 ~33 ~11 ~12 dirt 1  
fill ~31 ~11 ~13 ~32 ~11 ~13 dirt 1  
fill ~31 ~11 ~15 ~31 ~22 ~15 dirt 1  
fill ~31 ~11 ~16 ~33 ~11 ~16 wool 7  
fill ~31 ~11 ~22 ~32 ~11 ~22 dirt 1  
fill ~31 ~11 ~25 ~34 ~11 ~25 dirt 1  
fill ~31 ~11 ~26 ~34 ~11 ~26 dirt 1  
fill ~31 ~11 ~30 ~37 ~11 ~30 wool 7  
fill ~31 ~11 ~39 ~40 ~11 ~39 stained_hardened_clay 7  
fill ~31 ~11 ~45 ~34 ~11 ~45 wool 7  
fill ~31 ~11 ~48 ~34 ~11 ~48 wool 7  
fill ~32 ~11 ~14 ~35 ~11 ~14 wool 7  
fill ~32 ~11 ~15 ~34 ~11 ~15 wool 7  
fill ~32 ~11 ~27 ~34 ~11 ~27 dirt 1  
fill ~32 ~11 ~46 ~34 ~11 ~46 wool 7  
fill ~32 ~11 ~47 ~34 ~11 ~47 wool 7  
fill ~32 ~11 ~49 ~34 ~11 ~49 wool 7  
fill ~33 ~11 ~13 ~35 ~11 ~13 wool 7  
fill ~33 ~11 ~50 ~33 ~21 ~50 wool 7  
fill ~33 ~11 ~54 ~36 ~11 ~54 dirt 1  
fill ~34 ~11 ~12 ~36 ~11 ~12 wool 7  
fill ~34 ~11 ~16 ~40 ~11 ~16 stained_hardened_clay 7  
fill ~34 ~11 ~17 ~39 ~11 ~17 stained_hardened_clay 7  
fill ~34 ~11 ~19 ~39 ~11 ~19 stained_hardened_clay 7  
fill ~34 ~11 ~23 ~36 ~11 ~23 wool 7 
setblock ~34 ~11 ~31 wool 7  
fill ~35 ~11 ~15 ~41 ~11 ~15 stained_hardened_clay 7  
fill ~35 ~11 ~20 ~39 ~11 ~20 stained_hardened_clay 7  
fill ~35 ~11 ~24 ~37 ~11 ~24 wool 7  
fill ~35 ~11 ~25 ~35 ~18 ~25 wool 7  
fill ~35 ~11 ~26 ~35 ~18 ~26 wool 7  
fill ~35 ~11 ~27 ~37 ~11 ~27 wool 7  
fill ~35 ~11 ~44 ~45 ~11 ~44 dirt 1  
fill ~35 ~11 ~45 ~44 ~11 ~45 dirt 1  
fill ~35 ~11 ~47 ~43 ~11 ~47 dirt 1  
fill ~35 ~11 ~48 ~42 ~11 ~48 dirt 1  
fill ~35 ~11 ~49 ~40 ~11 ~49 dirt 1  
fill ~35 ~11 ~50 ~36 ~11 ~50 dirt 1  
fill ~35 ~11 ~51 ~36 ~11 ~51 dirt 1  
fill ~36 ~11 ~13 ~43 ~11 ~13 stained_hardened_clay 7  
fill ~36 ~11 ~21 ~39 ~11 ~21 stained_hardened_clay 7  
fill ~36 ~11 ~22 ~40 ~11 ~22 stained_hardened_clay 7  
fill ~36 ~11 ~34 ~55 ~11 ~34 wool 7  
fill ~36 ~11 ~43 ~43 ~11 ~43 dirt 1  
fill ~36 ~11 ~52 ~36 ~19 ~52 dirt 1  
fill ~36 ~11 ~53 ~36 ~15 ~53 dirt 1  
fill ~36 ~11 ~55 ~36 ~15 ~55 dirt 1  
fill ~36 ~11 ~56 ~36 ~15 ~56 dirt 1  
fill ~37 ~11 ~12 ~43 ~11 ~12 stained_hardened_clay 7  
fill ~37 ~11 ~35 ~49 ~11 ~35 wool 7  
fill ~37 ~11 ~50 ~42 ~11 ~50 wool 7  
fill ~37 ~11 ~51 ~42 ~11 ~51 wool 7  
fill ~37 ~11 ~52 ~40 ~11 ~52 wool 7  
fill ~37 ~11 ~53 ~38 ~11 ~53 wool 7  
fill ~37 ~11 ~54 ~38 ~11 ~54 wool 7  
fill ~37 ~11 ~55 ~37 ~11 ~50 wool 7  
fill ~38 ~11 ~8 ~43 ~11 ~8 wool 7  
fill ~38 ~11 ~24 ~43 ~11 ~24 stained_hardened_clay 7  
fill ~38 ~11 ~25 ~38 ~14 ~25 stained_hardened_clay 7  
fill ~38 ~11 ~26 ~46 ~11 ~26 stained_hardened_clay 7  
fill ~38 ~11 ~27 ~46 ~11 ~27 stained_hardened_clay 7  
fill ~38 ~11 ~28 ~47 ~11 ~28 stained_hardened_clay 7  
fill ~38 ~11 ~29 ~46 ~11 ~29 stained_hardened_clay 7  
fill ~38 ~11 ~30 ~38 ~12 ~30 stained_hardened_clay 7  
fill ~38 ~11 ~36 ~48 ~11 ~36 wool 7  
fill ~39 ~11 ~10 ~43 ~11 ~10 stained_hardened_clay 7  
fill ~39 ~11 ~14 ~42 ~11 ~14 stained_hardened_clay 7  
fill ~39 ~11 ~18 ~39 ~7 ~18 stained_hardened_clay 7  
fill ~39 ~11 ~33 ~54 ~11 ~33 wool 7  
fill ~40 ~11 ~7 ~40 ~14 ~7 wool 7  
fill ~40 ~11 ~11 ~43 ~11 ~11 stained_hardened_clay 7  
fill ~40 ~11 ~17 ~56 ~11 ~17 wool 7  
fill ~40 ~11 ~18 ~56 ~11 ~18 wool 7  
fill ~40 ~11 ~19 ~56 ~11 ~19 wool 7  
fill ~40 ~11 ~20 ~58 ~11 ~20 wool 7  
fill ~40 ~11 ~21 ~58 ~11 ~21 wool 7  
fill ~40 ~11 ~23 ~41 ~11 ~23 stained_hardened_clay 7  
fill ~40 ~11 ~32 ~54 ~11 ~32 wool 7  
fill ~40 ~11 ~37 ~49 ~11 ~37 wool 7  
fill ~41 ~11 ~16 ~57 ~11 ~16 wool 7  
fill ~41 ~11 ~22 ~41 ~15 ~22 wool 7  
fill ~41 ~11 ~25 ~44 ~11 ~25 stained_hardened_clay 7  
fill ~41 ~11 ~39 ~56 ~11 ~39 wool 7  
fill ~41 ~11 ~49 ~43 ~11 ~49 wool 7  
fill ~42 ~11 ~15 ~51 ~11 ~15 wool 7  
fill ~42 ~11 ~23 ~51 ~11 ~23 wool 7  
fill ~42 ~11 ~30 ~46 ~11 ~30 stained_hardened_clay 7  
fill ~42 ~11 ~31 ~44 ~11 ~31 stained_hardened_clay 7  
fill ~42 ~11 ~38 ~56 ~11 ~38 wool 7  
fill ~42 ~11 ~46 ~44 ~11 ~46 dirt 1  
fill ~43 ~11 ~9 ~46 ~11 ~9 wool 7  
fill ~43 ~11 ~14 ~50 ~11 ~14 wool 7 
setblock ~43 ~11 ~48 grass 0  
fill ~44 ~11 ~10 ~48 ~11 ~10 wool 7  
fill ~44 ~11 ~11 ~48 ~11 ~11 wool 7  
fill ~44 ~11 ~12 ~49 ~11 ~12 wool 7  
fill ~44 ~11 ~13 ~49 ~11 ~13 wool 7  
fill ~44 ~11 ~43 ~44 ~15 ~43 wool 7  
fill ~44 ~11 ~47 ~46 ~11 ~47 wool 7  
fill ~44 ~11 ~48 ~45 ~11 ~48 wool 7  
fill ~45 ~11 ~24 ~50 ~11 ~24 wool 7  
fill ~45 ~11 ~25 ~50 ~11 ~25 wool 7  
fill ~45 ~11 ~31 ~53 ~11 ~31 wool 7  
fill ~45 ~11 ~46 ~47 ~11 ~46 wool 7  
fill ~46 ~11 ~44 ~46 ~15 ~44 wool 7  
fill ~46 ~11 ~45 ~48 ~11 ~45 wool 7  
fill ~46 ~11 ~48 ~46 ~20 ~48 stained_hardened_clay 7  
fill ~47 ~11 ~26 ~50 ~11 ~26 wool 7  
fill ~47 ~11 ~27 ~50 ~11 ~27 wool 7  
fill ~47 ~11 ~29 ~54 ~11 ~29 wool 7  
fill ~47 ~11 ~30 ~54 ~11 ~30 wool 7  
fill ~47 ~11 ~43 ~47 ~13 ~43 dirt 1  
fill ~47 ~11 ~44 ~49 ~11 ~44 dirt 1  
fill ~47 ~11 ~47 ~52 ~11 ~47 grass 0  
fill ~47 ~11 ~48 ~52 ~11 ~48 grass 0  
fill ~48 ~11 ~22 ~51 ~11 ~22 wool 7  
fill ~48 ~11 ~28 ~48 ~23 ~28 wool 7  
fill ~48 ~11 ~42 ~56 ~11 ~42 dirt 1  
fill ~48 ~11 ~46 ~50 ~11 ~46 grass 0  
fill ~48 ~11 ~49 ~52 ~11 ~49 grass 0  
fill ~49 ~11 ~36 ~54 ~11 ~36 stained_hardened_clay 7  
fill ~49 ~11 ~41 ~54 ~11 ~41 dirt 1  
fill ~49 ~11 ~43 ~50 ~11 ~43 dirt 1  
fill ~49 ~11 ~45 ~52 ~11 ~45 dirt 0  
fill ~50 ~11 ~13 ~54 ~11 ~13 stained_hardened_clay 7  
fill ~50 ~11 ~28 ~53 ~11 ~28 wool 7  
fill ~50 ~11 ~37 ~54 ~11 ~37 stained_hardened_clay 7  
fill ~50 ~11 ~44 ~52 ~11 ~44 dirt 0  
fill ~50 ~11 ~50 ~52 ~11 ~50 grass 0  
fill ~51 ~11 ~14 ~55 ~11 ~14 stained_hardened_clay 7  
fill ~51 ~11 ~24 ~55 ~11 ~24 stained_hardened_clay 7  
fill ~51 ~11 ~26 ~53 ~11 ~26 stained_hardened_clay 7 
setblock ~51 ~11 ~35 stained_hardened_clay 7  
fill ~51 ~11 ~43 ~52 ~11 ~43 dirt 0  
fill ~51 ~11 ~46 ~52 ~11 ~46 dirt 0  
fill ~52 ~11 ~15 ~54 ~11 ~15 stained_hardened_clay 7  
fill ~52 ~11 ~22 ~57 ~11 ~22 stained_hardened_clay 7  
fill ~52 ~11 ~23 ~56 ~11 ~23 stained_hardened_clay 7 
setblock ~52 ~11 ~27 grass 0 
setblock ~53 ~11 ~27 stained_hardened_clay 7  
fill ~53 ~11 ~35 ~57 ~11 ~35 wool 7  
fill ~53 ~11 ~43 ~54 ~11 ~43 dirt 1  
fill ~53 ~11 ~44 ~54 ~11 ~44 dirt 1  
fill ~53 ~11 ~45 ~57 ~11 ~45 dirt 1  
fill ~53 ~11 ~46 ~54 ~11 ~46 dirt 1  
fill ~53 ~11 ~47 ~53 ~11 ~49 wool 7  
fill ~54 ~11 ~25 ~54 ~13 ~25 stained_hardened_clay 7  
fill ~54 ~11 ~47 ~54 ~13 ~47 dirt 1  
fill ~54 ~11 ~48 ~54 ~28 ~48 wool 7  
fill ~55 ~11 ~15 ~58 ~11 ~15 wool 7  
fill ~55 ~11 ~32 ~56 ~11 ~32 dirt 0  
fill ~55 ~11 ~33 ~56 ~11 ~33 dirt 0  
fill ~55 ~11 ~36 ~57 ~11 ~36 wool 7  
fill ~55 ~11 ~37 ~57 ~11 ~37 wool 7  
fill ~55 ~11 ~43 ~56 ~11 ~43 dirt 0  
fill ~55 ~11 ~44 ~55 ~11 ~43 dirt 0  
fill ~55 ~11 ~46 ~55 ~11 ~48 dirt 0  
fill ~56 ~11 ~14 ~56 ~8 ~14 wool 7  
fill ~56 ~11 ~34 ~57 ~11 ~34 grass 0  
fill ~56 ~11 ~44 ~57 ~11 ~44 dirt 1  
fill ~56 ~11 ~46 ~57 ~11 ~46 dirt 1  
fill ~56 ~11 ~47 ~57 ~11 ~47 dirt 0  
fill ~56 ~11 ~48 ~56 ~11 ~47 dirt 0  
fill ~57 ~11 ~17 ~59 ~11 ~17 dirt 1  
fill ~57 ~11 ~18 ~59 ~11 ~18 dirt 1  
fill ~57 ~11 ~19 ~59 ~11 ~19 dirt 1 
setblock ~57 ~11 ~33 grass 0  
fill ~57 ~11 ~43 ~57 ~13 ~43 dirt 1  
fill ~57 ~11 ~48 ~58 ~11 ~48 dirt 1  
fill ~58 ~11 ~43 ~59 ~11 ~43 wool 7  
fill ~58 ~11 ~44 ~60 ~11 ~44 wool 7  
fill ~58 ~11 ~45 ~58 ~11 ~47 wool 7 
setblock ~59 ~11 ~20 dirt 1  
fill ~59 ~11 ~46 ~62 ~11 ~46 wool 7  
fill ~59 ~11 ~47 ~62 ~11 ~47 wool 7  
fill ~59 ~11 ~48 ~61 ~11 ~48 wool 7  
fill ~10 ~12 ~29 ~10 ~12 ~30 stained_hardened_clay 7  
fill ~11 ~12 ~26 ~15 ~12 ~26 wool 7  
fill ~11 ~12 ~27 ~12 ~12 ~27 grass 0  
fill ~11 ~12 ~28 ~15 ~12 ~28 wool 7 
setblock ~11 ~12 ~29 grass 0  
fill ~11 ~12 ~30 ~14 ~12 ~30 stained_hardened_clay 7  
fill ~11 ~12 ~31 ~12 ~12 ~31 stained_hardened_clay 7  
fill ~12 ~12 ~24 ~12 ~24 ~24 dirt 1  
fill ~12 ~12 ~25 ~20 ~12 ~25 dirt 1  
fill ~12 ~12 ~29 ~13 ~12 ~29 stained_hardened_clay 7  
fill ~13 ~12 ~20 ~14 ~12 ~20 dirt 0  
fill ~13 ~12 ~21 ~23 ~12 ~21 dirt 1  
fill ~13 ~12 ~22 ~23 ~12 ~22 dirt 1  
fill ~13 ~12 ~23 ~22 ~12 ~23 dirt 1 
setblock ~13 ~12 ~24 dirt 0  
fill ~13 ~12 ~27 ~21 ~12 ~27 wool 7 
setblock ~14 ~12 ~18 dirt 0  
fill ~14 ~12 ~19 ~21 ~12 ~19 dirt 1  
fill ~14 ~12 ~24 ~21 ~12 ~24 dirt 1  
fill ~14 ~12 ~29 ~14 ~17 ~29 wool 7  
fill ~15 ~12 ~18 ~15 ~15 ~18 dirt 1  
fill ~15 ~12 ~20 ~23 ~12 ~20 dirt 1  
fill ~15 ~12 ~29 ~17 ~12 ~29 grass 0  
fill ~15 ~12 ~30 ~15 ~12 ~29 grass 0  
fill ~16 ~12 ~17 ~16 ~12 ~18 dirt 0  
fill ~16 ~12 ~26 ~19 ~12 ~26 dirt 1  
fill ~16 ~12 ~28 ~17 ~12 ~28 grass 0  
fill ~17 ~12 ~17 ~26 ~12 ~17 wool 7  
fill ~17 ~12 ~18 ~17 ~13 ~18 dirt 1  
fill ~18 ~12 ~18 ~35 ~12 ~18 wool 7  
fill ~18 ~12 ~30 ~18 ~18 ~30 wool 7  
fill ~18 ~12 ~31 ~18 ~18 ~31 wool 7  
fill ~19 ~12 ~15 ~19 ~12 ~18 wool 7  
fill ~19 ~12 ~32 ~26 ~12 ~32 wool 7  
fill ~20 ~12 ~13 ~20 ~20 ~13 stained_hardened_clay 7  
fill ~20 ~12 ~15 ~22 ~12 ~15 stained_hardened_clay 7  
fill ~20 ~12 ~16 ~25 ~12 ~16 wool 7  
fill ~20 ~12 ~26 ~22 ~12 ~26 wool 7  
fill ~20 ~12 ~34 ~23 ~12 ~34 dirt 1  
fill ~21 ~12 ~11 ~22 ~12 ~11 stained_hardened_clay 7  
fill ~21 ~12 ~12 ~22 ~12 ~12 stained_hardened_clay 7  
fill ~21 ~12 ~14 ~22 ~12 ~14 stained_hardened_clay 7  
fill ~21 ~12 ~25 ~23 ~12 ~25 wool 7  
fill ~21 ~12 ~28 ~29 ~12 ~28 stained_hardened_clay 7  
fill ~21 ~12 ~29 ~30 ~12 ~29 stained_hardened_clay 7  
fill ~22 ~12 ~10 ~22 ~23 ~10 stained_hardened_clay 7  
fill ~22 ~12 ~13 ~22 ~23 ~13 stained_hardened_clay 7  
fill ~22 ~12 ~19 ~35 ~12 ~19 wool 7  
fill ~22 ~12 ~24 ~24 ~12 ~24 wool 7  
fill ~22 ~12 ~27 ~28 ~12 ~27 stained_hardened_clay 7  
fill ~22 ~12 ~30 ~33 ~12 ~30 stained_hardened_clay 7  
fill ~22 ~12 ~33 ~27 ~12 ~33 wool 7  
fill ~22 ~12 ~36 ~24 ~12 ~36 dirt 1  
fill ~22 ~12 ~37 ~22 ~13 ~37 dirt 1  
fill ~22 ~12 ~38 ~24 ~12 ~38 dirt 1  
fill ~22 ~12 ~39 ~22 ~12 ~36 dirt 1  
fill ~22 ~12 ~40 ~35 ~12 ~40 wool 7  
fill ~22 ~12 ~41 ~47 ~12 ~41 wool 7  
fill ~22 ~12 ~42 ~46 ~12 ~42 wool 7  
fill ~23 ~12 ~10 ~25 ~12 ~10 wool 7 
setblock ~23 ~12 ~11 grass 0  
fill ~23 ~12 ~12 ~25 ~12 ~12 wool 7  
fill ~23 ~12 ~13 ~25 ~12 ~13 wool 7  
fill ~23 ~12 ~14 ~25 ~12 ~14 wool 7  
fill ~23 ~12 ~15 ~25 ~12 ~15 wool 7  
fill ~23 ~12 ~23 ~30 ~12 ~23 wool 7  
fill ~23 ~12 ~26 ~28 ~12 ~26 stained_hardened_clay 7  
fill ~23 ~12 ~31 ~23 ~17 ~31 wool 7  
fill ~23 ~12 ~35 ~23 ~13 ~35 dirt 1 
setblock ~23 ~12 ~37 dirt 0  
fill ~23 ~12 ~39 ~32 ~12 ~39 wool 7  
fill ~23 ~12 ~43 ~24 ~12 ~43 grass 0  
fill ~24 ~12 ~9 ~26 ~12 ~9 wool 7  
fill ~24 ~12 ~11 ~25 ~12 ~11 wool 7  
fill ~24 ~12 ~21 ~36 ~12 ~21 wool 7  
fill ~24 ~12 ~22 ~30 ~12 ~22 wool 7  
fill ~24 ~12 ~25 ~27 ~12 ~25 stained_hardened_clay 7  
fill ~24 ~12 ~31 ~34 ~12 ~31 stained_hardened_clay 7  
fill ~24 ~12 ~34 ~27 ~12 ~34 wool 7  
fill ~24 ~12 ~44 ~25 ~12 ~44 grass 0  
fill ~25 ~12 ~24 ~26 ~12 ~24 stained_hardened_clay 7  
fill ~25 ~12 ~35 ~27 ~12 ~35 wool 7  
fill ~25 ~12 ~43 ~46 ~12 ~43 wool 7  
fill ~26 ~12 ~10 ~33 ~12 ~10 dirt 1  
fill ~26 ~12 ~11 ~26 ~12 ~16 dirt 1  
fill ~26 ~12 ~20 ~35 ~12 ~20 wool 7  
fill ~26 ~12 ~44 ~29 ~12 ~44 stained_hardened_clay 7  
fill ~27 ~12 ~8 ~30 ~12 ~8 grass 0  
fill ~27 ~12 ~9 ~32 ~12 ~9 dirt 1  
fill ~27 ~12 ~11 ~29 ~12 ~11 dirt 0  
fill ~27 ~12 ~12 ~28 ~12 ~12 dirt 0  
fill ~27 ~12 ~13 ~27 ~13 ~13 dirt 1  
fill ~27 ~12 ~14 ~31 ~12 ~14 dirt 1  
fill ~27 ~12 ~15 ~31 ~12 ~15 dirt 1  
fill ~27 ~12 ~16 ~27 ~13 ~16 dirt 1  
fill ~27 ~12 ~17 ~27 ~12 ~13 dirt 1  
fill ~27 ~12 ~24 ~30 ~12 ~24 wool 7  
fill ~27 ~12 ~32 ~35 ~12 ~32 stained_hardened_clay 7 
setblock ~28 ~12 ~13 dirt 0  
fill ~28 ~12 ~33 ~35 ~12 ~33 stained_hardened_clay 7  
fill ~28 ~12 ~34 ~35 ~12 ~34 stained_hardened_clay 7  
fill ~28 ~12 ~35 ~35 ~12 ~35 stained_hardened_clay 7  
fill ~28 ~12 ~36 ~37 ~12 ~36 stained_hardened_clay 7  
fill ~29 ~12 ~6 ~32 ~12 ~6 grass 0  
fill ~29 ~12 ~7 ~31 ~12 ~7 grass 0  
fill ~29 ~12 ~12 ~33 ~12 ~12 dirt 1  
fill ~29 ~12 ~13 ~32 ~12 ~13 dirt 1  
fill ~29 ~12 ~27 ~37 ~12 ~27 wool 7  
fill ~29 ~12 ~37 ~41 ~12 ~37 stained_hardened_clay 7  
fill ~29 ~12 ~38 ~30 ~12 ~38 wool 7  
fill ~29 ~12 ~45 ~30 ~12 ~45 stained_hardened_clay 7  
fill ~30 ~12 ~4 ~33 ~12 ~4 grass 0  
fill ~30 ~12 ~5 ~33 ~12 ~5 grass 0  
fill ~30 ~12 ~11 ~34 ~12 ~11 dirt 1  
fill ~30 ~12 ~17 ~30 ~21 ~17 dirt 1  
fill ~30 ~12 ~28 ~37 ~12 ~28 wool 7  
fill ~30 ~12 ~44 ~35 ~12 ~44 wool 7  
fill ~30 ~12 ~46 ~31 ~12 ~46 stained_hardened_clay 7  
fill ~31 ~12 ~2 ~31 ~12 ~7 grass 0  
fill ~31 ~12 ~8 ~33 ~12 ~8 dirt 0  
fill ~31 ~12 ~16 ~34 ~12 ~16 wool 7  
fill ~31 ~12 ~17 ~35 ~12 ~17 wool 7  
fill ~31 ~12 ~22 ~31 ~15 ~22 dirt 1  
fill ~31 ~12 ~23 ~32 ~12 ~23 dirt 1  
fill ~31 ~12 ~24 ~33 ~12 ~24 dirt 1  
fill ~31 ~12 ~25 ~33 ~12 ~25 dirt 1  
fill ~31 ~12 ~26 ~31 ~18 ~26 wool 7  
fill ~31 ~12 ~29 ~37 ~12 ~29 wool 7  
fill ~31 ~12 ~38 ~42 ~12 ~38 stained_hardened_clay 7  
fill ~31 ~12 ~45 ~35 ~12 ~45 wool 7  
fill ~31 ~12 ~47 ~31 ~14 ~47 stained_hardened_clay 7  
fill ~32 ~12 ~2 ~33 ~12 ~2 stained_hardened_clay 7 
setblock ~32 ~12 ~3 grass 0  
fill ~32 ~12 ~7 ~33 ~12 ~7 dirt 0  
fill ~32 ~12 ~14 ~35 ~12 ~14 wool 7  
fill ~32 ~12 ~15 ~35 ~12 ~15 wool 7 
setblock ~32 ~12 ~22 wool 7  
fill ~32 ~12 ~26 ~33 ~12 ~26 dirt 1  
fill ~32 ~12 ~46 ~35 ~12 ~46 wool 7  
fill ~32 ~12 ~47 ~34 ~12 ~47 wool 7  
fill ~32 ~12 ~48 ~34 ~12 ~48 wool 7  
fill ~32 ~12 ~49 ~34 ~12 ~49 wool 7  
fill ~33 ~12 ~3 ~34 ~12 ~3 wool 7 
setblock ~33 ~12 ~6 dirt 0  
fill ~33 ~12 ~13 ~35 ~12 ~13 wool 7  
fill ~33 ~12 ~23 ~37 ~12 ~23 wool 7  
fill ~33 ~12 ~39 ~43 ~12 ~39 stained_hardened_clay 7  
fill ~33 ~12 ~54 ~37 ~12 ~54 dirt 1  
fill ~34 ~12 ~4 ~34 ~16 ~4 wool 7  
fill ~34 ~12 ~5 ~34 ~13 ~5 dirt 1  
fill ~34 ~12 ~6 ~34 ~14 ~6 dirt 1  
fill ~34 ~12 ~7 ~34 ~14 ~7 dirt 1  
fill ~34 ~12 ~12 ~36 ~12 ~12 wool 7  
fill ~34 ~12 ~24 ~37 ~12 ~24 wool 7  
fill ~34 ~12 ~25 ~34 ~18 ~25 wool 7  
fill ~34 ~12 ~26 ~34 ~18 ~26 wool 7 
setblock ~34 ~12 ~30 wool 7  
fill ~35 ~12 ~11 ~35 ~17 ~11 wool 7 
setblock ~35 ~12 ~16 stained_hardened_clay 7  
fill ~35 ~12 ~47 ~43 ~12 ~47 dirt 1  
fill ~35 ~12 ~48 ~42 ~12 ~48 dirt 1  
fill ~35 ~12 ~49 ~40 ~12 ~49 dirt 1  
fill ~35 ~12 ~50 ~37 ~12 ~50 dirt 1  
fill ~35 ~12 ~51 ~37 ~12 ~51 dirt 1  
fill ~36 ~12 ~13 ~43 ~12 ~13 stained_hardened_clay 7 
setblock ~36 ~12 ~15 stained_hardened_clay 7 
setblock ~36 ~12 ~17 stained_hardened_clay 7  
fill ~36 ~12 ~19 ~36 ~12 ~20 stained_hardened_clay 7  
fill ~36 ~12 ~22 ~36 ~20 ~22 wool 7  
fill ~36 ~12 ~34 ~58 ~12 ~34 wool 7  
fill ~36 ~12 ~35 ~58 ~12 ~35 wool 7  
fill ~36 ~12 ~40 ~42 ~12 ~40 stained_hardened_clay 7  
fill ~36 ~12 ~44 ~43 ~12 ~44 dirt 1  
fill ~36 ~12 ~45 ~44 ~12 ~45 dirt 1  
fill ~37 ~12 ~12 ~43 ~12 ~12 stained_hardened_clay 7  
fill ~37 ~12 ~21 ~38 ~12 ~21 stained_hardened_clay 7  
fill ~37 ~12 ~22 ~38 ~12 ~22 stained_hardened_clay 7  
fill ~37 ~12 ~52 ~37 ~17 ~52 dirt 1  
fill ~37 ~12 ~53 ~37 ~15 ~53 dirt 1  
fill ~37 ~12 ~55 ~37 ~14 ~55 dirt 1  
fill ~38 ~12 ~8 ~46 ~12 ~8 wool 7  
fill ~38 ~12 ~24 ~43 ~12 ~24 stained_hardened_clay 7  
fill ~38 ~12 ~26 ~46 ~12 ~26 stained_hardened_clay 7  
fill ~38 ~12 ~27 ~47 ~12 ~27 stained_hardened_clay 7  
fill ~38 ~12 ~28 ~47 ~12 ~28 stained_hardened_clay 7  
fill ~38 ~12 ~29 ~46 ~12 ~29 stained_hardened_clay 7  
fill ~38 ~12 ~36 ~58 ~12 ~36 wool 7  
fill ~38 ~12 ~50 ~43 ~12 ~50 wool 7  
fill ~38 ~12 ~51 ~42 ~12 ~51 wool 7  
fill ~38 ~12 ~52 ~40 ~12 ~52 wool 7  
fill ~38 ~12 ~53 ~38 ~12 ~54 wool 7  
fill ~39 ~12 ~7 ~39 ~13 ~7 wool 7  
fill ~39 ~12 ~10 ~43 ~12 ~10 stained_hardened_clay 7  
fill ~39 ~12 ~14 ~42 ~12 ~14 stained_hardened_clay 7  
fill ~39 ~12 ~15 ~41 ~12 ~15 stained_hardened_clay 7  
fill ~39 ~12 ~16 ~39 ~12 ~10 stained_hardened_clay 7  
fill ~39 ~12 ~17 ~43 ~12 ~17 wool 7  
fill ~39 ~12 ~18 ~41 ~12 ~18 wool 7  
fill ~39 ~12 ~19 ~41 ~12 ~19 wool 7  
fill ~39 ~12 ~20 ~41 ~12 ~20 wool 7  
fill ~39 ~12 ~21 ~42 ~12 ~21 wool 7  
fill ~39 ~12 ~22 ~44 ~12 ~22 wool 7  
fill ~39 ~12 ~31 ~39 ~15 ~31 wool 7  
fill ~39 ~12 ~33 ~53 ~12 ~33 wool 7  
fill ~40 ~12 ~11 ~43 ~12 ~11 stained_hardened_clay 7  
fill ~40 ~12 ~16 ~52 ~12 ~16 wool 7  
fill ~40 ~12 ~23 ~40 ~6 ~23 stained_hardened_clay 7  
fill ~40 ~12 ~32 ~51 ~12 ~32 wool 7  
fill ~41 ~12 ~7 ~41 ~15 ~7 wool 7  
fill ~41 ~12 ~23 ~50 ~12 ~23 wool 7  
fill ~41 ~12 ~25 ~45 ~12 ~25 stained_hardened_clay 7  
fill ~41 ~12 ~49 ~44 ~12 ~49 wool 7  
fill ~42 ~12 ~15 ~50 ~12 ~15 wool 7  
fill ~42 ~12 ~18 ~47 ~12 ~18 dirt 1  
fill ~42 ~12 ~19 ~48 ~12 ~19 dirt 1  
fill ~42 ~12 ~20 ~48 ~12 ~20 dirt 1  
fill ~42 ~12 ~30 ~46 ~12 ~30 stained_hardened_clay 7  
fill ~42 ~12 ~31 ~44 ~12 ~31 stained_hardened_clay 7  
fill ~42 ~12 ~37 ~58 ~12 ~37 wool 7  
fill ~42 ~12 ~46 ~43 ~12 ~46 dirt 1  
fill ~43 ~12 ~9 ~47 ~12 ~9 wool 7  
fill ~43 ~12 ~14 ~50 ~12 ~14 wool 7  
fill ~43 ~12 ~21 ~48 ~12 ~21 dirt 1  
fill ~43 ~12 ~38 ~57 ~12 ~38 wool 7  
fill ~43 ~12 ~40 ~48 ~12 ~40 wool 7  
fill ~43 ~12 ~48 ~45 ~12 ~48 wool 7  
fill ~44 ~12 ~10 ~47 ~12 ~10 wool 7  
fill ~44 ~12 ~11 ~48 ~12 ~11 wool 7  
fill ~44 ~12 ~12 ~48 ~12 ~12 wool 7  
fill ~44 ~12 ~13 ~49 ~12 ~13 wool 7  
fill ~44 ~12 ~17 ~46 ~12 ~17 dirt 1  
fill ~44 ~12 ~39 ~57 ~12 ~39 wool 7  
fill ~44 ~12 ~44 ~46 ~12 ~44 wool 7  
fill ~44 ~12 ~46 ~50 ~12 ~46 wool 7  
fill ~44 ~12 ~47 ~52 ~12 ~47 wool 7  
fill ~45 ~12 ~22 ~47 ~12 ~22 dirt 1  
fill ~45 ~12 ~24 ~50 ~12 ~24 wool 7  
fill ~45 ~12 ~31 ~51 ~12 ~31 wool 7  
fill ~45 ~12 ~49 ~45 ~17 ~49 stained_hardened_clay 7  
fill ~46 ~12 ~25 ~50 ~12 ~25 wool 7  
fill ~46 ~12 ~45 ~48 ~12 ~45 wool 7  
fill ~46 ~12 ~49 ~47 ~12 ~49 grass 0  
fill ~46 ~12 ~50 ~49 ~12 ~50 grass 0  
fill ~47 ~12 ~17 ~56 ~12 ~17 wool 7  
fill ~47 ~12 ~26 ~50 ~12 ~26 wool 7  
fill ~47 ~12 ~29 ~55 ~12 ~29 wool 7  
fill ~47 ~12 ~30 ~51 ~12 ~30 wool 7  
fill ~47 ~12 ~42 ~57 ~12 ~42 dirt 1  
fill ~47 ~12 ~44 ~57 ~12 ~44 dirt 1  
fill ~47 ~12 ~48 ~49 ~12 ~48 stained_hardened_clay 7  
fill ~48 ~12 ~9 ~48 ~19 ~9 stained_hardened_clay 7  
fill ~48 ~12 ~10 ~48 ~20 ~10 stained_hardened_clay 7  
fill ~48 ~12 ~18 ~56 ~12 ~18 wool 7  
fill ~48 ~12 ~22 ~51 ~12 ~22 wool 7  
fill ~48 ~12 ~27 ~48 ~23 ~27 wool 7  
fill ~48 ~12 ~41 ~55 ~12 ~41 dirt 1  
fill ~48 ~12 ~49 ~50 ~12 ~49 stained_hardened_clay 7  
fill ~48 ~12 ~51 ~49 ~12 ~51 grass 0  
fill ~49 ~12 ~11 ~49 ~17 ~11 stained_hardened_clay 7  
fill ~49 ~12 ~12 ~49 ~12 ~11 stained_hardened_clay 7  
fill ~49 ~12 ~19 ~56 ~12 ~19 wool 7  
fill ~49 ~12 ~20 ~57 ~12 ~20 wool 7  
fill ~49 ~12 ~21 ~58 ~12 ~21 wool 7  
fill ~49 ~12 ~40 ~55 ~12 ~40 dirt 1  
fill ~49 ~12 ~43 ~57 ~12 ~43 dirt 1  
fill ~49 ~12 ~45 ~58 ~12 ~45 dirt 1  
fill ~50 ~12 ~13 ~54 ~12 ~13 stained_hardened_clay 7  
fill ~50 ~12 ~27 ~54 ~12 ~27 wool 7  
fill ~50 ~12 ~28 ~54 ~12 ~28 wool 7  
fill ~50 ~12 ~48 ~54 ~12 ~48 wool 7  
fill ~50 ~12 ~50 ~54 ~12 ~50 wool 7  
fill ~50 ~12 ~51 ~53 ~12 ~51 wool 7  
fill ~51 ~12 ~14 ~56 ~12 ~14 stained_hardened_clay 7  
fill ~51 ~12 ~15 ~55 ~12 ~15 stained_hardened_clay 7  
fill ~51 ~12 ~23 ~56 ~12 ~23 stained_hardened_clay 7  
fill ~51 ~12 ~24 ~55 ~12 ~24 stained_hardened_clay 7  
fill ~51 ~12 ~26 ~54 ~12 ~26 stained_hardened_clay 7  
fill ~51 ~12 ~46 ~59 ~12 ~46 dirt 1  
fill ~51 ~12 ~49 ~54 ~12 ~49 wool 7  
fill ~52 ~12 ~22 ~56 ~12 ~22 stained_hardened_clay 7  
fill ~52 ~12 ~30 ~54 ~12 ~30 dirt 1  
fill ~52 ~12 ~31 ~54 ~12 ~31 dirt 1  
fill ~52 ~12 ~32 ~56 ~12 ~32 dirt 1  
fill ~53 ~12 ~16 ~53 ~18 ~16 stained_hardened_clay 7 
setblock ~53 ~12 ~47 dirt 1  
fill ~54 ~12 ~33 ~56 ~12 ~33 dirt 1  
fill ~55 ~12 ~16 ~57 ~12 ~16 wool 7  
fill ~55 ~12 ~25 ~55 ~13 ~25 stained_hardened_clay 7  
fill ~55 ~12 ~30 ~58 ~12 ~30 dirt 0  
fill ~55 ~12 ~31 ~58 ~12 ~31 dirt 0  
fill ~55 ~12 ~47 ~60 ~12 ~47 dirt 1  
fill ~55 ~12 ~48 ~60 ~12 ~48 dirt 1  
fill ~55 ~12 ~49 ~56 ~12 ~49 dirt 1  
fill ~56 ~12 ~15 ~57 ~12 ~15 wool 7 
setblock ~56 ~12 ~40 wool 7  
fill ~57 ~12 ~17 ~59 ~12 ~17 dirt 1  
fill ~57 ~12 ~18 ~59 ~12 ~18 dirt 1  
fill ~57 ~12 ~19 ~59 ~12 ~19 dirt 1  
fill ~57 ~12 ~22 ~57 ~21 ~22 wool 7  
fill ~57 ~12 ~32 ~58 ~12 ~32 dirt 0 
setblock ~57 ~12 ~33 wool 7  
fill ~58 ~12 ~20 ~58 ~15 ~20 dirt 1  
fill ~58 ~12 ~33 ~59 ~12 ~33 grass 0  
fill ~58 ~12 ~43 ~59 ~12 ~43 wool 7  
fill ~58 ~12 ~44 ~60 ~12 ~44 wool 7  
fill ~59 ~12 ~30 ~59 ~12 ~33 grass 0 
setblock ~60 ~12 ~46 wool 7  
fill ~62 ~12 ~46 ~62 ~12 ~47 wool 7  
fill ~10 ~13 ~26 ~18 ~13 ~26 dirt 1  
fill ~10 ~13 ~27 ~21 ~13 ~27 wool 7  
fill ~10 ~13 ~28 ~21 ~13 ~28 wool 7  
fill ~10 ~13 ~29 ~20 ~13 ~29 wool 7  
fill ~10 ~13 ~30 ~12 ~13 ~30 stained_hardened_clay 7  
fill ~11 ~13 ~24 ~11 ~24 ~24 dirt 1  
fill ~11 ~13 ~25 ~20 ~13 ~25 dirt 1  
fill ~11 ~13 ~31 ~13 ~13 ~31 stained_hardened_clay 7  
fill ~12 ~13 ~18 ~13 ~13 ~18 dirt 0  
fill ~12 ~13 ~19 ~13 ~13 ~19 dirt 0  
fill ~12 ~13 ~20 ~22 ~13 ~20 dirt 1  
fill ~12 ~13 ~21 ~22 ~13 ~21 dirt 1  
fill ~12 ~13 ~22 ~22 ~13 ~22 dirt 1  
fill ~12 ~13 ~23 ~22 ~13 ~23 dirt 1  
fill ~13 ~13 ~17 ~15 ~13 ~17 dirt 0  
fill ~13 ~13 ~24 ~21 ~13 ~24 dirt 1  
fill ~13 ~13 ~30 ~15 ~13 ~30 wool 7  
fill ~14 ~13 ~16 ~15 ~13 ~16 dirt 0  
fill ~14 ~13 ~18 ~14 ~16 ~18 dirt 1  
fill ~14 ~13 ~19 ~19 ~13 ~19 dirt 1  
fill ~14 ~13 ~31 ~15 ~13 ~31 wool 7  
fill ~16 ~13 ~16 ~16 ~13 ~26 dirt 1  
fill ~16 ~13 ~30 ~17 ~13 ~30 grass 0  
fill ~16 ~13 ~31 ~17 ~13 ~31 grass 0  
fill ~17 ~13 ~16 ~19 ~13 ~16 wool 7  
fill ~17 ~13 ~17 ~27 ~13 ~17 wool 7  
fill ~17 ~13 ~32 ~27 ~13 ~32 wool 7  
fill ~18 ~13 ~18 ~28 ~13 ~18 wool 7  
fill ~19 ~13 ~14 ~19 ~18 ~14 stained_hardened_clay 7  
fill ~19 ~13 ~15 ~23 ~13 ~15 stained_hardened_clay 7  
fill ~19 ~13 ~26 ~22 ~13 ~26 wool 7  
fill ~19 ~13 ~33 ~27 ~13 ~33 wool 7  
fill ~20 ~13 ~11 ~23 ~13 ~11 stained_hardened_clay 7  
fill ~20 ~13 ~12 ~23 ~13 ~12 stained_hardened_clay 7  
fill ~20 ~13 ~16 ~22 ~13 ~16 stained_hardened_clay 7  
fill ~20 ~13 ~19 ~28 ~13 ~19 wool 7  
fill ~20 ~13 ~34 ~22 ~13 ~34 dirt 1  
fill ~20 ~13 ~40 ~34 ~13 ~40 wool 7  
fill ~21 ~13 ~10 ~21 ~22 ~10 stained_hardened_clay 7  
fill ~21 ~13 ~14 ~23 ~13 ~14 stained_hardened_clay 7  
fill ~21 ~13 ~25 ~23 ~13 ~25 wool 7  
fill ~21 ~13 ~29 ~33 ~13 ~29 stained_hardened_clay 7  
fill ~21 ~13 ~35 ~23 ~13 ~35 dirt 1  
fill ~21 ~13 ~36 ~23 ~13 ~36 dirt 1  
fill ~21 ~13 ~37 ~21 ~13 ~38 dirt 1  
fill ~21 ~13 ~39 ~22 ~13 ~39 wool 7  
fill ~21 ~13 ~41 ~35 ~13 ~41 wool 7  
fill ~21 ~13 ~42 ~46 ~13 ~42 wool 7  
fill ~21 ~13 ~43 ~46 ~13 ~43 wool 7  
fill ~22 ~13 ~9 ~23 ~13 ~9 stained_hardened_clay 7  
fill ~22 ~13 ~24 ~25 ~13 ~24 wool 7  
fill ~22 ~13 ~27 ~28 ~13 ~27 stained_hardened_clay 7  
fill ~22 ~13 ~28 ~29 ~13 ~28 stained_hardened_clay 7  
fill ~22 ~13 ~30 ~35 ~13 ~30 stained_hardened_clay 7  
fill ~22 ~13 ~38 ~23 ~13 ~38 dirt 1  
fill ~22 ~13 ~44 ~22 ~26 ~44 wool 7  
fill ~22 ~13 ~45 ~22 ~25 ~45 wool 7  
fill ~23 ~13 ~8 ~24 ~13 ~8 wool 7  
fill ~23 ~13 ~10 ~23 ~24 ~10 stained_hardened_clay 7  
fill ~23 ~13 ~13 ~23 ~24 ~13 stained_hardened_clay 7  
fill ~23 ~13 ~16 ~26 ~13 ~16 wool 7  
fill ~23 ~13 ~20 ~23 ~16 ~20 wool 7  
fill ~23 ~13 ~21 ~30 ~13 ~21 wool 7  
fill ~23 ~13 ~22 ~30 ~13 ~22 wool 7  
fill ~23 ~13 ~23 ~30 ~13 ~23 wool 7  
fill ~23 ~13 ~26 ~28 ~13 ~26 stained_hardened_clay 7  
fill ~23 ~13 ~34 ~27 ~13 ~34 wool 7 
setblock ~23 ~13 ~37 dirt 1  
fill ~23 ~13 ~39 ~24 ~13 ~39 dirt 1  
fill ~23 ~13 ~44 ~23 ~13 ~45 grass 0  
fill ~23 ~13 ~46 ~25 ~13 ~46 stained_hardened_clay 7  
fill ~24 ~13 ~9 ~27 ~13 ~9 wool 7  
fill ~24 ~13 ~10 ~26 ~13 ~10 wool 7  
fill ~24 ~13 ~11 ~26 ~13 ~11 wool 7  
fill ~24 ~13 ~12 ~26 ~13 ~12 wool 7  
fill ~24 ~13 ~13 ~26 ~13 ~13 wool 7  
fill ~24 ~13 ~14 ~26 ~13 ~14 wool 7  
fill ~24 ~13 ~15 ~26 ~13 ~15 wool 7  
fill ~24 ~13 ~25 ~27 ~13 ~25 stained_hardened_clay 7  
fill ~24 ~13 ~31 ~26 ~13 ~31 wool 7  
fill ~24 ~13 ~35 ~27 ~13 ~35 wool 7  
fill ~24 ~13 ~36 ~24 ~27 ~36 wool 7  
fill ~24 ~13 ~37 ~24 ~27 ~37 wool 7  
fill ~24 ~13 ~38 ~24 ~27 ~38 wool 7  
fill ~24 ~13 ~44 ~47 ~13 ~44 wool 7  
fill ~24 ~13 ~45 ~25 ~13 ~45 grass 0  
fill ~25 ~13 ~7 ~28 ~13 ~7 grass 0  
fill ~25 ~13 ~8 ~26 ~13 ~8 grass 0  
fill ~25 ~13 ~39 ~33 ~13 ~39 wool 7  
fill ~26 ~13 ~20 ~29 ~13 ~20 wool 7 
setblock ~26 ~13 ~24 stained_hardened_clay 7  
fill ~26 ~13 ~45 ~30 ~13 ~45 stained_hardened_clay 7  
fill ~27 ~13 ~6 ~28 ~13 ~6 grass 0  
fill ~27 ~13 ~8 ~30 ~13 ~8 wool 7  
fill ~27 ~13 ~10 ~35 ~13 ~10 dirt 1  
fill ~27 ~13 ~11 ~33 ~13 ~11 dirt 1  
fill ~27 ~13 ~12 ~32 ~13 ~12 dirt 1  
fill ~27 ~13 ~14 ~31 ~13 ~14 dirt 1  
fill ~27 ~13 ~15 ~31 ~13 ~15 dirt 1  
fill ~27 ~13 ~24 ~37 ~13 ~24 wool 7  
fill ~27 ~13 ~31 ~35 ~13 ~31 stained_hardened_clay 7  
fill ~28 ~13 ~5 ~29 ~13 ~5 grass 0  
fill ~28 ~13 ~9 ~34 ~13 ~9 dirt 1  
fill ~28 ~13 ~13 ~32 ~13 ~13 dirt 1  
fill ~28 ~13 ~32 ~35 ~13 ~32 stained_hardened_clay 7  
fill ~28 ~13 ~33 ~35 ~13 ~33 stained_hardened_clay 7  
fill ~28 ~13 ~34 ~35 ~13 ~34 stained_hardened_clay 7  
fill ~28 ~13 ~35 ~35 ~13 ~35 stained_hardened_clay 7  
fill ~28 ~13 ~36 ~28 ~17 ~36 wool 7  
fill ~29 ~13 ~3 ~29 ~16 ~3 stained_hardened_clay 7  
fill ~29 ~13 ~4 ~32 ~13 ~4 stained_hardened_clay 7  
fill ~29 ~13 ~6 ~32 ~13 ~6 wool 7  
fill ~29 ~13 ~7 ~31 ~13 ~7 wool 7  
fill ~29 ~13 ~18 ~31 ~13 ~18 dirt 1  
fill ~29 ~13 ~19 ~31 ~13 ~19 dirt 1  
fill ~29 ~13 ~27 ~37 ~13 ~27 wool 7  
fill ~29 ~13 ~36 ~36 ~13 ~36 stained_hardened_clay 7  
fill ~29 ~13 ~37 ~29 ~19 ~37 wool 7  
fill ~29 ~13 ~38 ~31 ~13 ~38 wool 7  
fill ~30 ~13 ~2 ~33 ~13 ~2 stained_hardened_clay 7 
setblock ~30 ~13 ~3 grass 0  
fill ~30 ~13 ~5 ~30 ~19 ~5 stained_hardened_clay 7  
fill ~30 ~13 ~20 ~31 ~13 ~20 dirt 1  
fill ~30 ~13 ~28 ~37 ~13 ~28 wool 7  
fill ~30 ~13 ~37 ~41 ~13 ~37 stained_hardened_clay 7  
fill ~30 ~13 ~46 ~31 ~13 ~46 stained_hardened_clay 7  
fill ~31 ~13 ~1 ~32 ~13 ~1 stained_hardened_clay 7  
fill ~31 ~13 ~3 ~33 ~13 ~3 stained_hardened_clay 7  
fill ~31 ~13 ~5 ~33 ~13 ~5 wool 7  
fill ~31 ~13 ~8 ~34 ~13 ~8 dirt 1  
fill ~31 ~13 ~16 ~31 ~21 ~16 dirt 1  
fill ~31 ~13 ~17 ~31 ~21 ~17 dirt 1  
fill ~31 ~13 ~21 ~31 ~17 ~21 dirt 1  
fill ~31 ~13 ~23 ~32 ~13 ~23 dirt 1  
fill ~31 ~13 ~25 ~37 ~13 ~25 wool 7  
fill ~31 ~13 ~45 ~36 ~13 ~45 wool 7  
fill ~31 ~13 ~48 ~31 ~15 ~48 stained_hardened_clay 7  
fill ~31 ~13 ~49 ~31 ~14 ~49 stained_hardened_clay 7  
fill ~32 ~13 ~7 ~34 ~13 ~7 dirt 1  
fill ~32 ~13 ~14 ~35 ~13 ~14 wool 7  
fill ~32 ~13 ~15 ~36 ~13 ~15 wool 7  
fill ~32 ~13 ~16 ~36 ~13 ~16 wool 7  
fill ~32 ~13 ~17 ~41 ~13 ~17 wool 7  
fill ~32 ~13 ~18 ~40 ~13 ~18 wool 7  
fill ~32 ~13 ~19 ~40 ~13 ~19 wool 7  
fill ~32 ~13 ~20 ~40 ~13 ~20 wool 7  
fill ~32 ~13 ~21 ~41 ~13 ~21 wool 7  
fill ~32 ~13 ~22 ~32 ~15 ~22 dirt 1  
fill ~32 ~13 ~26 ~37 ~13 ~26 wool 7  
fill ~32 ~13 ~38 ~43 ~13 ~38 stained_hardened_clay 7  
fill ~32 ~13 ~46 ~35 ~13 ~46 wool 7  
fill ~32 ~13 ~47 ~35 ~13 ~47 wool 7  
fill ~32 ~13 ~48 ~35 ~13 ~48 wool 7  
fill ~32 ~13 ~49 ~34 ~13 ~49 wool 7  
fill ~32 ~13 ~50 ~32 ~21 ~50 wool 7  
fill ~33 ~13 ~4 ~33 ~14 ~4 wool 7 
setblock ~33 ~13 ~6 dirt 1  
fill ~33 ~13 ~12 ~36 ~13 ~12 wool 7  
fill ~33 ~13 ~13 ~36 ~13 ~13 wool 7  
fill ~33 ~13 ~23 ~51 ~13 ~23 wool 7  
fill ~33 ~13 ~51 ~33 ~18 ~51 dirt 1  
fill ~33 ~13 ~54 ~38 ~13 ~54 dirt 1  
fill ~34 ~13 ~3 ~34 ~14 ~3 wool 7  
fill ~34 ~13 ~11 ~34 ~17 ~11 wool 7  
fill ~34 ~13 ~29 ~37 ~13 ~29 wool 7  
fill ~34 ~13 ~39 ~43 ~13 ~39 stained_hardened_clay 7  
fill ~35 ~13 ~40 ~43 ~13 ~40 stained_hardened_clay 7  
fill ~35 ~13 ~49 ~40 ~13 ~49 dirt 1  
fill ~35 ~13 ~50 ~38 ~13 ~50 dirt 1  
fill ~35 ~13 ~51 ~37 ~13 ~51 dirt 1  
fill ~35 ~13 ~56 ~35 ~15 ~56 dirt 1  
fill ~36 ~13 ~34 ~59 ~13 ~34 wool 7  
fill ~36 ~13 ~35 ~59 ~13 ~35 wool 7  
fill ~36 ~13 ~41 ~43 ~13 ~41 stained_hardened_clay 7  
fill ~36 ~13 ~47 ~42 ~13 ~47 dirt 1  
fill ~36 ~13 ~48 ~41 ~13 ~48 dirt 1  
fill ~37 ~13 ~12 ~43 ~13 ~12 stained_hardened_clay 7  
fill ~37 ~13 ~13 ~42 ~13 ~13 stained_hardened_clay 7  
fill ~37 ~13 ~22 ~42 ~13 ~22 wool 7  
fill ~37 ~13 ~36 ~59 ~13 ~36 wool 7  
fill ~37 ~13 ~45 ~42 ~13 ~45 dirt 1  
fill ~38 ~13 ~8 ~47 ~13 ~8 wool 7  
fill ~38 ~13 ~24 ~42 ~13 ~24 stained_hardened_clay 7  
fill ~38 ~13 ~26 ~46 ~13 ~26 stained_hardened_clay 7  
fill ~38 ~13 ~27 ~47 ~13 ~27 stained_hardened_clay 7   
fill ~38 ~13 ~28 ~46 ~13 ~28 stained_hardened_clay 7  
fill ~38 ~13 ~29 ~46 ~13 ~29 stained_hardened_clay 7  
fill ~38 ~13 ~30 ~38 ~21 ~30 wool 7  
fill ~38 ~13 ~51 ~42 ~13 ~51 wool 7  
fill ~38 ~13 ~52 ~38 ~16 ~52 dirt 1  
fill ~38 ~13 ~53 ~38 ~14 ~53 dirt 1  
fill ~39 ~13 ~10 ~43 ~13 ~10 stained_hardened_clay 7  
fill ~39 ~13 ~14 ~41 ~13 ~14 stained_hardened_clay 7  
fill ~39 ~13 ~15 ~40 ~13 ~15 stained_hardened_clay 7  
fill ~39 ~13 ~16 ~43 ~13 ~16 wool 7  
fill ~39 ~13 ~33 ~51 ~13 ~33 wool 7  
fill ~39 ~13 ~50 ~43 ~13 ~50 wool 7  
fill ~39 ~13 ~52 ~40 ~13 ~52 wool 7  
fill ~40 ~13 ~9 ~40 ~17 ~9 wool 7  
fill ~40 ~13 ~11 ~43 ~13 ~11 stained_hardened_clay 7  
fill ~40 ~13 ~31 ~49 ~13 ~31 wool 7  
fill ~40 ~13 ~32 ~50 ~13 ~32 wool 7  
fill ~41 ~13 ~15 ~50 ~13 ~15 wool 7  
fill ~41 ~13 ~18 ~48 ~13 ~18 dirt 1  
fill ~41 ~13 ~19 ~49 ~13 ~19 dirt 1  
fill ~41 ~13 ~20 ~49 ~13 ~20 dirt 1  
fill ~41 ~13 ~25 ~45 ~13 ~25 stained_hardened_clay 7  
fill ~41 ~13 ~49 ~44 ~13 ~49 wool 7  
fill ~42 ~13 ~7 ~45 ~13 ~7 wool 7  
fill ~42 ~13 ~14 ~49 ~13 ~14 wool 7  
fill ~42 ~13 ~17 ~47 ~13 ~17 dirt 1  
fill ~42 ~13 ~21 ~48 ~13 ~21 dirt 1  
fill ~42 ~13 ~30 ~45 ~13 ~30 stained_hardened_clay 7  
fill ~42 ~13 ~37 ~58 ~13 ~37 wool 7  
fill ~42 ~13 ~46 ~42 ~10 ~46 dirt 1  
fill ~42 ~13 ~48 ~45 ~13 ~48 wool 7  
fill ~43 ~13 ~9 ~47 ~13 ~9 wool 7  
fill ~43 ~13 ~13 ~49 ~13 ~13 wool 7  
fill ~43 ~13 ~22 ~47 ~13 ~22 dirt 1  
fill ~43 ~13 ~24 ~43 ~23 ~24 wool 7  
fill ~43 ~13 ~45 ~48 ~13 ~45 wool 7  
fill ~43 ~13 ~46 ~50 ~13 ~46 wool 7  
fill ~43 ~13 ~47 ~46 ~13 ~47 wool 7  
fill ~44 ~13 ~10 ~47 ~13 ~10 wool 7  
fill ~44 ~13 ~11 ~48 ~13 ~11 wool 7  
fill ~44 ~13 ~12 ~49 ~13 ~12 wool 7  
fill ~44 ~13 ~16 ~45 ~13 ~16 dirt 1  
fill ~44 ~13 ~38 ~58 ~13 ~38 wool 7  
fill ~44 ~13 ~39 ~49 ~13 ~39 wool 7  
fill ~44 ~13 ~40 ~48 ~13 ~40 wool 7  
fill ~44 ~13 ~41 ~47 ~13 ~41 wool 7  
fill ~45 ~13 ~24 ~50 ~13 ~24 wool 7  
fill ~45 ~13 ~50 ~50 ~13 ~50 stained_hardened_clay 7  
fill ~46 ~13 ~16 ~51 ~13 ~16 wool 7  
fill ~46 ~13 ~25 ~51 ~13 ~25 wool 7  
fill ~46 ~13 ~30 ~50 ~13 ~30 wool 7  
fill ~46 ~13 ~49 ~50 ~13 ~49 stained_hardened_clay 7  
fill ~46 ~13 ~51 ~46 ~17 ~51 stained_hardened_clay 7  
fill ~47 ~13 ~26 ~54 ~13 ~26 wool 7  
fill ~47 ~13 ~28 ~47 ~23 ~28 wool 7  
fill ~47 ~13 ~29 ~50 ~13 ~29 wool 7  
fill ~47 ~13 ~42 ~57 ~13 ~42 dirt 1  
fill ~47 ~13 ~47 ~47 ~21 ~47 stained_hardened_clay 7  
fill ~47 ~13 ~48 ~49 ~13 ~48 stained_hardened_clay 7 
setblock ~47 ~13 ~51 grass 0  
fill ~47 ~13 ~52 ~48 ~13 ~52 stained_hardened_clay 7  
fill ~48 ~13 ~8 ~48 ~15 ~8 stained_hardened_clay 7  
fill ~48 ~13 ~17 ~56 ~13 ~17 wool 7  
fill ~48 ~13 ~22 ~51 ~13 ~22 wool 7  
fill ~48 ~13 ~41 ~56 ~13 ~41 dirt 1  
fill ~48 ~13 ~44 ~57 ~13 ~44 dirt 1  
fill ~48 ~13 ~47 ~53 ~13 ~47 wool 7  
fill ~48 ~13 ~51 ~49 ~13 ~51 stained_hardened_clay 7  
fill ~49 ~13 ~10 ~49 ~15 ~10 stained_hardened_clay 7  
fill ~49 ~13 ~18 ~56 ~13 ~18 wool 7  
fill ~49 ~13 ~21 ~57 ~13 ~21 wool 7  
fill ~49 ~13 ~40 ~56 ~13 ~40 dirt 1  
fill ~49 ~13 ~43 ~57 ~13 ~43 dirt 1  
fill ~49 ~13 ~45 ~57 ~13 ~45 dirt 1  
fill ~49 ~13 ~52 ~53 ~13 ~52 wool 7  
fill ~50 ~13 ~12 ~51 ~13 ~12 stained_hardened_clay 7  
fill ~50 ~13 ~13 ~54 ~13 ~13 stained_hardened_clay 7  
fill ~50 ~13 ~14 ~56 ~13 ~14 stained_hardened_clay 7  
fill ~50 ~13 ~19 ~55 ~13 ~19 wool 7  
fill ~50 ~13 ~20 ~56 ~13 ~20 wool 7  
fill ~50 ~13 ~27 ~55 ~13 ~27 wool 7  
fill ~50 ~13 ~28 ~55 ~13 ~28 wool 7  
fill ~50 ~13 ~31 ~58 ~13 ~31 dirt 1  
fill ~50 ~13 ~39 ~54 ~13 ~39 dirt 1  
fill ~50 ~13 ~48 ~54 ~13 ~48 wool 7  
fill ~50 ~13 ~51 ~54 ~13 ~51 wool 7  
fill ~51 ~13 ~15 ~55 ~13 ~15 stained_hardened_clay 7  
fill ~51 ~13 ~24 ~56 ~13 ~24 stained_hardened_clay 7  
fill ~51 ~13 ~29 ~55 ~13 ~29 dirt 1  
fill ~51 ~13 ~30 ~58 ~13 ~30 dirt 1  
fill ~51 ~13 ~32 ~58 ~13 ~32 dirt 1  
fill ~51 ~13 ~46 ~60 ~13 ~46 dirt 1  
fill ~51 ~13 ~49 ~54 ~13 ~49 wool 7  
fill ~51 ~13 ~50 ~54 ~13 ~50 wool 7  
fill ~52 ~13 ~16 ~52 ~19 ~16 stained_hardened_clay 7  
fill ~52 ~13 ~22 ~55 ~13 ~22 stained_hardened_clay 7  
fill ~52 ~13 ~23 ~56 ~13 ~23 stained_hardened_clay 7  
fill ~52 ~13 ~33 ~57 ~13 ~33 dirt 1  
fill ~54 ~13 ~16 ~54 ~17 ~16 stained_hardened_clay 7  
fill ~55 ~13 ~16 ~57 ~13 ~16 wool 7  
fill ~55 ~13 ~39 ~57 ~13 ~39 wool 7  
fill ~55 ~13 ~47 ~61 ~13 ~47 dirt 1  
fill ~55 ~13 ~48 ~59 ~13 ~48 dirt 1  
fill ~55 ~13 ~49 ~57 ~13 ~49 dirt 1  
fill ~55 ~13 ~50 ~55 ~16 ~50 dirt 1  
fill ~56 ~13 ~15 ~57 ~13 ~15 wool 7  
fill ~56 ~13 ~19 ~58 ~13 ~19 dirt 1  
fill ~56 ~13 ~22 ~56 ~19 ~22 wool 7  
fill ~56 ~13 ~28 ~57 ~13 ~28 dirt 0  
fill ~56 ~13 ~29 ~58 ~13 ~29 dirt 0  
fill ~57 ~13 ~17 ~58 ~13 ~17 dirt 1  
fill ~57 ~13 ~18 ~58 ~13 ~18 dirt 1  
fill ~57 ~13 ~20 ~57 ~18 ~20 dirt 1  
fill ~57 ~13 ~40 ~57 ~24 ~40 wool 7  
