fill ~1~0~1 ~74~0~7 minecraft:smooth_stone
fill ~1~1~1 ~75~2~1 minecraft:concrete 8
fill ~1~3~1 ~75~17~0 minecraft:concrete 8
fill ~1~3~1 ~42~20~1 minecraft:concrete 8
fill ~43~3~1 ~44~3~1 minecraft:concrete 13
fill ~43~4~1 ~44~17~1 minecraft:sandstone 3
fill ~43~18~1 ~75~20~1 minecraft:concrete 8
fill ~45~3~1 ~45~6~1 minecraft:stonebrick 0
fill ~45~7~1 ~45~8~14 minecraft:sandstone 3
fill ~45~9~1 ~45~17~1 minecraft:sandstone 3
fill ~46~3~1 ~55~12~1 minecraft:stone 0
fill ~46~13~1 ~75~13~1 minecraft:concrete 8
fill ~46~14~1 ~55~17~1 minecraft:sandstone 3
fill ~56~3~1 ~75~6~1 minecraft:concrete 8
fill ~56~7~1 ~56~10~1 minecraft:stonebrick 0
fill ~56~11~1 ~75~12~1 minecraft:concrete 8
fill ~56~14~1 ~75~17~1 minecraft:concrete 8
fill ~57~7~1 ~75~10~1 minecraft:concrete 8
fill ~75~0~1 ~75~0~96 minecraft:smooth_stone
fill ~1~1~2 ~30~17~6 minecraft:concrete 8
fill ~1~20~2 ~66~20~2 minecraft:concrete 8
fill ~1~21~2 ~3~22~2 minecraft:concrete 8
fill ~4~21~2 ~9~22~2 minecraft:stained_glass 8
fill ~10~21~2 ~12~22~2 minecraft:concrete 8
fill ~13~21~2 ~18~22~2 minecraft:stained_glass 8
fill ~19~21~2 ~21~22~2 minecraft:concrete 8
fill ~22~21~2 ~27~22~2 minecraft:stained_glass 8
fill ~28~21~2 ~30~22~2 minecraft:concrete 8
fill ~31~1~2 ~40~2~3 minecraft:smooth_stone
fill ~31~3~2 ~40~16~3 minecraft:concrete 8
fill ~31~17~2 ~40~17~2 minecraft:concrete 8
fill ~31~21~2 ~36~22~2 minecraft:stained_glass 8
fill ~37~21~2 ~39~22~2 minecraft:concrete 8
fill ~40~21~2 ~45~22~2 minecraft:stained_glass 8
fill ~41~17~2 ~42~17~2 minecraft:sandstone 3
fill ~41~18~2 ~41~19~2 minecraft:concrete 8
fill ~42~2~2 ~48~2~14 minecraft:smooth_stone
setblock ~42~3~2 minecraft:concrete 13
fill ~42~4~2 ~42~13~2 minecraft:sandstone 3
setblock ~42~14~2 minecraft:concrete 4
fill ~42~15~2 ~42~16~2 minecraft:sandstone 3
fill ~43~1~2 ~48~1~10 minecraft:smooth_stone
fill ~43~13~2 ~56~13~7 minecraft:sandstone 3
fill ~45~9~2 ~45~9~14 minecraft:concrete 13
fill ~45~10~2 ~45~12~14 minecraft:sandstone 3
fill ~45~14~2 ~45~17~2 minecraft:sandstone 3
fill ~45~18~2 ~45~18~14 minecraft:concrete 4
fill ~45~19~2 ~45~19~14 minecraft:sandstone 3
fill ~46~18~2 ~55~18~14 minecraft:concrete 8
fill ~46~19~2 ~55~19~2 minecraft:concrete 8
fill ~46~21~2 ~48~22~2 minecraft:concrete 8
fill ~49~1~2 ~75~1~5 minecraft:concrete 8
fill ~49~2~2 ~49~2~5 minecraft:stone_block_slab 8
fill ~49~3~2 ~49~3~4 minecraft:stone_block_slab 0
fill ~49~21~2 ~54~22~2 minecraft:stained_glass 8
fill ~50~2~2 ~74~2~10 minecraft:smooth_stone
fill ~50~3~2 ~50~3~4 minecraft:smooth_stone
fill ~51~3~2 ~51~4~4 minecraft:stone_block_slab 0
fill ~52~4~2 ~52~4~4 minecraft:smooth_stone
fill ~53~4~2 ~53~5~4 minecraft:stone_block_slab 0
fill ~54~5~2 ~54~5~4 minecraft:smooth_stone
fill ~55~5~2 ~55~6~4 minecraft:stone_block_slab 0
fill ~55~21~2 ~57~22~2 minecraft:concrete 8
fill ~56~6~2 ~67~6~4 minecraft:smooth_stone
fill ~56~11~2 ~56~12~14 minecraft:sandstone 3
fill ~56~14~2 ~56~17~5 minecraft:sandstone 3
fill ~56~18~2 ~56~18~14 minecraft:concrete 4
fill ~56~19~2 ~56~19~14 minecraft:sandstone 3
fill ~57~7~2 ~60~7~20 minecraft:carpet 7
fill ~58~21~2 ~63~22~2 minecraft:stained_glass 8
fill ~61~7~2 ~67~11~2 minecraft:concrete 8
fill ~61~12~2 ~61~18~2 minecraft:concrete 8
fill ~62~15~2 ~75~17~6 minecraft:concrete 8
fill ~64~21~2 ~66~22~2 minecraft:concrete 8
fill ~67~20~2 ~72~22~2 minecraft:stained_glass 8
fill ~72~5~2 ~74~5~40 minecraft:smooth_stone
fill ~73~20~2 ~75~22~2 minecraft:concrete 8
fill ~75~2~2 ~75~14~96 minecraft:concrete 8
fill ~75~18~2 ~75~19~95 minecraft:concrete 8
fill ~75~23~2 ~75~41~2 minecraft:barrier
fill ~1~22~3 ~3~23~3 minecraft:concrete 8
fill ~4~22~3 ~9~23~3 minecraft:stained_glass 8
fill ~10~22~3 ~12~23~3 minecraft:concrete 8
fill ~11~18~3 ~11~21~3 minecraft:concrete 7
fill ~13~22~3 ~18~23~3 minecraft:stained_glass 8
fill ~19~22~3 ~21~23~3 minecraft:concrete 8
fill ~22~22~3 ~27~23~3 minecraft:stained_glass 8
fill ~28~22~3 ~30~23~3 minecraft:concrete 8
fill ~29~18~3 ~29~21~3 minecraft:concrete 7
fill ~31~17~3 ~39~17~3 minecraft:concrete 8
fill ~31~22~3 ~36~23~3 minecraft:stained_glass 8
fill ~37~22~3 ~39~23~3 minecraft:concrete 8
fill ~40~17~3 ~41~17~3 minecraft:sandstone 3
setblock ~40~18~3 minecraft:concrete 8
fill ~40~22~3 ~45~23~3 minecraft:stained_glass 8
fill ~41~2~3 ~41~2~14 minecraft:smooth_stone
setblock ~41~3~3 minecraft:concrete 13
fill ~41~4~3 ~41~13~3 minecraft:sandstone 3
setblock ~41~14~3 minecraft:concrete 4
fill ~41~15~3 ~41~16~3 minecraft:sandstone 3
fill ~42~13~3 ~42~13~7 minecraft:sandstone 3
fill ~45~17~3 ~45~17~14 minecraft:sandstone 3
fill ~45~20~3 ~45~20~14 minecraft:stone_block_slab2 6
fill ~46~19~3 ~55~19~15 minecraft:sandstone 3
fill ~46~22~3 ~48~23~3 minecraft:concrete 8
fill ~47~20~3 ~47~21~3 minecraft:concrete 7
fill ~49~22~3 ~54~23~3 minecraft:stained_glass 8
fill ~55~22~3 ~57~23~3 minecraft:concrete 8
fill ~56~20~3 ~56~20~14 minecraft:stone_block_slab2 6
fill ~58~22~3 ~63~23~3 minecraft:stained_glass 8
fill ~61~7~3 ~67~7~5 minecraft:carpet 7
fill ~61~11~3 ~68~11~6 minecraft:concrete 8
fill ~61~12~3 ~61~14~5 minecraft:cobblestone_wall 0
fill ~61~15~3 ~61~16~5 minecraft:cobblestone_wall 0
fill ~61~17~3 ~61~18~6 minecraft:concrete 8
fill ~64~22~3 ~66~23~3 minecraft:concrete 8
fill ~65~18~3 ~65~21~3 minecraft:concrete 7
fill ~67~22~3 ~72~23~3 minecraft:stained_glass 8
fill ~68~6~3 ~68~6~9 minecraft:smooth_stone
fill ~68~7~3 ~68~10~3 minecraft:concrete 8
fill ~73~22~3 ~75~23~3 minecraft:concrete 8
fill ~1~23~4 ~3~24~4 minecraft:concrete 8
fill ~4~23~4 ~9~24~4 minecraft:stained_glass 8
fill ~10~23~4 ~12~24~4 minecraft:concrete 8
setblock ~11~22~4 minecraft:concrete 7
fill ~13~23~4 ~18~24~4 minecraft:stained_glass 8
fill ~19~23~4 ~21~24~4 minecraft:concrete 8
fill ~22~23~4 ~27~24~4 minecraft:stained_glass 8
fill ~28~23~4 ~30~24~4 minecraft:concrete 8
setblock ~29~22~4 minecraft:concrete 7
fill ~31~1~4 ~39~2~4 minecraft:smooth_stone
fill ~31~3~4 ~39~16~4 minecraft:concrete 8
fill ~31~17~4 ~38~17~4 minecraft:concrete 8
fill ~31~23~4 ~36~24~4 minecraft:stained_glass 8
fill ~37~23~4 ~39~24~4 minecraft:concrete 8
fill ~39~17~4 ~40~17~4 minecraft:sandstone 3
setblock ~39~18~4 minecraft:concrete 8
fill ~40~2~4 ~40~2~14 minecraft:smooth_stone
setblock ~40~3~4 minecraft:concrete 13
fill ~40~4~4 ~40~13~4 minecraft:sandstone 3
setblock ~40~14~4 minecraft:concrete 4
fill ~40~15~4 ~40~16~4 minecraft:sandstone 3
fill ~40~23~4 ~45~24~4 minecraft:stained_glass 8
fill ~41~13~4 ~41~13~7 minecraft:sandstone 3
fill ~46~23~4 ~48~24~4 minecraft:concrete 8
setblock ~47~22~4 minecraft:concrete 7
fill ~49~23~4 ~54~24~4 minecraft:stained_glass 8
fill ~55~23~4 ~57~24~4 minecraft:concrete 8
fill ~58~23~4 ~63~24~4 minecraft:stained_glass 8
fill ~64~23~4 ~66~24~4 minecraft:concrete 8
setblock ~65~22~4 minecraft:concrete 7
fill ~67~23~4 ~72~24~4 minecraft:stained_glass 8
fill ~68~7~4 ~68~7~9 minecraft:carpet 7
fill ~69~6~4 ~70~6~12 minecraft:smooth_stone
fill ~69~7~4 ~70~11~4 minecraft:concrete 8
fill ~73~23~4 ~75~24~4 minecraft:concrete 8
fill ~1~24~5 ~3~25~5 minecraft:concrete 8
fill ~4~24~5 ~9~25~5 minecraft:stained_glass 8
fill ~10~24~5 ~12~25~5 minecraft:concrete 8
setblock ~11~23~5 minecraft:concrete 7
fill ~13~24~5 ~18~25~5 minecraft:stained_glass 8
fill ~19~24~5 ~21~25~5 minecraft:concrete 8
fill ~22~24~5 ~27~25~5 minecraft:stained_glass 8
fill ~28~24~5 ~30~25~5 minecraft:concrete 8
setblock ~29~23~5 minecraft:concrete 7
fill ~31~1~5 ~38~2~5 minecraft:smooth_stone
fill ~31~3~5 ~38~16~5 minecraft:concrete 8
fill ~31~17~5 ~37~17~6 minecraft:concrete 8
fill ~31~24~5 ~36~25~5 minecraft:stained_glass 8
fill ~37~24~5 ~39~25~5 minecraft:concrete 8
fill ~38~17~5 ~39~17~5 minecraft:sandstone 3
setblock ~38~18~5 minecraft:concrete 8
fill ~39~2~5 ~39~2~14 minecraft:smooth_stone
setblock ~39~3~5 minecraft:concrete 13
fill ~39~4~5 ~39~13~5 minecraft:sandstone 3
setblock ~39~14~5 minecraft:concrete 4
fill ~39~15~5 ~39~16~5 minecraft:sandstone 3
fill ~40~13~5 ~40~13~7 minecraft:sandstone 3
fill ~40~24~5 ~45~25~5 minecraft:stained_glass 8
fill ~45~14~5 ~45~14~14 minecraft:sandstone 3
fill ~45~15~5 ~45~16~6 minecraft:sandstone 3
fill ~46~24~5 ~48~25~5 minecraft:concrete 8
setblock ~47~23~5 minecraft:concrete 7
setblock ~49~3~5 minecraft:stone_block_slab 5
fill ~49~24~5 ~54~25~5 minecraft:stained_glass 8
fill ~50~3~5 ~55~3~5 minecraft:stonebrick 0
setblock ~51~4~5 minecraft:stone_block_slab 5
fill ~52~4~5 ~55~4~5 minecraft:stonebrick 0
setblock ~53~5~5 minecraft:stone_block_slab 5
fill ~54~5~5 ~55~5~5 minecraft:stonebrick 0
setblock ~55~6~5 minecraft:stone_block_slab 5
fill ~55~24~5 ~57~25~5 minecraft:concrete 8
setblock ~56~6~5 minecraft:stonebrick 0
fill ~57~6~5 ~67~6~9 minecraft:smooth_stone
fill ~58~24~5 ~63~25~5 minecraft:stained_glass 8
fill ~64~24~5 ~66~25~5 minecraft:concrete 8
setblock ~65~23~5 minecraft:concrete 7
fill ~67~24~5 ~72~25~5 minecraft:stained_glass 8
fill ~69~7~5 ~69~7~10 minecraft:carpet 7
fill ~69~11~5 ~70~11~10 minecraft:concrete 8
fill ~70~7~5 ~71~10~5 minecraft:concrete 8
fill ~73~24~5 ~75~25~5 minecraft:concrete 8
fill ~1~18~6 ~37~18~6 minecraft:concrete 8
fill ~1~19~6 ~1~26~6 minecraft:concrete 8
fill ~2~25~6 ~3~26~6 minecraft:concrete 8
fill ~4~25~6 ~9~26~6 minecraft:stained_glass 8
fill ~10~25~6 ~12~26~6 minecraft:concrete 8
setblock ~11~24~6 minecraft:concrete 7
fill ~13~25~6 ~18~26~6 minecraft:stained_glass 8
fill ~19~25~6 ~21~26~6 minecraft:concrete 8
fill ~22~25~6 ~27~26~6 minecraft:stained_glass 8
fill ~28~25~6 ~30~26~6 minecraft:concrete 8
setblock ~29~24~6 minecraft:concrete 7
fill ~31~1~6 ~37~2~6 minecraft:smooth_stone
fill ~31~3~6 ~37~16~6 minecraft:concrete 8
fill ~31~25~6 ~36~26~6 minecraft:stained_glass 8
fill ~37~19~6 ~37~26~6 minecraft:concrete 8
fill ~38~2~6 ~38~2~14 minecraft:smooth_stone
setblock ~38~3~6 minecraft:concrete 13
fill ~38~4~6 ~38~13~6 minecraft:sandstone 3
setblock ~38~14~6 minecraft:concrete 4
fill ~38~15~6 ~38~17~6 minecraft:sandstone 3
fill ~38~25~6 ~39~26~6 minecraft:concrete 8
fill ~39~13~6 ~39~13~7 minecraft:sandstone 3
fill ~40~25~6 ~45~26~6 minecraft:stained_glass 8
fill ~46~25~6 ~48~26~6 minecraft:concrete 8
setblock ~47~24~6 minecraft:concrete 7
fill ~49~1~6 ~59~1~10 minecraft:concrete 8
fill ~49~2~6 ~49~2~15 minecraft:smooth_stone
fill ~49~25~6 ~54~26~6 minecraft:stained_glass 8
fill ~55~25~6 ~57~26~6 minecraft:concrete 8
fill ~56~3~6 ~56~8~12 minecraft:sandstone 3
fill ~56~9~6 ~56~9~14 minecraft:concrete 13
fill ~56~10~6 ~56~10~14 minecraft:sandstone 3
fill ~56~17~6 ~56~17~14 minecraft:sandstone 3
fill ~58~25~6 ~63~26~6 minecraft:stained_glass 8
fill ~61~1~6 ~75~1~10 minecraft:concrete 8
fill ~61~7~6 ~63~10~6 minecraft:concrete 8
fill ~61~12~6 ~61~16~6 minecraft:concrete 8
fill ~62~18~6 ~65~18~6 minecraft:concrete 8
fill ~64~7~6 ~67~7~6 minecraft:carpet 7
fill ~64~25~6 ~66~26~6 minecraft:concrete 8
setblock ~65~24~6 minecraft:concrete 7
fill ~67~25~6 ~72~26~6 minecraft:stained_glass 8
fill ~70~7~6 ~70~7~12 minecraft:carpet 7
fill ~71~6~6 ~71~6~14 minecraft:smooth_stone
fill ~71~7~6 ~71~11~6 minecraft:concrete 8
fill ~73~25~6 ~75~26~6 minecraft:concrete 8
fill ~1~1~7 ~10~2~7 minecraft:sandstone 3
fill ~1~3~7 ~10~3~7 minecraft:concrete 13
fill ~1~4~7 ~24~6~7 minecraft:sandstone 3
fill ~1~7~7 ~10~13~7 minecraft:sandstone 3
fill ~1~14~7 ~12~14~7 minecraft:concrete 4
fill ~1~15~7 ~12~17~7 minecraft:sandstone 3
fill ~1~26~7 ~3~27~7 minecraft:concrete 8
fill ~4~26~7 ~9~27~7 minecraft:stained_glass 8
fill ~10~26~7 ~12~27~7 minecraft:concrete 8
setblock ~11~1~7 minecraft:stonebrick 0
fill ~11~2~7 ~24~3~7 minecraft:sandstone 3
setblock ~11~7~7 minecraft:stonebrick 0
fill ~11~8~7 ~12~13~7 minecraft:sandstone 3
setblock ~11~25~7 minecraft:concrete 7
fill ~12~1~7 ~24~1~7 minecraft:sandstone 3
setblock ~12~7~7 minecraft:sandstone 3
setblock ~13~7~7 minecraft:stonebrick 0
setblock ~13~9~7 minecraft:stone_block_slab 11
setblock ~13~10~7 minecraft:cobblestone_wall 0
setblock ~13~11~7 minecraft:stone_block_slab 3
setblock ~13~15~7 minecraft:stone_block_slab 11
setblock ~13~16~7 minecraft:cobblestone_wall 0
setblock ~13~17~7 minecraft:stone_block_slab 3
fill ~13~26~7 ~18~27~7 minecraft:stained_glass 8
fill ~14~7~7 ~24~13~7 minecraft:sandstone 3
fill ~14~14~7 ~24~14~7 minecraft:concrete 4
fill ~14~15~7 ~24~17~7 minecraft:sandstone 3
fill ~19~26~7 ~21~27~7 minecraft:concrete 8
fill ~22~26~7 ~27~27~7 minecraft:stained_glass 8
fill ~25~1~7 ~25~4~11 minecraft:concrete 8
setblock ~25~5~7 minecraft:cobblestone_wall 0
setblock ~25~9~7 minecraft:stone_block_slab 11
setblock ~25~10~7 minecraft:cobblestone_wall 0
setblock ~25~11~7 minecraft:stone_block_slab 3
setblock ~25~15~7 minecraft:stone_block_slab 11
setblock ~25~16~7 minecraft:cobblestone_wall 0
setblock ~25~17~7 minecraft:stone_block_slab 3
fill ~26~1~7 ~37~1~7 minecraft:sandstone 3
fill ~26~2~7 ~36~2~7 minecraft:sandstone 3
fill ~26~3~7 ~27~13~7 minecraft:sandstone 3
fill ~26~14~7 ~36~14~7 minecraft:concrete 4
fill ~26~15~7 ~36~17~7 minecraft:sandstone 3
fill ~28~3~7 ~36~3~7 minecraft:concrete 13
fill ~28~4~7 ~36~13~7 minecraft:sandstone 3
fill ~28~26~7 ~30~27~7 minecraft:concrete 8
setblock ~29~25~7 minecraft:concrete 7
fill ~31~26~7 ~36~27~7 minecraft:stained_glass 8
fill ~37~2~7 ~37~2~14 minecraft:smooth_stone
setblock ~37~3~7 minecraft:stone_block_slab 11
setblock ~37~4~7 minecraft:cobblestone_wall 0
setblock ~37~5~7 minecraft:stone_block_slab 3
setblock ~37~9~7 minecraft:stone_block_slab 11
setblock ~37~10~7 minecraft:cobblestone_wall 0
setblock ~37~11~7 minecraft:stone_block_slab 3
setblock ~37~15~7 minecraft:stone_block_slab 11
setblock ~37~16~7 minecraft:cobblestone_wall 0
setblock ~37~17~7 minecraft:stone_block_slab 3
fill ~37~26~7 ~39~27~7 minecraft:concrete 8
setblock ~38~13~7 minecraft:sandstone 3
fill ~39~14~7 ~39~15~7 minecraft:double_stone_block_slab 0
fill ~39~16~7 ~39~25~7 minecraft:iron_bars
fill ~40~14~7 ~41~14~7 minecraft:stone_block_slab 0
fill ~40~26~7 ~45~27~7 minecraft:stained_glass 8
fill ~42~14~7 ~42~15~7 minecraft:double_stone_block_slab 0
fill ~42~16~7 ~42~25~7 minecraft:iron_bars
setblock ~45~16~7 minecraft:stone_block_slab2 6
fill ~46~26~7 ~48~27~7 minecraft:concrete 8
setblock ~47~25~7 minecraft:concrete 7
fill ~49~26~7 ~54~27~7 minecraft:stained_glass 8
fill ~55~26~7 ~57~27~7 minecraft:concrete 8
fill ~58~26~7 ~63~27~7 minecraft:stained_glass 8
fill ~60~1~7 ~60~1~10 minecraft:concrete 8
fill ~61~7~7 ~61~7~10 minecraft:carpet 7
fill ~62~7~7 ~63~13~7 minecraft:sandstone 3
fill ~62~14~7 ~63~14~7 minecraft:concrete 4
fill ~62~15~7 ~65~16~7 minecraft:sandstone 3
fill ~62~17~7 ~64~17~7 minecraft:sandstone 3
fill ~64~7~7 ~65~10~7 minecraft:concrete 8
fill ~64~11~7 ~65~11~8 minecraft:sandstone 3
fill ~64~26~7 ~66~27~7 minecraft:concrete 8
fill ~65~17~7 ~75~17~7 minecraft:concrete 8
fill ~65~18~7 ~67~18~7 minecraft:concrete 8
setblock ~65~25~7 minecraft:concrete 7
fill ~66~7~7 ~67~7~7 minecraft:carpet 7
fill ~66~11~7 ~68~11~7 minecraft:concrete 8
fill ~66~15~7 ~75~16~7 minecraft:concrete 8
fill ~67~26~7 ~72~27~7 minecraft:stained_glass 8
fill ~71~7~7 ~71~7~14 minecraft:carpet 7
fill ~71~11~7 ~73~11~15 minecraft:concrete 8
fill ~72~6~7 ~74~6~7 minecraft:smooth_stone
fill ~72~7~7 ~73~10~7 minecraft:concrete 8
fill ~73~26~7 ~75~27~7 minecraft:concrete 8
fill ~1~0~8 ~28~0~43 minecraft:smooth_stone
fill ~1~3~8 ~1~3~10 minecraft:stained_glass_pane 7
setblock ~1~4~8 minecraft:stained_glass_pane 15
fill ~1~5~8 ~1~5~9 minecraft:stained_glass_pane 7
fill ~1~6~8 ~1~7~9 minecraft:stained_glass_pane 15
fill ~1~8~8 ~1~9~8 minecraft:stained_glass_pane 15
setblock ~1~10~8 minecraft:stained_glass_pane 7
fill ~1~11~8 ~1~11~17 minecraft:stained_glass_pane 15
setblock ~1~12~8 minecraft:stained_glass_pane 7
fill ~1~13~8 ~1~14~8 minecraft:stained_glass_pane 15
fill ~1~15~8 ~1~16~8 minecraft:stained_glass_pane 7
fill ~1~17~8 ~1~17~14 minecraft:stained_glass_pane 15
fill ~1~27~8 ~3~27~9 minecraft:concrete 8
fill ~4~27~8 ~9~27~9 minecraft:stained_glass 8
fill ~10~27~8 ~12~27~9 minecraft:concrete 8
fill ~11~1~8 ~11~1~9 minecraft:stone_brick_stairs 0
fill ~11~2~8 ~11~6~9 minecraft:concrete 7
fill ~11~7~8 ~11~7~9 minecraft:stone_brick_stairs 4
fill ~11~26~8 ~11~26~9 minecraft:concrete 7
fill ~12~1~8 ~24~3~9 minecraft:concrete 8
fill ~12~4~8 ~22~5~9 minecraft:concrete 8
fill ~12~6~8 ~17~7~9 minecraft:concrete 8
fill ~13~27~8 ~18~27~9 minecraft:stained_glass 8
fill ~18~6~8 ~18~6~10 minecraft:stone_block_slab 8
fill ~18~7~8 ~19~7~19 minecraft:concrete 8
fill ~19~6~8 ~20~6~19 minecraft:concrete 8
fill ~19~27~8 ~21~27~9 minecraft:concrete 8
fill ~20~7~8 ~20~7~10 minecraft:stone_block_slab 0
fill ~21~6~8 ~22~6~10 minecraft:stone_block_slab 0
fill ~22~27~8 ~27~27~9 minecraft:stained_glass 8
fill ~23~5~8 ~23~5~11 minecraft:concrete 8
fill ~24~4~8 ~24~4~11 minecraft:concrete 8
fill ~24~5~8 ~24~5~10 minecraft:stone_block_slab 0
fill ~26~1~8 ~30~1~8 minecraft:concrete 8
fill ~26~2~8 ~29~2~10 minecraft:concrete 8
fill ~26~3~8 ~27~3~10 minecraft:concrete 8
fill ~26~4~8 ~26~4~10 minecraft:stone_block_slab 0
fill ~28~3~8 ~28~3~10 minecraft:stone_block_slab 0
fill ~28~27~8 ~30~27~9 minecraft:concrete 8
fill ~29~26~8 ~29~26~9 minecraft:concrete 7
fill ~30~0~8 ~74~0~96 minecraft:smooth_stone
fill ~30~2~8 ~30~2~10 minecraft:stone_block_slab 0
fill ~31~1~8 ~33~1~33 minecraft:smooth_stone
fill ~31~27~8 ~36~27~9 minecraft:stained_glass 8
fill ~34~2~8 ~34~2~33 minecraft:stone_block_slab 0
fill ~35~2~8 ~36~2~13 minecraft:smooth_stone
fill ~37~27~8 ~39~27~9 minecraft:concrete 8
fill ~40~14~8 ~41~14~8 minecraft:smooth_stone
fill ~40~27~8 ~45~27~9 minecraft:stained_glass 8
fill ~45~13~8 ~56~13~14 minecraft:sandstone 3
fill ~45~15~8 ~45~16~14 minecraft:sandstone 3
fill ~46~27~8 ~48~27~9 minecraft:concrete 8
fill ~47~26~8 ~47~26~9 minecraft:concrete 7
fill ~49~27~8 ~54~27~9 minecraft:stained_glass 8
fill ~55~27~8 ~57~27~9 minecraft:concrete 8
fill ~56~14~8 ~56~14~14 minecraft:sandstone 3
fill ~56~15~8 ~56~16~9 minecraft:sandstone 3
fill ~58~27~8 ~63~27~9 minecraft:stained_glass 8
fill ~62~7~8 ~63~7~10 minecraft:carpet 7
fill ~64~7~8 ~65~10~8 minecraft:sandstone 3
fill ~64~12~8 ~65~13~8 minecraft:sandstone 3
fill ~64~14~8 ~65~14~8 minecraft:concrete 4
fill ~64~15~8 ~67~16~8 minecraft:sandstone 3
fill ~64~17~8 ~66~17~8 minecraft:sandstone 3
fill ~64~27~8 ~66~27~9 minecraft:concrete 8
fill ~65~26~8 ~65~26~9 minecraft:concrete 7
fill ~66~7~8 ~66~10~8 minecraft:concrete 8
fill ~66~11~8 ~66~11~9 minecraft:sandstone 3
setblock ~67~7~8 minecraft:carpet 7
fill ~67~11~8 ~68~11~8 minecraft:concrete 8
fill ~67~17~8 ~75~17~8 minecraft:concrete 8
setblock ~67~18~8 minecraft:concrete 8
fill ~67~27~8 ~72~27~9 minecraft:stained_glass 8
fill ~68~15~8 ~75~16~9 minecraft:concrete 8
fill ~72~6~8 ~73~6~40 minecraft:smooth_stone
fill ~72~7~8 ~72~7~30 minecraft:carpet 7
fill ~73~7~8 ~74~10~8 minecraft:concrete 8
fill ~73~27~8 ~75~27~9 minecraft:concrete 8
fill ~74~11~8 ~74~11~15 minecraft:concrete 8
fill ~1~1~9 ~1~2~9 minecraft:stained_glass_pane 15
setblock ~1~4~9 minecraft:stained_glass_pane 7
fill ~1~8~9 ~1~9~9 minecraft:stained_glass_pane 7
setblock ~1~10~9 minecraft:stained_glass_pane 15
fill ~1~12~9 ~1~12~12 minecraft:stained_glass_pane 15
fill ~1~13~9 ~1~14~11 minecraft:stained_glass_pane 7
setblock ~1~15~9 minecraft:stained_glass_pane 15
fill ~1~16~9 ~1~16~10 minecraft:stained_glass_pane 7
fill ~1~28~9 ~3~28~11 minecraft:concrete 8
fill ~4~28~9 ~9~28~11 minecraft:stained_glass 8
fill ~10~28~9 ~12~28~11 minecraft:concrete 8
fill ~13~28~9 ~18~28~11 minecraft:stained_glass 8
fill ~19~28~9 ~21~28~11 minecraft:concrete 8
fill ~22~28~9 ~27~28~11 minecraft:stained_glass 8
fill ~26~1~9 ~28~1~10 minecraft:concrete 8
fill ~28~28~9 ~30~28~11 minecraft:concrete 8
setblock ~29~1~9 minecraft:stone_block_slab 0
fill ~30~1~9 ~30~1~10 minecraft:concrete 8
fill ~31~28~9 ~36~28~11 minecraft:stained_glass 8
fill ~37~28~9 ~39~28~11 minecraft:concrete 8
fill ~40~14~9 ~41~14~9 minecraft:stone_block_slab 8
fill ~40~15~9 ~41~15~9 minecraft:stone_block_slab 0
fill ~40~28~9 ~45~28~11 minecraft:stained_glass 8
fill ~45~3~9 ~45~6~13 minecraft:sandstone 3
fill ~46~14~9 ~49~17~15 minecraft:sandstone 3
fill ~46~28~9 ~48~28~11 minecraft:concrete 8
fill ~49~28~9 ~54~28~11 minecraft:stained_glass 8
fill ~55~28~9 ~57~28~11 minecraft:concrete 8
fill ~58~28~9 ~63~28~11 minecraft:stained_glass 8
fill ~64~7~9 ~65~7~10 minecraft:carpet 7
fill ~64~28~9 ~66~28~11 minecraft:concrete 8
fill ~66~7~9 ~66~10~9 minecraft:sandstone 3
fill ~66~12~9 ~66~13~9 minecraft:sandstone 3
fill ~66~14~9 ~67~14~9 minecraft:concrete 4
fill ~66~15~9 ~67~17~9 minecraft:sandstone 3
fill ~67~7~9 ~67~10~9 minecraft:concrete 8
fill ~67~11~9 ~67~11~10 minecraft:sandstone 3
fill ~67~28~9 ~72~28~11 minecraft:stained_glass 8
fill ~68~11~9 ~68~11~10 minecraft:concrete 8
fill ~68~17~9 ~75~17~10 minecraft:concrete 8
fill ~68~18~9 ~68~18~10 minecraft:concrete 8
fill ~73~7~9 ~73~7~30 minecraft:carpet 7
fill ~73~28~9 ~75~28~11 minecraft:concrete 8
fill ~74~7~9 ~74~10~9 minecraft:concrete 8
fill ~1~1~10 ~1~2~10 minecraft:stained_glass_pane 7
fill ~1~4~10 ~1~5~10 minecraft:stained_glass_pane 15
fill ~1~6~10 ~1~6~12 minecraft:stained_glass_pane 7
fill ~1~7~10 ~1~9~10 minecraft:stained_glass_pane 15
fill ~1~10~10 ~1~10~11 minecraft:stained_glass_pane 7
setblock ~1~15~10 minecraft:stained_glass_pane 7
fill ~11~1~10 ~11~7~10 minecraft:stonebrick 0
fill ~11~27~10 ~11~27~11 minecraft:concrete 7
fill ~12~1~10 ~13~1~10 minecraft:stone_brick_stairs 3
fill ~12~2~10 ~13~6~10 minecraft:concrete 7
fill ~12~7~10 ~13~7~10 minecraft:stone_brick_stairs 7
fill ~14~1~10 ~14~6~10 minecraft:stonebrick 0
fill ~14~7~10 ~17~7~10 minecraft:concrete 8
fill ~15~1~10 ~24~3~10 minecraft:concrete 8
fill ~15~4~10 ~22~5~10 minecraft:concrete 8
fill ~15~6~10 ~17~6~10 minecraft:concrete 8
setblock ~29~1~10 minecraft:concrete 8
fill ~29~27~10 ~29~27~11 minecraft:concrete 7
fill ~40~15~10 ~41~15~10 minecraft:smooth_stone
fill ~47~27~10 ~47~27~11 minecraft:concrete 7
setblock ~56~16~10 minecraft:stone_block_slab2 6
fill ~57~6~10 ~66~6~10 minecraft:smooth_stone
fill ~60~5~10 ~60~5~20 minecraft:smooth_stone
fill ~64~4~10 ~64~4~40 minecraft:smooth_stone
setblock ~64~5~10 minecraft:smooth_stone
fill ~65~27~10 ~65~27~11 minecraft:concrete 7
setblock ~66~7~10 minecraft:carpet 7
fill ~67~6~10 ~68~6~10 minecraft:sandstone 3
fill ~67~7~10 ~67~10~10 minecraft:sandstone 3
fill ~67~12~10 ~67~13~10 minecraft:sandstone 3
setblock ~67~14~10 minecraft:concrete 4
fill ~67~15~10 ~67~17~10 minecraft:sandstone 3
fill ~68~7~10 ~68~10~10 minecraft:concrete 8
fill ~74~6~10 ~74~6~15 minecraft:smooth_stone
fill ~74~7~10 ~74~7~14 minecraft:carpet 7
fill ~75~15~10 ~75~16~96 minecraft:concrete 8
fill ~1~1~11 ~1~1~12 minecraft:stained_glass_pane 15
setblock ~1~2~11 minecraft:stained_glass_pane 7
fill ~1~3~11 ~1~3~12 minecraft:stained_glass_pane 15
fill ~1~4~11 ~1~4~12 minecraft:stained_glass_pane 7
setblock ~1~5~11 minecraft:stained_glass_pane 15
fill ~1~7~11 ~1~7~12 minecraft:stained_glass_pane 7
setblock ~1~8~11 minecraft:stained_glass_pane 15
setblock ~1~9~11 minecraft:stained_glass_pane 7
fill ~1~15~11 ~1~16~11 minecraft:stained_glass_pane 15
fill ~1~29~11 ~3~29~13 minecraft:concrete 8
fill ~4~29~11 ~9~29~13 minecraft:stained_glass 8
fill ~10~29~11 ~12~29~13 minecraft:concrete 8
fill ~13~29~11 ~18~29~13 minecraft:stained_glass 8
fill ~14~1~11 ~14~4~11 minecraft:cobblestone_wall 0
setblock ~14~5~11 minecraft:cobblestone_wall 0
setblock ~14~6~11 minecraft:cobblestone_wall 0
setblock ~14~7~11 minecraft:cobblestone_wall 0
fill ~14~8~11 ~14~9~11 minecraft:cobblestone_wall 0
fill ~14~10~11 ~14~10~21 minecraft:stonebrick 0
fill ~15~1~11 ~16~3~11 minecraft:concrete 7
fill ~15~4~11 ~16~4~11 minecraft:cobblestone_wall 0
fill ~15~5~11 ~22~5~11 minecraft:concrete 8
fill ~15~7~11 ~17~7~13 minecraft:concrete 8
fill ~15~8~11 ~17~8~11 minecraft:normal_stone_stairs 2
fill ~16~6~11 ~18~6~19 minecraft:concrete 8
fill ~17~1~11 ~24~3~11 minecraft:concrete 8
fill ~17~4~11 ~23~4~11 minecraft:concrete 8
fill ~18~8~11 ~27~9~11 minecraft:concrete 8
fill ~18~10~11 ~28~10~11 minecraft:stonebrick 0
fill ~19~29~11 ~21~29~13 minecraft:concrete 8
fill ~20~7~11 ~27~7~12 minecraft:concrete 8
fill ~21~6~11 ~27~6~12 minecraft:concrete 8
fill ~22~29~11 ~27~29~13 minecraft:stained_glass 8
fill ~24~5~11 ~27~5~19 minecraft:concrete 8
fill ~26~1~11 ~27~3~11 minecraft:concrete 7
fill ~26~4~11 ~27~4~11 minecraft:cobblestone_wall 0
setblock ~28~1~11 minecraft:cobblestone_wall 0
setblock ~28~2~11 minecraft:cobblestone_wall 0
fill ~28~3~11 ~28~9~11 minecraft:cobblestone_wall 0
fill ~28~29~11 ~30~29~13 minecraft:concrete 8
fill ~29~1~11 ~30~1~33 minecraft:stone_block_slab 0
fill ~31~29~11 ~36~29~13 minecraft:stained_glass 8
fill ~37~29~11 ~39~29~13 minecraft:concrete 8
fill ~40~15~11 ~41~15~11 minecraft:stone_block_slab 8
fill ~40~16~11 ~41~16~11 minecraft:stone_block_slab 0
fill ~40~29~11 ~45~29~13 minecraft:stained_glass 8
fill ~46~29~11 ~48~29~13 minecraft:concrete 8
fill ~49~29~11 ~54~29~13 minecraft:stained_glass 8
fill ~50~2~11 ~55~2~15 minecraft:smooth_stone
fill ~55~29~11 ~57~29~13 minecraft:concrete 8
fill ~56~15~11 ~56~16~12 minecraft:sandstone 3
fill ~57~6~11 ~60~6~20 minecraft:smooth_stone
fill ~58~29~11 ~63~29~13 minecraft:stained_glass 8
fill ~61~5~11 ~61~5~20 minecraft:stonebrick 0
fill ~61~6~11 ~61~6~19 minecraft:stone_brick_stairs 5
fill ~62~5~11 ~63~5~11 minecraft:stone_block_slab 0
fill ~62~6~11 ~63~6~11 minecraft:stone_block_slab 8
fill ~64~5~11 ~64~5~16 minecraft:stonebrick 0
fill ~64~6~11 ~64~6~12 minecraft:stonebrick 0
fill ~64~29~11 ~66~29~13 minecraft:concrete 8
fill ~65~4~11 ~65~4~40 minecraft:smooth_stone
fill ~65~5~11 ~66~5~11 minecraft:double_stone_block_slab 5
fill ~65~6~11 ~66~6~11 minecraft:stone_brick_stairs 7
fill ~67~5~11 ~67~6~11 minecraft:stonebrick 0
fill ~67~29~11 ~72~29~13 minecraft:stained_glass 8
fill ~68~6~11 ~68~13~12 minecraft:sandstone 3
fill ~68~14~11 ~68~14~12 minecraft:concrete 4
fill ~68~15~11 ~69~16~12 minecraft:sandstone 3
fill ~68~17~11 ~68~17~12 minecraft:sandstone 3
fill ~69~7~11 ~69~10~12 minecraft:concrete 8
fill ~69~11~11 ~69~11~14 minecraft:sandstone 3
fill ~69~17~11 ~75~17~12 minecraft:concrete 8
fill ~69~18~11 ~69~18~12 minecraft:concrete 8
fill ~70~11~11 ~70~11~15 minecraft:concrete 8
fill ~70~15~11 ~74~16~13 minecraft:concrete 8
fill ~73~29~11 ~75~29~13 minecraft:concrete 8
fill ~75~1~11 ~75~1~96 minecraft:concrete 8
fill ~1~2~12 ~1~2~13 minecraft:stained_glass_pane 15
setblock ~1~5~12 minecraft:stained_glass_pane 7
fill ~1~8~12 ~1~8~13 minecraft:stained_glass_pane 7
fill ~1~9~12 ~1~10~12 minecraft:stained_glass_pane 15
fill ~1~13~12 ~1~13~14 minecraft:stained_glass_pane 15
fill ~1~14~12 ~1~16~12 minecraft:stained_glass_pane 7
fill ~11~28~12 ~11~28~13 minecraft:concrete 7
fill ~14~1~12 ~14~8~13 minecraft:concrete 7
setblock ~14~9~12 minecraft:cobblestone_wall 0
fill ~15~5~12 ~18~5~13 minecraft:concrete 8
fill ~15~6~12 ~15~6~13 minecraft:concrete 8
fill ~15~8~12 ~16~8~13 minecraft:concrete 8
fill ~15~9~12 ~17~9~12 minecraft:normal_stone_stairs 2
fill ~17~1~12 ~18~4~12 minecraft:concrete 4
fill ~17~8~12 ~19~8~12 minecraft:stone_block_slab 0
fill ~18~9~12 ~25~9~12 minecraft:concrete 8
fill ~18~10~12 ~18~10~13 minecraft:stonebrick 0
fill ~19~1~12 ~19~4~12 minecraft:cobblestone_wall 0
fill ~19~5~12 ~23~5~12 minecraft:cobblestone_wall 0
fill ~19~10~12 ~27~10~13 minecraft:concrete 8
fill ~19~11~12 ~27~11~13 minecraft:carpet 7
fill ~20~8~12 ~25~8~19 minecraft:concrete 8
fill ~23~1~12 ~23~4~12 minecraft:cobblestone_wall 0
fill ~24~1~12 ~25~4~12 minecraft:concrete 4
fill ~26~8~12 ~27~9~12 minecraft:concrete 4
fill ~28~1~12 ~28~8~13 minecraft:concrete 7
fill ~28~9~12 ~28~9~20 minecraft:cobblestone_wall 0
fill ~28~10~12 ~28~10~14 minecraft:stonebrick 0
fill ~29~28~12 ~29~28~13 minecraft:concrete 7
fill ~40~16~12 ~41~16~12 minecraft:smooth_stone
fill ~47~28~12 ~47~28~13 minecraft:concrete 7
fill ~62~5~12 ~63~5~13 minecraft:smooth_stone
fill ~62~6~12 ~63~6~12 minecraft:double_stone_block_slab 0
fill ~65~28~12 ~65~28~13 minecraft:concrete 7
fill ~66~4~12 ~69~4~22 minecraft:smooth_stone
fill ~68~5~12 ~69~5~12 minecraft:sandstone 3
fill ~69~12~12 ~69~13~14 minecraft:sandstone 3
setblock ~69~14~12 minecraft:sandstone 3
fill ~1~1~13 ~1~1~15 minecraft:stained_glass_pane 7
fill ~1~3~13 ~1~3~14 minecraft:stained_glass_pane 7
fill ~1~4~13 ~1~7~13 minecraft:stained_glass_pane 15
fill ~1~9~13 ~1~9~15 minecraft:stained_glass_pane 7
setblock ~1~10~13 minecraft:stained_glass_pane 15
fill ~1~12~13 ~1~12~14 minecraft:stained_glass_pane 7
fill ~1~14~13 ~1~14~15 minecraft:stained_glass_pane 15
fill ~1~15~13 ~1~15~14 minecraft:stained_glass_pane 15
fill ~1~16~13 ~1~16~16 minecraft:stained_glass_pane 7
fill ~1~30~13 ~3~30~15 minecraft:concrete 8
fill ~4~30~13 ~9~30~15 minecraft:stained_glass 8
fill ~10~30~13 ~12~30~15 minecraft:concrete 8
fill ~13~30~13 ~18~30~15 minecraft:stained_glass 8
fill ~14~9~13 ~14~9~20 minecraft:cobblestone_wall 0
fill ~15~9~13 ~16~9~13 minecraft:concrete 8
fill ~15~10~13 ~17~10~13 minecraft:normal_stone_stairs 2
fill ~17~8~13 ~17~9~13 minecraft:stone_block_slab 0
fill ~18~8~13 ~19~8~19 minecraft:concrete 8
fill ~19~5~13 ~23~5~19 minecraft:concrete 8
fill ~19~9~13 ~26~9~13 minecraft:concrete 8
fill ~19~30~13 ~21~30~15 minecraft:concrete 8
fill ~20~7~13 ~26~7~19 minecraft:concrete 8
fill ~21~6~13 ~26~6~19 minecraft:concrete 8
fill ~22~30~13 ~27~30~15 minecraft:stained_glass 8
fill ~26~8~13 ~26~8~19 minecraft:concrete 8
fill ~27~8~13 ~27~9~13 minecraft:concrete 4
fill ~28~30~13 ~30~30~15 minecraft:concrete 8
fill ~31~30~13 ~36~30~15 minecraft:stained_glass 8
fill ~37~30~13 ~39~30~15 minecraft:concrete 8
fill ~40~16~13 ~41~16~13 minecraft:stone_block_slab 8
fill ~40~17~13 ~41~17~13 minecraft:stone_block_slab 0
fill ~40~30~13 ~45~30~15 minecraft:stained_glass 8
fill ~46~3~13 ~47~8~15 minecraft:sandstone 3
fill ~46~9~13 ~47~9~15 minecraft:concrete 13
fill ~46~10~13 ~47~12~15 minecraft:sandstone 3
fill ~46~30~13 ~48~30~15 minecraft:concrete 8
fill ~49~30~13 ~54~30~15 minecraft:stained_glass 8
fill ~54~3~13 ~55~8~14 minecraft:sandstone 3
fill ~54~9~13 ~55~9~15 minecraft:concrete 13
fill ~54~10~13 ~55~12~15 minecraft:sandstone 3
fill ~55~30~13 ~57~30~15 minecraft:concrete 8
fill ~56~3~13 ~56~6~14 minecraft:smooth_stone
fill ~56~7~13 ~56~8~14 minecraft:sandstone 3
setblock ~56~16~13 minecraft:stone_block_slab2 6
fill ~58~30~13 ~63~30~15 minecraft:stained_glass 8
fill ~62~6~13 ~63~6~14 minecraft:stone_block_slab 0
fill ~64~6~13 ~64~6~14 minecraft:stone_block_slab 5
fill ~64~30~13 ~66~30~15 minecraft:concrete 8
fill ~67~30~13 ~72~30~15 minecraft:stained_glass 8
fill ~69~5~13 ~69~10~14 minecraft:sandstone 3
fill ~69~14~13 ~69~14~14 minecraft:concrete 4
fill ~69~15~13 ~69~17~14 minecraft:sandstone 3
fill ~70~6~13 ~70~6~14 minecraft:smooth_stone
fill ~70~7~13 ~70~10~15 minecraft:concrete 8
fill ~70~17~13 ~75~17~15 minecraft:concrete 8
fill ~70~18~13 ~70~18~15 minecraft:concrete 8
fill ~73~30~13 ~75~30~15 minecraft:concrete 8
setblock ~1~2~14 minecraft:stained_glass_pane 7
fill ~1~4~14 ~1~5~15 minecraft:stained_glass_pane 7
fill ~1~6~14 ~1~6~16 minecraft:stained_glass_pane 15
fill ~1~7~14 ~1~7~16 minecraft:stained_glass_pane 7
fill ~1~8~14 ~1~8~18 minecraft:stained_glass_pane 15
fill ~1~10~14 ~1~10~15 minecraft:stained_glass_pane 7
fill ~11~29~14 ~11~29~15 minecraft:concrete 7
fill ~14~1~14 ~14~4~14 minecraft:stonebrick 0
fill ~14~5~14 ~14~5~18 minecraft:cobblestone_wall 0
fill ~14~6~14 ~14~8~14 minecraft:cobblestone_wall 0
fill ~15~5~14 ~15~9~18 minecraft:concrete 13
fill ~15~10~14 ~18~10~14 minecraft:stone_block_slab 0
fill ~15~11~14 ~24~11~17 minecraft:carpet 7
fill ~16~5~14 ~18~5~19 minecraft:concrete 8
fill ~16~7~14 ~17~8~19 minecraft:concrete 8
fill ~16~9~14 ~19~9~15 minecraft:stone_block_slab 0
fill ~19~10~14 ~24~10~17 minecraft:concrete 8
fill ~20~9~14 ~26~9~19 minecraft:concrete 8
fill ~25~10~14 ~25~10~18 minecraft:wool 7
fill ~25~11~14 ~25~12~14 minecraft:cobblestone_wall 0
setblock ~25~13~14 minecraft:cobblestone_wall 0
fill ~26~10~14 ~27~10~20 minecraft:concrete 8
fill ~26~11~14 ~27~11~20 minecraft:carpet 7
fill ~27~6~14 ~27~9~18 minecraft:concrete 13
fill ~28~1~14 ~28~4~14 minecraft:stonebrick 0
fill ~28~5~14 ~28~5~18 minecraft:cobblestone_wall 0
fill ~28~6~14 ~28~8~14 minecraft:cobblestone_wall 0
setblock ~29~9~14 minecraft:stone_block_slab 13
setblock ~29~10~14 minecraft:stone_block_slab 5
fill ~29~29~14 ~29~29~15 minecraft:concrete 7
setblock ~30~9~14 minecraft:double_stone_block_slab 5
setblock ~31~8~14 minecraft:stone_block_slab 13
setblock ~31~9~14 minecraft:stone_block_slab 5
setblock ~32~8~14 minecraft:double_stone_block_slab 5
setblock ~33~7~14 minecraft:stone_block_slab 13
setblock ~33~8~14 minecraft:stone_block_slab 5
setblock ~34~1~14 minecraft:smooth_stone
setblock ~34~7~14 minecraft:double_stone_block_slab 5
fill ~35~2~14 ~35~2~20 minecraft:stonebrick 0
fill ~35~3~14 ~44~5~14 minecraft:stonebrick 0
setblock ~35~6~14 minecraft:stonebrick 0
setblock ~35~7~14 minecraft:stone_block_slab 5
setblock ~36~2~14 minecraft:smooth_stone
fill ~36~6~14 ~44~6~14 minecraft:stone_brick_stairs 6
fill ~40~17~14 ~41~17~14 minecraft:smooth_stone
fill ~45~3~14 ~45~6~14 minecraft:concrete 8
fill ~47~29~14 ~47~29~15 minecraft:concrete 7
fill ~56~15~14 ~56~16~14 minecraft:sandstone 3
fill ~61~4~14 ~63~4~19 minecraft:smooth_stone
fill ~62~5~14 ~63~5~16 minecraft:double_stone_block_slab 0
fill ~65~29~14 ~65~29~15 minecraft:concrete 7
fill ~70~4~14 ~70~4~22 minecraft:smooth_stone
setblock ~70~5~14 minecraft:smooth_stone
fill ~70~15~14 ~70~16~15 minecraft:concrete 8
fill ~71~16~14 ~74~16~14 minecraft:concrete 8
fill ~72~15~14 ~74~15~14 minecraft:concrete 8
fill ~1~2~15 ~1~3~15 minecraft:stained_glass_pane 15
setblock ~1~12~15 minecraft:stained_glass_pane 15
fill ~1~13~15 ~1~13~17 minecraft:stained_glass_pane 7
fill ~1~15~15 ~1~15~16 minecraft:stained_glass_pane 7
fill ~1~17~15 ~1~17~16 minecraft:stained_glass_pane 7
fill ~1~31~15 ~3~31~17 minecraft:concrete 8
fill ~4~31~15 ~9~31~17 minecraft:stained_glass 8
fill ~10~31~15 ~12~31~17 minecraft:concrete 8
fill ~13~31~15 ~18~31~17 minecraft:stained_glass 8
fill ~14~4~15 ~14~4~17 minecraft:stone_block_slab 13
fill ~14~6~15 ~14~8~17 minecraft:iron_bars
fill ~15~10~15 ~16~10~17 minecraft:stone_block_slab 0
fill ~17~10~15 ~18~10~20 minecraft:concrete 8
fill ~19~31~15 ~21~31~17 minecraft:concrete 8
fill ~22~31~15 ~27~31~17 minecraft:stained_glass 8
fill ~25~11~15 ~25~12~17 minecraft:cobblestone_wall 0
fill ~25~13~15 ~25~13~17 minecraft:cobblestone_wall 0
fill ~28~4~15 ~28~4~17 minecraft:stone_block_slab 13
fill ~28~6~15 ~28~8~17 minecraft:iron_bars
fill ~28~10~15 ~28~10~16 minecraft:double_stone_block_slab 0
fill ~28~31~15 ~30~31~17 minecraft:concrete 8
fill ~29~9~15 ~29~9~16 minecraft:stone_block_slab 8
fill ~29~10~15 ~29~10~16 minecraft:stone_block_slab 0
fill ~30~9~15 ~30~9~16 minecraft:double_stone_block_slab 0
fill ~31~8~15 ~31~8~16 minecraft:stone_block_slab 8
fill ~31~9~15 ~31~9~16 minecraft:stone_block_slab 0
fill ~31~31~15 ~36~31~17 minecraft:stained_glass 8
fill ~32~8~15 ~32~8~16 minecraft:double_stone_block_slab 0
fill ~33~7~15 ~33~7~16 minecraft:stone_block_slab 8
fill ~33~8~15 ~33~8~16 minecraft:stone_block_slab 0
fill ~34~1~15 ~34~1~17 minecraft:concrete 4
fill ~34~7~15 ~34~7~16 minecraft:double_stone_block_slab 0
fill ~35~3~15 ~35~3~19 minecraft:stone_brick_stairs 0
fill ~35~4~15 ~35~5~19 minecraft:concrete 4
fill ~35~6~15 ~35~6~19 minecraft:stone_brick_stairs 4
fill ~35~7~15 ~35~7~16 minecraft:stone_block_slab 0
setblock ~36~4~15 minecraft:stonebrick 0
fill ~36~6~15 ~44~6~19 minecraft:concrete 8
fill ~36~7~15 ~45~7~19 minecraft:carpet 7
fill ~37~31~15 ~39~31~17 minecraft:concrete 8
fill ~40~17~15 ~41~17~15 minecraft:stone_block_slab 8
fill ~40~18~15 ~41~18~15 minecraft:stone_block_slab 0
fill ~40~31~15 ~45~31~17 minecraft:stained_glass 8
setblock ~45~6~15 minecraft:stonebrick 0
setblock ~45~11~15 minecraft:cobblestone_wall 0
setblock ~45~17~15 minecraft:cobblestone_wall 0
fill ~46~2~15 ~48~2~15 minecraft:smooth_stone
fill ~46~13~15 ~55~13~15 minecraft:sandstone 3
fill ~46~18~15 ~55~18~15 minecraft:concrete 4
fill ~46~20~15 ~55~20~15 minecraft:stone_block_slab2 6
fill ~46~31~15 ~48~31~17 minecraft:concrete 8
fill ~48~3~15 ~53~5~15 minecraft:stonebrick 0
fill ~48~6~15 ~53~6~15 minecraft:stone_brick_stairs 6
fill ~48~12~15 ~53~12~15 minecraft:sandstone 3
fill ~49~31~15 ~54~31~17 minecraft:stained_glass 8
fill ~50~14~15 ~52~14~15 minecraft:sandstone 3
fill ~50~15~15 ~50~17~15 minecraft:sandstone 3
setblock ~51~16~15 minecraft:stone_block_slab2 6
fill ~51~17~15 ~55~17~15 minecraft:sandstone 3
fill ~52~15~15 ~52~16~15 minecraft:sandstone 3
fill ~54~3~15 ~54~8~15 minecraft:sandstone 3
fill ~55~3~15 ~55~6~15 minecraft:smooth_stone
fill ~55~7~15 ~55~8~15 minecraft:sandstone 3
fill ~55~14~15 ~55~16~15 minecraft:sandstone 3
fill ~55~31~15 ~57~31~17 minecraft:concrete 8
setblock ~56~6~15 minecraft:stonebrick 0
fill ~56~7~15 ~56~7~22 minecraft:carpet 7
setblock ~56~11~15 minecraft:cobblestone_wall 0
setblock ~56~17~15 minecraft:cobblestone_wall 0
fill ~58~31~15 ~63~31~17 minecraft:stained_glass 8
fill ~64~31~15 ~66~31~17 minecraft:concrete 8
fill ~67~31~15 ~72~31~17 minecraft:stained_glass 8
fill ~70~5~15 ~70~6~15 minecraft:concrete 8
fill ~70~12~15 ~70~14~15 minecraft:concrete 8
setblock ~71~5~15 minecraft:smooth_stone
setblock ~71~6~15 minecraft:double_stone_block_slab 5
fill ~71~12~15 ~73~14~15 minecraft:cobblestone_wall 0
setblock ~71~15~15 minecraft:cobblestone_wall 0
fill ~71~16~15 ~73~16~15 minecraft:cobblestone_wall 0
fill ~72~15~15 ~73~15~15 minecraft:cobblestone_wall 0
fill ~73~31~15 ~75~31~17 minecraft:concrete 8
fill ~74~7~15 ~74~10~15 minecraft:concrete 8
fill ~74~12~15 ~74~16~15 minecraft:concrete 8
setblock ~1~1~16 minecraft:stained_glass_pane 15
setblock ~1~2~16 minecraft:stained_glass_pane 7
fill ~1~3~16 ~1~5~16 minecraft:stained_glass_pane 15
fill ~1~9~16 ~1~9~18 minecraft:stained_glass_pane 15
fill ~1~10~16 ~1~10~17 minecraft:stained_glass_pane 15
setblock ~1~12~16 minecraft:stained_glass_pane 7
setblock ~1~14~16 minecraft:stained_glass_pane 7
fill ~11~30~16 ~11~30~17 minecraft:concrete 7
fill ~16~9~16 ~19~9~19 minecraft:concrete 8
fill ~29~30~16 ~29~30~17 minecraft:concrete 7
fill ~40~18~16 ~41~18~16 minecraft:smooth_stone
fill ~45~6~16 ~47~6~22 minecraft:concrete 8
fill ~46~7~16 ~55~7~23 minecraft:carpet 7
fill ~47~30~16 ~47~30~17 minecraft:concrete 7
fill ~48~3~16 ~53~6~16 minecraft:smooth_stone
setblock ~53~2~16 minecraft:smooth_stone
fill ~54~6~16 ~56~6~22 minecraft:smooth_stone
fill ~65~30~16 ~65~30~17 minecraft:concrete 7
fill ~71~5~16 ~71~5~21 minecraft:stonebrick 0
fill ~71~6~16 ~71~6~21 minecraft:stone_brick_stairs 4
fill ~71~17~16 ~74~17~16 minecraft:stone_block_slab 8
fill ~71~18~16 ~71~20~16 minecraft:double_stone_block_slab 0
fill ~71~21~16 ~71~30~16 minecraft:iron_bars
fill ~72~18~16 ~73~18~16 minecraft:stone_block_slab 0
setblock ~74~6~16 minecraft:wool 7
fill ~74~7~16 ~74~9~16 minecraft:cobblestone_wall 0
setblock ~74~10~16 minecraft:cobblestone_wall 0
fill ~74~18~16 ~74~20~16 minecraft:double_stone_block_slab 0
fill ~74~21~16 ~74~30~16 minecraft:iron_bars
fill ~75~17~16 ~75~17~96 minecraft:concrete 8
fill ~1~1~17 ~1~1~18 minecraft:stained_glass_pane 7
setblock ~1~2~17 minecraft:stained_glass_pane 15
fill ~1~3~17 ~1~3~19 minecraft:stained_glass_pane 7
fill ~1~4~17 ~1~6~17 minecraft:stained_glass_pane 7
setblock ~1~7~17 minecraft:stained_glass_pane 15
fill ~1~12~17 ~1~12~20 minecraft:stained_glass_pane 15
fill ~1~14~17 ~1~17~17 minecraft:stained_glass_pane 15
fill ~1~32~17 ~3~32~20 minecraft:concrete 8
fill ~4~32~17 ~9~32~20 minecraft:stained_glass 8
fill ~10~32~17 ~12~32~20 minecraft:concrete 8
fill ~13~32~17 ~18~32~20 minecraft:stained_glass 8
fill ~19~32~17 ~21~32~20 minecraft:concrete 8
fill ~22~32~17 ~27~32~20 minecraft:stained_glass 8
fill ~28~10~17 ~28~10~21 minecraft:stonebrick 0
fill ~28~32~17 ~30~32~20 minecraft:concrete 8
setblock ~29~9~17 minecraft:stone_block_slab 13
setblock ~29~10~17 minecraft:stone_block_slab 5
setblock ~30~9~17 minecraft:double_stone_block_slab 5
setblock ~31~8~17 minecraft:stone_block_slab 13
setblock ~31~9~17 minecraft:stone_block_slab 5
fill ~31~32~17 ~36~32~20 minecraft:stained_glass 8
setblock ~32~8~17 minecraft:double_stone_block_slab 5
setblock ~33~7~17 minecraft:stone_block_slab 13
setblock ~33~8~17 minecraft:stone_block_slab 5
setblock ~34~7~17 minecraft:double_stone_block_slab 5
setblock ~35~7~17 minecraft:stone_block_slab 5
fill ~37~32~17 ~39~32~20 minecraft:concrete 8
fill ~40~18~17 ~41~18~17 minecraft:stone_block_slab 8
fill ~40~19~17 ~41~19~17 minecraft:stone_block_slab 0
fill ~40~32~17 ~45~32~20 minecraft:stained_glass 8
fill ~46~32~17 ~48~32~20 minecraft:concrete 8
fill ~48~6~17 ~53~6~24 minecraft:smooth_stone
fill ~49~32~17 ~54~32~20 minecraft:stained_glass 8
fill ~55~32~17 ~57~32~20 minecraft:concrete 8
fill ~58~32~17 ~63~32~20 minecraft:stained_glass 8
fill ~62~5~17 ~63~5~18 minecraft:stone_block_slab 0
fill ~64~5~17 ~64~5~18 minecraft:stone_block_slab 5
fill ~64~32~17 ~66~32~20 minecraft:concrete 8
fill ~67~32~17 ~72~32~20 minecraft:stained_glass 8
fill ~72~18~17 ~73~18~17 minecraft:smooth_stone
fill ~73~32~17 ~75~32~20 minecraft:concrete 8
fill ~74~6~17 ~74~6~22 minecraft:smooth_stone
fill ~74~7~17 ~74~10~22 minecraft:concrete 4
setblock ~1~2~18 minecraft:stained_glass_pane 7
fill ~1~4~18 ~1~4~19 minecraft:stained_glass_pane 15
fill ~1~5~18 ~1~6~18 minecraft:stained_glass_pane 15
fill ~1~7~18 ~1~7~19 minecraft:stained_glass_pane 7
fill ~1~10~18 ~1~11~19 minecraft:stained_glass_pane 7
setblock ~1~13~18 minecraft:stained_glass_pane 15
setblock ~1~14~18 minecraft:stained_glass_pane 7
fill ~1~15~18 ~1~15~19 minecraft:stained_glass_pane 15
fill ~1~16~18 ~1~16~22 minecraft:stained_glass_pane 7
fill ~1~17~18 ~1~17~19 minecraft:stained_glass_pane 15
fill ~11~31~18 ~11~31~20 minecraft:concrete 7
fill ~14~1~18 ~14~4~18 minecraft:stonebrick 0
fill ~14~6~18 ~14~8~18 minecraft:cobblestone_wall 0
fill ~15~10~18 ~16~10~20 minecraft:concrete 8
fill ~15~11~18 ~21~11~20 minecraft:carpet 7
fill ~19~10~18 ~21~10~20 minecraft:concrete 8
fill ~22~10~18 ~24~10~18 minecraft:wool 7
fill ~22~11~18 ~22~12~18 minecraft:cobblestone_wall 0
setblock ~22~13~18 minecraft:cobblestone_wall 0
fill ~23~11~18 ~24~12~18 minecraft:cobblestone_wall 0
fill ~23~13~18 ~24~13~18 minecraft:cobblestone_wall 0
fill ~25~11~18 ~25~12~18 minecraft:cobblestone_wall 0
setblock ~25~13~18 minecraft:cobblestone_wall 0
fill ~28~1~18 ~28~4~18 minecraft:stonebrick 0
fill ~28~6~18 ~28~8~18 minecraft:cobblestone_wall 0
fill ~29~31~18 ~29~31~20 minecraft:concrete 7
fill ~40~19~18 ~41~19~18 minecraft:smooth_stone
fill ~47~31~18 ~47~31~20 minecraft:concrete 7
fill ~65~31~18 ~65~31~20 minecraft:concrete 7
fill ~72~18~18 ~73~18~18 minecraft:stone_block_slab 8
fill ~72~19~18 ~73~19~18 minecraft:stone_block_slab 0
fill ~1~1~19 ~1~2~19 minecraft:stained_glass_pane 15
fill ~1~5~19 ~1~6~19 minecraft:stained_glass_pane 7
fill ~1~8~19 ~1~9~19 minecraft:stained_glass_pane 7
fill ~1~13~19 ~1~13~20 minecraft:stained_glass_pane 7
fill ~1~14~19 ~1~14~21 minecraft:stained_glass_pane 15
fill ~14~1~19 ~14~8~20 minecraft:concrete 7
fill ~15~5~19 ~15~7~20 minecraft:concrete 8
fill ~15~8~19 ~15~9~20 minecraft:concrete 4
fill ~22~10~19 ~25~10~20 minecraft:concrete 8
fill ~22~11~19 ~25~11~20 minecraft:carpet 7
setblock ~27~8~19 minecraft:concrete 8
fill ~27~9~19 ~27~9~20 minecraft:concrete 4
fill ~28~1~19 ~28~8~20 minecraft:concrete 7
fill ~40~19~19 ~41~19~19 minecraft:stone_block_slab 8
fill ~40~20~19 ~41~20~19 minecraft:stone_block_slab 0
fill ~72~19~19 ~73~19~19 minecraft:smooth_stone
setblock ~1~1~20 minecraft:stained_glass_pane 7
fill ~1~2~20 ~1~3~20 minecraft:stained_glass_pane 15
fill ~1~4~20 ~1~4~25 minecraft:stained_glass_pane 7
fill ~1~5~20 ~1~5~23 minecraft:stained_glass_pane 15
setblock ~1~6~20 minecraft:stained_glass_pane 7
fill ~1~7~20 ~1~11~20 minecraft:stained_glass_pane 15
fill ~1~15~20 ~1~15~22 minecraft:stained_glass_pane 7
setblock ~1~17~20 minecraft:stained_glass_pane 7
fill ~1~33~20 ~3~33~23 minecraft:concrete 8
fill ~4~33~20 ~9~33~23 minecraft:stained_glass 8
fill ~10~33~20 ~12~33~23 minecraft:concrete 8
fill ~13~33~20 ~18~33~23 minecraft:stained_glass 8
fill ~16~5~20 ~16~7~20 minecraft:concrete 8
fill ~16~8~20 ~16~9~20 minecraft:concrete 4
fill ~17~1~20 ~17~5~20 minecraft:concrete 4
fill ~17~6~20 ~25~9~20 minecraft:concrete 13
fill ~18~1~20 ~18~4~21 minecraft:stonebrick 0
setblock ~18~5~20 minecraft:stonebrick 0
fill ~19~5~20 ~23~5~21 minecraft:stone_block_slab 13
fill ~19~33~20 ~21~33~23 minecraft:concrete 8
fill ~22~33~20 ~27~33~23 minecraft:stained_glass 8
fill ~24~1~20 ~24~5~21 minecraft:stonebrick 0
setblock ~25~1~20 minecraft:concrete 4
setblock ~25~2~20 minecraft:stonebrick 0
fill ~25~3~20 ~25~5~20 minecraft:concrete 4
fill ~26~8~20 ~27~8~20 minecraft:concrete 4
setblock ~26~9~20 minecraft:concrete 4
fill ~28~33~20 ~30~33~23 minecraft:concrete 8
fill ~31~33~20 ~36~33~23 minecraft:stained_glass 8
fill ~35~3~20 ~40~5~20 minecraft:stonebrick 0
setblock ~35~6~20 minecraft:stonebrick 0
setblock ~36~2~20 minecraft:stonebrick 0
fill ~36~6~20 ~41~6~20 minecraft:stone_brick_stairs 7
fill ~37~33~20 ~39~33~23 minecraft:concrete 8
fill ~39~20~20 ~39~22~20 minecraft:double_stone_block_slab 0
fill ~39~23~20 ~39~31~20 minecraft:iron_bars
fill ~40~20~20 ~41~20~20 minecraft:smooth_stone
fill ~40~33~20 ~45~33~23 minecraft:stained_glass 8
setblock ~41~3~20 minecraft:double_stone_block_slab 5
fill ~41~5~20 ~41~5~21 minecraft:concrete 4
fill ~42~6~20 ~44~6~20 minecraft:concrete 8
fill ~42~7~20 ~45~7~20 minecraft:carpet 7
fill ~42~20~20 ~42~22~20 minecraft:double_stone_block_slab 0
fill ~42~23~20 ~42~31~20 minecraft:iron_bars
fill ~46~33~20 ~48~33~23 minecraft:concrete 8
fill ~49~33~20 ~54~33~23 minecraft:stained_glass 8
fill ~55~33~20 ~57~33~23 minecraft:concrete 8
fill ~58~33~20 ~63~33~23 minecraft:stained_glass 8
fill ~60~4~20 ~60~4~40 minecraft:smooth_stone
setblock ~61~4~20 minecraft:stonebrick 0
setblock ~61~6~20 minecraft:stonebrick 0
fill ~62~4~20 ~63~4~40 minecraft:smooth_stone
fill ~64~33~20 ~66~33~23 minecraft:concrete 8
fill ~67~33~20 ~72~33~23 minecraft:stained_glass 8
fill ~72~19~20 ~73~19~20 minecraft:stone_block_slab 8
fill ~72~20~20 ~73~20~20 minecraft:stone_block_slab 0
fill ~73~33~20 ~75~33~23 minecraft:concrete 8
setblock ~1~1~21 minecraft:stained_glass_pane 15
fill ~1~2~21 ~1~2~28 minecraft:stained_glass_pane 7
fill ~1~3~21 ~1~3~23 minecraft:stained_glass_pane 7
fill ~1~6~21 ~1~6~24 minecraft:stained_glass_pane 15
fill ~1~7~21 ~1~7~22 minecraft:stained_glass_pane 7
setblock ~1~8~21 minecraft:stained_glass_pane 15
fill ~1~9~21 ~1~9~25 minecraft:stained_glass_pane 7
fill ~1~10~21 ~1~10~23 minecraft:stained_glass_pane 7
setblock ~1~11~21 minecraft:stained_glass_pane 15
fill ~1~12~21 ~1~12~23 minecraft:stained_glass_pane 7
setblock ~1~13~21 minecraft:stained_glass_pane 15
fill ~1~17~21 ~1~17~22 minecraft:stained_glass_pane 15
fill ~11~21~21 ~11~22~21 minecraft:double_stone_block_slab 0
fill ~11~23~21 ~11~31~21 minecraft:iron_bars
fill ~11~32~21 ~11~32~23 minecraft:concrete 7
fill ~12~21~21 ~41~21~22 minecraft:stone_block_slab 0
fill ~14~1~21 ~14~9~21 minecraft:cobblestone_wall 0
fill ~15~1~21 ~16~8~21 minecraft:concrete 7
fill ~15~9~21 ~27~9~21 minecraft:cobblestone_wall 0
fill ~15~10~21 ~27~10~21 minecraft:stonebrick 0
fill ~17~1~21 ~17~8~21 minecraft:cobblestone_wall 0
setblock ~18~5~21 minecraft:double_stone_block_slab 5
fill ~18~6~21 ~25~6~21 minecraft:cobblestone_wall 0
fill ~18~7~21 ~24~8~21 minecraft:iron_bars
setblock ~18~11~21 minecraft:cobblestone_wall 0
fill ~19~11~21 ~23~11~21 minecraft:cobblestone_wall 0
setblock ~24~11~21 minecraft:cobblestone_wall 0
fill ~25~1~21 ~25~5~21 minecraft:cobblestone_wall 0
fill ~25~7~21 ~25~8~21 minecraft:cobblestone_wall 0
fill ~26~1~21 ~27~8~21 minecraft:concrete 7
fill ~28~1~21 ~28~9~21 minecraft:cobblestone_wall 0
fill ~29~32~21 ~29~32~23 minecraft:concrete 7
fill ~35~2~21 ~36~2~33 minecraft:stone_block_slab 0
fill ~37~2~21 ~40~2~36 minecraft:smooth_stone
fill ~40~20~21 ~41~20~21 minecraft:stone_block_slab 8
setblock ~41~2~21 minecraft:concrete 4
setblock ~41~3~21 minecraft:stone_block_slab 5
setblock ~41~4~21 minecraft:concrete 4
setblock ~41~6~21 minecraft:stone_block_slab 13
setblock ~42~3~21 minecraft:double_stone_block_slab 5
fill ~42~5~21 ~42~6~21 minecraft:stonebrick 0
fill ~43~6~21 ~44~6~21 minecraft:concrete 8
fill ~43~7~21 ~45~7~21 minecraft:carpet 7
fill ~47~32~21 ~47~32~23 minecraft:concrete 7
fill ~57~6~21 ~58~6~21 minecraft:smooth_stone
fill ~57~7~21 ~58~7~21 minecraft:carpet 7
setblock ~59~6~21 minecraft:double_stone_block_slab 5
setblock ~60~5~21 minecraft:concrete 4
setblock ~60~6~21 minecraft:stone_block_slab 13
fill ~61~4~21 ~61~4~40 minecraft:smooth_stone
fill ~65~32~21 ~65~32~23 minecraft:concrete 7
fill ~70~5~21 ~70~5~23 minecraft:stonebrick 0
setblock ~70~6~21 minecraft:stone_brick_stairs 6
fill ~72~20~21 ~73~20~21 minecraft:smooth_stone
setblock ~1~1~22 minecraft:stained_glass_pane 7
fill ~1~8~22 ~1~8~26 minecraft:stained_glass_pane 7
fill ~1~11~22 ~1~11~23 minecraft:stained_glass_pane 7
fill ~1~13~22 ~1~14~22 minecraft:stained_glass_pane 7
fill ~34~1~22 ~34~1~33 minecraft:smooth_stone
fill ~41~2~22 ~42~2~36 minecraft:smooth_stone
setblock ~42~3~22 minecraft:stone_block_slab 5
fill ~42~4~22 ~42~5~22 minecraft:concrete 4
setblock ~42~6~22 minecraft:stone_block_slab 13
setblock ~43~3~22 minecraft:double_stone_block_slab 5
fill ~43~5~22 ~43~6~22 minecraft:stonebrick 0
setblock ~44~6~22 minecraft:concrete 8
fill ~44~7~22 ~45~7~22 minecraft:carpet 7
setblock ~57~6~22 minecraft:smooth_stone
setblock ~57~7~22 minecraft:carpet 7
setblock ~58~6~22 minecraft:stonebrick 0
fill ~59~2~22 ~59~2~40 minecraft:smooth_stone
fill ~59~3~22 ~59~3~34 minecraft:smooth_stone
fill ~59~4~22 ~59~5~22 minecraft:concrete 4
setblock ~59~6~22 minecraft:stone_block_slab 13
fill ~70~6~22 ~70~6~23 minecraft:stone_brick_stairs 4
fill ~71~6~22 ~71~6~40 minecraft:smooth_stone
fill ~71~7~22 ~71~7~30 minecraft:carpet 7
fill ~72~20~22 ~73~20~22 minecraft:stone_block_slab 8
fill ~72~21~22 ~73~21~22 minecraft:stone_block_slab 0
setblock ~1~1~23 minecraft:stained_glass_pane 15
fill ~1~7~23 ~1~7~26 minecraft:stained_glass_pane 15
fill ~1~13~23 ~1~14~25 minecraft:stained_glass_pane 15
fill ~1~15~23 ~1~16~24 minecraft:stained_glass_pane 15
fill ~1~17~23 ~1~17~24 minecraft:stained_glass_pane 7
fill ~1~34~23 ~3~34~26 minecraft:concrete 8
fill ~4~34~23 ~9~34~26 minecraft:stained_glass 8
fill ~10~34~23 ~12~34~26 minecraft:concrete 8
fill ~12~21~23 ~13~21~23 minecraft:smooth_stone
fill ~13~34~23 ~18~34~26 minecraft:stained_glass 8
fill ~14~21~23 ~14~23~23 minecraft:double_stone_block_slab 0
fill ~14~24~23 ~14~32~23 minecraft:iron_bars
fill ~19~34~23 ~21~34~26 minecraft:concrete 8
fill ~22~34~23 ~27~34~26 minecraft:stained_glass 8
fill ~28~34~23 ~30~34~26 minecraft:concrete 8
fill ~31~34~23 ~36~34~26 minecraft:stained_glass 8
fill ~37~34~23 ~39~34~26 minecraft:concrete 8
fill ~40~34~23 ~45~34~26 minecraft:stained_glass 8
fill ~41~21~23 ~41~22~23 minecraft:double_stone_block_slab 0
fill ~41~23~23 ~41~32~23 minecraft:iron_bars
fill ~43~2~23 ~43~2~36 minecraft:smooth_stone
setblock ~43~3~23 minecraft:stone_block_slab 5
fill ~43~4~23 ~43~5~23 minecraft:concrete 4
setblock ~43~6~23 minecraft:stone_block_slab 13
fill ~44~2~23 ~44~5~23 minecraft:stonebrick 0
setblock ~44~6~23 minecraft:stone_brick_stairs 7
setblock ~45~6~23 minecraft:stonebrick 0
fill ~46~6~23 ~47~6~23 minecraft:concrete 8
fill ~46~34~23 ~48~34~26 minecraft:concrete 8
fill ~49~34~23 ~54~34~26 minecraft:stained_glass 8
fill ~54~6~23 ~55~6~23 minecraft:smooth_stone
fill ~55~34~23 ~57~34~26 minecraft:concrete 8
setblock ~56~6~23 minecraft:stonebrick 0
fill ~57~3~23 ~57~5~23 minecraft:stonebrick 0
setblock ~57~6~23 minecraft:stone_brick_stairs 7
setblock ~58~3~23 minecraft:smooth_stone
fill ~58~4~23 ~58~5~23 minecraft:concrete 4
setblock ~58~6~23 minecraft:stone_block_slab 13
fill ~58~34~23 ~63~34~26 minecraft:stained_glass 8
fill ~59~4~23 ~59~4~36 minecraft:stone_block_slab 0
fill ~64~34~23 ~66~34~26 minecraft:concrete 8
fill ~66~4~23 ~68~4~24 minecraft:smooth_stone
fill ~67~34~23 ~72~34~26 minecraft:stained_glass 8
fill ~69~5~23 ~69~5~25 minecraft:stonebrick 0
setblock ~69~6~23 minecraft:stone_brick_stairs 6
fill ~72~21~23 ~73~21~23 minecraft:smooth_stone
fill ~73~34~23 ~75~34~26 minecraft:concrete 8
setblock ~74~6~23 minecraft:wool 7
fill ~74~7~23 ~74~9~23 minecraft:cobblestone_wall 0
setblock ~74~10~23 minecraft:cobblestone_wall 0
fill ~1~1~24 ~1~1~27 minecraft:stained_glass_pane 7
setblock ~1~3~24 minecraft:stained_glass_pane 15
fill ~1~5~24 ~1~5~25 minecraft:stained_glass_pane 7
fill ~1~10~24 ~1~11~26 minecraft:stained_glass_pane 15
setblock ~1~12~24 minecraft:stained_glass_pane 15
fill ~11~33~24 ~11~33~26 minecraft:concrete 7
fill ~12~21~24 ~13~21~24 minecraft:stone_block_slab 8
fill ~12~22~24 ~13~22~24 minecraft:stone_block_slab 0
fill ~29~33~24 ~29~33~26 minecraft:concrete 7
fill ~44~2~24 ~44~2~33 minecraft:smooth_stone
fill ~45~3~24 ~45~5~24 minecraft:stonebrick 0
setblock ~45~6~24 minecraft:stone_block_slab 13
setblock ~46~6~24 minecraft:stonebrick 0
setblock ~47~6~24 minecraft:concrete 8
fill ~47~7~24 ~54~7~24 minecraft:carpet 7
fill ~47~33~24 ~47~33~26 minecraft:concrete 7
setblock ~54~6~24 minecraft:smooth_stone
fill ~55~3~24 ~56~3~24 minecraft:stonebrick 0
setblock ~55~6~24 minecraft:stonebrick 0
fill ~56~4~24 ~56~5~24 minecraft:stonebrick 0
setblock ~56~6~24 minecraft:stone_block_slab 13
fill ~57~3~24 ~57~3~34 minecraft:smooth_stone
fill ~58~4~24 ~58~4~35 minecraft:stone_block_slab 0
fill ~65~33~24 ~65~33~26 minecraft:concrete 7
setblock ~69~6~24 minecraft:stone_brick_stairs 4
fill ~70~6~24 ~70~6~40 minecraft:smooth_stone
fill ~70~7~24 ~70~7~30 minecraft:carpet 7
fill ~72~21~24 ~73~21~24 minecraft:stone_block_slab 8
fill ~72~22~24 ~73~22~24 minecraft:stone_block_slab 0
fill ~74~6~24 ~74~6~29 minecraft:smooth_stone
fill ~74~7~24 ~74~10~29 minecraft:concrete 4
fill ~1~3~25 ~1~3~27 minecraft:stained_glass_pane 7
setblock ~1~6~25 minecraft:stained_glass_pane 7
setblock ~1~12~25 minecraft:stained_glass_pane 7
fill ~1~15~25 ~1~15~27 minecraft:stained_glass_pane 7
fill ~1~16~25 ~1~16~27 minecraft:stained_glass_pane 15
fill ~1~17~25 ~1~17~26 minecraft:stained_glass_pane 15
fill ~12~22~25 ~13~22~25 minecraft:smooth_stone
setblock ~43~1~25 minecraft:smooth_stone
fill ~45~2~25 ~45~2~33 minecraft:smooth_stone
fill ~46~3~25 ~47~5~25 minecraft:stonebrick 0
setblock ~46~6~25 minecraft:stone_block_slab 13
setblock ~47~6~25 minecraft:stone_brick_stairs 7
fill ~48~6~25 ~48~6~26 minecraft:stonebrick 0
fill ~49~6~25 ~53~6~25 minecraft:smooth_stone
fill ~49~7~25 ~53~7~25 minecraft:carpet 7
fill ~54~3~25 ~55~5~25 minecraft:stonebrick 0
setblock ~54~6~25 minecraft:stone_brick_stairs 7
setblock ~55~6~25 minecraft:stone_block_slab 13
fill ~56~3~25 ~56~3~35 minecraft:smooth_stone
fill ~66~4~25 ~67~4~40 minecraft:smooth_stone
fill ~68~5~25 ~68~5~33 minecraft:stonebrick 0
fill ~68~6~25 ~69~6~25 minecraft:stone_brick_stairs 6
fill ~72~22~25 ~73~22~25 minecraft:smooth_stone
fill ~1~4~26 ~1~4~27 minecraft:stained_glass_pane 15
fill ~1~5~26 ~1~6~26 minecraft:stained_glass_pane 15
fill ~1~9~26 ~1~9~27 minecraft:stained_glass_pane 15
setblock ~1~12~26 minecraft:stained_glass_pane 15
setblock ~1~13~26 minecraft:stained_glass_pane 7
setblock ~1~14~26 minecraft:stained_glass_pane 15
fill ~1~35~26 ~3~35~29 minecraft:concrete 8
fill ~4~35~26 ~9~35~29 minecraft:stained_glass 8
fill ~10~35~26 ~12~35~29 minecraft:concrete 8
fill ~12~22~26 ~13~22~26 minecraft:stone_block_slab 8
fill ~12~23~26 ~13~23~26 minecraft:stone_block_slab 0
fill ~13~35~26 ~18~35~29 minecraft:stained_glass 8
fill ~19~35~26 ~21~35~29 minecraft:concrete 8
fill ~22~35~26 ~27~35~29 minecraft:stained_glass 8
fill ~28~35~26 ~30~35~29 minecraft:concrete 8
fill ~31~35~26 ~36~35~29 minecraft:stained_glass 8
fill ~37~35~26 ~39~35~29 minecraft:concrete 8
fill ~40~35~26 ~45~35~29 minecraft:stained_glass 8
fill ~46~2~26 ~57~2~33 minecraft:smooth_stone
fill ~46~35~26 ~48~35~29 minecraft:concrete 8
fill ~48~3~26 ~48~5~26 minecraft:stonebrick 0
fill ~49~3~26 ~52~3~26 minecraft:stone_brick_stairs 3
fill ~49~4~26 ~52~5~26 minecraft:concrete 4
fill ~49~6~26 ~52~6~26 minecraft:stone_brick_stairs 7
fill ~49~35~26 ~54~35~29 minecraft:stained_glass 8
fill ~53~3~26 ~53~6~26 minecraft:stonebrick 0
fill ~54~3~26 ~55~3~33 minecraft:stone_block_slab 0
fill ~55~35~26 ~57~35~29 minecraft:concrete 8
fill ~58~35~26 ~63~35~29 minecraft:stained_glass 8
fill ~64~35~26 ~66~35~29 minecraft:concrete 8
fill ~67~35~26 ~72~35~29 minecraft:stained_glass 8
fill ~68~6~26 ~68~6~33 minecraft:stone_brick_stairs 4
fill ~69~6~26 ~69~6~40 minecraft:smooth_stone
fill ~69~7~26 ~69~7~30 minecraft:carpet 7
fill ~72~22~26 ~73~22~26 minecraft:stone_block_slab 8
fill ~72~23~26 ~73~23~26 minecraft:stone_block_slab 0
fill ~73~35~26 ~75~35~29 minecraft:concrete 8
setblock ~1~5~27 minecraft:stained_glass_pane 7
fill ~1~6~27 ~1~6~33 minecraft:stained_glass_pane 15
fill ~1~7~27 ~1~7~30 minecraft:stained_glass_pane 7
fill ~1~8~27 ~1~8~29 minecraft:stained_glass_pane 15
setblock ~1~10~27 minecraft:stained_glass_pane 7
fill ~1~11~27 ~1~11~28 minecraft:stained_glass_pane 15
fill ~1~12~27 ~1~12~35 minecraft:stained_glass_pane 7
setblock ~1~13~27 minecraft:stained_glass_pane 15
setblock ~1~14~27 minecraft:stained_glass_pane 7
fill ~1~17~27 ~1~17~28 minecraft:stained_glass_pane 7
fill ~11~34~27 ~11~34~29 minecraft:concrete 7
fill ~12~23~27 ~13~23~27 minecraft:smooth_stone
fill ~29~34~27 ~29~34~29 minecraft:concrete 7
fill ~47~34~27 ~47~34~29 minecraft:concrete 7
fill ~65~34~27 ~65~34~29 minecraft:concrete 7
fill ~68~4~27 ~68~4~31 minecraft:smooth_stone
fill ~72~23~27 ~73~23~27 minecraft:smooth_stone
fill ~1~1~28 ~1~1~29 minecraft:stained_glass_pane 15
setblock ~1~3~28 minecraft:stained_glass_pane 15
fill ~1~4~28 ~1~4~29 minecraft:stained_glass_pane 7
setblock ~1~5~28 minecraft:stained_glass_pane 15
fill ~1~9~28 ~1~9~29 minecraft:stained_glass_pane 7
setblock ~1~10~28 minecraft:stained_glass_pane 15
fill ~1~13~28 ~1~13~30 minecraft:stained_glass_pane 7
fill ~1~14~28 ~1~14~30 minecraft:stained_glass_pane 15
setblock ~1~15~28 minecraft:stained_glass_pane 15
setblock ~1~16~28 minecraft:stained_glass_pane 7
fill ~12~23~28 ~13~23~28 minecraft:stone_block_slab 8
fill ~12~24~28 ~13~24~28 minecraft:stone_block_slab 0
fill ~72~23~28 ~73~23~28 minecraft:stone_block_slab 8
fill ~72~24~28 ~73~24~28 minecraft:stone_block_slab 0
setblock ~1~2~29 minecraft:stained_glass_pane 15
setblock ~1~3~29 minecraft:stained_glass_pane 7
setblock ~1~5~29 minecraft:stained_glass_pane 7
fill ~1~10~29 ~1~11~29 minecraft:stained_glass_pane 7
setblock ~1~15~29 minecraft:stained_glass_pane 7
fill ~1~16~29 ~1~17~29 minecraft:stained_glass_pane 15
fill ~1~36~29 ~3~36~33 minecraft:concrete 8
fill ~4~36~29 ~9~36~33 minecraft:stained_glass 8
setblock ~9~1~29 minecraft:stone_block_slab 5
fill ~10~1~29 ~12~1~29 minecraft:stone_block_slab 0
fill ~10~36~29 ~12~36~33 minecraft:concrete 8
fill ~12~24~29 ~13~24~29 minecraft:smooth_stone
setblock ~13~1~29 minecraft:stone_block_slab 5
fill ~13~36~29 ~18~36~33 minecraft:stained_glass 8
fill ~19~36~29 ~21~36~33 minecraft:concrete 8
fill ~22~36~29 ~27~36~33 minecraft:stained_glass 8
fill ~28~36~29 ~30~36~33 minecraft:concrete 8
fill ~31~36~29 ~36~36~33 minecraft:stained_glass 8
fill ~37~36~29 ~39~36~33 minecraft:concrete 8
fill ~40~36~29 ~45~36~33 minecraft:stained_glass 8
fill ~46~36~29 ~48~36~33 minecraft:concrete 8
fill ~49~36~29 ~54~36~33 minecraft:stained_glass 8
fill ~55~36~29 ~57~36~33 minecraft:concrete 8
fill ~58~36~29 ~63~36~33 minecraft:stained_glass 8
fill ~64~36~29 ~66~36~33 minecraft:concrete 8
fill ~67~36~29 ~72~36~33 minecraft:stained_glass 8
fill ~72~24~29 ~73~24~29 minecraft:smooth_stone
fill ~73~36~29 ~75~36~33 minecraft:concrete 8
fill ~1~1~30 ~1~4~30 minecraft:stonebrick 0
setblock ~1~5~30 minecraft:stained_glass_pane 15
setblock ~1~8~30 minecraft:stained_glass_pane 7
fill ~1~9~30 ~1~11~30 minecraft:stained_glass_pane 15
fill ~1~15~30 ~1~15~34 minecraft:stained_glass_pane 15
fill ~1~16~30 ~1~16~31 minecraft:stained_glass_pane 7
setblock ~1~17~30 minecraft:stained_glass_pane 15
fill ~2~1~30 ~3~3~30 minecraft:concrete 4
fill ~2~4~30 ~3~4~30 minecraft:stone_brick_stairs 6
fill ~4~1~30 ~4~4~30 minecraft:stonebrick 0
fill ~9~1~30 ~9~1~31 minecraft:stonebrick 0
fill ~10~1~30 ~12~1~31 minecraft:smooth_stone
fill ~11~35~30 ~11~35~33 minecraft:concrete 7
fill ~12~24~30 ~13~24~30 minecraft:stone_block_slab 8
fill ~12~25~30 ~13~25~30 minecraft:stone_block_slab 0
setblock ~13~1~30 minecraft:stonebrick 0
fill ~29~35~30 ~29~35~33 minecraft:concrete 7
fill ~47~35~30 ~47~35~33 minecraft:concrete 7
fill ~65~35~30 ~65~35~33 minecraft:concrete 7
fill ~72~24~30 ~73~24~30 minecraft:stone_block_slab 8
fill ~72~25~30 ~73~25~30 minecraft:stone_block_slab 0
fill ~74~6~30 ~74~6~31 minecraft:wool 7
fill ~74~7~30 ~74~9~30 minecraft:cobblestone_wall 0
setblock ~74~10~30 minecraft:cobblestone_wall 0
fill ~1~1~31 ~3~3~38 minecraft:concrete 8
fill ~1~4~31 ~3~4~38 minecraft:stonebrick 0
setblock ~1~5~31 minecraft:stained_glass_pane 7
fill ~1~7~31 ~1~8~31 minecraft:stained_glass_pane 15
fill ~1~9~31 ~1~10~31 minecraft:stained_glass_pane 7
setblock ~1~11~31 minecraft:stained_glass_pane 15
setblock ~1~13~31 minecraft:stained_glass_pane 15
setblock ~1~14~31 minecraft:stained_glass_pane 7
setblock ~1~17~31 minecraft:stained_glass_pane 7
fill ~4~1~31 ~4~3~37 minecraft:stone 0
fill ~4~4~31 ~4~4~39 minecraft:stone_brick_stairs 5
setblock ~9~2~31 minecraft:stone_block_slab 5
fill ~10~2~31 ~12~2~31 minecraft:stone_block_slab 0
fill ~12~25~31 ~13~25~31 minecraft:smooth_stone
setblock ~13~1~31 minecraft:double_stone_block_slab 5
setblock ~13~2~31 minecraft:stone_block_slab 5
setblock ~64~5~31 minecraft:stone_block_slab 5
fill ~65~5~31 ~66~5~31 minecraft:stone_block_slab 0
setblock ~67~5~31 minecraft:cobblestone_wall 0
setblock ~67~6~31 minecraft:cobblestone_wall 0
fill ~67~7~31 ~67~16~31 minecraft:cobblestone_wall 0
setblock ~67~17~31 minecraft:cobblestone_wall 0
fill ~68~7~31 ~68~18~38 minecraft:concrete 8
fill ~69~5~31 ~69~5~40 minecraft:smooth_stone
fill ~69~7~31 ~69~7~32 minecraft:stone_block_slab 5
fill ~69~13~31 ~74~13~38 minecraft:concrete 8
fill ~69~14~31 ~73~16~31 minecraft:cobblestone_wall 0
fill ~69~17~31 ~74~17~38 minecraft:concrete 8
fill ~69~18~31 ~74~18~31 minecraft:concrete 8
fill ~70~7~31 ~72~7~32 minecraft:stone_block_slab 0
fill ~72~25~31 ~73~25~31 minecraft:smooth_stone
fill ~73~7~31 ~73~7~32 minecraft:stone_block_slab 5
fill ~74~7~31 ~74~12~35 minecraft:concrete 8
fill ~74~14~31 ~74~16~38 minecraft:concrete 8
fill ~1~5~32 ~1~5~38 minecraft:stained_glass_pane 15
setblock ~1~7~32 minecraft:stained_glass_pane 7
fill ~1~8~32 ~1~9~32 minecraft:stained_glass_pane 15
fill ~1~10~32 ~1~11~32 minecraft:stained_glass_pane 7
fill ~1~13~32 ~1~13~33 minecraft:stained_glass_pane 7
setblock ~1~14~32 minecraft:stained_glass_pane 15
fill ~1~16~32 ~1~17~32 minecraft:stained_glass_pane 15
fill ~9~1~32 ~9~1~36 minecraft:iron_bars
fill ~9~2~32 ~9~2~33 minecraft:stonebrick 0
fill ~10~1~32 ~10~2~36 minecraft:smooth_stone
fill ~11~2~32 ~12~2~33 minecraft:smooth_stone
fill ~12~1~32 ~12~1~38 minecraft:smooth_stone
fill ~12~25~32 ~13~25~32 minecraft:stone_block_slab 8
fill ~12~26~32 ~13~26~32 minecraft:stone_block_slab 0
fill ~13~1~32 ~13~1~36 minecraft:iron_bars
setblock ~13~2~32 minecraft:stonebrick 0
fill ~14~26~32 ~14~26~35 minecraft:stone_block_slab 8
setblock ~14~27~32 minecraft:double_stone_block_slab 0
fill ~14~28~32 ~14~35~32 minecraft:iron_bars
fill ~54~26~32 ~54~26~34 minecraft:stone_block_slab 8
fill ~54~27~32 ~54~28~32 minecraft:double_stone_block_slab 0
fill ~54~29~32 ~54~35~32 minecraft:iron_bars
fill ~64~5~32 ~64~5~33 minecraft:stonebrick 0
fill ~65~5~32 ~66~5~32 minecraft:smooth_stone
fill ~67~5~32 ~67~13~37 minecraft:sandstone 3
fill ~67~14~32 ~67~14~37 minecraft:concrete 4
fill ~67~15~32 ~67~17~37 minecraft:sandstone 3
fill ~67~18~32 ~67~18~37 minecraft:stone_block_slab2 6
fill ~69~14~32 ~73~16~37 minecraft:concrete 8
fill ~72~25~32 ~73~25~32 minecraft:stone_block_slab 8
fill ~72~26~32 ~73~26~32 minecraft:stone_block_slab 0
fill ~74~6~32 ~74~6~40 minecraft:smooth_stone
fill ~1~7~33 ~1~7~35 minecraft:stained_glass_pane 15
fill ~1~8~33 ~1~9~33 minecraft:stained_glass_pane 7
fill ~1~10~33 ~1~10~34 minecraft:stained_glass_pane 15
setblock ~1~11~33 minecraft:stained_glass_pane 15
fill ~1~14~33 ~1~14~34 minecraft:stained_glass_pane 7
fill ~1~16~33 ~1~17~33 minecraft:stained_glass_pane 7
fill ~1~37~33 ~3~37~37 minecraft:concrete 8
fill ~4~37~33 ~9~37~37 minecraft:stained_glass 8
setblock ~9~3~33 minecraft:stone_block_slab 5
fill ~10~3~33 ~12~3~33 minecraft:stone_block_slab 0
fill ~10~37~33 ~12~37~37 minecraft:concrete 8
fill ~11~26~33 ~12~26~33 minecraft:double_stone_block_slab 0
setblock ~11~27~33 minecraft:double_stone_block_slab 0
fill ~11~28~33 ~11~34~33 minecraft:iron_bars
setblock ~13~2~33 minecraft:double_stone_block_slab 5
setblock ~13~3~33 minecraft:stone_block_slab 5
fill ~13~26~33 ~13~26~40 minecraft:stone_block_slab 8
fill ~13~37~33 ~18~37~37 minecraft:stained_glass 8
fill ~15~26~33 ~53~26~34 minecraft:stone_block_slab 8
fill ~19~37~33 ~21~37~37 minecraft:concrete 8
fill ~22~37~33 ~27~37~37 minecraft:stained_glass 8
fill ~26~1~33 ~28~5~33 minecraft:concrete 4
fill ~28~37~33 ~30~37~37 minecraft:concrete 8
fill ~31~37~33 ~36~37~37 minecraft:stained_glass 8
setblock ~37~1~33 minecraft:smooth_stone
fill ~37~37~33 ~39~37~37 minecraft:concrete 8
fill ~40~37~33 ~45~37~37 minecraft:stained_glass 8
fill ~44~3~33 ~45~7~33 minecraft:concrete 4
fill ~46~37~33 ~48~37~37 minecraft:concrete 8
fill ~49~37~33 ~54~37~37 minecraft:stained_glass 8
fill ~52~3~33 ~53~7~33 minecraft:concrete 4
fill ~55~26~33 ~71~26~34 minecraft:stone_block_slab 8
fill ~55~37~33 ~57~37~37 minecraft:concrete 8
fill ~58~2~33 ~58~2~40 minecraft:smooth_stone
fill ~58~37~33 ~63~37~37 minecraft:stained_glass 8
setblock ~64~6~33 minecraft:stone_block_slab 5
fill ~64~37~33 ~66~37~37 minecraft:concrete 8
fill ~65~5~33 ~66~6~33 minecraft:stone_block_slab 0
fill ~67~37~33 ~72~37~37 minecraft:stained_glass 8
fill ~69~7~33 ~69~7~34 minecraft:stonebrick 0
fill ~70~7~33 ~72~7~40 minecraft:smooth_stone
fill ~72~26~33 ~73~26~33 minecraft:double_stone_block_slab 0
fill ~73~7~33 ~73~7~34 minecraft:stonebrick 0
fill ~73~37~33 ~75~37~37 minecraft:concrete 8
setblock ~74~26~33 minecraft:stone_block_slab 8
fill ~74~27~33 ~74~28~33 minecraft:double_stone_block_slab 0
fill ~74~29~33 ~74~35~33 minecraft:iron_bars
fill ~1~6~34 ~1~6~36 minecraft:stained_glass_pane 7
fill ~1~8~34 ~1~8~35 minecraft:stained_glass_pane 15
setblock ~1~9~34 minecraft:stained_glass_pane 7
setblock ~1~11~34 minecraft:stained_glass_pane 7
setblock ~1~13~34 minecraft:stained_glass_pane 15
fill ~1~16~34 ~1~16~38 minecraft:stained_glass_pane 15
setblock ~1~17~34 minecraft:stained_glass_pane 15
fill ~9~2~34 ~9~2~36 minecraft:iron_bars
fill ~9~3~34 ~9~3~35 minecraft:stonebrick 0
fill ~10~3~34 ~12~3~35 minecraft:smooth_stone
fill ~11~36~34 ~11~36~37 minecraft:concrete 7
fill ~12~2~34 ~12~2~38 minecraft:smooth_stone
fill ~12~26~34 ~12~26~40 minecraft:stone_block_slab 8
fill ~13~2~34 ~13~2~36 minecraft:iron_bars
setblock ~13~3~34 minecraft:stonebrick 0
fill ~25~1~34 ~25~4~36 minecraft:concrete 4
fill ~25~5~34 ~25~5~35 minecraft:concrete 4
fill ~26~1~34 ~27~4~34 minecraft:concrete 8
fill ~26~5~34 ~26~5~35 minecraft:concrete 8
fill ~26~6~34 ~31~6~34 minecraft:stonebrick 0
fill ~26~7~34 ~26~8~34 minecraft:cobblestone_wall 0
setblock ~26~9~34 minecraft:cobblestone_wall 0
fill ~27~5~34 ~29~5~34 minecraft:stonebrick 0
fill ~27~7~34 ~27~8~34 minecraft:cobblestone_wall 0
setblock ~27~9~34 minecraft:cobblestone_wall 0
fill ~28~1~34 ~30~2~34 minecraft:stonebrick 0
setblock ~28~3~34 minecraft:stone_brick_stairs 2
fill ~28~4~34 ~29~4~34 minecraft:stonebrick 0
fill ~28~7~34 ~28~8~34 minecraft:cobblestone_wall 0
setblock ~28~9~34 minecraft:cobblestone_wall 0
setblock ~29~3~34 minecraft:stonebrick 0
fill ~29~36~34 ~29~36~37 minecraft:concrete 7
fill ~30~3~34 ~34~3~34 minecraft:iron_bars
fill ~30~4~34 ~33~4~34 minecraft:iron_bars
fill ~30~5~34 ~32~5~34 minecraft:iron_bars
fill ~31~1~34 ~31~1~62 minecraft:concrete 8
fill ~31~2~34 ~36~2~34 minecraft:stonebrick 0
setblock ~32~1~34 minecraft:stone_block_slab 0
setblock ~32~6~34 minecraft:double_stone_block_slab 5
fill ~33~1~34 ~33~1~62 minecraft:concrete 8
setblock ~33~5~34 minecraft:stonebrick 0
setblock ~33~6~34 minecraft:stone_brick_stairs 1
setblock ~34~1~34 minecraft:stone_block_slab 0
setblock ~34~4~34 minecraft:stonebrick 0
setblock ~34~5~34 minecraft:stone_brick_stairs 1
fill ~35~1~34 ~36~1~62 minecraft:concrete 8
setblock ~35~3~34 minecraft:stonebrick 0
setblock ~35~4~34 minecraft:stone_brick_stairs 1
setblock ~36~3~34 minecraft:stone_brick_stairs 1
setblock ~37~1~34 minecraft:stone_block_slab 0
fill ~38~1~34 ~74~1~34 minecraft:concrete 8
fill ~43~3~34 ~43~7~35 minecraft:concrete 4
fill ~44~2~34 ~45~2~34 minecraft:concrete 8
fill ~44~3~34 ~44~8~34 minecraft:stonebrick 0
fill ~44~9~34 ~44~17~34 minecraft:cobblestone_wall 0
setblock ~44~18~34 minecraft:cobblestone_wall 0
fill ~45~3~34 ~45~7~34 minecraft:cobblestone_wall 0
fill ~45~8~34 ~53~8~34 minecraft:stonebrick 0
fill ~45~9~34 ~45~14~34 minecraft:concrete 13
fill ~45~15~34 ~52~15~34 minecraft:cobblestone_wall 0
fill ~45~16~34 ~52~17~34 minecraft:concrete 13
fill ~45~18~34 ~52~18~34 minecraft:cobblestone_wall 0
fill ~46~2~34 ~53~2~34 minecraft:stone_block_slab 13
fill ~46~3~34 ~51~3~34 minecraft:cobblestone_wall 0
fill ~46~4~34 ~51~6~35 minecraft:concrete 7
fill ~46~7~34 ~51~7~34 minecraft:cobblestone_wall 0
fill ~47~36~34 ~47~36~37 minecraft:concrete 7
fill ~51~9~34 ~51~14~34 minecraft:cobblestone_wall 0
fill ~52~3~34 ~52~7~34 minecraft:cobblestone_wall 0
fill ~52~9~34 ~52~14~34 minecraft:concrete 13
fill ~53~3~34 ~53~7~34 minecraft:stonebrick 0
fill ~53~9~34 ~53~17~34 minecraft:cobblestone_wall 0
setblock ~53~18~34 minecraft:cobblestone_wall 0
fill ~54~2~34 ~57~2~34 minecraft:smooth_stone
fill ~54~3~34 ~54~7~35 minecraft:concrete 4
fill ~55~3~34 ~55~3~35 minecraft:stone_block_slab 0
setblock ~58~3~34 minecraft:smooth_stone
fill ~60~2~34 ~74~2~40 minecraft:smooth_stone
fill ~64~5~34 ~64~6~34 minecraft:double_stone_block_slab 5
fill ~65~5~34 ~66~6~34 minecraft:smooth_stone
fill ~65~36~34 ~65~36~37 minecraft:concrete 7
fill ~68~4~34 ~74~4~40 minecraft:smooth_stone
fill ~68~5~34 ~68~6~40 minecraft:smooth_stone
fill ~70~5~34 ~71~5~40 minecraft:smooth_stone
fill ~72~26~34 ~73~26~34 minecraft:stone_block_slab 8
fill ~1~9~35 ~1~9~36 minecraft:stained_glass_pane 15
fill ~1~10~35 ~1~10~36 minecraft:stained_glass_pane 7
fill ~1~11~35 ~1~11~36 minecraft:stained_glass_pane 15
setblock ~1~13~35 minecraft:stained_glass_pane 7
setblock ~1~14~35 minecraft:stained_glass_pane 15
fill ~1~15~35 ~1~15~36 minecraft:stained_glass_pane 7
setblock ~1~17~35 minecraft:stained_glass_pane 7
setblock ~9~4~35 minecraft:stone_block_slab 5
fill ~10~4~35 ~12~4~35 minecraft:stone_block_slab 0
setblock ~13~3~35 minecraft:double_stone_block_slab 5
setblock ~13~4~35 minecraft:stone_block_slab 5
setblock ~14~27~35 minecraft:double_stone_block_slab 0
fill ~14~28~35 ~14~36~35 minecraft:iron_bars
setblock ~26~1~35 minecraft:concrete 8
setblock ~26~2~35 minecraft:concrete 4
setblock ~26~3~35 minecraft:concrete 8
setblock ~26~4~35 minecraft:concrete 4
fill ~26~6~35 ~26~6~37 minecraft:stonebrick 0
fill ~26~7~35 ~26~8~35 minecraft:cobblestone_wall 0
setblock ~26~9~35 minecraft:cobblestone_wall 0
fill ~27~6~35 ~32~6~37 minecraft:concrete 8
fill ~27~7~35 ~32~7~37 minecraft:carpet 7
fill ~29~0~35 ~29~0~96 minecraft:smooth_stone
fill ~29~2~35 ~36~2~37 minecraft:concrete 8
fill ~29~3~35 ~35~3~36 minecraft:concrete 8
fill ~29~4~35 ~34~4~36 minecraft:concrete 8
fill ~29~5~35 ~33~5~37 minecraft:concrete 8
fill ~30~1~35 ~30~1~61 minecraft:concrete 8
fill ~32~1~35 ~32~1~61 minecraft:concrete 8
fill ~33~6~35 ~33~6~36 minecraft:normal_stone_stairs 1
fill ~34~1~35 ~34~1~61 minecraft:concrete 8
fill ~34~5~35 ~34~5~36 minecraft:normal_stone_stairs 1
fill ~35~4~35 ~35~4~36 minecraft:normal_stone_stairs 1
fill ~36~3~35 ~36~3~36 minecraft:normal_stone_stairs 1
fill ~37~1~35 ~44~1~61 minecraft:concrete 8
fill ~44~2~35 ~44~2~62 minecraft:concrete 8
fill ~44~3~35 ~44~7~35 minecraft:cobblestone_wall 0
fill ~44~8~35 ~44~8~37 minecraft:stonebrick 0
fill ~44~9~35 ~44~14~35 minecraft:concrete 13
fill ~44~15~35 ~44~15~36 minecraft:cobblestone_wall 0
fill ~44~16~35 ~44~17~40 minecraft:concrete 13
setblock ~44~18~35 minecraft:cobblestone_wall 0
fill ~45~1~35 ~45~2~36 minecraft:stonebrick 0
fill ~45~3~35 ~53~3~35 minecraft:concrete 7
fill ~45~4~35 ~45~7~35 minecraft:concrete 7
fill ~45~8~35 ~47~8~35 minecraft:concrete 8
fill ~45~15~35 ~52~15~35 minecraft:concrete 13
fill ~45~17~35 ~53~17~36 minecraft:concrete 13
fill ~46~1~35 ~53~1~62 minecraft:concrete 8
fill ~46~2~35 ~47~2~61 minecraft:concrete 8
fill ~46~7~35 ~53~7~35 minecraft:concrete 7
fill ~46~9~35 ~46~14~35 minecraft:concrete 13
fill ~47~9~35 ~50~9~40 minecraft:carpet 7
fill ~48~2~35 ~53~2~40 minecraft:smooth_stone
fill ~48~8~35 ~52~8~35 minecraft:smooth_stone
fill ~51~9~35 ~51~14~35 minecraft:concrete 13
fill ~52~4~35 ~53~6~35 minecraft:concrete 7
fill ~53~8~35 ~53~8~36 minecraft:stonebrick 0
fill ~53~9~35 ~53~14~35 minecraft:concrete 13
fill ~53~15~35 ~53~15~36 minecraft:cobblestone_wall 0
fill ~53~16~35 ~53~16~40 minecraft:concrete 13
setblock ~53~18~35 minecraft:cobblestone_wall 0
fill ~54~1~35 ~54~2~35 minecraft:concrete 4
fill ~55~1~35 ~74~1~44 minecraft:concrete 8
fill ~55~2~35 ~57~2~40 minecraft:smooth_stone
fill ~57~3~35 ~58~3~35 minecraft:stone_block_slab 0
setblock ~57~26~35 minecraft:stone_block_slab 8
fill ~57~27~35 ~57~28~35 minecraft:double_stone_block_slab 0
fill ~57~29~35 ~57~36~35 minecraft:iron_bars
fill ~59~3~35 ~59~3~37 minecraft:stonebrick 0
fill ~64~5~35 ~64~6~38 minecraft:stonebrick 0
setblock ~64~7~35 minecraft:stone_block_slab 5
fill ~65~5~35 ~65~7~35 minecraft:stone_block_slab 0
fill ~66~5~35 ~66~5~40 minecraft:smooth_stone
fill ~66~6~35 ~66~7~35 minecraft:stone_block_slab 0
fill ~69~7~35 ~69~7~40 minecraft:smooth_stone
fill ~69~8~35 ~69~8~37 minecraft:stone_block_slab 5
fill ~70~8~35 ~72~8~37 minecraft:stone_block_slab 0
setblock ~71~26~35 minecraft:stone_block_slab 8
fill ~71~27~35 ~71~28~35 minecraft:double_stone_block_slab 0
fill ~71~29~35 ~71~36~35 minecraft:iron_bars
fill ~73~7~35 ~73~7~40 minecraft:smooth_stone
fill ~73~8~35 ~73~8~37 minecraft:stone_block_slab 5
fill ~1~7~36 ~1~8~36 minecraft:stained_glass_pane 7
fill ~1~12~36 ~1~12~38 minecraft:stained_glass_pane 15
setblock ~1~13~36 minecraft:stained_glass_pane 15
fill ~1~14~36 ~1~14~38 minecraft:stained_glass_pane 7
setblock ~1~17~36 minecraft:stained_glass_pane 15
setblock ~9~3~36 minecraft:iron_bars
fill ~9~4~36 ~9~4~37 minecraft:stonebrick 0
fill ~10~3~36 ~10~4~36 minecraft:smooth_stone
fill ~11~4~36 ~12~4~39 minecraft:smooth_stone
fill ~12~3~36 ~12~3~38 minecraft:smooth_stone
setblock ~13~3~36 minecraft:iron_bars
fill ~13~4~36 ~13~4~37 minecraft:stonebrick 0
fill ~26~1~36 ~26~5~37 minecraft:stonebrick 0
fill ~26~7~36 ~26~8~36 minecraft:cobblestone_wall 0
setblock ~26~9~36 minecraft:cobblestone_wall 0
fill ~29~1~36 ~29~1~37 minecraft:concrete 8
fill ~44~3~36 ~44~7~36 minecraft:stonebrick 0
fill ~44~9~36 ~44~14~36 minecraft:cobblestone_wall 0
setblock ~44~18~36 minecraft:cobblestone_wall 0
fill ~45~3~36 ~47~7~60 minecraft:concrete 8
fill ~45~8~36 ~45~8~61 minecraft:concrete 8
fill ~45~9~36 ~45~14~36 minecraft:concrete 13
fill ~45~15~36 ~52~15~36 minecraft:cobblestone_wall 0
fill ~45~16~36 ~52~16~36 minecraft:concrete 13
fill ~45~18~36 ~52~18~36 minecraft:cobblestone_wall 0
setblock ~46~8~36 minecraft:wool 7
fill ~46~9~36 ~46~14~36 minecraft:cobblestone_wall 0
fill ~47~8~36 ~47~8~61 minecraft:concrete 8
fill ~48~3~36 ~54~7~40 minecraft:smooth_stone
fill ~48~8~36 ~50~8~40 minecraft:smooth_stone
setblock ~51~8~36 minecraft:wool 7
fill ~51~9~36 ~51~14~36 minecraft:cobblestone_wall 0
fill ~52~8~36 ~52~8~40 minecraft:smooth_stone
fill ~52~9~36 ~52~14~36 minecraft:concrete 13
fill ~53~9~36 ~53~14~36 minecraft:cobblestone_wall 0
setblock ~53~18~36 minecraft:cobblestone_wall 0
fill ~54~1~36 ~54~1~60 minecraft:concrete 8
fill ~54~2~36 ~54~2~40 minecraft:smooth_stone
fill ~54~8~36 ~58~8~36 minecraft:stone_brick_stairs 6
fill ~55~3~36 ~58~7~36 minecraft:stonebrick 0
fill ~64~7~36 ~64~7~38 minecraft:stonebrick 0
fill ~65~5~36 ~65~7~36 minecraft:smooth_stone
fill ~66~6~36 ~66~6~40 minecraft:smooth_stone
setblock ~66~7~36 minecraft:smooth_stone
fill ~74~7~36 ~74~7~40 minecraft:smooth_stone
fill ~74~8~36 ~74~12~37 minecraft:concrete 8
fill ~1~6~37 ~1~7~37 minecraft:stained_glass_pane 15
fill ~1~8~37 ~1~8~38 minecraft:stained_glass_pane 7
setblock ~1~9~37 minecraft:stained_glass_pane 7
setblock ~1~10~37 minecraft:stained_glass_pane 15
setblock ~1~11~37 minecraft:stained_glass_pane 7
setblock ~1~13~37 minecraft:stained_glass_pane 7
fill ~1~15~37 ~1~15~38 minecraft:stained_glass_pane 15
setblock ~1~17~37 minecraft:stained_glass_pane 7
fill ~1~38~37 ~3~38~42 minecraft:concrete 8
fill ~4~38~37 ~9~38~42 minecraft:stained_glass 8
fill ~9~1~37 ~10~3~37 minecraft:stonebrick 0
fill ~10~4~37 ~10~4~39 minecraft:smooth_stone
fill ~10~38~37 ~12~38~42 minecraft:concrete 8
fill ~11~1~37 ~11~3~38 minecraft:monster_egg 0
fill ~13~1~37 ~13~3~37 minecraft:stonebrick 0
fill ~13~38~37 ~18~38~42 minecraft:stained_glass 8
fill ~19~38~37 ~21~38~42 minecraft:concrete 8
fill ~22~38~37 ~27~38~42 minecraft:stained_glass 8
fill ~27~1~37 ~28~1~42 minecraft:concrete 8
fill ~27~2~37 ~28~5~37 minecraft:concrete 8
fill ~28~38~37 ~30~38~42 minecraft:concrete 8
fill ~29~3~37 ~33~4~37 minecraft:concrete 8
fill ~31~38~37 ~36~38~42 minecraft:stained_glass 8
setblock ~33~6~37 minecraft:stonebrick 0
fill ~34~3~37 ~43~5~37 minecraft:stonebrick 0
fill ~34~6~37 ~43~6~37 minecraft:stone_brick_stairs 6
fill ~37~2~37 ~43~2~59 minecraft:concrete 8
fill ~37~7~37 ~38~7~37 minecraft:stone_block_slab 5
fill ~37~38~37 ~39~38~42 minecraft:concrete 8
fill ~39~7~37 ~43~7~37 minecraft:double_stone_block_slab 5
fill ~40~38~37 ~45~38~42 minecraft:stained_glass 8
fill ~41~8~37 ~42~8~37 minecraft:stone_block_slab 5
setblock ~43~8~37 minecraft:double_stone_block_slab 5
fill ~44~3~37 ~44~6~59 minecraft:concrete 8
setblock ~44~7~37 minecraft:stonebrick 0
fill ~44~15~37 ~44~15~40 minecraft:cobblestone_wall 0
fill ~44~18~37 ~44~18~40 minecraft:cobblestone_wall 0
fill ~45~1~37 ~45~2~59 minecraft:concrete 8
fill ~45~9~37 ~46~9~41 minecraft:carpet 7
fill ~46~8~37 ~46~8~59 minecraft:concrete 8
fill ~46~38~37 ~48~38~59 minecraft:concrete 8
fill ~49~38~37 ~54~38~42 minecraft:stained_glass 8
fill ~51~8~37 ~51~8~40 minecraft:smooth_stone
fill ~51~9~37 ~57~9~40 minecraft:carpet 7
fill ~53~8~37 ~57~8~40 minecraft:smooth_stone
fill ~53~15~37 ~53~15~40 minecraft:cobblestone_wall 0
fill ~53~17~37 ~53~17~40 minecraft:concrete 13
fill ~53~18~37 ~53~18~40 minecraft:cobblestone_wall 0
fill ~55~3~37 ~58~5~40 minecraft:smooth_stone
fill ~55~38~37 ~57~38~42 minecraft:concrete 8
setblock ~58~8~37 minecraft:double_stone_block_slab 5
fill ~58~38~37 ~63~38~42 minecraft:stained_glass 8
fill ~59~4~37 ~59~7~37 minecraft:stonebrick 0
setblock ~59~8~37 minecraft:stone_brick_stairs 5
setblock ~60~3~37 minecraft:stonebrick 0
fill ~60~5~37 ~62~7~37 minecraft:stonebrick 0
fill ~60~8~37 ~62~8~37 minecraft:stone_brick_stairs 6
setblock ~64~8~37 minecraft:stone_block_slab 5
fill ~64~38~37 ~66~38~42 minecraft:concrete 8
fill ~65~5~37 ~65~8~37 minecraft:stone_block_slab 0
fill ~66~7~37 ~66~8~37 minecraft:stone_block_slab 0
fill ~67~38~37 ~72~38~42 minecraft:stained_glass 8
fill ~73~38~37 ~75~38~42 minecraft:concrete 8
fill ~1~6~38 ~1~7~38 minecraft:stained_glass_pane 7
setblock ~1~9~38 minecraft:stained_glass_pane 15
setblock ~1~10~38 minecraft:stained_glass_pane 7
setblock ~1~11~38 minecraft:stained_glass_pane 15
setblock ~1~13~38 minecraft:stained_glass_pane 15
setblock ~1~17~38 minecraft:stained_glass_pane 15
fill ~4~1~38 ~4~3~39 minecraft:stonebrick 0
fill ~9~1~38 ~9~1~39 minecraft:stone 0
fill ~9~2~38 ~10~3~38 minecraft:monster_egg 0
setblock ~9~4~38 minecraft:stone_brick_stairs 4
setblock ~10~1~38 minecraft:monster_egg 0
fill ~11~37~38 ~11~37~42 minecraft:concrete 7
fill ~13~1~38 ~13~3~38 minecraft:monster_egg 0
setblock ~13~4~38 minecraft:stone_brick_stairs 5
fill ~26~1~38 ~26~1~41 minecraft:iron_bars
fill ~26~2~38 ~26~2~40 minecraft:iron_bars
fill ~26~3~38 ~26~3~39 minecraft:iron_bars
setblock ~26~4~38 minecraft:iron_bars
setblock ~26~5~38 minecraft:stonebrick 0
setblock ~26~6~38 minecraft:stone_brick_stairs 3
fill ~27~2~38 ~27~2~41 minecraft:concrete 8
fill ~27~3~38 ~27~3~40 minecraft:concrete 8
fill ~27~4~38 ~28~4~39 minecraft:concrete 8
fill ~27~5~38 ~28~5~38 minecraft:concrete 8
fill ~27~6~38 ~28~6~38 minecraft:normal_stone_stairs 3
fill ~29~1~38 ~29~5~58 minecraft:stonebrick 0
fill ~29~6~38 ~29~6~44 minecraft:stone_brick_stairs 4
fill ~29~37~38 ~29~37~42 minecraft:concrete 7
fill ~30~2~38 ~36~2~61 minecraft:concrete 8
fill ~30~3~38 ~43~5~58 minecraft:concrete 8
fill ~30~6~38 ~43~6~40 minecraft:concrete 8
fill ~30~7~38 ~36~7~40 minecraft:carpet 7
fill ~37~7~38 ~38~7~39 minecraft:stone_block_slab 0
fill ~39~7~38 ~40~7~39 minecraft:double_stone_block_slab 0
fill ~41~7~38 ~41~7~40 minecraft:monster_egg 0
fill ~41~8~38 ~42~8~40 minecraft:stone_block_slab 0
fill ~42~7~38 ~44~7~40 minecraft:concrete 8
fill ~43~8~38 ~43~8~39 minecraft:stone_block_slab 8
fill ~44~8~38 ~44~8~40 minecraft:concrete 8
fill ~44~9~38 ~44~9~40 minecraft:carpet 7
fill ~47~37~38 ~47~37~58 minecraft:concrete 7
fill ~55~6~38 ~59~7~40 minecraft:smooth_stone
fill ~58~8~38 ~61~8~40 minecraft:smooth_stone
fill ~58~9~38 ~61~9~40 minecraft:carpet 7
fill ~59~3~38 ~60~3~40 minecraft:smooth_stone
fill ~59~4~38 ~59~5~40 minecraft:smooth_stone
fill ~60~5~38 ~60~7~38 minecraft:concrete 15
fill ~61~3~38 ~74~3~38 minecraft:stonebrick 0
fill ~61~5~38 ~61~7~40 minecraft:smooth_stone
setblock ~62~5~38 minecraft:concrete 15
fill ~62~6~38 ~62~6~40 minecraft:smooth_stone
setblock ~62~7~38 minecraft:concrete 15
setblock ~62~8~38 minecraft:stonebrick 0
fill ~63~5~38 ~63~7~38 minecraft:stonebrick 0
fill ~63~8~38 ~64~8~38 minecraft:stone_brick_stairs 6
fill ~65~5~38 ~65~8~40 minecraft:smooth_stone
fill ~65~37~38 ~65~37~42 minecraft:concrete 7
fill ~66~7~38 ~67~7~40 minecraft:smooth_stone
fill ~66~8~38 ~66~8~40 minecraft:smooth_stone
fill ~67~5~38 ~67~6~40 minecraft:smooth_stone
setblock ~67~8~38 minecraft:stonebrick 0
fill ~67~9~38 ~67~16~38 minecraft:cobblestone_wall 0
setblock ~67~17~38 minecraft:cobblestone_wall 0
fill ~69~8~38 ~69~8~39 minecraft:stonebrick 0
fill ~69~14~38 ~73~16~38 minecraft:cobblestone_wall 0
fill ~69~18~38 ~74~18~38 minecraft:concrete 8
fill ~70~8~38 ~72~8~40 minecraft:smooth_stone
setblock ~73~8~38 minecraft:stonebrick 0
fill ~74~8~38 ~74~8~40 minecraft:smooth_stone
fill ~74~9~38 ~74~12~38 minecraft:concrete 8
fill ~1~1~39 ~3~2~39 minecraft:sandstone 3
fill ~1~3~39 ~1~3~43 minecraft:concrete 13
fill ~1~4~39 ~3~13~39 minecraft:sandstone 3
fill ~1~14~39 ~3~14~39 minecraft:concrete 4
fill ~1~15~39 ~3~17~39 minecraft:sandstone 3
fill ~1~18~39 ~3~18~39 minecraft:stone_block_slab2 6
fill ~2~3~39 ~3~3~39 minecraft:sandstone 3
setblock ~4~9~39 minecraft:stone_block_slab 11
setblock ~4~10~39 minecraft:cobblestone_wall 0
setblock ~4~11~39 minecraft:stone_block_slab 3
setblock ~4~15~39 minecraft:stone_block_slab 11
setblock ~4~16~39 minecraft:cobblestone_wall 0
setblock ~4~17~39 minecraft:stone_block_slab 3
fill ~5~1~39 ~8~1~39 minecraft:stone_brick_stairs 6
fill ~5~2~39 ~18~2~39 minecraft:sandstone 3
fill ~5~3~39 ~8~3~39 minecraft:concrete 13
fill ~5~4~39 ~8~13~39 minecraft:sandstone 3
fill ~5~14~39 ~18~14~39 minecraft:concrete 4
fill ~5~15~39 ~18~17~39 minecraft:sandstone 3
fill ~5~18~39 ~18~18~39 minecraft:stone_block_slab2 6
fill ~9~3~39 ~12~3~39 minecraft:sandstone 3
setblock ~9~4~39 minecraft:stonebrick 0
fill ~9~8~39 ~18~13~39 minecraft:sandstone 3
fill ~10~1~39 ~18~1~39 minecraft:sandstone 3
fill ~13~3~39 ~18~3~39 minecraft:concrete 13
setblock ~13~4~39 minecraft:stonebrick 0
fill ~14~4~39 ~18~7~39 minecraft:sandstone 3
setblock ~19~9~39 minecraft:stone_block_slab 11
setblock ~19~10~39 minecraft:cobblestone_wall 0
setblock ~19~11~39 minecraft:stone_block_slab 3
setblock ~19~15~39 minecraft:stone_block_slab 11
setblock ~19~16~39 minecraft:cobblestone_wall 0
setblock ~19~17~39 minecraft:stone_block_slab 3
setblock ~26~4~39 minecraft:stonebrick 0
setblock ~26~5~39 minecraft:stone_brick_stairs 3
fill ~27~5~39 ~28~5~39 minecraft:normal_stone_stairs 3
fill ~28~2~39 ~28~2~41 minecraft:concrete 8
fill ~28~3~39 ~28~3~40 minecraft:concrete 8
fill ~60~5~39 ~60~7~40 minecraft:smooth_stone
fill ~61~3~39 ~74~3~40 minecraft:smooth_stone
fill ~62~5~39 ~64~5~40 minecraft:smooth_stone
fill ~62~7~39 ~64~8~40 minecraft:smooth_stone
fill ~62~9~39 ~74~9~40 minecraft:carpet 7
fill ~63~6~39 ~64~6~40 minecraft:smooth_stone
fill ~67~8~39 ~68~8~40 minecraft:smooth_stone
fill ~68~7~39 ~68~7~40 minecraft:smooth_stone
fill ~73~8~39 ~73~8~40 minecraft:smooth_stone
fill ~1~1~40 ~1~2~43 minecraft:sandstone 3
fill ~1~4~40 ~1~13~43 minecraft:sandstone 3
fill ~1~14~40 ~1~14~43 minecraft:concrete 4
fill ~1~15~40 ~1~17~43 minecraft:sandstone 3
fill ~1~18~40 ~1~18~43 minecraft:stone_block_slab2 6
fill ~2~1~40 ~3~17~56 minecraft:concrete 8
fill ~4~1~40 ~8~1~56 minecraft:stone 0
fill ~4~2~40 ~19~4~40 minecraft:concrete 8
fill ~4~5~40 ~4~17~56 minecraft:concrete 8
fill ~5~5~40 ~7~5~56 minecraft:carpet 7
fill ~5~9~40 ~18~9~56 minecraft:concrete 8
fill ~5~10~40 ~8~17~56 minecraft:concrete 8
fill ~9~1~40 ~19~1~44 minecraft:concrete 8
fill ~9~12~40 ~18~12~56 minecraft:concrete 8
fill ~9~17~40 ~18~17~56 minecraft:concrete 8
fill ~16~14~40 ~17~14~40 minecraft:concrete 4
fill ~17~16~40 ~18~16~56 minecraft:concrete 8
fill ~18~13~40 ~18~15~56 minecraft:concrete 8
fill ~19~8~40 ~19~13~40 minecraft:sandstone 3
setblock ~19~14~40 minecraft:concrete 4
fill ~19~15~40 ~19~17~40 minecraft:sandstone 3
setblock ~19~18~40 minecraft:stone_block_slab2 6
setblock ~20~9~40 minecraft:stone_block_slab 11
setblock ~20~10~40 minecraft:cobblestone_wall 0
setblock ~20~11~40 minecraft:stone_block_slab 3
setblock ~20~15~40 minecraft:stone_block_slab 11
setblock ~20~16~40 minecraft:cobblestone_wall 0
setblock ~20~17~40 minecraft:stone_block_slab 3
setblock ~26~3~40 minecraft:stonebrick 0
setblock ~26~4~40 minecraft:stone_brick_stairs 3
fill ~27~4~40 ~28~4~40 minecraft:normal_stone_stairs 3
fill ~37~7~40 ~39~9~40 minecraft:concrete 4
setblock ~40~7~40 minecraft:double_stone_block_slab 0
setblock ~43~8~40 minecraft:double_stone_block_slab 0
setblock ~69~8~40 minecraft:smooth_stone
fill ~4~2~41 ~4~4~56 minecraft:concrete 8
fill ~5~4~41 ~19~4~45 minecraft:concrete 8
fill ~6~2~41 ~19~3~44 minecraft:concrete 8
fill ~7~26~41 ~18~26~55 minecraft:concrete 8
fill ~7~27~41 ~11~30~55 minecraft:concrete 8
fill ~9~10~41 ~19~11~55 minecraft:concrete 8
fill ~9~13~41 ~17~15~55 minecraft:concrete 8
fill ~9~16~41 ~16~16~55 minecraft:concrete 8
fill ~12~27~41 ~13~27~41 minecraft:stone_block_slab 0
fill ~12~29~41 ~13~29~41 minecraft:stone_block_slab 8
fill ~12~30~41 ~18~30~55 minecraft:concrete 8
fill ~14~27~41 ~18~29~55 minecraft:concrete 8
fill ~19~9~41 ~19~9~55 minecraft:concrete 8
fill ~19~12~41 ~19~17~55 minecraft:concrete 8
fill ~20~1~41 ~20~2~45 minecraft:sandstone 3
fill ~20~3~41 ~20~3~45 minecraft:concrete 13
fill ~20~4~41 ~20~13~44 minecraft:sandstone 3
fill ~20~14~41 ~20~14~55 minecraft:concrete 4
fill ~20~15~41 ~20~17~55 minecraft:sandstone 3
fill ~20~18~41 ~20~18~55 minecraft:stone_block_slab2 6
setblock ~26~2~41 minecraft:stonebrick 0
setblock ~26~3~41 minecraft:stone_brick_stairs 3
fill ~27~3~41 ~28~3~41 minecraft:normal_stone_stairs 3
fill ~30~6~41 ~37~6~46 minecraft:concrete 8
fill ~30~7~41 ~35~7~41 minecraft:carpet 7
fill ~36~7~41 ~36~9~43 minecraft:concrete 4
fill ~37~7~41 ~43~8~46 minecraft:concrete 13
setblock ~37~9~41 minecraft:concrete 4
setblock ~37~10~41 minecraft:cobblestone_wall 0
setblock ~37~11~41 minecraft:cobblestone_wall 0
fill ~37~12~41 ~37~22~41 minecraft:cobblestone_wall 0
fill ~37~23~41 ~66~23~55 minecraft:carpet 7
fill ~38~9~41 ~43~10~46 minecraft:concrete 13
fill ~38~11~41 ~43~11~41 minecraft:cobblestone_wall 0
fill ~38~12~41 ~43~21~41 minecraft:concrete 13
fill ~38~22~41 ~65~22~41 minecraft:cobblestone_wall 0
fill ~44~7~41 ~44~7~58 minecraft:concrete 8
setblock ~44~8~41 minecraft:wool 7
fill ~44~9~41 ~44~12~41 minecraft:cobblestone_wall 0
fill ~44~13~41 ~48~13~41 minecraft:cobblestone_wall 0
setblock ~44~14~41 minecraft:cobblestone_wall 0
fill ~44~15~41 ~44~17~41 minecraft:cobblestone_wall 0
setblock ~44~18~41 minecraft:cobblestone_wall 0
fill ~44~19~41 ~44~20~41 minecraft:cobblestone_wall 0
fill ~44~21~41 ~65~21~41 minecraft:concrete 13
fill ~45~14~41 ~52~20~41 minecraft:concrete 13
setblock ~47~9~41 minecraft:carpet 7
fill ~48~2~41 ~74~2~44 minecraft:concrete 8
fill ~48~3~41 ~59~7~55 minecraft:concrete 8
setblock ~48~8~41 minecraft:wool 7
fill ~48~9~41 ~48~12~41 minecraft:cobblestone_wall 0
fill ~49~9~41 ~52~13~41 minecraft:concrete 13
fill ~51~8~41 ~52~8~55 minecraft:concrete 8
setblock ~53~8~41 minecraft:wool 7
fill ~53~9~41 ~53~14~41 minecraft:cobblestone_wall 0
fill ~53~15~41 ~53~17~41 minecraft:cobblestone_wall 0
setblock ~53~18~41 minecraft:cobblestone_wall 0
fill ~53~19~41 ~53~20~41 minecraft:cobblestone_wall 0
fill ~54~9~41 ~65~14~41 minecraft:concrete 13
fill ~54~15~41 ~65~15~41 minecraft:cobblestone_wall 0
fill ~54~16~41 ~65~20~41 minecraft:concrete 13
fill ~56~8~41 ~56~8~55 minecraft:concrete 8
fill ~60~3~41 ~60~3~55 minecraft:stonebrick 0
fill ~60~4~41 ~74~7~55 minecraft:concrete 8
fill ~61~3~41 ~74~3~44 minecraft:concrete 8
setblock ~65~8~41 minecraft:concrete 8
setblock ~66~8~41 minecraft:wool 7
fill ~66~9~41 ~66~22~41 minecraft:cobblestone_wall 0
fill ~67~8~41 ~70~8~55 minecraft:concrete 8
fill ~67~9~41 ~70~9~57 minecraft:carpet 7
setblock ~71~8~41 minecraft:wool 7
fill ~71~9~41 ~71~14~41 minecraft:cobblestone_wall 0
setblock ~71~15~41 minecraft:cobblestone_wall 0
fill ~72~8~41 ~72~15~42 minecraft:concrete 8
fill ~73~9~41 ~74~15~41 minecraft:concrete 8
setblock ~74~8~41 minecraft:concrete 8
fill ~1~39~42 ~3~39~54 minecraft:concrete 8
fill ~4~39~42 ~9~39~47 minecraft:stained_glass 8
fill ~8~18~42 ~17~25~54 minecraft:concrete 8
fill ~10~39~42 ~12~39~54 minecraft:concrete 8
fill ~12~27~42 ~13~28~42 minecraft:water 8
fill ~12~29~42 ~13~29~42 minecraft:water 0
fill ~13~39~42 ~18~39~47 minecraft:stained_glass 8
fill ~19~39~42 ~21~39~54 minecraft:concrete 8
fill ~22~39~42 ~27~39~47 minecraft:stained_glass 8
setblock ~26~1~42 minecraft:stonebrick 0
setblock ~26~2~42 minecraft:stone_brick_stairs 3
fill ~27~2~42 ~28~2~42 minecraft:normal_stone_stairs 3
fill ~28~39~42 ~30~39~54 minecraft:concrete 8
fill ~31~7~42 ~35~7~46 minecraft:carpet 7
fill ~31~39~42 ~36~39~47 minecraft:stained_glass 8
fill ~37~9~42 ~37~10~47 minecraft:concrete 13
fill ~37~11~42 ~37~14~46 minecraft:concrete 13
fill ~37~15~42 ~37~15~46 minecraft:cobblestone_wall 0
fill ~37~16~42 ~37~21~54 minecraft:iron_bars
fill ~37~22~42 ~37~22~54 minecraft:cobblestone_wall 0
fill ~37~39~42 ~39~39~54 minecraft:concrete 8
fill ~38~11~42 ~38~14~47 minecraft:concrete 7
fill ~38~15~42 ~65~15~54 minecraft:concrete 8
fill ~38~16~42 ~43~20~54 minecraft:concrete 8
fill ~38~21~42 ~39~22~54 minecraft:concrete 8
fill ~39~11~42 ~44~13~54 minecraft:concrete 8
fill ~40~21~42 ~45~22~47 minecraft:stained_glass 8
fill ~40~39~42 ~45~39~47 minecraft:stained_glass 8
setblock ~42~14~42 minecraft:concrete 8
fill ~44~8~42 ~44~10~43 minecraft:concrete 8
setblock ~44~14~42 minecraft:concrete 8
setblock ~44~16~42 minecraft:concrete 13
fill ~44~17~42 ~65~20~54 minecraft:concrete 8
fill ~45~13~42 ~65~13~54 minecraft:concrete 8
fill ~45~16~42 ~65~16~54 minecraft:concrete 8
fill ~46~21~42 ~48~22~54 minecraft:concrete 8
fill ~46~39~42 ~48~39~54 minecraft:concrete 8
fill ~48~8~42 ~50~12~43 minecraft:concrete 8
fill ~48~14~42 ~65~14~42 minecraft:concrete 8
fill ~49~21~42 ~54~22~47 minecraft:stained_glass 8
fill ~49~39~42 ~54~39~47 minecraft:stained_glass 8
fill ~51~9~42 ~53~12~54 minecraft:concrete 8
fill ~53~8~42 ~53~8~54 minecraft:concrete 8
fill ~54~10~42 ~65~12~54 minecraft:concrete 8
fill ~55~21~42 ~57~22~54 minecraft:concrete 8
fill ~55~39~42 ~57~39~54 minecraft:concrete 8
fill ~56~9~42 ~56~9~54 minecraft:concrete 8
fill ~58~21~42 ~63~22~47 minecraft:stained_glass 8
fill ~58~39~42 ~63~39~47 minecraft:stained_glass 8
fill ~64~21~42 ~65~22~54 minecraft:concrete 8
fill ~64~39~42 ~66~39~54 minecraft:concrete 8
fill ~65~9~42 ~65~9~54 minecraft:concrete 8
setblock ~66~8~42 minecraft:concrete 8
fill ~66~9~42 ~66~21~54 minecraft:concrete 13
fill ~66~22~42 ~66~22~47 minecraft:cobblestone_wall 0
fill ~67~39~42 ~72~39~47 minecraft:stained_glass 8
fill ~71~8~42 ~71~8~54 minecraft:concrete 8
fill ~71~9~42 ~71~13~54 minecraft:sandstone 3
fill ~71~14~42 ~71~14~54 minecraft:concrete 4
fill ~71~15~42 ~71~15~54 minecraft:sandstone 3
fill ~71~16~42 ~71~16~54 minecraft:stone_block_slab2 6
fill ~73~9~42 ~73~15~42 minecraft:concrete 8
fill ~73~39~42 ~75~39~54 minecraft:concrete 8
fill ~74~15~42 ~74~15~55 minecraft:concrete 8
fill ~8~5~43 ~8~8~43 minecraft:cobblestone_wall 0
fill ~9~5~43 ~15~8~43 minecraft:concrete 13
fill ~11~38~43 ~11~38~53 minecraft:concrete 7
fill ~12~27~43 ~13~29~53 minecraft:concrete 8
fill ~16~5~43 ~16~8~43 minecraft:cobblestone_wall 0
setblock ~26~1~43 minecraft:stone_brick_stairs 3
fill ~27~1~43 ~28~1~43 minecraft:normal_stone_stairs 3
fill ~29~38~43 ~29~38~53 minecraft:concrete 7
fill ~30~7~43 ~30~7~53 minecraft:carpet 7
fill ~44~16~43 ~44~16~53 minecraft:concrete 8
fill ~50~14~43 ~53~14~54 minecraft:concrete 8
fill ~54~8~43 ~55~9~53 minecraft:concrete 8
fill ~57~8~43 ~65~8~53 minecraft:concrete 8
fill ~57~9~43 ~64~9~53 minecraft:concrete 8
setblock ~64~14~43 minecraft:concrete 8
fill ~65~38~43 ~65~38~53 minecraft:concrete 7
fill ~72~9~43 ~72~15~43 minecraft:concrete 8
fill ~73~15~43 ~73~15~55 minecraft:concrete 8
setblock ~1~3~44 minecraft:stone_block_slab 11
setblock ~1~4~44 minecraft:cobblestone_wall 0
setblock ~1~5~44 minecraft:stone_block_slab 3
setblock ~1~9~44 minecraft:stone_block_slab 11
setblock ~1~10~44 minecraft:cobblestone_wall 0
setblock ~1~11~44 minecraft:stone_block_slab 3
setblock ~1~15~44 minecraft:stone_block_slab 11
setblock ~1~16~44 minecraft:cobblestone_wall 0
setblock ~1~17~44 minecraft:stone_block_slab 3
fill ~2~0~44 ~2~0~49 minecraft:concrete 8
fill ~3~0~44 ~28~0~96 minecraft:smooth_stone
fill ~8~5~44 ~8~8~45 minecraft:concrete 13
fill ~9~5~44 ~15~5~52 minecraft:carpet 7
fill ~16~5~44 ~16~8~52 minecraft:concrete 8
fill ~36~7~44 ~36~7~46 minecraft:carpet 7
setblock ~44~8~44 minecraft:wool 14
fill ~44~9~44 ~44~10~54 minecraft:concrete 8
fill ~48~8~44 ~50~8~44 minecraft:wool 14
fill ~48~9~44 ~50~12~54 minecraft:concrete 8
fill ~72~14~44 ~72~15~47 minecraft:concrete 8
fill ~1~0~45 ~1~0~51 minecraft:concrete 8
fill ~1~1~45 ~1~2~51 minecraft:sandstone 3
fill ~1~3~45 ~1~3~51 minecraft:concrete 13
fill ~1~4~45 ~1~13~51 minecraft:sandstone 3
fill ~1~14~45 ~1~14~51 minecraft:concrete 4
fill ~1~15~45 ~1~17~51 minecraft:sandstone 3
fill ~1~18~45 ~1~18~51 minecraft:stone_block_slab2 6
fill ~6~2~45 ~9~3~45 minecraft:concrete 8
setblock ~9~1~45 minecraft:concrete 8
fill ~10~1~45 ~19~3~45 minecraft:stone 0
fill ~20~4~45 ~21~4~45 minecraft:double_stone_block_slab 5
fill ~20~8~45 ~20~13~55 minecraft:sandstone 3
fill ~22~4~45 ~23~4~45 minecraft:stone_block_slab 13
fill ~22~5~45 ~23~5~45 minecraft:stone_block_slab 5
fill ~24~5~45 ~25~5~45 minecraft:double_stone_block_slab 5
fill ~26~5~45 ~27~5~45 minecraft:stone_block_slab 13
fill ~26~6~45 ~27~6~45 minecraft:stone_block_slab 5
fill ~28~6~45 ~29~6~45 minecraft:double_stone_block_slab 5
fill ~44~8~45 ~44~8~51 minecraft:concrete 8
fill ~48~2~45 ~69~2~55 minecraft:concrete 8
fill ~48~8~45 ~49~8~51 minecraft:concrete 8
fill ~50~8~45 ~50~8~52 minecraft:wool 14
fill ~55~1~45 ~69~1~62 minecraft:concrete 8
fill ~61~3~45 ~69~3~55 minecraft:concrete 8
fill ~66~8~45 ~66~8~51 minecraft:concrete 8
fill ~71~1~45 ~74~1~62 minecraft:concrete 8
fill ~71~2~45 ~74~3~55 minecraft:concrete 8
fill ~5~2~46 ~8~3~50 minecraft:concrete 8
fill ~5~4~46 ~7~4~56 minecraft:concrete 8
setblock ~8~4~46 minecraft:wool 7
fill ~8~5~46 ~8~8~46 minecraft:cobblestone_wall 0
fill ~9~1~46 ~15~3~46 minecraft:stone 0
fill ~9~4~46 ~19~4~56 minecraft:concrete 8
fill ~19~1~46 ~19~2~47 minecraft:sandstone 3
fill ~19~3~46 ~19~3~50 minecraft:concrete 13
fill ~20~4~46 ~21~4~50 minecraft:double_stone_block_slab 0
fill ~22~4~46 ~23~4~50 minecraft:stone_block_slab 8
fill ~22~5~46 ~23~5~50 minecraft:stone_block_slab 0
fill ~24~5~46 ~25~5~50 minecraft:smooth_stone
fill ~26~5~46 ~27~5~50 minecraft:stone_block_slab 8
fill ~26~6~46 ~27~6~50 minecraft:stone_block_slab 0
fill ~28~6~46 ~29~6~50 minecraft:smooth_stone
fill ~29~7~46 ~29~7~50 minecraft:carpet 7
fill ~44~14~46 ~48~14~50 minecraft:concrete 8
fill ~70~1~46 ~70~3~50 minecraft:concrete 8
fill ~8~4~47 ~8~4~49 minecraft:concrete 8
fill ~8~5~47 ~8~5~49 minecraft:carpet 7
fill ~30~6~47 ~30~6~61 minecraft:concrete 8
setblock ~31~6~47 minecraft:wool 7
fill ~31~7~47 ~31~15~47 minecraft:cobblestone_wall 0
fill ~31~16~47 ~36~16~49 minecraft:carpet 7
fill ~32~6~47 ~35~6~58 minecraft:concrete 8
fill ~32~7~47 ~37~8~47 minecraft:concrete 13
fill ~32~9~47 ~36~14~47 minecraft:concrete 13
fill ~32~15~47 ~36~15~47 minecraft:cobblestone_wall 0
setblock ~36~6~47 minecraft:wool 7
fill ~37~6~47 ~43~6~49 minecraft:concrete 8
fill ~37~11~47 ~37~14~47 minecraft:cobblestone_wall 0
fill ~37~15~47 ~37~15~49 minecraft:cobblestone_wall 0
fill ~38~8~47 ~41~10~49 minecraft:concrete 8
fill ~42~8~47 ~42~8~49 minecraft:wool 14
fill ~42~9~47 ~43~10~49 minecraft:concrete 8
fill ~43~8~47 ~43~8~49 minecraft:concrete 8
fill ~4~39~48 ~9~39~48 minecraft:concrete 8
fill ~13~39~48 ~18~39~48 minecraft:concrete 8
fill ~20~1~48 ~20~2~48 minecraft:sandstone 3
setblock ~20~3~48 minecraft:concrete 13
fill ~22~39~48 ~27~39~48 minecraft:concrete 8
setblock ~31~6~48 minecraft:concrete 8
fill ~31~7~48 ~31~14~48 minecraft:concrete 7
setblock ~31~15~48 minecraft:cobblestone_wall 0
fill ~31~39~48 ~36~39~48 minecraft:concrete 8
fill ~32~7~48 ~37~11~48 minecraft:concrete 8
fill ~32~12~48 ~36~15~48 minecraft:concrete 8
setblock ~36~6~48 minecraft:concrete 8
fill ~37~12~48 ~37~14~48 minecraft:concrete 13
fill ~38~11~48 ~38~13~48 minecraft:concrete 8
fill ~40~21~48 ~45~22~48 minecraft:concrete 8
fill ~40~39~48 ~45~39~48 minecraft:concrete 8
setblock ~49~14~48 minecraft:concrete 8
fill ~49~21~48 ~54~22~48 minecraft:concrete 8
fill ~49~39~48 ~54~39~48 minecraft:concrete 8
fill ~58~21~48 ~63~22~48 minecraft:concrete 8
fill ~58~39~48 ~63~39~48 minecraft:concrete 8
setblock ~66~22~48 minecraft:cobblestone_wall 0
fill ~67~39~48 ~72~39~48 minecraft:concrete 8
fill ~72~15~48 ~72~15~55 minecraft:concrete 8
fill ~4~39~49 ~9~39~54 minecraft:stained_glass 8
fill ~13~39~49 ~18~39~54 minecraft:stained_glass 8
fill ~19~1~49 ~19~2~50 minecraft:sandstone 3
fill ~22~39~49 ~27~39~54 minecraft:stained_glass 8
setblock ~31~6~49 minecraft:wool 7
fill ~31~7~49 ~31~15~49 minecraft:cobblestone_wall 0
fill ~31~39~49 ~36~39~54 minecraft:stained_glass 8
fill ~32~7~49 ~37~10~49 minecraft:concrete 13
fill ~32~11~49 ~36~14~49 minecraft:concrete 13
fill ~32~15~49 ~36~15~49 minecraft:cobblestone_wall 0
setblock ~36~6~49 minecraft:wool 7
fill ~37~11~49 ~37~14~49 minecraft:cobblestone_wall 0
fill ~38~11~49 ~38~14~54 minecraft:concrete 7
fill ~40~21~49 ~45~22~54 minecraft:stained_glass 8
fill ~40~39~49 ~45~39~54 minecraft:stained_glass 8
fill ~49~21~49 ~54~22~54 minecraft:stained_glass 8
fill ~49~39~49 ~54~39~54 minecraft:stained_glass 8
fill ~58~21~49 ~63~22~54 minecraft:stained_glass 8
fill ~58~39~49 ~63~39~54 minecraft:stained_glass 8
fill ~66~22~49 ~66~22~54 minecraft:cobblestone_wall 0
fill ~67~39~49 ~72~39~54 minecraft:stained_glass 8
fill ~72~14~49 ~72~14~55 minecraft:concrete 8
fill ~2~0~50 ~2~0~96 minecraft:smooth_stone
setblock ~8~4~50 minecraft:wool 7
