fill ~43~60~7 ~43~60~8 minecraft:concrete 14
fill ~43~61~7 ~44~61~7 minecraft:red_glazed_terracotta 3
fill ~44~49~7 ~44~49~9 minecraft:concrete 14
setblock ~44~59~7 minecraft:red_glazed_terracotta 3
fill ~44~60~7 ~45~60~7 minecraft:stained_glass 14
setblock ~44~62~7 minecraft:red_glazed_terracotta 3
fill ~45~48~7 ~47~49~7 minecraft:stained_glass 14
setblock ~45~50~7 minecraft:red_glazed_terracotta 3
fill ~45~58~7 ~45~58~8 minecraft:red_glazed_terracotta 3
fill ~45~59~7 ~46~59~7 minecraft:stained_glass 14
fill ~45~61~7 ~45~61~9 minecraft:stained_glass 14
fill ~46~47~7 ~47~47~7 minecraft:stained_glass 14
fill ~46~50~7 ~50~50~7 minecraft:stained_glass 14
fill ~46~57~7 ~47~57~8 minecraft:stained_glass 14
fill ~46~58~7 ~46~58~8 minecraft:concrete 14
fill ~46~60~7 ~46~60~8 minecraft:concrete 14
setblock ~47~46~7 minecraft:concrete 14
setblock ~47~51~7 minecraft:stained_glass 14
fill ~47~56~7 ~47~56~8 minecraft:stained_glass 14
fill ~47~58~7 ~47~59~7 minecraft:red_glazed_terracotta 3
fill ~47~60~7 ~47~60~8 minecraft:stained_glass 14
fill ~48~45~7 ~50~45~7 minecraft:stained_glass 14
setblock ~48~46~7 minecraft:red_glazed_terracotta 3
fill ~48~47~7 ~48~48~7 minecraft:concrete 14
setblock ~48~49~7 minecraft:red_glazed_terracotta 3
setblock ~48~51~7 minecraft:red_glazed_terracotta 3
fill ~48~52~7 ~48~55~8 minecraft:stained_glass 14
setblock ~48~56~7 minecraft:red_glazed_terracotta 3
setblock ~48~57~7 minecraft:concrete 14
fill ~48~58~7 ~49~59~8 minecraft:stained_glass 14
fill ~48~60~7 ~49~60~7 minecraft:red_glazed_terracotta 3
setblock ~49~44~7 minecraft:red_glazed_terracotta 3
fill ~49~46~7 ~50~47~7 minecraft:stained_glass 14
setblock ~49~48~7 minecraft:concrete 14
fill ~49~49~7 ~50~49~7 minecraft:stained_glass 14
setblock ~49~51~7 minecraft:concrete 14
fill ~49~52~7 ~50~52~7 minecraft:red_glazed_terracotta 3
fill ~49~53~7 ~50~53~9 minecraft:stained_glass 14
fill ~49~54~7 ~49~54~8 minecraft:red_glazed_terracotta 3
fill ~49~55~7 ~49~55~8 minecraft:stained_glass 14
fill ~49~56~7 ~50~57~7 minecraft:stained_glass 14
fill ~50~43~7 ~51~44~7 minecraft:concrete 14
fill ~50~48~7 ~52~48~8 minecraft:stained_glass 14
setblock ~50~51~7 minecraft:stained_glass 14
fill ~50~54~7 ~52~54~7 minecraft:stained_glass 14
setblock ~50~55~7 minecraft:red_glazed_terracotta 3
fill ~50~58~7 ~50~59~7 minecraft:red_glazed_terracotta 3
fill ~50~60~7 ~50~61~9 minecraft:stained_glass 14
fill ~50~62~7 ~50~62~9 minecraft:concrete 14
fill ~51~45~7 ~52~45~7 minecraft:red_glazed_terracotta 3
fill ~51~46~7 ~51~47~7 minecraft:red_glazed_terracotta 3
setblock ~51~49~7 minecraft:concrete 14
fill ~51~50~7 ~51~51~7 minecraft:red_glazed_terracotta 3
fill ~51~52~7 ~52~52~7 minecraft:concrete 14
setblock ~51~53~7 minecraft:red_glazed_terracotta 3
fill ~51~55~7 ~52~55~7 minecraft:stained_glass 14
fill ~51~56~7 ~51~57~7 minecraft:concrete 14
fill ~51~58~7 ~52~59~7 minecraft:stained_glass 14
setblock ~51~60~7 minecraft:concrete 14
fill ~51~61~7 ~52~61~7 minecraft:stained_glass 14
fill ~51~62~7 ~51~63~7 minecraft:stained_glass 14
fill ~52~43~7 ~52~43~8 minecraft:stained_glass 14
setblock ~52~44~7 minecraft:stained_glass 14
fill ~52~46~7 ~52~46~8 minecraft:stained_glass 14
setblock ~52~47~7 minecraft:stained_glass 14
fill ~52~49~7 ~52~49~8 minecraft:stained_glass 14
fill ~52~50~7 ~52~50~8 minecraft:concrete 14
fill ~52~51~7 ~55~51~7 minecraft:stained_glass 14
fill ~52~53~7 ~55~53~7 minecraft:stained_glass 14
setblock ~52~56~7 minecraft:stained_glass 14
fill ~52~60~7 ~54~60~7 minecraft:stained_glass 14
setblock ~52~62~7 minecraft:red_glazed_terracotta 3
setblock ~52~63~7 minecraft:stained_glass 14
setblock ~53~49~7 minecraft:concrete 14
fill ~53~50~7 ~57~50~7 minecraft:stained_glass 14
setblock ~53~52~7 minecraft:stained_glass 14
setblock ~53~54~7 minecraft:concrete 14
setblock ~53~55~7 minecraft:red_glazed_terracotta 3
fill ~53~61~7 ~53~61~8 minecraft:red_glazed_terracotta 3
fill ~53~62~7 ~53~62~8 minecraft:stained_glass 14
setblock ~53~63~7 minecraft:concrete 14
setblock ~54~49~7 minecraft:red_glazed_terracotta 3
setblock ~54~52~7 minecraft:concrete 14
setblock ~54~54~7 minecraft:red_glazed_terracotta 3
setblock ~54~61~7 minecraft:stained_glass 14
fill ~54~62~7 ~55~62~7 minecraft:red_glazed_terracotta 3
setblock ~54~63~7 minecraft:red_glazed_terracotta 3
setblock ~55~52~7 minecraft:red_glazed_terracotta 3
fill ~55~54~7 ~56~54~7 minecraft:stained_glass 14
fill ~55~61~7 ~55~61~9 minecraft:concrete 14
setblock ~55~63~7 minecraft:stained_glass 14
setblock ~56~51~7 minecraft:concrete 14
fill ~56~52~7 ~59~52~7 minecraft:stained_glass 14
setblock ~56~53~7 minecraft:concrete 14
fill ~56~61~7 ~57~61~7 minecraft:stained_glass 14
setblock ~56~62~7 minecraft:stained_glass 14
setblock ~56~63~7 minecraft:red_glazed_terracotta 3
fill ~57~51~7 ~59~51~7 minecraft:stained_glass 14
fill ~57~53~7 ~58~53~7 minecraft:stained_glass 14
setblock ~57~54~7 minecraft:red_glazed_terracotta 3
fill ~57~62~7 ~57~62~8 minecraft:red_glazed_terracotta 3
setblock ~58~50~7 minecraft:red_glazed_terracotta 3
setblock ~58~54~7 minecraft:concrete 14
setblock ~58~61~7 minecraft:red_glazed_terracotta 3
fill ~58~62~7 ~60~62~7 minecraft:stained_glass 14
fill ~59~50~7 ~59~50~8 minecraft:concrete 14
setblock ~59~53~7 minecraft:concrete 14
fill ~59~54~7 ~60~54~7 minecraft:stained_glass 14
fill ~59~60~7 ~60~60~8 minecraft:stained_glass 14
setblock ~59~61~7 minecraft:stained_glass 14
fill ~60~50~7 ~60~50~8 minecraft:red_glazed_terracotta 3
fill ~60~51~7 ~60~52~7 minecraft:red_glazed_terracotta 3
fill ~60~53~7 ~60~53~8 minecraft:stained_glass 14
setblock ~60~61~7 minecraft:red_glazed_terracotta 3
setblock ~61~50~7 minecraft:concrete 14
setblock ~61~51~7 minecraft:stained_glass 14
fill ~61~52~7 ~62~52~7 minecraft:red_glazed_terracotta 3
fill ~61~53~7 ~63~53~7 minecraft:concrete 14
fill ~61~54~7 ~61~55~7 minecraft:red_glazed_terracotta 3
setblock ~61~59~7 minecraft:red_glazed_terracotta 3
setblock ~61~60~7 minecraft:concrete 14
fill ~61~61~7 ~62~61~7 minecraft:stained_glass 14
fill ~61~62~7 ~62~62~7 minecraft:red_glazed_terracotta 3
fill ~62~49~7 ~62~50~7 minecraft:stained_glass 14
fill ~62~51~7 ~62~51~8 minecraft:red_glazed_terracotta 3
fill ~62~54~7 ~62~54~10 minecraft:stained_glass 14
fill ~62~55~7 ~63~56~7 minecraft:red_glazed_terracotta 3
fill ~62~57~7 ~62~57~10 minecraft:stained_glass 14
fill ~62~58~7 ~63~58~7 minecraft:concrete 14
setblock ~62~59~7 minecraft:stained_glass 14
setblock ~62~60~7 minecraft:red_glazed_terracotta 3
fill ~63~49~7 ~64~49~7 minecraft:concrete 14
fill ~63~50~7 ~63~50~9 minecraft:red_glazed_terracotta 3
fill ~63~51~7 ~63~52~7 minecraft:concrete 14
setblock ~63~54~7 minecraft:red_glazed_terracotta 3
setblock ~63~57~7 minecraft:red_glazed_terracotta 3
setblock ~63~59~7 minecraft:red_glazed_terracotta 3
setblock ~63~60~7 minecraft:stained_glass 14
setblock ~63~61~7 minecraft:red_glazed_terracotta 3
setblock ~64~50~7 minecraft:concrete 14
fill ~64~51~7 ~65~52~7 minecraft:stained_glass 14
fill ~64~53~7 ~64~54~8 minecraft:stained_glass 14
fill ~64~55~7 ~66~55~7 minecraft:stained_glass 14
setblock ~64~56~7 minecraft:red_glazed_terracotta 3
setblock ~64~57~7 minecraft:concrete 14
setblock ~64~58~7 minecraft:stained_glass 14
fill ~64~59~7 ~64~60~7 minecraft:concrete 14
fill ~65~49~7 ~65~49~8 minecraft:stained_glass 14
fill ~65~50~7 ~66~50~7 minecraft:red_glazed_terracotta 3
fill ~65~53~7 ~65~53~9 minecraft:red_glazed_terracotta 3
setblock ~65~54~7 minecraft:stained_glass 14
setblock ~65~56~7 minecraft:concrete 14
fill ~65~57~7 ~66~57~7 minecraft:stained_glass 14
setblock ~65~58~7 minecraft:concrete 14
fill ~65~59~7 ~67~59~8 minecraft:stained_glass 14
fill ~65~60~7 ~65~60~10 minecraft:stained_glass 14
setblock ~66~49~7 minecraft:concrete 14
setblock ~66~51~7 minecraft:concrete 14
fill ~66~52~7 ~66~52~9 minecraft:stained_glass 14
setblock ~66~56~7 minecraft:stained_glass 14
setblock ~66~58~7 minecraft:red_glazed_terracotta 3
setblock ~67~51~7 minecraft:stained_glass 14
setblock ~67~57~7 minecraft:red_glazed_terracotta 3
setblock ~67~58~7 minecraft:concrete 14
fill ~36~55~8 ~36~55~9 minecraft:stained_glass 14
setblock ~36~56~8 minecraft:concrete 14
fill ~36~59~8 ~37~59~8 minecraft:red_glazed_terracotta 3
fill ~37~51~8 ~37~52~8 minecraft:red_glazed_terracotta 3
fill ~37~53~8 ~37~54~8 minecraft:stained_glass 14
fill ~37~55~8 ~37~55~9 minecraft:red_glazed_terracotta 3
fill ~37~58~8 ~37~58~11 minecraft:stained_glass 14
setblock ~37~60~8 minecraft:stained_glass 14
setblock ~37~61~8 minecraft:concrete 14
setblock ~37~62~8 minecraft:stained_glass 14
setblock ~37~63~8 minecraft:concrete 14
setblock ~38~49~8 minecraft:red_glazed_terracotta 3
fill ~38~50~8 ~39~50~8 minecraft:stained_glass 14
fill ~38~51~8 ~38~51~9 minecraft:stained_glass 14
fill ~38~52~8 ~38~52~9 minecraft:concrete 14
fill ~38~53~8 ~38~54~8 minecraft:red_glazed_terracotta 3
setblock ~38~60~8 minecraft:concrete 14
fill ~38~61~8 ~39~61~9 minecraft:stained_glass 14
fill ~38~62~8 ~38~63~8 minecraft:red_glazed_terracotta 3
fill ~39~47~8 ~40~47~8 minecraft:stained_glass 14
setblock ~39~48~8 minecraft:red_glazed_terracotta 3
setblock ~39~49~8 minecraft:concrete 14
fill ~39~51~8 ~39~51~11 minecraft:red_glazed_terracotta 3
fill ~39~52~8 ~40~52~8 minecraft:stained_glass 14
setblock ~39~53~8 minecraft:stained_glass 14
setblock ~39~60~8 minecraft:red_glazed_terracotta 3
fill ~39~62~8 ~39~63~10 minecraft:stained_glass 14
fill ~40~48~8 ~41~48~8 minecraft:stained_glass 14
fill ~40~49~8 ~40~49~9 minecraft:red_glazed_terracotta 3
fill ~40~50~8 ~41~50~8 minecraft:concrete 14
setblock ~40~51~8 minecraft:stained_glass 14
fill ~40~60~8 ~40~60~9 minecraft:stained_glass 14
fill ~40~61~8 ~40~62~8 minecraft:red_glazed_terracotta 3
fill ~40~63~8 ~41~63~8 minecraft:concrete 14
fill ~41~47~8 ~41~47~9 minecraft:red_glazed_terracotta 3
fill ~41~49~8 ~42~49~8 minecraft:stained_glass 14
fill ~41~51~8 ~41~51~9 minecraft:red_glazed_terracotta 3
setblock ~41~52~8 minecraft:red_glazed_terracotta 3
setblock ~41~60~8 minecraft:concrete 14
fill ~41~61~8 ~41~61~11 minecraft:stained_glass 14
fill ~41~62~8 ~44~62~8 minecraft:stained_glass 14
fill ~41~64~8 ~41~64~10 minecraft:concrete 14
setblock ~42~47~8 minecraft:concrete 14
fill ~42~48~8 ~43~48~8 minecraft:red_glazed_terracotta 3
fill ~42~50~8 ~43~50~8 minecraft:red_glazed_terracotta 3
fill ~42~51~8 ~43~51~8 minecraft:concrete 14
fill ~42~60~8 ~42~60~9 minecraft:red_glazed_terracotta 3
setblock ~42~61~8 minecraft:concrete 14
fill ~42~63~8 ~42~63~9 minecraft:red_glazed_terracotta 3
setblock ~42~64~8 minecraft:red_glazed_terracotta 3
fill ~43~47~8 ~45~47~8 minecraft:stained_glass 14
setblock ~43~49~8 minecraft:concrete 14
fill ~43~59~8 ~45~59~8 minecraft:stained_glass 14
fill ~43~61~8 ~44~61~8 minecraft:stained_glass 14
fill ~43~63~8 ~44~64~8 minecraft:stained_glass 14
setblock ~43~65~8 minecraft:stained_glass 14
fill ~44~46~8 ~46~46~8 minecraft:stained_glass 14
fill ~44~48~8 ~45~48~8 minecraft:stained_glass 14
fill ~44~50~8 ~44~51~8 minecraft:stained_glass 14
setblock ~44~58~8 minecraft:red_glazed_terracotta 3
setblock ~44~60~8 minecraft:red_glazed_terracotta 3
setblock ~44~65~8 minecraft:red_glazed_terracotta 3
fill ~45~49~8 ~45~49~9 minecraft:red_glazed_terracotta 3
fill ~45~50~8 ~45~50~9 minecraft:concrete 14
setblock ~45~51~8 minecraft:concrete 14
setblock ~45~57~8 minecraft:concrete 14
setblock ~45~60~8 minecraft:stained_glass 14
setblock ~45~62~8 minecraft:red_glazed_terracotta 3
fill ~45~63~8 ~46~63~9 minecraft:concrete 14
setblock ~45~64~8 minecraft:concrete 14
setblock ~45~65~8 minecraft:stained_glass 14
setblock ~45~66~8 minecraft:concrete 14
fill ~45~67~8 ~50~67~8 minecraft:stained_glass 14
fill ~46~45~8 ~48~45~8 minecraft:stained_glass 14
fill ~46~47~8 ~46~49~8 minecraft:concrete 14
fill ~46~50~8 ~47~50~8 minecraft:stained_glass 14
setblock ~46~51~8 minecraft:stained_glass 14
setblock ~46~56~8 minecraft:stained_glass 14
setblock ~46~59~8 minecraft:concrete 14
setblock ~46~61~8 minecraft:red_glazed_terracotta 3
setblock ~46~64~8 minecraft:red_glazed_terracotta 3
setblock ~46~65~8 minecraft:concrete 14
fill ~46~66~8 ~48~66~9 minecraft:stained_glass 14
setblock ~47~46~8 minecraft:red_glazed_terracotta 3
fill ~47~47~8 ~48~47~8 minecraft:stained_glass 14
fill ~47~48~8 ~47~49~8 minecraft:stained_glass 14
setblock ~47~51~8 minecraft:red_glazed_terracotta 3
setblock ~47~55~8 minecraft:stained_glass 14
fill ~47~58~8 ~47~59~8 minecraft:stained_glass 14
fill ~47~64~8 ~49~64~9 minecraft:stained_glass 14
fill ~47~65~8 ~47~65~9 minecraft:red_glazed_terracotta 3
fill ~48~43~8 ~48~44~9 minecraft:concrete 14
fill ~48~46~8 ~48~46~10 minecraft:stained_glass 14
setblock ~48~48~8 minecraft:red_glazed_terracotta 3
setblock ~48~49~8 minecraft:stained_glass 14
fill ~48~50~8 ~48~51~8 minecraft:concrete 14
fill ~48~56~8 ~48~56~10 minecraft:stained_glass 14
fill ~48~57~8 ~49~57~8 minecraft:stained_glass 14
setblock ~48~60~8 minecraft:red_glazed_terracotta 3
fill ~48~65~8 ~49~65~8 minecraft:stained_glass 14
setblock ~49~38~8 minecraft:red_glazed_terracotta 3
setblock ~49~39~8 minecraft:concrete 14
fill ~49~40~8 ~53~40~8 minecraft:stained_glass 14
fill ~49~41~8 ~49~41~9 minecraft:stained_glass 14
fill ~49~42~8 ~50~44~8 minecraft:stained_glass 14
setblock ~49~45~8 minecraft:red_glazed_terracotta 3
fill ~49~46~8 ~49~46~9 minecraft:concrete 14
fill ~49~47~8 ~52~47~8 minecraft:concrete 14
setblock ~49~48~8 minecraft:stained_glass 14
fill ~49~49~8 ~50~49~8 minecraft:red_glazed_terracotta 3
fill ~49~50~8 ~51~50~8 minecraft:stained_glass 14
fill ~49~51~8 ~49~51~9 minecraft:stained_glass 14
setblock ~49~52~8 minecraft:concrete 14
setblock ~49~56~8 minecraft:concrete 14
fill ~49~60~8 ~49~60~10 minecraft:stained_glass 14
setblock ~49~61~8 minecraft:red_glazed_terracotta 3
fill ~49~63~8 ~50~63~8 minecraft:red_glazed_terracotta 3
setblock ~49~66~8 minecraft:concrete 14
setblock ~50~38~8 minecraft:concrete 14
fill ~50~39~8 ~50~39~10 minecraft:red_glazed_terracotta 3
setblock ~50~41~8 minecraft:red_glazed_terracotta 3
setblock ~50~45~8 minecraft:concrete 14
setblock ~50~46~8 minecraft:red_glazed_terracotta 3
fill ~50~51~8 ~51~51~8 minecraft:concrete 14
setblock ~50~52~8 minecraft:red_glazed_terracotta 3
fill ~50~56~8 ~51~56~8 minecraft:red_glazed_terracotta 3
setblock ~50~57~8 minecraft:concrete 14
fill ~50~58~8 ~51~58~8 minecraft:stained_glass 14
setblock ~50~59~8 minecraft:concrete 14
setblock ~50~64~8 minecraft:red_glazed_terracotta 3
fill ~50~65~8 ~50~65~9 minecraft:concrete 14
fill ~50~66~8 ~51~66~10 minecraft:stained_glass 14
setblock ~51~37~8 minecraft:red_glazed_terracotta 3
fill ~51~38~8 ~52~39~8 minecraft:stained_glass 14
setblock ~51~41~8 minecraft:concrete 14
setblock ~51~42~8 minecraft:red_glazed_terracotta 3
fill ~51~43~8 ~51~45~10 minecraft:stained_glass 14
fill ~51~46~8 ~51~46~9 minecraft:stained_glass 14
fill ~51~49~8 ~51~49~9 minecraft:stained_glass 14
fill ~51~57~8 ~52~57~8 minecraft:stained_glass 14
fill ~51~59~8 ~53~59~9 minecraft:stained_glass 14
fill ~51~60~8 ~51~61~10 minecraft:stained_glass 14
fill ~51~62~8 ~51~62~9 minecraft:concrete 14
fill ~51~63~8 ~51~64~8 minecraft:stained_glass 14
setblock ~51~65~8 minecraft:red_glazed_terracotta 3
fill ~52~37~8 ~53~37~9 minecraft:stained_glass 14
fill ~52~41~8 ~53~41~8 minecraft:stained_glass 14
fill ~52~42~8 ~52~42~9 minecraft:stained_glass 14
fill ~52~44~8 ~52~44~10 minecraft:red_glazed_terracotta 3
setblock ~52~45~8 minecraft:stained_glass 14
setblock ~52~55~8 minecraft:red_glazed_terracotta 3
fill ~52~56~8 ~52~56~9 minecraft:concrete 14
setblock ~52~58~8 minecraft:red_glazed_terracotta 3
fill ~52~60~8 ~52~60~10 minecraft:red_glazed_terracotta 3
setblock ~52~61~8 minecraft:red_glazed_terracotta 3
fill ~52~62~8 ~52~62~9 minecraft:stained_glass 14
fill ~52~63~8 ~52~64~8 minecraft:red_glazed_terracotta 3
setblock ~52~65~8 minecraft:stained_glass 14
setblock ~53~38~8 minecraft:red_glazed_terracotta 3
fill ~53~39~8 ~55~39~8 minecraft:stained_glass 14
setblock ~53~42~8 minecraft:concrete 14
fill ~53~43~8 ~53~44~9 minecraft:stained_glass 14
setblock ~53~45~8 minecraft:concrete 14
fill ~53~48~8 ~53~49~9 minecraft:stained_glass 14
setblock ~53~50~8 minecraft:concrete 14
fill ~53~54~8 ~53~55~8 minecraft:stained_glass 14
fill ~53~60~8 ~53~60~9 minecraft:stained_glass 14
fill ~53~63~8 ~53~63~9 minecraft:stained_glass 14
fill ~53~64~8 ~53~65~9 minecraft:red_glazed_terracotta 3
setblock ~54~37~8 minecraft:concrete 14
setblock ~54~38~8 minecraft:stained_glass 14
setblock ~54~40~8 minecraft:red_glazed_terracotta 3
fill ~54~41~8 ~54~41~9 minecraft:concrete 14
setblock ~54~42~8 minecraft:stained_glass 14
fill ~54~43~8 ~54~43~9 minecraft:red_glazed_terracotta 3
fill ~54~49~8 ~54~49~9 minecraft:stained_glass 14
setblock ~54~50~8 minecraft:stained_glass 14
setblock ~54~53~8 minecraft:stained_glass 14
setblock ~54~54~8 minecraft:concrete 14
fill ~54~60~8 ~54~61~8 minecraft:red_glazed_terracotta 3
setblock ~54~62~8 minecraft:stained_glass 14
fill ~54~63~8 ~56~63~8 minecraft:concrete 14
fill ~54~64~8 ~55~64~8 minecraft:concrete 14
fill ~55~37~8 ~55~37~10 minecraft:stained_glass 14
setblock ~55~38~8 minecraft:red_glazed_terracotta 3
fill ~55~40~8 ~56~40~8 minecraft:concrete 14
fill ~55~41~8 ~55~41~9 minecraft:stained_glass 14
fill ~55~49~8 ~55~51~8 minecraft:concrete 14
setblock ~55~53~8 minecraft:red_glazed_terracotta 3
fill ~55~54~8 ~55~54~9 minecraft:stained_glass 14
fill ~55~60~8 ~57~60~8 minecraft:stained_glass 14
setblock ~55~62~8 minecraft:red_glazed_terracotta 3
setblock ~56~37~8 minecraft:red_glazed_terracotta 3
fill ~56~38~8 ~60~38~8 minecraft:stained_glass 14
setblock ~56~39~8 minecraft:red_glazed_terracotta 3
fill ~56~49~8 ~61~49~8 minecraft:stained_glass 14
fill ~56~50~8 ~58~50~8 minecraft:stained_glass 14
fill ~56~51~8 ~56~51~9 minecraft:red_glazed_terracotta 3
fill ~56~53~8 ~56~53~9 minecraft:stained_glass 14
fill ~56~54~8 ~57~54~8 minecraft:concrete 14
fill ~56~61~8 ~56~61~10 minecraft:stained_glass 14
setblock ~56~62~8 minecraft:concrete 14
fill ~56~64~8 ~57~64~8 minecraft:red_glazed_terracotta 3
fill ~57~37~8 ~59~37~8 minecraft:stained_glass 14
fill ~57~39~8 ~57~39~9 minecraft:stained_glass 14
setblock ~57~51~8 minecraft:stained_glass 14
fill ~57~53~8 ~57~53~9 minecraft:concrete 14
setblock ~57~61~8 minecraft:red_glazed_terracotta 3
setblock ~57~63~8 minecraft:stained_glass 14
setblock ~58~39~8 minecraft:red_glazed_terracotta 3
setblock ~58~51~8 minecraft:concrete 14
setblock ~58~53~8 minecraft:red_glazed_terracotta 3
fill ~58~54~8 ~58~54~9 minecraft:stained_glass 14
fill ~58~60~8 ~58~60~10 minecraft:concrete 14
fill ~58~61~8 ~58~62~8 minecraft:stained_glass 14
setblock ~58~63~8 minecraft:red_glazed_terracotta 3
fill ~58~64~8 ~61~64~8 minecraft:concrete 14
fill ~59~39~8 ~60~39~9 minecraft:concrete 14
fill ~59~51~8 ~60~52~8 minecraft:stained_glass 14
setblock ~59~53~8 minecraft:stained_glass 14
setblock ~59~54~8 minecraft:red_glazed_terracotta 3
fill ~59~61~8 ~60~61~8 minecraft:concrete 14
setblock ~59~62~8 minecraft:concrete 14
setblock ~59~63~8 minecraft:stained_glass 14
setblock ~59~65~8 minecraft:red_glazed_terracotta 3
setblock ~60~37~8 minecraft:red_glazed_terracotta 3
fill ~60~54~8 ~60~55~8 minecraft:concrete 14
fill ~60~59~8 ~61~59~8 minecraft:stained_glass 14
fill ~60~62~8 ~60~63~8 minecraft:red_glazed_terracotta 3
setblock ~60~65~8 minecraft:stained_glass 14
setblock ~61~38~8 minecraft:concrete 14
setblock ~61~39~8 minecraft:red_glazed_terracotta 3
fill ~61~40~8 ~61~40~9 minecraft:stained_glass 14
setblock ~61~50~8 minecraft:stained_glass 14
setblock ~61~51~8 minecraft:red_glazed_terracotta 3
fill ~61~52~8 ~61~52~9 minecraft:stained_glass 14
setblock ~61~53~8 minecraft:red_glazed_terracotta 3
fill ~61~54~8 ~61~55~8 minecraft:stained_glass 14
setblock ~61~56~8 minecraft:red_glazed_terracotta 3
setblock ~61~57~8 minecraft:stained_glass 14
setblock ~61~58~8 minecraft:concrete 14
setblock ~61~60~8 minecraft:red_glazed_terracotta 3
fill ~61~61~8 ~61~61~10 minecraft:stained_glass 14
fill ~61~62~8 ~61~63~8 minecraft:concrete 14
fill ~61~65~8 ~62~65~8 minecraft:red_glazed_terracotta 3
setblock ~61~66~8 minecraft:red_glazed_terracotta 3
fill ~62~39~8 ~62~39~9 minecraft:stained_glass 14
fill ~62~40~8 ~62~41~8 minecraft:concrete 14
fill ~62~49~8 ~62~50~8 minecraft:concrete 14
setblock ~62~52~8 minecraft:red_glazed_terracotta 3
setblock ~62~53~8 minecraft:stained_glass 14
setblock ~62~55~8 minecraft:concrete 14
setblock ~62~56~8 minecraft:stained_glass 14
fill ~62~58~8 ~62~58~9 minecraft:red_glazed_terracotta 3
fill ~62~59~8 ~63~59~8 minecraft:concrete 14
fill ~62~60~8 ~62~60~10 minecraft:stained_glass 14
fill ~62~61~8 ~64~61~8 minecraft:concrete 14
fill ~62~62~8 ~64~64~8 minecraft:stained_glass 14
fill ~62~66~8 ~66~66~8 minecraft:stained_glass 14
fill ~63~39~8 ~63~39~9 minecraft:red_glazed_terracotta 3
fill ~63~40~8 ~64~40~8 minecraft:stained_glass 14
setblock ~63~41~8 minecraft:red_glazed_terracotta 3
fill ~63~42~8 ~64~42~8 minecraft:stained_glass 14
setblock ~63~48~8 minecraft:red_glazed_terracotta 3
fill ~63~49~8 ~63~49~9 minecraft:stained_glass 14
fill ~63~51~8 ~64~51~8 minecraft:stained_glass 14
fill ~63~52~8 ~63~52~10 minecraft:concrete 14
setblock ~63~53~8 minecraft:concrete 14
setblock ~63~54~8 minecraft:stained_glass 14
fill ~63~55~8 ~64~55~8 minecraft:red_glazed_terracotta 3
fill ~63~56~8 ~64~56~8 minecraft:concrete 14
fill ~63~57~8 ~65~57~8 minecraft:stained_glass 14
fill ~63~58~8 ~63~58~10 minecraft:stained_glass 14
setblock ~63~60~8 minecraft:red_glazed_terracotta 3
fill ~63~65~8 ~63~65~9 minecraft:concrete 14
fill ~63~67~8 ~63~67~10 minecraft:stained_glass 14
setblock ~64~41~8 minecraft:concrete 14
setblock ~64~43~8 minecraft:concrete 14
fill ~64~48~8 ~65~48~8 minecraft:stained_glass 14
setblock ~64~49~8 minecraft:concrete 14
fill ~64~50~8 ~65~50~8 minecraft:red_glazed_terracotta 3
fill ~64~52~8 ~65~52~8 minecraft:stained_glass 14
setblock ~64~58~8 minecraft:red_glazed_terracotta 3
fill ~64~59~8 ~64~60~8 minecraft:stained_glass 14
fill ~64~65~8 ~64~65~9 minecraft:red_glazed_terracotta 3
setblock ~65~41~8 minecraft:stained_glass 14
setblock ~65~42~8 minecraft:concrete 14
fill ~65~43~8 ~66~44~8 minecraft:red_glazed_terracotta 3
fill ~65~45~8 ~65~46~8 minecraft:stained_glass 14
setblock ~65~47~8 minecraft:red_glazed_terracotta 3
fill ~65~51~8 ~65~51~9 minecraft:concrete 14
setblock ~65~54~8 minecraft:red_glazed_terracotta 3
fill ~65~55~8 ~66~55~9 minecraft:stained_glass 14
setblock ~65~56~8 minecraft:stained_glass 14
fill ~65~58~8 ~70~58~8 minecraft:stained_glass 14
fill ~65~61~8 ~65~61~9 minecraft:stained_glass 14
setblock ~65~65~8 minecraft:stained_glass 14
fill ~66~42~8 ~66~42~10 minecraft:red_glazed_terracotta 3
fill ~66~45~8 ~68~45~8 minecraft:red_glazed_terracotta 3
fill ~66~46~8 ~68~46~8 minecraft:stained_glass 14
fill ~66~47~8 ~66~48~8 minecraft:concrete 14
fill ~66~49~8 ~66~50~8 minecraft:stained_glass 14
fill ~66~51~8 ~67~51~8 minecraft:red_glazed_terracotta 3
setblock ~66~53~8 minecraft:concrete 14
setblock ~66~54~8 minecraft:stained_glass 14
fill ~66~56~8 ~67~56~8 minecraft:concrete 14
setblock ~66~57~8 minecraft:red_glazed_terracotta 3
fill ~66~60~8 ~66~60~9 minecraft:red_glazed_terracotta 3
fill ~67~43~8 ~67~44~9 minecraft:stained_glass 14
fill ~67~47~8 ~70~47~8 minecraft:stained_glass 14
fill ~67~48~8 ~68~48~8 minecraft:stained_glass 14
setblock ~67~49~8 minecraft:concrete 14
setblock ~67~50~8 minecraft:stained_glass 14
fill ~67~52~8 ~68~52~9 minecraft:stained_glass 14
fill ~67~57~8 ~67~57~9 minecraft:concrete 14
setblock ~67~60~8 minecraft:concrete 14
fill ~68~44~8 ~68~44~9 minecraft:stained_glass 14
fill ~68~49~8 ~68~50~8 minecraft:red_glazed_terracotta 3
setblock ~68~51~8 minecraft:stained_glass 14
fill ~68~57~8 ~68~57~10 minecraft:stained_glass 14
setblock ~68~59~8 minecraft:concrete 14
fill ~68~60~8 ~68~60~9 minecraft:stained_glass 14
setblock ~68~61~8 minecraft:concrete 14
setblock ~69~46~8 minecraft:red_glazed_terracotta 3
setblock ~69~48~8 minecraft:red_glazed_terracotta 3
fill ~69~49~8 ~71~49~9 minecraft:stained_glass 14
fill ~69~50~8 ~69~50~9 minecraft:stained_glass 14
setblock ~69~51~8 minecraft:red_glazed_terracotta 3
fill ~69~59~8 ~70~59~9 minecraft:red_glazed_terracotta 3
fill ~69~60~8 ~70~60~8 minecraft:concrete 14
setblock ~69~61~8 minecraft:red_glazed_terracotta 3
setblock ~70~48~8 minecraft:stained_glass 14
setblock ~70~50~8 minecraft:concrete 14
fill ~70~51~8 ~71~51~8 minecraft:stained_glass 14
setblock ~70~61~8 minecraft:stained_glass 14
fill ~70~62~8 ~70~62~9 minecraft:concrete 14
fill ~71~48~8 ~71~48~11 minecraft:red_glazed_terracotta 3
fill ~71~50~8 ~71~50~9 minecraft:stained_glass 14
fill ~71~59~8 ~72~59~8 minecraft:concrete 14
fill ~71~60~8 ~72~60~8 minecraft:red_glazed_terracotta 3
fill ~71~61~8 ~71~62~8 minecraft:red_glazed_terracotta 3
fill ~72~50~8 ~72~50~9 minecraft:concrete 14
setblock ~72~51~8 minecraft:concrete 14
setblock ~72~61~8 minecraft:concrete 14
fill ~72~62~8 ~73~62~10 minecraft:stained_glass 14
fill ~72~63~8 ~72~63~9 minecraft:red_glazed_terracotta 3
setblock ~73~60~8 minecraft:concrete 14
fill ~73~61~8 ~73~61~9 minecraft:stained_glass 14
fill ~73~63~8 ~73~63~9 minecraft:stained_glass 14
fill ~32~56~9 ~32~56~10 minecraft:red_glazed_terracotta 3
fill ~32~57~9 ~35~57~9 minecraft:stained_glass 14
setblock ~32~58~9 minecraft:concrete 14
fill ~33~54~9 ~33~56~9 minecraft:stained_glass 14
fill ~33~58~9 ~35~58~9 minecraft:red_glazed_terracotta 3
setblock ~33~59~9 minecraft:red_glazed_terracotta 3
setblock ~34~53~9 minecraft:stained_glass 14
fill ~34~54~9 ~34~55~9 minecraft:concrete 14
setblock ~34~56~9 minecraft:stained_glass 14
fill ~34~59~9 ~34~59~10 minecraft:stained_glass 14
fill ~34~60~9 ~34~60~11 minecraft:red_glazed_terracotta 3
fill ~34~61~9 ~34~64~9 minecraft:stained_glass 14
setblock ~34~65~9 minecraft:red_glazed_terracotta 3
setblock ~34~66~9 minecraft:stained_glass 14
fill ~35~52~9 ~35~52~10 minecraft:concrete 14
fill ~35~53~9 ~37~53~9 minecraft:concrete 14
setblock ~35~54~9 minecraft:red_glazed_terracotta 3
setblock ~35~55~9 minecraft:concrete 14
fill ~35~56~9 ~35~56~10 minecraft:red_glazed_terracotta 3
fill ~35~59~9 ~36~59~9 minecraft:concrete 14
setblock ~35~60~9 minecraft:stained_glass 14
setblock ~35~61~9 minecraft:concrete 14
setblock ~35~62~9 minecraft:red_glazed_terracotta 3
fill ~35~63~9 ~37~63~9 minecraft:stained_glass 14
setblock ~35~64~9 minecraft:concrete 14
setblock ~35~65~9 minecraft:stained_glass 14
fill ~35~66~9 ~35~66~10 minecraft:concrete 14
fill ~35~67~9 ~36~67~9 minecraft:stained_glass 14
fill ~36~49~9 ~37~49~10 minecraft:stained_glass 14
setblock ~36~50~9 minecraft:concrete 14
fill ~36~51~9 ~36~52~10 minecraft:red_glazed_terracotta 3
setblock ~36~54~9 minecraft:stained_glass 14
setblock ~36~56~9 minecraft:stained_glass 14
fill ~36~57~9 ~38~57~9 minecraft:red_glazed_terracotta 3
setblock ~36~58~9 minecraft:concrete 14
setblock ~36~60~9 minecraft:concrete 14
fill ~36~61~9 ~36~62~9 minecraft:stained_glass 14
setblock ~36~64~9 minecraft:red_glazed_terracotta 3
setblock ~36~65~9 minecraft:concrete 14
fill ~36~66~9 ~36~66~11 minecraft:stained_glass 14
fill ~37~45~9 ~38~45~9 minecraft:concrete 14
fill ~37~46~9 ~37~46~10 minecraft:red_glazed_terracotta 3
fill ~37~47~9 ~37~48~9 minecraft:stained_glass 14
fill ~37~50~9 ~38~50~10 minecraft:stained_glass 14
fill ~37~51~9 ~37~52~9 minecraft:concrete 14
fill ~37~54~9 ~38~54~9 minecraft:concrete 14
setblock ~37~56~9 minecraft:concrete 14
fill ~37~59~9 ~39~59~9 minecraft:stained_glass 14
fill ~37~60~9 ~38~60~9 minecraft:red_glazed_terracotta 3
fill ~37~61~9 ~37~62~9 minecraft:red_glazed_terracotta 3
fill ~37~64~9 ~38~64~9 minecraft:stained_glass 14
fill ~37~65~9 ~37~65~10 minecraft:stained_glass 14
fill ~38~43~9 ~39~43~10 minecraft:stained_glass 14
fill ~38~44~9 ~39~44~9 minecraft:red_glazed_terracotta 3
fill ~38~46~9 ~41~46~9 minecraft:stained_glass 14
setblock ~38~47~9 minecraft:concrete 14
fill ~38~48~9 ~39~48~9 minecraft:stained_glass 14
setblock ~38~49~9 minecraft:concrete 14
setblock ~38~53~9 minecraft:stained_glass 14
fill ~38~55~9 ~38~56~9 minecraft:stained_glass 14
setblock ~38~58~9 minecraft:stained_glass 14
fill ~38~62~9 ~38~62~11 minecraft:stained_glass 14
setblock ~38~63~9 minecraft:concrete 14
fill ~39~42~9 ~40~42~9 minecraft:stained_glass 14
fill ~39~45~9 ~41~45~9 minecraft:stained_glass 14
setblock ~39~47~9 minecraft:stained_glass 14
setblock ~39~49~9 minecraft:stained_glass 14
fill ~39~50~9 ~39~50~10 minecraft:concrete 14
setblock ~39~52~9 minecraft:red_glazed_terracotta 3
setblock ~39~53~9 minecraft:concrete 14
setblock ~39~54~9 minecraft:red_glazed_terracotta 3
setblock ~39~60~9 minecraft:concrete 14
setblock ~39~64~9 minecraft:red_glazed_terracotta 3
fill ~40~41~9 ~40~41~11 minecraft:stained_glass 14
setblock ~40~43~9 minecraft:concrete 14
fill ~40~44~9 ~40~44~10 minecraft:stained_glass 14
fill ~40~47~9 ~40~47~11 minecraft:red_glazed_terracotta 3
setblock ~40~48~9 minecraft:concrete 14
setblock ~40~50~9 minecraft:stained_glass 14
fill ~40~51~9 ~40~51~10 minecraft:red_glazed_terracotta 3
fill ~40~52~9 ~41~52~9 minecraft:stained_glass 14
setblock ~40~53~9 minecraft:red_glazed_terracotta 3
setblock ~40~61~9 minecraft:concrete 14
setblock ~40~62~9 minecraft:red_glazed_terracotta 3
fill ~40~63~9 ~41~63~9 minecraft:stained_glass 14
setblock ~40~64~9 minecraft:stained_glass 14
fill ~41~40~9 ~42~40~9 minecraft:stained_glass 14
setblock ~41~41~9 minecraft:concrete 14
fill ~41~42~9 ~41~42~10 minecraft:red_glazed_terracotta 3
fill ~41~43~9 ~41~44~9 minecraft:red_glazed_terracotta 3
fill ~41~48~9 ~42~48~10 minecraft:stained_glass 14
fill ~41~49~9 ~42~50~9 minecraft:red_glazed_terracotta 3
fill ~41~60~9 ~41~60~10 minecraft:red_glazed_terracotta 3
setblock ~41~62~9 minecraft:concrete 14
fill ~42~39~9 ~43~39~10 minecraft:stained_glass 14
fill ~42~41~9 ~42~41~10 minecraft:red_glazed_terracotta 3
setblock ~42~46~9 minecraft:concrete 14
fill ~42~47~9 ~44~47~9 minecraft:stained_glass 14
fill ~42~51~9 ~42~51~10 minecraft:red_glazed_terracotta 3
setblock ~42~59~9 minecraft:stained_glass 14
setblock ~42~64~9 minecraft:concrete 14
fill ~43~38~9 ~43~38~10 minecraft:stained_glass 14
setblock ~43~40~9 minecraft:red_glazed_terracotta 3
setblock ~43~46~9 minecraft:red_glazed_terracotta 3
fill ~43~50~9 ~43~51~9 minecraft:stained_glass 14
setblock ~43~59~9 minecraft:concrete 14
setblock ~43~60~9 minecraft:red_glazed_terracotta 3
fill ~43~61~9 ~43~61~10 minecraft:stained_glass 14
fill ~43~63~9 ~43~63~11 minecraft:stained_glass 14
fill ~43~64~9 ~44~64~9 minecraft:stained_glass 14
setblock ~43~65~9 minecraft:red_glazed_terracotta 3
fill ~43~70~9 ~43~70~11 minecraft:concrete 14
setblock ~43~71~9 minecraft:concrete 14
fill ~44~37~9 ~45~37~9 minecraft:stained_glass 14
setblock ~44~38~9 minecraft:red_glazed_terracotta 3
setblock ~44~39~9 minecraft:concrete 14
fill ~44~46~9 ~45~46~9 minecraft:stained_glass 14
fill ~44~48~9 ~45~48~9 minecraft:red_glazed_terracotta 3
setblock ~44~50~9 minecraft:concrete 14
setblock ~44~51~9 minecraft:red_glazed_terracotta 3
fill ~44~58~9 ~46~58~9 minecraft:stained_glass 14
setblock ~44~59~9 minecraft:red_glazed_terracotta 3
fill ~44~60~9 ~44~60~10 minecraft:stained_glass 14
fill ~44~61~9 ~44~61~10 minecraft:concrete 14
fill ~44~62~9 ~46~62~9 minecraft:stained_glass 14
fill ~44~65~9 ~44~68~9 minecraft:stained_glass 14
setblock ~44~69~9 minecraft:red_glazed_terracotta 3
fill ~44~70~9 ~44~71~9 minecraft:stained_glass 14
fill ~45~36~9 ~48~36~9 minecraft:stained_glass 14
fill ~45~38~9 ~46~38~9 minecraft:stained_glass 14
setblock ~45~39~9 minecraft:stained_glass 14
setblock ~45~47~9 minecraft:red_glazed_terracotta 3
setblock ~45~51~9 minecraft:stained_glass 14
fill ~45~59~9 ~47~59~9 minecraft:stained_glass 14
fill ~45~60~9 ~47~60~9 minecraft:red_glazed_terracotta 3
fill ~45~64~9 ~45~65~9 minecraft:red_glazed_terracotta 3
fill ~45~66~9 ~45~66~11 minecraft:stained_glass 14
setblock ~45~67~9 minecraft:stained_glass 14
setblock ~45~68~9 minecraft:concrete 14
fill ~45~69~9 ~47~69~9 minecraft:stained_glass 14
fill ~45~70~9 ~45~70~11 minecraft:concrete 14
fill ~45~71~9 ~45~71~10 minecraft:concrete 14
fill ~46~37~9 ~46~37~12 minecraft:red_glazed_terracotta 3
fill ~46~45~9 ~46~46~9 minecraft:red_glazed_terracotta 3
fill ~46~47~9 ~47~47~9 minecraft:stained_glass 14
fill ~46~48~9 ~48~48~9 minecraft:concrete 14
setblock ~46~49~9 minecraft:concrete 14
setblock ~46~50~9 minecraft:stained_glass 14
setblock ~46~51~9 minecraft:red_glazed_terracotta 3
setblock ~46~57~9 minecraft:red_glazed_terracotta 3
setblock ~46~61~9 minecraft:stained_glass 14
fill ~46~64~9 ~46~64~11 minecraft:concrete 14
setblock ~46~65~9 minecraft:stained_glass 14
fill ~46~67~9 ~47~67~10 minecraft:red_glazed_terracotta 3
setblock ~46~68~9 minecraft:stained_glass 14
fill ~46~70~9 ~48~71~9 minecraft:stained_glass 14
fill ~47~35~9 ~48~35~9 minecraft:stained_glass 14
fill ~47~37~9 ~48~37~9 minecraft:stained_glass 14
setblock ~47~38~9 minecraft:red_glazed_terracotta 3
fill ~47~39~9 ~49~39~9 minecraft:stained_glass 14
fill ~47~45~9 ~47~45~10 minecraft:concrete 14
fill ~47~46~9 ~47~46~10 minecraft:stained_glass 14
setblock ~47~49~9 minecraft:stained_glass 14
fill ~47~50~9 ~47~51~9 minecraft:concrete 14
setblock ~47~55~9 minecraft:red_glazed_terracotta 3
setblock ~47~56~9 minecraft:concrete 14
fill ~47~57~9 ~47~57~10 minecraft:stained_glass 14
setblock ~47~58~9 minecraft:red_glazed_terracotta 3
fill ~47~63~9 ~48~63~10 minecraft:stained_glass 14
setblock ~47~68~9 minecraft:red_glazed_terracotta 3
fill ~48~38~9 ~49~38~9 minecraft:stained_glass 14
fill ~48~40~9 ~48~40~10 minecraft:concrete 14
fill ~48~45~9 ~48~45~10 minecraft:stained_glass 14
fill ~48~47~9 ~50~47~9 minecraft:red_glazed_terracotta 3
setblock ~48~49~9 minecraft:concrete 14
fill ~48~50~9 ~48~50~10 minecraft:stained_glass 14
setblock ~48~51~9 minecraft:stained_glass 14
setblock ~48~52~9 minecraft:concrete 14
setblock ~48~53~9 minecraft:stained_glass 14
setblock ~48~54~9 minecraft:red_glazed_terracotta 3
setblock ~48~55~9 minecraft:stained_glass 14
setblock ~48~57~9 minecraft:red_glazed_terracotta 3
fill ~48~58~9 ~48~58~10 minecraft:stained_glass 14
fill ~48~59~9 ~49~59~9 minecraft:concrete 14
setblock ~48~60~9 minecraft:stained_glass 14
fill ~48~65~9 ~49~65~10 minecraft:concrete 14
fill ~48~67~9 ~48~67~10 minecraft:stained_glass 14
fill ~48~68~9 ~48~69~9 minecraft:concrete 14
fill ~49~35~9 ~50~35~9 minecraft:concrete 14
fill ~49~36~9 ~49~36~12 minecraft:concrete 14
fill ~49~37~9 ~49~37~10 minecraft:red_glazed_terracotta 3
setblock ~49~40~9 minecraft:stained_glass 14
setblock ~49~42~9 minecraft:red_glazed_terracotta 3
fill ~49~43~9 ~49~43~10 minecraft:stained_glass 14
fill ~49~44~9 ~50~44~9 minecraft:red_glazed_terracotta 3
setblock ~49~45~9 minecraft:concrete 14
fill ~49~48~9 ~50~48~9 minecraft:red_glazed_terracotta 3
fill ~49~49~9 ~50~49~9 minecraft:stained_glass 14
fill ~49~50~9 ~50~50~9 minecraft:concrete 14
fill ~49~52~9 ~51~52~9 minecraft:stained_glass 14
setblock ~49~54~9 minecraft:stained_glass 14
setblock ~49~55~9 minecraft:concrete 14
fill ~49~56~9 ~51~56~9 minecraft:stained_glass 14
setblock ~49~57~9 minecraft:concrete 14
setblock ~49~58~9 minecraft:red_glazed_terracotta 3
setblock ~49~61~9 minecraft:stained_glass 14
setblock ~49~63~9 minecraft:concrete 14
fill ~49~66~9 ~49~68~9 minecraft:red_glazed_terracotta 3
setblock ~49~69~9 minecraft:stained_glass 14
setblock ~49~70~9 minecraft:concrete 14
fill ~50~36~9 ~50~37~9 minecraft:stained_glass 14
fill ~50~38~9 ~51~38~9 minecraft:red_glazed_terracotta 3
fill ~50~40~9 ~50~42~9 minecraft:concrete 14
fill ~50~43~9 ~50~43~10 minecraft:red_glazed_terracotta 3
fill ~50~45~9 ~50~45~10 minecraft:stained_glass 14
setblock ~50~46~9 minecraft:concrete 14
setblock ~50~51~9 minecraft:red_glazed_terracotta 3
setblock ~50~54~9 minecraft:red_glazed_terracotta 3
fill ~50~55~9 ~51~55~9 minecraft:stained_glass 14
setblock ~50~57~9 minecraft:red_glazed_terracotta 3
setblock ~50~58~9 minecraft:concrete 14
setblock ~50~59~9 minecraft:red_glazed_terracotta 3
fill ~50~63~9 ~50~63~10 minecraft:stained_glass 14
fill ~50~67~9 ~50~68~10 minecraft:red_glazed_terracotta 3
fill ~51~35~9 ~51~36~9 minecraft:red_glazed_terracotta 3
setblock ~51~37~9 minecraft:concrete 14
setblock ~51~39~9 minecraft:concrete 14
fill ~51~40~9 ~52~40~9 minecraft:stained_glass 14
fill ~51~47~9 ~51~47~10 minecraft:concrete 14
fill ~51~48~9 ~52~48~9 minecraft:stained_glass 14
setblock ~51~50~9 minecraft:red_glazed_terracotta 3
setblock ~51~51~9 minecraft:stained_glass 14
setblock ~51~53~9 minecraft:concrete 14
fill ~51~54~9 ~52~54~9 minecraft:stained_glass 14
setblock ~51~57~9 minecraft:concrete 14
fill ~51~58~9 ~52~58~9 minecraft:stained_glass 14
fill ~51~63~9 ~51~63~10 minecraft:red_glazed_terracotta 3
setblock ~51~65~9 minecraft:concrete 14
setblock ~51~67~9 minecraft:concrete 14
fill ~52~36~9 ~53~36~9 minecraft:stained_glass 14
setblock ~52~38~9 minecraft:stained_glass 14
fill ~52~39~9 ~53~39~9 minecraft:red_glazed_terracotta 3
setblock ~52~43~9 minecraft:concrete 14
fill ~52~45~9 ~52~45~10 minecraft:red_glazed_terracotta 3
fill ~52~46~9 ~52~47~9 minecraft:red_glazed_terracotta 3
setblock ~52~49~9 minecraft:concrete 14
fill ~52~50~9 ~52~50~10 minecraft:stained_glass 14
setblock ~52~51~9 minecraft:red_glazed_terracotta 3
setblock ~52~52~9 minecraft:concrete 14
fill ~52~53~9 ~53~53~9 minecraft:stained_glass 14
fill ~52~55~9 ~53~55~9 minecraft:concrete 14
setblock ~52~57~9 minecraft:stained_glass 14
fill ~52~61~9 ~53~61~9 minecraft:stained_glass 14
setblock ~52~63~9 minecraft:concrete 14
setblock ~52~64~9 minecraft:stained_glass 14
setblock ~52~65~9 minecraft:red_glazed_terracotta 3
fill ~52~66~9 ~52~66~10 minecraft:stained_glass 14
fill ~53~38~9 ~55~38~9 minecraft:concrete 14
setblock ~53~40~9 minecraft:red_glazed_terracotta 3
fill ~53~42~9 ~54~42~9 minecraft:red_glazed_terracotta 3
setblock ~53~45~9 minecraft:stained_glass 14
fill ~53~50~9 ~54~50~9 minecraft:red_glazed_terracotta 3
fill ~53~51~9 ~55~52~9 minecraft:stained_glass 14
setblock ~53~54~9 minecraft:red_glazed_terracotta 3
setblock ~53~62~9 minecraft:concrete 14
setblock ~54~36~9 minecraft:concrete 14
setblock ~54~37~9 minecraft:red_glazed_terracotta 3
fill ~54~39~9 ~54~40~9 minecraft:stained_glass 14
setblock ~54~53~9 minecraft:red_glazed_terracotta 3
setblock ~54~54~9 minecraft:stained_glass 14
setblock ~54~60~9 minecraft:stained_glass 14
setblock ~54~61~9 minecraft:concrete 14
setblock ~54~62~9 minecraft:red_glazed_terracotta 3
fill ~54~63~9 ~56~64~9 minecraft:stained_glass 14
setblock ~54~65~9 minecraft:red_glazed_terracotta 3
fill ~55~35~9 ~58~35~9 minecraft:stained_glass 14
fill ~55~36~9 ~55~36~11 minecraft:stained_glass 14
fill ~55~39~9 ~55~39~10 minecraft:red_glazed_terracotta 3
fill ~55~40~9 ~55~40~10 minecraft:concrete 14
setblock ~55~42~9 minecraft:stained_glass 14
setblock ~55~49~9 minecraft:red_glazed_terracotta 3
setblock ~55~50~9 minecraft:concrete 14
setblock ~55~53~9 minecraft:stained_glass 14
setblock ~55~60~9 minecraft:red_glazed_terracotta 3
fill ~55~62~9 ~56~62~9 minecraft:stained_glass 14
fill ~56~36~9 ~56~36~10 minecraft:red_glazed_terracotta 3
fill ~56~37~9 ~56~37~11 minecraft:stained_glass 14
fill ~56~38~9 ~56~40~9 minecraft:stained_glass 14
setblock ~56~41~9 minecraft:concrete 14
setblock ~56~50~9 minecraft:stained_glass 14
fill ~56~52~9 ~57~52~9 minecraft:stained_glass 14
setblock ~56~54~9 minecraft:red_glazed_terracotta 3
fill ~56~60~9 ~56~60~10 minecraft:stained_glass 14
setblock ~57~34~9 minecraft:stained_glass 14
setblock ~57~36~9 minecraft:stained_glass 14
setblock ~57~37~9 minecraft:red_glazed_terracotta 3
fill ~57~38~9 ~57~38~10 minecraft:concrete 14
fill ~57~40~9 ~57~40~10 minecraft:stained_glass 14
setblock ~57~50~9 minecraft:concrete 14
setblock ~57~51~9 minecraft:red_glazed_terracotta 3
setblock ~57~54~9 minecraft:stained_glass 14
fill ~57~60~9 ~57~60~10 minecraft:red_glazed_terracotta 3
fill ~57~61~9 ~57~61~10 minecraft:stained_glass 14
setblock ~57~62~9 minecraft:concrete 14
fill ~57~63~9 ~57~63~10 minecraft:red_glazed_terracotta 3
fill ~57~64~9 ~57~64~10 minecraft:stained_glass 14
fill ~58~33~9 ~59~33~9 minecraft:stained_glass 14
fill ~58~34~9 ~60~34~9 minecraft:red_glazed_terracotta 3
fill ~58~36~9 ~59~36~9 minecraft:red_glazed_terracotta 3
fill ~58~37~9 ~59~37~9 minecraft:stained_glass 14
fill ~58~38~9 ~58~38~11 minecraft:stained_glass 14
setblock ~58~39~9 minecraft:stained_glass 14
fill ~58~40~9 ~59~40~9 minecraft:concrete 14
fill ~58~50~9 ~58~51~9 minecraft:stained_glass 14
fill ~58~52~9 ~59~52~9 minecraft:concrete 14
setblock ~58~53~9 minecraft:stained_glass 14
fill ~58~61~9 ~58~61~10 minecraft:concrete 14
fill ~58~62~9 ~61~62~9 minecraft:stained_glass 14
fill ~58~64~9 ~59~64~9 minecraft:concrete 14
setblock ~58~65~9 minecraft:concrete 14
setblock ~59~35~9 minecraft:concrete 14
setblock ~59~38~9 minecraft:red_glazed_terracotta 3
setblock ~59~50~9 minecraft:red_glazed_terracotta 3
setblock ~59~51~9 minecraft:concrete 14
setblock ~59~53~9 minecraft:concrete 14
fill ~59~54~9 ~60~54~9 minecraft:stained_glass 14
fill ~59~59~9 ~60~59~9 minecraft:stained_glass 14
fill ~59~60~9 ~59~60~10 minecraft:stained_glass 14
setblock ~59~61~9 minecraft:red_glazed_terracotta 3
fill ~59~65~9 ~59~65~10 minecraft:stained_glass 14
setblock ~60~35~9 minecraft:stained_glass 14
fill ~60~36~9 ~61~36~9 minecraft:concrete 14
fill ~60~37~9 ~60~38~9 minecraft:concrete 14
fill ~60~40~9 ~60~40~10 minecraft:stained_glass 14
setblock ~60~49~9 minecraft:red_glazed_terracotta 3
fill ~60~50~9 ~60~52~9 minecraft:stained_glass 14
setblock ~60~53~9 minecraft:red_glazed_terracotta 3
setblock ~60~60~9 minecraft:red_glazed_terracotta 3
fill ~60~61~9 ~60~61~10 minecraft:stained_glass 14
setblock ~60~64~9 minecraft:stained_glass 14
fill ~60~65~9 ~62~65~9 minecraft:concrete 14
setblock ~60~66~9 minecraft:red_glazed_terracotta 3
setblock ~61~34~9 minecraft:stained_glass 14
setblock ~61~35~9 minecraft:red_glazed_terracotta 3
setblock ~61~37~9 minecraft:stained_glass 14
setblock ~61~38~9 minecraft:red_glazed_terracotta 3
setblock ~61~39~9 minecraft:stained_glass 14
fill ~61~41~9 ~61~41~10 minecraft:stained_glass 14
fill ~61~49~9 ~62~49~9 minecraft:stained_glass 14
fill ~61~50~9 ~61~50~10 minecraft:concrete 14
fill ~61~51~9 ~63~51~9 minecraft:stained_glass 14
setblock ~61~53~9 minecraft:stained_glass 14
fill ~61~54~9 ~61~55~9 minecraft:red_glazed_terracotta 3
fill ~61~56~9 ~62~56~9 minecraft:concrete 14
setblock ~61~57~9 minecraft:concrete 14
fill ~61~58~9 ~61~59~9 minecraft:red_glazed_terracotta 3
setblock ~61~60~9 minecraft:stained_glass 14
fill ~61~64~9 ~61~64~10 minecraft:red_glazed_terracotta 3
setblock ~61~66~9 minecraft:stained_glass 14
fill ~61~67~9 ~61~67~10 minecraft:concrete 14
fill ~62~36~9 ~62~36~11 minecraft:stained_glass 14
setblock ~62~37~9 minecraft:concrete 14
fill ~62~38~9 ~64~38~9 minecraft:stained_glass 14
setblock ~62~40~9 minecraft:stained_glass 14
fill ~62~41~9 ~62~42~9 minecraft:red_glazed_terracotta 3
setblock ~62~50~9 minecraft:red_glazed_terracotta 3
setblock ~62~52~9 minecraft:stained_glass 14
setblock ~62~53~9 minecraft:concrete 14
fill ~62~55~9 ~62~55~10 minecraft:stained_glass 14
setblock ~62~59~9 minecraft:concrete 14
fill ~62~61~9 ~62~62~9 minecraft:concrete 14
fill ~62~64~9 ~64~64~9 minecraft:stained_glass 14
setblock ~62~66~9 minecraft:red_glazed_terracotta 3
fill ~62~67~9 ~62~67~10 minecraft:stained_glass 14
setblock ~62~68~9 minecraft:red_glazed_terracotta 3
setblock ~63~37~9 minecraft:stained_glass 14
fill ~63~40~9 ~64~40~9 minecraft:concrete 14
fill ~63~41~9 ~64~41~10 minecraft:stained_glass 14
fill ~63~42~9 ~63~43~9 minecraft:concrete 14
setblock ~63~48~9 minecraft:stained_glass 14
fill ~63~53~9 ~63~55~9 minecraft:red_glazed_terracotta 3
fill ~63~56~9 ~64~56~9 minecraft:stained_glass 14
fill ~63~57~9 ~64~57~9 minecraft:concrete 14
fill ~63~59~9 ~63~60~9 minecraft:stained_glass 14
setblock ~63~61~9 minecraft:red_glazed_terracotta 3
fill ~63~62~9 ~63~63~9 minecraft:stained_glass 14
setblock ~63~66~9 minecraft:stained_glass 14
setblock ~63~68~9 minecraft:stained_glass 14
fill ~63~69~9 ~63~69~10 minecraft:concrete 14
fill ~64~39~9 ~66~39~9 minecraft:stained_glass 14
fill ~64~42~9 ~65~42~10 minecraft:stained_glass 14
setblock ~64~43~9 minecraft:red_glazed_terracotta 3
fill ~64~44~9 ~64~44~10 minecraft:concrete 14
fill ~64~45~9 ~66~45~9 minecraft:red_glazed_terracotta 3
fill ~64~46~9 ~64~47~9 minecraft:stained_glass 14
fill ~64~48~9 ~65~48~9 minecraft:concrete 14
fill ~64~49~9 ~65~49~9 minecraft:red_glazed_terracotta 3
fill ~64~50~9 ~66~50~9 minecraft:stained_glass 14
setblock ~64~51~9 minecraft:red_glazed_terracotta 3
setblock ~64~52~9 minecraft:stained_glass 14
fill ~64~53~9 ~64~53~10 minecraft:concrete 14
setblock ~64~54~9 minecraft:concrete 14
fill ~64~55~9 ~64~55~10 minecraft:stained_glass 14
fill ~64~58~9 ~69~58~9 minecraft:stained_glass 14
setblock ~64~59~9 minecraft:concrete 14
setblock ~64~60~9 minecraft:red_glazed_terracotta 3
fill ~64~61~9 ~64~61~10 minecraft:concrete 14
setblock ~64~62~9 minecraft:concrete 14
setblock ~64~63~9 minecraft:stained_glass 14
fill ~64~66~9 ~65~67~9 minecraft:red_glazed_terracotta 3
setblock ~64~68~9 minecraft:concrete 14
fill ~64~69~9 ~64~69~10 minecraft:stained_glass 14
setblock ~64~70~9 minecraft:stained_glass 14
fill ~65~38~9 ~65~38~10 minecraft:red_glazed_terracotta 3
fill ~65~40~9 ~66~40~9 minecraft:stained_glass 14
setblock ~65~41~9 minecraft:red_glazed_terracotta 3
setblock ~65~43~9 minecraft:concrete 14
setblock ~65~44~9 minecraft:stained_glass 14
fill ~65~46~9 ~66~46~9 minecraft:concrete 14
fill ~65~47~9 ~66~47~9 minecraft:stained_glass 14
setblock ~65~52~9 minecraft:concrete 14
fill ~65~54~9 ~65~54~10 minecraft:stained_glass 14
setblock ~65~56~9 minecraft:concrete 14
fill ~65~57~9 ~66~57~9 minecraft:stained_glass 14
setblock ~65~59~9 minecraft:red_glazed_terracotta 3
setblock ~65~64~9 minecraft:red_glazed_terracotta 3
fill ~65~65~9 ~65~65~10 minecraft:concrete 14
fill ~65~68~9 ~66~68~9 minecraft:stained_glass 14
setblock ~65~69~9 minecraft:concrete 14
fill ~65~70~9 ~65~70~10 minecraft:red_glazed_terracotta 3
setblock ~66~41~9 minecraft:concrete 14
fill ~66~43~9 ~66~43~10 minecraft:red_glazed_terracotta 3
setblock ~66~44~9 minecraft:concrete 14
setblock ~66~49~9 minecraft:concrete 14
setblock ~66~51~9 minecraft:concrete 14
fill ~66~53~9 ~66~54~9 minecraft:red_glazed_terracotta 3
setblock ~66~56~9 minecraft:red_glazed_terracotta 3
fill ~66~59~9 ~67~59~9 minecraft:concrete 14
fill ~66~65~9 ~66~65~10 minecraft:red_glazed_terracotta 3
fill ~66~66~9 ~66~66~11 minecraft:stained_glass 14
setblock ~66~67~9 minecraft:concrete 14
fill ~66~69~9 ~67~69~10 minecraft:stained_glass 14
fill ~66~70~9 ~66~70~10 minecraft:concrete 14
setblock ~67~39~9 minecraft:concrete 14
setblock ~67~40~9 minecraft:red_glazed_terracotta 3
fill ~67~41~9 ~69~41~9 minecraft:stained_glass 14
setblock ~67~42~9 minecraft:stained_glass 14
fill ~67~45~9 ~68~45~9 minecraft:concrete 14
fill ~67~46~9 ~69~46~9 minecraft:stained_glass 14
setblock ~67~47~9 minecraft:concrete 14
setblock ~67~48~9 minecraft:red_glazed_terracotta 3
setblock ~67~51~9 minecraft:red_glazed_terracotta 3
setblock ~67~56~9 minecraft:concrete 14
fill ~67~60~9 ~67~60~10 minecraft:stained_glass 14
fill ~67~65~9 ~67~65~10 minecraft:stained_glass 14
setblock ~67~66~9 minecraft:red_glazed_terracotta 3
fill ~67~67~9 ~70~67~9 minecraft:stained_glass 14
setblock ~67~68~9 minecraft:red_glazed_terracotta 3
fill ~67~70~9 ~67~70~10 minecraft:stained_glass 14
fill ~68~40~9 ~68~40~10 minecraft:concrete 14
fill ~68~42~9 ~68~42~10 minecraft:red_glazed_terracotta 3
fill ~68~43~9 ~69~43~9 minecraft:stained_glass 14
fill ~68~47~9 ~68~50~9 minecraft:stained_glass 14
setblock ~68~51~9 minecraft:concrete 14
fill ~68~61~9 ~69~61~9 minecraft:stained_glass 14
setblock ~68~66~9 minecraft:concrete 14
fill ~68~68~9 ~72~68~9 minecraft:stained_glass 14
setblock ~68~69~9 minecraft:concrete 14
setblock ~69~40~9 minecraft:stained_glass 14
fill ~69~42~9 ~70~42~9 minecraft:stained_glass 14
fill ~69~44~9 ~69~45~9 minecraft:stained_glass 14
setblock ~69~47~9 minecraft:red_glazed_terracotta 3
fill ~69~48~9 ~69~48~11 minecraft:stained_glass 14
fill ~69~51~9 ~69~51~11 minecraft:stained_glass 14
fill ~69~52~9 ~69~52~10 minecraft:stained_glass 14
setblock ~69~57~9 minecraft:stained_glass 14
fill ~69~60~9 ~69~60~10 minecraft:stained_glass 14
fill ~69~66~9 ~71~66~10 minecraft:stained_glass 14
setblock ~69~69~9 minecraft:stained_glass 14
setblock ~70~45~9 minecraft:stained_glass 14
fill ~70~46~9 ~70~46~10 minecraft:red_glazed_terracotta 3
setblock ~70~47~9 minecraft:concrete 14
setblock ~70~48~9 minecraft:red_glazed_terracotta 3
fill ~70~50~9 ~70~52~9 minecraft:red_glazed_terracotta 3
setblock ~70~58~9 minecraft:concrete 14
setblock ~70~60~9 minecraft:red_glazed_terracotta 3
fill ~70~61~9 ~70~61~11 minecraft:concrete 14
fill ~70~65~9 ~70~65~11 minecraft:stained_glass 14
setblock ~71~47~9 minecraft:red_glazed_terracotta 3
fill ~71~51~9 ~71~51~10 minecraft:stained_glass 14
setblock ~71~52~9 minecraft:stained_glass 14
fill ~71~58~9 ~71~58~10 minecraft:stained_glass 14
setblock ~71~59~9 minecraft:red_glazed_terracotta 3
fill ~71~60~9 ~71~64~9 minecraft:stained_glass 14
setblock ~71~65~9 minecraft:red_glazed_terracotta 3
setblock ~71~67~9 minecraft:concrete 14
fill ~72~48~9 ~72~49~9 minecraft:stained_glass 14
setblock ~72~51~9 minecraft:red_glazed_terracotta 3
fill ~72~52~9 ~73~52~9 minecraft:concrete 14
fill ~72~59~9 ~72~59~11 minecraft:concrete 14
fill ~72~60~9 ~72~61~9 minecraft:red_glazed_terracotta 3
fill ~72~64~9 ~73~64~9 minecraft:stained_glass 14
setblock ~72~65~9 minecraft:concrete 14
fill ~72~66~9 ~73~66~9 minecraft:red_glazed_terracotta 3
fill ~72~67~9 ~73~67~9 minecraft:stained_glass 14
fill ~73~49~9 ~73~51~9 minecraft:stained_glass 14
fill ~73~53~9 ~74~53~9 minecraft:red_glazed_terracotta 3
fill ~73~59~9 ~73~60~9 minecraft:stained_glass 14
setblock ~73~65~9 minecraft:red_glazed_terracotta 3
setblock ~73~68~9 minecraft:red_glazed_terracotta 3
fill ~74~50~9 ~75~50~11 minecraft:stained_glass 14
fill ~74~51~9 ~76~51~9 minecraft:red_glazed_terracotta 3
fill ~74~52~9 ~76~52~9 minecraft:stained_glass 14
fill ~74~54~9 ~74~54~11 minecraft:stained_glass 14
fill ~74~58~9 ~74~59~9 minecraft:concrete 14
fill ~74~60~9 ~77~60~9 minecraft:red_glazed_terracotta 3
fill ~74~61~9 ~74~63~9 minecraft:stained_glass 14
setblock ~74~64~9 minecraft:red_glazed_terracotta 3
fill ~74~65~9 ~74~65~11 minecraft:stained_glass 14
fill ~74~66~9 ~75~66~9 minecraft:stained_glass 14
fill ~74~67~9 ~75~67~9 minecraft:concrete 14
fill ~74~68~9 ~74~68~10 minecraft:concrete 14
fill ~75~53~9 ~76~53~10 minecraft:stained_glass 14
setblock ~75~54~9 minecraft:concrete 14
fill ~75~55~9 ~75~59~9 minecraft:stained_glass 14
fill ~75~61~9 ~76~61~9 minecraft:red_glazed_terracotta 3
fill ~75~62~9 ~76~62~10 minecraft:stained_glass 14
setblock ~75~63~9 minecraft:concrete 14
setblock ~76~54~9 minecraft:red_glazed_terracotta 3
fill ~76~55~9 ~76~56~9 minecraft:concrete 14
setblock ~76~57~9 minecraft:stained_glass 14
fill ~76~58~9 ~77~58~9 minecraft:concrete 14
setblock ~76~59~9 minecraft:stained_glass 14
setblock ~77~52~9 minecraft:concrete 14
setblock ~77~53~9 minecraft:red_glazed_terracotta 3
fill ~77~54~9 ~77~55~9 minecraft:stained_glass 14
fill ~77~56~9 ~77~57~9 minecraft:concrete 14
setblock ~77~59~9 minecraft:concrete 14
fill ~77~61~9 ~77~61~10 minecraft:stained_glass 14
fill ~78~58~9 ~78~59~9 minecraft:stained_glass 14
fill ~78~60~9 ~78~60~10 minecraft:concrete 14
fill ~29~57~10 ~29~58~10 minecraft:concrete 14
fill ~29~59~10 ~30~59~10 minecraft:stained_glass 14
setblock ~30~56~10 minecraft:concrete 14
fill ~30~57~10 ~30~58~10 minecraft:stained_glass 14
setblock ~31~55~10 minecraft:red_glazed_terracotta 3
fill ~31~56~10 ~31~56~12 minecraft:stained_glass 14
setblock ~31~57~10 minecraft:red_glazed_terracotta 3
fill ~31~58~10 ~34~58~10 minecraft:stained_glass 14
setblock ~31~59~10 minecraft:red_glazed_terracotta 3
fill ~31~67~10 ~31~67~11 minecraft:stained_glass 14
fill ~31~68~10 ~32~68~10 minecraft:stained_glass 14
fill ~32~54~10 ~33~54~10 minecraft:concrete 14
fill ~32~55~10 ~35~55~10 minecraft:stained_glass 14
fill ~32~57~10 ~32~57~12 minecraft:stained_glass 14
fill ~32~59~10 ~33~59~10 minecraft:stained_glass 14
setblock ~32~66~10 minecraft:red_glazed_terracotta 3
setblock ~32~67~10 minecraft:concrete 14
fill ~32~69~10 ~34~69~11 minecraft:stained_glass 14
setblock ~33~56~10 minecraft:stained_glass 14
setblock ~33~57~10 minecraft:concrete 14
fill ~33~60~10 ~33~60~11 minecraft:stained_glass 14
fill ~33~64~10 ~33~64~11 minecraft:red_glazed_terracotta 3
setblock ~33~65~10 minecraft:concrete 14
fill ~33~66~10 ~33~67~10 minecraft:stained_glass 14
fill ~33~68~10 ~33~68~11 minecraft:red_glazed_terracotta 3
fill ~34~53~10 ~35~53~10 minecraft:red_glazed_terracotta 3
setblock ~34~54~10 minecraft:red_glazed_terracotta 3
setblock ~34~56~10 minecraft:red_glazed_terracotta 3
fill ~34~57~10 ~34~57~12 minecraft:stained_glass 14
fill ~34~61~10 ~34~61~11 minecraft:concrete 14
setblock ~34~62~10 minecraft:stained_glass 14
setblock ~34~63~10 minecraft:red_glazed_terracotta 3
fill ~34~64~10 ~35~64~10 minecraft:stained_glass 14
fill ~34~65~10 ~34~65~11 minecraft:stained_glass 14
setblock ~34~66~10 minecraft:concrete 14
fill ~34~67~10 ~34~68~10 minecraft:stained_glass 14
fill ~34~70~10 ~35~70~12 minecraft:red_glazed_terracotta 3
setblock ~35~51~10 minecraft:stained_glass 14
setblock ~35~54~10 minecraft:stained_glass 14
fill ~35~59~10 ~35~59~11 minecraft:stained_glass 14
setblock ~35~60~10 minecraft:concrete 14
fill ~35~61~10 ~35~61~11 minecraft:stained_glass 14
fill ~35~62~10 ~35~63~10 minecraft:concrete 14
fill ~35~65~10 ~35~65~11 minecraft:concrete 14
fill ~35~67~10 ~35~69~10 minecraft:red_glazed_terracotta 3
fill ~35~71~10 ~36~71~10 minecraft:stained_glass 14
setblock ~35~72~10 minecraft:concrete 14
fill ~36~41~10 ~36~41~11 minecraft:stained_glass 14
setblock ~36~42~10 minecraft:stained_glass 14
setblock ~36~43~10 minecraft:concrete 14
fill ~36~44~10 ~36~44~12 minecraft:stained_glass 14
setblock ~36~45~10 minecraft:red_glazed_terracotta 3
fill ~36~46~10 ~36~46~11 minecraft:stained_glass 14
fill ~36~47~10 ~37~48~10 minecraft:red_glazed_terracotta 3
setblock ~36~50~10 minecraft:stained_glass 14
setblock ~36~56~10 minecraft:concrete 14
fill ~36~57~10 ~38~57~10 minecraft:stained_glass 14
setblock ~36~58~10 minecraft:stained_glass 14
setblock ~36~64~10 minecraft:concrete 14
fill ~36~65~10 ~36~65~11 minecraft:red_glazed_terracotta 3
fill ~36~67~10 ~36~67~12 minecraft:stained_glass 14
setblock ~36~68~10 minecraft:red_glazed_terracotta 3
fill ~36~69~10 ~36~69~11 minecraft:concrete 14
setblock ~36~70~10 minecraft:concrete 14
fill ~36~72~10 ~38~72~11 minecraft:stained_glass 14
fill ~37~40~10 ~40~40~10 minecraft:stained_glass 14
setblock ~37~41~10 minecraft:concrete 14
setblock ~37~42~10 minecraft:red_glazed_terracotta 3
setblock ~37~43~10 minecraft:stained_glass 14
setblock ~37~44~10 minecraft:concrete 14
fill ~37~45~10 ~38~45~10 minecraft:stained_glass 14
fill ~37~51~10 ~37~52~10 minecraft:stained_glass 14
fill ~37~53~10 ~39~53~10 minecraft:red_glazed_terracotta 3
setblock ~37~54~10 minecraft:concrete 14
fill ~37~55~10 ~37~56~10 minecraft:stained_glass 14
fill ~37~59~10 ~37~60~11 minecraft:stained_glass 14
setblock ~37~61~10 minecraft:concrete 14
fill ~37~62~10 ~37~62~11 minecraft:stained_glass 14
fill ~37~63~10 ~38~63~10 minecraft:stained_glass 14
fill ~37~64~10 ~37~64~11 minecraft:stained_glass 14
fill ~37~66~10 ~37~66~11 minecraft:concrete 14
fill ~37~68~10 ~37~70~10 minecraft:stained_glass 14
fill ~37~71~10 ~37~71~11 minecraft:red_glazed_terracotta 3
setblock ~37~73~10 minecraft:concrete 14
setblock ~38~39~10 minecraft:red_glazed_terracotta 3
fill ~38~41~10 ~38~42~10 minecraft:stained_glass 14
fill ~38~44~10 ~38~44~11 minecraft:stained_glass 14
fill ~38~46~10 ~38~47~12 minecraft:stained_glass 14
fill ~38~49~10 ~39~49~10 minecraft:red_glazed_terracotta 3
setblock ~38~51~10 minecraft:concrete 14
fill ~38~52~10 ~39~52~10 minecraft:stained_glass 14
setblock ~38~54~10 minecraft:red_glazed_terracotta 3
setblock ~38~55~10 minecraft:concrete 14
setblock ~38~56~10 minecraft:stained_glass 14
setblock ~38~58~10 minecraft:concrete 14
setblock ~38~59~10 minecraft:red_glazed_terracotta 3
setblock ~38~60~10 minecraft:concrete 14
setblock ~38~61~10 minecraft:stained_glass 14
fill ~38~64~10 ~38~65~10 minecraft:concrete 14
setblock ~38~69~10 minecraft:red_glazed_terracotta 3
setblock ~38~70~10 minecraft:stained_glass 14
setblock ~38~71~10 minecraft:concrete 14
fill ~38~73~10 ~39~73~11 minecraft:stained_glass 14
fill ~39~39~10 ~40~39~11 minecraft:stained_glass 14
setblock ~39~41~10 minecraft:concrete 14
fill ~39~42~10 ~39~42~11 minecraft:stained_glass 14
fill ~39~44~10 ~39~45~10 minecraft:concrete 14
setblock ~39~48~10 minecraft:red_glazed_terracotta 3
setblock ~39~54~10 minecraft:concrete 14
fill ~39~59~10 ~39~60~10 minecraft:stained_glass 14
setblock ~39~61~10 minecraft:red_glazed_terracotta 3
setblock ~39~64~10 minecraft:stained_glass 14
setblock ~39~70~10 minecraft:concrete 14
fill ~39~71~10 ~39~71~11 minecraft:stained_glass 14
setblock ~39~72~10 minecraft:red_glazed_terracotta 3
setblock ~40~38~10 minecraft:red_glazed_terracotta 3
setblock ~40~42~10 minecraft:concrete 14
fill ~40~43~10 ~41~43~10 minecraft:stained_glass 14
fill ~40~45~10 ~41~45~10 minecraft:concrete 14
setblock ~40~46~10 minecraft:red_glazed_terracotta 3
fill ~40~48~10 ~40~49~11 minecraft:stained_glass 14
fill ~40~50~10 ~40~50~11 minecraft:concrete 14
fill ~40~52~10 ~41~52~10 minecraft:red_glazed_terracotta 3
setblock ~40~53~10 minecraft:stained_glass 14
setblock ~40~60~10 minecraft:red_glazed_terracotta 3
fill ~40~61~10 ~40~61~11 minecraft:stained_glass 14
fill ~40~62~10 ~40~63~10 minecraft:concrete 14
setblock ~40~64~10 minecraft:red_glazed_terracotta 3
fill ~40~70~10 ~40~71~10 minecraft:red_glazed_terracotta 3
fill ~40~72~10 ~41~72~10 minecraft:stained_glass 14
fill ~40~73~10 ~40~73~11 minecraft:concrete 14
setblock ~41~37~10 minecraft:red_glazed_terracotta 3
fill ~41~38~10 ~41~39~10 minecraft:concrete 14
fill ~41~40~10 ~42~40~10 minecraft:red_glazed_terracotta 3
fill ~41~41~10 ~41~41~12 minecraft:stained_glass 14
fill ~41~44~10 ~41~44~11 minecraft:stained_glass 14
fill ~41~46~10 ~41~46~11 minecraft:concrete 14
fill ~41~47~10 ~41~47~11 minecraft:stained_glass 14
fill ~41~49~10 ~43~49~10 minecraft:stained_glass 14
fill ~41~50~10 ~42~50~10 minecraft:stained_glass 14
setblock ~41~51~10 minecraft:stained_glass 14
fill ~41~62~10 ~42~62~10 minecraft:stained_glass 14
setblock ~41~63~10 minecraft:red_glazed_terracotta 3
fill ~41~70~10 ~41~70~12 minecraft:stained_glass 14
fill ~41~71~10 ~42~71~10 minecraft:concrete 14
setblock ~41~73~10 minecraft:red_glazed_terracotta 3
fill ~42~36~10 ~42~36~12 minecraft:stained_glass 14
fill ~42~37~10 ~43~37~10 minecraft:stained_glass 14
fill ~42~38~10 ~42~38~11 minecraft:stained_glass 14
fill ~42~42~10 ~42~42~11 minecraft:stained_glass 14
setblock ~42~46~10 minecraft:stained_glass 14
setblock ~42~47~10 minecraft:red_glazed_terracotta 3
fill ~42~60~10 ~43~60~10 minecraft:stained_glass 14
setblock ~42~61~10 minecraft:red_glazed_terracotta 3
fill ~42~63~10 ~42~63~11 minecraft:stained_glass 14
setblock ~42~64~10 minecraft:stained_glass 14
setblock ~42~69~10 minecraft:red_glazed_terracotta 3
fill ~42~70~10 ~42~70~11 minecraft:concrete 14
setblock ~42~72~10 minecraft:red_glazed_terracotta 3
fill ~42~73~10 ~43~73~10 minecraft:stained_glass 14
setblock ~43~35~10 minecraft:concrete 14
setblock ~43~36~10 minecraft:red_glazed_terracotta 3
fill ~43~40~10 ~43~41~11 minecraft:stained_glass 14
fill ~43~47~10 ~44~47~10 minecraft:concrete 14
setblock ~43~48~10 minecraft:red_glazed_terracotta 3
fill ~43~50~10 ~43~51~10 minecraft:red_glazed_terracotta 3
fill ~43~59~10 ~45~59~10 minecraft:stained_glass 14
fill ~43~62~10 ~44~62~10 minecraft:red_glazed_terracotta 3
fill ~43~64~10 ~43~65~10 minecraft:concrete 14
fill ~43~69~10 ~43~69~11 minecraft:concrete 14
setblock ~43~71~10 minecraft:red_glazed_terracotta 3
fill ~43~72~10 ~44~72~10 minecraft:stained_glass 14
setblock ~44~34~10 minecraft:concrete 14
fill ~44~35~10 ~47~35~10 minecraft:stained_glass 14
setblock ~44~36~10 minecraft:stained_glass 14
setblock ~44~37~10 minecraft:red_glazed_terracotta 3
fill ~44~38~10 ~44~39~10 minecraft:stained_glass 14
setblock ~44~40~10 minecraft:concrete 14
fill ~44~48~10 ~45~48~10 minecraft:stained_glass 14
setblock ~44~49~10 minecraft:red_glazed_terracotta 3
fill ~44~50~10 ~44~51~10 minecraft:stained_glass 14
fill ~44~63~10 ~46~63~10 minecraft:stained_glass 14
fill ~44~64~10 ~45~64~11 minecraft:stained_glass 14
fill ~44~65~10 ~46~65~10 minecraft:red_glazed_terracotta 3
setblock ~44~66~10 minecraft:red_glazed_terracotta 3
setblock ~44~67~10 minecraft:stained_glass 14
fill ~44~68~10 ~44~68~11 minecraft:concrete 14
fill ~44~69~10 ~45~69~10 minecraft:stained_glass 14
setblock ~44~70~10 minecraft:red_glazed_terracotta 3
setblock ~44~71~10 minecraft:stained_glass 14
fill ~44~73~10 ~44~73~11 minecraft:concrete 14
fill ~45~33~10 ~47~33~10 minecraft:red_glazed_terracotta 3
setblock ~45~34~10 minecraft:stained_glass 14
setblock ~45~36~10 minecraft:concrete 14
fill ~45~37~10 ~45~37~12 minecraft:stained_glass 14
fill ~45~38~10 ~45~39~10 minecraft:red_glazed_terracotta 3
fill ~45~46~10 ~45~47~10 minecraft:stained_glass 14
fill ~45~49~10 ~46~49~10 minecraft:stained_glass 14
fill ~45~50~10 ~46~50~10 minecraft:red_glazed_terracotta 3
setblock ~45~58~10 minecraft:concrete 14
setblock ~45~60~10 minecraft:stained_glass 14
setblock ~45~61~10 minecraft:red_glazed_terracotta 3
setblock ~45~62~10 minecraft:concrete 14
fill ~45~67~10 ~45~67~11 minecraft:red_glazed_terracotta 3
fill ~45~68~10 ~45~68~11 minecraft:stained_glass 14
setblock ~45~72~10 minecraft:red_glazed_terracotta 3
fill ~45~73~10 ~45~73~12 minecraft:stained_glass 14
fill ~46~32~10 ~46~32~11 minecraft:stained_glass 14
fill ~46~34~10 ~46~34~11 minecraft:concrete 14
fill ~46~36~10 ~46~36~11 minecraft:red_glazed_terracotta 3
fill ~46~38~10 ~48~38~10 minecraft:stained_glass 14
fill ~46~39~10 ~48~39~10 minecraft:red_glazed_terracotta 3
setblock ~46~46~10 minecraft:red_glazed_terracotta 3
setblock ~46~47~10 minecraft:stained_glass 14
setblock ~46~48~10 minecraft:red_glazed_terracotta 3
fill ~46~58~10 ~46~60~10 minecraft:red_glazed_terracotta 3
setblock ~46~61~10 minecraft:concrete 14
fill ~46~66~10 ~46~66~11 minecraft:concrete 14
fill ~46~69~10 ~47~69~10 minecraft:concrete 14
fill ~46~70~10 ~46~71~10 minecraft:concrete 14
setblock ~46~72~10 minecraft:stained_glass 14
setblock ~46~73~10 minecraft:red_glazed_terracotta 3
fill ~47~32~10 ~47~32~12 minecraft:concrete 14
fill ~47~34~10 ~48~34~10 minecraft:stained_glass 14
fill ~47~36~10 ~47~36~11 minecraft:stained_glass 14
fill ~47~37~10 ~48~37~10 minecraft:concrete 14
fill ~47~47~10 ~48~47~10 minecraft:concrete 14
setblock ~47~48~10 minecraft:concrete 14
setblock ~47~49~10 minecraft:red_glazed_terracotta 3
setblock ~47~50~10 minecraft:stained_glass 14
fill ~47~58~10 ~47~60~10 minecraft:stained_glass 14
fill ~47~64~10 ~48~64~10 minecraft:stained_glass 14
setblock ~47~65~10 minecraft:stained_glass 14
setblock ~47~66~10 minecraft:red_glazed_terracotta 3
setblock ~47~70~10 minecraft:red_glazed_terracotta 3
setblock ~47~71~10 minecraft:stained_glass 14
setblock ~47~72~10 minecraft:concrete 14
fill ~47~73~10 ~47~73~11 minecraft:stained_glass 14
fill ~48~32~10 ~48~32~11 minecraft:stained_glass 14
setblock ~48~33~10 minecraft:concrete 14
fill ~48~35~10 ~49~35~10 minecraft:concrete 14
fill ~48~36~10 ~48~36~11 minecraft:concrete 14
setblock ~48~44~10 minecraft:red_glazed_terracotta 3
fill ~48~48~10 ~49~49~10 minecraft:stained_glass 14
setblock ~48~51~10 minecraft:concrete 14
fill ~48~57~10 ~49~57~10 minecraft:stained_glass 14
fill ~48~59~10 ~49~59~10 minecraft:red_glazed_terracotta 3
setblock ~48~60~10 minecraft:red_glazed_terracotta 3
fill ~48~66~10 ~49~66~10 minecraft:stained_glass 14
fill ~48~69~10 ~49~69~10 minecraft:red_glazed_terracotta 3
setblock ~48~70~10 minecraft:concrete 14
fill ~48~71~10 ~50~71~10 minecraft:red_glazed_terracotta 3
setblock ~48~72~10 minecraft:stained_glass 14
fill ~48~73~10 ~49~73~11 minecraft:red_glazed_terracotta 3
fill ~49~33~10 ~49~34~11 minecraft:red_glazed_terracotta 3
fill ~49~38~10 ~49~41~10 minecraft:concrete 14
fill ~49~42~10 ~51~42~10 minecraft:stained_glass 14
fill ~49~44~10 ~50~44~10 minecraft:stained_glass 14
fill ~49~45~10 ~49~46~10 minecraft:stained_glass 14
fill ~49~47~10 ~50~47~10 minecraft:red_glazed_terracotta 3
fill ~49~50~10 ~50~50~10 minecraft:red_glazed_terracotta 3
setblock ~49~51~10 minecraft:red_glazed_terracotta 3
setblock ~49~56~10 minecraft:stained_glass 14
setblock ~49~58~10 minecraft:stained_glass 14
setblock ~49~63~10 minecraft:stained_glass 14
setblock ~49~64~10 minecraft:concrete 14
fill ~49~67~10 ~49~67~11 minecraft:red_glazed_terracotta 3
setblock ~49~68~10 minecraft:red_glazed_terracotta 3
fill ~49~70~10 ~49~70~11 minecraft:red_glazed_terracotta 3
setblock ~49~72~10 minecraft:red_glazed_terracotta 3
fill ~50~34~10 ~50~35~10 minecraft:red_glazed_terracotta 3
setblock ~50~36~10 minecraft:concrete 14
fill ~50~38~10 ~50~38~11 minecraft:stained_glass 14
fill ~50~40~10 ~50~41~10 minecraft:stained_glass 14
setblock ~50~46~10 minecraft:red_glazed_terracotta 3
setblock ~50~48~10 minecraft:red_glazed_terracotta 3
fill ~50~49~10 ~51~49~10 minecraft:concrete 14
setblock ~50~51~10 minecraft:stained_glass 14
setblock ~50~58~10 minecraft:red_glazed_terracotta 3
fill ~50~59~10 ~50~60~10 minecraft:concrete 14
fill ~50~61~10 ~50~62~10 minecraft:red_glazed_terracotta 3
fill ~50~64~10 ~51~64~10 minecraft:red_glazed_terracotta 3
setblock ~50~65~10 minecraft:red_glazed_terracotta 3
fill ~50~72~10 ~50~73~10 minecraft:concrete 14
fill ~51~35~10 ~51~36~11 minecraft:stained_glass 14
setblock ~51~37~10 minecraft:red_glazed_terracotta 3
fill ~51~38~10 ~52~38~10 minecraft:concrete 14
setblock ~51~39~10 minecraft:stained_glass 14
fill ~51~40~10 ~52~40~10 minecraft:concrete 14
setblock ~51~41~10 minecraft:red_glazed_terracotta 3
fill ~51~46~10 ~52~46~10 minecraft:concrete 14
setblock ~51~48~10 minecraft:concrete 14
setblock ~51~50~10 minecraft:concrete 14
setblock ~51~58~10 minecraft:concrete 14
setblock ~51~59~10 minecraft:red_glazed_terracotta 3
setblock ~51~62~10 minecraft:red_glazed_terracotta 3
fill ~51~65~10 ~51~65~11 minecraft:stained_glass 14
setblock ~51~67~10 minecraft:stained_glass 14
setblock ~51~73~10 minecraft:stained_glass 14
setblock ~52~35~10 minecraft:concrete 14
setblock ~52~36~10 minecraft:stained_glass 14
setblock ~52~37~10 minecraft:concrete 14
fill ~52~39~10 ~53~39~11 minecraft:concrete 14
setblock ~52~41~10 minecraft:concrete 14
fill ~52~42~10 ~53~43~10 minecraft:red_glazed_terracotta 3
setblock ~52~49~10 minecraft:stained_glass 14
setblock ~52~59~10 minecraft:concrete 14
setblock ~52~61~10 minecraft:stained_glass 14
setblock ~52~62~10 minecraft:concrete 14
setblock ~52~63~10 minecraft:stained_glass 14
fill ~52~64~10 ~52~65~10 minecraft:concrete 14
fill ~53~36~10 ~54~36~10 minecraft:red_glazed_terracotta 3
fill ~53~37~10 ~54~38~10 minecraft:stained_glass 14
fill ~53~40~10 ~54~40~10 minecraft:stained_glass 14
setblock ~53~41~10 minecraft:red_glazed_terracotta 3
setblock ~53~44~10 minecraft:red_glazed_terracotta 3
fill ~53~60~10 ~54~60~10 minecraft:red_glazed_terracotta 3
setblock ~53~61~10 minecraft:red_glazed_terracotta 3
setblock ~53~62~10 minecraft:stained_glass 14
fill ~53~63~10 ~54~63~10 minecraft:red_glazed_terracotta 3
fill ~53~64~10 ~53~65~10 minecraft:stained_glass 14
fill ~54~35~10 ~57~35~10 minecraft:stained_glass 14
setblock ~54~39~10 minecraft:red_glazed_terracotta 3
fill ~54~41~10 ~54~42~10 minecraft:stained_glass 14
fill ~54~61~10 ~55~61~10 minecraft:stained_glass 14
setblock ~54~62~10 minecraft:concrete 14
setblock ~54~64~10 minecraft:red_glazed_terracotta 3
setblock ~55~38~10 minecraft:stained_glass 14
setblock ~55~41~10 minecraft:concrete 14
setblock ~55~60~10 minecraft:stained_glass 14
fill ~55~62~10 ~56~62~10 minecraft:red_glazed_terracotta 3
fill ~55~63~10 ~56~63~10 minecraft:stained_glass 14
setblock ~55~64~10 minecraft:stained_glass 14
setblock ~56~34~10 minecraft:concrete 14
setblock ~56~38~10 minecraft:red_glazed_terracotta 3
fill ~56~39~10 ~56~39~11 minecraft:stained_glass 14
fill ~56~40~10 ~56~41~10 minecraft:stained_glass 14
setblock ~56~64~10 minecraft:red_glazed_terracotta 3
fill ~57~33~10 ~58~33~11 minecraft:stained_glass 14
setblock ~57~34~10 minecraft:red_glazed_terracotta 3
fill ~57~37~10 ~58~37~10 minecraft:concrete 14
fill ~57~39~10 ~57~39~11 minecraft:concrete 14
fill ~57~62~10 ~59~62~10 minecraft:stained_glass 14
fill ~58~31~10 ~59~31~10 minecraft:concrete 14
fill ~58~32~10 ~58~32~12 minecraft:concrete 14
fill ~58~34~10 ~58~35~10 minecraft:concrete 14
setblock ~58~39~10 minecraft:red_glazed_terracotta 3
setblock ~58~40~10 minecraft:concrete 14
fill ~58~51~10 ~60~51~10 minecraft:stained_glass 14
fill ~58~63~10 ~58~64~10 minecraft:stained_glass 14
setblock ~59~30~10 minecraft:stained_glass 14
fill ~59~32~10 ~59~32~11 minecraft:red_glazed_terracotta 3
setblock ~59~33~10 minecraft:red_glazed_terracotta 3
fill ~59~34~10 ~60~34~10 minecraft:stained_glass 14
fill ~59~35~10 ~60~35~10 minecraft:red_glazed_terracotta 3
setblock ~59~37~10 minecraft:red_glazed_terracotta 3
fill ~59~38~10 ~61~38~10 minecraft:stained_glass 14
fill ~59~39~10 ~59~39~11 minecraft:stained_glass 14
setblock ~59~40~10 minecraft:red_glazed_terracotta 3
setblock ~59~61~10 minecraft:stained_glass 14
setblock ~59~63~10 minecraft:red_glazed_terracotta 3
fill ~59~64~10 ~60~64~10 minecraft:concrete 14
setblock ~60~30~10 minecraft:red_glazed_terracotta 3
fill ~60~31~10 ~61~31~10 minecraft:stained_glass 14
fill ~60~32~10 ~60~32~11 minecraft:stained_glass 14
fill ~60~33~10 ~61~33~10 minecraft:stained_glass 14
setblock ~60~36~10 minecraft:stained_glass 14
fill ~60~39~10 ~60~39~11 minecraft:red_glazed_terracotta 3
setblock ~60~50~10 minecraft:red_glazed_terracotta 3
setblock ~60~52~10 minecraft:stained_glass 14
setblock ~60~60~10 minecraft:stained_glass 14
setblock ~60~62~10 minecraft:concrete 14
fill ~60~63~10 ~63~63~10 minecraft:stained_glass 14
fill ~60~65~10 ~60~65~11 minecraft:stained_glass 14
setblock ~60~66~10 minecraft:stained_glass 14
setblock ~61~32~10 minecraft:concrete 14
setblock ~61~34~10 minecraft:concrete 14
fill ~61~35~10 ~62~35~11 minecraft:stained_glass 14
fill ~61~36~10 ~61~36~12 minecraft:concrete 14
fill ~61~39~10 ~62~39~10 minecraft:concrete 14
setblock ~61~40~10 minecraft:red_glazed_terracotta 3
setblock ~61~51~10 minecraft:concrete 14
fill ~61~52~10 ~62~52~10 minecraft:red_glazed_terracotta 3
setblock ~61~53~10 minecraft:red_glazed_terracotta 3
fill ~61~59~10 ~62~59~10 minecraft:red_glazed_terracotta 3
setblock ~61~60~10 minecraft:concrete 14
setblock ~61~62~10 minecraft:red_glazed_terracotta 3
fill ~61~65~10 ~61~66~10 minecraft:concrete 14
fill ~62~31~10 ~62~31~11 minecraft:concrete 14
setblock ~62~32~10 minecraft:stained_glass 14
setblock ~62~33~10 minecraft:red_glazed_terracotta 3
fill ~62~37~10 ~62~37~11 minecraft:stained_glass 14
fill ~62~40~10 ~63~40~10 minecraft:concrete 14
fill ~62~41~10 ~62~41~11 minecraft:stained_glass 14
fill ~62~42~10 ~63~42~10 minecraft:stained_glass 14
fill ~62~50~10 ~64~50~10 minecraft:stained_glass 14
fill ~62~51~10 ~63~51~10 minecraft:stained_glass 14
setblock ~62~53~10 minecraft:stained_glass 14
fill ~62~56~10 ~63~56~10 minecraft:stained_glass 14
setblock ~62~58~10 minecraft:concrete 14
fill ~62~61~10 ~63~61~10 minecraft:stained_glass 14
setblock ~62~62~10 minecraft:stained_glass 14
fill ~62~64~10 ~62~65~10 minecraft:red_glazed_terracotta 3
setblock ~62~66~10 minecraft:concrete 14
fill ~62~68~10 ~62~68~11 minecraft:concrete 14
setblock ~62~69~10 minecraft:stained_glass 14
fill ~62~72~10 ~63~73~10 minecraft:stained_glass 14
setblock ~63~37~10 minecraft:concrete 14
fill ~63~38~10 ~64~38~10 minecraft:stained_glass 14
setblock ~63~43~10 minecraft:concrete 14
fill ~63~49~10 ~64~49~10 minecraft:red_glazed_terracotta 3
setblock ~63~53~10 minecraft:concrete 14
setblock ~63~54~10 minecraft:stained_glass 14
setblock ~63~55~10 minecraft:red_glazed_terracotta 3
setblock ~63~57~10 minecraft:stained_glass 14
setblock ~63~59~10 minecraft:concrete 14
fill ~63~60~10 ~64~60~10 minecraft:stained_glass 14
setblock ~63~62~10 minecraft:red_glazed_terracotta 3
fill ~63~64~10 ~64~64~11 minecraft:stained_glass 14
fill ~63~65~10 ~63~65~11 minecraft:stained_glass 14
fill ~63~66~10 ~64~66~10 minecraft:red_glazed_terracotta 3
setblock ~63~68~10 minecraft:red_glazed_terracotta 3
fill ~63~70~10 ~63~71~10 minecraft:red_glazed_terracotta 3
fill ~64~39~10 ~64~40~10 minecraft:red_glazed_terracotta 3
fill ~64~43~10 ~65~43~10 minecraft:stained_glass 14
fill ~64~45~10 ~69~45~10 minecraft:stained_glass 14
setblock ~64~48~10 minecraft:stained_glass 14
setblock ~64~51~10 minecraft:concrete 14
setblock ~64~52~10 minecraft:red_glazed_terracotta 3
setblock ~64~54~10 minecraft:red_glazed_terracotta 3
fill ~64~56~10 ~65~56~10 minecraft:red_glazed_terracotta 3
setblock ~64~57~10 minecraft:red_glazed_terracotta 3
fill ~64~58~10 ~65~58~10 minecraft:concrete 14
setblock ~64~59~10 minecraft:red_glazed_terracotta 3
setblock ~64~63~10 minecraft:concrete 14
setblock ~64~65~10 minecraft:concrete 14
fill ~64~68~10 ~65~68~10 minecraft:stained_glass 14
setblock ~64~70~10 minecraft:concrete 14
fill ~64~71~10 ~64~73~10 minecraft:red_glazed_terracotta 3
setblock ~65~39~10 minecraft:stained_glass 14
setblock ~65~41~10 minecraft:concrete 14
setblock ~65~44~10 minecraft:red_glazed_terracotta 3
fill ~65~46~10 ~66~46~10 minecraft:stained_glass 14
fill ~65~47~10 ~68~47~10 minecraft:red_glazed_terracotta 3
setblock ~65~48~10 minecraft:red_glazed_terracotta 3
fill ~65~49~10 ~70~49~10 minecraft:stained_glass 14
setblock ~65~50~10 minecraft:red_glazed_terracotta 3
fill ~65~51~10 ~66~51~10 minecraft:stained_glass 14
fill ~65~52~10 ~65~53~10 minecraft:stained_glass 14
setblock ~65~55~10 minecraft:stained_glass 14
setblock ~65~57~10 minecraft:concrete 14
setblock ~65~59~10 minecraft:concrete 14
setblock ~65~64~10 minecraft:concrete 14
setblock ~65~66~10 minecraft:concrete 14
fill ~65~69~10 ~65~69~11 minecraft:red_glazed_terracotta 3
fill ~65~71~10 ~67~71~10 minecraft:stained_glass 14
fill ~65~72~10 ~65~72~12 minecraft:stained_glass 14
fill ~65~73~10 ~65~73~11 minecraft:red_glazed_terracotta 3
fill ~66~38~10 ~67~38~10 minecraft:red_glazed_terracotta 3
fill ~66~39~10 ~66~39~11 minecraft:concrete 14
setblock ~66~40~10 minecraft:red_glazed_terracotta 3
fill ~66~44~10 ~67~44~10 minecraft:stained_glass 14
setblock ~66~48~10 minecraft:concrete 14
fill ~66~50~10 ~67~50~10 minecraft:stained_glass 14
setblock ~66~52~10 minecraft:concrete 14
setblock ~66~55~10 minecraft:red_glazed_terracotta 3
fill ~66~56~10 ~67~57~10 minecraft:stained_glass 14
fill ~66~58~10 ~66~60~10 minecraft:stained_glass 14
fill ~66~68~10 ~66~68~11 minecraft:red_glazed_terracotta 3
setblock ~66~72~10 minecraft:concrete 14
fill ~66~73~10 ~68~73~11 minecraft:stained_glass 14
fill ~67~39~10 ~68~39~10 minecraft:red_glazed_terracotta 3
setblock ~67~40~10 minecraft:stained_glass 14
setblock ~67~41~10 minecraft:concrete 14
setblock ~67~46~10 minecraft:concrete 14
fill ~67~48~10 ~67~48~11 minecraft:stained_glass 14
setblock ~67~51~10 minecraft:concrete 14
fill ~67~52~10 ~68~52~10 minecraft:red_glazed_terracotta 3
setblock ~67~58~10 minecraft:concrete 14
setblock ~67~59~10 minecraft:stained_glass 14
setblock ~67~66~10 minecraft:concrete 14
fill ~67~68~10 ~70~68~10 minecraft:stained_glass 14
fill ~67~72~10 ~68~72~11 minecraft:stained_glass 14
setblock ~68~38~10 minecraft:concrete 14
setblock ~68~41~10 minecraft:red_glazed_terracotta 3
fill ~68~43~10 ~69~43~10 minecraft:red_glazed_terracotta 3
setblock ~68~44~10 minecraft:concrete 14
setblock ~68~46~10 minecraft:stained_glass 14
setblock ~68~48~10 minecraft:concrete 14
setblock ~68~50~10 minecraft:red_glazed_terracotta 3
setblock ~68~51~10 minecraft:stained_glass 14
fill ~68~58~10 ~69~58~10 minecraft:stained_glass 14
fill ~68~59~10 ~68~60~10 minecraft:concrete 14
setblock ~68~61~10 minecraft:stained_glass 14
fill ~68~65~10 ~68~66~10 minecraft:red_glazed_terracotta 3
setblock ~68~67~10 minecraft:stained_glass 14
fill ~68~69~10 ~68~69~11 minecraft:stained_glass 14
setblock ~68~70~10 minecraft:stained_glass 14
setblock ~68~71~10 minecraft:concrete 14
fill ~69~38~10 ~70~38~12 minecraft:stained_glass 14
setblock ~69~39~10 minecraft:concrete 14
setblock ~69~40~10 minecraft:red_glazed_terracotta 3
fill ~69~41~10 ~70~41~10 minecraft:stained_glass 14
setblock ~69~42~10 minecraft:concrete 14
setblock ~69~44~10 minecraft:red_glazed_terracotta 3
setblock ~69~46~10 minecraft:red_glazed_terracotta 3
setblock ~69~47~10 minecraft:concrete 14
setblock ~69~50~10 minecraft:concrete 14
fill ~69~59~10 ~71~59~10 minecraft:stained_glass 14
setblock ~69~61~10 minecraft:concrete 14
setblock ~69~65~10 minecraft:concrete 14
setblock ~69~67~10 minecraft:red_glazed_terracotta 3
setblock ~69~69~10 minecraft:concrete 14
setblock ~69~70~10 minecraft:red_glazed_terracotta 3
setblock ~70~39~10 minecraft:red_glazed_terracotta 3
fill ~70~40~10 ~71~40~10 minecraft:concrete 14
fill ~70~42~10 ~72~42~10 minecraft:stained_glass 14
fill ~70~43~10 ~70~44~10 minecraft:concrete 14
setblock ~70~45~10 minecraft:red_glazed_terracotta 3
fill ~70~47~10 ~70~47~11 minecraft:red_glazed_terracotta 3
fill ~70~48~10 ~70~48~11 minecraft:stained_glass 14
fill ~70~50~10 ~70~50~11 minecraft:stained_glass 14
fill ~70~51~10 ~70~52~10 minecraft:red_glazed_terracotta 3
setblock ~70~58~10 minecraft:red_glazed_terracotta 3
setblock ~70~60~10 minecraft:stained_glass 14
fill ~70~62~10 ~71~62~10 minecraft:stained_glass 14
setblock ~70~67~10 minecraft:concrete 14
setblock ~70~69~10 minecraft:red_glazed_terracotta 3
setblock ~71~39~10 minecraft:stained_glass 14
fill ~71~41~10 ~72~41~10 minecraft:red_glazed_terracotta 3
setblock ~71~47~10 minecraft:stained_glass 14
fill ~71~49~10 ~71~49~11 minecraft:red_glazed_terracotta 3
fill ~71~50~10 ~71~50~11 minecraft:concrete 14
setblock ~71~52~10 minecraft:concrete 14
setblock ~71~60~10 minecraft:red_glazed_terracotta 3
setblock ~71~61~10 minecraft:stained_glass 14
fill ~71~63~10 ~71~64~10 minecraft:stained_glass 14
setblock ~71~65~10 minecraft:concrete 14
fill ~71~67~10 ~71~67~11 minecraft:stained_glass 14
setblock ~71~68~10 minecraft:red_glazed_terracotta 3
setblock ~71~69~10 minecraft:stained_glass 14
setblock ~72~40~10 minecraft:stained_glass 14
setblock ~72~48~10 minecraft:red_glazed_terracotta 3
setblock ~72~49~10 minecraft:concrete 14
fill ~72~50~10 ~73~50~10 minecraft:stained_glass 14
setblock ~72~51~10 minecraft:concrete 14
fill ~72~52~10 ~72~52~11 minecraft:stained_glass 14
fill ~72~53~10 ~73~53~10 minecraft:red_glazed_terracotta 3
fill ~72~60~10 ~73~60~11 minecraft:stained_glass 14
setblock ~72~61~10 minecraft:red_glazed_terracotta 3
fill ~72~63~10 ~72~63~11 minecraft:concrete 14
fill ~72~64~10 ~72~64~11 minecraft:stained_glass 14
fill ~72~66~10 ~74~66~10 minecraft:stained_glass 14
fill ~72~67~10 ~73~67~10 minecraft:red_glazed_terracotta 3
fill ~72~68~10 ~73~68~10 minecraft:stained_glass 14
fill ~72~69~10 ~74~69~10 minecraft:concrete 14
setblock ~73~41~10 minecraft:concrete 14
fill ~73~49~10 ~74~49~10 minecraft:red_glazed_terracotta 3
setblock ~73~52~10 minecraft:concrete 14
setblock ~73~59~10 minecraft:red_glazed_terracotta 3
setblock ~73~61~10 minecraft:concrete 14
fill ~73~65~10 ~73~65~12 minecraft:stained_glass 14
fill ~74~51~10 ~74~52~10 minecraft:red_glazed_terracotta 3
setblock ~74~53~10 minecraft:concrete 14
fill ~74~55~10 ~75~55~10 minecraft:red_glazed_terracotta 3
fill ~74~58~10 ~75~59~10 minecraft:stained_glass 14
fill ~74~62~10 ~74~62~11 minecraft:concrete 14
fill ~74~63~10 ~75~63~10 minecraft:stained_glass 14
fill ~74~64~10 ~74~64~11 minecraft:concrete 14
setblock ~74~67~10 minecraft:concrete 14
fill ~75~51~10 ~76~52~10 minecraft:stained_glass 14
setblock ~75~54~10 minecraft:red_glazed_terracotta 3
fill ~75~56~10 ~75~56~11 minecraft:concrete 14
fill ~75~57~10 ~76~57~10 minecraft:red_glazed_terracotta 3
setblock ~75~60~10 minecraft:stained_glass 14
fill ~75~61~10 ~75~61~11 minecraft:concrete 14
setblock ~75~64~10 minecraft:red_glazed_terracotta 3
fill ~75~65~10 ~75~65~11 minecraft:stained_glass 14
setblock ~75~66~10 minecraft:concrete 14
fill ~75~67~10 ~77~67~10 minecraft:stained_glass 14
setblock ~75~68~10 minecraft:concrete 14
fill ~75~69~10 ~75~69~13 minecraft:stained_glass 14
fill ~76~50~10 ~76~50~11 minecraft:stained_glass 14
fill ~76~54~10 ~76~55~10 minecraft:stained_glass 14
setblock ~76~56~10 minecraft:red_glazed_terracotta 3
setblock ~76~58~10 minecraft:red_glazed_terracotta 3
fill ~76~59~10 ~76~59~11 minecraft:concrete 14
fill ~76~60~10 ~77~60~10 minecraft:red_glazed_terracotta 3
fill ~76~61~10 ~76~61~12 minecraft:red_glazed_terracotta 3
setblock ~76~68~10 minecraft:stained_glass 14
fill ~76~69~10 ~78~69~10 minecraft:concrete 14
fill ~76~70~10 ~76~70~11 minecraft:concrete 14
fill ~77~50~10 ~77~50~11 minecraft:red_glazed_terracotta 3
setblock ~77~51~10 minecraft:concrete 14
setblock ~77~52~10 minecraft:red_glazed_terracotta 3
fill ~77~53~10 ~78~53~10 minecraft:concrete 14
fill ~77~54~10 ~77~55~10 minecraft:red_glazed_terracotta 3
fill ~77~56~10 ~79~56~10 minecraft:stained_glass 14
fill ~77~57~10 ~78~57~10 minecraft:concrete 14
setblock ~77~58~10 minecraft:stained_glass 14
setblock ~77~59~10 minecraft:red_glazed_terracotta 3
setblock ~77~62~10 minecraft:concrete 14
setblock ~77~68~10 minecraft:concrete 14
fill ~77~70~10 ~77~70~11 minecraft:stained_glass 14
fill ~78~51~10 ~78~52~10 minecraft:stained_glass 14
fill ~78~54~10 ~80~54~10 minecraft:stained_glass 14
setblock ~78~55~10 minecraft:red_glazed_terracotta 3
fill ~78~58~10 ~79~58~10 minecraft:concrete 14
setblock ~78~59~10 minecraft:stained_glass 14
fill ~78~61~10 ~79~61~10 minecraft:red_glazed_terracotta 3
fill ~78~62~10 ~78~62~11 minecraft:stained_glass 14
fill ~78~68~10 ~78~68~11 minecraft:stained_glass 14
setblock ~79~51~10 minecraft:red_glazed_terracotta 3
fill ~79~52~10 ~79~52~11 minecraft:stained_glass 14
fill ~79~53~10 ~79~53~11 minecraft:red_glazed_terracotta 3
fill ~79~55~10 ~79~55~11 minecraft:stained_glass 14
setblock ~79~57~10 minecraft:stained_glass 14
fill ~79~59~10 ~79~59~11 minecraft:concrete 14
setblock ~79~60~10 minecraft:stained_glass 14
setblock ~79~62~10 minecraft:red_glazed_terracotta 3
setblock ~79~63~10 minecraft:concrete 14
setblock ~80~53~10 minecraft:stained_glass 14
fill ~80~60~10 ~80~60~12 minecraft:concrete 14
fill ~80~61~10 ~80~61~11 minecraft:stained_glass 14
setblock ~80~62~10 minecraft:concrete 14
setblock ~80~63~10 minecraft:stained_glass 14
setblock ~80~64~10 minecraft:red_glazed_terracotta 3
setblock ~26~58~11 minecraft:concrete 14
fill ~26~59~11 ~27~59~12 minecraft:stained_glass 14
setblock ~26~60~11 minecraft:concrete 14
fill ~26~61~11 ~27~61~11 minecraft:red_glazed_terracotta 3
setblock ~26~62~11 minecraft:red_glazed_terracotta 3
fill ~27~55~11 ~27~56~11 minecraft:red_glazed_terracotta 3
fill ~27~57~11 ~28~57~11 minecraft:concrete 14
fill ~27~58~11 ~28~58~11 minecraft:stained_glass 14
setblock ~27~60~11 minecraft:red_glazed_terracotta 3
fill ~27~62~11 ~27~63~11 minecraft:stained_glass 14
fill ~27~66~11 ~27~66~12 minecraft:concrete 14
fill ~27~67~11 ~28~67~12 minecraft:stained_glass 14
setblock ~28~54~11 minecraft:concrete 14
fill ~28~55~11 ~28~56~12 minecraft:stained_glass 14
fill ~28~59~11 ~29~59~11 minecraft:concrete 14
fill ~28~60~11 ~28~61~12 minecraft:stained_glass 14
setblock ~28~62~11 minecraft:concrete 14
fill ~28~68~11 ~29~68~11 minecraft:stained_glass 14
fill ~28~69~11 ~28~69~12 minecraft:stained_glass 14
fill ~29~55~11 ~30~55~11 minecraft:concrete 14
setblock ~29~56~11 minecraft:concrete 14
fill ~29~57~11 ~30~57~12 minecraft:red_glazed_terracotta 3
fill ~29~58~11 ~32~58~11 minecraft:red_glazed_terracotta 3
setblock ~29~60~11 minecraft:red_glazed_terracotta 3
setblock ~29~61~11 minecraft:stained_glass 14
fill ~29~67~11 ~29~67~12 minecraft:red_glazed_terracotta 3
setblock ~29~69~11 minecraft:red_glazed_terracotta 3
fill ~29~70~11 ~31~70~12 minecraft:stained_glass 14
setblock ~30~56~11 minecraft:red_glazed_terracotta 3
setblock ~30~59~11 minecraft:red_glazed_terracotta 3
setblock ~30~60~11 minecraft:stained_glass 14
fill ~30~67~11 ~30~67~12 minecraft:concrete 14
fill ~30~68~11 ~31~68~11 minecraft:red_glazed_terracotta 3
setblock ~30~69~11 minecraft:stained_glass 14
fill ~31~55~11 ~31~55~12 minecraft:stained_glass 14
setblock ~31~57~11 minecraft:stained_glass 14
fill ~31~59~11 ~32~59~11 minecraft:stained_glass 14
setblock ~31~66~11 minecraft:red_glazed_terracotta 3
setblock ~31~69~11 minecraft:concrete 14
setblock ~32~43~11 minecraft:stained_glass 14
fill ~32~54~11 ~32~55~11 minecraft:concrete 14
setblock ~32~65~11 minecraft:concrete 14
fill ~32~66~11 ~32~67~12 minecraft:stained_glass 14
setblock ~32~68~11 minecraft:stained_glass 14
fill ~33~42~11 ~33~42~12 minecraft:stained_glass 14
fill ~33~43~11 ~34~43~11 minecraft:concrete 14
fill ~33~54~11 ~34~55~11 minecraft:stained_glass 14
setblock ~33~56~11 minecraft:red_glazed_terracotta 3
fill ~33~57~11 ~33~57~12 minecraft:stained_glass 14
fill ~33~58~11 ~34~58~12 minecraft:concrete 14
fill ~33~59~11 ~34~59~11 minecraft:red_glazed_terracotta 3
fill ~33~65~11 ~33~65~12 minecraft:red_glazed_terracotta 3
setblock ~33~66~11 minecraft:concrete 14
setblock ~33~67~11 minecraft:stained_glass 14
setblock ~33~70~11 minecraft:red_glazed_terracotta 3
setblock ~34~40~11 minecraft:stained_glass 14
fill ~34~41~11 ~34~42~11 minecraft:red_glazed_terracotta 3
setblock ~34~53~11 minecraft:red_glazed_terracotta 3
fill ~34~56~11 ~34~56~12 minecraft:stained_glass 14
setblock ~34~62~11 minecraft:concrete 14
fill ~34~63~11 ~36~63~11 minecraft:stained_glass 14
setblock ~34~64~11 minecraft:red_glazed_terracotta 3
fill ~34~66~11 ~34~66~12 minecraft:stained_glass 14
setblock ~34~68~11 minecraft:red_glazed_terracotta 3
setblock ~34~71~11 minecraft:stained_glass 14
fill ~34~72~11 ~35~72~12 minecraft:red_glazed_terracotta 3
fill ~34~73~11 ~34~73~14 minecraft:stained_glass 14
fill ~34~74~11 ~34~74~12 minecraft:stained_glass 14
fill ~34~75~11 ~35~75~11 minecraft:concrete 14
fill ~35~39~11 ~35~40~11 minecraft:concrete 14
fill ~35~41~11 ~35~42~11 minecraft:stained_glass 14
fill ~35~43~11 ~37~43~11 minecraft:red_glazed_terracotta 3
fill ~35~44~11 ~35~44~13 minecraft:stained_glass 14
fill ~35~52~11 ~36~52~11 minecraft:stained_glass 14
fill ~35~53~11 ~35~54~11 minecraft:concrete 14
setblock ~35~55~11 minecraft:red_glazed_terracotta 3
fill ~35~56~11 ~35~56~12 minecraft:concrete 14
fill ~35~57~11 ~35~58~11 minecraft:red_glazed_terracotta 3
fill ~35~60~11 ~36~60~11 minecraft:stained_glass 14
fill ~35~62~11 ~36~62~11 minecraft:stained_glass 14
fill ~35~64~11 ~36~64~11 minecraft:stained_glass 14
setblock ~35~66~11 minecraft:red_glazed_terracotta 3
fill ~35~67~11 ~35~67~12 minecraft:concrete 14
setblock ~35~69~11 minecraft:stained_glass 14
setblock ~35~71~11 minecraft:concrete 14
setblock ~35~73~11 minecraft:red_glazed_terracotta 3
fill ~35~74~11 ~36~74~11 minecraft:concrete 14
fill ~36~39~11 ~36~39~12 minecraft:red_glazed_terracotta 3
setblock ~36~40~11 minecraft:red_glazed_terracotta 3
setblock ~36~42~11 minecraft:red_glazed_terracotta 3
setblock ~36~45~11 minecraft:stained_glass 14
setblock ~36~49~11 minecraft:stained_glass 14
setblock ~36~50~11 minecraft:red_glazed_terracotta 3
setblock ~36~51~11 minecraft:stained_glass 14
setblock ~36~53~11 minecraft:red_glazed_terracotta 3
fill ~36~54~11 ~36~55~11 minecraft:concrete 14
setblock ~36~56~11 minecraft:red_glazed_terracotta 3
setblock ~36~57~11 minecraft:concrete 14
fill ~36~58~11 ~36~59~11 minecraft:red_glazed_terracotta 3
fill ~36~61~11 ~37~61~11 minecraft:stained_glass 14
fill ~36~68~11 ~37~68~11 minecraft:concrete 14
fill ~36~70~11 ~36~71~11 minecraft:stained_glass 14
fill ~36~73~11 ~37~73~11 minecraft:stained_glass 14
fill ~36~75~11 ~37~75~11 minecraft:stained_glass 14
fill ~37~39~11 ~38~39~11 minecraft:stained_glass 14
setblock ~37~40~11 minecraft:stained_glass 14
fill ~37~41~11 ~37~41~12 minecraft:red_glazed_terracotta 3
setblock ~37~42~11 minecraft:concrete 14
fill ~37~44~11 ~37~44~12 minecraft:stained_glass 14
setblock ~37~45~11 minecraft:red_glazed_terracotta 3
setblock ~37~46~11 minecraft:concrete 14
fill ~37~47~11 ~37~47~12 minecraft:stained_glass 14
fill ~37~48~11 ~39~48~11 minecraft:stained_glass 14
setblock ~37~49~11 minecraft:red_glazed_terracotta 3
setblock ~37~50~11 minecraft:stained_glass 14
fill ~37~51~11 ~37~52~11 minecraft:red_glazed_terracotta 3
setblock ~37~53~11 minecraft:concrete 14
fill ~37~54~11 ~38~54~11 minecraft:stained_glass 14
fill ~37~55~11 ~38~55~11 minecraft:red_glazed_terracotta 3
setblock ~37~56~11 minecraft:stained_glass 14
setblock ~37~57~11 minecraft:red_glazed_terracotta 3
fill ~37~63~11 ~38~63~11 minecraft:concrete 14
setblock ~37~65~11 minecraft:red_glazed_terracotta 3
setblock ~37~67~11 minecraft:concrete 14
fill ~37~69~11 ~37~69~12 minecraft:red_glazed_terracotta 3
setblock ~37~70~11 minecraft:concrete 14
fill ~37~74~11 ~37~74~13 minecraft:red_glazed_terracotta 3
fill ~38~40~11 ~39~40~11 minecraft:red_glazed_terracotta 3
setblock ~38~41~11 minecraft:concrete 14
fill ~38~42~11 ~38~42~12 minecraft:stained_glass 14
setblock ~38~45~11 minecraft:concrete 14
fill ~38~49~11 ~39~49~11 minecraft:stained_glass 14
fill ~38~50~11 ~39~50~11 minecraft:red_glazed_terracotta 3
fill ~38~51~11 ~38~52~11 minecraft:stained_glass 14
setblock ~38~53~11 minecraft:red_glazed_terracotta 3
fill ~38~58~11 ~38~60~11 minecraft:stained_glass 14
fill ~38~61~11 ~39~61~11 minecraft:concrete 14
fill ~38~64~11 ~39~64~11 minecraft:red_glazed_terracotta 3
fill ~38~69~11 ~39~69~11 minecraft:stained_glass 14
fill ~38~70~11 ~39~70~11 minecraft:red_glazed_terracotta 3
setblock ~38~71~11 minecraft:stained_glass 14
fill ~38~74~11 ~39~74~11 minecraft:stained_glass 14
setblock ~39~38~11 minecraft:concrete 14
fill ~39~43~11 ~39~44~11 minecraft:stained_glass 14
setblock ~39~45~11 minecraft:red_glazed_terracotta 3
setblock ~39~46~11 minecraft:stained_glass 14
setblock ~39~47~11 minecraft:red_glazed_terracotta 3
setblock ~39~52~11 minecraft:concrete 14
setblock ~39~53~11 minecraft:stained_glass 14
setblock ~39~60~11 minecraft:red_glazed_terracotta 3
setblock ~39~62~11 minecraft:concrete 14
fill ~39~63~11 ~40~63~11 minecraft:red_glazed_terracotta 3
fill ~39~72~11 ~40~72~11 minecraft:stained_glass 14
setblock ~40~38~11 minecraft:stained_glass 14
fill ~40~42~11 ~40~44~11 minecraft:red_glazed_terracotta 3
fill ~40~45~11 ~40~46~11 minecraft:concrete 14
fill ~40~51~11 ~40~52~11 minecraft:stained_glass 14
fill ~40~62~11 ~41~62~11 minecraft:stained_glass 14
fill ~40~70~11 ~40~70~12 minecraft:stained_glass 14
fill ~40~71~11 ~40~71~13 minecraft:concrete 14
fill ~41~37~11 ~41~37~12 minecraft:stained_glass 14
setblock ~41~38~11 minecraft:red_glazed_terracotta 3
fill ~41~39~11 ~42~39~11 minecraft:stained_glass 14
setblock ~41~40~11 minecraft:concrete 14
setblock ~41~42~11 minecraft:concrete 14
fill ~41~43~11 ~41~43~12 minecraft:red_glazed_terracotta 3
setblock ~41~45~11 minecraft:red_glazed_terracotta 3
setblock ~41~48~11 minecraft:concrete 14
fill ~41~49~11 ~41~50~11 minecraft:red_glazed_terracotta 3
setblock ~41~63~11 minecraft:stained_glass 14
fill ~41~69~11 ~42~69~11 minecraft:concrete 14
setblock ~41~72~11 minecraft:red_glazed_terracotta 3
fill ~41~73~11 ~41~73~12 minecraft:stained_glass 14
fill ~42~37~11 ~43~37~11 minecraft:concrete 14
fill ~42~40~11 ~42~40~12 minecraft:stained_glass 14
setblock ~42~41~11 minecraft:stained_glass 14
setblock ~42~47~11 minecraft:stained_glass 14
setblock ~42~48~11 minecraft:red_glazed_terracotta 3
setblock ~42~49~11 minecraft:concrete 14
setblock ~42~72~11 minecraft:stained_glass 14
setblock ~42~73~11 minecraft:concrete 14
fill ~43~35~11 ~45~35~11 minecraft:stained_glass 14
setblock ~43~36~11 minecraft:stained_glass 14
fill ~43~38~11 ~44~38~11 minecraft:concrete 14
setblock ~43~39~11 minecraft:concrete 14
fill ~43~72~11 ~43~72~12 minecraft:concrete 14
fill ~43~73~11 ~43~73~12 minecraft:red_glazed_terracotta 3
fill ~44~33~11 ~44~33~13 minecraft:stained_glass 14
setblock ~44~34~11 minecraft:stained_glass 14
fill ~44~36~11 ~44~36~12 minecraft:concrete 14
fill ~44~39~11 ~48~39~11 minecraft:stained_glass 14
setblock ~44~40~11 minecraft:stained_glass 14
setblock ~44~65~11 minecraft:red_glazed_terracotta 3
fill ~44~69~11 ~44~70~12 minecraft:stained_glass 14
fill ~44~72~11 ~45~72~12 minecraft:stained_glass 14
setblock ~44~74~11 minecraft:red_glazed_terracotta 3
fill ~45~30~11 ~45~34~11 minecraft:concrete 14
fill ~45~38~11 ~47~38~11 minecraft:stained_glass 14
setblock ~45~65~11 minecraft:stained_glass 14
fill ~45~69~11 ~45~69~12 minecraft:concrete 14
setblock ~45~74~11 minecraft:stained_glass 14
fill ~46~30~11 ~47~30~11 minecraft:stained_glass 14
setblock ~46~31~11 minecraft:concrete 14
fill ~46~33~11 ~47~33~11 minecraft:stained_glass 14
fill ~46~65~11 ~48~65~11 minecraft:concrete 14
fill ~46~67~11 ~47~67~11 minecraft:stained_glass 14
fill ~46~68~11 ~46~70~11 minecraft:stained_glass 14
setblock ~46~72~11 minecraft:red_glazed_terracotta 3
setblock ~46~73~11 minecraft:stained_glass 14
setblock ~46~74~11 minecraft:red_glazed_terracotta 3
setblock ~47~29~11 minecraft:red_glazed_terracotta 3
fill ~47~31~11 ~47~31~13 minecraft:stained_glass 14
setblock ~47~34~11 minecraft:concrete 14
setblock ~47~35~11 minecraft:stained_glass 14
fill ~47~37~11 ~49~37~11 minecraft:stained_glass 14
fill ~47~66~11 ~48~66~11 minecraft:concrete 14
setblock ~47~68~11 minecraft:concrete 14
fill ~47~69~11 ~47~70~11 minecraft:stained_glass 14
setblock ~47~72~11 minecraft:stained_glass 14
fill ~47~74~11 ~51~74~11 minecraft:stained_glass 14
fill ~47~75~11 ~49~75~11 minecraft:red_glazed_terracotta 3
fill ~48~29~11 ~49~29~11 minecraft:concrete 14
setblock ~48~30~11 minecraft:red_glazed_terracotta 3
fill ~48~31~11 ~48~31~13 minecraft:concrete 14
setblock ~48~33~11 minecraft:red_glazed_terracotta 3
fill ~48~35~11 ~48~35~12 minecraft:concrete 14
setblock ~48~38~11 minecraft:concrete 14
setblock ~48~67~11 minecraft:concrete 14
fill ~48~68~11 ~49~68~11 minecraft:stained_glass 14
setblock ~48~69~11 minecraft:red_glazed_terracotta 3
fill ~48~70~11 ~48~70~12 minecraft:stained_glass 14
setblock ~48~72~11 minecraft:concrete 14
fill ~49~28~11 ~49~28~12 minecraft:stained_glass 14
setblock ~49~30~11 minecraft:concrete 14
fill ~49~31~11 ~49~31~13 minecraft:stained_glass 14
setblock ~49~32~11 minecraft:concrete 14
setblock ~49~35~11 minecraft:red_glazed_terracotta 3
fill ~49~38~11 ~49~39~11 minecraft:red_glazed_terracotta 3
setblock ~49~40~11 minecraft:stained_glass 14
fill ~49~65~11 ~49~66~11 minecraft:stained_glass 14
setblock ~49~69~11 minecraft:stained_glass 14
fill ~49~71~11 ~49~71~12 minecraft:stained_glass 14
fill ~49~72~11 ~50~72~11 minecraft:stained_glass 14
fill ~49~76~11 ~49~76~12 minecraft:stained_glass 14
setblock ~50~34~11 minecraft:concrete 14
fill ~50~35~11 ~50~36~12 minecraft:stained_glass 14
fill ~50~37~11 ~51~37~11 minecraft:concrete 14
setblock ~50~39~11 minecraft:concrete 14
setblock ~50~40~11 minecraft:red_glazed_terracotta 3
fill ~50~41~11 ~51~41~11 minecraft:stained_glass 14
setblock ~50~65~11 minecraft:concrete 14
fill ~50~66~11 ~50~67~11 minecraft:stained_glass 14
setblock ~50~71~11 minecraft:red_glazed_terracotta 3
setblock ~50~73~11 minecraft:stained_glass 14
setblock ~50~75~11 minecraft:stained_glass 14
setblock ~50~76~11 minecraft:red_glazed_terracotta 3
fill ~51~38~11 ~54~38~11 minecraft:stained_glass 14
setblock ~51~39~11 minecraft:red_glazed_terracotta 3
setblock ~51~40~11 minecraft:stained_glass 14
fill ~51~72~11 ~52~73~11 minecraft:concrete 14
fill ~51~75~11 ~52~75~11 minecraft:red_glazed_terracotta 3
setblock ~52~36~11 minecraft:concrete 14
setblock ~52~37~11 minecraft:red_glazed_terracotta 3
fill ~52~40~11 ~53~40~11 minecraft:red_glazed_terracotta 3
setblock ~52~74~11 minecraft:red_glazed_terracotta 3
fill ~53~36~11 ~54~36~11 minecraft:stained_glass 14
setblock ~53~37~11 minecraft:stained_glass 14
fill ~53~72~11 ~53~73~12 minecraft:stained_glass 14
fill ~53~74~11 ~53~75~11 minecraft:stained_glass 14
fill ~54~37~11 ~55~37~11 minecraft:red_glazed_terracotta 3
setblock ~54~39~11 minecraft:stained_glass 14
setblock ~54~40~11 minecraft:concrete 14
fill ~54~73~11 ~56~73~11 minecraft:stained_glass 14
setblock ~54~74~11 minecraft:concrete 14
setblock ~54~75~11 minecraft:red_glazed_terracotta 3
setblock ~55~35~11 minecraft:concrete 14
setblock ~55~38~11 minecraft:red_glazed_terracotta 3
setblock ~55~39~11 minecraft:concrete 14
setblock ~55~40~11 minecraft:red_glazed_terracotta 3
fill ~55~74~11 ~55~74~14 minecraft:stained_glass 14
fill ~55~75~11 ~59~75~11 minecraft:stained_glass 14
fill ~56~34~11 ~56~35~11 minecraft:stained_glass 14
setblock ~56~36~11 minecraft:concrete 14
fill ~56~38~11 ~57~38~11 minecraft:stained_glass 14
setblock ~56~74~11 minecraft:red_glazed_terracotta 3
setblock ~57~32~11 minecraft:stained_glass 14
fill ~57~34~11 ~57~35~11 minecraft:concrete 14
fill ~57~36~11 ~57~37~11 minecraft:stained_glass 14
fill ~57~73~11 ~58~73~11 minecraft:concrete 14
fill ~57~74~11 ~57~74~12 minecraft:stained_glass 14
fill ~58~28~11 ~60~28~11 minecraft:stained_glass 14
fill ~58~29~11 ~58~30~11 minecraft:concrete 14
setblock ~58~31~11 minecraft:stained_glass 14
setblock ~58~34~11 minecraft:red_glazed_terracotta 3
fill ~58~35~11 ~58~35~12 minecraft:stained_glass 14
fill ~58~36~11 ~60~36~11 minecraft:concrete 14
setblock ~58~37~11 minecraft:red_glazed_terracotta 3
setblock ~58~39~11 minecraft:stained_glass 14
setblock ~58~74~11 minecraft:concrete 14
setblock ~59~29~11 minecraft:stained_glass 14
fill ~59~30~11 ~59~31~13 minecraft:red_glazed_terracotta 3
fill ~59~33~11 ~59~33~12 minecraft:stained_glass 14
fill ~59~34~11 ~59~34~12 minecraft:concrete 14
setblock ~59~35~11 minecraft:concrete 14
setblock ~59~37~11 minecraft:stained_glass 14
setblock ~59~38~11 minecraft:concrete 14
fill ~59~73~11 ~60~73~11 minecraft:stained_glass 14
setblock ~59~74~11 minecraft:red_glazed_terracotta 3
fill ~60~29~11 ~61~29~11 minecraft:red_glazed_terracotta 3
fill ~60~30~11 ~61~30~11 minecraft:stained_glass 14
fill ~60~31~11 ~60~31~13 minecraft:stained_glass 14
fill ~60~34~11 ~62~34~11 minecraft:stained_glass 14
fill ~60~35~11 ~60~35~12 minecraft:red_glazed_terracotta 3
setblock ~60~37~11 minecraft:concrete 14
fill ~60~38~11 ~62~38~11 minecraft:stained_glass 14
fill ~60~40~11 ~61~40~11 minecraft:concrete 14
fill ~60~64~11 ~61~64~11 minecraft:stained_glass 14
fill ~60~72~11 ~61~72~11 minecraft:red_glazed_terracotta 3
fill ~60~74~11 ~60~74~12 minecraft:concrete 14
setblock ~60~75~11 minecraft:concrete 14
setblock ~61~28~11 minecraft:red_glazed_terracotta 3
fill ~61~31~11 ~61~31~12 minecraft:concrete 14
fill ~61~32~11 ~61~32~13 minecraft:stained_glass 14
fill ~61~33~11 ~61~33~12 minecraft:red_glazed_terracotta 3
setblock ~61~37~11 minecraft:stained_glass 14
fill ~61~39~11 ~63~39~11 minecraft:stained_glass 14
fill ~61~65~11 ~61~66~11 minecraft:stained_glass 14
fill ~61~73~11 ~64~73~11 minecraft:red_glazed_terracotta 3
fill ~61~74~11 ~61~74~12 minecraft:red_glazed_terracotta 3
fill ~61~75~11 ~61~76~12 minecraft:stained_glass 14
setblock ~62~29~11 minecraft:stained_glass 14
setblock ~62~30~11 minecraft:red_glazed_terracotta 3
setblock ~62~32~11 minecraft:concrete 14
fill ~62~33~11 ~62~33~12 minecraft:stained_glass 14
fill ~62~40~11 ~63~40~11 minecraft:stained_glass 14
fill ~62~64~11 ~62~65~11 minecraft:concrete 14
setblock ~62~66~11 minecraft:stained_glass 14
fill ~62~67~11 ~64~67~11 minecraft:concrete 14
fill ~62~69~11 ~62~70~11 minecraft:concrete 14
fill ~62~71~11 ~62~72~11 minecraft:stained_glass 14
setblock ~62~74~11 minecraft:stained_glass 14
setblock ~62~75~11 minecraft:red_glazed_terracotta 3
fill ~63~30~11 ~64~30~11 minecraft:stained_glass 14
fill ~63~31~11 ~63~31~13 minecraft:red_glazed_terracotta 3
fill ~63~32~11 ~63~32~13 minecraft:stained_glass 14
setblock ~63~37~11 minecraft:red_glazed_terracotta 3
setblock ~63~38~11 minecraft:concrete 14
setblock ~63~41~11 minecraft:concrete 14
setblock ~63~42~11 minecraft:stained_glass 14
setblock ~63~66~11 minecraft:red_glazed_terracotta 3
