setblock ~1 ~0 ~53 glowstone 0  
fill ~1 ~0 ~54 ~1 ~0 ~58 iron_block 0 
setblock ~1 ~0 ~59 obsidian 0 
setblock ~1 ~0 ~63 obsidian 0  
fill ~1 ~0 ~64 ~1 ~0 ~68 iron_block 0 
setblock ~1 ~0 ~69 glowstone 0  
fill ~2 ~0 ~48 ~2 ~0 ~53 iron_block 0  
fill ~2 ~0 ~58 ~55 ~0 ~58 stone_slab 0  
fill ~2 ~0 ~64 ~52 ~0 ~64 stone_slab 0  
fill ~2 ~0 ~69 ~2 ~0 ~74 iron_block 0  
fill ~3 ~0 ~44 ~3 ~0 ~47 iron_block 0  
fill ~3 ~0 ~75 ~3 ~0 ~78 iron_block 0  
fill ~4 ~0 ~41 ~4 ~0 ~43 iron_block 0  
fill ~4 ~0 ~79 ~4 ~0 ~81 iron_block 0  
fill ~5 ~0 ~39 ~5 ~0 ~40 iron_block 0  
fill ~5 ~0 ~82 ~5 ~0 ~83 iron_block 0  
fill ~6 ~0 ~36 ~6 ~0 ~38 iron_block 0  
fill ~6 ~0 ~84 ~6 ~0 ~86 iron_block 0  
fill ~7 ~0 ~34 ~7 ~0 ~35 iron_block 0  
fill ~7 ~0 ~87 ~7 ~0 ~88 iron_block 0  
fill ~8 ~0 ~32 ~8 ~0 ~33 iron_block 0  
fill ~8 ~0 ~89 ~8 ~0 ~90 iron_block 0  
fill ~9 ~0 ~1 ~52 ~0 ~1 stone_slab 0 
setblock ~9 ~0 ~31 iron_block 0 
setblock ~9 ~0 ~91 iron_block 0  
fill ~10 ~0 ~29 ~10 ~0 ~30 iron_block 0  
fill ~10 ~0 ~92 ~10 ~0 ~93 iron_block 0  
fill ~11 ~0 ~27 ~11 ~0 ~28 iron_block 0  
fill ~11 ~0 ~94 ~11 ~0 ~95 iron_block 0 
setblock ~12 ~0 ~26 iron_block 0 
setblock ~12 ~0 ~96 iron_block 0 
setblock ~13 ~0 ~25 iron_block 0 
setblock ~13 ~0 ~97 iron_block 0  
fill ~14 ~0 ~23 ~14 ~0 ~24 iron_block 0  
fill ~14 ~0 ~98 ~14 ~0 ~99 iron_block 0 
setblock ~15 ~0 ~22 iron_block 0 
setblock ~15 ~0 ~100 iron_block 0 
setblock ~16 ~0 ~21 iron_block 0 
setblock ~16 ~0 ~101 iron_block 0 
setblock ~17 ~0 ~20 iron_block 0 
setblock ~17 ~0 ~102 iron_block 0 
setblock ~18 ~0 ~19 iron_block 0 
setblock ~18 ~0 ~103 iron_block 0 
setblock ~19 ~0 ~18 iron_block 0 
setblock ~19 ~0 ~104 iron_block 0 
setblock ~20 ~0 ~17 iron_block 0 
setblock ~20 ~0 ~105 iron_block 0 
setblock ~21 ~0 ~16 iron_block 0 
setblock ~21 ~0 ~106 iron_block 0 
setblock ~22 ~0 ~15 iron_block 0 
setblock ~22 ~0 ~107 iron_block 0  
fill ~23 ~0 ~14 ~24 ~0 ~14 iron_block 0  
fill ~23 ~0 ~108 ~24 ~0 ~108 iron_block 0 
setblock ~25 ~0 ~13 iron_block 0 
setblock ~25 ~0 ~109 iron_block 0 
setblock ~26 ~0 ~12 iron_block 0 
setblock ~26 ~0 ~110 iron_block 0  
fill ~27 ~0 ~11 ~28 ~0 ~11 iron_block 0  
fill ~27 ~0 ~111 ~28 ~0 ~111 iron_block 0  
fill ~29 ~0 ~10 ~30 ~0 ~10 iron_block 0  
fill ~29 ~0 ~112 ~30 ~0 ~112 iron_block 0 
setblock ~31 ~0 ~9 iron_block 0 
setblock ~31 ~0 ~113 iron_block 0  
fill ~32 ~0 ~8 ~33 ~0 ~8 iron_block 0  
fill ~32 ~0 ~81 ~32 ~0 ~85 iron_block 0  
fill ~32 ~0 ~114 ~33 ~0 ~114 iron_block 0  
fill ~33 ~0 ~79 ~33 ~0 ~80 iron_block 0  
fill ~33 ~0 ~86 ~33 ~0 ~87 iron_block 0  
fill ~34 ~0 ~7 ~35 ~0 ~7 iron_block 0 
setblock ~34 ~0 ~78 iron_block 0 
setblock ~34 ~0 ~88 iron_block 0  
fill ~34 ~0 ~115 ~35 ~0 ~115 iron_block 0  
fill ~35 ~0 ~77 ~36 ~0 ~77 iron_block 0  
fill ~35 ~0 ~89 ~36 ~0 ~89 iron_block 0  
fill ~36 ~0 ~6 ~38 ~0 ~6 iron_block 0  
fill ~36 ~0 ~116 ~39 ~0 ~116 iron_block 0  
fill ~37 ~0 ~76 ~42 ~0 ~76 iron_block 0  
fill ~37 ~0 ~90 ~41 ~0 ~90 iron_block 0  
fill ~39 ~0 ~5 ~40 ~0 ~5 iron_block 0 
setblock ~40 ~0 ~117 iron_block 0  
fill ~41 ~0 ~4 ~43 ~0 ~4 iron_block 0  
fill ~41 ~0 ~118 ~43 ~0 ~118 iron_block 0  
fill ~42 ~0 ~75 ~43 ~0 ~75 stone_slab 0  
fill ~42 ~0 ~89 ~43 ~0 ~89 iron_block 0  
fill ~43 ~0 ~74 ~44 ~0 ~74 stone_slab 0  
fill ~44 ~0 ~3 ~47 ~0 ~3 iron_block 0  
fill ~44 ~0 ~73 ~45 ~0 ~73 stone_slab 0 
setblock ~44 ~0 ~88 iron_block 0  
fill ~44 ~0 ~119 ~47 ~0 ~119 iron_block 0  
fill ~45 ~0 ~72 ~46 ~0 ~72 stone_slab 0  
fill ~45 ~0 ~86 ~45 ~0 ~87 iron_block 0  
fill ~46 ~0 ~71 ~47 ~0 ~71 stone_slab 0  
fill ~46 ~0 ~80 ~46 ~0 ~85 iron_block 0  
fill ~47 ~0 ~70 ~48 ~0 ~70 stone_slab 0  
fill ~47 ~0 ~79 ~48 ~0 ~79 stone_slab 0  
fill ~47 ~0 ~80 ~47 ~0 ~79 stone_slab 0  
fill ~48 ~0 ~2 ~53 ~0 ~2 iron_block 0  
fill ~48 ~0 ~69 ~49 ~0 ~69 stone_slab 0  
fill ~48 ~0 ~78 ~49 ~0 ~78 stone_slab 0  
fill ~48 ~0 ~120 ~53 ~0 ~120 iron_block 0  
fill ~49 ~0 ~68 ~50 ~0 ~68 stone_slab 0  
fill ~49 ~0 ~77 ~50 ~0 ~77 stone_slab 0  
fill ~50 ~0 ~67 ~51 ~0 ~67 stone_slab 0  
fill ~50 ~0 ~76 ~51 ~0 ~76 stone_slab 0  
fill ~51 ~0 ~66 ~52 ~0 ~66 stone_slab 0  
fill ~51 ~0 ~75 ~52 ~0 ~75 stone_slab 0 
setblock ~52 ~0 ~65 stone_slab 0  
fill ~52 ~0 ~74 ~53 ~0 ~74 stone_slab 0 
setblock ~53 ~0 ~1 glowstone 0  
fill ~53 ~0 ~73 ~54 ~0 ~73 stone_slab 0 
setblock ~53 ~0 ~121 glowstone 0  
fill ~54 ~0 ~1 ~58 ~0 ~1 iron_block 0  
fill ~54 ~0 ~72 ~55 ~0 ~72 stone_slab 0  
fill ~54 ~0 ~121 ~58 ~0 ~121 iron_block 0  
fill ~55 ~0 ~57 ~56 ~0 ~57 stone_slab 0  
fill ~55 ~0 ~71 ~56 ~0 ~71 stone_slab 0  
fill ~56 ~0 ~56 ~57 ~0 ~56 stone_slab 0  
fill ~56 ~0 ~70 ~58 ~0 ~70 stone_slab 0  
fill ~57 ~0 ~55 ~58 ~0 ~55 stone_slab 0  
fill ~58 ~0 ~2 ~58 ~0 ~55 stone_slab 0  
fill ~58 ~0 ~71 ~58 ~0 ~120 stone_slab 0 
setblock ~59 ~0 ~1 obsidian 0 
setblock ~59 ~0 ~121 obsidian 0 
setblock ~63 ~0 ~1 obsidian 0 
setblock ~63 ~0 ~121 obsidian 0  
fill ~64 ~0 ~1 ~68 ~0 ~1 iron_block 0  
fill ~64 ~0 ~2 ~64 ~0 ~52 stone_slab 0  
fill ~64 ~0 ~67 ~65 ~0 ~67 stone_slab 0  
fill ~64 ~0 ~68 ~64 ~0 ~120 stone_slab 0  
fill ~64 ~0 ~121 ~68 ~0 ~121 iron_block 0  
fill ~65 ~0 ~52 ~66 ~0 ~52 stone_slab 0  
fill ~65 ~0 ~66 ~66 ~0 ~66 stone_slab 0  
fill ~66 ~0 ~51 ~67 ~0 ~51 stone_slab 0  
fill ~66 ~0 ~65 ~67 ~0 ~65 stone_slab 0  
fill ~67 ~0 ~50 ~68 ~0 ~50 stone_slab 0  
fill ~67 ~0 ~64 ~120 ~0 ~64 stone_slab 0  
fill ~68 ~0 ~49 ~69 ~0 ~49 stone_slab 0 
setblock ~69 ~0 ~1 glowstone 0  
fill ~69 ~0 ~2 ~74 ~0 ~2 iron_block 0  
fill ~69 ~0 ~48 ~70 ~0 ~48 stone_slab 0  
fill ~69 ~0 ~120 ~74 ~0 ~120 iron_block 0 
setblock ~69 ~0 ~121 glowstone 0  
fill ~70 ~0 ~1 ~106 ~0 ~1 stone_slab 0  
fill ~70 ~0 ~47 ~71 ~0 ~47 stone_slab 0  
fill ~70 ~0 ~56 ~71 ~0 ~56 stone_slab 0  
fill ~70 ~0 ~57 ~70 ~0 ~58 stone_slab 0  
fill ~71 ~0 ~46 ~72 ~0 ~46 stone_slab 0  
fill ~71 ~0 ~55 ~72 ~0 ~55 stone_slab 0  
fill ~71 ~0 ~58 ~120 ~0 ~58 stone_slab 0  
fill ~72 ~0 ~45 ~73 ~0 ~45 stone_slab 0  
fill ~72 ~0 ~54 ~73 ~0 ~54 stone_slab 0  
fill ~73 ~0 ~44 ~74 ~0 ~44 stone_slab 0  
fill ~73 ~0 ~53 ~74 ~0 ~53 stone_slab 0  
fill ~74 ~0 ~43 ~75 ~0 ~43 stone_slab 0  
fill ~74 ~0 ~52 ~75 ~0 ~52 stone_slab 0  
fill ~75 ~0 ~3 ~78 ~0 ~3 iron_block 0 
setblock ~75 ~0 ~42 stone_slab 0  
fill ~75 ~0 ~51 ~76 ~0 ~51 stone_slab 0  
fill ~75 ~0 ~119 ~78 ~0 ~119 iron_block 0  
fill ~76 ~0 ~37 ~76 ~0 ~42 iron_block 0  
fill ~76 ~0 ~50 ~77 ~0 ~50 stone_slab 0  
fill ~77 ~0 ~35 ~77 ~0 ~36 iron_block 0  
fill ~77 ~0 ~49 ~78 ~0 ~49 stone_slab 0 
setblock ~78 ~0 ~34 iron_block 0  
fill ~78 ~0 ~48 ~79 ~0 ~48 stone_slab 0  
fill ~79 ~0 ~4 ~81 ~0 ~4 iron_block 0  
fill ~79 ~0 ~33 ~80 ~0 ~33 iron_block 0  
fill ~79 ~0 ~47 ~80 ~0 ~47 stone_slab 0  
fill ~79 ~0 ~118 ~81 ~0 ~118 iron_block 0  
fill ~80 ~0 ~46 ~85 ~0 ~46 iron_block 0  
fill ~81 ~0 ~32 ~85 ~0 ~32 iron_block 0  
fill ~82 ~0 ~5 ~83 ~0 ~5 iron_block 0  
fill ~82 ~0 ~117 ~83 ~0 ~117 iron_block 0  
fill ~84 ~0 ~6 ~86 ~0 ~6 iron_block 0  
fill ~84 ~0 ~116 ~86 ~0 ~116 iron_block 0  
fill ~86 ~0 ~33 ~87 ~0 ~33 iron_block 0  
fill ~86 ~0 ~45 ~87 ~0 ~45 iron_block 0  
fill ~87 ~0 ~7 ~88 ~0 ~7 iron_block 0  
fill ~87 ~0 ~115 ~88 ~0 ~115 iron_block 0 
setblock ~88 ~0 ~34 iron_block 0 
setblock ~88 ~0 ~44 iron_block 0  
fill ~89 ~0 ~8 ~90 ~0 ~8 iron_block 0  
fill ~89 ~0 ~35 ~89 ~0 ~36 iron_block 0  
fill ~89 ~0 ~42 ~89 ~0 ~43 iron_block 0  
fill ~89 ~0 ~114 ~90 ~0 ~114 iron_block 0  
fill ~90 ~0 ~37 ~90 ~0 ~41 iron_block 0 
setblock ~91 ~0 ~9 iron_block 0 
setblock ~91 ~0 ~113 iron_block 0  
fill ~92 ~0 ~10 ~93 ~0 ~10 iron_block 0  
fill ~92 ~0 ~112 ~93 ~0 ~112 iron_block 0  
fill ~94 ~0 ~11 ~95 ~0 ~11 iron_block 0  
fill ~94 ~0 ~111 ~95 ~0 ~111 iron_block 0 
setblock ~96 ~0 ~12 iron_block 0 
setblock ~96 ~0 ~110 iron_block 0 
setblock ~97 ~0 ~13 iron_block 0 
setblock ~97 ~0 ~109 iron_block 0  
fill ~98 ~0 ~14 ~99 ~0 ~14 iron_block 0  
fill ~98 ~0 ~108 ~99 ~0 ~108 iron_block 0 
setblock ~100 ~0 ~15 iron_block 0 
setblock ~100 ~0 ~107 iron_block 0 
setblock ~101 ~0 ~16 iron_block 0 
setblock ~101 ~0 ~106 iron_block 0 
setblock ~102 ~0 ~17 iron_block 0 
setblock ~102 ~0 ~105 iron_block 0 
setblock ~103 ~0 ~18 iron_block 0 
setblock ~103 ~0 ~104 iron_block 0 
setblock ~104 ~0 ~19 iron_block 0 
setblock ~104 ~0 ~103 iron_block 0 
setblock ~105 ~0 ~20 iron_block 0 
setblock ~105 ~0 ~102 iron_block 0 
setblock ~106 ~0 ~21 iron_block 0 
setblock ~106 ~0 ~101 iron_block 0 
setblock ~107 ~0 ~22 iron_block 0 
setblock ~107 ~0 ~100 iron_block 0  
fill ~108 ~0 ~1 ~121 ~0 ~1 stone_slab 0  
fill ~108 ~0 ~23 ~108 ~0 ~24 iron_block 0  
fill ~108 ~0 ~98 ~108 ~0 ~99 iron_block 0 
setblock ~109 ~0 ~25 iron_block 0 
setblock ~109 ~0 ~97 iron_block 0 
setblock ~110 ~0 ~26 iron_block 0 
setblock ~110 ~0 ~96 iron_block 0  
fill ~111 ~0 ~27 ~111 ~0 ~28 iron_block 0  
fill ~111 ~0 ~94 ~111 ~0 ~95 iron_block 0  
fill ~112 ~0 ~29 ~112 ~0 ~30 iron_block 0  
fill ~112 ~0 ~92 ~112 ~0 ~93 iron_block 0 
setblock ~113 ~0 ~31 iron_block 0 
setblock ~113 ~0 ~91 iron_block 0  
fill ~114 ~0 ~32 ~114 ~0 ~33 iron_block 0  
fill ~114 ~0 ~89 ~114 ~0 ~90 iron_block 0  
fill ~115 ~0 ~34 ~115 ~0 ~35 iron_block 0  
fill ~115 ~0 ~87 ~115 ~0 ~88 iron_block 0  
fill ~116 ~0 ~36 ~116 ~0 ~39 iron_block 0  
fill ~116 ~0 ~84 ~116 ~0 ~86 iron_block 0 
setblock ~117 ~0 ~40 iron_block 0  
fill ~117 ~0 ~82 ~117 ~0 ~83 iron_block 0  
fill ~118 ~0 ~41 ~118 ~0 ~43 iron_block 0  
fill ~118 ~0 ~79 ~118 ~0 ~81 iron_block 0  
fill ~119 ~0 ~44 ~119 ~0 ~47 iron_block 0  
fill ~119 ~0 ~75 ~119 ~0 ~78 iron_block 0  
fill ~120 ~0 ~48 ~120 ~0 ~53 iron_block 0  
fill ~120 ~0 ~69 ~120 ~0 ~74 iron_block 0 
setblock ~121 ~0 ~53 glowstone 0  
fill ~121 ~0 ~54 ~121 ~0 ~58 iron_block 0 
setblock ~121 ~0 ~59 obsidian 0 
setblock ~121 ~0 ~63 obsidian 0  
fill ~121 ~0 ~64 ~121 ~0 ~68 iron_block 0 
setblock ~121 ~0 ~69 glowstone 0  
fill ~2 ~1 ~53 ~3 ~1 ~53 glowstone 0  
fill ~2 ~1 ~54 ~3 ~1 ~54 stained_glass 0  
fill ~2 ~1 ~55 ~3 ~1 ~55 stained_glass 0  
fill ~2 ~1 ~56 ~3 ~1 ~56 stained_glass 0  
fill ~2 ~1 ~57 ~3 ~1 ~57 stained_glass 0  
fill ~2 ~1 ~58 ~3 ~1 ~58 stained_glass 0  
fill ~2 ~1 ~59 ~3 ~1 ~59 obsidian 0  
fill ~2 ~1 ~63 ~3 ~1 ~63 obsidian 0  
fill ~2 ~1 ~64 ~3 ~1 ~64 stained_glass 0  
fill ~2 ~1 ~65 ~3 ~1 ~65 stained_glass 0  
fill ~2 ~1 ~66 ~3 ~1 ~66 stained_glass 0  
fill ~2 ~1 ~67 ~3 ~1 ~67 stained_glass 0  
fill ~2 ~1 ~68 ~3 ~1 ~68 stained_glass 0  
fill ~2 ~1 ~69 ~3 ~1 ~69 glowstone 0  
fill ~3 ~1 ~48 ~3 ~1 ~52 stained_glass 0  
fill ~3 ~1 ~70 ~3 ~1 ~74 stained_glass 0  
fill ~4 ~1 ~44 ~4 ~1 ~47 stained_glass 0  
fill ~4 ~1 ~75 ~4 ~1 ~78 stained_glass 0  
fill ~5 ~1 ~41 ~5 ~1 ~43 stained_glass 0  
fill ~5 ~1 ~79 ~5 ~1 ~81 stained_glass 0  
fill ~6 ~1 ~39 ~6 ~1 ~40 stained_glass 0  
fill ~6 ~1 ~82 ~6 ~1 ~83 stained_glass 0  
fill ~7 ~1 ~36 ~7 ~1 ~38 stained_glass 0  
fill ~7 ~1 ~84 ~7 ~1 ~86 stained_glass 0  
fill ~8 ~1 ~34 ~8 ~1 ~35 stained_glass 0  
fill ~8 ~1 ~87 ~8 ~1 ~88 stained_glass 0  
fill ~9 ~1 ~32 ~9 ~1 ~33 stained_glass 0  
fill ~9 ~1 ~89 ~9 ~1 ~90 stained_glass 0 
setblock ~10 ~1 ~31 stained_glass 0 
setblock ~10 ~1 ~91 stained_glass 0  
fill ~11 ~1 ~29 ~11 ~1 ~30 stained_glass 0  
fill ~11 ~1 ~92 ~11 ~1 ~93 stained_glass 0  
fill ~12 ~1 ~27 ~12 ~1 ~28 stained_glass 0  
fill ~12 ~1 ~94 ~12 ~1 ~95 stained_glass 0 
setblock ~13 ~1 ~26 stained_glass 0 
setblock ~13 ~1 ~96 stained_glass 0 
setblock ~14 ~1 ~25 stained_glass 0 
setblock ~14 ~1 ~97 stained_glass 0  
fill ~15 ~1 ~23 ~15 ~1 ~24 stained_glass 0  
fill ~15 ~1 ~98 ~15 ~1 ~99 stained_glass 0 
setblock ~16 ~1 ~22 stained_glass 0 
setblock ~16 ~1 ~100 stained_glass 0 
setblock ~17 ~1 ~21 stained_glass 0 
setblock ~17 ~1 ~101 stained_glass 0 
setblock ~18 ~1 ~20 stained_glass 14 
setblock ~18 ~1 ~102 stained_glass 14 
setblock ~19 ~1 ~19 glowstone 0 
setblock ~19 ~1 ~103 glowstone 0 
setblock ~20 ~1 ~18 stained_glass 11 
setblock ~20 ~1 ~104 stained_glass 11 
setblock ~21 ~1 ~17 stained_glass 0 
setblock ~21 ~1 ~105 stained_glass 0 
setblock ~22 ~1 ~16 stained_glass 0 
setblock ~22 ~1 ~106 stained_glass 0  
fill ~23 ~1 ~15 ~24 ~1 ~15 stained_glass 0  
fill ~23 ~1 ~107 ~24 ~1 ~107 stained_glass 0 
setblock ~25 ~1 ~14 stained_glass 0 
setblock ~25 ~1 ~108 stained_glass 0 
setblock ~26 ~1 ~13 stained_glass 0 
setblock ~26 ~1 ~109 stained_glass 0  
fill ~27 ~1 ~12 ~28 ~1 ~12 stained_glass 0  
fill ~27 ~1 ~110 ~28 ~1 ~110 stained_glass 0  
fill ~29 ~1 ~11 ~30 ~1 ~11 stained_glass 0  
fill ~29 ~1 ~111 ~30 ~1 ~111 stained_glass 0 
setblock ~31 ~1 ~10 stained_glass 0 
setblock ~31 ~1 ~112 stained_glass 0  
fill ~32 ~1 ~9 ~33 ~1 ~9 stained_glass 0  
fill ~32 ~1 ~81 ~32 ~3 ~81 stained_glass 0  
fill ~32 ~1 ~82 ~32 ~3 ~82 stained_glass 0  
fill ~32 ~1 ~83 ~32 ~3 ~83 stained_glass 0  
fill ~32 ~1 ~84 ~32 ~3 ~84 stained_glass 0  
fill ~32 ~1 ~85 ~32 ~3 ~85 stained_glass 0  
fill ~32 ~1 ~113 ~33 ~1 ~113 stained_glass 0  
fill ~33 ~1 ~79 ~33 ~3 ~79 stained_glass 14  
fill ~33 ~1 ~80 ~33 ~3 ~80 stained_glass 0  
fill ~33 ~1 ~86 ~33 ~3 ~86 stained_glass 0  
fill ~33 ~1 ~87 ~33 ~3 ~87 stained_glass 14  
fill ~34 ~1 ~8 ~35 ~1 ~8 stained_glass 0  
fill ~34 ~1 ~78 ~34 ~3 ~78 glowstone 0  
fill ~34 ~1 ~88 ~34 ~3 ~88 glowstone 0  
fill ~34 ~1 ~114 ~35 ~1 ~114 stained_glass 0  
fill ~35 ~1 ~77 ~35 ~3 ~77 stained_glass 11  
fill ~35 ~1 ~89 ~35 ~3 ~89 stained_glass 11  
fill ~36 ~1 ~7 ~38 ~1 ~7 stained_glass 0  
fill ~36 ~1 ~77 ~36 ~3 ~77 stained_glass 0  
fill ~36 ~1 ~89 ~36 ~3 ~89 stained_glass 0  
fill ~36 ~1 ~115 ~38 ~1 ~115 stained_glass 0  
fill ~37 ~1 ~76 ~41 ~1 ~76 stained_glass 0  
fill ~37 ~1 ~90 ~41 ~1 ~90 stained_glass 0  
fill ~39 ~1 ~6 ~40 ~1 ~6 stained_glass 0  
fill ~39 ~1 ~116 ~40 ~1 ~116 stained_glass 0  
fill ~41 ~1 ~5 ~43 ~1 ~5 stained_glass 0  
fill ~41 ~1 ~117 ~43 ~1 ~117 stained_glass 0  
fill ~42 ~1 ~76 ~42 ~3 ~76 stained_glass 11  
fill ~42 ~1 ~89 ~42 ~3 ~89 stained_glass 0  
fill ~43 ~1 ~89 ~43 ~3 ~89 stained_glass 11  
fill ~44 ~1 ~4 ~47 ~1 ~4 stained_glass 0  
fill ~44 ~1 ~88 ~44 ~3 ~88 glowstone 0  
fill ~44 ~1 ~118 ~47 ~1 ~118 stained_glass 0  
fill ~45 ~1 ~86 ~45 ~3 ~86 stained_glass 0  
fill ~45 ~1 ~87 ~45 ~3 ~87 stained_glass 14  
fill ~46 ~1 ~80 ~46 ~3 ~80 stained_glass 14  
fill ~46 ~1 ~81 ~46 ~3 ~81 stained_glass 0  
fill ~46 ~1 ~82 ~46 ~3 ~82 stained_glass 0  
fill ~46 ~1 ~83 ~46 ~3 ~83 stained_glass 0  
fill ~46 ~1 ~84 ~46 ~3 ~84 stained_glass 0  
fill ~46 ~1 ~85 ~46 ~3 ~85 stained_glass 0  
fill ~48 ~1 ~3 ~52 ~1 ~3 stained_glass 0  
fill ~48 ~1 ~119 ~52 ~1 ~119 stained_glass 0  
fill ~53 ~1 ~2 ~53 ~1 ~3 glowstone 0  
fill ~53 ~1 ~119 ~53 ~1 ~120 glowstone 0  
fill ~54 ~1 ~2 ~58 ~1 ~2 stained_glass 0  
fill ~54 ~1 ~3 ~58 ~1 ~3 stained_glass 0  
fill ~54 ~1 ~119 ~58 ~1 ~119 stained_glass 0  
fill ~54 ~1 ~120 ~58 ~1 ~120 stained_glass 0  
fill ~59 ~1 ~2 ~59 ~1 ~3 obsidian 0  
fill ~59 ~1 ~119 ~59 ~1 ~120 obsidian 0  
fill ~63 ~1 ~2 ~63 ~1 ~3 obsidian 0  
fill ~63 ~1 ~119 ~63 ~1 ~120 obsidian 0  
fill ~64 ~1 ~2 ~68 ~1 ~2 stained_glass 0  
fill ~64 ~1 ~3 ~68 ~1 ~3 stained_glass 0  
fill ~64 ~1 ~119 ~68 ~1 ~119 stained_glass 0  
fill ~64 ~1 ~120 ~68 ~1 ~120 stained_glass 0  
fill ~69 ~1 ~2 ~69 ~1 ~3 glowstone 0  
fill ~69 ~1 ~119 ~69 ~1 ~120 glowstone 0  
fill ~70 ~1 ~3 ~74 ~1 ~3 stained_glass 0  
fill ~70 ~1 ~119 ~74 ~1 ~119 stained_glass 0  
fill ~75 ~1 ~4 ~78 ~1 ~4 stained_glass 0  
fill ~75 ~1 ~118 ~78 ~1 ~118 stained_glass 0  
fill ~76 ~1 ~37 ~76 ~3 ~37 stained_glass 0  
fill ~76 ~1 ~38 ~76 ~3 ~38 stained_glass 0  
fill ~76 ~1 ~39 ~76 ~3 ~39 stained_glass 0  
fill ~76 ~1 ~40 ~76 ~3 ~40 stained_glass 0  
fill ~76 ~1 ~41 ~76 ~3 ~41 stained_glass 0  
fill ~76 ~1 ~42 ~76 ~3 ~42 stained_glass 14  
fill ~77 ~1 ~35 ~77 ~3 ~35 stained_glass 14  
fill ~77 ~1 ~36 ~77 ~3 ~36 stained_glass 0  
fill ~78 ~1 ~34 ~78 ~3 ~34 glowstone 0  
fill ~79 ~1 ~5 ~81 ~1 ~5 stained_glass 0  
fill ~79 ~1 ~33 ~79 ~3 ~33 stained_glass 11  
fill ~79 ~1 ~117 ~81 ~1 ~117 stained_glass 0  
fill ~80 ~1 ~33 ~80 ~3 ~33 stained_glass 0  
fill ~80 ~1 ~46 ~80 ~3 ~46 stained_glass 11  
fill ~81 ~1 ~32 ~85 ~1 ~32 stained_glass 0  
fill ~81 ~1 ~46 ~85 ~1 ~46 stained_glass 0  
fill ~82 ~1 ~6 ~83 ~1 ~6 stained_glass 0  
fill ~82 ~1 ~116 ~83 ~1 ~116 stained_glass 0  
fill ~84 ~1 ~7 ~86 ~1 ~7 stained_glass 0  
fill ~84 ~1 ~115 ~86 ~1 ~115 stained_glass 0  
fill ~86 ~1 ~33 ~86 ~3 ~33 stained_glass 0  
fill ~86 ~1 ~45 ~86 ~3 ~45 stained_glass 0  
fill ~87 ~1 ~8 ~88 ~1 ~8 stained_glass 0  
fill ~87 ~1 ~33 ~87 ~3 ~33 stained_glass 11  
fill ~87 ~1 ~45 ~87 ~3 ~45 stained_glass 11  
fill ~87 ~1 ~114 ~88 ~1 ~114 stained_glass 0  
fill ~88 ~1 ~34 ~88 ~3 ~34 glowstone 0  
fill ~88 ~1 ~44 ~88 ~3 ~44 glowstone 0  
fill ~89 ~1 ~9 ~90 ~1 ~9 stained_glass 0  
fill ~89 ~1 ~35 ~89 ~3 ~35 stained_glass 14  
fill ~89 ~1 ~36 ~89 ~3 ~36 stained_glass 0  
fill ~89 ~1 ~42 ~89 ~3 ~42 stained_glass 0  
fill ~89 ~1 ~43 ~89 ~3 ~43 stained_glass 14  
fill ~89 ~1 ~113 ~90 ~1 ~113 stained_glass 0  
fill ~90 ~1 ~37 ~90 ~3 ~37 stained_glass 0  
fill ~90 ~1 ~38 ~90 ~3 ~38 stained_glass 0  
fill ~90 ~1 ~39 ~90 ~3 ~39 stained_glass 0  
fill ~90 ~1 ~40 ~90 ~3 ~40 stained_glass 0  
fill ~90 ~1 ~41 ~90 ~3 ~41 stained_glass 0 
setblock ~91 ~1 ~10 stained_glass 0 
setblock ~91 ~1 ~112 stained_glass 0  
fill ~92 ~1 ~11 ~93 ~1 ~11 stained_glass 0  
fill ~92 ~1 ~111 ~93 ~1 ~111 stained_glass 0  
fill ~94 ~1 ~12 ~95 ~1 ~12 stained_glass 0  
fill ~94 ~1 ~110 ~95 ~1 ~110 stained_glass 0 
setblock ~96 ~1 ~13 stained_glass 0 
setblock ~96 ~1 ~109 stained_glass 0 
setblock ~97 ~1 ~14 stained_glass 0 
setblock ~97 ~1 ~108 stained_glass 0  
fill ~98 ~1 ~15 ~99 ~1 ~15 stained_glass 0  
fill ~98 ~1 ~107 ~99 ~1 ~107 stained_glass 0 
setblock ~100 ~1 ~16 stained_glass 0 
setblock ~100 ~1 ~106 stained_glass 0 
setblock ~101 ~1 ~17 stained_glass 0 
setblock ~101 ~1 ~105 stained_glass 0 
setblock ~102 ~1 ~18 stained_glass 11 
setblock ~102 ~1 ~104 stained_glass 11 
setblock ~103 ~1 ~19 glowstone 0 
setblock ~103 ~1 ~103 glowstone 0 
setblock ~104 ~1 ~20 stained_glass 14 
setblock ~104 ~1 ~102 stained_glass 14 
setblock ~105 ~1 ~21 stained_glass 0 
setblock ~105 ~1 ~101 stained_glass 0 
setblock ~106 ~1 ~22 stained_glass 0 
setblock ~106 ~1 ~100 stained_glass 0  
fill ~107 ~1 ~23 ~107 ~1 ~24 stained_glass 0  
fill ~107 ~1 ~98 ~107 ~1 ~99 stained_glass 0 
setblock ~108 ~1 ~25 stained_glass 0 
setblock ~108 ~1 ~97 stained_glass 0 
setblock ~109 ~1 ~26 stained_glass 0 
setblock ~109 ~1 ~96 stained_glass 0  
fill ~110 ~1 ~27 ~110 ~1 ~28 stained_glass 0  
fill ~110 ~1 ~94 ~110 ~1 ~95 stained_glass 0  
fill ~111 ~1 ~29 ~111 ~1 ~30 stained_glass 0  
fill ~111 ~1 ~92 ~111 ~1 ~93 stained_glass 0 
setblock ~112 ~1 ~31 stained_glass 0 
setblock ~112 ~1 ~91 stained_glass 0  
fill ~113 ~1 ~32 ~113 ~1 ~33 stained_glass 0  
fill ~113 ~1 ~89 ~113 ~1 ~90 stained_glass 0  
fill ~114 ~1 ~34 ~114 ~1 ~35 stained_glass 0  
fill ~114 ~1 ~87 ~114 ~1 ~88 stained_glass 0  
fill ~115 ~1 ~36 ~115 ~1 ~38 stained_glass 0  
fill ~115 ~1 ~84 ~115 ~1 ~86 stained_glass 0  
fill ~116 ~1 ~39 ~116 ~1 ~40 stained_glass 0  
fill ~116 ~1 ~82 ~116 ~1 ~83 stained_glass 0  
fill ~117 ~1 ~41 ~117 ~1 ~43 stained_glass 0  
fill ~117 ~1 ~79 ~117 ~1 ~81 stained_glass 0  
fill ~118 ~1 ~44 ~118 ~1 ~47 stained_glass 0  
fill ~118 ~1 ~75 ~118 ~1 ~78 stained_glass 0  
fill ~119 ~1 ~48 ~119 ~1 ~52 stained_glass 0  
fill ~119 ~1 ~53 ~120 ~1 ~53 glowstone 0  
fill ~119 ~1 ~54 ~120 ~1 ~54 stained_glass 0  
fill ~119 ~1 ~55 ~120 ~1 ~55 stained_glass 0  
fill ~119 ~1 ~56 ~120 ~1 ~56 stained_glass 0  
fill ~119 ~1 ~57 ~120 ~1 ~57 stained_glass 0  
fill ~119 ~1 ~58 ~120 ~1 ~58 stained_glass 0  
fill ~119 ~1 ~59 ~120 ~1 ~59 obsidian 0  
fill ~119 ~1 ~63 ~120 ~1 ~63 obsidian 0  
fill ~119 ~1 ~64 ~120 ~1 ~64 stained_glass 0  
fill ~119 ~1 ~65 ~120 ~1 ~65 stained_glass 0  
fill ~119 ~1 ~66 ~120 ~1 ~66 stained_glass 0  
fill ~119 ~1 ~67 ~120 ~1 ~67 stained_glass 0  
fill ~119 ~1 ~68 ~120 ~1 ~68 stained_glass 0  
fill ~119 ~1 ~69 ~120 ~1 ~69 glowstone 0  
fill ~119 ~1 ~70 ~119 ~1 ~74 stained_glass 0  
fill ~4 ~2 ~48 ~5 ~2 ~48 stained_glass 0  
fill ~4 ~2 ~49 ~5 ~2 ~49 stained_glass 0  
fill ~4 ~2 ~50 ~5 ~2 ~50 stained_glass 0  
fill ~4 ~2 ~51 ~5 ~2 ~51 stained_glass 0  
fill ~4 ~2 ~52 ~5 ~2 ~52 stained_glass 0  
fill ~4 ~2 ~53 ~5 ~2 ~53 glowstone 0  
fill ~4 ~2 ~54 ~5 ~2 ~54 stained_glass 0  
fill ~4 ~2 ~55 ~5 ~2 ~55 stained_glass 0  
fill ~4 ~2 ~56 ~5 ~2 ~56 stained_glass 0  
fill ~4 ~2 ~57 ~5 ~2 ~57 stained_glass 0  
fill ~4 ~2 ~58 ~5 ~2 ~58 stained_glass 0  
fill ~4 ~2 ~59 ~5 ~2 ~59 obsidian 0  
fill ~4 ~2 ~63 ~5 ~2 ~63 obsidian 0  
fill ~4 ~2 ~64 ~5 ~2 ~64 stained_glass 0  
fill ~4 ~2 ~65 ~5 ~2 ~65 stained_glass 0  
fill ~4 ~2 ~66 ~5 ~2 ~66 stained_glass 0  
fill ~4 ~2 ~67 ~5 ~2 ~67 stained_glass 0  
fill ~4 ~2 ~68 ~5 ~2 ~68 stained_glass 0  
fill ~4 ~2 ~69 ~5 ~2 ~69 glowstone 0  
fill ~4 ~2 ~70 ~5 ~2 ~70 stained_glass 0  
fill ~4 ~2 ~71 ~5 ~2 ~71 stained_glass 0  
fill ~4 ~2 ~72 ~5 ~2 ~72 stained_glass 0  
fill ~4 ~2 ~73 ~5 ~2 ~73 stained_glass 0  
fill ~4 ~2 ~74 ~5 ~2 ~74 stained_glass 0  
fill ~5 ~2 ~44 ~6 ~2 ~44 stained_glass 0  
fill ~5 ~2 ~45 ~6 ~2 ~45 stained_glass 0  
fill ~5 ~2 ~46 ~6 ~2 ~46 stained_glass 0  
fill ~5 ~2 ~47 ~6 ~2 ~47 stained_glass 0  
fill ~5 ~2 ~75 ~6 ~2 ~75 stained_glass 0  
fill ~5 ~2 ~76 ~6 ~2 ~76 stained_glass 0  
fill ~5 ~2 ~77 ~6 ~2 ~77 stained_glass 0  
fill ~5 ~2 ~78 ~6 ~2 ~78 stained_glass 0  
fill ~6 ~2 ~41 ~7 ~2 ~41 stained_glass 0  
fill ~6 ~2 ~42 ~7 ~2 ~42 stained_glass 0  
fill ~6 ~2 ~43 ~7 ~2 ~43 stained_glass 0  
fill ~6 ~2 ~79 ~7 ~2 ~79 stained_glass 0  
fill ~6 ~2 ~80 ~7 ~2 ~80 stained_glass 0  
fill ~6 ~2 ~81 ~7 ~2 ~81 stained_glass 0  
fill ~7 ~2 ~39 ~8 ~2 ~39 stained_glass 0  
fill ~7 ~2 ~40 ~8 ~2 ~40 stained_glass 0  
fill ~7 ~2 ~82 ~8 ~2 ~82 stained_glass 0  
fill ~7 ~2 ~83 ~8 ~2 ~83 stained_glass 0  
fill ~8 ~2 ~36 ~9 ~2 ~36 stained_glass 0  
fill ~8 ~2 ~37 ~9 ~2 ~37 stained_glass 0  
fill ~8 ~2 ~38 ~9 ~2 ~38 stained_glass 0  
fill ~8 ~2 ~84 ~9 ~2 ~84 stained_glass 0  
fill ~8 ~2 ~85 ~9 ~2 ~85 stained_glass 0  
fill ~8 ~2 ~86 ~9 ~2 ~86 stained_glass 0  
fill ~9 ~2 ~34 ~10 ~2 ~34 stained_glass 0  
fill ~9 ~2 ~35 ~10 ~2 ~35 stained_glass 0  
fill ~9 ~2 ~87 ~10 ~2 ~87 stained_glass 0  
fill ~9 ~2 ~88 ~10 ~2 ~88 stained_glass 0  
fill ~10 ~2 ~32 ~11 ~2 ~32 stained_glass 0  
fill ~10 ~2 ~33 ~11 ~2 ~33 stained_glass 0  
fill ~10 ~2 ~89 ~11 ~2 ~89 stained_glass 0  
fill ~10 ~2 ~90 ~11 ~2 ~90 stained_glass 0  
fill ~11 ~2 ~31 ~12 ~2 ~31 stained_glass 0  
fill ~11 ~2 ~91 ~12 ~2 ~91 stained_glass 0  
fill ~12 ~2 ~29 ~13 ~2 ~29 stained_glass 0  
fill ~12 ~2 ~30 ~13 ~2 ~30 stained_glass 0  
fill ~12 ~2 ~92 ~13 ~2 ~92 stained_glass 0  
fill ~12 ~2 ~93 ~13 ~2 ~93 stained_glass 0  
fill ~13 ~2 ~27 ~14 ~2 ~27 stained_glass 0  
fill ~13 ~2 ~28 ~14 ~2 ~28 stained_glass 0  
fill ~13 ~2 ~94 ~14 ~2 ~94 stained_glass 0  
fill ~13 ~2 ~95 ~14 ~2 ~95 stained_glass 0  
fill ~14 ~2 ~26 ~15 ~2 ~26 stained_glass 0  
fill ~14 ~2 ~96 ~15 ~2 ~96 stained_glass 0  
fill ~15 ~2 ~25 ~16 ~2 ~25 stained_glass 0  
fill ~15 ~2 ~97 ~16 ~2 ~97 stained_glass 0  
fill ~16 ~2 ~23 ~17 ~2 ~23 stained_glass 0  
fill ~16 ~2 ~24 ~17 ~2 ~24 stained_glass 0  
fill ~16 ~2 ~98 ~17 ~2 ~98 stained_glass 0  
fill ~16 ~2 ~99 ~17 ~2 ~99 stained_glass 0  
fill ~17 ~2 ~22 ~19 ~2 ~22 stained_glass 0  
fill ~17 ~2 ~100 ~18 ~2 ~100 stained_glass 0 
setblock ~18 ~2 ~21 stained_glass 0 
setblock ~18 ~2 ~101 stained_glass 0 
setblock ~19 ~2 ~21 stained_glass 14 
setblock ~19 ~2 ~101 stained_glass 14 
setblock ~20 ~2 ~20 glowstone 0 
setblock ~20 ~2 ~102 glowstone 0  
fill ~21 ~2 ~18 ~22 ~2 ~18 stained_glass 0 
setblock ~21 ~2 ~19 stained_glass 11 
setblock ~21 ~2 ~103 stained_glass 11  
fill ~21 ~2 ~104 ~22 ~2 ~104 stained_glass 0  
fill ~22 ~2 ~17 ~24 ~2 ~17 stained_glass 0 
setblock ~22 ~2 ~19 stained_glass 0 
setblock ~22 ~2 ~103 stained_glass 0  
fill ~22 ~2 ~105 ~24 ~2 ~105 stained_glass 0  
fill ~23 ~2 ~16 ~25 ~2 ~16 stained_glass 0  
fill ~23 ~2 ~106 ~25 ~2 ~106 stained_glass 0  
fill ~25 ~2 ~15 ~26 ~2 ~15 stained_glass 0  
fill ~25 ~2 ~107 ~26 ~2 ~107 stained_glass 0  
fill ~26 ~2 ~14 ~28 ~2 ~14 stained_glass 0  
fill ~26 ~2 ~108 ~28 ~2 ~108 stained_glass 0  
fill ~27 ~2 ~13 ~30 ~2 ~13 stained_glass 0  
fill ~27 ~2 ~109 ~30 ~2 ~109 stained_glass 0  
fill ~29 ~2 ~12 ~31 ~2 ~12 stained_glass 0  
fill ~29 ~2 ~110 ~31 ~2 ~110 stained_glass 0  
fill ~31 ~2 ~11 ~33 ~2 ~11 stained_glass 0  
fill ~31 ~2 ~111 ~33 ~2 ~111 stained_glass 0  
fill ~32 ~2 ~10 ~35 ~2 ~10 stained_glass 0  
fill ~32 ~2 ~112 ~35 ~2 ~112 stained_glass 0  
fill ~34 ~2 ~9 ~38 ~2 ~9 stained_glass 0  
fill ~34 ~2 ~113 ~38 ~2 ~113 stained_glass 0  
fill ~36 ~2 ~8 ~40 ~2 ~8 stained_glass 0  
fill ~36 ~2 ~114 ~40 ~2 ~114 stained_glass 0  
fill ~37 ~2 ~76 ~41 ~2 ~76 stained_glass 0  
fill ~37 ~2 ~90 ~41 ~2 ~90 stained_glass 0  
fill ~39 ~2 ~7 ~43 ~2 ~7 stained_glass 0  
fill ~39 ~2 ~115 ~43 ~2 ~115 stained_glass 0  
fill ~41 ~2 ~6 ~47 ~2 ~6 stained_glass 0  
fill ~41 ~2 ~116 ~47 ~2 ~116 stained_glass 0  
fill ~44 ~2 ~5 ~52 ~2 ~5 stained_glass 0  
fill ~44 ~2 ~117 ~52 ~2 ~117 stained_glass 0  
fill ~48 ~2 ~4 ~52 ~2 ~4 stained_glass 0  
fill ~48 ~2 ~118 ~52 ~2 ~118 stained_glass 0  
fill ~53 ~2 ~4 ~53 ~2 ~5 glowstone 0  
fill ~53 ~2 ~117 ~53 ~2 ~118 glowstone 0  
fill ~54 ~2 ~4 ~58 ~2 ~4 stained_glass 0  
fill ~54 ~2 ~5 ~58 ~2 ~5 stained_glass 0  
fill ~54 ~2 ~117 ~58 ~2 ~117 stained_glass 0  
fill ~54 ~2 ~118 ~58 ~2 ~118 stained_glass 0  
fill ~59 ~2 ~4 ~59 ~2 ~5 obsidian 0  
fill ~59 ~2 ~117 ~59 ~2 ~118 obsidian 0  
fill ~63 ~2 ~4 ~63 ~2 ~5 obsidian 0  
fill ~63 ~2 ~117 ~63 ~2 ~118 obsidian 0  
fill ~64 ~2 ~4 ~68 ~2 ~4 stained_glass 0  
fill ~64 ~2 ~5 ~68 ~2 ~5 stained_glass 0  
fill ~64 ~2 ~117 ~68 ~2 ~117 stained_glass 0  
fill ~64 ~2 ~118 ~68 ~2 ~118 stained_glass 0  
fill ~69 ~2 ~4 ~69 ~2 ~5 glowstone 0  
fill ~69 ~2 ~117 ~69 ~2 ~118 glowstone 0  
fill ~70 ~2 ~4 ~74 ~2 ~4 stained_glass 0  
fill ~70 ~2 ~5 ~78 ~2 ~5 stained_glass 0  
fill ~70 ~2 ~117 ~78 ~2 ~117 stained_glass 0  
fill ~70 ~2 ~118 ~74 ~2 ~118 stained_glass 0  
fill ~75 ~2 ~6 ~81 ~2 ~6 stained_glass 0  
fill ~75 ~2 ~116 ~81 ~2 ~116 stained_glass 0  
fill ~79 ~2 ~7 ~83 ~2 ~7 stained_glass 0  
fill ~79 ~2 ~115 ~83 ~2 ~115 stained_glass 0  
fill ~81 ~2 ~32 ~85 ~2 ~32 stained_glass 0  
fill ~81 ~2 ~46 ~85 ~2 ~46 stained_glass 0  
fill ~82 ~2 ~8 ~86 ~2 ~8 stained_glass 0  
fill ~82 ~2 ~114 ~86 ~2 ~114 stained_glass 0  
fill ~84 ~2 ~9 ~88 ~2 ~9 stained_glass 0  
fill ~84 ~2 ~113 ~88 ~2 ~113 stained_glass 0  
fill ~87 ~2 ~10 ~90 ~2 ~10 stained_glass 0  
fill ~87 ~2 ~112 ~90 ~2 ~112 stained_glass 0  
fill ~89 ~2 ~11 ~91 ~2 ~11 stained_glass 0  
fill ~89 ~2 ~111 ~91 ~2 ~111 stained_glass 0  
fill ~91 ~2 ~12 ~93 ~2 ~12 stained_glass 0  
fill ~91 ~2 ~110 ~93 ~2 ~110 stained_glass 0  
fill ~92 ~2 ~13 ~95 ~2 ~13 stained_glass 0  
fill ~92 ~2 ~109 ~95 ~2 ~109 stained_glass 0  
fill ~94 ~2 ~14 ~96 ~2 ~14 stained_glass 0  
fill ~94 ~2 ~108 ~96 ~2 ~108 stained_glass 0  
fill ~96 ~2 ~15 ~97 ~2 ~15 stained_glass 0  
fill ~96 ~2 ~107 ~97 ~2 ~107 stained_glass 0  
fill ~97 ~2 ~16 ~99 ~2 ~16 stained_glass 0  
fill ~97 ~2 ~106 ~99 ~2 ~106 stained_glass 0  
fill ~98 ~2 ~17 ~100 ~2 ~17 stained_glass 0  
fill ~98 ~2 ~105 ~100 ~2 ~105 stained_glass 0  
fill ~100 ~2 ~18 ~101 ~2 ~18 stained_glass 0  
fill ~100 ~2 ~19 ~100 ~2 ~17 stained_glass 0  
fill ~100 ~2 ~103 ~100 ~2 ~105 stained_glass 0 
setblock ~101 ~2 ~19 stained_glass 11 
setblock ~101 ~2 ~103 stained_glass 11 
setblock ~101 ~2 ~104 stained_glass 0 
setblock ~102 ~2 ~20 glowstone 0 
setblock ~102 ~2 ~102 glowstone 0 
setblock ~103 ~2 ~21 stained_glass 14  
fill ~103 ~2 ~100 ~105 ~2 ~100 stained_glass 0 
setblock ~103 ~2 ~101 stained_glass 14  
fill ~104 ~2 ~21 ~104 ~2 ~22 stained_glass 0 
setblock ~104 ~2 ~101 stained_glass 0  
fill ~105 ~2 ~22 ~105 ~2 ~24 stained_glass 0  
fill ~105 ~2 ~98 ~106 ~2 ~98 stained_glass 0  
fill ~105 ~2 ~99 ~106 ~2 ~99 stained_glass 0  
fill ~106 ~2 ~23 ~106 ~2 ~25 stained_glass 0  
fill ~106 ~2 ~97 ~107 ~2 ~97 stained_glass 0  
fill ~107 ~2 ~25 ~107 ~2 ~26 stained_glass 0  
fill ~107 ~2 ~96 ~108 ~2 ~96 stained_glass 0  
fill ~108 ~2 ~26 ~108 ~2 ~28 stained_glass 0  
fill ~108 ~2 ~94 ~109 ~2 ~94 stained_glass 0  
fill ~108 ~2 ~95 ~109 ~2 ~95 stained_glass 0  
fill ~109 ~2 ~27 ~109 ~2 ~30 stained_glass 0  
fill ~109 ~2 ~92 ~110 ~2 ~92 stained_glass 0  
fill ~109 ~2 ~93 ~110 ~2 ~93 stained_glass 0  
fill ~110 ~2 ~29 ~110 ~2 ~31 stained_glass 0  
fill ~110 ~2 ~91 ~111 ~2 ~91 stained_glass 0  
fill ~111 ~2 ~31 ~111 ~2 ~33 stained_glass 0  
fill ~111 ~2 ~89 ~112 ~2 ~89 stained_glass 0  
fill ~111 ~2 ~90 ~112 ~2 ~90 stained_glass 0  
fill ~112 ~2 ~32 ~112 ~2 ~35 stained_glass 0  
fill ~112 ~2 ~87 ~113 ~2 ~87 stained_glass 0  
fill ~112 ~2 ~88 ~113 ~2 ~88 stained_glass 0  
fill ~113 ~2 ~34 ~113 ~2 ~38 stained_glass 0  
fill ~113 ~2 ~84 ~114 ~2 ~84 stained_glass 0  
fill ~113 ~2 ~85 ~114 ~2 ~85 stained_glass 0  
fill ~113 ~2 ~86 ~114 ~2 ~86 stained_glass 0  
fill ~114 ~2 ~36 ~114 ~2 ~40 stained_glass 0  
fill ~114 ~2 ~82 ~115 ~2 ~82 stained_glass 0  
fill ~114 ~2 ~83 ~115 ~2 ~83 stained_glass 0  
fill ~115 ~2 ~39 ~115 ~2 ~43 stained_glass 0  
fill ~115 ~2 ~79 ~116 ~2 ~79 stained_glass 0  
fill ~115 ~2 ~80 ~116 ~2 ~80 stained_glass 0  
fill ~115 ~2 ~81 ~116 ~2 ~81 stained_glass 0  
fill ~116 ~2 ~41 ~116 ~2 ~47 stained_glass 0  
fill ~116 ~2 ~75 ~117 ~2 ~75 stained_glass 0  
fill ~116 ~2 ~76 ~117 ~2 ~76 stained_glass 0  
fill ~116 ~2 ~77 ~117 ~2 ~77 stained_glass 0  
fill ~116 ~2 ~78 ~117 ~2 ~78 stained_glass 0  
fill ~117 ~2 ~44 ~117 ~2 ~52 stained_glass 0  
fill ~117 ~2 ~53 ~118 ~2 ~53 glowstone 0  
fill ~117 ~2 ~54 ~118 ~2 ~54 stained_glass 0  
fill ~117 ~2 ~55 ~118 ~2 ~55 stained_glass 0  
fill ~117 ~2 ~56 ~118 ~2 ~56 stained_glass 0  
fill ~117 ~2 ~57 ~118 ~2 ~57 stained_glass 0  
fill ~117 ~2 ~58 ~118 ~2 ~58 stained_glass 0  
fill ~117 ~2 ~59 ~118 ~2 ~59 obsidian 0  
fill ~117 ~2 ~64 ~118 ~2 ~64 stained_glass 0  
fill ~117 ~2 ~65 ~118 ~2 ~65 stained_glass 0  
fill ~117 ~2 ~66 ~118 ~2 ~66 stained_glass 0  
fill ~117 ~2 ~67 ~118 ~2 ~67 stained_glass 0  
fill ~117 ~2 ~68 ~118 ~2 ~68 stained_glass 0  
fill ~117 ~2 ~69 ~118 ~2 ~69 glowstone 0  
fill ~117 ~2 ~70 ~118 ~2 ~70 stained_glass 0  
fill ~117 ~2 ~71 ~118 ~2 ~71 stained_glass 0  
fill ~117 ~2 ~72 ~118 ~2 ~72 stained_glass 0  
fill ~117 ~2 ~73 ~118 ~2 ~73 stained_glass 0  
fill ~117 ~2 ~74 ~118 ~2 ~74 stained_glass 0  
fill ~118 ~2 ~48 ~118 ~2 ~52 stained_glass 0 
setblock ~118 ~2 ~63 obsidian 0  
fill ~5 ~3 ~59 ~5 ~3 ~63 obsidian 0  
fill ~6 ~3 ~48 ~7 ~3 ~48 stained_glass 0  
fill ~6 ~3 ~49 ~7 ~3 ~49 stained_glass 0  
fill ~6 ~3 ~50 ~7 ~3 ~50 stained_glass 0  
fill ~6 ~3 ~51 ~7 ~3 ~51 stained_glass 0  
fill ~6 ~3 ~52 ~7 ~3 ~52 stained_glass 0  
fill ~6 ~3 ~53 ~7 ~3 ~53 glowstone 0  
fill ~6 ~3 ~54 ~7 ~3 ~54 stained_glass 0  
fill ~6 ~3 ~55 ~7 ~3 ~55 stained_glass 0  
fill ~6 ~3 ~56 ~7 ~3 ~56 stained_glass 0  
fill ~6 ~3 ~57 ~7 ~3 ~57 stained_glass 0  
fill ~6 ~3 ~58 ~7 ~3 ~58 stained_glass 0  
fill ~6 ~3 ~59 ~7 ~3 ~59 stained_glass 0  
fill ~6 ~3 ~60 ~7 ~3 ~60 stained_glass 14  
fill ~6 ~3 ~61 ~7 ~3 ~61 stained_glass 14  
fill ~6 ~3 ~62 ~7 ~3 ~62 stained_glass 14  
fill ~6 ~3 ~63 ~7 ~3 ~63 stained_glass 0  
fill ~6 ~3 ~64 ~7 ~3 ~64 stained_glass 0  
fill ~6 ~3 ~65 ~7 ~3 ~65 stained_glass 0  
fill ~6 ~3 ~66 ~7 ~3 ~66 stained_glass 0  
fill ~6 ~3 ~67 ~7 ~3 ~67 stained_glass 0  
fill ~6 ~3 ~68 ~7 ~3 ~68 stained_glass 0  
fill ~6 ~3 ~69 ~7 ~3 ~69 glowstone 0  
fill ~6 ~3 ~70 ~7 ~3 ~70 stained_glass 0  
fill ~6 ~3 ~71 ~7 ~3 ~71 stained_glass 0  
fill ~6 ~3 ~72 ~7 ~3 ~72 stained_glass 0  
fill ~6 ~3 ~73 ~7 ~3 ~73 stained_glass 0  
fill ~6 ~3 ~74 ~7 ~3 ~74 stained_glass 0  
fill ~7 ~3 ~44 ~8 ~3 ~44 stained_glass 0  
fill ~7 ~3 ~45 ~8 ~3 ~45 stained_glass 0  
fill ~7 ~3 ~46 ~8 ~3 ~46 stained_glass 0  
fill ~7 ~3 ~47 ~8 ~3 ~47 stained_glass 0  
fill ~7 ~3 ~75 ~8 ~3 ~75 stained_glass 0  
fill ~7 ~3 ~76 ~8 ~3 ~76 stained_glass 0  
fill ~7 ~3 ~77 ~8 ~3 ~77 stained_glass 0    
fill ~7 ~3 ~78 ~8 ~3 ~78 stained_glass 0  
fill ~8 ~3 ~41 ~9 ~3 ~41 stained_glass 0  
fill ~8 ~3 ~42 ~9 ~3 ~42 stained_glass 0  
fill ~8 ~3 ~43 ~9 ~3 ~43 stained_glass 0  
fill ~8 ~3 ~79 ~9 ~3 ~79 stained_glass 0  
fill ~8 ~3 ~80 ~9 ~3 ~80 stained_glass 0  
fill ~8 ~3 ~81 ~9 ~3 ~81 stained_glass 0  
fill ~9 ~3 ~39 ~10 ~3 ~39 stained_glass 0  
fill ~9 ~3 ~40 ~10 ~3 ~40 stained_glass 0  
fill ~9 ~3 ~82 ~10 ~3 ~82 stained_glass 0  
fill ~9 ~3 ~83 ~10 ~3 ~83 stained_glass 0  
fill ~10 ~3 ~36 ~11 ~3 ~36 stained_glass 0  
fill ~10 ~3 ~37 ~11 ~3 ~37 stained_glass 0  
fill ~10 ~3 ~38 ~11 ~3 ~38 stained_glass 0  
fill ~10 ~3 ~84 ~11 ~3 ~84 stained_glass 0  
fill ~10 ~3 ~85 ~11 ~3 ~85 stained_glass 0  
fill ~10 ~3 ~86 ~11 ~3 ~86 stained_glass 0  
fill ~11 ~3 ~34 ~12 ~3 ~34 stained_glass 0  
fill ~11 ~3 ~35 ~12 ~3 ~35 stained_glass 0  
fill ~11 ~3 ~87 ~12 ~3 ~87 stained_glass 0  
fill ~11 ~3 ~88 ~12 ~3 ~88 stained_glass 0  
fill ~12 ~3 ~32 ~13 ~3 ~32 stained_glass 0  
fill ~12 ~3 ~33 ~13 ~3 ~33 stained_glass 0  
fill ~12 ~3 ~89 ~13 ~3 ~89 stained_glass 0  
fill ~12 ~3 ~90 ~13 ~3 ~90 stained_glass 0  
fill ~13 ~3 ~31 ~14 ~3 ~31 stained_glass 0  
fill ~13 ~3 ~91 ~14 ~3 ~91 stained_glass 0  
fill ~14 ~3 ~29 ~15 ~3 ~29 stained_glass 0  
fill ~14 ~3 ~30 ~15 ~3 ~30 stained_glass 0  
fill ~14 ~3 ~92 ~15 ~3 ~92 stained_glass 0  
fill ~14 ~3 ~93 ~15 ~3 ~93 stained_glass 0  
fill ~15 ~3 ~27 ~16 ~3 ~27 stained_glass 0  
fill ~15 ~3 ~28 ~16 ~3 ~28 stained_glass 0  
fill ~15 ~3 ~94 ~16 ~3 ~94 stained_glass 0  
fill ~15 ~3 ~95 ~16 ~3 ~95 stained_glass 0  
fill ~16 ~3 ~26 ~17 ~3 ~26 stained_glass 0  
fill ~16 ~3 ~96 ~17 ~3 ~96 stained_glass 0  
fill ~17 ~3 ~25 ~18 ~3 ~25 stained_glass 0  
fill ~17 ~3 ~97 ~18 ~3 ~97 stained_glass 0  
fill ~18 ~3 ~23 ~20 ~3 ~23 stained_glass 0  
fill ~18 ~3 ~24 ~19 ~3 ~24 stained_glass 0  
fill ~18 ~3 ~98 ~19 ~3 ~98 stained_glass 0  
fill ~18 ~3 ~99 ~19 ~3 ~99 stained_glass 0 
setblock ~19 ~3 ~100 stained_glass 0 
setblock ~20 ~3 ~22 stained_glass 14 
setblock ~20 ~3 ~100 stained_glass 14 
setblock ~21 ~3 ~21 glowstone 0 
setblock ~21 ~3 ~23 stained_glass 14 
setblock ~21 ~3 ~99 stained_glass 14 
setblock ~21 ~3 ~101 glowstone 0 
setblock ~22 ~3 ~20 stained_glass 11 
setblock ~22 ~3 ~22 glowstone 0 
setblock ~22 ~3 ~100 glowstone 0 
setblock ~22 ~3 ~102 stained_glass 11  
fill ~23 ~3 ~18 ~25 ~3 ~18 stained_glass 0  
fill ~23 ~3 ~19 ~24 ~3 ~19 stained_glass 0  
fill ~23 ~3 ~20 ~23 ~3 ~18 stained_glass 0 
setblock ~23 ~3 ~21 stained_glass 11 
setblock ~23 ~3 ~101 stained_glass 11  
fill ~23 ~3 ~102 ~23 ~3 ~104 stained_glass 0  
fill ~24 ~3 ~103 ~24 ~3 ~104 stained_glass 0  
fill ~25 ~3 ~17 ~26 ~3 ~17 stained_glass 0  
fill ~25 ~3 ~104 ~25 ~3 ~105 stained_glass 0  
fill ~26 ~3 ~16 ~28 ~3 ~16 stained_glass 0  
fill ~26 ~3 ~105 ~26 ~3 ~106 stained_glass 0  
fill ~27 ~3 ~15 ~30 ~3 ~15 stained_glass 0  
fill ~27 ~3 ~106 ~28 ~3 ~106 stained_glass 0  
fill ~27 ~3 ~107 ~30 ~3 ~107 stained_glass 0  
fill ~29 ~3 ~14 ~31 ~3 ~14 stained_glass 0  
fill ~29 ~3 ~108 ~31 ~3 ~108 stained_glass 0  
fill ~31 ~3 ~13 ~33 ~3 ~13 stained_glass 0  
fill ~31 ~3 ~109 ~33 ~3 ~109 stained_glass 0  
fill ~32 ~3 ~12 ~35 ~3 ~12 stained_glass 0  
fill ~32 ~3 ~110 ~35 ~3 ~110 stained_glass 0  
fill ~34 ~3 ~11 ~38 ~3 ~11 stained_glass 0  
fill ~34 ~3 ~111 ~38 ~3 ~111 stained_glass 0  
fill ~36 ~3 ~10 ~40 ~3 ~10 stained_glass 0  
fill ~36 ~3 ~112 ~40 ~3 ~112 stained_glass 0  
fill ~37 ~3 ~76 ~41 ~3 ~76 stained_glass 0  
fill ~37 ~3 ~90 ~41 ~3 ~90 stained_glass 0  
fill ~39 ~3 ~9 ~43 ~3 ~9 stained_glass 0  
fill ~39 ~3 ~113 ~43 ~3 ~113 stained_glass 0  
fill ~41 ~3 ~8 ~47 ~3 ~8 stained_glass 0  
fill ~41 ~3 ~114 ~47 ~3 ~114 stained_glass 0  
fill ~44 ~3 ~7 ~52 ~3 ~7 stained_glass 0  
fill ~44 ~3 ~115 ~52 ~3 ~115 stained_glass 0  
fill ~48 ~3 ~6 ~52 ~3 ~6 stained_glass 0  
fill ~48 ~3 ~116 ~52 ~3 ~116 stained_glass 0  
fill ~53 ~3 ~6 ~53 ~3 ~7 glowstone 0  
fill ~53 ~3 ~115 ~53 ~3 ~116 glowstone 0  
fill ~54 ~3 ~6 ~58 ~3 ~6 stained_glass 0  
fill ~54 ~3 ~7 ~59 ~3 ~7 stained_glass 0  
fill ~54 ~3 ~115 ~59 ~3 ~115 stained_glass 0  
fill ~54 ~3 ~116 ~58 ~3 ~116 stained_glass 0 
setblock ~59 ~3 ~6 obsidian 0  
fill ~59 ~3 ~116 ~63 ~3 ~116 obsidian 0  
fill ~60 ~3 ~7 ~62 ~3 ~7 obsidian 0  
fill ~60 ~3 ~115 ~62 ~3 ~115 stained_glass 11 
setblock ~63 ~3 ~6 obsidian 0  
fill ~63 ~3 ~7 ~68 ~3 ~7 stained_glass 0  
fill ~63 ~3 ~115 ~68 ~3 ~115 stained_glass 0  
fill ~64 ~3 ~6 ~68 ~3 ~6 stained_glass 0  
fill ~64 ~3 ~116 ~68 ~3 ~116 stained_glass 0  
fill ~69 ~3 ~6 ~69 ~3 ~7 glowstone 0  
fill ~69 ~3 ~115 ~69 ~3 ~116 glowstone 0  
fill ~70 ~3 ~6 ~74 ~3 ~6 stained_glass 0  
fill ~70 ~3 ~7 ~78 ~3 ~7 stained_glass 0  
fill ~70 ~3 ~115 ~78 ~3 ~115 stained_glass 0  
fill ~70 ~3 ~116 ~74 ~3 ~116 stained_glass 0  
fill ~75 ~3 ~8 ~81 ~3 ~8 stained_glass 0  
fill ~75 ~3 ~114 ~81 ~3 ~114 stained_glass 0  
fill ~79 ~3 ~9 ~83 ~3 ~9 stained_glass 0  
fill ~79 ~3 ~113 ~83 ~3 ~113 stained_glass 0  
fill ~81 ~3 ~32 ~85 ~3 ~32 stained_glass 0  
fill ~81 ~3 ~46 ~85 ~3 ~46 stained_glass 0  
fill ~82 ~3 ~10 ~86 ~3 ~10 stained_glass 0  
fill ~82 ~3 ~112 ~86 ~3 ~112 stained_glass 0  
fill ~84 ~3 ~11 ~88 ~3 ~11 stained_glass 0  
fill ~84 ~3 ~111 ~88 ~3 ~111 stained_glass 0  
fill ~87 ~3 ~12 ~90 ~3 ~12 stained_glass 0  
fill ~87 ~3 ~110 ~90 ~3 ~110 stained_glass 0  
fill ~89 ~3 ~13 ~91 ~3 ~13 stained_glass 0  
fill ~89 ~3 ~109 ~91 ~3 ~109 stained_glass 0  
fill ~91 ~3 ~14 ~93 ~3 ~14 stained_glass 0  
fill ~91 ~3 ~108 ~93 ~3 ~108 stained_glass 0  
fill ~92 ~3 ~15 ~95 ~3 ~15 stained_glass 0  
fill ~92 ~3 ~107 ~95 ~3 ~107 stained_glass 0  
fill ~94 ~3 ~16 ~96 ~3 ~16 stained_glass 0  
fill ~94 ~3 ~106 ~96 ~3 ~106 stained_glass 0  
fill ~96 ~3 ~17 ~97 ~3 ~17 stained_glass 0  
fill ~96 ~3 ~105 ~97 ~3 ~105 stained_glass 0  
fill ~97 ~3 ~18 ~99 ~3 ~18 stained_glass 0  
fill ~97 ~3 ~104 ~99 ~3 ~104 stained_glass 0  
fill ~98 ~3 ~19 ~99 ~3 ~19 stained_glass 0  
fill ~98 ~3 ~103 ~99 ~3 ~103 stained_glass 0 
setblock ~99 ~3 ~20 stained_glass 0 
setblock ~99 ~3 ~21 stained_glass 11 
setblock ~99 ~3 ~101 stained_glass 11 
setblock ~99 ~3 ~102 stained_glass 0 
setblock ~100 ~3 ~20 stained_glass 11 
setblock ~100 ~3 ~22 glowstone 0 
setblock ~100 ~3 ~100 glowstone 0 
setblock ~100 ~3 ~102 stained_glass 11 
setblock ~101 ~3 ~21 glowstone 0 
setblock ~101 ~3 ~23 stained_glass 14 
setblock ~101 ~3 ~99 stained_glass 14 
setblock ~101 ~3 ~101 glowstone 0 
setblock ~102 ~3 ~22 stained_glass 14  
fill ~102 ~3 ~99 ~104 ~3 ~99 stained_glass 0 
setblock ~102 ~3 ~100 stained_glass 14  
fill ~103 ~3 ~22 ~103 ~3 ~24 stained_glass 0  
fill ~103 ~3 ~98 ~104 ~3 ~98 stained_glass 0  
fill ~104 ~3 ~23 ~104 ~3 ~25 stained_glass 0  
fill ~104 ~3 ~97 ~105 ~3 ~97 stained_glass 0  
fill ~105 ~3 ~25 ~105 ~3 ~26 stained_glass 0  
fill ~105 ~3 ~96 ~106 ~3 ~96 stained_glass 0  
fill ~106 ~3 ~26 ~106 ~3 ~28 stained_glass 0  
fill ~106 ~3 ~94 ~107 ~3 ~94 stained_glass 0  
fill ~106 ~3 ~95 ~107 ~3 ~95 stained_glass 0  
fill ~107 ~3 ~27 ~107 ~3 ~30 stained_glass 0  
fill ~107 ~3 ~92 ~108 ~3 ~92 stained_glass 0  
fill ~107 ~3 ~93 ~108 ~3 ~93 stained_glass 0  
fill ~108 ~3 ~29 ~108 ~3 ~31 stained_glass 0  
fill ~108 ~3 ~91 ~109 ~3 ~91 stained_glass 0  
fill ~109 ~3 ~31 ~109 ~3 ~33 stained_glass 0  
fill ~109 ~3 ~89 ~110 ~3 ~89 stained_glass 0  
fill ~109 ~3 ~90 ~110 ~3 ~90 stained_glass 0  
fill ~110 ~3 ~32 ~110 ~3 ~35 stained_glass 0  
fill ~110 ~3 ~87 ~111 ~3 ~87 stained_glass 0  
fill ~110 ~3 ~88 ~111 ~3 ~88 stained_glass 0  
fill ~111 ~3 ~34 ~111 ~3 ~38 stained_glass 0  
fill ~111 ~3 ~84 ~112 ~3 ~84 stained_glass 0  
fill ~111 ~3 ~85 ~112 ~3 ~85 stained_glass 0  
fill ~111 ~3 ~86 ~112 ~3 ~86 stained_glass 0  
fill ~112 ~3 ~36 ~112 ~3 ~40 stained_glass 0  
fill ~112 ~3 ~82 ~113 ~3 ~82 stained_glass 0  
fill ~112 ~3 ~83 ~113 ~3 ~83 stained_glass 0  
fill ~113 ~3 ~39 ~113 ~3 ~43 stained_glass 0  
fill ~113 ~3 ~79 ~114 ~3 ~79 stained_glass 0  
fill ~113 ~3 ~80 ~114 ~3 ~80 stained_glass 0  
fill ~113 ~3 ~81 ~114 ~3 ~81 stained_glass 0  
fill ~114 ~3 ~41 ~114 ~3 ~47 stained_glass 0  
fill ~114 ~3 ~75 ~115 ~3 ~75 stained_glass 0  
fill ~114 ~3 ~76 ~115 ~3 ~76 stained_glass 0  
fill ~114 ~3 ~77 ~115 ~3 ~77 stained_glass 0  
fill ~114 ~3 ~78 ~115 ~3 ~78 stained_glass 0  
fill ~115 ~3 ~44 ~115 ~3 ~52 stained_glass 0  
fill ~115 ~3 ~53 ~116 ~3 ~53 glowstone 0  
fill ~115 ~3 ~54 ~116 ~3 ~54 stained_glass 0  
fill ~115 ~3 ~55 ~116 ~3 ~55 stained_glass 0  
fill ~115 ~3 ~56 ~116 ~3 ~56 stained_glass 0  
fill ~115 ~3 ~57 ~116 ~3 ~57 stained_glass 0  
fill ~115 ~3 ~58 ~116 ~3 ~58 stained_glass 0  
fill ~115 ~3 ~59 ~116 ~3 ~59 stained_glass 0  
fill ~115 ~3 ~60 ~116 ~3 ~60 stained_glass 14  
fill ~115 ~3 ~61 ~116 ~3 ~61 stained_glass 14  
fill ~115 ~3 ~62 ~116 ~3 ~62 stained_glass 14  
fill ~115 ~3 ~63 ~116 ~3 ~63 stained_glass 0  
fill ~115 ~3 ~64 ~116 ~3 ~64 stained_glass 0  
fill ~115 ~3 ~65 ~116 ~3 ~65 stained_glass 0  
fill ~115 ~3 ~66 ~116 ~3 ~66 stained_glass 0  
fill ~115 ~3 ~67 ~116 ~3 ~67 stained_glass 0  
fill ~115 ~3 ~68 ~116 ~3 ~68 stained_glass 0  
fill ~115 ~3 ~69 ~116 ~3 ~69 glowstone 0  
fill ~115 ~3 ~70 ~116 ~3 ~70 stained_glass 0  
fill ~115 ~3 ~71 ~116 ~3 ~71 stained_glass 0  
fill ~115 ~3 ~72 ~116 ~3 ~72 stained_glass 0  
fill ~115 ~3 ~73 ~116 ~3 ~73 stained_glass 0  
fill ~115 ~3 ~74 ~116 ~3 ~74 stained_glass 0  
fill ~116 ~3 ~48 ~116 ~3 ~52 stained_glass 0  
fill ~117 ~3 ~59 ~117 ~2 ~59 obsidian 0  
fill ~117 ~3 ~60 ~117 ~3 ~63 obsidian 0  
fill ~8 ~4 ~48 ~12 ~4 ~48 stained_glass 0  
fill ~8 ~4 ~49 ~11 ~4 ~49 stained_glass 0  
fill ~8 ~4 ~50 ~11 ~4 ~50 stained_glass 0  
fill ~8 ~4 ~51 ~11 ~4 ~51 stained_glass 0  
fill ~8 ~4 ~52 ~11 ~4 ~52 stained_glass 0  
fill ~8 ~4 ~53 ~11 ~4 ~53 glowstone 0  
fill ~8 ~4 ~54 ~10 ~4 ~54 stained_glass 0  
fill ~8 ~4 ~55 ~10 ~4 ~55 stained_glass 0  
fill ~8 ~4 ~56 ~10 ~4 ~56 stained_glass 0  
fill ~8 ~4 ~57 ~10 ~4 ~57 stained_glass 0  
fill ~8 ~4 ~58 ~10 ~4 ~58 stained_glass 0  
fill ~8 ~4 ~59 ~10 ~4 ~59 stained_glass 0  
fill ~8 ~4 ~60 ~10 ~4 ~60 stained_glass 14  
fill ~8 ~4 ~61 ~10 ~4 ~61 stained_glass 14  
fill ~8 ~4 ~62 ~10 ~4 ~62 stained_glass 14  
fill ~8 ~4 ~63 ~10 ~4 ~63 stained_glass 0  
fill ~8 ~4 ~64 ~10 ~4 ~64 stained_glass 0  
fill ~8 ~4 ~65 ~10 ~4 ~65 stained_glass 0  
fill ~8 ~4 ~66 ~10 ~4 ~66 stained_glass 0  
fill ~8 ~4 ~67 ~10 ~4 ~67 stained_glass 0  
fill ~8 ~4 ~68 ~10 ~4 ~68 stained_glass 0  
fill ~8 ~4 ~69 ~11 ~4 ~69 glowstone 0  
fill ~8 ~4 ~70 ~11 ~4 ~70 stained_glass 0  
fill ~8 ~4 ~71 ~11 ~4 ~71 stained_glass 0  
fill ~8 ~4 ~72 ~11 ~4 ~72 stained_glass 0  
fill ~8 ~4 ~73 ~11 ~4 ~73 stained_glass 0  
fill ~8 ~4 ~74 ~12 ~4 ~74 stained_glass 0  
fill ~9 ~4 ~44 ~13 ~4 ~44 stained_glass 0  
fill ~9 ~4 ~45 ~13 ~4 ~45 stained_glass 0  
fill ~9 ~4 ~46 ~12 ~4 ~46 stained_glass 0  
fill ~9 ~4 ~47 ~12 ~4 ~47 stained_glass 0  
fill ~9 ~4 ~75 ~12 ~4 ~75 stained_glass 0  
fill ~9 ~4 ~76 ~12 ~4 ~76 stained_glass 0  
fill ~9 ~4 ~77 ~13 ~4 ~77 stained_glass 0  
fill ~9 ~4 ~78 ~13 ~4 ~78 stained_glass 0  
fill ~10 ~4 ~41 ~14 ~4 ~41 stained_glass 0  
fill ~10 ~4 ~42 ~14 ~4 ~42 stained_glass 0  
fill ~10 ~4 ~43 ~13 ~4 ~43 stained_glass 0  
fill ~10 ~4 ~79 ~13 ~4 ~79 stained_glass 0  
fill ~10 ~4 ~80 ~14 ~4 ~80 stained_glass 0  
fill ~10 ~4 ~81 ~14 ~4 ~81 stained_glass 0  
fill ~11 ~4 ~39 ~15 ~4 ~39 stained_glass 0  
fill ~11 ~4 ~40 ~15 ~4 ~40 stained_glass 0  
fill ~11 ~4 ~54 ~11 ~4 ~68 iron_block 0  
fill ~11 ~4 ~82 ~15 ~4 ~82 stained_glass 0  
fill ~11 ~4 ~83 ~15 ~4 ~83 stained_glass 0  
fill ~12 ~4 ~36 ~17 ~4 ~36 stained_glass 0  
fill ~12 ~4 ~37 ~16 ~4 ~37 stained_glass 0  
fill ~12 ~4 ~38 ~16 ~4 ~38 stained_glass 0  
fill ~12 ~4 ~49 ~12 ~4 ~53 iron_block 0  
fill ~12 ~4 ~69 ~12 ~4 ~73 iron_block 0  
fill ~12 ~4 ~84 ~16 ~4 ~84 stained_glass 0  
fill ~12 ~4 ~85 ~16 ~4 ~85 stained_glass 0  
fill ~12 ~4 ~86 ~17 ~4 ~86 stained_glass 0  
fill ~13 ~4 ~34 ~18 ~4 ~34 stained_glass 0  
fill ~13 ~4 ~35 ~17 ~4 ~35 stained_glass 0  
fill ~13 ~4 ~46 ~13 ~4 ~48 iron_block 0  
fill ~13 ~4 ~74 ~13 ~4 ~76 iron_block 0  
fill ~13 ~4 ~87 ~17 ~4 ~87 stained_glass 0  
fill ~13 ~4 ~88 ~18 ~4 ~88 stained_glass 0  
fill ~14 ~4 ~32 ~19 ~4 ~32 stained_glass 0  
fill ~14 ~4 ~33 ~18 ~4 ~33 stained_glass 0  
fill ~14 ~4 ~43 ~14 ~4 ~45 iron_block 0  
fill ~14 ~4 ~77 ~14 ~4 ~79 iron_block 0  
fill ~14 ~4 ~89 ~18 ~4 ~89 stained_glass 0  
fill ~14 ~4 ~90 ~19 ~4 ~90 stained_glass 0  
fill ~15 ~4 ~31 ~20 ~4 ~31 stained_glass 0  
fill ~15 ~4 ~41 ~15 ~4 ~42 iron_block 0  
fill ~15 ~4 ~80 ~15 ~4 ~81 iron_block 0  
fill ~15 ~4 ~91 ~20 ~4 ~91 stained_glass 0  
fill ~16 ~4 ~29 ~21 ~4 ~29 stained_glass 0  
fill ~16 ~4 ~30 ~21 ~4 ~30 stained_glass 0  
fill ~16 ~4 ~39 ~16 ~4 ~40 iron_block 0  
fill ~16 ~4 ~82 ~16 ~4 ~83 iron_block 0  
fill ~16 ~4 ~92 ~21 ~4 ~92 stained_glass 0  
fill ~16 ~4 ~93 ~21 ~4 ~93 stained_glass 0  
fill ~17 ~4 ~27 ~23 ~4 ~27 stained_glass 0  
fill ~17 ~4 ~28 ~22 ~4 ~28 stained_glass 0  
fill ~17 ~4 ~37 ~17 ~4 ~38 iron_block 0  
fill ~17 ~4 ~84 ~17 ~4 ~85 iron_block 0  
fill ~17 ~4 ~94 ~22 ~4 ~94 stained_glass 0  
fill ~17 ~4 ~95 ~23 ~4 ~95 stained_glass 0  
fill ~18 ~4 ~26 ~23 ~4 ~26 stained_glass 0  
fill ~18 ~4 ~35 ~18 ~4 ~36 iron_block 0  
fill ~18 ~4 ~86 ~18 ~4 ~87 iron_block 0  
fill ~18 ~4 ~96 ~23 ~4 ~96 stained_glass 0  
fill ~19 ~4 ~25 ~22 ~4 ~25 stained_glass 0  
fill ~19 ~4 ~33 ~19 ~4 ~34 iron_block 0  
fill ~19 ~4 ~88 ~19 ~4 ~89 iron_block 0  
fill ~19 ~4 ~97 ~22 ~4 ~97 stained_glass 0  
fill ~20 ~4 ~24 ~21 ~4 ~24 stained_glass 0 
setblock ~20 ~4 ~32 iron_block 0 
setblock ~20 ~4 ~90 iron_block 0  
fill ~20 ~4 ~98 ~21 ~4 ~98 stained_glass 0  
fill ~20 ~4 ~99 ~20 ~4 ~91 stained_glass 0 
setblock ~21 ~4 ~31 iron_block 0 
setblock ~21 ~4 ~91 iron_block 0 
setblock ~22 ~4 ~24 stained_glass 14  
fill ~22 ~4 ~29 ~22 ~4 ~30 iron_block 0  
fill ~22 ~4 ~92 ~22 ~4 ~93 iron_block 0 
setblock ~22 ~4 ~98 stained_glass 14 
setblock ~23 ~4 ~23 glowstone 0 
setblock ~23 ~4 ~25 stained_glass 14 
setblock ~23 ~4 ~28 iron_block 0 
setblock ~23 ~4 ~94 iron_block 0 
setblock ~23 ~4 ~97 stained_glass 14 
setblock ~23 ~4 ~99 glowstone 0  
fill ~24 ~4 ~20 ~31 ~4 ~20 stained_glass 0  
fill ~24 ~4 ~21 ~30 ~4 ~21 stained_glass 0 
setblock ~24 ~4 ~22 stained_glass 11 
setblock ~24 ~4 ~24 glowstone 0 
setblock ~24 ~4 ~26 stained_glass 14 
setblock ~24 ~4 ~27 iron_block 0 
setblock ~24 ~4 ~95 iron_block 0 
setblock ~24 ~4 ~96 stained_glass 14 
setblock ~24 ~4 ~98 glowstone 0 
setblock ~24 ~4 ~100 stained_glass 11  
fill ~24 ~4 ~101 ~30 ~4 ~101 stained_glass 0  
fill ~24 ~4 ~102 ~31 ~4 ~102 stained_glass 0  
fill ~25 ~4 ~19 ~32 ~4 ~19 stained_glass 0  
fill ~25 ~4 ~22 ~28 ~4 ~22 stained_glass 0 
setblock ~25 ~4 ~23 stained_glass 11 
setblock ~25 ~4 ~25 glowstone 0 
setblock ~25 ~4 ~26 iron_block 0 
setblock ~25 ~4 ~96 iron_block 0 
setblock ~25 ~4 ~97 glowstone 0 
setblock ~25 ~4 ~99 stained_glass 11  
fill ~25 ~4 ~100 ~28 ~4 ~100 stained_glass 0  
fill ~25 ~4 ~103 ~32 ~4 ~103 stained_glass 0  
fill ~26 ~4 ~18 ~34 ~4 ~18 stained_glass 0  
fill ~26 ~4 ~23 ~27 ~4 ~23 stained_glass 0 
setblock ~26 ~4 ~24 stained_glass 11 
setblock ~26 ~4 ~25 iron_block 0 
setblock ~26 ~4 ~97 iron_block 0 
setblock ~26 ~4 ~98 stained_glass 11  
fill ~26 ~4 ~99 ~27 ~4 ~99 stained_glass 0  
fill ~26 ~4 ~104 ~34 ~4 ~104 stained_glass 0  
fill ~27 ~4 ~17 ~36 ~4 ~17 stained_glass 0 
setblock ~27 ~4 ~24 iron_block 0 
setblock ~27 ~4 ~98 iron_block 0  
fill ~27 ~4 ~105 ~36 ~4 ~105 stained_glass 0 
setblock ~28 ~4 ~23 iron_block 0 
setblock ~28 ~4 ~99 iron_block 0  
fill ~29 ~4 ~16 ~38 ~4 ~16 stained_glass 0  
fill ~29 ~4 ~22 ~30 ~4 ~22 iron_block 0  
fill ~29 ~4 ~100 ~30 ~4 ~100 iron_block 0  
fill ~29 ~4 ~106 ~38 ~4 ~106 stained_glass 0  
fill ~31 ~4 ~15 ~40 ~4 ~15 stained_glass 0 
setblock ~31 ~4 ~21 iron_block 0 
setblock ~31 ~4 ~101 iron_block 0  
fill ~31 ~4 ~107 ~40 ~4 ~107 stained_glass 0  
fill ~32 ~4 ~14 ~42 ~4 ~14 stained_glass 0 
setblock ~32 ~4 ~20 iron_block 0 
setblock ~32 ~4 ~102 iron_block 0  
fill ~32 ~4 ~108 ~42 ~4 ~108 stained_glass 0  
fill ~33 ~4 ~19 ~34 ~4 ~19 iron_block 0  
fill ~33 ~4 ~81 ~33 ~4 ~85 stained_glass 0  
fill ~33 ~4 ~103 ~34 ~4 ~103 iron_block 0  
fill ~34 ~4 ~13 ~45 ~4 ~13 stained_glass 0  
fill ~34 ~4 ~80 ~34 ~5 ~80 stained_glass 14  
fill ~34 ~4 ~85 ~34 ~5 ~85 stained_glass 0  
fill ~34 ~4 ~86 ~34 ~5 ~86 stained_glass 14  
fill ~34 ~4 ~109 ~45 ~4 ~109 stained_glass 0  
fill ~35 ~4 ~18 ~36 ~4 ~18 iron_block 0  
fill ~35 ~4 ~79 ~35 ~5 ~79 glowstone 0  
fill ~35 ~4 ~87 ~35 ~5 ~87 glowstone 0  
fill ~35 ~4 ~104 ~36 ~4 ~104 iron_block 0  
fill ~36 ~4 ~12 ~48 ~4 ~12 stained_glass 0  
fill ~36 ~4 ~78 ~36 ~5 ~78 stained_glass 11  
fill ~36 ~4 ~88 ~36 ~5 ~88 stained_glass 11  
fill ~36 ~4 ~110 ~48 ~4 ~110 stained_glass 0  
fill ~37 ~4 ~17 ~38 ~4 ~17 iron_block 0  
fill ~37 ~4 ~77 ~41 ~4 ~77 stained_glass 0  
fill ~37 ~4 ~78 ~37 ~5 ~78 stained_glass 0  
fill ~37 ~4 ~89 ~41 ~4 ~89 stained_glass 0  
fill ~37 ~4 ~105 ~38 ~4 ~105 iron_block 0  
fill ~39 ~4 ~11 ~52 ~4 ~11 stained_glass 0  
fill ~39 ~4 ~16 ~40 ~4 ~16 iron_block 0  
fill ~39 ~4 ~106 ~40 ~4 ~106 iron_block 0  
fill ~39 ~4 ~111 ~52 ~4 ~111 stained_glass 0  
fill ~41 ~4 ~10 ~52 ~4 ~10 stained_glass 0  
fill ~41 ~4 ~15 ~42 ~4 ~15 iron_block 0  
fill ~41 ~4 ~88 ~41 ~5 ~88 stained_glass 0  
fill ~41 ~4 ~107 ~42 ~4 ~107 iron_block 0  
fill ~41 ~4 ~112 ~52 ~4 ~112 stained_glass 0 
setblock ~42 ~4 ~77 stained_glass 11  
fill ~42 ~4 ~88 ~42 ~5 ~88 stained_glass 11  
fill ~43 ~4 ~14 ~45 ~4 ~14 iron_block 0  
fill ~43 ~4 ~87 ~43 ~5 ~87 glowstone 0  
fill ~43 ~4 ~108 ~45 ~4 ~108 iron_block 0  
fill ~44 ~4 ~9 ~52 ~4 ~9 stained_glass 0  
fill ~44 ~4 ~85 ~45 ~4 ~85 stained_glass 0  
fill ~44 ~4 ~86 ~44 ~5 ~86 stained_glass 14  
fill ~44 ~4 ~113 ~52 ~4 ~113 stained_glass 0 
setblock ~45 ~4 ~80 stained_glass 14  
fill ~45 ~4 ~81 ~45 ~4 ~85 stained_glass 0  
fill ~46 ~4 ~13 ~48 ~4 ~13 iron_block 0  
fill ~46 ~4 ~109 ~48 ~4 ~109 iron_block 0  
fill ~48 ~4 ~8 ~52 ~4 ~8 stained_glass 0  
fill ~48 ~4 ~114 ~52 ~4 ~114 stained_glass 0  
fill ~49 ~4 ~12 ~53 ~4 ~12 iron_block 0  
fill ~49 ~4 ~110 ~53 ~4 ~110 iron_block 0  
fill ~53 ~4 ~8 ~53 ~4 ~11 glowstone 0  
fill ~53 ~4 ~111 ~53 ~4 ~114 glowstone 0  
fill ~54 ~4 ~8 ~59 ~4 ~8 stained_glass 0  
fill ~54 ~4 ~9 ~59 ~4 ~9 stained_glass 0  
fill ~54 ~4 ~10 ~59 ~4 ~10 stained_glass 0  
fill ~54 ~4 ~11 ~68 ~4 ~11 iron_block 0  
fill ~54 ~4 ~111 ~68 ~4 ~111 iron_block 0  
fill ~54 ~4 ~112 ~59 ~4 ~112 stained_glass 0  
fill ~54 ~4 ~113 ~59 ~4 ~113 stained_glass 0  
fill ~54 ~4 ~114 ~59 ~4 ~114 stained_glass 0  
fill ~60 ~4 ~8 ~62 ~4 ~8 stained_glass 11  
fill ~60 ~4 ~9 ~62 ~4 ~9 stained_glass 11  
fill ~60 ~4 ~10 ~62 ~4 ~10 stained_glass 11  
fill ~60 ~4 ~112 ~62 ~4 ~112 stained_glass 11  
fill ~60 ~4 ~113 ~62 ~4 ~113 stained_glass 11  
fill ~60 ~4 ~114 ~62 ~4 ~114 stained_glass 11  
fill ~63 ~4 ~8 ~68 ~4 ~8 stained_glass 0  
fill ~63 ~4 ~9 ~68 ~4 ~9 stained_glass 0  
fill ~63 ~4 ~10 ~68 ~4 ~10 stained_glass 0  
fill ~63 ~4 ~112 ~68 ~4 ~112 stained_glass 0  
fill ~63 ~4 ~113 ~68 ~4 ~113 stained_glass 0  
fill ~63 ~4 ~114 ~68 ~4 ~114 stained_glass 0  
fill ~69 ~4 ~8 ~69 ~4 ~11 glowstone 0  
fill ~69 ~4 ~12 ~73 ~4 ~12 iron_block 0  
fill ~69 ~4 ~110 ~73 ~4 ~110 iron_block 0  
fill ~69 ~4 ~111 ~69 ~4 ~114 glowstone 0  
fill ~70 ~4 ~8 ~74 ~4 ~8 stained_glass 0  
fill ~70 ~4 ~9 ~78 ~4 ~9 stained_glass 0  
fill ~70 ~4 ~10 ~81 ~4 ~10 stained_glass 0  
fill ~70 ~4 ~11 ~83 ~4 ~11 stained_glass 0  
fill ~70 ~4 ~111 ~83 ~4 ~111 stained_glass 0  
fill ~70 ~4 ~112 ~81 ~4 ~112 stained_glass 0  
fill ~70 ~4 ~113 ~78 ~4 ~113 stained_glass 0  
fill ~70 ~4 ~114 ~74 ~4 ~114 stained_glass 0  
fill ~74 ~4 ~12 ~86 ~4 ~12 stained_glass 0  
fill ~74 ~4 ~13 ~76 ~4 ~13 iron_block 0  
fill ~74 ~4 ~109 ~76 ~4 ~109 iron_block 0  
fill ~74 ~4 ~110 ~86 ~4 ~110 stained_glass 0  
fill ~77 ~4 ~13 ~88 ~4 ~13 stained_glass 0  
fill ~77 ~4 ~14 ~79 ~4 ~14 iron_block 0  
fill ~77 ~4 ~37 ~78 ~4 ~37 stained_glass 0  
fill ~77 ~4 ~38 ~77 ~4 ~41 stained_glass 0 
setblock ~77 ~4 ~42 stained_glass 14  
fill ~77 ~4 ~108 ~79 ~4 ~108 iron_block 0  
fill ~77 ~4 ~109 ~88 ~4 ~109 stained_glass 0  
fill ~78 ~4 ~36 ~78 ~5 ~36 stained_glass 14  
fill ~79 ~4 ~35 ~79 ~5 ~35 glowstone 0  
fill ~80 ~4 ~14 ~90 ~4 ~14 stained_glass 0  
fill ~80 ~4 ~15 ~81 ~4 ~15 iron_block 0  
fill ~80 ~4 ~34 ~80 ~5 ~34 stained_glass 11 
setblock ~80 ~4 ~45 stained_glass 11  
fill ~80 ~4 ~107 ~81 ~4 ~107 iron_block 0  
fill ~80 ~4 ~108 ~90 ~4 ~108 stained_glass 0  
fill ~81 ~4 ~33 ~85 ~4 ~33 stained_glass 0  
fill ~81 ~4 ~34 ~81 ~5 ~34 stained_glass 0  
fill ~81 ~4 ~45 ~85 ~4 ~45 stained_glass 0  
fill ~82 ~4 ~15 ~91 ~4 ~15 stained_glass 0  
fill ~82 ~4 ~16 ~83 ~4 ~16 iron_block 0  
fill ~82 ~4 ~106 ~83 ~4 ~106 iron_block 0  
fill ~82 ~4 ~107 ~91 ~4 ~107 stained_glass 0  
fill ~84 ~4 ~16 ~93 ~4 ~16 stained_glass 0  
fill ~84 ~4 ~17 ~85 ~4 ~17 iron_block 0  
fill ~84 ~4 ~105 ~85 ~4 ~105 iron_block 0  
fill ~84 ~4 ~106 ~93 ~4 ~106 stained_glass 0  
fill ~85 ~4 ~44 ~85 ~5 ~44 stained_glass 0  
fill ~86 ~4 ~17 ~95 ~4 ~17 stained_glass 0  
fill ~86 ~4 ~18 ~87 ~4 ~18 iron_block 0  
fill ~86 ~4 ~34 ~86 ~5 ~34 stained_glass 11  
fill ~86 ~4 ~44 ~86 ~5 ~44 stained_glass 11  
fill ~86 ~4 ~104 ~87 ~4 ~104 iron_block 0  
fill ~86 ~4 ~105 ~95 ~4 ~105 stained_glass 0  
fill ~87 ~4 ~35 ~87 ~5 ~35 glowstone 0  
fill ~87 ~4 ~43 ~87 ~5 ~43 glowstone 0  
fill ~88 ~4 ~18 ~96 ~4 ~18 stained_glass 0  
fill ~88 ~4 ~19 ~89 ~4 ~19 iron_block 0  
fill ~88 ~4 ~36 ~88 ~5 ~36 stained_glass 14  
fill ~88 ~4 ~37 ~89 ~4 ~37 stained_glass 0  
fill ~88 ~4 ~42 ~88 ~5 ~42 stained_glass 14  
fill ~88 ~4 ~103 ~89 ~4 ~103 iron_block 0  
fill ~88 ~4 ~104 ~96 ~4 ~104 stained_glass 0  
fill ~89 ~4 ~38 ~89 ~4 ~41 stained_glass 0  
fill ~90 ~4 ~19 ~97 ~4 ~19 stained_glass 0 
setblock ~90 ~4 ~20 iron_block 0 
setblock ~90 ~4 ~102 iron_block 0  
fill ~90 ~4 ~103 ~97 ~4 ~103 stained_glass 0  
fill ~91 ~4 ~20 ~98 ~4 ~20 stained_glass 0 
setblock ~91 ~4 ~21 iron_block 0 
setblock ~91 ~4 ~101 iron_block 0  
fill ~91 ~4 ~102 ~98 ~4 ~102 stained_glass 0  
fill ~92 ~4 ~21 ~98 ~4 ~21 stained_glass 0  
fill ~92 ~4 ~22 ~93 ~4 ~22 iron_block 0  
fill ~92 ~4 ~100 ~93 ~4 ~100 iron_block 0  
fill ~92 ~4 ~101 ~98 ~4 ~101 stained_glass 0  
fill ~94 ~4 ~22 ~97 ~4 ~22 stained_glass 0 
setblock ~94 ~4 ~23 iron_block 0 
setblock ~94 ~4 ~99 iron_block 0  
fill ~94 ~4 ~100 ~97 ~4 ~100 stained_glass 0  
fill ~95 ~4 ~23 ~96 ~4 ~23 stained_glass 0 
setblock ~95 ~4 ~24 iron_block 0 
setblock ~95 ~4 ~98 iron_block 0  
fill ~95 ~4 ~99 ~96 ~4 ~99 stained_glass 0 
setblock ~96 ~4 ~24 stained_glass 11 
setblock ~96 ~4 ~25 iron_block 0 
setblock ~96 ~4 ~97 iron_block 0 
setblock ~96 ~4 ~98 stained_glass 11 
setblock ~97 ~4 ~23 stained_glass 11 
setblock ~97 ~4 ~25 glowstone 0 
setblock ~97 ~4 ~26 iron_block 0 
setblock ~97 ~4 ~96 iron_block 0 
setblock ~97 ~4 ~97 glowstone 0 
setblock ~97 ~4 ~99 stained_glass 11 
setblock ~98 ~4 ~22 stained_glass 11 
setblock ~98 ~4 ~24 glowstone 0 
setblock ~98 ~4 ~26 stained_glass 14 
setblock ~98 ~4 ~27 iron_block 0 
setblock ~98 ~4 ~95 iron_block 0 
setblock ~98 ~4 ~96 stained_glass 14 
setblock ~98 ~4 ~98 glowstone 0 
setblock ~98 ~4 ~100 stained_glass 11 
setblock ~99 ~4 ~23 glowstone 0 
setblock ~99 ~4 ~25 stained_glass 14  
fill ~99 ~4 ~26 ~104 ~4 ~26 stained_glass 0  
fill ~99 ~4 ~27 ~105 ~4 ~27 stained_glass 0 
setblock ~99 ~4 ~28 iron_block 0 
setblock ~99 ~4 ~94 iron_block 0  
fill ~99 ~4 ~95 ~105 ~4 ~95 stained_glass 0  
fill ~99 ~4 ~96 ~104 ~4 ~96 stained_glass 0 
setblock ~99 ~4 ~97 stained_glass 14 
setblock ~99 ~4 ~99 glowstone 0 
setblock ~100 ~4 ~24 stained_glass 14  
fill ~100 ~4 ~25 ~103 ~4 ~25 stained_glass 0  
fill ~100 ~4 ~28 ~105 ~4 ~28 stained_glass 0  
fill ~100 ~4 ~29 ~100 ~4 ~30 iron_block 0  
fill ~100 ~4 ~92 ~100 ~4 ~93 iron_block 0  
fill ~100 ~4 ~94 ~105 ~4 ~94 stained_glass 0  
fill ~100 ~4 ~97 ~103 ~4 ~97 stained_glass 0 
setblock ~100 ~4 ~98 stained_glass 14  
fill ~101 ~4 ~24 ~102 ~4 ~24 stained_glass 0  
fill ~101 ~4 ~29 ~106 ~4 ~29 stained_glass 0  
fill ~101 ~4 ~30 ~106 ~4 ~30 stained_glass 0 
setblock ~101 ~4 ~31 iron_block 0 
setblock ~101 ~4 ~91 iron_block 0  
fill ~101 ~4 ~92 ~106 ~4 ~92 stained_glass 0  
fill ~101 ~4 ~93 ~106 ~4 ~93 stained_glass 0  
fill ~101 ~4 ~98 ~102 ~4 ~98 stained_glass 0 
setblock ~102 ~4 ~23 stained_glass 0  
fill ~102 ~4 ~31 ~107 ~4 ~31 stained_glass 0 
setblock ~102 ~4 ~32 iron_block 0 
setblock ~102 ~4 ~90 iron_block 0  
fill ~102 ~4 ~91 ~107 ~4 ~91 stained_glass 0  
fill ~103 ~4 ~32 ~108 ~4 ~32 stained_glass 0  
fill ~103 ~4 ~33 ~103 ~4 ~34 iron_block 0  
fill ~103 ~4 ~88 ~103 ~4 ~89 iron_block 0  
fill ~103 ~4 ~90 ~108 ~4 ~90 stained_glass 0  
fill ~104 ~4 ~33 ~108 ~4 ~33 stained_glass 0  
fill ~104 ~4 ~34 ~109 ~4 ~34 stained_glass 0  
fill ~104 ~4 ~35 ~104 ~4 ~36 iron_block 0  
fill ~104 ~4 ~86 ~104 ~4 ~87 iron_block 0  
fill ~104 ~4 ~88 ~109 ~4 ~88 stained_glass 0  
fill ~104 ~4 ~89 ~108 ~4 ~89 stained_glass 0  
fill ~105 ~4 ~35 ~109 ~4 ~35 stained_glass 0  
fill ~105 ~4 ~36 ~110 ~4 ~36 stained_glass 0  
fill ~105 ~4 ~37 ~105 ~4 ~38 iron_block 0  
fill ~105 ~4 ~84 ~105 ~4 ~85 iron_block 0  
fill ~105 ~4 ~86 ~110 ~4 ~86 stained_glass 0  
fill ~105 ~4 ~87 ~109 ~4 ~87 stained_glass 0  
fill ~106 ~4 ~37 ~110 ~4 ~37 stained_glass 0  
fill ~106 ~4 ~38 ~110 ~4 ~38 stained_glass 0  
fill ~106 ~4 ~39 ~106 ~4 ~40 iron_block 0  
fill ~106 ~4 ~82 ~106 ~4 ~83 iron_block 0  
fill ~106 ~4 ~84 ~110 ~4 ~84 stained_glass 0  
fill ~106 ~4 ~85 ~110 ~4 ~85 stained_glass 0  
fill ~107 ~4 ~39 ~111 ~4 ~39 stained_glass 0  
fill ~107 ~4 ~40 ~111 ~4 ~40 stained_glass 0  
fill ~107 ~4 ~41 ~107 ~4 ~42 iron_block 0  
fill ~107 ~4 ~80 ~107 ~4 ~81 iron_block 0  
fill ~107 ~4 ~82 ~111 ~4 ~82 stained_glass 0  
fill ~107 ~4 ~83 ~111 ~4 ~83 stained_glass 0  
fill ~108 ~4 ~41 ~112 ~4 ~41 stained_glass 0  
fill ~108 ~4 ~42 ~112 ~4 ~42 stained_glass 0  
fill ~108 ~4 ~43 ~108 ~4 ~45 iron_block 0  
fill ~108 ~4 ~77 ~108 ~4 ~79 iron_block 0  
fill ~108 ~4 ~80 ~112 ~4 ~80 stained_glass 0  
fill ~108 ~4 ~81 ~112 ~4 ~81 stained_glass 0  
fill ~109 ~4 ~43 ~112 ~4 ~43 stained_glass 0  
fill ~109 ~4 ~44 ~113 ~4 ~44 stained_glass 0  
fill ~109 ~4 ~45 ~113 ~4 ~45 stained_glass 0  
fill ~109 ~4 ~46 ~109 ~4 ~48 iron_block 0  
fill ~109 ~4 ~74 ~109 ~4 ~76 iron_block 0  
fill ~109 ~4 ~77 ~113 ~4 ~77 stained_glass 0  
fill ~109 ~4 ~78 ~113 ~4 ~78 stained_glass 0  
fill ~109 ~4 ~79 ~112 ~4 ~79 stained_glass 0  
fill ~110 ~4 ~46 ~113 ~4 ~46 stained_glass 0  
fill ~110 ~4 ~47 ~113 ~4 ~47 stained_glass 0  
fill ~110 ~4 ~48 ~114 ~4 ~48 stained_glass 0  
fill ~110 ~4 ~49 ~110 ~4 ~53 iron_block 0  
fill ~110 ~4 ~69 ~110 ~4 ~73 iron_block 0  
fill ~110 ~4 ~74 ~114 ~4 ~74 stained_glass 0  
fill ~110 ~4 ~75 ~113 ~4 ~75 stained_glass 0  
fill ~110 ~4 ~76 ~113 ~4 ~76 stained_glass 0  
fill ~111 ~4 ~49 ~114 ~4 ~49 stained_glass 0  
fill ~111 ~4 ~50 ~114 ~4 ~50 stained_glass 0  
fill ~111 ~4 ~51 ~114 ~4 ~51 stained_glass 0  
fill ~111 ~4 ~52 ~114 ~4 ~52 stained_glass 0  
fill ~111 ~4 ~53 ~114 ~4 ~53 glowstone 0  
fill ~111 ~4 ~54 ~111 ~4 ~68 iron_block 0  
fill ~111 ~4 ~69 ~114 ~4 ~69 glowstone 0  
fill ~111 ~4 ~70 ~114 ~4 ~70 stained_glass 0  
fill ~111 ~4 ~71 ~114 ~4 ~71 stained_glass 0  
fill ~111 ~4 ~72 ~114 ~4 ~72 stained_glass 0  
fill ~111 ~4 ~73 ~114 ~4 ~73 stained_glass 0  
fill ~112 ~4 ~54 ~114 ~4 ~54 stained_glass 0  
fill ~112 ~4 ~55 ~114 ~4 ~55 stained_glass 0  
fill ~112 ~4 ~56 ~114 ~4 ~56 stained_glass 0  
fill ~112 ~4 ~57 ~114 ~4 ~57 stained_glass 0  
fill ~112 ~4 ~58 ~114 ~4 ~58 stained_glass 0  
fill ~112 ~4 ~59 ~114 ~4 ~59 stained_glass 0  
fill ~112 ~4 ~60 ~114 ~4 ~60 stained_glass 14  
fill ~112 ~4 ~61 ~114 ~4 ~61 stained_glass 14  
fill ~112 ~4 ~62 ~114 ~4 ~62 stained_glass 14  
fill ~112 ~4 ~63 ~114 ~4 ~63 stained_glass 0  
fill ~112 ~4 ~64 ~114 ~4 ~64 stained_glass 0  
fill ~112 ~4 ~65 ~114 ~4 ~65 stained_glass 0  
fill ~112 ~4 ~66 ~114 ~4 ~66 stained_glass 0  
fill ~112 ~4 ~67 ~114 ~4 ~67 stained_glass 0  
fill ~112 ~4 ~68 ~114 ~4 ~68 stained_glass 0  
fill ~12 ~5 ~54 ~13 ~5 ~54 glowstone 0  
fill ~12 ~5 ~55 ~13 ~5 ~55 stained_glass 0  
fill ~12 ~5 ~56 ~13 ~5 ~56 stained_glass 0  
fill ~12 ~5 ~57 ~13 ~5 ~57 stained_glass 0  
fill ~12 ~5 ~58 ~13 ~5 ~58 stained_glass 0  
fill ~12 ~5 ~59 ~13 ~5 ~59 stained_glass 0  
fill ~12 ~5 ~60 ~13 ~5 ~60 stained_glass 14  
fill ~12 ~5 ~61 ~13 ~5 ~61 stained_glass 14  
fill ~12 ~5 ~62 ~13 ~5 ~62 stained_glass 14  
fill ~12 ~5 ~63 ~13 ~5 ~63 stained_glass 0  
fill ~12 ~5 ~64 ~13 ~5 ~64 stained_glass 0  
fill ~12 ~5 ~65 ~13 ~5 ~65 stained_glass 0  
fill ~12 ~5 ~66 ~13 ~5 ~66 stained_glass 0  
fill ~12 ~5 ~67 ~13 ~5 ~67 stained_glass 0  
fill ~12 ~5 ~68 ~13 ~5 ~68 glowstone 0  
fill ~13 ~5 ~49 ~13 ~5 ~53 stained_glass 0  
fill ~13 ~5 ~69 ~13 ~5 ~73 stained_glass 0  
fill ~14 ~5 ~46 ~14 ~5 ~48 stained_glass 0  
fill ~14 ~5 ~74 ~14 ~5 ~76 stained_glass 0  
fill ~15 ~5 ~43 ~15 ~5 ~45 stained_glass 0  
fill ~15 ~5 ~77 ~15 ~5 ~79 stained_glass 0  
fill ~16 ~5 ~41 ~16 ~5 ~42 stained_glass 0  
fill ~16 ~5 ~80 ~16 ~5 ~81 stained_glass 0  
fill ~17 ~5 ~39 ~17 ~5 ~40 stained_glass 0  
fill ~17 ~5 ~82 ~17 ~5 ~83 stained_glass 0  
fill ~18 ~5 ~37 ~18 ~5 ~38 stained_glass 0  
fill ~18 ~5 ~84 ~18 ~5 ~85 stained_glass 0  
fill ~19 ~5 ~35 ~19 ~5 ~36 stained_glass 0  
fill ~19 ~5 ~86 ~19 ~5 ~87 stained_glass 0  
fill ~20 ~5 ~33 ~20 ~5 ~34 stained_glass 0  
fill ~20 ~5 ~88 ~20 ~5 ~89 stained_glass 0 
setblock ~21 ~5 ~32 stained_glass 0 
setblock ~21 ~5 ~90 stained_glass 0 
setblock ~22 ~5 ~31 stained_glass 0 
setblock ~22 ~5 ~91 stained_glass 0  
fill ~23 ~5 ~29 ~23 ~5 ~30 stained_glass 0  
fill ~23 ~5 ~92 ~23 ~5 ~93 stained_glass 0 
setblock ~24 ~5 ~28 stained_glass 0 
setblock ~24 ~5 ~94 stained_glass 0 
setblock ~25 ~5 ~27 stained_glass 14 
setblock ~25 ~5 ~95 stained_glass 14 
setblock ~26 ~5 ~26 glowstone 0 
setblock ~26 ~5 ~96 glowstone 0 
setblock ~27 ~5 ~25 stained_glass 11 
setblock ~27 ~5 ~97 stained_glass 11  
fill ~28 ~5 ~24 ~28 ~5 ~25 stained_glass 0 
setblock ~28 ~5 ~98 stained_glass 0  
fill ~29 ~5 ~23 ~30 ~5 ~23 stained_glass 0  
fill ~29 ~5 ~99 ~30 ~5 ~99 stained_glass 0 
setblock ~31 ~5 ~22 stained_glass 0 
setblock ~31 ~5 ~100 stained_glass 0 
setblock ~32 ~5 ~21 stained_glass 0 
setblock ~32 ~5 ~101 stained_glass 0  
fill ~33 ~5 ~20 ~34 ~5 ~20 stained_glass 0  
fill ~33 ~5 ~102 ~34 ~5 ~102 stained_glass 0  
fill ~34 ~5 ~81 ~34 ~5 ~85 stained_glass 0  
fill ~35 ~5 ~19 ~36 ~5 ~19 stained_glass 0  
fill ~35 ~5 ~103 ~36 ~5 ~103 stained_glass 0  
fill ~37 ~5 ~18 ~38 ~5 ~18 stained_glass 0  
fill ~37 ~5 ~88 ~41 ~5 ~88 stained_glass 0  
fill ~37 ~5 ~104 ~38 ~5 ~104 stained_glass 0  
fill ~38 ~5 ~78 ~41 ~5 ~78 stained_glass 0  
fill ~39 ~5 ~17 ~40 ~5 ~17 stained_glass 0  
fill ~39 ~5 ~105 ~40 ~5 ~105 stained_glass 0  
fill ~41 ~5 ~16 ~42 ~5 ~16 stained_glass 0  
fill ~41 ~5 ~106 ~42 ~5 ~106 stained_glass 0  
fill ~42 ~5 ~78 ~42 ~6 ~78 stained_glass 11  
fill ~43 ~5 ~15 ~45 ~5 ~15 stained_glass 0  
fill ~43 ~5 ~79 ~43 ~6 ~79 glowstone 0  
fill ~43 ~5 ~107 ~45 ~5 ~107 stained_glass 0  
fill ~44 ~5 ~80 ~44 ~6 ~80 stained_glass 14  
fill ~44 ~5 ~81 ~44 ~5 ~85 stained_glass 0  
fill ~46 ~5 ~14 ~48 ~5 ~14 stained_glass 0  
fill ~46 ~5 ~108 ~48 ~5 ~108 stained_glass 0  
fill ~49 ~5 ~13 ~53 ~5 ~13 stained_glass 0  
fill ~49 ~5 ~109 ~53 ~5 ~109 stained_glass 0  
fill ~54 ~5 ~12 ~54 ~5 ~13 glowstone 0  
fill ~54 ~5 ~109 ~54 ~5 ~110 glowstone 0  
fill ~55 ~5 ~12 ~59 ~5 ~12 stained_glass 0  
fill ~55 ~5 ~13 ~59 ~5 ~13 stained_glass 0  
fill ~55 ~5 ~109 ~59 ~5 ~109 stained_glass 0  
fill ~55 ~5 ~110 ~59 ~5 ~110 stained_glass 0  
fill ~60 ~5 ~12 ~62 ~5 ~12 stained_glass 11  
fill ~60 ~5 ~13 ~62 ~5 ~13 stained_glass 11  
fill ~60 ~5 ~109 ~62 ~5 ~109 stained_glass 11  
fill ~60 ~5 ~110 ~62 ~5 ~110 stained_glass 11  
fill ~63 ~5 ~12 ~67 ~5 ~12 stained_glass 0  
fill ~63 ~5 ~13 ~67 ~5 ~13 stained_glass 0  
fill ~63 ~5 ~109 ~67 ~5 ~109 stained_glass 0    
fill ~63 ~5 ~110 ~67 ~5 ~110 stained_glass 0  
fill ~68 ~5 ~12 ~68 ~5 ~13 glowstone 0  
fill ~68 ~5 ~109 ~68 ~5 ~110 glowstone 0  
fill ~69 ~5 ~13 ~73 ~5 ~13 stained_glass 0  
fill ~69 ~5 ~109 ~73 ~5 ~109 stained_glass 0  
fill ~74 ~5 ~14 ~76 ~5 ~14 stained_glass 0  
fill ~74 ~5 ~108 ~76 ~5 ~108 stained_glass 0  
fill ~77 ~5 ~15 ~79 ~5 ~15 stained_glass 0  
fill ~77 ~5 ~107 ~79 ~5 ~107 stained_glass 0  
fill ~78 ~5 ~37 ~78 ~5 ~41 stained_glass 0  
fill ~78 ~5 ~42 ~78 ~6 ~42 stained_glass 14  
fill ~79 ~5 ~43 ~79 ~6 ~43 glowstone 0  
fill ~80 ~5 ~16 ~81 ~5 ~16 stained_glass 0  
fill ~80 ~5 ~44 ~80 ~6 ~44 stained_glass 11  
fill ~80 ~5 ~106 ~81 ~5 ~106 stained_glass 0  
fill ~81 ~5 ~44 ~85 ~5 ~44 stained_glass 0  
fill ~82 ~5 ~17 ~83 ~5 ~17 stained_glass 0  
fill ~82 ~5 ~34 ~85 ~5 ~34 stained_glass 0  
fill ~82 ~5 ~105 ~83 ~5 ~105 stained_glass 0  
fill ~84 ~5 ~18 ~85 ~5 ~18 stained_glass 0  
fill ~84 ~5 ~104 ~85 ~5 ~104 stained_glass 0  
fill ~86 ~5 ~19 ~87 ~5 ~19 stained_glass 0  
fill ~86 ~5 ~103 ~87 ~5 ~103 stained_glass 0  
fill ~88 ~5 ~20 ~89 ~5 ~20 stained_glass 0  
fill ~88 ~5 ~37 ~88 ~4 ~37 stained_glass 0  
fill ~88 ~5 ~38 ~88 ~5 ~41 stained_glass 0  
fill ~88 ~5 ~102 ~89 ~5 ~102 stained_glass 0 
setblock ~90 ~5 ~21 stained_glass 0 
setblock ~90 ~5 ~101 stained_glass 0 
setblock ~91 ~5 ~22 stained_glass 0 
setblock ~91 ~5 ~100 stained_glass 0  
fill ~92 ~5 ~23 ~93 ~5 ~23 stained_glass 0  
fill ~92 ~5 ~99 ~93 ~5 ~99 stained_glass 0 
setblock ~94 ~5 ~24 stained_glass 0  
fill ~94 ~5 ~97 ~94 ~5 ~98 stained_glass 0 
setblock ~95 ~5 ~25 stained_glass 11 
setblock ~95 ~5 ~97 stained_glass 11 
setblock ~96 ~5 ~26 glowstone 0 
setblock ~96 ~5 ~96 glowstone 0 
setblock ~97 ~5 ~27 stained_glass 14 
setblock ~97 ~5 ~95 stained_glass 14 
setblock ~98 ~5 ~28 stained_glass 0 
setblock ~98 ~5 ~94 stained_glass 0  
fill ~99 ~5 ~29 ~99 ~5 ~30 stained_glass 0  
fill ~99 ~5 ~92 ~99 ~5 ~93 stained_glass 0 
setblock ~100 ~5 ~31 stained_glass 0 
setblock ~100 ~5 ~91 stained_glass 0 
setblock ~101 ~5 ~32 stained_glass 0 
setblock ~101 ~5 ~90 stained_glass 0  
fill ~102 ~5 ~33 ~102 ~5 ~34 stained_glass 0  
fill ~102 ~5 ~88 ~102 ~5 ~89 stained_glass 0  
fill ~103 ~5 ~35 ~103 ~5 ~36 stained_glass 0  
fill ~103 ~5 ~86 ~103 ~5 ~87 stained_glass 0  
fill ~104 ~5 ~37 ~104 ~5 ~38 stained_glass 0  
fill ~104 ~5 ~84 ~104 ~5 ~85 stained_glass 0  
fill ~105 ~5 ~39 ~105 ~5 ~40 stained_glass 0  
fill ~105 ~5 ~82 ~105 ~5 ~83 stained_glass 0  
fill ~106 ~5 ~41 ~106 ~5 ~42 stained_glass 0  
fill ~106 ~5 ~80 ~106 ~5 ~81 stained_glass 0  
fill ~107 ~5 ~43 ~107 ~5 ~45 stained_glass 0  
fill ~107 ~5 ~77 ~107 ~5 ~79 stained_glass 0  
fill ~108 ~5 ~46 ~108 ~5 ~48 stained_glass 0  
fill ~108 ~5 ~74 ~108 ~5 ~76 stained_glass 0  
fill ~109 ~5 ~49 ~109 ~5 ~53 stained_glass 0  
fill ~109 ~5 ~54 ~110 ~5 ~54 glowstone 0  
fill ~109 ~5 ~55 ~110 ~5 ~55 stained_glass 0  
fill ~109 ~5 ~56 ~110 ~5 ~56 stained_glass 0  
fill ~109 ~5 ~57 ~110 ~5 ~57 stained_glass 0  
fill ~109 ~5 ~58 ~110 ~5 ~58 stained_glass 0  
fill ~109 ~5 ~59 ~110 ~5 ~59 stained_glass 0  
fill ~109 ~5 ~60 ~110 ~5 ~60 stained_glass 14  
fill ~109 ~5 ~61 ~110 ~5 ~61 stained_glass 14  
fill ~109 ~5 ~62 ~110 ~5 ~62 stained_glass 14  
fill ~109 ~5 ~63 ~110 ~5 ~63 stained_glass 0  
fill ~109 ~5 ~64 ~110 ~5 ~64 stained_glass 0  
fill ~109 ~5 ~65 ~110 ~5 ~65 stained_glass 0  
fill ~109 ~5 ~66 ~110 ~5 ~66 stained_glass 0  
fill ~109 ~5 ~67 ~110 ~5 ~67 stained_glass 0  
fill ~109 ~5 ~68 ~110 ~5 ~68 glowstone 0  
fill ~109 ~5 ~69 ~109 ~5 ~73 stained_glass 0  
fill ~14 ~6 ~49 ~15 ~6 ~49 stained_glass 0  
fill ~14 ~6 ~50 ~15 ~6 ~50 stained_glass 0  
fill ~14 ~6 ~51 ~15 ~6 ~51 stained_glass 0  
fill ~14 ~6 ~52 ~15 ~6 ~52 stained_glass 0  
fill ~14 ~6 ~53 ~15 ~6 ~53 stained_glass 0  
fill ~14 ~6 ~54 ~15 ~6 ~54 glowstone 0  
fill ~14 ~6 ~55 ~15 ~6 ~55 stained_glass 0  
fill ~14 ~6 ~56 ~15 ~6 ~56 stained_glass 0  
fill ~14 ~6 ~57 ~15 ~6 ~57 stained_glass 0  
fill ~14 ~6 ~58 ~15 ~6 ~58 stained_glass 0  
fill ~14 ~6 ~59 ~15 ~6 ~59 stained_glass 0  
fill ~14 ~6 ~60 ~15 ~6 ~60 stained_glass 14  
fill ~14 ~6 ~61 ~15 ~6 ~61 stained_glass 14  
fill ~14 ~6 ~62 ~15 ~6 ~62 stained_glass 14  
fill ~14 ~6 ~63 ~15 ~6 ~63 stained_glass 0  
fill ~14 ~6 ~64 ~15 ~6 ~64 stained_glass 0  
fill ~14 ~6 ~65 ~15 ~6 ~65 stained_glass 0  
fill ~14 ~6 ~66 ~15 ~6 ~66 stained_glass 0  
fill ~14 ~6 ~67 ~15 ~6 ~67 stained_glass 0  
fill ~14 ~6 ~68 ~15 ~6 ~68 glowstone 0  
fill ~14 ~6 ~69 ~15 ~6 ~69 stained_glass 0  
fill ~14 ~6 ~70 ~15 ~6 ~70 stained_glass 0  
fill ~14 ~6 ~71 ~15 ~6 ~71 stained_glass 0  
fill ~14 ~6 ~72 ~15 ~6 ~72 stained_glass 0  
fill ~14 ~6 ~73 ~15 ~6 ~73 stained_glass 0  
fill ~15 ~6 ~46 ~16 ~6 ~46 stained_glass 0  
fill ~15 ~6 ~47 ~16 ~6 ~47 stained_glass 0  
fill ~15 ~6 ~48 ~16 ~6 ~48 stained_glass 0  
fill ~15 ~6 ~74 ~16 ~6 ~74 stained_glass 0  
fill ~15 ~6 ~75 ~16 ~6 ~75 stained_glass 0  
fill ~15 ~6 ~76 ~16 ~6 ~76 stained_glass 0  
fill ~16 ~6 ~43 ~17 ~6 ~43 stained_glass 0  
fill ~16 ~6 ~44 ~17 ~6 ~44 stained_glass 0  
fill ~16 ~6 ~45 ~17 ~6 ~45 stained_glass 0  
fill ~16 ~6 ~77 ~17 ~6 ~77 stained_glass 0  
fill ~16 ~6 ~78 ~17 ~6 ~78 stained_glass 0  
fill ~16 ~6 ~79 ~17 ~6 ~79 stained_glass 0  
fill ~17 ~6 ~41 ~18 ~6 ~41 stained_glass 0  
fill ~17 ~6 ~42 ~18 ~6 ~42 stained_glass 0  
fill ~17 ~6 ~80 ~18 ~6 ~80 stained_glass 0  
fill ~17 ~6 ~81 ~18 ~6 ~81 stained_glass 0  
fill ~18 ~6 ~39 ~19 ~6 ~39 stained_glass 0  
fill ~18 ~6 ~40 ~19 ~6 ~40 stained_glass 0  
fill ~18 ~6 ~82 ~19 ~6 ~82 stained_glass 0  
fill ~18 ~6 ~83 ~19 ~6 ~83 stained_glass 0  
fill ~19 ~6 ~37 ~20 ~6 ~37 stained_glass 0  
fill ~19 ~6 ~38 ~20 ~6 ~38 stained_glass 0  
fill ~19 ~6 ~84 ~20 ~6 ~84 stained_glass 0  
fill ~19 ~6 ~85 ~20 ~6 ~85 stained_glass 0  
fill ~20 ~6 ~35 ~21 ~6 ~35 stained_glass 0  
fill ~20 ~6 ~36 ~21 ~6 ~36 stained_glass 0  
fill ~20 ~6 ~86 ~21 ~6 ~86 stained_glass 0  
fill ~20 ~6 ~87 ~21 ~6 ~87 stained_glass 0  
fill ~21 ~6 ~33 ~22 ~6 ~33 stained_glass 0  
fill ~21 ~6 ~34 ~22 ~6 ~34 stained_glass 0  
fill ~21 ~6 ~88 ~22 ~6 ~88 stained_glass 0  
fill ~21 ~6 ~89 ~22 ~6 ~89 stained_glass 0  
fill ~22 ~6 ~32 ~23 ~6 ~32 stained_glass 0  
fill ~22 ~6 ~90 ~23 ~6 ~90 stained_glass 0  
fill ~23 ~6 ~31 ~24 ~6 ~31 stained_glass 0  
fill ~23 ~6 ~91 ~24 ~6 ~91 stained_glass 0  
fill ~24 ~6 ~29 ~26 ~6 ~29 stained_glass 0  
fill ~24 ~6 ~30 ~25 ~6 ~30 stained_glass 0  
fill ~24 ~6 ~92 ~25 ~6 ~92 stained_glass 0  
fill ~24 ~6 ~93 ~26 ~6 ~93 stained_glass 0 
setblock ~25 ~6 ~28 stained_glass 0 
setblock ~25 ~6 ~94 stained_glass 0 
setblock ~26 ~6 ~28 stained_glass 14 
setblock ~26 ~6 ~94 stained_glass 14 
setblock ~27 ~6 ~27 glowstone 0 
setblock ~27 ~6 ~95 glowstone 0 
setblock ~28 ~6 ~26 stained_glass 11 
setblock ~28 ~6 ~96 stained_glass 11  
fill ~28 ~6 ~97 ~30 ~6 ~97 stained_glass 0  
fill ~29 ~6 ~24 ~31 ~6 ~24 stained_glass 0  
fill ~29 ~6 ~25 ~30 ~6 ~25 stained_glass 0  
fill ~29 ~6 ~26 ~29 ~6 ~24 stained_glass 0  
fill ~29 ~6 ~98 ~31 ~6 ~98 stained_glass 0  
fill ~31 ~6 ~23 ~32 ~6 ~23 stained_glass 0  
fill ~31 ~6 ~99 ~32 ~6 ~99 stained_glass 0  
fill ~32 ~6 ~22 ~34 ~6 ~22 stained_glass 0  
fill ~32 ~6 ~100 ~34 ~6 ~100 stained_glass 0  
fill ~33 ~6 ~21 ~36 ~6 ~21 stained_glass 0  
fill ~33 ~6 ~101 ~36 ~6 ~101 stained_glass 0  
fill ~35 ~6 ~20 ~38 ~6 ~20 stained_glass 0 
setblock ~35 ~6 ~81 stained_glass 14  
fill ~35 ~6 ~82 ~35 ~6 ~84 stained_glass 0 
setblock ~35 ~6 ~85 stained_glass 14  
fill ~35 ~6 ~102 ~38 ~6 ~102 stained_glass 0 
setblock ~36 ~6 ~80 glowstone 0 
setblock ~36 ~6 ~82 stained_glass 14 
setblock ~36 ~6 ~83 stained_glass 0 
setblock ~36 ~6 ~84 stained_glass 14 
setblock ~36 ~6 ~86 glowstone 0  
fill ~37 ~6 ~19 ~40 ~6 ~19 stained_glass 0 
setblock ~37 ~6 ~79 stained_glass 11 
setblock ~37 ~6 ~81 glowstone 0 
setblock ~37 ~6 ~85 glowstone 0 
setblock ~37 ~6 ~87 stained_glass 11  
fill ~37 ~6 ~103 ~40 ~6 ~103 stained_glass 0  
fill ~38 ~6 ~79 ~40 ~6 ~79 stained_glass 0 
setblock ~38 ~6 ~80 stained_glass 11 
setblock ~38 ~6 ~86 stained_glass 11  
fill ~38 ~6 ~87 ~40 ~6 ~87 stained_glass 0  
fill ~39 ~6 ~18 ~42 ~6 ~18 stained_glass 0 
setblock ~39 ~6 ~80 stained_glass 0 
setblock ~39 ~6 ~86 stained_glass 0  
fill ~39 ~6 ~104 ~42 ~6 ~104 stained_glass 0 
setblock ~40 ~6 ~80 stained_glass 11 
setblock ~40 ~6 ~86 stained_glass 11  
fill ~41 ~6 ~17 ~45 ~6 ~17 stained_glass 0 
setblock ~41 ~6 ~79 stained_glass 11 
setblock ~41 ~6 ~81 glowstone 0 
setblock ~41 ~6 ~85 glowstone 0 
setblock ~41 ~6 ~87 stained_glass 11  
fill ~41 ~6 ~105 ~45 ~6 ~105 stained_glass 0 
setblock ~42 ~6 ~80 glowstone 0 
setblock ~42 ~6 ~82 stained_glass 14  
fill ~42 ~6 ~83 ~43 ~6 ~83 stained_glass 0 
setblock ~42 ~6 ~84 stained_glass 14 
setblock ~42 ~6 ~86 glowstone 0  
fill ~43 ~6 ~16 ~48 ~6 ~16 stained_glass 0 
setblock ~43 ~6 ~81 stained_glass 14 
setblock ~43 ~6 ~82 stained_glass 0 
setblock ~43 ~6 ~84 stained_glass 0 
setblock ~43 ~6 ~85 stained_glass 14  
fill ~43 ~6 ~106 ~48 ~6 ~106 stained_glass 0  
fill ~46 ~6 ~15 ~53 ~6 ~15 stained_glass 0  
fill ~46 ~6 ~107 ~53 ~6 ~107 stained_glass 0  
fill ~49 ~6 ~14 ~53 ~6 ~14 stained_glass 0  
fill ~49 ~6 ~108 ~53 ~6 ~108 stained_glass 0  
fill ~54 ~6 ~14 ~54 ~6 ~15 glowstone 0  
fill ~54 ~6 ~107 ~54 ~6 ~108 glowstone 0  
fill ~55 ~6 ~14 ~59 ~6 ~14 stained_glass 0  
fill ~55 ~6 ~15 ~59 ~6 ~15 stained_glass 0  
fill ~55 ~6 ~107 ~59 ~6 ~107 stained_glass 0  
fill ~55 ~6 ~108 ~59 ~6 ~108 stained_glass 0  
fill ~60 ~6 ~14 ~62 ~6 ~14 stained_glass 11  
fill ~60 ~6 ~15 ~62 ~6 ~15 stained_glass 11  
fill ~60 ~6 ~107 ~62 ~6 ~107 stained_glass 11  
fill ~60 ~6 ~108 ~62 ~6 ~108 stained_glass 11  
fill ~63 ~6 ~14 ~67 ~6 ~14 stained_glass 0  
fill ~63 ~6 ~15 ~67 ~6 ~15 stained_glass 0  
fill ~63 ~6 ~107 ~67 ~6 ~107 stained_glass 0  
fill ~63 ~6 ~108 ~67 ~6 ~108 stained_glass 0  
fill ~68 ~6 ~14 ~68 ~6 ~15 glowstone 0  
fill ~68 ~6 ~107 ~68 ~6 ~108 glowstone 0  
fill ~69 ~6 ~14 ~73 ~6 ~14 stained_glass 0  
fill ~69 ~6 ~15 ~76 ~6 ~15 stained_glass 0  
fill ~69 ~6 ~107 ~76 ~6 ~107 stained_glass 0  
fill ~69 ~6 ~108 ~73 ~6 ~108 stained_glass 0  
fill ~74 ~6 ~16 ~79 ~6 ~16 stained_glass 0  
fill ~74 ~6 ~106 ~79 ~6 ~106 stained_glass 0  
fill ~77 ~6 ~17 ~81 ~6 ~17 stained_glass 0  
fill ~77 ~6 ~105 ~81 ~6 ~105 stained_glass 0 
setblock ~79 ~6 ~37 stained_glass 14  
fill ~79 ~6 ~38 ~79 ~6 ~40 stained_glass 0 
setblock ~79 ~6 ~41 stained_glass 14  
fill ~80 ~6 ~18 ~83 ~6 ~18 stained_glass 0 
setblock ~80 ~6 ~36 glowstone 0 
setblock ~80 ~6 ~38 stained_glass 14 
setblock ~80 ~6 ~39 stained_glass 0 
setblock ~80 ~6 ~40 stained_glass 14 
setblock ~80 ~6 ~42 glowstone 0  
fill ~80 ~6 ~104 ~83 ~6 ~104 stained_glass 0 
setblock ~81 ~6 ~35 stained_glass 11 
setblock ~81 ~6 ~37 glowstone 0 
setblock ~81 ~6 ~41 glowstone 0 
setblock ~81 ~6 ~43 stained_glass 11  
fill ~82 ~6 ~19 ~85 ~6 ~19 stained_glass 0  
fill ~82 ~6 ~35 ~84 ~6 ~35 stained_glass 0 
setblock ~82 ~6 ~36 stained_glass 11 
setblock ~82 ~6 ~42 stained_glass 11  
fill ~82 ~6 ~43 ~84 ~6 ~43 stained_glass 0  
fill ~82 ~6 ~103 ~85 ~6 ~103 stained_glass 0 
setblock ~83 ~6 ~36 stained_glass 0 
setblock ~83 ~6 ~42 stained_glass 0  
fill ~84 ~6 ~20 ~87 ~6 ~20 stained_glass 0 
setblock ~84 ~6 ~36 stained_glass 11 
setblock ~84 ~6 ~42 stained_glass 11  
fill ~84 ~6 ~102 ~87 ~6 ~102 stained_glass 0 
setblock ~85 ~6 ~35 stained_glass 11 
setblock ~85 ~6 ~37 glowstone 0 
setblock ~85 ~6 ~41 glowstone 0 
setblock ~85 ~6 ~43 stained_glass 11  
fill ~86 ~6 ~21 ~89 ~6 ~21 stained_glass 0 
setblock ~86 ~6 ~36 glowstone 0 
setblock ~86 ~6 ~38 stained_glass 14  
fill ~86 ~6 ~39 ~87 ~6 ~39 stained_glass 0 
setblock ~86 ~6 ~40 stained_glass 14 
setblock ~86 ~6 ~42 glowstone 0  
fill ~86 ~6 ~101 ~89 ~6 ~101 stained_glass 0 
setblock ~87 ~6 ~37 stained_glass 14 
setblock ~87 ~6 ~38 stained_glass 0 
setblock ~87 ~6 ~40 stained_glass 0 
setblock ~87 ~6 ~41 stained_glass 14  
fill ~88 ~6 ~22 ~90 ~6 ~22 stained_glass 0  
fill ~88 ~6 ~100 ~90 ~6 ~100 stained_glass 0  
fill ~90 ~6 ~23 ~91 ~6 ~23 stained_glass 0  
fill ~90 ~6 ~99 ~91 ~6 ~99 stained_glass 0  
fill ~91 ~6 ~24 ~93 ~6 ~24 stained_glass 0  
fill ~91 ~6 ~98 ~93 ~6 ~98 stained_glass 0  
fill ~92 ~6 ~25 ~94 ~6 ~25 stained_glass 0  
fill ~92 ~6 ~97 ~93 ~6 ~97 stained_glass 0 
setblock ~93 ~6 ~96 stained_glass 0 
setblock ~94 ~6 ~26 stained_glass 11 
setblock ~94 ~6 ~96 stained_glass 11 
setblock ~95 ~6 ~27 glowstone 0 
setblock ~95 ~6 ~95 glowstone 0 
setblock ~96 ~6 ~28 stained_glass 14  
fill ~96 ~6 ~29 ~98 ~6 ~29 stained_glass 0  
fill ~96 ~6 ~93 ~98 ~6 ~93 stained_glass 0 
setblock ~96 ~6 ~94 stained_glass 14 
setblock ~97 ~6 ~28 stained_glass 0  
fill ~97 ~6 ~30 ~98 ~6 ~30 stained_glass 0  
fill ~97 ~6 ~92 ~98 ~6 ~92 stained_glass 0 
setblock ~97 ~6 ~94 stained_glass 0  
fill ~98 ~6 ~31 ~99 ~6 ~31 stained_glass 0  
fill ~98 ~6 ~91 ~99 ~6 ~91 stained_glass 0  
fill ~99 ~6 ~32 ~100 ~6 ~32 stained_glass 0  
fill ~99 ~6 ~90 ~100 ~6 ~90 stained_glass 0  
fill ~100 ~6 ~33 ~101 ~6 ~33 stained_glass 0  
fill ~100 ~6 ~34 ~101 ~6 ~34 stained_glass 0  
fill ~100 ~6 ~88 ~101 ~6 ~88 stained_glass 0  
fill ~100 ~6 ~89 ~101 ~6 ~89 stained_glass 0  
fill ~101 ~6 ~35 ~102 ~6 ~35 stained_glass 0  
fill ~101 ~6 ~36 ~102 ~6 ~36 stained_glass 0  
fill ~101 ~6 ~86 ~102 ~6 ~86 stained_glass 0  
fill ~101 ~6 ~87 ~102 ~6 ~87 stained_glass 0  
fill ~102 ~6 ~37 ~103 ~6 ~37 stained_glass 0  
fill ~102 ~6 ~38 ~103 ~6 ~38 stained_glass 0  
fill ~102 ~6 ~84 ~103 ~6 ~84 stained_glass 0  
fill ~102 ~6 ~85 ~103 ~6 ~85 stained_glass 0  
fill ~103 ~6 ~39 ~104 ~6 ~39 stained_glass 0  
fill ~103 ~6 ~40 ~104 ~6 ~40 stained_glass 0  
fill ~103 ~6 ~82 ~104 ~6 ~82 stained_glass 0  
fill ~103 ~6 ~83 ~104 ~6 ~83 stained_glass 0  
fill ~104 ~6 ~41 ~105 ~6 ~41 stained_glass 0  
fill ~104 ~6 ~42 ~105 ~6 ~42 stained_glass 0  
fill ~104 ~6 ~80 ~105 ~6 ~80 stained_glass 0  
fill ~104 ~6 ~81 ~105 ~6 ~81 stained_glass 0  
fill ~105 ~6 ~43 ~106 ~6 ~43 stained_glass 0  
fill ~105 ~6 ~44 ~106 ~6 ~44 stained_glass 0  
fill ~105 ~6 ~45 ~106 ~6 ~45 stained_glass 0  
fill ~105 ~6 ~77 ~106 ~6 ~77 stained_glass 0  
fill ~105 ~6 ~78 ~106 ~6 ~78 stained_glass 0  
fill ~105 ~6 ~79 ~106 ~6 ~79 stained_glass 0  
fill ~106 ~6 ~46 ~107 ~6 ~46 stained_glass 0  
fill ~106 ~6 ~47 ~107 ~6 ~47 stained_glass 0  
fill ~106 ~6 ~48 ~107 ~6 ~48 stained_glass 0  
fill ~106 ~6 ~74 ~107 ~6 ~74 stained_glass 0  
fill ~106 ~6 ~75 ~107 ~6 ~75 stained_glass 0  
fill ~106 ~6 ~76 ~107 ~6 ~76 stained_glass 0  
fill ~107 ~6 ~49 ~108 ~6 ~49 stained_glass 0  
fill ~107 ~6 ~50 ~108 ~6 ~50 stained_glass 0  
fill ~107 ~6 ~51 ~108 ~6 ~51 stained_glass 0  
fill ~107 ~6 ~52 ~108 ~6 ~52 stained_glass 0  
fill ~107 ~6 ~53 ~108 ~6 ~53 stained_glass 0  
fill ~107 ~6 ~54 ~108 ~6 ~54 glowstone 0  
fill ~107 ~6 ~55 ~108 ~6 ~55 stained_glass 0  
fill ~107 ~6 ~56 ~108 ~6 ~56 stained_glass 0  
fill ~107 ~6 ~57 ~108 ~6 ~57 stained_glass 0  
fill ~107 ~6 ~58 ~108 ~6 ~58 stained_glass 0  
fill ~107 ~6 ~59 ~108 ~6 ~59 stained_glass 0  
fill ~107 ~6 ~60 ~108 ~6 ~60 stained_glass 14  
fill ~107 ~6 ~61 ~108 ~6 ~61 stained_glass 14  
fill ~107 ~6 ~62 ~108 ~6 ~62 stained_glass 14  
fill ~107 ~6 ~63 ~108 ~6 ~63 stained_glass 0  
fill ~107 ~6 ~64 ~108 ~6 ~64 stained_glass 0  
fill ~107 ~6 ~65 ~108 ~6 ~65 stained_glass 0  
fill ~107 ~6 ~66 ~108 ~6 ~66 stained_glass 0  
fill ~107 ~6 ~67 ~108 ~6 ~67 stained_glass 0  
fill ~107 ~6 ~68 ~108 ~6 ~68 glowstone 0  
fill ~107 ~6 ~69 ~108 ~6 ~69 stained_glass 0  
fill ~107 ~6 ~70 ~108 ~6 ~70 stained_glass 0  
fill ~107 ~6 ~71 ~108 ~6 ~71 stained_glass 0  
fill ~107 ~6 ~72 ~108 ~6 ~72 stained_glass 0  
fill ~107 ~6 ~73 ~108 ~6 ~73 stained_glass 0  
fill ~16 ~7 ~49 ~17 ~7 ~49 stained_glass 0  
fill ~16 ~7 ~50 ~17 ~7 ~50 stained_glass 0  
fill ~16 ~7 ~51 ~17 ~7 ~51 stained_glass 0  
fill ~16 ~7 ~52 ~17 ~7 ~52 stained_glass 0  
fill ~16 ~7 ~53 ~17 ~7 ~53 stained_glass 0  
fill ~16 ~7 ~54 ~17 ~7 ~54 glowstone 0  
fill ~16 ~7 ~55 ~17 ~7 ~55 stained_glass 0  
fill ~16 ~7 ~56 ~17 ~7 ~56 stained_glass 0  
fill ~16 ~7 ~57 ~17 ~7 ~57 stained_glass 0  
fill ~16 ~7 ~58 ~17 ~7 ~58 stained_glass 0  
fill ~16 ~7 ~59 ~17 ~7 ~59 stained_glass 0  
fill ~16 ~7 ~60 ~17 ~7 ~60 stained_glass 14  
fill ~16 ~7 ~61 ~17 ~7 ~61 stained_glass 14  
fill ~16 ~7 ~62 ~17 ~7 ~62 stained_glass 14  
fill ~16 ~7 ~63 ~17 ~7 ~63 stained_glass 0  
fill ~16 ~7 ~64 ~17 ~7 ~64 stained_glass 0  
fill ~16 ~7 ~65 ~17 ~7 ~65 stained_glass 0  
fill ~16 ~7 ~66 ~17 ~7 ~66 stained_glass 0  
fill ~16 ~7 ~67 ~17 ~7 ~67 stained_glass 0  
fill ~16 ~7 ~68 ~17 ~7 ~68 glowstone 0  
fill ~16 ~7 ~69 ~17 ~7 ~69 stained_glass 0  
fill ~16 ~7 ~70 ~17 ~7 ~70 stained_glass 0  
fill ~16 ~7 ~71 ~17 ~7 ~71 stained_glass 0  
fill ~16 ~7 ~72 ~17 ~7 ~72 stained_glass 0  
fill ~16 ~7 ~73 ~17 ~7 ~73 stained_glass 0  
fill ~17 ~7 ~46 ~18 ~7 ~46 stained_glass 0  
fill ~17 ~7 ~47 ~18 ~7 ~47 stained_glass 0  
fill ~17 ~7 ~48 ~18 ~7 ~48 stained_glass 0  
fill ~17 ~7 ~74 ~18 ~7 ~74 stained_glass 0  
fill ~17 ~7 ~75 ~18 ~7 ~75 stained_glass 0  
fill ~17 ~7 ~76 ~18 ~7 ~76 stained_glass 0  
fill ~18 ~7 ~43 ~19 ~7 ~43 stained_glass 0  
fill ~18 ~7 ~44 ~19 ~7 ~44 stained_glass 0  
fill ~18 ~7 ~45 ~19 ~7 ~45 stained_glass 0  
fill ~18 ~7 ~77 ~19 ~7 ~77 stained_glass 0  
fill ~18 ~7 ~78 ~19 ~7 ~78 stained_glass 0  
fill ~18 ~7 ~79 ~19 ~7 ~79 stained_glass 0  
fill ~19 ~7 ~41 ~20 ~7 ~41 stained_glass 0  
fill ~19 ~7 ~42 ~20 ~7 ~42 stained_glass 0  
fill ~19 ~7 ~80 ~20 ~7 ~80 stained_glass 0  
fill ~19 ~7 ~81 ~20 ~7 ~81 stained_glass 0  
fill ~20 ~7 ~39 ~21 ~7 ~39 stained_glass 0  
fill ~20 ~7 ~40 ~21 ~7 ~40 stained_glass 0  
fill ~20 ~7 ~82 ~21 ~7 ~82 stained_glass 0  
fill ~20 ~7 ~83 ~21 ~7 ~83 stained_glass 0  
fill ~21 ~7 ~37 ~22 ~7 ~37 stained_glass 0  
fill ~21 ~7 ~38 ~22 ~7 ~38 stained_glass 0  
fill ~21 ~7 ~84 ~22 ~7 ~84 stained_glass 0  
fill ~21 ~7 ~85 ~22 ~7 ~85 stained_glass 0  
fill ~22 ~7 ~35 ~23 ~7 ~35 stained_glass 0  
fill ~22 ~7 ~36 ~23 ~7 ~36 stained_glass 0  
fill ~22 ~7 ~86 ~23 ~7 ~86 stained_glass 0  
fill ~22 ~7 ~87 ~23 ~7 ~87 stained_glass 0  
fill ~23 ~7 ~33 ~24 ~7 ~33 stained_glass 0  
fill ~23 ~7 ~34 ~24 ~7 ~34 stained_glass 0  
fill ~23 ~7 ~88 ~24 ~7 ~88 stained_glass 0  
fill ~23 ~7 ~89 ~24 ~7 ~89 stained_glass 0  
fill ~24 ~7 ~32 ~25 ~7 ~32 stained_glass 0  
fill ~24 ~7 ~90 ~25 ~7 ~90 stained_glass 0  
fill ~25 ~7 ~31 ~26 ~7 ~31 stained_glass 0  
fill ~25 ~7 ~91 ~26 ~7 ~91 stained_glass 0  
fill ~26 ~7 ~30 ~27 ~7 ~30 stained_glass 0  
fill ~26 ~7 ~92 ~27 ~7 ~92 stained_glass 0 
setblock ~27 ~7 ~29 stained_glass 14 
setblock ~27 ~7 ~93 stained_glass 14 
setblock ~28 ~7 ~28 glowstone 0 
setblock ~28 ~7 ~30 stained_glass 14 
setblock ~28 ~7 ~92 stained_glass 14 
setblock ~28 ~7 ~94 glowstone 0 
setblock ~29 ~7 ~27 stained_glass 11 
setblock ~29 ~7 ~29 glowstone 0 
setblock ~29 ~7 ~93 glowstone 0 
setblock ~29 ~7 ~95 stained_glass 11  
fill ~29 ~7 ~96 ~31 ~7 ~96 stained_glass 0  
fill ~30 ~7 ~26 ~31 ~7 ~26 stained_glass 0  
fill ~30 ~7 ~27 ~31 ~7 ~27 stained_glass 0 
setblock ~30 ~7 ~28 stained_glass 11 
setblock ~30 ~7 ~94 stained_glass 11 
setblock ~30 ~7 ~95 stained_glass 0  
fill ~31 ~7 ~25 ~32 ~7 ~25 stained_glass 0  
fill ~31 ~7 ~97 ~32 ~7 ~97 stained_glass 0  
fill ~32 ~7 ~24 ~34 ~7 ~24 stained_glass 0  
fill ~32 ~7 ~98 ~34 ~7 ~98 stained_glass 0  
fill ~33 ~7 ~23 ~36 ~7 ~23 stained_glass 0  
fill ~33 ~7 ~99 ~36 ~7 ~99 stained_glass 0  
fill ~35 ~7 ~22 ~38 ~7 ~22 stained_glass 0  
fill ~35 ~7 ~100 ~38 ~7 ~100 stained_glass 0  
fill ~37 ~7 ~21 ~40 ~7 ~21 stained_glass 0 
setblock ~37 ~7 ~83 stained_glass 14  
fill ~37 ~7 ~101 ~40 ~7 ~101 stained_glass 0 
setblock ~38 ~7 ~82 glowstone 0 
setblock ~38 ~7 ~84 glowstone 0  
fill ~39 ~7 ~20 ~42 ~7 ~20 stained_glass 0 
setblock ~39 ~7 ~81 stained_glass 11 
setblock ~39 ~7 ~83 glowstone 0 
setblock ~39 ~7 ~85 stained_glass 11  
fill ~39 ~7 ~102 ~42 ~7 ~102 stained_glass 0 
setblock ~40 ~7 ~82 glowstone 0 
setblock ~40 ~7 ~84 glowstone 0  
fill ~41 ~7 ~19 ~45 ~7 ~19 stained_glass 0 
setblock ~41 ~7 ~83 stained_glass 14  
fill ~41 ~7 ~103 ~45 ~7 ~103 stained_glass 0  
fill ~43 ~7 ~18 ~48 ~7 ~18 stained_glass 0  
fill ~43 ~7 ~104 ~48 ~7 ~104 stained_glass 0  
fill ~46 ~7 ~17 ~53 ~7 ~17 stained_glass 0  
fill ~46 ~7 ~105 ~53 ~7 ~105 stained_glass 0  
fill ~49 ~7 ~16 ~53 ~7 ~16 stained_glass 0  
fill ~49 ~7 ~106 ~53 ~7 ~106 stained_glass 0  
fill ~54 ~7 ~16 ~54 ~7 ~17 glowstone 0  
fill ~54 ~7 ~105 ~54 ~7 ~106 glowstone 0  
fill ~55 ~7 ~16 ~59 ~7 ~16 stained_glass 0  
fill ~55 ~7 ~17 ~59 ~7 ~17 stained_glass 0  
fill ~55 ~7 ~105 ~59 ~7 ~105 stained_glass 0  
fill ~55 ~7 ~106 ~59 ~7 ~106 stained_glass 0  
fill ~60 ~7 ~16 ~62 ~7 ~16 stained_glass 11  
fill ~60 ~7 ~17 ~62 ~7 ~17 stained_glass 11  
fill ~60 ~7 ~105 ~62 ~7 ~105 stained_glass 11  
fill ~60 ~7 ~106 ~62 ~7 ~106 stained_glass 11  
fill ~63 ~7 ~16 ~67 ~7 ~16 stained_glass 0  
fill ~63 ~7 ~17 ~67 ~7 ~17 stained_glass 0  
fill ~63 ~7 ~105 ~67 ~7 ~105 stained_glass 0  
fill ~63 ~7 ~106 ~67 ~7 ~106 stained_glass 0  
fill ~68 ~7 ~16 ~68 ~7 ~17 glowstone 0  
fill ~68 ~7 ~105 ~68 ~7 ~106 glowstone 0  
fill ~69 ~7 ~16 ~73 ~7 ~16 stained_glass 0  
fill ~69 ~7 ~17 ~76 ~7 ~17 stained_glass 0  
fill ~69 ~7 ~105 ~76 ~7 ~105 stained_glass 0  
fill ~69 ~7 ~106 ~73 ~7 ~106 stained_glass 0  
fill ~74 ~7 ~18 ~79 ~7 ~18 stained_glass 0  
fill ~74 ~7 ~104 ~79 ~7 ~104 stained_glass 0  
fill ~77 ~7 ~19 ~81 ~7 ~19 stained_glass 0  
fill ~77 ~7 ~103 ~81 ~7 ~103 stained_glass 0  
fill ~80 ~7 ~20 ~83 ~7 ~20 stained_glass 0  
fill ~80 ~7 ~102 ~83 ~7 ~102 stained_glass 0 
setblock ~81 ~7 ~39 stained_glass 14  
fill ~82 ~7 ~21 ~85 ~7 ~21 stained_glass 0 
setblock ~82 ~7 ~38 glowstone 0 
setblock ~82 ~7 ~40 glowstone 0  
fill ~82 ~7 ~101 ~85 ~7 ~101 stained_glass 0 
setblock ~83 ~7 ~37 stained_glass 11 
setblock ~83 ~7 ~39 glowstone 0 
setblock ~83 ~7 ~41 stained_glass 11  
fill ~84 ~7 ~22 ~87 ~7 ~22 stained_glass 0 
setblock ~84 ~7 ~38 glowstone 0 
setblock ~84 ~7 ~40 glowstone 0  
fill ~84 ~7 ~100 ~87 ~7 ~100 stained_glass 0 
setblock ~85 ~7 ~39 stained_glass 14  
fill ~86 ~7 ~23 ~89 ~7 ~23 stained_glass 0  
fill ~86 ~7 ~99 ~89 ~7 ~99 stained_glass 0  
fill ~88 ~7 ~24 ~90 ~7 ~24 stained_glass 0  
fill ~88 ~7 ~98 ~90 ~7 ~98 stained_glass 0  
fill ~90 ~7 ~25 ~91 ~7 ~25 stained_glass 0  
fill ~90 ~7 ~97 ~91 ~7 ~97 stained_glass 0  
fill ~91 ~7 ~26 ~93 ~7 ~26 stained_glass 0  
fill ~91 ~7 ~95 ~92 ~7 ~95 stained_glass 0  
fill ~91 ~7 ~96 ~92 ~7 ~96 stained_glass 0 
setblock ~92 ~7 ~27 stained_glass 0 
setblock ~92 ~7 ~28 stained_glass 11 
setblock ~92 ~7 ~94 stained_glass 11 
setblock ~93 ~7 ~27 stained_glass 11 
setblock ~93 ~7 ~29 glowstone 0 
setblock ~93 ~7 ~93 glowstone 0 
setblock ~93 ~7 ~95 stained_glass 11 
setblock ~94 ~7 ~28 glowstone 0 
setblock ~94 ~7 ~30 stained_glass 14 
setblock ~94 ~7 ~92 stained_glass 14 
setblock ~94 ~7 ~94 glowstone 0 
setblock ~95 ~7 ~29 stained_glass 14  
fill ~95 ~7 ~30 ~96 ~7 ~30 stained_glass 0  
fill ~95 ~7 ~92 ~96 ~7 ~92 stained_glass 0 
setblock ~95 ~7 ~93 stained_glass 14  
fill ~96 ~7 ~31 ~97 ~7 ~31 stained_glass 0  
fill ~96 ~7 ~91 ~97 ~7 ~91 stained_glass 0  
fill ~97 ~7 ~32 ~98 ~7 ~32 stained_glass 0  
fill ~97 ~7 ~90 ~98 ~7 ~90 stained_glass 0  
fill ~98 ~7 ~33 ~99 ~7 ~33 stained_glass 0  
fill ~98 ~7 ~34 ~99 ~7 ~34 stained_glass 0  
fill ~98 ~7 ~88 ~99 ~7 ~88 stained_glass 0  
fill ~98 ~7 ~89 ~99 ~7 ~89 stained_glass 0  
fill ~99 ~7 ~35 ~100 ~7 ~35 stained_glass 0  
fill ~99 ~7 ~36 ~100 ~7 ~36 stained_glass 0  
fill ~99 ~7 ~86 ~100 ~7 ~86 stained_glass 0  
fill ~99 ~7 ~87 ~100 ~7 ~87 stained_glass 0  
fill ~100 ~7 ~37 ~101 ~7 ~37 stained_glass 0  
fill ~100 ~7 ~38 ~101 ~7 ~38 stained_glass 0  
fill ~100 ~7 ~84 ~101 ~7 ~84 stained_glass 0  
fill ~100 ~7 ~85 ~101 ~7 ~85 stained_glass 0  
fill ~101 ~7 ~39 ~102 ~7 ~39 stained_glass 0  
fill ~101 ~7 ~40 ~102 ~7 ~40 stained_glass 0  
fill ~101 ~7 ~82 ~102 ~7 ~82 stained_glass 0  
fill ~101 ~7 ~83 ~102 ~7 ~83 stained_glass 0  
fill ~102 ~7 ~41 ~103 ~7 ~41 stained_glass 0  
fill ~102 ~7 ~42 ~103 ~7 ~42 stained_glass 0  
fill ~102 ~7 ~80 ~103 ~7 ~80 stained_glass 0  
fill ~102 ~7 ~81 ~103 ~7 ~81 stained_glass 0  
fill ~103 ~7 ~43 ~104 ~7 ~43 stained_glass 0  
fill ~103 ~7 ~44 ~104 ~7 ~44 stained_glass 0  
fill ~103 ~7 ~45 ~104 ~7 ~45 stained_glass 0  
fill ~103 ~7 ~77 ~104 ~7 ~77 stained_glass 0  
fill ~103 ~7 ~78 ~104 ~7 ~78 stained_glass 0  
fill ~103 ~7 ~79 ~104 ~7 ~79 stained_glass 0  
fill ~104 ~7 ~46 ~105 ~7 ~46 stained_glass 0  
fill ~104 ~7 ~47 ~105 ~7 ~47 stained_glass 0  
fill ~104 ~7 ~48 ~105 ~7 ~48 stained_glass 0  
fill ~104 ~7 ~74 ~105 ~7 ~74 stained_glass 0  
fill ~104 ~7 ~75 ~105 ~7 ~75 stained_glass 0  
fill ~104 ~7 ~76 ~105 ~7 ~76 stained_glass 0  
fill ~105 ~7 ~49 ~106 ~7 ~49 stained_glass 0  
fill ~105 ~7 ~50 ~106 ~7 ~50 stained_glass 0  
fill ~105 ~7 ~51 ~106 ~7 ~51 stained_glass 0  
fill ~105 ~7 ~52 ~106 ~7 ~52 stained_glass 0  
fill ~105 ~7 ~53 ~106 ~7 ~53 stained_glass 0  
fill ~105 ~7 ~54 ~106 ~7 ~54 glowstone 0  
fill ~105 ~7 ~55 ~106 ~7 ~55 stained_glass 0  
fill ~105 ~7 ~56 ~106 ~7 ~56 stained_glass 0  
fill ~105 ~7 ~57 ~106 ~7 ~57 stained_glass 0  
fill ~105 ~7 ~58 ~106 ~7 ~58 stained_glass 0  
fill ~105 ~7 ~59 ~106 ~7 ~59 stained_glass 0  
fill ~105 ~7 ~60 ~106 ~7 ~60 stained_glass 14  
fill ~105 ~7 ~61 ~106 ~7 ~61 stained_glass 14  
fill ~105 ~7 ~62 ~106 ~7 ~62 stained_glass 14  
fill ~105 ~7 ~63 ~106 ~7 ~63 stained_glass 0  
fill ~105 ~7 ~64 ~106 ~7 ~64 stained_glass 0  
fill ~105 ~7 ~65 ~106 ~7 ~65 stained_glass 0  
fill ~105 ~7 ~66 ~106 ~7 ~66 stained_glass 0  
fill ~105 ~7 ~67 ~106 ~7 ~67 stained_glass 0  
fill ~105 ~7 ~68 ~106 ~7 ~68 glowstone 0  
fill ~105 ~7 ~69 ~106 ~7 ~69 stained_glass 0  
fill ~105 ~7 ~70 ~106 ~7 ~70 stained_glass 0  
fill ~105 ~7 ~71 ~106 ~7 ~71 stained_glass 0  
fill ~105 ~7 ~72 ~106 ~7 ~72 stained_glass 0  
fill ~105 ~7 ~73 ~106 ~7 ~73 stained_glass 0  
fill ~18 ~8 ~49 ~22 ~8 ~49 stained_glass 0  
fill ~18 ~8 ~50 ~22 ~8 ~50 stained_glass 0  
fill ~18 ~8 ~51 ~21 ~8 ~51 stained_glass 0  
fill ~18 ~8 ~52 ~21 ~8 ~52 stained_glass 0  
fill ~18 ~8 ~53 ~21 ~8 ~53 stained_glass 0  
fill ~18 ~8 ~54 ~21 ~8 ~54 glowstone 0  
fill ~18 ~8 ~55 ~20 ~8 ~55 stained_glass 0  
fill ~18 ~8 ~56 ~20 ~8 ~56 stained_glass 0  
fill ~18 ~8 ~57 ~20 ~8 ~57 stained_glass 0  
fill ~18 ~8 ~58 ~20 ~8 ~58 stained_glass 0  
fill ~18 ~8 ~59 ~20 ~8 ~59 stained_glass 0  
fill ~18 ~8 ~60 ~20 ~8 ~60 stained_glass 14  
fill ~18 ~8 ~61 ~20 ~8 ~61 stained_glass 14  
fill ~18 ~8 ~62 ~20 ~8 ~62 stained_glass 14  
fill ~18 ~8 ~63 ~20 ~8 ~63 stained_glass 0  
fill ~18 ~8 ~64 ~20 ~8 ~64 stained_glass 0  
fill ~18 ~8 ~65 ~20 ~8 ~65 stained_glass 0  
fill ~18 ~8 ~66 ~20 ~8 ~66 stained_glass 0  
fill ~18 ~8 ~67 ~20 ~8 ~67 stained_glass 0  
fill ~18 ~8 ~68 ~21 ~8 ~68 glowstone 0  
fill ~18 ~8 ~69 ~21 ~8 ~69 stained_glass 0  
fill ~18 ~8 ~70 ~21 ~8 ~70 stained_glass 0  
fill ~18 ~8 ~71 ~21 ~8 ~71 stained_glass 0  
fill ~18 ~8 ~72 ~22 ~8 ~72 stained_glass 0  
fill ~18 ~8 ~73 ~22 ~8 ~73 stained_glass 0  
fill ~19 ~8 ~46 ~23 ~8 ~46 stained_glass 0  
fill ~19 ~8 ~47 ~22 ~8 ~47 stained_glass 0  
fill ~19 ~8 ~48 ~22 ~8 ~48 stained_glass 0  
fill ~19 ~8 ~74 ~22 ~8 ~74 stained_glass 0  
fill ~19 ~8 ~75 ~22 ~8 ~75 stained_glass 0  
fill ~19 ~8 ~76 ~23 ~8 ~76 stained_glass 0  
fill ~20 ~8 ~43 ~24 ~8 ~43 stained_glass 0  
fill ~20 ~8 ~44 ~24 ~8 ~44 stained_glass 0  
fill ~20 ~8 ~45 ~23 ~8 ~45 stained_glass 0  
fill ~20 ~8 ~77 ~23 ~8 ~77 stained_glass 0  
fill ~20 ~8 ~78 ~24 ~8 ~78 stained_glass 0  
fill ~20 ~8 ~79 ~24 ~8 ~79 stained_glass 0  
fill ~21 ~8 ~41 ~25 ~8 ~41 stained_glass 0  
fill ~21 ~8 ~42 ~25 ~8 ~42 stained_glass 0  
fill ~21 ~8 ~55 ~21 ~8 ~67 iron_block 0  
fill ~21 ~8 ~80 ~25 ~8 ~80 stained_glass 0  
fill ~21 ~8 ~81 ~25 ~8 ~81 stained_glass 0  
fill ~22 ~8 ~39 ~26 ~8 ~39 stained_glass 0  
fill ~22 ~8 ~40 ~26 ~8 ~40 stained_glass 0  
fill ~22 ~8 ~51 ~22 ~8 ~54 iron_block 0  
fill ~22 ~8 ~68 ~22 ~8 ~71 iron_block 0  
fill ~22 ~8 ~82 ~26 ~8 ~82 stained_glass 0  
fill ~22 ~8 ~83 ~26 ~8 ~83 stained_glass 0  
fill ~23 ~8 ~37 ~28 ~8 ~37 stained_glass 0  
fill ~23 ~8 ~38 ~27 ~8 ~38 stained_glass 0  
fill ~23 ~8 ~47 ~23 ~8 ~50 iron_block 0  
fill ~23 ~8 ~72 ~23 ~8 ~75 iron_block 0  
fill ~23 ~8 ~84 ~27 ~8 ~84 stained_glass 0  
fill ~23 ~8 ~85 ~28 ~8 ~85 stained_glass 0  
fill ~24 ~8 ~35 ~29 ~8 ~35 stained_glass 0  
fill ~24 ~8 ~36 ~29 ~8 ~36 stained_glass 0  
fill ~24 ~8 ~45 ~24 ~8 ~46 iron_block 0  
fill ~24 ~8 ~76 ~24 ~8 ~77 iron_block 0  
fill ~24 ~8 ~86 ~29 ~8 ~86 stained_glass 0  
fill ~24 ~8 ~87 ~29 ~8 ~87 stained_glass 0  
fill ~25 ~8 ~33 ~30 ~8 ~33 stained_glass 0  
fill ~25 ~8 ~34 ~30 ~8 ~34 stained_glass 0  
fill ~25 ~8 ~43 ~25 ~8 ~44 iron_block 0  
fill ~25 ~8 ~78 ~25 ~8 ~79 iron_block 0  
fill ~25 ~8 ~88 ~30 ~8 ~88 stained_glass 0  
fill ~25 ~8 ~89 ~30 ~8 ~89 stained_glass 0  
fill ~26 ~8 ~32 ~29 ~8 ~32 stained_glass 0  
fill ~26 ~8 ~41 ~26 ~8 ~42 iron_block 0  
fill ~26 ~8 ~80 ~26 ~8 ~81 iron_block 0  
fill ~26 ~8 ~90 ~29 ~8 ~90 stained_glass 0  
fill ~27 ~8 ~31 ~28 ~8 ~31 stained_glass 0  
fill ~27 ~8 ~39 ~27 ~8 ~40 iron_block 0  
fill ~27 ~8 ~82 ~27 ~8 ~83 iron_block 0  
fill ~27 ~8 ~91 ~28 ~8 ~91 stained_glass 0 
setblock ~28 ~8 ~38 iron_block 0 
setblock ~28 ~8 ~84 iron_block 0 
setblock ~29 ~8 ~31 stained_glass 14 
setblock ~29 ~8 ~37 iron_block 0 
setblock ~29 ~8 ~85 iron_block 0 
setblock ~29 ~8 ~91 stained_glass 14 
setblock ~30 ~8 ~30 glowstone 0 
setblock ~30 ~8 ~32 stained_glass 14  
fill ~30 ~8 ~35 ~30 ~8 ~36 iron_block 0  
fill ~30 ~8 ~86 ~30 ~8 ~87 iron_block 0 
setblock ~30 ~8 ~90 stained_glass 14 
setblock ~30 ~8 ~92 glowstone 0  
fill ~31 ~8 ~28 ~37 ~8 ~28 stained_glass 0 
setblock ~31 ~8 ~29 stained_glass 11 
setblock ~31 ~8 ~31 glowstone 0 
setblock ~31 ~8 ~33 stained_glass 14 
setblock ~31 ~8 ~34 iron_block 0 
setblock ~31 ~8 ~88 iron_block 0 
setblock ~31 ~8 ~89 stained_glass 14 
setblock ~31 ~8 ~91 glowstone 0 
setblock ~31 ~8 ~93 stained_glass 11  
fill ~31 ~8 ~94 ~37 ~8 ~94 stained_glass 0  
fill ~31 ~8 ~95 ~38 ~8 ~95 stained_glass 0  
fill ~32 ~8 ~26 ~40 ~8 ~26 stained_glass 0  
fill ~32 ~8 ~27 ~38 ~8 ~27 stained_glass 0  
fill ~32 ~8 ~29 ~36 ~8 ~29 stained_glass 0 
setblock ~32 ~8 ~30 stained_glass 11 
setblock ~32 ~8 ~32 glowstone 0 
setblock ~32 ~8 ~33 iron_block 0 
setblock ~32 ~8 ~89 iron_block 0 
setblock ~32 ~8 ~90 glowstone 0 
setblock ~32 ~8 ~92 stained_glass 11  
fill ~32 ~8 ~93 ~36 ~8 ~93 stained_glass 0  
fill ~32 ~8 ~96 ~40 ~8 ~96 stained_glass 0  
fill ~33 ~8 ~25 ~42 ~8 ~25 stained_glass 0  
fill ~33 ~8 ~30 ~34 ~8 ~30 stained_glass 0 
setblock ~33 ~8 ~31 stained_glass 11 
setblock ~33 ~8 ~32 iron_block 0 
setblock ~33 ~8 ~90 iron_block 0 
setblock ~33 ~8 ~91 stained_glass 11  
fill ~33 ~8 ~92 ~34 ~8 ~92 stained_glass 0  
fill ~33 ~8 ~97 ~42 ~8 ~97 stained_glass 0 
setblock ~34 ~8 ~31 iron_block 0 
setblock ~34 ~8 ~91 iron_block 0  
fill ~35 ~8 ~24 ~44 ~8 ~24 stained_glass 0  
fill ~35 ~8 ~30 ~36 ~8 ~30 iron_block 0  
fill ~35 ~8 ~92 ~36 ~8 ~92 iron_block 0  
fill ~35 ~8 ~98 ~44 ~8 ~98 stained_glass 0  
fill ~37 ~8 ~23 ~46 ~8 ~23 stained_glass 0 
setblock ~37 ~8 ~29 iron_block 0 
setblock ~37 ~8 ~93 iron_block 0  
fill ~37 ~8 ~99 ~46 ~8 ~99 stained_glass 0 
setblock ~38 ~8 ~28 iron_block 0 
setblock ~38 ~8 ~94 iron_block 0  
fill ~39 ~8 ~22 ~50 ~8 ~22 stained_glass 0  
fill ~39 ~8 ~27 ~40 ~8 ~27 iron_block 0  
fill ~39 ~8 ~95 ~40 ~8 ~95 iron_block 0  
fill ~39 ~8 ~100 ~50 ~8 ~100 stained_glass 0  
fill ~41 ~8 ~21 ~53 ~8 ~21 stained_glass 0  
fill ~41 ~8 ~26 ~42 ~8 ~26 iron_block 0  
fill ~41 ~8 ~96 ~42 ~8 ~96 iron_block 0  
fill ~41 ~8 ~101 ~53 ~8 ~101 stained_glass 0  
fill ~43 ~8 ~20 ~53 ~8 ~20 stained_glass 0  
fill ~43 ~8 ~25 ~44 ~8 ~25 iron_block 0  
fill ~43 ~8 ~97 ~44 ~8 ~97 iron_block 0  
fill ~43 ~8 ~102 ~53 ~8 ~102 stained_glass 0  
fill ~45 ~8 ~24 ~46 ~8 ~24 iron_block 0  
fill ~45 ~8 ~98 ~46 ~8 ~98 iron_block 0  
fill ~46 ~8 ~19 ~53 ~8 ~19 stained_glass 0    
fill ~46 ~8 ~103 ~53 ~8 ~103 stained_glass 0  
fill ~47 ~8 ~23 ~50 ~8 ~23 iron_block 0  
fill ~47 ~8 ~99 ~50 ~8 ~99 iron_block 0  
fill ~49 ~8 ~18 ~53 ~8 ~18 stained_glass 0  
fill ~49 ~8 ~104 ~53 ~8 ~104 stained_glass 0  
fill ~51 ~8 ~22 ~54 ~8 ~22 iron_block 0  
fill ~51 ~8 ~100 ~54 ~8 ~100 iron_block 0  
fill ~54 ~8 ~18 ~54 ~8 ~21 glowstone 0  
fill ~54 ~8 ~101 ~54 ~8 ~104 glowstone 0  
fill ~55 ~8 ~18 ~59 ~8 ~18 stained_glass 0  
fill ~55 ~8 ~19 ~59 ~8 ~19 stained_glass 0  
fill ~55 ~8 ~20 ~59 ~8 ~20 stained_glass 0  
fill ~55 ~8 ~21 ~67 ~8 ~21 iron_block 0  
fill ~55 ~8 ~101 ~67 ~8 ~101 iron_block 0  
fill ~55 ~8 ~102 ~59 ~8 ~102 stained_glass 0  
fill ~55 ~8 ~103 ~59 ~8 ~103 stained_glass 0  
fill ~55 ~8 ~104 ~59 ~8 ~104 stained_glass 0  
fill ~60 ~8 ~18 ~62 ~8 ~18 stained_glass 11  
fill ~60 ~8 ~19 ~62 ~8 ~19 stained_glass 11  
fill ~60 ~8 ~20 ~62 ~8 ~20 stained_glass 11  
fill ~60 ~8 ~102 ~62 ~8 ~102 stained_glass 11  
fill ~60 ~8 ~103 ~62 ~8 ~103 stained_glass 11  
fill ~60 ~8 ~104 ~62 ~8 ~104 stained_glass 11  
fill ~63 ~8 ~18 ~67 ~8 ~18 stained_glass 0  
fill ~63 ~8 ~19 ~67 ~8 ~19 stained_glass 0  
fill ~63 ~8 ~20 ~67 ~8 ~20 stained_glass 0  
fill ~63 ~8 ~102 ~67 ~8 ~102 stained_glass 0  
fill ~63 ~8 ~103 ~67 ~8 ~103 stained_glass 0  
fill ~63 ~8 ~104 ~67 ~8 ~104 stained_glass 0  
fill ~68 ~8 ~18 ~68 ~8 ~21 glowstone 0  
fill ~68 ~8 ~22 ~71 ~8 ~22 iron_block 0  
fill ~68 ~8 ~100 ~71 ~8 ~100 iron_block 0  
fill ~68 ~8 ~101 ~68 ~8 ~104 glowstone 0  
fill ~69 ~8 ~18 ~73 ~8 ~18 stained_glass 0  
fill ~69 ~8 ~19 ~76 ~8 ~19 stained_glass 0  
fill ~69 ~8 ~20 ~79 ~8 ~20 stained_glass 0  
fill ~69 ~8 ~21 ~81 ~8 ~21 stained_glass 0  
fill ~69 ~8 ~101 ~81 ~8 ~101 stained_glass 0  
fill ~69 ~8 ~102 ~79 ~8 ~102 stained_glass 0  
fill ~69 ~8 ~103 ~76 ~8 ~103 stained_glass 0  
fill ~69 ~8 ~104 ~73 ~8 ~104 stained_glass 0  
fill ~72 ~8 ~22 ~83 ~8 ~22 stained_glass 0  
fill ~72 ~8 ~23 ~75 ~8 ~23 iron_block 0  
fill ~72 ~8 ~99 ~75 ~8 ~99 iron_block 0  
fill ~72 ~8 ~100 ~83 ~8 ~100 stained_glass 0  
fill ~76 ~8 ~23 ~85 ~8 ~23 stained_glass 0  
fill ~76 ~8 ~24 ~77 ~8 ~24 iron_block 0  
fill ~76 ~8 ~98 ~77 ~8 ~98 iron_block 0  
fill ~76 ~8 ~99 ~85 ~8 ~99 stained_glass 0  
fill ~78 ~8 ~24 ~87 ~8 ~24 stained_glass 0  
fill ~78 ~8 ~25 ~79 ~8 ~25 iron_block 0  
fill ~78 ~8 ~97 ~79 ~8 ~97 iron_block 0  
fill ~78 ~8 ~98 ~87 ~8 ~98 stained_glass 0  
fill ~80 ~8 ~25 ~89 ~8 ~25 stained_glass 0  
fill ~80 ~8 ~26 ~81 ~8 ~26 iron_block 0  
fill ~80 ~8 ~96 ~81 ~8 ~96 iron_block 0  
fill ~80 ~8 ~97 ~89 ~8 ~97 stained_glass 0  
fill ~82 ~8 ~26 ~90 ~8 ~26 stained_glass 0  
fill ~82 ~8 ~27 ~83 ~8 ~27 iron_block 0  
fill ~82 ~8 ~95 ~83 ~8 ~95 iron_block 0  
fill ~82 ~8 ~96 ~90 ~8 ~96 stained_glass 0  
fill ~84 ~8 ~27 ~91 ~8 ~27 stained_glass 0 
setblock ~84 ~8 ~28 iron_block 0 
setblock ~84 ~8 ~94 iron_block 0  
fill ~84 ~8 ~95 ~90 ~8 ~95 stained_glass 0  
fill ~85 ~8 ~28 ~91 ~8 ~28 stained_glass 0 
setblock ~85 ~8 ~29 iron_block 0 
setblock ~85 ~8 ~93 iron_block 0  
fill ~85 ~8 ~94 ~91 ~8 ~94 stained_glass 0  
fill ~86 ~8 ~29 ~90 ~8 ~29 stained_glass 0  
fill ~86 ~8 ~30 ~87 ~8 ~30 iron_block 0  
fill ~86 ~8 ~92 ~87 ~8 ~92 iron_block 0  
fill ~86 ~8 ~93 ~90 ~8 ~93 stained_glass 0  
fill ~88 ~8 ~30 ~89 ~8 ~30 stained_glass 0 
setblock ~88 ~8 ~31 iron_block 0 
setblock ~88 ~8 ~91 iron_block 0  
fill ~88 ~8 ~92 ~89 ~8 ~92 stained_glass 0 
setblock ~89 ~8 ~31 stained_glass 11 
setblock ~89 ~8 ~32 iron_block 0 
setblock ~89 ~8 ~90 iron_block 0 
setblock ~89 ~8 ~91 stained_glass 11 
setblock ~90 ~8 ~30 stained_glass 11 
setblock ~90 ~8 ~32 glowstone 0 
setblock ~90 ~8 ~33 iron_block 0 
setblock ~90 ~8 ~89 iron_block 0 
setblock ~90 ~8 ~90 glowstone 0 
setblock ~90 ~8 ~92 stained_glass 11 
setblock ~91 ~8 ~29 stained_glass 11 
setblock ~91 ~8 ~31 glowstone 0 
setblock ~91 ~8 ~33 stained_glass 14 
setblock ~91 ~8 ~34 iron_block 0 
setblock ~91 ~8 ~88 iron_block 0 
setblock ~91 ~8 ~89 stained_glass 14 
setblock ~91 ~8 ~91 glowstone 0 
setblock ~91 ~8 ~93 stained_glass 11 
setblock ~92 ~8 ~30 glowstone 0 
setblock ~92 ~8 ~32 stained_glass 14  
fill ~92 ~8 ~33 ~97 ~8 ~33 stained_glass 0  
fill ~92 ~8 ~34 ~97 ~8 ~34 stained_glass 0  
fill ~92 ~8 ~35 ~92 ~8 ~36 iron_block 0  
fill ~92 ~8 ~86 ~92 ~8 ~87 iron_block 0  
fill ~92 ~8 ~88 ~97 ~8 ~88 stained_glass 0  
fill ~92 ~8 ~89 ~97 ~8 ~89 stained_glass 0 
setblock ~92 ~8 ~90 stained_glass 14 
setblock ~92 ~8 ~92 glowstone 0 
setblock ~93 ~8 ~31 stained_glass 14  
fill ~93 ~8 ~32 ~96 ~8 ~32 stained_glass 0  
fill ~93 ~8 ~35 ~98 ~8 ~35 stained_glass 0  
fill ~93 ~8 ~36 ~98 ~8 ~36 stained_glass 0 
setblock ~93 ~8 ~37 iron_block 0 
setblock ~93 ~8 ~85 iron_block 0  
fill ~93 ~8 ~86 ~98 ~8 ~86 stained_glass 0  
