fill ~11 ~0 ~19 ~12 ~0 ~19 stone 5  
fill ~11 ~0 ~20 ~11 ~1 ~20 stone 0  
fill ~11 ~0 ~56 ~12 ~0 ~56 stone 0  
fill ~12 ~0 ~18 ~12 ~0 ~18 cobblestone 0  
fill ~12 ~0 ~20 ~13 ~0 ~20 stone 5  
fill ~12 ~0 ~21 ~12 ~0 ~21 cobblestone 0  
fill ~12 ~0 ~55 ~15 ~0 ~55 stone 0 
setblock ~13 ~0 ~17 snow_layer 2  
fill ~13 ~0 ~18 ~14 ~0 ~18 stone 5  
fill ~13 ~0 ~19 ~13 ~1 ~19 stone 0  
fill ~13 ~0 ~21 ~13 ~3 ~21 stone 5 
setblock ~13 ~0 ~22 stone 0 
setblock ~13 ~0 ~54 cobblestone 0  
fill ~13 ~0 ~56 ~15 ~0 ~56 stone 5 
setblock ~14 ~0 ~17 stone 0  
fill ~14 ~0 ~19 ~14 ~0 ~21 cobblestone 0  
fill ~14 ~0 ~22 ~14 ~1 ~22 stone 5  
fill ~14 ~0 ~23 ~15 ~0 ~23 stone 5 
setblock ~14 ~0 ~52 cobblestone 0  
fill ~14 ~0 ~53 ~15 ~0 ~53 stone 0 
setblock ~14 ~0 ~54 stone 5  
fill ~14 ~0 ~57 ~17 ~0 ~57 cobblestone 0  
fill ~14 ~0 ~58 ~14 ~0 ~58 stone 5  
fill ~14 ~0 ~59 ~14 ~1 ~59 cobblestone 0  
fill ~14 ~0 ~60 ~14 ~0 ~60 stone 0  
fill ~15 ~0 ~16 ~15 ~0 ~18 cobblestone 0  
fill ~15 ~0 ~19 ~15 ~2 ~19 stone 5  
fill ~15 ~0 ~20 ~17 ~0 ~20 stone 5  
fill ~15 ~0 ~21 ~15 ~0 ~22 stone 0  
fill ~15 ~0 ~54 ~18 ~0 ~54 stone 0 
setblock ~15 ~0 ~58 cobblestone 0  
fill ~15 ~0 ~59 ~15 ~0 ~59 stone 0  
fill ~15 ~0 ~60 ~15 ~2 ~60 cobblestone 0  
fill ~16 ~0 ~17 ~17 ~0 ~17 cobblestone 0  
fill ~16 ~0 ~18 ~16 ~1 ~18 stone 0  
fill ~16 ~0 ~19 ~16 ~0 ~18 stone 0  
fill ~16 ~0 ~21 ~16 ~1 ~21 stone 5  
fill ~16 ~0 ~22 ~16 ~0 ~20 stone 5 
setblock ~16 ~0 ~23 stone 0  
fill ~16 ~0 ~53 ~16 ~0 ~53 stone 5 
setblock ~16 ~0 ~55 cobblestone 0  
fill ~16 ~0 ~56 ~16 ~1 ~56 stone 0  
fill ~16 ~0 ~58 ~17 ~0 ~58 stone 0  
fill ~16 ~0 ~59 ~17 ~0 ~59 stone 5  
fill ~16 ~0 ~60 ~16 ~0 ~59 stone 5  
fill ~17 ~0 ~19 ~17 ~0 ~19 cobblestone 0  
fill ~17 ~0 ~21 ~17 ~1 ~21 cobblestone 0  
fill ~17 ~0 ~22 ~18 ~0 ~22 stone 0  
fill ~17 ~0 ~23 ~17 ~0 ~23 cobblestone 0 
setblock ~17 ~0 ~24 stone 5  
fill ~17 ~0 ~55 ~17 ~1 ~55 stone 0  
fill ~17 ~0 ~56 ~17 ~0 ~56 cobblestone 0  
fill ~18 ~0 ~18 ~18 ~1 ~18 cobblestone 0  
fill ~18 ~0 ~21 ~18 ~0 ~21 stone 0  
fill ~18 ~0 ~23 ~19 ~0 ~23 stone 0 
setblock ~18 ~0 ~24 cobblestone 0 
setblock ~18 ~0 ~55 cobblestone 0 
setblock ~18 ~0 ~56 stone 5  
fill ~18 ~0 ~57 ~18 ~1 ~57 stone 0 
setblock ~18 ~0 ~58 cobblestone 0  
fill ~19 ~0 ~19 ~19 ~0 ~19 stone 5  
fill ~19 ~0 ~20 ~19 ~1 ~20 stone 5  
fill ~19 ~0 ~21 ~19 ~0 ~22 stone 5 
setblock ~19 ~0 ~24 stone 5 
setblock ~19 ~0 ~56 cobblestone 0  
fill ~20 ~0 ~22 ~20 ~0 ~22 cobblestone 0  
fill ~32 ~0 ~32 ~32 ~1 ~32 stone 0  
fill ~32 ~0 ~33 ~32 ~2 ~33 cobblestone 0 
setblock ~32 ~0 ~34 stone 0  
fill ~33 ~0 ~29 ~34 ~0 ~29 cobblestone 0  
fill ~33 ~0 ~30 ~33 ~0 ~30 cobblestone 0  
fill ~33 ~0 ~31 ~33 ~0 ~32 cobblestone 0 
setblock ~33 ~0 ~33 stone 0  
fill ~33 ~0 ~34 ~33 ~1 ~34 cobblestone 0  
fill ~33 ~0 ~35 ~33 ~0 ~34 cobblestone 0 
setblock ~34 ~0 ~28 cobblestone 0  
fill ~34 ~0 ~30 ~37 ~0 ~30 stone 0  
fill ~34 ~0 ~31 ~35 ~0 ~31 stone 5 
setblock ~34 ~0 ~32 stone 0 
setblock ~34 ~0 ~33 cobblestone 0  
fill ~34 ~0 ~34 ~36 ~0 ~34 stone 0  
fill ~34 ~0 ~35 ~35 ~0 ~35 stone 0  
fill ~34 ~0 ~36 ~35 ~0 ~36 cobblestone 0 
setblock ~35 ~0 ~27 stone 5  
fill ~35 ~0 ~28 ~35 ~1 ~28 stone 0  
fill ~35 ~0 ~29 ~36 ~0 ~29 stone 5 
setblock ~35 ~0 ~32 cobblestone 0 
setblock ~35 ~0 ~33 stone 0 
setblock ~36 ~0 ~27 cobblestone 0 
setblock ~36 ~0 ~28 stone 5  
fill ~36 ~0 ~31 ~36 ~1 ~31 cobblestone 0  
fill ~36 ~0 ~32 ~37 ~0 ~32 stone 0  
fill ~36 ~0 ~33 ~37 ~0 ~33 cobblestone 0  
fill ~36 ~0 ~35 ~36 ~0 ~35 cobblestone 0  
fill ~36 ~0 ~36 ~36 ~1 ~36 stone 5 
setblock ~37 ~0 ~27 stone 5  
fill ~37 ~0 ~28 ~38 ~0 ~28 stone 0  
fill ~37 ~0 ~29 ~37 ~0 ~29 stone 0  
fill ~37 ~0 ~31 ~37 ~1 ~31 stone 0  
fill ~37 ~0 ~34 ~37 ~1 ~34 cobblestone 0  
fill ~37 ~0 ~35 ~38 ~0 ~35 stone 5  
fill ~37 ~0 ~36 ~38 ~0 ~36 cobblestone 0  
fill ~37 ~0 ~37 ~38 ~0 ~37 cobblestone 0  
fill ~38 ~0 ~26 ~38 ~0 ~26 cobblestone 0  
fill ~38 ~0 ~27 ~39 ~0 ~27 cobblestone 0  
fill ~38 ~0 ~29 ~38 ~0 ~29 stone 5  
fill ~38 ~0 ~30 ~38 ~0 ~30 cobblestone 0  
fill ~38 ~0 ~31 ~38 ~0 ~32 cobblestone 0  
fill ~38 ~0 ~33 ~38 ~1 ~33 stone 5  
fill ~38 ~0 ~34 ~39 ~0 ~34 stone 5  
fill ~38 ~0 ~38 ~39 ~0 ~38 cobblestone 0  
fill ~39 ~0 ~26 ~39 ~1 ~26 stone 5 
setblock ~39 ~0 ~28 stone 5 
setblock ~39 ~0 ~29 cobblestone 0  
fill ~39 ~0 ~30 ~39 ~1 ~30 stone 5  
fill ~39 ~0 ~31 ~39 ~1 ~31 stone 0 
setblock ~39 ~0 ~32 stone 5  
fill ~39 ~0 ~33 ~39 ~1 ~33 cobblestone 0  
fill ~39 ~0 ~35 ~40 ~0 ~35 stone 0  
fill ~39 ~0 ~36 ~39 ~0 ~36 stone 5  
fill ~39 ~0 ~37 ~39 ~1 ~37 stone 0 
setblock ~39 ~0 ~39 stone 5  
fill ~40 ~0 ~28 ~41 ~0 ~28 cobblestone 0  
fill ~40 ~0 ~29 ~42 ~0 ~29 stone 0  
fill ~40 ~0 ~30 ~43 ~0 ~30 cobblestone 0 
setblock ~40 ~0 ~31 stone 5  
fill ~40 ~0 ~32 ~40 ~1 ~32 cobblestone 0  
fill ~40 ~0 ~33 ~41 ~0 ~33 stone 0  
fill ~40 ~0 ~34 ~40 ~0 ~34 cobblestone 0 
setblock ~40 ~0 ~36 stone 0  
fill ~40 ~0 ~37 ~40 ~0 ~37 stone 5  
fill ~40 ~0 ~38 ~40 ~1 ~38 stone 0  
fill ~40 ~0 ~40 ~40 ~2 ~40 stone 0  
fill ~40 ~0 ~41 ~40 ~1 ~41 stone 5  
fill ~41 ~0 ~31 ~42 ~0 ~31 cobblestone 0 
setblock ~41 ~0 ~32 stone 0  
fill ~41 ~0 ~34 ~41 ~2 ~34 stone 0  
fill ~41 ~0 ~35 ~41 ~0 ~36 cobblestone 0  
fill ~41 ~0 ~37 ~41 ~14 ~37 sea_lantern 0  
fill ~41 ~0 ~38 ~41 ~14 ~38 sea_lantern 0  
fill ~41 ~0 ~39 ~41 ~14 ~39 sea_lantern 0  
fill ~41 ~0 ~40 ~41 ~14 ~40 sea_lantern 0  
fill ~41 ~0 ~41 ~41 ~14 ~41 sea_lantern 0 
setblock ~41 ~0 ~42 cobblestone 0  
fill ~42 ~0 ~32 ~44 ~0 ~32 stone 5  
fill ~42 ~0 ~33 ~42 ~3 ~33 cobblestone 0  
fill ~42 ~0 ~34 ~42 ~1 ~34 stone 5  
fill ~42 ~0 ~35 ~42 ~1 ~35 stone 5  
fill ~42 ~0 ~36 ~43 ~0 ~36 sea_lantern 0  
fill ~42 ~0 ~37 ~42 ~2 ~37 stone 0  
fill ~42 ~0 ~38 ~42 ~13 ~38 quartz_block 0  
fill ~42 ~0 ~39 ~42 ~12 ~39 quartz_block 0  
fill ~42 ~0 ~40 ~42 ~11 ~40 quartz_block 0 
setblock ~42 ~0 ~41 stone 0  
fill ~42 ~0 ~42 ~42 ~14 ~42 sea_lantern 0  
fill ~42 ~0 ~43 ~42 ~0 ~43 stone 5  
fill ~43 ~0 ~31 ~43 ~0 ~31 stone 0  
fill ~43 ~0 ~33 ~43 ~0 ~33 stone 0  
fill ~43 ~0 ~34 ~43 ~1 ~34 cobblestone 0  
fill ~43 ~0 ~35 ~47 ~0 ~35 sea_lantern 0  
fill ~43 ~0 ~37 ~43 ~14 ~37 quartz_block 0  
fill ~43 ~0 ~41 ~43 ~10 ~41 quartz_block 0  
fill ~43 ~0 ~42 ~43 ~0 ~42 stone 0 
setblock ~43 ~0 ~44 cobblestone 0  
fill ~44 ~0 ~30 ~44 ~2 ~30 stone 0 
setblock ~44 ~0 ~33 stone 5  
fill ~44 ~0 ~34 ~44 ~1 ~34 stone 0 
setblock ~44 ~0 ~36 ice 0  
fill ~44 ~0 ~42 ~46 ~0 ~42 quartz_block 0 
setblock ~44 ~0 ~44 stone 5 
setblock ~44 ~0 ~45 cobblestone 0 
setblock ~45 ~0 ~30 stone 5  
fill ~45 ~0 ~34 ~45 ~1 ~34 cobblestone 0  
fill ~45 ~0 ~36 ~46 ~0 ~36 quartz_block 0  
fill ~45 ~0 ~45 ~46 ~0 ~45 stone 0  
fill ~46 ~0 ~31 ~46 ~1 ~31 cobblestone 0  
fill ~47 ~0 ~32 ~47 ~1 ~32 stone 0 
setblock ~47 ~0 ~36 stone 0  
fill ~47 ~0 ~37 ~47 ~2 ~37 quartz_block 0  
fill ~47 ~0 ~41 ~47 ~6 ~41 quartz_block 0 
setblock ~47 ~0 ~44 stone 0  
fill ~48 ~0 ~32 ~49 ~0 ~32 cobblestone 0  
fill ~48 ~0 ~35 ~49 ~0 ~35 stone 5  
fill ~48 ~0 ~36 ~48 ~14 ~36 sea_lantern 0 
setblock ~48 ~0 ~37 cobblestone 0  
fill ~48 ~0 ~38 ~48 ~3 ~38 quartz_block 0  
fill ~48 ~0 ~39 ~48 ~4 ~39 quartz_block 0  
fill ~48 ~0 ~40 ~48 ~5 ~40 quartz_block 0  
fill ~48 ~0 ~42 ~48 ~14 ~42 sea_lantern 0  
fill ~48 ~0 ~44 ~48 ~1 ~44 stone 5  
fill ~49 ~0 ~36 ~49 ~1 ~36 cobblestone 0  
fill ~49 ~0 ~37 ~49 ~14 ~37 sea_lantern 0  
fill ~49 ~0 ~38 ~49 ~14 ~38 sea_lantern 0  
fill ~49 ~0 ~39 ~49 ~14 ~39 sea_lantern 0  
fill ~49 ~0 ~40 ~49 ~14 ~40 sea_lantern 0  
fill ~49 ~0 ~41 ~49 ~14 ~41 sea_lantern 0 
setblock ~49 ~0 ~43 stone 0  
fill ~50 ~0 ~33 ~50 ~1 ~33 stone 5  
fill ~50 ~0 ~42 ~50 ~0 ~43 stone 5 
setblock ~51 ~0 ~34 stone 5 
setblock ~51 ~0 ~35 cobblestone 0  
fill ~51 ~0 ~40 ~51 ~0 ~41 stone 0 
setblock ~52 ~0 ~36 cobblestone 0  
fill ~52 ~0 ~38 ~52 ~0 ~39 stone 5 
setblock ~53 ~0 ~37 cobblestone 0 
setblock ~57 ~0 ~59 cobblestone 0  
fill ~58 ~0 ~57 ~59 ~0 ~57 cobblestone 0  
fill ~58 ~0 ~58 ~58 ~1 ~58 stone 5  
fill ~58 ~0 ~59 ~58 ~0 ~59 stone 5  
fill ~58 ~0 ~60 ~59 ~0 ~60 stone 5 
setblock ~59 ~0 ~55 stone 0 
setblock ~59 ~0 ~56 cobblestone 0  
fill ~59 ~0 ~58 ~63 ~0 ~58 cobblestone 0 
setblock ~59 ~0 ~59 stone 0 
setblock ~59 ~0 ~61 stone 0  
fill ~60 ~0 ~19 ~60 ~1 ~19 cobblestone 0 
setblock ~60 ~0 ~54 stone 5  
fill ~60 ~0 ~55 ~60 ~3 ~55 cobblestone 0  
fill ~60 ~0 ~56 ~63 ~0 ~56 stone 5  
fill ~60 ~0 ~57 ~60 ~1 ~57 stone 5  
fill ~60 ~0 ~59 ~61 ~0 ~59 cobblestone 0  
fill ~60 ~0 ~60 ~61 ~0 ~60 cobblestone 0  
fill ~60 ~0 ~61 ~60 ~0 ~58 cobblestone 0 
setblock ~60 ~0 ~62 stone 5  
fill ~61 ~0 ~54 ~61 ~1 ~54 cobblestone 0  
fill ~61 ~0 ~55 ~61 ~1 ~55 stone 5  
fill ~61 ~0 ~57 ~61 ~1 ~57 cobblestone 0  
fill ~61 ~0 ~61 ~61 ~0 ~61 stone 5  
fill ~61 ~0 ~62 ~61 ~0 ~62 stone 0 
setblock ~62 ~0 ~53 cobblestone 0  
fill ~62 ~0 ~54 ~62 ~2 ~54 stone 0  
fill ~62 ~0 ~55 ~63 ~0 ~55 stone 0  
fill ~62 ~0 ~57 ~62 ~1 ~57 stone 0  
fill ~62 ~0 ~59 ~63 ~0 ~59 stone 5  
fill ~62 ~0 ~60 ~62 ~0 ~59 stone 5  
fill ~62 ~0 ~61 ~62 ~2 ~61 stone 0  
fill ~62 ~0 ~62 ~64 ~0 ~62 cobblestone 0  
fill ~63 ~0 ~54 ~63 ~0 ~54 cobblestone 0  
fill ~63 ~0 ~57 ~66 ~0 ~57 cobblestone 0  
fill ~63 ~0 ~60 ~63 ~1 ~60 stone 0  
fill ~63 ~0 ~61 ~63 ~1 ~61 cobblestone 0  
fill ~64 ~0 ~54 ~64 ~0 ~54 stone 0  
fill ~64 ~0 ~55 ~64 ~1 ~55 cobblestone 0  
fill ~64 ~0 ~56 ~65 ~0 ~56 cobblestone 0 
setblock ~64 ~0 ~58 stone 0 
setblock ~64 ~0 ~59 cobblestone 0  
fill ~64 ~0 ~60 ~64 ~0 ~61 stone 5  
fill ~65 ~0 ~55 ~65 ~1 ~55 stone 5  
fill ~65 ~0 ~58 ~65 ~0 ~58 stone 5  
fill ~65 ~0 ~59 ~66 ~0 ~59 stone 5  
fill ~65 ~0 ~60 ~65 ~1 ~60 stone 0  
fill ~65 ~0 ~61 ~65 ~2 ~61 stone 0  
fill ~65 ~0 ~62 ~65 ~0 ~60 stone 0  
fill ~66 ~0 ~56 ~66 ~0 ~56 stone 0  
fill ~66 ~0 ~58 ~66 ~0 ~58 cobblestone 0 
setblock ~11 ~1 ~19 snow_layer 1  
fill ~12 ~1 ~18 ~14 ~1 ~18 stone 0  
fill ~12 ~1 ~19 ~12 ~1 ~22 stone 0  
fill ~12 ~1 ~55 ~13 ~1 ~55 stone 0 
setblock ~12 ~1 ~56 cobblestone 0 
setblock ~13 ~1 ~20 stone 0  
fill ~13 ~1 ~22 ~13 ~2 ~22 cobblestone 0 
setblock ~13 ~1 ~54 stone 5 
setblock ~13 ~1 ~56 stone 0  
fill ~14 ~1 ~17 ~16 ~1 ~17 stone 5 
setblock ~14 ~1 ~19 stone 0  
fill ~14 ~1 ~20 ~15 ~1 ~20 cobblestone 0 
setblock ~14 ~1 ~21 stone 5  
fill ~14 ~1 ~23 ~14 ~0 ~23 stone 5  
fill ~14 ~1 ~52 ~15 ~1 ~52 stone 0  
fill ~14 ~1 ~53 ~14 ~1 ~55 cobblestone 0  
fill ~14 ~1 ~56 ~15 ~1 ~56 stone 5  
fill ~14 ~1 ~57 ~14 ~3 ~57 stone 5  
fill ~14 ~1 ~58 ~16 ~1 ~58 stone 0 
setblock ~14 ~1 ~60 cobblestone 0 
setblock ~15 ~1 ~18 cobblestone 0  
fill ~15 ~1 ~21 ~15 ~1 ~23 cobblestone 0 
setblock ~15 ~1 ~53 stone 0 
setblock ~15 ~1 ~54 stone 5  
fill ~15 ~1 ~55 ~17 ~1 ~55 stone 0  
fill ~15 ~1 ~57 ~17 ~1 ~57 cobblestone 0 
setblock ~15 ~1 ~59 cobblestone 0  
fill ~16 ~1 ~19 ~17 ~1 ~19 stone 5 
setblock ~16 ~1 ~20 stone 0  
fill ~16 ~1 ~22 ~17 ~1 ~22 cobblestone 0  
fill ~16 ~1 ~23 ~16 ~2 ~23 cobblestone 0  
fill ~16 ~1 ~53 ~16 ~1 ~54 cobblestone 0  
fill ~16 ~1 ~59 ~16 ~2 ~59 stone 0 
setblock ~16 ~1 ~60 cobblestone 0 
setblock ~17 ~1 ~18 stone 5  
fill ~17 ~1 ~20 ~19 ~1 ~20 stone 5  
fill ~17 ~1 ~23 ~19 ~1 ~23 stone 5  
fill ~17 ~1 ~53 ~17 ~1 ~54 stone 5  
fill ~17 ~1 ~56 ~17 ~2 ~56 stone 5  
fill ~17 ~1 ~58 ~17 ~2 ~58 cobblestone 0  
fill ~17 ~1 ~59 ~18 ~1 ~59 cobblestone 0  
fill ~18 ~1 ~19 ~19 ~1 ~19 cobblestone 0  
fill ~18 ~1 ~21 ~18 ~1 ~23 stone 5  
fill ~18 ~1 ~54 ~18 ~1 ~55 stone 5 
setblock ~18 ~1 ~56 stone 0  
fill ~18 ~1 ~58 ~18 ~5 ~58 stone 0  
fill ~19 ~1 ~21 ~19 ~2 ~21 cobblestone 0 
setblock ~19 ~1 ~22 stone 5 
setblock ~19 ~1 ~55 cobblestone 0  
fill ~19 ~1 ~56 ~19 ~2 ~56 stone 5  
fill ~19 ~1 ~57 ~19 ~3 ~57 stone 0 
setblock ~33 ~1 ~30 stone 0  
fill ~33 ~1 ~31 ~34 ~1 ~31 stone 5  
fill ~33 ~1 ~32 ~34 ~1 ~32 stone 5 
setblock ~33 ~1 ~33 cobblestone 0 
setblock ~33 ~1 ~35 stone 5  
fill ~34 ~1 ~28 ~34 ~1 ~29 stone 0 
setblock ~34 ~1 ~30 cobblestone 0 
setblock ~34 ~1 ~33 stone 5  
fill ~34 ~1 ~34 ~34 ~0 ~34 stone 0  
fill ~34 ~1 ~35 ~34 ~2 ~35 cobblestone 0  
fill ~34 ~1 ~36 ~34 ~0 ~36 cobblestone 0 
setblock ~35 ~1 ~27 stone 0  
fill ~35 ~1 ~29 ~36 ~1 ~29 stone 5  
fill ~35 ~1 ~30 ~35 ~1 ~29 stone 5  
fill ~35 ~1 ~31 ~35 ~1 ~32 stone 0 
setblock ~35 ~1 ~33 cobblestone 0  
fill ~35 ~1 ~34 ~36 ~1 ~34 stone 5  
fill ~35 ~1 ~35 ~35 ~1 ~36 stone 5 
setblock ~36 ~1 ~27 stone 5 
setblock ~36 ~1 ~28 stone 0  
fill ~36 ~1 ~30 ~36 ~4 ~30 cobblestone 0  
fill ~36 ~1 ~32 ~37 ~1 ~32 stone 5  
fill ~36 ~1 ~33 ~36 ~1 ~32 stone 5  
fill ~36 ~1 ~35 ~36 ~3 ~35 stone 0  
fill ~36 ~1 ~37 ~37 ~1 ~37 stone 5  
fill ~37 ~1 ~27 ~39 ~1 ~27 cobblestone 0  
fill ~37 ~1 ~28 ~37 ~1 ~29 cobblestone 0  
fill ~37 ~1 ~30 ~37 ~5 ~30 stone 5 
setblock ~37 ~1 ~33 stone 0  
fill ~37 ~1 ~35 ~38 ~1 ~35 cobblestone 0  
fill ~37 ~1 ~36 ~37 ~0 ~36 cobblestone 0  
fill ~38 ~1 ~26 ~38 ~2 ~26 stone 5 
setblock ~38 ~1 ~28 stone 5  
fill ~38 ~1 ~29 ~40 ~1 ~29 stone 0  
fill ~38 ~1 ~30 ~38 ~2 ~30 stone 0 
setblock ~38 ~1 ~31 stone 5 
setblock ~38 ~1 ~32 cobblestone 0 
setblock ~38 ~1 ~34 cobblestone 0  
fill ~38 ~1 ~36 ~39 ~1 ~36 stone 0  
fill ~38 ~1 ~37 ~38 ~1 ~36 stone 0  
fill ~39 ~1 ~28 ~40 ~1 ~28 cobblestone 0 
setblock ~39 ~1 ~32 stone 0  
fill ~39 ~1 ~34 ~40 ~1 ~34 stone 5  
fill ~39 ~1 ~35 ~41 ~1 ~35 stone 0  
fill ~39 ~1 ~38 ~39 ~1 ~39 stone 0  
fill ~40 ~1 ~27 ~40 ~2 ~27 stone 5  
fill ~40 ~1 ~30 ~42 ~1 ~30 stone 0  
fill ~40 ~1 ~31 ~41 ~1 ~31 stone 0  
fill ~40 ~1 ~33 ~40 ~0 ~33 stone 0  
fill ~40 ~1 ~36 ~40 ~2 ~36 stone 5 
setblock ~40 ~1 ~37 cobblestone 0 
setblock ~40 ~1 ~39 stone 0 
setblock ~41 ~1 ~28 stone 5 
setblock ~41 ~1 ~29 cobblestone 0 
setblock ~41 ~1 ~32 cobblestone 0 
setblock ~41 ~1 ~33 stone 5 
setblock ~41 ~1 ~36 cobblestone 0 
setblock ~41 ~1 ~42 stone 0 
setblock ~42 ~1 ~29 stone 5  
fill ~42 ~1 ~31 ~44 ~1 ~31 cobblestone 0 
setblock ~42 ~1 ~32 stone 0  
fill ~42 ~1 ~36 ~42 ~30 ~36 sea_lantern 0  
fill ~42 ~1 ~41 ~42 ~2 ~41 cobblestone 0  
fill ~42 ~1 ~43 ~42 ~3 ~43 cobblestone 0  
fill ~43 ~1 ~30 ~43 ~4 ~30 stone 5  
fill ~43 ~1 ~32 ~43 ~2 ~32 cobblestone 0  
fill ~43 ~1 ~33 ~43 ~1 ~31 cobblestone 0  
fill ~43 ~1 ~35 ~47 ~1 ~35 sea_lantern 0 
setblock ~43 ~1 ~36 cobblestone 0  
fill ~43 ~1 ~42 ~43 ~1 ~43 stone 5 
setblock ~44 ~1 ~33 stone 0  
fill ~44 ~1 ~36 ~44 ~15 ~36 quartz_block 0  
fill ~44 ~1 ~42 ~46 ~1 ~42 quartz_block 0 
setblock ~44 ~1 ~44 stone 0 
setblock ~45 ~1 ~31 stone 5 
setblock ~45 ~1 ~36 ice 0  
fill ~45 ~1 ~45 ~46 ~1 ~45 cobblestone 0 
setblock ~46 ~1 ~36 quartz_block 0 
setblock ~47 ~1 ~36 cobblestone 0 
setblock ~47 ~1 ~42 stone 0 
setblock ~47 ~1 ~44 cobblestone 0 
setblock ~48 ~1 ~32 stone 5  
fill ~48 ~1 ~35 ~49 ~1 ~35 cobblestone 0 
setblock ~48 ~1 ~37 stone 0 
setblock ~48 ~1 ~41 stone 0 
setblock ~49 ~1 ~32 cobblestone 0 
setblock ~49 ~1 ~42 stone 0 
setblock ~49 ~1 ~43 stone 5  
fill ~50 ~1 ~42 ~50 ~1 ~43 cobblestone 0  
fill ~51 ~1 ~34 ~51 ~1 ~35 stone 0 
setblock ~51 ~1 ~40 stone 5 
setblock ~51 ~1 ~41 stone 0 
setblock ~52 ~1 ~36 stone 5 
setblock ~52 ~1 ~37 cobblestone 0 
setblock ~52 ~1 ~38 stone 0  
fill ~52 ~1 ~39 ~52 ~2 ~39 cobblestone 0 
setblock ~58 ~1 ~56 stone 5  
fill ~58 ~1 ~57 ~58 ~4 ~57 cobblestone 0 
setblock ~58 ~1 ~59 cobblestone 0  
fill ~58 ~1 ~60 ~58 ~0 ~60 stone 5 
setblock ~59 ~1 ~55 stone 5  
fill ~59 ~1 ~56 ~59 ~3 ~56 stone 0  
fill ~59 ~1 ~57 ~59 ~1 ~59 stone 5  
fill ~59 ~1 ~60 ~60 ~1 ~60 stone 0  
fill ~59 ~1 ~61 ~60 ~1 ~61 stone 5  
fill ~60 ~1 ~56 ~62 ~1 ~56 cobblestone 0  
fill ~60 ~1 ~58 ~61 ~1 ~58 stone 5 
setblock ~60 ~1 ~59 cobblestone 0 
setblock ~60 ~1 ~62 cobblestone 0 
setblock ~61 ~1 ~59 stone 5  
fill ~61 ~1 ~60 ~61 ~3 ~60 cobblestone 0 
setblock ~61 ~1 ~61 stone 0 
setblock ~61 ~1 ~62 stone 5 
setblock ~62 ~1 ~53 stone 5 
setblock ~62 ~1 ~55 cobblestone 0  
fill ~62 ~1 ~58 ~63 ~1 ~58 cobblestone 0  
fill ~62 ~1 ~59 ~62 ~1 ~62 stone 0  
fill ~63 ~1 ~54 ~63 ~2 ~54 stone 5  
fill ~63 ~1 ~55 ~63 ~1 ~54 stone 5  
fill ~63 ~1 ~56 ~65 ~1 ~56 stone 0  
fill ~63 ~1 ~57 ~64 ~1 ~57 stone 0 
setblock ~63 ~1 ~59 stone 5 
setblock ~63 ~1 ~62 stone 5  
fill ~64 ~1 ~54 ~64 ~3 ~54 cobblestone 0 
setblock ~64 ~1 ~58 stone 5  
fill ~64 ~1 ~59 ~64 ~1 ~62 stone 0  
fill ~65 ~1 ~57 ~66 ~1 ~57 cobblestone 0 
setblock ~65 ~1 ~58 stone 0  
fill ~65 ~1 ~59 ~65 ~0 ~59 stone 5 
setblock ~66 ~1 ~56 stone 5 
setblock ~66 ~1 ~58 stone 5 
setblock ~66 ~1 ~59 cobblestone 0 
setblock ~12 ~2 ~18 snow_layer 4  
fill ~12 ~2 ~19 ~14 ~2 ~19 cobblestone 0  
fill ~12 ~2 ~20 ~13 ~2 ~20 cobblestone 0 
setblock ~12 ~2 ~21 stone 5 
setblock ~12 ~2 ~55 cobblestone 0  
fill ~12 ~2 ~56 ~15 ~2 ~56 stone 5  
fill ~13 ~2 ~18 ~13 ~3 ~18 stone 0 
setblock ~13 ~2 ~54 cobblestone 0  
fill ~13 ~2 ~55 ~13 ~4 ~55 stone 0 
setblock ~14 ~2 ~17 stone 0  
fill ~14 ~2 ~18 ~15 ~2 ~18 stone 5 
setblock ~14 ~2 ~20 stone 5 
setblock ~14 ~2 ~21 cobblestone 0  
fill ~14 ~2 ~22 ~15 ~2 ~22 stone 0 
setblock ~14 ~2 ~53 stone 5  
fill ~14 ~2 ~54 ~15 ~2 ~54 stone 0 
setblock ~14 ~2 ~55 stone 5  
fill ~14 ~2 ~58 ~15 ~2 ~58 stone 0  
fill ~14 ~2 ~59 ~14 ~3 ~59 stone 5 
setblock ~15 ~2 ~17 stone 5  
fill ~15 ~2 ~20 ~17 ~2 ~20 cobblestone 0  
fill ~15 ~2 ~21 ~15 ~3 ~21 stone 5 
setblock ~15 ~2 ~23 stone 5  
fill ~15 ~2 ~52 ~15 ~4 ~52 stone 0  
fill ~15 ~2 ~53 ~15 ~3 ~53 cobblestone 0  
fill ~15 ~2 ~55 ~16 ~2 ~55 stone 0  
fill ~15 ~2 ~57 ~16 ~2 ~57 stone 0 
setblock ~15 ~2 ~59 stone 0  
fill ~16 ~2 ~17 ~16 ~4 ~17 stone 0  
fill ~16 ~2 ~19 ~16 ~4 ~19 stone 5 
setblock ~16 ~2 ~21 stone 0  
fill ~16 ~2 ~22 ~16 ~3 ~22 stone 5  
fill ~16 ~2 ~53 ~17 ~2 ~53 stone 0 
setblock ~16 ~2 ~54 stone 5 
setblock ~16 ~2 ~56 cobblestone 0 
setblock ~16 ~2 ~58 cobblestone 0 
setblock ~16 ~2 ~60 stone 5 
setblock ~17 ~2 ~18 cobblestone 0 
setblock ~17 ~2 ~19 stone 0 
setblock ~17 ~2 ~21 stone 5  
fill ~17 ~2 ~22 ~18 ~2 ~22 stone 0 
setblock ~17 ~2 ~23 cobblestone 0 
setblock ~17 ~2 ~54 cobblestone 0 
setblock ~17 ~2 ~55 stone 5 
setblock ~17 ~2 ~57 cobblestone 0  
fill ~17 ~2 ~59 ~18 ~2 ~59 cobblestone 0 
setblock ~17 ~2 ~60 stone 0  
fill ~18 ~2 ~19 ~19 ~2 ~19 cobblestone 0  
fill ~18 ~2 ~20 ~18 ~2 ~22 stone 0  
fill ~18 ~2 ~54 ~18 ~2 ~55 stone 0  
fill ~18 ~2 ~56 ~18 ~2 ~57 stone 5 
setblock ~19 ~2 ~20 cobblestone 0 
setblock ~19 ~2 ~22 cobblestone 0 
setblock ~19 ~2 ~55 stone 0  
fill ~19 ~2 ~58 ~19 ~3 ~58 stone 0 
setblock ~20 ~2 ~56 cobblestone 0  
fill ~33 ~2 ~31 ~35 ~2 ~31 stone 5 
setblock ~33 ~2 ~32 stone 0  
fill ~33 ~2 ~33 ~33 ~2 ~34 stone 5 
setblock ~34 ~2 ~29 cobblestone 0  
fill ~34 ~2 ~30 ~35 ~2 ~30 stone 0  
fill ~34 ~2 ~32 ~35 ~2 ~32 stone 5 
setblock ~34 ~2 ~33 cobblestone 0  
fill ~34 ~2 ~34 ~35 ~2 ~34 stone 5  
fill ~35 ~2 ~27 ~35 ~2 ~29 stone 5  
fill ~35 ~2 ~33 ~35 ~3 ~33 stone 5 
setblock ~35 ~2 ~35 stone 0  
fill ~35 ~2 ~36 ~36 ~2 ~36 cobblestone 0  
fill ~36 ~2 ~27 ~37 ~2 ~27 stone 0 
setblock ~36 ~2 ~28 cobblestone 0 
setblock ~36 ~2 ~29 stone 0  
fill ~36 ~2 ~31 ~36 ~2 ~33 stone 0 
setblock ~36 ~2 ~34 cobblestone 0  
fill ~36 ~2 ~37 ~37 ~2 ~37 stone 5  
fill ~37 ~2 ~28 ~39 ~2 ~28 stone 0 
setblock ~37 ~2 ~29 cobblestone 0  
fill ~37 ~2 ~31 ~38 ~2 ~31 cobblestone 0 
setblock ~37 ~2 ~32 stone 0 
setblock ~37 ~2 ~33 cobblestone 0  
fill ~37 ~2 ~34 ~37 ~2 ~35 stone 0  
fill ~37 ~2 ~36 ~37 ~3 ~36 stone 5  
fill ~38 ~2 ~27 ~40 ~2 ~27 stone 5  
fill ~38 ~2 ~29 ~40 ~2 ~29 stone 5 
setblock ~38 ~2 ~32 stone 5 
setblock ~38 ~2 ~33 stone 0  
fill ~38 ~2 ~34 ~39 ~2 ~34 stone 5  
fill ~38 ~2 ~35 ~38 ~2 ~36 stone 0 
setblock ~38 ~2 ~37 cobblestone 0  
fill ~38 ~2 ~38 ~38 ~3 ~38 stone 5  
fill ~39 ~2 ~30 ~39 ~3 ~30 cobblestone 0  
fill ~39 ~2 ~31 ~40 ~2 ~31 stone 5 
setblock ~39 ~2 ~32 cobblestone 0  
fill ~39 ~2 ~33 ~39 ~5 ~33 stone 5  
fill ~39 ~2 ~35 ~39 ~3 ~35 stone 5  
fill ~39 ~2 ~36 ~39 ~3 ~36 stone 5  
fill ~39 ~2 ~37 ~39 ~2 ~33 stone 5  
fill ~39 ~2 ~38 ~39 ~5 ~38 cobblestone 0  
fill ~39 ~2 ~39 ~40 ~2 ~39 cobblestone 0 
setblock ~40 ~2 ~28 stone 5  
fill ~40 ~2 ~30 ~41 ~2 ~30 stone 5 
setblock ~40 ~2 ~32 stone 5  
fill ~40 ~2 ~33 ~42 ~2 ~33 cobblestone 0 
setblock ~40 ~2 ~34 stone 0 
setblock ~40 ~2 ~35 cobblestone 0 
setblock ~40 ~2 ~37 stone 0 
setblock ~40 ~2 ~38 stone 5  
fill ~40 ~2 ~41 ~40 ~3 ~41 cobblestone 0 
setblock ~40 ~2 ~42 stone 0 
setblock ~41 ~2 ~28 cobblestone 0 
setblock ~41 ~2 ~29 stone 0  
fill ~41 ~2 ~31 ~43 ~2 ~31 stone 0  
fill ~41 ~2 ~32 ~41 ~2 ~31 stone 0  
fill ~41 ~2 ~35 ~42 ~2 ~35 stone 0 
setblock ~41 ~2 ~36 stone 5  
fill ~41 ~2 ~42 ~41 ~3 ~42 cobblestone 0 
setblock ~42 ~2 ~29 cobblestone 0 
setblock ~42 ~2 ~30 stone 0  
fill ~42 ~2 ~32 ~42 ~5 ~32 stone 5  
fill ~42 ~2 ~34 ~43 ~2 ~34 stone 0  
fill ~43 ~2 ~33 ~43 ~4 ~33 stone 5  
fill ~43 ~2 ~35 ~47 ~2 ~35 sea_lantern 0 
setblock ~43 ~2 ~36 stone 0  
fill ~43 ~2 ~42 ~43 ~2 ~43 stone 0 
setblock ~44 ~2 ~33 cobblestone 0  
fill ~44 ~2 ~34 ~45 ~2 ~34 stone 5  
fill ~44 ~2 ~42 ~46 ~2 ~42 quartz_block 0  
fill ~44 ~2 ~44 ~44 ~3 ~44 cobblestone 0 
setblock ~45 ~2 ~31 stone 0  
fill ~45 ~2 ~36 ~45 ~16 ~36 quartz_block 0 
setblock ~45 ~2 ~45 stone 0 
setblock ~46 ~2 ~31 stone 5 
setblock ~46 ~2 ~36 ice 0 
setblock ~46 ~2 ~44 cobblestone 0 
setblock ~47 ~2 ~32 stone 5  
fill ~47 ~2 ~36 ~47 ~3 ~36 sea_lantern 0 
setblock ~47 ~2 ~42 lapis_block 0  
fill ~47 ~2 ~44 ~47 ~3 ~44 stone 5 
setblock ~48 ~2 ~32 stone 0 
setblock ~48 ~2 ~35 stone 0 
setblock ~48 ~2 ~43 cobblestone 0  
fill ~49 ~2 ~33 ~50 ~2 ~33 stone 0 
setblock ~49 ~2 ~35 stone 5  
fill ~49 ~2 ~42 ~49 ~3 ~42 cobblestone 0 
setblock ~49 ~2 ~43 stone 0 
setblock ~50 ~2 ~34 stone 0 
setblock ~50 ~2 ~41 cobblestone 0 
setblock ~50 ~2 ~42 stone 0 
setblock ~51 ~2 ~35 stone 0 
setblock ~51 ~2 ~36 stone 5 
setblock ~51 ~2 ~40 cobblestone 0  
fill ~52 ~2 ~37 ~52 ~3 ~37 stone 5 
setblock ~52 ~2 ~38 cobblestone 0  
fill ~58 ~2 ~58 ~59 ~2 ~58 cobblestone 0  
fill ~58 ~2 ~59 ~58 ~2 ~60 stone 0 
setblock ~59 ~2 ~55 stone 0 
setblock ~59 ~2 ~57 stone 0  
fill ~59 ~2 ~59 ~59 ~2 ~60 cobblestone 0 
setblock ~59 ~2 ~61 stone 0 
setblock ~60 ~2 ~19 stone 0  
fill ~60 ~2 ~54 ~60 ~3 ~54 cobblestone 0  
fill ~60 ~2 ~56 ~60 ~4 ~56 cobblestone 0  
fill ~60 ~2 ~57 ~60 ~2 ~54 cobblestone 0  
fill ~60 ~2 ~58 ~61 ~2 ~58 stone 0  
fill ~60 ~2 ~59 ~60 ~4 ~59 stone 5  
fill ~60 ~2 ~60 ~60 ~2 ~61 stone 5  
fill ~61 ~2 ~53 ~61 ~2 ~54 stone 5 
setblock ~61 ~2 ~55 cobblestone 0  
fill ~61 ~2 ~56 ~63 ~2 ~56 stone 5 
setblock ~61 ~2 ~57 stone 0  
fill ~61 ~2 ~59 ~61 ~4 ~59 stone 0 
setblock ~61 ~2 ~61 stone 5 
setblock ~61 ~2 ~62 cobblestone 0 
setblock ~62 ~2 ~53 cobblestone 0  
fill ~62 ~2 ~55 ~65 ~2 ~55 stone 0  
fill ~62 ~2 ~57 ~62 ~2 ~58 stone 5  
fill ~62 ~2 ~59 ~62 ~4 ~59 cobblestone 0  
fill ~62 ~2 ~60 ~64 ~2 ~60 cobblestone 0 
setblock ~62 ~2 ~62 stone 0  
fill ~63 ~2 ~53 ~63 ~4 ~53 stone 5  
fill ~63 ~2 ~57 ~63 ~1 ~57 stone 0  
fill ~63 ~2 ~58 ~64 ~2 ~58 stone 0  
fill ~63 ~2 ~59 ~63 ~4 ~59 stone 0  
fill ~63 ~2 ~61 ~63 ~4 ~61 stone 0 
setblock ~63 ~2 ~62 cobblestone 0 
setblock ~64 ~2 ~56 stone 0 
setblock ~64 ~2 ~57 stone 5 
setblock ~64 ~2 ~59 cobblestone 0 
setblock ~64 ~2 ~61 stone 5 
setblock ~65 ~2 ~56 cobblestone 0  
fill ~65 ~2 ~57 ~66 ~2 ~57 stone 0  
fill ~65 ~2 ~58 ~65 ~4 ~58 stone 5  
fill ~65 ~2 ~59 ~65 ~3 ~59 stone 0  
fill ~65 ~2 ~60 ~65 ~4 ~60 stone 5 
setblock ~66 ~2 ~58 cobblestone 0 
setblock ~66 ~2 ~59 stone 5  
fill ~12 ~3 ~20 ~13 ~3 ~20 cobblestone 0 
setblock ~12 ~3 ~21 stone 0  
fill ~12 ~3 ~55 ~12 ~3 ~56 stone 5  
fill ~13 ~3 ~19 ~15 ~3 ~19 stone 0 
setblock ~13 ~3 ~22 stone 5 
setblock ~13 ~3 ~56 cobblestone 0  
fill ~14 ~3 ~18 ~14 ~5 ~18 stone 0  
fill ~14 ~3 ~20 ~15 ~3 ~20 stone 0  
fill ~14 ~3 ~21 ~14 ~5 ~21 stone 0 
setblock ~14 ~3 ~22 cobblestone 0 
setblock ~14 ~3 ~54 cobblestone 0  
fill ~14 ~3 ~55 ~14 ~4 ~55 stone 0  
fill ~14 ~3 ~56 ~14 ~3 ~55 stone 0  
fill ~14 ~3 ~58 ~14 ~1 ~58 stone 0 
setblock ~15 ~3 ~17 stone 0 
setblock ~15 ~3 ~18 stone 5  
fill ~15 ~3 ~22 ~15 ~3 ~23 stone 0 
setblock ~15 ~3 ~54 stone 0  
fill ~15 ~3 ~55 ~16 ~3 ~55 stone 5 
setblock ~15 ~3 ~56 cobblestone 0  
fill ~15 ~3 ~57 ~15 ~4 ~57 stone 5  
fill ~15 ~3 ~58 ~15 ~4 ~58 cobblestone 0  
fill ~15 ~3 ~59 ~17 ~3 ~59 stone 5  
fill ~15 ~3 ~60 ~15 ~3 ~59 stone 5 
setblock ~16 ~3 ~18 cobblestone 0  
fill ~16 ~3 ~20 ~18 ~3 ~20 cobblestone 0 
setblock ~16 ~3 ~21 stone 5  
fill ~16 ~3 ~23 ~17 ~3 ~23 stone 0  
fill ~16 ~3 ~53 ~17 ~3 ~53 stone 5 
setblock ~16 ~3 ~54 cobblestone 0  
fill ~16 ~3 ~56 ~16 ~5 ~56 stone 5  
fill ~16 ~3 ~57 ~16 ~4 ~57 cobblestone 0  
fill ~16 ~3 ~58 ~19 ~3 ~58 stone 0  
fill ~16 ~3 ~60 ~16 ~4 ~60 stone 0 
setblock ~17 ~3 ~18 stone 5 
setblock ~17 ~3 ~19 cobblestone 0  
fill ~17 ~3 ~21 ~18 ~3 ~21 cobblestone 0  
fill ~17 ~3 ~22 ~17 ~3 ~19 cobblestone 0  
fill ~17 ~3 ~54 ~17 ~4 ~54 stone 5  
fill ~17 ~3 ~55 ~19 ~3 ~55 cobblestone 0  
fill ~17 ~3 ~56 ~20 ~3 ~56 stone 0  
fill ~17 ~3 ~57 ~18 ~3 ~57 stone 5 
setblock ~17 ~3 ~60 cobblestone 0 
setblock ~18 ~3 ~19 stone 0  
fill ~18 ~3 ~22 ~19 ~3 ~22 stone 0 
setblock ~18 ~3 ~54 cobblestone 0  
fill ~18 ~3 ~59 ~18 ~4 ~59 cobblestone 0  
fill ~19 ~3 ~20 ~19 ~3 ~21 stone 5 
setblock ~33 ~3 ~32 stone 5  
fill ~33 ~3 ~33 ~33 ~3 ~34 cobblestone 0  
fill ~34 ~3 ~29 ~34 ~3 ~31 stone 0 
setblock ~34 ~3 ~32 cobblestone 0 
setblock ~34 ~3 ~33 stone 5 
setblock ~34 ~3 ~34 cobblestone 0 
setblock ~34 ~3 ~35 stone 0  
fill ~35 ~3 ~28 ~35 ~3 ~29 cobblestone 0  
fill ~35 ~3 ~30 ~35 ~4 ~30 stone 5  
fill ~35 ~3 ~31 ~35 ~3 ~32 stone 0  
fill ~35 ~3 ~34 ~35 ~4 ~34 stone 0  
fill ~35 ~3 ~35 ~35 ~3 ~36 stone 5 
setblock ~36 ~3 ~27 cobblestone 0 
setblock ~36 ~3 ~28 stone 5 
setblock ~36 ~3 ~29 cobblestone 0  
fill ~36 ~3 ~31 ~36 ~3 ~32 cobblestone 0  
fill ~36 ~3 ~33 ~39 ~3 ~33 stone 5  
fill ~36 ~3 ~34 ~39 ~3 ~34 stone 5  
fill ~36 ~3 ~36 ~36 ~5 ~36 stone 0  
fill ~36 ~3 ~37 ~37 ~3 ~37 cobblestone 0 
setblock ~37 ~3 ~27 stone 5 
setblock ~37 ~3 ~28 cobblestone 0 
setblock ~37 ~3 ~29 stone 5  
fill ~37 ~3 ~31 ~37 ~5 ~31 stone 0 
setblock ~37 ~3 ~32 stone 5 
setblock ~37 ~3 ~35 stone 0 
setblock ~38 ~3 ~27 cobblestone 0 
setblock ~38 ~3 ~28 stone 5  
fill ~38 ~3 ~29 ~40 ~3 ~29 stone 0  
fill ~38 ~3 ~30 ~38 ~4 ~30 stone 5  
fill ~38 ~3 ~31 ~39 ~3 ~31 stone 5 
setblock ~38 ~3 ~32 stone 0 
setblock ~38 ~3 ~35 stone 5 
setblock ~38 ~3 ~36 stone 0 
setblock ~38 ~3 ~37 stone 5 
setblock ~39 ~3 ~27 stone 0  
fill ~39 ~3 ~28 ~40 ~3 ~28 cobblestone 0  
fill ~39 ~3 ~32 ~39 ~4 ~32 stone 5  
fill ~39 ~3 ~37 ~39 ~4 ~37 stone 0 
setblock ~40 ~3 ~27 cobblestone 0  
fill ~40 ~3 ~30 ~42 ~3 ~30 cobblestone 0  
fill ~40 ~3 ~31 ~40 ~3 ~32 stone 0  
fill ~40 ~3 ~33 ~40 ~2 ~33 cobblestone 0  
fill ~40 ~3 ~34 ~41 ~3 ~34 cobblestone 0  
fill ~40 ~3 ~35 ~41 ~3 ~35 stone 5 
setblock ~40 ~3 ~36 stone 0 
setblock ~40 ~3 ~37 cobblestone 0 
setblock ~40 ~3 ~39 stone 5 
setblock ~40 ~3 ~40 cobblestone 0 
setblock ~40 ~3 ~42 cobblestone 0 
setblock ~41 ~3 ~28 stone 0  
fill ~41 ~3 ~29 ~42 ~3 ~29 stone 5  
fill ~41 ~3 ~31 ~41 ~3 ~32 cobblestone 0 
setblock ~41 ~3 ~33 stone 5  
fill ~41 ~3 ~36 ~41 ~4 ~36 cobblestone 0  
fill ~42 ~3 ~31 ~43 ~3 ~31 stone 0  
fill ~42 ~3 ~34 ~42 ~2 ~34 stone 0 
setblock ~42 ~3 ~35 cobblestone 0 
setblock ~42 ~3 ~37 stone 5 
setblock ~43 ~3 ~32 stone 5  
fill ~43 ~3 ~34 ~43 ~4 ~34 cobblestone 0  
fill ~43 ~3 ~35 ~47 ~3 ~35 sea_lantern 0 
setblock ~43 ~3 ~36 cobblestone 0 
setblock ~43 ~3 ~44 cobblestone 0 
setblock ~44 ~3 ~30 cobblestone 0  
fill ~44 ~3 ~32 ~44 ~3 ~33 stone 0  
fill ~44 ~3 ~34 ~44 ~2 ~34 stone 5  
fill ~44 ~3 ~42 ~46 ~3 ~42 quartz_block 0 
setblock ~45 ~3 ~31 cobblestone 0 
setblock ~45 ~3 ~33 stone 0 
setblock ~45 ~3 ~45 stone 5 
setblock ~46 ~3 ~32 stone 5  
fill ~46 ~3 ~36 ~46 ~17 ~36 quartz_block 0 
setblock ~46 ~3 ~44 stone 5 
setblock ~47 ~3 ~32 cobblestone 0 
setblock ~47 ~3 ~37 ice 0 
setblock ~48 ~3 ~32 stone 5  
fill ~48 ~3 ~37 ~48 ~4 ~37 sea_lantern 0 
setblock ~48 ~3 ~43 stone 0  
fill ~49 ~3 ~33 ~49 ~2 ~33 stone 0  
fill ~49 ~3 ~43 ~49 ~4 ~43 stone 5 
setblock ~50 ~3 ~34 cobblestone 0  
fill ~50 ~3 ~41 ~50 ~4 ~41 stone 5  
fill ~50 ~3 ~42 ~50 ~4 ~42 stone 5 
setblock ~51 ~3 ~35 cobblestone 0 
setblock ~51 ~3 ~36 stone 0 
setblock ~51 ~3 ~40 stone 0 
setblock ~52 ~3 ~38 stone 5 
setblock ~52 ~3 ~39 stone 0  
fill ~58 ~3 ~58 ~59 ~3 ~58 stone 5  
fill ~58 ~3 ~59 ~58 ~4 ~59 cobblestone 0 
setblock ~59 ~3 ~55 cobblestone 0 
setblock ~59 ~3 ~57 stone 5  
fill ~59 ~3 ~59 ~59 ~3 ~60 stone 0  
fill ~60 ~3 ~19 ~60 ~4 ~19 cobblestone 0 
setblock ~60 ~3 ~57 stone 0 
setblock ~60 ~3 ~58 cobblestone 0  
fill ~60 ~3 ~60 ~60 ~3 ~61 stone 0  
fill ~61 ~3 ~53 ~61 ~4 ~53 cobblestone 0  
fill ~61 ~3 ~54 ~64 ~3 ~54 cobblestone 0  
fill ~61 ~3 ~55 ~62 ~3 ~55 stone 0  
fill ~61 ~3 ~56 ~62 ~3 ~56 cobblestone 0  
fill ~61 ~3 ~57 ~61 ~4 ~57 cobblestone 0 
setblock ~61 ~3 ~58 stone 5  
fill ~61 ~3 ~61 ~61 ~4 ~61 cobblestone 0 
setblock ~61 ~3 ~62 stone 5 
setblock ~62 ~3 ~52 stone 5  
fill ~62 ~3 ~53 ~62 ~5 ~53 stone 0 
setblock ~62 ~3 ~57 stone 0  
fill ~62 ~3 ~58 ~62 ~4 ~58 cobblestone 0  
fill ~62 ~3 ~60 ~62 ~4 ~60 stone 5  
fill ~62 ~3 ~61 ~62 ~3 ~60 stone 5 
setblock ~62 ~3 ~62 cobblestone 0 
setblock ~63 ~3 ~55 cobblestone 0  
fill ~63 ~3 ~56 ~64 ~3 ~56 stone 5  
fill ~63 ~3 ~57 ~63 ~3 ~56 stone 5  
fill ~63 ~3 ~58 ~63 ~2 ~58 stone 0 
setblock ~63 ~3 ~60 stone 0 
setblock ~64 ~3 ~55 stone 5 
setblock ~64 ~3 ~57 stone 0  
fill ~64 ~3 ~58 ~64 ~4 ~58 cobblestone 0 
setblock ~64 ~3 ~59 stone 5 
setblock ~64 ~3 ~60 cobblestone 0  
fill ~64 ~3 ~61 ~64 ~5 ~61 stone 0 
setblock ~65 ~3 ~55 cobblestone 0 
setblock ~65 ~3 ~56 stone 0  
fill ~65 ~3 ~57 ~65 ~4 ~57 cobblestone 0  
fill ~66 ~3 ~57 ~66 ~4 ~57 stone 5 
setblock ~66 ~3 ~58 stone 0  
fill ~12 ~4 ~20 ~12 ~2 ~20 cobblestone 0  
fill ~12 ~4 ~56 ~12 ~6 ~56 cobblestone 0  
fill ~13 ~4 ~19 ~13 ~5 ~19 cobblestone 0  
fill ~13 ~4 ~20 ~13 ~6 ~20 stone 5  
fill ~13 ~4 ~21 ~13 ~5 ~21 cobblestone 0  
fill ~13 ~4 ~56 ~16 ~4 ~56 stone 5  
fill ~14 ~4 ~19 ~15 ~4 ~19 stone 0  
fill ~14 ~4 ~20 ~15 ~4 ~20 cobblestone 0  
fill ~14 ~4 ~22 ~14 ~5 ~22 stone 0  
fill ~14 ~4 ~23 ~15 ~4 ~23 cobblestone 0 
setblock ~14 ~4 ~54 stone 0 
setblock ~14 ~4 ~57 stone 0  
fill ~14 ~4 ~58 ~14 ~4 ~59 cobblestone 0  
fill ~15 ~4 ~18 ~17 ~4 ~18 stone 0  
fill ~15 ~4 ~21 ~15 ~5 ~21 stone 0 
setblock ~15 ~4 ~22 stone 5 
setblock ~15 ~4 ~53 stone 0  
fill ~15 ~4 ~54 ~15 ~4 ~55 cobblestone 0  
fill ~15 ~4 ~59 ~15 ~5 ~59 stone 0 
setblock ~16 ~4 ~20 stone 0  
fill ~16 ~4 ~21 ~16 ~4 ~22 cobblestone 0  
fill ~16 ~4 ~23 ~16 ~3 ~23 stone 0  
fill ~16 ~4 ~52 ~16 ~5 ~52 stone 5  
fill ~16 ~4 ~53 ~17 ~4 ~53 stone 5  
fill ~16 ~4 ~54 ~16 ~4 ~56 stone 5  
fill ~16 ~4 ~58 ~18 ~4 ~58 stone 0  
fill ~16 ~4 ~59 ~16 ~5 ~59 cobblestone 0 
setblock ~17 ~4 ~19 stone 0  
fill ~17 ~4 ~20 ~18 ~4 ~20 stone 5  
fill ~17 ~4 ~21 ~17 ~6 ~21 stone 0  
fill ~17 ~4 ~22 ~17 ~4 ~21 stone 0  
fill ~17 ~4 ~23 ~17 ~7 ~23 cobblestone 0  
fill ~17 ~4 ~24 ~17 ~8 ~24 cobblestone 0  
fill ~17 ~4 ~55 ~17 ~5 ~55 stone 5  
fill ~17 ~4 ~56 ~19 ~4 ~56 stone 0  
fill ~17 ~4 ~57 ~17 ~4 ~56 stone 0 
setblock ~17 ~4 ~59 stone 0 
setblock ~17 ~4 ~60 stone 5 
setblock ~18 ~4 ~19 stone 5  
fill ~18 ~4 ~21 ~18 ~4 ~22 cobblestone 0 
setblock ~18 ~4 ~53 stone 0  
fill ~18 ~4 ~54 ~18 ~5 ~54 stone 5 
setblock ~18 ~4 ~55 cobblestone 0  
fill ~18 ~4 ~57 ~18 ~5 ~57 cobblestone 0 
setblock ~19 ~4 ~20 stone 0  
fill ~19 ~4 ~21 ~19 ~5 ~21 stone 5 
setblock ~19 ~4 ~54 cobblestone 0  
fill ~19 ~4 ~55 ~19 ~8 ~55 stone 5 
setblock ~19 ~4 ~57 stone 5  
fill ~19 ~4 ~58 ~19 ~5 ~58 cobblestone 0  
fill ~19 ~4 ~59 ~19 ~5 ~59 cobblestone 0  
fill ~20 ~4 ~55 ~20 ~5 ~55 cobblestone 0  
fill ~20 ~4 ~56 ~20 ~4 ~57 cobblestone 0 
setblock ~33 ~4 ~32 cobblestone 0  
fill ~33 ~4 ~33 ~34 ~4 ~33 stone 0  
fill ~34 ~4 ~29 ~35 ~4 ~29 stone 5 
setblock ~34 ~4 ~30 cobblestone 0  
fill ~34 ~4 ~31 ~36 ~4 ~31 stone 5 
setblock ~34 ~4 ~32 stone 0  
fill ~34 ~4 ~34 ~34 ~6 ~34 stone 5  
fill ~34 ~4 ~35 ~34 ~5 ~35 stone 5 
setblock ~35 ~4 ~28 stone 0 
setblock ~35 ~4 ~32 stone 5 
setblock ~35 ~4 ~33 cobblestone 0  
fill ~35 ~4 ~35 ~35 ~5 ~35 stone 0 
setblock ~35 ~4 ~36 cobblestone 0 
setblock ~36 ~4 ~28 cobblestone 0  
fill ~36 ~4 ~29 ~37 ~4 ~29 stone 0 
setblock ~36 ~4 ~32 stone 0  
fill ~36 ~4 ~33 ~37 ~4 ~33 stone 5  
fill ~36 ~4 ~34 ~37 ~4 ~34 stone 0 
setblock ~36 ~4 ~35 cobblestone 0  
fill ~36 ~4 ~37 ~37 ~4 ~37 cobblestone 0 
setblock ~37 ~4 ~27 cobblestone 0  
fill ~37 ~4 ~28 ~37 ~5 ~28 stone 5  
fill ~37 ~4 ~32 ~38 ~4 ~32 cobblestone 0  
fill ~37 ~4 ~35 ~37 ~6 ~35 stone 5 
setblock ~37 ~4 ~36 stone 0  
fill ~38 ~4 ~27 ~38 ~4 ~28 stone 0  
fill ~38 ~4 ~29 ~38 ~6 ~29 stone 5  
fill ~38 ~4 ~31 ~38 ~5 ~31 cobblestone 0  
fill ~38 ~4 ~33 ~38 ~5 ~33 stone 0  
fill ~38 ~4 ~34 ~39 ~4 ~34 cobblestone 0  
fill ~38 ~4 ~35 ~40 ~4 ~35 stone 0 
setblock ~38 ~4 ~36 cobblestone 0  
fill ~38 ~4 ~37 ~38 ~5 ~37 stone 0  
fill ~39 ~4 ~27 ~39 ~4 ~28 stone 5  
fill ~39 ~4 ~29 ~42 ~4 ~29 stone 0  
fill ~39 ~4 ~30 ~40 ~4 ~30 stone 0  
fill ~39 ~4 ~31 ~41 ~4 ~31 stone 5 
setblock ~39 ~4 ~36 stone 0 
setblock ~40 ~4 ~28 stone 0 
setblock ~40 ~4 ~32 stone 5  
fill ~40 ~4 ~33 ~42 ~4 ~33 stone 0  
fill ~40 ~4 ~34 ~40 ~5 ~34 stone 0  
fill ~40 ~4 ~36 ~40 ~5 ~36 stone 5 
setblock ~40 ~4 ~39 stone 0  
fill ~40 ~4 ~40 ~40 ~4 ~41 stone 5 
setblock ~40 ~4 ~42 stone 0 
setblock ~41 ~4 ~28 stone 5  
fill ~41 ~4 ~30 ~43 ~4 ~30 stone 5 
setblock ~41 ~4 ~32 stone 0  
fill ~41 ~4 ~34 ~42 ~4 ~34 stone 5 
setblock ~41 ~4 ~35 cobblestone 0  
fill ~41 ~4 ~42 ~41 ~5 ~42 stone 5  
fill ~41 ~4 ~43 ~41 ~5 ~43 cobblestone 0  
fill ~42 ~4 ~31 ~42 ~2 ~31 stone 0 
setblock ~42 ~4 ~35 stone 0 
setblock ~42 ~4 ~43 stone 0  
fill ~43 ~4 ~31 ~43 ~5 ~31 stone 5  
fill ~43 ~4 ~32 ~43 ~7 ~32 stone 0  
fill ~43 ~4 ~35 ~47 ~4 ~35 sea_lantern 0 
setblock ~43 ~4 ~44 stone 5 
setblock ~44 ~4 ~31 stone 0  
fill ~44 ~4 ~32 ~44 ~8 ~32 stone 5 
setblock ~44 ~4 ~33 cobblestone 0  
fill ~44 ~4 ~42 ~46 ~4 ~42 quartz_block 0 
setblock ~44 ~4 ~44 stone 0 
setblock ~45 ~4 ~31 stone 5  
fill ~45 ~4 ~45 ~46 ~4 ~45 cobblestone 0  
fill ~46 ~4 ~32 ~48 ~4 ~32 stone 0  
fill ~47 ~4 ~37 ~47 ~18 ~37 quartz_block 0 
setblock ~47 ~4 ~44 stone 0 
setblock ~48 ~4 ~38 ice 0 
setblock ~48 ~4 ~43 stone 5 
setblock ~49 ~4 ~33 stone 5 
setblock ~49 ~4 ~42 stone 0 
setblock ~50 ~4 ~34 stone 5 
setblock ~51 ~4 ~35 stone 5  
fill ~51 ~4 ~36 ~51 ~6 ~36 cobblestone 0 
setblock ~51 ~4 ~39 stone 5 
setblock ~51 ~4 ~40 cobblestone 0  
fill ~52 ~4 ~37 ~52 ~4 ~38 stone 0 
setblock ~58 ~4 ~56 stone 5 
setblock ~58 ~4 ~58 stone 0  
fill ~59 ~4 ~54 ~60 ~4 ~54 stone 0  
fill ~59 ~4 ~55 ~60 ~4 ~55 stone 0  
fill ~59 ~4 ~56 ~59 ~4 ~59 cobblestone 0 
setblock ~59 ~4 ~60 stone 5 
setblock ~60 ~4 ~53 cobblestone 0  
fill ~60 ~4 ~57 ~60 ~6 ~57 stone 5  
fill ~60 ~4 ~58 ~61 ~4 ~58 stone 0  
fill ~60 ~4 ~60 ~60 ~4 ~61 cobblestone 0  
fill ~61 ~4 ~54 ~61 ~5 ~54 cobblestone 0  
fill ~61 ~4 ~55 ~61 ~7 ~55 cobblestone 0  
fill ~61 ~4 ~56 ~62 ~4 ~56 stone 0 
setblock ~61 ~4 ~60 stone 5 
setblock ~62 ~4 ~52 cobblestone 0 
setblock ~62 ~4 ~54 stone 0  
fill ~62 ~4 ~55 ~63 ~4 ~55 stone 5 
setblock ~62 ~4 ~57 stone 5 
setblock ~62 ~4 ~61 cobblestone 0  
fill ~63 ~4 ~54 ~64 ~4 ~54 stone 5 
setblock ~63 ~4 ~56 cobblestone 0 
setblock ~63 ~4 ~57 stone 0 
setblock ~63 ~4 ~58 cobblestone 0  
fill ~63 ~4 ~60 ~63 ~5 ~60 cobblestone 0 
setblock ~64 ~4 ~55 cobblestone 0  
fill ~64 ~4 ~56 ~64 ~5 ~56 stone 5  
fill ~64 ~4 ~57 ~64 ~8 ~57 cobblestone 0  
fill ~64 ~4 ~59 ~64 ~6 ~59 stone 0 
setblock ~64 ~4 ~60 stone 5  
fill ~65 ~4 ~54 ~65 ~5 ~54 cobblestone 0 
setblock ~65 ~4 ~55 stone 0  
fill ~65 ~4 ~56 ~65 ~5 ~56 cobblestone 0 
setblock ~65 ~4 ~59 cobblestone 0 
setblock ~66 ~4 ~56 stone 5  
fill ~66 ~4 ~58 ~66 ~5 ~58 stone 5  
fill ~13 ~5 ~55 ~17 ~5 ~55 stone 5 
setblock ~13 ~5 ~56 cobblestone 0  
fill ~14 ~5 ~19 ~14 ~3 ~19 stone 0  
fill ~14 ~5 ~20 ~14 ~4 ~20 cobblestone 0 
setblock ~14 ~5 ~23 stone 5  
fill ~14 ~5 ~54 ~14 ~6 ~54 cobblestone 0  
fill ~14 ~5 ~56 ~14 ~6 ~56 stone 0 
setblock ~14 ~5 ~57 cobblestone 0 
setblock ~14 ~5 ~58 stone 0 
setblock ~14 ~5 ~59 stone 5  
fill ~15 ~5 ~18 ~16 ~5 ~18 stone 5  
fill ~15 ~5 ~19 ~15 ~5 ~20 stone 5 
setblock ~15 ~5 ~22 cobblestone 0 
setblock ~15 ~5 ~23 stone 0  
fill ~15 ~5 ~52 ~15 ~5 ~53 cobblestone 0  
fill ~15 ~5 ~54 ~15 ~7 ~54 stone 5 
setblock ~15 ~5 ~56 cobblestone 0  
fill ~15 ~5 ~57 ~16 ~5 ~57 stone 0  
fill ~15 ~5 ~58 ~16 ~5 ~58 stone 5  
fill ~16 ~5 ~19 ~16 ~6 ~19 cobblestone 0  
fill ~16 ~5 ~20 ~16 ~5 ~21 stone 5  
fill ~16 ~5 ~22 ~16 ~7 ~22 stone 0 
setblock ~16 ~5 ~23 cobblestone 0  
fill ~16 ~5 ~53 ~16 ~5 ~54 stone 0 
setblock ~17 ~5 ~19 stone 5  
fill ~17 ~5 ~20 ~18 ~5 ~20 cobblestone 0 
setblock ~17 ~5 ~22 stone 5  
fill ~17 ~5 ~53 ~18 ~5 ~53 cobblestone 0 
setblock ~17 ~5 ~54 stone 0  
fill ~17 ~5 ~56 ~17 ~6 ~56 stone 0  
fill ~17 ~5 ~57 ~17 ~5 ~58 cobblestone 0  
fill ~17 ~5 ~59 ~18 ~5 ~59 stone 5 
setblock ~17 ~5 ~60 cobblestone 0  
fill ~18 ~5 ~19 ~18 ~6 ~19 stone 0 
setblock ~18 ~5 ~21 stone 5 
setblock ~18 ~5 ~22 stone 0  
fill ~18 ~5 ~23 ~18 ~6 ~23 stone 5  
fill ~18 ~5 ~55 ~18 ~6 ~55 stone 0  
fill ~18 ~5 ~56 ~19 ~5 ~56 cobblestone 0  
fill ~19 ~5 ~20 ~19 ~7 ~20 stone 5  
fill ~19 ~5 ~54 ~20 ~5 ~54 stone 0  
fill ~19 ~5 ~57 ~20 ~5 ~57 cobblestone 0 
setblock ~20 ~5 ~56 stone 0  
fill ~33 ~5 ~32 ~34 ~5 ~32 stone 5  
fill ~33 ~5 ~33 ~33 ~5 ~32 stone 5  
fill ~34 ~5 ~30 ~35 ~5 ~30 stone 0  
fill ~34 ~5 ~31 ~34 ~6 ~31 stone 0 
setblock ~34 ~5 ~33 cobblestone 0  
fill ~35 ~5 ~29 ~35 ~6 ~29 cobblestone 0  
fill ~35 ~5 ~31 ~36 ~5 ~31 stone 5  
fill ~35 ~5 ~32 ~38 ~5 ~32 cobblestone 0  
fill ~35 ~5 ~33 ~36 ~5 ~33 stone 0  
fill ~35 ~5 ~34 ~36 ~5 ~34 stone 5 
setblock ~35 ~5 ~36 stone 5 
setblock ~36 ~5 ~28 stone 0  
fill ~36 ~5 ~29 ~36 ~5 ~31 stone 5 
setblock ~36 ~5 ~35 stone 5  
fill ~36 ~5 ~37 ~38 ~5 ~37 stone 0 
setblock ~37 ~5 ~29 cobblestone 0 
setblock ~37 ~5 ~33 stone 5 
setblock ~37 ~5 ~34 stone 0  
fill ~37 ~5 ~36 ~40 ~5 ~36 stone 5  
fill ~38 ~5 ~27 ~38 ~6 ~27 stone 5 
setblock ~38 ~5 ~28 stone 0 
setblock ~38 ~5 ~30 cobblestone 0  
fill ~38 ~5 ~34 ~38 ~4 ~34 cobblestone 0  
fill ~38 ~5 ~35 ~40 ~5 ~35 cobblestone 0 
setblock ~39 ~5 ~27 stone 0 
setblock ~39 ~5 ~28 cobblestone 0  
fill ~39 ~5 ~29 ~40 ~5 ~29 stone 5  
fill ~39 ~5 ~30 ~39 ~6 ~30 stone 0 
setblock ~39 ~5 ~31 cobblestone 0  
fill ~39 ~5 ~32 ~39 ~7 ~32 stone 0 
setblock ~39 ~5 ~34 stone 0 
setblock ~39 ~5 ~37 cobblestone 0  
fill ~39 ~5 ~39 ~39 ~6 ~39 cobblestone 0  
fill ~39 ~5 ~58 ~39 ~6 ~58 stone 5  
fill ~40 ~5 ~27 ~40 ~6 ~27 cobblestone 0 
setblock ~40 ~5 ~28 stone 5  
fill ~40 ~5 ~30 ~40 ~5 ~31 stone 5 
setblock ~40 ~5 ~32 cobblestone 0  
fill ~40 ~5 ~33 ~40 ~4 ~33 stone 0  
fill ~40 ~5 ~37 ~40 ~7 ~37 stone 0 
setblock ~40 ~5 ~39 stone 5  
fill ~40 ~5 ~40 ~40 ~5 ~41 stone 0 
setblock ~40 ~5 ~42 cobblestone 0  
fill ~41 ~5 ~28 ~41 ~5 ~29 stone 0  
fill ~41 ~5 ~30 ~41 ~6 ~30 cobblestone 0  
fill ~41 ~5 ~31 ~42 ~5 ~31 cobblestone 0 
setblock ~41 ~5 ~32 stone 5 
setblock ~41 ~5 ~33 cobblestone 0 
setblock ~41 ~5 ~34 stone 0 
setblock ~41 ~5 ~35 stone 5  
fill ~41 ~5 ~36 ~41 ~9 ~36 stone 0  
fill ~42 ~5 ~28 ~42 ~5 ~29 stone 5 
setblock ~42 ~5 ~30 stone 0 
setblock ~42 ~5 ~33 stone 0  
fill ~42 ~5 ~34 ~42 ~7 ~34 cobblestone 0  
fill ~42 ~5 ~35 ~42 ~5 ~34 cobblestone 0  
fill ~42 ~5 ~44 ~42 ~7 ~44 cobblestone 0  
fill ~43 ~5 ~29 ~43 ~6 ~29 cobblestone 0  
fill ~43 ~5 ~30 ~43 ~5 ~29 cobblestone 0 
setblock ~43 ~5 ~33 cobblestone 0 
setblock ~43 ~5 ~34 stone 0  
fill ~43 ~5 ~35 ~47 ~5 ~35 sea_lantern 0 
setblock ~43 ~5 ~44 stone 0  
fill ~44 ~5 ~31 ~44 ~6 ~31 stone 5  
fill ~44 ~5 ~33 ~44 ~6 ~33 stone 0  
fill ~44 ~5 ~42 ~46 ~5 ~42 quartz_block 0  
fill ~44 ~5 ~44 ~44 ~5 ~45 cobblestone 0 
setblock ~45 ~5 ~31 cobblestone 0  
fill ~45 ~5 ~32 ~46 ~5 ~32 stone 0  
fill ~45 ~5 ~45 ~45 ~4 ~45 cobblestone 0  
fill ~45 ~5 ~46 ~45 ~7 ~46 cobblestone 0 
setblock ~46 ~5 ~45 stone 5 
setblock ~47 ~5 ~32 cobblestone 0 
setblock ~47 ~5 ~44 cobblestone 0  
fill ~48 ~5 ~33 ~48 ~7 ~33 cobblestone 0  
fill ~48 ~5 ~38 ~48 ~19 ~38 quartz_block 0 
setblock ~48 ~5 ~39 ice 0 
setblock ~48 ~5 ~43 cobblestone 0  
fill ~48 ~5 ~44 ~48 ~7 ~44 stone 0 
setblock ~49 ~5 ~33 stone 0 
setblock ~49 ~5 ~34 stone 5 
setblock ~49 ~5 ~42 cobblestone 0 
setblock ~49 ~5 ~43 stone 0 
setblock ~50 ~5 ~35 stone 5 
setblock ~50 ~5 ~41 cobblestone 0 
setblock ~51 ~5 ~35 cobblestone 0 
setblock ~51 ~5 ~39 cobblestone 0 
setblock ~51 ~5 ~40 stone 5 
setblock ~51 ~5 ~41 stone 0 
setblock ~52 ~5 ~37 cobblestone 0 
setblock ~52 ~5 ~38 stone 0  
fill ~58 ~5 ~55 ~59 ~5 ~55 stone 5  
fill ~58 ~5 ~56 ~63 ~5 ~56 stone 0  
fill ~58 ~5 ~57 ~59 ~5 ~57 stone 0  
fill ~58 ~5 ~58 ~61 ~5 ~58 cobblestone 0 
setblock ~58 ~5 ~59 stone 0  
fill ~59 ~5 ~54 ~59 ~4 ~54 stone 0 
setblock ~59 ~5 ~59 stone 5 
setblock ~59 ~5 ~60 cobblestone 0 
setblock ~60 ~5 ~18 stone 0 
setblock ~60 ~5 ~19 stone 5  
fill ~60 ~5 ~53 ~62 ~5 ~53 stone 0 
setblock ~60 ~5 ~54 stone 5 
setblock ~60 ~5 ~55 stone 0  
fill ~60 ~5 ~59 ~61 ~5 ~59 cobblestone 0  
fill ~60 ~5 ~60 ~61 ~5 ~60 stone 0 
setblock ~60 ~5 ~61 cobblestone 0  
fill ~61 ~5 ~57 ~62 ~5 ~57 stone 0  
fill ~61 ~5 ~61 ~61 ~6 ~61 stone 0 
setblock ~62 ~5 ~52 stone 0 
setblock ~62 ~5 ~54 cobblestone 0  
fill ~62 ~5 ~55 ~64 ~5 ~55 stone 0  
fill ~62 ~5 ~58 ~63 ~5 ~58 stone 0  
fill ~62 ~5 ~59 ~63 ~5 ~59 stone 5  
fill ~62 ~5 ~60 ~62 ~6 ~60 cobblestone 0  
fill ~62 ~5 ~61 ~63 ~5 ~61 stone 5 
setblock ~63 ~5 ~52 stone 5  
fill ~63 ~5 ~53 ~64 ~5 ~53 cobblestone 0 
setblock ~63 ~5 ~54 stone 0  
fill ~63 ~5 ~57 ~63 ~6 ~57 cobblestone 0 
setblock ~64 ~5 ~54 stone 5  
fill ~64 ~5 ~58 ~64 ~6 ~58 stone 5  
fill ~64 ~5 ~60 ~64 ~6 ~60 cobblestone 0  
fill ~65 ~5 ~55 ~66 ~5 ~55 stone 5  
fill ~65 ~5 ~57 ~65 ~7 ~57 stone 5  
fill ~65 ~5 ~58 ~65 ~6 ~58 cobblestone 0  
fill ~65 ~5 ~59 ~65 ~6 ~59 stone 5 
setblock ~65 ~5 ~60 stone 0  
fill ~66 ~5 ~56 ~66 ~5 ~57 stone 0 
setblock ~13 ~6 ~21 stone 0  
fill ~13 ~6 ~55 ~14 ~6 ~55 cobblestone 0 
setblock ~13 ~6 ~56 stone 5  
fill ~14 ~6 ~19 ~16 ~6 ~19 cobblestone 0 
setblock ~14 ~6 ~20 stone 5  
fill ~14 ~6 ~21 ~15 ~6 ~21 cobblestone 0 
setblock ~14 ~6 ~22 stone 5 
setblock ~14 ~6 ~23 cobblestone 0  
fill ~14 ~6 ~57 ~16 ~6 ~57 stone 5  
fill ~14 ~6 ~58 ~14 ~6 ~57 stone 5 
setblock ~15 ~6 ~18 cobblestone 0  
fill ~15 ~6 ~20 ~15 ~8 ~20 stone 0  
fill ~15 ~6 ~22 ~15 ~8 ~22 stone 0 
setblock ~15 ~6 ~23 stone 5  
fill ~15 ~6 ~53 ~18 ~6 ~53 stone 5  
fill ~15 ~6 ~55 ~16 ~6 ~55 stone 0 
setblock ~15 ~6 ~56 stone 5 
setblock ~15 ~6 ~58 cobblestone 0 
setblock ~16 ~6 ~18 stone 0 
setblock ~16 ~6 ~20 cobblestone 0 
setblock ~16 ~6 ~21 stone 5 
setblock ~16 ~6 ~23 stone 0  
fill ~16 ~6 ~52 ~17 ~6 ~52 cobblestone 0  
fill ~16 ~6 ~54 ~16 ~7 ~54 stone 0  
fill ~16 ~6 ~56 ~16 ~7 ~56 cobblestone 0 
setblock ~16 ~6 ~58 stone 0  
fill ~16 ~6 ~59 ~17 ~6 ~59 stone 5 
setblock ~17 ~6 ~19 stone 0 
setblock ~17 ~6 ~20 stone 5  
fill ~17 ~6 ~22 ~18 ~6 ~22 cobblestone 0 
setblock ~17 ~6 ~54 stone 5 
setblock ~17 ~6 ~55 cobblestone 0  
fill ~17 ~6 ~57 ~17 ~7 ~57 stone 0  
fill ~17 ~6 ~58 ~18 ~6 ~58 cobblestone 0 
setblock ~18 ~6 ~20 stone 0  
fill ~18 ~6 ~21 ~19 ~6 ~21 cobblestone 0  
fill ~18 ~6 ~54 ~18 ~9 ~54 stone 0  
fill ~18 ~6 ~56 ~19 ~6 ~56 stone 0  
fill ~18 ~6 ~57 ~18 ~8 ~57 stone 5 
setblock ~18 ~6 ~59 stone 0  
fill ~19 ~6 ~53 ~19 ~6 ~54 cobblestone 0  
fill ~19 ~6 ~57 ~19 ~5 ~57 cobblestone 0  
fill ~19 ~6 ~58 ~19 ~6 ~59 stone 5 
setblock ~20 ~6 ~54 stone 0  
fill ~20 ~6 ~55 ~20 ~7 ~55 stone 5  
fill ~20 ~6 ~56 ~21 ~6 ~56 cobblestone 0  
fill ~20 ~6 ~57 ~20 ~6 ~58 stone 0  
fill ~33 ~6 ~33 ~34 ~6 ~33 stone 0 
setblock ~33 ~6 ~34 cobblestone 0 
setblock ~34 ~6 ~30 stone 5  
fill ~34 ~6 ~32 ~34 ~7 ~32 stone 5 
setblock ~34 ~6 ~35 stone 0  
fill ~35 ~6 ~30 ~37 ~6 ~30 cobblestone 0  
fill ~35 ~6 ~31 ~35 ~6 ~32 stone 0 
setblock ~35 ~6 ~33 cobblestone 0  
fill ~35 ~6 ~34 ~36 ~6 ~34 stone 0 
setblock ~35 ~6 ~35 stone 5 
setblock ~35 ~6 ~36 cobblestone 0  
fill ~35 ~6 ~37 ~35 ~8 ~37 stone 0  
fill ~36 ~6 ~28 ~36 ~6 ~30 cobblestone 0 
setblock ~36 ~6 ~31 stone 5 
setblock ~36 ~6 ~32 cobblestone 0  
fill ~36 ~6 ~33 ~37 ~6 ~33 stone 0 
setblock ~36 ~6 ~35 cobblestone 0  
fill ~36 ~6 ~36 ~36 ~8 ~36 stone 5  
fill ~36 ~6 ~37 ~36 ~6 ~36 stone 5  
fill ~37 ~6 ~27 ~37 ~7 ~27 stone 0  
fill ~37 ~6 ~28 ~37 ~6 ~27 stone 0 
setblock ~37 ~6 ~29 stone 5 
setblock ~37 ~6 ~31 cobblestone 0 
setblock ~37 ~6 ~32 stone 0 
setblock ~37 ~6 ~34 cobblestone 0  
fill ~37 ~6 ~36 ~38 ~6 ~36 stone 0  
fill ~37 ~6 ~37 ~37 ~9 ~37 stone 0 
setblock ~38 ~6 ~28 stone 5  
fill ~38 ~6 ~30 ~38 ~6 ~31 stone 0  
fill ~38 ~6 ~32 ~38 ~9 ~32 cobblestone 0  
fill ~38 ~6 ~33 ~40 ~6 ~33 cobblestone 0  
fill ~38 ~6 ~34 ~39 ~6 ~34 stone 5  
fill ~38 ~6 ~35 ~39 ~6 ~35 stone 0  
fill ~38 ~6 ~37 ~38 ~8 ~37 stone 5  
fill ~38 ~6 ~38 ~39 ~6 ~38 stone 0  
fill ~39 ~6 ~27 ~39 ~8 ~27 stone 5 
setblock ~39 ~6 ~28 stone 0  
fill ~39 ~6 ~29 ~42 ~6 ~29 stone 5  
fill ~39 ~6 ~31 ~41 ~6 ~31 stone 5 
setblock ~39 ~6 ~36 stone 5 
setblock ~39 ~6 ~37 stone 0 
setblock ~39 ~6 ~40 cobblestone 0 
setblock ~40 ~6 ~28 cobblestone 0  
fill ~40 ~6 ~30 ~40 ~9 ~30 cobblestone 0  
fill ~40 ~6 ~32 ~43 ~6 ~32 stone 0  
fill ~40 ~6 ~34 ~43 ~6 ~34 cobblestone 0  
fill ~40 ~6 ~35 ~41 ~6 ~35 cobblestone 0  
fill ~40 ~6 ~36 ~40 ~7 ~36 stone 0 
setblock ~40 ~6 ~38 stone 5 
setblock ~40 ~6 ~41 cobblestone 0 
setblock ~40 ~6 ~42 stone 5 
setblock ~40 ~6 ~43 cobblestone 0 
setblock ~41 ~6 ~27 stone 0 
setblock ~41 ~6 ~28 stone 5 
setblock ~41 ~6 ~33 stone 0 
setblock ~41 ~6 ~43 stone 0  
fill ~42 ~6 ~28 ~42 ~7 ~28 stone 0  
fill ~42 ~6 ~30 ~42 ~8 ~30 stone 5  
fill ~42 ~6 ~31 ~43 ~6 ~31 stone 0 
setblock ~42 ~6 ~33 cobblestone 0 
setblock ~42 ~6 ~35 stone 0  
fill ~43 ~6 ~30 ~43 ~7 ~30 stone 0 
setblock ~43 ~6 ~33 stone 5  
fill ~43 ~6 ~35 ~47 ~6 ~35 sea_lantern 0  
fill ~43 ~6 ~45 ~44 ~6 ~45 cobblestone 0 
setblock ~44 ~6 ~30 stone 5  
fill ~44 ~6 ~34 ~44 ~9 ~34 stone 0  
fill ~44 ~6 ~42 ~46 ~6 ~42 quartz_block 0 
setblock ~45 ~6 ~31 stone 5 
setblock ~45 ~6 ~32 cobblestone 0  
fill ~45 ~6 ~45 ~46 ~6 ~45 stone 0  
fill ~46 ~6 ~32 ~47 ~6 ~32 stone 5 
setblock ~47 ~6 ~44 stone 0 
setblock ~47 ~6 ~45 cobblestone 0  
fill ~48 ~6 ~39 ~48 ~20 ~39 quartz_block 0 
setblock ~48 ~6 ~40 ice 0  
fill ~48 ~6 ~41 ~48 ~7 ~41 sea_lantern 0 
setblock ~49 ~6 ~34 cobblestone 0 
setblock ~49 ~6 ~42 stone 5 
setblock ~49 ~6 ~43 cobblestone 0 
setblock ~50 ~6 ~35 cobblestone 0 
setblock ~50 ~6 ~41 stone 0 
setblock ~51 ~6 ~37 stone 5 
setblock ~51 ~6 ~39 stone 0 
setblock ~51 ~6 ~40 cobblestone 0 
setblock ~51 ~6 ~41 stone 5  
fill ~52 ~6 ~38 ~52 ~9 ~38 cobblestone 0  
fill ~58 ~6 ~55 ~58 ~5 ~55 stone 5 
setblock ~58 ~6 ~56 cobblestone 0  
fill ~58 ~6 ~57 ~60 ~6 ~57 stone 5  
fill ~58 ~6 ~58 ~58 ~7 ~58 cobblestone 0 
setblock ~58 ~6 ~59 stone 5  
fill ~59 ~6 ~19 ~60 ~6 ~19 stone 0  
fill ~59 ~6 ~54 ~59 ~7 ~54 stone 5  
fill ~59 ~6 ~55 ~63 ~6 ~55 cobblestone 0 
setblock ~59 ~6 ~56 stone 5  
fill ~59 ~6 ~58 ~59 ~8 ~58 stone 0  
fill ~59 ~6 ~59 ~59 ~6 ~58 stone 0  
fill ~59 ~6 ~60 ~60 ~6 ~60 stone 5 
setblock ~60 ~6 ~18 cobblestone 0  
fill ~60 ~6 ~53 ~64 ~6 ~53 stone 5 
setblock ~60 ~6 ~54 cobblestone 0  
fill ~60 ~6 ~56 ~64 ~6 ~56 cobblestone 0  
fill ~60 ~6 ~58 ~62 ~6 ~58 stone 5  
fill ~60 ~6 ~59 ~60 ~6 ~57 stone 5 
setblock ~61 ~6 ~54 stone 0  
fill ~61 ~6 ~57 ~61 ~7 ~57 stone 0  
fill ~61 ~6 ~59 ~61 ~9 ~59 stone 0  
fill ~61 ~6 ~60 ~61 ~7 ~60 stone 0  
fill ~62 ~6 ~52 ~62 ~7 ~52 stone 5 
setblock ~62 ~6 ~54 stone 5  
fill ~62 ~6 ~57 ~62 ~8 ~57 stone 5  
fill ~62 ~6 ~59 ~63 ~6 ~59 stone 5  
fill ~62 ~6 ~61 ~62 ~7 ~61 stone 0  
fill ~63 ~6 ~52 ~63 ~7 ~52 stone 0 
setblock ~63 ~6 ~54 cobblestone 0  
fill ~63 ~6 ~58 ~63 ~7 ~58 stone 0  
fill ~63 ~6 ~60 ~63 ~7 ~60 stone 0 
setblock ~63 ~6 ~61 cobblestone 0  
fill ~64 ~6 ~54 ~64 ~6 ~55 stone 0  
fill ~65 ~6 ~54 ~65 ~13 ~54 stone 5  
fill ~65 ~6 ~55 ~65 ~5 ~55 stone 5 
setblock ~65 ~6 ~56 stone 0 
setblock ~65 ~6 ~60 stone 5 
setblock ~66 ~6 ~56 stone 5  
fill ~66 ~6 ~57 ~66 ~9 ~57 cobblestone 0 
setblock ~12 ~7 ~56 stone 5 
setblock ~13 ~7 ~21 cobblestone 0  
fill ~13 ~7 ~22 ~13 ~9 ~22 stone 5 
setblock ~13 ~7 ~55 stone 5 
setblock ~13 ~7 ~56 stone 0  
fill ~14 ~7 ~19 ~14 ~6 ~19 cobblestone 0  
fill ~14 ~7 ~20 ~14 ~7 ~23 stone 0 
setblock ~14 ~7 ~54 stone 5  
fill ~14 ~7 ~55 ~15 ~7 ~55 cobblestone 0  
fill ~14 ~7 ~56 ~14 ~9 ~56 stone 5  
fill ~14 ~7 ~57 ~14 ~7 ~56 stone 5 
setblock ~14 ~7 ~58 cobblestone 0  
fill ~15 ~7 ~19 ~16 ~7 ~19 stone 5  
fill ~15 ~7 ~21 ~17 ~7 ~21 cobblestone 0  
fill ~15 ~7 ~23 ~17 ~7 ~23 cobblestone 0 
setblock ~15 ~7 ~53 cobblestone 0  
fill ~15 ~7 ~56 ~15 ~8 ~56 stone 0  
fill ~15 ~7 ~57 ~16 ~7 ~57 cobblestone 0  
fill ~15 ~7 ~58 ~16 ~7 ~58 stone 5 
setblock ~16 ~7 ~18 stone 5 
setblock ~16 ~7 ~20 stone 5  
fill ~16 ~7 ~24 ~16 ~9 ~24 stone 5  
fill ~16 ~7 ~52 ~16 ~11 ~52 stone 0  
fill ~16 ~7 ~53 ~17 ~7 ~53 stone 0 
setblock ~16 ~7 ~55 stone 0 
setblock ~16 ~7 ~59 cobblestone 0  
fill ~17 ~7 ~19 ~17 ~7 ~21 cobblestone 0 
setblock ~17 ~7 ~22 stone 0  
fill ~17 ~7 ~52 ~17 ~10 ~52 cobblestone 0 
setblock ~17 ~7 ~54 stone 0  
fill ~17 ~7 ~55 ~20 ~7 ~55 stone 5  
fill ~17 ~7 ~56 ~17 ~8 ~56 stone 5  
fill ~17 ~7 ~58 ~17 ~5 ~58 cobblestone 0 
setblock ~17 ~7 ~59 stone 5  
fill ~18 ~7 ~19 ~18 ~7 ~21 stone 5  
fill ~18 ~7 ~22 ~19 ~7 ~22 cobblestone 0 
setblock ~18 ~7 ~23 stone 0 
setblock ~18 ~7 ~52 stone 5 
setblock ~18 ~7 ~53 cobblestone 0  
fill ~18 ~7 ~56 ~19 ~7 ~56 cobblestone 0  
fill ~18 ~7 ~58 ~18 ~8 ~58 stone 0 
setblock ~18 ~7 ~59 cobblestone 0  
fill ~19 ~7 ~21 ~19 ~10 ~21 stone 0  
fill ~19 ~7 ~53 ~20 ~7 ~53 stone 5  
fill ~19 ~7 ~54 ~19 ~8 ~54 stone 0  
fill ~19 ~7 ~57 ~19 ~9 ~57 stone 0  
fill ~19 ~7 ~58 ~20 ~7 ~58 cobblestone 0 
setblock ~20 ~7 ~21 cobblestone 0 
setblock ~20 ~7 ~54 stone 5  
fill ~20 ~7 ~56 ~21 ~7 ~56 stone 5  
fill ~20 ~7 ~57 ~20 ~9 ~57 cobblestone 0 
setblock ~21 ~7 ~55 cobblestone 0 
setblock ~32 ~7 ~34 cobblestone 0  
fill ~33 ~7 ~33 ~33 ~6 ~33 stone 0  
fill ~33 ~7 ~34 ~34 ~7 ~34 stone 0  
fill ~33 ~7 ~35 ~34 ~7 ~35 stone 5  
fill ~34 ~7 ~30 ~34 ~9 ~30 stone 0 
setblock ~34 ~7 ~31 stone 5  
fill ~34 ~7 ~33 ~34 ~8 ~33 cobblestone 0 
setblock ~34 ~7 ~36 cobblestone 0 
setblock ~35 ~7 ~29 stone 0  
fill ~35 ~7 ~30 ~35 ~8 ~30 cobblestone 0  
fill ~35 ~7 ~31 ~36 ~7 ~31 cobblestone 0  
fill ~35 ~7 ~32 ~35 ~7 ~30 cobblestone 0  
fill ~35 ~7 ~33 ~35 ~7 ~34 stone 5  
fill ~35 ~7 ~35 ~36 ~7 ~35 stone 0  
fill ~35 ~7 ~36 ~35 ~8 ~36 stone 0 
setblock ~36 ~7 ~28 stone 0  
fill ~36 ~7 ~29 ~36 ~9 ~29 cobblestone 0  
fill ~36 ~7 ~30 ~38 ~7 ~30 stone 5  
fill ~36 ~7 ~32 ~36 ~7 ~33 stone 0 
setblock ~36 ~7 ~34 cobblestone 0  
fill ~36 ~7 ~37 ~36 ~7 ~38 cobblestone 0 
setblock ~37 ~7 ~28 stone 5 
setblock ~37 ~7 ~29 stone 0  
fill ~37 ~7 ~31 ~38 ~7 ~31 stone 0  
fill ~37 ~7 ~32 ~37 ~7 ~33 cobblestone 0 
setblock ~37 ~7 ~34 stone 5 
setblock ~37 ~7 ~35 cobblestone 0 
setblock ~37 ~7 ~36 stone 5  
fill ~37 ~7 ~38 ~37 ~8 ~38 stone 5 
setblock ~38 ~7 ~27 cobblestone 0  
fill ~38 ~7 ~28 ~38 ~8 ~28 stone 0  
fill ~38 ~7 ~29 ~39 ~7 ~29 cobblestone 0  
fill ~38 ~7 ~33 ~38 ~8 ~33 cobblestone 0  
fill ~38 ~7 ~34 ~38 ~7 ~32 cobblestone 0  
fill ~38 ~7 ~35 ~38 ~6 ~35 stone 0  
fill ~38 ~7 ~36 ~39 ~7 ~36 cobblestone 0  
fill ~38 ~7 ~38 ~38 ~9 ~38 cobblestone 0  
fill ~39 ~7 ~28 ~39 ~9 ~28 cobblestone 0  
fill ~39 ~7 ~30 ~39 ~7 ~31 cobblestone 0  
fill ~39 ~7 ~33 ~40 ~7 ~33 stone 5 
setblock ~39 ~7 ~34 stone 0  
fill ~39 ~7 ~35 ~41 ~7 ~35 cobblestone 0 
setblock ~39 ~7 ~37 cobblestone 0 
setblock ~39 ~7 ~38 stone 5  
fill ~39 ~7 ~39 ~39 ~7 ~40 stone 0 
setblock ~39 ~7 ~58 stone 0  
fill ~40 ~7 ~27 ~40 ~7 ~29 stone 0 
setblock ~40 ~7 ~31 stone 0 
setblock ~40 ~7 ~32 cobblestone 0  
fill ~40 ~7 ~34 ~41 ~7 ~34 stone 5  
fill ~40 ~7 ~38 ~40 ~9 ~38 stone 0  
fill ~40 ~7 ~39 ~40 ~8 ~39 stone 5 
setblock ~40 ~7 ~41 stone 5  
fill ~40 ~7 ~42 ~40 ~9 ~42 cobblestone 0 
setblock ~40 ~7 ~43 stone 5  
fill ~41 ~7 ~27 ~41 ~8 ~27 stone 5 
setblock ~41 ~7 ~28 stone 0  
fill ~41 ~7 ~29 ~41 ~7 ~30 stone 5 
setblock ~41 ~7 ~31 cobblestone 0  
fill ~41 ~7 ~32 ~43 ~7 ~32 stone 0 
setblock ~41 ~7 ~33 cobblestone 0 
setblock ~41 ~7 ~43 cobblestone 0  
fill ~41 ~7 ~44 ~41 ~9 ~44 stone 5  
fill ~42 ~7 ~29 ~42 ~9 ~29 cobblestone 0  
fill ~42 ~7 ~31 ~43 ~7 ~31 stone 5  
fill ~42 ~7 ~33 ~42 ~9 ~33 stone 5  
fill ~42 ~7 ~35 ~42 ~8 ~35 stone 5  
fill ~42 ~7 ~37 ~42 ~8 ~37 stone 0  
fill ~43 ~7 ~29 ~43 ~8 ~29 stone 0  
fill ~43 ~7 ~33 ~43 ~8 ~33 stone 0 
setblock ~43 ~7 ~34 cobblestone 0  
fill ~43 ~7 ~35 ~47 ~7 ~35 sea_lantern 0  
fill ~43 ~7 ~36 ~43 ~8 ~36 lapis_block 0  
fill ~43 ~7 ~42 ~43 ~8 ~42 lapis_block 0 
setblock ~43 ~7 ~45 stone 5  
fill ~44 ~7 ~30 ~44 ~7 ~31 cobblestone 0  
fill ~44 ~7 ~33 ~44 ~8 ~33 cobblestone 0  
fill ~44 ~7 ~42 ~46 ~7 ~42 quartz_block 0  
fill ~44 ~7 ~45 ~44 ~8 ~45 cobblestone 0  
fill ~45 ~7 ~32 ~45 ~8 ~32 stone 0  
fill ~45 ~7 ~45 ~45 ~6 ~45 stone 0  
fill ~46 ~7 ~32 ~47 ~7 ~32 cobblestone 0 
setblock ~46 ~7 ~45 stone 5 
setblock ~47 ~7 ~41 ice 0  
fill ~47 ~7 ~42 ~47 ~8 ~42 sea_lantern 0  
fill ~47 ~7 ~45 ~47 ~11 ~45 stone 0  
fill ~48 ~7 ~40 ~48 ~21 ~40 quartz_block 0 
setblock ~49 ~7 ~34 stone 0  
fill ~49 ~7 ~43 ~49 ~7 ~44 stone 0 
setblock ~50 ~7 ~35 stone 5  
fill ~50 ~7 ~41 ~51 ~7 ~41 cobblestone 0 
setblock ~50 ~7 ~42 stone 0 
setblock ~51 ~7 ~36 stone 5 
setblock ~51 ~7 ~37 stone 0  
fill ~51 ~7 ~39 ~52 ~7 ~39 stone 5 
setblock ~51 ~7 ~40 stone 0  
fill ~58 ~7 ~55 ~59 ~7 ~55 stone 0 
setblock ~58 ~7 ~56 stone 5 
setblock ~58 ~7 ~57 stone 0 
setblock ~59 ~7 ~19 stone 5  
fill ~59 ~7 ~53 ~60 ~7 ~53 cobblestone 0  
fill ~59 ~7 ~56 ~60 ~7 ~56 stone 0  
fill ~59 ~7 ~57 ~59 ~12 ~57 stone 5  
fill ~59 ~7 ~59 ~59 ~8 ~59 stone 5 
setblock ~60 ~7 ~18 stone 5  
fill ~60 ~7 ~19 ~61 ~7 ~19 stone 0 
setblock ~60 ~7 ~54 stone 0 
setblock ~60 ~7 ~55 cobblestone 0  
fill ~60 ~7 ~57 ~60 ~7 ~58 cobblestone 0  
fill ~60 ~7 ~59 ~60 ~7 ~60 stone 0 
setblock ~61 ~7 ~53 stone 0  
fill ~61 ~7 ~54 ~62 ~7 ~54 cobblestone 0 
setblock ~61 ~7 ~56 stone 5  
fill ~61 ~7 ~58 ~62 ~7 ~58 stone 5  
fill ~62 ~7 ~53 ~63 ~7 ~53 cobblestone 0  
fill ~62 ~7 ~55 ~62 ~8 ~55 stone 5 
setblock ~62 ~7 ~56 cobblestone 0  
fill ~62 ~7 ~59 ~64 ~7 ~59 stone 5 
setblock ~62 ~7 ~60 stone 0 
setblock ~63 ~7 ~54 stone 5 
setblock ~63 ~7 ~55 cobblestone 0 
setblock ~63 ~7 ~56 stone 0  
fill ~63 ~7 ~57 ~63 ~8 ~57 stone 5  
fill ~64 ~7 ~53 ~65 ~7 ~53 stone 0 
setblock ~64 ~7 ~54 cobblestone 0  
fill ~64 ~7 ~55 ~64 ~7 ~56 stone 5  
fill ~64 ~7 ~58 ~65 ~7 ~58 stone 0  
fill ~64 ~7 ~60 ~64 ~9 ~60 stone 0  
fill ~65 ~7 ~55 ~65 ~8 ~55 cobblestone 0  
fill ~65 ~7 ~56 ~66 ~7 ~56 cobblestone 0  
fill ~65 ~7 ~59 ~65 ~8 ~59 stone 0 
setblock ~75 ~7 ~29 stone 5 
setblock ~12 ~8 ~56 cobblestone 0  
fill ~13 ~8 ~21 ~13 ~9 ~21 stone 0 
setblock ~13 ~8 ~56 stone 5 
setblock ~14 ~8 ~19 stone 0  
fill ~14 ~8 ~20 ~14 ~10 ~20 cobblestone 0  
fill ~14 ~8 ~21 ~14 ~8 ~20 cobblestone 0 
setblock ~14 ~8 ~22 stone 5  
fill ~14 ~8 ~23 ~16 ~8 ~23 cobblestone 0  
fill ~14 ~8 ~54 ~15 ~8 ~54 stone 0  
fill ~14 ~8 ~55 ~14 ~6 ~55 cobblestone 0 
setblock ~14 ~8 ~57 stone 0 
setblock ~14 ~8 ~58 stone 5  
fill ~15 ~8 ~19 ~15 ~7 ~19 stone 5 
setblock ~15 ~8 ~21 stone 0  
fill ~15 ~8 ~24 ~15 ~9 ~24 cobblestone 0 
setblock ~15 ~8 ~53 stone 0 
setblock ~15 ~8 ~55 stone 5 
setblock ~15 ~8 ~57 stone 5 
setblock ~15 ~8 ~58 stone 0  
fill ~16 ~8 ~19 ~17 ~8 ~19 stone 0  
fill ~16 ~8 ~20 ~16 ~8 ~21 cobblestone 0  
fill ~16 ~8 ~22 ~19 ~8 ~22 stone 5  
fill ~16 ~8 ~53 ~16 ~8 ~54 stone 5  
fill ~16 ~8 ~55 ~17 ~8 ~55 cobblestone 0 
setblock ~16 ~8 ~56 stone 5 
setblock ~16 ~8 ~57 stone 0 
setblock ~16 ~8 ~58 cobblestone 0  
fill ~17 ~8 ~20 ~18 ~8 ~20 stone 0  
fill ~17 ~8 ~21 ~17 ~8 ~19 stone 0  
fill ~17 ~8 ~23 ~18 ~8 ~23 stone 5  
fill ~17 ~8 ~25 ~17 ~9 ~25 stone 5  
fill ~17 ~8 ~53 ~18 ~8 ~53 stone 0  
fill ~17 ~8 ~54 ~17 ~9 ~54 cobblestone 0  
fill ~17 ~8 ~57 ~17 ~9 ~57 cobblestone 0  
fill ~17 ~8 ~58 ~17 ~10 ~58 stone 0 
setblock ~18 ~8 ~21 cobblestone 0 
setblock ~18 ~8 ~52 cobblestone 0  
fill ~18 ~8 ~55 ~18 ~8 ~56 stone 0 
setblock ~19 ~8 ~52 stone 5 
setblock ~19 ~8 ~53 cobblestone 0 
setblock ~19 ~8 ~56 stone 0 
setblock ~19 ~8 ~58 stone 0 
setblock ~20 ~8 ~21 stone 5  
fill ~20 ~8 ~53 ~20 ~8 ~54 stone 0  
fill ~20 ~8 ~55 ~20 ~9 ~55 cobblestone 0  
fill ~20 ~8 ~56 ~20 ~8 ~55 cobblestone 0 
setblock ~20 ~8 ~58 stone 5  
fill ~21 ~8 ~54 ~21 ~8 ~56 stone 0  
fill ~32 ~8 ~34 ~32 ~11 ~34 stone 0  
fill ~33 ~8 ~32 ~34 ~8 ~32 cobblestone 0  
fill ~33 ~8 ~33 ~33 ~8 ~34 cobblestone 0  
fill ~33 ~8 ~35 ~34 ~8 ~35 stone 0  
fill ~33 ~8 ~36 ~33 ~11 ~36 cobblestone 0 
setblock ~34 ~8 ~31 stone 0 
setblock ~34 ~8 ~34 cobblestone 0  
fill ~34 ~8 ~36 ~34 ~9 ~36 stone 5  
fill ~34 ~8 ~37 ~34 ~8 ~38 stone 5  
fill ~35 ~8 ~29 ~35 ~10 ~29 stone 5  
fill ~35 ~8 ~31 ~35 ~8 ~32 stone 5 
setblock ~35 ~8 ~33 stone 0  
fill ~35 ~8 ~34 ~35 ~11 ~34 stone 5  
fill ~35 ~8 ~35 ~35 ~8 ~34 stone 5 
setblock ~35 ~8 ~38 stone 0 
setblock ~36 ~8 ~28 stone 5 
setblock ~36 ~8 ~30 stone 0  
fill ~36 ~8 ~31 ~36 ~9 ~31 cobblestone 0  
fill ~36 ~8 ~32 ~36 ~8 ~33 stone 5 
setblock ~36 ~8 ~34 stone 0 
setblock ~36 ~8 ~35 cobblestone 0  
fill ~36 ~8 ~37 ~36 ~9 ~37 stone 0  
fill ~36 ~8 ~38 ~36 ~9 ~38 cobblestone 0  
fill ~37 ~8 ~27 ~37 ~8 ~29 cobblestone 0  
fill ~37 ~8 ~30 ~37 ~11 ~30 stone 5  
fill ~37 ~8 ~31 ~37 ~8 ~30 stone 5  
fill ~37 ~8 ~32 ~37 ~8 ~33 stone 0  
fill ~37 ~8 ~34 ~37 ~9 ~34 cobblestone 0  
fill ~37 ~8 ~35 ~37 ~8 ~37 stone 0 
setblock ~38 ~8 ~27 stone 5  
fill ~38 ~8 ~29 ~38 ~8 ~30 stone 0  
fill ~38 ~8 ~31 ~38 ~10 ~31 cobblestone 0  
fill ~38 ~8 ~34 ~39 ~8 ~34 stone 5  
fill ~38 ~8 ~35 ~39 ~8 ~35 cobblestone 0  
fill ~38 ~8 ~36 ~38 ~7 ~36 cobblestone 0  
fill ~38 ~8 ~39 ~40 ~8 ~39 stone 5  
fill ~39 ~8 ~29 ~40 ~8 ~29 cobblestone 0  
fill ~39 ~8 ~30 ~39 ~11 ~30 stone 5  
fill ~39 ~8 ~31 ~40 ~8 ~31 stone 5  
fill ~39 ~8 ~32 ~40 ~8 ~32 stone 5  
fill ~39 ~8 ~33 ~39 ~7 ~33 stone 5  
fill ~39 ~8 ~36 ~40 ~8 ~36 stone 5  
fill ~39 ~8 ~37 ~39 ~8 ~36 stone 5 
setblock ~39 ~8 ~38 cobblestone 0 
setblock ~39 ~8 ~40 cobblestone 0 
setblock ~39 ~8 ~41 stone 5 
setblock ~39 ~8 ~58 cobblestone 0 
setblock ~40 ~8 ~27 stone 5  
fill ~40 ~8 ~28 ~40 ~11 ~28 cobblestone 0 
setblock ~40 ~8 ~33 stone 0 
setblock ~40 ~8 ~34 cobblestone 0  
fill ~40 ~8 ~35 ~42 ~8 ~35 stone 5  
fill ~40 ~8 ~37 ~40 ~9 ~37 cobblestone 0  
fill ~40 ~8 ~41 ~40 ~9 ~41 stone 0  
fill ~40 ~8 ~43 ~40 ~10 ~43 cobblestone 0  
fill ~41 ~8 ~28 ~42 ~8 ~28 stone 5 
setblock ~41 ~8 ~29 stone 0 
setblock ~41 ~8 ~30 cobblestone 0 
setblock ~41 ~8 ~31 stone 0 
setblock ~41 ~8 ~32 cobblestone 0 
setblock ~41 ~8 ~33 stone 5 
setblock ~41 ~8 ~34 stone 0 
setblock ~41 ~8 ~43 stone 5  
fill ~42 ~8 ~31 ~43 ~8 ~31 cobblestone 0 
setblock ~42 ~8 ~32 stone 5  
fill ~42 ~8 ~34 ~42 ~12 ~34 stone 5  
fill ~42 ~8 ~45 ~44 ~8 ~45 cobblestone 0 
setblock ~43 ~8 ~30 stone 5 
setblock ~43 ~8 ~32 cobblestone 0 
setblock ~43 ~8 ~34 stone 0  
fill ~43 ~8 ~35 ~47 ~8 ~35 sea_lantern 0  
fill ~44 ~8 ~30 ~44 ~11 ~30 stone 0  
fill ~44 ~8 ~31 ~44 ~8 ~30 stone 0  
fill ~44 ~8 ~42 ~45 ~8 ~42 quartz_block 0  
fill ~44 ~8 ~46 ~45 ~8 ~46 stone 0  
fill ~45 ~8 ~31 ~45 ~9 ~31 cobblestone 0  
fill ~46 ~8 ~32 ~46 ~9 ~32 stone 0 
setblock ~46 ~8 ~42 ice 0 
setblock ~46 ~8 ~43 sea_lantern 0 
setblock ~46 ~8 ~45 cobblestone 0 
setblock ~47 ~8 ~33 cobblestone 0  
fill ~47 ~8 ~41 ~47 ~22 ~41 quartz_block 0 
setblock ~48 ~8 ~33 stone 0  
fill ~48 ~8 ~44 ~49 ~8 ~44 stone 5 
setblock ~49 ~8 ~33 cobblestone 0  
fill ~49 ~8 ~34 ~50 ~8 ~34 stone 5  
fill ~49 ~8 ~42 ~49 ~9 ~42 stone 5 
setblock ~49 ~8 ~43 cobblestone 0 
setblock ~50 ~8 ~35 stone 0  
fill ~50 ~8 ~41 ~50 ~7 ~41 cobblestone 0  
fill ~50 ~8 ~42 ~50 ~9 ~42 cobblestone 0 
setblock ~51 ~8 ~36 cobblestone 0 
setblock ~51 ~8 ~37 stone 5  
fill ~51 ~8 ~39 ~52 ~8 ~39 stone 0  
fill ~51 ~8 ~40 ~51 ~8 ~41 stone 5 
setblock ~58 ~8 ~54 stone 0  
fill ~58 ~8 ~55 ~58 ~9 ~55 stone 5  
fill ~58 ~8 ~56 ~58 ~9 ~56 cobblestone 0  
fill ~58 ~8 ~57 ~58 ~8 ~56 cobblestone 0 
setblock ~58 ~8 ~58 stone 0  
fill ~59 ~8 ~19 ~59 ~8 ~20 cobblestone 0 
setblock ~59 ~8 ~53 stone 0  
fill ~59 ~8 ~54 ~59 ~8 ~55 cobblestone 0  
fill ~59 ~8 ~56 ~62 ~8 ~56 stone 0  
fill ~60 ~8 ~18 ~61 ~8 ~18 stone 0  
fill ~60 ~8 ~19 ~60 ~10 ~19 stone 0  
fill ~60 ~8 ~53 ~61 ~8 ~53 cobblestone 0  
fill ~60 ~8 ~54 ~62 ~8 ~54 stone 5  
fill ~60 ~8 ~55 ~61 ~8 ~55 stone 0  
fill ~60 ~8 ~57 ~63 ~8 ~57 stone 5  
fill ~60 ~8 ~58 ~64 ~8 ~58 stone 5  
fill ~60 ~8 ~59 ~60 ~9 ~59 stone 5  
fill ~61 ~8 ~19 ~61 ~9 ~19 cobblestone 0 
setblock ~61 ~8 ~52 stone 5  
fill ~61 ~8 ~60 ~63 ~8 ~60 cobblestone 0  
fill ~62 ~8 ~52 ~62 ~8 ~53 stone 0  
fill ~62 ~8 ~59 ~64 ~8 ~59 cobblestone 0  
fill ~63 ~8 ~52 ~64 ~8 ~52 cobblestone 0  
fill ~63 ~8 ~53 ~63 ~8 ~54 cobblestone 0 
setblock ~63 ~8 ~55 stone 0  
fill ~63 ~8 ~56 ~64 ~8 ~56 stone 5  
fill ~64 ~8 ~53 ~64 ~8 ~54 stone 5 
setblock ~64 ~8 ~55 cobblestone 0  
fill ~65 ~8 ~53 ~65 ~9 ~53 stone 0  
fill ~65 ~8 ~56 ~65 ~9 ~56 stone 0  
fill ~65 ~8 ~57 ~65 ~9 ~57 cobblestone 0  
fill ~65 ~8 ~58 ~65 ~8 ~57 cobblestone 0 
setblock ~66 ~8 ~55 cobblestone 0 
setblock ~66 ~8 ~56 stone 5 
setblock ~75 ~8 ~29 stone 0 
setblock ~13 ~9 ~23 stone 0 
setblock ~13 ~9 ~56 cobblestone 0 
setblock ~14 ~9 ~19 stone 5  
fill ~14 ~9 ~21 ~14 ~9 ~22 stone 0  
fill ~14 ~9 ~23 ~14 ~8 ~23 cobblestone 0  
fill ~14 ~9 ~54 ~14 ~8 ~54 stone 0  
fill ~14 ~9 ~55 ~14 ~10 ~55 stone 5  
fill ~14 ~9 ~57 ~17 ~9 ~57 cobblestone 0  
fill ~15 ~9 ~19 ~16 ~9 ~19 stone 0  
fill ~15 ~9 ~20 ~15 ~10 ~20 stone 5  
fill ~15 ~9 ~21 ~18 ~9 ~21 stone 5 
setblock ~15 ~9 ~22 cobblestone 0 
setblock ~15 ~9 ~23 stone 5  
fill ~15 ~9 ~53 ~15 ~10 ~53 stone 5  
fill ~15 ~9 ~54 ~15 ~9 ~53 stone 5  
fill ~15 ~9 ~55 ~16 ~9 ~55 stone 0  
fill ~15 ~9 ~56 ~18 ~9 ~56 cobblestone 0  
fill ~15 ~9 ~58 ~16 ~9 ~58 stone 5  
fill ~16 ~9 ~20 ~16 ~10 ~20 stone 0  
fill ~16 ~9 ~22 ~19 ~9 ~22 stone 0  
fill ~16 ~9 ~23 ~16 ~9 ~22 stone 0  
fill ~16 ~9 ~53 ~16 ~10 ~53 cobblestone 0  
fill ~16 ~9 ~54 ~16 ~10 ~54 cobblestone 0  
fill ~17 ~9 ~19 ~17 ~9 ~20 cobblestone 0  
fill ~17 ~9 ~23 ~18 ~9 ~23 cobblestone 0 
setblock ~17 ~9 ~24 stone 5  
fill ~17 ~9 ~53 ~17 ~11 ~53 stone 0  
fill ~17 ~9 ~55 ~20 ~9 ~55 cobblestone 0 
setblock ~18 ~9 ~20 stone 0  
fill ~18 ~9 ~24 ~18 ~10 ~24 cobblestone 0  
fill ~18 ~9 ~52 ~18 ~9 ~53 stone 5  
fill ~18 ~9 ~57 ~18 ~10 ~57 stone 0 
setblock ~18 ~9 ~58 cobblestone 0 
setblock ~19 ~9 ~23 stone 0 
setblock ~19 ~9 ~52 cobblestone 0  
fill ~19 ~9 ~53 ~19 ~10 ~53 stone 0 
setblock ~19 ~9 ~54 stone 5  
fill ~19 ~9 ~56 ~20 ~9 ~56 stone 5  
fill ~19 ~9 ~58 ~19 ~10 ~58 stone 5 
setblock ~20 ~9 ~21 stone 0  
fill ~20 ~9 ~52 ~20 ~9 ~53 stone 5  
fill ~20 ~9 ~54 ~21 ~9 ~54 cobblestone 0 
setblock ~21 ~9 ~55 stone 5 
setblock ~21 ~9 ~56 stone 0 
setblock ~32 ~9 ~33 stone 0  
fill ~32 ~9 ~35 ~33 ~9 ~35 stone 0  
fill ~33 ~9 ~32 ~33 ~12 ~32 stone 0  
fill ~33 ~9 ~33 ~34 ~9 ~33 stone 5  
fill ~33 ~9 ~34 ~33 ~11 ~34 stone 5  
fill ~33 ~9 ~37 ~33 ~10 ~37 stone 0 
setblock ~33 ~9 ~39 cobblestone 0  
fill ~34 ~9 ~31 ~34 ~9 ~32 cobblestone 0  
fill ~34 ~9 ~35 ~35 ~9 ~35 cobblestone 0  
fill ~34 ~9 ~37 ~35 ~9 ~37 cobblestone 0  
fill ~34 ~9 ~38 ~38 ~9 ~38 cobblestone 0  
fill ~35 ~9 ~30 ~37 ~9 ~30 stone 5 
setblock ~35 ~9 ~31 stone 0  
fill ~35 ~9 ~32 ~38 ~9 ~32 cobblestone 0  
fill ~35 ~9 ~33 ~35 ~9 ~32 cobblestone 0  
fill ~35 ~9 ~36 ~36 ~9 ~36 cobblestone 0  
fill ~35 ~9 ~39 ~36 ~9 ~39 stone 5  
fill ~36 ~9 ~28 ~37 ~9 ~28 stone 0 
setblock ~36 ~9 ~33 stone 0 
setblock ~36 ~9 ~34 cobblestone 0 
setblock ~36 ~9 ~35 stone 0  
fill ~37 ~9 ~29 ~38 ~9 ~29 stone 5  
fill ~37 ~9 ~31 ~37 ~10 ~31 cobblestone 0  
fill ~37 ~9 ~33 ~38 ~9 ~33 stone 5  
fill ~37 ~9 ~35 ~37 ~10 ~35 cobblestone 0 
setblock ~37 ~9 ~36 stone 5 
setblock ~37 ~9 ~39 cobblestone 0 
setblock ~37 ~9 ~40 stone 0  
fill ~38 ~9 ~27 ~38 ~11 ~27 stone 0 
setblock ~38 ~9 ~28 cobblestone 0  
fill ~38 ~9 ~30 ~38 ~11 ~30 cobblestone 0  
fill ~38 ~9 ~34 ~38 ~8 ~34 stone 5  
fill ~38 ~9 ~35 ~39 ~9 ~35 stone 5 
setblock ~38 ~9 ~36 stone 0  
fill ~38 ~9 ~37 ~40 ~9 ~37 cobblestone 0  
fill ~38 ~9 ~39 ~40 ~9 ~39 stone 0 
setblock ~38 ~9 ~40 cobblestone 0  
fill ~39 ~9 ~27 ~41 ~9 ~27 cobblestone 0  
fill ~39 ~9 ~29 ~39 ~10 ~29 stone 0  
fill ~39 ~9 ~31 ~40 ~9 ~31 cobblestone 0  
fill ~39 ~9 ~32 ~39 ~9 ~34 stone 0 
setblock ~39 ~9 ~36 stone 5  
fill ~39 ~9 ~38 ~39 ~10 ~38 stone 0  
fill ~39 ~9 ~40 ~39 ~9 ~41 stone 0 
setblock ~39 ~9 ~58 stone 0 
setblock ~40 ~9 ~26 cobblestone 0  
fill ~40 ~9 ~29 ~41 ~9 ~29 stone 5  
fill ~40 ~9 ~32 ~40 ~10 ~32 cobblestone 0  
fill ~40 ~9 ~33 ~40 ~10 ~33 stone 5  
fill ~40 ~9 ~34 ~40 ~11 ~34 stone 0  
fill ~40 ~9 ~35 ~40 ~10 ~35 cobblestone 0 
setblock ~40 ~9 ~36 stone 0 
setblock ~40 ~9 ~40 stone 5 
setblock ~41 ~9 ~26 stone 5  
fill ~41 ~9 ~28 ~41 ~8 ~28 stone 5  
fill ~41 ~9 ~30 ~42 ~9 ~30 stone 0  
fill ~41 ~9 ~31 ~41 ~9 ~32 stone 5  
fill ~41 ~9 ~33 ~41 ~9 ~34 cobblestone 0  
fill ~41 ~9 ~35 ~42 ~9 ~35 stone 0  
fill ~42 ~9 ~26 ~42 ~9 ~27 stone 0 
setblock ~42 ~9 ~28 cobblestone 0  
fill ~42 ~9 ~31 ~43 ~9 ~31 cobblestone 0  
fill ~42 ~9 ~32 ~42 ~9 ~31 cobblestone 0 
setblock ~42 ~9 ~37 stone 5  
fill ~42 ~9 ~45 ~42 ~10 ~45 stone 5 
setblock ~43 ~9 ~29 stone 5 
setblock ~43 ~9 ~30 cobblestone 0  
fill ~43 ~9 ~32 ~43 ~12 ~32 stone 5 
setblock ~43 ~9 ~33 cobblestone 0  
fill ~43 ~9 ~34 ~43 ~10 ~34 stone 5  
fill ~43 ~9 ~35 ~47 ~9 ~35 sea_lantern 0  
fill ~43 ~9 ~36 ~43 ~10 ~36 stone 5 
setblock ~43 ~9 ~46 cobblestone 0  
fill ~44 ~9 ~31 ~44 ~10 ~31 stone 5  
fill ~44 ~9 ~32 ~45 ~9 ~32 cobblestone 0 
setblock ~44 ~9 ~33 stone 0  
fill ~44 ~9 ~42 ~44 ~0 ~42 quartz_block 0  
fill ~44 ~9 ~46 ~45 ~9 ~46 stone 0  
fill ~45 ~9 ~33 ~45 ~10 ~33 cobblestone 0 
setblock ~45 ~9 ~42 ice 0 
setblock ~45 ~9 ~43 sea_lantern 0 
setblock ~45 ~9 ~47 stone 5  
fill ~46 ~9 ~42 ~46 ~23 ~42 quartz_block 0 
setblock ~46 ~9 ~46 stone 5 
setblock ~47 ~9 ~32 cobblestone 0  
fill ~48 ~9 ~33 ~48 ~10 ~33 cobblestone 0 
setblock ~48 ~9 ~45 cobblestone 0 
setblock ~49 ~9 ~33 stone 0  
fill ~49 ~9 ~44 ~49 ~10 ~44 stone 0 
setblock ~50 ~9 ~34 stone 0 
setblock ~50 ~9 ~35 stone 5 
setblock ~50 ~9 ~43 cobblestone 0  
fill ~51 ~9 ~36 ~51 ~10 ~36 stone 0  
fill ~51 ~9 ~39 ~51 ~8 ~39 stone 0  
fill ~51 ~9 ~40 ~51 ~9 ~39 stone 0  
fill ~51 ~9 ~41 ~51 ~10 ~41 cobblestone 0  
fill ~51 ~9 ~42 ~51 ~9 ~41 cobblestone 0  
fill ~52 ~9 ~37 ~52 ~11 ~37 stone 5 
setblock ~52 ~9 ~39 cobblestone 0 
setblock ~58 ~9 ~19 stone 0  
fill ~58 ~9 ~54 ~58 ~10 ~54 cobblestone 0 
setblock ~58 ~9 ~57 stone 0 
setblock ~59 ~9 ~18 stone 0 
setblock ~59 ~9 ~19 stone 5 
setblock ~59 ~9 ~20 stone 0 
setblock ~59 ~9 ~53 stone 5 
setblock ~59 ~9 ~54 stone 0  
fill ~59 ~9 ~55 ~60 ~9 ~55 cobblestone 0  
fill ~59 ~9 ~56 ~60 ~9 ~56 stone 0  
fill ~59 ~9 ~58 ~59 ~11 ~58 stone 5  
fill ~60 ~9 ~17 ~60 ~14 ~17 cobblestone 0 
setblock ~60 ~9 ~18 stone 5 
setblock ~60 ~9 ~20 stone 5  
fill ~60 ~9 ~52 ~61 ~9 ~52 cobblestone 0  
fill ~60 ~9 ~53 ~60 ~10 ~53 cobblestone 0  
fill ~60 ~9 ~54 ~62 ~9 ~54 stone 5 
setblock ~60 ~9 ~57 stone 0 
setblock ~60 ~9 ~58 cobblestone 0 
setblock ~60 ~9 ~60 stone 5 
setblock ~61 ~9 ~18 stone 0 
setblock ~61 ~9 ~53 stone 0  
fill ~61 ~9 ~55 ~61 ~9 ~58 stone 5  
fill ~61 ~9 ~60 ~62 ~9 ~60 stone 0 
setblock ~62 ~9 ~52 stone 5 
setblock ~62 ~9 ~53 cobblestone 0 
setblock ~62 ~9 ~55 stone 0  
fill ~62 ~9 ~56 ~63 ~9 ~56 stone 5  
fill ~62 ~9 ~57 ~63 ~9 ~57 cobblestone 0  
fill ~62 ~9 ~58 ~63 ~9 ~58 stone 0 
setblock ~62 ~9 ~59 stone 5  
fill ~63 ~9 ~52 ~64 ~9 ~52 stone 0 
setblock ~63 ~9 ~53 stone 5  
fill ~63 ~9 ~54 ~63 ~9 ~55 cobblestone 0  
fill ~63 ~9 ~59 ~64 ~9 ~59 cobblestone 0  
fill ~63 ~9 ~60 ~63 ~11 ~60 cobblestone 0  
fill ~64 ~9 ~53 ~64 ~10 ~53 cobblestone 0 
setblock ~64 ~9 ~54 stone 0  
fill ~64 ~9 ~55 ~66 ~9 ~55 stone 5  
fill ~64 ~9 ~56 ~64 ~11 ~56 stone 0  
fill ~64 ~9 ~57 ~64 ~9 ~56 stone 0  
fill ~64 ~9 ~58 ~64 ~10 ~58 cobblestone 0  
fill ~65 ~9 ~58 ~65 ~10 ~58 stone 0 
setblock ~65 ~9 ~59 stone 5 
setblock ~66 ~9 ~54 stone 0 
setblock ~66 ~9 ~56 stone 0  
fill ~66 ~9 ~58 ~66 ~10 ~58 stone 5  
fill ~75 ~9 ~29 ~75 ~11 ~29 cobblestone 0 
setblock ~13 ~10 ~22 cobblestone 0  
fill ~13 ~10 ~23 ~14 ~10 ~23 stone 5  
fill ~13 ~10 ~55 ~13 ~12 ~55 stone 5  
fill ~13 ~10 ~56 ~14 ~10 ~56 stone 0  
fill ~14 ~10 ~21 ~14 ~11 ~21 cobblestone 0  
fill ~14 ~10 ~22 ~15 ~10 ~22 stone 0 
setblock ~14 ~10 ~53 stone 0 
setblock ~14 ~10 ~54 stone 5  
fill ~14 ~10 ~57 ~14 ~11 ~57 cobblestone 0 
setblock ~15 ~10 ~21 stone 0  
fill ~15 ~10 ~23 ~17 ~10 ~23 cobblestone 0 
setblock ~15 ~10 ~24 stone 0 
setblock ~15 ~10 ~52 cobblestone 0 
setblock ~15 ~10 ~54 stone 0  
fill ~15 ~10 ~55 ~15 ~10 ~57 stone 5 
setblock ~15 ~10 ~58 cobblestone 0  
fill ~16 ~10 ~21 ~16 ~10 ~22 stone 5  
fill ~16 ~10 ~24 ~18 ~10 ~24 cobblestone 0  
fill ~16 ~10 ~25 ~17 ~10 ~25 cobblestone 0  
fill ~16 ~10 ~55 ~17 ~10 ~55 cobblestone 0  
fill ~16 ~10 ~56 ~17 ~10 ~56 stone 0  
fill ~16 ~10 ~57 ~18 ~10 ~57 stone 0 
setblock ~16 ~10 ~58 stone 5  
fill ~17 ~10 ~20 ~17 ~10 ~21 stone 0  
fill ~17 ~10 ~22 ~17 ~12 ~22 stone 5  
fill ~17 ~10 ~54 ~18 ~10 ~54 stone 5  
fill ~18 ~10 ~21 ~18 ~11 ~21 stone 0 
setblock ~18 ~10 ~22 cobblestone 0  
fill ~18 ~10 ~23 ~19 ~10 ~23 stone 5  
fill ~18 ~10 ~52 ~18 ~10 ~53 stone 0  
fill ~18 ~10 ~55 ~20 ~10 ~55 stone 5  
fill ~18 ~10 ~56 ~18 ~11 ~56 cobblestone 0 
setblock ~18 ~10 ~58 stone 5 
setblock ~18 ~10 ~59 cobblestone 0  
fill ~19 ~10 ~22 ~20 ~10 ~22 stone 5 
setblock ~19 ~10 ~24 stone 0  
fill ~19 ~10 ~52 ~19 ~12 ~52 stone 5 
setblock ~19 ~10 ~54 stone 0  
fill ~19 ~10 ~56 ~19 ~12 ~56 stone 5  
fill ~19 ~10 ~57 ~19 ~10 ~55 stone 5 
setblock ~20 ~10 ~21 cobblestone 0 
setblock ~20 ~10 ~52 stone 0 
setblock ~20 ~10 ~53 stone 5  
fill ~20 ~10 ~54 ~20 ~12 ~54 cobblestone 0  
fill ~20 ~10 ~56 ~21 ~10 ~56 cobblestone 0 
setblock ~20 ~10 ~57 stone 0  
fill ~21 ~10 ~54 ~21 ~11 ~54 stone 0  
fill ~21 ~10 ~55 ~21 ~11 ~55 cobblestone 0 
setblock ~31 ~10 ~35 stone 5 
setblock ~32 ~10 ~33 cobblestone 0  
fill ~32 ~10 ~35 ~34 ~10 ~35 stone 0 
setblock ~32 ~10 ~36 cobblestone 0  
fill ~32 ~10 ~40 ~32 ~11 ~40 cobblestone 0  
fill ~33 ~10 ~29 ~34 ~10 ~29 cobblestone 0  
fill ~33 ~10 ~30 ~33 ~10 ~29 cobblestone 0  
fill ~33 ~10 ~33 ~33 ~9 ~33 stone 5  
fill ~33 ~10 ~38 ~33 ~10 ~39 stone 0  
fill ~33 ~10 ~40 ~33 ~11 ~40 stone 5 
setblock ~34 ~10 ~30 stone 5 
setblock ~34 ~10 ~31 stone 0 
setblock ~34 ~10 ~32 cobblestone 0 
setblock ~34 ~10 ~33 stone 0 
setblock ~34 ~10 ~34 stone 5 
setblock ~34 ~10 ~36 cobblestone 0 
setblock ~34 ~10 ~37 stone 0 
setblock ~34 ~10 ~38 stone 5 
setblock ~34 ~10 ~39 stone 0  
fill ~35 ~10 ~30 ~35 ~11 ~30 stone 0  
fill ~35 ~10 ~31 ~35 ~11 ~31 cobblestone 0  
fill ~35 ~10 ~32 ~35 ~11 ~32 stone 0  
fill ~35 ~10 ~33 ~37 ~10 ~33 stone 5 
setblock ~35 ~10 ~35 stone 5  
fill ~35 ~10 ~36 ~36 ~10 ~36 stone 0  
fill ~35 ~10 ~37 ~36 ~10 ~37 stone 5 
setblock ~35 ~10 ~38 stone 0  
fill ~35 ~10 ~39 ~36 ~10 ~39 cobblestone 0  
fill ~36 ~10 ~28 ~36 ~11 ~28 cobblestone 0  
fill ~36 ~10 ~29 ~37 ~10 ~29 stone 0  
fill ~36 ~10 ~30 ~36 ~11 ~30 cobblestone 0  
fill ~36 ~10 ~31 ~36 ~11 ~31 stone 5 
setblock ~36 ~10 ~32 cobblestone 0  
fill ~36 ~10 ~34 ~37 ~10 ~34 stone 5 
setblock ~36 ~10 ~35 cobblestone 0  
fill ~36 ~10 ~38 ~37 ~10 ~38 stone 5  
fill ~36 ~10 ~40 ~37 ~10 ~40 cobblestone 0 
setblock ~37 ~10 ~28 stone 5  
fill ~37 ~10 ~32 ~38 ~10 ~32 stone 0  
fill ~37 ~10 ~36 ~38 ~10 ~36 cobblestone 0  
fill ~37 ~10 ~37 ~37 ~10 ~35 cobblestone 0  
fill ~37 ~10 ~39 ~37 ~12 ~39 stone 5  
fill ~38 ~10 ~28 ~38 ~11 ~28 stone 0  
fill ~38 ~10 ~29 ~38 ~11 ~29 cobblestone 0  
fill ~38 ~10 ~33 ~38 ~10 ~34 stone 0  
fill ~38 ~10 ~35 ~39 ~10 ~35 stone 5  
fill ~38 ~10 ~37 ~38 ~11 ~37 stone 0  
fill ~38 ~10 ~38 ~38 ~10 ~39 stone 0  
fill ~38 ~10 ~40 ~38 ~13 ~40 stone 5  
fill ~38 ~10 ~58 ~39 ~10 ~58 cobblestone 0  
fill ~39 ~10 ~26 ~40 ~10 ~26 stone 0  
fill ~39 ~10 ~27 ~42 ~10 ~27 stone 5  
fill ~39 ~10 ~28 ~39 ~10 ~27 stone 5  
fill ~39 ~10 ~31 ~41 ~10 ~31 stone 0 
setblock ~39 ~10 ~32 stone 5  
fill ~39 ~10 ~33 ~39 ~11 ~33 cobblestone 0 
setblock ~39 ~10 ~34 stone 0 
setblock ~39 ~10 ~36 stone 0  
fill ~39 ~10 ~37 ~39 ~11 ~37 cobblestone 0 
setblock ~39 ~10 ~39 stone 5  
fill ~39 ~10 ~40 ~40 ~10 ~40 cobblestone 0  
fill ~39 ~10 ~41 ~39 ~11 ~41 stone 0 
setblock ~39 ~10 ~42 stone 5  
fill ~40 ~10 ~25 ~40 ~11 ~25 cobblestone 0  
fill ~40 ~10 ~29 ~40 ~9 ~29 stone 5  
fill ~40 ~10 ~30 ~41 ~10 ~30 stone 0  
fill ~40 ~10 ~36 ~41 ~10 ~36 cobblestone 0  
fill ~40 ~10 ~37 ~40 ~11 ~37 stone 0 
setblock ~40 ~10 ~38 stone 5 
setblock ~40 ~10 ~39 cobblestone 0 
setblock ~40 ~10 ~42 stone 0 
setblock ~41 ~10 ~25 stone 5  
fill ~41 ~10 ~26 ~41 ~11 ~26 cobblestone 0  
fill ~41 ~10 ~28 ~42 ~10 ~28 stone 0 
setblock ~41 ~10 ~29 cobblestone 0  
fill ~41 ~10 ~32 ~42 ~10 ~32 stone 0  
fill ~41 ~10 ~33 ~41 ~14 ~33 stone 5  
fill ~41 ~10 ~34 ~41 ~10 ~35 stone 5  
fill ~41 ~10 ~44 ~41 ~10 ~45 cobblestone 0 
setblock ~42 ~10 ~25 stone 0 
setblock ~42 ~10 ~26 stone 5  
fill ~42 ~10 ~29 ~42 ~10 ~31 stone 5 
setblock ~42 ~10 ~33 cobblestone 0 
setblock ~42 ~10 ~35 cobblestone 0 
setblock ~42 ~10 ~37 cobblestone 0  
fill ~43 ~10 ~22 ~43 ~11 ~22 cobblestone 0  
fill ~43 ~10 ~26 ~43 ~10 ~27 cobblestone 0  
fill ~43 ~10 ~28 ~43 ~11 ~28 stone 5 
setblock ~43 ~10 ~29 cobblestone 0  
fill ~43 ~10 ~30 ~43 ~12 ~30 stone 5  
fill ~43 ~10 ~31 ~43 ~10 ~30 stone 5  
fill ~43 ~10 ~33 ~44 ~10 ~33 stone 5  
fill ~43 ~10 ~35 ~47 ~10 ~35 sea_lantern 0  
fill ~43 ~10 ~42 ~43 ~11 ~42 sea_lantern 0  
fill ~43 ~10 ~46 ~44 ~10 ~46 stone 0  
fill ~44 ~10 ~29 ~44 ~11 ~29 stone 0  
fill ~44 ~10 ~32 ~44 ~9 ~32 cobblestone 0  
fill ~44 ~10 ~34 ~45 ~10 ~34 cobblestone 0 
setblock ~44 ~10 ~42 ice 0 
setblock ~44 ~10 ~43 sea_lantern 0  
fill ~45 ~10 ~31 ~45 ~12 ~31 stone 5  
fill ~45 ~10 ~32 ~45 ~11 ~32 stone 0  
fill ~45 ~10 ~42 ~45 ~24 ~42 quartz_block 0  
fill ~45 ~10 ~47 ~45 ~11 ~47 cobblestone 0  
fill ~46 ~10 ~32 ~47 ~10 ~32 stone 5 
setblock ~46 ~10 ~46 cobblestone 0  
fill ~48 ~10 ~45 ~48 ~12 ~45 stone 0  
fill ~49 ~10 ~33 ~49 ~11 ~33 stone 5  
fill ~50 ~10 ~34 ~50 ~11 ~34 cobblestone 0 
setblock ~50 ~10 ~43 stone 5 
setblock ~50 ~10 ~44 stone 0 
setblock ~51 ~10 ~35 stone 0  
fill ~51 ~10 ~39 ~51 ~10 ~40 stone 5 
setblock ~51 ~10 ~42 stone 0  
fill ~52 ~10 ~38 ~52 ~10 ~40 stone 0  
fill ~58 ~10 ~19 ~59 ~10 ~19 cobblestone 0 
setblock ~58 ~10 ~55 stone 0  
fill ~58 ~10 ~56 ~58 ~10 ~57 stone 5  
fill ~59 ~10 ~18 ~59 ~11 ~18 cobblestone 0  
fill ~59 ~10 ~20 ~59 ~11 ~20 cobblestone 0 
setblock ~59 ~10 ~21 stone 5 
setblock ~59 ~10 ~53 stone 0  
fill ~59 ~10 ~54 ~60 ~10 ~54 cobblestone 0 
setblock ~59 ~10 ~55 stone 5  
fill ~59 ~10 ~56 ~61 ~10 ~56 cobblestone 0  
fill ~60 ~10 ~18 ~60 ~11 ~18 stone 0 
setblock ~60 ~10 ~20 stone 0 
setblock ~60 ~10 ~52 stone 5  
fill ~60 ~10 ~55 ~63 ~10 ~55 cobblestone 0  
fill ~60 ~10 ~57 ~62 ~10 ~57 cobblestone 0  
fill ~60 ~10 ~58 ~62 ~10 ~58 stone 0  
fill ~60 ~10 ~59 ~62 ~10 ~59 cobblestone 0 
setblock ~61 ~10 ~17 stone 0 
setblock ~61 ~10 ~18 cobblestone 0  
fill ~61 ~10 ~19 ~62 ~10 ~19 stone 0 
setblock ~61 ~10 ~51 stone 0  
fill ~61 ~10 ~52 ~61 ~11 ~52 cobblestone 0  
fill ~61 ~10 ~53 ~61 ~11 ~53 cobblestone 0  
fill ~61 ~10 ~54 ~61 ~11 ~54 stone 5 
setblock ~61 ~10 ~60 stone 5  
fill ~62 ~10 ~18 ~62 ~13 ~18 stone 5  
fill ~62 ~10 ~51 ~62 ~12 ~51 cobblestone 0  
fill ~62 ~10 ~52 ~62 ~14 ~52 stone 0 
setblock ~62 ~10 ~53 stone 5 
setblock ~62 ~10 ~54 cobblestone 0  
fill ~62 ~10 ~56 ~62 ~9 ~56 stone 5 
setblock ~62 ~10 ~60 cobblestone 0  
fill ~63 ~10 ~51 ~63 ~11 ~51 stone 0  
fill ~63 ~10 ~52 ~63 ~11 ~52 stone 5 
setblock ~63 ~10 ~53 stone 0  
fill ~63 ~10 ~54 ~65 ~10 ~54 stone 5  
fill ~63 ~10 ~56 ~63 ~12 ~56 cobblestone 0  
fill ~63 ~10 ~57 ~65 ~10 ~57 stone 5  
fill ~63 ~10 ~58 ~63 ~12 ~58 stone 5  
fill ~63 ~10 ~59 ~63 ~10 ~57 stone 5  
fill ~64 ~10 ~52 ~64 ~11 ~52 cobblestone 0  
fill ~64 ~10 ~55 ~64 ~9 ~55 stone 5  
fill ~64 ~10 ~59 ~65 ~10 ~59 cobblestone 0  
fill ~64 ~10 ~60 ~64 ~11 ~60 cobblestone 0 
setblock ~65 ~10 ~52 stone 0 
setblock ~65 ~10 ~53 stone 5  
fill ~65 ~10 ~55 ~65 ~10 ~56 cobblestone 0 
setblock ~65 ~10 ~60 stone 5  
fill ~66 ~10 ~54 ~66 ~11 ~54 cobblestone 0  
fill ~66 ~10 ~55 ~66 ~11 ~55 stone 0 
setblock ~66 ~10 ~56 cobblestone 0 
setblock ~66 ~10 ~57 stone 0 
setblock ~74 ~10 ~43 stone 0  
fill ~13 ~11 ~22 ~18 ~11 ~22 stone 5  
fill ~13 ~11 ~23 ~14 ~11 ~23 stone 5  
fill ~13 ~11 ~56 ~14 ~11 ~56 stone 5 
setblock ~14 ~11 ~53 stone 5  
fill ~14 ~11 ~54 ~14 ~11 ~55 stone 0 
setblock ~15 ~11 ~20 stone 0  
fill ~15 ~11 ~21 ~15 ~13 ~21 stone 5  
fill ~15 ~11 ~23 ~16 ~11 ~23 stone 0 
setblock ~15 ~11 ~24 cobblestone 0 
setblock ~15 ~11 ~52 stone 5  
fill ~15 ~11 ~53 ~17 ~11 ~53 stone 0  
fill ~15 ~11 ~54 ~15 ~13 ~54 stone 5  
fill ~15 ~11 ~55 ~16 ~11 ~55 cobblestone 0  
fill ~15 ~11 ~56 ~16 ~11 ~56 stone 0 
setblock ~15 ~11 ~57 stone 5  
fill ~16 ~11 ~20 ~17 ~11 ~20 cobblestone 0  
fill ~16 ~11 ~21 ~18 ~11 ~21 stone 0 
setblock ~16 ~11 ~24 stone 0 
setblock ~16 ~11 ~25 stone 5  
fill ~16 ~11 ~54 ~17 ~11 ~54 stone 0  
fill ~16 ~11 ~57 ~16 ~13 ~57 stone 0  
fill ~16 ~11 ~58 ~16 ~11 ~56 stone 0  
fill ~17 ~11 ~23 ~18 ~11 ~23 stone 5 
setblock ~17 ~11 ~24 cobblestone 0  
fill ~17 ~11 ~25 ~18 ~11 ~25 stone 0  
fill ~17 ~11 ~51 ~17 ~11 ~52 stone 5  
fill ~17 ~11 ~55 ~18 ~11 ~55 stone 0  
fill ~17 ~11 ~56 ~17 ~13 ~56 stone 5  
fill ~17 ~11 ~57 ~18 ~11 ~57 stone 5  
fill ~17 ~11 ~58 ~17 ~11 ~56 stone 5 
setblock ~18 ~11 ~24 stone 0  
fill ~18 ~11 ~51 ~20 ~11 ~51 cobblestone 0  
fill ~18 ~11 ~52 ~18 ~11 ~53 cobblestone 0 
setblock ~18 ~11 ~54 stone 5  
fill ~18 ~11 ~58 ~19 ~11 ~58 cobblestone 0 
setblock ~19 ~11 ~21 stone 5  
fill ~19 ~11 ~22 ~20 ~11 ~22 cobblestone 0 
setblock ~19 ~11 ~23 stone 0  
fill ~19 ~11 ~24 ~19 ~11 ~25 stone 5  
fill ~19 ~11 ~53 ~20 ~11 ~53 cobblestone 0  
fill ~19 ~11 ~54 ~19 ~12 ~54 cobblestone 0  
fill ~19 ~11 ~55 ~21 ~11 ~55 cobblestone 0 
setblock ~19 ~11 ~57 cobblestone 0 
setblock ~19 ~11 ~59 stone 5 
setblock ~20 ~11 ~52 cobblestone 0  
fill ~20 ~11 ~56 ~20 ~13 ~56 stone 0 
setblock ~20 ~11 ~57 stone 5 
setblock ~20 ~11 ~59 cobblestone 0 
setblock ~21 ~11 ~53 stone 0  
fill ~31 ~11 ~34 ~31 ~12 ~34 stone 5 
setblock ~31 ~11 ~35 cobblestone 0  
fill ~31 ~11 ~40 ~31 ~13 ~40 cobblestone 0  
fill ~31 ~11 ~41 ~32 ~11 ~41 cobblestone 0 
setblock ~32 ~11 ~32 stone 0 
setblock ~32 ~11 ~33 stone 5  
fill ~32 ~11 ~35 ~32 ~11 ~37 stone 5  
fill ~32 ~11 ~39 ~35 ~11 ~39 cobblestone 0  
fill ~33 ~11 ~28 ~34 ~11 ~28 stone 5  
fill ~33 ~11 ~29 ~33 ~11 ~30 stone 0 
setblock ~33 ~11 ~31 stone 5  
fill ~33 ~11 ~33 ~35 ~11 ~33 cobblestone 0 
setblock ~33 ~11 ~35 stone 0  
fill ~33 ~11 ~37 ~33 ~11 ~38 stone 5  
fill ~34 ~11 ~29 ~35 ~11 ~29 cobblestone 0  
fill ~34 ~11 ~30 ~34 ~11 ~31 cobblestone 0  
fill ~34 ~11 ~32 ~34 ~12 ~32 stone 0 
setblock ~34 ~11 ~34 cobblestone 0 
setblock ~34 ~11 ~35 stone 5 
setblock ~34 ~11 ~36 stone 0  
fill ~34 ~11 ~37 ~35 ~11 ~37 cobblestone 0 
setblock ~34 ~11 ~38 stone 0  
fill ~35 ~11 ~28 ~35 ~14 ~28 cobblestone 0  
fill ~35 ~11 ~35 ~36 ~11 ~35 stone 0  
fill ~35 ~11 ~36 ~35 ~14 ~36 cobblestone 0 
setblock ~35 ~11 ~38 cobblestone 0 
setblock ~36 ~11 ~29 stone 5  
fill ~36 ~11 ~32 ~37 ~11 ~32 stone 0  
fill ~36 ~11 ~33 ~36 ~14 ~33 stone 0 
setblock ~36 ~11 ~34 cobblestone 0  
fill ~36 ~11 ~36 ~36 ~12 ~36 stone 0  
fill ~36 ~11 ~37 ~38 ~11 ~37 stone 0  
fill ~36 ~11 ~38 ~36 ~12 ~38 stone 0 
setblock ~36 ~11 ~39 stone 5  
fill ~36 ~11 ~40 ~36 ~13 ~40 stone 0 
setblock ~36 ~11 ~41 cobblestone 0  
fill ~37 ~11 ~27 ~37 ~11 ~29 cobblestone 0 
setblock ~37 ~11 ~31 stone 0 
setblock ~37 ~11 ~33 cobblestone 0  
fill ~37 ~11 ~34 ~38 ~11 ~34 stone 5  
fill ~37 ~11 ~35 ~37 ~13 ~35 stone 5  
fill ~37 ~11 ~36 ~37 ~12 ~36 cobblestone 0  
fill ~37 ~11 ~38 ~40 ~11 ~38 cobblestone 0  
fill ~37 ~11 ~40 ~37 ~11 ~41 stone 5  
fill ~38 ~11 ~31 ~39 ~11 ~31 stone 5  
fill ~38 ~11 ~32 ~38 ~12 ~32 stone 5  
fill ~38 ~11 ~33 ~38 ~11 ~31 stone 5  
fill ~38 ~11 ~35 ~38 ~13 ~35 cobblestone 0  
fill ~38 ~11 ~36 ~38 ~12 ~36 stone 5  
fill ~38 ~11 ~39 ~39 ~11 ~39 stone 0  
fill ~38 ~11 ~41 ~38 ~12 ~41 stone 0  
fill ~38 ~11 ~58 ~38 ~12 ~58 cobblestone 0 
setblock ~39 ~11 ~26 cobblestone 0  
fill ~39 ~11 ~27 ~40 ~11 ~27 stone 0 
setblock ~39 ~11 ~28 cobblestone 0  
fill ~39 ~11 ~29 ~39 ~13 ~29 stone 5 
setblock ~39 ~11 ~32 cobblestone 0 
setblock ~39 ~11 ~34 cobblestone 0 
setblock ~39 ~11 ~35 stone 5  
fill ~39 ~11 ~36 ~40 ~11 ~36 cobblestone 0  
fill ~39 ~11 ~40 ~40 ~11 ~40 cobblestone 0  
fill ~39 ~11 ~42 ~39 ~12 ~42 stone 0 
setblock ~39 ~11 ~43 stone 5 
setblock ~39 ~11 ~58 stone 5 
setblock ~39 ~11 ~59 stone 0 
setblock ~40 ~11 ~26 stone 5  
fill ~40 ~11 ~29 ~40 ~11 ~30 stone 0 
setblock ~40 ~11 ~31 cobblestone 0  
fill ~40 ~11 ~32 ~41 ~11 ~32 stone 5 
setblock ~40 ~11 ~33 cobblestone 0  
fill ~40 ~11 ~35 ~42 ~11 ~35 stone 0 
setblock ~40 ~11 ~39 stone 5  
fill ~40 ~11 ~41 ~40 ~13 ~41 stone 5 
setblock ~40 ~11 ~43 stone 0 
setblock ~40 ~11 ~44 stone 5  
fill ~41 ~11 ~24 ~41 ~12 ~24 stone 5 
setblock ~41 ~11 ~25 stone 0  
fill ~41 ~11 ~27 ~42 ~11 ~27 cobblestone 0  
fill ~41 ~11 ~28 ~42 ~11 ~28 stone 0  
fill ~41 ~11 ~29 ~41 ~12 ~29 stone 5  
fill ~41 ~11 ~30 ~41 ~15 ~30 cobblestone 0 
setblock ~41 ~11 ~31 stone 5  
fill ~41 ~11 ~34 ~41 ~12 ~34 stone 0 
setblock ~41 ~11 ~36 stone 5  
fill ~41 ~11 ~44 ~41 ~12 ~44 stone 0  
fill ~41 ~11 ~45 ~41 ~11 ~44 stone 0 
setblock ~42 ~11 ~25 cobblestone 0  
fill ~42 ~11 ~26 ~43 ~11 ~26 stone 0  
fill ~42 ~11 ~29 ~42 ~11 ~30 stone 0 
setblock ~42 ~11 ~31 cobblestone 0 
setblock ~42 ~11 ~32 stone 0 
setblock ~42 ~11 ~33 stone 5 
setblock ~42 ~11 ~37 stone 0 
setblock ~42 ~11 ~41 sea_lantern 0  
fill ~42 ~11 ~46 ~42 ~12 ~46 stone 0 
setblock ~43 ~11 ~27 stone 5  
fill ~43 ~11 ~29 ~43 ~13 ~29 stone 5  
fill ~43 ~11 ~31 ~44 ~11 ~31 stone 0 
setblock ~43 ~11 ~33 cobblestone 0  
fill ~43 ~11 ~34 ~44 ~11 ~34 stone 0  
fill ~43 ~11 ~35 ~47 ~11 ~35 sea_lantern 0  
fill ~43 ~11 ~36 ~43 ~12 ~36 stone 0 
setblock ~43 ~11 ~41 ice 0 
setblock ~43 ~11 ~46 cobblestone 0 
setblock ~44 ~11 ~28 stone 5  
fill ~44 ~11 ~32 ~44 ~13 ~32 stone 0  
fill ~44 ~11 ~33 ~45 ~11 ~33 stone 0  
fill ~44 ~11 ~42 ~44 ~25 ~42 quartz_block 0 
setblock ~44 ~11 ~46 stone 5 
setblock ~44 ~11 ~47 cobblestone 0 
setblock ~45 ~11 ~29 cobblestone 0 
setblock ~45 ~11 ~30 stone 0 
setblock ~45 ~11 ~34 cobblestone 0 
setblock ~46 ~11 ~31 cobblestone 0 
setblock ~46 ~11 ~32 stone 0 
setblock ~46 ~11 ~33 stone 5 
setblock ~46 ~11 ~34 stone 0 
setblock ~46 ~11 ~46 stone 0 
setblock ~47 ~11 ~32 stone 5  
fill ~48 ~11 ~33 ~48 ~12 ~33 stone 5 
setblock ~48 ~11 ~41 quartz_block 0 
setblock ~49 ~11 ~42 quartz_block 0 
setblock ~49 ~11 ~45 stone 0 
setblock ~50 ~11 ~33 cobblestone 0 
setblock ~50 ~11 ~44 cobblestone 0  
fill ~51 ~11 ~35 ~51 ~11 ~36 cobblestone 0 
setblock ~51 ~11 ~41 stone 0 
setblock ~51 ~11 ~42 stone 5  
fill ~51 ~11 ~43 ~51 ~12 ~43 stone 0 
setblock ~52 ~11 ~38 cobblestone 0 
setblock ~52 ~11 ~39 stone 0  
fill ~52 ~11 ~40 ~52 ~12 ~40 stone 5 
setblock ~53 ~11 ~38 stone 0  
fill ~57 ~11 ~19 ~57 ~12 ~19 cobblestone 0 
setblock ~58 ~11 ~18 stone 0  
fill ~58 ~11 ~19 ~59 ~11 ~19 stone 5 
setblock ~58 ~11 ~20 stone 0  
fill ~58 ~11 ~53 ~58 ~12 ~53 stone 5 
setblock ~58 ~11 ~54 stone 0  
fill ~58 ~11 ~55 ~59 ~11 ~55 cobblestone 0  
fill ~58 ~11 ~56 ~58 ~11 ~55 cobblestone 0  
fill ~59 ~11 ~21 ~60 ~11 ~21 cobblestone 0  
fill ~59 ~11 ~52 ~60 ~11 ~52 stone 0  
fill ~59 ~11 ~53 ~59 ~11 ~55 cobblestone 0 
setblock ~59 ~11 ~56 stone 5 
setblock ~60 ~11 ~16 stone 5  
fill ~60 ~11 ~19 ~60 ~12 ~19 cobblestone 0  
fill ~60 ~11 ~20 ~61 ~11 ~20 cobblestone 0 
setblock ~60 ~11 ~22 stone 5  
fill ~60 ~11 ~51 ~61 ~11 ~51 stone 5 
setblock ~60 ~11 ~53 stone 0  
fill ~60 ~11 ~54 ~60 ~13 ~54 cobblestone 0  
fill ~60 ~11 ~55 ~60 ~11 ~58 stone 0  
fill ~60 ~11 ~59 ~61 ~11 ~59 cobblestone 0 
setblock ~61 ~11 ~17 stone 5 
setblock ~61 ~11 ~18 stone 0  
fill ~61 ~11 ~19 ~62 ~11 ~19 stone 5 
setblock ~61 ~11 ~21 stone 0 
setblock ~61 ~11 ~55 stone 5  
fill ~61 ~11 ~56 ~61 ~12 ~56 cobblestone 0  
fill ~61 ~11 ~57 ~61 ~12 ~57 stone 0 
setblock ~61 ~11 ~58 cobblestone 0 
setblock ~62 ~11 ~20 stone 0 
setblock ~62 ~11 ~50 cobblestone 0  
fill ~62 ~11 ~53 ~63 ~11 ~53 cobblestone 0 
setblock ~62 ~11 ~54 stone 5  
fill ~62 ~11 ~55 ~63 ~11 ~55 cobblestone 0 
setblock ~62 ~11 ~56 stone 0  
fill ~62 ~11 ~57 ~62 ~13 ~57 stone 5  
fill ~62 ~11 ~58 ~62 ~12 ~58 stone 5  
fill ~62 ~11 ~59 ~62 ~11 ~57 stone 5  
fill ~62 ~11 ~60 ~62 ~13 ~60 stone 0 
setblock ~63 ~11 ~19 stone 0  
fill ~63 ~11 ~20 ~63 ~12 ~20 stone 5  
fill ~63 ~11 ~54 ~64 ~11 ~54 stone 0 
setblock ~63 ~11 ~57 cobblestone 0  
fill ~63 ~11 ~59 ~63 ~12 ~59 stone 0 
setblock ~64 ~11 ~51 stone 5 
setblock ~64 ~11 ~53 stone 0  
fill ~64 ~11 ~55 ~66 ~11 ~55 stone 0  
fill ~64 ~11 ~57 ~64 ~11 ~58 stone 5  
fill ~64 ~11 ~59 ~64 ~8 ~59 cobblestone 0 
setblock ~64 ~11 ~61 cobblestone 0  
fill ~65 ~11 ~52 ~65 ~11 ~53 cobblestone 0  
fill ~65 ~11 ~56 ~65 ~11 ~57 cobblestone 0  
fill ~65 ~11 ~58 ~65 ~12 ~58 stone 5  
fill ~65 ~11 ~59 ~65 ~11 ~58 stone 5 
setblock ~65 ~11 ~60 cobblestone 0 
setblock ~66 ~11 ~53 cobblestone 0  
fill ~66 ~11 ~56 ~66 ~13 ~56 stone 5  
fill ~66 ~11 ~57 ~66 ~11 ~56 stone 5  
fill ~66 ~11 ~58 ~66 ~11 ~59 cobblestone 0  
fill ~68 ~11 ~15 ~68 ~12 ~15 stone 5  
fill ~74 ~11 ~43 ~74 ~12 ~43 stone 5  
fill ~76 ~11 ~29 ~76 ~12 ~29 stone 5 
setblock ~13 ~12 ~23 cobblestone 0  
fill ~13 ~12 ~54 ~13 ~13 ~54 stone 5  
fill ~14 ~12 ~22 ~14 ~13 ~22 stone 0  
fill ~14 ~12 ~23 ~15 ~12 ~23 stone 5  
fill ~14 ~12 ~52 ~15 ~12 ~52 stone 0  
fill ~14 ~12 ~53 ~16 ~12 ~53 stone 0  
fill ~14 ~12 ~54 ~14 ~12 ~56 cobblestone 0  
fill ~14 ~12 ~57 ~14 ~15 ~57 stone 0  
fill ~15 ~12 ~20 ~16 ~12 ~20 cobblestone 0 
setblock ~15 ~12 ~22 cobblestone 0 
setblock ~15 ~12 ~24 stone 5  
fill ~15 ~12 ~55 ~15 ~11 ~55 cobblestone 0  
fill ~15 ~12 ~56 ~15 ~14 ~56 stone 0 
setblock ~15 ~12 ~57 cobblestone 0  
fill ~16 ~12 ~21 ~17 ~12 ~21 cobblestone 0 
setblock ~16 ~12 ~22 stone 0  
fill ~16 ~12 ~23 ~16 ~12 ~24 cobblestone 0  
fill ~16 ~12 ~25 ~17 ~12 ~25 stone 0 
setblock ~16 ~12 ~26 stone 5  
fill ~16 ~12 ~52 ~17 ~12 ~52 stone 5  
fill ~16 ~12 ~54 ~16 ~11 ~54 stone 0  
fill ~16 ~12 ~55 ~16 ~12 ~53 stone 0  
fill ~16 ~12 ~56 ~16 ~13 ~56 cobblestone 0 
setblock ~16 ~12 ~58 stone 5 
setblock ~17 ~12 ~20 stone 0  
fill ~17 ~12 ~23 ~17 ~13 ~23 stone 5  
fill ~17 ~12 ~24 ~18 ~12 ~24 stone 5 
setblock ~17 ~12 ~26 stone 0  
fill ~17 ~12 ~51 ~18 ~12 ~51 cobblestone 0 
setblock ~17 ~12 ~53 cobblestone 0 
setblock ~17 ~12 ~54 stone 5  
fill ~17 ~12 ~55 ~17 ~13 ~55 cobblestone 0  
fill ~17 ~12 ~57 ~18 ~12 ~57 cobblestone 0  
fill ~17 ~12 ~58 ~17 ~13 ~58 stone 0 
setblock ~18 ~12 ~21 stone 5 
setblock ~18 ~12 ~22 stone 0  
fill ~18 ~12 ~23 ~19 ~12 ~23 cobblestone 0  
fill ~18 ~12 ~25 ~19 ~12 ~25 cobblestone 0  
fill ~18 ~12 ~26 ~19 ~12 ~26 cobblestone 0  
fill ~18 ~12 ~52 ~18 ~12 ~54 stone 0  
fill ~18 ~12 ~55 ~20 ~12 ~55 stone 5  
fill ~18 ~12 ~56 ~18 ~14 ~56 stone 5  
fill ~18 ~12 ~58 ~18 ~11 ~58 cobblestone 0  
fill ~19 ~12 ~21 ~19 ~14 ~21 stone 0 
setblock ~19 ~12 ~22 stone 5  
fill ~19 ~12 ~24 ~19 ~13 ~24 cobblestone 0  
fill ~19 ~12 ~51 ~21 ~12 ~51 stone 0  
fill ~19 ~12 ~53 ~19 ~13 ~53 cobblestone 0 
setblock ~19 ~12 ~57 stone 5 
setblock ~19 ~12 ~58 stone 0  
fill ~19 ~12 ~59 ~19 ~14 ~59 cobblestone 0 
setblock ~20 ~12 ~22 cobblestone 0 
setblock ~20 ~12 ~23 stone 0 
setblock ~20 ~12 ~25 stone 0  
fill ~20 ~12 ~52 ~20 ~12 ~53 stone 0  
fill ~20 ~12 ~58 ~20 ~14 ~58 stone 5  
fill ~20 ~12 ~59 ~20 ~14 ~59 stone 5 
setblock ~20 ~12 ~60 stone 0  
fill ~21 ~12 ~52 ~21 ~13 ~52 stone 5  
fill ~21 ~12 ~53 ~21 ~12 ~54 stone 5  
fill ~21 ~12 ~55 ~22 ~12 ~55 stone 0 
setblock ~21 ~12 ~59 stone 0  
fill ~21 ~12 ~60 ~21 ~13 ~60 stone 5 
setblock ~22 ~12 ~61 stone 5  
fill ~29 ~12 ~41 ~30 ~12 ~41 cobblestone 0 
setblock ~30 ~12 ~35 cobblestone 0  
fill ~30 ~12 ~40 ~30 ~13 ~40 stone 5  
fill ~30 ~12 ~42 ~30 ~14 ~42 cobblestone 0  
fill ~31 ~12 ~33 ~32 ~12 ~33 stone 0 
setblock ~31 ~12 ~35 stone 0  
fill ~31 ~12 ~36 ~31 ~14 ~36 cobblestone 0  
fill ~31 ~12 ~39 ~33 ~12 ~39 stone 0 
setblock ~31 ~12 ~41 stone 0  
fill ~31 ~12 ~42 ~32 ~12 ~42 stone 5 
setblock ~32 ~12 ~28 stone 5 
setblock ~32 ~12 ~29 cobblestone 0 
setblock ~32 ~12 ~31 stone 5  
fill ~32 ~12 ~32 ~32 ~13 ~32 cobblestone 0  
fill ~32 ~12 ~34 ~32 ~12 ~35 cobblestone 0  
fill ~32 ~12 ~36 ~33 ~12 ~36 stone 0  
fill ~32 ~12 ~37 ~33 ~12 ~37 cobblestone 0 
setblock ~32 ~12 ~38 stone 0  
fill ~32 ~12 ~40 ~33 ~12 ~40 stone 0 
setblock ~32 ~12 ~41 cobblestone 0  
fill ~33 ~12 ~27 ~36 ~12 ~27 cobblestone 0  
fill ~33 ~12 ~28 ~33 ~12 ~27 cobblestone 0 
setblock ~33 ~12 ~29 stone 5  
fill ~33 ~12 ~30 ~33 ~12 ~31 cobblestone 0  
fill ~33 ~12 ~33 ~34 ~12 ~33 cobblestone 0  
fill ~33 ~12 ~34 ~33 ~15 ~34 stone 0 
setblock ~33 ~12 ~35 stone 5  
fill ~33 ~12 ~38 ~33 ~13 ~38 stone 5 
setblock ~34 ~12 ~28 stone 5  
fill ~34 ~12 ~29 ~36 ~12 ~29 stone 0  
fill ~34 ~12 ~30 ~36 ~12 ~30 stone 5  
fill ~34 ~12 ~31 ~34 ~13 ~31 stone 5  
fill ~34 ~12 ~34 ~34 ~13 ~34 stone 5 
setblock ~34 ~12 ~35 cobblestone 0 
setblock ~34 ~12 ~36 stone 5 
setblock ~34 ~12 ~37 stone 0 
setblock ~34 ~12 ~38 cobblestone 0  
fill ~34 ~12 ~39 ~34 ~15 ~39 stone 5  
fill ~34 ~12 ~40 ~35 ~12 ~40 cobblestone 0  
fill ~35 ~12 ~31 ~36 ~12 ~31 stone 0  
fill ~35 ~12 ~32 ~36 ~12 ~32 cobblestone 0 
setblock ~35 ~12 ~33 stone 5 
setblock ~35 ~12 ~34 cobblestone 0 
setblock ~35 ~12 ~35 stone 5  
fill ~35 ~12 ~37 ~35 ~14 ~37 cobblestone 0 
setblock ~35 ~12 ~38 stone 5 
setblock ~35 ~12 ~39 cobblestone 0 
setblock ~35 ~12 ~41 cobblestone 0 
setblock ~36 ~12 ~28 stone 5  
fill ~36 ~12 ~34 ~37 ~12 ~34 stone 0 
setblock ~36 ~12 ~35 cobblestone 0  
fill ~36 ~12 ~37 ~37 ~12 ~37 stone 0 
setblock ~36 ~12 ~39 stone 0  
fill ~36 ~12 ~41 ~38 ~12 ~41 stone 0 
setblock ~37 ~12 ~27 stone 5  
fill ~37 ~12 ~28 ~37 ~12 ~30 cobblestone 0  
fill ~37 ~12 ~31 ~40 ~12 ~31 stone 5  
fill ~37 ~12 ~32 ~37 ~13 ~32 stone 0  
fill ~37 ~12 ~33 ~37 ~13 ~33 stone 5  
fill ~37 ~12 ~38 ~37 ~13 ~38 cobblestone 0 
setblock ~37 ~12 ~40 stone 0  
fill ~38 ~12 ~26 ~38 ~13 ~26 stone 5  
fill ~38 ~12 ~27 ~38 ~13 ~27 cobblestone 0  
fill ~38 ~12 ~28 ~40 ~12 ~28 stone 5 
setblock ~38 ~12 ~29 stone 0  
fill ~38 ~12 ~30 ~38 ~13 ~30 stone 5  
fill ~38 ~12 ~33 ~38 ~12 ~35 cobblestone 0 
setblock ~38 ~12 ~37 stone 5  
fill ~38 ~12 ~39 ~38 ~9 ~39 stone 0  
fill ~38 ~12 ~42 ~38 ~13 ~42 stone 5 
setblock ~39 ~12 ~25 cobblestone 0  
fill ~39 ~12 ~26 ~40 ~12 ~26 stone 0  
fill ~39 ~12 ~27 ~43 ~12 ~27 stone 0  
fill ~39 ~12 ~30 ~39 ~14 ~30 stone 0  
fill ~39 ~12 ~32 ~39 ~13 ~32 stone 0  
fill ~39 ~12 ~33 ~40 ~12 ~33 stone 0  
fill ~39 ~12 ~34 ~39 ~12 ~32 stone 0  
fill ~39 ~12 ~35 ~40 ~12 ~35 cobblestone 0  
fill ~39 ~12 ~36 ~39 ~13 ~36 stone 0  
fill ~39 ~12 ~37 ~39 ~12 ~38 stone 0  
fill ~39 ~12 ~39 ~39 ~12 ~41 stone 5  
fill ~39 ~12 ~43 ~39 ~14 ~43 stone 0 
setblock ~39 ~12 ~57 stone 0 
setblock ~39 ~12 ~58 cobblestone 0  
fill ~39 ~12 ~59 ~39 ~13 ~59 stone 5  
fill ~40 ~12 ~24 ~40 ~13 ~24 cobblestone 0  
fill ~40 ~12 ~25 ~40 ~13 ~25 stone 5  
fill ~40 ~12 ~29 ~40 ~13 ~29 stone 5 
setblock ~40 ~12 ~30 cobblestone 0  
fill ~40 ~12 ~32 ~42 ~12 ~32 cobblestone 0 
setblock ~40 ~12 ~34 stone 5  
fill ~40 ~12 ~36 ~40 ~12 ~38 stone 5  
fill ~40 ~12 ~39 ~40 ~13 ~39 cobblestone 0  
fill ~40 ~12 ~42 ~41 ~12 ~42 stone 0  
fill ~40 ~12 ~44 ~40 ~13 ~44 stone 0 
setblock ~40 ~12 ~58 stone 5 
setblock ~41 ~12 ~25 cobblestone 0  
fill ~41 ~12 ~26 ~41 ~15 ~26 stone 5  
fill ~41 ~12 ~28 ~41 ~10 ~28 stone 0  
fill ~41 ~12 ~31 ~42 ~12 ~31 stone 0 
setblock ~41 ~12 ~35 stone 5 
setblock ~41 ~12 ~36 stone 0 
setblock ~41 ~12 ~45 cobblestone 0 
setblock ~41 ~12 ~46 stone 0  
fill ~42 ~12 ~25 ~43 ~12 ~25 stone 0 
setblock ~42 ~12 ~26 cobblestone 0  
fill ~42 ~12 ~28 ~42 ~12 ~29 stone 5 
setblock ~42 ~12 ~30 stone 0  
fill ~42 ~12 ~33 ~43 ~12 ~33 stone 0  
fill ~42 ~12 ~35 ~42 ~13 ~35 stone 0  
fill ~42 ~12 ~37 ~42 ~13 ~37 stone 5 
setblock ~42 ~12 ~40 ice 0 
setblock ~42 ~12 ~41 cobblestone 0 
setblock ~43 ~12 ~22 stone 0  
fill ~43 ~12 ~26 ~43 ~13 ~26 stone 0  
fill ~43 ~12 ~28 ~44 ~12 ~28 stone 0  
fill ~43 ~12 ~31 ~43 ~14 ~31 cobblestone 0 
setblock ~43 ~12 ~34 stone 5  
fill ~43 ~12 ~35 ~47 ~12 ~35 sea_lantern 0  
fill ~43 ~12 ~41 ~43 ~26 ~41 quartz_block 0  
fill ~43 ~12 ~47 ~43 ~13 ~47 cobblestone 0 
setblock ~44 ~12 ~29 cobblestone 0  
fill ~44 ~12 ~30 ~45 ~12 ~30 stone 5  
fill ~44 ~12 ~31 ~44 ~13 ~31 stone 5  
fill ~44 ~12 ~33 ~45 ~12 ~33 stone 5  
fill ~44 ~12 ~34 ~45 ~12 ~34 stone 0  
fill ~44 ~12 ~47 ~44 ~13 ~47 stone 0 
setblock ~45 ~12 ~28 stone 5  
fill ~45 ~12 ~29 ~46 ~12 ~29 stone 0  
fill ~45 ~12 ~32 ~45 ~13 ~32 stone 5 
setblock ~45 ~12 ~47 stone 5 
setblock ~46 ~12 ~30 cobblestone 0  
fill ~46 ~12 ~31 ~46 ~16 ~31 stone 5  
fill ~46 ~12 ~32 ~47 ~12 ~32 cobblestone 0  
fill ~46 ~12 ~33 ~46 ~13 ~33 cobblestone 0  
fill ~46 ~12 ~34 ~46 ~12 ~32 cobblestone 0  
fill ~46 ~12 ~46 ~47 ~12 ~46 cobblestone 0 
setblock ~48 ~12 ~32 stone 0  
fill ~49 ~12 ~33 ~50 ~12 ~33 stone 0 
setblock ~49 ~12 ~45 stone 5 
setblock ~50 ~12 ~44 stone 5 
setblock ~51 ~12 ~34 cobblestone 0 
setblock ~51 ~12 ~35 stone 5  
fill ~51 ~12 ~42 ~52 ~12 ~42 stone 0  
fill ~51 ~12 ~44 ~51 ~13 ~44 cobblestone 0  
fill ~52 ~12 ~36 ~52 ~12 ~37 cobblestone 0 
setblock ~52 ~12 ~41 stone 0  
fill ~53 ~12 ~38 ~53 ~14 ~38 stone 5  
fill ~53 ~12 ~39 ~53 ~13 ~39 stone 0  
fill ~57 ~12 ~18 ~57 ~13 ~18 stone 0  
fill ~57 ~12 ~20 ~57 ~12 ~21 stone 0 
setblock ~57 ~12 ~54 cobblestone 0  
fill ~58 ~12 ~18 ~58 ~14 ~18 stone 5  
fill ~58 ~12 ~19 ~59 ~12 ~19 stone 0 
setblock ~58 ~12 ~20 cobblestone 0 
setblock ~58 ~12 ~21 stone 0  
fill ~58 ~12 ~22 ~58 ~13 ~22 stone 5  
fill ~58 ~12 ~54 ~58 ~12 ~55 stone 5  
fill ~58 ~12 ~56 ~58 ~14 ~56 stone 0 
setblock ~58 ~12 ~57 cobblestone 0 
setblock ~59 ~12 ~17 stone 5  
fill ~59 ~12 ~18 ~59 ~14 ~18 stone 0  
fill ~59 ~12 ~20 ~59 ~13 ~20 stone 0 
setblock ~59 ~12 ~21 stone 5  
fill ~59 ~12 ~22 ~59 ~13 ~22 cobblestone 0 
setblock ~59 ~12 ~23 stone 0  
fill ~59 ~12 ~51 ~59 ~12 ~52 cobblestone 0  
fill ~59 ~12 ~53 ~59 ~16 ~53 stone 0 
setblock ~59 ~12 ~54 cobblestone 0 
setblock ~59 ~12 ~55 stone 0  
fill ~59 ~12 ~56 ~59 ~14 ~56 cobblestone 0  
fill ~59 ~12 ~58 ~59 ~13 ~58 cobblestone 0 
setblock ~60 ~12 ~16 stone 0 
setblock ~60 ~12 ~18 cobblestone 0  
fill ~60 ~12 ~20 ~61 ~12 ~20 stone 5  
fill ~60 ~12 ~21 ~62 ~12 ~21 cobblestone 0 
setblock ~60 ~12 ~22 stone 0  
fill ~60 ~12 ~23 ~61 ~12 ~23 cobblestone 0  
fill ~60 ~12 ~51 ~60 ~11 ~51 stone 5  
fill ~60 ~12 ~52 ~60 ~13 ~52 stone 0 
setblock ~60 ~12 ~53 stone 5  
fill ~60 ~12 ~55 ~63 ~12 ~55 cobblestone 0  
fill ~60 ~12 ~56 ~60 ~13 ~56 stone 0 
setblock ~60 ~12 ~57 cobblestone 0  
fill ~60 ~12 ~58 ~61 ~12 ~58 stone 0 
setblock ~61 ~12 ~17 cobblestone 0 
setblock ~61 ~12 ~18 stone 5  
fill ~61 ~12 ~19 ~62 ~12 ~19 stone 0  
fill ~61 ~12 ~22 ~62 ~12 ~22 cobblestone 0  
fill ~61 ~12 ~50 ~63 ~12 ~50 stone 5 
setblock ~61 ~12 ~51 cobblestone 0 
setblock ~61 ~12 ~52 stone 5  
fill ~61 ~12 ~53 ~61 ~13 ~53 stone 0  
fill ~61 ~12 ~54 ~62 ~12 ~54 stone 0 
setblock ~61 ~12 ~59 stone 0  
fill ~62 ~12 ~17 ~62 ~14 ~17 stone 0 
setblock ~62 ~12 ~20 cobblestone 0  
fill ~62 ~12 ~53 ~62 ~11 ~53 cobblestone 0 
setblock ~62 ~12 ~56 cobblestone 0  
fill ~62 ~12 ~59 ~62 ~15 ~59 cobblestone 0  
fill ~63 ~12 ~18 ~63 ~12 ~21 stone 5 
setblock ~63 ~12 ~49 stone 0  
fill ~63 ~12 ~51 ~65 ~12 ~51 cobblestone 0 
setblock ~63 ~12 ~52 stone 0  
fill ~63 ~12 ~53 ~64 ~12 ~53 stone 5  
fill ~63 ~12 ~54 ~64 ~12 ~54 cobblestone 0  
fill ~63 ~12 ~57 ~65 ~12 ~57 stone 0 
setblock ~63 ~12 ~60 stone 5 
setblock ~64 ~12 ~20 stone 0  
fill ~64 ~12 ~21 ~64 ~13 ~21 stone 5 
setblock ~64 ~12 ~22 stone 0 
setblock ~64 ~12 ~50 stone 0 
setblock ~64 ~12 ~52 stone 5  
fill ~64 ~12 ~55 ~64 ~13 ~55 stone 5  
fill ~64 ~12 ~56 ~66 ~12 ~56 stone 5  
fill ~64 ~12 ~58 ~64 ~12 ~59 stone 5  
fill ~64 ~12 ~60 ~65 ~12 ~60 stone 0  
fill ~64 ~12 ~61 ~65 ~12 ~61 stone 0  
fill ~65 ~12 ~52 ~66 ~12 ~52 stone 0  
fill ~65 ~12 ~53 ~65 ~12 ~52 stone 0 
setblock ~65 ~12 ~55 stone 0 
setblock ~65 ~12 ~59 stone 0  
fill ~66 ~12 ~53 ~66 ~12 ~56 stone 5  
fill ~66 ~12 ~57 ~66 ~13 ~57 cobblestone 0 
setblock ~66 ~12 ~58 stone 5  
fill ~66 ~12 ~59 ~66 ~13 ~59 cobblestone 0 
setblock ~67 ~12 ~56 stone 0 
setblock ~67 ~12 ~57 stone 5 
setblock ~75 ~12 ~28 stone 5 
setblock ~75 ~12 ~29 stone 0  
fill ~75 ~12 ~30 ~75 ~14 ~30 stone 5 
setblock ~13 ~13 ~23 stone 5  
fill ~13 ~13 ~53 ~14 ~13 ~53 stone 5  
fill ~13 ~13 ~55 ~13 ~15 ~55 cobblestone 0  
fill ~14 ~13 ~23 ~16 ~13 ~23 stone 0  
fill ~14 ~13 ~24 ~14 ~14 ~24 stone 5  
fill ~14 ~13 ~52 ~14 ~14 ~52 stone 5 
setblock ~14 ~13 ~54 stone 0  
fill ~14 ~13 ~55 ~16 ~13 ~55 stone 5  
fill ~14 ~13 ~56 ~14 ~14 ~56 stone 0  
fill ~15 ~13 ~20 ~16 ~13 ~20 stone 5 
setblock ~15 ~13 ~22 stone 0 
setblock ~15 ~13 ~24 stone 0 
setblock ~15 ~13 ~25 stone 5 
setblock ~15 ~13 ~26 stone 0  
fill ~15 ~13 ~52 ~15 ~13 ~53 stone 0 
setblock ~15 ~13 ~57 stone 0 
setblock ~15 ~13 ~58 cobblestone 0 
setblock ~16 ~13 ~21 stone 0 
setblock ~16 ~13 ~22 stone 5  
fill ~16 ~13 ~24 ~16 ~14 ~24 stone 5  
fill ~16 ~13 ~25 ~16 ~14 ~25 stone 0  
fill ~16 ~13 ~26 ~17 ~13 ~26 cobblestone 0  
fill ~16 ~13 ~27 ~17 ~13 ~27 cobblestone 0  
fill ~16 ~13 ~52 ~17 ~13 ~52 stone 5  
fill ~16 ~13 ~53 ~17 ~13 ~53 stone 5  
fill ~16 ~13 ~54 ~16 ~16 ~54 stone 5  
fill ~16 ~13 ~58 ~16 ~14 ~58 stone 0  
fill ~17 ~13 ~20 ~17 ~17 ~20 cobblestone 0  
fill ~17 ~13 ~21 ~18 ~13 ~21 cobblestone 0  
fill ~17 ~13 ~22 ~17 ~13 ~20 cobblestone 0  
fill ~17 ~13 ~24 ~17 ~14 ~24 cobblestone 0  
fill ~17 ~13 ~25 ~17 ~13 ~24 cobblestone 0  
fill ~17 ~13 ~51 ~17 ~12 ~51 cobblestone 0  
fill ~17 ~13 ~54 ~18 ~13 ~54 cobblestone 0  
fill ~17 ~13 ~57 ~18 ~13 ~57 stone 5 
setblock ~17 ~13 ~59 stone 5 
setblock ~18 ~13 ~20 stone 0  
fill ~18 ~13 ~22 ~18 ~13 ~23 stone 5 
setblock ~18 ~13 ~24 stone 0  
fill ~18 ~13 ~25 ~18 ~13 ~26 stone 5 
setblock ~18 ~13 ~27 stone 0 
setblock ~18 ~13 ~50 cobblestone 0 
setblock ~18 ~13 ~51 stone 0  
fill ~18 ~13 ~52 ~18 ~15 ~52 cobblestone 0  
fill ~18 ~13 ~53 ~18 ~13 ~52 cobblestone 0  
fill ~18 ~13 ~55 ~18 ~14 ~55 stone 5 
setblock ~18 ~13 ~58 stone 0 
setblock ~19 ~13 ~22 cobblestone 0  
fill ~19 ~13 ~23 ~19 ~14 ~23 stone 0  
fill ~19 ~13 ~25 ~19 ~14 ~25 stone 0  
fill ~19 ~13 ~26 ~19 ~15 ~26 cobblestone 0  
fill ~19 ~13 ~51 ~20 ~13 ~51 stone 5 
setblock ~19 ~13 ~52 stone 0  
fill ~19 ~13 ~54 ~20 ~13 ~54 stone 5  
fill ~19 ~13 ~55 ~22 ~13 ~55 stone 0  
fill ~19 ~13 ~56 ~19 ~13 ~55 stone 0  
fill ~19 ~13 ~57 ~20 ~13 ~57 cobblestone 0  
fill ~19 ~13 ~58 ~19 ~13 ~57 cobblestone 0  
fill ~19 ~13 ~60 ~19 ~16 ~60 stone 0 
setblock ~20 ~13 ~22 stone 0  
fill ~20 ~13 ~23 ~20 ~14 ~23 stone 5  
fill ~20 ~13 ~24 ~20 ~14 ~24 stone 5  
fill ~20 ~13 ~25 ~20 ~13 ~23 stone 5 
setblock ~20 ~13 ~26 stone 0  
fill ~20 ~13 ~52 ~20 ~14 ~52 cobblestone 0  
fill ~20 ~13 ~53 ~20 ~13 ~52 cobblestone 0 
setblock ~20 ~13 ~60 cobblestone 0 
setblock ~21 ~13 ~25 stone 0  
fill ~21 ~13 ~51 ~22 ~13 ~51 cobblestone 0  
fill ~21 ~13 ~53 ~21 ~13 ~55 stone 0  
fill ~21 ~13 ~59 ~22 ~13 ~59 cobblestone 0  
fill ~21 ~13 ~61 ~21 ~14 ~61 stone 0 
setblock ~22 ~13 ~50 stone 5 
setblock ~22 ~13 ~60 stone 0 
setblock ~22 ~13 ~61 cobblestone 0  
fill ~23 ~13 ~62 ~23 ~15 ~62 cobblestone 0  
fill ~28 ~13 ~41 ~28 ~14 ~41 stone 5  
fill ~29 ~13 ~35 ~30 ~13 ~35 stone 5  
fill ~29 ~13 ~39 ~30 ~13 ~39 stone 5 
setblock ~29 ~13 ~40 stone 0  
fill ~29 ~13 ~41 ~29 ~12 ~41 cobblestone 0 
setblock ~30 ~13 ~34 stone 0 
setblock ~30 ~13 ~38 cobblestone 0 
setblock ~30 ~13 ~41 stone 0  
fill ~30 ~13 ~43 ~30 ~16 ~43 stone 5  
fill ~31 ~13 ~32 ~31 ~13 ~37 cobblestone 0 
setblock ~31 ~13 ~38 stone 5  
fill ~31 ~13 ~39 ~32 ~13 ~39 cobblestone 0  
fill ~31 ~13 ~41 ~31 ~15 ~41 cobblestone 0  
fill ~31 ~13 ~42 ~32 ~13 ~42 stone 5 
setblock ~31 ~13 ~43 cobblestone 0 
setblock ~31 ~13 ~44 stone 0 
setblock ~32 ~13 ~27 stone 5  
fill ~32 ~13 ~28 ~32 ~13 ~31 stone 0 
setblock ~32 ~13 ~33 stone 5 
setblock ~32 ~13 ~34 stone 0 
setblock ~32 ~13 ~35 stone 5  
fill ~32 ~13 ~36 ~34 ~13 ~36 stone 0  
fill ~32 ~13 ~37 ~33 ~13 ~37 stone 0 
setblock ~32 ~13 ~38 cobblestone 0  
fill ~32 ~13 ~40 ~36 ~13 ~40 stone 0  
fill ~32 ~13 ~41 ~33 ~13 ~41 stone 5 
setblock ~32 ~13 ~43 stone 5  
fill ~33 ~13 ~27 ~33 ~15 ~27 stone 0 
setblock ~33 ~13 ~28 stone 5 
setblock ~33 ~13 ~29 cobblestone 0 
setblock ~33 ~13 ~30 stone 5  
