setblock ~33 ~36 ~81 chest 3  
setblock ~32 ~36 ~81 chest 3  
setblock ~46 ~22 ~92 hopper 0  
fill ~-10 ~0 ~107 ~-9 ~0 ~107 grass 0  
fill ~-10 ~0 ~108 ~-9 ~0 ~108 grass 0  
fill ~-9 ~0 ~106 ~-8 ~0 ~106 grass 0 
setblock ~-9 ~0 ~109 grass 0  
fill ~-9 ~0 ~116 ~-7 ~0 ~116 grass 0  
fill ~-9 ~0 ~117 ~-7 ~0 ~117 grass 0  
fill ~-9 ~0 ~118 ~-8 ~0 ~118 grass 0 
setblock ~-8 ~0 ~105 grass 0  
fill ~-8 ~0 ~107 ~12 ~0 ~107 stone 0  
fill ~-8 ~0 ~108 ~12 ~0 ~108 stone 0  
fill ~-8 ~0 ~109 ~12 ~0 ~109 stone 0 
setblock ~-8 ~0 ~110 grass 0  
fill ~-8 ~0 ~119 ~-8 ~0 ~120 grass 0  
fill ~-7 ~0 ~104 ~13 ~0 ~104 stone 0  
fill ~-7 ~0 ~105 ~13 ~0 ~105 stone 0  
fill ~-7 ~0 ~106 ~12 ~0 ~106 stone 0  
fill ~-7 ~0 ~110 ~14 ~0 ~110 stone 0  
fill ~-7 ~0 ~111 ~15 ~0 ~111 stone 0  
fill ~-7 ~0 ~112 ~15 ~0 ~112 stone 0  
fill ~-7 ~0 ~113 ~16 ~0 ~113 stone 0  
fill ~-7 ~0 ~114 ~16 ~0 ~114 stone 0 
setblock ~-7 ~0 ~115 grass 0  
fill ~-7 ~0 ~118 ~15 ~0 ~118 stone 0  
fill ~-7 ~0 ~119 ~16 ~0 ~119 stone 0 
setblock ~-7 ~0 ~120 grass 0 
setblock ~-6 ~0 ~101 grass 0  
fill ~-6 ~0 ~102 ~14 ~0 ~102 stone 0  
fill ~-6 ~0 ~103 ~14 ~0 ~103 stone 0  
fill ~-6 ~0 ~115 ~16 ~0 ~115 stone 0  
fill ~-6 ~0 ~117 ~15 ~0 ~117 stone 0  
fill ~-6 ~0 ~120 ~16 ~0 ~120 stone 0 
setblock ~-6 ~0 ~121 grass 0  
fill ~-5 ~0 ~81 ~-5 ~0 ~83 grass 0  
fill ~-5 ~0 ~101 ~14 ~0 ~101 stone 0  
fill ~-5 ~0 ~116 ~15 ~0 ~116 stone 0  
fill ~-5 ~0 ~121 ~17 ~0 ~121 stone 0  
fill ~-5 ~0 ~122 ~31 ~0 ~122 stone 0 
setblock ~-5 ~0 ~123 grass 0  
fill ~-4 ~0 ~80 ~-3 ~0 ~80 grass 0  
fill ~-4 ~0 ~81 ~11 ~0 ~81 stone 0  
fill ~-4 ~0 ~82 ~10 ~0 ~82 stone 0  
fill ~-4 ~0 ~83 ~11 ~0 ~83 stone 0  
fill ~-4 ~0 ~84 ~11 ~0 ~84 stone 0  
fill ~-4 ~0 ~85 ~12 ~0 ~85 stone 0  
fill ~-4 ~0 ~86 ~13 ~0 ~86 stone 0 
setblock ~-4 ~0 ~87 grass 0 
setblock ~-4 ~0 ~100 grass 0  
fill ~-4 ~0 ~123 ~31 ~0 ~123 stone 0  
fill ~-4 ~0 ~124 ~-4 ~0 ~126 grass 0  
fill ~-3 ~0 ~76 ~-3 ~0 ~76 dirt 0  
fill ~-3 ~0 ~78 ~-2 ~0 ~78 grass 0  
fill ~-3 ~0 ~79 ~-2 ~0 ~79 grass 0  
fill ~-3 ~0 ~87 ~13 ~0 ~87 stone 0  
fill ~-3 ~0 ~88 ~13 ~0 ~88 stone 0 
setblock ~-3 ~0 ~91 grass 0  
fill ~-3 ~0 ~92 ~15 ~0 ~92 stone 0  
fill ~-3 ~0 ~93 ~15 ~0 ~93 stone 0  
fill ~-3 ~0 ~94 ~14 ~0 ~94 stone 0 
setblock ~-3 ~0 ~95 grass 0 
setblock ~-3 ~0 ~99 grass 0  
fill ~-3 ~0 ~100 ~13 ~0 ~100 stone 0  
fill ~-3 ~0 ~124 ~32 ~0 ~124 stone 0  
fill ~-3 ~0 ~125 ~32 ~0 ~125 stone 0  
fill ~-3 ~0 ~126 ~32 ~0 ~126 stone 0  
fill ~-3 ~0 ~127 ~-2 ~0 ~127 grass 0  
fill ~-3 ~0 ~128 ~-2 ~0 ~128 grass 0  
fill ~-2 ~0 ~75 ~13 ~0 ~75 stone 0  
fill ~-2 ~0 ~76 ~12 ~0 ~76 stone 0 
setblock ~-2 ~0 ~77 grass 0  
fill ~-2 ~0 ~80 ~11 ~0 ~80 stone 0  
fill ~-2 ~0 ~89 ~14 ~0 ~89 stone 0  
fill ~-2 ~0 ~90 ~14 ~0 ~90 stone 0  
fill ~-2 ~0 ~91 ~15 ~0 ~91 stone 0  
fill ~-2 ~0 ~95 ~14 ~0 ~95 stone 0  
fill ~-2 ~0 ~96 ~13 ~0 ~96 stone 0  
fill ~-2 ~0 ~97 ~-2 ~0 ~98 grass 0  
fill ~-2 ~0 ~99 ~13 ~0 ~99 stone 0  
fill ~-2 ~0 ~129 ~-1 ~0 ~129 grass 0  
fill ~-1 ~0 ~74 ~14 ~0 ~74 stone 0  
fill ~-1 ~0 ~77 ~11 ~0 ~77 stone 0  
fill ~-1 ~0 ~78 ~11 ~0 ~78 stone 0  
fill ~-1 ~0 ~79 ~11 ~0 ~79 stone 0  
fill ~-1 ~0 ~97 ~11 ~0 ~97 stone 0  
fill ~-1 ~0 ~98 ~12 ~0 ~98 stone 0  
fill ~-1 ~0 ~127 ~31 ~0 ~127 stone 0  
fill ~-1 ~0 ~128 ~105 ~0 ~128 stone 0  
fill ~0 ~0 ~73 ~14 ~0 ~73 stone 0  
fill ~0 ~0 ~129 ~104 ~0 ~129 stone 0  
fill ~0 ~0 ~130 ~0 ~0 ~136 grass 0  
fill ~0 ~0 ~138 ~2 ~0 ~138 grass 0 
setblock ~1 ~0 ~69 grass 0  
fill ~1 ~0 ~70 ~17 ~0 ~70 stone 0  
fill ~1 ~0 ~71 ~16 ~0 ~71 stone 0  
fill ~1 ~0 ~72 ~15 ~0 ~72 stone 0  
fill ~1 ~0 ~130 ~104 ~0 ~130 stone 0  
fill ~1 ~0 ~131 ~103 ~0 ~131 stone 0  
fill ~1 ~0 ~132 ~1 ~0 ~133 grass 0  
fill ~1 ~0 ~134 ~104 ~0 ~134 stone 0  
fill ~1 ~0 ~135 ~1 ~0 ~138 grass 0  
fill ~2 ~0 ~68 ~19 ~0 ~68 stone 0  
fill ~2 ~0 ~69 ~18 ~0 ~69 stone 0  
fill ~2 ~0 ~132 ~104 ~0 ~132 stone 0  
fill ~2 ~0 ~133 ~104 ~0 ~133 stone 0  
fill ~2 ~0 ~135 ~104 ~0 ~135 stone 0  
fill ~2 ~0 ~136 ~103 ~0 ~136 stone 0  
fill ~2 ~0 ~137 ~69 ~0 ~137 stone 0  
fill ~2 ~0 ~139 ~3 ~0 ~139 grass 0  
fill ~2 ~0 ~140 ~4 ~0 ~140 grass 0  
fill ~3 ~0 ~67 ~19 ~0 ~67 stone 0  
fill ~3 ~0 ~138 ~59 ~0 ~138 stone 0  
fill ~3 ~0 ~141 ~5 ~0 ~141 grass 0  
fill ~4 ~0 ~66 ~20 ~0 ~66 stone 0  
fill ~4 ~0 ~139 ~56 ~0 ~139 stone 0  
fill ~5 ~0 ~63 ~21 ~0 ~63 stone 0  
fill ~5 ~0 ~64 ~20 ~0 ~64 stone 0  
fill ~5 ~0 ~65 ~20 ~0 ~65 stone 0  
fill ~5 ~0 ~140 ~56 ~0 ~140 stone 0  
fill ~6 ~0 ~62 ~21 ~0 ~62 stone 0  
fill ~6 ~0 ~141 ~56 ~0 ~141 stone 0  
fill ~7 ~0 ~57 ~29 ~0 ~57 stone 0  
fill ~7 ~0 ~58 ~22 ~0 ~58 stone 0  
fill ~7 ~0 ~59 ~21 ~0 ~59 stone 0  
fill ~7 ~0 ~60 ~21 ~0 ~60 stone 0  
fill ~7 ~0 ~61 ~21 ~0 ~61 stone 0  
fill ~7 ~0 ~142 ~8 ~0 ~142 grass 0  
fill ~8 ~0 ~55 ~31 ~0 ~55 stone 0  
fill ~8 ~0 ~56 ~30 ~0 ~56 stone 0  
fill ~8 ~0 ~143 ~11 ~0 ~143 grass 0  
fill ~9 ~0 ~54 ~32 ~0 ~54 stone 0  
fill ~9 ~0 ~142 ~10 ~0 ~142 stone 0  
fill ~10 ~0 ~53 ~33 ~0 ~53 stone 0  
fill ~11 ~0 ~52 ~33 ~0 ~52 stone 0 
setblock ~11 ~0 ~82 grass 0 
setblock ~11 ~0 ~142 grass 0  
fill ~12 ~0 ~51 ~34 ~0 ~51 stone 0  
fill ~12 ~0 ~77 ~12 ~0 ~79 grass 0 
setblock ~12 ~0 ~84 grass 0 
setblock ~12 ~0 ~97 grass 0  
fill ~12 ~0 ~142 ~56 ~0 ~142 stone 0  
fill ~12 ~0 ~143 ~56 ~0 ~143 stone 0 
setblock ~12 ~0 ~144 grass 0  
fill ~13 ~0 ~50 ~35 ~0 ~50 stone 0 
setblock ~13 ~0 ~98 grass 0 
setblock ~13 ~0 ~106 grass 0 
setblock ~13 ~0 ~109 grass 0  
fill ~13 ~0 ~144 ~56 ~0 ~144 stone 0 
setblock ~13 ~0 ~145 grass 0 
setblock ~14 ~0 ~88 grass 0 
setblock ~14 ~0 ~96 grass 0 
setblock ~14 ~0 ~100 grass 0 
setblock ~14 ~0 ~104 grass 0  
fill ~14 ~0 ~145 ~56 ~0 ~145 stone 0 
setblock ~15 ~0 ~90 grass 0 
setblock ~15 ~0 ~94 grass 0 
setblock ~15 ~0 ~110 grass 0  
fill ~15 ~0 ~146 ~55 ~0 ~146 stone 0  
fill ~16 ~0 ~46 ~39 ~0 ~46 stone 0  
fill ~16 ~0 ~47 ~39 ~0 ~47 stone 0 
setblock ~16 ~0 ~48 grass 0  
fill ~16 ~0 ~49 ~36 ~0 ~49 stone 0 
setblock ~16 ~0 ~112 grass 0 
setblock ~16 ~0 ~116 grass 0  
fill ~17 ~0 ~42 ~18 ~0 ~42 grass 0  
fill ~17 ~0 ~43 ~17 ~0 ~42 grass 0  
fill ~17 ~0 ~44 ~40 ~0 ~44 stone 0  
fill ~17 ~0 ~45 ~39 ~0 ~45 stone 0  
fill ~17 ~0 ~48 ~38 ~0 ~48 stone 0  
fill ~18 ~0 ~43 ~41 ~0 ~43 stone 0 
setblock ~18 ~0 ~121 grass 0  
fill ~19 ~0 ~42 ~43 ~0 ~42 stone 0  
fill ~19 ~0 ~147 ~55 ~0 ~147 stone 0  
fill ~20 ~0 ~40 ~20 ~0 ~41 grass 0 
setblock ~20 ~0 ~67 grass 0  
fill ~20 ~0 ~121 ~23 ~0 ~121 grass 0  
fill ~20 ~0 ~148 ~22 ~0 ~148 stone 0  
fill ~21 ~0 ~41 ~22 ~0 ~41 stone 0 
setblock ~21 ~0 ~64 grass 0  
fill ~22 ~0 ~59 ~22 ~0 ~61 grass 0  
fill ~23 ~0 ~41 ~25 ~0 ~41 grass 0 
setblock ~24 ~0 ~58 grass 0  
fill ~24 ~0 ~121 ~30 ~0 ~121 stone 0  
fill ~24 ~0 ~148 ~54 ~0 ~148 stone 0  
fill ~25 ~0 ~58 ~27 ~0 ~58 stone 0 
setblock ~25 ~0 ~120 grass 0  
fill ~25 ~0 ~149 ~27 ~0 ~149 grass 0  
fill ~26 ~0 ~25 ~26 ~0 ~25 dirt 0 
setblock ~26 ~0 ~26 grass 0  
fill ~26 ~0 ~120 ~28 ~0 ~120 stone 0 
setblock ~27 ~0 ~20 grass 0  
fill ~27 ~0 ~21 ~54 ~0 ~21 stone 0  
fill ~27 ~0 ~22 ~54 ~0 ~22 stone 0  
fill ~27 ~0 ~23 ~54 ~0 ~23 stone 0  
fill ~27 ~0 ~24 ~54 ~0 ~24 stone 0  
fill ~27 ~0 ~25 ~54 ~0 ~25 stone 0  
fill ~27 ~0 ~26 ~53 ~0 ~26 stone 0  
fill ~27 ~0 ~27 ~27 ~0 ~28 grass 0  
fill ~27 ~0 ~41 ~28 ~0 ~41 grass 0 
setblock ~28 ~0 ~18 grass 0  
fill ~28 ~0 ~19 ~52 ~0 ~19 stone 0  
fill ~28 ~0 ~20 ~53 ~0 ~20 stone 0  
fill ~28 ~0 ~27 ~52 ~0 ~27 stone 0  
fill ~28 ~0 ~28 ~52 ~0 ~28 stone 0  
fill ~28 ~0 ~29 ~28 ~0 ~29 dirt 0 
setblock ~28 ~0 ~40 grass 0 
setblock ~28 ~0 ~58 grass 0 
setblock ~29 ~0 ~17 grass 0  
fill ~29 ~0 ~18 ~51 ~0 ~18 stone 0  
fill ~29 ~0 ~29 ~53 ~0 ~29 stone 0  
fill ~29 ~0 ~30 ~29 ~0 ~32 grass 0  
fill ~29 ~0 ~39 ~30 ~0 ~39 grass 0  
fill ~29 ~0 ~40 ~29 ~0 ~40 dirt 0  
fill ~29 ~0 ~41 ~44 ~0 ~41 stone 0  
fill ~29 ~0 ~149 ~53 ~0 ~149 stone 0  
fill ~30 ~0 ~16 ~31 ~0 ~16 grass 0  
fill ~30 ~0 ~17 ~51 ~0 ~17 stone 0  
fill ~30 ~0 ~30 ~53 ~0 ~30 stone 0  
fill ~30 ~0 ~31 ~30 ~0 ~39 grass 0  
fill ~30 ~0 ~40 ~44 ~0 ~40 stone 0 
setblock ~30 ~0 ~57 grass 0  
fill ~30 ~0 ~150 ~32 ~0 ~150 grass 0  
fill ~31 ~0 ~31 ~53 ~0 ~31 stone 0  
fill ~31 ~0 ~32 ~32 ~0 ~32 grass 0  
fill ~31 ~0 ~33 ~32 ~0 ~33 grass 0  
fill ~31 ~0 ~34 ~32 ~0 ~34 grass 0  
fill ~31 ~0 ~35 ~51 ~0 ~35 stone 0  
fill ~31 ~0 ~36 ~50 ~0 ~36 stone 0  
fill ~31 ~0 ~37 ~45 ~0 ~37 stone 0  
fill ~31 ~0 ~38 ~45 ~0 ~38 stone 0  
fill ~31 ~0 ~39 ~45 ~0 ~39 stone 0 
setblock ~31 ~0 ~56 grass 0  
fill ~32 ~0 ~16 ~51 ~0 ~16 stone 0 
setblock ~32 ~0 ~123 grass 0 
setblock ~32 ~0 ~127 grass 0  
fill ~33 ~0 ~15 ~34 ~0 ~15 grass 0  
fill ~33 ~0 ~32 ~53 ~0 ~32 stone 0  
fill ~33 ~0 ~33 ~53 ~0 ~33 stone 0  
fill ~33 ~0 ~34 ~52 ~0 ~34 stone 0  
fill ~33 ~0 ~150 ~33 ~0 ~150 dirt 0  
fill ~33 ~0 ~151 ~38 ~0 ~151 grass 0 
setblock ~34 ~0 ~14 grass 0  
fill ~34 ~0 ~150 ~38 ~0 ~150 stone 0  
fill ~35 ~0 ~11 ~36 ~0 ~11 grass 0  
fill ~35 ~0 ~12 ~36 ~0 ~12 grass 0  
fill ~35 ~0 ~13 ~58 ~0 ~13 stone 0  
fill ~35 ~0 ~14 ~56 ~0 ~14 stone 0  
fill ~35 ~0 ~15 ~52 ~0 ~15 stone 0 
setblock ~35 ~0 ~126 grass 0  
fill ~35 ~0 ~127 ~43 ~0 ~127 stone 0  
fill ~36 ~0 ~10 ~37 ~0 ~10 grass 0  
fill ~36 ~0 ~126 ~42 ~0 ~126 stone 0  
fill ~37 ~0 ~9 ~38 ~0 ~9 grass 0  
fill ~37 ~0 ~11 ~92 ~0 ~11 stone 0  
fill ~37 ~0 ~12 ~92 ~0 ~12 stone 0 
setblock ~37 ~0 ~125 grass 0  
fill ~37 ~0 ~152 ~40 ~0 ~152 grass 0  
fill ~38 ~0 ~10 ~91 ~0 ~10 stone 0 
setblock ~38 ~0 ~49 grass 0  
fill ~38 ~0 ~125 ~40 ~0 ~125 stone 0  
fill ~39 ~0 ~8 ~90 ~0 ~8 stone 0  
fill ~39 ~0 ~9 ~91 ~0 ~9 stone 0 
setblock ~39 ~0 ~48 grass 0 
setblock ~39 ~0 ~118 grass 0  
fill ~39 ~0 ~119 ~49 ~0 ~119 stone 0  
fill ~39 ~0 ~120 ~62 ~0 ~120 stone 0  
fill ~39 ~0 ~121 ~67 ~0 ~121 stone 0 
setblock ~39 ~0 ~122 grass 0  
fill ~39 ~0 ~150 ~39 ~0 ~150 dirt 0  
fill ~39 ~0 ~151 ~39 ~0 ~151 dirt 0  
fill ~39 ~0 ~153 ~40 ~0 ~153 grass 0  
fill ~39 ~0 ~154 ~50 ~0 ~154 grass 0  
fill ~40 ~0 ~46 ~40 ~0 ~47 grass 0 
setblock ~40 ~0 ~116 grass 0  
fill ~40 ~0 ~117 ~48 ~0 ~117 stone 0  
fill ~40 ~0 ~118 ~48 ~0 ~118 stone 0  
fill ~40 ~0 ~122 ~72 ~0 ~122 stone 0  
fill ~40 ~0 ~123 ~74 ~0 ~123 stone 0 
setblock ~40 ~0 ~124 grass 0  
fill ~40 ~0 ~150 ~52 ~0 ~150 stone 0  
fill ~40 ~0 ~151 ~51 ~0 ~151 stone 0  
fill ~41 ~0 ~116 ~47 ~0 ~116 stone 0  
fill ~41 ~0 ~124 ~75 ~0 ~124 stone 0  
fill ~41 ~0 ~125 ~42 ~0 ~125 grass 0  
fill ~41 ~0 ~152 ~46 ~0 ~152 stone 0  
fill ~41 ~0 ~153 ~45 ~0 ~153 stone 0  
fill ~41 ~0 ~155 ~45 ~0 ~155 grass 0  
fill ~42 ~0 ~7 ~42 ~0 ~7 dirt 0 
setblock ~42 ~0 ~115 grass 0 
setblock ~43 ~0 ~6 grass 0  
fill ~43 ~0 ~7 ~89 ~0 ~7 stone 0  
fill ~43 ~0 ~115 ~45 ~0 ~115 stone 0  
fill ~43 ~0 ~125 ~76 ~0 ~125 stone 0 
setblock ~43 ~0 ~126 grass 0 
setblock ~44 ~0 ~5 grass 0  
fill ~44 ~0 ~6 ~88 ~0 ~6 stone 0 
setblock ~44 ~0 ~127 grass 0 
setblock ~45 ~0 ~4 grass 0  
fill ~45 ~0 ~5 ~84 ~0 ~5 stone 0  
fill ~45 ~0 ~126 ~77 ~0 ~126 stone 0  
fill ~45 ~0 ~127 ~81 ~0 ~127 stone 0  
fill ~46 ~0 ~4 ~46 ~0 ~4 dirt 0 
setblock ~46 ~0 ~115 grass 0  
fill ~46 ~0 ~153 ~51 ~0 ~153 grass 0  
fill ~47 ~0 ~1 ~48 ~0 ~1 grass 0  
fill ~47 ~0 ~2 ~83 ~0 ~2 stone 0  
fill ~47 ~0 ~3 ~83 ~0 ~3 stone 0  
fill ~47 ~0 ~4 ~84 ~0 ~4 stone 0  
fill ~47 ~0 ~152 ~52 ~0 ~152 grass 0  
fill ~48 ~0 ~-1 ~48 ~0 ~1 grass 0 
setblock ~48 ~0 ~116 grass 0  
fill ~49 ~0 ~-1 ~79 ~0 ~-1 stone 0  
fill ~49 ~0 ~0 ~80 ~0 ~0 stone 0  
fill ~49 ~0 ~1 ~82 ~0 ~1 stone 0 
setblock ~49 ~0 ~118 grass 0  
fill ~50 ~0 ~-3 ~77 ~0 ~-3 stone 0  
fill ~50 ~0 ~-2 ~78 ~0 ~-2 stone 0 
setblock ~51 ~0 ~36 grass 0  
fill ~52 ~0 ~-5 ~78 ~0 ~-5 stone 0  
fill ~52 ~0 ~-4 ~77 ~0 ~-4 stone 0 
setblock ~52 ~0 ~35 grass 0  
fill ~52 ~0 ~151 ~53 ~0 ~151 grass 0 
setblock ~53 ~0 ~-6 grass 0 
setblock ~53 ~0 ~34 grass 0  
fill ~53 ~0 ~150 ~54 ~0 ~150 grass 0 
setblock ~54 ~0 ~-7 grass 0  
fill ~54 ~0 ~-6 ~76 ~0 ~-6 stone 0  
fill ~54 ~0 ~149 ~55 ~0 ~149 grass 0  
fill ~55 ~0 ~-9 ~56 ~0 ~-9 grass 0  
fill ~55 ~0 ~-8 ~55 ~0 ~-9 grass 0  
fill ~55 ~0 ~-7 ~70 ~0 ~-7 stone 0 
setblock ~55 ~0 ~119 grass 0  
fill ~55 ~0 ~148 ~56 ~0 ~148 grass 0  
fill ~56 ~0 ~-8 ~70 ~0 ~-8 stone 0  
fill ~56 ~0 ~119 ~58 ~0 ~119 stone 0  
fill ~56 ~0 ~146 ~56 ~0 ~148 grass 0  
fill ~57 ~0 ~-10 ~57 ~0 ~-10 dirt 0  
fill ~57 ~0 ~-9 ~70 ~0 ~-9 stone 0 
setblock ~57 ~0 ~147 grass 0  
fill ~58 ~0 ~-10 ~62 ~0 ~-10 stone 0 
setblock ~59 ~0 ~119 grass 0  
fill ~60 ~0 ~138 ~64 ~0 ~138 grass 0  
fill ~61 ~0 ~21 ~61 ~0 ~25 grass 0 
setblock ~62 ~0 ~20 grass 0  
fill ~62 ~0 ~21 ~68 ~0 ~21 stone 0  
fill ~62 ~0 ~22 ~68 ~0 ~22 stone 0  
fill ~62 ~0 ~23 ~68 ~0 ~23 stone 0  
fill ~62 ~0 ~24 ~68 ~0 ~24 stone 0  
fill ~62 ~0 ~25 ~68 ~0 ~25 stone 0 
setblock ~62 ~0 ~26 grass 0  
fill ~63 ~0 ~-10 ~63 ~1 ~-10 dirt 0  
fill ~63 ~0 ~13 ~92 ~0 ~13 stone 0  
fill ~63 ~0 ~19 ~67 ~0 ~19 grass 0  
fill ~63 ~0 ~20 ~67 ~0 ~20 stone 0  
fill ~63 ~0 ~26 ~67 ~0 ~26 stone 0  
fill ~63 ~0 ~27 ~67 ~0 ~27 grass 0 
setblock ~63 ~0 ~120 grass 0  
fill ~65 ~0 ~14 ~92 ~0 ~14 stone 0  
fill ~65 ~0 ~138 ~67 ~0 ~138 stone 0  
fill ~66 ~0 ~15 ~92 ~0 ~15 stone 0  
fill ~68 ~0 ~16 ~92 ~0 ~16 stone 0 
setblock ~68 ~0 ~20 grass 0 
setblock ~68 ~0 ~26 grass 0 
setblock ~68 ~0 ~121 grass 0 
setblock ~68 ~0 ~138 grass 0  
fill ~69 ~0 ~21 ~69 ~0 ~25 grass 0 
setblock ~70 ~0 ~18 grass 0  
fill ~70 ~0 ~19 ~93 ~0 ~19 stone 0  
fill ~70 ~0 ~20 ~94 ~0 ~20 stone 0  
fill ~70 ~0 ~21 ~96 ~0 ~21 stone 0  
fill ~70 ~0 ~22 ~97 ~0 ~22 stone 0  
fill ~71 ~0 ~-8 ~72 ~0 ~-8 grass 0  
fill ~71 ~0 ~-7 ~72 ~0 ~-7 grass 0  
fill ~71 ~0 ~17 ~93 ~0 ~17 stone 0  
fill ~71 ~0 ~18 ~93 ~0 ~18 stone 0  
fill ~71 ~0 ~23 ~79 ~0 ~23 stone 0  
fill ~72 ~0 ~24 ~78 ~0 ~24 stone 0  
fill ~72 ~0 ~137 ~103 ~0 ~137 stone 0 
setblock ~72 ~0 ~138 grass 0 
setblock ~73 ~0 ~25 grass 0 
setblock ~73 ~0 ~122 grass 0  
fill ~73 ~0 ~138 ~102 ~0 ~138 stone 0 
setblock ~73 ~0 ~139 grass 0  
fill ~74 ~0 ~25 ~76 ~0 ~25 stone 0  
fill ~74 ~0 ~139 ~101 ~0 ~139 stone 0 
setblock ~75 ~0 ~123 grass 0 
setblock ~75 ~0 ~140 grass 0 
setblock ~76 ~0 ~124 grass 0  
fill ~76 ~0 ~140 ~100 ~0 ~140 stone 0 
setblock ~77 ~0 ~-6 grass 0 
setblock ~77 ~0 ~25 grass 0 
setblock ~77 ~0 ~125 grass 0  
fill ~77 ~0 ~141 ~99 ~0 ~141 stone 0  
fill ~77 ~0 ~142 ~98 ~0 ~142 stone 0 
setblock ~77 ~0 ~143 grass 0  
fill ~78 ~0 ~-4 ~78 ~0 ~-3 grass 0 
setblock ~78 ~0 ~126 grass 0  
fill ~78 ~0 ~143 ~97 ~0 ~143 stone 0  
fill ~78 ~0 ~144 ~88 ~0 ~144 stone 0 
setblock ~78 ~0 ~145 grass 0 
setblock ~79 ~0 ~-2 grass 0  
fill ~79 ~0 ~145 ~88 ~0 ~145 stone 0  
fill ~79 ~0 ~146 ~87 ~0 ~146 stone 0  
fill ~79 ~0 ~147 ~80 ~0 ~147 dirt 0  
fill ~79 ~0 ~148 ~87 ~0 ~148 grass 0 
setblock ~80 ~0 ~-1 grass 0 
setblock ~81 ~0 ~0 grass 0 
setblock ~81 ~0 ~23 grass 0  
fill ~81 ~0 ~147 ~85 ~0 ~147 stone 0  
fill ~82 ~0 ~23 ~97 ~0 ~23 stone 0  
fill ~82 ~0 ~24 ~98 ~0 ~24 stone 0 
setblock ~82 ~0 ~25 grass 0 
setblock ~82 ~0 ~127 grass 0  
fill ~83 ~0 ~25 ~98 ~0 ~25 stone 0  
fill ~83 ~0 ~26 ~99 ~0 ~26 stone 0  
fill ~83 ~0 ~27 ~101 ~0 ~27 stone 0  
fill ~84 ~0 ~28 ~102 ~0 ~28 stone 0 
setblock ~84 ~0 ~29 grass 0  
fill ~85 ~0 ~4 ~87 ~0 ~4 grass 0  
fill ~85 ~0 ~5 ~88 ~0 ~5 dirt 0  
fill ~85 ~0 ~29 ~103 ~0 ~29 stone 0  
fill ~85 ~0 ~30 ~104 ~0 ~30 stone 0 
setblock ~85 ~0 ~31 grass 0  
fill ~86 ~0 ~31 ~104 ~0 ~31 stone 0  
fill ~86 ~0 ~32 ~104 ~0 ~32 stone 0 
setblock ~86 ~0 ~33 grass 0  
fill ~86 ~0 ~74 ~108 ~0 ~74 stone 0  
fill ~86 ~0 ~75 ~108 ~0 ~75 stone 0  
fill ~86 ~0 ~76 ~108 ~0 ~76 stone 0  
fill ~86 ~0 ~147 ~86 ~0 ~147 dirt 0  
fill ~87 ~0 ~33 ~104 ~0 ~33 stone 0 
setblock ~87 ~0 ~34 grass 0  
fill ~87 ~0 ~72 ~108 ~0 ~72 stone 0  
fill ~87 ~0 ~73 ~108 ~0 ~73 stone 0  
fill ~87 ~0 ~77 ~107 ~0 ~77 stone 0  
fill ~87 ~0 ~78 ~107 ~0 ~78 stone 0  
fill ~87 ~0 ~79 ~106 ~0 ~79 stone 0  
fill ~87 ~0 ~80 ~104 ~0 ~80 stone 0  
fill ~87 ~0 ~81 ~106 ~0 ~81 stone 0  
fill ~87 ~0 ~82 ~107 ~0 ~82 stone 0  
fill ~87 ~0 ~83 ~107 ~0 ~83 stone 0  
fill ~87 ~0 ~147 ~88 ~0 ~147 grass 0  
fill ~88 ~0 ~34 ~104 ~0 ~34 stone 0 
setblock ~88 ~0 ~67 grass 0  
fill ~88 ~0 ~68 ~101 ~0 ~68 stone 0  
fill ~88 ~0 ~69 ~101 ~0 ~69 stone 0  
fill ~88 ~0 ~70 ~107 ~0 ~70 stone 0  
fill ~88 ~0 ~71 ~108 ~0 ~71 stone 0  
fill ~88 ~0 ~84 ~107 ~0 ~84 stone 0  
fill ~88 ~0 ~85 ~107 ~0 ~85 stone 0  
fill ~88 ~0 ~146 ~94 ~0 ~146 grass 0  
fill ~89 ~0 ~35 ~104 ~0 ~35 stone 0  
fill ~89 ~0 ~36 ~106 ~0 ~36 stone 0  
fill ~89 ~0 ~37 ~107 ~0 ~37 stone 0 
setblock ~89 ~0 ~38 grass 0 
setblock ~89 ~0 ~65 grass 0  
fill ~89 ~0 ~66 ~107 ~0 ~66 stone 0  
fill ~89 ~0 ~67 ~107 ~0 ~67 stone 0  
fill ~89 ~0 ~86 ~107 ~0 ~86 stone 0  
fill ~89 ~0 ~87 ~108 ~0 ~87 stone 0  
fill ~89 ~0 ~144 ~90 ~0 ~144 dirt 0  
fill ~89 ~0 ~145 ~94 ~0 ~145 dirt 0 
setblock ~90 ~0 ~7 grass 0  
fill ~90 ~0 ~38 ~107 ~0 ~38 stone 0  
fill ~90 ~0 ~39 ~108 ~0 ~39 stone 0 
setblock ~90 ~0 ~59 grass 0  
fill ~90 ~0 ~60 ~104 ~0 ~60 stone 0  
fill ~90 ~0 ~61 ~105 ~0 ~61 stone 0  
fill ~90 ~0 ~62 ~105 ~0 ~62 stone 0  
fill ~90 ~0 ~63 ~90 ~0 ~64 grass 0  
fill ~90 ~0 ~65 ~107 ~0 ~65 stone 0  
fill ~90 ~0 ~88 ~108 ~0 ~88 stone 0 
setblock ~91 ~0 ~8 grass 0  
fill ~91 ~0 ~40 ~108 ~0 ~40 stone 0 
setblock ~91 ~0 ~44 grass 0  
fill ~91 ~0 ~45 ~105 ~0 ~45 stone 0  
fill ~91 ~0 ~46 ~104 ~0 ~46 stone 0  
fill ~91 ~0 ~47 ~104 ~0 ~47 stone 0 
setblock ~91 ~0 ~48 grass 0 
setblock ~91 ~0 ~54 grass 0  
fill ~91 ~0 ~55 ~104 ~0 ~55 stone 0  
fill ~91 ~0 ~56 ~104 ~0 ~56 stone 0  
fill ~91 ~0 ~57 ~104 ~0 ~57 stone 0  
fill ~91 ~0 ~58 ~104 ~0 ~58 stone 0  
fill ~91 ~0 ~59 ~104 ~0 ~59 stone 0  
fill ~91 ~0 ~63 ~106 ~0 ~63 stone 0  
fill ~91 ~0 ~64 ~106 ~0 ~64 stone 0  
fill ~91 ~0 ~89 ~108 ~0 ~89 stone 0  
fill ~91 ~0 ~90 ~108 ~0 ~90 stone 0 
setblock ~91 ~0 ~91 grass 0  
fill ~91 ~0 ~123 ~105 ~0 ~123 stone 0  
fill ~91 ~0 ~124 ~104 ~0 ~124 stone 0  
fill ~91 ~0 ~125 ~105 ~0 ~125 stone 0  
fill ~91 ~0 ~126 ~105 ~0 ~126 stone 0  
fill ~91 ~0 ~127 ~105 ~0 ~127 stone 0  
fill ~91 ~0 ~144 ~94 ~0 ~144 stone 0 
setblock ~92 ~0 ~10 grass 0  
fill ~92 ~0 ~41 ~108 ~0 ~41 stone 0  
fill ~92 ~0 ~42 ~107 ~0 ~42 stone 0  
fill ~92 ~0 ~43 ~107 ~0 ~43 stone 0  
fill ~92 ~0 ~44 ~106 ~0 ~44 stone 0  
fill ~92 ~0 ~48 ~104 ~0 ~48 stone 0  
fill ~92 ~0 ~49 ~105 ~0 ~49 stone 0  
fill ~92 ~0 ~50 ~105 ~0 ~50 stone 0  
fill ~92 ~0 ~51 ~105 ~0 ~51 stone 0  
fill ~92 ~0 ~52 ~105 ~0 ~52 stone 0  
fill ~92 ~0 ~53 ~104 ~0 ~53 stone 0  
fill ~92 ~0 ~54 ~104 ~0 ~54 stone 0  
fill ~92 ~0 ~91 ~108 ~0 ~91 stone 0  
fill ~92 ~0 ~92 ~109 ~0 ~92 stone 0 
setblock ~92 ~0 ~93 grass 0  
fill ~92 ~0 ~109 ~107 ~0 ~109 stone 0  
fill ~92 ~0 ~110 ~107 ~0 ~110 stone 0  
fill ~92 ~0 ~111 ~106 ~0 ~111 stone 0  
fill ~92 ~0 ~112 ~105 ~0 ~112 stone 0  
fill ~92 ~0 ~113 ~104 ~0 ~113 stone 0  
fill ~92 ~0 ~117 ~104 ~0 ~117 stone 0  
fill ~92 ~0 ~118 ~104 ~0 ~118 stone 0  
fill ~92 ~0 ~119 ~104 ~0 ~119 stone 0  
fill ~92 ~0 ~120 ~105 ~0 ~120 stone 0  
fill ~92 ~0 ~121 ~105 ~0 ~121 stone 0  
fill ~92 ~0 ~122 ~105 ~0 ~122 stone 0  
fill ~93 ~0 ~93 ~109 ~0 ~93 stone 0  
fill ~93 ~0 ~107 ~109 ~0 ~107 stone 0  
fill ~93 ~0 ~108 ~108 ~0 ~108 stone 0  
fill ~93 ~0 ~114 ~104 ~0 ~114 stone 0  
fill ~93 ~0 ~115 ~104 ~0 ~115 stone 0  
fill ~93 ~0 ~116 ~104 ~0 ~116 stone 0 
setblock ~94 ~0 ~94 grass 0  
fill ~94 ~0 ~99 ~94 ~0 ~101 grass 0 
setblock ~94 ~0 ~104 grass 0  
fill ~94 ~0 ~105 ~109 ~0 ~105 stone 0  
fill ~94 ~0 ~106 ~109 ~0 ~106 stone 0 
setblock ~95 ~0 ~20 grass 0  
fill ~95 ~0 ~94 ~109 ~0 ~94 stone 0  
fill ~95 ~0 ~95 ~109 ~0 ~95 stone 0  
fill ~95 ~0 ~96 ~110 ~0 ~96 stone 0  
fill ~95 ~0 ~97 ~109 ~0 ~97 stone 0  
fill ~95 ~0 ~98 ~109 ~0 ~98 stone 0  
fill ~95 ~0 ~99 ~110 ~0 ~99 stone 0  
fill ~95 ~0 ~100 ~110 ~0 ~100 stone 0  
fill ~95 ~0 ~101 ~110 ~0 ~101 stone 0  
fill ~95 ~0 ~102 ~111 ~0 ~102 stone 0  
fill ~95 ~0 ~103 ~110 ~0 ~103 stone 0  
fill ~95 ~0 ~104 ~110 ~0 ~104 stone 0 
setblock ~95 ~0 ~144 grass 0  
fill ~96 ~0 ~144 ~96 ~0 ~144 dirt 0 
setblock ~97 ~0 ~21 grass 0 
setblock ~97 ~0 ~144 grass 0 
setblock ~98 ~0 ~23 grass 0  
fill ~98 ~0 ~143 ~98 ~0 ~143 dirt 0  
fill ~99 ~0 ~142 ~99 ~0 ~142 dirt 0 
setblock ~99 ~0 ~143 grass 0 
setblock ~100 ~0 ~26 grass 0  
fill ~100 ~0 ~141 ~100 ~0 ~141 dirt 0 
setblock ~100 ~0 ~142 grass 0  
fill ~101 ~0 ~140 ~101 ~0 ~140 dirt 0 
setblock ~101 ~0 ~141 grass 0 
setblock ~102 ~0 ~27 grass 0  
fill ~102 ~0 ~68 ~103 ~0 ~68 grass 0  
fill ~102 ~0 ~69 ~103 ~0 ~69 grass 0 
setblock ~102 ~0 ~139 grass 0 
setblock ~103 ~0 ~138 grass 0  
fill ~104 ~0 ~68 ~107 ~0 ~68 stone 0  
fill ~104 ~0 ~69 ~107 ~0 ~69 stone 0  
fill ~104 ~0 ~131 ~104 ~1 ~131 dirt 0 
setblock ~104 ~0 ~136 grass 0 
setblock ~105 ~0 ~35 grass 0 
setblock ~105 ~0 ~48 grass 0  
fill ~105 ~0 ~53 ~105 ~0 ~60 grass 0  
fill ~105 ~0 ~80 ~107 ~0 ~80 grass 0 
setblock ~105 ~0 ~124 grass 0  
fill ~105 ~0 ~129 ~105 ~0 ~129 dirt 0  
fill ~105 ~0 ~130 ~105 ~0 ~132 grass 0  
fill ~106 ~0 ~60 ~106 ~0 ~62 grass 0  
fill ~106 ~0 ~120 ~106 ~0 ~121 grass 0  
fill ~106 ~0 ~125 ~106 ~0 ~128 grass 0 
setblock ~107 ~0 ~36 grass 0 
setblock ~107 ~0 ~44 grass 0  
fill ~107 ~0 ~63 ~107 ~0 ~64 grass 0 
setblock ~107 ~0 ~79 grass 0 
setblock ~107 ~0 ~81 grass 0 
setblock ~108 ~0 ~38 grass 0 
setblock ~108 ~0 ~42 grass 0  
fill ~108 ~0 ~64 ~108 ~0 ~70 grass 0  
fill ~108 ~0 ~77 ~108 ~0 ~78 grass 0  
fill ~108 ~0 ~84 ~108 ~0 ~86 grass 0  
fill ~108 ~0 ~109 ~110 ~0 ~109 dirt 0  
fill ~108 ~0 ~110 ~109 ~0 ~110 dirt 0  
fill ~109 ~0 ~70 ~109 ~0 ~76 grass 0  
fill ~109 ~0 ~87 ~109 ~0 ~90 grass 0  
fill ~109 ~0 ~91 ~109 ~0 ~91 dirt 0  
fill ~109 ~0 ~108 ~110 ~0 ~108 dirt 0  
fill ~110 ~0 ~92 ~110 ~0 ~93 grass 0  
fill ~110 ~0 ~94 ~110 ~0 ~94 dirt 0  
fill ~110 ~0 ~95 ~110 ~0 ~95 dirt 0  
fill ~110 ~0 ~97 ~110 ~0 ~98 grass 0  
fill ~110 ~0 ~105 ~111 ~0 ~105 dirt 0  
fill ~110 ~0 ~106 ~111 ~0 ~106 dirt 0  
fill ~110 ~0 ~107 ~110 ~0 ~107 dirt 0  
fill ~111 ~0 ~98 ~111 ~0 ~101 grass 0  
fill ~111 ~0 ~103 ~111 ~1 ~103 dirt 0  
fill ~111 ~0 ~104 ~111 ~1 ~104 dirt 0 
setblock ~-8 ~1 ~107 grass 0  
fill ~-8 ~1 ~108 ~12 ~1 ~108 stone 0  
fill ~-8 ~1 ~109 ~12 ~1 ~109 stone 0  
fill ~-7 ~1 ~104 ~12 ~1 ~104 stone 0  
fill ~-7 ~1 ~105 ~11 ~1 ~105 stone 0  
fill ~-7 ~1 ~106 ~12 ~1 ~106 stone 0  
fill ~-7 ~1 ~107 ~12 ~1 ~107 stone 0  
fill ~-7 ~1 ~110 ~13 ~1 ~110 stone 0  
fill ~-7 ~1 ~111 ~13 ~1 ~111 stone 0  
fill ~-7 ~1 ~112 ~14 ~1 ~112 stone 0  
fill ~-7 ~1 ~113 ~15 ~1 ~113 stone 0  
fill ~-7 ~1 ~114 ~15 ~1 ~114 stone 0  
fill ~-7 ~1 ~118 ~15 ~1 ~118 stone 0 
setblock ~-7 ~1 ~119 grass 0  
fill ~-6 ~1 ~102 ~13 ~1 ~102 stone 0  
fill ~-6 ~1 ~103 ~13 ~1 ~103 stone 0  
fill ~-6 ~1 ~115 ~15 ~1 ~115 stone 0  
fill ~-6 ~1 ~117 ~15 ~1 ~117 stone 0  
fill ~-6 ~1 ~119 ~16 ~1 ~119 stone 0 
setblock ~-6 ~1 ~120 grass 0  
fill ~-5 ~1 ~101 ~13 ~1 ~101 stone 0  
fill ~-5 ~1 ~116 ~15 ~1 ~116 stone 0  
fill ~-5 ~1 ~120 ~16 ~1 ~120 stone 0  
fill ~-5 ~1 ~121 ~-5 ~1 ~122 grass 0  
fill ~-4 ~1 ~81 ~-3 ~1 ~81 grass 0  
fill ~-4 ~1 ~82 ~-3 ~1 ~82 grass 0  
fill ~-4 ~1 ~83 ~-3 ~1 ~83 grass 0  
fill ~-4 ~1 ~84 ~-4 ~1 ~86 grass 0  
fill ~-4 ~1 ~121 ~17 ~1 ~121 stone 0  
fill ~-4 ~1 ~122 ~23 ~1 ~122 stone 0 
setblock ~-4 ~1 ~123 grass 0 
setblock ~-3 ~1 ~76 grass 0  
fill ~-3 ~1 ~84 ~11 ~1 ~84 stone 0  
fill ~-3 ~1 ~85 ~12 ~1 ~85 stone 0  
fill ~-3 ~1 ~86 ~13 ~1 ~86 stone 0  
fill ~-3 ~1 ~87 ~13 ~1 ~87 stone 0 
setblock ~-3 ~1 ~88 grass 0  
fill ~-3 ~1 ~92 ~-3 ~1 ~94 grass 0  
fill ~-3 ~1 ~100 ~12 ~1 ~100 stone 0  
fill ~-3 ~1 ~123 ~30 ~1 ~123 stone 0  
fill ~-3 ~1 ~124 ~-3 ~1 ~126 grass 0  
fill ~-2 ~1 ~75 ~13 ~1 ~75 stone 0  
fill ~-2 ~1 ~76 ~12 ~1 ~76 stone 0 
setblock ~-2 ~1 ~80 grass 0  
fill ~-2 ~1 ~81 ~11 ~1 ~81 stone 0  
fill ~-2 ~1 ~82 ~10 ~1 ~82 stone 0  
fill ~-2 ~1 ~83 ~11 ~1 ~83 stone 0  
fill ~-2 ~1 ~88 ~13 ~1 ~88 stone 0  
fill ~-2 ~1 ~89 ~-2 ~1 ~90 grass 0  
fill ~-2 ~1 ~91 ~14 ~1 ~91 stone 0  
fill ~-2 ~1 ~92 ~14 ~1 ~92 stone 0  
fill ~-2 ~1 ~93 ~14 ~1 ~93 stone 0  
fill ~-2 ~1 ~94 ~13 ~1 ~94 stone 0  
fill ~-2 ~1 ~95 ~12 ~1 ~95 stone 0 
setblock ~-2 ~1 ~96 grass 0  
fill ~-2 ~1 ~99 ~11 ~1 ~99 stone 0  
fill ~-2 ~1 ~124 ~31 ~1 ~124 stone 0  
fill ~-2 ~1 ~125 ~31 ~1 ~125 stone 0 
setblock ~-2 ~1 ~126 grass 0  
fill ~-1 ~1 ~74 ~13 ~1 ~74 stone 0  
fill ~-1 ~1 ~77 ~11 ~1 ~77 stone 0  
fill ~-1 ~1 ~78 ~11 ~1 ~78 stone 0  
fill ~-1 ~1 ~79 ~11 ~1 ~79 stone 0  
fill ~-1 ~1 ~80 ~11 ~1 ~80 stone 0  
fill ~-1 ~1 ~89 ~13 ~1 ~89 stone 0  
fill ~-1 ~1 ~90 ~13 ~1 ~90 stone 0  
fill ~-1 ~1 ~96 ~11 ~1 ~96 stone 0  
fill ~-1 ~1 ~97 ~10 ~1 ~97 stone 0  
fill ~-1 ~1 ~98 ~10 ~1 ~98 stone 0  
fill ~-1 ~1 ~126 ~31 ~1 ~126 stone 0  
fill ~-1 ~1 ~127 ~-1 ~1 ~128 grass 0  
fill ~0 ~1 ~73 ~14 ~1 ~73 stone 0  
fill ~0 ~1 ~127 ~30 ~1 ~127 stone 0  
fill ~0 ~1 ~128 ~29 ~1 ~128 stone 0  
fill ~0 ~1 ~129 ~104 ~1 ~129 stone 0  
fill ~1 ~1 ~70 ~17 ~1 ~70 stone 0  
fill ~1 ~1 ~71 ~16 ~1 ~71 stone 0  
fill ~1 ~1 ~72 ~15 ~1 ~72 stone 0  
fill ~1 ~1 ~130 ~104 ~1 ~130 stone 0 
setblock ~1 ~1 ~131 grass 0  
fill ~1 ~1 ~134 ~2 ~1 ~134 grass 0  
fill ~2 ~1 ~68 ~18 ~1 ~68 stone 0  
fill ~2 ~1 ~69 ~17 ~1 ~69 stone 0  
fill ~2 ~1 ~131 ~103 ~1 ~131 stone 0  
fill ~2 ~1 ~132 ~104 ~1 ~132 stone 0  
fill ~2 ~1 ~133 ~103 ~1 ~133 stone 0  
fill ~2 ~1 ~135 ~2 ~1 ~137 grass 0  
fill ~3 ~1 ~67 ~19 ~1 ~67 stone 0  
fill ~3 ~1 ~134 ~104 ~1 ~134 stone 0  
fill ~3 ~1 ~135 ~104 ~1 ~135 stone 0  
fill ~3 ~1 ~136 ~3 ~1 ~138 grass 0  
fill ~4 ~1 ~66 ~19 ~1 ~66 stone 0  
fill ~4 ~1 ~136 ~103 ~1 ~136 stone 0  
fill ~4 ~1 ~137 ~59 ~1 ~137 stone 0  
fill ~4 ~1 ~138 ~58 ~1 ~138 stone 0  
fill ~4 ~1 ~139 ~5 ~1 ~139 grass 0  
fill ~5 ~1 ~63 ~19 ~1 ~63 stone 0  
fill ~5 ~1 ~64 ~19 ~1 ~64 stone 0  
fill ~5 ~1 ~65 ~19 ~1 ~65 stone 0  
fill ~5 ~1 ~140 ~6 ~1 ~140 grass 0  
fill ~6 ~1 ~62 ~20 ~1 ~62 stone 0  
fill ~6 ~1 ~139 ~56 ~1 ~139 stone 0  
fill ~6 ~1 ~141 ~8 ~1 ~141 grass 0  
fill ~7 ~1 ~57 ~29 ~1 ~57 stone 0  
fill ~7 ~1 ~58 ~22 ~1 ~58 stone 0  
fill ~7 ~1 ~59 ~21 ~1 ~59 stone 0  
fill ~7 ~1 ~60 ~20 ~1 ~60 stone 0  
fill ~7 ~1 ~61 ~20 ~1 ~61 stone 0  
fill ~7 ~1 ~140 ~56 ~1 ~140 stone 0  
fill ~8 ~1 ~55 ~31 ~1 ~55 stone 0  
fill ~8 ~1 ~56 ~30 ~1 ~56 stone 0  
fill ~9 ~1 ~54 ~32 ~1 ~54 stone 0  
fill ~9 ~1 ~141 ~56 ~1 ~141 stone 0  
fill ~9 ~1 ~142 ~10 ~1 ~142 grass 0  
fill ~10 ~1 ~53 ~32 ~1 ~53 stone 0  
fill ~11 ~1 ~52 ~33 ~1 ~52 stone 0  
fill ~11 ~1 ~97 ~11 ~1 ~98 grass 0  
fill ~12 ~1 ~51 ~34 ~1 ~51 stone 0  
fill ~12 ~1 ~96 ~13 ~1 ~96 grass 0  
fill ~12 ~1 ~98 ~12 ~1 ~99 grass 0  
fill ~12 ~1 ~105 ~13 ~1 ~105 grass 0  
fill ~12 ~1 ~142 ~55 ~1 ~142 stone 0  
fill ~12 ~1 ~143 ~55 ~1 ~143 stone 0  
fill ~13 ~1 ~50 ~35 ~1 ~50 stone 0  
fill ~13 ~1 ~95 ~14 ~1 ~95 grass 0  
fill ~13 ~1 ~99 ~13 ~1 ~100 grass 0 
setblock ~13 ~1 ~104 grass 0  
fill ~13 ~1 ~144 ~23 ~1 ~144 stone 0  
fill ~14 ~1 ~89 ~14 ~1 ~90 grass 0 
setblock ~14 ~1 ~94 grass 0  
fill ~14 ~1 ~101 ~14 ~1 ~103 grass 0  
fill ~14 ~1 ~110 ~14 ~1 ~111 grass 0  
fill ~14 ~1 ~145 ~23 ~1 ~145 stone 0  
fill ~15 ~1 ~91 ~15 ~1 ~93 grass 0  
fill ~15 ~1 ~111 ~15 ~1 ~112 grass 0  
fill ~15 ~1 ~146 ~23 ~1 ~146 stone 0  
fill ~16 ~1 ~46 ~16 ~1 ~47 grass 0  
fill ~16 ~1 ~49 ~36 ~1 ~49 stone 0  
fill ~16 ~1 ~113 ~16 ~1 ~115 grass 0  
fill ~17 ~1 ~44 ~18 ~1 ~44 grass 0  
fill ~17 ~1 ~45 ~17 ~1 ~44 grass 0  
fill ~17 ~1 ~46 ~39 ~1 ~46 stone 0  
fill ~17 ~1 ~47 ~38 ~1 ~47 stone 0  
fill ~17 ~1 ~48 ~37 ~1 ~48 stone 0  
fill ~18 ~1 ~43 ~19 ~1 ~43 grass 0  
fill ~18 ~1 ~45 ~39 ~1 ~45 stone 0 
setblock ~18 ~1 ~69 grass 0  
fill ~19 ~1 ~42 ~27 ~1 ~42 grass 0  
fill ~19 ~1 ~44 ~40 ~1 ~44 stone 0 
setblock ~19 ~1 ~68 grass 0  
fill ~19 ~1 ~147 ~23 ~1 ~147 stone 0  
fill ~20 ~1 ~43 ~41 ~1 ~43 stone 0  
fill ~20 ~1 ~63 ~21 ~1 ~63 grass 0  
fill ~20 ~1 ~64 ~20 ~1 ~66 grass 0  
fill ~20 ~1 ~148 ~22 ~1 ~148 grass 0  
fill ~21 ~1 ~41 ~22 ~1 ~41 grass 0  
fill ~21 ~1 ~60 ~21 ~1 ~63 grass 0  
fill ~24 ~1 ~121 ~25 ~1 ~121 grass 0  
fill ~24 ~1 ~122 ~24 ~1 ~121 grass 0  
fill ~24 ~1 ~144 ~25 ~1 ~144 grass 0  
fill ~24 ~1 ~145 ~24 ~1 ~148 grass 0  
fill ~25 ~1 ~58 ~27 ~1 ~58 stone 0  
fill ~25 ~1 ~122 ~29 ~1 ~122 stone 0  
fill ~25 ~1 ~145 ~27 ~1 ~145 stone 0  
fill ~25 ~1 ~146 ~27 ~1 ~146 stone 0  
fill ~25 ~1 ~147 ~27 ~1 ~147 stone 0  
fill ~25 ~1 ~148 ~29 ~1 ~148 grass 0 
setblock ~26 ~1 ~25 grass 0 
setblock ~26 ~1 ~120 grass 0  
fill ~26 ~1 ~121 ~28 ~1 ~121 stone 0  
fill ~26 ~1 ~144 ~55 ~1 ~144 stone 0  
fill ~27 ~1 ~21 ~54 ~1 ~21 stone 0  
fill ~27 ~1 ~22 ~54 ~1 ~22 stone 0  
fill ~27 ~1 ~23 ~54 ~1 ~23 stone 0  
fill ~27 ~1 ~24 ~54 ~1 ~24 stone 0  
fill ~27 ~1 ~25 ~54 ~1 ~25 stone 0 
setblock ~27 ~1 ~26 grass 0 
setblock ~28 ~1 ~19 grass 0  
fill ~28 ~1 ~20 ~53 ~1 ~20 stone 0  
fill ~28 ~1 ~26 ~53 ~1 ~26 stone 0  
fill ~28 ~1 ~27 ~52 ~1 ~27 stone 0  
fill ~28 ~1 ~28 ~28 ~1 ~29 grass 0  
fill ~28 ~1 ~42 ~43 ~1 ~42 stone 0 
setblock ~28 ~1 ~120 grass 0  
fill ~28 ~1 ~145 ~31 ~1 ~145 grass 0  
fill ~28 ~1 ~146 ~29 ~1 ~146 grass 0  
fill ~28 ~1 ~147 ~29 ~1 ~147 grass 0 
setblock ~29 ~1 ~18 grass 0  
fill ~29 ~1 ~19 ~52 ~1 ~19 stone 0  
fill ~29 ~1 ~28 ~52 ~1 ~28 stone 0  
fill ~29 ~1 ~29 ~53 ~1 ~29 stone 0  
fill ~29 ~1 ~40 ~30 ~1 ~40 grass 0  
fill ~29 ~1 ~41 ~29 ~1 ~40 grass 0  
fill ~29 ~1 ~149 ~33 ~1 ~149 grass 0 
setblock ~30 ~1 ~17 grass 0  
fill ~30 ~1 ~18 ~51 ~1 ~18 stone 0  
fill ~30 ~1 ~30 ~53 ~1 ~30 stone 0  
fill ~30 ~1 ~41 ~44 ~1 ~41 stone 0 
setblock ~30 ~1 ~128 grass 0  
fill ~30 ~1 ~146 ~53 ~1 ~146 stone 0  
fill ~30 ~1 ~147 ~52 ~1 ~147 stone 0  
fill ~30 ~1 ~148 ~51 ~1 ~148 stone 0  
fill ~31 ~1 ~17 ~51 ~1 ~17 stone 0  
fill ~31 ~1 ~31 ~53 ~1 ~31 stone 0  
fill ~31 ~1 ~35 ~31 ~1 ~39 grass 0  
fill ~31 ~1 ~40 ~44 ~1 ~40 stone 0 
setblock ~31 ~1 ~123 grass 0 
setblock ~31 ~1 ~127 grass 0  
fill ~31 ~1 ~128 ~42 ~1 ~128 stone 0 
setblock ~32 ~1 ~16 grass 0  
fill ~32 ~1 ~35 ~51 ~1 ~35 stone 0  
fill ~32 ~1 ~36 ~50 ~1 ~36 stone 0  
fill ~32 ~1 ~37 ~45 ~1 ~37 stone 0  
fill ~32 ~1 ~38 ~45 ~1 ~38 stone 0  
fill ~32 ~1 ~39 ~45 ~1 ~39 stone 0  
fill ~32 ~1 ~124 ~32 ~1 ~126 grass 0  
fill ~32 ~1 ~145 ~54 ~1 ~145 stone 0  
fill ~33 ~1 ~16 ~51 ~1 ~16 stone 0  
fill ~33 ~1 ~32 ~53 ~1 ~32 stone 0  
fill ~33 ~1 ~33 ~53 ~1 ~33 stone 0  
fill ~33 ~1 ~34 ~52 ~1 ~34 stone 0 
setblock ~33 ~1 ~53 grass 0  
fill ~33 ~1 ~150 ~52 ~1 ~150 grass 0  
fill ~34 ~1 ~149 ~50 ~1 ~149 stone 0  
fill ~35 ~1 ~13 ~58 ~1 ~13 stone 0  
fill ~35 ~1 ~14 ~56 ~1 ~14 stone 0  
fill ~35 ~1 ~15 ~52 ~1 ~15 stone 0  
fill ~35 ~1 ~127 ~36 ~1 ~127 grass 0  
fill ~36 ~1 ~126 ~37 ~1 ~126 grass 0  
fill ~37 ~1 ~11 ~37 ~1 ~12 grass 0  
fill ~37 ~1 ~127 ~41 ~1 ~127 stone 0 
setblock ~38 ~1 ~10 grass 0  
fill ~38 ~1 ~11 ~92 ~1 ~11 stone 0  
fill ~38 ~1 ~12 ~92 ~1 ~12 stone 0 
setblock ~38 ~1 ~48 grass 0  
fill ~38 ~1 ~125 ~40 ~1 ~125 grass 0  
fill ~38 ~1 ~126 ~40 ~1 ~126 stone 0 
setblock ~39 ~1 ~8 grass 0  
fill ~39 ~1 ~9 ~91 ~1 ~9 stone 0  
fill ~39 ~1 ~10 ~91 ~1 ~10 stone 0  
fill ~39 ~1 ~119 ~39 ~1 ~121 grass 0  
fill ~39 ~1 ~151 ~51 ~1 ~151 grass 0  
fill ~40 ~1 ~8 ~90 ~1 ~8 stone 0  
fill ~40 ~1 ~117 ~41 ~1 ~117 grass 0  
fill ~40 ~1 ~118 ~40 ~1 ~117 grass 0  
fill ~40 ~1 ~119 ~48 ~1 ~119 stone 0  
fill ~40 ~1 ~120 ~48 ~1 ~120 stone 0  
fill ~40 ~1 ~121 ~67 ~1 ~121 stone 0  
fill ~40 ~1 ~122 ~40 ~1 ~123 grass 0  
fill ~41 ~1 ~116 ~42 ~1 ~116 grass 0  
fill ~41 ~1 ~118 ~47 ~1 ~118 stone 0  
fill ~41 ~1 ~122 ~71 ~1 ~122 stone 0  
fill ~41 ~1 ~123 ~41 ~1 ~124 grass 0  
fill ~41 ~1 ~126 ~42 ~1 ~126 grass 0  
fill ~41 ~1 ~152 ~46 ~1 ~152 grass 0  
fill ~41 ~1 ~153 ~45 ~1 ~153 grass 0 
setblock ~42 ~1 ~7 grass 0  
fill ~42 ~1 ~117 ~46 ~1 ~117 stone 0  
fill ~42 ~1 ~123 ~73 ~1 ~123 stone 0 
setblock ~42 ~1 ~124 grass 0  
fill ~42 ~1 ~127 ~43 ~1 ~127 grass 0  
fill ~43 ~1 ~7 ~89 ~1 ~7 stone 0  
fill ~43 ~1 ~115 ~45 ~1 ~115 grass 0  
fill ~43 ~1 ~116 ~45 ~1 ~116 stone 0  
fill ~43 ~1 ~124 ~75 ~1 ~124 stone 0  
fill ~43 ~1 ~125 ~44 ~1 ~125 grass 0  
fill ~43 ~1 ~128 ~44 ~1 ~128 grass 0 
setblock ~44 ~1 ~6 grass 0 
setblock ~45 ~1 ~5 grass 0  
fill ~45 ~1 ~6 ~88 ~1 ~6 stone 0  
fill ~45 ~1 ~125 ~76 ~1 ~125 stone 0  
fill ~45 ~1 ~126 ~77 ~1 ~126 stone 0  
fill ~45 ~1 ~127 ~81 ~1 ~127 stone 0  
summon ItemFrame ~42.5 ~22.5 ~98.9375 
summon ItemFrame ~42.5 ~23.5 ~98.9375 
summon ItemFrame ~42.5 ~24.5 ~98.9375 
summon ItemFrame ~42.5 ~25.5 ~98.9375 
summon ItemFrame ~40.0625 ~22.5 ~96.5 
summon ItemFrame ~40.0625 ~23.5 ~96.5 
summon ItemFrame ~40.0625 ~23.5 ~96.5 
summon ItemFrame ~40.0625 ~24.5 ~96.5 
summon ItemFrame ~40.0625 ~25.5 ~96.5 
summon ItemFrame ~48.5 ~24.5 ~100.9375 
summon ItemFrame ~48.5 ~23.5 ~100.9375 
summon ItemFrame ~48.5 ~24.5 ~100.9375 
summon ItemFrame ~48.5 ~25.5 ~100.9375 
summon ItemFrame ~48.5 ~22.5 ~100.9375 
summon ItemFrame ~45.5 ~22.5 ~99.9375 
summon ItemFrame ~45.5 ~23.5 ~99.9375 
summon ItemFrame ~45.5 ~24.5 ~99.9375 
summon ItemFrame ~45.5 ~24.5 ~99.9375 
summon ItemFrame ~45.5 ~25.5 ~99.9375  
fill ~45 ~1 ~128 ~104 ~1 ~128 stone 0 
setblock ~46 ~1 ~4 grass 0  
fill ~46 ~1 ~5 ~84 ~1 ~5 stone 0  
fill ~46 ~1 ~116 ~47 ~1 ~116 grass 0  
fill ~47 ~1 ~2 ~82 ~1 ~2 stone 0  
fill ~47 ~1 ~3 ~83 ~1 ~3 stone 0  
fill ~47 ~1 ~4 ~83 ~1 ~4 stone 0  
fill ~47 ~1 ~117 ~48 ~1 ~117 grass 0 
setblock ~48 ~1 ~118 grass 0 
setblock ~49 ~1 ~-1 grass 0  
fill ~49 ~1 ~0 ~79 ~1 ~0 stone 0  
fill ~49 ~1 ~1 ~80 ~1 ~1 stone 0  
fill ~49 ~1 ~119 ~49 ~1 ~120 grass 0  
fill ~50 ~1 ~-3 ~50 ~1 ~-2 grass 0  
fill ~50 ~1 ~-1 ~78 ~1 ~-1 stone 0  
fill ~50 ~1 ~120 ~62 ~1 ~120 stone 0  
fill ~51 ~1 ~-3 ~76 ~1 ~-3 stone 0  
fill ~51 ~1 ~-2 ~76 ~1 ~-2 stone 0  
fill ~51 ~1 ~149 ~53 ~1 ~149 grass 0  
fill ~52 ~1 ~-5 ~73 ~1 ~-5 stone 0  
fill ~52 ~1 ~-4 ~75 ~1 ~-4 stone 0  
fill ~52 ~1 ~148 ~54 ~1 ~148 grass 0  
fill ~53 ~1 ~147 ~55 ~1 ~147 grass 0  
fill ~54 ~1 ~-6 ~55 ~1 ~-6 grass 0  
fill ~54 ~1 ~146 ~55 ~1 ~146 grass 0 
setblock ~55 ~1 ~-7 grass 0  
fill ~55 ~1 ~145 ~56 ~1 ~145 grass 0  
fill ~56 ~1 ~-8 ~69 ~1 ~-8 stone 0  
fill ~56 ~1 ~-7 ~70 ~1 ~-7 stone 0  
fill ~56 ~1 ~-6 ~72 ~1 ~-6 stone 0  
fill ~56 ~1 ~119 ~58 ~1 ~119 stone 0  
fill ~56 ~1 ~142 ~56 ~1 ~145 grass 0  
fill ~57 ~1 ~-10 ~60 ~1 ~-10 grass 0  
fill ~57 ~1 ~-9 ~58 ~1 ~-9 grass 0  
fill ~59 ~1 ~-9 ~68 ~1 ~-9 stone 0 
setblock ~59 ~1 ~138 grass 0  
fill ~60 ~1 ~137 ~63 ~1 ~137 grass 0  
fill ~61 ~1 ~-10 ~62 ~1 ~-10 stone 0  
fill ~62 ~1 ~21 ~63 ~1 ~21 grass 0  
fill ~62 ~1 ~22 ~62 ~1 ~25 grass 0  
fill ~63 ~1 ~13 ~92 ~1 ~13 stone 0  
fill ~63 ~1 ~20 ~67 ~1 ~20 grass 0  
fill ~63 ~1 ~22 ~67 ~1 ~22 stone 0  
fill ~63 ~1 ~23 ~67 ~1 ~23 stone 0  
fill ~63 ~1 ~24 ~67 ~1 ~24 stone 0  
fill ~63 ~1 ~25 ~63 ~1 ~26 grass 0  
fill ~64 ~1 ~21 ~66 ~1 ~21 stone 0  
fill ~64 ~1 ~25 ~66 ~1 ~25 stone 0  
fill ~64 ~1 ~26 ~67 ~1 ~26 grass 0  
fill ~64 ~1 ~137 ~68 ~1 ~137 stone 0  
fill ~65 ~1 ~14 ~91 ~1 ~14 stone 0  
fill ~65 ~1 ~138 ~67 ~1 ~138 grass 0  
fill ~66 ~1 ~15 ~92 ~1 ~15 stone 0  
fill ~67 ~1 ~21 ~68 ~1 ~21 grass 0  
fill ~67 ~1 ~25 ~68 ~1 ~25 grass 0  
fill ~68 ~1 ~16 ~92 ~1 ~16 stone 0  
fill ~68 ~1 ~22 ~68 ~1 ~25 grass 0  
fill ~69 ~1 ~-9 ~70 ~1 ~-9 grass 0 
setblock ~69 ~1 ~137 grass 0 
setblock ~70 ~1 ~-8 grass 0  
fill ~70 ~1 ~19 ~93 ~1 ~19 stone 0  
fill ~70 ~1 ~20 ~93 ~1 ~20 stone 0  
fill ~70 ~1 ~21 ~94 ~1 ~21 stone 0  
fill ~70 ~1 ~22 ~95 ~1 ~22 stone 0  
fill ~71 ~1 ~17 ~93 ~1 ~17 stone 0  
fill ~71 ~1 ~18 ~93 ~1 ~18 stone 0  
fill ~71 ~1 ~23 ~79 ~1 ~23 stone 0  
fill ~72 ~1 ~24 ~78 ~1 ~24 stone 0 
setblock ~72 ~1 ~122 grass 0  
fill ~72 ~1 ~137 ~103 ~1 ~137 stone 0  
fill ~73 ~1 ~-6 ~76 ~1 ~-6 grass 0  
fill ~73 ~1 ~138 ~102 ~1 ~138 stone 0  
fill ~74 ~1 ~-5 ~78 ~1 ~-5 grass 0  
fill ~74 ~1 ~25 ~76 ~1 ~25 stone 0 
setblock ~74 ~1 ~123 grass 0  
fill ~74 ~1 ~139 ~101 ~1 ~139 stone 0  
fill ~76 ~1 ~-4 ~77 ~1 ~-4 grass 0  
fill ~76 ~1 ~140 ~100 ~1 ~140 stone 0  
fill ~77 ~1 ~-3 ~77 ~1 ~-2 grass 0  
fill ~77 ~1 ~141 ~99 ~1 ~141 stone 0  
fill ~77 ~1 ~142 ~98 ~1 ~142 stone 0 
setblock ~78 ~1 ~-2 grass 0  
fill ~78 ~1 ~143 ~97 ~1 ~143 stone 0  
fill ~78 ~1 ~144 ~88 ~1 ~144 stone 0 
setblock ~79 ~1 ~-1 grass 0  
fill ~79 ~1 ~145 ~87 ~1 ~145 stone 0  
fill ~79 ~1 ~146 ~85 ~1 ~146 stone 0  
fill ~79 ~1 ~147 ~86 ~1 ~147 grass 0 
setblock ~80 ~1 ~0 grass 0  
fill ~81 ~1 ~1 ~82 ~1 ~1 grass 0  
fill ~82 ~1 ~23 ~96 ~1 ~23 stone 0  
fill ~82 ~1 ~24 ~97 ~1 ~24 stone 0 
setblock ~83 ~1 ~2 grass 0  
fill ~83 ~1 ~25 ~97 ~1 ~25 stone 0  
fill ~83 ~1 ~26 ~97 ~1 ~26 stone 0  
fill ~83 ~1 ~27 ~99 ~1 ~27 stone 0 
setblock ~84 ~1 ~4 grass 0  
fill ~84 ~1 ~28 ~100 ~1 ~28 stone 0  
fill ~85 ~1 ~5 ~85 ~0 ~5 dirt 0  
fill ~85 ~1 ~29 ~103 ~1 ~29 stone 0  
fill ~85 ~1 ~30 ~104 ~1 ~30 stone 0  
fill ~86 ~1 ~5 ~88 ~1 ~5 grass 0  
fill ~86 ~1 ~31 ~104 ~1 ~31 stone 0  
fill ~86 ~1 ~32 ~104 ~1 ~32 stone 0  
fill ~86 ~1 ~74 ~107 ~1 ~74 stone 0  
fill ~86 ~1 ~75 ~106 ~1 ~75 stone 0  
fill ~86 ~1 ~76 ~106 ~1 ~76 stone 0  
fill ~86 ~1 ~146 ~87 ~1 ~146 grass 0  
fill ~87 ~1 ~33 ~104 ~1 ~33 stone 0  
fill ~87 ~1 ~72 ~106 ~1 ~72 stone 0  
fill ~87 ~1 ~73 ~106 ~1 ~73 stone 0  
fill ~87 ~1 ~77 ~106 ~1 ~77 stone 0  
fill ~87 ~1 ~78 ~105 ~1 ~78 stone 0  
fill ~87 ~1 ~79 ~104 ~1 ~79 stone 0  
fill ~87 ~1 ~80 ~104 ~1 ~80 stone 0  
fill ~87 ~1 ~81 ~106 ~1 ~81 stone 0  
fill ~87 ~1 ~82 ~106 ~1 ~82 stone 0  
fill ~87 ~1 ~83 ~106 ~1 ~83 stone 0  
fill ~88 ~1 ~34 ~104 ~1 ~34 stone 0  
fill ~88 ~1 ~68 ~101 ~1 ~68 stone 0  
fill ~88 ~1 ~69 ~101 ~1 ~69 stone 0  
fill ~88 ~1 ~70 ~104 ~1 ~70 stone 0  
fill ~88 ~1 ~71 ~105 ~1 ~71 stone 0  
fill ~88 ~1 ~84 ~106 ~1 ~84 stone 0  
fill ~88 ~1 ~85 ~107 ~1 ~85 stone 0  
fill ~88 ~1 ~145 ~94 ~1 ~145 grass 0  
fill ~89 ~1 ~35 ~104 ~1 ~35 stone 0  
fill ~89 ~1 ~36 ~104 ~1 ~36 stone 0  
fill ~89 ~1 ~37 ~105 ~1 ~37 stone 0  
fill ~89 ~1 ~66 ~105 ~1 ~66 stone 0  
fill ~89 ~1 ~67 ~102 ~1 ~67 stone 0  
fill ~89 ~1 ~86 ~107 ~1 ~86 stone 0  
fill ~89 ~1 ~87 ~107 ~1 ~87 stone 0  
fill ~89 ~1 ~144 ~90 ~1 ~144 dirt 0  
fill ~90 ~1 ~38 ~106 ~1 ~38 stone 0  
fill ~90 ~1 ~39 ~107 ~1 ~39 stone 0  
fill ~90 ~1 ~60 ~103 ~1 ~60 stone 0  
fill ~90 ~1 ~61 ~103 ~1 ~61 stone 0  
fill ~90 ~1 ~62 ~103 ~1 ~62 stone 0  
fill ~90 ~1 ~65 ~105 ~1 ~65 stone 0  
fill ~90 ~1 ~88 ~108 ~1 ~88 stone 0  
fill ~91 ~1 ~40 ~107 ~1 ~40 stone 0  
fill ~91 ~1 ~45 ~105 ~1 ~45 stone 0  
fill ~91 ~1 ~46 ~104 ~1 ~46 stone 0  
fill ~91 ~1 ~47 ~104 ~1 ~47 stone 0  
fill ~91 ~1 ~55 ~91 ~1 ~56 grass 0  
fill ~91 ~1 ~57 ~104 ~1 ~57 stone 0  
fill ~91 ~1 ~58 ~104 ~1 ~58 stone 0  
fill ~91 ~1 ~59 ~103 ~1 ~59 stone 0  
fill ~91 ~1 ~63 ~104 ~1 ~63 stone 0  
fill ~91 ~1 ~64 ~104 ~1 ~64 stone 0  
fill ~91 ~1 ~89 ~91 ~1 ~90 grass 0  
fill ~91 ~1 ~123 ~104 ~1 ~123 stone 0  
fill ~91 ~1 ~124 ~104 ~1 ~124 stone 0  
fill ~91 ~1 ~125 ~105 ~1 ~125 stone 0  
fill ~91 ~1 ~126 ~105 ~1 ~126 stone 0  
fill ~91 ~1 ~127 ~105 ~1 ~127 stone 0  
fill ~91 ~1 ~144 ~94 ~1 ~144 stone 0 
setblock ~92 ~1 ~14 grass 0  
fill ~92 ~1 ~41 ~107 ~1 ~41 stone 0  
fill ~92 ~1 ~42 ~106 ~1 ~42 stone 0  
fill ~92 ~1 ~43 ~105 ~1 ~43 stone 0  
fill ~92 ~1 ~44 ~105 ~1 ~44 stone 0  
fill ~92 ~1 ~48 ~104 ~1 ~48 stone 0  
fill ~92 ~1 ~49 ~105 ~1 ~49 stone 0  
fill ~92 ~1 ~50 ~105 ~1 ~50 stone 0  
fill ~92 ~1 ~51 ~105 ~1 ~51 stone 0  
fill ~92 ~1 ~52 ~104 ~1 ~52 stone 0  
fill ~92 ~1 ~53 ~104 ~1 ~53 stone 0  
fill ~92 ~1 ~54 ~104 ~1 ~54 stone 0  
fill ~92 ~1 ~55 ~104 ~1 ~55 stone 0  
fill ~92 ~1 ~56 ~104 ~1 ~56 stone 0  
fill ~92 ~1 ~89 ~108 ~1 ~89 stone 0  
fill ~92 ~1 ~90 ~108 ~1 ~90 stone 0  
fill ~92 ~1 ~91 ~92 ~1 ~92 grass 0  
fill ~92 ~1 ~109 ~108 ~1 ~109 stone 0  
fill ~92 ~1 ~110 ~107 ~1 ~110 stone 0  
fill ~92 ~1 ~111 ~106 ~1 ~111 stone 0  
fill ~92 ~1 ~112 ~104 ~1 ~112 stone 0  
fill ~92 ~1 ~113 ~104 ~1 ~113 stone 0  
fill ~92 ~1 ~117 ~104 ~1 ~117 stone 0  
fill ~92 ~1 ~118 ~104 ~1 ~118 stone 0  
fill ~92 ~1 ~119 ~104 ~1 ~119 stone 0  
fill ~92 ~1 ~120 ~104 ~1 ~120 stone 0  
fill ~92 ~1 ~121 ~104 ~1 ~121 stone 0  
fill ~92 ~1 ~122 ~105 ~1 ~122 stone 0  
fill ~93 ~1 ~91 ~108 ~1 ~91 stone 0  
fill ~93 ~1 ~92 ~93 ~1 ~93 grass 0  
fill ~93 ~1 ~107 ~109 ~1 ~107 stone 0  
fill ~93 ~1 ~108 ~108 ~1 ~108 stone 0  
fill ~93 ~1 ~114 ~104 ~1 ~114 stone 0  
fill ~93 ~1 ~115 ~104 ~1 ~115 stone 0  
fill ~93 ~1 ~116 ~104 ~1 ~116 stone 0 
setblock ~94 ~1 ~20 grass 0  
fill ~94 ~1 ~92 ~108 ~1 ~92 stone 0 
setblock ~94 ~1 ~93 grass 0 
setblock ~94 ~1 ~105 grass 0  
fill ~94 ~1 ~106 ~109 ~1 ~106 stone 0  
fill ~95 ~1 ~21 ~96 ~1 ~21 grass 0  
fill ~95 ~1 ~93 ~109 ~1 ~93 stone 0  
fill ~95 ~1 ~94 ~109 ~1 ~94 stone 0  
fill ~95 ~1 ~95 ~109 ~1 ~95 stone 0  
fill ~95 ~1 ~96 ~109 ~1 ~96 stone 0  
fill ~95 ~1 ~97 ~109 ~1 ~97 stone 0  
fill ~95 ~1 ~98 ~109 ~1 ~98 stone 0  
fill ~95 ~1 ~99 ~109 ~1 ~99 stone 0  
fill ~95 ~1 ~100 ~109 ~1 ~100 stone 0  
fill ~95 ~1 ~101 ~109 ~1 ~101 stone 0  
fill ~95 ~1 ~102 ~111 ~1 ~102 stone 0 
setblock ~95 ~1 ~103 grass 0  
fill ~95 ~1 ~104 ~110 ~1 ~104 stone 0  
fill ~95 ~1 ~105 ~109 ~1 ~105 stone 0  
fill ~96 ~1 ~22 ~97 ~1 ~22 grass 0  
fill ~96 ~1 ~103 ~110 ~1 ~103 stone 0 
setblock ~96 ~1 ~144 grass 0 
setblock ~97 ~1 ~23 grass 0  
fill ~98 ~1 ~24 ~98 ~1 ~26 grass 0 
setblock ~98 ~1 ~143 grass 0 
setblock ~99 ~1 ~26 grass 0 
setblock ~99 ~1 ~142 grass 0  
fill ~100 ~1 ~27 ~101 ~1 ~27 grass 0 
setblock ~100 ~1 ~141 grass 0  
fill ~101 ~1 ~28 ~102 ~1 ~28 grass 0 
setblock ~101 ~1 ~140 grass 0 
setblock ~103 ~1 ~67 grass 0  
fill ~104 ~1 ~59 ~104 ~1 ~62 grass 0  
fill ~104 ~1 ~67 ~104 ~1 ~130 stone 0 
setblock ~104 ~1 ~133 grass 0  
fill ~105 ~1 ~36 ~106 ~1 ~36 grass 0 
setblock ~105 ~1 ~52 grass 0  
fill ~105 ~1 ~61 ~105 ~1 ~64 grass 0  
fill ~105 ~1 ~67 ~107 ~1 ~67 grass 0  
fill ~105 ~1 ~68 ~107 ~1 ~68 grass 0  
fill ~105 ~1 ~69 ~107 ~1 ~69 grass 0  
fill ~105 ~1 ~70 ~107 ~1 ~70 grass 0  
fill ~105 ~1 ~79 ~106 ~1 ~79 grass 0 
setblock ~105 ~1 ~112 grass 0  
fill ~105 ~1 ~120 ~105 ~1 ~121 grass 0 
setblock ~105 ~1 ~123 grass 0  
fill ~105 ~1 ~128 ~105 ~1 ~129 grass 0  
fill ~106 ~1 ~37 ~107 ~1 ~37 grass 0  
fill ~106 ~1 ~43 ~107 ~1 ~43 grass 0  
fill ~106 ~1 ~44 ~106 ~1 ~43 grass 0  
fill ~106 ~1 ~63 ~106 ~1 ~71 grass 0  
fill ~106 ~1 ~78 ~107 ~1 ~78 grass 0 
setblock ~107 ~1 ~38 grass 0 
setblock ~107 ~1 ~42 grass 0  
fill ~107 ~1 ~65 ~107 ~1 ~73 grass 0  
fill ~107 ~1 ~75 ~108 ~1 ~75 grass 0  
fill ~107 ~1 ~76 ~108 ~1 ~76 grass 0  
fill ~107 ~1 ~77 ~107 ~1 ~75 grass 0  
fill ~107 ~1 ~82 ~107 ~1 ~84 grass 0  
fill ~108 ~1 ~39 ~108 ~1 ~41 grass 0  
fill ~108 ~1 ~71 ~108 ~1 ~76 grass 0 
setblock ~108 ~1 ~87 grass 0  
fill ~108 ~1 ~110 ~108 ~0 ~110 dirt 0  
fill ~109 ~1 ~91 ~109 ~1 ~92 grass 0  
fill ~109 ~1 ~108 ~109 ~0 ~108 dirt 0  
fill ~109 ~1 ~109 ~110 ~1 ~109 grass 0  
fill ~109 ~1 ~110 ~109 ~1 ~109 grass 0  
fill ~110 ~1 ~94 ~110 ~1 ~96 grass 0  
fill ~110 ~1 ~99 ~110 ~1 ~101 grass 0  
fill ~110 ~1 ~105 ~111 ~1 ~105 dirt 0  
fill ~110 ~1 ~106 ~111 ~1 ~106 dirt 0  
fill ~110 ~1 ~107 ~110 ~1 ~109 grass 0  
fill ~-8 ~2 ~108 ~12 ~2 ~108 stone 0  
fill ~-8 ~2 ~109 ~12 ~2 ~109 stone 0 
setblock ~-7 ~2 ~104 grass 0  
fill ~-7 ~2 ~105 ~11 ~2 ~105 stone 0  
fill ~-7 ~2 ~106 ~12 ~2 ~106 stone 0  
fill ~-7 ~2 ~107 ~12 ~2 ~107 stone 0  
fill ~-7 ~2 ~110 ~13 ~2 ~110 stone 0  
fill ~-7 ~2 ~111 ~13 ~2 ~111 stone 0  
fill ~-7 ~2 ~112 ~13 ~2 ~112 stone 0  
fill ~-7 ~2 ~113 ~13 ~2 ~113 stone 0  
fill ~-7 ~2 ~114 ~14 ~2 ~114 stone 0  
fill ~-7 ~2 ~118 ~15 ~2 ~118 stone 0  
fill ~-6 ~2 ~102 ~11 ~2 ~102 stone 0  
fill ~-6 ~2 ~103 ~11 ~2 ~103 stone 0  
fill ~-6 ~2 ~104 ~11 ~2 ~104 stone 0  
fill ~-6 ~2 ~115 ~14 ~2 ~115 stone 0  
fill ~-6 ~2 ~117 ~15 ~2 ~117 stone 0 
setblock ~-6 ~2 ~119 grass 0  
fill ~-5 ~2 ~101 ~11 ~2 ~101 stone 0  
fill ~-5 ~2 ~116 ~15 ~2 ~116 stone 0  
fill ~-5 ~2 ~119 ~16 ~2 ~119 stone 0 
setblock ~-5 ~2 ~120 grass 0  
fill ~-4 ~2 ~120 ~16 ~2 ~120 stone 0  
fill ~-4 ~2 ~121 ~17 ~2 ~121 stone 0 
setblock ~-4 ~2 ~122 grass 0  
fill ~-3 ~2 ~84 ~-3 ~2 ~87 grass 0  
fill ~-3 ~2 ~100 ~10 ~2 ~100 stone 0  
fill ~-3 ~2 ~122 ~23 ~2 ~122 stone 0 
setblock ~-3 ~2 ~123 grass 0  
fill ~-2 ~2 ~75 ~-2 ~2 ~76 grass 0  
fill ~-2 ~2 ~81 ~-1 ~2 ~81 grass 0  
fill ~-2 ~2 ~82 ~-2 ~2 ~83 grass 0  
fill ~-2 ~2 ~84 ~11 ~2 ~84 stone 0  
fill ~-2 ~2 ~85 ~12 ~2 ~85 stone 0  
fill ~-2 ~2 ~86 ~12 ~2 ~86 stone 0  
fill ~-2 ~2 ~87 ~13 ~2 ~87 stone 0 
setblock ~-2 ~2 ~88 grass 0  
fill ~-2 ~2 ~91 ~-2 ~2 ~95 grass 0  
fill ~-2 ~2 ~99 ~10 ~2 ~99 stone 0  
fill ~-2 ~2 ~123 ~28 ~2 ~123 stone 0  
fill ~-2 ~2 ~124 ~29 ~2 ~124 stone 0  
fill ~-2 ~2 ~125 ~-1 ~2 ~125 grass 0 
setblock ~-1 ~2 ~74 grass 0  
fill ~-1 ~2 ~75 ~13 ~2 ~75 stone 0  
fill ~-1 ~2 ~76 ~12 ~2 ~76 stone 0  
fill ~-1 ~2 ~77 ~11 ~2 ~77 stone 0  
fill ~-1 ~2 ~78 ~11 ~2 ~78 stone 0  
fill ~-1 ~2 ~79 ~11 ~2 ~79 stone 0 
setblock ~-1 ~2 ~80 grass 0  
fill ~-1 ~2 ~82 ~10 ~2 ~82 stone 0  
fill ~-1 ~2 ~83 ~11 ~2 ~83 stone 0  
fill ~-1 ~2 ~88 ~13 ~2 ~88 stone 0  
fill ~-1 ~2 ~89 ~13 ~2 ~89 stone 0  
fill ~-1 ~2 ~90 ~13 ~2 ~90 stone 0  
fill ~-1 ~2 ~91 ~12 ~2 ~91 stone 0  
fill ~-1 ~2 ~92 ~12 ~2 ~92 stone 0  
fill ~-1 ~2 ~93 ~12 ~2 ~93 stone 0  
fill ~-1 ~2 ~94 ~11 ~2 ~94 stone 0  
fill ~-1 ~2 ~95 ~9 ~2 ~95 stone 0  
fill ~-1 ~2 ~96 ~10 ~2 ~96 stone 0  
fill ~-1 ~2 ~97 ~10 ~2 ~97 stone 0  
fill ~-1 ~2 ~98 ~10 ~2 ~98 stone 0 
setblock ~-1 ~2 ~126 grass 0  
fill ~0 ~2 ~73 ~14 ~2 ~73 stone 0  
fill ~0 ~2 ~74 ~13 ~2 ~74 stone 0  
fill ~0 ~2 ~80 ~11 ~2 ~80 stone 0  
fill ~0 ~2 ~81 ~11 ~2 ~81 stone 0  
fill ~0 ~2 ~125 ~29 ~2 ~125 stone 0  
fill ~0 ~2 ~126 ~29 ~2 ~126 stone 0  
fill ~0 ~2 ~127 ~28 ~2 ~127 stone 0  
fill ~0 ~2 ~128 ~27 ~2 ~128 stone 0  
fill ~0 ~2 ~129 ~27 ~2 ~129 stone 0  
fill ~1 ~2 ~70 ~1 ~2 ~71 grass 0  
fill ~1 ~2 ~72 ~14 ~2 ~72 stone 0  
fill ~1 ~2 ~130 ~103 ~2 ~130 stone 0  
fill ~2 ~2 ~68 ~17 ~2 ~68 stone 0  
fill ~2 ~2 ~69 ~17 ~2 ~69 stone 0  
fill ~2 ~2 ~70 ~17 ~2 ~70 stone 0  
fill ~2 ~2 ~71 ~15 ~2 ~71 stone 0  
fill ~2 ~2 ~131 ~103 ~2 ~131 stone 0  
fill ~2 ~2 ~132 ~103 ~2 ~132 stone 0  
fill ~2 ~2 ~133 ~103 ~2 ~133 stone 0  
fill ~3 ~2 ~67 ~18 ~2 ~67 stone 0  
fill ~3 ~2 ~134 ~103 ~2 ~134 stone 0  
fill ~3 ~2 ~135 ~4 ~2 ~135 grass 0  
fill ~4 ~2 ~66 ~18 ~2 ~66 stone 0  
fill ~4 ~2 ~136 ~4 ~2 ~138 grass 0  
fill ~5 ~2 ~63 ~19 ~2 ~63 stone 0  
fill ~5 ~2 ~64 ~19 ~2 ~64 stone 0 
setblock ~5 ~2 ~65 grass 0  
fill ~5 ~2 ~135 ~59 ~2 ~135 stone 0  
fill ~5 ~2 ~136 ~58 ~2 ~136 stone 0  
fill ~5 ~2 ~137 ~56 ~2 ~137 stone 0 
setblock ~5 ~2 ~138 grass 0  
fill ~6 ~2 ~62 ~19 ~2 ~62 stone 0  
fill ~6 ~2 ~65 ~19 ~2 ~65 stone 0  
fill ~6 ~2 ~138 ~56 ~2 ~138 stone 0 
setblock ~6 ~2 ~139 grass 0  
fill ~7 ~2 ~57 ~29 ~2 ~57 stone 0  
fill ~7 ~2 ~58 ~22 ~2 ~58 stone 0  
fill ~7 ~2 ~59 ~21 ~2 ~59 stone 0  
fill ~7 ~2 ~60 ~20 ~2 ~60 stone 0  
fill ~7 ~2 ~61 ~19 ~2 ~61 stone 0  
fill ~7 ~2 ~139 ~56 ~2 ~139 stone 0  
fill ~7 ~2 ~140 ~8 ~2 ~140 grass 0  
fill ~8 ~2 ~55 ~31 ~2 ~55 stone 0  
fill ~8 ~2 ~56 ~30 ~2 ~56 stone 0  
fill ~9 ~2 ~54 ~32 ~2 ~54 stone 0  
fill ~9 ~2 ~140 ~56 ~2 ~140 stone 0  
fill ~9 ~2 ~141 ~10 ~2 ~141 grass 0  
fill ~10 ~2 ~53 ~32 ~2 ~53 stone 0  
fill ~10 ~2 ~95 ~12 ~2 ~95 grass 0  
fill ~11 ~2 ~52 ~33 ~2 ~52 stone 0 
setblock ~11 ~2 ~96 grass 0  
fill ~11 ~2 ~99 ~11 ~2 ~100 grass 0  
fill ~11 ~2 ~141 ~55 ~2 ~141 stone 0  
fill ~12 ~2 ~51 ~34 ~2 ~51 stone 0  
fill ~12 ~2 ~94 ~13 ~2 ~94 grass 0  
fill ~12 ~2 ~100 ~12 ~2 ~104 grass 0  
fill ~12 ~2 ~142 ~54 ~2 ~142 stone 0  
fill ~12 ~2 ~143 ~54 ~2 ~143 stone 0 
setblock ~13 ~2 ~50 grass 0 
setblock ~13 ~2 ~86 grass 0  
fill ~13 ~2 ~91 ~14 ~2 ~91 grass 0  
fill ~13 ~2 ~92 ~14 ~2 ~92 grass 0  
fill ~13 ~2 ~93 ~14 ~2 ~93 grass 0  
fill ~13 ~2 ~101 ~13 ~2 ~103 grass 0  
fill ~13 ~2 ~144 ~23 ~2 ~144 stone 0  
fill ~14 ~2 ~50 ~35 ~2 ~50 stone 0  
fill ~14 ~2 ~112 ~14 ~2 ~113 grass 0  
fill ~14 ~2 ~145 ~23 ~2 ~145 stone 0  
fill ~15 ~2 ~113 ~15 ~2 ~115 grass 0  
fill ~15 ~2 ~146 ~23 ~2 ~146 stone 0  
fill ~16 ~2 ~49 ~36 ~2 ~49 stone 0 
setblock ~16 ~2 ~71 grass 0  
fill ~17 ~2 ~46 ~18 ~2 ~46 grass 0  
fill ~17 ~2 ~47 ~17 ~2 ~46 grass 0  
fill ~17 ~2 ~48 ~37 ~2 ~48 stone 0  
fill ~18 ~2 ~45 ~19 ~2 ~45 grass 0  
fill ~18 ~2 ~47 ~38 ~2 ~47 stone 0 
setblock ~18 ~2 ~68 grass 0  
fill ~19 ~2 ~44 ~20 ~2 ~44 grass 0  
fill ~19 ~2 ~46 ~39 ~2 ~46 stone 0  
fill ~19 ~2 ~66 ~19 ~2 ~67 grass 0  
fill ~19 ~2 ~147 ~23 ~2 ~147 grass 0  
fill ~20 ~2 ~43 ~27 ~2 ~43 grass 0  
fill ~20 ~2 ~45 ~39 ~2 ~45 stone 0  
fill ~20 ~2 ~61 ~20 ~2 ~62 grass 0  
fill ~21 ~2 ~44 ~40 ~2 ~44 stone 0  
fill ~25 ~2 ~58 ~27 ~2 ~58 grass 0  
fill ~25 ~2 ~122 ~26 ~2 ~122 grass 0  
fill ~25 ~2 ~145 ~27 ~2 ~145 stone 0  
fill ~25 ~2 ~146 ~27 ~2 ~146 stone 0  
fill ~25 ~2 ~147 ~27 ~2 ~147 grass 0 
setblock ~26 ~2 ~121 grass 0  
fill ~26 ~2 ~144 ~54 ~2 ~144 stone 0  
fill ~27 ~2 ~21 ~54 ~2 ~21 stone 0  
fill ~27 ~2 ~22 ~54 ~2 ~22 stone 0  
fill ~27 ~2 ~23 ~54 ~2 ~23 stone 0  
fill ~27 ~2 ~24 ~54 ~2 ~24 stone 0  
fill ~27 ~2 ~25 ~54 ~2 ~25 stone 0  
fill ~28 ~2 ~20 ~53 ~2 ~20 stone 0  
fill ~28 ~2 ~26 ~53 ~2 ~26 stone 0 
setblock ~28 ~2 ~27 grass 0  
fill ~28 ~2 ~42 ~42 ~2 ~42 stone 0  
fill ~28 ~2 ~43 ~41 ~2 ~43 stone 0  
fill ~28 ~2 ~121 ~28 ~2 ~122 grass 0  
fill ~28 ~2 ~128 ~29 ~2 ~128 grass 0  
fill ~28 ~2 ~129 ~28 ~2 ~128 grass 0 
setblock ~29 ~2 ~19 grass 0  
fill ~29 ~2 ~27 ~52 ~2 ~27 stone 0  
fill ~29 ~2 ~28 ~52 ~2 ~28 stone 0 
setblock ~29 ~2 ~29 grass 0  
fill ~29 ~2 ~123 ~30 ~2 ~123 grass 0  
fill ~29 ~2 ~127 ~30 ~2 ~127 grass 0  
fill ~29 ~2 ~129 ~41 ~2 ~129 stone 0 
setblock ~30 ~2 ~18 grass 0  
fill ~30 ~2 ~19 ~52 ~2 ~19 stone 0  
fill ~30 ~2 ~29 ~52 ~2 ~29 stone 0  
fill ~30 ~2 ~30 ~53 ~2 ~30 stone 0 
setblock ~30 ~2 ~41 grass 0  
fill ~30 ~2 ~124 ~31 ~2 ~124 grass 0  
fill ~30 ~2 ~125 ~31 ~2 ~125 grass 0  
fill ~30 ~2 ~126 ~31 ~2 ~126 grass 0  
fill ~30 ~2 ~146 ~31 ~2 ~146 grass 0  
fill ~30 ~2 ~147 ~32 ~2 ~147 grass 0  
fill ~30 ~2 ~148 ~32 ~2 ~148 grass 0 
setblock ~31 ~2 ~17 grass 0  
fill ~31 ~2 ~18 ~50 ~2 ~18 stone 0 
setblock ~31 ~2 ~31 grass 0  
fill ~31 ~2 ~40 ~44 ~2 ~40 stone 0  
fill ~31 ~2 ~41 ~43 ~2 ~41 stone 0  
fill ~31 ~2 ~128 ~35 ~2 ~128 stone 0  
fill ~32 ~2 ~17 ~50 ~2 ~17 stone 0  
fill ~32 ~2 ~31 ~53 ~2 ~31 stone 0 
setblock ~32 ~2 ~35 grass 0  
fill ~32 ~2 ~36 ~50 ~2 ~36 stone 0  
fill ~32 ~2 ~37 ~44 ~2 ~37 stone 0  
fill ~32 ~2 ~38 ~44 ~2 ~38 stone 0  
fill ~32 ~2 ~39 ~44 ~2 ~39 stone 0  
fill ~32 ~2 ~145 ~46 ~2 ~145 stone 0  
fill ~32 ~2 ~146 ~46 ~2 ~146 stone 0  
fill ~33 ~2 ~16 ~51 ~2 ~16 stone 0  
fill ~33 ~2 ~32 ~53 ~2 ~32 stone 0  
fill ~33 ~2 ~33 ~53 ~2 ~33 stone 0  
fill ~33 ~2 ~34 ~52 ~2 ~34 stone 0  
fill ~33 ~2 ~35 ~51 ~2 ~35 stone 0  
fill ~33 ~2 ~147 ~46 ~2 ~147 stone 0  
fill ~33 ~2 ~148 ~45 ~2 ~148 stone 0  
fill ~34 ~2 ~149 ~50 ~2 ~149 grass 0  
fill ~35 ~2 ~13 ~57 ~2 ~13 stone 0  
fill ~35 ~2 ~14 ~53 ~2 ~14 stone 0  
fill ~35 ~2 ~15 ~52 ~2 ~15 stone 0  
fill ~36 ~2 ~128 ~37 ~2 ~128 grass 0  
fill ~37 ~2 ~127 ~41 ~2 ~127 grass 0 
setblock ~38 ~2 ~11 grass 0  
fill ~38 ~2 ~12 ~91 ~2 ~12 stone 0  
fill ~38 ~2 ~126 ~40 ~2 ~126 grass 0  
fill ~38 ~2 ~128 ~40 ~2 ~128 stone 0  
fill ~39 ~2 ~9 ~90 ~2 ~9 stone 0  
fill ~39 ~2 ~10 ~91 ~2 ~10 stone 0  
fill ~39 ~2 ~11 ~91 ~2 ~11 stone 0  
fill ~40 ~2 ~8 ~41 ~2 ~8 grass 0  
fill ~40 ~2 ~119 ~41 ~2 ~119 grass 0  
fill ~40 ~2 ~120 ~41 ~2 ~120 grass 0  
fill ~40 ~2 ~121 ~41 ~2 ~121 grass 0  
fill ~41 ~2 ~118 ~42 ~2 ~118 grass 0  
fill ~41 ~2 ~122 ~42 ~2 ~122 grass 0  
fill ~41 ~2 ~128 ~42 ~2 ~128 grass 0  
fill ~42 ~2 ~8 ~90 ~2 ~8 stone 0  
fill ~42 ~2 ~117 ~46 ~2 ~117 grass 0  
fill ~42 ~2 ~119 ~46 ~2 ~119 stone 0  
fill ~42 ~2 ~120 ~46 ~2 ~120 stone 0  
fill ~42 ~2 ~121 ~46 ~2 ~121 stone 0  
fill ~42 ~2 ~123 ~45 ~2 ~123 grass 0 
setblock ~42 ~2 ~129 grass 0  
fill ~43 ~2 ~7 ~44 ~2 ~7 grass 0  
fill ~43 ~2 ~116 ~45 ~2 ~116 grass 0  
fill ~43 ~2 ~118 ~45 ~2 ~118 stone 0  
fill ~43 ~2 ~122 ~45 ~2 ~122 stone 0  
fill ~43 ~2 ~124 ~45 ~2 ~124 grass 0  
fill ~43 ~2 ~129 ~104 ~2 ~129 stone 0 
setblock ~45 ~2 ~6 grass 0  
fill ~45 ~2 ~7 ~88 ~2 ~7 stone 0 
setblock ~45 ~2 ~37 grass 0  
fill ~45 ~2 ~125 ~76 ~2 ~125 stone 0  
fill ~45 ~2 ~126 ~77 ~2 ~126 stone 0  
fill ~45 ~2 ~127 ~78 ~2 ~127 stone 0  
fill ~45 ~2 ~128 ~82 ~2 ~128 stone 0 
setblock ~46 ~2 ~5 grass 0  
fill ~46 ~2 ~6 ~86 ~2 ~6 stone 0  
fill ~46 ~2 ~118 ~47 ~2 ~118 grass 0 
setblock ~46 ~2 ~122 grass 0  
fill ~46 ~2 ~123 ~72 ~2 ~123 stone 0  
fill ~46 ~2 ~124 ~75 ~2 ~124 stone 0  
fill ~46 ~2 ~148 ~51 ~2 ~148 grass 0  
fill ~47 ~2 ~2 ~81 ~2 ~2 stone 0  
fill ~47 ~2 ~3 ~82 ~2 ~3 stone 0 
setblock ~47 ~2 ~4 grass 0  
fill ~47 ~2 ~5 ~83 ~2 ~5 stone 0  
fill ~47 ~2 ~119 ~48 ~2 ~119 grass 0  
fill ~47 ~2 ~120 ~48 ~2 ~120 grass 0  
fill ~47 ~2 ~121 ~47 ~2 ~118 grass 0  
fill ~47 ~2 ~122 ~71 ~2 ~122 stone 0  
fill ~47 ~2 ~145 ~47 ~2 ~149 grass 0  
fill ~48 ~2 ~4 ~83 ~2 ~4 stone 0  
fill ~48 ~2 ~121 ~65 ~2 ~121 stone 0  
fill ~48 ~2 ~145 ~53 ~2 ~145 stone 0  
fill ~48 ~2 ~146 ~53 ~2 ~146 grass 0  
fill ~48 ~2 ~147 ~52 ~2 ~147 grass 0  
fill ~49 ~2 ~0 ~74 ~2 ~0 stone 0  
fill ~49 ~2 ~1 ~78 ~2 ~1 stone 0  
fill ~50 ~2 ~-1 ~75 ~2 ~-1 stone 0  
fill ~50 ~2 ~120 ~52 ~2 ~120 grass 0  
fill ~51 ~2 ~-3 ~51 ~2 ~-2 grass 0  
fill ~52 ~2 ~-5 ~70 ~2 ~-5 stone 0  
fill ~52 ~2 ~-4 ~71 ~2 ~-4 stone 0  
fill ~52 ~2 ~-3 ~73 ~2 ~-3 stone 0  
fill ~52 ~2 ~-2 ~75 ~2 ~-2 stone 0 
setblock ~53 ~2 ~29 grass 0  
fill ~53 ~2 ~120 ~61 ~2 ~120 stone 0 
setblock ~54 ~2 ~145 grass 0  
fill ~55 ~2 ~142 ~55 ~2 ~144 grass 0  
fill ~56 ~2 ~-8 ~56 ~3 ~-8 stone 0  
fill ~56 ~2 ~-7 ~67 ~2 ~-7 stone 0  
fill ~56 ~2 ~-6 ~69 ~2 ~-6 stone 0  
fill ~56 ~2 ~119 ~58 ~2 ~119 grass 0 
setblock ~56 ~2 ~141 grass 0  
fill ~57 ~2 ~-8 ~60 ~2 ~-8 grass 0  
fill ~57 ~2 ~137 ~59 ~2 ~137 grass 0  
fill ~57 ~2 ~138 ~58 ~2 ~138 grass 0  
fill ~59 ~2 ~-9 ~62 ~2 ~-9 grass 0  
fill ~59 ~2 ~136 ~64 ~2 ~136 grass 0  
fill ~60 ~2 ~135 ~62 ~2 ~135 grass 0  
fill ~61 ~2 ~-10 ~63 ~2 ~-10 grass 0  
fill ~61 ~2 ~-8 ~66 ~2 ~-8 stone 0 
setblock ~62 ~2 ~120 grass 0  
fill ~63 ~2 ~-9 ~66 ~2 ~-9 stone 0  
fill ~63 ~2 ~22 ~67 ~2 ~22 grass 0  
fill ~63 ~2 ~23 ~67 ~2 ~23 grass 0  
fill ~63 ~2 ~24 ~67 ~2 ~24 grass 0  
fill ~63 ~2 ~135 ~103 ~2 ~135 stone 0  
fill ~64 ~2 ~13 ~91 ~2 ~13 stone 0  
fill ~64 ~2 ~21 ~66 ~2 ~21 grass 0  
fill ~64 ~2 ~25 ~66 ~2 ~25 grass 0  
fill ~64 ~2 ~137 ~68 ~2 ~137 grass 0  
fill ~65 ~2 ~14 ~91 ~2 ~14 stone 0  
fill ~65 ~2 ~136 ~68 ~2 ~136 stone 0  
fill ~66 ~2 ~15 ~92 ~2 ~15 stone 0  
fill ~66 ~2 ~121 ~67 ~2 ~121 grass 0  
fill ~67 ~2 ~-9 ~68 ~2 ~-9 grass 0  
fill ~67 ~2 ~-8 ~69 ~2 ~-8 grass 0  
fill ~68 ~2 ~-7 ~70 ~2 ~-7 grass 0  
fill ~68 ~2 ~16 ~92 ~2 ~16 stone 0 
setblock ~69 ~2 ~136 grass 0  
fill ~70 ~2 ~-6 ~72 ~2 ~-6 grass 0  
fill ~70 ~2 ~19 ~93 ~2 ~19 stone 0  
fill ~70 ~2 ~20 ~93 ~2 ~20 stone 0  
fill ~70 ~2 ~21 ~94 ~2 ~21 stone 0 
setblock ~70 ~2 ~22 grass 0  
fill ~70 ~2 ~136 ~103 ~2 ~136 stone 0  
fill ~71 ~2 ~-5 ~73 ~2 ~-5 grass 0  
fill ~71 ~2 ~17 ~93 ~2 ~17 stone 0  
fill ~71 ~2 ~18 ~93 ~2 ~18 stone 0  
fill ~71 ~2 ~22 ~94 ~2 ~22 stone 0 
setblock ~71 ~2 ~23 grass 0  
fill ~72 ~2 ~-4 ~75 ~2 ~-4 grass 0  
fill ~72 ~2 ~23 ~78 ~2 ~23 stone 0 
setblock ~72 ~2 ~24 grass 0 
setblock ~72 ~2 ~137 grass 0  
fill ~73 ~2 ~24 ~77 ~2 ~24 stone 0 
setblock ~73 ~2 ~123 grass 0  
fill ~73 ~2 ~137 ~102 ~2 ~137 stone 0  
fill ~73 ~2 ~138 ~101 ~2 ~138 stone 0  
fill ~74 ~2 ~-3 ~76 ~2 ~-3 grass 0  
fill ~74 ~2 ~25 ~76 ~2 ~25 grass 0 
setblock ~74 ~2 ~139 grass 0  
fill ~75 ~2 ~0 ~76 ~2 ~0 grass 0  
fill ~75 ~2 ~139 ~100 ~2 ~139 stone 0  
fill ~76 ~2 ~-2 ~76 ~2 ~0 grass 0  
fill ~76 ~2 ~140 ~100 ~2 ~140 stone 0  
fill ~77 ~2 ~-1 ~78 ~2 ~-1 grass 0 
setblock ~77 ~2 ~0 stone 0  
fill ~77 ~2 ~141 ~77 ~2 ~142 grass 0  
fill ~78 ~2 ~0 ~79 ~2 ~0 grass 0 
setblock ~78 ~2 ~24 grass 0  
fill ~78 ~2 ~141 ~99 ~2 ~141 stone 0  
fill ~78 ~2 ~142 ~98 ~2 ~142 stone 0  
fill ~78 ~2 ~143 ~96 ~2 ~143 stone 0 
setblock ~78 ~2 ~144 grass 0  
fill ~79 ~2 ~1 ~80 ~2 ~1 grass 0 
setblock ~79 ~2 ~23 grass 0  
fill ~79 ~2 ~127 ~81 ~2 ~127 grass 0  
fill ~79 ~2 ~144 ~88 ~2 ~144 stone 0  
fill ~79 ~2 ~145 ~85 ~2 ~145 stone 0  
fill ~79 ~2 ~146 ~82 ~2 ~146 grass 0 
setblock ~82 ~2 ~2 grass 0  
fill ~82 ~2 ~23 ~95 ~2 ~23 stone 0 
setblock ~82 ~2 ~24 grass 0 
setblock ~83 ~2 ~3 grass 0  
fill ~83 ~2 ~24 ~96 ~2 ~24 stone 0  
fill ~83 ~2 ~25 ~97 ~2 ~25 stone 0  
fill ~83 ~2 ~26 ~97 ~2 ~26 stone 0  
fill ~83 ~2 ~27 ~98 ~2 ~27 stone 0 
setblock ~83 ~2 ~128 grass 0 
setblock ~83 ~2 ~146 stone 0  
fill ~84 ~2 ~5 ~85 ~2 ~5 grass 0  
fill ~84 ~2 ~28 ~100 ~2 ~28 stone 0  
fill ~84 ~2 ~128 ~89 ~2 ~128 stone 0  
fill ~84 ~2 ~146 ~85 ~2 ~146 grass 0  
fill ~85 ~2 ~29 ~103 ~2 ~29 stone 0  
fill ~85 ~2 ~30 ~103 ~2 ~30 stone 0  
fill ~86 ~2 ~31 ~103 ~2 ~31 stone 0 
setblock ~86 ~2 ~32 grass 0  
fill ~86 ~2 ~145 ~87 ~2 ~145 grass 0  
fill ~87 ~2 ~6 ~88 ~2 ~6 grass 0  
fill ~87 ~2 ~32 ~103 ~2 ~32 stone 0  
fill ~87 ~2 ~33 ~104 ~2 ~33 stone 0  
fill ~87 ~2 ~73 ~104 ~2 ~73 stone 0  
fill ~87 ~2 ~74 ~105 ~2 ~74 stone 0  
fill ~87 ~2 ~75 ~105 ~2 ~75 stone 0  
fill ~87 ~2 ~76 ~105 ~2 ~76 stone 0  
fill ~87 ~2 ~77 ~105 ~2 ~77 stone 0  
fill ~87 ~2 ~79 ~104 ~2 ~79 stone 0  
fill ~87 ~2 ~80 ~104 ~2 ~80 stone 0  
fill ~87 ~2 ~81 ~105 ~2 ~81 stone 0  
fill ~87 ~2 ~82 ~105 ~2 ~82 stone 0  
fill ~87 ~2 ~83 ~106 ~2 ~83 stone 0  
fill ~88 ~2 ~34 ~104 ~2 ~34 stone 0  
fill ~88 ~2 ~68 ~88 ~2 ~69 grass 0  
fill ~88 ~2 ~70 ~102 ~2 ~70 stone 0  
fill ~88 ~2 ~71 ~103 ~2 ~71 stone 0  
fill ~88 ~2 ~72 ~103 ~2 ~72 stone 0  
fill ~88 ~2 ~78 ~104 ~2 ~78 stone 0  
fill ~88 ~2 ~84 ~106 ~2 ~84 stone 0  
fill ~88 ~2 ~85 ~106 ~2 ~85 stone 0 
setblock ~89 ~2 ~7 grass 0  
fill ~89 ~2 ~35 ~104 ~2 ~35 stone 0  
fill ~89 ~2 ~36 ~89 ~2 ~37 grass 0 
setblock ~89 ~2 ~66 grass 0  
fill ~89 ~2 ~67 ~102 ~2 ~67 stone 0  
fill ~89 ~2 ~68 ~101 ~2 ~68 stone 0  
fill ~89 ~2 ~69 ~101 ~2 ~69 stone 0  
fill ~89 ~2 ~86 ~106 ~2 ~86 stone 0  
fill ~89 ~2 ~144 ~90 ~2 ~144 grass 0  
fill ~90 ~2 ~36 ~103 ~2 ~36 stone 0  
fill ~90 ~2 ~37 ~103 ~2 ~37 stone 0  
fill ~90 ~2 ~38 ~104 ~2 ~38 stone 0 
setblock ~90 ~2 ~39 grass 0  
fill ~90 ~2 ~60 ~90 ~2 ~62 grass 0  
fill ~90 ~2 ~65 ~103 ~2 ~65 stone 0  
fill ~90 ~2 ~66 ~103 ~2 ~66 stone 0  
fill ~90 ~2 ~87 ~107 ~2 ~87 stone 0 
setblock ~90 ~2 ~128 grass 0 
setblock ~91 ~2 ~9 grass 0  
fill ~91 ~2 ~39 ~105 ~2 ~39 stone 0 
setblock ~91 ~2 ~40 grass 0  
fill ~91 ~2 ~45 ~91 ~2 ~47 grass 0  
fill ~91 ~2 ~57 ~104 ~2 ~57 stone 0  
fill ~91 ~2 ~58 ~104 ~2 ~58 stone 0  
fill ~91 ~2 ~59 ~103 ~2 ~59 stone 0  
fill ~91 ~2 ~60 ~103 ~2 ~60 stone 0  
fill ~91 ~2 ~61 ~103 ~2 ~61 stone 0  
fill ~91 ~2 ~62 ~103 ~2 ~62 stone 0  
fill ~91 ~2 ~63 ~103 ~2 ~63 stone 0  
fill ~91 ~2 ~64 ~103 ~2 ~64 stone 0  
fill ~91 ~2 ~88 ~107 ~2 ~88 stone 0  
fill ~91 ~2 ~123 ~104 ~2 ~123 stone 0  
fill ~91 ~2 ~124 ~104 ~2 ~124 stone 0  
fill ~91 ~2 ~125 ~104 ~2 ~125 stone 0  
fill ~91 ~2 ~126 ~104 ~2 ~126 stone 0  
fill ~91 ~2 ~127 ~104 ~2 ~127 stone 0  
fill ~91 ~2 ~128 ~104 ~2 ~128 stone 0  
fill ~91 ~2 ~144 ~94 ~2 ~144 stone 0  
fill ~92 ~2 ~11 ~92 ~2 ~13 grass 0  
fill ~92 ~2 ~40 ~105 ~2 ~40 stone 0  
fill ~92 ~2 ~41 ~105 ~2 ~41 stone 0  
fill ~92 ~2 ~42 ~105 ~2 ~42 stone 0  
fill ~92 ~2 ~43 ~105 ~2 ~43 stone 0  
fill ~92 ~2 ~44 ~105 ~2 ~44 stone 0  
fill ~92 ~2 ~45 ~104 ~2 ~45 stone 0  
fill ~92 ~2 ~46 ~104 ~2 ~46 stone 0  
fill ~92 ~2 ~47 ~104 ~2 ~47 stone 0  
fill ~92 ~2 ~48 ~104 ~2 ~48 stone 0 
setblock ~92 ~2 ~49 grass 0  
fill ~92 ~2 ~50 ~104 ~2 ~50 stone 0  
fill ~92 ~2 ~51 ~104 ~2 ~51 stone 0  
fill ~92 ~2 ~52 ~104 ~2 ~52 stone 0  
fill ~92 ~2 ~53 ~104 ~2 ~53 stone 0  
fill ~92 ~2 ~54 ~104 ~2 ~54 stone 0  
fill ~92 ~2 ~55 ~104 ~2 ~55 stone 0  
fill ~92 ~2 ~56 ~104 ~2 ~56 stone 0  
fill ~92 ~2 ~89 ~107 ~2 ~89 stone 0  
fill ~92 ~2 ~90 ~93 ~2 ~90 grass 0  
fill ~92 ~2 ~109 ~107 ~2 ~109 stone 0  
fill ~92 ~2 ~110 ~107 ~2 ~110 stone 0  
fill ~92 ~2 ~111 ~106 ~2 ~111 stone 0  
fill ~92 ~2 ~112 ~104 ~2 ~112 stone 0  
fill ~92 ~2 ~113 ~104 ~2 ~113 stone 0  
fill ~92 ~2 ~117 ~104 ~2 ~117 stone 0  
fill ~92 ~2 ~118 ~104 ~2 ~118 stone 0  
fill ~92 ~2 ~119 ~104 ~2 ~119 stone 0  
fill ~92 ~2 ~120 ~104 ~2 ~120 stone 0  
fill ~92 ~2 ~121 ~104 ~2 ~121 stone 0  
fill ~92 ~2 ~122 ~105 ~2 ~122 stone 0  
fill ~93 ~2 ~49 ~104 ~2 ~49 stone 0 
setblock ~93 ~2 ~91 grass 0  
fill ~93 ~2 ~107 ~108 ~2 ~107 stone 0  
fill ~93 ~2 ~108 ~108 ~2 ~108 stone 0  
fill ~93 ~2 ~114 ~104 ~2 ~114 stone 0  
fill ~93 ~2 ~115 ~104 ~2 ~115 stone 0  
fill ~93 ~2 ~116 ~104 ~2 ~116 stone 0  
fill ~94 ~2 ~90 ~107 ~2 ~90 stone 0  
fill ~94 ~2 ~91 ~107 ~2 ~91 stone 0  
fill ~94 ~2 ~92 ~108 ~2 ~92 stone 0  
fill ~94 ~2 ~106 ~109 ~2 ~106 stone 0 
setblock ~95 ~2 ~22 grass 0  
fill ~95 ~2 ~93 ~108 ~2 ~93 stone 0  
fill ~95 ~2 ~94 ~108 ~2 ~94 stone 0  
fill ~95 ~2 ~95 ~109 ~2 ~95 stone 0  
fill ~95 ~2 ~96 ~95 ~2 ~97 grass 0  
fill ~95 ~2 ~98 ~109 ~2 ~98 stone 0  
fill ~95 ~2 ~99 ~95 ~2 ~101 grass 0  
fill ~95 ~2 ~102 ~110 ~2 ~102 stone 0 
setblock ~95 ~2 ~104 grass 0  
fill ~95 ~2 ~105 ~109 ~2 ~105 stone 0 
setblock ~96 ~2 ~23 grass 0  
fill ~96 ~2 ~96 ~109 ~2 ~96 stone 0  
fill ~96 ~2 ~97 ~109 ~2 ~97 stone 0  
fill ~96 ~2 ~99 ~109 ~2 ~99 stone 0  
fill ~96 ~2 ~100 ~109 ~2 ~100 stone 0  
fill ~96 ~2 ~101 ~109 ~2 ~101 stone 0  
fill ~96 ~2 ~103 ~110 ~2 ~103 stone 0  
fill ~96 ~2 ~104 ~110 ~2 ~104 stone 0 
setblock ~97 ~2 ~24 grass 0 
setblock ~97 ~2 ~143 grass 0 
setblock ~99 ~2 ~27 grass 0 
setblock ~101 ~2 ~139 grass 0 
setblock ~102 ~2 ~138 grass 0  
fill ~103 ~2 ~70 ~104 ~2 ~70 grass 0 
setblock ~103 ~2 ~137 grass 0  
fill ~104 ~2 ~30 ~104 ~2 ~32 grass 0  
fill ~104 ~2 ~36 ~104 ~2 ~37 grass 0  
fill ~104 ~2 ~63 ~104 ~2 ~72 grass 0  
fill ~104 ~2 ~130 ~104 ~2 ~132 grass 0  
fill ~104 ~2 ~134 ~104 ~2 ~135 grass 0  
fill ~105 ~2 ~37 ~105 ~2 ~38 grass 0 
setblock ~105 ~2 ~45 grass 0  
fill ~105 ~2 ~49 ~105 ~2 ~51 grass 0  
fill ~105 ~2 ~65 ~105 ~2 ~66 grass 0  
fill ~105 ~2 ~71 ~105 ~2 ~73 grass 0 
setblock ~105 ~2 ~78 grass 0  
fill ~105 ~2 ~125 ~105 ~2 ~127 grass 0  
fill ~106 ~2 ~38 ~106 ~2 ~42 grass 0  
fill ~106 ~2 ~72 ~106 ~2 ~77 grass 0  
fill ~106 ~2 ~81 ~106 ~2 ~82 grass 0  
fill ~107 ~2 ~39 ~107 ~2 ~41 grass 0 
setblock ~107 ~2 ~74 grass 0  
fill ~107 ~2 ~85 ~107 ~2 ~86 grass 0  
fill ~108 ~2 ~88 ~108 ~2 ~91 grass 0  
fill ~108 ~2 ~109 ~108 ~2 ~110 grass 0  
fill ~109 ~2 ~93 ~109 ~2 ~94 grass 0  
fill ~109 ~2 ~107 ~109 ~2 ~108 grass 0  
fill ~110 ~2 ~105 ~110 ~0 ~105 dirt 0  
fill ~110 ~2 ~106 ~110 ~0 ~106 dirt 0  
fill ~111 ~2 ~102 ~111 ~2 ~106 grass 0  
fill ~-8 ~3 ~108 ~12 ~3 ~108 stone 0  
fill ~-8 ~3 ~109 ~12 ~3 ~109 stone 0 
setblock ~-7 ~3 ~105 grass 0  
fill ~-7 ~3 ~106 ~12 ~3 ~106 stone 0  
fill ~-7 ~3 ~107 ~12 ~3 ~107 stone 0  
fill ~-7 ~3 ~110 ~13 ~3 ~110 stone 0  
fill ~-7 ~3 ~111 ~13 ~3 ~111 stone 0  
fill ~-7 ~3 ~112 ~13 ~3 ~112 stone 0  
fill ~-7 ~3 ~113 ~13 ~3 ~113 stone 0  
fill ~-7 ~3 ~114 ~14 ~3 ~114 stone 0  
fill ~-7 ~3 ~118 ~-6 ~3 ~118 grass 0  
fill ~-6 ~3 ~102 ~11 ~3 ~102 stone 0  
fill ~-6 ~3 ~103 ~11 ~3 ~103 stone 0  
fill ~-6 ~3 ~104 ~11 ~3 ~104 stone 0  
fill ~-6 ~3 ~105 ~11 ~3 ~105 stone 0  
fill ~-6 ~3 ~115 ~14 ~3 ~115 stone 0 
setblock ~-6 ~3 ~117 grass 0 
setblock ~-5 ~3 ~101 grass 0  
fill ~-5 ~3 ~116 ~15 ~3 ~116 stone 0  
fill ~-5 ~3 ~117 ~15 ~3 ~117 stone 0  
fill ~-5 ~3 ~118 ~15 ~3 ~118 stone 0 
setblock ~-5 ~3 ~119 grass 0  
fill ~-4 ~3 ~101 ~11 ~3 ~101 stone 0  
fill ~-4 ~3 ~119 ~15 ~3 ~119 stone 0  
fill ~-4 ~3 ~120 ~-4 ~3 ~121 grass 0  
fill ~-3 ~3 ~100 ~10 ~3 ~100 stone 0  
fill ~-3 ~3 ~120 ~16 ~3 ~120 stone 0  
fill ~-3 ~3 ~121 ~17 ~3 ~121 stone 0 
setblock ~-3 ~3 ~122 grass 0  
fill ~-2 ~3 ~84 ~-1 ~3 ~84 grass 0  
fill ~-2 ~3 ~85 ~-2 ~3 ~87 grass 0 
setblock ~-2 ~3 ~99 grass 0  
fill ~-2 ~3 ~122 ~23 ~3 ~122 stone 0  
fill ~-2 ~3 ~123 ~-2 ~3 ~124 grass 0  
fill ~-1 ~3 ~75 ~-1 ~3 ~76 grass 0  
fill ~-1 ~3 ~77 ~11 ~3 ~77 stone 0  
fill ~-1 ~3 ~78 ~11 ~3 ~78 stone 0  
fill ~-1 ~3 ~79 ~11 ~3 ~79 stone 0  
fill ~-1 ~3 ~82 ~0 ~3 ~82 grass 0  
fill ~-1 ~3 ~83 ~0 ~3 ~83 grass 0  
fill ~-1 ~3 ~85 ~12 ~3 ~85 stone 0  
fill ~-1 ~3 ~86 ~12 ~3 ~86 stone 0  
fill ~-1 ~3 ~87 ~-1 ~3 ~88 grass 0  
fill ~-1 ~3 ~89 ~13 ~3 ~89 stone 0  
fill ~-1 ~3 ~90 ~13 ~3 ~90 stone 0  
fill ~-1 ~3 ~91 ~12 ~3 ~91 stone 0  
fill ~-1 ~3 ~92 ~11 ~3 ~92 stone 0  
fill ~-1 ~3 ~93 ~11 ~3 ~93 stone 0  
fill ~-1 ~3 ~94 ~10 ~3 ~94 stone 0  
fill ~-1 ~3 ~95 ~9 ~3 ~95 stone 0  
fill ~-1 ~3 ~96 ~10 ~3 ~96 stone 0  
fill ~-1 ~3 ~97 ~10 ~3 ~97 stone 0  
fill ~-1 ~3 ~98 ~10 ~3 ~98 stone 0  
fill ~-1 ~3 ~99 ~10 ~3 ~99 stone 0  
fill ~-1 ~3 ~123 ~25 ~3 ~123 stone 0  
fill ~-1 ~3 ~124 ~26 ~3 ~124 stone 0  
fill ~0 ~3 ~73 ~0 ~3 ~74 grass 0  
fill ~0 ~3 ~75 ~13 ~3 ~75 stone 0  
fill ~0 ~3 ~76 ~12 ~3 ~76 stone 0  
fill ~0 ~3 ~80 ~0 ~3 ~83 grass 0  
fill ~0 ~3 ~84 ~11 ~3 ~84 stone 0  
fill ~0 ~3 ~87 ~13 ~3 ~87 stone 0  
fill ~0 ~3 ~88 ~13 ~3 ~88 stone 0  
fill ~0 ~3 ~125 ~26 ~3 ~125 stone 0  
fill ~0 ~3 ~126 ~27 ~3 ~126 stone 0  
fill ~0 ~3 ~127 ~0 ~3 ~129 grass 0  
fill ~1 ~3 ~72 ~14 ~3 ~72 stone 0  
fill ~1 ~3 ~73 ~14 ~3 ~73 stone 0  
fill ~1 ~3 ~74 ~13 ~3 ~74 stone 0  
fill ~1 ~3 ~80 ~11 ~3 ~80 stone 0   
fill ~1 ~3 ~81 ~10 ~3 ~81 stone 0  
fill ~1 ~3 ~82 ~10 ~3 ~82 stone 0  
fill ~1 ~3 ~83 ~11 ~3 ~83 stone 0  
fill ~1 ~3 ~127 ~27 ~3 ~127 stone 0  
fill ~1 ~3 ~128 ~27 ~3 ~128 stone 0  
fill ~1 ~3 ~129 ~27 ~3 ~129 stone 0 
setblock ~1 ~3 ~130 grass 0  
fill ~2 ~3 ~68 ~17 ~3 ~68 stone 0  
fill ~2 ~3 ~69 ~17 ~3 ~69 stone 0  
fill ~2 ~3 ~70 ~16 ~3 ~70 stone 0  
fill ~2 ~3 ~71 ~15 ~3 ~71 stone 0  
fill ~2 ~3 ~130 ~38 ~3 ~130 stone 0  
fill ~2 ~3 ~131 ~103 ~3 ~131 stone 0  
fill ~2 ~3 ~132 ~103 ~3 ~132 stone 0  
fill ~2 ~3 ~133 ~102 ~3 ~133 stone 0  
fill ~3 ~3 ~67 ~17 ~3 ~67 stone 0  
fill ~3 ~3 ~134 ~4 ~3 ~134 grass 0  
fill ~4 ~3 ~66 ~18 ~3 ~66 stone 0  
fill ~5 ~3 ~63 ~5 ~3 ~64 grass 0  
fill ~5 ~3 ~134 ~57 ~3 ~134 stone 0  
fill ~5 ~3 ~135 ~57 ~3 ~135 stone 0  
fill ~5 ~3 ~136 ~5 ~3 ~137 grass 0  
fill ~6 ~3 ~62 ~19 ~3 ~62 stone 0  
fill ~6 ~3 ~63 ~19 ~3 ~63 stone 0  
fill ~6 ~3 ~64 ~19 ~3 ~64 stone 0  
fill ~6 ~3 ~65 ~19 ~3 ~65 stone 0  
fill ~6 ~3 ~136 ~57 ~3 ~136 stone 0  
fill ~6 ~3 ~137 ~6 ~3 ~138 grass 0 
setblock ~7 ~3 ~57 grass 0  
fill ~7 ~3 ~58 ~22 ~3 ~58 stone 0  
fill ~7 ~3 ~59 ~21 ~3 ~59 stone 0  
fill ~7 ~3 ~60 ~20 ~3 ~60 stone 0  
fill ~7 ~3 ~61 ~19 ~3 ~61 stone 0  
fill ~7 ~3 ~137 ~56 ~3 ~137 stone 0  
fill ~7 ~3 ~138 ~7 ~3 ~139 grass 0  
fill ~8 ~3 ~55 ~31 ~3 ~55 stone 0  
fill ~8 ~3 ~56 ~30 ~3 ~56 stone 0  
fill ~8 ~3 ~57 ~28 ~3 ~57 stone 0  
fill ~8 ~3 ~138 ~56 ~3 ~138 stone 0 
setblock ~8 ~3 ~139 grass 0  
fill ~9 ~3 ~54 ~32 ~3 ~54 stone 0  
fill ~9 ~3 ~139 ~56 ~3 ~139 stone 0  
fill ~9 ~3 ~140 ~11 ~3 ~140 grass 0  
fill ~10 ~3 ~53 ~32 ~3 ~53 stone 0 
setblock ~11 ~3 ~52 grass 0 
setblock ~11 ~3 ~81 grass 0 
setblock ~11 ~3 ~94 grass 0  
fill ~11 ~3 ~141 ~55 ~3 ~141 stone 0 
setblock ~12 ~3 ~51 grass 0  
fill ~12 ~3 ~52 ~33 ~3 ~52 stone 0  
fill ~12 ~3 ~92 ~12 ~3 ~93 grass 0  
fill ~12 ~3 ~140 ~56 ~3 ~140 stone 0  
fill ~12 ~3 ~142 ~54 ~3 ~142 stone 0  
fill ~12 ~3 ~143 ~53 ~3 ~143 stone 0  
fill ~13 ~3 ~51 ~34 ~3 ~51 stone 0  
fill ~13 ~3 ~144 ~23 ~3 ~144 stone 0 
setblock ~14 ~3 ~50 grass 0  
fill ~14 ~3 ~145 ~23 ~3 ~145 stone 0  
fill ~15 ~3 ~50 ~35 ~3 ~50 stone 0  
fill ~15 ~3 ~146 ~21 ~3 ~146 stone 0  
fill ~16 ~3 ~49 ~36 ~3 ~49 stone 0 
setblock ~16 ~3 ~119 grass 0  
fill ~17 ~3 ~48 ~37 ~3 ~48 stone 0 
setblock ~17 ~3 ~70 grass 0  
fill ~18 ~3 ~47 ~38 ~3 ~47 stone 0 
setblock ~18 ~3 ~67 grass 0  
fill ~19 ~3 ~46 ~21 ~3 ~46 grass 0  
fill ~20 ~3 ~45 ~21 ~3 ~45 grass 0 
setblock ~21 ~3 ~44 grass 0  
fill ~22 ~3 ~44 ~22 ~3 ~58 stone 0  
fill ~22 ~3 ~146 ~23 ~3 ~146 grass 0  
fill ~23 ~3 ~44 ~26 ~3 ~44 grass 0  
fill ~23 ~3 ~45 ~23 ~3 ~57 stone 0  
fill ~24 ~3 ~45 ~26 ~3 ~45 grass 0  
fill ~24 ~3 ~46 ~39 ~3 ~46 stone 0  
fill ~25 ~3 ~145 ~27 ~3 ~145 stone 0  
fill ~25 ~3 ~146 ~27 ~3 ~146 grass 0  
fill ~26 ~3 ~123 ~28 ~3 ~123 grass 0  
fill ~26 ~3 ~144 ~52 ~3 ~144 stone 0  
fill ~27 ~3 ~21 ~27 ~3 ~25 grass 0  
fill ~27 ~3 ~44 ~40 ~3 ~44 stone 0  
fill ~27 ~3 ~45 ~39 ~3 ~45 stone 0  
fill ~27 ~3 ~124 ~29 ~3 ~124 grass 0  
fill ~27 ~3 ~125 ~29 ~3 ~125 grass 0  
fill ~28 ~3 ~20 ~53 ~3 ~20 stone 0  
fill ~28 ~3 ~21 ~53 ~3 ~21 stone 0  
fill ~28 ~3 ~22 ~54 ~3 ~22 stone 0  
fill ~28 ~3 ~23 ~54 ~3 ~23 stone 0  
fill ~28 ~3 ~24 ~54 ~3 ~24 stone 0  
fill ~28 ~3 ~25 ~53 ~3 ~25 stone 0 
setblock ~28 ~3 ~26 grass 0  
fill ~28 ~3 ~42 ~42 ~3 ~42 stone 0  
fill ~28 ~3 ~43 ~41 ~3 ~43 stone 0  
fill ~28 ~3 ~126 ~29 ~3 ~126 grass 0  
fill ~28 ~3 ~127 ~28 ~3 ~123 grass 0  
fill ~29 ~3 ~26 ~53 ~3 ~26 stone 0  
fill ~29 ~3 ~27 ~52 ~3 ~27 stone 0 
setblock ~29 ~3 ~28 grass 0 
setblock ~29 ~3 ~57 grass 0  
fill ~29 ~3 ~129 ~37 ~3 ~129 stone 0 
setblock ~30 ~3 ~19 grass 0  
fill ~30 ~3 ~28 ~52 ~3 ~28 stone 0  
fill ~30 ~3 ~29 ~52 ~3 ~29 stone 0 
setblock ~30 ~3 ~30 grass 0 
setblock ~31 ~3 ~18 grass 0  
fill ~31 ~3 ~19 ~52 ~3 ~19 stone 0  
fill ~31 ~3 ~30 ~53 ~3 ~30 stone 0  
fill ~31 ~3 ~40 ~44 ~3 ~40 stone 0  
fill ~31 ~3 ~41 ~43 ~3 ~41 stone 0  
fill ~31 ~3 ~128 ~35 ~3 ~128 stone 0 
setblock ~32 ~3 ~17 grass 0  
fill ~32 ~3 ~18 ~50 ~3 ~18 stone 0  
fill ~32 ~3 ~31 ~53 ~3 ~31 stone 0 
setblock ~32 ~3 ~36 grass 0  
fill ~32 ~3 ~37 ~44 ~3 ~37 stone 0  
fill ~32 ~3 ~38 ~44 ~3 ~38 stone 0  
fill ~32 ~3 ~39 ~44 ~3 ~39 stone 0  
fill ~32 ~3 ~145 ~45 ~3 ~145 stone 0 
setblock ~32 ~3 ~146 grass 0  
fill ~33 ~3 ~16 ~51 ~3 ~16 stone 0  
fill ~33 ~3 ~17 ~50 ~3 ~17 stone 0  
fill ~33 ~3 ~32 ~53 ~3 ~32 stone 0  
fill ~33 ~3 ~33 ~52 ~3 ~33 stone 0  
fill ~33 ~3 ~34 ~52 ~3 ~34 stone 0  
fill ~33 ~3 ~35 ~51 ~3 ~35 stone 0  
fill ~33 ~3 ~36 ~49 ~3 ~36 stone 0  
fill ~33 ~3 ~146 ~42 ~3 ~146 stone 0  
fill ~33 ~3 ~147 ~40 ~3 ~147 stone 0  
fill ~33 ~3 ~148 ~35 ~3 ~148 grass 0 
setblock ~35 ~3 ~13 grass 0  
fill ~35 ~3 ~14 ~53 ~3 ~14 stone 0  
fill ~35 ~3 ~15 ~52 ~3 ~15 stone 0  
fill ~36 ~3 ~13 ~57 ~3 ~13 stone 0  
fill ~36 ~3 ~148 ~38 ~3 ~148 stone 0  
fill ~38 ~3 ~12 ~91 ~3 ~12 stone 0  
fill ~38 ~3 ~128 ~40 ~3 ~128 grass 0  
fill ~38 ~3 ~129 ~41 ~3 ~129 grass 0  
fill ~39 ~3 ~9 ~40 ~3 ~9 grass 0  
fill ~39 ~3 ~10 ~91 ~3 ~10 stone 0  
fill ~39 ~3 ~11 ~91 ~3 ~11 stone 0  
fill ~39 ~3 ~130 ~40 ~3 ~130 grass 0  
fill ~39 ~3 ~148 ~45 ~3 ~148 grass 0  
fill ~41 ~3 ~9 ~90 ~3 ~9 stone 0  
fill ~41 ~3 ~130 ~103 ~3 ~130 stone 0  
fill ~41 ~3 ~147 ~46 ~3 ~147 grass 0  
fill ~42 ~3 ~8 ~43 ~3 ~8 grass 0  
fill ~42 ~3 ~119 ~46 ~3 ~119 grass 0  
fill ~42 ~3 ~120 ~46 ~3 ~120 grass 0  
fill ~42 ~3 ~121 ~46 ~3 ~121 grass 0  
fill ~43 ~3 ~118 ~45 ~3 ~118 grass 0  
fill ~43 ~3 ~122 ~45 ~3 ~122 grass 0  
fill ~43 ~3 ~129 ~103 ~3 ~129 stone 0  
fill ~43 ~3 ~146 ~46 ~3 ~146 grass 0  
fill ~44 ~3 ~8 ~90 ~3 ~8 stone 0  
fill ~45 ~3 ~7 ~88 ~3 ~7 stone 0  
fill ~45 ~3 ~125 ~76 ~3 ~125 stone 0  
fill ~45 ~3 ~126 ~77 ~3 ~126 stone 0  
fill ~45 ~3 ~127 ~78 ~3 ~127 stone 0  
fill ~45 ~3 ~128 ~82 ~3 ~128 stone 0  
fill ~46 ~3 ~6 ~84 ~3 ~6 stone 0  
fill ~46 ~3 ~123 ~72 ~3 ~123 stone 0  
fill ~46 ~3 ~124 ~75 ~3 ~124 stone 0 
setblock ~46 ~3 ~145 grass 0  
fill ~47 ~3 ~2 ~80 ~3 ~2 stone 0 
setblock ~47 ~3 ~3 grass 0 
setblock ~47 ~3 ~5 grass 0  
fill ~47 ~3 ~122 ~71 ~3 ~122 stone 0  
fill ~48 ~3 ~3 ~82 ~3 ~3 stone 0  
fill ~48 ~3 ~4 ~82 ~3 ~4 stone 0  
fill ~48 ~3 ~5 ~83 ~3 ~5 stone 0  
fill ~48 ~3 ~121 ~65 ~3 ~121 stone 0  
fill ~48 ~3 ~145 ~52 ~3 ~145 stone 0  
fill ~49 ~3 ~0 ~73 ~3 ~0 stone 0  
fill ~49 ~3 ~1 ~76 ~3 ~1 stone 0  
fill ~50 ~3 ~-1 ~72 ~3 ~-1 stone 0 
setblock ~50 ~3 ~36 grass 0 
setblock ~52 ~3 ~-5 grass 0  
fill ~52 ~3 ~-4 ~71 ~3 ~-4 stone 0  
fill ~52 ~3 ~-3 ~72 ~3 ~-3 stone 0  
fill ~52 ~3 ~-2 ~72 ~3 ~-2 stone 0  
fill ~53 ~3 ~-5 ~69 ~3 ~-5 stone 0 
setblock ~53 ~3 ~33 grass 0  
fill ~53 ~3 ~120 ~61 ~3 ~120 stone 0  
fill ~53 ~3 ~144 ~54 ~3 ~144 grass 0  
fill ~53 ~3 ~145 ~53 ~3 ~144 grass 0 
setblock ~54 ~3 ~21 grass 0 
setblock ~54 ~3 ~25 grass 0 
setblock ~54 ~3 ~143 grass 0  
fill ~56 ~3 ~-7 ~66 ~3 ~-7 stone 0  
fill ~56 ~3 ~-6 ~69 ~3 ~-6 stone 0  
fill ~58 ~3 ~134 ~58 ~3 ~136 grass 0  
fill ~59 ~3 ~134 ~103 ~3 ~134 stone 0 
setblock ~59 ~3 ~135 grass 0 
setblock ~61 ~3 ~-8 grass 0  
fill ~62 ~3 ~-8 ~64 ~3 ~-8 stone 0  
fill ~63 ~3 ~-9 ~66 ~3 ~-9 grass 0  
fill ~63 ~3 ~135 ~65 ~3 ~135 grass 0  
fill ~64 ~3 ~13 ~91 ~3 ~13 stone 0  
fill ~65 ~3 ~-8 ~66 ~3 ~-8 grass 0  
fill ~65 ~3 ~14 ~91 ~3 ~14 stone 0  
fill ~65 ~3 ~136 ~68 ~3 ~136 grass 0  
fill ~66 ~3 ~15 ~91 ~3 ~15 stone 0  
fill ~66 ~3 ~135 ~103 ~3 ~135 stone 0 
setblock ~67 ~3 ~-7 grass 0  
fill ~68 ~3 ~16 ~92 ~3 ~16 stone 0 
setblock ~70 ~3 ~-5 grass 0  
fill ~70 ~3 ~19 ~70 ~3 ~21 grass 0 
setblock ~70 ~3 ~136 grass 0  
fill ~71 ~3 ~17 ~92 ~3 ~17 stone 0  
fill ~71 ~3 ~18 ~93 ~3 ~18 stone 0  
fill ~71 ~3 ~19 ~93 ~3 ~19 stone 0  
fill ~71 ~3 ~20 ~93 ~3 ~20 stone 0  
fill ~71 ~3 ~21 ~94 ~3 ~21 stone 0  
fill ~71 ~3 ~22 ~79 ~3 ~22 stone 0  
fill ~71 ~3 ~136 ~103 ~3 ~136 stone 0  
fill ~72 ~3 ~23 ~78 ~3 ~23 stone 0  
fill ~73 ~3 ~-3 ~73 ~3 ~-1 grass 0  
fill ~73 ~3 ~24 ~77 ~3 ~24 stone 0  
fill ~73 ~3 ~137 ~102 ~3 ~137 stone 0 
setblock ~73 ~3 ~138 grass 0  
fill ~74 ~3 ~-2 ~75 ~3 ~-2 grass 0  
fill ~74 ~3 ~-1 ~75 ~3 ~-1 grass 0  
fill ~74 ~3 ~0 ~74 ~3 ~-2 grass 0  
fill ~74 ~3 ~138 ~100 ~3 ~138 stone 0  
fill ~75 ~3 ~139 ~100 ~3 ~139 stone 0  
fill ~76 ~3 ~140 ~99 ~3 ~140 stone 0  
fill ~77 ~3 ~0 ~77 ~3 ~1 grass 0 
setblock ~78 ~3 ~1 grass 0  
fill ~78 ~3 ~141 ~98 ~3 ~141 stone 0  
fill ~78 ~3 ~142 ~97 ~3 ~142 stone 0 
setblock ~78 ~3 ~143 grass 0  
fill ~79 ~3 ~143 ~95 ~3 ~143 stone 0  
fill ~79 ~3 ~144 ~85 ~3 ~144 stone 0  
fill ~79 ~3 ~145 ~82 ~3 ~145 grass 0 
setblock ~80 ~3 ~22 grass 0 
setblock ~81 ~3 ~2 grass 0  
fill ~81 ~3 ~22 ~94 ~3 ~22 stone 0  
fill ~82 ~3 ~23 ~95 ~3 ~23 stone 0 
setblock ~83 ~3 ~4 grass 0  
fill ~83 ~3 ~24 ~96 ~3 ~24 stone 0  
fill ~83 ~3 ~25 ~97 ~3 ~25 stone 0  
fill ~83 ~3 ~26 ~97 ~3 ~26 stone 0 
setblock ~83 ~3 ~27 grass 0 
setblock ~83 ~3 ~145 stone 0 
setblock ~83 ~3 ~146 grass 0  
fill ~84 ~3 ~27 ~98 ~3 ~27 stone 0  
fill ~84 ~3 ~28 ~100 ~3 ~28 stone 0 
setblock ~84 ~3 ~128 grass 0  
fill ~84 ~3 ~145 ~85 ~3 ~145 grass 0  
fill ~85 ~3 ~6 ~86 ~3 ~6 grass 0  
fill ~85 ~3 ~29 ~102 ~3 ~29 stone 0  
fill ~85 ~3 ~30 ~103 ~3 ~30 stone 0  
fill ~85 ~3 ~128 ~88 ~3 ~128 stone 0  
fill ~86 ~3 ~31 ~103 ~3 ~31 stone 0  
fill ~86 ~3 ~144 ~88 ~3 ~144 grass 0  
fill ~87 ~3 ~32 ~103 ~3 ~32 stone 0  
fill ~87 ~3 ~33 ~104 ~3 ~33 stone 0  
fill ~87 ~3 ~73 ~104 ~3 ~73 stone 0  
fill ~87 ~3 ~74 ~104 ~3 ~74 stone 0  
fill ~87 ~3 ~75 ~105 ~3 ~75 stone 0  
fill ~87 ~3 ~76 ~105 ~3 ~76 stone 0  
fill ~87 ~3 ~77 ~105 ~3 ~77 stone 0  
fill ~87 ~3 ~79 ~104 ~3 ~79 stone 0  
fill ~87 ~3 ~80 ~104 ~3 ~80 stone 0  
fill ~87 ~3 ~81 ~105 ~3 ~81 stone 0  
fill ~87 ~3 ~82 ~105 ~3 ~82 stone 0  
fill ~88 ~3 ~34 ~104 ~3 ~34 stone 0  
fill ~88 ~3 ~70 ~102 ~3 ~70 stone 0  
fill ~88 ~3 ~71 ~103 ~3 ~71 stone 0  
fill ~88 ~3 ~72 ~103 ~3 ~72 stone 0  
fill ~88 ~3 ~78 ~104 ~3 ~78 stone 0  
fill ~88 ~3 ~83 ~105 ~3 ~83 stone 0  
fill ~88 ~3 ~84 ~105 ~3 ~84 stone 0  
fill ~88 ~3 ~85 ~105 ~3 ~85 stone 0  
fill ~89 ~3 ~35 ~104 ~3 ~35 stone 0  
fill ~89 ~3 ~67 ~102 ~3 ~67 stone 0  
fill ~89 ~3 ~68 ~101 ~3 ~68 stone 0  
fill ~89 ~3 ~69 ~101 ~3 ~69 stone 0  
fill ~89 ~3 ~86 ~106 ~3 ~86 stone 0 
setblock ~89 ~3 ~128 grass 0  
fill ~90 ~3 ~36 ~103 ~3 ~36 stone 0  
fill ~90 ~3 ~37 ~103 ~3 ~37 stone 0  
fill ~90 ~3 ~38 ~103 ~3 ~38 stone 0  
fill ~90 ~3 ~65 ~103 ~3 ~65 stone 0  
fill ~90 ~3 ~66 ~102 ~3 ~66 stone 0  
fill ~90 ~3 ~87 ~106 ~3 ~87 stone 0  
fill ~91 ~3 ~39 ~103 ~3 ~39 stone 0  
fill ~91 ~3 ~57 ~104 ~3 ~57 stone 0  
fill ~91 ~3 ~58 ~104 ~3 ~58 stone 0  
fill ~91 ~3 ~59 ~103 ~3 ~59 stone 0  
fill ~91 ~3 ~60 ~103 ~3 ~60 stone 0  
fill ~91 ~3 ~61 ~103 ~3 ~61 stone 0  
fill ~91 ~3 ~62 ~103 ~3 ~62 stone 0  
fill ~91 ~3 ~63 ~103 ~3 ~63 stone 0  
fill ~91 ~3 ~64 ~103 ~3 ~64 stone 0  
fill ~91 ~3 ~88 ~106 ~3 ~88 stone 0 
setblock ~91 ~3 ~123 grass 0  
fill ~91 ~3 ~124 ~104 ~3 ~124 stone 0  
fill ~91 ~3 ~125 ~104 ~3 ~125 stone 0  
fill ~91 ~3 ~126 ~104 ~3 ~126 stone 0  
fill ~91 ~3 ~127 ~91 ~3 ~128 grass 0  
fill ~91 ~3 ~144 ~94 ~3 ~144 grass 0 
setblock ~92 ~3 ~15 grass 0  
fill ~92 ~3 ~40 ~104 ~3 ~40 stone 0  
fill ~92 ~3 ~41 ~104 ~3 ~41 stone 0  
fill ~92 ~3 ~42 ~104 ~3 ~42 stone 0  
fill ~92 ~3 ~43 ~104 ~3 ~43 stone 0  
fill ~92 ~3 ~44 ~104 ~3 ~44 stone 0  
fill ~92 ~3 ~45 ~104 ~3 ~45 stone 0  
fill ~92 ~3 ~46 ~104 ~3 ~46 stone 0  
fill ~92 ~3 ~47 ~104 ~3 ~47 stone 0  
fill ~92 ~3 ~48 ~104 ~3 ~48 stone 0  
fill ~92 ~3 ~50 ~92 ~3 ~52 grass 0  
fill ~92 ~3 ~53 ~104 ~3 ~53 stone 0  
fill ~92 ~3 ~54 ~104 ~3 ~54 stone 0  
fill ~92 ~3 ~55 ~104 ~3 ~55 stone 0  
fill ~92 ~3 ~56 ~104 ~3 ~56 stone 0  
fill ~92 ~3 ~89 ~106 ~3 ~89 stone 0 
setblock ~92 ~3 ~109 grass 0  
fill ~92 ~3 ~110 ~106 ~3 ~110 stone 0  
fill ~92 ~3 ~111 ~104 ~3 ~111 stone 0  
fill ~92 ~3 ~112 ~104 ~3 ~112 stone 0 
setblock ~92 ~3 ~113 grass 0 
setblock ~92 ~3 ~117 grass 0  
fill ~92 ~3 ~118 ~104 ~3 ~118 stone 0  
fill ~92 ~3 ~119 ~104 ~3 ~119 stone 0  
fill ~92 ~3 ~120 ~104 ~3 ~120 stone 0  
fill ~92 ~3 ~121 ~104 ~3 ~121 stone 0  
fill ~92 ~3 ~122 ~105 ~3 ~122 stone 0  
fill ~92 ~3 ~123 ~104 ~3 ~123 stone 0  
fill ~92 ~3 ~127 ~104 ~3 ~127 stone 0  
fill ~92 ~3 ~128 ~104 ~3 ~128 stone 0 
setblock ~93 ~3 ~17 grass 0  
fill ~93 ~3 ~49 ~104 ~3 ~49 stone 0  
fill ~93 ~3 ~50 ~104 ~3 ~50 stone 0  
fill ~93 ~3 ~51 ~104 ~3 ~51 stone 0  
fill ~93 ~3 ~52 ~104 ~3 ~52 stone 0 
setblock ~93 ~3 ~107 grass 0  
fill ~93 ~3 ~108 ~107 ~3 ~108 stone 0  
fill ~93 ~3 ~109 ~107 ~3 ~109 stone 0  
fill ~93 ~3 ~113 ~103 ~3 ~113 stone 0  
fill ~93 ~3 ~114 ~103 ~3 ~114 stone 0  
fill ~93 ~3 ~115 ~104 ~3 ~115 stone 0  
fill ~93 ~3 ~116 ~104 ~3 ~116 stone 0  
fill ~93 ~3 ~117 ~104 ~3 ~117 stone 0  
fill ~94 ~3 ~90 ~106 ~3 ~90 stone 0  
fill ~94 ~3 ~91 ~107 ~3 ~91 stone 0  
fill ~94 ~3 ~92 ~107 ~3 ~92 stone 0  
fill ~94 ~3 ~106 ~109 ~3 ~106 stone 0  
fill ~94 ~3 ~107 ~108 ~3 ~107 stone 0  
fill ~95 ~3 ~93 ~108 ~3 ~93 stone 0  
fill ~95 ~3 ~94 ~108 ~3 ~94 stone 0  
fill ~95 ~3 ~95 ~108 ~3 ~95 stone 0  
fill ~95 ~3 ~98 ~109 ~3 ~98 stone 0  
fill ~95 ~3 ~102 ~109 ~3 ~102 stone 0 
setblock ~95 ~3 ~105 grass 0  
fill ~96 ~3 ~96 ~108 ~3 ~96 stone 0  
fill ~96 ~3 ~97 ~109 ~3 ~97 stone 0  
fill ~96 ~3 ~99 ~109 ~3 ~99 stone 0  
fill ~96 ~3 ~100 ~109 ~3 ~100 stone 0  
fill ~96 ~3 ~101 ~109 ~3 ~101 stone 0  
fill ~96 ~3 ~103 ~109 ~3 ~103 stone 0  
fill ~96 ~3 ~104 ~109 ~3 ~104 stone 0  
fill ~96 ~3 ~105 ~109 ~3 ~105 stone 0 
setblock ~96 ~3 ~143 grass 0 
setblock ~98 ~3 ~142 grass 0 
setblock ~99 ~3 ~141 grass 0 
setblock ~100 ~3 ~140 grass 0 
setblock ~101 ~3 ~138 grass 0 
setblock ~103 ~3 ~29 grass 0 
setblock ~103 ~3 ~66 grass 0 
setblock ~103 ~3 ~133 grass 0  
fill ~104 ~3 ~38 ~104 ~3 ~39 grass 0  
fill ~104 ~3 ~113 ~104 ~3 ~114 grass 0 
setblock ~104 ~3 ~129 grass 0  
fill ~105 ~3 ~39 ~105 ~3 ~44 grass 0 
setblock ~105 ~3 ~74 grass 0 
setblock ~105 ~3 ~111 grass 0  
fill ~106 ~3 ~83 ~106 ~3 ~85 grass 0 
setblock ~106 ~3 ~111 stone 0  
fill ~107 ~3 ~87 ~107 ~3 ~90 grass 0 
setblock ~107 ~3 ~110 grass 0 
setblock ~108 ~3 ~92 grass 0 
setblock ~108 ~3 ~108 grass 0  
fill ~109 ~3 ~95 ~109 ~3 ~96 grass 0  
fill ~110 ~3 ~102 ~110 ~3 ~106 grass 0  
fill ~-8 ~4 ~108 ~-8 ~4 ~109 grass 0 
setblock ~-7 ~4 ~106 grass 0  
fill ~-7 ~4 ~107 ~-5 ~4 ~107 stone 0  
fill ~-7 ~4 ~108 ~12 ~4 ~108 stone 0  
fill ~-7 ~4 ~109 ~12 ~4 ~109 stone 0  
fill ~-7 ~4 ~110 ~12 ~4 ~110 stone 0  
fill ~-7 ~4 ~111 ~13 ~4 ~111 stone 0  
fill ~-7 ~4 ~112 ~-7 ~4 ~114 grass 0  
fill ~-6 ~4 ~102 ~11 ~4 ~102 stone 0  
fill ~-6 ~4 ~103 ~11 ~4 ~103 stone 0 
setblock ~-6 ~4 ~104 grass 0  
fill ~-6 ~4 ~105 ~11 ~4 ~105 stone 0  
fill ~-6 ~4 ~106 ~11 ~4 ~106 stone 0  
fill ~-6 ~4 ~112 ~13 ~4 ~112 stone 0  
fill ~-6 ~4 ~113 ~13 ~4 ~113 stone 0  
fill ~-6 ~4 ~114 ~14 ~4 ~114 stone 0 
setblock ~-6 ~4 ~115 grass 0  
fill ~-5 ~4 ~104 ~11 ~4 ~104 stone 0  
fill ~-5 ~4 ~115 ~14 ~4 ~115 stone 0  
fill ~-5 ~4 ~116 ~-5 ~4 ~118 grass 0 
setblock ~-4 ~4 ~101 grass 0 
setblock ~-4 ~4 ~107 grass 0  
fill ~-4 ~4 ~116 ~14 ~4 ~116 stone 0  
fill ~-4 ~4 ~117 ~15 ~4 ~117 stone 0  
fill ~-4 ~4 ~118 ~15 ~4 ~118 stone 0 
setblock ~-4 ~4 ~119 grass 0 
setblock ~-3 ~4 ~100 grass 0  
fill ~-3 ~4 ~101 ~11 ~4 ~101 stone 0  
fill ~-3 ~4 ~107 ~11 ~4 ~107 stone 0  
fill ~-3 ~4 ~119 ~15 ~4 ~119 stone 0  
fill ~-3 ~4 ~120 ~-3 ~4 ~121 grass 0  
fill ~-2 ~4 ~100 ~10 ~4 ~100 stone 0  
fill ~-2 ~4 ~120 ~16 ~4 ~120 stone 0  
fill ~-2 ~4 ~121 ~17 ~4 ~121 stone 0 
setblock ~-2 ~4 ~122 grass 0  
fill ~-1 ~4 ~77 ~-1 ~4 ~79 grass 0  
fill ~-1 ~4 ~85 ~-1 ~4 ~86 grass 0  
fill ~-1 ~4 ~89 ~13 ~4 ~89 stone 0  
fill ~-1 ~4 ~90 ~12 ~4 ~90 stone 0  
fill ~-1 ~4 ~91 ~12 ~4 ~91 stone 0  
fill ~-1 ~4 ~92 ~11 ~4 ~92 stone 0  
fill ~-1 ~4 ~93 ~11 ~4 ~93 stone 0  
fill ~-1 ~4 ~94 ~10 ~4 ~94 stone 0  
fill ~-1 ~4 ~95 ~9 ~4 ~95 stone 0  
fill ~-1 ~4 ~96 ~10 ~4 ~96 stone 0  
fill ~-1 ~4 ~97 ~10 ~4 ~97 stone 0  
fill ~-1 ~4 ~98 ~10 ~4 ~98 stone 0  
fill ~-1 ~4 ~99 ~10 ~4 ~99 stone 0  
fill ~-1 ~4 ~122 ~22 ~4 ~122 stone 0  
fill ~-1 ~4 ~123 ~-1 ~4 ~124 grass 0 
setblock ~0 ~4 ~75 grass 0  
fill ~0 ~4 ~76 ~12 ~4 ~76 stone 0  
fill ~0 ~4 ~77 ~11 ~4 ~77 stone 0  
fill ~0 ~4 ~78 ~11 ~4 ~78 stone 0  
fill ~0 ~4 ~79 ~11 ~4 ~79 stone 0 
setblock ~0 ~4 ~84 grass 0  
fill ~0 ~4 ~85 ~12 ~4 ~85 stone 0  
fill ~0 ~4 ~86 ~12 ~4 ~86 stone 0  
fill ~0 ~4 ~87 ~12 ~4 ~87 stone 0  
fill ~0 ~4 ~88 ~13 ~4 ~88 stone 0  
fill ~0 ~4 ~123 ~25 ~4 ~123 stone 0  
fill ~0 ~4 ~124 ~26 ~4 ~124 stone 0  
fill ~0 ~4 ~125 ~26 ~4 ~125 stone 0  
fill ~0 ~4 ~126 ~27 ~4 ~126 stone 0  
fill ~1 ~4 ~72 ~14 ~4 ~72 stone 0  
fill ~1 ~4 ~73 ~1 ~4 ~74 grass 0  
fill ~1 ~4 ~75 ~12 ~4 ~75 stone 0  
fill ~1 ~4 ~80 ~11 ~4 ~80 stone 0  
fill ~1 ~4 ~81 ~10 ~4 ~81 stone 0  
fill ~1 ~4 ~82 ~10 ~4 ~82 stone 0  
fill ~1 ~4 ~83 ~10 ~4 ~83 stone 0  
fill ~1 ~4 ~84 ~11 ~4 ~84 stone 0  
fill ~1 ~4 ~127 ~27 ~4 ~127 stone 0  
fill ~1 ~4 ~128 ~27 ~4 ~128 stone 0  
fill ~1 ~4 ~129 ~27 ~4 ~129 stone 0  
fill ~2 ~4 ~68 ~17 ~4 ~68 stone 0  
fill ~2 ~4 ~69 ~17 ~4 ~69 stone 0  
fill ~2 ~4 ~70 ~16 ~4 ~70 stone 0  
fill ~2 ~4 ~71 ~14 ~4 ~71 stone 0  
fill ~2 ~4 ~73 ~14 ~4 ~73 stone 0  
fill ~2 ~4 ~74 ~13 ~4 ~74 stone 0  
fill ~2 ~4 ~130 ~27 ~4 ~130 stone 0  
fill ~2 ~4 ~131 ~102 ~4 ~131 stone 0  
fill ~2 ~4 ~132 ~3 ~4 ~132 grass 0  
fill ~2 ~4 ~133 ~6 ~4 ~133 grass 0  
fill ~3 ~4 ~67 ~17 ~4 ~67 stone 0  
fill ~4 ~4 ~66 ~18 ~4 ~66 stone 0  
fill ~4 ~4 ~132 ~102 ~4 ~132 stone 0  
fill ~5 ~4 ~134 ~5 ~4 ~135 grass 0  
fill ~6 ~4 ~62 ~6 ~4 ~63 grass 0  
fill ~6 ~4 ~64 ~19 ~4 ~64 stone 0  
fill ~6 ~4 ~65 ~19 ~4 ~65 stone 0  
fill ~6 ~4 ~134 ~57 ~4 ~134 stone 0  
fill ~6 ~4 ~135 ~57 ~4 ~135 stone 0 
setblock ~6 ~4 ~136 grass 0  
fill ~7 ~4 ~58 ~7 ~4 ~61 grass 0  
fill ~7 ~4 ~62 ~19 ~4 ~62 stone 0  
fill ~7 ~4 ~63 ~19 ~4 ~63 stone 0  
fill ~7 ~4 ~133 ~102 ~4 ~133 stone 0  
fill ~7 ~4 ~136 ~57 ~4 ~136 stone 0 
setblock ~7 ~4 ~137 grass 0 
setblock ~8 ~4 ~55 grass 0  
fill ~8 ~4 ~56 ~9 ~4 ~56 stone 0 
setblock ~8 ~4 ~57 grass 0  
fill ~8 ~4 ~58 ~22 ~4 ~58 stone 0  
fill ~8 ~4 ~59 ~21 ~4 ~59 stone 0  
fill ~8 ~4 ~60 ~20 ~4 ~60 stone 0  
fill ~8 ~4 ~61 ~19 ~4 ~61 stone 0  
fill ~8 ~4 ~137 ~56 ~4 ~137 stone 0 
setblock ~8 ~4 ~138 grass 0  
fill ~9 ~4 ~54 ~31 ~4 ~54 stone 0  
fill ~9 ~4 ~55 ~31 ~4 ~55 stone 0  
fill ~9 ~4 ~57 ~23 ~4 ~57 stone 0  
fill ~9 ~4 ~138 ~56 ~4 ~138 stone 0  
fill ~9 ~4 ~139 ~10 ~4 ~139 grass 0  
fill ~10 ~4 ~53 ~32 ~4 ~53 stone 0  
fill ~11 ~4 ~56 ~30 ~4 ~56 stone 0 
setblock ~11 ~4 ~83 grass 0  
fill ~11 ~4 ~139 ~56 ~4 ~139 stone 0 
setblock ~11 ~4 ~141 grass 0 
setblock ~12 ~4 ~52 grass 0  
fill ~12 ~4 ~106 ~12 ~4 ~107 grass 0  
fill ~12 ~4 ~140 ~55 ~4 ~140 stone 0  
fill ~12 ~4 ~141 ~55 ~4 ~141 stone 0  
fill ~12 ~4 ~142 ~12 ~4 ~143 grass 0 
setblock ~13 ~4 ~51 grass 0  
fill ~13 ~4 ~52 ~33 ~4 ~52 stone 0 
setblock ~13 ~4 ~75 grass 0 
setblock ~13 ~4 ~87 grass 0 
setblock ~13 ~4 ~90 grass 0 
setblock ~13 ~4 ~110 grass 0  
fill ~13 ~4 ~142 ~52 ~4 ~142 stone 0  
fill ~13 ~4 ~143 ~52 ~4 ~143 stone 0 
setblock ~13 ~4 ~144 grass 0  
fill ~14 ~4 ~51 ~34 ~4 ~51 stone 0  
fill ~14 ~4 ~144 ~23 ~4 ~144 stone 0  
fill ~14 ~4 ~145 ~15 ~4 ~145 grass 0 
setblock ~15 ~4 ~50 grass 0 
setblock ~15 ~4 ~71 grass 0 
setblock ~15 ~4 ~116 grass 0  
fill ~15 ~4 ~146 ~21 ~4 ~146 grass 0  
fill ~16 ~4 ~49 ~36 ~4 ~49 stone 0  
fill ~16 ~4 ~50 ~35 ~4 ~50 stone 0  
fill ~16 ~4 ~145 ~23 ~4 ~145 stone 0  
fill ~17 ~4 ~48 ~37 ~4 ~48 stone 0  
fill ~18 ~4 ~47 ~38 ~4 ~47 stone 0  
fill ~22 ~4 ~44 ~22 ~4 ~45 grass 0  
fill ~22 ~4 ~46 ~23 ~4 ~46 stone 0 
setblock ~23 ~4 ~45 grass 0 
setblock ~23 ~4 ~122 grass 0 
setblock ~24 ~4 ~46 grass 0  
fill ~24 ~4 ~57 ~28 ~4 ~57 grass 0  
fill ~25 ~4 ~46 ~38 ~4 ~46 stone 0  
fill ~25 ~4 ~145 ~27 ~4 ~145 stone 0  
fill ~26 ~4 ~144 ~52 ~4 ~144 stone 0  
fill ~27 ~4 ~44 ~40 ~4 ~44 stone 0  
fill ~27 ~4 ~45 ~39 ~4 ~45 stone 0 
setblock ~28 ~4 ~20 grass 0  
fill ~28 ~4 ~21 ~53 ~4 ~21 stone 0  
fill ~28 ~4 ~22 ~53 ~4 ~22 stone 0  
fill ~28 ~4 ~23 ~53 ~4 ~23 stone 0  
fill ~28 ~4 ~24 ~53 ~4 ~24 stone 0  
fill ~28 ~4 ~25 ~28 ~0 ~25 stone 0  
fill ~28 ~4 ~42 ~41 ~4 ~42 stone 0  
fill ~28 ~4 ~43 ~41 ~4 ~43 stone 0 
setblock ~28 ~4 ~130 grass 0  
fill ~29 ~4 ~20 ~52 ~4 ~20 stone 0 
setblock ~29 ~4 ~25 grass 0  
fill ~29 ~4 ~26 ~53 ~4 ~26 stone 0 
setblock ~29 ~4 ~27 grass 0 
setblock ~29 ~4 ~129 grass 0  
fill ~29 ~4 ~130 ~38 ~4 ~130 stone 0  
fill ~30 ~4 ~25 ~53 ~4 ~25 stone 0  
fill ~30 ~4 ~27 ~52 ~4 ~27 stone 0  
fill ~30 ~4 ~28 ~30 ~4 ~29 grass 0  
fill ~30 ~4 ~129 ~37 ~4 ~129 stone 0  
fill ~31 ~4 ~19 ~51 ~4 ~19 stone 0  
fill ~31 ~4 ~28 ~51 ~4 ~28 stone 0  
fill ~31 ~4 ~29 ~52 ~4 ~29 stone 0  
fill ~31 ~4 ~30 ~52 ~4 ~30 stone 0  
fill ~31 ~4 ~40 ~43 ~4 ~40 stone 0  
fill ~31 ~4 ~41 ~42 ~4 ~41 stone 0 
setblock ~31 ~4 ~128 grass 0 
setblock ~32 ~4 ~18 grass 0  
fill ~32 ~4 ~31 ~33 ~4 ~31 grass 0  
fill ~32 ~4 ~37 ~32 ~4 ~38 grass 0  
fill ~32 ~4 ~39 ~43 ~4 ~39 stone 0 
setblock ~32 ~4 ~54 grass 0  
fill ~32 ~4 ~128 ~34 ~4 ~128 stone 0 
setblock ~32 ~4 ~145 grass 0  
fill ~33 ~4 ~16 ~50 ~4 ~16 stone 0  
fill ~33 ~4 ~17 ~49 ~4 ~17 stone 0  
fill ~33 ~4 ~18 ~48 ~4 ~18 stone 0  
fill ~33 ~4 ~32 ~52 ~4 ~32 stone 0 
setblock ~33 ~4 ~33 grass 0  
fill ~33 ~4 ~34 ~51 ~4 ~34 stone 0  
fill ~33 ~4 ~35 ~50 ~4 ~35 stone 0  
fill ~33 ~4 ~36 ~48 ~4 ~36 stone 0  
fill ~33 ~4 ~37 ~43 ~4 ~37 stone 0  
fill ~33 ~4 ~38 ~43 ~4 ~38 stone 0  
fill ~33 ~4 ~145 ~42 ~4 ~145 stone 0  
fill ~33 ~4 ~146 ~38 ~4 ~146 stone 0  
fill ~33 ~4 ~147 ~34 ~4 ~147 grass 0  
fill ~34 ~4 ~31 ~52 ~4 ~31 stone 0  
fill ~34 ~4 ~33 ~52 ~4 ~33 stone 0 
setblock ~35 ~4 ~14 grass 0  
fill ~35 ~4 ~15 ~52 ~4 ~15 stone 0 
setblock ~35 ~4 ~128 grass 0  
fill ~35 ~4 ~147 ~38 ~4 ~147 stone 0  
fill ~36 ~4 ~13 ~37 ~4 ~13 grass 0  
fill ~36 ~4 ~14 ~53 ~4 ~14 stone 0  
fill ~36 ~4 ~148 ~38 ~4 ~148 grass 0  
fill ~38 ~4 ~12 ~58 ~4 ~12 stone 0  
fill ~38 ~4 ~13 ~56 ~4 ~13 stone 0 
setblock ~39 ~4 ~10 grass 0  
fill ~39 ~4 ~11 ~91 ~4 ~11 stone 0  
fill ~39 ~4 ~146 ~42 ~4 ~146 grass 0  
fill ~39 ~4 ~147 ~40 ~4 ~147 grass 0  
fill ~40 ~4 ~10 ~90 ~4 ~10 stone 0 
setblock ~41 ~4 ~9 grass 0  
fill ~41 ~4 ~130 ~102 ~4 ~130 stone 0  
fill ~42 ~4 ~9 ~90 ~4 ~9 stone 0  
fill ~43 ~4 ~129 ~103 ~4 ~129 stone 0  
fill ~43 ~4 ~145 ~45 ~4 ~145 grass 0 
setblock ~44 ~4 ~8 grass 0 
setblock ~44 ~4 ~37 grass 0 
setblock ~45 ~4 ~7 grass 0  
fill ~45 ~4 ~8 ~89 ~4 ~8 stone 0  
fill ~45 ~4 ~125 ~45 ~4 ~126 grass 0  
fill ~45 ~4 ~127 ~78 ~4 ~127 stone 0  
fill ~45 ~4 ~128 ~81 ~4 ~128 stone 0 
setblock ~46 ~4 ~6 grass 0  
fill ~46 ~4 ~7 ~85 ~4 ~7 stone 0  
fill ~46 ~4 ~123 ~72 ~4 ~123 stone 0  
fill ~46 ~4 ~124 ~75 ~4 ~124 stone 0  
fill ~46 ~4 ~125 ~76 ~4 ~125 stone 0  
fill ~46 ~4 ~126 ~77 ~4 ~126 stone 0 
setblock ~47 ~4 ~2 grass 0  
fill ~47 ~4 ~6 ~83 ~4 ~6 stone 0  
fill ~47 ~4 ~122 ~67 ~4 ~122 stone 0  
fill ~48 ~4 ~2 ~79 ~4 ~2 stone 0 
setblock ~48 ~4 ~3 grass 0  
fill ~48 ~4 ~4 ~82 ~4 ~4 stone 0  
fill ~48 ~4 ~5 ~83 ~4 ~5 stone 0  
fill ~48 ~4 ~121 ~62 ~4 ~121 stone 0 
setblock ~48 ~4 ~145 grass 0  
fill ~49 ~4 ~0 ~49 ~4 ~1 grass 0  
fill ~49 ~4 ~3 ~80 ~4 ~3 stone 0 
setblock ~49 ~4 ~36 grass 0  
fill ~49 ~4 ~145 ~51 ~4 ~145 stone 0  
fill ~50 ~4 ~-1 ~72 ~4 ~-1 stone 0  
fill ~50 ~4 ~0 ~73 ~4 ~0 stone 0  
fill ~50 ~4 ~1 ~76 ~4 ~1 stone 0 
setblock ~51 ~4 ~35 grass 0  
fill ~52 ~4 ~-4 ~69 ~4 ~-4 stone 0  
fill ~52 ~4 ~-3 ~72 ~4 ~-3 stone 0  
fill ~52 ~4 ~-2 ~72 ~4 ~-2 stone 0 
setblock ~52 ~4 ~28 grass 0 
setblock ~52 ~4 ~34 grass 0 
setblock ~52 ~4 ~145 grass 0  
fill ~53 ~4 ~-5 ~66 ~4 ~-5 stone 0  
fill ~53 ~4 ~30 ~53 ~4 ~32 grass 0  
fill ~53 ~4 ~120 ~54 ~4 ~120 stone 0  
fill ~53 ~4 ~142 ~54 ~4 ~142 grass 0  
fill ~53 ~4 ~143 ~53 ~4 ~142 grass 0  
fill ~54 ~4 ~22 ~54 ~4 ~24 grass 0 
setblock ~55 ~4 ~120 grass 0  
fill ~56 ~4 ~-8 ~56 ~4 ~-7 grass 0  
fill ~56 ~4 ~-6 ~66 ~4 ~-6 stone 0  
fill ~56 ~4 ~120 ~61 ~4 ~120 stone 0 
setblock ~56 ~4 ~140 grass 0 
setblock ~57 ~4 ~-7 grass 0  
fill ~58 ~4 ~-7 ~65 ~4 ~-7 stone 0  
fill ~59 ~4 ~134 ~103 ~4 ~134 stone 0  
fill ~60 ~4 ~12 ~91 ~4 ~12 stone 0 
setblock ~62 ~4 ~-8 grass 0  
fill ~63 ~4 ~-8 ~64 ~4 ~-8 stone 0 
setblock ~63 ~4 ~121 grass 0  
fill ~64 ~4 ~121 ~65 ~4 ~121 stone 0  
fill ~65 ~4 ~13 ~91 ~4 ~13 stone 0 
setblock ~65 ~4 ~14 grass 0 
setblock ~66 ~4 ~-7 grass 0  
fill ~66 ~4 ~14 ~91 ~4 ~14 stone 0 
setblock ~66 ~4 ~15 grass 0  
fill ~66 ~4 ~135 ~68 ~4 ~135 grass 0  
fill ~67 ~4 ~-6 ~69 ~4 ~-6 grass 0  
fill ~67 ~4 ~-5 ~69 ~4 ~-5 grass 0  
fill ~67 ~4 ~15 ~91 ~4 ~15 stone 0  
fill ~68 ~4 ~16 ~69 ~4 ~16 grass 0 
setblock ~68 ~4 ~122 grass 0  
fill ~69 ~4 ~122 ~70 ~4 ~122 stone 0  
fill ~69 ~4 ~135 ~103 ~4 ~135 stone 0  
fill ~70 ~4 ~-4 ~71 ~4 ~-4 grass 0  
fill ~70 ~4 ~16 ~92 ~4 ~16 stone 0  
fill ~71 ~4 ~17 ~71 ~4 ~22 grass 0 
setblock ~71 ~4 ~122 grass 0  
fill ~71 ~4 ~136 ~102 ~4 ~136 stone 0  
fill ~72 ~4 ~17 ~92 ~4 ~17 stone 0  
fill ~72 ~4 ~18 ~93 ~4 ~18 stone 0  
fill ~72 ~4 ~19 ~93 ~4 ~19 stone 0  
fill ~72 ~4 ~20 ~93 ~4 ~20 stone 0  
fill ~72 ~4 ~21 ~79 ~4 ~21 stone 0  
fill ~72 ~4 ~22 ~78 ~4 ~22 stone 0 
setblock ~72 ~4 ~23 grass 0  
fill ~73 ~4 ~23 ~77 ~4 ~23 stone 0  
fill ~73 ~4 ~24 ~77 ~4 ~24 grass 0  
fill ~73 ~4 ~137 ~102 ~4 ~137 stone 0  
fill ~74 ~4 ~138 ~100 ~4 ~138 stone 0  
fill ~75 ~4 ~139 ~99 ~4 ~139 stone 0  
fill ~76 ~4 ~140 ~99 ~4 ~140 stone 0 
setblock ~78 ~4 ~23 grass 0  
fill ~78 ~4 ~141 ~98 ~4 ~141 stone 0 
setblock ~78 ~4 ~142 grass 0 
setblock ~79 ~4 ~22 grass 0  
fill ~79 ~4 ~142 ~96 ~4 ~142 stone 0  
fill ~79 ~4 ~143 ~81 ~4 ~143 grass 0  
fill ~79 ~4 ~144 ~85 ~4 ~144 grass 0 
setblock ~80 ~4 ~2 grass 0 
setblock ~80 ~4 ~21 grass 0  
fill ~81 ~4 ~3 ~82 ~4 ~3 grass 0  
fill ~81 ~4 ~21 ~94 ~4 ~21 stone 0 
setblock ~81 ~4 ~22 grass 0  
fill ~82 ~4 ~22 ~94 ~4 ~22 stone 0  
fill ~82 ~4 ~23 ~95 ~4 ~23 stone 0 
setblock ~82 ~4 ~128 grass 0  
fill ~82 ~4 ~143 ~84 ~4 ~143 stone 0  
fill ~83 ~4 ~24 ~96 ~4 ~24 stone 0  
fill ~83 ~4 ~25 ~97 ~4 ~25 stone 0  
fill ~83 ~4 ~26 ~97 ~4 ~26 stone 0 
setblock ~83 ~4 ~145 grass 0 
setblock ~84 ~4 ~6 grass 0  
fill ~84 ~4 ~27 ~98 ~4 ~27 stone 0  
fill ~84 ~4 ~28 ~100 ~4 ~28 stone 0  
fill ~85 ~4 ~29 ~102 ~4 ~29 stone 0  
fill ~85 ~4 ~30 ~103 ~4 ~30 stone 0  
fill ~85 ~4 ~128 ~88 ~4 ~128 stone 0  
fill ~85 ~4 ~143 ~90 ~4 ~143 grass 0  
fill ~86 ~4 ~7 ~88 ~4 ~7 grass 0  
fill ~86 ~4 ~31 ~103 ~4 ~31 stone 0  
fill ~87 ~4 ~32 ~103 ~4 ~32 stone 0  
fill ~87 ~4 ~33 ~103 ~4 ~33 stone 0  
fill ~87 ~4 ~74 ~104 ~4 ~74 stone 0  
fill ~87 ~4 ~75 ~105 ~4 ~75 stone 0  
fill ~87 ~4 ~76 ~105 ~4 ~76 stone 0  
fill ~87 ~4 ~79 ~104 ~4 ~79 stone 0  
fill ~87 ~4 ~80 ~104 ~4 ~80 stone 0  
fill ~87 ~4 ~81 ~104 ~4 ~81 stone 0  
fill ~87 ~4 ~82 ~104 ~4 ~82 stone 0  
fill ~88 ~4 ~34 ~104 ~4 ~34 stone 0  
fill ~88 ~4 ~70 ~101 ~4 ~70 stone 0  
fill ~88 ~4 ~71 ~103 ~4 ~71 stone 0  
fill ~88 ~4 ~72 ~103 ~4 ~72 stone 0  
fill ~88 ~4 ~73 ~104 ~4 ~73 stone 0  
fill ~88 ~4 ~77 ~104 ~4 ~77 stone 0  
fill ~88 ~4 ~78 ~104 ~4 ~78 stone 0  
fill ~88 ~4 ~83 ~105 ~4 ~83 stone 0  
fill ~88 ~4 ~84 ~105 ~4 ~84 stone 0  
fill ~88 ~4 ~85 ~105 ~4 ~85 stone 0  
fill ~89 ~4 ~35 ~104 ~4 ~35 stone 0 
setblock ~89 ~4 ~67 grass 0  
fill ~89 ~4 ~68 ~101 ~4 ~68 stone 0  
fill ~89 ~4 ~69 ~101 ~4 ~69 stone 0  
fill ~89 ~4 ~86 ~105 ~4 ~86 stone 0 
setblock ~90 ~4 ~8 grass 0  
fill ~90 ~4 ~36 ~103 ~4 ~36 stone 0  
fill ~90 ~4 ~37 ~103 ~4 ~37 stone 0 
setblock ~90 ~4 ~38 grass 0 
setblock ~90 ~4 ~65 grass 0  
fill ~90 ~4 ~66 ~102 ~4 ~66 stone 0  
fill ~90 ~4 ~67 ~102 ~4 ~67 stone 0  
fill ~90 ~4 ~87 ~105 ~4 ~87 stone 0 
setblock ~91 ~4 ~10 grass 0  
fill ~91 ~4 ~38 ~103 ~4 ~38 stone 0 
setblock ~91 ~4 ~39 grass 0 
setblock ~91 ~4 ~57 grass 0  
fill ~91 ~4 ~58 ~103 ~4 ~58 stone 0  
fill ~91 ~4 ~59 ~103 ~4 ~59 stone 0  
fill ~91 ~4 ~60 ~103 ~4 ~60 stone 0  
fill ~91 ~4 ~61 ~102 ~4 ~61 stone 0  
fill ~91 ~4 ~62 ~103 ~4 ~62 stone 0  
fill ~91 ~4 ~63 ~103 ~4 ~63 stone 0  
fill ~91 ~4 ~64 ~103 ~4 ~64 stone 0  
fill ~91 ~4 ~65 ~103 ~4 ~65 stone 0  
fill ~91 ~4 ~88 ~105 ~4 ~88 stone 0  
fill ~91 ~4 ~124 ~104 ~4 ~124 stone 0  
fill ~91 ~4 ~125 ~104 ~4 ~125 stone 0  
fill ~91 ~4 ~126 ~104 ~4 ~126 stone 0  
fill ~91 ~4 ~143 ~95 ~4 ~143 stone 0  
fill ~92 ~4 ~39 ~103 ~4 ~39 stone 0  
fill ~92 ~4 ~40 ~104 ~4 ~40 stone 0  
fill ~92 ~4 ~41 ~104 ~4 ~41 stone 0  
fill ~92 ~4 ~42 ~104 ~4 ~42 stone 0  
fill ~92 ~4 ~43 ~104 ~4 ~43 stone 0  
fill ~92 ~4 ~44 ~104 ~4 ~44 stone 0  
fill ~92 ~4 ~45 ~103 ~4 ~45 stone 0  
fill ~92 ~4 ~46 ~104 ~4 ~46 stone 0  
fill ~92 ~4 ~47 ~104 ~4 ~47 stone 0 
setblock ~92 ~4 ~48 grass 0  
fill ~92 ~4 ~53 ~104 ~4 ~53 stone 0  
fill ~92 ~4 ~54 ~104 ~4 ~54 stone 0  
fill ~92 ~4 ~55 ~104 ~4 ~55 stone 0  
fill ~92 ~4 ~56 ~104 ~4 ~56 stone 0  
fill ~92 ~4 ~57 ~104 ~4 ~57 stone 0  
fill ~92 ~4 ~89 ~105 ~4 ~89 stone 0  
fill ~92 ~4 ~110 ~105 ~4 ~110 stone 0  
fill ~92 ~4 ~111 ~104 ~4 ~111 stone 0  
fill ~92 ~4 ~112 ~104 ~4 ~112 stone 0  
fill ~92 ~4 ~118 ~104 ~4 ~118 stone 0  
fill ~92 ~4 ~119 ~104 ~4 ~119 stone 0  
fill ~92 ~4 ~120 ~104 ~4 ~120 stone 0  
fill ~92 ~4 ~121 ~104 ~4 ~121 stone 0  
fill ~92 ~4 ~122 ~104 ~4 ~122 stone 0  
fill ~92 ~4 ~123 ~104 ~4 ~123 stone 0  
fill ~92 ~4 ~127 ~103 ~4 ~127 stone 0  
fill ~92 ~4 ~128 ~103 ~4 ~128 stone 0  
fill ~93 ~4 ~48 ~103 ~4 ~48 stone 0  
fill ~93 ~4 ~49 ~104 ~4 ~49 stone 0  
fill ~93 ~4 ~50 ~104 ~4 ~50 stone 0  
fill ~93 ~4 ~51 ~104 ~4 ~51 stone 0  
fill ~93 ~4 ~52 ~104 ~4 ~52 stone 0  
fill ~93 ~4 ~108 ~106 ~4 ~108 stone 0  
fill ~93 ~4 ~109 ~106 ~4 ~109 stone 0  
fill ~93 ~4 ~113 ~103 ~4 ~113 stone 0  
fill ~93 ~4 ~114 ~103 ~4 ~114 stone 0 
setblock ~93 ~4 ~115 grass 0  
fill ~93 ~4 ~116 ~104 ~4 ~116 stone 0  
fill ~93 ~4 ~117 ~104 ~4 ~117 stone 0  
fill ~94 ~4 ~90 ~105 ~4 ~90 stone 0  
fill ~94 ~4 ~91 ~106 ~4 ~91 stone 0  
fill ~94 ~4 ~92 ~107 ~4 ~92 stone 0 
setblock ~94 ~4 ~106 grass 0  
fill ~94 ~4 ~107 ~107 ~4 ~107 stone 0  
fill ~94 ~4 ~115 ~103 ~4 ~115 stone 0  
fill ~95 ~4 ~93 ~107 ~4 ~93 stone 0  
fill ~95 ~4 ~94 ~107 ~4 ~94 stone 0 
setblock ~95 ~4 ~95 grass 0  
fill ~95 ~4 ~98 ~109 ~4 ~98 stone 0  
fill ~95 ~4 ~102 ~109 ~4 ~102 stone 0  
fill ~95 ~4 ~106 ~106 ~4 ~106 stone 0  
fill ~96 ~4 ~95 ~108 ~4 ~95 stone 0  
fill ~96 ~4 ~96 ~108 ~4 ~96 stone 0  
fill ~96 ~4 ~97 ~109 ~4 ~97 stone 0  
fill ~96 ~4 ~99 ~109 ~4 ~99 stone 0  
fill ~96 ~4 ~100 ~109 ~4 ~100 stone 0  
fill ~96 ~4 ~101 ~109 ~4 ~101 stone 0  
fill ~96 ~4 ~103 ~109 ~4 ~103 stone 0  
fill ~96 ~4 ~104 ~109 ~4 ~104 stone 0  
fill ~96 ~4 ~105 ~108 ~4 ~105 stone 0 
setblock ~97 ~4 ~142 grass 0 
setblock ~100 ~4 ~139 grass 0 
setblock ~102 ~4 ~70 grass 0 
setblock ~103 ~4 ~61 grass 0  
fill ~103 ~4 ~130 ~103 ~4 ~132 grass 0 
setblock ~103 ~4 ~136 grass 0 
setblock ~104 ~4 ~33 grass 0 
setblock ~104 ~4 ~45 grass 0 
setblock ~104 ~4 ~48 grass 0 
setblock ~104 ~4 ~58 grass 0 
setblock ~104 ~4 ~115 grass 0  
fill ~104 ~4 ~127 ~104 ~4 ~128 grass 0 
setblock ~105 ~4 ~77 grass 0  
fill ~105 ~4 ~81 ~105 ~4 ~82 grass 0 
setblock ~105 ~4 ~122 grass 0  
fill ~106 ~4 ~86 ~106 ~4 ~90 grass 0  
fill ~106 ~4 ~110 ~106 ~4 ~111 grass 0 
setblock ~107 ~4 ~91 grass 0 
setblock ~107 ~4 ~106 grass 0  
fill ~107 ~4 ~108 ~107 ~4 ~109 grass 0  
fill ~108 ~4 ~93 ~108 ~4 ~94 grass 0  
fill ~108 ~4 ~106 ~108 ~5 ~106 stone 0 
setblock ~108 ~4 ~107 grass 0  
fill ~109 ~4 ~105 ~109 ~4 ~106 grass 0  
fill ~-7 ~5 ~107 ~-5 ~5 ~107 grass 0  
fill ~-7 ~5 ~108 ~-6 ~5 ~108 grass 0  
fill ~-7 ~5 ~109 ~-7 ~5 ~111 grass 0  
fill ~-6 ~5 ~102 ~-3 ~5 ~102 grass 0  
fill ~-6 ~5 ~103 ~-6 ~5 ~102 grass 0  
fill ~-6 ~5 ~105 ~-6 ~5 ~108 grass 0  
fill ~-6 ~5 ~109 ~12 ~5 ~109 stone 0  
fill ~-6 ~5 ~110 ~12 ~5 ~110 stone 0  
fill ~-6 ~5 ~111 ~13 ~5 ~111 stone 0  
fill ~-6 ~5 ~112 ~13 ~5 ~112 stone 0  
fill ~-6 ~5 ~113 ~-6 ~5 ~114 grass 0  
fill ~-5 ~5 ~103 ~11 ~5 ~103 stone 0  
fill ~-5 ~5 ~104 ~11 ~5 ~104 stone 0  
fill ~-5 ~5 ~105 ~11 ~5 ~105 stone 0  
fill ~-5 ~5 ~106 ~-3 ~5 ~106 grass 0  
fill ~-5 ~5 ~108 ~-3 ~5 ~108 stone 0  
fill ~-5 ~5 ~113 ~13 ~5 ~113 stone 0  
fill ~-5 ~5 ~114 ~13 ~5 ~114 stone 0   

KittysCommands:  
setblock ~-5 ~5 ~115 grass 0  
fill ~-4 ~5 ~115 ~14 ~5 ~115 stone 0  
fill ~-4 ~5 ~116 ~-4 ~5 ~118 grass 0  
fill ~-3 ~5 ~101 ~-2 ~5 ~101 grass 0 
setblock ~-3 ~5 ~107 grass 0  
fill ~-3 ~5 ~116 ~14 ~5 ~116 stone 0  
fill ~-3 ~5 ~117 ~15 ~5 ~117 stone 0  
fill ~-3 ~5 ~118 ~-3 ~5 ~119 grass 0 
setblock ~-2 ~5 ~100 grass 0  
fill ~-2 ~5 ~102 ~11 ~5 ~102 stone 0  
fill ~-2 ~5 ~106 ~11 ~5 ~106 stone 0  
fill ~-2 ~5 ~107 ~11 ~5 ~107 stone 0 
setblock ~-2 ~5 ~108 grass 0  
fill ~-2 ~5 ~118 ~15 ~5 ~118 stone 0  
fill ~-2 ~5 ~119 ~-2 ~5 ~121 grass 0 
setblock ~-1 ~5 ~89 grass 0  
fill ~-1 ~5 ~90 ~12 ~5 ~90 stone 0  
fill ~-1 ~5 ~91 ~11 ~5 ~91 stone 0  
fill ~-1 ~5 ~92 ~11 ~5 ~92 stone 0  
fill ~-1 ~5 ~93 ~11 ~5 ~93 stone 0  
fill ~-1 ~5 ~94 ~10 ~5 ~94 stone 0  
fill ~-1 ~5 ~95 ~9 ~5 ~95 stone 0 
setblock ~-1 ~5 ~96 grass 0  
fill ~-1 ~5 ~97 ~10 ~5 ~97 stone 0  
fill ~-1 ~5 ~98 ~10 ~5 ~98 stone 0  
fill ~-1 ~5 ~99 ~10 ~5 ~99 stone 0  
fill ~-1 ~5 ~100 ~10 ~5 ~100 stone 0  
fill ~-1 ~5 ~101 ~11 ~5 ~101 stone 0  
fill ~-1 ~5 ~108 ~12 ~5 ~108 stone 0  
fill ~-1 ~5 ~119 ~15 ~5 ~119 stone 0  
fill ~-1 ~5 ~120 ~16 ~5 ~120 stone 0  
fill ~-1 ~5 ~121 ~-1 ~5 ~122 grass 0 
setblock ~0 ~5 ~76 grass 0  
fill ~0 ~5 ~77 ~11 ~5 ~77 stone 0  
fill ~0 ~5 ~78 ~11 ~5 ~78 stone 0  
fill ~0 ~5 ~79 ~11 ~5 ~79 stone 0  
fill ~0 ~5 ~85 ~11 ~5 ~85 stone 0  
fill ~0 ~5 ~86 ~12 ~5 ~86 stone 0  
fill ~0 ~5 ~87 ~12 ~5 ~87 stone 0  
fill ~0 ~5 ~88 ~12 ~5 ~88 stone 0  
fill ~0 ~5 ~89 ~12 ~5 ~89 stone 0  
fill ~0 ~5 ~96 ~9 ~5 ~96 stone 0  
fill ~0 ~5 ~121 ~17 ~5 ~121 stone 0 
setblock ~0 ~5 ~122 grass 0  
fill ~0 ~5 ~123 ~24 ~5 ~123 stone 0  
fill ~0 ~5 ~124 ~26 ~5 ~124 stone 0  
fill ~0 ~5 ~125 ~26 ~5 ~125 stone 0 
setblock ~0 ~5 ~126 grass 0  
fill ~1 ~5 ~72 ~14 ~5 ~72 stone 0 
setblock ~1 ~5 ~75 grass 0  
fill ~1 ~5 ~80 ~11 ~5 ~80 stone 0  
fill ~1 ~5 ~81 ~10 ~5 ~81 stone 0  
fill ~1 ~5 ~82 ~10 ~5 ~82 stone 0  
fill ~1 ~5 ~83 ~10 ~5 ~83 stone 0  
fill ~1 ~5 ~84 ~11 ~5 ~84 stone 0  
fill ~1 ~5 ~122 ~22 ~5 ~122 stone 0  
fill ~1 ~5 ~126 ~27 ~5 ~126 stone 0  
fill ~1 ~5 ~127 ~27 ~5 ~127 stone 0  
fill ~1 ~5 ~128 ~1 ~5 ~129 grass 0  
fill ~2 ~5 ~68 ~17 ~5 ~68 stone 0  
fill ~2 ~5 ~69 ~17 ~5 ~69 stone 0  
fill ~2 ~5 ~70 ~16 ~5 ~70 stone 0  
fill ~2 ~5 ~71 ~14 ~5 ~71 stone 0  
fill ~2 ~5 ~73 ~14 ~5 ~73 stone 0  
fill ~2 ~5 ~74 ~13 ~5 ~74 stone 0  
fill ~2 ~5 ~75 ~12 ~5 ~75 stone 0  
fill ~2 ~5 ~76 ~11 ~5 ~76 stone 0  
fill ~2 ~5 ~128 ~27 ~5 ~128 stone 0  
fill ~2 ~5 ~129 ~27 ~5 ~129 stone 0  
fill ~2 ~5 ~130 ~3 ~5 ~130 grass 0  
fill ~2 ~5 ~131 ~5 ~5 ~131 grass 0  
fill ~3 ~5 ~67 ~17 ~5 ~67 stone 0  
fill ~4 ~5 ~66 ~18 ~5 ~66 stone 0  
fill ~4 ~5 ~130 ~27 ~5 ~130 stone 0  
fill ~4 ~5 ~132 ~6 ~5 ~132 grass 0 
setblock ~6 ~5 ~64 grass 0  
fill ~6 ~5 ~65 ~18 ~5 ~65 stone 0  
fill ~6 ~5 ~131 ~26 ~5 ~131 stone 0  
fill ~6 ~5 ~134 ~7 ~5 ~134 grass 0  
fill ~6 ~5 ~135 ~7 ~5 ~135 grass 0  
fill ~7 ~5 ~62 ~19 ~5 ~62 stone 0  
fill ~7 ~5 ~63 ~19 ~5 ~63 stone 0  
fill ~7 ~5 ~64 ~19 ~5 ~64 stone 0  
fill ~7 ~5 ~132 ~101 ~5 ~132 stone 0  
fill ~7 ~5 ~133 ~101 ~5 ~133 stone 0  
fill ~7 ~5 ~136 ~8 ~5 ~136 grass 0 
setblock ~8 ~5 ~56 grass 0  
fill ~8 ~5 ~58 ~22 ~5 ~58 stone 0  
fill ~8 ~5 ~59 ~21 ~5 ~59 stone 0  
fill ~8 ~5 ~60 ~20 ~5 ~60 stone 0  
fill ~8 ~5 ~61 ~19 ~5 ~61 stone 0  
fill ~8 ~5 ~134 ~57 ~5 ~134 stone 0  
fill ~8 ~5 ~135 ~57 ~5 ~135 stone 0  
fill ~8 ~5 ~137 ~10 ~5 ~137 grass 0 
setblock ~9 ~5 ~54 grass 0  
fill ~9 ~5 ~55 ~9 ~0 ~55 stone 0  
fill ~9 ~5 ~56 ~9 ~6 ~56 stone 0  
fill ~9 ~5 ~57 ~23 ~5 ~57 stone 0  
fill ~9 ~5 ~136 ~57 ~5 ~136 stone 0  
fill ~9 ~5 ~138 ~11 ~5 ~138 grass 0 
setblock ~10 ~5 ~53 grass 0  
fill ~10 ~5 ~54 ~31 ~5 ~54 stone 0 
setblock ~10 ~5 ~55 grass 0 
setblock ~10 ~5 ~96 grass 0  
fill ~11 ~5 ~53 ~32 ~5 ~53 stone 0  
fill ~11 ~5 ~55 ~31 ~5 ~55 stone 0  
fill ~11 ~5 ~56 ~30 ~5 ~56 stone 0  
fill ~11 ~5 ~137 ~56 ~5 ~137 stone 0 
setblock ~11 ~5 ~139 grass 0 
setblock ~12 ~5 ~76 grass 0 
setblock ~12 ~5 ~85 grass 0 
