fill ~50~0~0 ~89~0~0 minecraft:grass
fill ~52~0~1 ~89~0~1 minecraft:grass
fill ~53~0~2 ~89~0~9 minecraft:grass
fill ~43~0~3 ~52~0~9 minecraft:grass
setblock ~61~1~3 minecraft:tallgrass 0
setblock ~67~1~3 minecraft:red_flower 3
fill ~68~1~3 ~69~1~3 minecraft:tallgrass 0
fill ~83~1~3 ~84~1~3 minecraft:tallgrass 0
fill ~87~1~3 ~87~1~6 minecraft:tallgrass 0
fill ~89~1~3 ~89~1~4 minecraft:tallgrass 0
fill ~90~0~3 ~90~0~9 minecraft:grass
setblock ~44~1~4 minecraft:tallgrass 0
fill ~52~1~4 ~53~1~4 minecraft:tallgrass 0
fill ~57~1~4 ~59~1~4 minecraft:tallgrass 0
fill ~62~1~4 ~62~1~6 minecraft:tallgrass 0
setblock ~63~1~4 minecraft:red_flower 0
setblock ~78~1~4 minecraft:tallgrass 0
fill ~81~1~4 ~81~1~5 minecraft:tallgrass 0
fill ~88~1~4 ~88~1~7 minecraft:tallgrass 0
fill ~91~0~4 ~91~0~9 minecraft:grass
setblock ~45~1~5 minecraft:tallgrass 0
fill ~47~1~5 ~49~1~6 minecraft:tallgrass 0
setblock ~51~1~5 minecraft:yellow_flower
fill ~54~1~5 ~55~1~6 minecraft:tallgrass 0
fill ~58~1~5 ~60~1~5 minecraft:tallgrass 0
setblock ~61~1~5 minecraft:double_plant 2
setblock ~65~1~5 minecraft:tallgrass 0
fill ~67~1~5 ~72~1~5 minecraft:tallgrass 0
fill ~74~1~5 ~74~1~6 minecraft:tallgrass 0
fill ~76~1~5 ~76~1~8 minecraft:tallgrass 0
setblock ~78~1~5 minecraft:double_plant 2
setblock ~79~1~5 minecraft:yellow_flower
fill ~82~1~5 ~86~1~5 minecraft:tallgrass 0
setblock ~89~1~5 minecraft:red_flower 3
setblock ~91~1~5 minecraft:double_plant 2
fill ~92~0~5 ~92~0~9 minecraft:grass
fill ~92~1~5 ~92~1~6 minecraft:tallgrass 0
setblock ~46~1~6 minecraft:red_flower 0
fill ~51~1~6 ~51~1~7 minecraft:tallgrass 0
fill ~52~1~6 ~52~1~7 minecraft:double_plant 2
setblock ~53~1~6 minecraft:tallgrass 0
fill ~58~1~6 ~58~1~7 minecraft:double_plant 2
setblock ~59~1~6 minecraft:tallgrass 0
fill ~60~1~6 ~60~1~7 minecraft:double_plant 2
fill ~61~1~6 ~61~1~9 minecraft:tallgrass 0
fill ~63~1~6 ~64~1~6 minecraft:tallgrass 0
setblock ~65~1~6 minecraft:double_plant 2
fill ~66~1~6 ~71~1~6 minecraft:tallgrass 0
setblock ~72~1~6 minecraft:double_plant 2
fill ~73~1~6 ~73~1~7 minecraft:tallgrass 0
setblock ~75~1~6 minecraft:tallgrass 0
setblock ~77~1~6 minecraft:double_plant 2
fill ~78~1~6 ~79~1~6 minecraft:tallgrass 0
fill ~80~1~6 ~82~1~6 minecraft:double_plant 2
fill ~83~1~6 ~83~1~8 minecraft:tallgrass 0
setblock ~84~1~6 minecraft:yellow_flower
fill ~85~1~6 ~86~1~6 minecraft:tallgrass 0
setblock ~89~1~6 minecraft:double_plant 2
setblock ~90~1~6 minecraft:tallgrass 0
fill ~93~0~6 ~93~0~9 minecraft:grass
setblock ~93~1~6 minecraft:tallgrass 0
setblock ~43~1~7 minecraft:tallgrass 0
fill ~44~1~7 ~44~1~9 minecraft:double_plant 2
fill ~46~1~7 ~47~1~7 minecraft:double_plant 2
setblock ~48~1~7 minecraft:yellow_flower
fill ~49~1~7 ~50~1~7 minecraft:double_plant 2
fill ~53~1~7 ~54~1~7 minecraft:double_plant 2
fill ~55~1~7 ~55~1~9 minecraft:tallgrass 0
fill ~56~1~7 ~57~1~7 minecraft:double_plant 2
setblock ~59~1~7 minecraft:double_plant 2
setblock ~62~1~7 minecraft:double_plant 2
fill ~63~1~7 ~63~1~8 minecraft:tallgrass 0
fill ~66~1~7 ~66~1~9 minecraft:tallgrass 0
setblock ~67~1~7 minecraft:red_flower 0
fill ~68~1~7 ~69~1~7 minecraft:tallgrass 0
fill ~70~1~7 ~71~1~7 minecraft:double_plant 2
fill ~72~1~7 ~72~1~8 minecraft:tallgrass 0
fill ~74~1~7 ~75~1~7 minecraft:double_plant 2
fill ~77~1~7 ~77~1~9 minecraft:tallgrass 0
setblock ~78~1~7 minecraft:double_plant 2
fill ~79~1~7 ~81~1~7 minecraft:tallgrass 0
fill ~82~1~7 ~82~1~8 minecraft:double_plant 2
fill ~84~1~7 ~85~1~7 minecraft:double_plant 2
setblock ~86~1~7 minecraft:yellow_flower
setblock ~87~1~7 minecraft:double_plant 2
setblock ~89~1~7 minecraft:tallgrass 0
fill ~91~1~7 ~92~1~7 minecraft:double_plant 2
setblock ~93~1~7 minecraft:yellow_flower
setblock ~43~1~8 minecraft:double_plant 2
setblock ~47~1~8 minecraft:yellow_flower
fill ~48~1~8 ~49~1~8 minecraft:double_plant 2
setblock ~50~1~8 minecraft:red_flower 0
fill ~52~1~8 ~53~1~9 minecraft:tallgrass 0
setblock ~54~1~8 minecraft:double_plant 2
fill ~56~1~8 ~57~1~8 minecraft:tallgrass 0
setblock ~58~1~8 minecraft:yellow_flower
fill ~59~1~8 ~60~1~9 minecraft:tallgrass 0
fill ~62~1~8 ~62~1~9 minecraft:tallgrass 0
setblock ~65~1~8 minecraft:tallgrass 0
fill ~67~1~8 ~68~1~8 minecraft:tallgrass 0
fill ~70~1~8 ~71~1~8 minecraft:tallgrass 0
setblock ~73~1~8 minecraft:red_flower 0
fill ~74~1~8 ~75~1~8 minecraft:tallgrass 0
fill ~78~1~8 ~79~1~9 minecraft:tallgrass 0
fill ~81~1~8 ~81~1~9 minecraft:tallgrass 0
setblock ~84~1~8 minecraft:tallgrass 0
setblock ~85~1~8 minecraft:double_plant 2
fill ~86~1~8 ~87~1~8 minecraft:tallgrass 0
setblock ~88~1~8 minecraft:red_flower 3
fill ~90~1~8 ~91~1~8 minecraft:tallgrass 0
fill ~92~1~8 ~94~1~8 minecraft:double_plant 2
fill ~94~0~8 ~94~0~75 minecraft:grass
fill ~43~1~9 ~43~1~10 minecraft:red_flower 0
fill ~45~1~9 ~46~1~9 minecraft:tallgrass 0
fill ~47~1~9 ~48~1~9 minecraft:double_plant 2
fill ~49~1~9 ~50~1~9 minecraft:tallgrass 0
setblock ~54~1~9 minecraft:tallgrass 0
setblock ~56~1~9 minecraft:double_plant 2
setblock ~57~1~9 minecraft:tallgrass 0
setblock ~58~1~9 minecraft:red_flower 8
setblock ~69~1~9 minecraft:tallgrass 0
setblock ~70~1~9 minecraft:yellow_flower
setblock ~71~1~9 minecraft:tallgrass 0
setblock ~75~1~9 minecraft:tallgrass 0
setblock ~76~1~9 minecraft:red_flower 9
setblock ~82~1~9 minecraft:tallgrass 0
setblock ~83~1~9 minecraft:red_flower 3
setblock ~85~1~9 minecraft:tallgrass 0
setblock ~86~1~9 minecraft:yellow_flower
fill ~87~1~9 ~88~1~9 minecraft:tallgrass 0
setblock ~91~1~9 minecraft:red_flower 8
setblock ~92~1~9 minecraft:tallgrass 0
setblock ~94~1~9 minecraft:tallgrass 0
fill ~95~0~9 ~95~0~75 minecraft:grass
fill ~43~0~10 ~43~0~27 minecraft:grass
fill ~44~0~10 ~93~0~14 minecraft:dirt 0
fill ~44~1~10 ~44~19~10 minecraft:quartz_block 2
fill ~44~20~10 ~44~20~14 minecraft:smooth_quartz_stairs 0
fill ~45~1~10 ~48~1~10 minecraft:deepslate_tile_stairs 2
fill ~45~2~10 ~48~2~10 minecraft:iron_bars
fill ~45~3~10 ~45~4~10 minecraft:torch 1
setblock ~45~5~10 minecraft:lantern 1
setblock ~45~6~10 minecraft:deepslate_tile_stairs 2
fill ~45~7~10 ~93~7~10 minecraft:quartz_block 2
fill ~45~8~10 ~48~8~10 minecraft:quartz_stairs 2
fill ~45~9~10 ~48~9~10 minecraft:quartz_stairs 6
fill ~45~10~10 ~48~10~10 minecraft:quartz_stairs 2
fill ~45~11~10 ~48~11~10 minecraft:quartz_stairs 6
fill ~45~12~10 ~48~12~10 minecraft:quartz_stairs 2
fill ~45~13~10 ~48~13~10 minecraft:quartz_stairs 6
fill ~45~14~10 ~48~14~10 minecraft:quartz_stairs 2
fill ~45~15~10 ~48~15~10 minecraft:quartz_stairs 6
fill ~45~16~10 ~48~16~10 minecraft:polished_blackstone_brick_wall 0
setblock ~45~18~10 minecraft:torch 1
fill ~45~19~10 ~48~19~10 minecraft:quartz_block 2
fill ~45~20~10 ~49~20~10 minecraft:smooth_quartz_stairs 2
fill ~46~6~10 ~47~6~10 minecraft:deepslate_tile_stairs 6
fill ~48~3~10 ~48~4~10 minecraft:torch 2
setblock ~48~5~10 minecraft:lantern 1
setblock ~48~6~10 minecraft:deepslate_tile_stairs 2
setblock ~48~18~10 minecraft:torch 2
fill ~49~1~10 ~49~6~11 minecraft:quartz_block 2
fill ~49~8~10 ~49~19~10 minecraft:quartz_block 2
fill ~50~1~10 ~57~1~10 minecraft:deepslate_tile_stairs 2
fill ~50~2~10 ~57~2~10 minecraft:iron_bars
fill ~50~6~10 ~51~6~10 minecraft:deepslate_tile_stairs 6
fill ~50~8~10 ~57~8~10 minecraft:quartz_stairs 2
setblock ~52~4~10 minecraft:wall_banner 2
setblock ~52~5~10 minecraft:lantern 1
setblock ~52~6~10 minecraft:deepslate_tile_stairs 2
fill ~53~6~10 ~54~6~10 minecraft:deepslate_tile_stairs 6
setblock ~55~4~10 minecraft:wall_banner 2
setblock ~55~5~10 minecraft:lantern 1
setblock ~55~6~10 minecraft:deepslate_tile_stairs 2
fill ~56~6~10 ~57~6~10 minecraft:deepslate_tile_stairs 6
setblock ~57~5~10 minecraft:torch 2
fill ~58~1~10 ~58~6~11 minecraft:quartz_block 2
setblock ~58~8~10 minecraft:quartz_block 2
fill ~59~1~10 ~66~1~10 minecraft:deepslate_tile_stairs 2
fill ~59~2~10 ~66~2~10 minecraft:iron_bars
setblock ~59~5~10 minecraft:torch 1
fill ~59~6~10 ~60~6~10 minecraft:deepslate_tile_stairs 6
fill ~59~8~10 ~66~8~10 minecraft:quartz_stairs 2
setblock ~61~4~10 minecraft:wall_banner 2
setblock ~61~5~10 minecraft:lantern 1
setblock ~61~6~10 minecraft:deepslate_tile_stairs 2
fill ~62~6~10 ~63~6~10 minecraft:deepslate_tile_stairs 6
setblock ~64~4~10 minecraft:wall_banner 2
setblock ~64~5~10 minecraft:lantern 1
setblock ~64~6~10 minecraft:deepslate_tile_stairs 2
fill ~65~6~10 ~66~6~10 minecraft:deepslate_tile_stairs 6
setblock ~66~5~10 minecraft:torch 2
fill ~67~1~10 ~67~6~11 minecraft:quartz_block 2
setblock ~67~8~10 minecraft:quartz_block 2
fill ~68~1~10 ~75~1~10 minecraft:deepslate_tile_stairs 2
fill ~68~2~10 ~75~2~10 minecraft:iron_bars
setblock ~68~5~10 minecraft:torch 1
fill ~68~6~10 ~69~6~10 minecraft:deepslate_tile_stairs 6
fill ~68~8~10 ~75~8~10 minecraft:quartz_stairs 2
setblock ~70~4~10 minecraft:wall_banner 2
setblock ~70~5~10 minecraft:lantern 1
setblock ~70~6~10 minecraft:deepslate_tile_stairs 2
fill ~71~6~10 ~72~6~10 minecraft:deepslate_tile_stairs 6
setblock ~73~4~10 minecraft:wall_banner 2
setblock ~73~5~10 minecraft:lantern 1
setblock ~73~6~10 minecraft:deepslate_tile_stairs 2
fill ~74~6~10 ~75~6~10 minecraft:deepslate_tile_stairs 6
setblock ~75~5~10 minecraft:torch 2
fill ~76~1~10 ~76~6~11 minecraft:quartz_block 2
setblock ~76~8~10 minecraft:quartz_block 2
fill ~77~1~10 ~84~1~10 minecraft:deepslate_tile_stairs 2
fill ~77~2~10 ~84~2~10 minecraft:iron_bars
setblock ~77~5~10 minecraft:torch 1
fill ~77~6~10 ~78~6~10 minecraft:deepslate_tile_stairs 6
fill ~77~8~10 ~84~8~10 minecraft:quartz_stairs 2
setblock ~79~4~10 minecraft:wall_banner 2
setblock ~79~5~10 minecraft:lantern 1
setblock ~79~6~10 minecraft:deepslate_tile_stairs 2
fill ~80~6~10 ~81~6~10 minecraft:deepslate_tile_stairs 6
setblock ~82~4~10 minecraft:wall_banner 2
setblock ~82~5~10 minecraft:lantern 1
setblock ~82~6~10 minecraft:deepslate_tile_stairs 2
fill ~83~6~10 ~84~6~10 minecraft:deepslate_tile_stairs 6
setblock ~84~5~10 minecraft:torch 2
fill ~85~1~10 ~85~6~11 minecraft:quartz_block 2
setblock ~85~8~10 minecraft:quartz_block 2
fill ~86~1~10 ~87~1~10 minecraft:deepslate_tile_stairs 2
fill ~86~2~10 ~87~2~10 minecraft:iron_bars
setblock ~86~5~10 minecraft:torch 1
fill ~86~6~10 ~87~6~10 minecraft:deepslate_tile_stairs 6
fill ~86~8~10 ~87~8~10 minecraft:quartz_stairs 2
fill ~88~1~10 ~88~6~11 minecraft:quartz_block 2
fill ~88~8~10 ~88~19~10 minecraft:quartz_block 2
fill ~88~20~10 ~88~20~13 minecraft:smooth_quartz_stairs 0
fill ~89~1~10 ~92~1~10 minecraft:deepslate_tile_stairs 2
fill ~89~2~10 ~92~2~10 minecraft:iron_bars
fill ~89~3~10 ~89~4~10 minecraft:torch 1
setblock ~89~5~10 minecraft:lantern 1
setblock ~89~6~10 minecraft:deepslate_tile_stairs 2
fill ~89~8~10 ~92~8~10 minecraft:quartz_stairs 2
fill ~89~9~10 ~92~9~10 minecraft:quartz_stairs 6
fill ~89~10~10 ~92~10~10 minecraft:quartz_stairs 2
fill ~89~11~10 ~92~11~10 minecraft:quartz_stairs 6
fill ~89~12~10 ~92~12~10 minecraft:quartz_stairs 2
fill ~89~13~10 ~92~13~10 minecraft:quartz_stairs 6
fill ~89~14~10 ~92~14~10 minecraft:quartz_stairs 2
fill ~89~15~10 ~92~15~10 minecraft:quartz_stairs 6
fill ~89~16~10 ~92~16~10 minecraft:polished_blackstone_brick_wall 0
setblock ~89~18~10 minecraft:torch 1
fill ~89~19~10 ~92~19~10 minecraft:quartz_block 2
fill ~89~20~10 ~93~20~10 minecraft:smooth_quartz_stairs 2
fill ~90~6~10 ~91~6~10 minecraft:deepslate_tile_stairs 6
fill ~92~3~10 ~92~4~10 minecraft:torch 2
setblock ~92~5~10 minecraft:lantern 1
setblock ~92~6~10 minecraft:deepslate_tile_stairs 2
setblock ~92~18~10 minecraft:torch 2
fill ~93~1~10 ~93~6~10 minecraft:quartz_block 2
fill ~93~8~10 ~93~19~10 minecraft:quartz_block 2
fill ~94~1~10 ~95~1~10 minecraft:double_plant 2
fill ~96~0~10 ~96~0~75 minecraft:grass
setblock ~96~1~10 minecraft:tallgrass 0
setblock ~43~1~11 minecraft:tallgrass 0
fill ~44~1~11 ~44~1~14 minecraft:deepslate_tile_stairs 0
fill ~44~2~11 ~44~2~14 minecraft:iron_bars
fill ~44~3~11 ~44~4~11 minecraft:torch 3
setblock ~44~5~11 minecraft:lantern 1
setblock ~44~6~11 minecraft:deepslate_tile_stairs 0
fill ~44~7~11 ~44~7~43 minecraft:quartz_block 2
fill ~44~8~11 ~44~8~14 minecraft:quartz_stairs 0
fill ~44~9~11 ~44~9~14 minecraft:quartz_stairs 4
fill ~44~10~11 ~44~10~14 minecraft:quartz_stairs 0
fill ~44~11~11 ~44~11~14 minecraft:quartz_stairs 4
fill ~44~12~11 ~44~12~14 minecraft:quartz_stairs 0
fill ~44~13~11 ~44~13~14 minecraft:quartz_stairs 4
fill ~44~14~11 ~44~14~14 minecraft:quartz_stairs 0
fill ~44~15~11 ~44~15~14 minecraft:quartz_stairs 4
fill ~44~16~11 ~44~16~14 minecraft:polished_blackstone_brick_wall 0
setblock ~44~18~11 minecraft:torch 3
fill ~44~19~11 ~44~19~14 minecraft:quartz_block 2
fill ~45~1~11 ~48~2~11 minecraft:polished_blackstone_bricks
fill ~45~3~11 ~45~4~11 minecraft:cracked_deepslate_tiles
fill ~45~5~11 ~48~7~11 minecraft:polished_blackstone_bricks
setblock ~45~10~11 minecraft:quartz_block 3
fill ~45~15~11 ~46~15~12 minecraft:quartz_block 3
fill ~45~20~11 ~48~22~11 minecraft:quartz_block 2
fill ~45~23~11 ~45~23~14 minecraft:smooth_quartz_stairs 0
setblock ~46~3~11 minecraft:deepslate_tile_stairs 1
setblock ~46~4~11 minecraft:deepslate_tile_stairs 5
setblock ~46~11~11 minecraft:quartz_stairs 0
fill ~46~23~11 ~47~23~11 minecraft:smooth_quartz_stairs 2
setblock ~47~3~11 minecraft:deepslate_tile_stairs 0
setblock ~47~4~11 minecraft:deepslate_tile_stairs 4
setblock ~47~12~11 minecraft:quartz_stairs 0
fill ~48~3~11 ~48~4~11 minecraft:cracked_deepslate_tiles
setblock ~48~12~11 minecraft:quartz_block 3
fill ~48~23~11 ~48~23~13 minecraft:smooth_quartz_stairs 1
setblock ~49~7~11 minecraft:quartz_block 2
fill ~49~8~11 ~49~9~11 minecraft:polished_blackstone_bricks
fill ~49~10~11 ~49~10~13 minecraft:quartz_stairs 1
fill ~49~11~11 ~49~11~13 minecraft:quartz_stairs 5
fill ~49~12~11 ~49~12~13 minecraft:quartz_stairs 1
fill ~49~13~11 ~49~13~13 minecraft:quartz_stairs 5
fill ~49~14~11 ~49~14~13 minecraft:quartz_stairs 1
fill ~49~15~11 ~49~15~13 minecraft:quartz_stairs 5
fill ~49~16~11 ~49~16~13 minecraft:polished_blackstone_brick_wall 0
setblock ~49~18~11 minecraft:torch 3
fill ~49~19~11 ~49~19~13 minecraft:quartz_block 2
fill ~49~20~11 ~49~20~14 minecraft:smooth_quartz_stairs 1
fill ~50~1~11 ~57~2~11 minecraft:polished_blackstone_bricks
setblock ~50~3~11 minecraft:deepslate_tile_stairs 1
setblock ~50~4~11 minecraft:deepslate_tile_stairs 5
fill ~50~5~11 ~57~7~11 minecraft:polished_blackstone_bricks
setblock ~51~3~11 minecraft:deepslate_tile_stairs 0
setblock ~51~4~11 minecraft:deepslate_tile_stairs 4
fill ~52~3~11 ~52~4~11 minecraft:polished_blackstone_bricks
setblock ~53~3~11 minecraft:deepslate_tile_stairs 1
setblock ~53~4~11 minecraft:deepslate_tile_stairs 5
setblock ~54~3~11 minecraft:deepslate_tile_stairs 0
setblock ~54~4~11 minecraft:deepslate_tile_stairs 4
fill ~55~3~11 ~55~4~11 minecraft:polished_blackstone_bricks
setblock ~56~3~11 minecraft:deepslate_tile_stairs 1
setblock ~56~4~11 minecraft:deepslate_tile_stairs 5
setblock ~57~3~11 minecraft:deepslate_tile_stairs 0
setblock ~57~4~11 minecraft:deepslate_tile_stairs 4
setblock ~58~7~11 minecraft:quartz_block 2
fill ~59~1~11 ~66~2~11 minecraft:polished_blackstone_bricks
setblock ~59~3~11 minecraft:deepslate_tile_stairs 1
setblock ~59~4~11 minecraft:deepslate_tile_stairs 5
fill ~59~5~11 ~66~7~11 minecraft:polished_blackstone_bricks
setblock ~60~3~11 minecraft:deepslate_tile_stairs 0
setblock ~60~4~11 minecraft:deepslate_tile_stairs 4
fill ~61~3~11 ~61~4~11 minecraft:polished_blackstone_bricks
setblock ~62~3~11 minecraft:deepslate_tile_stairs 1
setblock ~62~4~11 minecraft:deepslate_tile_stairs 5
setblock ~63~3~11 minecraft:deepslate_tile_stairs 0
setblock ~63~4~11 minecraft:deepslate_tile_stairs 4
fill ~64~3~11 ~64~4~11 minecraft:polished_blackstone_bricks
setblock ~65~3~11 minecraft:deepslate_tile_stairs 1
setblock ~65~4~11 minecraft:deepslate_tile_stairs 5
setblock ~66~3~11 minecraft:deepslate_tile_stairs 0
setblock ~66~4~11 minecraft:deepslate_tile_stairs 4
setblock ~67~7~11 minecraft:quartz_block 2
fill ~68~1~11 ~75~2~11 minecraft:polished_blackstone_bricks
setblock ~68~3~11 minecraft:deepslate_tile_stairs 1
setblock ~68~4~11 minecraft:deepslate_tile_stairs 5
fill ~68~5~11 ~75~7~11 minecraft:polished_blackstone_bricks
setblock ~69~3~11 minecraft:deepslate_tile_stairs 0
setblock ~69~4~11 minecraft:deepslate_tile_stairs 4
fill ~70~3~11 ~70~4~11 minecraft:polished_blackstone_bricks
setblock ~71~3~11 minecraft:deepslate_tile_stairs 1
setblock ~71~4~11 minecraft:deepslate_tile_stairs 5
setblock ~72~3~11 minecraft:deepslate_tile_stairs 0
setblock ~72~4~11 minecraft:deepslate_tile_stairs 4
fill ~73~3~11 ~73~4~11 minecraft:polished_blackstone_bricks
setblock ~74~3~11 minecraft:deepslate_tile_stairs 1
setblock ~74~4~11 minecraft:deepslate_tile_stairs 5
setblock ~75~3~11 minecraft:deepslate_tile_stairs 0
setblock ~75~4~11 minecraft:deepslate_tile_stairs 4
setblock ~76~7~11 minecraft:quartz_block 2
fill ~77~1~11 ~84~2~11 minecraft:polished_blackstone_bricks
setblock ~77~3~11 minecraft:deepslate_tile_stairs 1
setblock ~77~4~11 minecraft:deepslate_tile_stairs 5
fill ~77~5~11 ~84~7~11 minecraft:polished_blackstone_bricks
setblock ~78~3~11 minecraft:deepslate_tile_stairs 0
setblock ~78~4~11 minecraft:deepslate_tile_stairs 4
fill ~79~3~11 ~79~4~11 minecraft:polished_blackstone_bricks
setblock ~80~3~11 minecraft:deepslate_tile_stairs 1
setblock ~80~4~11 minecraft:deepslate_tile_stairs 5
setblock ~81~3~11 minecraft:deepslate_tile_stairs 0
setblock ~81~4~11 minecraft:deepslate_tile_stairs 4
fill ~82~3~11 ~82~4~11 minecraft:polished_blackstone_bricks
setblock ~83~3~11 minecraft:deepslate_tile_stairs 1
setblock ~83~4~11 minecraft:deepslate_tile_stairs 5
setblock ~84~3~11 minecraft:deepslate_tile_stairs 0
setblock ~84~4~11 minecraft:deepslate_tile_stairs 4
setblock ~85~7~11 minecraft:quartz_block 2
fill ~86~1~11 ~87~2~11 minecraft:polished_blackstone_bricks
setblock ~86~3~11 minecraft:deepslate_tile_stairs 1
setblock ~86~4~11 minecraft:deepslate_tile_stairs 5
fill ~86~5~11 ~87~7~11 minecraft:polished_blackstone_bricks
setblock ~87~3~11 minecraft:deepslate_tile_stairs 0
setblock ~87~4~11 minecraft:deepslate_tile_stairs 4
setblock ~88~7~11 minecraft:quartz_block 2
fill ~88~8~11 ~88~9~11 minecraft:polished_blackstone_bricks
fill ~88~10~11 ~88~10~13 minecraft:quartz_stairs 0
fill ~88~11~11 ~88~11~13 minecraft:quartz_stairs 4
fill ~88~12~11 ~88~12~13 minecraft:quartz_stairs 0
fill ~88~13~11 ~88~13~13 minecraft:quartz_stairs 4
fill ~88~14~11 ~88~14~13 minecraft:quartz_stairs 0
fill ~88~15~11 ~88~15~13 minecraft:quartz_stairs 4
fill ~88~16~11 ~88~16~13 minecraft:polished_blackstone_brick_wall 0
setblock ~88~18~11 minecraft:torch 3
fill ~88~19~11 ~88~19~13 minecraft:quartz_block 2
fill ~89~1~11 ~92~2~11 minecraft:polished_blackstone_bricks
fill ~89~3~11 ~89~4~11 minecraft:cracked_deepslate_tiles
fill ~89~5~11 ~92~7~11 minecraft:polished_blackstone_bricks
setblock ~89~8~11 minecraft:quartz_stairs 0
fill ~89~15~11 ~92~15~11 minecraft:quartz_block 3
fill ~89~20~11 ~92~22~11 minecraft:quartz_block 2
fill ~89~23~11 ~92~23~11 minecraft:smooth_quartz_stairs 2
setblock ~90~3~11 minecraft:deepslate_tile_stairs 1
setblock ~90~4~11 minecraft:deepslate_tile_stairs 5
setblock ~90~9~11 minecraft:quartz_stairs 0
setblock ~91~3~11 minecraft:deepslate_tile_stairs 0
setblock ~91~4~11 minecraft:deepslate_tile_stairs 4
setblock ~91~10~11 minecraft:quartz_stairs 0
fill ~92~3~11 ~92~4~11 minecraft:cracked_deepslate_tiles
setblock ~92~10~11 minecraft:quartz_block 3
fill ~93~1~11 ~93~1~14 minecraft:deepslate_tile_stairs 1
fill ~93~2~11 ~93~2~14 minecraft:iron_bars
fill ~93~3~11 ~93~4~11 minecraft:torch 3
setblock ~93~5~11 minecraft:lantern 1
setblock ~93~6~11 minecraft:deepslate_tile_stairs 1
fill ~93~7~11 ~93~7~76 minecraft:quartz_block 2
fill ~93~8~11 ~93~8~14 minecraft:quartz_stairs 1
fill ~93~9~11 ~93~9~14 minecraft:quartz_stairs 5
fill ~93~10~11 ~93~10~14 minecraft:quartz_stairs 1
fill ~93~11~11 ~93~11~14 minecraft:quartz_stairs 5
fill ~93~12~11 ~93~12~14 minecraft:quartz_stairs 1
fill ~93~13~11 ~93~13~14 minecraft:quartz_stairs 5
fill ~93~14~11 ~93~14~14 minecraft:quartz_stairs 1
fill ~93~15~11 ~93~15~14 minecraft:quartz_stairs 5
fill ~93~16~11 ~93~16~14 minecraft:polished_blackstone_brick_wall 0
setblock ~93~18~11 minecraft:torch 3
fill ~93~19~11 ~93~19~14 minecraft:quartz_block 2
fill ~93~20~11 ~93~20~15 minecraft:smooth_quartz_stairs 1
setblock ~94~1~11 minecraft:yellow_flower
setblock ~95~1~11 minecraft:double_plant 2
setblock ~96~1~11 minecraft:red_flower 8
fill ~97~0~11 ~97~0~75 minecraft:grass
setblock ~97~1~11 minecraft:tallgrass 0
setblock ~43~1~12 minecraft:double_plant 2
fill ~44~6~12 ~44~6~13 minecraft:deepslate_tile_stairs 4
fill ~45~1~12 ~45~2~14 minecraft:polished_blackstone_bricks
setblock ~45~3~12 minecraft:deepslate_tile_stairs 3
setblock ~45~4~12 minecraft:deepslate_tile_stairs 7
fill ~45~5~12 ~45~7~14 minecraft:polished_blackstone_bricks
setblock ~45~10~12 minecraft:quartz_stairs 3
fill ~45~20~12 ~45~22~14 minecraft:quartz_block 2
fill ~46~1~12 ~91~7~12 minecraft:obsidian
fill ~46~8~12 ~46~14~12 minecraft:obsidian
fill ~46~20~12 ~47~20~12 minecraft:glowstone
fill ~46~21~12 ~48~22~13 minecraft:quartz_block 2
fill ~46~23~12 ~47~26~12 minecraft:quartz_block 2
setblock ~46~27~12 minecraft:quartz_block 2
fill ~46~28~12 ~46~32~12 minecraft:stained_glass_pane 0
setblock ~46~33~12 minecraft:sea_lantern
fill ~47~8~12 ~47~15~12 minecraft:ladder 5
setblock ~47~27~12 minecraft:stone_block_slab 6
setblock ~48~13~12 minecraft:quartz_stairs 2
fill ~48~20~12 ~48~20~13 minecraft:quartz_block 2
setblock ~49~8~12 minecraft:iron_door 2
setblock ~51~8~12 minecraft:torch 5
setblock ~56~8~12 minecraft:torch 5
setblock ~67~8~12 minecraft:torch 5
setblock ~76~8~12 minecraft:torch 5
setblock ~84~8~12 minecraft:torch 5
setblock ~88~8~12 minecraft:iron_door 0
setblock ~89~15~12 minecraft:quartz_block 3
fill ~89~20~12 ~89~22~13 minecraft:quartz_block 2
setblock ~89~23~12 minecraft:smooth_quartz_stairs 0
fill ~90~8~12 ~90~15~12 minecraft:ladder 4
fill ~90~20~12 ~91~20~12 minecraft:glowstone
fill ~90~21~12 ~92~22~14 minecraft:quartz_block 2
fill ~90~23~12 ~91~26~12 minecraft:quartz_block 2
setblock ~90~27~12 minecraft:stone_block_slab 6
fill ~91~8~12 ~91~14~12 minecraft:obsidian
fill ~91~15~12 ~92~15~12 minecraft:quartz_block 3
setblock ~91~27~12 minecraft:quartz_block 2
fill ~91~28~12 ~91~32~12 minecraft:stained_glass_pane 0
setblock ~91~33~12 minecraft:sea_lantern
fill ~92~1~12 ~92~2~14 minecraft:polished_blackstone_bricks
setblock ~92~3~12 minecraft:deepslate_tile_stairs 3
setblock ~92~4~12 minecraft:deepslate_tile_stairs 7
fill ~92~5~12 ~92~7~14 minecraft:polished_blackstone_bricks
setblock ~92~11~12 minecraft:quartz_stairs 2
fill ~92~20~12 ~92~20~14 minecraft:quartz_block 2
fill ~92~23~12 ~92~23~13 minecraft:smooth_quartz_stairs 1
fill ~93~6~12 ~93~6~13 minecraft:deepslate_tile_stairs 5
fill ~95~1~12 ~95~1~13 minecraft:tallgrass 0
fill ~96~1~12 ~97~1~12 minecraft:double_plant 2
fill ~98~0~12 ~98~0~39 minecraft:grass
setblock ~98~1~12 minecraft:tallgrass 0
fill ~43~1~13 ~43~1~18 minecraft:tallgrass 0
setblock ~45~3~13 minecraft:deepslate_tile_stairs 2
setblock ~45~4~13 minecraft:deepslate_tile_stairs 6
setblock ~45~9~13 minecraft:quartz_stairs 3
fill ~45~15~13 ~45~15~14 minecraft:quartz_block 3
fill ~46~1~13 ~48~6~14 minecraft:obsidian
fill ~46~7~13 ~46~7~45 minecraft:obsidian
fill ~46~8~13 ~46~15~13 minecraft:ladder 3
setblock ~46~20~13 minecraft:glowstone
fill ~46~23~13 ~46~26~13 minecraft:quartz_block 2
setblock ~46~27~13 minecraft:stone_block_slab 6
fill ~47~7~13 ~48~7~13 minecraft:polished_blackstone_bricks
setblock ~47~15~13 minecraft:quartz_block 3
fill ~47~20~13 ~47~20~14 minecraft:quartz_block 2
setblock ~47~23~13 minecraft:smooth_quartz_stairs 3
setblock ~48~9~13 minecraft:lever 2
setblock ~48~14~13 minecraft:quartz_stairs 2
fill ~49~1~13 ~49~7~14 minecraft:quartz_block 2
fill ~49~8~13 ~49~9~13 minecraft:polished_blackstone_bricks
setblock ~49~18~13 minecraft:torch 4
fill ~50~1~13 ~57~2~13 minecraft:polished_blackstone_bricks
setblock ~50~3~13 minecraft:deepslate_tile_stairs 1
setblock ~50~4~13 minecraft:deepslate_tile_stairs 5
fill ~50~5~13 ~57~7~13 minecraft:polished_blackstone_bricks
setblock ~51~3~13 minecraft:deepslate_tile_stairs 0
setblock ~51~4~13 minecraft:deepslate_tile_stairs 4
fill ~52~3~13 ~52~4~13 minecraft:polished_blackstone_bricks
setblock ~53~3~13 minecraft:deepslate_tile_stairs 1
setblock ~53~4~13 minecraft:deepslate_tile_stairs 5
setblock ~54~3~13 minecraft:deepslate_tile_stairs 0
setblock ~54~4~13 minecraft:deepslate_tile_stairs 4
fill ~55~3~13 ~55~4~13 minecraft:polished_blackstone_bricks
setblock ~56~3~13 minecraft:deepslate_tile_stairs 1
setblock ~56~4~13 minecraft:deepslate_tile_stairs 5
setblock ~57~3~13 minecraft:deepslate_tile_stairs 0
setblock ~57~4~13 minecraft:deepslate_tile_stairs 4
fill ~58~1~13 ~58~7~14 minecraft:quartz_block 2
fill ~59~1~13 ~66~2~13 minecraft:polished_blackstone_bricks
setblock ~59~3~13 minecraft:deepslate_tile_stairs 1
setblock ~59~4~13 minecraft:deepslate_tile_stairs 5
fill ~59~5~13 ~66~7~13 minecraft:polished_blackstone_bricks
setblock ~60~3~13 minecraft:deepslate_tile_stairs 0
setblock ~60~4~13 minecraft:deepslate_tile_stairs 4
fill ~61~3~13 ~61~4~13 minecraft:polished_blackstone_bricks
setblock ~62~3~13 minecraft:deepslate_tile_stairs 1
setblock ~62~4~13 minecraft:deepslate_tile_stairs 5
setblock ~63~3~13 minecraft:deepslate_tile_stairs 0
setblock ~63~4~13 minecraft:deepslate_tile_stairs 4
fill ~64~3~13 ~64~4~13 minecraft:polished_blackstone_bricks
setblock ~65~3~13 minecraft:deepslate_tile_stairs 1
setblock ~65~4~13 minecraft:deepslate_tile_stairs 5
setblock ~66~3~13 minecraft:deepslate_tile_stairs 0
setblock ~66~4~13 minecraft:deepslate_tile_stairs 4
fill ~67~1~13 ~67~7~14 minecraft:quartz_block 2
fill ~68~1~13 ~75~2~13 minecraft:polished_blackstone_bricks
setblock ~68~3~13 minecraft:deepslate_tile_stairs 1
setblock ~68~4~13 minecraft:deepslate_tile_stairs 5
fill ~68~5~13 ~75~7~13 minecraft:polished_blackstone_bricks
setblock ~69~3~13 minecraft:deepslate_tile_stairs 0
setblock ~69~4~13 minecraft:deepslate_tile_stairs 4
fill ~70~3~13 ~70~4~13 minecraft:polished_blackstone_bricks
setblock ~71~3~13 minecraft:deepslate_tile_stairs 1
setblock ~71~4~13 minecraft:deepslate_tile_stairs 5
setblock ~72~3~13 minecraft:deepslate_tile_stairs 0
setblock ~72~4~13 minecraft:deepslate_tile_stairs 4
fill ~73~3~13 ~73~4~13 minecraft:polished_blackstone_bricks
setblock ~74~3~13 minecraft:deepslate_tile_stairs 1
setblock ~74~4~13 minecraft:deepslate_tile_stairs 5
setblock ~75~3~13 minecraft:deepslate_tile_stairs 0
setblock ~75~4~13 minecraft:deepslate_tile_stairs 4
fill ~76~1~13 ~76~7~14 minecraft:quartz_block 2
fill ~77~1~13 ~84~2~13 minecraft:polished_blackstone_bricks
setblock ~77~3~13 minecraft:deepslate_tile_stairs 1
setblock ~77~4~13 minecraft:deepslate_tile_stairs 5
fill ~77~5~13 ~84~7~13 minecraft:polished_blackstone_bricks
setblock ~78~3~13 minecraft:deepslate_tile_stairs 0
setblock ~78~4~13 minecraft:deepslate_tile_stairs 4
fill ~79~3~13 ~79~4~13 minecraft:polished_blackstone_bricks
setblock ~80~3~13 minecraft:deepslate_tile_stairs 1
setblock ~80~4~13 minecraft:deepslate_tile_stairs 5
setblock ~81~3~13 minecraft:deepslate_tile_stairs 0
setblock ~81~4~13 minecraft:deepslate_tile_stairs 4
fill ~82~3~13 ~82~4~13 minecraft:polished_blackstone_bricks
setblock ~83~3~13 minecraft:deepslate_tile_stairs 1
setblock ~83~4~13 minecraft:deepslate_tile_stairs 5
setblock ~84~3~13 minecraft:deepslate_tile_stairs 0
setblock ~84~4~13 minecraft:deepslate_tile_stairs 4
fill ~85~1~13 ~85~7~14 minecraft:quartz_block 2
fill ~86~1~13 ~87~2~13 minecraft:polished_blackstone_bricks
setblock ~86~3~13 minecraft:deepslate_tile_stairs 1
setblock ~86~4~13 minecraft:deepslate_tile_stairs 5
fill ~86~5~13 ~87~7~13 minecraft:polished_blackstone_bricks
setblock ~87~3~13 minecraft:deepslate_tile_stairs 0
setblock ~87~4~13 minecraft:deepslate_tile_stairs 4
fill ~88~1~13 ~88~7~14 minecraft:quartz_block 2
fill ~88~8~13 ~88~9~13 minecraft:polished_blackstone_bricks
setblock ~88~18~13 minecraft:torch 4
fill ~89~1~13 ~91~6~14 minecraft:obsidian
fill ~89~7~13 ~90~7~13 minecraft:polished_blackstone_bricks
setblock ~89~9~13 minecraft:lever 1
setblock ~89~15~13 minecraft:quartz_stairs 3
setblock ~89~23~13 minecraft:smooth_quartz_stairs 3
setblock ~90~15~13 minecraft:quartz_block 3
fill ~90~20~13 ~90~20~14 minecraft:quartz_block 2
setblock ~90~23~13 minecraft:smooth_quartz_stairs 0
fill ~91~7~13 ~91~7~78 minecraft:obsidian
fill ~91~8~13 ~91~15~13 minecraft:ladder 3
setblock ~91~20~13 minecraft:glowstone
fill ~91~23~13 ~91~26~13 minecraft:quartz_block 2
setblock ~91~27~13 minecraft:stone_block_slab 6
setblock ~92~3~13 minecraft:deepslate_tile_stairs 2
setblock ~92~4~13 minecraft:deepslate_tile_stairs 6
setblock ~92~12~13 minecraft:quartz_stairs 2
setblock ~94~1~13 minecraft:double_plant 2
fill ~96~1~13 ~96~1~17 minecraft:tallgrass 0
setblock ~97~1~13 minecraft:double_plant 2
setblock ~98~1~13 minecraft:red_flower 8
fill ~99~0~13 ~99~0~32 minecraft:grass
fill ~44~3~14 ~44~4~14 minecraft:torch 4
setblock ~44~5~14 minecraft:lantern 1
setblock ~44~6~14 minecraft:deepslate_tile_stairs 0
setblock ~44~18~14 minecraft:torch 4
fill ~45~3~14 ~45~4~14 minecraft:cracked_deepslate_tiles
setblock ~45~8~14 minecraft:quartz_stairs 3
setblock ~46~15~14 minecraft:quartz_block 3
fill ~46~20~14 ~46~22~14 minecraft:quartz_block 2
setblock ~46~23~14 minecraft:smooth_quartz_stairs 3
setblock ~47~7~14 minecraft:polished_blackstone_bricks
setblock ~47~9~14 minecraft:lever 4
setblock ~47~15~14 minecraft:quartz_stairs 1
fill ~47~21~14 ~47~22~14 minecraft:quartz_block 2
setblock ~47~23~14 minecraft:smooth_quartz_stairs 1
fill ~48~7~14 ~48~7~47 minecraft:quartz_block 2
setblock ~48~14~14 minecraft:quartz_block 3
setblock ~48~18~14 minecraft:torch 2
setblock ~48~19~14 minecraft:quartz_block 2
setblock ~48~20~14 minecraft:smooth_quartz_stairs 3
fill ~49~8~14 ~49~19~14 minecraft:quartz_block 2
fill ~50~1~14 ~57~1~14 minecraft:deepslate_tile_stairs 3
fill ~50~2~14 ~57~2~14 minecraft:iron_bars
setblock ~50~5~14 minecraft:torch 1
fill ~50~6~14 ~51~6~14 minecraft:deepslate_tile_stairs 7
fill ~50~7~14 ~57~7~14 minecraft:quartz_block 2
fill ~50~8~14 ~57~8~14 minecraft:quartz_stairs 3
setblock ~52~4~14 minecraft:wall_banner 3
setblock ~52~5~14 minecraft:lantern 1
setblock ~52~6~14 minecraft:deepslate_tile_stairs 3
fill ~53~6~14 ~54~6~14 minecraft:deepslate_tile_stairs 7
setblock ~55~4~14 minecraft:wall_banner 3
setblock ~55~5~14 minecraft:lantern 1
setblock ~55~6~14 minecraft:deepslate_tile_stairs 3
fill ~56~6~14 ~57~6~14 minecraft:deepslate_tile_stairs 7
setblock ~57~5~14 minecraft:torch 2
setblock ~58~8~14 minecraft:quartz_block 2
fill ~59~1~14 ~66~1~14 minecraft:deepslate_tile_stairs 3
fill ~59~2~14 ~66~2~14 minecraft:iron_bars
setblock ~59~5~14 minecraft:torch 1
fill ~59~6~14 ~60~6~14 minecraft:deepslate_tile_stairs 7
fill ~59~7~14 ~66~7~14 minecraft:quartz_block 2
fill ~59~8~14 ~66~8~14 minecraft:quartz_stairs 3
setblock ~61~4~14 minecraft:wall_banner 3
setblock ~61~5~14 minecraft:lantern 1
setblock ~61~6~14 minecraft:deepslate_tile_stairs 3
fill ~62~6~14 ~63~6~14 minecraft:deepslate_tile_stairs 7
setblock ~64~4~14 minecraft:wall_banner 3
setblock ~64~5~14 minecraft:lantern 1
setblock ~64~6~14 minecraft:deepslate_tile_stairs 3
fill ~65~6~14 ~66~6~14 minecraft:deepslate_tile_stairs 7
setblock ~66~5~14 minecraft:torch 2
setblock ~67~8~14 minecraft:quartz_block 2
fill ~68~1~14 ~75~1~14 minecraft:deepslate_tile_stairs 3
fill ~68~2~14 ~75~2~14 minecraft:iron_bars
setblock ~68~5~14 minecraft:torch 1
fill ~68~6~14 ~69~6~14 minecraft:deepslate_tile_stairs 7
fill ~68~7~14 ~75~7~14 minecraft:quartz_block 2
fill ~68~8~14 ~75~8~14 minecraft:quartz_stairs 3
setblock ~70~4~14 minecraft:wall_banner 3
setblock ~70~5~14 minecraft:lantern 1
setblock ~70~6~14 minecraft:deepslate_tile_stairs 3
fill ~71~6~14 ~72~6~14 minecraft:deepslate_tile_stairs 7
setblock ~73~4~14 minecraft:wall_banner 3
setblock ~73~5~14 minecraft:lantern 1
setblock ~73~6~14 minecraft:deepslate_tile_stairs 3
fill ~74~6~14 ~75~6~14 minecraft:deepslate_tile_stairs 7
setblock ~75~5~14 minecraft:torch 2
setblock ~76~8~14 minecraft:quartz_block 2
fill ~77~1~14 ~84~1~14 minecraft:deepslate_tile_stairs 3
fill ~77~2~14 ~84~2~14 minecraft:iron_bars
setblock ~77~5~14 minecraft:torch 1
fill ~77~6~14 ~78~6~14 minecraft:deepslate_tile_stairs 7
fill ~77~7~14 ~84~7~14 minecraft:quartz_block 2
fill ~77~8~14 ~84~8~14 minecraft:quartz_stairs 3
setblock ~79~4~14 minecraft:wall_banner 3
setblock ~79~5~14 minecraft:lantern 1
setblock ~79~6~14 minecraft:deepslate_tile_stairs 3
fill ~80~6~14 ~81~6~14 minecraft:deepslate_tile_stairs 7
setblock ~82~4~14 minecraft:wall_banner 3
setblock ~82~5~14 minecraft:lantern 1
setblock ~82~6~14 minecraft:deepslate_tile_stairs 3
fill ~83~6~14 ~84~6~14 minecraft:deepslate_tile_stairs 7
setblock ~84~5~14 minecraft:torch 2
setblock ~85~8~14 minecraft:quartz_block 2
fill ~86~1~14 ~87~1~14 minecraft:deepslate_tile_stairs 3
fill ~86~2~14 ~87~2~14 minecraft:iron_bars
setblock ~86~5~14 minecraft:torch 1
fill ~86~6~14 ~87~6~14 minecraft:deepslate_tile_stairs 7
fill ~86~7~14 ~87~7~14 minecraft:quartz_block 2
fill ~86~8~14 ~87~8~14 minecraft:quartz_stairs 3
fill ~88~8~14 ~88~19~14 minecraft:quartz_block 2
setblock ~88~20~14 minecraft:smooth_quartz_stairs 3
fill ~89~7~14 ~89~7~80 minecraft:quartz_block 2
setblock ~89~14~14 minecraft:quartz_block 3
setblock ~89~18~14 minecraft:torch 4
setblock ~89~19~14 minecraft:quartz_block 2
setblock ~89~20~14 minecraft:smooth_quartz_stairs 0
setblock ~90~7~14 minecraft:polished_blackstone_bricks
setblock ~90~9~14 minecraft:lever 4
setblock ~90~14~14 minecraft:quartz_stairs 1
fill ~90~23~14 ~92~23~14 minecraft:smooth_quartz_stairs 3
setblock ~91~13~14 minecraft:quartz_stairs 1
setblock ~91~20~14 minecraft:quartz_block 2
fill ~92~3~14 ~92~4~14 minecraft:cracked_deepslate_tiles
setblock ~92~12~14 minecraft:quartz_block 3
fill ~93~3~14 ~93~4~14 minecraft:torch 4
setblock ~93~5~14 minecraft:lantern 1
setblock ~93~6~14 minecraft:deepslate_tile_stairs 1
setblock ~93~18~14 minecraft:torch 4
fill ~97~1~14 ~99~1~15 minecraft:tallgrass 0
fill ~100~0~14 ~100~0~28 minecraft:grass
fill ~44~0~15 ~46~0~19 minecraft:dirt 0
fill ~44~1~15 ~45~6~15 minecraft:quartz_block 2
fill ~44~8~15 ~44~19~15 minecraft:quartz_block 2
fill ~44~20~15 ~47~20~15 minecraft:smooth_quartz_stairs 3
setblock ~45~7~15 minecraft:quartz_block 2
fill ~45~8~15 ~45~9~15 minecraft:polished_blackstone_bricks
fill ~45~10~15 ~47~10~15 minecraft:quartz_stairs 3
fill ~45~11~15 ~47~11~15 minecraft:quartz_stairs 7
fill ~45~12~15 ~47~12~15 minecraft:quartz_stairs 3
fill ~45~13~15 ~47~13~15 minecraft:quartz_stairs 7
fill ~45~14~15 ~47~14~15 minecraft:quartz_stairs 3
fill ~45~15~15 ~47~15~15 minecraft:quartz_stairs 7
fill ~45~16~15 ~47~16~15 minecraft:polished_blackstone_brick_wall 0
setblock ~45~18~15 minecraft:torch 1
fill ~45~19~15 ~47~19~15 minecraft:quartz_block 2
fill ~46~1~15 ~46~6~45 minecraft:obsidian
setblock ~46~8~15 minecraft:iron_door 3
fill ~47~0~15 ~48~0~15 minecraft:sandstone
fill ~47~1~15 ~48~6~15 minecraft:quartz_block 2
setblock ~47~7~15 minecraft:quartz_block 2
fill ~47~8~15 ~47~9~15 minecraft:polished_blackstone_bricks
setblock ~47~18~15 minecraft:torch 2
fill ~48~8~15 ~48~19~15 minecraft:quartz_block 2
setblock ~48~20~15 minecraft:smooth_quartz_stairs 1
setblock ~49~0~15 minecraft:grass_path
fill ~50~0~15 ~50~0~16 minecraft:grass
setblock ~51~0~15 minecraft:podzol
fill ~52~0~15 ~53~0~15 minecraft:dirt 1
setblock ~54~0~15 minecraft:grass
fill ~55~0~15 ~56~0~15 minecraft:dirt_with_roots
setblock ~56~1~15 minecraft:torch 5
fill ~57~0~15 ~58~0~15 minecraft:grass
setblock ~59~0~15 minecraft:grass_path
setblock ~60~0~15 minecraft:podzol
fill ~61~0~15 ~61~0~17 minecraft:grass
setblock ~62~0~15 minecraft:dirt 1
setblock ~63~0~15 minecraft:podzol
setblock ~63~1~15 minecraft:torch 5
fill ~64~0~15 ~66~0~16 minecraft:grass
fill ~64~1~15 ~66~1~15 minecraft:tallgrass 0
setblock ~67~0~15 minecraft:dirt 1
setblock ~68~0~15 minecraft:dirt 0
setblock ~69~0~15 minecraft:podzol
fill ~70~0~15 ~70~0~16 minecraft:grass
setblock ~70~1~15 minecraft:torch 5
setblock ~71~0~15 minecraft:podzol
fill ~72~0~15 ~73~0~15 minecraft:grass
setblock ~72~1~15 minecraft:torch 5
fill ~74~0~15 ~74~0~16 minecraft:podzol
fill ~75~0~15 ~75~0~17 minecraft:grass
setblock ~75~1~15 minecraft:tallgrass 0
setblock ~76~0~15 minecraft:dirt 1
fill ~77~0~15 ~78~0~15 minecraft:grass
setblock ~77~1~15 minecraft:tallgrass 0
setblock ~79~0~15 minecraft:grass_path
setblock ~80~0~15 minecraft:dirt 1
setblock ~81~0~15 minecraft:grass
setblock ~81~1~15 minecraft:yellow_flower
setblock ~82~0~15 minecraft:podzol
fill ~83~0~15 ~84~0~15 minecraft:grass
setblock ~85~0~15 minecraft:grass_path
fill ~86~0~15 ~88~0~15 minecraft:grass
setblock ~86~1~15 minecraft:torch 5
setblock ~88~1~15 minecraft:torch 5
fill ~89~0~15 ~93~0~80 minecraft:dirt 0
fill ~89~1~15 ~90~6~15 minecraft:quartz_block 2
fill ~89~8~15 ~89~19~15 minecraft:quartz_block 2
fill ~89~20~15 ~92~20~15 minecraft:smooth_quartz_stairs 3
setblock ~90~7~15 minecraft:quartz_block 2
fill ~90~8~15 ~90~9~15 minecraft:polished_blackstone_bricks
fill ~90~10~15 ~92~10~15 minecraft:quartz_stairs 3
fill ~90~11~15 ~92~11~15 minecraft:quartz_stairs 7
fill ~90~12~15 ~92~12~15 minecraft:quartz_stairs 3
fill ~90~13~15 ~92~13~15 minecraft:quartz_stairs 7
fill ~90~14~15 ~92~14~15 minecraft:quartz_stairs 3
fill ~90~15~15 ~92~15~15 minecraft:quartz_stairs 7
fill ~90~16~15 ~92~16~15 minecraft:polished_blackstone_brick_wall 0
setblock ~90~18~15 minecraft:torch 1
fill ~90~19~15 ~92~19~15 minecraft:quartz_block 2
fill ~91~1~15 ~91~6~78 minecraft:obsidian
setblock ~91~8~15 minecraft:iron_door 3
fill ~92~1~15 ~93~6~15 minecraft:quartz_block 2
setblock ~92~7~15 minecraft:quartz_block 2
fill ~92~8~15 ~92~9~15 minecraft:polished_blackstone_bricks
setblock ~92~18~15 minecraft:torch 2
fill ~93~8~15 ~93~19~15 minecraft:quartz_block 2
fill ~94~1~15 ~94~1~17 minecraft:tallgrass 0
setblock ~95~1~15 minecraft:red_flower 0
fill ~100~1~15 ~100~1~17 minecraft:tallgrass 0
fill ~44~1~16 ~44~1~23 minecraft:deepslate_tile_stairs 0
fill ~44~2~16 ~44~2~23 minecraft:iron_bars
setblock ~44~5~16 minecraft:torch 3
fill ~44~6~16 ~44~6~17 minecraft:deepslate_tile_stairs 4
fill ~44~8~16 ~44~8~23 minecraft:quartz_stairs 0
fill ~45~1~16 ~45~2~23 minecraft:polished_blackstone_bricks
setblock ~45~3~16 minecraft:deepslate_tile_stairs 3
setblock ~45~4~16 minecraft:deepslate_tile_stairs 7
fill ~45~5~16 ~45~7~23 minecraft:polished_blackstone_bricks
fill ~47~0~16 ~48~0~47 minecraft:dirt 0
fill ~47~1~16 ~47~2~23 minecraft:polished_blackstone_bricks
setblock ~47~3~16 minecraft:deepslate_tile_stairs 3
setblock ~47~4~16 minecraft:deepslate_tile_stairs 7
fill ~47~5~16 ~47~7~23 minecraft:polished_blackstone_bricks
fill ~48~1~16 ~48~1~23 minecraft:deepslate_tile_stairs 1
fill ~48~2~16 ~48~2~23 minecraft:iron_bars
fill ~48~6~16 ~48~6~17 minecraft:deepslate_tile_stairs 5
fill ~48~8~16 ~48~8~23 minecraft:quartz_stairs 1
fill ~49~0~16 ~49~0~18 minecraft:grass
fill ~49~1~16 ~49~1~18 minecraft:tallgrass 0
setblock ~50~1~16 minecraft:double_plant 2
setblock ~51~0~16 minecraft:dirt 1
setblock ~52~0~16 minecraft:grass_path
fill ~53~0~16 ~53~0~17 minecraft:grass
setblock ~54~0~16 minecraft:dirt_with_roots
fill ~55~0~16 ~55~0~17 minecraft:grass
setblock ~55~1~16 minecraft:double_plant 2
fill ~56~0~16 ~58~0~16 minecraft:podzol
setblock ~57~1~16 minecraft:torch 5
fill ~59~0~16 ~59~0~17 minecraft:grass
setblock ~60~0~16 minecraft:dirt_with_roots
setblock ~61~1~16 minecraft:tallgrass 0
fill ~62~0~16 ~63~0~16 minecraft:grass
setblock ~63~1~16 minecraft:tallgrass 0
fill ~65~1~16 ~65~2~16 minecraft:bamboo 2
fill ~65~3~16 ~65~4~16 minecraft:bamboo 2
fill ~65~5~16 ~65~13~16 minecraft:bamboo 2
setblock ~65~14~16 minecraft:bamboo 2
setblock ~65~15~16 minecraft:bamboo 2
setblock ~65~16~16 minecraft:bamboo 2
setblock ~67~0~16 minecraft:grass_path
setblock ~68~0~16 minecraft:podzol
setblock ~68~1~16 minecraft:bamboo 2
fill ~68~2~16 ~68~3~16 minecraft:bamboo 2
fill ~68~4~16 ~68~9~16 minecraft:bamboo 2
setblock ~68~10~16 minecraft:bamboo 2
fill ~68~11~16 ~68~12~16 minecraft:bamboo 2
setblock ~69~0~16 minecraft:dirt 1
setblock ~71~0~16 minecraft:grass_path
fill ~72~0~16 ~72~0~18 minecraft:grass
fill ~73~0~16 ~73~0~17 minecraft:dirt 1
setblock ~75~1~16 minecraft:double_plant 2
setblock ~76~0~16 minecraft:grass
setblock ~76~1~16 minecraft:tallgrass 0
setblock ~77~0~16 minecraft:podzol
fill ~78~0~16 ~78~0~17 minecraft:grass
setblock ~78~1~16 minecraft:tallgrass 0
setblock ~79~0~16 minecraft:dirt 1
setblock ~80~0~16 minecraft:dirt_with_roots
setblock ~81~0~16 minecraft:podzol
fill ~82~0~16 ~82~0~17 minecraft:grass
setblock ~82~1~16 minecraft:tallgrass 0
setblock ~83~0~16 minecraft:dirt_with_roots
setblock ~84~0~16 minecraft:grass
setblock ~84~1~16 minecraft:tallgrass 0
fill ~85~0~16 ~86~0~16 minecraft:dirt 1
setblock ~87~0~16 minecraft:podzol
setblock ~88~0~16 minecraft:grass
fill ~89~1~16 ~89~1~20 minecraft:deepslate_tile_stairs 0
fill ~89~2~16 ~89~2~20 minecraft:iron_bars
fill ~89~6~16 ~89~6~17 minecraft:deepslate_tile_stairs 4
fill ~89~8~16 ~89~8~20 minecraft:quartz_stairs 0
fill ~90~1~16 ~90~2~20 minecraft:polished_blackstone_bricks
setblock ~90~3~16 minecraft:deepslate_tile_stairs 3
setblock ~90~4~16 minecraft:deepslate_tile_stairs 7
fill ~90~5~16 ~90~7~20 minecraft:polished_blackstone_bricks
fill ~92~1~16 ~92~2~20 minecraft:polished_blackstone_bricks
setblock ~92~3~16 minecraft:deepslate_tile_stairs 3
setblock ~92~4~16 minecraft:deepslate_tile_stairs 7
fill ~92~5~16 ~92~7~20 minecraft:polished_blackstone_bricks
fill ~93~1~16 ~93~1~20 minecraft:deepslate_tile_stairs 1
fill ~93~2~16 ~93~2~20 minecraft:iron_bars
fill ~93~6~16 ~93~6~17 minecraft:deepslate_tile_stairs 5
fill ~93~8~16 ~93~8~20 minecraft:quartz_stairs 1
setblock ~95~1~16 minecraft:tallgrass 0
fill ~97~1~16 ~97~1~18 minecraft:tallgrass 0
setblock ~98~1~16 minecraft:double_plant 2
fill ~99~1~16 ~99~1~17 minecraft:tallgrass 0
fill ~101~0~16 ~101~0~24 minecraft:grass
setblock ~45~3~17 minecraft:deepslate_tile_stairs 2
setblock ~45~4~17 minecraft:deepslate_tile_stairs 6
setblock ~47~3~17 minecraft:deepslate_tile_stairs 2
setblock ~47~4~17 minecraft:deepslate_tile_stairs 6
setblock ~50~0~17 minecraft:dirt 1
setblock ~51~0~17 minecraft:grass_path
fill ~52~0~17 ~52~0~19 minecraft:grass
setblock ~54~0~17 minecraft:grass_path
setblock ~55~1~17 minecraft:tallgrass 0
fill ~56~0~17 ~56~0~18 minecraft:grass
setblock ~56~1~17 minecraft:double_plant 2
setblock ~57~0~17 minecraft:grass_path
setblock ~58~0~17 minecraft:grass
fill ~60~0~17 ~60~0~18 minecraft:podzol
setblock ~61~1~17 minecraft:red_flower 8
setblock ~62~0~17 minecraft:dirt_with_roots
setblock ~63~0~17 minecraft:grass_path
fill ~64~0~17 ~65~0~17 minecraft:podzol
fill ~66~0~17 ~69~0~17 minecraft:grass
setblock ~66~1~17 minecraft:tallgrass 0
setblock ~67~1~17 minecraft:double_plant 2
setblock ~68~1~17 minecraft:tallgrass 0
setblock ~69~1~17 minecraft:bamboo 2
fill ~69~2~17 ~70~2~17 minecraft:bamboo 2
fill ~69~3~17 ~69~6~17 minecraft:bamboo 2
setblock ~69~7~17 minecraft:bamboo 2
fill ~69~8~17 ~70~9~17 minecraft:bamboo 2
setblock ~69~10~17 minecraft:bamboo 2
fill ~69~11~17 ~70~11~17 minecraft:bamboo 2
setblock ~69~12~17 minecraft:bamboo 2
fill ~69~13~17 ~69~14~17 minecraft:bamboo 2
setblock ~70~0~17 minecraft:dirt 1
setblock ~70~1~17 minecraft:bamboo 2
fill ~70~3~17 ~70~4~17 minecraft:bamboo 2
fill ~70~5~17 ~70~7~17 minecraft:bamboo 2
setblock ~70~10~17 minecraft:bamboo 2
setblock ~70~12~17 minecraft:bamboo 2
setblock ~70~13~17 minecraft:bamboo 2
setblock ~70~14~17 minecraft:bamboo 2
setblock ~70~15~17 minecraft:bamboo 2
setblock ~70~16~17 minecraft:bamboo 2
fill ~71~0~17 ~71~0~18 minecraft:dirt_with_roots
setblock ~72~1~17 minecraft:bamboo 2
setblock ~72~2~17 minecraft:bamboo 2
fill ~72~3~17 ~73~5~17 minecraft:bamboo 2
fill ~72~6~17 ~72~7~17 minecraft:bamboo 2
setblock ~72~8~17 minecraft:bamboo 2
fill ~72~9~17 ~72~10~17 minecraft:bamboo 2
setblock ~72~11~17 minecraft:bamboo 2
fill ~72~12~17 ~72~13~17 minecraft:bamboo 2
setblock ~73~1~17 minecraft:bamboo 2
setblock ~73~2~17 minecraft:bamboo 2
fill ~73~6~17 ~73~7~17 minecraft:bamboo 2
setblock ~73~8~17 minecraft:bamboo 2
setblock ~73~9~17 minecraft:bamboo 2
setblock ~73~10~17 minecraft:bamboo 2
setblock ~73~11~17 minecraft:bamboo 2
setblock ~73~12~17 minecraft:bamboo 2
setblock ~73~13~17 minecraft:bamboo 2
fill ~74~0~17 ~74~0~18 minecraft:grass
fill ~74~1~17 ~75~1~17 minecraft:tallgrass 0
setblock ~76~0~17 minecraft:dirt_with_roots
setblock ~77~0~17 minecraft:grass_path
setblock ~78~1~17 minecraft:red_flower 0
fill ~79~0~17 ~79~0~18 minecraft:grass
setblock ~79~1~17 minecraft:double_plant 2
setblock ~80~0~17 minecraft:dirt 1
fill ~81~0~17 ~81~0~18 minecraft:grass
setblock ~81~1~17 minecraft:red_flower 9
setblock ~82~1~17 minecraft:double_plant 2
setblock ~83~0~17 minecraft:podzol
fill ~84~0~17 ~84~0~18 minecraft:grass_path
setblock ~85~0~17 minecraft:grass
setblock ~85~1~17 minecraft:tallgrass 0
setblock ~86~0~17 minecraft:podzol
setblock ~87~0~17 minecraft:dirt 1
setblock ~88~0~17 minecraft:grass_path
setblock ~90~3~17 minecraft:deepslate_tile_stairs 2
setblock ~90~4~17 minecraft:deepslate_tile_stairs 6
setblock ~92~3~17 minecraft:deepslate_tile_stairs 2
setblock ~92~4~17 minecraft:deepslate_tile_stairs 6
setblock ~95~1~17 minecraft:double_plant 2
fill ~98~1~17 ~98~1~22 minecraft:tallgrass 0
setblock ~101~1~17 minecraft:tallgrass 0
setblock ~44~4~18 minecraft:wall_banner 4
setblock ~44~5~18 minecraft:lantern 1
setblock ~44~6~18 minecraft:deepslate_tile_stairs 0
fill ~45~3~18 ~45~4~18 minecraft:polished_blackstone_bricks
fill ~47~3~18 ~47~4~18 minecraft:polished_blackstone_bricks
setblock ~48~4~18 minecraft:wall_banner 5
setblock ~48~5~18 minecraft:lantern 1
setblock ~48~6~18 minecraft:deepslate_tile_stairs 1
fill ~50~0~18 ~50~0~21 minecraft:grass
fill ~50~1~18 ~50~1~20 minecraft:tallgrass 0
setblock ~51~0~18 minecraft:podzol
fill ~52~1~18 ~52~1~19 minecraft:double_plant 2
setblock ~53~0~18 minecraft:dirt 1
setblock ~53~1~18 minecraft:torch 5
fill ~54~0~18 ~54~0~22 minecraft:grass
fill ~55~0~18 ~55~0~19 minecraft:podzol
setblock ~56~1~18 minecraft:bamboo 2
setblock ~56~2~18 minecraft:bamboo 2
setblock ~56~3~18 minecraft:bamboo 2
fill ~56~4~18 ~56~10~18 minecraft:bamboo 2
setblock ~56~11~18 minecraft:bamboo 2
fill ~56~12~18 ~56~13~18 minecraft:bamboo 2
setblock ~57~0~18 minecraft:dirt 1
setblock ~58~0~18 minecraft:podzol
setblock ~59~0~18 minecraft:dirt 1
fill ~60~1~18 ~60~7~18 minecraft:bamboo 2
setblock ~60~8~18 minecraft:bamboo 2
fill ~60~9~18 ~60~11~18 minecraft:bamboo 2
setblock ~60~12~18 minecraft:bamboo 2
fill ~60~13~18 ~60~14~18 minecraft:bamboo 2
fill ~61~0~18 ~63~0~18 minecraft:podzol
setblock ~62~1~18 minecraft:bamboo 2
fill ~62~2~18 ~62~11~18 minecraft:bamboo 2
setblock ~62~12~18 minecraft:bamboo 2
setblock ~62~13~18 minecraft:bamboo 2
setblock ~62~14~18 minecraft:bamboo 2
fill ~62~15~18 ~62~16~18 minecraft:bamboo 2
setblock ~63~1~18 minecraft:torch 5
setblock ~64~0~18 minecraft:grass
setblock ~65~0~18 minecraft:dirt_with_roots
fill ~66~0~18 ~67~0~18 minecraft:grass
setblock ~66~1~18 minecraft:red_flower 0
fill ~67~1~18 ~67~2~18 minecraft:bamboo 2
setblock ~67~3~18 minecraft:bamboo 2
fill ~67~4~18 ~67~5~18 minecraft:bamboo 2
setblock ~67~6~18 minecraft:bamboo 2
fill ~67~7~18 ~67~11~18 minecraft:bamboo 2
setblock ~67~12~18 minecraft:bamboo 2
setblock ~67~13~18 minecraft:bamboo 2
fill ~67~14~18 ~67~15~18 minecraft:bamboo 2
setblock ~68~0~18 minecraft:dirt 1
setblock ~69~0~18 minecraft:grass
fill ~70~0~18 ~70~0~19 minecraft:dirt_with_roots
setblock ~72~1~18 minecraft:double_plant 2
setblock ~73~0~18 minecraft:grass_path
setblock ~74~1~18 minecraft:tallgrass 0
setblock ~75~0~18 minecraft:dirt_with_roots
fill ~76~0~18 ~76~0~19 minecraft:podzol
fill ~77~0~18 ~77~0~25 minecraft:grass
setblock ~77~1~18 minecraft:red_flower 3
setblock ~78~0~18 minecraft:podzol
setblock ~79~1~18 minecraft:tallgrass 0
setblock ~80~0~18 minecraft:podzol
setblock ~81~1~18 minecraft:tallgrass 0
fill ~82~0~18 ~83~0~18 minecraft:dirt 1
setblock ~85~0~18 minecraft:dirt_with_roots
setblock ~86~0~18 minecraft:grass_path
setblock ~87~0~18 minecraft:grass
setblock ~88~0~18 minecraft:dirt_with_roots
setblock ~89~4~18 minecraft:wall_banner 4
setblock ~89~5~18 minecraft:lantern 1
setblock ~89~6~18 minecraft:deepslate_tile_stairs 0
fill ~90~3~18 ~90~4~18 minecraft:polished_blackstone_bricks
fill ~92~3~18 ~92~4~18 minecraft:polished_blackstone_bricks
setblock ~93~4~18 minecraft:wall_banner 5
setblock ~93~5~18 minecraft:lantern 1
setblock ~93~6~18 minecraft:deepslate_tile_stairs 1
setblock ~94~1~18 minecraft:double_plant 2
setblock ~95~1~18 minecraft:tallgrass 0
fill ~102~0~18 ~102~0~22 minecraft:grass
setblock ~43~1~19 minecraft:double_plant 2
fill ~44~6~19 ~44~6~20 minecraft:deepslate_tile_stairs 4
setblock ~45~3~19 minecraft:deepslate_tile_stairs 3
setblock ~45~4~19 minecraft:deepslate_tile_stairs 7
setblock ~46~8~19 minecraft:torch 5
setblock ~47~3~19 minecraft:deepslate_tile_stairs 3
setblock ~47~4~19 minecraft:deepslate_tile_stairs 7
fill ~48~6~19 ~48~6~20 minecraft:deepslate_tile_stairs 5
setblock ~49~0~19 minecraft:podzol
setblock ~51~0~19 minecraft:grass
setblock ~51~1~19 minecraft:double_plant 2
setblock ~53~0~19 minecraft:dirt_with_roots
fill ~53~1~19 ~53~2~19 minecraft:bamboo 2
fill ~53~3~19 ~53~4~19 minecraft:bamboo 2
fill ~53~5~19 ~53~9~19 minecraft:bamboo 2
setblock ~53~10~19 minecraft:bamboo 2
setblock ~53~11~19 minecraft:bamboo 2
fill ~53~12~19 ~53~13~19 minecraft:bamboo 2
setblock ~56~0~19 minecraft:podzol
fill ~57~0~19 ~58~0~19 minecraft:grass
setblock ~57~1~19 minecraft:torch 5
fill ~59~0~19 ~62~0~19 minecraft:dirt_with_roots
setblock ~63~0~19 minecraft:grass
setblock ~64~0~19 minecraft:podzol
fill ~64~1~19 ~70~3~19 minecraft:reeds 0
setblock ~65~0~19 minecraft:grass
setblock ~66~0~19 minecraft:dirt 1
fill ~67~0~19 ~68~0~19 minecraft:podzol
setblock ~69~0~19 minecraft:dirt_with_roots
fill ~71~0~19 ~71~0~20 minecraft:grass
setblock ~71~1~19 minecraft:tallgrass 0
setblock ~72~0~19 minecraft:podzol
setblock ~73~0~19 minecraft:grass
setblock ~73~1~19 minecraft:tallgrass 0
fill ~74~0~19 ~74~0~20 minecraft:podzol
fill ~75~0~19 ~75~0~21 minecraft:grass
fill ~77~1~19 ~78~1~19 minecraft:tallgrass 0
fill ~78~0~19 ~78~0~20 minecraft:grass
setblock ~79~0~19 minecraft:grass_path
fill ~80~0~19 ~80~0~20 minecraft:grass
setblock ~81~0~19 minecraft:grass_path
setblock ~82~0~19 minecraft:dirt 1
setblock ~83~0~19 minecraft:grass_path
setblock ~84~0~19 minecraft:dirt_with_roots
setblock ~85~0~19 minecraft:podzol
setblock ~86~0~19 minecraft:dirt_with_roots
setblock ~87~0~19 minecraft:dirt 1
setblock ~88~0~19 minecraft:podzol
fill ~89~6~19 ~89~6~20 minecraft:deepslate_tile_stairs 4
setblock ~90~3~19 minecraft:deepslate_tile_stairs 3
setblock ~90~4~19 minecraft:deepslate_tile_stairs 7
setblock ~92~3~19 minecraft:deepslate_tile_stairs 3
setblock ~92~4~19 minecraft:deepslate_tile_stairs 7
fill ~93~6~19 ~93~6~20 minecraft:deepslate_tile_stairs 5
setblock ~96~1~19 minecraft:red_flower 8
setblock ~99~1~19 minecraft:double_plant 2
fill ~101~1~19 ~102~1~20 minecraft:tallgrass 0
setblock ~43~1~20 minecraft:tallgrass 0
fill ~44~0~20 ~44~0~23 minecraft:sandstone
fill ~45~0~20 ~46~0~21 minecraft:dirt 0
setblock ~45~3~20 minecraft:deepslate_tile_stairs 2
setblock ~45~4~20 minecraft:deepslate_tile_stairs 6
setblock ~47~3~20 minecraft:deepslate_tile_stairs 2
setblock ~47~4~20 minecraft:deepslate_tile_stairs 6
fill ~49~0~20 ~49~0~21 minecraft:grass
setblock ~49~1~20 minecraft:red_flower 8
fill ~51~0~20 ~52~0~20 minecraft:grass_path
setblock ~53~0~20 minecraft:grass
setblock ~55~0~20 minecraft:dirt_with_roots
fill ~56~0~20 ~57~0~20 minecraft:grass
setblock ~58~0~20 minecraft:podzol
fill ~59~0~20 ~60~0~22 minecraft:grass
setblock ~61~0~20 minecraft:dirt_with_roots
fill ~62~0~20 ~63~0~20 minecraft:podzol
fill ~62~1~20 ~63~3~20 minecraft:reeds 0
fill ~64~0~20 ~70~0~34 minecraft:water 0
fill ~71~1~20 ~72~3~20 minecraft:reeds 0
fill ~72~0~20 ~73~0~20 minecraft:dirt_with_roots
fill ~75~1~20 ~75~3~20 minecraft:bamboo 2
fill ~75~4~20 ~75~5~20 minecraft:bamboo 2
fill ~75~6~20 ~75~8~20 minecraft:bamboo 2
setblock ~75~9~20 minecraft:bamboo 2
setblock ~75~10~20 minecraft:bamboo 2
setblock ~75~11~20 minecraft:bamboo 2
setblock ~75~12~20 minecraft:bamboo 2
setblock ~75~13~20 minecraft:bamboo 2
setblock ~76~0~20 minecraft:grass_path
setblock ~77~1~20 minecraft:yellow_flower
setblock ~78~1~20 minecraft:tallgrass 0
setblock ~79~0~20 minecraft:podzol
setblock ~80~1~20 minecraft:bamboo 2
setblock ~80~2~20 minecraft:bamboo 2
fill ~80~3~20 ~80~4~20 minecraft:bamboo 2
setblock ~80~5~20 minecraft:bamboo 2
setblock ~80~6~20 minecraft:bamboo 2
fill ~80~7~20 ~80~8~20 minecraft:bamboo 2
setblock ~80~9~20 minecraft:bamboo 2
setblock ~80~10~20 minecraft:bamboo 2
fill ~80~11~20 ~80~12~20 minecraft:bamboo 2
fill ~81~0~20 ~84~0~20 minecraft:grass
fill ~83~1~20 ~83~1~21 minecraft:tallgrass 0
setblock ~84~1~20 minecraft:double_plant 2
setblock ~85~0~20 minecraft:grass_path
fill ~86~0~20 ~86~0~24 minecraft:grass
setblock ~87~0~20 minecraft:grass_path
fill ~88~0~20 ~88~0~21 minecraft:dirt_with_roots
setblock ~89~5~20 minecraft:torch 4
setblock ~90~3~20 minecraft:deepslate_tile_stairs 2
setblock ~90~4~20 minecraft:deepslate_tile_stairs 6
setblock ~91~8~20 minecraft:torch 5
setblock ~92~3~20 minecraft:deepslate_tile_stairs 2
setblock ~92~4~20 minecraft:deepslate_tile_stairs 6
setblock ~93~5~20 minecraft:torch 4
fill ~94~1~20 ~95~1~20 minecraft:tallgrass 0
setblock ~96~1~20 minecraft:double_plant 2
fill ~97~1~20 ~97~1~22 minecraft:tallgrass 0
setblock ~99~1~20 minecraft:tallgrass 0
setblock ~43~1~21 minecraft:double_plant 2
setblock ~44~4~21 minecraft:wall_banner 4
setblock ~44~5~21 minecraft:lantern 1
setblock ~44~6~21 minecraft:deepslate_tile_stairs 0
fill ~45~3~21 ~45~4~21 minecraft:polished_blackstone_bricks
fill ~47~3~21 ~47~4~21 minecraft:polished_blackstone_bricks
setblock ~48~4~21 minecraft:wall_banner 5
setblock ~48~5~21 minecraft:lantern 1
setblock ~48~6~21 minecraft:deepslate_tile_stairs 1
setblock ~51~0~21 minecraft:grass
setblock ~52~0~21 minecraft:podzol
fill ~52~1~21 ~52~12~21 minecraft:bamboo 2
setblock ~52~13~21 minecraft:bamboo 2
setblock ~52~14~21 minecraft:bamboo 2
setblock ~52~15~21 minecraft:bamboo 2
setblock ~52~16~21 minecraft:bamboo 2
setblock ~53~0~21 minecraft:dirt 1
setblock ~54~1~21 minecraft:double_plant 2
setblock ~55~0~21 minecraft:podzol
setblock ~55~1~21 minecraft:torch 5
setblock ~56~0~21 minecraft:dirt_with_roots
fill ~57~0~21 ~58~0~21 minecraft:grass
fill ~58~1~21 ~58~7~21 minecraft:bamboo 2
fill ~58~8~21 ~58~9~21 minecraft:bamboo 2
fill ~58~10~21 ~58~11~21 minecraft:bamboo 2
setblock ~58~12~21 minecraft:bamboo 2
fill ~58~13~21 ~58~14~21 minecraft:bamboo 2
setblock ~61~0~21 minecraft:grass
fill ~61~1~21 ~61~3~21 minecraft:reeds 0
fill ~62~0~21 ~63~0~39 minecraft:water 0
setblock ~69~1~21 minecraft:torch 5
fill ~71~0~21 ~72~0~35 minecraft:water 0
setblock ~73~0~21 minecraft:grass
fill ~73~1~21 ~73~3~21 minecraft:reeds 0
setblock ~74~0~21 minecraft:dirt 1
setblock ~76~0~21 minecraft:podzol
fill ~77~1~21 ~77~1~23 minecraft:tallgrass 0
setblock ~78~0~21 minecraft:grass_path
setblock ~79~0~21 minecraft:dirt 1
fill ~80~0~21 ~81~0~21 minecraft:podzol
fill ~82~0~21 ~82~0~22 minecraft:grass_path
setblock ~83~0~21 minecraft:grass
setblock ~84~0~21 minecraft:grass_path
setblock ~85~0~21 minecraft:dirt_with_roots
fill ~85~1~21 ~85~2~21 minecraft:bamboo 2
fill ~85~3~21 ~85~4~21 minecraft:bamboo 2
fill ~85~5~21 ~85~7~21 minecraft:bamboo 2
setblock ~85~8~21 minecraft:bamboo 2
fill ~85~9~21 ~85~11~21 minecraft:bamboo 2
setblock ~85~12~21 minecraft:bamboo 2
fill ~85~13~21 ~85~14~21 minecraft:bamboo 2
fill ~87~0~21 ~87~0~27 minecraft:grass
fill ~89~1~21 ~90~6~21 minecraft:quartz_block 2
setblock ~89~8~21 minecraft:quartz_block 2
setblock ~90~7~21 minecraft:quartz_block 2
fill ~92~1~21 ~93~6~21 minecraft:quartz_block 2
setblock ~92~7~21 minecraft:quartz_block 2
setblock ~93~8~21 minecraft:quartz_block 2
fill ~94~1~21 ~94~1~24 minecraft:tallgrass 0
setblock ~95~1~21 minecraft:double_plant 2
fill ~96~1~21 ~96~1~22 minecraft:tallgrass 0
fill ~99~1~21 ~101~1~21 minecraft:double_plant 2
setblock ~102~1~21 minecraft:tallgrass 0
fill ~43~1~22 ~43~1~23 minecraft:tallgrass 0
fill ~44~6~22 ~44~6~23 minecraft:deepslate_tile_stairs 4
setblock ~45~0~22 minecraft:sandstone
setblock ~45~3~22 minecraft:deepslate_tile_stairs 3
setblock ~45~4~22 minecraft:deepslate_tile_stairs 7
fill ~46~0~22 ~46~0~47 minecraft:dirt 0
setblock ~47~3~22 minecraft:deepslate_tile_stairs 3
setblock ~47~4~22 minecraft:deepslate_tile_stairs 7
fill ~48~6~22 ~48~6~23 minecraft:deepslate_tile_stairs 5
setblock ~49~0~22 minecraft:dirt_with_roots
fill ~50~0~22 ~50~0~23 minecraft:podzol
fill ~51~0~22 ~51~0~23 minecraft:grass_path
fill ~52~0~22 ~53~0~22 minecraft:grass
setblock ~53~1~22 minecraft:torch 5
fill ~54~1~22 ~55~1~22 minecraft:tallgrass 0
fill ~55~0~22 ~55~0~23 minecraft:grass
fill ~56~0~22 ~56~0~24 minecraft:podzol
setblock ~57~0~22 minecraft:dirt 1
fill ~58~0~22 ~58~0~24 minecraft:grass
fill ~60~1~22 ~60~3~22 minecraft:reeds 0
fill ~61~0~22 ~61~0~38 minecraft:water 0
fill ~73~0~22 ~73~0~38 minecraft:water 0
setblock ~74~0~22 minecraft:podzol
fill ~74~1~22 ~74~3~22 minecraft:reeds 0
setblock ~75~0~22 minecraft:dirt_with_roots
fill ~76~0~22 ~76~0~24 minecraft:grass
setblock ~78~0~22 minecraft:grass
setblock ~78~1~22 minecraft:double_plant 2
fill ~79~0~22 ~79~0~23 minecraft:podzol
setblock ~80~0~22 minecraft:grass_path
setblock ~80~1~22 minecraft:torch 5
setblock ~81~0~22 minecraft:podzol
setblock ~83~0~22 minecraft:dirt_with_roots
setblock ~84~0~22 minecraft:grass
setblock ~85~0~22 minecraft:dirt 1
setblock ~88~0~22 minecraft:grass_path
fill ~89~1~22 ~89~1~29 minecraft:deepslate_tile_stairs 0
fill ~89~2~22 ~89~2~29 minecraft:iron_bars
setblock ~89~5~22 minecraft:torch 3
fill ~89~6~22 ~89~6~23 minecraft:deepslate_tile_stairs 4
fill ~89~8~22 ~89~8~29 minecraft:quartz_stairs 0
fill ~90~1~22 ~90~2~29 minecraft:polished_blackstone_bricks
setblock ~90~3~22 minecraft:deepslate_tile_stairs 3
setblock ~90~4~22 minecraft:deepslate_tile_stairs 7
fill ~90~5~22 ~90~7~29 minecraft:polished_blackstone_bricks
fill ~92~1~22 ~92~2~29 minecraft:polished_blackstone_bricks
setblock ~92~3~22 minecraft:deepslate_tile_stairs 3
setblock ~92~4~22 minecraft:deepslate_tile_stairs 7
fill ~92~5~22 ~92~7~29 minecraft:polished_blackstone_bricks
fill ~93~1~22 ~93~1~29 minecraft:deepslate_tile_stairs 1
fill ~93~2~22 ~93~2~29 minecraft:iron_bars
setblock ~93~5~22 minecraft:torch 3
fill ~93~6~22 ~93~6~23 minecraft:deepslate_tile_stairs 5
fill ~93~8~22 ~93~8~29 minecraft:quartz_stairs 1
setblock ~95~1~22 minecraft:tallgrass 0
fill ~99~1~22 ~100~1~22 minecraft:tallgrass 0
setblock ~44~5~23 minecraft:torch 4
fill ~45~0~23 ~45~0~29 minecraft:dirt 0
setblock ~45~3~23 minecraft:deepslate_tile_stairs 2
setblock ~45~4~23 minecraft:deepslate_tile_stairs 6
setblock ~47~3~23 minecraft:deepslate_tile_stairs 2
setblock ~47~4~23 minecraft:deepslate_tile_stairs 6
setblock ~48~5~23 minecraft:torch 4
setblock ~49~0~23 minecraft:podzol
fill ~52~0~23 ~52~0~25 minecraft:grass
setblock ~53~0~23 minecraft:dirt_with_roots
setblock ~54~0~23 minecraft:grass_path
setblock ~55~1~23 minecraft:double_plant 2
setblock ~57~0~23 minecraft:dirt_with_roots
setblock ~59~0~23 minecraft:dirt_with_roots
fill ~59~1~23 ~59~3~23 minecraft:reeds 0
fill ~60~0~23 ~60~0~37 minecraft:water 0
setblock ~62~1~23 minecraft:torch 5
fill ~74~0~23 ~74~0~37 minecraft:water 0
setblock ~74~1~23 minecraft:torch 5
setblock ~75~0~23 minecraft:grass
fill ~75~1~23 ~75~3~23 minecraft:reeds 0
setblock ~78~0~23 minecraft:podzol
setblock ~80~0~23 minecraft:dirt_with_roots
fill ~81~0~23 ~83~0~23 minecraft:grass
fill ~81~1~23 ~82~1~23 minecraft:double_plant 2
setblock ~84~0~23 minecraft:podzol
setblock ~85~0~23 minecraft:dirt_with_roots
setblock ~88~0~23 minecraft:podzol
setblock ~90~3~23 minecraft:deepslate_tile_stairs 2
setblock ~90~4~23 minecraft:deepslate_tile_stairs 6
setblock ~92~3~23 minecraft:deepslate_tile_stairs 2
setblock ~92~4~23 minecraft:deepslate_tile_stairs 6
fill ~95~1~23 ~96~1~23 minecraft:double_plant 2
setblock ~97~1~23 minecraft:red_flower 0
setblock ~98~1~23 minecraft:yellow_flower
setblock ~99~1~23 minecraft:red_flower 9
fill ~100~1~23 ~101~1~23 minecraft:tallgrass 0
setblock ~43~1~24 minecraft:double_plant 2
fill ~44~0~24 ~44~0~27 minecraft:dirt 0
fill ~44~1~24 ~45~6~24 minecraft:quartz_block 2
setblock ~44~8~24 minecraft:quartz_block 2
setblock ~45~7~24 minecraft:quartz_block 2
fill ~47~1~24 ~48~6~24 minecraft:quartz_block 2
setblock ~47~7~24 minecraft:quartz_block 2
setblock ~48~8~24 minecraft:quartz_block 2
fill ~49~0~24 ~50~0~24 minecraft:dirt_with_roots
fill ~51~0~24 ~51~0~25 minecraft:grass
setblock ~53~0~24 minecraft:dirt 1
fill ~54~0~24 ~54~0~28 minecraft:grass
fill ~54~1~24 ~54~1~26 minecraft:tallgrass 0
setblock ~55~0~24 minecraft:dirt 1
setblock ~57~0~24 minecraft:grass
fill ~58~1~24 ~58~3~24 minecraft:reeds 0
fill ~59~0~24 ~59~0~36 minecraft:water 0
fill ~75~0~24 ~75~0~36 minecraft:water 0
fill ~76~1~24 ~76~3~24 minecraft:reeds 0
setblock ~78~0~24 minecraft:dirt 1
setblock ~79~0~24 minecraft:grass
setblock ~79~1~24 minecraft:torch 5
setblock ~80~0~24 minecraft:podzol
fill ~81~0~24 ~81~0~25 minecraft:grass
setblock ~82~0~24 minecraft:dirt_with_roots
fill ~83~0~24 ~83~0~25 minecraft:podzol
fill ~84~0~24 ~85~0~24 minecraft:grass
setblock ~84~1~24 minecraft:torch 5
fill ~86~1~24 ~86~2~24 minecraft:bamboo 2
setblock ~86~3~24 minecraft:bamboo 2
setblock ~86~4~24 minecraft:bamboo 2
fill ~86~5~24 ~86~9~24 minecraft:bamboo 2
setblock ~86~10~24 minecraft:bamboo 2
setblock ~86~11~24 minecraft:bamboo 2
setblock ~86~12~24 minecraft:bamboo 2
fill ~88~0~24 ~88~0~25 minecraft:grass
setblock ~89~4~24 minecraft:wall_banner 4
setblock ~89~5~24 minecraft:lantern 1
setblock ~89~6~24 minecraft:deepslate_tile_stairs 0
fill ~90~3~24 ~90~4~24 minecraft:polished_blackstone_bricks
fill ~92~3~24 ~92~4~24 minecraft:polished_blackstone_bricks
setblock ~93~4~24 minecraft:wall_banner 5
setblock ~93~5~24 minecraft:lantern 1
setblock ~93~6~24 minecraft:deepslate_tile_stairs 1
fill ~95~1~24 ~96~1~24 minecraft:tallgrass 0
fill ~98~1~24 ~99~1~24 minecraft:tallgrass 0
setblock ~100~1~24 minecraft:red_flower 0
setblock ~101~1~24 minecraft:tallgrass 0
fill ~44~1~25 ~44~1~32 minecraft:deepslate_tile_stairs 0
fill ~44~2~25 ~44~2~32 minecraft:iron_bars
setblock ~44~5~25 minecraft:torch 3
fill ~44~6~25 ~44~6~26 minecraft:deepslate_tile_stairs 4
fill ~44~8~25 ~44~8~32 minecraft:quartz_stairs 0
fill ~45~1~25 ~45~2~32 minecraft:polished_blackstone_bricks
setblock ~45~3~25 minecraft:deepslate_tile_stairs 3
setblock ~45~4~25 minecraft:deepslate_tile_stairs 7
fill ~45~5~25 ~45~7~32 minecraft:polished_blackstone_bricks
fill ~47~1~25 ~47~2~32 minecraft:polished_blackstone_bricks
setblock ~47~3~25 minecraft:deepslate_tile_stairs 3
setblock ~47~4~25 minecraft:deepslate_tile_stairs 7
fill ~47~5~25 ~47~7~32 minecraft:polished_blackstone_bricks
fill ~48~1~25 ~48~1~32 minecraft:deepslate_tile_stairs 1
fill ~48~2~25 ~48~2~32 minecraft:iron_bars
setblock ~48~5~25 minecraft:torch 3
fill ~48~6~25 ~48~6~26 minecraft:deepslate_tile_stairs 5
fill ~48~8~25 ~48~8~32 minecraft:quartz_stairs 1
fill ~49~0~25 ~49~0~26 minecraft:grass
setblock ~50~0~25 minecraft:dirt 1
setblock ~53~0~25 minecraft:podzol
setblock ~55~0~25 minecraft:podzol
setblock ~56~0~25 minecraft:grass_path
fill ~57~0~25 ~57~0~26 minecraft:dirt 1
fill ~57~1~25 ~57~3~26 minecraft:reeds 0
fill ~58~0~25 ~58~0~35 minecraft:water 0
setblock ~68~1~25 minecraft:torch 5
fill ~76~0~25 ~76~0~35 minecraft:water 0
fill ~77~1~25 ~77~3~26 minecraft:reeds 0
setblock ~78~0~25 minecraft:grass
setblock ~79~0~25 minecraft:dirt 1
setblock ~80~0~25 minecraft:dirt_with_roots
setblock ~81~1~25 minecraft:red_flower 9
fill ~82~0~25 ~82~0~26 minecraft:podzol
setblock ~83~1~25 minecraft:torch 5
fill ~84~0~25 ~84~0~27 minecraft:grass
setblock ~85~0~25 minecraft:grass_path
setblock ~85~1~25 minecraft:torch 5
setblock ~86~0~25 minecraft:podzol
setblock ~88~1~25 minecraft:torch 5
fill ~89~6~25 ~89~6~26 minecraft:deepslate_tile_stairs 4
setblock ~90~3~25 minecraft:deepslate_tile_stairs 3
setblock ~90~4~25 minecraft:deepslate_tile_stairs 7
setblock ~92~3~25 minecraft:deepslate_tile_stairs 3
setblock ~92~4~25 minecraft:deepslate_tile_stairs 7
fill ~93~6~25 ~93~6~26 minecraft:deepslate_tile_stairs 5
fill ~94~1~25 ~95~1~25 minecraft:double_plant 2
setblock ~96~1~25 minecraft:red_flower 8
setblock ~98~1~25 minecraft:red_flower 3
fill ~99~1~25 ~99~1~32 minecraft:tallgrass 0
setblock ~101~0~25 minecraft:tallgrass 0
setblock ~43~1~26 minecraft:tallgrass 0
setblock ~45~3~26 minecraft:deepslate_tile_stairs 2
setblock ~45~4~26 minecraft:deepslate_tile_stairs 6
setblock ~47~3~26 minecraft:deepslate_tile_stairs 2
setblock ~47~4~26 minecraft:deepslate_tile_stairs 6
fill ~50~0~26 ~51~0~26 minecraft:podzol
setblock ~52~0~26 minecraft:grass_path
setblock ~53~0~26 minecraft:grass
fill ~53~1~26 ~53~2~26 minecraft:bamboo 2
fill ~53~3~26 ~53~4~26 minecraft:bamboo 2
fill ~53~5~26 ~53~7~26 minecraft:bamboo 2
setblock ~53~8~26 minecraft:bamboo 2
setblock ~53~9~26 minecraft:bamboo 2
setblock ~53~10~26 minecraft:bamboo 2
fill ~53~11~26 ~53~12~26 minecraft:bamboo 2
setblock ~55~0~26 minecraft:dirt_with_roots
fill ~56~0~26 ~56~0~27 minecraft:podzol
setblock ~67~1~26 minecraft:torch 5
setblock ~77~0~26 minecraft:dirt 1
setblock ~78~0~26 minecraft:grass_path
setblock ~78~1~26 minecraft:torch 5
setblock ~79~0~26 minecraft:dirt_with_roots
fill ~80~0~26 ~80~0~27 minecraft:grass
setblock ~80~1~26 minecraft:tallgrass 0
setblock ~81~0~26 minecraft:grass_path
setblock ~83~0~26 minecraft:dirt_with_roots
setblock ~85~0~26 minecraft:grass
setblock ~86~0~26 minecraft:dirt_with_roots
setblock ~88~0~26 minecraft:dirt_with_roots
setblock ~90~3~26 minecraft:deepslate_tile_stairs 2
setblock ~90~4~26 minecraft:deepslate_tile_stairs 6
setblock ~92~3~26 minecraft:deepslate_tile_stairs 2
setblock ~92~4~26 minecraft:deepslate_tile_stairs 6
setblock ~94~1~26 minecraft:double_plant 2
setblock ~95~1~26 minecraft:yellow_flower
fill ~96~1~26 ~96~1~27 minecraft:tallgrass 0
setblock ~97~1~26 minecraft:double_plant 2
setblock ~98~1~26 minecraft:tallgrass 0
setblock ~100~1~26 minecraft:tallgrass 0
setblock ~42~0~27 minecraft:grass
setblock ~42~1~27 minecraft:tallgrass 0
setblock ~43~1~27 minecraft:double_plant 2
setblock ~44~4~27 minecraft:wall_banner 4
setblock ~44~5~27 minecraft:lantern 1
setblock ~44~6~27 minecraft:deepslate_tile_stairs 0
fill ~45~3~27 ~45~4~27 minecraft:polished_blackstone_bricks
setblock ~46~8~27 minecraft:torch 5
fill ~47~3~27 ~47~4~27 minecraft:polished_blackstone_bricks
setblock ~48~4~27 minecraft:wall_banner 5
setblock ~48~5~27 minecraft:lantern 1
setblock ~48~6~27 minecraft:deepslate_tile_stairs 1
setblock ~49~0~27 minecraft:podzol
setblock ~50~0~27 minecraft:dirt 1
setblock ~51~0~27 minecraft:dirt_with_roots
setblock ~52~0~27 minecraft:grass
setblock ~52~1~27 minecraft:torch 5
setblock ~53~0~27 minecraft:podzol
setblock ~54~1~27 minecraft:double_plant 2
setblock ~55~0~27 minecraft:grass
setblock ~55~1~27 minecraft:tallgrass 0
fill ~56~1~27 ~56~3~33 minecraft:reeds 0
fill ~57~0~27 ~57~0~33 minecraft:water 0
fill ~77~0~27 ~77~0~33 minecraft:water 0
fill ~78~0~27 ~79~0~27 minecraft:podzol
fill ~78~1~27 ~78~3~33 minecraft:reeds 0
setblock ~80~1~27 minecraft:double_plant 2
setblock ~81~0~27 minecraft:grass
setblock ~81~1~27 minecraft:torch 5
setblock ~82~0~27 minecraft:dirt_with_roots
setblock ~83~0~27 minecraft:grass_path
setblock ~85~0~27 minecraft:podzol
setblock ~86~0~27 minecraft:grass
setblock ~88~0~27 minecraft:podzol
setblock ~89~4~27 minecraft:wall_banner 4
setblock ~89~5~27 minecraft:lantern 1
setblock ~89~6~27 minecraft:deepslate_tile_stairs 0
fill ~90~3~27 ~90~4~27 minecraft:polished_blackstone_bricks
fill ~92~3~27 ~92~4~27 minecraft:polished_blackstone_bricks
setblock ~93~4~27 minecraft:wall_banner 5
setblock ~93~5~27 minecraft:lantern 1
setblock ~93~6~27 minecraft:deepslate_tile_stairs 1
fill ~94~1~27 ~95~1~27 minecraft:tallgrass 0
fill ~97~1~27 ~97~1~30 minecraft:tallgrass 0
fill ~44~6~28 ~44~6~29 minecraft:deepslate_tile_stairs 4
setblock ~45~3~28 minecraft:deepslate_tile_stairs 3
setblock ~45~4~28 minecraft:deepslate_tile_stairs 7
setblock ~47~3~28 minecraft:deepslate_tile_stairs 3
setblock ~47~4~28 minecraft:deepslate_tile_stairs 7
fill ~48~6~28 ~48~6~29 minecraft:deepslate_tile_stairs 5
setblock ~49~0~28 minecraft:dirt 1
fill ~50~0~28 ~50~0~29 minecraft:grass_path
setblock ~51~0~28 minecraft:grass
setblock ~51~1~28 minecraft:torch 5
setblock ~52~0~28 minecraft:grass_path
setblock ~53~0~28 minecraft:grass
fill ~53~1~28 ~54~1~28 minecraft:tallgrass 0
setblock ~55~0~28 minecraft:podzol
setblock ~56~0~28 minecraft:dirt 1
setblock ~78~0~28 minecraft:grass
fill ~79~0~28 ~79~0~29 minecraft:dirt 1
setblock ~80~0~28 minecraft:grass_path
setblock ~81~0~28 minecraft:dirt 1
fill ~82~0~28 ~82~0~29 minecraft:grass
setblock ~83~0~28 minecraft:dirt 1
setblock ~83~1~28 minecraft:torch 5
setblock ~84~0~28 minecraft:dirt_with_roots
fill ~84~1~28 ~84~3~28 minecraft:bamboo 2
setblock ~84~4~28 minecraft:bamboo 2
fill ~84~5~28 ~84~6~28 minecraft:bamboo 2
setblock ~84~7~28 minecraft:bamboo 2
setblock ~84~8~28 minecraft:bamboo 2
setblock ~84~9~28 minecraft:bamboo 2
setblock ~84~10~28 minecraft:bamboo 2
setblock ~84~11~28 minecraft:bamboo 2
fill ~84~12~28 ~84~13~28 minecraft:bamboo 2
fill ~85~0~28 ~86~0~28 minecraft:grass_path
fill ~87~0~28 ~87~0~29 minecraft:dirt 1
setblock ~88~0~28 minecraft:grass
fill ~89~6~28 ~89~6~29 minecraft:deepslate_tile_stairs 4
setblock ~90~3~28 minecraft:deepslate_tile_stairs 3
setblock ~90~4~28 minecraft:deepslate_tile_stairs 7
setblock ~92~3~28 minecraft:deepslate_tile_stairs 3
setblock ~92~4~28 minecraft:deepslate_tile_stairs 7
fill ~93~6~28 ~93~6~29 minecraft:deepslate_tile_stairs 5
setblock ~94~1~28 minecraft:red_flower 0
fill ~95~1~28 ~96~1~28 minecraft:double_plant 2
setblock ~98~1~28 minecraft:tallgrass 0
setblock ~100~1~28 minecraft:yellow_flower
fill ~40~0~29 ~40~0~42 minecraft:grass
setblock ~45~3~29 minecraft:deepslate_tile_stairs 2
setblock ~45~4~29 minecraft:deepslate_tile_stairs 6
setblock ~47~3~29 minecraft:deepslate_tile_stairs 2
setblock ~47~4~29 minecraft:deepslate_tile_stairs 6
fill ~49~0~29 ~49~0~30 minecraft:grass
setblock ~51~0~29 minecraft:podzol
fill ~52~0~29 ~52~0~30 minecraft:grass
setblock ~52~1~29 minecraft:tallgrass 0
fill ~53~0~29 ~54~0~29 minecraft:podzol
fill ~54~1~29 ~54~7~29 minecraft:bamboo 2
setblock ~54~8~29 minecraft:bamboo 2
fill ~54~9~29 ~54~11~29 minecraft:bamboo 2
setblock ~54~12~29 minecraft:bamboo 2
fill ~54~13~29 ~54~14~29 minecraft:bamboo 2
setblock ~55~0~29 minecraft:grass
setblock ~56~0~29 minecraft:podzol
setblock ~66~1~29 minecraft:torch 5
setblock ~78~0~29 minecraft:dirt_with_roots
setblock ~80~0~29 minecraft:podzol
setblock ~81~0~29 minecraft:grass
setblock ~81~1~29 minecraft:double_plant 2
fill ~83~0~29 ~84~0~30 minecraft:grass
setblock ~85~0~29 minecraft:dirt 1
fill ~86~0~29 ~86~0~32 minecraft:grass
setblock ~88~0~29 minecraft:podzol
setblock ~89~5~29 minecraft:torch 4
setblock ~90~3~29 minecraft:deepslate_tile_stairs 2
setblock ~90~4~29 minecraft:deepslate_tile_stairs 6
setblock ~91~8~29 minecraft:torch 5
setblock ~92~3~29 minecraft:deepslate_tile_stairs 2
setblock ~92~4~29 minecraft:deepslate_tile_stairs 6
setblock ~93~5~29 minecraft:torch 4
setblock ~94~1~29 minecraft:tallgrass 0
fill ~95~1~29 ~95~1~30 minecraft:double_plant 2
setblock ~96~1~29 minecraft:red_flower 3
fill ~98~1~29 ~98~1~30 minecraft:red_flower 3
fill ~32~0~30 ~33~0~42 minecraft:grass
fill ~37~0~30 ~39~0~42 minecraft:grass
setblock ~38~1~30 minecraft:tallgrass 0
fill ~41~0~30 ~42~0~42 minecraft:grass
fill ~41~1~30 ~42~1~30 minecraft:double_plant 2
setblock ~44~4~30 minecraft:wall_banner 4
setblock ~44~5~30 minecraft:lantern 1
setblock ~44~6~30 minecraft:deepslate_tile_stairs 0
fill ~45~3~30 ~45~4~30 minecraft:polished_blackstone_bricks
fill ~47~3~30 ~47~4~30 minecraft:polished_blackstone_bricks
setblock ~48~4~30 minecraft:wall_banner 5
setblock ~48~5~30 minecraft:lantern 1
setblock ~48~6~30 minecraft:deepslate_tile_stairs 1
setblock ~50~0~30 minecraft:dirt 1
setblock ~51~0~30 minecraft:grass
setblock ~51~1~30 minecraft:tallgrass 0
setblock ~52~1~30 minecraft:double_plant 2
fill ~53~0~30 ~53~0~31 minecraft:grass
setblock ~53~1~30 minecraft:tallgrass 0
setblock ~54~0~30 minecraft:dirt 1
setblock ~55~0~30 minecraft:grass_path
fill ~56~0~30 ~56~0~32 minecraft:grass
setblock ~59~1~30 minecraft:torch 5
setblock ~78~0~30 minecraft:podzol
fill ~79~0~30 ~80~0~30 minecraft:grass
setblock ~79~1~30 minecraft:tallgrass 0
setblock ~80~1~30 minecraft:double_plant 2
setblock ~81~0~30 minecraft:grass_path
setblock ~82~0~30 minecraft:podzol
setblock ~85~0~30 minecraft:grass
fill ~87~0~30 ~87~0~32 minecraft:podzol
fill ~88~0~30 ~88~0~33 minecraft:grass
fill ~89~1~30 ~90~6~30 minecraft:quartz_block 2
setblock ~89~8~30 minecraft:quartz_block 2
setblock ~90~7~30 minecraft:quartz_block 2
fill ~92~1~30 ~93~6~30 minecraft:quartz_block 2
setblock ~92~7~30 minecraft:quartz_block 2
setblock ~93~8~30 minecraft:quartz_block 2
setblock ~94~1~30 minecraft:double_plant 2
setblock ~96~1~30 minecraft:tallgrass 0
fill ~31~0~31 ~31~0~42 minecraft:grass
fill ~34~0~31 ~36~0~42 minecraft:grass
fill ~41~1~31 ~41~1~37 minecraft:tallgrass 0
setblock ~42~1~31 minecraft:red_flower 8
fill ~43~0~31 ~43~0~42 minecraft:grass
fill ~43~1~31 ~43~1~32 minecraft:tallgrass 0
fill ~44~6~31 ~44~6~32 minecraft:deepslate_tile_stairs 4
fill ~45~0~31 ~45~0~47 minecraft:dirt 0
setblock ~45~3~31 minecraft:deepslate_tile_stairs 3
setblock ~45~4~31 minecraft:deepslate_tile_stairs 7
setblock ~47~3~31 minecraft:deepslate_tile_stairs 3
setblock ~47~4~31 minecraft:deepslate_tile_stairs 7
fill ~48~6~31 ~48~6~32 minecraft:deepslate_tile_stairs 5
setblock ~49~0~31 minecraft:dirt 1
fill ~50~0~31 ~50~0~34 minecraft:grass
fill ~51~0~31 ~52~0~31 minecraft:podzol
setblock ~53~1~31 minecraft:yellow_flower
fill ~54~0~31 ~55~0~31 minecraft:grass
setblock ~54~1~31 minecraft:tallgrass 0
setblock ~67~1~31 minecraft:torch 5
setblock ~78~0~31 minecraft:grass
fill ~79~0~31 ~79~0~32 minecraft:podzol
fill ~80~0~31 ~81~0~33 minecraft:grass
setblock ~81~1~31 minecraft:yellow_flower
fill ~82~0~31 ~83~0~31 minecraft:dirt_with_roots
fill ~82~1~31 ~82~2~31 minecraft:bamboo 2
setblock ~82~3~31 minecraft:bamboo 2
fill ~82~4~31 ~82~10~31 minecraft:bamboo 2
setblock ~82~11~31 minecraft:bamboo 2
fill ~82~12~31 ~82~13~31 minecraft:bamboo 2
setblock ~82~14~31 minecraft:bamboo 2
fill ~82~15~31 ~82~16~31 minecraft:bamboo 2
setblock ~84~0~31 minecraft:grass
setblock ~85~0~31 minecraft:dirt_with_roots
setblock ~87~1~31 minecraft:torch 5
fill ~89~1~31 ~89~1~38 minecraft:deepslate_tile_stairs 0
fill ~89~2~31 ~89~2~38 minecraft:iron_bars
setblock ~89~5~31 minecraft:torch 3
fill ~89~6~31 ~89~6~32 minecraft:deepslate_tile_stairs 4
fill ~89~8~31 ~89~8~38 minecraft:quartz_stairs 0
fill ~90~1~31 ~90~2~38 minecraft:polished_blackstone_bricks
setblock ~90~3~31 minecraft:deepslate_tile_stairs 3
setblock ~90~4~31 minecraft:deepslate_tile_stairs 7
fill ~90~5~31 ~90~7~38 minecraft:polished_blackstone_bricks
fill ~92~1~31 ~92~2~38 minecraft:polished_blackstone_bricks
setblock ~92~3~31 minecraft:deepslate_tile_stairs 3
setblock ~92~4~31 minecraft:deepslate_tile_stairs 7
fill ~92~5~31 ~92~7~38 minecraft:polished_blackstone_bricks
fill ~93~1~31 ~93~1~38 minecraft:deepslate_tile_stairs 1
fill ~93~2~31 ~93~2~38 minecraft:iron_bars
setblock ~93~5~31 minecraft:torch 3
fill ~93~6~31 ~93~6~32 minecraft:deepslate_tile_stairs 5
fill ~93~8~31 ~93~8~38 minecraft:quartz_stairs 1
fill ~94~1~31 ~94~1~32 minecraft:tallgrass 0
fill ~96~1~31 ~97~1~31 minecraft:double_plant 2
fill ~98~1~31 ~98~1~33 minecraft:tallgrass 0
fill ~30~0~32 ~30~0~42 minecraft:grass
fill ~42~1~32 ~42~1~35 minecraft:double_plant 2
fill ~44~0~32 ~44~0~47 minecraft:dirt 0
setblock ~44~5~32 minecraft:torch 4
setblock ~45~3~32 minecraft:deepslate_tile_stairs 2
setblock ~45~4~32 minecraft:deepslate_tile_stairs 6
setblock ~47~3~32 minecraft:deepslate_tile_stairs 2
setblock ~47~4~32 minecraft:deepslate_tile_stairs 6
setblock ~48~5~32 minecraft:torch 4
fill ~49~0~32 ~49~0~34 minecraft:grass
fill ~51~0~32 ~52~0~32 minecraft:grass_path
setblock ~52~1~32 minecraft:torch 5
fill ~53~0~32 ~53~0~33 minecraft:dirt_with_roots
setblock ~54~0~32 minecraft:podzol
setblock ~55~0~32 minecraft:dirt_with_roots
setblock ~58~1~32 minecraft:torch 5
setblock ~74~1~32 minecraft:torch 5
setblock ~78~0~32 minecraft:podzol
fill ~80~1~32 ~81~1~32 minecraft:tallgrass 0
setblock ~82~0~32 minecraft:podzol
setblock ~83~0~32 minecraft:grass
fill ~84~0~32 ~85~0~32 minecraft:podzol
setblock ~84~1~32 minecraft:torch 5
setblock ~90~3~32 minecraft:deepslate_tile_stairs 2
setblock ~90~4~32 minecraft:deepslate_tile_stairs 6
setblock ~92~3~32 minecraft:deepslate_tile_stairs 2
setblock ~92~4~32 minecraft:deepslate_tile_stairs 6
setblock ~95~1~32 minecraft:tallgrass 0
setblock ~96~1~32 minecraft:double_plant 2
setblock ~97~1~32 minecraft:red_flower 9
fill ~4~0~33 ~4~0~34 minecraft:sandstone
fill ~29~0~33 ~29~0~38 minecraft:grass
fill ~39~1~33 ~40~1~34 minecraft:tallgrass 0
fill ~43~1~33 ~43~1~34 minecraft:double_plant 2
fill ~44~1~33 ~45~6~33 minecraft:quartz_block 2
setblock ~44~8~33 minecraft:quartz_block 2
setblock ~45~7~33 minecraft:quartz_block 2
fill ~47~1~33 ~48~6~33 minecraft:quartz_block 2
setblock ~47~7~33 minecraft:quartz_block 2
setblock ~48~8~33 minecraft:quartz_block 2
setblock ~51~0~33 minecraft:podzol
fill ~52~0~33 ~52~0~34 minecraft:grass
setblock ~54~0~33 minecraft:grass_path
fill ~55~0~33 ~55~0~34 minecraft:grass
setblock ~55~1~33 minecraft:tallgrass 0
setblock ~56~0~33 minecraft:podzol
setblock ~78~0~33 minecraft:dirt_with_roots
fill ~79~0~33 ~79~0~38 minecraft:grass
fill ~81~1~33 ~82~1~33 minecraft:tallgrass 0
setblock ~82~0~33 minecraft:grass
setblock ~83~0~33 minecraft:grass_path
fill ~84~0~33 ~85~0~33 minecraft:grass
setblock ~86~0~33 minecraft:podzol
fill ~86~1~33 ~86~1~34 minecraft:torch 5
setblock ~87~0~33 minecraft:grass
setblock ~89~4~33 minecraft:wall_banner 4
setblock ~89~5~33 minecraft:lantern 1
setblock ~89~6~33 minecraft:deepslate_tile_stairs 0
fill ~90~3~33 ~90~4~33 minecraft:polished_blackstone_bricks
fill ~92~3~33 ~92~4~33 minecraft:polished_blackstone_bricks
setblock ~93~4~33 minecraft:wall_banner 5
setblock ~93~5~33 minecraft:lantern 1
setblock ~93~6~33 minecraft:deepslate_tile_stairs 1
setblock ~95~1~33 minecraft:double_plant 2
fill ~96~1~33 ~97~1~33 minecraft:tallgrass 0
fill ~0~0~34 ~3~0~34 minecraft:sandstone
fill ~5~0~34 ~6~0~38 minecraft:grass
fill ~28~0~34 ~28~0~36 minecraft:grass
setblock ~38~1~34 minecraft:tallgrass 0
fill ~44~1~34 ~44~1~41 minecraft:deepslate_tile_stairs 0
fill ~44~2~34 ~44~2~41 minecraft:iron_bars
setblock ~44~5~34 minecraft:torch 3
fill ~44~6~34 ~44~6~35 minecraft:deepslate_tile_stairs 4
fill ~44~8~34 ~44~8~41 minecraft:quartz_stairs 0
fill ~45~1~34 ~45~2~41 minecraft:polished_blackstone_bricks
setblock ~45~3~34 minecraft:deepslate_tile_stairs 3
setblock ~45~4~34 minecraft:deepslate_tile_stairs 7
fill ~45~5~34 ~45~7~41 minecraft:polished_blackstone_bricks
setblock ~46~8~34 minecraft:torch 5
fill ~47~1~34 ~47~2~41 minecraft:polished_blackstone_bricks
setblock ~47~3~34 minecraft:deepslate_tile_stairs 3
setblock ~47~4~34 minecraft:deepslate_tile_stairs 7
fill ~47~5~34 ~47~7~41 minecraft:polished_blackstone_bricks
fill ~48~1~34 ~48~1~41 minecraft:deepslate_tile_stairs 1
fill ~48~2~34 ~48~2~41 minecraft:iron_bars
setblock ~48~5~34 minecraft:torch 3
fill ~48~6~34 ~48~6~35 minecraft:deepslate_tile_stairs 5
fill ~48~8~34 ~48~8~41 minecraft:quartz_stairs 1
setblock ~50~1~34 minecraft:torch 5
fill ~51~0~34 ~51~0~41 minecraft:grass
setblock ~52~1~34 minecraft:bamboo 2
setblock ~52~2~34 minecraft:bamboo 2
setblock ~52~3~34 minecraft:bamboo 2
setblock ~52~4~34 minecraft:bamboo 2
fill ~52~5~34 ~52~9~34 minecraft:bamboo 2
fill ~52~10~34 ~52~11~34 minecraft:bamboo 2
setblock ~52~12~34 minecraft:bamboo 2
fill ~52~13~34 ~52~14~34 minecraft:bamboo 2
fill ~53~0~34 ~54~0~34 minecraft:grass
fill ~54~1~34 ~54~1~35 minecraft:tallgrass 0
setblock ~55~1~34 minecraft:red_flower 8
fill ~56~0~34 ~56~0~39 minecraft:grass
setblock ~56~1~34 minecraft:yellow_flower
setblock ~57~0~34 minecraft:podzol
fill ~57~1~34 ~57~3~35 minecraft:reeds 0
fill ~77~0~34 ~78~0~35 minecraft:grass
fill ~77~1~34 ~77~3~35 minecraft:reeds 0
setblock ~78~1~34 minecraft:tallgrass 0
setblock ~79~1~34 minecraft:red_flower 0
fill ~80~0~34 ~80~0~35 minecraft:dirt 1
fill ~81~0~34 ~81~0~36 minecraft:grass
fill ~81~1~34 ~81~2~34 minecraft:bamboo 2
fill ~81~3~34 ~81~5~34 minecraft:bamboo 2
fill ~81~6~34 ~81~8~34 minecraft:bamboo 2
setblock ~81~9~34 minecraft:bamboo 2
setblock ~81~10~34 minecraft:bamboo 2
setblock ~81~11~34 minecraft:bamboo 2
setblock ~81~12~34 minecraft:bamboo 2
setblock ~82~0~34 minecraft:podzol
setblock ~83~0~34 minecraft:dirt 1
setblock ~84~0~34 minecraft:grass
setblock ~85~0~34 minecraft:podzol
setblock ~86~0~34 minecraft:grass
setblock ~87~0~34 minecraft:podzol
setblock ~88~0~34 minecraft:grass_path
setblock ~88~1~34 minecraft:torch 5
fill ~89~6~34 ~89~6~35 minecraft:deepslate_tile_stairs 4
setblock ~90~3~34 minecraft:deepslate_tile_stairs 3
setblock ~90~4~34 minecraft:deepslate_tile_stairs 7
setblock ~92~3~34 minecraft:deepslate_tile_stairs 3
setblock ~92~4~34 minecraft:deepslate_tile_stairs 7
fill ~93~6~34 ~93~6~35 minecraft:deepslate_tile_stairs 5
fill ~95~1~34 ~95~1~36 minecraft:tallgrass 0
setblock ~96~1~34 minecraft:red_flower 8
fill ~0~0~35 ~1~0~35 minecraft:sandstone
fill ~2~0~35 ~4~0~42 minecraft:grass
fill ~7~0~35 ~7~0~42 minecraft:grass
fill ~40~1~35 ~40~1~37 minecraft:tallgrass 0
setblock ~45~3~35 minecraft:deepslate_tile_stairs 2
setblock ~45~4~35 minecraft:deepslate_tile_stairs 6
setblock ~47~3~35 minecraft:deepslate_tile_stairs 2
setblock ~47~4~35 minecraft:deepslate_tile_stairs 6
setblock ~49~0~35 minecraft:dirt_with_roots
setblock ~50~0~35 minecraft:grass_path
fill ~52~0~35 ~52~0~36 minecraft:dirt_with_roots
setblock ~53~0~35 minecraft:podzol
setblock ~54~0~35 minecraft:grass
setblock ~55~0~35 minecraft:grass_path
setblock ~56~1~35 minecraft:tallgrass 0
fill ~57~0~35 ~57~0~37 minecraft:grass
fill ~64~0~35 ~68~0~35 minecraft:water 0
fill ~69~0~35 ~70~0~41 minecraft:planks 0
setblock ~69~1~35 minecraft:torch 5
setblock ~70~1~35 minecraft:chest 3
setblock ~71~1~35 minecraft:torch 5
setblock ~78~1~35 minecraft:red_flower 3
setblock ~82~0~35 minecraft:dirt 1
setblock ~82~1~35 minecraft:bamboo 2
setblock ~82~2~35 minecraft:bamboo 2
fill ~82~3~35 ~82~4~35 minecraft:bamboo 2
setblock ~82~5~35 minecraft:bamboo 2
fill ~82~6~35 ~82~7~35 minecraft:bamboo 2
fill ~82~8~35 ~82~9~35 minecraft:bamboo 2
fill ~82~10~35 ~82~13~35 minecraft:bamboo 2
setblock ~82~14~35 minecraft:bamboo 2
fill ~82~15~35 ~82~16~35 minecraft:bamboo 2
fill ~83~0~35 ~83~0~37 minecraft:grass
setblock ~84~0~35 minecraft:podzol
setblock ~85~0~35 minecraft:grass_path
setblock ~86~0~35 minecraft:dirt 1
fill ~87~0~35 ~88~0~35 minecraft:grass
setblock ~90~3~35 minecraft:deepslate_tile_stairs 2
setblock ~90~4~35 minecraft:deepslate_tile_stairs 6
setblock ~92~3~35 minecraft:deepslate_tile_stairs 2
setblock ~92~4~35 minecraft:deepslate_tile_stairs 6
setblock ~94~1~35 minecraft:tallgrass 0
fill ~97~1~35 ~97~1~36 minecraft:tallgrass 0
setblock ~0~0~36 minecraft:sandstone
fill ~1~0~36 ~1~0~106 minecraft:grass
fill ~8~0~36 ~10~0~42 minecraft:grass
setblock ~10~1~36 minecraft:yellow_flower
setblock ~35~1~36 minecraft:tallgrass 0
setblock ~38~1~36 minecraft:tallgrass 0
fill ~42~1~36 ~43~1~38 minecraft:tallgrass 0
setblock ~44~4~36 minecraft:wall_banner 4
setblock ~44~5~36 minecraft:lantern 1
setblock ~44~6~36 minecraft:deepslate_tile_stairs 0
fill ~45~3~36 ~45~4~36 minecraft:polished_blackstone_bricks
fill ~47~3~36 ~47~4~36 minecraft:polished_blackstone_bricks
setblock ~48~4~36 minecraft:wall_banner 5
setblock ~48~5~36 minecraft:lantern 1
setblock ~48~6~36 minecraft:deepslate_tile_stairs 1
fill ~49~0~36 ~50~0~36 minecraft:grass
setblock ~53~0~36 minecraft:dirt 1
fill ~54~0~36 ~55~0~36 minecraft:podzol
setblock ~57~1~36 minecraft:yellow_flower
setblock ~58~0~36 minecraft:dirt_with_roots
fill ~58~1~36 ~58~3~36 minecraft:reeds 0
fill ~64~0~36 ~67~0~40 minecraft:water 0
setblock ~68~0~36 minecraft:cobblestone_wall 7
setblock ~68~1~36 minecraft:cobblestone_wall 7
setblock ~68~2~36 minecraft:lantern 0
setblock ~71~0~36 minecraft:cobblestone_wall 7
setblock ~71~1~36 minecraft:cobblestone_wall 7
setblock ~71~2~36 minecraft:lantern 0
fill ~72~0~36 ~72~0~39 minecraft:water 0
fill ~76~0~36 ~77~0~36 minecraft:grass
fill ~76~1~36 ~76~3~36 minecraft:reeds 0
setblock ~78~0~36 minecraft:grass_path
setblock ~79~1~36 minecraft:double_plant 2
fill ~80~0~36 ~80~0~37 minecraft:grass
fill ~80~1~36 ~81~1~36 minecraft:tallgrass 0
setblock ~82~0~36 minecraft:grass
fill ~84~0~36 ~85~0~37 minecraft:grass
setblock ~85~1~36 minecraft:bamboo 2
setblock ~85~2~36 minecraft:bamboo 2
fill ~85~3~36 ~85~8~36 minecraft:bamboo 2
setblock ~85~9~36 minecraft:bamboo 2
fill ~85~10~36 ~85~12~36 minecraft:bamboo 2
setblock ~85~13~36 minecraft:bamboo 2
fill ~85~14~36 ~85~15~36 minecraft:bamboo 2
setblock ~86~0~36 minecraft:grass_path
setblock ~87~0~36 minecraft:podzol
setblock ~88~0~36 minecraft:grass
setblock ~89~4~36 minecraft:wall_banner 4
setblock ~89~5~36 minecraft:lantern 1
setblock ~89~6~36 minecraft:deepslate_tile_stairs 0
fill ~90~3~36 ~90~4~36 minecraft:polished_blackstone_bricks
fill ~92~3~36 ~92~4~36 minecraft:polished_blackstone_bricks
setblock ~93~4~36 minecraft:wall_banner 5
setblock ~93~5~36 minecraft:lantern 1
setblock ~93~6~36 minecraft:deepslate_tile_stairs 1
setblock ~94~1~36 minecraft:double_plant 2
fill ~96~1~36 ~96~1~37 minecraft:double_plant 2
setblock ~98~1~36 minecraft:tallgrass 0
fill ~0~0~37 ~0~0~40 minecraft:grass
fill ~1~1~37 ~1~1~38 minecraft:tallgrass 0
fill ~3~1~37 ~4~1~37 minecraft:tallgrass 0
fill ~11~0~37 ~13~0~42 minecraft:grass
fill ~12~1~37 ~13~1~37 minecraft:tallgrass 0
setblock ~29~1~37 minecraft:tallgrass 0
setblock ~31~1~37 minecraft:yellow_flower
setblock ~34~1~37 minecraft:tallgrass 0
setblock ~36~1~37 minecraft:tallgrass 0
setblock ~39~1~37 minecraft:tallgrass 0
fill ~44~6~37 ~44~6~38 minecraft:deepslate_tile_stairs 4
setblock ~45~3~37 minecraft:deepslate_tile_stairs 3
setblock ~45~4~37 minecraft:deepslate_tile_stairs 7
setblock ~47~3~37 minecraft:deepslate_tile_stairs 3
setblock ~47~4~37 minecraft:deepslate_tile_stairs 7
fill ~48~6~37 ~48~6~38 minecraft:deepslate_tile_stairs 5
setblock ~49~0~37 minecraft:grass
setblock ~50~0~37 minecraft:podzol
fill ~50~1~37 ~50~2~37 minecraft:bamboo 2
fill ~50~3~37 ~50~4~37 minecraft:bamboo 2
setblock ~50~5~37 minecraft:bamboo 2
setblock ~50~6~37 minecraft:bamboo 2
setblock ~50~7~37 minecraft:bamboo 2
setblock ~50~8~37 minecraft:bamboo 2
setblock ~50~9~37 minecraft:bamboo 2
setblock ~50~10~37 minecraft:bamboo 2
setblock ~50~11~37 minecraft:bamboo 2
setblock ~50~12~37 minecraft:bamboo 2
fill ~51~1~37 ~51~1~38 minecraft:torch 5
fill ~52~0~37 ~53~0~37 minecraft:grass
setblock ~54~0~37 minecraft:podzol
setblock ~55~0~37 minecraft:grass_path
fill ~56~1~37 ~57~1~37 minecraft:tallgrass 0
setblock ~58~0~37 minecraft:podzol
setblock ~59~0~37 minecraft:grass
fill ~59~1~37 ~59~3~37 minecraft:reeds 0
fill ~68~0~37 ~68~0~40 minecraft:water 0
fill ~71~0~37 ~71~0~39 minecraft:water 0
setblock ~75~0~37 minecraft:dirt_with_roots
fill ~75~1~37 ~75~3~37 minecraft:reeds 0
setblock ~76~0~37 minecraft:dirt 1
setblock ~77~0~37 minecraft:podzol
fill ~78~0~37 ~78~0~38 minecraft:grass
fill ~78~1~37 ~79~1~37 minecraft:tallgrass 0
setblock ~80~1~37 minecraft:red_flower 8
fill ~81~0~37 ~81~0~38 minecraft:grass_path
setblock ~82~0~37 minecraft:dirt_with_roots
fill ~86~0~37 ~87~0~37 minecraft:dirt_with_roots
setblock ~88~0~37 minecraft:grass_path
setblock ~88~1~37 minecraft:torch 5
fill ~89~6~37 ~89~6~38 minecraft:deepslate_tile_stairs 4
setblock ~90~3~37 minecraft:deepslate_tile_stairs 3
setblock ~90~4~37 minecraft:deepslate_tile_stairs 7
setblock ~92~3~37 minecraft:deepslate_tile_stairs 3
setblock ~92~4~37 minecraft:deepslate_tile_stairs 7
fill ~93~6~37 ~93~6~38 minecraft:deepslate_tile_stairs 5
fill ~94~1~37 ~94~1~39 minecraft:tallgrass 0
setblock ~95~1~37 minecraft:double_plant 2
setblock ~97~1~37 minecraft:double_plant 2
fill ~2~1~38 ~3~1~38 minecraft:tallgrass 0
setblock ~6~21~38 minecraft:wall_banner 2
setblock ~6~23~38 minecraft:wall_banner 2
setblock ~6~25~38 minecraft:wall_banner 2
setblock ~6~26~38 minecraft:sea_lantern
setblock ~13~1~38 minecraft:tallgrass 0
fill ~14~0~38 ~17~0~42 minecraft:grass
fill ~16~1~38 ~16~1~42 minecraft:tallgrass 0
setblock ~17~1~38 minecraft:red_flower 8
fill ~28~0~38 ~28~0~41 minecraft:sandstone 0
setblock ~30~1~38 minecraft:tallgrass 0
fill ~32~1~38 ~33~1~41 minecraft:tallgrass 0
setblock ~39~1~38 minecraft:red_flower 9
fill ~40~1~38 ~41~1~38 minecraft:double_plant 2
setblock ~45~3~38 minecraft:deepslate_tile_stairs 2
setblock ~45~4~38 minecraft:deepslate_tile_stairs 6
setblock ~47~3~38 minecraft:deepslate_tile_stairs 2
setblock ~47~4~38 minecraft:deepslate_tile_stairs 6
fill ~49~0~38 ~50~0~38 minecraft:dirt_with_roots
setblock ~49~1~38 minecraft:torch 5
fill ~52~0~38 ~53~0~38 minecraft:dirt_with_roots
setblock ~54~0~38 minecraft:dirt 1
setblock ~55~0~38 minecraft:grass
setblock ~56~1~38 minecraft:tallgrass 0
setblock ~57~0~38 minecraft:dirt_with_roots
fill ~58~0~38 ~58~0~40 minecraft:grass
fill ~58~1~38 ~58~1~39 minecraft:tallgrass 0
setblock ~59~0~38 minecraft:dirt 1
setblock ~60~0~38 minecraft:podzol
fill ~60~1~38 ~60~3~38 minecraft:reeds 0
setblock ~62~1~38 minecraft:torch 5
setblock ~74~0~38 minecraft:grass
fill ~74~1~38 ~74~3~38 minecraft:reeds 0
setblock ~75~0~38 minecraft:dirt 1
fill ~76~0~38 ~76~0~39 minecraft:podzol
setblock ~77~0~38 minecraft:grass
setblock ~79~1~38 minecraft:tallgrass 0
setblock ~80~0~38 minecraft:dirt 1
setblock ~82~0~38 minecraft:grass_path
setblock ~83~0~38 minecraft:podzol
setblock ~83~1~38 minecraft:bamboo 2
fill ~83~2~38 ~83~4~38 minecraft:bamboo 2
fill ~83~5~38 ~83~6~38 minecraft:bamboo 2
setblock ~83~7~38 minecraft:bamboo 2
setblock ~83~8~38 minecraft:bamboo 2
fill ~83~9~38 ~83~10~38 minecraft:bamboo 2
setblock ~83~11~38 minecraft:bamboo 2
setblock ~83~12~38 minecraft:bamboo 2
setblock ~83~13~38 minecraft:bamboo 2
setblock ~84~0~38 minecraft:grass
setblock ~84~1~38 minecraft:torch 5
fill ~85~0~38 ~86~0~38 minecraft:podzol
fill ~87~0~38 ~87~0~44 minecraft:grass
setblock ~88~0~38 minecraft:dirt 1
setblock ~89~5~38 minecraft:torch 4
setblock ~90~3~38 minecraft:deepslate_tile_stairs 2
setblock ~90~4~38 minecraft:deepslate_tile_stairs 6
setblock ~91~8~38 minecraft:torch 5
setblock ~92~3~38 minecraft:deepslate_tile_stairs 2
setblock ~92~4~38 minecraft:deepslate_tile_stairs 6
setblock ~93~5~38 minecraft:torch 4
setblock ~95~1~38 minecraft:red_flower 0
fill ~96~1~38 ~97~1~38 minecraft:tallgrass 0
setblock ~0~1~39 minecraft:tallgrass 0
setblock ~2~1~39 minecraft:tallgrass 0
fill ~3~1~39 ~3~1~40 minecraft:double_plant 2
fill ~5~0~39 ~5~0~42 minecraft:grass
setblock ~5~1~39 minecraft:tallgrass 0
setblock ~5~21~39 minecraft:wall_banner 4
setblock ~5~23~39 minecraft:wall_banner 4
setblock ~5~25~39 minecraft:wall_banner 4
setblock ~5~26~39 minecraft:sea_lantern
setblock ~6~0~39 minecraft:dirt 0
fill ~6~1~39 ~6~19~39 minecraft:polished_blackstone
fill ~6~20~39 ~6~25~39 minecraft:quartz_block 2
setblock ~6~26~39 minecraft:polished_blackstone
setblock ~6~27~39 minecraft:sea_lantern
setblock ~7~21~39 minecraft:wall_banner 5
setblock ~7~23~39 minecraft:wall_banner 5
setblock ~7~25~39 minecraft:wall_banner 5
setblock ~7~26~39 minecraft:sea_lantern
setblock ~8~1~39 minecraft:tallgrass 0
fill ~12~1~39 ~12~1~40 minecraft:tallgrass 0
setblock ~13~1~39 minecraft:red_flower 8
fill ~14~1~39 ~14~1~42 minecraft:tallgrass 0
fill ~18~0~39 ~21~0~42 minecraft:grass
fill ~18~1~39 ~18~1~41 minecraft:tallgrass 0
setblock ~19~1~39 minecraft:red_flower 8
setblock ~20~1~39 minecraft:tallgrass 0
setblock ~29~0~39 minecraft:sandstone 0
setblock ~30~1~39 minecraft:yellow_flower
fill ~34~1~39 ~34~1~41 minecraft:double_plant 2
fill ~35~1~39 ~35~1~42 minecraft:tallgrass 0
setblock ~36~1~39 minecraft:red_flower 3
fill ~37~1~39 ~38~1~39 minecraft:tallgrass 0
setblock ~41~1~39 minecraft:tallgrass 0
setblock ~42~1~39 minecraft:double_plant 2
fill ~43~1~39 ~43~1~41 minecraft:tallgrass 0
setblock ~44~4~39 minecraft:wall_banner 4
setblock ~44~5~39 minecraft:lantern 1
setblock ~44~6~39 minecraft:deepslate_tile_stairs 0
fill ~45~3~39 ~45~4~39 minecraft:polished_blackstone_bricks
fill ~47~3~39 ~47~4~39 minecraft:polished_blackstone_bricks
setblock ~48~4~39 minecraft:wall_banner 5
setblock ~48~5~39 minecraft:lantern 1
setblock ~48~6~39 minecraft:deepslate_tile_stairs 1
fill ~49~0~39 ~50~0~39 minecraft:grass
setblock ~52~0~39 minecraft:podzol
fill ~53~0~39 ~54~0~39 minecraft:grass
setblock ~55~0~39 minecraft:podzol
setblock ~57~0~39 minecraft:grass
setblock ~57~1~39 minecraft:red_flower 9
fill ~59~0~39 ~60~0~39 minecraft:grass
setblock ~61~0~39 minecraft:dirt_with_roots
fill ~61~1~39 ~61~3~39 minecraft:reeds 0
setblock ~64~1~39 minecraft:torch 5
setblock ~73~0~39 minecraft:dirt 1
fill ~73~1~39 ~73~3~39 minecraft:reeds 0
setblock ~74~0~39 minecraft:podzol
setblock ~75~0~39 minecraft:grass_path
setblock ~77~0~39 minecraft:grass_path
fill ~78~0~39 ~78~0~42 minecraft:podzol
setblock ~79~0~39 minecraft:dirt 1
fill ~80~0~39 ~81~0~39 minecraft:grass
setblock ~81~1~39 minecraft:tallgrass 0
setblock ~82~0~39 minecraft:podzol
fill ~82~1~39 ~82~11~39 minecraft:bamboo 2
setblock ~82~12~39 minecraft:bamboo 2
fill ~82~13~39 ~82~14~39 minecraft:bamboo 2
setblock ~83~0~39 minecraft:grass
setblock ~83~1~39 minecraft:tallgrass 0
fill ~84~0~39 ~85~0~39 minecraft:podzol
fill ~85~1~39 ~85~7~39 minecraft:bamboo 2
setblock ~85~8~39 minecraft:bamboo 2
fill ~85~9~39 ~85~11~39 minecraft:bamboo 2
setblock ~85~12~39 minecraft:bamboo 2
setblock ~85~13~39 minecraft:bamboo 2
setblock ~85~14~39 minecraft:bamboo 2
setblock ~85~15~39 minecraft:bamboo 2
setblock ~85~16~39 minecraft:bamboo 2
setblock ~86~0~39 minecraft:dirt 1
setblock ~88~0~39 minecraft:grass
fill ~89~1~39 ~90~6~39 minecraft:quartz_block 2
setblock ~89~8~39 minecraft:quartz_block 2
setblock ~90~7~39 minecraft:quartz_block 2
fill ~92~1~39 ~93~6~39 minecraft:quartz_block 2
setblock ~92~7~39 minecraft:quartz_block 2
setblock ~93~8~39 minecraft:quartz_block 2
fill ~95~1~39 ~96~1~39 minecraft:tallgrass 0
fill ~1~1~40 ~2~1~40 minecraft:double_plant 2
fill ~4~1~40 ~4~1~41 minecraft:tallgrass 0
fill ~5~1~40 ~5~1~41 minecraft:double_plant 2
fill ~6~0~40 ~6~0~42 minecraft:grass
fill ~6~1~40 ~6~1~41 minecraft:tallgrass 0
setblock ~6~21~40 minecraft:wall_banner 3
setblock ~6~23~40 minecraft:wall_banner 3
setblock ~6~25~40 minecraft:wall_banner 3
setblock ~6~26~40 minecraft:sea_lantern
fill ~10~1~40 ~11~1~40 minecraft:tallgrass 0
setblock ~13~1~40 minecraft:tallgrass 0
fill ~15~1~40 ~15~1~41 minecraft:tallgrass 0
setblock ~17~1~40 minecraft:tallgrass 0
fill ~19~1~40 ~19~1~42 minecraft:tallgrass 0
fill ~20~1~40 ~20~1~41 minecraft:double_plant 2
setblock ~21~1~40 minecraft:tallgrass 0
fill ~29~0~40 ~29~0~42 minecraft:grass
setblock ~29~1~40 minecraft:red_flower 9
fill ~30~1~40 ~31~1~40 minecraft:tallgrass 0
setblock ~36~1~40 minecraft:tallgrass 0
setblock ~37~1~40 minecraft:double_plant 2
fill ~38~1~40 ~40~1~40 minecraft:tallgrass 0
setblock ~41~1~40 minecraft:double_plant 2
setblock ~42~1~40 minecraft:red_flower 0
fill ~44~6~40 ~44~6~41 minecraft:deepslate_tile_stairs 4
setblock ~45~3~40 minecraft:deepslate_tile_stairs 3
setblock ~45~4~40 minecraft:deepslate_tile_stairs 7
setblock ~46~8~40 minecraft:torch 5
setblock ~47~3~40 minecraft:deepslate_tile_stairs 3
setblock ~47~4~40 minecraft:deepslate_tile_stairs 7
fill ~48~6~40 ~48~6~41 minecraft:deepslate_tile_stairs 5
setblock ~49~0~40 minecraft:dirt 1
setblock ~50~0~40 minecraft:dirt_with_roots
setblock ~50~1~40 minecraft:torch 5
fill ~52~0~40 ~52~0~41 minecraft:grass
fill ~52~1~40 ~52~3~40 minecraft:bamboo 2
fill ~52~4~40 ~52~6~40 minecraft:bamboo 2
setblock ~52~7~40 minecraft:bamboo 2
setblock ~52~8~40 minecraft:bamboo 2
setblock ~52~9~40 minecraft:bamboo 2
setblock ~52~10~40 minecraft:bamboo 2
setblock ~52~11~40 minecraft:bamboo 2
fill ~52~12~40 ~52~13~40 minecraft:bamboo 2
fill ~53~0~40 ~54~0~40 minecraft:podzol
setblock ~55~0~40 minecraft:grass
fill ~56~0~40 ~57~0~40 minecraft:podzol
setblock ~58~1~40 minecraft:double_plant 2
fill ~59~0~40 ~60~0~40 minecraft:podzol
fill ~61~0~40 ~61~0~41 minecraft:grass
setblock ~62~0~40 minecraft:dirt_with_roots
fill ~62~1~40 ~63~3~40 minecraft:reeds 0
fill ~63~0~40 ~63~0~42 minecraft:podzol
fill ~71~0~40 ~72~0~40 minecraft:grass
setblock ~73~0~40 minecraft:podzol
setblock ~74~0~40 minecraft:grass_path
setblock ~75~0~40 minecraft:grass
setblock ~76~0~40 minecraft:grass_path
fill ~77~0~40 ~77~0~43 minecraft:grass
setblock ~77~1~40 minecraft:double_plant 2
setblock ~79~0~40 minecraft:podzol
setblock ~80~0~40 minecraft:dirt_with_roots
setblock ~81~0~40 minecraft:podzol
fill ~82~0~40 ~82~0~41 minecraft:grass
setblock ~82~1~40 minecraft:tallgrass 0
fill ~83~0~40 ~84~0~40 minecraft:podzol
fill ~85~0~40 ~85~0~42 minecraft:grass
setblock ~86~0~40 minecraft:dirt_with_roots
setblock ~88~0~40 minecraft:grass_path
fill ~89~1~40 ~89~1~47 minecraft:deepslate_tile_stairs 0
fill ~89~2~40 ~89~2~47 minecraft:iron_bars
setblock ~89~5~40 minecraft:torch 3
fill ~89~6~40 ~89~6~41 minecraft:deepslate_tile_stairs 4
fill ~89~8~40 ~89~8~47 minecraft:quartz_stairs 0
fill ~90~1~40 ~90~2~47 minecraft:polished_blackstone_bricks
setblock ~90~3~40 minecraft:deepslate_tile_stairs 3
setblock ~90~4~40 minecraft:deepslate_tile_stairs 7
fill ~90~5~40 ~90~7~47 minecraft:polished_blackstone_bricks
fill ~92~1~40 ~92~2~47 minecraft:polished_blackstone_bricks
setblock ~92~3~40 minecraft:deepslate_tile_stairs 3
setblock ~92~4~40 minecraft:deepslate_tile_stairs 7
fill ~92~5~40 ~92~7~47 minecraft:polished_blackstone_bricks
fill ~93~1~40 ~93~1~47 minecraft:deepslate_tile_stairs 1
fill ~93~2~40 ~93~2~47 minecraft:iron_bars
setblock ~93~5~40 minecraft:torch 3
fill ~93~6~40 ~93~6~41 minecraft:deepslate_tile_stairs 5
fill ~93~8~40 ~93~8~47 minecraft:quartz_stairs 1
setblock ~94~1~40 minecraft:double_plant 2
setblock ~96~1~40 minecraft:tallgrass 0
fill ~0~0~41 ~0~0~43 minecraft:sandstone
setblock ~1~1~41 minecraft:double_plant 2
fill ~2~1~41 ~2~1~42 minecraft:tallgrass 0
setblock ~3~1~41 minecraft:red_flower 3
setblock ~8~1~41 minecraft:double_plant 2
fill ~10~1~41 ~10~1~42 minecraft:tallgrass 0
setblock ~11~1~41 minecraft:double_plant 2
setblock ~12~1~41 minecraft:red_flower 8
setblock ~13~1~41 minecraft:red_flower 0
setblock ~17~1~41 minecraft:double_plant 2
setblock ~21~1~41 minecraft:double_plant 2
fill ~23~0~41 ~23~0~42 minecraft:grass
setblock ~29~1~41 minecraft:tallgrass 0
setblock ~30~1~41 minecraft:double_plant 2
setblock ~31~1~41 minecraft:red_flower 0
fill ~36~1~41 ~36~1~42 minecraft:double_plant 2
fill ~37~1~41 ~37~1~42 minecraft:tallgrass 0
fill ~38~1~41 ~39~1~41 minecraft:double_plant 2
setblock ~40~1~41 minecraft:red_flower 3
fill ~41~1~41 ~42~1~41 minecraft:tallgrass 0
setblock ~45~3~41 minecraft:deepslate_tile_stairs 2
setblock ~45~4~41 minecraft:deepslate_tile_stairs 6
setblock ~47~3~41 minecraft:deepslate_tile_stairs 2
setblock ~47~4~41 minecraft:deepslate_tile_stairs 6
fill ~49~0~41 ~50~0~41 minecraft:grass
setblock ~53~0~41 minecraft:dirt 1
setblock ~54~0~41 minecraft:grass
setblock ~55~0~41 minecraft:podzol
setblock ~56~0~41 minecraft:dirt_with_roots
fill ~57~0~41 ~57~0~43 minecraft:grass
setblock ~57~1~41 minecraft:tallgrass 0
setblock ~58~0~41 minecraft:dirt 1
fill ~59~0~41 ~59~0~43 minecraft:grass
setblock ~59~1~41 minecraft:tallgrass 0
setblock ~60~0~41 minecraft:grass_path
setblock ~61~1~41 minecraft:red_flower 9
setblock ~62~0~41 minecraft:podzol
setblock ~64~0~41 minecraft:dirt_with_roots
