    
fill ~4 ~0 ~41 ~13 ~0 ~41 snow_layer  
fill ~4 ~0 ~42 ~15 ~0 ~42 stone  
fill ~4 ~0 ~43 ~4 ~2 ~43 stone  
fill ~4 ~0 ~44 ~4 ~2 ~44 stone  
fill ~4 ~0 ~45 ~4 ~2 ~45 stone  
fill ~4 ~0 ~46 ~4 ~2 ~46 stone  
fill ~4 ~0 ~47 ~4 ~2 ~47 stone  
fill ~4 ~0 ~48 ~4 ~2 ~48 stone  
fill ~4 ~0 ~49 ~4 ~2 ~49 stone  
fill ~4 ~0 ~50 ~4 ~2 ~50 stone  
fill ~4 ~0 ~51 ~4 ~3 ~51 stone  
fill ~4 ~0 ~52 ~4 ~3 ~52 stone  
fill ~4 ~0 ~53 ~4 ~3 ~53 stone  
fill ~4 ~0 ~54 ~4 ~3 ~54 stone  
fill ~4 ~0 ~55 ~4 ~3 ~55 stone  
fill ~4 ~0 ~56 ~4 ~3 ~56 stone  
fill ~4 ~0 ~57 ~4 ~3 ~57 stone  
fill ~4 ~0 ~58 ~4 ~3 ~58 stone  
fill ~4 ~0 ~59 ~4 ~3 ~59 stone  
fill ~4 ~0 ~60 ~4 ~3 ~60 stone  
fill ~4 ~0 ~61 ~4 ~3 ~61 stone  
fill ~4 ~0 ~62 ~4 ~3 ~62 stone  
fill ~4 ~0 ~63 ~4 ~3 ~63 stone  
fill ~4 ~0 ~64 ~4 ~3 ~64 stone  
fill ~4 ~0 ~65 ~4 ~3 ~65 stone  
fill ~4 ~0 ~66 ~4 ~3 ~66 stone  
fill ~4 ~0 ~67 ~4 ~3 ~67 stone  
fill ~4 ~0 ~68 ~4 ~3 ~68 stone  
fill ~4 ~0 ~69 ~4 ~3 ~69 stone  
fill ~4 ~0 ~70 ~4 ~3 ~70 stone  
fill ~4 ~0 ~71 ~4 ~3 ~71 stone  
fill ~4 ~0 ~72 ~4 ~3 ~72 stone  
fill ~4 ~0 ~73 ~4 ~3 ~73 stone  
fill ~4 ~0 ~74 ~4 ~3 ~74 stone  
fill ~4 ~0 ~75 ~4 ~3 ~75 stone  
fill ~4 ~0 ~76 ~4 ~3 ~76 stone  
fill ~4 ~0 ~77 ~4 ~3 ~77 stone  
fill ~4 ~0 ~78 ~4 ~3 ~78 stone  
fill ~4 ~0 ~79 ~4 ~3 ~79 stone  
fill ~4 ~0 ~80 ~4 ~2 ~80 stone  
fill ~4 ~0 ~81 ~4 ~2 ~81 stone  
fill ~4 ~0 ~82 ~4 ~2 ~82 stone  
fill ~4 ~0 ~83 ~4 ~2 ~83 stone  
fill ~4 ~0 ~84 ~4 ~2 ~84 stone  
fill ~4 ~0 ~85 ~4 ~2 ~85 stone  
fill ~4 ~0 ~86 ~4 ~2 ~86 stone  
fill ~4 ~0 ~87 ~4 ~2 ~87 stone  
fill ~4 ~0 ~88 ~15 ~0 ~88 stone  
fill ~6 ~0 ~67 ~6 ~7 ~67 dirt  
fill ~14 ~0 ~41 ~15 ~0 ~41 stone  
fill ~15 ~0 ~30 ~61 ~0 ~30 stone  
fill ~15 ~0 ~31 ~26 ~0 ~31 stone  
fill ~15 ~0 ~32 ~15 ~2 ~32 stone  
fill ~15 ~0 ~33 ~15 ~2 ~33 stone  
fill ~15 ~0 ~34 ~15 ~2 ~34 stone  
fill ~15 ~0 ~35 ~15 ~2 ~35 stone  
fill ~15 ~0 ~36 ~15 ~2 ~36 stone  
fill ~15 ~0 ~37 ~15 ~2 ~37 stone  
fill ~15 ~0 ~38 ~15 ~2 ~38 stone  
fill ~15 ~0 ~39 ~15 ~2 ~39 stone  
fill ~15 ~0 ~40 ~15 ~2 ~40 stone  
fill ~15 ~0 ~89 ~15 ~2 ~89 stone  
fill ~15 ~0 ~90 ~15 ~2 ~90 stone  
fill ~15 ~0 ~91 ~15 ~2 ~91 stone  
fill ~15 ~0 ~92 ~15 ~2 ~92 stone  
fill ~15 ~0 ~93 ~15 ~2 ~93 stone  
fill ~15 ~0 ~94 ~15 ~2 ~94 stone  
fill ~15 ~0 ~95 ~15 ~2 ~95 stone  
fill ~15 ~0 ~96 ~15 ~2 ~96 stone  
fill ~15 ~0 ~97 ~15 ~2 ~97 stone  
fill ~15 ~0 ~98 ~15 ~2 ~98 stone  
fill ~15 ~0 ~99 ~53 ~0 ~99 stone 
setblock ~16 ~0 ~95 torch 1 
setblock ~17 ~0 ~33 dirt 0  
fill ~17 ~0 ~34 ~17 ~4 ~34 stone  
fill ~17 ~0 ~86 ~17 ~7 ~86 dirt  
fill ~21 ~0 ~32 ~21 ~3 ~32 dirt  
fill ~31 ~0 ~59 ~31 ~0 ~59 stone 
setblock ~31 ~0 ~60 glowstone 0  
fill ~31 ~0 ~61 ~31 ~0 ~67 stone 
setblock ~31 ~0 ~68 glowstone 0  
fill ~31 ~0 ~69 ~31 ~0 ~69 stone 
setblock ~32 ~0 ~58 glowstone 0  
fill ~32 ~0 ~64 ~32 ~1 ~64 stone 
setblock ~32 ~0 ~70 glowstone 0  
fill ~32 ~0 ~84 ~33 ~0 ~84 snow_layer  
fill ~32 ~0 ~85 ~32 ~0 ~84 snow_layer 
setblock ~32 ~0 ~88 snow_layer 0 
setblock ~33 ~0 ~57 glowstone 0 
setblock ~33 ~0 ~71 glowstone 0  
fill ~33 ~0 ~83 ~34 ~0 ~83 snow_layer  
fill ~33 ~0 ~86 ~33 ~0 ~87 snow_layer  
fill ~33 ~0 ~89 ~33 ~0 ~92 snow_layer  
fill ~33 ~0 ~94 ~36 ~0 ~94 snow_layer 
setblock ~34 ~0 ~56 glowstone 0 
setblock ~34 ~0 ~72 glowstone 0  
fill ~34 ~0 ~82 ~35 ~0 ~82 snow_layer  
fill ~34 ~0 ~87 ~34 ~0 ~88 snow_layer  
fill ~34 ~0 ~90 ~34 ~0 ~96 snow_layer  
fill ~34 ~0 ~98 ~61 ~0 ~98 stone 
setblock ~35 ~0 ~55 glowstone 0 
setblock ~35 ~0 ~73 glowstone 0  
fill ~35 ~0 ~81 ~36 ~0 ~81 snow_layer 
setblock ~35 ~0 ~85 torch 5 
setblock ~35 ~0 ~93 snow_layer 0  
fill ~35 ~0 ~96 ~43 ~0 ~96 snow_layer  
fill ~36 ~0 ~54 ~36 ~0 ~54 stone  
fill ~36 ~0 ~74 ~36 ~0 ~74 stone 
setblock ~36 ~0 ~80 snow_layer 0 
setblock ~36 ~0 ~83 snow_layer 0 
setblock ~36 ~0 ~89 torch 5  
fill ~36 ~0 ~95 ~37 ~0 ~95 snow_layer 
setblock ~37 ~0 ~54 glowstone 0 
setblock ~37 ~0 ~74 glowstone 0 
setblock ~37 ~0 ~84 snow_layer 0  
fill ~37 ~0 ~86 ~41 ~0 ~86 snow_layer  
fill ~37 ~0 ~87 ~40 ~0 ~87 snow_layer 
setblock ~37 ~0 ~92 torch 5  
fill ~38 ~0 ~54 ~44 ~0 ~54 stone  
fill ~38 ~0 ~74 ~44 ~0 ~74 stone 
setblock ~38 ~0 ~82 torch 5  
fill ~38 ~0 ~85 ~47 ~0 ~85 snow_layer  
fill ~38 ~0 ~88 ~39 ~0 ~88 snow_layer 
setblock ~38 ~0 ~90 snow_layer 0  
fill ~38 ~0 ~94 ~47 ~0 ~94 snow_layer  
fill ~39 ~0 ~84 ~47 ~0 ~84 snow_layer  
fill ~39 ~0 ~95 ~46 ~0 ~95 snow_layer 
setblock ~40 ~0 ~91 torch 5  
fill ~41 ~0 ~55 ~41 ~1 ~55 stone  
fill ~41 ~0 ~73 ~41 ~1 ~73 stone  
fill ~41 ~0 ~93 ~44 ~0 ~93 snow_layer 
setblock ~42 ~0 ~88 torch 5  
fill ~42 ~0 ~92 ~44 ~0 ~92 snow_layer  
fill ~43 ~0 ~83 ~49 ~0 ~83 snow_layer  
fill ~43 ~0 ~86 ~46 ~0 ~86 snow_layer  
fill ~43 ~0 ~90 ~44 ~0 ~90 snow_layer  
fill ~43 ~0 ~91 ~43 ~0 ~90 snow_layer  
fill ~44 ~0 ~81 ~45 ~0 ~81 snow_layer  
fill ~44 ~0 ~82 ~48 ~0 ~82 snow_layer  
fill ~44 ~0 ~87 ~45 ~0 ~87 snow_layer  
fill ~44 ~0 ~89 ~45 ~0 ~89 snow_layer 
setblock ~45 ~0 ~54 glowstone 0 
setblock ~45 ~0 ~74 glowstone 0  
fill ~45 ~0 ~88 ~46 ~0 ~88 snow_layer  
fill ~45 ~0 ~96 ~50 ~0 ~96 snow_layer  
fill ~46 ~0 ~54 ~46 ~0 ~54 stone  
fill ~46 ~0 ~74 ~46 ~0 ~74 stone 
setblock ~46 ~0 ~91 torch 5 
setblock ~47 ~0 ~55 glowstone 0 
setblock ~47 ~0 ~73 glowstone 0 
setblock ~47 ~0 ~89 snow_layer 0  
fill ~47 ~0 ~93 ~48 ~0 ~93 snow_layer 
setblock ~48 ~0 ~56 glowstone 0 
setblock ~48 ~0 ~72 glowstone 0 
setblock ~48 ~0 ~87 torch 5 
setblock ~48 ~0 ~90 snow_layer 0 
setblock ~48 ~0 ~92 snow_layer 0  
fill ~48 ~0 ~95 ~49 ~0 ~95 snow_layer 
setblock ~49 ~0 ~57 glowstone 0 
setblock ~49 ~0 ~71 glowstone 0 
setblock ~49 ~0 ~85 snow_layer 0 
setblock ~50 ~0 ~58 glowstone 0 
setblock ~50 ~0 ~70 glowstone 0  
fill ~50 ~0 ~81 ~50 ~0 ~82 snow_layer  
fill ~51 ~0 ~59 ~51 ~0 ~59 stone 
setblock ~51 ~0 ~60 glowstone 0  
fill ~51 ~0 ~64 ~52 ~0 ~64 stone 
setblock ~51 ~0 ~68 glowstone 0  
fill ~51 ~0 ~69 ~51 ~0 ~69 stone  
fill ~52 ~0 ~61 ~52 ~0 ~61 stone  
fill ~52 ~0 ~62 ~52 ~0 ~62 stone  
fill ~52 ~0 ~63 ~52 ~0 ~63 stone  
fill ~52 ~0 ~65 ~52 ~0 ~65 stone  
fill ~52 ~0 ~66 ~52 ~0 ~66 stone  
fill ~52 ~0 ~67 ~52 ~0 ~67 stone  
fill ~54 ~0 ~99 ~62 ~0 ~99 snow_layer  
fill ~61 ~0 ~31 ~61 ~5 ~31 stone  
fill ~61 ~0 ~32 ~61 ~5 ~32 stone  
fill ~61 ~0 ~33 ~61 ~5 ~33 stone  
fill ~61 ~0 ~34 ~61 ~5 ~34 stone  
fill ~61 ~0 ~35 ~61 ~5 ~35 stone  
fill ~61 ~0 ~36 ~61 ~5 ~36 stone  
fill ~61 ~0 ~37 ~61 ~5 ~37 stone  
fill ~61 ~0 ~38 ~61 ~5 ~38 stone  
fill ~61 ~0 ~39 ~61 ~5 ~39 stone  
fill ~61 ~0 ~40 ~61 ~5 ~40 stone  
fill ~61 ~0 ~41 ~72 ~0 ~41 stone  
fill ~61 ~0 ~42 ~61 ~0 ~42 stone  
fill ~61 ~0 ~87 ~72 ~0 ~87 stone  
fill ~61 ~0 ~88 ~61 ~5 ~88 stone  
fill ~61 ~0 ~89 ~61 ~5 ~89 stone  
fill ~61 ~0 ~90 ~61 ~5 ~90 stone  
fill ~61 ~0 ~91 ~61 ~5 ~91 stone  
fill ~61 ~0 ~92 ~61 ~5 ~92 stone  
fill ~61 ~0 ~93 ~61 ~5 ~93 stone  
fill ~61 ~0 ~94 ~61 ~5 ~94 stone  
fill ~61 ~0 ~95 ~61 ~5 ~95 stone  
fill ~61 ~0 ~96 ~61 ~5 ~96 stone  
fill ~61 ~0 ~97 ~61 ~5 ~97 stone  
fill ~62 ~0 ~30 ~62 ~0 ~40 snow_layer 
setblock ~62 ~0 ~88 snow_layer 0  
fill ~62 ~0 ~90 ~62 ~0 ~99 snow_layer 
setblock ~64 ~0 ~88 snow_layer 0 
setblock ~69 ~0 ~42 torch 3  
fill ~70 ~0 ~49 ~71 ~0 ~49 dirt  
fill ~72 ~0 ~42 ~72 ~5 ~42 stone  
fill ~72 ~0 ~43 ~72 ~5 ~43 stone  
fill ~72 ~0 ~44 ~72 ~5 ~44 stone  
fill ~72 ~0 ~45 ~72 ~5 ~45 stone  
fill ~72 ~0 ~46 ~72 ~5 ~46 stone  
fill ~72 ~0 ~47 ~73 ~0 ~47 stone  
fill ~72 ~0 ~48 ~73 ~0 ~48 stone  
fill ~72 ~0 ~49 ~73 ~0 ~49 stone  
fill ~72 ~0 ~50 ~73 ~0 ~50 stone  
fill ~72 ~0 ~51 ~73 ~0 ~51 stone  
fill ~72 ~0 ~52 ~73 ~0 ~52 stone  
fill ~72 ~0 ~53 ~73 ~0 ~53 stone  
fill ~72 ~0 ~54 ~73 ~0 ~54 stone  
fill ~72 ~0 ~55 ~73 ~0 ~55 stone  
fill ~72 ~0 ~56 ~73 ~0 ~56 stone  
fill ~72 ~0 ~57 ~73 ~0 ~57 stone  
fill ~72 ~0 ~58 ~73 ~0 ~58 stone  
fill ~72 ~0 ~59 ~73 ~0 ~59 stone  
fill ~72 ~0 ~60 ~73 ~0 ~60 stone  
fill ~72 ~0 ~61 ~73 ~0 ~61 stone  
fill ~72 ~0 ~62 ~73 ~0 ~62 stone  
fill ~72 ~0 ~63 ~73 ~0 ~63 stone  
fill ~72 ~0 ~65 ~73 ~0 ~65 stone  
fill ~72 ~0 ~66 ~73 ~0 ~66 stone  
fill ~72 ~0 ~67 ~73 ~0 ~67 stone  
fill ~72 ~0 ~68 ~73 ~0 ~68 stone  
fill ~72 ~0 ~69 ~73 ~0 ~69 stone  
fill ~72 ~0 ~70 ~73 ~0 ~70 stone  
fill ~72 ~0 ~71 ~73 ~0 ~71 stone  
fill ~72 ~0 ~72 ~73 ~0 ~72 stone  
fill ~72 ~0 ~73 ~73 ~0 ~73 stone  
fill ~72 ~0 ~74 ~73 ~0 ~74 stone  
fill ~72 ~0 ~75 ~73 ~0 ~75 stone  
fill ~72 ~0 ~76 ~73 ~0 ~76 stone  
fill ~72 ~0 ~77 ~73 ~0 ~77 stone  
fill ~72 ~0 ~78 ~73 ~0 ~78 stone  
fill ~72 ~0 ~79 ~73 ~0 ~79 stone  
fill ~72 ~0 ~80 ~73 ~0 ~80 stone  
fill ~72 ~0 ~81 ~73 ~0 ~81 stone  
fill ~72 ~0 ~82 ~72 ~5 ~82 stone  
fill ~72 ~0 ~83 ~72 ~5 ~83 stone  
fill ~72 ~0 ~84 ~72 ~5 ~84 stone  
fill ~72 ~0 ~85 ~72 ~5 ~85 stone  
fill ~72 ~0 ~86 ~72 ~5 ~86 stone  
fill ~73 ~0 ~64 ~73 ~0 ~64 stone  
fill ~4 ~1 ~42 ~15 ~1 ~42 stone  
fill ~4 ~1 ~88 ~15 ~1 ~88 stone  
fill ~5 ~1 ~87 ~15 ~1 ~87 stone 
setblock ~14 ~1 ~41 snow_layer 0  
fill ~15 ~1 ~30 ~25 ~1 ~30 snow_layer  
fill ~15 ~1 ~31 ~50 ~1 ~31 stone  
fill ~15 ~1 ~41 ~15 ~2 ~41 stone  
fill ~15 ~1 ~99 ~34 ~1 ~99 stone  
fill ~16 ~1 ~98 ~61 ~1 ~98 stone  
fill ~17 ~1 ~33 ~17 ~2 ~33 stone  
fill ~18 ~1 ~34 ~19 ~1 ~34 dirt  
fill ~26 ~1 ~30 ~61 ~1 ~30 stone  
fill ~32 ~1 ~59 ~35 ~1 ~59 stone  
fill ~32 ~1 ~60 ~34 ~1 ~60 stone  
fill ~32 ~1 ~61 ~33 ~1 ~61 stone  
fill ~32 ~1 ~62 ~33 ~1 ~62 stone  
fill ~32 ~1 ~63 ~33 ~1 ~63 stone  
fill ~32 ~1 ~65 ~33 ~1 ~65 stone  
fill ~32 ~1 ~66 ~33 ~1 ~66 stone  
fill ~32 ~1 ~67 ~33 ~1 ~67 stone  
fill ~32 ~1 ~68 ~34 ~1 ~68 stone  
fill ~32 ~1 ~69 ~35 ~1 ~69 stone  
fill ~33 ~1 ~58 ~36 ~1 ~58 stone 
setblock ~33 ~1 ~64 stone 0  
fill ~33 ~1 ~70 ~36 ~1 ~70 stone  
fill ~34 ~1 ~57 ~37 ~1 ~57 stone  
fill ~34 ~1 ~71 ~37 ~1 ~71 stone  
fill ~35 ~1 ~56 ~47 ~1 ~56 stone  
fill ~35 ~1 ~72 ~47 ~1 ~72 stone  
fill ~36 ~1 ~55 ~46 ~1 ~55 stone  
fill ~36 ~1 ~73 ~46 ~1 ~73 stone  
fill ~42 ~1 ~99 ~53 ~1 ~99 snow_layer  
fill ~45 ~1 ~57 ~48 ~1 ~57 stone  
fill ~45 ~1 ~71 ~48 ~1 ~71 stone  
fill ~46 ~1 ~58 ~49 ~1 ~58 stone  
fill ~46 ~1 ~70 ~49 ~1 ~70 stone  
fill ~47 ~1 ~59 ~50 ~1 ~59 stone  
fill ~47 ~1 ~69 ~50 ~1 ~69 stone  
fill ~48 ~1 ~60 ~50 ~1 ~60 stone  
fill ~48 ~1 ~68 ~50 ~1 ~68 stone  
fill ~49 ~1 ~61 ~51 ~1 ~61 stone  
fill ~49 ~1 ~62 ~51 ~1 ~62 stone  
fill ~49 ~1 ~63 ~51 ~1 ~63 stone  
fill ~49 ~1 ~64 ~51 ~1 ~64 stone  
fill ~49 ~1 ~65 ~51 ~1 ~65 stone  
fill ~49 ~1 ~66 ~51 ~1 ~66 stone  
fill ~49 ~1 ~67 ~51 ~1 ~67 stone  
fill ~61 ~1 ~41 ~72 ~1 ~41 stone  
fill ~61 ~1 ~87 ~72 ~1 ~87 stone  
fill ~64 ~1 ~84 ~64 ~12 ~84 dirt  
fill ~70 ~1 ~49 ~71 ~1 ~49 dirt  
fill ~72 ~1 ~47 ~72 ~5 ~47 stone  
fill ~72 ~1 ~48 ~72 ~5 ~48 stone  
fill ~72 ~1 ~49 ~72 ~5 ~49 stone  
fill ~72 ~1 ~50 ~72 ~5 ~50 stone  
fill ~72 ~1 ~51 ~72 ~5 ~51 stone  
fill ~72 ~1 ~52 ~72 ~5 ~52 stone  
fill ~72 ~1 ~53 ~72 ~5 ~53 stone  
fill ~72 ~1 ~54 ~72 ~5 ~54 stone  
fill ~72 ~1 ~55 ~72 ~5 ~55 stone  
fill ~72 ~1 ~56 ~72 ~5 ~56 stone  
fill ~72 ~1 ~57 ~72 ~5 ~57 stone  
fill ~72 ~1 ~58 ~72 ~5 ~58 stone  
fill ~72 ~1 ~59 ~72 ~5 ~59 stone  
fill ~72 ~1 ~60 ~72 ~5 ~60 stone  
fill ~72 ~1 ~61 ~72 ~5 ~61 stone  
fill ~72 ~1 ~62 ~72 ~5 ~62 stone  
fill ~72 ~1 ~63 ~72 ~5 ~63 stone  
fill ~72 ~1 ~64 ~72 ~5 ~64 stone  
fill ~72 ~1 ~65 ~72 ~5 ~65 stone  
fill ~72 ~1 ~66 ~72 ~5 ~66 stone  
fill ~72 ~1 ~67 ~72 ~5 ~67 stone  
fill ~72 ~1 ~68 ~72 ~5 ~68 stone  
fill ~72 ~1 ~69 ~72 ~5 ~69 stone  
fill ~72 ~1 ~70 ~72 ~5 ~70 stone  
fill ~72 ~1 ~71 ~72 ~5 ~71 stone  
fill ~72 ~1 ~72 ~72 ~5 ~72 stone  
fill ~72 ~1 ~73 ~72 ~5 ~73 stone  
fill ~72 ~1 ~74 ~72 ~5 ~74 stone  
fill ~72 ~1 ~75 ~72 ~5 ~75 stone  
fill ~72 ~1 ~76 ~72 ~5 ~76 stone  
fill ~72 ~1 ~77 ~72 ~5 ~77 stone  
fill ~72 ~1 ~78 ~72 ~5 ~78 stone  
fill ~72 ~1 ~79 ~72 ~5 ~79 stone  
fill ~72 ~1 ~80 ~72 ~5 ~80 stone  
fill ~72 ~1 ~81 ~72 ~5 ~81 stone 
setblock ~73 ~1 ~47 snow_layer 0 
setblock ~73 ~1 ~53 snow_layer 0 
setblock ~73 ~1 ~72 snow_layer 0 
setblock ~73 ~1 ~74 snow_layer 0 
setblock ~73 ~1 ~76 snow_layer 0 
setblock ~73 ~1 ~78 snow_layer 0  
fill ~73 ~1 ~80 ~73 ~1 ~81 snow_layer  
fill ~4 ~2 ~42 ~16 ~2 ~42 stone  
fill ~4 ~2 ~88 ~14 ~2 ~88 snow_layer  
fill ~5 ~2 ~43 ~5 ~8 ~43 stone  
fill ~5 ~2 ~44 ~5 ~8 ~44 stone  
fill ~5 ~2 ~45 ~5 ~8 ~45 stone  
fill ~5 ~2 ~46 ~5 ~8 ~46 stone  
fill ~5 ~2 ~47 ~5 ~8 ~47 stone  
fill ~5 ~2 ~48 ~5 ~8 ~48 stone  
fill ~5 ~2 ~49 ~5 ~8 ~49 stone  
fill ~5 ~2 ~50 ~5 ~8 ~50 stone  
fill ~5 ~2 ~51 ~5 ~8 ~51 stone  
fill ~5 ~2 ~79 ~5 ~8 ~79 stone  
fill ~5 ~2 ~80 ~5 ~8 ~80 stone  
fill ~5 ~2 ~81 ~5 ~8 ~81 stone  
fill ~5 ~2 ~82 ~5 ~8 ~82 stone  
fill ~5 ~2 ~83 ~5 ~8 ~83 stone  
fill ~5 ~2 ~84 ~5 ~8 ~84 stone  
fill ~5 ~2 ~85 ~5 ~8 ~85 stone  
fill ~5 ~2 ~86 ~5 ~8 ~86 stone  
fill ~5 ~2 ~87 ~16 ~2 ~87 stone  
fill ~6 ~2 ~78 ~6 ~7 ~78 dirt  
fill ~15 ~2 ~31 ~61 ~2 ~31 stone  
fill ~15 ~2 ~88 ~16 ~2 ~88 stone  
fill ~15 ~2 ~99 ~31 ~2 ~99 snow_layer  
fill ~16 ~2 ~32 ~16 ~8 ~32 stone  
fill ~16 ~2 ~33 ~16 ~8 ~33 stone  
fill ~16 ~2 ~34 ~16 ~8 ~34 stone  
fill ~16 ~2 ~35 ~16 ~8 ~35 stone  
fill ~16 ~2 ~36 ~16 ~8 ~36 stone  
fill ~16 ~2 ~37 ~16 ~8 ~37 stone  
fill ~16 ~2 ~38 ~16 ~8 ~38 stone  
fill ~16 ~2 ~39 ~16 ~8 ~39 stone  
fill ~16 ~2 ~40 ~16 ~8 ~40 stone  
fill ~16 ~2 ~41 ~16 ~8 ~41 stone  
fill ~16 ~2 ~89 ~16 ~8 ~89 stone  
fill ~16 ~2 ~90 ~16 ~8 ~90 stone  
fill ~16 ~2 ~91 ~16 ~8 ~91 stone  
fill ~16 ~2 ~92 ~16 ~8 ~92 stone  
fill ~16 ~2 ~93 ~16 ~8 ~93 stone  
fill ~16 ~2 ~94 ~16 ~8 ~94 stone  
fill ~16 ~2 ~95 ~16 ~8 ~95 stone  
fill ~16 ~2 ~96 ~16 ~8 ~96 stone  
fill ~16 ~2 ~97 ~16 ~8 ~97 stone  
fill ~16 ~2 ~98 ~61 ~2 ~98 stone  
fill ~17 ~2 ~35 ~17 ~3 ~35 dirt  
fill ~26 ~2 ~30 ~35 ~2 ~30 snow_layer 
setblock ~33 ~2 ~99 snow_layer 0 
setblock ~34 ~2 ~60 glowstone 0  
fill ~34 ~2 ~61 ~36 ~2 ~61 stone  
fill ~34 ~2 ~62 ~36 ~2 ~62 stone  
fill ~34 ~2 ~63 ~36 ~2 ~63 stone  
fill ~34 ~2 ~64 ~36 ~2 ~64 stone  
fill ~34 ~2 ~65 ~36 ~2 ~65 stone  
fill ~34 ~2 ~66 ~36 ~2 ~66 stone  
fill ~34 ~2 ~67 ~36 ~2 ~67 stone 
setblock ~34 ~2 ~68 glowstone 0 
setblock ~35 ~2 ~59 glowstone 0  
fill ~35 ~2 ~60 ~37 ~2 ~60 stone  
fill ~35 ~2 ~68 ~37 ~2 ~68 stone 
setblock ~35 ~2 ~69 glowstone 0 
setblock ~36 ~2 ~58 glowstone 0  
fill ~36 ~2 ~59 ~46 ~2 ~59 stone  
fill ~36 ~2 ~69 ~46 ~2 ~69 stone 
setblock ~36 ~2 ~70 glowstone 0  
fill ~37 ~2 ~30 ~40 ~2 ~30 snow_layer 
setblock ~37 ~2 ~57 glowstone 0  
fill ~37 ~2 ~58 ~45 ~2 ~58 stone  
fill ~37 ~2 ~70 ~45 ~2 ~70 stone 
setblock ~37 ~2 ~71 glowstone 0  
fill ~38 ~2 ~57 ~44 ~2 ~57 stone  
fill ~38 ~2 ~71 ~44 ~2 ~71 stone  
fill ~42 ~2 ~30 ~49 ~2 ~30 snow_layer 
setblock ~45 ~2 ~57 glowstone 0  
fill ~45 ~2 ~60 ~47 ~2 ~60 stone  
fill ~45 ~2 ~68 ~47 ~2 ~68 stone 
setblock ~45 ~2 ~71 glowstone 0 
setblock ~46 ~2 ~58 glowstone 0  
fill ~46 ~2 ~61 ~48 ~2 ~61 stone  
fill ~46 ~2 ~62 ~48 ~2 ~62 stone  
fill ~46 ~2 ~63 ~48 ~2 ~63 stone  
fill ~46 ~2 ~64 ~48 ~2 ~64 stone  
fill ~46 ~2 ~65 ~48 ~2 ~65 stone  
fill ~46 ~2 ~66 ~48 ~2 ~66 stone  
fill ~46 ~2 ~67 ~48 ~2 ~67 stone 
setblock ~46 ~2 ~70 glowstone 0 
setblock ~47 ~2 ~59 glowstone 0 
setblock ~47 ~2 ~69 glowstone 0 
setblock ~48 ~2 ~60 glowstone 0 
setblock ~48 ~2 ~68 glowstone 0  
fill ~50 ~2 ~30 ~61 ~2 ~30 stone  
fill ~52 ~2 ~34 ~52 ~11 ~34 dirt  
fill ~56 ~2 ~33 ~56 ~7 ~33 dirt  
fill ~61 ~2 ~41 ~72 ~2 ~41 stone  
fill ~61 ~2 ~42 ~72 ~2 ~42 stone  
fill ~61 ~2 ~87 ~72 ~2 ~87 stone  
fill ~70 ~2 ~49 ~71 ~2 ~49 dirt  
fill ~4 ~3 ~42 ~4 ~3 ~50 snow_layer  
fill ~4 ~3 ~80 ~4 ~3 ~87 snow_layer  
fill ~5 ~3 ~42 ~16 ~3 ~42 stone  
fill ~5 ~3 ~52 ~5 ~8 ~52 stone  
fill ~5 ~3 ~53 ~5 ~8 ~53 stone  
fill ~5 ~3 ~54 ~5 ~8 ~54 stone  
fill ~5 ~3 ~55 ~5 ~8 ~55 stone  
fill ~5 ~3 ~56 ~5 ~8 ~56 stone  
fill ~5 ~3 ~57 ~5 ~8 ~57 stone  
fill ~5 ~3 ~58 ~5 ~8 ~58 stone  
fill ~5 ~3 ~59 ~5 ~8 ~59 stone  
fill ~5 ~3 ~60 ~5 ~8 ~60 stone  
fill ~5 ~3 ~61 ~5 ~8 ~61 stone  
fill ~5 ~3 ~62 ~5 ~8 ~62 stone  
fill ~5 ~3 ~63 ~5 ~8 ~63 stone  
fill ~5 ~3 ~64 ~5 ~8 ~64 stone  
fill ~5 ~3 ~65 ~5 ~8 ~65 stone  
fill ~5 ~3 ~66 ~5 ~8 ~66 stone  
fill ~5 ~3 ~67 ~5 ~8 ~67 stone  
fill ~5 ~3 ~68 ~5 ~8 ~68 stone  
fill ~5 ~3 ~69 ~5 ~8 ~69 stone  
fill ~5 ~3 ~70 ~5 ~8 ~70 stone  
fill ~5 ~3 ~71 ~5 ~8 ~71 stone  
fill ~5 ~3 ~72 ~5 ~8 ~72 stone  
fill ~5 ~3 ~73 ~5 ~8 ~73 stone  
fill ~5 ~3 ~74 ~5 ~8 ~74 stone  
fill ~5 ~3 ~75 ~5 ~8 ~75 stone  
fill ~5 ~3 ~76 ~5 ~8 ~76 stone  
fill ~5 ~3 ~77 ~5 ~8 ~77 stone  
fill ~5 ~3 ~78 ~5 ~8 ~78 stone  
fill ~5 ~3 ~87 ~16 ~3 ~87 stone  
fill ~15 ~3 ~31 ~15 ~3 ~41 snow_layer  
fill ~15 ~3 ~88 ~15 ~3 ~98 snow_layer  
fill ~16 ~3 ~31 ~61 ~3 ~31 stone  
fill ~16 ~3 ~88 ~16 ~8 ~88 stone  
fill ~16 ~3 ~98 ~61 ~3 ~98 stone  
fill ~21 ~3 ~33 ~21 ~3 ~34 dirt  
fill ~37 ~3 ~61 ~37 ~3 ~67 stone  
fill ~38 ~3 ~60 ~44 ~3 ~60 stone 
setblock ~38 ~3 ~61 glowstone 0  
fill ~38 ~3 ~62 ~45 ~3 ~62 stone  
fill ~38 ~3 ~63 ~39 ~3 ~63 stone  
fill ~38 ~3 ~64 ~45 ~3 ~64 stone  
fill ~38 ~3 ~65 ~39 ~3 ~65 stone  
fill ~38 ~3 ~66 ~45 ~3 ~66 stone 
setblock ~38 ~3 ~67 glowstone 0  
fill ~38 ~3 ~68 ~44 ~3 ~68 stone  
fill ~39 ~3 ~32 ~39 ~5 ~32 dirt  
fill ~39 ~3 ~61 ~43 ~3 ~61 stone  
fill ~39 ~3 ~67 ~43 ~3 ~67 stone 
setblock ~40 ~3 ~63 glowstone 0 
setblock ~40 ~3 ~65 glowstone 0 
setblock ~41 ~3 ~63 stone 0 
setblock ~41 ~3 ~65 stone 0 
setblock ~42 ~3 ~63 glowstone 0 
setblock ~42 ~3 ~65 glowstone 0  
fill ~43 ~3 ~63 ~45 ~3 ~63 stone  
fill ~43 ~3 ~65 ~45 ~3 ~65 stone 
setblock ~44 ~3 ~61 glowstone 0 
setblock ~44 ~3 ~67 glowstone 0 
setblock ~45 ~3 ~61 stone 0 
setblock ~45 ~3 ~67 stone 0  
fill ~50 ~3 ~30 ~61 ~3 ~30 snow_layer  
fill ~61 ~3 ~41 ~61 ~5 ~41 stone  
fill ~61 ~3 ~42 ~72 ~3 ~42 stone  
fill ~61 ~3 ~87 ~72 ~3 ~87 stone  
fill ~62 ~3 ~41 ~70 ~3 ~41 snow_layer  
fill ~70 ~3 ~49 ~70 ~5 ~49 dirt 
setblock ~73 ~3 ~64 wall_sign 5  
fill ~4 ~4 ~51 ~4 ~4 ~79 snow_layer  
fill ~5 ~4 ~42 ~16 ~4 ~42 stone  
fill ~5 ~4 ~87 ~16 ~4 ~87 stone  
fill ~16 ~4 ~31 ~61 ~4 ~31 stone  
fill ~16 ~4 ~98 ~61 ~4 ~98 stone 
setblock ~17 ~4 ~33 dirt 0  
fill ~21 ~4 ~34 ~21 ~7 ~34 dirt  
fill ~61 ~4 ~42 ~72 ~4 ~42 stone  
fill ~61 ~4 ~86 ~72 ~4 ~86 stone  
fill ~61 ~4 ~87 ~72 ~4 ~87 stone  
fill ~5 ~5 ~42 ~16 ~5 ~42 stone  
fill ~5 ~5 ~87 ~16 ~5 ~87 stone  
fill ~6 ~5 ~43 ~16 ~5 ~43 stone  
fill ~16 ~5 ~31 ~61 ~5 ~31 stone  
fill ~16 ~5 ~98 ~61 ~5 ~98 stone  
fill ~17 ~5 ~32 ~19 ~5 ~32 stone  
fill ~45 ~5 ~97 ~61 ~5 ~97 stone  
fill ~60 ~5 ~32 ~60 ~10 ~32 stone  
fill ~60 ~5 ~33 ~60 ~10 ~33 stone  
fill ~60 ~5 ~34 ~60 ~10 ~34 stone  
fill ~60 ~5 ~35 ~60 ~10 ~35 stone  
fill ~60 ~5 ~36 ~60 ~10 ~36 stone  
fill ~60 ~5 ~37 ~60 ~10 ~37 stone  
fill ~60 ~5 ~38 ~60 ~10 ~38 stone  
fill ~60 ~5 ~39 ~60 ~10 ~39 stone  
fill ~60 ~5 ~40 ~60 ~10 ~40 stone  
fill ~60 ~5 ~41 ~60 ~10 ~41 stone  
fill ~60 ~5 ~42 ~72 ~5 ~42 stone  
fill ~60 ~5 ~86 ~72 ~5 ~86 stone  
fill ~60 ~5 ~87 ~61 ~5 ~87 stone  
fill ~60 ~5 ~88 ~60 ~10 ~88 stone  
fill ~60 ~5 ~89 ~60 ~10 ~89 stone  
fill ~60 ~5 ~90 ~60 ~10 ~90 stone  
fill ~60 ~5 ~91 ~60 ~10 ~91 stone  
fill ~60 ~5 ~92 ~60 ~10 ~92 stone  
fill ~60 ~5 ~93 ~60 ~10 ~93 stone  
fill ~60 ~5 ~94 ~60 ~10 ~94 stone  
fill ~60 ~5 ~95 ~60 ~10 ~95 stone  
fill ~60 ~5 ~96 ~60 ~10 ~96 stone  
fill ~62 ~5 ~87 ~69 ~5 ~87 snow_layer  
fill ~71 ~5 ~43 ~71 ~10 ~43 stone  
fill ~71 ~5 ~44 ~71 ~10 ~44 stone  
fill ~71 ~5 ~45 ~71 ~10 ~45 stone  
fill ~71 ~5 ~46 ~71 ~10 ~46 stone  
fill ~71 ~5 ~47 ~71 ~10 ~47 stone  
fill ~71 ~5 ~48 ~71 ~10 ~48 stone  
fill ~71 ~5 ~49 ~71 ~10 ~49 stone  
fill ~71 ~5 ~50 ~71 ~10 ~50 stone  
fill ~71 ~5 ~51 ~71 ~10 ~51 stone  
fill ~71 ~5 ~52 ~71 ~10 ~52 stone  
fill ~71 ~5 ~53 ~71 ~10 ~53 stone  
fill ~71 ~5 ~54 ~71 ~10 ~54 stone  
fill ~71 ~5 ~55 ~71 ~10 ~55 stone  
fill ~71 ~5 ~56 ~71 ~10 ~56 stone  
fill ~71 ~5 ~57 ~71 ~10 ~57 stone  
fill ~71 ~5 ~58 ~71 ~10 ~58 stone  
fill ~71 ~5 ~59 ~71 ~10 ~59 stone  
fill ~71 ~5 ~60 ~71 ~10 ~60 stone  
fill ~71 ~5 ~61 ~71 ~10 ~61 stone  
fill ~71 ~5 ~62 ~71 ~10 ~62 stone  
fill ~71 ~5 ~63 ~71 ~10 ~63 stone  
fill ~71 ~5 ~64 ~71 ~10 ~64 stone  
fill ~71 ~5 ~65 ~71 ~10 ~65 stone  
fill ~71 ~5 ~66 ~71 ~10 ~66 stone  
fill ~71 ~5 ~67 ~71 ~10 ~67 stone  
fill ~71 ~5 ~68 ~71 ~10 ~68 stone  
fill ~71 ~5 ~69 ~71 ~10 ~69 stone  
fill ~71 ~5 ~70 ~71 ~10 ~70 stone  
fill ~71 ~5 ~71 ~71 ~10 ~71 stone  
fill ~71 ~5 ~72 ~71 ~10 ~72 stone  
fill ~71 ~5 ~73 ~71 ~10 ~73 stone  
fill ~71 ~5 ~74 ~71 ~10 ~74 stone  
fill ~71 ~5 ~75 ~71 ~10 ~75 stone  
fill ~71 ~5 ~76 ~71 ~10 ~76 stone  
fill ~71 ~5 ~77 ~71 ~10 ~77 stone  
fill ~71 ~5 ~78 ~71 ~10 ~78 stone  
fill ~71 ~5 ~79 ~71 ~10 ~79 stone  
fill ~71 ~5 ~80 ~71 ~10 ~80 stone  
fill ~71 ~5 ~81 ~71 ~10 ~81 stone  
fill ~71 ~5 ~82 ~71 ~10 ~82 stone  
fill ~71 ~5 ~83 ~71 ~10 ~83 stone  
fill ~71 ~5 ~84 ~71 ~10 ~84 stone  
fill ~71 ~5 ~85 ~71 ~10 ~85 stone  
fill ~5 ~6 ~42 ~15 ~6 ~42 snow_layer  
fill ~5 ~6 ~87 ~16 ~6 ~87 stone  
fill ~6 ~6 ~43 ~16 ~6 ~43 stone  
fill ~13 ~6 ~86 ~16 ~6 ~86 stone 
setblock ~16 ~6 ~31 glowstone 0  
fill ~16 ~6 ~42 ~16 ~8 ~42 stone  
fill ~16 ~6 ~98 ~45 ~6 ~98 stone  
fill ~17 ~6 ~32 ~38 ~6 ~32 stone  
fill ~17 ~6 ~97 ~60 ~6 ~97 stone 
setblock ~18 ~6 ~31 glowstone 0  
fill ~19 ~6 ~31 ~60 ~6 ~31 stone 
setblock ~19 ~6 ~33 dirt 0  
fill ~46 ~6 ~98 ~61 ~6 ~98 snow_layer  
fill ~60 ~6 ~42 ~71 ~6 ~42 stone  
fill ~60 ~6 ~86 ~71 ~6 ~86 stone  
fill ~60 ~6 ~87 ~60 ~10 ~87 stone 
setblock ~61 ~6 ~32 snow_layer 0  
fill ~61 ~6 ~34 ~61 ~6 ~41 snow_layer  
fill ~61 ~6 ~87 ~61 ~6 ~98 snow_layer 
setblock ~72 ~6 ~42 glowstone 0 
setblock ~72 ~6 ~44 glowstone 0 
setblock ~72 ~6 ~46 glowstone 0 
setblock ~72 ~6 ~48 glowstone 0 
setblock ~72 ~6 ~50 glowstone 0 
setblock ~72 ~6 ~52 glowstone 0 
setblock ~72 ~6 ~54 glowstone 0 
setblock ~72 ~6 ~56 glowstone 0 
setblock ~72 ~6 ~58 glowstone 0 
setblock ~72 ~6 ~60 glowstone 0 
setblock ~72 ~6 ~62 glowstone 0 
setblock ~72 ~6 ~64 glowstone 0 
setblock ~72 ~6 ~66 glowstone 0 
setblock ~72 ~6 ~68 glowstone 0 
setblock ~72 ~6 ~70 glowstone 0 
setblock ~72 ~6 ~72 glowstone 0 
setblock ~72 ~6 ~74 glowstone 0 
setblock ~72 ~6 ~76 glowstone 0 
setblock ~72 ~6 ~78 glowstone 0 
setblock ~72 ~6 ~80 glowstone 0 
setblock ~72 ~6 ~82 glowstone 0 
setblock ~72 ~6 ~84 glowstone 0 
setblock ~72 ~6 ~86 glowstone 0  
fill ~5 ~7 ~87 ~13 ~7 ~87 stone  
fill ~6 ~7 ~43 ~16 ~7 ~43 stone  
fill ~6 ~7 ~86 ~16 ~7 ~86 stone  
fill ~14 ~7 ~87 ~15 ~7 ~87 snow_layer  
fill ~16 ~7 ~87 ~16 ~8 ~87 stone  
fill ~16 ~7 ~98 ~45 ~7 ~98 snow_layer  
fill ~17 ~7 ~32 ~60 ~7 ~32 stone  
fill ~17 ~7 ~97 ~60 ~7 ~97 stone  
fill ~19 ~7 ~33 ~19 ~7 ~34 stone  
fill ~19 ~7 ~35 ~22 ~7 ~35 dirt 
setblock ~20 ~7 ~31 glowstone 0 
setblock ~22 ~7 ~31 glowstone 0  
fill ~23 ~7 ~33 ~23 ~7 ~34 cobblestone 
setblock ~24 ~7 ~31 glowstone 0 
setblock ~26 ~7 ~31 glowstone 0 
setblock ~28 ~7 ~31 glowstone 0 
setblock ~30 ~7 ~31 glowstone 0 
setblock ~32 ~7 ~31 glowstone 0 
setblock ~34 ~7 ~31 glowstone 0 
setblock ~36 ~7 ~31 glowstone 0  
fill ~38 ~7 ~31 ~60 ~7 ~31 stone  
fill ~60 ~7 ~42 ~71 ~7 ~42 stone  
fill ~60 ~7 ~43 ~69 ~7 ~43 stone  
fill ~60 ~7 ~86 ~71 ~7 ~86 stone  
fill ~5 ~8 ~87 ~13 ~8 ~87 snow_layer  
fill ~6 ~8 ~43 ~17 ~8 ~43 stone  
fill ~6 ~8 ~44 ~6 ~13 ~44 stone  
fill ~6 ~8 ~45 ~6 ~13 ~45 stone  
fill ~6 ~8 ~46 ~6 ~13 ~46 stone  
fill ~6 ~8 ~47 ~6 ~13 ~47 stone  
fill ~6 ~8 ~48 ~6 ~14 ~48 stone  
fill ~6 ~8 ~49 ~6 ~14 ~49 stone  
fill ~6 ~8 ~50 ~6 ~14 ~50 stone  
fill ~6 ~8 ~51 ~6 ~14 ~51 stone  
fill ~6 ~8 ~52 ~6 ~14 ~52 stone  
fill ~6 ~8 ~53 ~6 ~14 ~53 stone  
fill ~6 ~8 ~54 ~6 ~14 ~54 stone  
fill ~6 ~8 ~55 ~6 ~14 ~55 stone  
fill ~6 ~8 ~56 ~6 ~14 ~56 stone  
fill ~6 ~8 ~57 ~6 ~14 ~57 stone  
fill ~6 ~8 ~58 ~6 ~14 ~58 stone  
fill ~6 ~8 ~59 ~6 ~14 ~59 stone  
fill ~6 ~8 ~60 ~6 ~14 ~60 stone  
fill ~6 ~8 ~61 ~6 ~14 ~61 stone  
fill ~6 ~8 ~62 ~6 ~14 ~62 stone  
fill ~6 ~8 ~63 ~6 ~14 ~63 stone  
fill ~6 ~8 ~64 ~6 ~14 ~64 stone  
fill ~6 ~8 ~65 ~6 ~14 ~65 stone  
fill ~6 ~8 ~66 ~6 ~14 ~66 stone  
fill ~6 ~8 ~67 ~6 ~14 ~67 stone  
fill ~6 ~8 ~68 ~6 ~14 ~68 stone  
fill ~6 ~8 ~69 ~6 ~14 ~69 stone  
fill ~6 ~8 ~70 ~6 ~14 ~70 stone  
fill ~6 ~8 ~71 ~6 ~14 ~71 stone  
fill ~6 ~8 ~72 ~6 ~14 ~72 stone  
fill ~6 ~8 ~73 ~6 ~14 ~73 stone  
fill ~6 ~8 ~74 ~6 ~14 ~74 stone  
fill ~6 ~8 ~75 ~6 ~14 ~75 stone  
fill ~6 ~8 ~76 ~6 ~14 ~76 stone  
fill ~6 ~8 ~77 ~6 ~14 ~77 stone  
fill ~6 ~8 ~78 ~6 ~14 ~78 stone  
fill ~6 ~8 ~79 ~6 ~14 ~79 stone  
fill ~6 ~8 ~80 ~6 ~14 ~80 stone  
fill ~6 ~8 ~81 ~6 ~14 ~81 stone  
fill ~6 ~8 ~82 ~6 ~13 ~82 stone  
fill ~6 ~8 ~83 ~6 ~13 ~83 stone  
fill ~6 ~8 ~84 ~6 ~13 ~84 stone  
fill ~6 ~8 ~85 ~6 ~13 ~85 stone  
fill ~6 ~8 ~86 ~17 ~8 ~86 stone  
fill ~17 ~8 ~32 ~60 ~8 ~32 stone  
fill ~17 ~8 ~33 ~17 ~14 ~33 stone  
fill ~17 ~8 ~34 ~17 ~14 ~34 stone  
fill ~17 ~8 ~35 ~17 ~14 ~35 stone  
fill ~17 ~8 ~36 ~17 ~14 ~36 stone  
fill ~17 ~8 ~37 ~17 ~14 ~37 stone  
fill ~17 ~8 ~38 ~17 ~14 ~38 stone  
fill ~17 ~8 ~39 ~17 ~14 ~39 stone  
fill ~17 ~8 ~40 ~17 ~14 ~40 stone  
fill ~17 ~8 ~41 ~17 ~14 ~41 stone  
fill ~17 ~8 ~42 ~17 ~14 ~42 stone  
fill ~17 ~8 ~87 ~17 ~14 ~87 stone  
fill ~17 ~8 ~88 ~17 ~14 ~88 stone  
fill ~17 ~8 ~89 ~17 ~14 ~89 stone  
fill ~17 ~8 ~90 ~17 ~14 ~90 stone  
fill ~17 ~8 ~91 ~17 ~14 ~91 stone  
fill ~17 ~8 ~92 ~17 ~14 ~92 stone  
fill ~17 ~8 ~93 ~17 ~14 ~93 stone  
fill ~17 ~8 ~94 ~17 ~14 ~94 stone  
fill ~17 ~8 ~95 ~17 ~14 ~95 stone  
fill ~17 ~8 ~96 ~17 ~14 ~96 stone  
fill ~17 ~8 ~97 ~60 ~8 ~97 stone 
setblock ~18 ~8 ~33 dirt 0  
fill ~18 ~8 ~34 ~18 ~10 ~34 cobblestone 
setblock ~19 ~8 ~34 stone 0  
fill ~19 ~8 ~35 ~22 ~8 ~35 snow_layer  
fill ~23 ~8 ~34 ~23 ~15 ~34 cobblestone 
setblock ~38 ~8 ~31 glowstone 0 
setblock ~40 ~8 ~31 glowstone 0 
setblock ~42 ~8 ~31 glowstone 0 
setblock ~44 ~8 ~31 glowstone 0 
setblock ~46 ~8 ~31 glowstone 0 
setblock ~48 ~8 ~31 glowstone 0 
setblock ~50 ~8 ~31 glowstone 0 
setblock ~52 ~8 ~31 glowstone 0 
setblock ~54 ~8 ~31 glowstone 0 
setblock ~56 ~8 ~31 glowstone 0 
setblock ~58 ~8 ~31 glowstone 0 
setblock ~60 ~8 ~31 glowstone 0  
fill ~60 ~8 ~42 ~71 ~8 ~42 stone  
fill ~60 ~8 ~43 ~71 ~8 ~43 stone  
fill ~60 ~8 ~86 ~71 ~8 ~86 stone  
fill ~5 ~9 ~44 ~5 ~9 ~86 snow_layer  
fill ~6 ~9 ~43 ~17 ~9 ~43 stone  
fill ~6 ~9 ~86 ~17 ~9 ~86 stone 
setblock ~16 ~9 ~32 glowstone 0 
setblock ~16 ~9 ~34 glowstone 0 
setblock ~16 ~9 ~36 glowstone 0 
setblock ~16 ~9 ~38 glowstone 0 
setblock ~16 ~9 ~40 glowstone 0 
setblock ~16 ~9 ~42 glowstone 0  
fill ~16 ~9 ~87 ~16 ~9 ~97 snow_layer  
fill ~17 ~9 ~32 ~60 ~9 ~32 stone  
fill ~17 ~9 ~97 ~60 ~9 ~97 stone 
setblock ~19 ~9 ~34 dirt 0  
fill ~20 ~9 ~34 ~20 ~10 ~34 stone  
fill ~60 ~9 ~42 ~71 ~9 ~42 stone  
fill ~60 ~9 ~43 ~71 ~9 ~43 stone  
fill ~60 ~9 ~86 ~71 ~9 ~86 stone  
fill ~6 ~10 ~43 ~17 ~10 ~43 stone  
fill ~6 ~10 ~86 ~17 ~10 ~86 stone  
fill ~7 ~10 ~44 ~7 ~16 ~44 stone  
fill ~17 ~10 ~32 ~60 ~10 ~32 stone  
fill ~17 ~10 ~97 ~60 ~10 ~97 stone 
setblock ~19 ~10 ~35 cobblestone 0  
fill ~54 ~10 ~96 ~60 ~10 ~96 stone  
fill ~59 ~10 ~33 ~59 ~16 ~33 stone  
fill ~59 ~10 ~34 ~59 ~16 ~34 stone  
fill ~59 ~10 ~35 ~59 ~16 ~35 stone  
fill ~59 ~10 ~36 ~59 ~16 ~36 stone  
fill ~59 ~10 ~37 ~59 ~16 ~37 stone  
fill ~59 ~10 ~38 ~59 ~16 ~38 stone  
fill ~59 ~10 ~39 ~59 ~16 ~39 stone  
fill ~59 ~10 ~40 ~59 ~16 ~40 stone  
fill ~59 ~10 ~41 ~59 ~16 ~41 stone  
fill ~59 ~10 ~42 ~71 ~10 ~42 stone  
fill ~59 ~10 ~43 ~71 ~10 ~43 stone  
fill ~59 ~10 ~85 ~71 ~10 ~85 stone  
fill ~59 ~10 ~86 ~71 ~10 ~86 stone  
fill ~59 ~10 ~87 ~59 ~21 ~87 stone  
fill ~59 ~10 ~88 ~59 ~21 ~88 stone  
fill ~59 ~10 ~89 ~59 ~21 ~89 stone  
fill ~59 ~10 ~90 ~59 ~21 ~90 stone  
fill ~59 ~10 ~91 ~59 ~21 ~91 stone  
fill ~59 ~10 ~92 ~59 ~21 ~92 stone  
fill ~59 ~10 ~93 ~59 ~21 ~93 stone  
fill ~59 ~10 ~94 ~59 ~21 ~94 stone  
fill ~59 ~10 ~95 ~59 ~21 ~95 stone  
fill ~70 ~10 ~44 ~70 ~16 ~44 stone  
fill ~70 ~10 ~45 ~70 ~16 ~45 stone  
fill ~70 ~10 ~46 ~70 ~16 ~46 stone  
fill ~70 ~10 ~47 ~70 ~16 ~47 stone  
fill ~70 ~10 ~48 ~70 ~16 ~48 stone  
fill ~70 ~10 ~49 ~70 ~16 ~49 stone  
fill ~70 ~10 ~50 ~70 ~16 ~50 stone  
fill ~70 ~10 ~51 ~70 ~16 ~51 stone  
fill ~70 ~10 ~52 ~70 ~16 ~52 stone  
fill ~70 ~10 ~53 ~70 ~16 ~53 stone  
fill ~70 ~10 ~54 ~70 ~16 ~54 stone  
fill ~70 ~10 ~55 ~70 ~16 ~55 stone  
fill ~70 ~10 ~56 ~70 ~16 ~56 stone  
fill ~70 ~10 ~57 ~70 ~16 ~57 stone  
fill ~70 ~10 ~58 ~70 ~16 ~58 stone  
fill ~70 ~10 ~59 ~70 ~16 ~59 stone  
fill ~70 ~10 ~60 ~70 ~16 ~60 stone  
fill ~70 ~10 ~61 ~70 ~16 ~61 stone  
fill ~70 ~10 ~62 ~70 ~16 ~62 stone  
fill ~70 ~10 ~63 ~70 ~16 ~63 stone  
fill ~70 ~10 ~64 ~70 ~16 ~64 stone  
fill ~70 ~10 ~65 ~70 ~16 ~65 stone  
fill ~70 ~10 ~66 ~70 ~16 ~66 stone  
fill ~70 ~10 ~67 ~70 ~16 ~67 stone  
fill ~70 ~10 ~68 ~70 ~16 ~68 stone  
fill ~70 ~10 ~69 ~70 ~16 ~69 stone  
fill ~70 ~10 ~70 ~70 ~16 ~70 stone  
fill ~70 ~10 ~71 ~70 ~16 ~71 stone  
fill ~70 ~10 ~72 ~70 ~16 ~72 stone  
fill ~70 ~10 ~73 ~70 ~16 ~73 stone  
fill ~70 ~10 ~74 ~70 ~16 ~74 stone  
fill ~70 ~10 ~75 ~70 ~16 ~75 stone  
fill ~70 ~10 ~76 ~70 ~16 ~76 stone  
fill ~70 ~10 ~77 ~70 ~16 ~77 stone  
fill ~70 ~10 ~78 ~70 ~16 ~78 stone  
fill ~70 ~10 ~79 ~70 ~16 ~79 stone  
fill ~70 ~10 ~80 ~70 ~16 ~80 stone  
fill ~70 ~10 ~81 ~70 ~16 ~81 stone  
fill ~70 ~10 ~82 ~70 ~16 ~82 stone  
fill ~70 ~10 ~83 ~70 ~16 ~83 stone  
fill ~70 ~10 ~84 ~70 ~16 ~84 stone 
setblock ~6 ~11 ~43 glowstone 0  
fill ~6 ~11 ~86 ~17 ~11 ~86 stone  
fill ~7 ~11 ~43 ~17 ~11 ~43 stone  
fill ~8 ~11 ~44 ~17 ~11 ~44 stone  
fill ~17 ~11 ~32 ~59 ~11 ~32 stone  
fill ~17 ~11 ~97 ~54 ~11 ~97 stone  
fill ~18 ~11 ~33 ~30 ~11 ~33 stone  
fill ~20 ~11 ~34 ~20 ~13 ~34 cobblestone  
fill ~20 ~11 ~35 ~20 ~11 ~34 cobblestone  
fill ~21 ~11 ~34 ~21 ~12 ~34 dirt  
fill ~30 ~11 ~96 ~59 ~11 ~96 stone 
setblock ~55 ~11 ~97 glowstone 0 
setblock ~57 ~11 ~97 glowstone 0  
fill ~59 ~11 ~42 ~59 ~16 ~42 stone  
fill ~59 ~11 ~43 ~70 ~11 ~43 stone  
fill ~59 ~11 ~85 ~70 ~11 ~85 stone  
fill ~59 ~11 ~86 ~59 ~21 ~86 stone 
setblock ~59 ~11 ~97 glowstone 0 
setblock ~60 ~11 ~32 glowstone 0 
setblock ~60 ~11 ~34 glowstone 0 
setblock ~60 ~11 ~36 glowstone 0 
setblock ~60 ~11 ~38 glowstone 0 
setblock ~60 ~11 ~40 glowstone 0 
setblock ~60 ~11 ~42 glowstone 0 
setblock ~60 ~11 ~86 glowstone 0 
setblock ~60 ~11 ~88 glowstone 0 
setblock ~60 ~11 ~90 glowstone 0 
setblock ~60 ~11 ~92 glowstone 0 
setblock ~60 ~11 ~94 glowstone 0 
setblock ~60 ~11 ~96 glowstone 0 
setblock ~62 ~11 ~42 glowstone 0 
setblock ~62 ~11 ~86 glowstone 0 
setblock ~64 ~11 ~42 glowstone 0 
setblock ~64 ~11 ~86 glowstone 0 
setblock ~66 ~11 ~42 glowstone 0 
setblock ~66 ~11 ~86 glowstone 0 
setblock ~68 ~11 ~42 glowstone 0 
setblock ~68 ~11 ~86 glowstone 0 
setblock ~70 ~11 ~42 glowstone 0 
setblock ~70 ~11 ~86 glowstone 0 
setblock ~71 ~11 ~43 glowstone 0 
setblock ~71 ~11 ~45 glowstone 0 
setblock ~71 ~11 ~47 glowstone 0 
setblock ~71 ~11 ~49 glowstone 0 
setblock ~71 ~11 ~51 glowstone 0 
setblock ~71 ~11 ~53 glowstone 0 
setblock ~71 ~11 ~55 glowstone 0 
setblock ~71 ~11 ~57 glowstone 0 
setblock ~71 ~11 ~59 glowstone 0 
setblock ~71 ~11 ~61 glowstone 0 
setblock ~71 ~11 ~63 glowstone 0 
setblock ~71 ~11 ~65 glowstone 0 
setblock ~71 ~11 ~67 glowstone 0 
setblock ~71 ~11 ~69 glowstone 0 
setblock ~71 ~11 ~71 glowstone 0 
setblock ~71 ~11 ~73 glowstone 0 
setblock ~71 ~11 ~75 glowstone 0 
setblock ~71 ~11 ~77 glowstone 0 
setblock ~71 ~11 ~79 glowstone 0 
setblock ~71 ~11 ~81 glowstone 0 
setblock ~71 ~11 ~83 glowstone 0 
setblock ~71 ~11 ~85 glowstone 0  
fill ~6 ~12 ~86 ~17 ~12 ~86 stone 
setblock ~8 ~12 ~43 glowstone 0  
fill ~8 ~12 ~44 ~17 ~12 ~44 stone  
fill ~8 ~12 ~85 ~17 ~12 ~85 stone 
setblock ~10 ~12 ~43 glowstone 0 
setblock ~12 ~12 ~43 glowstone 0 
setblock ~14 ~12 ~43 glowstone 0 
setblock ~16 ~12 ~43 glowstone 0  
fill ~17 ~12 ~32 ~29 ~12 ~32 snow_layer  
fill ~17 ~12 ~43 ~17 ~14 ~43 stone  
fill ~17 ~12 ~97 ~30 ~12 ~97 stone  
fill ~18 ~12 ~33 ~59 ~12 ~33 stone  
fill ~18 ~12 ~96 ~59 ~12 ~96 stone  
fill ~21 ~12 ~35 ~22 ~12 ~35 cobblestone 
setblock ~22 ~12 ~34 cobblestone 0  
fill ~30 ~12 ~32 ~59 ~12 ~32 stone  

KittysCommands:  
setblock ~31 ~12 ~97 glowstone 0 
setblock ~33 ~12 ~97 glowstone 0 
setblock ~35 ~12 ~97 glowstone 0 
setblock ~37 ~12 ~97 glowstone 0 
setblock ~39 ~12 ~97 glowstone 0 
setblock ~41 ~12 ~97 glowstone 0 
setblock ~43 ~12 ~97 glowstone 0 
setblock ~45 ~12 ~97 glowstone 0 
setblock ~47 ~12 ~97 glowstone 0 
setblock ~49 ~12 ~97 glowstone 0 
setblock ~51 ~12 ~97 glowstone 0  
fill ~52 ~12 ~34 ~52 ~16 ~34 cobblestone 
setblock ~53 ~12 ~97 glowstone 0  
fill ~59 ~12 ~43 ~70 ~12 ~43 stone  
fill ~59 ~12 ~85 ~70 ~12 ~85 stone  
fill ~6 ~13 ~86 ~8 ~13 ~86 stone  
fill ~7 ~13 ~45 ~7 ~19 ~45 stone  
fill ~7 ~13 ~46 ~7 ~19 ~46 stone  
fill ~7 ~13 ~47 ~7 ~19 ~47 stone  
fill ~7 ~13 ~48 ~7 ~19 ~48 stone  
fill ~7 ~13 ~81 ~7 ~19 ~81 stone  
fill ~7 ~13 ~82 ~7 ~19 ~82 stone  
fill ~7 ~13 ~83 ~7 ~19 ~83 stone  
fill ~7 ~13 ~84 ~7 ~19 ~84 stone  
fill ~7 ~13 ~85 ~17 ~13 ~85 stone  
fill ~8 ~13 ~44 ~17 ~13 ~44 stone 
setblock ~10 ~13 ~86 glowstone 0 
setblock ~12 ~13 ~86 glowstone 0 
setblock ~14 ~13 ~86 glowstone 0 
setblock ~16 ~13 ~86 glowstone 0  
fill ~17 ~13 ~86 ~17 ~14 ~86 stone 
setblock ~17 ~13 ~97 glowstone 0  
fill ~18 ~13 ~33 ~59 ~13 ~33 stone  
fill ~18 ~13 ~96 ~59 ~13 ~96 stone 
setblock ~19 ~13 ~97 glowstone 0 
setblock ~21 ~13 ~97 glowstone 0  
fill ~23 ~13 ~35 ~25 ~13 ~35 cobblestone 
setblock ~23 ~13 ~97 glowstone 0  
fill ~24 ~13 ~34 ~25 ~13 ~34 cobblestone 
setblock ~25 ~13 ~36 cobblestone 0 
setblock ~25 ~13 ~97 glowstone 0 
setblock ~27 ~13 ~97 glowstone 0 
setblock ~29 ~13 ~97 glowstone 0  
fill ~30 ~13 ~32 ~35 ~13 ~32 snow_layer  
fill ~37 ~13 ~32 ~40 ~13 ~32 snow_layer  
fill ~42 ~13 ~32 ~58 ~13 ~32 snow_layer  
fill ~59 ~13 ~43 ~70 ~13 ~43 stone  
fill ~59 ~13 ~44 ~70 ~13 ~44 stone  
fill ~59 ~13 ~85 ~70 ~13 ~85 stone 
setblock ~6 ~14 ~44 glowstone 0 
setblock ~6 ~14 ~46 glowstone 0 
setblock ~6 ~14 ~82 glowstone 0 
setblock ~6 ~14 ~84 glowstone 0 
setblock ~6 ~14 ~86 glowstone 0  
fill ~7 ~14 ~49 ~7 ~19 ~49 stone  
fill ~7 ~14 ~50 ~7 ~19 ~50 stone  
fill ~7 ~14 ~51 ~7 ~19 ~51 stone  
fill ~7 ~14 ~52 ~7 ~19 ~52 stone  
fill ~7 ~14 ~53 ~7 ~19 ~53 stone  
fill ~7 ~14 ~54 ~7 ~19 ~54 stone  
fill ~7 ~14 ~55 ~7 ~19 ~55 stone  
fill ~7 ~14 ~56 ~7 ~19 ~56 stone  
fill ~7 ~14 ~57 ~7 ~19 ~57 stone  
fill ~7 ~14 ~58 ~7 ~19 ~58 stone  
fill ~7 ~14 ~59 ~7 ~19 ~59 stone  
fill ~7 ~14 ~60 ~7 ~19 ~60 stone  
fill ~7 ~14 ~61 ~7 ~19 ~61 stone  
fill ~7 ~14 ~62 ~7 ~19 ~62 stone  
fill ~7 ~14 ~63 ~7 ~19 ~63 stone  
fill ~7 ~14 ~64 ~7 ~19 ~64 stone  
fill ~7 ~14 ~65 ~7 ~19 ~65 stone  
fill ~7 ~14 ~66 ~7 ~19 ~66 stone  
fill ~7 ~14 ~67 ~7 ~19 ~67 stone  
fill ~7 ~14 ~68 ~7 ~19 ~68 stone  
fill ~7 ~14 ~69 ~7 ~19 ~69 stone  
fill ~7 ~14 ~70 ~7 ~19 ~70 stone  
fill ~7 ~14 ~71 ~7 ~19 ~71 stone  
fill ~7 ~14 ~72 ~7 ~19 ~72 stone  
fill ~7 ~14 ~73 ~7 ~19 ~73 stone  
fill ~7 ~14 ~74 ~7 ~19 ~74 stone  
fill ~7 ~14 ~75 ~7 ~19 ~75 stone  
fill ~7 ~14 ~76 ~7 ~19 ~76 stone  
fill ~7 ~14 ~77 ~7 ~19 ~77 stone  
fill ~7 ~14 ~78 ~7 ~19 ~78 stone  
fill ~7 ~14 ~79 ~7 ~19 ~79 stone  
fill ~7 ~14 ~80 ~7 ~19 ~80 stone  
fill ~7 ~14 ~85 ~18 ~14 ~85 stone  
fill ~8 ~14 ~44 ~18 ~14 ~44 stone 
setblock ~8 ~14 ~86 glowstone 0  
fill ~18 ~14 ~33 ~59 ~14 ~33 stone  
fill ~18 ~14 ~34 ~18 ~19 ~34 stone  
fill ~18 ~14 ~35 ~18 ~19 ~35 stone  
fill ~18 ~14 ~36 ~18 ~19 ~36 stone  
fill ~18 ~14 ~37 ~18 ~19 ~37 stone  
fill ~18 ~14 ~38 ~18 ~19 ~38 stone  
fill ~18 ~14 ~39 ~18 ~19 ~39 stone  
fill ~18 ~14 ~40 ~18 ~19 ~40 stone  
fill ~18 ~14 ~41 ~18 ~19 ~41 stone  
fill ~18 ~14 ~42 ~18 ~19 ~42 stone  
fill ~18 ~14 ~43 ~18 ~19 ~43 stone  
fill ~18 ~14 ~86 ~18 ~19 ~86 stone  
fill ~18 ~14 ~87 ~18 ~19 ~87 stone  
fill ~18 ~14 ~88 ~18 ~19 ~88 stone  
fill ~18 ~14 ~89 ~18 ~19 ~89 stone  
fill ~18 ~14 ~90 ~18 ~19 ~90 stone  
fill ~18 ~14 ~91 ~18 ~19 ~91 stone  
fill ~18 ~14 ~92 ~18 ~19 ~92 stone  
fill ~18 ~14 ~93 ~18 ~19 ~93 stone  
fill ~18 ~14 ~94 ~18 ~19 ~94 stone  
fill ~18 ~14 ~95 ~18 ~19 ~95 stone  
fill ~18 ~14 ~96 ~59 ~14 ~96 stone  
fill ~25 ~14 ~34 ~25 ~14 ~35 cobblestone  
fill ~59 ~14 ~43 ~59 ~16 ~43 stone  
fill ~59 ~14 ~44 ~70 ~14 ~44 stone  
fill ~59 ~14 ~85 ~70 ~14 ~85 stone  
fill ~60 ~14 ~43 ~69 ~14 ~43 snow_layer 
setblock ~70 ~14 ~43 stone 0 
setblock ~6 ~15 ~48 glowstone 0 
setblock ~6 ~15 ~50 glowstone 0 
setblock ~6 ~15 ~52 glowstone 0 
setblock ~6 ~15 ~54 glowstone 0 
setblock ~6 ~15 ~56 glowstone 0 
setblock ~6 ~15 ~58 glowstone 0 
setblock ~6 ~15 ~60 glowstone 0 
setblock ~6 ~15 ~62 glowstone 0 
setblock ~6 ~15 ~64 glowstone 0 
setblock ~6 ~15 ~66 glowstone 0 
setblock ~6 ~15 ~68 glowstone 0 
setblock ~6 ~15 ~70 glowstone 0 
setblock ~6 ~15 ~72 glowstone 0 
setblock ~6 ~15 ~74 glowstone 0 
setblock ~6 ~15 ~76 glowstone 0 
setblock ~6 ~15 ~78 glowstone 0 
setblock ~6 ~15 ~80 glowstone 0  
fill ~7 ~15 ~85 ~18 ~15 ~85 stone  
fill ~8 ~15 ~44 ~18 ~15 ~44 stone  
fill ~17 ~15 ~33 ~17 ~15 ~43 snow_layer 
setblock ~17 ~15 ~86 glowstone 0 
setblock ~17 ~15 ~88 glowstone 0 
setblock ~17 ~15 ~90 glowstone 0 
setblock ~17 ~15 ~92 glowstone 0 
setblock ~17 ~15 ~94 glowstone 0 
setblock ~17 ~15 ~96 glowstone 0  
fill ~18 ~15 ~33 ~59 ~15 ~33 stone  
fill ~18 ~15 ~96 ~59 ~15 ~96 stone  
fill ~25 ~15 ~35 ~25 ~19 ~35 cobblestone  
fill ~59 ~15 ~44 ~70 ~15 ~44 stone  
fill ~59 ~15 ~85 ~70 ~15 ~85 stone 
setblock ~70 ~15 ~43 snow_layer 0  
fill ~7 ~16 ~85 ~18 ~16 ~85 stone  
fill ~8 ~16 ~44 ~18 ~16 ~44 stone  
fill ~8 ~16 ~45 ~16 ~16 ~45 stone  
fill ~18 ~16 ~33 ~59 ~16 ~33 stone  
fill ~18 ~16 ~96 ~59 ~16 ~96 stone  
fill ~19 ~16 ~34 ~24 ~16 ~34 stone  
fill ~40 ~16 ~95 ~59 ~16 ~95 stone  
fill ~58 ~16 ~34 ~58 ~21 ~34 stone  
fill ~58 ~16 ~35 ~58 ~21 ~35 stone  
fill ~58 ~16 ~36 ~58 ~21 ~36 stone  
fill ~58 ~16 ~37 ~58 ~21 ~37 stone  
fill ~58 ~16 ~38 ~58 ~21 ~38 stone  
fill ~58 ~16 ~39 ~58 ~21 ~39 stone  
fill ~58 ~16 ~40 ~58 ~21 ~40 stone  
fill ~58 ~16 ~41 ~58 ~21 ~41 stone  
fill ~58 ~16 ~42 ~58 ~21 ~42 stone  
fill ~58 ~16 ~43 ~58 ~21 ~43 stone  
fill ~58 ~16 ~44 ~70 ~16 ~44 stone  
fill ~58 ~16 ~84 ~70 ~16 ~84 stone  
fill ~58 ~16 ~85 ~70 ~16 ~85 stone  
fill ~58 ~16 ~86 ~58 ~16 ~96 stone  
fill ~69 ~16 ~45 ~69 ~21 ~45 stone  
fill ~69 ~16 ~46 ~69 ~21 ~46 stone  
fill ~69 ~16 ~47 ~69 ~21 ~47 stone  
fill ~69 ~16 ~48 ~69 ~21 ~48 stone  
fill ~69 ~16 ~49 ~69 ~21 ~49 stone  
fill ~69 ~16 ~50 ~69 ~21 ~50 stone  
fill ~69 ~16 ~51 ~69 ~21 ~51 stone  
fill ~69 ~16 ~52 ~69 ~21 ~52 stone  
fill ~69 ~16 ~53 ~69 ~21 ~53 stone  
fill ~69 ~16 ~54 ~69 ~21 ~54 stone  
fill ~69 ~16 ~55 ~69 ~21 ~55 stone  
fill ~69 ~16 ~56 ~69 ~21 ~56 stone  
fill ~69 ~16 ~57 ~69 ~21 ~57 stone  
fill ~69 ~16 ~58 ~69 ~21 ~58 stone  
fill ~69 ~16 ~59 ~69 ~21 ~59 stone  
fill ~69 ~16 ~60 ~69 ~21 ~60 stone  
fill ~69 ~16 ~61 ~69 ~21 ~61 stone  
fill ~69 ~16 ~62 ~69 ~21 ~62 stone  
fill ~69 ~16 ~63 ~69 ~21 ~63 stone  
fill ~69 ~16 ~64 ~69 ~21 ~64 stone  
fill ~69 ~16 ~65 ~69 ~21 ~65 stone  
fill ~69 ~16 ~66 ~69 ~21 ~66 stone  
fill ~69 ~16 ~67 ~69 ~21 ~67 stone  
fill ~69 ~16 ~68 ~69 ~21 ~68 stone  
fill ~69 ~16 ~69 ~69 ~21 ~69 stone  
fill ~69 ~16 ~70 ~69 ~21 ~70 stone  
fill ~69 ~16 ~71 ~69 ~21 ~71 stone  
fill ~69 ~16 ~72 ~69 ~21 ~72 stone  
fill ~69 ~16 ~73 ~69 ~21 ~73 stone  
fill ~69 ~16 ~74 ~69 ~21 ~74 stone  
fill ~69 ~16 ~75 ~69 ~21 ~75 stone  
fill ~69 ~16 ~76 ~69 ~21 ~76 stone  
fill ~69 ~16 ~77 ~69 ~21 ~77 stone  
fill ~69 ~16 ~78 ~69 ~21 ~78 stone  
fill ~69 ~16 ~79 ~69 ~21 ~79 stone  
fill ~69 ~16 ~80 ~69 ~21 ~80 stone  
fill ~69 ~16 ~81 ~69 ~21 ~81 stone  
fill ~69 ~16 ~82 ~69 ~21 ~82 stone  
fill ~69 ~16 ~83 ~69 ~21 ~83 stone  
fill ~7 ~17 ~44 ~15 ~17 ~44 snow_layer  
fill ~7 ~17 ~85 ~18 ~17 ~85 stone  
fill ~8 ~17 ~45 ~18 ~17 ~45 stone  
fill ~16 ~17 ~44 ~18 ~17 ~44 stone  
fill ~18 ~17 ~33 ~23 ~17 ~33 snow_layer  
fill ~18 ~17 ~96 ~40 ~17 ~96 stone  
fill ~19 ~17 ~34 ~50 ~17 ~34 stone  
fill ~19 ~17 ~95 ~59 ~17 ~95 stone  
fill ~24 ~17 ~33 ~58 ~17 ~33 stone  
fill ~41 ~17 ~96 ~59 ~17 ~96 snow_layer  
fill ~58 ~17 ~44 ~69 ~17 ~44 stone  
fill ~58 ~17 ~84 ~58 ~17 ~94 snow_layer  
fill ~59 ~17 ~33 ~59 ~17 ~43 snow_layer  
fill ~59 ~17 ~84 ~69 ~17 ~84 stone  
fill ~59 ~17 ~85 ~59 ~21 ~85 stone  
fill ~60 ~17 ~85 ~70 ~17 ~85 snow_layer  
fill ~70 ~17 ~44 ~70 ~17 ~85 snow_layer  
fill ~7 ~18 ~85 ~18 ~18 ~85 stone  
fill ~8 ~18 ~45 ~18 ~18 ~45 stone  
fill ~8 ~18 ~84 ~18 ~18 ~84 stone  
fill ~16 ~18 ~44 ~17 ~18 ~44 snow_layer  
fill ~18 ~18 ~44 ~18 ~19 ~44 stone  
fill ~18 ~18 ~96 ~40 ~18 ~96 snow_layer  
fill ~19 ~18 ~34 ~58 ~18 ~34 stone  
fill ~19 ~18 ~95 ~59 ~18 ~95 stone  
fill ~24 ~18 ~33 ~35 ~18 ~33 snow_layer  
fill ~37 ~18 ~33 ~40 ~18 ~33 snow_layer  
fill ~42 ~18 ~33 ~48 ~18 ~33 snow_layer  
fill ~49 ~18 ~33 ~58 ~18 ~33 stone  
fill ~58 ~18 ~44 ~69 ~18 ~44 stone  
fill ~58 ~18 ~45 ~62 ~18 ~45 stone  
fill ~59 ~18 ~84 ~69 ~18 ~84 stone  
fill ~7 ~19 ~85 ~17 ~19 ~85 snow_layer  
fill ~8 ~19 ~45 ~19 ~19 ~45 stone  
fill ~8 ~19 ~46 ~8 ~24 ~46 stone  
fill ~8 ~19 ~47 ~8 ~24 ~47 stone  
fill ~8 ~19 ~48 ~8 ~24 ~48 stone  
fill ~8 ~19 ~49 ~8 ~24 ~49 stone  
fill ~8 ~19 ~50 ~8 ~24 ~50 stone  
fill ~8 ~19 ~51 ~8 ~24 ~51 stone  
fill ~8 ~19 ~52 ~8 ~24 ~52 stone  
fill ~8 ~19 ~53 ~8 ~24 ~53 stone  
fill ~8 ~19 ~54 ~8 ~24 ~54 stone  
fill ~8 ~19 ~55 ~8 ~24 ~55 stone  
fill ~8 ~19 ~56 ~8 ~24 ~56 stone  
fill ~8 ~19 ~57 ~8 ~24 ~57 stone  
fill ~8 ~19 ~58 ~8 ~24 ~58 stone  
fill ~8 ~19 ~59 ~8 ~24 ~59 stone  
fill ~8 ~19 ~60 ~8 ~24 ~60 stone  
fill ~8 ~19 ~61 ~8 ~24 ~61 stone  
fill ~8 ~19 ~62 ~8 ~24 ~62 stone  
fill ~8 ~19 ~63 ~8 ~24 ~63 stone  
fill ~8 ~19 ~64 ~8 ~24 ~64 stone  
fill ~8 ~19 ~65 ~8 ~24 ~65 stone  
fill ~8 ~19 ~66 ~8 ~24 ~66 stone  
fill ~8 ~19 ~67 ~8 ~24 ~67 stone  
fill ~8 ~19 ~68 ~8 ~24 ~68 stone  
fill ~8 ~19 ~69 ~8 ~24 ~69 stone  
fill ~8 ~19 ~70 ~8 ~24 ~70 stone  
fill ~8 ~19 ~71 ~8 ~24 ~71 stone  
fill ~8 ~19 ~72 ~8 ~24 ~72 stone  
fill ~8 ~19 ~73 ~8 ~24 ~73 stone  
fill ~8 ~19 ~74 ~8 ~24 ~74 stone  
fill ~8 ~19 ~75 ~8 ~24 ~75 stone  
fill ~8 ~19 ~76 ~8 ~24 ~76 stone  
fill ~8 ~19 ~77 ~8 ~24 ~77 stone  
fill ~8 ~19 ~78 ~8 ~24 ~78 stone  
fill ~8 ~19 ~79 ~8 ~24 ~79 stone  
fill ~8 ~19 ~80 ~8 ~24 ~80 stone  
fill ~8 ~19 ~81 ~8 ~24 ~81 stone  
fill ~8 ~19 ~82 ~8 ~24 ~82 stone  
fill ~8 ~19 ~83 ~8 ~24 ~83 stone  
fill ~8 ~19 ~84 ~19 ~19 ~84 stone  
fill ~18 ~19 ~85 ~19 ~19 ~85 stone  
fill ~19 ~19 ~34 ~58 ~19 ~34 stone  
fill ~19 ~19 ~35 ~19 ~25 ~35 stone  
fill ~19 ~19 ~36 ~19 ~25 ~36 stone  
fill ~19 ~19 ~37 ~19 ~25 ~37 stone  
fill ~19 ~19 ~38 ~19 ~25 ~38 stone  
fill ~19 ~19 ~39 ~19 ~25 ~39 stone  
fill ~19 ~19 ~40 ~19 ~25 ~40 stone  
fill ~19 ~19 ~41 ~19 ~25 ~41 stone  
fill ~19 ~19 ~42 ~19 ~25 ~42 stone  
fill ~19 ~19 ~43 ~19 ~25 ~43 stone  
fill ~19 ~19 ~44 ~19 ~25 ~44 stone  
fill ~19 ~19 ~86 ~19 ~25 ~86 stone  
fill ~19 ~19 ~87 ~19 ~25 ~87 stone  
fill ~19 ~19 ~88 ~19 ~25 ~88 stone  
fill ~19 ~19 ~89 ~19 ~25 ~89 stone  
fill ~19 ~19 ~90 ~19 ~25 ~90 stone  
fill ~19 ~19 ~91 ~19 ~25 ~91 stone  
fill ~19 ~19 ~92 ~19 ~25 ~92 stone  
fill ~19 ~19 ~93 ~19 ~25 ~93 stone  
fill ~19 ~19 ~94 ~19 ~25 ~94 stone  
fill ~19 ~19 ~95 ~59 ~19 ~95 stone  
fill ~49 ~19 ~33 ~58 ~19 ~33 snow_layer  
fill ~58 ~19 ~44 ~58 ~21 ~44 stone  
fill ~58 ~19 ~45 ~69 ~19 ~45 stone  
fill ~59 ~19 ~44 ~61 ~19 ~44 snow_layer  
fill ~59 ~19 ~84 ~69 ~19 ~84 stone  
fill ~62 ~19 ~44 ~69 ~19 ~44 stone  
fill ~7 ~20 ~45 ~7 ~20 ~84 snow_layer  
fill ~8 ~20 ~45 ~19 ~20 ~45 stone  
fill ~8 ~20 ~84 ~19 ~20 ~84 stone  
fill ~18 ~20 ~34 ~18 ~20 ~44 snow_layer  
fill ~18 ~20 ~85 ~18 ~20 ~95 snow_layer  
fill ~19 ~20 ~34 ~58 ~20 ~34 stone  
fill ~19 ~20 ~85 ~19 ~25 ~85 stone  
fill ~19 ~20 ~95 ~59 ~20 ~95 stone  
fill ~58 ~20 ~45 ~69 ~20 ~45 stone  
fill ~59 ~20 ~84 ~69 ~20 ~84 stone  
fill ~62 ~20 ~44 ~69 ~20 ~44 snow_layer  
fill ~8 ~21 ~45 ~19 ~21 ~45 stone  
fill ~8 ~21 ~84 ~19 ~21 ~84 stone  
fill ~19 ~21 ~34 ~58 ~21 ~34 stone  
fill ~19 ~21 ~95 ~59 ~21 ~95 stone  
fill ~53 ~21 ~94 ~59 ~21 ~94 stone  
fill ~57 ~21 ~35 ~57 ~26 ~35 stone  
fill ~57 ~21 ~36 ~57 ~26 ~36 stone  
fill ~57 ~21 ~37 ~57 ~26 ~37 stone  
fill ~57 ~21 ~38 ~57 ~26 ~38 stone  
fill ~57 ~21 ~39 ~57 ~26 ~39 stone  
fill ~57 ~21 ~40 ~57 ~26 ~40 stone  
fill ~57 ~21 ~41 ~57 ~26 ~41 stone  
fill ~57 ~21 ~42 ~57 ~26 ~42 stone  
fill ~57 ~21 ~43 ~57 ~26 ~43 stone  
fill ~57 ~21 ~44 ~57 ~26 ~44 stone  
fill ~57 ~21 ~45 ~69 ~21 ~45 stone  
fill ~58 ~21 ~84 ~69 ~21 ~84 stone  
fill ~58 ~21 ~85 ~58 ~26 ~85 stone  
fill ~58 ~21 ~86 ~58 ~26 ~86 stone  
fill ~58 ~21 ~87 ~58 ~26 ~87 stone  
fill ~58 ~21 ~88 ~58 ~26 ~88 stone  
fill ~58 ~21 ~89 ~58 ~26 ~89 stone  
fill ~58 ~21 ~90 ~58 ~26 ~90 stone  
fill ~58 ~21 ~91 ~58 ~26 ~91 stone  
fill ~58 ~21 ~92 ~58 ~26 ~92 stone  
fill ~58 ~21 ~93 ~58 ~26 ~93 stone  
fill ~67 ~21 ~83 ~69 ~21 ~83 stone  
fill ~68 ~21 ~46 ~68 ~31 ~46 stone  
fill ~68 ~21 ~47 ~68 ~33 ~47 stone  
fill ~68 ~21 ~48 ~68 ~33 ~48 stone  
fill ~68 ~21 ~49 ~68 ~33 ~49 stone  
fill ~68 ~21 ~50 ~68 ~33 ~50 stone  
fill ~68 ~21 ~51 ~68 ~33 ~51 stone  
fill ~68 ~21 ~52 ~68 ~33 ~52 stone  
fill ~68 ~21 ~53 ~68 ~33 ~53 stone  
fill ~68 ~21 ~54 ~68 ~33 ~54 stone  
fill ~68 ~21 ~55 ~68 ~33 ~55 stone  
fill ~68 ~21 ~56 ~68 ~33 ~56 stone  
fill ~68 ~21 ~57 ~68 ~33 ~57 stone  
fill ~68 ~21 ~58 ~68 ~33 ~58 stone  
fill ~68 ~21 ~59 ~68 ~33 ~59 stone  
fill ~68 ~21 ~60 ~68 ~33 ~60 stone  
fill ~68 ~21 ~61 ~68 ~33 ~61 stone  
fill ~68 ~21 ~62 ~68 ~33 ~62 stone  
fill ~68 ~21 ~63 ~68 ~33 ~63 stone  
fill ~68 ~21 ~64 ~68 ~33 ~64 stone  
fill ~68 ~21 ~65 ~68 ~33 ~65 stone  
fill ~68 ~21 ~66 ~68 ~33 ~66 stone  
fill ~68 ~21 ~67 ~68 ~33 ~67 stone  
fill ~68 ~21 ~68 ~68 ~33 ~68 stone  
fill ~68 ~21 ~69 ~68 ~33 ~69 stone  
fill ~68 ~21 ~70 ~68 ~33 ~70 stone  
fill ~68 ~21 ~71 ~68 ~33 ~71 stone  
fill ~68 ~21 ~72 ~68 ~33 ~72 stone  
fill ~68 ~21 ~73 ~68 ~33 ~73 stone  
fill ~68 ~21 ~74 ~68 ~33 ~74 stone  
fill ~68 ~21 ~75 ~68 ~33 ~75 stone  
fill ~68 ~21 ~76 ~68 ~33 ~76 stone  
fill ~68 ~21 ~77 ~68 ~33 ~77 stone  
fill ~68 ~21 ~78 ~68 ~33 ~78 stone  
fill ~68 ~21 ~79 ~68 ~33 ~79 stone  
fill ~68 ~21 ~80 ~68 ~33 ~80 stone  
fill ~68 ~21 ~81 ~68 ~33 ~81 stone  
fill ~68 ~21 ~82 ~68 ~33 ~82 stone  
fill ~8 ~22 ~45 ~19 ~22 ~45 stone  
fill ~8 ~22 ~84 ~19 ~22 ~84 stone  
fill ~9 ~22 ~46 ~19 ~22 ~46 stone  
fill ~19 ~22 ~34 ~57 ~22 ~34 stone  
fill ~19 ~22 ~95 ~53 ~22 ~95 stone  
fill ~20 ~22 ~35 ~42 ~22 ~35 stone  
fill ~28 ~22 ~94 ~58 ~22 ~94 stone  
fill ~54 ~22 ~95 ~59 ~22 ~95 snow_layer  
fill ~57 ~22 ~45 ~68 ~22 ~45 stone  
fill ~58 ~22 ~34 ~58 ~22 ~44 snow_layer  
fill ~58 ~22 ~83 ~68 ~22 ~83 stone  
fill ~58 ~22 ~84 ~67 ~22 ~84 stone  
fill ~59 ~22 ~85 ~59 ~22 ~95 snow_layer 
setblock ~69 ~22 ~45 torch 5  
fill ~69 ~22 ~48 ~69 ~22 ~49 snow_layer 
setblock ~69 ~22 ~52 torch 5 
setblock ~69 ~22 ~57 snow_layer 0 
setblock ~69 ~22 ~62 torch 5 
setblock ~69 ~22 ~70 torch 5 
setblock ~69 ~22 ~73 snow_layer 0 
setblock ~69 ~22 ~77 torch 5 
setblock ~69 ~22 ~81 snow_layer 0 
setblock ~69 ~22 ~84 torch 5  
fill ~8 ~23 ~45 ~18 ~23 ~45 snow_layer  
fill ~8 ~23 ~84 ~19 ~23 ~84 stone  
fill ~9 ~23 ~46 ~19 ~23 ~46 stone  
fill ~19 ~23 ~34 ~35 ~23 ~34 snow_layer  
fill ~19 ~23 ~45 ~19 ~25 ~45 stone  
fill ~19 ~23 ~95 ~28 ~23 ~95 stone  
fill ~20 ~23 ~35 ~57 ~23 ~35 stone  
fill ~20 ~23 ~94 ~58 ~23 ~94 stone  
fill ~29 ~23 ~95 ~53 ~23 ~95 snow_layer  
fill ~37 ~23 ~34 ~40 ~23 ~34 snow_layer  
fill ~42 ~23 ~34 ~57 ~23 ~34 stone  
fill ~57 ~23 ~45 ~68 ~23 ~45 stone  
fill ~58 ~23 ~83 ~68 ~23 ~83 stone  
fill ~58 ~23 ~84 ~58 ~26 ~84 stone  
fill ~59 ~23 ~84 ~67 ~23 ~84 snow_layer  
fill ~8 ~24 ~84 ~19 ~24 ~84 stone  
fill ~9 ~24 ~46 ~19 ~24 ~46 stone  
fill ~9 ~24 ~47 ~9 ~27 ~47 stone  
fill ~9 ~24 ~48 ~9 ~27 ~48 stone  
fill ~9 ~24 ~49 ~9 ~27 ~49 stone  
fill ~9 ~24 ~50 ~9 ~27 ~50 stone  
fill ~9 ~24 ~51 ~9 ~27 ~51 stone  
fill ~9 ~24 ~52 ~9 ~27 ~52 stone  
fill ~9 ~24 ~53 ~9 ~27 ~53 stone  
fill ~9 ~24 ~54 ~9 ~27 ~54 stone  
fill ~9 ~24 ~55 ~9 ~27 ~55 stone  
fill ~9 ~24 ~56 ~9 ~27 ~56 stone  
fill ~9 ~24 ~57 ~9 ~27 ~57 stone  
fill ~9 ~24 ~58 ~9 ~27 ~58 stone  
fill ~9 ~24 ~59 ~9 ~27 ~59 stone  
fill ~9 ~24 ~60 ~9 ~27 ~60 stone  
fill ~9 ~24 ~61 ~9 ~27 ~61 stone  
fill ~9 ~24 ~62 ~9 ~27 ~62 stone  
fill ~9 ~24 ~63 ~9 ~27 ~63 stone  
fill ~9 ~24 ~64 ~9 ~27 ~64 stone  
fill ~9 ~24 ~65 ~9 ~27 ~65 stone  
fill ~9 ~24 ~66 ~9 ~27 ~66 stone  
fill ~9 ~24 ~67 ~9 ~27 ~67 stone  
fill ~9 ~24 ~68 ~9 ~27 ~68 stone  
fill ~9 ~24 ~69 ~9 ~27 ~69 stone  
fill ~9 ~24 ~70 ~9 ~27 ~70 stone  
fill ~9 ~24 ~71 ~9 ~27 ~71 stone  
fill ~9 ~24 ~72 ~9 ~27 ~72 stone  
fill ~9 ~24 ~73 ~9 ~27 ~73 stone  
fill ~9 ~24 ~74 ~9 ~27 ~74 stone  
fill ~9 ~24 ~75 ~9 ~27 ~75 stone  
fill ~9 ~24 ~76 ~9 ~27 ~76 stone  
fill ~9 ~24 ~77 ~9 ~27 ~77 stone  
fill ~9 ~24 ~78 ~9 ~27 ~78 stone  
fill ~9 ~24 ~79 ~9 ~27 ~79 stone  
fill ~9 ~24 ~80 ~9 ~27 ~80 stone  
fill ~9 ~24 ~81 ~9 ~27 ~81 stone  
fill ~9 ~24 ~82 ~9 ~27 ~82 stone  
fill ~9 ~24 ~83 ~19 ~24 ~83 stone  
fill ~19 ~24 ~95 ~28 ~24 ~95 snow_layer  
fill ~20 ~24 ~35 ~57 ~24 ~35 stone  
fill ~20 ~24 ~94 ~58 ~24 ~94 stone  
fill ~42 ~24 ~34 ~57 ~24 ~34 snow_layer  
fill ~57 ~24 ~45 ~68 ~24 ~45 stone  
fill ~57 ~24 ~46 ~68 ~24 ~46 stone  
fill ~58 ~24 ~83 ~68 ~24 ~83 stone  
fill ~8 ~25 ~46 ~8 ~25 ~84 snow_layer  
fill ~9 ~25 ~46 ~20 ~25 ~46 stone  
fill ~9 ~25 ~83 ~20 ~25 ~83 stone  
fill ~9 ~25 ~84 ~18 ~25 ~84 snow_layer  
fill ~19 ~25 ~84 ~20 ~25 ~84 stone  
fill ~20 ~25 ~35 ~57 ~25 ~35 stone  
fill ~20 ~25 ~36 ~20 ~32 ~36 stone  
fill ~20 ~25 ~37 ~20 ~32 ~37 stone  
fill ~20 ~25 ~38 ~20 ~32 ~38 stone  
fill ~20 ~25 ~39 ~20 ~32 ~39 stone  
fill ~20 ~25 ~40 ~20 ~32 ~40 stone  
fill ~20 ~25 ~41 ~20 ~32 ~41 stone  
fill ~20 ~25 ~42 ~20 ~32 ~42 stone  
fill ~20 ~25 ~43 ~20 ~32 ~43 stone  
fill ~20 ~25 ~44 ~20 ~32 ~44 stone  
fill ~20 ~25 ~45 ~20 ~32 ~45 stone  
fill ~20 ~25 ~85 ~20 ~32 ~85 stone  
fill ~20 ~25 ~86 ~20 ~32 ~86 stone  
fill ~20 ~25 ~87 ~20 ~32 ~87 stone  
fill ~20 ~25 ~88 ~20 ~32 ~88 stone  
fill ~20 ~25 ~89 ~20 ~32 ~89 stone  
fill ~20 ~25 ~90 ~20 ~32 ~90 stone  
fill ~20 ~25 ~91 ~20 ~32 ~91 stone  
fill ~20 ~25 ~92 ~20 ~32 ~92 stone  
fill ~20 ~25 ~93 ~20 ~32 ~93 stone  
fill ~20 ~25 ~94 ~58 ~25 ~94 stone  
fill ~57 ~25 ~45 ~57 ~26 ~45 stone  
fill ~57 ~25 ~46 ~68 ~25 ~46 stone  
fill ~58 ~25 ~45 ~68 ~25 ~45 snow_layer  
fill ~58 ~25 ~83 ~68 ~25 ~83 stone  
fill ~9 ~26 ~46 ~20 ~26 ~46 stone  
fill ~9 ~26 ~83 ~20 ~26 ~83 stone  
fill ~19 ~26 ~35 ~19 ~26 ~45 snow_layer  
fill ~19 ~26 ~84 ~19 ~26 ~94 snow_layer  
fill ~20 ~26 ~35 ~57 ~26 ~35 stone  
fill ~20 ~26 ~84 ~20 ~32 ~84 stone  
fill ~20 ~26 ~94 ~58 ~26 ~94 stone  
fill ~56 ~26 ~36 ~56 ~28 ~36 stone  
fill ~56 ~26 ~37 ~56 ~28 ~37 stone  
fill ~56 ~26 ~38 ~56 ~28 ~38 stone  
fill ~56 ~26 ~39 ~56 ~28 ~39 stone  
fill ~56 ~26 ~40 ~56 ~28 ~40 stone  
fill ~56 ~26 ~41 ~56 ~28 ~41 stone  
fill ~56 ~26 ~42 ~56 ~28 ~42 stone  
fill ~56 ~26 ~43 ~56 ~28 ~43 stone  
fill ~56 ~26 ~44 ~56 ~28 ~44 stone  
fill ~56 ~26 ~45 ~56 ~28 ~45 stone  
fill ~56 ~26 ~46 ~68 ~26 ~46 stone  
fill ~57 ~26 ~83 ~68 ~26 ~83 stone  
fill ~57 ~26 ~84 ~57 ~28 ~84 stone  
fill ~57 ~26 ~85 ~57 ~28 ~85 stone  
fill ~57 ~26 ~86 ~57 ~28 ~86 stone  
fill ~57 ~26 ~87 ~57 ~28 ~87 stone  
fill ~57 ~26 ~88 ~57 ~28 ~88 stone  
fill ~57 ~26 ~89 ~57 ~28 ~89 stone  
fill ~57 ~26 ~90 ~57 ~28 ~90 stone  
fill ~57 ~26 ~91 ~57 ~28 ~91 stone  
fill ~57 ~26 ~92 ~57 ~28 ~92 stone  
fill ~57 ~26 ~93 ~57 ~28 ~93 stone  
fill ~9 ~27 ~46 ~20 ~27 ~46 stone  
fill ~9 ~27 ~83 ~20 ~27 ~83 stone  
fill ~10 ~27 ~47 ~10 ~31 ~47 stone  
fill ~10 ~27 ~48 ~10 ~31 ~48 stone  
fill ~10 ~27 ~49 ~10 ~31 ~49 stone  
fill ~10 ~27 ~50 ~10 ~31 ~50 stone  
fill ~10 ~27 ~51 ~10 ~31 ~51 stone  
fill ~10 ~27 ~52 ~10 ~31 ~52 stone  
fill ~10 ~27 ~53 ~10 ~31 ~53 stone  
fill ~10 ~27 ~54 ~10 ~31 ~54 stone  
fill ~10 ~27 ~55 ~10 ~31 ~55 stone  
fill ~10 ~27 ~56 ~10 ~31 ~56 stone  
fill ~10 ~27 ~57 ~10 ~31 ~57 stone  
fill ~10 ~27 ~58 ~10 ~31 ~58 stone  
fill ~10 ~27 ~59 ~10 ~31 ~59 stone  
fill ~10 ~27 ~60 ~10 ~31 ~60 stone  
fill ~10 ~27 ~61 ~10 ~31 ~61 stone  
fill ~10 ~27 ~62 ~10 ~31 ~62 stone  
fill ~10 ~27 ~63 ~10 ~31 ~63 stone  
fill ~10 ~27 ~64 ~10 ~31 ~64 stone  
fill ~10 ~27 ~65 ~10 ~31 ~65 stone  
fill ~10 ~27 ~66 ~10 ~31 ~66 stone  
fill ~10 ~27 ~67 ~10 ~31 ~67 stone  
fill ~10 ~27 ~68 ~10 ~31 ~68 stone  
fill ~10 ~27 ~69 ~10 ~31 ~69 stone  
fill ~10 ~27 ~70 ~10 ~31 ~70 stone  
fill ~10 ~27 ~71 ~10 ~31 ~71 stone  
fill ~10 ~27 ~72 ~10 ~31 ~72 stone  
fill ~10 ~27 ~73 ~10 ~31 ~73 stone  
fill ~10 ~27 ~74 ~10 ~31 ~74 stone  
fill ~10 ~27 ~75 ~10 ~31 ~75 stone  
fill ~10 ~27 ~76 ~10 ~31 ~76 stone  
fill ~10 ~27 ~77 ~10 ~31 ~77 stone  
fill ~10 ~27 ~78 ~10 ~31 ~78 stone  
fill ~10 ~27 ~79 ~10 ~31 ~79 stone  
fill ~10 ~27 ~80 ~10 ~31 ~80 stone  
fill ~10 ~27 ~81 ~10 ~31 ~81 stone  
fill ~10 ~27 ~82 ~10 ~31 ~82 stone  
fill ~20 ~27 ~35 ~56 ~27 ~35 stone  
fill ~20 ~27 ~94 ~57 ~27 ~94 stone  
fill ~56 ~27 ~46 ~68 ~27 ~46 stone  
fill ~57 ~27 ~35 ~57 ~27 ~45 snow_layer  
fill ~57 ~27 ~83 ~68 ~27 ~83 stone  
fill ~58 ~27 ~84 ~58 ~27 ~94 snow_layer  
fill ~9 ~28 ~46 ~9 ~28 ~83 snow_layer  
fill ~10 ~28 ~46 ~20 ~28 ~46 stone  
fill ~10 ~28 ~83 ~20 ~28 ~83 stone  
fill ~20 ~28 ~35 ~56 ~28 ~35 stone  
fill ~20 ~28 ~94 ~57 ~28 ~94 stone  
fill ~21 ~28 ~36 ~30 ~28 ~36 stone  
fill ~40 ~28 ~93 ~57 ~28 ~93 stone  
fill ~55 ~28 ~36 ~55 ~34 ~36 stone  
fill ~55 ~28 ~37 ~55 ~34 ~37 stone  
fill ~55 ~28 ~38 ~55 ~34 ~38 stone  
fill ~55 ~28 ~39 ~55 ~34 ~39 stone  
fill ~55 ~28 ~40 ~55 ~34 ~40 stone  
fill ~55 ~28 ~41 ~55 ~34 ~41 stone  
fill ~55 ~28 ~42 ~55 ~34 ~42 stone  
fill ~55 ~28 ~43 ~55 ~34 ~43 stone  
fill ~55 ~28 ~44 ~55 ~34 ~44 stone  
fill ~55 ~28 ~45 ~55 ~34 ~45 stone  
fill ~55 ~28 ~46 ~68 ~28 ~46 stone  
fill ~56 ~28 ~83 ~68 ~28 ~83 stone  
fill ~56 ~28 ~84 ~56 ~34 ~84 stone  
fill ~56 ~28 ~85 ~56 ~34 ~85 stone  
fill ~56 ~28 ~86 ~56 ~34 ~86 stone  
fill ~56 ~28 ~87 ~56 ~34 ~87 stone  
fill ~56 ~28 ~88 ~56 ~34 ~88 stone  
fill ~56 ~28 ~89 ~56 ~34 ~89 stone  
fill ~56 ~28 ~90 ~56 ~34 ~90 stone  
fill ~56 ~28 ~91 ~56 ~34 ~91 stone  
fill ~56 ~28 ~92 ~56 ~34 ~92 stone  
fill ~63 ~28 ~82 ~68 ~28 ~82 stone  
fill ~10 ~29 ~46 ~20 ~29 ~46 stone  
fill ~10 ~29 ~83 ~20 ~29 ~83 stone  
fill ~11 ~29 ~47 ~20 ~29 ~47 stone  
fill ~20 ~29 ~35 ~29 ~29 ~35 snow_layer  
fill ~20 ~29 ~94 ~40 ~29 ~94 stone  
fill ~21 ~29 ~36 ~53 ~29 ~36 stone  
fill ~21 ~29 ~93 ~56 ~29 ~93 stone  
fill ~30 ~29 ~35 ~55 ~29 ~35 stone  
fill ~41 ~29 ~94 ~57 ~29 ~94 snow_layer  
fill ~55 ~29 ~46 ~68 ~29 ~46 stone  
fill ~56 ~29 ~35 ~56 ~29 ~45 snow_layer  
fill ~56 ~29 ~82 ~68 ~29 ~82 stone  
fill ~56 ~29 ~83 ~62 ~29 ~83 stone  
fill ~57 ~29 ~84 ~57 ~29 ~94 snow_layer  
fill ~63 ~29 ~83 ~68 ~29 ~83 snow_layer  
fill ~10 ~30 ~46 ~19 ~30 ~46 snow_layer  
fill ~10 ~30 ~83 ~20 ~30 ~83 stone  
fill ~11 ~30 ~47 ~20 ~30 ~47 stone  
fill ~16 ~30 ~82 ~20 ~30 ~82 stone  
fill ~20 ~30 ~46 ~20 ~32 ~46 stone  
fill ~20 ~30 ~94 ~40 ~30 ~94 snow_layer  
fill ~21 ~30 ~36 ~55 ~30 ~36 stone  
fill ~21 ~30 ~93 ~56 ~30 ~93 stone  
fill ~30 ~30 ~35 ~35 ~30 ~35 snow_layer  
fill ~37 ~30 ~35 ~52 ~30 ~35 snow_layer  
fill ~53 ~30 ~35 ~55 ~30 ~35 stone  
fill ~55 ~30 ~46 ~68 ~30 ~46 stone  
fill ~56 ~30 ~82 ~68 ~30 ~82 stone  
fill ~56 ~30 ~83 ~56 ~34 ~83 stone  
fill ~57 ~30 ~83 ~62 ~30 ~83 snow_layer  
fill ~10 ~31 ~83 ~17 ~31 ~83 stone  
fill ~11 ~31 ~47 ~20 ~31 ~47 stone  
fill ~11 ~31 ~48 ~11 ~38 ~48 stone  
fill ~11 ~31 ~49 ~11 ~38 ~49 stone  
fill ~11 ~31 ~50 ~11 ~38 ~50 stone  
fill ~11 ~31 ~51 ~11 ~38 ~51 stone  
fill ~11 ~31 ~52 ~11 ~38 ~52 stone  
fill ~11 ~31 ~53 ~11 ~38 ~53 stone  
fill ~11 ~31 ~54 ~11 ~38 ~54 stone  
fill ~11 ~31 ~55 ~11 ~38 ~55 stone  
fill ~11 ~31 ~56 ~11 ~38 ~56 stone  
fill ~11 ~31 ~57 ~11 ~38 ~57 stone  
fill ~11 ~31 ~58 ~11 ~38 ~58 stone  
fill ~11 ~31 ~59 ~11 ~38 ~59 stone  
fill ~11 ~31 ~60 ~11 ~38 ~60 stone  
fill ~11 ~31 ~61 ~11 ~38 ~61 stone  
fill ~11 ~31 ~62 ~11 ~38 ~62 stone  
fill ~11 ~31 ~63 ~11 ~38 ~63 stone  
fill ~11 ~31 ~64 ~11 ~38 ~64 stone  
fill ~11 ~31 ~65 ~11 ~38 ~65 stone  
fill ~11 ~31 ~66 ~11 ~38 ~66 stone  
fill ~11 ~31 ~67 ~11 ~38 ~67 stone  
fill ~11 ~31 ~68 ~11 ~38 ~68 stone  
fill ~11 ~31 ~69 ~11 ~38 ~69 stone  
fill ~11 ~31 ~70 ~11 ~38 ~70 stone  
fill ~11 ~31 ~71 ~11 ~38 ~71 stone  
fill ~11 ~31 ~72 ~11 ~38 ~72 stone  
fill ~11 ~31 ~73 ~11 ~38 ~73 stone  
fill ~11 ~31 ~74 ~11 ~38 ~74 stone  
fill ~11 ~31 ~75 ~11 ~38 ~75 stone  
fill ~11 ~31 ~76 ~11 ~38 ~76 stone  
fill ~11 ~31 ~77 ~11 ~38 ~77 stone  
fill ~11 ~31 ~78 ~11 ~38 ~78 stone  
fill ~11 ~31 ~79 ~11 ~38 ~79 stone  
fill ~11 ~31 ~80 ~11 ~38 ~80 stone  
fill ~11 ~31 ~81 ~11 ~38 ~81 stone  
fill ~11 ~31 ~82 ~20 ~31 ~82 stone  
fill ~18 ~31 ~83 ~19 ~31 ~83 snow_layer  
fill ~20 ~31 ~83 ~20 ~32 ~83 stone  
fill ~21 ~31 ~36 ~55 ~31 ~36 stone  
fill ~21 ~31 ~93 ~56 ~31 ~93 stone  
fill ~53 ~31 ~35 ~55 ~31 ~35 snow_layer  
fill ~55 ~31 ~46 ~68 ~31 ~46 stone  
fill ~55 ~31 ~47 ~68 ~31 ~47 stone  
fill ~56 ~31 ~82 ~68 ~31 ~82 stone  
fill ~10 ~32 ~47 ~10 ~32 ~83 snow_layer  
fill ~11 ~32 ~47 ~21 ~32 ~47 stone  
fill ~11 ~32 ~82 ~21 ~32 ~82 stone  
fill ~11 ~32 ~83 ~17 ~32 ~83 snow_layer  
fill ~21 ~32 ~36 ~55 ~32 ~36 stone  
fill ~21 ~32 ~37 ~21 ~38 ~37 stone  
fill ~21 ~32 ~38 ~21 ~38 ~38 stone  
fill ~21 ~32 ~39 ~21 ~38 ~39 stone  
fill ~21 ~32 ~40 ~21 ~38 ~40 stone  
fill ~21 ~32 ~41 ~21 ~38 ~41 stone  
fill ~21 ~32 ~42 ~21 ~38 ~42 stone  
fill ~21 ~32 ~43 ~21 ~38 ~43 stone  
fill ~21 ~32 ~44 ~21 ~38 ~44 stone  
fill ~21 ~32 ~45 ~21 ~38 ~45 stone  
fill ~21 ~32 ~46 ~21 ~38 ~46 stone  
fill ~21 ~32 ~83 ~21 ~38 ~83 stone  
fill ~21 ~32 ~84 ~21 ~38 ~84 stone  
fill ~21 ~32 ~85 ~21 ~38 ~85 stone  
fill ~21 ~32 ~86 ~21 ~38 ~86 stone  
fill ~21 ~32 ~87 ~21 ~38 ~87 stone  
fill ~21 ~32 ~88 ~21 ~38 ~88 stone  
fill ~21 ~32 ~89 ~21 ~38 ~89 stone  
fill ~21 ~32 ~90 ~21 ~38 ~90 stone  
fill ~21 ~32 ~91 ~21 ~38 ~91 stone  
fill ~21 ~32 ~92 ~21 ~38 ~92 stone  
fill ~21 ~32 ~93 ~56 ~32 ~93 stone  
fill ~55 ~32 ~46 ~55 ~34 ~46 stone  
fill ~55 ~32 ~47 ~68 ~32 ~47 stone  
fill ~56 ~32 ~46 ~68 ~32 ~46 snow_layer  
fill ~56 ~32 ~82 ~68 ~32 ~82 stone  
fill ~11 ~33 ~47 ~21 ~33 ~47 stone  
fill ~11 ~33 ~82 ~21 ~33 ~82 stone  
fill ~20 ~33 ~36 ~20 ~33 ~46 snow_layer  
fill ~20 ~33 ~83 ~20 ~33 ~93 snow_layer  
fill ~21 ~33 ~36 ~55 ~33 ~36 stone  
fill ~21 ~33 ~93 ~56 ~33 ~93 stone  
fill ~53 ~33 ~92 ~56 ~33 ~92 stone  
fill ~55 ~33 ~47 ~68 ~33 ~47 stone  
fill ~56 ~33 ~82 ~68 ~33 ~82 stone  
fill ~67 ~33 ~48 ~67 ~38 ~48 stone  
fill ~67 ~33 ~49 ~67 ~38 ~49 stone  
fill ~67 ~33 ~50 ~67 ~38 ~50 stone  
fill ~67 ~33 ~51 ~67 ~38 ~51 stone  
fill ~67 ~33 ~52 ~67 ~38 ~52 stone  
fill ~67 ~33 ~53 ~67 ~38 ~53 stone  
fill ~67 ~33 ~54 ~67 ~38 ~54 stone  
fill ~67 ~33 ~55 ~67 ~38 ~55 stone  
fill ~67 ~33 ~56 ~67 ~38 ~56 stone  
fill ~67 ~33 ~57 ~67 ~38 ~57 stone  
fill ~67 ~33 ~58 ~67 ~38 ~58 stone  
fill ~67 ~33 ~59 ~67 ~38 ~59 stone  
fill ~67 ~33 ~60 ~67 ~38 ~60 stone  
fill ~67 ~33 ~61 ~67 ~38 ~61 stone  
fill ~67 ~33 ~62 ~67 ~38 ~62 stone  
fill ~67 ~33 ~63 ~67 ~38 ~63 stone  
fill ~67 ~33 ~64 ~67 ~38 ~64 stone  
fill ~67 ~33 ~65 ~67 ~38 ~65 stone  
fill ~67 ~33 ~66 ~67 ~38 ~66 stone  
fill ~67 ~33 ~67 ~67 ~38 ~67 stone  
fill ~67 ~33 ~68 ~67 ~38 ~68 stone  
fill ~67 ~33 ~69 ~67 ~38 ~69 stone  
fill ~67 ~33 ~70 ~67 ~38 ~70 stone  
fill ~67 ~33 ~71 ~67 ~38 ~71 stone  
fill ~67 ~33 ~72 ~67 ~38 ~72 stone  
fill ~67 ~33 ~73 ~67 ~38 ~73 stone  
fill ~67 ~33 ~74 ~67 ~38 ~74 stone  
fill ~67 ~33 ~75 ~67 ~38 ~75 stone  
fill ~67 ~33 ~76 ~67 ~38 ~76 stone  
fill ~67 ~33 ~77 ~67 ~38 ~77 stone  
fill ~67 ~33 ~78 ~67 ~38 ~78 stone  
fill ~67 ~33 ~79 ~67 ~38 ~79 stone  
fill ~67 ~33 ~80 ~67 ~38 ~80 stone  
fill ~67 ~33 ~81 ~67 ~38 ~81 stone  
fill ~11 ~34 ~47 ~21 ~34 ~47 stone  
fill ~11 ~34 ~82 ~21 ~34 ~82 stone  
fill ~12 ~34 ~48 ~17 ~34 ~48 stone  
fill ~21 ~34 ~36 ~55 ~34 ~36 stone  
fill ~21 ~34 ~93 ~53 ~34 ~93 stone  
fill ~22 ~34 ~37 ~43 ~34 ~37 stone  
fill ~29 ~34 ~92 ~56 ~34 ~92 stone  
fill ~54 ~34 ~37 ~54 ~38 ~37 stone  
fill ~54 ~34 ~38 ~54 ~38 ~38 stone  
fill ~54 ~34 ~39 ~54 ~38 ~39 stone  
fill ~54 ~34 ~40 ~54 ~38 ~40 stone  
fill ~54 ~34 ~41 ~54 ~38 ~41 stone  
fill ~54 ~34 ~42 ~54 ~38 ~42 stone  
fill ~54 ~34 ~43 ~54 ~38 ~43 stone  
fill ~54 ~34 ~44 ~54 ~38 ~44 stone  
fill ~54 ~34 ~45 ~54 ~38 ~45 stone  
fill ~54 ~34 ~46 ~54 ~38 ~46 stone  
fill ~54 ~34 ~47 ~67 ~34 ~47 stone  
fill ~54 ~34 ~93 ~56 ~34 ~93 snow_layer  
fill ~55 ~34 ~82 ~67 ~34 ~82 stone  
fill ~55 ~34 ~83 ~55 ~38 ~83 stone  
fill ~55 ~34 ~84 ~55 ~38 ~84 stone  
fill ~55 ~34 ~85 ~55 ~38 ~85 stone  
fill ~55 ~34 ~86 ~55 ~38 ~86 stone  
fill ~55 ~34 ~87 ~55 ~38 ~87 stone  
fill ~55 ~34 ~88 ~55 ~38 ~88 stone  
fill ~55 ~34 ~89 ~55 ~38 ~89 stone  
fill ~55 ~34 ~90 ~55 ~38 ~90 stone  
fill ~55 ~34 ~91 ~55 ~38 ~91 stone  
fill ~57 ~34 ~81 ~67 ~34 ~81 stone  
fill ~68 ~34 ~47 ~68 ~34 ~82 snow_layer  
fill ~11 ~35 ~47 ~16 ~35 ~47 snow_layer  
fill ~11 ~35 ~82 ~21 ~35 ~82 stone  
fill ~12 ~35 ~48 ~21 ~35 ~48 stone  
fill ~17 ~35 ~47 ~21 ~35 ~47 stone  
fill ~21 ~35 ~36 ~35 ~35 ~36 snow_layer  
fill ~21 ~35 ~93 ~29 ~35 ~93 stone  
fill ~22 ~35 ~37 ~54 ~35 ~37 stone  
fill ~22 ~35 ~92 ~55 ~35 ~92 stone  
fill ~30 ~35 ~93 ~53 ~35 ~93 snow_layer  
fill ~37 ~35 ~36 ~41 ~35 ~36 snow_layer  
fill ~43 ~35 ~36 ~54 ~35 ~36 stone  
fill ~54 ~35 ~47 ~67 ~35 ~47 stone  
fill ~55 ~35 ~36 ~55 ~35 ~46 snow_layer  
fill ~55 ~35 ~81 ~67 ~35 ~81 stone  
fill ~55 ~35 ~82 ~57 ~35 ~82 stone  
fill ~56 ~35 ~83 ~56 ~35 ~92 snow_layer  
fill ~58 ~35 ~82 ~67 ~35 ~82 snow_layer  
fill ~11 ~36 ~82 ~21 ~36 ~82 stone  
fill ~12 ~36 ~48 ~21 ~36 ~48 stone  
fill ~12 ~36 ~81 ~21 ~36 ~81 stone  
fill ~17 ~36 ~47 ~20 ~36 ~47 snow_layer  
fill ~21 ~36 ~47 ~21 ~38 ~47 stone  
fill ~21 ~36 ~93 ~29 ~36 ~93 snow_layer  
fill ~22 ~36 ~37 ~54 ~36 ~37 stone  
fill ~22 ~36 ~92 ~55 ~36 ~92 stone  
fill ~43 ~36 ~36 ~54 ~36 ~36 snow_layer  
fill ~54 ~36 ~47 ~67 ~36 ~47 stone  
fill ~54 ~36 ~48 ~64 ~36 ~48 stone  
fill ~55 ~36 ~81 ~67 ~36 ~81 stone  
fill ~55 ~36 ~82 ~55 ~38 ~82 stone  
fill ~56 ~36 ~82 ~57 ~36 ~82 snow_layer  
fill ~11 ~37 ~82 ~12 ~37 ~82 stone  
fill ~12 ~37 ~48 ~21 ~37 ~48 stone  
fill ~12 ~37 ~49 ~12 ~39 ~49 stone  
fill ~12 ~37 ~50 ~12 ~39 ~50 stone  
fill ~12 ~37 ~51 ~12 ~39 ~51 stone  
fill ~12 ~37 ~52 ~12 ~39 ~52 stone  
fill ~12 ~37 ~53 ~12 ~39 ~53 stone  
fill ~12 ~37 ~54 ~12 ~39 ~54 stone  
fill ~12 ~37 ~55 ~12 ~39 ~55 stone  
fill ~12 ~37 ~56 ~12 ~39 ~56 stone  
fill ~12 ~37 ~57 ~12 ~39 ~57 stone  
fill ~12 ~37 ~58 ~12 ~39 ~58 stone  
fill ~12 ~37 ~59 ~12 ~39 ~59 stone  
fill ~12 ~37 ~60 ~12 ~39 ~60 stone  
fill ~12 ~37 ~61 ~12 ~39 ~61 stone  
fill ~12 ~37 ~62 ~12 ~39 ~62 stone  
fill ~12 ~37 ~63 ~12 ~39 ~63 stone  
fill ~12 ~37 ~64 ~12 ~39 ~64 stone  
fill ~12 ~37 ~65 ~12 ~39 ~65 stone  
fill ~12 ~37 ~66 ~12 ~39 ~66 stone  
fill ~12 ~37 ~67 ~12 ~39 ~67 stone  
fill ~12 ~37 ~68 ~12 ~39 ~68 stone  
fill ~12 ~37 ~69 ~12 ~39 ~69 stone  
fill ~12 ~37 ~70 ~12 ~39 ~70 stone  
fill ~12 ~37 ~71 ~12 ~39 ~71 stone  
fill ~12 ~37 ~72 ~12 ~39 ~72 stone  
fill ~12 ~37 ~73 ~12 ~39 ~73 stone  
fill ~12 ~37 ~74 ~12 ~39 ~74 stone  
fill ~12 ~37 ~75 ~12 ~39 ~75 stone  
fill ~12 ~37 ~76 ~12 ~39 ~76 stone  
fill ~12 ~37 ~77 ~12 ~39 ~77 stone  
fill ~12 ~37 ~78 ~12 ~39 ~78 stone  
fill ~12 ~37 ~79 ~12 ~39 ~79 stone  
fill ~12 ~37 ~80 ~12 ~39 ~80 stone  
fill ~13 ~37 ~81 ~21 ~37 ~81 stone  
fill ~13 ~37 ~82 ~20 ~37 ~82 snow_layer  
fill ~21 ~37 ~82 ~21 ~38 ~82 stone  
fill ~22 ~37 ~37 ~54 ~37 ~37 stone  
fill ~22 ~37 ~92 ~55 ~37 ~92 stone  
fill ~54 ~37 ~47 ~54 ~38 ~47 stone  
fill ~54 ~37 ~48 ~67 ~37 ~48 stone  
fill ~55 ~37 ~47 ~63 ~37 ~47 snow_layer  
fill ~55 ~37 ~81 ~67 ~37 ~81 stone  
fill ~64 ~37 ~47 ~67 ~37 ~47 stone  
fill ~11 ~38 ~82 ~12 ~38 ~82 snow_layer  
fill ~12 ~38 ~48 ~23 ~38 ~48 stone  
fill ~12 ~38 ~81 ~23 ~38 ~81 stone  
fill ~13 ~38 ~49 ~23 ~38 ~49 stone  
fill ~13 ~38 ~80 ~23 ~38 ~80 stone  
fill ~22 ~38 ~37 ~54 ~38 ~37 stone  

KittysCommands:   
fill ~22 ~38 ~38 ~54 ~38 ~38 stone  
fill ~22 ~38 ~39 ~23 ~38 ~39 stone  
fill ~22 ~38 ~40 ~23 ~38 ~40 stone  
fill ~22 ~38 ~41 ~23 ~38 ~41 stone  
fill ~22 ~38 ~42 ~23 ~38 ~42 stone  
fill ~22 ~38 ~43 ~23 ~38 ~43 stone  
fill ~22 ~38 ~44 ~23 ~38 ~44 stone  
fill ~22 ~38 ~45 ~23 ~38 ~45 stone  
fill ~22 ~38 ~46 ~23 ~38 ~46 stone  
fill ~22 ~38 ~47 ~23 ~38 ~47 stone  
fill ~22 ~38 ~82 ~23 ~38 ~82 stone  
fill ~22 ~38 ~83 ~23 ~38 ~83 stone  
fill ~22 ~38 ~84 ~23 ~38 ~84 stone  
fill ~22 ~38 ~85 ~23 ~38 ~85 stone  
fill ~22 ~38 ~86 ~23 ~38 ~86 stone  
fill ~22 ~38 ~87 ~23 ~38 ~87 stone  
fill ~22 ~38 ~88 ~23 ~38 ~88 stone  
fill ~22 ~38 ~89 ~23 ~38 ~89 stone  
fill ~22 ~38 ~90 ~23 ~38 ~90 stone  
fill ~22 ~38 ~91 ~55 ~38 ~91 stone  
fill ~22 ~38 ~92 ~55 ~38 ~92 stone  
fill ~53 ~38 ~39 ~53 ~39 ~39 stone  
fill ~53 ~38 ~40 ~53 ~39 ~40 stone  
fill ~53 ~38 ~41 ~53 ~39 ~41 stone  
fill ~53 ~38 ~42 ~53 ~39 ~42 stone  
fill ~53 ~38 ~43 ~53 ~39 ~43 stone  
fill ~53 ~38 ~44 ~53 ~39 ~44 stone  
fill ~53 ~38 ~45 ~53 ~39 ~45 stone  
fill ~53 ~38 ~46 ~53 ~39 ~46 stone  
fill ~53 ~38 ~47 ~53 ~39 ~47 stone  
fill ~53 ~38 ~48 ~67 ~38 ~48 stone  
fill ~53 ~38 ~49 ~67 ~38 ~49 stone  
fill ~54 ~38 ~80 ~67 ~38 ~80 stone  
fill ~54 ~38 ~81 ~67 ~38 ~81 stone  
fill ~54 ~38 ~82 ~54 ~39 ~82 stone  
fill ~54 ~38 ~83 ~54 ~39 ~83 stone  
fill ~54 ~38 ~84 ~54 ~39 ~84 stone  
fill ~54 ~38 ~85 ~54 ~39 ~85 stone  
fill ~54 ~38 ~86 ~54 ~39 ~86 stone  
fill ~54 ~38 ~87 ~54 ~39 ~87 stone  
fill ~54 ~38 ~88 ~54 ~39 ~88 stone  
fill ~54 ~38 ~89 ~54 ~39 ~89 stone  
fill ~54 ~38 ~90 ~54 ~39 ~90 stone  
fill ~64 ~38 ~47 ~67 ~38 ~47 snow_layer  
fill ~65 ~38 ~50 ~67 ~38 ~50 stone  
fill ~65 ~38 ~51 ~67 ~38 ~51 stone  
fill ~65 ~38 ~52 ~67 ~38 ~52 stone  
fill ~65 ~38 ~53 ~67 ~38 ~53 stone  
fill ~65 ~38 ~54 ~67 ~38 ~54 stone  
fill ~65 ~38 ~55 ~67 ~38 ~55 stone  
fill ~65 ~38 ~56 ~67 ~38 ~56 stone  
fill ~65 ~38 ~57 ~67 ~38 ~57 stone  
fill ~65 ~38 ~58 ~67 ~38 ~58 stone  
fill ~65 ~38 ~59 ~67 ~38 ~59 stone  
fill ~65 ~38 ~60 ~67 ~38 ~60 stone  
fill ~65 ~38 ~61 ~67 ~38 ~61 stone  
fill ~65 ~38 ~62 ~67 ~38 ~62 stone  
fill ~65 ~38 ~63 ~67 ~38 ~63 stone  
fill ~65 ~38 ~64 ~67 ~38 ~64 stone  
fill ~65 ~38 ~65 ~67 ~38 ~65 stone  
fill ~65 ~38 ~66 ~67 ~38 ~66 stone  
fill ~65 ~38 ~67 ~67 ~38 ~67 stone  
fill ~65 ~38 ~68 ~67 ~38 ~68 stone  
fill ~65 ~38 ~69 ~67 ~38 ~69 stone  
fill ~65 ~38 ~70 ~67 ~38 ~70 stone  
fill ~65 ~38 ~71 ~67 ~38 ~71 stone  
fill ~65 ~38 ~72 ~67 ~38 ~72 stone  
fill ~65 ~38 ~73 ~67 ~38 ~73 stone  
fill ~65 ~38 ~74 ~67 ~38 ~74 stone  
fill ~65 ~38 ~75 ~67 ~38 ~75 stone  
fill ~65 ~38 ~76 ~67 ~38 ~76 stone  
fill ~65 ~38 ~77 ~67 ~38 ~77 stone  
fill ~65 ~38 ~78 ~67 ~38 ~78 stone  
fill ~65 ~38 ~79 ~67 ~38 ~79 stone  
fill ~11 ~39 ~48 ~22 ~39 ~48 snow_layer  
fill ~11 ~39 ~49 ~11 ~39 ~81 snow_layer  
fill ~12 ~39 ~81 ~22 ~39 ~81 snow_layer  
fill ~13 ~39 ~49 ~23 ~39 ~49 stone  
fill ~13 ~39 ~50 ~23 ~39 ~50 stone  
fill ~13 ~39 ~51 ~13 ~43 ~51 stone  
fill ~13 ~39 ~52 ~13 ~43 ~52 stone  
fill ~13 ~39 ~53 ~13 ~43 ~53 stone  
fill ~13 ~39 ~54 ~13 ~43 ~54 stone  
fill ~13 ~39 ~55 ~13 ~43 ~55 stone  
fill ~13 ~39 ~56 ~13 ~43 ~56 stone  
fill ~13 ~39 ~57 ~13 ~43 ~57 stone  
fill ~13 ~39 ~58 ~13 ~43 ~58 stone  
fill ~13 ~39 ~59 ~13 ~43 ~59 stone  
fill ~13 ~39 ~60 ~13 ~43 ~60 stone  
fill ~13 ~39 ~61 ~13 ~43 ~61 stone  
fill ~13 ~39 ~62 ~13 ~43 ~62 stone  
fill ~13 ~39 ~63 ~13 ~43 ~63 stone  
fill ~13 ~39 ~64 ~13 ~43 ~64 stone  
fill ~13 ~39 ~65 ~13 ~43 ~65 stone  
fill ~13 ~39 ~66 ~13 ~43 ~66 stone  
fill ~13 ~39 ~67 ~13 ~43 ~67 stone  
fill ~13 ~39 ~68 ~13 ~43 ~68 stone  
fill ~13 ~39 ~69 ~13 ~43 ~69 stone  
fill ~13 ~39 ~70 ~13 ~43 ~70 stone  
fill ~13 ~39 ~71 ~13 ~43 ~71 stone  
fill ~13 ~39 ~72 ~13 ~43 ~72 stone  
fill ~13 ~39 ~73 ~13 ~43 ~73 stone  
fill ~13 ~39 ~74 ~13 ~43 ~74 stone  
fill ~13 ~39 ~75 ~13 ~43 ~75 stone  
fill ~13 ~39 ~76 ~13 ~43 ~76 stone  
fill ~13 ~39 ~77 ~13 ~43 ~77 stone  
fill ~13 ~39 ~78 ~13 ~43 ~78 stone  
fill ~13 ~39 ~79 ~23 ~39 ~79 stone  
fill ~13 ~39 ~80 ~23 ~39 ~80 stone  
fill ~21 ~39 ~37 ~35 ~39 ~37 snow_layer  
fill ~21 ~39 ~38 ~22 ~39 ~38 snow_layer  
fill ~21 ~39 ~39 ~22 ~39 ~39 snow_layer  
fill ~21 ~39 ~40 ~22 ~39 ~40 snow_layer  
fill ~21 ~39 ~41 ~22 ~39 ~41 snow_layer  
fill ~21 ~39 ~42 ~22 ~39 ~42 snow_layer  
fill ~21 ~39 ~43 ~22 ~39 ~43 snow_layer  
fill ~21 ~39 ~44 ~22 ~39 ~44 snow_layer  
fill ~21 ~39 ~45 ~22 ~39 ~45 snow_layer  
fill ~21 ~39 ~46 ~22 ~39 ~46 snow_layer  
fill ~21 ~39 ~47 ~22 ~39 ~47 snow_layer  
fill ~21 ~39 ~82 ~22 ~39 ~82 snow_layer  
fill ~21 ~39 ~83 ~22 ~39 ~83 snow_layer  
fill ~21 ~39 ~84 ~22 ~39 ~84 snow_layer  
fill ~21 ~39 ~85 ~22 ~39 ~85 snow_layer  
fill ~21 ~39 ~86 ~22 ~39 ~86 snow_layer  
fill ~21 ~39 ~87 ~22 ~39 ~87 snow_layer  
fill ~21 ~39 ~88 ~22 ~39 ~88 snow_layer  
fill ~21 ~39 ~89 ~22 ~39 ~89 snow_layer  
fill ~21 ~39 ~90 ~22 ~39 ~90 snow_layer  
fill ~21 ~39 ~91 ~22 ~39 ~91 snow_layer  
fill ~21 ~39 ~92 ~55 ~39 ~92 snow_layer  
fill ~23 ~39 ~38 ~53 ~39 ~38 stone  
fill ~23 ~39 ~39 ~53 ~39 ~39 stone  
fill ~23 ~39 ~40 ~23 ~40 ~40 stone  
fill ~23 ~39 ~41 ~23 ~40 ~41 stone  
fill ~23 ~39 ~42 ~23 ~40 ~42 stone  
fill ~23 ~39 ~43 ~23 ~40 ~43 stone  
fill ~23 ~39 ~44 ~23 ~40 ~44 stone  
fill ~23 ~39 ~45 ~23 ~40 ~45 stone  
fill ~23 ~39 ~46 ~23 ~40 ~46 stone  
fill ~23 ~39 ~47 ~23 ~40 ~47 stone  
fill ~23 ~39 ~48 ~23 ~40 ~48 stone  
fill ~23 ~39 ~81 ~23 ~40 ~81 stone  
fill ~23 ~39 ~82 ~23 ~40 ~82 stone  
fill ~23 ~39 ~83 ~23 ~40 ~83 stone  
fill ~23 ~39 ~84 ~23 ~40 ~84 stone  
fill ~23 ~39 ~85 ~23 ~40 ~85 stone  
fill ~23 ~39 ~86 ~23 ~40 ~86 stone  
fill ~23 ~39 ~87 ~23 ~40 ~87 stone  
fill ~23 ~39 ~88 ~23 ~40 ~88 stone  
fill ~23 ~39 ~89 ~23 ~40 ~89 stone  
fill ~23 ~39 ~90 ~54 ~39 ~90 stone  
fill ~23 ~39 ~91 ~54 ~39 ~91 stone  
fill ~37 ~39 ~37 ~54 ~39 ~37 snow_layer  
fill ~52 ~39 ~40 ~52 ~42 ~40 stone  
fill ~52 ~39 ~41 ~52 ~42 ~41 stone  
fill ~52 ~39 ~42 ~52 ~42 ~42 stone  
fill ~52 ~39 ~43 ~52 ~42 ~43 stone  
fill ~52 ~39 ~44 ~52 ~42 ~44 stone  
fill ~52 ~39 ~45 ~52 ~42 ~45 stone  
fill ~52 ~39 ~46 ~52 ~42 ~46 stone  
fill ~52 ~39 ~47 ~52 ~42 ~47 stone  
fill ~52 ~39 ~48 ~53 ~39 ~48 stone  
fill ~52 ~39 ~49 ~65 ~39 ~49 stone  
fill ~52 ~39 ~50 ~65 ~39 ~50 stone  
fill ~53 ~39 ~79 ~65 ~39 ~79 stone  
fill ~53 ~39 ~80 ~65 ~39 ~80 stone  
fill ~53 ~39 ~81 ~54 ~39 ~81 stone  
fill ~53 ~39 ~82 ~53 ~43 ~82 stone  
fill ~53 ~39 ~83 ~53 ~43 ~83 stone  
fill ~53 ~39 ~84 ~53 ~43 ~84 stone  
fill ~53 ~39 ~85 ~53 ~43 ~85 stone  
fill ~53 ~39 ~86 ~53 ~43 ~86 stone  
fill ~53 ~39 ~87 ~53 ~43 ~87 stone  
fill ~53 ~39 ~88 ~53 ~43 ~88 stone  
fill ~53 ~39 ~89 ~53 ~43 ~89 stone  
fill ~54 ~39 ~38 ~54 ~39 ~48 snow_layer  
fill ~55 ~39 ~48 ~67 ~39 ~48 snow_layer  
fill ~55 ~39 ~81 ~67 ~39 ~81 snow_layer  
fill ~55 ~39 ~82 ~55 ~39 ~92 snow_layer  
fill ~65 ~39 ~51 ~65 ~40 ~51 stone  
fill ~65 ~39 ~52 ~65 ~40 ~52 stone  
fill ~65 ~39 ~53 ~65 ~40 ~53 stone  
fill ~65 ~39 ~54 ~65 ~40 ~54 stone  
fill ~65 ~39 ~55 ~65 ~40 ~55 stone  
fill ~65 ~39 ~56 ~65 ~40 ~56 stone  
fill ~65 ~39 ~57 ~65 ~40 ~57 stone  
fill ~65 ~39 ~58 ~65 ~40 ~58 stone  
fill ~65 ~39 ~59 ~65 ~40 ~59 stone  
fill ~65 ~39 ~60 ~65 ~40 ~60 stone  
fill ~65 ~39 ~61 ~65 ~40 ~61 stone  
fill ~65 ~39 ~62 ~65 ~40 ~62 stone  
fill ~65 ~39 ~63 ~65 ~40 ~63 stone  
fill ~65 ~39 ~64 ~65 ~40 ~64 stone  
fill ~65 ~39 ~65 ~65 ~40 ~65 stone  
fill ~65 ~39 ~66 ~65 ~40 ~66 stone  
fill ~65 ~39 ~67 ~65 ~40 ~67 stone  
fill ~65 ~39 ~68 ~65 ~40 ~68 stone  
fill ~65 ~39 ~69 ~65 ~40 ~69 stone  
fill ~65 ~39 ~70 ~65 ~40 ~70 stone  
fill ~65 ~39 ~71 ~65 ~40 ~71 stone  
fill ~65 ~39 ~72 ~65 ~40 ~72 stone  
fill ~65 ~39 ~73 ~65 ~40 ~73 stone  
fill ~65 ~39 ~74 ~65 ~40 ~74 stone  
fill ~65 ~39 ~75 ~65 ~40 ~75 stone  
fill ~65 ~39 ~76 ~65 ~40 ~76 stone  
fill ~65 ~39 ~77 ~65 ~40 ~77 stone  
fill ~65 ~39 ~78 ~65 ~40 ~78 stone  
fill ~66 ~39 ~49 ~67 ~39 ~49 snow_layer  
fill ~66 ~39 ~50 ~67 ~39 ~50 snow_layer  
fill ~66 ~39 ~51 ~67 ~39 ~51 snow_layer  
fill ~66 ~39 ~52 ~67 ~39 ~52 snow_layer  
fill ~66 ~39 ~53 ~67 ~39 ~53 snow_layer  
fill ~66 ~39 ~54 ~67 ~39 ~54 snow_layer  
fill ~66 ~39 ~55 ~67 ~39 ~55 snow_layer  
fill ~66 ~39 ~56 ~67 ~39 ~56 snow_layer  
fill ~66 ~39 ~57 ~67 ~39 ~57 snow_layer  
fill ~66 ~39 ~58 ~67 ~39 ~58 snow_layer  
fill ~66 ~39 ~59 ~67 ~39 ~59 snow_layer  
fill ~66 ~39 ~60 ~67 ~39 ~60 snow_layer  
fill ~66 ~39 ~61 ~67 ~39 ~61 snow_layer  
fill ~66 ~39 ~62 ~67 ~39 ~62 snow_layer  
fill ~66 ~39 ~63 ~67 ~39 ~63 snow_layer  
fill ~66 ~39 ~64 ~67 ~39 ~64 snow_layer  
fill ~66 ~39 ~65 ~67 ~39 ~65 snow_layer  
fill ~66 ~39 ~66 ~67 ~39 ~66 snow_layer  
fill ~66 ~39 ~67 ~67 ~39 ~67 snow_layer  
fill ~66 ~39 ~68 ~67 ~39 ~68 snow_layer  
fill ~66 ~39 ~69 ~67 ~39 ~69 snow_layer  
fill ~66 ~39 ~70 ~67 ~39 ~70 snow_layer  
fill ~66 ~39 ~71 ~67 ~39 ~71 snow_layer  
fill ~66 ~39 ~72 ~67 ~39 ~72 snow_layer  
fill ~66 ~39 ~73 ~67 ~39 ~73 snow_layer  
fill ~66 ~39 ~74 ~67 ~39 ~74 snow_layer  
fill ~66 ~39 ~75 ~67 ~39 ~75 snow_layer  
fill ~66 ~39 ~76 ~67 ~39 ~76 snow_layer  
fill ~66 ~39 ~77 ~67 ~39 ~77 snow_layer  
fill ~66 ~39 ~78 ~67 ~39 ~78 snow_layer  
fill ~66 ~39 ~79 ~67 ~39 ~79 snow_layer  
fill ~66 ~39 ~80 ~67 ~39 ~80 snow_layer  
fill ~12 ~40 ~49 ~22 ~40 ~49 snow_layer  
fill ~12 ~40 ~50 ~12 ~40 ~80 snow_layer  
fill ~13 ~40 ~50 ~24 ~40 ~50 stone  
fill ~13 ~40 ~79 ~24 ~40 ~79 stone  
fill ~13 ~40 ~80 ~22 ~40 ~80 snow_layer  
fill ~23 ~40 ~38 ~35 ~40 ~38 snow_layer  
fill ~23 ~40 ~39 ~52 ~40 ~39 stone  
fill ~23 ~40 ~49 ~24 ~40 ~49 stone  
fill ~23 ~40 ~80 ~24 ~40 ~80 stone  
fill ~23 ~40 ~90 ~53 ~40 ~90 stone  
fill ~23 ~40 ~91 ~54 ~40 ~91 snow_layer  
fill ~24 ~40 ~40 ~24 ~43 ~40 stone  
fill ~24 ~40 ~41 ~24 ~43 ~41 stone  
fill ~24 ~40 ~42 ~24 ~43 ~42 stone  
fill ~24 ~40 ~43 ~24 ~43 ~43 stone  
fill ~24 ~40 ~44 ~24 ~43 ~44 stone  
fill ~24 ~40 ~45 ~24 ~43 ~45 stone  
fill ~24 ~40 ~46 ~24 ~43 ~46 stone  
fill ~24 ~40 ~47 ~24 ~43 ~47 stone  
fill ~24 ~40 ~48 ~24 ~43 ~48 stone  
fill ~24 ~40 ~81 ~24 ~43 ~81 stone  
fill ~24 ~40 ~82 ~24 ~43 ~82 stone  
fill ~24 ~40 ~83 ~24 ~43 ~83 stone  
fill ~24 ~40 ~84 ~24 ~43 ~84 stone  
fill ~24 ~40 ~85 ~24 ~43 ~85 stone  
fill ~24 ~40 ~86 ~24 ~43 ~86 stone  
fill ~24 ~40 ~87 ~24 ~43 ~87 stone  
fill ~24 ~40 ~88 ~24 ~43 ~88 stone  
fill ~24 ~40 ~89 ~24 ~43 ~89 stone  
fill ~37 ~40 ~38 ~53 ~40 ~38 snow_layer  
fill ~52 ~40 ~48 ~52 ~42 ~48 stone  
fill ~52 ~40 ~49 ~52 ~42 ~49 stone  
fill ~52 ~40 ~50 ~65 ~40 ~50 stone  
fill ~53 ~40 ~39 ~53 ~40 ~49 snow_layer  
fill ~53 ~40 ~79 ~65 ~40 ~79 stone  
fill ~53 ~40 ~80 ~53 ~43 ~80 stone  
fill ~53 ~40 ~81 ~53 ~43 ~81 stone  
fill ~54 ~40 ~49 ~65 ~40 ~49 snow_layer  
fill ~54 ~40 ~80 ~65 ~40 ~80 snow_layer  
fill ~54 ~40 ~81 ~54 ~40 ~91 snow_layer  
fill ~64 ~40 ~51 ~64 ~43 ~51 stone  
fill ~64 ~40 ~52 ~64 ~43 ~52 stone  
fill ~64 ~40 ~53 ~64 ~43 ~53 stone  
fill ~64 ~40 ~54 ~64 ~43 ~54 stone  
fill ~64 ~40 ~55 ~64 ~43 ~55 stone  
fill ~64 ~40 ~56 ~64 ~43 ~56 stone  
fill ~64 ~40 ~57 ~64 ~43 ~57 stone  
fill ~64 ~40 ~58 ~64 ~43 ~58 stone  
fill ~64 ~40 ~59 ~64 ~43 ~59 stone  
fill ~64 ~40 ~60 ~64 ~43 ~60 stone  
fill ~64 ~40 ~61 ~64 ~43 ~61 stone  
fill ~64 ~40 ~62 ~64 ~43 ~62 stone  
fill ~64 ~40 ~63 ~64 ~43 ~63 stone  
fill ~64 ~40 ~64 ~64 ~43 ~64 stone  
fill ~64 ~40 ~65 ~64 ~43 ~65 stone  
fill ~64 ~40 ~66 ~64 ~43 ~66 stone  
fill ~64 ~40 ~67 ~64 ~43 ~67 stone  
fill ~64 ~40 ~68 ~64 ~43 ~68 stone  
fill ~64 ~40 ~69 ~64 ~43 ~69 stone  
fill ~64 ~40 ~70 ~64 ~43 ~70 stone  
fill ~64 ~40 ~71 ~64 ~43 ~71 stone  
fill ~64 ~40 ~72 ~64 ~43 ~72 stone  
fill ~64 ~40 ~73 ~64 ~43 ~73 stone  
fill ~64 ~40 ~74 ~64 ~43 ~74 stone  
fill ~64 ~40 ~75 ~64 ~43 ~75 stone  
fill ~64 ~40 ~76 ~64 ~43 ~76 stone  
fill ~64 ~40 ~77 ~64 ~43 ~77 stone  
fill ~64 ~40 ~78 ~64 ~43 ~78 stone  
fill ~13 ~41 ~50 ~24 ~41 ~50 stone  
fill ~13 ~41 ~79 ~24 ~41 ~79 stone  
fill ~23 ~41 ~39 ~23 ~41 ~49 snow_layer  
fill ~23 ~41 ~80 ~23 ~41 ~90 snow_layer  
fill ~24 ~41 ~39 ~52 ~41 ~39 stone  
fill ~24 ~41 ~49 ~24 ~43 ~49 stone  
fill ~24 ~41 ~80 ~24 ~43 ~80 stone  
fill ~24 ~41 ~90 ~53 ~41 ~90 stone  
fill ~52 ~41 ~50 ~64 ~41 ~50 stone  
fill ~53 ~41 ~79 ~64 ~41 ~79 stone  
fill ~65 ~41 ~50 ~65 ~41 ~79 snow_layer  
fill ~13 ~42 ~50 ~24 ~42 ~50 stone  
fill ~13 ~42 ~79 ~24 ~42 ~79 stone  
fill ~14 ~42 ~51 ~24 ~42 ~51 stone  
fill ~24 ~42 ~39 ~52 ~42 ~39 stone  
fill ~24 ~42 ~90 ~53 ~42 ~90 stone  
fill ~25 ~42 ~40 ~52 ~42 ~40 stone  
fill ~25 ~42 ~89 ~53 ~42 ~89 stone  
fill ~51 ~42 ~41 ~51 ~43 ~41 stone  
fill ~51 ~42 ~42 ~51 ~43 ~42 stone  
fill ~51 ~42 ~43 ~51 ~43 ~43 stone  
fill ~51 ~42 ~44 ~51 ~43 ~44 stone  
fill ~51 ~42 ~45 ~51 ~43 ~45 stone  
fill ~51 ~42 ~46 ~51 ~43 ~46 stone  
fill ~51 ~42 ~47 ~51 ~43 ~47 stone  
fill ~51 ~42 ~48 ~51 ~43 ~48 stone  
fill ~51 ~42 ~49 ~51 ~43 ~49 stone  
fill ~51 ~42 ~50 ~64 ~42 ~50 stone  
fill ~52 ~42 ~78 ~64 ~42 ~78 stone  
fill ~52 ~42 ~79 ~64 ~42 ~79 stone  
fill ~52 ~42 ~80 ~52 ~44 ~80 stone  
fill ~52 ~42 ~81 ~52 ~44 ~81 stone  
fill ~52 ~42 ~82 ~52 ~44 ~82 stone  
fill ~52 ~42 ~83 ~52 ~44 ~83 stone  
fill ~52 ~42 ~84 ~52 ~44 ~84 stone  
fill ~52 ~42 ~85 ~52 ~44 ~85 stone  
fill ~52 ~42 ~86 ~52 ~44 ~86 stone  
fill ~52 ~42 ~87 ~52 ~44 ~87 stone  
fill ~52 ~42 ~88 ~52 ~44 ~88 stone  
fill ~13 ~43 ~50 ~23 ~43 ~50 snow_layer  
fill ~13 ~43 ~79 ~25 ~43 ~79 stone  
fill ~14 ~43 ~51 ~25 ~43 ~51 stone  
fill ~14 ~43 ~52 ~25 ~43 ~52 stone  
fill ~14 ~43 ~53 ~15 ~43 ~53 stone  
fill ~14 ~43 ~54 ~15 ~43 ~54 stone  
fill ~14 ~43 ~55 ~15 ~43 ~55 stone  
fill ~14 ~43 ~56 ~15 ~43 ~56 stone  
fill ~14 ~43 ~57 ~15 ~43 ~57 stone  
fill ~14 ~43 ~58 ~15 ~43 ~58 stone  
fill ~14 ~43 ~59 ~15 ~43 ~59 stone  
fill ~14 ~43 ~60 ~15 ~43 ~60 stone  
fill ~14 ~43 ~61 ~15 ~43 ~61 stone  
fill ~14 ~43 ~62 ~15 ~43 ~62 stone  
fill ~14 ~43 ~63 ~15 ~43 ~63 stone  
fill ~14 ~43 ~64 ~15 ~43 ~64 stone  
fill ~14 ~43 ~65 ~15 ~43 ~65 stone  
fill ~14 ~43 ~66 ~15 ~43 ~66 stone  
fill ~14 ~43 ~67 ~15 ~43 ~67 stone  
fill ~14 ~43 ~68 ~15 ~43 ~68 stone  
fill ~14 ~43 ~69 ~15 ~43 ~69 stone  
fill ~14 ~43 ~70 ~15 ~43 ~70 stone  
fill ~14 ~43 ~71 ~15 ~43 ~71 stone  
fill ~14 ~43 ~72 ~15 ~43 ~72 stone  
fill ~14 ~43 ~73 ~15 ~43 ~73 stone  
fill ~14 ~43 ~74 ~15 ~43 ~74 stone  
fill ~14 ~43 ~75 ~15 ~43 ~75 stone  
fill ~14 ~43 ~76 ~15 ~43 ~76 stone  
fill ~14 ~43 ~77 ~25 ~43 ~77 stone  
fill ~14 ~43 ~78 ~25 ~43 ~78 stone  
fill ~24 ~43 ~39 ~35 ~43 ~39 snow_layer  
fill ~24 ~43 ~50 ~25 ~43 ~50 stone  
fill ~24 ~43 ~90 ~53 ~43 ~90 stone  
fill ~25 ~43 ~40 ~51 ~43 ~40 stone  
fill ~25 ~43 ~41 ~51 ~43 ~41 stone  
fill ~25 ~43 ~42 ~25 ~44 ~42 stone  
fill ~25 ~43 ~43 ~25 ~44 ~43 stone  
fill ~25 ~43 ~44 ~25 ~44 ~44 stone  
fill ~25 ~43 ~45 ~25 ~44 ~45 stone  
fill ~25 ~43 ~46 ~25 ~44 ~46 stone  
fill ~25 ~43 ~47 ~25 ~44 ~47 stone  
fill ~25 ~43 ~48 ~25 ~44 ~48 stone  
fill ~25 ~43 ~49 ~25 ~44 ~49 stone  
fill ~25 ~43 ~80 ~25 ~44 ~80 stone  
fill ~25 ~43 ~81 ~25 ~44 ~81 stone  
fill ~25 ~43 ~82 ~25 ~44 ~82 stone  
fill ~25 ~43 ~83 ~25 ~44 ~83 stone  
fill ~25 ~43 ~84 ~25 ~44 ~84 stone  
fill ~25 ~43 ~85 ~25 ~44 ~85 stone  
fill ~25 ~43 ~86 ~25 ~44 ~86 stone  
fill ~25 ~43 ~87 ~25 ~44 ~87 stone  
fill ~25 ~43 ~88 ~25 ~44 ~88 stone  
fill ~25 ~43 ~89 ~53 ~43 ~89 stone  
fill ~37 ~43 ~39 ~52 ~43 ~39 snow_layer  
fill ~50 ~43 ~42 ~50 ~44 ~42 stone  
fill ~50 ~43 ~43 ~50 ~44 ~43 stone  
fill ~50 ~43 ~44 ~50 ~44 ~44 stone  
fill ~50 ~43 ~45 ~50 ~44 ~45 stone  
fill ~50 ~43 ~46 ~50 ~44 ~46 stone  
fill ~50 ~43 ~47 ~50 ~44 ~47 stone  
fill ~50 ~43 ~48 ~50 ~44 ~48 stone  
fill ~50 ~43 ~49 ~50 ~44 ~49 stone  
fill ~50 ~43 ~50 ~64 ~43 ~50 stone  
fill ~50 ~43 ~51 ~64 ~43 ~51 stone  
fill ~50 ~43 ~52 ~64 ~43 ~52 stone  
fill ~52 ~43 ~40 ~52 ~43 ~49 snow_layer  
fill ~52 ~43 ~78 ~64 ~43 ~78 stone  
fill ~52 ~43 ~79 ~64 ~43 ~79 stone  
fill ~63 ~43 ~53 ~63 ~44 ~53 stone  
fill ~63 ~43 ~54 ~63 ~44 ~54 stone  
fill ~63 ~43 ~55 ~63 ~44 ~55 stone  
fill ~63 ~43 ~56 ~63 ~44 ~56 stone  
fill ~63 ~43 ~57 ~63 ~44 ~57 stone  
fill ~63 ~43 ~58 ~63 ~44 ~58 stone  
fill ~63 ~43 ~59 ~63 ~44 ~59 stone  
fill ~63 ~43 ~60 ~63 ~44 ~60 stone  
fill ~63 ~43 ~61 ~63 ~44 ~61 stone  
fill ~63 ~43 ~62 ~63 ~44 ~62 stone  
fill ~63 ~43 ~63 ~63 ~44 ~63 stone  
fill ~63 ~43 ~64 ~63 ~44 ~64 stone  
fill ~63 ~43 ~65 ~63 ~44 ~65 stone  
fill ~63 ~43 ~66 ~63 ~44 ~66 stone  
fill ~63 ~43 ~67 ~63 ~44 ~67 stone  
fill ~63 ~43 ~68 ~63 ~44 ~68 stone  
fill ~63 ~43 ~69 ~63 ~44 ~69 stone  
fill ~63 ~43 ~70 ~63 ~44 ~70 stone  
fill ~63 ~43 ~71 ~63 ~44 ~71 stone  
fill ~63 ~43 ~72 ~63 ~44 ~72 stone  
fill ~63 ~43 ~73 ~63 ~44 ~73 stone  
fill ~63 ~43 ~74 ~63 ~44 ~74 stone  
fill ~63 ~43 ~75 ~63 ~44 ~75 stone  
fill ~63 ~43 ~76 ~63 ~44 ~76 stone  
fill ~63 ~43 ~77 ~63 ~44 ~77 stone  
fill ~13 ~44 ~51 ~24 ~44 ~51 snow_layer  
fill ~13 ~44 ~52 ~14 ~44 ~52 snow_layer  
fill ~13 ~44 ~53 ~14 ~44 ~53 snow_layer  
fill ~13 ~44 ~54 ~14 ~44 ~54 snow_layer  
fill ~13 ~44 ~55 ~14 ~44 ~55 snow_layer  
fill ~13 ~44 ~56 ~14 ~44 ~56 snow_layer  
fill ~13 ~44 ~57 ~14 ~44 ~57 snow_layer  
fill ~13 ~44 ~58 ~14 ~44 ~58 snow_layer  
fill ~13 ~44 ~59 ~14 ~44 ~59 snow_layer  
fill ~13 ~44 ~60 ~14 ~44 ~60 snow_layer  
fill ~13 ~44 ~61 ~14 ~44 ~61 snow_layer  
fill ~13 ~44 ~62 ~14 ~44 ~62 snow_layer  
fill ~13 ~44 ~63 ~14 ~44 ~63 snow_layer  
fill ~13 ~44 ~64 ~14 ~44 ~64 snow_layer  
fill ~13 ~44 ~65 ~14 ~44 ~65 snow_layer  
fill ~13 ~44 ~66 ~14 ~44 ~66 snow_layer  
fill ~13 ~44 ~67 ~14 ~44 ~67 snow_layer  
fill ~13 ~44 ~68 ~14 ~44 ~68 snow_layer  
fill ~13 ~44 ~69 ~14 ~44 ~69 snow_layer  
fill ~13 ~44 ~70 ~14 ~44 ~70 snow_layer  
fill ~13 ~44 ~71 ~14 ~44 ~71 snow_layer  
fill ~13 ~44 ~72 ~14 ~44 ~72 snow_layer  
fill ~13 ~44 ~73 ~14 ~44 ~73 snow_layer  
fill ~13 ~44 ~74 ~14 ~44 ~74 snow_layer  
fill ~13 ~44 ~75 ~14 ~44 ~75 snow_layer  
fill ~13 ~44 ~76 ~14 ~44 ~76 snow_layer  
fill ~13 ~44 ~77 ~14 ~44 ~77 snow_layer  
fill ~13 ~44 ~78 ~24 ~44 ~78 snow_layer  
fill ~13 ~44 ~79 ~24 ~44 ~79 snow_layer  
fill ~15 ~44 ~52 ~26 ~44 ~52 stone  
fill ~15 ~44 ~53 ~15 ~55 ~53 stone  
fill ~15 ~44 ~54 ~15 ~55 ~54 stone  
fill ~15 ~44 ~55 ~15 ~55 ~55 stone  
fill ~15 ~44 ~56 ~15 ~55 ~56 stone  
fill ~15 ~44 ~57 ~15 ~55 ~57 stone  
fill ~15 ~44 ~58 ~15 ~55 ~58 stone  
fill ~15 ~44 ~59 ~15 ~55 ~59 stone  
fill ~15 ~44 ~60 ~15 ~55 ~60 stone  
fill ~15 ~44 ~61 ~15 ~55 ~61 stone  
fill ~15 ~44 ~62 ~15 ~55 ~62 stone  
fill ~15 ~44 ~63 ~15 ~55 ~63 stone  
fill ~15 ~44 ~64 ~15 ~55 ~64 stone  
fill ~15 ~44 ~65 ~15 ~55 ~65 stone  
fill ~15 ~44 ~66 ~15 ~55 ~66 stone  
fill ~15 ~44 ~67 ~15 ~55 ~67 stone  
fill ~15 ~44 ~68 ~15 ~55 ~68 stone  
fill ~15 ~44 ~69 ~15 ~55 ~69 stone  
fill ~15 ~44 ~70 ~15 ~55 ~70 stone  
fill ~15 ~44 ~71 ~15 ~55 ~71 stone  
fill ~15 ~44 ~72 ~15 ~55 ~72 stone  
fill ~15 ~44 ~73 ~15 ~55 ~73 stone  
fill ~15 ~44 ~74 ~15 ~55 ~74 stone  
fill ~15 ~44 ~75 ~15 ~55 ~75 stone  
fill ~15 ~44 ~76 ~15 ~55 ~76 stone  
fill ~15 ~44 ~77 ~26 ~44 ~77 stone  
fill ~24 ~44 ~40 ~35 ~44 ~40 snow_layer  
fill ~24 ~44 ~41 ~24 ~44 ~51 snow_layer  
fill ~24 ~44 ~80 ~24 ~44 ~90 snow_layer  
fill ~25 ~44 ~41 ~50 ~44 ~41 stone  
fill ~25 ~44 ~50 ~26 ~44 ~50 stone  
fill ~25 ~44 ~51 ~26 ~44 ~51 stone  
fill ~25 ~44 ~78 ~26 ~44 ~78 stone  
fill ~25 ~44 ~79 ~26 ~44 ~79 stone  
fill ~25 ~44 ~89 ~52 ~44 ~89 stone  
fill ~25 ~44 ~90 ~53 ~44 ~90 snow_layer  
fill ~26 ~44 ~42 ~35 ~44 ~42 stone  
fill ~26 ~44 ~43 ~26 ~58 ~43 stone  
fill ~26 ~44 ~44 ~26 ~58 ~44 stone  
fill ~26 ~44 ~45 ~26 ~58 ~45 stone  
fill ~26 ~44 ~46 ~26 ~58 ~46 stone  
fill ~26 ~44 ~47 ~26 ~58 ~47 stone  
fill ~26 ~44 ~48 ~26 ~58 ~48 stone  
fill ~26 ~44 ~49 ~26 ~58 ~49 stone  
fill ~26 ~44 ~80 ~26 ~58 ~80 stone  
fill ~26 ~44 ~81 ~26 ~58 ~81 stone  
fill ~26 ~44 ~82 ~26 ~58 ~82 stone  
fill ~26 ~44 ~83 ~26 ~58 ~83 stone  
fill ~26 ~44 ~84 ~26 ~58 ~84 stone  
fill ~26 ~44 ~85 ~26 ~58 ~85 stone  
fill ~26 ~44 ~86 ~26 ~58 ~86 stone  
fill ~26 ~44 ~87 ~26 ~58 ~87 stone  
fill ~26 ~44 ~88 ~26 ~58 ~88 stone  
fill ~37 ~44 ~40 ~51 ~44 ~40 snow_layer  
fill ~45 ~44 ~88 ~52 ~44 ~88 stone  
fill ~49 ~44 ~42 ~49 ~58 ~42 stone  
fill ~49 ~44 ~43 ~49 ~58 ~43 stone  
fill ~49 ~44 ~44 ~49 ~58 ~44 stone  
fill ~49 ~44 ~45 ~49 ~58 ~45 stone  
fill ~49 ~44 ~46 ~49 ~58 ~46 stone  
fill ~49 ~44 ~47 ~49 ~58 ~47 stone  
fill ~49 ~44 ~48 ~49 ~58 ~48 stone  
fill ~49 ~44 ~49 ~49 ~58 ~49 stone  
fill ~49 ~44 ~50 ~50 ~44 ~50 stone  
fill ~49 ~44 ~51 ~50 ~44 ~51 stone  
fill ~49 ~44 ~52 ~63 ~44 ~52 stone  
fill ~51 ~44 ~41 ~51 ~44 ~51 snow_layer  
fill ~51 ~44 ~78 ~63 ~44 ~78 stone  
fill ~51 ~44 ~79 ~52 ~44 ~79 stone  
fill ~51 ~44 ~80 ~51 ~58 ~80 stone  
fill ~51 ~44 ~81 ~51 ~58 ~81 stone  
fill ~51 ~44 ~82 ~51 ~58 ~82 stone  
fill ~51 ~44 ~83 ~51 ~58 ~83 stone  
fill ~51 ~44 ~84 ~51 ~58 ~84 stone  
fill ~51 ~44 ~85 ~51 ~58 ~85 stone  
fill ~51 ~44 ~86 ~51 ~58 ~86 stone  
fill ~51 ~44 ~87 ~51 ~58 ~87 stone  
fill ~52 ~44 ~50 ~64 ~44 ~50 snow_layer  
fill ~52 ~44 ~51 ~64 ~44 ~51 snow_layer  
fill ~53 ~44 ~79 ~64 ~44 ~79 snow_layer  
fill ~53 ~44 ~80 ~53 ~44 ~90 snow_layer  
fill ~62 ~44 ~53 ~62 ~58 ~53 stone  
fill ~62 ~44 ~54 ~62 ~58 ~54 stone  
fill ~62 ~44 ~55 ~62 ~58 ~55 stone  
fill ~62 ~44 ~56 ~62 ~58 ~56 stone  
fill ~62 ~44 ~57 ~62 ~58 ~57 stone  
fill ~62 ~44 ~58 ~62 ~58 ~58 stone  
fill ~62 ~44 ~59 ~62 ~58 ~59 stone  
fill ~62 ~44 ~60 ~62 ~58 ~60 stone  
fill ~62 ~44 ~61 ~62 ~58 ~61 stone  
fill ~62 ~44 ~62 ~62 ~58 ~62 stone  
fill ~62 ~44 ~63 ~62 ~58 ~63 stone  
fill ~62 ~44 ~64 ~62 ~58 ~64 stone  
fill ~62 ~44 ~65 ~62 ~58 ~65 stone  
fill ~62 ~44 ~66 ~62 ~58 ~66 stone  
fill ~62 ~44 ~67 ~62 ~58 ~67 stone  
fill ~62 ~44 ~68 ~62 ~58 ~68 stone  
fill ~62 ~44 ~69 ~62 ~58 ~69 stone  
fill ~62 ~44 ~70 ~62 ~58 ~70 stone  
fill ~62 ~44 ~71 ~62 ~58 ~71 stone  
fill ~62 ~44 ~72 ~62 ~58 ~72 stone  
fill ~62 ~44 ~73 ~62 ~58 ~73 stone  
fill ~62 ~44 ~74 ~62 ~58 ~74 stone  
fill ~62 ~44 ~75 ~62 ~58 ~75 stone  
fill ~62 ~44 ~76 ~62 ~58 ~76 stone  
fill ~62 ~44 ~77 ~62 ~61 ~77 stone  
fill ~64 ~44 ~52 ~64 ~44 ~79 snow_layer  
fill ~15 ~45 ~52 ~26 ~45 ~52 stone  
fill ~15 ~45 ~77 ~26 ~45 ~77 stone  
fill ~25 ~45 ~41 ~34 ~45 ~41 snow_layer  
fill ~25 ~45 ~42 ~25 ~45 ~51 snow_layer  
fill ~25 ~45 ~78 ~25 ~45 ~88 snow_layer  
fill ~26 ~45 ~42 ~42 ~45 ~42 stone  
fill ~26 ~45 ~50 ~26 ~58 ~50 stone  
fill ~26 ~45 ~51 ~26 ~58 ~51 stone  
fill ~26 ~45 ~78 ~26 ~58 ~78 stone  
fill ~26 ~45 ~79 ~26 ~58 ~79 stone  
fill ~26 ~45 ~89 ~45 ~45 ~89 stone  
fill ~35 ~45 ~41 ~49 ~45 ~41 stone  
fill ~36 ~45 ~88 ~51 ~45 ~88 stone  
fill ~46 ~45 ~89 ~52 ~45 ~89 snow_layer  
fill ~49 ~45 ~50 ~49 ~58 ~50 stone  
fill ~49 ~45 ~51 ~49 ~58 ~51 stone  
fill ~49 ~45 ~52 ~62 ~45 ~52 stone  
fill ~50 ~45 ~41 ~50 ~45 ~51 snow_layer  
fill ~51 ~45 ~78 ~62 ~45 ~78 stone  
fill ~51 ~45 ~79 ~51 ~58 ~79 stone  
fill ~52 ~45 ~80 ~52 ~45 ~89 snow_layer  
fill ~63 ~45 ~52 ~63 ~45 ~53 snow_layer  
fill ~63 ~45 ~55 ~63 ~45 ~78 snow_layer  
fill ~15 ~46 ~52 ~26 ~46 ~52 stone  
fill ~15 ~46 ~77 ~26 ~46 ~77 stone  
fill ~16 ~46 ~53 ~18 ~46 ~53 stone  
fill ~26 ~46 ~42 ~49 ~46 ~42 stone  
fill ~26 ~46 ~89 ~36 ~46 ~89 stone  
fill ~30 ~46 ~88 ~51 ~46 ~88 stone  
fill ~35 ~46 ~41 ~41 ~46 ~41 snow_layer  
fill ~37 ~46 ~89 ~45 ~46 ~89 snow_layer  
fill ~42 ~46 ~41 ~49 ~46 ~41 stone  
fill ~49 ~46 ~52 ~62 ~46 ~52 stone  
fill ~51 ~46 ~78 ~62 ~46 ~78 stone  
fill ~15 ~47 ~52 ~17 ~47 ~52 snow_layer  
fill ~15 ~47 ~77 ~26 ~47 ~77 stone  
fill ~16 ~47 ~53 ~25 ~47 ~53 stone  
fill ~18 ~47 ~52 ~26 ~47 ~52 stone  
fill ~26 ~47 ~42 ~49 ~47 ~42 stone  
fill ~26 ~47 ~89 ~31 ~47 ~89 stone  
fill ~27 ~47 ~88 ~51 ~47 ~88 stone  
fill ~32 ~47 ~89 ~36 ~47 ~89 snow_layer  
fill ~42 ~47 ~41 ~45 ~47 ~41 snow_layer 
setblock ~47 ~47 ~41 snow_layer 0  
fill ~48 ~47 ~41 ~49 ~47 ~41 stone  
fill ~49 ~47 ~52 ~62 ~47 ~52 stone  
fill ~51 ~47 ~78 ~62 ~47 ~78 stone  
fill ~57 ~47 ~77 ~62 ~47 ~77 stone  
fill ~15 ~48 ~77 ~26 ~48 ~77 stone  
fill ~16 ~48 ~53 ~26 ~48 ~53 stone  
fill ~18 ~48 ~52 ~24 ~48 ~52 snow_layer  
fill ~25 ~48 ~52 ~26 ~48 ~52 stone  
fill ~26 ~48 ~42 ~49 ~48 ~42 stone  
fill ~27 ~48 ~88 ~51 ~48 ~88 stone  
fill ~29 ~48 ~89 ~31 ~48 ~89 snow_layer  
fill ~48 ~48 ~41 ~49 ~48 ~41 snow_layer  
fill ~49 ~48 ~52 ~62 ~48 ~52 stone  
fill ~51 ~48 ~77 ~62 ~48 ~77 stone  
fill ~51 ~48 ~78 ~57 ~48 ~78 stone  
fill ~58 ~48 ~78 ~62 ~48 ~78 snow_layer  
fill ~15 ~49 ~77 ~26 ~49 ~77 stone  
fill ~16 ~49 ~53 ~26 ~49 ~53 stone 
setblock ~25 ~49 ~52 snow_layer 0  
fill ~26 ~49 ~42 ~49 ~49 ~42 stone  
fill ~26 ~49 ~52 ~26 ~58 ~52 stone  
fill ~27 ~49 ~88 ~51 ~49 ~88 stone  
fill ~49 ~49 ~52 ~62 ~49 ~52 stone  
fill ~51 ~49 ~77 ~62 ~49 ~77 stone  
fill ~51 ~49 ~78 ~51 ~58 ~78 stone  
fill ~53 ~49 ~78 ~57 ~49 ~78 snow_layer  
fill ~15 ~50 ~77 ~26 ~50 ~77 stone  
fill ~16 ~50 ~53 ~26 ~50 ~53 stone  
fill ~26 ~50 ~42 ~49 ~50 ~42 stone  
fill ~27 ~50 ~88 ~51 ~50 ~88 stone  
fill ~49 ~50 ~52 ~62 ~50 ~52 stone  
fill ~51 ~50 ~77 ~62 ~50 ~77 stone  
fill ~15 ~51 ~77 ~26 ~51 ~77 stone  
fill ~16 ~51 ~53 ~26 ~51 ~53 stone  
fill ~26 ~51 ~42 ~49 ~51 ~42 stone  
fill ~27 ~51 ~88 ~51 ~51 ~88 stone  
fill ~49 ~51 ~52 ~62 ~51 ~52 stone  
fill ~49 ~51 ~53 ~52 ~51 ~53 stone  
fill ~51 ~51 ~77 ~62 ~51 ~77 stone  
fill ~15 ~52 ~77 ~26 ~52 ~77 stone  
fill ~16 ~52 ~53 ~26 ~52 ~53 stone  
fill ~24 ~52 ~76 ~26 ~52 ~76 stone  
fill ~26 ~52 ~42 ~49 ~52 ~42 stone  
fill ~27 ~52 ~88 ~51 ~52 ~88 stone  
fill ~49 ~52 ~52 ~49 ~58 ~52 stone  
fill ~49 ~52 ~53 ~60 ~52 ~53 stone  
fill ~50 ~52 ~52 ~51 ~52 ~52 snow_layer  
fill ~51 ~52 ~77 ~62 ~52 ~77 stone  
fill ~52 ~52 ~52 ~62 ~52 ~52 stone  
fill ~15 ~53 ~77 ~23 ~53 ~77 stone  
fill ~16 ~53 ~53 ~26 ~53 ~53 stone  
fill ~18 ~53 ~76 ~26 ~53 ~76 stone  
fill ~24 ~53 ~77 ~25 ~53 ~77 snow_layer  
fill ~26 ~53 ~42 ~49 ~53 ~42 stone  
fill ~26 ~53 ~77 ~26 ~58 ~77 stone  
fill ~27 ~53 ~88 ~51 ~53 ~88 stone  
fill ~49 ~53 ~53 ~62 ~53 ~53 stone  
fill ~51 ~53 ~77 ~62 ~53 ~77 stone  
fill ~52 ~53 ~52 ~57 ~53 ~52 snow_layer  
fill ~60 ~53 ~52 ~62 ~53 ~52 stone  
fill ~15 ~54 ~77 ~18 ~54 ~77 stone  
fill ~16 ~54 ~53 ~26 ~54 ~53 stone  
fill ~16 ~54 ~76 ~26 ~54 ~76 stone  
fill ~19 ~54 ~77 ~22 ~54 ~77 snow_layer  
fill ~26 ~54 ~42 ~49 ~54 ~42 stone  
fill ~27 ~54 ~88 ~51 ~54 ~88 stone  
fill ~49 ~54 ~53 ~62 ~54 ~53 stone  
fill ~51 ~54 ~77 ~62 ~54 ~77 stone  
fill ~60 ~54 ~52 ~62 ~54 ~52 snow_layer  
fill ~15 ~55 ~77 ~18 ~55 ~77 snow_layer  
fill ~16 ~55 ~53 ~26 ~55 ~53 stone  
fill ~16 ~55 ~54 ~16 ~58 ~54 stone  
fill ~16 ~55 ~55 ~16 ~58 ~55 stone  
fill ~16 ~55 ~56 ~16 ~58 ~56 stone  
fill ~16 ~55 ~57 ~16 ~58 ~57 stone  
fill ~16 ~55 ~58 ~16 ~58 ~58 stone  
fill ~16 ~55 ~59 ~16 ~58 ~59 stone  
fill ~16 ~55 ~60 ~16 ~58 ~60 stone  
fill ~16 ~55 ~61 ~16 ~58 ~61 stone  
fill ~16 ~55 ~62 ~16 ~58 ~62 stone  
fill ~16 ~55 ~63 ~16 ~58 ~63 stone  
fill ~16 ~55 ~64 ~16 ~58 ~64 stone  
fill ~16 ~55 ~65 ~16 ~58 ~65 stone  
fill ~16 ~55 ~66 ~16 ~58 ~66 stone  
fill ~16 ~55 ~67 ~16 ~58 ~67 stone  
fill ~16 ~55 ~68 ~16 ~58 ~68 stone  
fill ~16 ~55 ~69 ~16 ~58 ~69 stone  
fill ~16 ~55 ~70 ~16 ~58 ~70 stone  
fill ~16 ~55 ~71 ~16 ~58 ~71 stone  
fill ~16 ~55 ~72 ~16 ~58 ~72 stone  
fill ~16 ~55 ~73 ~16 ~58 ~73 stone  
fill ~16 ~55 ~74 ~16 ~58 ~74 stone  
fill ~16 ~55 ~75 ~16 ~58 ~75 stone  
fill ~16 ~55 ~76 ~26 ~55 ~76 stone  
fill ~26 ~55 ~42 ~49 ~55 ~42 stone  
fill ~27 ~55 ~88 ~51 ~55 ~88 stone  
fill ~49 ~55 ~53 ~62 ~55 ~53 stone  
fill ~51 ~55 ~77 ~62 ~55 ~77 stone 
setblock ~15 ~56 ~55 snow_layer 0  
fill ~15 ~56 ~57 ~15 ~56 ~58 snow_layer  
fill ~15 ~56 ~62 ~15 ~56 ~67 snow_layer  
fill ~15 ~56 ~73 ~15 ~56 ~74 snow_layer  
fill ~16 ~56 ~53 ~26 ~56 ~53 stone  
fill ~16 ~56 ~76 ~26 ~56 ~76 stone  
fill ~26 ~56 ~42 ~49 ~56 ~42 stone  
fill ~27 ~56 ~88 ~51 ~56 ~88 stone  
fill ~49 ~56 ~53 ~62 ~56 ~53 stone  
fill ~51 ~56 ~77 ~62 ~56 ~77 stone  
fill ~16 ~57 ~53 ~26 ~57 ~53 stone  
fill ~16 ~57 ~76 ~26 ~57 ~76 stone  
fill ~26 ~57 ~42 ~49 ~57 ~42 stone  
fill ~27 ~57 ~88 ~51 ~57 ~88 stone  
fill ~49 ~57 ~53 ~62 ~57 ~53 stone  
fill ~51 ~57 ~77 ~62 ~57 ~77 stone  
fill ~15 ~58 ~52 ~26 ~58 ~52 stone  
fill ~15 ~58 ~53 ~26 ~58 ~53 stone  
fill ~15 ~58 ~54 ~15 ~61 ~54 stone  
fill ~15 ~58 ~55 ~15 ~61 ~55 stone  
fill ~15 ~58 ~56 ~15 ~61 ~56 stone  
fill ~15 ~58 ~57 ~15 ~61 ~57 stone  
fill ~15 ~58 ~58 ~15 ~61 ~58 stone  
fill ~15 ~58 ~59 ~15 ~61 ~59 stone  
fill ~15 ~58 ~60 ~15 ~61 ~60 stone  
fill ~15 ~58 ~61 ~15 ~61 ~61 stone  
fill ~15 ~58 ~62 ~15 ~61 ~62 stone  
fill ~15 ~58 ~63 ~15 ~61 ~63 stone  
fill ~15 ~58 ~64 ~15 ~61 ~64 stone  
fill ~15 ~58 ~65 ~15 ~61 ~65 stone  
fill ~15 ~58 ~66 ~15 ~61 ~66 stone  
fill ~15 ~58 ~67 ~15 ~61 ~67 stone  
fill ~15 ~58 ~68 ~15 ~61 ~68 stone  
fill ~15 ~58 ~69 ~15 ~61 ~69 stone  
fill ~15 ~58 ~70 ~15 ~61 ~70 stone  
fill ~15 ~58 ~71 ~15 ~61 ~71 stone  
fill ~15 ~58 ~72 ~15 ~61 ~72 stone  
fill ~15 ~58 ~73 ~15 ~61 ~73 stone  
fill ~15 ~58 ~74 ~15 ~61 ~74 stone  
fill ~15 ~58 ~75 ~15 ~61 ~75 stone  
fill ~15 ~58 ~76 ~26 ~58 ~76 stone  
fill ~15 ~58 ~77 ~26 ~58 ~77 stone  
fill ~25 ~58 ~41 ~50 ~58 ~41 stone  
fill ~25 ~58 ~42 ~50 ~58 ~42 stone  
fill ~25 ~58 ~43 ~25 ~61 ~43 stone  
fill ~25 ~58 ~44 ~25 ~61 ~44 stone  
fill ~25 ~58 ~45 ~25 ~61 ~45 stone  
fill ~25 ~58 ~46 ~25 ~61 ~46 stone  
fill ~25 ~58 ~47 ~25 ~61 ~47 stone  
fill ~25 ~58 ~48 ~25 ~61 ~48 stone  
fill ~25 ~58 ~49 ~25 ~61 ~49 stone  
fill ~25 ~58 ~50 ~25 ~61 ~50 stone  
fill ~25 ~58 ~51 ~25 ~61 ~51 stone  
fill ~25 ~58 ~78 ~25 ~61 ~78 stone  
fill ~25 ~58 ~79 ~25 ~61 ~79 stone  
fill ~25 ~58 ~80 ~25 ~61 ~80 stone  
fill ~25 ~58 ~81 ~25 ~61 ~81 stone  
fill ~25 ~58 ~82 ~25 ~61 ~82 stone  
fill ~25 ~58 ~83 ~25 ~61 ~83 stone  
fill ~25 ~58 ~84 ~25 ~61 ~84 stone  
fill ~25 ~58 ~85 ~25 ~61 ~85 stone  
fill ~25 ~58 ~86 ~25 ~61 ~86 stone  
fill ~25 ~58 ~87 ~25 ~61 ~87 stone  
fill ~25 ~58 ~88 ~25 ~61 ~88 stone  
fill ~25 ~58 ~89 ~52 ~58 ~89 stone  
fill ~27 ~58 ~88 ~52 ~58 ~88 stone  
fill ~49 ~58 ~53 ~63 ~58 ~53 stone  
fill ~50 ~58 ~43 ~50 ~61 ~43 stone  
fill ~50 ~58 ~44 ~50 ~61 ~44 stone  
fill ~50 ~58 ~45 ~50 ~61 ~45 stone  
fill ~50 ~58 ~46 ~50 ~61 ~46 stone  
fill ~50 ~58 ~47 ~50 ~61 ~47 stone  
fill ~50 ~58 ~48 ~50 ~61 ~48 stone  
fill ~50 ~58 ~49 ~50 ~61 ~49 stone  
fill ~50 ~58 ~50 ~50 ~61 ~50 stone  
fill ~50 ~58 ~51 ~50 ~61 ~51 stone  
fill ~50 ~58 ~52 ~63 ~58 ~52 stone  
fill ~51 ~58 ~76 ~63 ~58 ~76 stone  
fill ~51 ~58 ~77 ~63 ~58 ~77 stone  
fill ~52 ~58 ~78 ~52 ~61 ~78 stone  
fill ~52 ~58 ~79 ~52 ~61 ~79 stone  
fill ~52 ~58 ~80 ~52 ~61 ~80 stone  
fill ~52 ~58 ~81 ~52 ~61 ~81 stone  
fill ~52 ~58 ~82 ~52 ~61 ~82 stone  
fill ~52 ~58 ~83 ~52 ~61 ~83 stone  
fill ~52 ~58 ~84 ~52 ~61 ~84 stone  
fill ~52 ~58 ~85 ~52 ~61 ~85 stone  
fill ~52 ~58 ~86 ~52 ~61 ~86 stone  
fill ~52 ~58 ~87 ~52 ~61 ~87 stone  
fill ~63 ~58 ~54 ~63 ~61 ~54 stone  
fill ~63 ~58 ~55 ~63 ~61 ~55 stone  
fill ~63 ~58 ~56 ~63 ~61 ~56 stone  
fill ~63 ~58 ~57 ~63 ~61 ~57 stone  
fill ~63 ~58 ~58 ~63 ~61 ~58 stone  
fill ~63 ~58 ~59 ~63 ~61 ~59 stone  
fill ~63 ~58 ~60 ~63 ~61 ~60 stone  
fill ~63 ~58 ~61 ~63 ~61 ~61 stone  
fill ~63 ~58 ~62 ~63 ~61 ~62 stone  
fill ~63 ~58 ~63 ~63 ~61 ~63 stone  
fill ~63 ~58 ~64 ~63 ~61 ~64 stone  
fill ~63 ~58 ~65 ~63 ~61 ~65 stone  
fill ~63 ~58 ~66 ~63 ~61 ~66 stone  
fill ~63 ~58 ~67 ~63 ~61 ~67 stone  
fill ~63 ~58 ~68 ~63 ~61 ~68 stone  
fill ~63 ~58 ~69 ~63 ~61 ~69 stone  
fill ~63 ~58 ~70 ~63 ~61 ~70 stone  
fill ~63 ~58 ~71 ~63 ~61 ~71 stone  
fill ~63 ~58 ~72 ~63 ~61 ~72 stone  
fill ~63 ~58 ~73 ~63 ~61 ~73 stone  
fill ~63 ~58 ~74 ~63 ~61 ~74 stone  
fill ~63 ~58 ~75 ~63 ~61 ~75 stone  
fill ~15 ~59 ~52 ~25 ~59 ~52 stone  
fill ~15 ~59 ~53 ~15 ~61 ~53 stone  
fill ~15 ~59 ~76 ~15 ~61 ~76 stone  
fill ~15 ~59 ~77 ~25 ~59 ~77 stone  
fill ~25 ~59 ~41 ~50 ~59 ~41 stone  
fill ~25 ~59 ~42 ~25 ~61 ~42 stone  
fill ~25 ~59 ~89 ~52 ~59 ~89 stone  
fill ~50 ~59 ~42 ~50 ~61 ~42 stone  
fill ~50 ~59 ~52 ~63 ~59 ~52 stone  

KittysCommands:   
fill ~52 ~59 ~77 ~63 ~59 ~77 stone  
fill ~52 ~59 ~88 ~52 ~61 ~88 stone  
fill ~63 ~59 ~53 ~63 ~61 ~53 stone  
fill ~63 ~59 ~76 ~63 ~61 ~76 stone  
fill ~15 ~60 ~52 ~25 ~60 ~52 stone  
fill ~15 ~60 ~77 ~25 ~60 ~77 stone  
fill ~25 ~60 ~41 ~50 ~60 ~41 stone  
fill ~25 ~60 ~89 ~52 ~60 ~89 stone  
fill ~50 ~60 ~52 ~63 ~60 ~52 stone  
fill ~52 ~60 ~77 ~63 ~60 ~77 stone  
fill ~15 ~61 ~52 ~63 ~61 ~52 stone  
fill ~15 ~61 ~77 ~63 ~61 ~77 stone  
fill ~16 ~61 ~53 ~63 ~61 ~53 stone  
fill ~16 ~61 ~54 ~63 ~61 ~54 stone  
fill ~16 ~61 ~55 ~63 ~61 ~55 stone  
fill ~16 ~61 ~56 ~63 ~61 ~56 stone  
fill ~16 ~61 ~57 ~63 ~61 ~57 stone  
fill ~16 ~61 ~58 ~63 ~61 ~58 stone  
fill ~16 ~61 ~59 ~63 ~61 ~59 stone  
fill ~16 ~61 ~60 ~63 ~61 ~60 stone  
fill ~16 ~61 ~61 ~63 ~61 ~61 stone  
fill ~16 ~61 ~62 ~63 ~61 ~62 stone  
fill ~16 ~61 ~63 ~63 ~61 ~63 stone  
fill ~16 ~61 ~64 ~63 ~61 ~64 stone  
fill ~16 ~61 ~65 ~63 ~61 ~65 stone  
fill ~16 ~61 ~66 ~63 ~61 ~66 stone  
fill ~16 ~61 ~67 ~63 ~61 ~67 stone  
fill ~16 ~61 ~68 ~63 ~61 ~68 stone  
fill ~16 ~61 ~69 ~63 ~61 ~69 stone  
fill ~16 ~61 ~70 ~63 ~61 ~70 stone  
fill ~16 ~61 ~71 ~63 ~61 ~71 stone  
fill ~16 ~61 ~72 ~63 ~61 ~72 stone  
fill ~16 ~61 ~73 ~63 ~61 ~73 stone  
fill ~16 ~61 ~74 ~63 ~61 ~74 stone  
fill ~16 ~61 ~75 ~63 ~61 ~75 stone  
fill ~16 ~61 ~76 ~63 ~61 ~76 stone  
fill ~25 ~61 ~41 ~50 ~61 ~41 stone  
fill ~25 ~61 ~89 ~52 ~61 ~89 stone  
fill ~26 ~61 ~42 ~50 ~61 ~42 stone  
fill ~26 ~61 ~43 ~50 ~61 ~43 stone  
fill ~26 ~61 ~44 ~50 ~61 ~44 stone  
fill ~26 ~61 ~45 ~50 ~61 ~45 stone  
fill ~26 ~61 ~46 ~50 ~61 ~46 stone  
fill ~26 ~61 ~47 ~50 ~61 ~47 stone  
fill ~26 ~61 ~48 ~50 ~61 ~48 stone  
fill ~26 ~61 ~49 ~50 ~61 ~49 stone  
fill ~26 ~61 ~50 ~50 ~61 ~50 stone  
fill ~26 ~61 ~51 ~50 ~61 ~51 stone  
fill ~26 ~61 ~78 ~52 ~61 ~78 stone  
fill ~26 ~61 ~79 ~52 ~61 ~79 stone  
fill ~26 ~61 ~80 ~52 ~61 ~80 stone  
fill ~26 ~61 ~81 ~52 ~61 ~81 stone  
fill ~26 ~61 ~82 ~52 ~61 ~82 stone  
fill ~26 ~61 ~83 ~52 ~61 ~83 stone  
fill ~26 ~61 ~84 ~52 ~61 ~84 stone  
fill ~26 ~61 ~85 ~52 ~61 ~85 stone  
fill ~26 ~61 ~86 ~52 ~61 ~86 stone  
fill ~26 ~61 ~87 ~52 ~61 ~87 stone  
fill ~26 ~61 ~88 ~52 ~61 ~88 stone  
fill ~15 ~62 ~52 ~23 ~62 ~52 snow_layer  
fill ~15 ~62 ~53 ~22 ~62 ~53 snow_layer  
fill ~15 ~62 ~54 ~22 ~62 ~54 snow_layer  
fill ~15 ~62 ~55 ~21 ~62 ~55 snow_layer  
fill ~15 ~62 ~56 ~21 ~62 ~56 snow_layer  
fill ~15 ~62 ~57 ~21 ~62 ~57 snow_layer  
fill ~15 ~62 ~58 ~21 ~62 ~58 snow_layer  
fill ~15 ~62 ~59 ~21 ~62 ~59 snow_layer  
fill ~15 ~62 ~60 ~20 ~62 ~60 snow_layer  
fill ~15 ~62 ~61 ~20 ~62 ~61 snow_layer  
fill ~15 ~62 ~62 ~20 ~62 ~62 snow_layer  
fill ~15 ~62 ~63 ~20 ~62 ~63 snow_layer  
fill ~15 ~62 ~64 ~20 ~62 ~64 snow_layer  
fill ~15 ~62 ~65 ~20 ~62 ~65 snow_layer  
fill ~15 ~62 ~66 ~20 ~62 ~66 snow_layer  
fill ~15 ~62 ~67 ~20 ~62 ~67 snow_layer  
fill ~15 ~62 ~68 ~20 ~62 ~68 snow_layer  
fill ~15 ~62 ~69 ~20 ~62 ~69 snow_layer  
fill ~15 ~62 ~70 ~20 ~62 ~70 snow_layer  
fill ~15 ~62 ~71 ~21 ~62 ~71 snow_layer  
fill ~15 ~62 ~72 ~21 ~62 ~72 snow_layer  
fill ~15 ~62 ~73 ~21 ~62 ~73 snow_layer  
fill ~15 ~62 ~74 ~21 ~62 ~74 snow_layer  
fill ~15 ~62 ~75 ~21 ~62 ~75 snow_layer  
fill ~15 ~62 ~76 ~22 ~62 ~76 snow_layer  
fill ~15 ~62 ~77 ~23 ~62 ~77 snow_layer  
fill ~24 ~62 ~60 ~24 ~62 ~70 glowstone  
fill ~25 ~62 ~41 ~34 ~62 ~41 snow_layer  
fill ~25 ~62 ~42 ~33 ~62 ~42 snow_layer  
fill ~25 ~62 ~43 ~32 ~62 ~43 snow_layer  
fill ~25 ~62 ~44 ~31 ~62 ~44 snow_layer  
fill ~25 ~62 ~45 ~30 ~62 ~45 snow_layer  
fill ~25 ~62 ~46 ~29 ~62 ~46 snow_layer  
fill ~25 ~62 ~47 ~28 ~62 ~47 snow_layer  
fill ~25 ~62 ~48 ~27 ~62 ~48 snow_layer  
fill ~25 ~62 ~49 ~26 ~62 ~49 snow_layer  
fill ~25 ~62 ~50 ~25 ~62 ~41 snow_layer  
fill ~25 ~62 ~55 ~25 ~62 ~59 glowstone  
fill ~25 ~62 ~71 ~25 ~62 ~75 glowstone  
fill ~25 ~62 ~80 ~25 ~62 ~89 snow_layer  
fill ~26 ~62 ~53 ~26 ~62 ~54 glowstone  
fill ~26 ~62 ~61 ~27 ~62 ~61 stone  
fill ~26 ~62 ~62 ~26 ~66 ~62 stone  
fill ~26 ~62 ~63 ~26 ~66 ~63 stone  
fill ~26 ~62 ~64 ~26 ~67 ~64 stone  
fill ~26 ~62 ~65 ~26 ~67 ~65 stone  
fill ~26 ~62 ~66 ~26 ~67 ~66 stone  
fill ~26 ~62 ~67 ~26 ~66 ~67 stone  
fill ~26 ~62 ~68 ~27 ~62 ~68 stone 
setblock ~26 ~62 ~76 glowstone 0  
fill ~26 ~62 ~83 ~26 ~62 ~89 snow_layer 
setblock ~27 ~62 ~52 glowstone 0  
fill ~27 ~62 ~56 ~28 ~62 ~56 stone  
fill ~27 ~62 ~57 ~27 ~64 ~57 stone  
fill ~27 ~62 ~58 ~27 ~65 ~58 stone  
fill ~27 ~62 ~59 ~27 ~66 ~59 stone  
fill ~27 ~62 ~60 ~27 ~70 ~60 stone  
fill ~27 ~62 ~69 ~27 ~72 ~69 stone  
fill ~27 ~62 ~70 ~27 ~67 ~70 stone  
fill ~27 ~62 ~71 ~27 ~65 ~71 stone  
fill ~27 ~62 ~72 ~27 ~64 ~72 stone  
fill ~27 ~62 ~73 ~27 ~63 ~73 stone  
