setblock ~11 ~0 ~102 purple_shulker_box 1 
setblock ~11 ~0 ~107 beacon 0  
fill ~13 ~0 ~99 ~13 ~16 ~99 quartz_block 0  
fill ~13 ~0 ~100 ~13 ~0 ~99 quartz_block 0 
setblock ~15 ~0 ~109 beacon 0 
setblock ~17 ~0 ~107 tallgrass 1  
fill ~19 ~0 ~107 ~19 ~0 ~109 tallgrass 1  
fill ~71 ~0 ~87 ~72 ~0 ~87 quartz_block 0  
fill ~71 ~0 ~88 ~71 ~8 ~88 quartz_block 0  
fill ~71 ~0 ~89 ~72 ~0 ~89 quartz_block 0  
fill ~71 ~0 ~90 ~72 ~0 ~90 quartz_block 0  
fill ~71 ~0 ~92 ~72 ~0 ~92 quartz_block 0  
fill ~71 ~0 ~93 ~72 ~0 ~93 quartz_block 0  
fill ~71 ~0 ~94 ~72 ~0 ~94 quartz_block 0  
fill ~72 ~0 ~85 ~73 ~0 ~85 quartz_block 0  
fill ~72 ~0 ~86 ~72 ~6 ~86 quartz_block 0  
fill ~72 ~0 ~91 ~72 ~21 ~91 quartz_block 0  
fill ~72 ~0 ~95 ~73 ~0 ~95 quartz_block 0  
fill ~73 ~0 ~80 ~74 ~0 ~80 quartz_block 0  
fill ~73 ~0 ~81 ~74 ~0 ~81 quartz_block 0  
fill ~73 ~0 ~82 ~73 ~11 ~82 quartz_block 0  
fill ~73 ~0 ~83 ~74 ~0 ~83 quartz_block 0  
fill ~73 ~0 ~84 ~74 ~0 ~84 quartz_block 0  
fill ~73 ~0 ~96 ~74 ~0 ~96 quartz_block 0  
fill ~73 ~0 ~97 ~74 ~0 ~97 quartz_block 0  
fill ~74 ~0 ~79 ~75 ~0 ~79 quartz_block 0  
fill ~74 ~0 ~98 ~75 ~0 ~98 quartz_block 0  
fill ~75 ~0 ~78 ~76 ~0 ~78 quartz_block 0  
fill ~75 ~0 ~99 ~78 ~0 ~99 quartz_block 0  
fill ~77 ~0 ~77 ~82 ~0 ~77 quartz_block 0  
fill ~77 ~0 ~100 ~78 ~0 ~100 quartz_block 0  
fill ~78 ~0 ~101 ~80 ~0 ~101 quartz_block 0  
fill ~78 ~0 ~102 ~81 ~0 ~102 quartz_block 0  
fill ~79 ~0 ~76 ~84 ~0 ~76 quartz_block 0  
fill ~81 ~0 ~103 ~87 ~0 ~103 quartz_block 0  
fill ~84 ~0 ~75 ~94 ~0 ~75 quartz_block 0  
fill ~84 ~0 ~104 ~95 ~0 ~104 quartz_block 0  
fill ~87 ~0 ~76 ~91 ~0 ~76 quartz_block 0  
fill ~92 ~0 ~103 ~93 ~0 ~103 quartz_block 0  
fill ~93 ~0 ~76 ~100 ~0 ~76 quartz_block 0  
fill ~95 ~0 ~77 ~102 ~0 ~77 quartz_block 0  
fill ~95 ~0 ~103 ~98 ~0 ~103 quartz_block 0  
fill ~98 ~0 ~102 ~101 ~0 ~102 quartz_block 0  
fill ~99 ~0 ~101 ~101 ~0 ~101 quartz_block 0  
fill ~101 ~0 ~78 ~103 ~0 ~78 quartz_block 0  
fill ~102 ~0 ~100 ~102 ~18 ~100 quartz_block 0  
fill ~103 ~0 ~79 ~105 ~0 ~79 quartz_block 0  
fill ~103 ~0 ~99 ~104 ~0 ~99 quartz_block 0  
fill ~104 ~0 ~80 ~106 ~0 ~80 quartz_block 0  
fill ~105 ~0 ~-9 ~107 ~0 ~-9 leaves 0  
fill ~105 ~0 ~81 ~106 ~0 ~81 quartz_block 0  
fill ~105 ~0 ~82 ~106 ~0 ~82 quartz_block 0  
fill ~105 ~0 ~83 ~106 ~0 ~83 quartz_block 0  
fill ~105 ~0 ~84 ~106 ~0 ~84 quartz_block 0  
fill ~105 ~0 ~96 ~106 ~0 ~96 quartz_block 0  
fill ~105 ~0 ~97 ~106 ~0 ~97 quartz_block 0  
fill ~105 ~0 ~98 ~105 ~54 ~98 quartz_block 0  
fill ~106 ~0 ~-10 ~108 ~0 ~-10 leaves 0  
fill ~106 ~0 ~-6 ~106 ~2 ~-6 leaves 0  
fill ~106 ~0 ~85 ~106 ~5 ~85 quartz_block 0  
fill ~106 ~0 ~90 ~107 ~0 ~90 quartz_block 0  
fill ~106 ~0 ~91 ~107 ~0 ~91 quartz_block 0  
fill ~106 ~0 ~92 ~107 ~0 ~92 quartz_block 0  
fill ~106 ~0 ~94 ~107 ~0 ~94 quartz_block 0  
fill ~106 ~0 ~95 ~107 ~0 ~95 quartz_block 0  
fill ~107 ~0 ~-7 ~108 ~0 ~-7 leaves 0 
setblock ~107 ~0 ~-6 log 8  
fill ~107 ~0 ~-5 ~112 ~0 ~-5 leaves 0  
fill ~107 ~0 ~86 ~107 ~2 ~86 quartz_block 0  
fill ~107 ~0 ~87 ~107 ~8 ~87 quartz_block 0  
fill ~107 ~0 ~88 ~108 ~0 ~88 quartz_block 0  
fill ~107 ~0 ~89 ~108 ~0 ~89 quartz_block 0  
fill ~107 ~0 ~93 ~107 ~8 ~93 quartz_block 0  
fill ~108 ~0 ~-6 ~108 ~6 ~-6 leaves 0  
fill ~108 ~0 ~-4 ~112 ~0 ~-4 leaves 0  
fill ~109 ~0 ~-9 ~109 ~5 ~-9 log 0  
fill ~109 ~0 ~-8 ~111 ~0 ~-8 leaves 0  
fill ~109 ~0 ~-7 ~109 ~0 ~-6 log 8  
fill ~109 ~0 ~-3 ~111 ~0 ~-3 leaves 0  
fill ~110 ~0 ~-7 ~112 ~0 ~-7 leaves 0  
fill ~110 ~0 ~-6 ~110 ~4 ~-6 leaves 0 
setblock ~111 ~0 ~-6 log 8  
fill ~112 ~0 ~-6 ~112 ~3 ~-6 leaves 0  
fill ~13 ~1 ~100 ~13 ~16 ~100 ladder 3  
fill ~71 ~1 ~87 ~72 ~1 ~87 quartz_block 0  
fill ~71 ~1 ~89 ~71 ~13 ~89 quartz_block 0  
fill ~71 ~1 ~90 ~72 ~1 ~90 quartz_block 0  
fill ~71 ~1 ~93 ~72 ~1 ~93 quartz_block 0  
fill ~71 ~1 ~94 ~72 ~1 ~94 quartz_block 0  
fill ~72 ~1 ~85 ~74 ~1 ~85 quartz_block 0  
fill ~72 ~1 ~88 ~72 ~2 ~88 quartz_block 0  
fill ~72 ~1 ~92 ~72 ~13 ~92 quartz_block 0  
fill ~72 ~1 ~95 ~73 ~1 ~95 quartz_block 0  
fill ~73 ~1 ~80 ~74 ~1 ~80 quartz_block 0  
fill ~73 ~1 ~81 ~74 ~1 ~81 quartz_block 0  
fill ~73 ~1 ~83 ~74 ~1 ~83 quartz_block 0  
fill ~73 ~1 ~84 ~74 ~1 ~84 quartz_block 0  
fill ~73 ~1 ~86 ~73 ~16 ~86 quartz_block 0  
fill ~73 ~1 ~91 ~73 ~3 ~91 quartz_block 0  
fill ~73 ~1 ~96 ~74 ~1 ~96 quartz_block 0  
fill ~73 ~1 ~97 ~74 ~1 ~97 quartz_block 0  
fill ~74 ~1 ~79 ~76 ~1 ~79 quartz_block 0  
fill ~74 ~1 ~82 ~74 ~3 ~82 quartz_block 0  
fill ~74 ~1 ~98 ~75 ~1 ~98 quartz_block 0  
fill ~74 ~1 ~99 ~78 ~1 ~99 quartz_block 0  
fill ~75 ~1 ~78 ~77 ~1 ~78 quartz_block 0  
fill ~76 ~1 ~100 ~78 ~1 ~100 quartz_block 0  
fill ~77 ~1 ~77 ~83 ~1 ~77 quartz_block 0  
fill ~78 ~1 ~101 ~79 ~1 ~101 quartz_block 0  
fill ~78 ~1 ~102 ~82 ~1 ~102 quartz_block 0  
fill ~81 ~1 ~76 ~85 ~1 ~76 quartz_block 0  
fill ~81 ~1 ~103 ~87 ~1 ~103 quartz_block 0  
fill ~84 ~1 ~75 ~94 ~1 ~75 quartz_block 0  
fill ~84 ~1 ~104 ~95 ~1 ~104 quartz_block 0  
fill ~90 ~1 ~76 ~90 ~3 ~76 quartz_block 0  
fill ~92 ~1 ~76 ~98 ~1 ~76 quartz_block 0  
fill ~95 ~1 ~77 ~102 ~1 ~77 quartz_block 0  
fill ~96 ~1 ~103 ~98 ~1 ~103 quartz_block 0  
fill ~97 ~1 ~102 ~101 ~1 ~102 quartz_block 0  
fill ~99 ~1 ~101 ~101 ~1 ~101 quartz_block 0  
fill ~101 ~1 ~78 ~103 ~1 ~78 quartz_block 0  
fill ~101 ~1 ~100 ~101 ~2 ~100 quartz_block 0  
fill ~102 ~1 ~79 ~104 ~1 ~79 quartz_block 0  
fill ~102 ~1 ~99 ~104 ~1 ~99 quartz_block 0  
fill ~104 ~1 ~80 ~106 ~1 ~80 quartz_block 0  
fill ~105 ~1 ~-10 ~108 ~1 ~-10 leaves 0  
fill ~105 ~1 ~-9 ~107 ~1 ~-9 leaves 0  
fill ~105 ~1 ~-7 ~113 ~1 ~-7 leaves 0  
fill ~105 ~1 ~-6 ~105 ~6 ~-6 leaves 0  
fill ~105 ~1 ~-5 ~108 ~1 ~-5 leaves 0  
fill ~105 ~1 ~84 ~106 ~1 ~84 quartz_block 0  
fill ~105 ~1 ~96 ~106 ~1 ~96 quartz_block 0  
fill ~105 ~1 ~97 ~106 ~1 ~97 quartz_block 0 
setblock ~106 ~1 ~-8 leaves 0  
fill ~106 ~1 ~-4 ~108 ~1 ~-4 leaves 0  
fill ~106 ~1 ~81 ~106 ~4 ~81 quartz_block 0  
fill ~106 ~1 ~82 ~106 ~5 ~82 quartz_block 0  
fill ~106 ~1 ~83 ~106 ~4 ~83 quartz_block 0  
fill ~106 ~1 ~90 ~107 ~1 ~90 quartz_block 0  
fill ~106 ~1 ~91 ~107 ~1 ~91 quartz_block 0  
fill ~106 ~1 ~92 ~107 ~1 ~92 quartz_block 0  
fill ~106 ~1 ~93 ~106 ~1 ~97 quartz_block 0 
setblock ~107 ~1 ~-8 log 4  
fill ~107 ~1 ~-6 ~107 ~6 ~-6 leaves 0  
fill ~107 ~1 ~88 ~108 ~1 ~88 quartz_block 0  
fill ~107 ~1 ~89 ~108 ~1 ~89 quartz_block 0  
fill ~107 ~1 ~94 ~107 ~10 ~94 quartz_block 0  
fill ~107 ~1 ~95 ~107 ~11 ~95 quartz_block 0 
setblock ~108 ~1 ~-9 log 4  
fill ~108 ~1 ~-8 ~112 ~1 ~-8 leaves 0  
fill ~109 ~1 ~-6 ~109 ~6 ~-6 leaves 0  
fill ~109 ~1 ~-5 ~109 ~1 ~-4 log 8  
fill ~109 ~1 ~-3 ~111 ~1 ~-3 leaves 0  
fill ~110 ~1 ~-5 ~113 ~1 ~-5 leaves 0  
fill ~110 ~1 ~-4 ~112 ~1 ~-4 leaves 0  
fill ~111 ~1 ~-6 ~111 ~4 ~-6 leaves 0  
fill ~113 ~1 ~-6 ~113 ~2 ~-6 leaves 0  
fill ~71 ~2 ~87 ~73 ~2 ~87 quartz_block 0  
fill ~71 ~2 ~90 ~72 ~2 ~90 quartz_block 0  
fill ~71 ~2 ~93 ~72 ~2 ~93 quartz_block 0  
fill ~71 ~2 ~94 ~73 ~2 ~94 quartz_block 0  
fill ~72 ~2 ~95 ~73 ~2 ~95 quartz_block 0  
fill ~73 ~2 ~80 ~74 ~2 ~80 quartz_block 0  
fill ~73 ~2 ~81 ~74 ~2 ~81 quartz_block 0  
fill ~73 ~2 ~83 ~74 ~2 ~83 quartz_block 0  
fill ~73 ~2 ~84 ~74 ~2 ~84 quartz_block 0  
fill ~73 ~2 ~85 ~74 ~2 ~85 quartz_block 0  
fill ~73 ~2 ~96 ~74 ~2 ~96 quartz_block 0  
fill ~73 ~2 ~97 ~74 ~2 ~97 quartz_block 0  
fill ~74 ~2 ~79 ~75 ~2 ~79 quartz_block 0  
fill ~74 ~2 ~98 ~75 ~2 ~98 quartz_block 0  
fill ~74 ~2 ~99 ~78 ~2 ~99 quartz_block 0  
fill ~76 ~2 ~78 ~77 ~2 ~78 quartz_block 0  
fill ~76 ~2 ~100 ~78 ~2 ~100 quartz_block 0  
fill ~77 ~2 ~77 ~84 ~2 ~77 quartz_block 0  
fill ~78 ~2 ~101 ~79 ~2 ~101 quartz_block 0  
fill ~78 ~2 ~102 ~82 ~2 ~102 quartz_block 0  
fill ~81 ~2 ~103 ~83 ~2 ~103 quartz_block 0  
fill ~82 ~2 ~76 ~86 ~2 ~76 quartz_block 0  
fill ~84 ~2 ~104 ~95 ~2 ~104 quartz_block 0  
fill ~85 ~2 ~75 ~94 ~2 ~75 quartz_block 0  
fill ~89 ~2 ~76 ~89 ~19 ~76 quartz_block 0  
fill ~89 ~2 ~105 ~90 ~2 ~105 quartz_block 0  
fill ~91 ~2 ~76 ~91 ~6 ~76 quartz_block 0  
fill ~93 ~2 ~76 ~97 ~2 ~76 quartz_block 0  
fill ~94 ~2 ~103 ~98 ~2 ~103 quartz_block 0  
fill ~95 ~2 ~77 ~102 ~2 ~77 quartz_block 0  
fill ~96 ~2 ~102 ~101 ~2 ~102 quartz_block 0  
fill ~100 ~2 ~101 ~101 ~2 ~101 quartz_block 0  
fill ~101 ~2 ~78 ~103 ~2 ~78 quartz_block 0  
fill ~102 ~2 ~79 ~104 ~2 ~79 quartz_block 0  
fill ~102 ~2 ~99 ~104 ~2 ~99 quartz_block 0  
fill ~103 ~2 ~100 ~103 ~29 ~100 quartz_block 0  
fill ~104 ~2 ~-10 ~108 ~2 ~-10 leaves 0  
fill ~104 ~2 ~80 ~105 ~2 ~80 quartz_block 0  
fill ~104 ~2 ~98 ~104 ~9 ~98 quartz_block 0  
fill ~105 ~2 ~-9 ~107 ~2 ~-9 leaves 0  
fill ~105 ~2 ~-8 ~105 ~5 ~-8 leaves 0  
fill ~105 ~2 ~-7 ~106 ~2 ~-7 leaves 0  
fill ~105 ~2 ~-5 ~112 ~2 ~-5 leaves 0  
fill ~105 ~2 ~81 ~105 ~15 ~81 quartz_block 0  
fill ~105 ~2 ~83 ~105 ~21 ~83 quartz_block 0  
fill ~105 ~2 ~84 ~106 ~2 ~84 quartz_block 0  
fill ~105 ~2 ~96 ~106 ~2 ~96 quartz_block 0  
fill ~105 ~2 ~97 ~106 ~2 ~97 quartz_block 0 
setblock ~106 ~2 ~-8 log 4  
fill ~106 ~2 ~-4 ~112 ~2 ~-4 leaves 0  
fill ~106 ~2 ~86 ~106 ~11 ~86 quartz_block 0  
fill ~106 ~2 ~94 ~106 ~2 ~97 quartz_block 0  
fill ~107 ~2 ~-8 ~107 ~7 ~-8 leaves 0 
setblock ~107 ~2 ~-7 log 4  
fill ~107 ~2 ~-3 ~111 ~2 ~-3 leaves 0  
fill ~107 ~2 ~88 ~108 ~2 ~88 quartz_block 0  
fill ~107 ~2 ~89 ~108 ~2 ~89 quartz_block 0  
fill ~107 ~2 ~90 ~107 ~18 ~90 quartz_block 0  
fill ~107 ~2 ~91 ~107 ~12 ~91 quartz_block 0  
fill ~107 ~2 ~92 ~107 ~6 ~92 quartz_block 0 
setblock ~108 ~2 ~-8 log 4  
fill ~108 ~2 ~-7 ~113 ~2 ~-7 leaves 0  
fill ~108 ~2 ~-2 ~110 ~2 ~-2 leaves 0  
fill ~109 ~2 ~-8 ~112 ~2 ~-8 leaves 0  
fill ~110 ~2 ~-9 ~111 ~2 ~-9 log 4  
fill ~111 ~2 ~-10 ~111 ~6 ~-10 leaves 0  
fill ~112 ~2 ~-9 ~112 ~6 ~-9 leaves 0  
fill ~71 ~3 ~90 ~72 ~3 ~90 quartz_block 0  
fill ~71 ~3 ~94 ~73 ~3 ~94 quartz_block 0  
fill ~72 ~3 ~87 ~72 ~12 ~87 quartz_block 0 
setblock ~72 ~3 ~89 quartz_block 0  
fill ~72 ~3 ~93 ~72 ~12 ~93 quartz_block 0  
fill ~72 ~3 ~95 ~73 ~3 ~95 quartz_block 0  
fill ~73 ~3 ~80 ~73 ~4 ~80 quartz_block 0  
fill ~73 ~3 ~81 ~74 ~3 ~81 quartz_block 0  
fill ~73 ~3 ~83 ~74 ~3 ~83 quartz_block 0  
fill ~73 ~3 ~84 ~74 ~3 ~84 quartz_block 0  
fill ~73 ~3 ~85 ~74 ~3 ~85 quartz_block 0 
setblock ~73 ~3 ~92 quartz_block 0  
fill ~73 ~3 ~96 ~74 ~3 ~96 quartz_block 0  
fill ~73 ~3 ~97 ~74 ~3 ~97 quartz_block 0  
fill ~74 ~3 ~79 ~75 ~3 ~79 quartz_block 0  
fill ~74 ~3 ~98 ~75 ~3 ~98 quartz_block 0  
fill ~74 ~3 ~99 ~77 ~3 ~99 quartz_block 0  
fill ~76 ~3 ~78 ~76 ~7 ~78 quartz_block 0  
fill ~76 ~3 ~100 ~78 ~3 ~100 quartz_block 0  
fill ~77 ~3 ~77 ~84 ~3 ~77 quartz_block 0  
fill ~78 ~3 ~101 ~79 ~3 ~101 quartz_block 0  
fill ~78 ~3 ~102 ~82 ~3 ~102 quartz_block 0 
setblock ~80 ~3 ~78 quartz_block 0  
fill ~81 ~3 ~103 ~83 ~3 ~103 quartz_block 0  
fill ~83 ~3 ~76 ~84 ~3 ~76 quartz_block 0  
fill ~84 ~3 ~104 ~95 ~3 ~104 quartz_block 0  
fill ~85 ~3 ~75 ~94 ~3 ~75 quartz_block 0  
fill ~89 ~3 ~105 ~90 ~3 ~105 quartz_block 0  
fill ~93 ~3 ~76 ~96 ~3 ~76 quartz_block 0  
fill ~94 ~3 ~103 ~98 ~3 ~103 quartz_block 0  
fill ~95 ~3 ~77 ~101 ~3 ~77 quartz_block 0  
fill ~97 ~3 ~102 ~101 ~3 ~102 quartz_block 0  
fill ~99 ~3 ~78 ~103 ~3 ~78 quartz_block 0  
fill ~100 ~3 ~101 ~101 ~3 ~101 quartz_block 0  
fill ~102 ~3 ~79 ~104 ~3 ~79 quartz_block 0  
fill ~102 ~3 ~99 ~105 ~3 ~99 quartz_block 0  
fill ~103 ~3 ~80 ~105 ~3 ~80 quartz_block 0  
fill ~104 ~3 ~-9 ~108 ~3 ~-9 leaves 0  
fill ~104 ~3 ~-8 ~104 ~4 ~-8 leaves 0  
fill ~104 ~3 ~-7 ~112 ~3 ~-7 leaves 0  
fill ~105 ~3 ~-10 ~107 ~3 ~-10 leaves 0  
fill ~105 ~3 ~-5 ~111 ~3 ~-5 leaves 0  
fill ~105 ~3 ~82 ~105 ~22 ~82 quartz_block 0  
fill ~105 ~3 ~84 ~106 ~3 ~84 quartz_block 0  
fill ~105 ~3 ~97 ~106 ~3 ~97 quartz_block 0  
fill ~106 ~3 ~-8 ~106 ~6 ~-8 leaves 0 
setblock ~106 ~3 ~-6 log 4  
fill ~106 ~3 ~-4 ~111 ~3 ~-4 leaves 0  
fill ~106 ~3 ~87 ~106 ~18 ~87 quartz_block 0  
fill ~106 ~3 ~92 ~106 ~27 ~92 quartz_block 0  
fill ~106 ~3 ~96 ~106 ~28 ~96 quartz_block 0  
fill ~107 ~3 ~-3 ~110 ~3 ~-3 leaves 0  
fill ~107 ~3 ~88 ~108 ~3 ~88 quartz_block 0  
fill ~107 ~3 ~89 ~108 ~3 ~89 quartz_block 0 
setblock ~108 ~3 ~-10 log 4  
fill ~108 ~3 ~-8 ~113 ~3 ~-8 leaves 0  
fill ~109 ~3 ~-10 ~113 ~3 ~-10 leaves 0 
setblock ~109 ~3 ~-2 leaves 0  
fill ~110 ~3 ~-9 ~110 ~2 ~-9 log 4  
fill ~111 ~3 ~-9 ~111 ~7 ~-9 leaves 0  
fill ~113 ~3 ~-9 ~113 ~5 ~-9 leaves 0  
fill ~71 ~4 ~90 ~72 ~4 ~90 quartz_block 0  
fill ~72 ~4 ~88 ~72 ~20 ~88 quartz_block 0  
fill ~72 ~4 ~94 ~72 ~14 ~94 quartz_block 0  
fill ~72 ~4 ~95 ~73 ~4 ~95 quartz_block 0  
fill ~73 ~4 ~81 ~74 ~4 ~81 quartz_block 0  
fill ~73 ~4 ~83 ~74 ~4 ~83 quartz_block 0  
fill ~73 ~4 ~84 ~74 ~4 ~84 quartz_block 0  
fill ~73 ~4 ~85 ~74 ~4 ~85 quartz_block 0  
fill ~73 ~4 ~87 ~73 ~24 ~87 quartz_block 0  
fill ~73 ~4 ~93 ~73 ~25 ~93 quartz_block 0  
fill ~73 ~4 ~96 ~74 ~4 ~96 quartz_block 0  
fill ~73 ~4 ~97 ~74 ~4 ~97 quartz_block 0  
fill ~74 ~4 ~80 ~75 ~4 ~80 quartz_block 0  
fill ~74 ~4 ~98 ~75 ~4 ~98 quartz_block 0  
fill ~74 ~4 ~99 ~77 ~4 ~99 quartz_block 0  
fill ~75 ~4 ~79 ~76 ~4 ~79 quartz_block 0  
fill ~76 ~4 ~100 ~78 ~4 ~100 quartz_block 0  
fill ~77 ~4 ~77 ~84 ~4 ~77 quartz_block 0  
fill ~77 ~4 ~78 ~77 ~13 ~78 quartz_block 0  
fill ~78 ~4 ~101 ~79 ~4 ~101 quartz_block 0  
fill ~78 ~4 ~102 ~80 ~4 ~102 quartz_block 0  
fill ~80 ~4 ~103 ~83 ~4 ~103 quartz_block 0  
fill ~81 ~4 ~78 ~81 ~6 ~78 quartz_block 0  
fill ~83 ~4 ~76 ~86 ~4 ~76 quartz_block 0  
fill ~83 ~4 ~104 ~95 ~4 ~104 quartz_block 0  
fill ~85 ~4 ~75 ~93 ~4 ~75 quartz_block 0  
fill ~88 ~4 ~76 ~88 ~19 ~76 quartz_block 0  
fill ~88 ~4 ~105 ~91 ~4 ~105 quartz_block 0  
fill ~92 ~4 ~76 ~95 ~4 ~76 quartz_block 0  
fill ~94 ~4 ~77 ~101 ~4 ~77 quartz_block 0  
fill ~95 ~4 ~103 ~98 ~4 ~103 quartz_block 0  
fill ~97 ~4 ~78 ~103 ~4 ~78 quartz_block 0  
fill ~98 ~4 ~102 ~100 ~4 ~102 quartz_block 0  
fill ~100 ~4 ~101 ~101 ~4 ~101 quartz_block 0  
fill ~103 ~4 ~79 ~104 ~4 ~79 quartz_block 0  
fill ~103 ~4 ~99 ~105 ~4 ~99 quartz_block 0  
fill ~104 ~4 ~-7 ~111 ~4 ~-7 leaves 0  
fill ~104 ~4 ~-6 ~104 ~5 ~-6 leaves 0  
fill ~104 ~4 ~-5 ~110 ~4 ~-5 leaves 0  
fill ~105 ~4 ~-10 ~112 ~4 ~-10 leaves 0  
fill ~105 ~4 ~-9 ~108 ~4 ~-9 leaves 0  
fill ~105 ~4 ~-4 ~110 ~4 ~-4 leaves 0  
fill ~105 ~4 ~80 ~105 ~7 ~80 quartz_block 0  
fill ~105 ~4 ~84 ~105 ~17 ~84 quartz_block 0  
fill ~105 ~4 ~85 ~105 ~16 ~85 quartz_block 0  
fill ~105 ~4 ~97 ~106 ~4 ~97 quartz_block 0  
fill ~106 ~4 ~-6 ~106 ~7 ~-6 leaves 0  
fill ~106 ~4 ~88 ~108 ~4 ~88 quartz_block 0  
fill ~106 ~4 ~91 ~106 ~84 ~91 quartz_block 0  
fill ~106 ~4 ~93 ~106 ~20 ~93 quartz_block 0  
fill ~106 ~4 ~94 ~106 ~21 ~94 quartz_block 0  
fill ~106 ~4 ~95 ~106 ~25 ~95 quartz_block 0  
fill ~107 ~4 ~89 ~108 ~4 ~89 quartz_block 0 
setblock ~108 ~4 ~-8 log 4  
fill ~109 ~4 ~-8 ~112 ~4 ~-8 leaves 0 
setblock ~109 ~4 ~-3 leaves 0  
fill ~110 ~4 ~-9 ~110 ~8 ~-9 leaves 0  
fill ~71 ~5 ~90 ~72 ~5 ~90 quartz_block 0  
fill ~72 ~5 ~89 ~72 ~12 ~89 quartz_block 0  
fill ~72 ~5 ~95 ~73 ~5 ~95 quartz_block 0  
fill ~73 ~5 ~81 ~73 ~11 ~81 quartz_block 0  
fill ~73 ~5 ~83 ~73 ~10 ~83 quartz_block 0  
fill ~73 ~5 ~84 ~73 ~9 ~84 quartz_block 0  
fill ~73 ~5 ~85 ~74 ~5 ~85 quartz_block 0  
fill ~73 ~5 ~92 ~73 ~25 ~92 quartz_block 0  
fill ~73 ~5 ~94 ~73 ~25 ~94 quartz_block 0  
fill ~73 ~5 ~96 ~74 ~5 ~96 quartz_block 0  
fill ~73 ~5 ~97 ~74 ~5 ~97 quartz_block 0  
fill ~74 ~5 ~80 ~75 ~5 ~80 quartz_block 0  
fill ~74 ~5 ~82 ~74 ~24 ~82 quartz_block 0  
fill ~74 ~5 ~98 ~75 ~5 ~98 quartz_block 0  
fill ~74 ~5 ~99 ~77 ~5 ~99 quartz_block 0  
fill ~75 ~5 ~79 ~76 ~5 ~79 quartz_block 0  
fill ~76 ~5 ~100 ~78 ~5 ~100 quartz_block 0  
fill ~77 ~5 ~77 ~84 ~5 ~77 quartz_block 0  
fill ~78 ~5 ~78 ~78 ~6 ~78 quartz_block 0  
fill ~78 ~5 ~101 ~79 ~5 ~101 quartz_block 0  
fill ~78 ~5 ~102 ~80 ~5 ~102 quartz_block 0  
fill ~80 ~5 ~78 ~80 ~8 ~78 quartz_block 0  
fill ~80 ~5 ~103 ~83 ~5 ~103 quartz_block 0  
fill ~82 ~5 ~78 ~82 ~6 ~78 quartz_block 0  
fill ~83 ~5 ~76 ~95 ~5 ~76 quartz_block 0  
fill ~83 ~5 ~104 ~88 ~5 ~104 quartz_block 0  
fill ~85 ~5 ~75 ~93 ~5 ~75 quartz_block 0  
fill ~85 ~5 ~105 ~94 ~5 ~105 quartz_block 0  
fill ~90 ~5 ~104 ~96 ~5 ~104 quartz_block 0  
fill ~94 ~5 ~77 ~101 ~5 ~77 quartz_block 0  
fill ~95 ~5 ~103 ~99 ~5 ~103 quartz_block 0  
fill ~96 ~5 ~78 ~97 ~5 ~78 quartz_block 0  
fill ~98 ~5 ~102 ~100 ~5 ~102 quartz_block 0  
fill ~99 ~5 ~78 ~102 ~5 ~78 quartz_block 0  
fill ~100 ~5 ~100 ~103 ~5 ~100 quartz_block 0  
fill ~100 ~5 ~101 ~101 ~5 ~101 quartz_block 0  
fill ~102 ~5 ~79 ~104 ~5 ~79 quartz_block 0  
fill ~103 ~5 ~99 ~105 ~5 ~99 quartz_block 0  
fill ~105 ~5 ~-9 ~108 ~5 ~-9 leaves 0  
fill ~105 ~5 ~-7 ~111 ~5 ~-7 leaves 0  
fill ~105 ~5 ~-5 ~109 ~5 ~-5 leaves 0  
fill ~105 ~5 ~86 ~105 ~21 ~86 quartz_block 0  
fill ~105 ~5 ~96 ~105 ~8 ~96 quartz_block 0  
fill ~105 ~5 ~97 ~106 ~5 ~97 quartz_block 0  
fill ~106 ~5 ~-10 ~112 ~5 ~-10 leaves 0 
setblock ~106 ~5 ~-4 leaves 0  
fill ~106 ~5 ~88 ~108 ~5 ~88 quartz_block 0  
fill ~106 ~5 ~90 ~106 ~8 ~90 quartz_block 0  
fill ~108 ~5 ~-8 ~112 ~5 ~-8 leaves 0  
fill ~108 ~5 ~89 ~108 ~7 ~89 quartz_block 0 
setblock ~109 ~5 ~-4 leaves 0  
fill ~72 ~6 ~90 ~72 ~24 ~90 quartz_block 0  
fill ~72 ~6 ~95 ~73 ~6 ~95 quartz_block 0  
fill ~73 ~6 ~85 ~74 ~6 ~85 quartz_block 0  
fill ~73 ~6 ~91 ~73 ~24 ~91 quartz_block 0  
fill ~73 ~6 ~96 ~74 ~6 ~96 quartz_block 0  
fill ~73 ~6 ~97 ~74 ~6 ~97 quartz_block 0  
fill ~74 ~6 ~80 ~75 ~6 ~80 quartz_block 0  
fill ~74 ~6 ~81 ~74 ~19 ~81 quartz_block 0  
fill ~74 ~6 ~83 ~74 ~23 ~83 quartz_block 0  
fill ~74 ~6 ~84 ~74 ~23 ~84 quartz_block 0  
fill ~74 ~6 ~86 ~74 ~23 ~86 quartz_block 0  
fill ~74 ~6 ~98 ~75 ~6 ~98 quartz_block 0  
fill ~74 ~6 ~99 ~77 ~6 ~99 quartz_block 0  
fill ~75 ~6 ~79 ~76 ~6 ~79 quartz_block 0  
fill ~76 ~6 ~100 ~78 ~6 ~100 quartz_block 0  
fill ~78 ~6 ~77 ~85 ~6 ~77 quartz_block 0  
fill ~78 ~6 ~101 ~78 ~27 ~101 quartz_block 0  
fill ~78 ~6 ~102 ~80 ~6 ~102 quartz_block 0  
fill ~80 ~6 ~103 ~82 ~6 ~103 quartz_block 0 
setblock ~83 ~6 ~78 quartz_block 0  
fill ~83 ~6 ~104 ~88 ~6 ~104 quartz_block 0  
fill ~84 ~6 ~76 ~85 ~6 ~76 quartz_block 0  
fill ~85 ~6 ~105 ~94 ~6 ~105 quartz_block 0  
fill ~86 ~6 ~75 ~93 ~6 ~75 quartz_block 0  
fill ~90 ~6 ~76 ~90 ~19 ~76 quartz_block 0  
fill ~90 ~6 ~104 ~96 ~6 ~104 quartz_block 0  
fill ~92 ~6 ~76 ~95 ~6 ~76 quartz_block 0  
fill ~94 ~6 ~77 ~101 ~6 ~77 quartz_block 0  
fill ~96 ~6 ~78 ~102 ~6 ~78 quartz_block 0  
fill ~96 ~6 ~103 ~99 ~6 ~103 quartz_block 0  
fill ~97 ~6 ~102 ~100 ~6 ~102 quartz_block 0  
fill ~100 ~6 ~100 ~100 ~5 ~100 quartz_block 0  
fill ~100 ~6 ~101 ~101 ~6 ~101 quartz_block 0  
fill ~102 ~6 ~79 ~103 ~6 ~79 quartz_block 0  
fill ~103 ~6 ~80 ~105 ~6 ~80 quartz_block 0  
fill ~104 ~6 ~84 ~104 ~62 ~84 quartz_block 0  
fill ~104 ~6 ~85 ~104 ~49 ~85 quartz_block 0  
fill ~104 ~6 ~99 ~105 ~6 ~99 quartz_block 0  
fill ~105 ~6 ~97 ~106 ~6 ~97 quartz_block 0  
fill ~106 ~6 ~-9 ~112 ~6 ~-9 leaves 0  
fill ~106 ~6 ~-7 ~110 ~6 ~-7 leaves 0 
setblock ~106 ~6 ~-5 leaves 0  
fill ~107 ~6 ~-10 ~111 ~6 ~-10 leaves 0  
fill ~107 ~6 ~88 ~107 ~14 ~88 quartz_block 0  
fill ~107 ~6 ~89 ~107 ~21 ~89 quartz_block 0  
fill ~108 ~6 ~-8 ~111 ~6 ~-8 leaves 0  
fill ~72 ~7 ~95 ~73 ~7 ~95 quartz_block 0  
fill ~73 ~7 ~85 ~74 ~7 ~85 quartz_block 0  
fill ~73 ~7 ~96 ~74 ~7 ~96 quartz_block 0  
fill ~73 ~7 ~97 ~74 ~7 ~97 quartz_block 0  
fill ~74 ~7 ~80 ~75 ~7 ~80 quartz_block 0  
fill ~74 ~7 ~98 ~75 ~7 ~98 quartz_block 0  
fill ~74 ~7 ~99 ~77 ~7 ~99 quartz_block 0  
fill ~75 ~7 ~79 ~76 ~7 ~79 quartz_block 0  
fill ~76 ~7 ~100 ~78 ~7 ~100 quartz_block 0  
fill ~78 ~7 ~77 ~83 ~7 ~77 quartz_block 0  
fill ~78 ~7 ~102 ~80 ~7 ~102 quartz_block 0  
fill ~79 ~7 ~101 ~79 ~17 ~101 quartz_block 0  
fill ~80 ~7 ~103 ~83 ~7 ~103 quartz_block 0  
fill ~83 ~7 ~104 ~87 ~7 ~104 quartz_block 0  
fill ~84 ~7 ~76 ~90 ~7 ~76 quartz_block 0  
fill ~85 ~7 ~105 ~94 ~7 ~105 quartz_block 0  
fill ~86 ~7 ~75 ~93 ~7 ~75 quartz_block 0  
fill ~91 ~7 ~104 ~92 ~7 ~104 quartz_block 0  
fill ~92 ~7 ~76 ~95 ~7 ~76 quartz_block 0  
fill ~94 ~7 ~77 ~101 ~7 ~77 quartz_block 0  
fill ~94 ~7 ~104 ~96 ~7 ~104 quartz_block 0  
fill ~96 ~7 ~78 ~102 ~7 ~78 quartz_block 0  
fill ~96 ~7 ~103 ~99 ~7 ~103 quartz_block 0  
fill ~98 ~7 ~102 ~100 ~7 ~102 quartz_block 0  
fill ~100 ~7 ~101 ~101 ~7 ~101 quartz_block 0  
fill ~101 ~7 ~79 ~103 ~7 ~79 quartz_block 0  
fill ~103 ~7 ~80 ~105 ~7 ~80 quartz_block 0  
fill ~103 ~7 ~99 ~105 ~7 ~99 quartz_block 0  
fill ~104 ~7 ~83 ~104 ~77 ~83 quartz_block 0  
fill ~105 ~7 ~97 ~106 ~7 ~97 quartz_block 0  
fill ~107 ~7 ~-9 ~111 ~7 ~-9 leaves 0  
fill ~108 ~7 ~-10 ~110 ~7 ~-10 leaves 0  
fill ~108 ~7 ~-8 ~110 ~7 ~-8 leaves 0  
fill ~108 ~7 ~-7 ~109 ~7 ~-7 leaves 0  
fill ~72 ~8 ~95 ~73 ~8 ~95 quartz_block 0  
fill ~73 ~8 ~85 ~74 ~8 ~85 quartz_block 0  
fill ~73 ~8 ~90 ~73 ~17 ~90 quartz_block 0  
fill ~73 ~8 ~96 ~74 ~8 ~96 quartz_block 0  
fill ~73 ~8 ~97 ~74 ~8 ~97 quartz_block 0  
fill ~74 ~8 ~80 ~76 ~8 ~80 quartz_block 0  
fill ~74 ~8 ~98 ~75 ~8 ~98 quartz_block 0  
fill ~74 ~8 ~99 ~77 ~8 ~99 quartz_block 0  
fill ~75 ~8 ~79 ~77 ~8 ~79 quartz_block 0  
fill ~76 ~8 ~100 ~78 ~8 ~100 quartz_block 0  
fill ~78 ~8 ~77 ~84 ~8 ~77 quartz_block 0  
fill ~78 ~8 ~78 ~82 ~8 ~78 quartz_block 0  
fill ~78 ~8 ~102 ~80 ~8 ~102 quartz_block 0  
fill ~80 ~8 ~103 ~82 ~8 ~103 quartz_block 0  
fill ~83 ~8 ~104 ~89 ~8 ~104 quartz_block 0  
fill ~84 ~8 ~76 ~94 ~8 ~76 quartz_block 0  
fill ~85 ~8 ~105 ~94 ~8 ~105 quartz_block 0  
fill ~86 ~8 ~75 ~92 ~8 ~75 quartz_block 0  
fill ~91 ~8 ~104 ~92 ~8 ~104 quartz_block 0  
fill ~94 ~8 ~77 ~101 ~8 ~77 quartz_block 0  
fill ~95 ~8 ~103 ~99 ~8 ~103 quartz_block 0  
fill ~95 ~8 ~104 ~96 ~8 ~104 quartz_block 0  
fill ~96 ~8 ~78 ~102 ~8 ~78 quartz_block 0  
fill ~98 ~8 ~102 ~100 ~8 ~102 quartz_block 0  
fill ~100 ~8 ~101 ~101 ~8 ~101 quartz_block 0  
fill ~101 ~8 ~79 ~103 ~8 ~79 quartz_block 0  
fill ~101 ~8 ~100 ~101 ~11 ~100 quartz_block 0  
fill ~102 ~8 ~80 ~104 ~8 ~80 quartz_block 0 
setblock ~102 ~8 ~99 quartz_block 0  
fill ~104 ~8 ~81 ~104 ~21 ~81 quartz_block 0  
fill ~104 ~8 ~82 ~104 ~9 ~82 quartz_block 0  
fill ~104 ~8 ~99 ~105 ~8 ~99 quartz_block 0  
fill ~105 ~8 ~87 ~105 ~9 ~87 quartz_block 0  
fill ~105 ~8 ~97 ~106 ~8 ~97 quartz_block 0  
fill ~106 ~8 ~88 ~106 ~8 ~97 quartz_block 0  
fill ~108 ~8 ~-9 ~110 ~8 ~-9 leaves 0  
fill ~108 ~8 ~-8 ~109 ~8 ~-8 leaves 0 
setblock ~109 ~8 ~-10 leaves 0  
fill ~72 ~9 ~95 ~73 ~9 ~95 quartz_block 0  
fill ~73 ~9 ~85 ~74 ~9 ~85 quartz_block 0  
fill ~73 ~9 ~96 ~74 ~9 ~96 quartz_block 0  
fill ~73 ~9 ~97 ~74 ~9 ~97 quartz_block 0  
fill ~74 ~9 ~80 ~76 ~9 ~80 quartz_block 0  
fill ~74 ~9 ~98 ~75 ~9 ~98 quartz_block 0  
fill ~74 ~9 ~99 ~77 ~9 ~99 quartz_block 0 
setblock ~75 ~9 ~81 quartz_block 0  
fill ~76 ~9 ~79 ~77 ~9 ~79 quartz_block 0  
fill ~76 ~9 ~100 ~78 ~9 ~100 quartz_block 0  
fill ~78 ~9 ~77 ~85 ~9 ~77 quartz_block 0  
fill ~78 ~9 ~78 ~79 ~9 ~78 quartz_block 0  
fill ~78 ~9 ~102 ~80 ~9 ~102 quartz_block 0  
fill ~80 ~9 ~103 ~82 ~9 ~103 quartz_block 0  
fill ~81 ~9 ~78 ~82 ~9 ~78 quartz_block 0  
fill ~83 ~9 ~104 ~85 ~9 ~104 quartz_block 0  
fill ~84 ~9 ~76 ~94 ~9 ~76 quartz_block 0  
fill ~85 ~9 ~105 ~94 ~9 ~105 quartz_block 0  
fill ~87 ~9 ~104 ~90 ~9 ~104 quartz_block 0 
setblock ~93 ~9 ~104 quartz_block 0  
fill ~94 ~9 ~77 ~100 ~9 ~77 quartz_block 0  
fill ~95 ~9 ~103 ~99 ~9 ~103 quartz_block 0  
fill ~95 ~9 ~104 ~96 ~9 ~104 quartz_block 0  
fill ~96 ~9 ~78 ~97 ~9 ~78 quartz_block 0  
fill ~98 ~9 ~102 ~100 ~9 ~102 quartz_block 0  
fill ~99 ~9 ~78 ~102 ~9 ~78 quartz_block 0  
fill ~100 ~9 ~100 ~100 ~10 ~100 quartz_block 0  
fill ~100 ~9 ~101 ~101 ~9 ~101 quartz_block 0  
fill ~101 ~9 ~79 ~103 ~9 ~79 quartz_block 0  
fill ~102 ~9 ~80 ~104 ~9 ~80 quartz_block 0  
fill ~103 ~9 ~99 ~105 ~9 ~99 quartz_block 0  
fill ~105 ~9 ~92 ~105 ~75 ~92 quartz_block 0  
fill ~105 ~9 ~97 ~106 ~9 ~97 quartz_block 0  
fill ~106 ~9 ~89 ~106 ~35 ~89 quartz_block 0 
setblock ~109 ~9 ~-9 leaves 0  
fill ~72 ~10 ~95 ~73 ~10 ~95 quartz_block 0 
setblock ~73 ~10 ~88 quartz_block 0  
fill ~73 ~10 ~96 ~74 ~10 ~96 quartz_block 0  
fill ~73 ~10 ~97 ~74 ~10 ~97 quartz_block 0  
fill ~74 ~10 ~80 ~76 ~10 ~80 quartz_block 0  
fill ~74 ~10 ~85 ~74 ~23 ~85 quartz_block 0  
fill ~74 ~10 ~98 ~75 ~10 ~98 quartz_block 0  
fill ~74 ~10 ~99 ~77 ~10 ~99 quartz_block 0  
fill ~75 ~10 ~100 ~78 ~10 ~100 quartz_block 0  
fill ~76 ~10 ~79 ~77 ~10 ~79 quartz_block 0  
fill ~78 ~10 ~77 ~84 ~10 ~77 quartz_block 0  
fill ~78 ~10 ~78 ~83 ~10 ~78 quartz_block 0  
fill ~79 ~10 ~102 ~80 ~10 ~102 quartz_block 0  
fill ~80 ~10 ~103 ~83 ~10 ~103 quartz_block 0  
fill ~82 ~10 ~104 ~90 ~10 ~104 quartz_block 0  
fill ~84 ~10 ~76 ~94 ~10 ~76 quartz_block 0  
fill ~85 ~10 ~105 ~94 ~10 ~105 quartz_block 0  
fill ~93 ~10 ~77 ~100 ~10 ~77 quartz_block 0  
fill ~94 ~10 ~104 ~96 ~10 ~104 quartz_block 0  
fill ~96 ~10 ~103 ~99 ~10 ~103 quartz_block 0  
fill ~99 ~10 ~78 ~101 ~10 ~78 quartz_block 0  
fill ~99 ~10 ~102 ~100 ~10 ~102 quartz_block 0  
fill ~100 ~10 ~101 ~101 ~10 ~101 quartz_block 0  
fill ~101 ~10 ~79 ~103 ~10 ~79 quartz_block 0  
fill ~102 ~10 ~80 ~104 ~10 ~80 quartz_block 0  
fill ~102 ~10 ~99 ~104 ~10 ~99 quartz_block 0  
fill ~103 ~10 ~81 ~103 ~15 ~81 quartz_block 0  
fill ~104 ~10 ~97 ~106 ~10 ~97 quartz_block 0 
setblock ~105 ~10 ~96 quartz_block 0  
fill ~106 ~10 ~88 ~106 ~26 ~88 quartz_block 0  
fill ~106 ~10 ~90 ~106 ~33 ~90 quartz_block 0  
fill ~72 ~11 ~95 ~73 ~11 ~95 quartz_block 0  
fill ~73 ~11 ~96 ~74 ~11 ~96 quartz_block 0  
fill ~73 ~11 ~97 ~74 ~11 ~97 quartz_block 0  
fill ~74 ~11 ~98 ~75 ~11 ~98 quartz_block 0  
fill ~74 ~11 ~99 ~77 ~11 ~99 quartz_block 0  
fill ~75 ~11 ~80 ~76 ~11 ~80 quartz_block 0  
fill ~75 ~11 ~81 ~75 ~23 ~81 quartz_block 0  
fill ~75 ~11 ~100 ~78 ~11 ~100 quartz_block 0  
fill ~76 ~11 ~79 ~77 ~11 ~79 quartz_block 0  
fill ~78 ~11 ~78 ~83 ~11 ~78 quartz_block 0  
fill ~79 ~11 ~77 ~89 ~11 ~77 quartz_block 0  
fill ~79 ~11 ~102 ~81 ~11 ~102 quartz_block 0  
fill ~79 ~11 ~103 ~83 ~11 ~103 quartz_block 0  
fill ~82 ~11 ~104 ~90 ~11 ~104 quartz_block 0  
fill ~84 ~11 ~105 ~94 ~11 ~105 quartz_block 0  
fill ~85 ~11 ~76 ~94 ~11 ~76 quartz_block 0  
fill ~92 ~11 ~77 ~99 ~11 ~77 quartz_block 0  
fill ~92 ~11 ~104 ~96 ~11 ~104 quartz_block 0  
fill ~96 ~11 ~103 ~99 ~11 ~103 quartz_block 0  
fill ~98 ~11 ~78 ~101 ~11 ~78 quartz_block 0  
fill ~99 ~11 ~102 ~100 ~11 ~102 quartz_block 0  
fill ~100 ~11 ~101 ~101 ~11 ~101 quartz_block 0  
fill ~101 ~11 ~79 ~103 ~11 ~79 quartz_block 0  
fill ~102 ~11 ~80 ~104 ~11 ~80 quartz_block 0  
fill ~102 ~11 ~99 ~104 ~11 ~99 quartz_block 0  
fill ~104 ~11 ~82 ~104 ~15 ~82 quartz_block 0  
fill ~104 ~11 ~86 ~104 ~33 ~86 quartz_block 0  
fill ~104 ~11 ~97 ~106 ~11 ~97 quartz_block 0  
fill ~105 ~11 ~87 ~105 ~32 ~87 quartz_block 0  
fill ~105 ~11 ~93 ~105 ~62 ~93 quartz_block 0  
fill ~72 ~12 ~95 ~73 ~12 ~95 quartz_block 0  
fill ~73 ~12 ~88 ~73 ~23 ~88 quartz_block 0  
fill ~73 ~12 ~96 ~74 ~12 ~96 quartz_block 0  
fill ~73 ~12 ~97 ~74 ~12 ~97 quartz_block 0  
fill ~74 ~12 ~98 ~75 ~12 ~98 quartz_block 0  
fill ~74 ~12 ~99 ~76 ~12 ~99 quartz_block 0  
fill ~75 ~12 ~80 ~76 ~12 ~80 quartz_block 0  
fill ~75 ~12 ~100 ~78 ~12 ~100 quartz_block 0  
fill ~76 ~12 ~79 ~78 ~12 ~79 quartz_block 0  
fill ~78 ~12 ~78 ~83 ~12 ~78 quartz_block 0  
fill ~79 ~12 ~102 ~81 ~12 ~102 quartz_block 0  
fill ~79 ~12 ~103 ~83 ~12 ~103 quartz_block 0  
fill ~82 ~12 ~77 ~89 ~12 ~77 quartz_block 0  
fill ~82 ~12 ~104 ~84 ~12 ~104 quartz_block 0  
fill ~84 ~12 ~105 ~94 ~12 ~105 quartz_block 0  
fill ~85 ~12 ~76 ~94 ~12 ~76 quartz_block 0  
fill ~86 ~12 ~104 ~89 ~12 ~104 quartz_block 0  
fill ~91 ~12 ~104 ~97 ~12 ~104 quartz_block 0  
fill ~92 ~12 ~77 ~97 ~12 ~77 quartz_block 0  
fill ~95 ~12 ~103 ~100 ~12 ~103 quartz_block 0  
fill ~98 ~12 ~78 ~101 ~12 ~78 quartz_block 0  
fill ~99 ~12 ~102 ~100 ~12 ~102 quartz_block 0  
fill ~100 ~12 ~79 ~102 ~12 ~79 quartz_block 0  
fill ~100 ~12 ~101 ~101 ~12 ~101 quartz_block 0  
fill ~102 ~12 ~80 ~104 ~12 ~80 quartz_block 0  
fill ~102 ~12 ~99 ~104 ~12 ~99 quartz_block 0  
fill ~104 ~12 ~97 ~105 ~12 ~97 quartz_block 0  
fill ~104 ~12 ~98 ~104 ~17 ~98 quartz_block 0  
fill ~104 ~12 ~100 ~104 ~75 ~100 quartz_block 0  
fill ~105 ~12 ~95 ~105 ~17 ~95 quartz_block 0  
fill ~105 ~12 ~96 ~105 ~16 ~96 quartz_block 0  
fill ~72 ~13 ~95 ~73 ~13 ~95 quartz_block 0  
fill ~73 ~13 ~96 ~74 ~13 ~96 quartz_block 0  
fill ~73 ~13 ~97 ~74 ~13 ~97 quartz_block 0  
fill ~74 ~13 ~87 ~74 ~23 ~87 quartz_block 0  
fill ~74 ~13 ~98 ~75 ~13 ~98 quartz_block 0  
fill ~74 ~13 ~99 ~75 ~13 ~99 quartz_block 0  
fill ~75 ~13 ~80 ~76 ~13 ~80 quartz_block 0  
fill ~75 ~13 ~85 ~75 ~15 ~85 quartz_block 0  
fill ~75 ~13 ~100 ~78 ~13 ~100 quartz_block 0  
fill ~76 ~13 ~79 ~76 ~14 ~79 quartz_block 0  
fill ~76 ~13 ~81 ~76 ~15 ~81 quartz_block 0  
fill ~77 ~13 ~101 ~77 ~28 ~101 quartz_block 0  
fill ~78 ~13 ~78 ~84 ~13 ~78 quartz_block 0  
fill ~79 ~13 ~102 ~81 ~13 ~102 quartz_block 0  
fill ~79 ~13 ~103 ~84 ~13 ~103 quartz_block 0  
fill ~82 ~13 ~104 ~84 ~13 ~104 quartz_block 0  
fill ~83 ~13 ~77 ~86 ~13 ~77 quartz_block 0  
fill ~84 ~13 ~105 ~94 ~13 ~105 quartz_block 0  
fill ~85 ~13 ~76 ~94 ~13 ~76 quartz_block 0  
fill ~86 ~13 ~104 ~97 ~13 ~104 quartz_block 0  
fill ~92 ~13 ~77 ~96 ~13 ~77 quartz_block 0  
fill ~95 ~13 ~103 ~96 ~13 ~103 quartz_block 0  
fill ~96 ~13 ~78 ~101 ~13 ~78 quartz_block 0  
fill ~98 ~13 ~103 ~100 ~13 ~103 quartz_block 0  
fill ~100 ~13 ~79 ~102 ~13 ~79 quartz_block 0  
fill ~100 ~13 ~101 ~101 ~13 ~101 quartz_block 0  
fill ~100 ~13 ~102 ~100 ~29 ~102 quartz_block 0  
fill ~101 ~13 ~100 ~101 ~19 ~100 quartz_block 0  
fill ~102 ~13 ~80 ~104 ~13 ~80 quartz_block 0  
fill ~102 ~13 ~99 ~104 ~13 ~99 quartz_block 0  
fill ~104 ~13 ~97 ~105 ~13 ~97 quartz_block 0  
fill ~105 ~13 ~94 ~105 ~20 ~94 quartz_block 0  
fill ~72 ~14 ~89 ~72 ~23 ~89 quartz_block 0  
fill ~72 ~14 ~95 ~73 ~14 ~95 quartz_block 0  
fill ~73 ~14 ~96 ~74 ~14 ~96 quartz_block 0  
fill ~73 ~14 ~97 ~74 ~14 ~97 quartz_block 0  
fill ~74 ~14 ~98 ~75 ~14 ~98 quartz_block 0  
fill ~74 ~14 ~99 ~76 ~14 ~99 quartz_block 0  
fill ~75 ~14 ~80 ~76 ~14 ~80 quartz_block 0  
fill ~75 ~14 ~83 ~75 ~15 ~83 quartz_block 0  
fill ~75 ~14 ~84 ~75 ~16 ~84 quartz_block 0  
fill ~75 ~14 ~100 ~78 ~14 ~100 quartz_block 0  
fill ~77 ~14 ~79 ~78 ~14 ~79 quartz_block 0  
fill ~78 ~14 ~78 ~84 ~14 ~78 quartz_block 0  
fill ~79 ~14 ~102 ~81 ~14 ~102 quartz_block 0  
fill ~79 ~14 ~103 ~84 ~14 ~103 quartz_block 0  
fill ~80 ~14 ~79 ~81 ~14 ~79 quartz_block 0  
fill ~82 ~14 ~104 ~85 ~14 ~104 quartz_block 0  
fill ~83 ~14 ~77 ~89 ~14 ~77 quartz_block 0  
fill ~84 ~14 ~105 ~95 ~14 ~105 quartz_block 0  
fill ~85 ~14 ~76 ~93 ~14 ~76 quartz_block 0  
fill ~87 ~14 ~104 ~89 ~14 ~104 quartz_block 0  
fill ~91 ~14 ~104 ~91 ~16 ~104 quartz_block 0  
fill ~93 ~14 ~104 ~97 ~14 ~104 quartz_block 0  
fill ~94 ~14 ~77 ~95 ~14 ~77 quartz_block 0  
fill ~95 ~14 ~78 ~101 ~14 ~78 quartz_block 0  
fill ~96 ~14 ~103 ~96 ~16 ~103 quartz_block 0  
fill ~98 ~14 ~102 ~100 ~14 ~102 quartz_block 0  
fill ~98 ~14 ~103 ~100 ~14 ~103 quartz_block 0  
fill ~99 ~14 ~79 ~102 ~14 ~79 quartz_block 0  
fill ~100 ~14 ~101 ~101 ~14 ~101 quartz_block 0  
fill ~101 ~14 ~80 ~103 ~14 ~80 quartz_block 0  
fill ~103 ~14 ~99 ~104 ~14 ~99 quartz_block 0  
fill ~104 ~14 ~97 ~105 ~14 ~97 quartz_block 0 
setblock ~105 ~14 ~88 quartz_block 0  
fill ~72 ~15 ~95 ~72 ~17 ~95 quartz_block 0  
fill ~73 ~15 ~89 ~73 ~23 ~89 quartz_block 0  
fill ~73 ~15 ~96 ~74 ~15 ~96 quartz_block 0  
fill ~73 ~15 ~97 ~74 ~15 ~97 quartz_block 0  
fill ~74 ~15 ~93 ~74 ~24 ~93 quartz_block 0  
fill ~74 ~15 ~98 ~75 ~15 ~98 quartz_block 0  
fill ~74 ~15 ~99 ~76 ~15 ~99 quartz_block 0  
fill ~75 ~15 ~80 ~76 ~15 ~80 quartz_block 0  
fill ~75 ~15 ~82 ~75 ~16 ~82 quartz_block 0  
fill ~75 ~15 ~100 ~78 ~15 ~100 quartz_block 0   
fill ~77 ~15 ~79 ~77 ~20 ~79 quartz_block 0  
fill ~78 ~15 ~78 ~84 ~15 ~78 quartz_block 0  
fill ~79 ~15 ~102 ~80 ~15 ~102 quartz_block 0  
fill ~79 ~15 ~103 ~84 ~15 ~103 quartz_block 0  
fill ~81 ~15 ~79 ~81 ~42 ~79 quartz_block 0  
fill ~82 ~15 ~104 ~84 ~15 ~104 quartz_block 0  
fill ~83 ~15 ~77 ~88 ~15 ~77 quartz_block 0  
fill ~84 ~15 ~105 ~95 ~15 ~105 quartz_block 0  
fill ~85 ~15 ~76 ~93 ~15 ~76 quartz_block 0  
fill ~86 ~15 ~104 ~89 ~15 ~104 quartz_block 0  
fill ~92 ~15 ~104 ~97 ~15 ~104 quartz_block 0  
fill ~93 ~15 ~77 ~95 ~15 ~77 quartz_block 0  
fill ~95 ~15 ~78 ~101 ~15 ~78 quartz_block 0  
fill ~97 ~15 ~103 ~100 ~15 ~103 quartz_block 0  
fill ~98 ~15 ~79 ~98 ~40 ~79 quartz_block 0  
fill ~98 ~15 ~102 ~100 ~15 ~102 quartz_block 0  
fill ~100 ~15 ~79 ~102 ~15 ~79 quartz_block 0  
fill ~100 ~15 ~101 ~102 ~15 ~101 quartz_block 0  
fill ~101 ~15 ~80 ~103 ~15 ~80 quartz_block 0  
fill ~103 ~15 ~99 ~104 ~15 ~99 quartz_block 0  
fill ~104 ~15 ~97 ~105 ~15 ~97 quartz_block 0  
fill ~10 ~16 ~82 ~10 ~16 ~98 beacon 0  
fill ~11 ~16 ~75 ~11 ~16 ~81 beacon 0  
fill ~11 ~16 ~82 ~18 ~16 ~82 quartz_block 0  
fill ~11 ~16 ~83 ~18 ~16 ~83 quartz_block 0  
fill ~11 ~16 ~84 ~18 ~16 ~84 quartz_block 0  
fill ~11 ~16 ~85 ~18 ~16 ~85 quartz_block 0  
fill ~11 ~16 ~86 ~18 ~16 ~86 quartz_block 0  
fill ~11 ~16 ~87 ~18 ~16 ~87 quartz_block 0  
fill ~11 ~16 ~88 ~18 ~16 ~88 quartz_block 0  
fill ~11 ~16 ~89 ~18 ~16 ~89 quartz_block 0  
fill ~11 ~16 ~90 ~18 ~16 ~90 quartz_block 0  
fill ~11 ~16 ~91 ~18 ~16 ~91 quartz_block 0  
fill ~11 ~16 ~92 ~18 ~16 ~92 quartz_block 0  
fill ~11 ~16 ~93 ~18 ~16 ~93 quartz_block 0  
fill ~11 ~16 ~94 ~18 ~16 ~94 quartz_block 0  
fill ~11 ~16 ~95 ~18 ~16 ~95 quartz_block 0  
fill ~11 ~16 ~96 ~18 ~16 ~96 quartz_block 0  
fill ~11 ~16 ~97 ~18 ~16 ~97 quartz_block 0  
fill ~11 ~16 ~98 ~18 ~16 ~98 quartz_block 0  
fill ~11 ~16 ~99 ~11 ~16 ~105 beacon 0  
fill ~12 ~16 ~71 ~12 ~16 ~74 beacon 0  
fill ~12 ~16 ~75 ~20 ~16 ~75 quartz_block 0  
fill ~12 ~16 ~76 ~19 ~16 ~76 quartz_block 0  
fill ~12 ~16 ~77 ~19 ~16 ~77 quartz_block 0  
fill ~12 ~16 ~78 ~19 ~16 ~78 quartz_block 0  
fill ~12 ~16 ~79 ~19 ~16 ~79 quartz_block 0  
fill ~12 ~16 ~80 ~19 ~16 ~80 quartz_block 0  
fill ~12 ~16 ~81 ~19 ~16 ~81 quartz_block 0  
fill ~12 ~16 ~99 ~12 ~16 ~105 quartz_block 0  
fill ~12 ~16 ~106 ~12 ~16 ~109 beacon 0  
fill ~13 ~16 ~67 ~13 ~16 ~70 beacon 0  
fill ~13 ~16 ~71 ~21 ~16 ~71 quartz_block 0  
fill ~13 ~16 ~72 ~20 ~16 ~72 quartz_block 0  
fill ~13 ~16 ~73 ~20 ~16 ~73 quartz_block 0  
fill ~13 ~16 ~74 ~20 ~16 ~74 quartz_block 0  
fill ~13 ~16 ~101 ~19 ~16 ~101 quartz_block 0  
fill ~13 ~16 ~102 ~19 ~16 ~102 quartz_block 0  
fill ~13 ~16 ~103 ~19 ~16 ~103 quartz_block 0  
fill ~13 ~16 ~104 ~19 ~16 ~104 quartz_block 0  
fill ~13 ~16 ~105 ~20 ~16 ~105 quartz_block 0  
fill ~13 ~16 ~106 ~20 ~16 ~106 quartz_block 0  
fill ~13 ~16 ~107 ~20 ~16 ~107 quartz_block 0  
fill ~13 ~16 ~108 ~20 ~16 ~108 quartz_block 0  
fill ~13 ~16 ~109 ~21 ~16 ~109 quartz_block 0  
fill ~13 ~16 ~110 ~13 ~16 ~113 beacon 0  
fill ~14 ~16 ~64 ~14 ~16 ~66 beacon 0  
fill ~14 ~16 ~67 ~22 ~16 ~67 quartz_block 0  
fill ~14 ~16 ~68 ~22 ~16 ~68 quartz_block 0  
fill ~14 ~16 ~69 ~21 ~16 ~69 quartz_block 0  
fill ~14 ~16 ~70 ~21 ~16 ~70 quartz_block 0  
fill ~14 ~16 ~99 ~19 ~16 ~99 quartz_block 0  
fill ~14 ~16 ~100 ~19 ~16 ~100 quartz_block 0  
fill ~14 ~16 ~110 ~21 ~16 ~110 quartz_block 0  
fill ~14 ~16 ~111 ~21 ~16 ~111 quartz_block 0  
fill ~14 ~16 ~112 ~22 ~16 ~112 quartz_block 0  
fill ~14 ~16 ~113 ~22 ~16 ~113 quartz_block 0  
fill ~14 ~16 ~114 ~14 ~16 ~116 beacon 0  
fill ~15 ~16 ~61 ~15 ~16 ~63 beacon 0  
fill ~15 ~16 ~64 ~23 ~16 ~64 quartz_block 0  
fill ~15 ~16 ~65 ~23 ~16 ~65 quartz_block 0  
fill ~15 ~16 ~66 ~22 ~16 ~66 quartz_block 0  
fill ~15 ~16 ~114 ~22 ~16 ~114 quartz_block 0  
fill ~15 ~16 ~115 ~23 ~16 ~115 quartz_block 0  
fill ~15 ~16 ~116 ~23 ~16 ~116 quartz_block 0  
fill ~15 ~16 ~117 ~15 ~16 ~119 beacon 0  
fill ~16 ~16 ~59 ~16 ~16 ~60 beacon 0  
fill ~16 ~16 ~61 ~24 ~16 ~61 quartz_block 0  
fill ~16 ~16 ~62 ~24 ~16 ~62 quartz_block 0  
fill ~16 ~16 ~63 ~23 ~16 ~63 quartz_block 0  
fill ~16 ~16 ~117 ~23 ~16 ~117 quartz_block 0  
fill ~16 ~16 ~118 ~24 ~16 ~118 quartz_block 0  
fill ~16 ~16 ~119 ~24 ~16 ~119 quartz_block 0  
fill ~16 ~16 ~120 ~16 ~16 ~121 beacon 0  
fill ~17 ~16 ~57 ~17 ~16 ~58 beacon 0  
fill ~17 ~16 ~59 ~25 ~16 ~59 quartz_block 0  
fill ~17 ~16 ~60 ~25 ~16 ~60 quartz_block 0  
fill ~17 ~16 ~120 ~25 ~16 ~120 quartz_block 0  
fill ~17 ~16 ~121 ~25 ~16 ~121 quartz_block 0  
fill ~17 ~16 ~122 ~17 ~16 ~123 beacon 0  
fill ~18 ~16 ~55 ~18 ~16 ~56 beacon 0  
fill ~18 ~16 ~57 ~26 ~16 ~57 quartz_block 0  
fill ~18 ~16 ~58 ~26 ~16 ~58 quartz_block 0  
fill ~18 ~16 ~122 ~26 ~16 ~122 quartz_block 0  
fill ~18 ~16 ~123 ~26 ~16 ~123 quartz_block 0  
fill ~18 ~16 ~124 ~18 ~16 ~125 beacon 0  
fill ~19 ~16 ~53 ~19 ~16 ~54 beacon 0  
fill ~19 ~16 ~55 ~27 ~16 ~55 quartz_block 0  
fill ~19 ~16 ~56 ~27 ~16 ~56 quartz_block 0  
fill ~19 ~16 ~82 ~19 ~16 ~98 beacon 0  
fill ~19 ~16 ~124 ~27 ~16 ~124 quartz_block 0  
fill ~19 ~16 ~125 ~27 ~16 ~125 quartz_block 0  
fill ~19 ~16 ~126 ~19 ~16 ~127 beacon 0  
fill ~20 ~16 ~51 ~20 ~16 ~52 beacon 0  
fill ~20 ~16 ~53 ~28 ~16 ~53 quartz_block 0  
fill ~20 ~16 ~54 ~28 ~16 ~54 quartz_block 0  
fill ~20 ~16 ~76 ~20 ~16 ~81 beacon 0  
fill ~20 ~16 ~99 ~20 ~16 ~104 beacon 0  
fill ~20 ~16 ~126 ~28 ~16 ~126 quartz_block 0  
fill ~20 ~16 ~127 ~28 ~16 ~127 quartz_block 0  
fill ~20 ~16 ~128 ~20 ~16 ~129 beacon 0  
fill ~21 ~16 ~49 ~21 ~16 ~50 beacon 0  
fill ~21 ~16 ~51 ~30 ~16 ~51 quartz_block 0  
fill ~21 ~16 ~52 ~29 ~16 ~52 quartz_block 0  
fill ~21 ~16 ~72 ~21 ~16 ~75 beacon 0  
fill ~21 ~16 ~105 ~21 ~16 ~108 beacon 0  
fill ~21 ~16 ~128 ~29 ~16 ~128 quartz_block 0  
fill ~21 ~16 ~129 ~30 ~16 ~129 quartz_block 0  
fill ~21 ~16 ~130 ~21 ~16 ~131 beacon 0  
fill ~22 ~16 ~46 ~22 ~17 ~46 quartz_block 0  
fill ~22 ~16 ~47 ~22 ~16 ~48 beacon 0  
fill ~22 ~16 ~49 ~31 ~16 ~49 quartz_block 0  
fill ~22 ~16 ~50 ~30 ~16 ~50 quartz_block 0  
fill ~22 ~16 ~69 ~22 ~16 ~71 beacon 0  
fill ~22 ~16 ~109 ~22 ~16 ~111 beacon 0  
fill ~22 ~16 ~130 ~30 ~16 ~130 quartz_block 0  
fill ~22 ~16 ~131 ~31 ~16 ~131 quartz_block 0  
fill ~22 ~16 ~132 ~22 ~16 ~133 beacon 0 
setblock ~23 ~16 ~46 beacon 0  
fill ~23 ~16 ~47 ~33 ~16 ~47 quartz_block 0  
fill ~23 ~16 ~48 ~32 ~16 ~48 quartz_block 0  
fill ~23 ~16 ~66 ~23 ~16 ~68 beacon 0  
fill ~23 ~16 ~112 ~23 ~16 ~114 beacon 0  
fill ~23 ~16 ~132 ~32 ~16 ~132 quartz_block 0  
fill ~23 ~16 ~133 ~33 ~16 ~133 quartz_block 0 
setblock ~23 ~16 ~134 beacon 0  
fill ~24 ~16 ~44 ~24 ~16 ~45 beacon 0  
fill ~24 ~16 ~46 ~34 ~16 ~46 quartz_block 0  
fill ~24 ~16 ~63 ~24 ~16 ~65 beacon 0  
fill ~24 ~16 ~115 ~24 ~16 ~117 beacon 0  
fill ~24 ~16 ~134 ~33 ~16 ~134 quartz_block 0  
fill ~24 ~16 ~135 ~24 ~16 ~136 beacon 0 
setblock ~25 ~16 ~43 beacon 0  
fill ~25 ~16 ~44 ~35 ~16 ~44 quartz_block 0  
fill ~25 ~16 ~45 ~34 ~16 ~45 quartz_block 0  
fill ~25 ~16 ~61 ~25 ~16 ~62 beacon 0  
fill ~25 ~16 ~118 ~25 ~16 ~119 beacon 0  
fill ~25 ~16 ~135 ~34 ~16 ~135 quartz_block 0  
fill ~25 ~16 ~136 ~35 ~16 ~136 quartz_block 0 
setblock ~25 ~16 ~137 beacon 0 
setblock ~26 ~16 ~42 beacon 0  
fill ~26 ~16 ~43 ~36 ~16 ~43 quartz_block 0  
fill ~26 ~16 ~59 ~26 ~16 ~60 beacon 0  
fill ~26 ~16 ~120 ~26 ~16 ~121 beacon 0  
fill ~26 ~16 ~137 ~36 ~16 ~137 quartz_block 0 
setblock ~26 ~16 ~138 beacon 0  
fill ~27 ~16 ~40 ~27 ~16 ~41 beacon 0  
fill ~27 ~16 ~42 ~37 ~16 ~42 quartz_block 0  
fill ~27 ~16 ~57 ~27 ~16 ~58 beacon 0  
fill ~27 ~16 ~122 ~27 ~16 ~123 beacon 0  
fill ~27 ~16 ~138 ~37 ~16 ~138 quartz_block 0  
fill ~27 ~16 ~139 ~27 ~16 ~140 beacon 0 
setblock ~28 ~16 ~39 beacon 0  
fill ~28 ~16 ~40 ~39 ~16 ~40 quartz_block 0  
fill ~28 ~16 ~41 ~38 ~16 ~41 quartz_block 0  
fill ~28 ~16 ~55 ~28 ~16 ~56 beacon 0  
fill ~28 ~16 ~124 ~28 ~16 ~125 beacon 0  
fill ~28 ~16 ~139 ~38 ~16 ~139 quartz_block 0  
fill ~28 ~16 ~140 ~39 ~16 ~140 quartz_block 0 
setblock ~28 ~16 ~141 beacon 0 
setblock ~29 ~16 ~38 beacon 0  
fill ~29 ~16 ~39 ~40 ~16 ~39 quartz_block 0  
fill ~29 ~16 ~53 ~29 ~16 ~54 beacon 0  
fill ~29 ~16 ~126 ~29 ~16 ~127 beacon 0  
fill ~29 ~16 ~141 ~40 ~16 ~141 quartz_block 0 
setblock ~29 ~16 ~142 beacon 0 
setblock ~30 ~16 ~37 beacon 0  
fill ~30 ~16 ~38 ~41 ~16 ~38 quartz_block 0 
setblock ~30 ~16 ~52 beacon 0 
setblock ~30 ~16 ~128 beacon 0  
fill ~30 ~16 ~142 ~41 ~16 ~142 quartz_block 0 
setblock ~30 ~16 ~143 beacon 0 
setblock ~31 ~16 ~36 beacon 0  
fill ~31 ~16 ~37 ~42 ~16 ~37 quartz_block 0  
fill ~31 ~16 ~50 ~31 ~16 ~51 beacon 0  
fill ~31 ~16 ~129 ~31 ~16 ~130 beacon 0  
fill ~31 ~16 ~143 ~42 ~16 ~143 quartz_block 0 
setblock ~31 ~16 ~144 beacon 0 
setblock ~32 ~16 ~35 beacon 0  
fill ~32 ~16 ~36 ~43 ~16 ~36 quartz_block 0 
setblock ~32 ~16 ~49 beacon 0 
setblock ~32 ~16 ~131 beacon 0  
fill ~32 ~16 ~144 ~43 ~16 ~144 quartz_block 0 
setblock ~32 ~16 ~145 beacon 0 
setblock ~33 ~16 ~34 beacon 0  
fill ~33 ~16 ~35 ~44 ~16 ~35 quartz_block 0 
setblock ~33 ~16 ~48 beacon 0 
setblock ~33 ~16 ~132 beacon 0  
fill ~33 ~16 ~145 ~44 ~16 ~145 quartz_block 0 
setblock ~33 ~16 ~146 beacon 0 
setblock ~34 ~16 ~33 beacon 0  
fill ~34 ~16 ~34 ~45 ~16 ~34 quartz_block 0 
setblock ~34 ~16 ~47 beacon 0  
fill ~34 ~16 ~133 ~34 ~16 ~134 beacon 0  
fill ~34 ~16 ~146 ~45 ~16 ~146 quartz_block 0 
setblock ~34 ~16 ~147 beacon 0 
setblock ~35 ~16 ~32 beacon 0  
fill ~35 ~16 ~33 ~47 ~16 ~33 quartz_block 0  
fill ~35 ~16 ~45 ~35 ~16 ~46 beacon 0 
setblock ~35 ~16 ~135 beacon 0  
fill ~35 ~16 ~147 ~47 ~16 ~147 quartz_block 0 
setblock ~35 ~16 ~148 beacon 0 
setblock ~36 ~16 ~31 beacon 0  
fill ~36 ~16 ~32 ~48 ~16 ~32 quartz_block 0 
setblock ~36 ~16 ~44 beacon 0 
setblock ~36 ~16 ~136 beacon 0  
fill ~36 ~16 ~148 ~48 ~16 ~148 quartz_block 0 
setblock ~36 ~16 ~149 beacon 0 
setblock ~37 ~16 ~30 beacon 0  
fill ~37 ~16 ~31 ~49 ~16 ~31 quartz_block 0 
setblock ~37 ~16 ~43 beacon 0 
setblock ~37 ~16 ~137 beacon 0  
fill ~37 ~16 ~149 ~49 ~16 ~149 quartz_block 0 
setblock ~37 ~16 ~150 beacon 0 
setblock ~38 ~16 ~29 beacon 0  
fill ~38 ~16 ~30 ~51 ~16 ~30 quartz_block 0 
setblock ~38 ~16 ~42 beacon 0 
setblock ~38 ~16 ~138 beacon 0  
fill ~38 ~16 ~150 ~51 ~16 ~150 quartz_block 0 
setblock ~38 ~16 ~151 beacon 0 
setblock ~39 ~16 ~28 beacon 0  
fill ~39 ~16 ~29 ~52 ~16 ~29 quartz_block 0 
setblock ~39 ~16 ~41 beacon 0 
setblock ~39 ~16 ~139 beacon 0  
fill ~39 ~16 ~151 ~52 ~16 ~151 quartz_block 0 
setblock ~39 ~16 ~152 beacon 0  
fill ~40 ~16 ~27 ~41 ~16 ~27 beacon 0  
fill ~40 ~16 ~28 ~54 ~16 ~28 quartz_block 0 
setblock ~40 ~16 ~40 beacon 0 
setblock ~40 ~16 ~140 beacon 0  
fill ~40 ~16 ~152 ~54 ~16 ~152 quartz_block 0  
fill ~40 ~16 ~153 ~41 ~16 ~153 beacon 0 
setblock ~41 ~16 ~39 beacon 0 
setblock ~41 ~16 ~141 beacon 0 
setblock ~42 ~16 ~26 beacon 0  
fill ~42 ~16 ~27 ~56 ~16 ~27 quartz_block 0 
setblock ~42 ~16 ~38 beacon 0 
setblock ~42 ~16 ~142 beacon 0  
fill ~42 ~16 ~153 ~56 ~16 ~153 quartz_block 0 
setblock ~42 ~16 ~154 beacon 0 
setblock ~43 ~16 ~25 beacon 0  
fill ~43 ~16 ~26 ~58 ~16 ~26 quartz_block 0 
setblock ~43 ~16 ~37 beacon 0 
setblock ~43 ~16 ~143 beacon 0  
fill ~43 ~16 ~154 ~58 ~16 ~154 quartz_block 0 
setblock ~43 ~16 ~155 beacon 0  
fill ~44 ~16 ~24 ~45 ~16 ~24 beacon 0  
fill ~44 ~16 ~25 ~60 ~16 ~25 quartz_block 0 
setblock ~44 ~16 ~36 beacon 0 
setblock ~44 ~16 ~144 beacon 0  
fill ~44 ~16 ~155 ~60 ~16 ~155 quartz_block 0  
fill ~44 ~16 ~156 ~45 ~16 ~156 beacon 0 
setblock ~45 ~16 ~35 beacon 0 
setblock ~45 ~16 ~145 beacon 0 
setblock ~46 ~16 ~23 beacon 0  
fill ~46 ~16 ~24 ~62 ~16 ~24 quartz_block 0  
fill ~46 ~16 ~34 ~47 ~16 ~34 beacon 0  
fill ~46 ~16 ~146 ~47 ~16 ~146 beacon 0  
fill ~46 ~16 ~156 ~62 ~16 ~156 quartz_block 0 
setblock ~46 ~16 ~157 beacon 0  
fill ~47 ~16 ~22 ~48 ~16 ~22 beacon 0  
fill ~47 ~16 ~23 ~65 ~16 ~23 quartz_block 0  
fill ~47 ~16 ~157 ~65 ~16 ~157 quartz_block 0  
fill ~47 ~16 ~158 ~48 ~16 ~158 beacon 0 
setblock ~48 ~16 ~33 beacon 0 
setblock ~48 ~16 ~147 beacon 0  
fill ~49 ~16 ~21 ~50 ~16 ~21 beacon 0  
fill ~49 ~16 ~22 ~68 ~16 ~22 quartz_block 0 
setblock ~49 ~16 ~32 beacon 0 
setblock ~49 ~16 ~148 beacon 0  
fill ~49 ~16 ~158 ~68 ~16 ~158 quartz_block 0  
fill ~49 ~16 ~159 ~50 ~16 ~159 beacon 0  
fill ~50 ~16 ~31 ~51 ~16 ~31 beacon 0  
fill ~50 ~16 ~149 ~51 ~16 ~149 beacon 0  
fill ~51 ~16 ~20 ~52 ~16 ~20 beacon 0  
fill ~51 ~16 ~21 ~71 ~16 ~21 quartz_block 0  
fill ~51 ~16 ~159 ~71 ~16 ~159 quartz_block 0  
fill ~51 ~16 ~160 ~52 ~16 ~160 beacon 0 
setblock ~52 ~16 ~30 beacon 0 
setblock ~52 ~16 ~150 beacon 0  
fill ~53 ~16 ~19 ~54 ~16 ~19 beacon 0  
fill ~53 ~16 ~20 ~75 ~16 ~20 quartz_block 0  
fill ~53 ~16 ~29 ~54 ~16 ~29 beacon 0  
fill ~53 ~16 ~151 ~54 ~16 ~151 beacon 0  
fill ~53 ~16 ~160 ~75 ~16 ~160 quartz_block 0  
fill ~53 ~16 ~161 ~54 ~16 ~161 beacon 0  
fill ~55 ~16 ~18 ~56 ~16 ~18 beacon 0  
fill ~55 ~16 ~19 ~81 ~16 ~19 quartz_block 0  
fill ~55 ~16 ~28 ~56 ~16 ~28 beacon 0  
fill ~55 ~16 ~152 ~56 ~16 ~152 beacon 0  
fill ~55 ~16 ~161 ~81 ~16 ~161 quartz_block 0  
fill ~55 ~16 ~162 ~56 ~16 ~162 beacon 0  
fill ~57 ~16 ~17 ~58 ~16 ~17 beacon 0  
fill ~57 ~16 ~18 ~123 ~16 ~18 quartz_block 0  
fill ~57 ~16 ~27 ~58 ~16 ~27 beacon 0  
fill ~57 ~16 ~153 ~58 ~16 ~153 beacon 0  
fill ~57 ~16 ~162 ~123 ~16 ~162 quartz_block 0  
fill ~57 ~16 ~163 ~58 ~16 ~163 beacon 0  
fill ~59 ~16 ~16 ~60 ~16 ~16 beacon 0  
fill ~59 ~16 ~17 ~121 ~16 ~17 quartz_block 0  
fill ~59 ~16 ~26 ~60 ~16 ~26 beacon 0  
fill ~59 ~16 ~154 ~60 ~16 ~154 beacon 0  
fill ~59 ~16 ~163 ~121 ~16 ~163 quartz_block 0  
fill ~59 ~16 ~164 ~60 ~16 ~164 beacon 0  
fill ~61 ~16 ~15 ~63 ~16 ~15 beacon 0  
fill ~61 ~16 ~16 ~119 ~16 ~16 quartz_block 0  
fill ~61 ~16 ~25 ~62 ~16 ~25 beacon 0  
fill ~61 ~16 ~155 ~62 ~16 ~155 beacon 0  
fill ~61 ~16 ~164 ~119 ~16 ~164 quartz_block 0  
fill ~61 ~16 ~165 ~63 ~16 ~165 beacon 0  
fill ~63 ~16 ~24 ~65 ~16 ~24 beacon 0  
fill ~63 ~16 ~156 ~65 ~16 ~156 beacon 0  
fill ~64 ~16 ~14 ~66 ~16 ~14 beacon 0  
fill ~64 ~16 ~15 ~116 ~16 ~15 quartz_block 0  
fill ~64 ~16 ~165 ~116 ~16 ~165 quartz_block 0  
fill ~64 ~16 ~166 ~66 ~16 ~166 beacon 0  
fill ~66 ~16 ~23 ~68 ~16 ~23 beacon 0  
fill ~66 ~16 ~157 ~68 ~16 ~157 beacon 0  
fill ~67 ~16 ~13 ~70 ~16 ~13 beacon 0  
fill ~67 ~16 ~14 ~113 ~16 ~14 quartz_block 0  
fill ~67 ~16 ~166 ~113 ~16 ~166 quartz_block 0  
fill ~67 ~16 ~167 ~70 ~16 ~167 beacon 0  
fill ~69 ~16 ~22 ~71 ~16 ~22 beacon 0  
fill ~69 ~16 ~158 ~71 ~16 ~158 beacon 0  
fill ~71 ~16 ~12 ~74 ~16 ~12 beacon 0  
fill ~71 ~16 ~13 ~109 ~16 ~13 quartz_block 0  
fill ~71 ~16 ~167 ~109 ~16 ~167 quartz_block 0  
fill ~71 ~16 ~168 ~74 ~16 ~168 beacon 0  
fill ~72 ~16 ~21 ~75 ~16 ~21 beacon 0  
fill ~72 ~16 ~159 ~75 ~16 ~159 beacon 0  
fill ~73 ~16 ~95 ~73 ~24 ~95 quartz_block 0  
fill ~73 ~16 ~96 ~74 ~16 ~96 quartz_block 0  
fill ~73 ~16 ~97 ~74 ~16 ~97 quartz_block 0  
fill ~74 ~16 ~98 ~75 ~16 ~98 quartz_block 0  
fill ~74 ~16 ~99 ~76 ~16 ~99 quartz_block 0  
fill ~75 ~16 ~11 ~81 ~16 ~11 beacon 0  
fill ~75 ~16 ~12 ~105 ~16 ~12 quartz_block 0  
fill ~75 ~16 ~80 ~76 ~16 ~80 quartz_block 0  
fill ~75 ~16 ~100 ~78 ~16 ~100 quartz_block 0  
fill ~75 ~16 ~168 ~105 ~16 ~168 quartz_block 0  
fill ~75 ~16 ~169 ~81 ~16 ~169 beacon 0  
fill ~76 ~16 ~20 ~81 ~16 ~20 beacon 0  
fill ~76 ~16 ~160 ~81 ~16 ~160 beacon 0  
fill ~78 ~16 ~78 ~84 ~16 ~78 quartz_block 0  
fill ~78 ~16 ~79 ~78 ~16 ~78 quartz_block 0  
fill ~79 ~16 ~102 ~79 ~29 ~102 quartz_block 0  
fill ~79 ~16 ~103 ~83 ~16 ~103 quartz_block 0 
setblock ~81 ~16 ~102 quartz_block 0  
fill ~82 ~16 ~10 ~98 ~16 ~10 beacon 0  
fill ~82 ~16 ~11 ~98 ~16 ~11 quartz_block 0  
fill ~82 ~16 ~19 ~98 ~16 ~19 beacon 0  
fill ~82 ~16 ~104 ~87 ~16 ~104 quartz_block 0  
fill ~82 ~16 ~161 ~97 ~16 ~161 beacon 0  
fill ~82 ~16 ~169 ~98 ~16 ~169 quartz_block 0  
fill ~82 ~16 ~170 ~98 ~16 ~170 beacon 0  
fill ~83 ~16 ~77 ~88 ~16 ~77 quartz_block 0  
fill ~84 ~16 ~105 ~95 ~16 ~105 quartz_block 0  
fill ~85 ~16 ~76 ~93 ~16 ~76 quartz_block 0  
fill ~90 ~16 ~77 ~91 ~16 ~77 quartz_block 0 
setblock ~90 ~16 ~104 quartz_block 0  
fill ~92 ~16 ~104 ~97 ~16 ~104 quartz_block 0  
fill ~94 ~16 ~77 ~95 ~16 ~77 quartz_block 0  
fill ~95 ~16 ~78 ~100 ~16 ~78 quartz_block 0 
setblock ~95 ~16 ~103 quartz_block 0  
fill ~97 ~16 ~103 ~100 ~16 ~103 quartz_block 0  
fill ~98 ~16 ~160 ~104 ~16 ~160 beacon 0  
fill ~98 ~16 ~161 ~125 ~16 ~161 quartz_block 0  
fill ~99 ~16 ~11 ~105 ~16 ~11 beacon 0  
fill ~99 ~16 ~19 ~125 ~16 ~19 quartz_block 0  
fill ~99 ~16 ~20 ~104 ~16 ~20 beacon 0  
fill ~99 ~16 ~169 ~105 ~16 ~169 beacon 0  
fill ~100 ~16 ~79 ~102 ~16 ~79 quartz_block 0  
fill ~100 ~16 ~101 ~102 ~16 ~101 quartz_block 0  
fill ~101 ~16 ~80 ~103 ~16 ~80 quartz_block 0  
fill ~102 ~16 ~81 ~102 ~23 ~81 quartz_block 0  
fill ~103 ~16 ~99 ~104 ~16 ~99 quartz_block 0  
fill ~105 ~16 ~20 ~127 ~16 ~20 quartz_block 0  
fill ~105 ~16 ~21 ~108 ~16 ~21 beacon 0  
fill ~105 ~16 ~88 ~105 ~34 ~88 quartz_block 0  
fill ~105 ~16 ~91 ~105 ~17 ~91 quartz_block 0  
fill ~105 ~16 ~97 ~105 ~64 ~97 quartz_block 0  
fill ~105 ~16 ~159 ~108 ~16 ~159 beacon 0  
fill ~105 ~16 ~160 ~127 ~16 ~160 quartz_block 0  
fill ~106 ~16 ~12 ~109 ~16 ~12 beacon 0  
fill ~106 ~16 ~168 ~109 ~16 ~168 beacon 0  
fill ~109 ~16 ~21 ~129 ~16 ~21 quartz_block 0  
fill ~109 ~16 ~22 ~111 ~16 ~22 beacon 0  
fill ~109 ~16 ~158 ~111 ~16 ~158 beacon 0  
fill ~109 ~16 ~159 ~129 ~16 ~159 quartz_block 0  
fill ~110 ~16 ~13 ~113 ~16 ~13 beacon 0  
fill ~110 ~16 ~167 ~113 ~16 ~167 beacon 0  
fill ~112 ~16 ~22 ~131 ~16 ~22 quartz_block 0  
fill ~112 ~16 ~23 ~114 ~16 ~23 beacon 0  
fill ~112 ~16 ~157 ~114 ~16 ~157 beacon 0  
fill ~112 ~16 ~158 ~131 ~16 ~158 quartz_block 0  
fill ~114 ~16 ~14 ~116 ~16 ~14 beacon 0  
fill ~114 ~16 ~166 ~116 ~16 ~166 beacon 0  
fill ~115 ~16 ~23 ~133 ~16 ~23 quartz_block 0  
fill ~115 ~16 ~24 ~117 ~16 ~24 beacon 0  
fill ~115 ~16 ~156 ~117 ~16 ~156 beacon 0  
fill ~115 ~16 ~157 ~133 ~16 ~157 quartz_block 0  
fill ~117 ~16 ~15 ~119 ~16 ~15 beacon 0  
fill ~117 ~16 ~165 ~119 ~16 ~165 beacon 0  
fill ~118 ~16 ~24 ~134 ~16 ~24 quartz_block 0  
fill ~118 ~16 ~25 ~119 ~16 ~25 beacon 0  
fill ~118 ~16 ~155 ~119 ~16 ~155 beacon 0  
fill ~118 ~16 ~156 ~134 ~16 ~156 quartz_block 0  
fill ~120 ~16 ~16 ~121 ~16 ~16 beacon 0  
fill ~120 ~16 ~25 ~136 ~16 ~25 quartz_block 0  
fill ~120 ~16 ~26 ~121 ~16 ~26 beacon 0  
fill ~120 ~16 ~154 ~121 ~16 ~154 beacon 0  
fill ~120 ~16 ~155 ~136 ~16 ~155 quartz_block 0  
fill ~120 ~16 ~164 ~121 ~16 ~164 beacon 0  
fill ~122 ~16 ~17 ~123 ~16 ~17 beacon 0  
fill ~122 ~16 ~26 ~137 ~16 ~26 quartz_block 0  
fill ~122 ~16 ~27 ~123 ~16 ~27 beacon 0  
fill ~122 ~16 ~153 ~123 ~16 ~153 beacon 0  
fill ~122 ~16 ~154 ~137 ~16 ~154 quartz_block 0  
fill ~122 ~16 ~163 ~123 ~16 ~163 beacon 0  
fill ~124 ~16 ~18 ~125 ~16 ~18 beacon 0  
fill ~124 ~16 ~27 ~138 ~16 ~27 quartz_block 0  
fill ~124 ~16 ~28 ~125 ~16 ~28 beacon 0  
fill ~124 ~16 ~152 ~125 ~16 ~152 beacon 0  
fill ~124 ~16 ~153 ~138 ~16 ~153 quartz_block 0  
fill ~124 ~16 ~162 ~125 ~16 ~162 beacon 0  
fill ~126 ~16 ~19 ~127 ~16 ~19 beacon 0  
fill ~126 ~16 ~28 ~140 ~16 ~28 quartz_block 0  
fill ~126 ~16 ~29 ~127 ~16 ~29 beacon 0  
fill ~126 ~16 ~151 ~127 ~16 ~151 beacon 0  
fill ~126 ~16 ~152 ~140 ~16 ~152 quartz_block 0  
fill ~126 ~16 ~161 ~127 ~16 ~161 beacon 0  
fill ~128 ~16 ~20 ~129 ~16 ~20 beacon 0  
fill ~128 ~16 ~29 ~141 ~16 ~29 quartz_block 0 
setblock ~128 ~16 ~30 beacon 0 
setblock ~128 ~16 ~150 beacon 0  
fill ~128 ~16 ~151 ~141 ~16 ~151 quartz_block 0  
fill ~128 ~16 ~160 ~129 ~16 ~160 beacon 0  
fill ~129 ~16 ~30 ~142 ~16 ~30 quartz_block 0  
fill ~129 ~16 ~31 ~130 ~16 ~31 beacon 0  
fill ~129 ~16 ~149 ~130 ~16 ~149 beacon 0  
fill ~129 ~16 ~150 ~142 ~16 ~150 quartz_block 0  
fill ~130 ~16 ~21 ~131 ~16 ~21 beacon 0  
fill ~130 ~16 ~159 ~131 ~16 ~159 beacon 0  
fill ~131 ~16 ~31 ~143 ~16 ~31 quartz_block 0 
setblock ~131 ~16 ~32 beacon 0 
setblock ~131 ~16 ~148 beacon 0  
fill ~131 ~16 ~149 ~143 ~16 ~149 quartz_block 0  
fill ~132 ~16 ~22 ~133 ~16 ~22 beacon 0  
fill ~132 ~16 ~32 ~144 ~16 ~32 quartz_block 0 
setblock ~132 ~16 ~33 beacon 0 
setblock ~132 ~16 ~147 beacon 0  
fill ~132 ~16 ~148 ~144 ~16 ~148 quartz_block 0  
fill ~132 ~16 ~158 ~133 ~16 ~158 beacon 0  
fill ~133 ~16 ~33 ~145 ~16 ~33 quartz_block 0  
fill ~133 ~16 ~34 ~134 ~16 ~34 beacon 0  
fill ~133 ~16 ~146 ~134 ~16 ~146 beacon 0  
fill ~133 ~16 ~147 ~145 ~16 ~147 quartz_block 0 
setblock ~134 ~16 ~23 beacon 0 
setblock ~134 ~16 ~157 beacon 0  
fill ~135 ~16 ~24 ~136 ~16 ~24 beacon 0  
fill ~135 ~16 ~34 ~146 ~16 ~34 quartz_block 0 
setblock ~135 ~16 ~35 beacon 0 
setblock ~135 ~16 ~145 beacon 0  
fill ~135 ~16 ~146 ~146 ~16 ~146 quartz_block 0  
fill ~135 ~16 ~156 ~136 ~16 ~156 beacon 0  
fill ~136 ~16 ~35 ~147 ~16 ~35 quartz_block 0 
setblock ~136 ~16 ~36 beacon 0 
setblock ~136 ~16 ~144 beacon 0  
fill ~136 ~16 ~145 ~147 ~16 ~145 quartz_block 0 
setblock ~137 ~16 ~25 beacon 0  
fill ~137 ~16 ~36 ~148 ~16 ~36 quartz_block 0 
setblock ~137 ~16 ~37 beacon 0 
setblock ~137 ~16 ~143 beacon 0  
fill ~137 ~16 ~144 ~148 ~16 ~144 quartz_block 0 
setblock ~137 ~16 ~155 beacon 0 
setblock ~138 ~16 ~26 beacon 0  
fill ~138 ~16 ~37 ~149 ~16 ~37 quartz_block 0 
setblock ~138 ~16 ~38 beacon 0 
setblock ~138 ~16 ~142 beacon 0  
fill ~138 ~16 ~143 ~149 ~16 ~143 quartz_block 0 
setblock ~138 ~16 ~154 beacon 0  
fill ~139 ~16 ~27 ~140 ~16 ~27 beacon 0  
fill ~139 ~16 ~38 ~150 ~16 ~38 quartz_block 0 
setblock ~139 ~16 ~39 beacon 0 
setblock ~139 ~16 ~141 beacon 0  
fill ~139 ~16 ~142 ~150 ~16 ~142 quartz_block 0  
fill ~139 ~16 ~153 ~140 ~16 ~153 beacon 0  
fill ~140 ~16 ~39 ~151 ~16 ~39 quartz_block 0 
setblock ~140 ~16 ~40 beacon 0 
setblock ~140 ~16 ~140 beacon 0  
fill ~140 ~16 ~141 ~151 ~16 ~141 quartz_block 0 
setblock ~141 ~16 ~28 beacon 0  
fill ~141 ~16 ~40 ~152 ~16 ~40 quartz_block 0 
setblock ~141 ~16 ~41 beacon 0 
setblock ~141 ~16 ~139 beacon 0  
fill ~141 ~16 ~140 ~152 ~16 ~140 quartz_block 0 
setblock ~141 ~16 ~152 beacon 0 
setblock ~142 ~16 ~29 beacon 0  
fill ~142 ~16 ~41 ~152 ~16 ~41 quartz_block 0 
setblock ~142 ~16 ~42 beacon 0 
setblock ~142 ~16 ~138 beacon 0  
fill ~142 ~16 ~139 ~152 ~16 ~139 quartz_block 0 
setblock ~142 ~16 ~151 beacon 0 
setblock ~143 ~16 ~30 beacon 0  
fill ~143 ~16 ~42 ~153 ~16 ~42 quartz_block 0 
setblock ~143 ~16 ~43 beacon 0 
setblock ~143 ~16 ~137 beacon 0  
fill ~143 ~16 ~138 ~153 ~16 ~138 quartz_block 0 
setblock ~143 ~16 ~150 beacon 0 
setblock ~144 ~16 ~31 beacon 0  
fill ~144 ~16 ~43 ~154 ~16 ~43 quartz_block 0 
setblock ~144 ~16 ~44 beacon 0 
setblock ~144 ~16 ~136 beacon 0  
fill ~144 ~16 ~137 ~154 ~16 ~137 quartz_block 0 
setblock ~144 ~16 ~149 beacon 0 
setblock ~145 ~16 ~32 beacon 0  
fill ~145 ~16 ~44 ~155 ~16 ~44 quartz_block 0 
setblock ~145 ~16 ~45 beacon 0 
setblock ~145 ~16 ~135 beacon 0  
fill ~145 ~16 ~136 ~155 ~16 ~136 quartz_block 0 
setblock ~145 ~16 ~148 beacon 0 
setblock ~146 ~16 ~33 beacon 0  
fill ~146 ~16 ~45 ~155 ~16 ~45 quartz_block 0  
fill ~146 ~16 ~46 ~146 ~16 ~47 beacon 0  
fill ~146 ~16 ~133 ~146 ~16 ~134 beacon 0  
fill ~146 ~16 ~135 ~155 ~16 ~135 quartz_block 0 
setblock ~146 ~16 ~147 beacon 0 
setblock ~147 ~16 ~34 beacon 0  
fill ~147 ~16 ~46 ~156 ~16 ~46 quartz_block 0  
fill ~147 ~16 ~47 ~157 ~16 ~47 quartz_block 0 
setblock ~147 ~16 ~48 beacon 0 
setblock ~147 ~16 ~132 beacon 0  
fill ~147 ~16 ~133 ~157 ~16 ~133 quartz_block 0  
fill ~147 ~16 ~134 ~156 ~16 ~134 quartz_block 0 
setblock ~147 ~16 ~146 beacon 0 
setblock ~148 ~16 ~35 beacon 0  
fill ~148 ~16 ~48 ~157 ~16 ~48 quartz_block 0 
setblock ~148 ~16 ~49 beacon 0 
setblock ~148 ~16 ~131 beacon 0  
fill ~148 ~16 ~132 ~157 ~16 ~132 quartz_block 0 
setblock ~148 ~16 ~145 beacon 0 
setblock ~149 ~16 ~36 beacon 0  
fill ~149 ~16 ~49 ~158 ~16 ~49 quartz_block 0  
fill ~149 ~16 ~50 ~149 ~16 ~51 beacon 0  
fill ~149 ~16 ~129 ~149 ~16 ~130 beacon 0  
fill ~149 ~16 ~131 ~158 ~16 ~131 quartz_block 0 
setblock ~149 ~16 ~144 beacon 0 
setblock ~150 ~16 ~37 beacon 0  
fill ~150 ~16 ~50 ~158 ~16 ~50 quartz_block 0  
fill ~150 ~16 ~51 ~159 ~16 ~51 quartz_block 0 
setblock ~150 ~16 ~52 beacon 0 
setblock ~150 ~16 ~128 beacon 0  
fill ~150 ~16 ~129 ~159 ~16 ~129 quartz_block 0  
fill ~150 ~16 ~130 ~158 ~16 ~130 quartz_block 0 
setblock ~150 ~16 ~143 beacon 0 
setblock ~151 ~16 ~38 beacon 0  
fill ~151 ~16 ~52 ~159 ~16 ~52 quartz_block 0  
fill ~151 ~16 ~53 ~151 ~16 ~54 beacon 0  
fill ~151 ~16 ~126 ~151 ~16 ~127 beacon 0  
fill ~151 ~16 ~128 ~159 ~16 ~128 quartz_block 0 
setblock ~151 ~16 ~142 beacon 0 
setblock ~152 ~16 ~39 beacon 0  
fill ~152 ~16 ~53 ~160 ~16 ~53 quartz_block 0  
fill ~152 ~16 ~54 ~160 ~16 ~54 quartz_block 0  
fill ~152 ~16 ~55 ~152 ~16 ~56 beacon 0  
fill ~152 ~16 ~124 ~152 ~16 ~125 beacon 0  
fill ~152 ~16 ~126 ~160 ~16 ~126 quartz_block 0  
fill ~152 ~16 ~127 ~160 ~16 ~127 quartz_block 0 
setblock ~152 ~16 ~141 beacon 0  
fill ~153 ~16 ~40 ~153 ~16 ~41 beacon 0  
fill ~153 ~16 ~55 ~161 ~16 ~55 quartz_block 0  
fill ~153 ~16 ~56 ~161 ~16 ~56 quartz_block 0  
fill ~153 ~16 ~57 ~153 ~16 ~58 beacon 0  
fill ~153 ~16 ~122 ~153 ~16 ~123 beacon 0  
fill ~153 ~16 ~124 ~161 ~16 ~124 quartz_block 0  
fill ~153 ~16 ~125 ~161 ~16 ~125 quartz_block 0  
fill ~153 ~16 ~139 ~153 ~16 ~140 beacon 0 
setblock ~154 ~16 ~42 beacon 0  
fill ~154 ~16 ~57 ~162 ~16 ~57 quartz_block 0  
fill ~154 ~16 ~58 ~162 ~16 ~58 quartz_block 0  
fill ~154 ~16 ~59 ~154 ~16 ~60 beacon 0  
fill ~154 ~16 ~120 ~154 ~16 ~121 beacon 0  
fill ~154 ~16 ~122 ~162 ~16 ~122 quartz_block 0  
fill ~154 ~16 ~123 ~162 ~16 ~123 quartz_block 0 
setblock ~154 ~16 ~138 beacon 0 
setblock ~155 ~16 ~43 beacon 0  
fill ~155 ~16 ~59 ~163 ~16 ~59 quartz_block 0  
fill ~155 ~16 ~60 ~163 ~16 ~60 quartz_block 0  
fill ~155 ~16 ~61 ~155 ~16 ~62 beacon 0  
fill ~155 ~16 ~118 ~155 ~16 ~119 beacon 0  
fill ~155 ~16 ~120 ~163 ~16 ~120 quartz_block 0  
fill ~155 ~16 ~121 ~163 ~16 ~121 quartz_block 0 
setblock ~155 ~16 ~137 beacon 0  
fill ~156 ~16 ~44 ~156 ~16 ~45 beacon 0  
fill ~156 ~16 ~61 ~164 ~16 ~61 quartz_block 0  
fill ~156 ~16 ~62 ~164 ~16 ~62 quartz_block 0  
fill ~156 ~16 ~63 ~156 ~16 ~64 beacon 0  
fill ~156 ~16 ~115 ~156 ~16 ~117 beacon 0  
fill ~156 ~16 ~118 ~164 ~16 ~118 quartz_block 0  
fill ~156 ~16 ~119 ~164 ~16 ~119 quartz_block 0  
fill ~156 ~16 ~135 ~156 ~16 ~136 beacon 0 
setblock ~157 ~16 ~46 beacon 0  
fill ~157 ~16 ~63 ~164 ~16 ~63 quartz_block 0  
fill ~157 ~16 ~64 ~165 ~16 ~64 quartz_block 0  
fill ~157 ~16 ~65 ~157 ~16 ~68 beacon 0  
fill ~157 ~16 ~112 ~157 ~16 ~114 beacon 0  
fill ~157 ~16 ~115 ~165 ~16 ~115 quartz_block 0  
fill ~157 ~16 ~116 ~165 ~16 ~116 quartz_block 0  
fill ~157 ~16 ~117 ~164 ~16 ~117 quartz_block 0 
setblock ~157 ~16 ~134 beacon 0  
fill ~158 ~16 ~47 ~158 ~16 ~48 beacon 0  
fill ~158 ~16 ~65 ~165 ~16 ~65 quartz_block 0  
fill ~158 ~16 ~66 ~165 ~16 ~66 quartz_block 0  
fill ~158 ~16 ~67 ~166 ~16 ~67 quartz_block 0  
fill ~158 ~16 ~68 ~166 ~16 ~68 quartz_block 0  
fill ~158 ~16 ~69 ~158 ~16 ~71 beacon 0  
fill ~158 ~16 ~109 ~158 ~16 ~111 beacon 0  
fill ~158 ~16 ~112 ~166 ~16 ~112 quartz_block 0  
fill ~158 ~16 ~113 ~166 ~16 ~113 quartz_block 0  
fill ~158 ~16 ~114 ~165 ~16 ~114 quartz_block 0  
fill ~158 ~16 ~132 ~158 ~16 ~133 beacon 0  
fill ~159 ~16 ~49 ~159 ~16 ~50 beacon 0  
fill ~159 ~16 ~69 ~166 ~16 ~69 quartz_block 0  
fill ~159 ~16 ~70 ~166 ~16 ~70 quartz_block 0  
fill ~159 ~16 ~71 ~167 ~16 ~71 quartz_block 0  
fill ~159 ~16 ~72 ~159 ~16 ~75 beacon 0  
fill ~159 ~16 ~105 ~159 ~16 ~108 beacon 0  
fill ~159 ~16 ~109 ~167 ~16 ~109 quartz_block 0  
fill ~159 ~16 ~110 ~166 ~16 ~110 quartz_block 0  
fill ~159 ~16 ~111 ~166 ~16 ~111 quartz_block 0  
fill ~159 ~16 ~130 ~159 ~16 ~131 beacon 0  
fill ~160 ~16 ~51 ~160 ~16 ~52 beacon 0  
fill ~160 ~16 ~72 ~167 ~16 ~72 quartz_block 0  
fill ~160 ~16 ~73 ~167 ~16 ~73 quartz_block 0  
fill ~160 ~16 ~74 ~167 ~16 ~74 quartz_block 0  
fill ~160 ~16 ~75 ~168 ~16 ~75 quartz_block 0  
fill ~160 ~16 ~76 ~160 ~16 ~82 beacon 0  
fill ~160 ~16 ~99 ~160 ~16 ~104 beacon 0  
fill ~160 ~16 ~105 ~168 ~16 ~105 quartz_block 0  
fill ~160 ~16 ~106 ~167 ~16 ~106 quartz_block 0  
fill ~160 ~16 ~107 ~167 ~16 ~107 quartz_block 0  
fill ~160 ~16 ~108 ~167 ~16 ~108 quartz_block 0  
fill ~160 ~16 ~128 ~160 ~16 ~129 beacon 0  
fill ~161 ~16 ~53 ~161 ~16 ~54 beacon 0  
fill ~161 ~16 ~76 ~168 ~16 ~76 quartz_block 0  
fill ~161 ~16 ~77 ~168 ~16 ~77 quartz_block 0  
fill ~161 ~16 ~78 ~168 ~16 ~78 quartz_block 0  
fill ~161 ~16 ~79 ~168 ~16 ~79 quartz_block 0  
fill ~161 ~16 ~80 ~168 ~16 ~80 quartz_block 0  
fill ~161 ~16 ~81 ~168 ~16 ~81 quartz_block 0  
fill ~161 ~16 ~82 ~169 ~16 ~82 quartz_block 0  
fill ~161 ~16 ~83 ~161 ~16 ~98 beacon 0  
fill ~161 ~16 ~99 ~168 ~16 ~99 quartz_block 0  
fill ~161 ~16 ~100 ~168 ~16 ~100 quartz_block 0  
fill ~161 ~16 ~101 ~168 ~16 ~101 quartz_block 0  
fill ~161 ~16 ~102 ~168 ~16 ~102 quartz_block 0  
fill ~161 ~16 ~103 ~168 ~16 ~103 quartz_block 0  
fill ~161 ~16 ~104 ~168 ~16 ~104 quartz_block 0  
fill ~161 ~16 ~126 ~161 ~16 ~127 beacon 0  
fill ~162 ~16 ~55 ~162 ~16 ~56 beacon 0  
fill ~162 ~16 ~83 ~169 ~16 ~83 quartz_block 0  
fill ~162 ~16 ~84 ~169 ~16 ~84 quartz_block 0  
fill ~162 ~16 ~85 ~169 ~16 ~85 quartz_block 0  
fill ~162 ~16 ~86 ~169 ~16 ~86 quartz_block 0  
fill ~162 ~16 ~87 ~169 ~16 ~87 quartz_block 0  
fill ~162 ~16 ~88 ~169 ~16 ~88 quartz_block 0  
fill ~162 ~16 ~89 ~169 ~16 ~89 quartz_block 0  
fill ~162 ~16 ~90 ~169 ~16 ~90 quartz_block 0  
fill ~162 ~16 ~91 ~169 ~16 ~91 quartz_block 0  
fill ~162 ~16 ~92 ~169 ~16 ~92 quartz_block 0  
fill ~162 ~16 ~93 ~169 ~16 ~93 quartz_block 0  
fill ~162 ~16 ~94 ~169 ~16 ~94 quartz_block 0  
fill ~162 ~16 ~95 ~169 ~16 ~95 quartz_block 0  
fill ~162 ~16 ~96 ~169 ~16 ~96 quartz_block 0  
fill ~162 ~16 ~97 ~169 ~16 ~97 quartz_block 0  
fill ~162 ~16 ~98 ~169 ~16 ~98 quartz_block 0  
fill ~162 ~16 ~124 ~162 ~16 ~125 beacon 0  
fill ~163 ~16 ~57 ~163 ~16 ~58 beacon 0  
fill ~163 ~16 ~122 ~163 ~16 ~123 beacon 0  
fill ~164 ~16 ~59 ~164 ~16 ~60 beacon 0  
fill ~164 ~16 ~120 ~164 ~16 ~121 beacon 0  
fill ~165 ~16 ~61 ~165 ~16 ~63 beacon 0  
fill ~165 ~16 ~117 ~165 ~16 ~119 beacon 0  
fill ~166 ~16 ~64 ~166 ~16 ~66 beacon 0  
fill ~166 ~16 ~114 ~166 ~16 ~116 beacon 0  
fill ~167 ~16 ~67 ~167 ~16 ~70 beacon 0  
fill ~167 ~16 ~110 ~167 ~16 ~113 beacon 0  
fill ~168 ~16 ~71 ~168 ~16 ~74 beacon 0  
fill ~168 ~16 ~106 ~168 ~16 ~109 beacon 0  
fill ~168 ~16 ~113 ~168 ~17 ~113 quartz_block 0  
fill ~169 ~16 ~75 ~169 ~16 ~81 beacon 0  
fill ~169 ~16 ~99 ~169 ~16 ~105 beacon 0  
fill ~170 ~16 ~82 ~170 ~16 ~98 beacon 0  
fill ~6 ~17 ~88 ~9 ~17 ~88 quartz_block 0  
fill ~6 ~17 ~89 ~9 ~17 ~89 quartz_block 0  
fill ~6 ~17 ~90 ~9 ~17 ~90 quartz_block 0  
fill ~6 ~17 ~91 ~9 ~17 ~91 quartz_block 0  
fill ~6 ~17 ~92 ~9 ~17 ~92 quartz_block 0  
fill ~7 ~17 ~77 ~10 ~17 ~77 quartz_block 0  
fill ~7 ~17 ~78 ~10 ~17 ~78 quartz_block 0  
fill ~7 ~17 ~79 ~10 ~17 ~79 quartz_block 0  
fill ~7 ~17 ~80 ~10 ~17 ~80 quartz_block 0  
fill ~7 ~17 ~81 ~10 ~17 ~81 quartz_block 0  
fill ~7 ~17 ~82 ~9 ~17 ~82 quartz_block 0  
fill ~7 ~17 ~83 ~9 ~17 ~83 quartz_block 0  
fill ~7 ~17 ~84 ~9 ~17 ~84 quartz_block 0  
fill ~7 ~17 ~85 ~9 ~17 ~85 quartz_block 0  
fill ~7 ~17 ~86 ~9 ~17 ~86 quartz_block 0  
fill ~7 ~17 ~87 ~9 ~17 ~87 quartz_block 0  
fill ~7 ~17 ~93 ~9 ~17 ~93 quartz_block 0  
fill ~7 ~17 ~94 ~9 ~17 ~94 quartz_block 0  
fill ~7 ~17 ~95 ~9 ~17 ~95 quartz_block 0  
fill ~7 ~17 ~96 ~9 ~17 ~96 quartz_block 0  
fill ~7 ~17 ~97 ~9 ~17 ~97 quartz_block 0  
fill ~7 ~17 ~98 ~9 ~17 ~98 quartz_block 0  
fill ~7 ~17 ~99 ~10 ~17 ~99 quartz_block 0  
fill ~7 ~17 ~100 ~10 ~17 ~100 quartz_block 0  
fill ~7 ~17 ~101 ~10 ~17 ~101 quartz_block 0  
fill ~7 ~17 ~102 ~10 ~17 ~102 quartz_block 0   
fill ~7 ~17 ~103 ~10 ~17 ~103 quartz_block 0  
fill ~8 ~17 ~72 ~11 ~17 ~72 quartz_block 0  
fill ~8 ~17 ~73 ~11 ~17 ~73 quartz_block 0  
fill ~8 ~17 ~74 ~11 ~17 ~74 quartz_block 0  
fill ~8 ~17 ~75 ~10 ~17 ~75 quartz_block 0  
fill ~8 ~17 ~76 ~10 ~17 ~76 quartz_block 0  
fill ~8 ~17 ~104 ~10 ~17 ~104 quartz_block 0  
fill ~8 ~17 ~105 ~10 ~17 ~105 quartz_block 0  
fill ~8 ~17 ~106 ~11 ~17 ~106 quartz_block 0  
fill ~8 ~17 ~107 ~11 ~17 ~107 quartz_block 0  
fill ~8 ~17 ~108 ~11 ~17 ~108 quartz_block 0  
fill ~9 ~17 ~68 ~12 ~17 ~68 quartz_block 0  
fill ~9 ~17 ~69 ~12 ~17 ~69 quartz_block 0  
fill ~9 ~17 ~70 ~12 ~17 ~70 quartz_block 0  
fill ~9 ~17 ~71 ~11 ~17 ~71 quartz_block 0  
fill ~9 ~17 ~109 ~11 ~17 ~109 quartz_block 0  
fill ~9 ~17 ~110 ~12 ~17 ~110 quartz_block 0  
fill ~9 ~17 ~111 ~12 ~17 ~111 quartz_block 0  
fill ~9 ~17 ~112 ~12 ~17 ~112 quartz_block 0  
fill ~10 ~17 ~65 ~13 ~17 ~65 quartz_block 0  
fill ~10 ~17 ~66 ~13 ~17 ~66 quartz_block 0  
fill ~10 ~17 ~67 ~12 ~17 ~67 quartz_block 0  
fill ~10 ~17 ~113 ~12 ~17 ~113 quartz_block 0  
fill ~10 ~17 ~114 ~13 ~17 ~114 quartz_block 0  
fill ~10 ~17 ~115 ~13 ~17 ~115 quartz_block 0  
fill ~11 ~17 ~62 ~14 ~17 ~62 quartz_block 0  
fill ~11 ~17 ~63 ~14 ~17 ~63 quartz_block 0  
fill ~11 ~17 ~64 ~13 ~17 ~64 quartz_block 0  
fill ~11 ~17 ~116 ~13 ~17 ~116 quartz_block 0  
fill ~11 ~17 ~117 ~14 ~17 ~117 quartz_block 0  
fill ~11 ~17 ~118 ~14 ~17 ~118 quartz_block 0  
fill ~12 ~17 ~59 ~15 ~17 ~59 quartz_block 0  
fill ~12 ~17 ~60 ~15 ~17 ~60 quartz_block 0  
fill ~12 ~17 ~61 ~14 ~17 ~61 quartz_block 0  
fill ~12 ~17 ~119 ~14 ~17 ~119 quartz_block 0  
fill ~12 ~17 ~120 ~15 ~17 ~120 quartz_block 0  
fill ~12 ~17 ~121 ~15 ~17 ~121 quartz_block 0  
fill ~13 ~17 ~57 ~16 ~17 ~57 quartz_block 0  
fill ~13 ~17 ~58 ~16 ~17 ~58 quartz_block 0  
fill ~13 ~17 ~122 ~16 ~17 ~122 quartz_block 0  
fill ~13 ~17 ~123 ~16 ~17 ~123 quartz_block 0  
fill ~14 ~17 ~55 ~17 ~17 ~55 quartz_block 0  
fill ~14 ~17 ~56 ~17 ~17 ~56 quartz_block 0  
fill ~14 ~17 ~124 ~17 ~17 ~124 quartz_block 0  
fill ~14 ~17 ~125 ~17 ~17 ~125 quartz_block 0  
fill ~15 ~17 ~53 ~18 ~17 ~53 quartz_block 0  
fill ~15 ~17 ~54 ~18 ~17 ~54 quartz_block 0  
fill ~15 ~17 ~126 ~18 ~17 ~126 quartz_block 0  
fill ~15 ~17 ~127 ~18 ~17 ~127 quartz_block 0  
fill ~16 ~17 ~51 ~19 ~17 ~51 quartz_block 0  
fill ~16 ~17 ~52 ~19 ~17 ~52 quartz_block 0  
fill ~16 ~17 ~128 ~19 ~17 ~128 quartz_block 0  
fill ~16 ~17 ~129 ~19 ~17 ~129 quartz_block 0  
fill ~17 ~17 ~49 ~20 ~17 ~49 quartz_block 0  
fill ~17 ~17 ~50 ~20 ~17 ~50 quartz_block 0  
fill ~17 ~17 ~130 ~20 ~17 ~130 quartz_block 0  
fill ~17 ~17 ~131 ~20 ~17 ~131 quartz_block 0  
fill ~18 ~17 ~47 ~21 ~17 ~47 quartz_block 0  
fill ~18 ~17 ~48 ~21 ~17 ~48 quartz_block 0  
fill ~18 ~17 ~132 ~21 ~17 ~132 quartz_block 0  
fill ~18 ~17 ~133 ~21 ~17 ~133 quartz_block 0  
fill ~19 ~17 ~46 ~22 ~17 ~46 quartz_block 0  
fill ~19 ~17 ~134 ~22 ~17 ~134 quartz_block 0  
fill ~20 ~17 ~44 ~23 ~17 ~44 quartz_block 0  
fill ~20 ~17 ~45 ~23 ~17 ~45 quartz_block 0  
fill ~20 ~17 ~82 ~23 ~17 ~82 quartz_block 0  
fill ~20 ~17 ~83 ~23 ~17 ~83 quartz_block 0  
fill ~20 ~17 ~84 ~23 ~17 ~84 quartz_block 0  
fill ~20 ~17 ~85 ~23 ~17 ~85 quartz_block 0  
fill ~20 ~17 ~86 ~23 ~17 ~86 quartz_block 0  
fill ~20 ~17 ~87 ~23 ~17 ~87 quartz_block 0  
fill ~20 ~17 ~88 ~23 ~17 ~88 quartz_block 0  
fill ~20 ~17 ~89 ~23 ~17 ~89 quartz_block 0  
fill ~20 ~17 ~90 ~23 ~17 ~90 quartz_block 0  
fill ~20 ~17 ~91 ~23 ~17 ~91 quartz_block 0  
fill ~20 ~17 ~92 ~23 ~17 ~92 quartz_block 0  
fill ~20 ~17 ~93 ~23 ~17 ~93 quartz_block 0  
fill ~20 ~17 ~94 ~23 ~17 ~94 quartz_block 0  
fill ~20 ~17 ~95 ~23 ~17 ~95 quartz_block 0  
fill ~20 ~17 ~96 ~23 ~17 ~96 quartz_block 0  
fill ~20 ~17 ~97 ~23 ~17 ~97 quartz_block 0  
fill ~20 ~17 ~98 ~23 ~17 ~98 quartz_block 0  
fill ~20 ~17 ~135 ~23 ~17 ~135 quartz_block 0  
fill ~20 ~17 ~136 ~23 ~17 ~136 quartz_block 0  
fill ~21 ~17 ~43 ~24 ~17 ~43 quartz_block 0  
fill ~21 ~17 ~76 ~24 ~17 ~76 quartz_block 0  
fill ~21 ~17 ~77 ~24 ~17 ~77 quartz_block 0  
fill ~21 ~17 ~78 ~24 ~17 ~78 quartz_block 0  
fill ~21 ~17 ~79 ~23 ~17 ~79 quartz_block 0  
fill ~21 ~17 ~80 ~23 ~17 ~80 quartz_block 0  
fill ~21 ~17 ~81 ~23 ~17 ~81 quartz_block 0  
fill ~21 ~17 ~99 ~23 ~17 ~99 quartz_block 0  
fill ~21 ~17 ~100 ~23 ~17 ~100 quartz_block 0  
fill ~21 ~17 ~101 ~23 ~17 ~101 quartz_block 0  
fill ~21 ~17 ~102 ~24 ~17 ~102 quartz_block 0  
fill ~21 ~17 ~103 ~24 ~17 ~103 quartz_block 0  
fill ~21 ~17 ~104 ~24 ~17 ~104 quartz_block 0  
fill ~21 ~17 ~137 ~24 ~17 ~137 quartz_block 0  
fill ~22 ~17 ~41 ~26 ~17 ~41 quartz_block 0  
fill ~22 ~17 ~42 ~25 ~17 ~42 quartz_block 0  
fill ~22 ~17 ~72 ~25 ~17 ~72 quartz_block 0  
fill ~22 ~17 ~73 ~25 ~17 ~73 quartz_block 0  
fill ~22 ~17 ~74 ~24 ~17 ~74 quartz_block 0  
fill ~22 ~17 ~75 ~24 ~17 ~75 quartz_block 0  
fill ~22 ~17 ~105 ~24 ~17 ~105 quartz_block 0  
fill ~22 ~17 ~106 ~24 ~17 ~106 quartz_block 0  
fill ~22 ~17 ~107 ~25 ~17 ~107 quartz_block 0  
fill ~22 ~17 ~108 ~25 ~17 ~108 quartz_block 0  
fill ~22 ~17 ~138 ~25 ~17 ~138 quartz_block 0  
fill ~22 ~17 ~139 ~26 ~17 ~139 quartz_block 0  
fill ~23 ~17 ~40 ~26 ~17 ~40 quartz_block 0  
fill ~23 ~17 ~69 ~26 ~17 ~69 quartz_block 0  
fill ~23 ~17 ~70 ~26 ~17 ~70 quartz_block 0  
fill ~23 ~17 ~71 ~25 ~17 ~71 quartz_block 0  
fill ~23 ~17 ~109 ~25 ~17 ~109 quartz_block 0  
fill ~23 ~17 ~110 ~26 ~17 ~110 quartz_block 0  
fill ~23 ~17 ~111 ~26 ~17 ~111 quartz_block 0  
fill ~23 ~17 ~140 ~26 ~17 ~140 quartz_block 0  
fill ~24 ~17 ~38 ~28 ~17 ~38 quartz_block 0  
fill ~24 ~17 ~39 ~27 ~17 ~39 quartz_block 0  
fill ~24 ~17 ~66 ~27 ~17 ~66 quartz_block 0  
fill ~24 ~17 ~67 ~27 ~17 ~67 quartz_block 0  
fill ~24 ~17 ~68 ~26 ~17 ~68 quartz_block 0  
fill ~24 ~17 ~112 ~26 ~17 ~112 quartz_block 0  
fill ~24 ~17 ~113 ~27 ~17 ~113 quartz_block 0  
fill ~24 ~17 ~114 ~27 ~17 ~114 quartz_block 0  
fill ~24 ~17 ~141 ~27 ~17 ~141 quartz_block 0  
fill ~24 ~17 ~142 ~28 ~17 ~142 quartz_block 0  
fill ~25 ~17 ~37 ~29 ~17 ~37 quartz_block 0  
fill ~25 ~17 ~63 ~28 ~17 ~63 quartz_block 0  
fill ~25 ~17 ~64 ~28 ~17 ~64 quartz_block 0  
fill ~25 ~17 ~65 ~27 ~17 ~65 quartz_block 0  
fill ~25 ~17 ~115 ~27 ~17 ~115 quartz_block 0  
fill ~25 ~17 ~116 ~28 ~17 ~116 quartz_block 0  
fill ~25 ~17 ~117 ~28 ~17 ~117 quartz_block 0  
fill ~25 ~17 ~143 ~29 ~17 ~143 quartz_block 0  
fill ~26 ~17 ~36 ~30 ~17 ~36 quartz_block 0  
fill ~26 ~17 ~61 ~29 ~17 ~61 quartz_block 0  
fill ~26 ~17 ~62 ~29 ~17 ~62 quartz_block 0  
fill ~26 ~17 ~118 ~29 ~17 ~118 quartz_block 0  
fill ~26 ~17 ~119 ~29 ~17 ~119 quartz_block 0  
fill ~26 ~17 ~144 ~30 ~17 ~144 quartz_block 0  
fill ~27 ~17 ~35 ~31 ~17 ~35 quartz_block 0  
fill ~27 ~17 ~59 ~30 ~17 ~59 quartz_block 0  
fill ~27 ~17 ~60 ~30 ~17 ~60 quartz_block 0  
fill ~27 ~17 ~120 ~30 ~17 ~120 quartz_block 0  
fill ~27 ~17 ~121 ~30 ~17 ~121 quartz_block 0  
fill ~27 ~17 ~145 ~31 ~17 ~145 quartz_block 0  
fill ~28 ~17 ~34 ~32 ~17 ~34 quartz_block 0  
fill ~28 ~17 ~57 ~31 ~17 ~57 quartz_block 0  
fill ~28 ~17 ~58 ~31 ~17 ~58 quartz_block 0  
fill ~28 ~17 ~122 ~31 ~17 ~122 quartz_block 0  
fill ~28 ~17 ~123 ~31 ~17 ~123 quartz_block 0  
fill ~28 ~17 ~146 ~32 ~17 ~146 quartz_block 0  
fill ~29 ~17 ~33 ~33 ~17 ~33 quartz_block 0  
fill ~29 ~17 ~55 ~32 ~17 ~55 quartz_block 0  
fill ~29 ~17 ~56 ~32 ~17 ~56 quartz_block 0  
fill ~29 ~17 ~124 ~32 ~17 ~124 quartz_block 0  
fill ~29 ~17 ~125 ~32 ~17 ~125 quartz_block 0  
fill ~29 ~17 ~147 ~33 ~17 ~147 quartz_block 0  
fill ~30 ~17 ~32 ~34 ~17 ~32 quartz_block 0  
fill ~30 ~17 ~53 ~34 ~17 ~53 quartz_block 0  
fill ~30 ~17 ~54 ~33 ~17 ~54 quartz_block 0  
fill ~30 ~17 ~126 ~33 ~17 ~126 quartz_block 0  
fill ~30 ~17 ~127 ~34 ~17 ~127 quartz_block 0  
fill ~30 ~17 ~148 ~34 ~17 ~148 quartz_block 0  
fill ~31 ~17 ~31 ~35 ~17 ~31 quartz_block 0  
fill ~31 ~17 ~52 ~34 ~17 ~52 quartz_block 0  
fill ~31 ~17 ~128 ~34 ~17 ~128 quartz_block 0  
fill ~31 ~17 ~149 ~35 ~17 ~149 quartz_block 0  
fill ~32 ~17 ~30 ~36 ~17 ~30 quartz_block 0  
fill ~32 ~17 ~50 ~36 ~17 ~50 quartz_block 0  
fill ~32 ~17 ~51 ~35 ~17 ~51 quartz_block 0  
fill ~32 ~17 ~129 ~35 ~17 ~129 quartz_block 0  
fill ~32 ~17 ~130 ~36 ~17 ~130 quartz_block 0  
fill ~32 ~17 ~150 ~36 ~17 ~150 quartz_block 0  
fill ~33 ~17 ~29 ~37 ~17 ~29 quartz_block 0  
fill ~33 ~17 ~49 ~37 ~17 ~49 quartz_block 0  
fill ~33 ~17 ~131 ~37 ~17 ~131 quartz_block 0  
fill ~33 ~17 ~151 ~37 ~17 ~151 quartz_block 0  
fill ~34 ~17 ~28 ~38 ~17 ~28 quartz_block 0  
fill ~34 ~17 ~48 ~37 ~17 ~48 quartz_block 0  
fill ~34 ~17 ~132 ~37 ~17 ~132 quartz_block 0  
fill ~34 ~17 ~152 ~38 ~17 ~152 quartz_block 0  
fill ~35 ~17 ~27 ~39 ~17 ~27 quartz_block 0  
fill ~35 ~17 ~47 ~38 ~17 ~47 quartz_block 0  
fill ~35 ~17 ~133 ~38 ~17 ~133 quartz_block 0  
fill ~35 ~17 ~134 ~39 ~17 ~134 quartz_block 0  
fill ~35 ~17 ~153 ~39 ~17 ~153 quartz_block 0  
fill ~36 ~17 ~26 ~41 ~17 ~26 quartz_block 0  
fill ~36 ~17 ~45 ~40 ~17 ~45 quartz_block 0  
fill ~36 ~17 ~46 ~39 ~17 ~46 quartz_block 0  
fill ~36 ~17 ~135 ~40 ~17 ~135 quartz_block 0  
fill ~36 ~17 ~154 ~41 ~17 ~154 quartz_block 0  
fill ~37 ~17 ~25 ~42 ~17 ~25 quartz_block 0  
fill ~37 ~17 ~44 ~41 ~17 ~44 quartz_block 0  
fill ~37 ~17 ~136 ~41 ~17 ~136 quartz_block 0  
fill ~37 ~17 ~155 ~42 ~17 ~155 quartz_block 0  
fill ~38 ~17 ~24 ~43 ~17 ~24 quartz_block 0  
fill ~38 ~17 ~43 ~42 ~17 ~43 quartz_block 0  
fill ~38 ~17 ~137 ~42 ~17 ~137 quartz_block 0  
fill ~38 ~17 ~156 ~43 ~17 ~156 quartz_block 0  
fill ~39 ~17 ~42 ~43 ~17 ~42 quartz_block 0  
fill ~39 ~17 ~138 ~43 ~17 ~138 quartz_block 0  
fill ~40 ~17 ~23 ~45 ~17 ~23 quartz_block 0  
fill ~40 ~17 ~41 ~44 ~17 ~41 quartz_block 0  
fill ~40 ~17 ~139 ~44 ~17 ~139 quartz_block 0  
fill ~40 ~17 ~157 ~45 ~17 ~157 quartz_block 0  
fill ~41 ~17 ~22 ~46 ~17 ~22 quartz_block 0  
fill ~41 ~17 ~40 ~45 ~17 ~40 quartz_block 0  
fill ~41 ~17 ~140 ~45 ~17 ~140 quartz_block 0  
fill ~41 ~17 ~158 ~46 ~17 ~158 quartz_block 0  
fill ~42 ~17 ~39 ~46 ~17 ~39 quartz_block 0  
fill ~42 ~17 ~141 ~46 ~17 ~141 quartz_block 0  
fill ~43 ~17 ~21 ~48 ~17 ~21 quartz_block 0  
fill ~43 ~17 ~38 ~47 ~17 ~38 quartz_block 0  
fill ~43 ~17 ~142 ~47 ~17 ~142 quartz_block 0  
fill ~43 ~17 ~159 ~48 ~17 ~159 quartz_block 0  
fill ~44 ~17 ~20 ~50 ~17 ~20 quartz_block 0  
fill ~44 ~17 ~37 ~49 ~17 ~37 quartz_block 0  
fill ~44 ~17 ~143 ~49 ~17 ~143 quartz_block 0  
fill ~44 ~17 ~160 ~50 ~17 ~160 quartz_block 0  
fill ~45 ~17 ~36 ~50 ~17 ~36 quartz_block 0  
fill ~45 ~17 ~144 ~50 ~17 ~144 quartz_block 0  
fill ~46 ~17 ~19 ~52 ~17 ~19 quartz_block 0  
fill ~46 ~17 ~35 ~51 ~17 ~35 quartz_block 0  
fill ~46 ~17 ~145 ~51 ~17 ~145 quartz_block 0  
fill ~46 ~17 ~161 ~52 ~17 ~161 quartz_block 0  
fill ~47 ~17 ~18 ~54 ~17 ~18 quartz_block 0  
fill ~47 ~17 ~162 ~54 ~17 ~162 quartz_block 0  
fill ~48 ~17 ~34 ~53 ~17 ~34 quartz_block 0  
fill ~48 ~17 ~146 ~53 ~17 ~146 quartz_block 0  
fill ~49 ~17 ~17 ~56 ~17 ~17 quartz_block 0  
fill ~49 ~17 ~33 ~54 ~17 ~33 quartz_block 0  
fill ~49 ~17 ~147 ~54 ~17 ~147 quartz_block 0  
fill ~49 ~17 ~163 ~56 ~17 ~163 quartz_block 0  
fill ~50 ~17 ~32 ~56 ~17 ~32 quartz_block 0  
fill ~50 ~17 ~148 ~56 ~17 ~148 quartz_block 0  
fill ~51 ~17 ~16 ~58 ~17 ~16 quartz_block 0  
fill ~51 ~17 ~164 ~58 ~17 ~164 quartz_block 0  
fill ~52 ~17 ~31 ~58 ~17 ~31 quartz_block 0  
fill ~52 ~17 ~149 ~58 ~17 ~149 quartz_block 0  
fill ~53 ~17 ~15 ~60 ~17 ~15 quartz_block 0  
fill ~53 ~17 ~30 ~60 ~17 ~30 quartz_block 0  
fill ~53 ~17 ~150 ~60 ~17 ~150 quartz_block 0  
fill ~53 ~17 ~165 ~60 ~17 ~165 quartz_block 0  
fill ~55 ~17 ~14 ~63 ~17 ~14 quartz_block 0  
fill ~55 ~17 ~29 ~62 ~17 ~29 quartz_block 0  
fill ~55 ~17 ~151 ~62 ~17 ~151 quartz_block 0  
fill ~55 ~17 ~166 ~63 ~17 ~166 quartz_block 0  
fill ~57 ~17 ~13 ~66 ~17 ~13 quartz_block 0  
fill ~57 ~17 ~28 ~64 ~17 ~28 quartz_block 0  
fill ~57 ~17 ~152 ~64 ~17 ~152 quartz_block 0  
fill ~57 ~17 ~167 ~66 ~17 ~167 quartz_block 0  
fill ~59 ~17 ~12 ~70 ~17 ~12 quartz_block 0  
fill ~59 ~17 ~27 ~67 ~17 ~27 quartz_block 0  
fill ~59 ~17 ~153 ~67 ~17 ~153 quartz_block 0  
fill ~59 ~17 ~168 ~70 ~17 ~168 quartz_block 0  
fill ~61 ~17 ~26 ~70 ~17 ~26 quartz_block 0  
fill ~61 ~17 ~154 ~70 ~17 ~154 quartz_block 0  
fill ~62 ~17 ~11 ~74 ~17 ~11 quartz_block 0  
fill ~62 ~17 ~169 ~74 ~17 ~169 quartz_block 0  
fill ~63 ~17 ~25 ~73 ~17 ~25 quartz_block 0  
fill ~63 ~17 ~155 ~73 ~17 ~155 quartz_block 0  
fill ~65 ~17 ~10 ~81 ~17 ~10 quartz_block 0  
fill ~65 ~17 ~170 ~81 ~17 ~170 quartz_block 0  
fill ~66 ~17 ~24 ~78 ~17 ~24 quartz_block 0  
fill ~66 ~17 ~156 ~78 ~17 ~156 quartz_block 0  
fill ~68 ~17 ~9 ~112 ~17 ~9 quartz_block 0  
fill ~68 ~17 ~171 ~112 ~17 ~171 quartz_block 0  
fill ~69 ~17 ~23 ~111 ~17 ~23 quartz_block 0  
fill ~69 ~17 ~157 ~111 ~17 ~157 quartz_block 0  
fill ~72 ~17 ~8 ~108 ~17 ~8 quartz_block 0  
fill ~72 ~17 ~22 ~108 ~17 ~22 quartz_block 0  
fill ~72 ~17 ~158 ~108 ~17 ~158 quartz_block 0  
fill ~72 ~17 ~172 ~108 ~17 ~172 quartz_block 0  
fill ~73 ~17 ~96 ~74 ~17 ~96 quartz_block 0  
fill ~73 ~17 ~97 ~74 ~17 ~97 quartz_block 0  
fill ~74 ~17 ~92 ~74 ~24 ~92 quartz_block 0  
fill ~74 ~17 ~98 ~75 ~17 ~98 quartz_block 0  
fill ~74 ~17 ~99 ~76 ~17 ~99 quartz_block 0  
fill ~75 ~17 ~100 ~78 ~17 ~100 quartz_block 0  
fill ~76 ~17 ~21 ~104 ~17 ~21 quartz_block 0  
fill ~76 ~17 ~80 ~77 ~17 ~80 quartz_block 0  
fill ~76 ~17 ~81 ~76 ~20 ~81 quartz_block 0  
fill ~76 ~17 ~159 ~104 ~17 ~159 quartz_block 0  
fill ~77 ~17 ~7 ~103 ~17 ~7 quartz_block 0  
fill ~77 ~17 ~173 ~103 ~17 ~173 quartz_block 0  
fill ~78 ~17 ~78 ~85 ~17 ~78 quartz_block 0  
fill ~79 ~17 ~103 ~84 ~17 ~103 quartz_block 0  
fill ~80 ~17 ~102 ~80 ~28 ~102 quartz_block 0  
fill ~82 ~17 ~20 ~98 ~17 ~20 quartz_block 0  
fill ~82 ~17 ~104 ~87 ~17 ~104 quartz_block 0  
fill ~82 ~17 ~160 ~97 ~17 ~160 quartz_block 0  
fill ~84 ~17 ~77 ~92 ~17 ~77 quartz_block 0  
fill ~84 ~17 ~105 ~95 ~17 ~105 quartz_block 0  
fill ~86 ~17 ~76 ~93 ~17 ~76 quartz_block 0  
fill ~88 ~17 ~6 ~92 ~17 ~6 quartz_block 0  
fill ~88 ~17 ~174 ~92 ~17 ~174 quartz_block 0  
fill ~92 ~17 ~104 ~97 ~17 ~104 quartz_block 0  
fill ~94 ~17 ~77 ~95 ~17 ~77 quartz_block 0  
fill ~95 ~17 ~78 ~100 ~17 ~78 quartz_block 0  
fill ~97 ~17 ~103 ~100 ~17 ~103 quartz_block 0  
fill ~99 ~17 ~10 ~115 ~17 ~10 quartz_block 0  
fill ~99 ~17 ~79 ~102 ~17 ~79 quartz_block 0  
fill ~99 ~17 ~102 ~99 ~20 ~102 quartz_block 0  
fill ~99 ~17 ~170 ~115 ~17 ~170 quartz_block 0  
fill ~100 ~17 ~101 ~102 ~17 ~101 quartz_block 0  
fill ~101 ~17 ~80 ~103 ~17 ~80 quartz_block 0  
fill ~102 ~17 ~24 ~114 ~17 ~24 quartz_block 0  
fill ~102 ~17 ~156 ~114 ~17 ~156 quartz_block 0  
fill ~103 ~17 ~81 ~103 ~32 ~81 quartz_block 0 
setblock ~104 ~17 ~82 quartz_block 0  
fill ~104 ~17 ~87 ~104 ~20 ~87 quartz_block 0  
fill ~104 ~17 ~97 ~104 ~21 ~97 quartz_block 0  
fill ~104 ~17 ~99 ~104 ~83 ~99 quartz_block 0  
fill ~106 ~17 ~11 ~118 ~17 ~11 quartz_block 0  
fill ~106 ~17 ~169 ~118 ~17 ~169 quartz_block 0  
fill ~107 ~17 ~25 ~117 ~17 ~25 quartz_block 0  
fill ~107 ~17 ~155 ~117 ~17 ~155 quartz_block 0  
fill ~110 ~17 ~12 ~121 ~17 ~12 quartz_block 0  
fill ~110 ~17 ~26 ~119 ~17 ~26 quartz_block 0  
fill ~110 ~17 ~154 ~119 ~17 ~154 quartz_block 0  
fill ~110 ~17 ~168 ~121 ~17 ~168 quartz_block 0  
fill ~113 ~17 ~27 ~121 ~17 ~27 quartz_block 0  
fill ~113 ~17 ~153 ~121 ~17 ~153 quartz_block 0  
fill ~114 ~17 ~13 ~123 ~17 ~13 quartz_block 0  
fill ~114 ~17 ~167 ~123 ~17 ~167 quartz_block 0  
fill ~116 ~17 ~28 ~123 ~17 ~28 quartz_block 0  
fill ~116 ~17 ~152 ~123 ~17 ~152 quartz_block 0  
fill ~117 ~17 ~14 ~125 ~17 ~14 quartz_block 0  
fill ~117 ~17 ~166 ~125 ~17 ~166 quartz_block 0  
fill ~118 ~17 ~29 ~125 ~17 ~29 quartz_block 0  
fill ~118 ~17 ~151 ~125 ~17 ~151 quartz_block 0  
fill ~120 ~17 ~15 ~127 ~17 ~15 quartz_block 0  
fill ~120 ~17 ~30 ~127 ~17 ~30 quartz_block 0  
fill ~120 ~17 ~150 ~127 ~17 ~150 quartz_block 0  
fill ~120 ~17 ~165 ~127 ~17 ~165 quartz_block 0  
fill ~122 ~17 ~16 ~129 ~17 ~16 quartz_block 0  
fill ~122 ~17 ~31 ~128 ~17 ~31 quartz_block 0  
fill ~122 ~17 ~149 ~128 ~17 ~149 quartz_block 0  
fill ~122 ~17 ~164 ~129 ~17 ~164 quartz_block 0  
fill ~124 ~17 ~17 ~131 ~17 ~17 quartz_block 0  
fill ~124 ~17 ~32 ~130 ~17 ~32 quartz_block 0  
fill ~124 ~17 ~148 ~130 ~17 ~148 quartz_block 0  
fill ~124 ~17 ~163 ~131 ~17 ~163 quartz_block 0  
fill ~126 ~17 ~18 ~133 ~17 ~18 quartz_block 0  
fill ~126 ~17 ~33 ~131 ~17 ~33 quartz_block 0  
fill ~126 ~17 ~147 ~131 ~17 ~147 quartz_block 0  
fill ~126 ~17 ~162 ~133 ~17 ~162 quartz_block 0  
fill ~127 ~17 ~34 ~132 ~17 ~34 quartz_block 0  
fill ~127 ~17 ~146 ~132 ~17 ~146 quartz_block 0  
fill ~128 ~17 ~19 ~134 ~17 ~19 quartz_block 0  
fill ~128 ~17 ~161 ~134 ~17 ~161 quartz_block 0  
fill ~129 ~17 ~35 ~134 ~17 ~35 quartz_block 0  
fill ~129 ~17 ~145 ~134 ~17 ~145 quartz_block 0  
fill ~130 ~17 ~20 ~136 ~17 ~20 quartz_block 0  
fill ~130 ~17 ~36 ~135 ~17 ~36 quartz_block 0  
fill ~130 ~17 ~144 ~135 ~17 ~144 quartz_block 0  
fill ~130 ~17 ~160 ~136 ~17 ~160 quartz_block 0  
fill ~131 ~17 ~37 ~136 ~17 ~37 quartz_block 0  
fill ~131 ~17 ~143 ~136 ~17 ~143 quartz_block 0  
fill ~132 ~17 ~21 ~137 ~17 ~21 quartz_block 0  
fill ~132 ~17 ~159 ~137 ~17 ~159 quartz_block 0  
fill ~133 ~17 ~38 ~137 ~17 ~38 quartz_block 0  
fill ~133 ~17 ~142 ~137 ~17 ~142 quartz_block 0  
fill ~134 ~17 ~22 ~139 ~17 ~22 quartz_block 0  
fill ~134 ~17 ~39 ~138 ~17 ~39 quartz_block 0  
fill ~134 ~17 ~141 ~138 ~17 ~141 quartz_block 0  
fill ~134 ~17 ~158 ~139 ~17 ~158 quartz_block 0  
fill ~135 ~17 ~23 ~140 ~17 ~23 quartz_block 0  
fill ~135 ~17 ~40 ~139 ~17 ~40 quartz_block 0  
fill ~135 ~17 ~140 ~139 ~17 ~140 quartz_block 0  
fill ~135 ~17 ~157 ~140 ~17 ~157 quartz_block 0  
fill ~136 ~17 ~41 ~140 ~17 ~41 quartz_block 0  
fill ~136 ~17 ~139 ~140 ~17 ~139 quartz_block 0  
fill ~137 ~17 ~24 ~142 ~17 ~24 quartz_block 0  
fill ~137 ~17 ~42 ~141 ~17 ~42 quartz_block 0  
fill ~137 ~17 ~138 ~141 ~17 ~138 quartz_block 0  
fill ~137 ~17 ~156 ~142 ~17 ~156 quartz_block 0  
fill ~138 ~17 ~25 ~143 ~17 ~25 quartz_block 0  
fill ~138 ~17 ~43 ~142 ~17 ~43 quartz_block 0  
fill ~138 ~17 ~137 ~142 ~17 ~137 quartz_block 0  
fill ~138 ~17 ~155 ~143 ~17 ~155 quartz_block 0  
fill ~139 ~17 ~26 ~144 ~17 ~26 quartz_block 0  
fill ~139 ~17 ~44 ~143 ~17 ~44 quartz_block 0  
fill ~139 ~17 ~136 ~143 ~17 ~136 quartz_block 0  
fill ~139 ~17 ~154 ~144 ~17 ~154 quartz_block 0  
fill ~140 ~17 ~45 ~144 ~17 ~45 quartz_block 0  
fill ~140 ~17 ~135 ~144 ~17 ~135 quartz_block 0  
fill ~141 ~17 ~27 ~145 ~17 ~27 quartz_block 0  
fill ~141 ~17 ~46 ~145 ~17 ~46 quartz_block 0  
fill ~141 ~17 ~134 ~145 ~17 ~134 quartz_block 0  
fill ~141 ~17 ~153 ~145 ~17 ~153 quartz_block 0  
fill ~142 ~17 ~28 ~146 ~17 ~28 quartz_block 0  
fill ~142 ~17 ~47 ~145 ~17 ~47 quartz_block 0  
fill ~142 ~17 ~133 ~145 ~17 ~133 quartz_block 0  
fill ~142 ~17 ~152 ~146 ~17 ~152 quartz_block 0  
fill ~143 ~17 ~29 ~147 ~17 ~29 quartz_block 0  
fill ~143 ~17 ~48 ~146 ~17 ~48 quartz_block 0  
fill ~143 ~17 ~49 ~147 ~17 ~49 quartz_block 0  
fill ~143 ~17 ~131 ~147 ~17 ~131 quartz_block 0  
fill ~143 ~17 ~132 ~146 ~17 ~132 quartz_block 0  
fill ~143 ~17 ~151 ~147 ~17 ~151 quartz_block 0  
fill ~144 ~17 ~30 ~148 ~17 ~30 quartz_block 0  
fill ~144 ~17 ~50 ~148 ~17 ~50 quartz_block 0  
fill ~144 ~17 ~130 ~148 ~17 ~130 quartz_block 0  
fill ~144 ~17 ~150 ~148 ~17 ~150 quartz_block 0  
fill ~145 ~17 ~31 ~149 ~17 ~31 quartz_block 0  
fill ~145 ~17 ~51 ~148 ~17 ~51 quartz_block 0  
fill ~145 ~17 ~129 ~148 ~17 ~129 quartz_block 0  
fill ~145 ~17 ~149 ~149 ~17 ~149 quartz_block 0  
fill ~146 ~17 ~32 ~150 ~17 ~32 quartz_block 0  
fill ~146 ~17 ~52 ~149 ~17 ~52 quartz_block 0  
fill ~146 ~17 ~53 ~150 ~17 ~53 quartz_block 0  
fill ~146 ~17 ~127 ~150 ~17 ~127 quartz_block 0  
fill ~146 ~17 ~128 ~149 ~17 ~128 quartz_block 0  
fill ~146 ~17 ~148 ~150 ~17 ~148 quartz_block 0  
fill ~147 ~17 ~33 ~151 ~17 ~33 quartz_block 0  
fill ~147 ~17 ~54 ~150 ~17 ~54 quartz_block 0  
fill ~147 ~17 ~126 ~150 ~17 ~126 quartz_block 0  
fill ~147 ~17 ~147 ~151 ~17 ~147 quartz_block 0  
fill ~148 ~17 ~34 ~152 ~17 ~34 quartz_block 0  
fill ~148 ~17 ~55 ~151 ~17 ~55 quartz_block 0  
fill ~148 ~17 ~56 ~151 ~17 ~56 quartz_block 0  
fill ~148 ~17 ~124 ~151 ~17 ~124 quartz_block 0  
fill ~148 ~17 ~125 ~151 ~17 ~125 quartz_block 0  
fill ~148 ~17 ~146 ~152 ~17 ~146 quartz_block 0  
fill ~149 ~17 ~35 ~153 ~17 ~35 quartz_block 0  
fill ~149 ~17 ~57 ~152 ~17 ~57 quartz_block 0  
fill ~149 ~17 ~58 ~152 ~17 ~58 quartz_block 0  
fill ~149 ~17 ~122 ~152 ~17 ~122 quartz_block 0  
fill ~149 ~17 ~123 ~152 ~17 ~123 quartz_block 0  
fill ~149 ~17 ~145 ~153 ~17 ~145 quartz_block 0  
fill ~150 ~17 ~36 ~154 ~17 ~36 quartz_block 0  
fill ~150 ~17 ~59 ~153 ~17 ~59 quartz_block 0  
fill ~150 ~17 ~60 ~153 ~17 ~60 quartz_block 0  
fill ~150 ~17 ~120 ~153 ~17 ~120 quartz_block 0  
fill ~150 ~17 ~121 ~153 ~17 ~121 quartz_block 0  
fill ~150 ~17 ~144 ~154 ~17 ~144 quartz_block 0  
fill ~151 ~17 ~37 ~155 ~17 ~37 quartz_block 0  
fill ~151 ~17 ~61 ~154 ~17 ~61 quartz_block 0  
fill ~151 ~17 ~62 ~154 ~17 ~62 quartz_block 0  
fill ~151 ~17 ~118 ~154 ~17 ~118 quartz_block 0  
fill ~151 ~17 ~119 ~154 ~17 ~119 quartz_block 0  
fill ~151 ~17 ~143 ~155 ~17 ~143 quartz_block 0  
fill ~152 ~17 ~38 ~156 ~17 ~38 quartz_block 0  
fill ~152 ~17 ~63 ~155 ~17 ~63 quartz_block 0  
fill ~152 ~17 ~64 ~155 ~17 ~64 quartz_block 0  
fill ~152 ~17 ~116 ~155 ~17 ~116 quartz_block 0  
fill ~152 ~17 ~117 ~155 ~17 ~117 quartz_block 0  
fill ~152 ~17 ~142 ~156 ~17 ~142 quartz_block 0  
fill ~153 ~17 ~39 ~156 ~17 ~39 quartz_block 0  
fill ~153 ~17 ~65 ~156 ~17 ~65 quartz_block 0  
fill ~153 ~17 ~66 ~156 ~17 ~66 quartz_block 0  
fill ~153 ~17 ~67 ~156 ~17 ~67 quartz_block 0  
fill ~153 ~17 ~113 ~156 ~17 ~113 quartz_block 0  
fill ~153 ~17 ~114 ~156 ~17 ~114 quartz_block 0  
fill ~153 ~17 ~115 ~155 ~17 ~115 quartz_block 0  
fill ~153 ~17 ~141 ~156 ~17 ~141 quartz_block 0  
fill ~154 ~17 ~40 ~157 ~17 ~40 quartz_block 0  
fill ~154 ~17 ~41 ~158 ~17 ~41 quartz_block 0  
fill ~154 ~17 ~68 ~156 ~17 ~68 quartz_block 0  
fill ~154 ~17 ~69 ~157 ~17 ~69 quartz_block 0  
fill ~154 ~17 ~70 ~157 ~17 ~70 quartz_block 0  
fill ~154 ~17 ~110 ~157 ~17 ~110 quartz_block 0  
fill ~154 ~17 ~111 ~157 ~17 ~111 quartz_block 0  
fill ~154 ~17 ~112 ~156 ~17 ~112 quartz_block 0  
fill ~154 ~17 ~139 ~158 ~17 ~139 quartz_block 0  
fill ~154 ~17 ~140 ~157 ~17 ~140 quartz_block 0  
fill ~155 ~17 ~42 ~158 ~17 ~42 quartz_block 0  
fill ~155 ~17 ~71 ~157 ~17 ~71 quartz_block 0  
fill ~155 ~17 ~72 ~158 ~17 ~72 quartz_block 0  
fill ~155 ~17 ~73 ~158 ~17 ~73 quartz_block 0  
fill ~155 ~17 ~107 ~158 ~17 ~107 quartz_block 0  
fill ~155 ~17 ~108 ~158 ~17 ~108 quartz_block 0  
fill ~155 ~17 ~109 ~157 ~17 ~109 quartz_block 0  
fill ~155 ~17 ~138 ~158 ~17 ~138 quartz_block 0  
fill ~156 ~17 ~43 ~159 ~17 ~43 quartz_block 0  
fill ~156 ~17 ~74 ~158 ~17 ~74 quartz_block 0  
fill ~156 ~17 ~75 ~158 ~17 ~75 quartz_block 0  
fill ~156 ~17 ~76 ~159 ~17 ~76 quartz_block 0  
fill ~156 ~17 ~77 ~159 ~17 ~77 quartz_block 0  
fill ~156 ~17 ~78 ~159 ~17 ~78 quartz_block 0  
fill ~156 ~17 ~102 ~159 ~17 ~102 quartz_block 0  
fill ~156 ~17 ~103 ~159 ~17 ~103 quartz_block 0  
fill ~156 ~17 ~104 ~159 ~17 ~104 quartz_block 0  
fill ~156 ~17 ~105 ~158 ~17 ~105 quartz_block 0  
fill ~156 ~17 ~106 ~158 ~17 ~106 quartz_block 0  
fill ~156 ~17 ~137 ~159 ~17 ~137 quartz_block 0  
fill ~157 ~17 ~44 ~160 ~17 ~44 quartz_block 0  
fill ~157 ~17 ~45 ~160 ~17 ~45 quartz_block 0  
fill ~157 ~17 ~79 ~159 ~17 ~79 quartz_block 0  
fill ~157 ~17 ~80 ~159 ~17 ~80 quartz_block 0  
fill ~157 ~17 ~81 ~159 ~17 ~81 quartz_block 0  
fill ~157 ~17 ~82 ~159 ~17 ~82 quartz_block 0  
fill ~157 ~17 ~83 ~160 ~17 ~83 quartz_block 0  
fill ~157 ~17 ~84 ~160 ~17 ~84 quartz_block 0  
fill ~157 ~17 ~85 ~160 ~17 ~85 quartz_block 0  
fill ~157 ~17 ~86 ~160 ~17 ~86 quartz_block 0  
fill ~157 ~17 ~87 ~160 ~17 ~87 quartz_block 0  
fill ~157 ~17 ~88 ~160 ~17 ~88 quartz_block 0  
fill ~157 ~17 ~89 ~160 ~17 ~89 quartz_block 0  
fill ~157 ~17 ~90 ~160 ~17 ~90 quartz_block 0  
fill ~157 ~17 ~91 ~160 ~17 ~91 quartz_block 0  
fill ~157 ~17 ~92 ~160 ~17 ~92 quartz_block 0  
fill ~157 ~17 ~93 ~160 ~17 ~93 quartz_block 0  
fill ~157 ~17 ~94 ~160 ~17 ~94 quartz_block 0  
fill ~157 ~17 ~95 ~160 ~17 ~95 quartz_block 0  
fill ~157 ~17 ~96 ~160 ~17 ~96 quartz_block 0  
fill ~157 ~17 ~97 ~160 ~17 ~97 quartz_block 0  
fill ~157 ~17 ~98 ~160 ~17 ~98 quartz_block 0  
fill ~157 ~17 ~99 ~159 ~17 ~99 quartz_block 0  
fill ~157 ~17 ~100 ~159 ~17 ~100 quartz_block 0  
fill ~157 ~17 ~101 ~159 ~17 ~101 quartz_block 0  
fill ~157 ~17 ~135 ~160 ~17 ~135 quartz_block 0  
fill ~157 ~17 ~136 ~160 ~17 ~136 quartz_block 0  
fill ~158 ~17 ~46 ~161 ~17 ~46 quartz_block 0  
fill ~158 ~17 ~134 ~161 ~17 ~134 quartz_block 0  
fill ~159 ~17 ~47 ~162 ~17 ~47 quartz_block 0  
fill ~159 ~17 ~48 ~162 ~17 ~48 quartz_block 0  
fill ~159 ~17 ~132 ~162 ~17 ~132 quartz_block 0  
fill ~159 ~17 ~133 ~162 ~17 ~133 quartz_block 0  
fill ~160 ~17 ~49 ~163 ~17 ~49 quartz_block 0  
fill ~160 ~17 ~50 ~163 ~17 ~50 quartz_block 0  
fill ~160 ~17 ~130 ~163 ~17 ~130 quartz_block 0  
fill ~160 ~17 ~131 ~163 ~17 ~131 quartz_block 0  
fill ~161 ~17 ~51 ~164 ~17 ~51 quartz_block 0  
fill ~161 ~17 ~52 ~164 ~17 ~52 quartz_block 0  
fill ~161 ~17 ~128 ~164 ~17 ~128 quartz_block 0  
fill ~161 ~17 ~129 ~164 ~17 ~129 quartz_block 0  
fill ~162 ~17 ~53 ~165 ~17 ~53 quartz_block 0  
fill ~162 ~17 ~54 ~165 ~17 ~54 quartz_block 0  
fill ~162 ~17 ~126 ~165 ~17 ~126 quartz_block 0  
fill ~162 ~17 ~127 ~165 ~17 ~127 quartz_block 0  
fill ~163 ~17 ~55 ~166 ~17 ~55 quartz_block 0  
fill ~163 ~17 ~56 ~166 ~17 ~56 quartz_block 0  
fill ~163 ~17 ~124 ~166 ~17 ~124 quartz_block 0  
fill ~163 ~17 ~125 ~166 ~17 ~125 quartz_block 0  
fill ~164 ~17 ~57 ~167 ~17 ~57 quartz_block 0  
fill ~164 ~17 ~58 ~167 ~17 ~58 quartz_block 0  
fill ~164 ~17 ~122 ~167 ~17 ~122 quartz_block 0  
fill ~164 ~17 ~123 ~167 ~17 ~123 quartz_block 0  
fill ~165 ~17 ~59 ~168 ~17 ~59 quartz_block 0  
fill ~165 ~17 ~60 ~168 ~17 ~60 quartz_block 0  
fill ~165 ~17 ~120 ~168 ~17 ~120 quartz_block 0  
fill ~165 ~17 ~121 ~168 ~17 ~121 quartz_block 0  
fill ~166 ~17 ~61 ~168 ~17 ~61 quartz_block 0  
fill ~166 ~17 ~62 ~169 ~17 ~62 quartz_block 0  
fill ~166 ~17 ~63 ~169 ~17 ~63 quartz_block 0  
fill ~166 ~17 ~117 ~169 ~17 ~117 quartz_block 0  
fill ~166 ~17 ~118 ~169 ~17 ~118 quartz_block 0  
fill ~166 ~17 ~119 ~168 ~17 ~119 quartz_block 0  
fill ~167 ~17 ~64 ~169 ~17 ~64 quartz_block 0  
fill ~167 ~17 ~65 ~170 ~17 ~65 quartz_block 0  
fill ~167 ~17 ~66 ~170 ~17 ~66 quartz_block 0  
fill ~167 ~17 ~114 ~170 ~17 ~114 quartz_block 0  
fill ~167 ~17 ~115 ~170 ~17 ~115 quartz_block 0  
fill ~167 ~17 ~116 ~169 ~17 ~116 quartz_block 0  
fill ~168 ~17 ~67 ~170 ~17 ~67 quartz_block 0  
fill ~168 ~17 ~68 ~171 ~17 ~68 quartz_block 0  
fill ~168 ~17 ~69 ~171 ~17 ~69 quartz_block 0  
fill ~168 ~17 ~70 ~171 ~17 ~70 quartz_block 0  
fill ~168 ~17 ~110 ~171 ~17 ~110 quartz_block 0  
fill ~168 ~17 ~111 ~171 ~17 ~111 quartz_block 0  
fill ~168 ~17 ~112 ~171 ~17 ~112 quartz_block 0  
fill ~169 ~17 ~71 ~171 ~17 ~71 quartz_block 0  
fill ~169 ~17 ~72 ~172 ~17 ~72 quartz_block 0  
fill ~169 ~17 ~73 ~172 ~17 ~73 quartz_block 0  
fill ~169 ~17 ~74 ~172 ~17 ~74 quartz_block 0  
fill ~169 ~17 ~106 ~172 ~17 ~106 quartz_block 0  
fill ~169 ~17 ~107 ~172 ~17 ~107 quartz_block 0  
fill ~169 ~17 ~108 ~172 ~17 ~108 quartz_block 0  
fill ~169 ~17 ~109 ~171 ~17 ~109 quartz_block 0  
fill ~169 ~17 ~113 ~170 ~17 ~113 quartz_block 0  
fill ~170 ~17 ~75 ~172 ~17 ~75 quartz_block 0  
fill ~170 ~17 ~76 ~172 ~17 ~76 quartz_block 0  
fill ~170 ~17 ~77 ~173 ~17 ~77 quartz_block 0  
fill ~170 ~17 ~78 ~173 ~17 ~78 quartz_block 0  
fill ~170 ~17 ~79 ~173 ~17 ~79 quartz_block 0  
fill ~170 ~17 ~80 ~173 ~17 ~80 quartz_block 0  
fill ~170 ~17 ~81 ~173 ~17 ~81 quartz_block 0  
fill ~170 ~17 ~99 ~173 ~17 ~99 quartz_block 0  
fill ~170 ~17 ~100 ~173 ~17 ~100 quartz_block 0  
fill ~170 ~17 ~101 ~173 ~17 ~101 quartz_block 0  
fill ~170 ~17 ~102 ~173 ~17 ~102 quartz_block 0  
fill ~170 ~17 ~103 ~173 ~17 ~103 quartz_block 0  
fill ~170 ~17 ~104 ~172 ~17 ~104 quartz_block 0  
fill ~170 ~17 ~105 ~172 ~17 ~105 quartz_block 0  
fill ~171 ~17 ~82 ~173 ~17 ~82 quartz_block 0  
fill ~171 ~17 ~83 ~173 ~17 ~83 quartz_block 0  
fill ~171 ~17 ~84 ~173 ~17 ~84 quartz_block 0  
fill ~171 ~17 ~85 ~173 ~17 ~85 quartz_block 0  
fill ~171 ~17 ~86 ~173 ~17 ~86 quartz_block 0  
fill ~171 ~17 ~87 ~173 ~17 ~87 quartz_block 0  
fill ~171 ~17 ~88 ~174 ~17 ~88 quartz_block 0  
fill ~171 ~17 ~89 ~174 ~17 ~89 quartz_block 0  
fill ~171 ~17 ~90 ~174 ~17 ~90 quartz_block 0  
fill ~171 ~17 ~91 ~174 ~17 ~91 quartz_block 0  
fill ~171 ~17 ~92 ~174 ~17 ~92 quartz_block 0  
fill ~171 ~17 ~93 ~173 ~17 ~93 quartz_block 0  
fill ~171 ~17 ~94 ~173 ~17 ~94 quartz_block 0  
fill ~171 ~17 ~95 ~173 ~17 ~95 quartz_block 0  
fill ~171 ~17 ~96 ~173 ~17 ~96 quartz_block 0  
fill ~171 ~17 ~97 ~173 ~17 ~97 quartz_block 0  
fill ~171 ~17 ~98 ~173 ~17 ~98 quartz_block 0  
fill ~4 ~18 ~82 ~5 ~18 ~82 quartz_block 0  
fill ~4 ~18 ~83 ~5 ~18 ~83 quartz_block 0  
fill ~4 ~18 ~84 ~5 ~18 ~84 quartz_block 0  
fill ~4 ~18 ~85 ~5 ~18 ~85 quartz_block 0  
fill ~4 ~18 ~86 ~5 ~18 ~86 quartz_block 0  
fill ~4 ~18 ~87 ~5 ~18 ~87 quartz_block 0  
fill ~4 ~18 ~88 ~4 ~18 ~98 quartz_block 0  
fill ~5 ~18 ~75 ~6 ~18 ~75 quartz_block 0  
fill ~5 ~18 ~76 ~6 ~18 ~76 quartz_block 0  
fill ~5 ~18 ~77 ~5 ~18 ~87 quartz_block 0  
fill ~5 ~18 ~88 ~5 ~18 ~92 beacon 0  
fill ~5 ~18 ~93 ~5 ~18 ~105 quartz_block 0  
fill ~6 ~18 ~70 ~7 ~18 ~70 quartz_block 0  
fill ~6 ~18 ~71 ~7 ~18 ~71 quartz_block 0  
fill ~6 ~18 ~72 ~6 ~18 ~76 quartz_block 0  
fill ~6 ~18 ~77 ~6 ~18 ~87 beacon 0  
fill ~6 ~18 ~93 ~6 ~18 ~103 beacon 0  
fill ~6 ~18 ~104 ~6 ~18 ~110 quartz_block 0  
fill ~7 ~18 ~66 ~8 ~18 ~66 quartz_block 0  
fill ~7 ~18 ~67 ~8 ~18 ~67 quartz_block 0  
fill ~7 ~18 ~68 ~7 ~18 ~71 quartz_block 0  
fill ~7 ~18 ~72 ~7 ~18 ~76 beacon 0  
fill ~7 ~18 ~104 ~7 ~18 ~108 beacon 0  
fill ~7 ~18 ~109 ~7 ~18 ~114 quartz_block 0  
fill ~8 ~18 ~63 ~9 ~18 ~63 quartz_block 0  
fill ~8 ~18 ~64 ~9 ~18 ~64 quartz_block 0  
fill ~8 ~18 ~65 ~8 ~18 ~63 quartz_block 0  
fill ~8 ~18 ~68 ~8 ~18 ~71 beacon 0  
fill ~8 ~18 ~109 ~8 ~18 ~112 beacon 0  
fill ~8 ~18 ~113 ~8 ~18 ~117 quartz_block 0  
fill ~9 ~18 ~60 ~10 ~18 ~60 quartz_block 0  
fill ~9 ~18 ~61 ~10 ~18 ~61 quartz_block 0  
fill ~9 ~18 ~62 ~9 ~18 ~60 quartz_block 0  
fill ~9 ~18 ~65 ~9 ~18 ~67 beacon 0  
fill ~9 ~18 ~113 ~9 ~18 ~115 beacon 0  
fill ~9 ~18 ~116 ~9 ~18 ~120 quartz_block 0  
fill ~10 ~18 ~58 ~11 ~18 ~58 quartz_block 0  
fill ~10 ~18 ~59 ~10 ~18 ~58 quartz_block 0  
fill ~10 ~18 ~62 ~10 ~18 ~64 beacon 0  
fill ~10 ~18 ~116 ~10 ~18 ~118 beacon 0  
fill ~10 ~18 ~119 ~10 ~18 ~122 quartz_block 0  
fill ~11 ~18 ~56 ~12 ~18 ~56 quartz_block 0  
fill ~11 ~18 ~57 ~11 ~18 ~56 quartz_block 0  
fill ~11 ~18 ~59 ~11 ~18 ~61 beacon 0  
fill ~11 ~18 ~119 ~11 ~18 ~121 beacon 0  
fill ~11 ~18 ~122 ~11 ~18 ~124 quartz_block 0  
fill ~12 ~18 ~53 ~13 ~18 ~53 quartz_block 0  
fill ~12 ~18 ~54 ~13 ~18 ~54 quartz_block 0  
fill ~12 ~18 ~55 ~12 ~18 ~53 quartz_block 0  
fill ~12 ~18 ~57 ~12 ~18 ~58 beacon 0  
fill ~12 ~18 ~122 ~12 ~18 ~123 beacon 0  
fill ~12 ~18 ~124 ~12 ~18 ~127 quartz_block 0  
fill ~13 ~18 ~51 ~14 ~18 ~51 quartz_block 0  
fill ~13 ~18 ~52 ~14 ~18 ~52 quartz_block 0  
fill ~13 ~18 ~55 ~13 ~18 ~56 beacon 0  
fill ~13 ~18 ~124 ~13 ~18 ~125 beacon 0  
fill ~13 ~18 ~126 ~13 ~18 ~129 quartz_block 0  
fill ~14 ~18 ~49 ~15 ~18 ~49 quartz_block 0  
fill ~14 ~18 ~50 ~15 ~18 ~50 quartz_block 0  
fill ~14 ~18 ~53 ~14 ~18 ~54 beacon 0  
fill ~14 ~18 ~126 ~14 ~18 ~127 beacon 0  
fill ~14 ~18 ~128 ~14 ~18 ~131 quartz_block 0  
fill ~15 ~18 ~48 ~16 ~18 ~48 quartz_block 0   
fill ~15 ~18 ~51 ~15 ~18 ~52 beacon 0  
fill ~15 ~18 ~128 ~15 ~18 ~129 beacon 0  
fill ~15 ~18 ~130 ~15 ~18 ~132 quartz_block 0  
fill ~16 ~18 ~46 ~17 ~18 ~46 quartz_block 0  
fill ~16 ~18 ~47 ~16 ~18 ~46 quartz_block 0  
fill ~16 ~18 ~49 ~16 ~18 ~50 beacon 0  
fill ~16 ~18 ~130 ~16 ~18 ~131 beacon 0  
fill ~16 ~18 ~132 ~16 ~18 ~134 quartz_block 0  
fill ~17 ~18 ~44 ~18 ~18 ~44 quartz_block 0  
fill ~17 ~18 ~45 ~18 ~18 ~45 quartz_block 0  
fill ~17 ~18 ~47 ~17 ~18 ~48 beacon 0  
fill ~17 ~18 ~132 ~17 ~18 ~133 beacon 0  
fill ~17 ~18 ~134 ~17 ~18 ~136 quartz_block 0  
fill ~18 ~18 ~43 ~19 ~18 ~43 quartz_block 0 
setblock ~18 ~18 ~46 beacon 0 
setblock ~18 ~18 ~134 beacon 0  
fill ~18 ~18 ~135 ~18 ~18 ~137 quartz_block 0  
fill ~19 ~18 ~41 ~20 ~18 ~41 quartz_block 0  
fill ~19 ~18 ~42 ~20 ~18 ~42 quartz_block 0  
fill ~19 ~18 ~44 ~19 ~18 ~45 beacon 0  
fill ~19 ~18 ~135 ~19 ~18 ~136 beacon 0  
fill ~19 ~18 ~137 ~19 ~18 ~139 quartz_block 0  
fill ~20 ~18 ~40 ~21 ~18 ~40 quartz_block 0 
setblock ~20 ~18 ~43 beacon 0 
setblock ~20 ~18 ~137 beacon 0  
fill ~20 ~18 ~138 ~20 ~18 ~140 quartz_block 0  
fill ~21 ~18 ~39 ~22 ~18 ~39 quartz_block 0  
fill ~21 ~18 ~41 ~21 ~18 ~42 beacon 0  
fill ~21 ~18 ~138 ~21 ~18 ~139 beacon 0  
fill ~21 ~18 ~140 ~21 ~18 ~141 quartz_block 0  
fill ~22 ~18 ~37 ~23 ~18 ~37 quartz_block 0  
fill ~22 ~18 ~38 ~22 ~18 ~37 quartz_block 0 
setblock ~22 ~18 ~40 beacon 0 
setblock ~22 ~18 ~140 beacon 0  
fill ~22 ~18 ~141 ~22 ~18 ~143 quartz_block 0  
fill ~23 ~18 ~36 ~24 ~18 ~36 quartz_block 0  
fill ~23 ~18 ~38 ~23 ~18 ~39 beacon 0  
fill ~23 ~18 ~141 ~23 ~18 ~142 beacon 0  
fill ~23 ~18 ~143 ~23 ~18 ~144 quartz_block 0  
fill ~24 ~18 ~35 ~25 ~18 ~35 quartz_block 0 
setblock ~24 ~18 ~37 beacon 0  
fill ~24 ~18 ~79 ~24 ~18 ~101 beacon 0 
setblock ~24 ~18 ~143 beacon 0  
fill ~24 ~18 ~144 ~24 ~18 ~145 quartz_block 0  
fill ~25 ~18 ~34 ~26 ~18 ~34 quartz_block 0 
setblock ~25 ~18 ~36 beacon 0  
fill ~25 ~18 ~74 ~25 ~18 ~78 beacon 0  
fill ~25 ~18 ~79 ~26 ~18 ~79 quartz_block 0  
fill ~25 ~18 ~80 ~26 ~18 ~80 quartz_block 0  
fill ~25 ~18 ~81 ~26 ~18 ~81 quartz_block 0  
fill ~25 ~18 ~82 ~25 ~18 ~101 quartz_block 0  
fill ~25 ~18 ~102 ~25 ~18 ~106 beacon 0 
setblock ~25 ~18 ~144 beacon 0  
fill ~25 ~18 ~145 ~25 ~18 ~146 quartz_block 0  
fill ~26 ~18 ~32 ~28 ~18 ~32 quartz_block 0  
fill ~26 ~18 ~33 ~27 ~18 ~33 quartz_block 0 
setblock ~26 ~18 ~35 beacon 0  
fill ~26 ~18 ~71 ~26 ~18 ~73 beacon 0  
fill ~26 ~18 ~74 ~27 ~18 ~74 quartz_block 0  
fill ~26 ~18 ~75 ~27 ~18 ~75 quartz_block 0  
fill ~26 ~18 ~76 ~26 ~18 ~81 quartz_block 0  
fill ~26 ~18 ~98 ~26 ~18 ~106 quartz_block 0  
fill ~26 ~18 ~107 ~26 ~18 ~109 beacon 0 
setblock ~26 ~18 ~145 beacon 0  
fill ~26 ~18 ~146 ~26 ~18 ~148 quartz_block 0  
fill ~27 ~18 ~31 ~29 ~18 ~31 quartz_block 0 
setblock ~27 ~18 ~34 beacon 0  
fill ~27 ~18 ~68 ~27 ~18 ~70 beacon 0  
fill ~27 ~18 ~71 ~28 ~18 ~71 quartz_block 0  
fill ~27 ~18 ~72 ~27 ~18 ~75 quartz_block 0  
fill ~27 ~18 ~104 ~27 ~18 ~109 quartz_block 0  
fill ~27 ~18 ~110 ~27 ~18 ~112 beacon 0 
setblock ~27 ~18 ~146 beacon 0  
fill ~27 ~18 ~147 ~27 ~18 ~149 quartz_block 0  
fill ~28 ~18 ~30 ~30 ~18 ~30 quartz_block 0 
setblock ~28 ~18 ~33 beacon 0  
fill ~28 ~18 ~65 ~28 ~18 ~67 beacon 0  
fill ~28 ~18 ~68 ~29 ~18 ~68 quartz_block 0  
fill ~28 ~18 ~69 ~28 ~18 ~71 quartz_block 0  
fill ~28 ~18 ~108 ~28 ~18 ~112 quartz_block 0  
fill ~28 ~18 ~113 ~28 ~18 ~115 beacon 0 
setblock ~28 ~18 ~147 beacon 0  
fill ~28 ~18 ~148 ~28 ~18 ~150 quartz_block 0  
fill ~29 ~18 ~29 ~31 ~18 ~29 quartz_block 0 
setblock ~29 ~18 ~32 beacon 0  
fill ~29 ~18 ~63 ~29 ~18 ~64 beacon 0  
fill ~29 ~18 ~65 ~30 ~18 ~65 quartz_block 0  
fill ~29 ~18 ~66 ~30 ~18 ~66 quartz_block 0  
fill ~29 ~18 ~67 ~29 ~18 ~65 quartz_block 0  
fill ~29 ~18 ~111 ~29 ~18 ~115 quartz_block 0  
fill ~29 ~18 ~116 ~29 ~18 ~117 beacon 0 
setblock ~29 ~18 ~148 beacon 0  
fill ~29 ~18 ~149 ~29 ~18 ~151 quartz_block 0  
fill ~30 ~18 ~28 ~32 ~18 ~28 quartz_block 0 
setblock ~30 ~18 ~31 beacon 0  
fill ~30 ~18 ~61 ~30 ~18 ~62 beacon 0  
fill ~30 ~18 ~63 ~31 ~18 ~63 quartz_block 0  
fill ~30 ~18 ~64 ~30 ~18 ~63 quartz_block 0  
fill ~30 ~18 ~113 ~30 ~18 ~117 quartz_block 0  
fill ~30 ~18 ~118 ~30 ~18 ~119 beacon 0 
setblock ~30 ~18 ~149 beacon 0  
fill ~30 ~18 ~150 ~30 ~18 ~152 quartz_block 0  
fill ~31 ~18 ~27 ~33 ~18 ~27 quartz_block 0 
setblock ~31 ~18 ~30 beacon 0  
fill ~31 ~18 ~59 ~31 ~18 ~60 beacon 0  
fill ~31 ~18 ~61 ~32 ~18 ~61 quartz_block 0  
fill ~31 ~18 ~62 ~31 ~18 ~61 quartz_block 0  
fill ~31 ~18 ~116 ~31 ~18 ~119 quartz_block 0  
fill ~31 ~18 ~120 ~31 ~18 ~121 beacon 0 
setblock ~31 ~18 ~150 beacon 0  
fill ~31 ~18 ~151 ~31 ~18 ~153 quartz_block 0  
fill ~32 ~18 ~26 ~34 ~18 ~26 quartz_block 0 
