setblock ~0~1~0 minecraft:stone 0
fill ~22~3~1 ~22~3~2 minecraft:nether_brick_fence
fill ~22~3~3 ~22~3~69 minecraft:wool 15
setblock ~21~3~4 minecraft:stone_block_slab 0
setblock ~23~3~4 minecraft:stone_block_slab 0
fill ~20~3~5 ~20~3~6 minecraft:stone_block_slab 0
fill ~21~3~5 ~21~3~69 minecraft:wool 15
fill ~23~3~5 ~23~3~69 minecraft:wool 15
fill ~24~3~5 ~24~3~6 minecraft:stone_block_slab 0
fill ~22~4~6 ~22~4~7 minecraft:stone_block_slab 0
fill ~19~3~7 ~19~3~8 minecraft:stone_block_slab 0
fill ~20~3~7 ~20~3~68 minecraft:wool 15
fill ~24~3~7 ~24~3~68 minecraft:wool 15
fill ~25~3~7 ~25~3~8 minecraft:stone_block_slab 0
fill ~21~4~8 ~21~4~9 minecraft:stone_block_slab 0
fill ~22~4~8 ~22~4~9 minecraft:wool 15
fill ~23~4~8 ~23~4~9 minecraft:stone_block_slab 0
fill ~18~3~9 ~18~3~10 minecraft:stone_block_slab 0
fill ~19~3~9 ~19~3~67 minecraft:wool 15
fill ~25~3~9 ~25~3~67 minecraft:wool 15
fill ~26~3~9 ~26~3~10 minecraft:stone_block_slab 0
fill ~20~4~10 ~20~4~11 minecraft:stone_block_slab 0
fill ~21~4~10 ~21~4~69 minecraft:wool 15
setblock ~22~4~10 minecraft:crafting_table
setblock ~22~5~10 minecraft:glass
fill ~23~4~10 ~23~4~69 minecraft:wool 15
fill ~24~4~10 ~24~4~11 minecraft:stone_block_slab 0
fill ~17~3~11 ~17~3~36 minecraft:stone_block_slab 0
fill ~18~3~11 ~18~3~67 minecraft:wool 15
fill ~21~5~11 ~21~5~12 minecraft:glass
setblock ~22~4~11 minecraft:lever 5
fill ~22~6~11 ~22~6~13 minecraft:stone_block_slab 0
fill ~23~5~11 ~23~5~12 minecraft:glass
fill ~26~3~11 ~26~3~67 minecraft:wool 15
fill ~27~3~11 ~27~3~36 minecraft:stone_block_slab 0
fill ~19~4~12 ~19~4~66 minecraft:stone_block_slab 0
fill ~20~4~12 ~20~4~69 minecraft:wool 15
setblock ~22~4~12 minecraft:stone_brick_stairs 2
fill ~24~4~12 ~24~4~69 minecraft:wool 15
fill ~25~4~12 ~25~4~66 minecraft:stone_block_slab 0
fill ~21~5~13 ~23~5~13 minecraft:wool 15
fill ~22~4~13 ~22~4~69 minecraft:wool 15
setblock ~33~0~13 minecraft:air
fill ~20~5~14 ~20~5~68 minecraft:stone_block_slab 0
fill ~21~5~14 ~21~5~69 minecraft:wool 15
setblock ~22~5~14 minecraft:noteblock
setblock ~22~6~14 minecraft:glass
fill ~23~5~14 ~23~5~69 minecraft:wool 15
fill ~24~5~14 ~24~5~68 minecraft:stone_block_slab 0
fill ~21~6~15 ~21~6~16 minecraft:glass
fill ~22~7~15 ~22~7~17 minecraft:stone_block_slab 0
fill ~23~6~15 ~23~6~16 minecraft:glass
setblock ~22~5~16 minecraft:stone_brick_stairs 2
fill ~21~6~17 ~21~6~18 minecraft:stone_block_slab 0
fill ~22~5~17 ~22~5~69 minecraft:wool 15
fill ~22~6~17 ~22~6~18 minecraft:wool 15
fill ~23~6~17 ~23~6~18 minecraft:stone_block_slab 0
fill ~22~6~19 ~22~6~69 minecraft:stone_block_slab 0
setblock ~21~0~23 minecraft:wool 15
fill ~22~1~23 ~22~2~23 minecraft:nether_brick_fence
setblock ~23~0~23 minecraft:wool 15
fill ~9~4~36 ~9~4~54 minecraft:wool 15
fill ~35~4~36 ~35~4~54 minecraft:wool 15
setblock ~9~3~37 minecraft:stone_block_slab 8
setblock ~9~5~37 minecraft:stone_block_slab 0
setblock ~16~3~37 minecraft:stone_block_slab 0
fill ~17~3~37 ~17~3~66 minecraft:wool 15
fill ~27~3~37 ~27~3~66 minecraft:wool 15
setblock ~28~3~37 minecraft:stone_block_slab 0
setblock ~35~3~37 minecraft:stone_block_slab 8
setblock ~35~5~37 minecraft:stone_block_slab 0
fill ~8~3~38 ~8~3~39 minecraft:stone_block_slab 8
fill ~8~4~38 ~8~4~39 minecraft:wool 15
fill ~8~5~38 ~8~5~39 minecraft:stone_block_slab 0
fill ~9~3~38 ~9~3~39 minecraft:double_stone_block_slab 0
fill ~9~5~38 ~9~5~39 minecraft:double_stone_block_slab 0
fill ~10~3~38 ~10~3~39 minecraft:stone_block_slab 8
fill ~10~4~38 ~10~4~39 minecraft:wool 15
fill ~10~5~38 ~10~5~39 minecraft:stone_block_slab 0
fill ~15~3~38 ~15~3~39 minecraft:stone_block_slab 0
fill ~16~3~38 ~16~3~65 minecraft:wool 15
fill ~28~3~38 ~28~3~65 minecraft:wool 15
fill ~29~3~38 ~29~3~39 minecraft:stone_block_slab 0
fill ~34~3~38 ~34~3~39 minecraft:stone_block_slab 8
fill ~34~4~38 ~34~4~39 minecraft:wool 15
fill ~34~5~38 ~34~5~39 minecraft:stone_block_slab 0
fill ~35~3~38 ~35~3~39 minecraft:double_stone_block_slab 0
fill ~35~5~38 ~35~5~39 minecraft:double_stone_block_slab 0
fill ~36~3~38 ~36~3~39 minecraft:stone_block_slab 8
fill ~36~4~38 ~36~4~39 minecraft:wool 15
fill ~36~5~38 ~36~5~39 minecraft:stone_block_slab 0
fill ~7~3~40 ~7~5~58 minecraft:wool 15
fill ~8~2~40 ~10~2~58 minecraft:wool 15
fill ~8~6~40 ~10~6~58 minecraft:wool 15
fill ~11~3~40 ~11~5~58 minecraft:wool 15
setblock ~14~3~40 minecraft:stone_block_slab 0
fill ~15~3~40 ~15~3~64 minecraft:wool 15
fill ~29~3~40 ~29~3~64 minecraft:wool 15
setblock ~30~3~40 minecraft:stone_block_slab 0
fill ~33~3~40 ~33~5~58 minecraft:wool 15
fill ~34~2~40 ~36~2~58 minecraft:wool 15
fill ~34~6~40 ~36~6~58 minecraft:wool 15
fill ~37~3~40 ~37~5~58 minecraft:wool 15
fill ~6~4~41 ~6~4~60 minecraft:stone_block_slab 0
setblock ~13~3~41 minecraft:stone_block_slab 0
fill ~14~3~41 ~14~3~64 minecraft:wool 15
fill ~30~3~41 ~30~3~64 minecraft:wool 15
setblock ~31~3~41 minecraft:stone_block_slab 0
fill ~38~4~41 ~38~4~60 minecraft:stone_block_slab 0
setblock ~12~3~42 minecraft:stone_block_slab 0
fill ~13~3~42 ~13~3~63 minecraft:wool 15
fill ~31~3~42 ~31~3~63 minecraft:wool 15
setblock ~32~3~42 minecraft:stone_block_slab 0
fill ~5~4~43 ~5~4~51 minecraft:stone_block_slab 0
fill ~8~3~43 ~10~3~54 minecraft:wool 15
fill ~8~4~43 ~8~5~54 minecraft:wool 15
fill ~9~5~43 ~10~5~54 minecraft:wool 15
fill ~10~4~43 ~10~4~54 minecraft:wool 15
fill ~12~3~43 ~12~3~62 minecraft:wool 15
fill ~32~3~43 ~32~3~62 minecraft:wool 15
fill ~34~3~43 ~36~3~54 minecraft:wool 15
fill ~34~4~43 ~34~5~54 minecraft:wool 15
fill ~35~5~43 ~36~5~54 minecraft:wool 15
fill ~36~4~43 ~36~4~54 minecraft:wool 15
fill ~39~4~43 ~39~4~51 minecraft:stone_block_slab 0
fill ~12~4~44 ~12~4~61 minecraft:stone_block_slab 0
fill ~32~4~44 ~32~4~61 minecraft:stone_block_slab 0
fill ~4~4~46 ~4~4~50 minecraft:stone_block_slab 0
fill ~40~4~46 ~40~4~50 minecraft:stone_block_slab 0
setblock ~15~0~49 minecraft:wool 15
setblock ~29~0~49 minecraft:wool 15
setblock ~14~0~50 minecraft:wool 15
fill ~15~1~50 ~15~2~50 minecraft:nether_brick_fence
setblock ~16~0~50 minecraft:wool 15
setblock ~28~0~50 minecraft:wool 15
fill ~29~1~50 ~29~2~50 minecraft:nether_brick_fence
setblock ~30~0~50 minecraft:wool 15
fill ~6~3~51 ~6~3~61 minecraft:wool 15
fill ~38~3~51 ~38~3~61 minecraft:wool 15
setblock ~4~3~52 minecraft:stone_block_slab 0
fill ~5~3~52 ~5~3~62 minecraft:wool 15
fill ~39~3~52 ~39~3~62 minecraft:wool 15
setblock ~40~3~52 minecraft:stone_block_slab 0
fill ~3~3~53 ~3~3~54 minecraft:stone_block_slab 0
fill ~4~3~53 ~4~3~63 minecraft:wool 15
fill ~40~3~53 ~40~3~63 minecraft:wool 15
fill ~41~3~53 ~41~3~54 minecraft:stone_block_slab 0
fill ~9~7~54 ~9~7~62 minecraft:wool 15
fill ~35~7~54 ~35~7~62 minecraft:wool 15
setblock ~2~3~55 minecraft:stone_block_slab 0
fill ~3~3~55 ~3~3~62 minecraft:wool 15
fill ~9~8~55 ~9~8~63 minecraft:wool 15
fill ~35~8~55 ~35~8~63 minecraft:wool 15
fill ~41~3~55 ~41~3~62 minecraft:wool 15
setblock ~42~3~55 minecraft:stone_block_slab 0
setblock ~1~3~56 minecraft:stone_block_slab 0
fill ~2~3~56 ~2~3~61 minecraft:wool 15
fill ~8~3~56 ~10~5~57 minecraft:wool 15
fill ~9~9~56 ~9~9~63 minecraft:wool 15
fill ~34~3~56 ~36~5~57 minecraft:wool 15
fill ~35~9~56 ~35~9~63 minecraft:wool 15
fill ~42~3~56 ~42~3~61 minecraft:wool 15
setblock ~43~3~56 minecraft:stone_block_slab 0
setblock ~0~3~57 minecraft:stone_block_slab 0
fill ~1~3~57 ~1~3~60 minecraft:wool 15
fill ~10~9~57 ~10~9~63 minecraft:stone_block_slab 8
fill ~10~10~57 ~10~10~63 minecraft:wool 15
fill ~34~9~57 ~34~9~63 minecraft:stone_block_slab 8
fill ~34~10~57 ~34~10~63 minecraft:wool 15
fill ~43~3~57 ~43~3~60 minecraft:wool 15
setblock ~44~3~57 minecraft:stone_block_slab 0
fill ~0~3~58 ~0~3~59 minecraft:wool 15
fill ~10~11~58 ~10~11~62 minecraft:wool 15
fill ~34~11~58 ~34~11~63 minecraft:wool 15
fill ~44~3~58 ~44~3~59 minecraft:wool 15
fill ~45~3~58 ~45~3~59 minecraft:stone_block_slab 0
setblock ~7~3~59 minecraft:double_stone_block_slab 0
fill ~7~4~59 ~7~4~62 minecraft:wool 15
setblock ~7~5~59 minecraft:double_stone_block_slab 0
setblock ~8~2~59 minecraft:double_stone_block_slab 0
setblock ~8~6~59 minecraft:double_stone_block_slab 0
fill ~9~2~59 ~9~2~62 minecraft:wool 15
fill ~9~6~59 ~9~6~62 minecraft:wool 15
setblock ~10~2~59 minecraft:double_stone_block_slab 0
setblock ~10~6~59 minecraft:double_stone_block_slab 0
setblock ~11~3~59 minecraft:double_stone_block_slab 0
fill ~11~4~59 ~11~4~62 minecraft:wool 15
setblock ~11~5~59 minecraft:double_stone_block_slab 0
setblock ~33~3~59 minecraft:double_stone_block_slab 0
fill ~33~4~59 ~33~4~62 minecraft:wool 15
setblock ~33~5~59 minecraft:double_stone_block_slab 0
setblock ~34~2~59 minecraft:double_stone_block_slab 0
setblock ~34~6~59 minecraft:double_stone_block_slab 0
fill ~35~2~59 ~35~2~62 minecraft:wool 15
fill ~35~6~59 ~35~6~62 minecraft:wool 15
setblock ~36~2~59 minecraft:double_stone_block_slab 0
setblock ~36~6~59 minecraft:double_stone_block_slab 0
setblock ~37~3~59 minecraft:double_stone_block_slab 0
fill ~37~4~59 ~37~4~62 minecraft:wool 15
setblock ~37~5~59 minecraft:double_stone_block_slab 0
setblock ~0~3~60 minecraft:stone_block_slab 0
fill ~7~3~60 ~7~3~62 minecraft:wool 15
fill ~7~5~60 ~7~5~62 minecraft:wool 15
fill ~8~2~60 ~8~2~62 minecraft:wool 15
fill ~8~6~60 ~8~6~62 minecraft:wool 15
fill ~10~2~60 ~10~2~62 minecraft:wool 15
fill ~10~6~60 ~10~6~62 minecraft:wool 15
fill ~11~3~60 ~11~3~62 minecraft:wool 15
fill ~11~5~60 ~11~5~62 minecraft:wool 15
fill ~33~3~60 ~33~3~62 minecraft:wool 15
fill ~33~5~60 ~33~5~62 minecraft:wool 15
fill ~34~2~60 ~34~2~62 minecraft:wool 15
fill ~34~6~60 ~34~6~62 minecraft:wool 15
fill ~36~2~60 ~36~2~62 minecraft:wool 15
fill ~36~6~60 ~36~6~62 minecraft:wool 15
fill ~37~3~60 ~37~3~62 minecraft:wool 15
fill ~37~5~60 ~37~5~62 minecraft:wool 15
setblock ~44~3~60 minecraft:stone_block_slab 0
setblock ~1~3~61 minecraft:stone_block_slab 0
setblock ~43~3~61 minecraft:stone_block_slab 0
setblock ~2~3~62 minecraft:stone_block_slab 0
setblock ~6~3~62 minecraft:stone_block_slab 0
",TickDelay:99999,Persistent:1b,Ticking:t:stone_block_slab 0
setblock ~42~3~62 minecraft:stone_block_slab 0
setblock ~3~3~63 minecraft:stone_block_slab 0
setblock ~5~3~63 minecraft:stone_block_slab 0
fill ~7~3~63 ~7~5~64 minecraft:double_stone_block_slab 0
fill ~8~2~63 ~10~2~64 minecraft:double_stone_block_slab 0
fill ~8~6~63 ~10~6~64 minecraft:double_stone_block_slab 0
fill ~11~3~63 ~11~5~64 minecraft:double_stone_block_slab 0
setblock ~12~3~63 minecraft:stone_block_slab 0
setblock ~32~3~63 minecraft:stone_block_slab 0
fill ~33~3~63 ~33~5~64 minecraft:double_stone_block_slab 0
fill ~34~2~63 ~36~2~64 minecraft:double_stone_block_slab 0
fill ~34~6~63 ~36~6~64 minecraft:double_stone_block_slab 0
fill ~37~3~63 ~37~5~64 minecraft:double_stone_block_slab 0
setblock ~39~3~63 minecraft:stone_block_slab 0
setblock ~41~3~63 minecraft:stone_block_slab 0
setblock ~13~3~64 minecraft:stone_block_slab 0
setblock ~31~3~64 minecraft:stone_block_slab 0
fill ~14~3~65 ~15~3~65 minecraft:stone_block_slab 0
fill ~29~3~65 ~30~3~65 minecraft:stone_block_slab 0
setblock ~16~3~66 minecraft:stone_block_slab 0
setblock ~28~3~66 minecraft:stone_block_slab 0
setblock ~17~3~67 minecraft:stone_block_slab 0
setblock ~27~3~67 minecraft:stone_block_slab 0
fill ~18~3~68 ~19~3~68 minecraft:stone_block_slab 0
fill ~25~3~68 ~26~3~68 minecraft:stone_block_slab 0