fill ~0 ~0 ~32 ~17 ~0 ~32 cobblestone 0  
fill ~0 ~0 ~33 ~17 ~0 ~33 cobblestone 0  
fill ~0 ~0 ~34 ~1 ~0 ~34 cobblestone 0  
fill ~0 ~0 ~35 ~1 ~0 ~35 cobblestone 0  
fill ~0 ~0 ~36 ~1 ~0 ~36 cobblestone 0  
fill ~0 ~0 ~37 ~1 ~0 ~37 cobblestone 0  
fill ~0 ~0 ~38 ~1 ~0 ~38 cobblestone 0  
fill ~0 ~0 ~39 ~1 ~0 ~39 cobblestone 0  
fill ~0 ~0 ~40 ~1 ~0 ~40 cobblestone 0  
fill ~0 ~0 ~41 ~1 ~0 ~41 cobblestone 0  
fill ~0 ~0 ~42 ~1 ~0 ~42 cobblestone 0  
fill ~0 ~0 ~43 ~1 ~0 ~43 cobblestone 0  
fill ~0 ~0 ~44 ~1 ~0 ~44 cobblestone 0  
fill ~0 ~0 ~45 ~1 ~0 ~45 cobblestone 0  
fill ~0 ~0 ~46 ~1 ~0 ~46 cobblestone 0  
fill ~0 ~0 ~47 ~1 ~0 ~47 cobblestone 0  
fill ~0 ~0 ~48 ~1 ~0 ~48 cobblestone 0  
fill ~0 ~0 ~49 ~1 ~0 ~49 cobblestone 0  
fill ~0 ~0 ~50 ~1 ~0 ~50 cobblestone 0  
fill ~0 ~0 ~51 ~1 ~0 ~51 cobblestone 0  
fill ~0 ~0 ~52 ~17 ~0 ~52 cobblestone 0  
fill ~0 ~0 ~53 ~17 ~0 ~53 cobblestone 0  
fill ~4 ~0 ~34 ~5 ~0 ~34 double_stone_slab 3  
fill ~4 ~0 ~35 ~5 ~0 ~35 double_stone_slab 3  
fill ~14 ~0 ~50 ~15 ~0 ~50 double_stone_slab 3  
fill ~14 ~0 ~51 ~15 ~0 ~51 double_stone_slab 3  
fill ~16 ~0 ~34 ~17 ~0 ~34 cobblestone 0  
fill ~16 ~0 ~35 ~17 ~0 ~35 cobblestone 0  
fill ~16 ~0 ~36 ~17 ~0 ~36 cobblestone 0  
fill ~16 ~0 ~37 ~17 ~0 ~37 cobblestone 0  
fill ~16 ~0 ~38 ~17 ~0 ~38 cobblestone 0  
fill ~16 ~0 ~39 ~17 ~0 ~39 cobblestone 0  
fill ~16 ~0 ~40 ~17 ~0 ~40 cobblestone 0  
fill ~16 ~0 ~41 ~17 ~0 ~41 cobblestone 0  
fill ~16 ~0 ~42 ~17 ~0 ~42 cobblestone 0  
fill ~16 ~0 ~43 ~17 ~0 ~43 cobblestone 0  
fill ~16 ~0 ~44 ~17 ~0 ~44 cobblestone 0  
fill ~16 ~0 ~45 ~17 ~0 ~45 cobblestone 0  
fill ~16 ~0 ~46 ~17 ~0 ~46 cobblestone 0  
fill ~16 ~0 ~47 ~17 ~0 ~47 cobblestone 0  
fill ~16 ~0 ~48 ~17 ~0 ~48 cobblestone 0  
fill ~16 ~0 ~49 ~17 ~0 ~49 cobblestone 0  
fill ~16 ~0 ~50 ~17 ~0 ~50 cobblestone 0  
fill ~16 ~0 ~51 ~17 ~0 ~51 cobblestone 0  
fill ~0 ~1 ~32 ~17 ~1 ~32 cobblestone 0  
fill ~0 ~1 ~33 ~17 ~1 ~33 cobblestone 0  
fill ~0 ~1 ~34 ~1 ~1 ~34 cobblestone 0  
fill ~0 ~1 ~35 ~1 ~1 ~35 cobblestone 0  
fill ~0 ~1 ~36 ~1 ~1 ~36 cobblestone 0  
fill ~0 ~1 ~37 ~1 ~1 ~37 cobblestone 0  
fill ~0 ~1 ~38 ~1 ~1 ~38 cobblestone 0  
fill ~0 ~1 ~39 ~1 ~1 ~39 cobblestone 0  
fill ~0 ~1 ~40 ~1 ~1 ~40 cobblestone 0  
fill ~0 ~1 ~41 ~1 ~1 ~41 cobblestone 0  
fill ~0 ~1 ~42 ~1 ~1 ~42 cobblestone 0  
fill ~0 ~1 ~43 ~1 ~1 ~43 cobblestone 0  
fill ~0 ~1 ~44 ~1 ~1 ~44 cobblestone 0  
fill ~0 ~1 ~45 ~1 ~1 ~45 cobblestone 0  
fill ~0 ~1 ~46 ~1 ~1 ~46 cobblestone 0  
fill ~0 ~1 ~47 ~1 ~1 ~47 cobblestone 0  
fill ~0 ~1 ~48 ~1 ~1 ~48 cobblestone 0  
fill ~0 ~1 ~49 ~1 ~1 ~49 cobblestone 0  
fill ~0 ~1 ~50 ~1 ~1 ~50 cobblestone 0  
fill ~0 ~1 ~51 ~1 ~1 ~51 cobblestone 0  
fill ~0 ~1 ~52 ~17 ~1 ~52 cobblestone 0  
fill ~0 ~1 ~53 ~17 ~1 ~53 cobblestone 0  
fill ~4 ~1 ~34 ~5 ~1 ~34 double_stone_slab 3  
fill ~4 ~1 ~35 ~5 ~1 ~35 double_stone_slab 3  
fill ~14 ~1 ~50 ~15 ~1 ~50 double_stone_slab 3  
fill ~14 ~1 ~51 ~15 ~1 ~51 double_stone_slab 3  
fill ~16 ~1 ~34 ~17 ~1 ~34 cobblestone 0  
fill ~16 ~1 ~35 ~17 ~1 ~35 cobblestone 0  
fill ~16 ~1 ~36 ~17 ~1 ~36 cobblestone 0  
fill ~16 ~1 ~37 ~17 ~1 ~37 cobblestone 0  
fill ~16 ~1 ~38 ~17 ~1 ~38 cobblestone 0  
fill ~16 ~1 ~39 ~17 ~1 ~39 cobblestone 0  
fill ~16 ~1 ~40 ~17 ~1 ~40 cobblestone 0  
fill ~16 ~1 ~41 ~17 ~1 ~41 cobblestone 0  
fill ~16 ~1 ~42 ~17 ~1 ~42 cobblestone 0  
fill ~16 ~1 ~43 ~17 ~1 ~43 cobblestone 0  
fill ~16 ~1 ~44 ~17 ~1 ~44 cobblestone 0  
fill ~16 ~1 ~45 ~17 ~1 ~45 cobblestone 0  
fill ~16 ~1 ~46 ~17 ~1 ~46 cobblestone 0  
fill ~16 ~1 ~47 ~17 ~1 ~47 cobblestone 0  
fill ~16 ~1 ~48 ~17 ~1 ~48 cobblestone 0  
fill ~16 ~1 ~49 ~17 ~1 ~49 cobblestone 0  
fill ~16 ~1 ~50 ~17 ~1 ~50 cobblestone 0  
fill ~16 ~1 ~51 ~17 ~1 ~51 cobblestone 0  
fill ~2 ~2 ~34 ~15 ~2 ~34 stone_slab 3  
fill ~2 ~2 ~35 ~15 ~2 ~35 stone_slab 3  
fill ~2 ~2 ~36 ~3 ~2 ~36 stone_slab 3  
fill ~2 ~2 ~37 ~3 ~2 ~37 stone_slab 3  
fill ~2 ~2 ~38 ~3 ~2 ~38 stone_slab 3  
fill ~2 ~2 ~39 ~3 ~2 ~39 stone_slab 3  
fill ~2 ~2 ~40 ~3 ~2 ~40 stone_slab 3  
fill ~2 ~2 ~41 ~3 ~2 ~41 stone_slab 3  
fill ~2 ~2 ~42 ~3 ~2 ~42 stone_slab 3  
fill ~2 ~2 ~43 ~3 ~2 ~43 stone_slab 3  
fill ~2 ~2 ~44 ~3 ~2 ~44 stone_slab 3  
fill ~2 ~2 ~45 ~3 ~2 ~45 stone_slab 3  
fill ~2 ~2 ~46 ~3 ~2 ~46 stone_slab 3  
fill ~2 ~2 ~47 ~3 ~2 ~47 stone_slab 3  
fill ~2 ~2 ~48 ~3 ~2 ~48 stone_slab 3  
fill ~2 ~2 ~49 ~3 ~2 ~49 stone_slab 3  
fill ~2 ~2 ~50 ~15 ~2 ~50 stone_slab 3  
fill ~2 ~2 ~51 ~15 ~2 ~51 stone_slab 3  
fill ~4 ~2 ~36 ~13 ~2 ~36 cobblestone 0  
fill ~4 ~2 ~37 ~13 ~2 ~37 cobblestone 0  
fill ~4 ~2 ~38 ~5 ~2 ~38 cobblestone 0  
fill ~4 ~2 ~39 ~5 ~2 ~39 cobblestone 0  
fill ~4 ~2 ~40 ~5 ~2 ~40 cobblestone 0  
fill ~4 ~2 ~41 ~5 ~2 ~41 cobblestone 0  
fill ~4 ~2 ~42 ~5 ~2 ~42 cobblestone 0  
fill ~4 ~2 ~43 ~5 ~2 ~43 cobblestone 0  
fill ~4 ~2 ~44 ~5 ~2 ~44 cobblestone 0  
fill ~4 ~2 ~45 ~5 ~2 ~45 cobblestone 0  
fill ~4 ~2 ~46 ~7 ~2 ~46 cobblestone 0  
fill ~4 ~2 ~47 ~7 ~2 ~47 cobblestone 0  
fill ~4 ~2 ~48 ~13 ~2 ~48 cobblestone 0  
fill ~4 ~2 ~49 ~13 ~2 ~49 cobblestone 0  
fill ~12 ~2 ~38 ~13 ~2 ~38 cobblestone 0  
fill ~12 ~2 ~39 ~13 ~2 ~39 cobblestone 0  
fill ~12 ~2 ~40 ~13 ~2 ~40 cobblestone 0  
fill ~12 ~2 ~41 ~13 ~2 ~41 cobblestone 0  
fill ~12 ~2 ~42 ~13 ~2 ~42 cobblestone 0  
fill ~12 ~2 ~43 ~13 ~2 ~43 cobblestone 0  
fill ~12 ~2 ~44 ~13 ~2 ~44 cobblestone 0  
fill ~12 ~2 ~45 ~13 ~2 ~45 cobblestone 0  
fill ~12 ~2 ~46 ~13 ~2 ~46 cobblestone 0  
fill ~12 ~2 ~47 ~13 ~2 ~47 cobblestone 0  
fill ~14 ~2 ~36 ~15 ~2 ~36 stone_slab 3  
fill ~14 ~2 ~37 ~15 ~2 ~37 stone_slab 3  
fill ~14 ~2 ~38 ~15 ~2 ~38 stone_slab 3  
fill ~14 ~2 ~39 ~15 ~2 ~39 stone_slab 3  
fill ~14 ~2 ~40 ~15 ~2 ~40 stone_slab 3  
fill ~14 ~2 ~41 ~15 ~2 ~41 stone_slab 3  
fill ~14 ~2 ~42 ~15 ~2 ~42 stone_slab 3  
fill ~14 ~2 ~43 ~15 ~2 ~43 stone_slab 3  
fill ~14 ~2 ~44 ~15 ~2 ~44 stone_slab 3  
fill ~14 ~2 ~45 ~15 ~2 ~45 stone_slab 3  
fill ~14 ~2 ~46 ~15 ~2 ~46 stone_slab 3  
fill ~14 ~2 ~47 ~15 ~2 ~47 stone_slab 3  
fill ~14 ~2 ~48 ~15 ~2 ~48 stone_slab 3  
fill ~14 ~2 ~49 ~15 ~2 ~49 stone_slab 3  
fill ~2 ~3 ~34 ~15 ~3 ~34 stone_slab 3  
fill ~2 ~3 ~35 ~15 ~3 ~35 stone_slab 3  
fill ~2 ~3 ~36 ~3 ~3 ~36 stone_slab 3  
fill ~2 ~3 ~37 ~3 ~3 ~37 stone_slab 3  
fill ~2 ~3 ~38 ~3 ~3 ~38 stone_slab 3  
fill ~2 ~3 ~39 ~3 ~3 ~39 stone_slab 3  
fill ~2 ~3 ~40 ~3 ~3 ~40 stone_slab 3  
fill ~2 ~3 ~41 ~3 ~3 ~41 stone_slab 3  
fill ~2 ~3 ~42 ~3 ~3 ~42 stone_slab 3  
fill ~2 ~3 ~43 ~3 ~3 ~43 stone_slab 3  
fill ~2 ~3 ~44 ~3 ~3 ~44 stone_slab 3  
fill ~2 ~3 ~45 ~3 ~3 ~45 stone_slab 3  
fill ~2 ~3 ~46 ~3 ~3 ~46 stone_slab 3  
fill ~2 ~3 ~47 ~3 ~3 ~47 stone_slab 3  
fill ~2 ~3 ~48 ~3 ~3 ~48 stone_slab 3  
fill ~2 ~3 ~49 ~3 ~3 ~49 stone_slab 3  
fill ~2 ~3 ~50 ~15 ~3 ~50 stone_slab 3  
fill ~2 ~3 ~51 ~15 ~3 ~51 stone_slab 3  
fill ~4 ~3 ~36 ~13 ~3 ~36 cobblestone 0  
fill ~4 ~3 ~37 ~13 ~3 ~37 cobblestone 0  
fill ~4 ~3 ~38 ~5 ~3 ~38 cobblestone 0  
fill ~4 ~3 ~39 ~5 ~3 ~39 cobblestone 0  
fill ~4 ~3 ~40 ~5 ~3 ~40 cobblestone 0  
fill ~4 ~3 ~41 ~5 ~3 ~41 cobblestone 0  
fill ~4 ~3 ~42 ~5 ~3 ~42 cobblestone 0  
fill ~4 ~3 ~43 ~5 ~3 ~43 cobblestone 0  
fill ~4 ~3 ~44 ~5 ~3 ~44 cobblestone 0  
fill ~4 ~3 ~45 ~5 ~3 ~45 cobblestone 0  
fill ~4 ~3 ~46 ~7 ~3 ~46 cobblestone 0  
fill ~4 ~3 ~47 ~7 ~3 ~47 cobblestone 0  
fill ~4 ~3 ~48 ~13 ~3 ~48 cobblestone 0  
fill ~4 ~3 ~49 ~13 ~3 ~49 cobblestone 0  
fill ~12 ~3 ~38 ~13 ~3 ~38 cobblestone 0  
fill ~12 ~3 ~39 ~13 ~3 ~39 cobblestone 0  
fill ~12 ~3 ~40 ~13 ~3 ~40 cobblestone 0  
fill ~12 ~3 ~41 ~13 ~3 ~41 cobblestone 0  
fill ~12 ~3 ~42 ~13 ~3 ~42 cobblestone 0  
fill ~12 ~3 ~43 ~13 ~3 ~43 cobblestone 0  
fill ~12 ~3 ~44 ~13 ~3 ~44 cobblestone 0  
fill ~12 ~3 ~45 ~13 ~3 ~45 cobblestone 0  
fill ~12 ~3 ~46 ~13 ~3 ~46 cobblestone 0  
fill ~12 ~3 ~47 ~13 ~3 ~47 cobblestone 0  
fill ~14 ~3 ~36 ~15 ~3 ~36 stone_slab 3  
fill ~14 ~3 ~37 ~15 ~3 ~37 stone_slab 3  
fill ~14 ~3 ~38 ~15 ~3 ~38 stone_slab 3  
fill ~14 ~3 ~39 ~15 ~3 ~39 stone_slab 3  
fill ~14 ~3 ~40 ~15 ~3 ~40 stone_slab 3  
fill ~14 ~3 ~41 ~15 ~3 ~41 stone_slab 3  
fill ~14 ~3 ~42 ~15 ~3 ~42 stone_slab 3  
fill ~14 ~3 ~43 ~15 ~3 ~43 stone_slab 3  
fill ~14 ~3 ~44 ~15 ~3 ~44 stone_slab 3  
fill ~14 ~3 ~45 ~15 ~3 ~45 stone_slab 3  
fill ~14 ~3 ~46 ~15 ~3 ~46 stone_slab 3  
fill ~14 ~3 ~47 ~15 ~3 ~47 stone_slab 3  
fill ~14 ~3 ~48 ~15 ~3 ~48 stone_slab 3  
fill ~14 ~3 ~49 ~15 ~3 ~49 stone_slab 3  
fill ~6 ~4 ~38 ~11 ~4 ~38 stonebrick 0  
fill ~6 ~4 ~39 ~11 ~4 ~39 stonebrick 0  
fill ~6 ~4 ~40 ~7 ~4 ~40 stonebrick 0  
fill ~6 ~4 ~41 ~7 ~4 ~41 stonebrick 0  
fill ~6 ~4 ~42 ~7 ~4 ~42 stonebrick 0  
fill ~6 ~4 ~43 ~7 ~4 ~43 stonebrick 0  
fill ~6 ~4 ~44 ~7 ~4 ~44 stonebrick 0  
fill ~6 ~4 ~45 ~7 ~4 ~45 stonebrick 0  
fill ~6 ~4 ~46 ~11 ~4 ~46 stonebrick 0  
fill ~6 ~4 ~47 ~11 ~4 ~47 stonebrick 0  
fill ~10 ~4 ~40 ~11 ~4 ~40 stonebrick 0  
fill ~10 ~4 ~41 ~11 ~4 ~41 stonebrick 0  
fill ~10 ~4 ~42 ~11 ~4 ~42 stonebrick 0  
fill ~10 ~4 ~43 ~11 ~4 ~43 stonebrick 0  
fill ~10 ~4 ~44 ~11 ~4 ~44 stonebrick 0  
fill ~10 ~4 ~45 ~11 ~4 ~45 stonebrick 0  
fill ~6 ~5 ~38 ~11 ~5 ~38 stonebrick 0  
fill ~6 ~5 ~39 ~11 ~5 ~39 stonebrick 0  
fill ~6 ~5 ~40 ~7 ~5 ~40 stonebrick 0  
fill ~6 ~5 ~41 ~7 ~5 ~41 stonebrick 0  
fill ~6 ~5 ~42 ~7 ~5 ~42 stonebrick 0  
fill ~6 ~5 ~43 ~7 ~5 ~43 stonebrick 0  
fill ~6 ~5 ~44 ~7 ~5 ~44 stonebrick 0  
fill ~6 ~5 ~45 ~7 ~5 ~45 stonebrick 0  
fill ~6 ~5 ~46 ~11 ~5 ~46 stonebrick 0  
fill ~6 ~5 ~47 ~11 ~5 ~47 stonebrick 0  
fill ~10 ~5 ~40 ~11 ~5 ~40 stonebrick 0  
fill ~10 ~5 ~41 ~11 ~5 ~41 stonebrick 0  
fill ~10 ~5 ~42 ~11 ~5 ~42 stonebrick 0  
fill ~10 ~5 ~43 ~11 ~5 ~43 stonebrick 0  
fill ~10 ~5 ~44 ~11 ~5 ~44 stonebrick 0  
fill ~10 ~5 ~45 ~11 ~5 ~45 stonebrick 0  
fill ~4 ~6 ~36 ~13 ~6 ~36 stone_slab 13  
fill ~4 ~6 ~37 ~13 ~6 ~37 stone_slab 13  
fill ~4 ~6 ~38 ~5 ~6 ~38 stone_slab 13  
fill ~4 ~6 ~39 ~5 ~6 ~39 stone_slab 13  
fill ~4 ~6 ~40 ~5 ~6 ~40 stone_slab 13  
fill ~4 ~6 ~41 ~5 ~6 ~41 stone_slab 13  
fill ~4 ~6 ~42 ~5 ~6 ~42 stone_slab 13  
fill ~4 ~6 ~43 ~5 ~6 ~43 stone_slab 13  
fill ~4 ~6 ~44 ~5 ~6 ~44 stone_slab 13  
fill ~4 ~6 ~45 ~5 ~6 ~45 stone_slab 13  
fill ~4 ~6 ~46 ~5 ~6 ~46 stone_slab 13  
fill ~4 ~6 ~47 ~5 ~6 ~47 stone_slab 13  
fill ~4 ~6 ~48 ~13 ~6 ~48 stone_slab 13  
fill ~4 ~6 ~49 ~13 ~6 ~49 stone_slab 13  
fill ~6 ~6 ~38 ~11 ~6 ~38 stonebrick 0  
fill ~6 ~6 ~39 ~11 ~6 ~39 stonebrick 0  
fill ~6 ~6 ~40 ~7 ~6 ~40 stonebrick 0  
fill ~6 ~6 ~41 ~7 ~6 ~41 stonebrick 0  
fill ~6 ~6 ~42 ~7 ~6 ~42 stonebrick 0  
fill ~6 ~6 ~43 ~7 ~6 ~43 stonebrick 0  
fill ~6 ~6 ~44 ~7 ~6 ~44 stonebrick 0  
fill ~6 ~6 ~45 ~7 ~6 ~45 stonebrick 0  
fill ~6 ~6 ~46 ~11 ~6 ~46 stonebrick 0  
fill ~6 ~6 ~47 ~11 ~6 ~47 stonebrick 0  
fill ~10 ~6 ~40 ~11 ~6 ~40 stonebrick 0  
fill ~10 ~6 ~41 ~11 ~6 ~41 stonebrick 0  
fill ~10 ~6 ~42 ~11 ~6 ~42 stonebrick 0  
fill ~10 ~6 ~43 ~11 ~6 ~43 stonebrick 0  
fill ~10 ~6 ~44 ~11 ~6 ~44 stonebrick 0  
fill ~10 ~6 ~45 ~11 ~6 ~45 stonebrick 0  
fill ~12 ~6 ~38 ~13 ~6 ~38 stone_slab 13  
fill ~12 ~6 ~39 ~13 ~6 ~39 stone_slab 13  
fill ~12 ~6 ~40 ~13 ~6 ~40 stone_slab 13  
fill ~12 ~6 ~41 ~13 ~6 ~41 stone_slab 13  
fill ~12 ~6 ~42 ~13 ~6 ~42 stone_slab 13  
fill ~12 ~6 ~43 ~13 ~6 ~43 stone_slab 13  
fill ~12 ~6 ~44 ~13 ~6 ~44 stone_slab 13  
fill ~12 ~6 ~45 ~13 ~6 ~45 stone_slab 13  
fill ~12 ~6 ~46 ~13 ~6 ~46 stone_slab 13  
fill ~12 ~6 ~47 ~13 ~6 ~47 stone_slab 13  
fill ~4 ~7 ~36 ~13 ~7 ~36 stone_slab 13  
fill ~4 ~7 ~37 ~13 ~7 ~37 stone_slab 13  
fill ~4 ~7 ~38 ~5 ~7 ~38 stone_slab 13  
fill ~4 ~7 ~39 ~5 ~7 ~39 stone_slab 13  
fill ~4 ~7 ~40 ~5 ~7 ~40 stone_slab 13  
fill ~4 ~7 ~41 ~5 ~7 ~41 stone_slab 13  
fill ~4 ~7 ~42 ~5 ~7 ~42 stone_slab 13  
fill ~4 ~7 ~43 ~5 ~7 ~43 stone_slab 13  
fill ~4 ~7 ~44 ~5 ~7 ~44 stone_slab 13  
fill ~4 ~7 ~45 ~5 ~7 ~45 stone_slab 13  
fill ~4 ~7 ~46 ~5 ~7 ~46 stone_slab 13  
fill ~4 ~7 ~47 ~5 ~7 ~47 stone_slab 13  
fill ~4 ~7 ~48 ~13 ~7 ~48 stone_slab 13  
fill ~4 ~7 ~49 ~13 ~7 ~49 stone_slab 13  
fill ~6 ~7 ~38 ~11 ~7 ~38 stonebrick 0  
fill ~6 ~7 ~39 ~11 ~7 ~39 stonebrick 0  
fill ~6 ~7 ~40 ~7 ~7 ~40 stonebrick 0  
fill ~6 ~7 ~41 ~7 ~7 ~41 stonebrick 0  
fill ~6 ~7 ~42 ~7 ~7 ~42 stonebrick 0  
fill ~6 ~7 ~43 ~7 ~7 ~43 stonebrick 0  
fill ~6 ~7 ~44 ~7 ~7 ~44 stonebrick 0  
fill ~6 ~7 ~45 ~7 ~7 ~45 stonebrick 0  
fill ~6 ~7 ~46 ~11 ~7 ~46 stonebrick 0  
fill ~6 ~7 ~47 ~11 ~7 ~47 stonebrick 0  
fill ~10 ~7 ~40 ~11 ~7 ~40 stonebrick 0  
fill ~10 ~7 ~41 ~11 ~7 ~41 stonebrick 0  
fill ~10 ~7 ~42 ~11 ~7 ~42 stonebrick 0  
fill ~10 ~7 ~43 ~11 ~7 ~43 stonebrick 0  
fill ~10 ~7 ~44 ~11 ~7 ~44 stonebrick 0  
fill ~10 ~7 ~45 ~11 ~7 ~45 stonebrick 0  
fill ~12 ~7 ~38 ~13 ~7 ~38 stone_slab 13  
fill ~12 ~7 ~39 ~13 ~7 ~39 stone_slab 13  
fill ~12 ~7 ~40 ~13 ~7 ~40 stone_slab 13  
fill ~12 ~7 ~41 ~13 ~7 ~41 stone_slab 13  
fill ~12 ~7 ~42 ~13 ~7 ~42 stone_slab 13  
fill ~12 ~7 ~43 ~13 ~7 ~43 stone_slab 13  
fill ~12 ~7 ~44 ~13 ~7 ~44 stone_slab 13  
fill ~12 ~7 ~45 ~13 ~7 ~45 stone_slab 13  
fill ~12 ~7 ~46 ~13 ~7 ~46 stone_slab 13  
fill ~12 ~7 ~47 ~13 ~7 ~47 stone_slab 13  
fill ~6 ~8 ~38 ~11 ~8 ~38 wool 8  
fill ~6 ~8 ~39 ~11 ~8 ~39 wool 8  
fill ~6 ~8 ~40 ~11 ~8 ~40 wool 0  
fill ~6 ~8 ~41 ~11 ~8 ~41 wool 0  
fill ~6 ~8 ~42 ~11 ~8 ~42 wool 0  
fill ~6 ~8 ~43 ~11 ~8 ~43 wool 0  
fill ~6 ~8 ~44 ~11 ~8 ~44 wool 0  
fill ~6 ~8 ~45 ~11 ~8 ~45 wool 0  
fill ~6 ~8 ~46 ~11 ~8 ~46 wool 0  
fill ~6 ~8 ~47 ~11 ~8 ~47 wool 0  
fill ~6 ~9 ~38 ~11 ~9 ~38 wool 8  
fill ~6 ~9 ~39 ~11 ~9 ~39 wool 8  
fill ~6 ~9 ~40 ~11 ~9 ~40 wool 0  
fill ~6 ~9 ~41 ~11 ~9 ~41 wool 0  
fill ~6 ~9 ~42 ~11 ~9 ~42 wool 0  
fill ~6 ~9 ~43 ~11 ~9 ~43 wool 0  
fill ~6 ~9 ~44 ~11 ~9 ~44 wool 0  
fill ~6 ~9 ~45 ~11 ~9 ~45 wool 0  
fill ~6 ~9 ~46 ~11 ~9 ~46 wool 0  
fill ~6 ~9 ~47 ~11 ~9 ~47 wool 0  
fill ~6 ~10 ~36 ~11 ~10 ~36 wool 8  
fill ~6 ~10 ~37 ~11 ~10 ~37 wool 8  
fill ~6 ~10 ~38 ~11 ~10 ~38 wool 0  
fill ~6 ~10 ~39 ~11 ~10 ~39 wool 0  
fill ~6 ~10 ~40 ~11 ~10 ~40 wool 0  
fill ~6 ~10 ~41 ~11 ~10 ~41 wool 0  
fill ~6 ~10 ~42 ~11 ~10 ~42 wool 0  
fill ~6 ~10 ~43 ~11 ~10 ~43 wool 0  
fill ~6 ~10 ~44 ~11 ~10 ~44 wool 0  
fill ~6 ~10 ~45 ~11 ~10 ~45 wool 0  
fill ~6 ~11 ~36 ~11 ~11 ~36 wool 8  
fill ~6 ~11 ~37 ~11 ~11 ~37 wool 8  
fill ~6 ~11 ~38 ~11 ~11 ~38 wool 0  
fill ~6 ~11 ~39 ~11 ~11 ~39 wool 0  
fill ~6 ~11 ~40 ~11 ~11 ~40 wool 0  
fill ~6 ~11 ~41 ~11 ~11 ~41 wool 0  
fill ~6 ~11 ~42 ~11 ~11 ~42 wool 0  
fill ~6 ~11 ~43 ~11 ~11 ~43 wool 0  
fill ~6 ~11 ~44 ~11 ~11 ~44 wool 0  
fill ~6 ~11 ~45 ~11 ~11 ~45 wool 0  
fill ~6 ~12 ~34 ~11 ~12 ~34 wool 8  
fill ~6 ~12 ~35 ~11 ~12 ~35 wool 8  
fill ~6 ~12 ~36 ~11 ~12 ~36 wool 0  
fill ~6 ~12 ~37 ~11 ~12 ~37 wool 0  
fill ~6 ~12 ~38 ~11 ~12 ~38 wool 0  
fill ~6 ~12 ~39 ~11 ~12 ~39 wool 0  
fill ~6 ~12 ~40 ~11 ~12 ~40 wool 0  
fill ~6 ~12 ~41 ~11 ~12 ~41 wool 0  
fill ~6 ~12 ~42 ~11 ~12 ~42 wool 0  
fill ~6 ~12 ~43 ~11 ~12 ~43 wool 0  
fill ~6 ~13 ~34 ~11 ~13 ~34 wool 8  
fill ~6 ~13 ~35 ~11 ~13 ~35 wool 8  
fill ~6 ~13 ~36 ~11 ~13 ~36 wool 0  
fill ~6 ~13 ~37 ~11 ~13 ~37 wool 0  
fill ~6 ~13 ~38 ~11 ~13 ~38 wool 0  
fill ~6 ~13 ~39 ~11 ~13 ~39 wool 0  
fill ~6 ~13 ~40 ~11 ~13 ~40 wool 0  
fill ~6 ~13 ~41 ~11 ~13 ~41 wool 0  
fill ~6 ~13 ~42 ~11 ~13 ~42 wool 0  
fill ~6 ~13 ~43 ~11 ~13 ~43 wool 0  
fill ~6 ~14 ~32 ~11 ~14 ~32 wool 8  
fill ~6 ~14 ~33 ~11 ~14 ~33 wool 8  
fill ~6 ~14 ~34 ~11 ~14 ~34 wool 0  
fill ~6 ~14 ~35 ~11 ~14 ~35 wool 0  
fill ~6 ~14 ~36 ~11 ~14 ~36 wool 0  
fill ~6 ~14 ~37 ~11 ~14 ~37 wool 0  
fill ~6 ~14 ~38 ~11 ~14 ~38 wool 0  
fill ~6 ~14 ~39 ~11 ~14 ~39 wool 0  
fill ~6 ~14 ~40 ~11 ~14 ~40 wool 0  
fill ~6 ~14 ~41 ~11 ~14 ~41 wool 0  
fill ~6 ~15 ~32 ~11 ~15 ~32 wool 8  
fill ~6 ~15 ~33 ~11 ~15 ~33 wool 8  
fill ~6 ~15 ~34 ~11 ~15 ~34 wool 0  
fill ~6 ~15 ~35 ~11 ~15 ~35 wool 0  
fill ~6 ~15 ~36 ~11 ~15 ~36 wool 0  
fill ~6 ~15 ~37 ~11 ~15 ~37 wool 0  
fill ~6 ~15 ~38 ~11 ~15 ~38 wool 0  
fill ~6 ~15 ~39 ~11 ~15 ~39 wool 0  
fill ~6 ~15 ~40 ~11 ~15 ~40 wool 0  
fill ~6 ~15 ~41 ~11 ~15 ~41 wool 0  
fill ~6 ~16 ~30 ~11 ~16 ~30 wool 8  
fill ~6 ~16 ~31 ~11 ~16 ~31 wool 8  
fill ~6 ~16 ~32 ~11 ~16 ~32 wool 0  
fill ~6 ~16 ~33 ~11 ~16 ~33 wool 0  
fill ~6 ~16 ~34 ~11 ~16 ~34 wool 0  
fill ~6 ~16 ~35 ~11 ~16 ~35 wool 0  
fill ~6 ~16 ~36 ~11 ~16 ~36 wool 0  
fill ~6 ~16 ~37 ~11 ~16 ~37 wool 0  
fill ~6 ~16 ~38 ~11 ~16 ~38 wool 0  
fill ~6 ~16 ~39 ~11 ~16 ~39 wool 0  
fill ~6 ~17 ~30 ~11 ~17 ~30 wool 8  
fill ~6 ~17 ~31 ~11 ~17 ~31 wool 8  
fill ~6 ~17 ~32 ~11 ~17 ~32 wool 0  
fill ~6 ~17 ~33 ~11 ~17 ~33 wool 0  
fill ~6 ~17 ~34 ~11 ~17 ~34 wool 0  
fill ~6 ~17 ~35 ~11 ~17 ~35 wool 0  
fill ~6 ~17 ~36 ~11 ~17 ~36 wool 0  
fill ~6 ~17 ~37 ~11 ~17 ~37 wool 0  
fill ~6 ~17 ~38 ~11 ~17 ~38 wool 0  
fill ~6 ~17 ~39 ~11 ~17 ~39 wool 0  
fill ~6 ~18 ~28 ~11 ~18 ~28 wool 8  
fill ~6 ~18 ~29 ~11 ~18 ~29 wool 8  
fill ~6 ~18 ~30 ~11 ~18 ~30 wool 0  
fill ~6 ~18 ~31 ~11 ~18 ~31 wool 0  
fill ~6 ~18 ~32 ~11 ~18 ~32 wool 0  
fill ~6 ~18 ~33 ~11 ~18 ~33 wool 0  
fill ~6 ~18 ~34 ~11 ~18 ~34 wool 0  
fill ~6 ~18 ~35 ~11 ~18 ~35 wool 0  
fill ~6 ~18 ~36 ~11 ~18 ~36 wool 0  
fill ~6 ~18 ~37 ~11 ~18 ~37 wool 0  
fill ~6 ~19 ~28 ~11 ~19 ~28 wool 8  
fill ~6 ~19 ~29 ~11 ~19 ~29 wool 8  
fill ~6 ~19 ~30 ~11 ~19 ~30 wool 0  
fill ~6 ~19 ~31 ~11 ~19 ~31 wool 0  
fill ~6 ~19 ~32 ~11 ~19 ~32 wool 0  
fill ~6 ~19 ~33 ~11 ~19 ~33 wool 0  
fill ~6 ~19 ~34 ~11 ~19 ~34 wool 0  
fill ~6 ~19 ~35 ~11 ~19 ~35 wool 0  
fill ~6 ~19 ~36 ~11 ~19 ~36 wool 0  
fill ~6 ~19 ~37 ~11 ~19 ~37 wool 0  
fill ~6 ~20 ~14 ~11 ~20 ~14 wool 15  
fill ~6 ~20 ~15 ~11 ~20 ~15 wool 15  
fill ~6 ~20 ~26 ~11 ~20 ~26 wool 8  
fill ~6 ~20 ~27 ~11 ~20 ~27 wool 8  
fill ~6 ~20 ~28 ~11 ~20 ~28 wool 0  
fill ~6 ~20 ~29 ~11 ~20 ~29 wool 0  
fill ~6 ~20 ~30 ~11 ~20 ~30 wool 0  
fill ~6 ~20 ~31 ~11 ~20 ~31 wool 0  
fill ~6 ~20 ~32 ~11 ~20 ~32 wool 0  
fill ~6 ~20 ~33 ~11 ~20 ~33 wool 0  
fill ~6 ~20 ~34 ~11 ~20 ~34 wool 0  
fill ~6 ~20 ~35 ~11 ~20 ~35 wool 0  
fill ~6 ~21 ~14 ~11 ~21 ~14 wool 15  
fill ~6 ~21 ~15 ~11 ~21 ~15 wool 15  
fill ~6 ~21 ~26 ~11 ~21 ~26 wool 8  
fill ~6 ~21 ~27 ~11 ~21 ~27 wool 8  
fill ~6 ~21 ~28 ~11 ~21 ~28 wool 0  
fill ~6 ~21 ~29 ~11 ~21 ~29 wool 0  
fill ~6 ~21 ~30 ~11 ~21 ~30 wool 0  
fill ~6 ~21 ~31 ~11 ~21 ~31 wool 0  
fill ~6 ~21 ~32 ~11 ~21 ~32 wool 0  
fill ~6 ~21 ~33 ~11 ~21 ~33 wool 0  
fill ~6 ~21 ~34 ~11 ~21 ~34 wool 0  
fill ~6 ~21 ~35 ~11 ~21 ~35 wool 0  
fill ~4 ~22 ~16 ~13 ~22 ~16 wool 15  
fill ~4 ~22 ~17 ~13 ~22 ~17 wool 15  
fill ~6 ~22 ~24 ~11 ~22 ~24 wool 8  
fill ~6 ~22 ~25 ~11 ~22 ~25 wool 8  
fill ~6 ~22 ~26 ~11 ~22 ~26 wool 0  
fill ~6 ~22 ~27 ~11 ~22 ~27 wool 0  
fill ~6 ~22 ~28 ~11 ~22 ~28 wool 0  
fill ~6 ~22 ~29 ~11 ~22 ~29 wool 0  
fill ~6 ~22 ~30 ~11 ~22 ~30 wool 0  
fill ~6 ~22 ~31 ~11 ~22 ~31 wool 0  
fill ~6 ~22 ~32 ~11 ~22 ~32 wool 0  
fill ~6 ~22 ~33 ~11 ~22 ~33 wool 0  
fill ~4 ~23 ~16 ~13 ~23 ~16 wool 15  
fill ~4 ~23 ~17 ~13 ~23 ~17 wool 15  
fill ~6 ~23 ~24 ~11 ~23 ~24 wool 8  
fill ~6 ~23 ~25 ~11 ~23 ~25 wool 8  
fill ~6 ~23 ~26 ~11 ~23 ~26 wool 0  
fill ~6 ~23 ~27 ~11 ~23 ~27 wool 0  
fill ~6 ~23 ~28 ~11 ~23 ~28 wool 0  
fill ~6 ~23 ~29 ~11 ~23 ~29 wool 0  
fill ~6 ~23 ~30 ~11 ~23 ~30 wool 0  
fill ~6 ~23 ~31 ~11 ~23 ~31 wool 0  
fill ~6 ~23 ~32 ~11 ~23 ~32 wool 0  
fill ~6 ~23 ~33 ~11 ~23 ~33 wool 0  
fill ~2 ~24 ~18 ~15 ~24 ~18 wool 15  
fill ~2 ~24 ~19 ~15 ~24 ~19 wool 15  
fill ~6 ~24 ~22 ~11 ~24 ~22 wool 8  
fill ~6 ~24 ~23 ~11 ~24 ~23 wool 8  
fill ~6 ~24 ~24 ~11 ~24 ~24 wool 0  
fill ~6 ~24 ~25 ~11 ~24 ~25 wool 0  
fill ~6 ~24 ~26 ~11 ~24 ~26 wool 0  
fill ~6 ~24 ~27 ~11 ~24 ~27 wool 0  
fill ~6 ~24 ~28 ~11 ~24 ~28 wool 0  
fill ~6 ~24 ~29 ~11 ~24 ~29 wool 0  
fill ~6 ~24 ~30 ~11 ~24 ~30 wool 0  
fill ~6 ~24 ~31 ~11 ~24 ~31 wool 0  
fill ~2 ~25 ~18 ~15 ~25 ~18 wool 15  
fill ~2 ~25 ~19 ~15 ~25 ~19 wool 15  
fill ~6 ~25 ~22 ~11 ~25 ~22 wool 8  
fill ~6 ~25 ~23 ~11 ~25 ~23 wool 8  
fill ~6 ~25 ~24 ~11 ~25 ~24 wool 0  
fill ~6 ~25 ~25 ~11 ~25 ~25 wool 0  
fill ~6 ~25 ~26 ~11 ~25 ~26 wool 0  
fill ~6 ~25 ~27 ~11 ~25 ~27 wool 0  
fill ~6 ~25 ~28 ~11 ~25 ~28 wool 0  
fill ~6 ~25 ~29 ~11 ~25 ~29 wool 0  
fill ~6 ~25 ~30 ~11 ~25 ~30 wool 0  
fill ~6 ~25 ~31 ~11 ~25 ~31 wool 0  
fill ~2 ~26 ~20 ~15 ~26 ~20 wool 15  
fill ~2 ~26 ~21 ~15 ~26 ~21 wool 15  
fill ~6 ~26 ~22 ~7 ~26 ~22 wool 15  
fill ~6 ~26 ~23 ~7 ~26 ~23 wool 15  
fill ~6 ~26 ~24 ~11 ~26 ~24 wool 0  
fill ~6 ~26 ~25 ~11 ~26 ~25 wool 0  
fill ~6 ~26 ~26 ~11 ~26 ~26 wool 0  
fill ~6 ~26 ~27 ~11 ~26 ~27 wool 0  
fill ~6 ~26 ~28 ~11 ~26 ~28 wool 0  
fill ~6 ~26 ~29 ~11 ~26 ~29 wool 0  
fill ~8 ~26 ~22 ~9 ~26 ~22 wool 0  
fill ~8 ~26 ~23 ~9 ~26 ~23 wool 0  
fill ~10 ~26 ~22 ~11 ~26 ~22 wool 15  
fill ~10 ~26 ~23 ~11 ~26 ~23 wool 15  
fill ~2 ~27 ~20 ~15 ~27 ~20 wool 15  
fill ~2 ~27 ~21 ~15 ~27 ~21 wool 15  
fill ~6 ~27 ~22 ~7 ~27 ~22 wool 15  
fill ~6 ~27 ~23 ~7 ~27 ~23 wool 15  
fill ~6 ~27 ~24 ~11 ~27 ~24 wool 0  
fill ~6 ~27 ~25 ~11 ~27 ~25 wool 0  
fill ~6 ~27 ~26 ~11 ~27 ~26 wool 0  
fill ~6 ~27 ~27 ~11 ~27 ~27 wool 0  
fill ~6 ~27 ~28 ~11 ~27 ~28 wool 0  
fill ~6 ~27 ~29 ~11 ~27 ~29 wool 0  
fill ~8 ~27 ~22 ~9 ~27 ~22 wool 0  
fill ~8 ~27 ~23 ~9 ~27 ~23 wool 0  
fill ~10 ~27 ~22 ~11 ~27 ~22 wool 15  
fill ~10 ~27 ~23 ~11 ~27 ~23 wool 15  
fill ~2 ~28 ~22 ~15 ~28 ~22 wool 15  
fill ~2 ~28 ~23 ~15 ~28 ~23 wool 15  
fill ~6 ~28 ~18 ~11 ~28 ~18 wool 15  
fill ~6 ~28 ~19 ~11 ~28 ~19 wool 15  
fill ~6 ~28 ~20 ~11 ~28 ~20 wool 15  
fill ~6 ~28 ~21 ~11 ~28 ~21 wool 15  
fill ~6 ~28 ~24 ~11 ~28 ~24 wool 15  
fill ~6 ~28 ~25 ~11 ~28 ~25 wool 15  
fill ~6 ~28 ~26 ~11 ~28 ~26 wool 0  
fill ~6 ~28 ~27 ~11 ~28 ~27 wool 0  
fill ~2 ~29 ~22 ~15 ~29 ~22 wool 15  
fill ~2 ~29 ~23 ~15 ~29 ~23 wool 15  
fill ~6 ~29 ~18 ~11 ~29 ~18 wool 15  
fill ~6 ~29 ~19 ~11 ~29 ~19 wool 15  
fill ~6 ~29 ~20 ~11 ~29 ~20 wool 15  
fill ~6 ~29 ~21 ~11 ~29 ~21 wool 15  
fill ~6 ~29 ~24 ~11 ~29 ~24 wool 15  
fill ~6 ~29 ~25 ~11 ~29 ~25 wool 15  
fill ~6 ~29 ~26 ~11 ~29 ~26 wool 0  
fill ~6 ~29 ~27 ~11 ~29 ~27 wool 0  
fill ~2 ~30 ~24 ~15 ~30 ~24 wool 15  
fill ~2 ~30 ~25 ~15 ~30 ~25 wool 15  
fill ~6 ~30 ~16 ~11 ~30 ~16 wool 15  
fill ~6 ~30 ~17 ~11 ~30 ~17 wool 15  
fill ~6 ~30 ~18 ~11 ~30 ~18 wool 15  
fill ~6 ~30 ~19 ~11 ~30 ~19 wool 15  
fill ~6 ~30 ~20 ~7 ~30 ~20 wool 0  
fill ~6 ~30 ~21 ~7 ~30 ~21 wool 0  
fill ~6 ~30 ~22 ~11 ~30 ~22 wool 15  
fill ~6 ~30 ~23 ~11 ~30 ~23 wool 15  
fill ~8 ~30 ~20 ~9 ~30 ~20 wool 15  
fill ~8 ~30 ~21 ~9 ~30 ~21 wool 15  
fill ~10 ~30 ~20 ~11 ~30 ~20 wool 0  
fill ~10 ~30 ~21 ~11 ~30 ~21 wool 0  
fill ~2 ~31 ~24 ~15 ~31 ~24 wool 15  
fill ~2 ~31 ~25 ~15 ~31 ~25 wool 15  
fill ~6 ~31 ~16 ~11 ~31 ~16 wool 15  
fill ~6 ~31 ~17 ~11 ~31 ~17 wool 15  
fill ~6 ~31 ~18 ~11 ~31 ~18 wool 15  
fill ~6 ~31 ~19 ~11 ~31 ~19 wool 15  
fill ~6 ~31 ~20 ~7 ~31 ~20 wool 0  
fill ~6 ~31 ~21 ~7 ~31 ~21 wool 0  
fill ~6 ~31 ~22 ~11 ~31 ~22 wool 15  
fill ~6 ~31 ~23 ~11 ~31 ~23 wool 15  
fill ~8 ~31 ~20 ~9 ~31 ~20 wool 15  
fill ~8 ~31 ~21 ~9 ~31 ~21 wool 15  
fill ~10 ~31 ~20 ~11 ~31 ~20 wool 0  
fill ~10 ~31 ~21 ~11 ~31 ~21 wool 0  
fill ~2 ~32 ~26 ~15 ~32 ~26 wool 15  
fill ~2 ~32 ~27 ~15 ~32 ~27 wool 15  
fill ~6 ~32 ~14 ~11 ~32 ~14 wool 15  
fill ~6 ~32 ~15 ~11 ~32 ~15 wool 15  
fill ~6 ~32 ~16 ~11 ~32 ~16 wool 15  
fill ~6 ~32 ~17 ~11 ~32 ~17 wool 15  
fill ~6 ~32 ~18 ~7 ~32 ~18 wool 0  
fill ~6 ~32 ~19 ~7 ~32 ~19 wool 0  
fill ~6 ~32 ~20 ~11 ~32 ~20 wool 15  
fill ~6 ~32 ~21 ~11 ~32 ~21 wool 15  
fill ~6 ~32 ~22 ~11 ~32 ~22 wool 15  
fill ~6 ~32 ~23 ~11 ~32 ~23 wool 15  
fill ~8 ~32 ~18 ~9 ~32 ~18 wool 15  
fill ~8 ~32 ~19 ~9 ~32 ~19 wool 15  
fill ~10 ~32 ~18 ~11 ~32 ~18 wool 0  
fill ~10 ~32 ~19 ~11 ~32 ~19 wool 0  
fill ~2 ~33 ~26 ~15 ~33 ~26 wool 15  
fill ~2 ~33 ~27 ~15 ~33 ~27 wool 15  
fill ~6 ~33 ~14 ~11 ~33 ~14 wool 15  
fill ~6 ~33 ~15 ~11 ~33 ~15 wool 15  
fill ~6 ~33 ~16 ~11 ~33 ~16 wool 15  
fill ~6 ~33 ~17 ~11 ~33 ~17 wool 15  
fill ~6 ~33 ~18 ~7 ~33 ~18 wool 0  
fill ~6 ~33 ~19 ~7 ~33 ~19 wool 0  
fill ~6 ~33 ~20 ~11 ~33 ~20 wool 15  
fill ~6 ~33 ~21 ~11 ~33 ~21 wool 15  
fill ~6 ~33 ~22 ~11 ~33 ~22 wool 15  
fill ~6 ~33 ~23 ~11 ~33 ~23 wool 15  
fill ~8 ~33 ~18 ~9 ~33 ~18 wool 15  
fill ~8 ~33 ~19 ~9 ~33 ~19 wool 15  
fill ~10 ~33 ~18 ~11 ~33 ~18 wool 0  
fill ~10 ~33 ~19 ~11 ~33 ~19 wool 0  
fill ~4 ~34 ~28 ~13 ~34 ~28 wool 15  
fill ~4 ~34 ~29 ~13 ~34 ~29 wool 15  
fill ~6 ~34 ~12 ~11 ~34 ~12 wool 15  
fill ~6 ~34 ~13 ~11 ~34 ~13 wool 15  
fill ~6 ~34 ~14 ~11 ~34 ~14 wool 15  
fill ~6 ~34 ~15 ~11 ~34 ~15 wool 15  
fill ~6 ~34 ~16 ~7 ~34 ~16 wool 0  
fill ~6 ~34 ~17 ~7 ~34 ~17 wool 0  
fill ~6 ~34 ~18 ~11 ~34 ~18 wool 15  
fill ~6 ~34 ~19 ~11 ~34 ~19 wool 15  
fill ~6 ~34 ~20 ~11 ~34 ~20 wool 15  
fill ~6 ~34 ~21 ~11 ~34 ~21 wool 15  
fill ~8 ~34 ~16 ~9 ~34 ~16 wool 15  
fill ~8 ~34 ~17 ~9 ~34 ~17 wool 15  
fill ~10 ~34 ~16 ~11 ~34 ~16 wool 0  
fill ~10 ~34 ~17 ~11 ~34 ~17 wool 0  
fill ~4 ~35 ~28 ~13 ~35 ~28 wool 15  
fill ~4 ~35 ~29 ~13 ~35 ~29 wool 15  
fill ~6 ~35 ~12 ~11 ~35 ~12 wool 15  
fill ~6 ~35 ~13 ~11 ~35 ~13 wool 15  
fill ~6 ~35 ~14 ~11 ~35 ~14 wool 15  
fill ~6 ~35 ~15 ~11 ~35 ~15 wool 15  
fill ~6 ~35 ~16 ~7 ~35 ~16 wool 0  
fill ~6 ~35 ~17 ~7 ~35 ~17 wool 0  
fill ~6 ~35 ~18 ~11 ~35 ~18 wool 15  
fill ~6 ~35 ~19 ~11 ~35 ~19 wool 15  
fill ~6 ~35 ~20 ~11 ~35 ~20 wool 15  
fill ~6 ~35 ~21 ~11 ~35 ~21 wool 15  
fill ~8 ~35 ~16 ~9 ~35 ~16 wool 15  
fill ~8 ~35 ~17 ~9 ~35 ~17 wool 15  
fill ~10 ~35 ~16 ~11 ~35 ~16 wool 0  
fill ~10 ~35 ~17 ~11 ~35 ~17 wool 0  
fill ~6 ~36 ~10 ~11 ~36 ~10 wool 15  
fill ~6 ~36 ~11 ~11 ~36 ~11 wool 15  
fill ~6 ~36 ~12 ~11 ~36 ~12 wool 15  
fill ~6 ~36 ~13 ~11 ~36 ~13 wool 15  
fill ~6 ~36 ~14 ~7 ~36 ~14 wool 0  
fill ~6 ~36 ~15 ~7 ~36 ~15 wool 0  
fill ~6 ~36 ~16 ~11 ~36 ~16 wool 15  
fill ~6 ~36 ~17 ~11 ~36 ~17 wool 15  
fill ~6 ~36 ~18 ~11 ~36 ~18 wool 15  
fill ~6 ~36 ~19 ~11 ~36 ~19 wool 15  
fill ~6 ~36 ~30 ~11 ~36 ~30 wool 15  
fill ~6 ~36 ~31 ~11 ~36 ~31 wool 15  
fill ~8 ~36 ~14 ~9 ~36 ~14 wool 15  
fill ~8 ~36 ~15 ~9 ~36 ~15 wool 15  
fill ~10 ~36 ~14 ~11 ~36 ~14 wool 0  
fill ~10 ~36 ~15 ~11 ~36 ~15 wool 0  
fill ~6 ~37 ~10 ~11 ~37 ~10 wool 15  
fill ~6 ~37 ~11 ~11 ~37 ~11 wool 15  
fill ~6 ~37 ~12 ~11 ~37 ~12 wool 15  
fill ~6 ~37 ~13 ~11 ~37 ~13 wool 15  
fill ~6 ~37 ~14 ~7 ~37 ~14 wool 0  
fill ~6 ~37 ~15 ~7 ~37 ~15 wool 0  
fill ~6 ~37 ~16 ~11 ~37 ~16 wool 15  
fill ~6 ~37 ~17 ~11 ~37 ~17 wool 15  
fill ~6 ~37 ~18 ~11 ~37 ~18 wool 15  
fill ~6 ~37 ~19 ~11 ~37 ~19 wool 15  
fill ~6 ~37 ~30 ~11 ~37 ~30 wool 15  
fill ~6 ~37 ~31 ~11 ~37 ~31 wool 15  
fill ~8 ~37 ~14 ~9 ~37 ~14 wool 15  
fill ~8 ~37 ~15 ~9 ~37 ~15 wool 15  
fill ~10 ~37 ~14 ~11 ~37 ~14 wool 0  
fill ~10 ~37 ~15 ~11 ~37 ~15 wool 0  
fill ~6 ~38 ~8 ~11 ~38 ~8 wool 15  
fill ~6 ~38 ~9 ~11 ~38 ~9 wool 15  
fill ~6 ~38 ~10 ~11 ~38 ~10 wool 15  
fill ~6 ~38 ~11 ~11 ~38 ~11 wool 15  
fill ~6 ~38 ~12 ~7 ~38 ~12 wool 0  
fill ~6 ~38 ~13 ~7 ~38 ~13 wool 0  
fill ~6 ~38 ~14 ~11 ~38 ~14 wool 15  
fill ~6 ~38 ~15 ~11 ~38 ~15 wool 15  
fill ~6 ~38 ~16 ~11 ~38 ~16 wool 15  
fill ~6 ~38 ~17 ~11 ~38 ~17 wool 15  
fill ~8 ~38 ~12 ~9 ~38 ~12 wool 15  
fill ~8 ~38 ~13 ~9 ~38 ~13 wool 15  
fill ~10 ~38 ~12 ~11 ~38 ~12 wool 0  
fill ~10 ~38 ~13 ~11 ~38 ~13 wool 0  
fill ~6 ~39 ~8 ~11 ~39 ~8 wool 15  
fill ~6 ~39 ~9 ~11 ~39 ~9 wool 15  
fill ~6 ~39 ~10 ~11 ~39 ~10 wool 15  
fill ~6 ~39 ~11 ~11 ~39 ~11 wool 15  
fill ~6 ~39 ~12 ~7 ~39 ~12 wool 0  
fill ~6 ~39 ~13 ~7 ~39 ~13 wool 0  
fill ~6 ~39 ~14 ~11 ~39 ~14 wool 15  
fill ~6 ~39 ~15 ~11 ~39 ~15 wool 15  
fill ~6 ~39 ~16 ~11 ~39 ~16 wool 15  
fill ~6 ~39 ~17 ~11 ~39 ~17 wool 15  
fill ~8 ~39 ~12 ~9 ~39 ~12 wool 15  
fill ~8 ~39 ~13 ~9 ~39 ~13 wool 15  
fill ~10 ~39 ~12 ~11 ~39 ~12 wool 0  
fill ~10 ~39 ~13 ~11 ~39 ~13 wool 0  
fill ~6 ~40 ~6 ~11 ~40 ~6 wool 15  
fill ~6 ~40 ~7 ~11 ~40 ~7 wool 15  
fill ~6 ~40 ~8 ~11 ~40 ~8 wool 15  
fill ~6 ~40 ~9 ~11 ~40 ~9 wool 15  
fill ~6 ~40 ~10 ~7 ~40 ~10 wool 0  
fill ~6 ~40 ~11 ~7 ~40 ~11 wool 0  
fill ~6 ~40 ~12 ~11 ~40 ~12 wool 15  
fill ~6 ~40 ~13 ~11 ~40 ~13 wool 15  
fill ~6 ~40 ~14 ~11 ~40 ~14 wool 15  
fill ~6 ~40 ~15 ~11 ~40 ~15 wool 15  
fill ~8 ~40 ~10 ~9 ~40 ~10 wool 15  
fill ~8 ~40 ~11 ~9 ~40 ~11 wool 15  
fill ~10 ~40 ~10 ~11 ~40 ~10 wool 0  
fill ~10 ~40 ~11 ~11 ~40 ~11 wool 0  
fill ~6 ~41 ~6 ~11 ~41 ~6 wool 15  
fill ~6 ~41 ~7 ~11 ~41 ~7 wool 15  
fill ~6 ~41 ~8 ~11 ~41 ~8 wool 15  
fill ~6 ~41 ~9 ~11 ~41 ~9 wool 15  
fill ~6 ~41 ~10 ~7 ~41 ~10 wool 0  
fill ~6 ~41 ~11 ~7 ~41 ~11 wool 0  
fill ~6 ~41 ~12 ~11 ~41 ~12 wool 15  
fill ~6 ~41 ~13 ~11 ~41 ~13 wool 15  
fill ~6 ~41 ~14 ~11 ~41 ~14 wool 15  
fill ~6 ~41 ~15 ~11 ~41 ~15 wool 15  
fill ~8 ~41 ~10 ~9 ~41 ~10 wool 15  
fill ~8 ~41 ~11 ~9 ~41 ~11 wool 15  
fill ~10 ~41 ~10 ~11 ~41 ~10 wool 0  
fill ~10 ~41 ~11 ~11 ~41 ~11 wool 0  
fill ~6 ~42 ~4 ~11 ~42 ~4 wool 15  
fill ~6 ~42 ~5 ~11 ~42 ~5 wool 15  
fill ~6 ~42 ~6 ~11 ~42 ~6 wool 15  
fill ~6 ~42 ~7 ~11 ~42 ~7 wool 15  
fill ~6 ~42 ~8 ~7 ~42 ~8 wool 0  
fill ~6 ~42 ~9 ~7 ~42 ~9 wool 0  
fill ~6 ~42 ~10 ~11 ~42 ~10 wool 15  
fill ~6 ~42 ~11 ~11 ~42 ~11 wool 15  
fill ~6 ~42 ~12 ~11 ~42 ~12 wool 15  
fill ~6 ~42 ~13 ~11 ~42 ~13 wool 15  
fill ~8 ~42 ~8 ~9 ~42 ~8 wool 15  
fill ~8 ~42 ~9 ~9 ~42 ~9 wool 15  
fill ~10 ~42 ~8 ~11 ~42 ~8 wool 0  
fill ~10 ~42 ~9 ~11 ~42 ~9 wool 0  
fill ~6 ~43 ~4 ~11 ~43 ~4 wool 15  
fill ~6 ~43 ~5 ~11 ~43 ~5 wool 15  
fill ~6 ~43 ~6 ~11 ~43 ~6 wool 15  
fill ~6 ~43 ~7 ~11 ~43 ~7 wool 15  
fill ~6 ~43 ~8 ~7 ~43 ~8 wool 0  
fill ~6 ~43 ~9 ~7 ~43 ~9 wool 0  
fill ~6 ~43 ~10 ~11 ~43 ~10 wool 15  
fill ~6 ~43 ~11 ~11 ~43 ~11 wool 15  
fill ~6 ~43 ~12 ~11 ~43 ~12 wool 15  
fill ~6 ~43 ~13 ~11 ~43 ~13 wool 15  
fill ~8 ~43 ~8 ~9 ~43 ~8 wool 15  
fill ~8 ~43 ~9 ~9 ~43 ~9 wool 15  
fill ~10 ~43 ~8 ~11 ~43 ~8 wool 0  
fill ~10 ~43 ~9 ~11 ~43 ~9 wool 0  
fill ~6 ~44 ~2 ~11 ~44 ~2 wool 15  
fill ~6 ~44 ~3 ~11 ~44 ~3 wool 15  
fill ~6 ~44 ~4 ~11 ~44 ~4 wool 15  
fill ~6 ~44 ~5 ~11 ~44 ~5 wool 15  
fill ~6 ~44 ~6 ~7 ~44 ~6 wool 0  
fill ~6 ~44 ~7 ~7 ~44 ~7 wool 0  
fill ~6 ~44 ~8 ~11 ~44 ~8 wool 15  
fill ~6 ~44 ~9 ~11 ~44 ~9 wool 15  
fill ~6 ~44 ~10 ~11 ~44 ~10 wool 15  
fill ~6 ~44 ~11 ~11 ~44 ~11 wool 15  
fill ~8 ~44 ~6 ~9 ~44 ~6 wool 15  
fill ~8 ~44 ~7 ~9 ~44 ~7 wool 15  
fill ~10 ~44 ~6 ~11 ~44 ~6 wool 0  
fill ~10 ~44 ~7 ~11 ~44 ~7 wool 0  
fill ~6 ~45 ~2 ~11 ~45 ~2 wool 15  
fill ~6 ~45 ~3 ~11 ~45 ~3 wool 15  
fill ~6 ~45 ~4 ~11 ~45 ~4 wool 15  
fill ~6 ~45 ~5 ~11 ~45 ~5 wool 15  
fill ~6 ~45 ~6 ~7 ~45 ~6 wool 0  
fill ~6 ~45 ~7 ~7 ~45 ~7 wool 0  
fill ~6 ~45 ~8 ~11 ~45 ~8 wool 15  
fill ~6 ~45 ~9 ~11 ~45 ~9 wool 15  
fill ~6 ~45 ~10 ~11 ~45 ~10 wool 15  
fill ~6 ~45 ~11 ~11 ~45 ~11 wool 15  
fill ~8 ~45 ~6 ~9 ~45 ~6 wool 15  
fill ~8 ~45 ~7 ~9 ~45 ~7 wool 15  
fill ~10 ~45 ~6 ~11 ~45 ~6 wool 0  
fill ~10 ~45 ~7 ~11 ~45 ~7 wool 0  
fill ~6 ~46 ~2 ~11 ~46 ~2 wool 15  
fill ~6 ~46 ~3 ~11 ~46 ~3 wool 15  
fill ~6 ~46 ~4 ~7 ~46 ~4 wool 0  
fill ~6 ~46 ~5 ~7 ~46 ~5 wool 0  
fill ~6 ~46 ~6 ~11 ~46 ~6 wool 15  
fill ~6 ~46 ~7 ~11 ~46 ~7 wool 15  
fill ~6 ~46 ~8 ~11 ~46 ~8 wool 15  
fill ~6 ~46 ~9 ~11 ~46 ~9 wool 15  
fill ~8 ~46 ~4 ~9 ~46 ~4 wool 15  
fill ~8 ~46 ~5 ~9 ~46 ~5 wool 15  
fill ~10 ~46 ~4 ~11 ~46 ~4 wool 0  
fill ~10 ~46 ~5 ~11 ~46 ~5 wool 0  
fill ~6 ~47 ~2 ~11 ~47 ~2 wool 15  
fill ~6 ~47 ~3 ~11 ~47 ~3 wool 15  
fill ~6 ~47 ~4 ~7 ~47 ~4 wool 0  
fill ~6 ~47 ~5 ~7 ~47 ~5 wool 0  
fill ~6 ~47 ~6 ~11 ~47 ~6 wool 15  
fill ~6 ~47 ~7 ~11 ~47 ~7 wool 15  
fill ~6 ~47 ~8 ~11 ~47 ~8 wool 15  
fill ~6 ~47 ~9 ~11 ~47 ~9 wool 15  
fill ~8 ~47 ~4 ~9 ~47 ~4 wool 15  
fill ~8 ~47 ~5 ~9 ~47 ~5 wool 15  
fill ~10 ~47 ~4 ~11 ~47 ~4 wool 0  
fill ~10 ~47 ~5 ~11 ~47 ~5 wool 0  
fill ~6 ~48 ~0 ~11 ~48 ~0 wool 15  
fill ~6 ~48 ~1 ~11 ~48 ~1 wool 15  
fill ~6 ~48 ~2 ~11 ~48 ~2 wool 0  
fill ~6 ~48 ~3 ~11 ~48 ~3 wool 0  
fill ~6 ~48 ~4 ~11 ~48 ~4 wool 15  
fill ~6 ~48 ~5 ~11 ~48 ~5 wool 15  
fill ~6 ~48 ~6 ~11 ~48 ~6 wool 15  
summon minecraft:slime ~7.68716813098 ~0.0 ~27.6672089896 
summon minecraft:cow ~11.8104146947 ~0.0 ~4.14847886859  
fill ~6 ~48 ~7 ~11 ~48 ~7 wool 15  
fill ~6 ~49 ~0 ~11 ~49 ~0 wool 15  
fill ~6 ~49 ~1 ~11 ~49 ~1 wool 15  
fill ~6 ~49 ~2 ~11 ~49 ~2 wool 0  
fill ~6 ~49 ~3 ~11 ~49 ~3 wool 0  
fill ~6 ~49 ~4 ~11 ~49 ~4 wool 15  
fill ~6 ~49 ~5 ~11 ~49 ~5 wool 15  
fill ~6 ~49 ~6 ~11 ~49 ~6 wool 15  
fill ~6 ~49 ~7 ~11 ~49 ~7 wool 15  
fill ~6 ~50 ~0 ~11 ~50 ~0 wool 0  
fill ~6 ~50 ~1 ~11 ~50 ~1 wool 0  
fill ~6 ~50 ~2 ~11 ~50 ~2 wool 15  
fill ~6 ~50 ~3 ~11 ~50 ~3 wool 15  
fill ~6 ~51 ~0 ~11 ~51 ~0 wool 0  
fill ~6 ~51 ~1 ~11 ~51 ~1 wool 0  
fill ~6 ~51 ~2 ~11 ~51 ~2 wool 15  
fill ~6 ~51 ~3 ~11 ~51 ~3 wool 15    