setblock ~45 ~8 ~68 furnace 5  
setblock ~42 ~12 ~74 chest 2  
setblock ~41 ~14 ~75 chest 2  
setblock ~44 ~12 ~76 chest 2  
setblock ~43 ~14 ~77 chest 2  
setblock ~46 ~12 ~78 trapped_chest 2  
setblock ~45 ~8 ~72 furnace 2  
setblock ~41 ~13 ~74 chest 2  
setblock ~43 ~13 ~76 chest 2  
setblock ~46 ~11 ~77 chest 2  
setblock ~45 ~13 ~78 chest 2  
setblock ~42 ~14 ~76 chest 2  
setblock ~41 ~12 ~73 chest 2  
setblock ~44 ~14 ~78 chest 2  
setblock ~43 ~12 ~75 chest 2  
setblock ~45 ~12 ~77 chest 2  
setblock ~42 ~13 ~75 chest 2  
setblock ~44 ~13 ~77 chest 2  
setblock ~44 ~19 ~80 chest 2  
setblock ~46 ~13 ~79 chest 2  
setblock ~47 ~22 ~63 hopper 0  
setblock ~49 ~8 ~68 furnace 2  
setblock ~50 ~12 ~76 chest 2  
setblock ~51 ~14 ~77 chest 2  
setblock ~48 ~12 ~78 trapped_chest 2  
setblock ~52 ~12 ~74 chest 2  
setblock ~53 ~14 ~75 chest 2  
setblock ~49 ~8 ~72 furnace 4  
setblock ~47 ~12 ~78 chest 2  
setblock ~51 ~13 ~76 chest 2  
setblock ~48 ~11 ~77 chest 2  
setblock ~49 ~13 ~78 chest 2  
setblock ~53 ~13 ~74 chest 2  
setblock ~51 ~12 ~75 chest 2  
setblock ~49 ~12 ~77 chest 2  
setblock ~50 ~14 ~78 chest 2  
setblock ~53 ~12 ~73 chest 2  
setblock ~52 ~14 ~76 chest 2  
setblock ~50 ~13 ~77 chest 2  
setblock ~48 ~13 ~79 chest 2  
setblock ~52 ~13 ~75 chest 2  
setblock ~47 ~13 ~79 trapped_chest 2  
setblock ~50 ~19 ~80 chest 2 
setblock ~72 ~-5 ~34 sea_lantern 0  
fill ~74 ~-5 ~34 ~77 ~-5 ~34 stained_hardened_clay 8 
setblock ~75 ~-5 ~33 sea_lantern 0  
fill ~77 ~-5 ~35 ~78 ~-5 ~35 stained_hardened_clay 8  
fill ~77 ~-5 ~36 ~79 ~-5 ~36 stained_hardened_clay 8 
setblock ~78 ~-5 ~34 sea_lantern 0  
fill ~79 ~-5 ~37 ~80 ~-5 ~37 stained_hardened_clay 8 
setblock ~81 ~-5 ~37 sea_lantern 0 
setblock ~81 ~-5 ~38 stained_hardened_clay 8  
fill ~82 ~-5 ~39 ~83 ~-5 ~39 stained_hardened_clay 8  
fill ~82 ~-5 ~40 ~82 ~-2 ~40 stained_hardened_clay 15  
fill ~83 ~-5 ~40 ~84 ~-5 ~40 stained_hardened_clay 8  
fill ~83 ~-5 ~41 ~83 ~-2 ~41 stained_hardened_clay 15 
setblock ~84 ~-5 ~39 sea_lantern 0  
fill ~84 ~-5 ~41 ~85 ~-5 ~41 stained_hardened_clay 8  
fill ~84 ~-5 ~42 ~84 ~-2 ~42 stained_hardened_clay 15 
setblock ~84 ~-5 ~53 sea_lantern 0  
fill ~85 ~-5 ~42 ~86 ~-5 ~42 stained_hardened_clay 8  
fill ~85 ~-5 ~43 ~86 ~-5 ~43 stained_hardened_clay 8  
fill ~85 ~-5 ~44 ~86 ~-5 ~44 stained_hardened_clay 8  
fill ~85 ~-5 ~45 ~85 ~-2 ~45 stained_hardened_clay 15 
setblock ~85 ~-5 ~50 sea_lantern 0  
fill ~86 ~-5 ~45 ~87 ~-5 ~45 stained_hardened_clay 8  
fill ~86 ~-5 ~46 ~87 ~-5 ~46 stained_hardened_clay 8  
fill ~86 ~-5 ~49 ~88 ~-5 ~49 stained_hardened_clay 8  
fill ~86 ~-5 ~50 ~87 ~-5 ~50 stained_hardened_clay 8 
setblock ~87 ~-5 ~44 sea_lantern 0  
fill ~87 ~-5 ~47 ~88 ~-5 ~47 stained_hardened_clay 8  
fill ~87 ~-5 ~48 ~88 ~-5 ~48 stained_hardened_clay 8 
setblock ~87 ~-5 ~51 sea_lantern 0 
setblock ~42 ~-4 ~85 sea_lantern 0 
setblock ~47 ~-4 ~81 sea_lantern 0 
setblock ~69 ~-4 ~34 sea_lantern 0  
fill ~71 ~-4 ~34 ~73 ~-4 ~34 stained_hardened_clay 8  
fill ~72 ~-4 ~33 ~75 ~-4 ~33 stained_hardened_clay 8  
fill ~74 ~-4 ~32 ~75 ~-4 ~32 stained_hardened_clay 15  
fill ~75 ~-4 ~34 ~76 ~-4 ~34 stained_hardened_clay 8  
fill ~76 ~-4 ~33 ~77 ~-4 ~33 stained_hardened_clay 15  
fill ~77 ~-4 ~34 ~78 ~-4 ~34 stained_hardened_clay 15  
fill ~77 ~-4 ~35 ~79 ~-4 ~35 stained_hardened_clay 15  
fill ~77 ~-4 ~36 ~77 ~-5 ~36 stained_hardened_clay 8  
fill ~78 ~-4 ~36 ~80 ~-4 ~36 stained_hardened_clay 15  
fill ~78 ~-4 ~37 ~82 ~-4 ~37 stained_hardened_clay 15  
fill ~79 ~-4 ~38 ~84 ~-4 ~38 stained_hardened_clay 15  
fill ~81 ~-4 ~39 ~85 ~-4 ~39 stained_hardened_clay 15  
fill ~81 ~-4 ~40 ~81 ~-2 ~40 stained_hardened_clay 15  
fill ~81 ~-4 ~41 ~86 ~-4 ~41 stained_hardened_clay 15  
fill ~81 ~-4 ~42 ~87 ~-4 ~42 stained_hardened_clay 15  
fill ~82 ~-4 ~43 ~88 ~-4 ~43 stained_hardened_clay 15  
fill ~83 ~-4 ~40 ~86 ~-4 ~40 stained_hardened_clay 15  
fill ~83 ~-4 ~44 ~89 ~-4 ~44 stained_hardened_clay 15 
setblock ~84 ~-4 ~45 stained_hardened_clay 15  
fill ~84 ~-4 ~52 ~86 ~-4 ~52 stained_hardened_clay 8  
fill ~84 ~-4 ~53 ~85 ~-4 ~53 stained_hardened_clay 8 
setblock ~84 ~-4 ~56 sea_lantern 0  
fill ~85 ~-4 ~46 ~90 ~-4 ~46 stained_hardened_clay 15  
fill ~85 ~-4 ~49 ~89 ~-4 ~49 stained_hardened_clay 15  
fill ~85 ~-4 ~50 ~89 ~-4 ~50 stained_hardened_clay 15  
fill ~85 ~-4 ~51 ~86 ~-4 ~51 stained_hardened_clay 8  
fill ~86 ~-4 ~45 ~89 ~-4 ~45 stained_hardened_clay 15  
fill ~87 ~-4 ~47 ~90 ~-4 ~47 stained_hardened_clay 15  
fill ~87 ~-4 ~48 ~90 ~-4 ~48 stained_hardened_clay 15  
fill ~87 ~-4 ~51 ~87 ~-3 ~51 stained_hardened_clay 15  
fill ~21 ~-3 ~42 ~24 ~-3 ~42 stained_hardened_clay 8  
fill ~33 ~-3 ~82 ~33 ~-2 ~82 stained_hardened_clay 8  
fill ~34 ~-3 ~83 ~34 ~-2 ~83 stained_hardened_clay 8 
setblock ~34 ~-3 ~85 sea_lantern 0  
fill ~35 ~-3 ~84 ~35 ~-2 ~84 stained_hardened_clay 8  
fill ~36 ~-3 ~85 ~36 ~-2 ~85 stained_hardened_clay 8 
setblock ~37 ~-3 ~53 sea_lantern 0 
setblock ~37 ~-3 ~85 sea_lantern 0  
fill ~37 ~-3 ~86 ~37 ~-2 ~86 stained_hardened_clay 8 
setblock ~37 ~-3 ~87 sea_lantern 0  
fill ~38 ~-3 ~51 ~38 ~-3 ~53 stained_hardened_clay 8  
fill ~38 ~-3 ~87 ~38 ~-2 ~87 stained_hardened_clay 8  
fill ~39 ~-3 ~88 ~39 ~-2 ~88 stained_hardened_clay 8 
setblock ~40 ~-3 ~64 sea_lantern 0  
fill ~40 ~-3 ~65 ~40 ~-2 ~65 stained_hardened_clay 8  
fill ~40 ~-3 ~87 ~41 ~-3 ~87 stained_hardened_clay 8 
setblock ~40 ~-3 ~88 sea_lantern 0 
setblock ~41 ~-3 ~86 sea_lantern 0  
fill ~42 ~-3 ~86 ~42 ~-2 ~86 stained_hardened_clay 8  
fill ~43 ~-3 ~85 ~43 ~-2 ~85 stained_hardened_clay 8 
setblock ~44 ~-3 ~26 sea_lantern 0  
fill ~44 ~-3 ~84 ~44 ~-2 ~84 stained_hardened_clay 8 
setblock ~45 ~-3 ~24 sea_lantern 0  
fill ~45 ~-3 ~25 ~45 ~-3 ~28 stained_hardened_clay 8 
setblock ~45 ~-3 ~29 sea_lantern 0 
setblock ~45 ~-3 ~72 sea_lantern 0 
setblock ~45 ~-3 ~82 sea_lantern 0  
fill ~45 ~-3 ~83 ~45 ~-2 ~83 stained_hardened_clay 8 
setblock ~45 ~-3 ~84 sea_lantern 0 
setblock ~46 ~-3 ~26 sea_lantern 0  
fill ~46 ~-3 ~82 ~46 ~-2 ~82 stained_hardened_clay 8  
fill ~47 ~-3 ~76 ~47 ~-2 ~76 stained_hardened_clay 8 
setblock ~47 ~-3 ~78 sea_lantern 0  
fill ~47 ~-3 ~81 ~47 ~-2 ~81 stained_hardened_clay 8 
setblock ~48 ~-3 ~75 sea_lantern 0  
fill ~48 ~-3 ~77 ~48 ~-2 ~77 stained_hardened_clay 8  
fill ~48 ~-3 ~78 ~48 ~-2 ~78 stained_hardened_clay 8  
fill ~48 ~-3 ~79 ~48 ~-2 ~79 stained_hardened_clay 8  
fill ~48 ~-3 ~80 ~48 ~-2 ~80 stained_hardened_clay 8 
setblock ~49 ~-3 ~79 sea_lantern 0  
fill ~69 ~-3 ~33 ~71 ~-3 ~33 stained_hardened_clay 8  
fill ~69 ~-3 ~34 ~70 ~-3 ~34 stained_hardened_clay 8  
fill ~70 ~-3 ~32 ~74 ~-3 ~32 stained_hardened_clay 15  
fill ~71 ~-3 ~34 ~77 ~-3 ~34 stained_hardened_clay 15  
fill ~72 ~-3 ~33 ~75 ~-3 ~33 stained_hardened_clay 15  
fill ~73 ~-3 ~35 ~78 ~-3 ~35 stained_hardened_clay 15  
fill ~75 ~-3 ~36 ~79 ~-3 ~36 stained_hardened_clay 15  
fill ~76 ~-3 ~37 ~80 ~-3 ~37 stained_hardened_clay 15  
fill ~77 ~-3 ~38 ~81 ~-3 ~38 stained_hardened_clay 15  
fill ~78 ~-3 ~39 ~83 ~-3 ~39 stained_hardened_clay 15  
fill ~79 ~-3 ~40 ~84 ~-3 ~40 stained_hardened_clay 15  
fill ~80 ~-3 ~41 ~85 ~-3 ~41 stained_hardened_clay 15  
fill ~82 ~-3 ~42 ~86 ~-3 ~42 stained_hardened_clay 15  
fill ~82 ~-3 ~54 ~83 ~-3 ~54 stained_hardened_clay 15  
fill ~82 ~-3 ~55 ~82 ~-3 ~54 stained_hardened_clay 15  
fill ~83 ~-3 ~43 ~87 ~-3 ~43 stained_hardened_clay 15  
fill ~83 ~-3 ~52 ~87 ~-3 ~52 stained_hardened_clay 15  
fill ~83 ~-3 ~53 ~86 ~-3 ~53 stained_hardened_clay 15  
fill ~83 ~-3 ~55 ~84 ~-3 ~55 stained_hardened_clay 8  
fill ~83 ~-3 ~56 ~84 ~-3 ~56 stained_hardened_clay 8  
fill ~84 ~-3 ~51 ~88 ~-3 ~51 stained_hardened_clay 15 
setblock ~84 ~-3 ~54 stained_hardened_clay 8  
fill ~85 ~-3 ~44 ~88 ~-3 ~44 stained_hardened_clay 15  
fill ~85 ~-3 ~46 ~89 ~-3 ~46 stained_hardened_clay 15  
fill ~85 ~-3 ~49 ~89 ~-3 ~49 stained_hardened_clay 15  
fill ~85 ~-3 ~50 ~88 ~-3 ~50 stained_hardened_clay 15  
fill ~85 ~-3 ~54 ~86 ~-3 ~54 stained_hardened_clay 15  
fill ~85 ~-3 ~55 ~85 ~-1 ~55 stained_hardened_clay 15  
fill ~86 ~-3 ~45 ~89 ~-3 ~45 stained_hardened_clay 15  
fill ~86 ~-3 ~47 ~89 ~-3 ~47 stained_hardened_clay 15  
fill ~86 ~-3 ~48 ~89 ~-3 ~48 stained_hardened_clay 15  
fill ~19 ~-2 ~42 ~20 ~-2 ~42 stained_hardened_clay 8 
setblock ~20 ~-2 ~41 sea_lantern 0 
setblock ~20 ~-2 ~43 sea_lantern 0  
fill ~21 ~-2 ~41 ~24 ~-2 ~41 stained_hardened_clay 8  
fill ~21 ~-2 ~42 ~24 ~-2 ~42 stained_hardened_clay 15  
fill ~21 ~-2 ~43 ~24 ~-2 ~43 stained_hardened_clay 8 
setblock ~25 ~-2 ~41 sea_lantern 0  
fill ~25 ~-2 ~42 ~26 ~-2 ~42 stained_hardened_clay 8 
setblock ~25 ~-2 ~43 sea_lantern 0  
fill ~28 ~-2 ~74 ~28 ~-1 ~74 stained_hardened_clay 15 
setblock ~30 ~-2 ~79 sea_lantern 0  
fill ~30 ~-2 ~80 ~31 ~-2 ~80 stained_hardened_clay 8  
fill ~31 ~-2 ~81 ~32 ~-2 ~81 stained_hardened_clay 8 
setblock ~31 ~-2 ~82 sea_lantern 0 
setblock ~32 ~-2 ~82 stained_hardened_clay 8 
setblock ~33 ~-2 ~83 stained_hardened_clay 8 
setblock ~34 ~-2 ~84 stained_hardened_clay 8 
setblock ~35 ~-2 ~85 stained_hardened_clay 8 
setblock ~36 ~-2 ~86 stained_hardened_clay 8 
setblock ~37 ~-2 ~50 sea_lantern 0  
fill ~37 ~-2 ~51 ~37 ~-2 ~53 stained_hardened_clay 8 
setblock ~37 ~-2 ~56 sea_lantern 0 
setblock ~37 ~-2 ~87 stained_hardened_clay 8 
setblock ~38 ~-2 ~50 stained_hardened_clay 8  
fill ~38 ~-2 ~51 ~39 ~-2 ~51 stained_hardened_clay 15  
fill ~38 ~-2 ~52 ~39 ~-2 ~52 stained_hardened_clay 15  
fill ~38 ~-2 ~53 ~39 ~-2 ~53 stained_hardened_clay 15  
fill ~38 ~-2 ~54 ~38 ~-2 ~56 stained_hardened_clay 8 
setblock ~38 ~-2 ~86 stained_hardened_clay 8 
setblock ~38 ~-2 ~88 stained_hardened_clay 8 
setblock ~39 ~-2 ~62 sea_lantern 0 
setblock ~39 ~-2 ~65 sea_lantern 0  
fill ~39 ~-2 ~66 ~41 ~-2 ~66 stained_hardened_clay 8  
fill ~39 ~-2 ~68 ~40 ~-2 ~68 stained_hardened_clay 8 
setblock ~39 ~-2 ~69 sea_lantern 0  
fill ~39 ~-2 ~87 ~42 ~-2 ~87 stained_hardened_clay 8  
fill ~39 ~-2 ~89 ~40 ~-2 ~89 stained_hardened_clay 8  
fill ~40 ~-2 ~62 ~40 ~-2 ~69 stained_hardened_clay 8  
fill ~40 ~-2 ~88 ~41 ~-2 ~88 stained_hardened_clay 8 
setblock ~41 ~-2 ~68 sea_lantern 0  
fill ~41 ~-2 ~69 ~41 ~-2 ~72 stained_hardened_clay 8 
setblock ~41 ~-2 ~73 sea_lantern 0 
setblock ~41 ~-2 ~86 stained_hardened_clay 8  
fill ~42 ~-2 ~71 ~42 ~-2 ~73 stained_hardened_clay 8 
setblock ~42 ~-2 ~85 stained_hardened_clay 8  
fill ~43 ~-2 ~72 ~44 ~-2 ~72 stained_hardened_clay 8  
fill ~43 ~-2 ~73 ~45 ~-2 ~73 stained_hardened_clay 8 
setblock ~43 ~-2 ~84 stained_hardened_clay 8 
setblock ~43 ~-2 ~86 stained_hardened_clay 8  
fill ~44 ~-2 ~25 ~44 ~-2 ~28 stained_hardened_clay 8  
fill ~44 ~-2 ~74 ~46 ~-2 ~74 stained_hardened_clay 8 
setblock ~44 ~-2 ~75 sea_lantern 0 
setblock ~44 ~-2 ~83 stained_hardened_clay 8 
setblock ~44 ~-2 ~85 stained_hardened_clay 8  
fill ~45 ~-2 ~23 ~45 ~-2 ~24 stained_hardened_clay 8  
fill ~45 ~-2 ~25 ~45 ~2 ~25 stained_hardened_clay 15  
fill ~45 ~-2 ~26 ~45 ~1 ~26 stained_hardened_clay 15  
fill ~45 ~-2 ~27 ~45 ~1 ~27 stained_hardened_clay 15  
fill ~45 ~-2 ~28 ~45 ~2 ~28 stained_hardened_clay 15  
fill ~45 ~-2 ~29 ~45 ~-2 ~30 stained_hardened_clay 8  
fill ~45 ~-2 ~75 ~47 ~-2 ~75 stained_hardened_clay 8 
setblock ~45 ~-2 ~82 stained_hardened_clay 8 
setblock ~45 ~-2 ~84 stained_hardened_clay 8  
fill ~46 ~-2 ~25 ~46 ~-2 ~28 stained_hardened_clay 8 
setblock ~46 ~-2 ~76 stained_hardened_clay 8 
setblock ~46 ~-2 ~81 stained_hardened_clay 8 
setblock ~46 ~-2 ~83 stained_hardened_clay 8  
fill ~47 ~-2 ~77 ~47 ~-2 ~82 stained_hardened_clay 8 
setblock ~48 ~-2 ~76 stained_hardened_clay 8 
setblock ~48 ~-2 ~81 stained_hardened_clay 8  
fill ~49 ~-2 ~77 ~49 ~-2 ~80 stained_hardened_clay 8 
setblock ~65 ~-2 ~35 sea_lantern 0 
setblock ~67 ~-2 ~33 sea_lantern 0  
fill ~68 ~-2 ~32 ~73 ~-2 ~32 stained_hardened_clay 15  
fill ~68 ~-2 ~33 ~68 ~-2 ~34 stained_hardened_clay 8  
fill ~69 ~-2 ~31 ~71 ~-2 ~31 stained_hardened_clay 15  
fill ~69 ~-2 ~33 ~74 ~-2 ~33 stained_hardened_clay 15  
fill ~69 ~-2 ~34 ~76 ~-2 ~34 stained_hardened_clay 15  
fill ~73 ~-2 ~35 ~77 ~-2 ~35 stained_hardened_clay 15  
fill ~75 ~-2 ~36 ~78 ~-2 ~36 stained_hardened_clay 15  
fill ~76 ~-2 ~37 ~79 ~-2 ~37 stained_hardened_clay 15  
fill ~77 ~-2 ~38 ~80 ~-2 ~38 stained_hardened_clay 15  
fill ~78 ~-2 ~39 ~81 ~-2 ~39 stained_hardened_clay 15  
fill ~79 ~-2 ~40 ~82 ~-2 ~40 stained_hardened_clay 15 
setblock ~82 ~-2 ~41 stained_hardened_clay 15 
setblock ~83 ~-2 ~42 stained_hardened_clay 15  
fill ~83 ~-2 ~54 ~85 ~-2 ~54 stained_hardened_clay 15  
fill ~83 ~-2 ~55 ~85 ~-2 ~55 stained_hardened_clay 15  
fill ~83 ~-2 ~56 ~85 ~-2 ~56 stained_hardened_clay 15 
setblock ~83 ~-2 ~57 sea_lantern 0  
fill ~83 ~-2 ~67 ~83 ~-1 ~67 stained_hardened_clay 15  
fill ~84 ~-2 ~43 ~86 ~-2 ~43 stained_hardened_clay 15  
fill ~84 ~-2 ~52 ~86 ~-2 ~52 stained_hardened_clay 15  
fill ~84 ~-2 ~53 ~85 ~-2 ~53 stained_hardened_clay 15  
fill ~84 ~-2 ~57 ~84 ~-1 ~57 stained_hardened_clay 8 
setblock ~85 ~-2 ~42 stained_hardened_clay 15  
fill ~85 ~-2 ~44 ~87 ~-2 ~44 stained_hardened_clay 15  
fill ~85 ~-2 ~50 ~87 ~-2 ~50 stained_hardened_clay 15  
fill ~85 ~-2 ~51 ~86 ~-2 ~51 stained_hardened_clay 15  
fill ~86 ~-2 ~45 ~87 ~-2 ~45 stained_hardened_clay 15  
fill ~86 ~-2 ~46 ~87 ~-2 ~46 stained_hardened_clay 15  
fill ~86 ~-2 ~49 ~87 ~-2 ~49 stained_hardened_clay 15  
fill ~87 ~-2 ~47 ~88 ~-2 ~47 stained_hardened_clay 15  
fill ~87 ~-2 ~48 ~88 ~-2 ~48 stained_hardened_clay 15 
setblock ~17 ~-1 ~42 sea_lantern 0 
setblock ~18 ~-1 ~42 stained_hardened_clay 8  
fill ~19 ~-1 ~41 ~21 ~-1 ~41 stained_hardened_clay 8  
fill ~19 ~-1 ~42 ~26 ~-1 ~42 stained_hardened_clay 15  
fill ~19 ~-1 ~43 ~21 ~-1 ~43 stained_hardened_clay 8  
fill ~22 ~-1 ~40 ~24 ~-1 ~40 stained_hardened_clay 15  
fill ~22 ~-1 ~41 ~24 ~-1 ~41 stained_hardened_clay 15  
fill ~22 ~-1 ~43 ~24 ~-1 ~43 stained_hardened_clay 15  
fill ~22 ~-1 ~44 ~24 ~-1 ~44 stained_hardened_clay 15  
fill ~25 ~-1 ~41 ~26 ~-1 ~41 stained_hardened_clay 8  
fill ~25 ~-1 ~43 ~26 ~-1 ~43 stained_hardened_clay 8 
setblock ~27 ~-1 ~42 stained_hardened_clay 8 
setblock ~28 ~-1 ~42 sea_lantern 0  
fill ~28 ~-1 ~75 ~29 ~-1 ~75 stained_hardened_clay 15  
fill ~28 ~-1 ~76 ~28 ~-1 ~77 stained_hardened_clay 15  
fill ~29 ~-1 ~73 ~34 ~-1 ~73 stained_hardened_clay 15  
fill ~29 ~-1 ~74 ~35 ~-1 ~74 stained_hardened_clay 15 
setblock ~29 ~-1 ~76 stained_hardened_clay 8  
fill ~30 ~-1 ~72 ~33 ~-1 ~72 stained_hardened_clay 15  
fill ~30 ~-1 ~75 ~32 ~-1 ~75 stained_hardened_clay 8  
fill ~30 ~-1 ~80 ~34 ~-1 ~80 stained_hardened_clay 15  
fill ~30 ~-1 ~81 ~30 ~0 ~81 stained_hardened_clay 15  
fill ~31 ~-1 ~78 ~31 ~0 ~78 stained_hardened_clay 8  
fill ~31 ~-1 ~79 ~35 ~-1 ~79 stained_hardened_clay 15  
fill ~31 ~-1 ~81 ~31 ~-2 ~81 stained_hardened_clay 8  
fill ~31 ~-1 ~82 ~35 ~-1 ~82 stained_hardened_clay 15  
fill ~31 ~-1 ~83 ~36 ~-1 ~83 stained_hardened_clay 15 
setblock ~32 ~-1 ~76 sea_lantern 0  
fill ~32 ~-1 ~77 ~32 ~0 ~77 stained_hardened_clay 8  
fill ~32 ~-1 ~78 ~36 ~-1 ~78 stained_hardened_clay 15  
fill ~32 ~-1 ~81 ~34 ~-1 ~81 stained_hardened_clay 15  
fill ~32 ~-1 ~84 ~37 ~-1 ~84 stained_hardened_clay 15  
fill ~33 ~-1 ~75 ~36 ~-1 ~75 stained_hardened_clay 15 
setblock ~33 ~-1 ~76 stained_hardened_clay 8  
fill ~33 ~-1 ~77 ~36 ~-1 ~77 stained_hardened_clay 15  
fill ~33 ~-1 ~85 ~46 ~-1 ~85 stained_hardened_clay 15  
fill ~34 ~-1 ~76 ~36 ~-1 ~76 stained_hardened_clay 15  
fill ~34 ~-1 ~86 ~45 ~-1 ~86 stained_hardened_clay 15  
fill ~35 ~-1 ~87 ~44 ~-1 ~87 stained_hardened_clay 15  
fill ~36 ~-1 ~51 ~39 ~-1 ~51 stained_hardened_clay 15  
fill ~36 ~-1 ~52 ~39 ~-1 ~52 stained_hardened_clay 15  
fill ~36 ~-1 ~53 ~39 ~-1 ~53 stained_hardened_clay 15  
fill ~36 ~-1 ~88 ~43 ~-1 ~88 stained_hardened_clay 15 
setblock ~37 ~-1 ~50 stained_hardened_clay 8  
fill ~37 ~-1 ~54 ~37 ~-1 ~56 stained_hardened_clay 8  
fill ~37 ~-1 ~89 ~41 ~-1 ~89 stained_hardened_clay 15 
setblock ~38 ~-1 ~49 stained_hardened_clay 8  
fill ~38 ~-1 ~50 ~39 ~-1 ~50 stained_hardened_clay 15  
fill ~38 ~-1 ~54 ~39 ~-1 ~54 stained_hardened_clay 15  
fill ~38 ~-1 ~55 ~39 ~-1 ~55 stained_hardened_clay 15  
fill ~38 ~-1 ~56 ~39 ~-1 ~56 stained_hardened_clay 15  
fill ~38 ~-1 ~57 ~38 ~-1 ~58 stained_hardened_clay 8 
setblock ~38 ~-1 ~59 sea_lantern 0 
setblock ~38 ~-1 ~63 sea_lantern 0  
fill ~38 ~-1 ~64 ~42 ~-1 ~64 stained_hardened_clay 15  
fill ~38 ~-1 ~65 ~42 ~-1 ~65 stained_hardened_clay 15  
fill ~38 ~-1 ~66 ~42 ~-1 ~66 stained_hardened_clay 15  
fill ~38 ~-1 ~67 ~42 ~-1 ~67 stained_hardened_clay 15  
fill ~38 ~-1 ~68 ~42 ~-1 ~68 stained_hardened_clay 15  
fill ~39 ~-1 ~62 ~39 ~-1 ~63 stained_hardened_clay 8  
fill ~39 ~-1 ~69 ~43 ~-1 ~69 stained_hardened_clay 15  
fill ~39 ~-1 ~70 ~43 ~-1 ~70 stained_hardened_clay 15  
fill ~39 ~-1 ~90 ~40 ~-1 ~90 stained_hardened_clay 15 
setblock ~40 ~-1 ~61 stained_hardened_clay 8  
fill ~40 ~-1 ~62 ~41 ~-1 ~62 stained_hardened_clay 15  
fill ~40 ~-1 ~63 ~41 ~-1 ~63 stained_hardened_clay 15  
fill ~40 ~-1 ~71 ~44 ~-1 ~71 stained_hardened_clay 15  
fill ~40 ~-1 ~72 ~45 ~-1 ~72 stained_hardened_clay 15  
fill ~41 ~-1 ~73 ~46 ~-1 ~73 stained_hardened_clay 15  
fill ~42 ~-1 ~74 ~47 ~-1 ~74 stained_hardened_clay 15  
fill ~42 ~-1 ~84 ~47 ~-1 ~84 stained_hardened_clay 15  
fill ~43 ~-1 ~25 ~47 ~-1 ~25 stained_hardened_clay 15  
fill ~43 ~-1 ~26 ~47 ~-1 ~26 stained_hardened_clay 15  
fill ~43 ~-1 ~27 ~47 ~-1 ~27 stained_hardened_clay 15  
fill ~43 ~-1 ~28 ~47 ~-1 ~28 stained_hardened_clay 15  
fill ~43 ~-1 ~83 ~48 ~-1 ~83 stained_hardened_clay 15 
setblock ~44 ~-1 ~22 sea_lantern 0  
fill ~44 ~-1 ~23 ~44 ~-1 ~24 stained_hardened_clay 8  
fill ~44 ~-1 ~29 ~44 ~-1 ~30 stained_hardened_clay 8 
setblock ~44 ~-1 ~31 sea_lantern 0  
fill ~44 ~-1 ~75 ~48 ~-1 ~75 stained_hardened_clay 15  
fill ~44 ~-1 ~82 ~49 ~-1 ~82 stained_hardened_clay 15  
fill ~45 ~-1 ~21 ~45 ~-1 ~22 stained_hardened_clay 8  
fill ~45 ~-1 ~23 ~45 ~2 ~23 stained_hardened_clay 15  
fill ~45 ~-1 ~24 ~45 ~2 ~24 stained_hardened_clay 15  
fill ~45 ~-1 ~29 ~45 ~2 ~29 stained_hardened_clay 15  
fill ~45 ~-1 ~30 ~45 ~3 ~30 stained_hardened_clay 15 
setblock ~45 ~-1 ~31 stained_hardened_clay 8  
fill ~45 ~-1 ~76 ~49 ~-1 ~76 stained_hardened_clay 15  
fill ~45 ~-1 ~80 ~50 ~-1 ~80 stained_hardened_clay 15  
fill ~45 ~-1 ~81 ~49 ~-1 ~81 stained_hardened_clay 15 
setblock ~46 ~-1 ~22 sea_lantern 0  
fill ~46 ~-1 ~23 ~46 ~-1 ~24 stained_hardened_clay 8  
fill ~46 ~-1 ~29 ~46 ~-1 ~30 stained_hardened_clay 8 
setblock ~46 ~-1 ~31 sea_lantern 0  
fill ~46 ~-1 ~77 ~50 ~-1 ~77 stained_hardened_clay 15  
fill ~46 ~-1 ~78 ~50 ~-1 ~78 stained_hardened_clay 15  
fill ~46 ~-1 ~79 ~50 ~-1 ~79 stained_hardened_clay 15  
fill ~47 ~-1 ~29 ~47 ~0 ~29 stained_hardened_clay 15  
fill ~47 ~-1 ~30 ~47 ~0 ~30 stained_hardened_clay 15 
setblock ~63 ~-1 ~35 sea_lantern 0 
setblock ~63 ~-1 ~36 stained_hardened_clay 8 
setblock ~64 ~-1 ~35 stained_hardened_clay 8  
fill ~64 ~-1 ~36 ~64 ~3 ~36 stained_hardened_clay 15  
fill ~65 ~-1 ~34 ~67 ~-1 ~34 stained_hardened_clay 8  
fill ~65 ~-1 ~35 ~65 ~3 ~35 stained_hardened_clay 15  
fill ~66 ~-1 ~33 ~67 ~-1 ~33 stained_hardened_clay 8  
fill ~67 ~-1 ~32 ~72 ~-1 ~32 stained_hardened_clay 15 
setblock ~67 ~-1 ~35 stained_hardened_clay 8  
fill ~68 ~-1 ~31 ~69 ~-1 ~31 stained_hardened_clay 15  
fill ~68 ~-1 ~33 ~73 ~-1 ~33 stained_hardened_clay 15  
fill ~68 ~-1 ~34 ~74 ~-1 ~34 stained_hardened_clay 15  
fill ~68 ~-1 ~35 ~76 ~-1 ~35 stained_hardened_clay 15  
fill ~76 ~-1 ~36 ~77 ~-1 ~36 stained_hardened_clay 15  
fill ~77 ~-1 ~37 ~78 ~-1 ~37 stained_hardened_clay 15  
fill ~78 ~-1 ~38 ~79 ~-1 ~38 stained_hardened_clay 15  
fill ~79 ~-1 ~39 ~80 ~-1 ~39 stained_hardened_clay 15 
setblock ~81 ~-1 ~66 sea_lantern 0 
setblock ~82 ~-1 ~66 stained_hardened_clay 8  
fill ~83 ~-1 ~56 ~85 ~-1 ~56 stained_hardened_clay 15 
setblock ~83 ~-1 ~66 stained_hardened_clay 15  
fill ~84 ~-1 ~54 ~84 ~-1 ~56 stained_hardened_clay 15  
fill ~85 ~-1 ~57 ~85 ~0 ~57 stained_hardened_clay 15  
fill ~17 ~0 ~42 ~17 ~2 ~42 stained_hardened_clay 8  
fill ~18 ~0 ~41 ~19 ~0 ~41 stained_hardened_clay 8  
fill ~18 ~0 ~42 ~27 ~0 ~42 stained_hardened_clay 15  
fill ~18 ~0 ~43 ~18 ~2 ~43 stained_hardened_clay 8  
fill ~19 ~0 ~43 ~26 ~0 ~43 stained_hardened_clay 15  
fill ~19 ~0 ~44 ~22 ~0 ~44 stained_hardened_clay 15  
fill ~20 ~0 ~40 ~22 ~0 ~40 stained_hardened_clay 15  
fill ~20 ~0 ~41 ~26 ~0 ~41 stained_hardened_clay 15  
fill ~24 ~0 ~40 ~26 ~0 ~40 stained_hardened_clay 15  
fill ~24 ~0 ~44 ~26 ~0 ~44 stained_hardened_clay 15  
fill ~27 ~0 ~41 ~27 ~1 ~41 stained_hardened_clay 8  
fill ~27 ~0 ~43 ~27 ~1 ~43 stained_hardened_clay 8  
fill ~28 ~0 ~42 ~28 ~1 ~42 stained_hardened_clay 8  
fill ~29 ~0 ~74 ~29 ~-1 ~74 stained_hardened_clay 15  
fill ~30 ~0 ~73 ~33 ~0 ~73 stained_hardened_clay 15 
setblock ~30 ~0 ~75 sea_lantern 0  
fill ~30 ~0 ~79 ~34 ~0 ~79 stained_hardened_clay 15  
fill ~30 ~0 ~80 ~33 ~0 ~80 stained_hardened_clay 15 
setblock ~31 ~0 ~77 sea_lantern 0  
fill ~31 ~0 ~81 ~33 ~0 ~81 stained_hardened_clay 15  
fill ~31 ~0 ~82 ~33 ~0 ~82 stained_hardened_clay 15  
fill ~32 ~0 ~78 ~35 ~0 ~78 stained_hardened_clay 15  
fill ~32 ~0 ~83 ~34 ~0 ~83 stained_hardened_clay 15  
fill ~33 ~0 ~74 ~34 ~0 ~74 stained_hardened_clay 15  
fill ~33 ~0 ~77 ~35 ~0 ~77 stained_hardened_clay 15  
fill ~34 ~0 ~75 ~35 ~0 ~75 stained_hardened_clay 15  
fill ~34 ~0 ~76 ~35 ~0 ~76 stained_hardened_clay 15  
fill ~34 ~0 ~84 ~35 ~0 ~84 stained_hardened_clay 15  
fill ~35 ~0 ~85 ~37 ~0 ~85 stained_hardened_clay 15  
fill ~36 ~0 ~50 ~40 ~0 ~50 stained_hardened_clay 15  
fill ~36 ~0 ~51 ~39 ~0 ~51 stained_hardened_clay 15  
fill ~36 ~0 ~52 ~38 ~0 ~52 stained_hardened_clay 15  
fill ~36 ~0 ~54 ~38 ~0 ~54 stained_hardened_clay 15  
fill ~36 ~0 ~55 ~38 ~0 ~55 stained_hardened_clay 15  
fill ~36 ~0 ~56 ~38 ~0 ~56 stained_hardened_clay 15  
fill ~36 ~0 ~86 ~38 ~0 ~86 stained_hardened_clay 15 
setblock ~37 ~0 ~48 sea_lantern 0  
fill ~37 ~0 ~49 ~37 ~1 ~49 stained_hardened_clay 8  
fill ~37 ~0 ~53 ~38 ~0 ~53 stained_hardened_clay 15  
fill ~37 ~0 ~57 ~37 ~0 ~58 stained_hardened_clay 8  
fill ~37 ~0 ~64 ~40 ~0 ~64 stained_hardened_clay 15  
fill ~37 ~0 ~65 ~40 ~0 ~65 stained_hardened_clay 15  
fill ~37 ~0 ~66 ~41 ~0 ~66 stained_hardened_clay 15  
fill ~37 ~0 ~67 ~41 ~0 ~67 stained_hardened_clay 15  
fill ~37 ~0 ~68 ~41 ~0 ~68 stained_hardened_clay 15  
fill ~37 ~0 ~87 ~43 ~0 ~87 stained_hardened_clay 15  
fill ~38 ~0 ~48 ~38 ~1 ~48 stained_hardened_clay 8  
fill ~38 ~0 ~49 ~39 ~0 ~49 stained_hardened_clay 15  
fill ~38 ~0 ~57 ~39 ~0 ~57 stained_hardened_clay 15  
fill ~38 ~0 ~58 ~39 ~0 ~58 stained_hardened_clay 15 
setblock ~38 ~0 ~59 stained_hardened_clay 8  
fill ~38 ~0 ~62 ~38 ~0 ~63 stained_hardened_clay 8  
fill ~38 ~0 ~69 ~41 ~0 ~69 stained_hardened_clay 15  
fill ~38 ~0 ~70 ~42 ~0 ~70 stained_hardened_clay 15 
setblock ~39 ~0 ~48 sea_lantern 0 
setblock ~39 ~0 ~61 stained_hardened_clay 8  
fill ~39 ~0 ~62 ~40 ~0 ~62 stained_hardened_clay 15  
fill ~39 ~0 ~63 ~40 ~0 ~63 stained_hardened_clay 15  
fill ~39 ~0 ~71 ~43 ~0 ~71 stained_hardened_clay 15  
fill ~39 ~0 ~72 ~44 ~0 ~72 stained_hardened_clay 15  
fill ~39 ~0 ~88 ~42 ~0 ~88 stained_hardened_clay 15  
fill ~39 ~0 ~89 ~40 ~0 ~89 stained_hardened_clay 15  
fill ~40 ~0 ~73 ~45 ~0 ~73 stained_hardened_clay 15  
fill ~40 ~0 ~86 ~44 ~0 ~86 stained_hardened_clay 15  
fill ~41 ~0 ~85 ~45 ~0 ~85 stained_hardened_clay 15  
fill ~42 ~0 ~74 ~46 ~0 ~74 stained_hardened_clay 15  
fill ~43 ~0 ~23 ~47 ~0 ~23 stained_hardened_clay 15  
fill ~43 ~0 ~24 ~47 ~0 ~24 stained_hardened_clay 15  
fill ~43 ~0 ~29 ~47 ~0 ~29 stained_hardened_clay 15  
fill ~43 ~0 ~30 ~47 ~0 ~30 stained_hardened_clay 15  
fill ~43 ~0 ~75 ~47 ~0 ~75 stained_hardened_clay 15  
fill ~43 ~0 ~84 ~46 ~0 ~84 stained_hardened_clay 15  
fill ~44 ~0 ~21 ~44 ~0 ~22 stained_hardened_clay 8  
fill ~44 ~0 ~25 ~44 ~0 ~30 stained_hardened_clay 15 
setblock ~44 ~0 ~31 stained_hardened_clay 8  
fill ~44 ~0 ~76 ~48 ~0 ~76 stained_hardened_clay 15  
fill ~44 ~0 ~83 ~47 ~0 ~83 stained_hardened_clay 15 
setblock ~45 ~0 ~19 sea_lantern 0 
setblock ~45 ~0 ~20 stained_hardened_clay 8  
fill ~45 ~0 ~21 ~45 ~3 ~21 stained_hardened_clay 15  
fill ~45 ~0 ~22 ~45 ~2 ~22 stained_hardened_clay 15  
fill ~45 ~0 ~31 ~45 ~5 ~31 stained_hardened_clay 15 
setblock ~45 ~0 ~32 stained_hardened_clay 8 
setblock ~45 ~0 ~33 sea_lantern 0  
fill ~45 ~0 ~77 ~49 ~0 ~77 stained_hardened_clay 15  
fill ~45 ~0 ~81 ~48 ~0 ~81 stained_hardened_clay 15  
fill ~45 ~0 ~82 ~48 ~0 ~82 stained_hardened_clay 15  
fill ~46 ~0 ~21 ~46 ~0 ~22 stained_hardened_clay 8  
fill ~46 ~0 ~25 ~46 ~0 ~30 stained_hardened_clay 15 
setblock ~46 ~0 ~31 stained_hardened_clay 8  
fill ~46 ~0 ~80 ~49 ~0 ~80 stained_hardened_clay 15  
fill ~47 ~0 ~31 ~47 ~1 ~31 stained_hardened_clay 15  
fill ~47 ~0 ~78 ~49 ~0 ~78 stained_hardened_clay 15  
fill ~47 ~0 ~79 ~49 ~0 ~79 stained_hardened_clay 15 
setblock ~48 ~0 ~47 coal_block 0 
setblock ~48 ~0 ~52 coal_block 0 
setblock ~51 ~0 ~45 sea_lantern 0  
fill ~62 ~0 ~37 ~62 ~3 ~37 stained_hardened_clay 15  
fill ~63 ~0 ~35 ~71 ~0 ~35 stained_hardened_clay 15  
fill ~63 ~0 ~36 ~63 ~3 ~36 stained_hardened_clay 15 
setblock ~63 ~0 ~37 stained_hardened_clay 8  
fill ~64 ~0 ~34 ~73 ~0 ~34 stained_hardened_clay 15  
fill ~64 ~0 ~37 ~64 ~4 ~37 stained_hardened_clay 15  
fill ~65 ~0 ~33 ~72 ~0 ~33 stained_hardened_clay 15  
fill ~65 ~0 ~36 ~65 ~3 ~36 stained_hardened_clay 15  
fill ~66 ~0 ~32 ~70 ~0 ~32 stained_hardened_clay 15 
setblock ~81 ~0 ~65 sea_lantern 0 
setblock ~81 ~0 ~66 stained_hardened_clay 8 
setblock ~82 ~0 ~62 sea_lantern 0  
fill ~82 ~0 ~66 ~82 ~1 ~66 stained_hardened_clay 15  
fill ~82 ~0 ~67 ~82 ~0 ~66 stained_hardened_clay 15  
fill ~83 ~0 ~57 ~85 ~0 ~57 stained_hardened_clay 15 
setblock ~84 ~0 ~56 stained_hardened_clay 15 
setblock ~84 ~0 ~58 stained_hardened_clay 8 
setblock ~85 ~0 ~58 sea_lantern 0  
fill ~18 ~1 ~41 ~18 ~2 ~41 stained_hardened_clay 8  
fill ~18 ~1 ~42 ~27 ~1 ~42 stained_hardened_clay 15  
fill ~19 ~1 ~40 ~20 ~1 ~40 stained_hardened_clay 15  
fill ~19 ~1 ~41 ~21 ~1 ~41 stained_hardened_clay 15  
fill ~19 ~1 ~43 ~21 ~1 ~43 stained_hardened_clay 15  
fill ~19 ~1 ~44 ~20 ~1 ~44 stained_hardened_clay 15  
fill ~25 ~1 ~41 ~26 ~1 ~41 stained_hardened_clay 15  
fill ~25 ~1 ~43 ~26 ~1 ~43 stained_hardened_clay 15 
setblock ~26 ~1 ~40 stained_hardened_clay 15 
setblock ~26 ~1 ~44 stained_hardened_clay 15  
fill ~29 ~1 ~42 ~29 ~2 ~42 stained_hardened_clay 8  
fill ~31 ~1 ~79 ~32 ~1 ~79 stained_hardened_clay 15  
fill ~31 ~1 ~80 ~31 ~1 ~79 stained_hardened_clay 15  
fill ~32 ~1 ~78 ~32 ~-1 ~78 stained_hardened_clay 15 
setblock ~32 ~1 ~81 stained_hardened_clay 15  
fill ~33 ~1 ~77 ~33 ~-1 ~77 stained_hardened_clay 15  
fill ~36 ~1 ~50 ~39 ~1 ~50 stained_hardened_clay 15  
fill ~36 ~1 ~51 ~38 ~1 ~51 stained_hardened_clay 15  
fill ~36 ~1 ~56 ~37 ~1 ~56 stained_hardened_clay 15  
fill ~36 ~1 ~57 ~37 ~1 ~57 stained_hardened_clay 15  
fill ~36 ~1 ~58 ~38 ~1 ~58 stained_hardened_clay 15 
setblock ~36 ~1 ~59 sea_lantern 0  
fill ~36 ~1 ~63 ~39 ~1 ~63 stained_hardened_clay 15  
fill ~36 ~1 ~64 ~39 ~1 ~64 stained_hardened_clay 15  
fill ~37 ~1 ~52 ~37 ~2 ~52 stained_hardened_clay 15  
fill ~37 ~1 ~53 ~37 ~-1 ~53 stained_hardened_clay 15  
fill ~37 ~1 ~54 ~37 ~1 ~58 stained_hardened_clay 15 
setblock ~37 ~1 ~59 stained_hardened_clay 8 
setblock ~37 ~1 ~61 sea_lantern 0 
setblock ~37 ~1 ~62 stained_hardened_clay 8  
fill ~37 ~1 ~65 ~39 ~1 ~65 stained_hardened_clay 15  
fill ~37 ~1 ~66 ~39 ~1 ~66 stained_hardened_clay 15 
setblock ~37 ~1 ~86 stained_hardened_clay 15  
fill ~38 ~1 ~49 ~40 ~1 ~49 stained_hardened_clay 15  
fill ~38 ~1 ~59 ~39 ~1 ~59 stained_hardened_clay 15  
fill ~38 ~1 ~60 ~38 ~1 ~61 stained_hardened_clay 8  
fill ~38 ~1 ~62 ~40 ~1 ~62 stained_hardened_clay 15  
fill ~38 ~1 ~67 ~39 ~1 ~67 stained_hardened_clay 15  
fill ~38 ~1 ~87 ~41 ~1 ~87 stained_hardened_clay 15  
fill ~39 ~1 ~48 ~40 ~1 ~48 stained_hardened_clay 15  
fill ~39 ~1 ~61 ~39 ~6 ~61 stained_hardened_clay 15  
fill ~39 ~1 ~68 ~40 ~1 ~68 stained_hardened_clay 15  
fill ~39 ~1 ~69 ~40 ~1 ~69 stained_hardened_clay 15  
fill ~39 ~1 ~88 ~40 ~1 ~88 stained_hardened_clay 15 
setblock ~40 ~1 ~70 stained_hardened_clay 15 
setblock ~41 ~1 ~71 stained_hardened_clay 15 
setblock ~42 ~1 ~72 stained_hardened_clay 15 
setblock ~42 ~1 ~86 stained_hardened_clay 15  
fill ~43 ~1 ~21 ~47 ~1 ~21 stained_hardened_clay 15  
fill ~43 ~1 ~22 ~47 ~1 ~22 stained_hardened_clay 15  
fill ~43 ~1 ~30 ~46 ~1 ~30 stained_hardened_clay 15  
fill ~43 ~1 ~31 ~47 ~1 ~31 stained_hardened_clay 15 
setblock ~43 ~1 ~73 stained_hardened_clay 15 
setblock ~43 ~1 ~85 stained_hardened_clay 15 
setblock ~44 ~1 ~20 stained_hardened_clay 8  
fill ~44 ~1 ~23 ~44 ~1 ~24 stained_hardened_clay 15 
setblock ~44 ~1 ~29 stained_hardened_clay 15 
setblock ~44 ~1 ~32 stained_hardened_clay 8 
setblock ~44 ~1 ~74 stained_hardened_clay 15 
setblock ~44 ~1 ~84 stained_hardened_clay 15 
setblock ~45 ~1 ~19 stained_hardened_clay 8  
fill ~45 ~1 ~20 ~45 ~5 ~20 stained_hardened_clay 15  
fill ~45 ~1 ~32 ~45 ~6 ~32 stained_hardened_clay 15 
setblock ~45 ~1 ~33 stained_hardened_clay 8 
setblock ~45 ~1 ~75 stained_hardened_clay 15 
setblock ~45 ~1 ~83 stained_hardened_clay 15 
setblock ~46 ~1 ~20 stained_hardened_clay 8  
fill ~46 ~1 ~23 ~46 ~1 ~24 stained_hardened_clay 15 
setblock ~46 ~1 ~29 stained_hardened_clay 15 
setblock ~46 ~1 ~32 stained_hardened_clay 8 
setblock ~46 ~1 ~76 stained_hardened_clay 15 
setblock ~46 ~1 ~82 stained_hardened_clay 15  
fill ~47 ~1 ~32 ~47 ~2 ~32 stained_hardened_clay 15  
fill ~47 ~1 ~47 ~47 ~2 ~47 coal_block 0  
fill ~47 ~1 ~52 ~47 ~4 ~52 coal_block 0 
setblock ~47 ~1 ~77 stained_hardened_clay 15 
setblock ~47 ~1 ~81 stained_hardened_clay 15  
fill ~48 ~1 ~46 ~48 ~2 ~46 coal_block 0  
fill ~48 ~1 ~53 ~48 ~4 ~53 coal_block 0  
fill ~48 ~1 ~78 ~48 ~1 ~80 stained_hardened_clay 15  
fill ~49 ~1 ~47 ~49 ~2 ~47 coal_block 0  
fill ~49 ~1 ~52 ~49 ~4 ~52 coal_block 0 
setblock ~49 ~1 ~53 sea_lantern 0 
setblock ~49 ~1 ~54 stained_hardened_clay 8 
setblock ~50 ~1 ~42 sea_lantern 0  
fill ~50 ~1 ~44 ~52 ~1 ~44 stained_hardened_clay 8  
fill ~50 ~1 ~55 ~50 ~2 ~55 stained_hardened_clay 8 
setblock ~50 ~1 ~56 sea_lantern 0 
setblock ~51 ~1 ~43 stained_hardened_clay 8 
setblock ~51 ~1 ~45 stained_hardened_clay 8  
fill ~51 ~1 ~56 ~51 ~3 ~56 stained_hardened_clay 8 
setblock ~52 ~1 ~42 sea_lantern 0 
setblock ~53 ~1 ~58 sea_lantern 0  
fill ~61 ~1 ~37 ~61 ~2 ~37 stained_hardened_clay 15  
fill ~61 ~1 ~38 ~61 ~3 ~38 stained_hardened_clay 15  
fill ~62 ~1 ~36 ~62 ~2 ~36 stained_hardened_clay 15 
setblock ~62 ~1 ~38 stained_hardened_clay 8 
setblock ~62 ~1 ~39 sea_lantern 0  
fill ~63 ~1 ~35 ~67 ~1 ~35 stained_hardened_clay 15  
fill ~63 ~1 ~37 ~63 ~4 ~37 stained_hardened_clay 15  
fill ~63 ~1 ~38 ~63 ~5 ~38 stained_hardened_clay 15  
fill ~64 ~1 ~34 ~70 ~1 ~34 stained_hardened_clay 15  
fill ~65 ~1 ~33 ~69 ~1 ~33 stained_hardened_clay 15  
fill ~65 ~1 ~37 ~65 ~3 ~37 stained_hardened_clay 15  
fill ~66 ~1 ~36 ~66 ~2 ~36 stained_hardened_clay 15 
setblock ~79 ~1 ~65 sea_lantern 0  
fill ~80 ~1 ~64 ~80 ~1 ~65 stained_hardened_clay 8  
fill ~80 ~1 ~66 ~82 ~1 ~66 stained_hardened_clay 15 
setblock ~81 ~1 ~63 stained_hardened_clay 8  
fill ~81 ~1 ~65 ~81 ~2 ~65 stained_hardened_clay 15 
setblock ~81 ~1 ~67 stained_hardened_clay 15 
setblock ~82 ~1 ~62 stained_hardened_clay 8  
fill ~83 ~1 ~58 ~85 ~1 ~58 stained_hardened_clay 15 
setblock ~83 ~1 ~59 sea_lantern 0 
setblock ~83 ~1 ~61 stained_hardened_clay 8 
setblock ~84 ~1 ~57 stained_hardened_clay 15  
fill ~84 ~1 ~59 ~84 ~1 ~60 stained_hardened_clay 8 
setblock ~84 ~1 ~61 sea_lantern 0 
setblock ~17 ~2 ~41 sea_lantern 0 
setblock ~17 ~2 ~43 sea_lantern 0  
fill ~18 ~2 ~42 ~22 ~2 ~42 stained_hardened_clay 15  
fill ~19 ~2 ~40 ~19 ~1 ~40 stained_hardened_clay 15  
summon Bat ~47.1260632236 ~-1.93768741518 ~11.8486909772
fill ~19 ~2 ~41 ~20 ~2 ~41 stained_hardened_clay 15  
fill ~19 ~2 ~43 ~20 ~2 ~43 stained_hardened_clay 15  
fill ~19 ~2 ~44 ~19 ~0 ~44 stained_hardened_clay 15  
fill ~25 ~2 ~42 ~28 ~2 ~42 stained_hardened_clay 15  
fill ~26 ~2 ~41 ~27 ~2 ~41 stained_hardened_clay 15  
fill ~26 ~2 ~43 ~27 ~2 ~43 stained_hardened_clay 15 
setblock ~27 ~2 ~40 stained_hardened_clay 15 
setblock ~27 ~2 ~44 stained_hardened_clay 15 
setblock ~28 ~2 ~41 stained_hardened_clay 8 
setblock ~28 ~2 ~43 stained_hardened_clay 8 
setblock ~29 ~2 ~41 sea_lantern 0 
setblock ~29 ~2 ~43 sea_lantern 0  
fill ~30 ~2 ~42 ~30 ~3 ~42 stained_hardened_clay 8  
fill ~36 ~2 ~49 ~39 ~2 ~49 stained_hardened_clay 15  
fill ~36 ~2 ~50 ~38 ~2 ~50 stained_hardened_clay 15  
fill ~36 ~2 ~59 ~38 ~2 ~59 stained_hardened_clay 15  
fill ~36 ~2 ~62 ~39 ~2 ~62 stained_hardened_clay 15 
setblock ~37 ~2 ~48 stained_hardened_clay 8  
fill ~37 ~2 ~51 ~38 ~2 ~51 stained_hardened_clay 15  
fill ~37 ~2 ~57 ~37 ~2 ~59 stained_hardened_clay 15  
fill ~37 ~2 ~60 ~37 ~2 ~61 stained_hardened_clay 8  
fill ~37 ~2 ~63 ~38 ~2 ~63 stained_hardened_clay 15  
fill ~38 ~2 ~47 ~38 ~5 ~47 stained_hardened_clay 8  
fill ~38 ~2 ~48 ~39 ~2 ~48 stained_hardened_clay 15  
fill ~38 ~2 ~60 ~45 ~2 ~60 stained_hardened_clay 15  
fill ~38 ~2 ~61 ~38 ~4 ~61 stained_hardened_clay 15  
fill ~38 ~2 ~64 ~38 ~2 ~66 stained_hardened_clay 15  
fill ~40 ~2 ~61 ~40 ~6 ~61 stained_hardened_clay 15  
fill ~41 ~2 ~58 ~45 ~2 ~58 stained_hardened_clay 15  
fill ~41 ~2 ~59 ~45 ~2 ~59 stained_hardened_clay 15  
fill ~42 ~2 ~57 ~50 ~2 ~57 stained_hardened_clay 15  
fill ~42 ~2 ~61 ~44 ~2 ~61 stained_hardened_clay 15  
fill ~43 ~2 ~20 ~47 ~2 ~20 stained_hardened_clay 15  
fill ~43 ~2 ~31 ~46 ~2 ~31 stained_hardened_clay 15  
fill ~43 ~2 ~32 ~47 ~2 ~32 stained_hardened_clay 15 
setblock ~44 ~2 ~18 sea_lantern 0 
setblock ~44 ~2 ~19 stained_hardened_clay 8 
setblock ~44 ~2 ~21 stained_hardened_clay 15 
setblock ~44 ~2 ~30 stained_hardened_clay 15  
fill ~44 ~2 ~33 ~44 ~3 ~33 stained_hardened_clay 8 
setblock ~44 ~2 ~34 sea_lantern 0  
fill ~44 ~2 ~54 ~47 ~2 ~54 stained_hardened_clay 15  
fill ~44 ~2 ~55 ~48 ~2 ~55 stained_hardened_clay 15  
fill ~44 ~2 ~56 ~49 ~2 ~56 stained_hardened_clay 15 
setblock ~45 ~2 ~18 stained_hardened_clay 8  
fill ~45 ~2 ~19 ~45 ~7 ~19 stained_hardened_clay 15  
fill ~45 ~2 ~33 ~45 ~7 ~33 stained_hardened_clay 15  
fill ~45 ~2 ~34 ~45 ~3 ~34 stained_hardened_clay 8 
setblock ~45 ~2 ~44 sea_lantern 0  
fill ~45 ~2 ~53 ~46 ~2 ~53 stained_hardened_clay 15 
setblock ~46 ~2 ~18 sea_lantern 0 
setblock ~46 ~2 ~19 stained_hardened_clay 8 
setblock ~46 ~2 ~21 stained_hardened_clay 15  
fill ~46 ~2 ~33 ~46 ~3 ~33 stained_hardened_clay 8 
setblock ~46 ~2 ~34 sea_lantern 0 
setblock ~46 ~2 ~48 coal_block 0 
setblock ~46 ~2 ~50 coal_block 0  
fill ~47 ~2 ~33 ~47 ~5 ~33 stained_hardened_clay 15 
setblock ~47 ~2 ~51 coal_block 0 
setblock ~47 ~2 ~53 stained_hardened_clay 8  
fill ~47 ~2 ~58 ~47 ~2 ~61 coal_block 0 
setblock ~48 ~2 ~54 stained_hardened_clay 8  
fill ~49 ~2 ~44 ~53 ~2 ~44 stained_hardened_clay 15 
setblock ~49 ~2 ~51 coal_block 0 
setblock ~49 ~2 ~53 stained_hardened_clay 8  
fill ~49 ~2 ~54 ~49 ~6 ~54 stained_hardened_clay 15 
setblock ~49 ~2 ~55 stained_hardened_clay 8  
fill ~49 ~2 ~58 ~51 ~2 ~58 stained_hardened_clay 15  
fill ~49 ~2 ~59 ~52 ~2 ~59 stained_hardened_clay 15  
fill ~49 ~2 ~60 ~53 ~2 ~60 stained_hardened_clay 15  
fill ~50 ~2 ~42 ~52 ~2 ~42 stained_hardened_clay 8  
fill ~50 ~2 ~43 ~50 ~2 ~42 stained_hardened_clay 8 
setblock ~50 ~2 ~45 stained_hardened_clay 8 
setblock ~50 ~2 ~46 sea_lantern 0 
setblock ~50 ~2 ~48 coal_block 0 
setblock ~50 ~2 ~50 coal_block 0 
setblock ~50 ~2 ~54 stained_hardened_clay 8 
setblock ~50 ~2 ~56 stained_hardened_clay 8  
fill ~50 ~2 ~61 ~52 ~2 ~61 stained_hardened_clay 15 
setblock ~51 ~2 ~41 stained_hardened_clay 8  
fill ~51 ~2 ~43 ~51 ~13 ~43 stained_hardened_clay 15  
fill ~51 ~2 ~45 ~51 ~14 ~45 stained_hardened_clay 15 
setblock ~51 ~2 ~46 stained_hardened_clay 8  
fill ~51 ~2 ~55 ~51 ~3 ~55 stained_hardened_clay 8  
fill ~51 ~2 ~57 ~52 ~2 ~57 stained_hardened_clay 8 
setblock ~52 ~2 ~43 stained_hardened_clay 8 
setblock ~52 ~2 ~45 stained_hardened_clay 8 
setblock ~52 ~2 ~46 sea_lantern 0  
fill ~52 ~2 ~58 ~53 ~2 ~58 stained_hardened_clay 8 
setblock ~53 ~2 ~59 stained_hardened_clay 8 
setblock ~60 ~2 ~38 stained_hardened_clay 15 
setblock ~60 ~2 ~39 sea_lantern 0  
fill ~61 ~2 ~39 ~62 ~2 ~39 stained_hardened_clay 8  
fill ~62 ~2 ~38 ~62 ~4 ~38 stained_hardened_clay 15 
setblock ~62 ~2 ~40 stained_hardened_clay 8 
setblock ~62 ~2 ~41 sea_lantern 0  
fill ~63 ~2 ~35 ~66 ~2 ~35 stained_hardened_clay 15  
fill ~63 ~2 ~39 ~63 ~6 ~39 stained_hardened_clay 15  
fill ~64 ~2 ~34 ~67 ~2 ~34 stained_hardened_clay 15  
fill ~64 ~2 ~38 ~65 ~2 ~38 stained_hardened_clay 15 
setblock ~66 ~2 ~37 stained_hardened_clay 15  
fill ~79 ~2 ~65 ~81 ~2 ~65 stained_hardened_clay 15  
fill ~79 ~2 ~66 ~81 ~2 ~66 stained_hardened_clay 15  
fill ~80 ~2 ~64 ~81 ~2 ~64 stained_hardened_clay 15 
setblock ~80 ~2 ~67 stained_hardened_clay 15  
fill ~81 ~2 ~63 ~82 ~2 ~63 stained_hardened_clay 15  
fill ~82 ~2 ~62 ~83 ~2 ~62 stained_hardened_clay 15  
fill ~83 ~2 ~59 ~85 ~2 ~59 stained_hardened_clay 15  
fill ~83 ~2 ~60 ~85 ~2 ~60 stained_hardened_clay 15  
fill ~83 ~2 ~61 ~84 ~2 ~61 stained_hardened_clay 15 
setblock ~84 ~2 ~58 stained_hardened_clay 15  
fill ~16 ~3 ~42 ~16 ~4 ~42 stained_hardened_clay 8  
fill ~17 ~3 ~41 ~17 ~4 ~41 stained_hardened_clay 8  
fill ~17 ~3 ~42 ~21 ~3 ~42 stained_hardened_clay 15  
fill ~17 ~3 ~43 ~17 ~4 ~43 stained_hardened_clay 8  
fill ~18 ~3 ~40 ~18 ~4 ~40 stained_hardened_clay 15  
fill ~18 ~3 ~41 ~19 ~3 ~41 stained_hardened_clay 15  
fill ~18 ~3 ~43 ~19 ~3 ~43 stained_hardened_clay 15  
fill ~18 ~3 ~44 ~18 ~4 ~44 stained_hardened_clay 15  
fill ~26 ~3 ~42 ~29 ~3 ~42 stained_hardened_clay 15  
fill ~27 ~3 ~41 ~28 ~3 ~41 stained_hardened_clay 15  
fill ~27 ~3 ~43 ~28 ~3 ~43 stained_hardened_clay 15 
setblock ~28 ~3 ~40 stained_hardened_clay 15 
setblock ~28 ~3 ~44 stained_hardened_clay 15 
setblock ~29 ~3 ~41 stained_hardened_clay 8 
setblock ~29 ~3 ~43 stained_hardened_clay 8 
setblock ~31 ~3 ~42 stained_hardened_clay 8 
setblock ~32 ~3 ~42 sea_lantern 0  
fill ~36 ~3 ~49 ~40 ~3 ~49 stained_hardened_clay 15  
fill ~36 ~3 ~60 ~38 ~3 ~60 stained_hardened_clay 15  
fill ~36 ~3 ~61 ~54 ~3 ~61 stained_hardened_clay 15  
fill ~37 ~3 ~48 ~39 ~3 ~48 stained_hardened_clay 15  
fill ~37 ~3 ~50 ~39 ~3 ~50 stained_hardened_clay 15  
fill ~37 ~3 ~51 ~38 ~3 ~51 stained_hardened_clay 15  
fill ~37 ~3 ~59 ~38 ~3 ~59 stained_hardened_clay 15 
setblock ~38 ~3 ~46 sea_lantern 0 
setblock ~38 ~3 ~62 stained_hardened_clay 15  
fill ~40 ~3 ~48 ~42 ~3 ~48 stained_hardened_clay 8  
fill ~40 ~3 ~57 ~52 ~3 ~57 stained_hardened_clay 15  
fill ~40 ~3 ~58 ~53 ~3 ~58 stained_hardened_clay 15  
fill ~40 ~3 ~59 ~53 ~3 ~59 stained_hardened_clay 15  
fill ~40 ~3 ~60 ~53 ~3 ~60 stained_hardened_clay 15  
fill ~41 ~3 ~56 ~50 ~3 ~56 stained_hardened_clay 15  
fill ~41 ~3 ~62 ~45 ~3 ~62 stained_hardened_clay 15  
fill ~43 ~3 ~19 ~47 ~3 ~19 stained_hardened_clay 15  
fill ~43 ~3 ~32 ~46 ~3 ~32 stained_hardened_clay 15  
fill ~43 ~3 ~49 ~43 ~4 ~49 stained_hardened_clay 8  
fill ~43 ~3 ~54 ~51 ~3 ~54 stained_hardened_clay 15  
fill ~43 ~3 ~55 ~50 ~3 ~55 stained_hardened_clay 15  
fill ~44 ~3 ~18 ~44 ~4 ~18 stained_hardened_clay 8 
setblock ~44 ~3 ~20 stained_hardened_clay 15 
setblock ~44 ~3 ~31 stained_hardened_clay 15 
setblock ~44 ~3 ~42 sea_lantern 0  
fill ~44 ~3 ~53 ~47 ~3 ~53 stained_hardened_clay 15  
fill ~45 ~3 ~17 ~45 ~4 ~17 stained_hardened_clay 8  
fill ~45 ~3 ~18 ~45 ~12 ~18 stained_hardened_clay 15  
fill ~45 ~3 ~43 ~45 ~3 ~47 stained_hardened_clay 8  
fill ~45 ~3 ~48 ~45 ~4 ~48 coal_block 0  
fill ~45 ~3 ~50 ~45 ~4 ~50 coal_block 0  
fill ~45 ~3 ~52 ~46 ~3 ~52 stained_hardened_clay 15  
fill ~46 ~3 ~18 ~46 ~4 ~18 stained_hardened_clay 8 
setblock ~46 ~3 ~20 stained_hardened_clay 15 
setblock ~46 ~3 ~42 sea_lantern 0  
fill ~46 ~3 ~47 ~46 ~4 ~47 coal_block 0  
fill ~46 ~3 ~51 ~46 ~4 ~51 coal_block 0  
fill ~47 ~3 ~46 ~47 ~4 ~46 coal_block 0 
setblock ~47 ~3 ~62 coal_block 0  
fill ~48 ~3 ~45 ~48 ~4 ~45 coal_block 0  
fill ~49 ~3 ~43 ~53 ~3 ~43 stained_hardened_clay 15  
fill ~49 ~3 ~44 ~53 ~3 ~44 stained_hardened_clay 15  
fill ~49 ~3 ~45 ~53 ~3 ~45 stained_hardened_clay 15  
fill ~49 ~3 ~46 ~49 ~4 ~46 coal_block 0  
fill ~49 ~3 ~53 ~51 ~3 ~53 stained_hardened_clay 15  
fill ~49 ~3 ~62 ~53 ~3 ~62 stained_hardened_clay 15  
fill ~50 ~3 ~41 ~50 ~4 ~41 stained_hardened_clay 8  
fill ~50 ~3 ~42 ~50 ~3 ~41 stained_hardened_clay 8 
setblock ~50 ~3 ~46 stained_hardened_clay 8  
fill ~50 ~3 ~47 ~50 ~4 ~47 coal_block 0  
fill ~50 ~3 ~51 ~50 ~4 ~51 coal_block 0  
fill ~50 ~3 ~52 ~50 ~6 ~52 stained_hardened_clay 15 
setblock ~51 ~3 ~39 sea_lantern 0 
setblock ~51 ~3 ~40 stained_hardened_clay 8  
fill ~51 ~3 ~41 ~51 ~11 ~41 stained_hardened_clay 15  
fill ~51 ~3 ~42 ~51 ~12 ~42 stained_hardened_clay 15  
fill ~51 ~3 ~46 ~51 ~6 ~46 stained_hardened_clay 15 
setblock ~51 ~3 ~47 stained_hardened_clay 8  
fill ~51 ~3 ~48 ~51 ~4 ~48 coal_block 0  
fill ~51 ~3 ~50 ~51 ~4 ~50 coal_block 0  
fill ~52 ~3 ~41 ~52 ~4 ~41 stained_hardened_clay 8  
fill ~52 ~3 ~42 ~52 ~3 ~41 stained_hardened_clay 8 
setblock ~52 ~3 ~46 stained_hardened_clay 8 
setblock ~52 ~3 ~55 sea_lantern 0  
fill ~52 ~3 ~56 ~53 ~3 ~56 stained_hardened_clay 15 
setblock ~53 ~3 ~57 stained_hardened_clay 8 
setblock ~54 ~3 ~47 sea_lantern 0  
fill ~54 ~3 ~57 ~54 ~6 ~57 stained_hardened_clay 15  
fill ~54 ~3 ~58 ~54 ~3 ~60 stained_hardened_clay 8 
setblock ~55 ~3 ~58 sea_lantern 0 
setblock ~55 ~3 ~60 sea_lantern 0 
setblock ~56 ~3 ~45 sea_lantern 0 
setblock ~57 ~3 ~52 sea_lantern 0  
fill ~60 ~3 ~39 ~65 ~3 ~39 stained_hardened_clay 15  
fill ~60 ~3 ~40 ~60 ~4 ~40 stained_hardened_clay 15  
fill ~60 ~3 ~41 ~61 ~3 ~41 stained_hardened_clay 8 
setblock ~60 ~3 ~43 sea_lantern 0 
setblock ~61 ~3 ~40 stained_hardened_clay 8  
fill ~62 ~3 ~40 ~64 ~3 ~40 stained_hardened_clay 15  
fill ~62 ~3 ~41 ~62 ~7 ~41 stained_hardened_clay 15 
setblock ~64 ~3 ~35 stained_hardened_clay 15  
fill ~64 ~3 ~38 ~65 ~3 ~38 stained_hardened_clay 15  
fill ~79 ~3 ~65 ~80 ~3 ~65 stained_hardened_clay 15  
fill ~79 ~3 ~66 ~80 ~3 ~66 stained_hardened_clay 15  
fill ~80 ~3 ~63 ~83 ~3 ~63 stained_hardened_clay 15  
fill ~80 ~3 ~64 ~82 ~3 ~64 stained_hardened_clay 15  
fill ~81 ~3 ~62 ~84 ~3 ~62 stained_hardened_clay 15  
fill ~82 ~3 ~61 ~85 ~3 ~61 stained_hardened_clay 15  
fill ~83 ~3 ~60 ~84 ~3 ~60 stained_hardened_clay 15 
setblock ~84 ~3 ~59 stained_hardened_clay 15 
setblock ~0 ~4 ~42 sea_lantern 0  
fill ~2 ~4 ~42 ~5 ~4 ~42 stained_hardened_clay 8 
setblock ~3 ~4 ~41 sea_lantern 0 
setblock ~3 ~4 ~43 sea_lantern 0 
setblock ~7 ~4 ~42 sea_lantern 0 
setblock ~15 ~4 ~42 sea_lantern 0  
fill ~17 ~4 ~42 ~20 ~4 ~42 stained_hardened_clay 15  
fill ~18 ~4 ~41 ~18 ~5 ~41 stained_hardened_clay 15  
fill ~18 ~4 ~43 ~18 ~5 ~43 stained_hardened_clay 15  
fill ~27 ~4 ~42 ~31 ~4 ~42 stained_hardened_clay 15  
fill ~28 ~4 ~41 ~29 ~4 ~41 stained_hardened_clay 15  
fill ~28 ~4 ~43 ~29 ~4 ~43 stained_hardened_clay 15 
setblock ~29 ~4 ~40 stained_hardened_clay 15 
setblock ~29 ~4 ~44 stained_hardened_clay 15  
fill ~30 ~4 ~41 ~31 ~4 ~41 stained_hardened_clay 8  
fill ~30 ~4 ~43 ~31 ~4 ~43 stained_hardened_clay 8  
fill ~32 ~4 ~42 ~33 ~4 ~42 stained_hardened_clay 8  
fill ~36 ~4 ~49 ~40 ~4 ~49 stained_hardened_clay 15  
fill ~37 ~4 ~48 ~40 ~4 ~48 stained_hardened_clay 15  
fill ~37 ~4 ~50 ~39 ~4 ~50 stained_hardened_clay 15  
fill ~37 ~4 ~60 ~54 ~4 ~60 stained_hardened_clay 15  
fill ~38 ~4 ~51 ~38 ~7 ~51 stained_hardened_clay 15  
fill ~39 ~4 ~47 ~44 ~4 ~47 stained_hardened_clay 8  
fill ~39 ~4 ~53 ~41 ~4 ~53 stained_hardened_clay 8  
fill ~39 ~4 ~57 ~55 ~4 ~57 stained_hardened_clay 15  
fill ~39 ~4 ~58 ~55 ~4 ~58 stained_hardened_clay 15  
fill ~39 ~4 ~59 ~54 ~4 ~59 stained_hardened_clay 15 
setblock ~40 ~4 ~46 sea_lantern 0 
setblock ~40 ~4 ~54 sea_lantern 0  
fill ~40 ~4 ~56 ~54 ~4 ~56 stained_hardened_clay 15  
fill ~40 ~4 ~62 ~54 ~4 ~62 stained_hardened_clay 15  
fill ~41 ~4 ~46 ~43 ~4 ~46 stained_hardened_clay 15  
fill ~41 ~4 ~48 ~44 ~4 ~48 stained_hardened_clay 8  
fill ~41 ~4 ~49 ~44 ~4 ~49 stained_hardened_clay 8  
fill ~41 ~4 ~50 ~41 ~6 ~50 stained_hardened_clay 15 
setblock ~41 ~4 ~52 sea_lantern 0  
fill ~41 ~4 ~55 ~53 ~4 ~55 stained_hardened_clay 15  
fill ~41 ~4 ~61 ~55 ~4 ~61 stained_hardened_clay 15  
fill ~41 ~4 ~63 ~45 ~4 ~63 stained_hardened_clay 15  
fill ~42 ~4 ~45 ~43 ~4 ~45 stained_hardened_clay 15 
setblock ~42 ~4 ~52 stained_hardened_clay 8  
fill ~42 ~4 ~54 ~52 ~4 ~54 stained_hardened_clay 15  
fill ~43 ~4 ~19 ~47 ~4 ~19 stained_hardened_clay 15  
fill ~43 ~4 ~33 ~47 ~4 ~33 stained_hardened_clay 15  
fill ~43 ~4 ~44 ~43 ~13 ~44 stained_hardened_clay 15  
fill ~43 ~4 ~50 ~43 ~4 ~51 stained_hardened_clay 8 
setblock ~43 ~4 ~52 sea_lantern 0  
fill ~43 ~4 ~53 ~47 ~4 ~53 stained_hardened_clay 15  
fill ~44 ~4 ~32 ~44 ~5 ~32 stained_hardened_clay 15  
fill ~44 ~4 ~34 ~44 ~5 ~34 stained_hardened_clay 8  
fill ~44 ~4 ~42 ~46 ~4 ~42 stained_hardened_clay 8  
fill ~44 ~4 ~43 ~44 ~4 ~49 stained_hardened_clay 8 
setblock ~44 ~4 ~50 sea_lantern 0  
fill ~44 ~4 ~51 ~45 ~4 ~51 stained_hardened_clay 8  
fill ~44 ~4 ~52 ~46 ~4 ~52 stained_hardened_clay 15 
setblock ~45 ~4 ~16 sea_lantern 0  
fill ~45 ~4 ~34 ~45 ~8 ~34 stained_hardened_clay 15  
fill ~45 ~4 ~35 ~45 ~5 ~35 stained_hardened_clay 8 
setblock ~45 ~4 ~36 sea_lantern 0 
setblock ~45 ~4 ~40 sea_lantern 0  
fill ~45 ~4 ~41 ~45 ~5 ~41 stained_hardened_clay 8  
fill ~45 ~4 ~43 ~45 ~14 ~43 stained_hardened_clay 15  
fill ~45 ~4 ~44 ~45 ~15 ~44 stained_hardened_clay 15  
fill ~45 ~4 ~45 ~45 ~15 ~45 stained_hardened_clay 15  
fill ~45 ~4 ~46 ~45 ~6 ~46 stained_hardened_clay 15  
fill ~45 ~4 ~47 ~45 ~6 ~47 stained_hardened_clay 15 
setblock ~46 ~4 ~32 stained_hardened_clay 15  
fill ~46 ~4 ~34 ~46 ~5 ~34 stained_hardened_clay 8  
fill ~46 ~4 ~43 ~46 ~4 ~46 stained_hardened_clay 8  
fill ~47 ~4 ~43 ~53 ~4 ~43 stained_hardened_clay 15  
fill ~47 ~4 ~44 ~54 ~4 ~44 stained_hardened_clay 15  
fill ~47 ~4 ~45 ~47 ~16 ~45 stained_hardened_clay 15  
fill ~47 ~4 ~63 ~47 ~4 ~65 coal_block 0  
fill ~49 ~4 ~42 ~53 ~4 ~42 stained_hardened_clay 15  
fill ~49 ~4 ~45 ~53 ~4 ~45 stained_hardened_clay 15  
fill ~49 ~4 ~53 ~52 ~4 ~53 stained_hardened_clay 15  
fill ~49 ~4 ~63 ~53 ~4 ~63 stained_hardened_clay 15 
setblock ~50 ~4 ~40 stained_hardened_clay 8  
fill ~50 ~4 ~46 ~50 ~6 ~46 stained_hardened_clay 15 
setblock ~51 ~4 ~39 stained_hardened_clay 8  
fill ~51 ~4 ~40 ~51 ~11 ~40 stained_hardened_clay 15  
fill ~51 ~4 ~47 ~51 ~6 ~47 stained_hardened_clay 15  
fill ~51 ~4 ~51 ~51 ~4 ~52 stained_hardened_clay 8 
setblock ~52 ~4 ~40 stained_hardened_clay 8  
fill ~52 ~4 ~46 ~53 ~4 ~46 stained_hardened_clay 15  
fill ~52 ~4 ~47 ~55 ~4 ~47 stained_hardened_clay 8  
fill ~52 ~4 ~48 ~54 ~4 ~48 stained_hardened_clay 8 
setblock ~52 ~4 ~52 sea_lantern 0 
setblock ~54 ~4 ~45 sea_lantern 0  
fill ~54 ~4 ~46 ~56 ~4 ~46 stained_hardened_clay 8 
setblock ~54 ~4 ~51 sea_lantern 0 
setblock ~54 ~4 ~53 sea_lantern 0  
fill ~55 ~4 ~45 ~57 ~4 ~45 stained_hardened_clay 8  
fill ~55 ~4 ~59 ~56 ~4 ~59 stained_hardened_clay 8  
fill ~55 ~4 ~60 ~56 ~4 ~60 stained_hardened_clay 8 
setblock ~56 ~4 ~47 sea_lantern 0  
fill ~56 ~4 ~52 ~58 ~4 ~52 stained_hardened_clay 8  
fill ~59 ~4 ~41 ~63 ~4 ~41 stained_hardened_clay 15  
fill ~59 ~4 ~42 ~59 ~7 ~42 stained_hardened_clay 15  
fill ~59 ~4 ~44 ~60 ~4 ~44 stained_hardened_clay 8  
fill ~60 ~4 ~42 ~61 ~4 ~42 stained_hardened_clay 8  
fill ~60 ~4 ~43 ~61 ~4 ~43 stained_hardened_clay 8 
setblock ~60 ~4 ~45 sea_lantern 0  
fill ~61 ~4 ~39 ~64 ~4 ~39 stained_hardened_clay 15  
fill ~61 ~4 ~40 ~64 ~4 ~40 stained_hardened_clay 15  
fill ~62 ~4 ~42 ~62 ~8 ~42 stained_hardened_clay 15  
fill ~64 ~4 ~38 ~64 ~2 ~38 stained_hardened_clay 15  
fill ~80 ~4 ~64 ~81 ~4 ~64 stained_hardened_clay 15  
fill ~81 ~4 ~63 ~82 ~4 ~63 stained_hardened_clay 15  
fill ~82 ~4 ~62 ~83 ~4 ~62 stained_hardened_clay 15  
fill ~83 ~4 ~61 ~84 ~4 ~61 stained_hardened_clay 15  
fill ~0 ~5 ~42 ~1 ~5 ~42 stained_hardened_clay 8  
fill ~2 ~5 ~41 ~5 ~5 ~41 stained_hardened_clay 8  
fill ~2 ~5 ~42 ~5 ~5 ~42 stained_hardened_clay 15  
fill ~2 ~5 ~43 ~5 ~5 ~43 stained_hardened_clay 8  
fill ~6 ~5 ~42 ~7 ~5 ~42 stained_hardened_clay 8 
setblock ~15 ~5 ~42 stained_hardened_clay 8 
setblock ~16 ~5 ~41 stained_hardened_clay 8  
fill ~16 ~5 ~42 ~19 ~5 ~42 stained_hardened_clay 15 
setblock ~16 ~5 ~43 stained_hardened_clay 8  
fill ~17 ~5 ~40 ~17 ~5 ~44 stained_hardened_clay 15  
fill ~28 ~5 ~42 ~33 ~5 ~42 stained_hardened_clay 15  
fill ~29 ~5 ~41 ~31 ~5 ~41 stained_hardened_clay 15  
fill ~29 ~5 ~43 ~31 ~5 ~43 stained_hardened_clay 15  
fill ~30 ~5 ~40 ~31 ~5 ~40 stained_hardened_clay 15  
fill ~30 ~5 ~44 ~31 ~5 ~44 stained_hardened_clay 15  
fill ~32 ~5 ~41 ~33 ~5 ~41 stained_hardened_clay 8  
fill ~32 ~5 ~43 ~33 ~5 ~43 stained_hardened_clay 8 
setblock ~34 ~5 ~41 sea_lantern 0  
fill ~34 ~5 ~42 ~36 ~5 ~42 stained_hardened_clay 8 
setblock ~34 ~5 ~43 sea_lantern 0  
fill ~36 ~5 ~48 ~44 ~5 ~48 stained_hardened_clay 15  
fill ~36 ~5 ~49 ~44 ~5 ~49 stained_hardened_clay 15 
setblock ~37 ~5 ~42 sea_lantern 0  
fill ~37 ~5 ~50 ~41 ~5 ~50 stained_hardened_clay 15 
setblock ~37 ~5 ~53 sea_lantern 0  
fill ~38 ~5 ~52 ~38 ~7 ~52 stained_hardened_clay 15 
setblock ~38 ~5 ~53 stained_hardened_clay 8  
fill ~38 ~5 ~58 ~56 ~5 ~58 stained_hardened_clay 15  
fill ~38 ~5 ~59 ~56 ~5 ~59 stained_hardened_clay 15  
fill ~38 ~5 ~60 ~56 ~5 ~60 stained_hardened_clay 15  
fill ~39 ~5 ~46 ~47 ~5 ~46 stained_hardened_clay 15  
fill ~39 ~5 ~47 ~46 ~5 ~47 stained_hardened_clay 15  
fill ~39 ~5 ~53 ~41 ~5 ~53 stained_hardened_clay 15  
fill ~39 ~5 ~54 ~41 ~5 ~54 stained_hardened_clay 8  
fill ~39 ~5 ~55 ~55 ~5 ~55 stained_hardened_clay 15  
fill ~39 ~5 ~56 ~55 ~5 ~56 stained_hardened_clay 15  
fill ~39 ~5 ~57 ~55 ~5 ~57 stained_hardened_clay 15  
fill ~39 ~5 ~62 ~55 ~5 ~62 stained_hardened_clay 15  
fill ~40 ~5 ~45 ~57 ~5 ~45 stained_hardened_clay 15  
fill ~40 ~5 ~51 ~41 ~5 ~51 stained_hardened_clay 15  
fill ~40 ~5 ~52 ~40 ~6 ~52 stained_hardened_clay 15  
fill ~40 ~5 ~63 ~54 ~5 ~63 stained_hardened_clay 15 
setblock ~41 ~5 ~42 sea_lantern 0 
setblock ~41 ~5 ~52 stained_hardened_clay 8  
fill ~41 ~5 ~61 ~55 ~5 ~61 stained_hardened_clay 15  
fill ~42 ~5 ~42 ~44 ~5 ~42 stained_hardened_clay 8  
fill ~42 ~5 ~44 ~42 ~13 ~44 stained_hardened_clay 15  
fill ~42 ~5 ~50 ~42 ~5 ~51 stained_hardened_clay 8  
fill ~42 ~5 ~52 ~42 ~6 ~52 stained_hardened_clay 15 
setblock ~42 ~5 ~53 stained_hardened_clay 8  
fill ~42 ~5 ~54 ~55 ~5 ~54 stained_hardened_clay 15  
fill ~42 ~5 ~64 ~52 ~5 ~64 stained_hardened_clay 15  
fill ~43 ~5 ~18 ~47 ~5 ~18 stained_hardened_clay 15  
fill ~43 ~5 ~33 ~47 ~5 ~33 stained_hardened_clay 15  
fill ~43 ~5 ~34 ~43 ~6 ~34 stained_hardened_clay 15 
setblock ~43 ~5 ~41 sea_lantern 0 
setblock ~43 ~5 ~43 sea_lantern 0  
fill ~43 ~5 ~50 ~43 ~6 ~50 stained_hardened_clay 15  
fill ~43 ~5 ~51 ~46 ~5 ~51 stained_hardened_clay 15 
setblock ~43 ~5 ~52 stained_hardened_clay 8  
fill ~43 ~5 ~53 ~52 ~5 ~53 stained_hardened_clay 15  
fill ~44 ~5 ~17 ~44 ~6 ~17 stained_hardened_clay 8  
fill ~44 ~5 ~19 ~44 ~6 ~19 stained_hardened_clay 15  
fill ~44 ~5 ~35 ~44 ~6 ~35 stained_hardened_clay 8  
fill ~44 ~5 ~41 ~44 ~6 ~41 stained_hardened_clay 8  
fill ~44 ~5 ~43 ~44 ~13 ~43 stained_hardened_clay 15  
fill ~44 ~5 ~44 ~44 ~14 ~44 stained_hardened_clay 15  
fill ~44 ~5 ~50 ~45 ~5 ~50 stained_hardened_clay 8  
fill ~44 ~5 ~52 ~47 ~5 ~52 stained_hardened_clay 15  
fill ~45 ~5 ~16 ~45 ~6 ~16 stained_hardened_clay 8  
fill ~45 ~5 ~17 ~45 ~16 ~17 stained_hardened_clay 15  
fill ~45 ~5 ~36 ~45 ~6 ~36 stained_hardened_clay 8  
fill ~45 ~5 ~40 ~45 ~6 ~40 stained_hardened_clay 8  
fill ~45 ~5 ~42 ~45 ~13 ~42 stained_hardened_clay 15 
setblock ~45 ~5 ~48 stained_hardened_clay 8 
setblock ~45 ~5 ~49 glowstone 0  
fill ~45 ~5 ~65 ~49 ~5 ~65 stained_hardened_clay 15  
fill ~46 ~5 ~17 ~46 ~6 ~17 stained_hardened_clay 8  
fill ~46 ~5 ~19 ~46 ~6 ~19 stained_hardened_clay 15  
fill ~46 ~5 ~41 ~46 ~6 ~41 stained_hardened_clay 8  
fill ~46 ~5 ~42 ~46 ~5 ~41 stained_hardened_clay 8  
fill ~46 ~5 ~43 ~54 ~5 ~43 stained_hardened_clay 15  
fill ~46 ~5 ~44 ~56 ~5 ~44 stained_hardened_clay 15 
setblock ~46 ~5 ~48 glowstone 0 
setblock ~46 ~5 ~50 glowstone 0  
fill ~47 ~5 ~34 ~47 ~6 ~34 stained_hardened_clay 15  
fill ~47 ~5 ~42 ~54 ~5 ~42 stained_hardened_clay 15 
setblock ~47 ~5 ~47 glowstone 0 
setblock ~47 ~5 ~51 glowstone 0  
fill ~47 ~5 ~66 ~47 ~5 ~71 coal_block 0  
fill ~48 ~5 ~41 ~53 ~5 ~41 stained_hardened_clay 15 
setblock ~48 ~5 ~46 glowstone 0 
setblock ~48 ~5 ~52 glowstone 0  
fill ~49 ~5 ~39 ~49 ~9 ~39 stained_hardened_clay 15  
fill ~49 ~5 ~40 ~53 ~5 ~40 stained_hardened_clay 15  
fill ~49 ~5 ~46 ~49 ~6 ~46 stained_hardened_clay 15 
setblock ~49 ~5 ~47 glowstone 0 
setblock ~49 ~5 ~51 glowstone 0  
fill ~49 ~5 ~52 ~49 ~6 ~52 stained_hardened_clay 15 
setblock ~50 ~5 ~37 sea_lantern 0  
fill ~50 ~5 ~38 ~52 ~5 ~38 stained_hardened_clay 8  
fill ~50 ~5 ~39 ~50 ~5 ~38 stained_hardened_clay 8  
fill ~50 ~5 ~47 ~50 ~6 ~47 stained_hardened_clay 15 
setblock ~50 ~5 ~48 glowstone 0 
setblock ~50 ~5 ~50 glowstone 0  
fill ~50 ~5 ~51 ~50 ~6 ~51 stained_hardened_clay 15 
setblock ~51 ~5 ~35 sea_lantern 0 
setblock ~51 ~5 ~37 stained_hardened_clay 8  
fill ~51 ~5 ~39 ~51 ~11 ~39 stained_hardened_clay 15  
fill ~51 ~5 ~48 ~55 ~5 ~48 stained_hardened_clay 15 
setblock ~51 ~5 ~49 glowstone 0  
fill ~51 ~5 ~50 ~51 ~6 ~50 stained_hardened_clay 15  
fill ~51 ~5 ~52 ~51 ~6 ~52 stained_hardened_clay 15 
setblock ~52 ~5 ~37 sea_lantern 0 
setblock ~52 ~5 ~39 stained_hardened_clay 8  
fill ~52 ~5 ~46 ~56 ~5 ~46 stained_hardened_clay 15  
fill ~52 ~5 ~47 ~56 ~5 ~47 stained_hardened_clay 15  
fill ~52 ~5 ~49 ~53 ~5 ~49 stained_hardened_clay 8  
fill ~52 ~5 ~50 ~52 ~5 ~52 stained_hardened_clay 8  
fill ~53 ~5 ~50 ~56 ~5 ~50 stained_hardened_clay 15  
fill ~53 ~5 ~51 ~58 ~5 ~51 stained_hardened_clay 8  
fill ~53 ~5 ~52 ~56 ~5 ~52 stained_hardened_clay 8  
fill ~53 ~5 ~53 ~58 ~5 ~53 stained_hardened_clay 8  
fill ~54 ~5 ~49 ~55 ~5 ~49 stained_hardened_clay 15 
setblock ~56 ~5 ~61 stained_hardened_clay 8 
setblock ~57 ~5 ~46 stained_hardened_clay 8  
fill ~57 ~5 ~52 ~58 ~5 ~52 stained_hardened_clay 15  
fill ~57 ~5 ~59 ~57 ~5 ~60 stained_hardened_clay 8 
setblock ~58 ~5 ~44 sea_lantern 0  
fill ~58 ~5 ~45 ~60 ~5 ~45 stained_hardened_clay 8 
setblock ~58 ~5 ~60 sea_lantern 0  
fill ~59 ~5 ~41 ~64 ~5 ~41 stained_hardened_clay 15  
fill ~59 ~5 ~43 ~62 ~5 ~43 stained_hardened_clay 15  
fill ~59 ~5 ~44 ~61 ~5 ~44 stained_hardened_clay 15 
setblock ~59 ~5 ~51 sea_lantern 0 
setblock ~59 ~5 ~52 stained_hardened_clay 8 
setblock ~59 ~5 ~53 sea_lantern 0  
fill ~60 ~5 ~42 ~63 ~5 ~42 stained_hardened_clay 15  
fill ~61 ~5 ~40 ~64 ~5 ~40 stained_hardened_clay 15 
setblock ~62 ~5 ~39 stained_hardened_clay 15 
setblock ~-2 ~6 ~41 sea_lantern 0  
fill ~-2 ~6 ~42 ~-1 ~6 ~42 stained_hardened_clay 8 
setblock ~-2 ~6 ~43 sea_lantern 0  
fill ~0 ~6 ~41 ~1 ~6 ~41 stained_hardened_clay 8  
fill ~0 ~6 ~42 ~7 ~6 ~42 stained_hardened_clay 15  
fill ~0 ~6 ~43 ~1 ~6 ~43 stained_hardened_clay 8  
fill ~2 ~6 ~40 ~5 ~6 ~40 stained_hardened_clay 15  
fill ~2 ~6 ~41 ~5 ~6 ~41 stained_hardened_clay 15  
fill ~2 ~6 ~43 ~5 ~6 ~43 stained_hardened_clay 15  
fill ~2 ~6 ~44 ~5 ~6 ~44 stained_hardened_clay 15  
fill ~6 ~6 ~41 ~7 ~6 ~41 stained_hardened_clay 8  
fill ~6 ~6 ~43 ~7 ~6 ~43 stained_hardened_clay 8  
fill ~8 ~6 ~42 ~10 ~6 ~42 stained_hardened_clay 8 
setblock ~9 ~6 ~41 sea_lantern 0 
setblock ~9 ~6 ~43 sea_lantern 0 
setblock ~12 ~6 ~42 sea_lantern 0  
fill ~13 ~6 ~42 ~14 ~6 ~42 stained_hardened_clay 8 
setblock ~14 ~6 ~41 sea_lantern 0 
setblock ~14 ~6 ~43 sea_lantern 0 
setblock ~15 ~6 ~41 stained_hardened_clay 8  
fill ~15 ~6 ~42 ~18 ~6 ~42 stained_hardened_clay 15 
setblock ~15 ~6 ~43 stained_hardened_clay 8  
fill ~16 ~6 ~40 ~16 ~6 ~44 stained_hardened_clay 15 
setblock ~17 ~6 ~41 stained_hardened_clay 15 
setblock ~17 ~6 ~43 stained_hardened_clay 15  
fill ~29 ~6 ~42 ~36 ~6 ~42 stained_hardened_clay 15  
fill ~30 ~6 ~41 ~33 ~6 ~41 stained_hardened_clay 15  
fill ~30 ~6 ~43 ~33 ~6 ~43 stained_hardened_clay 15  
fill ~32 ~6 ~40 ~33 ~6 ~40 stained_hardened_clay 15  
fill ~32 ~6 ~44 ~33 ~6 ~44 stained_hardened_clay 15  
fill ~34 ~6 ~41 ~36 ~6 ~41 stained_hardened_clay 8  
fill ~34 ~6 ~43 ~36 ~6 ~43 stained_hardened_clay 8  
fill ~36 ~6 ~47 ~56 ~6 ~47 stained_hardened_clay 15  
fill ~36 ~6 ~48 ~46 ~6 ~48 stained_hardened_clay 15  
fill ~36 ~6 ~49 ~45 ~6 ~49 stained_hardened_clay 15  
fill ~36 ~6 ~53 ~37 ~6 ~53 stained_hardened_clay 8  
fill ~37 ~6 ~42 ~38 ~6 ~42 stained_hardened_clay 8  
fill ~37 ~6 ~46 ~57 ~6 ~46 stained_hardened_clay 15  
fill ~37 ~6 ~50 ~46 ~6 ~50 stained_hardened_clay 15  
fill ~37 ~6 ~51 ~37 ~12 ~51 stained_hardened_clay 15  
fill ~38 ~6 ~53 ~56 ~6 ~53 stained_hardened_clay 15 
setblock ~38 ~6 ~54 stained_hardened_clay 8  
fill ~38 ~6 ~55 ~56 ~6 ~55 stained_hardened_clay 15  
fill ~38 ~6 ~56 ~56 ~6 ~56 stained_hardened_clay 15  
fill ~38 ~6 ~57 ~56 ~6 ~57 stained_hardened_clay 15  
fill ~38 ~6 ~58 ~57 ~6 ~58 stained_hardened_clay 15  
fill ~38 ~6 ~59 ~57 ~6 ~59 stained_hardened_clay 15  
fill ~38 ~6 ~60 ~57 ~6 ~60 stained_hardened_clay 15  
fill ~38 ~6 ~61 ~38 ~11 ~61 stained_hardened_clay 15  
fill ~39 ~6 ~45 ~61 ~6 ~45 stained_hardened_clay 15  
fill ~39 ~6 ~51 ~58 ~6 ~51 stained_hardened_clay 15  
fill ~39 ~6 ~52 ~39 ~6 ~45 stained_hardened_clay 15  
fill ~39 ~6 ~54 ~56 ~6 ~54 stained_hardened_clay 15  
fill ~39 ~6 ~62 ~56 ~6 ~62 stained_hardened_clay 15  
fill ~39 ~6 ~63 ~55 ~6 ~63 stained_hardened_clay 15  
fill ~40 ~6 ~44 ~62 ~6 ~44 stained_hardened_clay 15  
fill ~40 ~6 ~64 ~54 ~6 ~64 stained_hardened_clay 15  
fill ~41 ~6 ~42 ~41 ~6 ~43 stained_hardened_clay 8 
setblock ~41 ~6 ~52 stained_hardened_clay 15  
fill ~41 ~6 ~61 ~56 ~6 ~61 stained_hardened_clay 15  
fill ~41 ~6 ~65 ~53 ~6 ~65 stained_hardened_clay 15  
fill ~42 ~6 ~41 ~44 ~6 ~41 stained_hardened_clay 8  
fill ~42 ~6 ~42 ~55 ~6 ~42 stained_hardened_clay 15 
setblock ~42 ~6 ~43 stained_hardened_clay 8  
fill ~42 ~6 ~66 ~52 ~6 ~66 stained_hardened_clay 15  
fill ~43 ~6 ~18 ~47 ~6 ~18 stained_hardened_clay 15  
fill ~43 ~6 ~35 ~43 ~7 ~35 stained_hardened_clay 15  
fill ~43 ~6 ~43 ~43 ~13 ~43 stained_hardened_clay 15  
fill ~43 ~6 ~52 ~59 ~6 ~52 stained_hardened_clay 15 
setblock ~44 ~6 ~16 sea_lantern 0  
fill ~44 ~6 ~33 ~44 ~6 ~34 stained_hardened_clay 15  
fill ~44 ~6 ~36 ~44 ~7 ~36 stained_hardened_clay 8 
setblock ~44 ~6 ~38 sea_lantern 0  
fill ~44 ~6 ~40 ~44 ~7 ~40 stained_hardened_clay 8  
fill ~44 ~6 ~68 ~50 ~6 ~68 stained_hardened_clay 15  
fill ~44 ~6 ~69 ~50 ~6 ~69 stained_hardened_clay 15  
fill ~44 ~6 ~70 ~50 ~6 ~70 stained_hardened_clay 15  
fill ~45 ~6 ~35 ~45 ~9 ~35 stained_hardened_clay 15  
fill ~45 ~6 ~37 ~45 ~7 ~37 stained_hardened_clay 8  
fill ~45 ~6 ~38 ~45 ~7 ~38 stained_hardened_clay 8  
fill ~45 ~6 ~39 ~45 ~7 ~39 stained_hardened_clay 8  
fill ~45 ~6 ~41 ~45 ~12 ~41 stained_hardened_clay 15  
fill ~45 ~6 ~67 ~49 ~6 ~67 stained_hardened_clay 15  
fill ~45 ~6 ~71 ~49 ~6 ~71 stained_hardened_clay 15 
setblock ~46 ~6 ~16 sea_lantern 0  
fill ~46 ~6 ~33 ~46 ~6 ~34 stained_hardened_clay 15 
setblock ~46 ~6 ~35 stained_hardened_clay 8  
fill ~46 ~6 ~40 ~46 ~7 ~40 stained_hardened_clay 8  
fill ~46 ~6 ~43 ~55 ~6 ~43 stained_hardened_clay 15  
fill ~47 ~6 ~35 ~47 ~7 ~35 stained_hardened_clay 15  
fill ~47 ~6 ~41 ~55 ~6 ~41 stained_hardened_clay 15 
setblock ~47 ~6 ~72 coal_block 0  
fill ~48 ~6 ~40 ~54 ~6 ~40 stained_hardened_clay 15  
fill ~49 ~6 ~38 ~53 ~6 ~38 stained_hardened_clay 15  
fill ~50 ~6 ~36 ~52 ~6 ~36 stained_hardened_clay 8  
fill ~50 ~6 ~37 ~50 ~6 ~36 stained_hardened_clay 8  
fill ~50 ~6 ~39 ~50 ~10 ~39 stained_hardened_clay 15  
fill ~50 ~6 ~48 ~56 ~6 ~48 stained_hardened_clay 15  
fill ~50 ~6 ~49 ~56 ~6 ~49 stained_hardened_clay 15  
fill ~50 ~6 ~50 ~50 ~6 ~38 stained_hardened_clay 15 
setblock ~51 ~6 ~35 stained_hardened_clay 8  
fill ~51 ~6 ~37 ~51 ~10 ~37 stained_hardened_clay 15 
setblock ~52 ~6 ~37 stained_hardened_clay 8  
fill ~52 ~6 ~39 ~53 ~6 ~39 stained_hardened_clay 15  
fill ~52 ~6 ~50 ~58 ~6 ~50 stained_hardened_clay 15  
fill ~57 ~6 ~53 ~59 ~6 ~53 stained_hardened_clay 8  
fill ~57 ~6 ~61 ~58 ~6 ~61 stained_hardened_clay 8  
fill ~58 ~6 ~43 ~63 ~6 ~43 stained_hardened_clay 15  
fill ~58 ~6 ~46 ~59 ~6 ~46 stained_hardened_clay 8  
fill ~58 ~6 ~59 ~58 ~6 ~61 stained_hardened_clay 8 
setblock ~59 ~6 ~51 stained_hardened_clay 8 
setblock ~59 ~6 ~60 stained_hardened_clay 8  
fill ~60 ~6 ~41 ~63 ~6 ~41 stained_hardened_clay 15  
fill ~60 ~6 ~42 ~64 ~6 ~42 stained_hardened_clay 15  
fill ~60 ~6 ~46 ~60 ~10 ~46 stained_hardened_clay 15 
setblock ~60 ~6 ~52 stained_hardened_clay 8  
fill ~62 ~6 ~40 ~63 ~6 ~40 stained_hardened_clay 15 
setblock ~64 ~6 ~83 sea_lantern 0 
setblock ~-3 ~7 ~42 stained_hardened_clay 8  
fill ~-2 ~7 ~41 ~-1 ~7 ~41 stained_hardened_clay 8  
fill ~-2 ~7 ~42 ~10 ~7 ~42 stained_hardened_clay 15  
fill ~-2 ~7 ~43 ~-1 ~7 ~43 stained_hardened_clay 8  
fill ~0 ~7 ~40 ~1 ~7 ~40 stained_hardened_clay 15  
fill ~0 ~7 ~41 ~7 ~7 ~41 stained_hardened_clay 15  
fill ~0 ~7 ~43 ~7 ~7 ~43 stained_hardened_clay 15  
fill ~0 ~7 ~44 ~1 ~7 ~44 stained_hardened_clay 15  
fill ~6 ~7 ~40 ~7 ~7 ~40 stained_hardened_clay 15  
fill ~6 ~7 ~44 ~7 ~7 ~44 stained_hardened_clay 15  
fill ~8 ~7 ~41 ~10 ~7 ~41 stained_hardened_clay 8  
fill ~8 ~7 ~43 ~10 ~7 ~43 stained_hardened_clay 8  
fill ~11 ~7 ~42 ~12 ~7 ~42 stained_hardened_clay 8  
fill ~13 ~7 ~41 ~14 ~7 ~41 stained_hardened_clay 8  
fill ~13 ~7 ~42 ~17 ~7 ~42 stained_hardened_clay 15  
fill ~13 ~7 ~43 ~14 ~7 ~43 stained_hardened_clay 8  
fill ~15 ~7 ~40 ~15 ~7 ~44 stained_hardened_clay 15 
setblock ~16 ~7 ~41 stained_hardened_clay 15 
setblock ~16 ~7 ~43 stained_hardened_clay 15  
fill ~31 ~7 ~42 ~38 ~7 ~42 stained_hardened_clay 15  
fill ~32 ~7 ~41 ~36 ~7 ~41 stained_hardened_clay 15  
fill ~32 ~7 ~43 ~36 ~7 ~43 stained_hardened_clay 15 
setblock ~33 ~7 ~53 sea_lantern 0  
fill ~34 ~7 ~40 ~36 ~7 ~40 stained_hardened_clay 15  
fill ~34 ~7 ~44 ~36 ~7 ~44 stained_hardened_clay 15  
fill ~34 ~7 ~53 ~36 ~7 ~53 stained_hardened_clay 8  
fill ~35 ~7 ~47 ~38 ~7 ~47 stained_hardened_clay 15  
fill ~35 ~7 ~48 ~38 ~7 ~48 stained_hardened_clay 15  
fill ~35 ~7 ~49 ~38 ~7 ~49 stained_hardened_clay 15  
fill ~36 ~7 ~45 ~62 ~7 ~45 stained_hardened_clay 15  
fill ~36 ~7 ~46 ~38 ~7 ~46 stained_hardened_clay 15  
fill ~36 ~7 ~50 ~38 ~7 ~50 stained_hardened_clay 15 
setblock ~36 ~7 ~52 sea_lantern 0 
setblock ~36 ~7 ~54 sea_lantern 0  
fill ~37 ~7 ~41 ~38 ~7 ~41 stained_hardened_clay 8  
fill ~37 ~7 ~43 ~38 ~7 ~43 stained_hardened_clay 8  
fill ~37 ~7 ~52 ~37 ~13 ~52 stained_hardened_clay 15  
fill ~37 ~7 ~53 ~38 ~7 ~53 stained_hardened_clay 15 
setblock ~37 ~7 ~54 stained_hardened_clay 8  
fill ~37 ~7 ~55 ~38 ~7 ~55 stained_hardened_clay 15  
fill ~37 ~7 ~56 ~38 ~7 ~56 stained_hardened_clay 15  
fill ~38 ~7 ~44 ~63 ~7 ~44 stained_hardened_clay 15 
setblock ~38 ~7 ~54 stained_hardened_clay 15  
fill ~38 ~7 ~57 ~38 ~8 ~57 stained_hardened_clay 15  
fill ~38 ~7 ~58 ~38 ~9 ~58 stained_hardened_clay 15  
fill ~38 ~7 ~59 ~38 ~10 ~59 stained_hardened_clay 15  
fill ~38 ~7 ~60 ~38 ~11 ~60 stained_hardened_clay 15  
fill ~38 ~7 ~62 ~38 ~11 ~62 stained_hardened_clay 15 
setblock ~39 ~7 ~41 sea_lantern 0  
fill ~39 ~7 ~42 ~40 ~7 ~42 stained_hardened_clay 8 
setblock ~39 ~7 ~43 sea_lantern 0 
setblock ~39 ~7 ~46 prismarine 1 
setblock ~39 ~7 ~47 redstone_torch 5  
fill ~39 ~7 ~48 ~39 ~7 ~62 planks 5 
fill ~39 ~7 ~63 ~39 ~6 ~63 stained_hardened_clay 15  
fill ~39 ~7 ~64 ~40 ~7 ~64 stained_hardened_clay 15  
fill ~39 ~7 ~65 ~41 ~7 ~65 stained_hardened_clay 15 
setblock ~40 ~7 ~43 stained_hardened_clay 8  
fill ~40 ~7 ~46 ~55 ~7 ~46 planks 5  
fill ~40 ~7 ~47 ~41 ~7 ~47 planks 5  
fill ~40 ~7 ~48 ~43 ~7 ~48 planks 0  
fill ~40 ~7 ~49 ~40 ~7 ~55 planks 0  
fill ~40 ~7 ~56 ~40 ~7 ~57 planks 5  
fill ~40 ~7 ~58 ~40 ~7 ~59 prismarine 2  
fill ~40 ~7 ~60 ~40 ~7 ~63 planks 5  
fill ~40 ~7 ~66 ~42 ~7 ~66 stained_hardened_clay 15 
setblock ~41 ~7 ~41 stained_hardened_clay 8  
fill ~41 ~7 ~42 ~56 ~7 ~42 stained_hardened_clay 15  
fill ~41 ~7 ~43 ~64 ~7 ~43 stained_hardened_clay 15  
fill ~41 ~7 ~49 ~41 ~7 ~50 prismarine 2  
fill ~41 ~7 ~51 ~41 ~7 ~53 planks 5 
setblock ~41 ~7 ~54 prismarine 2 
setblock ~41 ~7 ~55 planks 5  
fill ~41 ~7 ~56 ~41 ~7 ~59 planks 0  
fill ~41 ~7 ~60 ~42 ~7 ~60 prismarine 2  
fill ~41 ~7 ~61 ~41 ~7 ~63 planks 0 
setblock ~41 ~7 ~64 planks 5  
fill ~41 ~7 ~67 ~53 ~7 ~67 stained_hardened_clay 15  
fill ~41 ~7 ~68 ~53 ~7 ~68 stained_hardened_clay 15  
fill ~42 ~7 ~36 ~43 ~7 ~36 stained_hardened_clay 15  
fill ~42 ~7 ~37 ~43 ~7 ~37 stained_hardened_clay 15  
fill ~42 ~7 ~40 ~43 ~7 ~40 stained_hardened_clay 15  
fill ~42 ~7 ~41 ~55 ~7 ~41 stained_hardened_clay 15  
fill ~42 ~7 ~47 ~43 ~7 ~47 prismarine 2  
fill ~42 ~7 ~49 ~43 ~7 ~49 planks 5  
fill ~42 ~7 ~50 ~45 ~7 ~50 planks 5  
fill ~42 ~7 ~51 ~44 ~7 ~51 prismarine 2  
fill ~42 ~7 ~52 ~44 ~7 ~52 planks 5  
fill ~42 ~7 ~53 ~43 ~7 ~53 prismarine 2  
fill ~42 ~7 ~54 ~43 ~7 ~54 planks 5 
setblock ~42 ~7 ~55 prismarine 2 
setblock ~42 ~7 ~56 planks 5 
setblock ~42 ~7 ~57 prismarine 2  
fill ~42 ~7 ~58 ~45 ~7 ~58 planks 5  
fill ~42 ~7 ~59 ~42 ~7 ~58 planks 5  
fill ~42 ~7 ~61 ~44 ~7 ~61 planks 5  
fill ~42 ~7 ~62 ~44 ~7 ~62 planks 5  
fill ~42 ~7 ~63 ~45 ~7 ~63 planks 5 
setblock ~42 ~7 ~64 planks 0 
setblock ~42 ~7 ~65 planks 5  
fill ~42 ~7 ~69 ~45 ~7 ~69 stained_hardened_clay 15  
fill ~43 ~7 ~17 ~47 ~7 ~17 stained_hardened_clay 15  
fill ~43 ~7 ~38 ~43 ~9 ~38 stained_hardened_clay 15  
fill ~43 ~7 ~39 ~43 ~9 ~39 stained_hardened_clay 15  
fill ~43 ~7 ~55 ~44 ~7 ~55 planks 5 
setblock ~43 ~7 ~56 prismarine 2  
fill ~43 ~7 ~57 ~45 ~7 ~57 planks 5 
setblock ~43 ~7 ~59 prismarine 2  
fill ~43 ~7 ~60 ~44 ~7 ~60 planks 5  
fill ~43 ~7 ~64 ~51 ~7 ~64 planks 5  
fill ~43 ~7 ~65 ~51 ~7 ~65 planks 0  
fill ~43 ~7 ~66 ~51 ~7 ~66 planks 5  
fill ~43 ~7 ~70 ~45 ~7 ~70 stained_hardened_clay 15  
fill ~43 ~7 ~71 ~45 ~7 ~71 stained_hardened_clay 15  
fill ~44 ~7 ~16 ~44 ~9 ~16 stained_hardened_clay 8  
fill ~44 ~7 ~18 ~44 ~8 ~18 stained_hardened_clay 15  
fill ~44 ~7 ~34 ~44 ~7 ~35 stained_hardened_clay 15  
fill ~44 ~7 ~37 ~44 ~8 ~37 stained_hardened_clay 8  
fill ~44 ~7 ~38 ~44 ~8 ~38 stained_hardened_clay 8  
fill ~44 ~7 ~39 ~44 ~8 ~39 stained_hardened_clay 8  
fill ~44 ~7 ~47 ~50 ~7 ~47 planks 5  
fill ~44 ~7 ~48 ~44 ~7 ~49 prismarine 2  
fill ~44 ~7 ~53 ~45 ~7 ~53 planks 5 
setblock ~44 ~7 ~54 prismarine 2 
setblock ~44 ~7 ~56 planks 5 
setblock ~44 ~7 ~59 planks 5  
fill ~44 ~7 ~72 ~50 ~7 ~72 stained_hardened_clay 15  
fill ~45 ~7 ~15 ~45 ~9 ~15 stained_hardened_clay 8  
fill ~45 ~7 ~16 ~45 ~17 ~16 stained_hardened_clay 15  
fill ~45 ~7 ~36 ~45 ~10 ~36 stained_hardened_clay 15  
fill ~45 ~7 ~40 ~45 ~11 ~40 stained_hardened_clay 15  
fill ~45 ~7 ~48 ~49 ~7 ~48 planks 0 
setblock ~45 ~7 ~49 planks 5  
fill ~45 ~7 ~51 ~49 ~7 ~51 planks 5 
setblock ~45 ~7 ~52 prismarine 2  
fill ~45 ~7 ~54 ~46 ~7 ~54 planks 5  
fill ~45 ~7 ~55 ~45 ~7 ~56 prismarine 2  
fill ~45 ~7 ~59 ~49 ~7 ~59 prismarine 2  
fill ~45 ~7 ~60 ~49 ~7 ~60 prismarine 2  
fill ~45 ~7 ~61 ~49 ~7 ~61 prismarine 2  
fill ~45 ~7 ~62 ~49 ~7 ~62 prismarine 2  
fill ~46 ~7 ~16 ~46 ~9 ~16 stained_hardened_clay 8  
fill ~46 ~7 ~18 ~46 ~8 ~18 stained_hardened_clay 15  
fill ~46 ~7 ~34 ~46 ~7 ~35 stained_hardened_clay 15 
setblock ~46 ~7 ~36 stained_hardened_clay 8 
setblock ~46 ~7 ~38 sea_lantern 0  
fill ~46 ~7 ~39 ~46 ~8 ~39 stained_hardened_clay 8  
fill ~46 ~7 ~49 ~46 ~7 ~50 planks 0  
fill ~46 ~7 ~52 ~48 ~7 ~52 planks 5 
setblock ~46 ~7 ~53 prismarine 2  
fill ~46 ~7 ~55 ~46 ~7 ~56 planks 5  
fill ~46 ~7 ~57 ~48 ~7 ~57 prismarine 2 
setblock ~46 ~7 ~58 sea_lantern 0  
fill ~46 ~7 ~63 ~48 ~7 ~63 prismarine 2  
fill ~46 ~7 ~69 ~48 ~7 ~69 bookshelf 0  
fill ~46 ~7 ~70 ~48 ~7 ~70 bookshelf 0  
fill ~46 ~7 ~71 ~48 ~7 ~71 bookshelf 0  
fill ~47 ~7 ~36 ~47 ~8 ~36 stained_hardened_clay 15  
fill ~47 ~7 ~40 ~55 ~7 ~40 stained_hardened_clay 15 
setblock ~47 ~7 ~49 trapdoor 9  
fill ~47 ~7 ~50 ~48 ~7 ~50 planks 0 
setblock ~47 ~7 ~53 planks 5  
fill ~47 ~7 ~54 ~47 ~7 ~63 prismarine 2  
fill ~47 ~7 ~73 ~47 ~7 ~75 coal_block 0  
fill ~48 ~7 ~38 ~53 ~7 ~38 stained_hardened_clay 15  
fill ~48 ~7 ~39 ~48 ~8 ~39 stained_hardened_clay 15 
setblock ~48 ~7 ~49 planks 0 
setblock ~48 ~7 ~53 prismarine 2  
fill ~48 ~7 ~54 ~49 ~7 ~54 planks 5  
fill ~48 ~7 ~55 ~48 ~7 ~56 planks 5 
setblock ~48 ~7 ~58 sea_lantern 0  
fill ~49 ~7 ~36 ~53 ~7 ~36 stained_hardened_clay 15  
fill ~49 ~7 ~37 ~53 ~7 ~37 stained_hardened_clay 15  
fill ~49 ~7 ~49 ~49 ~7 ~51 planks 5 
setblock ~49 ~7 ~52 prismarine 2  
fill ~49 ~7 ~53 ~50 ~7 ~53 planks 5  
fill ~49 ~7 ~55 ~49 ~7 ~56 prismarine 2  
fill ~49 ~7 ~57 ~51 ~7 ~57 planks 5  
fill ~49 ~7 ~58 ~52 ~7 ~58 planks 5  
fill ~49 ~7 ~63 ~52 ~7 ~63 planks 5  
fill ~49 ~7 ~69 ~52 ~7 ~69 stained_hardened_clay 15  
fill ~49 ~7 ~70 ~51 ~7 ~70 stained_hardened_clay 15  
fill ~49 ~7 ~71 ~51 ~7 ~71 stained_hardened_clay 15 
setblock ~50 ~7 ~33 sea_lantern 0  
fill ~50 ~7 ~34 ~52 ~7 ~34 stained_hardened_clay 8  
fill ~50 ~7 ~35 ~50 ~7 ~34 stained_hardened_clay 8  
fill ~50 ~7 ~48 ~50 ~7 ~49 prismarine 2  
fill ~50 ~7 ~50 ~52 ~7 ~50 planks 5  
fill ~50 ~7 ~51 ~52 ~7 ~51 prismarine 2  
fill ~50 ~7 ~52 ~53 ~7 ~52 planks 5 
setblock ~50 ~7 ~54 prismarine 2  
fill ~50 ~7 ~55 ~51 ~7 ~55 planks 5  
fill ~50 ~7 ~56 ~50 ~7 ~55 planks 5  
fill ~50 ~7 ~59 ~50 ~7 ~64 planks 5 
setblock ~51 ~7 ~30 sea_lantern 0 
setblock ~51 ~7 ~33 stained_hardened_clay 8  
fill ~51 ~7 ~35 ~51 ~10 ~35 stained_hardened_clay 15  
fill ~51 ~7 ~47 ~52 ~7 ~47 prismarine 2  
fill ~51 ~7 ~48 ~54 ~7 ~48 planks 0  
fill ~51 ~7 ~49 ~52 ~7 ~49 planks 5  
fill ~51 ~7 ~53 ~52 ~7 ~53 prismarine 2  
fill ~51 ~7 ~54 ~52 ~7 ~54 planks 5 
setblock ~51 ~7 ~56 prismarine 2 
setblock ~51 ~7 ~59 prismarine 2  
fill ~51 ~7 ~60 ~51 ~7 ~64 planks 5 
setblock ~52 ~7 ~33 sea_lantern 0 
setblock ~52 ~7 ~35 stained_hardened_clay 8  
fill ~52 ~7 ~39 ~54 ~7 ~39 stained_hardened_clay 15 
setblock ~52 ~7 ~55 prismarine 2 
setblock ~52 ~7 ~56 planks 5 
setblock ~52 ~7 ~57 prismarine 2 
setblock ~52 ~7 ~59 planks 5  
fill ~52 ~7 ~60 ~53 ~7 ~60 prismarine 2  
fill ~52 ~7 ~61 ~52 ~7 ~63 planks 5 
setblock ~52 ~7 ~64 planks 0 
setblock ~52 ~7 ~65 planks 5  
fill ~52 ~7 ~66 ~54 ~7 ~66 stained_hardened_clay 15  
fill ~53 ~7 ~47 ~54 ~7 ~47 planks 5  
fill ~53 ~7 ~49 ~53 ~7 ~50 prismarine 2 
setblock ~53 ~7 ~51 planks 5 
setblock ~53 ~7 ~53 planks 5 
setblock ~53 ~7 ~54 prismarine 2 
setblock ~53 ~7 ~55 planks 5  
fill ~53 ~7 ~56 ~53 ~7 ~59 planks 0  
fill ~53 ~7 ~61 ~53 ~7 ~63 planks 0 
setblock ~53 ~7 ~64 planks 5  
fill ~53 ~7 ~65 ~55 ~7 ~65 stained_hardened_clay 15  
fill ~54 ~7 ~49 ~54 ~7 ~55 planks 0  
fill ~54 ~7 ~56 ~55 ~7 ~56 planks 5  
fill ~54 ~7 ~57 ~55 ~7 ~57 planks 5  
fill ~54 ~7 ~58 ~54 ~7 ~59 prismarine 2  
fill ~54 ~7 ~60 ~55 ~7 ~60 planks 5  
fill ~54 ~7 ~61 ~55 ~7 ~61 planks 5  
fill ~54 ~7 ~62 ~55 ~7 ~62 planks 5  
fill ~54 ~7 ~63 ~54 ~7 ~60 planks 5  
fill ~54 ~7 ~64 ~55 ~7 ~64 stained_hardened_clay 15  
fill ~54 ~7 ~90 ~55 ~7 ~90 stained_hardened_clay 15  
fill ~54 ~7 ~91 ~54 ~9 ~91 stained_hardened_clay 15  
fill ~54 ~7 ~92 ~55 ~7 ~92 stained_hardened_clay 15 
setblock ~55 ~7 ~47 redstone_torch 5  
fill ~55 ~7 ~48 ~55 ~7 ~62 planks 5  
fill ~55 ~7 ~63 ~56 ~7 ~63 stained_hardened_clay 15  
fill ~55 ~7 ~87 ~59 ~7 ~87 stained_hardened_clay 8  
fill ~55 ~7 ~88 ~56 ~7 ~88 stained_hardened_clay 8  
fill ~55 ~7 ~89 ~55 ~9 ~89 stained_hardened_clay 15  
fill ~55 ~7 ~91 ~55 ~9 ~91 stained_hardened_clay 8  
fill ~55 ~7 ~93 ~55 ~9 ~93 stained_hardened_clay 15  
fill ~55 ~7 ~94 ~56 ~7 ~94 stained_hardened_clay 15  
fill ~56 ~7 ~46 ~60 ~7 ~46 stained_hardened_clay 15  
fill ~56 ~7 ~47 ~59 ~7 ~47 stained_hardened_clay 15  
fill ~56 ~7 ~48 ~57 ~7 ~48 stained_hardened_clay 15  
fill ~56 ~7 ~49 ~58 ~7 ~49 stained_hardened_clay 15  
fill ~56 ~7 ~50 ~59 ~7 ~50 stained_hardened_clay 15  
fill ~56 ~7 ~51 ~59 ~7 ~51 stained_hardened_clay 15  
fill ~56 ~7 ~52 ~60 ~7 ~52 stained_hardened_clay 15  
fill ~56 ~7 ~53 ~58 ~7 ~53 stained_hardened_clay 15  
fill ~56 ~7 ~54 ~58 ~7 ~54 stained_hardened_clay 15  
fill ~56 ~7 ~55 ~57 ~7 ~55 stained_hardened_clay 15  
fill ~56 ~7 ~56 ~57 ~7 ~56 stained_hardened_clay 15  
fill ~56 ~7 ~57 ~57 ~7 ~57 stained_hardened_clay 15  
fill ~56 ~7 ~58 ~57 ~7 ~58 stained_hardened_clay 15  
fill ~56 ~7 ~59 ~58 ~7 ~59 stained_hardened_clay 15  
fill ~56 ~7 ~60 ~59 ~7 ~60 stained_hardened_clay 15  
fill ~56 ~7 ~61 ~58 ~7 ~61 stained_hardened_clay 15  
fill ~56 ~7 ~62 ~58 ~7 ~62 stained_hardened_clay 15 
setblock ~56 ~7 ~86 stained_hardened_clay 8  
fill ~56 ~7 ~89 ~56 ~9 ~89 stained_hardened_clay 8  
fill ~56 ~7 ~90 ~56 ~8 ~90 stained_hardened_clay 8  
fill ~56 ~7 ~92 ~56 ~8 ~92 stained_hardened_clay 8  
fill ~56 ~7 ~93 ~56 ~9 ~93 stained_hardened_clay 8  
fill ~56 ~7 ~95 ~60 ~7 ~95 stained_hardened_clay 15 
setblock ~57 ~7 ~88 sea_lantern 0 
setblock ~57 ~7 ~93 sea_lantern 0  
fill ~57 ~7 ~94 ~60 ~7 ~94 stained_hardened_clay 8  
fill ~59 ~7 ~53 ~60 ~7 ~53 stained_hardened_clay 8 
setblock ~59 ~7 ~59 stained_hardened_clay 8  
fill ~59 ~7 ~61 ~60 ~7 ~61 stained_hardened_clay 8  
fill ~59 ~7 ~62 ~61 ~7 ~62 stained_hardened_clay 8  
fill ~59 ~7 ~86 ~61 ~7 ~86 stained_hardened_clay 8  
fill ~60 ~7 ~42 ~63 ~7 ~42 stained_hardened_clay 15 
setblock ~60 ~7 ~51 stained_hardened_clay 8  
fill ~60 ~7 ~59 ~60 ~9 ~59 stained_hardened_clay 15 
setblock ~60 ~7 ~60 stained_hardened_clay 8 
setblock ~60 ~7 ~63 sea_lantern 0 
setblock ~60 ~7 ~87 sea_lantern 0  
fill ~60 ~7 ~90 ~61 ~7 ~90 stained_hardened_clay 15 
setblock ~60 ~7 ~91 stained_hardened_clay 8 
setblock ~61 ~7 ~41 stained_hardened_clay 15 
setblock ~61 ~7 ~52 stained_hardened_clay 8  
fill ~61 ~7 ~60 ~61 ~10 ~60 stained_hardened_clay 15  
fill ~61 ~7 ~61 ~62 ~7 ~61 stained_hardened_clay 15  
fill ~61 ~7 ~63 ~62 ~7 ~63 stained_hardened_clay 8  
fill ~61 ~7 ~85 ~63 ~7 ~85 stained_hardened_clay 8  
fill ~61 ~7 ~91 ~62 ~7 ~91 stained_hardened_clay 15  
fill ~61 ~7 ~92 ~61 ~8 ~92 stained_hardened_clay 8  
fill ~61 ~7 ~93 ~61 ~7 ~92 stained_hardened_clay 8  
fill ~61 ~7 ~94 ~61 ~9 ~94 stained_hardened_clay 15 
setblock ~62 ~7 ~52 sea_lantern 0  
fill ~62 ~7 ~62 ~63 ~7 ~62 stained_hardened_clay 15  
fill ~62 ~7 ~64 ~63 ~7 ~64 stained_hardened_clay 8 
setblock ~62 ~7 ~84 sea_lantern 0  
fill ~62 ~7 ~92 ~62 ~9 ~92 stained_hardened_clay 15  
fill ~62 ~7 ~93 ~62 ~9 ~93 stained_hardened_clay 15 
setblock ~63 ~7 ~41 stained_hardened_clay 15  
fill ~63 ~7 ~63 ~64 ~7 ~63 stained_hardened_clay 15  
fill ~63 ~7 ~65 ~63 ~9 ~65 stained_hardened_clay 8  
fill ~63 ~7 ~84 ~64 ~7 ~84 stained_hardened_clay 8 
setblock ~63 ~7 ~86 sea_lantern 0  
fill ~64 ~7 ~64 ~64 ~10 ~64 stained_hardened_clay 15  
fill ~64 ~7 ~65 ~65 ~7 ~65 stained_hardened_clay 15 
setblock ~64 ~7 ~83 stained_hardened_clay 8  
fill ~65 ~7 ~66 ~65 ~10 ~66 stained_hardened_clay 15  
fill ~65 ~7 ~67 ~66 ~7 ~67 stained_hardened_clay 15 
setblock ~65 ~7 ~81 sea_lantern 0 
setblock ~65 ~7 ~82 stained_hardened_clay 8  
fill ~65 ~7 ~83 ~65 ~10 ~83 stained_hardened_clay 15  
fill ~66 ~7 ~68 ~66 ~10 ~68 stained_hardened_clay 15  
fill ~66 ~7 ~69 ~66 ~10 ~69 stained_hardened_clay 15  
fill ~66 ~7 ~70 ~67 ~7 ~70 stained_hardened_clay 15 
setblock ~66 ~7 ~78 sea_lantern 0  
fill ~66 ~7 ~80 ~66 ~7 ~81 stained_hardened_clay 8  
fill ~66 ~7 ~82 ~66 ~10 ~82 stained_hardened_clay 15  
fill ~67 ~7 ~71 ~67 ~10 ~71 stained_hardened_clay 15  
fill ~67 ~7 ~72 ~67 ~10 ~72 stained_hardened_clay 15  
fill ~67 ~7 ~73 ~68 ~7 ~73 stained_hardened_clay 15 
setblock ~67 ~7 ~76 sea_lantern 0  
fill ~67 ~7 ~77 ~67 ~7 ~79 stained_hardened_clay 8  
fill ~67 ~7 ~80 ~67 ~10 ~80 stained_hardened_clay 15  
fill ~68 ~7 ~74 ~68 ~10 ~74 stained_hardened_clay 15  
fill ~68 ~7 ~75 ~68 ~10 ~75 stained_hardened_clay 15 
setblock ~68 ~7 ~76 stained_hardened_clay 8  
fill ~68 ~7 ~77 ~68 ~10 ~77 stained_hardened_clay 15 
setblock ~-5 ~8 ~42 sea_lantern 0 
setblock ~-4 ~8 ~42 stained_hardened_clay 8 
setblock ~-3 ~8 ~41 stained_hardened_clay 8  
fill ~-3 ~8 ~42 ~16 ~8 ~42 stained_hardened_clay 15 
setblock ~-3 ~8 ~43 stained_hardened_clay 8  
fill ~-2 ~8 ~40 ~-1 ~8 ~40 stained_hardened_clay 15  
fill ~-2 ~8 ~41 ~1 ~8 ~41 stained_hardened_clay 15  
fill ~-2 ~8 ~43 ~1 ~8 ~43 stained_hardened_clay 15  
fill ~-2 ~8 ~44 ~-1 ~8 ~44 stained_hardened_clay 15  
fill ~7 ~8 ~41 ~10 ~8 ~41 stained_hardened_clay 15  
fill ~7 ~8 ~43 ~10 ~8 ~43 stained_hardened_clay 15  
fill ~8 ~8 ~40 ~10 ~8 ~40 stained_hardened_clay 15  
fill ~8 ~8 ~44 ~10 ~8 ~44 stained_hardened_clay 15  
fill ~11 ~8 ~41 ~12 ~8 ~41 stained_hardened_clay 8  
fill ~11 ~8 ~43 ~12 ~8 ~43 stained_hardened_clay 8  
fill ~13 ~8 ~40 ~14 ~8 ~40 stained_hardened_clay 15  
fill ~13 ~8 ~41 ~15 ~8 ~41 stained_hardened_clay 15  
fill ~13 ~8 ~43 ~15 ~8 ~43 stained_hardened_clay 15  
fill ~13 ~8 ~44 ~14 ~8 ~44 stained_hardened_clay 15  
fill ~31 ~8 ~53 ~33 ~8 ~53 stained_hardened_clay 8  
fill ~33 ~8 ~42 ~55 ~8 ~42 stained_hardened_clay 15  
fill ~34 ~8 ~52 ~36 ~8 ~52 stained_hardened_clay 8  
fill ~34 ~8 ~53 ~37 ~8 ~53 stained_hardened_clay 15  
fill ~34 ~8 ~54 ~36 ~8 ~54 stained_hardened_clay 8  
fill ~35 ~8 ~41 ~38 ~8 ~41 stained_hardened_clay 15  
fill ~35 ~8 ~43 ~38 ~8 ~43 stained_hardened_clay 15  
fill ~35 ~8 ~48 ~37 ~8 ~48 stained_hardened_clay 15  
fill ~35 ~8 ~49 ~37 ~8 ~49 stained_hardened_clay 15  
fill ~35 ~8 ~50 ~37 ~8 ~50 stained_hardened_clay 15  
fill ~36 ~8 ~47 ~37 ~8 ~47 stained_hardened_clay 15  
fill ~36 ~8 ~51 ~36 ~10 ~51 stained_hardened_clay 15  
fill ~37 ~8 ~40 ~38 ~8 ~40 stained_hardened_clay 15  
fill ~37 ~8 ~44 ~62 ~8 ~44 stained_hardened_clay 15  
fill ~37 ~8 ~45 ~62 ~8 ~45 stained_hardened_clay 15  
fill ~37 ~8 ~46 ~38 ~8 ~46 stained_hardened_clay 15  
fill ~37 ~8 ~54 ~37 ~11 ~54 stained_hardened_clay 15  
fill ~37 ~8 ~55 ~37 ~12 ~55 stained_hardened_clay 15  
fill ~37 ~8 ~56 ~37 ~13 ~56 stained_hardened_clay 15  
fill ~37 ~8 ~57 ~37 ~14 ~57 stained_hardened_clay 15  
fill ~38 ~8 ~47 ~38 ~9 ~47 planks 5  
fill ~38 ~8 ~48 ~38 ~10 ~48 planks 5  
fill ~38 ~8 ~49 ~38 ~10 ~49 planks 5  
fill ~38 ~8 ~50 ~38 ~11 ~50 planks 5  
fill ~38 ~8 ~51 ~38 ~11 ~51 planks 5  
fill ~38 ~8 ~52 ~38 ~11 ~52 planks 5  
fill ~38 ~8 ~53 ~38 ~10 ~53 planks 5  
fill ~38 ~8 ~54 ~38 ~10 ~54 planks 5  
fill ~38 ~8 ~55 ~38 ~11 ~55 planks 5  
fill ~38 ~8 ~56 ~38 ~12 ~56 planks 5  
fill ~38 ~8 ~63 ~38 ~11 ~63 stained_hardened_clay 15  
fill ~38 ~8 ~64 ~39 ~8 ~64 stained_hardened_clay 15  
fill ~38 ~8 ~65 ~40 ~8 ~65 stained_hardened_clay 15  
fill ~38 ~8 ~66 ~41 ~8 ~66 stained_hardened_clay 15  
fill ~38 ~8 ~67 ~40 ~8 ~67 stained_hardened_clay 15  
fill ~39 ~8 ~41 ~40 ~8 ~41 stained_hardened_clay 8 
setblock ~39 ~8 ~43 stained_hardened_clay 8  
fill ~39 ~8 ~46 ~55 ~8 ~46 planks 5 
setblock ~39 ~8 ~47 wool 0  
fill ~39 ~8 ~48 ~39 ~8 ~56 soul_sand 0  
fill ~39 ~8 ~57 ~39 ~8 ~62 prismarine 1 
setblock ~39 ~8 ~63 planks 5  
fill ~39 ~8 ~68 ~40 ~8 ~68 stained_hardened_clay 15  
fill ~40 ~8 ~43 ~56 ~8 ~43 stained_hardened_clay 15  
fill ~40 ~8 ~48 ~40 ~8 ~56 trapdoor 7 
setblock ~40 ~8 ~64 planks 5  
fill ~40 ~8 ~69 ~41 ~8 ~69 stained_hardened_clay 15  
fill ~41 ~8 ~40 ~54 ~8 ~40 stained_hardened_clay 15  
fill ~41 ~8 ~41 ~54 ~8 ~41 stained_hardened_clay 15 
setblock ~41 ~8 ~65 planks 5  
fill ~41 ~8 ~67 ~42 ~8 ~67 planks 5  
fill ~41 ~8 ~68 ~42 ~8 ~68 planks 5  
fill ~42 ~8 ~37 ~43 ~8 ~37 stained_hardened_clay 15  
fill ~42 ~8 ~38 ~42 ~8 ~45 stained_hardened_clay 15 
setblock ~42 ~8 ~66 planks 5  
fill ~42 ~8 ~69 ~43 ~8 ~69 planks 5  
fill ~42 ~8 ~70 ~42 ~8 ~71 stained_hardened_clay 15  
fill ~43 ~8 ~17 ~47 ~8 ~17 stained_hardened_clay 15  
fill ~43 ~8 ~36 ~54 ~8 ~36 stained_hardened_clay 15  
fill ~43 ~8 ~67 ~51 ~8 ~67 dark_oak_stairs 2 
setblock ~43 ~8 ~68 planks 0  
fill ~43 ~8 ~70 ~44 ~8 ~70 planks 5  
fill ~43 ~8 ~71 ~44 ~8 ~71 planks 5 
setblock ~43 ~8 ~72 stained_hardened_clay 15 
setblock ~44 ~8 ~35 stained_hardened_clay 15 
setblock ~44 ~8 ~68 planks 5 
setblock ~44 ~8 ~69 planks 0 
setblock ~44 ~8 ~72 iron_block 0  
fill ~44 ~8 ~73 ~45 ~8 ~73 stained_hardened_clay 15 
setblock ~45 ~8 ~14 sea_lantern 0  
fill ~45 ~8 ~37 ~45 ~10 ~37 stained_hardened_clay 15  
fill ~45 ~8 ~38 ~45 ~11 ~38 stained_hardened_clay 15  
fill ~45 ~8 ~39 ~45 ~11 ~39 stained_hardened_clay 15  
fill ~45 ~8 ~69 ~45 ~8 ~71 bookshelf 0  
fill ~45 ~8 ~74 ~49 ~8 ~74 stained_hardened_clay 15 
setblock ~46 ~8 ~35 stained_hardened_clay 15  
fill ~46 ~8 ~37 ~46 ~8 ~39 stained_hardened_clay 8  
fill ~46 ~8 ~68 ~48 ~8 ~68 bookshelf 0  
fill ~46 ~8 ~72 ~48 ~8 ~72 bookshelf 0 
setblock ~46 ~8 ~73 sea_lantern 0  
fill ~46 ~8 ~75 ~48 ~8 ~75 stained_hardened_clay 15  
fill ~47 ~8 ~37 ~54 ~8 ~37 stained_hardened_clay 15  
fill ~47 ~8 ~38 ~54 ~8 ~38 stained_hardened_clay 15  
fill ~47 ~8 ~39 ~47 ~9 ~39 stained_hardened_clay 15 
setblock ~47 ~8 ~50 wooden_pressure_plate 0 
setblock ~47 ~8 ~70 enchanting_table 0 
setblock ~47 ~8 ~73 planks 5  
fill ~47 ~8 ~76 ~47 ~8 ~77 coal_block 0 
setblock ~48 ~8 ~73 sea_lantern 0  
fill ~49 ~8 ~34 ~53 ~8 ~34 stained_hardened_clay 15  
fill ~49 ~8 ~35 ~53 ~8 ~35 stained_hardened_clay 15  
fill ~49 ~8 ~69 ~49 ~8 ~71 bookshelf 0  
fill ~49 ~8 ~73 ~50 ~8 ~73 stained_hardened_clay 15  
fill ~50 ~8 ~32 ~52 ~8 ~32 stained_hardened_clay 8  
fill ~50 ~8 ~33 ~50 ~8 ~32 stained_hardened_clay 8 
setblock ~50 ~8 ~68 planks 5 
setblock ~50 ~8 ~69 planks 0  
fill ~50 ~8 ~70 ~51 ~8 ~70 planks 5  
fill ~50 ~8 ~71 ~51 ~8 ~71 planks 5 
setblock ~50 ~8 ~72 gold_block 0  
fill ~51 ~8 ~30 ~51 ~8 ~32 stained_hardened_clay 8  
fill ~51 ~8 ~33 ~51 ~11 ~33 stained_hardened_clay 15 
setblock ~51 ~8 ~68 planks 0  
fill ~51 ~8 ~69 ~52 ~8 ~69 planks 5 
setblock ~51 ~8 ~72 stained_hardened_clay 15 
setblock ~52 ~8 ~33 stained_hardened_clay 8  
fill ~52 ~8 ~39 ~54 ~8 ~39 stained_hardened_clay 15  
fill ~52 ~8 ~66 ~52 ~8 ~69 planks 5  
fill ~52 ~8 ~70 ~52 ~8 ~71 stained_hardened_clay 15 
setblock ~53 ~8 ~65 planks 5  
fill ~53 ~8 ~66 ~56 ~8 ~66 stained_hardened_clay 15  
fill ~53 ~8 ~67 ~53 ~8 ~68 planks 5  
fill ~53 ~8 ~69 ~54 ~8 ~69 stained_hardened_clay 15  
fill ~53 ~8 ~90 ~55 ~8 ~90 stained_hardened_clay 15  
fill ~53 ~8 ~91 ~53 ~8 ~92 stained_hardened_clay 15  
fill ~54 ~8 ~48 ~54 ~8 ~56 trapdoor 6 
setblock ~54 ~8 ~64 planks 5  
fill ~54 ~8 ~65 ~56 ~8 ~65 stained_hardened_clay 15  
fill ~54 ~8 ~67 ~56 ~8 ~67 stained_hardened_clay 15  
fill ~54 ~8 ~68 ~55 ~8 ~68 stained_hardened_clay 15  
fill ~54 ~8 ~87 ~59 ~8 ~87 stained_hardened_clay 15  
fill ~54 ~8 ~88 ~56 ~8 ~88 stained_hardened_clay 15  
fill ~54 ~8 ~89 ~54 ~8 ~87 stained_hardened_clay 15  
fill ~54 ~8 ~92 ~55 ~8 ~92 stained_hardened_clay 15  
fill ~54 ~8 ~93 ~54 ~8 ~94 stained_hardened_clay 15 
setblock ~55 ~8 ~47 wool 0  
fill ~55 ~8 ~48 ~55 ~8 ~56 soul_sand 0  
fill ~55 ~8 ~57 ~55 ~8 ~61 prismarine 1  
fill ~55 ~8 ~62 ~55 ~8 ~63 planks 5  
fill ~55 ~8 ~64 ~56 ~8 ~64 stained_hardened_clay 15  
fill ~55 ~8 ~86 ~56 ~8 ~86 stained_hardened_clay 15  
fill ~55 ~8 ~94 ~57 ~8 ~94 stained_hardened_clay 15  
fill ~55 ~8 ~95 ~61 ~8 ~95 stained_hardened_clay 15  
fill ~56 ~8 ~46 ~61 ~8 ~46 stained_hardened_clay 15  
fill ~56 ~8 ~47 ~56 ~9 ~47 planks 5  
fill ~56 ~8 ~48 ~56 ~10 ~48 planks 5  
fill ~56 ~8 ~49 ~56 ~10 ~49 planks 5  
fill ~56 ~8 ~50 ~56 ~11 ~50 planks 5  
fill ~56 ~8 ~51 ~56 ~11 ~51 planks 5  
fill ~56 ~8 ~52 ~56 ~11 ~52 planks 5  
fill ~56 ~8 ~53 ~56 ~10 ~53 planks 5  
fill ~56 ~8 ~54 ~56 ~10 ~54 planks 5  
fill ~56 ~8 ~55 ~56 ~11 ~55 planks 5  
fill ~56 ~8 ~56 ~56 ~12 ~56 planks 5  
fill ~56 ~8 ~57 ~58 ~8 ~57 stained_hardened_clay 15  
fill ~56 ~8 ~58 ~60 ~8 ~58 stained_hardened_clay 15  
fill ~56 ~8 ~59 ~61 ~8 ~59 stained_hardened_clay 15  
fill ~56 ~8 ~60 ~62 ~8 ~60 stained_hardened_clay 15  
fill ~56 ~8 ~61 ~63 ~8 ~61 stained_hardened_clay 15  
fill ~56 ~8 ~62 ~59 ~8 ~62 stained_hardened_clay 15  
fill ~56 ~8 ~63 ~58 ~8 ~63 stained_hardened_clay 15 
setblock ~56 ~8 ~91 sea_lantern 0  
fill ~56 ~8 ~96 ~59 ~8 ~96 stained_hardened_clay 15  
fill ~57 ~8 ~47 ~60 ~8 ~47 stained_hardened_clay 15  
fill ~57 ~8 ~48 ~58 ~8 ~48 stained_hardened_clay 15  
fill ~57 ~8 ~49 ~59 ~8 ~49 stained_hardened_clay 15  
fill ~57 ~8 ~50 ~60 ~8 ~50 stained_hardened_clay 15  
fill ~57 ~8 ~51 ~60 ~8 ~51 stained_hardened_clay 15  
fill ~57 ~8 ~52 ~61 ~8 ~52 stained_hardened_clay 15  
fill ~57 ~8 ~53 ~59 ~8 ~53 stained_hardened_clay 15  
fill ~57 ~8 ~54 ~59 ~8 ~54 stained_hardened_clay 15  
fill ~57 ~8 ~55 ~58 ~8 ~55 stained_hardened_clay 15  
fill ~57 ~8 ~56 ~57 ~13 ~56 stained_hardened_clay 15  
fill ~57 ~8 ~86 ~58 ~8 ~86 stained_hardened_clay 8  
fill ~57 ~8 ~88 ~59 ~8 ~88 stained_hardened_clay 8  
fill ~57 ~8 ~93 ~60 ~8 ~93 stained_hardened_clay 8  
fill ~58 ~8 ~43 ~63 ~8 ~43 stained_hardened_clay 15  
fill ~58 ~8 ~94 ~60 ~8 ~94 stained_hardened_clay 8  
fill ~59 ~8 ~63 ~62 ~8 ~63 stained_hardened_clay 8  
fill ~59 ~8 ~85 ~60 ~8 ~85 stained_hardened_clay 8  
fill ~59 ~8 ~86 ~63 ~8 ~86 stained_hardened_clay 15  
fill ~60 ~8 ~42 ~62 ~8 ~42 stained_hardened_clay 15  
fill ~60 ~8 ~53 ~61 ~8 ~53 stained_hardened_clay 8  
fill ~60 ~8 ~62 ~61 ~8 ~62 stained_hardened_clay 8  
fill ~60 ~8 ~87 ~61 ~8 ~87 stained_hardened_clay 8  
fill ~60 ~8 ~90 ~61 ~8 ~90 stained_hardened_clay 15 
setblock ~60 ~8 ~92 sea_lantern 0 
setblock ~61 ~8 ~51 stained_hardened_clay 8  
fill ~61 ~8 ~64 ~63 ~8 ~64 stained_hardened_clay 8  
fill ~61 ~8 ~84 ~62 ~8 ~84 stained_hardened_clay 8  
fill ~61 ~8 ~85 ~64 ~8 ~85 stained_hardened_clay 15  
fill ~61 ~8 ~91 ~62 ~8 ~91 stained_hardened_clay 15 
setblock ~61 ~8 ~93 stained_hardened_clay 15 
setblock ~62 ~8 ~52 stained_hardened_clay 8  
fill ~62 ~8 ~62 ~64 ~8 ~62 stained_hardened_clay 15 
setblock ~62 ~8 ~65 stained_hardened_clay 8 
setblock ~62 ~8 ~94 stained_hardened_clay 15  
fill ~63 ~8 ~63 ~65 ~8 ~63 stained_hardened_clay 15  
fill ~63 ~8 ~66 ~64 ~8 ~66 stained_hardened_clay 8 
setblock ~63 ~8 ~67 sea_lantern 0  
fill ~63 ~8 ~83 ~63 ~9 ~83 stained_hardened_clay 8  
fill ~63 ~8 ~84 ~65 ~8 ~84 stained_hardened_clay 15  
fill ~63 ~8 ~92 ~63 ~8 ~93 stained_hardened_clay 15  
fill ~64 ~8 ~65 ~66 ~8 ~65 stained_hardened_clay 15  
fill ~64 ~8 ~67 ~64 ~9 ~67 stained_hardened_clay 8  
fill ~64 ~8 ~70 ~65 ~8 ~70 stained_hardened_clay 8  
fill ~64 ~8 ~82 ~64 ~9 ~82 stained_hardened_clay 8  
fill ~64 ~8 ~83 ~64 ~10 ~83 stained_hardened_clay 15  
fill ~65 ~8 ~64 ~65 ~9 ~64 stained_hardened_clay 15  
fill ~65 ~8 ~67 ~67 ~8 ~67 stained_hardened_clay 15  
fill ~65 ~8 ~68 ~65 ~9 ~68 stained_hardened_clay 8  
fill ~65 ~8 ~69 ~65 ~9 ~69 stained_hardened_clay 8  
fill ~65 ~8 ~71 ~65 ~9 ~71 stained_hardened_clay 8  
fill ~65 ~8 ~80 ~65 ~9 ~80 stained_hardened_clay 8  
fill ~65 ~8 ~81 ~65 ~9 ~81 stained_hardened_clay 8  
fill ~65 ~8 ~82 ~65 ~10 ~82 stained_hardened_clay 15  
fill ~66 ~8 ~66 ~66 ~9 ~66 stained_hardened_clay 15  
fill ~66 ~8 ~70 ~68 ~8 ~70 stained_hardened_clay 15  
fill ~66 ~8 ~71 ~66 ~9 ~71 stained_hardened_clay 15  
fill ~66 ~8 ~72 ~66 ~9 ~72 stained_hardened_clay 8  
fill ~66 ~8 ~73 ~66 ~9 ~73 stained_hardened_clay 8  
fill ~66 ~8 ~77 ~66 ~9 ~77 stained_hardened_clay 8  
fill ~66 ~8 ~78 ~66 ~9 ~78 stained_hardened_clay 8  
fill ~66 ~8 ~79 ~66 ~9 ~79 stained_hardened_clay 8  
fill ~66 ~8 ~80 ~66 ~10 ~80 stained_hardened_clay 15  
fill ~66 ~8 ~81 ~68 ~8 ~81 stained_hardened_clay 15  
fill ~66 ~8 ~83 ~66 ~9 ~83 stained_hardened_clay 15  
fill ~67 ~8 ~68 ~67 ~9 ~68 stained_hardened_clay 15  
fill ~67 ~8 ~69 ~68 ~8 ~69 stained_hardened_clay 15  
fill ~67 ~8 ~73 ~69 ~8 ~73 stained_hardened_clay 15  
fill ~67 ~8 ~74 ~67 ~9 ~74 stained_hardened_clay 8  
fill ~67 ~8 ~75 ~67 ~9 ~75 stained_hardened_clay 8  
fill ~67 ~8 ~76 ~67 ~9 ~76 stained_hardened_clay 8  
fill ~67 ~8 ~77 ~67 ~10 ~77 stained_hardened_clay 15  
fill ~67 ~8 ~78 ~69 ~8 ~78 stained_hardened_clay 15  
fill ~67 ~8 ~79 ~68 ~8 ~79 stained_hardened_clay 15  
fill ~67 ~8 ~82 ~67 ~9 ~82 stained_hardened_clay 15  
fill ~68 ~8 ~71 ~68 ~9 ~71 stained_hardened_clay 15  
fill ~68 ~8 ~72 ~69 ~8 ~72 stained_hardened_clay 15  
fill ~68 ~8 ~76 ~69 ~8 ~76 stained_hardened_clay 15  
fill ~68 ~8 ~80 ~68 ~9 ~80 stained_hardened_clay 15  
fill ~69 ~8 ~74 ~69 ~9 ~74 stained_hardened_clay 15  
fill ~69 ~8 ~75 ~69 ~9 ~75 stained_hardened_clay 15  
fill ~69 ~8 ~77 ~69 ~9 ~77 stained_hardened_clay 15  
fill ~-5 ~9 ~42 ~-5 ~12 ~42 stained_hardened_clay 8  
fill ~-4 ~9 ~41 ~-4 ~12 ~41 stained_hardened_clay 8  
fill ~-4 ~9 ~42 ~1 ~9 ~42 stained_hardened_clay 15  
fill ~-4 ~9 ~43 ~-4 ~12 ~43 stained_hardened_clay 8  
fill ~-3 ~9 ~40 ~-2 ~9 ~40 stained_hardened_clay 15  
fill ~-3 ~9 ~41 ~-1 ~9 ~41 stained_hardened_clay 15  
fill ~-3 ~9 ~43 ~-1 ~9 ~43 stained_hardened_clay 15  
fill ~-3 ~9 ~44 ~-2 ~9 ~44 stained_hardened_clay 15  
fill ~6 ~9 ~42 ~15 ~9 ~42 stained_hardened_clay 15  
fill ~8 ~9 ~41 ~14 ~9 ~41 stained_hardened_clay 15  
fill ~8 ~9 ~43 ~14 ~9 ~43 stained_hardened_clay 15  
fill ~10 ~9 ~40 ~12 ~9 ~40 stained_hardened_clay 15  
fill ~10 ~9 ~44 ~12 ~9 ~44 stained_hardened_clay 15 
setblock ~27 ~9 ~53 sea_lantern 0  
fill ~28 ~9 ~53 ~30 ~9 ~53 stained_hardened_clay 8 
setblock ~30 ~9 ~52 sea_lantern 0 
setblock ~30 ~9 ~54 sea_lantern 0  
fill ~31 ~9 ~52 ~33 ~9 ~52 stained_hardened_clay 8  
fill ~31 ~9 ~53 ~37 ~9 ~53 stained_hardened_clay 15  
fill ~31 ~9 ~54 ~33 ~9 ~54 stained_hardened_clay 8  
fill ~34 ~9 ~51 ~37 ~9 ~51 stained_hardened_clay 15  
fill ~34 ~9 ~52 ~37 ~9 ~52 stained_hardened_clay 15  
fill ~34 ~9 ~54 ~37 ~9 ~54 stained_hardened_clay 15  
fill ~34 ~9 ~55 ~37 ~9 ~55 stained_hardened_clay 15  
fill ~35 ~9 ~49 ~37 ~9 ~49 stained_hardened_clay 15  
fill ~36 ~9 ~42 ~54 ~9 ~42 stained_hardened_clay 15  
fill ~36 ~9 ~48 ~37 ~9 ~48 stained_hardened_clay 15  
fill ~36 ~9 ~50 ~37 ~9 ~50 stained_hardened_clay 15  
fill ~37 ~9 ~46 ~38 ~9 ~46 stained_hardened_clay 15  
fill ~37 ~9 ~47 ~37 ~11 ~47 stained_hardened_clay 15  
fill ~37 ~9 ~64 ~38 ~9 ~64 stained_hardened_clay 15  
fill ~37 ~9 ~65 ~39 ~9 ~65 stained_hardened_clay 15  
fill ~37 ~9 ~66 ~40 ~9 ~66 stained_hardened_clay 15  
fill ~37 ~9 ~67 ~39 ~9 ~67 stained_hardened_clay 15  
fill ~37 ~9 ~68 ~39 ~9 ~68 stained_hardened_clay 15  
fill ~38 ~9 ~41 ~53 ~9 ~41 stained_hardened_clay 15  
fill ~38 ~9 ~43 ~55 ~9 ~43 stained_hardened_clay 15  
fill ~38 ~9 ~45 ~61 ~9 ~45 stained_hardened_clay 15  
fill ~38 ~9 ~57 ~38 ~13 ~57 planks 5  
fill ~38 ~9 ~69 ~40 ~9 ~69 stained_hardened_clay 15  
fill ~39 ~9 ~40 ~53 ~9 ~40 stained_hardened_clay 15  
fill ~39 ~9 ~44 ~62 ~9 ~44 stained_hardened_clay 15  
fill ~39 ~9 ~46 ~55 ~9 ~46 planks 5 
setblock ~39 ~9 ~47 piston_head 1  
fill ~39 ~9 ~48 ~39 ~9 ~56 nether_wart 3  
fill ~39 ~9 ~58 ~39 ~9 ~63 prismarine 1 
setblock ~39 ~9 ~64 sea_lantern 0 
setblock ~40 ~9 ~65 planks 5  
fill ~40 ~9 ~67 ~40 ~9 ~68 planks 5 
setblock ~41 ~9 ~66 planks 5  
fill ~41 ~9 ~67 ~41 ~9 ~68 dark_oak_stairs 1 
setblock ~41 ~9 ~69 planks 5  
fill ~41 ~9 ~70 ~41 ~9 ~71 stained_hardened_clay 15  
fill ~42 ~9 ~70 ~42 ~9 ~71 planks 5  
fill ~42 ~9 ~72 ~42 ~9 ~73 stained_hardened_clay 15  
fill ~43 ~9 ~17 ~47 ~9 ~17 stained_hardened_clay 15  
fill ~43 ~9 ~37 ~47 ~9 ~37 stained_hardened_clay 15 
setblock ~43 ~9 ~72 planks 5  
fill ~43 ~9 ~73 ~43 ~9 ~75 stained_hardened_clay 15 
setblock ~44 ~9 ~36 stained_hardened_clay 15  
fill ~44 ~9 ~38 ~44 ~10 ~38 stained_hardened_clay 15  
fill ~44 ~9 ~39 ~44 ~10 ~39 stained_hardened_clay 15 
setblock ~44 ~9 ~73 planks 5  
fill ~44 ~9 ~74 ~44 ~9 ~76 stained_hardened_clay 15 
setblock ~45 ~9 ~73 dark_oak_stairs 2  
fill ~45 ~9 ~74 ~49 ~9 ~74 planks 5  
fill ~45 ~9 ~75 ~45 ~9 ~77 stained_hardened_clay 15 
setblock ~46 ~9 ~36 stained_hardened_clay 15  
fill ~46 ~9 ~38 ~47 ~9 ~38 stained_hardened_clay 15  
fill ~46 ~9 ~39 ~46 ~10 ~39 stained_hardened_clay 15 
setblock ~46 ~9 ~73 cauldron 6  
fill ~46 ~9 ~75 ~48 ~9 ~75 planks 5  
fill ~46 ~9 ~76 ~50 ~9 ~76 stained_hardened_clay 15  
fill ~46 ~9 ~77 ~49 ~9 ~77 stained_hardened_clay 15 
setblock ~47 ~9 ~73 crafting_table 0 
setblock ~47 ~9 ~78 coal_block 0 
setblock ~48 ~9 ~73 cauldron 6  
fill ~49 ~9 ~31 ~49 ~10 ~31 stained_hardened_clay 15  
fill ~49 ~9 ~32 ~53 ~9 ~32 stained_hardened_clay 15  
fill ~49 ~9 ~33 ~53 ~9 ~33 stained_hardened_clay 15  
fill ~49 ~9 ~34 ~53 ~9 ~34 stained_hardened_clay 15  
fill ~49 ~9 ~35 ~53 ~9 ~35 stained_hardened_clay 15  
fill ~49 ~9 ~36 ~53 ~9 ~36 stained_hardened_clay 15  
fill ~49 ~9 ~37 ~53 ~9 ~37 stained_hardened_clay 15  
fill ~49 ~9 ~38 ~53 ~9 ~38 stained_hardened_clay 15 
setblock ~49 ~9 ~73 dark_oak_stairs 2  
fill ~49 ~9 ~75 ~51 ~9 ~75 stained_hardened_clay 15 
setblock ~50 ~9 ~28 sea_lantern 0  
fill ~50 ~9 ~29 ~52 ~9 ~29 stained_hardened_clay 8  
fill ~50 ~9 ~30 ~50 ~9 ~31 stained_hardened_clay 8 
setblock ~50 ~9 ~73 planks 5  
fill ~50 ~9 ~74 ~51 ~9 ~74 stained_hardened_clay 15 
setblock ~51 ~9 ~25 sea_lantern 0  
fill ~51 ~9 ~27 ~51 ~9 ~29 stained_hardened_clay 8  
fill ~51 ~9 ~30 ~51 ~12 ~30 stained_hardened_clay 15  
fill ~51 ~9 ~31 ~51 ~12 ~31 stained_hardened_clay 15 
setblock ~51 ~9 ~72 planks 5  
fill ~51 ~9 ~73 ~52 ~9 ~73 stained_hardened_clay 15 
setblock ~52 ~9 ~28 sea_lantern 0  
fill ~52 ~9 ~30 ~52 ~9 ~31 stained_hardened_clay 8  
fill ~52 ~9 ~39 ~53 ~9 ~39 stained_hardened_clay 15  
fill ~52 ~9 ~70 ~52 ~9 ~71 planks 5 
setblock ~52 ~9 ~72 stained_hardened_clay 15 
setblock ~53 ~9 ~66 planks 5  
fill ~53 ~9 ~67 ~53 ~9 ~68 dark_oak_stairs 0 
setblock ~53 ~9 ~69 planks 5  
fill ~53 ~9 ~70 ~53 ~9 ~71 stained_hardened_clay 15 
setblock ~54 ~9 ~65 planks 5  
fill ~54 ~9 ~66 ~57 ~9 ~66 stained_hardened_clay 15  
fill ~54 ~9 ~67 ~54 ~9 ~68 planks 5  
fill ~54 ~9 ~69 ~56 ~9 ~69 stained_hardened_clay 15 
setblock ~54 ~9 ~90 stained_hardened_clay 15  
fill ~54 ~9 ~92 ~54 ~7 ~92 stained_hardened_clay 15 
setblock ~55 ~9 ~47 piston_head 1  
fill ~55 ~9 ~48 ~55 ~9 ~56 nether_wart 3  
fill ~55 ~9 ~58 ~55 ~9 ~63 prismarine 1 
setblock ~55 ~9 ~64 sea_lantern 0  
fill ~55 ~9 ~65 ~57 ~9 ~65 stained_hardened_clay 15  
fill ~55 ~9 ~67 ~57 ~9 ~67 stained_hardened_clay 15 
setblock ~55 ~9 ~68 planks 5  
fill ~55 ~9 ~87 ~61 ~9 ~87 stained_hardened_clay 15  
fill ~55 ~9 ~88 ~56 ~9 ~88 stained_hardened_clay 15 
setblock ~55 ~9 ~90 stained_hardened_clay 8 
setblock ~55 ~9 ~92 stained_hardened_clay 8  
fill ~55 ~9 ~94 ~56 ~9 ~94 stained_hardened_clay 15  
fill ~56 ~9 ~46 ~60 ~9 ~46 stained_hardened_clay 15  
fill ~56 ~9 ~57 ~56 ~13 ~57 planks 5  
fill ~56 ~9 ~58 ~59 ~9 ~58 stained_hardened_clay 15  
fill ~56 ~9 ~59 ~60 ~9 ~59 stained_hardened_clay 15  
fill ~56 ~9 ~60 ~62 ~9 ~60 stained_hardened_clay 15  
fill ~56 ~9 ~61 ~63 ~9 ~61 stained_hardened_clay 15  
fill ~56 ~9 ~62 ~64 ~9 ~62 stained_hardened_clay 15  
fill ~56 ~9 ~63 ~60 ~9 ~63 stained_hardened_clay 15  
fill ~56 ~9 ~64 ~57 ~9 ~64 stained_hardened_clay 15  
fill ~56 ~9 ~68 ~57 ~9 ~68 stained_hardened_clay 15  
fill ~56 ~9 ~86 ~63 ~9 ~86 stained_hardened_clay 15  
fill ~56 ~9 ~95 ~60 ~9 ~95 stained_hardened_clay 15  
fill ~57 ~9 ~47 ~60 ~9 ~47 stained_hardened_clay 15  
fill ~57 ~9 ~48 ~59 ~9 ~48 stained_hardened_clay 15  
fill ~57 ~9 ~49 ~58 ~9 ~49 stained_hardened_clay 15  
fill ~57 ~9 ~50 ~61 ~9 ~50 stained_hardened_clay 15  
fill ~57 ~9 ~51 ~61 ~9 ~51 stained_hardened_clay 15  
fill ~57 ~9 ~52 ~62 ~9 ~52 stained_hardened_clay 15  
fill ~57 ~9 ~53 ~61 ~9 ~53 stained_hardened_clay 15 
fill ~57 ~9 ~54 ~61 ~9 ~54 stained_hardened_clay 15  
fill ~57 ~9 ~55 ~59 ~9 ~55 stained_hardened_clay 15  
fill ~57 ~9 ~57 ~58 ~9 ~57 stained_hardened_clay 15  
fill ~57 ~9 ~88 ~57 ~8 ~88 stained_hardened_clay 8 
setblock ~57 ~9 ~89 sea_lantern 0  
fill ~57 ~9 ~94 ~60 ~9 ~94 stained_hardened_clay 8  
fill ~58 ~9 ~56 ~58 ~12 ~56 stained_hardened_clay 15  
fill ~58 ~9 ~88 ~59 ~9 ~88 stained_hardened_clay 15 
setblock ~58 ~9 ~93 sea_lantern 0  
fill ~59 ~9 ~85 ~64 ~9 ~85 stained_hardened_clay 15  
fill ~61 ~9 ~43 ~62 ~9 ~43 stained_hardened_clay 15 
setblock ~61 ~9 ~63 sea_lantern 0  
fill ~61 ~9 ~84 ~62 ~9 ~84 stained_hardened_clay 8 
setblock ~61 ~9 ~93 stained_hardened_clay 8 
setblock ~62 ~9 ~51 stained_hardened_clay 8 
setblock ~62 ~9 ~53 stained_hardened_clay 8  
fill ~62 ~9 ~63 ~65 ~9 ~63 stained_hardened_clay 15 
setblock ~62 ~9 ~64 stained_hardened_clay 8 
setblock ~63 ~9 ~51 sea_lantern 0 
setblock ~63 ~9 ~52 stained_hardened_clay 8 
setblock ~63 ~9 ~53 sea_lantern 0 
setblock ~63 ~9 ~64 stained_hardened_clay 15  
fill ~63 ~9 ~66 ~64 ~9 ~66 stained_hardened_clay 8  
fill ~63 ~9 ~84 ~65 ~9 ~84 stained_hardened_clay 15  
fill ~64 ~9 ~65 ~66 ~9 ~65 stained_hardened_clay 15 
setblock ~64 ~9 ~68 stained_hardened_clay 8 
setblock ~64 ~9 ~71 sea_lantern 0  
fill ~65 ~9 ~67 ~67 ~9 ~67 stained_hardened_clay 15 
setblock ~65 ~9 ~70 stained_hardened_clay 8 
setblock ~65 ~9 ~72 stained_hardened_clay 8 
setblock ~65 ~9 ~79 sea_lantern 0  
fill ~66 ~9 ~70 ~68 ~9 ~70 stained_hardened_clay 15 
setblock ~66 ~9 ~74 sea_lantern 0  
fill ~66 ~9 ~81 ~68 ~9 ~81 stained_hardened_clay 15  
fill ~67 ~9 ~69 ~68 ~9 ~69 stained_hardened_clay 15  
fill ~67 ~9 ~73 ~69 ~9 ~73 stained_hardened_clay 15  
fill ~67 ~9 ~78 ~69 ~9 ~78 stained_hardened_clay 15  
fill ~67 ~9 ~79 ~68 ~9 ~79 stained_hardened_clay 15  
fill ~68 ~9 ~72 ~69 ~9 ~72 stained_hardened_clay 15  
fill ~68 ~9 ~76 ~69 ~9 ~76 stained_hardened_clay 15  
fill ~-4 ~10 ~42 ~-1 ~10 ~42 stained_hardened_clay 15  
fill ~-3 ~10 ~40 ~-3 ~12 ~40 stained_hardened_clay 15  
fill ~-3 ~10 ~41 ~-2 ~10 ~41 stained_hardened_clay 15  
fill ~-3 ~10 ~43 ~-2 ~10 ~43 stained_hardened_clay 15  
fill ~-3 ~10 ~44 ~-3 ~12 ~44 stained_hardened_clay 15  
fill ~8 ~10 ~42 ~14 ~10 ~42 stained_hardened_clay 15  
fill ~9 ~10 ~41 ~12 ~10 ~41 stained_hardened_clay 15  
fill ~9 ~10 ~43 ~12 ~10 ~43 stained_hardened_clay 15 
setblock ~27 ~10 ~53 stained_hardened_clay 8  
fill ~28 ~10 ~52 ~30 ~10 ~52 stained_hardened_clay 8  
fill ~28 ~10 ~53 ~37 ~10 ~53 stained_hardened_clay 15  
fill ~28 ~10 ~54 ~30 ~10 ~54 stained_hardened_clay 8  
fill ~31 ~10 ~51 ~33 ~10 ~51 stained_hardened_clay 15  
fill ~31 ~10 ~52 ~37 ~10 ~52 stained_hardened_clay 15  
fill ~31 ~10 ~54 ~37 ~10 ~54 stained_hardened_clay 15  
fill ~31 ~10 ~55 ~33 ~10 ~55 stained_hardened_clay 15  
fill ~36 ~10 ~49 ~37 ~10 ~49 stained_hardened_clay 15  
fill ~36 ~10 ~55 ~36 ~11 ~55 stained_hardened_clay 15  
fill ~36 ~10 ~64 ~38 ~10 ~64 stained_hardened_clay 15  
fill ~36 ~10 ~65 ~38 ~10 ~65 stained_hardened_clay 15  
fill ~36 ~10 ~66 ~39 ~10 ~66 stained_hardened_clay 15  
fill ~36 ~10 ~67 ~39 ~10 ~67 stained_hardened_clay 15  
fill ~36 ~10 ~68 ~39 ~10 ~68 stained_hardened_clay 15  
fill ~37 ~10 ~46 ~39 ~10 ~46 stained_hardened_clay 15  
fill ~37 ~10 ~48 ~37 ~11 ~48 stained_hardened_clay 15  
fill ~37 ~10 ~50 ~37 ~12 ~50 stained_hardened_clay 15  
fill ~37 ~10 ~58 ~37 ~16 ~58 stained_hardened_clay 15  
fill ~37 ~10 ~59 ~37 ~17 ~59 stained_hardened_clay 15  
fill ~37 ~10 ~61 ~37 ~27 ~61 stained_hardened_clay 15  
fill ~37 ~10 ~62 ~37 ~28 ~62 stained_hardened_clay 15  
fill ~37 ~10 ~63 ~37 ~29 ~63 stained_hardened_clay 15  
fill ~37 ~10 ~69 ~39 ~10 ~69 stained_hardened_clay 15  
fill ~38 ~10 ~42 ~52 ~10 ~42 stained_hardened_clay 15  
fill ~38 ~10 ~45 ~60 ~10 ~45 stained_hardened_clay 15  
fill ~38 ~10 ~47 ~38 ~12 ~47 stained_hardened_clay 15  
fill ~38 ~10 ~58 ~38 ~14 ~58 planks 5  
fill ~38 ~10 ~70 ~40 ~10 ~70 stained_hardened_clay 15  
fill ~39 ~10 ~43 ~54 ~10 ~43 stained_hardened_clay 15  
fill ~39 ~10 ~44 ~56 ~10 ~44 stained_hardened_clay 15 
setblock ~39 ~10 ~47 prismarine 1  
fill ~39 ~10 ~59 ~39 ~10 ~65 prismarine 1  
fill ~40 ~10 ~41 ~52 ~10 ~41 stained_hardened_clay 15  
fill ~40 ~10 ~46 ~54 ~10 ~46 planks 5  
fill ~40 ~10 ~66 ~40 ~10 ~69 prismarine 1 
setblock ~40 ~10 ~71 stained_hardened_clay 15  
fill ~41 ~10 ~70 ~41 ~10 ~71 prismarine 1  
fill ~41 ~10 ~72 ~41 ~10 ~74 stained_hardened_clay 15  
fill ~42 ~10 ~40 ~52 ~10 ~40 stained_hardened_clay 15  
fill ~42 ~10 ~72 ~42 ~10 ~73 prismarine 1  
fill ~42 ~10 ~74 ~42 ~10 ~76 stained_hardened_clay 15  
fill ~43 ~10 ~16 ~47 ~10 ~16 stained_hardened_clay 15  
fill ~43 ~10 ~73 ~43 ~10 ~75 prismarine 1  
