fill ~22~0~0 ~22~0~5 minecraft:log 1
setblock ~22~1~0 minecraft:deepslate_brick_wall 0
fill ~23~0~0 ~25~0~0 minecraft:spruce_stairs 2
fill ~26~0~0 ~26~0~5 minecraft:log 1
setblock ~26~1~0 minecraft:deepslate_brick_wall 0
fill ~30~0~0 ~30~0~5 minecraft:log 1
setblock ~30~1~0 minecraft:deepslate_brick_wall 0
fill ~31~0~0 ~33~0~0 minecraft:spruce_stairs 2
fill ~34~0~0 ~34~0~5 minecraft:log 1
setblock ~34~1~0 minecraft:deepslate_brick_wall 0
setblock ~22~1~1 minecraft:log 1
setblock ~22~2~1 minecraft:deepslate_brick_wall 0
fill ~23~0~1 ~25~0~1 minecraft:barrel 3
fill ~23~1~1 ~25~1~1 minecraft:spruce_stairs 2
setblock ~26~1~1 minecraft:log 1
setblock ~26~2~1 minecraft:deepslate_brick_wall 0
setblock ~30~1~1 minecraft:log 1
setblock ~30~2~1 minecraft:deepslate_brick_wall 0
fill ~31~0~1 ~33~0~1 minecraft:barrel 3
fill ~31~1~1 ~33~1~1 minecraft:spruce_stairs 2
setblock ~34~1~1 minecraft:log 1
setblock ~34~2~1 minecraft:deepslate_brick_wall 0
fill ~22~1~2 ~22~1~4 minecraft:fence 5
setblock ~22~2~2 minecraft:log 1
setblock ~22~3~2 minecraft:deepslate_brick_wall 0
fill ~23~0~2 ~23~1~5 minecraft:chest 5
fill ~23~2~2 ~25~2~2 minecraft:spruce_stairs 2
fill ~25~0~2 ~25~1~5 minecraft:chest 4
fill ~26~1~2 ~26~1~4 minecraft:fence 5
setblock ~26~2~2 minecraft:log 1
setblock ~26~3~2 minecraft:deepslate_brick_wall 0
fill ~30~1~2 ~30~1~4 minecraft:fence 5
setblock ~30~2~2 minecraft:log 1
setblock ~30~3~2 minecraft:deepslate_brick_wall 0
fill ~31~0~2 ~31~1~5 minecraft:chest 5
fill ~31~2~2 ~33~2~2 minecraft:spruce_stairs 2
fill ~33~0~2 ~33~1~5 minecraft:chest 4
fill ~34~1~2 ~34~1~4 minecraft:fence 5
setblock ~34~2~2 minecraft:log 1
setblock ~34~3~2 minecraft:deepslate_brick_wall 0
fill ~22~2~3 ~22~2~4 minecraft:fence 5
setblock ~22~3~3 minecraft:log 1
setblock ~22~4~3 minecraft:deepslate_brick_wall 0
fill ~23~3~3 ~25~3~3 minecraft:spruce_stairs 2
fill ~26~2~3 ~26~2~4 minecraft:fence 5
setblock ~26~3~3 minecraft:log 1
setblock ~26~4~3 minecraft:deepslate_brick_wall 0
fill ~30~2~3 ~30~2~4 minecraft:fence 5
setblock ~30~3~3 minecraft:log 1
setblock ~30~4~3 minecraft:deepslate_brick_wall 0
fill ~31~3~3 ~33~3~3 minecraft:spruce_stairs 2
setblock ~32~2~3 minecraft:lantern 1
fill ~34~2~3 ~34~2~4 minecraft:fence 5
setblock ~34~3~3 minecraft:log 1
setblock ~34~4~3 minecraft:deepslate_brick_wall 0
fill ~5~15~4 ~11~15~4 minecraft:deepslate_brick_stairs 2
setblock ~6~0~4 minecraft:jungle_stairs 6
setblock ~6~1~4 minecraft:deepslate_brick_wall 0
setblock ~6~2~4 minecraft:fence 5
setblock ~6~3~4 minecraft:deepslate_brick_wall 0
setblock ~6~4~4 minecraft:jungle_stairs 2
setblock ~6~9~4 minecraft:jungle_trapdoor 3
fill ~7~9~4 ~9~9~4 minecraft:spruce_wall_sign 2
setblock ~10~0~4 minecraft:jungle_stairs 6
setblock ~10~1~4 minecraft:deepslate_brick_wall 0
setblock ~10~2~4 minecraft:fence 5
setblock ~10~3~4 minecraft:deepslate_brick_wall 0
setblock ~10~4~4 minecraft:jungle_stairs 2
setblock ~10~9~4 minecraft:jungle_trapdoor 3
setblock ~14~0~4 minecraft:jungle_stairs 6
setblock ~14~1~4 minecraft:deepslate_brick_wall 0
setblock ~14~2~4 minecraft:fence 5
setblock ~14~3~4 minecraft:deepslate_brick_wall 0
setblock ~14~4~4 minecraft:jungle_stairs 2
setblock ~14~9~4 minecraft:jungle_trapdoor 3
setblock ~18~0~4 minecraft:jungle_stairs 6
setblock ~18~1~4 minecraft:deepslate_brick_wall 0
setblock ~18~2~4 minecraft:fence 5
setblock ~18~3~4 minecraft:deepslate_brick_wall 0
setblock ~18~4~4 minecraft:jungle_stairs 2
setblock ~18~9~4 minecraft:jungle_trapdoor 3
setblock ~22~3~4 minecraft:fence 5
fill ~22~4~4 ~22~4~5 minecraft:log 1
setblock ~22~5~4 minecraft:deepslate_brick_wall 0
setblock ~22~9~4 minecraft:jungle_trapdoor 3
fill ~23~4~4 ~25~4~4 minecraft:spruce_stairs 2
setblock ~26~3~4 minecraft:fence 5
fill ~26~4~4 ~26~4~5 minecraft:log 1
setblock ~26~5~4 minecraft:deepslate_brick_wall 0
setblock ~26~9~4 minecraft:jungle_trapdoor 3
fill ~27~3~4 ~29~3~4 minecraft:dark_oak_stairs 2
fill ~27~4~4 ~29~4~4 minecraft:trapdoor 3
setblock ~28~2~4 minecraft:lantern 1
setblock ~30~3~4 minecraft:fence 5
fill ~30~4~4 ~30~4~5 minecraft:log 1
setblock ~30~5~4 minecraft:deepslate_brick_wall 0
setblock ~30~9~4 minecraft:jungle_trapdoor 3
fill ~31~4~4 ~33~4~4 minecraft:spruce_stairs 2
setblock ~32~3~4 minecraft:lantern 1
setblock ~34~3~4 minecraft:fence 5
fill ~34~4~4 ~34~4~5 minecraft:log 1
setblock ~34~5~4 minecraft:deepslate_brick_wall 0
setblock ~34~9~4 minecraft:jungle_trapdoor 3
setblock ~38~0~4 minecraft:jungle_stairs 6
setblock ~38~1~4 minecraft:deepslate_brick_wall 0
setblock ~38~2~4 minecraft:fence 5
setblock ~38~3~4 minecraft:deepslate_brick_wall 0
setblock ~38~4~4 minecraft:jungle_stairs 2
setblock ~38~9~4 minecraft:jungle_trapdoor 3
setblock ~42~0~4 minecraft:jungle_stairs 6
setblock ~42~1~4 minecraft:deepslate_brick_wall 0
setblock ~42~2~4 minecraft:fence 5
setblock ~42~3~4 minecraft:deepslate_brick_wall 0
setblock ~42~4~4 minecraft:jungle_stairs 2
setblock ~42~9~4 minecraft:jungle_trapdoor 3
setblock ~45~14~4 minecraft:lantern 1
fill ~45~15~4 ~51~15~4 minecraft:deepslate_brick_stairs 2
setblock ~46~0~4 minecraft:jungle_stairs 6
setblock ~46~1~4 minecraft:deepslate_brick_wall 0
setblock ~46~2~4 minecraft:fence 5
setblock ~46~3~4 minecraft:deepslate_brick_wall 0
setblock ~46~4~4 minecraft:jungle_stairs 2
setblock ~46~9~4 minecraft:jungle_trapdoor 3
fill ~47~9~4 ~49~9~4 minecraft:spruce_wall_sign 2
setblock ~50~0~4 minecraft:jungle_stairs 6
setblock ~50~1~4 minecraft:deepslate_brick_wall 0
setblock ~50~2~4 minecraft:fence 5
setblock ~50~3~4 minecraft:deepslate_brick_wall 0
setblock ~50~4~4 minecraft:jungle_stairs 2
setblock ~50~9~4 minecraft:jungle_trapdoor 3
setblock ~51~14~4 minecraft:lantern 1
setblock ~5~0~5 minecraft:jungle_stairs 4
setblock ~5~1~5 minecraft:deepslate_brick_wall 0
setblock ~5~2~5 minecraft:fence 5
setblock ~5~3~5 minecraft:deepslate_brick_wall 0
setblock ~5~4~5 minecraft:jungle_stairs 0
setblock ~5~9~5 minecraft:jungle_trapdoor 1
setblock ~5~15~5 minecraft:deepslate_brick_stairs 7
setblock ~5~16~5 minecraft:deepslate_brick_stairs 2
fill ~6~0~5 ~6~15~5 minecraft:log 1
fill ~6~16~5 ~10~16~5 minecraft:dark_oak_stairs 2
fill ~7~0~5 ~9~0~5 minecraft:deepslate_brick_stairs 2
fill ~7~1~5 ~9~1~5 minecraft:fence 5
fill ~7~4~5 ~9~4~5 minecraft:log 1
fill ~7~5~5 ~9~5~5 minecraft:fence 5
fill ~7~9~5 ~9~9~5 minecraft:log 1
fill ~7~10~5 ~9~10~5 minecraft:fence 5
fill ~7~14~5 ~9~14~5 minecraft:jungle_fence_gate 2
fill ~7~15~5 ~9~15~5 minecraft:log 1
setblock ~8~3~5 minecraft:lantern 1
fill ~10~0~5 ~10~15~5 minecraft:log 1
fill ~11~0~5 ~13~0~5 minecraft:deepslate_brick_stairs 2
fill ~11~1~5 ~13~1~5 minecraft:fence 5
fill ~11~4~5 ~13~4~5 minecraft:log 1
fill ~11~5~5 ~13~5~5 minecraft:fence 5
setblock ~11~9~5 minecraft:jungle_trapdoor 0
setblock ~11~15~5 minecraft:deepslate_brick_stairs 7
setblock ~11~16~5 minecraft:deepslate_brick_stairs 2
setblock ~12~3~5 minecraft:lantern 1
setblock ~13~9~5 minecraft:jungle_trapdoor 1
fill ~14~0~5 ~14~5~5 minecraft:log 1
setblock ~14~6~5 minecraft:deepslate_brick_wall 0
setblock ~14~7~5 minecraft:fence 5
setblock ~14~8~5 minecraft:deepslate_brick_wall 0
setblock ~14~9~5 minecraft:glowstone
setblock ~14~10~5 minecraft:deepslate_brick_slab 0
fill ~15~0~5 ~17~0~5 minecraft:deepslate_brick_stairs 2
fill ~15~1~5 ~17~1~5 minecraft:fence 5
fill ~15~4~5 ~17~4~5 minecraft:log 1
fill ~15~5~5 ~17~5~5 minecraft:fence 5
setblock ~15~9~5 minecraft:jungle_trapdoor 0
setblock ~16~3~5 minecraft:lantern 1
setblock ~17~9~5 minecraft:jungle_trapdoor 1
fill ~18~0~5 ~18~5~5 minecraft:log 1
setblock ~18~6~5 minecraft:deepslate_brick_wall 0
setblock ~18~7~5 minecraft:fence 5
setblock ~18~8~5 minecraft:deepslate_brick_wall 0
setblock ~18~9~5 minecraft:glowstone
setblock ~18~10~5 minecraft:deepslate_brick_slab 0
fill ~19~0~5 ~21~0~5 minecraft:deepslate_brick_stairs 2
fill ~19~1~5 ~21~1~5 minecraft:fence 5
fill ~19~4~5 ~21~4~5 minecraft:log 1
fill ~19~5~5 ~21~5~5 minecraft:fence 5
setblock ~19~9~5 minecraft:jungle_trapdoor 0
setblock ~20~3~5 minecraft:lantern 1
setblock ~21~9~5 minecraft:jungle_trapdoor 1
fill ~22~1~5 ~22~3~5 minecraft:log 1
setblock ~22~5~5 minecraft:log 1
setblock ~22~6~5 minecraft:deepslate_brick_wall 0
setblock ~22~7~5 minecraft:fence 5
setblock ~22~8~5 minecraft:deepslate_brick_wall 0
setblock ~22~9~5 minecraft:glowstone
setblock ~22~10~5 minecraft:deepslate_brick_slab 0
fill ~23~4~5 ~25~4~5 minecraft:log 1
setblock ~23~9~5 minecraft:jungle_trapdoor 0
setblock ~25~9~5 minecraft:jungle_trapdoor 1
fill ~26~1~5 ~26~3~5 minecraft:log 1
setblock ~26~5~5 minecraft:log 1
setblock ~26~6~5 minecraft:deepslate_brick_wall 0
setblock ~26~7~5 minecraft:fence 5
setblock ~26~8~5 minecraft:deepslate_brick_wall 0
setblock ~26~9~5 minecraft:glowstone
setblock ~26~10~5 minecraft:deepslate_brick_slab 0
setblock ~27~0~5 minecraft:deepslate_brick_wall 0
setblock ~27~1~5 minecraft:fence 5
setblock ~27~2~5 minecraft:deepslate_brick_wall 0
fill ~27~3~5 ~29~3~5 minecraft:log 1
fill ~27~4~5 ~29~4~5 minecraft:glowstone
fill ~27~5~5 ~29~5~5 minecraft:leaves 0
setblock ~27~9~5 minecraft:jungle_trapdoor 0
setblock ~28~2~5 minecraft:dark_oak_stairs 2
setblock ~29~0~5 minecraft:deepslate_brick_wall 0
setblock ~29~1~5 minecraft:fence 5
setblock ~29~2~5 minecraft:deepslate_brick_wall 0
setblock ~29~9~5 minecraft:jungle_trapdoor 1
fill ~30~1~5 ~30~3~5 minecraft:log 1
setblock ~30~5~5 minecraft:log 1
setblock ~30~6~5 minecraft:deepslate_brick_wall 0
setblock ~30~7~5 minecraft:fence 5
setblock ~30~8~5 minecraft:deepslate_brick_wall 0
setblock ~30~9~5 minecraft:glowstone
setblock ~30~10~5 minecraft:deepslate_brick_slab 0
fill ~31~4~5 ~33~4~5 minecraft:log 1
setblock ~31~9~5 minecraft:jungle_trapdoor 0
setblock ~33~9~5 minecraft:jungle_trapdoor 1
fill ~34~1~5 ~34~3~5 minecraft:log 1
setblock ~34~5~5 minecraft:log 1
setblock ~34~6~5 minecraft:deepslate_brick_wall 0
setblock ~34~7~5 minecraft:fence 5
setblock ~34~8~5 minecraft:deepslate_brick_wall 0
setblock ~34~9~5 minecraft:glowstone
setblock ~34~10~5 minecraft:deepslate_brick_slab 0
fill ~35~0~5 ~37~0~5 minecraft:deepslate_brick_stairs 2
fill ~35~1~5 ~37~1~5 minecraft:fence 5
fill ~35~4~5 ~37~4~5 minecraft:log 1
fill ~35~5~5 ~37~5~5 minecraft:fence 5
setblock ~35~9~5 minecraft:jungle_trapdoor 0
setblock ~36~3~5 minecraft:lantern 1
setblock ~37~9~5 minecraft:jungle_trapdoor 1
fill ~38~0~5 ~38~5~5 minecraft:log 1
setblock ~38~6~5 minecraft:deepslate_brick_wall 0
setblock ~38~7~5 minecraft:fence 5
setblock ~38~8~5 minecraft:deepslate_brick_wall 0
setblock ~38~9~5 minecraft:glowstone
setblock ~38~10~5 minecraft:deepslate_brick_slab 0
fill ~39~0~5 ~41~0~5 minecraft:deepslate_brick_stairs 2
fill ~39~1~5 ~41~1~5 minecraft:fence 5
fill ~39~4~5 ~41~4~5 minecraft:log 1
fill ~39~5~5 ~41~5~5 minecraft:fence 5
setblock ~39~9~5 minecraft:jungle_trapdoor 0
setblock ~40~3~5 minecraft:lantern 1
setblock ~41~9~5 minecraft:jungle_trapdoor 1
fill ~42~0~5 ~42~5~5 minecraft:log 1
setblock ~42~6~5 minecraft:deepslate_brick_wall 0
setblock ~42~7~5 minecraft:fence 5
setblock ~42~8~5 minecraft:deepslate_brick_wall 0
setblock ~42~9~5 minecraft:glowstone
setblock ~42~10~5 minecraft:deepslate_brick_slab 0
fill ~43~0~5 ~45~0~5 minecraft:deepslate_brick_stairs 2
fill ~43~1~5 ~45~1~5 minecraft:fence 5
fill ~43~4~5 ~45~4~5 minecraft:log 1
fill ~43~5~5 ~45~5~5 minecraft:fence 5
setblock ~43~9~5 minecraft:jungle_trapdoor 0
setblock ~44~3~5 minecraft:lantern 1
setblock ~45~9~5 minecraft:jungle_trapdoor 1
setblock ~45~15~5 minecraft:deepslate_brick_stairs 7
setblock ~45~16~5 minecraft:deepslate_brick_stairs 2
fill ~46~0~5 ~46~15~5 minecraft:log 1
fill ~46~16~5 ~50~16~5 minecraft:dark_oak_stairs 2
fill ~47~0~5 ~49~0~5 minecraft:deepslate_brick_stairs 2
fill ~47~1~5 ~49~1~5 minecraft:fence 5
fill ~47~4~5 ~49~4~5 minecraft:log 1
fill ~47~5~5 ~49~5~5 minecraft:fence 5
fill ~47~9~5 ~49~9~5 minecraft:log 1
fill ~47~10~5 ~49~10~5 minecraft:fence 5
fill ~47~14~5 ~49~14~5 minecraft:jungle_fence_gate 0
fill ~47~15~5 ~49~15~5 minecraft:log 1
setblock ~48~3~5 minecraft:lantern 1
fill ~50~0~5 ~50~15~5 minecraft:log 1
setblock ~51~0~5 minecraft:jungle_stairs 5
setblock ~51~1~5 minecraft:deepslate_brick_wall 0
setblock ~51~2~5 minecraft:fence 5
setblock ~51~3~5 minecraft:deepslate_brick_wall 0
setblock ~51~4~5 minecraft:jungle_stairs 1
setblock ~51~9~5 minecraft:jungle_trapdoor 0
setblock ~51~15~5 minecraft:deepslate_brick_stairs 7
setblock ~51~16~5 minecraft:deepslate_brick_stairs 2
fill ~5~9~6 ~5~9~8 minecraft:spruce_wall_sign 4
fill ~5~15~6 ~5~15~8 minecraft:dark_oak_stairs 4
setblock ~5~16~6 minecraft:deepslate_brick_stairs 7
setblock ~5~17~6 minecraft:deepslate_brick_stairs 2
fill ~6~0~6 ~6~0~8 minecraft:deepslate_brick_stairs 0
fill ~6~1~6 ~6~1~8 minecraft:fence 5
fill ~6~4~6 ~6~4~8 minecraft:log 1
fill ~6~5~6 ~6~5~8 minecraft:fence 5
fill ~6~9~6 ~6~9~8 minecraft:log 1
fill ~6~10~6 ~6~10~8 minecraft:fence 5
fill ~6~14~6 ~6~14~8 minecraft:jungle_fence_gate 1
fill ~6~15~6 ~6~15~8 minecraft:log 1
setblock ~6~16~6 minecraft:log 1
fill ~6~17~6 ~10~17~6 minecraft:dark_oak_stairs 2
fill ~7~4~6 ~21~4~8 minecraft:planks 1
fill ~7~9~6 ~9~9~8 minecraft:planks 1
fill ~8~0~6 ~16~2~6 minecraft:reeds 0
setblock ~8~8~6 minecraft:jungle_trapdoor 3
fill ~10~9~6 ~10~9~8 minecraft:log 1
fill ~10~10~6 ~10~10~8 minecraft:fence 5
fill ~10~14~6 ~10~14~8 minecraft:jungle_fence_gate 1
fill ~10~15~6 ~10~15~8 minecraft:log 1
setblock ~10~16~6 minecraft:log 1
fill ~11~9~6 ~11~9~8 minecraft:spruce_wall_sign 5
fill ~11~15~6 ~11~15~8 minecraft:dark_oak_stairs 5
setblock ~11~16~6 minecraft:deepslate_brick_stairs 7
setblock ~11~17~6 minecraft:deepslate_brick_stairs 2
setblock ~14~9~6 minecraft:jungle_trapdoor 2
setblock ~18~0~6 minecraft:fence 5
setblock ~18~9~6 minecraft:jungle_trapdoor 2
setblock ~19~0~6 minecraft:barrel 3
setblock ~20~0~6 minecraft:chest 3
setblock ~21~0~6 minecraft:barrel 3
fill ~22~0~6 ~23~3~6 minecraft:planks 1
fill ~22~4~6 ~22~4~8 minecraft:log 1
setblock ~22~9~6 minecraft:jungle_trapdoor 2
fill ~23~4~6 ~33~4~8 minecraft:planks 1
setblock ~24~0~6 minecraft:dark_oak_door 1
fill ~24~2~6 ~26~3~6 minecraft:planks 1
fill ~25~0~6 ~26~1~6 minecraft:planks 1
fill ~26~5~6 ~27~5~6 minecraft:smoker 3
setblock ~26~9~6 minecraft:jungle_trapdoor 2
fill ~27~0~6 ~27~3~6 minecraft:stripped_spruce_log 0
setblock ~28~0~6 minecraft:dark_oak_door 3
setblock ~28~2~6 minecraft:stripped_spruce_log 1
setblock ~28~3~6 minecraft:lantern 0
setblock ~28~5~6 minecraft:crafting_table
fill ~29~0~6 ~29~3~6 minecraft:stripped_spruce_log 0
fill ~29~5~6 ~30~5~6 minecraft:blast_furnace 3
fill ~30~0~6 ~31~3~6 minecraft:planks 1
setblock ~30~9~6 minecraft:jungle_trapdoor 2
setblock ~32~0~6 minecraft:dark_oak_door 1
fill ~32~2~6 ~34~3~6 minecraft:planks 1
fill ~33~0~6 ~34~1~6 minecraft:planks 1
fill ~34~4~6 ~34~4~8 minecraft:log 1
setblock ~34~9~6 minecraft:jungle_trapdoor 2
setblock ~35~0~6 minecraft:barrel 3
fill ~35~4~6 ~49~4~8 minecraft:planks 1
setblock ~36~0~6 minecraft:chest 3
setblock ~37~0~6 minecraft:barrel 3
setblock ~38~0~6 minecraft:fence 5
setblock ~38~9~6 minecraft:jungle_trapdoor 2
fill ~40~0~6 ~41~0~6 minecraft:reeds 0
fill ~42~0~6 ~43~0~6 minecraft:reeds 1
setblock ~42~9~6 minecraft:jungle_trapdoor 2
setblock ~44~0~6 minecraft:reeds 0
setblock ~45~0~6 minecraft:reeds 2
fill ~45~9~6 ~45~9~8 minecraft:spruce_wall_sign 4
fill ~45~15~6 ~45~15~8 minecraft:dark_oak_stairs 4
setblock ~45~16~6 minecraft:deepslate_brick_stairs 7
setblock ~45~17~6 minecraft:deepslate_brick_stairs 2
setblock ~46~0~6 minecraft:reeds 3
fill ~46~9~6 ~46~9~8 minecraft:log 1
fill ~46~10~6 ~46~10~8 minecraft:fence 5
fill ~46~14~6 ~46~14~8 minecraft:jungle_fence_gate 3
fill ~46~15~6 ~46~15~8 minecraft:log 1
setblock ~46~16~6 minecraft:log 1
fill ~46~17~6 ~50~17~6 minecraft:dark_oak_stairs 2
setblock ~47~0~6 minecraft:reeds 0
setblock ~47~1~6 minecraft:reeds 1
fill ~47~9~6 ~49~9~8 minecraft:planks 1
setblock ~48~0~6 minecraft:reeds 2
setblock ~48~8~6 minecraft:jungle_trapdoor 3
fill ~50~0~6 ~50~0~8 minecraft:deepslate_brick_stairs 1
fill ~50~1~6 ~50~1~8 minecraft:fence 5
fill ~50~4~6 ~50~4~8 minecraft:log 1
fill ~50~5~6 ~50~5~8 minecraft:fence 5
fill ~50~9~6 ~50~9~8 minecraft:log 1
fill ~50~10~6 ~50~10~8 minecraft:fence 5
fill ~50~14~6 ~50~14~8 minecraft:jungle_fence_gate 1
fill ~50~15~6 ~50~15~8 minecraft:log 1
setblock ~50~16~6 minecraft:log 1
fill ~51~9~6 ~51~9~8 minecraft:spruce_wall_sign 5
fill ~51~15~6 ~51~15~8 minecraft:dark_oak_stairs 5
setblock ~51~16~6 minecraft:deepslate_brick_stairs 7
setblock ~51~17~6 minecraft:deepslate_brick_stairs 2
setblock ~4~17~7 minecraft:lantern 1
setblock ~4~18~7 minecraft:deepslate_brick_slab 0
setblock ~5~17~7 minecraft:deepslate_brick_slab 0
setblock ~5~18~7 minecraft:deepslate_brick_double_slab 0
setblock ~6~3~7 minecraft:lantern 1
setblock ~6~16~7 minecraft:fence 3
setblock ~6~17~7 minecraft:deepslate_brick_wall
setblock ~6~18~7 minecraft:deepslate_brick_slab 0
fill ~7~0~7 ~7~2~15 minecraft:reeds 0
setblock ~7~8~7 minecraft:jungle_trapdoor 1
setblock ~7~18~7 minecraft:deepslate_brick_double_slab 0
setblock ~8~7~7 minecraft:jungle_trapdoor 0
setblock ~8~8~7 minecraft:glowstone
setblock ~8~15~7 minecraft:lantern 1
setblock ~8~16~7 minecraft:deepslate_brick_wall 0
setblock ~8~17~7 minecraft:log 1
setblock ~8~18~7 minecraft:deepslate_brick_slab 0
setblock ~9~8~7 minecraft:jungle_trapdoor 0
setblock ~9~18~7 minecraft:deepslate_brick_double_slab 0
setblock ~10~16~7 minecraft:fence 3
setblock ~10~17~7 minecraft:deepslate_brick_wall
setblock ~10~18~7 minecraft:deepslate_brick_slab 0
setblock ~11~17~7 minecraft:deepslate_brick_slab 0
setblock ~11~18~7 minecraft:deepslate_brick_double_slab 0
setblock ~12~17~7 minecraft:lantern 1
setblock ~12~18~7 minecraft:deepslate_brick_slab 0
setblock ~18~0~7 minecraft:dark_oak_fence_gate 1
setblock ~22~0~7 minecraft:dark_oak_door 2
fill ~22~2~7 ~22~3~8 minecraft:planks 1
fill ~23~2~7 ~25~2~7 minecraft:spruce_trapdoor 2
fill ~23~3~7 ~24~3~7 minecraft:flower_pot
setblock ~26~0~7 minecraft:flower_pot
fill ~26~1~7 ~26~2~7 minecraft:leaves 0
fill ~27~0~7 ~27~1~7 minecraft:fence 5
fill ~27~2~7 ~29~2~7 minecraft:dark_oak_stairs 3
setblock ~28~3~7 minecraft:jungle_trapdoor 2
fill ~29~0~7 ~29~1~7 minecraft:fence 5
setblock ~30~0~7 minecraft:flower_pot
fill ~30~1~7 ~30~2~7 minecraft:leaves 0
fill ~31~2~7 ~33~2~7 minecraft:spruce_trapdoor 2
fill ~32~3~7 ~33~3~7 minecraft:flower_pot
setblock ~34~0~7 minecraft:dark_oak_door 0
fill ~34~2~7 ~34~3~8 minecraft:planks 1
setblock ~38~0~7 minecraft:dark_oak_fence_gate 3
setblock ~44~17~7 minecraft:lantern 1
setblock ~44~18~7 minecraft:deepslate_brick_slab 0
setblock ~45~17~7 minecraft:deepslate_brick_slab 0
setblock ~45~18~7 minecraft:deepslate_brick_double_slab 0
setblock ~46~16~7 minecraft:fence 3
setblock ~46~17~7 minecraft:deepslate_brick_wall
setblock ~46~18~7 minecraft:deepslate_brick_slab 0
setblock ~47~8~7 minecraft:jungle_trapdoor 1
setblock ~47~18~7 minecraft:deepslate_brick_double_slab 0
setblock ~48~7~7 minecraft:jungle_trapdoor 1
setblock ~48~8~7 minecraft:glowstone
setblock ~48~15~7 minecraft:lantern 1
setblock ~48~16~7 minecraft:deepslate_brick_wall 0
setblock ~48~17~7 minecraft:log 1
setblock ~48~18~7 minecraft:deepslate_brick_slab 0
setblock ~49~0~7 minecraft:reeds 0
setblock ~49~8~7 minecraft:jungle_trapdoor 0
setblock ~49~18~7 minecraft:deepslate_brick_double_slab 0
setblock ~50~3~7 minecraft:lantern 1
setblock ~50~16~7 minecraft:fence 3
setblock ~50~17~7 minecraft:deepslate_brick_wall
setblock ~50~18~7 minecraft:deepslate_brick_slab 0
setblock ~51~17~7 minecraft:deepslate_brick_slab 0
setblock ~51~18~7 minecraft:deepslate_brick_double_slab 0
setblock ~52~17~7 minecraft:lantern 1
setblock ~52~18~7 minecraft:deepslate_brick_slab 0
setblock ~5~16~8 minecraft:deepslate_brick_stairs 6
setblock ~5~17~8 minecraft:deepslate_brick_stairs 3
setblock ~6~16~8 minecraft:log 1
fill ~6~17~8 ~10~17~8 minecraft:dark_oak_stairs 3
setblock ~8~8~8 minecraft:jungle_trapdoor 2
fill ~9~0~8 ~16~2~8 minecraft:reeds 0
setblock ~10~16~8 minecraft:log 1
setblock ~11~16~8 minecraft:deepslate_brick_stairs 6
setblock ~11~17~8 minecraft:deepslate_brick_stairs 3
setblock ~18~0~8 minecraft:fence 5
fill ~22~0~8 ~22~1~8 minecraft:planks 1
fill ~34~0~8 ~34~1~8 minecraft:planks 1
setblock ~38~0~8 minecraft:fence 5
setblock ~40~0~8 minecraft:reeds 1
fill ~41~0~8 ~42~0~8 minecraft:reeds 0
setblock ~43~0~8 minecraft:reeds 1
setblock ~44~0~8 minecraft:reeds 0
setblock ~45~0~8 minecraft:reeds 4
setblock ~45~16~8 minecraft:deepslate_brick_stairs 6
setblock ~45~17~8 minecraft:deepslate_brick_stairs 3
setblock ~46~0~8 minecraft:reeds 2
setblock ~46~16~8 minecraft:log 1
fill ~46~17~8 ~50~17~8 minecraft:dark_oak_stairs 3
setblock ~47~0~8 minecraft:reeds 3
setblock ~48~8~8 minecraft:jungle_trapdoor 2
setblock ~49~0~8 minecraft:reeds 3
setblock ~50~16~8 minecraft:log 1
setblock ~51~16~8 minecraft:deepslate_brick_stairs 6
setblock ~51~17~8 minecraft:deepslate_brick_stairs 3
setblock ~5~0~9 minecraft:jungle_stairs 4
setblock ~5~1~9 minecraft:deepslate_brick_wall 0
setblock ~5~2~9 minecraft:fence 5
setblock ~5~3~9 minecraft:deepslate_brick_wall 0
setblock ~5~4~9 minecraft:jungle_stairs 0
setblock ~5~9~9 minecraft:jungle_trapdoor 1
setblock ~5~15~9 minecraft:deepslate_brick_stairs 6
setblock ~5~16~9 minecraft:deepslate_brick_stairs 3
fill ~6~0~9 ~6~15~9 minecraft:log 1
fill ~6~16~9 ~10~16~9 minecraft:dark_oak_stairs 3
fill ~7~4~9 ~9~4~20 minecraft:planks 1
fill ~7~9~9 ~9~9~9 minecraft:log 1
fill ~7~10~9 ~9~10~9 minecraft:fence 5
fill ~7~14~9 ~9~14~9 minecraft:jungle_fence_gate 0
fill ~7~15~9 ~9~15~9 minecraft:log 1
fill ~9~0~9 ~9~2~15 minecraft:reeds 0
fill ~10~0~9 ~10~15~9 minecraft:log 1
fill ~11~0~9 ~13~0~9 minecraft:fence 5
fill ~11~4~9 ~13~4~9 minecraft:log 1
fill ~11~5~9 ~13~5~9 minecraft:fence 5
setblock ~11~9~9 minecraft:jungle_trapdoor 0
setblock ~11~13~9 minecraft:spruce_fence_gate 2
fill ~11~14~9 ~13~14~9 minecraft:dark_oak_trapdoor 0
setblock ~11~15~9 minecraft:deepslate_brick_stairs 6
setblock ~11~16~9 minecraft:deepslate_brick_stairs 3
setblock ~12~3~9 minecraft:lantern 1
setblock ~12~13~9 minecraft:grindstone 3
setblock ~13~13~9 minecraft:spruce_fence_gate 2
fill ~14~0~9 ~14~5~9 minecraft:log 1
setblock ~14~6~9 minecraft:deepslate_brick_wall 0
fill ~14~7~9 ~14~11~9 minecraft:fence 5
setblock ~14~12~9 minecraft:deepslate_brick_wall 0
setblock ~14~13~9 minecraft:log 1
setblock ~14~14~9 minecraft:deepslate_brick_slab 0
fill ~15~0~9 ~17~0~9 minecraft:fence 5
fill ~15~4~9 ~17~4~9 minecraft:log 1
fill ~15~5~9 ~17~5~9 minecraft:fence 5
setblock ~15~13~9 minecraft:spruce_fence_gate 2
fill ~15~14~9 ~17~14~9 minecraft:dark_oak_trapdoor 0
setblock ~16~3~9 minecraft:lantern 1
setblock ~16~13~9 minecraft:grindstone 3
setblock ~17~13~9 minecraft:spruce_fence_gate 2
fill ~18~0~9 ~18~5~9 minecraft:log 1
setblock ~18~6~9 minecraft:deepslate_brick_wall 0
fill ~18~7~9 ~18~11~9 minecraft:fence 5
setblock ~18~12~9 minecraft:deepslate_brick_wall 0
setblock ~18~13~9 minecraft:log 1
setblock ~18~14~9 minecraft:deepslate_brick_slab 0
setblock ~19~0~9 minecraft:fence 5
fill ~19~4~9 ~21~4~9 minecraft:log 1
fill ~19~5~9 ~21~5~9 minecraft:fence 5
setblock ~19~13~9 minecraft:spruce_fence_gate 2
fill ~19~14~9 ~21~14~9 minecraft:dark_oak_trapdoor 0
setblock ~20~0~9 minecraft:dark_oak_fence_gate 0
setblock ~20~3~9 minecraft:lantern 1
setblock ~20~13~9 minecraft:grindstone 3
setblock ~21~0~9 minecraft:fence 5
setblock ~21~13~9 minecraft:spruce_fence_gate 2
fill ~22~0~9 ~22~6~9 minecraft:log 1
setblock ~22~7~9 minecraft:deepslate_brick_wall 0
fill ~22~8~9 ~22~11~9 minecraft:fence 5
setblock ~22~12~9 minecraft:deepslate_brick_wall 0
setblock ~22~13~9 minecraft:log 1
setblock ~22~14~9 minecraft:deepslate_brick_slab 0
fill ~23~0~9 ~23~0~10 minecraft:chest 5
fill ~23~4~9 ~33~4~9 minecraft:log 1
setblock ~26~3~9 minecraft:lantern 1
setblock ~30~3~9 minecraft:lantern 1
fill ~33~0~9 ~33~0~10 minecraft:chest 4
fill ~34~0~9 ~34~6~9 minecraft:log 1
setblock ~34~7~9 minecraft:deepslate_brick_wall 0
fill ~34~8~9 ~34~11~9 minecraft:fence 5
setblock ~34~12~9 minecraft:deepslate_brick_wall 0
setblock ~34~13~9 minecraft:log 1
setblock ~34~14~9 minecraft:deepslate_brick_slab 0
setblock ~35~0~9 minecraft:fence 5
fill ~35~4~9 ~37~4~9 minecraft:log 1
fill ~35~5~9 ~37~5~9 minecraft:fence 5
setblock ~35~13~9 minecraft:spruce_fence_gate 0
fill ~35~14~9 ~37~14~9 minecraft:dark_oak_trapdoor 0
setblock ~36~0~9 minecraft:dark_oak_fence_gate 0
setblock ~36~3~9 minecraft:lantern 1
setblock ~36~13~9 minecraft:grindstone 1
setblock ~37~0~9 minecraft:fence 5
setblock ~37~13~9 minecraft:spruce_fence_gate 0
fill ~38~0~9 ~38~5~9 minecraft:log 1
setblock ~38~6~9 minecraft:deepslate_brick_wall 0
fill ~38~7~9 ~38~11~9 minecraft:fence 5
setblock ~38~12~9 minecraft:deepslate_brick_wall 0
setblock ~38~13~9 minecraft:log 1
setblock ~38~14~9 minecraft:deepslate_brick_slab 0
fill ~39~0~9 ~41~0~9 minecraft:fence 5
fill ~39~4~9 ~41~4~9 minecraft:log 1
fill ~39~5~9 ~41~5~9 minecraft:fence 5
setblock ~39~13~9 minecraft:spruce_fence_gate 0
fill ~39~14~9 ~41~14~9 minecraft:dark_oak_trapdoor 0
setblock ~40~3~9 minecraft:lantern 1
setblock ~40~13~9 minecraft:grindstone 1
setblock ~41~13~9 minecraft:spruce_fence_gate 0
fill ~42~0~9 ~42~5~9 minecraft:log 1
setblock ~42~6~9 minecraft:deepslate_brick_wall 0
fill ~42~7~9 ~42~11~9 minecraft:fence 5
setblock ~42~12~9 minecraft:deepslate_brick_wall 0
setblock ~42~13~9 minecraft:log 1
setblock ~42~14~9 minecraft:deepslate_brick_slab 0
fill ~43~0~9 ~45~0~9 minecraft:fence 5
fill ~43~4~9 ~45~4~9 minecraft:log 1
fill ~43~5~9 ~45~5~9 minecraft:fence 5
setblock ~43~13~9 minecraft:spruce_fence_gate 0
fill ~43~14~9 ~45~14~9 minecraft:dark_oak_trapdoor 1
setblock ~44~3~9 minecraft:lantern 1
setblock ~44~13~9 minecraft:grindstone 1
setblock ~45~9~9 minecraft:jungle_trapdoor 1
setblock ~45~13~9 minecraft:spruce_fence_gate 0
setblock ~45~15~9 minecraft:deepslate_brick_stairs 6
setblock ~45~16~9 minecraft:deepslate_brick_stairs 3
fill ~46~0~9 ~46~15~9 minecraft:log 1
fill ~46~16~9 ~50~16~9 minecraft:dark_oak_stairs 3
setblock ~47~0~9 minecraft:reeds 2
fill ~47~4~9 ~49~4~20 minecraft:planks 1
fill ~47~9~9 ~49~9~9 minecraft:log 1
fill ~47~10~9 ~49~10~9 minecraft:fence 5
fill ~47~14~9 ~49~14~9 minecraft:jungle_fence_gate 2
fill ~47~15~9 ~49~15~9 minecraft:log 1
fill ~49~0~9 ~49~0~10 minecraft:reeds 2
fill ~50~0~9 ~50~15~9 minecraft:log 1
setblock ~51~0~9 minecraft:jungle_stairs 5
setblock ~51~1~9 minecraft:deepslate_brick_wall 0
setblock ~51~2~9 minecraft:fence 5
setblock ~51~3~9 minecraft:deepslate_brick_wall 0
setblock ~51~4~9 minecraft:jungle_stairs 1
setblock ~51~9~9 minecraft:jungle_trapdoor 0
setblock ~51~15~9 minecraft:deepslate_brick_stairs 6
setblock ~51~16~9 minecraft:deepslate_brick_stairs 3
fill ~5~15~10 ~11~15~10 minecraft:deepslate_brick_stairs 3
fill ~6~0~10 ~6~0~12 minecraft:deepslate_brick_stairs 0
fill ~6~1~10 ~6~1~12 minecraft:fence 5
fill ~6~4~10 ~6~4~12 minecraft:log 1
fill ~6~5~10 ~6~5~12 minecraft:fence 5
setblock ~6~9~10 minecraft:jungle_trapdoor 2
fill ~7~9~10 ~9~9~10 minecraft:spruce_wall_sign 3
fill ~10~0~10 ~10~0~12 minecraft:fence 5
fill ~10~4~10 ~10~4~12 minecraft:log 1
fill ~10~5~10 ~10~5~12 minecraft:fence 5
setblock ~10~9~10 minecraft:jungle_trapdoor 2
setblock ~10~13~10 minecraft:spruce_fence_gate 1
fill ~10~14~10 ~10~14~12 minecraft:dark_oak_trapdoor 3
fill ~11~0~10 ~11~0~12 minecraft:spruce_stairs 1
fill ~12~0~10 ~13~0~10 minecraft:spruce_stairs 3
setblock ~15~0~10 minecraft:barrel 1
setblock ~16~0~10 minecraft:chest 3
setblock ~17~0~10 minecraft:barrel 1
fill ~21~0~10 ~21~0~12 minecraft:dark_oak_stairs 4
fill ~21~3~10 ~21~3~12 minecraft:dark_oak_stairs 0
fill ~22~0~10 ~22~0~12 minecraft:planks 1
fill ~22~1~10 ~22~2~12 minecraft:glass_pane
fill ~22~3~10 ~22~3~12 minecraft:planks 1
fill ~22~4~10 ~22~4~12 minecraft:log 1
fill ~22~5~10 ~22~5~12 minecraft:deepslate_brick_stairs 0
fill ~22~6~10 ~22~6~12 minecraft:fence 1
setblock ~22~13~10 minecraft:spruce_fence_gate 3
fill ~22~14~10 ~22~14~12 minecraft:dark_oak_trapdoor 2
fill ~23~4~10 ~33~4~20 minecraft:planks 1
fill ~23~5~10 ~23~5~12 minecraft:barrel 5
setblock ~23~6~10 minecraft:barrel 5
fill ~24~5~10 ~24~5~12 minecraft:barrel 1
setblock ~24~6~10 minecraft:lantern 0
fill ~32~5~10 ~32~5~11 minecraft:barrel 4
setblock ~33~5~10 minecraft:barrel 1
fill ~34~0~10 ~34~0~12 minecraft:planks 1
fill ~34~1~10 ~34~2~12 minecraft:glass_pane
fill ~34~3~10 ~34~3~12 minecraft:planks 1
fill ~34~4~10 ~34~4~12 minecraft:log 1
fill ~34~5~10 ~34~5~12 minecraft:deepslate_brick_stairs 1
fill ~34~6~10 ~34~6~12 minecraft:fence 1
setblock ~34~13~10 minecraft:spruce_fence_gate 1
fill ~34~14~10 ~34~14~12 minecraft:dark_oak_trapdoor 2
fill ~35~0~10 ~35~0~12 minecraft:dark_oak_stairs 5
fill ~35~3~10 ~35~3~12 minecraft:dark_oak_stairs 1
setblock ~39~0~10 minecraft:barrel 1
setblock ~40~0~10 minecraft:chest 3
setblock ~41~0~10 minecraft:barrel 1
fill ~43~0~10 ~45~0~10 minecraft:spruce_stairs 3
setblock ~45~14~10 minecraft:lantern 1
fill ~45~15~10 ~51~15~10 minecraft:deepslate_brick_stairs 3
fill ~46~0~10 ~46~0~12 minecraft:fence 5
fill ~46~4~10 ~46~4~12 minecraft:log 1
fill ~46~5~10 ~46~5~12 minecraft:fence 5
setblock ~46~9~10 minecraft:jungle_trapdoor 2
setblock ~46~13~10 minecraft:spruce_fence_gate 1
fill ~46~14~10 ~46~14~12 minecraft:dark_oak_trapdoor 2
setblock ~47~0~10 minecraft:reeds 0
fill ~47~9~10 ~49~9~10 minecraft:spruce_wall_sign 3
fill ~50~0~10 ~50~0~12 minecraft:deepslate_brick_stairs 1
fill ~50~1~10 ~50~1~12 minecraft:fence 5
fill ~50~4~10 ~50~4~12 minecraft:log 1
fill ~50~5~10 ~50~5~12 minecraft:fence 5
setblock ~50~9~10 minecraft:jungle_trapdoor 2
setblock ~51~14~10 minecraft:lantern 1
setblock ~6~3~11 minecraft:lantern 1
setblock ~10~3~11 minecraft:lantern 1
setblock ~10~13~11 minecraft:grindstone 2
fill ~12~0~11 ~13~0~11 minecraft:fence 5
fill ~12~1~11 ~13~1~11 minecraft:dark_oak_pressure_plate 0
setblock ~21~2~11 minecraft:lantern 1
setblock ~22~13~11 minecraft:grindstone 0
setblock ~23~0~11 minecraft:smoker 5
setblock ~23~2~11 minecraft:lantern 1
fill ~23~3~11 ~23~3~12 minecraft:barrel 5
setblock ~23~6~11 minecraft:barrel 1
setblock ~23~7~11 minecraft:barrel 5
setblock ~33~0~11 minecraft:smoker 4
setblock ~33~2~11 minecraft:lantern 1
fill ~33~3~11 ~33~3~12 minecraft:barrel 4
fill ~33~5~11 ~33~5~12 minecraft:barrel 4
fill ~33~6~11 ~33~6~12 minecraft:barrel 1
setblock ~33~7~11 minecraft:lantern 0
setblock ~34~13~11 minecraft:grindstone 2
setblock ~35~2~11 minecraft:lantern 1
fill ~43~0~11 ~44~0~11 minecraft:fence 5
fill ~43~1~11 ~44~1~11 minecraft:dark_oak_pressure_plate 0
fill ~45~0~11 ~45~0~12 minecraft:spruce_stairs 0
setblock ~46~3~11 minecraft:lantern 1
setblock ~46~13~11 minecraft:grindstone 0
setblock ~47~0~11 minecraft:reeds 1
setblock ~49~0~11 minecraft:reeds 0
setblock ~50~3~11 minecraft:lantern 1
setblock ~6~9~12 minecraft:jungle_trapdoor 3
setblock ~10~13~12 minecraft:spruce_fence_gate 1
setblock ~12~0~12 minecraft:fence 5
setblock ~12~1~12 minecraft:dark_oak_pressure_plate 0
setblock ~22~13~12 minecraft:spruce_fence_gate 3
setblock ~23~0~12 minecraft:blast_furnace 5
fill ~23~6~12 ~24~6~12 minecraft:barrel 5
fill ~24~0~12 ~26~0~12 minecraft:spruce_trapdoor 3
fill ~30~0~12 ~32~0~12 minecraft:spruce_trapdoor 3
fill ~32~5~12 ~32~6~12 minecraft:barrel 1
setblock ~33~0~12 minecraft:blast_furnace 4
setblock ~33~7~12 minecraft:barrel 1
setblock ~34~13~12 minecraft:spruce_fence_gate 1
setblock ~44~0~12 minecraft:fence 5
setblock ~44~1~12 minecraft:dark_oak_pressure_plate 0
setblock ~46~13~12 minecraft:spruce_fence_gate 1
setblock ~47~0~12 minecraft:reeds 0
setblock ~47~1~12 minecraft:reeds 2
setblock ~49~0~12 minecraft:reeds 1
setblock ~50~9~12 minecraft:jungle_trapdoor 3
setblock ~5~0~13 minecraft:jungle_stairs 4
setblock ~5~1~13 minecraft:deepslate_brick_wall 0
setblock ~5~2~13 minecraft:fence 5
setblock ~5~3~13 minecraft:deepslate_brick_wall 0
setblock ~5~4~13 minecraft:jungle_stairs 0
setblock ~5~9~13 minecraft:jungle_trapdoor 1
fill ~6~0~13 ~6~5~13 minecraft:log 1
setblock ~6~6~13 minecraft:deepslate_brick_wall 0
setblock ~6~7~13 minecraft:fence 5
setblock ~6~8~13 minecraft:deepslate_brick_wall 0
setblock ~6~9~13 minecraft:glowstone
setblock ~6~10~13 minecraft:deepslate_brick_slab 0
setblock ~7~9~13 minecraft:jungle_trapdoor 0
fill ~10~0~13 ~10~5~13 minecraft:log 1
setblock ~10~6~13 minecraft:deepslate_brick_wall 0
fill ~10~7~13 ~10~11~13 minecraft:fence 5
setblock ~10~12~13 minecraft:deepslate_brick_wall 0
setblock ~10~13~13 minecraft:log 1
setblock ~10~14~13 minecraft:deepslate_brick_slab 0
fill ~14~0~13 ~14~0~17 minecraft:deepslate_brick_stairs 0
fill ~15~0~13 ~17~0~13 minecraft:deepslate_brick_stairs 2
fill ~18~0~13 ~18~0~16 minecraft:deepslate_brick_stairs 1
setblock ~21~0~13 minecraft:deepslate_brick_wall 0
fill ~21~1~13 ~21~2~13 minecraft:fence 5
setblock ~21~3~13 minecraft:deepslate_brick_wall 0
setblock ~21~4~13 minecraft:deepslate_brick_stairs 0
fill ~22~0~13 ~22~7~13 minecraft:log 1
setblock ~22~8~13 minecraft:deepslate_brick_wall 0
fill ~22~9~13 ~22~11~13 minecraft:fence 5
setblock ~22~12~13 minecraft:deepslate_brick_wall 0
setblock ~22~13~13 minecraft:log 1
setblock ~22~14~13 minecraft:deepslate_brick_slab 0
setblock ~23~0~13 minecraft:planks 1
setblock ~23~1~13 minecraft:spruce_trapdoor 3
fill ~23~5~13 ~24~5~13 minecraft:deepslate_brick_stairs 2
fill ~24~0~13 ~25~0~13 minecraft:glowstone
fill ~24~1~13 ~25~1~13 minecraft:carpet 15
setblock ~26~0~13 minecraft:planks 1
setblock ~26~1~13 minecraft:spruce_trapdoor 3
setblock ~26~3~13 minecraft:lantern 1
fill ~27~0~13 ~27~0~14 minecraft:spruce_trapdoor 0
fill ~29~0~13 ~29~0~16 minecraft:spruce_trapdoor 1
setblock ~30~0~13 minecraft:planks 1
setblock ~30~1~13 minecraft:spruce_trapdoor 3
setblock ~30~3~13 minecraft:lantern 1
fill ~31~0~13 ~32~0~13 minecraft:glowstone
fill ~31~1~13 ~32~1~13 minecraft:carpet 15
fill ~32~5~13 ~33~5~13 minecraft:deepslate_brick_stairs 2
setblock ~33~0~13 minecraft:planks 1
setblock ~33~1~13 minecraft:spruce_trapdoor 3
fill ~34~0~13 ~34~7~13 minecraft:log 1
setblock ~34~8~13 minecraft:deepslate_brick_wall 0
fill ~34~9~13 ~34~11~13 minecraft:fence 5
setblock ~34~12~13 minecraft:deepslate_brick_wall 0
setblock ~34~13~13 minecraft:log 1
setblock ~34~14~13 minecraft:deepslate_brick_slab 0
setblock ~35~0~13 minecraft:deepslate_brick_wall 0
fill ~35~1~13 ~35~2~13 minecraft:fence 5
setblock ~35~3~13 minecraft:deepslate_brick_wall 0
setblock ~35~4~13 minecraft:deepslate_brick_stairs 1
fill ~38~0~13 ~38~0~17 minecraft:deepslate_brick_stairs 0
fill ~39~0~13 ~41~0~13 minecraft:deepslate_brick_stairs 2
fill ~42~0~13 ~42~0~17 minecraft:deepslate_brick_stairs 1
fill ~46~0~13 ~46~5~13 minecraft:log 1
setblock ~46~6~13 minecraft:deepslate_brick_wall 0
fill ~46~7~13 ~46~11~13 minecraft:fence 5
setblock ~46~12~13 minecraft:deepslate_brick_wall 0
setblock ~46~13~13 minecraft:log 1
setblock ~46~14~13 minecraft:deepslate_brick_slab 0
setblock ~47~0~13 minecraft:reeds 1
setblock ~49~0~13 minecraft:reeds 0
setblock ~49~9~13 minecraft:jungle_trapdoor 1
fill ~50~0~13 ~50~5~13 minecraft:log 1
setblock ~50~6~13 minecraft:deepslate_brick_wall 0
setblock ~50~7~13 minecraft:fence 5
setblock ~50~8~13 minecraft:deepslate_brick_wall 0
setblock ~50~9~13 minecraft:glowstone
setblock ~50~10~13 minecraft:deepslate_brick_slab 0
setblock ~51~0~13 minecraft:jungle_stairs 5
setblock ~51~1~13 minecraft:deepslate_brick_wall 0
setblock ~51~2~13 minecraft:fence 5
setblock ~51~3~13 minecraft:deepslate_brick_wall 0
setblock ~51~4~13 minecraft:jungle_stairs 1
setblock ~51~9~13 minecraft:jungle_trapdoor 0
fill ~6~0~14 ~6~0~16 minecraft:deepslate_brick_stairs 0
fill ~6~1~14 ~6~1~16 minecraft:fence 5
fill ~6~4~14 ~6~4~16 minecraft:log 1
fill ~6~5~14 ~6~5~16 minecraft:fence 5
setblock ~6~9~14 minecraft:jungle_trapdoor 2
fill ~10~0~14 ~10~0~16 minecraft:fence 5
fill ~10~4~14 ~10~4~16 minecraft:log 1
fill ~10~5~14 ~10~5~16 minecraft:fence 5
setblock ~10~13~14 minecraft:spruce_fence_gate 1
fill ~10~14~14 ~10~14~16 minecraft:dark_oak_trapdoor 3
setblock ~11~0~14 minecraft:barrel 1
fill ~15~0~14 ~17~0~14 minecraft:grass
fill ~15~1~14 ~17~9~14 minecraft:bamboo 2
fill ~15~10~14 ~15~12~16 minecraft:bamboo 2
fill ~15~13~14 ~15~13~16 minecraft:bamboo 2
fill ~15~14~14 ~15~15~16 minecraft:bamboo 2
fill ~16~10~14 ~17~10~14 minecraft:bamboo 2
fill ~16~11~14 ~17~12~14 minecraft:bamboo 2
fill ~21~0~14 ~21~0~16 minecraft:dark_oak_stairs 4
fill ~21~3~14 ~21~3~16 minecraft:dark_oak_stairs 0
fill ~21~5~14 ~21~5~16 minecraft:trapdoor 1
fill ~22~0~14 ~22~0~16 minecraft:planks 1
fill ~22~1~14 ~22~2~16 minecraft:glass_pane
fill ~22~3~14 ~22~3~16 minecraft:planks 1
fill ~22~4~14 ~22~4~16 minecraft:log 1
fill ~22~5~14 ~22~5~16 minecraft:glowstone
fill ~22~6~14 ~22~6~16 minecraft:deepslate_brick_stairs 0
fill ~22~7~14 ~22~7~16 minecraft:fence 1
setblock ~22~13~14 minecraft:spruce_fence_gate 3
fill ~22~14~14 ~22~14~16 minecraft:dark_oak_trapdoor 2
setblock ~23~0~14 minecraft:glowstone
setblock ~23~1~14 minecraft:carpet 15
fill ~23~5~14 ~23~5~16 minecraft:grass
fill ~23~6~14 ~23~6~16 minecraft:sweet_berry_bush 3
fill ~24~0~14 ~25~0~17 minecraft:planks 1
fill ~24~5~14 ~24~5~16 minecraft:deepslate_brick_stairs 1
setblock ~25~5~14 minecraft:dark_oak_stairs 7
setblock ~25~6~14 minecraft:flower_pot
setblock ~26~0~14 minecraft:glowstone
setblock ~26~1~14 minecraft:carpet 15
setblock ~30~0~14 minecraft:glowstone
setblock ~30~1~14 minecraft:carpet 15
fill ~31~0~14 ~32~0~17 minecraft:planks 1
setblock ~31~5~14 minecraft:dark_oak_stairs 7
setblock ~31~6~14 minecraft:flower_pot
fill ~32~5~14 ~32~5~16 minecraft:deepslate_brick_stairs 0
setblock ~33~0~14 minecraft:glowstone
setblock ~33~1~14 minecraft:carpet 15
fill ~33~5~14 ~33~5~16 minecraft:grass
fill ~33~6~14 ~33~6~16 minecraft:sweet_berry_bush 3
fill ~34~0~14 ~34~0~16 minecraft:planks 1
fill ~34~1~14 ~34~2~16 minecraft:glass_pane
fill ~34~3~14 ~34~3~16 minecraft:planks 1
fill ~34~4~14 ~34~4~16 minecraft:log 1
fill ~34~5~14 ~34~5~16 minecraft:glowstone
fill ~34~6~14 ~34~6~16 minecraft:deepslate_brick_stairs 1
fill ~34~7~14 ~34~7~16 minecraft:fence 1
setblock ~34~13~14 minecraft:spruce_fence_gate 1
fill ~34~14~14 ~34~14~16 minecraft:dark_oak_trapdoor 3
fill ~35~0~14 ~35~0~16 minecraft:dark_oak_stairs 5
fill ~35~3~14 ~35~3~16 minecraft:dark_oak_stairs 1
fill ~35~5~14 ~35~5~16 minecraft:trapdoor 0
fill ~39~0~14 ~41~0~14 minecraft:grass
fill ~39~1~14 ~41~9~14 minecraft:bamboo 2
setblock ~39~10~14 minecraft:bamboo 2
fill ~39~11~14 ~39~12~14 minecraft:bamboo 2
fill ~40~10~14 ~41~11~14 minecraft:bamboo 2
setblock ~40~12~14 minecraft:bamboo 2
fill ~40~13~14 ~40~14~14 minecraft:bamboo 2
setblock ~41~12~14 minecraft:bamboo 2
setblock ~41~13~14 minecraft:bamboo 2
fill ~41~14~14 ~41~15~14 minecraft:bamboo 2
setblock ~45~0~14 minecraft:barrel 1
fill ~46~0~14 ~46~0~16 minecraft:fence 5
fill ~46~4~14 ~46~4~16 minecraft:log 1
fill ~46~5~14 ~46~5~16 minecraft:fence 5
setblock ~46~13~14 minecraft:spruce_fence_gate 1
fill ~46~14~14 ~46~14~16 minecraft:dark_oak_trapdoor 2
setblock ~47~0~14 minecraft:reeds 3
setblock ~49~0~14 minecraft:reeds 1
fill ~50~0~14 ~50~0~16 minecraft:deepslate_brick_stairs 1
fill ~50~1~14 ~50~1~16 minecraft:fence 5
fill ~50~4~14 ~50~4~16 minecraft:log 1
fill ~50~5~14 ~50~5~16 minecraft:fence 5
setblock ~50~9~14 minecraft:jungle_trapdoor 2
setblock ~6~3~15 minecraft:lantern 1
setblock ~10~3~15 minecraft:lantern 1
setblock ~10~13~15 minecraft:grindstone 2
setblock ~11~0~15 minecraft:chest 5
fill ~15~0~15 ~15~0~16 minecraft:grass
fill ~15~1~15 ~15~9~16 minecraft:bamboo 2
setblock ~16~0~15 minecraft:glowstone
setblock ~16~1~15 minecraft:jungle_trapdoor 3
fill ~17~0~15 ~17~0~16 minecraft:grass
fill ~17~1~15 ~17~10~16 minecraft:bamboo 2
setblock ~17~11~15 minecraft:bamboo 2
fill ~17~12~15 ~17~13~15 minecraft:bamboo 2
setblock ~21~2~15 minecraft:lantern 1
fill ~23~0~15 ~23~0~17 minecraft:planks 1
setblock ~23~1~15 minecraft:spruce_trapdoor 3
fill ~24~1~15 ~25~1~15 minecraft:bed 0
setblock ~25~5~15 minecraft:spruce_trapdoor 0
fill ~25~6~15 ~25~6~16 minecraft:chest 5
fill ~26~0~15 ~26~0~17 minecraft:planks 1
setblock ~26~1~15 minecraft:spruce_trapdoor 3
setblock ~27~0~15 minecraft:spruce_trapdoor 0
fill ~30~0~15 ~30~0~17 minecraft:planks 1
setblock ~30~1~15 minecraft:spruce_trapdoor 3
fill ~31~1~15 ~32~1~15 minecraft:bed 0
setblock ~31~5~15 minecraft:spruce_trapdoor 1
fill ~31~6~15 ~31~6~16 minecraft:chest 4
fill ~33~0~15 ~33~0~17 minecraft:planks 1
setblock ~33~1~15 minecraft:spruce_trapdoor 3
setblock ~34~13~15 minecraft:grindstone 2
setblock ~35~2~15 minecraft:lantern 1
fill ~39~0~15 ~39~0~16 minecraft:grass
fill ~39~1~15 ~39~11~16 minecraft:bamboo 2
setblock ~39~12~15 minecraft:bamboo 2
setblock ~39~13~15 minecraft:bamboo 2
fill ~39~14~15 ~39~14~16 minecraft:bamboo 2
setblock ~39~15~15 minecraft:bamboo 2
setblock ~40~0~15 minecraft:glowstone
setblock ~40~1~15 minecraft:jungle_trapdoor 2
fill ~41~0~15 ~41~0~16 minecraft:grass
fill ~41~1~15 ~41~9~16 minecraft:bamboo 2
setblock ~41~10~15 minecraft:bamboo 2
fill ~41~11~15 ~41~12~15 minecraft:bamboo 2
setblock ~45~0~15 minecraft:chest 4
setblock ~46~3~15 minecraft:lantern 1
setblock ~46~13~15 minecraft:grindstone 0
setblock ~47~0~15 minecraft:reeds 0
setblock ~49~0~15 minecraft:reeds 2
setblock ~50~3~15 minecraft:lantern 1
setblock ~6~9~16 minecraft:jungle_trapdoor 3
setblock ~10~13~16 minecraft:spruce_fence_gate 1
setblock ~11~0~16 minecraft:barrel 1
setblock ~16~0~16 minecraft:grass
fill ~16~1~16 ~16~13~16 minecraft:bamboo 2
setblock ~16~14~16 minecraft:bamboo 2
fill ~16~15~16 ~16~16~16 minecraft:bamboo 2
setblock ~17~11~16 minecraft:bamboo 2
setblock ~17~12~16 minecraft:bamboo 2
fill ~17~13~16 ~17~14~16 minecraft:bamboo 2
setblock ~22~13~16 minecraft:spruce_fence_gate 3
fill ~23~1~16 ~26~1~16 minecraft:bookshelf
setblock ~23~2~16 minecraft:lantern 0
setblock ~25~5~16 minecraft:dark_oak_stairs 6
setblock ~26~2~16 minecraft:lantern 0
setblock ~26~5~16 minecraft:deepslate_brick_wall 0
setblock ~26~6~16 minecraft:lantern 0
setblock ~27~0~16 minecraft:spruce_trapdoor 0
setblock ~28~3~16 minecraft:jungle_trapdoor 3
fill ~30~1~16 ~33~1~16 minecraft:bookshelf
setblock ~30~2~16 minecraft:lantern 0
setblock ~30~5~16 minecraft:deepslate_brick_wall 0
setblock ~30~6~16 minecraft:lantern 0
setblock ~31~5~16 minecraft:dark_oak_stairs 6
setblock ~33~2~16 minecraft:lantern 0
setblock ~34~13~16 minecraft:spruce_fence_gate 1
fill ~39~12~16 ~41~12~16 minecraft:bamboo 2
fill ~39~13~16 ~41~13~16 minecraft:bamboo 2
setblock ~40~0~16 minecraft:grass
fill ~40~1~16 ~40~11~16 minecraft:bamboo 2
fill ~40~14~16 ~41~14~16 minecraft:bamboo 2
fill ~41~10~16 ~41~11~16 minecraft:bamboo 2
setblock ~45~0~16 minecraft:barrel 1
setblock ~46~13~16 minecraft:spruce_fence_gate 1
setblock ~50~9~16 minecraft:jungle_trapdoor 3
setblock ~5~0~17 minecraft:jungle_stairs 4
setblock ~5~1~17 minecraft:deepslate_brick_wall 0
setblock ~5~2~17 minecraft:fence 5
setblock ~5~3~17 minecraft:deepslate_brick_wall 0
setblock ~5~4~17 minecraft:jungle_stairs 0
setblock ~5~9~17 minecraft:jungle_trapdoor 1
fill ~6~0~17 ~6~5~17 minecraft:log 1
setblock ~6~6~17 minecraft:deepslate_brick_wall 0
setblock ~6~7~17 minecraft:fence 5
setblock ~6~8~17 minecraft:deepslate_brick_wall 0
setblock ~6~9~17 minecraft:glowstone
setblock ~6~10~17 minecraft:deepslate_brick_slab 0
setblock ~7~0~17 minecraft:fence 5
setblock ~7~9~17 minecraft:jungle_trapdoor 0
setblock ~8~0~17 minecraft:dark_oak_fence_gate 2
setblock ~9~0~17 minecraft:fence 5
fill ~10~0~17 ~10~5~17 minecraft:log 1
setblock ~10~6~17 minecraft:deepslate_brick_wall 0
fill ~10~7~17 ~10~11~17 minecraft:fence 5
setblock ~10~12~17 minecraft:deepslate_brick_wall 0
setblock ~10~13~17 minecraft:log 1
setblock ~10~14~17 minecraft:deepslate_brick_slab 0
fill ~15~0~17 ~18~0~17 minecraft:deepslate_brick_stairs 3
setblock ~21~0~17 minecraft:deepslate_brick_wall 0
fill ~21~1~17 ~21~2~17 minecraft:fence 5
setblock ~21~3~17 minecraft:deepslate_brick_wall 0
setblock ~21~4~17 minecraft:deepslate_brick_stairs 0
fill ~22~0~17 ~22~8~17 minecraft:log 1
setblock ~22~9~17 minecraft:deepslate_brick_wall 0
fill ~22~10~17 ~22~11~17 minecraft:fence 5
setblock ~22~12~17 minecraft:deepslate_brick_wall 0
setblock ~22~13~17 minecraft:log 1
setblock ~22~14~17 minecraft:deepslate_brick_slab 0
fill ~23~1~17 ~26~3~17 minecraft:planks 1
fill ~23~5~17 ~25~5~17 minecraft:deepslate_bricks
fill ~23~6~17 ~25~6~17 minecraft:deepslate_brick_stairs 2
fill ~26~5~17 ~26~5~20 minecraft:log 1
setblock ~26~6~17 minecraft:deepslate_brick_wall 0
fill ~27~0~17 ~27~3~17 minecraft:log 1
fill ~27~5~17 ~29~5~17 minecraft:spruce_stairs 2
setblock ~28~0~17 minecraft:spruce_door 3
setblock ~28~2~17 minecraft:log 1
setblock ~28~3~17 minecraft:lantern 0
fill ~29~0~17 ~29~3~17 minecraft:log 1
fill ~30~1~17 ~33~3~17 minecraft:planks 1
fill ~30~5~17 ~30~5~20 minecraft:log 1
setblock ~30~6~17 minecraft:deepslate_brick_wall 0
fill ~31~5~17 ~33~5~17 minecraft:deepslate_bricks
fill ~31~6~17 ~33~6~17 minecraft:deepslate_brick_stairs 2
fill ~34~0~17 ~34~8~17 minecraft:log 1
setblock ~34~9~17 minecraft:deepslate_brick_wall 0
fill ~34~10~17 ~34~11~17 minecraft:fence 5
setblock ~34~12~17 minecraft:deepslate_brick_wall 0
setblock ~34~13~17 minecraft:log 1
setblock ~34~14~17 minecraft:deepslate_brick_slab 0
setblock ~35~0~17 minecraft:deepslate_brick_wall 0
fill ~35~1~17 ~35~2~17 minecraft:fence 5
setblock ~35~3~17 minecraft:deepslate_brick_wall 0
setblock ~35~4~17 minecraft:deepslate_brick_stairs 1
fill ~39~0~17 ~41~0~17 minecraft:deepslate_brick_stairs 3
fill ~46~0~17 ~46~5~17 minecraft:log 1
setblock ~46~6~17 minecraft:deepslate_brick_wall 0
fill ~46~7~17 ~46~11~17 minecraft:fence 5
setblock ~46~12~17 minecraft:deepslate_brick_wall 0
setblock ~46~13~17 minecraft:log 1
setblock ~46~14~17 minecraft:deepslate_brick_slab 0
setblock ~47~0~17 minecraft:fence 5
setblock ~48~0~17 minecraft:dark_oak_fence_gate 2
setblock ~49~0~17 minecraft:fence 5
setblock ~49~9~17 minecraft:jungle_trapdoor 1
fill ~50~0~17 ~50~5~17 minecraft:log 1
setblock ~50~6~17 minecraft:deepslate_brick_wall 0
setblock ~50~7~17 minecraft:fence 5
setblock ~50~8~17 minecraft:deepslate_brick_wall 0
setblock ~50~9~17 minecraft:glowstone
setblock ~50~10~17 minecraft:deepslate_brick_slab 0
setblock ~51~0~17 minecraft:jungle_stairs 5
setblock ~51~1~17 minecraft:deepslate_brick_wall 0
setblock ~51~2~17 minecraft:fence 5
setblock ~51~3~17 minecraft:deepslate_brick_wall 0
setblock ~51~4~17 minecraft:jungle_stairs 1
setblock ~51~9~17 minecraft:jungle_trapdoor 0
fill ~6~0~18 ~6~0~20 minecraft:deepslate_brick_stairs 0
fill ~6~1~18 ~6~1~20 minecraft:fence 5
fill ~6~4~18 ~6~4~20 minecraft:log 1
fill ~6~5~18 ~6~5~20 minecraft:fence 5
setblock ~6~9~18 minecraft:jungle_trapdoor 2
setblock ~7~0~18 minecraft:barrel 5
setblock ~10~0~18 minecraft:fence 5
fill ~10~4~18 ~10~4~20 minecraft:log 1
fill ~10~5~18 ~10~5~20 minecraft:fence 5
setblock ~10~13~18 minecraft:spruce_fence_gate 1
fill ~10~14~18 ~10~14~20 minecraft:dark_oak_trapdoor 3
fill ~21~0~18 ~21~0~20 minecraft:dark_oak_stairs 4
fill ~21~3~18 ~21~3~19 minecraft:dark_oak_stairs 0
fill ~21~6~18 ~21~6~19 minecraft:trapdoor 1
fill ~22~0~18 ~22~0~20 minecraft:planks 1
fill ~22~1~18 ~22~2~20 minecraft:glass_pane
fill ~22~3~18 ~22~3~20 minecraft:planks 1
fill ~22~4~18 ~22~4~20 minecraft:log 1
fill ~22~5~18 ~22~5~20 minecraft:deepslate_brick_wall 0
fill ~22~6~18 ~22~6~20 minecraft:glowstone
fill ~22~7~18 ~22~7~20 minecraft:deepslate_brick_stairs 0
fill ~22~8~18 ~22~8~20 minecraft:fence 1
setblock ~22~13~18 minecraft:spruce_fence_gate 3
fill ~22~14~18 ~22~14~19 minecraft:dark_oak_trapdoor 2
fill ~23~0~18 ~23~0~20 minecraft:grass
fill ~23~1~18 ~23~1~20 minecraft:bamboo 1
fill ~23~2~18 ~23~3~20 minecraft:bamboo 1
fill ~23~5~18 ~25~5~21 minecraft:planks 1
fill ~23~6~18 ~25~6~19 minecraft:farmland 7
fill ~23~7~18 ~25~7~19 minecraft:carrots 7
fill ~24~0~18 ~24~0~20 minecraft:spruce_trapdoor 0
fill ~25~0~18 ~25~2~18 minecraft:dark_oak_stairs 5
fill ~26~0~18 ~26~2~18 minecraft:dark_oak_stairs 4
fill ~26~6~18 ~26~6~20 minecraft:log 1
setblock ~26~7~18 minecraft:deepslate_brick_wall 0
setblock ~26~8~18 minecraft:lantern 0
fill ~27~6~18 ~29~6~18 minecraft:spruce_stairs 2
setblock ~28~3~18 minecraft:jungle_trapdoor 2
fill ~30~0~18 ~30~2~18 minecraft:dark_oak_stairs 5
fill ~30~6~18 ~30~6~20 minecraft:log 1
setblock ~30~7~18 minecraft:deepslate_brick_wall 0
setblock ~30~8~18 minecraft:lantern 0
fill ~31~0~18 ~31~2~18 minecraft:dark_oak_stairs 4
fill ~31~5~18 ~33~5~21 minecraft:planks 1
fill ~31~6~18 ~33~6~18 minecraft:farmland 7
fill ~31~7~18 ~33~7~18 minecraft:carrots 7
fill ~32~0~18 ~32~0~20 minecraft:spruce_trapdoor 1
fill ~33~0~18 ~33~0~20 minecraft:grass
fill ~33~1~18 ~33~1~20 minecraft:bamboo 1
fill ~33~2~18 ~33~3~20 minecraft:bamboo 1
fill ~34~0~18 ~34~0~20 minecraft:planks 1
fill ~34~1~18 ~34~2~20 minecraft:glass_pane
fill ~34~3~18 ~34~3~20 minecraft:planks 1
fill ~34~4~18 ~34~4~20 minecraft:log 1
fill ~34~5~18 ~34~5~20 minecraft:deepslate_brick_wall 0
fill ~34~6~18 ~34~6~20 minecraft:glowstone
fill ~34~7~18 ~34~7~20 minecraft:deepslate_brick_stairs 1
fill ~34~8~18 ~34~8~20 minecraft:fence 1
setblock ~34~13~18 minecraft:spruce_fence_gate 1
fill ~34~14~18 ~34~14~20 minecraft:dark_oak_trapdoor 3
fill ~35~0~18 ~35~0~19 minecraft:dark_oak_stairs 5
fill ~35~3~18 ~35~3~20 minecraft:dark_oak_stairs 1
fill ~35~6~18 ~35~6~19 minecraft:trapdoor 0
setblock ~46~0~18 minecraft:fence 5
fill ~46~4~18 ~46~4~20 minecraft:log 1
fill ~46~5~18 ~46~5~20 minecraft:fence 5
setblock ~46~13~18 minecraft:spruce_fence_gate 1
fill ~46~14~18 ~46~14~20 minecraft:dark_oak_trapdoor 2
setblock ~49~0~18 minecraft:barrel 4
fill ~50~0~18 ~50~0~20 minecraft:deepslate_brick_stairs 1
fill ~50~1~18 ~50~1~20 minecraft:fence 5
fill ~50~4~18 ~50~4~20 minecraft:log 1
fill ~50~5~18 ~50~5~20 minecraft:fence 5
setblock ~50~9~18 minecraft:jungle_trapdoor 2
setblock ~6~3~19 minecraft:lantern 1
setblock ~7~0~19 minecraft:chest 5
setblock ~10~0~19 minecraft:dark_oak_fence_gate 3
setblock ~10~3~19 minecraft:lantern 1
setblock ~10~13~19 minecraft:grindstone 2
setblock ~21~2~19 minecraft:lantern 1
setblock ~22~13~19 minecraft:grindstone 0
fill ~26~7~19 ~26~7~20 minecraft:log 1
setblock ~26~8~19 minecraft:deepslate_brick_wall 0
setblock ~27~5~19 minecraft:torch 5
fill ~27~7~19 ~29~7~19 minecraft:spruce_stairs 2
setblock ~29~5~19 minecraft:torch 5
fill ~30~7~19 ~30~7~20 minecraft:log 1
setblock ~30~8~19 minecraft:deepslate_brick_wall 0
fill ~31~6~19 ~31~6~20 minecraft:farmland 7
fill ~31~7~19 ~31~7~20 minecraft:carrots 7
setblock ~32~6~19 minecraft:dirt 0
setblock ~33~6~19 minecraft:farmland 7
setblock ~33~7~19 minecraft:carrots 7
setblock ~34~13~19 minecraft:grindstone 2
setblock ~35~2~19 minecraft:lantern 1
setblock ~46~0~19 minecraft:dark_oak_fence_gate 1
setblock ~46~3~19 minecraft:lantern 1
setblock ~46~13~19 minecraft:grindstone 0
setblock ~49~0~19 minecraft:chest 4
setblock ~50~3~19 minecraft:lantern 1
setblock ~6~9~20 minecraft:jungle_trapdoor 3
setblock ~7~0~20 minecraft:barrel 5
setblock ~10~0~20 minecraft:fence 5
setblock ~10~13~20 minecraft:spruce_fence_gate 1
fill ~11~0~20 ~13~0~20 minecraft:dark_oak_stairs 6
fill ~11~3~20 ~13~3~20 minecraft:dark_oak_stairs 2
setblock ~12~2~20 minecraft:lantern 1
setblock ~14~0~20 minecraft:deepslate_brick_wall 0
fill ~14~1~20 ~14~2~20 minecraft:fence 5
setblock ~14~3~20 minecraft:deepslate_brick_wall 0
setblock ~14~4~20 minecraft:deepslate_brick_stairs 2
fill ~15~0~20 ~17~0~20 minecraft:dark_oak_stairs 6
fill ~15~3~20 ~17~3~20 minecraft:dark_oak_stairs 2
fill ~15~5~20 ~17~5~20 minecraft:trapdoor 3
setblock ~16~2~20 minecraft:lantern 1
setblock ~18~0~20 minecraft:deepslate_brick_wall 0
fill ~18~1~20 ~18~2~20 minecraft:fence 5
setblock ~18~3~20 minecraft:deepslate_brick_wall 0
setblock ~18~4~20 minecraft:deepslate_brick_stairs 2
fill ~19~0~20 ~20~0~20 minecraft:dark_oak_stairs 6
fill ~19~3~20 ~21~3~20 minecraft:dark_oak_stairs 2
fill ~19~6~20 ~20~6~20 minecraft:trapdoor 3
setblock ~20~2~20 minecraft:lantern 1
setblock ~21~5~20 minecraft:lantern 1
setblock ~21~6~20 minecraft:deepslate_bricks
setblock ~22~13~20 minecraft:spruce_fence_gate 3
setblock ~22~14~20 minecraft:dark_oak_trapdoor 1
setblock ~23~6~20 minecraft:spruce_trapdoor 3
fill ~23~7~20 ~23~8~20 minecraft:log 1
setblock ~23~9~20 minecraft:deepslate_brick_wall 0
fill ~23~10~20 ~23~12~20 minecraft:fence 4
setblock ~23~13~20 minecraft:deepslate_brick_wall 0
setblock ~23~14~20 minecraft:deepslate_brick_stairs 2
fill ~24~6~20 ~25~6~20 minecraft:farmland 7
fill ~24~7~20 ~25~7~20 minecraft:carrots 7
fill ~24~9~20 ~25~9~20 minecraft:dark_oak_stairs 6
setblock ~24~11~20 minecraft:lantern 1
fill ~24~12~20 ~25~12~20 minecraft:dark_oak_stairs 2
fill ~24~13~20 ~25~13~20 minecraft:spruce_fence_gate 0
setblock ~24~14~20 minecraft:deepslate_brick_slab 0
setblock ~25~14~20 minecraft:deepslate_bricks
setblock ~26~8~20 minecraft:log 1
setblock ~26~9~20 minecraft:deepslate_brick_wall 0
fill ~26~10~20 ~26~12~20 minecraft:fence 4
setblock ~26~13~20 minecraft:deepslate_brick_wall 0
fill ~26~14~20 ~26~15~20 minecraft:deepslate_brick_slab 0
setblock ~26~21~20 minecraft:dark_oak_trapdoor 3
fill ~27~8~20 ~29~8~20 minecraft:spruce_stairs 2
fill ~27~12~20 ~29~12~20 minecraft:dark_oak_stairs 2
fill ~27~13~20 ~29~13~20 minecraft:trapdoor 3
setblock ~27~14~20 minecraft:deepslate_bricks
setblock ~28~11~20 minecraft:lantern 1
setblock ~28~14~20 minecraft:deepslate_brick_slab 0
setblock ~29~14~20 minecraft:deepslate_bricks
setblock ~30~8~20 minecraft:log 1
setblock ~30~9~20 minecraft:deepslate_brick_wall 0
fill ~30~10~20 ~30~12~20 minecraft:fence 4
setblock ~30~13~20 minecraft:deepslate_brick_wall 0
fill ~30~14~20 ~30~15~20 minecraft:deepslate_brick_slab 0
setblock ~30~21~20 minecraft:dark_oak_trapdoor 3
fill ~31~9~20 ~32~9~20 minecraft:dark_oak_stairs 6
fill ~31~12~20 ~32~12~20 minecraft:dark_oak_stairs 2
fill ~31~13~20 ~32~13~20 minecraft:spruce_fence_gate 0
setblock ~31~14~20 minecraft:deepslate_bricks
setblock ~32~6~20 minecraft:farmland 7
setblock ~32~7~20 minecraft:carrots 7
setblock ~32~11~20 minecraft:lantern 1
setblock ~32~14~20 minecraft:deepslate_brick_slab 0
setblock ~33~6~20 minecraft:spruce_trapdoor 3
fill ~33~7~20 ~33~8~20 minecraft:log 1
setblock ~33~9~20 minecraft:deepslate_brick_wall 0
fill ~33~10~20 ~33~12~20 minecraft:fence 4
setblock ~33~13~20 minecraft:deepslate_brick_wall 0
setblock ~33~14~20 minecraft:deepslate_brick_stairs 2
setblock ~34~13~20 minecraft:spruce_fence_gate 1
fill ~35~0~20 ~37~0~20 minecraft:dark_oak_stairs 6
setblock ~35~5~20 minecraft:lantern 1
setblock ~35~6~20 minecraft:deepslate_bricks
setblock ~36~2~20 minecraft:lantern 1
fill ~36~3~20 ~37~3~20 minecraft:dark_oak_stairs 2
fill ~36~6~20 ~37~6~20 minecraft:trapdoor 3
setblock ~38~0~20 minecraft:deepslate_brick_wall 0
fill ~38~1~20 ~38~2~20 minecraft:fence 5
setblock ~38~3~20 minecraft:deepslate_brick_wall 0
setblock ~38~4~20 minecraft:deepslate_brick_stairs 2
fill ~39~0~20 ~41~0~20 minecraft:dark_oak_stairs 6
fill ~39~3~20 ~41~3~20 minecraft:dark_oak_stairs 2
fill ~39~5~20 ~41~5~20 minecraft:trapdoor 3
setblock ~40~2~20 minecraft:lantern 1
setblock ~42~0~20 minecraft:deepslate_brick_wall 0
fill ~42~1~20 ~42~2~20 minecraft:fence 5
setblock ~42~3~20 minecraft:deepslate_brick_wall 0
setblock ~42~4~20 minecraft:deepslate_brick_stairs 2
fill ~43~0~20 ~45~0~20 minecraft:dark_oak_stairs 6
fill ~43~3~20 ~45~3~20 minecraft:dark_oak_stairs 2
setblock ~44~2~20 minecraft:lantern 1
setblock ~46~0~20 minecraft:fence 5
setblock ~46~13~20 minecraft:spruce_fence_gate 1
setblock ~49~0~20 minecraft:barrel 4
setblock ~50~9~20 minecraft:jungle_trapdoor 3
setblock ~0~0~21 minecraft:deepslate_brick_wall 0
fill ~1~0~21 ~6~0~21 minecraft:log 1
setblock ~1~1~21 minecraft:deepslate_brick_wall 0
setblock ~2~1~21 minecraft:log 1
setblock ~2~2~21 minecraft:deepslate_brick_wall 0
fill ~3~1~21 ~5~1~21 minecraft:fence 5
setblock ~3~2~21 minecraft:log 1
setblock ~3~3~21 minecraft:deepslate_brick_wall 0
fill ~4~2~21 ~5~2~21 minecraft:fence 5
setblock ~4~3~21 minecraft:log 1
setblock ~4~4~21 minecraft:deepslate_brick_wall 0
setblock ~5~3~21 minecraft:fence 5
fill ~5~4~21 ~6~4~21 minecraft:log 1
setblock ~5~5~21 minecraft:deepslate_brick_wall 0
setblock ~5~9~21 minecraft:jungle_trapdoor 1
fill ~6~1~21 ~6~3~21 minecraft:log 1
setblock ~6~5~21 minecraft:log 1
setblock ~6~6~21 minecraft:deepslate_brick_wall 0
setblock ~6~7~21 minecraft:fence 5
setblock ~6~8~21 minecraft:deepslate_brick_wall 0
setblock ~6~9~21 minecraft:glowstone
setblock ~6~10~21 minecraft:deepslate_brick_slab 0
fill ~7~0~21 ~7~3~22 minecraft:planks 1
fill ~7~4~21 ~9~4~21 minecraft:log 1
setblock ~7~9~21 minecraft:jungle_trapdoor 0
setblock ~8~0~21 minecraft:dark_oak_door 3
fill ~8~2~21 ~9~3~21 minecraft:planks 1
fill ~9~0~21 ~9~1~21 minecraft:planks 1
fill ~10~0~21 ~10~6~21 minecraft:log 1
setblock ~10~7~21 minecraft:deepslate_brick_wall 0
fill ~10~8~21 ~10~11~21 minecraft:fence 5
setblock ~10~12~21 minecraft:deepslate_brick_wall 0
setblock ~10~13~21 minecraft:log 1
setblock ~10~14~21 minecraft:deepslate_brick_slab 0
fill ~11~0~21 ~13~0~21 minecraft:planks 1
fill ~11~1~21 ~13~2~21 minecraft:glass_pane
fill ~11~3~21 ~13~3~21 minecraft:planks 1
fill ~11~4~21 ~13~4~21 minecraft:log 1
fill ~11~5~21 ~13~5~21 minecraft:deepslate_brick_stairs 2
fill ~11~6~21 ~13~6~21 minecraft:fence 1
setblock ~11~13~21 minecraft:spruce_fence_gate 0
fill ~11~14~21 ~13~14~21 minecraft:dark_oak_trapdoor 1
setblock ~12~13~21 minecraft:grindstone 1
setblock ~13~13~21 minecraft:spruce_fence_gate 0
fill ~14~0~21 ~14~7~21 minecraft:log 1
setblock ~14~8~21 minecraft:deepslate_brick_wall 0
fill ~14~9~21 ~14~11~21 minecraft:fence 5
setblock ~14~12~21 minecraft:deepslate_brick_wall 0
setblock ~14~13~21 minecraft:log 1
setblock ~14~14~21 minecraft:deepslate_brick_slab 0
fill ~15~0~21 ~17~0~21 minecraft:planks 1
fill ~15~1~21 ~17~2~21 minecraft:glass_pane
fill ~15~3~21 ~17~3~21 minecraft:planks 1
fill ~15~4~21 ~17~4~21 minecraft:log 1
fill ~15~5~21 ~17~5~21 minecraft:glowstone
fill ~15~6~21 ~17~6~21 minecraft:deepslate_brick_stairs 2
fill ~15~7~21 ~17~7~21 minecraft:fence 1
setblock ~15~13~21 minecraft:spruce_fence_gate 0
fill ~15~14~21 ~17~14~21 minecraft:dark_oak_trapdoor 1
setblock ~16~13~21 minecraft:grindstone 1
setblock ~17~13~21 minecraft:spruce_fence_gate 0
fill ~18~0~21 ~18~8~21 minecraft:log 1
setblock ~18~9~21 minecraft:deepslate_brick_wall 0
fill ~18~10~21 ~18~11~21 minecraft:fence 5
setblock ~18~12~21 minecraft:deepslate_brick_wall 0
setblock ~18~13~21 minecraft:log 1
setblock ~18~14~21 minecraft:deepslate_brick_slab 0
fill ~19~0~21 ~21~0~21 minecraft:planks 1
fill ~19~1~21 ~21~2~21 minecraft:glass_pane
fill ~19~3~21 ~21~3~21 minecraft:planks 1
fill ~19~4~21 ~21~4~21 minecraft:log 1
fill ~19~5~21 ~21~5~21 minecraft:deepslate_brick_wall 0
fill ~19~6~21 ~21~6~21 minecraft:glowstone
fill ~19~7~21 ~21~7~21 minecraft:deepslate_brick_stairs 2
fill ~19~8~21 ~21~8~21 minecraft:fence 1
setblock ~19~13~21 minecraft:spruce_fence_gate 0
fill ~19~14~21 ~21~14~21 minecraft:dark_oak_trapdoor 1
setblock ~20~13~21 minecraft:grindstone 1
fill ~22~0~21 ~22~9~21 minecraft:log 1
setblock ~22~10~21 minecraft:deepslate_brick_wall 0
setblock ~22~11~21 minecraft:fence 5
setblock ~22~12~21 minecraft:deepslate_brick_wall 0
fill ~22~13~21 ~23~13~21 minecraft:log 1
setblock ~22~14~21 minecraft:deepslate_bricks
setblock ~22~15~21 minecraft:log 1
setblock ~22~16~21 minecraft:deepslate_brick_slab 0
fill ~22~19~21 ~23~19~21 minecraft:deepslate_brick_slab 0
setblock ~23~0~21 minecraft:spruce_trapdoor 2
fill ~23~4~21 ~33~4~21 minecraft:log 1
fill ~23~6~21 ~33~7~21 minecraft:planks 1
fill ~23~8~21 ~33~8~21 minecraft:log 1
fill ~23~9~21 ~23~12~21 minecraft:log 1
setblock ~23~14~21 minecraft:log 1
setblock ~23~15~21 minecraft:fence 5
setblock ~23~20~21 minecraft:deepslate_brick_stairs 0
fill ~24~9~21 ~25~9~21 minecraft:planks 1
fill ~24~10~21 ~25~11~21 minecraft:glass_pane
fill ~24~12~21 ~25~13~21 minecraft:planks 1
fill ~24~14~21 ~25~14~21 minecraft:log 1
fill ~24~15~21 ~24~15~22 minecraft:log 1
setblock ~24~16~21 minecraft:deepslate_brick_wall 0
fill ~24~17~21 ~24~18~21 minecraft:fence 4
setblock ~24~19~21 minecraft:deepslate_brick_wall 0
setblock ~24~20~21 minecraft:deepslate_brick_stairs 5
setblock ~24~21~21 minecraft:deepslate_brick_stairs 0
setblock ~25~15~21 minecraft:fence 5
setblock ~25~18~21 minecraft:lantern 1
setblock ~25~19~21 minecraft:dark_oak_stairs 2
fill ~25~20~21 ~31~20~21 minecraft:dark_oak_stairs 6
setblock ~25~21~21 minecraft:deepslate_brick_stairs 5
setblock ~25~22~21 minecraft:deepslate_brick_stairs 0
fill ~26~5~21 ~30~5~21 minecraft:planks 1
fill ~26~9~21 ~26~15~21 minecraft:log 1
setblock ~26~16~21 minecraft:deepslate_brick_wall 0
fill ~26~17~21 ~26~18~21 minecraft:fence 4
setblock ~26~19~21 minecraft:deepslate_brick_wall 0
setblock ~26~21~21 minecraft:glowstone
setblock ~26~22~21 minecraft:deepslate_brick_stairs 5
setblock ~26~23~21 minecraft:deepslate_brick_stairs 0
setblock ~27~9~21 minecraft:deepslate_brick_wall 0
setblock ~27~10~21 minecraft:fence 5
setblock ~27~11~21 minecraft:deepslate_brick_wall 0
fill ~27~12~21 ~29~12~21 minecraft:log 1
fill ~27~13~21 ~29~13~21 minecraft:glowstone
fill ~27~14~21 ~29~14~21 minecraft:log 1
setblock ~27~15~21 minecraft:fence 5
setblock ~27~21~21 minecraft:deepslate_brick_wall 0
setblock ~27~22~21 minecraft:fence 1
setblock ~27~23~21 minecraft:deepslate_brick_stairs 5
setblock ~27~24~21 minecraft:deepslate_brick_stairs 0
setblock ~28~11~21 minecraft:dark_oak_stairs 2
setblock ~28~15~21 minecraft:dark_oak_fence_gate 0
setblock ~28~21~21 minecraft:lantern 0
setblock ~28~24~21 minecraft:deepslate_brick_slab 0
setblock ~28~25~21 minecraft:deepslate_brick_double_slab 0
setblock ~29~9~21 minecraft:deepslate_brick_wall 0
setblock ~29~10~21 minecraft:fence 5
setblock ~29~11~21 minecraft:deepslate_brick_wall 0
setblock ~29~15~21 minecraft:fence 5
setblock ~29~21~21 minecraft:deepslate_brick_wall 0
setblock ~29~22~21 minecraft:fence 1
setblock ~29~23~21 minecraft:deepslate_brick_stairs 4
setblock ~29~24~21 minecraft:deepslate_brick_stairs 1
fill ~30~9~21 ~30~15~21 minecraft:log 1
setblock ~30~16~21 minecraft:deepslate_brick_wall 0
fill ~30~17~21 ~30~18~21 minecraft:fence 4
setblock ~30~19~21 minecraft:deepslate_brick_wall 0
setblock ~30~21~21 minecraft:glowstone
setblock ~30~22~21 minecraft:deepslate_brick_stairs 4
setblock ~30~23~21 minecraft:deepslate_brick_stairs 1
fill ~31~9~21 ~32~9~21 minecraft:planks 1
fill ~31~10~21 ~32~11~21 minecraft:glass_pane
fill ~31~12~21 ~32~13~21 minecraft:planks 1
fill ~31~14~21 ~32~14~21 minecraft:log 1
setblock ~31~15~21 minecraft:fence 5
setblock ~31~18~21 minecraft:lantern 1
setblock ~31~19~21 minecraft:dark_oak_stairs 2
setblock ~31~21~21 minecraft:deepslate_brick_stairs 4
setblock ~31~22~21 minecraft:deepslate_brick_stairs 1
fill ~32~15~21 ~32~15~22 minecraft:log 1
setblock ~32~16~21 minecraft:deepslate_brick_wall 0
fill ~32~17~21 ~32~18~21 minecraft:fence 4
setblock ~32~19~21 minecraft:deepslate_brick_wall 0
setblock ~32~20~21 minecraft:deepslate_brick_stairs 4
setblock ~32~21~21 minecraft:deepslate_brick_stairs 1
setblock ~33~0~21 minecraft:spruce_trapdoor 2
fill ~33~9~21 ~34~9~21 minecraft:log 1
fill ~33~10~21 ~33~14~21 minecraft:log 1
setblock ~33~15~21 minecraft:fence 5
fill ~33~19~21 ~34~19~21 minecraft:deepslate_brick_slab 0
setblock ~33~20~21 minecraft:deepslate_brick_stairs 1
fill ~34~0~21 ~34~8~21 minecraft:log 1
setblock ~34~10~21 minecraft:deepslate_brick_wall 0
setblock ~34~11~21 minecraft:fence 5
setblock ~34~12~21 minecraft:deepslate_brick_wall 0
fill ~34~13~21 ~34~13~22 minecraft:log 1
setblock ~34~14~21 minecraft:deepslate_bricks
setblock ~34~15~21 minecraft:log 1
setblock ~34~16~21 minecraft:deepslate_brick_slab 0
fill ~35~0~21 ~37~0~21 minecraft:planks 1
fill ~35~1~21 ~37~2~21 minecraft:glass_pane
fill ~35~3~21 ~37~3~21 minecraft:planks 1
fill ~35~4~21 ~37~4~21 minecraft:log 1
fill ~35~5~21 ~37~5~21 minecraft:deepslate_brick_wall 0
fill ~35~6~21 ~37~6~21 minecraft:glowstone
fill ~35~7~21 ~37~7~21 minecraft:deepslate_brick_stairs 2
fill ~35~8~21 ~37~8~21 minecraft:fence 1
setblock ~35~13~21 minecraft:spruce_fence_gate 2
fill ~35~14~21 ~37~14~21 minecraft:dark_oak_trapdoor 1
setblock ~36~13~21 minecraft:grindstone 1
setblock ~37~13~21 minecraft:spruce_fence_gate 2
fill ~38~0~21 ~38~8~21 minecraft:log 1
setblock ~38~9~21 minecraft:deepslate_brick_wall 0
fill ~38~10~21 ~38~11~21 minecraft:fence 5
setblock ~38~12~21 minecraft:deepslate_brick_wall 0
setblock ~38~13~21 minecraft:log 1
setblock ~38~14~21 minecraft:deepslate_brick_slab 0
fill ~39~0~21 ~41~0~21 minecraft:planks 1
fill ~39~1~21 ~41~2~21 minecraft:glass_pane
fill ~39~3~21 ~41~3~21 minecraft:planks 1
fill ~39~4~21 ~41~4~21 minecraft:log 1
fill ~39~5~21 ~41~5~21 minecraft:glowstone
fill ~39~6~21 ~41~6~21 minecraft:deepslate_brick_stairs 2
fill ~39~7~21 ~41~7~21 minecraft:fence 1
setblock ~39~13~21 minecraft:spruce_fence_gate 2
fill ~39~14~21 ~41~14~21 minecraft:dark_oak_trapdoor 1
setblock ~40~13~21 minecraft:grindstone 1
setblock ~41~13~21 minecraft:spruce_fence_gate 2
fill ~42~0~21 ~42~7~21 minecraft:log 1
setblock ~42~8~21 minecraft:deepslate_brick_wall 0
fill ~42~9~21 ~42~11~21 minecraft:fence 5
setblock ~42~12~21 minecraft:deepslate_brick_wall 0
setblock ~42~13~21 minecraft:log 1
setblock ~42~14~21 minecraft:deepslate_brick_slab 0
fill ~43~0~21 ~45~0~21 minecraft:planks 1
fill ~43~1~21 ~45~2~21 minecraft:glass_pane
fill ~43~3~21 ~45~3~21 minecraft:planks 1
fill ~43~4~21 ~45~4~21 minecraft:log 1
fill ~43~5~21 ~45~5~21 minecraft:deepslate_brick_stairs 2
fill ~43~6~21 ~45~6~21 minecraft:fence 1
setblock ~43~13~21 minecraft:spruce_fence_gate 2
fill ~43~14~21 ~45~14~21 minecraft:dark_oak_trapdoor 1
setblock ~44~13~21 minecraft:grindstone 1
setblock ~45~13~21 minecraft:spruce_fence_gate 2
fill ~46~0~21 ~46~6~21 minecraft:log 1
setblock ~46~7~21 minecraft:deepslate_brick_wall 0
fill ~46~8~21 ~46~11~21 minecraft:fence 5
setblock ~46~12~21 minecraft:deepslate_brick_wall 0
setblock ~46~13~21 minecraft:log 1
setblock ~46~14~21 minecraft:deepslate_brick_slab 0
fill ~47~0~21 ~47~3~21 minecraft:planks 1
fill ~47~4~21 ~49~4~21 minecraft:log 1
setblock ~48~0~21 minecraft:dark_oak_door 3
fill ~48~2~21 ~49~3~21 minecraft:planks 1
fill ~49~0~21 ~49~1~22 minecraft:planks 1
setblock ~49~9~21 minecraft:jungle_trapdoor 1
fill ~50~0~21 ~55~0~21 minecraft:log 1
fill ~50~1~21 ~50~5~21 minecraft:log 1
setblock ~50~6~21 minecraft:deepslate_brick_wall 0
setblock ~50~7~21 minecraft:fence 5
setblock ~50~8~21 minecraft:deepslate_brick_wall 0
setblock ~50~9~21 minecraft:glowstone
setblock ~50~10~21 minecraft:deepslate_brick_slab 0
fill ~51~1~21 ~53~1~21 minecraft:fence 5
fill ~51~2~21 ~52~2~21 minecraft:fence 5
setblock ~51~3~21 minecraft:fence 5
setblock ~51~4~21 minecraft:log 1
setblock ~51~5~21 minecraft:deepslate_brick_wall 0
setblock ~51~9~21 minecraft:jungle_trapdoor 0
setblock ~52~3~21 minecraft:log 1
setblock ~52~4~21 minecraft:deepslate_brick_wall 0
setblock ~52~5~21 minecraft:lantern 0
setblock ~53~2~21 minecraft:log 1
setblock ~53~3~21 minecraft:deepslate_brick_wall 0
setblock ~54~1~21 minecraft:log 1
setblock ~54~2~21 minecraft:deepslate_brick_wall 0
setblock ~54~3~21 minecraft:lantern 0
setblock ~55~1~21 minecraft:deepslate_brick_wall 0
setblock ~56~0~21 minecraft:deepslate_brick_wall 0
setblock ~56~1~21 minecraft:lantern 0
fill ~1~0~22 ~1~0~24 minecraft:spruce_stairs 0
fill ~2~0~22 ~2~0~24 minecraft:barrel 5
fill ~2~1~22 ~2~1~24 minecraft:spruce_stairs 0
fill ~3~0~22 ~6~1~22 minecraft:chest 3
fill ~3~2~22 ~3~2~24 minecraft:spruce_stairs 0
fill ~4~3~22 ~4~3~24 minecraft:spruce_stairs 0
fill ~5~4~22 ~5~4~24 minecraft:spruce_stairs 0
fill ~6~4~22 ~6~4~24 minecraft:log 1
setblock ~6~9~22 minecraft:jungle_trapdoor 2
fill ~7~4~22 ~9~4~32 minecraft:planks 1
fill ~8~2~22 ~8~2~24 minecraft:spruce_trapdoor 0
fill ~8~3~22 ~8~3~23 minecraft:flower_pot
fill ~10~0~22 ~11~0~22 minecraft:chest 3
fill ~10~4~22 ~10~4~32 minecraft:log 1
fill ~11~4~22 ~21~4~32 minecraft:planks 1
fill ~11~5~22 ~12~5~22 minecraft:barrel 1
setblock ~12~0~22 minecraft:smoker 3
setblock ~12~2~22 minecraft:lantern 1
fill ~12~3~22 ~13~3~22 minecraft:barrel 3
setblock ~12~6~22 minecraft:barrel 1
setblock ~12~7~22 minecraft:lantern 0
setblock ~13~0~22 minecraft:blast_furnace 3
fill ~13~5~22 ~13~6~22 minecraft:barrel 3
setblock ~13~7~22 minecraft:barrel 1
setblock ~14~0~22 minecraft:planks 1
setblock ~14~1~22 minecraft:spruce_trapdoor 1
fill ~14~5~22 ~14~5~23 minecraft:deepslate_brick_stairs 0
setblock ~15~0~22 minecraft:glowstone
setblock ~15~1~22 minecraft:carpet 15
fill ~15~5~22 ~17~5~22 minecraft:grass
fill ~15~6~22 ~17~6~22 minecraft:sweet_berry_bush 3
fill ~16~0~22 ~18~0~25 minecraft:planks 1
setblock ~16~1~22 minecraft:spruce_trapdoor 1
fill ~17~1~22 ~17~1~25 minecraft:bookshelf
setblock ~17~2~22 minecraft:lantern 0
fill ~18~1~22 ~18~3~25 minecraft:planks 1
fill ~18~5~22 ~18~5~24 minecraft:deepslate_bricks
fill ~18~6~22 ~18~6~24 minecraft:deepslate_brick_stairs 0
fill ~19~0~22 ~21~0~22 minecraft:grass
fill ~19~1~22 ~21~1~22 minecraft:bamboo 1
fill ~19~2~22 ~21~3~22 minecraft:bamboo 1
fill ~19~5~22 ~22~5~24 minecraft:planks 1
fill ~19~6~22 ~20~6~24 minecraft:farmland 7
fill ~19~7~22 ~20~7~24 minecraft:carrots 7
setblock ~21~6~22 minecraft:spruce_trapdoor 1
fill ~21~7~22 ~21~8~22 minecraft:log 1
setblock ~21~9~22 minecraft:deepslate_brick_wall 0
fill ~21~10~22 ~21~12~22 minecraft:fence 4
setblock ~21~13~22 minecraft:deepslate_brick_wall 0
setblock ~21~14~22 minecraft:deepslate_brick_stairs 0
setblock ~22~0~22 minecraft:spruce_trapdoor 0
fill ~22~4~22 ~22~4~32 minecraft:log 1
fill ~22~6~22 ~22~7~32 minecraft:planks 1
fill ~22~8~22 ~22~8~32 minecraft:log 1
fill ~22~9~22 ~22~14~22 minecraft:log 1
setblock ~22~15~22 minecraft:fence 5
setblock ~22~19~22 minecraft:deepslate_brick_slab 0
setblock ~22~20~22 minecraft:deepslate_brick_stairs 2
fill ~23~4~22 ~23~4~31 minecraft:spruce_trapdoor 0
fill ~23~5~22 ~24~5~22 minecraft:grass
fill ~23~6~22 ~24~6~22 minecraft:bamboo 1
fill ~23~7~22 ~24~7~22 minecraft:bamboo 1
fill ~23~8~22 ~33~8~32 minecraft:planks 1
fill ~23~9~22 ~25~9~22 minecraft:bookshelf
setblock ~23~12~22 minecraft:lantern 1
setblock ~23~13~22 minecraft:fence 5
fill ~23~14~22 ~33~14~22 minecraft:planks 1
setblock ~23~15~22 minecraft:glowstone
fill ~23~16~22 ~23~17~22 minecraft:leaves 0
setblock ~23~20~22 minecraft:dark_oak_stairs 2
fill ~24~4~22 ~33~4~22 minecraft:spruce_trapdoor 2
setblock ~24~10~22 minecraft:lantern 0
fill ~24~13~22 ~25~13~22 minecraft:dark_oak_fence_gate 2
fill ~24~16~22 ~24~20~22 minecraft:log 1
setblock ~24~21~22 minecraft:dark_oak_stairs 0
setblock ~25~5~22 minecraft:dirt 0
setblock ~25~6~22 minecraft:barrel 0
fill ~25~7~22 ~25~7~23 minecraft:log 1
setblock ~25~10~22 minecraft:flower_pot
setblock ~25~15~22 minecraft:planks 1
fill ~25~16~22 ~25~18~22 minecraft:glass_pane
setblock ~25~19~22 minecraft:planks 1
fill ~25~20~22 ~25~20~23 minecraft:log 1
fill ~25~21~22 ~26~21~22 minecraft:fence 4
fill ~25~22~22 ~25~22~23 minecraft:dark_oak_stairs 0
fill ~26~5~22 ~30~5~22 minecraft:grass
fill ~26~6~22 ~30~6~22 minecraft:bamboo 1
fill ~26~7~22 ~30~7~22 minecraft:bamboo 1
fill ~26~9~22 ~26~13~22 minecraft:planks 1
fill ~26~15~22 ~26~20~22 minecraft:log 1
setblock ~26~22~22 minecraft:fence 4
fill ~26~23~22 ~26~23~24 minecraft:dark_oak_stairs 0
fill ~27~9~22 ~27~13~22 minecraft:stripped_spruce_log 0
setblock ~27~15~22 minecraft:dark_oak_stairs 6
setblock ~27~16~22 minecraft:deepslate_brick_wall 0
setblock ~27~17~22 minecraft:fence 5
setblock ~27~18~22 minecraft:deepslate_brick_wall 0
fill ~27~19~22 ~29~19~22 minecraft:dark_oak_stairs 2
fill ~27~20~22 ~29~20~23 minecraft:log 1
fill ~27~21~22 ~27~23~22 minecraft:log 1
fill ~27~24~22 ~27~24~25 minecraft:dark_oak_stairs 0
setblock ~28~9~22 minecraft:dark_oak_door 3
setblock ~28~11~22 minecraft:stripped_spruce_log 1
setblock ~28~12~22 minecraft:lantern 0
setblock ~28~13~22 minecraft:trapdoor 2
setblock ~28~15~22 minecraft:glowstone
setblock ~28~18~22 minecraft:lantern 1
setblock ~28~21~22 minecraft:deepslate_bricks
setblock ~28~22~22 minecraft:fence 4
setblock ~28~23~22 minecraft:deepslate_bricks
fill ~28~24~22 ~28~24~23 minecraft:log 1
setblock ~28~25~22 minecraft:deepslate_brick_slab 0
fill ~29~9~22 ~29~13~22 minecraft:stripped_spruce_log 0
setblock ~29~15~22 minecraft:dark_oak_stairs 6
setblock ~29~16~22 minecraft:deepslate_brick_wall 0
setblock ~29~17~22 minecraft:fence 5
setblock ~29~18~22 minecraft:deepslate_brick_wall 0
fill ~29~21~22 ~29~23~22 minecraft:log 1
fill ~29~24~22 ~29~24~26 minecraft:dark_oak_stairs 1
fill ~30~9~22 ~33~9~22 minecraft:bookshelf
setblock ~30~12~22 minecraft:lantern 1
setblock ~30~13~22 minecraft:fence 5
fill ~30~15~22 ~30~20~22 minecraft:log 1
fill ~30~21~22 ~31~21~22 minecraft:fence 4
setblock ~30~22~22 minecraft:fence 4
fill ~30~23~22 ~30~23~24 minecraft:dark_oak_stairs 1
setblock ~31~5~22 minecraft:dirt 0
setblock ~31~6~22 minecraft:barrel 0
fill ~31~7~22 ~31~7~23 minecraft:log 1
fill ~31~13~22 ~32~13~22 minecraft:dark_oak_fence_gate 2
setblock ~31~15~22 minecraft:planks 1
fill ~31~16~22 ~31~18~22 minecraft:glass_pane
setblock ~31~19~22 minecraft:planks 1
fill ~31~20~22 ~31~20~23 minecraft:log 1
fill ~31~22~22 ~31~22~24 minecraft:dark_oak_stairs 1
fill ~32~5~22 ~33~5~22 minecraft:grass
fill ~32~6~22 ~33~6~22 minecraft:bamboo 1
fill ~32~7~22 ~33~7~22 minecraft:bamboo 1
setblock ~32~10~22 minecraft:lantern 0
fill ~32~16~22 ~32~20~22 minecraft:log 1
fill ~32~21~22 ~32~21~23 minecraft:dark_oak_stairs 1
setblock ~33~10~22 minecraft:flower_pot
setblock ~33~12~22 minecraft:lantern 1
setblock ~33~13~22 minecraft:fence 5
setblock ~33~15~22 minecraft:glowstone
fill ~33~16~22 ~33~17~22 minecraft:leaves 0
setblock ~33~20~22 minecraft:dark_oak_stairs 2
setblock ~34~0~22 minecraft:spruce_trapdoor 1
fill ~34~4~22 ~34~4~32 minecraft:log 1
fill ~34~5~22 ~37~5~24 minecraft:planks 1
fill ~34~6~22 ~34~7~32 minecraft:planks 1
fill ~34~8~22 ~34~8~32 minecraft:log 1
fill ~34~9~22 ~34~12~22 minecraft:log 1
setblock ~34~14~22 minecraft:log 1
setblock ~34~15~22 minecraft:fence 5
setblock ~34~19~22 minecraft:deepslate_brick_slab 0
setblock ~34~20~22 minecraft:deepslate_brick_stairs 2
fill ~35~0~22 ~37~0~22 minecraft:grass
fill ~35~1~22 ~37~1~22 minecraft:bamboo 1
fill ~35~2~22 ~37~3~22 minecraft:bamboo 1
fill ~35~4~22 ~45~4~32 minecraft:planks 1
setblock ~35~6~22 minecraft:spruce_trapdoor 0
fill ~35~7~22 ~35~8~22 minecraft:log 1
setblock ~35~9~22 minecraft:deepslate_brick_wall 0
fill ~35~10~22 ~35~12~22 minecraft:fence 4
setblock ~35~13~22 minecraft:deepslate_brick_wall 0
setblock ~35~14~22 minecraft:deepslate_brick_stairs 1
fill ~36~6~22 ~37~6~24 minecraft:farmland 7
fill ~36~7~22 ~37~7~24 minecraft:carrots 7
fill ~38~0~22 ~40~0~25 minecraft:planks 1
fill ~38~1~22 ~38~3~25 minecraft:planks 1
fill ~38~5~22 ~38~5~24 minecraft:deepslate_bricks
fill ~38~6~22 ~38~6~24 minecraft:deepslate_brick_stairs 1
fill ~39~1~22 ~39~1~25 minecraft:bookshelf
setblock ~39~2~22 minecraft:lantern 0
fill ~39~5~22 ~41~5~22 minecraft:grass
fill ~39~6~22 ~41~6~22 minecraft:sweet_berry_bush 3
setblock ~40~1~22 minecraft:spruce_trapdoor 0
setblock ~41~0~22 minecraft:glowstone
setblock ~41~1~22 minecraft:carpet 15
setblock ~42~0~22 minecraft:planks 1
setblock ~42~1~22 minecraft:spruce_trapdoor 0
fill ~42~5~22 ~42~5~23 minecraft:deepslate_brick_stairs 1
setblock ~43~0~22 minecraft:blast_furnace 3
fill ~43~3~22 ~44~3~22 minecraft:barrel 3
fill ~43~5~22 ~45~5~22 minecraft:barrel 3
fill ~43~6~22 ~43~6~23 minecraft:barrel 3
setblock ~44~0~22 minecraft:smoker 3
setblock ~44~6~22 minecraft:barrel 1
setblock ~44~7~22 minecraft:barrel 3
fill ~45~0~22 ~46~0~22 minecraft:chest 3
setblock ~45~6~22 minecraft:barrel 3
fill ~46~4~22 ~46~4~32 minecraft:log 1
fill ~47~4~22 ~49~4~32 minecraft:planks 1
fill ~48~2~22 ~48~2~24 minecraft:spruce_trapdoor 1
fill ~48~3~22 ~48~3~23 minecraft:flower_pot
fill ~49~2~22 ~49~3~25 minecraft:planks 1
fill ~50~0~22 ~53~1~22 minecraft:chest 3
fill ~50~4~22 ~50~4~24 minecraft:log 1
setblock ~50~9~22 minecraft:jungle_trapdoor 2
fill ~51~4~22 ~51~4~24 minecraft:spruce_stairs 1
fill ~52~3~22 ~52~3~24 minecraft:spruce_stairs 1
fill ~53~2~22 ~53~2~24 minecraft:spruce_stairs 1
fill ~54~0~22 ~54~0~24 minecraft:barrel 4
fill ~54~1~22 ~54~1~24 minecraft:spruce_stairs 1
fill ~55~0~22 ~55~0~24 minecraft:spruce_stairs 1
setblock ~4~2~23 minecraft:lantern 1
setblock ~5~3~23 minecraft:lantern 1
setblock ~7~0~23 minecraft:dark_oak_door 0
fill ~7~2~23 ~7~3~25 minecraft:planks 1
fill ~11~5~23 ~12~5~23 minecraft:barrel 3
fill ~13~0~23 ~13~0~25 minecraft:spruce_trapdoor 1
fill ~13~5~23 ~13~6~23 minecraft:barrel 1
fill ~14~0~23 ~14~0~24 minecraft:glowstone
fill ~14~1~23 ~14~1~24 minecraft:carpet 15
fill ~15~0~23 ~15~0~24 minecraft:planks 1
fill ~15~5~23 ~17~5~23 minecraft:deepslate_brick_stairs 3
fill ~16~1~23 ~16~1~24 minecraft:bed 3
fill ~19~0~23 ~21~0~23 minecraft:spruce_trapdoor 2
fill ~21~6~23 ~21~6~24 minecraft:farmland 7
fill ~21~7~23 ~21~7~24 minecraft:carrots 7
fill ~21~9~23 ~21~9~24 minecraft:dark_oak_stairs 4
fill ~21~12~23 ~21~12~24 minecraft:dark_oak_stairs 0
fill ~21~13~23 ~21~13~24 minecraft:spruce_fence_gate 3
setblock ~21~14~23 minecraft:deepslate_brick_slab 0
fill ~22~9~23 ~22~9~24 minecraft:planks 1
fill ~22~10~23 ~22~11~24 minecraft:glass_pane
fill ~22~12~23 ~22~13~24 minecraft:planks 1
fill ~22~14~23 ~22~14~24 minecraft:log 1
fill ~22~15~23 ~23~15~23 minecraft:log 1
setblock ~22~16~23 minecraft:deepslate_brick_wall 0
fill ~22~17~23 ~22~18~23 minecraft:fence 4
setblock ~22~19~23 minecraft:deepslate_brick_wall 0
setblock ~22~20~23 minecraft:deepslate_brick_stairs 7
setblock ~22~21~23 minecraft:deepslate_brick_stairs 2
setblock ~23~5~23 minecraft:grass
setblock ~23~6~23 minecraft:bamboo 1
setblock ~23~7~23 minecraft:bamboo 1
fill ~23~9~23 ~23~9~25 minecraft:bookshelf
fill ~23~13~23 ~23~13~24 minecraft:dark_oak_fence_gate 1
fill ~23~14~23 ~25~14~32 minecraft:planks 1
fill ~23~16~23 ~23~20~23 minecraft:log 1
fill ~23~21~23 ~24~21~23 minecraft:dark_oak_stairs 2
setblock ~24~5~23 minecraft:log 1
setblock ~24~7~23 minecraft:lantern 1
setblock ~24~9~23 minecraft:carpet 5
fill ~24~15~23 ~24~16~23 minecraft:deepslate_bricks
setblock ~24~19~23 minecraft:fence 5
setblock ~24~20~23 minecraft:log 1
fill ~25~5~23 ~31~5~23 minecraft:spruce_trapdoor 2
setblock ~25~9~23 minecraft:carpet 0
setblock ~25~15~23 minecraft:dark_oak_stairs 4
setblock ~25~16~23 minecraft:flower_pot
setblock ~25~19~23 minecraft:dark_oak_fence_gate 2
setblock ~26~9~23 minecraft:carpet 5
fill ~26~10~23 ~26~14~23 minecraft:ladder 3
setblock ~26~18~23 minecraft:lantern 1
setblock ~26~19~23 minecraft:fence 5
setblock ~26~20~23 minecraft:log 1
setblock ~27~9~23 minecraft:carpet 0
fill ~27~14~23 ~33~14~32 minecraft:planks 1
fill ~27~15~23 ~27~19~23 minecraft:stripped_spruce_log 0
setblock ~28~7~23 minecraft:lantern 1
setblock ~28~9~23 minecraft:carpet 5
setblock ~28~15~23 minecraft:stripped_spruce_log 1
fill ~28~16~23 ~28~18~23 minecraft:glass_pane
setblock ~28~19~23 minecraft:stripped_spruce_log 1
setblock ~28~22~23 minecraft:lantern 1
setblock ~28~23~23 minecraft:deepslate_brick_wall 0
setblock ~28~25~23 minecraft:deepslate_brick_double_slab 0
setblock ~29~9~23 minecraft:carpet 0
fill ~29~15~23 ~29~19~23 minecraft:stripped_spruce_log 0
setblock ~30~9~23 minecraft:carpet 5
setblock ~30~15~23 minecraft:dark_oak_stairs 5
setblock ~30~16~23 minecraft:anvil 3
setblock ~30~18~23 minecraft:lantern 1
setblock ~30~19~23 minecraft:fence 5
setblock ~30~20~23 minecraft:log 1
setblock ~31~9~23 minecraft:carpet 0
setblock ~31~15~23 minecraft:dark_oak_stairs 4
setblock ~31~16~23 minecraft:chest 3
setblock ~31~19~23 minecraft:dark_oak_fence_gate 2
setblock ~32~5~23 minecraft:log 1
setblock ~32~7~23 minecraft:lantern 1
setblock ~32~9~23 minecraft:carpet 5
fill ~32~15~23 ~32~16~23 minecraft:deepslate_bricks
setblock ~32~19~23 minecraft:fence 5
fill ~32~20~23 ~33~20~23 minecraft:log 1
fill ~33~4~23 ~33~4~31 minecraft:spruce_trapdoor 1
setblock ~33~5~23 minecraft:grass
setblock ~33~6~23 minecraft:bamboo 1
setblock ~33~7~23 minecraft:bamboo 1
fill ~33~9~23 ~33~9~25 minecraft:bookshelf
fill ~33~13~23 ~33~13~24 minecraft:dark_oak_fence_gate 3
fill ~33~15~23 ~34~15~23 minecraft:log 1
fill ~33~16~23 ~33~19~23 minecraft:log 1
setblock ~33~21~23 minecraft:dark_oak_stairs 2
fill ~34~9~23 ~34~9~24 minecraft:planks 1
fill ~34~10~23 ~34~11~24 minecraft:glass_pane
fill ~34~12~23 ~34~13~24 minecraft:planks 1
fill ~34~14~23 ~34~14~24 minecraft:log 1
setblock ~34~16~23 minecraft:deepslate_brick_wall 0
fill ~34~17~23 ~34~18~23 minecraft:fence 4
setblock ~34~19~23 minecraft:deepslate_brick_wall 0
setblock ~34~20~23 minecraft:deepslate_brick_stairs 7
setblock ~34~21~23 minecraft:deepslate_brick_stairs 2
fill ~35~0~23 ~37~0~23 minecraft:spruce_trapdoor 2
setblock ~35~6~23 minecraft:dirt 0
fill ~35~9~23 ~35~9~24 minecraft:dark_oak_stairs 5
fill ~35~12~23 ~35~12~24 minecraft:dark_oak_stairs 1
fill ~35~13~23 ~35~13~24 minecraft:spruce_fence_gate 1
setblock ~35~14~23 minecraft:deepslate_brick_slab 0
fill ~39~5~23 ~41~5~23 minecraft:deepslate_brick_stairs 3
fill ~40~1~23 ~40~1~24 minecraft:bed 1
fill ~41~0~23 ~41~0~24 minecraft:planks 1
fill ~42~0~23 ~42~0~24 minecraft:glowstone
fill ~42~1~23 ~42~1~24 minecraft:carpet 15
fill ~43~0~23 ~43~0~25 minecraft:spruce_trapdoor 0
fill ~43~5~23 ~45~5~23 minecraft:barrel 1
setblock ~45~6~23 minecraft:lantern 0
setblock ~49~0~23 minecraft:dark_oak_door 2
fill ~3~0~24 ~6~1~24 minecraft:chest 2
setblock ~6~9~24 minecraft:jungle_trapdoor 3
fill ~7~0~24 ~7~1~25 minecraft:planks 1
setblock ~15~5~24 minecraft:dark_oak_stairs 5
setblock ~15~6~24 minecraft:flower_pot
setblock ~16~5~24 minecraft:spruce_trapdoor 2
fill ~16~6~24 ~17~6~24 minecraft:chest 3
setblock ~17~5~24 minecraft:dark_oak_stairs 4
fill ~19~0~24 ~19~2~24 minecraft:dark_oak_stairs 7
setblock ~21~14~24 minecraft:deepslate_bricks
setblock ~22~15~24 minecraft:fence 5
setblock ~22~18~24 minecraft:lantern 1
setblock ~22~19~24 minecraft:dark_oak_stairs 0
fill ~22~20~24 ~22~20~30 minecraft:dark_oak_stairs 4
setblock ~22~21~24 minecraft:deepslate_brick_stairs 7
setblock ~22~22~24 minecraft:deepslate_brick_stairs 2
setblock ~23~5~24 minecraft:dirt 0
setblock ~23~6~24 minecraft:barrel 0
fill ~23~7~24 ~33~7~24 minecraft:log 1
setblock ~23~10~24 minecraft:stonecutter_block 5
setblock ~23~15~24 minecraft:planks 1
fill ~23~16~24 ~23~18~24 minecraft:glass_pane
setblock ~23~19~24 minecraft:planks 1
fill ~23~20~24 ~24~20~24 minecraft:log 1
fill ~23~21~24 ~23~21~25 minecraft:fence 4
fill ~23~22~24 ~25~22~24 minecraft:dark_oak_stairs 2
fill ~24~5~24 ~24~5~30 minecraft:spruce_trapdoor 0
setblock ~24~9~24 minecraft:carpet 0
setblock ~24~15~24 minecraft:dark_oak_stairs 7
setblock ~24~16~24 minecraft:chest 5
setblock ~24~19~24 minecraft:dark_oak_fence_gate 1
setblock ~25~9~24 minecraft:carpet 5
setblock ~25~15~24 minecraft:carpet 14
setblock ~26~9~24 minecraft:carpet 0
fill ~26~14~24 ~26~14~32 minecraft:planks 1
setblock ~26~15~24 minecraft:carpet 10
setblock ~27~9~24 minecraft:carpet 5
setblock ~27~15~24 minecraft:carpet 14
setblock ~27~18~24 minecraft:glow_frame 3
setblock ~28~9~24 minecraft:dark_oak_stairs 3
setblock ~28~15~24 minecraft:carpet 10
setblock ~28~25~24 minecraft:deepslate_brick_slab 0
setblock ~29~9~24 minecraft:carpet 5
setblock ~29~15~24 minecraft:carpet 14
setblock ~29~18~24 minecraft:glow_frame 3
setblock ~30~9~24 minecraft:carpet 0
setblock ~30~15~24 minecraft:carpet 10
setblock ~31~9~24 minecraft:carpet 5
setblock ~31~15~24 minecraft:carpet 14
fill ~32~5~24 ~32~5~30 minecraft:spruce_trapdoor 1
setblock ~32~9~24 minecraft:carpet 0
setblock ~32~15~24 minecraft:dark_oak_stairs 7
setblock ~32~16~24 minecraft:chest 4
setblock ~32~19~24 minecraft:dark_oak_fence_gate 3
fill ~32~20~24 ~33~20~24 minecraft:log 1
fill ~32~22~24 ~33~22~24 minecraft:dark_oak_stairs 2
setblock ~33~5~24 minecraft:dirt 0
setblock ~33~6~24 minecraft:barrel 0
setblock ~33~10~24 minecraft:chest 4
setblock ~33~15~24 minecraft:planks 1
fill ~33~16~24 ~33~18~24 minecraft:glass_pane
setblock ~33~19~24 minecraft:planks 1
fill ~33~21~24 ~33~21~25 minecraft:fence 4
setblock ~34~15~24 minecraft:fence 5
setblock ~34~18~24 minecraft:lantern 1
setblock ~34~19~24 minecraft:dark_oak_stairs 1
fill ~34~20~24 ~34~20~30 minecraft:dark_oak_stairs 5
setblock ~34~21~24 minecraft:deepslate_brick_stairs 7
setblock ~34~22~24 minecraft:deepslate_brick_stairs 2
setblock ~35~6~24 minecraft:farmland 7
setblock ~35~7~24 minecraft:carrots 7
setblock ~35~14~24 minecraft:deepslate_bricks
fill ~37~0~24 ~37~2~24 minecraft:dark_oak_stairs 7
setblock ~39~5~24 minecraft:dark_oak_stairs 5
fill ~39~6~24 ~40~6~24 minecraft:chest 3
setblock ~40~5~24 minecraft:spruce_trapdoor 2
setblock ~41~5~24 minecraft:dark_oak_stairs 4
setblock ~41~6~24 minecraft:flower_pot
fill ~49~0~24 ~49~1~25 minecraft:planks 1
fill ~50~0~24 ~53~1~24 minecraft:chest 2
setblock ~50~9~24 minecraft:jungle_trapdoor 3
fill ~1~0~25 ~6~0~25 minecraft:log 1
setblock ~1~1~25 minecraft:deepslate_brick_wall 0
setblock ~2~1~25 minecraft:log 1
setblock ~2~2~25 minecraft:deepslate_brick_wall 0
fill ~3~1~25 ~5~1~25 minecraft:fence 5
setblock ~3~2~25 minecraft:log 1
setblock ~3~3~25 minecraft:deepslate_brick_wall 0
fill ~4~2~25 ~5~2~25 minecraft:fence 5
setblock ~4~3~25 minecraft:log 1
setblock ~4~4~25 minecraft:deepslate_brick_wall 0
setblock ~5~3~25 minecraft:fence 5
fill ~5~4~25 ~6~4~25 minecraft:log 1
setblock ~5~5~25 minecraft:deepslate_brick_wall 0
setblock ~5~9~25 minecraft:jungle_trapdoor 1
fill ~6~1~25 ~6~3~25 minecraft:log 1
setblock ~6~5~25 minecraft:log 1
setblock ~6~6~25 minecraft:deepslate_brick_wall 0
setblock ~6~7~25 minecraft:fence 5
setblock ~6~8~25 minecraft:deepslate_brick_wall 0
setblock ~6~9~25 minecraft:glowstone
setblock ~6~10~25 minecraft:deepslate_brick_slab 0
fill ~7~5~25 ~7~5~26 minecraft:blast_furnace 5
setblock ~7~9~25 minecraft:jungle_trapdoor 0
setblock ~8~0~25 minecraft:flower_pot
fill ~8~1~25 ~8~2~25 minecraft:leaves 0
setblock ~10~3~25 minecraft:lantern 1
setblock ~14~0~25 minecraft:planks 1
setblock ~14~1~25 minecraft:spruce_trapdoor 1
setblock ~15~0~25 minecraft:glowstone
setblock ~15~1~25 minecraft:carpet 15
setblock ~16~1~25 minecraft:spruce_trapdoor 1
setblock ~17~2~25 minecraft:lantern 0
setblock ~17~5~25 minecraft:deepslate_brick_wall 0
setblock ~17~6~25 minecraft:lantern 0
fill ~18~5~25 ~21~5~25 minecraft:log 1
setblock ~18~6~25 minecraft:deepslate_brick_wall 0
fill ~19~0~25 ~19~2~25 minecraft:dark_oak_stairs 6
fill ~19~6~25 ~21~6~25 minecraft:log 1
setblock ~19~7~25 minecraft:deepslate_brick_wall 0
setblock ~19~8~25 minecraft:lantern 0
fill ~20~7~25 ~21~7~25 minecraft:log 1
setblock ~20~8~25 minecraft:deepslate_brick_wall 0
setblock ~21~8~25 minecraft:log 1
setblock ~21~9~25 minecraft:deepslate_brick_wall 0
fill ~21~10~25 ~21~12~25 minecraft:fence 4
setblock ~21~13~25 minecraft:deepslate_brick_wall 0
fill ~21~14~25 ~21~15~25 minecraft:deepslate_brick_slab 0
setblock ~21~21~25 minecraft:dark_oak_trapdoor 1
fill ~22~5~25 ~22~5~32 minecraft:planks 1
fill ~22~9~25 ~22~15~25 minecraft:log 1
setblock ~22~16~25 minecraft:deepslate_brick_wall 0
fill ~22~17~25 ~22~18~25 minecraft:fence 4
setblock ~22~19~25 minecraft:deepslate_brick_wall 0
setblock ~22~21~25 minecraft:glowstone
setblock ~22~22~25 minecraft:deepslate_brick_stairs 7
setblock ~22~23~25 minecraft:deepslate_brick_stairs 2
fill ~23~5~25 ~23~5~29 minecraft:grass
fill ~23~6~25 ~23~6~29 minecraft:bamboo 1
fill ~23~7~25 ~23~7~29 minecraft:bamboo 1
setblock ~23~10~25 minecraft:loom 3
setblock ~23~12~25 minecraft:lantern 1
setblock ~23~13~25 minecraft:fence 5
fill ~23~15~25 ~23~20~25 minecraft:log 1
setblock ~23~22~25 minecraft:fence 4
fill ~23~23~25 ~26~23~25 minecraft:dark_oak_stairs 2
setblock ~24~9~25 minecraft:carpet 5
setblock ~24~15~25 minecraft:dark_oak_stairs 6
setblock ~24~16~25 minecraft:anvil 2
setblock ~24~18~25 minecraft:lantern 1
setblock ~24~19~25 minecraft:fence 5
fill ~24~20~25 ~24~20~30 minecraft:log 1
fill ~25~7~25 ~25~7~29 minecraft:log 1
setblock ~25~9~25 minecraft:carpet 0
setblock ~25~15~25 minecraft:carpet 10
fill ~26~6~25 ~30~6~29 minecraft:jungle_trapdoor 0
fill ~26~7~25 ~30~7~29 minecraft:glowstone
setblock ~26~9~25 minecraft:log 1
setblock ~26~10~25 minecraft:torch 5
fill ~26~15~25 ~27~15~25 minecraft:bookshelf
setblock ~26~16~25 minecraft:bookshelf
setblock ~26~17~25 minecraft:light_blue_candle 2
fill ~27~9~25 ~27~9~26 minecraft:wooden_slab 9
setblock ~27~10~25 minecraft:flower_pot
setblock ~27~16~25 minecraft:fence 5
setblock ~28~9~25 minecraft:wooden_slab 13
setblock ~28~15~25 minecraft:dark_oak_fence_gate 2
setblock ~28~25~25 minecraft:deepslate_brick_double_slab 0
fill ~29~9~25 ~29~9~26 minecraft:wooden_slab 9
fill ~29~15~25 ~30~15~25 minecraft:bookshelf
setblock ~29~16~25 minecraft:fence 5
setblock ~30~9~25 minecraft:log 1
setblock ~30~10~25 minecraft:torch 5
setblock ~30~16~25 minecraft:bookshelf
setblock ~30~17~25 minecraft:light_blue_candle 2
fill ~30~23~25 ~33~23~25 minecraft:dark_oak_stairs 2
fill ~31~7~25 ~31~7~29 minecraft:log 1
setblock ~31~9~25 minecraft:carpet 0
setblock ~31~15~25 minecraft:carpet 10
setblock ~32~9~25 minecraft:carpet 5
setblock ~32~15~25 minecraft:dark_oak_stairs 6
setblock ~32~16~25 minecraft:flower_pot
setblock ~32~18~25 minecraft:lantern 1
setblock ~32~19~25 minecraft:fence 5
fill ~32~20~25 ~32~20~30 minecraft:log 1
fill ~33~5~25 ~33~5~29 minecraft:grass
fill ~33~6~25 ~33~6~29 minecraft:bamboo 1
fill ~33~7~25 ~33~7~29 minecraft:bamboo 1
setblock ~33~10~25 minecraft:ender_chest 4
setblock ~33~12~25 minecraft:lantern 1
setblock ~33~13~25 minecraft:fence 5
fill ~33~15~25 ~34~15~25 minecraft:log 1
fill ~33~16~25 ~33~20~25 minecraft:log 1
setblock ~33~22~25 minecraft:fence 4
fill ~34~5~25 ~34~5~32 minecraft:planks 1
fill ~34~9~25 ~34~14~25 minecraft:log 1
setblock ~34~16~25 minecraft:deepslate_brick_wall 0
fill ~34~17~25 ~34~18~25 minecraft:fence 4
setblock ~34~19~25 minecraft:deepslate_brick_wall 0
setblock ~34~21~25 minecraft:glowstone
setblock ~34~22~25 minecraft:deepslate_brick_stairs 7
setblock ~34~23~25 minecraft:deepslate_brick_stairs 2
fill ~35~5~25 ~38~5~25 minecraft:log 1
fill ~35~6~25 ~37~6~25 minecraft:log 1
fill ~35~7~25 ~36~7~25 minecraft:log 1
setblock ~35~8~25 minecraft:log 1
setblock ~35~9~25 minecraft:deepslate_brick_wall 0
fill ~35~10~25 ~35~12~25 minecraft:fence 4
setblock ~35~13~25 minecraft:deepslate_brick_wall 0
fill ~35~14~25 ~35~15~25 minecraft:deepslate_brick_slab 0
setblock ~35~21~25 minecraft:dark_oak_trapdoor 0
setblock ~36~8~25 minecraft:deepslate_brick_wall 0
fill ~37~0~25 ~37~2~25 minecraft:dark_oak_stairs 6
setblock ~37~7~25 minecraft:deepslate_brick_wall 0
setblock ~37~8~25 minecraft:lantern 0
setblock ~38~6~25 minecraft:deepslate_brick_wall 0
setblock ~39~2~25 minecraft:lantern 0
setblock ~39~5~25 minecraft:deepslate_brick_wall 0
setblock ~39~6~25 minecraft:lantern 0
setblock ~40~1~25 minecraft:spruce_trapdoor 0
setblock ~41~0~25 minecraft:glowstone
setblock ~41~1~25 minecraft:carpet 15
setblock ~42~0~25 minecraft:planks 1
setblock ~42~1~25 minecraft:spruce_trapdoor 0
setblock ~46~3~25 minecraft:lantern 1
setblock ~48~0~25 minecraft:flower_pot
fill ~48~1~25 ~48~2~25 minecraft:leaves 0
fill ~49~5~25 ~49~5~26 minecraft:smoker 4
setblock ~49~9~25 minecraft:jungle_trapdoor 1
fill ~50~0~25 ~55~0~25 minecraft:log 1
fill ~50~1~25 ~50~5~25 minecraft:log 1
setblock ~50~6~25 minecraft:deepslate_brick_wall 0
setblock ~50~7~25 minecraft:fence 5
setblock ~50~8~25 minecraft:deepslate_brick_wall 0
setblock ~50~9~25 minecraft:glowstone
setblock ~50~10~25 minecraft:deepslate_brick_slab 0
fill ~51~1~25 ~53~1~25 minecraft:fence 5
fill ~51~2~25 ~52~2~25 minecraft:fence 5
setblock ~51~3~25 minecraft:fence 5
setblock ~51~4~25 minecraft:log 1
setblock ~51~5~25 minecraft:deepslate_brick_wall 0
setblock ~51~9~25 minecraft:jungle_trapdoor 0
setblock ~52~3~25 minecraft:log 1
setblock ~52~4~25 minecraft:deepslate_brick_wall 0
setblock ~52~5~25 minecraft:lantern 0
setblock ~53~2~25 minecraft:log 1
setblock ~53~3~25 minecraft:deepslate_brick_wall 0
setblock ~54~1~25 minecraft:log 1
setblock ~54~2~25 minecraft:deepslate_brick_wall 0
setblock ~54~3~25 minecraft:lantern 0
setblock ~55~1~25 minecraft:deepslate_brick_wall 0
setblock ~56~0~25 minecraft:deepslate_brick_wall 0
setblock ~56~1~25 minecraft:lantern 0
fill ~5~3~26 ~5~3~28 minecraft:dark_oak_stairs 0
fill ~5~4~26 ~5~4~28 minecraft:trapdoor 1
setblock ~6~0~26 minecraft:deepslate_brick_wall 0
setblock ~6~1~26 minecraft:fence 5
setblock ~6~2~26 minecraft:deepslate_brick_wall 0
fill ~6~3~26 ~6~3~28 minecraft:log 1
fill ~6~4~26 ~6~4~28 minecraft:glowstone
fill ~6~5~26 ~6~5~28 minecraft:leaves 0
setblock ~6~9~26 minecraft:jungle_trapdoor 2
fill ~7~0~26 ~7~3~26 minecraft:stripped_spruce_log 0
fill ~8~0~26 ~8~1~26 minecraft:fence 5
fill ~8~2~26 ~8~2~28 minecraft:dark_oak_stairs 1
fill ~14~0~26 ~17~0~26 minecraft:spruce_trapdoor 2
fill ~18~0~26 ~18~3~26 minecraft:log 1
fill ~18~5~26 ~18~5~28 minecraft:spruce_stairs 0
fill ~19~6~26 ~19~6~28 minecraft:spruce_stairs 0
setblock ~20~5~26 minecraft:torch 5
fill ~20~7~26 ~20~7~28 minecraft:spruce_stairs 0
fill ~21~8~26 ~21~8~28 minecraft:spruce_stairs 0
fill ~21~12~26 ~21~12~28 minecraft:dark_oak_stairs 0
fill ~21~13~26 ~21~13~28 minecraft:trapdoor 1
setblock ~21~14~26 minecraft:deepslate_bricks
setblock ~22~9~26 minecraft:deepslate_brick_wall 0
setblock ~22~10~26 minecraft:fence 5
setblock ~22~11~26 minecraft:deepslate_brick_wall 0
fill ~22~12~26 ~22~12~28 minecraft:log 1
fill ~22~13~26 ~22~13~28 minecraft:glowstone
fill ~22~14~26 ~22~14~28 minecraft:log 1
setblock ~22~15~26 minecraft:fence 5
setblock ~22~21~26 minecraft:deepslate_brick_wall 0
setblock ~22~22~26 minecraft:fence 1
setblock ~22~23~26 minecraft:deepslate_brick_stairs 7
setblock ~22~24~26 minecraft:deepslate_brick_stairs 2
fill ~23~9~26 ~23~13~26 minecraft:stripped_spruce_log 0
setblock ~23~15~26 minecraft:dark_oak_stairs 4
setblock ~23~16~26 minecraft:deepslate_brick_wall 0
setblock ~23~17~26 minecraft:fence 5
setblock ~23~18~26 minecraft:deepslate_brick_wall 0
fill ~23~19~26 ~23~19~28 minecraft:dark_oak_stairs 0
fill ~23~20~26 ~23~20~28 minecraft:log 1
fill ~23~21~26 ~23~23~26 minecraft:log 1
fill ~23~24~26 ~27~24~26 minecraft:dark_oak_stairs 2
setblock ~24~9~26 minecraft:carpet 0
fill ~24~15~26 ~24~19~26 minecraft:stripped_spruce_log 0
setblock ~25~9~26 minecraft:carpet 5
setblock ~25~15~26 minecraft:carpet 14
setblock ~25~18~26 minecraft:glow_frame 3
setblock ~26~9~26 minecraft:wooden_slab 9
setblock ~26~15~26 minecraft:bookshelf
setblock ~26~16~26 minecraft:fence 5
setblock ~27~10~26 minecraft:spruce_trapdoor 3
setblock ~27~15~26 minecraft:carpet 14
setblock ~28~9~26 minecraft:glowstone
setblock ~28~10~26 minecraft:carpet 2
setblock ~28~13~26 minecraft:dark_oak_stairs 6
setblock ~28~15~26 minecraft:carpet 10
setblock ~28~25~26 minecraft:deepslate_brick_slab 0
setblock ~29~10~26 minecraft:spruce_trapdoor 3
setblock ~29~15~26 minecraft:carpet 14
setblock ~30~9~26 minecraft:wooden_slab 9
setblock ~30~15~26 minecraft:bookshelf
setblock ~30~16~26 minecraft:fence 5
fill ~30~24~26 ~33~24~26 minecraft:dark_oak_stairs 2
setblock ~31~9~26 minecraft:carpet 5
setblock ~31~15~26 minecraft:carpet 14
setblock ~31~18~26 minecraft:glow_frame 4
setblock ~32~9~26 minecraft:carpet 0
fill ~32~15~26 ~32~19~26 minecraft:stripped_spruce_log 0
fill ~33~9~26 ~33~13~26 minecraft:stripped_spruce_log 0
setblock ~33~15~26 minecraft:dark_oak_stairs 5
setblock ~33~16~26 minecraft:deepslate_brick_wall 0
setblock ~33~17~26 minecraft:fence 5
setblock ~33~18~26 minecraft:deepslate_brick_wall 0
fill ~33~19~26 ~33~19~28 minecraft:dark_oak_stairs 1
fill ~33~20~26 ~33~20~28 minecraft:log 1
fill ~33~21~26 ~33~23~26 minecraft:log 1
setblock ~34~9~26 minecraft:deepslate_brick_wall 0
setblock ~34~10~26 minecraft:fence 5
setblock ~34~11~26 minecraft:deepslate_brick_wall 0
fill ~34~12~26 ~34~12~28 minecraft:log 1
fill ~34~13~26 ~34~13~28 minecraft:glowstone
fill ~34~14~26 ~34~14~28 minecraft:log 1
setblock ~34~15~26 minecraft:fence 5
setblock ~34~21~26 minecraft:deepslate_brick_wall 0
setblock ~34~22~26 minecraft:fence 1
setblock ~34~23~26 minecraft:deepslate_brick_stairs 7
setblock ~34~24~26 minecraft:deepslate_brick_stairs 2
fill ~35~8~26 ~35~8~28 minecraft:spruce_stairs 1
fill ~35~12~26 ~35~12~28 minecraft:dark_oak_stairs 1
fill ~35~13~26 ~35~13~28 minecraft:trapdoor 0
setblock ~35~14~26 minecraft:deepslate_bricks
fill ~36~7~26 ~36~7~28 minecraft:spruce_stairs 1
setblock ~37~5~26 minecraft:torch 5
fill ~37~6~26 ~37~6~28 minecraft:spruce_stairs 1
fill ~38~0~26 ~38~3~26 minecraft:log 1
fill ~38~5~26 ~38~5~28 minecraft:spruce_stairs 1
fill ~39~0~26 ~42~0~26 minecraft:spruce_trapdoor 2
fill ~48~0~26 ~48~1~26 minecraft:fence 5
fill ~48~2~26 ~48~2~28 minecraft:dark_oak_stairs 0
fill ~49~0~26 ~49~3~26 minecraft:stripped_spruce_log 0
setblock ~50~0~26 minecraft:deepslate_brick_wall 0
setblock ~50~1~26 minecraft:fence 5
setblock ~50~2~26 minecraft:deepslate_brick_wall 0
fill ~50~3~26 ~50~3~28 minecraft:log 1
fill ~50~4~26 ~50~4~28 minecraft:glowstone
fill ~50~5~26 ~50~5~28 minecraft:leaves 0
setblock ~50~9~26 minecraft:jungle_trapdoor 2
fill ~51~3~26 ~51~3~28 minecraft:dark_oak_stairs 1
fill ~51~4~26 ~51~4~28 minecraft:trapdoor 0
setblock ~5~2~27 minecraft:lantern 1
setblock ~6~2~27 minecraft:dark_oak_stairs 4
setblock ~7~0~27 minecraft:dark_oak_door 2
setblock ~7~2~27 minecraft:stripped_spruce_log 2
setblock ~7~3~27 minecraft:lantern 0
setblock ~7~5~27 minecraft:crafting_table
setblock ~8~3~27 minecraft:jungle_trapdoor 0
setblock ~17~3~27 minecraft:jungle_trapdoor 1
setblock ~18~0~27 minecraft:spruce_door 2
setblock ~18~2~27 minecraft:log 1
setblock ~18~3~27 minecraft:lantern 0
setblock ~19~3~27 minecraft:jungle_trapdoor 0
setblock ~21~11~27 minecraft:lantern 1
setblock ~21~14~27 minecraft:deepslate_brick_slab 0
setblock ~22~11~27 minecraft:dark_oak_stairs 0
setblock ~22~15~27 minecraft:dark_oak_fence_gate 3
setblock ~22~21~27 minecraft:lantern 0
setblock ~22~24~27 minecraft:deepslate_brick_slab 0
setblock ~22~25~27 minecraft:deepslate_brick_double_slab 0
setblock ~23~9~27 minecraft:dark_oak_door 2
setblock ~23~11~27 minecraft:stripped_spruce_log 2
setblock ~23~12~27 minecraft:lantern 0
setblock ~23~13~27 minecraft:trapdoor 0
setblock ~23~15~27 minecraft:glowstone
setblock ~23~18~27 minecraft:lantern 1
setblock ~23~21~27 minecraft:deepslate_bricks
setblock ~23~22~27 minecraft:fence 4
setblock ~23~23~27 minecraft:deepslate_bricks
fill ~23~24~27 ~24~24~27 minecraft:log 1
setblock ~23~25~27 minecraft:deepslate_brick_slab 0
setblock ~24~7~27 minecraft:lantern 1
setblock ~24~9~27 minecraft:carpet 5
setblock ~24~15~27 minecraft:stripped_spruce_log 2
fill ~24~16~27 ~24~18~27 minecraft:glass_pane
setblock ~24~19~27 minecraft:stripped_spruce_log 2
setblock ~24~22~27 minecraft:lantern 1
setblock ~24~23~27 minecraft:deepslate_brick_wall 0
setblock ~24~25~27 minecraft:deepslate_brick_double_slab 0
setblock ~25~9~27 minecraft:dark_oak_stairs 1
setblock ~25~15~27 minecraft:carpet 10
setblock ~25~25~27 minecraft:deepslate_brick_slab 0
setblock ~26~9~27 minecraft:wooden_slab 13
setblock ~26~15~27 minecraft:dark_oak_fence_gate 1
setblock ~26~25~27 minecraft:deepslate_brick_double_slab 0
setblock ~27~9~27 minecraft:glowstone
setblock ~27~10~27 minecraft:carpet 2
setblock ~27~13~27 minecraft:dark_oak_stairs 4
setblock ~27~15~27 minecraft:carpet 10
setblock ~27~25~27 minecraft:deepslate_brick_slab 0
setblock ~28~9~27 minecraft:grass
setblock ~28~10~27 minecraft:sweet_berry_bush 3
setblock ~28~12~27 minecraft:jungle_trapdoor 3
setblock ~28~13~27 minecraft:glowstone
setblock ~28~15~27 minecraft:enchanting_table
setblock ~28~21~27 minecraft:lantern 1
fill ~28~22~27 ~28~23~27 minecraft:chain 0
setblock ~28~24~27 minecraft:deepslate_brick_wall 0
setblock ~28~25~27 minecraft:deepslate_brick_double_slab 0
setblock ~29~9~27 minecraft:glowstone
setblock ~29~10~27 minecraft:carpet 2
setblock ~29~13~27 minecraft:dark_oak_stairs 5
setblock ~29~15~27 minecraft:carpet 10
setblock ~29~25~27 minecraft:deepslate_brick_slab 0
setblock ~30~9~27 minecraft:wooden_slab 13
setblock ~30~15~27 minecraft:dark_oak_fence_gate 3
setblock ~30~25~27 minecraft:deepslate_brick_double_slab 0
setblock ~31~9~27 minecraft:dark_oak_stairs 0
