setblock ~9 ~0 ~25 chest 3  
setblock ~10 ~0 ~25 chest 3  
setblock ~9 ~0 ~37 chest 2  
setblock ~10 ~0 ~37 chest 2  
fill ~1 ~-1 ~0 ~1 ~-1 ~25 grass 0  
fill ~1 ~-1 ~26 ~1 ~-1 ~27 dirt 0  
fill ~1 ~-1 ~28 ~62 ~-1 ~28 planks 0  
fill ~1 ~-1 ~29 ~62 ~-1 ~29 planks 0  
fill ~1 ~-1 ~30 ~62 ~-1 ~30 planks 0  
fill ~1 ~-1 ~31 ~62 ~-1 ~31 planks 0  
fill ~1 ~-1 ~32 ~62 ~-1 ~32 planks 0  
fill ~1 ~-1 ~33 ~62 ~-1 ~33 planks 0  
fill ~1 ~-1 ~34 ~62 ~-1 ~34 planks 0 
setblock ~1 ~-1 ~35 dirt 0  
fill ~1 ~-1 ~36 ~1 ~6 ~36 stained_hardened_clay 13  
fill ~1 ~-1 ~37 ~1 ~-1 ~61 grass 0 
setblock ~1 ~-1 ~62 dirt 0 
setblock ~2 ~-1 ~0 dirt 0  
fill ~2 ~-1 ~1 ~22 ~-1 ~1 grass 0  
fill ~2 ~-1 ~2 ~19 ~-1 ~2 grass 0  
fill ~2 ~-1 ~3 ~17 ~-1 ~3 grass 0  
fill ~2 ~-1 ~4 ~15 ~-1 ~4 grass 0  
fill ~2 ~-1 ~5 ~14 ~-1 ~5 grass 0  
fill ~2 ~-1 ~6 ~12 ~-1 ~6 grass 0  
fill ~2 ~-1 ~7 ~11 ~-1 ~7 grass 0  
fill ~2 ~-1 ~8 ~10 ~-1 ~8 grass 0  
fill ~2 ~-1 ~9 ~9 ~-1 ~9 grass 0  
fill ~2 ~-1 ~10 ~8 ~-1 ~10 grass 0  
fill ~2 ~-1 ~11 ~7 ~-1 ~11 grass 0  
fill ~2 ~-1 ~12 ~6 ~-1 ~12 grass 0  
fill ~2 ~-1 ~13 ~6 ~-1 ~13 grass 0  
fill ~2 ~-1 ~14 ~5 ~-1 ~14 grass 0  
fill ~2 ~-1 ~15 ~4 ~-1 ~15 grass 0  
fill ~2 ~-1 ~16 ~4 ~-1 ~16 grass 0  
fill ~2 ~-1 ~17 ~3 ~-1 ~17 grass 0  
fill ~2 ~-1 ~18 ~3 ~-1 ~18 grass 0  
fill ~2 ~-1 ~19 ~2 ~-1 ~21 grass 0  
fill ~2 ~-1 ~22 ~2 ~-1 ~25 dirt 0  
fill ~2 ~-1 ~26 ~62 ~-1 ~26 planks 0  
fill ~2 ~-1 ~27 ~62 ~-1 ~27 planks 0  
fill ~2 ~-1 ~35 ~62 ~-1 ~35 planks 0  
fill ~2 ~-1 ~36 ~62 ~-1 ~36 planks 0  
fill ~2 ~-1 ~37 ~2 ~-1 ~40 dirt 0  
fill ~2 ~-1 ~41 ~2 ~-1 ~62 grass 0  
fill ~3 ~-1 ~0 ~26 ~-1 ~0 grass 0  
fill ~3 ~-1 ~19 ~3 ~-1 ~21 dirt 0  
fill ~3 ~-1 ~22 ~6 ~-1 ~22 planks 0  
fill ~3 ~-1 ~23 ~61 ~-1 ~23 planks 0  
fill ~3 ~-1 ~24 ~61 ~-1 ~24 planks 0  
fill ~3 ~-1 ~25 ~3 ~-1 ~22 planks 0  
fill ~3 ~-1 ~37 ~3 ~-1 ~40 planks 0  
fill ~3 ~-1 ~41 ~3 ~-1 ~43 dirt 0  
fill ~3 ~-1 ~44 ~3 ~-1 ~62 grass 0  
fill ~4 ~-1 ~17 ~4 ~-1 ~18 dirt 0  
fill ~4 ~-1 ~19 ~9 ~-1 ~19 planks 0  
fill ~4 ~-1 ~20 ~4 ~-1 ~24 planks 0 
setblock ~4 ~-1 ~25 glowstone 0 
setblock ~4 ~-1 ~37 glowstone 0  
fill ~4 ~-1 ~38 ~61 ~-1 ~38 planks 0  
fill ~4 ~-1 ~39 ~61 ~-1 ~39 planks 0  
fill ~4 ~-1 ~40 ~61 ~-1 ~40 planks 0  
fill ~4 ~-1 ~41 ~60 ~-1 ~41 planks 0  
fill ~4 ~-1 ~42 ~60 ~-1 ~42 planks 0  
fill ~4 ~-1 ~43 ~60 ~-1 ~43 planks 0  
fill ~4 ~-1 ~44 ~4 ~-1 ~45 dirt 0  
fill ~4 ~-1 ~46 ~4 ~-1 ~62 grass 0  
fill ~5 ~-1 ~15 ~6 ~-1 ~15 dirt 0  
fill ~5 ~-1 ~16 ~5 ~-1 ~15 dirt 0  
fill ~5 ~-1 ~17 ~20 ~-1 ~17 planks 0  
fill ~5 ~-1 ~18 ~5 ~-1 ~17 planks 0 
setblock ~5 ~-1 ~20 wool 13  
fill ~5 ~-1 ~21 ~60 ~-1 ~21 planks 0  
fill ~5 ~-1 ~25 ~61 ~-1 ~25 planks 0  
fill ~5 ~-1 ~37 ~61 ~-1 ~37 planks 0  
fill ~5 ~-1 ~44 ~59 ~-1 ~44 planks 0  
fill ~5 ~-1 ~45 ~59 ~-1 ~45 planks 0  
fill ~5 ~-1 ~46 ~5 ~-1 ~47 dirt 0  
fill ~5 ~-1 ~48 ~5 ~-1 ~62 grass 0 
setblock ~6 ~-1 ~14 dirt 0  
fill ~6 ~-1 ~16 ~8 ~-1 ~16 planks 0 
setblock ~6 ~-1 ~18 wool 13  
fill ~6 ~-1 ~20 ~16 ~-1 ~20 planks 0  
fill ~6 ~-1 ~46 ~6 ~-1 ~47 planks 0 
setblock ~6 ~-1 ~48 dirt 0  
fill ~6 ~-1 ~49 ~6 ~-1 ~62 grass 0  
fill ~7 ~-1 ~12 ~7 ~-1 ~13 dirt 0  
fill ~7 ~-1 ~14 ~13 ~-1 ~14 planks 0  
fill ~7 ~-1 ~15 ~13 ~-1 ~15 planks 0  
fill ~7 ~-1 ~18 ~12 ~-1 ~18 planks 0 
setblock ~7 ~-1 ~22 wool 13 
setblock ~7 ~-1 ~46 wool 13  
fill ~7 ~-1 ~47 ~57 ~-1 ~47 planks 0  
fill ~7 ~-1 ~48 ~7 ~-1 ~47 planks 0  
fill ~7 ~-1 ~49 ~7 ~-1 ~50 dirt 0  
fill ~7 ~-1 ~51 ~7 ~-1 ~62 grass 0 
setblock ~8 ~-1 ~11 dirt 0  
fill ~8 ~-1 ~12 ~8 ~-1 ~47 planks 0  
fill ~8 ~-1 ~48 ~8 ~-1 ~49 wool 13  
fill ~8 ~-1 ~50 ~55 ~-1 ~50 planks 0 
setblock ~8 ~-1 ~51 dirt 0  
fill ~8 ~-1 ~52 ~8 ~-1 ~62 grass 0 
setblock ~9 ~-1 ~10 dirt 0  
fill ~9 ~-1 ~11 ~11 ~-1 ~11 planks 0  
fill ~9 ~-1 ~12 ~10 ~-1 ~12 wool 13  
fill ~9 ~-1 ~13 ~14 ~-1 ~13 planks 0 
setblock ~9 ~-1 ~16 wool 13  
fill ~9 ~-1 ~22 ~61 ~-1 ~22 planks 0  
fill ~9 ~-1 ~46 ~58 ~-1 ~46 planks 0  
fill ~9 ~-1 ~48 ~57 ~-1 ~48 planks 0  
fill ~9 ~-1 ~49 ~56 ~-1 ~49 planks 0  
fill ~9 ~-1 ~51 ~55 ~-1 ~51 planks 0 
setblock ~9 ~-1 ~52 dirt 0  
fill ~9 ~-1 ~53 ~9 ~-1 ~62 grass 0 
setblock ~10 ~-1 ~9 dirt 0  
fill ~10 ~-1 ~10 ~17 ~-1 ~10 planks 0  
fill ~10 ~-1 ~16 ~15 ~-1 ~16 planks 0 
setblock ~10 ~-1 ~19 wool 13  
fill ~10 ~-1 ~52 ~54 ~-1 ~52 planks 0 
setblock ~10 ~-1 ~53 dirt 0  
fill ~10 ~-1 ~54 ~10 ~-1 ~62 grass 0 
setblock ~11 ~-1 ~8 dirt 0  
fill ~11 ~-1 ~9 ~19 ~-1 ~9 planks 0  
fill ~11 ~-1 ~12 ~18 ~-1 ~12 planks 0  
fill ~11 ~-1 ~19 ~14 ~-1 ~19 planks 0  
fill ~11 ~-1 ~53 ~53 ~-1 ~53 planks 0 
setblock ~11 ~-1 ~54 dirt 0  
fill ~11 ~-1 ~55 ~11 ~-1 ~62 grass 0 
setblock ~12 ~-1 ~7 dirt 0 
setblock ~12 ~-1 ~8 planks 0 
setblock ~12 ~-1 ~11 wool 13  
fill ~12 ~-1 ~54 ~52 ~-1 ~54 planks 0 
setblock ~12 ~-1 ~55 dirt 0  
fill ~12 ~-1 ~56 ~12 ~-1 ~62 grass 0  
fill ~13 ~-1 ~6 ~14 ~-1 ~6 dirt 0  
fill ~13 ~-1 ~7 ~50 ~-1 ~7 planks 0 
setblock ~13 ~-1 ~8 wool 13  
fill ~13 ~-1 ~11 ~55 ~-1 ~11 planks 0 
setblock ~13 ~-1 ~18 wool 13  
fill ~13 ~-1 ~55 ~50 ~-1 ~55 planks 0  
fill ~13 ~-1 ~56 ~14 ~-1 ~56 dirt 0  
fill ~13 ~-1 ~57 ~14 ~-1 ~57 grass 0  
fill ~13 ~-1 ~58 ~15 ~-1 ~58 grass 0  
fill ~13 ~-1 ~59 ~17 ~-1 ~59 grass 0  
fill ~13 ~-1 ~60 ~19 ~-1 ~60 grass 0  
fill ~13 ~-1 ~61 ~22 ~-1 ~61 grass 0  
fill ~13 ~-1 ~62 ~26 ~-1 ~62 grass 0  
fill ~14 ~-1 ~8 ~16 ~-1 ~8 planks 0  
fill ~14 ~-1 ~14 ~17 ~-1 ~14 wool 13  
fill ~14 ~-1 ~15 ~16 ~-1 ~15 wool 13  
fill ~14 ~-1 ~18 ~59 ~-1 ~18 planks 0  
fill ~15 ~-1 ~5 ~16 ~-1 ~5 dirt 0  
fill ~15 ~-1 ~6 ~22 ~-1 ~6 planks 0  
fill ~15 ~-1 ~13 ~16 ~-1 ~13 wool 13 
setblock ~15 ~-1 ~19 wool 13  
fill ~15 ~-1 ~56 ~49 ~-1 ~56 planks 0 
setblock ~15 ~-1 ~57 dirt 0  
fill ~16 ~-1 ~4 ~17 ~-1 ~4 dirt 0 
setblock ~16 ~-1 ~16 wool 13  
fill ~16 ~-1 ~19 ~20 ~-1 ~19 planks 0  
fill ~16 ~-1 ~57 ~47 ~-1 ~57 planks 0  
fill ~16 ~-1 ~58 ~17 ~-1 ~58 dirt 0 
setblock ~17 ~-1 ~5 planks 0 
setblock ~17 ~-1 ~8 wool 13  
fill ~17 ~-1 ~13 ~56 ~-1 ~13 planks 0  
fill ~17 ~-1 ~15 ~57 ~-1 ~15 planks 0  
fill ~17 ~-1 ~16 ~20 ~-1 ~16 planks 0 
setblock ~17 ~-1 ~20 wool 13  
fill ~18 ~-1 ~3 ~19 ~-1 ~3 dirt 0  
fill ~18 ~-1 ~4 ~20 ~-1 ~4 planks 0  
fill ~18 ~-1 ~5 ~19 ~-1 ~5 wool 13  
fill ~18 ~-1 ~8 ~52 ~-1 ~8 planks 0 
setblock ~18 ~-1 ~10 wool 13  
fill ~18 ~-1 ~14 ~19 ~-1 ~14 planks 0  
fill ~18 ~-1 ~20 ~60 ~-1 ~20 planks 0  
fill ~18 ~-1 ~58 ~46 ~-1 ~58 planks 0  
fill ~18 ~-1 ~59 ~19 ~-1 ~59 dirt 0  
fill ~19 ~-1 ~10 ~54 ~-1 ~10 planks 0 
setblock ~19 ~-1 ~12 wool 13  
fill ~20 ~-1 ~2 ~22 ~-1 ~2 dirt 0  
fill ~20 ~-1 ~3 ~44 ~-1 ~3 planks 0  
fill ~20 ~-1 ~5 ~47 ~-1 ~5 planks 0 
setblock ~20 ~-1 ~9 wool 13  
fill ~20 ~-1 ~12 ~55 ~-1 ~12 planks 0 
setblock ~20 ~-1 ~14 wool 13  
fill ~20 ~-1 ~59 ~44 ~-1 ~59 planks 0  
fill ~20 ~-1 ~60 ~22 ~-1 ~60 dirt 0 
setblock ~21 ~-1 ~4 wool 13  
fill ~21 ~-1 ~9 ~53 ~-1 ~9 planks 0  
fill ~21 ~-1 ~14 ~57 ~-1 ~14 planks 0  
fill ~21 ~-1 ~16 ~21 ~-1 ~17 wool 13 
setblock ~21 ~-1 ~19 wool 13  
fill ~22 ~-1 ~4 ~46 ~-1 ~4 planks 0  
fill ~22 ~-1 ~16 ~58 ~-1 ~16 planks 0  
fill ~22 ~-1 ~17 ~59 ~-1 ~17 planks 0  
fill ~22 ~-1 ~19 ~60 ~-1 ~19 planks 0  
fill ~23 ~-1 ~1 ~26 ~-1 ~1 dirt 0  
fill ~23 ~-1 ~2 ~41 ~-1 ~2 planks 0 
setblock ~23 ~-1 ~6 wool 13  
fill ~23 ~-1 ~60 ~41 ~-1 ~60 planks 0  
fill ~23 ~-1 ~61 ~26 ~-1 ~61 dirt 0  
fill ~24 ~-1 ~6 ~49 ~-1 ~6 planks 0  
fill ~27 ~-1 ~0 ~37 ~-1 ~0 dirt 0  
fill ~27 ~-1 ~1 ~37 ~-1 ~1 planks 0  
fill ~27 ~-1 ~61 ~37 ~-1 ~61 planks 0  
fill ~27 ~-1 ~62 ~37 ~-1 ~62 dirt 0  
fill ~38 ~-1 ~0 ~62 ~-1 ~0 grass 0  
fill ~38 ~-1 ~1 ~41 ~-1 ~1 dirt 0  
fill ~38 ~-1 ~61 ~41 ~-1 ~61 dirt 0  
fill ~38 ~-1 ~62 ~61 ~-1 ~62 grass 0  
fill ~42 ~-1 ~1 ~63 ~-1 ~1 grass 0  
fill ~42 ~-1 ~2 ~44 ~-1 ~2 dirt 0  
fill ~42 ~-1 ~60 ~44 ~-1 ~60 dirt 0  
fill ~42 ~-1 ~61 ~63 ~-1 ~61 grass 0  
fill ~45 ~-1 ~2 ~63 ~-1 ~2 grass 0  
fill ~45 ~-1 ~3 ~46 ~-1 ~3 dirt 0  
fill ~45 ~-1 ~59 ~46 ~-1 ~59 dirt 0  
fill ~45 ~-1 ~60 ~63 ~-1 ~60 grass 0  
fill ~47 ~-1 ~3 ~63 ~-1 ~3 grass 0  
fill ~47 ~-1 ~4 ~48 ~-1 ~4 dirt 0  
fill ~47 ~-1 ~58 ~48 ~-1 ~58 dirt 0  
fill ~47 ~-1 ~59 ~63 ~-1 ~59 grass 0  
fill ~48 ~-1 ~5 ~49 ~-1 ~5 dirt 0  
fill ~48 ~-1 ~57 ~49 ~-1 ~57 dirt 0  
fill ~49 ~-1 ~4 ~63 ~-1 ~4 grass 0  
fill ~49 ~-1 ~58 ~63 ~-1 ~58 grass 0  
fill ~50 ~-1 ~5 ~63 ~-1 ~5 grass 0  
fill ~50 ~-1 ~6 ~51 ~-1 ~6 dirt 0  
fill ~50 ~-1 ~56 ~51 ~-1 ~56 dirt 0  
fill ~50 ~-1 ~57 ~63 ~-1 ~57 grass 0 
setblock ~51 ~-1 ~7 grass 0 
setblock ~51 ~-1 ~55 grass 0  
fill ~52 ~-1 ~6 ~63 ~-1 ~6 grass 0 
setblock ~52 ~-1 ~7 dirt 0 
setblock ~52 ~-1 ~55 dirt 0  
fill ~52 ~-1 ~56 ~63 ~-1 ~56 grass 0  
fill ~53 ~-1 ~7 ~63 ~-1 ~7 grass 0 
setblock ~53 ~-1 ~8 dirt 0 
setblock ~53 ~-1 ~54 dirt 0  
fill ~53 ~-1 ~55 ~63 ~-1 ~55 grass 0  
fill ~54 ~-1 ~8 ~63 ~-1 ~8 grass 0 
setblock ~54 ~-1 ~9 dirt 0 
setblock ~54 ~-1 ~53 dirt 0  
fill ~54 ~-1 ~54 ~63 ~-1 ~54 grass 0  
fill ~55 ~-1 ~9 ~63 ~-1 ~9 grass 0 
setblock ~55 ~-1 ~10 dirt 0 
setblock ~55 ~-1 ~52 dirt 0  
fill ~55 ~-1 ~53 ~63 ~-1 ~53 grass 0  
fill ~56 ~-1 ~10 ~63 ~-1 ~10 grass 0 
setblock ~56 ~-1 ~11 dirt 0 
setblock ~56 ~-1 ~12 grass 0 
setblock ~56 ~-1 ~50 grass 0 
setblock ~56 ~-1 ~51 dirt 0  
fill ~56 ~-1 ~52 ~63 ~-1 ~52 grass 0  
fill ~57 ~-1 ~11 ~63 ~-1 ~11 grass 0  
fill ~57 ~-1 ~12 ~57 ~-1 ~13 dirt 0  
fill ~57 ~-1 ~49 ~57 ~-1 ~50 dirt 0  
fill ~57 ~-1 ~51 ~63 ~-1 ~51 grass 0  
fill ~58 ~-1 ~12 ~63 ~-1 ~12 grass 0  
fill ~58 ~-1 ~13 ~63 ~-1 ~13 grass 0  
fill ~58 ~-1 ~14 ~58 ~-1 ~15 dirt 0  
fill ~58 ~-1 ~47 ~59 ~-1 ~47 dirt 0  
fill ~58 ~-1 ~48 ~58 ~-1 ~47 dirt 0  
fill ~58 ~-1 ~49 ~63 ~-1 ~49 grass 0  
fill ~58 ~-1 ~50 ~63 ~-1 ~50 grass 0  
fill ~59 ~-1 ~14 ~63 ~-1 ~14 grass 0  
fill ~59 ~-1 ~15 ~59 ~-1 ~16 dirt 0 
setblock ~59 ~-1 ~46 dirt 0  
fill ~59 ~-1 ~48 ~63 ~-1 ~48 grass 0  
fill ~60 ~-1 ~15 ~63 ~-1 ~15 grass 0  
fill ~60 ~-1 ~16 ~63 ~-1 ~16 grass 0  
fill ~60 ~-1 ~17 ~60 ~-1 ~18 dirt 0  
fill ~60 ~-1 ~44 ~60 ~-1 ~45 dirt 0  
fill ~60 ~-1 ~46 ~63 ~-1 ~46 grass 0  
fill ~60 ~-1 ~47 ~63 ~-1 ~47 grass 0  
fill ~61 ~-1 ~17 ~63 ~-1 ~17 grass 0  
fill ~61 ~-1 ~18 ~63 ~-1 ~18 grass 0  
fill ~61 ~-1 ~19 ~61 ~-1 ~21 dirt 0  
fill ~61 ~-1 ~41 ~61 ~-1 ~43 dirt 0  
fill ~61 ~-1 ~44 ~63 ~-1 ~44 grass 0  
fill ~61 ~-1 ~45 ~63 ~-1 ~45 grass 0  
fill ~62 ~-1 ~19 ~63 ~-1 ~19 grass 0  
fill ~62 ~-1 ~20 ~63 ~-1 ~20 grass 0  
fill ~62 ~-1 ~21 ~63 ~-1 ~21 grass 0  
fill ~62 ~-1 ~22 ~62 ~-1 ~25 dirt 0  
fill ~62 ~-1 ~37 ~62 ~-1 ~40 dirt 0  
fill ~62 ~-1 ~41 ~63 ~-1 ~41 grass 0  
fill ~62 ~-1 ~42 ~63 ~-1 ~42 grass 0  
fill ~62 ~-1 ~43 ~63 ~-1 ~43 grass 0 
setblock ~62 ~-1 ~62 dirt 0 
setblock ~63 ~-1 ~0 dirt 0  
fill ~63 ~-1 ~22 ~63 ~-1 ~25 grass 0  
fill ~63 ~-1 ~26 ~63 ~-1 ~36 dirt 0  
fill ~63 ~-1 ~37 ~63 ~-1 ~62 grass 0  
fill ~1 ~0 ~26 ~1 ~6 ~26 stained_hardened_clay 13  
fill ~1 ~0 ~27 ~1 ~14 ~27 stained_hardened_clay 13  
fill ~1 ~0 ~28 ~1 ~5 ~28 stained_hardened_clay 13  
fill ~1 ~0 ~29 ~1 ~4 ~29 stained_hardened_clay 13 
setblock ~1 ~0 ~30 wooden_door 0  
fill ~1 ~0 ~31 ~1 ~2 ~31 stained_hardened_clay 13 
setblock ~1 ~0 ~32 wooden_door 0  
fill ~1 ~0 ~33 ~1 ~4 ~33 stained_hardened_clay 13  
fill ~1 ~0 ~34 ~1 ~5 ~34 stained_hardened_clay 13  
fill ~1 ~0 ~35 ~1 ~14 ~35 stained_hardened_clay 13 
setblock ~1 ~0 ~62 planks 0 
setblock ~2 ~0 ~0 stained_hardened_clay 4  
fill ~2 ~0 ~22 ~2 ~1 ~22 stained_hardened_clay 13  
fill ~2 ~0 ~23 ~2 ~2 ~23 stained_hardened_clay 13  
fill ~2 ~0 ~24 ~2 ~3 ~24 stained_hardened_clay 13  
fill ~2 ~0 ~25 ~2 ~4 ~25 stained_hardened_clay 13  
fill ~2 ~0 ~28 ~6 ~0 ~28 bookshelf 0  
fill ~2 ~0 ~29 ~6 ~0 ~29 bookshelf 0  
fill ~2 ~0 ~33 ~6 ~0 ~33 bookshelf 0  
fill ~2 ~0 ~34 ~6 ~0 ~34 bookshelf 0  
fill ~2 ~0 ~37 ~2 ~4 ~37 stained_hardened_clay 13  
fill ~2 ~0 ~38 ~2 ~3 ~38 stained_hardened_clay 13  
fill ~2 ~0 ~39 ~2 ~3 ~39 stained_hardened_clay 13  
fill ~2 ~0 ~40 ~2 ~2 ~40 stained_hardened_clay 13  
fill ~3 ~0 ~19 ~3 ~1 ~19 stained_hardened_clay 13  
fill ~3 ~0 ~20 ~3 ~0 ~21 stained_hardened_clay 13  
fill ~3 ~0 ~22 ~6 ~0 ~22 bookshelf 0  
fill ~3 ~0 ~23 ~10 ~0 ~23 bookshelf 0  
fill ~3 ~0 ~39 ~10 ~0 ~39 bookshelf 0  
fill ~3 ~0 ~40 ~6 ~0 ~40 bookshelf 0  
fill ~3 ~0 ~41 ~3 ~0 ~43 stained_hardened_clay 13  
fill ~4 ~0 ~17 ~4 ~14 ~17 stained_hardened_clay 13  
fill ~4 ~0 ~18 ~4 ~2 ~18 stained_hardened_clay 13 
setblock ~4 ~0 ~19 oak_stairs 3 
setblock ~4 ~0 ~20 oak_stairs 1 
setblock ~4 ~0 ~21 oak_stairs 2 
setblock ~4 ~0 ~25 enchanting_table 0 
setblock ~4 ~0 ~37 enchanting_table 0 
setblock ~4 ~0 ~41 oak_stairs 3 
setblock ~4 ~0 ~42 oak_stairs 1 
setblock ~4 ~0 ~43 oak_stairs 2  
fill ~4 ~0 ~44 ~4 ~2 ~44 stained_hardened_clay 13  
fill ~4 ~0 ~45 ~4 ~14 ~45 stained_hardened_clay 13  
fill ~5 ~0 ~15 ~5 ~14 ~15 stained_hardened_clay 13  
fill ~5 ~0 ~16 ~5 ~14 ~16 stained_hardened_clay 13  
fill ~5 ~0 ~17 ~5 ~0 ~18 oak_stairs 1 
setblock ~5 ~0 ~19 carpet 13 
setblock ~5 ~0 ~20 fence 0  
fill ~5 ~0 ~21 ~8 ~0 ~21 carpet 13  
fill ~5 ~0 ~41 ~8 ~0 ~41 carpet 13 
setblock ~5 ~0 ~42 fence 0 
setblock ~5 ~0 ~43 carpet 13  
fill ~5 ~0 ~44 ~5 ~0 ~45 oak_stairs 1  
fill ~5 ~0 ~46 ~5 ~14 ~46 stained_hardened_clay 13  
fill ~5 ~0 ~47 ~5 ~14 ~47 stained_hardened_clay 13  
fill ~6 ~0 ~14 ~6 ~6 ~14 stained_hardened_clay 13  
fill ~6 ~0 ~15 ~6 ~7 ~15 bookshelf 0  
fill ~6 ~0 ~16 ~8 ~0 ~16 bookshelf 0 
setblock ~6 ~0 ~17 oak_stairs 3 
setblock ~6 ~0 ~18 fence 0  
fill ~6 ~0 ~19 ~7 ~0 ~19 carpet 4  
fill ~6 ~0 ~20 ~7 ~0 ~20 carpet 13  
fill ~6 ~0 ~42 ~7 ~0 ~42 carpet 13  
fill ~6 ~0 ~43 ~7 ~0 ~43 carpet 4 
setblock ~6 ~0 ~44 fence 0 
setblock ~6 ~0 ~45 oak_stairs 2  
fill ~6 ~0 ~46 ~8 ~0 ~46 bookshelf 0  
fill ~6 ~0 ~47 ~6 ~7 ~47 bookshelf 0  
fill ~6 ~0 ~48 ~6 ~6 ~48 stained_hardened_clay 13  
fill ~7 ~0 ~12 ~7 ~0 ~13 stained_hardened_clay 13  
fill ~7 ~0 ~14 ~7 ~0 ~15 oak_stairs 1  
fill ~7 ~0 ~17 ~10 ~0 ~17 bookshelf 0  
fill ~7 ~0 ~18 ~8 ~0 ~18 carpet 13 
setblock ~7 ~0 ~22 fence 0  
fill ~7 ~0 ~24 ~14 ~0 ~24 bookshelf 0 
setblock ~7 ~0 ~28 oak_stairs 3  
fill ~7 ~0 ~29 ~8 ~0 ~29 oak_stairs 7  
fill ~7 ~0 ~33 ~8 ~0 ~33 oak_stairs 6 
setblock ~7 ~0 ~34 oak_stairs 2  
fill ~7 ~0 ~38 ~14 ~0 ~38 bookshelf 0 
setblock ~7 ~0 ~40 fence 0  
fill ~7 ~0 ~44 ~8 ~0 ~44 carpet 13  
fill ~7 ~0 ~45 ~10 ~0 ~45 bookshelf 0  
fill ~7 ~0 ~47 ~7 ~0 ~48 oak_stairs 1  
fill ~7 ~0 ~49 ~7 ~1 ~49 stained_hardened_clay 13  
fill ~7 ~0 ~50 ~7 ~0 ~49 stained_hardened_clay 13  
fill ~8 ~0 ~11 ~8 ~1 ~11 stained_hardened_clay 13 
setblock ~8 ~0 ~12 oak_stairs 1 
setblock ~8 ~0 ~13 oak_stairs 2  
fill ~8 ~0 ~14 ~8 ~0 ~15 carpet 13 
setblock ~8 ~0 ~19 carpet 13 
setblock ~8 ~0 ~20 carpet 4 
setblock ~8 ~0 ~22 oak_stairs 0 
setblock ~8 ~0 ~40 oak_stairs 0 
setblock ~8 ~0 ~42 carpet 4 
setblock ~8 ~0 ~43 carpet 13  
fill ~8 ~0 ~47 ~9 ~0 ~47 carpet 13  
fill ~8 ~0 ~48 ~8 ~0 ~47 carpet 13 
setblock ~8 ~0 ~49 oak_stairs 3 
setblock ~8 ~0 ~50 oak_stairs 1  
fill ~8 ~0 ~51 ~8 ~1 ~51 stained_hardened_clay 13  
fill ~9 ~0 ~10 ~9 ~2 ~10 stained_hardened_clay 13  
fill ~9 ~0 ~11 ~10 ~0 ~11 bookshelf 0 
setblock ~9 ~0 ~12 fence 0  
fill ~9 ~0 ~13 ~11 ~0 ~13 carpet 13 
setblock ~9 ~0 ~14 carpet 4 
setblock ~9 ~0 ~15 carpet 13 
setblock ~9 ~0 ~16 fence 0  
fill ~9 ~0 ~18 ~12 ~0 ~18 bookshelf 0 
setblock ~9 ~0 ~19 oak_stairs 1  
fill ~9 ~0 ~20 ~12 ~0 ~20 carpet 13  
fill ~9 ~0 ~21 ~10 ~0 ~21 carpet 4  
fill ~9 ~0 ~22 ~10 ~0 ~22 carpet 13 
setblock ~9 ~0 ~29 fence_gate 2 
setblock ~9 ~0 ~33 fence_gate 2  
fill ~9 ~0 ~40 ~10 ~0 ~40 carpet 13  
fill ~9 ~0 ~41 ~10 ~0 ~41 carpet 4  
fill ~9 ~0 ~42 ~12 ~0 ~42 carpet 13 
setblock ~9 ~0 ~43 oak_stairs 1  
fill ~9 ~0 ~44 ~12 ~0 ~44 bookshelf 0 
setblock ~9 ~0 ~46 fence 0 
setblock ~9 ~0 ~48 carpet 4  
fill ~9 ~0 ~49 ~11 ~0 ~49 carpet 13 
setblock ~9 ~0 ~50 fence 0  
fill ~9 ~0 ~51 ~10 ~0 ~51 bookshelf 0  
fill ~9 ~0 ~52 ~9 ~2 ~52 stained_hardened_clay 13  
fill ~10 ~0 ~9 ~10 ~3 ~9 stained_hardened_clay 13  
fill ~10 ~0 ~10 ~10 ~3 ~10 bookshelf 0  
fill ~10 ~0 ~12 ~14 ~0 ~12 carpet 13  
fill ~10 ~0 ~14 ~11 ~0 ~14 carpet 13  
fill ~10 ~0 ~15 ~11 ~0 ~15 carpet 4 
setblock ~10 ~0 ~16 oak_stairs 0 
setblock ~10 ~0 ~19 fence 0  
fill ~10 ~0 ~28 ~15 ~0 ~28 bookshelf 0  
fill ~10 ~0 ~29 ~15 ~0 ~29 bookshelf 0  
fill ~10 ~0 ~33 ~15 ~0 ~33 bookshelf 0  
fill ~10 ~0 ~34 ~15 ~0 ~34 bookshelf 0 
setblock ~10 ~0 ~43 fence 0 
setblock ~10 ~0 ~46 oak_stairs 0  
fill ~10 ~0 ~47 ~11 ~0 ~47 carpet 4  
fill ~10 ~0 ~48 ~11 ~0 ~48 carpet 13  
fill ~10 ~0 ~50 ~14 ~0 ~50 carpet 13  
fill ~10 ~0 ~52 ~10 ~3 ~52 bookshelf 0  
fill ~10 ~0 ~53 ~10 ~3 ~53 stained_hardened_clay 13  
fill ~11 ~0 ~8 ~11 ~2 ~8 stained_hardened_clay 13  
fill ~11 ~0 ~9 ~12 ~0 ~9 bookshelf 0  
fill ~11 ~0 ~10 ~12 ~0 ~10 oak_stairs 3 
setblock ~11 ~0 ~11 oak_stairs 1  
fill ~11 ~0 ~16 ~13 ~0 ~16 carpet 13  
fill ~11 ~0 ~17 ~14 ~0 ~17 carpet 13  
fill ~11 ~0 ~19 ~14 ~0 ~19 bookshelf 0  
fill ~11 ~0 ~21 ~14 ~0 ~21 carpet 13  
fill ~11 ~0 ~22 ~14 ~0 ~22 carpet 4  
fill ~11 ~0 ~23 ~14 ~0 ~23 carpet 13  
fill ~11 ~0 ~25 ~17 ~0 ~25 bookshelf 0 
setblock ~11 ~0 ~26 fence_gate 3  
fill ~11 ~0 ~27 ~11 ~1 ~27 planks 0 
setblock ~11 ~0 ~35 fence_gate 3  
fill ~11 ~0 ~36 ~11 ~1 ~36 planks 0  
fill ~11 ~0 ~37 ~17 ~0 ~37 bookshelf 0  
fill ~11 ~0 ~39 ~14 ~0 ~39 carpet 13  
fill ~11 ~0 ~40 ~14 ~0 ~40 carpet 4  
fill ~11 ~0 ~41 ~14 ~0 ~41 carpet 13  
fill ~11 ~0 ~43 ~14 ~0 ~43 bookshelf 0  
fill ~11 ~0 ~46 ~13 ~0 ~46 carpet 13  
fill ~11 ~0 ~51 ~11 ~0 ~52 oak_stairs 1  
fill ~11 ~0 ~53 ~12 ~0 ~53 bookshelf 0  
fill ~11 ~0 ~54 ~11 ~2 ~54 stained_hardened_clay 13  
fill ~12 ~0 ~7 ~12 ~1 ~7 stained_hardened_clay 13  
fill ~12 ~0 ~8 ~12 ~2 ~8 bookshelf 0 
setblock ~12 ~0 ~11 fence 0  
fill ~12 ~0 ~13 ~12 ~0 ~14 carpet 4 
setblock ~12 ~0 ~15 carpet 13  
fill ~12 ~0 ~45 ~14 ~0 ~45 carpet 13 
setblock ~12 ~0 ~47 carpet 13  
fill ~12 ~0 ~48 ~12 ~0 ~49 carpet 4 
setblock ~12 ~0 ~51 fence 0 
setblock ~12 ~0 ~52 oak_stairs 2  
fill ~12 ~0 ~54 ~12 ~2 ~54 bookshelf 0  
fill ~12 ~0 ~55 ~12 ~1 ~55 stained_hardened_clay 13  
fill ~13 ~0 ~6 ~14 ~0 ~6 stained_hardened_clay 13 
setblock ~13 ~0 ~7 oak_stairs 3 
setblock ~13 ~0 ~8 fence 0  
fill ~13 ~0 ~9 ~15 ~0 ~9 carpet 13  
fill ~13 ~0 ~10 ~15 ~0 ~10 carpet 13  
fill ~13 ~0 ~11 ~13 ~0 ~9 carpet 13  
fill ~13 ~0 ~13 ~14 ~0 ~13 carpet 13  
fill ~13 ~0 ~14 ~13 ~0 ~15 oak_stairs 1 
setblock ~13 ~0 ~18 fence 0  
fill ~13 ~0 ~20 ~16 ~0 ~20 bookshelf 0  
fill ~13 ~0 ~42 ~16 ~0 ~42 bookshelf 0 
setblock ~13 ~0 ~44 fence 0  
fill ~13 ~0 ~47 ~13 ~0 ~48 oak_stairs 1  
fill ~13 ~0 ~49 ~14 ~0 ~49 carpet 13  
fill ~13 ~0 ~51 ~13 ~0 ~53 carpet 13 
setblock ~13 ~0 ~54 fence 0 
setblock ~13 ~0 ~55 oak_stairs 2  
fill ~13 ~0 ~56 ~14 ~0 ~56 stained_hardened_clay 13 
setblock ~14 ~0 ~7 oak_stairs 0 
setblock ~14 ~0 ~8 carpet 13  
fill ~14 ~0 ~11 ~15 ~0 ~11 carpet 4 
setblock ~14 ~0 ~14 oak_stairs 4  
fill ~14 ~0 ~15 ~15 ~0 ~15 oak_stairs 7  
fill ~14 ~0 ~16 ~15 ~0 ~16 oak_stairs 2 
setblock ~14 ~0 ~18 oak_stairs 0 
setblock ~14 ~0 ~44 oak_stairs 0  
fill ~14 ~0 ~46 ~15 ~0 ~46 oak_stairs 3  
fill ~14 ~0 ~47 ~15 ~0 ~47 oak_stairs 6 
setblock ~14 ~0 ~48 oak_stairs 4  
fill ~14 ~0 ~51 ~15 ~0 ~51 carpet 4  
fill ~14 ~0 ~52 ~15 ~0 ~52 carpet 13  
fill ~14 ~0 ~53 ~15 ~0 ~53 carpet 13  
fill ~14 ~0 ~54 ~14 ~0 ~52 carpet 13 
setblock ~14 ~0 ~55 oak_stairs 0  
fill ~15 ~0 ~5 ~15 ~6 ~5 stained_hardened_clay 13  
fill ~15 ~0 ~6 ~16 ~0 ~6 oak_stairs 3  
fill ~15 ~0 ~7 ~16 ~0 ~7 carpet 13 
setblock ~15 ~0 ~8 carpet 4  
fill ~15 ~0 ~12 ~16 ~0 ~12 oak_stairs 3 
setblock ~15 ~0 ~13 oak_stairs 6 
setblock ~15 ~0 ~14 planks 0 
setblock ~15 ~0 ~17 carpet 4  
fill ~15 ~0 ~18 ~15 ~0 ~19 carpet 13  
fill ~15 ~0 ~21 ~18 ~0 ~21 bookshelf 0  
fill ~15 ~0 ~22 ~16 ~0 ~22 carpet 13  
fill ~15 ~0 ~23 ~17 ~0 ~23 carpet 4  
fill ~15 ~0 ~24 ~17 ~0 ~24 carpet 13  
fill ~15 ~0 ~38 ~17 ~0 ~38 carpet 13  
fill ~15 ~0 ~39 ~17 ~0 ~39 carpet 4  
fill ~15 ~0 ~40 ~16 ~0 ~40 carpet 13  
fill ~15 ~0 ~41 ~18 ~0 ~41 bookshelf 0 
setblock ~15 ~0 ~44 carpet 13 
setblock ~15 ~0 ~45 carpet 4 
setblock ~15 ~0 ~48 planks 0 
setblock ~15 ~0 ~49 oak_stairs 7  
fill ~15 ~0 ~50 ~16 ~0 ~50 oak_stairs 2 
setblock ~15 ~0 ~54 carpet 4  
fill ~15 ~0 ~55 ~16 ~0 ~55 carpet 13  
fill ~15 ~0 ~56 ~16 ~0 ~56 oak_stairs 2  
fill ~15 ~0 ~57 ~15 ~6 ~57 stained_hardened_clay 13  
fill ~16 ~0 ~4 ~17 ~0 ~4 stained_hardened_clay 13  
fill ~16 ~0 ~5 ~17 ~0 ~5 bookshelf 0 
setblock ~16 ~0 ~8 carpet 13  
fill ~16 ~0 ~9 ~16 ~0 ~10 carpet 4  
fill ~16 ~0 ~11 ~18 ~0 ~11 carpet 13  
fill ~16 ~0 ~13 ~16 ~0 ~14 oak_stairs 5  
fill ~16 ~0 ~16 ~18 ~0 ~16 carpet 13  
fill ~16 ~0 ~17 ~19 ~0 ~17 carpet 13  
fill ~16 ~0 ~18 ~17 ~0 ~18 carpet 4  
fill ~16 ~0 ~19 ~17 ~0 ~19 carpet 13  
fill ~16 ~0 ~43 ~17 ~0 ~43 carpet 13  
fill ~16 ~0 ~44 ~17 ~0 ~44 carpet 4  
fill ~16 ~0 ~45 ~19 ~0 ~45 carpet 13  
fill ~16 ~0 ~46 ~18 ~0 ~46 carpet 13  
fill ~16 ~0 ~48 ~16 ~0 ~49 oak_stairs 5  
fill ~16 ~0 ~51 ~18 ~0 ~51 carpet 13  
fill ~16 ~0 ~52 ~16 ~0 ~53 carpet 4 
setblock ~16 ~0 ~54 carpet 13  
fill ~16 ~0 ~57 ~17 ~0 ~57 bookshelf 0  
fill ~16 ~0 ~58 ~17 ~0 ~58 stained_hardened_clay 13  
fill ~17 ~0 ~6 ~18 ~0 ~6 bookshelf 0  
fill ~17 ~0 ~7 ~18 ~0 ~7 bookshelf 0 
setblock ~17 ~0 ~8 fence 0 
setblock ~17 ~0 ~9 oak_stairs 2 
setblock ~17 ~0 ~10 carpet 13  
fill ~17 ~0 ~12 ~18 ~0 ~12 carpet 13  
fill ~17 ~0 ~13 ~17 ~0 ~14 oak_stairs 0  
fill ~17 ~0 ~15 ~18 ~0 ~15 carpet 13 
setblock ~17 ~0 ~20 fence 0  
fill ~17 ~0 ~22 ~20 ~0 ~22 bookshelf 0  
fill ~17 ~0 ~40 ~20 ~0 ~40 bookshelf 0 
setblock ~17 ~0 ~42 fence 0  
fill ~17 ~0 ~47 ~18 ~0 ~47 carpet 13  
fill ~17 ~0 ~48 ~17 ~0 ~49 oak_stairs 0  
fill ~17 ~0 ~50 ~18 ~0 ~50 carpet 13  
fill ~17 ~0 ~52 ~18 ~0 ~52 carpet 13 
setblock ~17 ~0 ~53 oak_stairs 3 
setblock ~17 ~0 ~54 fence 0  
fill ~17 ~0 ~55 ~18 ~0 ~55 bookshelf 0  
fill ~17 ~0 ~56 ~18 ~0 ~56 bookshelf 0  
fill ~18 ~0 ~3 ~19 ~0 ~3 stained_hardened_clay 13  
fill ~18 ~0 ~4 ~19 ~0 ~4 oak_stairs 3 
setblock ~18 ~0 ~5 oak_stairs 1  
fill ~18 ~0 ~8 ~19 ~0 ~8 bookshelf 0  
fill ~18 ~0 ~9 ~19 ~0 ~9 bookshelf 0 
setblock ~18 ~0 ~13 carpet 13 
setblock ~18 ~0 ~14 carpet 4 
setblock ~18 ~0 ~18 carpet 13 
setblock ~18 ~0 ~19 carpet 4 
setblock ~18 ~0 ~20 oak_stairs 0 
setblock ~18 ~0 ~23 carpet 13 
setblock ~18 ~0 ~24 carpet 4 
setblock ~18 ~0 ~38 carpet 4 
setblock ~18 ~0 ~39 carpet 13 
setblock ~18 ~0 ~42 oak_stairs 0 
setblock ~18 ~0 ~43 carpet 4 
setblock ~18 ~0 ~44 carpet 13 
setblock ~18 ~0 ~48 carpet 4 
setblock ~18 ~0 ~49 carpet 13  
fill ~18 ~0 ~53 ~19 ~0 ~53 bookshelf 0  
fill ~18 ~0 ~54 ~19 ~0 ~54 bookshelf 0 
setblock ~18 ~0 ~57 oak_stairs 1  
fill ~18 ~0 ~58 ~19 ~0 ~58 oak_stairs 2  
fill ~18 ~0 ~59 ~19 ~0 ~59 stained_hardened_clay 13 
setblock ~19 ~0 ~5 fence 0  
fill ~19 ~0 ~6 ~19 ~0 ~7 carpet 13  
fill ~19 ~0 ~10 ~20 ~0 ~10 bookshelf 0  
fill ~19 ~0 ~11 ~20 ~0 ~11 bookshelf 0 
setblock ~19 ~0 ~12 fence 0 
setblock ~19 ~0 ~13 oak_stairs 2 
setblock ~19 ~0 ~14 carpet 13  
fill ~19 ~0 ~15 ~19 ~0 ~16 carpet 4 
setblock ~19 ~0 ~18 carpet 4  
fill ~19 ~0 ~19 ~19 ~0 ~21 carpet 13  
fill ~19 ~0 ~23 ~22 ~0 ~23 bookshelf 0  
fill ~19 ~0 ~28 ~24 ~0 ~28 bookshelf 0  
fill ~19 ~0 ~29 ~24 ~0 ~29 bookshelf 0  
fill ~19 ~0 ~33 ~24 ~0 ~33 bookshelf 0  
fill ~19 ~0 ~34 ~24 ~0 ~34 bookshelf 0  
fill ~19 ~0 ~39 ~22 ~0 ~39 bookshelf 0  
fill ~19 ~0 ~41 ~21 ~0 ~41 carpet 13  
fill ~19 ~0 ~42 ~20 ~0 ~42 carpet 13  
fill ~19 ~0 ~43 ~19 ~0 ~41 carpet 13 
setblock ~19 ~0 ~44 carpet 4  
fill ~19 ~0 ~46 ~19 ~0 ~47 carpet 4  
fill ~19 ~0 ~48 ~20 ~0 ~48 carpet 13 
setblock ~19 ~0 ~49 oak_stairs 3 
setblock ~19 ~0 ~50 fence 0  
fill ~19 ~0 ~51 ~20 ~0 ~51 bookshelf 0  
fill ~19 ~0 ~52 ~20 ~0 ~52 bookshelf 0  
fill ~19 ~0 ~55 ~20 ~0 ~55 carpet 13  
fill ~19 ~0 ~56 ~19 ~0 ~55 carpet 13 
setblock ~19 ~0 ~57 fence 0  
fill ~20 ~0 ~2 ~22 ~0 ~2 stained_hardened_clay 13 
setblock ~20 ~0 ~3 oak_stairs 1 
setblock ~20 ~0 ~4 carpet 13  
fill ~20 ~0 ~5 ~20 ~0 ~6 carpet 4 
setblock ~20 ~0 ~7 carpet 13 
setblock ~20 ~0 ~8 oak_stairs 3 
setblock ~20 ~0 ~9 fence 0  
fill ~20 ~0 ~12 ~21 ~0 ~12 bookshelf 0  
fill ~20 ~0 ~13 ~21 ~0 ~13 bookshelf 0  
fill ~20 ~0 ~15 ~20 ~0 ~16 carpet 13 
setblock ~20 ~0 ~17 carpet 4  
fill ~20 ~0 ~18 ~22 ~0 ~18 carpet 13 
setblock ~20 ~0 ~19 carpet 4  
fill ~20 ~0 ~20 ~20 ~0 ~21 carpet 13 
setblock ~20 ~0 ~43 carpet 4  
fill ~20 ~0 ~44 ~22 ~0 ~44 carpet 13 
setblock ~20 ~0 ~45 carpet 4  
fill ~20 ~0 ~46 ~20 ~0 ~48 carpet 13  
fill ~20 ~0 ~49 ~21 ~0 ~49 bookshelf 0  
fill ~20 ~0 ~50 ~21 ~0 ~50 bookshelf 0 
setblock ~20 ~0 ~53 fence 0 
setblock ~20 ~0 ~54 oak_stairs 2  
fill ~20 ~0 ~56 ~20 ~0 ~57 carpet 4 
setblock ~20 ~0 ~58 carpet 13 
setblock ~20 ~0 ~59 oak_stairs 1  
fill ~20 ~0 ~60 ~22 ~0 ~60 stained_hardened_clay 13 
setblock ~21 ~0 ~3 oak_stairs 3 
setblock ~21 ~0 ~4 fence 0  
fill ~21 ~0 ~5 ~22 ~0 ~5 carpet 13  
fill ~21 ~0 ~6 ~22 ~0 ~6 carpet 13 
setblock ~21 ~0 ~7 carpet 4  
fill ~21 ~0 ~8 ~21 ~0 ~11 carpet 13  
fill ~21 ~0 ~14 ~22 ~0 ~14 bookshelf 0  
fill ~21 ~0 ~15 ~22 ~0 ~15 bookshelf 0 
setblock ~21 ~0 ~16 fence 0 
setblock ~21 ~0 ~17 oak_stairs 2  
fill ~21 ~0 ~19 ~22 ~0 ~19 carpet 13 
setblock ~21 ~0 ~20 carpet 4  
fill ~21 ~0 ~21 ~21 ~0 ~22 carpet 13  
fill ~21 ~0 ~24 ~23 ~0 ~24 bookshelf 0  
fill ~21 ~0 ~38 ~23 ~0 ~38 bookshelf 0  
fill ~21 ~0 ~40 ~22 ~0 ~40 carpet 13 
setblock ~21 ~0 ~42 carpet 4  
fill ~21 ~0 ~43 ~22 ~0 ~43 carpet 13 
setblock ~21 ~0 ~45 oak_stairs 3 
setblock ~21 ~0 ~46 fence 0  
fill ~21 ~0 ~47 ~22 ~0 ~47 bookshelf 0  
fill ~21 ~0 ~48 ~22 ~0 ~48 bookshelf 0  
fill ~21 ~0 ~51 ~22 ~0 ~51 carpet 13  
fill ~21 ~0 ~52 ~22 ~0 ~52 carpet 13  
fill ~21 ~0 ~53 ~21 ~0 ~54 carpet 13 
setblock ~21 ~0 ~55 carpet 4  
fill ~21 ~0 ~56 ~22 ~0 ~56 carpet 13  
fill ~21 ~0 ~57 ~22 ~0 ~57 carpet 13 
setblock ~21 ~0 ~58 fence 0 
setblock ~21 ~0 ~59 oak_stairs 2 
setblock ~22 ~0 ~3 oak_stairs 0 
setblock ~22 ~0 ~4 carpet 13 
setblock ~22 ~0 ~7 carpet 13  
fill ~22 ~0 ~8 ~22 ~0 ~9 carpet 4  
fill ~22 ~0 ~10 ~22 ~0 ~13 carpet 13  
fill ~22 ~0 ~16 ~23 ~0 ~16 bookshelf 0  
fill ~22 ~0 ~17 ~23 ~0 ~17 bookshelf 0  
fill ~22 ~0 ~20 ~23 ~0 ~20 carpet 13 
setblock ~22 ~0 ~21 carpet 4 
setblock ~22 ~0 ~22 carpet 13 
setblock ~22 ~0 ~41 carpet 4  
fill ~22 ~0 ~42 ~23 ~0 ~42 carpet 13  
fill ~22 ~0 ~45 ~23 ~0 ~45 bookshelf 0  
fill ~22 ~0 ~46 ~23 ~0 ~46 bookshelf 0  
fill ~22 ~0 ~49 ~22 ~0 ~52 carpet 13  
fill ~22 ~0 ~53 ~22 ~0 ~54 carpet 4 
setblock ~22 ~0 ~55 carpet 13 
setblock ~22 ~0 ~58 carpet 13 
setblock ~22 ~0 ~59 oak_stairs 0  
fill ~23 ~0 ~1 ~26 ~0 ~1 stained_hardened_clay 13  
fill ~23 ~0 ~2 ~24 ~0 ~2 bookshelf 0  
fill ~23 ~0 ~3 ~24 ~0 ~3 bookshelf 0  
fill ~23 ~0 ~4 ~24 ~0 ~4 bookshelf 0  
fill ~23 ~0 ~5 ~24 ~0 ~5 bookshelf 0 
setblock ~23 ~0 ~6 fence 0 
setblock ~23 ~0 ~7 oak_stairs 2  
fill ~23 ~0 ~8 ~23 ~0 ~9 carpet 13  
fill ~23 ~0 ~10 ~23 ~0 ~13 carpet 4  
fill ~23 ~0 ~14 ~23 ~0 ~15 carpet 13  
fill ~23 ~0 ~18 ~24 ~0 ~18 bookshelf 0  
fill ~23 ~0 ~19 ~24 ~0 ~19 bookshelf 0 
setblock ~23 ~0 ~21 carpet 13 
setblock ~23 ~0 ~22 carpet 4  
fill ~23 ~0 ~23 ~24 ~0 ~23 carpet 13  
fill ~23 ~0 ~25 ~23 ~7 ~25 bookshelf 0  
fill ~23 ~0 ~37 ~23 ~7 ~37 bookshelf 0  
fill ~23 ~0 ~39 ~24 ~0 ~39 carpet 13 
setblock ~23 ~0 ~40 carpet 4 
setblock ~23 ~0 ~41 carpet 13  
fill ~23 ~0 ~43 ~24 ~0 ~43 bookshelf 0  
fill ~23 ~0 ~44 ~24 ~0 ~44 bookshelf 0  
fill ~23 ~0 ~47 ~23 ~0 ~48 carpet 13  
fill ~23 ~0 ~49 ~23 ~0 ~52 carpet 4  
fill ~23 ~0 ~53 ~23 ~0 ~54 carpet 13 
setblock ~23 ~0 ~55 oak_stairs 3 
setblock ~23 ~0 ~56 fence 0  
fill ~23 ~0 ~57 ~24 ~0 ~57 bookshelf 0  
fill ~23 ~0 ~58 ~24 ~0 ~58 bookshelf 0  
fill ~23 ~0 ~59 ~24 ~0 ~59 bookshelf 0  
fill ~23 ~0 ~60 ~24 ~0 ~60 bookshelf 0  
fill ~23 ~0 ~61 ~26 ~0 ~61 stained_hardened_clay 13  
fill ~24 ~0 ~6 ~25 ~0 ~6 bookshelf 0  
fill ~24 ~0 ~7 ~25 ~0 ~7 bookshelf 0  
fill ~24 ~0 ~8 ~25 ~0 ~8 bookshelf 0  
fill ~24 ~0 ~9 ~30 ~0 ~9 bookshelf 0  
fill ~24 ~0 ~10 ~24 ~0 ~13 carpet 13  
fill ~24 ~0 ~14 ~24 ~0 ~16 carpet 4 
setblock ~24 ~0 ~17 carpet 13  
fill ~24 ~0 ~20 ~25 ~0 ~20 bookshelf 0  
fill ~24 ~0 ~21 ~25 ~0 ~21 bookshelf 0 
setblock ~24 ~0 ~22 carpet 13 
setblock ~24 ~0 ~40 carpet 13  
fill ~24 ~0 ~41 ~25 ~0 ~41 bookshelf 0  
fill ~24 ~0 ~42 ~25 ~0 ~42 bookshelf 0 
setblock ~24 ~0 ~45 carpet 13  
fill ~24 ~0 ~46 ~24 ~0 ~48 carpet 4  
fill ~24 ~0 ~49 ~24 ~0 ~52 carpet 13  
fill ~24 ~0 ~53 ~30 ~0 ~53 bookshelf 0  
fill ~24 ~0 ~54 ~25 ~0 ~54 bookshelf 0  
fill ~24 ~0 ~55 ~25 ~0 ~55 bookshelf 0  
fill ~24 ~0 ~56 ~25 ~0 ~56 bookshelf 0 
setblock ~25 ~0 ~2 oak_stairs 3  
fill ~25 ~0 ~3 ~25 ~0 ~4 oak_stairs 1 
setblock ~25 ~0 ~5 oak_stairs 2  
fill ~25 ~0 ~10 ~26 ~0 ~10 bookshelf 0  
fill ~25 ~0 ~11 ~26 ~0 ~11 bookshelf 0  
fill ~25 ~0 ~12 ~26 ~0 ~12 bookshelf 0  
fill ~25 ~0 ~13 ~26 ~0 ~13 bookshelf 0  
fill ~25 ~0 ~14 ~25 ~0 ~16 carpet 13 
setblock ~25 ~0 ~17 carpet 4  
fill ~25 ~0 ~22 ~26 ~0 ~22 bookshelf 0  
fill ~25 ~0 ~40 ~26 ~0 ~40 bookshelf 0 
setblock ~25 ~0 ~45 carpet 4  
fill ~25 ~0 ~46 ~25 ~0 ~48 carpet 13  
fill ~25 ~0 ~49 ~26 ~0 ~49 bookshelf 0  
fill ~25 ~0 ~50 ~26 ~0 ~50 bookshelf 0  
fill ~25 ~0 ~51 ~26 ~0 ~51 bookshelf 0  
fill ~25 ~0 ~52 ~26 ~0 ~52 bookshelf 0 
setblock ~25 ~0 ~57 oak_stairs 3  
fill ~25 ~0 ~58 ~25 ~0 ~59 oak_stairs 1 
setblock ~25 ~0 ~60 oak_stairs 2 
setblock ~26 ~0 ~7 oak_stairs 1  
fill ~26 ~0 ~8 ~28 ~0 ~8 oak_stairs 2  
fill ~26 ~0 ~14 ~26 ~7 ~14 bookshelf 0  
fill ~26 ~0 ~15 ~26 ~7 ~15 bookshelf 0  
fill ~26 ~0 ~16 ~26 ~7 ~16 bookshelf 0  
fill ~26 ~0 ~46 ~26 ~7 ~46 bookshelf 0  
fill ~26 ~0 ~47 ~26 ~7 ~47 bookshelf 0  
fill ~26 ~0 ~48 ~26 ~7 ~48 bookshelf 0  
fill ~26 ~0 ~54 ~28 ~0 ~54 oak_stairs 3 
setblock ~26 ~0 ~55 oak_stairs 1  
fill ~27 ~0 ~0 ~37 ~0 ~0 stained_hardened_clay 13 
setblock ~27 ~0 ~1 oak_stairs 1  
fill ~27 ~0 ~7 ~28 ~0 ~7 fence 0  
fill ~27 ~0 ~55 ~28 ~0 ~55 fence 0 
setblock ~27 ~0 ~61 oak_stairs 1  
fill ~27 ~0 ~62 ~37 ~0 ~62 stained_hardened_clay 13 
setblock ~28 ~0 ~1 oak_stairs 3 
setblock ~28 ~0 ~2 fence 0 
setblock ~28 ~0 ~60 fence 0 
setblock ~28 ~0 ~61 oak_stairs 2 
setblock ~29 ~0 ~1 oak_stairs 0 
setblock ~29 ~0 ~8 oak_stairs 0  
fill ~29 ~0 ~10 ~30 ~0 ~10 bookshelf 0  
fill ~29 ~0 ~11 ~30 ~0 ~11 bookshelf 0  
fill ~29 ~0 ~12 ~30 ~0 ~12 bookshelf 0  
fill ~29 ~0 ~13 ~30 ~0 ~13 bookshelf 0  
fill ~29 ~0 ~14 ~30 ~0 ~14 bookshelf 0  
fill ~29 ~0 ~18 ~30 ~0 ~18 bookshelf 0  
fill ~29 ~0 ~19 ~30 ~0 ~19 bookshelf 0  
fill ~29 ~0 ~20 ~30 ~0 ~20 bookshelf 0  
fill ~29 ~0 ~21 ~30 ~0 ~21 bookshelf 0  
fill ~29 ~0 ~22 ~30 ~0 ~22 bookshelf 0  
fill ~29 ~0 ~23 ~30 ~0 ~23 bookshelf 0  
fill ~29 ~0 ~39 ~30 ~0 ~39 bookshelf 0  
fill ~29 ~0 ~40 ~30 ~0 ~40 bookshelf 0  
fill ~29 ~0 ~41 ~30 ~0 ~41 bookshelf 0  
fill ~29 ~0 ~42 ~30 ~0 ~42 bookshelf 0  
fill ~29 ~0 ~43 ~30 ~0 ~43 bookshelf 0  
fill ~29 ~0 ~44 ~30 ~0 ~44 bookshelf 0  
fill ~29 ~0 ~48 ~30 ~0 ~48 bookshelf 0  
fill ~29 ~0 ~49 ~30 ~0 ~49 bookshelf 0  
fill ~29 ~0 ~50 ~30 ~0 ~50 bookshelf 0  
fill ~29 ~0 ~51 ~30 ~0 ~51 bookshelf 0  
fill ~29 ~0 ~52 ~30 ~0 ~52 bookshelf 0 
setblock ~29 ~0 ~54 oak_stairs 0 
setblock ~29 ~0 ~61 oak_stairs 0  
fill ~30 ~0 ~1 ~34 ~0 ~1 bookshelf 0 
setblock ~30 ~0 ~4 oak_stairs 1 
setblock ~30 ~0 ~58 oak_stairs 1  
fill ~30 ~0 ~61 ~34 ~0 ~61 bookshelf 0 
setblock ~31 ~0 ~3 oak_stairs 3  
fill ~31 ~0 ~4 ~33 ~0 ~4 fence 0 
setblock ~31 ~0 ~5 oak_stairs 2  
fill ~31 ~0 ~30 ~31 ~1 ~30 log 1  
fill ~31 ~0 ~31 ~31 ~3 ~31 bookshelf 0  
fill ~31 ~0 ~32 ~31 ~1 ~32 log 1 
setblock ~31 ~0 ~57 oak_stairs 3  
fill ~31 ~0 ~58 ~33 ~0 ~58 fence 0 
setblock ~31 ~0 ~59 oak_stairs 2  
fill ~32 ~0 ~30 ~32 ~3 ~30 planks 0  
fill ~32 ~0 ~32 ~32 ~3 ~32 bookshelf 0 
setblock ~33 ~0 ~3 oak_stairs 3 
setblock ~33 ~0 ~5 oak_stairs 2  
fill ~33 ~0 ~30 ~33 ~1 ~30 log 1 
setblock ~33 ~0 ~31 planks 0  
fill ~33 ~0 ~32 ~33 ~1 ~32 log 1 
setblock ~33 ~0 ~57 oak_stairs 3 
setblock ~33 ~0 ~59 oak_stairs 2 
setblock ~34 ~0 ~4 oak_stairs 0  
fill ~34 ~0 ~9 ~40 ~0 ~9 bookshelf 0  
fill ~34 ~0 ~10 ~35 ~0 ~10 bookshelf 0  
fill ~34 ~0 ~11 ~35 ~0 ~11 bookshelf 0  
fill ~34 ~0 ~12 ~35 ~0 ~12 bookshelf 0 KittysCommands:  

KittysCommands:   
fill ~34 ~0 ~13 ~35 ~0 ~13 bookshelf 0  
fill ~34 ~0 ~14 ~35 ~0 ~14 bookshelf 0  
fill ~34 ~0 ~18 ~35 ~0 ~18 bookshelf 0  
fill ~34 ~0 ~19 ~35 ~0 ~19 bookshelf 0  
fill ~34 ~0 ~20 ~35 ~0 ~20 bookshelf 0  
fill ~34 ~0 ~21 ~35 ~0 ~21 bookshelf 0  
fill ~34 ~0 ~22 ~35 ~0 ~22 bookshelf 0  
fill ~34 ~0 ~23 ~35 ~0 ~23 bookshelf 0  
fill ~34 ~0 ~31 ~35 ~0 ~31 oak_stairs 6 
setblock ~34 ~0 ~32 oak_stairs 3  
fill ~34 ~0 ~39 ~35 ~0 ~39 bookshelf 0  
fill ~34 ~0 ~40 ~35 ~0 ~40 bookshelf 0  
fill ~34 ~0 ~41 ~35 ~0 ~41 bookshelf 0  
fill ~34 ~0 ~42 ~35 ~0 ~42 bookshelf 0  
fill ~34 ~0 ~43 ~35 ~0 ~43 bookshelf 0  
fill ~34 ~0 ~44 ~35 ~0 ~44 bookshelf 0  
fill ~34 ~0 ~48 ~35 ~0 ~48 bookshelf 0  
fill ~34 ~0 ~49 ~35 ~0 ~49 bookshelf 0  
fill ~34 ~0 ~50 ~35 ~0 ~50 bookshelf 0  
fill ~34 ~0 ~51 ~35 ~0 ~51 bookshelf 0  
fill ~34 ~0 ~52 ~35 ~0 ~52 bookshelf 0  
fill ~34 ~0 ~53 ~40 ~0 ~53 bookshelf 0 
setblock ~34 ~0 ~58 oak_stairs 0 
setblock ~35 ~0 ~1 oak_stairs 1 
setblock ~35 ~0 ~8 oak_stairs 1 
setblock ~35 ~0 ~32 spruce_stairs 3 
setblock ~35 ~0 ~54 oak_stairs 1 
setblock ~35 ~0 ~61 oak_stairs 1 
setblock ~36 ~0 ~1 oak_stairs 3 
setblock ~36 ~0 ~2 fence 0  
fill ~36 ~0 ~7 ~37 ~0 ~7 fence 0  
fill ~36 ~0 ~8 ~38 ~0 ~8 oak_stairs 2  
fill ~36 ~0 ~54 ~38 ~0 ~54 oak_stairs 3  
fill ~36 ~0 ~55 ~37 ~0 ~55 fence 0 
setblock ~36 ~0 ~60 fence 0 
setblock ~36 ~0 ~61 oak_stairs 2 
setblock ~37 ~0 ~1 oak_stairs 0 
setblock ~37 ~0 ~61 oak_stairs 0  
fill ~38 ~0 ~1 ~41 ~0 ~1 stained_hardened_clay 13 
setblock ~38 ~0 ~7 oak_stairs 0  
fill ~38 ~0 ~10 ~39 ~0 ~10 bookshelf 0  
fill ~38 ~0 ~11 ~39 ~0 ~11 bookshelf 0  
fill ~38 ~0 ~12 ~39 ~0 ~12 bookshelf 0  
fill ~38 ~0 ~13 ~39 ~0 ~13 bookshelf 0  
fill ~38 ~0 ~14 ~38 ~7 ~14 bookshelf 0  
fill ~38 ~0 ~15 ~38 ~7 ~15 bookshelf 0  
fill ~38 ~0 ~16 ~38 ~7 ~16 bookshelf 0  
fill ~38 ~0 ~22 ~39 ~0 ~22 bookshelf 0  
fill ~38 ~0 ~40 ~39 ~0 ~40 bookshelf 0  
fill ~38 ~0 ~46 ~38 ~7 ~46 bookshelf 0  
fill ~38 ~0 ~47 ~38 ~7 ~47 bookshelf 0  
fill ~38 ~0 ~48 ~38 ~7 ~48 bookshelf 0  
fill ~38 ~0 ~49 ~39 ~0 ~49 bookshelf 0  
fill ~38 ~0 ~50 ~39 ~0 ~50 bookshelf 0  
fill ~38 ~0 ~51 ~39 ~0 ~51 bookshelf 0  
fill ~38 ~0 ~52 ~39 ~0 ~52 bookshelf 0 
setblock ~38 ~0 ~55 oak_stairs 0  
fill ~38 ~0 ~61 ~41 ~0 ~61 stained_hardened_clay 13  
fill ~39 ~0 ~6 ~40 ~0 ~6 bookshelf 0  
fill ~39 ~0 ~7 ~40 ~0 ~7 bookshelf 0  
fill ~39 ~0 ~8 ~40 ~0 ~8 bookshelf 0  
fill ~39 ~0 ~14 ~39 ~0 ~16 carpet 13 
setblock ~39 ~0 ~17 carpet 4  
fill ~39 ~0 ~20 ~40 ~0 ~20 bookshelf 0  
fill ~39 ~0 ~21 ~40 ~0 ~21 bookshelf 0  
fill ~39 ~0 ~41 ~40 ~0 ~41 bookshelf 0  
fill ~39 ~0 ~42 ~40 ~0 ~42 bookshelf 0 
setblock ~39 ~0 ~45 carpet 4  
fill ~39 ~0 ~46 ~39 ~0 ~48 carpet 13  
fill ~39 ~0 ~54 ~40 ~0 ~54 bookshelf 0  
fill ~39 ~0 ~55 ~40 ~0 ~55 bookshelf 0  
fill ~39 ~0 ~56 ~40 ~0 ~56 bookshelf 0 
setblock ~39 ~0 ~57 oak_stairs 3  
fill ~39 ~0 ~58 ~39 ~0 ~59 oak_stairs 0 
setblock ~39 ~0 ~60 oak_stairs 2  
fill ~40 ~0 ~2 ~41 ~0 ~2 bookshelf 0  
fill ~40 ~0 ~3 ~41 ~0 ~3 bookshelf 0  
fill ~40 ~0 ~4 ~41 ~0 ~4 bookshelf 0  
fill ~40 ~0 ~5 ~41 ~0 ~5 bookshelf 0  
fill ~40 ~0 ~10 ~40 ~0 ~13 carpet 13  
fill ~40 ~0 ~14 ~40 ~0 ~16 carpet 4 
setblock ~40 ~0 ~17 carpet 13  
fill ~40 ~0 ~18 ~41 ~0 ~18 bookshelf 0  
fill ~40 ~0 ~19 ~41 ~0 ~19 bookshelf 0  
fill ~40 ~0 ~22 ~40 ~0 ~23 carpet 13  
fill ~40 ~0 ~28 ~45 ~0 ~28 bookshelf 0  
fill ~40 ~0 ~29 ~45 ~0 ~29 bookshelf 0  
fill ~40 ~0 ~33 ~45 ~0 ~33 bookshelf 0  
fill ~40 ~0 ~34 ~45 ~0 ~34 bookshelf 0  
fill ~40 ~0 ~39 ~41 ~0 ~39 carpet 13  
fill ~40 ~0 ~40 ~40 ~0 ~39 carpet 13  
fill ~40 ~0 ~43 ~41 ~0 ~43 bookshelf 0  
fill ~40 ~0 ~44 ~41 ~0 ~44 bookshelf 0 
setblock ~40 ~0 ~45 carpet 13  
fill ~40 ~0 ~46 ~40 ~0 ~48 carpet 4  
fill ~40 ~0 ~49 ~40 ~0 ~52 carpet 13  
fill ~40 ~0 ~57 ~41 ~0 ~57 bookshelf 0  
fill ~40 ~0 ~58 ~41 ~0 ~58 bookshelf 0  
fill ~40 ~0 ~59 ~41 ~0 ~59 bookshelf 0  
fill ~40 ~0 ~60 ~41 ~0 ~60 bookshelf 0 
setblock ~41 ~0 ~6 fence 0 
setblock ~41 ~0 ~7 oak_stairs 2  
fill ~41 ~0 ~8 ~41 ~0 ~9 carpet 13  
fill ~41 ~0 ~10 ~41 ~0 ~13 carpet 4  
fill ~41 ~0 ~14 ~41 ~0 ~15 carpet 13  
fill ~41 ~0 ~16 ~42 ~0 ~16 bookshelf 0  
fill ~41 ~0 ~17 ~42 ~0 ~17 bookshelf 0  
fill ~41 ~0 ~20 ~42 ~0 ~20 carpet 13  
fill ~41 ~0 ~21 ~41 ~0 ~20 carpet 13 
setblock ~41 ~0 ~22 carpet 4 
setblock ~41 ~0 ~23 carpet 13  
fill ~41 ~0 ~24 ~43 ~0 ~24 bookshelf 0  
fill ~41 ~0 ~25 ~41 ~7 ~25 bookshelf 0  
fill ~41 ~0 ~37 ~41 ~7 ~37 bookshelf 0  
fill ~41 ~0 ~38 ~43 ~0 ~38 bookshelf 0 
setblock ~41 ~0 ~40 carpet 4  
fill ~41 ~0 ~41 ~41 ~0 ~42 carpet 13  
fill ~41 ~0 ~45 ~42 ~0 ~45 bookshelf 0  
fill ~41 ~0 ~46 ~42 ~0 ~46 bookshelf 0  
fill ~41 ~0 ~47 ~41 ~0 ~48 carpet 13  
fill ~41 ~0 ~49 ~41 ~0 ~52 carpet 4  
fill ~41 ~0 ~53 ~41 ~0 ~54 carpet 13 
setblock ~41 ~0 ~55 oak_stairs 3 
setblock ~41 ~0 ~56 fence 0  
fill ~42 ~0 ~2 ~44 ~0 ~2 stained_hardened_clay 13 
setblock ~42 ~0 ~3 oak_stairs 1  
fill ~42 ~0 ~4 ~42 ~0 ~7 carpet 13  
fill ~42 ~0 ~8 ~42 ~0 ~9 carpet 4  
fill ~42 ~0 ~10 ~43 ~0 ~10 carpet 13  
fill ~42 ~0 ~11 ~43 ~0 ~11 carpet 13  
fill ~42 ~0 ~12 ~42 ~0 ~13 carpet 13  
fill ~42 ~0 ~14 ~43 ~0 ~14 bookshelf 0  
fill ~42 ~0 ~15 ~43 ~0 ~15 bookshelf 0  
fill ~42 ~0 ~18 ~44 ~0 ~18 carpet 13  
fill ~42 ~0 ~19 ~43 ~0 ~19 carpet 13 
setblock ~42 ~0 ~21 carpet 4  
fill ~42 ~0 ~22 ~43 ~0 ~22 carpet 13  
fill ~42 ~0 ~23 ~45 ~0 ~23 bookshelf 0  
fill ~42 ~0 ~39 ~45 ~0 ~39 bookshelf 0  
fill ~42 ~0 ~40 ~43 ~0 ~40 carpet 13 
setblock ~42 ~0 ~41 carpet 4  
fill ~42 ~0 ~42 ~42 ~0 ~44 carpet 13  
fill ~42 ~0 ~47 ~43 ~0 ~47 bookshelf 0  
fill ~42 ~0 ~48 ~43 ~0 ~48 bookshelf 0  
fill ~42 ~0 ~49 ~42 ~0 ~52 carpet 13  
fill ~42 ~0 ~53 ~42 ~0 ~54 carpet 4  
fill ~42 ~0 ~55 ~42 ~0 ~58 carpet 13 
setblock ~42 ~0 ~59 oak_stairs 1  
fill ~42 ~0 ~60 ~44 ~0 ~60 stained_hardened_clay 13 
setblock ~43 ~0 ~3 oak_stairs 3 
setblock ~43 ~0 ~4 fence 0  
fill ~43 ~0 ~5 ~43 ~0 ~6 carpet 13 
setblock ~43 ~0 ~7 carpet 4  
fill ~43 ~0 ~8 ~43 ~0 ~11 carpet 13  
fill ~43 ~0 ~12 ~44 ~0 ~12 bookshelf 0  
fill ~43 ~0 ~13 ~44 ~0 ~13 bookshelf 0 
setblock ~43 ~0 ~16 fence 0 
setblock ~43 ~0 ~17 oak_stairs 2 
setblock ~43 ~0 ~20 carpet 4  
fill ~43 ~0 ~21 ~45 ~0 ~21 carpet 13  
fill ~43 ~0 ~41 ~45 ~0 ~41 carpet 13 
setblock ~43 ~0 ~42 carpet 4  
fill ~43 ~0 ~43 ~43 ~0 ~44 carpet 13 
setblock ~43 ~0 ~45 oak_stairs 3 
setblock ~43 ~0 ~46 fence 0  
fill ~43 ~0 ~49 ~44 ~0 ~49 bookshelf 0  
fill ~43 ~0 ~50 ~44 ~0 ~50 bookshelf 0  
fill ~43 ~0 ~51 ~43 ~0 ~54 carpet 13 
setblock ~43 ~0 ~55 carpet 4  
fill ~43 ~0 ~56 ~43 ~0 ~57 carpet 13 
setblock ~43 ~0 ~58 fence 0 
setblock ~43 ~0 ~59 oak_stairs 2 
setblock ~44 ~0 ~3 oak_stairs 0 
setblock ~44 ~0 ~4 carpet 13  
fill ~44 ~0 ~5 ~44 ~0 ~6 carpet 4  
fill ~44 ~0 ~7 ~45 ~0 ~7 carpet 13 
setblock ~44 ~0 ~8 oak_stairs 3 
setblock ~44 ~0 ~9 fence 0  
fill ~44 ~0 ~10 ~45 ~0 ~10 bookshelf 0  
fill ~44 ~0 ~11 ~45 ~0 ~11 bookshelf 0  
fill ~44 ~0 ~14 ~45 ~0 ~14 carpet 13  
fill ~44 ~0 ~15 ~44 ~0 ~16 carpet 13 
setblock ~44 ~0 ~17 carpet 4 
setblock ~44 ~0 ~19 carpet 4  
fill ~44 ~0 ~20 ~45 ~0 ~20 carpet 13  
fill ~44 ~0 ~22 ~47 ~0 ~22 bookshelf 0  
fill ~44 ~0 ~40 ~47 ~0 ~40 bookshelf 0  
fill ~44 ~0 ~42 ~45 ~0 ~42 carpet 13 
setblock ~44 ~0 ~43 carpet 4 
setblock ~44 ~0 ~44 carpet 13 
setblock ~44 ~0 ~45 carpet 4  
fill ~44 ~0 ~46 ~44 ~0 ~47 carpet 13  
fill ~44 ~0 ~51 ~45 ~0 ~51 bookshelf 0  
fill ~44 ~0 ~52 ~45 ~0 ~52 bookshelf 0 
setblock ~44 ~0 ~53 fence 0 
setblock ~44 ~0 ~54 oak_stairs 2  
fill ~44 ~0 ~55 ~45 ~0 ~55 carpet 13  
fill ~44 ~0 ~56 ~44 ~0 ~57 carpet 4 
setblock ~44 ~0 ~58 carpet 13 
setblock ~44 ~0 ~59 oak_stairs 0  
fill ~45 ~0 ~3 ~46 ~0 ~3 stained_hardened_clay 13  
fill ~45 ~0 ~4 ~46 ~0 ~4 oak_stairs 3 
setblock ~45 ~0 ~5 fence 0 
setblock ~45 ~0 ~6 carpet 13  
fill ~45 ~0 ~8 ~46 ~0 ~8 bookshelf 0  
fill ~45 ~0 ~9 ~46 ~0 ~9 bookshelf 0 
setblock ~45 ~0 ~12 fence 0 
setblock ~45 ~0 ~13 oak_stairs 2  
fill ~45 ~0 ~15 ~45 ~0 ~16 carpet 4  
fill ~45 ~0 ~17 ~48 ~0 ~17 carpet 13 
setblock ~45 ~0 ~18 carpet 4 
setblock ~45 ~0 ~19 carpet 13 
setblock ~45 ~0 ~43 carpet 13 
setblock ~45 ~0 ~44 carpet 4  
fill ~45 ~0 ~45 ~48 ~0 ~45 carpet 13  
fill ~45 ~0 ~46 ~45 ~0 ~47 carpet 4 
setblock ~45 ~0 ~48 carpet 13 
setblock ~45 ~0 ~49 oak_stairs 3 
setblock ~45 ~0 ~50 fence 0  
fill ~45 ~0 ~53 ~46 ~0 ~53 bookshelf 0  
fill ~45 ~0 ~54 ~46 ~0 ~54 bookshelf 0 
setblock ~45 ~0 ~56 carpet 13 
setblock ~45 ~0 ~57 fence 0  
fill ~45 ~0 ~58 ~46 ~0 ~58 oak_stairs 2  
fill ~45 ~0 ~59 ~46 ~0 ~59 stained_hardened_clay 13 
setblock ~46 ~0 ~5 oak_stairs 0  
fill ~46 ~0 ~6 ~47 ~0 ~6 bookshelf 0  
fill ~46 ~0 ~7 ~47 ~0 ~7 bookshelf 0  
fill ~46 ~0 ~10 ~47 ~0 ~10 carpet 13  
fill ~46 ~0 ~11 ~48 ~0 ~11 carpet 13  
fill ~46 ~0 ~12 ~47 ~0 ~12 carpet 13  
fill ~46 ~0 ~13 ~46 ~0 ~10 carpet 13 
setblock ~46 ~0 ~14 carpet 4  
fill ~46 ~0 ~15 ~47 ~0 ~15 carpet 13  
fill ~46 ~0 ~16 ~48 ~0 ~16 carpet 13 
setblock ~46 ~0 ~18 carpet 13 
setblock ~46 ~0 ~19 carpet 4 
setblock ~46 ~0 ~20 oak_stairs 1  
fill ~46 ~0 ~21 ~49 ~0 ~21 bookshelf 0 
setblock ~46 ~0 ~23 carpet 13 
setblock ~46 ~0 ~24 carpet 4 
setblock ~46 ~0 ~38 carpet 4 
setblock ~46 ~0 ~39 carpet 13  
fill ~46 ~0 ~41 ~49 ~0 ~41 bookshelf 0 
setblock ~46 ~0 ~42 oak_stairs 1 
setblock ~46 ~0 ~43 carpet 4 
setblock ~46 ~0 ~44 carpet 13  
fill ~46 ~0 ~46 ~48 ~0 ~46 carpet 13  
fill ~46 ~0 ~47 ~47 ~0 ~47 carpet 13 
setblock ~46 ~0 ~48 carpet 4  
fill ~46 ~0 ~49 ~46 ~0 ~51 carpet 13  
fill ~46 ~0 ~55 ~47 ~0 ~55 bookshelf 0  
fill ~46 ~0 ~56 ~47 ~0 ~56 bookshelf 0 
setblock ~46 ~0 ~57 oak_stairs 0  
fill ~47 ~0 ~4 ~48 ~0 ~4 stained_hardened_clay 13  
fill ~47 ~0 ~5 ~48 ~0 ~5 bookshelf 0 
setblock ~47 ~0 ~8 fence 0 
setblock ~47 ~0 ~9 oak_stairs 2  
fill ~47 ~0 ~13 ~47 ~0 ~14 oak_stairs 1  
fill ~47 ~0 ~18 ~48 ~0 ~18 carpet 4  
fill ~47 ~0 ~19 ~48 ~0 ~19 carpet 13 
setblock ~47 ~0 ~20 fence 0  
fill ~47 ~0 ~23 ~49 ~0 ~23 carpet 4  
fill ~47 ~0 ~24 ~49 ~0 ~24 carpet 13  
fill ~47 ~0 ~25 ~54 ~0 ~25 bookshelf 0  
fill ~47 ~0 ~37 ~54 ~0 ~37 bookshelf 0  
fill ~47 ~0 ~38 ~49 ~0 ~38 carpet 13  
fill ~47 ~0 ~39 ~49 ~0 ~39 carpet 4 
setblock ~47 ~0 ~42 fence 0  
fill ~47 ~0 ~43 ~49 ~0 ~43 carpet 13  
fill ~47 ~0 ~44 ~48 ~0 ~44 carpet 4  
fill ~47 ~0 ~48 ~47 ~0 ~49 oak_stairs 1  
fill ~47 ~0 ~50 ~47 ~0 ~52 carpet 13 
setblock ~47 ~0 ~53 oak_stairs 3 
setblock ~47 ~0 ~54 fence 0  
fill ~47 ~0 ~57 ~48 ~0 ~57 bookshelf 0  
fill ~47 ~0 ~58 ~48 ~0 ~58 stained_hardened_clay 13  
fill ~48 ~0 ~6 ~49 ~0 ~6 oak_stairs 3  
fill ~48 ~0 ~7 ~49 ~0 ~7 carpet 13  
fill ~48 ~0 ~8 ~48 ~0 ~7 carpet 13  
fill ~48 ~0 ~9 ~48 ~0 ~10 carpet 4  
fill ~48 ~0 ~12 ~49 ~0 ~12 oak_stairs 3  
fill ~48 ~0 ~13 ~48 ~0 ~14 oak_stairs 4  
fill ~48 ~0 ~20 ~51 ~0 ~20 bookshelf 0  
fill ~48 ~0 ~22 ~49 ~0 ~22 carpet 13  
fill ~48 ~0 ~40 ~49 ~0 ~40 carpet 13  
fill ~48 ~0 ~42 ~51 ~0 ~42 bookshelf 0  
fill ~48 ~0 ~48 ~48 ~0 ~49 oak_stairs 4  
fill ~48 ~0 ~50 ~49 ~0 ~50 oak_stairs 2 
setblock ~48 ~0 ~51 carpet 13  
fill ~48 ~0 ~52 ~48 ~0 ~53 carpet 4  
fill ~48 ~0 ~54 ~48 ~0 ~55 carpet 13  
fill ~48 ~0 ~56 ~49 ~0 ~56 oak_stairs 2  
fill ~49 ~0 ~5 ~49 ~6 ~5 stained_hardened_clay 13 
setblock ~49 ~0 ~8 carpet 4  
fill ~49 ~0 ~9 ~51 ~0 ~9 carpet 13  
fill ~49 ~0 ~10 ~51 ~0 ~10 carpet 13  
fill ~49 ~0 ~11 ~50 ~0 ~11 carpet 4 
setblock ~49 ~0 ~13 oak_stairs 6 
setblock ~49 ~0 ~14 planks 0  
fill ~49 ~0 ~15 ~50 ~0 ~15 oak_stairs 7  
fill ~49 ~0 ~16 ~50 ~0 ~16 oak_stairs 2 
setblock ~49 ~0 ~17 carpet 4 
setblock ~49 ~0 ~18 carpet 13  
fill ~49 ~0 ~28 ~54 ~0 ~28 bookshelf 0  
fill ~49 ~0 ~29 ~54 ~0 ~29 bookshelf 0  
fill ~49 ~0 ~33 ~54 ~0 ~33 bookshelf 0  
fill ~49 ~0 ~34 ~54 ~0 ~34 bookshelf 0 
setblock ~49 ~0 ~44 carpet 13 
setblock ~49 ~0 ~45 carpet 4  
fill ~49 ~0 ~46 ~50 ~0 ~46 oak_stairs 3  
fill ~49 ~0 ~47 ~50 ~0 ~47 oak_stairs 6 
setblock ~49 ~0 ~48 planks 0 
setblock ~49 ~0 ~49 oak_stairs 7  
fill ~49 ~0 ~51 ~50 ~0 ~51 carpet 4  
fill ~49 ~0 ~52 ~51 ~0 ~52 carpet 13  
fill ~49 ~0 ~53 ~51 ~0 ~53 carpet 13 
setblock ~49 ~0 ~54 carpet 4 
setblock ~49 ~0 ~55 carpet 13  
fill ~49 ~0 ~57 ~49 ~6 ~57 stained_hardened_clay 13  
fill ~50 ~0 ~6 ~51 ~0 ~6 stained_hardened_clay 13 
setblock ~50 ~0 ~7 oak_stairs 1 
setblock ~50 ~0 ~8 carpet 13  
fill ~50 ~0 ~12 ~54 ~0 ~12 carpet 13  
fill ~50 ~0 ~13 ~51 ~0 ~13 carpet 13 
setblock ~50 ~0 ~14 oak_stairs 5  
fill ~50 ~0 ~17 ~52 ~0 ~17 carpet 13 
setblock ~50 ~0 ~18 oak_stairs 1  
fill ~50 ~0 ~19 ~53 ~0 ~19 bookshelf 0  
fill ~50 ~0 ~21 ~53 ~0 ~21 carpet 13  
fill ~50 ~0 ~22 ~53 ~0 ~22 carpet 4  
fill ~50 ~0 ~23 ~53 ~0 ~23 carpet 13  
fill ~50 ~0 ~24 ~57 ~0 ~24 bookshelf 0  
fill ~50 ~0 ~38 ~57 ~0 ~38 bookshelf 0  
fill ~50 ~0 ~39 ~53 ~0 ~39 carpet 13  
fill ~50 ~0 ~40 ~53 ~0 ~40 carpet 4  
fill ~50 ~0 ~41 ~53 ~0 ~41 carpet 13  
fill ~50 ~0 ~43 ~53 ~0 ~43 bookshelf 0 
setblock ~50 ~0 ~44 oak_stairs 1  
fill ~50 ~0 ~45 ~53 ~0 ~45 carpet 13 
setblock ~50 ~0 ~48 oak_stairs 5  
fill ~50 ~0 ~49 ~51 ~0 ~49 carpet 13  
fill ~50 ~0 ~50 ~54 ~0 ~50 carpet 13 
setblock ~50 ~0 ~54 carpet 13 
setblock ~50 ~0 ~55 oak_stairs 1  
fill ~50 ~0 ~56 ~51 ~0 ~56 stained_hardened_clay 13 
setblock ~51 ~0 ~7 oak_stairs 3 
setblock ~51 ~0 ~8 fence 0 
setblock ~51 ~0 ~11 carpet 13  
fill ~51 ~0 ~14 ~51 ~0 ~15 oak_stairs 0  
fill ~51 ~0 ~16 ~53 ~0 ~16 carpet 13 
setblock ~51 ~0 ~18 fence 0 
setblock ~51 ~0 ~44 fence 0  
fill ~51 ~0 ~46 ~53 ~0 ~46 carpet 13  
fill ~51 ~0 ~47 ~51 ~0 ~48 oak_stairs 0 
setblock ~51 ~0 ~51 carpet 13 
setblock ~51 ~0 ~54 fence 0 
setblock ~51 ~0 ~55 oak_stairs 2  
fill ~52 ~0 ~7 ~52 ~1 ~7 stained_hardened_clay 13  
fill ~52 ~0 ~8 ~52 ~2 ~8 bookshelf 0  
fill ~52 ~0 ~9 ~53 ~0 ~9 bookshelf 0 
setblock ~52 ~0 ~10 oak_stairs 3 
setblock ~52 ~0 ~11 fence 0  
fill ~52 ~0 ~13 ~52 ~0 ~14 carpet 4 
setblock ~52 ~0 ~15 carpet 13  
fill ~52 ~0 ~18 ~55 ~0 ~18 bookshelf 0  
fill ~52 ~0 ~20 ~55 ~0 ~20 carpet 13  
fill ~52 ~0 ~42 ~55 ~0 ~42 carpet 13  
fill ~52 ~0 ~44 ~55 ~0 ~44 bookshelf 0 
setblock ~52 ~0 ~47 carpet 13  
fill ~52 ~0 ~48 ~52 ~0 ~49 carpet 4 
setblock ~52 ~0 ~51 fence 0  
fill ~52 ~0 ~52 ~53 ~0 ~52 oak_stairs 2  
fill ~52 ~0 ~53 ~53 ~0 ~53 bookshelf 0  
fill ~52 ~0 ~54 ~52 ~2 ~54 bookshelf 0  
fill ~52 ~0 ~55 ~52 ~1 ~55 stained_hardened_clay 13  
fill ~53 ~0 ~8 ~53 ~2 ~8 stained_hardened_clay 13  
fill ~53 ~0 ~10 ~53 ~0 ~11 oak_stairs 0  
fill ~53 ~0 ~13 ~55 ~0 ~13 carpet 13  
fill ~53 ~0 ~14 ~54 ~0 ~14 carpet 13  
fill ~53 ~0 ~15 ~54 ~0 ~15 carpet 4  
fill ~53 ~0 ~47 ~54 ~0 ~47 carpet 4  
fill ~53 ~0 ~48 ~54 ~0 ~48 carpet 13  
fill ~53 ~0 ~49 ~55 ~0 ~49 carpet 13 
setblock ~53 ~0 ~51 oak_stairs 0  
fill ~53 ~0 ~54 ~53 ~2 ~54 stained_hardened_clay 13  
fill ~54 ~0 ~9 ~54 ~3 ~9 stained_hardened_clay 13  
fill ~54 ~0 ~10 ~54 ~3 ~10 bookshelf 0  
fill ~54 ~0 ~11 ~55 ~0 ~11 bookshelf 0 
setblock ~54 ~0 ~16 oak_stairs 1  
fill ~54 ~0 ~17 ~57 ~0 ~17 bookshelf 0 
setblock ~54 ~0 ~19 fence 0  
fill ~54 ~0 ~21 ~55 ~0 ~21 carpet 4  
fill ~54 ~0 ~22 ~55 ~0 ~22 carpet 13  
fill ~54 ~0 ~23 ~61 ~0 ~23 bookshelf 0  
fill ~54 ~0 ~26 ~54 ~7 ~26 bookshelf 0  
fill ~54 ~0 ~27 ~54 ~7 ~27 bookshelf 0  
fill ~54 ~0 ~35 ~54 ~7 ~35 bookshelf 0  
fill ~54 ~0 ~36 ~54 ~7 ~36 bookshelf 0  
fill ~54 ~0 ~39 ~61 ~0 ~39 bookshelf 0  
fill ~54 ~0 ~40 ~55 ~0 ~40 carpet 13  
fill ~54 ~0 ~41 ~55 ~0 ~41 carpet 4 
setblock ~54 ~0 ~43 fence 0  
fill ~54 ~0 ~45 ~57 ~0 ~45 bookshelf 0 
setblock ~54 ~0 ~46 oak_stairs 1  
fill ~54 ~0 ~51 ~55 ~0 ~51 bookshelf 0  
fill ~54 ~0 ~52 ~54 ~3 ~52 bookshelf 0  
fill ~54 ~0 ~53 ~54 ~3 ~53 stained_hardened_clay 13  
fill ~55 ~0 ~10 ~55 ~2 ~10 stained_hardened_clay 13 
setblock ~55 ~0 ~12 fence 0 
setblock ~55 ~0 ~14 carpet 4  
fill ~55 ~0 ~15 ~56 ~0 ~15 carpet 13 
setblock ~55 ~0 ~16 fence 0 
setblock ~55 ~0 ~19 oak_stairs 0  
fill ~55 ~0 ~25 ~55 ~0 ~27 oak_stairs 1 
setblock ~55 ~0 ~28 oak_stairs 2 
setblock ~55 ~0 ~34 oak_stairs 3  
fill ~55 ~0 ~35 ~55 ~0 ~37 oak_stairs 1 
setblock ~55 ~0 ~43 oak_stairs 0 
setblock ~55 ~0 ~46 fence 0  
fill ~55 ~0 ~47 ~56 ~0 ~47 carpet 13 
setblock ~55 ~0 ~48 carpet 4 
setblock ~55 ~0 ~50 fence 0  
fill ~55 ~0 ~52 ~55 ~2 ~52 stained_hardened_clay 13  
fill ~56 ~0 ~11 ~56 ~1 ~11 stained_hardened_clay 13 
setblock ~56 ~0 ~12 oak_stairs 0 
setblock ~56 ~0 ~13 oak_stairs 2 
setblock ~56 ~0 ~14 carpet 13  
fill ~56 ~0 ~16 ~58 ~0 ~16 bookshelf 0  
fill ~56 ~0 ~18 ~57 ~0 ~18 carpet 13  
fill ~56 ~0 ~19 ~56 ~0 ~18 carpet 13 
setblock ~56 ~0 ~20 carpet 4  
fill ~56 ~0 ~21 ~59 ~0 ~21 carpet 13 
setblock ~56 ~0 ~22 oak_stairs 1 
setblock ~56 ~0 ~25 oak_stairs 3  
fill ~56 ~0 ~26 ~56 ~0 ~27 fence 0  
fill ~56 ~0 ~35 ~56 ~0 ~36 fence 0 
setblock ~56 ~0 ~37 oak_stairs 2 
setblock ~56 ~0 ~40 oak_stairs 1  
fill ~56 ~0 ~41 ~59 ~0 ~41 carpet 13 
setblock ~56 ~0 ~42 carpet 4  
fill ~56 ~0 ~43 ~56 ~0 ~44 carpet 13  
fill ~56 ~0 ~46 ~58 ~0 ~46 bookshelf 0 
setblock ~56 ~0 ~48 carpet 13 
setblock ~56 ~0 ~49 oak_stairs 3 
setblock ~56 ~0 ~50 oak_stairs 0  
fill ~56 ~0 ~51 ~56 ~1 ~51 stained_hardened_clay 13  
fill ~57 ~0 ~12 ~57 ~0 ~13 stained_hardened_clay 13  
fill ~57 ~0 ~14 ~57 ~0 ~15 oak_stairs 0  
fill ~57 ~0 ~19 ~58 ~0 ~19 carpet 4  
fill ~57 ~0 ~20 ~58 ~0 ~20 carpet 13 
setblock ~57 ~0 ~22 fence 0 
setblock ~57 ~0 ~40 fence 0  
fill ~57 ~0 ~42 ~58 ~0 ~42 carpet 13  
fill ~57 ~0 ~43 ~58 ~0 ~43 carpet 4 
setblock ~57 ~0 ~44 carpet 13  
fill ~57 ~0 ~47 ~57 ~0 ~48 oak_stairs 0  
fill ~57 ~0 ~49 ~57 ~1 ~49 stained_hardened_clay 13  
fill ~57 ~0 ~50 ~57 ~0 ~49 stained_hardened_clay 13  
fill ~58 ~0 ~14 ~58 ~6 ~14 stained_hardened_clay 13  
fill ~58 ~0 ~15 ~58 ~7 ~15 bookshelf 0 
setblock ~58 ~0 ~17 oak_stairs 3 
setblock ~58 ~0 ~18 fence 0  
fill ~58 ~0 ~22 ~61 ~0 ~22 bookshelf 0 
setblock ~58 ~0 ~24 oak_stairs 1 
setblock ~58 ~0 ~30 oak_stairs 1 
setblock ~58 ~0 ~32 oak_stairs 1  
fill ~58 ~0 ~40 ~61 ~0 ~40 bookshelf 0 
setblock ~58 ~0 ~44 fence 0 
setblock ~58 ~0 ~45 oak_stairs 2  
fill ~58 ~0 ~47 ~58 ~7 ~47 bookshelf 0  
fill ~58 ~0 ~48 ~58 ~6 ~48 stained_hardened_clay 13  
fill ~59 ~0 ~15 ~59 ~7 ~15 stained_hardened_clay 13  
fill ~59 ~0 ~16 ~59 ~9 ~16 stained_hardened_clay 13  
fill ~59 ~0 ~17 ~59 ~0 ~18 oak_stairs 0 
setblock ~59 ~0 ~19 carpet 13 
setblock ~59 ~0 ~20 fence 0  
fill ~59 ~0 ~24 ~60 ~0 ~24 oak_stairs 3 
setblock ~59 ~0 ~29 oak_stairs 3  
fill ~59 ~0 ~30 ~59 ~0 ~32 fence 0 
setblock ~59 ~0 ~33 oak_stairs 2 
setblock ~59 ~0 ~42 fence 0 
setblock ~59 ~0 ~43 carpet 13  
fill ~59 ~0 ~44 ~59 ~0 ~45 oak_stairs 0  
fill ~59 ~0 ~46 ~59 ~9 ~46 stained_hardened_clay 13  
fill ~59 ~0 ~47 ~59 ~7 ~47 stained_hardened_clay 13  
fill ~60 ~0 ~17 ~60 ~10 ~17 stained_hardened_clay 13  
fill ~60 ~0 ~18 ~60 ~2 ~18 stained_hardened_clay 13 
setblock ~60 ~0 ~19 oak_stairs 3 
setblock ~60 ~0 ~20 oak_stairs 0 
setblock ~60 ~0 ~21 oak_stairs 2 
setblock ~60 ~0 ~30 oak_stairs 0 
setblock ~60 ~0 ~32 oak_stairs 0 
setblock ~60 ~0 ~41 oak_stairs 3 
setblock ~60 ~0 ~42 oak_stairs 0 
setblock ~60 ~0 ~43 oak_stairs 2  
fill ~60 ~0 ~44 ~60 ~2 ~44 stained_hardened_clay 13  
fill ~60 ~0 ~45 ~60 ~10 ~45 stained_hardened_clay 13  
fill ~61 ~0 ~19 ~61 ~1 ~19 stained_hardened_clay 13  
fill ~61 ~0 ~20 ~61 ~2 ~20 stained_hardened_clay 13  
fill ~61 ~0 ~21 ~61 ~3 ~21 stained_hardened_clay 13 
setblock ~61 ~0 ~24 oak_stairs 0 
setblock ~61 ~0 ~27 fence 0 
setblock ~61 ~0 ~35 fence 0  
fill ~61 ~0 ~41 ~61 ~3 ~41 stained_hardened_clay 13  
fill ~61 ~0 ~42 ~61 ~2 ~42 stained_hardened_clay 13  
fill ~61 ~0 ~43 ~61 ~1 ~43 stained_hardened_clay 13  
fill ~62 ~0 ~22 ~62 ~3 ~22 stained_hardened_clay 13  
fill ~62 ~0 ~23 ~62 ~4 ~23 stained_hardened_clay 13  
fill ~62 ~0 ~24 ~62 ~4 ~24 stained_hardened_clay 13  
fill ~62 ~0 ~25 ~62 ~5 ~25 stained_hardened_clay 13 
setblock ~62 ~0 ~26 oak_stairs 3 
setblock ~62 ~0 ~27 oak_stairs 0 
setblock ~62 ~0 ~28 oak_stairs 2  
fill ~62 ~0 ~29 ~62 ~0 ~33 bookshelf 0 
setblock ~62 ~0 ~34 oak_stairs 3 
setblock ~62 ~0 ~35 oak_stairs 0 
setblock ~62 ~0 ~36 oak_stairs 2  
fill ~62 ~0 ~37 ~62 ~5 ~37 stained_hardened_clay 13  
fill ~62 ~0 ~38 ~62 ~4 ~38 stained_hardened_clay 13  
fill ~62 ~0 ~39 ~62 ~4 ~39 stained_hardened_clay 13  
fill ~62 ~0 ~40 ~62 ~3 ~40 stained_hardened_clay 13 
setblock ~62 ~0 ~62 stained_hardened_clay 4 
setblock ~63 ~0 ~0 planks 0  
fill ~63 ~0 ~26 ~63 ~6 ~26 stained_hardened_clay 13  
fill ~63 ~0 ~27 ~63 ~0 ~36 stained_hardened_clay 13 
setblock ~1 ~1 ~30 wooden_door 8 
setblock ~1 ~1 ~32 wooden_door 9  
fill ~2 ~1 ~28 ~6 ~1 ~28 bookshelf 0  
fill ~2 ~1 ~29 ~6 ~1 ~29 bookshelf 0  
fill ~2 ~1 ~33 ~6 ~1 ~33 bookshelf 0  
fill ~2 ~1 ~34 ~6 ~1 ~34 bookshelf 0  
fill ~3 ~1 ~20 ~3 ~1 ~21 stained_hardened_clay 4  
fill ~3 ~1 ~22 ~6 ~1 ~22 bookshelf 0  
fill ~3 ~1 ~23 ~10 ~1 ~23 bookshelf 0  
fill ~3 ~1 ~39 ~10 ~1 ~39 bookshelf 0  
fill ~3 ~1 ~40 ~6 ~1 ~40 bookshelf 0  
fill ~3 ~1 ~41 ~3 ~1 ~42 stained_hardened_clay 4 
setblock ~3 ~1 ~43 stained_hardened_clay 13 
setblock ~5 ~1 ~20 light_weighted_pressure_plate 0 
setblock ~5 ~1 ~42 light_weighted_pressure_plate 0  
fill ~6 ~1 ~16 ~8 ~1 ~16 bookshelf 0 
setblock ~6 ~1 ~18 light_weighted_pressure_plate 0 
setblock ~6 ~1 ~44 light_weighted_pressure_plate 0  
fill ~6 ~1 ~46 ~8 ~1 ~46 bookshelf 0 
setblock ~7 ~1 ~12 stained_hardened_clay 4 
setblock ~7 ~1 ~13 stained_hardened_clay 13  
fill ~7 ~1 ~17 ~10 ~1 ~17 bookshelf 0 
setblock ~7 ~1 ~22 light_weighted_pressure_plate 0  
fill ~7 ~1 ~24 ~14 ~1 ~24 bookshelf 0  
fill ~7 ~1 ~38 ~14 ~1 ~38 bookshelf 0 
setblock ~7 ~1 ~40 light_weighted_pressure_plate 0  
fill ~7 ~1 ~45 ~10 ~1 ~45 bookshelf 0 
setblock ~7 ~1 ~50 stained_hardened_clay 4  
fill ~9 ~1 ~11 ~10 ~1 ~11 bookshelf 0 
setblock ~9 ~1 ~12 light_weighted_pressure_plate 0 
setblock ~9 ~1 ~16 light_weighted_pressure_plate 0  
fill ~9 ~1 ~18 ~12 ~1 ~18 bookshelf 0  
fill ~9 ~1 ~44 ~12 ~1 ~44 bookshelf 0 
setblock ~9 ~1 ~46 light_weighted_pressure_plate 0 
setblock ~9 ~1 ~50 light_weighted_pressure_plate 0  
fill ~9 ~1 ~51 ~10 ~1 ~51 bookshelf 0 
setblock ~10 ~1 ~19 light_weighted_pressure_plate 0  
fill ~10 ~1 ~28 ~15 ~1 ~28 bookshelf 0  
fill ~10 ~1 ~29 ~15 ~1 ~29 bookshelf 0  
fill ~10 ~1 ~33 ~15 ~1 ~33 bookshelf 0  
fill ~10 ~1 ~34 ~15 ~1 ~34 bookshelf 0 
setblock ~10 ~1 ~43 light_weighted_pressure_plate 0  
fill ~11 ~1 ~9 ~12 ~1 ~9 bookshelf 0  
fill ~11 ~1 ~19 ~14 ~1 ~19 bookshelf 0  
fill ~11 ~1 ~25 ~17 ~1 ~25 bookshelf 0  
fill ~11 ~1 ~37 ~17 ~1 ~37 bookshelf 0  
fill ~11 ~1 ~43 ~14 ~1 ~43 bookshelf 0  
fill ~11 ~1 ~53 ~12 ~1 ~53 bookshelf 0 
setblock ~12 ~1 ~11 light_weighted_pressure_plate 0 
setblock ~12 ~1 ~51 light_weighted_pressure_plate 0 
setblock ~13 ~1 ~6 stained_hardened_clay 4 
setblock ~13 ~1 ~8 light_weighted_pressure_plate 0 
setblock ~13 ~1 ~18 light_weighted_pressure_plate 0  
fill ~13 ~1 ~20 ~16 ~1 ~20 bookshelf 0  
fill ~13 ~1 ~42 ~16 ~1 ~42 bookshelf 0 
setblock ~13 ~1 ~44 light_weighted_pressure_plate 0 
setblock ~13 ~1 ~54 light_weighted_pressure_plate 0 
setblock ~13 ~1 ~56 stained_hardened_clay 4 
setblock ~14 ~1 ~6 stained_hardened_clay 13 
setblock ~14 ~1 ~56 stained_hardened_clay 13  
fill ~15 ~1 ~21 ~18 ~1 ~21 bookshelf 0  
fill ~15 ~1 ~41 ~18 ~1 ~41 bookshelf 0  
fill ~16 ~1 ~4 ~17 ~1 ~4 stained_hardened_clay 13  
fill ~16 ~1 ~5 ~17 ~1 ~5 bookshelf 0  
fill ~16 ~1 ~57 ~17 ~1 ~57 bookshelf 0  
fill ~16 ~1 ~58 ~17 ~1 ~58 stained_hardened_clay 13  
fill ~17 ~1 ~6 ~18 ~1 ~6 bookshelf 0  
fill ~17 ~1 ~7 ~18 ~1 ~7 bookshelf 0 
setblock ~17 ~1 ~8 light_weighted_pressure_plate 0 
setblock ~17 ~1 ~20 light_weighted_pressure_plate 0  
fill ~17 ~1 ~22 ~20 ~1 ~22 bookshelf 0  
fill ~17 ~1 ~40 ~20 ~1 ~40 bookshelf 0 
setblock ~17 ~1 ~42 light_weighted_pressure_plate 0 
setblock ~17 ~1 ~54 light_weighted_pressure_plate 0  
fill ~17 ~1 ~55 ~18 ~1 ~55 bookshelf 0  
fill ~17 ~1 ~56 ~18 ~1 ~56 bookshelf 0  
fill ~18 ~1 ~3 ~19 ~1 ~3 stained_hardened_clay 13  
fill ~18 ~1 ~8 ~19 ~1 ~8 bookshelf 0  
fill ~18 ~1 ~9 ~19 ~1 ~9 bookshelf 0  
fill ~18 ~1 ~53 ~19 ~1 ~53 bookshelf 0  
fill ~18 ~1 ~54 ~19 ~1 ~54 bookshelf 0  
fill ~18 ~1 ~59 ~19 ~1 ~59 stained_hardened_clay 13 
setblock ~19 ~1 ~5 light_weighted_pressure_plate 0  
fill ~19 ~1 ~10 ~20 ~1 ~10 bookshelf 0  
fill ~19 ~1 ~11 ~20 ~1 ~11 bookshelf 0 
setblock ~19 ~1 ~12 light_weighted_pressure_plate 0  
fill ~19 ~1 ~23 ~22 ~1 ~23 bookshelf 0  
fill ~19 ~1 ~28 ~24 ~1 ~28 bookshelf 0  
fill ~19 ~1 ~29 ~24 ~1 ~29 bookshelf 0  
fill ~19 ~1 ~33 ~24 ~1 ~33 bookshelf 0  
fill ~19 ~1 ~34 ~24 ~1 ~34 bookshelf 0  
fill ~19 ~1 ~39 ~22 ~1 ~39 bookshelf 0 
setblock ~19 ~1 ~50 light_weighted_pressure_plate 0  
fill ~19 ~1 ~51 ~20 ~1 ~51 bookshelf 0  
fill ~19 ~1 ~52 ~20 ~1 ~52 bookshelf 0 
setblock ~19 ~1 ~57 light_weighted_pressure_plate 0  
fill ~20 ~1 ~2 ~22 ~1 ~2 stained_hardened_clay 13 
setblock ~20 ~1 ~9 light_weighted_pressure_plate 0  
fill ~20 ~1 ~12 ~21 ~1 ~12 bookshelf 0  
fill ~20 ~1 ~13 ~21 ~1 ~13 bookshelf 0  
fill ~20 ~1 ~49 ~21 ~1 ~49 bookshelf 0  
fill ~20 ~1 ~50 ~21 ~1 ~50 bookshelf 0 
setblock ~20 ~1 ~53 light_weighted_pressure_plate 0  
fill ~20 ~1 ~60 ~22 ~1 ~60 stained_hardened_clay 13 
setblock ~21 ~1 ~4 light_weighted_pressure_plate 0  
fill ~21 ~1 ~14 ~22 ~1 ~14 bookshelf 0  
fill ~21 ~1 ~15 ~22 ~1 ~15 bookshelf 0 
setblock ~21 ~1 ~16 light_weighted_pressure_plate 0  
fill ~21 ~1 ~24 ~23 ~1 ~24 bookshelf 0  
fill ~21 ~1 ~38 ~23 ~1 ~38 bookshelf 0 
setblock ~21 ~1 ~46 light_weighted_pressure_plate 0  
fill ~21 ~1 ~47 ~22 ~1 ~47 bookshelf 0  
fill ~21 ~1 ~48 ~22 ~1 ~48 bookshelf 0 
setblock ~21 ~1 ~58 light_weighted_pressure_plate 0  
fill ~22 ~1 ~16 ~23 ~1 ~16 bookshelf 0  
fill ~22 ~1 ~17 ~23 ~1 ~17 bookshelf 0  
fill ~22 ~1 ~45 ~23 ~1 ~45 bookshelf 0  
fill ~22 ~1 ~46 ~23 ~1 ~46 bookshelf 0  
fill ~23 ~1 ~1 ~26 ~1 ~1 stained_hardened_clay 13  
fill ~23 ~1 ~2 ~24 ~1 ~2 bookshelf 0  
fill ~23 ~1 ~3 ~24 ~1 ~3 bookshelf 0  
fill ~23 ~1 ~4 ~24 ~1 ~4 bookshelf 0  
fill ~23 ~1 ~5 ~24 ~1 ~5 bookshelf 0 
setblock ~23 ~1 ~6 light_weighted_pressure_plate 0  
fill ~23 ~1 ~18 ~24 ~1 ~18 bookshelf 0  
fill ~23 ~1 ~19 ~24 ~1 ~19 bookshelf 0  
fill ~23 ~1 ~43 ~24 ~1 ~43 bookshelf 0  
fill ~23 ~1 ~44 ~24 ~1 ~44 bookshelf 0 
setblock ~23 ~1 ~56 light_weighted_pressure_plate 0  
fill ~23 ~1 ~57 ~24 ~1 ~57 bookshelf 0  
fill ~23 ~1 ~58 ~24 ~1 ~58 bookshelf 0  
fill ~23 ~1 ~59 ~24 ~1 ~59 bookshelf 0  
fill ~23 ~1 ~60 ~24 ~1 ~60 bookshelf 0  
fill ~23 ~1 ~61 ~26 ~1 ~61 stained_hardened_clay 13  
fill ~24 ~1 ~6 ~25 ~1 ~6 bookshelf 0  
fill ~24 ~1 ~7 ~25 ~1 ~7 bookshelf 0  
fill ~24 ~1 ~8 ~25 ~1 ~8 bookshelf 0  
fill ~24 ~1 ~9 ~30 ~1 ~9 bookshelf 0  
fill ~24 ~1 ~20 ~25 ~1 ~20 bookshelf 0  
fill ~24 ~1 ~21 ~25 ~1 ~21 bookshelf 0  
fill ~24 ~1 ~41 ~25 ~1 ~41 bookshelf 0  
fill ~24 ~1 ~42 ~25 ~1 ~42 bookshelf 0  
fill ~24 ~1 ~53 ~30 ~1 ~53 bookshelf 0  
fill ~24 ~1 ~54 ~25 ~1 ~54 bookshelf 0  
fill ~24 ~1 ~55 ~25 ~1 ~55 bookshelf 0  
fill ~24 ~1 ~56 ~25 ~1 ~56 bookshelf 0  
fill ~25 ~1 ~10 ~26 ~1 ~10 bookshelf 0  
fill ~25 ~1 ~11 ~26 ~1 ~11 bookshelf 0  
fill ~25 ~1 ~12 ~26 ~1 ~12 bookshelf 0  
fill ~25 ~1 ~13 ~26 ~1 ~13 bookshelf 0  
fill ~25 ~1 ~22 ~26 ~1 ~22 bookshelf 0  
fill ~25 ~1 ~40 ~26 ~1 ~40 bookshelf 0  
fill ~25 ~1 ~49 ~26 ~1 ~49 bookshelf 0  
fill ~25 ~1 ~50 ~26 ~1 ~50 bookshelf 0  
fill ~25 ~1 ~51 ~26 ~1 ~51 bookshelf 0  
fill ~25 ~1 ~52 ~26 ~1 ~52 bookshelf 0  
fill ~27 ~1 ~0 ~27 ~6 ~0 stained_hardened_clay 13  
fill ~27 ~1 ~7 ~28 ~1 ~7 light_weighted_pressure_plate 0  
fill ~27 ~1 ~55 ~28 ~1 ~55 light_weighted_pressure_plate 0  
fill ~27 ~1 ~62 ~27 ~6 ~62 stained_hardened_clay 13 
setblock ~28 ~1 ~0 stained_hardened_clay 4 
setblock ~28 ~1 ~2 light_weighted_pressure_plate 0 
setblock ~28 ~1 ~60 light_weighted_pressure_plate 0 
setblock ~28 ~1 ~62 stained_hardened_clay 4  
fill ~29 ~1 ~0 ~35 ~1 ~0 stained_hardened_clay 13  
fill ~29 ~1 ~10 ~30 ~1 ~10 bookshelf 0  
fill ~29 ~1 ~11 ~30 ~1 ~11 bookshelf 0  
fill ~29 ~1 ~12 ~30 ~1 ~12 bookshelf 0  
fill ~29 ~1 ~13 ~30 ~1 ~13 bookshelf 0  
fill ~29 ~1 ~14 ~30 ~1 ~14 bookshelf 0  
fill ~29 ~1 ~18 ~30 ~1 ~18 bookshelf 0  
fill ~29 ~1 ~19 ~30 ~1 ~19 bookshelf 0  
fill ~29 ~1 ~20 ~30 ~1 ~20 bookshelf 0  
fill ~29 ~1 ~21 ~30 ~1 ~21 bookshelf 0  
fill ~29 ~1 ~22 ~30 ~1 ~22 bookshelf 0  
fill ~29 ~1 ~23 ~30 ~1 ~23 bookshelf 0  
fill ~29 ~1 ~39 ~30 ~1 ~39 bookshelf 0  
fill ~29 ~1 ~40 ~30 ~1 ~40 bookshelf 0  
fill ~29 ~1 ~41 ~30 ~1 ~41 bookshelf 0  
fill ~29 ~1 ~42 ~30 ~1 ~42 bookshelf 0  
fill ~29 ~1 ~43 ~30 ~1 ~43 bookshelf 0  
fill ~29 ~1 ~44 ~30 ~1 ~44 bookshelf 0  
fill ~29 ~1 ~48 ~30 ~1 ~48 bookshelf 0  
fill ~29 ~1 ~49 ~30 ~1 ~49 bookshelf 0  
fill ~29 ~1 ~50 ~30 ~1 ~50 bookshelf 0  
fill ~29 ~1 ~51 ~30 ~1 ~51 bookshelf 0  
fill ~29 ~1 ~52 ~30 ~1 ~52 bookshelf 0  
fill ~29 ~1 ~62 ~35 ~1 ~62 stained_hardened_clay 13 
setblock ~30 ~1 ~1 oak_stairs 0 
setblock ~30 ~1 ~61 oak_stairs 0  
fill ~31 ~1 ~1 ~33 ~1 ~1 bookshelf 0  
fill ~31 ~1 ~4 ~33 ~1 ~4 light_weighted_pressure_plate 0  
fill ~31 ~1 ~58 ~33 ~1 ~58 light_weighted_pressure_plate 0  
fill ~31 ~1 ~61 ~33 ~1 ~61 bookshelf 0  
fill ~33 ~1 ~31 ~33 ~5 ~31 bookshelf 0 
setblock ~34 ~1 ~1 oak_stairs 1  
fill ~34 ~1 ~9 ~40 ~1 ~9 bookshelf 0  
fill ~34 ~1 ~10 ~35 ~1 ~10 bookshelf 0  
fill ~34 ~1 ~11 ~35 ~1 ~11 bookshelf 0  
fill ~34 ~1 ~12 ~35 ~1 ~12 bookshelf 0  
fill ~34 ~1 ~13 ~35 ~1 ~13 bookshelf 0  
fill ~34 ~1 ~14 ~35 ~1 ~14 bookshelf 0  
fill ~34 ~1 ~18 ~35 ~1 ~18 bookshelf 0  
fill ~34 ~1 ~19 ~35 ~1 ~19 bookshelf 0  
fill ~34 ~1 ~20 ~35 ~1 ~20 bookshelf 0  
fill ~34 ~1 ~21 ~35 ~1 ~21 bookshelf 0  
fill ~34 ~1 ~22 ~35 ~1 ~22 bookshelf 0  
fill ~34 ~1 ~23 ~35 ~1 ~23 bookshelf 0  
fill ~34 ~1 ~30 ~35 ~1 ~30 oak_stairs 6 
setblock ~34 ~1 ~31 spruce_stairs 3  
fill ~34 ~1 ~39 ~35 ~1 ~39 bookshelf 0  
fill ~34 ~1 ~40 ~35 ~1 ~40 bookshelf 0  
fill ~34 ~1 ~41 ~35 ~1 ~41 bookshelf 0  
fill ~34 ~1 ~42 ~35 ~1 ~42 bookshelf 0  
fill ~34 ~1 ~43 ~35 ~1 ~43 bookshelf 0  
fill ~34 ~1 ~44 ~35 ~1 ~44 bookshelf 0  
fill ~34 ~1 ~48 ~35 ~1 ~48 bookshelf 0  
fill ~34 ~1 ~49 ~35 ~1 ~49 bookshelf 0  
fill ~34 ~1 ~50 ~35 ~1 ~50 bookshelf 0  
fill ~34 ~1 ~51 ~35 ~1 ~51 bookshelf 0  
fill ~34 ~1 ~52 ~35 ~1 ~52 bookshelf 0  
fill ~34 ~1 ~53 ~40 ~1 ~53 bookshelf 0 
setblock ~34 ~1 ~61 oak_stairs 1 
setblock ~35 ~1 ~31 oak_stairs 3 
setblock ~36 ~1 ~0 stained_hardened_clay 4 
setblock ~36 ~1 ~2 light_weighted_pressure_plate 0  
fill ~36 ~1 ~7 ~37 ~1 ~7 light_weighted_pressure_plate 0  
fill ~36 ~1 ~55 ~37 ~1 ~55 light_weighted_pressure_plate 0 
setblock ~36 ~1 ~60 light_weighted_pressure_plate 0 
setblock ~36 ~1 ~62 stained_hardened_clay 4  
fill ~37 ~1 ~0 ~37 ~6 ~0 stained_hardened_clay 13  
fill ~37 ~1 ~62 ~37 ~6 ~62 stained_hardened_clay 13  
fill ~38 ~1 ~1 ~41 ~1 ~1 stained_hardened_clay 13  
fill ~38 ~1 ~10 ~39 ~1 ~10 bookshelf 0  
fill ~38 ~1 ~11 ~39 ~1 ~11 bookshelf 0  
fill ~38 ~1 ~12 ~39 ~1 ~12 bookshelf 0  
fill ~38 ~1 ~13 ~39 ~1 ~13 bookshelf 0  
fill ~38 ~1 ~22 ~39 ~1 ~22 bookshelf 0  
fill ~38 ~1 ~40 ~39 ~1 ~40 bookshelf 0  
fill ~38 ~1 ~49 ~39 ~1 ~49 bookshelf 0  
fill ~38 ~1 ~50 ~39 ~1 ~50 bookshelf 0  
fill ~38 ~1 ~51 ~39 ~1 ~51 bookshelf 0  
fill ~38 ~1 ~52 ~39 ~1 ~52 bookshelf 0  
fill ~38 ~1 ~61 ~41 ~1 ~61 stained_hardened_clay 13  
fill ~39 ~1 ~6 ~40 ~1 ~6 bookshelf 0  
fill ~39 ~1 ~7 ~40 ~1 ~7 bookshelf 0  
fill ~39 ~1 ~8 ~40 ~1 ~8 bookshelf 0  
fill ~39 ~1 ~20 ~40 ~1 ~20 bookshelf 0  
fill ~39 ~1 ~21 ~40 ~1 ~21 bookshelf 0  
fill ~39 ~1 ~41 ~40 ~1 ~41 bookshelf 0  
fill ~39 ~1 ~42 ~40 ~1 ~42 bookshelf 0  
fill ~39 ~1 ~54 ~40 ~1 ~54 bookshelf 0  
fill ~39 ~1 ~55 ~40 ~1 ~55 bookshelf 0  
fill ~39 ~1 ~56 ~40 ~1 ~56 bookshelf 0  
fill ~40 ~1 ~2 ~41 ~1 ~2 bookshelf 0  
fill ~40 ~1 ~3 ~41 ~1 ~3 bookshelf 0  
fill ~40 ~1 ~4 ~41 ~1 ~4 bookshelf 0  
fill ~40 ~1 ~5 ~41 ~1 ~5 bookshelf 0  
fill ~40 ~1 ~18 ~41 ~1 ~18 bookshelf 0  
fill ~40 ~1 ~19 ~41 ~1 ~19 bookshelf 0  
fill ~40 ~1 ~28 ~45 ~1 ~28 bookshelf 0  
fill ~40 ~1 ~29 ~45 ~1 ~29 bookshelf 0  
fill ~40 ~1 ~33 ~45 ~1 ~33 bookshelf 0  
fill ~40 ~1 ~34 ~45 ~1 ~34 bookshelf 0  
fill ~40 ~1 ~43 ~41 ~1 ~43 bookshelf 0  
fill ~40 ~1 ~44 ~41 ~1 ~44 bookshelf 0
fill ~40 ~1 ~57 ~41 ~1 ~57 bookshelf 0  
fill ~40 ~1 ~58 ~41 ~1 ~58 bookshelf 0  
fill ~40 ~1 ~59 ~41 ~1 ~59 bookshelf 0  
fill ~40 ~1 ~60 ~41 ~1 ~60 bookshelf 0 
setblock ~41 ~1 ~6 light_weighted_pressure_plate 0  
fill ~41 ~1 ~16 ~42 ~1 ~16 bookshelf 0  
fill ~41 ~1 ~17 ~42 ~1 ~17 bookshelf 0  
fill ~41 ~1 ~24 ~43 ~1 ~24 bookshelf 0  
fill ~41 ~1 ~38 ~43 ~1 ~38 bookshelf 0  
fill ~41 ~1 ~45 ~42 ~1 ~45 bookshelf 0  
fill ~41 ~1 ~46 ~42 ~1 ~46 bookshelf 0 
setblock ~41 ~1 ~56 light_weighted_pressure_plate 0  
fill ~42 ~1 ~2 ~44 ~1 ~2 stained_hardened_clay 13  
fill ~42 ~1 ~14 ~43 ~1 ~14 bookshelf 0  
fill ~42 ~1 ~15 ~43 ~1 ~15 bookshelf 0  
fill ~42 ~1 ~23 ~45 ~1 ~23 bookshelf 0  
fill ~42 ~1 ~39 ~45 ~1 ~39 bookshelf 0  
fill ~42 ~1 ~47 ~43 ~1 ~47 bookshelf 0  
fill ~42 ~1 ~48 ~43 ~1 ~48 bookshelf 0  
fill ~42 ~1 ~60 ~44 ~1 ~60 stained_hardened_clay 13 
setblock ~43 ~1 ~4 light_weighted_pressure_plate 0  
fill ~43 ~1 ~12 ~44 ~1 ~12 bookshelf 0  
fill ~43 ~1 ~13 ~44 ~1 ~13 bookshelf 0 
setblock ~43 ~1 ~16 light_weighted_pressure_plate 0 
setblock ~43 ~1 ~46 light_weighted_pressure_plate 0  
fill ~43 ~1 ~49 ~44 ~1 ~49 bookshelf 0  
fill ~43 ~1 ~50 ~44 ~1 ~50 bookshelf 0 
setblock ~43 ~1 ~58 light_weighted_pressure_plate 0 
setblock ~44 ~1 ~9 light_weighted_pressure_plate 0  
fill ~44 ~1 ~10 ~45 ~1 ~10 bookshelf 0  
fill ~44 ~1 ~11 ~45 ~1 ~11 bookshelf 0  
fill ~44 ~1 ~22 ~47 ~1 ~22 bookshelf 0  
fill ~44 ~1 ~40 ~47 ~1 ~40 bookshelf 0  
fill ~44 ~1 ~51 ~45 ~1 ~51 bookshelf 0  
fill ~44 ~1 ~52 ~45 ~1 ~52 bookshelf 0 
setblock ~44 ~1 ~53 light_weighted_pressure_plate 0  
fill ~45 ~1 ~3 ~46 ~1 ~3 stained_hardened_clay 13 
setblock ~45 ~1 ~5 light_weighted_pressure_plate 0  
fill ~45 ~1 ~8 ~46 ~1 ~8 bookshelf 0  
fill ~45 ~1 ~9 ~46 ~1 ~9 bookshelf 0 
setblock ~45 ~1 ~12 light_weighted_pressure_plate 0 
setblock ~45 ~1 ~50 light_weighted_pressure_plate 0  
fill ~45 ~1 ~53 ~46 ~1 ~53 bookshelf 0  
fill ~45 ~1 ~54 ~46 ~1 ~54 bookshelf 0 
setblock ~45 ~1 ~57 light_weighted_pressure_plate 0  
fill ~45 ~1 ~59 ~46 ~1 ~59 stained_hardened_clay 13  
fill ~46 ~1 ~6 ~47 ~1 ~6 bookshelf 0  
fill ~46 ~1 ~7 ~47 ~1 ~7 bookshelf 0  
fill ~46 ~1 ~21 ~49 ~1 ~21 bookshelf 0  
fill ~46 ~1 ~41 ~49 ~1 ~41 bookshelf 0  
fill ~46 ~1 ~55 ~47 ~1 ~55 bookshelf 0  
fill ~46 ~1 ~56 ~47 ~1 ~56 bookshelf 0  
fill ~47 ~1 ~4 ~48 ~1 ~4 stained_hardened_clay 13  
fill ~47 ~1 ~5 ~48 ~1 ~5 bookshelf 0 
setblock ~47 ~1 ~8 light_weighted_pressure_plate 0 
setblock ~47 ~1 ~20 light_weighted_pressure_plate 0  
fill ~47 ~1 ~25 ~54 ~1 ~25 bookshelf 0  
fill ~47 ~1 ~37 ~54 ~1 ~37 bookshelf 0 
setblock ~47 ~1 ~42 light_weighted_pressure_plate 0 
setblock ~47 ~1 ~54 light_weighted_pressure_plate 0  
fill ~47 ~1 ~57 ~48 ~1 ~57 bookshelf 0  
fill ~47 ~1 ~58 ~48 ~1 ~58 stained_hardened_clay 13  
fill ~48 ~1 ~20 ~51 ~1 ~20 bookshelf 0  
fill ~48 ~1 ~42 ~51 ~1 ~42 bookshelf 0  
fill ~49 ~1 ~28 ~54 ~1 ~28 bookshelf 0  
fill ~49 ~1 ~29 ~54 ~1 ~29 bookshelf 0  
fill ~49 ~1 ~33 ~54 ~1 ~33 bookshelf 0  
fill ~49 ~1 ~34 ~54 ~1 ~34 bookshelf 0  
fill ~50 ~1 ~6 ~50 ~0 ~6 stained_hardened_clay 13  
fill ~50 ~1 ~19 ~53 ~1 ~19 bookshelf 0  
fill ~50 ~1 ~24 ~57 ~1 ~24 bookshelf 0  
fill ~50 ~1 ~38 ~57 ~1 ~38 bookshelf 0  
fill ~50 ~1 ~43 ~53 ~1 ~43 bookshelf 0  
fill ~50 ~1 ~56 ~50 ~0 ~56 stained_hardened_clay 13 
setblock ~51 ~1 ~6 stained_hardened_clay 4 
setblock ~51 ~1 ~8 light_weighted_pressure_plate 0 
setblock ~51 ~1 ~18 light_weighted_pressure_plate 0 
setblock ~51 ~1 ~44 light_weighted_pressure_plate 0 
setblock ~51 ~1 ~54 light_weighted_pressure_plate 0 
setblock ~51 ~1 ~56 stained_hardened_clay 4  
fill ~52 ~1 ~9 ~53 ~1 ~9 bookshelf 0 
setblock ~52 ~1 ~11 light_weighted_pressure_plate 0  
fill ~52 ~1 ~18 ~55 ~1 ~18 bookshelf 0  
fill ~52 ~1 ~44 ~55 ~1 ~44 bookshelf 0 
setblock ~52 ~1 ~51 light_weighted_pressure_plate 0  
fill ~52 ~1 ~53 ~53 ~1 ~53 bookshelf 0  
fill ~54 ~1 ~11 ~55 ~1 ~11 bookshelf 0  
fill ~54 ~1 ~17 ~57 ~1 ~17 bookshelf 0 
setblock ~54 ~1 ~19 light_weighted_pressure_plate 0  
fill ~54 ~1 ~23 ~61 ~1 ~23 bookshelf 0  
fill ~54 ~1 ~39 ~61 ~1 ~39 bookshelf 0 
setblock ~54 ~1 ~43 light_weighted_pressure_plate 0  
fill ~54 ~1 ~45 ~57 ~1 ~45 bookshelf 0  
fill ~54 ~1 ~51 ~55 ~1 ~51 bookshelf 0 
setblock ~55 ~1 ~12 light_weighted_pressure_plate 0 
setblock ~55 ~1 ~16 light_weighted_pressure_plate 0 
setblock ~55 ~1 ~46 light_weighted_pressure_plate 0 
setblock ~55 ~1 ~50 light_weighted_pressure_plate 0  
fill ~56 ~1 ~16 ~58 ~1 ~16 bookshelf 0  
fill ~56 ~1 ~26 ~56 ~1 ~27 light_weighted_pressure_plate 0  
fill ~56 ~1 ~35 ~56 ~1 ~36 light_weighted_pressure_plate 0  
fill ~56 ~1 ~46 ~58 ~1 ~46 bookshelf 0 
setblock ~57 ~1 ~12 stained_hardened_clay 4 
setblock ~57 ~1 ~13 stained_hardened_clay 13 
setblock ~57 ~1 ~22 light_weighted_pressure_plate 0 
setblock ~57 ~1 ~40 light_weighted_pressure_plate 0 
setblock ~57 ~1 ~50 stained_hardened_clay 4 
setblock ~58 ~1 ~18 light_weighted_pressure_plate 0  
fill ~58 ~1 ~22 ~61 ~1 ~22 bookshelf 0  
fill ~58 ~1 ~40 ~61 ~1 ~40 bookshelf 0 
setblock ~58 ~1 ~44 light_weighted_pressure_plate 0 
setblock ~59 ~1 ~20 light_weighted_pressure_plate 0  
fill ~59 ~1 ~30 ~59 ~1 ~32 light_weighted_pressure_plate 0 
setblock ~59 ~1 ~42 light_weighted_pressure_plate 0 
setblock ~61 ~1 ~27 light_weighted_pressure_plate 0 
setblock ~61 ~1 ~35 light_weighted_pressure_plate 0 
setblock ~62 ~1 ~29 oak_stairs 2  
fill ~62 ~1 ~30 ~62 ~1 ~32 bookshelf 0 
setblock ~62 ~1 ~33 oak_stairs 3 
setblock ~63 ~1 ~27 stained_hardened_clay 4  
fill ~63 ~1 ~28 ~63 ~1 ~34 stained_hardened_clay 13 
setblock ~63 ~1 ~35 stained_hardened_clay 4  
fill ~63 ~1 ~36 ~63 ~6 ~36 stained_hardened_clay 13 
setblock ~1 ~2 ~30 stained_hardened_clay 4 
setblock ~1 ~2 ~32 stained_hardened_clay 4 
setblock ~2 ~2 ~22 stained_hardened_clay 4  
fill ~2 ~2 ~28 ~6 ~2 ~28 bookshelf 0  
fill ~2 ~2 ~29 ~6 ~2 ~29 bookshelf 0  
fill ~2 ~2 ~33 ~6 ~2 ~33 bookshelf 0  
fill ~2 ~2 ~34 ~6 ~2 ~34 bookshelf 0 
setblock ~3 ~2 ~19 stained_hardened_clay 4  
fill ~3 ~2 ~20 ~3 ~8 ~20 stained_hardened_clay 13  
fill ~3 ~2 ~21 ~3 ~9 ~21 stained_hardened_clay 13  
fill ~3 ~2 ~22 ~6 ~2 ~22 bookshelf 0  
fill ~3 ~2 ~23 ~10 ~2 ~23 bookshelf 0  
fill ~3 ~2 ~39 ~10 ~2 ~39 bookshelf 0  
fill ~3 ~2 ~40 ~6 ~2 ~40 bookshelf 0  
fill ~3 ~2 ~41 ~3 ~9 ~41 stained_hardened_clay 13  
fill ~3 ~2 ~42 ~3 ~8 ~42 stained_hardened_clay 13 
setblock ~3 ~2 ~43 stained_hardened_clay 4  
fill ~6 ~2 ~16 ~8 ~2 ~16 bookshelf 0  
fill ~6 ~2 ~46 ~8 ~2 ~46 bookshelf 0  
fill ~7 ~2 ~12 ~7 ~8 ~12 stained_hardened_clay 13 
setblock ~7 ~2 ~13 stained_hardened_clay 4  
fill ~7 ~2 ~17 ~10 ~2 ~17 bookshelf 0  
fill ~7 ~2 ~24 ~14 ~2 ~24 bookshelf 0 
setblock ~7 ~2 ~29 oak_stairs 5 
setblock ~7 ~2 ~33 oak_stairs 5  
fill ~7 ~2 ~38 ~14 ~2 ~38 bookshelf 0  
fill ~7 ~2 ~45 ~10 ~2 ~45 bookshelf 0 
setblock ~7 ~2 ~49 stained_hardened_clay 4  
fill ~7 ~2 ~50 ~7 ~8 ~50 stained_hardened_clay 13 
setblock ~8 ~2 ~11 stained_hardened_clay 4  
fill ~8 ~2 ~29 ~8 ~3 ~29 dropper 8  
fill ~8 ~2 ~33 ~8 ~3 ~33 dropper 8 
setblock ~8 ~2 ~51 stained_hardened_clay 4  
fill ~9 ~2 ~11 ~9 ~0 ~11 bookshelf 0  
fill ~9 ~2 ~18 ~12 ~2 ~18 bookshelf 0 
setblock ~9 ~2 ~29 oak_stairs 4 
setblock ~9 ~2 ~33 oak_stairs 4  
fill ~9 ~2 ~44 ~12 ~2 ~44 bookshelf 0  
fill ~9 ~2 ~51 ~9 ~0 ~51 bookshelf 0  
fill ~10 ~2 ~28 ~15 ~2 ~28 bookshelf 0  
fill ~10 ~2 ~29 ~15 ~2 ~29 bookshelf 0  
fill ~10 ~2 ~33 ~15 ~2 ~33 bookshelf 0  
fill ~10 ~2 ~34 ~15 ~2 ~34 bookshelf 0  
fill ~11 ~2 ~9 ~11 ~3 ~9 bookshelf 0  
fill ~11 ~2 ~19 ~14 ~2 ~19 bookshelf 0  
fill ~11 ~2 ~25 ~17 ~2 ~25 bookshelf 0  
fill ~11 ~2 ~37 ~17 ~2 ~37 bookshelf 0  
fill ~11 ~2 ~43 ~14 ~2 ~43 bookshelf 0  
fill ~11 ~2 ~53 ~11 ~3 ~53 bookshelf 0 
setblock ~12 ~2 ~7 stained_hardened_clay 4 
setblock ~12 ~2 ~55 stained_hardened_clay 4  
fill ~13 ~2 ~6 ~13 ~8 ~6 stained_hardened_clay 13  
fill ~13 ~2 ~20 ~16 ~2 ~20 bookshelf 0  
fill ~13 ~2 ~42 ~16 ~2 ~42 bookshelf 0  
fill ~13 ~2 ~56 ~13 ~8 ~56 stained_hardened_clay 13 
setblock ~14 ~2 ~6 stained_hardened_clay 4 
setblock ~14 ~2 ~56 stained_hardened_clay 4  
fill ~15 ~2 ~21 ~18 ~2 ~21 bookshelf 0  
fill ~15 ~2 ~41 ~18 ~2 ~41 bookshelf 0  
fill ~16 ~2 ~4 ~17 ~2 ~4 stained_hardened_clay 13  
fill ~16 ~2 ~5 ~17 ~2 ~5 bookshelf 0  
fill ~16 ~2 ~57 ~17 ~2 ~57 bookshelf 0  
fill ~16 ~2 ~58 ~17 ~2 ~58 stained_hardened_clay 13  
fill ~17 ~2 ~6 ~18 ~2 ~6 bookshelf 0  
fill ~17 ~2 ~7 ~18 ~2 ~7 bookshelf 0  
fill ~17 ~2 ~22 ~20 ~2 ~22 bookshelf 0  
fill ~17 ~2 ~40 ~20 ~2 ~40 bookshelf 0  
fill ~17 ~2 ~55 ~18 ~2 ~55 bookshelf 0  
fill ~17 ~2 ~56 ~18 ~2 ~56 bookshelf 0  
fill ~18 ~2 ~3 ~19 ~2 ~3 stained_hardened_clay 13  
fill ~18 ~2 ~8 ~19 ~2 ~8 bookshelf 0  
fill ~18 ~2 ~9 ~19 ~2 ~9 bookshelf 0  
fill ~18 ~2 ~53 ~19 ~2 ~53 bookshelf 0  
fill ~18 ~2 ~54 ~19 ~2 ~54 bookshelf 0  
fill ~18 ~2 ~59 ~19 ~2 ~59 stained_hardened_clay 13  
fill ~19 ~2 ~10 ~20 ~2 ~10 bookshelf 0  
fill ~19 ~2 ~11 ~20 ~2 ~11 bookshelf 0  
fill ~19 ~2 ~23 ~22 ~2 ~23 bookshelf 0  
fill ~19 ~2 ~28 ~24 ~2 ~28 bookshelf 0  
fill ~19 ~2 ~29 ~24 ~2 ~29 bookshelf 0  
fill ~19 ~2 ~33 ~24 ~2 ~33 bookshelf 0  
fill ~19 ~2 ~34 ~24 ~2 ~34 bookshelf 0  
fill ~19 ~2 ~39 ~22 ~2 ~39 bookshelf 0  
fill ~19 ~2 ~51 ~20 ~2 ~51 bookshelf 0  
fill ~19 ~2 ~52 ~20 ~2 ~52 bookshelf 0 
setblock ~20 ~2 ~2 stained_hardened_clay 4  
fill ~20 ~2 ~12 ~21 ~2 ~12 bookshelf 0  
fill ~20 ~2 ~13 ~21 ~2 ~13 bookshelf 0  
fill ~20 ~2 ~49 ~21 ~2 ~49 bookshelf 0  
fill ~20 ~2 ~50 ~21 ~2 ~50 bookshelf 0 
setblock ~20 ~2 ~60 stained_hardened_clay 4  
fill ~21 ~2 ~2 ~22 ~2 ~2 stained_hardened_clay 13  
fill ~21 ~2 ~14 ~22 ~2 ~14 bookshelf 0  
fill ~21 ~2 ~15 ~22 ~2 ~15 bookshelf 0  
fill ~21 ~2 ~24 ~23 ~2 ~24 bookshelf 0  
fill ~21 ~2 ~38 ~23 ~2 ~38 bookshelf 0  
fill ~21 ~2 ~47 ~22 ~2 ~47 bookshelf 0  
fill ~21 ~2 ~48 ~22 ~2 ~48 bookshelf 0  
fill ~21 ~2 ~60 ~22 ~2 ~60 stained_hardened_clay 13  
fill ~22 ~2 ~16 ~23 ~2 ~16 bookshelf 0  
fill ~22 ~2 ~17 ~23 ~2 ~17 bookshelf 0  
fill ~22 ~2 ~45 ~23 ~2 ~45 bookshelf 0  
fill ~22 ~2 ~46 ~23 ~2 ~46 bookshelf 0  
fill ~23 ~2 ~1 ~26 ~2 ~1 stained_hardened_clay 13  
fill ~23 ~2 ~2 ~24 ~2 ~2 bookshelf 0  
fill ~23 ~2 ~3 ~24 ~2 ~3 bookshelf 0  
fill ~23 ~2 ~4 ~24 ~2 ~4 bookshelf 0  
fill ~23 ~2 ~5 ~24 ~2 ~5 bookshelf 0  
fill ~23 ~2 ~18 ~24 ~2 ~18 bookshelf 0  
fill ~23 ~2 ~19 ~24 ~2 ~19 bookshelf 0  
fill ~23 ~2 ~43 ~24 ~2 ~43 bookshelf 0  
fill ~23 ~2 ~44 ~24 ~2 ~44 bookshelf 0  
fill ~23 ~2 ~57 ~24 ~2 ~57 bookshelf 0  
fill ~23 ~2 ~58 ~24 ~2 ~58 bookshelf 0  
fill ~23 ~2 ~59 ~24 ~2 ~59 bookshelf 0  
fill ~23 ~2 ~60 ~24 ~2 ~60 bookshelf 0  
fill ~23 ~2 ~61 ~26 ~2 ~61 stained_hardened_clay 13  
fill ~24 ~2 ~6 ~25 ~2 ~6 bookshelf 0  
fill ~24 ~2 ~7 ~25 ~2 ~7 bookshelf 0  
fill ~24 ~2 ~8 ~25 ~2 ~8 bookshelf 0  
fill ~24 ~2 ~9 ~30 ~2 ~9 bookshelf 0  
fill ~24 ~2 ~20 ~25 ~2 ~20 bookshelf 0  
fill ~24 ~2 ~21 ~25 ~2 ~21 bookshelf 0  
fill ~24 ~2 ~41 ~25 ~2 ~41 bookshelf 0  
fill ~24 ~2 ~42 ~25 ~2 ~42 bookshelf 0  
fill ~24 ~2 ~53 ~30 ~2 ~53 bookshelf 0  
fill ~24 ~2 ~54 ~25 ~2 ~54 bookshelf 0  
fill ~24 ~2 ~55 ~25 ~2 ~55 bookshelf 0  
fill ~24 ~2 ~56 ~25 ~2 ~56 bookshelf 0  
fill ~25 ~2 ~10 ~26 ~2 ~10 bookshelf 0  
fill ~25 ~2 ~11 ~26 ~2 ~11 bookshelf 0  
fill ~25 ~2 ~12 ~26 ~2 ~12 bookshelf 0  
fill ~25 ~2 ~13 ~26 ~2 ~13 bookshelf 0  
fill ~25 ~2 ~22 ~26 ~2 ~22 bookshelf 0  
fill ~25 ~2 ~40 ~26 ~2 ~40 bookshelf 0  
fill ~25 ~2 ~49 ~26 ~2 ~49 bookshelf 0  
fill ~25 ~2 ~50 ~26 ~2 ~50 bookshelf 0  
fill ~25 ~2 ~51 ~26 ~2 ~51 bookshelf 0  
fill ~25 ~2 ~52 ~26 ~2 ~52 bookshelf 0  
fill ~28 ~2 ~0 ~28 ~5 ~0 stained_hardened_clay 13  
fill ~28 ~2 ~62 ~28 ~5 ~62 stained_hardened_clay 13 
setblock ~29 ~2 ~0 stained_hardened_clay 4  
fill ~29 ~2 ~10 ~30 ~2 ~10 bookshelf 0  
fill ~29 ~2 ~11 ~30 ~2 ~11 bookshelf 0  
fill ~29 ~2 ~12 ~30 ~2 ~12 bookshelf 0  
fill ~29 ~2 ~13 ~30 ~2 ~13 bookshelf 0  
fill ~29 ~2 ~14 ~30 ~2 ~14 bookshelf 0  
fill ~29 ~2 ~18 ~30 ~2 ~18 bookshelf 0  
fill ~29 ~2 ~19 ~30 ~2 ~19 bookshelf 0  
fill ~29 ~2 ~20 ~30 ~2 ~20 bookshelf 0  
fill ~29 ~2 ~21 ~30 ~2 ~21 bookshelf 0  
fill ~29 ~2 ~22 ~30 ~2 ~22 bookshelf 0  
fill ~29 ~2 ~23 ~30 ~2 ~23 bookshelf 0  
fill ~29 ~2 ~39 ~30 ~2 ~39 bookshelf 0  
fill ~29 ~2 ~40 ~30 ~2 ~40 bookshelf 0  
fill ~29 ~2 ~41 ~30 ~2 ~41 bookshelf 0  
fill ~29 ~2 ~42 ~30 ~2 ~42 bookshelf 0  
fill ~29 ~2 ~43 ~30 ~2 ~43 bookshelf 0  
fill ~29 ~2 ~44 ~30 ~2 ~44 bookshelf 0  
fill ~29 ~2 ~48 ~30 ~2 ~48 bookshelf 0  
fill ~29 ~2 ~49 ~30 ~2 ~49 bookshelf 0  
fill ~29 ~2 ~50 ~30 ~2 ~50 bookshelf 0  
fill ~29 ~2 ~51 ~30 ~2 ~51 bookshelf 0  
fill ~29 ~2 ~52 ~30 ~2 ~52 bookshelf 0 
setblock ~29 ~2 ~62 stained_hardened_clay 4  
fill ~30 ~2 ~0 ~30 ~4 ~0 stained_hardened_clay 13  
fill ~30 ~2 ~62 ~30 ~4 ~62 stained_hardened_clay 13 
setblock ~31 ~2 ~0 stained_hardened_clay 4 
setblock ~31 ~2 ~1 oak_stairs 0 
setblock ~31 ~2 ~30 planks 0 
setblock ~31 ~2 ~32 planks 0 
setblock ~31 ~2 ~61 oak_stairs 0 
setblock ~31 ~2 ~62 stained_hardened_clay 4 
setblock ~32 ~2 ~0 stained_hardened_clay 13 
setblock ~32 ~2 ~1 glowstone 0  
fill ~32 ~2 ~31 ~32 ~11 ~31 planks 0 
setblock ~32 ~2 ~61 glowstone 0 
setblock ~32 ~2 ~62 stained_hardened_clay 13 
setblock ~33 ~2 ~0 stained_hardened_clay 4 
setblock ~33 ~2 ~1 oak_stairs 1  
fill ~33 ~2 ~28 ~33 ~2 ~29 oak_stairs 4 
setblock ~33 ~2 ~30 planks 0 
setblock ~33 ~2 ~32 planks 0 
setblock ~33 ~2 ~61 oak_stairs 1 
setblock ~33 ~2 ~62 stained_hardened_clay 4  
fill ~34 ~2 ~0 ~34 ~4 ~0 stained_hardened_clay 13  
fill ~34 ~2 ~9 ~40 ~2 ~9 bookshelf 0  
fill ~34 ~2 ~10 ~35 ~2 ~10 bookshelf 0  
fill ~34 ~2 ~11 ~35 ~2 ~11 bookshelf 0  
fill ~34 ~2 ~12 ~35 ~2 ~12 bookshelf 0  
fill ~34 ~2 ~13 ~35 ~2 ~13 bookshelf 0  
fill ~34 ~2 ~14 ~35 ~2 ~14 bookshelf 0  
fill ~34 ~2 ~18 ~35 ~2 ~18 bookshelf 0  
fill ~34 ~2 ~19 ~35 ~2 ~19 bookshelf 0  
fill ~34 ~2 ~20 ~35 ~2 ~20 bookshelf 0  
fill ~34 ~2 ~21 ~35 ~2 ~21 bookshelf 0  
fill ~34 ~2 ~22 ~35 ~2 ~22 bookshelf 0  
fill ~34 ~2 ~23 ~35 ~2 ~23 bookshelf 0  
fill ~34 ~2 ~28 ~34 ~2 ~29 planks 0 
setblock ~34 ~2 ~30 oak_stairs 3  
fill ~34 ~2 ~39 ~35 ~2 ~39 bookshelf 0  
fill ~34 ~2 ~40 ~35 ~2 ~40 bookshelf 0  
fill ~34 ~2 ~41 ~35 ~2 ~41 bookshelf 0  
fill ~34 ~2 ~42 ~35 ~2 ~42 bookshelf 0  
fill ~34 ~2 ~43 ~35 ~2 ~43 bookshelf 0  
fill ~34 ~2 ~44 ~35 ~2 ~44 bookshelf 0  
fill ~34 ~2 ~48 ~35 ~2 ~48 bookshelf 0  
fill ~34 ~2 ~49 ~35 ~2 ~49 bookshelf 0  
fill ~34 ~2 ~50 ~35 ~2 ~50 bookshelf 0  
fill ~34 ~2 ~51 ~35 ~2 ~51 bookshelf 0  
fill ~34 ~2 ~52 ~35 ~2 ~52 bookshelf 0  
fill ~34 ~2 ~53 ~40 ~2 ~53 bookshelf 0  
fill ~34 ~2 ~62 ~34 ~4 ~62 stained_hardened_clay 13 
setblock ~35 ~2 ~0 stained_hardened_clay 4 
setblock ~35 ~2 ~29 planks 0 
setblock ~35 ~2 ~30 spruce_stairs 3 
setblock ~35 ~2 ~62 stained_hardened_clay 4  
fill ~36 ~2 ~0 ~36 ~5 ~0 stained_hardened_clay 13  
fill ~36 ~2 ~62 ~36 ~5 ~62 stained_hardened_clay 13  
fill ~38 ~2 ~1 ~41 ~2 ~1 stained_hardened_clay 13  
fill ~38 ~2 ~10 ~39 ~2 ~10 bookshelf 0  
fill ~38 ~2 ~11 ~39 ~2 ~11 bookshelf 0  
fill ~38 ~2 ~12 ~39 ~2 ~12 bookshelf 0  
fill ~38 ~2 ~13 ~39 ~2 ~13 bookshelf 0  
fill ~38 ~2 ~22 ~39 ~2 ~22 bookshelf 0  
fill ~38 ~2 ~40 ~39 ~2 ~40 bookshelf 0  
fill ~38 ~2 ~49 ~39 ~2 ~49 bookshelf 0  
fill ~38 ~2 ~50 ~39 ~2 ~50 bookshelf 0  
fill ~38 ~2 ~51 ~39 ~2 ~51 bookshelf 0  
fill ~38 ~2 ~52 ~39 ~2 ~52 bookshelf 0  
fill ~38 ~2 ~61 ~41 ~2 ~61 stained_hardened_clay 13  
fill ~39 ~2 ~6 ~40 ~2 ~6 bookshelf 0  
fill ~39 ~2 ~7 ~40 ~2 ~7 bookshelf 0  
fill ~39 ~2 ~8 ~40 ~2 ~8 bookshelf 0  
fill ~39 ~2 ~20 ~40 ~2 ~20 bookshelf 0  
fill ~39 ~2 ~21 ~40 ~2 ~21 bookshelf 0  
fill ~39 ~2 ~41 ~40 ~2 ~41 bookshelf 0  
fill ~39 ~2 ~42 ~40 ~2 ~42 bookshelf 0  
fill ~39 ~2 ~54 ~40 ~2 ~54 bookshelf 0  
fill ~39 ~2 ~55 ~40 ~2 ~55 bookshelf 0  
fill ~39 ~2 ~56 ~40 ~2 ~56 bookshelf 0  
fill ~40 ~2 ~2 ~41 ~2 ~2 bookshelf 0  
fill ~40 ~2 ~3 ~41 ~2 ~3 bookshelf 0  
fill ~40 ~2 ~4 ~41 ~2 ~4 bookshelf 0  
fill ~40 ~2 ~5 ~41 ~2 ~5 bookshelf 0  
fill ~40 ~2 ~18 ~41 ~2 ~18 bookshelf 0  
fill ~40 ~2 ~19 ~41 ~2 ~19 bookshelf 0  
fill ~40 ~2 ~28 ~45 ~2 ~28 bookshelf 0  
fill ~40 ~2 ~29 ~45 ~2 ~29 bookshelf 0  
fill ~40 ~2 ~33 ~45 ~2 ~33 bookshelf 0  
fill ~40 ~2 ~34 ~45 ~2 ~34 bookshelf 0  
fill ~40 ~2 ~43 ~41 ~2 ~43 bookshelf 0  
fill ~40 ~2 ~44 ~41 ~2 ~44 bookshelf 0  
fill ~40 ~2 ~57 ~41 ~2 ~57 bookshelf 0  
fill ~40 ~2 ~58 ~41 ~2 ~58 bookshelf 0  
fill ~40 ~2 ~59 ~41 ~2 ~59 bookshelf 0  
fill ~40 ~2 ~60 ~41 ~2 ~60 bookshelf 0  
fill ~41 ~2 ~16 ~42 ~2 ~16 bookshelf 0  
fill ~41 ~2 ~17 ~42 ~2 ~17 bookshelf 0  
fill ~41 ~2 ~24 ~43 ~2 ~24 bookshelf 0  
fill ~41 ~2 ~38 ~43 ~2 ~38 bookshelf 0  
fill ~41 ~2 ~45 ~42 ~2 ~45 bookshelf 0  
fill ~41 ~2 ~46 ~42 ~2 ~46 bookshelf 0  
fill ~42 ~2 ~2 ~43 ~2 ~2 stained_hardened_clay 13  
fill ~42 ~2 ~14 ~43 ~2 ~14 bookshelf 0  
fill ~42 ~2 ~15 ~43 ~2 ~15 bookshelf 0  
fill ~42 ~2 ~23 ~45 ~2 ~23 bookshelf 0  
fill ~42 ~2 ~39 ~45 ~2 ~39 bookshelf 0  
fill ~42 ~2 ~47 ~43 ~2 ~47 bookshelf 0  
fill ~42 ~2 ~48 ~43 ~2 ~48 bookshelf 0  
fill ~42 ~2 ~60 ~43 ~2 ~60 stained_hardened_clay 13  
fill ~43 ~2 ~12 ~44 ~2 ~12 bookshelf 0  
fill ~43 ~2 ~13 ~44 ~2 ~13 bookshelf 0  
fill ~43 ~2 ~49 ~44 ~2 ~49 bookshelf 0  
fill ~43 ~2 ~50 ~44 ~2 ~50 bookshelf 0 
setblock ~44 ~2 ~2 stained_hardened_clay 4  
fill ~44 ~2 ~10 ~45 ~2 ~10 bookshelf 0  
fill ~44 ~2 ~11 ~45 ~2 ~11 bookshelf 0  
fill ~44 ~2 ~22 ~47 ~2 ~22 bookshelf 0  
fill ~44 ~2 ~40 ~47 ~2 ~40 bookshelf 0  
fill ~44 ~2 ~51 ~45 ~2 ~51 bookshelf 0  
fill ~44 ~2 ~52 ~45 ~2 ~52 bookshelf 0 
setblock ~44 ~2 ~60 stained_hardened_clay 4  
fill ~45 ~2 ~3 ~46 ~2 ~3 stained_hardened_clay 13  
fill ~45 ~2 ~8 ~46 ~2 ~8 bookshelf 0  
fill ~45 ~2 ~9 ~46 ~2 ~9 bookshelf 0  
fill ~45 ~2 ~53 ~46 ~2 ~53 bookshelf 0  
fill ~45 ~2 ~54 ~46 ~2 ~54 bookshelf 0  
fill ~45 ~2 ~59 ~46 ~2 ~59 stained_hardened_clay 13  
fill ~46 ~2 ~6 ~47 ~2 ~6 bookshelf 0  
fill ~46 ~2 ~7 ~47 ~2 ~7 bookshelf 0  
fill ~46 ~2 ~21 ~49 ~2 ~21 bookshelf 0  
fill ~46 ~2 ~41 ~49 ~2 ~41 bookshelf 0  
fill ~46 ~2 ~55 ~47 ~2 ~55 bookshelf 0  
fill ~46 ~2 ~56 ~47 ~2 ~56 bookshelf 0  
fill ~47 ~2 ~4 ~48 ~2 ~4 stained_hardened_clay 13  
fill ~47 ~2 ~5 ~48 ~2 ~5 bookshelf 0  
fill ~47 ~2 ~25 ~54 ~2 ~25 bookshelf 0  
fill ~47 ~2 ~37 ~54 ~2 ~37 bookshelf 0  
fill ~47 ~2 ~57 ~48 ~2 ~57 bookshelf 0  
fill ~47 ~2 ~58 ~48 ~2 ~58 stained_hardened_clay 13  
fill ~48 ~2 ~20 ~51 ~2 ~20 bookshelf 0  
fill ~48 ~2 ~42 ~51 ~2 ~42 bookshelf 0  
fill ~49 ~2 ~28 ~54 ~2 ~28 bookshelf 0  
fill ~49 ~2 ~29 ~54 ~2 ~29 bookshelf 0  
fill ~49 ~2 ~33 ~54 ~2 ~33 bookshelf 0  
fill ~49 ~2 ~34 ~54 ~2 ~34 bookshelf 0 
setblock ~50 ~2 ~6 stained_hardened_clay 4  
fill ~50 ~2 ~19 ~53 ~2 ~19 bookshelf 0  
fill ~50 ~2 ~24 ~57 ~2 ~24 bookshelf 0  
fill ~50 ~2 ~38 ~57 ~2 ~38 bookshelf 0  
fill ~50 ~2 ~43 ~53 ~2 ~43 bookshelf 0 
setblock ~50 ~2 ~56 stained_hardened_clay 4  
fill ~51 ~2 ~6 ~51 ~8 ~6 stained_hardened_clay 13  
fill ~51 ~2 ~56 ~51 ~8 ~56 stained_hardened_clay 13 
setblock ~52 ~2 ~7 stained_hardened_clay 4  
fill ~52 ~2 ~18 ~55 ~2 ~18 bookshelf 0  
fill ~52 ~2 ~44 ~55 ~2 ~44 bookshelf 0 
setblock ~52 ~2 ~55 stained_hardened_clay 4  
fill ~53 ~2 ~9 ~53 ~3 ~9 bookshelf 0  
fill ~53 ~2 ~53 ~53 ~3 ~53 bookshelf 0  
fill ~54 ~2 ~17 ~57 ~2 ~17 bookshelf 0  
fill ~54 ~2 ~23 ~61 ~2 ~23 bookshelf 0  
fill ~54 ~2 ~39 ~61 ~2 ~39 bookshelf 0  
fill ~54 ~2 ~45 ~57 ~2 ~45 bookshelf 0 
setblock ~55 ~2 ~11 bookshelf 0 
setblock ~55 ~2 ~51 bookshelf 0 
setblock ~56 ~2 ~11 stained_hardened_clay 4  
fill ~56 ~2 ~16 ~58 ~2 ~16 bookshelf 0  
fill ~56 ~2 ~46 ~58 ~2 ~46 bookshelf 0 
setblock ~56 ~2 ~51 stained_hardened_clay 4  
fill ~57 ~2 ~12 ~57 ~8 ~12 stained_hardened_clay 13 
setblock ~57 ~2 ~13 stained_hardened_clay 4 
setblock ~57 ~2 ~49 stained_hardened_clay 4  
fill ~57 ~2 ~50 ~57 ~8 ~50 stained_hardened_clay 13  
fill ~58 ~2 ~22 ~61 ~2 ~22 bookshelf 0  
fill ~58 ~2 ~40 ~61 ~2 ~40 bookshelf 0 
setblock ~61 ~2 ~19 stained_hardened_clay 4 
setblock ~61 ~2 ~43 stained_hardened_clay 4 
setblock ~62 ~2 ~30 oak_stairs 2 
setblock ~62 ~2 ~31 glowstone 0 
setblock ~62 ~2 ~32 oak_stairs 3  
fill ~63 ~2 ~27 ~63 ~5 ~27 stained_hardened_clay 13 
setblock ~63 ~2 ~28 stained_hardened_clay 4  
fill ~63 ~2 ~29 ~63 ~4 ~29 stained_hardened_clay 13 
setblock ~63 ~2 ~30 stained_hardened_clay 4 
setblock ~63 ~2 ~31 stained_hardened_clay 13 
setblock ~63 ~2 ~32 stained_hardened_clay 4  
fill ~63 ~2 ~33 ~63 ~4 ~33 stained_hardened_clay 13 
setblock ~63 ~2 ~34 stained_hardened_clay 4  
fill ~63 ~2 ~35 ~63 ~5 ~35 stained_hardened_clay 13 
setblock ~1 ~3 ~30 stained_hardened_clay 13 
setblock ~1 ~3 ~31 stained_hardened_clay 4 
setblock ~1 ~3 ~32 stained_hardened_clay 13  
fill ~2 ~3 ~22 ~2 ~11 ~22 stained_hardened_clay 13 
setblock ~2 ~3 ~23 stained_hardened_clay 4  
fill ~2 ~3 ~28 ~6 ~3 ~28 bookshelf 0  
fill ~2 ~3 ~29 ~6 ~3 ~29 bookshelf 0  
fill ~2 ~3 ~33 ~6 ~3 ~33 bookshelf 0  
fill ~2 ~3 ~34 ~6 ~3 ~34 bookshelf 0 
setblock ~2 ~3 ~40 stained_hardened_clay 4  
fill ~3 ~3 ~19 ~3 ~7 ~19 stained_hardened_clay 13  
fill ~3 ~3 ~22 ~6 ~3 ~22 bookshelf 0  
fill ~3 ~3 ~23 ~10 ~3 ~23 bookshelf 0  
fill ~3 ~3 ~39 ~10 ~3 ~39 bookshelf 0  
fill ~3 ~3 ~40 ~6 ~3 ~40 bookshelf 0  
fill ~3 ~3 ~43 ~3 ~7 ~43 stained_hardened_clay 13 
setblock ~4 ~3 ~18 stained_hardened_clay 4 
setblock ~4 ~3 ~44 stained_hardened_clay 4  
fill ~6 ~3 ~16 ~8 ~3 ~16 bookshelf 0  
fill ~6 ~3 ~46 ~8 ~3 ~46 bookshelf 0  
fill ~7 ~3 ~13 ~7 ~5 ~13 glass 4  
fill ~7 ~3 ~17 ~10 ~3 ~17 bookshelf 0  
fill ~7 ~3 ~24 ~14 ~3 ~24 bookshelf 0 
setblock ~7 ~3 ~29 oak_stairs 0 
setblock ~7 ~3 ~33 oak_stairs 0  
fill ~7 ~3 ~38 ~14 ~3 ~38 bookshelf 0  
fill ~7 ~3 ~45 ~10 ~3 ~45 bookshelf 0  
fill ~7 ~3 ~49 ~7 ~5 ~49 glass 4  
fill ~8 ~3 ~11 ~8 ~9 ~11 stained_hardened_clay 13  
fill ~8 ~3 ~51 ~8 ~9 ~51 stained_hardened_clay 13 
setblock ~9 ~3 ~10 stained_hardened_clay 4  
fill ~9 ~3 ~18 ~12 ~3 ~18 bookshelf 0 
setblock ~9 ~3 ~29 oak_stairs 1 
setblock ~9 ~3 ~33 oak_stairs 1  
fill ~9 ~3 ~44 ~12 ~3 ~44 bookshelf 0 
setblock ~9 ~3 ~52 stained_hardened_clay 4  
fill ~10 ~3 ~28 ~15 ~3 ~28 bookshelf 0  
fill ~10 ~3 ~29 ~15 ~3 ~29 bookshelf 0  
fill ~10 ~3 ~33 ~15 ~3 ~33 bookshelf 0  
fill ~10 ~3 ~34 ~15 ~3 ~34 bookshelf 0 
setblock ~11 ~3 ~8 stained_hardened_clay 4  
fill ~11 ~3 ~19 ~14 ~3 ~19 bookshelf 0  
fill ~11 ~3 ~25 ~17 ~3 ~25 bookshelf 0  
fill ~11 ~3 ~37 ~17 ~3 ~37 bookshelf 0  
fill ~11 ~3 ~43 ~14 ~3 ~43 bookshelf 0 
setblock ~11 ~3 ~54 stained_hardened_clay 4  
fill ~12 ~3 ~7 ~12 ~9 ~7 stained_hardened_clay 13  
fill ~12 ~3 ~55 ~12 ~9 ~55 stained_hardened_clay 13  
fill ~13 ~3 ~20 ~16 ~3 ~20 bookshelf 0  
fill ~13 ~3 ~42 ~16 ~3 ~42 bookshelf 0  
fill ~14 ~3 ~6 ~14 ~5 ~6 glass 4  
fill ~14 ~3 ~56 ~14 ~5 ~56 glass 4  
fill ~15 ~3 ~21 ~18 ~3 ~21 bookshelf 0  
fill ~15 ~3 ~41 ~18 ~3 ~41 bookshelf 0  
fill ~16 ~3 ~4 ~17 ~3 ~4 stained_hardened_clay 13  
fill ~16 ~3 ~5 ~17 ~3 ~5 bookshelf 0  
fill ~16 ~3 ~57 ~17 ~3 ~57 bookshelf 0  
fill ~16 ~3 ~58 ~17 ~3 ~58 stained_hardened_clay 13  
fill ~17 ~3 ~6 ~18 ~3 ~6 bookshelf 0  
fill ~17 ~3 ~7 ~18 ~3 ~7 bookshelf 0  
fill ~17 ~3 ~22 ~20 ~3 ~22 bookshelf 0  
fill ~17 ~3 ~40 ~20 ~3 ~40 bookshelf 0  
fill ~17 ~3 ~55 ~18 ~3 ~55 bookshelf 0  
fill ~17 ~3 ~56 ~18 ~3 ~56 bookshelf 0  
fill ~18 ~3 ~3 ~18 ~10 ~3 stained_hardened_clay 13  
fill ~18 ~3 ~8 ~19 ~3 ~8 bookshelf 0  
fill ~18 ~3 ~9 ~19 ~3 ~9 bookshelf 0  
fill ~18 ~3 ~53 ~19 ~3 ~53 bookshelf 0  
fill ~18 ~3 ~54 ~19 ~3 ~54 bookshelf 0  
fill ~18 ~3 ~59 ~18 ~10 ~59 stained_hardened_clay 13 
setblock ~19 ~3 ~3 stained_hardened_clay 4  
fill ~19 ~3 ~10 ~20 ~3 ~10 bookshelf 0  
fill ~19 ~3 ~11 ~20 ~3 ~11 bookshelf 0  
fill ~19 ~3 ~23 ~22 ~3 ~23 bookshelf 0  
fill ~19 ~3 ~28 ~24 ~3 ~28 bookshelf 0  
fill ~19 ~3 ~29 ~24 ~3 ~29 bookshelf 0  
fill ~19 ~3 ~33 ~24 ~3 ~33 bookshelf 0  
fill ~19 ~3 ~34 ~24 ~3 ~34 bookshelf 0  
fill ~19 ~3 ~39 ~22 ~3 ~39 bookshelf 0  
fill ~19 ~3 ~51 ~20 ~3 ~51 bookshelf 0  
fill ~19 ~3 ~52 ~20 ~3 ~52 bookshelf 0 
setblock ~19 ~3 ~59 stained_hardened_clay 4  
fill ~20 ~3 ~2 ~20 ~7 ~2 stained_hardened_clay 13  
fill ~20 ~3 ~12 ~21 ~3 ~12 bookshelf 0  
fill ~20 ~3 ~13 ~21 ~3 ~13 bookshelf 0  
fill ~20 ~3 ~49 ~21 ~3 ~49 bookshelf 0  
fill ~20 ~3 ~50 ~21 ~3 ~50 bookshelf 0  
fill ~20 ~3 ~60 ~20 ~7 ~60 stained_hardened_clay 13 
setblock ~21 ~3 ~2 stained_hardened_clay 4  
fill ~21 ~3 ~14 ~22 ~3 ~14 bookshelf 0  
fill ~21 ~3 ~15 ~22 ~3 ~15 bookshelf 0  
fill ~21 ~3 ~24 ~23 ~3 ~24 bookshelf 0  
fill ~21 ~3 ~38 ~23 ~3 ~38 bookshelf 0  
fill ~21 ~3 ~47 ~22 ~3 ~47 bookshelf 0  
fill ~21 ~3 ~48 ~22 ~3 ~48 bookshelf 0 
setblock ~21 ~3 ~60 stained_hardened_clay 4 
setblock ~22 ~3 ~2 stained_hardened_clay 13  
fill ~22 ~3 ~16 ~23 ~3 ~16 bookshelf 0  
fill ~22 ~3 ~17 ~23 ~3 ~17 bookshelf 0  
fill ~22 ~3 ~45 ~23 ~3 ~45 bookshelf 0  
fill ~22 ~3 ~46 ~23 ~3 ~46 bookshelf 0 
setblock ~22 ~3 ~60 stained_hardened_clay 13  
fill ~23 ~3 ~1 ~26 ~3 ~1 stained_hardened_clay 13  
fill ~23 ~3 ~2 ~24 ~3 ~2 bookshelf 0  
fill ~23 ~3 ~3 ~24 ~3 ~3 bookshelf 0  
fill ~23 ~3 ~4 ~24 ~3 ~4 bookshelf 0  
fill ~23 ~3 ~5 ~24 ~3 ~5 bookshelf 0  
fill ~23 ~3 ~18 ~24 ~3 ~18 bookshelf 0  
fill ~23 ~3 ~19 ~24 ~3 ~19 bookshelf 0  
fill ~23 ~3 ~43 ~24 ~3 ~43 bookshelf 0  
fill ~23 ~3 ~44 ~24 ~3 ~44 bookshelf 0  
fill ~23 ~3 ~57 ~24 ~3 ~57 bookshelf 0  
fill ~23 ~3 ~58 ~24 ~3 ~58 bookshelf 0  
fill ~23 ~3 ~59 ~24 ~3 ~59 bookshelf 0  
fill ~23 ~3 ~60 ~24 ~3 ~60 bookshelf 0  
fill ~23 ~3 ~61 ~26 ~3 ~61 stained_hardened_clay 13  
fill ~24 ~3 ~6 ~25 ~3 ~6 bookshelf 0  
fill ~24 ~3 ~7 ~25 ~3 ~7 bookshelf 0  
fill ~24 ~3 ~8 ~25 ~3 ~8 bookshelf 0  
fill ~24 ~3 ~9 ~30 ~3 ~9 bookshelf 0  
fill ~24 ~3 ~20 ~25 ~3 ~20 bookshelf 0  
fill ~24 ~3 ~21 ~25 ~3 ~21 bookshelf 0  
fill ~24 ~3 ~41 ~25 ~3 ~41 bookshelf 0  
fill ~24 ~3 ~42 ~25 ~3 ~42 bookshelf 0  
fill ~24 ~3 ~53 ~30 ~3 ~53 bookshelf 0  
fill ~24 ~3 ~54 ~25 ~3 ~54 bookshelf 0  
fill ~24 ~3 ~55 ~25 ~3 ~55 bookshelf 0  
fill ~24 ~3 ~56 ~25 ~3 ~56 bookshelf 0  
fill ~25 ~3 ~10 ~26 ~3 ~10 bookshelf 0  
fill ~25 ~3 ~11 ~26 ~3 ~11 bookshelf 0  
fill ~25 ~3 ~12 ~26 ~3 ~12 bookshelf 0  
fill ~25 ~3 ~13 ~26 ~3 ~13 bookshelf 0  
fill ~25 ~3 ~22 ~26 ~3 ~22 bookshelf 0  
fill ~25 ~3 ~40 ~26 ~3 ~40 bookshelf 0  
fill ~25 ~3 ~49 ~26 ~3 ~49 bookshelf 0  
fill ~25 ~3 ~50 ~26 ~3 ~50 bookshelf 0  
fill ~25 ~3 ~51 ~26 ~3 ~51 bookshelf 0  
fill ~25 ~3 ~52 ~26 ~3 ~52 bookshelf 0  
fill ~29 ~3 ~0 ~29 ~4 ~0 glass 4  
fill ~29 ~3 ~10 ~30 ~3 ~10 bookshelf 0  
fill ~29 ~3 ~11 ~30 ~3 ~11 bookshelf 0  
fill ~29 ~3 ~12 ~30 ~3 ~12 bookshelf 0  
fill ~29 ~3 ~13 ~30 ~3 ~13 bookshelf 0  
fill ~29 ~3 ~14 ~30 ~3 ~14 bookshelf 0  
fill ~29 ~3 ~18 ~30 ~3 ~18 bookshelf 0  
fill ~29 ~3 ~19 ~30 ~3 ~19 bookshelf 0  
fill ~29 ~3 ~20 ~30 ~3 ~20 bookshelf 0  
fill ~29 ~3 ~21 ~30 ~3 ~21 bookshelf 0  
fill ~29 ~3 ~22 ~30 ~3 ~22 bookshelf 0  
fill ~29 ~3 ~23 ~30 ~3 ~23 bookshelf 0  
fill ~29 ~3 ~39 ~30 ~3 ~39 bookshelf 0  
fill ~29 ~3 ~40 ~30 ~3 ~40 bookshelf 0  
fill ~29 ~3 ~41 ~30 ~3 ~41 bookshelf 0  
fill ~29 ~3 ~42 ~30 ~3 ~42 bookshelf 0  
fill ~29 ~3 ~43 ~30 ~3 ~43 bookshelf 0  
fill ~29 ~3 ~44 ~30 ~3 ~44 bookshelf 0  
fill ~29 ~3 ~48 ~30 ~3 ~48 bookshelf 0  
fill ~29 ~3 ~49 ~30 ~3 ~49 bookshelf 0  
fill ~29 ~3 ~50 ~30 ~3 ~50 bookshelf 0  
fill ~29 ~3 ~51 ~30 ~3 ~51 bookshelf 0  
fill ~29 ~3 ~52 ~30 ~3 ~52 bookshelf 0  
fill ~29 ~3 ~62 ~29 ~4 ~62 glass 4 
setblock ~31 ~3 ~0 stained_hardened_clay 13  
fill ~31 ~3 ~30 ~31 ~4 ~30 log 1  
fill ~31 ~3 ~32 ~31 ~4 ~32 log 1 
setblock ~31 ~3 ~62 stained_hardened_clay 13 
setblock ~32 ~3 ~0 glass 4  
fill ~32 ~3 ~28 ~32 ~3 ~29 oak_stairs 4 
setblock ~32 ~3 ~62 glass 4 
setblock ~33 ~3 ~0 stained_hardened_clay 13 
setblock ~33 ~3 ~28 oak_stairs 1 
setblock ~33 ~3 ~29 spruce_stairs 1  
fill ~33 ~3 ~30 ~33 ~4 ~30 log 1  
fill ~33 ~3 ~32 ~33 ~4 ~32 log 1 
setblock ~33 ~3 ~62 stained_hardened_clay 13  
fill ~34 ~3 ~9 ~40 ~3 ~9 bookshelf 0  
fill ~34 ~3 ~10 ~35 ~3 ~10 bookshelf 0  
fill ~34 ~3 ~11 ~35 ~3 ~11 bookshelf 0  
fill ~34 ~3 ~12 ~35 ~3 ~12 bookshelf 0  
fill ~34 ~3 ~13 ~35 ~3 ~13 bookshelf 0  
fill ~34 ~3 ~14 ~35 ~3 ~14 bookshelf 0  
fill ~34 ~3 ~18 ~35 ~3 ~18 bookshelf 0  
fill ~34 ~3 ~19 ~35 ~3 ~19 bookshelf 0  
fill ~34 ~3 ~20 ~35 ~3 ~20 bookshelf 0  
fill ~34 ~3 ~21 ~35 ~3 ~21 bookshelf 0  
fill ~34 ~3 ~22 ~35 ~3 ~22 bookshelf 0  
fill ~34 ~3 ~23 ~35 ~3 ~23 bookshelf 0  
fill ~34 ~3 ~39 ~35 ~3 ~39 bookshelf 0  
fill ~34 ~3 ~40 ~35 ~3 ~40 bookshelf 0  
fill ~34 ~3 ~41 ~35 ~3 ~41 bookshelf 0  
fill ~34 ~3 ~42 ~35 ~3 ~42 bookshelf 0  
fill ~34 ~3 ~43 ~35 ~3 ~43 bookshelf 0  
fill ~34 ~3 ~44 ~35 ~3 ~44 bookshelf 0  
fill ~34 ~3 ~48 ~35 ~3 ~48 bookshelf 0  
fill ~34 ~3 ~49 ~35 ~3 ~49 bookshelf 0  
fill ~34 ~3 ~50 ~35 ~3 ~50 bookshelf 0  
fill ~34 ~3 ~51 ~35 ~3 ~51 bookshelf 0  
fill ~34 ~3 ~52 ~35 ~3 ~52 bookshelf 0  
fill ~34 ~3 ~53 ~40 ~3 ~53 bookshelf 0  
fill ~35 ~3 ~0 ~35 ~4 ~0 glass 4  
fill ~35 ~3 ~62 ~35 ~4 ~62 glass 4  
fill ~38 ~3 ~1 ~41 ~3 ~1 stained_hardened_clay 13  
fill ~38 ~3 ~10 ~39 ~3 ~10 bookshelf 0  
fill ~38 ~3 ~11 ~39 ~3 ~11 bookshelf 0  
fill ~38 ~3 ~12 ~39 ~3 ~12 bookshelf 0  
fill ~38 ~3 ~13 ~39 ~3 ~13 bookshelf 0  
fill ~38 ~3 ~22 ~39 ~3 ~22 bookshelf 0  
fill ~38 ~3 ~40 ~39 ~3 ~40 bookshelf 0  
fill ~38 ~3 ~49 ~39 ~3 ~49 bookshelf 0  
fill ~38 ~3 ~50 ~39 ~3 ~50 bookshelf 0  
fill ~38 ~3 ~51 ~39 ~3 ~51 bookshelf 0  
fill ~38 ~3 ~52 ~39 ~3 ~52 bookshelf 0  
fill ~38 ~3 ~61 ~41 ~3 ~61 stained_hardened_clay 13  
fill ~39 ~3 ~6 ~40 ~3 ~6 bookshelf 0  
fill ~39 ~3 ~7 ~40 ~3 ~7 bookshelf 0  
fill ~39 ~3 ~8 ~40 ~3 ~8 bookshelf 0  
fill ~39 ~3 ~20 ~40 ~3 ~20 bookshelf 0  
fill ~39 ~3 ~21 ~40 ~3 ~21 bookshelf 0  
fill ~39 ~3 ~41 ~40 ~3 ~41 bookshelf 0  
fill ~39 ~3 ~42 ~40 ~3 ~42 bookshelf 0  
fill ~39 ~3 ~54 ~40 ~3 ~54 bookshelf 0  
fill ~39 ~3 ~55 ~40 ~3 ~55 bookshelf 0  
fill ~39 ~3 ~56 ~40 ~3 ~56 bookshelf 0  
fill ~40 ~3 ~2 ~41 ~3 ~2 bookshelf 0  
fill ~40 ~3 ~3 ~41 ~3 ~3 bookshelf 0  
fill ~40 ~3 ~4 ~41 ~3 ~4 bookshelf 0  
fill ~40 ~3 ~5 ~41 ~3 ~5 bookshelf 0  
fill ~40 ~3 ~18 ~41 ~3 ~18 bookshelf 0  
fill ~40 ~3 ~19 ~41 ~3 ~19 bookshelf 0  
fill ~40 ~3 ~28 ~45 ~3 ~28 bookshelf 0  
fill ~40 ~3 ~29 ~45 ~3 ~29 bookshelf 0  
fill ~40 ~3 ~33 ~45 ~3 ~33 bookshelf 0  
fill ~40 ~3 ~34 ~45 ~3 ~34 bookshelf 0  
fill ~40 ~3 ~43 ~41 ~3 ~43 bookshelf 0  
fill ~40 ~3 ~44 ~41 ~3 ~44 bookshelf 0  
fill ~40 ~3 ~57 ~41 ~3 ~57 bookshelf 0  
fill ~40 ~3 ~58 ~41 ~3 ~58 bookshelf 0  
fill ~40 ~3 ~59 ~41 ~3 ~59 bookshelf 0  
fill ~40 ~3 ~60 ~41 ~3 ~60 bookshelf 0  
fill ~41 ~3 ~16 ~42 ~3 ~16 bookshelf 0  
fill ~41 ~3 ~17 ~42 ~3 ~17 bookshelf 0  
fill ~41 ~3 ~24 ~43 ~3 ~24 bookshelf 0  
fill ~41 ~3 ~38 ~43 ~3 ~38 bookshelf 0  
fill ~41 ~3 ~45 ~42 ~3 ~45 bookshelf 0  
fill ~41 ~3 ~46 ~42 ~3 ~46 bookshelf 0  
fill ~42 ~3 ~2 ~42 ~0 ~2 stained_hardened_clay 13  
fill ~42 ~3 ~14 ~43 ~3 ~14 bookshelf 0  
fill ~42 ~3 ~15 ~43 ~3 ~15 bookshelf 0  
fill ~42 ~3 ~23 ~45 ~3 ~23 bookshelf 0  
fill ~42 ~3 ~39 ~45 ~3 ~39 bookshelf 0  
fill ~42 ~3 ~47 ~43 ~3 ~47 bookshelf 0  
fill ~42 ~3 ~48 ~43 ~3 ~48 bookshelf 0  
fill ~42 ~3 ~60 ~42 ~0 ~60 stained_hardened_clay 13 
setblock ~43 ~3 ~2 stained_hardened_clay 4  
fill ~43 ~3 ~12 ~44 ~3 ~12 bookshelf 0  
fill ~43 ~3 ~13 ~44 ~3 ~13 bookshelf 0  
fill ~43 ~3 ~49 ~44 ~3 ~49 bookshelf 0  
fill ~43 ~3 ~50 ~44 ~3 ~50 bookshelf 0 
setblock ~43 ~3 ~60 stained_hardened_clay 4  
fill ~44 ~3 ~2 ~44 ~7 ~2 stained_hardened_clay 13  
fill ~44 ~3 ~10 ~45 ~3 ~10 bookshelf 0  
fill ~44 ~3 ~11 ~45 ~3 ~11 bookshelf 0  
fill ~44 ~3 ~22 ~47 ~3 ~22 bookshelf 0  
fill ~44 ~3 ~40 ~47 ~3 ~40 bookshelf 0  
fill ~44 ~3 ~51 ~45 ~3 ~51 bookshelf 0  
fill ~44 ~3 ~52 ~45 ~3 ~52 bookshelf 0  
fill ~44 ~3 ~60 ~44 ~7 ~60 stained_hardened_clay 13 
setblock ~45 ~3 ~3 stained_hardened_clay 4  
fill ~45 ~3 ~8 ~46 ~3 ~8 bookshelf 0  
fill ~45 ~3 ~9 ~46 ~3 ~9 bookshelf 0  
fill ~45 ~3 ~53 ~46 ~3 ~53 bookshelf 0  
fill ~45 ~3 ~54 ~46 ~3 ~54 bookshelf 0 
setblock ~45 ~3 ~59 stained_hardened_clay 4
fill ~46 ~3 ~3 ~46 ~10 ~3 stained_hardened_clay 13  
fill ~46 ~3 ~6 ~47 ~3 ~6 bookshelf 0  
fill ~46 ~3 ~7 ~47 ~3 ~7 bookshelf 0  
fill ~46 ~3 ~21 ~49 ~3 ~21 bookshelf 0  
fill ~46 ~3 ~41 ~49 ~3 ~41 bookshelf 0  
fill ~46 ~3 ~55 ~47 ~3 ~55 bookshelf 0  
fill ~46 ~3 ~56 ~47 ~3 ~56 bookshelf 0  
fill ~46 ~3 ~59 ~46 ~10 ~59 stained_hardened_clay 13  
fill ~47 ~3 ~4 ~48 ~3 ~4 stained_hardened_clay 13  
fill ~47 ~3 ~5 ~48 ~3 ~5 bookshelf 0  
fill ~47 ~3 ~25 ~54 ~3 ~25 bookshelf 0  
fill ~47 ~3 ~37 ~54 ~3 ~37 bookshelf 0  
fill ~47 ~3 ~57 ~48 ~3 ~57 bookshelf 0  
fill ~47 ~3 ~58 ~48 ~3 ~58 stained_hardened_clay 13  
fill ~48 ~3 ~20 ~51 ~3 ~20 bookshelf 0  
fill ~48 ~3 ~42 ~51 ~3 ~42 bookshelf 0  
fill ~49 ~3 ~28 ~54 ~3 ~28 bookshelf 0  
fill ~49 ~3 ~29 ~54 ~3 ~29 bookshelf 0  
fill ~49 ~3 ~33 ~54 ~3 ~33 bookshelf 0  
fill ~49 ~3 ~34 ~54 ~3 ~34 bookshelf 0  
fill ~50 ~3 ~6 ~50 ~5 ~6 glass 4  
fill ~50 ~3 ~19 ~53 ~3 ~19 bookshelf 0  
fill ~50 ~3 ~24 ~57 ~3 ~24 bookshelf 0  
fill ~50 ~3 ~38 ~57 ~3 ~38 bookshelf 0  
fill ~50 ~3 ~43 ~53 ~3 ~43 bookshelf 0  
fill ~50 ~3 ~56 ~50 ~5 ~56 glass 4  
fill ~52 ~3 ~7 ~52 ~9 ~7 stained_hardened_clay 13  
fill ~52 ~3 ~18 ~55 ~3 ~18 bookshelf 0  
fill ~52 ~3 ~44 ~55 ~3 ~44 bookshelf 0  
fill ~52 ~3 ~55 ~52 ~9 ~55 stained_hardened_clay 13 
setblock ~53 ~3 ~8 stained_hardened_clay 4 
setblock ~53 ~3 ~54 stained_hardened_clay 4  
fill ~54 ~3 ~17 ~57 ~3 ~17 bookshelf 0  
fill ~54 ~3 ~23 ~61 ~3 ~23 bookshelf 0  
fill ~54 ~3 ~39 ~61 ~3 ~39 bookshelf 0  
fill ~54 ~3 ~45 ~57 ~3 ~45 bookshelf 0 
setblock ~55 ~3 ~10 stained_hardened_clay 4 
setblock ~55 ~3 ~52 stained_hardened_clay 4  
fill ~56 ~3 ~11 ~56 ~9 ~11 stained_hardened_clay 13  
fill ~56 ~3 ~16 ~58 ~3 ~16 bookshelf 0  
fill ~56 ~3 ~46 ~58 ~3 ~46 bookshelf 0  
fill ~56 ~3 ~51 ~56 ~9 ~51 stained_hardened_clay 13  
fill ~57 ~3 ~13 ~57 ~5 ~13 glass 4  
fill ~57 ~3 ~49 ~57 ~5 ~49 glass 4  
fill ~58 ~3 ~22 ~61 ~3 ~22 bookshelf 0  
fill ~58 ~3 ~40 ~61 ~3 ~40 bookshelf 0 
setblock ~60 ~3 ~18 stained_hardened_clay 4 
setblock ~60 ~3 ~44 stained_hardened_clay 4  
fill ~61 ~3 ~19 ~61 ~7 ~19 stained_hardened_clay 13 
setblock ~61 ~3 ~20 stained_hardened_clay 4 
setblock ~61 ~3 ~42 stained_hardened_clay 4  
fill ~61 ~3 ~43 ~61 ~7 ~43 stained_hardened_clay 13  
fill ~63 ~3 ~28 ~63 ~4 ~28 glass 4 
setblock ~63 ~3 ~30 stained_hardened_clay 13 
setblock ~63 ~3 ~31 glass 4 
setblock ~63 ~3 ~32 stained_hardened_clay 13  
fill ~63 ~3 ~34 ~63 ~4 ~34 glass 4 
setblock ~1 ~4 ~30 stained_hardened_clay 4  
fill ~1 ~4 ~31 ~1 ~6 ~31 stained_hardened_clay 13 
setblock ~1 ~4 ~32 stained_hardened_clay 4  
fill ~2 ~4 ~23 ~2 ~12 ~23 stained_hardened_clay 13 
setblock ~2 ~4 ~24 stained_hardened_clay 4  
fill ~2 ~4 ~28 ~6 ~4 ~28 bookshelf 0  
fill ~2 ~4 ~29 ~6 ~4 ~29 bookshelf 0  
fill ~2 ~4 ~33 ~6 ~4 ~33 bookshelf 0  
fill ~2 ~4 ~34 ~6 ~4 ~34 bookshelf 0  
fill ~2 ~4 ~38 ~2 ~4 ~39 stained_hardened_clay 4  
fill ~2 ~4 ~40 ~2 ~11 ~40 stained_hardened_clay 13  
fill ~3 ~4 ~22 ~6 ~4 ~22 bookshelf 0  
fill ~3 ~4 ~23 ~10 ~4 ~23 bookshelf 0  
fill ~3 ~4 ~39 ~10 ~4 ~39 bookshelf 0  
fill ~3 ~4 ~40 ~6 ~4 ~40 bookshelf 0  
fill ~4 ~4 ~18 ~4 ~6 ~18 glass 4  
fill ~4 ~4 ~44 ~4 ~6 ~44 glass 4  
fill ~6 ~4 ~16 ~8 ~4 ~16 bookshelf 0  
fill ~6 ~4 ~46 ~8 ~4 ~46 bookshelf 0  
fill ~7 ~4 ~17 ~10 ~4 ~17 bookshelf 0  
fill ~7 ~4 ~24 ~14 ~4 ~24 bookshelf 0  
fill ~7 ~4 ~38 ~14 ~4 ~38 bookshelf 0  
fill ~7 ~4 ~45 ~10 ~4 ~45 bookshelf 0  
fill ~9 ~4 ~10 ~9 ~8 ~10 stained_hardened_clay 13  
fill ~9 ~4 ~18 ~12 ~4 ~18 bookshelf 0  
fill ~9 ~4 ~44 ~12 ~4 ~44 bookshelf 0  
fill ~9 ~4 ~52 ~9 ~8 ~52 stained_hardened_clay 13 
setblock ~10 ~4 ~9 stained_hardened_clay 4  
fill ~10 ~4 ~28 ~15 ~4 ~28 bookshelf 0  
fill ~10 ~4 ~29 ~15 ~4 ~29 bookshelf 0  
fill ~10 ~4 ~33 ~15 ~4 ~33 bookshelf 0  
fill ~10 ~4 ~34 ~15 ~4 ~34 bookshelf 0 
setblock ~10 ~4 ~53 stained_hardened_clay 4  
fill ~11 ~4 ~8 ~11 ~8 ~8 stained_hardened_clay 13 
setblock ~11 ~4 ~10 glowstone 0  
fill ~11 ~4 ~19 ~14 ~4 ~19 bookshelf 0  
fill ~11 ~4 ~25 ~17 ~4 ~25 bookshelf 0  
fill ~11 ~4 ~37 ~17 ~4 ~37 bookshelf 0  
fill ~11 ~4 ~43 ~14 ~4 ~43 bookshelf 0 
setblock ~11 ~4 ~52 glowstone 0  
fill ~11 ~4 ~54 ~11 ~8 ~54 stained_hardened_clay 13  
fill ~13 ~4 ~20 ~16 ~4 ~20 bookshelf 0 
setblock ~13 ~4 ~22 glowstone 0 
setblock ~13 ~4 ~40 glowstone 0  
fill ~13 ~4 ~42 ~16 ~4 ~42 bookshelf 0 
setblock ~14 ~4 ~17 glowstone 0 
setblock ~14 ~4 ~45 glowstone 0  
fill ~15 ~4 ~21 ~18 ~4 ~21 bookshelf 0  
fill ~15 ~4 ~41 ~18 ~4 ~41 bookshelf 0  
fill ~16 ~4 ~4 ~17 ~4 ~4 stained_hardened_clay 13  
fill ~16 ~4 ~5 ~17 ~4 ~5 bookshelf 0  
fill ~16 ~4 ~57 ~17 ~4 ~57 bookshelf 0  
fill ~16 ~4 ~58 ~17 ~4 ~58 stained_hardened_clay 13  
fill ~17 ~4 ~6 ~18 ~4 ~6 bookshelf 0  
