setblock ~15~22~9 minecraft:cobblestone_wall 13
fill ~16~22~9 ~17~22~9 minecraft:cobblestone_wall 13
setblock ~18~22~9 minecraft:cobblestone_wall 13
fill ~19~22~9 ~20~22~9 minecraft:cobblestone_wall 13
setblock ~21~22~9 minecraft:cobblestone_wall 13
fill ~22~22~9 ~23~22~9 minecraft:cobblestone_wall 13
setblock ~24~22~9 minecraft:cobblestone_wall 13
setblock ~13~22~10 minecraft:cobblestone_wall 13
setblock ~14~22~10 minecraft:cobblestone_wall 13
setblock ~15~17~10 minecraft:soul_lantern 1
fill ~15~18~10 ~15~19~10 minecraft:cobblestone_wall 7
setblock ~15~20~10 minecraft:stonebrick 0
fill ~15~21~10 ~15~22~10 minecraft:stone 6
setblock ~15~23~10 minecraft:stonebrick 0
setblock ~15~24~10 minecraft:polished_andesite_stairs 2
fill ~16~21~10 ~17~21~10 minecraft:polished_andesite_stairs 6
fill ~18~18~10 ~18~19~10 minecraft:cobblestone_wall 8
setblock ~18~20~10 minecraft:stonebrick 0
fill ~18~21~10 ~18~22~10 minecraft:stone 6
setblock ~18~23~10 minecraft:stonebrick 0
setblock ~18~24~10 minecraft:polished_andesite_stairs 2
fill ~19~0~10 ~22~0~18 minecraft:stone 0
fill ~19~21~10 ~20~21~10 minecraft:polished_andesite_stairs 6
setblock ~21~17~10 minecraft:soul_lantern 1
fill ~21~18~10 ~21~19~10 minecraft:cobblestone_wall 8
setblock ~21~20~10 minecraft:stonebrick 0
fill ~21~21~10 ~21~22~10 minecraft:stone 6
setblock ~21~23~10 minecraft:stonebrick 0
setblock ~21~24~10 minecraft:polished_andesite_stairs 2
fill ~22~21~10 ~23~21~10 minecraft:polished_andesite_stairs 6
fill ~24~18~10 ~24~19~10 minecraft:cobblestone_wall 7
setblock ~24~20~10 minecraft:stonebrick 0
fill ~24~21~10 ~24~22~10 minecraft:stone 6
setblock ~24~23~10 minecraft:stonebrick 0
setblock ~24~24~10 minecraft:polished_andesite_stairs 2
setblock ~25~22~10 minecraft:cobblestone_wall 13
setblock ~26~22~10 minecraft:cobblestone_wall 13
setblock ~12~22~11 minecraft:cobblestone_wall 13
setblock ~13~22~11 minecraft:cobblestone_wall 13
setblock ~14~21~11 minecraft:polished_andesite_stairs 6
setblock ~15~21~11 minecraft:polished_andesite_stairs 4
setblock ~15~24~11 minecraft:stone_block_slab 8
setblock ~15~25~11 minecraft:cobblestone_wall 13
fill ~16~0~11 ~18~2~18 minecraft:stone 0
fill ~16~3~11 ~16~4~11 minecraft:netherite_block
fill ~16~5~11 ~16~6~11 minecraft:cobblestone_wall 3
fill ~16~7~11 ~16~8~11 minecraft:netherite_block
fill ~16~9~11 ~16~10~11 minecraft:cobblestone_wall 3
fill ~16~11~11 ~16~12~11 minecraft:netherite_block
fill ~16~13~11 ~16~14~11 minecraft:cobblestone_wall 3
fill ~16~15~11 ~16~16~11 minecraft:netherite_block
fill ~16~17~11 ~16~18~11 minecraft:cobblestone_wall 3
fill ~16~19~11 ~16~20~11 minecraft:netherite_block
fill ~16~21~11 ~23~21~11 minecraft:stone_block_slab 5
fill ~17~3~11 ~18~15~11 minecraft:cobblestone_wall 13
setblock ~17~16~11 minecraft:cobblestone_wall 13
setblock ~17~17~11 minecraft:cobblestone_wall 13
fill ~17~18~11 ~17~20~11 minecraft:cobblestone_wall 13
setblock ~18~16~11 minecraft:cobblestone_wall 13
fill ~18~18~11 ~18~20~11 minecraft:cobblestone_wall 13
setblock ~18~24~11 minecraft:stone_block_slab 8
setblock ~18~25~11 minecraft:cobblestone_wall 13
setblock ~18~26~11 minecraft:lantern 0
fill ~19~1~11 ~23~2~18 minecraft:stone 0
fill ~19~3~11 ~20~4~11 minecraft:netherite_block
fill ~19~5~11 ~20~6~11 minecraft:cobblestone_wall 3
fill ~19~7~11 ~20~8~11 minecraft:netherite_block
fill ~19~9~11 ~20~10~11 minecraft:cobblestone_wall 3
fill ~19~11~11 ~20~12~11 minecraft:netherite_block
fill ~19~13~11 ~20~14~11 minecraft:cobblestone_wall 3
fill ~19~15~11 ~20~16~11 minecraft:netherite_block
fill ~19~18~11 ~20~18~11 minecraft:cobblestone_wall 3
fill ~19~19~11 ~20~20~11 minecraft:netherite_block
setblock ~20~17~11 minecraft:cobblestone_wall 3
fill ~21~3~11 ~22~17~11 minecraft:cobblestone_wall 13
fill ~21~18~11 ~21~20~11 minecraft:cobblestone_wall 13
setblock ~21~24~11 minecraft:stone_block_slab 8
setblock ~21~25~11 minecraft:cobblestone_wall 13
fill ~22~18~11 ~22~20~11 minecraft:cobblestone_wall 13
fill ~23~0~11 ~25~0~19 minecraft:stone 0
fill ~23~3~11 ~23~4~11 minecraft:netherite_block
fill ~23~5~11 ~23~6~11 minecraft:cobblestone_wall 3
fill ~23~7~11 ~23~8~11 minecraft:netherite_block
fill ~23~9~11 ~23~10~11 minecraft:cobblestone_wall 3
fill ~23~11~11 ~23~12~11 minecraft:netherite_block
fill ~23~13~11 ~23~14~11 minecraft:cobblestone_wall 3
fill ~23~15~11 ~23~16~11 minecraft:netherite_block
fill ~23~17~11 ~23~18~11 minecraft:cobblestone_wall 3
fill ~23~19~11 ~23~20~11 minecraft:netherite_block
setblock ~24~21~11 minecraft:polished_andesite_stairs 5
setblock ~24~24~11 minecraft:stone_block_slab 8
setblock ~24~25~11 minecraft:cobblestone_wall 13
setblock ~24~26~11 minecraft:lantern 0
setblock ~25~21~11 minecraft:polished_andesite_stairs 6
setblock ~26~22~11 minecraft:cobblestone_wall 13
setblock ~27~22~11 minecraft:cobblestone_wall 13
setblock ~28~22~11 minecraft:cobblestone_wall 13
setblock ~12~22~12 minecraft:cobblestone_wall 13
setblock ~13~21~12 minecraft:polished_andesite_stairs 6
fill ~14~0~12 ~14~20~12 minecraft:iron_bars
setblock ~14~21~12 minecraft:polished_andesite_stairs 4
fill ~15~0~12 ~15~0~19 minecraft:stone 0
fill ~15~1~12 ~15~1~18 minecraft:stone 0
fill ~15~2~12 ~15~20~12 minecraft:netherite_block
setblock ~15~21~12 minecraft:stone_block_slab 5
fill ~16~3~12 ~16~20~12 minecraft:stone 6
setblock ~16~28~12 minecraft:polished_andesite_stairs 4
setblock ~16~29~12 minecraft:polished_andesite_stairs 0
fill ~16~34~12 ~16~34~13 minecraft:polished_andesite_stairs 4
fill ~16~35~12 ~17~35~12 minecraft:stone 6
setblock ~16~36~12 minecraft:stonebrick 0
fill ~16~37~12 ~17~37~12 minecraft:polished_andesite_stairs 2
fill ~17~3~12 ~22~3~27 minecraft:stonebrick 0
fill ~17~4~12 ~22~16~12 minecraft:stonebrick 0
fill ~17~17~12 ~17~20~12 minecraft:stonebrick 0
setblock ~17~28~12 minecraft:polished_andesite_stairs 6
setblock ~17~29~12 minecraft:polished_andesite_stairs 2
setblock ~17~34~12 minecraft:polished_andesite_stairs 6
setblock ~17~36~12 minecraft:stone_brick_stairs 0
fill ~18~17~12 ~19~17~12 minecraft:iron_bars
fill ~18~18~12 ~22~20~12 minecraft:stonebrick 0
fill ~18~35~12 ~21~35~12 minecraft:cobblestone_wall 13
setblock ~19~23~12 minecraft:polished_andesite_stairs 6
fill ~19~24~12 ~19~25~12 minecraft:cobblestone_wall 13
setblock ~19~26~12 minecraft:polished_andesite_stairs 2
fill ~20~17~12 ~22~17~12 minecraft:stonebrick 0
setblock ~20~29~12 minecraft:polished_andesite_stairs 6
setblock ~20~30~12 minecraft:cobblestone_wall 13
setblock ~20~31~12 minecraft:cobblestone_wall 13
setblock ~20~32~12 minecraft:cobblestone_wall 13
setblock ~20~33~12 minecraft:polished_andesite_stairs 2
setblock ~22~28~12 minecraft:polished_andesite_stairs 6
setblock ~22~29~12 minecraft:polished_andesite_stairs 2
fill ~22~34~12 ~23~34~12 minecraft:polished_andesite_stairs 6
fill ~22~35~12 ~23~35~12 minecraft:stone 6
setblock ~22~36~12 minecraft:stone_brick_stairs 1
setblock ~22~37~12 minecraft:polished_andesite_stairs 2
fill ~23~3~12 ~23~20~12 minecraft:stone 6
setblock ~23~28~12 minecraft:polished_andesite_stairs 5
setblock ~23~29~12 minecraft:polished_andesite_stairs 1
setblock ~23~36~12 minecraft:stonebrick 0
fill ~23~37~12 ~23~37~13 minecraft:polished_andesite_stairs 1
fill ~24~1~12 ~24~20~12 minecraft:netherite_block
setblock ~24~21~12 minecraft:stone_block_slab 5
setblock ~25~21~12 minecraft:polished_andesite_stairs 5
fill ~26~0~12 ~28~0~28 minecraft:stone 0
fill ~26~21~12 ~27~21~12 minecraft:polished_andesite_stairs 6
setblock ~27~24~12 minecraft:stone_block_slab 8
setblock ~27~25~12 minecraft:cobblestone_wall 13
setblock ~28~17~12 minecraft:soul_lantern 1
fill ~28~18~12 ~28~19~12 minecraft:cobblestone_wall 7
setblock ~28~20~12 minecraft:stonebrick 0
fill ~28~21~12 ~28~22~12 minecraft:stone 6
setblock ~28~23~12 minecraft:stonebrick 0
setblock ~28~24~12 minecraft:polished_andesite_stairs 1
setblock ~29~22~12 minecraft:cobblestone_wall 13
setblock ~30~22~12 minecraft:cobblestone_wall 13
setblock ~10~22~13 minecraft:cobblestone_wall 13
setblock ~11~22~13 minecraft:cobblestone_wall 13
fill ~12~18~13 ~12~19~13 minecraft:cobblestone_wall 7
setblock ~12~20~13 minecraft:stonebrick 0
fill ~12~21~13 ~12~22~13 minecraft:stone 6
setblock ~12~23~13 minecraft:stonebrick 0
setblock ~12~24~13 minecraft:polished_andesite_stairs 0
fill ~13~0~13 ~14~0~20 minecraft:stone 0
fill ~13~1~13 ~13~20~13 minecraft:iron_bars
setblock ~13~21~13 minecraft:polished_andesite_stairs 4
setblock ~13~24~13 minecraft:stone_block_slab 8
setblock ~13~25~13 minecraft:cobblestone_wall 13
setblock ~13~26~13 minecraft:lantern 0
fill ~14~1~13 ~14~1~20 minecraft:stone 0
fill ~14~2~13 ~14~20~13 minecraft:netherite_block
setblock ~14~21~13 minecraft:stone_block_slab 5
fill ~15~2~13 ~15~2~18 minecraft:stone 0
fill ~15~3~13 ~16~3~13 minecraft:stonebrick 0
fill ~15~4~13 ~15~20~13 minecraft:stonebrick 0
setblock ~15~35~13 minecraft:cobblestone_wall 13
fill ~16~4~13 ~16~5~13 minecraft:fence 0
setblock ~16~6~13 minecraft:double_wooden_slab 0
setblock ~16~7~13 minecraft:fence 0
setblock ~16~8~13 minecraft:double_wooden_slab 0
setblock ~16~9~13 minecraft:fence 0
setblock ~16~10~13 minecraft:double_wooden_slab 0
fill ~16~11~13 ~16~11~18 minecraft:log 0
fill ~16~12~13 ~16~13~13 minecraft:barrel 3
fill ~16~14~13 ~16~15~13 minecraft:barrel 5
setblock ~16~18~13 minecraft:warped_stairs 1
fill ~16~20~13 ~24~20~13 minecraft:stonebrick 0
setblock ~16~28~13 minecraft:polished_andesite_stairs 7
setblock ~16~29~13 minecraft:polished_andesite_stairs 3
setblock ~16~35~13 minecraft:stone 6
setblock ~16~36~13 minecraft:stone_brick_stairs 2
setblock ~16~37~13 minecraft:polished_andesite_stairs 0
fill ~17~4~13 ~22~4~13 minecraft:chest 3
fill ~17~5~13 ~22~5~13 minecraft:wooden_slab 8
fill ~17~6~13 ~22~6~13 minecraft:chest 3
fill ~17~7~13 ~22~7~13 minecraft:wooden_slab 8
fill ~17~8~13 ~22~8~13 minecraft:chest 3
fill ~17~9~13 ~22~9~13 minecraft:wooden_slab 8
fill ~17~10~13 ~22~10~13 minecraft:chest 3
fill ~17~11~13 ~22~11~17 minecraft:wooden_slab 8
fill ~17~18~13 ~23~18~13 minecraft:warped_stairs 3
fill ~17~21~13 ~17~34~13 minecraft:stone 6
setblock ~17~37~13 minecraft:stone_block_slab 8
setblock ~18~15~13 minecraft:wall_banner 3
setblock ~18~21~13 minecraft:stonebrick 0
fill ~18~22~13 ~18~23~13 minecraft:stonebrick 3
fill ~18~24~13 ~19~25~13 minecraft:stonebrick 0
fill ~18~26~13 ~18~27~13 minecraft:stonebrick 3
fill ~18~28~13 ~18~29~13 minecraft:stonebrick 0
fill ~18~30~13 ~18~31~13 minecraft:stonebrick 3
fill ~18~32~13 ~18~33~13 minecraft:stonebrick 0
fill ~18~34~13 ~22~34~14 minecraft:stone 6
fill ~19~21~13 ~20~21~13 minecraft:stone_brick_stairs 2
fill ~19~22~13 ~20~22~13 minecraft:iron_bars
setblock ~19~23~13 minecraft:stone 6
setblock ~19~26~13 minecraft:stone 6
fill ~19~27~13 ~20~27~13 minecraft:iron_bars
fill ~19~28~13 ~20~28~13 minecraft:stone_brick_stairs 6
setblock ~19~29~13 minecraft:stone_brick_stairs 2
fill ~19~30~13 ~19~31~13 minecraft:iron_bars
fill ~19~32~13 ~20~32~13 minecraft:stone_brick_stairs 6
fill ~19~33~13 ~21~33~13 minecraft:stonebrick 0
setblock ~20~16~13 minecraft:wall_banner 3
setblock ~20~23~13 minecraft:iron_bars
setblock ~20~24~13 minecraft:stone_brick_stairs 6
setblock ~20~25~13 minecraft:stone_brick_stairs 2
setblock ~20~26~13 minecraft:iron_bars
fill ~20~29~13 ~21~29~13 minecraft:stonebrick 0
setblock ~20~30~13 minecraft:stone 6
setblock ~20~31~13 minecraft:iron_bars
fill ~20~35~13 ~21~35~13 minecraft:snow_layer 0
fill ~21~12~13 ~23~12~13 minecraft:spruce_stairs 3
setblock ~21~15~13 minecraft:wall_banner 3
setblock ~21~17~13 minecraft:lantern 1
setblock ~21~21~13 minecraft:stonebrick 0
fill ~21~22~13 ~21~23~13 minecraft:stonebrick 3
fill ~21~24~13 ~21~25~13 minecraft:stonebrick 0
fill ~21~26~13 ~21~27~13 minecraft:stonebrick 3
setblock ~21~28~13 minecraft:stonebrick 0
fill ~21~30~13 ~21~31~13 minecraft:stonebrick 3
setblock ~21~32~13 minecraft:stonebrick 0
fill ~22~21~13 ~22~33~13 minecraft:stone 6
setblock ~22~37~13 minecraft:stone_block_slab 8
fill ~23~3~13 ~24~3~14 minecraft:stonebrick 0
fill ~23~4~13 ~23~5~13 minecraft:fence 0
setblock ~23~6~13 minecraft:double_wooden_slab 0
setblock ~23~7~13 minecraft:fence 0
setblock ~23~8~13 minecraft:double_wooden_slab 0
setblock ~23~9~13 minecraft:fence 0
setblock ~23~10~13 minecraft:double_wooden_slab 0
fill ~23~11~13 ~23~11~17 minecraft:log 0
setblock ~23~28~13 minecraft:polished_andesite_stairs 7
setblock ~23~29~13 minecraft:polished_andesite_stairs 3
setblock ~23~34~13 minecraft:polished_andesite_stairs 5
setblock ~23~35~13 minecraft:stone 6
setblock ~23~36~13 minecraft:stone_brick_stairs 2
fill ~24~1~13 ~24~2~20 minecraft:stone 0
fill ~24~4~13 ~24~19~13 minecraft:stonebrick 0
setblock ~24~35~13 minecraft:cobblestone_wall 13
fill ~25~1~13 ~27~1~13 minecraft:netherite_block
setblock ~25~2~13 minecraft:netherite_block
fill ~25~3~13 ~25~4~13 minecraft:cobblestone_wall 3
fill ~25~5~13 ~25~6~13 minecraft:netherite_block
fill ~25~7~13 ~25~8~13 minecraft:cobblestone_wall 3
fill ~25~9~13 ~25~10~13 minecraft:netherite_block
fill ~25~11~13 ~25~12~13 minecraft:cobblestone_wall 3
fill ~25~13~13 ~25~14~13 minecraft:netherite_block
fill ~25~15~13 ~25~16~13 minecraft:cobblestone_wall 3
fill ~25~17~13 ~25~18~13 minecraft:netherite_block
fill ~25~19~13 ~25~20~13 minecraft:cobblestone_wall 3
fill ~25~21~13 ~27~21~13 minecraft:stone_block_slab 5
fill ~26~2~13 ~27~2~13 minecraft:stone 6
fill ~26~3~13 ~26~20~13 minecraft:cobblestone_wall 13
fill ~27~3~13 ~27~20~13 minecraft:cobblestone_wall 13
setblock ~28~21~13 minecraft:polished_andesite_stairs 5
fill ~29~0~13 ~29~0~28 minecraft:stone 0
setblock ~29~21~13 minecraft:polished_andesite_stairs 6
setblock ~30~22~13 minecraft:cobblestone_wall 13
setblock ~10~22~14 minecraft:cobblestone_wall 13
setblock ~11~21~14 minecraft:polished_andesite_stairs 6
fill ~12~0~14 ~12~0~29 minecraft:stone 0
fill ~12~1~14 ~12~20~14 minecraft:iron_bars
setblock ~12~21~14 minecraft:polished_andesite_stairs 4
fill ~13~1~14 ~13~1~21 minecraft:stone 0
fill ~13~2~14 ~13~20~14 minecraft:netherite_block
setblock ~13~21~14 minecraft:stone_block_slab 5
fill ~14~2~14 ~14~2~19 minecraft:stone 0
fill ~14~3~14 ~14~20~14 minecraft:stone 0
setblock ~14~35~14 minecraft:cobblestone_wall 13
fill ~15~3~14 ~15~3~44 minecraft:stonebrick 0
setblock ~15~4~14 minecraft:chest 3
setblock ~15~5~14 minecraft:wooden_slab 8
setblock ~15~6~14 minecraft:chest 3
setblock ~15~7~14 minecraft:wooden_slab 8
setblock ~15~8~14 minecraft:chest 3
setblock ~15~9~14 minecraft:wooden_slab 8
setblock ~15~10~14 minecraft:chest 3
fill ~15~11~14 ~15~11~18 minecraft:wooden_slab 8
setblock ~15~12~14 minecraft:barrel 3
fill ~15~13~14 ~15~15~14 minecraft:barrel 5
setblock ~15~18~14 minecraft:warped_stairs 1
fill ~15~20~14 ~16~20~14 minecraft:stonebrick 0
setblock ~15~35~14 minecraft:cobblestone_wall 13
setblock ~16~3~14 minecraft:stone 0
setblock ~16~18~14 minecraft:warped_stairs 3
fill ~16~21~14 ~16~23~17 minecraft:stonebrick 0
fill ~16~24~14 ~16~33~14 minecraft:stonebrick 0
fill ~16~34~14 ~17~34~15 minecraft:stone 6
fill ~17~20~14 ~22~20~17 minecraft:wooden_slab 8
setblock ~17~21~14 minecraft:bed 1
fill ~17~24~14 ~22~24~14 minecraft:wooden_slab 8
setblock ~17~25~14 minecraft:jukebox
fill ~17~28~14 ~22~28~14 minecraft:wooden_slab 8
fill ~17~29~14 ~18~29~14 minecraft:wooden_slab 9
fill ~17~30~14 ~18~30~14 minecraft:chest 3
fill ~17~32~14 ~17~33~14 minecraft:leaves 3
fill ~18~25~14 ~18~25~15 minecraft:carpet 14
setblock ~18~27~14 minecraft:wall_banner 3
fill ~18~33~14 ~19~33~14 minecraft:leaves 3
setblock ~18~35~14 minecraft:concrete 14
setblock ~18~36~14 minecraft:concrete 0
setblock ~18~37~14 minecraft:crimson_fence
setblock ~18~38~14 minecraft:lantern 0
fill ~19~35~14 ~20~35~14 minecraft:red_nether_brick_stairs 2
setblock ~20~25~14 minecraft:warped_trapdoor 1
setblock ~20~29~14 minecraft:cartography_table
fill ~20~30~14 ~22~30~14 minecraft:wooden_slab 9
fill ~20~31~14 ~20~33~14 minecraft:chain 0
fill ~21~12~14 ~22~12~14 minecraft:fence 0
fill ~21~13~14 ~22~13~14 minecraft:dark_oak_pressure_plate 0
setblock ~21~25~14 minecraft:warped_stairs 3
setblock ~21~26~14 minecraft:warped_trapdoor 2
fill ~21~29~14 ~22~29~14 minecraft:chest 3
fill ~21~31~14 ~22~31~14 minecraft:chest 3
fill ~21~33~14 ~22~33~14 minecraft:leaves 3
fill ~21~35~14 ~21~36~14 minecraft:concrete 14
setblock ~22~21~14 minecraft:bed 3
setblock ~22~25~14 minecraft:warped_trapdoor 0
setblock ~23~12~14 minecraft:spruce_stairs 0
setblock ~23~18~14 minecraft:warped_stairs 3
fill ~23~20~14 ~26~20~14 minecraft:stonebrick 0
fill ~23~21~14 ~23~33~14 minecraft:stonebrick 0
fill ~23~34~14 ~23~34~16 minecraft:stone 6
fill ~24~11~14 ~24~11~17 minecraft:wooden_slab 8
setblock ~24~15~14 minecraft:wall_banner 3
setblock ~24~18~14 minecraft:warped_stairs 0
setblock ~24~35~14 minecraft:cobblestone_wall 13
fill ~25~1~14 ~27~1~28 minecraft:stone 0
fill ~25~2~14 ~26~2~28 minecraft:stone 0
fill ~25~3~14 ~26~19~14 minecraft:stonebrick 0
setblock ~25~35~14 minecraft:cobblestone_wall 13
setblock ~26~34~14 minecraft:polished_andesite_stairs 6
fill ~26~35~14 ~27~35~14 minecraft:stone 6
setblock ~26~36~14 minecraft:stone_brick_stairs 1
setblock ~26~37~14 minecraft:polished_andesite_stairs 2
fill ~27~2~14 ~27~20~14 minecraft:stone 6
fill ~27~34~14 ~27~34~15 minecraft:polished_andesite_stairs 5
setblock ~27~36~14 minecraft:stonebrick 0
fill ~27~37~14 ~27~37~15 minecraft:polished_andesite_stairs 1
fill ~28~1~14 ~28~20~14 minecraft:netherite_block
setblock ~28~21~14 minecraft:stone_block_slab 5
fill ~29~1~14 ~29~20~14 minecraft:iron_bars
setblock ~29~21~14 minecraft:polished_andesite_stairs 5
setblock ~29~24~14 minecraft:stone_block_slab 8
setblock ~29~25~14 minecraft:cobblestone_wall 13
setblock ~29~26~14 minecraft:lantern 0
fill ~30~0~14 ~30~0~32 minecraft:stone 0
fill ~30~18~14 ~30~19~14 minecraft:cobblestone_wall 7
setblock ~30~20~14 minecraft:stonebrick 0
fill ~30~21~14 ~30~22~14 minecraft:stone 6
setblock ~30~23~14 minecraft:stonebrick 0
setblock ~30~24~14 minecraft:polished_andesite_stairs 1
setblock ~31~22~14 minecraft:cobblestone_wall 13
setblock ~32~22~14 minecraft:cobblestone_wall 13
setblock ~9~22~15 minecraft:cobblestone_wall 13
setblock ~10~17~15 minecraft:soul_lantern 1
fill ~10~18~15 ~10~19~15 minecraft:cobblestone_wall 7
setblock ~10~20~15 minecraft:stonebrick 0
fill ~10~21~15 ~10~22~15 minecraft:stone 6
setblock ~10~23~15 minecraft:stonebrick 0
setblock ~10~24~15 minecraft:polished_andesite_stairs 0
setblock ~11~21~15 minecraft:polished_andesite_stairs 4
setblock ~11~24~15 minecraft:stone_block_slab 8
setblock ~11~25~15 minecraft:cobblestone_wall 13
fill ~12~1~15 ~12~1~28 minecraft:stone 0
fill ~12~2~15 ~12~20~15 minecraft:netherite_block
setblock ~12~21~15 minecraft:stone_block_slab 5
fill ~13~2~15 ~13~2~20 minecraft:stone 0
fill ~13~3~15 ~14~3~43 minecraft:stonebrick 0
fill ~13~4~15 ~13~20~15 minecraft:stonebrick 0
setblock ~13~35~15 minecraft:cobblestone_wall 13
setblock ~14~4~15 minecraft:chest 5
setblock ~14~5~15 minecraft:wooden_slab 8
setblock ~14~6~15 minecraft:chest 5
setblock ~14~7~15 minecraft:wooden_slab 8
setblock ~14~8~15 minecraft:chest 5
setblock ~14~9~15 minecraft:wooden_slab 8
setblock ~14~10~15 minecraft:chest 3
setblock ~14~11~15 minecraft:wooden_slab 8
fill ~14~12~15 ~14~16~15 minecraft:barrel 5
setblock ~14~18~15 minecraft:warped_stairs 1
fill ~14~20~15 ~15~20~15 minecraft:stonebrick 0
setblock ~14~35~15 minecraft:cobblestone_wall 13
setblock ~15~18~15 minecraft:warped_stairs 3
fill ~15~21~15 ~15~34~15 minecraft:stone 6
fill ~16~3~15 ~16~3~33 minecraft:stonebrick 0
setblock ~16~20~15 minecraft:double_wooden_slab 1
setblock ~16~24~15 minecraft:double_wooden_slab 1
fill ~16~25~15 ~17~25~17 minecraft:carpet 14
setblock ~16~27~15 minecraft:lantern 1
fill ~16~28~15 ~22~28~15 minecraft:planks 1
fill ~16~29~15 ~16~29~16 minecraft:wooden_slab 9
setblock ~16~30~15 minecraft:chest 5
setblock ~16~31~15 minecraft:wooden_slab 9
setblock ~16~32~15 minecraft:chest 5
setblock ~16~35~15 minecraft:snow_layer 0
setblock ~17~21~15 minecraft:flower_pot 0
fill ~17~24~15 ~22~24~15 minecraft:planks 1
setblock ~17~33~15 minecraft:leaves 3
fill ~17~35~15 ~17~36~15 minecraft:concrete 14
setblock ~18~34~15 minecraft:polished_andesite_stairs 5
fill ~18~35~15 ~21~35~29 minecraft:stonebrick 0
setblock ~19~25~15 minecraft:crimson_stairs 7
setblock ~19~26~15 minecraft:skull 1
setblock ~19~27~15 minecraft:fence 5
fill ~19~34~15 ~21~34~15 minecraft:polished_andesite_stairs 7
setblock ~20~36~15 minecraft:snow_layer 0
setblock ~22~25~15 minecraft:enchanting_table
setblock ~22~27~15 minecraft:fence 5
fill ~22~29~15 ~22~31~21 minecraft:fence 1
setblock ~22~33~15 minecraft:leaves 3
setblock ~22~34~15 minecraft:stone 6
setblock ~22~35~15 minecraft:concrete 14
setblock ~22~36~15 minecraft:concrete 0
setblock ~22~37~15 minecraft:crimson_fence
setblock ~22~38~15 minecraft:lantern 0
fill ~23~3~15 ~23~3~16 minecraft:stonebrick 0
fill ~23~20~15 ~23~33~15 minecraft:stone 6
setblock ~24~3~15 minecraft:gold_block
setblock ~24~4~15 minecraft:noteblock
setblock ~24~6~15 minecraft:noteblock
fill ~24~18~15 ~27~18~15 minecraft:warped_stairs 3
fill ~24~20~15 ~28~20~15 minecraft:stonebrick 0
setblock ~24~21~15 minecraft:stone_brick_stairs 2
fill ~24~22~15 ~24~23~15 minecraft:iron_bars
setblock ~24~24~15 minecraft:stone_brick_stairs 6
setblock ~24~25~15 minecraft:stone_brick_stairs 2
fill ~24~26~15 ~24~27~15 minecraft:iron_bars
setblock ~24~28~15 minecraft:stone_brick_stairs 6
setblock ~24~29~15 minecraft:stone_brick_stairs 2
fill ~24~30~15 ~24~31~15 minecraft:iron_bars
setblock ~24~32~15 minecraft:stone_brick_stairs 6
fill ~24~33~15 ~25~33~15 minecraft:stonebrick 0
fill ~24~34~15 ~26~34~16 minecraft:stone 6
fill ~25~3~15 ~25~3~16 minecraft:stonebrick 0
fill ~25~11~15 ~26~11~17 minecraft:wooden_slab 8
setblock ~25~14~15 minecraft:wall_banner 3
setblock ~25~21~15 minecraft:stonebrick 0
fill ~25~22~15 ~25~23~15 minecraft:stonebrick 3
fill ~25~24~15 ~25~25~15 minecraft:stonebrick 0
fill ~25~26~15 ~25~27~15 minecraft:stonebrick 3
fill ~25~28~15 ~25~29~15 minecraft:stonebrick 0
fill ~25~30~15 ~25~31~15 minecraft:stonebrick 3
setblock ~25~32~15 minecraft:stonebrick 0
setblock ~26~3~15 minecraft:gold_block
setblock ~26~4~15 minecraft:noteblock
setblock ~26~6~15 minecraft:noteblock
fill ~26~21~15 ~26~33~15 minecraft:stone 6
setblock ~26~37~15 minecraft:stone_block_slab 8
fill ~27~2~15 ~28~2~28 minecraft:stone 0
fill ~27~11~15 ~27~11~18 minecraft:log 0
setblock ~27~15~15 minecraft:wall_banner 4
setblock ~27~17~15 minecraft:lantern 1
setblock ~27~35~15 minecraft:stone 6
setblock ~27~36~15 minecraft:stone_brick_stairs 2
fill ~28~1~15 ~28~1~30 minecraft:stone 0
fill ~28~3~15 ~28~3~29 minecraft:stonebrick 0
fill ~28~4~15 ~28~19~15 minecraft:stonebrick 0
setblock ~28~35~15 minecraft:cobblestone_wall 13
fill ~29~1~15 ~29~20~15 minecraft:netherite_block
setblock ~29~21~15 minecraft:stone_block_slab 5
fill ~30~1~15 ~30~20~15 minecraft:iron_bars
setblock ~30~21~15 minecraft:polished_andesite_stairs 5
fill ~31~0~15 ~31~0~29 minecraft:stone 0
setblock ~31~21~15 minecraft:polished_andesite_stairs 6
setblock ~32~22~15 minecraft:cobblestone_wall 13
fill ~9~22~16 ~9~22~17 minecraft:cobblestone_wall 13
fill ~10~0~16 ~11~0~47 minecraft:stone 0
fill ~10~21~16 ~10~21~18 minecraft:polished_andesite_stairs 4
fill ~11~1~16 ~11~1~29 minecraft:stone 0
fill ~11~2~16 ~11~3~16 minecraft:netherite_block
fill ~11~4~16 ~11~5~16 minecraft:cobblestone_wall 3
fill ~11~6~16 ~11~7~16 minecraft:netherite_block
fill ~11~8~16 ~11~9~16 minecraft:cobblestone_wall 3
fill ~11~10~16 ~11~11~16 minecraft:netherite_block
fill ~11~12~16 ~11~13~16 minecraft:cobblestone_wall 3
fill ~11~14~16 ~11~15~16 minecraft:netherite_block
fill ~11~16~16 ~11~17~16 minecraft:cobblestone_wall 3
fill ~11~18~16 ~11~19~16 minecraft:netherite_block
setblock ~11~20~16 minecraft:cobblestone_wall 3
fill ~11~21~16 ~11~21~18 minecraft:stone_block_slab 5
fill ~12~2~16 ~12~2~28 minecraft:stone 0
fill ~12~3~16 ~12~20~16 minecraft:stone 6
fill ~12~34~16 ~13~34~16 minecraft:polished_andesite_stairs 6
fill ~12~35~16 ~13~35~16 minecraft:stone 6
setblock ~12~36~16 minecraft:stonebrick 0
fill ~12~37~16 ~13~37~16 minecraft:polished_andesite_stairs 2
fill ~13~4~16 ~13~5~16 minecraft:fence 0
setblock ~13~6~16 minecraft:double_wooden_slab 0
setblock ~13~7~16 minecraft:fence 0
setblock ~13~8~16 minecraft:double_wooden_slab 0
setblock ~13~9~16 minecraft:fence 0
setblock ~13~10~16 minecraft:double_wooden_slab 0
fill ~13~11~16 ~14~11~16 minecraft:log 0
fill ~13~12~16 ~13~14~16 minecraft:barrel 5
fill ~13~18~16 ~13~18~18 minecraft:warped_stairs 1
fill ~13~20~16 ~14~20~16 minecraft:stonebrick 0
setblock ~13~28~16 minecraft:polished_andesite_stairs 6
setblock ~13~29~16 minecraft:polished_andesite_stairs 2
setblock ~13~36~16 minecraft:stone_brick_stairs 0
setblock ~14~18~16 minecraft:warped_stairs 3
fill ~14~21~16 ~14~33~16 minecraft:stonebrick 0
fill ~14~34~16 ~16~34~16 minecraft:stone 6
fill ~15~20~16 ~16~20~17 minecraft:wooden_slab 8
setblock ~15~21~16 minecraft:bed 2
fill ~15~24~16 ~15~24~17 minecraft:wooden_slab 8
setblock ~15~25~16 minecraft:chest 3
setblock ~15~26~16 minecraft:warped_trapdoor 2
setblock ~15~27~16 minecraft:chest 3
fill ~15~28~16 ~26~28~17 minecraft:wooden_slab 8
setblock ~15~29~16 minecraft:wooden_slab 9
setblock ~15~30~16 minecraft:chest 3
setblock ~15~31~16 minecraft:wooden_slab 9
setblock ~15~32~16 minecraft:chest 3
setblock ~16~4~16 minecraft:dark_oak_trapdoor 1
setblock ~16~10~16 minecraft:lantern 1
fill ~16~24~16 ~23~24~16 minecraft:double_wooden_slab 0
setblock ~16~27~16 minecraft:warped_trapdoor 0
setblock ~16~30~16 minecraft:chain 0
setblock ~16~31~16 minecraft:double_wooden_slab 1
fill ~16~32~16 ~16~33~16 minecraft:chain 0
fill ~16~35~16 ~16~36~16 minecraft:concrete 14
setblock ~17~4~16 minecraft:planks 0
setblock ~17~5~16 minecraft:oak_stairs 2
fill ~17~6~16 ~17~9~16 minecraft:trapdoor 3
setblock ~17~21~16 minecraft:stonebrick 0
fill ~17~22~16 ~22~22~16 minecraft:iron_bars
fill ~17~23~16 ~23~23~16 minecraft:stonebrick 0
setblock ~17~34~16 minecraft:polished_andesite_stairs 5
fill ~17~35~16 ~17~35~29 minecraft:stonebrick 0
setblock ~18~4~16 minecraft:dark_oak_trapdoor 0
fill ~18~21~16 ~20~21~16 minecraft:iron_bars
setblock ~18~25~16 minecraft:warped_trapdoor 1
setblock ~18~29~16 minecraft:birch_stairs 3
setblock ~18~34~16 minecraft:polished_andesite_stairs 7
fill ~19~25~16 ~22~25~16 minecraft:wooden_slab 13
setblock ~19~26~16 minecraft:fence 5
setblock ~19~27~16 minecraft:bookshelf
setblock ~19~32~16 minecraft:lantern 1
fill ~19~33~16 ~19~34~16 minecraft:chain 0
fill ~21~21~16 ~23~21~16 minecraft:stonebrick 0
setblock ~21~34~16 minecraft:polished_andesite_stairs 4
setblock ~22~26~16 minecraft:fence 5
setblock ~22~27~16 minecraft:bookshelf
fill ~22~32~16 ~22~32~21 minecraft:fence 1
setblock ~22~34~16 minecraft:polished_andesite_stairs 7
fill ~22~35~16 ~22~35~47 minecraft:stonebrick 0
setblock ~23~4~16 minecraft:redstone_lamp
fill ~23~5~16 ~27~5~16 minecraft:brick_block
setblock ~23~6~16 minecraft:redstone_lamp
fill ~23~7~16 ~27~7~16 minecraft:brick_block
fill ~23~20~16 ~26~20~17 minecraft:wooden_slab 8
fill ~23~22~16 ~23~22~17 minecraft:stonebrick 0
setblock ~23~25~16 minecraft:crimson_stairs 4
setblock ~23~26~16 minecraft:end_rod 1
fill ~23~35~16 ~25~35~16 minecraft:concrete 14
setblock ~23~36~16 minecraft:concrete 14
setblock ~24~3~16 minecraft:stonebrick 0
setblock ~24~4~16 minecraft:target
setblock ~24~6~16 minecraft:target
setblock ~24~21~16 minecraft:bed 2
fill ~24~24~16 ~26~24~17 minecraft:wooden_slab 8
setblock ~24~36~16 minecraft:concrete 0
setblock ~24~37~16 minecraft:crimson_fence
setblock ~24~38~16 minecraft:lantern 0
setblock ~25~4~16 minecraft:brick_block
setblock ~25~6~16 minecraft:brick_block
setblock ~25~27~16 minecraft:wall_banner 3
setblock ~25~33~16 minecraft:lantern 1
setblock ~25~36~16 minecraft:concrete 14
fill ~26~3~16 ~27~3~16 minecraft:stonebrick 0
setblock ~26~4~16 minecraft:target
setblock ~26~6~16 minecraft:target
setblock ~26~21~16 minecraft:bed 2
fill ~26~25~16 ~26~27~16 minecraft:bookshelf
fill ~26~29~16 ~26~32~16 minecraft:vine 8
setblock ~27~4~16 minecraft:redstone_lamp
setblock ~27~6~16 minecraft:redstone_lamp
setblock ~27~18~16 minecraft:warped_stairs 0
fill ~27~20~16 ~29~20~16 minecraft:stonebrick 0
fill ~27~21~16 ~27~33~16 minecraft:stonebrick 0
fill ~27~34~16 ~27~34~18 minecraft:stone 6
fill ~28~11~16 ~28~11~19 minecraft:wooden_slab 8
setblock ~28~14~16 minecraft:wall_banner 4
setblock ~28~18~16 minecraft:warped_stairs 3
setblock ~28~35~16 minecraft:cobblestone_wall 13
fill ~29~1~16 ~29~2~27 minecraft:stone 0
fill ~29~3~16 ~29~3~29 minecraft:stonebrick 0
fill ~29~4~16 ~29~19~16 minecraft:stonebrick 0
setblock ~29~35~16 minecraft:cobblestone_wall 13
fill ~30~1~16 ~30~20~16 minecraft:netherite_block
setblock ~30~21~16 minecraft:stone_block_slab 5
setblock ~31~21~16 minecraft:polished_andesite_stairs 5
setblock ~31~24~16 minecraft:stone_block_slab 8
setblock ~31~25~16 minecraft:cobblestone_wall 13
fill ~32~0~16 ~32~0~35 minecraft:stone 0
setblock ~32~17~16 minecraft:soul_lantern 1
fill ~32~18~16 ~32~19~16 minecraft:cobblestone_wall 7
setblock ~32~20~16 minecraft:stonebrick 0
fill ~32~21~16 ~32~22~16 minecraft:stone 6
setblock ~32~23~16 minecraft:stonebrick 0
setblock ~32~24~16 minecraft:polished_andesite_stairs 1
setblock ~33~22~16 minecraft:cobblestone_wall 13
fill ~9~0~17 ~9~0~43 minecraft:stone 0
fill ~11~2~17 ~11~2~18 minecraft:stone 6
fill ~11~3~17 ~11~20~18 minecraft:cobblestone_wall 13
fill ~12~3~17 ~12~3~47 minecraft:stonebrick 0
fill ~12~4~17 ~12~20~18 minecraft:stonebrick 0
setblock ~12~28~17 minecraft:polished_andesite_stairs 4
setblock ~12~29~17 minecraft:polished_andesite_stairs 0
setblock ~12~34~17 minecraft:polished_andesite_stairs 4
setblock ~12~35~17 minecraft:stone 6
setblock ~12~36~17 minecraft:stone_brick_stairs 2
setblock ~12~37~17 minecraft:polished_andesite_stairs 0
fill ~13~4~17 ~13~4~18 minecraft:chest 5
fill ~13~5~17 ~13~5~18 minecraft:wooden_slab 8
fill ~13~6~17 ~13~6~18 minecraft:chest 5
fill ~13~7~17 ~13~7~18 minecraft:wooden_slab 8
fill ~13~8~17 ~13~8~18 minecraft:chest 5
fill ~13~9~17 ~13~9~18 minecraft:wooden_slab 8
fill ~13~10~17 ~13~10~18 minecraft:chest 5
fill ~13~11~17 ~14~11~18 minecraft:wooden_slab 8
fill ~13~20~17 ~13~20~20 minecraft:stonebrick 0
fill ~13~21~17 ~13~34~17 minecraft:stone 6
setblock ~13~37~17 minecraft:stone_block_slab 8
setblock ~14~20~17 minecraft:wooden_slab 8
setblock ~14~21~17 minecraft:bed 2
setblock ~14~24~17 minecraft:wooden_slab 8
fill ~14~25~17 ~15~25~17 minecraft:crimson_wall_sign 2
setblock ~14~26~17 minecraft:wall_banner 5
setblock ~14~28~17 minecraft:wooden_slab 8
setblock ~14~29~17 minecraft:cartography_table
fill ~14~34~17 ~15~34~17 minecraft:stone 6
setblock ~15~35~17 minecraft:concrete 14
setblock ~15~36~17 minecraft:concrete 0
setblock ~15~37~17 minecraft:crimson_fence
setblock ~15~38~17 minecraft:lantern 0
setblock ~16~24~17 minecraft:double_wooden_slab 0
setblock ~16~34~17 minecraft:polished_andesite_stairs 5
fill ~16~35~17 ~16~35~46 minecraft:stonebrick 0
setblock ~17~4~17 minecraft:ladder 3
fill ~17~12~17 ~27~12~17 minecraft:fence 1
setblock ~17~21~17 minecraft:chest 5
setblock ~17~22~17 minecraft:wooden_slab 1
fill ~17~23~17 ~22~23~17 minecraft:wooden_slab 9
fill ~17~24~17 ~22~24~17 minecraft:wooden_slab 8
setblock ~17~34~17 minecraft:polished_andesite_stairs 7
fill ~18~4~17 ~19~4~17 minecraft:trapdoor 3
fill ~18~21~17 ~21~21~18 minecraft:carpet 15
fill ~18~25~17 ~18~25~20 minecraft:carpet 14
fill ~18~34~17 ~21~34~17 minecraft:wooden_slab 9
setblock ~19~25~17 minecraft:warped_trapdoor 2
fill ~19~36~17 ~20~36~17 minecraft:snow_layer 0
fill ~20~25~17 ~26~25~17 minecraft:carpet 14
setblock ~22~21~17 minecraft:chest 4
setblock ~22~22~17 minecraft:wooden_slab 1
fill ~22~33~17 ~22~33~21 minecraft:fence 1
setblock ~22~34~17 minecraft:polished_andesite_stairs 4
setblock ~22~36~17 minecraft:snow_layer 0
fill ~23~3~17 ~27~3~24 minecraft:hay_block 0
fill ~23~4~17 ~23~4~25 minecraft:fence 0
setblock ~23~10~17 minecraft:lantern 1
setblock ~23~21~17 minecraft:stonebrick 0
fill ~23~23~17 ~23~23~20 minecraft:stonebrick 0
setblock ~23~24~17 minecraft:double_wooden_slab 0
fill ~23~34~17 ~25~34~17 minecraft:polished_andesite_stairs 7
fill ~23~35~17 ~25~35~47 minecraft:stonebrick 0
setblock ~24~23~17 minecraft:torch 1
fill ~24~30~17 ~24~30~20 minecraft:dispenser 2
setblock ~26~34~17 minecraft:stone 6
fill ~26~35~17 ~26~36~17 minecraft:concrete 14
fill ~27~4~17 ~27~4~25 minecraft:fence 0
setblock ~27~20~17 minecraft:wooden_slab 8
setblock ~27~24~17 minecraft:wooden_slab 8
fill ~27~25~17 ~27~26~17 minecraft:bookshelf
setblock ~27~28~17 minecraft:wooden_slab 8
fill ~27~29~17 ~27~32~17 minecraft:vine 12
setblock ~28~18~17 minecraft:warped_stairs 0
fill ~28~20~17 ~29~20~17 minecraft:stonebrick 0
fill ~28~21~17 ~28~33~17 minecraft:stonebrick 0
fill ~28~34~17 ~28~34~20 minecraft:stone 6
fill ~29~4~17 ~29~4~18 minecraft:crafting_table
fill ~29~5~17 ~29~6~18 minecraft:bookshelf
fill ~29~7~17 ~29~7~18 minecraft:crafting_table
fill ~29~11~17 ~29~11~18 minecraft:log 0
setblock ~29~15~17 minecraft:wall_banner 4
setblock ~29~17~17 minecraft:warped_stairs 6
setblock ~29~18~17 minecraft:warped_stairs 3
setblock ~29~28~17 minecraft:polished_andesite_stairs 6
setblock ~29~29~17 minecraft:polished_andesite_stairs 2
setblock ~29~34~17 minecraft:polished_andesite_stairs 6
fill ~29~35~17 ~30~35~17 minecraft:stone 6
setblock ~29~36~17 minecraft:stone_brick_stairs 1
setblock ~29~37~17 minecraft:polished_andesite_stairs 2
fill ~30~1~17 ~30~2~27 minecraft:stone 0
fill ~30~3~17 ~30~20~17 minecraft:stone 6
fill ~30~34~17 ~30~34~18 minecraft:polished_andesite_stairs 5
setblock ~30~36~17 minecraft:stonebrick 0
fill ~30~37~17 ~30~37~18 minecraft:polished_andesite_stairs 1
fill ~31~1~17 ~31~1~18 minecraft:netherite_block
setblock ~31~2~17 minecraft:netherite_block
fill ~31~3~17 ~31~4~17 minecraft:cobblestone_wall 3
fill ~31~5~17 ~31~6~17 minecraft:netherite_block
fill ~31~7~17 ~31~8~17 minecraft:cobblestone_wall 3
fill ~31~9~17 ~31~10~17 minecraft:netherite_block
fill ~31~11~17 ~31~12~17 minecraft:cobblestone_wall 3
fill ~31~13~17 ~31~14~17 minecraft:netherite_block
fill ~31~15~17 ~31~16~17 minecraft:cobblestone_wall 3
fill ~31~17~17 ~31~18~17 minecraft:netherite_block
fill ~31~19~17 ~31~20~17 minecraft:cobblestone_wall 3
fill ~31~21~17 ~31~21~18 minecraft:stone_block_slab 5
fill ~32~21~17 ~32~21~18 minecraft:polished_andesite_stairs 5
setblock ~33~22~17 minecraft:cobblestone_wall 13
setblock ~34~22~17 minecraft:cobblestone_wall 13
setblock ~8~22~18 minecraft:cobblestone_wall 13
fill ~9~18~18 ~9~19~18 minecraft:cobblestone_wall 7
setblock ~9~20~18 minecraft:stonebrick 0
fill ~9~21~18 ~9~22~18 minecraft:stone 6
setblock ~9~23~18 minecraft:stonebrick 0
setblock ~9~24~18 minecraft:polished_andesite_stairs 0
fill ~10~1~18 ~10~1~20 minecraft:stone 0
setblock ~10~24~18 minecraft:stone_block_slab 8
setblock ~10~25~18 minecraft:cobblestone_wall 13
setblock ~10~26~18 minecraft:lantern 0
setblock ~12~35~18 minecraft:cobblestone_wall 13
setblock ~13~15~18 minecraft:wall_banner 5
setblock ~13~16~18 minecraft:spruce_stairs 5
setblock ~13~17~18 minecraft:spruce_stairs 0
setblock ~13~21~18 minecraft:stonebrick 0
fill ~13~22~18 ~13~23~18 minecraft:stonebrick 3
fill ~13~24~18 ~13~25~18 minecraft:stonebrick 0
fill ~13~26~18 ~13~27~18 minecraft:stonebrick 3
fill ~13~28~18 ~13~29~18 minecraft:stonebrick 0
fill ~13~30~18 ~13~31~18 minecraft:stonebrick 3
fill ~13~32~18 ~13~33~18 minecraft:stonebrick 0
fill ~13~34~18 ~14~34~20 minecraft:stone 6
setblock ~13~35~18 minecraft:snow_layer 0
fill ~14~12~18 ~17~12~18 minecraft:fence 1
setblock ~14~17~18 minecraft:spruce_stairs 5
setblock ~14~18~18 minecraft:spruce_stairs 0
setblock ~14~20~18 minecraft:double_wooden_slab 1
setblock ~14~24~18 minecraft:double_wooden_slab 1
fill ~14~25~18 ~14~25~19 minecraft:bed 1
setblock ~14~27~18 minecraft:wall_banner 5
fill ~14~28~18 ~28~28~18 minecraft:planks 1
fill ~14~35~18 ~14~35~20 minecraft:concrete 14
setblock ~14~36~18 minecraft:concrete 14
setblock ~15~18~18 minecraft:spruce_stairs 5
setblock ~15~19~18 minecraft:spruce_stairs 0
fill ~15~20~18 ~28~20~18 minecraft:planks 1
fill ~15~24~18 ~28~24~18 minecraft:planks 1
fill ~15~34~18 ~15~34~20 minecraft:polished_andesite_stairs 5
fill ~15~35~18 ~15~35~45 minecraft:stonebrick 0
setblock ~16~19~18 minecraft:spruce_stairs 5
fill ~16~21~18 ~16~22~19 minecraft:iron_bars
fill ~16~23~18 ~16~23~20 minecraft:stonebrick 0
fill ~16~25~18 ~16~25~19 minecraft:crimson_slab 0
setblock ~16~31~18 minecraft:bookshelf
setblock ~16~34~18 minecraft:polished_andesite_stairs 7
setblock ~17~11~18 minecraft:wooden_slab 8
fill ~17~21~18 ~17~21~19 minecraft:carpet 15
fill ~17~23~18 ~17~23~21 minecraft:wooden_slab 9
fill ~17~25~18 ~17~25~20 minecraft:carpet 14
setblock ~17~29~18 minecraft:lectern 2
fill ~18~4~18 ~19~4~18 minecraft:spruce_stairs 3
fill ~18~5~18 ~19~5~18 minecraft:trapdoor 2
setblock ~18~31~18 minecraft:bookshelf
setblock ~18~36~18 minecraft:polished_blackstone_stairs 6
setblock ~18~37~18 minecraft:polished_blackstone_stairs 2
setblock ~19~23~18 minecraft:lantern 1
fill ~19~25~18 ~23~25~20 minecraft:carpet 14
setblock ~19~37~18 minecraft:dark_oak_stairs 6
setblock ~19~38~18 minecraft:dark_oak_stairs 2
setblock ~19~41~18 minecraft:wall_banner 2
fill ~20~36~18 ~21~36~18 minecraft:snow_layer 0
fill ~22~21~18 ~22~21~19 minecraft:carpet 15
fill ~22~23~18 ~22~23~21 minecraft:wooden_slab 9
fill ~22~34~18 ~22~34~19 minecraft:fence 1
fill ~23~11~18 ~23~12~18 minecraft:dark_oak_trapdoor 2
fill ~23~21~18 ~23~22~19 minecraft:iron_bars
setblock ~23~29~18 minecraft:dark_oak_trapdoor 1
setblock ~23~37~18 minecraft:dark_oak_stairs 6
setblock ~23~38~18 minecraft:dark_oak_stairs 2
setblock ~23~41~18 minecraft:wall_banner 2
fill ~24~25~18 ~25~25~19 minecraft:fence 5
fill ~24~26~18 ~25~26~19 minecraft:warped_pressure_plate 0
setblock ~24~27~18 minecraft:lantern 1
setblock ~24~29~18 minecraft:fence 1
setblock ~24~36~18 minecraft:polished_blackstone_stairs 6
setblock ~24~37~18 minecraft:polished_blackstone_stairs 2
setblock ~25~29~18 minecraft:dark_oak_trapdoor 1
setblock ~25~34~18 minecraft:polished_andesite_stairs 4
fill ~26~25~18 ~26~25~20 minecraft:carpet 14
setblock ~26~34~18 minecraft:polished_andesite_stairs 7
fill ~26~35~18 ~26~35~47 minecraft:stonebrick 0
setblock ~27~10~18 minecraft:lantern 1
fill ~27~12~18 ~28~12~18 minecraft:fence 1
setblock ~27~25~18 minecraft:enchanting_table
setblock ~27~35~18 minecraft:concrete 14
setblock ~27~36~18 minecraft:concrete 0
setblock ~27~37~18 minecraft:crimson_fence
setblock ~27~38~18 minecraft:lantern 0
setblock ~28~19~18 minecraft:spruce_stairs 4
fill ~28~25~18 ~28~25~19 minecraft:bookshelf
setblock ~28~26~18 minecraft:bookshelf
fill ~28~29~18 ~28~29~19 minecraft:iron_trapdoor 1
fill ~28~30~18 ~28~30~19 minecraft:skull 1
fill ~28~31~18 ~28~31~19 minecraft:iron_trapdoor 1
fill ~28~32~18 ~28~32~19 minecraft:skull 1
setblock ~29~17~18 minecraft:warped_stairs 0
setblock ~29~18~18 minecraft:spruce_stairs 4
setblock ~29~19~18 minecraft:spruce_stairs 1
fill ~29~20~18 ~30~20~19 minecraft:stonebrick 0
fill ~29~21~18 ~29~34~18 minecraft:stone 6
setblock ~29~37~18 minecraft:stone_block_slab 8
fill ~30~3~18 ~30~3~29 minecraft:stonebrick 0
fill ~30~4~18 ~30~19~18 minecraft:stonebrick 0
fill ~30~21~18 ~30~27~18 minecraft:vine 2
setblock ~30~28~18 minecraft:polished_andesite_stairs 5
setblock ~30~29~18 minecraft:polished_andesite_stairs 1
setblock ~30~30~18 minecraft:vine 2
setblock ~30~35~18 minecraft:stone 6
setblock ~30~36~18 minecraft:stone_brick_stairs 2
setblock ~31~2~18 minecraft:stone 6
fill ~31~3~18 ~31~20~18 minecraft:cobblestone_wall 13
fill ~33~0~18 ~33~0~49 minecraft:stone 0
setblock ~33~21~18 minecraft:polished_andesite_stairs 6
setblock ~34~22~18 minecraft:cobblestone_wall 13
setblock ~8~22~19 minecraft:cobblestone_wall 13
fill ~9~21~19 ~9~21~20 minecraft:polished_andesite_stairs 4
fill ~10~2~19 ~10~3~19 minecraft:netherite_block
fill ~10~4~19 ~10~5~19 minecraft:cobblestone_wall 3
fill ~10~6~19 ~10~7~19 minecraft:netherite_block
fill ~10~8~19 ~10~9~19 minecraft:cobblestone_wall 3
fill ~10~10~19 ~10~11~19 minecraft:netherite_block
fill ~10~12~19 ~10~13~19 minecraft:cobblestone_wall 3
fill ~10~14~19 ~10~15~19 minecraft:netherite_block
fill ~10~16~19 ~10~17~19 minecraft:cobblestone_wall 3
fill ~10~18~19 ~10~19~19 minecraft:netherite_block
setblock ~10~20~19 minecraft:cobblestone_wall 3
fill ~10~21~19 ~10~21~20 minecraft:stone_block_slab 5
fill ~11~2~19 ~11~2~30 minecraft:stone 0
fill ~11~3~19 ~11~20~19 minecraft:stone 6
setblock ~11~35~19 minecraft:cobblestone_wall 13
fill ~12~11~19 ~14~11~19 minecraft:log 0
setblock ~12~14~19 minecraft:wall_banner 5
fill ~12~18~19 ~13~18~19 minecraft:warped_stairs 3
fill ~12~20~19 ~12~20~21 minecraft:stonebrick 0
setblock ~12~35~19 minecraft:cobblestone_wall 13
setblock ~13~4~19 minecraft:torch 5
setblock ~13~17~19 minecraft:lantern 1
setblock ~13~21~19 minecraft:stone_brick_stairs 0
fill ~13~22~19 ~13~23~19 minecraft:iron_bars
setblock ~13~24~19 minecraft:stone_brick_stairs 4
setblock ~13~25~19 minecraft:stone_brick_stairs 0
fill ~13~26~19 ~13~27~19 minecraft:iron_bars
setblock ~13~28~19 minecraft:stone_brick_stairs 4
setblock ~13~29~19 minecraft:stone_brick_stairs 0
fill ~13~30~19 ~13~31~19 minecraft:iron_bars
setblock ~13~32~19 minecraft:stone_brick_stairs 4
fill ~13~33~19 ~13~33~20 minecraft:stonebrick 0
fill ~14~12~19 ~14~12~20 minecraft:fence 1
fill ~14~20~19 ~28~20~20 minecraft:wooden_slab 8
fill ~14~24~19 ~15~24~19 minecraft:wooden_slab 8
fill ~14~28~19 ~28~28~20 minecraft:wooden_slab 8
setblock ~14~36~19 minecraft:concrete 0
fill ~15~1~19 ~16~2~22 minecraft:stone 5
setblock ~15~11~19 minecraft:dark_oak_trapdoor 1
setblock ~15~12~19 minecraft:dark_oak_trapdoor 0
fill ~15~29~19 ~15~30~19 minecraft:dark_oak_trapdoor 1
setblock ~15~31~19 minecraft:spruce_stairs 4
fill ~15~32~19 ~15~33~19 minecraft:chain 0
fill ~16~0~19 ~16~0~21 minecraft:stone 5
setblock ~16~4~19 minecraft:spruce_stairs 1
setblock ~16~5~19 minecraft:trapdoor 0
fill ~16~11~19 ~16~12~19 minecraft:dark_oak_trapdoor 2
fill ~16~24~19 ~16~24~20 minecraft:double_wooden_slab 0
fill ~16~29~19 ~18~31~19 minecraft:double_wooden_slab 0
setblock ~16~32~19 minecraft:wooden_slab 1
fill ~17~0~19 ~21~2~19 minecraft:stone 0
fill ~17~4~19 ~20~4~19 minecraft:wooden_slab 8
fill ~17~24~19 ~28~24~19 minecraft:wooden_slab 8
setblock ~17~32~19 minecraft:double_wooden_slab 1
fill ~18~21~19 ~19~21~20 minecraft:carpet 15
setblock ~18~32~19 minecraft:wooden_slab 1
setblock ~18~36~19 minecraft:polished_blackstone_stairs 7
setblock ~18~37~19 minecraft:polished_blackstone_stairs 3
setblock ~19~29~19 minecraft:dark_oak_trapdoor 1
setblock ~19~30~19 minecraft:dark_oak_trapdoor 0
setblock ~19~31~19 minecraft:spruce_stairs 5
fill ~19~32~19 ~19~34~19 minecraft:chain 0
fill ~19~37~19 ~19~37~21 minecraft:planks 5
setblock ~19~38~19 minecraft:log2 1
fill ~19~39~19 ~19~40~19 minecraft:fence 5
setblock ~19~41~19 minecraft:log2 1
setblock ~19~42~19 minecraft:spruce_stairs 2
setblock ~20~21~19 minecraft:crimson_trapdoor 3
setblock ~20~22~19 minecraft:crimson_trapdoor 3
fill ~20~37~19 ~22~37~19 minecraft:wooden_slab 13
setblock ~20~38~19 minecraft:dark_oak_stairs 1
fill ~20~41~19 ~22~41~19 minecraft:fence 0
setblock ~21~4~19 minecraft:spruce_stairs 0
setblock ~21~5~19 minecraft:trapdoor 1
fill ~21~21~19 ~21~21~20 minecraft:carpet 15
setblock ~21~38~19 minecraft:wooden_slab 5
fill ~22~0~19 ~22~2~21 minecraft:stone 1
setblock ~22~38~19 minecraft:dark_oak_stairs 0
fill ~23~1~19 ~23~2~19 minecraft:stone 0
setblock ~23~5~19 minecraft:lantern 0
fill ~23~37~19 ~23~37~21 minecraft:planks 5
setblock ~23~38~19 minecraft:log2 1
fill ~23~39~19 ~23~40~19 minecraft:fence 5
setblock ~23~41~19 minecraft:log2 1
setblock ~23~42~19 minecraft:spruce_stairs 2
setblock ~24~29~19 minecraft:wooden_slab 10
setblock ~24~36~19 minecraft:polished_blackstone_stairs 7
setblock ~24~37~19 minecraft:polished_blackstone_stairs 3
setblock ~26~29~19 minecraft:barrel 1
setblock ~26~34~19 minecraft:polished_andesite_stairs 4
fill ~27~11~19 ~27~12~19 minecraft:dark_oak_trapdoor 2
setblock ~27~34~19 minecraft:polished_andesite_stairs 7
fill ~27~35~19 ~27~35~46 minecraft:stonebrick 0
fill ~28~12~19 ~28~12~20 minecraft:fence 1
setblock ~28~27~19 minecraft:wall_banner 4
fill ~28~35~19 ~28~35~20 minecraft:concrete 14
setblock ~28~36~19 minecraft:concrete 14
fill ~29~11~19 ~30~11~19 minecraft:wooden_slab 8
fill ~29~17~19 ~30~17~19 minecraft:warped_stairs 3
fill ~29~21~19 ~29~33~19 minecraft:stonebrick 0
fill ~29~34~19 ~29~34~21 minecraft:stone 6
setblock ~30~4~19 minecraft:crafting_table
fill ~30~5~19 ~30~6~19 minecraft:bookshelf
setblock ~30~7~19 minecraft:crafting_table
setblock ~30~14~19 minecraft:wall_banner 3
setblock ~30~16~19 minecraft:lantern 1
fill ~30~21~19 ~30~30~19 minecraft:vine 3
setblock ~30~35~19 minecraft:cobblestone_wall 13
fill ~31~1~19 ~31~2~27 minecraft:stone 0
fill ~31~3~19 ~31~3~29 minecraft:stonebrick 0
fill ~31~4~19 ~31~20~19 minecraft:stonebrick 0
setblock ~31~35~19 minecraft:cobblestone_wall 13
fill ~32~1~19 ~32~20~19 minecraft:netherite_block
setblock ~32~21~19 minecraft:stone_block_slab 5
setblock ~33~21~19 minecraft:polished_andesite_stairs 5
setblock ~33~24~19 minecraft:stone_block_slab 8
setblock ~33~25~19 minecraft:cobblestone_wall 13
setblock ~33~26~19 minecraft:lantern 0
fill ~34~0~19 ~34~0~48 minecraft:stone 0
fill ~34~18~19 ~34~19~19 minecraft:cobblestone_wall 7
setblock ~34~20~19 minecraft:stonebrick 0
fill ~34~21~19 ~34~22~19 minecraft:stone 6
setblock ~34~23~19 minecraft:stonebrick 0
setblock ~34~24~19 minecraft:polished_andesite_stairs 1
setblock ~35~22~19 minecraft:cobblestone_wall 13
setblock ~7~22~20 minecraft:cobblestone_wall 13
fill ~8~0~20 ~8~0~44 minecraft:stone 0
setblock ~8~17~20 minecraft:soul_lantern 1
fill ~8~18~20 ~8~19~20 minecraft:cobblestone_wall 7
setblock ~8~20~20 minecraft:stonebrick 0
fill ~8~21~20 ~8~22~20 minecraft:stone 6
setblock ~8~23~20 minecraft:stonebrick 0
setblock ~8~24~20 minecraft:polished_andesite_stairs 0
fill ~9~1~20 ~9~1~45 minecraft:stone 0
setblock ~9~24~20 minecraft:stone_block_slab 8
setblock ~9~25~20 minecraft:cobblestone_wall 13
fill ~10~2~20 ~10~2~21 minecraft:stone 6
fill ~10~3~20 ~10~20~20 minecraft:cobblestone_wall 13
fill ~11~3~20 ~11~3~42 minecraft:stonebrick 0
fill ~11~4~20 ~13~5~20 minecraft:brick_block
fill ~11~6~20 ~11~20~20 minecraft:stonebrick 0
setblock ~11~35~20 minecraft:cobblestone_wall 13
fill ~12~6~20 ~13~6~20 minecraft:brick_stairs 2
fill ~12~11~20 ~14~11~20 minecraft:wooden_slab 8
setblock ~12~18~20 minecraft:warped_stairs 1
fill ~12~21~20 ~12~34~20 minecraft:stone 6
fill ~13~12~20 ~13~12~22 minecraft:fence 1
fill ~13~21~20 ~16~22~20 minecraft:stonebrick 0
fill ~13~23~20 ~15~23~20 minecraft:stonebrick 0
fill ~13~24~20 ~13~32~20 minecraft:stonebrick 0
fill ~14~2~20 ~14~2~23 minecraft:stone 5
fill ~14~4~20 ~14~4~23 minecraft:coal_block
fill ~14~5~20 ~14~5~22 minecraft:coal_block
fill ~14~24~20 ~15~24~20 minecraft:double_wooden_slab 0
fill ~14~25~20 ~15~25~20 minecraft:crimson_wall_sign 3
fill ~14~29~20 ~14~29~21 minecraft:wooden_slab 9
setblock ~14~36~20 minecraft:concrete 14
setblock ~14~37~20 minecraft:crimson_fence
setblock ~14~38~20 minecraft:lantern 0
fill ~15~0~20 ~15~0~21 minecraft:stone 5
setblock ~15~29~20 minecraft:cartography_table
setblock ~16~25~20 minecraft:carpet 14
fill ~16~34~20 ~26~34~20 minecraft:wooden_slab 9
fill ~17~0~20 ~21~2~20 minecraft:stone 1
fill ~17~4~20 ~17~4~23 minecraft:wooden_slab 8
setblock ~17~21~20 minecraft:polished_blackstone_brick_wall 0
setblock ~17~22~20 minecraft:polished_blackstone_brick_wall 0
fill ~17~24~20 ~22~24~20 minecraft:wooden_slab 8
fill ~18~4~20 ~19~4~22 minecraft:stripped_jungle_log 0
setblock ~19~5~20 minecraft:cake 0
setblock ~19~42~20 minecraft:planks 5
setblock ~19~43~20 minecraft:snow_layer 0
fill ~20~4~20 ~20~4~23 minecraft:wooden_slab 8
setblock ~20~21~20 minecraft:crimson_stairs 3
fill ~20~36~20 ~22~36~20 minecraft:snow_layer 0
setblock ~22~21~20 minecraft:polished_blackstone_brick_wall 0
setblock ~22~22~20 minecraft:polished_blackstone_brick_wall 0
fill ~23~0~20 ~23~2~20 minecraft:stone 1
fill ~23~21~20 ~25~21~20 minecraft:stonebrick 0
fill ~23~22~20 ~24~22~20 minecraft:stonebrick 0
fill ~23~24~20 ~25~24~20 minecraft:double_wooden_slab 0
setblock ~23~29~20 minecraft:dark_oak_trapdoor 1
setblock ~23~42~20 minecraft:planks 5
setblock ~23~43~20 minecraft:snow_layer 0
fill ~24~0~20 ~25~0~28 minecraft:stone 0
setblock ~24~23~20 minecraft:stonebrick 0
fill ~24~25~20 ~25~25~20 minecraft:carpet 14
setblock ~24~29~20 minecraft:fence 1
setblock ~24~36~20 minecraft:snow_layer 0
fill ~25~22~20 ~25~23~21 minecraft:iron_bars
setblock ~25~29~20 minecraft:dark_oak_trapdoor 1
fill ~26~24~20 ~29~24~20 minecraft:wooden_slab 8
setblock ~26~29~20 minecraft:torch 3
setblock ~27~11~20 minecraft:dark_oak_trapdoor 1
setblock ~27~12~20 minecraft:dark_oak_trapdoor 1
fill ~27~34~20 ~27~34~21 minecraft:polished_andesite_stairs 4
fill ~28~11~20 ~31~11~20 minecraft:log 0
setblock ~28~23~20 minecraft:torch 4
setblock ~28~29~20 minecraft:birch_stairs 2
setblock ~28~30~20 minecraft:tripwire_hook 2
setblock ~28~36~20 minecraft:concrete 0
setblock ~28~37~20 minecraft:crimson_fence
setblock ~28~38~20 minecraft:lantern 0
fill ~29~12~20 ~29~12~21 minecraft:fence 1
setblock ~29~20~20 minecraft:wooden_slab 8
setblock ~29~21~20 minecraft:bed 3
setblock ~29~27~20 minecraft:wall_banner 4
setblock ~29~28~20 minecraft:wooden_slab 8
fill ~29~29~20 ~29~32~20 minecraft:vine 4
setblock ~30~10~20 minecraft:lantern 1
setblock ~30~17~20 minecraft:warped_stairs 0
fill ~30~20~20 ~31~20~20 minecraft:stonebrick 0
fill ~30~21~20 ~30~23~21 minecraft:stonebrick 0
fill ~30~24~20 ~30~33~20 minecraft:stonebrick 0
fill ~30~34~20 ~30~34~23 minecraft:stone 6
fill ~31~4~20 ~31~4~21 minecraft:crafting_table
fill ~31~5~20 ~31~6~21 minecraft:bookshelf
fill ~31~7~20 ~31~7~21 minecraft:crafting_table
setblock ~31~15~20 minecraft:wall_banner 3
setblock ~31~17~20 minecraft:warped_stairs 3
fill ~31~21~20 ~31~29~20 minecraft:vine 3
setblock ~31~30~20 minecraft:vine 2
setblock ~31~34~20 minecraft:polished_andesite_stairs 6
fill ~31~35~20 ~32~35~20 minecraft:stone 6
setblock ~31~36~20 minecraft:stone_brick_stairs 1
setblock ~31~37~20 minecraft:polished_andesite_stairs 2
fill ~32~1~20 ~32~2~27 minecraft:stone 0
fill ~32~3~20 ~32~20~20 minecraft:stone 6
fill ~32~34~20 ~32~34~21 minecraft:polished_andesite_stairs 5
setblock ~32~36~20 minecraft:stonebrick 0
fill ~32~37~20 ~32~37~21 minecraft:polished_andesite_stairs 1
fill ~33~1~20 ~33~1~21 minecraft:netherite_block
setblock ~33~2~20 minecraft:netherite_block
fill ~33~3~20 ~33~4~20 minecraft:cobblestone_wall 3
fill ~33~5~20 ~33~6~20 minecraft:netherite_block
fill ~33~7~20 ~33~8~20 minecraft:cobblestone_wall 3
fill ~33~9~20 ~33~10~20 minecraft:netherite_block
fill ~33~11~20 ~33~12~20 minecraft:cobblestone_wall 3
fill ~33~13~20 ~33~14~20 minecraft:netherite_block
fill ~33~15~20 ~33~16~20 minecraft:cobblestone_wall 3
fill ~33~17~20 ~33~18~20 minecraft:netherite_block
fill ~33~19~20 ~33~20~20 minecraft:cobblestone_wall 3
fill ~33~21~20 ~33~21~21 minecraft:stone_block_slab 5
fill ~34~21~20 ~34~21~21 minecraft:polished_andesite_stairs 5
setblock ~35~22~20 minecraft:cobblestone_wall 13
setblock ~36~22~20 minecraft:cobblestone_wall 13
fill ~7~22~21 ~7~22~23 minecraft:cobblestone_wall 13
fill ~8~21~21 ~8~21~23 minecraft:polished_andesite_stairs 4
fill ~9~2~21 ~9~3~22 minecraft:netherite_block
fill ~9~4~21 ~9~20~21 minecraft:netherite_block
fill ~9~21~21 ~9~21~27 minecraft:stone_block_slab 5
fill ~10~3~21 ~10~20~21 minecraft:stone 6
fill ~10~34~21 ~11~34~21 minecraft:polished_andesite_stairs 6
fill ~10~35~21 ~11~35~21 minecraft:stone 6
setblock ~10~36~21 minecraft:stonebrick 0
fill ~10~37~21 ~11~37~21 minecraft:polished_andesite_stairs 2
fill ~11~4~21 ~12~4~22 minecraft:netherrack
fill ~11~5~21 ~12~5~22 minecraft:fire 15
fill ~11~6~21 ~12~6~22 minecraft:stone_block_slab 12
fill ~11~11~21 ~13~11~21 minecraft:log 0
setblock ~11~15~21 minecraft:wall_banner 3
fill ~11~18~21 ~12~18~21 minecraft:warped_stairs 3
fill ~11~20~21 ~11~20~28 minecraft:stonebrick 0
setblock ~11~28~21 minecraft:polished_andesite_stairs 6
setblock ~11~29~21 minecraft:polished_andesite_stairs 2
setblock ~11~36~21 minecraft:stone_brick_stairs 0
fill ~12~21~21 ~12~33~21 minecraft:stonebrick 0
fill ~12~34~21 ~13~34~22 minecraft:stone 6
fill ~13~0~21 ~13~0~28 minecraft:stone 0
fill ~13~2~21 ~13~2~23 minecraft:stone 5
fill ~13~4~21 ~13~5~23 minecraft:brick_block
fill ~13~6~21 ~13~6~23 minecraft:brick_stairs 1
setblock ~13~10~21 minecraft:lantern 1
setblock ~13~20~21 minecraft:double_wooden_slab 1
fill ~13~21~21 ~14~21~21 minecraft:carpet 11
fill ~13~23~21 ~16~23~21 minecraft:wooden_slab 9
setblock ~13~24~21 minecraft:double_wooden_slab 1
fill ~13~25~21 ~13~27~22 minecraft:stone 6
setblock ~13~28~21 minecraft:double_wooden_slab 1
setblock ~13~29~21 minecraft:wooden_slab 9
fill ~13~30~21 ~13~31~21 minecraft:bookshelf
fill ~13~35~21 ~13~35~22 minecraft:concrete 14
setblock ~13~36~21 minecraft:concrete 0
fill ~14~0~21 ~14~1~21 minecraft:stone 5
setblock ~14~6~21 minecraft:coal_block
fill ~14~11~21 ~14~12~21 minecraft:dark_oak_trapdoor 1
fill ~14~20~21 ~30~20~21 minecraft:planks 1
setblock ~14~22~21 minecraft:skull 3
fill ~14~24~21 ~30~24~21 minecraft:planks 1
fill ~14~25~21 ~18~27~21 minecraft:stained_glass_pane 15
fill ~14~28~21 ~29~28~21 minecraft:planks 1
fill ~14~34~21 ~14~34~22 minecraft:polished_andesite_stairs 5
fill ~14~35~21 ~14~35~44 minecraft:stonebrick 0
setblock ~15~21~21 minecraft:oak_stairs 3
setblock ~15~34~21 minecraft:polished_andesite_stairs 7
setblock ~16~4~21 minecraft:spruce_stairs 1
setblock ~16~5~21 minecraft:trapdoor 0
setblock ~16~29~21 minecraft:birch_stairs 0
fill ~17~0~21 ~19~1~21 minecraft:stone 1
fill ~17~2~21 ~17~2~24 minecraft:stone 0
fill ~17~21~21 ~18~21~22 minecraft:carpet 15
fill ~18~2~21 ~21~2~21 minecraft:stone 1
fill ~18~39~21 ~18~40~21 minecraft:wall_banner 4
setblock ~18~42~21 minecraft:fence 0
fill ~19~21~21 ~19~21~22 minecraft:fence 5
fill ~19~22~21 ~19~22~22 minecraft:polished_blackstone_pressure_plate 0
fill ~19~25~21 ~20~25~21 minecraft:carpet 14
fill ~19~27~21 ~29~27~21 minecraft:stained_glass_pane 15
fill ~19~38~21 ~19~42~21 minecraft:log2 1
setblock ~19~43~21 minecraft:standing_banner 8
fill ~20~0~21 ~20~0~25 minecraft:stone 0
fill ~20~1~21 ~21~1~21 minecraft:stone 1
setblock ~20~21~21 minecraft:carpet 15
setblock ~20~23~21 minecraft:lantern 1
setblock ~20~40~21 minecraft:cobblestone_wall 8
fill ~20~42~21 ~22~42~21 minecraft:spruce_stairs 6
fill ~20~43~21 ~22~43~21 minecraft:snow_layer 0
setblock ~21~0~21 minecraft:stone 1
setblock ~21~4~21 minecraft:spruce_stairs 0
setblock ~21~5~21 minecraft:trapdoor 1
fill ~21~21~21 ~21~21~22 minecraft:fence 5
fill ~21~22~21 ~21~22~22 minecraft:polished_blackstone_pressure_plate 0
fill ~21~25~21 ~29~26~21 minecraft:stained_glass_pane 15
fill ~21~29~21 ~21~34~22 minecraft:fence 1
setblock ~21~40~21 minecraft:cobblestone_wall 8
fill ~22~21~21 ~22~21~22 minecraft:carpet 15
setblock ~22~34~21 minecraft:fence 1
setblock ~22~40~21 minecraft:cobblestone_wall 8
fill ~23~0~21 ~23~0~28 minecraft:stone 0
fill ~23~1~21 ~24~2~21 minecraft:stone 1
fill ~23~21~21 ~23~21~22 minecraft:dark_oak_trapdoor 1
fill ~23~23~21 ~24~23~21 minecraft:wooden_slab 9
fill ~23~38~21 ~23~42~21 minecraft:log2 1
setblock ~23~43~21 minecraft:standing_banner 8
fill ~24~21~21 ~24~21~22 minecraft:chest 4
fill ~24~22~21 ~24~22~22 minecraft:dark_oak_trapdoor 1
setblock ~24~29~21 minecraft:birch_stairs 3
setblock ~24~30~21 minecraft:tripwire_hook 0
setblock ~24~37~21 minecraft:lever 1
fill ~24~40~21 ~24~41~21 minecraft:wall_banner 5
setblock ~24~42~21 minecraft:fence 0
fill ~25~21~21 ~29~21~21 minecraft:stonebrick 0
fill ~25~36~21 ~25~36~28 minecraft:snow_layer 0
fill ~26~22~21 ~27~23~21 minecraft:iron_bars
setblock ~27~29~21 minecraft:dark_oak_trapdoor 1
fill ~28~22~21 ~29~23~21 minecraft:stonebrick 0
setblock ~28~29~21 minecraft:fence 1
setblock ~28~30~21 minecraft:dispenser 2
setblock ~28~34~21 minecraft:polished_andesite_stairs 7
fill ~28~35~21 ~28~35~46 minecraft:stonebrick 0
fill ~29~11~21 ~31~11~21 minecraft:wooden_slab 8
setblock ~29~29~21 minecraft:dark_oak_trapdoor 0
fill ~29~35~21 ~29~36~21 minecraft:concrete 14
fill ~30~12~21 ~30~12~23 minecraft:fence 1
setblock ~30~19~21 minecraft:spruce_stairs 4
fill ~30~25~21 ~31~27~21 minecraft:stone 6
fill ~30~28~21 ~30~28~22 minecraft:double_wooden_slab 0
setblock ~30~32~21 minecraft:lantern 1
setblock ~30~33~21 minecraft:chain 0
setblock ~31~14~21 minecraft:wall_banner 4
setblock ~31~17~21 minecraft:warped_stairs 0
setblock ~31~18~21 minecraft:spruce_stairs 4
setblock ~31~19~21 minecraft:spruce_stairs 1
fill ~31~20~21 ~32~20~22 minecraft:stonebrick 0
fill ~31~21~21 ~31~24~21 minecraft:stone 6
fill ~31~28~21 ~31~34~21 minecraft:stone 6
setblock ~31~37~21 minecraft:stone_block_slab 8
fill ~32~3~21 ~32~3~29 minecraft:stonebrick 0
fill ~32~4~21 ~32~19~21 minecraft:stonebrick 0
fill ~32~21~21 ~32~22~21 minecraft:vine 2
setblock ~32~35~21 minecraft:stone 6
setblock ~32~36~21 minecraft:stone_brick_stairs 2
setblock ~33~2~21 minecraft:stone 6
fill ~33~3~21 ~33~20~21 minecraft:cobblestone_wall 13
fill ~35~0~21 ~35~0~48 minecraft:stone 0
setblock ~35~21~21 minecraft:polished_andesite_stairs 6
setblock ~36~22~21 minecraft:cobblestone_wall 13
fill ~9~4~22 ~9~5~22 minecraft:cobblestone_wall 3
fill ~9~6~22 ~9~7~22 minecraft:netherite_block
fill ~9~8~22 ~9~9~22 minecraft:cobblestone_wall 3
fill ~9~10~22 ~9~12~22 minecraft:netherite_block
fill ~9~13~22 ~9~14~22 minecraft:cobblestone_wall 3
fill ~9~15~22 ~9~16~22 minecraft:netherite_block
fill ~9~17~22 ~9~18~22 minecraft:cobblestone_wall 3
fill ~9~19~22 ~9~20~22 minecraft:netherite_block
fill ~10~1~22 ~10~1~46 minecraft:stone 0
fill ~10~2~22 ~10~3~28 minecraft:stonebrick 0
fill ~10~4~22 ~10~20~27 minecraft:stonebrick 0
setblock ~10~28~22 minecraft:polished_andesite_stairs 4
setblock ~10~29~22 minecraft:polished_andesite_stairs 0
setblock ~10~34~22 minecraft:polished_andesite_stairs 4
setblock ~10~35~22 minecraft:stone 6
setblock ~10~36~22 minecraft:stone_brick_stairs 2
setblock ~10~37~22 minecraft:polished_andesite_stairs 0
setblock ~11~8~22 minecraft:cobblestone_wall 6
fill ~11~11~22 ~13~11~22 minecraft:wooden_slab 8
fill ~11~18~22 ~11~18~27 minecraft:warped_stairs 1
fill ~11~21~22 ~11~34~22 minecraft:stone 6
setblock ~11~37~22 minecraft:stone_block_slab 8
setblock ~12~7~22 minecraft:cobblestone_wall 6
setblock ~12~8~22 minecraft:cobblestone_wall 6
fill ~12~12~22 ~12~12~29 minecraft:fence 1
fill ~12~20~22 ~30~20~23 minecraft:wooden_slab 8
fill ~12~21~22 ~13~21~22 minecraft:carpet 11
setblock ~12~23~22 minecraft:lantern 1
setblock ~12~24~22 minecraft:double_wooden_slab 0
fill ~12~25~22 ~12~27~22 minecraft:stone 6
fill ~12~28~22 ~29~28~22 minecraft:double_wooden_slab 0
setblock ~12~29~22 minecraft:double_wooden_slab 1
setblock ~12~30~22 minecraft:bookshelf
fill ~13~1~22 ~14~1~23 minecraft:stone 5
fill ~13~24~22 ~29~24~23 minecraft:wooden_slab 8
setblock ~13~29~22 minecraft:chest 5
setblock ~13~36~22 minecraft:concrete 14
setblock ~13~37~22 minecraft:crimson_fence
setblock ~13~38~22 minecraft:lantern 0
fill ~14~0~22 ~19~0~24 minecraft:stone 0
fill ~14~21~22 ~16~21~22 minecraft:spruce_stairs 6
fill ~14~25~22 ~14~26~22 minecraft:fence 5
setblock ~14~27~22 minecraft:dark_oak_stairs 4
fill ~15~25~22 ~15~26~22 minecraft:log 1
setblock ~15~27~22 minecraft:stone 6
fill ~16~25~22 ~17~26~22 minecraft:fence 5
setblock ~16~27~22 minecraft:dark_oak_stairs 5
setblock ~16~36~22 minecraft:campfire 2
fill ~17~1~22 ~24~1~25 minecraft:stone 0
setblock ~17~27~22 minecraft:dark_oak_stairs 4
setblock ~17~33~22 minecraft:lantern 1
setblock ~17~34~22 minecraft:chain 0
fill ~18~2~22 ~24~2~22 minecraft:stone 0
setblock ~18~5~22 minecraft:cake 0
fill ~18~25~22 ~18~26~22 minecraft:log 1
setblock ~18~27~22 minecraft:stone 6
fill ~19~25~22 ~20~25~25 minecraft:carpet 13
setblock ~19~27~22 minecraft:dark_oak_stairs 5
fill ~19~37~22 ~19~37~24 minecraft:wooden_slab 13
fill ~19~38~22 ~19~38~24 minecraft:fence 1
setblock ~19~40~22 minecraft:wooden_slab 8
setblock ~19~41~22 minecraft:wooden_slab 0
setblock ~20~21~22 minecraft:fence 5
setblock ~20~22~22 minecraft:polished_blackstone_pressure_plate 0
setblock ~20~27~22 minecraft:dark_oak_stairs 4
fill ~20~32~22 ~20~33~23 minecraft:fence 1
setblock ~20~34~22 minecraft:fence 1
fill ~21~0~22 ~22~0~28 minecraft:stone 0
fill ~21~25~22 ~21~26~22 minecraft:log 1
setblock ~21~27~22 minecraft:stone 6
fill ~21~40~22 ~21~40~24 minecraft:cobblestone_wall 8
fill ~22~25~22 ~23~26~22 minecraft:fence 5
setblock ~22~27~22 minecraft:dark_oak_stairs 5
setblock ~23~27~22 minecraft:dark_oak_stairs 4
fill ~23~37~22 ~23~37~24 minecraft:wooden_slab 13
fill ~23~38~22 ~23~38~24 minecraft:fence 1
setblock ~23~40~22 minecraft:wooden_slab 8
setblock ~23~41~22 minecraft:wooden_slab 0
fill ~24~25~22 ~24~26~22 minecraft:log 1
setblock ~24~27~22 minecraft:stone 6
fill ~24~37~22 ~24~37~25 minecraft:wall_sign 5
setblock ~25~21~22 minecraft:wooden_slab 9
fill ~25~25~22 ~26~26~22 minecraft:fence 5
setblock ~25~27~22 minecraft:dark_oak_stairs 5
setblock ~26~21~22 minecraft:blast_furnace 3
setblock ~26~22~22 minecraft:iron_trapdoor 2
setblock ~26~27~22 minecraft:dark_oak_stairs 4
fill ~26~36~22 ~26~36~28 minecraft:snow_layer 0
setblock ~27~21~22 minecraft:wooden_slab 9
fill ~27~25~22 ~27~26~22 minecraft:log 1
setblock ~27~27~22 minecraft:stone 6
fill ~28~21~22 ~30~22~22 minecraft:fence 1
fill ~28~23~22 ~29~23~22 minecraft:chest 3
fill ~28~25~22 ~29~26~22 minecraft:fence 5
setblock ~28~27~22 minecraft:dark_oak_stairs 5
setblock ~28~29~22 minecraft:wooden_slab 10
fill ~28~30~22 ~28~30~24 minecraft:dispenser 3
setblock ~28~34~22 minecraft:polished_andesite_stairs 4
setblock ~29~27~22 minecraft:dark_oak_stairs 4
setblock ~29~34~22 minecraft:polished_andesite_stairs 7
fill ~29~35~22 ~29~35~45 minecraft:stonebrick 0
fill ~30~11~22 ~32~11~22 minecraft:wooden_slab 8
setblock ~30~23~22 minecraft:lantern 1
setblock ~30~24~22 minecraft:double_wooden_slab 0
fill ~30~25~22 ~30~27~22 minecraft:stone 6
fill ~30~35~22 ~30~35~23 minecraft:concrete 14
setblock ~30~36~22 minecraft:concrete 0
setblock ~30~37~22 minecraft:crimson_fence
setblock ~30~38~22 minecraft:lantern 0
fill ~31~17~22 ~32~17~22 minecraft:warped_stairs 3
fill ~31~21~22 ~31~33~22 minecraft:stonebrick 0
fill ~31~34~22 ~31~34~24 minecraft:stone 6
setblock ~32~4~22 minecraft:crafting_table
fill ~32~5~22 ~32~6~22 minecraft:bookshelf
setblock ~32~7~22 minecraft:crafting_table
setblock ~32~15~22 minecraft:wall_banner 4
setblock ~32~35~22 minecraft:cobblestone_wall 13
fill ~33~1~22 ~33~2~34 minecraft:stone 0
fill ~33~3~22 ~33~3~29 minecraft:stonebrick 0
fill ~33~4~22 ~33~20~22 minecraft:stonebrick 0
setblock ~33~35~22 minecraft:cobblestone_wall 13
fill ~34~1~22 ~34~20~22 minecraft:netherite_block
setblock ~34~21~22 minecraft:stone_block_slab 5
setblock ~35~21~22 minecraft:polished_andesite_stairs 5
setblock ~35~24~22 minecraft:stone_block_slab 8
setblock ~35~25~22 minecraft:cobblestone_wall 13
fill ~36~0~22 ~36~0~46 minecraft:stone 0
setblock ~36~17~22 minecraft:soul_lantern 1
fill ~36~18~22 ~36~19~22 minecraft:cobblestone_wall 7
setblock ~36~20~22 minecraft:stonebrick 0
fill ~36~21~22 ~36~22~22 minecraft:stone 6
setblock ~36~23~22 minecraft:stonebrick 0
setblock ~36~24~22 minecraft:polished_andesite_stairs 1
setblock ~37~22~22 minecraft:cobblestone_wall 13
fill ~9~2~23 ~9~2~24 minecraft:stone 6
fill ~9~3~23 ~9~17~24 minecraft:cobblestone_wall 13
fill ~9~18~23 ~9~20~23 minecraft:cobblestone_wall 13
fill ~10~35~23 ~10~35~27 minecraft:cobblestone_wall 13
fill ~11~4~23 ~12~4~23 minecraft:brick_block
fill ~11~6~23 ~12~6~23 minecraft:brick_block
fill ~11~11~23 ~12~11~27 minecraft:wooden_slab 8
setblock ~11~15~23 minecraft:wall_banner 5
setblock ~11~21~23 minecraft:stonebrick 0
fill ~11~22~23 ~11~23~23 minecraft:stonebrick 3
fill ~11~24~23 ~11~25~23 minecraft:stonebrick 0
fill ~11~26~23 ~11~27~23 minecraft:stonebrick 3
fill ~11~28~23 ~11~29~23 minecraft:stonebrick 0
fill ~11~30~23 ~11~31~23 minecraft:stonebrick 3
fill ~11~32~23 ~11~33~23 minecraft:stonebrick 0
fill ~11~34~23 ~12~34~29 minecraft:stone 6
fill ~11~35~23 ~11~35~26 minecraft:snow_layer 0
fill ~12~21~23 ~12~21~30 minecraft:carpet 11
setblock ~12~24~23 minecraft:wooden_slab 8
setblock ~12~27~23 minecraft:wall_banner 3
fill ~12~28~23 ~31~28~23 minecraft:wooden_slab 8
setblock ~12~29~23 minecraft:chest 5
fill ~12~35~23 ~12~35~29 minecraft:concrete 14
setblock ~12~36~23 minecraft:concrete 0
setblock ~13~21~23 minecraft:oak_stairs 1
fill ~13~34~23 ~13~34~29 minecraft:polished_andesite_stairs 5
fill ~13~35~23 ~13~35~42 minecraft:stonebrick 0
fill ~14~21~23 ~14~21~26 minecraft:spruce_stairs 4
setblock ~14~34~23 minecraft:polished_andesite_stairs 7
fill ~15~1~23 ~16~1~27 minecraft:stone 0
setblock ~15~2~23 minecraft:stone 5
fill ~15~21~23 ~15~21~25 minecraft:stone 6
setblock ~15~22~23 minecraft:furnace 4
setblock ~15~25~23 minecraft:spruce_stairs 1
setblock ~15~27~23 minecraft:wall_banner 3
setblock ~15~29~23 minecraft:birch_stairs 3
fill ~15~34~23 ~28~34~23 minecraft:wooden_slab 9
fill ~16~2~23 ~16~2~29 minecraft:stone 0
setblock ~16~4~23 minecraft:spruce_stairs 1
setblock ~16~5~23 minecraft:trapdoor 0
fill ~16~21~23 ~16~21~25 minecraft:spruce_stairs 5
fill ~16~25~23 ~17~25~23 minecraft:spruce_stairs 3
setblock ~17~21~23 minecraft:oak_stairs 0
fill ~18~2~23 ~20~2~24 minecraft:stone 5
fill ~18~4~23 ~19~4~23 minecraft:wooden_slab 8
fill ~18~21~23 ~20~21~26 minecraft:carpet 11
fill ~18~25~23 ~18~26~23 minecraft:iron_bars
fill ~19~32~23 ~19~33~24 minecraft:fence 1
setblock ~19~40~23 minecraft:double_wooden_slab 0
setblock ~19~41~23 minecraft:snow_layer 0
fill ~21~2~23 ~24~2~28 minecraft:stone 0
setblock ~21~4~23 minecraft:spruce_stairs 0
setblock ~21~5~23 minecraft:trapdoor 1
fill ~21~21~23 ~22~21~25 minecraft:carpet 7
fill ~21~25~23 ~21~26~23 minecraft:iron_bars
setblock ~22~29~23 minecraft:skull 1
fill ~23~29~23 ~23~29~25 minecraft:coal_block
setblock ~23~30~23 minecraft:skull 1
setblock ~23~40~23 minecraft:double_wooden_slab 0
setblock ~23~41~23 minecraft:snow_layer 0
setblock ~24~21~23 minecraft:dark_oak_trapdoor 2
setblock ~24~27~23 minecraft:wall_banner 3
setblock ~24~29~23 minecraft:skull 1
setblock ~27~5~23 minecraft:lantern 0
setblock ~27~27~23 minecraft:wall_banner 3
setblock ~27~29~23 minecraft:dark_oak_trapdoor 1
fill ~27~36~23 ~28~36~29 minecraft:snow_layer 0
setblock ~28~29~23 minecraft:fence 1
setblock ~29~11~23 minecraft:dark_oak_trapdoor 1
setblock ~29~12~23 minecraft:dark_oak_trapdoor 1
setblock ~29~29~23 minecraft:dark_oak_trapdoor 0
fill ~29~34~23 ~29~34~24 minecraft:polished_andesite_stairs 4
fill ~30~11~23 ~33~11~23 minecraft:log 0
fill ~30~24~23 ~31~24~23 minecraft:wooden_slab 8
setblock ~30~36~23 minecraft:concrete 14
fill ~31~12~23 ~31~12~24 minecraft:fence 1
setblock ~31~20~23 minecraft:wooden_slab 8
setblock ~31~21~23 minecraft:smithing_table
setblock ~31~22~23 minecraft:grindstone 3
fill ~31~29~23 ~31~32~23 minecraft:vine 8
setblock ~32~17~23 minecraft:warped_stairs 0
fill ~32~20~23 ~33~20~23 minecraft:stonebrick 0
fill ~32~21~23 ~32~33~23 minecraft:stonebrick 0
fill ~32~34~23 ~32~34~27 minecraft:stone 6
fill ~33~4~23 ~33~4~24 minecraft:crafting_table
fill ~33~5~23 ~33~6~24 minecraft:bookshelf
fill ~33~7~23 ~33~7~24 minecraft:crafting_table
setblock ~33~17~23 minecraft:warped_stairs 3
setblock ~33~28~23 minecraft:polished_andesite_stairs 6
setblock ~33~29~23 minecraft:polished_andesite_stairs 2
setblock ~33~34~23 minecraft:polished_andesite_stairs 6
fill ~33~35~23 ~34~35~23 minecraft:stone 6
setblock ~33~36~23 minecraft:stone_brick_stairs 1
setblock ~33~37~23 minecraft:polished_andesite_stairs 2
fill ~34~1~23 ~34~1~48 minecraft:stone 0
fill ~34~2~23 ~34~2~43 minecraft:stone 0
fill ~34~3~23 ~34~20~23 minecraft:stone 6
fill ~34~34~23 ~34~34~24 minecraft:polished_andesite_stairs 5
setblock ~34~36~23 minecraft:stonebrick 0
fill ~34~37~23 ~34~37~24 minecraft:polished_andesite_stairs 1
fill ~35~1~23 ~35~1~24 minecraft:netherite_block
setblock ~35~2~23 minecraft:netherite_block
fill ~35~3~23 ~35~4~23 minecraft:cobblestone_wall 3
fill ~35~5~23 ~35~6~23 minecraft:netherite_block
fill ~35~7~23 ~35~8~23 minecraft:cobblestone_wall 3
fill ~35~9~23 ~35~10~23 minecraft:netherite_block
fill ~35~11~23 ~35~12~23 minecraft:cobblestone_wall 3
fill ~35~13~23 ~35~14~23 minecraft:netherite_block
fill ~35~15~23 ~35~16~23 minecraft:cobblestone_wall 3
fill ~35~17~23 ~35~18~23 minecraft:netherite_block
fill ~35~19~23 ~35~20~23 minecraft:cobblestone_wall 3
fill ~35~21~23 ~35~21~25 minecraft:stone_block_slab 5
fill ~36~21~23 ~36~21~24 minecraft:polished_andesite_stairs 5
setblock ~37~22~23 minecraft:cobblestone_wall 13
setblock ~38~22~23 minecraft:cobblestone_wall 13
fill ~7~0~24 ~7~0~42 minecraft:stone 0
setblock ~7~22~24 minecraft:cobblestone_wall 13
fill ~8~18~24 ~8~19~24 minecraft:cobblestone_wall 7
setblock ~8~20~24 minecraft:stonebrick 0
fill ~8~21~24 ~8~22~24 minecraft:stone 6
setblock ~8~23~24 minecraft:stonebrick 0
setblock ~8~24~24 minecraft:polished_andesite_stairs 0
fill ~9~18~24 ~9~20~24 minecraft:cobblestone_wall 13
setblock ~9~24~24 minecraft:stone_block_slab 8
setblock ~9~25~24 minecraft:cobblestone_wall 13
setblock ~9~26~24 minecraft:lantern 0
fill ~11~5~24 ~12~5~24 minecraft:iron_trapdoor 2
fill ~11~6~24 ~12~6~24 minecraft:lever 3
setblock ~11~16~24 minecraft:spruce_stairs 5
setblock ~11~17~24 minecraft:spruce_stairs 0
setblock ~11~21~24 minecraft:stone_brick_stairs 0
fill ~11~22~24 ~11~23~24 minecraft:iron_bars
setblock ~11~24~24 minecraft:stone_brick_stairs 4
setblock ~11~25~24 minecraft:stone_brick_stairs 0
fill ~11~26~24 ~11~27~24 minecraft:iron_bars
setblock ~11~28~24 minecraft:stone_brick_stairs 4
setblock ~11~29~24 minecraft:stone_brick_stairs 0
fill ~11~30~24 ~11~31~24 minecraft:iron_bars
setblock ~11~32~24 minecraft:stone_brick_stairs 4
fill ~11~33~24 ~11~33~25 minecraft:stonebrick 0
setblock ~12~17~24 minecraft:spruce_stairs 5
setblock ~12~18~24 minecraft:spruce_stairs 0
setblock ~12~20~24 minecraft:double_wooden_slab 1
setblock ~12~24~24 minecraft:double_wooden_slab 1
setblock ~12~28~24 minecraft:double_wooden_slab 1
setblock ~12~36~24 minecraft:concrete 14
fill ~13~1~24 ~14~2~28 minecraft:stone 0
setblock ~13~4~24 minecraft:anvil 0
setblock ~13~18~24 minecraft:spruce_stairs 5
setblock ~13~19~24 minecraft:spruce_stairs 0
fill ~13~20~24 ~32~20~24 minecraft:planks 1
setblock ~13~21~24 minecraft:carpet 11
fill ~13~24~24 ~32~24~24 minecraft:planks 1
setblock ~13~25~24 minecraft:spruce_stairs 3
setblock ~13~27~24 minecraft:lantern 1
fill ~13~28~24 ~32~28~24 minecraft:planks 1
setblock ~14~19~24 minecraft:spruce_stairs 5
setblock ~14~25~24 minecraft:fence 0
setblock ~14~26~24 minecraft:dark_oak_pressure_plate 0
setblock ~14~29~24 minecraft:spruce_stairs 5
fill ~14~33~24 ~17~33~24 minecraft:bookshelf
fill ~15~2~24 ~15~2~29 minecraft:stone 0
setblock ~15~22~24 minecraft:barrel 5
fill ~15~29~24 ~16~29~24 minecraft:wooden_slab 9
fill ~18~4~24 ~19~4~24 minecraft:spruce_stairs 2
fill ~18~5~24 ~19~5~24 minecraft:trapdoor 3
fill ~18~25~24 ~18~25~26 minecraft:carpet 13
fill ~18~32~24 ~18~33~25 minecraft:fence 1
setblock ~19~34~24 minecraft:fence 1
setblock ~19~39~24 minecraft:wooden_slab 8
setblock ~19~40~24 minecraft:wooden_slab 0
fill ~20~36~24 ~20~36~26 minecraft:snow_layer 0
setblock ~21~23~24 minecraft:lantern 1
fill ~21~25~24 ~29~25~25 minecraft:carpet 13
setblock ~21~27~24 minecraft:lantern 1
setblock ~22~12~24 minecraft:wall_banner 2
setblock ~22~29~24 minecraft:coal_block
setblock ~22~30~24 minecraft:skull 1
fill ~22~36~24 ~22~36~26 minecraft:snow_layer 0
setblock ~23~13~24 minecraft:wall_banner 2
fill ~23~21~24 ~30~21~25 minecraft:carpet 7
setblock ~23~30~24 minecraft:coal_block
setblock ~23~31~24 minecraft:skull 1
setblock ~23~39~24 minecraft:wooden_slab 8
setblock ~23~40~24 minecraft:wooden_slab 0
setblock ~24~29~24 minecraft:coal_block
setblock ~24~30~24 minecraft:skull 1
fill ~26~15~24 ~27~15~24 minecraft:wall_banner 2
setblock ~28~27~24 minecraft:lantern 1
setblock ~30~34~24 minecraft:polished_andesite_stairs 7
fill ~30~35~24 ~30~35~43 minecraft:stonebrick 0
fill ~31~11~24 ~33~11~24 minecraft:wooden_slab 8
setblock ~31~23~24 minecraft:lantern 1
setblock ~31~35~24 minecraft:concrete 14
setblock ~31~36~24 minecraft:concrete 0
setblock ~31~37~24 minecraft:crimson_fence
setblock ~31~38~24 minecraft:lantern 0
fill ~32~12~24 ~32~12~27 minecraft:fence 1
setblock ~32~21~24 minecraft:wooden_slab 9
setblock ~32~22~24 minecraft:skull 1
setblock ~32~26~24 minecraft:wall_banner 4
fill ~32~29~24 ~32~32~24 minecraft:vine 4
setblock ~33~15~24 minecraft:wall_banner 4
fill ~33~17~24 ~33~17~26 minecraft:warped_stairs 0
fill ~33~20~24 ~34~20~27 minecraft:stonebrick 0
fill ~33~21~24 ~33~34~24 minecraft:stone 6
setblock ~33~37~24 minecraft:stone_block_slab 8
fill ~34~3~24 ~34~3~29 minecraft:stonebrick 0
fill ~34~4~24 ~34~19~25 minecraft:stonebrick 0
setblock ~34~28~24 minecraft:polished_andesite_stairs 5
setblock ~34~29~24 minecraft:polished_andesite_stairs 1
setblock ~34~35~24 minecraft:stone 6
setblock ~34~36~24 minecraft:stone_brick_stairs 2
setblock ~35~2~24 minecraft:stone 6
fill ~35~3~24 ~35~20~24 minecraft:cobblestone_wall 13
fill ~37~0~24 ~37~0~44 minecraft:stone 0
setblock ~37~21~24 minecraft:polished_andesite_stairs 6
setblock ~38~22~24 minecraft:cobblestone_wall 13
setblock ~39~22~24 minecraft:cobblestone_wall 13
fill ~7~22~25 ~7~22~26 minecraft:cobblestone_wall 13
fill ~8~1~25 ~8~1~41 minecraft:stone 0
fill ~8~2~25 ~8~20~25 minecraft:iron_bars
fill ~8~21~25 ~8~21~27 minecraft:polished_andesite_stairs 4
fill ~9~2~25 ~9~20~25 minecraft:netherite_block
setblock ~11~14~25 minecraft:wall_banner 5
setblock ~11~17~25 minecraft:lantern 1
setblock ~11~21~25 minecraft:stonebrick 0
fill ~11~22~25 ~11~23~25 minecraft:stonebrick 3
fill ~11~24~25 ~11~25~25 minecraft:stonebrick 0
fill ~11~26~25 ~11~27~25 minecraft:stonebrick 3
fill ~11~28~25 ~11~29~25 minecraft:stonebrick 0
fill ~11~30~25 ~11~31~25 minecraft:stonebrick 3
setblock ~11~32~25 minecraft:stonebrick 0
fill ~12~20~25 ~32~20~26 minecraft:wooden_slab 8
fill ~12~24~25 ~32~24~26 minecraft:wooden_slab 8
fill ~12~27~25 ~12~27~26 minecraft:wall_banner 5
fill ~12~28~25 ~32~28~26 minecraft:wooden_slab 8
fill ~12~29~25 ~18~31~25 minecraft:fence 1
fill ~12~32~25 ~17~33~25 minecraft:fence 1
setblock ~12~36~25 minecraft:concrete 0
setblock ~13~4~25 minecraft:cauldron 6
setblock ~13~21~25 minecraft:oak_stairs 1
fill ~13~25~25 ~13~25~28 minecraft:spruce_stairs 1
fill ~14~0~25 ~16~0~26 minecraft:stone 0
fill ~14~34~25 ~18~34~25 minecraft:fence 1
setblock ~15~22~25 minecraft:furnace 5
fill ~17~0~25 ~19~0~29 minecraft:stone 1
fill ~17~2~25 ~19~2~25 minecraft:stone 5
setblock ~17~21~25 minecraft:oak_stairs 0
fill ~17~25~25 ~17~25~27 minecraft:carpet 13
setblock ~18~9~25 minecraft:wall_banner 2
setblock ~19~8~25 minecraft:log 0
fill ~19~9~25 ~20~9~25 minecraft:log 0
setblock ~19~10~25 minecraft:crafting_table
setblock ~19~37~25 minecraft:dark_oak_stairs 6
setblock ~19~39~25 minecraft:double_wooden_slab 0
setblock ~19~40~25 minecraft:snow_layer 0
fill ~20~2~25 ~20~2~27 minecraft:stone 0
setblock ~20~10~25 minecraft:log 0
setblock ~21~10~25 minecraft:log 0
setblock ~21~11~25 minecraft:log 0
setblock ~21~39~25 minecraft:cobblestone_wall 1
setblock ~21~40~25 minecraft:cobblestone_wall 1
setblock ~22~11~25 minecraft:log 0
setblock ~22~12~25 minecraft:log 0
setblock ~22~29~25 minecraft:skull 1
fill ~23~3~25 ~23~3~34 minecraft:stonebrick 0
setblock ~23~12~25 minecraft:log 0
setblock ~23~13~25 minecraft:log 0
setblock ~23~30~25 minecraft:skull 1
setblock ~23~33~25 minecraft:lantern 1
setblock ~23~34~25 minecraft:chain 0
setblock ~23~37~25 minecraft:dark_oak_stairs 6
setblock ~23~39~25 minecraft:double_wooden_slab 0
setblock ~23~40~25 minecraft:snow_layer 0
fill ~24~3~25 ~27~3~25 minecraft:hay_block 0
setblock ~24~13~25 minecraft:log 0
setblock ~24~14~25 minecraft:log 0
setblock ~24~29~25 minecraft:skull 1
fill ~25~14~25 ~27~14~25 minecraft:log 0
setblock ~25~15~25 minecraft:crafting_table
fill ~26~15~25 ~27~15~25 minecraft:log 0
setblock ~28~14~25 minecraft:log 0
fill ~30~25~25 ~30~25~27 minecraft:carpet 13
setblock ~30~34~25 minecraft:polished_andesite_stairs 4
fill ~31~21~25 ~31~21~35 minecraft:carpet 7
setblock ~31~34~25 minecraft:polished_andesite_stairs 7
fill ~31~35~25 ~31~35~41 minecraft:stonebrick 0
fill ~32~11~25 ~33~11~26 minecraft:wooden_slab 8
fill ~32~21~25 ~32~21~26 minecraft:blast_furnace 4
fill ~32~22~25 ~32~22~26 minecraft:iron_trapdoor 1
setblock ~32~27~25 minecraft:wall_banner 4
fill ~32~35~25 ~32~35~27 minecraft:concrete 14
setblock ~32~36~25 minecraft:concrete 14
setblock ~33~21~25 minecraft:stonebrick 0
fill ~33~22~25 ~33~23~25 minecraft:stonebrick 3
fill ~33~24~25 ~33~25~25 minecraft:stonebrick 0
fill ~33~26~25 ~33~27~25 minecraft:stonebrick 3
fill ~33~28~25 ~33~29~25 minecraft:stonebrick 0
fill ~33~30~25 ~33~31~25 minecraft:stonebrick 3
fill ~33~32~25 ~33~33~25 minecraft:stonebrick 0
fill ~33~34~25 ~33~34~28 minecraft:stone 6
setblock ~34~35~25 minecraft:cobblestone_wall 13
fill ~35~1~25 ~35~20~25 minecraft:cobblestone_wall 13
fill ~36~1~25 ~36~20~25 minecraft:netherite_block
setblock ~36~21~25 minecraft:stone_block_slab 5
fill ~37~1~25 ~37~20~25 minecraft:iron_bars
setblock ~37~21~25 minecraft:polished_andesite_stairs 5
fill ~38~0~25 ~38~0~42 minecraft:stone 0
setblock ~38~21~25 minecraft:polished_andesite_stairs 6
setblock ~39~22~25 minecraft:cobblestone_wall 13
fill ~9~2~26 ~9~2~28 minecraft:stone 6
fill ~9~3~26 ~9~20~27 minecraft:cobblestone_wall 13
fill ~11~21~26 ~11~33~26 minecraft:stone 6
setblock ~12~36~26 minecraft:concrete 14
setblock ~13~4~26 minecraft:smithing_table
fill ~13~21~26 ~13~21~29 minecraft:carpet 11
fill ~13~29~26 ~15~30~27 minecraft:barrel 3
setblock ~13~31~26 minecraft:barrel 3
setblock ~14~25~26 minecraft:fence 0
setblock ~14~26~26 minecraft:dark_oak_pressure_plate 0
fill ~14~34~26 ~30~34~26 minecraft:wooden_slab 9
setblock ~14~36~26 minecraft:snow_layer 0
fill ~15~21~26 ~16~21~26 minecraft:spruce_stairs 7
fill ~16~25~26 ~16~25~30 minecraft:carpet 13
setblock ~17~1~26 minecraft:stone 0
fill ~17~2~26 ~18~2~26 minecraft:stone 5
setblock ~17~8~26 minecraft:wall_banner 2
fill ~17~21~26 ~17~21~41 minecraft:carpet 11
fill ~18~1~26 ~19~1~27 minecraft:stone 1
fill ~18~4~26 ~18~6~27 minecraft:fence 0
setblock ~18~7~26 minecraft:log 0
setblock ~18~8~26 minecraft:log 0
setblock ~18~9~26 minecraft:log 0
setblock ~18~36~26 minecraft:polished_blackstone_stairs 6
setblock ~18~37~26 minecraft:polished_blackstone_stairs 2
fill ~19~2~26 ~19~2~28 minecraft:stone 0
fill ~19~4~26 ~19~5~26 minecraft:fence_gate 2
fill ~19~6~26 ~21~8~26 minecraft:fence 0
fill ~19~9~26 ~19~9~28 minecraft:wooden_slab 2
fill ~19~37~26 ~19~37~27 minecraft:planks 5
setblock ~19~38~26 minecraft:spruce_stairs 6
setblock ~19~39~26 minecraft:wooden_slab 0
fill ~20~0~26 ~20~0~27 minecraft:stone 1
fill ~20~1~26 ~24~1~28 minecraft:stone 0
fill ~20~4~26 ~21~5~26 minecraft:fence 0
fill ~20~9~26 ~20~9~27 minecraft:birch_stairs 0
fill ~21~9~26 ~21~9~27 minecraft:birch_stairs 5
fill ~21~10~26 ~21~10~27 minecraft:birch_stairs 0
fill ~21~39~26 ~21~39~27 minecraft:cobblestone_wall 8
fill ~22~10~26 ~22~10~27 minecraft:birch_stairs 5
fill ~22~11~26 ~22~11~27 minecraft:birch_stairs 0
setblock ~22~25~26 minecraft:spruce_stairs 1
fill ~23~4~26 ~23~4~27 minecraft:fletching_table
fill ~23~11~26 ~23~11~27 minecraft:birch_stairs 5
fill ~23~12~26 ~23~12~27 minecraft:birch_stairs 0
setblock ~23~25~26 minecraft:fence 0
setblock ~23~26~26 minecraft:dark_oak_pressure_plate 0
fill ~23~37~26 ~23~37~27 minecraft:planks 5
setblock ~23~38~26 minecraft:wooden_slab 8
setblock ~23~39~26 minecraft:wooden_slab 0
setblock ~24~3~26 minecraft:concrete 14
fill ~24~12~26 ~24~12~27 minecraft:birch_stairs 5
fill ~24~13~26 ~24~13~27 minecraft:birch_stairs 0
setblock ~24~25~26 minecraft:spruce_stairs 0
setblock ~24~36~26 minecraft:polished_blackstone_stairs 6
setblock ~24~37~26 minecraft:polished_blackstone_stairs 2
fill ~25~3~26 ~25~3~34 minecraft:stonebrick 0
fill ~25~13~26 ~25~13~27 minecraft:birch_stairs 5
fill ~25~14~26 ~25~14~27 minecraft:birch_stairs 0
setblock ~26~3~26 minecraft:concrete 14
fill ~26~14~26 ~27~14~26 minecraft:birch_stairs 5
fill ~27~3~26 ~27~3~30 minecraft:stonebrick 3
setblock ~28~13~26 minecraft:log 0
setblock ~28~14~26 minecraft:log 0
setblock ~28~15~26 minecraft:log 0
fill ~29~21~26 ~30~21~26 minecraft:carpet 7
setblock ~29~25~26 minecraft:carpet 13
fill ~31~25~26 ~31~25~27 minecraft:carpet 13
fill ~31~34~26 ~31~34~28 minecraft:polished_andesite_stairs 4
setblock ~32~36~26 minecraft:concrete 0
setblock ~32~37~26 minecraft:crimson_fence
setblock ~32~38~26 minecraft:lantern 0
setblock ~33~21~26 minecraft:stone_brick_stairs 1
fill ~33~22~26 ~33~23~26 minecraft:iron_bars
setblock ~33~24~26 minecraft:stone_brick_stairs 5
setblock ~33~25~26 minecraft:stone_brick_stairs 1
fill ~33~26~26 ~33~27~26 minecraft:iron_bars
setblock ~33~28~26 minecraft:stone_brick_stairs 5
setblock ~33~29~26 minecraft:stone_brick_stairs 1
fill ~33~30~26 ~33~31~26 minecraft:iron_bars
setblock ~33~32~26 minecraft:stone_brick_stairs 5
fill ~33~33~26 ~33~33~27 minecraft:stonebrick 0
setblock ~34~11~26 minecraft:wooden_slab 8
setblock ~34~14~26 minecraft:wall_banner 3
setblock ~34~16~26 minecraft:lantern 1
setblock ~34~17~26 minecraft:warped_stairs 3
setblock ~34~35~26 minecraft:cobblestone_wall 13
fill ~35~1~26 ~36~2~40 minecraft:stone 0
fill ~35~3~26 ~36~3~29 minecraft:stonebrick 0
fill ~35~4~26 ~36~20~26 minecraft:stonebrick 0
setblock ~35~35~26 minecraft:cobblestone_wall 13
setblock ~36~35~26 minecraft:cobblestone_wall 13
fill ~37~1~26 ~37~20~26 minecraft:netherite_block
setblock ~37~21~26 minecraft:stone_block_slab 5
setblock ~38~21~26 minecraft:polished_andesite_stairs 5
setblock ~38~24~26 minecraft:stone_block_slab 8
setblock ~38~25~26 minecraft:cobblestone_wall 13
setblock ~38~26~26 minecraft:lantern 0
fill ~39~0~26 ~39~0~41 minecraft:stone 0
fill ~39~18~26 ~39~19~26 minecraft:cobblestone_wall 7
setblock ~39~20~26 minecraft:stonebrick 0
fill ~39~21~26 ~39~22~26 minecraft:stone 6
setblock ~39~23~26 minecraft:stonebrick 0
setblock ~39~24~26 minecraft:polished_andesite_stairs 1
setblock ~40~22~26 minecraft:cobblestone_wall 13
setblock ~6~22~27 minecraft:cobblestone_wall 13
setblock ~7~17~27 minecraft:soul_lantern 1
fill ~7~18~27 ~7~19~27 minecraft:cobblestone_wall 7
setblock ~7~20~27 minecraft:stonebrick 0
fill ~7~21~27 ~7~22~27 minecraft:stone 6
setblock ~7~23~27 minecraft:stonebrick 0
setblock ~7~24~27 minecraft:polished_andesite_stairs 0
setblock ~8~24~27 minecraft:stone_block_slab 8
setblock ~8~25~27 minecraft:cobblestone_wall 13
setblock ~11~4~27 minecraft:grindstone 1
setblock ~11~5~27 minecraft:grindstone 3
setblock ~11~15~27 minecraft:wall_banner 5
fill ~11~21~27 ~11~33~28 minecraft:stonebrick 0
setblock ~12~20~27 minecraft:double_wooden_slab 1
setblock ~12~23~27 minecraft:lantern 1
setblock ~12~24~27 minecraft:double_wooden_slab 1
setblock ~12~28~27 minecraft:double_wooden_slab 1
fill ~12~29~27 ~12~33~28 minecraft:vine 2
setblock ~12~36~27 minecraft:concrete 0
fill ~13~20~27 ~20~20~27 minecraft:planks 1
fill ~13~24~27 ~19~24~27 minecraft:planks 1
fill ~13~28~27 ~19~28~27 minecraft:planks 1
fill ~14~0~27 ~15~0~27 minecraft:stone 0
fill ~14~21~27 ~14~21~30 minecraft:carpet 11
setblock ~15~21~27 minecraft:oak_stairs 2
fill ~15~25~27 ~15~25~31 minecraft:carpet 13
setblock ~15~31~27 minecraft:barrel 1
setblock ~15~36~27 minecraft:snow_layer 0
fill ~16~0~27 ~16~0~29 minecraft:stone 1
fill ~16~4~27 ~17~5~27 minecraft:fence 0
fill ~16~6~27 ~16~6~31 minecraft:fence 0
fill ~16~21~27 ~16~21~37 minecraft:carpet 11
fill ~17~1~27 ~17~1~29 minecraft:stone 1
fill ~17~2~27 ~18~2~32 minecraft:stone 0
setblock ~17~6~27 minecraft:log 0
setblock ~17~7~27 minecraft:log 0
setblock ~17~8~27 minecraft:log 0
fill ~17~36~27 ~17~36~29 minecraft:snow_layer 0
setblock ~18~7~27 minecraft:fence 0
fill ~18~8~27 ~18~8~28 minecraft:birch_stairs 0
fill ~18~21~27 ~18~23~27 minecraft:chain 0
fill ~18~25~27 ~18~27~28 minecraft:iron_bars
setblock ~18~36~27 minecraft:polished_blackstone_stairs 7
setblock ~18~37~27 minecraft:polished_blackstone_stairs 3
setblock ~19~8~27 minecraft:wooden_slab 8
fill ~19~21~27 ~20~21~27 minecraft:carpet 11
fill ~19~25~27 ~19~27~27 minecraft:chain 0
setblock ~19~38~27 minecraft:spruce_stairs 3
fill ~20~24~27 ~26~24~27 minecraft:wooden_slab 8
fill ~20~28~27 ~26~28~27 minecraft:wooden_slab 8
fill ~20~30~27 ~20~33~27 minecraft:jungle_trapdoor 3
setblock ~20~37~27 minecraft:dark_oak_stairs 5
setblock ~20~38~27 minecraft:snow_layer 0
fill ~21~4~27 ~21~8~28 minecraft:fence 0
fill ~21~20~27 ~25~20~27 minecraft:wooden_slab 8
fill ~21~21~27 ~25~21~27 minecraft:wooden_slab 5
fill ~21~25~27 ~25~25~27 minecraft:wooden_slab 5
setblock ~21~29~27 minecraft:dark_oak_stairs 1
setblock ~21~37~27 minecraft:wooden_slab 13
fill ~22~8~27 ~22~9~28 minecraft:fence 0
fill ~22~29~27 ~24~29~27 minecraft:dark_oak_stairs 2
setblock ~22~37~27 minecraft:dark_oak_stairs 4
setblock ~22~38~27 minecraft:snow_layer 0
fill ~23~9~27 ~23~10~28 minecraft:fence 0
setblock ~23~38~27 minecraft:spruce_stairs 3
setblock ~24~3~27 minecraft:stonebrick 0
fill ~24~10~27 ~24~11~28 minecraft:fence 0
setblock ~24~36~27 minecraft:polished_blackstone_stairs 7
setblock ~24~37~27 minecraft:polished_blackstone_stairs 3
fill ~25~11~27 ~25~12~28 minecraft:fence 0
setblock ~25~29~27 minecraft:dark_oak_stairs 0
fill ~26~3~27 ~26~3~34 minecraft:stonebrick 0
fill ~26~12~27 ~26~13~28 minecraft:fence 0
setblock ~26~14~27 minecraft:birch_stairs 5
fill ~26~15~27 ~26~15~28 minecraft:birch_stairs 0
fill ~26~20~27 ~32~20~27 minecraft:planks 1
setblock ~26~21~27 minecraft:smithing_table
setblock ~26~22~27 minecraft:grindstone 0
setblock ~26~29~27 minecraft:wooden_slab 1
fill ~26~30~27 ~26~33~27 minecraft:jungle_trapdoor 3
fill ~27~13~27 ~29~13~28 minecraft:fence 0
setblock ~27~14~27 minecraft:wooden_slab 8
fill ~27~15~27 ~28~15~27 minecraft:birch_stairs 2
fill ~27~21~27 ~28~23~27 minecraft:fence 1
fill ~27~24~27 ~32~24~27 minecraft:planks 1
fill ~27~25~27 ~28~27~27 minecraft:iron_bars
fill ~27~28~27 ~32~28~27 minecraft:planks 1
fill ~28~4~27 ~29~12~28 minecraft:fence 0
fill ~28~14~27 ~28~14~29 minecraft:fence 0
setblock ~29~14~27 minecraft:log 0
setblock ~29~15~27 minecraft:log 0
setblock ~29~16~27 minecraft:log 0
setblock ~29~23~27 minecraft:lantern 1
setblock ~29~25~27 minecraft:oak_stairs 3
fill ~29~36~27 ~29~36~39 minecraft:snow_layer 0
fill ~30~21~27 ~30~21~29 minecraft:carpet 7
setblock ~30~27~27 minecraft:lantern 1
fill ~31~11~27 ~31~12~27 minecraft:dark_oak_trapdoor 1
fill ~32~11~27 ~35~11~27 minecraft:log 0
setblock ~32~21~27 minecraft:wooden_slab 9
setblock ~32~25~27 minecraft:oak_stairs 0
fill ~32~29~27 ~32~29~28 minecraft:skull 1
setblock ~32~36~27 minecraft:concrete 14
fill ~33~4~27 ~35~4~27 minecraft:polished_andesite_stairs 2
fill ~33~12~27 ~33~12~34 minecraft:fence 1
fill ~33~21~27 ~33~25~27 minecraft:stonebrick 0
fill ~33~26~27 ~33~27~27 minecraft:stonebrick 3
fill ~33~28~27 ~33~29~27 minecraft:stonebrick 0
fill ~33~30~27 ~33~31~27 minecraft:stonebrick 3
setblock ~33~32~27 minecraft:stonebrick 0
setblock ~34~17~27 minecraft:warped_stairs 0
fill ~34~21~27 ~34~34~27 minecraft:stone 6
setblock ~35~10~27 minecraft:lantern 1
setblock ~35~17~27 minecraft:warped_stairs 3
fill ~35~20~27 ~36~20~27 minecraft:stonebrick 0
fill ~35~21~27 ~35~33~27 minecraft:stonebrick 0
fill ~35~34~27 ~35~34~39 minecraft:stone 6
fill ~36~4~27 ~37~19~27 minecraft:stone 6
setblock ~36~28~27 minecraft:polished_andesite_stairs 4
setblock ~36~29~27 minecraft:polished_andesite_stairs 0
setblock ~36~34~27 minecraft:polished_andesite_stairs 6
fill ~36~35~27 ~37~35~27 minecraft:stone 6
setblock ~36~36~27 minecraft:stone_brick_stairs 1
setblock ~36~37~27 minecraft:polished_andesite_stairs 2
fill ~37~1~27 ~37~1~42 minecraft:stone 0
fill ~37~2~27 ~37~2~37 minecraft:stone 0
setblock ~37~3~27 minecraft:stone 6
setblock ~37~20~27 minecraft:stone 6
setblock ~37~28~27 minecraft:polished_andesite_stairs 6
setblock ~37~29~27 minecraft:polished_andesite_stairs 2
fill ~37~34~27 ~37~34~28 minecraft:polished_andesite_stairs 5
setblock ~37~36~27 minecraft:stonebrick 0
fill ~37~37~27 ~37~37~28 minecraft:polished_andesite_stairs 1
fill ~38~1~27 ~38~1~30 minecraft:netherite_block
setblock ~38~2~27 minecraft:netherite_block
fill ~38~3~27 ~38~4~27 minecraft:cobblestone_wall 3
fill ~38~5~27 ~38~6~27 minecraft:netherite_block
fill ~38~7~27 ~38~8~27 minecraft:cobblestone_wall 3
fill ~38~9~27 ~38~10~27 minecraft:netherite_block
fill ~38~11~27 ~38~12~27 minecraft:cobblestone_wall 3
fill ~38~13~27 ~38~14~27 minecraft:netherite_block
fill ~38~15~27 ~38~16~27 minecraft:cobblestone_wall 3
fill ~38~17~27 ~38~18~27 minecraft:netherite_block
fill ~38~19~27 ~38~20~27 minecraft:cobblestone_wall 3
fill ~38~21~27 ~38~21~37 minecraft:stone_block_slab 5
fill ~39~21~27 ~39~21~29 minecraft:polished_andesite_stairs 5
fill ~40~22~27 ~40~22~29 minecraft:cobblestone_wall 13
fill ~6~22~28 ~6~22~30 minecraft:cobblestone_wall 13
fill ~7~21~28 ~7~21~31 minecraft:polished_andesite_stairs 4
fill ~8~2~28 ~8~3~28 minecraft:netherite_block
fill ~8~4~28 ~8~5~28 minecraft:cobblestone_wall 3
fill ~8~6~28 ~8~7~28 minecraft:netherite_block
fill ~8~8~28 ~8~9~28 minecraft:cobblestone_wall 3
fill ~8~10~28 ~8~11~28 minecraft:netherite_block
fill ~8~12~28 ~8~13~28 minecraft:cobblestone_wall 3
fill ~8~14~28 ~8~15~28 minecraft:netherite_block
fill ~8~16~28 ~8~17~28 minecraft:cobblestone_wall 3
fill ~8~18~28 ~8~19~28 minecraft:netherite_block
setblock ~8~20~28 minecraft:cobblestone_wall 3
fill ~8~21~28 ~8~21~31 minecraft:stone_block_slab 5
fill ~9~3~28 ~9~20~28 minecraft:stone 6
fill ~9~34~28 ~10~34~28 minecraft:polished_andesite_stairs 6
fill ~9~35~28 ~10~35~28 minecraft:stone 6
setblock ~9~36~28 minecraft:stonebrick 0
fill ~9~37~28 ~9~37~29 minecraft:polished_andesite_stairs 0
fill ~10~4~28 ~10~5~29 minecraft:blast_furnace 5
fill ~10~6~28 ~10~7~31 minecraft:barrel 5
fill ~10~11~28 ~12~11~28 minecraft:log 0
fill ~10~18~28 ~10~18~31 minecraft:warped_stairs 1
fill ~10~20~28 ~10~20~32 minecraft:stonebrick 0
setblock ~10~28~28 minecraft:polished_andesite_stairs 6
setblock ~10~29~28 minecraft:polished_andesite_stairs 2
setblock ~10~36~28 minecraft:stone_brick_stairs 0
setblock ~10~37~28 minecraft:polished_andesite_stairs 2
setblock ~11~18~28 minecraft:warped_stairs 3
setblock ~12~10~28 minecraft:lantern 1
fill ~12~20~28 ~18~20~29 minecraft:wooden_slab 8
fill ~12~24~28 ~18~24~29 minecraft:wooden_slab 8
fill ~12~28~28 ~18~28~29 minecraft:wooden_slab 8
setblock ~12~36~28 minecraft:concrete 14
setblock ~12~37~28 minecraft:crimson_fence
setblock ~12~38~28 minecraft:lantern 0
setblock ~13~11~28 minecraft:dark_oak_trapdoor 1
setblock ~13~12~28 minecraft:dark_oak_trapdoor 0
setblock ~14~0~28 minecraft:stone 0
setblock ~14~25~28 minecraft:fence 0
setblock ~14~26~28 minecraft:dark_oak_pressure_plate 0
fill ~15~0~28 ~15~0~29 minecraft:stone 1
fill ~15~1~28 ~15~1~29 minecraft:stone 0
fill ~15~21~28 ~15~21~31 minecraft:carpet 11
fill ~16~1~28 ~16~1~29 minecraft:stone 1
fill ~16~4~28 ~16~5~31 minecraft:fence 0
fill ~16~36~28 ~16~36~30 minecraft:snow_layer 0
fill ~17~3~28 ~17~3~29 minecraft:cauldron 6
fill ~17~7~28 ~17~7~30 minecraft:birch_stairs 0
fill ~18~1~28 ~18~1~29 minecraft:stone 1
fill ~18~3~28 ~22~3~31 minecraft:stonebrick 0
setblock ~18~7~28 minecraft:wooden_slab 8
fill ~18~21~28 ~18~21~29 minecraft:carpet 11
setblock ~18~34~28 minecraft:lantern 1
fill ~18~36~28 ~19~36~29 minecraft:snow_layer 0
fill ~19~1~28 ~19~1~36 minecraft:stone 0
setblock ~19~8~28 minecraft:birch_stairs 6
fill ~19~20~28 ~19~28~28 minecraft:planks 5
fill ~19~30~28 ~19~33~28 minecraft:jungle_trapdoor 3
fill ~20~0~28 ~20~0~31 minecraft:stone 0
fill ~20~2~28 ~20~2~33 minecraft:stone 3
fill ~20~4~28 ~20~6~29 minecraft:fence 0
fill ~20~7~28 ~20~8~28 minecraft:fence 0
setblock ~20~9~28 minecraft:birch_stairs 3
setblock ~20~20~28 minecraft:wooden_slab 8
setblock ~20~21~28 minecraft:wooden_slab 5
setblock ~20~23~28 minecraft:wall_banner 5
setblock ~20~24~28 minecraft:wooden_slab 8
setblock ~20~25~28 minecraft:wooden_slab 5
setblock ~20~27~28 minecraft:wall_banner 5
setblock ~20~28~28 minecraft:wooden_slab 8
setblock ~20~29~28 minecraft:double_wooden_slab 5
fill ~20~30~28 ~20~33~28 minecraft:jungle_trapdoor 0
fill ~20~39~28 ~20~39~29 minecraft:trapdoor 1
setblock ~21~9~28 minecraft:log 0
fill ~21~10~28 ~22~10~28 minecraft:log 0
setblock ~21~11~28 minecraft:lantern 0
setblock ~21~29~28 minecraft:dark_oak_stairs 5
setblock ~21~30~28 minecraft:fence 0
setblock ~21~31~28 minecraft:dark_oak_stairs 0
fill ~21~38~28 ~21~38~29 minecraft:trapdoor 2
setblock ~21~39~28 minecraft:cobblestone_wall 8
setblock ~21~40~28 minecraft:trapdoor 1
setblock ~22~11~28 minecraft:log 0
fill ~22~29~28 ~24~29~28 minecraft:wooden_slab 13
setblock ~22~30~28 minecraft:dark_oak_trapdoor 0
setblock ~22~31~28 minecraft:fence 0
setblock ~22~32~28 minecraft:dark_oak_stairs 0
setblock ~22~39~28 minecraft:trapdoor 0
setblock ~23~11~28 minecraft:log 0
setblock ~23~12~28 minecraft:log 0
setblock ~23~32~28 minecraft:fence 0
fill ~23~36~28 ~24~36~33 minecraft:snow_layer 0
setblock ~24~3~28 minecraft:stonebrick 3
fill ~24~12~28 ~24~13~28 minecraft:log 0
setblock ~24~30~28 minecraft:dark_oak_trapdoor 1
setblock ~24~31~28 minecraft:fence 0
setblock ~24~32~28 minecraft:dark_oak_stairs 1
setblock ~25~13~28 minecraft:log 0
setblock ~25~14~28 minecraft:log 0
setblock ~25~29~28 minecraft:dark_oak_stairs 4
setblock ~25~30~28 minecraft:fence 0
setblock ~25~31~28 minecraft:dark_oak_stairs 1
fill ~26~14~28 ~27~14~28 minecraft:fence 0
setblock ~26~20~28 minecraft:wooden_slab 8
setblock ~26~21~28 minecraft:wooden_slab 5
setblock ~26~23~28 minecraft:wall_banner 4
setblock ~26~24~28 minecraft:wooden_slab 8
setblock ~26~25~28 minecraft:wooden_slab 5
setblock ~26~27~28 minecraft:wall_banner 4
setblock ~26~28~28 minecraft:wooden_slab 8
setblock ~26~29~28 minecraft:double_wooden_slab 5
fill ~26~30~28 ~26~33~28 minecraft:jungle_trapdoor 1
fill ~27~4~28 ~27~12~29 minecraft:fence 0
setblock ~27~15~28 minecraft:birch_stairs 5
fill ~27~16~28 ~29~16~28 minecraft:wooden_slab 2
fill ~27~20~28 ~27~28~28 minecraft:planks 5
setblock ~27~29~28 minecraft:wooden_slab 1
setblock ~28~15~28 minecraft:wooden_slab 8
fill ~28~20~28 ~35~20~29 minecraft:wooden_slab 8
fill ~28~21~28 ~28~23~28 minecraft:fence 1
fill ~28~24~28 ~35~24~29 minecraft:wooden_slab 8
fill ~28~25~28 ~29~25~28 minecraft:log 2
fill ~28~26~28 ~29~26~28 minecraft:stone_pressure_plate 0
setblock ~28~27~28 minecraft:iron_bars
fill ~28~28~28 ~35~28~29 minecraft:wooden_slab 8
fill ~29~14~28 ~29~15~28 minecraft:fence 0
setblock ~30~15~28 minecraft:log 0
setblock ~30~16~28 minecraft:log 0
setblock ~30~17~28 minecraft:log 0
setblock ~30~25~28 minecraft:birch_fence_gate 0
setblock ~30~29~28 minecraft:torch 2
fill ~30~36~28 ~30~36~38 minecraft:snow_layer 0
setblock ~31~17~28 minecraft:wall_banner 5
fill ~31~25~28 ~32~25~28 minecraft:log 2
fill ~31~26~28 ~32~26~28 minecraft:stone_pressure_plate 0
setblock ~31~29~28 minecraft:barrel 1
setblock ~32~4~28 minecraft:polished_andesite_stairs 2
setblock ~32~21~28 minecraft:smithing_table
setblock ~32~22~28 minecraft:grindstone 3
setblock ~32~27~28 minecraft:wall_banner 4
setblock ~32~34~28 minecraft:polished_andesite_stairs 7
fill ~32~35~28 ~32~35~39 minecraft:stonebrick 0
fill ~33~4~28 ~36~4~28 minecraft:polished_andesite_stairs 7
fill ~33~5~28 ~35~5~28 minecraft:polished_andesite_stairs 2
fill ~33~11~28 ~35~11~28 minecraft:wooden_slab 8
fill ~33~21~28 ~35~23~28 minecraft:fence 1
fill ~33~25~28 ~34~26~28 minecraft:iron_block
fill ~33~27~28 ~34~27~28 minecraft:bookshelf
setblock ~33~29~28 minecraft:skull 1
fill ~33~30~28 ~34~33~28 minecraft:vine 4
fill ~33~35~28 ~34~35~28 minecraft:concrete 14
setblock ~33~36~28 minecraft:concrete 14
setblock ~34~29~28 minecraft:vine 4
setblock ~34~34~28 minecraft:stone 6
setblock ~34~36~28 minecraft:concrete 0
setblock ~34~37~28 minecraft:crimson_fence
setblock ~34~38~28 minecraft:lantern 0
setblock ~35~16~28 minecraft:wall_banner 4
fill ~35~17~28 ~35~17~40 minecraft:warped_stairs 0
fill ~35~25~28 ~35~25~30 minecraft:log 2
fill ~35~26~28 ~35~27~28 minecraft:chest 3
fill ~36~5~28 ~36~7~28 minecraft:stone 6
fill ~36~8~28 ~36~8~36 minecraft:coral_block 1
fill ~36~9~28 ~36~11~30 minecraft:coral_block 1
fill ~36~12~28 ~36~19~29 minecraft:coral_block 1
fill ~36~20~28 ~37~20~36 minecraft:stonebrick 0
fill ~36~21~28 ~36~34~28 minecraft:stone 6
setblock ~36~37~28 minecraft:stone_block_slab 8
fill ~37~3~28 ~37~3~36 minecraft:stonebrick 0
fill ~37~4~28 ~37~19~30 minecraft:stonebrick 0
setblock ~37~28~28 minecraft:polished_andesite_stairs 5
setblock ~37~29~28 minecraft:polished_andesite_stairs 1
setblock ~37~35~28 minecraft:stone 6
setblock ~37~36~28 minecraft:stone_brick_stairs 2
fill ~38~2~28 ~38~2~29 minecraft:stone 6
fill ~38~3~28 ~38~19~29 minecraft:cobblestone_wall 13
fill ~38~20~28 ~38~20~35 minecraft:netherite_block
fill ~6~0~29 ~6~0~42 minecraft:stone 0
setblock ~8~2~29 minecraft:stone 6
fill ~8~3~29 ~8~20~31 minecraft:cobblestone_wall 13
fill ~9~2~29 ~9~20~31 minecraft:stonebrick 0
setblock ~9~28~29 minecraft:polished_andesite_stairs 4
setblock ~9~29~29 minecraft:polished_andesite_stairs 0
setblock ~9~34~29 minecraft:polished_andesite_stairs 4
setblock ~9~35~29 minecraft:stone 6
setblock ~9~36~29 minecraft:stone_brick_stairs 2
fill ~10~2~29 ~10~2~45 minecraft:stone 0
fill ~10~3~29 ~10~3~44 minecraft:stonebrick 0
fill ~10~11~29 ~12~11~29 minecraft:wooden_slab 8
setblock ~10~14~29 minecraft:wall_banner 5
fill ~10~21~29 ~10~34~29 minecraft:stone 6
setblock ~10~37~29 minecraft:stone_block_slab 8
fill ~11~12~29 ~11~12~33 minecraft:fence 1
setblock ~11~20~29 minecraft:wooden_slab 8
fill ~11~21~29 ~11~21~31 minecraft:carpet 11
setblock ~11~22~29 minecraft:oak_stairs 5
setblock ~11~23~29 minecraft:skull 1
setblock ~11~24~29 minecraft:wooden_slab 8
fill ~11~27~29 ~11~27~30 minecraft:wall_banner 5
setblock ~11~28~29 minecraft:wooden_slab 8
setblock ~11~33~29 minecraft:lantern 1
fill ~12~1~29 ~14~2~32 minecraft:dirt 0
setblock ~12~36~29 minecraft:concrete 0
fill ~13~0~29 ~14~0~36 minecraft:dirt 0
setblock ~13~4~29 minecraft:iron_trapdoor 3
setblock ~13~25~29 minecraft:spruce_stairs 2
setblock ~14~29~29 minecraft:dark_oak_trapdoor 3
fill ~14~34~29 ~31~34~29 minecraft:wooden_slab 9
fill ~15~36~29 ~15~36~30 minecraft:snow_layer 0
setblock ~17~25~29 minecraft:spruce_stairs 3
setblock ~18~7~29 minecraft:birch_stairs 6
fill ~18~8~29 ~19~8~29 minecraft:birch_stairs 3
fill ~19~2~29 ~19~2~32 minecraft:stone 3
fill ~19~4~29 ~19~5~31 minecraft:fence 0
fill ~19~6~29 ~19~7~29 minecraft:fence 0
setblock ~19~20~29 minecraft:wooden_slab 8
setblock ~19~21~29 minecraft:wooden_slab 5
setblock ~19~23~29 minecraft:wall_banner 3
setblock ~19~24~29 minecraft:wooden_slab 8
setblock ~19~25~29 minecraft:wooden_slab 5
setblock ~19~27~29 minecraft:wall_banner 3
setblock ~19~28~29 minecraft:wooden_slab 8
setblock ~19~29~29 minecraft:double_wooden_slab 5
fill ~19~30~29 ~19~33~29 minecraft:jungle_trapdoor 0
fill ~20~1~29 ~21~1~29 minecraft:stone 3
setblock ~20~7~29 minecraft:log 0
setblock ~20~8~29 minecraft:log 0
setblock ~20~9~29 minecraft:log 0
fill ~21~0~29 ~27~0~29 minecraft:stonebrick 0
setblock ~21~2~29 minecraft:stone 3
setblock ~21~10~29 minecraft:wall_banner 3
fill ~21~30~29 ~21~30~30 minecraft:jungle_trapdoor 1
setblock ~21~39~29 minecraft:cauldron 0
fill ~22~1~29 ~27~2~29 minecraft:stonebrick 0
fill ~22~4~29 ~26~4~29 minecraft:wooden_slab 5
setblock ~22~11~29 minecraft:wall_banner 3
fill ~22~29~29 ~24~29~29 minecraft:dark_oak_trapdoor 2
setblock ~22~39~29 minecraft:trapdoor 1
setblock ~24~3~29 minecraft:double_wooden_slab 5
setblock ~25~15~29 minecraft:fence 1
fill ~25~30~29 ~25~30~30 minecraft:jungle_trapdoor 0
setblock ~26~14~29 minecraft:log 0
setblock ~26~15~29 minecraft:log 0
setblock ~26~16~29 minecraft:log 0
fill ~27~13~29 ~28~13~29 minecraft:fence 0
fill ~27~14~29 ~27~15~29 minecraft:fence 0
