fill ~-2 ~0 ~18 ~-2 ~4 ~18 log 0  
fill ~-2 ~0 ~22 ~-2 ~4 ~22 log 0  
fill ~2 ~0 ~18 ~2 ~4 ~18 log 0  
fill ~2 ~0 ~22 ~2 ~4 ~22 log 0  
fill ~5 ~0 ~10 ~5 ~1 ~10 sand 0  
fill ~5 ~0 ~11 ~5 ~1 ~11 sand 0  
fill ~5 ~0 ~12 ~5 ~1 ~12 sand 0  
fill ~5 ~0 ~13 ~5 ~1 ~13 sand 0  
fill ~5 ~0 ~14 ~29 ~0 ~14 stone 0  
fill ~5 ~0 ~15 ~5 ~0 ~15 sand 0  
fill ~6 ~0 ~9 ~6 ~1 ~9 sand 0  
fill ~6 ~0 ~10 ~9 ~0 ~10 stone 0  
fill ~6 ~0 ~11 ~22 ~0 ~11 stone 0  
fill ~6 ~0 ~12 ~24 ~0 ~12 stone 0  
fill ~6 ~0 ~13 ~27 ~0 ~13 stone 0  
fill ~6 ~0 ~15 ~31 ~0 ~15 stone 0  
fill ~6 ~0 ~18 ~6 ~4 ~18 log 0  
fill ~6 ~0 ~22 ~6 ~4 ~22 log 0  
fill ~7 ~0 ~7 ~7 ~0 ~7 sand 0  
fill ~7 ~0 ~8 ~7 ~1 ~8 sand 0  
fill ~7 ~0 ~9 ~9 ~0 ~9 stone 0  
fill ~7 ~0 ~16 ~27 ~0 ~16 stone 0  
fill ~7 ~0 ~17 ~7 ~2 ~17 cobblestone 0  
fill ~7 ~0 ~18 ~8 ~0 ~18 cobblestone 0  
fill ~7 ~0 ~19 ~7 ~2 ~19 cobblestone 0  
fill ~7 ~0 ~20 ~7 ~2 ~20 cobblestone 0  
fill ~7 ~0 ~21 ~7 ~1 ~21 cobblestone 0  
fill ~7 ~0 ~22 ~7 ~2 ~22 cobblestone 0  
fill ~7 ~0 ~23 ~7 ~2 ~23 cobblestone 0  
fill ~7 ~0 ~24 ~7 ~2 ~24 cobblestone 0  
fill ~7 ~0 ~25 ~7 ~2 ~25 cobblestone 0  
fill ~7 ~0 ~26 ~8 ~0 ~26 cobblestone 0  
fill ~8 ~0 ~5 ~8 ~0 ~5 stone 0  
fill ~8 ~0 ~6 ~8 ~0 ~6 dirt 0  
fill ~8 ~0 ~7 ~8 ~2 ~7 dirt 0  
fill ~8 ~0 ~8 ~8 ~1 ~8 stone 0  
fill ~8 ~0 ~17 ~27 ~0 ~17 stone 0  
fill ~8 ~0 ~19 ~27 ~0 ~19 stone 0  
fill ~8 ~0 ~20 ~11 ~0 ~20 stone 0  
fill ~8 ~0 ~21 ~8 ~0 ~21 stone 0  
fill ~8 ~0 ~22 ~9 ~0 ~22 stone 0  
fill ~8 ~0 ~23 ~12 ~0 ~23 stone 0  
fill ~8 ~0 ~24 ~12 ~0 ~24 stone 0  
fill ~8 ~0 ~25 ~13 ~0 ~25 stone 0  
fill ~9 ~0 ~2 ~9 ~0 ~2 stone 0  
fill ~9 ~0 ~3 ~12 ~0 ~3 stone 5  
fill ~9 ~0 ~4 ~12 ~0 ~4 stone 5  
fill ~9 ~0 ~5 ~12 ~0 ~5 stone 5  
fill ~9 ~0 ~6 ~9 ~0 ~7 iron_ore 0  
fill ~9 ~0 ~8 ~12 ~0 ~8 stone 5  
fill ~9 ~0 ~18 ~27 ~0 ~18 stone 0  
fill ~9 ~0 ~21 ~10 ~0 ~21 monster_egg 0  
fill ~9 ~0 ~26 ~14 ~0 ~26 stone 0  
fill ~9 ~0 ~27 ~12 ~0 ~27 stone 0  
fill ~9 ~0 ~28 ~12 ~0 ~28 stone 0  
fill ~10 ~0 ~-1 ~20 ~0 ~-1 stone 0  
fill ~10 ~0 ~0 ~20 ~0 ~0 stone 0  
fill ~10 ~0 ~1 ~20 ~0 ~1 stone 0  
fill ~10 ~0 ~2 ~11 ~0 ~2 stone 5  
fill ~10 ~0 ~6 ~12 ~0 ~6 stone 5  
fill ~10 ~0 ~7 ~12 ~0 ~7 stone 5  
fill ~10 ~0 ~9 ~11 ~0 ~9 stone 5  
fill ~10 ~0 ~10 ~11 ~0 ~10 stone 5  
fill ~10 ~0 ~22 ~10 ~1 ~22 monster_egg 0  
fill ~10 ~0 ~29 ~10 ~0 ~29 stone 0  
fill ~10 ~0 ~30 ~11 ~0 ~30 stone 3  
fill ~11 ~0 ~-2 ~12 ~0 ~-2 stone 0  
fill ~11 ~0 ~21 ~28 ~0 ~21 stone 0  
fill ~11 ~0 ~22 ~28 ~0 ~22 stone 0  
fill ~11 ~0 ~29 ~11 ~2 ~29 stone 3 
setblock ~11 ~0 ~31 stone 3  
fill ~12 ~0 ~2 ~20 ~0 ~2 stone 0  
fill ~12 ~0 ~9 ~23 ~0 ~9 stone 0  
fill ~12 ~0 ~10 ~24 ~0 ~10 stone 0  
fill ~12 ~0 ~20 ~12 ~1 ~20 chain_command_block 0  
fill ~12 ~0 ~29 ~15 ~0 ~29 stone 1  
fill ~12 ~0 ~30 ~15 ~0 ~30 stone 1  
fill ~12 ~0 ~31 ~15 ~0 ~31 stone 1  
fill ~13 ~0 ~-2 ~13 ~2 ~-2 dirt 0  
fill ~13 ~0 ~3 ~20 ~0 ~3 stone 0  
fill ~13 ~0 ~4 ~21 ~0 ~4 stone 0  
fill ~13 ~0 ~5 ~22 ~0 ~5 stone 0  
fill ~13 ~0 ~6 ~21 ~0 ~6 stone 0  
fill ~13 ~0 ~7 ~21 ~0 ~7 stone 0  
fill ~13 ~0 ~8 ~22 ~0 ~8 stone 0  
fill ~13 ~0 ~20 ~28 ~0 ~20 stone 0  
fill ~13 ~0 ~23 ~14 ~0 ~23 coal_ore 0  
fill ~13 ~0 ~24 ~15 ~0 ~24 coal_ore 0  
fill ~13 ~0 ~27 ~15 ~0 ~27 stone 1  
fill ~13 ~0 ~28 ~15 ~0 ~28 stone 1  
fill ~13 ~0 ~32 ~15 ~0 ~32 stone 1 
setblock ~14 ~0 ~-3 grass 0  
fill ~14 ~0 ~-2 ~18 ~0 ~-2 stone 0  
fill ~14 ~0 ~25 ~16 ~0 ~25 coal_ore 0  
fill ~15 ~0 ~-3 ~15 ~1 ~-3 stone 0  
fill ~15 ~0 ~23 ~28 ~0 ~23 stone 0  
fill ~15 ~0 ~26 ~16 ~0 ~26 coal_ore 0  
fill ~16 ~0 ~-3 ~18 ~0 ~-3 dirt 0  
fill ~16 ~0 ~24 ~23 ~0 ~24 stone 0  
fill ~16 ~0 ~27 ~16 ~3 ~27 stone 5  
fill ~16 ~0 ~28 ~27 ~0 ~28 stone 0  
fill ~16 ~0 ~29 ~26 ~0 ~29 stone 0  
fill ~16 ~0 ~30 ~25 ~0 ~30 stone 0  
fill ~16 ~0 ~31 ~22 ~0 ~31 stone 0  
fill ~16 ~0 ~32 ~19 ~0 ~32 stone 0  
fill ~17 ~0 ~25 ~22 ~0 ~25 stone 0  
fill ~17 ~0 ~26 ~29 ~0 ~26 stone 0  
fill ~17 ~0 ~27 ~28 ~0 ~27 stone 0 
setblock ~19 ~0 ~-3 grass 0  
fill ~19 ~0 ~-2 ~19 ~2 ~-2 dirt 0 
setblock ~20 ~0 ~-2 grass 0 
setblock ~21 ~0 ~2 grass 0 
setblock ~21 ~0 ~3 dirt 0  
fill ~22 ~0 ~6 ~22 ~1 ~6 coal_ore 0  
fill ~22 ~0 ~7 ~22 ~1 ~7 coal_ore 0  
fill ~23 ~0 ~7 ~23 ~0 ~7 dirt 0  
fill ~23 ~0 ~8 ~24 ~0 ~8 dirt 0  
fill ~23 ~0 ~11 ~23 ~4 ~11 dirt 0  
fill ~23 ~0 ~25 ~24 ~0 ~25 stone 3  
fill ~24 ~0 ~9 ~24 ~1 ~9 dirt 0  
fill ~24 ~0 ~11 ~24 ~0 ~11 stone 0  
fill ~24 ~0 ~24 ~24 ~0 ~24 stone 3 
setblock ~25 ~0 ~9 grass 0  
fill ~25 ~0 ~10 ~25 ~0 ~10 dirt 0  
fill ~25 ~0 ~11 ~26 ~0 ~11 dirt 0  
fill ~25 ~0 ~12 ~25 ~0 ~12 stone 5  
fill ~25 ~0 ~24 ~28 ~0 ~24 stone 0  
fill ~25 ~0 ~25 ~30 ~0 ~25 stone 0  
fill ~26 ~0 ~12 ~28 ~0 ~12 dirt 0 
setblock ~27 ~0 ~11 grass 0  
fill ~28 ~0 ~13 ~30 ~0 ~13 dirt 0  
fill ~28 ~0 ~16 ~29 ~0 ~16 stone 1  
fill ~28 ~0 ~17 ~30 ~0 ~17 stone 1  
fill ~28 ~0 ~18 ~29 ~0 ~18 stone 1  
fill ~28 ~0 ~19 ~28 ~0 ~19 stone 1 
setblock ~29 ~0 ~12 grass 0 
setblock ~29 ~0 ~19 stone 0  
fill ~29 ~0 ~20 ~30 ~0 ~20 stone 3  
fill ~29 ~0 ~21 ~30 ~0 ~21 stone 3  
fill ~29 ~0 ~22 ~30 ~0 ~22 stone 3  
fill ~29 ~0 ~23 ~30 ~0 ~23 stone 3  
fill ~29 ~0 ~24 ~29 ~3 ~24 stone 3  
fill ~30 ~0 ~14 ~31 ~0 ~14 dirt 0  
fill ~30 ~0 ~16 ~32 ~0 ~16 stone 0  
fill ~30 ~0 ~18 ~32 ~0 ~18 stone 0  
fill ~30 ~0 ~19 ~30 ~4 ~19 stone 3  
fill ~30 ~0 ~24 ~31 ~0 ~24 stone 0  
fill ~31 ~0 ~17 ~32 ~0 ~17 stone 0  
fill ~31 ~0 ~19 ~32 ~0 ~19 stone 0  
fill ~31 ~0 ~20 ~32 ~0 ~20 stone 0  
fill ~31 ~0 ~21 ~32 ~0 ~21 stone 0  
fill ~31 ~0 ~22 ~32 ~0 ~22 stone 0  
fill ~31 ~0 ~23 ~32 ~0 ~23 stone 0  
fill ~5 ~1 ~14 ~29 ~1 ~14 stone 0  
fill ~6 ~1 ~10 ~21 ~1 ~10 stone 0  
fill ~6 ~1 ~11 ~20 ~1 ~11 stone 0  
fill ~6 ~1 ~12 ~20 ~1 ~12 stone 0  
fill ~6 ~1 ~13 ~20 ~1 ~13 stone 0 
setblock ~6 ~1 ~15 sand 0  
fill ~7 ~1 ~9 ~22 ~1 ~9 stone 0  
fill ~7 ~1 ~15 ~31 ~1 ~15 stone 0  
fill ~7 ~1 ~16 ~31 ~1 ~16 stone 0  
fill ~7 ~1 ~18 ~8 ~1 ~18 cobblestone 0  
fill ~7 ~1 ~26 ~8 ~1 ~26 cobblestone 0 
setblock ~8 ~1 ~6 grass 0  
fill ~8 ~1 ~17 ~28 ~1 ~17 stone 0  
fill ~8 ~1 ~19 ~8 ~2 ~19 cobblestone 0  
fill ~8 ~1 ~20 ~8 ~2 ~20 cobblestone 0  
fill ~8 ~1 ~21 ~8 ~2 ~21 cobblestone 0  
fill ~8 ~1 ~22 ~9 ~1 ~22 stone 0  
fill ~8 ~1 ~23 ~8 ~2 ~23 cobblestone 0  
fill ~8 ~1 ~24 ~8 ~2 ~24 cobblestone 0  
fill ~8 ~1 ~25 ~8 ~2 ~25 cobblestone 0  
fill ~9 ~1 ~3 ~10 ~1 ~3 stone 0  
fill ~9 ~1 ~4 ~9 ~2 ~4 stone 0  
fill ~9 ~1 ~5 ~9 ~4 ~5 stone 0  
fill ~9 ~1 ~6 ~9 ~1 ~20 stone 0  
fill ~9 ~1 ~21 ~10 ~1 ~21 monster_egg 0  
fill ~9 ~1 ~23 ~27 ~1 ~23 stone 0  
fill ~9 ~1 ~24 ~9 ~2 ~24 stone 5  
fill ~9 ~1 ~25 ~11 ~1 ~25 stone 5  
fill ~9 ~1 ~26 ~16 ~1 ~26 stone 5  
fill ~9 ~1 ~27 ~17 ~1 ~27 stone 5  
fill ~10 ~1 ~0 ~20 ~1 ~0 stone 0  
fill ~10 ~1 ~1 ~20 ~1 ~1 stone 0  
fill ~10 ~1 ~2 ~20 ~1 ~2 stone 0  
fill ~10 ~1 ~4 ~11 ~1 ~4 stone 5  
fill ~10 ~1 ~5 ~11 ~1 ~5 stone 5  
fill ~10 ~1 ~6 ~11 ~1 ~6 stone 5  
fill ~10 ~1 ~7 ~11 ~1 ~7 stone 5  
fill ~10 ~1 ~8 ~22 ~1 ~8 stone 0  
fill ~10 ~1 ~18 ~28 ~1 ~18 stone 0  
fill ~10 ~1 ~19 ~27 ~1 ~19 stone 0  
fill ~10 ~1 ~20 ~11 ~1 ~20 stone 0  
fill ~10 ~1 ~24 ~27 ~1 ~24 stone 0  
fill ~10 ~1 ~28 ~12 ~1 ~28 stone 0 
setblock ~10 ~1 ~29 stone 3  
fill ~11 ~1 ~-1 ~19 ~1 ~-1 stone 0 
setblock ~11 ~1 ~3 stone 5  
fill ~11 ~1 ~21 ~27 ~1 ~21 stone 0  
fill ~11 ~1 ~22 ~27 ~1 ~22 stone 0 
setblock ~11 ~1 ~30 stone 3 
setblock ~12 ~1 ~-2 stone 0  
fill ~12 ~1 ~3 ~19 ~1 ~3 stone 0  
fill ~12 ~1 ~4 ~21 ~1 ~4 stone 0  
fill ~12 ~1 ~5 ~21 ~1 ~5 stone 0  
fill ~12 ~1 ~6 ~21 ~1 ~6 stone 0  
fill ~12 ~1 ~7 ~21 ~1 ~7 stone 0  
fill ~12 ~1 ~25 ~13 ~1 ~25 stone 0  
fill ~12 ~1 ~29 ~12 ~2 ~29 stone 3  
fill ~12 ~1 ~30 ~15 ~1 ~30 stone 1  
fill ~12 ~1 ~31 ~15 ~1 ~31 stone 1  
fill ~13 ~1 ~20 ~27 ~1 ~20 stone 0  
fill ~13 ~1 ~28 ~16 ~1 ~28 stone 5  
fill ~13 ~1 ~29 ~15 ~1 ~29 stone 1  
fill ~14 ~1 ~-2 ~18 ~1 ~-2 stone 0  
fill ~14 ~1 ~25 ~14 ~2 ~25 stone 5  
fill ~14 ~1 ~32 ~15 ~1 ~32 stone 1  
fill ~15 ~1 ~25 ~27 ~1 ~25 stone 0 
setblock ~16 ~1 ~-3 grass 0  
fill ~16 ~1 ~29 ~26 ~1 ~29 stone 0  
fill ~16 ~1 ~30 ~25 ~1 ~30 stone 0  
fill ~16 ~1 ~31 ~22 ~1 ~31 stone 0  
fill ~16 ~1 ~32 ~19 ~1 ~32 stone 0  
fill ~17 ~1 ~-3 ~18 ~1 ~-3 dirt 0  
fill ~17 ~1 ~26 ~28 ~1 ~26 stone 0  
fill ~17 ~1 ~28 ~27 ~1 ~28 stone 0  
fill ~18 ~1 ~27 ~28 ~1 ~27 stone 0  
fill ~20 ~1 ~3 ~20 ~3 ~3 dirt 0 
setblock ~21 ~1 ~3 grass 0  
fill ~21 ~1 ~11 ~25 ~1 ~11 dirt 0  
fill ~21 ~1 ~12 ~24 ~1 ~12 dirt 0  
fill ~21 ~1 ~13 ~23 ~1 ~13 dirt 0  
fill ~22 ~1 ~10 ~24 ~1 ~10 dirt 0 
setblock ~23 ~1 ~7 grass 0  
fill ~23 ~1 ~8 ~23 ~2 ~8 dirt 0  
fill ~23 ~1 ~9 ~23 ~4 ~9 dirt 0 
setblock ~24 ~1 ~8 grass 0  
fill ~24 ~1 ~13 ~27 ~1 ~13 stone 0 
setblock ~25 ~1 ~10 grass 0 
setblock ~25 ~1 ~12 stone 0 
setblock ~26 ~1 ~11 grass 0  
fill ~26 ~1 ~12 ~27 ~1 ~12 dirt 0 
setblock ~28 ~1 ~12 grass 0  
fill ~28 ~1 ~13 ~29 ~1 ~13 dirt 0  
fill ~28 ~1 ~19 ~31 ~1 ~19 stone 3  
fill ~28 ~1 ~20 ~31 ~1 ~20 stone 3  
fill ~28 ~1 ~21 ~31 ~1 ~21 stone 3  
fill ~28 ~1 ~22 ~31 ~1 ~22 stone 3  
fill ~28 ~1 ~23 ~30 ~1 ~23 stone 3  
fill ~28 ~1 ~24 ~28 ~3 ~24 stone 3  
fill ~28 ~1 ~25 ~29 ~1 ~25 stone 3  
fill ~29 ~1 ~17 ~31 ~1 ~17 stone 3  
fill ~29 ~1 ~18 ~30 ~1 ~18 stone 3 
setblock ~30 ~1 ~13 grass 0  
fill ~30 ~1 ~14 ~30 ~2 ~14 dirt 0  
fill ~30 ~1 ~24 ~30 ~2 ~24 stone 3 
setblock ~31 ~1 ~14 grass 0 
setblock ~31 ~1 ~18 stone 0  
fill ~31 ~1 ~23 ~31 ~0 ~23 stone 0  
fill ~32 ~1 ~20 ~32 ~1 ~22 stone 0 
setblock ~5 ~2 ~11 grass 0  
fill ~5 ~2 ~12 ~5 ~2 ~14 dirt 0 
setblock ~6 ~2 ~9 grass 0  
fill ~6 ~2 ~10 ~20 ~2 ~10 stone 0  
fill ~6 ~2 ~11 ~19 ~2 ~11 stone 0  
fill ~6 ~2 ~12 ~19 ~2 ~12 stone 0  
fill ~6 ~2 ~13 ~19 ~2 ~13 stone 0  
fill ~6 ~2 ~14 ~19 ~2 ~14 stone 0  
fill ~6 ~2 ~15 ~6 ~3 ~15 dirt 0 
setblock ~7 ~2 ~8 grass 0  
fill ~7 ~2 ~9 ~7 ~4 ~9 dirt 0  
fill ~7 ~2 ~15 ~20 ~2 ~15 stone 0  
fill ~7 ~2 ~16 ~28 ~2 ~16 stone 0  
fill ~7 ~2 ~18 ~8 ~2 ~18 cobblestone 0  
fill ~7 ~2 ~26 ~9 ~2 ~26 cobblestone 0  
fill ~8 ~2 ~8 ~8 ~4 ~8 dirt 0  
fill ~8 ~2 ~9 ~21 ~2 ~9 stone 0  
fill ~8 ~2 ~17 ~28 ~2 ~17 stone 0 
setblock ~8 ~2 ~22 cobblestone 0  
fill ~9 ~2 ~6 ~9 ~4 ~6 dirt 0  
fill ~9 ~2 ~7 ~22 ~2 ~7 stone 0  
fill ~9 ~2 ~8 ~22 ~2 ~8 stone 0  
fill ~9 ~2 ~18 ~28 ~2 ~18 stone 0  
fill ~9 ~2 ~19 ~27 ~2 ~19 stone 0  
fill ~9 ~2 ~20 ~11 ~2 ~20 stone 0  
fill ~9 ~2 ~21 ~27 ~2 ~21 stone 0  
fill ~9 ~2 ~22 ~10 ~2 ~22 stone 0 
setblock ~9 ~2 ~23 stone 5 
setblock ~9 ~2 ~25 cobblestone 0  
fill ~10 ~2 ~0 ~19 ~2 ~0 stone 0  
fill ~10 ~2 ~1 ~20 ~2 ~1 stone 0  
fill ~10 ~2 ~2 ~20 ~2 ~2 stone 0  
fill ~10 ~2 ~3 ~19 ~2 ~3 stone 0  
fill ~10 ~2 ~4 ~19 ~2 ~4 stone 0  
fill ~10 ~2 ~5 ~19 ~2 ~5 stone 0  
fill ~10 ~2 ~6 ~20 ~2 ~6 stone 0  
fill ~10 ~2 ~23 ~27 ~2 ~23 stone 0  
fill ~10 ~2 ~24 ~10 ~2 ~27 stone 5  
fill ~11 ~2 ~-1 ~19 ~2 ~-1 stone 0  
fill ~11 ~2 ~22 ~11 ~4 ~22 dirt 0  
fill ~11 ~2 ~24 ~27 ~2 ~24 stone 0  
fill ~11 ~2 ~25 ~15 ~2 ~25 stone 5  
fill ~11 ~2 ~26 ~16 ~2 ~26 stone 5  
fill ~11 ~2 ~27 ~17 ~2 ~27 stone 5  
fill ~11 ~2 ~28 ~16 ~2 ~28 stone 5 
setblock ~12 ~2 ~20 command_block 0  
fill ~12 ~2 ~22 ~27 ~2 ~22 stone 0 
setblock ~12 ~2 ~30 stone 3  
fill ~13 ~2 ~20 ~27 ~2 ~20 stone 0  
fill ~13 ~2 ~29 ~26 ~2 ~29 stone 0  
fill ~13 ~2 ~30 ~25 ~2 ~30 stone 0  
fill ~13 ~2 ~31 ~22 ~2 ~31 stone 0  
fill ~14 ~2 ~-2 ~18 ~2 ~-2 stone 0  
fill ~16 ~2 ~25 ~27 ~2 ~25 stone 0  
fill ~16 ~2 ~32 ~18 ~2 ~32 stone 0  
fill ~17 ~2 ~-3 ~18 ~2 ~-3 grass 0  
fill ~17 ~2 ~26 ~28 ~2 ~26 stone 0  
fill ~17 ~2 ~28 ~27 ~2 ~28 stone 0  
fill ~18 ~2 ~27 ~27 ~2 ~27 stone 0  
fill ~20 ~2 ~4 ~21 ~2 ~4 coal_ore 0  
fill ~20 ~2 ~5 ~21 ~2 ~5 coal_ore 0  
fill ~20 ~2 ~11 ~25 ~2 ~11 dirt 0  
fill ~20 ~2 ~12 ~26 ~2 ~12 dirt 0  
fill ~20 ~2 ~13 ~24 ~2 ~13 dirt 0  
fill ~20 ~2 ~14 ~23 ~2 ~14 dirt 0  
fill ~21 ~2 ~6 ~21 ~3 ~6 coal_ore 0  
fill ~21 ~2 ~10 ~24 ~2 ~10 dirt 0  
fill ~21 ~2 ~15 ~21 ~4 ~15 dirt 0  
fill ~22 ~2 ~9 ~22 ~3 ~9 dirt 0  
fill ~22 ~2 ~15 ~30 ~2 ~15 stone 0 
setblock ~24 ~2 ~9 grass 0  
fill ~24 ~2 ~14 ~28 ~2 ~14 stone 0  
fill ~25 ~2 ~13 ~26 ~2 ~13 stone 0 
setblock ~27 ~2 ~12 grass 0  
fill ~27 ~2 ~13 ~28 ~2 ~13 dirt 0  
fill ~28 ~2 ~19 ~31 ~2 ~19 stone 3  
fill ~28 ~2 ~20 ~31 ~2 ~20 stone 3  
fill ~28 ~2 ~21 ~31 ~2 ~21 stone 3  
fill ~28 ~2 ~22 ~31 ~2 ~22 stone 3  
fill ~28 ~2 ~23 ~31 ~2 ~23 stone 3  
fill ~28 ~2 ~25 ~29 ~2 ~25 stone 3 
setblock ~29 ~2 ~13 grass 0  
fill ~29 ~2 ~14 ~29 ~4 ~14 dirt 0  
fill ~29 ~2 ~16 ~31 ~2 ~16 stone 3  
fill ~29 ~2 ~17 ~31 ~2 ~17 stone 3  
fill ~29 ~2 ~18 ~31 ~2 ~18 stone 3  
fill ~-3 ~3 ~19 ~9 ~3 ~19 planks 0  
fill ~-3 ~3 ~20 ~17 ~3 ~20 planks 0  
fill ~-3 ~3 ~21 ~9 ~3 ~21 planks 0  
fill ~5 ~3 ~12 ~5 ~3 ~13 grass 0  
fill ~5 ~3 ~14 ~5 ~4 ~14 dirt 0  
fill ~6 ~3 ~10 ~6 ~5 ~10 dirt 0  
fill ~6 ~3 ~11 ~19 ~3 ~11 stone 0  
fill ~6 ~3 ~12 ~19 ~3 ~12 stone 0  
fill ~6 ~3 ~13 ~18 ~3 ~13 stone 0  
fill ~6 ~3 ~14 ~18 ~3 ~14 stone 0  
fill ~7 ~3 ~10 ~20 ~3 ~10 stone 0  
fill ~7 ~3 ~15 ~18 ~3 ~15 stone 0  
fill ~7 ~3 ~16 ~7 ~3 ~26 planks 0 
setblock ~8 ~3 ~7 grass 0  
fill ~8 ~3 ~9 ~21 ~3 ~9 stone 0  
fill ~8 ~3 ~16 ~28 ~3 ~16 stone 0  
fill ~8 ~3 ~17 ~8 ~3 ~26 planks 0  
fill ~9 ~3 ~7 ~22 ~3 ~7 stone 0  
fill ~9 ~3 ~8 ~22 ~3 ~8 stone 0  
fill ~9 ~3 ~17 ~28 ~3 ~17 stone 0 
setblock ~9 ~3 ~18 planks 0  
fill ~9 ~3 ~22 ~9 ~3 ~26 planks 0  
fill ~10 ~3 ~1 ~19 ~3 ~1 stone 0  
fill ~10 ~3 ~2 ~20 ~3 ~2 stone 0  
fill ~10 ~3 ~3 ~18 ~3 ~3 stone 0  
fill ~10 ~3 ~4 ~18 ~3 ~4 stone 0  
fill ~10 ~3 ~5 ~19 ~3 ~5 stone 0  
fill ~10 ~3 ~6 ~20 ~3 ~6 stone 0  
fill ~10 ~3 ~18 ~28 ~3 ~18 stone 0  
fill ~10 ~3 ~19 ~14 ~3 ~19 stone 0  
fill ~10 ~3 ~21 ~10 ~3 ~22 stone 0  
fill ~10 ~3 ~23 ~10 ~3 ~26 planks 0  
fill ~11 ~3 ~0 ~19 ~3 ~0 stone 0 
setblock ~11 ~3 ~21 dirt 0  
fill ~11 ~3 ~23 ~18 ~3 ~23 stone 0  
fill ~11 ~3 ~24 ~11 ~3 ~27 stone 5  
fill ~11 ~3 ~28 ~13 ~3 ~28 stone 0  
fill ~12 ~3 ~-1 ~19 ~3 ~-1 stone 0  
fill ~12 ~3 ~21 ~14 ~3 ~21 stone 0  
fill ~12 ~3 ~22 ~27 ~3 ~22 stone 0  
fill ~12 ~3 ~24 ~12 ~5 ~24 dirt 0  
fill ~12 ~3 ~25 ~12 ~4 ~25 stone 5  
fill ~12 ~3 ~26 ~16 ~3 ~26 stone 5  
fill ~12 ~3 ~27 ~16 ~3 ~27 stone 5  
fill ~12 ~3 ~29 ~26 ~3 ~29 stone 0 
setblock ~13 ~3 ~-2 grass 0  
fill ~13 ~3 ~24 ~18 ~3 ~24 stone 0  
fill ~13 ~3 ~25 ~18 ~3 ~25 stone 0  
fill ~13 ~3 ~30 ~25 ~3 ~30 stone 0  
fill ~14 ~3 ~-2 ~18 ~3 ~-2 stone 0 
setblock ~14 ~3 ~28 stone 5  
fill ~14 ~3 ~31 ~21 ~3 ~31 stone 0  
fill ~15 ~3 ~19 ~16 ~3 ~19 planks 0  
fill ~15 ~3 ~21 ~17 ~3 ~21 planks 0  
fill ~15 ~3 ~28 ~27 ~3 ~28 stone 0  
fill ~17 ~3 ~19 ~27 ~3 ~19 stone 0  
fill ~17 ~3 ~26 ~20 ~3 ~26 stone 0  
fill ~17 ~3 ~27 ~21 ~3 ~27 stone 0  
fill ~17 ~3 ~32 ~18 ~3 ~32 stone 0  
fill ~18 ~3 ~20 ~27 ~3 ~20 stone 0  
fill ~18 ~3 ~21 ~27 ~3 ~21 stone 0 
setblock ~19 ~3 ~-2 grass 0  
fill ~19 ~3 ~3 ~19 ~4 ~3 coal_ore 0  
fill ~19 ~3 ~4 ~20 ~3 ~4 coal_ore 0  
fill ~19 ~3 ~13 ~24 ~3 ~13 dirt 0  
fill ~19 ~3 ~14 ~23 ~3 ~14 dirt 0  
fill ~19 ~3 ~15 ~21 ~3 ~15 dirt 0  
fill ~19 ~3 ~23 ~20 ~3 ~23 stone 3  
fill ~19 ~3 ~24 ~21 ~3 ~24 stone 3  
fill ~19 ~3 ~25 ~21 ~3 ~25 stone 3  
fill ~20 ~3 ~5 ~21 ~3 ~5 coal_ore 0  
fill ~20 ~3 ~11 ~24 ~3 ~11 dirt 0  
fill ~20 ~3 ~12 ~25 ~3 ~12 dirt 0  
fill ~21 ~3 ~10 ~24 ~3 ~10 dirt 0  
fill ~21 ~3 ~23 ~27 ~3 ~23 stone 0  
fill ~21 ~3 ~26 ~23 ~3 ~26 stone 3  
fill ~22 ~3 ~15 ~28 ~3 ~15 stone 0  
fill ~22 ~3 ~24 ~27 ~3 ~24 stone 0  
fill ~22 ~3 ~25 ~28 ~3 ~25 stone 0  
fill ~22 ~3 ~27 ~22 ~8 ~27 stone 3 
setblock ~23 ~3 ~8 grass 0  
fill ~23 ~3 ~27 ~27 ~3 ~27 stone 0  
fill ~24 ~3 ~14 ~28 ~3 ~14 stone 0  
fill ~24 ~3 ~26 ~28 ~3 ~26 stone 0 
setblock ~25 ~3 ~11 grass 0  
fill ~25 ~3 ~13 ~26 ~3 ~13 stone 0 
setblock ~26 ~3 ~12 grass 0  
fill ~27 ~3 ~13 ~27 ~4 ~13 dirt 0 
setblock ~28 ~3 ~13 grass 0  
fill ~28 ~3 ~19 ~31 ~3 ~19 stone 3  
fill ~28 ~3 ~20 ~31 ~3 ~20 stone 3  
fill ~28 ~3 ~21 ~31 ~3 ~21 stone 3  
fill ~28 ~3 ~22 ~31 ~3 ~22 stone 3  
fill ~28 ~3 ~23 ~30 ~3 ~23 stone 3  
fill ~29 ~3 ~15 ~29 ~5 ~15 dirt 0  
fill ~29 ~3 ~16 ~30 ~3 ~16 stone 3  
fill ~29 ~3 ~17 ~30 ~3 ~17 stone 3  
fill ~29 ~3 ~18 ~31 ~3 ~18 stone 3 
setblock ~30 ~3 ~14 grass 0  
fill ~30 ~3 ~15 ~30 ~4 ~15 stone 0 
setblock ~5 ~4 ~13 tallgrass 1  
fill ~6 ~4 ~11 ~20 ~4 ~11 stone 0  
fill ~6 ~4 ~12 ~19 ~4 ~12 stone 0  
fill ~6 ~4 ~13 ~18 ~4 ~13 stone 0  
fill ~6 ~4 ~14 ~18 ~4 ~14 stone 0 
setblock ~6 ~4 ~15 grass 0  
fill ~7 ~4 ~10 ~21 ~4 ~10 stone 0  
fill ~7 ~4 ~15 ~7 ~6 ~15 dirt 0  
fill ~7 ~4 ~16 ~7 ~4 ~19 spruce_fence 0  
fill ~7 ~4 ~21 ~7 ~4 ~23 spruce_fence 0  
fill ~8 ~4 ~9 ~8 ~6 ~9 dirt 0  
fill ~8 ~4 ~15 ~18 ~4 ~15 stone 0  
fill ~8 ~4 ~16 ~30 ~4 ~16 stone 0  
fill ~9 ~4 ~7 ~9 ~6 ~7 dirt 0  
fill ~9 ~4 ~8 ~22 ~4 ~8 stone 0  
fill ~9 ~4 ~9 ~22 ~4 ~9 stone 0  
fill ~9 ~4 ~17 ~15 ~4 ~17 stone 0 
setblock ~9 ~4 ~24 trapdoor 4 
setblock ~9 ~4 ~25 wooden_slab 0 
setblock ~9 ~4 ~26 trapdoor 5  
fill ~10 ~4 ~2 ~17 ~4 ~2 stone 0  
fill ~10 ~4 ~3 ~18 ~4 ~3 stone 0  
fill ~10 ~4 ~4 ~18 ~4 ~4 stone 0  
fill ~10 ~4 ~5 ~19 ~4 ~5 stone 0  
fill ~10 ~4 ~6 ~21 ~4 ~6 stone 0  
fill ~10 ~4 ~7 ~21 ~4 ~7 stone 0  
fill ~10 ~4 ~18 ~13 ~4 ~18 stone 0  
fill ~10 ~4 ~19 ~10 ~6 ~19 log 0 
setblock ~10 ~4 ~20 spruce_door 2  
fill ~10 ~4 ~21 ~10 ~6 ~21 log 0 
setblock ~10 ~4 ~22 stone 0 
setblock ~10 ~4 ~23 chest 4  
fill ~10 ~4 ~25 ~10 ~5 ~25 trapdoor 7  
fill ~11 ~4 ~1 ~16 ~4 ~1 stone 0  
fill ~11 ~4 ~19 ~13 ~4 ~19 stone 0  
fill ~11 ~4 ~21 ~13 ~4 ~21 stone 0  
fill ~11 ~4 ~23 ~11 ~5 ~23 stone 0  
fill ~11 ~4 ~24 ~11 ~4 ~23 stone 0  
fill ~11 ~4 ~25 ~11 ~4 ~26 stone 5  
fill ~12 ~4 ~0 ~16 ~4 ~0 stone 0 
setblock ~12 ~4 ~20 wooden_pressure_plate 0  
fill ~12 ~4 ~22 ~13 ~4 ~22 stone 3  
fill ~12 ~4 ~23 ~12 ~6 ~23 dirt 0  
fill ~12 ~4 ~26 ~12 ~1 ~26 stone 5  
fill ~12 ~4 ~27 ~12 ~1 ~27 stone 5  
fill ~12 ~4 ~28 ~21 ~4 ~28 stone 0  
fill ~13 ~4 ~-1 ~15 ~4 ~-1 stone 0  
fill ~13 ~4 ~23 ~16 ~4 ~23 stone 0  
fill ~13 ~4 ~24 ~17 ~4 ~24 stone 0  
fill ~13 ~4 ~25 ~17 ~4 ~25 stone 0  
fill ~13 ~4 ~26 ~18 ~4 ~26 stone 0  
fill ~13 ~4 ~27 ~20 ~4 ~27 stone 0  
fill ~13 ~4 ~29 ~25 ~4 ~29 stone 0  
fill ~14 ~4 ~-2 ~15 ~4 ~-2 stone 0  
fill ~14 ~4 ~18 ~14 ~7 ~18 stone 3  
fill ~14 ~4 ~19 ~14 ~30 ~19 bone_block 0  
fill ~14 ~4 ~21 ~14 ~30 ~21 bone_block 0  
fill ~14 ~4 ~22 ~14 ~30 ~22 stone 0  
fill ~14 ~4 ~30 ~23 ~4 ~30 stone 0  
fill ~15 ~4 ~18 ~17 ~4 ~18 bone_block 0  
fill ~15 ~4 ~22 ~17 ~4 ~22 bone_block 0  
fill ~16 ~4 ~-2 ~18 ~4 ~-2 stone 3  
fill ~16 ~4 ~-1 ~18 ~4 ~-1 stone 3  
fill ~16 ~4 ~17 ~16 ~7 ~17 stone 3  
fill ~16 ~4 ~31 ~21 ~4 ~31 stone 0  
fill ~17 ~4 ~0 ~18 ~4 ~0 stone 3  
fill ~17 ~4 ~1 ~18 ~4 ~1 stone 3  
fill ~17 ~4 ~17 ~29 ~4 ~17 stone 0 
setblock ~17 ~4 ~19 wooden_slab 0 
setblock ~17 ~4 ~20 wooden_slab 8  
fill ~17 ~4 ~23 ~23 ~4 ~23 stone 3  
fill ~18 ~4 ~2 ~18 ~8 ~2 stone 3  
fill ~18 ~4 ~18 ~29 ~4 ~18 stone 0  
fill ~18 ~4 ~19 ~18 ~30 ~19 bone_block 0  
fill ~18 ~4 ~20 ~18 ~30 ~20 bone_block 0  
fill ~18 ~4 ~21 ~18 ~30 ~21 bone_block 0  
fill ~18 ~4 ~22 ~19 ~4 ~22 stone 3  
fill ~18 ~4 ~24 ~25 ~4 ~24 stone 3  
fill ~18 ~4 ~25 ~25 ~4 ~25 stone 3  
fill ~18 ~4 ~32 ~18 ~8 ~32 stone 0 
setblock ~19 ~4 ~-2 tallgrass 1  
fill ~19 ~4 ~-1 ~19 ~4 ~2 stone 0  
fill ~19 ~4 ~4 ~20 ~4 ~4 coal_ore 0  
fill ~19 ~4 ~13 ~23 ~4 ~13 dirt 0  
fill ~19 ~4 ~14 ~22 ~4 ~14 dirt 0  
fill ~19 ~4 ~15 ~21 ~4 ~15 dirt 0  
fill ~19 ~4 ~19 ~28 ~4 ~19 stone 0  
fill ~19 ~4 ~20 ~28 ~4 ~20 stone 0  
fill ~19 ~4 ~21 ~28 ~4 ~21 stone 0  
fill ~19 ~4 ~26 ~25 ~4 ~26 stone 3 
setblock ~20 ~4 ~3 grass 0  
fill ~20 ~4 ~5 ~20 ~2 ~5 coal_ore 0  
fill ~20 ~4 ~12 ~25 ~4 ~12 dirt 0  
fill ~20 ~4 ~22 ~31 ~4 ~22 stone 0  
fill ~21 ~4 ~11 ~24 ~4 ~11 dirt 0  
fill ~21 ~4 ~27 ~21 ~7 ~27 stone 3  
fill ~22 ~4 ~5 ~22 ~14 ~5 vine 2  
fill ~22 ~4 ~6 ~22 ~14 ~6 vine 2  
fill ~22 ~4 ~7 ~22 ~4 ~5 vine 2  
fill ~22 ~4 ~10 ~23 ~4 ~10 dirt 0  
fill ~22 ~4 ~15 ~28 ~4 ~15 stone 0  
fill ~22 ~4 ~28 ~25 ~4 ~28 stone 3  
fill ~23 ~4 ~14 ~24 ~4 ~14 stone 0  
fill ~23 ~4 ~27 ~25 ~4 ~27 stone 3 
setblock ~24 ~4 ~10 grass 0  
fill ~24 ~4 ~13 ~25 ~4 ~13 stone 5  
fill ~24 ~4 ~23 ~30 ~4 ~23 stone 0  
fill ~24 ~4 ~30 ~25 ~4 ~30 coal_ore 0  
fill ~25 ~4 ~5 ~25 ~16 ~5 vine 2  
fill ~25 ~4 ~14 ~25 ~5 ~14 stone 5  
fill ~26 ~4 ~13 ~26 ~6 ~13 dirt 0  
fill ~26 ~4 ~14 ~27 ~4 ~14 stone 0  
fill ~26 ~4 ~24 ~29 ~4 ~24 stone 0  
fill ~26 ~4 ~25 ~28 ~4 ~25 stone 0  
fill ~26 ~4 ~26 ~27 ~4 ~26 stone 0  
fill ~26 ~4 ~27 ~27 ~4 ~27 stone 0  
fill ~26 ~4 ~28 ~26 ~4 ~14 stone 0  
fill ~26 ~4 ~29 ~26 ~6 ~29 gravel 0  
fill ~28 ~4 ~14 ~28 ~6 ~14 dirt 0  
fill ~29 ~4 ~19 ~29 ~4 ~21 stone 3  
fill ~30 ~4 ~17 ~30 ~4 ~21 stone 3  
fill ~31 ~4 ~20 ~31 ~4 ~22 stone 0 
setblock ~-2 ~5 ~18 torch 5 
setblock ~-2 ~5 ~22 torch 5 
setblock ~5 ~5 ~14 grass 0  
fill ~6 ~5 ~11 ~6 ~0 ~11 stone 0  
fill ~6 ~5 ~12 ~6 ~0 ~12 stone 0  
fill ~6 ~5 ~13 ~20 ~5 ~13 stone 0  
fill ~6 ~5 ~14 ~6 ~7 ~14 dirt 0 
setblock ~6 ~5 ~15 tallgrass 1 
setblock ~7 ~5 ~9 grass 0  
fill ~7 ~5 ~10 ~9 ~5 ~10 stone 3  
fill ~7 ~5 ~11 ~8 ~5 ~11 stone 3  
fill ~7 ~5 ~12 ~8 ~5 ~12 stone 3  
fill ~7 ~5 ~14 ~20 ~5 ~14 stone 0 
setblock ~7 ~5 ~19 torch 5 
setblock ~7 ~5 ~21 torch 5 
setblock ~8 ~5 ~8 grass 0  
fill ~8 ~5 ~15 ~27 ~5 ~15 stone 0  
fill ~8 ~5 ~16 ~30 ~5 ~16 stone 0 
setblock ~9 ~5 ~6 grass 0  
fill ~9 ~5 ~8 ~9 ~7 ~8 dirt 0  
fill ~9 ~5 ~9 ~9 ~6 ~9 stone 3  
fill ~9 ~5 ~11 ~22 ~5 ~11 stone 0  
fill ~9 ~5 ~12 ~20 ~5 ~12 stone 0  
fill ~9 ~5 ~17 ~13 ~5 ~17 stone 0  
fill ~10 ~5 ~3 ~16 ~5 ~3 stone 0  
fill ~10 ~5 ~4 ~17 ~5 ~4 stone 0  
fill ~10 ~5 ~5 ~20 ~5 ~5 stone 0  
fill ~10 ~5 ~6 ~20 ~5 ~6 stone 0  
fill ~10 ~5 ~7 ~21 ~5 ~7 stone 0  
fill ~10 ~5 ~8 ~22 ~5 ~8 stone 0  
fill ~10 ~5 ~9 ~22 ~5 ~9 stone 0  
fill ~10 ~5 ~10 ~22 ~5 ~10 stone 0  
fill ~10 ~5 ~18 ~13 ~5 ~18 stone 0 
setblock ~10 ~5 ~20 spruce_door 8  
fill ~11 ~5 ~2 ~15 ~5 ~2 stone 0  
fill ~11 ~5 ~19 ~13 ~5 ~19 stone 0  
fill ~11 ~5 ~21 ~13 ~5 ~21 stone 0  
fill ~11 ~5 ~22 ~11 ~6 ~22 stone 0 
setblock ~11 ~5 ~26 torch 5  
fill ~12 ~5 ~1 ~15 ~5 ~1 stone 0  
fill ~12 ~5 ~22 ~12 ~7 ~22 dirt 0  
fill ~12 ~5 ~25 ~17 ~5 ~25 stone 0  
fill ~12 ~5 ~26 ~18 ~5 ~26 stone 0  
fill ~13 ~5 ~0 ~15 ~5 ~0 stone 0  
fill ~13 ~5 ~22 ~13 ~7 ~22 stone 3  
fill ~13 ~5 ~23 ~16 ~5 ~23 stone 0  
fill ~13 ~5 ~24 ~17 ~5 ~24 stone 0  
fill ~13 ~5 ~27 ~19 ~5 ~27 stone 0  
fill ~14 ~5 ~-1 ~14 ~6 ~-1 stone 0  
fill ~14 ~5 ~17 ~18 ~5 ~17 stone 3  
fill ~14 ~5 ~28 ~20 ~5 ~28 stone 0  
fill ~14 ~5 ~29 ~23 ~5 ~29 stone 0  
fill ~15 ~5 ~-2 ~18 ~5 ~-2 stone 3  
fill ~15 ~5 ~-1 ~18 ~5 ~-1 stone 3  
fill ~15 ~5 ~18 ~17 ~5 ~18 bone_block 0  
fill ~15 ~5 ~22 ~17 ~5 ~22 bone_block 0  
fill ~15 ~5 ~30 ~23 ~5 ~30 stone 0  
fill ~16 ~5 ~0 ~19 ~5 ~0 stone 3  
fill ~16 ~5 ~1 ~19 ~5 ~1 stone 3  
fill ~16 ~5 ~2 ~19 ~5 ~2 stone 3 
setblock ~16 ~5 ~19 torch 3 
setblock ~16 ~5 ~21 wooden_slab 8  
fill ~16 ~5 ~31 ~20 ~5 ~31 stone 0  
fill ~17 ~5 ~3 ~19 ~5 ~3 stone 3 
setblock ~17 ~5 ~21 wooden_slab 0  
fill ~17 ~5 ~23 ~25 ~5 ~23 stone 3  
fill ~18 ~5 ~4 ~19 ~5 ~4 stone 3  
fill ~18 ~5 ~18 ~18 ~6 ~18 stone 3  
fill ~18 ~5 ~22 ~23 ~5 ~22 stone 3  
fill ~18 ~5 ~24 ~26 ~5 ~24 stone 3  
fill ~18 ~5 ~25 ~26 ~5 ~25 stone 3  
fill ~19 ~5 ~17 ~30 ~5 ~17 stone 0  
fill ~19 ~5 ~18 ~30 ~5 ~18 stone 0  
fill ~19 ~5 ~19 ~30 ~5 ~19 stone 0  
fill ~19 ~5 ~20 ~30 ~5 ~20 stone 0  
fill ~19 ~5 ~21 ~30 ~5 ~21 stone 0  
fill ~19 ~5 ~26 ~26 ~5 ~26 stone 3 
setblock ~20 ~5 ~4 stone 0 
setblock ~20 ~5 ~27 stone 3  
fill ~21 ~5 ~12 ~22 ~5 ~12 dirt 0  
fill ~21 ~5 ~13 ~22 ~5 ~13 dirt 0  
fill ~21 ~5 ~14 ~21 ~5 ~12 dirt 0  
fill ~21 ~5 ~28 ~25 ~5 ~28 stone 3  
fill ~22 ~5 ~14 ~24 ~5 ~14 stone 0 
setblock ~23 ~5 ~9 grass 0  
fill ~23 ~5 ~10 ~23 ~5 ~11 stone 5  
fill ~23 ~5 ~12 ~23 ~13 ~12 stone 0  
fill ~23 ~5 ~13 ~24 ~5 ~13 stone 0  
fill ~23 ~5 ~27 ~25 ~5 ~27 stone 3  
fill ~24 ~5 ~11 ~24 ~5 ~12 stone 5  
fill ~24 ~5 ~22 ~30 ~5 ~22 stone 0  
fill ~24 ~5 ~29 ~24 ~6 ~29 stone 3  
fill ~24 ~5 ~30 ~25 ~5 ~30 gravel 0 
setblock ~25 ~5 ~12 dirt 0 
setblock ~25 ~5 ~13 stone 5  
fill ~25 ~5 ~29 ~25 ~7 ~29 gravel 0  
fill ~26 ~5 ~14 ~27 ~5 ~14 stone 0  
fill ~26 ~5 ~23 ~30 ~5 ~23 stone 0  
fill ~26 ~5 ~27 ~27 ~5 ~27 stone 0  
fill ~26 ~5 ~28 ~26 ~7 ~28 gravel 0 
setblock ~27 ~5 ~13 grass 0  
fill ~27 ~5 ~24 ~28 ~5 ~24 stone 0  
fill ~27 ~5 ~25 ~27 ~5 ~27 stone 0  
fill ~28 ~5 ~15 ~28 ~7 ~15 dirt 0 
setblock ~28 ~5 ~25 vine 4 
setblock ~29 ~5 ~14 grass 0  
fill ~29 ~5 ~24 ~29 ~6 ~24 vine 2 
setblock ~5 ~6 ~14 tallgrass 1 
setblock ~6 ~6 ~10 grass 0  
fill ~6 ~6 ~11 ~9 ~6 ~11 stone 3  
fill ~6 ~6 ~12 ~9 ~6 ~12 stone 3  
fill ~6 ~6 ~13 ~6 ~8 ~13 stone 0 
setblock ~7 ~6 ~9 tallgrass 1  
fill ~7 ~6 ~10 ~7 ~7 ~10 stone 3  
fill ~7 ~6 ~13 ~7 ~7 ~13 stone 3  
fill ~7 ~6 ~14 ~27 ~6 ~14 stone 0 
setblock ~8 ~6 ~8 tallgrass 1  
fill ~8 ~6 ~10 ~8 ~8 ~10 dirt 0  
fill ~8 ~6 ~13 ~25 ~6 ~13 stone 0  
fill ~8 ~6 ~15 ~27 ~6 ~15 stone 0  
fill ~8 ~6 ~16 ~29 ~6 ~16 stone 0 
setblock ~9 ~6 ~6 tallgrass 1  
fill ~9 ~6 ~10 ~9 ~8 ~10 stone 3  
fill ~9 ~6 ~17 ~13 ~6 ~17 stone 0  
fill ~10 ~6 ~3 ~16 ~6 ~3 stone 0  
fill ~10 ~6 ~4 ~16 ~6 ~4 stone 0  
fill ~10 ~6 ~5 ~17 ~6 ~5 stone 0  
fill ~10 ~6 ~6 ~20 ~6 ~6 stone 0  
fill ~10 ~6 ~7 ~21 ~6 ~7 stone 0  
fill ~10 ~6 ~8 ~22 ~6 ~8 stone 0  
fill ~10 ~6 ~9 ~22 ~6 ~9 stone 0  
fill ~10 ~6 ~10 ~23 ~6 ~10 stone 0  
fill ~10 ~6 ~11 ~24 ~6 ~11 stone 0  
fill ~10 ~6 ~12 ~24 ~6 ~12 stone 0  
fill ~10 ~6 ~18 ~13 ~6 ~18 stone 0 
setblock ~10 ~6 ~20 log 0  
fill ~11 ~6 ~2 ~15 ~6 ~2 stone 0  
fill ~11 ~6 ~19 ~12 ~6 ~19 stone 0  
fill ~11 ~6 ~20 ~11 ~7 ~20 stone 0  
fill ~11 ~6 ~21 ~11 ~4 ~21 stone 0  
fill ~12 ~6 ~1 ~15 ~6 ~1 stone 0 
setblock ~12 ~6 ~20 lit_redstone_lamp 0  
fill ~12 ~6 ~21 ~13 ~6 ~21 stone 3 
setblock ~12 ~6 ~24 grass 0  
fill ~12 ~6 ~25 ~18 ~6 ~25 stone 0  
fill ~13 ~6 ~0 ~14 ~6 ~0 stone 0 
setblock ~13 ~6 ~19 stone 3  
fill ~13 ~6 ~20 ~13 ~27 ~20 stone 0  
fill ~13 ~6 ~23 ~17 ~6 ~23 stone 0  
fill ~13 ~6 ~24 ~17 ~6 ~24 stone 0  
fill ~13 ~6 ~26 ~19 ~6 ~26 stone 0  
fill ~13 ~6 ~27 ~20 ~6 ~27 stone 0  
fill ~14 ~6 ~17 ~18 ~6 ~17 stone 3  
fill ~14 ~6 ~20 ~14 ~30 ~20 bone_block 0  
fill ~14 ~6 ~28 ~21 ~6 ~28 stone 0  
fill ~14 ~6 ~29 ~23 ~6 ~29 stone 0  
fill ~15 ~6 ~-1 ~18 ~6 ~-1 stone 3  
fill ~15 ~6 ~0 ~18 ~6 ~0 stone 3  
fill ~15 ~6 ~18 ~17 ~6 ~18 bone_block 0 
setblock ~15 ~6 ~20 wooden_slab 8 
setblock ~15 ~6 ~21 wooden_slab 0  
fill ~15 ~6 ~22 ~17 ~6 ~22 bone_block 0  
fill ~15 ~6 ~30 ~23 ~6 ~30 stone 0  
fill ~16 ~6 ~1 ~19 ~6 ~1 stone 3  
fill ~16 ~6 ~2 ~19 ~6 ~2 stone 3  
fill ~17 ~6 ~-2 ~18 ~6 ~-2 stone 3  
fill ~17 ~6 ~3 ~19 ~6 ~3 stone 3  
fill ~17 ~6 ~4 ~19 ~6 ~4 stone 3  
fill ~17 ~6 ~31 ~20 ~6 ~31 stone 0  
fill ~18 ~6 ~5 ~19 ~6 ~5 stone 3  
fill ~18 ~6 ~22 ~18 ~12 ~22 stone 0  
fill ~18 ~6 ~23 ~25 ~6 ~23 stone 3  
fill ~18 ~6 ~24 ~26 ~6 ~24 stone 3  
fill ~19 ~6 ~17 ~30 ~6 ~17 stone 0  
fill ~19 ~6 ~18 ~30 ~6 ~18 stone 0  
fill ~19 ~6 ~19 ~30 ~6 ~19 stone 0  
fill ~19 ~6 ~20 ~30 ~6 ~20 stone 0  
fill ~19 ~6 ~21 ~30 ~6 ~21 stone 0  
fill ~19 ~6 ~22 ~23 ~6 ~22 stone 3  
fill ~19 ~6 ~25 ~27 ~6 ~25 stone 3 
setblock ~20 ~6 ~5 stone 0  
fill ~20 ~6 ~26 ~27 ~6 ~26 stone 3  
fill ~22 ~6 ~28 ~25 ~6 ~28 stone 3  
fill ~23 ~6 ~27 ~26 ~6 ~27 stone 3  
fill ~24 ~6 ~22 ~30 ~6 ~22 stone 0  
fill ~24 ~6 ~30 ~25 ~6 ~30 gravel 0 
setblock ~25 ~6 ~12 grass 0  
fill ~26 ~6 ~23 ~29 ~6 ~23 stone 0  
fill ~27 ~6 ~24 ~28 ~6 ~24 stone 0  
fill ~28 ~6 ~25 ~28 ~8 ~25 vine 6 
setblock ~29 ~6 ~15 grass 0 
setblock ~6 ~7 ~10 tallgrass 1  
fill ~6 ~7 ~12 ~9 ~7 ~12 stone 3  
fill ~7 ~7 ~11 ~9 ~7 ~11 stone 3  
fill ~7 ~7 ~14 ~26 ~7 ~14 stone 0 
setblock ~7 ~7 ~15 grass 0 
setblock ~8 ~7 ~9 grass 0  
fill ~8 ~7 ~13 ~25 ~7 ~13 stone 0  
fill ~8 ~7 ~15 ~27 ~7 ~15 stone 0 
setblock ~9 ~7 ~7 grass 0  
fill ~9 ~7 ~9 ~9 ~9 ~9 dirt 0  
fill ~9 ~7 ~16 ~29 ~7 ~16 stone 0  
fill ~9 ~7 ~17 ~15 ~7 ~17 stone 0  
fill ~10 ~7 ~4 ~16 ~7 ~4 stone 0  
fill ~10 ~7 ~5 ~18 ~7 ~5 stone 0  
fill ~10 ~7 ~6 ~20 ~7 ~6 stone 0  
fill ~10 ~7 ~7 ~14 ~7 ~7 stone 0  
fill ~10 ~7 ~8 ~14 ~7 ~8 stone 0  
fill ~10 ~7 ~9 ~22 ~7 ~9 stone 0  
fill ~10 ~7 ~10 ~23 ~7 ~10 stone 0  
fill ~10 ~7 ~11 ~23 ~7 ~11 stone 0  
fill ~10 ~7 ~12 ~24 ~7 ~12 stone 0  
fill ~10 ~7 ~18 ~13 ~7 ~18 stone 0  
fill ~10 ~7 ~19 ~13 ~7 ~19 stone 0  
fill ~10 ~7 ~20 ~10 ~7 ~4 stone 0  
fill ~10 ~7 ~21 ~11 ~7 ~21 grass 0  
fill ~11 ~7 ~3 ~16 ~7 ~3 stone 0  
fill ~12 ~7 ~2 ~15 ~7 ~2 stone 0 
setblock ~12 ~7 ~20 redstone_block 0  
fill ~12 ~7 ~21 ~12 ~9 ~21 dirt 0 
setblock ~12 ~7 ~23 grass 0 
setblock ~12 ~7 ~24 tallgrass 1  
fill ~13 ~7 ~1 ~15 ~7 ~1 stone 0 
setblock ~13 ~7 ~21 stone 3  
fill ~13 ~7 ~23 ~19 ~7 ~23 stone 0  
fill ~13 ~7 ~24 ~13 ~9 ~24 dirt 0  
fill ~13 ~7 ~25 ~19 ~7 ~25 stone 0  
fill ~13 ~7 ~26 ~19 ~7 ~26 stone 0  
fill ~14 ~7 ~0 ~15 ~7 ~0 stone 0  
fill ~14 ~7 ~24 ~19 ~7 ~24 stone 0  
fill ~14 ~7 ~27 ~20 ~7 ~27 stone 0  
fill ~14 ~7 ~28 ~17 ~7 ~28 stone 5  
fill ~14 ~7 ~29 ~19 ~7 ~29 stone 5  
fill ~15 ~7 ~7 ~15 ~9 ~7 stone 1  
fill ~15 ~7 ~8 ~15 ~9 ~8 stone 1  
fill ~15 ~7 ~18 ~17 ~7 ~18 bone_block 0 
setblock ~15 ~7 ~19 wooden_slab 0  
fill ~15 ~7 ~22 ~17 ~7 ~22 bone_block 0  
fill ~15 ~7 ~30 ~20 ~7 ~30 stone 5  
fill ~16 ~7 ~0 ~18 ~7 ~0 stone 3  
fill ~16 ~7 ~1 ~18 ~7 ~1 stone 3  
fill ~16 ~7 ~2 ~19 ~7 ~2 stone 3  
fill ~16 ~7 ~7 ~20 ~7 ~7 stone 0  
fill ~16 ~7 ~8 ~21 ~7 ~8 stone 0 
setblock ~16 ~7 ~19 wooden_slab 8  
fill ~17 ~7 ~-1 ~18 ~7 ~-1 stone 3  
fill ~17 ~7 ~3 ~19 ~7 ~3 stone 3  
fill ~17 ~7 ~4 ~19 ~7 ~4 stone 3  
fill ~17 ~7 ~17 ~29 ~7 ~17 stone 0  
fill ~17 ~7 ~31 ~19 ~7 ~31 stone 5  
fill ~18 ~7 ~18 ~30 ~7 ~18 stone 0  
fill ~18 ~7 ~28 ~23 ~7 ~28 stone 0 
setblock ~19 ~7 ~5 stone 3  
fill ~19 ~7 ~19 ~30 ~7 ~19 stone 0  
fill ~19 ~7 ~20 ~30 ~7 ~20 stone 0  
fill ~19 ~7 ~21 ~30 ~7 ~21 stone 0  
fill ~19 ~7 ~22 ~19 ~30 ~22 stone 0  
fill ~20 ~7 ~22 ~21 ~7 ~22 stone 3  
fill ~20 ~7 ~23 ~25 ~7 ~23 stone 3  
fill ~20 ~7 ~24 ~27 ~7 ~24 stone 3  
fill ~20 ~7 ~25 ~27 ~7 ~25 stone 3  
fill ~20 ~7 ~26 ~26 ~7 ~26 stone 3  
fill ~20 ~7 ~29 ~24 ~7 ~29 stone 0 
setblock ~20 ~7 ~31 stone 0  
fill ~21 ~7 ~1 ~21 ~16 ~1 vine 1  
fill ~21 ~7 ~30 ~24 ~7 ~30 stone 0  
fill ~22 ~7 ~22 ~30 ~7 ~22 stone 0  
fill ~23 ~7 ~27 ~26 ~7 ~27 stone 3 
setblock ~24 ~7 ~28 stone 3  
fill ~25 ~7 ~28 ~25 ~9 ~28 stone 0 
setblock ~25 ~7 ~30 gravel 0 
setblock ~26 ~7 ~13 grass 0  
fill ~26 ~7 ~23 ~29 ~7 ~23 stone 0  
fill ~27 ~7 ~14 ~27 ~9 ~14 dirt 0 
setblock ~28 ~7 ~14 grass 0 
setblock ~6 ~8 ~14 grass 0  
fill ~7 ~8 ~11 ~8 ~8 ~11 stone 3  
fill ~7 ~8 ~12 ~8 ~8 ~12 stone 3  
fill ~7 ~8 ~13 ~25 ~8 ~13 stone 0  
fill ~7 ~8 ~14 ~26 ~8 ~14 stone 0 
setblock ~7 ~8 ~15 tallgrass 1 
setblock ~8 ~8 ~9 tallgrass 1  
fill ~8 ~8 ~15 ~26 ~8 ~15 stone 0 
setblock ~9 ~8 ~7 tallgrass 1 
setblock ~9 ~8 ~8 grass 0  
fill ~9 ~8 ~11 ~23 ~8 ~11 stone 0  
fill ~9 ~8 ~12 ~24 ~8 ~12 stone 0  
fill ~9 ~8 ~16 ~28 ~8 ~16 stone 0  
fill ~9 ~8 ~17 ~9 ~0 ~17 stone 0  
fill ~10 ~8 ~4 ~17 ~8 ~4 stone 0  
fill ~10 ~8 ~5 ~16 ~8 ~5 stone 0  
fill ~10 ~8 ~6 ~13 ~8 ~6 stone 0  
fill ~10 ~8 ~7 ~12 ~8 ~7 stone 0  
fill ~10 ~8 ~8 ~11 ~8 ~8 stone 0  
fill ~10 ~8 ~9 ~11 ~8 ~9 stone 0  
fill ~10 ~8 ~10 ~11 ~8 ~10 stone 0  
fill ~10 ~8 ~17 ~10 ~10 ~17 stone 3  
fill ~10 ~8 ~18 ~10 ~11 ~18 stone 3 
setblock ~10 ~8 ~19 dirt 0 
setblock ~10 ~8 ~20 grass 0  
fill ~11 ~8 ~3 ~17 ~8 ~3 stone 0  
fill ~11 ~8 ~17 ~29 ~8 ~17 stone 0  
fill ~11 ~8 ~18 ~14 ~8 ~18 stone 0  
fill ~11 ~8 ~19 ~11 ~10 ~19 stone 3 
setblock ~11 ~8 ~20 dirt 0 
setblock ~11 ~8 ~21 tallgrass 1  
fill ~12 ~8 ~2 ~16 ~8 ~2 stone 0  
fill ~12 ~8 ~8 ~16 ~8 ~8 stone 1  
fill ~12 ~8 ~9 ~16 ~8 ~9 stone 1  
fill ~12 ~8 ~10 ~14 ~8 ~10 stone 1  
fill ~12 ~8 ~19 ~13 ~8 ~19 stone 0  
fill ~12 ~8 ~20 ~12 ~27 ~20 stone 0 
setblock ~12 ~8 ~22 grass 0 
setblock ~12 ~8 ~23 tallgrass 1  
fill ~13 ~8 ~1 ~16 ~8 ~1 stone 0  
fill ~13 ~8 ~7 ~17 ~8 ~7 stone 1  
fill ~13 ~8 ~21 ~13 ~30 ~21 stone 0  
fill ~13 ~8 ~22 ~13 ~30 ~22 stone 0  
fill ~13 ~8 ~23 ~13 ~10 ~23 dirt 0  
fill ~13 ~8 ~25 ~21 ~8 ~25 stone 0  
fill ~14 ~8 ~6 ~18 ~8 ~6 stone 1  
fill ~14 ~8 ~23 ~25 ~8 ~23 stone 0  
fill ~14 ~8 ~24 ~21 ~8 ~24 stone 0  
fill ~14 ~8 ~26 ~20 ~8 ~26 stone 0   
fill ~14 ~8 ~27 ~14 ~10 ~27 stone 0  
fill ~14 ~8 ~28 ~18 ~8 ~28 stone 5  
fill ~15 ~8 ~0 ~16 ~8 ~0 coal_ore 0  
fill ~15 ~8 ~10 ~23 ~8 ~10 stone 0  
fill ~15 ~8 ~18 ~17 ~8 ~18 bone_block 0  
fill ~15 ~8 ~22 ~17 ~8 ~22 bone_block 0  
fill ~15 ~8 ~27 ~16 ~8 ~27 stone 5  
fill ~15 ~8 ~29 ~20 ~8 ~29 stone 5  
fill ~15 ~8 ~30 ~21 ~8 ~30 stone 5 
setblock ~16 ~8 ~19 torch 3 
setblock ~16 ~8 ~21 torch 4  
fill ~17 ~8 ~0 ~18 ~8 ~0 stone 3  
fill ~17 ~8 ~1 ~18 ~8 ~1 stone 3  
fill ~17 ~8 ~2 ~17 ~8 ~0 stone 3  
fill ~17 ~8 ~5 ~17 ~9 ~5 stone 1  
fill ~17 ~8 ~8 ~21 ~8 ~8 stone 0  
fill ~17 ~8 ~9 ~22 ~8 ~9 stone 0 
setblock ~17 ~8 ~19 wooden_slab 0 
setblock ~17 ~8 ~20 wooden_slab 8  
fill ~17 ~8 ~27 ~21 ~8 ~27 stone 0  
fill ~17 ~8 ~31 ~19 ~8 ~31 stone 5  
fill ~18 ~8 ~3 ~19 ~8 ~3 stone 3  
fill ~18 ~8 ~4 ~19 ~8 ~4 stone 3  
fill ~18 ~8 ~5 ~19 ~8 ~5 stone 0  
fill ~18 ~8 ~7 ~20 ~8 ~7 stone 0  
fill ~18 ~8 ~18 ~30 ~8 ~18 stone 0  
fill ~19 ~8 ~6 ~19 ~10 ~6 stone 0  
fill ~19 ~8 ~19 ~30 ~8 ~19 stone 0  
fill ~19 ~8 ~20 ~30 ~8 ~20 stone 0  
fill ~19 ~8 ~21 ~30 ~8 ~21 stone 0  
fill ~19 ~8 ~28 ~26 ~8 ~28 stone 0  
fill ~20 ~8 ~22 ~30 ~8 ~22 stone 0  
fill ~21 ~8 ~26 ~26 ~8 ~26 stone 3  
fill ~21 ~8 ~29 ~25 ~8 ~29 stone 0  
fill ~22 ~8 ~24 ~27 ~8 ~24 stone 3  
fill ~22 ~8 ~25 ~27 ~8 ~25 stone 3  
fill ~22 ~8 ~30 ~24 ~8 ~30 stone 0  
fill ~23 ~8 ~27 ~26 ~8 ~27 stone 3 
setblock ~26 ~8 ~23 stone 3  
fill ~27 ~8 ~15 ~27 ~10 ~15 dirt 0  
fill ~27 ~8 ~23 ~28 ~8 ~23 stone 0 
setblock ~28 ~8 ~15 grass 0  
fill ~29 ~8 ~25 ~29 ~14 ~25 vine 4 
setblock ~6 ~9 ~14 tallgrass 1  
fill ~7 ~9 ~12 ~24 ~9 ~12 stone 0  
fill ~7 ~9 ~13 ~25 ~9 ~13 stone 0  
fill ~7 ~9 ~14 ~26 ~9 ~14 stone 0 
setblock ~8 ~9 ~10 grass 0  
fill ~8 ~9 ~11 ~10 ~9 ~11 stone 0  
fill ~8 ~9 ~15 ~26 ~9 ~15 stone 0 
setblock ~9 ~9 ~8 tallgrass 1  
fill ~9 ~9 ~10 ~9 ~11 ~10 stone 0  
fill ~9 ~9 ~16 ~11 ~9 ~16 stone 3  
fill ~9 ~9 ~17 ~9 ~9 ~16 stone 3  
fill ~10 ~9 ~5 ~15 ~9 ~5 stone 0  
fill ~10 ~9 ~6 ~13 ~9 ~6 stone 0  
fill ~10 ~9 ~7 ~11 ~9 ~7 stone 0  
fill ~10 ~9 ~8 ~11 ~9 ~8 stone 0  
fill ~10 ~9 ~9 ~10 ~1 ~9 stone 0  
fill ~10 ~9 ~10 ~15 ~9 ~10 stone 1 
setblock ~10 ~9 ~19 grass 0 
setblock ~10 ~9 ~20 tallgrass 1  
fill ~11 ~9 ~4 ~18 ~9 ~4 stone 0  
fill ~11 ~9 ~9 ~16 ~9 ~9 stone 1  
fill ~11 ~9 ~11 ~13 ~9 ~11 stone 1  
fill ~11 ~9 ~17 ~11 ~10 ~17 stone 3  
fill ~11 ~9 ~18 ~11 ~10 ~18 stone 3 
setblock ~11 ~9 ~20 grass 0  
fill ~12 ~9 ~3 ~18 ~9 ~3 stone 0  
fill ~12 ~9 ~7 ~17 ~9 ~7 stone 1  
fill ~12 ~9 ~8 ~17 ~9 ~8 stone 1  
fill ~12 ~9 ~16 ~28 ~9 ~16 stone 0  
fill ~12 ~9 ~17 ~28 ~9 ~17 stone 0  
fill ~12 ~9 ~18 ~14 ~9 ~18 stone 0  
fill ~12 ~9 ~19 ~13 ~9 ~19 stone 0 
setblock ~12 ~9 ~22 tallgrass 1  
fill ~13 ~9 ~2 ~18 ~9 ~2 stone 0  
fill ~14 ~9 ~1 ~18 ~9 ~1 stone 0  
fill ~14 ~9 ~6 ~18 ~9 ~6 stone 1  
fill ~14 ~9 ~11 ~23 ~9 ~11 stone 0  
fill ~14 ~9 ~23 ~28 ~9 ~23 stone 0  
fill ~14 ~9 ~24 ~23 ~9 ~24 stone 0  
fill ~14 ~9 ~25 ~23 ~9 ~25 stone 0  
fill ~14 ~9 ~26 ~23 ~9 ~26 stone 0  
fill ~14 ~9 ~28 ~18 ~9 ~28 stone 5  
fill ~15 ~9 ~18 ~17 ~9 ~18 bone_block 0  
fill ~15 ~9 ~22 ~17 ~9 ~22 bone_block 0  
fill ~15 ~9 ~27 ~16 ~9 ~27 stone 5  
fill ~15 ~9 ~29 ~20 ~9 ~29 stone 5  
fill ~15 ~9 ~30 ~21 ~9 ~30 stone 5 
setblock ~16 ~9 ~5 stone 1  
fill ~16 ~9 ~10 ~22 ~9 ~10 stone 0 
setblock ~16 ~9 ~21 wooden_slab 8  
fill ~17 ~9 ~9 ~22 ~9 ~9 stone 0 
setblock ~17 ~9 ~21 wooden_slab 0  
fill ~17 ~9 ~27 ~23 ~9 ~27 stone 0 
setblock ~17 ~9 ~31 coal_ore 0  
fill ~18 ~9 ~5 ~19 ~9 ~5 stone 0  
fill ~18 ~9 ~7 ~19 ~9 ~7 stone 0  
fill ~18 ~9 ~8 ~20 ~9 ~8 stone 0  
fill ~18 ~9 ~18 ~29 ~9 ~18 stone 0  
fill ~18 ~9 ~31 ~19 ~9 ~31 stone 5  
fill ~18 ~9 ~32 ~18 ~10 ~32 coal_ore 0  
fill ~19 ~9 ~3 ~19 ~14 ~3 vine 1  
fill ~19 ~9 ~19 ~29 ~9 ~19 stone 0  
fill ~19 ~9 ~20 ~29 ~9 ~20 stone 0  
fill ~19 ~9 ~21 ~29 ~9 ~21 stone 0  
fill ~19 ~9 ~28 ~25 ~9 ~28 stone 0  
fill ~20 ~9 ~1 ~20 ~16 ~1 vine 1  
fill ~20 ~9 ~7 ~20 ~11 ~7 log 12  
fill ~20 ~9 ~22 ~29 ~9 ~22 stone 0  
fill ~21 ~9 ~29 ~24 ~9 ~29 stone 0  
fill ~22 ~9 ~30 ~23 ~9 ~30 stone 0  
fill ~24 ~9 ~24 ~27 ~9 ~24 stone 3  
fill ~24 ~9 ~25 ~26 ~9 ~25 stone 3  
fill ~24 ~9 ~26 ~26 ~9 ~26 stone 3  
fill ~24 ~9 ~27 ~26 ~9 ~27 stone 3  
fill ~27 ~9 ~25 ~29 ~9 ~25 vine 4  
fill ~7 ~10 ~14 ~25 ~10 ~14 stone 0  
fill ~8 ~10 ~11 ~9 ~10 ~11 stone 0  
fill ~8 ~10 ~12 ~10 ~10 ~12 stone 0  
fill ~8 ~10 ~13 ~25 ~10 ~13 stone 0  
fill ~8 ~10 ~15 ~26 ~10 ~15 stone 0 
setblock ~9 ~10 ~9 grass 0  
fill ~9 ~10 ~16 ~11 ~10 ~16 stone 3  
fill ~10 ~10 ~6 ~13 ~10 ~6 stone 0  
fill ~10 ~10 ~7 ~11 ~10 ~7 stone 0  
fill ~10 ~10 ~8 ~10 ~13 ~8 stone 0  
fill ~10 ~10 ~9 ~12 ~10 ~9 stone 1  
fill ~10 ~10 ~10 ~15 ~10 ~10 stone 1  
fill ~10 ~10 ~11 ~13 ~10 ~11 stone 1 
setblock ~10 ~10 ~19 tallgrass 1  
fill ~11 ~10 ~5 ~18 ~10 ~5 stone 0  
fill ~11 ~10 ~8 ~12 ~10 ~8 stone 1 
setblock ~11 ~10 ~12 stone 1 
setblock ~11 ~10 ~20 tallgrass 1  
fill ~12 ~10 ~4 ~18 ~10 ~4 stone 0  
fill ~12 ~10 ~7 ~14 ~10 ~7 stone 1  
fill ~12 ~10 ~12 ~23 ~10 ~12 stone 0  
fill ~12 ~10 ~16 ~28 ~10 ~16 stone 0  
fill ~12 ~10 ~17 ~28 ~10 ~17 stone 0  
fill ~12 ~10 ~18 ~14 ~10 ~18 stone 0  
fill ~12 ~10 ~19 ~13 ~10 ~19 stone 0 
setblock ~12 ~10 ~21 grass 0  
fill ~13 ~10 ~2 ~18 ~10 ~2 stone 0  
fill ~13 ~10 ~3 ~18 ~10 ~3 stone 0  
fill ~13 ~10 ~8 ~17 ~10 ~8 stone 5  
fill ~13 ~10 ~9 ~13 ~13 ~9 stone 5 
setblock ~13 ~10 ~24 grass 0  
fill ~14 ~10 ~6 ~15 ~10 ~6 stone 1  
fill ~14 ~10 ~9 ~16 ~10 ~9 stone 1  
fill ~14 ~10 ~11 ~23 ~10 ~11 stone 0  
fill ~14 ~10 ~23 ~27 ~10 ~23 stone 0  
fill ~14 ~10 ~24 ~26 ~10 ~24 stone 0  
fill ~14 ~10 ~25 ~25 ~10 ~25 stone 0  
fill ~14 ~10 ~26 ~25 ~10 ~26 stone 0  
fill ~15 ~10 ~7 ~17 ~10 ~7 stone 5  
fill ~15 ~10 ~18 ~17 ~10 ~18 bone_block 0 
setblock ~15 ~10 ~20 wooden_slab 8 
setblock ~15 ~10 ~21 wooden_slab 0  
fill ~15 ~10 ~22 ~17 ~10 ~22 bone_block 0  
fill ~15 ~10 ~27 ~20 ~10 ~27 stone 0  
fill ~15 ~10 ~28 ~17 ~10 ~28 stone 5  
fill ~15 ~10 ~29 ~19 ~10 ~29 stone 5  
fill ~15 ~10 ~30 ~20 ~10 ~30 stone 5  
fill ~16 ~10 ~6 ~16 ~14 ~6 stone 5  
fill ~16 ~10 ~10 ~22 ~10 ~10 stone 0 
setblock ~17 ~10 ~6 stone 1  
fill ~17 ~10 ~9 ~21 ~10 ~9 stone 0  
fill ~17 ~10 ~31 ~19 ~10 ~31 stone 5 
setblock ~18 ~10 ~1 stone 0  
fill ~18 ~10 ~6 ~18 ~10 ~18 stone 0  
fill ~18 ~10 ~28 ~22 ~10 ~28 stone 0  
fill ~19 ~10 ~7 ~19 ~10 ~28 stone 0  
fill ~20 ~10 ~5 ~20 ~13 ~5 vine 1 
setblock ~20 ~10 ~8 stone 0  
fill ~20 ~10 ~18 ~29 ~10 ~18 stone 0  
fill ~20 ~10 ~19 ~29 ~10 ~19 stone 0  
fill ~20 ~10 ~20 ~29 ~10 ~20 stone 0  
fill ~20 ~10 ~21 ~29 ~10 ~21 stone 0  
fill ~20 ~10 ~22 ~29 ~10 ~22 stone 0  
fill ~20 ~10 ~29 ~22 ~10 ~29 stone 0  
fill ~21 ~10 ~27 ~24 ~10 ~27 gravel 0  
fill ~21 ~10 ~30 ~23 ~10 ~30 stone 0  
fill ~23 ~10 ~28 ~25 ~10 ~28 gravel 0  
fill ~23 ~10 ~29 ~24 ~10 ~29 gravel 0  
fill ~25 ~10 ~4 ~25 ~16 ~4 vine 2  
fill ~25 ~10 ~6 ~25 ~16 ~6 vine 2 
setblock ~25 ~10 ~27 stone 0  
fill ~26 ~10 ~14 ~26 ~12 ~14 dirt 0  
fill ~26 ~10 ~25 ~26 ~10 ~26 stone 3 
setblock ~27 ~10 ~14 grass 0  
fill ~28 ~10 ~25 ~28 ~13 ~25 vine 4  
fill ~8 ~11 ~12 ~16 ~11 ~12 stone 0  
fill ~8 ~11 ~13 ~15 ~11 ~13 stone 0  
fill ~8 ~11 ~14 ~15 ~11 ~14 stone 0 
setblock ~9 ~11 ~9 tallgrass 1  
fill ~9 ~11 ~11 ~9 ~12 ~11 stone 0  
fill ~9 ~11 ~15 ~26 ~11 ~15 stone 0  
fill ~9 ~11 ~16 ~27 ~11 ~16 stone 0  
fill ~10 ~11 ~6 ~10 ~2 ~6 stone 0  
fill ~10 ~11 ~7 ~12 ~11 ~7 stone 0  
fill ~10 ~11 ~9 ~10 ~16 ~9 stone 0  
fill ~10 ~11 ~10 ~12 ~11 ~10 stone 1  
fill ~10 ~11 ~11 ~12 ~11 ~11 stone 1  
fill ~10 ~11 ~17 ~28 ~11 ~17 stone 0  
fill ~11 ~11 ~5 ~11 ~11 ~6 stone 5  
fill ~11 ~11 ~8 ~11 ~17 ~8 stone 0 
setblock ~11 ~11 ~9 stone 1  
fill ~11 ~11 ~18 ~14 ~11 ~18 stone 0  
fill ~11 ~11 ~19 ~13 ~11 ~19 stone 0  
fill ~12 ~11 ~4 ~18 ~11 ~4 stone 0  
fill ~12 ~11 ~5 ~15 ~11 ~5 stone 0  
fill ~12 ~11 ~6 ~12 ~11 ~4 stone 0  
fill ~12 ~11 ~8 ~18 ~11 ~8 stone 5  
fill ~12 ~11 ~9 ~12 ~13 ~9 stone 5 
setblock ~12 ~11 ~21 tallgrass 1  
fill ~13 ~11 ~3 ~18 ~11 ~3 stone 0  
fill ~13 ~11 ~6 ~13 ~15 ~6 stone 5  
fill ~13 ~11 ~7 ~19 ~11 ~7 stone 5  
fill ~13 ~11 ~10 ~13 ~12 ~10 stone 5  
fill ~13 ~11 ~11 ~22 ~11 ~11 stone 0 
setblock ~13 ~11 ~23 grass 0 
setblock ~13 ~11 ~24 tallgrass 1  
fill ~14 ~11 ~2 ~18 ~11 ~2 stone 0 
setblock ~14 ~11 ~6 stone 0  
fill ~14 ~11 ~9 ~17 ~11 ~9 stone 5 
setblock ~14 ~11 ~10 stone 1  
fill ~14 ~11 ~23 ~27 ~11 ~23 stone 0  
fill ~14 ~11 ~24 ~26 ~11 ~24 stone 0  
fill ~14 ~11 ~25 ~20 ~11 ~25 stone 0  
fill ~15 ~11 ~6 ~15 ~15 ~6 stone 5  
fill ~15 ~11 ~10 ~22 ~11 ~10 stone 0  
fill ~15 ~11 ~18 ~17 ~11 ~18 bone_block 0 
setblock ~15 ~11 ~19 wooden_slab 0  
fill ~15 ~11 ~22 ~17 ~11 ~22 bone_block 0  
fill ~15 ~11 ~26 ~19 ~11 ~26 stone 0  
fill ~15 ~11 ~27 ~19 ~11 ~27 stone 0  
fill ~15 ~11 ~28 ~19 ~11 ~28 stone 0  
fill ~15 ~11 ~29 ~21 ~11 ~29 stone 0  
fill ~15 ~11 ~30 ~22 ~11 ~30 stone 0  
fill ~16 ~11 ~5 ~17 ~11 ~5 stone 5  
fill ~16 ~11 ~13 ~17 ~11 ~13 coal_ore 0  
fill ~16 ~11 ~14 ~17 ~11 ~14 coal_ore 0 
setblock ~16 ~11 ~19 wooden_slab 8  
fill ~17 ~11 ~6 ~18 ~11 ~6 stone 5  
fill ~17 ~11 ~12 ~18 ~11 ~12 coal_ore 0  
fill ~17 ~11 ~31 ~19 ~11 ~31 stone 0 
setblock ~18 ~11 ~5 stone 0  
fill ~18 ~11 ~9 ~21 ~11 ~9 stone 0  
fill ~18 ~11 ~13 ~24 ~11 ~13 stone 0  
fill ~18 ~11 ~14 ~25 ~11 ~14 stone 0  
fill ~18 ~11 ~18 ~28 ~11 ~18 stone 0  
fill ~18 ~11 ~32 ~18 ~13 ~32 stone 0 
setblock ~19 ~11 ~8 stone 0  
fill ~19 ~11 ~12 ~23 ~11 ~12 stone 0  
fill ~19 ~11 ~19 ~28 ~11 ~19 stone 0  
fill ~19 ~11 ~20 ~28 ~11 ~20 stone 0  
fill ~19 ~11 ~21 ~28 ~11 ~21 stone 0  
fill ~20 ~11 ~22 ~28 ~11 ~22 stone 0  
fill ~20 ~11 ~26 ~23 ~11 ~26 gravel 0  
fill ~20 ~11 ~27 ~25 ~11 ~27 gravel 0  
fill ~20 ~11 ~28 ~24 ~11 ~28 gravel 0  
fill ~21 ~11 ~6 ~21 ~13 ~6 log 12  
fill ~21 ~11 ~25 ~22 ~11 ~25 gravel 0  
fill ~22 ~11 ~7 ~22 ~14 ~7 vine 2  
fill ~22 ~11 ~29 ~23 ~11 ~29 gravel 0  
fill ~23 ~11 ~25 ~26 ~11 ~25 stone 0 
setblock ~23 ~11 ~30 gravel 0  
fill ~24 ~11 ~26 ~26 ~11 ~26 stone 0 
setblock ~27 ~11 ~15 grass 0  
fill ~31 ~11 ~24 ~31 ~17 ~24 vine 2  
fill ~8 ~12 ~14 ~14 ~12 ~14 stone 0  
fill ~9 ~12 ~12 ~16 ~12 ~12 stone 0  
fill ~9 ~12 ~13 ~15 ~12 ~13 stone 0  
fill ~9 ~12 ~15 ~14 ~12 ~15 stone 0  
fill ~9 ~12 ~16 ~27 ~12 ~16 stone 0  
fill ~10 ~12 ~7 ~10 ~2 ~7 stone 0  
fill ~10 ~12 ~10 ~11 ~12 ~10 stone 0  
fill ~10 ~12 ~11 ~22 ~12 ~11 stone 0  
fill ~10 ~12 ~17 ~27 ~12 ~17 stone 0  
fill ~10 ~12 ~18 ~14 ~12 ~18 stone 0  
fill ~11 ~12 ~6 ~18 ~12 ~6 stone 5  
fill ~11 ~12 ~7 ~19 ~12 ~7 stone 5  
fill ~11 ~12 ~9 ~11 ~21 ~9 stone 0  
fill ~11 ~12 ~19 ~13 ~12 ~19 stone 0  
fill ~12 ~12 ~5 ~18 ~12 ~5 stone 5  
fill ~12 ~12 ~8 ~19 ~12 ~8 stone 5 
setblock ~12 ~12 ~10 stone 5  
fill ~13 ~12 ~4 ~13 ~13 ~4 stone 5 
setblock ~13 ~12 ~23 tallgrass 1  
fill ~14 ~12 ~3 ~18 ~12 ~3 stone 0  
fill ~14 ~12 ~4 ~18 ~12 ~4 stone 0  
fill ~14 ~12 ~9 ~18 ~12 ~9 stone 5  
fill ~14 ~12 ~10 ~14 ~12 ~5 stone 5  
fill ~14 ~12 ~23 ~26 ~12 ~23 stone 0  
fill ~14 ~12 ~24 ~26 ~12 ~24 stone 0  
fill ~14 ~12 ~25 ~18 ~12 ~25 stone 0 
setblock ~15 ~12 ~2 leaves 15  
fill ~15 ~12 ~10 ~22 ~12 ~10 stone 0  
fill ~15 ~12 ~14 ~17 ~12 ~14 coal_ore 0  
fill ~15 ~12 ~15 ~16 ~12 ~15 coal_ore 0  
fill ~15 ~12 ~18 ~17 ~12 ~18 bone_block 0  
fill ~15 ~12 ~22 ~17 ~12 ~22 bone_block 0  
fill ~15 ~12 ~26 ~17 ~12 ~26 stone 0  
fill ~15 ~12 ~27 ~18 ~12 ~27 stone 0  
fill ~15 ~12 ~28 ~19 ~12 ~28 stone 0  
fill ~15 ~12 ~29 ~20 ~12 ~29 stone 0  
fill ~15 ~12 ~30 ~22 ~12 ~30 stone 0  
fill ~16 ~12 ~13 ~18 ~12 ~13 coal_ore 0 
setblock ~16 ~12 ~19 torch 3 
setblock ~16 ~12 ~21 torch 4  
fill ~17 ~12 ~12 ~18 ~12 ~12 coal_ore 0  
fill ~17 ~12 ~15 ~26 ~12 ~15 stone 0 
setblock ~17 ~12 ~19 wooden_slab 0 
setblock ~17 ~12 ~20 wooden_slab 8  
fill ~17 ~12 ~31 ~19 ~12 ~31 stone 0  
fill ~18 ~12 ~14 ~25 ~12 ~14 stone 0  
fill ~18 ~12 ~18 ~28 ~12 ~18 stone 0  
fill ~18 ~12 ~26 ~24 ~12 ~26 gravel 0  
fill ~19 ~12 ~2 ~19 ~16 ~2 vine 8  
fill ~19 ~12 ~9 ~20 ~12 ~9 stone 0  
fill ~19 ~12 ~12 ~23 ~12 ~12 stone 0  
fill ~19 ~12 ~13 ~24 ~12 ~13 stone 0  
fill ~19 ~12 ~19 ~28 ~12 ~19 stone 0  
fill ~19 ~12 ~20 ~28 ~12 ~20 stone 0  
fill ~19 ~12 ~21 ~28 ~12 ~21 stone 0  
fill ~19 ~12 ~25 ~22 ~12 ~25 gravel 0  
fill ~19 ~12 ~27 ~24 ~12 ~27 gravel 0  
fill ~20 ~12 ~22 ~28 ~12 ~22 stone 0  
fill ~20 ~12 ~28 ~23 ~12 ~28 gravel 0  
fill ~21 ~12 ~29 ~23 ~12 ~29 gravel 0  
fill ~23 ~12 ~25 ~26 ~12 ~25 stone 0  
fill ~25 ~12 ~26 ~25 ~13 ~26 stone 0 
setblock ~27 ~12 ~23 log 12  
fill ~27 ~12 ~24 ~27 ~13 ~24 vine 8  
fill ~31 ~12 ~29 ~31 ~18 ~29 vine 4 
setblock ~9 ~13 ~11 leaves 7  
fill ~9 ~13 ~12 ~23 ~13 ~12 stone 0  
fill ~9 ~13 ~13 ~15 ~13 ~13 stone 0  
fill ~9 ~13 ~14 ~14 ~13 ~14 stone 0  
fill ~9 ~13 ~15 ~14 ~13 ~15 stone 0  
fill ~9 ~13 ~16 ~26 ~13 ~16 stone 0  
fill ~10 ~13 ~10 ~22 ~13 ~10 stone 0  
fill ~10 ~13 ~11 ~22 ~13 ~11 stone 0  
fill ~10 ~13 ~17 ~27 ~13 ~17 stone 0  
fill ~10 ~13 ~18 ~14 ~13 ~18 stone 0  
fill ~11 ~13 ~6 ~18 ~13 ~6 stone 5  
fill ~11 ~13 ~7 ~18 ~13 ~7 stone 5  
fill ~11 ~13 ~19 ~13 ~13 ~19 stone 0  
fill ~11 ~13 ~22 ~11 ~17 ~22 vine 4  
fill ~12 ~13 ~5 ~18 ~13 ~5 stone 5  
fill ~12 ~13 ~8 ~19 ~13 ~8 stone 5  
fill ~14 ~13 ~3 ~15 ~13 ~3 stone 0  
fill ~14 ~13 ~4 ~14 ~14 ~4 stone 5  
fill ~14 ~13 ~9 ~17 ~13 ~9 stone 5  
fill ~14 ~13 ~23 ~14 ~29 ~23 stone 0  
fill ~14 ~13 ~24 ~26 ~13 ~24 stone 0  
fill ~14 ~13 ~25 ~18 ~13 ~25 stone 0  
fill ~15 ~13 ~4 ~18 ~13 ~4 stone 0  
fill ~15 ~13 ~14 ~17 ~13 ~14 coal_ore 0  
fill ~15 ~13 ~15 ~16 ~13 ~15 coal_ore 0  
fill ~15 ~13 ~18 ~17 ~13 ~18 bone_block 0  
fill ~15 ~13 ~22 ~17 ~13 ~22 bone_block 0  
fill ~15 ~13 ~23 ~16 ~13 ~23 coal_ore 0  
fill ~15 ~13 ~26 ~18 ~13 ~26 stone 0  
fill ~15 ~13 ~27 ~18 ~13 ~27 stone 0  
fill ~15 ~13 ~28 ~19 ~13 ~28 stone 0  
fill ~15 ~13 ~29 ~21 ~13 ~29 stone 0  
fill ~15 ~13 ~30 ~22 ~13 ~30 stone 0 
setblock ~16 ~13 ~3 leaves 15  
fill ~16 ~13 ~13 ~17 ~13 ~13 coal_ore 0 
setblock ~16 ~13 ~21 wooden_slab 8  
fill ~16 ~13 ~32 ~16 ~21 ~32 vine 4  
fill ~17 ~13 ~15 ~26 ~13 ~15 stone 0 
setblock ~17 ~13 ~21 wooden_slab 0  
fill ~17 ~13 ~23 ~26 ~13 ~23 stone 0  
fill ~17 ~13 ~31 ~18 ~13 ~31 stone 0  
fill ~18 ~13 ~9 ~20 ~13 ~9 stone 0  
fill ~18 ~13 ~13 ~23 ~13 ~13 stone 0  
fill ~18 ~13 ~14 ~25 ~13 ~14 stone 0  
fill ~18 ~13 ~18 ~27 ~13 ~18 stone 0  
fill ~18 ~13 ~22 ~18 ~14 ~22 coal_ore 0  
fill ~19 ~13 ~19 ~27 ~13 ~19 stone 0  
fill ~19 ~13 ~20 ~27 ~13 ~20 stone 0  
fill ~19 ~13 ~21 ~19 ~14 ~21 coal_ore 0  
fill ~19 ~13 ~25 ~22 ~13 ~25 gravel 0  
fill ~19 ~13 ~26 ~23 ~13 ~26 gravel 0  
fill ~19 ~13 ~27 ~24 ~13 ~27 gravel 0 
setblock ~20 ~13 ~6 log 12  
fill ~20 ~13 ~21 ~27 ~13 ~21 stone 0  
fill ~20 ~13 ~22 ~27 ~13 ~22 stone 0  
fill ~20 ~13 ~28 ~23 ~13 ~28 gravel 0 
setblock ~22 ~13 ~29 gravel 0  
fill ~23 ~13 ~25 ~25 ~13 ~25 stone 0  
fill ~24 ~13 ~26 ~24 ~21 ~26 stone 0 
setblock ~26 ~13 ~14 grass 0 
setblock ~28 ~13 ~24 log 12 
setblock ~33 ~13 ~26 structure_void 0 
setblock ~9 ~14 ~9 leaves 7  
fill ~9 ~14 ~12 ~22 ~14 ~12 stone 0  
fill ~9 ~14 ~13 ~23 ~14 ~13 stone 0  
fill ~9 ~14 ~14 ~25 ~14 ~14 stone 0  
fill ~9 ~14 ~15 ~26 ~14 ~15 stone 0  
fill ~9 ~14 ~16 ~26 ~14 ~16 stone 0  
fill ~10 ~14 ~10 ~22 ~14 ~10 stone 0  
fill ~10 ~14 ~11 ~22 ~14 ~11 stone 0  
fill ~10 ~14 ~17 ~27 ~14 ~17 stone 0  
fill ~10 ~14 ~18 ~14 ~14 ~18 stone 0  
fill ~10 ~14 ~21 ~10 ~17 ~21 vine 8  
fill ~11 ~14 ~7 ~18 ~14 ~7 stone 5  
fill ~11 ~14 ~19 ~13 ~14 ~19 stone 0  
fill ~12 ~14 ~6 ~12 ~15 ~6 stone 5  
fill ~12 ~14 ~8 ~14 ~14 ~8 stone 0  
fill ~12 ~14 ~9 ~19 ~14 ~9 stone 0  
fill ~12 ~14 ~22 ~12 ~15 ~22 vine 12  
fill ~13 ~14 ~5 ~16 ~14 ~5 stone 5  
fill ~14 ~14 ~3 ~15 ~14 ~3 leaves 7  
fill ~14 ~14 ~6 ~14 ~15 ~6 stone 5  
fill ~14 ~14 ~24 ~26 ~14 ~24 stone 0  
fill ~14 ~14 ~25 ~25 ~14 ~25 stone 0  
fill ~15 ~14 ~4 ~16 ~14 ~4 stone 0  
fill ~15 ~14 ~8 ~17 ~14 ~8 stone 5  
fill ~15 ~14 ~18 ~17 ~14 ~18 bone_block 0 
setblock ~15 ~14 ~20 wooden_slab 8 
setblock ~15 ~14 ~21 wooden_slab 0  
fill ~15 ~14 ~22 ~17 ~14 ~22 bone_block 0  
fill ~15 ~14 ~23 ~16 ~14 ~23 coal_ore 0  
fill ~15 ~14 ~26 ~20 ~14 ~26 stone 0  
fill ~15 ~14 ~27 ~19 ~14 ~27 stone 0  
fill ~15 ~14 ~28 ~20 ~14 ~28 stone 0  
fill ~15 ~14 ~29 ~22 ~14 ~29 stone 0  
fill ~15 ~14 ~30 ~22 ~14 ~30 stone 0  
fill ~17 ~14 ~5 ~18 ~14 ~5 stone 0  
fill ~17 ~14 ~6 ~18 ~14 ~6 stone 5  
fill ~17 ~14 ~23 ~26 ~14 ~23 stone 0  
fill ~18 ~14 ~4 ~20 ~14 ~4 leaves 3  
fill ~18 ~14 ~8 ~19 ~14 ~8 stone 0  
fill ~18 ~14 ~18 ~27 ~14 ~18 stone 0  
fill ~18 ~14 ~31 ~18 ~16 ~31 stone 0  
fill ~19 ~14 ~5 ~20 ~14 ~5 leaves 3 
setblock ~19 ~14 ~6 log 12  
fill ~19 ~14 ~7 ~21 ~14 ~7 leaves 3  
fill ~19 ~14 ~19 ~27 ~14 ~19 stone 0  
fill ~19 ~14 ~20 ~27 ~14 ~20 stone 0  
fill ~20 ~14 ~6 ~21 ~14 ~6 leaves 3 
setblock ~20 ~14 ~8 leaves 3  
fill ~20 ~14 ~21 ~27 ~14 ~21 stone 0  
fill ~20 ~14 ~22 ~27 ~14 ~22 stone 0  
fill ~20 ~14 ~27 ~22 ~14 ~27 gravel 0  
fill ~21 ~14 ~5 ~21 ~16 ~5 log 12  
fill ~21 ~14 ~26 ~22 ~14 ~26 gravel 0  
fill ~21 ~14 ~28 ~23 ~14 ~28 gravel 0  
fill ~23 ~14 ~26 ~23 ~15 ~26 stone 0  
fill ~23 ~14 ~27 ~23 ~21 ~27 stone 0  
fill ~28 ~14 ~28 ~28 ~18 ~28 vine 4 
setblock ~29 ~14 ~24 log 12  
fill ~30 ~14 ~29 ~30 ~18 ~29 vine 4  
fill ~33 ~14 ~26 ~33 ~17 ~26 vine 2  
fill ~9 ~15 ~12 ~22 ~15 ~12 stone 0  
fill ~9 ~15 ~13 ~23 ~15 ~13 stone 0  
fill ~9 ~15 ~14 ~25 ~15 ~14 stone 0  
fill ~9 ~15 ~15 ~26 ~15 ~15 stone 0  
fill ~9 ~15 ~16 ~26 ~15 ~16 stone 0  
fill ~9 ~15 ~17 ~26 ~15 ~17 stone 0  
fill ~9 ~15 ~18 ~14 ~15 ~18 stone 0  
fill ~10 ~15 ~8 ~10 ~16 ~8 leaves 7  
fill ~10 ~15 ~10 ~21 ~15 ~10 stone 0  
fill ~10 ~15 ~11 ~22 ~15 ~11 stone 0  
fill ~11 ~15 ~7 ~18 ~15 ~7 stone 0  
fill ~11 ~15 ~19 ~13 ~15 ~19 stone 0  
fill ~12 ~15 ~8 ~18 ~15 ~8 stone 0  
fill ~12 ~15 ~9 ~19 ~15 ~9 stone 0 
setblock ~13 ~15 ~4 leaves 7  
fill ~13 ~15 ~5 ~14 ~15 ~5 stone 5  
fill ~13 ~15 ~23 ~13 ~30 ~23 stone 0  
fill ~14 ~15 ~4 ~15 ~15 ~4 stone 0  
fill ~14 ~15 ~24 ~20 ~15 ~24 stone 0  
fill ~14 ~15 ~25 ~20 ~15 ~25 stone 0  
fill ~14 ~15 ~26 ~24 ~15 ~26 stone 0  
fill ~14 ~15 ~27 ~23 ~15 ~27 stone 0  
fill ~14 ~15 ~28 ~23 ~15 ~28 stone 0  
fill ~15 ~15 ~5 ~17 ~15 ~5 stone 0  
fill ~15 ~15 ~18 ~17 ~15 ~18 bone_block 0 
setblock ~15 ~15 ~19 wooden_slab 0  
fill ~15 ~15 ~22 ~17 ~15 ~22 bone_block 0  
fill ~15 ~15 ~23 ~21 ~15 ~23 stone 0  
fill ~15 ~15 ~29 ~22 ~15 ~29 stone 0  
fill ~15 ~15 ~30 ~21 ~15 ~30 stone 0  
fill ~16 ~15 ~6 ~18 ~15 ~6 stone 0 
setblock ~16 ~15 ~19 wooden_slab 8  
fill ~18 ~15 ~5 ~20 ~15 ~5 leaves 3  
fill ~18 ~15 ~18 ~27 ~15 ~18 stone 0  
fill ~18 ~15 ~22 ~18 ~17 ~22 stone 0  
fill ~18 ~15 ~32 ~18 ~21 ~32 vine 4  
fill ~19 ~15 ~6 ~20 ~15 ~6 leaves 3  
fill ~19 ~15 ~7 ~20 ~15 ~7 leaves 3  
fill ~19 ~15 ~19 ~27 ~15 ~19 stone 0  
fill ~19 ~15 ~20 ~27 ~15 ~20 stone 0  
fill ~19 ~15 ~21 ~27 ~15 ~21 stone 0  
fill ~20 ~15 ~22 ~23 ~15 ~22 stone 0  
fill ~21 ~15 ~24 ~26 ~15 ~24 stone 5  
fill ~21 ~15 ~25 ~25 ~15 ~25 stone 5  
fill ~22 ~15 ~23 ~26 ~15 ~23 stone 5  
fill ~24 ~15 ~22 ~27 ~15 ~22 stone 5  
fill ~30 ~15 ~23 ~30 ~17 ~23 vine 2  
fill ~30 ~15 ~24 ~30 ~17 ~24 log 12  
fill ~32 ~15 ~25 ~32 ~17 ~25 vine 2  
fill ~9 ~16 ~11 ~9 ~16 ~12 leaves 7  
fill ~9 ~16 ~13 ~23 ~16 ~13 stone 0  
fill ~9 ~16 ~14 ~25 ~16 ~14 stone 0  
fill ~9 ~16 ~15 ~25 ~16 ~15 stone 0  
fill ~9 ~16 ~16 ~26 ~16 ~16 stone 0  
fill ~9 ~16 ~17 ~26 ~16 ~17 stone 0  
fill ~9 ~16 ~18 ~14 ~16 ~18 stone 0  
fill ~10 ~16 ~10 ~21 ~16 ~10 stone 0  
fill ~10 ~16 ~11 ~22 ~16 ~11 stone 0  
fill ~10 ~16 ~12 ~22 ~16 ~12 stone 0  
fill ~10 ~16 ~19 ~13 ~16 ~19 stone 0 
setblock ~12 ~16 ~5 leaves 7  
fill ~12 ~16 ~6 ~18 ~16 ~6 stone 0  
fill ~12 ~16 ~7 ~18 ~16 ~7 stone 0  
fill ~12 ~16 ~8 ~18 ~16 ~8 stone 0  
fill ~12 ~16 ~9 ~19 ~16 ~9 stone 0  
fill ~12 ~16 ~21 ~12 ~30 ~21 stone 0  
fill ~12 ~16 ~22 ~12 ~17 ~22 vine 4  
fill ~12 ~16 ~23 ~12 ~19 ~23 vine 4  
fill ~13 ~16 ~5 ~16 ~16 ~5 stone 0  
fill ~14 ~16 ~24 ~19 ~16 ~24 stone 0  
fill ~14 ~16 ~25 ~19 ~16 ~25 stone 0  
fill ~14 ~16 ~26 ~20 ~16 ~26 stone 0  
fill ~14 ~16 ~27 ~23 ~16 ~27 stone 0  
fill ~14 ~16 ~28 ~22 ~16 ~28 stone 0  
fill ~14 ~16 ~29 ~22 ~16 ~29 stone 0  
fill ~14 ~16 ~30 ~21 ~16 ~30 stone 0  
fill ~15 ~16 ~18 ~17 ~16 ~18 bone_block 0  
fill ~15 ~16 ~22 ~17 ~16 ~22 bone_block 0  
fill ~15 ~16 ~23 ~20 ~16 ~23 stone 0 
setblock ~16 ~16 ~19 torch 3 
setblock ~16 ~16 ~21 torch 4 
setblock ~17 ~16 ~19 wooden_slab 0 
setblock ~17 ~16 ~20 wooden_slab 8  
fill ~18 ~16 ~4 ~24 ~16 ~4 leaves 3  
fill ~18 ~16 ~5 ~20 ~16 ~5 leaves 3  
fill ~18 ~16 ~18 ~27 ~16 ~18 stone 0  
fill ~19 ~16 ~3 ~23 ~16 ~3 leaves 3  
fill ~19 ~16 ~6 ~24 ~16 ~6 leaves 3  
fill ~19 ~16 ~7 ~23 ~16 ~7 leaves 3  
fill ~19 ~16 ~8 ~22 ~16 ~8 leaves 3  
fill ~19 ~16 ~19 ~27 ~16 ~19 stone 0  
fill ~19 ~16 ~20 ~27 ~16 ~20 stone 0  
fill ~19 ~16 ~21 ~25 ~16 ~21 stone 0  
fill ~20 ~16 ~2 ~22 ~16 ~2 leaves 3  
fill ~20 ~16 ~22 ~22 ~16 ~22 stone 0  
fill ~20 ~16 ~24 ~26 ~16 ~24 stone 5  
fill ~20 ~16 ~25 ~25 ~16 ~25 stone 5  
fill ~21 ~16 ~23 ~26 ~16 ~23 stone 5  
fill ~21 ~16 ~26 ~23 ~16 ~26 stone 5  
fill ~22 ~16 ~5 ~24 ~16 ~5 leaves 3  
fill ~23 ~16 ~22 ~27 ~16 ~22 stone 5  
fill ~26 ~16 ~21 ~27 ~16 ~21 stone 5  
fill ~33 ~16 ~23 ~33 ~18 ~23 vine 1 
setblock ~9 ~17 ~10 leaves 7  
fill ~9 ~17 ~13 ~22 ~17 ~13 stone 0  
fill ~9 ~17 ~14 ~24 ~17 ~14 stone 0  
fill ~9 ~17 ~15 ~9 ~0 ~15 stone 0  
fill ~9 ~17 ~16 ~11 ~17 ~16 stone 5  
fill ~9 ~17 ~17 ~11 ~17 ~17 stone 5  
fill ~9 ~17 ~18 ~14 ~17 ~18 stone 0  
fill ~9 ~17 ~20 ~9 ~19 ~20 vine 4 
setblock ~10 ~17 ~9 leaves 7  
fill ~10 ~17 ~10 ~20 ~17 ~10 stone 0  
fill ~10 ~17 ~11 ~21 ~17 ~11 stone 0  
fill ~10 ~17 ~12 ~22 ~17 ~12 stone 0  
fill ~10 ~17 ~15 ~11 ~17 ~15 stone 5  
fill ~10 ~17 ~19 ~13 ~17 ~19 stone 0  
fill ~11 ~17 ~20 ~11 ~27 ~20 stone 0  
fill ~12 ~17 ~6 ~12 ~18 ~6 leaves 7  
fill ~12 ~17 ~7 ~18 ~17 ~7 stone 0  
fill ~12 ~17 ~8 ~18 ~17 ~8 stone 0  
fill ~12 ~17 ~9 ~19 ~17 ~9 stone 0  
fill ~12 ~17 ~15 ~25 ~17 ~15 stone 0  
fill ~12 ~17 ~16 ~18 ~17 ~16 stone 0  
fill ~12 ~17 ~17 ~17 ~17 ~17 stone 0  
fill ~13 ~17 ~6 ~17 ~17 ~6 stone 0  
fill ~13 ~17 ~24 ~19 ~17 ~24 stone 0  
fill ~14 ~17 ~5 ~15 ~17 ~5 stone 0  
fill ~14 ~17 ~25 ~19 ~17 ~25 stone 0  
fill ~14 ~17 ~26 ~20 ~17 ~26 stone 0  
fill ~14 ~17 ~27 ~23 ~17 ~27 stone 0  
fill ~14 ~17 ~28 ~22 ~17 ~28 stone 0  
fill ~14 ~17 ~29 ~22 ~17 ~29 stone 0  
fill ~14 ~17 ~30 ~19 ~17 ~30 stone 0  
fill ~15 ~17 ~18 ~17 ~17 ~18 bone_block 0  
fill ~15 ~17 ~22 ~17 ~17 ~22 bone_block 0  
fill ~15 ~17 ~23 ~20 ~17 ~23 stone 0 
setblock ~16 ~17 ~21 wooden_slab 8 
setblock ~17 ~17 ~21 wooden_slab 0  
fill ~18 ~17 ~17 ~20 ~17 ~17 stone 5  
fill ~18 ~17 ~18 ~20 ~17 ~18 stone 5  
fill ~19 ~17 ~5 ~23 ~17 ~5 leaves 3  
fill ~19 ~17 ~16 ~20 ~17 ~16 stone 5  
fill ~19 ~17 ~19 ~20 ~17 ~19 stone 5  
fill ~19 ~17 ~20 ~19 ~20 ~20 stone 5  
fill ~19 ~17 ~21 ~25 ~17 ~21 stone 0  
fill ~20 ~17 ~4 ~22 ~17 ~4 leaves 3  
fill ~20 ~17 ~6 ~22 ~17 ~6 leaves 3  
fill ~20 ~17 ~20 ~27 ~17 ~20 stone 0  
fill ~20 ~17 ~22 ~22 ~17 ~22 stone 0  
fill ~20 ~17 ~24 ~26 ~17 ~24 stone 5  
fill ~20 ~17 ~25 ~25 ~17 ~25 stone 5  
fill ~20 ~17 ~30 ~21 ~17 ~30 stone 1 
setblock ~21 ~17 ~3 leaves 3 
setblock ~21 ~17 ~7 leaves 3  
fill ~21 ~17 ~16 ~26 ~17 ~16 stone 0  
fill ~21 ~17 ~17 ~26 ~17 ~17 stone 0  
fill ~21 ~17 ~18 ~27 ~17 ~18 stone 0  
fill ~21 ~17 ~19 ~27 ~17 ~19 stone 0  
fill ~21 ~17 ~23 ~26 ~17 ~23 stone 5  
fill ~21 ~17 ~26 ~23 ~17 ~26 stone 5  
fill ~23 ~17 ~22 ~27 ~17 ~22 stone 5  
fill ~26 ~17 ~21 ~27 ~17 ~21 stone 5  
fill ~29 ~17 ~23 ~29 ~17 ~24 log 12 
setblock ~31 ~17 ~25 log 12  
fill ~32 ~17 ~26 ~32 ~17 ~27 log 12  
fill ~8 ~18 ~17 ~12 ~18 ~17 stone 5  
fill ~8 ~18 ~18 ~11 ~18 ~18 stone 5 
setblock ~9 ~18 ~11 leaves 7  
fill ~9 ~18 ~13 ~10 ~18 ~13 stone 0  
fill ~9 ~18 ~14 ~9 ~0 ~14 stone 0  
fill ~9 ~18 ~15 ~12 ~18 ~15 stone 5  
fill ~9 ~18 ~16 ~12 ~18 ~16 stone 5  
fill ~10 ~18 ~10 ~12 ~18 ~10 stone 0  
fill ~10 ~18 ~11 ~12 ~18 ~11 stone 0  
fill ~10 ~18 ~12 ~11 ~18 ~12 stone 0  
fill ~10 ~18 ~14 ~13 ~18 ~14 stone 5  
fill ~10 ~18 ~19 ~13 ~18 ~19 stone 0  
fill ~10 ~18 ~21 ~10 ~20 ~21 vine 12 
setblock ~11 ~18 ~8 leaves 7  
fill ~11 ~18 ~13 ~13 ~18 ~13 stone 5  
fill ~11 ~18 ~22 ~11 ~19 ~22 vine 12  
fill ~12 ~18 ~7 ~18 ~18 ~7 stone 0  
fill ~12 ~18 ~8 ~18 ~18 ~8 stone 0  
fill ~12 ~18 ~9 ~18 ~18 ~9 stone 0  
fill ~12 ~18 ~12 ~12 ~20 ~12 stone 5  
fill ~12 ~18 ~18 ~14 ~18 ~18 stone 0  
fill ~12 ~18 ~22 ~12 ~30 ~22 stone 0  
fill ~13 ~18 ~6 ~16 ~18 ~6 stone 0  
fill ~13 ~18 ~10 ~15 ~18 ~10 coal_ore 0  
fill ~13 ~18 ~11 ~16 ~18 ~11 coal_ore 0  
fill ~13 ~18 ~12 ~22 ~18 ~12 stone 0  
fill ~13 ~18 ~15 ~19 ~18 ~15 stone 0  
fill ~13 ~18 ~16 ~17 ~18 ~16 stone 0  
fill ~13 ~18 ~17 ~16 ~18 ~17 stone 0  
fill ~13 ~18 ~24 ~20 ~18 ~24 stone 0  
fill ~13 ~18 ~25 ~20 ~18 ~25 stone 0  
fill ~14 ~18 ~5 ~14 ~19 ~5 stone 0  
fill ~14 ~18 ~13 ~22 ~18 ~13 stone 0  
fill ~14 ~18 ~14 ~24 ~18 ~14 stone 0  
fill ~14 ~18 ~26 ~24 ~18 ~26 stone 0  
fill ~14 ~18 ~27 ~23 ~18 ~27 stone 0  
fill ~14 ~18 ~28 ~22 ~18 ~28 stone 0  
fill ~14 ~18 ~29 ~21 ~18 ~29 stone 0  
fill ~14 ~18 ~30 ~19 ~18 ~30 stone 0  
fill ~15 ~18 ~18 ~17 ~18 ~18 bone_block 0 
setblock ~15 ~18 ~20 wooden_slab 8 
setblock ~15 ~18 ~21 wooden_slab 0  
fill ~15 ~18 ~22 ~17 ~18 ~22 bone_block 0  
fill ~15 ~18 ~23 ~15 ~29 ~23 stone 0  
fill ~16 ~18 ~10 ~20 ~18 ~10 stone 0  
fill ~16 ~18 ~23 ~17 ~18 ~23 stone 5  
fill ~17 ~18 ~11 ~21 ~18 ~11 stone 0  
fill ~17 ~18 ~17 ~21 ~18 ~17 stone 5  
fill ~17 ~18 ~32 ~17 ~21 ~32 vine 4  
fill ~18 ~18 ~16 ~21 ~18 ~16 stone 5  
fill ~18 ~18 ~18 ~21 ~18 ~18 stone 5  
fill ~18 ~18 ~22 ~18 ~19 ~22 stone 5  
fill ~18 ~18 ~23 ~21 ~18 ~23 stone 0  
fill ~19 ~18 ~19 ~20 ~18 ~19 stone 5  
fill ~19 ~18 ~21 ~19 ~19 ~21 stone 5  
fill ~20 ~18 ~15 ~21 ~18 ~15 stone 5  
fill ~20 ~18 ~20 ~27 ~18 ~20 stone 0  
fill ~20 ~18 ~21 ~27 ~18 ~21 stone 0  
fill ~20 ~18 ~22 ~23 ~18 ~22 stone 0  
fill ~20 ~18 ~30 ~21 ~18 ~30 stone 1  
fill ~21 ~18 ~19 ~27 ~18 ~19 stone 0  
fill ~21 ~18 ~24 ~26 ~18 ~24 stone 5  
fill ~21 ~18 ~25 ~25 ~18 ~25 stone 5  
fill ~22 ~18 ~15 ~25 ~18 ~15 stone 0  
fill ~22 ~18 ~16 ~26 ~18 ~16 stone 0  
fill ~22 ~18 ~17 ~26 ~18 ~17 stone 0  
fill ~22 ~18 ~18 ~27 ~18 ~18 stone 0  
fill ~22 ~18 ~23 ~26 ~18 ~23 stone 5  
fill ~22 ~18 ~29 ~22 ~21 ~29 vine 2  
fill ~24 ~18 ~22 ~27 ~18 ~22 stone 5  
fill ~27 ~18 ~23 ~32 ~18 ~23 leaves 3  
fill ~27 ~18 ~24 ~33 ~18 ~24 leaves 3  
fill ~27 ~18 ~25 ~29 ~18 ~25 leaves 3  
fill ~27 ~18 ~26 ~33 ~18 ~26 leaves 3  
fill ~28 ~18 ~22 ~31 ~18 ~22 leaves 3  
fill ~28 ~18 ~27 ~33 ~18 ~27 leaves 3  
fill ~29 ~18 ~28 ~32 ~18 ~28 leaves 3 
setblock ~30 ~18 ~25 log 12  
fill ~31 ~18 ~25 ~33 ~18 ~25 leaves 3  
fill ~8 ~19 ~16 ~12 ~19 ~16 stone 5  
fill ~8 ~19 ~17 ~12 ~19 ~17 stone 5  
fill ~8 ~19 ~18 ~11 ~19 ~18 stone 5  
fill ~9 ~19 ~12 ~9 ~21 ~12 leaves 7  
fill ~9 ~19 ~13 ~9 ~21 ~13 stone 0  
fill ~9 ~19 ~14 ~13 ~19 ~14 stone 5  
fill ~9 ~19 ~15 ~13 ~19 ~15 stone 5 
setblock ~9 ~19 ~19 stone 5  
fill ~10 ~19 ~10 ~11 ~19 ~10 stone 0  
fill ~10 ~19 ~11 ~11 ~19 ~11 stone 0  
fill ~10 ~19 ~12 ~10 ~24 ~12 stone 0  
fill ~10 ~19 ~13 ~13 ~19 ~13 stone 5  
fill ~10 ~19 ~19 ~13 ~19 ~19 stone 0  
fill ~11 ~19 ~12 ~11 ~20 ~12 stone 5  
fill ~12 ~19 ~7 ~12 ~22 ~7 leaves 7  
fill ~12 ~19 ~8 ~18 ~19 ~8 stone 0  
fill ~12 ~19 ~9 ~18 ~19 ~9 stone 0  
fill ~12 ~19 ~10 ~15 ~19 ~10 coal_ore 0  
fill ~12 ~19 ~11 ~16 ~19 ~11 coal_ore 0  
fill ~12 ~19 ~18 ~14 ~19 ~18 stone 0  
fill ~13 ~19 ~6 ~16 ~19 ~6 stone 0  
fill ~13 ~19 ~7 ~17 ~19 ~7 stone 0  
fill ~13 ~19 ~12 ~13 ~20 ~12 stone 5  
fill ~13 ~19 ~16 ~17 ~19 ~16 stone 0  
fill ~13 ~19 ~17 ~16 ~19 ~17 stone 0  
fill ~13 ~19 ~24 ~26 ~19 ~24 stone 0  
fill ~13 ~19 ~25 ~25 ~19 ~25 stone 0 
setblock ~14 ~19 ~12 coal_ore 0  
fill ~14 ~19 ~13 ~22 ~19 ~13 stone 0  
fill ~14 ~19 ~14 ~24 ~19 ~14 stone 0  
fill ~14 ~19 ~15 ~19 ~19 ~15 stone 0  
fill ~14 ~19 ~26 ~24 ~19 ~26 stone 0  
fill ~14 ~19 ~27 ~23 ~19 ~27 stone 0  
fill ~14 ~19 ~28 ~22 ~19 ~28 stone 0  
fill ~14 ~19 ~29 ~21 ~19 ~29 stone 0  
fill ~14 ~19 ~30 ~20 ~19 ~30 stone 0  
fill ~15 ~19 ~12 ~21 ~19 ~12 stone 0  
fill ~15 ~19 ~18 ~17 ~19 ~18 bone_block 0 
setblock ~15 ~19 ~19 wooden_slab 0  
fill ~15 ~19 ~22 ~17 ~19 ~22 bone_block 0  
fill ~16 ~19 ~10 ~19 ~19 ~10 stone 0 
setblock ~16 ~19 ~19 wooden_slab 8  
fill ~16 ~19 ~23 ~17 ~19 ~23 stone 5  
fill ~17 ~19 ~11 ~20 ~19 ~11 stone 0  
fill ~17 ~19 ~17 ~21 ~19 ~17 stone 5  
fill ~18 ~19 ~16 ~21 ~19 ~16 stone 5  
fill ~18 ~19 ~18 ~21 ~19 ~18 stone 5  
fill ~18 ~19 ~23 ~26 ~19 ~23 stone 0 
setblock ~19 ~19 ~9 leaves 7  
fill ~19 ~19 ~19 ~20 ~19 ~19 stone 5  
fill ~20 ~19 ~15 ~21 ~19 ~15 stone 5  
fill ~20 ~19 ~20 ~27 ~19 ~20 stone 0  
fill ~20 ~19 ~21 ~27 ~19 ~21 stone 0  
fill ~20 ~19 ~22 ~27 ~19 ~22 stone 0  
fill ~21 ~19 ~19 ~27 ~19 ~19 stone 0 
setblock ~21 ~19 ~30 vine 4  
fill ~22 ~19 ~15 ~24 ~19 ~15 stone 0  
fill ~22 ~19 ~16 ~25 ~19 ~16 stone 0  
fill ~22 ~19 ~17 ~25 ~19 ~17 stone 0  
fill ~22 ~19 ~18 ~26 ~19 ~18 stone 0  
fill ~26 ~19 ~17 ~26 ~20 ~17 stone 1  
fill ~28 ~19 ~25 ~32 ~19 ~25 leaves 3  
fill ~29 ~19 ~24 ~31 ~19 ~24 leaves 3  
fill ~29 ~19 ~26 ~31 ~19 ~26 leaves 3 
setblock ~30 ~19 ~23 leaves 3 
setblock ~30 ~19 ~27 leaves 3 
setblock ~31 ~19 ~23 vine 1 
setblock ~32 ~19 ~24 vine 2  
fill ~8 ~20 ~16 ~12 ~20 ~16 stone 5  
fill ~8 ~20 ~17 ~12 ~20 ~17 stone 5  
fill ~8 ~20 ~18 ~8 ~27 ~18 stone 0  
fill ~9 ~20 ~14 ~9 ~22 ~14 stone 0  
fill ~9 ~20 ~15 ~12 ~20 ~15 stone 5  
fill ~9 ~20 ~18 ~11 ~20 ~18 stone 5  
fill ~9 ~20 ~19 ~13 ~20 ~19 stone 0 
setblock ~9 ~20 ~20 vine 12  
fill ~10 ~20 ~10 ~11 ~20 ~10 stone 0  
fill ~10 ~20 ~11 ~11 ~20 ~11 stone 0  
fill ~10 ~20 ~13 ~13 ~20 ~13 stone 5  
fill ~10 ~20 ~14 ~13 ~20 ~14 stone 5  
fill ~10 ~20 ~20 ~10 ~30 ~20 stone 0  
fill ~11 ~20 ~21 ~11 ~30 ~21 stone 0 
setblock ~11 ~20 ~22 vine 4  
fill ~12 ~20 ~8 ~17 ~20 ~8 stone 0  
fill ~12 ~20 ~9 ~18 ~20 ~9 stone 0  
fill ~12 ~20 ~10 ~14 ~20 ~10 coal_ore 0  
fill ~12 ~20 ~11 ~14 ~20 ~11 coal_ore 0  
fill ~12 ~20 ~18 ~14 ~20 ~18 stone 0  
fill ~13 ~20 ~7 ~16 ~20 ~7 stone 0  
fill ~13 ~20 ~15 ~24 ~20 ~15 stone 0  
fill ~13 ~20 ~16 ~18 ~20 ~16 stone 0  
fill ~13 ~20 ~17 ~17 ~20 ~17 stone 0  
fill ~13 ~20 ~24 ~26 ~20 ~24 stone 0  
fill ~13 ~20 ~25 ~25 ~20 ~25 stone 0  
fill ~13 ~20 ~26 ~24 ~20 ~26 stone 0  
fill ~14 ~20 ~6 ~15 ~20 ~6 stone 0  
fill ~14 ~20 ~12 ~21 ~20 ~12 stone 0  
fill ~14 ~20 ~13 ~22 ~20 ~13 stone 0  
fill ~14 ~20 ~14 ~23 ~20 ~14 stone 0  
fill ~14 ~20 ~27 ~23 ~20 ~27 stone 0  
fill ~14 ~20 ~28 ~22 ~20 ~28 stone 0  
fill ~14 ~20 ~29 ~21 ~20 ~29 stone 0  
fill ~14 ~20 ~30 ~20 ~20 ~30 stone 0  
fill ~14 ~20 ~32 ~14 ~25 ~32 vine 4  
fill ~15 ~20 ~10 ~19 ~20 ~10 stone 0  
fill ~15 ~20 ~11 ~20 ~20 ~11 stone 0  
fill ~15 ~20 ~18 ~17 ~20 ~18 bone_block 0  
fill ~15 ~20 ~22 ~17 ~20 ~22 bone_block 0 
setblock ~16 ~20 ~19 torch 3 
setblock ~16 ~20 ~21 torch 4  
fill ~16 ~20 ~23 ~26 ~20 ~23 stone 0 
setblock ~17 ~20 ~7 leaves 7 
setblock ~17 ~20 ~19 wooden_slab 0 
setblock ~17 ~20 ~20 wooden_slab 8 
setblock ~18 ~20 ~8 leaves 7  
fill ~18 ~20 ~17 ~20 ~20 ~17 stone 5  
fill ~18 ~20 ~18 ~20 ~20 ~18 stone 5  
fill ~18 ~20 ~22 ~18 ~30 ~22 stone 0  
fill ~19 ~20 ~16 ~20 ~20 ~16 stone 5  
fill ~19 ~20 ~19 ~20 ~20 ~19 stone 5  
fill ~19 ~20 ~21 ~27 ~20 ~21 stone 0  
fill ~20 ~20 ~20 ~27 ~20 ~20 stone 0  
fill ~20 ~20 ~22 ~27 ~20 ~22 stone 0  
fill ~20 ~20 ~31 ~20 ~21 ~31 vine 4  
fill ~21 ~20 ~16 ~25 ~20 ~16 stone 0  
fill ~21 ~20 ~17 ~25 ~20 ~17 stone 0  
fill ~21 ~20 ~18 ~26 ~20 ~18 stone 0  
fill ~21 ~20 ~19 ~26 ~20 ~19 stone 0  
fill ~8 ~21 ~16 ~8 ~22 ~16 stone 0  
fill ~8 ~21 ~17 ~9 ~21 ~17 stone 0  
fill ~9 ~21 ~15 ~9 ~24 ~15 stone 0  
fill ~9 ~21 ~16 ~11 ~21 ~16 stone 5  
fill ~9 ~21 ~18 ~14 ~21 ~18 stone 0  
fill ~9 ~21 ~19 ~13 ~21 ~19 stone 0 
setblock ~9 ~21 ~20 vine 8  
fill ~10 ~21 ~10 ~19 ~21 ~10 stone 0  
fill ~10 ~21 ~11 ~19 ~21 ~11 stone 0  
fill ~10 ~21 ~13 ~10 ~25 ~13 stone 0  
fill ~10 ~21 ~14 ~10 ~27 ~14 stone 0  
fill ~10 ~21 ~15 ~11 ~21 ~15 stone 5   
fill ~10 ~21 ~17 ~11 ~21 ~17 stone 5 
setblock ~10 ~21 ~21 vine 4  
fill ~11 ~21 ~12 ~20 ~21 ~12 stone 0  
fill ~11 ~21 ~13 ~12 ~21 ~13 stone 5  
fill ~11 ~21 ~14 ~12 ~21 ~14 stone 5  
fill ~12 ~21 ~8 ~17 ~21 ~8 stone 0  
fill ~12 ~21 ~9 ~18 ~21 ~9 stone 0  
fill ~12 ~21 ~15 ~24 ~21 ~15 stone 0  
fill ~12 ~21 ~16 ~25 ~21 ~16 stone 0  
fill ~12 ~21 ~17 ~26 ~21 ~17 stone 0  
fill ~12 ~21 ~23 ~12 ~31 ~23 stone 0  
fill ~13 ~21 ~7 ~15 ~21 ~7 stone 0  
fill ~13 ~21 ~13 ~22 ~21 ~13 stone 0  
fill ~13 ~21 ~14 ~23 ~21 ~14 stone 0  
fill ~13 ~21 ~24 ~26 ~21 ~24 stone 0  
fill ~13 ~21 ~25 ~25 ~21 ~25 stone 0  
fill ~13 ~21 ~26 ~24 ~21 ~26 stone 0  
fill ~13 ~21 ~27 ~17 ~21 ~27 stone 0  
fill ~14 ~21 ~6 ~14 ~23 ~6 stone 0  
fill ~14 ~21 ~28 ~18 ~21 ~28 stone 0  
fill ~14 ~21 ~29 ~16 ~21 ~29 stone 0  
fill ~14 ~21 ~30 ~14 ~16 ~30 stone 0  
fill ~15 ~21 ~18 ~17 ~21 ~18 bone_block 0  
fill ~15 ~21 ~22 ~17 ~21 ~22 bone_block 0  
fill ~15 ~21 ~30 ~20 ~21 ~30 grass 0 
setblock ~15 ~21 ~31 fence 0 
setblock ~16 ~21 ~7 leaves 7 
setblock ~16 ~21 ~21 wooden_slab 8  
fill ~16 ~21 ~23 ~26 ~21 ~23 stone 0  
fill ~16 ~21 ~31 ~18 ~21 ~31 grass 0 
setblock ~17 ~21 ~21 wooden_slab 0  
fill ~17 ~21 ~29 ~18 ~21 ~29 grass 0  
fill ~18 ~21 ~18 ~26 ~21 ~18 stone 0  
fill ~18 ~21 ~27 ~18 ~22 ~27 dirt 0  
fill ~19 ~21 ~19 ~26 ~21 ~19 stone 0  
fill ~19 ~21 ~20 ~26 ~21 ~20 stone 0  
fill ~19 ~21 ~21 ~27 ~21 ~21 stone 0  
fill ~19 ~21 ~27 ~23 ~21 ~27 stone 0  
fill ~19 ~21 ~32 ~19 ~26 ~32 vine 2  
fill ~20 ~21 ~22 ~27 ~21 ~22 stone 0  
fill ~21 ~21 ~28 ~22 ~21 ~28 grass 0  
fill ~21 ~21 ~29 ~21 ~21 ~28 grass 0  
fill ~8 ~22 ~17 ~26 ~22 ~17 stone 0  
fill ~9 ~22 ~16 ~25 ~22 ~16 stone 0  
fill ~9 ~22 ~18 ~14 ~22 ~18 stone 0  
fill ~9 ~22 ~19 ~13 ~22 ~19 stone 0  
fill ~10 ~22 ~11 ~19 ~22 ~11 stone 0  
fill ~10 ~22 ~15 ~24 ~22 ~15 stone 0  
fill ~11 ~22 ~10 ~18 ~22 ~10 stone 0  
fill ~11 ~22 ~12 ~20 ~22 ~12 stone 0  
fill ~11 ~22 ~13 ~22 ~22 ~13 stone 0  
fill ~11 ~22 ~14 ~23 ~22 ~14 stone 0  
fill ~11 ~22 ~22 ~11 ~31 ~22 stone 0  
fill ~12 ~22 ~9 ~18 ~22 ~9 stone 0  
fill ~13 ~22 ~7 ~15 ~22 ~7 stone 0  
fill ~13 ~22 ~8 ~16 ~22 ~8 stone 0  
fill ~13 ~22 ~24 ~25 ~22 ~24 stone 0  
fill ~13 ~22 ~25 ~24 ~22 ~25 stone 0  
fill ~13 ~22 ~26 ~22 ~22 ~26 stone 0  
fill ~13 ~22 ~29 ~13 ~24 ~29 fence 0  
fill ~13 ~22 ~30 ~13 ~22 ~29 fence 0  
fill ~14 ~22 ~27 ~17 ~22 ~27 stone 0  
fill ~14 ~22 ~28 ~16 ~22 ~28 stone 0  
fill ~14 ~22 ~29 ~14 ~16 ~29 stone 0 
setblock ~14 ~22 ~30 wooden_slab 8 
setblock ~15 ~22 ~6 leaves 15  
fill ~15 ~22 ~18 ~17 ~22 ~18 bone_block 0 
setblock ~15 ~22 ~20 wooden_slab 8 
setblock ~15 ~22 ~21 wooden_slab 0  
fill ~15 ~22 ~22 ~17 ~22 ~22 bone_block 0 
setblock ~15 ~22 ~29 grass 0 
setblock ~15 ~22 ~30 red_flower 0 
setblock ~15 ~22 ~31 wooden_slab 0  
fill ~16 ~22 ~23 ~26 ~22 ~23 stone 0  
fill ~16 ~22 ~29 ~16 ~23 ~29 log 12  
fill ~16 ~22 ~30 ~18 ~22 ~30 tallgrass 1  
fill ~16 ~22 ~31 ~16 ~24 ~31 vine 4 
setblock ~17 ~22 ~8 leaves 15  
fill ~17 ~22 ~28 ~18 ~22 ~28 grass 0 
setblock ~17 ~22 ~29 tallgrass 1  
fill ~17 ~22 ~31 ~18 ~22 ~31 tallgrass 1  
fill ~18 ~22 ~18 ~26 ~22 ~18 stone 0  
fill ~19 ~22 ~19 ~26 ~22 ~19 stone 0  
fill ~19 ~22 ~20 ~26 ~22 ~20 stone 0  
fill ~19 ~22 ~21 ~26 ~22 ~21 stone 0  
fill ~19 ~22 ~27 ~22 ~22 ~27 stone 0 
setblock ~19 ~22 ~30 yellow_flower 0  
fill ~19 ~22 ~31 ~19 ~26 ~31 vine 4  
fill ~20 ~22 ~22 ~26 ~22 ~22 stone 0 
setblock ~20 ~22 ~30 tallgrass 1  
fill ~21 ~22 ~28 ~22 ~22 ~28 tallgrass 1  
fill ~21 ~22 ~29 ~21 ~22 ~28 tallgrass 1  
fill ~23 ~22 ~26 ~23 ~24 ~26 coal_ore 0  
fill ~8 ~23 ~17 ~25 ~23 ~17 stone 0  
fill ~9 ~23 ~16 ~24 ~23 ~16 stone 0  
fill ~9 ~23 ~18 ~14 ~23 ~18 stone 0  
fill ~9 ~23 ~19 ~13 ~23 ~19 stone 0  
fill ~10 ~23 ~15 ~23 ~23 ~15 stone 0  
fill ~10 ~23 ~21 ~10 ~30 ~21 stone 0  
fill ~11 ~23 ~10 ~18 ~23 ~10 stone 0  
fill ~11 ~23 ~11 ~19 ~23 ~11 stone 0  
fill ~11 ~23 ~12 ~20 ~23 ~12 stone 0  
fill ~11 ~23 ~13 ~22 ~23 ~13 stone 0  
fill ~11 ~23 ~14 ~23 ~23 ~14 stone 0  
fill ~12 ~23 ~9 ~18 ~23 ~9 stone 0  
fill ~12 ~23 ~29 ~12 ~26 ~29 vine 8  
fill ~13 ~23 ~7 ~13 ~24 ~7 leaves 7  
fill ~13 ~23 ~8 ~16 ~23 ~8 stone 0  
fill ~13 ~23 ~24 ~25 ~23 ~24 stone 0  
fill ~13 ~23 ~25 ~22 ~23 ~25 stone 0  
fill ~13 ~23 ~26 ~21 ~23 ~26 stone 0  
fill ~13 ~23 ~28 ~13 ~24 ~28 fence 0  
fill ~14 ~23 ~7 ~15 ~23 ~7 stone 0  
fill ~14 ~23 ~27 ~17 ~23 ~27 stone 0 
setblock ~14 ~23 ~28 wooden_slab 8 
setblock ~14 ~23 ~29 wooden_slab 0 
setblock ~15 ~23 ~6 leaves 7  
fill ~15 ~23 ~18 ~17 ~23 ~18 bone_block 0 
setblock ~15 ~23 ~19 wooden_slab 0  
fill ~15 ~23 ~22 ~17 ~23 ~22 bone_block 0  
fill ~15 ~23 ~28 ~16 ~23 ~28 stone 0 
setblock ~16 ~23 ~19 wooden_slab 8  
fill ~16 ~23 ~23 ~26 ~23 ~23 stone 0 
setblock ~17 ~23 ~28 yellow_flower 0  
fill ~18 ~23 ~8 ~18 ~24 ~8 leaves 7  
fill ~18 ~23 ~18 ~26 ~23 ~18 stone 0 
setblock ~18 ~23 ~27 grass 0  
fill ~19 ~23 ~19 ~26 ~23 ~19 stone 0  
fill ~19 ~23 ~20 ~26 ~23 ~20 stone 0  
fill ~19 ~23 ~21 ~26 ~23 ~21 stone 0  
fill ~19 ~23 ~27 ~20 ~23 ~27 stone 0  
fill ~20 ~23 ~22 ~26 ~23 ~22 stone 0  
fill ~20 ~23 ~30 ~20 ~26 ~30 vine 2  
fill ~22 ~23 ~26 ~22 ~26 ~26 coal_ore 0  
fill ~23 ~23 ~25 ~24 ~23 ~25 coal_ore 0  
fill ~8 ~24 ~17 ~25 ~24 ~17 stone 0  
fill ~8 ~24 ~19 ~13 ~24 ~19 stone 0  
fill ~9 ~24 ~16 ~24 ~24 ~16 stone 0  
fill ~9 ~24 ~18 ~14 ~24 ~18 stone 0  
fill ~9 ~24 ~20 ~9 ~30 ~20 stone 0  
fill ~10 ~24 ~15 ~23 ~24 ~15 stone 0  
fill ~11 ~24 ~11 ~19 ~24 ~11 stone 0  
fill ~11 ~24 ~12 ~20 ~24 ~12 stone 0  
fill ~11 ~24 ~13 ~21 ~24 ~13 stone 0  
fill ~11 ~24 ~14 ~23 ~24 ~14 stone 0  
fill ~12 ~24 ~10 ~18 ~24 ~10 stone 0  
fill ~12 ~24 ~30 ~12 ~26 ~30 vine 8  
fill ~13 ~24 ~8 ~16 ~24 ~8 stone 0  
fill ~13 ~24 ~9 ~18 ~24 ~9 stone 0  
fill ~13 ~24 ~24 ~24 ~24 ~24 stone 0  
fill ~13 ~24 ~25 ~23 ~24 ~25 stone 0  
fill ~13 ~24 ~26 ~20 ~24 ~26 stone 0 
setblock ~13 ~24 ~27 fence 0 
setblock ~14 ~24 ~6 leaves 15  
fill ~14 ~24 ~7 ~14 ~26 ~7 stone 0  
fill ~15 ~24 ~18 ~17 ~24 ~18 bone_block 0  
fill ~15 ~24 ~22 ~17 ~24 ~22 bone_block 0 
setblock ~15 ~24 ~27 wooden_slab 0 
setblock ~16 ~24 ~19 torch 3 
setblock ~16 ~24 ~21 torch 4  
fill ~16 ~24 ~23 ~26 ~24 ~23 stone 0 
setblock ~16 ~24 ~27 wooden_slab 8  
fill ~16 ~24 ~30 ~16 ~25 ~30 log 12 
setblock ~17 ~24 ~19 wooden_slab 0 
setblock ~17 ~24 ~20 wooden_slab 8 
setblock ~17 ~24 ~27 stone 0  
fill ~18 ~24 ~18 ~26 ~24 ~18 stone 0 
setblock ~18 ~24 ~27 yellow_flower 0  
fill ~19 ~24 ~19 ~26 ~24 ~19 stone 0  
fill ~19 ~24 ~20 ~26 ~24 ~20 stone 0  
fill ~19 ~24 ~21 ~26 ~24 ~21 stone 0  
fill ~20 ~24 ~22 ~26 ~24 ~22 stone 0  
fill ~21 ~24 ~26 ~21 ~26 ~26 coal_ore 0  
fill ~8 ~25 ~17 ~25 ~25 ~17 stone 0  
fill ~8 ~25 ~19 ~13 ~25 ~19 stone 0  
fill ~9 ~25 ~16 ~24 ~25 ~16 stone 0  
fill ~9 ~25 ~18 ~14 ~25 ~18 stone 0  
fill ~10 ~25 ~15 ~23 ~25 ~15 stone 0  
fill ~10 ~25 ~22 ~10 ~31 ~22 stone 0  
fill ~11 ~25 ~12 ~20 ~25 ~12 stone 0  
fill ~11 ~25 ~13 ~21 ~25 ~13 stone 0  
fill ~11 ~25 ~14 ~22 ~25 ~14 stone 0  
fill ~12 ~25 ~10 ~18 ~25 ~10 stone 0  
fill ~12 ~25 ~11 ~19 ~25 ~11 stone 0  
fill ~13 ~25 ~8 ~13 ~26 ~8 leaves 15  
fill ~13 ~25 ~9 ~17 ~25 ~9 stone 0  
fill ~13 ~25 ~24 ~24 ~25 ~24 stone 0  
fill ~13 ~25 ~25 ~17 ~25 ~25 stone 0  
fill ~13 ~25 ~26 ~18 ~25 ~26 stone 0  
fill ~14 ~25 ~8 ~15 ~25 ~8 stone 0 
setblock ~14 ~25 ~31 log 12  
fill ~15 ~25 ~18 ~17 ~25 ~18 bone_block 0  
fill ~15 ~25 ~22 ~17 ~25 ~22 bone_block 0 
setblock ~15 ~25 ~30 log 12 
setblock ~15 ~25 ~31 torch 3 
setblock ~16 ~25 ~21 wooden_slab 8  
fill ~16 ~25 ~23 ~25 ~25 ~23 stone 0 
setblock ~16 ~25 ~27 torch 4  
fill ~16 ~25 ~28 ~16 ~25 ~31 log 12 
setblock ~17 ~25 ~21 wooden_slab 0 
setblock ~17 ~25 ~27 wooden_slab 0  
fill ~18 ~25 ~18 ~26 ~25 ~18 stone 0 
setblock ~18 ~25 ~25 torch 3 
setblock ~18 ~25 ~27 wooden_slab 8  
fill ~19 ~25 ~19 ~26 ~25 ~19 stone 0  
fill ~19 ~25 ~20 ~26 ~25 ~20 stone 0  
fill ~19 ~25 ~21 ~26 ~25 ~21 stone 0  
fill ~20 ~25 ~22 ~26 ~25 ~22 stone 0  
fill ~20 ~25 ~25 ~21 ~25 ~25 coal_ore 0  
fill ~20 ~25 ~26 ~20 ~26 ~26 coal_ore 0  
fill ~21 ~25 ~27 ~22 ~25 ~27 fence 0  
fill ~22 ~25 ~25 ~23 ~25 ~25 stone 0  
fill ~6 ~26 ~8 ~6 ~34 ~8 vine 1  
fill ~7 ~26 ~12 ~7 ~31 ~12 vine 8  
fill ~8 ~26 ~16 ~8 ~31 ~16 vine 8  
fill ~8 ~26 ~17 ~8 ~26 ~16 vine 8  
fill ~8 ~26 ~19 ~13 ~26 ~19 stone 0  
fill ~9 ~26 ~16 ~24 ~26 ~16 stone 0  
fill ~9 ~26 ~17 ~24 ~26 ~17 stone 0  
fill ~9 ~26 ~18 ~14 ~26 ~18 stone 0  
fill ~9 ~26 ~21 ~9 ~30 ~21 stone 0  
fill ~10 ~26 ~15 ~23 ~26 ~15 stone 0  
fill ~11 ~26 ~13 ~21 ~26 ~13 stone 0  
fill ~11 ~26 ~14 ~22 ~26 ~14 stone 0  
fill ~11 ~26 ~23 ~11 ~35 ~23 stone 0  
fill ~12 ~26 ~11 ~19 ~26 ~11 stone 0  
fill ~12 ~26 ~12 ~19 ~26 ~12 stone 0  
fill ~12 ~26 ~24 ~24 ~26 ~24 stone 0  
fill ~13 ~26 ~9 ~17 ~26 ~9 stone 0  
fill ~13 ~26 ~10 ~18 ~26 ~10 stone 0  
fill ~13 ~26 ~25 ~19 ~26 ~25 stone 0  
fill ~13 ~26 ~26 ~19 ~26 ~26 stone 0  
fill ~13 ~26 ~28 ~19 ~26 ~28 leaves 3  
fill ~13 ~26 ~29 ~15 ~26 ~29 leaves 3  
fill ~13 ~26 ~30 ~19 ~26 ~30 leaves 3  
fill ~13 ~26 ~31 ~18 ~26 ~31 leaves 3  
fill ~14 ~26 ~8 ~15 ~26 ~8 stone 0  
fill ~14 ~26 ~32 ~18 ~26 ~32 leaves 3  
fill ~15 ~26 ~18 ~17 ~26 ~18 bone_block 0 
setblock ~15 ~26 ~20 wooden_slab 8 
setblock ~15 ~26 ~21 wooden_slab 0  
fill ~15 ~26 ~22 ~17 ~26 ~22 bone_block 0  
fill ~16 ~26 ~23 ~25 ~26 ~23 stone 0 
setblock ~16 ~26 ~29 log 12  
fill ~17 ~26 ~29 ~19 ~26 ~29 leaves 3  
fill ~18 ~26 ~18 ~25 ~26 ~18 stone 0  
fill ~19 ~26 ~19 ~26 ~26 ~19 stone 0  
fill ~19 ~26 ~20 ~26 ~26 ~20 stone 0  
fill ~19 ~26 ~21 ~26 ~26 ~21 stone 0  
fill ~19 ~26 ~27 ~22 ~26 ~27 wooden_slab 0  
fill ~20 ~26 ~22 ~26 ~26 ~22 stone 0  
fill ~20 ~26 ~25 ~21 ~26 ~25 coal_ore 0  
fill ~22 ~26 ~25 ~23 ~26 ~25 stone 0 
setblock ~23 ~26 ~26 wooden_slab 8 
setblock ~24 ~26 ~25 fence 0  
fill ~7 ~27 ~15 ~7 ~31 ~15 vine 8  
fill ~9 ~27 ~17 ~11 ~27 ~17 gravel 0  
fill ~9 ~27 ~18 ~11 ~27 ~18 gravel 0  
fill ~9 ~27 ~19 ~11 ~27 ~19 stone 0  
fill ~9 ~27 ~22 ~9 ~30 ~22 stone 0  
fill ~10 ~27 ~15 ~10 ~29 ~15 gravel 0  
fill ~10 ~27 ~16 ~11 ~27 ~16 gravel 0  
fill ~11 ~27 ~12 ~11 ~28 ~12 log 12  
fill ~11 ~27 ~13 ~21 ~27 ~13 stone 0  
fill ~11 ~27 ~14 ~22 ~27 ~14 stone 0  
fill ~11 ~27 ~15 ~23 ~27 ~15 stone 0  
fill ~12 ~27 ~11 ~18 ~27 ~11 stone 0  
fill ~12 ~27 ~12 ~19 ~27 ~12 stone 0  
fill ~12 ~27 ~16 ~23 ~27 ~16 stone 0  
fill ~12 ~27 ~17 ~24 ~27 ~17 stone 0  
fill ~12 ~27 ~18 ~14 ~27 ~18 stone 0  
fill ~12 ~27 ~19 ~12 ~30 ~19 gravel 0  
fill ~12 ~27 ~24 ~23 ~27 ~24 stone 0  
fill ~13 ~27 ~8 ~13 ~27 ~9 leaves 7  
fill ~13 ~27 ~10 ~18 ~27 ~10 stone 0 
setblock ~13 ~27 ~19 stone 0  
fill ~13 ~27 ~25 ~23 ~27 ~25 stone 0  
fill ~13 ~27 ~26 ~22 ~27 ~26 stone 0  
fill ~14 ~27 ~8 ~14 ~28 ~8 stone 0  
fill ~14 ~27 ~9 ~16 ~27 ~9 stone 0  
fill ~14 ~27 ~29 ~18 ~27 ~29 leaves 3  
fill ~15 ~27 ~18 ~17 ~27 ~18 bone_block 0 
setblock ~15 ~27 ~19 wooden_slab 0  
fill ~15 ~27 ~22 ~17 ~27 ~22 bone_block 0  
fill ~15 ~27 ~28 ~17 ~27 ~28 leaves 3  
fill ~15 ~27 ~30 ~17 ~27 ~30 leaves 3 
setblock ~16 ~27 ~19 wooden_slab 8  
fill ~16 ~27 ~23 ~24 ~27 ~23 stone 0 
setblock ~16 ~27 ~31 leaves 3  
fill ~18 ~27 ~18 ~25 ~27 ~18 stone 0  
fill ~19 ~27 ~19 ~25 ~27 ~19 stone 0  
fill ~19 ~27 ~20 ~25 ~27 ~20 stone 0  
fill ~19 ~27 ~21 ~26 ~27 ~21 stone 0  
fill ~20 ~27 ~22 ~26 ~27 ~22 stone 0 
setblock ~24 ~27 ~24 wooden_slab 8 
setblock ~24 ~27 ~25 wooden_slab 0 
setblock ~25 ~27 ~23 fence 0  
fill ~9 ~28 ~17 ~12 ~28 ~17 gravel 0  
fill ~9 ~28 ~18 ~13 ~28 ~18 gravel 0  
fill ~9 ~28 ~19 ~9 ~30 ~19 stone 0  
fill ~10 ~28 ~16 ~11 ~28 ~16 gravel 0  
fill ~10 ~28 ~19 ~13 ~28 ~19 gravel 0  
fill ~10 ~28 ~23 ~10 ~32 ~23 stone 0  
fill ~11 ~28 ~13 ~20 ~28 ~13 stone 0  
fill ~11 ~28 ~14 ~22 ~28 ~14 stone 0 
setblock ~11 ~28 ~15 gravel 0  
fill ~11 ~28 ~20 ~13 ~28 ~20 gravel 0 
setblock ~12 ~28 ~12 log 12  
fill ~12 ~28 ~15 ~22 ~28 ~15 stone 0  
fill ~12 ~28 ~16 ~23 ~28 ~16 stone 0  
fill ~12 ~28 ~24 ~23 ~28 ~24 stone 0 
setblock ~13 ~28 ~9 leaves 7  
fill ~13 ~28 ~10 ~18 ~28 ~10 stone 0  
fill ~13 ~28 ~11 ~18 ~28 ~11 stone 0  
fill ~13 ~28 ~12 ~19 ~28 ~12 stone 0  
fill ~13 ~28 ~17 ~24 ~28 ~17 stone 0  
fill ~13 ~28 ~25 ~22 ~28 ~25 stone 0  
fill ~13 ~28 ~26 ~22 ~28 ~26 stone 0  
fill ~14 ~28 ~9 ~16 ~28 ~9 stone 0  
fill ~14 ~28 ~18 ~14 ~30 ~18 stone 0  
fill ~15 ~28 ~18 ~17 ~28 ~18 bone_block 0  
fill ~15 ~28 ~22 ~17 ~28 ~22 bone_block 0  
fill ~16 ~28 ~20 ~17 ~28 ~20 wooden_slab 8  
fill ~16 ~28 ~21 ~17 ~28 ~21 wooden_slab 8  
fill ~16 ~28 ~23 ~24 ~28 ~23 stone 0 
setblock ~17 ~28 ~19 wooden_slab 0  
fill ~18 ~28 ~18 ~25 ~28 ~18 stone 0  
fill ~19 ~28 ~19 ~25 ~28 ~19 stone 0  
fill ~19 ~28 ~20 ~25 ~28 ~20 stone 0  
fill ~19 ~28 ~21 ~25 ~28 ~21 stone 0  
fill ~20 ~28 ~22 ~24 ~28 ~22 stone 0 
setblock ~23 ~28 ~25 spruce_fence 0 
setblock ~25 ~28 ~22 wooden_slab 8 
setblock ~25 ~28 ~23 wooden_slab 0  
fill ~26 ~28 ~21 ~26 ~32 ~21 fence 0  
fill ~26 ~28 ~22 ~26 ~29 ~22 fence 0  
fill ~7 ~29 ~14 ~7 ~31 ~14 vine 8  
fill ~9 ~29 ~17 ~12 ~29 ~17 gravel 0  
fill ~9 ~29 ~18 ~13 ~29 ~18 gravel 0  
fill ~10 ~29 ~12 ~10 ~30 ~12 log 12  
fill ~10 ~29 ~16 ~11 ~29 ~16 gravel 0  
fill ~10 ~29 ~19 ~13 ~29 ~19 gravel 0  
fill ~11 ~29 ~14 ~22 ~29 ~14 stone 0  
fill ~11 ~29 ~15 ~11 ~31 ~15 dirt 0  
fill ~11 ~29 ~20 ~13 ~29 ~20 gravel 0  
fill ~12 ~29 ~12 ~19 ~29 ~12 stone 0  
fill ~12 ~29 ~13 ~20 ~29 ~13 stone 0  
fill ~12 ~29 ~15 ~22 ~29 ~15 stone 0  
fill ~12 ~29 ~16 ~22 ~29 ~16 stone 0  
fill ~12 ~29 ~24 ~12 ~31 ~24 dirt 0  
fill ~13 ~29 ~10 ~13 ~30 ~10 leaves 7  
fill ~13 ~29 ~11 ~18 ~29 ~11 stone 0  
fill ~13 ~29 ~17 ~22 ~29 ~17 stone 0  
fill ~13 ~29 ~24 ~23 ~29 ~24 stone 0  
fill ~13 ~29 ~25 ~22 ~29 ~25 stone 0  
fill ~13 ~29 ~26 ~21 ~29 ~26 stone 0  
fill ~14 ~29 ~9 ~15 ~29 ~9 stone 0  
fill ~14 ~29 ~10 ~18 ~29 ~10 stone 0  
fill ~15 ~29 ~18 ~17 ~29 ~18 bone_block 0  
fill ~15 ~29 ~22 ~17 ~29 ~22 bone_block 0 
setblock ~16 ~29 ~9 leaves 7 
setblock ~16 ~29 ~19 torch 3  
fill ~16 ~29 ~20 ~16 ~30 ~20 ladder 2  
fill ~16 ~29 ~21 ~16 ~30 ~21 barrier 0  
fill ~16 ~29 ~23 ~23 ~29 ~23 stone 0  
fill ~18 ~29 ~18 ~23 ~29 ~18 stone 0  
fill ~18 ~29 ~27 ~18 ~33 ~27 stone 0  
fill ~19 ~29 ~19 ~24 ~29 ~19 stone 0  
fill ~19 ~29 ~20 ~24 ~29 ~20 stone 0  
fill ~19 ~29 ~21 ~24 ~29 ~21 stone 0  
fill ~20 ~29 ~22 ~24 ~29 ~22 stone 0  
fill ~22 ~29 ~26 ~22 ~34 ~26 fence 0  
fill ~23 ~29 ~16 ~23 ~32 ~16 gravel 0  
fill ~23 ~29 ~17 ~24 ~29 ~17 gravel 0 
setblock ~23 ~29 ~25 torch 5 
setblock ~24 ~29 ~18 gravel 0  
fill ~24 ~29 ~23 ~24 ~32 ~23 fence 0 
setblock ~25 ~29 ~18 fence 0 
setblock ~25 ~29 ~19 wooden_slab 8  
fill ~25 ~29 ~20 ~25 ~29 ~21 wooden_slab 0  
fill ~7 ~30 ~11 ~7 ~33 ~11 vine 1 
setblock ~8 ~30 ~18 fence 0 
setblock ~8 ~30 ~22 fence 0  
fill ~9 ~30 ~14 ~10 ~30 ~14 log 12  
fill ~9 ~30 ~18 ~11 ~30 ~18 gravel 0 
setblock ~10 ~30 ~13 log 12  
fill ~10 ~30 ~16 ~11 ~30 ~16 gravel 0  
fill ~10 ~30 ~17 ~11 ~30 ~17 gravel 0  
fill ~10 ~30 ~19 ~11 ~30 ~19 stone 0  
fill ~11 ~30 ~14 ~22 ~30 ~14 stone 0  
fill ~11 ~30 ~20 ~13 ~30 ~20 stone 0  
fill ~12 ~30 ~13 ~17 ~30 ~13 stone 0  
fill ~12 ~30 ~15 ~21 ~30 ~15 stone 0  
fill ~12 ~30 ~16 ~21 ~30 ~16 stone 0  
fill ~12 ~30 ~17 ~22 ~30 ~17 stone 0  
fill ~12 ~30 ~18 ~14 ~30 ~18 stone 0  
fill ~13 ~30 ~11 ~18 ~30 ~11 stone 0  
fill ~13 ~30 ~12 ~18 ~30 ~12 stone 0 
setblock ~13 ~30 ~19 stone 0  
fill ~13 ~30 ~24 ~22 ~30 ~24 stone 0  
fill ~13 ~30 ~25 ~22 ~30 ~25 stone 0  
fill ~13 ~30 ~26 ~21 ~30 ~26 stone 0  
fill ~14 ~30 ~10 ~16 ~30 ~10 stone 0  
fill ~14 ~30 ~23 ~15 ~30 ~23 planks 2  
fill ~15 ~30 ~18 ~17 ~30 ~18 bone_block 0  
fill ~15 ~30 ~22 ~17 ~30 ~22 bone_block 0  
fill ~16 ~30 ~23 ~18 ~30 ~23 stone 0 
setblock ~17 ~30 ~10 leaves 7  
fill ~17 ~30 ~27 ~17 ~35 ~27 stone 0  
fill ~18 ~30 ~13 ~18 ~31 ~13 dirt 0  
fill ~18 ~30 ~18 ~22 ~30 ~18 stone 0  
fill ~19 ~30 ~13 ~20 ~30 ~13 stone 0  
fill ~19 ~30 ~19 ~24 ~30 ~19 stone 0  
fill ~19 ~30 ~20 ~24 ~30 ~20 stone 0  
fill ~19 ~30 ~21 ~24 ~30 ~21 stone 0  
fill ~19 ~30 ~23 ~20 ~30 ~23 planks 2  
fill ~20 ~30 ~22 ~24 ~30 ~22 stone 0  
fill ~21 ~30 ~23 ~23 ~30 ~23 stone 0  
fill ~22 ~30 ~15 ~22 ~31 ~15 gravel 0  
fill ~22 ~30 ~16 ~22 ~32 ~16 gravel 0  
fill ~23 ~30 ~17 ~23 ~32 ~17 gravel 0  
fill ~23 ~30 ~18 ~23 ~31 ~18 gravel 0 
setblock ~24 ~30 ~18 double_wooden_slab 0 
setblock ~25 ~30 ~18 wooden_slab 0  
fill ~4 ~31 ~10 ~4 ~34 ~10 vine 8  
fill ~8 ~31 ~12 ~9 ~31 ~12 log 12  
fill ~8 ~31 ~13 ~11 ~31 ~13 leaves 3  
fill ~8 ~31 ~14 ~9 ~31 ~14 leaves 3  
fill ~8 ~31 ~15 ~10 ~31 ~15 leaves 3  
fill ~8 ~31 ~18 ~9 ~31 ~18 log 4  
fill ~8 ~31 ~22 ~9 ~31 ~22 log 4 
setblock ~9 ~31 ~16 leaves 3  
fill ~9 ~31 ~19 ~9 ~31 ~21 log 8  
fill ~10 ~31 ~12 ~11 ~31 ~12 leaves 3 
setblock ~10 ~31 ~14 log 12  
fill ~10 ~31 ~16 ~15 ~31 ~16 stone 0  
fill ~10 ~31 ~17 ~12 ~31 ~17 stone 0  
fill ~10 ~31 ~18 ~11 ~31 ~18 stone 0  
fill ~10 ~31 ~19 ~21 ~31 ~19 planks 2  
fill ~10 ~31 ~20 ~15 ~31 ~20 planks 2  
fill ~10 ~31 ~21 ~21 ~31 ~21 planks 2  
fill ~11 ~31 ~14 ~11 ~32 ~14 leaves 3  
fill ~12 ~31 ~13 ~16 ~31 ~13 stone 0  
fill ~12 ~31 ~14 ~20 ~31 ~14 stone 0  
fill ~12 ~31 ~15 ~15 ~31 ~15 stone 0  
fill ~12 ~31 ~18 ~21 ~31 ~18 planks 2  
fill ~12 ~31 ~22 ~21 ~31 ~22 planks 2 
setblock ~13 ~31 ~11 leaves 7  
fill ~13 ~31 ~12 ~18 ~31 ~12 stone 0  
fill ~13 ~31 ~17 ~21 ~31 ~17 planks 2 
setblock ~13 ~31 ~23 planks 2  
fill ~13 ~31 ~24 ~13 ~17 ~24 stone 0  
fill ~13 ~31 ~25 ~22 ~31 ~25 stone 0  
fill ~14 ~31 ~10 ~14 ~21 ~10 stone 0  
fill ~14 ~31 ~11 ~17 ~31 ~11 stone 0  
fill ~14 ~31 ~23 ~15 ~31 ~23 chest 2  
fill ~14 ~31 ~24 ~15 ~31 ~24 planks 2  
fill ~14 ~31 ~26 ~20 ~31 ~26 stone 0  
fill ~15 ~31 ~10 ~16 ~31 ~10 leaves 7  
fill ~16 ~31 ~15 ~18 ~31 ~15 planks 2  
fill ~16 ~31 ~16 ~18 ~31 ~16 planks 2 
setblock ~16 ~31 ~20 trapdoor 9  
fill ~16 ~31 ~23 ~18 ~31 ~23 planks 2  
fill ~16 ~31 ~24 ~18 ~31 ~24 stone 0  
fill ~17 ~31 ~13 ~17 ~33 ~13 dirt 0  
fill ~17 ~31 ~20 ~21 ~31 ~20 planks 2  
fill ~19 ~31 ~13 ~19 ~5 ~13 stone 0  
fill ~19 ~31 ~15 ~20 ~31 ~15 stone 0  
fill ~19 ~31 ~16 ~20 ~31 ~16 stone 0  
fill ~19 ~31 ~23 ~20 ~31 ~23 chest 2  
fill ~19 ~31 ~24 ~20 ~31 ~24 planks 2  
fill ~21 ~31 ~14 ~21 ~31 ~16 gravel 0 
setblock ~21 ~31 ~23 planks 2  
fill ~21 ~31 ~24 ~22 ~31 ~24 stone 0  
fill ~22 ~31 ~17 ~22 ~31 ~19 stone 0  
fill ~22 ~31 ~20 ~23 ~31 ~20 wooden_slab 9  
fill ~22 ~31 ~21 ~24 ~31 ~21 stone 0  
fill ~22 ~31 ~22 ~24 ~31 ~22 stone 0  
fill ~22 ~31 ~23 ~23 ~31 ~23 stone 0  
fill ~23 ~31 ~19 ~23 ~36 ~19 stone 0 
setblock ~24 ~31 ~19 wooden_slab 0 
setblock ~24 ~31 ~20 double_wooden_slab 0  
fill ~7 ~32 ~12 ~8 ~32 ~12 log 12  
fill ~9 ~32 ~13 ~11 ~32 ~13 leaves 3  
fill ~9 ~32 ~14 ~11 ~32 ~14 leaves 3  
fill ~9 ~32 ~15 ~10 ~32 ~15 leaves 3  
fill ~9 ~32 ~18 ~9 ~36 ~18 log 0  
fill ~9 ~32 ~19 ~9 ~32 ~21 bone_block 8  
fill ~9 ~32 ~22 ~9 ~36 ~22 log 0  
fill ~10 ~32 ~16 ~10 ~31 ~16 stone 0  
fill ~10 ~32 ~17 ~11 ~32 ~17 stone 0  
fill ~10 ~32 ~18 ~12 ~32 ~18 bone_block 0 
setblock ~10 ~32 ~19 wooden_slab 8 
setblock ~10 ~32 ~21 quartz_stairs 4  
fill ~10 ~32 ~22 ~12 ~32 ~22 bone_block 0 
setblock ~11 ~32 ~15 grass 0  
fill ~11 ~32 ~16 ~11 ~34 ~16 dirt 0 
setblock ~11 ~32 ~19 cauldron 3 
setblock ~11 ~32 ~21 quartz_stairs 5  
fill ~12 ~32 ~14 ~15 ~32 ~14 stone 0  
fill ~12 ~32 ~15 ~12 ~34 ~15 dirt 0  
fill ~12 ~32 ~16 ~12 ~35 ~16 stone 0 
setblock ~12 ~32 ~17 bone_block 0  
fill ~12 ~32 ~19 ~12 ~34 ~19 bone_block 0 
setblock ~12 ~32 ~20 birch_door 2  
fill ~12 ~32 ~21 ~12 ~34 ~21 bone_block 0 
setblock ~12 ~32 ~23 bone_block 0  
fill ~12 ~32 ~24 ~12 ~35 ~24 stone 0  
fill ~13 ~32 ~12 ~17 ~32 ~12 stone 0  
fill ~13 ~32 ~13 ~16 ~32 ~13 stone 0  
fill ~13 ~32 ~15 ~14 ~32 ~15 stone 0  
fill ~13 ~32 ~16 ~15 ~32 ~16 bone_block 0 
setblock ~13 ~32 ~17 jukebox 0  
fill ~13 ~32 ~24 ~15 ~32 ~24 bone_block 4  
fill ~13 ~32 ~25 ~21 ~32 ~25 stone 0 
setblock ~14 ~32 ~10 leaves 7  
fill ~14 ~32 ~11 ~15 ~32 ~11 stone 0 
setblock ~14 ~32 ~17 cauldron 3  
fill ~14 ~32 ~26 ~20 ~32 ~26 stone 0  
fill ~15 ~32 ~15 ~15 ~34 ~15 bookshelf 0  
fill ~15 ~32 ~19 ~18 ~32 ~19 carpet 8  
fill ~15 ~32 ~20 ~15 ~32 ~21 carpet 8  
fill ~16 ~32 ~14 ~18 ~32 ~14 bookshelf 0  
fill ~16 ~32 ~21 ~19 ~32 ~21 carpet 7  
fill ~16 ~32 ~24 ~18 ~32 ~24 lit_furnace 2  
fill ~16 ~32 ~27 ~16 ~36 ~27 stone 0 
setblock ~17 ~32 ~16 enchanting_table 0  
fill ~17 ~32 ~20 ~18 ~32 ~20 carpet 0  
fill ~18 ~32 ~13 ~18 ~34 ~13 stone 0  
fill ~19 ~32 ~14 ~20 ~32 ~14 stone 0  
fill ~19 ~32 ~15 ~19 ~34 ~15 bookshelf 0  
fill ~19 ~32 ~16 ~21 ~32 ~16 bone_block 0  
fill ~19 ~32 ~19 ~19 ~32 ~21 carpet 7  
fill ~19 ~32 ~24 ~21 ~32 ~24 bone_block 4  
fill ~19 ~32 ~27 ~19 ~33 ~27 stone 0  
fill ~20 ~32 ~15 ~20 ~35 ~15 stone 0 
setblock ~20 ~32 ~17 trapdoor 9 
setblock ~21 ~32 ~15 gravel 0 
setblock ~21 ~32 ~17 anvil 3  
fill ~22 ~32 ~17 ~22 ~32 ~19 bone_block 0  
fill ~22 ~32 ~21 ~22 ~32 ~23 bone_block 0  
fill ~22 ~32 ~24 ~22 ~36 ~24 stone 0  
fill ~22 ~32 ~25 ~22 ~34 ~25 fence 0  
fill ~23 ~32 ~18 ~23 ~36 ~18 stone 0 
setblock ~23 ~32 ~20 spruce_door 0  
fill ~23 ~32 ~21 ~23 ~38 ~21 stone 0  
fill ~23 ~32 ~22 ~23 ~40 ~22 stone 0  
fill ~23 ~32 ~23 ~23 ~35 ~23 stone 0  
fill ~24 ~32 ~21 ~25 ~32 ~21 double_wooden_slab 0 
setblock ~24 ~32 ~22 wooden_slab 8 
setblock ~25 ~32 ~20 wooden_slab 0  
fill ~6 ~33 ~12 ~7 ~33 ~12 log 12 
setblock ~7 ~33 ~10 vine 0  
fill ~7 ~33 ~13 ~7 ~33 ~14 log 12  
fill ~9 ~33 ~19 ~9 ~34 ~19 bone_block 0  
fill ~9 ~33 ~20 ~9 ~34 ~20 glass_pane 0  
fill ~9 ~33 ~21 ~9 ~34 ~21 bone_block 0  
fill ~10 ~33 ~17 ~11 ~33 ~17 stone 0  
fill ~10 ~33 ~18 ~10 ~35 ~18 bone_block 0 
setblock ~10 ~33 ~19 wall_banner 3  
fill ~10 ~33 ~22 ~10 ~35 ~22 bone_block 0  
fill ~11 ~33 ~18 ~11 ~34 ~18 planks 0 
setblock ~11 ~33 ~20 stone_button 4 
setblock ~11 ~33 ~21 quartz_block 0  
fill ~11 ~33 ~22 ~11 ~34 ~22 planks 0  
fill ~12 ~33 ~14 ~15 ~33 ~14 stone 0  
fill ~12 ~33 ~17 ~12 ~35 ~17 planks 1  
fill ~12 ~33 ~18 ~12 ~35 ~18 planks 1 
setblock ~12 ~33 ~20 birch_door 8  
fill ~12 ~33 ~22 ~12 ~35 ~22 planks 1  
fill ~12 ~33 ~23 ~12 ~35 ~23 planks 1  
fill ~13 ~33 ~13 ~16 ~33 ~13 stone 0  
fill ~13 ~33 ~15 ~14 ~33 ~15 stone 0  
fill ~13 ~33 ~16 ~13 ~35 ~16 planks 1 
setblock ~13 ~33 ~19 torch 1 
setblock ~13 ~33 ~21 torch 1  
fill ~13 ~33 ~24 ~13 ~35 ~24 planks 1  
fill ~13 ~33 ~25 ~21 ~33 ~25 stone 0  
fill ~14 ~33 ~11 ~14 ~21 ~11 stone 0  
fill ~14 ~33 ~12 ~16 ~33 ~12 stone 0  
fill ~14 ~33 ~16 ~15 ~33 ~16 planks 0  
fill ~14 ~33 ~24 ~14 ~34 ~24 planks 0 
setblock ~15 ~33 ~11 leaves 7 
setblock ~15 ~33 ~24 crafting_table 0  
fill ~15 ~33 ~26 ~20 ~33 ~26 stone 0  
fill ~16 ~33 ~14 ~18 ~33 ~14 bookshelf 0  
fill ~16 ~33 ~24 ~18 ~33 ~24 lit_furnace 2 
setblock ~17 ~33 ~28 cobblestone_wall 0  
fill ~19 ~33 ~14 ~19 ~34 ~14 stone 0  
fill ~19 ~33 ~16 ~20 ~33 ~16 planks 0 
setblock ~19 ~33 ~24 crafting_table 0 
setblock ~20 ~33 ~17 brewing_stand 7  
fill ~20 ~33 ~24 ~20 ~34 ~24 planks 0  
fill ~21 ~33 ~15 ~21 ~35 ~15 stone 0  
fill ~21 ~33 ~16 ~21 ~35 ~16 planks 1 
setblock ~21 ~33 ~19 torch 2 
setblock ~21 ~33 ~21 torch 2  
fill ~21 ~33 ~24 ~21 ~35 ~24 planks 1  
fill ~22 ~33 ~16 ~22 ~35 ~16 stone 0  
fill ~22 ~33 ~17 ~22 ~35 ~17 planks 1  
fill ~22 ~33 ~18 ~22 ~34 ~18 planks 0  
fill ~22 ~33 ~19 ~22 ~34 ~19 planks 0  
fill ~22 ~33 ~21 ~22 ~34 ~21 planks 0  
fill ~22 ~33 ~22 ~22 ~34 ~22 planks 0  
fill ~22 ~33 ~23 ~22 ~35 ~23 planks 1  
fill ~23 ~33 ~17 ~23 ~35 ~17 stone 0 
setblock ~23 ~33 ~20 spruce_door 9  
fill ~23 ~33 ~24 ~24 ~33 ~24 fence 0 
setblock ~24 ~33 ~19 spruce_fence 0 
setblock ~24 ~33 ~21 torch 5  
fill ~24 ~33 ~22 ~25 ~33 ~22 wooden_slab 0  
fill ~24 ~33 ~23 ~25 ~33 ~23 wooden_slab 8 
setblock ~3 ~34 ~11 vine 8  
fill ~4 ~34 ~11 ~10 ~34 ~11 leaves 3  
fill ~4 ~34 ~12 ~6 ~34 ~12 leaves 3  
fill ~4 ~34 ~13 ~10 ~34 ~13 leaves 3  
fill ~4 ~34 ~14 ~10 ~34 ~14 leaves 3  
fill ~5 ~34 ~10 ~9 ~34 ~10 leaves 3  
fill ~5 ~34 ~15 ~9 ~34 ~15 leaves 3  
fill ~6 ~34 ~9 ~8 ~34 ~9 leaves 3 
setblock ~7 ~34 ~12 log 12  
fill ~8 ~34 ~12 ~10 ~34 ~12 leaves 3 
setblock ~8 ~34 ~19 fence 0 
setblock ~8 ~34 ~21 fence 0  
fill ~10 ~34 ~17 ~11 ~34 ~17 stone 0 
setblock ~11 ~34 ~20 torch 2 
setblock ~12 ~34 ~20 bone_block 0  
fill ~13 ~34 ~13 ~16 ~34 ~13 stone 0  
fill ~13 ~34 ~14 ~15 ~34 ~14 stone 0  
fill ~13 ~34 ~15 ~14 ~34 ~15 stone 0  
fill ~13 ~34 ~25 ~21 ~34 ~25 stone 0  
fill ~14 ~34 ~12 ~15 ~34 ~12 stone 0  
fill ~14 ~34 ~16 ~15 ~34 ~16 planks 0 
setblock ~15 ~34 ~17 torch 3  
fill ~15 ~34 ~24 ~20 ~34 ~24 planks 0  
fill ~15 ~34 ~26 ~19 ~34 ~26 stone 0 
setblock ~16 ~34 ~12 leaves 7  
fill ~16 ~34 ~14 ~18 ~34 ~14 bookshelf 0  
fill ~16 ~34 ~15 ~19 ~34 ~15 bookshelf 0 
setblock ~17 ~34 ~13 grass 0 
setblock ~17 ~34 ~28 stone 0  
fill ~17 ~34 ~29 ~17 ~35 ~29 cobblestone_wall 1 
setblock ~18 ~34 ~27 cobblestone_wall 1  
fill ~19 ~34 ~16 ~20 ~34 ~16 planks 0 
setblock ~19 ~34 ~17 torch 3 
setblock ~20 ~34 ~26 snow_layer 0 
setblock ~21 ~34 ~26 fence 0 
setblock ~22 ~34 ~20 double_wooden_slab 0 
setblock ~23 ~34 ~20 oak_stairs 5  
fill ~23 ~34 ~24 ~25 ~34 ~24 wooden_slab 0  
fill ~23 ~34 ~25 ~23 ~34 ~26 wooden_slab 8 
setblock ~24 ~34 ~19 torch 5 
setblock ~24 ~34 ~25 wooden_slab 0  
fill ~5 ~35 ~12 ~9 ~35 ~12 leaves 3  
fill ~6 ~35 ~11 ~8 ~35 ~11 leaves 3  
fill ~6 ~35 ~13 ~8 ~35 ~13 leaves 3 
setblock ~7 ~35 ~10 leaves 3 
setblock ~7 ~35 ~14 leaves 3  
fill ~8 ~35 ~19 ~8 ~35 ~21 trapdoor 2  
fill ~9 ~35 ~19 ~9 ~35 ~21 spruce_stairs 0  
fill ~10 ~35 ~17 ~11 ~35 ~17 stone 0  
fill ~10 ~35 ~19 ~11 ~35 ~19 stone_slab 8  
fill ~10 ~35 ~20 ~11 ~35 ~20 stone_slab 8  
fill ~10 ~35 ~21 ~11 ~35 ~21 stone_slab 8 
setblock ~11 ~35 ~16 grass 0 
setblock ~11 ~35 ~18 planks 1 
setblock ~11 ~35 ~22 planks 1 
setblock ~12 ~35 ~15 grass 0  
fill ~12 ~35 ~19 ~12 ~35 ~23 planks 1  
fill ~13 ~35 ~13 ~13 ~37 ~13 fence 0  
fill ~13 ~35 ~14 ~13 ~37 ~14 fence 0  
fill ~13 ~35 ~15 ~15 ~35 ~15 stone 0  
fill ~13 ~35 ~17 ~14 ~35 ~17 stone_slab 8  
fill ~13 ~35 ~18 ~14 ~35 ~18 stone_slab 8  
fill ~13 ~35 ~19 ~14 ~35 ~19 stone_slab 8  
fill ~13 ~35 ~20 ~14 ~35 ~20 stone_slab 8  
fill ~13 ~35 ~21 ~14 ~35 ~21 stone_slab 8  
fill ~13 ~35 ~22 ~14 ~35 ~22 stone_slab 8  
fill ~13 ~35 ~23 ~14 ~35 ~23 stone_slab 8  
fill ~13 ~35 ~25 ~20 ~35 ~25 stone 0  
fill ~14 ~35 ~12 ~14 ~20 ~12 stone 0  
fill ~14 ~35 ~13 ~15 ~35 ~13 stone 0  
fill ~14 ~35 ~14 ~14 ~36 ~14 stone 0  
fill ~14 ~35 ~16 ~21 ~35 ~16 planks 1  
fill ~14 ~35 ~24 ~21 ~35 ~24 planks 1 
setblock ~15 ~35 ~12 leaves 7  
fill ~15 ~35 ~14 ~16 ~35 ~14 dirt 0  
fill ~15 ~35 ~17 ~15 ~35 ~23 log 8  
fill ~15 ~35 ~26 ~19 ~35 ~26 stone 0  
fill ~16 ~35 ~15 ~18 ~35 ~15 double_stone_slab 0  
fill ~16 ~35 ~17 ~18 ~35 ~17 stone_slab 8  
fill ~16 ~35 ~18 ~18 ~35 ~18 stone_slab 8  
fill ~16 ~35 ~19 ~18 ~35 ~19 stone_slab 8  
fill ~16 ~35 ~20 ~18 ~35 ~20 stone_slab 8  
fill ~16 ~35 ~21 ~18 ~35 ~21 stone_slab 8  
fill ~16 ~35 ~22 ~18 ~35 ~22 stone_slab 8  
fill ~16 ~35 ~23 ~18 ~35 ~23 stone_slab 8 
setblock ~17 ~35 ~13 double_plant 2 
setblock ~17 ~35 ~14 grass 0  
fill ~18 ~35 ~13 ~18 ~37 ~13 fence 0 
setblock ~18 ~35 ~14 stone 0 
setblock ~19 ~35 ~15 stone 0  
fill ~19 ~35 ~17 ~19 ~35 ~23 log 8  
fill ~19 ~35 ~27 ~20 ~35 ~27 fence 0  
fill ~20 ~35 ~17 ~21 ~35 ~17 stone_slab 8  
fill ~20 ~35 ~18 ~21 ~35 ~18 stone_slab 8  
fill ~20 ~35 ~19 ~21 ~35 ~19 stone_slab 8  
fill ~20 ~35 ~20 ~21 ~35 ~20 stone_slab 8  
fill ~20 ~35 ~21 ~21 ~35 ~21 stone_slab 8  
fill ~20 ~35 ~22 ~21 ~35 ~22 stone_slab 8  
fill ~20 ~35 ~23 ~21 ~35 ~23 stone_slab 8 
setblock ~20 ~35 ~26 fence 0 
setblock ~21 ~35 ~25 double_wooden_slab 0  
fill ~21 ~35 ~26 ~21 ~35 ~27 wooden_slab 8  
fill ~22 ~35 ~18 ~22 ~35 ~23 planks 1  
fill ~22 ~35 ~25 ~22 ~35 ~26 wooden_slab 0  
fill ~23 ~35 ~20 ~23 ~37 ~20 stone 0  
fill ~8 ~36 ~17 ~10 ~36 ~17 wooden_slab 13 
setblock ~8 ~36 ~20 torch 2  
fill ~8 ~36 ~23 ~11 ~36 ~23 wooden_slab 13  
fill ~9 ~36 ~19 ~9 ~36 ~21 log 8 
setblock ~10 ~36 ~18 log 4  
fill ~10 ~36 ~19 ~23 ~36 ~19 stone 0  
fill ~10 ~36 ~20 ~16 ~36 ~20 stone 0  
fill ~10 ~36 ~21 ~23 ~36 ~21 stone 0  
fill ~10 ~36 ~22 ~11 ~36 ~22 log 4 
setblock ~11 ~36 ~16 tallgrass 1 
setblock ~11 ~36 ~17 dirt 0  
fill ~11 ~36 ~18 ~23 ~36 ~18 stone 0 
setblock ~12 ~36 ~15 double_plant 2 
setblock ~12 ~36 ~16 dirt 0  
fill ~12 ~36 ~17 ~22 ~36 ~17 stone 0  
fill ~12 ~36 ~22 ~23 ~36 ~22 stone 0  
fill ~12 ~36 ~23 ~22 ~36 ~23 stone 0  
fill ~13 ~36 ~12 ~13 ~37 ~12 fence 0  
fill ~13 ~36 ~15 ~13 ~37 ~15 dirt 0  
fill ~13 ~36 ~16 ~21 ~36 ~16 stone 0  
fill ~13 ~36 ~24 ~22 ~36 ~24 stone 0  
fill ~13 ~36 ~25 ~20 ~36 ~25 stone 0  
fill ~14 ~36 ~13 ~14 ~0 ~13 stone 0  
fill ~14 ~36 ~15 ~16 ~36 ~15 stone 0  
fill ~15 ~36 ~14 ~16 ~36 ~14 grass 0  
fill ~15 ~36 ~26 ~19 ~36 ~26 stone 0 
setblock ~17 ~36 ~13 double_plant 10 
setblock ~17 ~36 ~14 yellow_flower 0  
fill ~17 ~36 ~15 ~17 ~37 ~15 dirt 0 
setblock ~17 ~36 ~20 redstone_block 0  
fill ~17 ~36 ~27 ~18 ~36 ~27 fence 0  
fill ~17 ~36 ~29 ~17 ~37 ~29 cobblestone_wall 0  
fill ~18 ~36 ~12 ~18 ~37 ~12 fence 0  
fill ~18 ~36 ~14 ~18 ~37 ~14 fence 0 
setblock ~18 ~36 ~15 grass 0  
fill ~18 ~36 ~20 ~23 ~36 ~20 stone 0 
setblock ~18 ~36 ~28 fence 0  
fill ~19 ~36 ~27 ~19 ~36 ~28 wooden_slab 8  
fill ~20 ~36 ~26 ~20 ~36 ~28 wooden_slab 0  
fill ~22 ~36 ~16 ~22 ~38 ~16 fence 0 
setblock ~23 ~36 ~23 spruce_fence 0  
fill ~8 ~37 ~18 ~9 ~37 ~18 wooden_slab 5 
setblock ~8 ~37 ~19 wooden_slab 13 
setblock ~8 ~37 ~21 wooden_slab 13  
fill ~8 ~37 ~22 ~9 ~37 ~22 wooden_slab 5  
fill ~9 ~37 ~19 ~9 ~37 ~21 double_wooden_slab 5  
fill ~10 ~37 ~18 ~10 ~38 ~18 stone 0  
fill ~10 ~37 ~19 ~22 ~37 ~19 stone 0  
fill ~10 ~37 ~20 ~23 ~37 ~20 stone 0  
fill ~10 ~37 ~21 ~23 ~37 ~21 stone 0  
fill ~10 ~37 ~22 ~23 ~37 ~22 stone 0 
setblock ~11 ~37 ~17 grass 0  
fill ~11 ~37 ~18 ~11 ~38 ~18 dirt 0 
setblock ~12 ~37 ~15 double_plant 10 
setblock ~12 ~37 ~16 grass 0  
fill ~12 ~37 ~17 ~22 ~37 ~17 stone 0  
fill ~12 ~37 ~18 ~22 ~37 ~18 stone 0  
fill ~12 ~37 ~23 ~22 ~37 ~23 stone 0  
fill ~13 ~37 ~16 ~19 ~37 ~16 stone 0  
fill ~13 ~37 ~24 ~21 ~37 ~24 stone 0  
fill ~13 ~37 ~25 ~20 ~37 ~25 stone 0  
fill ~14 ~37 ~14 ~18 ~37 ~14 fence 0  
fill ~14 ~37 ~15 ~15 ~37 ~15 stone 0  
fill ~14 ~37 ~26 ~19 ~37 ~26 stone 0  
fill ~15 ~37 ~13 ~16 ~37 ~13 fence 0  
fill ~15 ~37 ~27 ~16 ~37 ~27 fence 0 
setblock ~16 ~37 ~15 dirt 0 
setblock ~16 ~37 ~28 fence 0  
fill ~17 ~37 ~27 ~17 ~37 ~28 wooden_slab 8 
setblock ~18 ~37 ~15 fence 0  
fill ~18 ~37 ~27 ~18 ~37 ~28 wooden_slab 0  
fill ~20 ~37 ~16 ~23 ~37 ~16 fence 0  
fill ~23 ~37 ~17 ~23 ~37 ~18 fence 0 
setblock ~23 ~37 ~23 torch 5  
fill ~8 ~38 ~19 ~9 ~38 ~19 wooden_slab 5  
fill ~8 ~38 ~20 ~9 ~38 ~20 double_wooden_slab 5  
fill ~8 ~38 ~21 ~9 ~38 ~21 wooden_slab 5  
fill ~10 ~38 ~19 ~12 ~38 ~19 stone 0  
fill ~10 ~38 ~20 ~12 ~38 ~20 stone 0  
fill ~10 ~38 ~21 ~12 ~38 ~21 stone 0  
fill ~10 ~38 ~22 ~12 ~38 ~22 stone 0 
setblock ~11 ~38 ~17 tallgrass 1 
setblock ~12 ~38 ~16 tallgrass 1 
setblock ~12 ~38 ~17 dirt 0  
fill ~12 ~38 ~18 ~13 ~38 ~18 stone 0  
fill ~12 ~38 ~23 ~13 ~38 ~23 stone 0  
fill ~13 ~38 ~12 ~13 ~38 ~15 log 8  
fill ~13 ~38 ~16 ~13 ~36 ~16 stone 0  
fill ~13 ~38 ~17 ~13 ~38 ~16 stone 0  
fill ~13 ~38 ~19 ~18 ~38 ~19 planks 1  
fill ~13 ~38 ~20 ~18 ~38 ~20 planks 1  
fill ~13 ~38 ~21 ~18 ~38 ~21 planks 1  
fill ~13 ~38 ~22 ~18 ~38 ~22 planks 1  
fill ~13 ~38 ~24 ~14 ~38 ~24 stone 0  
fill ~13 ~38 ~25 ~14 ~38 ~25 stone 0  
fill ~14 ~38 ~13 ~17 ~38 ~13 log 4  
fill ~14 ~38 ~14 ~17 ~38 ~14 wooden_slab 8  
fill ~14 ~38 ~15 ~17 ~38 ~15 planks 0  
fill ~14 ~38 ~16 ~17 ~38 ~16 planks 0  
fill ~14 ~38 ~17 ~17 ~38 ~17 planks 0  
fill ~14 ~38 ~18 ~17 ~38 ~18 log 4  
fill ~14 ~38 ~23 ~17 ~38 ~23 planks 1  
fill ~14 ~38 ~26 ~14 ~40 ~26 stone 0  
fill ~14 ~38 ~27 ~16 ~38 ~27 wooden_slab 0  
fill ~15 ~38 ~24 ~16 ~38 ~24 planks 1  
fill ~15 ~38 ~25 ~16 ~38 ~25 planks 1  
fill ~15 ~38 ~26 ~16 ~38 ~26 planks 1  
fill ~15 ~38 ~28 ~16 ~38 ~28 wooden_slab 0  
fill ~17 ~38 ~24 ~21 ~38 ~24 stone 0  
fill ~17 ~38 ~25 ~20 ~38 ~25 stone 0  
fill ~17 ~38 ~26 ~18 ~38 ~26 stone 0   

KittysCommands:  
setblock ~17 ~38 ~29 cobblestone_wall 1  
fill ~18 ~38 ~12 ~18 ~38 ~15 log 8  
fill ~18 ~38 ~16 ~19 ~38 ~16 stone 0  
fill ~18 ~38 ~17 ~21 ~38 ~17 stone 0  
fill ~18 ~38 ~18 ~22 ~38 ~18 stone 0  
fill ~18 ~38 ~23 ~22 ~38 ~23 stone 0  
fill ~19 ~38 ~19 ~22 ~38 ~19 stone 0  
fill ~19 ~38 ~20 ~22 ~38 ~20 stone 0  
fill ~19 ~38 ~21 ~23 ~38 ~21 stone 0  
fill ~19 ~38 ~22 ~23 ~38 ~22 stone 0 
setblock ~19 ~38 ~26 spruce_fence 0  
fill ~20 ~38 ~16 ~24 ~38 ~16 fence 0  
fill ~22 ~38 ~17 ~26 ~38 ~17 stone_slab 11  
fill ~23 ~38 ~18 ~24 ~38 ~18 fence 0  
fill ~8 ~39 ~20 ~9 ~39 ~20 double_wooden_slab 5  
fill ~10 ~39 ~19 ~10 ~36 ~19 stone 0  
fill ~10 ~39 ~20 ~11 ~39 ~20 stone 0  
fill ~10 ~39 ~21 ~11 ~39 ~21 stone 0  
fill ~10 ~39 ~22 ~11 ~39 ~22 stone 0 
setblock ~11 ~39 ~18 grass 0  
fill ~11 ~39 ~19 ~11 ~42 ~19 dirt 0  
fill ~12 ~39 ~17 ~12 ~44 ~17 stone 0  
fill ~12 ~39 ~18 ~12 ~57 ~18 stone 0  
fill ~12 ~39 ~19 ~12 ~43 ~19 log 0  
fill ~12 ~39 ~20 ~12 ~39 ~22 bone_block 8  
fill ~12 ~39 ~23 ~12 ~43 ~23 stone 0  
fill ~13 ~39 ~13 ~13 ~44 ~13 log 0  
fill ~13 ~39 ~14 ~13 ~39 ~17 bone_block 8  
fill ~13 ~39 ~18 ~13 ~43 ~18 bone_block 0 
setblock ~13 ~39 ~19 chest 5  
fill ~13 ~39 ~20 ~13 ~58 ~20 ladder 5  
fill ~13 ~39 ~21 ~13 ~58 ~21 ladder 5 
setblock ~13 ~39 ~22 crafting_table 0  
fill ~13 ~39 ~23 ~13 ~43 ~23 log 0  
fill ~13 ~39 ~24 ~13 ~55 ~24 stone 0  
fill ~14 ~39 ~13 ~17 ~39 ~13 bone_block 4 
setblock ~14 ~39 ~14 jungle_stairs 5 
setblock ~14 ~39 ~24 bone_block 4  
fill ~14 ~39 ~25 ~14 ~58 ~25 stone 0 
setblock ~14 ~39 ~27 spruce_fence 0  
fill ~15 ~39 ~14 ~16 ~39 ~14 wooden_slab 11  
fill ~15 ~39 ~15 ~16 ~39 ~15 bed 10  
fill ~15 ~39 ~16 ~16 ~39 ~16 bed 2  
fill ~15 ~39 ~25 ~16 ~39 ~25 spruce_door 1 
setblock ~17 ~39 ~14 jungle_stairs 4 
setblock ~17 ~39 ~24 bone_block 4  
fill ~17 ~39 ~25 ~19 ~39 ~25 stone 0  
fill ~17 ~39 ~26 ~18 ~39 ~26 stone 0 
setblock ~17 ~39 ~29 cobblestone_wall 0  
fill ~18 ~39 ~13 ~18 ~44 ~13 log 0  
fill ~18 ~39 ~14 ~18 ~39 ~17 bone_block 8  
fill ~18 ~39 ~18 ~18 ~43 ~18 bone_block 0  
fill ~18 ~39 ~20 ~18 ~39 ~21 iron_trapdoor 10 
setblock ~18 ~39 ~22 crafting_table 0  
fill ~18 ~39 ~23 ~18 ~43 ~23 log 0  
fill ~18 ~39 ~24 ~21 ~39 ~24 stone 0  
fill ~19 ~39 ~16 ~26 ~39 ~16 log 4  
fill ~19 ~39 ~17 ~20 ~39 ~17 stone 0  
fill ~19 ~39 ~18 ~20 ~39 ~18 stone 0  
fill ~19 ~39 ~19 ~19 ~43 ~19 log 0  
fill ~19 ~39 ~20 ~19 ~39 ~22 bone_block 8  
fill ~19 ~39 ~23 ~22 ~39 ~23 stone 0 
setblock ~19 ~39 ~26 torch 5  
fill ~20 ~39 ~19 ~22 ~39 ~19 stone 0  
fill ~20 ~39 ~20 ~22 ~39 ~20 stone 0  
fill ~20 ~39 ~21 ~22 ~39 ~21 stone 0  
fill ~20 ~39 ~22 ~23 ~39 ~22 stone 0  
fill ~21 ~39 ~18 ~26 ~39 ~18 log 4 
setblock ~27 ~39 ~16 torch 1 
setblock ~27 ~39 ~18 torch 1  
fill ~10 ~40 ~20 ~10 ~36 ~20 stone 0  
fill ~10 ~40 ~21 ~11 ~40 ~21 stone 0 
setblock ~10 ~40 ~22 leaves 7 
setblock ~11 ~40 ~18 yellow_flower 0  
fill ~11 ~40 ~20 ~11 ~43 ~20 dirt 0  
fill ~11 ~40 ~22 ~11 ~54 ~22 stone 0  
fill ~12 ~40 ~20 ~12 ~43 ~20 planks 1  
fill ~12 ~40 ~21 ~12 ~43 ~21 planks 1  
fill ~12 ~40 ~22 ~12 ~43 ~22 planks 1  
fill ~13 ~40 ~14 ~13 ~42 ~14 bone_block 0  
fill ~13 ~40 ~15 ~13 ~42 ~15 glass_pane 0  
fill ~13 ~40 ~16 ~13 ~42 ~16 glass_pane 0  
fill ~13 ~40 ~17 ~13 ~43 ~17 bone_block 0 
setblock ~13 ~40 ~22 torch 5  
fill ~14 ~40 ~13 ~14 ~42 ~13 bone_block 0 
setblock ~14 ~40 ~14 torch 5  
fill ~14 ~40 ~24 ~14 ~43 ~24 planks 1 
setblock ~14 ~40 ~27 torch 5  
fill ~15 ~40 ~13 ~16 ~40 ~13 glass_pane 0 
setblock ~15 ~40 ~25 spruce_door 9 
setblock ~16 ~40 ~25 spruce_door 8  
fill ~17 ~40 ~13 ~17 ~42 ~13 bone_block 0 
setblock ~17 ~40 ~14 torch 5  
fill ~17 ~40 ~24 ~17 ~43 ~24 planks 1  
fill ~17 ~40 ~25 ~19 ~40 ~25 stone 0  
fill ~17 ~40 ~26 ~18 ~40 ~26 stone 0 
setblock ~17 ~40 ~29 stone_slab 3  
fill ~18 ~40 ~14 ~18 ~42 ~14 bone_block 0  
fill ~18 ~40 ~15 ~18 ~42 ~15 glass_pane 0  
fill ~18 ~40 ~16 ~18 ~42 ~16 glass_pane 0  
fill ~18 ~40 ~17 ~18 ~43 ~17 bone_block 0  
fill ~18 ~40 ~20 ~18 ~41 ~20 chest 4  
fill ~18 ~40 ~21 ~18 ~41 ~21 chest 4 
setblock ~18 ~40 ~22 torch 5  
fill ~18 ~40 ~24 ~20 ~40 ~24 stone 0  
fill ~19 ~40 ~17 ~20 ~40 ~17 stone 0  
fill ~19 ~40 ~18 ~22 ~40 ~18 stone 0  
fill ~19 ~40 ~20 ~19 ~40 ~22 planks 1  
fill ~19 ~40 ~23 ~22 ~40 ~23 stone 0  
fill ~20 ~40 ~19 ~22 ~40 ~19 stone 0  
fill ~20 ~40 ~20 ~22 ~40 ~20 stone 0  
fill ~20 ~40 ~21 ~22 ~40 ~21 stone 0  
fill ~20 ~40 ~22 ~23 ~40 ~22 stone 0 
setblock ~22 ~40 ~17 torch 4 
setblock ~10 ~41 ~20 leaves 7  
fill ~10 ~41 ~21 ~10 ~36 ~21 stone 0  
fill ~11 ~41 ~21 ~11 ~43 ~21 dirt 0 
setblock ~11 ~41 ~23 leaves 7  
fill ~15 ~41 ~13 ~16 ~41 ~13 glass_pane 0  
fill ~15 ~41 ~24 ~17 ~41 ~24 planks 1  
fill ~15 ~41 ~25 ~19 ~41 ~25 stone 0  
