setblock ~37 ~1 ~22 chest 0  
setblock ~37 ~7 ~16 chest 0  
setblock ~37 ~7 ~17 chest 0  
setblock ~38 ~1 ~22 chest 0  
setblock ~40 ~1 ~22 chest 0  
setblock ~41 ~1 ~22 chest 0  
setblock ~43 ~1 ~19 lit_furnace 4  
setblock ~43 ~1 ~21 lit_furnace 4  
fill ~-3 ~0 ~19 ~3 ~0 ~19 sand 0  
fill ~-2 ~0 ~18 ~3 ~0 ~18 sand 0  
fill ~-2 ~0 ~20 ~3 ~0 ~20 sand 0  
fill ~-1 ~0 ~21 ~3 ~0 ~21 sand 0  
fill ~0 ~0 ~17 ~4 ~0 ~17 sand 0  
fill ~1 ~0 ~22 ~4 ~0 ~22 sand 0  
fill ~1 ~0 ~23 ~5 ~0 ~23 sand 0  
fill ~2 ~0 ~16 ~5 ~0 ~16 sand 0  
fill ~2 ~0 ~24 ~7 ~0 ~24 sand 0  
fill ~3 ~0 ~14 ~6 ~0 ~14 sand 0  
fill ~3 ~0 ~15 ~5 ~0 ~15 sand 0  
fill ~4 ~0 ~12 ~8 ~0 ~12 sand 0  
fill ~4 ~0 ~13 ~7 ~0 ~13 sand 0  
fill ~4 ~0 ~18 ~5 ~0 ~18 dirt 0  
fill ~4 ~0 ~19 ~4 ~2 ~19 dirt 0  
fill ~4 ~0 ~20 ~4 ~2 ~20 dirt 0  
fill ~4 ~0 ~21 ~5 ~0 ~21 dirt 0  
fill ~5 ~0 ~11 ~10 ~0 ~11 sand 0  
fill ~5 ~0 ~17 ~5 ~2 ~17 dirt 0  
fill ~5 ~0 ~19 ~5 ~0 ~20 gravel 0  
fill ~5 ~0 ~22 ~5 ~2 ~22 dirt 0  
fill ~5 ~0 ~25 ~8 ~0 ~25 sand 0  
fill ~6 ~0 ~10 ~11 ~0 ~10 sand 0  
fill ~6 ~0 ~15 ~6 ~2 ~15 dirt 0  
fill ~6 ~0 ~16 ~6 ~2 ~16 dirt 0  
fill ~6 ~0 ~17 ~38 ~0 ~17 stone 0  
fill ~6 ~0 ~18 ~13 ~0 ~18 stone 0  
fill ~6 ~0 ~19 ~11 ~0 ~19 stone 0  
fill ~6 ~0 ~20 ~10 ~0 ~20 stone 0  
fill ~6 ~0 ~21 ~9 ~0 ~21 stone 0  
fill ~6 ~0 ~22 ~9 ~0 ~22 stone 0  
fill ~6 ~0 ~23 ~6 ~3 ~23 dirt 0  
fill ~7 ~0 ~9 ~20 ~0 ~9 sand 0  
fill ~7 ~0 ~14 ~8 ~0 ~14 dirt 0  
fill ~7 ~0 ~15 ~17 ~0 ~15 stone 0  
fill ~7 ~0 ~16 ~17 ~0 ~16 stone 0  
fill ~7 ~0 ~23 ~9 ~0 ~23 stone 0  
fill ~7 ~0 ~26 ~8 ~0 ~26 sand 0  
fill ~8 ~0 ~8 ~20 ~0 ~8 sand 0  
fill ~8 ~0 ~13 ~9 ~0 ~13 dirt 0  
fill ~8 ~0 ~24 ~22 ~0 ~24 stone 0  
fill ~8 ~0 ~27 ~9 ~0 ~27 sand 0  
fill ~9 ~0 ~5 ~11 ~0 ~5 sand 0  
fill ~9 ~0 ~6 ~12 ~0 ~6 sand 0  
fill ~9 ~0 ~7 ~14 ~0 ~7 sand 0  
fill ~9 ~0 ~12 ~12 ~0 ~12 dirt 0  
fill ~9 ~0 ~14 ~17 ~0 ~14 stone 0  
fill ~9 ~0 ~25 ~19 ~0 ~25 stone 0  
fill ~9 ~0 ~26 ~9 ~2 ~26 dirt 0  
fill ~9 ~0 ~28 ~10 ~0 ~28 sand 0  
fill ~10 ~0 ~4 ~10 ~0 ~4 sand 0  
fill ~10 ~0 ~13 ~16 ~0 ~13 stone 0  
fill ~10 ~0 ~21 ~14 ~0 ~21 gravel 0  
fill ~10 ~0 ~22 ~13 ~0 ~22 gravel 0  
fill ~10 ~0 ~23 ~11 ~0 ~23 gravel 0  
fill ~10 ~0 ~26 ~29 ~0 ~26 stone 0  
fill ~10 ~0 ~27 ~29 ~0 ~27 stone 0  
fill ~10 ~0 ~29 ~15 ~0 ~29 sand 0  
fill ~11 ~0 ~11 ~13 ~0 ~11 dirt 0  
fill ~11 ~0 ~20 ~15 ~0 ~20 gravel 0  
fill ~11 ~0 ~28 ~12 ~0 ~28 dirt 0  
fill ~12 ~0 ~10 ~16 ~0 ~10 dirt 0  
fill ~12 ~0 ~19 ~15 ~0 ~19 gravel 0  
fill ~12 ~0 ~23 ~48 ~0 ~23 stone 0  
fill ~13 ~0 ~12 ~16 ~0 ~12 stone 0  
fill ~13 ~0 ~28 ~20 ~0 ~28 stone 0  
fill ~14 ~0 ~11 ~15 ~0 ~11 stone 0  
fill ~14 ~0 ~18 ~15 ~0 ~18 gravel 0  
fill ~14 ~0 ~22 ~33 ~0 ~22 stone 0  
fill ~14 ~0 ~30 ~23 ~0 ~30 sand 0  
fill ~15 ~0 ~21 ~32 ~0 ~21 stone 0  
fill ~16 ~0 ~11 ~21 ~0 ~11 dirt 0  
fill ~16 ~0 ~18 ~33 ~0 ~18 stone 0  
fill ~16 ~0 ~19 ~23 ~0 ~19 stone 0  
fill ~16 ~0 ~20 ~23 ~0 ~20 stone 0  
fill ~16 ~0 ~29 ~17 ~0 ~29 dirt 0  
fill ~16 ~0 ~31 ~20 ~0 ~31 sand 0  
fill ~16 ~0 ~32 ~20 ~0 ~32 sand 0  
fill ~16 ~0 ~33 ~20 ~0 ~33 sand 0  
fill ~16 ~0 ~34 ~20 ~0 ~34 sand 0  
fill ~16 ~0 ~35 ~19 ~0 ~35 sand 0  
fill ~17 ~0 ~10 ~19 ~0 ~10 sand 0  
fill ~17 ~0 ~12 ~21 ~0 ~12 dirt 0  
fill ~17 ~0 ~13 ~21 ~0 ~13 dirt 0  
fill ~17 ~0 ~36 ~19 ~0 ~36 sand 0  
fill ~17 ~0 ~37 ~19 ~0 ~37 sand 0  
fill ~18 ~0 ~4 ~27 ~0 ~4 sand 0  
fill ~18 ~0 ~5 ~25 ~0 ~5 sand 0  
fill ~18 ~0 ~6 ~22 ~0 ~6 sand 0  
fill ~18 ~0 ~7 ~20 ~0 ~7 sand 0  
fill ~18 ~0 ~14 ~22 ~0 ~14 dirt 0  
fill ~18 ~0 ~15 ~22 ~0 ~15 dirt 0  
fill ~18 ~0 ~16 ~18 ~3 ~16 dirt 0  
fill ~18 ~0 ~29 ~18 ~0 ~29 stone 0  
fill ~18 ~0 ~38 ~18 ~0 ~38 sand 0  
fill ~19 ~0 ~16 ~24 ~0 ~16 stone 0  
fill ~19 ~0 ~29 ~19 ~4 ~29 dirt 0  
fill ~20 ~0 ~2 ~32 ~0 ~2 sand 0  
fill ~20 ~0 ~3 ~29 ~0 ~3 sand 0  
fill ~20 ~0 ~10 ~21 ~0 ~10 dirt 0  
fill ~20 ~0 ~25 ~20 ~0 ~25 iron_ore 0  
fill ~20 ~0 ~29 ~31 ~0 ~29 sand 0  
fill ~21 ~0 ~-1 ~22 ~0 ~-1 sand 0  
fill ~21 ~0 ~7 ~21 ~2 ~7 dirt 0  
fill ~21 ~0 ~8 ~21 ~2 ~8 dirt 0  
fill ~21 ~0 ~9 ~21 ~2 ~9 dirt 0  
fill ~21 ~0 ~25 ~21 ~1 ~25 stone 0  
fill ~21 ~0 ~28 ~21 ~3 ~28 dirt 0  
fill ~22 ~0 ~7 ~38 ~0 ~7 stone 0  
fill ~22 ~0 ~8 ~37 ~0 ~8 stone 0  
fill ~22 ~0 ~9 ~37 ~0 ~9 stone 0  
fill ~22 ~0 ~10 ~37 ~0 ~10 stone 0  
fill ~22 ~0 ~11 ~24 ~0 ~11 gravel 0  
fill ~22 ~0 ~12 ~25 ~0 ~12 gravel 0  
fill ~22 ~0 ~13 ~25 ~0 ~13 gravel 0  
fill ~22 ~0 ~25 ~23 ~0 ~25 iron_ore 0  
fill ~22 ~0 ~28 ~22 ~2 ~28 sand 0  
fill ~23 ~0 ~1 ~42 ~0 ~1 sand 0  
fill ~23 ~0 ~6 ~27 ~0 ~6 dirt 0  
fill ~23 ~0 ~14 ~27 ~0 ~14 gravel 0  
fill ~23 ~0 ~15 ~27 ~0 ~15 gravel 0  
fill ~23 ~0 ~24 ~23 ~1 ~24 iron_ore 0  
fill ~23 ~0 ~28 ~26 ~0 ~28 dirt 0  
fill ~24 ~0 ~19 ~24 ~2 ~19 gravel 0  
fill ~24 ~0 ~20 ~24 ~2 ~20 gravel 0  
fill ~24 ~0 ~24 ~32 ~0 ~24 stone 0  
fill ~24 ~0 ~25 ~27 ~0 ~25 stone 0  
fill ~25 ~0 ~0 ~41 ~0 ~0 sand 0  
fill ~25 ~0 ~11 ~37 ~0 ~11 stone 0  
fill ~25 ~0 ~16 ~27 ~0 ~16 gravel 0  
fill ~25 ~0 ~19 ~28 ~0 ~19 stone 0  
fill ~25 ~0 ~20 ~26 ~0 ~20 stone 0  
fill ~26 ~0 ~-2 ~31 ~0 ~-2 sand 0  
fill ~26 ~0 ~-1 ~41 ~0 ~-1 sand 0  
fill ~26 ~0 ~5 ~31 ~0 ~5 dirt 0  
fill ~26 ~0 ~12 ~37 ~0 ~12 stone 0  
fill ~26 ~0 ~13 ~37 ~0 ~13 stone 0  
fill ~27 ~0 ~20 ~28 ~0 ~20 coal_ore 0  
fill ~27 ~0 ~28 ~33 ~0 ~28 sand 0  
fill ~28 ~0 ~4 ~31 ~0 ~4 dirt 0  
fill ~28 ~0 ~6 ~37 ~0 ~6 stone 0  
fill ~28 ~0 ~14 ~47 ~0 ~14 stone 0  
fill ~28 ~0 ~15 ~41 ~0 ~15 stone 0  
fill ~28 ~0 ~16 ~33 ~0 ~16 stone 0  
fill ~28 ~0 ~25 ~28 ~0 ~25 iron_ore 0  
fill ~29 ~0 ~19 ~29 ~2 ~19 coal_ore 0  
fill ~29 ~0 ~20 ~33 ~0 ~20 stone 0  
fill ~29 ~0 ~25 ~30 ~0 ~25 stone 0  
fill ~30 ~0 ~-3 ~31 ~0 ~-3 sand 0  
fill ~30 ~0 ~3 ~31 ~0 ~3 dirt 0  
fill ~30 ~0 ~19 ~32 ~0 ~19 stone 0  
fill ~30 ~0 ~26 ~31 ~0 ~26 dirt 0  
fill ~30 ~0 ~27 ~30 ~2 ~27 dirt 0  
fill ~31 ~0 ~25 ~31 ~2 ~25 dirt 0  
fill ~31 ~0 ~27 ~33 ~0 ~27 sand 0  
fill ~32 ~0 ~-3 ~34 ~0 ~-3 gravel 0  
fill ~32 ~0 ~-2 ~34 ~0 ~-2 gravel 0  
fill ~32 ~0 ~3 ~35 ~0 ~3 stone 0  
fill ~32 ~0 ~4 ~35 ~0 ~4 stone 0  
fill ~32 ~0 ~5 ~36 ~0 ~5 stone 0  
fill ~32 ~0 ~25 ~37 ~0 ~25 sand 0  
fill ~32 ~0 ~26 ~57 ~0 ~26 sand 0  
fill ~33 ~0 ~2 ~33 ~2 ~2 dirt 0  
fill ~33 ~0 ~19 ~33 ~3 ~19 double_stone_slab 0  
fill ~33 ~0 ~21 ~33 ~3 ~21 double_stone_slab 0  
fill ~33 ~0 ~24 ~35 ~0 ~24 dirt 0 
setblock ~34 ~0 ~2 stone 0  
fill ~34 ~0 ~16 ~39 ~0 ~16 double_stone_slab 0  
fill ~34 ~0 ~18 ~43 ~0 ~18 double_stone_slab 0  
fill ~34 ~0 ~19 ~36 ~0 ~19 glass 0  
fill ~34 ~0 ~20 ~35 ~0 ~20 double_stone_slab 0  
fill ~34 ~0 ~21 ~36 ~0 ~21 glass 0  
fill ~34 ~0 ~22 ~43 ~0 ~22 double_stone_slab 0  
fill ~35 ~0 ~-3 ~35 ~0 ~-3 sand 0  
fill ~35 ~0 ~-2 ~38 ~0 ~-2 sand 0  
fill ~35 ~0 ~2 ~43 ~0 ~2 sand 0  
fill ~35 ~0 ~27 ~41 ~0 ~27 sand 0  
fill ~36 ~0 ~3 ~37 ~0 ~3 dirt 0  
fill ~36 ~0 ~4 ~38 ~0 ~4 dirt 0 
setblock ~36 ~0 ~20 glass 0  
fill ~36 ~0 ~24 ~47 ~0 ~24 stone 0  
fill ~36 ~0 ~28 ~40 ~0 ~28 sand 0  
fill ~37 ~0 ~5 ~39 ~0 ~5 dirt 0  
fill ~37 ~0 ~19 ~43 ~0 ~19 double_stone_slab 0  
fill ~37 ~0 ~20 ~43 ~0 ~20 double_stone_slab 0  
fill ~37 ~0 ~21 ~43 ~0 ~21 double_stone_slab 0  
fill ~37 ~0 ~29 ~39 ~0 ~29 sand 0  
fill ~38 ~0 ~3 ~43 ~0 ~3 sand 0  
fill ~38 ~0 ~6 ~40 ~0 ~6 dirt 0  
fill ~38 ~0 ~8 ~42 ~0 ~8 dirt 0  
fill ~38 ~0 ~9 ~42 ~0 ~9 dirt 0  
fill ~38 ~0 ~10 ~41 ~0 ~10 dirt 0  
fill ~38 ~0 ~11 ~41 ~0 ~11 dirt 0  
fill ~38 ~0 ~12 ~40 ~0 ~12 dirt 0  
fill ~38 ~0 ~13 ~39 ~0 ~13 dirt 0  
fill ~38 ~0 ~25 ~38 ~2 ~25 dirt 0  
fill ~38 ~0 ~30 ~38 ~0 ~30 sand 0  
fill ~38 ~0 ~31 ~38 ~0 ~31 sand 0  
fill ~39 ~0 ~4 ~43 ~0 ~4 sand 0  
fill ~39 ~0 ~7 ~41 ~0 ~7 dirt 0 
setblock ~39 ~0 ~17 double_stone_slab 0  
fill ~39 ~0 ~25 ~45 ~0 ~25 sand 0  
fill ~40 ~0 ~5 ~44 ~0 ~5 sand 0  
fill ~40 ~0 ~13 ~46 ~0 ~13 stone 0  
fill ~40 ~0 ~16 ~40 ~0 ~16 stone 0  
fill ~40 ~0 ~17 ~40 ~0 ~17 stone 0  
fill ~41 ~0 ~6 ~44 ~0 ~6 sand 0  
fill ~41 ~0 ~12 ~44 ~0 ~12 stone 0  
fill ~41 ~0 ~16 ~43 ~0 ~16 dirt 0  
fill ~41 ~0 ~17 ~44 ~0 ~17 dirt 0  
fill ~42 ~0 ~7 ~44 ~0 ~7 sand 0  
fill ~42 ~0 ~10 ~42 ~0 ~10 stone 0  
fill ~42 ~0 ~11 ~43 ~0 ~11 stone 0  
fill ~42 ~0 ~15 ~42 ~0 ~15 dirt 0  
fill ~43 ~0 ~8 ~44 ~0 ~8 sand 0  
fill ~43 ~0 ~9 ~45 ~0 ~9 sand 0  
fill ~43 ~0 ~10 ~43 ~2 ~10 dirt 0  
fill ~43 ~0 ~15 ~48 ~0 ~15 stone 0  
fill ~43 ~0 ~27 ~57 ~0 ~27 sand 0  
fill ~44 ~0 ~10 ~45 ~0 ~10 sand 0  
fill ~44 ~0 ~11 ~46 ~0 ~11 sand 0  
fill ~44 ~0 ~16 ~48 ~0 ~16 stone 0  
fill ~44 ~0 ~18 ~44 ~0 ~18 dirt 0  
fill ~44 ~0 ~19 ~44 ~0 ~19 dirt 0  
fill ~44 ~0 ~20 ~44 ~0 ~20 dirt 0  
fill ~44 ~0 ~21 ~48 ~0 ~21 stone 0  
fill ~44 ~0 ~22 ~47 ~0 ~22 stone 0  
fill ~44 ~0 ~28 ~52 ~0 ~28 sand 0  
fill ~45 ~0 ~12 ~45 ~2 ~12 dirt 0  
fill ~45 ~0 ~17 ~48 ~0 ~17 stone 0  
fill ~45 ~0 ~18 ~48 ~0 ~18 stone 0  
fill ~45 ~0 ~19 ~48 ~0 ~19 stone 0  
fill ~45 ~0 ~20 ~48 ~0 ~20 stone 0  
fill ~46 ~0 ~12 ~48 ~0 ~12 sand 0  
fill ~46 ~0 ~25 ~46 ~2 ~25 dirt 0  
fill ~47 ~0 ~13 ~50 ~0 ~13 sand 0  
fill ~47 ~0 ~25 ~57 ~0 ~25 sand 0  
fill ~48 ~0 ~14 ~48 ~2 ~14 dirt 0  
fill ~48 ~0 ~22 ~49 ~0 ~22 dirt 0  
fill ~48 ~0 ~24 ~48 ~2 ~24 dirt 0  
fill ~49 ~0 ~14 ~51 ~0 ~14 sand 0  
fill ~49 ~0 ~15 ~49 ~2 ~15 dirt 0  
fill ~49 ~0 ~16 ~49 ~2 ~16 dirt 0  
fill ~49 ~0 ~17 ~53 ~0 ~17 sand 0  
fill ~49 ~0 ~18 ~54 ~0 ~18 sand 0  
fill ~49 ~0 ~19 ~55 ~0 ~19 sand 0  
fill ~49 ~0 ~20 ~56 ~0 ~20 sand 0  
fill ~49 ~0 ~21 ~49 ~2 ~21 dirt 0  
fill ~49 ~0 ~23 ~49 ~2 ~23 dirt 0  
fill ~49 ~0 ~24 ~57 ~0 ~24 sand 0  
fill ~50 ~0 ~15 ~52 ~0 ~15 sand 0  
fill ~50 ~0 ~16 ~53 ~0 ~16 sand 0  
fill ~50 ~0 ~21 ~57 ~0 ~21 sand 0  
fill ~50 ~0 ~22 ~57 ~0 ~22 sand 0  
fill ~50 ~0 ~23 ~57 ~0 ~23 sand 0  
fill ~-2 ~1 ~19 ~3 ~1 ~19 sand 0  
fill ~0 ~1 ~20 ~3 ~1 ~20 sand 0  
fill ~1 ~1 ~18 ~3 ~1 ~18 sand 0  
fill ~1 ~1 ~21 ~3 ~1 ~21 sand 0  
fill ~2 ~1 ~22 ~4 ~1 ~22 sand 0  
fill ~2 ~1 ~23 ~5 ~1 ~23 sand 0  
fill ~3 ~1 ~17 ~4 ~1 ~17 sand 0  
fill ~4 ~1 ~15 ~5 ~1 ~15 sand 0  
fill ~4 ~1 ~16 ~5 ~1 ~16 sand 0  
fill ~4 ~1 ~18 ~6 ~1 ~18 dirt 0  
fill ~4 ~1 ~21 ~5 ~1 ~21 dirt 0  
fill ~5 ~1 ~12 ~8 ~1 ~12 sand 0  
fill ~5 ~1 ~13 ~7 ~1 ~13 sand 0  
fill ~5 ~1 ~14 ~6 ~1 ~14 sand 0  
fill ~5 ~1 ~19 ~5 ~3 ~19 dirt 0  
fill ~5 ~1 ~20 ~5 ~3 ~20 dirt 0  
fill ~5 ~1 ~24 ~7 ~1 ~24 sand 0  
fill ~6 ~1 ~11 ~10 ~1 ~11 sand 0  
fill ~6 ~1 ~17 ~7 ~1 ~17 dirt 0  
fill ~6 ~1 ~19 ~22 ~1 ~19 stone 0  
fill ~6 ~1 ~20 ~22 ~1 ~20 stone 0  
fill ~6 ~1 ~21 ~22 ~1 ~21 stone 0  
fill ~6 ~1 ~22 ~6 ~3 ~22 dirt 0  
fill ~7 ~1 ~10 ~11 ~1 ~10 sand 0  
fill ~7 ~1 ~14 ~9 ~1 ~14 dirt 0  
fill ~7 ~1 ~15 ~8 ~1 ~15 dirt 0  
fill ~7 ~1 ~16 ~7 ~3 ~16 dirt 0  
fill ~7 ~1 ~18 ~17 ~1 ~18 stone 0  
fill ~7 ~1 ~22 ~23 ~1 ~22 stone 0  
fill ~7 ~1 ~23 ~8 ~1 ~23 dirt 0  
fill ~8 ~1 ~13 ~26 ~1 ~13 dirt 0  
fill ~8 ~1 ~16 ~16 ~1 ~16 stone 0  
fill ~8 ~1 ~17 ~16 ~1 ~17 stone 0  
fill ~8 ~1 ~24 ~8 ~3 ~24 dirt 0  
fill ~8 ~1 ~25 ~8 ~2 ~25 sand 0  
fill ~8 ~1 ~26 ~8 ~1 ~25 sand 0  
fill ~9 ~1 ~9 ~20 ~1 ~9 sand 0  
fill ~9 ~1 ~12 ~27 ~1 ~12 dirt 0  
fill ~9 ~1 ~15 ~15 ~1 ~15 stone 0  
fill ~9 ~1 ~23 ~33 ~1 ~23 stone 0  
fill ~9 ~1 ~24 ~20 ~1 ~24 stone 0  
fill ~9 ~1 ~25 ~9 ~3 ~25 dirt 0  
fill ~9 ~1 ~27 ~9 ~2 ~27 sand 0  
fill ~10 ~1 ~8 ~13 ~1 ~8 sand 0  
fill ~10 ~1 ~14 ~14 ~1 ~14 stone 0  
fill ~10 ~1 ~25 ~21 ~1 ~25 stone 0  
fill ~10 ~1 ~26 ~27 ~1 ~26 stone 0  
fill ~10 ~1 ~27 ~27 ~1 ~27 stone 0  
fill ~10 ~1 ~28 ~10 ~2 ~28 sand 0  
fill ~11 ~1 ~11 ~28 ~1 ~11 dirt 0  
fill ~11 ~1 ~28 ~13 ~1 ~28 dirt 0  
fill ~12 ~1 ~10 ~16 ~1 ~10 dirt 0  
fill ~14 ~1 ~28 ~18 ~1 ~28 stone 0  
fill ~14 ~1 ~29 ~15 ~1 ~29 sand 0  
fill ~15 ~1 ~14 ~25 ~1 ~14 dirt 0  
fill ~16 ~1 ~15 ~25 ~1 ~15 dirt 0  
fill ~16 ~1 ~29 ~19 ~1 ~29 dirt 0  
fill ~17 ~1 ~10 ~19 ~1 ~10 sand 0  
fill ~17 ~1 ~16 ~17 ~3 ~16 dirt 0  
fill ~17 ~1 ~17 ~22 ~1 ~17 dirt 0  
fill ~17 ~1 ~30 ~17 ~2 ~30 sand 0  
fill ~17 ~1 ~31 ~17 ~1 ~32 sand 0  
fill ~17 ~1 ~35 ~18 ~1 ~35 sand 0  
fill ~18 ~1 ~8 ~20 ~1 ~8 sand 0  
fill ~18 ~1 ~18 ~19 ~1 ~18 dirt 0  
fill ~18 ~1 ~30 ~18 ~2 ~30 gravel 0  
fill ~18 ~1 ~31 ~18 ~1 ~30 gravel 0  
fill ~18 ~1 ~32 ~19 ~1 ~32 sand 0  
fill ~18 ~1 ~33 ~18 ~1 ~36 sand 0  
fill ~19 ~1 ~5 ~25 ~1 ~5 sand 0  
fill ~19 ~1 ~6 ~22 ~1 ~6 sand 0  
fill ~19 ~1 ~7 ~20 ~1 ~7 sand 0  
fill ~19 ~1 ~16 ~23 ~1 ~16 dirt 0  
fill ~19 ~1 ~28 ~21 ~1 ~28 dirt 0  
fill ~19 ~1 ~30 ~20 ~1 ~30 sand 0  
fill ~19 ~1 ~31 ~19 ~1 ~30 sand 0  
fill ~20 ~1 ~10 ~29 ~1 ~10 dirt 0  
fill ~20 ~1 ~18 ~21 ~1 ~18 stone 0  
fill ~20 ~1 ~29 ~21 ~1 ~29 sand 0  
fill ~21 ~1 ~3 ~29 ~1 ~3 sand 0  
fill ~21 ~1 ~4 ~27 ~1 ~4 sand 0  
fill ~21 ~1 ~24 ~21 ~2 ~24 iron_ore 0  
fill ~22 ~1 ~7 ~23 ~1 ~7 dirt 0  
fill ~22 ~1 ~8 ~24 ~1 ~8 dirt 0  
fill ~22 ~1 ~9 ~42 ~1 ~9 dirt 0  
fill ~22 ~1 ~18 ~25 ~1 ~18 gravel 0  
fill ~22 ~1 ~24 ~22 ~2 ~24 stone 0  
fill ~22 ~1 ~25 ~23 ~1 ~25 iron_ore 0  
fill ~23 ~1 ~6 ~40 ~1 ~6 dirt 0  
fill ~23 ~1 ~17 ~24 ~1 ~17 gravel 0  
fill ~23 ~1 ~19 ~23 ~2 ~19 gravel 0  
fill ~23 ~1 ~20 ~23 ~2 ~20 gravel 0  
fill ~23 ~1 ~21 ~26 ~1 ~21 gravel 0  
fill ~23 ~1 ~28 ~26 ~1 ~28 dirt 0  
fill ~24 ~1 ~2 ~32 ~1 ~2 sand 0  
fill ~24 ~1 ~7 ~27 ~1 ~7 stone 0  
fill ~24 ~1 ~16 ~25 ~1 ~16 stone 0  
fill ~24 ~1 ~22 ~26 ~1 ~22 gravel 0  
fill ~24 ~1 ~24 ~30 ~1 ~24 stone 0  
fill ~24 ~1 ~25 ~28 ~1 ~25 stone 0  
fill ~25 ~1 ~8 ~27 ~1 ~8 stone 0  
fill ~25 ~1 ~17 ~33 ~1 ~17 stone 0  
fill ~25 ~1 ~19 ~25 ~2 ~19 gravel 0  
fill ~25 ~1 ~20 ~26 ~1 ~20 gravel 0  
fill ~26 ~1 ~1 ~40 ~1 ~1 sand 0  
fill ~26 ~1 ~5 ~35 ~1 ~5 dirt 0  
fill ~26 ~1 ~14 ~37 ~1 ~14 stone 0  
fill ~26 ~1 ~15 ~26 ~1 ~16 gravel 0  
fill ~26 ~1 ~18 ~32 ~1 ~18 stone 0  
fill ~26 ~1 ~19 ~27 ~1 ~19 stone 0  
fill ~27 ~1 ~0 ~31 ~1 ~0 sand 0  
fill ~27 ~1 ~13 ~37 ~1 ~13 stone 0  
fill ~27 ~1 ~15 ~33 ~1 ~15 stone 0  
fill ~27 ~1 ~16 ~32 ~1 ~16 stone 0  
fill ~27 ~1 ~20 ~30 ~1 ~20 coal_ore 0  
fill ~27 ~1 ~21 ~32 ~1 ~21 stone 0  
fill ~27 ~1 ~22 ~32 ~1 ~22 stone 0  
fill ~27 ~1 ~28 ~31 ~1 ~28 sand 0  
fill ~28 ~1 ~4 ~38 ~1 ~4 dirt 0  
fill ~28 ~1 ~7 ~41 ~1 ~7 dirt 0  
fill ~28 ~1 ~8 ~42 ~1 ~8 dirt 0  
fill ~28 ~1 ~12 ~32 ~1 ~12 stone 0 
setblock ~28 ~1 ~19 coal_ore 0  
fill ~28 ~1 ~26 ~31 ~1 ~26 dirt 0  
fill ~28 ~1 ~27 ~30 ~1 ~27 dirt 0  
fill ~29 ~1 ~-1 ~31 ~1 ~-1 sand 0  
fill ~29 ~1 ~11 ~30 ~1 ~11 stone 0  
fill ~29 ~1 ~25 ~31 ~1 ~25 dirt 0  
fill ~30 ~1 ~3 ~37 ~1 ~3 dirt 0 
setblock ~30 ~1 ~10 stone 0  
fill ~30 ~1 ~19 ~31 ~1 ~19 coal_ore 0  
fill ~31 ~1 ~-3 ~31 ~1 ~-2 fence 0  
fill ~31 ~1 ~10 ~43 ~1 ~10 dirt 0  
fill ~31 ~1 ~11 ~43 ~1 ~11 dirt 0  
fill ~31 ~1 ~20 ~32 ~1 ~20 stone 0  
fill ~31 ~1 ~24 ~37 ~1 ~24 dirt 0  
fill ~31 ~1 ~27 ~32 ~1 ~27 sand 0  
fill ~32 ~1 ~-1 ~34 ~1 ~-1 gravel 0  
fill ~32 ~1 ~0 ~34 ~1 ~0 gravel 0  
fill ~32 ~1 ~19 ~32 ~3 ~19 stone 0  
fill ~32 ~1 ~25 ~37 ~1 ~25 sand 0  
fill ~32 ~1 ~26 ~33 ~1 ~26 sand 0  
fill ~33 ~1 ~12 ~34 ~1 ~12 dirt 0  
fill ~33 ~1 ~16 ~34 ~1 ~16 double_stone_slab 0  
fill ~33 ~1 ~18 ~33 ~3 ~18 double_stone_slab 0  
fill ~33 ~1 ~20 ~33 ~3 ~20 double_stone_slab 0  
fill ~33 ~1 ~22 ~33 ~3 ~22 double_stone_slab 0  
fill ~34 ~1 ~2 ~34 ~2 ~2 dirt 0  
fill ~34 ~1 ~15 ~39 ~1 ~15 double_stone_slab 0  
fill ~34 ~1 ~17 ~38 ~1 ~17 double_stone_slab 0 
setblock ~34 ~1 ~18 grass 0 
setblock ~34 ~1 ~20 bed 9 
setblock ~34 ~1 ~22 grass 0  
fill ~34 ~1 ~23 ~43 ~1 ~23 double_stone_slab 0  
fill ~35 ~1 ~-3 ~35 ~1 ~-2 fence 0  
fill ~35 ~1 ~-1 ~38 ~1 ~-1 sand 0  
fill ~35 ~1 ~0 ~40 ~1 ~0 sand 0  
fill ~35 ~1 ~2 ~40 ~1 ~2 sand 0  
fill ~35 ~1 ~12 ~37 ~1 ~12 stone 0 
setblock ~35 ~1 ~16 stone_slab 0 
setblock ~35 ~1 ~20 bed 1 
setblock ~36 ~1 ~5 stone 0  
fill ~37 ~1 ~5 ~39 ~1 ~5 dirt 0  
fill ~37 ~1 ~26 ~38 ~1 ~26 sand 0  
fill ~38 ~1 ~3 ~41 ~1 ~3 sand 0  
fill ~38 ~1 ~12 ~41 ~1 ~12 dirt 0  
fill ~38 ~1 ~13 ~40 ~1 ~13 dirt 0  
fill ~38 ~1 ~14 ~39 ~1 ~14 dirt 0 
setblock ~38 ~1 ~24 stone 0  
fill ~39 ~1 ~4 ~42 ~1 ~4 sand 0 
setblock ~39 ~1 ~17 iron_door 1  
fill ~39 ~1 ~25 ~45 ~1 ~25 sand 0  
fill ~40 ~1 ~5 ~42 ~1 ~5 sand 0  
fill ~40 ~1 ~14 ~46 ~1 ~14 stone 0  
fill ~40 ~1 ~15 ~47 ~1 ~15 stone 0  
fill ~40 ~1 ~16 ~40 ~2 ~16 double_stone_slab 0  
fill ~40 ~1 ~17 ~43 ~1 ~17 double_stone_slab 0  
fill ~40 ~1 ~24 ~44 ~1 ~24 stone 0  
fill ~41 ~1 ~6 ~42 ~1 ~6 sand 0  
fill ~41 ~1 ~13 ~44 ~1 ~13 stone 0  
fill ~41 ~1 ~16 ~47 ~1 ~16 stone 0  
fill ~42 ~1 ~7 ~43 ~1 ~7 sand 0 
setblock ~42 ~1 ~12 stone 0  
fill ~43 ~1 ~8 ~43 ~0 ~8 sand 0  
fill ~43 ~1 ~9 ~43 ~2 ~9 sand 0  
fill ~43 ~1 ~12 ~45 ~1 ~12 dirt 0 
setblock ~43 ~1 ~20 crafting_table 0  
fill ~44 ~1 ~10 ~44 ~0 ~10 sand 0  
fill ~44 ~1 ~11 ~44 ~2 ~11 sand 0  
fill ~44 ~1 ~17 ~47 ~1 ~17 stone 0  
fill ~44 ~1 ~18 ~44 ~3 ~18 double_stone_slab 0  
fill ~44 ~1 ~19 ~44 ~3 ~19 double_stone_slab 0  
fill ~44 ~1 ~20 ~44 ~3 ~20 double_stone_slab 0  
fill ~44 ~1 ~21 ~44 ~3 ~21 double_stone_slab 0  
fill ~44 ~1 ~22 ~44 ~3 ~22 double_stone_slab 0  
fill ~44 ~1 ~23 ~47 ~1 ~23 stone 0  
fill ~45 ~1 ~13 ~46 ~1 ~13 dirt 0  
fill ~45 ~1 ~18 ~47 ~1 ~18 stone 0  
fill ~45 ~1 ~19 ~48 ~1 ~19 stone 0  
fill ~45 ~1 ~20 ~47 ~1 ~20 stone 0  
fill ~45 ~1 ~21 ~47 ~1 ~21 stone 0  
fill ~45 ~1 ~22 ~46 ~1 ~22 stone 0  
fill ~45 ~1 ~24 ~48 ~1 ~24 dirt 0  
fill ~45 ~1 ~26 ~48 ~1 ~26 sand 0  
fill ~46 ~1 ~12 ~46 ~0 ~12 sand 0  
fill ~47 ~1 ~13 ~48 ~1 ~13 sand 0  
fill ~47 ~1 ~14 ~47 ~3 ~14 dirt 0  
fill ~47 ~1 ~22 ~49 ~1 ~22 dirt 0  
fill ~47 ~1 ~25 ~50 ~1 ~25 sand 0  
fill ~48 ~1 ~15 ~48 ~3 ~15 dirt 0  
fill ~48 ~1 ~16 ~48 ~3 ~16 dirt 0  
fill ~48 ~1 ~17 ~48 ~3 ~17 dirt 0  
fill ~48 ~1 ~18 ~48 ~3 ~18 dirt 0  
fill ~48 ~1 ~20 ~48 ~3 ~20 dirt 0  
fill ~48 ~1 ~21 ~48 ~3 ~21 dirt 0  
fill ~48 ~1 ~23 ~48 ~3 ~23 dirt 0  
fill ~49 ~1 ~14 ~49 ~0 ~14 sand 0  
fill ~49 ~1 ~17 ~49 ~2 ~17 sand 0  
fill ~49 ~1 ~18 ~49 ~2 ~18 sand 0  
fill ~49 ~1 ~19 ~49 ~0 ~19 sand 0  
fill ~49 ~1 ~20 ~49 ~2 ~20 sand 0  
fill ~49 ~1 ~24 ~52 ~1 ~24 sand 0  
fill ~50 ~1 ~15 ~51 ~1 ~15 sand 0  
fill ~50 ~1 ~16 ~50 ~0 ~16 sand 0  
fill ~50 ~1 ~21 ~50 ~0 ~21 sand 0  
fill ~50 ~1 ~22 ~52 ~1 ~22 sand 0  
fill ~50 ~1 ~23 ~52 ~1 ~23 sand 0  
fill ~2 ~2 ~19 ~3 ~2 ~19 sand 0 
setblock ~3 ~2 ~18 sand 0  
fill ~3 ~2 ~20 ~3 ~2 ~21 sand 0 
setblock ~4 ~2 ~17 sand 0  
fill ~4 ~2 ~18 ~8 ~2 ~18 dirt 0  
fill ~4 ~2 ~21 ~8 ~2 ~21 dirt 0  
fill ~4 ~2 ~22 ~4 ~2 ~23 sand 0  
fill ~5 ~2 ~15 ~5 ~2 ~16 sand 0 
setblock ~5 ~2 ~23 sand 0  
fill ~6 ~2 ~13 ~7 ~2 ~13 sand 0  
fill ~6 ~2 ~14 ~6 ~2 ~13 sand 0  
fill ~6 ~2 ~17 ~8 ~2 ~17 dirt 0  
fill ~6 ~2 ~19 ~8 ~2 ~19 dirt 0  
fill ~6 ~2 ~20 ~8 ~2 ~20 dirt 0  
fill ~7 ~2 ~12 ~8 ~2 ~12 sand 0  
fill ~7 ~2 ~14 ~39 ~2 ~14 dirt 0  
fill ~7 ~2 ~15 ~10 ~2 ~15 dirt 0  
fill ~7 ~2 ~22 ~8 ~2 ~22 dirt 0  
fill ~7 ~2 ~23 ~12 ~2 ~23 dirt 0 
setblock ~7 ~2 ~24 sand 0  
fill ~8 ~2 ~11 ~10 ~2 ~11 sand 0  
fill ~8 ~2 ~13 ~46 ~2 ~13 dirt 0  
fill ~8 ~2 ~16 ~10 ~2 ~16 dirt 0  
fill ~9 ~2 ~12 ~45 ~2 ~12 dirt 0  
fill ~9 ~2 ~17 ~9 ~2 ~22 stone 0  
fill ~9 ~2 ~24 ~13 ~2 ~24 dirt 0  
fill ~10 ~2 ~10 ~11 ~2 ~10 sand 0  
fill ~10 ~2 ~17 ~11 ~2 ~17 coal_ore 0  
fill ~10 ~2 ~18 ~11 ~2 ~18 coal_ore 0  
fill ~10 ~2 ~19 ~10 ~3 ~19 stone 0  
fill ~10 ~2 ~20 ~16 ~2 ~20 stone 0  
fill ~10 ~2 ~21 ~16 ~2 ~21 stone 0  
fill ~10 ~2 ~22 ~16 ~2 ~22 stone 0  
fill ~10 ~2 ~25 ~10 ~0 ~25 stone 0  
fill ~10 ~2 ~26 ~12 ~2 ~26 stone 0  
fill ~10 ~2 ~27 ~10 ~4 ~27 dirt 0  
fill ~11 ~2 ~9 ~12 ~2 ~9 sand 0  
fill ~11 ~2 ~11 ~43 ~2 ~11 dirt 0  
fill ~11 ~2 ~15 ~13 ~2 ~15 stone 0  
fill ~11 ~2 ~16 ~14 ~2 ~16 stone 0  
fill ~11 ~2 ~19 ~12 ~2 ~19 coal_ore 0  
fill ~11 ~2 ~25 ~13 ~2 ~25 dirt 0  
fill ~11 ~2 ~27 ~20 ~2 ~27 stone 0  
fill ~11 ~2 ~28 ~21 ~2 ~28 dirt 0  
fill ~12 ~2 ~10 ~16 ~2 ~10 dirt 0  
fill ~12 ~2 ~17 ~15 ~2 ~17 stone 0  
fill ~12 ~2 ~18 ~15 ~2 ~18 stone 0  
fill ~13 ~2 ~19 ~16 ~2 ~19 stone 0  
fill ~13 ~2 ~23 ~16 ~2 ~23 stone 0  
fill ~13 ~2 ~26 ~13 ~5 ~26 dirt 0  
fill ~14 ~2 ~15 ~32 ~2 ~15 dirt 0  
fill ~14 ~2 ~24 ~20 ~2 ~24 stone 0  
fill ~14 ~2 ~25 ~20 ~2 ~25 stone 0  
fill ~14 ~2 ~26 ~20 ~2 ~26 stone 0  
fill ~15 ~2 ~16 ~30 ~2 ~16 dirt 0 
setblock ~15 ~2 ~29 sand 0  
fill ~16 ~2 ~17 ~27 ~2 ~17 dirt 0  
fill ~16 ~2 ~18 ~25 ~2 ~18 dirt 0  
fill ~16 ~2 ~29 ~19 ~2 ~29 dirt 0  
fill ~17 ~2 ~10 ~19 ~2 ~10 sand 0  
fill ~17 ~2 ~19 ~21 ~2 ~19 dirt 0  
fill ~17 ~2 ~20 ~20 ~2 ~20 dirt 0  
fill ~17 ~2 ~21 ~20 ~2 ~21 dirt 0  
fill ~17 ~2 ~22 ~19 ~2 ~22 dirt 0  
fill ~17 ~2 ~23 ~19 ~2 ~23 dirt 0 
setblock ~17 ~2 ~31 fence 0 
setblock ~18 ~2 ~35 sand 0  
fill ~19 ~2 ~9 ~20 ~2 ~9 sand 0  
fill ~19 ~2 ~30 ~19 ~3 ~30 sand 0 
setblock ~19 ~2 ~31 fence 0  
fill ~20 ~2 ~6 ~22 ~2 ~6 sand 0  
fill ~20 ~2 ~7 ~20 ~2 ~9 sand 0  
fill ~20 ~2 ~10 ~43 ~2 ~10 dirt 0  
fill ~20 ~2 ~22 ~22 ~2 ~22 stone 0  
fill ~20 ~2 ~23 ~23 ~2 ~23 stone 0  
fill ~20 ~2 ~29 ~20 ~0 ~29 sand 0  
fill ~21 ~2 ~20 ~22 ~2 ~20 stone 0  
fill ~21 ~2 ~21 ~22 ~2 ~21 stone 0  
fill ~21 ~2 ~25 ~22 ~2 ~25 dirt 0  
fill ~21 ~2 ~26 ~23 ~2 ~26 dirt 0  
fill ~21 ~2 ~27 ~23 ~2 ~27 dirt 0  
fill ~21 ~2 ~29 ~21 ~3 ~29 dirt 0  
fill ~22 ~2 ~4 ~27 ~2 ~4 sand 0  
fill ~22 ~2 ~5 ~25 ~2 ~5 sand 0  
fill ~22 ~2 ~7 ~41 ~2 ~7 dirt 0  
fill ~22 ~2 ~8 ~42 ~2 ~8 dirt 0  
fill ~22 ~2 ~9 ~42 ~2 ~9 dirt 0 
setblock ~22 ~2 ~19 gravel 0  
fill ~23 ~2 ~6 ~40 ~2 ~6 dirt 0  
fill ~23 ~2 ~21 ~27 ~2 ~21 gravel 0  
fill ~23 ~2 ~22 ~27 ~2 ~22 gravel 0  
fill ~23 ~2 ~24 ~24 ~2 ~24 stone 0  
fill ~23 ~2 ~25 ~26 ~2 ~25 stone 0  
fill ~23 ~2 ~28 ~26 ~2 ~28 dirt 0  
fill ~24 ~2 ~23 ~27 ~2 ~23 gravel 0  
fill ~24 ~2 ~26 ~26 ~2 ~26 stone 0  
fill ~24 ~2 ~27 ~26 ~2 ~27 stone 0  
fill ~25 ~2 ~3 ~29 ~2 ~3 sand 0  
fill ~25 ~2 ~20 ~26 ~2 ~20 gravel 0  
fill ~25 ~2 ~24 ~26 ~2 ~24 gravel 0  
fill ~26 ~2 ~5 ~39 ~2 ~5 dirt 0  
fill ~26 ~2 ~18 ~32 ~2 ~18 stone 0 
setblock ~26 ~2 ~19 gravel 0  
fill ~27 ~2 ~2 ~32 ~2 ~2 sand 0  
fill ~27 ~2 ~19 ~28 ~2 ~19 stone 0  
fill ~27 ~2 ~20 ~28 ~2 ~20 stone 0  
fill ~27 ~2 ~24 ~28 ~2 ~24 stone 0  
fill ~27 ~2 ~25 ~31 ~2 ~25 dirt 0  
fill ~27 ~2 ~26 ~31 ~2 ~26 dirt 0  
fill ~27 ~2 ~27 ~30 ~2 ~27 dirt 0  
fill ~27 ~2 ~28 ~29 ~2 ~28 sand 0  
fill ~28 ~2 ~1 ~31 ~2 ~1 sand 0  
fill ~28 ~2 ~4 ~38 ~2 ~4 dirt 0  
fill ~28 ~2 ~17 ~32 ~2 ~17 stone 0  
fill ~28 ~2 ~21 ~32 ~2 ~21 stone 0  
fill ~28 ~2 ~22 ~32 ~2 ~22 stone 0  
fill ~28 ~2 ~23 ~31 ~2 ~23 stone 0 
setblock ~29 ~2 ~20 coal_ore 0  
fill ~29 ~2 ~24 ~38 ~2 ~24 dirt 0  
fill ~30 ~2 ~3 ~37 ~2 ~3 dirt 0  
fill ~30 ~2 ~19 ~30 ~1 ~19 coal_ore 0  
fill ~30 ~2 ~20 ~32 ~2 ~20 stone 0  
fill ~31 ~2 ~-1 ~31 ~2 ~0 fence 0 
setblock ~31 ~2 ~16 stone 0 
setblock ~31 ~2 ~19 stone 0  
fill ~31 ~2 ~27 ~31 ~0 ~27 sand 0  
fill ~32 ~2 ~1 ~34 ~2 ~1 gravel 0 
setblock ~32 ~2 ~16 double_stone_slab 0  
fill ~32 ~2 ~23 ~33 ~2 ~23 dirt 0  
fill ~32 ~2 ~25 ~33 ~2 ~25 sand 0  
fill ~32 ~2 ~26 ~32 ~0 ~26 sand 0  
fill ~33 ~2 ~15 ~39 ~2 ~15 double_stone_slab 0 
setblock ~33 ~2 ~16 stone_slab 0  
fill ~33 ~2 ~17 ~38 ~2 ~17 double_stone_slab 0 
setblock ~34 ~2 ~18 red_flower 0 
setblock ~34 ~2 ~22 red_flower 0  
fill ~34 ~2 ~23 ~43 ~2 ~23 double_stone_slab 0  
fill ~35 ~2 ~-1 ~35 ~2 ~0 fence 0  
fill ~35 ~2 ~1 ~38 ~2 ~1 sand 0  
fill ~35 ~2 ~2 ~39 ~2 ~2 sand 0  
fill ~36 ~2 ~0 ~37 ~2 ~0 sand 0  
fill ~36 ~2 ~25 ~37 ~2 ~25 sand 0  
fill ~38 ~2 ~3 ~39 ~2 ~3 sand 0  
fill ~39 ~2 ~4 ~40 ~2 ~4 sand 0 
setblock ~39 ~2 ~16 stone_button 2 
setblock ~39 ~2 ~17 iron_door 9  
fill ~39 ~2 ~25 ~45 ~2 ~25 sand 0  
fill ~40 ~2 ~5 ~41 ~2 ~5 sand 0  
fill ~40 ~2 ~14 ~44 ~2 ~14 stone 0  
fill ~40 ~2 ~15 ~46 ~2 ~15 stone 0  
fill ~40 ~2 ~17 ~43 ~2 ~17 double_stone_slab 0  
fill ~40 ~2 ~24 ~48 ~2 ~24 dirt 0  
fill ~41 ~2 ~6 ~42 ~2 ~6 sand 0  
fill ~41 ~2 ~16 ~47 ~2 ~16 stone 0  
fill ~42 ~2 ~7 ~42 ~0 ~7 sand 0 
setblock ~43 ~2 ~18 torch 2 
setblock ~43 ~2 ~22 torch 2  
fill ~44 ~2 ~17 ~47 ~2 ~17 stone 0  
fill ~44 ~2 ~23 ~46 ~2 ~23 stone 0  
fill ~45 ~2 ~14 ~48 ~2 ~14 dirt 0  
fill ~45 ~2 ~18 ~47 ~2 ~18 stone 0  
fill ~45 ~2 ~19 ~47 ~2 ~19 stone 0  
fill ~45 ~2 ~20 ~47 ~2 ~20 stone 0  
fill ~45 ~2 ~21 ~46 ~2 ~21 stone 0  
fill ~45 ~2 ~22 ~45 ~3 ~22 stone 0  
fill ~46 ~2 ~22 ~49 ~2 ~22 dirt 0  
fill ~47 ~2 ~13 ~47 ~0 ~13 sand 0  
fill ~47 ~2 ~15 ~47 ~4 ~15 dirt 0  
fill ~47 ~2 ~21 ~47 ~5 ~21 dirt 0  
fill ~47 ~2 ~23 ~47 ~5 ~23 dirt 0  
fill ~47 ~2 ~25 ~48 ~2 ~25 sand 0  
fill ~48 ~2 ~19 ~48 ~4 ~19 dirt 0  
fill ~49 ~2 ~24 ~50 ~2 ~24 sand 0  
fill ~50 ~2 ~15 ~50 ~0 ~15 sand 0  
fill ~50 ~2 ~22 ~50 ~0 ~22 sand 0  
fill ~50 ~2 ~23 ~51 ~2 ~23 sand 0  
fill ~4 ~3 ~18 ~5 ~3 ~18 grass 0  
fill ~4 ~3 ~19 ~4 ~3 ~21 grass 0 
setblock ~5 ~3 ~17 grass 0  
fill ~5 ~3 ~21 ~5 ~3 ~22 grass 0  
fill ~6 ~3 ~15 ~6 ~3 ~16 grass 0  
fill ~6 ~3 ~17 ~30 ~3 ~17 dirt 0  
fill ~6 ~3 ~18 ~9 ~3 ~18 dirt 0  
fill ~6 ~3 ~19 ~9 ~3 ~19 dirt 0  
fill ~6 ~3 ~20 ~32 ~3 ~20 dirt 0  
fill ~6 ~3 ~21 ~29 ~3 ~21 dirt 0  
fill ~7 ~3 ~14 ~8 ~3 ~14 grass 0  
fill ~7 ~3 ~15 ~30 ~3 ~15 dirt 0  
fill ~7 ~3 ~22 ~28 ~3 ~22 dirt 0  
fill ~7 ~3 ~23 ~28 ~3 ~23 dirt 0  
fill ~8 ~3 ~13 ~9 ~3 ~13 grass 0  
fill ~8 ~3 ~16 ~29 ~3 ~16 dirt 0  
fill ~9 ~3 ~12 ~12 ~3 ~12 grass 0  
fill ~9 ~3 ~14 ~47 ~3 ~14 dirt 0  
fill ~9 ~3 ~24 ~32 ~3 ~24 dirt 0 
setblock ~9 ~3 ~26 grass 0  
fill ~10 ~3 ~13 ~46 ~3 ~13 dirt 0  
fill ~10 ~3 ~18 ~11 ~3 ~18 coal_ore 0  
fill ~10 ~3 ~25 ~30 ~3 ~25 dirt 0  
fill ~10 ~3 ~26 ~29 ~3 ~26 dirt 0  
fill ~11 ~3 ~11 ~13 ~3 ~11 grass 0  
fill ~11 ~3 ~19 ~12 ~3 ~19 coal_ore 0  
fill ~11 ~3 ~27 ~29 ~3 ~27 dirt 0  
fill ~11 ~3 ~28 ~12 ~3 ~28 grass 0  
fill ~12 ~3 ~10 ~19 ~3 ~10 grass 0  
fill ~12 ~3 ~18 ~30 ~3 ~18 dirt 0  
fill ~13 ~3 ~12 ~44 ~3 ~12 dirt 0  
fill ~13 ~3 ~19 ~31 ~3 ~19 dirt 0  
fill ~13 ~3 ~28 ~21 ~3 ~28 dirt 0  
fill ~14 ~3 ~11 ~15 ~3 ~11 dirt 0  
fill ~16 ~3 ~11 ~18 ~3 ~11 grass 0 
setblock ~16 ~3 ~29 grass 0 
setblock ~17 ~3 ~29 dirt 0 
setblock ~17 ~3 ~30 grass 0 
setblock ~17 ~3 ~31 torch 5 
setblock ~18 ~3 ~29 gravel 0 
setblock ~18 ~3 ~35 torch 5  
fill ~19 ~3 ~9 ~21 ~3 ~9 grass 0  
fill ~19 ~3 ~11 ~43 ~3 ~11 dirt 0 
setblock ~19 ~3 ~31 torch 5  
fill ~20 ~3 ~10 ~42 ~3 ~10 dirt 0  
fill ~20 ~3 ~29 ~20 ~4 ~29 dirt 0  
fill ~21 ~3 ~7 ~21 ~3 ~9 grass 0  
fill ~22 ~3 ~7 ~39 ~3 ~7 dirt 0  
fill ~22 ~3 ~8 ~40 ~3 ~8 dirt 0  
fill ~22 ~3 ~9 ~41 ~3 ~9 dirt 0  
fill ~23 ~3 ~5 ~25 ~3 ~5 sand 0 
setblock ~23 ~3 ~6 grass 0  
fill ~23 ~3 ~28 ~26 ~3 ~28 grass 0 
setblock ~24 ~3 ~6 dirt 0 
setblock ~25 ~3 ~6 grass 0  
fill ~26 ~3 ~4 ~27 ~3 ~4 sand 0  
fill ~26 ~3 ~5 ~29 ~3 ~5 grass 0  
fill ~26 ~3 ~6 ~37 ~3 ~6 dirt 0  
fill ~28 ~3 ~3 ~29 ~3 ~3 sand 0  
fill ~28 ~3 ~4 ~29 ~3 ~4 grass 0  
fill ~29 ~3 ~22 ~30 ~3 ~22 stone 0  
fill ~29 ~3 ~23 ~30 ~3 ~23 stone 0  
fill ~30 ~3 ~2 ~31 ~3 ~2 sand 0 
setblock ~30 ~3 ~3 grass 0  
fill ~30 ~3 ~4 ~35 ~3 ~4 dirt 0  
fill ~30 ~3 ~5 ~36 ~3 ~5 dirt 0  
fill ~30 ~3 ~16 ~30 ~7 ~16 double_stone_slab 0 
setblock ~30 ~3 ~21 stone 0  
fill ~30 ~3 ~26 ~31 ~3 ~26 grass 0  
fill ~30 ~3 ~27 ~30 ~3 ~26 grass 0 
setblock ~31 ~3 ~-1 torch 5 
setblock ~31 ~3 ~1 fence 0  
fill ~31 ~3 ~3 ~35 ~3 ~3 dirt 0  
fill ~31 ~3 ~15 ~38 ~3 ~15 double_stone_slab 0 
setblock ~31 ~3 ~16 stone_slab 0  
fill ~31 ~3 ~17 ~43 ~3 ~17 double_stone_slab 0  
fill ~31 ~3 ~21 ~32 ~3 ~21 dirt 0  
fill ~31 ~3 ~22 ~32 ~3 ~22 dirt 0  
fill ~31 ~3 ~23 ~33 ~3 ~23 dirt 0 
setblock ~31 ~3 ~25 grass 0  
fill ~32 ~3 ~2 ~34 ~3 ~2 gravel 0 
setblock ~32 ~3 ~18 dirt 0  
fill ~33 ~3 ~24 ~35 ~3 ~24 grass 0 
setblock ~34 ~3 ~19 torch 1 
setblock ~34 ~3 ~21 torch 1  
fill ~34 ~3 ~23 ~43 ~3 ~23 double_stone_slab 0 
setblock ~35 ~3 ~-1 torch 5 
setblock ~35 ~3 ~1 fence 0  
fill ~35 ~3 ~2 ~35 ~0 ~2 sand 0  
fill ~36 ~3 ~3 ~37 ~3 ~3 grass 0  
fill ~36 ~3 ~4 ~38 ~3 ~4 grass 0 
setblock ~36 ~3 ~22 torch 4  
fill ~36 ~3 ~24 ~47 ~3 ~24 dirt 0  
fill ~37 ~3 ~5 ~39 ~3 ~5 grass 0  
fill ~38 ~3 ~6 ~40 ~3 ~6 grass 0 
setblock ~38 ~3 ~16 torch 2 
setblock ~38 ~3 ~18 torch 3 
setblock ~38 ~3 ~25 grass 0  
fill ~39 ~3 ~15 ~48 ~3 ~15 dirt 0 
setblock ~39 ~3 ~16 double_stone_slab 0 
setblock ~39 ~3 ~18 stone_button 3 
setblock ~39 ~3 ~22 torch 4  
fill ~40 ~3 ~7 ~41 ~3 ~7 grass 0  
fill ~40 ~3 ~16 ~40 ~5 ~16 dirt 0 
setblock ~40 ~3 ~18 torch 3  
fill ~41 ~3 ~8 ~42 ~3 ~8 grass 0  
fill ~41 ~3 ~16 ~46 ~3 ~16 stone 0 
setblock ~42 ~3 ~9 grass 0 
setblock ~42 ~3 ~22 torch 4 
setblock ~43 ~3 ~10 grass 0 
setblock ~43 ~3 ~19 stone_slab 0  
fill ~43 ~3 ~20 ~43 ~4 ~20 double_stone_slab 0 
setblock ~43 ~3 ~21 stone_slab 0  
fill ~44 ~3 ~17 ~46 ~3 ~17 stone 0  
fill ~44 ~3 ~23 ~44 ~0 ~23 stone 0 
setblock ~45 ~3 ~12 grass 0  
fill ~45 ~3 ~18 ~46 ~3 ~18 stone 0  
fill ~45 ~3 ~19 ~47 ~3 ~19 stone 0  
fill ~45 ~3 ~20 ~46 ~3 ~20 stone 0  
fill ~45 ~3 ~21 ~48 ~3 ~21 dirt 0  
fill ~45 ~3 ~23 ~48 ~3 ~23 dirt 0  
fill ~46 ~3 ~22 ~48 ~3 ~22 dirt 0 
setblock ~46 ~3 ~25 grass 0  
fill ~47 ~3 ~16 ~47 ~5 ~16 dirt 0  
fill ~47 ~3 ~17 ~47 ~5 ~17 dirt 0  
fill ~47 ~3 ~18 ~47 ~5 ~18 dirt 0  
fill ~47 ~3 ~20 ~47 ~5 ~20 dirt 0 
setblock ~48 ~3 ~14 grass 0 
setblock ~48 ~3 ~24 grass 0  
fill ~49 ~3 ~15 ~49 ~3 ~16 grass 0  
fill ~49 ~3 ~21 ~49 ~3 ~23 grass 0  
fill ~5 ~4 ~19 ~5 ~4 ~20 grass 0  
fill ~6 ~4 ~17 ~7 ~4 ~17 grass 0  
fill ~6 ~4 ~18 ~6 ~4 ~17 grass 0  
fill ~6 ~4 ~19 ~30 ~4 ~19 dirt 0  
fill ~6 ~4 ~20 ~33 ~4 ~20 dirt 0  
fill ~6 ~4 ~21 ~33 ~4 ~21 dirt 0  
fill ~6 ~4 ~22 ~6 ~4 ~23 grass 0  
fill ~7 ~4 ~15 ~8 ~4 ~15 grass 0  
fill ~7 ~4 ~16 ~7 ~4 ~15 grass 0  
fill ~7 ~4 ~18 ~17 ~4 ~18 dirt 0  
fill ~7 ~4 ~22 ~33 ~4 ~22 dirt 0 
setblock ~7 ~4 ~23 grass 0  
fill ~8 ~4 ~16 ~16 ~4 ~16 dirt 0  
fill ~8 ~4 ~17 ~16 ~4 ~17 dirt 0  
fill ~8 ~4 ~23 ~33 ~4 ~23 dirt 0 
setblock ~8 ~4 ~24 grass 0 
setblock ~9 ~4 ~14 grass 0  
fill ~9 ~4 ~15 ~15 ~4 ~15 dirt 0  
fill ~9 ~4 ~24 ~30 ~4 ~24 dirt 0 
setblock ~9 ~4 ~25 grass 0  
fill ~10 ~4 ~13 ~18 ~4 ~13 grass 0  
fill ~10 ~4 ~14 ~14 ~4 ~14 dirt 0  
fill ~10 ~4 ~25 ~28 ~4 ~25 dirt 0  
fill ~10 ~4 ~26 ~27 ~4 ~26 dirt 0  
fill ~11 ~4 ~27 ~27 ~4 ~27 dirt 0  
fill ~13 ~4 ~12 ~18 ~4 ~12 grass 0 
setblock ~13 ~4 ~28 grass 0  
fill ~14 ~4 ~11 ~15 ~4 ~11 grass 0  
fill ~14 ~4 ~28 ~16 ~4 ~28 dirt 0  
fill ~15 ~4 ~14 ~18 ~4 ~14 grass 0  
fill ~16 ~4 ~15 ~18 ~4 ~15 grass 0  
fill ~17 ~4 ~16 ~18 ~4 ~16 grass 0  
fill ~17 ~4 ~17 ~18 ~4 ~17 grass 0  
fill ~17 ~4 ~28 ~17 ~4 ~29 grass 0 
setblock ~17 ~4 ~30 fence 0  
fill ~18 ~4 ~10 ~19 ~4 ~10 fence 0  
fill ~18 ~4 ~11 ~18 ~5 ~11 fence 0 
setblock ~18 ~4 ~18 grass 0  
fill ~18 ~4 ~28 ~20 ~4 ~28 gravel 0  
fill ~19 ~4 ~11 ~27 ~4 ~11 gravel 0  
fill ~19 ~4 ~12 ~27 ~4 ~12 gravel 0  
fill ~19 ~4 ~13 ~20 ~4 ~13 gravel 0  
fill ~19 ~4 ~14 ~20 ~4 ~14 gravel 0  
fill ~19 ~4 ~15 ~20 ~4 ~15 gravel 0  
fill ~19 ~4 ~16 ~20 ~4 ~16 gravel 0  
fill ~19 ~4 ~17 ~20 ~4 ~17 gravel 0  
fill ~19 ~4 ~18 ~20 ~4 ~18 gravel 0 
setblock ~19 ~4 ~30 fence 0  
fill ~20 ~4 ~10 ~25 ~4 ~10 grass 0  
fill ~21 ~4 ~13 ~26 ~4 ~13 grass 0  
fill ~21 ~4 ~14 ~23 ~4 ~14 grass 0  
fill ~21 ~4 ~15 ~25 ~4 ~15 grass 0  
fill ~21 ~4 ~16 ~23 ~4 ~16 grass 0  
fill ~21 ~4 ~17 ~22 ~4 ~17 grass 0  
fill ~21 ~4 ~18 ~29 ~4 ~18 dirt 0  
fill ~21 ~4 ~28 ~21 ~4 ~29 grass 0  
fill ~22 ~4 ~7 ~23 ~4 ~7 grass 0  
fill ~22 ~4 ~8 ~25 ~4 ~8 grass 0  
fill ~22 ~4 ~9 ~23 ~4 ~9 grass 0  
fill ~23 ~4 ~17 ~29 ~4 ~17 dirt 0 
setblock ~24 ~4 ~6 sand 0  
fill ~24 ~4 ~7 ~36 ~4 ~7 dirt 0 
setblock ~24 ~4 ~9 dirt 0 
setblock ~24 ~4 ~14 dirt 0  
fill ~24 ~4 ~16 ~29 ~4 ~16 dirt 0 
setblock ~25 ~4 ~9 grass 0 
setblock ~25 ~4 ~14 grass 0  
fill ~26 ~4 ~6 ~29 ~4 ~6 grass 0  
fill ~26 ~4 ~8 ~28 ~4 ~8 gravel 0  
fill ~26 ~4 ~9 ~28 ~4 ~9 gravel 0  
fill ~26 ~4 ~10 ~27 ~4 ~10 gravel 0  
fill ~26 ~4 ~14 ~46 ~4 ~14 dirt 0  
fill ~26 ~4 ~15 ~28 ~4 ~15 dirt 0  
fill ~27 ~4 ~13 ~44 ~4 ~13 dirt 0  
fill ~28 ~4 ~10 ~29 ~4 ~10 grass 0  
fill ~28 ~4 ~11 ~28 ~4 ~10 grass 0  
fill ~28 ~4 ~12 ~42 ~4 ~12 dirt 0  
fill ~28 ~4 ~26 ~29 ~4 ~26 grass 0  
fill ~28 ~4 ~27 ~29 ~4 ~27 grass 0  
fill ~29 ~4 ~8 ~37 ~4 ~8 dirt 0  
fill ~29 ~4 ~9 ~39 ~4 ~9 dirt 0  
fill ~29 ~4 ~11 ~40 ~4 ~11 dirt 0 
setblock ~29 ~4 ~15 grass 0  
fill ~29 ~4 ~25 ~30 ~4 ~25 grass 0  
fill ~30 ~4 ~4 ~31 ~4 ~4 grass 0  
fill ~30 ~4 ~5 ~31 ~4 ~5 grass 0  
fill ~30 ~4 ~6 ~35 ~4 ~6 dirt 0  
fill ~30 ~4 ~10 ~39 ~4 ~10 dirt 0  
fill ~30 ~4 ~15 ~30 ~5 ~15 dirt 0  
fill ~30 ~4 ~17 ~30 ~8 ~17 double_stone_slab 0  
fill ~30 ~4 ~18 ~30 ~8 ~18 double_stone_slab 0 
setblock ~31 ~4 ~1 torch 5 
setblock ~31 ~4 ~2 fence 0   

KittysCommands:  
setblock ~31 ~4 ~3 grass 0  
fill ~31 ~4 ~15 ~35 ~4 ~15 double_stone_slab 0 
setblock ~31 ~4 ~18 stone_slab 0  
fill ~31 ~4 ~19 ~31 ~9 ~19 double_stone_slab 0  
fill ~31 ~4 ~24 ~32 ~4 ~24 grass 0  
fill ~32 ~4 ~3 ~34 ~4 ~3 gravel 0  
fill ~32 ~4 ~4 ~34 ~4 ~4 gravel 0  
fill ~32 ~4 ~5 ~34 ~4 ~5 gravel 0  
fill ~32 ~4 ~17 ~35 ~4 ~17 double_stone_slab 0  
fill ~32 ~4 ~18 ~32 ~4 ~17 double_stone_slab 0  
fill ~32 ~4 ~19 ~33 ~4 ~19 dirt 0 
setblock ~33 ~4 ~18 dirt 0  
fill ~34 ~4 ~18 ~43 ~4 ~18 double_stone_slab 0  
fill ~34 ~4 ~19 ~37 ~4 ~19 double_stone_slab 0  
fill ~34 ~4 ~20 ~43 ~4 ~20 double_stone_slab 0  
fill ~34 ~4 ~21 ~43 ~4 ~21 double_stone_slab 0  
fill ~34 ~4 ~22 ~43 ~4 ~22 double_stone_slab 0 
setblock ~34 ~4 ~23 grass 0 
setblock ~35 ~4 ~1 torch 5 
setblock ~35 ~4 ~2 fence 0  
fill ~35 ~4 ~3 ~35 ~4 ~5 grass 0 
setblock ~35 ~4 ~16 torch 2  
fill ~35 ~4 ~23 ~37 ~4 ~23 dirt 0  
fill ~36 ~4 ~5 ~36 ~4 ~6 grass 0  
fill ~36 ~4 ~15 ~47 ~4 ~15 dirt 0  
fill ~36 ~4 ~16 ~38 ~4 ~16 double_stone_slab 0  
fill ~36 ~4 ~17 ~45 ~4 ~17 dirt 0  
fill ~36 ~4 ~24 ~37 ~4 ~24 grass 0  
fill ~37 ~4 ~6 ~37 ~4 ~7 grass 0  
fill ~38 ~4 ~7 ~39 ~4 ~7 grass 0  
fill ~38 ~4 ~8 ~40 ~4 ~8 grass 0 
setblock ~38 ~4 ~19 stone 0  
fill ~38 ~4 ~23 ~43 ~4 ~23 stone 0  
fill ~38 ~4 ~24 ~44 ~4 ~24 dirt 0  
fill ~39 ~4 ~16 ~39 ~5 ~16 dirt 0  
fill ~39 ~4 ~19 ~43 ~4 ~19 double_stone_slab 0  
fill ~40 ~4 ~9 ~41 ~4 ~9 grass 0  
fill ~40 ~4 ~10 ~42 ~4 ~10 grass 0  
fill ~41 ~4 ~11 ~43 ~4 ~11 grass 0  
fill ~41 ~4 ~16 ~47 ~4 ~16 dirt 0  
fill ~43 ~4 ~12 ~44 ~4 ~12 grass 0  
fill ~44 ~4 ~18 ~46 ~4 ~18 stone 0  
fill ~44 ~4 ~19 ~44 ~7 ~19 dirt 0 
setblock ~44 ~4 ~20 stone 0  
fill ~44 ~4 ~21 ~47 ~4 ~21 dirt 0  
fill ~44 ~4 ~22 ~47 ~4 ~22 dirt 0  
fill ~44 ~4 ~23 ~47 ~4 ~23 dirt 0  
fill ~45 ~4 ~13 ~46 ~4 ~13 grass 0  
fill ~45 ~4 ~19 ~45 ~0 ~19 stone 0  
fill ~45 ~4 ~20 ~45 ~7 ~20 dirt 0  
fill ~45 ~4 ~24 ~47 ~4 ~24 grass 0 
setblock ~46 ~4 ~17 stone 0  
fill ~46 ~4 ~19 ~46 ~5 ~19 gravel 0  
fill ~46 ~4 ~20 ~46 ~4 ~19 gravel 0 
setblock ~47 ~4 ~14 grass 0  
fill ~47 ~4 ~19 ~47 ~6 ~19 dirt 0  
fill ~48 ~4 ~15 ~48 ~4 ~18 grass 0  
fill ~48 ~4 ~20 ~48 ~4 ~23 grass 0  
fill ~6 ~5 ~19 ~8 ~5 ~19 grass 0  
fill ~6 ~5 ~20 ~8 ~5 ~20 grass 0  
fill ~6 ~5 ~21 ~8 ~5 ~21 grass 0  
fill ~7 ~5 ~18 ~8 ~5 ~18 grass 0  
fill ~7 ~5 ~22 ~8 ~5 ~22 grass 0  
fill ~8 ~5 ~16 ~9 ~5 ~16 grass 0  
fill ~8 ~5 ~17 ~8 ~5 ~16 grass 0  
fill ~8 ~5 ~23 ~9 ~5 ~23 grass 0 
setblock ~9 ~5 ~15 grass 0  
fill ~9 ~5 ~17 ~15 ~5 ~17 dirt 0  
fill ~9 ~5 ~18 ~15 ~5 ~18 dirt 0  
fill ~9 ~5 ~19 ~16 ~5 ~19 dirt 0  
fill ~9 ~5 ~20 ~16 ~5 ~20 dirt 0  
fill ~9 ~5 ~21 ~16 ~5 ~21 dirt 0  
fill ~9 ~5 ~22 ~16 ~5 ~22 dirt 0 
setblock ~9 ~5 ~24 grass 0  
fill ~10 ~5 ~14 ~14 ~5 ~14 grass 0  
fill ~10 ~5 ~15 ~14 ~5 ~15 dirt 0  
fill ~10 ~5 ~16 ~14 ~5 ~16 dirt 0  
fill ~10 ~5 ~23 ~16 ~5 ~23 dirt 0  
fill ~10 ~5 ~24 ~28 ~5 ~24 dirt 0  
fill ~10 ~5 ~25 ~26 ~5 ~25 dirt 0  
fill ~10 ~5 ~26 ~26 ~5 ~26 dirt 0 
setblock ~10 ~5 ~27 grass 0  
fill ~11 ~5 ~27 ~18 ~5 ~27 dirt 0  
fill ~14 ~5 ~28 ~16 ~5 ~28 grass 0  
fill ~15 ~5 ~15 ~15 ~5 ~16 grass 0  
fill ~16 ~5 ~16 ~16 ~5 ~18 grass 0  
fill ~17 ~5 ~18 ~17 ~5 ~23 grass 0  
fill ~17 ~5 ~28 ~17 ~5 ~29 fence 0  
fill ~18 ~5 ~10 ~25 ~5 ~10 fence 0  
fill ~18 ~5 ~12 ~18 ~5 ~18 fence 0  
fill ~18 ~5 ~19 ~18 ~5 ~23 grass 0  
fill ~19 ~5 ~19 ~20 ~5 ~19 gravel 0  
fill ~19 ~5 ~20 ~20 ~5 ~20 gravel 0  
fill ~19 ~5 ~21 ~20 ~5 ~21 gravel 0  
fill ~19 ~5 ~22 ~20 ~5 ~22 gravel 0  
fill ~19 ~5 ~23 ~20 ~5 ~23 gravel 0  
fill ~19 ~5 ~27 ~20 ~5 ~27 gravel 0  
fill ~19 ~5 ~29 ~21 ~5 ~29 fence 0  
fill ~21 ~5 ~13 ~26 ~5 ~13 fence 0  
fill ~21 ~5 ~14 ~21 ~5 ~17 fence 0  
fill ~21 ~5 ~18 ~25 ~5 ~18 grass 0  
fill ~21 ~5 ~19 ~22 ~5 ~19 grass 0  
fill ~21 ~5 ~20 ~36 ~5 ~20 dirt 0  
fill ~21 ~5 ~21 ~41 ~5 ~21 dirt 0  
fill ~21 ~5 ~22 ~32 ~5 ~22 dirt 0  
fill ~21 ~5 ~23 ~31 ~5 ~23 dirt 0  
fill ~21 ~5 ~27 ~23 ~5 ~27 grass 0 
setblock ~21 ~5 ~28 fence 0  
fill ~23 ~5 ~17 ~27 ~5 ~17 grass 0  
fill ~23 ~5 ~19 ~30 ~5 ~19 dirt 0  
fill ~24 ~5 ~7 ~31 ~5 ~7 grass 0  
fill ~24 ~5 ~9 ~24 ~9 ~9 log 0  
fill ~24 ~5 ~14 ~24 ~9 ~14 log 0  
fill ~24 ~5 ~16 ~27 ~5 ~16 grass 0  
fill ~24 ~5 ~27 ~26 ~5 ~27 dirt 0  
fill ~25 ~5 ~8 ~25 ~5 ~10 fence 0  
fill ~26 ~5 ~14 ~27 ~5 ~14 grass 0  
fill ~26 ~5 ~15 ~27 ~5 ~15 grass 0  
fill ~26 ~5 ~18 ~29 ~5 ~18 dirt 0 
setblock ~27 ~5 ~13 grass 0  
fill ~27 ~5 ~25 ~28 ~5 ~25 grass 0  
fill ~27 ~5 ~26 ~27 ~5 ~27 grass 0  
fill ~28 ~5 ~10 ~29 ~5 ~10 fence 0  
fill ~28 ~5 ~11 ~28 ~5 ~10 fence 0 
setblock ~28 ~5 ~12 grass 0  
fill ~28 ~5 ~13 ~39 ~5 ~13 dirt 0  
fill ~28 ~5 ~14 ~44 ~5 ~14 dirt 0  
fill ~28 ~5 ~15 ~28 ~5 ~24 dirt 0  
fill ~29 ~5 ~8 ~31 ~5 ~8 gravel 0  
fill ~29 ~5 ~9 ~31 ~5 ~9 gravel 0 
setblock ~29 ~5 ~11 grass 0  
fill ~29 ~5 ~12 ~32 ~5 ~12 dirt 0  
fill ~29 ~5 ~16 ~29 ~5 ~23 dirt 0  
fill ~29 ~5 ~24 ~30 ~5 ~24 grass 0  
fill ~30 ~5 ~6 ~31 ~5 ~6 grass 0 
setblock ~30 ~5 ~10 grass 0  
fill ~30 ~5 ~11 ~33 ~5 ~11 dirt 0  
fill ~31 ~5 ~3 ~31 ~5 ~5 fence 0  
fill ~31 ~5 ~10 ~37 ~5 ~10 dirt 0  
fill ~31 ~5 ~15 ~34 ~5 ~15 double_stone_slab 0  
fill ~32 ~5 ~6 ~34 ~5 ~6 gravel 0  
fill ~32 ~5 ~7 ~34 ~5 ~7 gravel 0  
fill ~32 ~5 ~8 ~34 ~5 ~8 dirt 0 
setblock ~32 ~5 ~9 grass 0  
fill ~32 ~5 ~17 ~34 ~5 ~17 double_stone_slab 0  
fill ~32 ~5 ~19 ~33 ~5 ~19 double_stone_slab 0  
fill ~32 ~5 ~23 ~33 ~5 ~23 grass 0 
setblock ~33 ~5 ~9 dirt 0 
setblock ~33 ~5 ~18 stone_slab 0  
fill ~33 ~5 ~22 ~34 ~5 ~22 grass 0  
fill ~34 ~5 ~9 ~39 ~5 ~9 grass 0 
setblock ~34 ~5 ~16 torch 2  
fill ~34 ~5 ~18 ~34 ~4 ~18 double_stone_slab 0  
fill ~34 ~5 ~19 ~38 ~5 ~19 dirt 0  
fill ~35 ~5 ~3 ~35 ~5 ~5 fence 0  
fill ~35 ~5 ~6 ~35 ~5 ~9 grass 0  
fill ~35 ~5 ~11 ~38 ~5 ~11 dirt 0  
fill ~35 ~5 ~15 ~46 ~5 ~15 dirt 0  
fill ~35 ~5 ~16 ~35 ~6 ~16 double_stone_slab 0  
fill ~35 ~5 ~17 ~47 ~5 ~17 dirt 0  
fill ~35 ~5 ~18 ~47 ~5 ~18 dirt 0  
fill ~35 ~5 ~22 ~37 ~5 ~22 dirt 0 
setblock ~35 ~5 ~23 grass 0  
fill ~36 ~5 ~7 ~36 ~5 ~9 grass 0  
fill ~36 ~5 ~12 ~39 ~5 ~12 dirt 0  
fill ~36 ~5 ~16 ~47 ~5 ~16 dirt 0  
fill ~36 ~5 ~23 ~37 ~5 ~23 dirt 0 
setblock ~37 ~5 ~8 grass 0 
setblock ~37 ~5 ~20 double_stone_slab 0  
fill ~38 ~5 ~10 ~39 ~5 ~10 grass 0  
fill ~38 ~5 ~20 ~47 ~5 ~20 dirt 0  
fill ~38 ~5 ~22 ~38 ~5 ~23 stone 0  
fill ~38 ~5 ~24 ~44 ~5 ~24 grass 0  
fill ~39 ~5 ~11 ~40 ~5 ~11 grass 0  
fill ~39 ~5 ~19 ~39 ~4 ~19 double_stone_slab 0  
fill ~39 ~5 ~22 ~41 ~5 ~22 dirt 0  
fill ~39 ~5 ~23 ~42 ~5 ~23 stone 0  
fill ~40 ~5 ~12 ~42 ~5 ~12 grass 0  
fill ~40 ~5 ~13 ~44 ~5 ~13 grass 0  
fill ~40 ~5 ~19 ~45 ~5 ~19 dirt 0  
fill ~42 ~5 ~21 ~42 ~5 ~23 stone 0  
fill ~43 ~5 ~21 ~47 ~5 ~21 dirt 0  
fill ~43 ~5 ~22 ~46 ~5 ~22 dirt 0  
fill ~43 ~5 ~23 ~47 ~5 ~23 dirt 0  
fill ~45 ~5 ~14 ~46 ~5 ~14 grass 0 
setblock ~47 ~5 ~15 grass 0 
setblock ~47 ~5 ~22 grass 0 
setblock ~48 ~5 ~19 grass 0  
fill ~9 ~6 ~17 ~9 ~6 ~21 grass 0  
fill ~9 ~6 ~22 ~9 ~3 ~22 dirt 0  
fill ~10 ~6 ~15 ~10 ~2 ~15 dirt 0  
fill ~10 ~6 ~16 ~10 ~2 ~16 dirt 0  
fill ~10 ~6 ~17 ~11 ~6 ~17 dirt 0  
fill ~10 ~6 ~18 ~11 ~6 ~18 dirt 0  
fill ~10 ~6 ~19 ~12 ~6 ~19 dirt 0  
fill ~10 ~6 ~20 ~16 ~6 ~20 grass 0  
fill ~10 ~6 ~21 ~16 ~6 ~21 grass 0  
fill ~10 ~6 ~22 ~16 ~6 ~22 grass 0  
fill ~10 ~6 ~23 ~16 ~6 ~23 grass 0  
fill ~10 ~6 ~24 ~18 ~6 ~24 grass 0  
fill ~10 ~6 ~25 ~13 ~6 ~25 grass 0  
fill ~10 ~6 ~26 ~18 ~6 ~26 grass 0  
fill ~11 ~6 ~15 ~13 ~6 ~15 grass 0  
fill ~11 ~6 ~16 ~14 ~6 ~16 grass 0  
fill ~11 ~6 ~27 ~18 ~6 ~27 grass 0  
fill ~12 ~6 ~17 ~15 ~6 ~17 grass 0  
fill ~12 ~6 ~18 ~15 ~6 ~18 grass 0  
fill ~13 ~6 ~19 ~16 ~6 ~19 grass 0  
fill ~14 ~6 ~15 ~14 ~11 ~15 log 0 
setblock ~14 ~6 ~25 dirt 0  
fill ~15 ~6 ~25 ~18 ~6 ~25 grass 0 
setblock ~17 ~6 ~29 torch 5 
setblock ~18 ~6 ~10 torch 5 
setblock ~18 ~6 ~14 torch 5 
setblock ~18 ~6 ~18 torch 5  
fill ~18 ~6 ~19 ~18 ~6 ~23 fence 0  
fill ~19 ~6 ~24 ~20 ~6 ~24 gravel 0  
fill ~19 ~6 ~25 ~20 ~6 ~25 gravel 0  
fill ~19 ~6 ~26 ~20 ~6 ~26 gravel 0 
setblock ~21 ~6 ~10 torch 5 
setblock ~21 ~6 ~13 torch 5 
setblock ~21 ~6 ~17 torch 5  
fill ~21 ~6 ~18 ~21 ~6 ~19 fence 0  
fill ~21 ~6 ~20 ~30 ~6 ~20 grass 0  
fill ~21 ~6 ~21 ~29 ~6 ~21 grass 0  
fill ~21 ~6 ~22 ~21 ~6 ~26 grass 0 
setblock ~21 ~6 ~27 fence 0 
setblock ~21 ~6 ~29 torch 5 
setblock ~22 ~6 ~22 dirt 0  
fill ~22 ~6 ~23 ~28 ~6 ~23 grass 0  
fill ~22 ~6 ~24 ~28 ~6 ~24 grass 0  
fill ~22 ~6 ~25 ~26 ~6 ~25 grass 0  
fill ~22 ~6 ~26 ~26 ~6 ~26 grass 0  
fill ~23 ~6 ~19 ~29 ~6 ~19 grass 0  
fill ~23 ~6 ~22 ~28 ~6 ~22 grass 0  
fill ~24 ~6 ~27 ~26 ~6 ~27 grass 0  
fill ~25 ~6 ~7 ~31 ~6 ~7 fence 0 
setblock ~25 ~6 ~8 torch 5 
setblock ~25 ~6 ~10 torch 5 
setblock ~26 ~6 ~13 torch 5  
fill ~26 ~6 ~18 ~28 ~6 ~18 grass 0 
setblock ~27 ~6 ~13 fence 0 
setblock ~28 ~6 ~10 torch 5 
setblock ~28 ~6 ~12 fence 0  
fill ~28 ~6 ~13 ~28 ~9 ~13 wool 15  
fill ~28 ~6 ~14 ~28 ~9 ~14 wool 15  
fill ~28 ~6 ~15 ~28 ~9 ~15 wool 15  
fill ~28 ~6 ~16 ~28 ~9 ~16 wool 15  
fill ~28 ~6 ~17 ~28 ~9 ~17 wool 15  
fill ~29 ~6 ~12 ~29 ~9 ~12 wool 15  
fill ~29 ~6 ~13 ~37 ~6 ~13 double_stone_slab 0  
fill ~29 ~6 ~14 ~37 ~6 ~14 double_stone_slab 0  
fill ~29 ~6 ~15 ~37 ~6 ~15 double_stone_slab 0  
fill ~29 ~6 ~16 ~29 ~7 ~16 double_stone_slab 0  
fill ~29 ~6 ~17 ~29 ~8 ~17 double_stone_slab 0 
setblock ~29 ~6 ~18 dirt 0  
fill ~29 ~6 ~22 ~30 ~6 ~22 dirt 0  
fill ~29 ~6 ~23 ~30 ~6 ~23 dirt 0 
setblock ~30 ~6 ~10 fence 0  
fill ~30 ~6 ~11 ~30 ~9 ~11 wool 15  
fill ~30 ~6 ~12 ~36 ~6 ~12 double_stone_slab 0 
setblock ~30 ~6 ~19 dirt 0 
setblock ~30 ~6 ~21 dirt 0 
setblock ~31 ~6 ~3 torch 5 
setblock ~31 ~6 ~6 fence 0  
fill ~31 ~6 ~10 ~32 ~6 ~10 wool 15  
fill ~31 ~6 ~11 ~35 ~6 ~11 double_stone_slab 0  
fill ~31 ~6 ~20 ~36 ~6 ~20 dirt 0  
fill ~31 ~6 ~21 ~35 ~6 ~21 grass 0  
fill ~31 ~6 ~22 ~32 ~6 ~22 grass 0  
fill ~31 ~6 ~23 ~31 ~6 ~21 grass 0  
fill ~32 ~6 ~8 ~34 ~6 ~8 stone_slab 0  
fill ~32 ~6 ~9 ~32 ~6 ~8 stone_slab 0 
setblock ~32 ~6 ~16 torch 2  
fill ~32 ~6 ~17 ~37 ~6 ~17 double_stone_slab 0  
fill ~32 ~6 ~19 ~35 ~6 ~19 double_stone_slab 0  
fill ~33 ~6 ~9 ~33 ~6 ~17 double_stone_slab 0 
setblock ~34 ~6 ~9 stone_slab 0  
fill ~34 ~6 ~10 ~35 ~6 ~10 wool 15  
fill ~34 ~6 ~16 ~34 ~8 ~16 double_stone_slab 0 
setblock ~35 ~6 ~3 torch 5  
fill ~35 ~6 ~6 ~35 ~6 ~7 fence 0 
setblock ~35 ~6 ~18 stone_slab 0  
fill ~35 ~6 ~22 ~36 ~6 ~22 grass 0  
fill ~36 ~6 ~10 ~37 ~6 ~10 grass 0 
setblock ~36 ~6 ~11 dirt 0  
fill ~36 ~6 ~16 ~37 ~6 ~16 double_stone_slab 0 
setblock ~36 ~6 ~18 double_stone_slab 0 
setblock ~36 ~6 ~19 dirt 0  
fill ~36 ~6 ~21 ~46 ~6 ~21 dirt 0 
setblock ~36 ~6 ~23 grass 0  
fill ~37 ~6 ~11 ~38 ~6 ~11 grass 0 
setblock ~37 ~6 ~12 dirt 0 
setblock ~37 ~6 ~18 dirt 0  
fill ~37 ~6 ~19 ~38 ~6 ~19 grass 0  
fill ~37 ~6 ~20 ~37 ~6 ~19 grass 0  
fill ~37 ~6 ~22 ~45 ~6 ~22 dirt 0  
fill ~37 ~6 ~23 ~44 ~6 ~23 dirt 0 
setblock ~38 ~6 ~12 grass 0  
fill ~38 ~6 ~13 ~38 ~6 ~17 dirt 0 
setblock ~38 ~6 ~18 grass 0  
fill ~38 ~6 ~20 ~46 ~6 ~20 dirt 0 
setblock ~39 ~6 ~12 dirt 0  
fill ~39 ~6 ~13 ~39 ~6 ~16 grass 0  
fill ~39 ~6 ~17 ~46 ~6 ~17 dirt 0  
fill ~39 ~6 ~18 ~46 ~6 ~18 dirt 0  
fill ~39 ~6 ~19 ~47 ~6 ~19 dirt 0  
fill ~40 ~6 ~14 ~44 ~6 ~14 grass 0  
fill ~40 ~6 ~15 ~46 ~6 ~15 grass 0  
fill ~40 ~6 ~16 ~40 ~6 ~14 grass 0  
fill ~41 ~6 ~16 ~46 ~6 ~16 dirt 0  
fill ~45 ~6 ~23 ~46 ~6 ~23 grass 0 
setblock ~46 ~6 ~22 grass 0  
fill ~47 ~6 ~16 ~47 ~6 ~18 grass 0  
fill ~47 ~6 ~20 ~47 ~6 ~21 grass 0  
fill ~47 ~6 ~23 ~47 ~9 ~23 log 0  
fill ~9 ~7 ~22 ~9 ~10 ~22 log 0  
fill ~10 ~7 ~15 ~10 ~7 ~19 grass 0  
fill ~11 ~7 ~17 ~11 ~7 ~19 grass 0 
setblock ~12 ~7 ~19 grass 0  
fill ~14 ~7 ~25 ~14 ~12 ~25 log 0  
fill ~18 ~7 ~24 ~18 ~7 ~27 fence 0 
setblock ~21 ~7 ~18 torch 5  
fill ~21 ~7 ~20 ~21 ~7 ~26 fence 0  
fill ~22 ~7 ~8 ~26 ~7 ~8 leaves 0  
fill ~22 ~7 ~9 ~23 ~7 ~9 leaves 0  
fill ~22 ~7 ~10 ~26 ~7 ~10 leaves 0  
fill ~22 ~7 ~11 ~26 ~7 ~11 leaves 0  
fill ~22 ~7 ~13 ~26 ~7 ~13 leaves 0  
fill ~22 ~7 ~14 ~23 ~7 ~14 leaves 0  
fill ~22 ~7 ~15 ~26 ~7 ~15 leaves 0  
fill ~22 ~7 ~16 ~26 ~7 ~16 leaves 0  
fill ~22 ~7 ~22 ~22 ~12 ~22 log 0  
fill ~23 ~7 ~7 ~25 ~7 ~7 leaves 0  
fill ~23 ~7 ~12 ~26 ~7 ~12 leaves 0  
fill ~25 ~7 ~9 ~26 ~7 ~9 leaves 0  
fill ~25 ~7 ~14 ~26 ~7 ~14 leaves 0  
fill ~29 ~7 ~14 ~32 ~7 ~14 stone_slab 0  
fill ~29 ~7 ~15 ~32 ~7 ~15 double_stone_slab 0  
fill ~29 ~7 ~18 ~29 ~9 ~18 wool 15  
fill ~29 ~7 ~22 ~30 ~7 ~22 grass 0  
fill ~29 ~7 ~23 ~30 ~7 ~23 grass 0 
setblock ~30 ~7 ~10 torch 5  
fill ~30 ~7 ~19 ~30 ~9 ~19 wool 15 
setblock ~30 ~7 ~21 grass 0 
setblock ~31 ~7 ~7 torch 5  
fill ~31 ~7 ~10 ~32 ~7 ~10 wool 15  
fill ~31 ~7 ~16 ~32 ~7 ~16 double_stone_slab 0 
setblock ~31 ~7 ~17 torch 3  
fill ~31 ~7 ~20 ~35 ~7 ~20 wool 15  
fill ~32 ~7 ~17 ~32 ~8 ~17 double_stone_slab 0  
fill ~32 ~7 ~19 ~35 ~7 ~19 double_stone_slab 0 
setblock ~33 ~7 ~9 stone_pressure_plate 0 
setblock ~33 ~7 ~10 iron_door 1 
setblock ~33 ~7 ~11 stone_pressure_plate 0  
fill ~33 ~7 ~15 ~33 ~36 ~15 glowstone 0  
fill ~34 ~7 ~10 ~35 ~7 ~10 wool 15  
fill ~34 ~7 ~11 ~34 ~9 ~11 planks 0  
fill ~34 ~7 ~12 ~34 ~7 ~13 planks 0  
fill ~34 ~7 ~15 ~34 ~8 ~15 planks 0  
fill ~34 ~7 ~17 ~34 ~8 ~17 double_stone_slab 0 
setblock ~35 ~7 ~7 torch 5  
fill ~36 ~7 ~11 ~36 ~9 ~11 wool 15 
setblock ~36 ~7 ~13 oak_stairs 0 
setblock ~36 ~7 ~18 torch 5  
fill ~36 ~7 ~19 ~36 ~9 ~19 wool 15  
fill ~36 ~7 ~20 ~36 ~7 ~21 grass 0  
fill ~37 ~7 ~12 ~37 ~9 ~12 wool 15 
setblock ~37 ~7 ~13 glowstone 0  
fill ~37 ~7 ~18 ~37 ~9 ~18 wool 15  
fill ~37 ~7 ~21 ~38 ~7 ~21 grass 0  
fill ~37 ~7 ~22 ~37 ~7 ~23 grass 0  
fill ~38 ~7 ~13 ~38 ~9 ~13 wool 15  
fill ~38 ~7 ~14 ~38 ~9 ~14 wool 15  
fill ~38 ~7 ~15 ~38 ~9 ~15 wool 15  
fill ~38 ~7 ~16 ~38 ~9 ~16 wool 15  
fill ~38 ~7 ~17 ~38 ~9 ~17 wool 15  
fill ~38 ~7 ~20 ~39 ~7 ~20 grass 0  
fill ~38 ~7 ~22 ~43 ~7 ~22 dirt 0  
fill ~38 ~7 ~23 ~43 ~7 ~23 dirt 0  
fill ~39 ~7 ~17 ~45 ~7 ~17 grass 0  
fill ~39 ~7 ~18 ~41 ~7 ~18 grass 0  
fill ~39 ~7 ~19 ~39 ~7 ~17 grass 0  
fill ~39 ~7 ~21 ~44 ~7 ~21 dirt 0  
fill ~40 ~7 ~19 ~46 ~7 ~19 dirt 0  
fill ~40 ~7 ~20 ~46 ~7 ~20 dirt 0  
fill ~41 ~7 ~16 ~46 ~7 ~16 grass 0  
fill ~42 ~7 ~18 ~46 ~7 ~18 dirt 0  
fill ~44 ~7 ~22 ~45 ~7 ~22 grass 0  
fill ~44 ~7 ~23 ~44 ~7 ~22 grass 0  
fill ~45 ~7 ~21 ~46 ~7 ~21 grass 0 
setblock ~46 ~7 ~17 dirt 0  
fill ~46 ~7 ~23 ~46 ~11 ~23 leaves 0 
setblock ~47 ~7 ~19 grass 0  
fill ~47 ~7 ~22 ~47 ~11 ~22 leaves 0  
fill ~47 ~7 ~24 ~47 ~11 ~24 leaves 0  
fill ~48 ~7 ~23 ~48 ~11 ~23 leaves 0  
fill ~7 ~8 ~20 ~11 ~8 ~20 leaves 0  
fill ~7 ~8 ~21 ~11 ~8 ~21 leaves 0  
fill ~7 ~8 ~22 ~8 ~8 ~22 leaves 0  
fill ~7 ~8 ~23 ~11 ~8 ~23 leaves 0  
fill ~8 ~8 ~24 ~10 ~8 ~24 leaves 0  
fill ~10 ~8 ~22 ~11 ~8 ~22 leaves 0 
setblock ~18 ~8 ~24 torch 5 
setblock ~21 ~8 ~20 torch 5 
setblock ~21 ~8 ~26 torch 5  
fill ~22 ~8 ~7 ~25 ~8 ~7 leaves 0  
fill ~22 ~8 ~8 ~26 ~8 ~8 leaves 0  
fill ~22 ~8 ~9 ~23 ~8 ~9 leaves 0  
fill ~22 ~8 ~10 ~26 ~8 ~10 leaves 0  
fill ~22 ~8 ~11 ~26 ~8 ~11 leaves 0  
fill ~22 ~8 ~12 ~26 ~8 ~12 leaves 0  
fill ~22 ~8 ~13 ~26 ~8 ~13 leaves 0  
fill ~22 ~8 ~14 ~23 ~8 ~14 leaves 0  
fill ~22 ~8 ~15 ~26 ~8 ~15 leaves 0  
fill ~22 ~8 ~16 ~25 ~8 ~16 leaves 0  
fill ~25 ~8 ~9 ~26 ~8 ~9 leaves 0  
fill ~25 ~8 ~14 ~26 ~8 ~14 leaves 0  
fill ~29 ~8 ~16 ~32 ~8 ~16 stone_slab 0  
fill ~31 ~8 ~10 ~32 ~8 ~10 wool 15  
fill ~31 ~8 ~17 ~31 ~8 ~19 double_stone_slab 0  
fill ~31 ~8 ~20 ~35 ~8 ~20 wool 15  
fill ~32 ~8 ~18 ~33 ~8 ~18 double_stone_slab 0  
fill ~32 ~8 ~19 ~35 ~8 ~19 double_stone_slab 0 
setblock ~33 ~8 ~10 iron_door 9  
fill ~33 ~8 ~16 ~33 ~8 ~19 double_stone_slab 0  
fill ~34 ~8 ~10 ~35 ~8 ~10 wool 15  
fill ~34 ~8 ~12 ~34 ~8 ~13 glass 0 
setblock ~35 ~8 ~11 torch 3 
setblock ~37 ~8 ~13 stone_slab 2  
fill ~38 ~8 ~22 ~38 ~8 ~23 grass 0 
setblock ~39 ~8 ~21 grass 0  
fill ~39 ~8 ~22 ~42 ~8 ~22 dirt 0  
fill ~39 ~8 ~23 ~42 ~8 ~23 dirt 0  
fill ~40 ~8 ~19 ~45 ~8 ~19 grass 0  
fill ~40 ~8 ~20 ~46 ~8 ~20 grass 0  
fill ~40 ~8 ~21 ~42 ~8 ~21 dirt 0  
fill ~42 ~8 ~18 ~46 ~8 ~18 grass 0  
fill ~43 ~8 ~21 ~44 ~8 ~21 grass 0  
fill ~43 ~8 ~22 ~43 ~8 ~23 grass 0  
fill ~45 ~8 ~22 ~49 ~8 ~22 leaves 0  
fill ~45 ~8 ~23 ~45 ~10 ~23 leaves 0  
fill ~45 ~8 ~24 ~49 ~8 ~24 leaves 0 
setblock ~46 ~8 ~17 grass 0 
setblock ~46 ~8 ~19 dirt 0  
fill ~46 ~8 ~21 ~48 ~8 ~21 leaves 0  
fill ~46 ~8 ~25 ~48 ~8 ~25 leaves 0  
fill ~49 ~8 ~23 ~49 ~10 ~23 leaves 0  
fill ~7 ~9 ~21 ~11 ~9 ~21 leaves 0  
fill ~7 ~9 ~22 ~8 ~9 ~22 leaves 0  
fill ~7 ~9 ~23 ~11 ~9 ~23 leaves 0  
fill ~7 ~9 ~24 ~11 ~9 ~24 leaves 0  
fill ~8 ~9 ~20 ~10 ~9 ~20 leaves 0  
fill ~10 ~9 ~22 ~11 ~9 ~22 leaves 0  
fill ~12 ~9 ~13 ~16 ~9 ~13 leaves 0  
fill ~12 ~9 ~14 ~16 ~9 ~14 leaves 0  
fill ~12 ~9 ~15 ~13 ~9 ~15 leaves 0  
fill ~12 ~9 ~16 ~16 ~9 ~16 leaves 0  
fill ~12 ~9 ~17 ~16 ~9 ~17 leaves 0  
fill ~15 ~9 ~15 ~16 ~9 ~15 leaves 0  
fill ~23 ~9 ~9 ~23 ~10 ~9 leaves 0  
fill ~23 ~9 ~10 ~24 ~9 ~10 leaves 0  
fill ~23 ~9 ~14 ~23 ~10 ~14 leaves 0  
fill ~23 ~9 ~16 ~23 ~10 ~16 leaves 2  
fill ~24 ~9 ~8 ~27 ~9 ~8 leaves 0  
fill ~24 ~9 ~13 ~25 ~9 ~13 leaves 0  
fill ~24 ~9 ~15 ~25 ~9 ~15 leaves 0  
fill ~25 ~9 ~9 ~25 ~10 ~9 leaves 0  
fill ~25 ~9 ~14 ~25 ~10 ~14 leaves 0 
setblock ~26 ~9 ~7 leaves 0  
fill ~30 ~9 ~18 ~34 ~9 ~18 stone_slab 0  
fill ~31 ~9 ~10 ~35 ~9 ~10 wool 15  
fill ~31 ~9 ~20 ~35 ~9 ~20 wool 15  
fill ~32 ~9 ~19 ~35 ~9 ~19 double_stone_slab 0  
fill ~34 ~9 ~12 ~35 ~9 ~12 planks 0  
fill ~34 ~9 ~13 ~35 ~9 ~13 planks 0  
fill ~34 ~9 ~14 ~34 ~9 ~11 planks 0  
fill ~34 ~9 ~15 ~36 ~9 ~15 double_stone_slab 0  
fill ~34 ~9 ~16 ~34 ~9 ~18 stone_slab 0 
setblock ~35 ~9 ~11 planks 0 
setblock ~35 ~9 ~14 torch 1  
fill ~35 ~9 ~16 ~36 ~9 ~16 double_stone_slab 0  
fill ~35 ~9 ~17 ~37 ~9 ~17 double_stone_slab 0  
fill ~35 ~9 ~18 ~36 ~9 ~18 double_stone_slab 0  
fill ~36 ~9 ~12 ~36 ~9 ~13 torch 1 
setblock ~37 ~9 ~16 torch 4  
fill ~39 ~9 ~22 ~42 ~9 ~22 grass 0  
fill ~39 ~9 ~23 ~42 ~9 ~23 grass 0  
fill ~40 ~9 ~21 ~42 ~9 ~21 grass 0  
fill ~45 ~9 ~22 ~49 ~9 ~22 leaves 0  
fill ~45 ~9 ~24 ~49 ~9 ~24 leaves 0 
setblock ~46 ~9 ~19 grass 0  
fill ~46 ~9 ~21 ~48 ~9 ~21 leaves 0  
fill ~46 ~9 ~25 ~48 ~9 ~25 leaves 0  
fill ~8 ~10 ~22 ~8 ~11 ~22 leaves 0  
fill ~8 ~10 ~23 ~9 ~10 ~23 leaves 0  
fill ~9 ~10 ~21 ~9 ~11 ~21 leaves 0  
fill ~10 ~10 ~22 ~10 ~11 ~22 leaves 0  
fill ~12 ~10 ~13 ~16 ~10 ~13 leaves 0  
fill ~12 ~10 ~14 ~16 ~10 ~14 leaves 0  
fill ~12 ~10 ~15 ~13 ~10 ~15 leaves 0  
fill ~12 ~10 ~16 ~16 ~10 ~16 leaves 0  
fill ~12 ~10 ~23 ~15 ~10 ~23 leaves 0  
fill ~12 ~10 ~24 ~16 ~10 ~24 leaves 0  
fill ~12 ~10 ~25 ~13 ~10 ~25 leaves 0  
fill ~12 ~10 ~26 ~16 ~10 ~26 leaves 0  
fill ~13 ~10 ~17 ~15 ~10 ~17 leaves 0  
fill ~13 ~10 ~27 ~15 ~10 ~27 leaves 0  
fill ~15 ~10 ~15 ~16 ~10 ~15 leaves 0  
fill ~15 ~10 ~25 ~16 ~10 ~25 leaves 0  
fill ~20 ~10 ~21 ~24 ~10 ~21 leaves 0  
fill ~20 ~10 ~22 ~21 ~10 ~22 leaves 0  
fill ~20 ~10 ~23 ~24 ~10 ~23 leaves 0  
fill ~20 ~10 ~24 ~23 ~10 ~24 leaves 0  
fill ~21 ~10 ~20 ~24 ~10 ~20 leaves 0  
fill ~23 ~10 ~22 ~24 ~10 ~22 leaves 0  
fill ~24 ~10 ~8 ~24 ~7 ~8 leaves 0  
fill ~24 ~10 ~9 ~24 ~10 ~10 leaves 0  
fill ~24 ~10 ~13 ~24 ~7 ~13 leaves 0  
fill ~24 ~10 ~14 ~24 ~10 ~15 leaves 0  
fill ~24 ~10 ~16 ~24 ~10 ~17 leaves 2 
setblock ~26 ~10 ~8 leaves 0  
fill ~28 ~10 ~13 ~28 ~12 ~13 wool 0  
fill ~28 ~10 ~14 ~28 ~12 ~14 wool 0  
fill ~28 ~10 ~15 ~28 ~12 ~15 wool 0  
fill ~28 ~10 ~16 ~28 ~12 ~16 wool 0  
fill ~28 ~10 ~17 ~28 ~12 ~17 wool 0  
fill ~29 ~10 ~12 ~29 ~12 ~12 wool 0  
fill ~29 ~10 ~18 ~29 ~12 ~18 wool 0  
fill ~30 ~10 ~11 ~30 ~12 ~11 wool 0  
fill ~30 ~10 ~19 ~30 ~12 ~19 wool 0  
fill ~31 ~10 ~10 ~35 ~10 ~10 wool 0  
fill ~31 ~10 ~20 ~35 ~10 ~20 wool 0  
fill ~33 ~10 ~13 ~37 ~10 ~13 double_stone_slab 0  
fill ~33 ~10 ~14 ~33 ~10 ~13 double_stone_slab 0  
fill ~34 ~10 ~14 ~36 ~10 ~14 stone_slab 0  
fill ~35 ~10 ~11 ~35 ~11 ~11 double_stone_slab 0  
fill ~35 ~10 ~12 ~35 ~11 ~12 stone_slab 0  
fill ~36 ~10 ~11 ~36 ~12 ~11 wool 0  
fill ~36 ~10 ~15 ~36 ~10 ~18 stone_slab 0  
fill ~36 ~10 ~19 ~36 ~12 ~19 wool 0  
fill ~37 ~10 ~12 ~37 ~12 ~12 wool 0  
fill ~37 ~10 ~14 ~37 ~10 ~17 double_stone_slab 0  
fill ~37 ~10 ~18 ~37 ~12 ~18 wool 0  
fill ~38 ~10 ~13 ~38 ~12 ~13 wool 0  
fill ~38 ~10 ~14 ~38 ~12 ~14 wool 0  
fill ~38 ~10 ~15 ~38 ~12 ~15 wool 0  
fill ~38 ~10 ~16 ~38 ~12 ~16 wool 0  
fill ~38 ~10 ~17 ~38 ~12 ~17 wool 0  
fill ~45 ~10 ~22 ~49 ~10 ~22 leaves 0  
fill ~45 ~10 ~24 ~49 ~10 ~24 leaves 0  
fill ~46 ~10 ~21 ~48 ~10 ~21 leaves 0  
fill ~46 ~10 ~25 ~48 ~10 ~25 leaves 0  
fill ~47 ~10 ~23 ~47 ~11 ~23 leaves 0  
fill ~9 ~11 ~22 ~9 ~11 ~23 leaves 0  
fill ~12 ~11 ~23 ~15 ~11 ~23 leaves 0  
fill ~12 ~11 ~24 ~16 ~11 ~24 leaves 0  
fill ~12 ~11 ~25 ~13 ~11 ~25 leaves 0  
fill ~12 ~11 ~26 ~16 ~11 ~26 leaves 0  
fill ~12 ~11 ~27 ~16 ~11 ~27 leaves 0  
fill ~13 ~11 ~15 ~13 ~12 ~15 leaves 0  
fill ~14 ~11 ~14 ~14 ~12 ~14 leaves 0  
fill ~14 ~11 ~16 ~14 ~12 ~16 leaves 0  
fill ~15 ~11 ~15 ~15 ~12 ~15 leaves 0  
fill ~15 ~11 ~25 ~16 ~11 ~25 leaves 0  
fill ~20 ~11 ~21 ~24 ~11 ~21 leaves 0  
fill ~20 ~11 ~22 ~21 ~11 ~22 leaves 0  
fill ~20 ~11 ~23 ~24 ~11 ~23 leaves 0  
fill ~21 ~11 ~20 ~24 ~11 ~20 leaves 0  
fill ~21 ~11 ~24 ~24 ~11 ~24 leaves 0  
fill ~23 ~11 ~22 ~24 ~11 ~22 leaves 0  
fill ~31 ~11 ~10 ~35 ~11 ~10 wool 0  
fill ~31 ~11 ~11 ~35 ~11 ~11 double_stone_slab 0  
fill ~31 ~11 ~12 ~31 ~11 ~15 double_stone_slab 0  
fill ~31 ~11 ~20 ~35 ~11 ~20 wool 0  
fill ~32 ~11 ~12 ~36 ~11 ~12 stone_slab 0  
fill ~32 ~11 ~13 ~32 ~11 ~14 stone_slab 0 
setblock ~32 ~11 ~15 double_stone_slab 0  
fill ~13 ~12 ~24 ~15 ~12 ~24 leaves 0  
fill ~13 ~12 ~25 ~13 ~13 ~25 leaves 0  
fill ~13 ~12 ~26 ~14 ~12 ~26 leaves 0 
setblock ~14 ~12 ~15 leaves 0  
fill ~15 ~12 ~25 ~15 ~13 ~25 leaves 0  
fill ~21 ~12 ~22 ~21 ~13 ~22 leaves 0  
fill ~22 ~12 ~21 ~23 ~12 ~21 leaves 0  
fill ~22 ~12 ~23 ~23 ~12 ~23 leaves 0  
fill ~23 ~12 ~22 ~23 ~13 ~22 leaves 0  
fill ~29 ~12 ~13 ~29 ~12 ~17 double_stone_slab 0  
fill ~30 ~12 ~12 ~30 ~12 ~16 stone_slab 0  
fill ~30 ~12 ~17 ~33 ~12 ~17 double_stone_slab 0  
fill ~31 ~12 ~10 ~35 ~12 ~10 wool 0  
fill ~31 ~12 ~16 ~32 ~12 ~16 stone_slab 0  
fill ~31 ~12 ~20 ~35 ~12 ~20 wool 0 
setblock ~33 ~12 ~16 double_stone_slab 0  
fill ~14 ~13 ~24 ~14 ~13 ~26 leaves 0  
fill ~22 ~13 ~21 ~22 ~10 ~21 leaves 0  
fill ~22 ~13 ~22 ~22 ~13 ~23 leaves 0  
fill ~28 ~13 ~13 ~28 ~15 ~13 wool 14  
fill ~28 ~13 ~14 ~28 ~15 ~14 wool 14  
fill ~28 ~13 ~15 ~28 ~15 ~15 wool 14  
fill ~28 ~13 ~16 ~28 ~15 ~16 wool 14  
fill ~28 ~13 ~17 ~28 ~15 ~17 wool 14  
fill ~29 ~13 ~12 ~29 ~15 ~12 wool 14  
fill ~29 ~13 ~18 ~29 ~15 ~18 wool 14  
fill ~30 ~13 ~11 ~30 ~15 ~11 wool 14  
fill ~30 ~13 ~18 ~34 ~13 ~18 stone_slab 0  
fill ~30 ~13 ~19 ~30 ~15 ~19 wool 14  
fill ~31 ~13 ~10 ~31 ~15 ~10 wool 14  
fill ~31 ~13 ~19 ~35 ~13 ~19 double_stone_slab 0  
fill ~31 ~13 ~20 ~35 ~13 ~20 wool 14  
fill ~32 ~13 ~10 ~34 ~13 ~10 glass 0  
fill ~34 ~13 ~15 ~35 ~13 ~15 double_stone_slab 0  
fill ~34 ~13 ~16 ~34 ~13 ~18 stone_slab 0  
fill ~35 ~13 ~10 ~35 ~15 ~10 wool 14  
fill ~35 ~13 ~16 ~35 ~13 ~19 double_stone_slab 0  
fill ~36 ~13 ~11 ~36 ~15 ~11 wool 14  
fill ~36 ~13 ~19 ~36 ~15 ~19 wool 14  
fill ~37 ~13 ~12 ~37 ~15 ~12 wool 14  
fill ~37 ~13 ~18 ~37 ~15 ~18 wool 14  
fill ~38 ~13 ~13 ~38 ~15 ~13 wool 14  
fill ~38 ~13 ~14 ~38 ~15 ~14 wool 14  
fill ~38 ~13 ~15 ~38 ~15 ~15 wool 14  
fill ~38 ~13 ~16 ~38 ~15 ~16 wool 14  
fill ~38 ~13 ~17 ~38 ~15 ~17 wool 14  
fill ~31 ~14 ~20 ~35 ~14 ~20 wool 14  
fill ~32 ~14 ~10 ~34 ~14 ~10 glass 0  
fill ~33 ~14 ~13 ~37 ~14 ~13 double_stone_slab 0  
fill ~33 ~14 ~14 ~33 ~14 ~13 double_stone_slab 0  
fill ~34 ~14 ~14 ~36 ~14 ~14 stone_slab 0  
fill ~36 ~14 ~15 ~36 ~14 ~18 stone_slab 0  
fill ~37 ~14 ~14 ~37 ~14 ~17 double_stone_slab 0  
fill ~31 ~15 ~11 ~35 ~15 ~11 double_stone_slab 0  
fill ~31 ~15 ~12 ~31 ~15 ~15 double_stone_slab 0  
fill ~31 ~15 ~20 ~35 ~15 ~20 wool 14  
fill ~32 ~15 ~10 ~34 ~15 ~10 glass 0  
fill ~32 ~15 ~12 ~36 ~15 ~12 stone_slab 0  
fill ~32 ~15 ~13 ~32 ~15 ~14 stone_slab 0 
setblock ~32 ~15 ~15 double_stone_slab 0  
fill ~28 ~16 ~13 ~28 ~17 ~13 wool 0  
fill ~28 ~16 ~14 ~28 ~17 ~14 wool 0  
fill ~28 ~16 ~15 ~28 ~17 ~15 wool 0  
fill ~28 ~16 ~16 ~28 ~17 ~16 wool 0  
fill ~28 ~16 ~17 ~28 ~17 ~17 wool 0  
fill ~29 ~16 ~12 ~29 ~17 ~12 wool 0  
fill ~29 ~16 ~13 ~29 ~16 ~17 double_stone_slab 0  
fill ~29 ~16 ~18 ~29 ~17 ~18 wool 0  
fill ~30 ~16 ~11 ~30 ~17 ~11 wool 0  
fill ~30 ~16 ~12 ~30 ~16 ~16 stone_slab 0  
fill ~30 ~16 ~17 ~33 ~16 ~17 double_stone_slab 0  
fill ~30 ~16 ~19 ~30 ~17 ~19 wool 0  
fill ~31 ~16 ~10 ~35 ~16 ~10 wool 0  
fill ~31 ~16 ~16 ~32 ~16 ~16 stone_slab 0  
fill ~31 ~16 ~20 ~35 ~16 ~20 wool 0 
setblock ~33 ~16 ~16 double_stone_slab 0  
fill ~36 ~16 ~11 ~36 ~17 ~11 wool 0  
fill ~36 ~16 ~19 ~36 ~17 ~19 wool 0  
fill ~37 ~16 ~12 ~37 ~17 ~12 wool 0  
fill ~37 ~16 ~18 ~37 ~17 ~18 wool 0  
fill ~38 ~16 ~13 ~38 ~17 ~13 wool 0  
fill ~38 ~16 ~14 ~38 ~17 ~14 wool 0  
fill ~38 ~16 ~15 ~38 ~17 ~15 wool 0  
fill ~38 ~16 ~16 ~38 ~17 ~16 wool 0  
fill ~38 ~16 ~17 ~38 ~17 ~17 wool 0  
fill ~30 ~17 ~18 ~34 ~17 ~18 stone_slab 0  
fill ~31 ~17 ~10 ~35 ~17 ~10 wool 0  
fill ~31 ~17 ~19 ~35 ~17 ~19 double_stone_slab 0  
fill ~31 ~17 ~20 ~35 ~17 ~20 wool 0  
fill ~34 ~17 ~15 ~35 ~17 ~15 double_stone_slab 0  
fill ~34 ~17 ~16 ~34 ~17 ~18 stone_slab 0  
fill ~35 ~17 ~16 ~35 ~17 ~19 double_stone_slab 0  
fill ~29 ~18 ~13 ~29 ~19 ~13 wool 0  
fill ~29 ~18 ~14 ~29 ~19 ~14 wool 0  
fill ~29 ~18 ~15 ~29 ~19 ~15 wool 0  
fill ~29 ~18 ~16 ~29 ~19 ~16 wool 0  
fill ~29 ~18 ~17 ~29 ~19 ~17 wool 0  
fill ~30 ~18 ~12 ~30 ~19 ~12 wool 0  
fill ~30 ~18 ~18 ~30 ~19 ~18 wool 0  
fill ~31 ~18 ~11 ~35 ~18 ~11 wool 0  
fill ~31 ~18 ~19 ~35 ~18 ~19 wool 0  
fill ~33 ~18 ~13 ~36 ~18 ~13 double_stone_slab 0  
fill ~33 ~18 ~14 ~33 ~18 ~13 double_stone_slab 0  
fill ~34 ~18 ~14 ~36 ~18 ~14 stone_slab 0  
fill ~36 ~18 ~12 ~36 ~19 ~12 wool 0  
fill ~36 ~18 ~15 ~36 ~18 ~17 stone_slab 0  
fill ~36 ~18 ~18 ~36 ~19 ~18 wool 0  
fill ~37 ~18 ~13 ~37 ~19 ~13 wool 0  
fill ~37 ~18 ~14 ~37 ~19 ~14 wool 0  
fill ~37 ~18 ~15 ~37 ~19 ~15 wool 0  
fill ~37 ~18 ~16 ~37 ~19 ~16 wool 0  
fill ~37 ~18 ~17 ~37 ~19 ~17 wool 0  
fill ~31 ~19 ~11 ~35 ~19 ~11 wool 0  
fill ~31 ~19 ~12 ~31 ~19 ~16 double_stone_slab 0  
fill ~31 ~19 ~19 ~35 ~19 ~19 wool 0  
fill ~32 ~19 ~12 ~35 ~19 ~12 stone_slab 0  
fill ~32 ~19 ~13 ~32 ~19 ~15 stone_slab 0 
setblock ~32 ~19 ~16 double_stone_slab 0  
fill ~29 ~20 ~13 ~29 ~22 ~13 wool 14  
fill ~29 ~20 ~14 ~29 ~22 ~14 wool 14  
fill ~29 ~20 ~15 ~29 ~22 ~15 wool 14  
fill ~29 ~20 ~16 ~29 ~22 ~16 wool 14  
fill ~29 ~20 ~17 ~29 ~22 ~17 wool 14  
fill ~30 ~20 ~12 ~30 ~22 ~12 wool 14  
fill ~30 ~20 ~13 ~30 ~20 ~17 stone_slab 0  
fill ~30 ~20 ~18 ~30 ~22 ~18 wool 14  
fill ~31 ~20 ~11 ~35 ~20 ~11 wool 14  
fill ~31 ~20 ~17 ~33 ~20 ~17 stone_slab 0  
fill ~31 ~20 ~18 ~34 ~20 ~18 double_stone_slab 0  
fill ~31 ~20 ~19 ~35 ~20 ~19 wool 14 
setblock ~33 ~20 ~16 stone_slab 0  
fill ~34 ~20 ~16 ~34 ~20 ~18 double_stone_slab 0  
fill ~36 ~20 ~12 ~36 ~22 ~12 wool 14  
fill ~36 ~20 ~18 ~36 ~22 ~18 wool 14  
fill ~37 ~20 ~13 ~37 ~22 ~13 wool 14  
fill ~37 ~20 ~14 ~37 ~22 ~14 wool 14  
fill ~37 ~20 ~15 ~37 ~22 ~15 wool 14  
fill ~37 ~20 ~16 ~37 ~22 ~16 wool 14  
fill ~37 ~20 ~17 ~37 ~22 ~17 wool 14  
fill ~31 ~21 ~11 ~31 ~22 ~11 wool 14  
fill ~31 ~21 ~19 ~35 ~21 ~19 wool 14  
fill ~32 ~21 ~11 ~34 ~21 ~11 glass 0  
fill ~34 ~21 ~14 ~36 ~21 ~14 double_stone_slab 0  
fill ~34 ~21 ~15 ~35 ~21 ~15 stone_slab 0  
fill ~35 ~21 ~11 ~35 ~22 ~11 wool 14  
fill ~35 ~21 ~16 ~35 ~21 ~18 stone_slab 0  
fill ~36 ~21 ~15 ~36 ~21 ~17 double_stone_slab 0  
fill ~31 ~22 ~19 ~35 ~22 ~19 wool 14  
fill ~32 ~22 ~11 ~35 ~22 ~11 wool 14  
fill ~32 ~22 ~12 ~35 ~22 ~12 double_stone_slab 0  
fill ~32 ~22 ~13 ~32 ~22 ~14 double_stone_slab 0  
fill ~33 ~22 ~13 ~36 ~22 ~13 stone_slab 0  
fill ~33 ~22 ~14 ~33 ~22 ~13 stone_slab 0  
fill ~29 ~23 ~13 ~29 ~24 ~13 wool 0  
fill ~29 ~23 ~14 ~29 ~24 ~14 wool 0  
fill ~29 ~23 ~15 ~29 ~24 ~15 wool 0  
fill ~29 ~23 ~16 ~29 ~24 ~16 wool 0  
fill ~29 ~23 ~17 ~29 ~24 ~17 wool 0  
fill ~30 ~23 ~12 ~30 ~24 ~12 wool 0  
fill ~30 ~23 ~13 ~30 ~23 ~16 double_stone_slab 0  
fill ~30 ~23 ~18 ~30 ~24 ~18 wool 0  
fill ~31 ~23 ~11 ~31 ~24 ~11 wool 0  
fill ~31 ~23 ~12 ~31 ~23 ~15 stone_slab 0  
fill ~31 ~23 ~16 ~32 ~23 ~16 double_stone_slab 0  
fill ~31 ~23 ~19 ~35 ~23 ~19 wool 0  
fill ~32 ~23 ~11 ~34 ~23 ~11 glass 0 
setblock ~32 ~23 ~15 stone_slab 0  
fill ~35 ~23 ~11 ~35 ~24 ~11 wool 0  
fill ~36 ~23 ~12 ~36 ~24 ~12 wool 0  
fill ~36 ~23 ~13 ~37 ~23 ~13 wool 0  
fill ~36 ~23 ~18 ~36 ~24 ~18 wool 0  
fill ~37 ~23 ~14 ~37 ~24 ~14 wool 0  
fill ~37 ~23 ~15 ~37 ~24 ~15 wool 0  
fill ~37 ~23 ~16 ~37 ~24 ~16 wool 0  
fill ~37 ~23 ~17 ~37 ~24 ~17 wool 0 
setblock ~30 ~24 ~13 wool 0 
setblock ~30 ~24 ~17 wool 0  
fill ~31 ~24 ~12 ~36 ~24 ~12 wool 0  
fill ~31 ~24 ~17 ~33 ~24 ~17 stone_slab 0  
fill ~31 ~24 ~18 ~31 ~24 ~19 wool 0  
fill ~32 ~24 ~11 ~35 ~24 ~11 wool 0  
fill ~32 ~24 ~18 ~34 ~24 ~18 double_stone_slab 0  
fill ~32 ~24 ~19 ~35 ~24 ~19 wool 0 
setblock ~33 ~24 ~16 stone_slab 0  
fill ~34 ~24 ~16 ~34 ~24 ~18 double_stone_slab 0 
setblock ~35 ~24 ~18 wool 0  
fill ~36 ~24 ~13 ~37 ~24 ~13 wool 0 
setblock ~36 ~24 ~17 wool 0  
fill ~30 ~25 ~14 ~30 ~26 ~14 wool 0  
fill ~30 ~25 ~15 ~30 ~26 ~15 wool 0  
fill ~30 ~25 ~16 ~30 ~26 ~16 wool 0  
fill ~31 ~25 ~13 ~31 ~26 ~13 wool 0  
fill ~31 ~25 ~17 ~31 ~26 ~17 wool 0  
fill ~32 ~25 ~12 ~34 ~25 ~12 wool 0  
fill ~32 ~25 ~18 ~34 ~25 ~18 wool 0  
fill ~34 ~25 ~14 ~35 ~25 ~14 double_stone_slab 0  
fill ~34 ~25 ~15 ~35 ~25 ~15 stone_slab 0  
fill ~35 ~25 ~13 ~35 ~26 ~13 wool 0 
setblock ~35 ~25 ~16 stone_slab 0  
fill ~35 ~25 ~17 ~35 ~26 ~17 wool 0  
fill ~36 ~25 ~14 ~36 ~26 ~14 wool 0  
fill ~36 ~25 ~15 ~36 ~26 ~15 wool 0  
fill ~36 ~25 ~16 ~36 ~26 ~16 wool 0  
fill ~32 ~26 ~12 ~34 ~26 ~12 wool 0  
fill ~32 ~26 ~13 ~32 ~26 ~14 double_stone_slab 0  
fill ~32 ~26 ~18 ~34 ~26 ~18 wool 0  
fill ~33 ~26 ~13 ~34 ~26 ~13 stone_slab 0  
fill ~33 ~26 ~14 ~33 ~26 ~13 stone_slab 0  
fill ~30 ~27 ~14 ~30 ~29 ~14 wool 14  
fill ~30 ~27 ~15 ~30 ~29 ~15 wool 14  
fill ~30 ~27 ~16 ~30 ~29 ~16 wool 14  
fill ~31 ~27 ~13 ~31 ~29 ~13 wool 14  
fill ~31 ~27 ~14 ~31 ~27 ~15 stone_slab 0  
fill ~31 ~27 ~16 ~32 ~27 ~16 double_stone_slab 0  
fill ~31 ~27 ~17 ~31 ~29 ~17 wool 14  
fill ~32 ~27 ~12 ~34 ~27 ~12 wool 14 
setblock ~32 ~27 ~15 stone_slab 0  
fill ~32 ~27 ~18 ~34 ~27 ~18 wool 14  
fill ~35 ~27 ~13 ~35 ~29 ~13 wool 14  
fill ~35 ~27 ~17 ~35 ~29 ~17 wool 14  
fill ~36 ~27 ~14 ~36 ~29 ~14 wool 14  
fill ~36 ~27 ~15 ~36 ~29 ~15 wool 14  
fill ~36 ~27 ~16 ~36 ~29 ~16 wool 14  
fill ~32 ~28 ~12 ~32 ~29 ~12 wool 14  
fill ~32 ~28 ~17 ~33 ~28 ~17 stone_slab 0  
fill ~32 ~28 ~18 ~34 ~28 ~18 wool 14 
setblock ~33 ~28 ~12 glass 0 
setblock ~33 ~28 ~16 stone_slab 0  
fill ~34 ~28 ~12 ~34 ~29 ~12 wool 14  
fill ~34 ~28 ~16 ~34 ~28 ~17 double_stone_slab 0  
fill ~32 ~29 ~18 ~34 ~29 ~18 wool 14 
setblock ~33 ~29 ~12 wool 14  
fill ~34 ~29 ~14 ~35 ~29 ~14 double_stone_slab 0  
fill ~34 ~29 ~15 ~35 ~29 ~15 stone_slab 0 
setblock ~35 ~29 ~16 stone_slab 0  
fill ~30 ~30 ~14 ~30 ~32 ~14 wool 0  
fill ~30 ~30 ~15 ~30 ~32 ~15 wool 0  
fill ~30 ~30 ~16 ~30 ~32 ~16 wool 0  
fill ~31 ~30 ~13 ~31 ~32 ~13 wool 0  
fill ~31 ~30 ~17 ~31 ~32 ~17 wool 0  
fill ~32 ~30 ~12 ~34 ~30 ~12 wool 0  
fill ~32 ~30 ~13 ~32 ~30 ~14 double_stone_slab 0  
fill ~32 ~30 ~18 ~34 ~30 ~18 wool 0  
fill ~33 ~30 ~13 ~34 ~30 ~13 stone_slab 0  
fill ~33 ~30 ~14 ~33 ~30 ~13 stone_slab 0  
fill ~35 ~30 ~13 ~35 ~32 ~13 wool 0  
fill ~35 ~30 ~17 ~35 ~32 ~17 wool 0  
fill ~36 ~30 ~14 ~36 ~32 ~14 wool 0  
fill ~36 ~30 ~15 ~36 ~32 ~15 wool 0  
fill ~36 ~30 ~16 ~36 ~32 ~16 wool 0  
fill ~31 ~31 ~14 ~31 ~31 ~15 stone_slab 0  
fill ~31 ~31 ~16 ~32 ~31 ~16 double_stone_slab 0  
fill ~32 ~31 ~12 ~32 ~32 ~12 wool 0 
setblock ~32 ~31 ~15 stone_slab 0  
fill ~32 ~31 ~18 ~34 ~31 ~18 wool 0   
fill ~33 ~31 ~12 ~33 ~32 ~12 glass 0  
fill ~34 ~31 ~12 ~34 ~32 ~12 wool 0  
fill ~32 ~32 ~17 ~33 ~32 ~17 stone_slab 0  
fill ~32 ~32 ~18 ~34 ~32 ~18 wool 0 
setblock ~33 ~32 ~16 stone_slab 0  
fill ~34 ~32 ~16 ~34 ~32 ~17 double_stone_slab 0  
fill ~30 ~33 ~14 ~30 ~35 ~14 wool 14  
fill ~30 ~33 ~15 ~30 ~35 ~15 wool 14  
fill ~30 ~33 ~16 ~30 ~35 ~16 wool 14  
fill ~31 ~33 ~13 ~31 ~35 ~13 wool 14  
fill ~31 ~33 ~17 ~31 ~35 ~17 wool 14  
fill ~32 ~33 ~12 ~34 ~33 ~12 wool 14  
fill ~32 ~33 ~18 ~34 ~33 ~18 wool 14  
fill ~34 ~33 ~14 ~35 ~33 ~14 double_stone_slab 0  
fill ~34 ~33 ~15 ~35 ~33 ~15 stone_slab 0  
fill ~35 ~33 ~13 ~35 ~35 ~13 wool 14 
setblock ~35 ~33 ~16 stone_slab 0  
fill ~35 ~33 ~17 ~35 ~35 ~17 wool 14  
fill ~36 ~33 ~14 ~36 ~35 ~14 wool 14  
fill ~36 ~33 ~15 ~36 ~35 ~15 wool 14  
fill ~36 ~33 ~16 ~36 ~35 ~16 wool 14  
fill ~32 ~34 ~12 ~34 ~34 ~12 wool 14  
fill ~32 ~34 ~13 ~32 ~34 ~14 double_stone_slab 0  
fill ~32 ~34 ~18 ~34 ~34 ~18 wool 14  
fill ~33 ~34 ~13 ~34 ~34 ~13 stone_slab 0  
fill ~33 ~34 ~14 ~33 ~34 ~13 stone_slab 0  
fill ~31 ~35 ~14 ~31 ~35 ~16 stone_slab 0  
fill ~32 ~35 ~12 ~34 ~35 ~12 wool 14  
fill ~32 ~35 ~15 ~32 ~35 ~16 stone_slab 0  
fill ~32 ~35 ~17 ~33 ~35 ~17 double_stone_slab 0  
fill ~32 ~35 ~18 ~34 ~35 ~18 wool 14 
setblock ~33 ~35 ~16 double_stone_slab 0  
fill ~30 ~36 ~14 ~30 ~38 ~14 wool 0  
fill ~30 ~36 ~15 ~30 ~38 ~15 wool 0  
fill ~30 ~36 ~16 ~30 ~38 ~16 wool 0  
fill ~31 ~36 ~13 ~31 ~38 ~13 wool 0  
fill ~31 ~36 ~15 ~31 ~38 ~15 ladder 5  
fill ~31 ~36 ~17 ~31 ~38 ~17 wool 0  
fill ~32 ~36 ~12 ~32 ~38 ~12 wool 0  
fill ~32 ~36 ~17 ~33 ~36 ~17 fence 0  
fill ~32 ~36 ~18 ~34 ~36 ~18 wool 0 
setblock ~33 ~36 ~12 glass 0 
setblock ~33 ~36 ~16 fence 0  
fill ~34 ~36 ~12 ~34 ~38 ~12 wool 0  
fill ~35 ~36 ~13 ~35 ~38 ~13 wool 0  
fill ~35 ~36 ~17 ~35 ~38 ~17 wool 0  
fill ~36 ~36 ~14 ~36 ~38 ~14 wool 0  
fill ~36 ~36 ~15 ~36 ~38 ~15 wool 0  
fill ~36 ~36 ~16 ~36 ~38 ~16 wool 0  
fill ~32 ~37 ~13 ~35 ~37 ~13 wool 0  
fill ~32 ~37 ~17 ~35 ~37 ~17 wool 0  
fill ~32 ~37 ~18 ~34 ~37 ~18 wool 0  
fill ~33 ~37 ~12 ~33 ~38 ~12 wool 0  
fill ~33 ~37 ~14 ~36 ~37 ~14 wool 0  
fill ~33 ~37 ~15 ~36 ~37 ~15 wool 0  
fill ~33 ~37 ~16 ~36 ~37 ~16 wool 0  
fill ~29 ~38 ~14 ~29 ~38 ~16 wool 0 
setblock ~30 ~38 ~13 wool 0 
setblock ~30 ~38 ~17 wool 0 
setblock ~31 ~38 ~12 wool 0  
fill ~31 ~38 ~14 ~37 ~38 ~14 wool 0  
fill ~31 ~38 ~16 ~37 ~38 ~16 wool 0  
fill ~31 ~38 ~18 ~35 ~38 ~18 wool 0  
fill ~32 ~38 ~11 ~34 ~38 ~11 wool 0  
fill ~32 ~38 ~13 ~36 ~38 ~13 wool 0  
fill ~32 ~38 ~15 ~37 ~38 ~15 wool 0  
fill ~32 ~38 ~17 ~36 ~38 ~17 wool 0  
fill ~32 ~38 ~19 ~34 ~38 ~19 wool 0 
setblock ~35 ~38 ~12 wool 0  
fill ~29 ~39 ~14 ~29 ~43 ~14 glass 0  
fill ~29 ~39 ~15 ~29 ~43 ~15 glass 0  
fill ~29 ~39 ~16 ~29 ~43 ~16 glass 0  
fill ~30 ~39 ~13 ~30 ~43 ~13 glass 0  
fill ~30 ~39 ~17 ~30 ~43 ~17 glass 0  
fill ~31 ~39 ~12 ~31 ~43 ~12 glass 0  
fill ~31 ~39 ~18 ~31 ~43 ~18 glass 0  
fill ~32 ~39 ~11 ~34 ~39 ~11 glass 0  
fill ~32 ~39 ~19 ~34 ~39 ~19 glass 0  
fill ~35 ~39 ~12 ~35 ~43 ~12 glass 0  
fill ~35 ~39 ~18 ~35 ~43 ~18 glass 0  
fill ~36 ~39 ~13 ~36 ~43 ~13 glass 0  
fill ~36 ~39 ~17 ~36 ~43 ~17 glass 0  
fill ~37 ~39 ~14 ~37 ~43 ~14 glass 0  
fill ~37 ~39 ~15 ~37 ~43 ~15 glass 0  
fill ~37 ~39 ~16 ~37 ~43 ~16 glass 0  
fill ~32 ~40 ~11 ~34 ~40 ~11 glass 0  
fill ~32 ~40 ~14 ~34 ~40 ~14 glowstone 0  
fill ~32 ~40 ~15 ~34 ~40 ~15 glowstone 0  
fill ~32 ~40 ~16 ~34 ~40 ~16 glowstone 0  
fill ~32 ~40 ~19 ~34 ~40 ~19 glass 0  
fill ~32 ~41 ~11 ~34 ~41 ~11 glass 0  
fill ~32 ~41 ~14 ~34 ~41 ~14 glowstone 0  
fill ~32 ~41 ~15 ~34 ~41 ~15 glowstone 0  
fill ~32 ~41 ~16 ~34 ~41 ~16 glowstone 0  
fill ~32 ~41 ~19 ~34 ~41 ~19 glass 0  
fill ~32 ~42 ~11 ~34 ~42 ~11 glass 0  
fill ~32 ~42 ~14 ~34 ~42 ~14 glowstone 0  
fill ~32 ~42 ~15 ~34 ~42 ~15 glowstone 0  
fill ~32 ~42 ~16 ~34 ~42 ~16 glowstone 0  
fill ~32 ~42 ~19 ~34 ~42 ~19 glass 0  
fill ~32 ~43 ~11 ~34 ~43 ~11 glass 0  
fill ~32 ~43 ~19 ~34 ~43 ~19 glass 0  
fill ~29 ~44 ~14 ~29 ~44 ~16 wool 0 
setblock ~30 ~44 ~13 wool 0 
setblock ~30 ~44 ~17 wool 0 
setblock ~31 ~44 ~12 wool 0 
setblock ~31 ~44 ~18 wool 0  
fill ~32 ~44 ~11 ~34 ~44 ~11 wool 0  
fill ~32 ~44 ~19 ~34 ~44 ~19 wool 0 
setblock ~35 ~44 ~12 wool 0 
setblock ~35 ~44 ~18 wool 0 
setblock ~36 ~44 ~13 wool 0 
setblock ~36 ~44 ~17 wool 0  
fill ~37 ~44 ~14 ~37 ~44 ~16 wool 0  
fill ~30 ~45 ~14 ~30 ~45 ~16 wool 0 
setblock ~31 ~45 ~13 wool 0 
setblock ~31 ~45 ~17 wool 0  
fill ~32 ~45 ~12 ~34 ~45 ~12 wool 0  
fill ~32 ~45 ~18 ~34 ~45 ~18 wool 0 
setblock ~35 ~45 ~13 wool 0 
setblock ~35 ~45 ~17 wool 0  
fill ~36 ~45 ~14 ~36 ~45 ~16 wool 0  
fill ~31 ~46 ~14 ~31 ~46 ~16 wool 0  
fill ~32 ~46 ~13 ~34 ~46 ~13 wool 0  
fill ~32 ~46 ~14 ~34 ~46 ~14 glowstone 0  
fill ~32 ~46 ~15 ~34 ~46 ~15 glowstone 0  
fill ~32 ~46 ~16 ~34 ~46 ~16 glowstone 0  
fill ~32 ~46 ~17 ~34 ~46 ~17 wool 0  
fill ~35 ~46 ~14 ~35 ~46 ~16 wool 0  
fill ~32 ~47 ~15 ~34 ~47 ~15 wool 14 
setblock ~33 ~47 ~14 wool 14 
setblock ~33 ~47 ~16 wool 14 
setblock ~33 ~48 ~15 wool 14  
setblock ~33 ~9 ~14 wall_sign 4  
setblock ~36 ~7 ~12 wall_sign 2  
setblock ~36 ~7 ~14 wall_sign 3  
setblock ~34 ~1 ~19 wall_sign 3  
setblock ~34 ~1 ~21 wall_sign 2  
setblock ~35 ~1 ~18 wall_sign 5  
setblock ~35 ~1 ~22 wall_sign 5    