fill ~1 ~-1 ~1 ~21 ~-1 ~1 grass 0  
fill ~1 ~-1 ~2 ~21 ~-1 ~2 grass 0  
fill ~1 ~-1 ~3 ~3 ~-1 ~3 grass 0  
fill ~1 ~-1 ~4 ~2 ~-1 ~4 grass 0  
fill ~1 ~-1 ~5 ~2 ~-1 ~5 grass 0  
fill ~1 ~-1 ~6 ~2 ~-1 ~6 grass 0  
fill ~1 ~-1 ~7 ~11 ~-1 ~7 grass 0  
fill ~1 ~-1 ~8 ~11 ~-1 ~8 grass 0  
fill ~1 ~-1 ~9 ~11 ~-1 ~9 grass 0  
fill ~1 ~-1 ~10 ~11 ~-1 ~10 grass 0  
fill ~1 ~-1 ~11 ~11 ~-1 ~11 grass 0  
fill ~1 ~-1 ~12 ~2 ~-1 ~12 grass 0  
fill ~1 ~-1 ~13 ~3 ~-1 ~13 grass 0  
fill ~1 ~-1 ~14 ~3 ~-1 ~14 grass 0  
fill ~1 ~-1 ~15 ~3 ~-1 ~15 grass 0  
fill ~1 ~-1 ~16 ~2 ~-1 ~16 grass 0  
fill ~1 ~-1 ~17 ~3 ~-1 ~17 grass 0  
fill ~1 ~-1 ~18 ~3 ~-1 ~18 grass 0  
fill ~1 ~-1 ~19 ~3 ~-1 ~19 grass 0  
fill ~1 ~-1 ~20 ~2 ~-1 ~20 grass 0  
fill ~1 ~-1 ~21 ~11 ~-1 ~21 grass 0  
fill ~1 ~-1 ~22 ~11 ~-1 ~22 grass 0  
fill ~1 ~-1 ~23 ~11 ~-1 ~23 grass 0  
fill ~1 ~-1 ~24 ~11 ~-1 ~24 grass 0  
fill ~1 ~-1 ~25 ~12 ~-1 ~25 grass 0  
fill ~1 ~-1 ~26 ~12 ~-1 ~26 grass 0  
fill ~1 ~-1 ~27 ~11 ~-1 ~27 grass 0  
fill ~1 ~-1 ~28 ~12 ~-1 ~28 grass 0  
fill ~1 ~-1 ~29 ~12 ~-1 ~29 grass 0  
fill ~1 ~-1 ~30 ~11 ~-1 ~30 grass 0  
fill ~1 ~-1 ~31 ~12 ~-1 ~31 grass 0  
fill ~1 ~-1 ~32 ~12 ~-1 ~32 grass 0  
fill ~1 ~-1 ~33 ~11 ~-1 ~33 grass 0  
fill ~1 ~-1 ~34 ~11 ~-1 ~34 grass 0  
fill ~1 ~-1 ~35 ~69 ~-1 ~35 grass 0  
fill ~1 ~-1 ~36 ~69 ~-1 ~36 grass 0  
fill ~1 ~-1 ~37 ~69 ~-1 ~37 grass 0  
fill ~1 ~-1 ~38 ~69 ~-1 ~38 grass 0  
fill ~1 ~-1 ~39 ~31 ~-1 ~39 grass 0  
fill ~1 ~-1 ~40 ~69 ~-1 ~40 grass 0  
fill ~1 ~-1 ~41 ~69 ~-1 ~41 grass 0  
fill ~1 ~-1 ~42 ~69 ~-1 ~42 grass 0  
fill ~1 ~-1 ~43 ~22 ~-1 ~43 grass 0  
fill ~3 ~-1 ~4 ~7 ~-1 ~4 dirt 0  
fill ~3 ~-1 ~5 ~7 ~-1 ~5 dirt 0  
fill ~3 ~-1 ~6 ~6 ~-1 ~6 dirt 0 
setblock ~3 ~-1 ~12 dirt 0 
setblock ~3 ~-1 ~16 dirt 0 
setblock ~3 ~-1 ~20 dirt 0  
fill ~4 ~-1 ~3 ~6 ~-1 ~3 dirt 0  
fill ~4 ~-1 ~12 ~6 ~-1 ~12 grass 0  
fill ~4 ~-1 ~13 ~11 ~-1 ~13 glowstone 0  
fill ~4 ~-1 ~14 ~4 ~-1 ~19 glowstone 0  
fill ~4 ~-1 ~20 ~6 ~-1 ~20 grass 0  
fill ~5 ~-1 ~14 ~19 ~-1 ~14 planks 2  
fill ~5 ~-1 ~15 ~19 ~-1 ~15 planks 2  
fill ~5 ~-1 ~16 ~19 ~-1 ~16 planks 2  
fill ~5 ~-1 ~17 ~19 ~-1 ~17 planks 2  
fill ~5 ~-1 ~18 ~19 ~-1 ~18 planks 2  
fill ~5 ~-1 ~19 ~11 ~-1 ~19 glowstone 0  
fill ~7 ~-1 ~3 ~21 ~-1 ~3 grass 0  
fill ~7 ~-1 ~6 ~11 ~-1 ~6 grass 0 
setblock ~7 ~-1 ~12 dirt 0 
setblock ~7 ~-1 ~20 dirt 0  
fill ~8 ~-1 ~4 ~11 ~-1 ~4 grass 0  
fill ~8 ~-1 ~5 ~11 ~-1 ~5 grass 0  
fill ~8 ~-1 ~12 ~10 ~-1 ~12 grass 0  
fill ~8 ~-1 ~20 ~10 ~-1 ~20 grass 0 
setblock ~11 ~-1 ~12 dirt 0 
setblock ~11 ~-1 ~20 dirt 0  
fill ~12 ~-1 ~4 ~12 ~-1 ~5 dirt 0  
fill ~12 ~-1 ~6 ~19 ~-1 ~6 planks 2  
fill ~12 ~-1 ~7 ~19 ~-1 ~7 planks 2  
fill ~12 ~-1 ~8 ~19 ~-1 ~8 planks 2  
fill ~12 ~-1 ~9 ~19 ~-1 ~9 planks 2  
fill ~12 ~-1 ~10 ~19 ~-1 ~10 planks 2  
fill ~12 ~-1 ~11 ~19 ~-1 ~11 planks 2  
fill ~12 ~-1 ~12 ~19 ~-1 ~12 planks 2  
fill ~12 ~-1 ~13 ~19 ~-1 ~13 planks 2  
fill ~12 ~-1 ~19 ~19 ~-1 ~19 planks 2  
fill ~12 ~-1 ~20 ~19 ~-1 ~20 planks 2  
fill ~12 ~-1 ~21 ~19 ~-1 ~21 planks 2  
fill ~12 ~-1 ~22 ~19 ~-1 ~22 planks 2  
fill ~12 ~-1 ~23 ~12 ~-1 ~24 dirt 0 
setblock ~12 ~-1 ~27 dirt 0 
setblock ~12 ~-1 ~30 dirt 0  
fill ~12 ~-1 ~33 ~12 ~-1 ~34 dirt 0  
fill ~13 ~-1 ~4 ~15 ~-1 ~4 grass 0  
fill ~13 ~-1 ~5 ~19 ~-1 ~5 glowstone 0  
fill ~13 ~-1 ~23 ~27 ~-1 ~23 planks 2  
fill ~13 ~-1 ~24 ~57 ~-1 ~24 planks 2  
fill ~13 ~-1 ~25 ~57 ~-1 ~25 planks 2  
fill ~13 ~-1 ~26 ~57 ~-1 ~26 planks 2  
fill ~13 ~-1 ~27 ~57 ~-1 ~27 planks 2  
fill ~13 ~-1 ~28 ~57 ~-1 ~28 planks 2  
fill ~13 ~-1 ~29 ~57 ~-1 ~29 planks 2  
fill ~13 ~-1 ~30 ~57 ~-1 ~30 planks 2  
fill ~13 ~-1 ~31 ~57 ~-1 ~31 planks 2  
fill ~13 ~-1 ~32 ~35 ~-1 ~32 planks 2  
fill ~13 ~-1 ~33 ~13 ~-1 ~6 planks 2  
fill ~13 ~-1 ~34 ~17 ~-1 ~34 dirt 0 
setblock ~14 ~-1 ~33 glowstone 0  
fill ~15 ~-1 ~33 ~26 ~-1 ~33 planks 2 
setblock ~16 ~-1 ~4 dirt 0  
fill ~17 ~-1 ~4 ~19 ~-1 ~4 grass 0  
fill ~18 ~-1 ~34 ~19 ~-1 ~34 grass 0  
fill ~20 ~-1 ~4 ~20 ~-1 ~18 dirt 0  
fill ~20 ~-1 ~19 ~21 ~-1 ~19 grass 0  
fill ~20 ~-1 ~20 ~20 ~-1 ~22 dirt 0 
setblock ~20 ~-1 ~34 dirt 0 
setblock ~21 ~-1 ~4 grass 0 
setblock ~21 ~-1 ~5 glowstone 0  
fill ~21 ~-1 ~6 ~21 ~-1 ~10 grass 0 
setblock ~21 ~-1 ~11 glowstone 0  
fill ~21 ~-1 ~12 ~21 ~-1 ~16 grass 0 
setblock ~21 ~-1 ~17 glowstone 0 
setblock ~21 ~-1 ~18 grass 0 
setblock ~21 ~-1 ~20 grass 0 
setblock ~21 ~-1 ~21 glowstone 0  
fill ~21 ~-1 ~22 ~29 ~-1 ~22 dirt 0  
fill ~21 ~-1 ~34 ~22 ~-1 ~34 grass 0  
fill ~22 ~-1 ~1 ~24 ~-1 ~1 double_stone_slab 0  
fill ~22 ~-1 ~2 ~24 ~-1 ~2 double_stone_slab 0  
fill ~22 ~-1 ~3 ~24 ~-1 ~3 double_stone_slab 0  
fill ~22 ~-1 ~4 ~24 ~-1 ~4 double_stone_slab 0  
fill ~22 ~-1 ~5 ~24 ~-1 ~5 double_stone_slab 0  
fill ~22 ~-1 ~6 ~24 ~-1 ~6 double_stone_slab 0  
fill ~22 ~-1 ~7 ~24 ~-1 ~7 double_stone_slab 0  
fill ~22 ~-1 ~8 ~24 ~-1 ~8 double_stone_slab 0  
fill ~22 ~-1 ~9 ~24 ~-1 ~9 double_stone_slab 0  
fill ~22 ~-1 ~10 ~24 ~-1 ~10 double_stone_slab 0  
fill ~22 ~-1 ~11 ~24 ~-1 ~11 double_stone_slab 0  
fill ~22 ~-1 ~12 ~24 ~-1 ~12 double_stone_slab 0  
fill ~22 ~-1 ~13 ~24 ~-1 ~13 double_stone_slab 0  
fill ~22 ~-1 ~14 ~24 ~-1 ~14 double_stone_slab 0  
fill ~22 ~-1 ~15 ~24 ~-1 ~15 double_stone_slab 0  
fill ~22 ~-1 ~16 ~24 ~-1 ~16 double_stone_slab 0  
fill ~22 ~-1 ~17 ~24 ~-1 ~17 double_stone_slab 0  
fill ~22 ~-1 ~18 ~28 ~-1 ~18 double_stone_slab 0  
fill ~22 ~-1 ~19 ~28 ~-1 ~19 double_stone_slab 0  
fill ~22 ~-1 ~20 ~28 ~-1 ~20 double_stone_slab 0  
fill ~22 ~-1 ~21 ~24 ~-1 ~21 grass 0 
setblock ~23 ~-1 ~34 dirt 0  
fill ~23 ~-1 ~43 ~24 ~-1 ~43 sand 0  
fill ~24 ~-1 ~34 ~25 ~-1 ~34 grass 0  
fill ~25 ~-1 ~1 ~45 ~-1 ~1 grass 0  
fill ~25 ~-1 ~2 ~28 ~-1 ~2 grass 0  
fill ~25 ~-1 ~3 ~28 ~-1 ~3 grass 0  
fill ~25 ~-1 ~4 ~28 ~-1 ~4 grass 0 
setblock ~25 ~-1 ~5 glowstone 0  
fill ~25 ~-1 ~6 ~28 ~-1 ~6 grass 0  
fill ~25 ~-1 ~7 ~28 ~-1 ~7 grass 0  
fill ~25 ~-1 ~8 ~28 ~-1 ~8 grass 0  
fill ~25 ~-1 ~9 ~28 ~-1 ~9 grass 0  
fill ~25 ~-1 ~10 ~28 ~-1 ~10 grass 0 
setblock ~25 ~-1 ~11 glowstone 0  
fill ~25 ~-1 ~12 ~28 ~-1 ~12 grass 0  
fill ~25 ~-1 ~13 ~28 ~-1 ~13 grass 0  
fill ~25 ~-1 ~14 ~28 ~-1 ~14 grass 0  
fill ~25 ~-1 ~15 ~28 ~-1 ~15 grass 0  
fill ~25 ~-1 ~16 ~28 ~-1 ~16 grass 0 
setblock ~25 ~-1 ~17 glowstone 0 
setblock ~25 ~-1 ~21 glowstone 0  
fill ~25 ~-1 ~43 ~28 ~-1 ~43 grass 0  
fill ~26 ~-1 ~5 ~28 ~-1 ~5 grass 0  
fill ~26 ~-1 ~11 ~28 ~-1 ~11 grass 0  
fill ~26 ~-1 ~17 ~29 ~-1 ~17 grass 0  
fill ~26 ~-1 ~21 ~29 ~-1 ~21 grass 0  
fill ~26 ~-1 ~34 ~31 ~-1 ~34 dirt 0 
setblock ~27 ~-1 ~33 glowstone 0 
setblock ~28 ~-1 ~23 glowstone 0  
fill ~28 ~-1 ~33 ~42 ~-1 ~33 planks 2  
fill ~29 ~-1 ~2 ~41 ~-1 ~2 sand 0  
fill ~29 ~-1 ~3 ~41 ~-1 ~3 sand 0  
fill ~29 ~-1 ~4 ~41 ~-1 ~4 sand 0  
fill ~29 ~-1 ~5 ~41 ~-1 ~5 double_stone_slab 0  
fill ~29 ~-1 ~6 ~29 ~-1 ~15 double_stone_slab 0 
setblock ~29 ~-1 ~16 dirt 0 
setblock ~29 ~-1 ~18 dirt 0  
fill ~29 ~-1 ~19 ~41 ~-1 ~19 planks 2 
setblock ~29 ~-1 ~20 dirt 0  
fill ~29 ~-1 ~23 ~41 ~-1 ~23 planks 2  
fill ~29 ~-1 ~43 ~39 ~-1 ~43 sand 0  
fill ~30 ~-1 ~6 ~40 ~-1 ~6 water 0  
fill ~30 ~-1 ~7 ~40 ~-1 ~7 water 0  
fill ~30 ~-1 ~8 ~40 ~-1 ~8 water 0  
fill ~30 ~-1 ~9 ~40 ~-1 ~9 water 0  
fill ~30 ~-1 ~10 ~40 ~-1 ~10 water 0  
fill ~30 ~-1 ~11 ~40 ~-1 ~11 water 0  
fill ~30 ~-1 ~12 ~40 ~-1 ~12 water 0  
fill ~30 ~-1 ~13 ~40 ~-1 ~13 water 0  
fill ~30 ~-1 ~14 ~40 ~-1 ~14 water 0  
fill ~30 ~-1 ~15 ~31 ~-1 ~15 double_stone_slab 0  
fill ~30 ~-1 ~16 ~34 ~-1 ~16 glowstone 0  
fill ~30 ~-1 ~17 ~40 ~-1 ~17 planks 2  
fill ~30 ~-1 ~18 ~40 ~-1 ~18 planks 2  
fill ~30 ~-1 ~20 ~40 ~-1 ~20 planks 2  
fill ~30 ~-1 ~21 ~40 ~-1 ~21 planks 2  
fill ~30 ~-1 ~22 ~40 ~-1 ~22 planks 2 
setblock ~32 ~-1 ~15 glowstone 0  
fill ~32 ~-1 ~34 ~38 ~-1 ~34 grass 0 
setblock ~32 ~-1 ~39 dirt 0  
fill ~33 ~-1 ~15 ~37 ~-1 ~15 double_stone_slab 0  
fill ~33 ~-1 ~39 ~37 ~-1 ~39 grass 0  
fill ~36 ~-1 ~16 ~40 ~-1 ~16 glowstone 0 
setblock ~36 ~-1 ~32 glowstone 0  
fill ~37 ~-1 ~32 ~57 ~-1 ~32 planks 2 
setblock ~38 ~-1 ~15 glowstone 0 
setblock ~38 ~-1 ~39 dirt 0  
fill ~39 ~-1 ~15 ~41 ~-1 ~15 double_stone_slab 0  
fill ~39 ~-1 ~34 ~44 ~-1 ~34 dirt 0  
fill ~39 ~-1 ~39 ~69 ~-1 ~39 grass 0  
fill ~40 ~-1 ~43 ~68 ~-1 ~43 grass 0  
fill ~41 ~-1 ~6 ~41 ~-1 ~15 double_stone_slab 0 
setblock ~41 ~-1 ~16 dirt 0  
fill ~41 ~-1 ~17 ~44 ~-1 ~17 grass 0 
setblock ~41 ~-1 ~18 dirt 0 
setblock ~41 ~-1 ~20 dirt 0  
fill ~41 ~-1 ~21 ~44 ~-1 ~21 grass 0  
fill ~41 ~-1 ~22 ~50 ~-1 ~22 dirt 0  
fill ~42 ~-1 ~2 ~45 ~-1 ~2 grass 0  
fill ~42 ~-1 ~3 ~45 ~-1 ~3 grass 0  
fill ~42 ~-1 ~4 ~45 ~-1 ~4 grass 0  
fill ~42 ~-1 ~5 ~44 ~-1 ~5 grass 0  
fill ~42 ~-1 ~6 ~45 ~-1 ~6 grass 0  
fill ~42 ~-1 ~7 ~45 ~-1 ~7 grass 0  
fill ~42 ~-1 ~8 ~45 ~-1 ~8 grass 0  
fill ~42 ~-1 ~9 ~45 ~-1 ~9 grass 0  
fill ~42 ~-1 ~10 ~45 ~-1 ~10 grass 0  
fill ~42 ~-1 ~11 ~44 ~-1 ~11 grass 0  
fill ~42 ~-1 ~12 ~45 ~-1 ~12 grass 0  
fill ~42 ~-1 ~13 ~45 ~-1 ~13 grass 0  
fill ~42 ~-1 ~14 ~45 ~-1 ~14 grass 0  
fill ~42 ~-1 ~15 ~45 ~-1 ~15 grass 0  
fill ~42 ~-1 ~16 ~45 ~-1 ~16 grass 0  
fill ~42 ~-1 ~18 ~48 ~-1 ~18 double_stone_slab 0  
fill ~42 ~-1 ~19 ~48 ~-1 ~19 double_stone_slab 0  
fill ~42 ~-1 ~20 ~48 ~-1 ~20 double_stone_slab 0 
setblock ~42 ~-1 ~23 glowstone 0  
fill ~43 ~-1 ~23 ~57 ~-1 ~23 planks 2 
setblock ~43 ~-1 ~33 glowstone 0  
fill ~44 ~-1 ~33 ~55 ~-1 ~33 planks 2 
setblock ~45 ~-1 ~5 glowstone 0 
setblock ~45 ~-1 ~11 glowstone 0 
setblock ~45 ~-1 ~17 glowstone 0 
setblock ~45 ~-1 ~21 glowstone 0  
fill ~45 ~-1 ~34 ~46 ~-1 ~34 grass 0  
fill ~46 ~-1 ~1 ~48 ~-1 ~1 double_stone_slab 0  
fill ~46 ~-1 ~2 ~48 ~-1 ~2 double_stone_slab 0  
fill ~46 ~-1 ~3 ~48 ~-1 ~3 double_stone_slab 0  
fill ~46 ~-1 ~4 ~48 ~-1 ~4 double_stone_slab 0  
fill ~46 ~-1 ~5 ~48 ~-1 ~5 double_stone_slab 0  
fill ~46 ~-1 ~6 ~48 ~-1 ~6 double_stone_slab 0  
fill ~46 ~-1 ~7 ~48 ~-1 ~7 double_stone_slab 0  
fill ~46 ~-1 ~8 ~48 ~-1 ~8 double_stone_slab 0  
fill ~46 ~-1 ~9 ~48 ~-1 ~9 double_stone_slab 0  
fill ~46 ~-1 ~10 ~48 ~-1 ~10 double_stone_slab 0  
fill ~46 ~-1 ~11 ~48 ~-1 ~11 double_stone_slab 0  
fill ~46 ~-1 ~12 ~48 ~-1 ~12 double_stone_slab 0  
fill ~46 ~-1 ~13 ~48 ~-1 ~13 double_stone_slab 0  
fill ~46 ~-1 ~14 ~48 ~-1 ~14 double_stone_slab 0  
fill ~46 ~-1 ~15 ~48 ~-1 ~15 double_stone_slab 0  
fill ~46 ~-1 ~16 ~48 ~-1 ~16 double_stone_slab 0  
fill ~46 ~-1 ~17 ~48 ~-1 ~17 double_stone_slab 0  
fill ~46 ~-1 ~21 ~48 ~-1 ~21 grass 0 
setblock ~47 ~-1 ~34 dirt 0  
fill ~48 ~-1 ~34 ~49 ~-1 ~34 grass 0  
fill ~49 ~-1 ~1 ~69 ~-1 ~1 grass 0  
fill ~49 ~-1 ~2 ~69 ~-1 ~2 grass 0  
fill ~49 ~-1 ~3 ~63 ~-1 ~3 grass 0  
fill ~49 ~-1 ~4 ~49 ~-1 ~1 grass 0 
setblock ~49 ~-1 ~5 glowstone 0  
fill ~49 ~-1 ~6 ~49 ~-1 ~10 grass 0 
setblock ~49 ~-1 ~11 glowstone 0  
fill ~49 ~-1 ~12 ~49 ~-1 ~16 grass 0 
setblock ~49 ~-1 ~17 glowstone 0  
fill ~49 ~-1 ~18 ~49 ~-1 ~20 grass 0 
setblock ~49 ~-1 ~21 glowstone 0  
fill ~50 ~-1 ~4 ~50 ~-1 ~18 dirt 0 
setblock ~50 ~-1 ~19 grass 0  
fill ~50 ~-1 ~20 ~50 ~-1 ~22 dirt 0 
setblock ~50 ~-1 ~34 dirt 0  
fill ~51 ~-1 ~4 ~53 ~-1 ~4 grass 0  
fill ~51 ~-1 ~5 ~57 ~-1 ~5 glowstone 0  
fill ~51 ~-1 ~6 ~58 ~-1 ~6 planks 2  
fill ~51 ~-1 ~7 ~58 ~-1 ~7 planks 2  
fill ~51 ~-1 ~8 ~58 ~-1 ~8 planks 2  
fill ~51 ~-1 ~9 ~58 ~-1 ~9 planks 2  
fill ~51 ~-1 ~10 ~58 ~-1 ~10 planks 2  
fill ~51 ~-1 ~11 ~58 ~-1 ~11 planks 2  
fill ~51 ~-1 ~12 ~58 ~-1 ~12 planks 2  
fill ~51 ~-1 ~13 ~58 ~-1 ~13 planks 2  
fill ~51 ~-1 ~14 ~65 ~-1 ~14 planks 2  
fill ~51 ~-1 ~15 ~65 ~-1 ~15 planks 2  
fill ~51 ~-1 ~16 ~65 ~-1 ~16 planks 2  
fill ~51 ~-1 ~17 ~65 ~-1 ~17 planks 2  
fill ~51 ~-1 ~18 ~65 ~-1 ~18 planks 2  
fill ~51 ~-1 ~19 ~58 ~-1 ~19 planks 2  
fill ~51 ~-1 ~20 ~58 ~-1 ~20 planks 2  
fill ~51 ~-1 ~21 ~58 ~-1 ~21 planks 2  
fill ~51 ~-1 ~22 ~58 ~-1 ~22 planks 2  
fill ~51 ~-1 ~34 ~52 ~-1 ~34 grass 0  
fill ~53 ~-1 ~34 ~58 ~-1 ~34 dirt 0 
setblock ~54 ~-1 ~4 dirt 0  
fill ~55 ~-1 ~4 ~57 ~-1 ~4 grass 0 
setblock ~56 ~-1 ~33 glowstone 0 
setblock ~57 ~-1 ~33 planks 2  
fill ~58 ~-1 ~4 ~58 ~-1 ~5 dirt 0  
fill ~58 ~-1 ~23 ~58 ~-1 ~24 dirt 0  
fill ~58 ~-1 ~25 ~69 ~-1 ~25 grass 0  
fill ~58 ~-1 ~26 ~69 ~-1 ~26 grass 0 
setblock ~58 ~-1 ~27 dirt 0  
fill ~58 ~-1 ~28 ~69 ~-1 ~28 grass 0  
fill ~58 ~-1 ~29 ~69 ~-1 ~29 grass 0 
setblock ~58 ~-1 ~30 dirt 0  
fill ~58 ~-1 ~31 ~69 ~-1 ~31 grass 0  
fill ~58 ~-1 ~32 ~69 ~-1 ~32 grass 0 
setblock ~58 ~-1 ~33 dirt 0  
fill ~59 ~-1 ~4 ~62 ~-1 ~4 grass 0  
fill ~59 ~-1 ~5 ~62 ~-1 ~5 grass 0  
fill ~59 ~-1 ~6 ~63 ~-1 ~6 grass 0  
fill ~59 ~-1 ~7 ~69 ~-1 ~7 grass 0  
fill ~59 ~-1 ~8 ~69 ~-1 ~8 grass 0  
fill ~59 ~-1 ~9 ~69 ~-1 ~9 grass 0  
fill ~59 ~-1 ~10 ~69 ~-1 ~10 grass 0  
fill ~59 ~-1 ~11 ~69 ~-1 ~11 grass 0 
setblock ~59 ~-1 ~12 dirt 0  
fill ~59 ~-1 ~13 ~66 ~-1 ~13 glowstone 0  
fill ~59 ~-1 ~19 ~66 ~-1 ~19 glowstone 0 
setblock ~59 ~-1 ~20 dirt 0  
fill ~59 ~-1 ~21 ~69 ~-1 ~21 grass 0  
fill ~59 ~-1 ~22 ~69 ~-1 ~22 grass 0  
fill ~59 ~-1 ~23 ~69 ~-1 ~23 grass 0  
fill ~59 ~-1 ~24 ~69 ~-1 ~24 grass 0  
fill ~59 ~-1 ~27 ~69 ~-1 ~27 grass 0  
fill ~59 ~-1 ~30 ~69 ~-1 ~30 grass 0  
fill ~59 ~-1 ~33 ~69 ~-1 ~33 grass 0  
fill ~59 ~-1 ~34 ~69 ~-1 ~34 grass 0  
fill ~60 ~-1 ~12 ~62 ~-1 ~12 grass 0  
fill ~60 ~-1 ~20 ~62 ~-1 ~20 grass 0  
fill ~63 ~-1 ~4 ~67 ~-1 ~4 dirt 0  
fill ~63 ~-1 ~5 ~67 ~-1 ~5 dirt 0 
setblock ~63 ~-1 ~12 dirt 0 
setblock ~63 ~-1 ~20 dirt 0  
fill ~64 ~-1 ~3 ~66 ~-1 ~3 dirt 0  
fill ~64 ~-1 ~6 ~67 ~-1 ~6 dirt 0  
fill ~64 ~-1 ~12 ~66 ~-1 ~12 grass 0  
fill ~64 ~-1 ~20 ~66 ~-1 ~20 grass 0  
fill ~66 ~-1 ~14 ~66 ~-1 ~19 glowstone 0  
fill ~67 ~-1 ~3 ~69 ~-1 ~3 grass 0 
setblock ~67 ~-1 ~12 dirt 0  
fill ~67 ~-1 ~13 ~69 ~-1 ~13 grass 0  
fill ~67 ~-1 ~14 ~69 ~-1 ~14 grass 0  
fill ~67 ~-1 ~15 ~69 ~-1 ~15 grass 0 
setblock ~67 ~-1 ~16 dirt 0  
fill ~67 ~-1 ~17 ~69 ~-1 ~17 grass 0  
fill ~67 ~-1 ~18 ~69 ~-1 ~18 grass 0  
fill ~67 ~-1 ~19 ~69 ~-1 ~19 grass 0 
setblock ~67 ~-1 ~20 dirt 0  
fill ~68 ~-1 ~4 ~69 ~-1 ~4 grass 0  
fill ~68 ~-1 ~5 ~69 ~-1 ~5 grass 0  
fill ~68 ~-1 ~6 ~69 ~-1 ~6 grass 0  
fill ~68 ~-1 ~12 ~69 ~-1 ~12 grass 0  
fill ~68 ~-1 ~16 ~69 ~-1 ~16 grass 0  
fill ~68 ~-1 ~20 ~69 ~-1 ~20 grass 0  
fill ~2 ~0 ~4 ~2 ~0 ~6 stone_slab 0 
setblock ~2 ~0 ~12 leaves 12 
setblock ~2 ~0 ~16 leaves 12 
setblock ~2 ~0 ~20 leaves 12 
setblock ~3 ~0 ~3 stone_slab 0 
setblock ~3 ~0 ~4 water 2 
setblock ~3 ~0 ~5 water 1 
setblock ~3 ~0 ~6 water 2 
setblock ~3 ~0 ~7 stone_slab 0 
setblock ~3 ~0 ~11 leaves 12  
fill ~3 ~0 ~12 ~3 ~4 ~12 snow 0  
fill ~3 ~0 ~13 ~3 ~0 ~15 leaves 12  
fill ~3 ~0 ~16 ~3 ~4 ~16 snow 0  
fill ~3 ~0 ~17 ~3 ~0 ~19 leaves 12  
fill ~3 ~0 ~20 ~3 ~4 ~20 snow 0 
setblock ~3 ~0 ~21 leaves 12  
fill ~4 ~0 ~2 ~6 ~0 ~2 stone_slab 0 
setblock ~4 ~0 ~3 water 2 
setblock ~4 ~0 ~4 water 1  
fill ~4 ~0 ~5 ~4 ~2 ~5 water 9 
setblock ~4 ~0 ~6 water 1 
setblock ~4 ~0 ~7 water 2  
fill ~4 ~0 ~8 ~6 ~0 ~8 stone_slab 0  
fill ~4 ~0 ~12 ~6 ~0 ~12 leaves 12  
fill ~4 ~0 ~13 ~11 ~0 ~13 glass 0  
fill ~4 ~0 ~14 ~4 ~4 ~14 glass 0  
fill ~4 ~0 ~15 ~4 ~4 ~15 glass 0  
fill ~4 ~0 ~16 ~4 ~4 ~16 glass 0  
fill ~4 ~0 ~17 ~4 ~4 ~17 glass 0  
fill ~4 ~0 ~18 ~4 ~4 ~18 glass 0  
fill ~4 ~0 ~19 ~11 ~0 ~19 glass 0  
fill ~4 ~0 ~20 ~6 ~0 ~20 leaves 12 
setblock ~5 ~0 ~3 water 1  
fill ~5 ~0 ~4 ~5 ~2 ~4 water 9  
fill ~5 ~0 ~5 ~5 ~2 ~5 double_stone_slab 0  
fill ~5 ~0 ~6 ~5 ~2 ~6 water 9 
setblock ~5 ~0 ~7 water 1 
setblock ~6 ~0 ~3 water 2 
setblock ~6 ~0 ~4 water 1  
fill ~6 ~0 ~5 ~6 ~2 ~5 water 9 
setblock ~6 ~0 ~6 water 1 
setblock ~6 ~0 ~7 water 2 
setblock ~7 ~0 ~3 stone_slab 0 
setblock ~7 ~0 ~4 water 2 
setblock ~7 ~0 ~5 water 1 
setblock ~7 ~0 ~6 water 2 
setblock ~7 ~0 ~7 stone_slab 0 
setblock ~7 ~0 ~11 leaves 8  
fill ~7 ~0 ~12 ~7 ~4 ~12 snow 0  
fill ~7 ~0 ~20 ~7 ~4 ~20 snow 0 
setblock ~7 ~0 ~21 leaves 8  
fill ~8 ~0 ~4 ~8 ~0 ~6 stone_slab 0  
fill ~8 ~0 ~12 ~10 ~0 ~12 leaves 12  
fill ~8 ~0 ~20 ~10 ~0 ~20 leaves 12  
fill ~11 ~0 ~4 ~11 ~0 ~11 leaves 12  
fill ~11 ~0 ~12 ~12 ~0 ~12 snow 0  
fill ~11 ~0 ~20 ~12 ~0 ~20 snow 0  
fill ~11 ~0 ~21 ~11 ~0 ~24 leaves 12 
setblock ~11 ~0 ~27 leaves 12 
setblock ~11 ~0 ~30 leaves 12  
fill ~11 ~0 ~33 ~11 ~0 ~34 leaves 12 
setblock ~12 ~0 ~3 leaves 12  
fill ~12 ~0 ~4 ~12 ~6 ~4 snow 0  
fill ~12 ~0 ~5 ~12 ~6 ~5 snow 0  
fill ~12 ~0 ~6 ~12 ~6 ~6 snow 0  
fill ~12 ~0 ~7 ~12 ~6 ~7 snow 0  
fill ~12 ~0 ~8 ~12 ~6 ~8 snow 0  
fill ~12 ~0 ~9 ~12 ~10 ~9 snow 0  
fill ~12 ~0 ~10 ~12 ~10 ~10 snow 0  
fill ~12 ~0 ~11 ~12 ~7 ~11 snow 0  
fill ~12 ~0 ~13 ~12 ~7 ~13 snow 0  
fill ~12 ~0 ~19 ~12 ~7 ~19 snow 0  
fill ~12 ~0 ~21 ~12 ~7 ~21 snow 0  
fill ~12 ~0 ~22 ~12 ~10 ~22 snow 0  
fill ~12 ~0 ~23 ~12 ~7 ~23 snow 0  
fill ~12 ~0 ~24 ~13 ~0 ~24 snow 0  
fill ~12 ~0 ~25 ~12 ~0 ~26 leaves 12  
fill ~12 ~0 ~27 ~13 ~0 ~27 snow 0  
fill ~12 ~0 ~28 ~12 ~0 ~29 leaves 12  
fill ~12 ~0 ~30 ~13 ~0 ~30 snow 0  
fill ~12 ~0 ~31 ~12 ~0 ~32 leaves 12  
fill ~12 ~0 ~33 ~13 ~0 ~33 snow 0  
fill ~12 ~0 ~34 ~17 ~0 ~34 snow 0  
fill ~12 ~0 ~35 ~17 ~0 ~35 leaves 12  
fill ~13 ~0 ~4 ~15 ~0 ~4 leaves 12  
fill ~13 ~0 ~5 ~19 ~0 ~5 glass 0  
fill ~13 ~0 ~25 ~13 ~4 ~25 glass 0  
fill ~13 ~0 ~26 ~13 ~4 ~26 glass 0  
fill ~13 ~0 ~28 ~13 ~4 ~28 glass 0  
fill ~13 ~0 ~29 ~13 ~4 ~29 glass 0  
fill ~13 ~0 ~31 ~13 ~4 ~31 glass 0  
fill ~13 ~0 ~32 ~13 ~4 ~32 glass 0 
setblock ~16 ~0 ~3 leaves 12  
fill ~16 ~0 ~4 ~16 ~6 ~4 snow 0  
fill ~17 ~0 ~4 ~19 ~0 ~4 leaves 12  
fill ~17 ~0 ~33 ~17 ~6 ~33 snow 0  
fill ~18 ~0 ~33 ~19 ~0 ~33 glass 0  
fill ~18 ~0 ~34 ~19 ~0 ~34 leaves 12 
setblock ~20 ~0 ~3 leaves 12  
fill ~20 ~0 ~4 ~20 ~6 ~4 snow 0  
fill ~20 ~0 ~5 ~20 ~6 ~5 snow 0  
fill ~20 ~0 ~6 ~20 ~6 ~6 snow 0  
fill ~20 ~0 ~7 ~20 ~0 ~17 snow 0  
fill ~20 ~0 ~18 ~20 ~4 ~18 planks 3  
fill ~20 ~0 ~20 ~20 ~4 ~20 planks 3  
fill ~20 ~0 ~21 ~20 ~6 ~21 snow 0  
fill ~20 ~0 ~22 ~29 ~0 ~22 snow 0  
fill ~20 ~0 ~33 ~20 ~6 ~33 snow 0  
fill ~20 ~0 ~34 ~20 ~10 ~34 snow 0 
setblock ~20 ~0 ~35 leaves 8 
setblock ~21 ~0 ~4 leaves 12  
fill ~21 ~0 ~5 ~21 ~4 ~5 cobblestone_wall 0  
fill ~21 ~0 ~6 ~21 ~0 ~9 leaves 12 
setblock ~21 ~0 ~10 leaves 8  
fill ~21 ~0 ~11 ~21 ~4 ~11 cobblestone_wall 0  
fill ~21 ~0 ~12 ~21 ~0 ~15 leaves 12 
setblock ~21 ~0 ~16 leaves 8  
fill ~21 ~0 ~17 ~21 ~4 ~17 cobblestone_wall 0 
setblock ~21 ~0 ~18 tallgrass 0 
setblock ~21 ~0 ~20 tallgrass 0  
fill ~21 ~0 ~21 ~21 ~4 ~21 cobblestone_wall 0  
fill ~21 ~0 ~33 ~22 ~0 ~33 glass 0  
fill ~21 ~0 ~34 ~22 ~0 ~34 leaves 12  
fill ~22 ~0 ~21 ~23 ~0 ~21 leaves 12  
fill ~23 ~0 ~33 ~23 ~6 ~33 snow 0  
fill ~23 ~0 ~34 ~23 ~10 ~34 snow 0 
setblock ~23 ~0 ~35 leaves 12 
setblock ~24 ~0 ~21 leaves 8  
fill ~24 ~0 ~33 ~25 ~0 ~33 glass 0  
fill ~24 ~0 ~34 ~25 ~0 ~34 leaves 12  
fill ~25 ~0 ~5 ~25 ~4 ~5 cobblestone_wall 0  
fill ~25 ~0 ~11 ~25 ~4 ~11 cobblestone_wall 0  
fill ~25 ~0 ~17 ~25 ~4 ~17 cobblestone_wall 0  
fill ~25 ~0 ~21 ~25 ~4 ~21 cobblestone_wall 0  
fill ~26 ~0 ~8 ~26 ~1 ~8 fence 0  
fill ~26 ~0 ~14 ~26 ~1 ~14 fence 0  
fill ~26 ~0 ~21 ~28 ~0 ~21 leaves 12  
fill ~26 ~0 ~33 ~26 ~6 ~33 snow 0  
fill ~26 ~0 ~34 ~31 ~0 ~34 snow 0  
fill ~26 ~0 ~35 ~30 ~0 ~35 leaves 12  
fill ~27 ~0 ~3 ~27 ~1 ~3 fence 0 
setblock ~28 ~0 ~4 leaves 8  
fill ~28 ~0 ~5 ~28 ~0 ~15 leaves 12  
fill ~29 ~0 ~16 ~29 ~10 ~16 double_stone_slab 0  
fill ~29 ~0 ~17 ~29 ~10 ~17 glass 0  
fill ~29 ~0 ~18 ~29 ~2 ~18 double_stone_slab 0 
setblock ~29 ~0 ~19 wooden_door 4  
fill ~29 ~0 ~20 ~29 ~2 ~20 double_stone_slab 0  
fill ~29 ~0 ~21 ~29 ~10 ~21 glass 0  
fill ~29 ~0 ~23 ~29 ~10 ~23 snow 0  
fill ~30 ~0 ~16 ~31 ~0 ~16 glass 0  
fill ~31 ~0 ~33 ~31 ~2 ~33 snow 0 
setblock ~31 ~0 ~35 leaves 8  
fill ~32 ~0 ~15 ~32 ~13 ~15 snow 0  
fill ~32 ~0 ~16 ~32 ~8 ~16 snow 0  
fill ~32 ~0 ~33 ~33 ~0 ~33 glass 0  
fill ~32 ~0 ~39 ~32 ~10 ~39 snow 0  
fill ~33 ~0 ~16 ~37 ~0 ~16 glass 0  
fill ~34 ~0 ~33 ~34 ~2 ~33 snow 0 
setblock ~35 ~0 ~33 wooden_door 7  
fill ~36 ~0 ~33 ~36 ~2 ~33 snow 0  
fill ~37 ~0 ~33 ~38 ~0 ~33 glass 0  
fill ~38 ~0 ~15 ~38 ~13 ~15 snow 0  
fill ~38 ~0 ~16 ~38 ~8 ~16 snow 0  
fill ~38 ~0 ~39 ~38 ~10 ~39 snow 0  
fill ~39 ~0 ~16 ~40 ~0 ~16 glass 0  
fill ~39 ~0 ~33 ~39 ~2 ~33 snow 0  
fill ~39 ~0 ~34 ~44 ~0 ~34 snow 0 
setblock ~39 ~0 ~35 leaves 8  
fill ~40 ~0 ~35 ~44 ~0 ~35 leaves 12  
fill ~41 ~0 ~16 ~41 ~10 ~16 double_stone_slab 0  
fill ~41 ~0 ~17 ~41 ~10 ~17 glass 0  
fill ~41 ~0 ~18 ~41 ~2 ~18 double_stone_slab 0 
setblock ~41 ~0 ~19 wooden_door 2  
fill ~41 ~0 ~20 ~41 ~2 ~20 double_stone_slab 0  
fill ~41 ~0 ~21 ~41 ~10 ~21 glass 0  
fill ~41 ~0 ~22 ~50 ~0 ~22 snow 0  
fill ~41 ~0 ~23 ~41 ~10 ~23 snow 0 
setblock ~42 ~0 ~4 leaves 8  
fill ~42 ~0 ~5 ~42 ~0 ~15 leaves 12  
fill ~42 ~0 ~21 ~44 ~0 ~21 leaves 12  
fill ~43 ~0 ~3 ~43 ~1 ~3 fence 0  
fill ~44 ~0 ~8 ~44 ~1 ~8 fence 0  
fill ~44 ~0 ~14 ~44 ~1 ~14 fence 0  
fill ~44 ~0 ~33 ~44 ~6 ~33 snow 0  
fill ~45 ~0 ~5 ~45 ~4 ~5 cobblestone_wall 0  
fill ~45 ~0 ~11 ~45 ~4 ~11 cobblestone_wall 0  
fill ~45 ~0 ~17 ~45 ~4 ~17 cobblestone_wall 0  
fill ~45 ~0 ~21 ~45 ~4 ~21 cobblestone_wall 0  
fill ~45 ~0 ~33 ~46 ~0 ~33 glass 0  
fill ~45 ~0 ~34 ~46 ~0 ~34 leaves 12 
setblock ~46 ~0 ~21 leaves 8  
fill ~47 ~0 ~21 ~48 ~0 ~21 leaves 12  
fill ~47 ~0 ~33 ~47 ~6 ~33 snow 0  
fill ~47 ~0 ~34 ~47 ~10 ~34 snow 0 
setblock ~47 ~0 ~35 leaves 12  
fill ~48 ~0 ~33 ~49 ~0 ~33 glass 0  
fill ~48 ~0 ~34 ~49 ~0 ~34 leaves 12 
setblock ~49 ~0 ~4 leaves 12  
fill ~49 ~0 ~5 ~49 ~4 ~5 cobblestone_wall 0  
fill ~49 ~0 ~6 ~49 ~0 ~9 leaves 12 
setblock ~49 ~0 ~10 leaves 8  
fill ~49 ~0 ~11 ~49 ~4 ~11 cobblestone_wall 0  
fill ~49 ~0 ~12 ~49 ~0 ~15 leaves 12 
setblock ~49 ~0 ~16 leaves 8  
fill ~49 ~0 ~17 ~49 ~4 ~17 cobblestone_wall 0 
setblock ~49 ~0 ~18 tallgrass 0 
setblock ~49 ~0 ~20 tallgrass 0  
fill ~49 ~0 ~21 ~49 ~4 ~21 cobblestone_wall 0 
setblock ~50 ~0 ~3 leaves 12  
fill ~50 ~0 ~4 ~50 ~6 ~4 snow 0  
fill ~50 ~0 ~5 ~50 ~6 ~5 snow 0  
fill ~50 ~0 ~6 ~50 ~6 ~6 snow 0  
fill ~50 ~0 ~7 ~50 ~0 ~17 snow 0  
fill ~50 ~0 ~18 ~50 ~4 ~18 planks 3  
fill ~50 ~0 ~20 ~50 ~4 ~20 planks 3  
fill ~50 ~0 ~21 ~50 ~6 ~21 snow 0  
fill ~50 ~0 ~33 ~50 ~6 ~33 snow 0  
fill ~50 ~0 ~34 ~50 ~10 ~34 snow 0 
setblock ~50 ~0 ~35 leaves 8  
fill ~51 ~0 ~4 ~53 ~0 ~4 leaves 12  
fill ~51 ~0 ~5 ~57 ~0 ~5 glass 0  
fill ~51 ~0 ~33 ~52 ~0 ~33 glass 0  
fill ~51 ~0 ~34 ~52 ~0 ~34 leaves 12  
fill ~53 ~0 ~33 ~53 ~6 ~33 snow 0  
fill ~53 ~0 ~34 ~58 ~0 ~34 snow 0  
fill ~53 ~0 ~35 ~58 ~0 ~35 leaves 12 
setblock ~54 ~0 ~3 leaves 12  
fill ~54 ~0 ~4 ~54 ~6 ~4 snow 0  
fill ~55 ~0 ~4 ~57 ~0 ~4 leaves 12  
fill ~57 ~0 ~24 ~58 ~0 ~24 snow 0  
fill ~57 ~0 ~25 ~57 ~4 ~25 glass 0  
fill ~57 ~0 ~26 ~57 ~4 ~26 glass 0  
fill ~57 ~0 ~27 ~58 ~0 ~27 snow 0  
fill ~57 ~0 ~28 ~57 ~4 ~28 glass 0  
fill ~57 ~0 ~29 ~57 ~4 ~29 glass 0  
fill ~57 ~0 ~30 ~58 ~0 ~30 snow 0  
fill ~57 ~0 ~31 ~57 ~4 ~31 glass 0  
fill ~57 ~0 ~32 ~57 ~4 ~32 glass 0  
fill ~57 ~0 ~33 ~58 ~0 ~33 snow 0 
setblock ~58 ~0 ~3 leaves 12  
fill ~58 ~0 ~4 ~58 ~6 ~4 snow 0  
fill ~58 ~0 ~5 ~58 ~6 ~5 snow 0  
fill ~58 ~0 ~6 ~58 ~6 ~6 snow 0  
fill ~58 ~0 ~7 ~58 ~6 ~7 snow 0  
fill ~58 ~0 ~8 ~58 ~6 ~8 snow 0  
fill ~58 ~0 ~9 ~58 ~10 ~9 snow 0  
fill ~58 ~0 ~10 ~58 ~10 ~10 snow 0  
fill ~58 ~0 ~11 ~58 ~7 ~11 snow 0  
fill ~58 ~0 ~12 ~59 ~0 ~12 snow 0  
fill ~58 ~0 ~13 ~58 ~7 ~13 snow 0  
fill ~58 ~0 ~19 ~58 ~7 ~19 snow 0  
fill ~58 ~0 ~20 ~59 ~0 ~20 snow 0  
fill ~58 ~0 ~21 ~58 ~7 ~21 snow 0  
fill ~58 ~0 ~22 ~58 ~10 ~22 snow 0  
fill ~58 ~0 ~23 ~58 ~7 ~23 snow 0  
fill ~58 ~0 ~25 ~58 ~0 ~26 leaves 12  
fill ~58 ~0 ~28 ~58 ~0 ~29 leaves 12  
fill ~58 ~0 ~31 ~58 ~0 ~32 leaves 12  
fill ~59 ~0 ~4 ~59 ~0 ~11 leaves 12  
fill ~59 ~0 ~13 ~66 ~0 ~13 glass 0  
fill ~59 ~0 ~19 ~66 ~0 ~19 glass 0  
fill ~59 ~0 ~21 ~59 ~0 ~24 leaves 12 
setblock ~59 ~0 ~27 leaves 12 
setblock ~59 ~0 ~30 leaves 12  
fill ~59 ~0 ~33 ~59 ~0 ~34 leaves 12  
fill ~60 ~0 ~12 ~62 ~0 ~12 leaves 12  
fill ~60 ~0 ~20 ~62 ~0 ~20 leaves 12  
fill ~62 ~0 ~4 ~62 ~0 ~6 stone_slab 0 
setblock ~63 ~0 ~3 stone_slab 0 
setblock ~63 ~0 ~4 water 2 
setblock ~63 ~0 ~5 water 1 
setblock ~63 ~0 ~6 water 2 
setblock ~63 ~0 ~7 stone_slab 0 
setblock ~63 ~0 ~11 leaves 8  
fill ~63 ~0 ~12 ~63 ~4 ~12 snow 0  
fill ~63 ~0 ~20 ~63 ~4 ~20 snow 0 
setblock ~63 ~0 ~21 leaves 8  
fill ~64 ~0 ~2 ~66 ~0 ~2 stone_slab 0 
setblock ~64 ~0 ~3 water 2 
setblock ~64 ~0 ~4 water 1  
fill ~64 ~0 ~5 ~64 ~2 ~5 water 9 
setblock ~64 ~0 ~6 water 1 
setblock ~64 ~0 ~7 water 2  
fill ~64 ~0 ~8 ~66 ~0 ~8 stone_slab 0  
fill ~64 ~0 ~12 ~66 ~0 ~12 leaves 12  
fill ~64 ~0 ~20 ~66 ~0 ~20 leaves 12 
setblock ~65 ~0 ~3 water 1  
fill ~65 ~0 ~4 ~65 ~2 ~4 water 9  
fill ~65 ~0 ~5 ~65 ~2 ~5 double_stone_slab 0  
fill ~65 ~0 ~6 ~65 ~2 ~6 water 9 
setblock ~65 ~0 ~7 water 1 
setblock ~66 ~0 ~3 water 2 
setblock ~66 ~0 ~4 water 1  
fill ~66 ~0 ~5 ~66 ~2 ~5 water 9 
setblock ~66 ~0 ~6 water 1 
setblock ~66 ~0 ~7 water 2  
fill ~66 ~0 ~14 ~66 ~4 ~14 glass 0  
fill ~66 ~0 ~15 ~66 ~4 ~15 glass 0  
fill ~66 ~0 ~16 ~66 ~4 ~16 glass 0  
fill ~66 ~0 ~17 ~66 ~4 ~17 glass 0  
fill ~66 ~0 ~18 ~66 ~4 ~18 glass 0 
setblock ~67 ~0 ~3 stone_slab 0 
setblock ~67 ~0 ~4 water 2 
setblock ~67 ~0 ~5 water 1 
setblock ~67 ~0 ~6 water 2 
setblock ~67 ~0 ~7 stone_slab 0 
setblock ~67 ~0 ~11 leaves 12  
fill ~67 ~0 ~12 ~67 ~4 ~12 snow 0  
fill ~67 ~0 ~13 ~67 ~0 ~15 leaves 12  
fill ~67 ~0 ~16 ~67 ~4 ~16 snow 0  
fill ~67 ~0 ~17 ~67 ~0 ~19 leaves 12  
fill ~67 ~0 ~20 ~67 ~4 ~20 snow 0 
setblock ~67 ~0 ~21 leaves 12  
fill ~68 ~0 ~4 ~68 ~0 ~6 stone_slab 0 
setblock ~68 ~0 ~12 leaves 12 
setblock ~68 ~0 ~16 leaves 12 
setblock ~68 ~0 ~20 leaves 12  
fill ~4 ~1 ~13 ~11 ~1 ~13 glass 0  
fill ~4 ~1 ~19 ~11 ~1 ~19 glass 0  
fill ~11 ~1 ~12 ~12 ~1 ~12 snow 0  
fill ~11 ~1 ~20 ~12 ~1 ~20 snow 0  
fill ~12 ~1 ~24 ~13 ~1 ~24 snow 0  
fill ~12 ~1 ~27 ~13 ~1 ~27 snow 0  
fill ~12 ~1 ~30 ~13 ~1 ~30 snow 0  
fill ~12 ~1 ~33 ~13 ~1 ~33 snow 0  
fill ~12 ~1 ~34 ~17 ~1 ~34 snow 0  
fill ~13 ~1 ~5 ~19 ~1 ~5 glass 0  
fill ~18 ~1 ~33 ~19 ~1 ~33 glass 0  
fill ~20 ~1 ~7 ~20 ~3 ~7 sandstone 0  
fill ~20 ~1 ~8 ~20 ~1 ~9 sandstone 0  
fill ~20 ~1 ~10 ~20 ~6 ~10 snow 0  
fill ~20 ~1 ~11 ~20 ~6 ~11 snow 0  
fill ~20 ~1 ~12 ~20 ~6 ~12 snow 0  
fill ~20 ~1 ~13 ~20 ~3 ~13 sandstone 0  
fill ~20 ~1 ~14 ~20 ~1 ~15 sandstone 0  
fill ~20 ~1 ~16 ~20 ~6 ~16 snow 0  
fill ~20 ~1 ~17 ~20 ~6 ~17 snow 0  
fill ~20 ~1 ~22 ~29 ~1 ~22 snow 0  
fill ~21 ~1 ~33 ~22 ~1 ~33 glass 0  
fill ~24 ~1 ~33 ~25 ~1 ~33 glass 0  
fill ~26 ~1 ~34 ~31 ~1 ~34 snow 0 
setblock ~29 ~1 ~19 wooden_door 8  
fill ~30 ~1 ~16 ~31 ~1 ~16 glass 0  
fill ~32 ~1 ~33 ~33 ~1 ~33 glass 0  
fill ~33 ~1 ~16 ~37 ~1 ~16 glass 0 
setblock ~35 ~1 ~33 wooden_door 8  
fill ~37 ~1 ~33 ~38 ~1 ~33 glass 0  
fill ~39 ~1 ~16 ~40 ~1 ~16 glass 0  
fill ~39 ~1 ~34 ~44 ~1 ~34 snow 0 
setblock ~41 ~1 ~19 wooden_door 8  
fill ~41 ~1 ~22 ~50 ~1 ~22 snow 0  
fill ~45 ~1 ~33 ~46 ~1 ~33 glass 0  
fill ~48 ~1 ~33 ~49 ~1 ~33 glass 0  
fill ~50 ~1 ~7 ~50 ~3 ~7 sandstone 0  
fill ~50 ~1 ~8 ~50 ~1 ~9 sandstone 0  
fill ~50 ~1 ~10 ~50 ~6 ~10 snow 0  
fill ~50 ~1 ~11 ~50 ~6 ~11 snow 0  
fill ~50 ~1 ~12 ~50 ~6 ~12 snow 0  
fill ~50 ~1 ~13 ~50 ~3 ~13 sandstone 0  
fill ~50 ~1 ~14 ~50 ~1 ~15 sandstone 0  
fill ~50 ~1 ~16 ~50 ~6 ~16 snow 0  
fill ~50 ~1 ~17 ~50 ~6 ~17 snow 0  
fill ~51 ~1 ~5 ~57 ~1 ~5 glass 0  
fill ~51 ~1 ~33 ~52 ~1 ~33 glass 0  
fill ~53 ~1 ~34 ~58 ~1 ~34 snow 0  
fill ~57 ~1 ~24 ~58 ~1 ~24 snow 0  
fill ~57 ~1 ~27 ~58 ~1 ~27 snow 0  
fill ~57 ~1 ~30 ~58 ~1 ~30 snow 0  
fill ~57 ~1 ~33 ~58 ~1 ~33 snow 0  
fill ~58 ~1 ~12 ~59 ~1 ~12 snow 0  
fill ~58 ~1 ~20 ~59 ~1 ~20 snow 0  
fill ~59 ~1 ~13 ~66 ~1 ~13 glass 0  
fill ~59 ~1 ~19 ~66 ~1 ~19 glass 0  
fill ~4 ~2 ~13 ~11 ~2 ~13 glass 0  
fill ~4 ~2 ~19 ~11 ~2 ~19 glass 0  
fill ~11 ~2 ~12 ~12 ~2 ~12 snow 0  
fill ~11 ~2 ~20 ~12 ~2 ~20 snow 0  
fill ~12 ~2 ~24 ~13 ~2 ~24 snow 0  
fill ~12 ~2 ~27 ~13 ~2 ~27 snow 0  
fill ~12 ~2 ~30 ~13 ~2 ~30 snow 0  
fill ~12 ~2 ~33 ~13 ~2 ~33 snow 0  
fill ~12 ~2 ~34 ~17 ~2 ~34 snow 0  
fill ~13 ~2 ~5 ~19 ~2 ~5 glass 0  
fill ~18 ~2 ~33 ~19 ~2 ~33 glass 0 
setblock ~20 ~2 ~8 snow 0  
fill ~20 ~2 ~9 ~20 ~3 ~9 sandstone 0 
setblock ~20 ~2 ~14 snow 0  
fill ~20 ~2 ~15 ~20 ~3 ~15 sandstone 0  
fill ~20 ~2 ~19 ~20 ~4 ~19 planks 3  
fill ~20 ~2 ~22 ~29 ~2 ~22 snow 0  
fill ~21 ~2 ~33 ~22 ~2 ~33 glass 0  
fill ~24 ~2 ~33 ~25 ~2 ~33 glass 0  
fill ~26 ~2 ~8 ~26 ~3 ~8 leaves 12  
fill ~26 ~2 ~14 ~26 ~3 ~14 leaves 12  
fill ~26 ~2 ~34 ~31 ~2 ~34 snow 0  
fill ~27 ~2 ~3 ~27 ~3 ~3 leaves 12 
setblock ~29 ~2 ~19 double_stone_slab 0  
fill ~30 ~2 ~16 ~31 ~2 ~16 glass 0  
fill ~32 ~2 ~33 ~33 ~2 ~33 glass 0  
fill ~33 ~2 ~16 ~37 ~2 ~16 glass 0 
setblock ~35 ~2 ~33 snow 0  
fill ~37 ~2 ~33 ~38 ~2 ~33 glass 0  
fill ~39 ~2 ~16 ~40 ~2 ~16 glass 0  
fill ~39 ~2 ~34 ~44 ~2 ~34 snow 0 
setblock ~41 ~2 ~19 double_stone_slab 0  
fill ~41 ~2 ~22 ~50 ~2 ~22 snow 0  
fill ~43 ~2 ~3 ~43 ~3 ~3 leaves 12  
fill ~44 ~2 ~8 ~44 ~3 ~8 leaves 12  
fill ~44 ~2 ~14 ~44 ~3 ~14 leaves 12  
fill ~45 ~2 ~33 ~46 ~2 ~33 glass 0  
fill ~48 ~2 ~33 ~49 ~2 ~33 glass 0 
setblock ~50 ~2 ~8 snow 0  
fill ~50 ~2 ~9 ~50 ~3 ~9 sandstone 0 
setblock ~50 ~2 ~14 snow 0  
fill ~50 ~2 ~15 ~50 ~3 ~15 sandstone 0  
fill ~50 ~2 ~19 ~50 ~4 ~19 planks 3  
fill ~51 ~2 ~5 ~57 ~2 ~5 glass 0  
fill ~51 ~2 ~33 ~52 ~2 ~33 glass 0  
fill ~53 ~2 ~34 ~58 ~2 ~34 snow 0  
fill ~57 ~2 ~24 ~58 ~2 ~24 snow 0  
fill ~57 ~2 ~27 ~58 ~2 ~27 snow 0  
fill ~57 ~2 ~30 ~58 ~2 ~30 snow 0  
fill ~57 ~2 ~33 ~58 ~2 ~33 snow 0  
fill ~58 ~2 ~12 ~59 ~2 ~12 snow 0  
fill ~58 ~2 ~20 ~59 ~2 ~20 snow 0  
fill ~59 ~2 ~13 ~66 ~2 ~13 glass 0  
fill ~59 ~2 ~19 ~66 ~2 ~19 glass 0 
setblock ~4 ~3 ~5 water 1  
fill ~4 ~3 ~13 ~11 ~3 ~13 glass 0  
fill ~4 ~3 ~19 ~11 ~3 ~19 glass 0 
setblock ~5 ~3 ~4 water 1 
setblock ~5 ~3 ~5 water 0 
setblock ~5 ~3 ~6 water 1 
setblock ~6 ~3 ~5 water 1 
setblock ~11 ~3 ~7 torch 2  
fill ~11 ~3 ~12 ~12 ~3 ~12 snow 0  
fill ~11 ~3 ~20 ~12 ~3 ~20 snow 0 
setblock ~11 ~3 ~27 torch 2 
setblock ~11 ~3 ~30 torch 2  
fill ~12 ~3 ~24 ~13 ~3 ~24 snow 0  
fill ~12 ~3 ~27 ~13 ~3 ~27 snow 0  
fill ~12 ~3 ~30 ~13 ~3 ~30 snow 0  
fill ~12 ~3 ~33 ~13 ~3 ~33 snow 0  
fill ~12 ~3 ~34 ~17 ~3 ~34 snow 0  
fill ~13 ~3 ~5 ~19 ~3 ~5 glass 0  
fill ~18 ~3 ~33 ~19 ~3 ~33 glass 0 
setblock ~20 ~3 ~8 sandstone 0 
setblock ~20 ~3 ~14 sandstone 0  
fill ~20 ~3 ~22 ~29 ~3 ~22 snow 0  
fill ~21 ~3 ~33 ~22 ~3 ~33 glass 0  
fill ~24 ~3 ~33 ~25 ~3 ~33 glass 0  
fill ~26 ~3 ~34 ~32 ~3 ~34 snow 0  
fill ~29 ~3 ~18 ~29 ~10 ~18 glass 0  
fill ~29 ~3 ~19 ~29 ~10 ~19 glass 0  
fill ~29 ~3 ~20 ~29 ~10 ~20 glass 0  
fill ~30 ~3 ~16 ~31 ~3 ~16 glass 0 
setblock ~32 ~3 ~33 snow 0  
fill ~33 ~3 ~16 ~37 ~3 ~16 glass 0  
fill ~33 ~3 ~33 ~37 ~3 ~33 glass 0 
setblock ~34 ~3 ~20 glowstone 0  
fill ~38 ~3 ~33 ~38 ~3 ~34 snow 0  
fill ~39 ~3 ~16 ~40 ~3 ~16 glass 0  
fill ~39 ~3 ~34 ~44 ~3 ~34 snow 0  
fill ~41 ~3 ~18 ~41 ~10 ~18 glass 0  
fill ~41 ~3 ~19 ~41 ~10 ~19 glass 0  
fill ~41 ~3 ~20 ~41 ~10 ~20 glass 0  
fill ~41 ~3 ~22 ~50 ~3 ~22 snow 0  
fill ~45 ~3 ~33 ~46 ~3 ~33 glass 0  
fill ~48 ~3 ~33 ~49 ~3 ~33 glass 0 
setblock ~50 ~3 ~8 sandstone 0 
setblock ~50 ~3 ~14 sandstone 0  
fill ~51 ~3 ~5 ~57 ~3 ~5 glass 0  
fill ~51 ~3 ~33 ~52 ~3 ~33 glass 0  
fill ~53 ~3 ~34 ~58 ~3 ~34 snow 0  
fill ~57 ~3 ~24 ~58 ~3 ~24 snow 0  
fill ~57 ~3 ~27 ~58 ~3 ~27 snow 0  
fill ~57 ~3 ~30 ~58 ~3 ~30 snow 0  
fill ~57 ~3 ~33 ~58 ~3 ~33 snow 0  
fill ~58 ~3 ~12 ~59 ~3 ~12 snow 0  
fill ~58 ~3 ~20 ~59 ~3 ~20 snow 0 
setblock ~59 ~3 ~7 torch 1  
fill ~59 ~3 ~13 ~66 ~3 ~13 glass 0  
fill ~59 ~3 ~19 ~66 ~3 ~19 glass 0 
setblock ~59 ~3 ~27 torch 1 
setblock ~59 ~3 ~30 torch 1 
setblock ~64 ~3 ~5 water 1 
setblock ~65 ~3 ~4 water 1 
setblock ~65 ~3 ~5 water 0 
setblock ~65 ~3 ~6 water 1 
setblock ~66 ~3 ~5 water 1  
fill ~4 ~4 ~13 ~11 ~4 ~13 glass 0  
fill ~4 ~4 ~19 ~11 ~4 ~19 glass 0  
fill ~11 ~4 ~12 ~12 ~4 ~12 snow 0  
fill ~11 ~4 ~20 ~12 ~4 ~20 snow 0  
fill ~12 ~4 ~24 ~13 ~4 ~24 snow 0  
fill ~12 ~4 ~27 ~13 ~4 ~27 snow 0 
fill ~12 ~4 ~30 ~13 ~4 ~30 snow 0  
fill ~12 ~4 ~33 ~13 ~4 ~33 snow 0  
fill ~12 ~4 ~34 ~17 ~4 ~34 snow 0  
fill ~13 ~4 ~5 ~19 ~4 ~5 glass 0  
fill ~18 ~4 ~33 ~19 ~4 ~33 glass 0  
fill ~18 ~4 ~34 ~19 ~4 ~34 stone_slab 0  
fill ~20 ~4 ~7 ~20 ~6 ~7 snow 0  
fill ~20 ~4 ~8 ~20 ~6 ~8 snow 0  
fill ~20 ~4 ~9 ~20 ~6 ~9 snow 0  
fill ~20 ~4 ~13 ~20 ~6 ~13 snow 0  
fill ~20 ~4 ~14 ~20 ~6 ~14 snow 0  
fill ~20 ~4 ~15 ~20 ~6 ~15 snow 0  
fill ~20 ~4 ~22 ~29 ~4 ~22 snow 0 
setblock ~20 ~4 ~35 torch 3  
fill ~21 ~4 ~33 ~22 ~4 ~33 glass 0  
fill ~21 ~4 ~34 ~22 ~4 ~34 stone_slab 0 
setblock ~23 ~4 ~35 torch 3  
fill ~24 ~4 ~33 ~25 ~4 ~33 glass 0  
fill ~24 ~4 ~34 ~25 ~4 ~34 stone_slab 0 
setblock ~26 ~4 ~8 leaves 8 
setblock ~26 ~4 ~14 leaves 8  
fill ~26 ~4 ~34 ~33 ~4 ~34 snow 0 
setblock ~27 ~4 ~3 leaves 8  
fill ~30 ~4 ~16 ~31 ~4 ~16 glass 0  
fill ~33 ~4 ~16 ~37 ~4 ~16 glass 0 
setblock ~33 ~4 ~33 snow 0  
fill ~34 ~4 ~20 ~34 ~10 ~20 fence 0  
fill ~34 ~4 ~33 ~36 ~4 ~33 glass 0  
fill ~37 ~4 ~33 ~37 ~4 ~34 snow 0  
fill ~38 ~4 ~34 ~44 ~4 ~34 snow 0  
fill ~39 ~4 ~16 ~40 ~4 ~16 glass 0  
fill ~41 ~4 ~22 ~50 ~4 ~22 snow 0 
setblock ~43 ~4 ~3 leaves 8 
setblock ~44 ~4 ~8 leaves 8 
setblock ~44 ~4 ~14 leaves 8  
fill ~45 ~4 ~33 ~46 ~4 ~33 glass 0  
fill ~45 ~4 ~34 ~46 ~4 ~34 stone_slab 0 
setblock ~47 ~4 ~35 torch 3  
fill ~48 ~4 ~33 ~49 ~4 ~33 glass 0  
fill ~48 ~4 ~34 ~49 ~4 ~34 stone_slab 0  
fill ~50 ~4 ~7 ~50 ~6 ~7 snow 0  
fill ~50 ~4 ~8 ~50 ~6 ~8 snow 0  
fill ~50 ~4 ~9 ~50 ~6 ~9 snow 0  
fill ~50 ~4 ~13 ~50 ~6 ~13 snow 0  
fill ~50 ~4 ~14 ~50 ~6 ~14 snow 0  
fill ~50 ~4 ~15 ~50 ~6 ~15 snow 0 
setblock ~50 ~4 ~35 torch 3  
fill ~51 ~4 ~5 ~57 ~4 ~5 glass 0  
fill ~51 ~4 ~33 ~52 ~4 ~33 glass 0  
fill ~51 ~4 ~34 ~52 ~4 ~34 stone_slab 0  
fill ~53 ~4 ~34 ~58 ~4 ~34 snow 0  
fill ~57 ~4 ~24 ~58 ~4 ~24 snow 0  
fill ~57 ~4 ~27 ~58 ~4 ~27 snow 0  
fill ~57 ~4 ~30 ~58 ~4 ~30 snow 0  
fill ~57 ~4 ~33 ~58 ~4 ~33 snow 0  
fill ~58 ~4 ~12 ~59 ~4 ~12 snow 0  
fill ~58 ~4 ~20 ~59 ~4 ~20 snow 0  
fill ~59 ~4 ~13 ~66 ~4 ~13 glass 0  
fill ~59 ~4 ~19 ~66 ~4 ~19 glass 0  
fill ~1 ~5 ~10 ~11 ~5 ~10 stone_slab 8  
fill ~1 ~5 ~11 ~1 ~5 ~22 stone_slab 8  
fill ~2 ~5 ~11 ~11 ~5 ~11 stone_slab 0  
fill ~2 ~5 ~12 ~11 ~5 ~12 stone_slab 0  
fill ~2 ~5 ~13 ~11 ~5 ~13 stone_slab 0  
fill ~2 ~5 ~14 ~11 ~5 ~14 stone_slab 0  
fill ~2 ~5 ~15 ~11 ~5 ~15 stone_slab 0  
fill ~2 ~5 ~16 ~11 ~5 ~16 stone_slab 0  
fill ~2 ~5 ~17 ~11 ~5 ~17 stone_slab 0  
fill ~2 ~5 ~18 ~11 ~5 ~18 stone_slab 0  
fill ~2 ~5 ~19 ~11 ~5 ~19 stone_slab 0  
fill ~2 ~5 ~20 ~11 ~5 ~20 stone_slab 0  
fill ~2 ~5 ~21 ~11 ~5 ~21 stone_slab 0  
fill ~2 ~5 ~22 ~11 ~5 ~22 stone_slab 8  
fill ~12 ~5 ~12 ~12 ~7 ~12 snow 0  
fill ~12 ~5 ~14 ~12 ~10 ~14 snow 0  
fill ~12 ~5 ~15 ~12 ~7 ~15 snow 0  
fill ~12 ~5 ~16 ~12 ~7 ~16 snow 0  
fill ~12 ~5 ~17 ~12 ~7 ~17 snow 0  
fill ~12 ~5 ~18 ~12 ~10 ~18 snow 0  
fill ~12 ~5 ~20 ~12 ~7 ~20 snow 0  
fill ~12 ~5 ~24 ~13 ~5 ~24 snow 0  
fill ~12 ~5 ~25 ~13 ~5 ~25 snow 0  
fill ~12 ~5 ~26 ~13 ~5 ~26 snow 0  
fill ~12 ~5 ~27 ~13 ~5 ~27 snow 0  
fill ~12 ~5 ~28 ~13 ~5 ~28 snow 0  
fill ~12 ~5 ~29 ~13 ~5 ~29 snow 0  
fill ~12 ~5 ~30 ~13 ~5 ~30 snow 0  
fill ~12 ~5 ~31 ~13 ~5 ~31 snow 0  
fill ~12 ~5 ~32 ~13 ~5 ~32 snow 0  
fill ~12 ~5 ~33 ~13 ~5 ~33 snow 0  
fill ~12 ~5 ~34 ~17 ~5 ~34 snow 0  
fill ~13 ~5 ~4 ~15 ~5 ~4 stone_slab 0  
fill ~13 ~5 ~5 ~19 ~5 ~5 glass 0  
fill ~17 ~5 ~4 ~19 ~5 ~4 stone_slab 0  
fill ~18 ~5 ~33 ~19 ~5 ~33 glass 0  
fill ~20 ~5 ~18 ~20 ~6 ~18 snow 0  
fill ~20 ~5 ~19 ~20 ~6 ~19 snow 0  
fill ~20 ~5 ~20 ~20 ~6 ~20 snow 0  
fill ~20 ~5 ~22 ~29 ~5 ~22 snow 0  
fill ~21 ~5 ~4 ~21 ~5 ~21 stone_slab 0  
fill ~21 ~5 ~33 ~22 ~5 ~33 glass 0  
fill ~22 ~5 ~5 ~25 ~5 ~5 stone_slab 0  
fill ~22 ~5 ~11 ~25 ~5 ~11 stone_slab 0  
fill ~22 ~5 ~17 ~25 ~5 ~17 stone_slab 0  
fill ~22 ~5 ~21 ~25 ~5 ~21 stone_slab 0  
fill ~24 ~5 ~33 ~25 ~5 ~33 glass 0  
fill ~25 ~5 ~6 ~25 ~5 ~21 stone_slab 0  
fill ~26 ~5 ~34 ~44 ~5 ~34 snow 0  
fill ~28 ~5 ~15 ~31 ~5 ~15 stone_slab 0  
fill ~28 ~5 ~16 ~28 ~5 ~21 stone_slab 0  
fill ~30 ~5 ~16 ~31 ~5 ~16 glass 0 
setblock ~32 ~5 ~14 stone_button 4 
setblock ~32 ~5 ~38 torch 4  
fill ~33 ~5 ~15 ~37 ~5 ~15 stone_slab 0  
fill ~33 ~5 ~16 ~37 ~5 ~16 glass 0  
fill ~34 ~5 ~33 ~36 ~5 ~33 snow 0 
setblock ~35 ~5 ~22 glowstone 0 
setblock ~38 ~5 ~14 stone_button 4 
setblock ~38 ~5 ~38 torch 4  
fill ~39 ~5 ~15 ~42 ~5 ~15 stone_slab 0  
fill ~39 ~5 ~16 ~40 ~5 ~16 glass 0  
fill ~41 ~5 ~22 ~50 ~5 ~22 snow 0  
fill ~42 ~5 ~16 ~42 ~5 ~21 stone_slab 0  
fill ~45 ~5 ~5 ~49 ~5 ~5 stone_slab 0  
fill ~45 ~5 ~6 ~45 ~5 ~21 stone_slab 0  
fill ~45 ~5 ~33 ~46 ~5 ~33 glass 0  
fill ~46 ~5 ~11 ~49 ~5 ~11 stone_slab 0  
fill ~46 ~5 ~17 ~49 ~5 ~17 stone_slab 0  
fill ~46 ~5 ~21 ~49 ~5 ~21 stone_slab 0  
fill ~48 ~5 ~33 ~49 ~5 ~33 glass 0 
setblock ~49 ~5 ~4 stone_slab 0  
fill ~49 ~5 ~6 ~49 ~5 ~21 stone_slab 0  
fill ~50 ~5 ~18 ~50 ~6 ~18 snow 0  
fill ~50 ~5 ~19 ~50 ~6 ~19 snow 0  
fill ~50 ~5 ~20 ~50 ~6 ~20 snow 0  
fill ~51 ~5 ~4 ~53 ~5 ~4 stone_slab 0  
fill ~51 ~5 ~5 ~57 ~5 ~5 glass 0  
fill ~51 ~5 ~33 ~52 ~5 ~33 glass 0  
fill ~53 ~5 ~34 ~58 ~5 ~34 snow 0  
fill ~55 ~5 ~4 ~57 ~5 ~4 stone_slab 0  
fill ~57 ~5 ~24 ~58 ~5 ~24 snow 0  
fill ~57 ~5 ~25 ~58 ~5 ~25 snow 0  
fill ~57 ~5 ~26 ~58 ~5 ~26 snow 0  
fill ~57 ~5 ~27 ~58 ~5 ~27 snow 0  
fill ~57 ~5 ~28 ~58 ~5 ~28 snow 0  
fill ~57 ~5 ~29 ~58 ~5 ~29 snow 0  
fill ~57 ~5 ~30 ~58 ~5 ~30 snow 0  
fill ~57 ~5 ~31 ~58 ~5 ~31 snow 0  
fill ~57 ~5 ~32 ~58 ~5 ~32 snow 0  
fill ~57 ~5 ~33 ~58 ~5 ~33 snow 0  
fill ~58 ~5 ~12 ~58 ~7 ~12 snow 0  
fill ~58 ~5 ~14 ~58 ~10 ~14 snow 0  
fill ~58 ~5 ~15 ~58 ~7 ~15 snow 0  
fill ~58 ~5 ~16 ~58 ~7 ~16 snow 0  
fill ~58 ~5 ~17 ~58 ~7 ~17 snow 0  
fill ~58 ~5 ~18 ~58 ~10 ~18 snow 0  
fill ~58 ~5 ~20 ~58 ~7 ~20 snow 0  
fill ~59 ~5 ~10 ~69 ~5 ~10 stone_slab 8  
fill ~59 ~5 ~11 ~68 ~5 ~11 stone_slab 0  
fill ~59 ~5 ~12 ~68 ~5 ~12 stone_slab 0  
fill ~59 ~5 ~13 ~68 ~5 ~13 stone_slab 0  
fill ~59 ~5 ~14 ~68 ~5 ~14 stone_slab 0  
fill ~59 ~5 ~15 ~68 ~5 ~15 stone_slab 0  
fill ~59 ~5 ~16 ~68 ~5 ~16 stone_slab 0  
fill ~59 ~5 ~17 ~68 ~5 ~17 stone_slab 0  
fill ~59 ~5 ~18 ~68 ~5 ~18 stone_slab 0  
fill ~59 ~5 ~19 ~68 ~5 ~19 stone_slab 0  
fill ~59 ~5 ~20 ~68 ~5 ~20 stone_slab 0  
fill ~59 ~5 ~21 ~68 ~5 ~21 stone_slab 0  
fill ~59 ~5 ~22 ~69 ~5 ~22 stone_slab 8  
fill ~69 ~5 ~11 ~69 ~5 ~22 stone_slab 8 
setblock ~12 ~6 ~3 stone_button 4  
fill ~12 ~6 ~24 ~13 ~6 ~24 snow 0  
fill ~12 ~6 ~25 ~13 ~6 ~25 snow 0  
fill ~12 ~6 ~26 ~13 ~6 ~26 snow 0  
fill ~12 ~6 ~27 ~13 ~6 ~27 snow 0  
fill ~12 ~6 ~28 ~13 ~6 ~28 snow 0  
fill ~12 ~6 ~29 ~13 ~6 ~29 snow 0  
fill ~12 ~6 ~30 ~13 ~6 ~30 snow 0  
fill ~12 ~6 ~31 ~13 ~6 ~31 snow 0  
fill ~12 ~6 ~32 ~13 ~6 ~32 snow 0  
fill ~12 ~6 ~33 ~13 ~6 ~33 snow 0  
fill ~12 ~6 ~34 ~17 ~6 ~34 snow 0  
fill ~13 ~6 ~5 ~19 ~6 ~5 glass 0 
setblock ~16 ~6 ~3 stone_button 4  
fill ~18 ~6 ~33 ~19 ~6 ~33 glass 0  
fill ~19 ~6 ~24 ~28 ~6 ~24 planks 2  
fill ~19 ~6 ~25 ~28 ~6 ~25 planks 2  
fill ~19 ~6 ~26 ~28 ~6 ~26 planks 2  
fill ~19 ~6 ~27 ~28 ~6 ~27 planks 2  
fill ~19 ~6 ~28 ~28 ~6 ~28 planks 2  
fill ~19 ~6 ~29 ~28 ~6 ~29 planks 2  
fill ~19 ~6 ~30 ~28 ~6 ~30 planks 2  
fill ~19 ~6 ~31 ~28 ~6 ~31 planks 2  
fill ~19 ~6 ~32 ~34 ~6 ~32 planks 2 
setblock ~20 ~6 ~3 stone_button 4  
fill ~20 ~6 ~22 ~29 ~6 ~22 snow 0 
setblock ~21 ~6 ~5 torch 1 
setblock ~21 ~6 ~11 torch 1 
setblock ~21 ~6 ~17 torch 1  
fill ~21 ~6 ~33 ~22 ~6 ~33 glass 0  
fill ~24 ~6 ~33 ~25 ~6 ~33 glass 0  
fill ~26 ~6 ~34 ~34 ~6 ~34 snow 0  
fill ~27 ~6 ~33 ~43 ~6 ~33 planks 2  
fill ~29 ~6 ~24 ~29 ~10 ~24 snow 0  
fill ~29 ~6 ~25 ~29 ~7 ~25 snow 0  
fill ~29 ~6 ~26 ~29 ~6 ~31 snow 0  
fill ~30 ~6 ~16 ~31 ~6 ~16 glass 0  
fill ~30 ~6 ~31 ~41 ~6 ~31 snow 0  
fill ~33 ~6 ~16 ~37 ~6 ~16 glass 0  
fill ~33 ~6 ~35 ~37 ~6 ~35 snow 0  
fill ~33 ~6 ~36 ~37 ~6 ~36 snow 0  
fill ~33 ~6 ~37 ~37 ~6 ~37 snow 0  
fill ~33 ~6 ~38 ~37 ~6 ~38 snow 0  
fill ~35 ~6 ~22 ~35 ~10 ~22 fence 0 
setblock ~35 ~6 ~32 glowstone 0 
setblock ~35 ~6 ~34 planks 2 
setblock ~36 ~6 ~21 glowstone 0  
fill ~36 ~6 ~32 ~41 ~6 ~32 planks 2  
fill ~36 ~6 ~34 ~44 ~6 ~34 snow 0  
fill ~39 ~6 ~16 ~40 ~6 ~16 glass 0  
fill ~41 ~6 ~22 ~50 ~6 ~22 snow 0  
fill ~41 ~6 ~24 ~41 ~10 ~24 snow 0  
fill ~41 ~6 ~25 ~41 ~7 ~25 snow 0  
fill ~41 ~6 ~26 ~41 ~6 ~31 snow 0  
fill ~42 ~6 ~24 ~51 ~6 ~24 planks 2 
setblock ~42 ~6 ~25 glowstone 0  
fill ~42 ~6 ~26 ~51 ~6 ~26 planks 2  
fill ~42 ~6 ~27 ~51 ~6 ~27 planks 2  
fill ~42 ~6 ~28 ~51 ~6 ~28 planks 2  
fill ~42 ~6 ~29 ~51 ~6 ~29 planks 2  
fill ~42 ~6 ~30 ~51 ~6 ~30 planks 2  
fill ~42 ~6 ~31 ~51 ~6 ~31 planks 2 
setblock ~42 ~6 ~32 glowstone 0  
fill ~43 ~6 ~25 ~51 ~6 ~25 planks 2  
fill ~43 ~6 ~32 ~51 ~6 ~32 planks 2  
fill ~45 ~6 ~33 ~46 ~6 ~33 glass 0  
fill ~48 ~6 ~33 ~49 ~6 ~33 glass 0 
setblock ~49 ~6 ~5 torch 2 
setblock ~49 ~6 ~11 torch 2 
setblock ~49 ~6 ~17 torch 2 
setblock ~50 ~6 ~3 stone_button 4  
fill ~51 ~6 ~5 ~57 ~6 ~5 glass 0  
fill ~51 ~6 ~33 ~52 ~6 ~33 glass 0  
fill ~53 ~6 ~34 ~58 ~6 ~34 snow 0 
setblock ~54 ~6 ~3 stone_button 4  
fill ~57 ~6 ~24 ~58 ~6 ~24 snow 0  
fill ~57 ~6 ~25 ~58 ~6 ~25 snow 0  
fill ~57 ~6 ~26 ~58 ~6 ~26 snow 0  
fill ~57 ~6 ~27 ~58 ~6 ~27 snow 0  
fill ~57 ~6 ~28 ~58 ~6 ~28 snow 0  
fill ~57 ~6 ~29 ~58 ~6 ~29 snow 0  
fill ~57 ~6 ~30 ~58 ~6 ~30 snow 0  
fill ~57 ~6 ~31 ~58 ~6 ~31 snow 0  
fill ~57 ~6 ~32 ~58 ~6 ~32 snow 0  
fill ~57 ~6 ~33 ~58 ~6 ~33 snow 0 
setblock ~58 ~6 ~3 stone_button 4  
fill ~9 ~7 ~1 ~23 ~7 ~1 stone_slab 8  
fill ~9 ~7 ~2 ~23 ~7 ~2 stone_slab 8  
fill ~9 ~7 ~3 ~10 ~7 ~3 stone_slab 8  
fill ~9 ~7 ~4 ~10 ~7 ~4 stone_slab 8  
fill ~9 ~7 ~5 ~10 ~7 ~5 stone_slab 8  
fill ~9 ~7 ~6 ~10 ~7 ~6 stone_slab 8  
fill ~9 ~7 ~7 ~10 ~7 ~7 stone_slab 8  
fill ~9 ~7 ~8 ~10 ~7 ~8 stone_slab 8  
fill ~9 ~7 ~9 ~10 ~7 ~9 stone_slab 8  
fill ~9 ~7 ~10 ~10 ~7 ~10 stone_slab 8  
fill ~9 ~7 ~11 ~10 ~7 ~11 stone_slab 8  
fill ~9 ~7 ~12 ~10 ~7 ~12 stone_slab 8  
fill ~9 ~7 ~13 ~10 ~7 ~13 stone_slab 8  
fill ~9 ~7 ~14 ~10 ~7 ~14 stone_slab 8  
fill ~9 ~7 ~15 ~10 ~7 ~15 stone_slab 8  
fill ~9 ~7 ~16 ~10 ~7 ~16 stone_slab 8  
fill ~9 ~7 ~17 ~10 ~7 ~17 stone_slab 8  
fill ~9 ~7 ~18 ~10 ~7 ~18 stone_slab 8  
fill ~9 ~7 ~19 ~10 ~7 ~19 stone_slab 8  
fill ~9 ~7 ~20 ~10 ~7 ~20 stone_slab 8  
fill ~9 ~7 ~21 ~10 ~7 ~21 stone_slab 8  
fill ~9 ~7 ~22 ~10 ~7 ~22 stone_slab 8  
fill ~9 ~7 ~23 ~10 ~7 ~23 stone_slab 8  
fill ~9 ~7 ~24 ~10 ~7 ~24 stone_slab 8  
fill ~9 ~7 ~25 ~10 ~7 ~25 stone_slab 8  
fill ~9 ~7 ~26 ~10 ~7 ~26 stone_slab 8  
fill ~9 ~7 ~27 ~10 ~7 ~27 stone_slab 8  
fill ~9 ~7 ~28 ~10 ~7 ~28 stone_slab 8  
fill ~9 ~7 ~29 ~10 ~7 ~29 stone_slab 8  
fill ~9 ~7 ~30 ~10 ~7 ~30 stone_slab 8  
fill ~9 ~7 ~31 ~10 ~7 ~31 stone_slab 8  
fill ~9 ~7 ~32 ~10 ~7 ~32 stone_slab 8  
fill ~9 ~7 ~33 ~10 ~7 ~33 stone_slab 8  
fill ~9 ~7 ~34 ~10 ~7 ~34 stone_slab 8  
fill ~9 ~7 ~35 ~10 ~7 ~35 stone_slab 8  
fill ~9 ~7 ~36 ~31 ~7 ~36 stone_slab 8  
fill ~9 ~7 ~37 ~31 ~7 ~37 stone_slab 8  
fill ~11 ~7 ~3 ~21 ~7 ~3 stone_slab 0  
fill ~11 ~7 ~4 ~21 ~7 ~4 stone_slab 0  
fill ~11 ~7 ~5 ~12 ~7 ~5 stone_slab 0  
fill ~11 ~7 ~6 ~13 ~7 ~6 stone_slab 0  
fill ~11 ~7 ~7 ~13 ~7 ~7 stone_slab 0  
fill ~11 ~7 ~8 ~12 ~7 ~8 stone_slab 0  
fill ~11 ~7 ~9 ~11 ~7 ~13 stone_slab 0 
setblock ~11 ~7 ~14 glowstone 0  
fill ~11 ~7 ~15 ~11 ~7 ~17 stone_slab 0 
setblock ~11 ~7 ~18 glowstone 0  
fill ~11 ~7 ~19 ~11 ~7 ~35 stone_slab 0  
fill ~12 ~7 ~24 ~12 ~0 ~24 snow 0  
fill ~12 ~7 ~25 ~12 ~5 ~25 snow 0  
fill ~12 ~7 ~26 ~12 ~10 ~26 snow 0  
fill ~12 ~7 ~27 ~12 ~0 ~27 snow 0  
fill ~12 ~7 ~28 ~12 ~5 ~28 snow 0  
fill ~12 ~7 ~29 ~12 ~5 ~29 snow 0  
fill ~12 ~7 ~30 ~12 ~10 ~30 snow 0  
fill ~12 ~7 ~31 ~12 ~5 ~31 snow 0  
fill ~12 ~7 ~32 ~12 ~5 ~32 snow 0  
fill ~12 ~7 ~33 ~12 ~0 ~33 snow 0  
fill ~12 ~7 ~34 ~33 ~7 ~34 snow 0  
fill ~12 ~7 ~35 ~31 ~7 ~35 stone_slab 0 
setblock ~13 ~7 ~5 glowstone 0 
setblock ~13 ~7 ~8 glowstone 0  
fill ~13 ~7 ~9 ~13 ~10 ~9 snow 0  
fill ~13 ~7 ~10 ~17 ~7 ~10 planks 2  
fill ~13 ~7 ~11 ~17 ~7 ~11 planks 2  
fill ~13 ~7 ~12 ~17 ~7 ~12 planks 2  
fill ~13 ~7 ~13 ~17 ~7 ~13 planks 2  
fill ~13 ~7 ~14 ~17 ~7 ~14 planks 2  
fill ~13 ~7 ~15 ~17 ~7 ~15 planks 2  
fill ~13 ~7 ~16 ~17 ~7 ~16 planks 2  
fill ~13 ~7 ~17 ~17 ~7 ~17 planks 2  
fill ~13 ~7 ~18 ~17 ~7 ~18 planks 2  
fill ~13 ~7 ~19 ~17 ~7 ~19 planks 2  
fill ~13 ~7 ~20 ~17 ~7 ~20 planks 2  
fill ~13 ~7 ~21 ~17 ~7 ~21 planks 2  
fill ~13 ~7 ~22 ~17 ~7 ~22 planks 2  
fill ~13 ~7 ~23 ~17 ~7 ~23 planks 2  
fill ~13 ~7 ~24 ~17 ~7 ~24 planks 2  
fill ~13 ~7 ~25 ~18 ~7 ~25 planks 2  
fill ~13 ~7 ~26 ~18 ~7 ~26 planks 2  
fill ~13 ~7 ~27 ~18 ~7 ~27 planks 2  
fill ~13 ~7 ~28 ~18 ~7 ~28 planks 2  
fill ~13 ~7 ~29 ~18 ~7 ~29 planks 2  
fill ~13 ~7 ~30 ~18 ~7 ~30 planks 2  
fill ~13 ~7 ~31 ~18 ~7 ~31 planks 2  
fill ~13 ~7 ~32 ~18 ~7 ~32 planks 2  
fill ~13 ~7 ~33 ~18 ~7 ~33 planks 2  
fill ~14 ~7 ~5 ~18 ~7 ~5 stone_slab 0  
fill ~14 ~7 ~6 ~14 ~10 ~6 snow 0  
fill ~14 ~7 ~7 ~14 ~10 ~7 snow 0  
fill ~14 ~7 ~8 ~14 ~10 ~8 snow 0  
fill ~14 ~7 ~9 ~17 ~7 ~9 planks 2 
setblock ~15 ~7 ~6 stone_slab 0  
fill ~15 ~7 ~7 ~15 ~10 ~7 glass 0  
fill ~15 ~7 ~8 ~17 ~7 ~8 planks 2  
fill ~16 ~7 ~6 ~16 ~10 ~6 snow 0 
setblock ~16 ~7 ~7 stone_slab 0 
setblock ~17 ~7 ~6 stone_slab 0  
fill ~17 ~7 ~7 ~17 ~10 ~7 glass 0  
fill ~18 ~7 ~6 ~18 ~10 ~6 snow 0  
fill ~18 ~7 ~7 ~18 ~10 ~7 snow 0  
fill ~18 ~7 ~8 ~18 ~7 ~24 snow 0 
setblock ~19 ~7 ~5 glowstone 0  
fill ~19 ~7 ~6 ~21 ~7 ~6 stone_slab 0  
fill ~19 ~7 ~7 ~21 ~7 ~7 stone_slab 0  
fill ~19 ~7 ~8 ~21 ~7 ~8 stone_slab 0  
fill ~19 ~7 ~9 ~21 ~7 ~9 stone_slab 0  
fill ~19 ~7 ~10 ~21 ~7 ~10 stone_slab 0  
fill ~19 ~7 ~11 ~21 ~7 ~11 stone_slab 0 
setblock ~19 ~7 ~12 glowstone 0  
fill ~19 ~7 ~13 ~21 ~7 ~13 stone_slab 0  
fill ~19 ~7 ~14 ~21 ~7 ~14 stone_slab 0  
fill ~19 ~7 ~15 ~21 ~7 ~15 stone_slab 0  
fill ~19 ~7 ~16 ~21 ~7 ~16 stone_slab 0  
fill ~19 ~7 ~17 ~21 ~7 ~17 stone_slab 0  
fill ~19 ~7 ~18 ~21 ~7 ~18 stone_slab 0  
fill ~19 ~7 ~19 ~21 ~7 ~19 stone_slab 0  
fill ~19 ~7 ~20 ~21 ~7 ~20 stone_slab 0  
fill ~19 ~7 ~21 ~28 ~7 ~21 stone_slab 0  
fill ~19 ~7 ~22 ~28 ~7 ~22 stone_slab 0 
setblock ~19 ~7 ~23 glowstone 0  
fill ~19 ~7 ~24 ~29 ~7 ~24 snow 0  
fill ~20 ~7 ~5 ~21 ~7 ~5 stone_slab 0  
fill ~20 ~7 ~12 ~21 ~7 ~12 stone_slab 0  
fill ~20 ~7 ~23 ~27 ~7 ~23 stone_slab 0  
fill ~22 ~7 ~3 ~23 ~7 ~3 stone_slab 8  
fill ~22 ~7 ~4 ~23 ~7 ~4 stone_slab 8  
fill ~22 ~7 ~5 ~23 ~7 ~5 stone_slab 8  
fill ~22 ~7 ~6 ~23 ~7 ~6 stone_slab 8  
fill ~22 ~7 ~7 ~23 ~7 ~7 stone_slab 8  
fill ~22 ~7 ~8 ~23 ~7 ~8 stone_slab 8  
fill ~22 ~7 ~9 ~23 ~7 ~9 stone_slab 8  
fill ~22 ~7 ~10 ~23 ~7 ~10 stone_slab 8  
fill ~22 ~7 ~11 ~23 ~7 ~11 stone_slab 8  
fill ~22 ~7 ~12 ~23 ~7 ~12 stone_slab 8  
fill ~22 ~7 ~13 ~23 ~7 ~13 stone_slab 8  
fill ~22 ~7 ~14 ~23 ~7 ~14 stone_slab 8  
fill ~22 ~7 ~15 ~23 ~7 ~15 stone_slab 8  
fill ~22 ~7 ~16 ~23 ~7 ~16 stone_slab 8  
fill ~22 ~7 ~17 ~23 ~7 ~17 stone_slab 8  
fill ~22 ~7 ~18 ~23 ~7 ~18 stone_slab 8  
fill ~22 ~7 ~19 ~28 ~7 ~19 stone_slab 8  
fill ~22 ~7 ~20 ~28 ~7 ~20 stone_slab 8 
setblock ~28 ~7 ~23 glowstone 0  
fill ~29 ~7 ~22 ~29 ~10 ~22 glass 0  
fill ~29 ~7 ~26 ~29 ~7 ~30 glass_pane 0 
setblock ~29 ~7 ~31 snow 0  
fill ~30 ~7 ~16 ~31 ~7 ~16 glass 0  
fill ~30 ~7 ~31 ~33 ~7 ~31 glass_pane 0  
fill ~32 ~7 ~35 ~32 ~7 ~39 snow 0  
fill ~33 ~7 ~16 ~37 ~7 ~16 glass 0  
fill ~33 ~7 ~39 ~38 ~7 ~39 snow 0  
fill ~34 ~7 ~31 ~36 ~7 ~31 snow 0  
fill ~34 ~7 ~34 ~34 ~9 ~34 double_stone_slab 0 
setblock ~35 ~7 ~34 wooden_door 3  
fill ~36 ~7 ~21 ~36 ~10 ~21 fence 0  
fill ~36 ~7 ~34 ~36 ~9 ~34 double_stone_slab 0  
fill ~37 ~7 ~31 ~40 ~7 ~31 glass_pane 0  
fill ~37 ~7 ~34 ~58 ~7 ~34 snow 0  
fill ~38 ~7 ~35 ~38 ~7 ~39 snow 0  
fill ~39 ~7 ~16 ~40 ~7 ~16 glass 0  
fill ~39 ~7 ~35 ~59 ~7 ~35 stone_slab 0  
fill ~39 ~7 ~36 ~61 ~7 ~36 stone_slab 8  
fill ~39 ~7 ~37 ~61 ~7 ~37 stone_slab 8  
fill ~41 ~7 ~22 ~41 ~10 ~22 glass 0  
fill ~41 ~7 ~26 ~41 ~7 ~30 glass_pane 0 
setblock ~41 ~7 ~31 snow 0  
fill ~42 ~7 ~19 ~48 ~7 ~19 stone_slab 8  
fill ~42 ~7 ~20 ~48 ~7 ~20 stone_slab 8  
fill ~42 ~7 ~21 ~51 ~7 ~21 stone_slab 0  
fill ~42 ~7 ~22 ~51 ~7 ~22 stone_slab 0 
setblock ~42 ~7 ~23 glowstone 0  
fill ~42 ~7 ~24 ~52 ~7 ~24 snow 0  
fill ~43 ~7 ~23 ~50 ~7 ~23 stone_slab 0  
fill ~47 ~7 ~1 ~61 ~7 ~1 stone_slab 8  
fill ~47 ~7 ~2 ~61 ~7 ~2 stone_slab 8  
fill ~47 ~7 ~3 ~48 ~7 ~3 stone_slab 8  
fill ~47 ~7 ~4 ~48 ~7 ~4 stone_slab 8  
fill ~47 ~7 ~5 ~48 ~7 ~5 stone_slab 8  
fill ~47 ~7 ~6 ~48 ~7 ~6 stone_slab 8  
fill ~47 ~7 ~7 ~48 ~7 ~7 stone_slab 8  
fill ~47 ~7 ~8 ~48 ~7 ~8 stone_slab 8  
fill ~47 ~7 ~9 ~48 ~7 ~9 stone_slab 8  
fill ~47 ~7 ~10 ~48 ~7 ~10 stone_slab 8  
fill ~47 ~7 ~11 ~48 ~7 ~11 stone_slab 8  
fill ~47 ~7 ~12 ~48 ~7 ~12 stone_slab 8  
fill ~47 ~7 ~13 ~48 ~7 ~13 stone_slab 8  
fill ~47 ~7 ~14 ~48 ~7 ~14 stone_slab 8  
fill ~47 ~7 ~15 ~48 ~7 ~15 stone_slab 8  
fill ~47 ~7 ~16 ~48 ~7 ~16 stone_slab 8  
fill ~47 ~7 ~17 ~48 ~7 ~17 stone_slab 8  
fill ~47 ~7 ~18 ~48 ~7 ~18 stone_slab 8  
fill ~49 ~7 ~3 ~59 ~7 ~3 stone_slab 0  
fill ~49 ~7 ~4 ~59 ~7 ~4 stone_slab 0  
fill ~49 ~7 ~5 ~50 ~7 ~5 stone_slab 0  
fill ~49 ~7 ~6 ~51 ~7 ~6 stone_slab 0  
fill ~49 ~7 ~7 ~51 ~7 ~7 stone_slab 0  
fill ~49 ~7 ~8 ~51 ~7 ~8 stone_slab 0  
fill ~49 ~7 ~9 ~51 ~7 ~9 stone_slab 0  
fill ~49 ~7 ~10 ~51 ~7 ~10 stone_slab 0  
fill ~49 ~7 ~11 ~51 ~7 ~11 stone_slab 0  
fill ~49 ~7 ~12 ~50 ~7 ~12 stone_slab 0  
fill ~49 ~7 ~13 ~51 ~7 ~13 stone_slab 0  
fill ~49 ~7 ~14 ~51 ~7 ~14 stone_slab 0  
fill ~49 ~7 ~15 ~51 ~7 ~15 stone_slab 0  
fill ~49 ~7 ~16 ~51 ~7 ~16 stone_slab 0  
fill ~49 ~7 ~17 ~51 ~7 ~17 stone_slab 0  
fill ~49 ~7 ~18 ~51 ~7 ~18 stone_slab 0  
fill ~49 ~7 ~19 ~51 ~7 ~19 stone_slab 0  
fill ~49 ~7 ~20 ~51 ~7 ~20 stone_slab 0 
setblock ~51 ~7 ~5 glowstone 0 
setblock ~51 ~7 ~12 glowstone 0 
setblock ~51 ~7 ~23 glowstone 0  
fill ~52 ~7 ~5 ~56 ~7 ~5 stone_slab 0  
fill ~52 ~7 ~6 ~52 ~10 ~6 snow 0  
fill ~52 ~7 ~7 ~52 ~10 ~7 snow 0  
fill ~52 ~7 ~8 ~52 ~7 ~24 snow 0  
fill ~52 ~7 ~25 ~57 ~7 ~25 planks 2  
fill ~52 ~7 ~26 ~57 ~7 ~26 planks 2  
fill ~52 ~7 ~27 ~57 ~7 ~27 planks 2  
fill ~52 ~7 ~28 ~57 ~7 ~28 planks 2  
fill ~52 ~7 ~29 ~57 ~7 ~29 planks 2  
fill ~52 ~7 ~30 ~57 ~7 ~30 planks 2  
fill ~52 ~7 ~31 ~57 ~7 ~31 planks 2  
fill ~52 ~7 ~32 ~57 ~7 ~32 planks 2  
fill ~52 ~7 ~33 ~57 ~7 ~33 planks 2 
setblock ~53 ~7 ~6 stone_slab 0  
fill ~53 ~7 ~7 ~53 ~10 ~7 glass 0  
fill ~53 ~7 ~8 ~55 ~7 ~8 planks 2  
fill ~53 ~7 ~9 ~56 ~7 ~9 planks 2  
fill ~53 ~7 ~10 ~57 ~7 ~10 planks 2  
fill ~53 ~7 ~11 ~57 ~7 ~11 planks 2  
fill ~53 ~7 ~12 ~57 ~7 ~12 planks 2  
fill ~53 ~7 ~13 ~57 ~7 ~13 planks 2  
fill ~53 ~7 ~14 ~57 ~7 ~14 planks 2  
fill ~53 ~7 ~15 ~57 ~7 ~15 planks 2  
fill ~53 ~7 ~16 ~57 ~7 ~16 planks 2  
fill ~53 ~7 ~17 ~57 ~7 ~17 planks 2  
fill ~53 ~7 ~18 ~57 ~7 ~18 planks 2  
fill ~53 ~7 ~19 ~57 ~7 ~19 planks 2  
fill ~53 ~7 ~20 ~57 ~7 ~20 planks 2  
fill ~53 ~7 ~21 ~57 ~7 ~21 planks 2  
fill ~53 ~7 ~22 ~57 ~7 ~22 planks 2  
fill ~53 ~7 ~23 ~57 ~7 ~23 planks 2  
fill ~53 ~7 ~24 ~57 ~7 ~24 planks 2  
fill ~54 ~7 ~6 ~54 ~10 ~6 snow 0 
setblock ~54 ~7 ~7 stone_slab 0 
setblock ~55 ~7 ~6 stone_slab 0  
fill ~55 ~7 ~7 ~55 ~10 ~7 glass 0  
fill ~56 ~7 ~6 ~56 ~10 ~6 snow 0  
fill ~56 ~7 ~7 ~56 ~10 ~7 snow 0  
fill ~56 ~7 ~8 ~56 ~10 ~8 snow 0 
setblock ~57 ~7 ~5 glowstone 0  
fill ~57 ~7 ~6 ~59 ~7 ~6 stone_slab 0  
fill ~57 ~7 ~7 ~59 ~7 ~7 stone_slab 0 
setblock ~57 ~7 ~8 glowstone 0  
fill ~57 ~7 ~9 ~57 ~10 ~9 snow 0  
fill ~58 ~7 ~5 ~59 ~7 ~5 stone_slab 0  
fill ~58 ~7 ~8 ~59 ~7 ~8 stone_slab 0  
fill ~58 ~7 ~24 ~58 ~7 ~34 snow 0  
fill ~59 ~7 ~9 ~59 ~7 ~13 stone_slab 0 
setblock ~59 ~7 ~14 glowstone 0  
fill ~59 ~7 ~15 ~59 ~7 ~17 stone_slab 0 
setblock ~59 ~7 ~18 glowstone 0  
fill ~59 ~7 ~19 ~59 ~7 ~35 stone_slab 0  
fill ~60 ~7 ~3 ~61 ~7 ~3 stone_slab 8  
fill ~60 ~7 ~4 ~61 ~7 ~4 stone_slab 8  
fill ~60 ~7 ~5 ~61 ~7 ~5 stone_slab 8  
fill ~60 ~7 ~6 ~61 ~7 ~6 stone_slab 8  
fill ~60 ~7 ~7 ~61 ~7 ~7 stone_slab 8  
fill ~60 ~7 ~8 ~61 ~7 ~8 stone_slab 8  
fill ~60 ~7 ~9 ~61 ~7 ~9 stone_slab 8  
fill ~60 ~7 ~10 ~61 ~7 ~10 stone_slab 8  
fill ~60 ~7 ~11 ~61 ~7 ~11 stone_slab 8  
fill ~60 ~7 ~12 ~61 ~7 ~12 stone_slab 8  
fill ~60 ~7 ~13 ~61 ~7 ~13 stone_slab 8  
fill ~60 ~7 ~14 ~61 ~7 ~14 stone_slab 8  
fill ~60 ~7 ~15 ~61 ~7 ~15 stone_slab 8  
fill ~60 ~7 ~16 ~61 ~7 ~16 stone_slab 8  
fill ~60 ~7 ~17 ~61 ~7 ~17 stone_slab 8  
fill ~60 ~7 ~18 ~61 ~7 ~18 stone_slab 8  
fill ~60 ~7 ~19 ~61 ~7 ~19 stone_slab 8  
fill ~60 ~7 ~20 ~61 ~7 ~20 stone_slab 8  
fill ~60 ~7 ~21 ~61 ~7 ~21 stone_slab 8  
fill ~60 ~7 ~22 ~61 ~7 ~22 stone_slab 8  
fill ~60 ~7 ~23 ~61 ~7 ~23 stone_slab 8  
fill ~60 ~7 ~24 ~61 ~7 ~24 stone_slab 8  
fill ~60 ~7 ~25 ~61 ~7 ~25 stone_slab 8  
fill ~60 ~7 ~26 ~61 ~7 ~26 stone_slab 8  
fill ~60 ~7 ~27 ~61 ~7 ~27 stone_slab 8  
fill ~60 ~7 ~28 ~61 ~7 ~28 stone_slab 8  
fill ~60 ~7 ~29 ~61 ~7 ~29 stone_slab 8  
fill ~60 ~7 ~30 ~61 ~7 ~30 stone_slab 8  
fill ~60 ~7 ~31 ~61 ~7 ~31 stone_slab 8  
fill ~60 ~7 ~32 ~61 ~7 ~32 stone_slab 8  
fill ~60 ~7 ~33 ~61 ~7 ~33 stone_slab 8  
fill ~60 ~7 ~34 ~61 ~7 ~34 stone_slab 8  
fill ~60 ~7 ~35 ~61 ~7 ~35 stone_slab 8  
fill ~12 ~8 ~11 ~12 ~9 ~11 glass 0  
fill ~12 ~8 ~12 ~12 ~9 ~12 glass 0  
fill ~12 ~8 ~13 ~12 ~9 ~13 glass 0  
fill ~12 ~8 ~15 ~12 ~9 ~15 glass 0  
fill ~12 ~8 ~16 ~12 ~9 ~16 glass 0  
fill ~12 ~8 ~17 ~12 ~9 ~17 glass 0  
fill ~12 ~8 ~19 ~12 ~9 ~19 glass 0  
fill ~12 ~8 ~20 ~12 ~9 ~20 glass 0  
fill ~12 ~8 ~21 ~12 ~9 ~21 glass 0  
fill ~12 ~8 ~23 ~12 ~9 ~23 glass 0  
fill ~12 ~8 ~24 ~12 ~9 ~24 glass 0  
fill ~12 ~8 ~25 ~12 ~9 ~25 glass 0  
fill ~12 ~8 ~27 ~12 ~9 ~27 glass 0  
fill ~12 ~8 ~28 ~12 ~9 ~28 glass 0  
fill ~12 ~8 ~29 ~12 ~9 ~29 glass 0  
fill ~12 ~8 ~31 ~12 ~9 ~31 glass 0  
fill ~12 ~8 ~32 ~12 ~9 ~32 glass 0  
fill ~12 ~8 ~33 ~12 ~9 ~33 glass 0  
fill ~12 ~8 ~34 ~12 ~10 ~34 snow 0  
fill ~13 ~8 ~34 ~15 ~8 ~34 glass 0  
fill ~16 ~8 ~34 ~24 ~8 ~34 snow 0  
fill ~18 ~8 ~8 ~18 ~9 ~8 glass 0  
fill ~18 ~8 ~9 ~18 ~9 ~9 glass 0  
fill ~18 ~8 ~10 ~18 ~9 ~10 glass 0  
fill ~18 ~8 ~11 ~18 ~10 ~11 snow 0  
fill ~18 ~8 ~12 ~18 ~10 ~12 snow 0  
fill ~18 ~8 ~13 ~18 ~9 ~13 glass 0  
fill ~18 ~8 ~14 ~18 ~9 ~14 glass 0  
fill ~18 ~8 ~15 ~18 ~9 ~15 glass 0  
fill ~18 ~8 ~16 ~18 ~9 ~16 glass 0  
fill ~18 ~8 ~17 ~18 ~10 ~17 snow 0  
fill ~18 ~8 ~18 ~18 ~10 ~18 snow 0  
fill ~18 ~8 ~19 ~18 ~9 ~19 glass 0  
fill ~18 ~8 ~20 ~18 ~9 ~20 glass 0  
fill ~18 ~8 ~21 ~18 ~9 ~21 glass 0  
fill ~18 ~8 ~22 ~18 ~10 ~22 snow 0  
fill ~18 ~8 ~23 ~18 ~10 ~23 snow 0  
fill ~18 ~8 ~24 ~20 ~8 ~24 snow 0  
fill ~21 ~8 ~24 ~22 ~8 ~24 glass 0  
fill ~23 ~8 ~24 ~24 ~8 ~24 snow 0  
fill ~25 ~8 ~24 ~26 ~8 ~24 glass 0  
fill ~25 ~8 ~34 ~25 ~9 ~34 glass 0  
fill ~26 ~8 ~34 ~26 ~10 ~34 snow 0  
fill ~27 ~8 ~24 ~29 ~8 ~24 snow 0  
fill ~27 ~8 ~34 ~27 ~9 ~34 glass 0  
fill ~28 ~8 ~34 ~28 ~10 ~34 snow 0  
fill ~29 ~8 ~34 ~29 ~9 ~34 glass 0  
fill ~30 ~8 ~16 ~31 ~8 ~16 glass 0  
fill ~30 ~8 ~34 ~33 ~8 ~34 snow 0  
fill ~33 ~8 ~16 ~37 ~8 ~16 glass 0 
setblock ~35 ~8 ~31 snow 0 
setblock ~35 ~8 ~34 wooden_door 8  
fill ~37 ~8 ~34 ~40 ~8 ~34 snow 0  
fill ~39 ~8 ~16 ~40 ~8 ~16 glass 0  
fill ~41 ~8 ~34 ~41 ~9 ~34 glass 0  
fill ~42 ~8 ~24 ~43 ~8 ~24 snow 0  
fill ~42 ~8 ~34 ~42 ~10 ~34 snow 0  
fill ~43 ~8 ~34 ~43 ~9 ~34 glass 0  
fill ~44 ~8 ~24 ~45 ~8 ~24 glass 0  
fill ~44 ~8 ~34 ~44 ~10 ~34 snow 0  
fill ~45 ~8 ~34 ~45 ~9 ~34 glass 0  
fill ~46 ~8 ~24 ~47 ~8 ~24 snow 0  
fill ~46 ~8 ~34 ~46 ~10 ~34 snow 0  
fill ~48 ~8 ~24 ~49 ~8 ~24 glass 0  
fill ~48 ~8 ~34 ~54 ~8 ~34 snow 0  
fill ~50 ~8 ~24 ~52 ~8 ~24 snow 0  
fill ~52 ~8 ~8 ~52 ~9 ~8 glass 0  
fill ~52 ~8 ~9 ~52 ~9 ~9 glass 0  
fill ~52 ~8 ~10 ~52 ~9 ~10 glass 0  
fill ~52 ~8 ~11 ~52 ~10 ~11 snow 0  
fill ~52 ~8 ~12 ~52 ~10 ~12 snow 0  
fill ~52 ~8 ~13 ~52 ~9 ~13 glass 0  
fill ~52 ~8 ~14 ~52 ~9 ~14 glass 0  
fill ~52 ~8 ~15 ~52 ~9 ~15 glass 0  
fill ~52 ~8 ~16 ~52 ~9 ~16 glass 0  
fill ~52 ~8 ~17 ~52 ~10 ~17 snow 0  
fill ~52 ~8 ~18 ~52 ~10 ~18 snow 0  
fill ~52 ~8 ~19 ~52 ~9 ~19 glass 0  
fill ~52 ~8 ~20 ~52 ~9 ~20 glass 0  
fill ~52 ~8 ~21 ~52 ~9 ~21 glass 0  
fill ~52 ~8 ~22 ~52 ~10 ~22 snow 0  
fill ~52 ~8 ~23 ~52 ~10 ~23 snow 0  
fill ~55 ~8 ~34 ~57 ~8 ~34 glass 0  
fill ~58 ~8 ~11 ~58 ~9 ~11 glass 0  
fill ~58 ~8 ~12 ~58 ~9 ~12 glass 0  
fill ~58 ~8 ~13 ~58 ~9 ~13 glass 0  
fill ~58 ~8 ~15 ~58 ~9 ~15 glass 0  
fill ~58 ~8 ~16 ~58 ~9 ~16 glass 0  
fill ~58 ~8 ~17 ~58 ~9 ~17 glass 0  
fill ~58 ~8 ~19 ~58 ~9 ~19 glass 0  
fill ~58 ~8 ~20 ~58 ~9 ~20 glass 0  
fill ~58 ~8 ~21 ~58 ~9 ~21 glass 0  
fill ~58 ~8 ~23 ~58 ~9 ~23 glass 0  
fill ~58 ~8 ~24 ~58 ~9 ~24 glass 0  
fill ~58 ~8 ~25 ~58 ~9 ~25 glass 0  
fill ~58 ~8 ~26 ~58 ~10 ~26 snow 0  
fill ~58 ~8 ~27 ~58 ~9 ~27 glass 0  
fill ~58 ~8 ~28 ~58 ~9 ~28 glass 0  
fill ~58 ~8 ~29 ~58 ~9 ~29 glass 0  
fill ~58 ~8 ~30 ~58 ~10 ~30 snow 0  
fill ~58 ~8 ~31 ~58 ~9 ~31 glass 0  
fill ~58 ~8 ~32 ~58 ~9 ~32 glass 0  
fill ~58 ~8 ~33 ~58 ~9 ~33 glass 0  
fill ~58 ~8 ~34 ~58 ~10 ~34 snow 0 
setblock ~11 ~9 ~26 torch 2 
setblock ~11 ~9 ~30 torch 2  
fill ~13 ~9 ~34 ~15 ~9 ~34 glass 0  
fill ~16 ~9 ~34 ~24 ~9 ~34 snow 0  
fill ~18 ~9 ~24 ~20 ~9 ~24 snow 0 
setblock ~20 ~9 ~35 torch 3  
fill ~21 ~9 ~24 ~22 ~9 ~24 glass 0  
fill ~23 ~9 ~24 ~24 ~9 ~24 snow 0  
fill ~25 ~9 ~24 ~26 ~9 ~24 glass 0  
fill ~27 ~9 ~24 ~29 ~9 ~24 snow 0  
fill ~28 ~9 ~15 ~31 ~9 ~15 stone_slab 0  
fill ~28 ~9 ~16 ~28 ~9 ~23 stone_slab 0  
fill ~30 ~9 ~16 ~41 ~9 ~16 double_stone_slab 0  
fill ~30 ~9 ~34 ~33 ~9 ~34 snow 0  
fill ~33 ~9 ~15 ~37 ~9 ~15 stone_slab 0 
setblock ~35 ~9 ~34 double_stone_slab 0  
fill ~37 ~9 ~34 ~40 ~9 ~34 snow 0  
fill ~39 ~9 ~15 ~42 ~9 ~15 stone_slab 0  
fill ~42 ~9 ~16 ~42 ~9 ~23 stone_slab 0  
fill ~42 ~9 ~24 ~43 ~9 ~24 snow 0  
fill ~44 ~9 ~24 ~45 ~9 ~24 glass 0  
fill ~46 ~9 ~24 ~47 ~9 ~24 snow 0  
fill ~48 ~9 ~24 ~49 ~9 ~24 glass 0  
fill ~48 ~9 ~34 ~54 ~9 ~34 snow 0  
fill ~50 ~9 ~24 ~52 ~9 ~24 snow 0 
setblock ~50 ~9 ~35 torch 3  
fill ~55 ~9 ~34 ~57 ~9 ~34 glass 0 
setblock ~59 ~9 ~26 torch 1 
setblock ~59 ~9 ~30 torch 1  
fill ~12 ~10 ~11 ~12 ~10 ~34 snow 0  
fill ~13 ~10 ~34 ~58 ~10 ~34 snow 0 
setblock ~14 ~10 ~5 stone_button 4 
setblock ~16 ~10 ~5 stone_button 4 
setblock ~18 ~10 ~5 stone_button 4  
fill ~18 ~10 ~8 ~18 ~10 ~24 snow 0 
setblock ~19 ~10 ~22 stone_button 1  
fill ~19 ~10 ~24 ~29 ~10 ~24 snow 0 
setblock ~20 ~10 ~23 stone_button 4  
fill ~30 ~10 ~16 ~41 ~10 ~16 double_stone_slab 0 
setblock ~31 ~10 ~15 torch 2 
setblock ~32 ~10 ~14 stone_button 4 
setblock ~32 ~10 ~38 torch 4 
setblock ~33 ~10 ~15 torch 1 
setblock ~37 ~10 ~15 torch 2 
setblock ~38 ~10 ~14 stone_button 4 
setblock ~38 ~10 ~38 torch 4 
setblock ~39 ~10 ~15 torch 1  
fill ~42 ~10 ~24 ~52 ~10 ~24 snow 0 
setblock ~50 ~10 ~23 stone_button 4 
setblock ~51 ~10 ~22 stone_button 2 
setblock ~52 ~10 ~5 stone_button 4  
fill ~52 ~10 ~8 ~52 ~10 ~24 snow 0 
setblock ~54 ~10 ~5 stone_button 4 
setblock ~56 ~10 ~5 stone_button 4  
fill ~58 ~10 ~11 ~58 ~10 ~34 snow 0  
fill ~9 ~11 ~6 ~12 ~11 ~6 stone_slab 8  
fill ~9 ~11 ~7 ~12 ~11 ~7 stone_slab 8  
fill ~9 ~11 ~8 ~10 ~11 ~8 stone_slab 8  
fill ~9 ~11 ~9 ~10 ~11 ~9 stone_slab 8  
fill ~9 ~11 ~10 ~10 ~11 ~10 stone_slab 8  
fill ~9 ~11 ~11 ~10 ~11 ~11 stone_slab 8  
fill ~9 ~11 ~12 ~10 ~11 ~12 stone_slab 8  
fill ~9 ~11 ~13 ~10 ~11 ~13 stone_slab 8  
fill ~9 ~11 ~14 ~10 ~11 ~14 stone_slab 8  
fill ~9 ~11 ~15 ~10 ~11 ~15 stone_slab 8  
fill ~9 ~11 ~16 ~10 ~11 ~16 stone_slab 8  
fill ~9 ~11 ~17 ~10 ~11 ~17 stone_slab 8  
fill ~9 ~11 ~18 ~10 ~11 ~18 stone_slab 8  
fill ~9 ~11 ~19 ~10 ~11 ~19 stone_slab 8  
fill ~9 ~11 ~20 ~10 ~11 ~20 stone_slab 8  
fill ~9 ~11 ~21 ~10 ~11 ~21 stone_slab 8  
fill ~9 ~11 ~22 ~10 ~11 ~22 stone_slab 8  
fill ~9 ~11 ~23 ~10 ~11 ~23 stone_slab 8  
fill ~9 ~11 ~24 ~10 ~11 ~24 stone_slab 8  
fill ~9 ~11 ~25 ~10 ~11 ~25 stone_slab 8  
fill ~9 ~11 ~26 ~10 ~11 ~26 stone_slab 8  
fill ~9 ~11 ~27 ~10 ~11 ~27 stone_slab 8  
fill ~9 ~11 ~28 ~10 ~11 ~28 stone_slab 8  
fill ~9 ~11 ~29 ~10 ~11 ~29 stone_slab 8  
fill ~9 ~11 ~30 ~10 ~11 ~30 stone_slab 8  
fill ~9 ~11 ~31 ~10 ~11 ~31 stone_slab 8  
fill ~9 ~11 ~32 ~10 ~11 ~32 stone_slab 8  
fill ~9 ~11 ~33 ~10 ~11 ~33 stone_slab 8  
fill ~9 ~11 ~34 ~10 ~11 ~34 stone_slab 8  
fill ~9 ~11 ~35 ~10 ~11 ~35 stone_slab 8  
fill ~9 ~11 ~36 ~30 ~11 ~36 stone_slab 8  
fill ~9 ~11 ~37 ~30 ~11 ~37 stone_slab 8  
fill ~11 ~11 ~3 ~21 ~11 ~3 stone_slab 8  
fill ~11 ~11 ~4 ~21 ~11 ~4 stone_slab 8  
fill ~11 ~11 ~5 ~12 ~11 ~5 stone_slab 8  
fill ~11 ~11 ~8 ~19 ~11 ~8 stone_slab 0  
fill ~11 ~11 ~9 ~19 ~11 ~9 stone_slab 0  
fill ~11 ~11 ~10 ~19 ~11 ~10 stone_slab 0  
fill ~11 ~11 ~11 ~19 ~11 ~11 stone_slab 0  
fill ~11 ~11 ~12 ~19 ~11 ~12 stone_slab 0  
fill ~11 ~11 ~13 ~19 ~11 ~13 stone_slab 0  
fill ~11 ~11 ~14 ~19 ~11 ~14 stone_slab 0  
fill ~11 ~11 ~15 ~19 ~11 ~15 stone_slab 0  
fill ~11 ~11 ~16 ~19 ~11 ~16 stone_slab 0  
fill ~11 ~11 ~17 ~19 ~11 ~17 stone_slab 0  
fill ~11 ~11 ~18 ~19 ~11 ~18 stone_slab 0  
fill ~11 ~11 ~19 ~19 ~11 ~19 stone_slab 0  
fill ~11 ~11 ~20 ~19 ~11 ~20 stone_slab 0  
fill ~11 ~11 ~21 ~19 ~11 ~21 stone_slab 0  
fill ~11 ~11 ~22 ~19 ~11 ~22 stone_slab 0  
fill ~11 ~11 ~23 ~33 ~11 ~23 stone_slab 0  
fill ~11 ~11 ~24 ~33 ~11 ~24 stone_slab 0  
fill ~11 ~11 ~25 ~33 ~11 ~25 stone_slab 0  
fill ~11 ~11 ~26 ~59 ~11 ~26 stone_slab 0  
fill ~11 ~11 ~27 ~59 ~11 ~27 stone_slab 0  
fill ~11 ~11 ~28 ~59 ~11 ~28 stone_slab 0  
fill ~11 ~11 ~29 ~59 ~11 ~29 stone_slab 0  
fill ~11 ~11 ~30 ~59 ~11 ~30 stone_slab 0  
fill ~11 ~11 ~31 ~59 ~11 ~31 stone_slab 0  
fill ~11 ~11 ~32 ~59 ~11 ~32 stone_slab 0  
fill ~11 ~11 ~33 ~59 ~11 ~33 stone_slab 0  
fill ~11 ~11 ~34 ~59 ~11 ~34 stone_slab 0  
fill ~11 ~11 ~35 ~59 ~11 ~35 stone_slab 0 
setblock ~13 ~11 ~5 double_stone_slab 0  
fill ~13 ~11 ~6 ~19 ~11 ~6 stone_slab 0  
fill ~13 ~11 ~7 ~19 ~11 ~7 stone_slab 0  
fill ~14 ~11 ~5 ~19 ~11 ~5 stone_slab 0  
fill ~20 ~11 ~5 ~21 ~11 ~5 stone_slab 8  
fill ~20 ~11 ~6 ~21 ~11 ~6 stone_slab 8  
fill ~20 ~11 ~7 ~21 ~11 ~7 stone_slab 8  
fill ~20 ~11 ~8 ~21 ~11 ~8 stone_slab 8  
fill ~20 ~11 ~9 ~21 ~11 ~9 stone_slab 8  
fill ~20 ~11 ~10 ~21 ~11 ~10 stone_slab 8  
fill ~20 ~11 ~11 ~21 ~11 ~11 stone_slab 8  
fill ~20 ~11 ~12 ~21 ~11 ~12 stone_slab 8  
fill ~20 ~11 ~13 ~21 ~11 ~13 stone_slab 8  
fill ~20 ~11 ~14 ~21 ~11 ~14 stone_slab 8  
fill ~20 ~11 ~15 ~21 ~11 ~15 stone_slab 8  
fill ~20 ~11 ~16 ~21 ~11 ~16 stone_slab 8  
fill ~20 ~11 ~17 ~21 ~11 ~17 stone_slab 8  
fill ~20 ~11 ~18 ~21 ~11 ~18 stone_slab 8  
fill ~20 ~11 ~19 ~21 ~11 ~19 stone_slab 8  
fill ~20 ~11 ~20 ~21 ~11 ~20 stone_slab 8  
fill ~20 ~11 ~21 ~26 ~11 ~21 stone_slab 8  
fill ~20 ~11 ~22 ~26 ~11 ~22 stone_slab 8  
fill ~25 ~11 ~12 ~45 ~11 ~12 stone_slab 8  
fill ~25 ~11 ~13 ~45 ~11 ~13 stone_slab 8  
fill ~25 ~11 ~14 ~26 ~11 ~14 stone_slab 8  
fill ~25 ~11 ~15 ~26 ~11 ~15 stone_slab 8  
fill ~25 ~11 ~16 ~26 ~11 ~16 stone_slab 8  
fill ~25 ~11 ~17 ~26 ~11 ~17 stone_slab 8  
fill ~25 ~11 ~18 ~26 ~11 ~18 stone_slab 8  
fill ~25 ~11 ~19 ~26 ~11 ~19 stone_slab 8  
fill ~25 ~11 ~20 ~26 ~11 ~20 stone_slab 8  
fill ~27 ~11 ~14 ~27 ~11 ~15 double_stone_slab 0  
fill ~27 ~11 ~16 ~43 ~11 ~16 stone_slab 0  
fill ~27 ~11 ~17 ~43 ~11 ~17 stone_slab 0  
fill ~27 ~11 ~18 ~43 ~11 ~18 stone_slab 0  
fill ~27 ~11 ~19 ~43 ~11 ~19 stone_slab 0  
fill ~27 ~11 ~20 ~43 ~11 ~20 stone_slab 0  
fill ~27 ~11 ~21 ~43 ~11 ~21 stone_slab 0  
fill ~27 ~11 ~22 ~43 ~11 ~22 stone_slab 0  
fill ~28 ~11 ~14 ~42 ~11 ~14 stone_slab 0  
fill ~28 ~11 ~15 ~31 ~11 ~15 stone_slab 0  
fill ~29 ~11 ~38 ~30 ~11 ~38 stone_slab 8  
fill ~29 ~11 ~39 ~30 ~11 ~39 stone_slab 8  
fill ~29 ~11 ~40 ~30 ~11 ~40 stone_slab 8  
fill ~29 ~11 ~41 ~41 ~11 ~41 stone_slab 8  
fill ~29 ~11 ~42 ~41 ~11 ~42 stone_slab 8  
fill ~31 ~11 ~36 ~39 ~11 ~36 stone_slab 0  
fill ~31 ~11 ~37 ~39 ~11 ~37 stone_slab 0 
fill ~31 ~11 ~38 ~39 ~11 ~38 stone_slab 0  
fill ~31 ~11 ~39 ~39 ~11 ~39 stone_slab 0  
fill ~31 ~11 ~40 ~39 ~11 ~40 stone_slab 0  
fill ~33 ~11 ~15 ~37 ~11 ~15 stone_slab 0  
fill ~34 ~11 ~23 ~34 ~11 ~25 double_stone_slab 0  
fill ~35 ~11 ~23 ~35 ~11 ~40 stone_slab 0  
fill ~36 ~11 ~23 ~36 ~11 ~25 double_stone_slab 0  
fill ~37 ~11 ~23 ~59 ~11 ~23 stone_slab 0  
fill ~37 ~11 ~24 ~59 ~11 ~24 stone_slab 0  
fill ~37 ~11 ~25 ~59 ~11 ~25 stone_slab 0  
fill ~39 ~11 ~15 ~42 ~11 ~15 stone_slab 0  
fill ~40 ~11 ~36 ~61 ~11 ~36 stone_slab 8  
fill ~40 ~11 ~37 ~61 ~11 ~37 stone_slab 8  
fill ~40 ~11 ~38 ~41 ~11 ~38 stone_slab 8  
fill ~40 ~11 ~39 ~41 ~11 ~39 stone_slab 8  
fill ~40 ~11 ~40 ~41 ~11 ~40 stone_slab 8  
fill ~43 ~11 ~14 ~43 ~11 ~15 double_stone_slab 0  
fill ~44 ~11 ~14 ~45 ~11 ~14 stone_slab 8  
fill ~44 ~11 ~15 ~45 ~11 ~15 stone_slab 8  
fill ~44 ~11 ~16 ~45 ~11 ~16 stone_slab 8  
fill ~44 ~11 ~17 ~45 ~11 ~17 stone_slab 8  
fill ~44 ~11 ~18 ~45 ~11 ~18 stone_slab 8  
fill ~44 ~11 ~19 ~45 ~11 ~19 stone_slab 8  
fill ~44 ~11 ~20 ~45 ~11 ~20 stone_slab 8  
fill ~44 ~11 ~21 ~50 ~11 ~21 stone_slab 8  
fill ~44 ~11 ~22 ~50 ~11 ~22 stone_slab 8  
fill ~49 ~11 ~3 ~59 ~11 ~3 stone_slab 8  
fill ~49 ~11 ~4 ~59 ~11 ~4 stone_slab 8  
fill ~49 ~11 ~5 ~50 ~11 ~5 stone_slab 8  
fill ~49 ~11 ~6 ~50 ~11 ~6 stone_slab 8  
fill ~49 ~11 ~7 ~50 ~11 ~7 stone_slab 8  
fill ~49 ~11 ~8 ~50 ~11 ~8 stone_slab 8  
fill ~49 ~11 ~9 ~50 ~11 ~9 stone_slab 8  
fill ~49 ~11 ~10 ~50 ~11 ~10 stone_slab 8  
fill ~49 ~11 ~11 ~50 ~11 ~11 stone_slab 8  
fill ~49 ~11 ~12 ~50 ~11 ~12 stone_slab 8  
fill ~49 ~11 ~13 ~50 ~11 ~13 stone_slab 8  
fill ~49 ~11 ~14 ~50 ~11 ~14 stone_slab 8  
fill ~49 ~11 ~15 ~50 ~11 ~15 stone_slab 8  
fill ~49 ~11 ~16 ~50 ~11 ~16 stone_slab 8  
fill ~49 ~11 ~17 ~50 ~11 ~17 stone_slab 8  
fill ~49 ~11 ~18 ~50 ~11 ~18 stone_slab 8  
fill ~49 ~11 ~19 ~50 ~11 ~19 stone_slab 8  
fill ~49 ~11 ~20 ~50 ~11 ~20 stone_slab 8  
fill ~51 ~11 ~5 ~56 ~11 ~5 stone_slab 0  
fill ~51 ~11 ~6 ~57 ~11 ~6 stone_slab 0  
fill ~51 ~11 ~7 ~57 ~11 ~7 stone_slab 0  
fill ~51 ~11 ~8 ~59 ~11 ~8 stone_slab 0  
fill ~51 ~11 ~9 ~59 ~11 ~9 stone_slab 0  
fill ~51 ~11 ~10 ~59 ~11 ~10 stone_slab 0  
fill ~51 ~11 ~11 ~59 ~11 ~11 stone_slab 0  
fill ~51 ~11 ~12 ~59 ~11 ~12 stone_slab 0  
fill ~51 ~11 ~13 ~59 ~11 ~13 stone_slab 0  
fill ~51 ~11 ~14 ~59 ~11 ~14 stone_slab 0  
fill ~51 ~11 ~15 ~59 ~11 ~15 stone_slab 0  
fill ~51 ~11 ~16 ~59 ~11 ~16 stone_slab 0  
fill ~51 ~11 ~17 ~59 ~11 ~17 stone_slab 0  
fill ~51 ~11 ~18 ~59 ~11 ~18 stone_slab 0  
fill ~51 ~11 ~19 ~59 ~11 ~19 stone_slab 0  
fill ~51 ~11 ~20 ~59 ~11 ~20 stone_slab 0  
fill ~51 ~11 ~21 ~59 ~11 ~21 stone_slab 0  
fill ~51 ~11 ~22 ~59 ~11 ~22 stone_slab 0 
setblock ~57 ~11 ~5 double_stone_slab 0  
fill ~58 ~11 ~5 ~59 ~11 ~5 stone_slab 8  
fill ~58 ~11 ~6 ~61 ~11 ~6 stone_slab 8  
fill ~58 ~11 ~7 ~61 ~11 ~7 stone_slab 8  
fill ~60 ~11 ~8 ~61 ~11 ~8 stone_slab 8  
fill ~60 ~11 ~9 ~61 ~11 ~9 stone_slab 8  
fill ~60 ~11 ~10 ~61 ~11 ~10 stone_slab 8  
fill ~60 ~11 ~11 ~61 ~11 ~11 stone_slab 8  
fill ~60 ~11 ~12 ~61 ~11 ~12 stone_slab 8  
fill ~60 ~11 ~13 ~61 ~11 ~13 stone_slab 8  
fill ~60 ~11 ~14 ~61 ~11 ~14 stone_slab 8  
fill ~60 ~11 ~15 ~61 ~11 ~15 stone_slab 8  
fill ~60 ~11 ~16 ~61 ~11 ~16 stone_slab 8  
fill ~60 ~11 ~17 ~61 ~11 ~17 stone_slab 8  
fill ~60 ~11 ~18 ~61 ~11 ~18 stone_slab 8  
fill ~60 ~11 ~19 ~61 ~11 ~19 stone_slab 8  
fill ~60 ~11 ~20 ~61 ~11 ~20 stone_slab 8  
fill ~60 ~11 ~21 ~61 ~11 ~21 stone_slab 8  
fill ~60 ~11 ~22 ~61 ~11 ~22 stone_slab 8  
fill ~60 ~11 ~23 ~61 ~11 ~23 stone_slab 8  
fill ~60 ~11 ~24 ~61 ~11 ~24 stone_slab 8  
fill ~60 ~11 ~25 ~61 ~11 ~25 stone_slab 8  
fill ~60 ~11 ~26 ~61 ~11 ~26 stone_slab 8  
fill ~60 ~11 ~27 ~61 ~11 ~27 stone_slab 8  
fill ~60 ~11 ~28 ~61 ~11 ~28 stone_slab 8  
fill ~60 ~11 ~29 ~61 ~11 ~29 stone_slab 8  
fill ~60 ~11 ~30 ~61 ~11 ~30 stone_slab 8  
fill ~60 ~11 ~31 ~61 ~11 ~31 stone_slab 8  
fill ~60 ~11 ~32 ~61 ~11 ~32 stone_slab 8  
fill ~60 ~11 ~33 ~61 ~11 ~33 stone_slab 8  
fill ~60 ~11 ~34 ~61 ~11 ~34 stone_slab 8  
fill ~60 ~11 ~35 ~61 ~11 ~35 stone_slab 8 
setblock ~32 ~13 ~16 torch 3 
setblock ~38 ~13 ~16 torch 3 
setblock ~32 ~14 ~15 stone_slab 0 
setblock ~38 ~14 ~15 stone_slab 0    