fill ~1 ~0 ~43 ~1 ~2 ~43 vine 8 
setblock ~1 ~0 ~44 tallgrass 1 
setblock ~1 ~0 ~69 tallgrass 1  
fill ~1 ~0 ~70 ~1 ~2 ~70 vine 8  
fill ~2 ~0 ~42 ~5 ~0 ~42 tallgrass 1  
fill ~2 ~0 ~43 ~5 ~0 ~43 stonebrick 0  
fill ~2 ~0 ~44 ~5 ~0 ~44 stonebrick 0 
setblock ~2 ~0 ~48 tallgrass 1 
setblock ~2 ~0 ~50 tallgrass 1  
fill ~2 ~0 ~54 ~2 ~0 ~55 tallgrass 1 
setblock ~2 ~0 ~62 tallgrass 1  
fill ~2 ~0 ~68 ~2 ~2 ~68 vine 1  
fill ~2 ~0 ~69 ~5 ~0 ~69 stonebrick 0  
fill ~2 ~0 ~70 ~5 ~0 ~70 stonebrick 0  
fill ~2 ~0 ~71 ~2 ~2 ~71 vine 4  
fill ~3 ~0 ~41 ~5 ~0 ~41 tallgrass 1  
fill ~3 ~0 ~45 ~3 ~0 ~68 stone_brick_stairs 0  
fill ~3 ~0 ~71 ~5 ~0 ~71 tallgrass 1 
setblock ~4 ~0 ~19 stone_slab 0 
setblock ~4 ~0 ~39 stone_slab 0  
fill ~4 ~0 ~40 ~5 ~0 ~40 tallgrass 1  
fill ~4 ~0 ~45 ~5 ~0 ~45 stonebrick 0  
fill ~4 ~0 ~46 ~5 ~0 ~46 stonebrick 0  
fill ~4 ~0 ~47 ~5 ~0 ~47 stonebrick 0  
fill ~4 ~0 ~48 ~5 ~0 ~48 stonebrick 0  
fill ~4 ~0 ~49 ~5 ~0 ~49 stonebrick 0  
fill ~4 ~0 ~50 ~5 ~0 ~50 stonebrick 0  
fill ~4 ~0 ~51 ~5 ~0 ~51 stonebrick 0  
fill ~4 ~0 ~52 ~5 ~0 ~52 stonebrick 0  
fill ~4 ~0 ~53 ~5 ~0 ~53 stonebrick 0  
fill ~4 ~0 ~54 ~5 ~0 ~54 stonebrick 0  
fill ~4 ~0 ~55 ~5 ~0 ~55 stonebrick 0  
fill ~4 ~0 ~56 ~5 ~0 ~56 stonebrick 0  
fill ~4 ~0 ~57 ~5 ~0 ~57 stonebrick 0  
fill ~4 ~0 ~58 ~5 ~0 ~58 stonebrick 0  
fill ~4 ~0 ~59 ~5 ~0 ~59 stonebrick 0  
fill ~4 ~0 ~60 ~5 ~0 ~60 stonebrick 0  
fill ~4 ~0 ~61 ~5 ~0 ~61 stonebrick 0  
fill ~4 ~0 ~62 ~5 ~0 ~62 stonebrick 0  
fill ~4 ~0 ~63 ~5 ~0 ~63 stonebrick 0  
fill ~4 ~0 ~64 ~5 ~0 ~64 stonebrick 0  
fill ~4 ~0 ~65 ~5 ~0 ~65 stonebrick 0  
fill ~4 ~0 ~66 ~5 ~0 ~66 stonebrick 0  
fill ~4 ~0 ~67 ~5 ~0 ~67 stonebrick 0  
fill ~4 ~0 ~68 ~5 ~0 ~68 stonebrick 0  
fill ~4 ~0 ~72 ~5 ~0 ~72 tallgrass 1 
setblock ~4 ~0 ~97 stone_slab 0  
fill ~4 ~0 ~103 ~5 ~0 ~103 tallgrass 1  
fill ~4 ~0 ~104 ~5 ~0 ~104 tallgrass 1  
fill ~5 ~0 ~6 ~5 ~0 ~12 tallgrass 1  
fill ~5 ~0 ~13 ~5 ~2 ~13 vine 8 
setblock ~5 ~0 ~14 tallgrass 1  
fill ~5 ~0 ~15 ~5 ~0 ~17 vine 8  
fill ~5 ~0 ~18 ~5 ~0 ~19 tallgrass 1  
fill ~5 ~0 ~20 ~5 ~2 ~20 vine 8  
fill ~5 ~0 ~21 ~5 ~0 ~20 vine 8  
fill ~5 ~0 ~22 ~5 ~0 ~26 tallgrass 1  
fill ~5 ~0 ~27 ~5 ~0 ~28 vine 8 
setblock ~5 ~0 ~29 tallgrass 1  
fill ~5 ~0 ~30 ~5 ~2 ~30 vine 8  
fill ~5 ~0 ~33 ~5 ~2 ~33 vine 8  
fill ~5 ~0 ~35 ~5 ~0 ~42 tallgrass 1  
fill ~5 ~0 ~73 ~5 ~0 ~78 tallgrass 1  
fill ~5 ~0 ~79 ~5 ~2 ~79 vine 8  
fill ~5 ~0 ~80 ~5 ~2 ~80 vine 8  
fill ~5 ~0 ~81 ~5 ~2 ~81 vine 8  
fill ~5 ~0 ~82 ~5 ~2 ~82 vine 8 
setblock ~5 ~0 ~83 tallgrass 1  
fill ~5 ~0 ~84 ~5 ~0 ~85 vine 8  
fill ~5 ~0 ~87 ~5 ~2 ~87 vine 8  
fill ~5 ~0 ~88 ~5 ~2 ~88 vine 8  
fill ~5 ~0 ~89 ~5 ~2 ~89 vine 8  
fill ~5 ~0 ~91 ~5 ~0 ~101 tallgrass 1  
fill ~5 ~0 ~105 ~5 ~2 ~105 vine 8  
fill ~5 ~0 ~107 ~5 ~0 ~108 tallgrass 1 
setblock ~5 ~0 ~109 stone_slab 0  
fill ~6 ~0 ~6 ~107 ~0 ~6 double_stone_slab 5  
fill ~6 ~0 ~7 ~107 ~0 ~7 double_stone_slab 5  
fill ~6 ~0 ~8 ~7 ~0 ~8 double_stone_slab 5  
fill ~6 ~0 ~9 ~7 ~0 ~9 double_stone_slab 5  
fill ~6 ~0 ~10 ~7 ~0 ~10 double_stone_slab 5  
fill ~6 ~0 ~11 ~7 ~0 ~11 double_stone_slab 5  
fill ~6 ~0 ~12 ~7 ~0 ~12 double_stone_slab 5  
fill ~6 ~0 ~13 ~7 ~0 ~13 double_stone_slab 5  
fill ~6 ~0 ~14 ~7 ~0 ~14 double_stone_slab 5  
fill ~6 ~0 ~15 ~7 ~0 ~15 double_stone_slab 5  
fill ~6 ~0 ~16 ~7 ~0 ~16 double_stone_slab 5  
fill ~6 ~0 ~17 ~7 ~0 ~17 double_stone_slab 5  
fill ~6 ~0 ~18 ~7 ~0 ~18 double_stone_slab 5  
fill ~6 ~0 ~19 ~7 ~0 ~19 double_stone_slab 5  
fill ~6 ~0 ~20 ~7 ~0 ~20 double_stone_slab 5  
fill ~6 ~0 ~21 ~7 ~0 ~21 double_stone_slab 5  
fill ~6 ~0 ~22 ~7 ~0 ~22 double_stone_slab 5  
fill ~6 ~0 ~23 ~7 ~0 ~23 double_stone_slab 5  
fill ~6 ~0 ~24 ~7 ~0 ~24 double_stone_slab 5  
fill ~6 ~0 ~25 ~7 ~0 ~25 double_stone_slab 5  
fill ~6 ~0 ~26 ~7 ~0 ~26 double_stone_slab 5  
fill ~6 ~0 ~27 ~7 ~0 ~27 double_stone_slab 5  
fill ~6 ~0 ~28 ~7 ~0 ~28 double_stone_slab 5  
fill ~6 ~0 ~29 ~7 ~0 ~29 double_stone_slab 5  
fill ~6 ~0 ~30 ~7 ~0 ~30 double_stone_slab 5  
fill ~6 ~0 ~31 ~7 ~0 ~31 double_stone_slab 5  
fill ~6 ~0 ~32 ~7 ~0 ~32 double_stone_slab 5  
fill ~6 ~0 ~33 ~7 ~0 ~33 double_stone_slab 5  
fill ~6 ~0 ~34 ~7 ~0 ~34 double_stone_slab 5  
fill ~6 ~0 ~35 ~7 ~0 ~35 double_stone_slab 5  
fill ~6 ~0 ~36 ~7 ~0 ~36 double_stone_slab 5  
fill ~6 ~0 ~37 ~7 ~0 ~37 double_stone_slab 5  
fill ~6 ~0 ~38 ~7 ~0 ~38 double_stone_slab 5  
fill ~6 ~0 ~39 ~7 ~0 ~39 double_stone_slab 5  
fill ~6 ~0 ~40 ~7 ~0 ~40 double_stone_slab 5  
fill ~6 ~0 ~41 ~7 ~0 ~41 double_stone_slab 5  
fill ~6 ~0 ~42 ~7 ~0 ~42 double_stone_slab 5  
fill ~6 ~0 ~43 ~7 ~0 ~43 double_stone_slab 5  
fill ~6 ~0 ~44 ~7 ~0 ~44 double_stone_slab 5  
fill ~6 ~0 ~45 ~7 ~0 ~45 double_stone_slab 5  
fill ~6 ~0 ~46 ~7 ~0 ~46 double_stone_slab 5  
fill ~6 ~0 ~47 ~7 ~0 ~47 double_stone_slab 5  
fill ~6 ~0 ~48 ~7 ~0 ~48 double_stone_slab 5  
fill ~6 ~0 ~49 ~7 ~0 ~49 double_stone_slab 5  
fill ~6 ~0 ~50 ~7 ~0 ~50 double_stone_slab 5  
fill ~6 ~0 ~51 ~7 ~0 ~51 double_stone_slab 5  
fill ~6 ~0 ~52 ~7 ~0 ~52 double_stone_slab 5  
fill ~6 ~0 ~53 ~7 ~0 ~53 double_stone_slab 5  
fill ~6 ~0 ~54 ~7 ~0 ~54 double_stone_slab 5  
fill ~6 ~0 ~55 ~7 ~0 ~55 double_stone_slab 5  
fill ~6 ~0 ~56 ~7 ~0 ~56 double_stone_slab 5  
fill ~6 ~0 ~57 ~7 ~0 ~57 double_stone_slab 5  
fill ~6 ~0 ~58 ~7 ~0 ~58 double_stone_slab 5  
fill ~6 ~0 ~59 ~7 ~0 ~59 double_stone_slab 5  
fill ~6 ~0 ~60 ~7 ~0 ~60 double_stone_slab 5  
fill ~6 ~0 ~61 ~7 ~0 ~61 double_stone_slab 5  
fill ~6 ~0 ~62 ~7 ~0 ~62 double_stone_slab 5  
fill ~6 ~0 ~63 ~7 ~0 ~63 double_stone_slab 5  
fill ~6 ~0 ~64 ~7 ~0 ~64 double_stone_slab 5  
fill ~6 ~0 ~65 ~7 ~0 ~65 double_stone_slab 5  
fill ~6 ~0 ~66 ~7 ~0 ~66 double_stone_slab 5  
fill ~6 ~0 ~67 ~7 ~0 ~67 double_stone_slab 5  
fill ~6 ~0 ~68 ~7 ~0 ~68 double_stone_slab 5  
fill ~6 ~0 ~69 ~7 ~0 ~69 double_stone_slab 5  
fill ~6 ~0 ~70 ~7 ~0 ~70 double_stone_slab 5  
fill ~6 ~0 ~71 ~7 ~0 ~71 double_stone_slab 5  
fill ~6 ~0 ~72 ~7 ~0 ~72 double_stone_slab 5  
fill ~6 ~0 ~73 ~7 ~0 ~73 double_stone_slab 5  
fill ~6 ~0 ~74 ~7 ~0 ~74 double_stone_slab 5  
fill ~6 ~0 ~75 ~7 ~0 ~75 double_stone_slab 5  
fill ~6 ~0 ~76 ~7 ~0 ~76 double_stone_slab 5  
fill ~6 ~0 ~77 ~7 ~0 ~77 double_stone_slab 5  
fill ~6 ~0 ~78 ~7 ~0 ~78 double_stone_slab 5  
fill ~6 ~0 ~79 ~7 ~0 ~79 double_stone_slab 5  
fill ~6 ~0 ~80 ~7 ~0 ~80 double_stone_slab 5  
fill ~6 ~0 ~81 ~7 ~0 ~81 double_stone_slab 5  
fill ~6 ~0 ~82 ~7 ~0 ~82 double_stone_slab 5  
fill ~6 ~0 ~83 ~7 ~0 ~83 double_stone_slab 5  
fill ~6 ~0 ~84 ~7 ~0 ~84 double_stone_slab 5  
fill ~6 ~0 ~85 ~7 ~0 ~85 double_stone_slab 5  
fill ~6 ~0 ~86 ~7 ~0 ~86 double_stone_slab 5  
fill ~6 ~0 ~87 ~7 ~0 ~87 double_stone_slab 5  
fill ~6 ~0 ~88 ~7 ~0 ~88 double_stone_slab 5  
fill ~6 ~0 ~89 ~7 ~0 ~89 double_stone_slab 5  
fill ~6 ~0 ~90 ~7 ~0 ~90 double_stone_slab 5  
fill ~6 ~0 ~91 ~7 ~0 ~91 double_stone_slab 5  
fill ~6 ~0 ~92 ~7 ~0 ~92 double_stone_slab 5  
fill ~6 ~0 ~93 ~7 ~0 ~93 double_stone_slab 5  
fill ~6 ~0 ~94 ~7 ~0 ~94 double_stone_slab 5  
fill ~6 ~0 ~95 ~7 ~0 ~95 double_stone_slab 5  
fill ~6 ~0 ~96 ~7 ~0 ~96 double_stone_slab 5  
fill ~6 ~0 ~97 ~7 ~0 ~97 double_stone_slab 5  
fill ~6 ~0 ~98 ~7 ~0 ~98 double_stone_slab 5  
fill ~6 ~0 ~99 ~7 ~0 ~99 double_stone_slab 5  
fill ~6 ~0 ~100 ~7 ~0 ~100 double_stone_slab 5  
fill ~6 ~0 ~101 ~7 ~0 ~101 double_stone_slab 5  
fill ~6 ~0 ~102 ~7 ~0 ~102 double_stone_slab 5  
fill ~6 ~0 ~103 ~7 ~0 ~103 double_stone_slab 5  
fill ~6 ~0 ~104 ~7 ~0 ~104 double_stone_slab 5  
fill ~6 ~0 ~105 ~7 ~0 ~105 double_stone_slab 5  
fill ~6 ~0 ~106 ~7 ~0 ~106 double_stone_slab 5  
fill ~6 ~0 ~107 ~107 ~0 ~107 double_stone_slab 5  
fill ~6 ~0 ~108 ~41 ~0 ~108 double_stone_slab 5  
fill ~6 ~0 ~109 ~7 ~0 ~109 vine 4 
setblock ~8 ~0 ~5 tallgrass 1  
fill ~8 ~0 ~8 ~105 ~0 ~8 dirt 0  
fill ~8 ~0 ~9 ~105 ~0 ~9 dirt 0  
fill ~8 ~0 ~10 ~105 ~0 ~10 dirt 0  
fill ~8 ~0 ~11 ~105 ~0 ~11 dirt 0  
fill ~8 ~0 ~12 ~105 ~0 ~12 dirt 0  
fill ~8 ~0 ~13 ~105 ~0 ~13 dirt 0  
fill ~8 ~0 ~14 ~105 ~0 ~14 dirt 0  
fill ~8 ~0 ~15 ~105 ~0 ~15 dirt 0  
fill ~8 ~0 ~16 ~105 ~0 ~16 dirt 0  
fill ~8 ~0 ~17 ~105 ~0 ~17 dirt 0  
fill ~8 ~0 ~18 ~105 ~0 ~18 dirt 0  
fill ~8 ~0 ~19 ~105 ~0 ~19 dirt 0  
fill ~8 ~0 ~20 ~105 ~0 ~20 dirt 0  
fill ~8 ~0 ~21 ~105 ~0 ~21 dirt 0  
fill ~8 ~0 ~22 ~105 ~0 ~22 dirt 0  
fill ~8 ~0 ~23 ~105 ~0 ~23 dirt 0  
fill ~8 ~0 ~24 ~105 ~0 ~24 dirt 0  
fill ~8 ~0 ~25 ~105 ~0 ~25 dirt 0  
fill ~8 ~0 ~26 ~105 ~0 ~26 dirt 0  
fill ~8 ~0 ~27 ~105 ~0 ~27 dirt 0  
fill ~8 ~0 ~28 ~105 ~0 ~28 dirt 0  
fill ~8 ~0 ~29 ~105 ~0 ~29 dirt 0  
fill ~8 ~0 ~30 ~105 ~0 ~30 dirt 0  
fill ~8 ~0 ~31 ~105 ~0 ~31 dirt 0  
fill ~8 ~0 ~32 ~105 ~0 ~32 dirt 0  
fill ~8 ~0 ~33 ~105 ~0 ~33 dirt 0  
fill ~8 ~0 ~34 ~105 ~0 ~34 dirt 0  
fill ~8 ~0 ~35 ~105 ~0 ~35 dirt 0  
fill ~8 ~0 ~36 ~105 ~0 ~36 dirt 0  
fill ~8 ~0 ~37 ~105 ~0 ~37 dirt 0  
fill ~8 ~0 ~38 ~105 ~0 ~38 dirt 0  
fill ~8 ~0 ~39 ~105 ~0 ~39 dirt 0  
fill ~8 ~0 ~40 ~105 ~0 ~40 dirt 0  
fill ~8 ~0 ~41 ~105 ~0 ~41 dirt 0  
fill ~8 ~0 ~42 ~105 ~0 ~42 dirt 0  
fill ~8 ~0 ~43 ~105 ~0 ~43 dirt 0  
fill ~8 ~0 ~44 ~105 ~0 ~44 dirt 0  
fill ~8 ~0 ~45 ~105 ~0 ~45 dirt 0  
fill ~8 ~0 ~46 ~105 ~0 ~46 dirt 0  
fill ~8 ~0 ~47 ~105 ~0 ~47 dirt 0  
fill ~8 ~0 ~48 ~105 ~0 ~48 dirt 0  
fill ~8 ~0 ~49 ~105 ~0 ~49 dirt 0  
fill ~8 ~0 ~50 ~105 ~0 ~50 dirt 0  
fill ~8 ~0 ~51 ~105 ~0 ~51 dirt 0  
fill ~8 ~0 ~52 ~105 ~0 ~52 dirt 0  
fill ~8 ~0 ~53 ~105 ~0 ~53 dirt 0  
fill ~8 ~0 ~54 ~105 ~0 ~54 dirt 0  
fill ~8 ~0 ~55 ~105 ~0 ~55 dirt 0  
fill ~8 ~0 ~56 ~105 ~0 ~56 dirt 0  
fill ~8 ~0 ~57 ~105 ~0 ~57 dirt 0  
fill ~8 ~0 ~58 ~105 ~0 ~58 dirt 0  
fill ~8 ~0 ~59 ~105 ~0 ~59 dirt 0  
fill ~8 ~0 ~60 ~105 ~0 ~60 dirt 0  
fill ~8 ~0 ~61 ~105 ~0 ~61 dirt 0  
fill ~8 ~0 ~62 ~105 ~0 ~62 dirt 0  
fill ~8 ~0 ~63 ~105 ~0 ~63 dirt 0  
fill ~8 ~0 ~64 ~105 ~0 ~64 dirt 0  
fill ~8 ~0 ~65 ~105 ~0 ~65 dirt 0  
fill ~8 ~0 ~66 ~105 ~0 ~66 dirt 0  
fill ~8 ~0 ~67 ~105 ~0 ~67 dirt 0  
fill ~8 ~0 ~68 ~105 ~0 ~68 dirt 0  
fill ~8 ~0 ~69 ~105 ~0 ~69 dirt 0  
fill ~8 ~0 ~70 ~105 ~0 ~70 dirt 0  
fill ~8 ~0 ~71 ~105 ~0 ~71 dirt 0  
fill ~8 ~0 ~72 ~105 ~0 ~72 dirt 0  
fill ~8 ~0 ~73 ~105 ~0 ~73 dirt 0  
fill ~8 ~0 ~74 ~105 ~0 ~74 dirt 0  
fill ~8 ~0 ~75 ~105 ~0 ~75 dirt 0  
fill ~8 ~0 ~76 ~105 ~0 ~76 dirt 0  
fill ~8 ~0 ~77 ~105 ~0 ~77 dirt 0  
fill ~8 ~0 ~78 ~105 ~0 ~78 dirt 0  
fill ~8 ~0 ~79 ~105 ~0 ~79 dirt 0  
fill ~8 ~0 ~80 ~105 ~0 ~80 dirt 0  
fill ~8 ~0 ~81 ~105 ~0 ~81 dirt 0  
fill ~8 ~0 ~82 ~105 ~0 ~82 dirt 0  
fill ~8 ~0 ~83 ~105 ~0 ~83 dirt 0  
fill ~8 ~0 ~84 ~105 ~0 ~84 dirt 0  
fill ~8 ~0 ~85 ~105 ~0 ~85 dirt 0  
fill ~8 ~0 ~86 ~105 ~0 ~86 dirt 0  
fill ~8 ~0 ~87 ~105 ~0 ~87 dirt 0  
fill ~8 ~0 ~88 ~105 ~0 ~88 dirt 0  
fill ~8 ~0 ~89 ~105 ~0 ~89 dirt 0  
fill ~8 ~0 ~90 ~105 ~0 ~90 dirt 0  
fill ~8 ~0 ~91 ~105 ~0 ~91 dirt 0  
fill ~8 ~0 ~92 ~105 ~0 ~92 dirt 0  
fill ~8 ~0 ~93 ~105 ~0 ~93 dirt 0  
fill ~8 ~0 ~94 ~105 ~0 ~94 dirt 0  
fill ~8 ~0 ~95 ~105 ~0 ~95 dirt 0  
fill ~8 ~0 ~96 ~105 ~0 ~96 dirt 0  
fill ~8 ~0 ~97 ~105 ~0 ~97 dirt 0  
fill ~8 ~0 ~98 ~105 ~0 ~98 dirt 0  
fill ~8 ~0 ~99 ~105 ~0 ~99 dirt 0  
fill ~8 ~0 ~100 ~105 ~0 ~100 dirt 0  
fill ~8 ~0 ~101 ~105 ~0 ~101 dirt 0  
fill ~8 ~0 ~102 ~105 ~0 ~102 dirt 0  
fill ~8 ~0 ~103 ~105 ~0 ~103 dirt 0  
fill ~8 ~0 ~104 ~105 ~0 ~104 dirt 0  
fill ~8 ~0 ~105 ~105 ~0 ~105 dirt 0  
fill ~8 ~0 ~106 ~105 ~0 ~106 dirt 0 
setblock ~8 ~0 ~109 tallgrass 1  
fill ~9 ~0 ~5 ~12 ~0 ~5 vine 1  
fill ~9 ~0 ~109 ~9 ~2 ~109 vine 4  
fill ~10 ~0 ~109 ~16 ~0 ~109 tallgrass 1  
fill ~13 ~0 ~4 ~13 ~0 ~5 tallgrass 1  
fill ~14 ~0 ~5 ~16 ~0 ~5 tallgrass 1 
setblock ~15 ~0 ~4 tallgrass 1  
fill ~17 ~0 ~109 ~19 ~0 ~109 vine 4 
setblock ~18 ~0 ~5 vine 1  
fill ~19 ~0 ~5 ~24 ~0 ~5 tallgrass 1  
fill ~20 ~0 ~4 ~21 ~0 ~4 tallgrass 1  
fill ~22 ~0 ~109 ~22 ~2 ~109 vine 4 
setblock ~23 ~0 ~4 tallgrass 1  
fill ~23 ~0 ~109 ~30 ~0 ~109 tallgrass 1  
fill ~27 ~0 ~5 ~27 ~2 ~5 vine 1 
setblock ~27 ~0 ~112 stone_brick_stairs 1 
setblock ~28 ~0 ~5 tallgrass 1  
fill ~28 ~0 ~110 ~29 ~0 ~110 stone_slab 0  
fill ~29 ~0 ~5 ~30 ~0 ~5 vine 1 
setblock ~29 ~0 ~112 stone_slab 0  
fill ~31 ~0 ~5 ~32 ~0 ~5 tallgrass 1  
fill ~32 ~0 ~109 ~32 ~0 ~110 tallgrass 1  
fill ~33 ~0 ~5 ~34 ~0 ~5 vine 1  
fill ~33 ~0 ~109 ~34 ~0 ~109 vine 4 
setblock ~34 ~0 ~110 tallgrass 1  
fill ~35 ~0 ~5 ~39 ~0 ~5 tallgrass 1  
fill ~35 ~0 ~109 ~37 ~0 ~109 tallgrass 1 
setblock ~38 ~0 ~109 vine 4 
setblock ~39 ~0 ~109 tallgrass 1  
fill ~40 ~0 ~5 ~40 ~2 ~5 vine 1  
fill ~40 ~0 ~109 ~40 ~2 ~109 vine 4  
fill ~41 ~0 ~5 ~42 ~0 ~5 tallgrass 1  
fill ~41 ~0 ~109 ~42 ~0 ~109 tallgrass 1  
fill ~41 ~0 ~110 ~42 ~0 ~110 tallgrass 1 
setblock ~42 ~0 ~3 tallgrass 1  
fill ~42 ~0 ~4 ~42 ~2 ~4 vine 8 
setblock ~42 ~0 ~108 stonebrick 0  
fill ~42 ~0 ~111 ~42 ~0 ~112 tallgrass 1 
setblock ~43 ~0 ~1 tallgrass 1  
fill ~43 ~0 ~2 ~44 ~0 ~2 stonebrick 0  
fill ~43 ~0 ~3 ~44 ~0 ~3 stonebrick 0  
fill ~43 ~0 ~4 ~70 ~0 ~4 stonebrick 0  
fill ~43 ~0 ~5 ~70 ~0 ~5 stonebrick 0  
fill ~43 ~0 ~108 ~107 ~0 ~108 double_stone_slab 5  
fill ~43 ~0 ~109 ~70 ~0 ~109 stonebrick 0  
fill ~43 ~0 ~110 ~70 ~0 ~110 stonebrick 0  
fill ~43 ~0 ~111 ~44 ~0 ~111 stonebrick 0  
fill ~43 ~0 ~112 ~44 ~0 ~112 stonebrick 0  
fill ~43 ~0 ~113 ~44 ~0 ~113 tallgrass 1 
setblock ~44 ~0 ~1 vine 1  
fill ~45 ~0 ~1 ~45 ~0 ~2 tallgrass 1  
fill ~45 ~0 ~3 ~68 ~0 ~3 stone_brick_stairs 2  
fill ~45 ~0 ~111 ~64 ~0 ~111 stone_brick_stairs 3  
fill ~45 ~0 ~112 ~46 ~0 ~112 tallgrass 1 
setblock ~48 ~0 ~112 tallgrass 1  
fill ~52 ~0 ~2 ~53 ~0 ~2 tallgrass 1  
fill ~52 ~0 ~112 ~53 ~0 ~112 tallgrass 1 
setblock ~57 ~0 ~112 tallgrass 1 
setblock ~63 ~0 ~112 tallgrass 1 
setblock ~65 ~0 ~2 tallgrass 1  
fill ~66 ~0 ~111 ~68 ~0 ~111 stone_brick_stairs 3 
setblock ~66 ~0 ~113 stone_brick_stairs 0 
setblock ~68 ~0 ~112 tallgrass 1 
setblock ~69 ~0 ~1 tallgrass 1  
fill ~69 ~0 ~2 ~70 ~0 ~2 stonebrick 0  
fill ~69 ~0 ~3 ~70 ~0 ~3 stonebrick 0  
fill ~69 ~0 ~111 ~70 ~0 ~111 stonebrick 0  
fill ~69 ~0 ~112 ~70 ~0 ~112 stonebrick 0  
fill ~69 ~0 ~113 ~70 ~0 ~113 tallgrass 1 
setblock ~71 ~0 ~2 tallgrass 1  
fill ~71 ~0 ~4 ~72 ~0 ~4 tallgrass 1  
fill ~71 ~0 ~5 ~71 ~2 ~5 vine 2  
fill ~71 ~0 ~109 ~72 ~0 ~109 tallgrass 1  
fill ~71 ~0 ~110 ~72 ~0 ~110 tallgrass 1  
fill ~71 ~0 ~111 ~72 ~0 ~111 tallgrass 1 
setblock ~72 ~0 ~3 tallgrass 1 
setblock ~72 ~0 ~5 tallgrass 1 
setblock ~73 ~0 ~112 tallgrass 1 
setblock ~74 ~0 ~5 tallgrass 1  
fill ~74 ~0 ~109 ~74 ~2 ~109 vine 4 
setblock ~75 ~0 ~5 vine 1  
fill ~75 ~0 ~109 ~78 ~0 ~109 tallgrass 1 
setblock ~76 ~0 ~5 tallgrass 1 
setblock ~79 ~0 ~5 tallgrass 1  
fill ~80 ~0 ~5 ~81 ~0 ~5 vine 1 
setblock ~82 ~0 ~109 tallgrass 1  
fill ~83 ~0 ~109 ~84 ~0 ~109 vine 4  
fill ~85 ~0 ~5 ~85 ~2 ~5 vine 1 
setblock ~85 ~0 ~109 tallgrass 1 
setblock ~86 ~0 ~5 tallgrass 1  
fill ~86 ~0 ~109 ~89 ~0 ~109 vine 4  
fill ~87 ~0 ~5 ~87 ~2 ~5 vine 1 
setblock ~87 ~0 ~110 stone_slab 0 
setblock ~89 ~0 ~4 stone_slab 0  
fill ~89 ~0 ~5 ~90 ~0 ~5 tallgrass 1  
fill ~90 ~0 ~109 ~95 ~0 ~109 tallgrass 1 
setblock ~91 ~0 ~5 stone_slab 0  
fill ~92 ~0 ~5 ~92 ~2 ~5 vine 1 
setblock ~93 ~0 ~5 tallgrass 1  
fill ~95 ~0 ~5 ~96 ~0 ~5 tallgrass 1  
fill ~96 ~0 ~109 ~97 ~0 ~109 vine 4  
fill ~97 ~0 ~5 ~98 ~0 ~5 vine 1 
setblock ~98 ~0 ~109 tallgrass 1  
fill ~99 ~0 ~109 ~101 ~0 ~109 vine 4  
fill ~100 ~0 ~5 ~103 ~0 ~5 tallgrass 1  
fill ~102 ~0 ~109 ~104 ~0 ~109 tallgrass 1  
fill ~104 ~0 ~5 ~104 ~2 ~5 vine 1 
setblock ~105 ~0 ~5 tallgrass 1  
fill ~105 ~0 ~109 ~107 ~0 ~109 vine 4  
fill ~106 ~0 ~8 ~107 ~0 ~8 double_stone_slab 5  
fill ~106 ~0 ~9 ~107 ~0 ~9 double_stone_slab 5  
fill ~106 ~0 ~10 ~107 ~0 ~10 double_stone_slab 5  
fill ~106 ~0 ~11 ~107 ~0 ~11 double_stone_slab 5  
fill ~106 ~0 ~12 ~107 ~0 ~12 double_stone_slab 5  
fill ~106 ~0 ~13 ~107 ~0 ~13 double_stone_slab 5  
fill ~106 ~0 ~14 ~107 ~0 ~14 double_stone_slab 5  
fill ~106 ~0 ~15 ~107 ~0 ~15 double_stone_slab 5  
fill ~106 ~0 ~16 ~107 ~0 ~16 double_stone_slab 5  
fill ~106 ~0 ~17 ~107 ~0 ~17 double_stone_slab 5  
fill ~106 ~0 ~18 ~107 ~0 ~18 double_stone_slab 5  
fill ~106 ~0 ~19 ~107 ~0 ~19 double_stone_slab 5  
fill ~106 ~0 ~20 ~107 ~0 ~20 double_stone_slab 5  
fill ~106 ~0 ~21 ~107 ~0 ~21 double_stone_slab 5  
fill ~106 ~0 ~22 ~107 ~0 ~22 double_stone_slab 5  
fill ~106 ~0 ~23 ~107 ~0 ~23 double_stone_slab 5  
fill ~106 ~0 ~24 ~107 ~0 ~24 double_stone_slab 5  
fill ~106 ~0 ~25 ~107 ~0 ~25 double_stone_slab 5  
fill ~106 ~0 ~26 ~107 ~0 ~26 double_stone_slab 5  
fill ~106 ~0 ~27 ~107 ~0 ~27 double_stone_slab 5  
fill ~106 ~0 ~28 ~107 ~0 ~28 double_stone_slab 5  
fill ~106 ~0 ~29 ~107 ~0 ~29 double_stone_slab 5  
fill ~106 ~0 ~30 ~107 ~0 ~30 double_stone_slab 5  
fill ~106 ~0 ~31 ~107 ~0 ~31 double_stone_slab 5  
fill ~106 ~0 ~32 ~107 ~0 ~32 double_stone_slab 5  
fill ~106 ~0 ~33 ~107 ~0 ~33 double_stone_slab 5  
fill ~106 ~0 ~34 ~107 ~0 ~34 double_stone_slab 5  
fill ~106 ~0 ~35 ~107 ~0 ~35 double_stone_slab 5  
fill ~106 ~0 ~36 ~107 ~0 ~36 double_stone_slab 5  
fill ~106 ~0 ~37 ~107 ~0 ~37 double_stone_slab 5  
fill ~106 ~0 ~38 ~107 ~0 ~38 double_stone_slab 5  
fill ~106 ~0 ~39 ~107 ~0 ~39 double_stone_slab 5  
fill ~106 ~0 ~40 ~107 ~0 ~40 double_stone_slab 5  
fill ~106 ~0 ~41 ~107 ~0 ~41 double_stone_slab 5  
fill ~106 ~0 ~42 ~107 ~0 ~42 double_stone_slab 5  
fill ~106 ~0 ~43 ~107 ~0 ~43 double_stone_slab 5  
fill ~106 ~0 ~44 ~107 ~0 ~44 double_stone_slab 5  
fill ~106 ~0 ~45 ~107 ~0 ~45 double_stone_slab 5  
fill ~106 ~0 ~46 ~107 ~0 ~46 double_stone_slab 5  
fill ~106 ~0 ~47 ~107 ~0 ~47 double_stone_slab 5  
fill ~106 ~0 ~48 ~107 ~0 ~48 double_stone_slab 5  
fill ~106 ~0 ~49 ~107 ~0 ~49 double_stone_slab 5  
fill ~106 ~0 ~50 ~107 ~0 ~50 double_stone_slab 5  
fill ~106 ~0 ~51 ~107 ~0 ~51 double_stone_slab 5  
fill ~106 ~0 ~52 ~107 ~0 ~52 double_stone_slab 5  
fill ~106 ~0 ~53 ~107 ~0 ~53 double_stone_slab 5  
fill ~106 ~0 ~54 ~107 ~0 ~54 double_stone_slab 5  
fill ~106 ~0 ~55 ~107 ~0 ~55 double_stone_slab 5  
fill ~106 ~0 ~56 ~107 ~0 ~56 double_stone_slab 5  
fill ~106 ~0 ~57 ~107 ~0 ~57 double_stone_slab 5  
fill ~106 ~0 ~58 ~107 ~0 ~58 double_stone_slab 5  
fill ~106 ~0 ~59 ~107 ~0 ~59 double_stone_slab 5  
fill ~106 ~0 ~60 ~107 ~0 ~60 double_stone_slab 5  
fill ~106 ~0 ~61 ~107 ~0 ~61 double_stone_slab 5  
fill ~106 ~0 ~62 ~107 ~0 ~62 double_stone_slab 5  
fill ~106 ~0 ~63 ~107 ~0 ~63 double_stone_slab 5  
fill ~106 ~0 ~64 ~107 ~0 ~64 double_stone_slab 5  
fill ~106 ~0 ~65 ~107 ~0 ~65 double_stone_slab 5  
fill ~106 ~0 ~66 ~107 ~0 ~66 double_stone_slab 5  
fill ~106 ~0 ~67 ~107 ~0 ~67 double_stone_slab 5  
fill ~106 ~0 ~68 ~107 ~0 ~68 double_stone_slab 5  
fill ~106 ~0 ~69 ~107 ~0 ~69 double_stone_slab 5  
fill ~106 ~0 ~70 ~107 ~0 ~70 double_stone_slab 5  
fill ~106 ~0 ~71 ~107 ~0 ~71 stonebrick 0  
fill ~106 ~0 ~72 ~107 ~0 ~72 double_stone_slab 5  
fill ~106 ~0 ~73 ~107 ~0 ~73 double_stone_slab 5  
fill ~106 ~0 ~74 ~107 ~0 ~74 double_stone_slab 5  
fill ~106 ~0 ~75 ~107 ~0 ~75 double_stone_slab 5  
fill ~106 ~0 ~76 ~107 ~0 ~76 double_stone_slab 5  
fill ~106 ~0 ~77 ~107 ~0 ~77 double_stone_slab 5  
fill ~106 ~0 ~78 ~107 ~0 ~78 double_stone_slab 5  
fill ~106 ~0 ~79 ~107 ~0 ~79 double_stone_slab 5  
fill ~106 ~0 ~80 ~107 ~0 ~80 double_stone_slab 5  
fill ~106 ~0 ~81 ~107 ~0 ~81 double_stone_slab 5  
fill ~106 ~0 ~82 ~107 ~0 ~82 double_stone_slab 5  
fill ~106 ~0 ~83 ~107 ~0 ~83 double_stone_slab 5  
fill ~106 ~0 ~84 ~107 ~0 ~84 double_stone_slab 5  
fill ~106 ~0 ~85 ~107 ~0 ~85 double_stone_slab 5  
fill ~106 ~0 ~86 ~107 ~0 ~86 double_stone_slab 5  
fill ~106 ~0 ~87 ~107 ~0 ~87 double_stone_slab 5  
fill ~106 ~0 ~88 ~107 ~0 ~88 double_stone_slab 5  
fill ~106 ~0 ~89 ~107 ~0 ~89 double_stone_slab 5  
fill ~106 ~0 ~90 ~107 ~0 ~90 double_stone_slab 5  
fill ~106 ~0 ~91 ~107 ~0 ~91 double_stone_slab 5  
fill ~106 ~0 ~92 ~107 ~0 ~92 double_stone_slab 5  
fill ~106 ~0 ~93 ~107 ~0 ~93 double_stone_slab 5  
fill ~106 ~0 ~94 ~107 ~0 ~94 double_stone_slab 5  
fill ~106 ~0 ~95 ~107 ~0 ~95 double_stone_slab 5  
fill ~106 ~0 ~96 ~107 ~0 ~96 double_stone_slab 5  
fill ~106 ~0 ~97 ~107 ~0 ~97 double_stone_slab 5  
fill ~106 ~0 ~98 ~107 ~0 ~98 double_stone_slab 5  
fill ~106 ~0 ~99 ~107 ~0 ~99 double_stone_slab 5  
fill ~106 ~0 ~100 ~107 ~0 ~100 double_stone_slab 5  
fill ~106 ~0 ~101 ~107 ~0 ~101 double_stone_slab 5  
fill ~106 ~0 ~102 ~107 ~0 ~102 double_stone_slab 5  
fill ~106 ~0 ~103 ~107 ~0 ~103 double_stone_slab 5  
fill ~106 ~0 ~104 ~107 ~0 ~104 double_stone_slab 5  
fill ~106 ~0 ~105 ~107 ~0 ~105 double_stone_slab 5  
fill ~106 ~0 ~106 ~107 ~0 ~106 double_stone_slab 5 
setblock ~108 ~0 ~5 tallgrass 1  
fill ~108 ~0 ~6 ~108 ~2 ~6 vine 2  
fill ~108 ~0 ~7 ~108 ~2 ~7 vine 2  
fill ~108 ~0 ~8 ~108 ~2 ~8 vine 2  
fill ~108 ~0 ~9 ~109 ~0 ~9 tallgrass 1  
fill ~108 ~0 ~10 ~108 ~2 ~10 vine 2  
fill ~108 ~0 ~11 ~108 ~2 ~11 vine 2  
fill ~108 ~0 ~12 ~108 ~2 ~12 vine 2  
fill ~108 ~0 ~13 ~108 ~0 ~14 vine 2  
fill ~108 ~0 ~17 ~108 ~0 ~18 vine 2 
setblock ~108 ~0 ~19 tallgrass 1  
fill ~108 ~0 ~20 ~108 ~2 ~20 vine 2 
setblock ~108 ~0 ~21 tallgrass 1 
setblock ~108 ~0 ~24 tallgrass 1  
fill ~108 ~0 ~25 ~108 ~0 ~26 vine 2  
fill ~108 ~0 ~27 ~108 ~0 ~29 tallgrass 1 
setblock ~108 ~0 ~31 tallgrass 1  
fill ~108 ~0 ~32 ~108 ~2 ~32 vine 2  
fill ~108 ~0 ~33 ~108 ~2 ~33 vine 2  
fill ~108 ~0 ~34 ~108 ~2 ~34 vine 2 
setblock ~108 ~0 ~36 tallgrass 1 
setblock ~108 ~0 ~38 tallgrass 1 
setblock ~108 ~0 ~39 vine 2  
fill ~108 ~0 ~40 ~109 ~0 ~40 tallgrass 1  
fill ~108 ~0 ~41 ~110 ~0 ~41 tallgrass 1  
fill ~108 ~0 ~42 ~111 ~0 ~42 tallgrass 1  
fill ~108 ~0 ~43 ~111 ~0 ~43 stonebrick 0  
fill ~108 ~0 ~44 ~111 ~0 ~44 stonebrick 0  
fill ~108 ~0 ~45 ~109 ~0 ~45 stonebrick 0  
fill ~108 ~0 ~46 ~109 ~0 ~46 stonebrick 0  
fill ~108 ~0 ~47 ~109 ~0 ~47 stonebrick 0  
fill ~108 ~0 ~48 ~109 ~0 ~48 stonebrick 0  
fill ~108 ~0 ~49 ~109 ~0 ~49 stonebrick 0  
fill ~108 ~0 ~50 ~109 ~0 ~50 stonebrick 0  
fill ~108 ~0 ~51 ~109 ~0 ~51 stonebrick 0  
fill ~108 ~0 ~52 ~109 ~0 ~52 stonebrick 0  
fill ~108 ~0 ~53 ~109 ~0 ~53 stonebrick 0  
fill ~108 ~0 ~54 ~109 ~0 ~54 stonebrick 0  
fill ~108 ~0 ~55 ~109 ~0 ~55 stonebrick 0  
fill ~108 ~0 ~56 ~109 ~0 ~56 stonebrick 0  
fill ~108 ~0 ~57 ~109 ~0 ~57 stonebrick 0  
fill ~108 ~0 ~58 ~109 ~0 ~58 stonebrick 0  
fill ~108 ~0 ~59 ~109 ~0 ~59 stonebrick 0  
fill ~108 ~0 ~60 ~109 ~0 ~60 stonebrick 0  
fill ~108 ~0 ~61 ~109 ~0 ~61 stonebrick 0  
fill ~108 ~0 ~62 ~109 ~0 ~62 stonebrick 0  
fill ~108 ~0 ~63 ~109 ~0 ~63 stonebrick 0  
fill ~108 ~0 ~64 ~109 ~0 ~64 stonebrick 0  
fill ~108 ~0 ~65 ~109 ~0 ~65 stonebrick 0  
fill ~108 ~0 ~66 ~109 ~0 ~66 stonebrick 0  
fill ~108 ~0 ~67 ~109 ~0 ~67 stonebrick 0  
fill ~108 ~0 ~68 ~109 ~0 ~68 stonebrick 0  
fill ~108 ~0 ~69 ~111 ~0 ~69 stonebrick 0  
fill ~108 ~0 ~70 ~111 ~0 ~70 stonebrick 0  
fill ~108 ~0 ~71 ~110 ~0 ~71 tallgrass 1  
fill ~108 ~0 ~72 ~110 ~0 ~72 tallgrass 1  
fill ~108 ~0 ~73 ~108 ~0 ~71 tallgrass 1  
fill ~108 ~0 ~74 ~108 ~2 ~74 vine 2  
fill ~108 ~0 ~75 ~108 ~2 ~75 vine 2  
fill ~108 ~0 ~76 ~108 ~0 ~77 vine 2  
fill ~108 ~0 ~78 ~108 ~0 ~79 tallgrass 1  
fill ~108 ~0 ~81 ~108 ~2 ~81 vine 2  
fill ~108 ~0 ~83 ~108 ~0 ~84 vine 2  
fill ~108 ~0 ~85 ~108 ~0 ~89 tallgrass 1 
setblock ~108 ~0 ~91 tallgrass 1 
setblock ~108 ~0 ~92 vine 2  
fill ~108 ~0 ~93 ~108 ~0 ~96 tallgrass 1  
fill ~108 ~0 ~97 ~108 ~2 ~97 vine 2  
fill ~108 ~0 ~98 ~108 ~0 ~99 tallgrass 1  
fill ~108 ~0 ~100 ~108 ~2 ~100 vine 2 
setblock ~108 ~0 ~101 tallgrass 1  
fill ~108 ~0 ~102 ~108 ~0 ~103 vine 2  
fill ~108 ~0 ~104 ~108 ~0 ~105 tallgrass 1  
fill ~108 ~0 ~107 ~108 ~2 ~107 vine 2  
fill ~108 ~0 ~108 ~108 ~2 ~108 vine 2  
fill ~108 ~0 ~109 ~108 ~0 ~110 tallgrass 1 
setblock ~109 ~0 ~7 stone_slab 0 
setblock ~109 ~0 ~16 stone_slab 0 
setblock ~109 ~0 ~74 tallgrass 1  
fill ~110 ~0 ~45 ~110 ~0 ~68 stone_brick_stairs 1 
setblock ~111 ~0 ~45 tallgrass 1 
setblock ~111 ~0 ~56 tallgrass 1  
fill ~111 ~0 ~66 ~111 ~0 ~67 tallgrass 1  
fill ~111 ~0 ~68 ~111 ~2 ~68 vine 1  
fill ~111 ~0 ~71 ~111 ~2 ~71 vine 4 
setblock ~112 ~0 ~43 tallgrass 1 
setblock ~112 ~0 ~44 vine 2 
setblock ~112 ~0 ~63 stone_slab 0 
setblock ~112 ~0 ~70 tallgrass 1  
fill ~1 ~1 ~44 ~1 ~2 ~44 vine 8  
fill ~1 ~1 ~69 ~1 ~2 ~69 vine 8  
fill ~2 ~1 ~43 ~2 ~1 ~44 stone_brick_stairs 0  
fill ~2 ~1 ~69 ~2 ~1 ~70 stone_brick_stairs 0  
fill ~3 ~1 ~43 ~5 ~1 ~43 stone_brick_stairs 2 
setblock ~3 ~1 ~44 stone_brick_stairs 3  
fill ~3 ~1 ~45 ~3 ~2 ~45 vine 4  
fill ~3 ~1 ~68 ~3 ~2 ~68 vine 1 
setblock ~3 ~1 ~69 stone_brick_stairs 2  
fill ~3 ~1 ~70 ~5 ~1 ~70 stone_brick_stairs 3  
fill ~4 ~1 ~42 ~4 ~2 ~42 vine 1  
fill ~4 ~1 ~44 ~5 ~1 ~44 stonebrick 0  
fill ~4 ~1 ~45 ~4 ~1 ~68 stone_brick_stairs 0  
fill ~4 ~1 ~69 ~5 ~1 ~69 stonebrick 0  
fill ~4 ~1 ~71 ~5 ~1 ~71 vine 4  
fill ~5 ~1 ~6 ~5 ~2 ~6 vine 8  
fill ~5 ~1 ~7 ~5 ~2 ~7 vine 8  
fill ~5 ~1 ~11 ~5 ~2 ~11 vine 8  
fill ~5 ~1 ~12 ~5 ~2 ~12 vine 8  
fill ~5 ~1 ~17 ~5 ~2 ~17 vine 8  
fill ~5 ~1 ~19 ~5 ~2 ~19 vine 8  
fill ~5 ~1 ~28 ~5 ~2 ~28 vine 8  
fill ~5 ~1 ~29 ~5 ~2 ~29 vine 8  
fill ~5 ~1 ~31 ~5 ~2 ~31 vine 8  
fill ~5 ~1 ~36 ~5 ~2 ~36 vine 8  
fill ~5 ~1 ~37 ~5 ~2 ~37 vine 8  
fill ~5 ~1 ~41 ~5 ~2 ~41 vine 8  
fill ~5 ~1 ~45 ~5 ~1 ~69 stonebrick 0  
fill ~5 ~1 ~74 ~5 ~2 ~74 vine 8  
fill ~5 ~1 ~78 ~5 ~2 ~78 vine 8  
fill ~5 ~1 ~85 ~5 ~2 ~85 vine 8  
fill ~5 ~1 ~91 ~5 ~2 ~91 vine 8  
fill ~5 ~1 ~95 ~5 ~2 ~95 vine 8  
fill ~5 ~1 ~99 ~5 ~2 ~99 vine 8  
fill ~5 ~1 ~100 ~5 ~2 ~100 vine 8  
fill ~5 ~1 ~103 ~5 ~2 ~103 vine 8  
fill ~5 ~1 ~104 ~5 ~2 ~104 vine 8  
fill ~5 ~1 ~106 ~5 ~2 ~106 vine 8  
fill ~5 ~1 ~107 ~5 ~2 ~107 vine 8 
setblock ~6 ~1 ~6 stone_slab 5  
fill ~6 ~1 ~7 ~6 ~1 ~42 stone_brick_stairs 0 
setblock ~6 ~1 ~43 stone_slab 5  
fill ~6 ~1 ~44 ~7 ~1 ~44 double_stone_slab 5  
fill ~6 ~1 ~45 ~7 ~1 ~45 double_stone_slab 5  
fill ~6 ~1 ~46 ~7 ~1 ~46 double_stone_slab 5  
fill ~6 ~1 ~47 ~7 ~1 ~47 double_stone_slab 5  
fill ~6 ~1 ~48 ~7 ~1 ~48 double_stone_slab 5  
fill ~6 ~1 ~49 ~7 ~1 ~49 double_stone_slab 5  
fill ~6 ~1 ~50 ~7 ~1 ~50 double_stone_slab 5  
fill ~6 ~1 ~51 ~7 ~1 ~51 double_stone_slab 5  
fill ~6 ~1 ~52 ~7 ~1 ~52 double_stone_slab 5  
fill ~6 ~1 ~53 ~7 ~1 ~53 double_stone_slab 5  
fill ~6 ~1 ~54 ~7 ~1 ~54 double_stone_slab 5  
fill ~6 ~1 ~55 ~7 ~1 ~55 double_stone_slab 5  
fill ~6 ~1 ~56 ~7 ~1 ~56 double_stone_slab 5  
fill ~6 ~1 ~57 ~7 ~1 ~57 double_stone_slab 5  
fill ~6 ~1 ~58 ~7 ~1 ~58 double_stone_slab 5  
fill ~6 ~1 ~59 ~7 ~1 ~59 double_stone_slab 5  
fill ~6 ~1 ~60 ~7 ~1 ~60 double_stone_slab 5  
fill ~6 ~1 ~61 ~7 ~1 ~61 double_stone_slab 5  
fill ~6 ~1 ~62 ~7 ~1 ~62 double_stone_slab 5  
fill ~6 ~1 ~63 ~7 ~1 ~63 double_stone_slab 5  
fill ~6 ~1 ~64 ~7 ~1 ~64 double_stone_slab 5  
fill ~6 ~1 ~65 ~7 ~1 ~65 double_stone_slab 5  
fill ~6 ~1 ~66 ~7 ~1 ~66 double_stone_slab 5  
fill ~6 ~1 ~67 ~7 ~1 ~67 double_stone_slab 5  
fill ~6 ~1 ~68 ~7 ~1 ~68 double_stone_slab 5  
fill ~6 ~1 ~69 ~7 ~1 ~69 double_stone_slab 5 
setblock ~6 ~1 ~70 stone_slab 5  
fill ~6 ~1 ~71 ~6 ~1 ~107 stone_brick_stairs 0 
setblock ~6 ~1 ~108 stone_slab 5  
fill ~7 ~1 ~6 ~42 ~1 ~6 stone_brick_stairs 2  
fill ~7 ~1 ~7 ~106 ~1 ~7 double_stone_slab 5  
fill ~7 ~1 ~8 ~7 ~3 ~8 double_stone_slab 5  
fill ~7 ~1 ~9 ~7 ~3 ~9 double_stone_slab 5  
fill ~7 ~1 ~10 ~7 ~3 ~10 double_stone_slab 5  
fill ~7 ~1 ~11 ~7 ~3 ~11 double_stone_slab 5  
fill ~7 ~1 ~12 ~7 ~3 ~12 double_stone_slab 5  
fill ~7 ~1 ~13 ~7 ~3 ~13 double_stone_slab 5  
fill ~7 ~1 ~14 ~7 ~3 ~14 double_stone_slab 5  
fill ~7 ~1 ~15 ~7 ~3 ~15 double_stone_slab 5  
fill ~7 ~1 ~16 ~7 ~3 ~16 double_stone_slab 5  
fill ~7 ~1 ~17 ~7 ~3 ~17 double_stone_slab 5  
fill ~7 ~1 ~18 ~7 ~3 ~18 double_stone_slab 5  
fill ~7 ~1 ~19 ~7 ~3 ~19 double_stone_slab 5  
fill ~7 ~1 ~20 ~7 ~3 ~20 double_stone_slab 5  
fill ~7 ~1 ~21 ~7 ~3 ~21 double_stone_slab 5  
fill ~7 ~1 ~22 ~7 ~3 ~22 double_stone_slab 5  
fill ~7 ~1 ~23 ~7 ~3 ~23 double_stone_slab 5  
fill ~7 ~1 ~24 ~7 ~3 ~24 double_stone_slab 5  
fill ~7 ~1 ~25 ~7 ~3 ~25 double_stone_slab 5  
fill ~7 ~1 ~26 ~7 ~3 ~26 double_stone_slab 5  
fill ~7 ~1 ~27 ~7 ~3 ~27 double_stone_slab 5  
fill ~7 ~1 ~28 ~7 ~3 ~28 double_stone_slab 5  
fill ~7 ~1 ~29 ~7 ~3 ~29 double_stone_slab 5  
fill ~7 ~1 ~30 ~7 ~3 ~30 double_stone_slab 5  
fill ~7 ~1 ~31 ~7 ~3 ~31 double_stone_slab 5  
fill ~7 ~1 ~32 ~7 ~3 ~32 double_stone_slab 5  
fill ~7 ~1 ~33 ~7 ~3 ~33 double_stone_slab 5  
fill ~7 ~1 ~34 ~7 ~3 ~34 double_stone_slab 5  
fill ~7 ~1 ~35 ~7 ~3 ~35 double_stone_slab 5  
fill ~7 ~1 ~36 ~7 ~3 ~36 double_stone_slab 5  
fill ~7 ~1 ~37 ~7 ~3 ~37 double_stone_slab 5  
fill ~7 ~1 ~38 ~7 ~3 ~38 double_stone_slab 5  
fill ~7 ~1 ~39 ~7 ~3 ~39 double_stone_slab 5  
fill ~7 ~1 ~40 ~7 ~3 ~40 double_stone_slab 5  
fill ~7 ~1 ~41 ~7 ~3 ~41 double_stone_slab 5  
fill ~7 ~1 ~42 ~7 ~3 ~42 double_stone_slab 5  
fill ~7 ~1 ~43 ~7 ~3 ~43 double_stone_slab 5  
fill ~7 ~1 ~70 ~7 ~3 ~70 double_stone_slab 5  
fill ~7 ~1 ~71 ~7 ~3 ~71 double_stone_slab 5  
fill ~7 ~1 ~72 ~7 ~3 ~72 double_stone_slab 5  
fill ~7 ~1 ~73 ~7 ~3 ~73 double_stone_slab 5  
fill ~7 ~1 ~74 ~7 ~3 ~74 double_stone_slab 5  
fill ~7 ~1 ~75 ~7 ~3 ~75 double_stone_slab 5  
fill ~7 ~1 ~76 ~7 ~3 ~76 double_stone_slab 5  
fill ~7 ~1 ~77 ~7 ~3 ~77 double_stone_slab 5  
fill ~7 ~1 ~78 ~7 ~3 ~78 double_stone_slab 5  
fill ~7 ~1 ~79 ~7 ~3 ~79 double_stone_slab 5  
fill ~7 ~1 ~80 ~7 ~3 ~80 double_stone_slab 5  
fill ~7 ~1 ~81 ~7 ~3 ~81 double_stone_slab 5  
fill ~7 ~1 ~82 ~7 ~3 ~82 double_stone_slab 5  
fill ~7 ~1 ~83 ~7 ~3 ~83 double_stone_slab 5  
fill ~7 ~1 ~84 ~7 ~3 ~84 double_stone_slab 5  
fill ~7 ~1 ~85 ~7 ~3 ~85 double_stone_slab 5  
fill ~7 ~1 ~86 ~7 ~3 ~86 double_stone_slab 5  
fill ~7 ~1 ~87 ~7 ~3 ~87 double_stone_slab 5  
fill ~7 ~1 ~88 ~7 ~3 ~88 double_stone_slab 5  
fill ~7 ~1 ~89 ~7 ~3 ~89 double_stone_slab 5  
fill ~7 ~1 ~90 ~7 ~3 ~90 double_stone_slab 5  
fill ~7 ~1 ~91 ~7 ~3 ~91 double_stone_slab 5  
fill ~7 ~1 ~92 ~7 ~3 ~92 double_stone_slab 5  
fill ~7 ~1 ~93 ~7 ~3 ~93 double_stone_slab 5  
fill ~7 ~1 ~94 ~7 ~3 ~94 double_stone_slab 5  
fill ~7 ~1 ~95 ~7 ~3 ~95 double_stone_slab 5  
fill ~7 ~1 ~96 ~7 ~3 ~96 double_stone_slab 5  
fill ~7 ~1 ~97 ~7 ~3 ~97 double_stone_slab 5  
fill ~7 ~1 ~98 ~7 ~3 ~98 double_stone_slab 5  
fill ~7 ~1 ~99 ~7 ~3 ~99 double_stone_slab 5  
fill ~7 ~1 ~100 ~7 ~3 ~100 double_stone_slab 5  
fill ~7 ~1 ~101 ~7 ~3 ~101 double_stone_slab 5  
fill ~7 ~1 ~102 ~7 ~3 ~102 double_stone_slab 5  
fill ~7 ~1 ~103 ~7 ~3 ~103 double_stone_slab 5  
fill ~7 ~1 ~104 ~7 ~3 ~104 double_stone_slab 5  
fill ~7 ~1 ~105 ~7 ~3 ~105 double_stone_slab 5  
fill ~7 ~1 ~106 ~7 ~3 ~106 double_stone_slab 5  
fill ~7 ~1 ~107 ~106 ~1 ~107 double_stone_slab 5  
fill ~7 ~1 ~108 ~42 ~1 ~108 stone_brick_stairs 3  
fill ~7 ~1 ~109 ~7 ~2 ~109 vine 4  
fill ~8 ~1 ~5 ~9 ~1 ~5 vine 1  
fill ~8 ~1 ~8 ~105 ~1 ~8 dirt 0  
fill ~8 ~1 ~9 ~105 ~1 ~9 dirt 0  
fill ~8 ~1 ~10 ~105 ~1 ~10 dirt 0  
fill ~8 ~1 ~11 ~105 ~1 ~11 dirt 0  
fill ~8 ~1 ~12 ~105 ~1 ~12 dirt 0  
fill ~8 ~1 ~13 ~105 ~1 ~13 dirt 0  
fill ~8 ~1 ~14 ~105 ~1 ~14 dirt 0  
fill ~8 ~1 ~15 ~105 ~1 ~15 dirt 0  
fill ~8 ~1 ~16 ~105 ~1 ~16 dirt 0  
fill ~8 ~1 ~17 ~105 ~1 ~17 dirt 0  
fill ~8 ~1 ~18 ~105 ~1 ~18 dirt 0  
fill ~8 ~1 ~19 ~105 ~1 ~19 dirt 0  
fill ~8 ~1 ~20 ~105 ~1 ~20 dirt 0  
fill ~8 ~1 ~21 ~105 ~1 ~21 dirt 0  
fill ~8 ~1 ~22 ~105 ~1 ~22 dirt 0  
fill ~8 ~1 ~23 ~105 ~1 ~23 dirt 0  
fill ~8 ~1 ~24 ~105 ~1 ~24 dirt 0  
fill ~8 ~1 ~25 ~105 ~1 ~25 dirt 0  
fill ~8 ~1 ~26 ~105 ~1 ~26 dirt 0  
fill ~8 ~1 ~27 ~105 ~1 ~27 dirt 0  
fill ~8 ~1 ~28 ~105 ~1 ~28 dirt 0  
fill ~8 ~1 ~29 ~105 ~1 ~29 dirt 0  
fill ~8 ~1 ~30 ~105 ~1 ~30 dirt 0  
fill ~8 ~1 ~31 ~105 ~1 ~31 dirt 0  
fill ~8 ~1 ~32 ~105 ~1 ~32 dirt 0  
fill ~8 ~1 ~33 ~105 ~1 ~33 dirt 0  
fill ~8 ~1 ~34 ~105 ~1 ~34 dirt 0  
fill ~8 ~1 ~35 ~105 ~1 ~35 dirt 0  
fill ~8 ~1 ~36 ~105 ~1 ~36 dirt 0  
fill ~8 ~1 ~37 ~105 ~1 ~37 dirt 0  
fill ~8 ~1 ~38 ~105 ~1 ~38 dirt 0   
fill ~8 ~1 ~39 ~105 ~1 ~39 dirt 0  
fill ~8 ~1 ~40 ~105 ~1 ~40 dirt 0  
fill ~8 ~1 ~41 ~105 ~1 ~41 dirt 0  
fill ~8 ~1 ~42 ~105 ~1 ~42 dirt 0  
fill ~8 ~1 ~43 ~105 ~1 ~43 dirt 0  
fill ~8 ~1 ~44 ~105 ~1 ~44 dirt 0  
fill ~8 ~1 ~45 ~105 ~1 ~45 dirt 0  
fill ~8 ~1 ~46 ~105 ~1 ~46 dirt 0  
fill ~8 ~1 ~47 ~105 ~1 ~47 dirt 0  
fill ~8 ~1 ~48 ~105 ~1 ~48 dirt 0  
fill ~8 ~1 ~49 ~105 ~1 ~49 dirt 0  
fill ~8 ~1 ~50 ~105 ~1 ~50 dirt 0  
fill ~8 ~1 ~51 ~105 ~1 ~51 dirt 0  
fill ~8 ~1 ~52 ~105 ~1 ~52 dirt 0  
fill ~8 ~1 ~53 ~105 ~1 ~53 dirt 0  
fill ~8 ~1 ~54 ~105 ~1 ~54 dirt 0  
fill ~8 ~1 ~55 ~105 ~1 ~55 dirt 0  
fill ~8 ~1 ~56 ~105 ~1 ~56 dirt 0  
fill ~8 ~1 ~57 ~105 ~1 ~57 dirt 0  
fill ~8 ~1 ~58 ~105 ~1 ~58 dirt 0  
fill ~8 ~1 ~59 ~105 ~1 ~59 dirt 0  
fill ~8 ~1 ~60 ~105 ~1 ~60 dirt 0  
fill ~8 ~1 ~61 ~105 ~1 ~61 dirt 0  
fill ~8 ~1 ~62 ~105 ~1 ~62 dirt 0  
fill ~8 ~1 ~63 ~105 ~1 ~63 dirt 0  
fill ~8 ~1 ~64 ~105 ~1 ~64 dirt 0  
fill ~8 ~1 ~65 ~105 ~1 ~65 dirt 0  
fill ~8 ~1 ~66 ~105 ~1 ~66 dirt 0  
fill ~8 ~1 ~67 ~105 ~1 ~67 dirt 0  
fill ~8 ~1 ~68 ~105 ~1 ~68 dirt 0  
fill ~8 ~1 ~69 ~105 ~1 ~69 dirt 0  
fill ~8 ~1 ~70 ~105 ~1 ~70 dirt 0  
fill ~8 ~1 ~71 ~105 ~1 ~71 dirt 0  
fill ~8 ~1 ~72 ~105 ~1 ~72 dirt 0  
fill ~8 ~1 ~73 ~105 ~1 ~73 dirt 0  
fill ~8 ~1 ~74 ~105 ~1 ~74 dirt 0  
fill ~8 ~1 ~75 ~105 ~1 ~75 dirt 0  
fill ~8 ~1 ~76 ~105 ~1 ~76 dirt 0  
fill ~8 ~1 ~77 ~105 ~1 ~77 dirt 0  
fill ~8 ~1 ~78 ~105 ~1 ~78 dirt 0  
fill ~8 ~1 ~79 ~105 ~1 ~79 dirt 0  
fill ~8 ~1 ~80 ~105 ~1 ~80 dirt 0  
fill ~8 ~1 ~81 ~105 ~1 ~81 dirt 0  
fill ~8 ~1 ~82 ~105 ~1 ~82 dirt 0  
fill ~8 ~1 ~83 ~105 ~1 ~83 dirt 0  
fill ~8 ~1 ~84 ~105 ~1 ~84 dirt 0  
fill ~8 ~1 ~85 ~105 ~1 ~85 dirt 0  
fill ~8 ~1 ~86 ~105 ~1 ~86 dirt 0  
fill ~8 ~1 ~87 ~105 ~1 ~87 dirt 0  
fill ~8 ~1 ~88 ~105 ~1 ~88 dirt 0  
fill ~8 ~1 ~89 ~105 ~1 ~89 dirt 0  
fill ~8 ~1 ~90 ~105 ~1 ~90 dirt 0  
fill ~8 ~1 ~91 ~105 ~1 ~91 dirt 0  
fill ~8 ~1 ~92 ~105 ~1 ~92 dirt 0  
fill ~8 ~1 ~93 ~105 ~1 ~93 dirt 0  
fill ~8 ~1 ~94 ~105 ~1 ~94 dirt 0  
fill ~8 ~1 ~95 ~105 ~1 ~95 dirt 0  
fill ~8 ~1 ~96 ~105 ~1 ~96 dirt 0  
fill ~8 ~1 ~97 ~105 ~1 ~97 dirt 0  
fill ~8 ~1 ~98 ~105 ~1 ~98 dirt 0  
fill ~8 ~1 ~99 ~105 ~1 ~99 dirt 0  
fill ~8 ~1 ~100 ~105 ~1 ~100 dirt 0  
fill ~8 ~1 ~101 ~105 ~1 ~101 dirt 0  
fill ~8 ~1 ~102 ~105 ~1 ~102 dirt 0  
fill ~8 ~1 ~103 ~105 ~1 ~103 dirt 0  
fill ~8 ~1 ~104 ~105 ~1 ~104 dirt 0  
fill ~8 ~1 ~105 ~105 ~1 ~105 dirt 0  
fill ~8 ~1 ~106 ~105 ~1 ~106 dirt 0  
fill ~12 ~1 ~109 ~12 ~2 ~109 vine 4  
fill ~14 ~1 ~5 ~16 ~1 ~5 vine 1  
fill ~14 ~1 ~109 ~17 ~1 ~109 vine 4  
fill ~21 ~1 ~5 ~23 ~1 ~5 vine 1  
fill ~23 ~1 ~109 ~25 ~1 ~109 vine 4  
fill ~29 ~1 ~5 ~31 ~1 ~5 vine 1  
fill ~32 ~1 ~109 ~35 ~1 ~109 vine 4  
fill ~33 ~1 ~5 ~35 ~1 ~5 vine 1  
fill ~42 ~1 ~5 ~42 ~2 ~5 vine 8  
fill ~42 ~1 ~109 ~42 ~2 ~109 vine 8  
fill ~42 ~1 ~110 ~42 ~2 ~110 vine 8  
fill ~42 ~1 ~111 ~42 ~2 ~111 vine 8  
fill ~42 ~1 ~112 ~42 ~2 ~112 vine 8  
fill ~43 ~1 ~1 ~43 ~2 ~1 vine 1  
fill ~43 ~1 ~2 ~44 ~1 ~2 stone_brick_stairs 2  
fill ~43 ~1 ~3 ~43 ~1 ~5 stone_brick_stairs 0 
setblock ~43 ~1 ~6 stone_slab 5 
setblock ~43 ~1 ~108 stone_slab 5  
fill ~43 ~1 ~109 ~43 ~1 ~111 stone_brick_stairs 0  
fill ~43 ~1 ~112 ~44 ~1 ~112 stone_brick_stairs 3 
setblock ~44 ~1 ~3 stone_brick_stairs 1  
fill ~44 ~1 ~4 ~44 ~2 ~4 stonebrick 0  
fill ~44 ~1 ~5 ~69 ~1 ~5 stonebrick 0  
fill ~44 ~1 ~6 ~69 ~1 ~6 double_stone_slab 5  
fill ~44 ~1 ~108 ~69 ~1 ~108 double_stone_slab 5  
fill ~44 ~1 ~109 ~69 ~1 ~109 stonebrick 0  
fill ~44 ~1 ~110 ~44 ~2 ~110 stonebrick 0 
setblock ~44 ~1 ~111 stone_brick_stairs 1  
fill ~45 ~1 ~2 ~45 ~2 ~2 vine 2  
fill ~45 ~1 ~3 ~45 ~2 ~3 vine 2  
fill ~45 ~1 ~4 ~68 ~1 ~4 stone_brick_stairs 2  
fill ~45 ~1 ~110 ~68 ~1 ~110 stone_brick_stairs 3  
fill ~45 ~1 ~111 ~45 ~2 ~111 vine 2  
fill ~68 ~1 ~111 ~68 ~2 ~111 vine 8  
fill ~68 ~1 ~112 ~68 ~2 ~112 vine 8  
fill ~69 ~1 ~2 ~70 ~1 ~2 stone_brick_stairs 2 
setblock ~69 ~1 ~3 stone_brick_stairs 0  
fill ~69 ~1 ~4 ~69 ~2 ~4 stonebrick 0  
fill ~69 ~1 ~110 ~69 ~2 ~110 stonebrick 0 
setblock ~69 ~1 ~111 stone_brick_stairs 0  
fill ~69 ~1 ~112 ~70 ~1 ~112 stone_brick_stairs 3  
fill ~69 ~1 ~113 ~70 ~1 ~113 vine 4  
fill ~70 ~1 ~1 ~70 ~2 ~1 vine 1  
fill ~70 ~1 ~3 ~70 ~1 ~5 stone_brick_stairs 1 
setblock ~70 ~1 ~6 stone_slab 5 
setblock ~70 ~1 ~108 stone_slab 5  
fill ~70 ~1 ~109 ~70 ~1 ~111 stone_brick_stairs 1  
fill ~71 ~1 ~4 ~71 ~2 ~4 vine 2  
fill ~71 ~1 ~6 ~106 ~1 ~6 stone_brick_stairs 2  
fill ~71 ~1 ~108 ~106 ~1 ~108 stone_brick_stairs 3  
fill ~71 ~1 ~109 ~71 ~2 ~109 vine 2  
fill ~71 ~1 ~110 ~71 ~2 ~110 vine 2  
fill ~71 ~1 ~111 ~71 ~2 ~111 vine 2  
fill ~72 ~1 ~5 ~72 ~2 ~5 vine 1  
fill ~75 ~1 ~109 ~76 ~1 ~109 vine 4  
fill ~78 ~1 ~5 ~81 ~1 ~5 vine 1  
fill ~82 ~1 ~109 ~84 ~1 ~109 vine 4  
fill ~86 ~1 ~5 ~86 ~2 ~5 vine 1  
fill ~88 ~1 ~109 ~92 ~1 ~109 vine 4  
fill ~91 ~1 ~5 ~91 ~2 ~5 vine 1  
fill ~93 ~1 ~5 ~93 ~2 ~5 vine 1  
fill ~95 ~1 ~5 ~95 ~2 ~5 vine 1  
fill ~97 ~1 ~5 ~98 ~1 ~5 vine 1  
fill ~98 ~1 ~109 ~101 ~1 ~109 vine 4  
fill ~100 ~1 ~5 ~100 ~2 ~5 vine 1  
fill ~102 ~1 ~5 ~104 ~1 ~5 vine 1  
fill ~105 ~1 ~109 ~107 ~1 ~109 vine 4  
fill ~106 ~1 ~8 ~106 ~3 ~8 double_stone_slab 5  
fill ~106 ~1 ~9 ~106 ~3 ~9 double_stone_slab 5  
fill ~106 ~1 ~10 ~106 ~3 ~10 double_stone_slab 5  
fill ~106 ~1 ~11 ~106 ~3 ~11 double_stone_slab 5  
fill ~106 ~1 ~12 ~106 ~3 ~12 double_stone_slab 5  
fill ~106 ~1 ~13 ~106 ~3 ~13 double_stone_slab 5  
fill ~106 ~1 ~14 ~106 ~3 ~14 double_stone_slab 5  
fill ~106 ~1 ~15 ~106 ~3 ~15 double_stone_slab 5  
fill ~106 ~1 ~16 ~106 ~3 ~16 double_stone_slab 5  
fill ~106 ~1 ~17 ~106 ~3 ~17 double_stone_slab 5  
fill ~106 ~1 ~18 ~106 ~3 ~18 double_stone_slab 5  
fill ~106 ~1 ~19 ~106 ~3 ~19 double_stone_slab 5  
fill ~106 ~1 ~20 ~106 ~3 ~20 double_stone_slab 5  
fill ~106 ~1 ~21 ~106 ~3 ~21 double_stone_slab 5  
fill ~106 ~1 ~22 ~106 ~3 ~22 double_stone_slab 5  
fill ~106 ~1 ~23 ~106 ~3 ~23 double_stone_slab 5  
fill ~106 ~1 ~24 ~106 ~3 ~24 double_stone_slab 5  
fill ~106 ~1 ~25 ~106 ~3 ~25 double_stone_slab 5  
fill ~106 ~1 ~26 ~106 ~3 ~26 double_stone_slab 5  
fill ~106 ~1 ~27 ~106 ~3 ~27 double_stone_slab 5  
fill ~106 ~1 ~28 ~106 ~3 ~28 double_stone_slab 5  
fill ~106 ~1 ~29 ~106 ~3 ~29 double_stone_slab 5  
fill ~106 ~1 ~30 ~106 ~3 ~30 double_stone_slab 5  
fill ~106 ~1 ~31 ~106 ~3 ~31 double_stone_slab 5  
fill ~106 ~1 ~32 ~106 ~3 ~32 double_stone_slab 5  
fill ~106 ~1 ~33 ~106 ~3 ~33 double_stone_slab 5  
fill ~106 ~1 ~34 ~106 ~3 ~34 double_stone_slab 5  
fill ~106 ~1 ~35 ~106 ~3 ~35 double_stone_slab 5  
fill ~106 ~1 ~36 ~106 ~3 ~36 double_stone_slab 5  
fill ~106 ~1 ~37 ~106 ~3 ~37 double_stone_slab 5  
fill ~106 ~1 ~38 ~106 ~3 ~38 double_stone_slab 5  
fill ~106 ~1 ~39 ~106 ~3 ~39 double_stone_slab 5  
fill ~106 ~1 ~40 ~106 ~3 ~40 double_stone_slab 5  
fill ~106 ~1 ~41 ~106 ~3 ~41 double_stone_slab 5  
fill ~106 ~1 ~42 ~106 ~3 ~42 double_stone_slab 5  
fill ~106 ~1 ~43 ~106 ~3 ~43 double_stone_slab 5  
fill ~106 ~1 ~44 ~107 ~1 ~44 double_stone_slab 5  
fill ~106 ~1 ~45 ~107 ~1 ~45 double_stone_slab 5  
fill ~106 ~1 ~46 ~107 ~1 ~46 double_stone_slab 5  
fill ~106 ~1 ~47 ~107 ~1 ~47 double_stone_slab 5  
fill ~106 ~1 ~48 ~107 ~1 ~48 double_stone_slab 5  
fill ~106 ~1 ~49 ~107 ~1 ~49 double_stone_slab 5  
fill ~106 ~1 ~50 ~107 ~1 ~50 double_stone_slab 5  
fill ~106 ~1 ~51 ~107 ~1 ~51 double_stone_slab 5  
fill ~106 ~1 ~52 ~107 ~1 ~52 double_stone_slab 5  
fill ~106 ~1 ~53 ~107 ~1 ~53 double_stone_slab 5  
fill ~106 ~1 ~54 ~107 ~1 ~54 double_stone_slab 5  
fill ~106 ~1 ~55 ~107 ~1 ~55 double_stone_slab 5  
fill ~106 ~1 ~56 ~107 ~1 ~56 double_stone_slab 5  
fill ~106 ~1 ~57 ~107 ~1 ~57 double_stone_slab 5  
fill ~106 ~1 ~58 ~107 ~1 ~58 double_stone_slab 5  
fill ~106 ~1 ~59 ~107 ~1 ~59 double_stone_slab 5  
fill ~106 ~1 ~60 ~107 ~1 ~60 double_stone_slab 5  
fill ~106 ~1 ~61 ~107 ~1 ~61 double_stone_slab 5  
fill ~106 ~1 ~62 ~107 ~1 ~62 double_stone_slab 5  
fill ~106 ~1 ~63 ~107 ~1 ~63 double_stone_slab 5  
fill ~106 ~1 ~64 ~107 ~1 ~64 double_stone_slab 5  
fill ~106 ~1 ~65 ~107 ~1 ~65 double_stone_slab 5  
fill ~106 ~1 ~66 ~107 ~1 ~66 double_stone_slab 5  
fill ~106 ~1 ~67 ~107 ~1 ~67 double_stone_slab 5  
fill ~106 ~1 ~68 ~107 ~1 ~68 double_stone_slab 5  
fill ~106 ~1 ~69 ~107 ~1 ~69 double_stone_slab 5  
fill ~106 ~1 ~70 ~106 ~3 ~70 double_stone_slab 5  
fill ~106 ~1 ~71 ~106 ~3 ~71 stonebrick 0  
fill ~106 ~1 ~72 ~106 ~3 ~72 double_stone_slab 5  
fill ~106 ~1 ~73 ~106 ~3 ~73 double_stone_slab 5  
fill ~106 ~1 ~74 ~106 ~3 ~74 double_stone_slab 5  
fill ~106 ~1 ~75 ~106 ~3 ~75 double_stone_slab 5  
fill ~106 ~1 ~76 ~106 ~3 ~76 double_stone_slab 5  
fill ~106 ~1 ~77 ~106 ~3 ~77 double_stone_slab 5  
fill ~106 ~1 ~78 ~106 ~3 ~78 double_stone_slab 5  
fill ~106 ~1 ~79 ~106 ~3 ~79 double_stone_slab 5  
fill ~106 ~1 ~80 ~106 ~3 ~80 double_stone_slab 5  
fill ~106 ~1 ~81 ~106 ~3 ~81 double_stone_slab 5  
fill ~106 ~1 ~82 ~106 ~3 ~82 double_stone_slab 5  
fill ~106 ~1 ~83 ~106 ~3 ~83 double_stone_slab 5  
fill ~106 ~1 ~84 ~106 ~3 ~84 double_stone_slab 5  
fill ~106 ~1 ~85 ~106 ~3 ~85 double_stone_slab 5  
fill ~106 ~1 ~86 ~106 ~3 ~86 double_stone_slab 5  
fill ~106 ~1 ~87 ~106 ~3 ~87 double_stone_slab 5  
fill ~106 ~1 ~88 ~106 ~3 ~88 double_stone_slab 5  
fill ~106 ~1 ~89 ~106 ~3 ~89 double_stone_slab 5  
fill ~106 ~1 ~90 ~106 ~3 ~90 double_stone_slab 5  
fill ~106 ~1 ~91 ~106 ~3 ~91 double_stone_slab 5  
fill ~106 ~1 ~92 ~106 ~3 ~92 double_stone_slab 5  
fill ~106 ~1 ~93 ~106 ~3 ~93 double_stone_slab 5  
fill ~106 ~1 ~94 ~106 ~3 ~94 double_stone_slab 5  
fill ~106 ~1 ~95 ~106 ~3 ~95 double_stone_slab 5  
fill ~106 ~1 ~96 ~106 ~3 ~96 double_stone_slab 5  
fill ~106 ~1 ~97 ~106 ~3 ~97 double_stone_slab 5  
fill ~106 ~1 ~98 ~106 ~3 ~98 double_stone_slab 5  
fill ~106 ~1 ~99 ~106 ~3 ~99 double_stone_slab 5  
fill ~106 ~1 ~100 ~106 ~3 ~100 double_stone_slab 5  
fill ~106 ~1 ~101 ~106 ~3 ~101 double_stone_slab 5  
fill ~106 ~1 ~102 ~106 ~3 ~102 double_stone_slab 5  
fill ~106 ~1 ~103 ~106 ~3 ~103 double_stone_slab 5  
fill ~106 ~1 ~104 ~106 ~3 ~104 double_stone_slab 5  
fill ~106 ~1 ~105 ~106 ~3 ~105 double_stone_slab 5  
fill ~106 ~1 ~106 ~106 ~3 ~106 double_stone_slab 5 
setblock ~107 ~1 ~6 stone_slab 5  
fill ~107 ~1 ~7 ~107 ~1 ~42 stone_brick_stairs 1 
setblock ~107 ~1 ~43 stone_slab 5 
setblock ~107 ~1 ~70 stone_slab 5  
fill ~107 ~1 ~71 ~107 ~1 ~107 stone_brick_stairs 1 
setblock ~107 ~1 ~108 stone_slab 5  
fill ~108 ~1 ~9 ~108 ~2 ~9 vine 2  
fill ~108 ~1 ~19 ~108 ~2 ~19 vine 2  
fill ~108 ~1 ~21 ~108 ~2 ~21 vine 2  
fill ~108 ~1 ~26 ~108 ~2 ~26 vine 2  
fill ~108 ~1 ~27 ~108 ~2 ~27 vine 2  
fill ~108 ~1 ~28 ~108 ~2 ~28 vine 2  
fill ~108 ~1 ~43 ~110 ~1 ~43 stone_brick_stairs 2  
fill ~108 ~1 ~44 ~109 ~1 ~44 stonebrick 0  
fill ~108 ~1 ~45 ~108 ~0 ~45 stonebrick 0  
fill ~108 ~1 ~46 ~108 ~0 ~46 stonebrick 0  
fill ~108 ~1 ~47 ~108 ~0 ~47 stonebrick 0  
fill ~108 ~1 ~48 ~108 ~0 ~48 stonebrick 0  
fill ~108 ~1 ~49 ~108 ~0 ~49 stonebrick 0  
fill ~108 ~1 ~50 ~108 ~0 ~50 stonebrick 0  
fill ~108 ~1 ~51 ~108 ~0 ~51 stonebrick 0  
fill ~108 ~1 ~52 ~108 ~0 ~52 stonebrick 0  
fill ~108 ~1 ~53 ~108 ~0 ~53 stonebrick 0  
fill ~108 ~1 ~54 ~108 ~0 ~54 stonebrick 0  
fill ~108 ~1 ~55 ~108 ~0 ~55 stonebrick 0  
fill ~108 ~1 ~56 ~108 ~0 ~56 stonebrick 0  
fill ~108 ~1 ~57 ~108 ~0 ~57 stonebrick 0  
fill ~108 ~1 ~58 ~108 ~0 ~58 stonebrick 0  
fill ~108 ~1 ~59 ~108 ~0 ~59 stonebrick 0  
fill ~108 ~1 ~60 ~108 ~0 ~60 stonebrick 0  
fill ~108 ~1 ~61 ~108 ~0 ~61 stonebrick 0  
fill ~108 ~1 ~62 ~108 ~0 ~62 stonebrick 0  
fill ~108 ~1 ~63 ~108 ~0 ~63 stonebrick 0  
fill ~108 ~1 ~64 ~108 ~0 ~64 stonebrick 0  
fill ~108 ~1 ~65 ~108 ~0 ~65 stonebrick 0  
fill ~108 ~1 ~66 ~108 ~0 ~66 stonebrick 0  
fill ~108 ~1 ~67 ~108 ~0 ~67 stonebrick 0  
fill ~108 ~1 ~68 ~108 ~0 ~68 stonebrick 0  
fill ~108 ~1 ~69 ~109 ~1 ~69 stonebrick 0  
fill ~108 ~1 ~70 ~110 ~1 ~70 stone_brick_stairs 3  
fill ~108 ~1 ~71 ~109 ~1 ~71 vine 4  
fill ~108 ~1 ~72 ~108 ~2 ~72 vine 2  
fill ~108 ~1 ~73 ~108 ~2 ~73 vine 2  
fill ~108 ~1 ~80 ~108 ~2 ~80 vine 2  
fill ~108 ~1 ~85 ~108 ~2 ~85 vine 2  
fill ~108 ~1 ~86 ~108 ~2 ~86 vine 2  
fill ~108 ~1 ~87 ~108 ~2 ~87 vine 2  
fill ~108 ~1 ~88 ~108 ~2 ~88 vine 2  
fill ~108 ~1 ~93 ~108 ~2 ~93 vine 2  
fill ~108 ~1 ~95 ~108 ~2 ~95 vine 2  
fill ~108 ~1 ~98 ~108 ~2 ~98 vine 2  
fill ~108 ~1 ~101 ~108 ~2 ~101 vine 2  
fill ~109 ~1 ~42 ~110 ~1 ~42 vine 1  
fill ~109 ~1 ~45 ~109 ~1 ~62 stone_brick_stairs 1  
fill ~109 ~1 ~64 ~109 ~1 ~68 stone_brick_stairs 1 
setblock ~110 ~1 ~44 stone_brick_stairs 3 
setblock ~110 ~1 ~69 stone_brick_stairs 2  
fill ~111 ~1 ~43 ~111 ~1 ~44 stone_brick_stairs 1  
fill ~111 ~1 ~45 ~111 ~2 ~45 vine 4  
fill ~111 ~1 ~69 ~111 ~1 ~70 stone_brick_stairs 1  
fill ~112 ~1 ~70 ~112 ~2 ~70 vine 2  
fill ~2 ~2 ~43 ~5 ~2 ~43 stonebrick 0  
fill ~2 ~2 ~44 ~5 ~2 ~44 stonebrick 0  
fill ~2 ~2 ~69 ~5 ~2 ~69 stonebrick 0  
fill ~2 ~2 ~70 ~5 ~2 ~70 stonebrick 0 
setblock ~4 ~2 ~45 vine 4  
fill ~4 ~2 ~71 ~5 ~2 ~71 vine 4 
setblock ~5 ~2 ~10 vine 8 
setblock ~5 ~2 ~18 vine 8  
fill ~5 ~2 ~45 ~5 ~2 ~68 stone_brick_stairs 0  
fill ~6 ~2 ~6 ~107 ~2 ~6 double_stone_slab 5  
fill ~6 ~2 ~7 ~107 ~2 ~7 double_stone_slab 5  
fill ~6 ~2 ~8 ~6 ~2 ~108 double_stone_slab 5  
fill ~7 ~2 ~44 ~7 ~3 ~44 double_stone_slab 5  
fill ~7 ~2 ~45 ~7 ~2 ~108 double_stone_slab 5  
fill ~8 ~2 ~5 ~9 ~2 ~5 vine 1  
fill ~8 ~2 ~8 ~105 ~2 ~8 dirt 0  
fill ~8 ~2 ~9 ~105 ~2 ~9 dirt 0  
fill ~8 ~2 ~10 ~105 ~2 ~10 dirt 0  
fill ~8 ~2 ~11 ~105 ~2 ~11 dirt 0  
fill ~8 ~2 ~12 ~105 ~2 ~12 dirt 0  
fill ~8 ~2 ~13 ~105 ~2 ~13 dirt 0  
fill ~8 ~2 ~14 ~105 ~2 ~14 dirt 0  
fill ~8 ~2 ~15 ~105 ~2 ~15 dirt 0  
fill ~8 ~2 ~16 ~105 ~2 ~16 dirt 0  
fill ~8 ~2 ~17 ~105 ~2 ~17 dirt 0  
fill ~8 ~2 ~18 ~105 ~2 ~18 dirt 0  
fill ~8 ~2 ~19 ~105 ~2 ~19 dirt 0  
fill ~8 ~2 ~20 ~105 ~2 ~20 dirt 0  
fill ~8 ~2 ~21 ~105 ~2 ~21 dirt 0  
fill ~8 ~2 ~22 ~105 ~2 ~22 dirt 0  
fill ~8 ~2 ~23 ~105 ~2 ~23 dirt 0  
fill ~8 ~2 ~24 ~105 ~2 ~24 dirt 0  
fill ~8 ~2 ~25 ~105 ~2 ~25 dirt 0  
fill ~8 ~2 ~26 ~105 ~2 ~26 dirt 0  
fill ~8 ~2 ~27 ~105 ~2 ~27 dirt 0  
fill ~8 ~2 ~28 ~105 ~2 ~28 dirt 0  
fill ~8 ~2 ~29 ~105 ~2 ~29 dirt 0  
fill ~8 ~2 ~30 ~105 ~2 ~30 dirt 0  
fill ~8 ~2 ~31 ~105 ~2 ~31 dirt 0  
fill ~8 ~2 ~32 ~105 ~2 ~32 dirt 0  
fill ~8 ~2 ~33 ~105 ~2 ~33 dirt 0  
fill ~8 ~2 ~34 ~105 ~2 ~34 dirt 0  
fill ~8 ~2 ~35 ~105 ~2 ~35 dirt 0  
fill ~8 ~2 ~36 ~105 ~2 ~36 dirt 0  
fill ~8 ~2 ~37 ~105 ~2 ~37 dirt 0  
fill ~8 ~2 ~38 ~105 ~2 ~38 dirt 0  
fill ~8 ~2 ~39 ~105 ~2 ~39 dirt 0  
fill ~8 ~2 ~40 ~105 ~2 ~40 dirt 0  
fill ~8 ~2 ~41 ~105 ~2 ~41 dirt 0  
fill ~8 ~2 ~42 ~105 ~2 ~42 dirt 0  
fill ~8 ~2 ~43 ~105 ~2 ~43 dirt 0  
fill ~8 ~2 ~44 ~105 ~2 ~44 dirt 0  
fill ~8 ~2 ~45 ~105 ~2 ~45 dirt 0  
fill ~8 ~2 ~46 ~105 ~2 ~46 dirt 0  
fill ~8 ~2 ~47 ~105 ~2 ~47 dirt 0  
fill ~8 ~2 ~48 ~105 ~2 ~48 dirt 0  
fill ~8 ~2 ~49 ~105 ~2 ~49 dirt 0  
fill ~8 ~2 ~50 ~105 ~2 ~50 dirt 0  
fill ~8 ~2 ~51 ~105 ~2 ~51 dirt 0  
fill ~8 ~2 ~52 ~105 ~2 ~52 dirt 0  
fill ~8 ~2 ~53 ~105 ~2 ~53 dirt 0  
fill ~8 ~2 ~54 ~105 ~2 ~54 dirt 0  
fill ~8 ~2 ~55 ~105 ~2 ~55 dirt 0  
fill ~8 ~2 ~56 ~105 ~2 ~56 dirt 0  
fill ~8 ~2 ~57 ~105 ~2 ~57 dirt 0  
fill ~8 ~2 ~58 ~105 ~2 ~58 dirt 0  
fill ~8 ~2 ~59 ~105 ~2 ~59 dirt 0  
fill ~8 ~2 ~60 ~105 ~2 ~60 dirt 0  
fill ~8 ~2 ~61 ~105 ~2 ~61 dirt 0  
fill ~8 ~2 ~62 ~105 ~2 ~62 dirt 0  
fill ~8 ~2 ~63 ~105 ~2 ~63 dirt 0  
fill ~8 ~2 ~64 ~105 ~2 ~64 dirt 0  
fill ~8 ~2 ~65 ~105 ~2 ~65 dirt 0  
fill ~8 ~2 ~66 ~105 ~2 ~66 dirt 0  
fill ~8 ~2 ~67 ~105 ~2 ~67 dirt 0  
fill ~8 ~2 ~68 ~105 ~2 ~68 dirt 0  
fill ~8 ~2 ~69 ~105 ~2 ~69 dirt 0  
fill ~8 ~2 ~70 ~105 ~2 ~70 dirt 0  
fill ~8 ~2 ~71 ~105 ~2 ~71 dirt 0  
fill ~8 ~2 ~72 ~105 ~2 ~72 dirt 0  
fill ~8 ~2 ~73 ~105 ~2 ~73 dirt 0  
fill ~8 ~2 ~74 ~105 ~2 ~74 dirt 0  
fill ~8 ~2 ~75 ~105 ~2 ~75 dirt 0  
fill ~8 ~2 ~76 ~105 ~2 ~76 dirt 0  
fill ~8 ~2 ~77 ~105 ~2 ~77 dirt 0  
fill ~8 ~2 ~78 ~105 ~2 ~78 dirt 0  
fill ~8 ~2 ~79 ~105 ~2 ~79 dirt 0  
fill ~8 ~2 ~80 ~105 ~2 ~80 dirt 0  
fill ~8 ~2 ~81 ~105 ~2 ~81 dirt 0  
fill ~8 ~2 ~82 ~105 ~2 ~82 dirt 0  
fill ~8 ~2 ~83 ~105 ~2 ~83 dirt 0  
fill ~8 ~2 ~84 ~105 ~2 ~84 dirt 0  
fill ~8 ~2 ~85 ~105 ~2 ~85 dirt 0  
fill ~8 ~2 ~86 ~105 ~2 ~86 dirt 0  
fill ~8 ~2 ~87 ~105 ~2 ~87 dirt 0  
fill ~8 ~2 ~88 ~105 ~2 ~88 dirt 0  
fill ~8 ~2 ~89 ~105 ~2 ~89 dirt 0  
fill ~8 ~2 ~90 ~105 ~2 ~90 dirt 0  
fill ~8 ~2 ~91 ~105 ~2 ~91 dirt 0  
fill ~8 ~2 ~92 ~105 ~2 ~92 dirt 0  
fill ~8 ~2 ~93 ~105 ~2 ~93 dirt 0  
fill ~8 ~2 ~94 ~105 ~2 ~94 dirt 0  
fill ~8 ~2 ~95 ~105 ~2 ~95 dirt 0  
fill ~8 ~2 ~96 ~105 ~2 ~96 dirt 0  
fill ~8 ~2 ~97 ~105 ~2 ~97 dirt 0  
fill ~8 ~2 ~98 ~105 ~2 ~98 dirt 0  
fill ~8 ~2 ~99 ~105 ~2 ~99 dirt 0  
fill ~8 ~2 ~100 ~105 ~2 ~100 dirt 0  
fill ~8 ~2 ~101 ~105 ~2 ~101 dirt 0  
fill ~8 ~2 ~102 ~105 ~2 ~102 dirt 0  
fill ~8 ~2 ~103 ~105 ~2 ~103 dirt 0  
fill ~8 ~2 ~104 ~105 ~2 ~104 dirt 0  
fill ~8 ~2 ~105 ~105 ~2 ~105 dirt 0  
fill ~8 ~2 ~106 ~105 ~2 ~106 dirt 0  
fill ~8 ~2 ~107 ~107 ~2 ~107 double_stone_slab 5  
fill ~8 ~2 ~108 ~27 ~2 ~108 double_stone_slab 5  
fill ~14 ~2 ~5 ~16 ~2 ~5 vine 1  
fill ~14 ~2 ~109 ~18 ~2 ~109 vine 4  
fill ~21 ~2 ~5 ~23 ~2 ~5 vine 1  
fill ~23 ~2 ~109 ~25 ~2 ~109 vine 4  
fill ~29 ~2 ~5 ~31 ~2 ~5 vine 1  
fill ~30 ~2 ~108 ~41 ~2 ~108 double_stone_slab 5  
fill ~32 ~2 ~109 ~35 ~2 ~109 vine 4  
fill ~33 ~2 ~5 ~35 ~2 ~5 vine 1 
setblock ~41 ~2 ~5 vine 1 
setblock ~41 ~2 ~109 vine 4 
setblock ~42 ~2 ~108 stonebrick 0  
fill ~43 ~2 ~2 ~44 ~2 ~2 stonebrick 0  
fill ~43 ~2 ~3 ~44 ~2 ~3 stonebrick 0  
fill ~43 ~2 ~4 ~43 ~2 ~5 stonebrick 0  
fill ~43 ~2 ~108 ~107 ~2 ~108 double_stone_slab 5  
fill ~43 ~2 ~109 ~44 ~2 ~109 stonebrick 0  
fill ~43 ~2 ~110 ~43 ~2 ~112 stonebrick 0  
fill ~44 ~2 ~5 ~44 ~0 ~5 stonebrick 0  
fill ~44 ~2 ~111 ~44 ~2 ~112 stonebrick 0  
fill ~45 ~2 ~5 ~68 ~2 ~5 stone_brick_stairs 2  
fill ~45 ~2 ~109 ~68 ~2 ~109 stone_brick_stairs 3 
setblock ~45 ~2 ~110 vine 2  
fill ~69 ~2 ~2 ~70 ~2 ~2 stonebrick 0  
fill ~69 ~2 ~3 ~70 ~2 ~3 stonebrick 0  
fill ~69 ~2 ~5 ~70 ~2 ~5 stonebrick 0  
fill ~69 ~2 ~109 ~70 ~2 ~109 stonebrick 0  
fill ~69 ~2 ~111 ~70 ~2 ~111 stonebrick 0  
fill ~69 ~2 ~112 ~70 ~2 ~112 stonebrick 0  
fill ~69 ~2 ~113 ~70 ~2 ~113 vine 4 
setblock ~70 ~2 ~4 stonebrick 0 
setblock ~70 ~2 ~110 stonebrick 0 
setblock ~71 ~2 ~3 vine 2  
fill ~75 ~2 ~109 ~76 ~2 ~109 vine 4  
fill ~78 ~2 ~5 ~81 ~2 ~5 vine 1  
fill ~82 ~2 ~109 ~84 ~2 ~109 vine 4  
fill ~88 ~2 ~109 ~92 ~2 ~109 vine 4  
fill ~97 ~2 ~5 ~98 ~2 ~5 vine 1  
fill ~98 ~2 ~109 ~101 ~2 ~109 vine 4  
fill ~102 ~2 ~5 ~104 ~2 ~5 vine 1  
fill ~105 ~2 ~109 ~107 ~2 ~109 vine 4  
fill ~106 ~2 ~44 ~107 ~2 ~44 double_stone_slab 5  
fill ~106 ~2 ~45 ~107 ~2 ~45 double_stone_slab 5  
fill ~106 ~2 ~46 ~107 ~2 ~46 double_stone_slab 5  
fill ~106 ~2 ~47 ~107 ~2 ~47 double_stone_slab 5  
fill ~106 ~2 ~48 ~107 ~2 ~48 double_stone_slab 5  
fill ~106 ~2 ~49 ~107 ~2 ~49 double_stone_slab 5  
fill ~106 ~2 ~50 ~107 ~2 ~50 double_stone_slab 5  
fill ~106 ~2 ~51 ~107 ~2 ~51 double_stone_slab 5  
fill ~106 ~2 ~52 ~107 ~2 ~52 double_stone_slab 5  
fill ~106 ~2 ~53 ~107 ~2 ~53 double_stone_slab 5  
fill ~106 ~2 ~54 ~107 ~2 ~54 double_stone_slab 5  
fill ~106 ~2 ~55 ~107 ~2 ~55 double_stone_slab 5  
fill ~106 ~2 ~56 ~107 ~2 ~56 double_stone_slab 5  
fill ~106 ~2 ~57 ~107 ~2 ~57 double_stone_slab 5  
fill ~106 ~2 ~58 ~107 ~2 ~58 double_stone_slab 5  
fill ~106 ~2 ~59 ~107 ~2 ~59 double_stone_slab 5  
fill ~106 ~2 ~60 ~107 ~2 ~60 double_stone_slab 5  
fill ~106 ~2 ~61 ~107 ~2 ~61 double_stone_slab 5  
fill ~106 ~2 ~62 ~107 ~2 ~62 double_stone_slab 5  
fill ~106 ~2 ~63 ~107 ~2 ~63 double_stone_slab 5  
fill ~106 ~2 ~64 ~107 ~2 ~64 double_stone_slab 5  
fill ~106 ~2 ~65 ~107 ~2 ~65 double_stone_slab 5  
fill ~106 ~2 ~66 ~107 ~2 ~66 double_stone_slab 5  
fill ~106 ~2 ~67 ~107 ~2 ~67 double_stone_slab 5  
fill ~106 ~2 ~68 ~107 ~2 ~68 double_stone_slab 5  
fill ~106 ~2 ~69 ~107 ~2 ~69 double_stone_slab 5  
fill ~107 ~2 ~8 ~107 ~2 ~70 double_stone_slab 5 
setblock ~107 ~2 ~71 stonebrick 0  
fill ~107 ~2 ~72 ~107 ~2 ~108 double_stone_slab 5  
fill ~108 ~2 ~43 ~111 ~2 ~43 stonebrick 0  
fill ~108 ~2 ~44 ~111 ~2 ~44 stonebrick 0  
fill ~108 ~2 ~45 ~108 ~2 ~61 stone_brick_stairs 1  
fill ~108 ~2 ~63 ~108 ~2 ~68 stone_brick_stairs 1  
fill ~108 ~2 ~69 ~111 ~2 ~69 stonebrick 0  
fill ~108 ~2 ~70 ~111 ~2 ~70 stonebrick 0  
fill ~108 ~2 ~71 ~109 ~2 ~71 vine 4 
setblock ~108 ~2 ~92 vine 2 
setblock ~108 ~2 ~99 vine 2  
fill ~109 ~2 ~42 ~110 ~2 ~42 vine 1 
setblock ~109 ~2 ~61 stone_slab 0  
fill ~2 ~3 ~43 ~2 ~3 ~44 stone_brick_stairs 0  
fill ~2 ~3 ~69 ~2 ~3 ~70 stone_brick_stairs 0  
fill ~3 ~3 ~43 ~5 ~3 ~43 stone_brick_stairs 2  
fill ~3 ~3 ~44 ~5 ~3 ~44 stone_brick_stairs 3  
fill ~3 ~3 ~69 ~5 ~3 ~69 stone_brick_stairs 2  
fill ~3 ~3 ~70 ~5 ~3 ~70 stone_brick_stairs 3 
setblock ~6 ~3 ~6 stone_slab 5  
fill ~6 ~3 ~7 ~6 ~3 ~42 stone_brick_stairs 0 
setblock ~6 ~3 ~43 stone_slab 5 
setblock ~6 ~3 ~44 double_stone_slab 5  
fill ~6 ~3 ~45 ~6 ~3 ~68 stone_brick_stairs 0  
fill ~6 ~3 ~69 ~7 ~3 ~69 double_stone_slab 5 
setblock ~6 ~3 ~70 stone_slab 5  
fill ~6 ~3 ~71 ~6 ~3 ~107 stone_brick_stairs 0 
setblock ~6 ~3 ~108 stone_slab 5  
fill ~7 ~3 ~6 ~42 ~3 ~6 stone_brick_stairs 2  
fill ~7 ~3 ~7 ~44 ~3 ~7 double_stone_slab 5  
fill ~7 ~3 ~45 ~7 ~3 ~68 double_stone_slab 0  
fill ~7 ~3 ~107 ~44 ~3 ~107 double_stone_slab 5  
fill ~7 ~3 ~108 ~27 ~3 ~108 stone_brick_stairs 3  
fill ~8 ~3 ~8 ~105 ~3 ~8 grass 0  
fill ~8 ~3 ~9 ~105 ~3 ~9 grass 0  
fill ~8 ~3 ~10 ~105 ~3 ~10 grass 0  
fill ~8 ~3 ~11 ~105 ~3 ~11 grass 0  
fill ~8 ~3 ~12 ~105 ~3 ~12 grass 0  
fill ~8 ~3 ~13 ~105 ~3 ~13 grass 0  
fill ~8 ~3 ~14 ~105 ~3 ~14 grass 0  
fill ~8 ~3 ~15 ~105 ~3 ~15 grass 0  
fill ~8 ~3 ~16 ~105 ~3 ~16 grass 0  
fill ~8 ~3 ~17 ~49 ~3 ~17 grass 0  
fill ~8 ~3 ~18 ~49 ~3 ~18 grass 0  
fill ~8 ~3 ~19 ~49 ~3 ~19 grass 0  
fill ~8 ~3 ~20 ~49 ~3 ~20 grass 0  
fill ~8 ~3 ~21 ~49 ~3 ~21 grass 0  
fill ~8 ~3 ~22 ~49 ~3 ~22 grass 0  
fill ~8 ~3 ~23 ~49 ~3 ~23 grass 0  
fill ~8 ~3 ~24 ~23 ~3 ~24 grass 0  
fill ~8 ~3 ~25 ~23 ~3 ~25 grass 0  
fill ~8 ~3 ~26 ~23 ~3 ~26 grass 0  
fill ~8 ~3 ~27 ~23 ~3 ~27 grass 0  
fill ~8 ~3 ~28 ~23 ~3 ~28 grass 0  
fill ~8 ~3 ~29 ~23 ~3 ~29 grass 0  
fill ~8 ~3 ~30 ~23 ~3 ~30 grass 0  
fill ~8 ~3 ~31 ~23 ~3 ~31 grass 0  
fill ~8 ~3 ~32 ~23 ~3 ~32 grass 0  
fill ~8 ~3 ~33 ~23 ~3 ~33 grass 0  
fill ~8 ~3 ~34 ~23 ~3 ~34 grass 0  
fill ~8 ~3 ~35 ~23 ~3 ~35 grass 0  
fill ~8 ~3 ~36 ~23 ~3 ~36 grass 0  
fill ~8 ~3 ~37 ~23 ~3 ~37 grass 0  
fill ~8 ~3 ~38 ~23 ~3 ~38 grass 0  
fill ~8 ~3 ~39 ~23 ~3 ~39 grass 0  
fill ~8 ~3 ~40 ~23 ~3 ~40 grass 0  
fill ~8 ~3 ~41 ~23 ~3 ~41 grass 0  
fill ~8 ~3 ~42 ~23 ~3 ~42 grass 0  
fill ~8 ~3 ~43 ~23 ~3 ~43 grass 0  
fill ~8 ~3 ~44 ~23 ~3 ~44 grass 0  
fill ~8 ~3 ~45 ~23 ~3 ~45 grass 0  
fill ~8 ~3 ~46 ~23 ~3 ~46 grass 0  
fill ~8 ~3 ~47 ~23 ~3 ~47 grass 0  
fill ~8 ~3 ~48 ~23 ~3 ~48 grass 0  
fill ~8 ~3 ~49 ~23 ~3 ~49 grass 0  
fill ~8 ~3 ~50 ~16 ~3 ~50 grass 0  
fill ~8 ~3 ~51 ~16 ~3 ~51 grass 0  
fill ~8 ~3 ~52 ~17 ~3 ~52 grass 0  
fill ~8 ~3 ~53 ~17 ~3 ~53 grass 0  
fill ~8 ~3 ~54 ~17 ~3 ~54 grass 0  
fill ~8 ~3 ~55 ~17 ~3 ~55 grass 0  
fill ~8 ~3 ~56 ~17 ~3 ~56 grass 0  
fill ~8 ~3 ~57 ~17 ~3 ~57 grass 0  
fill ~8 ~3 ~58 ~17 ~3 ~58 grass 0  
fill ~8 ~3 ~59 ~17 ~3 ~59 grass 0  
fill ~8 ~3 ~60 ~17 ~3 ~60 grass 0  
fill ~8 ~3 ~61 ~17 ~3 ~61 grass 0  
fill ~8 ~3 ~62 ~16 ~3 ~62 grass 0  
fill ~8 ~3 ~63 ~16 ~3 ~63 grass 0  
fill ~8 ~3 ~64 ~23 ~3 ~64 grass 0  
fill ~8 ~3 ~65 ~23 ~3 ~65 grass 0  
fill ~8 ~3 ~66 ~23 ~3 ~66 grass 0  
fill ~8 ~3 ~67 ~23 ~3 ~67 grass 0  
fill ~8 ~3 ~68 ~23 ~3 ~68 grass 0  
fill ~8 ~3 ~69 ~23 ~3 ~69 grass 0  
fill ~8 ~3 ~70 ~23 ~3 ~70 grass 0  
fill ~8 ~3 ~71 ~23 ~3 ~71 grass 0  
fill ~8 ~3 ~72 ~23 ~3 ~72 grass 0  
fill ~8 ~3 ~73 ~23 ~3 ~73 grass 0  
fill ~8 ~3 ~74 ~23 ~3 ~74 grass 0  
fill ~8 ~3 ~75 ~23 ~3 ~75 grass 0  
fill ~8 ~3 ~76 ~23 ~3 ~76 grass 0  
fill ~8 ~3 ~77 ~23 ~3 ~77 grass 0  
fill ~8 ~3 ~78 ~23 ~3 ~78 grass 0  
fill ~8 ~3 ~79 ~23 ~3 ~79 grass 0  
fill ~8 ~3 ~80 ~23 ~3 ~80 grass 0  
fill ~8 ~3 ~81 ~23 ~3 ~81 grass 0  
fill ~8 ~3 ~82 ~23 ~3 ~82 grass 0  
fill ~8 ~3 ~83 ~23 ~3 ~83 grass 0  
fill ~8 ~3 ~84 ~23 ~3 ~84 grass 0  
fill ~8 ~3 ~85 ~23 ~3 ~85 grass 0  
fill ~8 ~3 ~86 ~23 ~3 ~86 grass 0  
fill ~8 ~3 ~87 ~23 ~3 ~87 grass 0  
fill ~8 ~3 ~88 ~23 ~3 ~88 grass 0  
fill ~8 ~3 ~89 ~23 ~3 ~89 grass 0  
fill ~8 ~3 ~90 ~49 ~3 ~90 grass 0  
fill ~8 ~3 ~91 ~49 ~3 ~91 grass 0  
fill ~8 ~3 ~92 ~49 ~3 ~92 grass 0  
fill ~8 ~3 ~93 ~49 ~3 ~93 grass 0  
fill ~8 ~3 ~94 ~49 ~3 ~94 grass 0  
fill ~8 ~3 ~95 ~49 ~3 ~95 grass 0  
fill ~8 ~3 ~96 ~49 ~3 ~96 grass 0  
fill ~8 ~3 ~97 ~105 ~3 ~97 grass 0  
fill ~8 ~3 ~98 ~105 ~3 ~98 grass 0  
fill ~8 ~3 ~99 ~105 ~3 ~99 grass 0  
fill ~8 ~3 ~100 ~105 ~3 ~100 grass 0  
fill ~8 ~3 ~101 ~105 ~3 ~101 grass 0  
fill ~8 ~3 ~102 ~105 ~3 ~102 grass 0  
fill ~8 ~3 ~103 ~105 ~3 ~103 grass 0  
fill ~8 ~3 ~104 ~105 ~3 ~104 grass 0  
fill ~8 ~3 ~105 ~105 ~3 ~105 grass 0  
fill ~8 ~3 ~106 ~105 ~3 ~106 grass 0  
fill ~17 ~3 ~50 ~25 ~3 ~50 dirt 0  
fill ~17 ~3 ~51 ~18 ~3 ~51 dirt 0  
fill ~17 ~3 ~62 ~18 ~3 ~62 dirt 0  
fill ~17 ~3 ~63 ~25 ~3 ~63 dirt 0  
fill ~18 ~3 ~52 ~18 ~3 ~63 dirt 0  
fill ~19 ~3 ~51 ~94 ~3 ~51 grass 0  
fill ~19 ~3 ~52 ~94 ~3 ~52 grass 0  
fill ~19 ~3 ~53 ~94 ~3 ~53 grass 0  
fill ~19 ~3 ~54 ~94 ~3 ~54 grass 0  
fill ~19 ~3 ~55 ~94 ~3 ~55 grass 0  
fill ~19 ~3 ~56 ~94 ~3 ~56 grass 0  
fill ~19 ~3 ~57 ~94 ~3 ~57 grass 0  
fill ~19 ~3 ~58 ~94 ~3 ~58 grass 0  
fill ~19 ~3 ~59 ~94 ~3 ~59 grass 0  
fill ~19 ~3 ~60 ~94 ~3 ~60 grass 0  
fill ~19 ~3 ~61 ~94 ~3 ~61 grass 0  
fill ~19 ~3 ~62 ~94 ~3 ~62 grass 0  
fill ~24 ~3 ~24 ~50 ~3 ~24 dirt 0  
fill ~24 ~3 ~25 ~24 ~3 ~50 dirt 0  
fill ~24 ~3 ~64 ~24 ~3 ~89 dirt 0  
fill ~25 ~3 ~25 ~49 ~3 ~25 grass 0  
fill ~25 ~3 ~26 ~88 ~3 ~26 grass 0  
fill ~25 ~3 ~27 ~88 ~3 ~27 grass 0  
fill ~25 ~3 ~28 ~88 ~3 ~28 grass 0  
fill ~25 ~3 ~29 ~88 ~3 ~29 grass 0  
fill ~25 ~3 ~30 ~88 ~3 ~30 grass 0  
fill ~25 ~3 ~31 ~88 ~3 ~31 grass 0  
fill ~25 ~3 ~32 ~88 ~3 ~32 grass 0  
fill ~25 ~3 ~33 ~88 ~3 ~33 grass 0  
fill ~25 ~3 ~34 ~88 ~3 ~34 grass 0  
fill ~25 ~3 ~35 ~88 ~3 ~35 grass 0  
fill ~25 ~3 ~36 ~88 ~3 ~36 grass 0  
fill ~25 ~3 ~37 ~88 ~3 ~37 grass 0  
fill ~25 ~3 ~38 ~88 ~3 ~38 grass 0  
fill ~25 ~3 ~39 ~88 ~3 ~39 grass 0  
fill ~25 ~3 ~40 ~88 ~3 ~40 grass 0  
fill ~25 ~3 ~41 ~88 ~3 ~41 grass 0  
fill ~25 ~3 ~42 ~88 ~3 ~42 grass 0  
fill ~25 ~3 ~43 ~88 ~3 ~43 grass 0  
fill ~25 ~3 ~44 ~88 ~3 ~44 grass 0  
fill ~25 ~3 ~45 ~88 ~3 ~45 grass 0  
fill ~25 ~3 ~46 ~88 ~3 ~46 grass 0  
fill ~25 ~3 ~47 ~88 ~3 ~47 grass 0  
fill ~25 ~3 ~48 ~88 ~3 ~48 grass 0  
fill ~25 ~3 ~49 ~88 ~3 ~49 grass 0  
fill ~25 ~3 ~64 ~88 ~3 ~64 grass 0  
fill ~25 ~3 ~65 ~88 ~3 ~65 grass 0  
fill ~25 ~3 ~66 ~88 ~3 ~66 grass 0  
fill ~25 ~3 ~67 ~88 ~3 ~67 grass 0  
fill ~25 ~3 ~68 ~88 ~3 ~68 grass 0  
fill ~25 ~3 ~69 ~88 ~3 ~69 grass 0  
fill ~25 ~3 ~70 ~88 ~3 ~70 grass 0  
fill ~25 ~3 ~71 ~88 ~3 ~71 grass 0  
fill ~25 ~3 ~72 ~88 ~3 ~72 grass 0  
fill ~25 ~3 ~73 ~88 ~3 ~73 grass 0  
fill ~25 ~3 ~74 ~88 ~3 ~74 grass 0  
fill ~25 ~3 ~75 ~88 ~3 ~75 grass 0  
fill ~25 ~3 ~76 ~88 ~3 ~76 grass 0  
fill ~25 ~3 ~77 ~88 ~3 ~77 grass 0  
fill ~25 ~3 ~78 ~88 ~3 ~78 grass 0  
fill ~25 ~3 ~79 ~88 ~3 ~79 grass 0  
fill ~25 ~3 ~80 ~88 ~3 ~80 grass 0  
fill ~25 ~3 ~81 ~88 ~3 ~81 grass 0  
fill ~25 ~3 ~82 ~88 ~3 ~82 grass 0  
fill ~25 ~3 ~83 ~88 ~3 ~83 grass 0  
fill ~25 ~3 ~84 ~88 ~3 ~84 grass 0  
fill ~25 ~3 ~85 ~88 ~3 ~85 grass 0  
fill ~25 ~3 ~86 ~88 ~3 ~86 grass 0  
fill ~25 ~3 ~87 ~88 ~3 ~87 grass 0  
fill ~25 ~3 ~88 ~49 ~3 ~88 grass 0  
fill ~25 ~3 ~89 ~50 ~3 ~89 dirt 0  
fill ~26 ~3 ~50 ~87 ~3 ~50 grass 0  
fill ~26 ~3 ~63 ~87 ~3 ~63 grass 0  
fill ~29 ~3 ~108 ~42 ~3 ~108 stone_brick_stairs 3  
fill ~43 ~3 ~2 ~44 ~3 ~2 stone_brick_stairs 2  
fill ~43 ~3 ~3 ~43 ~3 ~5 stone_brick_stairs 0 
setblock ~43 ~3 ~6 stone_slab 5 
setblock ~43 ~3 ~108 stone_slab 5  
fill ~43 ~3 ~109 ~43 ~3 ~111 stone_brick_stairs 0  
fill ~43 ~3 ~112 ~44 ~3 ~112 stone_brick_stairs 3  
fill ~44 ~3 ~3 ~44 ~3 ~5 stone_brick_stairs 1 
setblock ~44 ~3 ~6 double_stone_slab 5 
setblock ~44 ~3 ~108 double_stone_slab 5  
fill ~44 ~3 ~109 ~44 ~3 ~111 stone_brick_stairs 1  
fill ~45 ~3 ~6 ~68 ~3 ~6 stone_brick_stairs 2  
fill ~45 ~3 ~7 ~68 ~3 ~7 double_stone_slab 0  
fill ~45 ~3 ~107 ~68 ~3 ~107 double_stone_slab 0  
fill ~45 ~3 ~108 ~68 ~3 ~108 stone_brick_stairs 3  
fill ~50 ~3 ~17 ~51 ~3 ~17 dirt 0  
fill ~50 ~3 ~18 ~63 ~3 ~18 dirt 0  
fill ~50 ~3 ~19 ~50 ~3 ~25 dirt 0 
setblock ~50 ~3 ~88 dirt 0  
fill ~50 ~3 ~90 ~50 ~3 ~96 dirt 0  
fill ~51 ~3 ~19 ~62 ~3 ~19 grass 0  
fill ~51 ~3 ~20 ~62 ~3 ~20 grass 0  
fill ~51 ~3 ~21 ~62 ~3 ~21 grass 0  
fill ~51 ~3 ~22 ~62 ~3 ~22 grass 0  
fill ~51 ~3 ~23 ~62 ~3 ~23 grass 0  
fill ~51 ~3 ~24 ~62 ~3 ~24 grass 0  
fill ~51 ~3 ~25 ~62 ~3 ~25 grass 0  
fill ~51 ~3 ~88 ~62 ~3 ~88 grass 0  
fill ~51 ~3 ~89 ~62 ~3 ~89 grass 0  
fill ~51 ~3 ~90 ~62 ~3 ~90 grass 0  
fill ~51 ~3 ~91 ~62 ~3 ~91 grass 0  
fill ~51 ~3 ~92 ~62 ~3 ~92 grass 0  
fill ~51 ~3 ~93 ~62 ~3 ~93 grass 0  
fill ~51 ~3 ~94 ~62 ~3 ~94 grass 0  
fill ~51 ~3 ~95 ~63 ~3 ~95 dirt 0  
fill ~51 ~3 ~96 ~51 ~3 ~95 dirt 0  
fill ~52 ~3 ~17 ~61 ~3 ~17 grass 0  
fill ~52 ~3 ~96 ~61 ~3 ~96 grass 0  
fill ~62 ~3 ~17 ~63 ~3 ~17 dirt 0  
fill ~62 ~3 ~96 ~63 ~3 ~96 dirt 0  
fill ~63 ~3 ~19 ~63 ~3 ~25 dirt 0  
fill ~63 ~3 ~88 ~63 ~3 ~96 dirt 0  
fill ~64 ~3 ~17 ~105 ~3 ~17 grass 0  
fill ~64 ~3 ~18 ~105 ~3 ~18 grass 0  
fill ~64 ~3 ~19 ~105 ~3 ~19 grass 0  
fill ~64 ~3 ~20 ~105 ~3 ~20 grass 0  
fill ~64 ~3 ~21 ~105 ~3 ~21 grass 0  
fill ~64 ~3 ~22 ~105 ~3 ~22 grass 0  
fill ~64 ~3 ~23 ~105 ~3 ~23 grass 0  
fill ~64 ~3 ~24 ~89 ~3 ~24 dirt 0  
fill ~64 ~3 ~25 ~87 ~3 ~25 grass 0  
fill ~64 ~3 ~88 ~88 ~3 ~88 grass 0  
fill ~64 ~3 ~89 ~89 ~3 ~89 dirt 0  
fill ~64 ~3 ~90 ~105 ~3 ~90 grass 0  
fill ~64 ~3 ~91 ~105 ~3 ~91 grass 0  
fill ~64 ~3 ~92 ~105 ~3 ~92 grass 0  
fill ~64 ~3 ~93 ~105 ~3 ~93 grass 0  
fill ~64 ~3 ~94 ~105 ~3 ~94 grass 0  
fill ~64 ~3 ~95 ~105 ~3 ~95 grass 0  
fill ~64 ~3 ~96 ~105 ~3 ~96 grass 0  
fill ~69 ~3 ~2 ~70 ~3 ~2 stone_brick_stairs 2  
fill ~69 ~3 ~3 ~69 ~3 ~5 stone_brick_stairs 0  
fill ~69 ~3 ~6 ~69 ~3 ~7 double_stone_slab 5  
fill ~69 ~3 ~107 ~106 ~3 ~107 double_stone_slab 5  
fill ~69 ~3 ~108 ~69 ~3 ~107 double_stone_slab 5  
fill ~69 ~3 ~109 ~69 ~3 ~111 stone_brick_stairs 0  
fill ~69 ~3 ~112 ~70 ~3 ~112 stone_brick_stairs 3  
fill ~70 ~3 ~3 ~70 ~3 ~5 stone_brick_stairs 1 
setblock ~70 ~3 ~6 stone_slab 5  
fill ~70 ~3 ~7 ~106 ~3 ~7 double_stone_slab 5 
setblock ~70 ~3 ~108 stone_slab 5  
fill ~70 ~3 ~109 ~70 ~3 ~111 stone_brick_stairs 1  
fill ~71 ~3 ~6 ~106 ~3 ~6 stone_brick_stairs 2  
fill ~71 ~3 ~108 ~106 ~3 ~108 stone_brick_stairs 3  
fill ~88 ~3 ~25 ~89 ~3 ~25 dirt 0  
fill ~88 ~3 ~50 ~96 ~3 ~50 dirt 0  
fill ~88 ~3 ~63 ~96 ~3 ~63 dirt 0  
fill ~89 ~3 ~26 ~89 ~3 ~50 dirt 0  
fill ~89 ~3 ~64 ~89 ~3 ~89 dirt 0  
fill ~90 ~3 ~24 ~105 ~3 ~24 grass 0  
fill ~90 ~3 ~25 ~105 ~3 ~25 grass 0  
fill ~90 ~3 ~26 ~105 ~3 ~26 grass 0  
fill ~90 ~3 ~27 ~105 ~3 ~27 grass 0  
fill ~90 ~3 ~28 ~105 ~3 ~28 grass 0  
fill ~90 ~3 ~29 ~105 ~3 ~29 grass 0  
fill ~90 ~3 ~30 ~105 ~3 ~30 grass 0  
fill ~90 ~3 ~31 ~105 ~3 ~31 grass 0  
fill ~90 ~3 ~32 ~105 ~3 ~32 grass 0  
fill ~90 ~3 ~33 ~105 ~3 ~33 grass 0  
fill ~90 ~3 ~34 ~105 ~3 ~34 grass 0  
fill ~90 ~3 ~35 ~105 ~3 ~35 grass 0  
fill ~90 ~3 ~36 ~105 ~3 ~36 grass 0  
fill ~90 ~3 ~37 ~105 ~3 ~37 grass 0  
fill ~90 ~3 ~38 ~105 ~3 ~38 grass 0  
fill ~90 ~3 ~39 ~105 ~3 ~39 grass 0  
fill ~90 ~3 ~40 ~105 ~3 ~40 grass 0  
fill ~90 ~3 ~41 ~105 ~3 ~41 grass 0  
fill ~90 ~3 ~42 ~105 ~3 ~42 grass 0  
fill ~90 ~3 ~43 ~105 ~3 ~43 grass 0  
fill ~90 ~3 ~44 ~105 ~3 ~44 grass 0  
fill ~90 ~3 ~45 ~105 ~3 ~45 grass 0  
fill ~90 ~3 ~46 ~105 ~3 ~46 grass 0   
fill ~90 ~3 ~47 ~105 ~3 ~47 grass 0  
fill ~90 ~3 ~48 ~105 ~3 ~48 grass 0  
fill ~90 ~3 ~49 ~105 ~3 ~49 grass 0  
fill ~90 ~3 ~64 ~105 ~3 ~64 grass 0  
fill ~90 ~3 ~65 ~105 ~3 ~65 grass 0  
fill ~90 ~3 ~66 ~105 ~3 ~66 grass 0  
fill ~90 ~3 ~67 ~105 ~3 ~67 grass 0  
fill ~90 ~3 ~68 ~105 ~3 ~68 grass 0  
fill ~90 ~3 ~69 ~105 ~3 ~69 grass 0  
fill ~90 ~3 ~70 ~105 ~3 ~70 grass 0  
fill ~90 ~3 ~71 ~105 ~3 ~71 grass 0  
fill ~90 ~3 ~72 ~105 ~3 ~72 grass 0  
fill ~90 ~3 ~73 ~105 ~3 ~73 grass 0  
fill ~90 ~3 ~74 ~105 ~3 ~74 grass 0  
fill ~90 ~3 ~75 ~105 ~3 ~75 grass 0  
fill ~90 ~3 ~76 ~105 ~3 ~76 grass 0  
fill ~90 ~3 ~77 ~105 ~3 ~77 grass 0  
fill ~90 ~3 ~78 ~105 ~3 ~78 grass 0  
fill ~90 ~3 ~79 ~105 ~3 ~79 grass 0  
fill ~90 ~3 ~80 ~105 ~3 ~80 grass 0  
fill ~90 ~3 ~81 ~105 ~3 ~81 grass 0  
fill ~90 ~3 ~82 ~105 ~3 ~82 grass 0  
fill ~90 ~3 ~83 ~105 ~3 ~83 grass 0  
fill ~90 ~3 ~84 ~105 ~3 ~84 grass 0  
fill ~90 ~3 ~85 ~105 ~3 ~85 grass 0  
fill ~90 ~3 ~86 ~105 ~3 ~86 grass 0  
fill ~90 ~3 ~87 ~105 ~3 ~87 grass 0  
fill ~90 ~3 ~88 ~105 ~3 ~88 grass 0  
fill ~90 ~3 ~89 ~105 ~3 ~89 grass 0  
fill ~95 ~3 ~51 ~96 ~3 ~51 dirt 0  
fill ~95 ~3 ~52 ~95 ~3 ~63 dirt 0  
fill ~96 ~3 ~52 ~105 ~3 ~52 grass 0  
fill ~96 ~3 ~53 ~105 ~3 ~53 grass 0  
fill ~96 ~3 ~54 ~105 ~3 ~54 grass 0  
fill ~96 ~3 ~55 ~105 ~3 ~55 grass 0  
fill ~96 ~3 ~56 ~105 ~3 ~56 grass 0  
fill ~96 ~3 ~57 ~105 ~3 ~57 grass 0  
fill ~96 ~3 ~58 ~105 ~3 ~58 grass 0  
fill ~96 ~3 ~59 ~105 ~3 ~59 grass 0  
fill ~96 ~3 ~60 ~105 ~3 ~60 grass 0  
fill ~96 ~3 ~61 ~105 ~3 ~61 grass 0 
setblock ~96 ~3 ~62 dirt 0  
fill ~97 ~3 ~50 ~105 ~3 ~50 grass 0  
fill ~97 ~3 ~51 ~105 ~3 ~51 grass 0  
fill ~97 ~3 ~62 ~105 ~3 ~62 grass 0  
fill ~97 ~3 ~63 ~105 ~3 ~63 grass 0  
fill ~106 ~3 ~44 ~107 ~3 ~44 double_stone_slab 5  
fill ~106 ~3 ~45 ~106 ~3 ~68 double_stone_slab 0  
fill ~106 ~3 ~69 ~107 ~3 ~69 double_stone_slab 5 
setblock ~107 ~3 ~6 stone_slab 5  
fill ~107 ~3 ~7 ~107 ~3 ~42 stone_brick_stairs 1 
setblock ~107 ~3 ~43 stone_slab 5  
fill ~107 ~3 ~45 ~107 ~3 ~68 stone_brick_stairs 1 
setblock ~107 ~3 ~70 stone_slab 5  
fill ~107 ~3 ~71 ~107 ~3 ~107 stone_brick_stairs 1 
setblock ~107 ~3 ~108 stone_slab 5  
fill ~108 ~3 ~43 ~110 ~3 ~43 stone_brick_stairs 2  
fill ~108 ~3 ~44 ~110 ~3 ~44 stone_brick_stairs 3  
fill ~108 ~3 ~69 ~110 ~3 ~69 stone_brick_stairs 2  
fill ~108 ~3 ~70 ~110 ~3 ~70 stone_brick_stairs 3  
fill ~111 ~3 ~43 ~111 ~3 ~44 stone_brick_stairs 1  
fill ~111 ~3 ~69 ~111 ~3 ~70 stone_brick_stairs 1  
fill ~2 ~4 ~43 ~7 ~4 ~43 stone_slab 0  
fill ~2 ~4 ~44 ~7 ~4 ~44 stone_slab 0  
fill ~2 ~4 ~69 ~7 ~4 ~69 stone_slab 0  
fill ~2 ~4 ~70 ~7 ~4 ~70 stone_slab 0  
fill ~6 ~4 ~6 ~44 ~4 ~6 stone_slab 0  
fill ~6 ~4 ~7 ~44 ~4 ~7 stone_slab 0  
fill ~6 ~4 ~8 ~7 ~4 ~8 stone_slab 0  
fill ~6 ~4 ~9 ~7 ~4 ~9 stone_slab 0  
fill ~6 ~4 ~10 ~7 ~4 ~10 stone_slab 0  
fill ~6 ~4 ~11 ~7 ~4 ~11 stone_slab 0  
fill ~6 ~4 ~12 ~7 ~4 ~12 stone_slab 0  
fill ~6 ~4 ~13 ~7 ~4 ~13 stone_slab 0  
fill ~6 ~4 ~14 ~7 ~4 ~14 stone_slab 0  
fill ~6 ~4 ~15 ~7 ~4 ~15 stone_slab 0  
fill ~6 ~4 ~16 ~7 ~4 ~16 stone_slab 0  
fill ~6 ~4 ~17 ~7 ~4 ~17 stone_slab 0  
fill ~6 ~4 ~18 ~7 ~4 ~18 stone_slab 0  
fill ~6 ~4 ~20 ~7 ~4 ~20 stone_slab 0  
fill ~6 ~4 ~21 ~7 ~4 ~21 stone_slab 0  
fill ~6 ~4 ~22 ~7 ~4 ~22 stone_slab 0  
fill ~6 ~4 ~23 ~7 ~4 ~23 stone_slab 0  
fill ~6 ~4 ~24 ~7 ~4 ~24 stone_slab 0  
fill ~6 ~4 ~25 ~7 ~4 ~25 stone_slab 0  
fill ~6 ~4 ~26 ~7 ~4 ~26 stone_slab 0  
fill ~6 ~4 ~27 ~7 ~4 ~27 stone_slab 0  
fill ~6 ~4 ~28 ~7 ~4 ~28 stone_slab 0  
fill ~6 ~4 ~29 ~7 ~4 ~29 stone_slab 0  
fill ~6 ~4 ~30 ~7 ~4 ~30 stone_slab 0  
fill ~6 ~4 ~31 ~7 ~4 ~31 stone_slab 0  
fill ~6 ~4 ~32 ~7 ~4 ~32 stone_slab 0  
fill ~6 ~4 ~33 ~7 ~4 ~33 stone_slab 0  
fill ~6 ~4 ~34 ~7 ~4 ~34 stone_slab 0  
fill ~6 ~4 ~35 ~7 ~4 ~35 stone_slab 0  
fill ~6 ~4 ~36 ~7 ~4 ~36 stone_slab 0  
fill ~6 ~4 ~37 ~7 ~4 ~37 stone_slab 0  
fill ~6 ~4 ~38 ~7 ~4 ~38 stone_slab 0  
fill ~6 ~4 ~39 ~7 ~4 ~39 stone_slab 0  
fill ~6 ~4 ~41 ~7 ~4 ~41 stone_slab 0  
fill ~6 ~4 ~42 ~7 ~4 ~42 stone_slab 0  
fill ~6 ~4 ~71 ~7 ~4 ~71 stone_slab 0  
fill ~6 ~4 ~72 ~7 ~4 ~72 stone_slab 0  
fill ~6 ~4 ~73 ~7 ~4 ~73 stone_slab 0  
fill ~6 ~4 ~74 ~7 ~4 ~74 stone_slab 0  
fill ~6 ~4 ~75 ~7 ~4 ~75 stone_slab 0  
fill ~6 ~4 ~76 ~7 ~4 ~76 stone_slab 0  
fill ~6 ~4 ~77 ~7 ~4 ~77 stone_slab 0  
fill ~6 ~4 ~78 ~7 ~4 ~78 stone_slab 0  
fill ~6 ~4 ~79 ~7 ~4 ~79 stone_slab 0  
fill ~6 ~4 ~80 ~7 ~4 ~80 stone_slab 0  
fill ~6 ~4 ~81 ~7 ~4 ~81 stone_slab 0  
fill ~6 ~4 ~82 ~7 ~4 ~82 stone_slab 0  
fill ~6 ~4 ~83 ~7 ~4 ~83 stone_slab 0  
fill ~6 ~4 ~84 ~7 ~4 ~84 stone_slab 0  
fill ~6 ~4 ~85 ~7 ~4 ~85 stone_slab 0  
fill ~6 ~4 ~86 ~7 ~4 ~86 stone_slab 0  
fill ~6 ~4 ~87 ~7 ~4 ~87 stone_slab 0  
fill ~6 ~4 ~88 ~7 ~4 ~88 stone_slab 0  
fill ~6 ~4 ~89 ~7 ~4 ~89 stone_slab 0  
fill ~6 ~4 ~90 ~7 ~4 ~90 stone_slab 0  
fill ~6 ~4 ~91 ~7 ~4 ~91 stone_slab 0  
fill ~6 ~4 ~92 ~7 ~4 ~92 stone_slab 0  
fill ~6 ~4 ~93 ~7 ~4 ~93 stone_slab 0  
fill ~6 ~4 ~94 ~7 ~4 ~94 stone_slab 0  
fill ~6 ~4 ~95 ~7 ~4 ~95 stone_slab 0  
fill ~6 ~4 ~98 ~7 ~4 ~98 stone_slab 0  
fill ~6 ~4 ~99 ~7 ~4 ~99 stone_slab 0  
fill ~6 ~4 ~100 ~7 ~4 ~100 stone_slab 0  
fill ~6 ~4 ~101 ~7 ~4 ~101 stone_slab 0  
fill ~6 ~4 ~102 ~7 ~4 ~102 stone_slab 0  
fill ~6 ~4 ~103 ~7 ~4 ~103 stone_slab 0  
fill ~6 ~4 ~104 ~7 ~4 ~104 stone_slab 0  
fill ~6 ~4 ~105 ~7 ~4 ~105 stone_slab 0  
fill ~6 ~4 ~106 ~7 ~4 ~106 stone_slab 0 
setblock ~7 ~4 ~19 stone_slab 0 
setblock ~7 ~4 ~40 stone_slab 0  
fill ~7 ~4 ~96 ~7 ~4 ~108 stone_slab 0 
setblock ~8 ~4 ~80 tallgrass 1 
setblock ~8 ~4 ~97 tallgrass 1  
fill ~8 ~4 ~106 ~9 ~4 ~106 tallgrass 1  
fill ~8 ~4 ~107 ~44 ~4 ~107 stone_slab 0  
fill ~8 ~4 ~108 ~27 ~4 ~108 stone_slab 0  
fill ~9 ~4 ~10 ~9 ~4 ~12 tallgrass 1 
setblock ~9 ~4 ~27 tallgrass 1 
setblock ~9 ~4 ~64 tallgrass 1 
setblock ~9 ~4 ~74 tallgrass 1 
setblock ~9 ~4 ~94 tallgrass 1 
setblock ~9 ~4 ~105 tallgrass 1 
setblock ~10 ~4 ~39 tallgrass 1 
setblock ~10 ~4 ~42 tallgrass 1 
setblock ~10 ~4 ~50 tallgrass 1 
setblock ~10 ~4 ~55 tallgrass 1 
setblock ~10 ~4 ~69 tallgrass 1 
setblock ~10 ~4 ~77 tallgrass 1 
setblock ~11 ~4 ~14 tallgrass 1 
setblock ~11 ~4 ~25 tallgrass 1 
setblock ~11 ~4 ~29 tallgrass 1 
setblock ~11 ~4 ~46 tallgrass 1  
fill ~11 ~4 ~81 ~11 ~4 ~82 tallgrass 1 
setblock ~11 ~4 ~103 tallgrass 1 
setblock ~12 ~4 ~44 tallgrass 1 
setblock ~12 ~4 ~59 tallgrass 1 
setblock ~12 ~4 ~74 tallgrass 1 
setblock ~12 ~4 ~89 tallgrass 1 
setblock ~12 ~4 ~92 tallgrass 1 
setblock ~12 ~4 ~99 tallgrass 1 
setblock ~13 ~4 ~16 tallgrass 1  
fill ~13 ~4 ~36 ~13 ~4 ~37 tallgrass 1 
setblock ~14 ~4 ~10 tallgrass 1 
setblock ~14 ~4 ~24 tallgrass 1 
setblock ~14 ~4 ~31 tallgrass 1 
setblock ~14 ~4 ~50 tallgrass 1 
setblock ~14 ~4 ~68 tallgrass 1 
setblock ~14 ~4 ~73 tallgrass 1 
setblock ~14 ~4 ~82 tallgrass 1 
setblock ~14 ~4 ~106 tallgrass 1 
setblock ~15 ~4 ~32 tallgrass 1  
fill ~15 ~4 ~51 ~16 ~4 ~51 tallgrass 1 
setblock ~15 ~4 ~91 tallgrass 1  
fill ~15 ~4 ~97 ~16 ~4 ~97 tallgrass 1 
setblock ~16 ~4 ~20 tallgrass 1 
setblock ~16 ~4 ~22 tallgrass 1 
setblock ~16 ~4 ~31 tallgrass 1 
setblock ~16 ~4 ~33 tallgrass 1 
setblock ~16 ~4 ~37 tallgrass 1 
setblock ~16 ~4 ~44 tallgrass 1 
setblock ~16 ~4 ~50 tallgrass 1  
fill ~16 ~4 ~63 ~16 ~4 ~64 tallgrass 1 
setblock ~16 ~4 ~68 tallgrass 1 
setblock ~16 ~4 ~71 tallgrass 1 
setblock ~16 ~4 ~103 tallgrass 1 
setblock ~17 ~4 ~11 tallgrass 1 
setblock ~17 ~4 ~49 tallgrass 1  
fill ~17 ~4 ~50 ~25 ~4 ~50 stonebrick 0  
fill ~17 ~4 ~51 ~18 ~4 ~51 stonebrick 0 
setblock ~17 ~4 ~53 tallgrass 1  
fill ~17 ~4 ~57 ~17 ~4 ~58 tallgrass 1  
fill ~17 ~4 ~62 ~18 ~4 ~62 stonebrick 0  
fill ~17 ~4 ~63 ~25 ~4 ~63 stonebrick 0 
setblock ~17 ~4 ~89 tallgrass 1 
setblock ~17 ~4 ~99 tallgrass 1 
setblock ~18 ~4 ~26 tallgrass 1  
fill ~18 ~4 ~48 ~19 ~4 ~48 tallgrass 1  
fill ~18 ~4 ~52 ~18 ~4 ~61 stone_brick_stairs 0  
fill ~18 ~4 ~64 ~19 ~4 ~64 vine 4 
setblock ~18 ~4 ~78 tallgrass 1 
setblock ~18 ~4 ~84 tallgrass 1 
setblock ~18 ~4 ~105 tallgrass 1 
setblock ~19 ~4 ~12 tallgrass 1 
setblock ~19 ~4 ~34 tallgrass 1 
setblock ~19 ~4 ~39 tallgrass 1  
fill ~19 ~4 ~49 ~19 ~6 ~49 vine 1 
setblock ~19 ~4 ~94 tallgrass 1 
setblock ~20 ~4 ~49 tallgrass 1  
fill ~20 ~4 ~64 ~22 ~4 ~64 tallgrass 1 
setblock ~20 ~4 ~87 tallgrass 1 
setblock ~20 ~4 ~97 tallgrass 1  
fill ~21 ~4 ~15 ~22 ~4 ~15 tallgrass 1  
fill ~21 ~4 ~48 ~22 ~4 ~48 tallgrass 1 
setblock ~21 ~4 ~66 tallgrass 1  
fill ~21 ~4 ~76 ~22 ~4 ~76 tallgrass 1 
setblock ~21 ~4 ~105 tallgrass 1  
fill ~22 ~4 ~28 ~23 ~4 ~28 tallgrass 1  
fill ~22 ~4 ~30 ~22 ~4 ~31 tallgrass 1  
fill ~22 ~4 ~46 ~22 ~4 ~49 tallgrass 1  
fill ~22 ~4 ~65 ~23 ~4 ~65 tallgrass 1 
setblock ~22 ~4 ~71 tallgrass 1 
setblock ~22 ~4 ~102 tallgrass 1 
setblock ~23 ~4 ~17 tallgrass 1 
setblock ~23 ~4 ~23 tallgrass 1  
fill ~23 ~4 ~24 ~23 ~4 ~25 vine 8 
setblock ~23 ~4 ~26 tallgrass 1 
setblock ~23 ~4 ~31 tallgrass 1  
fill ~23 ~4 ~33 ~23 ~4 ~34 tallgrass 1  
fill ~23 ~4 ~36 ~23 ~4 ~37 tallgrass 1 
setblock ~23 ~4 ~38 vine 8  
fill ~23 ~4 ~39 ~23 ~4 ~42 tallgrass 1 
setblock ~23 ~4 ~43 vine 8  
fill ~23 ~4 ~45 ~23 ~4 ~46 vine 8 
setblock ~23 ~4 ~47 tallgrass 1 
setblock ~23 ~4 ~49 tallgrass 1 
setblock ~23 ~4 ~64 vine 4  
fill ~23 ~4 ~67 ~23 ~4 ~68 tallgrass 1 
setblock ~23 ~4 ~70 tallgrass 1 
setblock ~23 ~4 ~72 tallgrass 1 
setblock ~23 ~4 ~75 tallgrass 1 
setblock ~23 ~4 ~77 vine 8  
fill ~23 ~4 ~78 ~23 ~4 ~80 tallgrass 1 
setblock ~23 ~4 ~81 vine 8 
setblock ~23 ~4 ~82 tallgrass 1 
setblock ~23 ~4 ~84 tallgrass 1 
setblock ~23 ~4 ~85 vine 8 
setblock ~23 ~4 ~86 tallgrass 1 
setblock ~23 ~4 ~88 tallgrass 1 
setblock ~23 ~4 ~94 tallgrass 1  
fill ~24 ~4 ~24 ~50 ~4 ~24 stonebrick 0  
fill ~24 ~4 ~25 ~24 ~4 ~50 stonebrick 0  
fill ~24 ~4 ~64 ~24 ~4 ~89 stonebrick 0 
setblock ~24 ~4 ~98 tallgrass 1 
setblock ~24 ~4 ~100 tallgrass 1 
setblock ~25 ~4 ~23 tallgrass 1  
fill ~25 ~4 ~89 ~50 ~4 ~89 stonebrick 0 
setblock ~25 ~4 ~90 tallgrass 1 
setblock ~26 ~4 ~18 tallgrass 1 
setblock ~26 ~4 ~23 vine 1  
fill ~26 ~4 ~90 ~27 ~4 ~90 vine 4 
setblock ~27 ~4 ~97 tallgrass 1 
setblock ~28 ~4 ~14 tallgrass 1 
setblock ~28 ~4 ~23 vine 1 
setblock ~28 ~4 ~90 tallgrass 1 
setblock ~29 ~4 ~10 tallgrass 1  
fill ~29 ~4 ~17 ~29 ~4 ~18 tallgrass 1 
setblock ~29 ~4 ~23 tallgrass 1 
setblock ~29 ~4 ~90 vine 4  
fill ~29 ~4 ~108 ~44 ~4 ~108 stone_slab 0 
setblock ~31 ~4 ~23 vine 1 
setblock ~31 ~4 ~90 tallgrass 1 
setblock ~31 ~4 ~94 tallgrass 1 
setblock ~31 ~4 ~104 tallgrass 1 
setblock ~32 ~4 ~11 tallgrass 1 
setblock ~32 ~4 ~14 tallgrass 1 
setblock ~32 ~4 ~23 tallgrass 1 
setblock ~32 ~4 ~101 tallgrass 1  
fill ~33 ~4 ~90 ~34 ~4 ~90 tallgrass 1 
setblock ~33 ~4 ~95 tallgrass 1 
setblock ~33 ~4 ~98 tallgrass 1 
setblock ~34 ~4 ~13 tallgrass 1 
setblock ~34 ~4 ~23 vine 1 
setblock ~34 ~4 ~104 tallgrass 1 
setblock ~36 ~4 ~15 tallgrass 1 
setblock ~36 ~4 ~23 vine 1 
setblock ~36 ~4 ~90 vine 4 
setblock ~37 ~4 ~17 tallgrass 1 
setblock ~37 ~4 ~23 tallgrass 1 
setblock ~37 ~4 ~99 tallgrass 1 
setblock ~38 ~4 ~9 tallgrass 1 
setblock ~38 ~4 ~104 tallgrass 1  
fill ~39 ~4 ~23 ~40 ~4 ~23 tallgrass 1  
fill ~39 ~4 ~90 ~41 ~4 ~90 vine 4 
setblock ~39 ~4 ~101 tallgrass 1 
setblock ~40 ~4 ~19 tallgrass 1 
setblock ~40 ~4 ~97 tallgrass 1 
setblock ~41 ~4 ~14 tallgrass 1 
setblock ~41 ~4 ~22 tallgrass 1 
setblock ~42 ~4 ~13 tallgrass 1  
fill ~43 ~4 ~3 ~44 ~4 ~3 stone_slab 0  
fill ~43 ~4 ~4 ~44 ~4 ~4 stone_slab 0  
fill ~43 ~4 ~5 ~44 ~4 ~5 stone_slab 0  
fill ~43 ~4 ~23 ~44 ~4 ~23 tallgrass 1  
fill ~43 ~4 ~90 ~45 ~4 ~90 tallgrass 1 
setblock ~43 ~4 ~95 tallgrass 1  
fill ~43 ~4 ~109 ~44 ~4 ~109 stone_slab 0  
fill ~43 ~4 ~110 ~44 ~4 ~110 stone_slab 0  
fill ~43 ~4 ~111 ~44 ~4 ~111 stone_slab 0  
fill ~43 ~4 ~112 ~44 ~4 ~112 stone_slab 0 
setblock ~44 ~4 ~2 stone_slab 0 
setblock ~44 ~4 ~22 tallgrass 1 
setblock ~44 ~4 ~97 tallgrass 1 
setblock ~45 ~4 ~11 tallgrass 1 
setblock ~45 ~4 ~16 tallgrass 1 
setblock ~45 ~4 ~18 tallgrass 1 
setblock ~45 ~4 ~100 tallgrass 1  
fill ~46 ~4 ~22 ~46 ~4 ~23 tallgrass 1 
setblock ~46 ~4 ~90 vine 4 
setblock ~46 ~4 ~102 tallgrass 1  
fill ~47 ~4 ~90 ~49 ~4 ~90 tallgrass 1  
fill ~47 ~4 ~91 ~48 ~4 ~91 tallgrass 1 
setblock ~48 ~4 ~10 tallgrass 1 
setblock ~48 ~4 ~13 tallgrass 1  
fill ~48 ~4 ~19 ~49 ~4 ~19 tallgrass 1  
fill ~48 ~4 ~20 ~48 ~4 ~23 tallgrass 1  
fill ~48 ~4 ~92 ~49 ~4 ~92 tallgrass 1 
setblock ~49 ~4 ~18 vine 8  
fill ~49 ~4 ~20 ~49 ~6 ~20 vine 8  
fill ~49 ~4 ~21 ~49 ~4 ~23 tallgrass 1  
fill ~49 ~4 ~93 ~49 ~4 ~94 tallgrass 1  
fill ~49 ~4 ~95 ~49 ~4 ~96 vine 8 
setblock ~49 ~4 ~104 tallgrass 1 
setblock ~50 ~4 ~16 tallgrass 1  
fill ~50 ~4 ~17 ~51 ~4 ~17 stonebrick 0  
fill ~50 ~4 ~18 ~51 ~4 ~18 stonebrick 0  
fill ~50 ~4 ~19 ~50 ~6 ~19 stonebrick 0  
fill ~50 ~4 ~20 ~50 ~6 ~20 stonebrick 0  
fill ~50 ~4 ~21 ~50 ~7 ~21 stonebrick 0  
fill ~50 ~4 ~22 ~50 ~8 ~22 stonebrick 0  
fill ~50 ~4 ~23 ~50 ~9 ~23 stonebrick 0  
fill ~50 ~4 ~25 ~50 ~10 ~25 stonebrick 0  
fill ~50 ~4 ~88 ~50 ~10 ~88 stonebrick 0  
fill ~50 ~4 ~90 ~50 ~9 ~90 stonebrick 0  
fill ~50 ~4 ~91 ~50 ~8 ~91 stonebrick 0  
fill ~50 ~4 ~92 ~50 ~7 ~92 stonebrick 0  
fill ~50 ~4 ~93 ~50 ~6 ~93 stonebrick 0  
fill ~50 ~4 ~94 ~50 ~6 ~94 stonebrick 0  
fill ~50 ~4 ~95 ~51 ~4 ~95 stonebrick 0  
fill ~50 ~4 ~96 ~51 ~4 ~96 stonebrick 0 
setblock ~50 ~4 ~97 vine 4 
setblock ~51 ~4 ~10 tallgrass 1 
setblock ~51 ~4 ~16 vine 1 
setblock ~51 ~4 ~97 tallgrass 1 
setblock ~52 ~4 ~14 tallgrass 1  
fill ~52 ~4 ~18 ~61 ~4 ~18 stone_brick_stairs 2  
fill ~52 ~4 ~95 ~61 ~4 ~95 stone_brick_stairs 3 
setblock ~52 ~4 ~102 tallgrass 1  
fill ~53 ~4 ~11 ~54 ~4 ~11 tallgrass 1 
setblock ~53 ~4 ~17 tallgrass 1  
fill ~53 ~4 ~96 ~53 ~4 ~97 tallgrass 1 
setblock ~53 ~4 ~100 tallgrass 1 
setblock ~55 ~4 ~96 tallgrass 1  
fill ~55 ~4 ~100 ~56 ~4 ~100 tallgrass 1 
setblock ~57 ~4 ~14 tallgrass 1 
setblock ~58 ~4 ~11 tallgrass 1 
setblock ~59 ~4 ~17 tallgrass 1 
setblock ~60 ~4 ~104 tallgrass 1 
setblock ~61 ~4 ~10 tallgrass 1  
fill ~61 ~4 ~97 ~63 ~4 ~97 tallgrass 1 
setblock ~62 ~4 ~16 tallgrass 1  
fill ~62 ~4 ~17 ~63 ~4 ~17 stonebrick 0  
fill ~62 ~4 ~18 ~63 ~4 ~18 stonebrick 0  
fill ~62 ~4 ~95 ~63 ~4 ~95 stonebrick 0  
fill ~62 ~4 ~96 ~63 ~4 ~96 stonebrick 0 
setblock ~62 ~4 ~98 tallgrass 1 
setblock ~63 ~4 ~13 tallgrass 1 
setblock ~63 ~4 ~16 vine 1  
fill ~63 ~4 ~19 ~63 ~6 ~19 stonebrick 0  
fill ~63 ~4 ~20 ~63 ~6 ~20 stonebrick 0  
fill ~63 ~4 ~21 ~63 ~7 ~21 stonebrick 0  
fill ~63 ~4 ~22 ~63 ~8 ~22 stonebrick 0  
fill ~63 ~4 ~23 ~63 ~9 ~23 stonebrick 0  
fill ~63 ~4 ~24 ~89 ~4 ~24 stonebrick 0  
fill ~63 ~4 ~25 ~63 ~10 ~25 stonebrick 0  
fill ~63 ~4 ~88 ~63 ~10 ~88 stonebrick 0  
fill ~63 ~4 ~89 ~89 ~4 ~89 stonebrick 0  
fill ~63 ~4 ~90 ~63 ~9 ~90 stonebrick 0  
fill ~63 ~4 ~91 ~63 ~8 ~91 stonebrick 0  
fill ~63 ~4 ~92 ~63 ~7 ~92 stonebrick 0  
fill ~63 ~4 ~93 ~63 ~6 ~93 stonebrick 0  
fill ~63 ~4 ~94 ~63 ~6 ~94 stonebrick 0 
setblock ~63 ~4 ~106 tallgrass 1  
fill ~64 ~4 ~17 ~65 ~4 ~17 tallgrass 1  
fill ~64 ~4 ~18 ~64 ~4 ~19 tallgrass 1  
fill ~64 ~4 ~21 ~66 ~4 ~21 tallgrass 1  
fill ~64 ~4 ~22 ~64 ~4 ~23 tallgrass 1  
fill ~64 ~4 ~90 ~64 ~4 ~93 tallgrass 1  
fill ~64 ~4 ~94 ~64 ~4 ~96 vine 2 
setblock ~65 ~4 ~10 tallgrass 1 
setblock ~65 ~4 ~20 tallgrass 1 
setblock ~65 ~4 ~23 tallgrass 1 
setblock ~65 ~4 ~91 tallgrass 1  
fill ~65 ~4 ~93 ~65 ~4 ~94 tallgrass 1  
fill ~66 ~4 ~18 ~66 ~4 ~19 tallgrass 1 
setblock ~66 ~4 ~23 vine 1 
setblock ~66 ~4 ~90 tallgrass 1 
setblock ~66 ~4 ~105 tallgrass 1 
setblock ~67 ~4 ~8 tallgrass 1 
setblock ~67 ~4 ~12 tallgrass 1 
setblock ~67 ~4 ~16 tallgrass 1  
fill ~67 ~4 ~91 ~68 ~4 ~91 tallgrass 1  
fill ~67 ~4 ~92 ~67 ~4 ~91 tallgrass 1 
setblock ~68 ~4 ~23 vine 1  
fill ~68 ~4 ~90 ~70 ~4 ~90 vine 4 
setblock ~68 ~4 ~103 tallgrass 1  
fill ~69 ~4 ~2 ~70 ~4 ~2 stone_slab 0  
fill ~69 ~4 ~3 ~70 ~4 ~3 stone_slab 0  
fill ~69 ~4 ~4 ~70 ~4 ~4 stone_slab 0  
fill ~69 ~4 ~5 ~70 ~4 ~5 stone_slab 0  
fill ~69 ~4 ~6 ~88 ~4 ~6 stone_slab 0  
fill ~69 ~4 ~7 ~107 ~4 ~7 stone_slab 0 
setblock ~69 ~4 ~13 tallgrass 1 
setblock ~69 ~4 ~20 tallgrass 1 
setblock ~69 ~4 ~100 tallgrass 1  
fill ~69 ~4 ~107 ~107 ~4 ~107 stone_slab 0  
fill ~69 ~4 ~108 ~85 ~4 ~108 stone_slab 0  
fill ~69 ~4 ~109 ~70 ~4 ~109 stone_slab 0  
fill ~69 ~4 ~110 ~70 ~4 ~110 stone_slab 0  
fill ~69 ~4 ~111 ~70 ~4 ~111 stone_slab 0  
fill ~69 ~4 ~112 ~70 ~4 ~112 stone_slab 0  
fill ~70 ~4 ~14 ~72 ~4 ~14 tallgrass 1 
setblock ~70 ~4 ~95 tallgrass 1  
fill ~71 ~4 ~23 ~72 ~4 ~23 tallgrass 1 
setblock ~71 ~4 ~90 tallgrass 1 
setblock ~72 ~4 ~15 tallgrass 1 
setblock ~73 ~4 ~13 tallgrass 1 
setblock ~73 ~4 ~22 tallgrass 1 
setblock ~73 ~4 ~94 tallgrass 1 
setblock ~74 ~4 ~9 tallgrass 1  
fill ~74 ~4 ~12 ~75 ~4 ~12 tallgrass 1 
setblock ~74 ~4 ~19 tallgrass 1  
fill ~74 ~4 ~23 ~78 ~4 ~23 tallgrass 1  
fill ~74 ~4 ~90 ~75 ~4 ~90 vine 4 
setblock ~75 ~4 ~10 tallgrass 1 
setblock ~75 ~4 ~95 tallgrass 1 
setblock ~75 ~4 ~98 tallgrass 1 
setblock ~76 ~4 ~19 tallgrass 1 
setblock ~76 ~4 ~90 tallgrass 1 
setblock ~76 ~4 ~101 tallgrass 1 
setblock ~77 ~4 ~103 tallgrass 1 
setblock ~78 ~4 ~90 tallgrass 1 
setblock ~79 ~4 ~9 tallgrass 1 
setblock ~79 ~4 ~104 tallgrass 1 
setblock ~80 ~4 ~16 tallgrass 1 
setblock ~80 ~4 ~23 vine 1  
fill ~80 ~4 ~90 ~81 ~4 ~90 tallgrass 1 
setblock ~81 ~4 ~23 tallgrass 1 
setblock ~81 ~4 ~105 tallgrass 1  
fill ~82 ~4 ~10 ~83 ~4 ~10 tallgrass 1 
setblock ~82 ~4 ~90 vine 4 
setblock ~82 ~4 ~99 tallgrass 1 
setblock ~83 ~4 ~19 tallgrass 1 
setblock ~83 ~4 ~23 tallgrass 1 
setblock ~83 ~4 ~96 tallgrass 1 
setblock ~83 ~4 ~101 tallgrass 1  
fill ~84 ~4 ~23 ~85 ~4 ~23 vine 1  
fill ~85 ~4 ~11 ~86 ~4 ~11 tallgrass 1 
setblock ~85 ~4 ~18 tallgrass 1  
fill ~85 ~4 ~90 ~86 ~4 ~90 vine 4 
setblock ~85 ~4 ~94 tallgrass 1 
setblock ~86 ~4 ~23 tallgrass 1 
setblock ~86 ~4 ~98 tallgrass 1 
setblock ~86 ~4 ~101 tallgrass 1  
fill ~87 ~4 ~12 ~88 ~4 ~12 tallgrass 1  
fill ~87 ~4 ~108 ~107 ~4 ~108 stone_slab 0 
setblock ~88 ~4 ~16 tallgrass 1  
fill ~88 ~4 ~23 ~90 ~4 ~23 tallgrass 1 
setblock ~88 ~4 ~25 double_stone_slab 0  
fill ~88 ~4 ~50 ~96 ~4 ~50 stonebrick 0  
fill ~88 ~4 ~63 ~96 ~4 ~63 stonebrick 0 
setblock ~88 ~4 ~90 tallgrass 1 
setblock ~88 ~4 ~103 tallgrass 1 
setblock ~89 ~4 ~22 stone_slab 0  
fill ~89 ~4 ~25 ~89 ~4 ~50 stonebrick 0  
fill ~89 ~4 ~64 ~89 ~4 ~89 stonebrick 0 
setblock ~90 ~4 ~17 tallgrass 1  
fill ~90 ~4 ~24 ~90 ~4 ~25 vine 2 
setblock ~90 ~4 ~26 tallgrass 1 
setblock ~90 ~4 ~29 tallgrass 1 
setblock ~90 ~4 ~31 vine 2 
setblock ~90 ~4 ~32 tallgrass 1  
fill ~90 ~4 ~34 ~90 ~4 ~35 vine 2  
fill ~90 ~4 ~38 ~90 ~4 ~42 tallgrass 1 
setblock ~90 ~4 ~45 vine 2  
fill ~90 ~4 ~48 ~93 ~4 ~48 tallgrass 1  
fill ~90 ~4 ~49 ~90 ~4 ~48 tallgrass 1  
fill ~90 ~4 ~64 ~93 ~4 ~64 tallgrass 1  
fill ~90 ~4 ~65 ~91 ~4 ~65 tallgrass 1  
fill ~90 ~4 ~66 ~91 ~4 ~66 tallgrass 1  
fill ~90 ~4 ~67 ~90 ~4 ~64 tallgrass 1  
fill ~90 ~4 ~69 ~90 ~4 ~70 vine 2 
setblock ~90 ~4 ~71 tallgrass 1 
setblock ~90 ~4 ~73 tallgrass 1 
setblock ~90 ~4 ~75 vine 2  
fill ~90 ~4 ~77 ~90 ~4 ~81 tallgrass 1  
fill ~90 ~4 ~82 ~90 ~4 ~83 vine 2 
setblock ~90 ~4 ~84 tallgrass 1 
setblock ~90 ~4 ~86 tallgrass 1  
fill ~90 ~4 ~88 ~90 ~4 ~90 tallgrass 1 
setblock ~90 ~4 ~105 tallgrass 1  
fill ~91 ~4 ~6 ~106 ~4 ~6 stone_slab 0  
fill ~91 ~4 ~49 ~91 ~8 ~49 vine 1  
fill ~92 ~4 ~11 ~93 ~4 ~11 tallgrass 1 
setblock ~92 ~4 ~47 tallgrass 1  
fill ~92 ~4 ~101 ~93 ~4 ~101 tallgrass 1 
setblock ~93 ~4 ~31 tallgrass 1 
setblock ~93 ~4 ~33 tallgrass 1 
setblock ~93 ~4 ~49 tallgrass 1  
fill ~93 ~4 ~65 ~94 ~4 ~65 tallgrass 1  
fill ~93 ~4 ~66 ~93 ~4 ~67 tallgrass 1 
setblock ~93 ~4 ~78 tallgrass 1 
setblock ~93 ~4 ~105 tallgrass 1 
setblock ~94 ~4 ~16 tallgrass 1 
setblock ~94 ~4 ~23 tallgrass 1 
setblock ~94 ~4 ~25 tallgrass 1 
setblock ~94 ~4 ~44 tallgrass 1  
fill ~94 ~4 ~49 ~94 ~6 ~49 vine 1  
fill ~94 ~4 ~64 ~95 ~4 ~64 vine 4 
setblock ~94 ~4 ~84 tallgrass 1 
setblock ~94 ~4 ~95 tallgrass 1 
setblock ~95 ~4 ~10 tallgrass 1 
setblock ~95 ~4 ~42 tallgrass 1 
setblock ~95 ~4 ~48 stone_slab 0 
setblock ~95 ~4 ~49 tallgrass 1  
fill ~95 ~4 ~51 ~96 ~4 ~51 stonebrick 0  
fill ~95 ~4 ~52 ~95 ~4 ~61 stone_brick_stairs 1  
fill ~95 ~4 ~62 ~96 ~4 ~62 stonebrick 0 
setblock ~95 ~4 ~75 tallgrass 1 
setblock ~95 ~4 ~82 tallgrass 1  
fill ~95 ~4 ~88 ~96 ~4 ~88 tallgrass 1 
setblock ~96 ~4 ~34 tallgrass 1 
setblock ~96 ~4 ~52 tallgrass 1 
setblock ~96 ~4 ~54 tallgrass 1 
setblock ~96 ~4 ~59 tallgrass 1 
setblock ~96 ~4 ~61 tallgrass 1 
setblock ~96 ~4 ~74 tallgrass 1 
setblock ~96 ~4 ~78 tallgrass 1 
setblock ~96 ~4 ~96 tallgrass 1 
setblock ~96 ~4 ~102 tallgrass 1 
setblock ~97 ~4 ~17 tallgrass 1 
setblock ~97 ~4 ~22 tallgrass 1 
setblock ~97 ~4 ~25 tallgrass 1 
setblock ~97 ~4 ~29 tallgrass 1 
setblock ~97 ~4 ~50 tallgrass 1 
setblock ~97 ~4 ~51 vine 2  
fill ~97 ~4 ~63 ~97 ~4 ~64 tallgrass 1 
setblock ~97 ~4 ~91 tallgrass 1  
fill ~98 ~4 ~11 ~98 ~4 ~12 tallgrass 1 
setblock ~98 ~4 ~35 tallgrass 1 
setblock ~98 ~4 ~42 tallgrass 1 
setblock ~98 ~4 ~45 tallgrass 1 
setblock ~98 ~4 ~51 tallgrass 1 
setblock ~98 ~4 ~67 tallgrass 1 
setblock ~98 ~4 ~84 tallgrass 1 
setblock ~98 ~4 ~93 tallgrass 1 
setblock ~99 ~4 ~13 tallgrass 1 
setblock ~99 ~4 ~28 tallgrass 1 
setblock ~99 ~4 ~56 tallgrass 1 
setblock ~99 ~4 ~65 tallgrass 1  
fill ~99 ~4 ~78 ~99 ~4 ~79 tallgrass 1 
setblock ~99 ~4 ~103 tallgrass 1 
setblock ~100 ~4 ~41 tallgrass 1 
setblock ~100 ~4 ~48 tallgrass 1 
setblock ~100 ~4 ~55 tallgrass 1  
fill ~101 ~4 ~19 ~101 ~4 ~20 tallgrass 1 
setblock ~101 ~4 ~28 tallgrass 1  
fill ~101 ~4 ~53 ~101 ~4 ~54 tallgrass 1  
fill ~101 ~4 ~61 ~101 ~4 ~62 tallgrass 1 
setblock ~101 ~4 ~71 tallgrass 1 
setblock ~101 ~4 ~83 tallgrass 1 
setblock ~102 ~4 ~13 tallgrass 1 
setblock ~102 ~4 ~23 tallgrass 1 
setblock ~102 ~4 ~36 tallgrass 1 
setblock ~102 ~4 ~41 tallgrass 1 
setblock ~102 ~4 ~64 tallgrass 1 
setblock ~102 ~4 ~66 tallgrass 1 
setblock ~102 ~4 ~78 tallgrass 1 
setblock ~102 ~4 ~91 tallgrass 1 
setblock ~102 ~4 ~95 tallgrass 1 
setblock ~102 ~4 ~100 tallgrass 1 
setblock ~103 ~4 ~11 tallgrass 1 
setblock ~103 ~4 ~27 tallgrass 1 
setblock ~103 ~4 ~38 tallgrass 1 
setblock ~103 ~4 ~48 tallgrass 1 
setblock ~103 ~4 ~51 tallgrass 1 
setblock ~103 ~4 ~57 tallgrass 1 
setblock ~103 ~4 ~69 tallgrass 1 
setblock ~103 ~4 ~83 tallgrass 1 
setblock ~103 ~4 ~106 tallgrass 1 
setblock ~104 ~4 ~80 tallgrass 1 
setblock ~104 ~4 ~98 tallgrass 1 
setblock ~104 ~4 ~102 tallgrass 1  
fill ~104 ~4 ~104 ~104 ~4 ~105 tallgrass 1 
setblock ~105 ~4 ~8 tallgrass 1 
setblock ~105 ~4 ~27 tallgrass 1 
setblock ~105 ~4 ~53 tallgrass 1 
setblock ~105 ~4 ~72 tallgrass 1  
fill ~106 ~4 ~8 ~107 ~4 ~8 stone_slab 0  
fill ~106 ~4 ~9 ~107 ~4 ~9 stone_slab 0  
fill ~106 ~4 ~10 ~107 ~4 ~10 stone_slab 0  
fill ~106 ~4 ~11 ~107 ~4 ~11 stone_slab 0  
fill ~106 ~4 ~12 ~107 ~4 ~12 stone_slab 0  
fill ~106 ~4 ~13 ~107 ~4 ~13 stone_slab 0  
fill ~106 ~4 ~14 ~107 ~4 ~14 stone_slab 0  
fill ~106 ~4 ~15 ~107 ~4 ~15 stone_slab 0  
fill ~106 ~4 ~16 ~106 ~4 ~44 stone_slab 0  
fill ~106 ~4 ~69 ~111 ~4 ~69 stone_slab 0  
fill ~106 ~4 ~70 ~111 ~4 ~70 stone_slab 0  
fill ~106 ~4 ~71 ~107 ~4 ~71 stone_slab 0  
fill ~106 ~4 ~72 ~107 ~4 ~72 stone_slab 0  
fill ~106 ~4 ~73 ~107 ~4 ~73 stone_slab 0  
fill ~106 ~4 ~74 ~107 ~4 ~74 stone_slab 0  
fill ~106 ~4 ~75 ~107 ~4 ~75 stone_slab 0  
fill ~106 ~4 ~76 ~107 ~4 ~76 stone_slab 0  
fill ~106 ~4 ~77 ~107 ~4 ~77 stone_slab 0  
fill ~106 ~4 ~78 ~107 ~4 ~78 stone_slab 0  
fill ~106 ~4 ~79 ~107 ~4 ~79 stone_slab 0  
fill ~106 ~4 ~80 ~107 ~4 ~80 stone_slab 0  
fill ~106 ~4 ~81 ~107 ~4 ~81 stone_slab 0  
fill ~106 ~4 ~82 ~107 ~4 ~82 stone_slab 0  
fill ~106 ~4 ~83 ~107 ~4 ~83 stone_slab 0  
fill ~106 ~4 ~84 ~107 ~4 ~84 stone_slab 0  
fill ~106 ~4 ~85 ~107 ~4 ~85 stone_slab 0  
fill ~106 ~4 ~86 ~107 ~4 ~86 stone_slab 0  
fill ~106 ~4 ~87 ~107 ~4 ~87 stone_slab 0  
fill ~106 ~4 ~88 ~107 ~4 ~88 stone_slab 0  
fill ~106 ~4 ~89 ~107 ~4 ~89 stone_slab 0  
fill ~106 ~4 ~90 ~107 ~4 ~90 stone_slab 0  
fill ~106 ~4 ~91 ~107 ~4 ~91 stone_slab 0  
fill ~106 ~4 ~92 ~107 ~4 ~92 stone_slab 0  
fill ~106 ~4 ~93 ~107 ~4 ~93 stone_slab 0  
fill ~106 ~4 ~94 ~107 ~4 ~94 stone_slab 0  
fill ~106 ~4 ~95 ~107 ~4 ~95 stone_slab 0  
fill ~106 ~4 ~96 ~107 ~4 ~96 stone_slab 0  
fill ~106 ~4 ~97 ~107 ~4 ~97 stone_slab 0  
fill ~106 ~4 ~98 ~107 ~4 ~98 stone_slab 0  
fill ~106 ~4 ~99 ~107 ~4 ~99 stone_slab 0  
fill ~106 ~4 ~100 ~107 ~4 ~100 stone_slab 0  
fill ~106 ~4 ~101 ~107 ~4 ~101 stone_slab 0  
fill ~106 ~4 ~102 ~107 ~4 ~102 stone_slab 0  
fill ~106 ~4 ~103 ~107 ~4 ~103 stone_slab 0  
fill ~106 ~4 ~104 ~107 ~4 ~104 stone_slab 0  
fill ~106 ~4 ~105 ~107 ~4 ~105 stone_slab 0  
fill ~106 ~4 ~106 ~107 ~4 ~106 stone_slab 0  
fill ~107 ~4 ~17 ~107 ~4 ~44 stone_slab 0  
fill ~108 ~4 ~43 ~111 ~4 ~43 stone_slab 0  
fill ~108 ~4 ~44 ~111 ~4 ~44 stone_slab 0  
fill ~17 ~5 ~50 ~17 ~5 ~51 stone_slab 6  
fill ~17 ~5 ~62 ~17 ~5 ~63 stone_slab 6  
fill ~18 ~5 ~50 ~26 ~5 ~50 stonebrick 0  
fill ~18 ~5 ~51 ~21 ~5 ~51 stonebrick 0  
fill ~18 ~5 ~62 ~20 ~5 ~62 stonebrick 0  
fill ~18 ~5 ~63 ~26 ~5 ~63 stonebrick 0  
fill ~18 ~5 ~64 ~22 ~5 ~64 vine 4  
fill ~19 ~5 ~52 ~19 ~5 ~61 stone_brick_stairs 0  
fill ~20 ~5 ~52 ~20 ~5 ~61 double_stone_slab 0  
fill ~21 ~5 ~52 ~21 ~5 ~61 stonebrick 0  
fill ~22 ~5 ~49 ~24 ~5 ~49 vine 1 
setblock ~24 ~5 ~26 vine 8 
setblock ~24 ~5 ~29 vine 8  
fill ~24 ~5 ~31 ~24 ~5 ~36 vine 8 
setblock ~24 ~5 ~40 vine 8 
setblock ~24 ~5 ~43 vine 8 
setblock ~24 ~5 ~46 vine 8  
fill ~24 ~5 ~64 ~24 ~5 ~65 vine 8 
setblock ~24 ~5 ~70 vine 8 
setblock ~24 ~5 ~73 vine 8  
fill ~24 ~5 ~79 ~24 ~5 ~81 vine 8 
setblock ~24 ~5 ~83 vine 8 
setblock ~24 ~5 ~85 vine 8 
setblock ~24 ~5 ~87 vine 8  
fill ~25 ~5 ~25 ~50 ~5 ~25 stonebrick 0  
fill ~25 ~5 ~26 ~25 ~5 ~50 stonebrick 0  
fill ~25 ~5 ~64 ~25 ~5 ~88 stonebrick 0 
setblock ~26 ~5 ~24 vine 1  
fill ~26 ~5 ~88 ~50 ~5 ~88 stonebrick 0 
setblock ~26 ~5 ~89 vine 4 
setblock ~29 ~5 ~24 vine 1 
setblock ~32 ~5 ~24 vine 1  
fill ~32 ~5 ~89 ~35 ~5 ~89 vine 4  
fill ~38 ~5 ~24 ~39 ~5 ~24 vine 1 
setblock ~39 ~5 ~89 vine 4 
setblock ~41 ~5 ~89 vine 4 
setblock ~42 ~5 ~24 vine 1 
setblock ~45 ~5 ~89 vine 4  
fill ~46 ~5 ~24 ~47 ~5 ~24 vine 1 
setblock ~48 ~5 ~89 vine 4 
setblock ~49 ~5 ~19 vine 8  
fill ~49 ~5 ~21 ~49 ~6 ~21 vine 8  
fill ~49 ~5 ~22 ~49 ~8 ~22 vine 8  
fill ~49 ~5 ~24 ~49 ~9 ~24 vine 8  
fill ~49 ~5 ~89 ~49 ~7 ~89 vine 8  
fill ~49 ~5 ~90 ~49 ~9 ~90 vine 8  
fill ~49 ~5 ~93 ~49 ~6 ~93 vine 8  
fill ~49 ~5 ~94 ~49 ~5 ~93 vine 8  
fill ~50 ~5 ~17 ~51 ~5 ~17 stone_slab 6  
fill ~50 ~5 ~18 ~51 ~5 ~18 stonebrick 0  
fill ~50 ~5 ~24 ~50 ~9 ~24 stonebrick 0  
fill ~50 ~5 ~26 ~50 ~11 ~26 stonebrick 0  
fill ~50 ~5 ~87 ~50 ~11 ~87 stonebrick 0  
fill ~50 ~5 ~89 ~50 ~9 ~89 stonebrick 0  
fill ~50 ~5 ~95 ~51 ~5 ~95 stonebrick 0  
fill ~50 ~5 ~96 ~51 ~5 ~96 stone_slab 6  
fill ~51 ~5 ~19 ~51 ~6 ~19 stonebrick 0  
fill ~51 ~5 ~20 ~51 ~6 ~20 stonebrick 0  
fill ~51 ~5 ~92 ~61 ~5 ~92 stonebrick 0  
fill ~51 ~5 ~93 ~51 ~6 ~93 stonebrick 0  
fill ~51 ~5 ~94 ~51 ~6 ~94 stonebrick 0  
fill ~52 ~5 ~19 ~61 ~5 ~19 stone_brick_stairs 2  
fill ~52 ~5 ~20 ~61 ~5 ~20 double_stone_slab 0  
fill ~52 ~5 ~21 ~63 ~5 ~21 stonebrick 0  
fill ~52 ~5 ~93 ~61 ~5 ~93 double_stone_slab 0  
fill ~52 ~5 ~94 ~61 ~5 ~94 stone_brick_stairs 3 
setblock ~52 ~5 ~95 vine 2  
fill ~62 ~5 ~17 ~63 ~5 ~17 stone_slab 6  
fill ~62 ~5 ~18 ~63 ~5 ~18 stonebrick 0  
fill ~62 ~5 ~19 ~62 ~6 ~19 stonebrick 0  
fill ~62 ~5 ~20 ~62 ~6 ~20 stonebrick 0  
fill ~62 ~5 ~93 ~62 ~6 ~93 stonebrick 0  
fill ~62 ~5 ~94 ~62 ~6 ~94 stonebrick 0  
fill ~62 ~5 ~95 ~63 ~5 ~95 stonebrick 0  
fill ~62 ~5 ~96 ~63 ~5 ~96 stone_slab 6  
fill ~63 ~5 ~24 ~63 ~9 ~24 stonebrick 0  
fill ~63 ~5 ~26 ~63 ~11 ~26 stonebrick 0  
fill ~63 ~5 ~87 ~63 ~11 ~87 stonebrick 0  
fill ~63 ~5 ~89 ~63 ~9 ~89 stonebrick 0  
fill ~64 ~5 ~22 ~64 ~7 ~22 vine 2  
fill ~64 ~5 ~23 ~64 ~9 ~23 vine 2  
fill ~64 ~5 ~24 ~64 ~9 ~24 vine 2  
fill ~64 ~5 ~25 ~87 ~5 ~25 stonebrick 0  
fill ~64 ~5 ~88 ~88 ~5 ~88 stonebrick 0  
fill ~64 ~5 ~89 ~64 ~5 ~92 vine 2 
setblock ~64 ~5 ~95 vine 2 
setblock ~66 ~5 ~24 vine 1 
setblock ~67 ~5 ~89 vine 4 
setblock ~68 ~5 ~24 vine 1 
setblock ~71 ~5 ~24 vine 1 
setblock ~73 ~5 ~24 vine 1 
setblock ~73 ~5 ~89 vine 4  
fill ~75 ~5 ~24 ~78 ~5 ~24 vine 1  
fill ~77 ~5 ~89 ~79 ~5 ~89 vine 4  
fill ~81 ~5 ~89 ~82 ~5 ~89 vine 4 
setblock ~83 ~5 ~24 vine 1 
setblock ~84 ~5 ~89 vine 4 
setblock ~87 ~5 ~24 vine 1  
fill ~87 ~5 ~50 ~95 ~5 ~50 stonebrick 0  
fill ~87 ~5 ~63 ~95 ~5 ~63 stonebrick 0 
setblock ~87 ~5 ~89 vine 4 
setblock ~88 ~5 ~24 stone_slab 0  
fill ~88 ~5 ~26 ~88 ~5 ~50 stonebrick 0  
fill ~88 ~5 ~64 ~88 ~5 ~88 stonebrick 0 
setblock ~89 ~5 ~26 vine 2 
setblock ~89 ~5 ~29 vine 2 
setblock ~89 ~5 ~32 vine 2  
fill ~89 ~5 ~38 ~89 ~5 ~42 vine 2  
fill ~89 ~5 ~45 ~89 ~5 ~48 vine 2  
fill ~89 ~5 ~49 ~91 ~5 ~49 vine 1  
fill ~89 ~5 ~64 ~89 ~5 ~67 vine 2 
setblock ~89 ~5 ~69 vine 2 
setblock ~89 ~5 ~72 vine 2 
setblock ~89 ~5 ~74 vine 2  
fill ~89 ~5 ~76 ~89 ~5 ~77 vine 2  
fill ~89 ~5 ~81 ~89 ~5 ~82 vine 2  
fill ~91 ~5 ~64 ~92 ~5 ~64 vine 4  
fill ~92 ~5 ~52 ~92 ~5 ~63 stonebrick 0  
fill ~93 ~5 ~51 ~95 ~5 ~51 stonebrick 0  
fill ~93 ~5 ~52 ~93 ~5 ~61 double_stone_slab 0  
fill ~93 ~5 ~62 ~95 ~5 ~62 stonebrick 0  
fill ~94 ~5 ~52 ~94 ~5 ~61 stone_brick_stairs 1 
setblock ~95 ~5 ~49 vine 1 
setblock ~95 ~5 ~52 vine 4 
setblock ~95 ~5 ~61 vine 1 
setblock ~95 ~5 ~64 vine 4  
fill ~96 ~5 ~50 ~96 ~5 ~51 stone_slab 6  
fill ~96 ~5 ~62 ~96 ~5 ~63 stone_slab 6  
fill ~18 ~6 ~50 ~18 ~6 ~51 stone_slab 0  
fill ~18 ~6 ~62 ~18 ~6 ~63 stone_slab 0  
fill ~19 ~6 ~50 ~27 ~6 ~50 stonebrick 0  
fill ~19 ~6 ~51 ~22 ~6 ~51 stonebrick 0  
fill ~19 ~6 ~62 ~22 ~6 ~62 stonebrick 0  
fill ~19 ~6 ~63 ~27 ~6 ~63 stonebrick 0  
fill ~19 ~6 ~64 ~22 ~6 ~64 vine 4 
setblock ~20 ~6 ~52 vine 4 
setblock ~20 ~6 ~61 vine 1  
fill ~21 ~6 ~52 ~21 ~6 ~61 stone_brick_stairs 0  
fill ~22 ~6 ~49 ~24 ~6 ~49 vine 1  
fill ~22 ~6 ~52 ~22 ~6 ~63 stonebrick 0 
setblock ~25 ~6 ~28 vine 8  
fill ~25 ~6 ~32 ~25 ~6 ~34 vine 8 
setblock ~25 ~6 ~36 vine 8 
setblock ~25 ~6 ~39 vine 8  
fill ~25 ~6 ~42 ~25 ~6 ~43 vine 8 
setblock ~25 ~6 ~46 vine 8 
setblock ~25 ~6 ~48 vine 8  
fill ~25 ~6 ~64 ~25 ~9 ~64 vine 4 
setblock ~25 ~6 ~67 vine 8  
fill ~25 ~6 ~72 ~25 ~6 ~76 vine 8  
fill ~26 ~6 ~26 ~50 ~6 ~26 stonebrick 0  
fill ~26 ~6 ~27 ~26 ~6 ~50 stonebrick 0  
fill ~26 ~6 ~64 ~26 ~6 ~87 stonebrick 0 
setblock ~27 ~6 ~25 vine 1  
fill ~27 ~6 ~87 ~50 ~6 ~87 stonebrick 0 
setblock ~29 ~6 ~25 vine 1 
setblock ~29 ~6 ~88 vine 4 
setblock ~31 ~6 ~88 vine 4 
setblock ~33 ~6 ~25 vine 1  
fill ~37 ~6 ~25 ~39 ~6 ~25 vine 1 
setblock ~37 ~6 ~88 vine 4 
setblock ~42 ~6 ~25 vine 1 
setblock ~43 ~6 ~88 vine 4 
setblock ~44 ~6 ~25 vine 1 
setblock ~47 ~6 ~25 vine 1  
fill ~49 ~6 ~23 ~49 ~7 ~23 vine 8  
fill ~49 ~6 ~88 ~49 ~10 ~88 vine 8  
fill ~50 ~6 ~18 ~51 ~6 ~18 stone_slab 0  
fill ~50 ~6 ~27 ~50 ~12 ~27 stonebrick 0  
fill ~50 ~6 ~86 ~50 ~12 ~86 stonebrick 0  
fill ~50 ~6 ~95 ~51 ~6 ~95 stone_slab 0  
fill ~51 ~6 ~21 ~51 ~7 ~21 stonebrick 0  
fill ~51 ~6 ~22 ~63 ~6 ~22 stonebrick 0  
fill ~51 ~6 ~91 ~63 ~6 ~91 stonebrick 0  
fill ~51 ~6 ~92 ~51 ~7 ~92 stonebrick 0  
fill ~52 ~6 ~21 ~61 ~6 ~21 stone_brick_stairs 2  
fill ~52 ~6 ~92 ~61 ~6 ~92 stone_brick_stairs 3 
setblock ~58 ~6 ~20 stone_slab 0 
setblock ~61 ~6 ~93 vine 8  
fill ~62 ~6 ~18 ~63 ~6 ~18 stone_slab 0  
fill ~62 ~6 ~21 ~62 ~7 ~21 stonebrick 0  
fill ~62 ~6 ~92 ~62 ~7 ~92 stonebrick 0  
fill ~62 ~6 ~95 ~63 ~6 ~95 stone_slab 0  
fill ~63 ~6 ~27 ~63 ~12 ~27 stonebrick 0  
fill ~63 ~6 ~86 ~63 ~12 ~86 stonebrick 0  
fill ~64 ~6 ~26 ~87 ~6 ~26 stonebrick 0  
fill ~64 ~6 ~87 ~87 ~6 ~87 stonebrick 0  
fill ~64 ~6 ~88 ~64 ~10 ~88 vine 2  
fill ~64 ~6 ~90 ~64 ~9 ~90 vine 2  
fill ~64 ~6 ~91 ~64 ~8 ~91 vine 2   
fill ~64 ~6 ~92 ~64 ~7 ~92 vine 2 
setblock ~65 ~6 ~25 vine 1 
setblock ~68 ~6 ~25 vine 1 
setblock ~69 ~6 ~88 vine 4 
setblock ~71 ~6 ~25 vine 1 
setblock ~71 ~6 ~88 vine 4  
fill ~73 ~6 ~25 ~76 ~6 ~25 vine 1 
setblock ~74 ~6 ~88 vine 4 
setblock ~79 ~6 ~25 vine 1 
setblock ~79 ~6 ~88 vine 4  
fill ~81 ~6 ~88 ~82 ~6 ~88 vine 4  
fill ~84 ~6 ~88 ~85 ~6 ~88 vine 4 
setblock ~85 ~6 ~25 vine 1  
fill ~86 ~6 ~50 ~94 ~6 ~50 stonebrick 0  
fill ~86 ~6 ~63 ~94 ~6 ~63 stonebrick 0  
fill ~87 ~6 ~27 ~87 ~6 ~50 stonebrick 0  
fill ~87 ~6 ~64 ~87 ~6 ~87 stonebrick 0 
setblock ~88 ~6 ~28 vine 2  
fill ~88 ~6 ~37 ~88 ~6 ~41 vine 2  
fill ~88 ~6 ~49 ~91 ~6 ~49 vine 1 
setblock ~88 ~6 ~72 vine 2 
setblock ~88 ~6 ~74 vine 2 
setblock ~88 ~6 ~79 vine 2 
setblock ~88 ~6 ~82 vine 2  
fill ~91 ~6 ~51 ~94 ~6 ~51 stonebrick 0  
fill ~91 ~6 ~52 ~91 ~6 ~63 stonebrick 0  
fill ~91 ~6 ~64 ~92 ~6 ~64 vine 4  
fill ~92 ~6 ~52 ~92 ~6 ~61 stone_brick_stairs 1  
fill ~92 ~6 ~62 ~94 ~6 ~62 stonebrick 0 
setblock ~94 ~6 ~52 vine 4 
setblock ~95 ~6 ~51 stone_slab 0  
fill ~95 ~6 ~62 ~95 ~6 ~63 stone_slab 0  
fill ~19 ~7 ~50 ~20 ~7 ~50 stone_slab 0  
fill ~19 ~7 ~51 ~20 ~7 ~51 stone_slab 0  
fill ~19 ~7 ~62 ~20 ~7 ~62 stone_slab 0  
fill ~19 ~7 ~63 ~20 ~7 ~63 stone_slab 0  
fill ~21 ~7 ~50 ~29 ~7 ~50 stonebrick 0  
fill ~21 ~7 ~51 ~23 ~7 ~51 stonebrick 0 
setblock ~21 ~7 ~52 vine 4  
fill ~21 ~7 ~62 ~23 ~7 ~62 stonebrick 0  
fill ~21 ~7 ~63 ~29 ~7 ~63 stonebrick 0  
fill ~22 ~7 ~49 ~24 ~7 ~49 vine 1  
fill ~22 ~7 ~52 ~22 ~7 ~61 stone_brick_stairs 0  
fill ~22 ~7 ~64 ~22 ~8 ~64 vine 4  
fill ~23 ~7 ~52 ~23 ~7 ~63 stonebrick 0 
setblock ~26 ~7 ~29 vine 8 
setblock ~26 ~7 ~40 vine 8  
fill ~26 ~7 ~64 ~26 ~11 ~64 vine 4 
setblock ~26 ~7 ~77 vine 8  
fill ~26 ~7 ~83 ~26 ~7 ~84 vine 8  
fill ~27 ~7 ~27 ~50 ~7 ~27 stonebrick 0  
fill ~27 ~7 ~28 ~50 ~7 ~28 stonebrick 0  
fill ~27 ~7 ~29 ~50 ~7 ~29 stonebrick 0  
fill ~27 ~7 ~30 ~29 ~7 ~30 stonebrick 0  
fill ~27 ~7 ~31 ~29 ~7 ~31 stonebrick 0  
fill ~27 ~7 ~32 ~29 ~7 ~32 stonebrick 0  
fill ~27 ~7 ~33 ~29 ~7 ~33 stonebrick 0  
fill ~27 ~7 ~34 ~29 ~7 ~34 stonebrick 0  
fill ~27 ~7 ~35 ~29 ~7 ~35 stonebrick 0  
fill ~27 ~7 ~36 ~29 ~7 ~36 stonebrick 0  
fill ~27 ~7 ~37 ~29 ~7 ~37 stonebrick 0  
fill ~27 ~7 ~38 ~29 ~7 ~38 stonebrick 0  
fill ~27 ~7 ~39 ~29 ~7 ~39 stonebrick 0  
fill ~27 ~7 ~40 ~29 ~7 ~40 stonebrick 0  
fill ~27 ~7 ~41 ~29 ~7 ~41 stonebrick 0  
fill ~27 ~7 ~42 ~29 ~7 ~42 stonebrick 0  
fill ~27 ~7 ~43 ~29 ~7 ~43 stonebrick 0  
fill ~27 ~7 ~44 ~29 ~7 ~44 stonebrick 0  
fill ~27 ~7 ~45 ~29 ~7 ~45 stonebrick 0  
fill ~27 ~7 ~46 ~29 ~7 ~46 stonebrick 0  
fill ~27 ~7 ~47 ~29 ~7 ~47 stonebrick 0  
fill ~27 ~7 ~48 ~29 ~7 ~48 stonebrick 0  
fill ~27 ~7 ~49 ~29 ~7 ~49 stonebrick 0  
fill ~27 ~7 ~64 ~29 ~7 ~64 stonebrick 0  
fill ~27 ~7 ~65 ~29 ~7 ~65 stonebrick 0  
fill ~27 ~7 ~66 ~29 ~7 ~66 stonebrick 0  
fill ~27 ~7 ~67 ~29 ~7 ~67 stonebrick 0  
fill ~27 ~7 ~68 ~29 ~7 ~68 stonebrick 0  
fill ~27 ~7 ~69 ~29 ~7 ~69 stonebrick 0  
fill ~27 ~7 ~70 ~29 ~7 ~70 stonebrick 0  
fill ~27 ~7 ~71 ~29 ~7 ~71 stonebrick 0  
fill ~27 ~7 ~72 ~29 ~7 ~72 stonebrick 0  
fill ~27 ~7 ~73 ~29 ~7 ~73 stonebrick 0  
fill ~27 ~7 ~74 ~29 ~7 ~74 stonebrick 0  
fill ~27 ~7 ~75 ~29 ~7 ~75 stonebrick 0  
fill ~27 ~7 ~76 ~29 ~7 ~76 stonebrick 0  
fill ~27 ~7 ~77 ~29 ~7 ~77 stonebrick 0  
fill ~27 ~7 ~78 ~29 ~7 ~78 stonebrick 0  
fill ~27 ~7 ~79 ~29 ~7 ~79 stonebrick 0  
fill ~27 ~7 ~80 ~29 ~7 ~80 stonebrick 0  
fill ~27 ~7 ~81 ~29 ~7 ~81 stonebrick 0  
fill ~27 ~7 ~82 ~29 ~7 ~82 stonebrick 0  
fill ~27 ~7 ~83 ~29 ~7 ~83 stonebrick 0  
fill ~27 ~7 ~84 ~50 ~7 ~84 stonebrick 0  
fill ~27 ~7 ~85 ~50 ~7 ~85 stonebrick 0  
fill ~27 ~7 ~86 ~50 ~7 ~86 stonebrick 0  
fill ~27 ~7 ~87 ~28 ~7 ~87 vine 4 
setblock ~30 ~7 ~26 vine 1 
setblock ~34 ~7 ~87 vine 4 
setblock ~38 ~7 ~26 vine 1 
setblock ~46 ~7 ~87 vine 4  
fill ~50 ~7 ~19 ~51 ~7 ~19 stone_slab 0  
fill ~50 ~7 ~20 ~51 ~7 ~20 stone_slab 0  
fill ~50 ~7 ~93 ~51 ~7 ~93 stone_slab 0  
fill ~50 ~7 ~94 ~51 ~7 ~94 stone_slab 0  
fill ~51 ~7 ~22 ~51 ~8 ~22 stonebrick 0  
fill ~51 ~7 ~23 ~63 ~7 ~23 stonebrick 0  
fill ~51 ~7 ~90 ~63 ~7 ~90 stonebrick 0  
fill ~51 ~7 ~91 ~51 ~8 ~91 stonebrick 0 
setblock ~52 ~7 ~21 vine 2  
fill ~52 ~7 ~22 ~61 ~7 ~22 stone_brick_stairs 2  
fill ~52 ~7 ~91 ~61 ~7 ~91 stone_brick_stairs 3 
setblock ~61 ~7 ~92 vine 8  
fill ~62 ~7 ~19 ~63 ~7 ~19 stone_slab 0  
fill ~62 ~7 ~20 ~63 ~7 ~20 stone_slab 0  
fill ~62 ~7 ~22 ~62 ~8 ~22 stonebrick 0  
fill ~62 ~7 ~91 ~62 ~8 ~91 stonebrick 0  
fill ~62 ~7 ~93 ~63 ~7 ~93 stone_slab 0  
fill ~62 ~7 ~94 ~63 ~7 ~94 stone_slab 0  
fill ~63 ~7 ~28 ~86 ~7 ~28 stonebrick 0  
fill ~63 ~7 ~29 ~86 ~7 ~29 stonebrick 0  
fill ~63 ~7 ~84 ~86 ~7 ~84 stonebrick 0  
