fill ~3~11~1 ~3~11~2 minecraft:wool 14
fill ~3~12~1 ~3~14~1 minecraft:gold_block
fill ~2~0~2 ~4~0~4 minecraft:stone 0
fill ~2~11~2 ~2~11~4 minecraft:wool 14
setblock ~3~10~2 minecraft:wool 14
setblock ~3~15~2 minecraft:gold_block
fill ~4~11~2 ~4~11~4 minecraft:wool 14
setblock ~1~11~3 minecraft:wool 14
setblock ~2~10~3 minecraft:wool 14
fill ~3~1~3 ~3~10~3 minecraft:iron_block
fill ~3~13~3 ~3~14~3 minecraft:gold_block
setblock ~4~10~3 minecraft:wool 14
setblock ~5~11~3 minecraft:wool 14
fill ~3~10~4 ~3~11~4 minecraft:wool 14
setblock ~3~15~4 minecraft:gold_block
setblock ~3~11~5 minecraft:wool 14
fill ~3~12~5 ~3~14~5 minecraft:gold_block
fill ~0~0~6 ~3~0~8 minecraft:stone 0
fill ~4~0~6 ~19~0~6 minecraft:stone_block_slab 0
fill ~20~0~6 ~22~0~8 minecraft:stone 0
fill ~1~5~7 ~22~5~7 minecraft:stonebrick 0
fill ~2~1~7 ~2~3~7 minecraft:gold_block
fill ~4~0~7 ~9~0~8 minecraft:stone_block_slab 0
fill ~10~0~7 ~11~0~8 minecraft:double_stone_block_slab 0
fill ~12~0~7 ~19~0~8 minecraft:stone_block_slab 0
fill ~21~1~7 ~21~3~7 minecraft:gold_block
fill ~1~5~8 ~1~5~22 minecraft:stonebrick 0
fill ~2~4~8 ~2~5~8 minecraft:gold_block
fill ~3~5~8 ~20~5~21 minecraft:stone_block_slab 0
setblock ~9~2~8 minecraft:torch 4
fill ~10~1~8 ~11~1~8 minecraft:stone_pressure_plate 0
setblock ~12~2~8 minecraft:torch 4
fill ~21~4~8 ~21~5~8 minecraft:gold_block
fill ~22~5~8 ~22~5~22 minecraft:stonebrick 0
fill ~0~0~9 ~1~0~22 minecraft:stone 0
fill ~2~0~9 ~21~0~9 minecraft:brick_block
fill ~2~1~9 ~2~4~9 minecraft:brick_block
fill ~2~5~9 ~2~5~18 minecraft:stone_block_slab 0
setblock ~2~6~9 minecraft:gold_block
fill ~3~1~9 ~8~3~9 minecraft:glass
fill ~3~4~9 ~21~4~9 minecraft:brick_block
fill ~9~1~9 ~9~3~9 minecraft:brick_block
fill ~10~1~9 ~11~1~9 minecraft:iron_door 1
fill ~10~3~9 ~11~3~9 minecraft:glass
fill ~12~1~9 ~12~3~9 minecraft:brick_block
fill ~13~1~9 ~20~3~9 minecraft:glass
fill ~21~1~9 ~21~3~9 minecraft:brick_block
fill ~21~5~9 ~21~5~19 minecraft:stone_block_slab 0
setblock ~21~6~9 minecraft:gold_block
fill ~22~0~9 ~22~0~22 minecraft:stone 0
setblock ~2~0~10 minecraft:stone 0
fill ~2~1~10 ~2~2~10 minecraft:glass
fill ~2~3~10 ~2~4~10 minecraft:brick_block
setblock ~2~7~10 minecraft:gold_block
setblock ~3~0~10 minecraft:wool 15
setblock ~3~1~10 minecraft:stone_block_slab 0
setblock ~4~0~10 minecraft:wool 0
fill ~4~1~10 ~6~1~10 minecraft:oak_stairs 1
setblock ~5~0~10 minecraft:wool 15
setblock ~6~0~10 minecraft:wool 0
setblock ~7~0~10 minecraft:wool 15
setblock ~7~1~10 minecraft:stone_block_slab 0
setblock ~8~0~10 minecraft:wool 0
fill ~9~0~10 ~9~0~11 minecraft:brick_block
fill ~9~1~10 ~9~1~11 minecraft:iron_block
fill ~9~2~10 ~9~2~11 minecraft:stone_pressure_plate 0
fill ~10~0~10 ~11~0~16 minecraft:wool 14
fill ~10~1~10 ~11~1~10 minecraft:stone_pressure_plate 0
fill ~12~0~10 ~12~0~11 minecraft:brick_block
fill ~12~1~10 ~12~1~11 minecraft:iron_block
fill ~12~2~10 ~12~2~11 minecraft:stone_pressure_plate 0
setblock ~13~0~10 minecraft:wool 0
setblock ~14~0~10 minecraft:wool 15
fill ~14~1~10 ~14~1~11 minecraft:oak_stairs 2
setblock ~15~0~10 minecraft:wool 0
fill ~15~1~10 ~15~1~11 minecraft:fence 0
fill ~15~2~10 ~15~2~11 minecraft:stone_pressure_plate 0
setblock ~16~0~10 minecraft:wool 15
fill ~16~1~10 ~16~1~11 minecraft:oak_stairs 3
setblock ~17~0~10 minecraft:wool 0
setblock ~18~0~10 minecraft:wool 15
fill ~18~1~10 ~18~1~11 minecraft:oak_stairs 2
setblock ~19~0~10 minecraft:wool 0
fill ~19~1~10 ~19~1~11 minecraft:fence 0
fill ~19~2~10 ~19~2~11 minecraft:stone_pressure_plate 0
setblock ~20~0~10 minecraft:wool 15
fill ~20~1~10 ~20~1~11 minecraft:oak_stairs 3
setblock ~21~0~10 minecraft:stone 0
fill ~21~1~10 ~21~2~10 minecraft:glass
fill ~21~3~10 ~21~4~10 minecraft:brick_block
setblock ~21~7~10 minecraft:gold_block
fill ~2~0~11 ~2~2~12 minecraft:brick_block
fill ~2~3~11 ~2~3~12 minecraft:glass
fill ~2~4~11 ~2~4~19 minecraft:brick_block
fill ~2~8~11 ~2~8~12 minecraft:gold_block
setblock ~3~0~11 minecraft:wool 0
setblock ~3~1~11 minecraft:oak_stairs 2
setblock ~4~0~11 minecraft:wool 15
fill ~4~1~11 ~6~1~11 minecraft:fence 0
fill ~4~2~11 ~6~2~11 minecraft:stone_pressure_plate 0
setblock ~5~0~11 minecraft:wool 0
setblock ~6~0~11 minecraft:wool 15
setblock ~7~0~11 minecraft:wool 0
setblock ~7~1~11 minecraft:oak_stairs 3
setblock ~8~0~11 minecraft:wool 15
setblock ~13~0~11 minecraft:wool 15
setblock ~14~0~11 minecraft:wool 0
setblock ~15~0~11 minecraft:wool 15
setblock ~16~0~11 minecraft:wool 0
setblock ~17~0~11 minecraft:wool 15
setblock ~18~0~11 minecraft:wool 0
setblock ~19~0~11 minecraft:wool 15
setblock ~20~0~11 minecraft:wool 0
fill ~21~0~11 ~21~2~12 minecraft:brick_block
fill ~21~3~11 ~21~3~12 minecraft:glass
fill ~21~4~11 ~21~4~19 minecraft:brick_block
fill ~21~8~11 ~21~8~12 minecraft:gold_block
setblock ~3~0~12 minecraft:wool 15
setblock ~4~0~12 minecraft:wool 0
setblock ~5~0~12 minecraft:wool 15
setblock ~6~0~12 minecraft:wool 0
setblock ~7~0~12 minecraft:wool 15
setblock ~8~0~12 minecraft:wool 0
setblock ~9~0~12 minecraft:wool 15
setblock ~12~0~12 minecraft:wool 15
setblock ~13~0~12 minecraft:wool 0
setblock ~14~0~12 minecraft:wool 15
setblock ~15~0~12 minecraft:wool 0
setblock ~16~0~12 minecraft:wool 15
setblock ~17~0~12 minecraft:wool 0
setblock ~18~0~12 minecraft:wool 15
setblock ~19~0~12 minecraft:wool 0
setblock ~20~0~12 minecraft:wool 15
setblock ~2~0~13 minecraft:stone 0
fill ~2~1~13 ~2~2~13 minecraft:glass
setblock ~2~3~13 minecraft:brick_block
fill ~2~9~13 ~2~9~15 minecraft:gold_block
setblock ~3~0~13 minecraft:wool 0
setblock ~4~0~13 minecraft:wool 15
setblock ~5~0~13 minecraft:wool 0
setblock ~6~0~13 minecraft:wool 15
setblock ~7~0~13 minecraft:wool 0
setblock ~8~0~13 minecraft:wool 15
setblock ~9~0~13 minecraft:wool 0
setblock ~12~0~13 minecraft:wool 0
setblock ~13~0~13 minecraft:wool 15
setblock ~13~1~13 minecraft:oak_stairs 2
setblock ~14~0~13 minecraft:wool 0
setblock ~14~1~13 minecraft:fence 0
setblock ~14~2~13 minecraft:stone_pressure_plate 0
setblock ~15~0~13 minecraft:wool 15
setblock ~15~1~13 minecraft:oak_stairs 3
setblock ~16~0~13 minecraft:wool 0
setblock ~17~0~13 minecraft:wool 15
setblock ~17~1~13 minecraft:oak_stairs 2
setblock ~18~0~13 minecraft:wool 0
setblock ~18~1~13 minecraft:fence 0
setblock ~18~2~13 minecraft:stone_pressure_plate 0
setblock ~19~0~13 minecraft:wool 15
setblock ~19~1~13 minecraft:oak_stairs 3
setblock ~20~0~13 minecraft:wool 0
setblock ~21~0~13 minecraft:stone 0
fill ~21~1~13 ~21~2~13 minecraft:glass
setblock ~21~3~13 minecraft:brick_block
fill ~21~9~13 ~21~9~15 minecraft:gold_block
fill ~2~0~14 ~2~2~15 minecraft:brick_block
fill ~2~3~14 ~2~3~15 minecraft:glass
setblock ~3~0~14 minecraft:wool 15
setblock ~4~0~14 minecraft:wool 0
setblock ~4~1~14 minecraft:oak_stairs 1
setblock ~5~0~14 minecraft:wool 15
setblock ~6~0~14 minecraft:wool 0
setblock ~6~1~14 minecraft:oak_stairs 2
setblock ~7~0~14 minecraft:wool 15
setblock ~7~1~14 minecraft:fence 0
setblock ~7~2~14 minecraft:stone_pressure_plate 0
setblock ~8~0~14 minecraft:wool 0
setblock ~8~1~14 minecraft:oak_stairs 3
setblock ~9~0~14 minecraft:wool 15
setblock ~12~0~14 minecraft:wool 15
setblock ~13~0~14 minecraft:wool 0
setblock ~14~0~14 minecraft:wool 15
setblock ~15~0~14 minecraft:wool 0
setblock ~16~0~14 minecraft:wool 15
setblock ~17~0~14 minecraft:wool 0
setblock ~18~0~14 minecraft:wool 15
setblock ~19~0~14 minecraft:wool 0
setblock ~20~0~14 minecraft:wool 15
fill ~21~0~14 ~21~2~15 minecraft:brick_block
fill ~21~3~14 ~21~3~15 minecraft:glass
setblock ~3~0~15 minecraft:wool 0
setblock ~4~0~15 minecraft:wool 15
setblock ~4~1~15 minecraft:fence 0
setblock ~4~2~15 minecraft:stone_pressure_plate 0
setblock ~5~0~15 minecraft:wool 0
setblock ~6~0~15 minecraft:wool 15
setblock ~7~0~15 minecraft:wool 0
setblock ~8~0~15 minecraft:wool 15
setblock ~9~0~15 minecraft:wool 0
setblock ~12~0~15 minecraft:wool 0
setblock ~13~0~15 minecraft:wool 15
setblock ~14~0~15 minecraft:wool 0
setblock ~15~0~15 minecraft:wool 15
setblock ~15~1~15 minecraft:oak_stairs 1
setblock ~16~0~15 minecraft:wool 0
setblock ~17~0~15 minecraft:wool 15
setblock ~17~1~15 minecraft:oak_stairs 1
setblock ~18~0~15 minecraft:wool 0
setblock ~19~0~15 minecraft:wool 15
setblock ~19~1~15 minecraft:oak_stairs 1
setblock ~20~0~15 minecraft:wool 0
setblock ~2~0~16 minecraft:stone 0
fill ~2~1~16 ~2~2~16 minecraft:glass
fill ~2~3~16 ~2~3~20 minecraft:brick_block
fill ~2~8~16 ~2~8~17 minecraft:gold_block
setblock ~3~0~16 minecraft:wool 15
setblock ~4~0~16 minecraft:wool 0
setblock ~4~1~16 minecraft:oak_stairs 0
setblock ~5~0~16 minecraft:wool 15
setblock ~6~0~16 minecraft:wool 0
setblock ~7~0~16 minecraft:wool 15
fill ~8~0~16 ~9~0~16 minecraft:wool 14
setblock ~9~2~16 minecraft:wall_sign 4
setblock ~11~2~16 minecraft:wall_sign 4
fill ~12~0~16 ~13~0~16 minecraft:wool 14
setblock ~13~2~16 minecraft:wall_sign 4
setblock ~14~0~16 minecraft:wool 15
setblock ~15~0~16 minecraft:wool 0
setblock ~15~1~16 minecraft:fence 0
fill ~15~2~16 ~20~2~16 minecraft:stone_block_slab 5
setblock ~16~0~16 minecraft:wool 15
setblock ~17~0~16 minecraft:wool 0
setblock ~17~1~16 minecraft:fence 0
setblock ~18~0~16 minecraft:wool 15
setblock ~19~0~16 minecraft:wool 0
setblock ~19~1~16 minecraft:fence 0
setblock ~20~0~16 minecraft:wool 15
setblock ~21~0~16 minecraft:stone 0
fill ~21~1~16 ~21~2~16 minecraft:glass
fill ~21~3~16 ~21~3~20 minecraft:brick_block
fill ~21~8~16 ~21~8~17 minecraft:gold_block
fill ~2~0~17 ~20~0~17 minecraft:stonebrick 0
fill ~2~1~17 ~2~2~20 minecraft:brick_block
fill ~3~1~17 ~13~1~17 minecraft:stonebrick 0
fill ~3~2~17 ~7~4~17 minecraft:stonebrick 0
setblock ~9~2~17 minecraft:stone_stairs 1
setblock ~11~2~17 minecraft:stone_stairs 1
setblock ~13~2~17 minecraft:stone_stairs 1
setblock ~14~2~17 minecraft:trapdoor 2
fill ~15~1~17 ~20~4~17 minecraft:stonebrick 0
fill ~21~0~17 ~21~2~17 minecraft:brick_block
fill ~2~0~18 ~21~0~22 minecraft:stone 0
setblock ~2~7~18 minecraft:gold_block
fill ~3~1~18 ~6~1~18 minecraft:furnace 5
fill ~16~1~18 ~17~1~18 minecraft:crafting_table
fill ~18~1~18 ~19~1~18 minecraft:iron_block
fill ~18~2~18 ~19~2~18 minecraft:redstone_lamp
fill ~20~1~18 ~21~2~20 minecraft:brick_block
fill ~20~3~18 ~20~4~21 minecraft:brick_block
setblock ~21~7~18 minecraft:gold_block
setblock ~2~6~19 minecraft:gold_block
fill ~18~2~19 ~19~2~19 minecraft:stone_button 5
setblock ~21~6~19 minecraft:gold_block
fill ~2~4~20 ~2~5~20 minecraft:gold_block
setblock ~3~1~20 minecraft:iron_block
fill ~4~1~20 ~5~1~20 minecraft:bedrock 0
fill ~4~3~20 ~5~4~20 minecraft:iron_block
setblock ~6~1~20 minecraft:iron_block
setblock ~7~1~20 minecraft:wall_sign 2
fill ~8~1~20 ~10~1~20 minecraft:double_stone_block_slab 5
fill ~8~2~20 ~8~4~20 minecraft:double_stone_block_slab 5
fill ~9~2~20 ~9~3~20 minecraft:stone_block_slab 5
fill ~9~4~20 ~10~4~20 minecraft:double_stone_block_slab 5
fill ~10~2~20 ~10~3~20 minecraft:double_stone_block_slab 5
fill ~11~1~20 ~14~1~20 minecraft:stonebrick 0
fill ~11~2~20 ~11~3~20 minecraft:stone_block_slab 5
fill ~12~2~20 ~12~4~20 minecraft:stonebrick 0
fill ~13~2~20 ~13~3~20 minecraft:stone_block_slab 5
fill ~13~4~20 ~14~4~20 minecraft:stonebrick 0
fill ~14~2~20 ~14~3~20 minecraft:stonebrick 0
fill ~16~1~20 ~19~1~20 minecraft:iron_block
fill ~16~3~20 ~19~3~20 minecraft:planks 1
fill ~21~4~20 ~21~5~20 minecraft:gold_block
fill ~2~1~21 ~2~3~21 minecraft:gold_block
fill ~2~4~21 ~19~4~21 minecraft:brick_block
setblock ~2~5~21 minecraft:stone_block_slab 0
fill ~3~1~21 ~20~2~21 minecraft:brick_block
fill ~3~3~21 ~19~3~21 minecraft:brick_block
fill ~21~1~21 ~21~3~21 minecraft:gold_block
setblock ~21~4~21 minecraft:brick_block
setblock ~21~5~21 minecraft:stone_block_slab 0
fill ~2~5~22 ~21~5~22 minecraft:stonebrick 0