fill ~0~0~2 ~138~1~47 minecraft:dirt 0
fill ~0~2~2 ~138~2~4 minecraft:grass
fill ~0~0~2 ~0~1~148 minecraft:dirt 0
fill ~0~2~2 ~0~2~148 minecraft:grass
fill ~24~3~4 ~24~3~6 minecraft:leaves 2
fill ~2~2~5 ~22~2~7 minecraft:grass
setblock ~23~2~5 minecraft:dirt 0
setblock ~23~3~5 minecraft:log 1
fill ~24~2~5 ~138~2~7 minecraft:grass
setblock ~25~3~5 minecraft:leaves 2
fill ~18~5~6 ~20~5~6 minecraft:leaves 2
fill ~19~4~6 ~19~4~7 minecraft:leaves 2
setblock ~19~6~6 minecraft:log 1
fill ~21~30~6 ~24~30~6 minecraft:leaves 2
fill ~21~31~6 ~21~31~7 minecraft:leaves 2
setblock ~22~31~6 minecraft:leaves 2
fill ~23~2~6 ~23~2~8 minecraft:grass
fill ~23~29~6 ~23~29~7 minecraft:leaves 2
fill ~23~31~6 ~23~31~8 minecraft:leaves 2
fill ~18~4~7 ~18~4~9 minecraft:leaves 2
setblock ~18~5~7 minecraft:log 1
fill ~18~6~7 ~21~6~7 minecraft:leaves 2
fill ~18~25~7 ~20~25~8 minecraft:leaves 2
setblock ~19~3~7 minecraft:leaves 1
fill ~19~5~7 ~20~5~7 minecraft:leaves 2
fill ~19~11~7 ~21~11~7 minecraft:leaves 2
fill ~19~24~7 ~19~24~8 minecraft:leaves 2
setblock ~19~26~7 minecraft:leaves 2
setblock ~19~31~7 minecraft:leaves 2
fill ~20~7~7 ~20~7~8 minecraft:leaves 2
fill ~20~9~7 ~22~9~8 minecraft:leaves 2
fill ~20~10~7 ~21~10~8 minecraft:leaves 2
fill ~20~12~7 ~20~12~8 minecraft:leaves 2
fill ~20~30~7 ~22~30~8 minecraft:leaves 2
setblock ~20~31~7 minecraft:leaves 2
fill ~20~32~7 ~21~32~8 minecraft:leaves 2
setblock ~21~8~7 minecraft:leaves 2
fill ~22~29~7 ~22~29~8 minecraft:leaves 1
setblock ~22~31~7 minecraft:leaves 1
setblock ~22~32~7 minecraft:leaves 2
setblock ~23~30~7 minecraft:log 1
fill ~24~29~7 ~24~31~7 minecraft:leaves 2
setblock ~25~30~7 minecraft:leaves 1
setblock ~25~32~7 minecraft:leaves 2
fill ~26~31~7 ~27~31~8 minecraft:leaves 2
fill ~27~30~7 ~27~30~8 minecraft:leaves 2
fill ~27~32~7 ~27~32~9 minecraft:leaves 2
fill ~29~30~7 ~30~30~8 minecraft:leaves 2
setblock ~30~12~7 minecraft:leaves 2
fill ~30~29~7 ~30~29~8 minecraft:leaves 2
setblock ~30~31~7 minecraft:leaves 2
fill ~31~12~7 ~31~12~8 minecraft:log 1
fill ~100~14~7 ~102~14~7 minecraft:leaves 2
setblock ~100~20~7 minecraft:leaves 1
fill ~101~13~7 ~103~13~7 minecraft:leaves 2
setblock ~101~15~7 minecraft:leaves 2
fill ~101~20~7 ~102~20~9 minecraft:leaves 2
fill ~101~21~7 ~101~21~9 minecraft:leaves 2
fill ~102~12~7 ~102~12~9 minecraft:leaves 2
fill ~105~4~7 ~106~4~7 minecraft:leaves 2
setblock ~106~3~7 minecraft:leaves 2
setblock ~106~5~7 minecraft:leaves 2
setblock ~107~4~7 minecraft:log 1
fill ~1~2~8 ~16~2~8 minecraft:grass
fill ~14~3~8 ~14~3~9 minecraft:leaves 2
fill ~14~24~8 ~15~24~8 minecraft:log 1
setblock ~15~3~8 minecraft:leaves 1
fill ~15~4~8 ~17~4~8 minecraft:leaves 2
fill ~15~16~8 ~17~16~8 minecraft:leaves 2
setblock ~15~23~8 minecraft:leaves 1
fill ~15~25~8 ~15~25~9 minecraft:leaves 2
setblock ~15~31~8 minecraft:leaves 2
setblock ~15~32~8 minecraft:log 1
setblock ~16~3~8 minecraft:leaves 2
setblock ~16~15~8 minecraft:leaves 2
fill ~16~17~8 ~16~17~9 minecraft:leaves 2
fill ~16~24~8 ~16~24~9 minecraft:leaves 2
setblock ~16~31~8 minecraft:leaves 1
fill ~17~2~8 ~17~2~46 minecraft:dirt 0
fill ~17~3~8 ~17~3~9 minecraft:log 1
fill ~17~14~8 ~18~14~8 minecraft:leaves 2
fill ~18~2~8 ~22~2~8 minecraft:grass
fill ~18~3~8 ~20~3~8 minecraft:leaves 2
setblock ~18~5~8 minecraft:leaves 1
fill ~18~13~8 ~20~13~8 minecraft:leaves 2
setblock ~18~15~8 minecraft:leaves 2
setblock ~18~24~8 minecraft:leaves 2
setblock ~18~26~8 minecraft:leaves 1
setblock ~19~4~8 minecraft:leaves 1
setblock ~19~5~8 minecraft:log 1
setblock ~19~6~8 minecraft:leaves 2
setblock ~19~7~8 minecraft:log 1
setblock ~19~10~8 minecraft:log 1
fill ~19~11~8 ~20~11~8 minecraft:leaves 1
setblock ~19~12~8 minecraft:leaves 2
setblock ~19~14~8 minecraft:leaves 1
setblock ~19~22~8 minecraft:leaves 2
setblock ~19~26~8 minecraft:log 1
setblock ~19~31~8 minecraft:log 1
setblock ~19~32~8 minecraft:leaves 1
fill ~20~4~8 ~20~5~8 minecraft:leaves 2
setblock ~20~6~8 minecraft:log 1
setblock ~20~8~8 minecraft:leaves 1
setblock ~20~19~8 minecraft:leaves 2
setblock ~20~24~8 minecraft:leaves 1
setblock ~20~28~8 minecraft:leaves 1
setblock ~20~31~8 minecraft:leaves 2
setblock ~21~5~8 minecraft:log 1
fill ~21~6~8 ~21~7~8 minecraft:leaves 2
setblock ~21~8~8 minecraft:log 1
fill ~21~11~8 ~21~12~8 minecraft:leaves 2
setblock ~21~18~8 minecraft:leaves 2
setblock ~21~19~8 minecraft:log 1
setblock ~21~26~8 minecraft:log 1
fill ~21~27~8 ~21~28~8 minecraft:leaves 2
setblock ~21~31~8 minecraft:leaves 1
fill ~22~4~8 ~23~4~8 minecraft:leaves 2
setblock ~22~5~8 minecraft:leaves 1
setblock ~22~8~8 minecraft:leaves 2
setblock ~22~10~8 minecraft:leaves 2
setblock ~22~17~8 minecraft:leaves 2
setblock ~22~18~8 minecraft:leaves 1
setblock ~22~19~8 minecraft:leaves 2
setblock ~22~28~8 minecraft:log 1
fill ~22~31~8 ~22~32~8 minecraft:leaves 2
setblock ~23~16~8 minecraft:leaves 1
setblock ~23~18~8 minecraft:leaves 2
setblock ~23~29~8 minecraft:leaves 1
setblock ~23~30~8 minecraft:leaves 2
fill ~24~2~8 ~105~2~8 minecraft:grass
fill ~24~15~8 ~24~16~8 minecraft:leaves 2
fill ~24~30~8 ~24~32~8 minecraft:log 1
fill ~25~16~8 ~26~16~8 minecraft:leaves 2
fill ~25~30~8 ~26~30~8 minecraft:leaves 2
setblock ~25~31~8 minecraft:leaves 2
fill ~25~32~8 ~26~32~8 minecraft:log 1
setblock ~26~14~8 minecraft:leaves 1
setblock ~26~15~8 minecraft:log 1
setblock ~27~15~8 minecraft:leaves 2
fill ~28~30~8 ~28~32~8 minecraft:leaves 2
fill ~29~3~8 ~29~3~9 minecraft:leaves 2
fill ~29~12~8 ~29~12~9 minecraft:leaves 2
setblock ~29~15~8 minecraft:log 1
setblock ~29~29~8 minecraft:log 1
fill ~29~31~8 ~30~31~8 minecraft:leaves 1
setblock ~29~32~8 minecraft:leaves 1
setblock ~29~33~8 minecraft:leaves 2
setblock ~30~4~8 minecraft:log 1
fill ~30~11~8 ~32~11~8 minecraft:leaves 2
setblock ~30~12~8 minecraft:log 1
fill ~30~13~8 ~32~13~8 minecraft:leaves 2
fill ~30~14~8 ~30~16~8 minecraft:leaves 2
fill ~30~32~8 ~30~32~9 minecraft:leaves 2
fill ~31~3~8 ~31~3~10 minecraft:leaves 2
fill ~31~4~8 ~31~5~8 minecraft:leaves 2
fill ~31~9~8 ~33~9~9 minecraft:leaves 2
fill ~31~28~8 ~31~28~9 minecraft:leaves 2
fill ~31~29~8 ~31~29~9 minecraft:log 1
fill ~31~30~8 ~32~30~8 minecraft:leaves 2
setblock ~31~31~8 minecraft:leaves 2
setblock ~32~4~8 minecraft:log 1
setblock ~32~8~8 minecraft:log 1
fill ~32~10~8 ~32~10~10 minecraft:leaves 2
fill ~32~12~8 ~32~12~9 minecraft:leaves 2
fill ~32~29~8 ~32~29~9 minecraft:leaves 2
fill ~99~18~8 ~101~18~10 minecraft:leaves 2
fill ~100~13~8 ~101~13~8 minecraft:leaves 1
fill ~100~14~8 ~100~14~9 minecraft:leaves 2
fill ~100~15~8 ~101~15~8 minecraft:log 1
fill ~100~17~8 ~101~17~8 minecraft:leaves 2
fill ~100~19~8 ~102~19~9 minecraft:leaves 2
fill ~100~20~8 ~100~20~9 minecraft:leaves 2
setblock ~100~21~8 minecraft:leaves 2
fill ~101~6~8 ~103~6~9 minecraft:leaves 2
fill ~101~9~8 ~103~9~9 minecraft:leaves 2
fill ~101~12~8 ~101~12~9 minecraft:leaves 2
setblock ~101~14~8 minecraft:leaves 1
fill ~101~16~8 ~101~16~10 minecraft:leaves 2
fill ~102~5~8 ~104~5~8 minecraft:leaves 2
setblock ~102~7~8 minecraft:leaves 1
fill ~102~8~8 ~102~8~9 minecraft:log 1
setblock ~102~10~8 minecraft:leaves 1
fill ~102~13~8 ~102~15~8 minecraft:leaves 2
setblock ~102~21~8 minecraft:leaves 2
setblock ~103~4~8 minecraft:leaves 2
fill ~103~12~8 ~103~12~9 minecraft:leaves 2
fill ~103~13~8 ~103~13~9 minecraft:log 1
setblock ~103~14~8 minecraft:log 1
setblock ~104~4~8 minecraft:leaves 1
fill ~104~6~8 ~106~6~8 minecraft:leaves 1
setblock ~104~30~8 minecraft:leaves 1
fill ~105~3~8 ~105~4~8 minecraft:leaves 2
setblock ~105~5~8 minecraft:log 1
setblock ~105~7~8 minecraft:leaves 2
fill ~105~28~8 ~105~29~8 minecraft:leaves 1
fill ~105~30~8 ~105~31~8 minecraft:leaves 2
fill ~106~2~8 ~106~2~47 minecraft:dirt 0
setblock ~106~3~8 minecraft:leaves 1
setblock ~106~4~8 minecraft:log 1
fill ~106~28~8 ~106~29~8 minecraft:leaves 2
fill ~107~2~8 ~138~2~8 minecraft:grass
fill ~107~3~8 ~107~5~8 minecraft:leaves 2
setblock ~107~29~8 minecraft:leaves 2
fill ~108~4~8 ~110~4~8 minecraft:leaves 1
setblock ~108~26~8 minecraft:leaves 2
setblock ~108~28~8 minecraft:leaves 1
setblock ~109~26~8 minecraft:leaves 2
setblock ~109~27~8 minecraft:log 1
setblock ~110~5~8 minecraft:leaves 2
setblock ~110~27~8 minecraft:leaves 2
setblock ~111~4~8 minecraft:log 1
setblock ~111~26~8 minecraft:leaves 1
setblock ~112~4~8 minecraft:leaves 1
setblock ~112~22~8 minecraft:leaves 1
fill ~112~24~8 ~112~25~8 minecraft:leaves 1
setblock ~112~26~8 minecraft:leaves 2
fill ~113~3~8 ~113~4~8 minecraft:leaves 2
setblock ~113~16~8 minecraft:leaves 1
setblock ~113~17~8 minecraft:leaves 2
setblock ~113~18~8 minecraft:log 1
fill ~113~20~8 ~114~20~8 minecraft:leaves 2
fill ~113~21~8 ~113~23~8 minecraft:leaves 2
setblock ~113~24~8 minecraft:log 1
setblock ~113~25~8 minecraft:leaves 2
setblock ~114~22~8 minecraft:log 1
fill ~114~24~8 ~114~24~9 minecraft:leaves 2
fill ~117~29~8 ~117~29~9 minecraft:leaves 2
setblock ~117~30~8 minecraft:leaves 2
setblock ~118~30~8 minecraft:leaves 1
fill ~1~2~9 ~15~2~9 minecraft:grass
setblock ~12~3~9 minecraft:leaves 1
fill ~13~18~9 ~15~18~9 minecraft:leaves 2
setblock ~13~21~9 minecraft:log 1
setblock ~13~24~9 minecraft:leaves 2
setblock ~13~29~9 minecraft:leaves 2
fill ~13~30~9 ~15~30~10 minecraft:stonebrick 0
fill ~14~17~9 ~15~17~10 minecraft:leaves 2
fill ~14~19~9 ~14~20~10 minecraft:leaves 2
fill ~14~21~9 ~15~21~9 minecraft:leaves 2
fill ~14~22~9 ~14~22~10 minecraft:leaves 2
fill ~14~23~9 ~15~23~9 minecraft:leaves 2
setblock ~14~24~9 minecraft:log 1
setblock ~14~25~9 minecraft:leaves 2
setblock ~14~32~9 minecraft:log 1
fill ~15~3~9 ~15~3~10 minecraft:leaves 2
setblock ~15~4~9 minecraft:leaves 1
fill ~15~5~9 ~16~5~9 minecraft:log 1
fill ~15~15~9 ~15~16~9 minecraft:leaves 2
setblock ~15~24~9 minecraft:leaves 1
setblock ~15~31~9 minecraft:stonebrick 0
setblock ~15~32~9 minecraft:leaves 2
setblock ~15~33~9 minecraft:stonebrick 0
fill ~16~2~9 ~16~2~46 minecraft:dirt 0
setblock ~16~3~9 minecraft:log 1
fill ~16~4~9 ~17~4~9 minecraft:leaves 2
fill ~16~15~9 ~18~15~9 minecraft:log 1
setblock ~16~16~9 minecraft:leaves 2
setblock ~16~25~9 minecraft:leaves 2
setblock ~16~30~9 minecraft:leaves 2
setblock ~16~31~9 minecraft:log 1
setblock ~17~5~9 minecraft:leaves 1
setblock ~17~13~9 minecraft:log 1
fill ~17~14~9 ~18~14~9 minecraft:leaves 1
setblock ~17~16~9 minecraft:log 1
setblock ~17~17~9 minecraft:leaves 2
setblock ~17~31~9 minecraft:leaves 1
setblock ~18~2~9 minecraft:grass
setblock ~18~3~9 minecraft:leaves 2
setblock ~18~5~9 minecraft:leaves 2
fill ~18~10~9 ~18~13~9 minecraft:leaves 2
fill ~18~21~9 ~18~22~9 minecraft:leaves 2
setblock ~18~25~9 minecraft:leaves 1
setblock ~18~31~9 minecraft:leaves 2
setblock ~18~32~9 minecraft:leaves 1
fill ~19~2~9 ~28~2~26 minecraft:dirt 0
fill ~19~3~9 ~27~3~9 minecraft:dirt 0
fill ~19~4~9 ~27~31~9 minecraft:stonebrick 0
setblock ~19~32~9 minecraft:log 1
fill ~19~33~9 ~19~34~9 minecraft:stonebrick 0
fill ~20~32~9 ~26~33~9 minecraft:stained_hardened_clay 9
fill ~20~34~9 ~21~34~9 minecraft:stonebrick 0
fill ~21~35~9 ~26~35~9 minecraft:stonebrick 0
fill ~22~34~9 ~24~34~9 minecraft:stained_hardened_clay 9
fill ~23~36~9 ~23~37~9 minecraft:stonebrick 0
setblock ~28~3~9 minecraft:log 1
fill ~28~13~9 ~29~13~9 minecraft:leaves 2
fill ~28~31~9 ~28~32~9 minecraft:leaves 2
fill ~28~33~9 ~29~33~9 minecraft:leaves 1
fill ~29~2~9 ~102~2~9 minecraft:grass
fill ~29~14~9 ~30~14~9 minecraft:log 1
fill ~29~15~9 ~30~15~9 minecraft:leaves 2
setblock ~29~16~9 minecraft:leaves 1
fill ~29~30~9 ~30~30~9 minecraft:log 1
setblock ~29~32~9 minecraft:log 1
fill ~30~3~9 ~30~4~9 minecraft:leaves 2
setblock ~30~11~9 minecraft:log 1
fill ~30~12~9 ~31~12~9 minecraft:leaves 2
setblock ~30~13~9 minecraft:leaves 1
setblock ~30~16~9 minecraft:log 1
fill ~30~17~9 ~31~17~9 minecraft:leaves 1
setblock ~30~29~9 minecraft:log 1
setblock ~30~31~9 minecraft:log 1
fill ~31~4~9 ~32~4~9 minecraft:leaves 1
fill ~31~5~9 ~32~5~10 minecraft:leaves 2
setblock ~31~8~9 minecraft:log 1
fill ~31~10~9 ~31~10~10 minecraft:leaves 2
setblock ~31~11~9 minecraft:leaves 2
setblock ~31~13~9 minecraft:leaves 2
setblock ~31~15~9 minecraft:log 1
setblock ~31~16~9 minecraft:leaves 1
setblock ~31~18~9 minecraft:leaves 1
fill ~31~30~9 ~33~30~10 minecraft:stonebrick 0
setblock ~31~31~9 minecraft:stonebrick 0
fill ~32~3~9 ~32~3~10 minecraft:leaves 2
fill ~32~8~9 ~33~8~9 minecraft:leaves 2
fill ~32~17~9 ~32~17~10 minecraft:leaves 2
fill ~32~18~9 ~33~18~9 minecraft:leaves 2
setblock ~32~19~9 minecraft:leaves 2
fill ~32~28~9 ~34~28~9 minecraft:leaves 2
setblock ~33~10~9 minecraft:leaves 2
setblock ~33~27~9 minecraft:log 1
setblock ~33~29~9 minecraft:leaves 2
setblock ~34~29~9 minecraft:log 1
fill ~35~3~9 ~37~3~10 minecraft:leaves 2
fill ~35~4~9 ~36~4~10 minecraft:leaves 2
fill ~35~5~9 ~35~5~12 minecraft:leaves 2
fill ~40~3~9 ~40~3~10 minecraft:leaves 2
fill ~99~11~9 ~103~11~9 minecraft:leaves 2
fill ~99~16~9 ~100~17~10 minecraft:leaves 2
setblock ~99~19~9 minecraft:leaves 2
fill ~99~30~9 ~101~30~10 minecraft:stonebrick 0
setblock ~100~10~9 minecraft:leaves 1
fill ~100~12~9 ~100~12~10 minecraft:leaves 2
setblock ~100~13~9 minecraft:leaves 1
setblock ~100~15~9 minecraft:log 1
fill ~101~5~9 ~103~5~9 minecraft:leaves 2
fill ~101~7~9 ~102~7~9 minecraft:leaves 2
setblock ~101~8~9 minecraft:leaves 1
setblock ~101~10~9 minecraft:leaves 2
fill ~101~13~9 ~102~13~9 minecraft:log 1
fill ~101~14~9 ~102~14~9 minecraft:leaves 2
fill ~101~15~9 ~101~15~10 minecraft:leaves 2
setblock ~101~17~9 minecraft:leaves 1
setblock ~101~31~9 minecraft:stonebrick 0
setblock ~101~33~9 minecraft:stonebrick 0
fill ~102~3~9 ~102~4~9 minecraft:leaves 2
setblock ~102~10~9 minecraft:log 1
fill ~102~16~9 ~103~16~9 minecraft:leaves 2
setblock ~102~17~9 minecraft:leaves 2
setblock ~102~18~9 minecraft:log 1
setblock ~102~21~9 minecraft:log 1
fill ~102~30~9 ~102~31~9 minecraft:log 1
fill ~103~2~9 ~105~2~44 minecraft:dirt 0
fill ~103~3~9 ~103~4~9 minecraft:leaves 1
setblock ~103~8~9 minecraft:leaves 2
setblock ~103~10~9 minecraft:leaves 2
setblock ~103~21~9 minecraft:leaves 2
setblock ~103~30~9 minecraft:leaves 1
setblock ~104~3~9 minecraft:log 1
setblock ~104~4~9 minecraft:leaves 2
setblock ~104~5~9 minecraft:log 1
setblock ~104~6~9 minecraft:leaves 2
setblock ~104~7~9 minecraft:leaves 1
setblock ~104~9~9 minecraft:leaves 2
setblock ~104~28~9 minecraft:log 1
setblock ~104~29~9 minecraft:leaves 1
setblock ~104~30~9 minecraft:log 1
fill ~105~3~9 ~113~3~9 minecraft:dirt 0
fill ~105~4~9 ~113~31~9 minecraft:stonebrick 0
fill ~106~32~9 ~112~33~9 minecraft:stained_hardened_clay 9
fill ~107~2~9 ~114~2~44 minecraft:dirt 0
fill ~107~35~9 ~112~35~9 minecraft:stonebrick 0
fill ~108~34~9 ~110~34~9 minecraft:stained_hardened_clay 9
fill ~109~36~9 ~109~37~9 minecraft:stonebrick 0
fill ~111~34~9 ~113~34~9 minecraft:stonebrick 0
setblock ~113~33~9 minecraft:stonebrick 0
fill ~114~3~9 ~114~4~9 minecraft:log 1
fill ~114~15~9 ~115~15~9 minecraft:leaves 2
setblock ~114~16~9 minecraft:leaves 1
setblock ~114~17~9 minecraft:leaves 2
setblock ~114~18~9 minecraft:leaves 1
setblock ~114~19~9 minecraft:leaves 2
setblock ~114~21~9 minecraft:leaves 1
setblock ~114~23~9 minecraft:leaves 2
fill ~114~25~9 ~115~25~9 minecraft:leaves 2
fill ~115~2~9 ~138~2~9 minecraft:grass
setblock ~115~4~9 minecraft:leaves 2
setblock ~115~11~9 minecraft:leaves 2
fill ~115~12~9 ~116~13~9 minecraft:log 1
setblock ~115~14~9 minecraft:log 1
setblock ~115~24~9 minecraft:log 1
setblock ~115~26~9 minecraft:leaves 2
setblock ~116~3~9 minecraft:leaves 2
setblock ~116~4~9 minecraft:log 1
setblock ~116~5~9 minecraft:leaves 2
setblock ~116~10~9 minecraft:leaves 2
setblock ~116~11~9 minecraft:log 1
setblock ~116~26~9 minecraft:log 1
fill ~116~29~9 ~116~30~9 minecraft:leaves 1
setblock ~116~31~9 minecraft:leaves 2
setblock ~117~26~9 minecraft:leaves 2
fill ~117~28~9 ~118~28~9 minecraft:leaves 1
fill ~117~30~9 ~119~30~10 minecraft:stonebrick 0
setblock ~117~31~9 minecraft:stonebrick 0
setblock ~118~27~9 minecraft:leaves 2
setblock ~118~29~9 minecraft:log 1
fill ~119~4~9 ~119~6~9 minecraft:leaves 2
fill ~120~5~9 ~120~5~11 minecraft:leaves 2
fill ~1~2~10 ~12~2~10 minecraft:grass
fill ~11~30~10 ~12~30~13 minecraft:stonebrick 0
setblock ~12~3~10 minecraft:leaves 2
fill ~12~24~10 ~12~29~10 minecraft:stonebrick 0
fill ~13~2~10 ~14~2~43 minecraft:dirt 0
fill ~13~3~10 ~14~3~10 minecraft:leaves 1
setblock ~13~4~10 minecraft:log 1
setblock ~13~17~10 minecraft:leaves 2
setblock ~13~18~10 minecraft:log 1
fill ~13~19~10 ~13~19~11 minecraft:leaves 1
setblock ~13~20~10 minecraft:leaves 2
fill ~13~21~10 ~13~21~11 minecraft:leaves 1
setblock ~13~22~10 minecraft:leaves 2
setblock ~13~27~10 minecraft:log 1
fill ~13~28~10 ~18~29~10 minecraft:stonebrick 0
setblock ~14~18~10 minecraft:leaves 1
setblock ~14~21~10 minecraft:log 1
setblock ~14~23~10 minecraft:leaves 1
fill ~14~24~10 ~18~26~10 minecraft:stonebrick 0
fill ~14~27~10 ~14~27~11 minecraft:stonebrick 0
fill ~14~34~10 ~14~34~11 minecraft:stonebrick 0
setblock ~15~2~10 minecraft:grass
setblock ~15~4~10 minecraft:log 1
setblock ~15~16~10 minecraft:leaves 2
fill ~15~18~10 ~15~23~10 minecraft:leaves 2
fill ~15~31~10 ~15~32~10 minecraft:leaves 1
fill ~15~35~10 ~15~36~11 minecraft:stonebrick 0
fill ~16~3~10 ~19~3~10 minecraft:dirt 0
fill ~16~4~10 ~18~23~10 minecraft:stonebrick 0
fill ~16~27~10 ~18~27~10 minecraft:stonebrick 0
fill ~16~30~10 ~18~31~10 minecraft:stonebrick 0
fill ~16~32~10 ~19~32~10 minecraft:stained_hardened_clay 9
fill ~16~37~10 ~16~37~11 minecraft:stonebrick 0
fill ~17~33~10 ~19~34~10 minecraft:stained_hardened_clay 9
fill ~17~38~10 ~18~38~11 minecraft:stonebrick 0
fill ~18~2~10 ~18~2~46 minecraft:dirt 0
fill ~18~35~10 ~21~35~10 minecraft:stained_hardened_clay 9
setblock ~19~4~10 minecraft:log 1
fill ~19~5~10 ~19~6~10 minecraft:leaves 2
fill ~19~11~10 ~27~11~43 minecraft:stained_hardened_clay 9
fill ~19~12~10 ~19~13~10 minecraft:leaves 2
setblock ~19~14~10 minecraft:log 1
setblock ~19~15~10 minecraft:leaves 1
fill ~19~21~10 ~27~21~43 minecraft:stained_hardened_clay 9
fill ~19~25~10 ~20~25~10 minecraft:leaves 2
fill ~19~36~10 ~21~36~10 minecraft:stained_hardened_clay 9
fill ~19~39~10 ~20~39~11 minecraft:stonebrick 0
fill ~20~3~10 ~27~3~26 minecraft:grass
setblock ~20~5~10 minecraft:leaves 2
setblock ~20~8~10 minecraft:log 1
setblock ~20~13~10 minecraft:leaves 1
setblock ~20~26~10 minecraft:log 1
setblock ~20~28~10 minecraft:leaves 1
fill ~20~34~10 ~21~34~10 minecraft:stained_hardened_clay 9
setblock ~21~6~10 minecraft:leaves 2
setblock ~21~8~10 minecraft:leaves 1
setblock ~21~19~10 minecraft:leaves 1
setblock ~21~20~10 minecraft:log 1
setblock ~21~25~10 minecraft:leaves 1
fill ~21~27~10 ~21~28~10 minecraft:leaves 2
setblock ~21~29~10 minecraft:log 1
setblock ~21~37~10 minecraft:stained_hardened_clay 9
fill ~21~40~10 ~25~40~11 minecraft:stonebrick 0
setblock ~22~8~10 minecraft:leaves 2
fill ~22~17~10 ~22~18~10 minecraft:leaves 2
setblock ~22~19~10 minecraft:log 1
setblock ~22~28~10 minecraft:leaves 2
setblock ~22~30~10 minecraft:log 1
fill ~22~35~10 ~24~37~10 minecraft:stone 6
setblock ~23~18~10 minecraft:leaves 2
fill ~23~38~10 ~23~39~10 minecraft:stonebrick 0
fill ~24~15~10 ~24~17~10 minecraft:leaves 2
fill ~25~15~10 ~25~16~10 minecraft:log 1
fill ~25~30~10 ~26~30~10 minecraft:log 1
setblock ~25~31~10 minecraft:leaves 1
fill ~25~34~10 ~29~34~10 minecraft:stained_hardened_clay 9
fill ~25~35~10 ~28~35~10 minecraft:stained_hardened_clay 9
fill ~25~36~10 ~27~36~10 minecraft:stained_hardened_clay 9
setblock ~25~37~10 minecraft:stained_hardened_clay 9
fill ~26~14~10 ~26~15~10 minecraft:leaves 1
setblock ~26~16~10 minecraft:log 1
setblock ~26~31~10 minecraft:leaves 2
fill ~26~39~10 ~27~39~11 minecraft:stonebrick 0
setblock ~27~12~10 minecraft:log 1
setblock ~27~13~10 minecraft:leaves 1
setblock ~27~31~10 minecraft:log 1
fill ~27~32~10 ~30~32~10 minecraft:stained_hardened_clay 9
fill ~27~33~10 ~29~33~10 minecraft:stained_hardened_clay 9
fill ~28~3~10 ~30~3~10 minecraft:dirt 0
fill ~28~4~10 ~30~31~10 minecraft:stonebrick 0
fill ~28~38~10 ~29~38~11 minecraft:stonebrick 0
fill ~29~2~10 ~30~2~46 minecraft:dirt 0
fill ~30~37~10 ~30~37~11 minecraft:stonebrick 0
fill ~31~2~10 ~38~2~10 minecraft:grass
fill ~31~4~10 ~33~4~10 minecraft:leaves 2
setblock ~31~9~10 minecraft:leaves 2
setblock ~31~12~10 minecraft:log 1
setblock ~31~13~10 minecraft:leaves 1
setblock ~31~14~10 minecraft:leaves 2
setblock ~31~15~10 minecraft:leaves 1
fill ~31~16~10 ~32~16~10 minecraft:leaves 2
fill ~31~17~10 ~31~18~10 minecraft:leaves 2
setblock ~31~19~10 minecraft:leaves 1
fill ~31~24~10 ~32~29~11 minecraft:stonebrick 0
fill ~31~35~10 ~31~36~11 minecraft:stonebrick 0
fill ~32~8~10 ~32~9~10 minecraft:leaves 1
fill ~32~18~10 ~32~19~10 minecraft:log 1
fill ~32~34~10 ~32~34~11 minecraft:stonebrick 0
fill ~33~3~10 ~34~3~10 minecraft:leaves 2
fill ~33~6~10 ~35~6~10 minecraft:leaves 2
fill ~33~8~10 ~33~8~11 minecraft:leaves 2
setblock ~33~9~10 minecraft:leaves 2
fill ~33~17~10 ~33~19~10 minecraft:leaves 2
setblock ~33~27~10 minecraft:leaves 1
fill ~33~28~10 ~34~29~10 minecraft:stonebrick 0
setblock ~34~4~10 minecraft:leaves 1
setblock ~34~5~10 minecraft:leaves 2
fill ~34~7~10 ~35~7~11 minecraft:leaves 2
fill ~34~24~10 ~34~27~10 minecraft:stonebrick 0
fill ~34~30~10 ~35~30~13 minecraft:stonebrick 0
fill ~35~25~10 ~35~25~12 minecraft:leaves 2
fill ~35~26~10 ~36~26~10 minecraft:leaves 2
fill ~35~27~10 ~35~27~11 minecraft:leaves 2
setblock ~35~28~10 minecraft:leaves 2
setblock ~35~29~10 minecraft:leaves 1
setblock ~36~5~10 minecraft:leaves 2
setblock ~37~4~10 minecraft:leaves 2
fill ~39~2~10 ~39~2~11 minecraft:dirt 0
fill ~39~3~10 ~39~3~11 minecraft:leaves 1
fill ~40~2~10 ~100~2~10 minecraft:grass
setblock ~41~3~10 minecraft:leaves 2
fill ~97~30~10 ~98~30~13 minecraft:stonebrick 0
fill ~98~7~10 ~98~7~12 minecraft:leaves 2
fill ~98~24~10 ~98~29~10 minecraft:stonebrick 0
setblock ~99~3~10 minecraft:leaves 2
fill ~99~5~10 ~99~6~10 minecraft:leaves 2
setblock ~99~7~10 minecraft:leaves 1
fill ~99~8~10 ~100~8~10 minecraft:leaves 2
fill ~99~10~10 ~100~10~10 minecraft:leaves 2
fill ~99~11~10 ~99~11~11 minecraft:leaves 2
setblock ~99~12~10 minecraft:leaves 1
fill ~99~15~10 ~100~15~10 minecraft:leaves 2
fill ~99~28~10 ~104~29~10 minecraft:stonebrick 0
setblock ~100~5~10 minecraft:leaves 1
setblock ~100~6~10 minecraft:log 1
setblock ~100~7~10 minecraft:leaves 2
setblock ~100~9~10 minecraft:leaves 1
setblock ~100~11~10 minecraft:leaves 1
fill ~100~19~10 ~101~19~10 minecraft:leaves 2
fill ~100~24~10 ~104~26~10 minecraft:stonebrick 0
fill ~100~27~10 ~100~27~11 minecraft:stonebrick 0
setblock ~100~31~10 minecraft:leaves 1
fill ~100~34~10 ~100~34~11 minecraft:stonebrick 0
fill ~101~2~10 ~102~2~35 minecraft:dirt 0
setblock ~101~3~10 minecraft:log 1
setblock ~101~4~10 minecraft:leaves 2
setblock ~101~6~10 minecraft:leaves 2
setblock ~101~7~10 minecraft:log 1
fill ~101~8~10 ~101~9~10 minecraft:leaves 1
setblock ~101~10~10 minecraft:log 1
setblock ~101~11~10 minecraft:leaves 2
setblock ~101~12~10 minecraft:leaves 1
setblock ~101~13~10 minecraft:leaves 2
setblock ~101~14~10 minecraft:leaves 1
setblock ~101~17~10 minecraft:log 1
setblock ~101~20~10 minecraft:leaves 2
setblock ~101~21~10 minecraft:log 1
setblock ~101~22~10 minecraft:leaves 2
setblock ~101~31~10 minecraft:leaves 2
fill ~101~35~10 ~101~36~11 minecraft:stonebrick 0
fill ~102~3~10 ~106~3~10 minecraft:dirt 0
fill ~102~4~10 ~104~23~10 minecraft:stonebrick 0
fill ~102~27~10 ~104~27~10 minecraft:stonebrick 0
fill ~102~30~10 ~104~31~10 minecraft:stonebrick 0
fill ~102~32~10 ~105~32~10 minecraft:stained_hardened_clay 9
fill ~102~37~10 ~102~37~11 minecraft:stonebrick 0
fill ~103~33~10 ~105~34~10 minecraft:stained_hardened_clay 9
fill ~103~38~10 ~104~38~11 minecraft:stonebrick 0
fill ~104~35~10 ~107~35~10 minecraft:stained_hardened_clay 9
setblock ~105~4~10 minecraft:leaves 1
setblock ~105~5~10 minecraft:leaves 2
fill ~105~11~10 ~113~11~43 minecraft:stained_hardened_clay 9
fill ~105~21~10 ~113~21~43 minecraft:stained_hardened_clay 9
fill ~105~28~10 ~105~30~10 minecraft:leaves 2
fill ~105~36~10 ~107~36~10 minecraft:stained_hardened_clay 9
fill ~105~39~10 ~106~39~11 minecraft:stonebrick 0
setblock ~106~4~10 minecraft:log 1
setblock ~106~6~10 minecraft:leaves 2
fill ~106~28~10 ~107~28~10 minecraft:log 1
fill ~106~29~10 ~107~29~10 minecraft:leaves 1
setblock ~106~30~10 minecraft:leaves 2
fill ~106~34~10 ~107~34~10 minecraft:stained_hardened_clay 9
fill ~107~3~10 ~110~3~26 minecraft:grass
fill ~107~4~10 ~107~5~10 minecraft:leaves 2
setblock ~107~27~10 minecraft:log 1
setblock ~107~37~10 minecraft:stained_hardened_clay 9
fill ~107~40~10 ~111~40~11 minecraft:stonebrick 0
setblock ~108~26~10 minecraft:log 1
fill ~108~27~10 ~110~27~10 minecraft:leaves 2
setblock ~108~28~10 minecraft:leaves 1
fill ~108~35~10 ~110~37~10 minecraft:stone 6
fill ~109~4~10 ~110~4~10 minecraft:leaves 2
setblock ~109~26~10 minecraft:leaves 1
fill ~109~38~10 ~109~39~10 minecraft:stonebrick 0
setblock ~110~25~10 minecraft:leaves 1
setblock ~110~26~10 minecraft:log 1
setblock ~111~3~10 minecraft:dirt 0
setblock ~111~4~10 minecraft:leaves 1
fill ~111~25~10 ~111~26~10 minecraft:leaves 2
fill ~111~34~10 ~115~34~10 minecraft:stained_hardened_clay 9
fill ~111~35~10 ~114~35~10 minecraft:stained_hardened_clay 9
fill ~111~36~10 ~113~36~10 minecraft:stained_hardened_clay 9
setblock ~111~37~10 minecraft:stained_hardened_clay 9
fill ~112~3~10 ~113~3~43 minecraft:grass
setblock ~112~17~10 minecraft:log 1
setblock ~112~22~10 minecraft:leaves 2
setblock ~112~24~10 minecraft:log 1
setblock ~112~25~10 minecraft:leaves 1
fill ~112~39~10 ~113~39~11 minecraft:stonebrick 0
setblock ~113~5~10 minecraft:log 1
setblock ~113~14~10 minecraft:leaves 2
fill ~113~15~10 ~113~15~11 minecraft:log 1
setblock ~113~16~10 minecraft:leaves 1
setblock ~113~17~10 minecraft:leaves 2
fill ~113~18~10 ~113~20~10 minecraft:leaves 1
setblock ~113~23~10 minecraft:leaves 2
setblock ~113~24~10 minecraft:leaves 1
setblock ~113~25~10 minecraft:log 1
fill ~113~32~10 ~116~32~10 minecraft:stained_hardened_clay 9
fill ~113~33~10 ~115~33~10 minecraft:stained_hardened_clay 9
fill ~114~3~10 ~116~3~10 minecraft:dirt 0
fill ~114~4~10 ~116~31~10 minecraft:stonebrick 0
fill ~114~38~10 ~115~38~11 minecraft:stonebrick 0
fill ~115~2~10 ~117~2~43 minecraft:dirt 0
fill ~116~37~10 ~116~37~11 minecraft:stonebrick 0
fill ~117~3~10 ~117~4~10 minecraft:log 1
setblock ~117~9~10 minecraft:leaves 1
setblock ~117~10~10 minecraft:leaves 2
setblock ~117~11~10 minecraft:leaves 1
fill ~117~24~10 ~118~29~11 minecraft:stonebrick 0
fill ~117~35~10 ~117~36~11 minecraft:stonebrick 0
fill ~118~2~10 ~138~2~10 minecraft:grass
fill ~118~4~10 ~118~5~10 minecraft:leaves 2
fill ~118~6~10 ~120~6~10 minecraft:leaves 1
setblock ~118~8~10 minecraft:log 1
fill ~118~9~10 ~119~9~10 minecraft:leaves 2
setblock ~118~10~10 minecraft:leaves 1
fill ~118~34~10 ~118~34~11 minecraft:stonebrick 0
fill ~119~4~10 ~119~4~11 minecraft:log 1
setblock ~119~5~10 minecraft:leaves 1
fill ~119~28~10 ~120~29~10 minecraft:stonebrick 0
fill ~120~24~10 ~120~27~10 minecraft:stonebrick 0
fill ~120~30~10 ~121~30~13 minecraft:stonebrick 0
fill ~1~2~11 ~11~2~12 minecraft:grass
fill ~9~30~11 ~10~30~14 minecraft:stonebrick 0
setblock ~12~2~11 minecraft:dirt 0
fill ~12~3~11 ~13~3~11 minecraft:log 1
fill ~12~4~11 ~13~4~11 minecraft:leaves 2
fill ~12~25~11 ~12~25~13 minecraft:stonebrick 0
fill ~12~28~11 ~12~29~13 minecraft:stonebrick 0
setblock ~13~18~11 minecraft:leaves 2
setblock ~13~22~11 minecraft:log 1
fill ~14~3~11 ~15~3~12 minecraft:dirt 0
fill ~14~4~11 ~15~26~11 minecraft:stonebrick 0
fill ~14~28~11 ~15~31~11 minecraft:stonebrick 0
fill ~14~32~11 ~15~32~11 minecraft:stained_hardened_clay 9
fill ~15~2~11 ~15~2~51 minecraft:dirt 0
fill ~15~27~11 ~15~27~13 minecraft:stonebrick 0
fill ~15~33~11 ~16~34~11 minecraft:stained_hardened_clay 9
fill ~16~3~11 ~17~3~43 minecraft:grass
fill ~16~11~11 ~18~11~43 minecraft:stained_hardened_clay 9
fill ~16~15~11 ~16~16~11 minecraft:log 1
fill ~16~21~11 ~18~21~43 minecraft:stained_hardened_clay 9
setblock ~16~26~11 minecraft:stonebrick 0
fill ~16~35~11 ~17~36~11 minecraft:stained_hardened_clay 9
fill ~17~14~11 ~18~14~11 minecraft:log 1
fill ~17~37~11 ~20~37~11 minecraft:stained_hardened_clay 9
setblock ~18~3~11 minecraft:dirt 0
setblock ~18~4~11 minecraft:log 1
setblock ~18~36~11 minecraft:stained_hardened_clay 9
fill ~19~3~11 ~19~3~43 minecraft:grass
fill ~19~38~11 ~21~38~11 minecraft:stained_hardened_clay 9
setblock ~21~39~11 minecraft:stained_hardened_clay 9
fill ~22~38~11 ~24~39~11 minecraft:stone 6
fill ~23~41~11 ~23~41~12 minecraft:stonebrick 0
fill ~25~38~11 ~27~38~11 minecraft:stained_hardened_clay 9
setblock ~25~39~11 minecraft:stained_hardened_clay 9
fill ~26~37~11 ~29~37~11 minecraft:stained_hardened_clay 9
setblock ~27~13~11 minecraft:log 1
fill ~28~3~11 ~30~3~40 minecraft:grass
fill ~28~11~11 ~30~11~44 minecraft:stained_hardened_clay 9
setblock ~28~13~11 minecraft:leaves 1
fill ~28~14~11 ~28~15~11 minecraft:leaves 2
fill ~28~21~11 ~30~21~43 minecraft:stained_hardened_clay 9
fill ~28~36~11 ~30~36~11 minecraft:stained_hardened_clay 9
fill ~29~15~11 ~30~15~11 minecraft:leaves 2
setblock ~29~16~11 minecraft:leaves 1
fill ~29~35~11 ~30~35~11 minecraft:stained_hardened_clay 9
setblock ~30~9~11 minecraft:leaves 2
fill ~30~12~11 ~30~13~11 minecraft:leaves 1
setblock ~30~14~11 minecraft:log 1
fill ~30~16~11 ~30~17~11 minecraft:log 1
setblock ~30~26~11 minecraft:stonebrick 0
fill ~30~33~11 ~31~34~11 minecraft:stained_hardened_clay 9
fill ~31~2~11 ~32~2~33 minecraft:dirt 0
fill ~31~3~11 ~32~3~11 minecraft:dirt 0
fill ~31~4~11 ~32~23~11 minecraft:stonebrick 0
fill ~31~30~11 ~32~31~11 minecraft:stonebrick 0
fill ~31~32~11 ~32~32~11 minecraft:stained_hardened_clay 9
fill ~33~2~11 ~34~2~11 minecraft:grass
fill ~33~3~11 ~33~7~11 minecraft:leaves 2
setblock ~33~9~11 minecraft:leaves 1
setblock ~33~17~11 minecraft:log 1
fill ~33~18~11 ~33~20~11 minecraft:leaves 2
fill ~33~27~11 ~33~29~11 minecraft:leaves 2
fill ~34~4~11 ~35~4~12 minecraft:leaves 2
setblock ~34~5~11 minecraft:log 1
fill ~34~6~11 ~35~6~11 minecraft:leaves 1
fill ~34~8~11 ~35~8~11 minecraft:leaves 1
fill ~34~19~11 ~34~19~12 minecraft:leaves 1
fill ~34~22~11 ~34~22~12 minecraft:leaves 2
fill ~34~25~11 ~34~25~13 minecraft:stonebrick 0
setblock ~34~26~11 minecraft:log 1
fill ~34~27~11 ~34~29~13 minecraft:stonebrick 0
fill ~35~2~11 ~35~2~35 minecraft:dirt 0
setblock ~35~3~11 minecraft:log 1
setblock ~35~21~11 minecraft:leaves 2
fill ~35~22~11 ~35~22~12 minecraft:log 1
fill ~35~23~11 ~36~23~12 minecraft:leaves 2
fill ~35~24~11 ~37~24~11 minecraft:leaves 2
setblock ~35~26~11 minecraft:leaves 2
fill ~36~2~11 ~37~2~13 minecraft:grass
fill ~36~3~11 ~37~3~13 minecraft:leaves 2
setblock ~36~6~11 minecraft:leaves 2
fill ~36~7~11 ~36~8~11 minecraft:log 1
fill ~36~22~11 ~36~22~13 minecraft:leaves 2
fill ~36~25~11 ~36~25~12 minecraft:leaves 2
fill ~36~26~11 ~36~26~12 minecraft:leaves 1
fill ~36~27~11 ~36~27~12 minecraft:log 1
fill ~36~30~11 ~37~30~14 minecraft:stonebrick 0
setblock ~37~4~11 minecraft:log 1
setblock ~38~2~11 minecraft:dirt 0
setblock ~38~3~11 minecraft:log 1
setblock ~38~4~11 minecraft:leaves 1
fill ~39~4~11 ~39~4~12 minecraft:leaves 2
fill ~40~2~11 ~98~2~11 minecraft:grass
setblock ~40~3~11 minecraft:leaves 1
fill ~95~30~11 ~96~30~14 minecraft:stonebrick 0
fill ~96~7~11 ~97~7~11 minecraft:leaves 2
fill ~97~6~11 ~97~6~12 minecraft:leaves 2
fill ~97~8~11 ~97~8~12 minecraft:leaves 2
fill ~98~3~11 ~99~3~11 minecraft:leaves 1
fill ~98~4~11 ~99~4~11 minecraft:log 1
setblock ~98~5~11 minecraft:leaves 2
fill ~98~6~11 ~98~6~12 minecraft:log 1
fill ~98~25~11 ~98~25~13 minecraft:stonebrick 0
fill ~98~28~11 ~98~29~13 minecraft:stonebrick 0
fill ~99~2~11 ~100~2~38 minecraft:dirt 0
setblock ~99~5~11 minecraft:leaves 1
fill ~99~6~11 ~99~7~11 minecraft:leaves 2
setblock ~99~8~11 minecraft:log 1
setblock ~99~9~11 minecraft:leaves 1
setblock ~99~31~11 minecraft:leaves 1
setblock ~99~32~11 minecraft:leaves 2
fill ~100~3~11 ~101~3~12 minecraft:dirt 0
fill ~100~4~11 ~101~26~11 minecraft:stonebrick 0
fill ~100~28~11 ~101~31~11 minecraft:stonebrick 0
fill ~100~32~11 ~101~32~11 minecraft:stained_hardened_clay 9
fill ~101~27~11 ~101~27~13 minecraft:stonebrick 0
fill ~101~33~11 ~102~34~11 minecraft:stained_hardened_clay 9
fill ~102~3~11 ~106~3~18 minecraft:grass
fill ~102~4~11 ~104~4~11 minecraft:leaves 2
fill ~102~8~11 ~103~8~11 minecraft:leaves 2
setblock ~102~9~11 minecraft:leaves 2
fill ~102~11~11 ~104~11~44 minecraft:stained_hardened_clay 9
fill ~102~12~11 ~103~12~11 minecraft:log 1
setblock ~102~13~11 minecraft:leaves 1
setblock ~102~14~11 minecraft:leaves 2
setblock ~102~15~11 minecraft:log 1
setblock ~102~16~11 minecraft:leaves 1
setblock ~102~17~11 minecraft:leaves 2
setblock ~102~18~11 minecraft:log 1
fill ~102~21~11 ~104~21~43 minecraft:stained_hardened_clay 9
setblock ~102~26~11 minecraft:stonebrick 0
fill ~102~29~11 ~102~30~11 minecraft:log 1
setblock ~102~31~11 minecraft:leaves 1
fill ~102~35~11 ~103~36~11 minecraft:stained_hardened_clay 9
setblock ~103~9~11 minecraft:leaves 1
setblock ~103~13~11 minecraft:leaves 2
setblock ~103~16~11 minecraft:log 1
setblock ~103~18~11 minecraft:leaves 1
setblock ~103~30~11 minecraft:log 1
fill ~103~37~11 ~106~37~11 minecraft:stained_hardened_clay 9
setblock ~104~12~11 minecraft:leaves 2
setblock ~104~36~11 minecraft:stained_hardened_clay 9
fill ~105~38~11 ~107~38~11 minecraft:stained_hardened_clay 9
setblock ~107~39~11 minecraft:stained_hardened_clay 9
fill ~108~38~11 ~110~39~11 minecraft:stone 6
fill ~109~41~11 ~109~41~12 minecraft:stonebrick 0
fill ~111~3~11 ~111~3~47 minecraft:grass
fill ~111~38~11 ~113~38~11 minecraft:stained_hardened_clay 9
setblock ~111~39~11 minecraft:stained_hardened_clay 9
fill ~112~37~11 ~115~37~11 minecraft:stained_hardened_clay 9
fill ~114~3~11 ~114~3~43 minecraft:grass
fill ~114~11~11 ~116~11~43 minecraft:stained_hardened_clay 9
setblock ~114~14~11 minecraft:leaves 2
setblock ~114~15~11 minecraft:log 1
setblock ~114~16~11 minecraft:leaves 1
fill ~114~21~11 ~116~21~43 minecraft:stained_hardened_clay 9
setblock ~114~23~11 minecraft:leaves 2
setblock ~114~24~11 minecraft:log 1
setblock ~114~26~11 minecraft:leaves 1
fill ~114~36~11 ~116~36~11 minecraft:stained_hardened_clay 9
setblock ~115~3~11 minecraft:dirt 0
setblock ~115~4~11 minecraft:log 1
fill ~115~13~11 ~116~13~11 minecraft:leaves 2
setblock ~115~14~11 minecraft:log 1
fill ~115~24~11 ~115~26~11 minecraft:leaves 2
setblock ~115~27~11 minecraft:log 1
fill ~115~35~11 ~116~35~11 minecraft:stained_hardened_clay 9
fill ~116~3~11 ~116~3~43 minecraft:grass
setblock ~116~10~11 minecraft:log 1
setblock ~116~26~11 minecraft:stonebrick 0
fill ~116~33~11 ~117~34~11 minecraft:stained_hardened_clay 9
fill ~117~3~11 ~118~3~11 minecraft:dirt 0
fill ~117~4~11 ~118~23~11 minecraft:stonebrick 0
fill ~117~30~11 ~118~31~11 minecraft:stonebrick 0
fill ~117~32~11 ~118~32~11 minecraft:stained_hardened_clay 9
fill ~118~2~11 ~118~2~43 minecraft:dirt 0
fill ~119~2~11 ~138~2~11 minecraft:grass
fill ~119~5~11 ~119~6~11 minecraft:leaves 2
setblock ~119~7~11 minecraft:leaves 1
setblock ~119~8~11 minecraft:log 1
fill ~119~9~11 ~119~10~11 minecraft:leaves 2
setblock ~119~28~11 minecraft:log 1
setblock ~120~7~11 minecraft:leaves 2
fill ~120~25~11 ~120~25~13 minecraft:stonebrick 0
fill ~120~27~11 ~120~29~13 minecraft:stonebrick 0
fill ~122~30~11 ~123~30~14 minecraft:stonebrick 0
fill ~8~30~12 ~8~30~17 minecraft:stonebrick 0
setblock ~11~3~12 minecraft:leaves 1
setblock ~11~5~12 minecraft:log 1
setblock ~11~6~12 minecraft:leaves 2
fill ~11~29~12 ~11~29~13 minecraft:stonebrick 0
fill ~11~35~12 ~11~37~12 minecraft:stonebrick 0
setblock ~12~2~12 minecraft:grass
setblock ~12~3~12 minecraft:leaves 2
fill ~12~24~12 ~13~24~13 minecraft:stonebrick 0
fill ~12~26~12 ~13~27~13 minecraft:stonebrick 0
setblock ~13~3~12 minecraft:dirt 0
fill ~13~4~12 ~13~23~12 minecraft:stonebrick 0
fill ~13~25~12 ~13~25~13 minecraft:stonebrick 0
fill ~13~28~12 ~13~30~13 minecraft:stonebrick 0
setblock ~13~31~12 minecraft:stonebrick 0
fill ~13~32~12 ~13~34~12 minecraft:stained_hardened_clay 9
fill ~14~4~12 ~15~4~12 minecraft:log 1
fill ~14~11~12 ~15~11~43 minecraft:stained_hardened_clay 9
fill ~14~21~12 ~15~21~42 minecraft:stained_hardened_clay 9
setblock ~14~22~12 minecraft:log 1
setblock ~14~26~12 minecraft:leaves 1
setblock ~14~27~12 minecraft:log 1
setblock ~14~28~12 minecraft:leaves 2
fill ~14~33~12 ~14~36~12 minecraft:stained_hardened_clay 9
fill ~15~26~12 ~15~26~14 minecraft:stonebrick 0
fill ~15~28~12 ~15~30~13 minecraft:stonebrick 0
fill ~15~35~12 ~15~37~12 minecraft:stained_hardened_clay 9
setblock ~16~27~12 minecraft:stonebrick 0
setblock ~16~30~12 minecraft:stonebrick 0
fill ~16~37~12 ~16~38~12 minecraft:stained_hardened_clay 9
fill ~17~38~12 ~18~39~12 minecraft:stained_hardened_clay 9
fill ~18~3~12 ~18~3~43 minecraft:grass
fill ~19~39~12 ~20~40~12 minecraft:stained_hardened_clay 9
setblock ~21~40~12 minecraft:stained_hardened_clay 9
fill ~22~40~12 ~24~40~12 minecraft:stone 6
setblock ~23~42~12 minecraft:stonebrick 0
fill ~25~40~12 ~27~40~12 minecraft:stained_hardened_clay 9
fill ~26~39~12 ~29~39~12 minecraft:stained_hardened_clay 9
fill ~28~38~12 ~30~38~12 minecraft:stained_hardened_clay 9
fill ~30~27~12 ~31~27~12 minecraft:stonebrick 0
fill ~30~30~12 ~31~30~12 minecraft:stonebrick 0
fill ~30~37~12 ~31~37~12 minecraft:stained_hardened_clay 9
fill ~31~3~12 ~32~3~39 minecraft:grass
fill ~31~9~12 ~32~9~12 minecraft:leaves 2
fill ~31~10~12 ~32~10~12 minecraft:log 1
fill ~31~11~12 ~32~11~41 minecraft:stained_hardened_clay 9
setblock ~31~18~12 minecraft:log 1
fill ~31~21~12 ~32~21~41 minecraft:stained_hardened_clay 9
fill ~31~26~12 ~31~26~14 minecraft:stonebrick 0
fill ~31~28~12 ~31~29~13 minecraft:stonebrick 0
setblock ~31~32~12 minecraft:stonebrick 0
fill ~31~35~12 ~32~36~12 minecraft:stained_hardened_clay 9
fill ~32~4~12 ~32~4~13 minecraft:leaves 2
setblock ~32~5~12 minecraft:leaves 2
setblock ~32~6~12 minecraft:log 1
setblock ~32~7~12 minecraft:leaves 2
setblock ~32~8~12 minecraft:leaves 1
setblock ~32~17~12 minecraft:log 1
setblock ~32~18~12 minecraft:leaves 1
fill ~32~19~12 ~32~20~12 minecraft:log 1
fill ~32~33~12 ~33~34~12 minecraft:stained_hardened_clay 9
fill ~33~2~12 ~33~2~44 minecraft:dirt 0
setblock ~33~3~12 minecraft:dirt 0
fill ~33~4~12 ~33~31~12 minecraft:stonebrick 0
setblock ~33~32~12 minecraft:stained_hardened_clay 9
setblock ~34~2~12 minecraft:grass
setblock ~34~3~12 minecraft:leaves 2
setblock ~34~5~12 minecraft:leaves 1
fill ~34~6~12 ~35~6~12 minecraft:leaves 2
setblock ~34~7~12 minecraft:log 1
fill ~34~8~12 ~36~8~12 minecraft:leaves 2
setblock ~34~9~12 minecraft:leaves 2
setblock ~34~18~12 minecraft:leaves 2
setblock ~34~20~12 minecraft:leaves 1
setblock ~34~21~12 minecraft:leaves 2
setblock ~34~23~12 minecraft:leaves 1
fill ~34~24~12 ~34~24~13 minecraft:stonebrick 0
fill ~34~26~12 ~34~26~13 minecraft:stonebrick 0
setblock ~35~3~12 minecraft:leaves 1
setblock ~35~7~12 minecraft:leaves 1
setblock ~35~9~12 minecraft:log 1
setblock ~35~20~12 minecraft:leaves 2
setblock ~35~21~12 minecraft:log 1
setblock ~35~24~12 minecraft:leaves 2
setblock ~35~26~12 minecraft:log 1
setblock ~35~27~12 minecraft:leaves 1
fill ~35~29~12 ~35~29~13 minecraft:stonebrick 0
fill ~35~34~12 ~35~37~12 minecraft:stonebrick 0
setblock ~36~4~12 minecraft:leaves 1
setblock ~36~6~12 minecraft:leaves 1
fill ~36~7~12 ~36~7~13 minecraft:leaves 2
setblock ~36~9~12 minecraft:leaves 2
setblock ~36~21~12 minecraft:leaves 2
setblock ~36~24~12 minecraft:leaves 1
fill ~37~4~12 ~38~4~13 minecraft:leaves 2
fill ~37~23~12 ~37~24~13 minecraft:leaves 2
setblock ~37~25~12 minecraft:leaves 2
fill ~38~2~12 ~97~2~12 minecraft:grass
fill ~38~3~12 ~40~3~12 minecraft:leaves 2
setblock ~38~5~12 minecraft:leaves 1
fill ~38~30~12 ~38~30~17 minecraft:stonebrick 0
setblock ~39~5~12 minecraft:leaves 2
setblock ~40~4~12 minecraft:leaves 2
fill ~42~3~12 ~42~3~13 minecraft:leaves 2
fill ~94~30~12 ~94~30~17 minecraft:stonebrick 0
fill ~96~3~12 ~97~3~12 minecraft:leaves 2
fill ~96~6~12 ~96~7~12 minecraft:leaves 2
setblock ~97~4~12 minecraft:leaves 1
setblock ~97~7~12 minecraft:log 1
fill ~97~29~12 ~97~29~13 minecraft:stonebrick 0
fill ~97~35~12 ~97~37~12 minecraft:stonebrick 0
fill ~98~2~12 ~98~2~40 minecraft:dirt 0
setblock ~98~3~12 minecraft:leaves 1
setblock ~98~4~12 minecraft:leaves 2
setblock ~98~5~12 minecraft:leaves 1
setblock ~98~8~12 minecraft:leaves 2
fill ~98~24~12 ~99~24~13 minecraft:stonebrick 0
fill ~98~26~12 ~99~27~13 minecraft:stonebrick 0
setblock ~99~3~12 minecraft:dirt 0
fill ~99~4~12 ~99~23~12 minecraft:stonebrick 0
fill ~99~25~12 ~99~25~13 minecraft:stonebrick 0
fill ~99~28~12 ~99~30~13 minecraft:stonebrick 0
setblock ~99~31~12 minecraft:stonebrick 0
fill ~99~32~12 ~99~34~12 minecraft:stained_hardened_clay 9
fill ~100~4~12 ~101~4~12 minecraft:leaves 1
fill ~100~5~12 ~100~7~12 minecraft:leaves 2
setblock ~100~8~12 minecraft:leaves 1
fill ~100~9~12 ~101~9~12 minecraft:leaves 2
fill ~100~11~12 ~101~11~41 minecraft:stained_hardened_clay 9
fill ~100~21~12 ~101~21~41 minecraft:stained_hardened_clay 9
setblock ~100~31~12 minecraft:log 1
fill ~100~33~12 ~100~36~12 minecraft:stained_hardened_clay 9
setblock ~101~7~12 minecraft:leaves 2
fill ~101~26~12 ~101~26~14 minecraft:stonebrick 0
fill ~101~28~12 ~101~30~13 minecraft:stonebrick 0
setblock ~101~31~12 minecraft:leaves 2
fill ~101~35~12 ~101~37~12 minecraft:stained_hardened_clay 9
setblock ~102~8~12 minecraft:leaves 2
setblock ~102~27~12 minecraft:stonebrick 0
setblock ~102~30~12 minecraft:stonebrick 0
fill ~102~37~12 ~102~38~12 minecraft:stained_hardened_clay 9
fill ~103~38~12 ~104~39~12 minecraft:stained_hardened_clay 9
fill ~105~39~12 ~106~40~12 minecraft:stained_hardened_clay 9
setblock ~107~40~12 minecraft:stained_hardened_clay 9
fill ~108~40~12 ~110~40~12 minecraft:stone 6
setblock ~109~42~12 minecraft:stonebrick 0
fill ~111~40~12 ~113~40~12 minecraft:stained_hardened_clay 9
fill ~112~39~12 ~115~39~12 minecraft:stained_hardened_clay 9
fill ~114~38~12 ~116~38~12 minecraft:stained_hardened_clay 9
fill ~115~3~12 ~115~3~43 minecraft:grass
fill ~116~27~12 ~117~27~12 minecraft:stonebrick 0
fill ~116~30~12 ~117~30~12 minecraft:stonebrick 0
fill ~116~37~12 ~117~37~12 minecraft:stained_hardened_clay 9
fill ~117~3~12 ~118~3~42 minecraft:grass
fill ~117~5~12 ~118~5~12 minecraft:leaves 2
setblock ~117~9~12 minecraft:leaves 2
fill ~117~11~12 ~118~11~42 minecraft:stained_hardened_clay 9
fill ~117~21~12 ~118~21~42 minecraft:stained_hardened_clay 9
fill ~117~26~12 ~117~26~14 minecraft:stonebrick 0
fill ~117~28~12 ~117~29~13 minecraft:stonebrick 0
setblock ~117~32~12 minecraft:stonebrick 0
fill ~117~35~12 ~118~36~12 minecraft:stained_hardened_clay 9
setblock ~118~6~12 minecraft:leaves 2
setblock ~118~7~12 minecraft:log 1
fill ~118~8~12 ~118~9~12 minecraft:leaves 2
setblock ~118~10~12 minecraft:leaves 2
fill ~118~33~12 ~119~34~12 minecraft:stained_hardened_clay 9
fill ~119~2~12 ~119~2~42 minecraft:dirt 0
setblock ~119~3~12 minecraft:dirt 0
fill ~119~4~12 ~119~31~12 minecraft:stonebrick 0
setblock ~119~32~12 minecraft:stained_hardened_clay 9
fill ~120~2~12 ~138~2~12 minecraft:grass
setblock ~120~6~12 minecraft:leaves 1
fill ~120~7~12 ~121~7~12 minecraft:leaves 2
setblock ~120~8~12 minecraft:log 1
fill ~120~24~12 ~120~24~13 minecraft:stonebrick 0
fill ~120~26~12 ~120~26~13 minecraft:stonebrick 0
setblock ~121~6~12 minecraft:log 1
fill ~121~29~12 ~121~29~13 minecraft:stonebrick 0
fill ~121~34~12 ~121~37~12 minecraft:stonebrick 0
fill ~124~30~12 ~124~30~17 minecraft:stonebrick 0
fill ~1~2~13 ~10~2~13 minecraft:grass
fill ~7~30~13 ~7~30~16 minecraft:stonebrick 0
setblock ~10~7~13 minecraft:log 1
fill ~10~29~13 ~10~29~14 minecraft:stonebrick 0
fill ~10~35~13 ~10~37~13 minecraft:stonebrick 0
fill ~11~2~13 ~12~2~41 minecraft:dirt 0
fill ~11~3~13 ~12~3~13 minecraft:dirt 0
fill ~11~4~13 ~12~23~13 minecraft:stonebrick 0
fill ~11~24~13 ~11~28~13 minecraft:stonebrick 0
fill ~11~31~13 ~12~31~13 minecraft:stonebrick 0
fill ~12~32~13 ~12~35~13 minecraft:stained_hardened_clay 9
fill ~13~3~13 ~15~3~31 minecraft:grass
fill ~13~11~13 ~13~11~42 minecraft:stained_hardened_clay 9
fill ~13~21~13 ~13~21~41 minecraft:stained_hardened_clay 9
setblock ~13~32~13 minecraft:stonebrick 0
fill ~13~35~13 ~13~36~13 minecraft:stained_hardened_clay 9
setblock ~14~26~13 minecraft:stonebrick 0
setblock ~14~30~13 minecraft:stonebrick 0
fill ~14~37~13 ~14~38~13 minecraft:stained_hardened_clay 9
fill ~15~24~13 ~15~25~13 minecraft:stonebrick 0
setblock ~15~32~13 minecraft:stonebrick 0
fill ~15~38~13 ~15~39~13 minecraft:stained_hardened_clay 9
setblock ~16~26~13 minecraft:stonebrick 0
setblock ~16~39~13 minecraft:stained_hardened_clay 9
fill ~17~40~13 ~18~40~13 minecraft:stained_hardened_clay 9
fill ~18~41~13 ~21~41~13 minecraft:stained_hardened_clay 9
fill ~22~41~13 ~24~42~13 minecraft:stone 6
setblock ~23~43~13 minecraft:stonebrick 0
fill ~25~41~13 ~28~41~13 minecraft:stained_hardened_clay 9
fill ~28~40~13 ~29~40~13 minecraft:stained_hardened_clay 9
setblock ~30~26~13 minecraft:stonebrick 0
fill ~30~39~13 ~31~39~13 minecraft:stained_hardened_clay 9
fill ~31~24~13 ~31~25~13 minecraft:stonebrick 0
setblock ~31~27~13 minecraft:stonebrick 0
fill ~31~30~13 ~33~30~13 minecraft:stonebrick 0
fill ~31~38~13 ~32~38~13 minecraft:stained_hardened_clay 9
setblock ~32~7~13 minecraft:log 1
fill ~32~19~13 ~33~19~13 minecraft:leaves 1
fill ~32~26~13 ~33~26~13 minecraft:stonebrick 0
setblock ~32~37~13 minecraft:stained_hardened_clay 9
fill ~33~3~13 ~33~3~40 minecraft:grass
setblock ~33~4~13 minecraft:leaves 2
fill ~33~5~13 ~33~6~13 minecraft:leaves 1
setblock ~33~7~13 minecraft:leaves 2
fill ~33~8~13 ~33~9~13 minecraft:log 1
fill ~33~11~13 ~33~11~41 minecraft:stained_hardened_clay 9
setblock ~33~18~13 minecraft:leaves 1
setblock ~33~20~13 minecraft:leaves 2
fill ~33~21~13 ~33~21~41 minecraft:stained_hardened_clay 9
fill ~33~24~13 ~33~25~13 minecraft:stonebrick 0
fill ~33~27~13 ~33~29~13 minecraft:stonebrick 0
setblock ~33~32~13 minecraft:stonebrick 0
fill ~33~35~13 ~34~35~13 minecraft:stained_hardened_clay 9
setblock ~33~36~13 minecraft:stained_hardened_clay 9
fill ~34~2~13 ~34~2~44 minecraft:dirt 0
fill ~34~3~13 ~35~3~13 minecraft:dirt 0
fill ~34~4~13 ~35~23~13 minecraft:stonebrick 0
fill ~34~31~13 ~35~31~13 minecraft:stonebrick 0
fill ~34~32~13 ~34~34~13 minecraft:stained_hardened_clay 9
fill ~35~24~13 ~35~28~13 minecraft:stonebrick 0
fill ~36~4~13 ~36~5~13 minecraft:leaves 2
setblock ~36~6~13 minecraft:leaves 2
setblock ~36~8~13 minecraft:leaves 2
setblock ~36~21~13 minecraft:leaves 1
setblock ~36~23~13 minecraft:log 1
setblock ~36~24~13 minecraft:leaves 2
fill ~36~25~13 ~36~26~13 minecraft:log 1
fill ~36~29~13 ~36~29~14 minecraft:stonebrick 0
fill ~36~35~13 ~36~37~13 minecraft:stonebrick 0
setblock ~37~22~13 minecraft:leaves 1
fill ~38~2~13 ~42~2~16 minecraft:grass
fill ~38~3~13 ~39~3~13 minecraft:leaves 2
setblock ~39~4~13 minecraft:leaves 2
fill ~39~30~13 ~39~30~16 minecraft:stonebrick 0
setblock ~43~2~13 minecraft:dirt 0
setblock ~43~3~13 minecraft:log 1
fill ~44~2~13 ~95~2~13 minecraft:grass
fill ~63~3~13 ~63~6~13 minecraft:stained_glass_pane 12
fill ~63~7~13 ~63~7~14 minecraft:wood 1
fill ~63~8~13 ~63~11~13 minecraft:stained_glass_pane 12
fill ~63~12~13 ~63~12~20 minecraft:wood 1
fill ~63~13~13 ~63~16~13 minecraft:stained_glass_pane 12
fill ~63~17~13 ~63~17~20 minecraft:wood 1
fill ~63~18~13 ~63~21~13 minecraft:stained_glass_pane 12
fill ~63~22~13 ~63~22~21 minecraft:wood 1
fill ~63~23~13 ~63~27~13 minecraft:stained_glass_pane 12
fill ~63~28~13 ~63~28~21 minecraft:wood 1
fill ~63~29~13 ~63~29~14 minecraft:stained_glass_pane 12
setblock ~64~7~13 minecraft:fence 1
fill ~64~33~13 ~68~33~13 minecraft:cobblestone
fill ~64~34~13 ~68~34~13 minecraft:stone_stairs 2
setblock ~66~7~13 minecraft:fence 1
setblock ~68~7~13 minecraft:fence 1
fill ~69~3~13 ~69~6~13 minecraft:stained_glass_pane 12
fill ~69~7~13 ~69~7~14 minecraft:wood 1
fill ~69~8~13 ~69~11~13 minecraft:stained_glass_pane 12
fill ~69~12~13 ~69~12~20 minecraft:wood 1
fill ~69~13~13 ~69~16~13 minecraft:stained_glass_pane 12
fill ~69~17~13 ~69~17~20 minecraft:wood 1
fill ~69~18~13 ~69~21~13 minecraft:stained_glass_pane 12
fill ~69~22~13 ~69~22~21 minecraft:wood 1
fill ~69~23~13 ~69~27~13 minecraft:stained_glass_pane 12
fill ~69~28~13 ~69~28~21 minecraft:wood 1
fill ~69~29~13 ~69~29~14 minecraft:stained_glass_pane 12
fill ~93~30~13 ~93~30~16 minecraft:stonebrick 0
setblock ~94~3~13 minecraft:leaves 2
setblock ~95~4~13 minecraft:leaves 1
fill ~96~2~13 ~97~2~38 minecraft:dirt 0
setblock ~96~3~13 minecraft:log 1
setblock ~96~5~13 minecraft:leaves 1
setblock ~96~7~13 minecraft:leaves 2
fill ~96~29~13 ~96~29~14 minecraft:stonebrick 0
fill ~96~35~13 ~96~37~13 minecraft:stonebrick 0
fill ~97~3~13 ~98~3~13 minecraft:dirt 0
fill ~97~4~13 ~98~23~13 minecraft:stonebrick 0
fill ~97~24~13 ~97~28~13 minecraft:stonebrick 0
fill ~97~31~13 ~98~31~13 minecraft:stonebrick 0
fill ~98~32~13 ~98~35~13 minecraft:stained_hardened_clay 9
fill ~99~3~13 ~101~3~39 minecraft:grass
setblock ~99~5~13 minecraft:leaves 1
fill ~99~6~13 ~99~7~13 minecraft:leaves 2
setblock ~99~8~13 minecraft:leaves 2
fill ~99~11~13 ~99~11~41 minecraft:stained_hardened_clay 9
fill ~99~21~13 ~99~21~41 minecraft:stained_hardened_clay 9
setblock ~99~32~13 minecraft:stonebrick 0
fill ~99~35~13 ~99~36~13 minecraft:stained_hardened_clay 9
setblock ~100~26~13 minecraft:stonebrick 0
setblock ~100~30~13 minecraft:stonebrick 0
fill ~100~37~13 ~100~38~13 minecraft:stained_hardened_clay 9
fill ~101~24~13 ~101~25~13 minecraft:stonebrick 0
setblock ~101~32~13 minecraft:stonebrick 0
fill ~101~38~13 ~101~39~13 minecraft:stained_hardened_clay 9
fill ~101~40~13 ~102~40~13 minecraft:stonebrick 0
setblock ~102~26~13 minecraft:stonebrick 0
setblock ~102~39~13 minecraft:stained_hardened_clay 9
fill ~103~40~13 ~104~40~13 minecraft:stained_hardened_clay 9
fill ~104~41~13 ~107~41~13 minecraft:stained_hardened_clay 9
fill ~108~41~13 ~110~42~13 minecraft:stone 6
setblock ~109~43~13 minecraft:stonebrick 0
fill ~111~41~13 ~114~41~13 minecraft:stained_hardened_clay 9
fill ~114~40~13 ~115~40~13 minecraft:stained_hardened_clay 9
setblock ~116~26~13 minecraft:stonebrick 0
fill ~116~39~13 ~117~39~13 minecraft:stained_hardened_clay 9
fill ~117~24~13 ~117~25~13 minecraft:stonebrick 0
setblock ~117~27~13 minecraft:stonebrick 0
fill ~117~30~13 ~119~30~13 minecraft:stonebrick 0
fill ~117~38~13 ~118~38~13 minecraft:stained_hardened_clay 9
setblock ~118~7~13 minecraft:leaves 2
fill ~118~26~13 ~119~26~13 minecraft:stonebrick 0
setblock ~118~37~13 minecraft:stained_hardened_clay 9
fill ~119~3~13 ~119~3~40 minecraft:grass
setblock ~119~6~13 minecraft:log 1
fill ~119~11~13 ~119~11~41 minecraft:stained_hardened_clay 9
fill ~119~21~13 ~119~21~41 minecraft:stained_hardened_clay 9
fill ~119~24~13 ~119~25~13 minecraft:stonebrick 0
fill ~119~27~13 ~119~29~13 minecraft:stonebrick 0
setblock ~119~32~13 minecraft:stonebrick 0
fill ~119~35~13 ~120~35~13 minecraft:stained_hardened_clay 9
setblock ~119~36~13 minecraft:stained_hardened_clay 9
fill ~120~2~13 ~121~2~41 minecraft:dirt 0
fill ~120~3~13 ~121~3~13 minecraft:dirt 0
fill ~120~4~13 ~121~23~13 minecraft:stonebrick 0
fill ~120~31~13 ~121~31~13 minecraft:stonebrick 0
fill ~120~32~13 ~120~34~13 minecraft:stained_hardened_clay 9
fill ~121~24~13 ~121~28~13 minecraft:stonebrick 0
fill ~122~2~13 ~138~2~13 minecraft:grass
setblock ~122~6~13 minecraft:leaves 1
fill ~122~29~13 ~122~29~14 minecraft:stonebrick 0
fill ~122~35~13 ~122~37~13 minecraft:stonebrick 0
fill ~125~30~13 ~125~30~16 minecraft:stonebrick 0
fill ~1~2~14 ~9~2~14 minecraft:grass
setblock ~9~7~14 minecraft:leaves 2
fill ~9~29~14 ~9~29~17 minecraft:stonebrick 0
fill ~9~35~14 ~9~37~14 minecraft:stonebrick 0
fill ~10~2~14 ~10~2~40 minecraft:dirt 0
setblock ~10~3~14 minecraft:dirt 0
fill ~10~4~14 ~10~28~14 minecraft:stonebrick 0
setblock ~10~31~14 minecraft:stonebrick 0
fill ~10~32~14 ~11~32~14 minecraft:stained_hardened_clay 9
fill ~11~3~14 ~12~3~39 minecraft:grass
fill ~11~11~14 ~12~11~40 minecraft:stained_hardened_clay 9
fill ~11~21~14 ~12~21~40 minecraft:stained_hardened_clay 9
fill ~11~33~14 ~11~35~14 minecraft:stained_hardened_clay 9
setblock ~12~6~14 minecraft:log 1
fill ~12~36~14 ~12~37~14 minecraft:stained_hardened_clay 9
setblock ~13~30~14 minecraft:stonebrick 0
fill ~13~37~14 ~13~38~14 minecraft:stained_hardened_clay 9
setblock ~14~39~14 minecraft:stained_hardened_clay 9
setblock ~15~30~14 minecraft:stonebrick 0
fill ~15~40~14 ~16~40~14 minecraft:stained_hardened_clay 9
fill ~16~41~14 ~17~41~14 minecraft:stained_hardened_clay 9
fill ~18~42~14 ~21~42~14 minecraft:stained_hardened_clay 9
fill ~21~43~14 ~21~43~15 minecraft:stained_hardened_clay 9
fill ~22~43~14 ~24~43~14 minecraft:stone 6
setblock ~23~44~14 minecraft:stonebrick 0
fill ~25~42~14 ~28~42~14 minecraft:stained_hardened_clay 9
fill ~25~43~14 ~25~43~15 minecraft:stained_hardened_clay 9
fill ~29~41~14 ~30~41~14 minecraft:stained_hardened_clay 9
fill ~30~40~14 ~31~40~14 minecraft:stained_hardened_clay 9
setblock ~31~30~14 minecraft:stonebrick 0
setblock ~32~39~14 minecraft:stained_hardened_clay 9
fill ~32~40~14 ~33~40~14 minecraft:stonebrick 0
setblock ~33~8~14 minecraft:leaves 1
setblock ~33~20~14 minecraft:leaves 1
setblock ~33~30~14 minecraft:stonebrick 0
fill ~33~37~14 ~34~37~14 minecraft:stained_hardened_clay 9
setblock ~33~38~14 minecraft:stained_hardened_clay 9
fill ~34~3~14 ~35~3~40 minecraft:grass
setblock ~34~5~14 minecraft:leaves 1
setblock ~34~7~14 minecraft:leaves 2
fill ~34~8~14 ~35~8~14 minecraft:log 1
setblock ~34~9~14 minecraft:leaves 2
fill ~34~11~14 ~35~11~37 minecraft:stained_hardened_clay 9
fill ~34~21~14 ~35~21~37 minecraft:stained_hardened_clay 9
fill ~34~22~14 ~35~22~14 minecraft:leaves 1
setblock ~34~25~14 minecraft:leaves 2
setblock ~34~36~14 minecraft:stained_hardened_clay 9
setblock ~35~23~14 minecraft:leaves 1
setblock ~35~24~14 minecraft:log 1
setblock ~35~25~14 minecraft:leaves 1
setblock ~35~26~14 minecraft:log 1
fill ~35~32~14 ~36~32~14 minecraft:stained_hardened_clay 9
fill ~35~33~14 ~35~35~14 minecraft:stained_hardened_clay 9
fill ~36~2~14 ~36~2~34 minecraft:dirt 0
setblock ~36~3~14 minecraft:dirt 0
fill ~36~4~14 ~36~28~14 minecraft:stonebrick 0
setblock ~36~31~14 minecraft:stonebrick 0
setblock ~37~2~14 minecraft:grass
setblock ~37~3~14 minecraft:leaves 2
setblock ~37~4~14 minecraft:leaves 2
setblock ~37~23~14 minecraft:leaves 1
fill ~37~29~14 ~37~29~17 minecraft:stonebrick 0
fill ~37~35~14 ~37~37~14 minecraft:stonebrick 0
setblock ~38~3~14 minecraft:leaves 2
fill ~43~2~14 ~62~2~14 minecraft:grass
setblock ~62~3~14 minecraft:stone_brick_stairs 1
fill ~62~4~14 ~62~5~15 minecraft:stained_glass_pane 12
setblock ~62~6~14 minecraft:stone_brick_stairs 5
setblock ~62~7~14 minecraft:wood 1
fill ~62~8~14 ~62~11~14 minecraft:stained_glass_pane 12
setblock ~62~12~14 minecraft:wood 1
fill ~62~13~14 ~62~16~14 minecraft:stained_glass_pane 12
setblock ~62~17~14 minecraft:wood 1
fill ~62~18~14 ~62~21~14 minecraft:stained_glass_pane 12
setblock ~62~22~14 minecraft:wood 1
fill ~62~23~14 ~62~27~14 minecraft:stained_glass_pane 12
setblock ~62~28~14 minecraft:wood 1
setblock ~62~29~14 minecraft:stained_glass_pane 12
fill ~63~2~14 ~64~2~20 minecraft:dirt 0
fill ~63~3~14 ~63~6~14 minecraft:wood 1
fill ~63~8~14 ~63~11~14 minecraft:wood 1
fill ~63~13~14 ~63~16~14 minecraft:wood 1
fill ~63~18~14 ~63~21~14 minecraft:wood 1
fill ~63~23~14 ~63~27~14 minecraft:wood 1
fill ~63~30~14 ~63~32~14 minecraft:stained_glass_pane 12
setblock ~63~33~14 minecraft:cobblestone
setblock ~63~34~14 minecraft:stone_block_slab 3
setblock ~64~3~14 minecraft:stone_brick_stairs 0
fill ~64~4~14 ~64~5~14 minecraft:stained_glass_pane 12
setblock ~64~6~14 minecraft:stone_brick_stairs 4
fill ~64~7~14 ~68~7~14 minecraft:wood 1
fill ~64~16~14 ~64~16~39 minecraft:log 1
fill ~64~17~14 ~68~17~14 minecraft:wood 1
setblock ~64~21~14 minecraft:spruce_stairs 5
fill ~64~22~14 ~68~22~14 minecraft:wood 1
fill ~64~28~14 ~68~28~14 minecraft:wood 1
fill ~64~29~14 ~64~33~14 minecraft:wood 1
setblock ~64~34~14 minecraft:cobblestone
setblock ~64~35~14 minecraft:spruce_stairs 2
fill ~65~2~14 ~67~2~14 minecraft:grass
setblock ~65~3~14 minecraft:stone_brick_stairs 5
setblock ~65~4~14 minecraft:stone_brick_stairs 0
setblock ~65~5~14 minecraft:stone_brick_stairs 4
setblock ~65~6~14 minecraft:stone_brick_stairs 1
setblock ~65~21~14 minecraft:wooden_slab 9
fill ~65~29~14 ~67~29~14 minecraft:fence 1
setblock ~65~32~14 minecraft:stone_brick_stairs 5
fill ~65~33~14 ~68~33~14 minecraft:wood 1
fill ~65~35~14 ~65~35~15 minecraft:planks 1
setblock ~65~36~14 minecraft:spruce_stairs 2
setblock ~66~3~14 minecraft:stained_glass_pane 12
setblock ~66~4~14 minecraft:stone_block_slab 13
setblock ~66~5~14 minecraft:stone_block_slab 5
setblock ~66~6~14 minecraft:stained_glass_pane 12
setblock ~66~21~14 minecraft:double_wooden_slab 1
setblock ~66~35~14 minecraft:cobblestone
setblock ~66~36~14 minecraft:stone_stairs 2
setblock ~67~3~14 minecraft:stone_brick_stairs 4
setblock ~67~4~14 minecraft:stone_brick_stairs 1
setblock ~67~5~14 minecraft:stone_brick_stairs 5
setblock ~67~6~14 minecraft:stone_brick_stairs 0
setblock ~67~21~14 minecraft:wooden_slab 9
setblock ~67~32~14 minecraft:stone_brick_stairs 4
fill ~67~35~14 ~67~35~15 minecraft:planks 1
setblock ~67~36~14 minecraft:spruce_stairs 2
fill ~68~2~14 ~70~2~15 minecraft:dirt 0
setblock ~68~3~14 minecraft:stone_brick_stairs 1
fill ~68~4~14 ~68~5~14 minecraft:stained_glass_pane 12
setblock ~68~6~14 minecraft:stone_brick_stairs 5
fill ~68~16~14 ~68~16~39 minecraft:log 1
setblock ~68~21~14 minecraft:spruce_stairs 4
fill ~68~29~14 ~68~32~14 minecraft:wood 1
setblock ~68~34~14 minecraft:cobblestone
setblock ~68~35~14 minecraft:spruce_stairs 2
fill ~69~3~14 ~69~6~14 minecraft:wood 1
fill ~69~8~14 ~69~11~14 minecraft:wood 1
fill ~69~13~14 ~69~16~14 minecraft:wood 1
fill ~69~18~14 ~69~21~14 minecraft:wood 1
fill ~69~23~14 ~69~27~14 minecraft:wood 1
fill ~69~30~14 ~69~32~14 minecraft:stained_glass_pane 12
setblock ~69~33~14 minecraft:cobblestone
setblock ~69~34~14 minecraft:stone_block_slab 3
setblock ~70~3~14 minecraft:stone_brick_stairs 0
fill ~70~4~14 ~70~5~15 minecraft:stained_glass_pane 12
setblock ~70~6~14 minecraft:stone_brick_stairs 4
setblock ~70~7~14 minecraft:wood 1
fill ~70~8~14 ~70~11~14 minecraft:stained_glass_pane 12
setblock ~70~12~14 minecraft:wood 1
fill ~70~13~14 ~70~16~14 minecraft:stained_glass_pane 12
setblock ~70~17~14 minecraft:wood 1
fill ~70~18~14 ~70~21~14 minecraft:stained_glass_pane 12
setblock ~70~22~14 minecraft:wood 1
fill ~70~23~14 ~70~27~14 minecraft:stained_glass_pane 12
setblock ~70~28~14 minecraft:wood 1
setblock ~70~29~14 minecraft:stained_glass_pane 12
fill ~71~2~14 ~93~2~15 minecraft:grass
setblock ~93~3~14 minecraft:leaves 2
setblock ~94~2~14 minecraft:dirt 0
setblock ~94~3~14 minecraft:log 1
fill ~94~5~14 ~94~5~16 minecraft:leaves 2
setblock ~95~2~14 minecraft:grass
fill ~95~4~14 ~95~5~14 minecraft:log 1
setblock ~95~6~14 minecraft:leaves 1
fill ~95~29~14 ~95~29~17 minecraft:stonebrick 0
fill ~95~35~14 ~95~37~14 minecraft:stonebrick 0
fill ~96~3~14 ~96~3~15 minecraft:dirt 0
fill ~96~4~14 ~96~28~14 minecraft:stonebrick 0
setblock ~96~31~14 minecraft:stonebrick 0
fill ~96~32~14 ~97~32~14 minecraft:stained_hardened_clay 9
fill ~97~3~14 ~98~3~40 minecraft:grass
fill ~97~4~14 ~97~4~15 minecraft:leaves 2
fill ~97~5~14 ~97~6~14 minecraft:log 1
fill ~97~11~14 ~98~11~37 minecraft:stained_hardened_clay 9
fill ~97~21~14 ~98~21~37 minecraft:stained_hardened_clay 9
fill ~97~33~14 ~97~35~14 minecraft:stained_hardened_clay 9
setblock ~98~5~14 minecraft:leaves 2
setblock ~98~7~14 minecraft:leaves 2
fill ~98~36~14 ~98~37~14 minecraft:stained_hardened_clay 9
setblock ~99~6~14 minecraft:leaves 1
setblock ~99~8~14 minecraft:log 1
setblock ~99~30~14 minecraft:stonebrick 0
fill ~99~37~14 ~99~38~14 minecraft:stained_hardened_clay 9
setblock ~100~39~14 minecraft:stained_hardened_clay 9
setblock ~100~40~14 minecraft:stonebrick 0
setblock ~101~30~14 minecraft:stonebrick 0
fill ~101~40~14 ~102~40~14 minecraft:stained_hardened_clay 9
fill ~102~41~14 ~103~41~14 minecraft:stained_hardened_clay 9
fill ~104~42~14 ~107~42~14 minecraft:stained_hardened_clay 9
fill ~107~43~14 ~107~43~15 minecraft:stained_hardened_clay 9
fill ~108~43~14 ~110~43~14 minecraft:stone 6
setblock ~109~44~14 minecraft:stonebrick 0
fill ~111~42~14 ~114~42~14 minecraft:stained_hardened_clay 9
fill ~111~43~14 ~111~43~15 minecraft:stained_hardened_clay 9
fill ~115~41~14 ~116~41~14 minecraft:stained_hardened_clay 9
fill ~116~40~14 ~117~40~14 minecraft:stained_hardened_clay 9
setblock ~117~30~14 minecraft:stonebrick 0
setblock ~118~39~14 minecraft:stained_hardened_clay 9
setblock ~119~30~14 minecraft:stonebrick 0
fill ~119~37~14 ~120~37~14 minecraft:stained_hardened_clay 9
setblock ~119~38~14 minecraft:stained_hardened_clay 9
fill ~120~3~14 ~121~3~40 minecraft:grass
fill ~120~11~14 ~121~11~40 minecraft:stained_hardened_clay 9
fill ~120~21~14 ~121~21~40 minecraft:stained_hardened_clay 9
setblock ~120~36~14 minecraft:stained_hardened_clay 9
setblock ~121~5~14 minecraft:leaves 2
setblock ~121~7~14 minecraft:leaves 2
fill ~121~32~14 ~122~32~14 minecraft:stained_hardened_clay 9
fill ~121~33~14 ~121~35~14 minecraft:stained_hardened_clay 9
fill ~122~2~14 ~122~2~40 minecraft:dirt 0
setblock ~122~3~14 minecraft:dirt 0
fill ~122~4~14 ~122~28~14 minecraft:stonebrick 0
setblock ~122~31~14 minecraft:stonebrick 0
fill ~123~2~14 ~138~2~14 minecraft:grass
setblock ~123~7~14 minecraft:leaves 1
fill ~123~29~14 ~123~29~17 minecraft:stonebrick 0
fill ~123~35~14 ~123~37~14 minecraft:stonebrick 0
fill ~1~2~15 ~8~2~16 minecraft:grass
fill ~6~30~15 ~6~30~22 minecraft:stonebrick 0
fill ~8~6~15 ~8~6~16 minecraft:leaves 1
setblock ~8~7~15 minecraft:leaves 2
fill ~8~29~15 ~8~29~17 minecraft:stonebrick 0
fill ~8~34~15 ~8~37~15 minecraft:stonebrick 0
fill ~9~2~15 ~9~2~40 minecraft:dirt 0
fill ~9~3~15 ~9~3~16 minecraft:dirt 0
fill ~9~4~15 ~9~28~16 minecraft:stonebrick 0
fill ~9~30~15 ~9~30~19 minecraft:stonebrick 0
fill ~9~31~15 ~9~31~16 minecraft:stonebrick 0
fill ~10~3~15 ~10~3~39 minecraft:grass
fill ~10~11~15 ~10~11~39 minecraft:stained_hardened_clay 9
fill ~10~21~15 ~10~21~39 minecraft:stained_hardened_clay 9
fill ~10~32~15 ~10~35~15 minecraft:stained_hardened_clay 9
fill ~11~36~15 ~11~37~15 minecraft:stained_hardened_clay 9
setblock ~12~38~15 minecraft:stained_hardened_clay 9
setblock ~13~39~15 minecraft:stained_hardened_clay 9
setblock ~14~40~15 minecraft:stained_hardened_clay 9
setblock ~15~41~15 minecraft:stained_hardened_clay 9
fill ~16~42~15 ~17~42~15 minecraft:stained_hardened_clay 9
fill ~18~43~15 ~20~43~15 minecraft:stained_hardened_clay 9
fill ~22~44~15 ~24~44~16 minecraft:stone 6
fill ~23~45~15 ~23~45~16 minecraft:stonebrick 0
fill ~26~43~15 ~28~43~15 minecraft:stained_hardened_clay 9
fill ~29~42~15 ~30~42~15 minecraft:stained_hardened_clay 9
setblock ~31~41~15 minecraft:stained_hardened_clay 9
setblock ~32~40~15 minecraft:stained_hardened_clay 9
setblock ~33~39~15 minecraft:stained_hardened_clay 9
fill ~33~40~15 ~34~40~15 minecraft:stonebrick 0
setblock ~34~38~15 minecraft:stained_hardened_clay 9
fill ~35~36~15 ~35~37~15 minecraft:stained_hardened_clay 9
fill ~36~3~15 ~36~3~35 minecraft:grass
fill ~36~11~15 ~36~11~38 minecraft:stained_hardened_clay 9
fill ~36~21~15 ~36~21~37 minecraft:stained_hardened_clay 9
fill ~36~32~15 ~36~35~15 minecraft:stained_hardened_clay 9
fill ~37~2~15 ~37~2~36 minecraft:dirt 0
fill ~37~3~15 ~37~3~17 minecraft:dirt 0
fill ~37~4~15 ~37~28~16 minecraft:stonebrick 0
fill ~37~30~15 ~37~30~19 minecraft:stonebrick 0
fill ~37~31~15 ~37~31~16 minecraft:stonebrick 0
setblock ~38~3~15 minecraft:leaves 2
fill ~38~29~15 ~38~29~17 minecraft:stonebrick 0
fill ~38~35~15 ~38~37~15 minecraft:stonebrick 0
fill ~40~30~15 ~40~30~22 minecraft:stonebrick 0
fill ~43~2~15 ~61~2~17 minecraft:grass
fill ~62~2~15 ~62~2~17 minecraft:dirt 0
fill ~62~3~15 ~62~3~16 minecraft:cobblestone
setblock ~62~6~15 minecraft:cobblestone
setblock ~62~7~15 minecraft:double_wooden_slab 1
setblock ~62~12~15 minecraft:fence 1
setblock ~62~17~15 minecraft:fence 1
fill ~62~33~15 ~62~33~19 minecraft:cobblestone
fill ~62~34~15 ~62~34~19 minecraft:stone_stairs 0
setblock ~63~3~15 minecraft:stone_brick_stairs 0
fill ~63~4~15 ~63~5~15 minecraft:cobblestone
setblock ~63~6~15 minecraft:stone_brick_stairs 4
fill ~63~7~15 ~63~7~19 minecraft:wooden_slab 9
setblock ~63~8~15 minecraft:stone_brick_stairs 0
setblock ~63~11~15 minecraft:stone_brick_stairs 7
setblock ~63~16~15 minecraft:stone_brick_stairs 7
setblock ~63~21~15 minecraft:spruce_stairs 7
setblock ~63~23~15 minecraft:spruce_stairs 2
setblock ~63~25~15 minecraft:stained_glass_pane 12
setblock ~63~27~15 minecraft:spruce_stairs 6
fill ~63~29~15 ~63~33~15 minecraft:wood 1
setblock ~63~34~15 minecraft:cobblestone
setblock ~63~35~15 minecraft:spruce_stairs 0
fill ~64~3~15 ~68~6~15 minecraft:stonebrick 0
fill ~64~7~15 ~68~7~39 minecraft:planks 1
fill ~64~17~15 ~68~17~19 minecraft:wooden_slab 9
fill ~64~18~15 ~68~18~15 minecraft:wool 0
fill ~64~19~15 ~64~21~15 minecraft:wool 0
fill ~64~23~15 ~68~23~15 minecraft:wool 0
fill ~64~24~15 ~64~27~19 minecraft:wool 0
fill ~64~28~15 ~68~28~19 minecraft:planks 1
fill ~64~35~15 ~64~35~16 minecraft:planks 1
setblock ~64~36~15 minecraft:double_wooden_slab 1
fill ~65~2~15 ~67~2~16 minecraft:dirt 0
fill ~65~19~15 ~65~20~15 minecraft:stained_glass_pane 11
fill ~65~21~15 ~68~21~15 minecraft:wool 0
fill ~65~24~15 ~67~26~15 minecraft:quartz_block 1
fill ~65~27~15 ~68~27~15 minecraft:wool 0
fill ~65~36~15 ~65~37~15 minecraft:planks 1
setblock ~65~38~15 minecraft:spruce_stairs 2
fill ~66~19~15 ~66~20~15 minecraft:stained_glass 11
setblock ~66~37~15 minecraft:cobblestone
setblock ~66~38~15 minecraft:stone_stairs 2
fill ~67~19~15 ~67~20~15 minecraft:stained_glass_pane 11
fill ~67~36~15 ~67~37~15 minecraft:planks 1
setblock ~67~38~15 minecraft:spruce_stairs 2
fill ~68~19~15 ~68~20~15 minecraft:wool 0
fill ~68~24~15 ~68~26~19 minecraft:wool 0
fill ~68~35~15 ~68~35~16 minecraft:planks 1
setblock ~68~36~15 minecraft:double_wooden_slab 1
setblock ~69~3~15 minecraft:stone_brick_stairs 1
fill ~69~4~15 ~69~5~15 minecraft:cobblestone
setblock ~69~6~15 minecraft:stone_brick_stairs 5
fill ~69~7~15 ~69~7~19 minecraft:wooden_slab 9
setblock ~69~8~15 minecraft:stone_brick_stairs 1
setblock ~69~11~15 minecraft:stone_brick_stairs 7
setblock ~69~16~15 minecraft:stone_brick_stairs 7
setblock ~69~21~15 minecraft:spruce_stairs 7
setblock ~69~23~15 minecraft:spruce_stairs 2
setblock ~69~25~15 minecraft:stained_glass_pane 12
setblock ~69~27~15 minecraft:spruce_stairs 6
fill ~69~29~15 ~69~33~15 minecraft:wood 1
setblock ~69~34~15 minecraft:cobblestone
setblock ~69~35~15 minecraft:spruce_stairs 1
fill ~70~3~15 ~70~3~16 minecraft:cobblestone
setblock ~70~6~15 minecraft:cobblestone
setblock ~70~7~15 minecraft:double_wooden_slab 1
setblock ~70~12~15 minecraft:fence 1
setblock ~70~17~15 minecraft:fence 1
fill ~70~33~15 ~70~33~19 minecraft:cobblestone
fill ~70~34~15 ~70~34~19 minecraft:stone_stairs 1
fill ~92~30~15 ~92~30~22 minecraft:stonebrick 0
fill ~94~2~15 ~94~2~16 minecraft:grass
setblock ~94~4~15 minecraft:leaves 2
setblock ~94~6~15 minecraft:leaves 2
fill ~94~29~15 ~94~29~17 minecraft:stonebrick 0
fill ~94~34~15 ~94~37~15 minecraft:stonebrick 0
fill ~95~2~15 ~95~2~48 minecraft:dirt 0
fill ~95~3~15 ~95~3~17 minecraft:dirt 0
fill ~95~4~15 ~95~28~16 minecraft:stonebrick 0
fill ~95~30~15 ~95~30~19 minecraft:stonebrick 0
fill ~95~31~15 ~95~31~16 minecraft:stonebrick 0
setblock ~96~4~15 minecraft:log 1
fill ~96~5~15 ~96~5~16 minecraft:leaves 2
setblock ~96~6~15 minecraft:leaves 1
fill ~96~11~15 ~96~11~38 minecraft:stained_hardened_clay 9
fill ~96~21~15 ~96~21~37 minecraft:stained_hardened_clay 9
fill ~96~32~15 ~96~35~15 minecraft:stained_hardened_clay 9
fill ~97~36~15 ~97~37~15 minecraft:stained_hardened_clay 9
setblock ~98~38~15 minecraft:stained_hardened_clay 9
fill ~98~40~15 ~99~40~15 minecraft:stonebrick 0
setblock ~99~39~15 minecraft:stained_hardened_clay 9
setblock ~100~40~15 minecraft:stained_hardened_clay 9
setblock ~101~41~15 minecraft:stained_hardened_clay 9
fill ~102~42~15 ~103~42~15 minecraft:stained_hardened_clay 9
fill ~104~43~15 ~106~43~15 minecraft:stained_hardened_clay 9
fill ~108~44~15 ~110~44~16 minecraft:stone 6
fill ~109~45~15 ~109~45~16 minecraft:stonebrick 0
fill ~112~43~15 ~114~43~15 minecraft:stained_hardened_clay 9
fill ~115~42~15 ~116~42~15 minecraft:stained_hardened_clay 9
setblock ~117~41~15 minecraft:stained_hardened_clay 9
setblock ~118~40~15 minecraft:stained_hardened_clay 9
setblock ~119~39~15 minecraft:stained_hardened_clay 9
setblock ~120~38~15 minecraft:stained_hardened_clay 9
fill ~121~36~15 ~121~37~15 minecraft:stained_hardened_clay 9
fill ~122~3~15 ~122~3~39 minecraft:grass
setblock ~122~7~15 minecraft:leaves 1
fill ~122~11~15 ~122~11~39 minecraft:stained_hardened_clay 9
fill ~122~21~15 ~122~21~39 minecraft:stained_hardened_clay 9
fill ~122~32~15 ~122~35~15 minecraft:stained_hardened_clay 9
fill ~123~2~15 ~124~2~15 minecraft:dirt 0
fill ~123~3~15 ~123~3~16 minecraft:dirt 0
fill ~123~4~15 ~123~28~16 minecraft:stonebrick 0
fill ~123~30~15 ~123~30~19 minecraft:stonebrick 0
fill ~123~31~15 ~123~31~16 minecraft:stonebrick 0
setblock ~124~3~15 minecraft:log 1
setblock ~124~5~15 minecraft:log 1
setblock ~124~6~15 minecraft:leaves 2
fill ~124~29~15 ~124~29~17 minecraft:stonebrick 0
fill ~124~35~15 ~124~37~15 minecraft:stonebrick 0
fill ~125~2~15 ~138~2~15 minecraft:grass
fill ~126~30~15 ~126~30~22 minecraft:stonebrick 0
fill ~5~5~16 ~7~5~16 minecraft:leaves 2
fill ~6~6~16 ~6~6~17 minecraft:leaves 1
fill ~6~24~16 ~6~29~16 minecraft:stonebrick 0
setblock ~7~7~16 minecraft:leaves 2
fill ~7~25~16 ~8~25~16 minecraft:stonebrick 0
fill ~7~27~16 ~8~28~16 minecraft:stonebrick 0
setblock ~7~29~16 minecraft:stonebrick 0
setblock ~8~7~16 minecraft:leaves 2
setblock ~8~8~16 minecraft:log 1
fill ~8~24~16 ~8~24~17 minecraft:stonebrick 0
fill ~8~26~16 ~8~26~17 minecraft:stonebrick 0
fill ~9~32~16 ~9~35~16 minecraft:stained_hardened_clay 9
fill ~10~36~16 ~10~37~16 minecraft:stained_hardened_clay 9
setblock ~11~38~16 minecraft:stained_hardened_clay 9
fill ~12~39~16 ~12~40~16 minecraft:stained_hardened_clay 9
fill ~13~40~16 ~13~41~16 minecraft:stained_hardened_clay 9
setblock ~14~41~16 minecraft:stained_hardened_clay 9
setblock ~15~42~16 minecraft:stained_hardened_clay 9
fill ~16~43~16 ~17~43~16 minecraft:stained_hardened_clay 9
fill ~18~44~16 ~21~44~16 minecraft:stained_hardened_clay 9
fill ~25~44~16 ~28~44~16 minecraft:stained_hardened_clay 9
fill ~29~43~16 ~30~43~16 minecraft:stained_hardened_clay 9
setblock ~31~42~16 minecraft:stained_hardened_clay 9
fill ~32~41~16 ~33~41~16 minecraft:stained_hardened_clay 9
fill ~33~40~16 ~34~40~16 minecraft:stained_hardened_clay 9
setblock ~34~39~16 minecraft:stained_hardened_clay 9
setblock ~35~38~16 minecraft:stained_hardened_clay 9
fill ~35~40~16 ~35~40~17 minecraft:stonebrick 0
fill ~36~36~16 ~36~37~16 minecraft:stained_hardened_clay 9
fill ~37~32~16 ~37~35~16 minecraft:stained_hardened_clay 9
fill ~38~24~16 ~38~28~17 minecraft:stonebrick 0
fill ~39~3~16 ~40~3~16 minecraft:leaves 2
fill ~39~25~16 ~40~25~16 minecraft:stonebrick 0
fill ~39~28~16 ~40~29~16 minecraft:stonebrick 0
setblock ~40~24~16 minecraft:stonebrick 0
fill ~40~26~16 ~40~27~16 minecraft:stonebrick 0
setblock ~55~22~16 minecraft:stone_brick_stairs 6
fill ~62~4~16 ~62~5~16 minecraft:cobblestone
fill ~62~7~16 ~62~7~19 minecraft:wooden_slab 9
fill ~63~3~16 ~63~3~18 minecraft:stone_block_slab 5
fill ~63~6~16 ~63~6~18 minecraft:stone_block_slab 13
setblock ~63~8~16 minecraft:stone_block_slab 5
setblock ~63~11~16 minecraft:stone_block_slab 13
setblock ~63~16~16 minecraft:stone_block_slab 13
setblock ~63~21~16 minecraft:wooden_slab 9
setblock ~63~23~16 minecraft:spruce_stairs 7
setblock ~63~24~16 minecraft:spruce_stairs 2
setblock ~63~26~16 minecraft:spruce_stairs 6
setblock ~63~27~16 minecraft:spruce_stairs 3
fill ~63~29~16 ~63~29~18 minecraft:fence 1
setblock ~63~32~16 minecraft:stone_brick_stairs 7
fill ~63~33~16 ~63~33~19 minecraft:wood 1
setblock ~63~35~16 minecraft:planks 1
setblock ~63~36~16 minecraft:spruce_stairs 0
fill ~64~3~16 ~64~6~19 minecraft:stonebrick 0
fill ~64~18~16 ~64~18~19 minecraft:wool 0
fill ~64~19~16 ~64~20~16 minecraft:stained_glass_pane 11
fill ~64~21~16 ~64~21~19 minecraft:wool 0
fill ~64~23~16 ~64~23~19 minecraft:wool 0
fill ~64~36~16 ~64~37~16 minecraft:planks 1
setblock ~64~38~16 minecraft:spruce_stairs 0
fill ~65~31~16 ~67~31~18 minecraft:gold_block
setblock ~65~39~16 minecraft:wooden_slab 1
fill ~66~30~16 ~66~30~18 minecraft:gold_block
fill ~66~32~16 ~66~33~18 minecraft:gold_block
setblock ~66~39~16 minecraft:double_stone_block_slab 3
setblock ~67~39~16 minecraft:wooden_slab 1
fill ~68~2~16 ~68~2~20 minecraft:dirt 0
fill ~68~3~16 ~68~6~19 minecraft:stonebrick 0
fill ~68~18~16 ~68~18~19 minecraft:wool 0
fill ~68~19~16 ~68~20~16 minecraft:stained_glass_pane 11
fill ~68~21~16 ~68~21~19 minecraft:wool 0
fill ~68~23~16 ~68~23~19 minecraft:wool 0
fill ~68~27~16 ~68~27~19 minecraft:wool 0
fill ~68~36~16 ~68~37~16 minecraft:planks 1
setblock ~68~38~16 minecraft:spruce_stairs 1
setblock ~69~2~16 minecraft:grass
fill ~69~3~16 ~69~3~18 minecraft:stone_block_slab 5
fill ~69~6~16 ~69~6~18 minecraft:stone_block_slab 13
setblock ~69~8~16 minecraft:stone_block_slab 5
setblock ~69~11~16 minecraft:stone_block_slab 13
setblock ~69~16~16 minecraft:stone_block_slab 13
setblock ~69~21~16 minecraft:wooden_slab 9
setblock ~69~23~16 minecraft:spruce_stairs 7
setblock ~69~24~16 minecraft:spruce_stairs 2
setblock ~69~26~16 minecraft:spruce_stairs 6
setblock ~69~27~16 minecraft:spruce_stairs 3
fill ~69~29~16 ~69~29~18 minecraft:fence 1
setblock ~69~32~16 minecraft:stone_brick_stairs 7
fill ~69~33~16 ~69~33~19 minecraft:wood 1
setblock ~69~35~16 minecraft:planks 1
setblock ~69~36~16 minecraft:spruce_stairs 1
setblock ~70~2~16 minecraft:dirt 0
fill ~70~4~16 ~70~5~16 minecraft:cobblestone
fill ~70~7~16 ~70~7~19 minecraft:wooden_slab 9
fill ~71~2~16 ~91~2~17 minecraft:grass
setblock ~77~22~16 minecraft:stone_brick_stairs 6
fill ~91~4~16 ~92~4~16 minecraft:leaves 2
setblock ~92~2~16 minecraft:dirt 0
setblock ~92~3~16 minecraft:log 1
fill ~92~5~16 ~92~5~17 minecraft:leaves 2
fill ~92~24~16 ~92~29~16 minecraft:stonebrick 0
setblock ~93~2~16 minecraft:grass
fill ~93~25~16 ~94~25~16 minecraft:stonebrick 0
fill ~93~27~16 ~94~28~16 minecraft:stonebrick 0
setblock ~93~29~16 minecraft:stonebrick 0
setblock ~94~3~16 minecraft:leaves 2
setblock ~94~4~16 minecraft:log 1
fill ~94~24~16 ~94~24~17 minecraft:stonebrick 0
fill ~94~26~16 ~94~26~17 minecraft:stonebrick 0
fill ~95~32~16 ~95~35~16 minecraft:stained_hardened_clay 9
fill ~96~3~16 ~96~3~35 minecraft:grass
fill ~96~36~16 ~96~37~16 minecraft:stained_hardened_clay 9
setblock ~97~38~16 minecraft:stained_hardened_clay 9
fill ~97~40~16 ~97~40~17 minecraft:stonebrick 0
fill ~98~39~16 ~98~40~16 minecraft:stained_hardened_clay 9
fill ~99~40~16 ~99~41~16 minecraft:stained_hardened_clay 9
setblock ~100~41~16 minecraft:stained_hardened_clay 9
setblock ~101~42~16 minecraft:stained_hardened_clay 9
fill ~102~43~16 ~103~43~16 minecraft:stained_hardened_clay 9
fill ~104~44~16 ~107~44~16 minecraft:stained_hardened_clay 9
fill ~111~44~16 ~114~44~16 minecraft:stained_hardened_clay 9
fill ~115~43~16 ~116~43~16 minecraft:stained_hardened_clay 9
setblock ~117~42~16 minecraft:stained_hardened_clay 9
fill ~118~41~16 ~119~41~16 minecraft:stained_hardened_clay 9
fill ~119~40~16 ~120~40~16 minecraft:stained_hardened_clay 9
setblock ~120~39~16 minecraft:stained_hardened_clay 9
setblock ~121~38~16 minecraft:stained_hardened_clay 9
setblock ~122~6~16 minecraft:leaves 1
fill ~122~36~16 ~122~37~16 minecraft:stained_hardened_clay 9
fill ~123~2~16 ~123~2~39 minecraft:dirt 0
fill ~123~32~16 ~123~35~16 minecraft:stained_hardened_clay 9
setblock ~124~2~16 minecraft:grass
setblock ~124~3~16 minecraft:leaves 2
fill ~124~24~16 ~124~28~17 minecraft:stonebrick 0
fill ~125~2~16 ~125~2~36 minecraft:dirt 0
setblock ~125~3~16 minecraft:log 1
fill ~125~4~16 ~125~4~17 minecraft:leaves 2
fill ~125~25~16 ~126~25~16 minecraft:stonebrick 0
fill ~125~28~16 ~126~29~16 minecraft:stonebrick 0
fill ~126~2~16 ~138~2~16 minecraft:grass
setblock ~126~3~16 minecraft:leaves 2
setblock ~126~24~16 minecraft:stonebrick 0
fill ~126~26~16 ~126~27~16 minecraft:stonebrick 0
setblock ~127~3~16 minecraft:leaves 1
fill ~1~2~17 ~7~2~17 minecraft:grass
fill ~5~4~17 ~5~6~17 minecraft:leaves 2
fill ~5~30~17 ~5~30~19 minecraft:stonebrick 0
fill ~6~4~17 ~6~5~17 minecraft:leaves 1
fill ~6~9~17 ~7~9~17 minecraft:leaves 2
fill ~6~28~17 ~6~29~22 minecraft:stonebrick 0
setblock ~7~4~17 minecraft:log 1
fill ~7~5~17 ~7~6~17 minecraft:leaves 2
setblock ~7~7~17 minecraft:leaves 1
setblock ~7~8~17 minecraft:log 1
setblock ~7~10~17 minecraft:leaves 2
setblock ~7~28~17 minecraft:log 1
fill ~8~2~17 ~8~2~38 minecraft:dirt 0
setblock ~8~3~17 minecraft:dirt 0
fill ~8~4~17 ~8~23~17 minecraft:stonebrick 0
fill ~8~25~17 ~9~25~17 minecraft:stonebrick 0
fill ~8~27~17 ~9~28~17 minecraft:stonebrick 0
setblock ~8~31~17 minecraft:stonebrick 0
fill ~8~32~17 ~8~34~17 minecraft:stained_hardened_clay 9
fill ~9~3~17 ~9~3~37 minecraft:grass
setblock ~9~8~17 minecraft:leaves 2
fill ~9~11~17 ~9~11~37 minecraft:stained_hardened_clay 9
fill ~9~21~17 ~9~21~37 minecraft:stained_hardened_clay 9
setblock ~9~24~17 minecraft:stonebrick 0
fill ~9~26~17 ~9~26~20 minecraft:stonebrick 0
setblock ~9~32~17 minecraft:stonebrick 0
fill ~9~35~17 ~9~36~17 minecraft:stained_hardened_clay 9
setblock ~10~30~17 minecraft:stonebrick 0
fill ~10~37~17 ~10~38~17 minecraft:stained_hardened_clay 9
setblock ~11~39~17 minecraft:stained_hardened_clay 9
fill ~12~40~17 ~12~41~17 minecraft:stained_hardened_clay 9
setblock ~13~41~17 minecraft:stained_hardened_clay 9
setblock ~14~42~17 minecraft:stained_hardened_clay 9
fill ~15~43~17 ~16~43~17 minecraft:stained_hardened_clay 9
fill ~17~44~17 ~18~44~17 minecraft:stained_hardened_clay 9
fill ~19~45~17 ~21~45~17 minecraft:stained_hardened_clay 9
fill ~22~45~17 ~24~45~17 minecraft:stone 6
setblock ~23~46~17 minecraft:stonebrick 0
fill ~25~45~17 ~27~45~17 minecraft:stained_hardened_clay 9
fill ~28~44~17 ~29~44~17 minecraft:stained_hardened_clay 9
fill ~30~43~17 ~31~43~17 minecraft:stained_hardened_clay 9
setblock ~32~42~17 minecraft:stained_hardened_clay 9
fill ~33~41~17 ~34~41~17 minecraft:stained_hardened_clay 9
setblock ~34~40~17 minecraft:stained_hardened_clay 9
setblock ~35~39~17 minecraft:stained_hardened_clay 9
setblock ~36~30~17 minecraft:stonebrick 0
fill ~36~37~17 ~36~38~17 minecraft:stained_hardened_clay 9
fill ~36~40~17 ~36~40~18 minecraft:stonebrick 0
fill ~37~4~17 ~37~5~17 minecraft:log 1
fill ~37~11~17 ~37~11~39 minecraft:stained_hardened_clay 9
fill ~37~21~17 ~37~21~37 minecraft:stained_hardened_clay 9
fill ~37~24~17 ~37~28~17 minecraft:stonebrick 0
setblock ~37~32~17 minecraft:stonebrick 0
fill ~37~35~17 ~37~36~17 minecraft:stained_hardened_clay 9
fill ~38~2~17 ~38~2~36 minecraft:dirt 0
setblock ~38~3~17 minecraft:dirt 0
fill ~38~4~17 ~38~23~17 minecraft:stonebrick 0
setblock ~38~31~17 minecraft:stonebrick 0
fill ~38~32~17 ~38~34~17 minecraft:stained_hardened_clay 9
fill ~39~2~17 ~42~2~17 minecraft:grass
fill ~40~28~17 ~40~29~22 minecraft:stonebrick 0
fill ~41~3~17 ~41~6~17 minecraft:stained_glass_pane 12
fill ~41~7~17 ~41~7~25 minecraft:wood 1
fill ~41~8~17 ~41~11~17 minecraft:stained_glass_pane 12
fill ~41~12~17 ~41~12~25 minecraft:wood 1
fill ~41~13~17 ~41~16~17 minecraft:stained_glass_pane 12
fill ~41~17~17 ~41~17~25 minecraft:wood 1
fill ~41~18~17 ~41~18~18 minecraft:stained_glass_pane 12
fill ~41~30~17 ~41~30~19 minecraft:stonebrick 0
setblock ~42~7~17 minecraft:fence 1
setblock ~42~12~17 minecraft:fence 1
setblock ~42~17~17 minecraft:fence 1
fill ~42~22~17 ~42~22~18 minecraft:wood 1
fill ~42~27~17 ~46~27~17 minecraft:cobblestone
fill ~42~28~17 ~46~28~17 minecraft:stone_stairs 2
setblock ~44~7~17 minecraft:fence 1
setblock ~46~7~17 minecraft:fence 1
setblock ~46~17~17 minecraft:fence 1
fill ~46~22~17 ~46~22~18 minecraft:wood 1
fill ~47~3~17 ~47~6~17 minecraft:stained_glass_pane 12
fill ~47~7~17 ~47~7~20 minecraft:wood 1
fill ~47~8~17 ~47~11~17 minecraft:stained_glass_pane 12
fill ~47~12~17 ~47~12~20 minecraft:wood 1
fill ~47~13~17 ~47~16~17 minecraft:stained_glass_pane 12
fill ~47~17~17 ~47~17~23 minecraft:wood 1
setblock ~52~19~17 minecraft:stone_brick_stairs 0
fill ~53~3~17 ~53~6~17 minecraft:stained_glass_pane 12
fill ~53~7~17 ~53~7~20 minecraft:wood 1
fill ~53~8~17 ~53~11~17 minecraft:stained_glass_pane 12
fill ~53~12~17 ~53~12~20 minecraft:wood 1
fill ~53~13~17 ~53~16~17 minecraft:stained_glass_pane 12
fill ~53~17~17 ~53~17~20 minecraft:wood 1
setblock ~53~19~17 minecraft:stone_brick_stairs 5
setblock ~53~20~17 minecraft:stone_brick_stairs 0
setblock ~54~7~17 minecraft:fence 1
setblock ~54~12~17 minecraft:fence 1
setblock ~54~17~17 minecraft:fence 1
setblock ~54~20~17 minecraft:stone_brick_stairs 5
setblock ~54~21~17 minecraft:stone_brick_stairs 2
setblock ~55~21~17 minecraft:stone_brick_stairs 6
setblock ~55~22~17 minecraft:stone_brick_stairs 3
setblock ~56~7~17 minecraft:fence 1
setblock ~56~12~17 minecraft:fence 1
setblock ~56~17~17 minecraft:fence 1
setblock ~56~20~17 minecraft:stone_brick_stairs 4
setblock ~56~21~17 minecraft:stone_brick_stairs 1
fill ~57~3~17 ~57~6~17 minecraft:stained_glass_pane 12
fill ~57~7~17 ~57~7~20 minecraft:wood 1
fill ~57~8~17 ~57~11~17 minecraft:stained_glass_pane 12
fill ~57~12~17 ~57~12~20 minecraft:wood 1
fill ~57~13~17 ~57~16~17 minecraft:stained_glass_pane 12
fill ~57~17~17 ~57~17~20 minecraft:wood 1
setblock ~57~19~17 minecraft:stone_brick_stairs 4
setblock ~57~20~17 minecraft:stone_brick_stairs 1
setblock ~58~19~17 minecraft:stone_brick_stairs 1
setblock ~62~12~17 minecraft:fence 1
setblock ~62~17~17 minecraft:fence 1
setblock ~63~8~17 minecraft:stone_brick_stairs 0
setblock ~63~11~17 minecraft:double_stone_block_slab 5
setblock ~63~16~17 minecraft:stone_brick_stairs 4
setblock ~63~21~17 minecraft:double_wooden_slab 1
setblock ~63~23~17 minecraft:stained_glass_pane 12
setblock ~63~24~17 minecraft:spruce_stairs 4
setblock ~63~25~17 minecraft:glowstone
setblock ~63~26~17 minecraft:spruce_stairs 0
setblock ~63~27~17 minecraft:stained_glass_pane 12
setblock ~63~35~17 minecraft:double_stone_block_slab 3
setblock ~63~36~17 minecraft:stone_stairs 0
fill ~64~19~17 ~64~20~17 minecraft:stained_glass 11
setblock ~64~37~17 minecraft:double_stone_block_slab 3
setblock ~64~38~17 minecraft:stone_stairs 0
fill ~65~2~17 ~67~2~37 minecraft:grass
setblock ~65~30~17 minecraft:gold_block
fill ~65~32~17 ~65~33~17 minecraft:gold_block
setblock ~65~39~17 minecraft:double_stone_block_slab 3
fill ~66~34~17 ~66~38~17 minecraft:fence 1
fill ~66~39~17 ~66~40~17 minecraft:cobblestone
fill ~66~41~17 ~66~42~17 minecraft:cobblestone_wall 0
fill ~66~43~17 ~66~46~17 minecraft:fence 1
setblock ~67~30~17 minecraft:gold_block
fill ~67~32~17 ~67~33~17 minecraft:gold_block
setblock ~67~39~17 minecraft:double_stone_block_slab 3
fill ~68~19~17 ~68~20~17 minecraft:stained_glass 11
setblock ~68~37~17 minecraft:double_stone_block_slab 3
setblock ~68~38~17 minecraft:stone_stairs 1
setblock ~69~2~17 minecraft:dirt 0
setblock ~69~8~17 minecraft:stone_brick_stairs 1
setblock ~69~11~17 minecraft:double_stone_block_slab 5
setblock ~69~16~17 minecraft:stone_brick_stairs 5
setblock ~69~21~17 minecraft:double_wooden_slab 1
setblock ~69~23~17 minecraft:stained_glass_pane 12
setblock ~69~24~17 minecraft:spruce_stairs 5
setblock ~69~25~17 minecraft:glowstone
setblock ~69~26~17 minecraft:spruce_stairs 1
setblock ~69~27~17 minecraft:stained_glass_pane 12
setblock ~69~35~17 minecraft:double_stone_block_slab 3
setblock ~69~36~17 minecraft:stone_stairs 1
fill ~70~2~17 ~70~2~20 minecraft:grass
setblock ~70~12~17 minecraft:fence 1
setblock ~70~17~17 minecraft:fence 1
setblock ~74~19~17 minecraft:stone_brick_stairs 0
fill ~75~3~17 ~75~6~17 minecraft:stained_glass_pane 12
fill ~75~7~17 ~75~7~20 minecraft:wood 1
fill ~75~8~17 ~75~11~17 minecraft:stained_glass_pane 12
fill ~75~12~17 ~75~12~20 minecraft:wood 1
fill ~75~13~17 ~75~16~17 minecraft:stained_glass_pane 12
fill ~75~17~17 ~75~17~20 minecraft:wood 1
setblock ~75~19~17 minecraft:stone_brick_stairs 5
setblock ~75~20~17 minecraft:stone_brick_stairs 0
setblock ~76~7~17 minecraft:fence 1
setblock ~76~12~17 minecraft:fence 1
setblock ~76~17~17 minecraft:fence 1
setblock ~76~20~17 minecraft:stone_brick_stairs 5
setblock ~76~21~17 minecraft:stone_brick_stairs 0
setblock ~77~21~17 minecraft:stone_brick_stairs 6
setblock ~77~22~17 minecraft:stone_brick_stairs 3
setblock ~78~7~17 minecraft:fence 1
setblock ~78~12~17 minecraft:fence 1
setblock ~78~17~17 minecraft:fence 1
setblock ~78~20~17 minecraft:stone_brick_stairs 4
setblock ~78~21~17 minecraft:stone_brick_stairs 1
fill ~79~3~17 ~79~6~17 minecraft:stained_glass_pane 12
fill ~79~7~17 ~79~7~20 minecraft:wood 1
fill ~79~8~17 ~79~11~17 minecraft:stained_glass_pane 12
fill ~79~12~17 ~79~12~20 minecraft:wood 1
fill ~79~13~17 ~79~16~17 minecraft:stained_glass_pane 12
fill ~79~17~17 ~79~17~20 minecraft:wood 1
setblock ~79~19~17 minecraft:stone_brick_stairs 4
setblock ~79~20~17 minecraft:stone_brick_stairs 1
setblock ~80~19~17 minecraft:stone_brick_stairs 1
fill ~85~3~17 ~85~6~17 minecraft:stained_glass_pane 12
fill ~85~7~17 ~85~7~20 minecraft:wood 1
fill ~85~8~17 ~85~11~17 minecraft:stained_glass_pane 12
fill ~85~12~17 ~85~12~20 minecraft:wood 1
fill ~85~13~17 ~85~16~17 minecraft:stained_glass_pane 12
fill ~85~17~17 ~85~17~23 minecraft:wood 1
fill ~85~18~17 ~85~18~18 minecraft:stained_glass_pane 12
setblock ~86~17~17 minecraft:fence 1
fill ~86~22~17 ~86~22~18 minecraft:wood 1
fill ~86~27~17 ~90~27~17 minecraft:cobblestone
fill ~86~28~17 ~90~28~17 minecraft:stone_stairs 2
setblock ~90~12~17 minecraft:fence 1
setblock ~90~17~17 minecraft:fence 1
fill ~90~22~17 ~90~22~18 minecraft:wood 1
fill ~91~3~17 ~91~6~17 minecraft:stained_glass_pane 12
fill ~91~7~17 ~91~7~25 minecraft:wood 1
fill ~91~8~17 ~91~11~17 minecraft:stained_glass_pane 12
fill ~91~12~17 ~91~12~25 minecraft:wood 1
fill ~91~13~17 ~91~16~17 minecraft:stained_glass_pane 12
fill ~91~17~17 ~91~17~25 minecraft:wood 1
fill ~91~30~17 ~91~30~19 minecraft:stonebrick 0
setblock ~92~2~17 minecraft:grass
setblock ~92~3~17 minecraft:leaves 2
setblock ~92~4~17 minecraft:log 1
fill ~92~28~17 ~92~29~22 minecraft:stonebrick 0
fill ~93~2~17 ~94~2~39 minecraft:dirt 0
setblock ~93~3~17 minecraft:log 1
setblock ~93~4~17 minecraft:leaves 2
setblock ~93~5~17 minecraft:leaves 1
setblock ~94~3~17 minecraft:dirt 0
fill ~94~4~17 ~94~10~17 minecraft:stonebrick 0
fill ~94~11~17 ~95~11~35 minecraft:stained_hardened_clay 9
fill ~94~12~17 ~94~23~17 minecraft:stonebrick 0
fill ~94~25~17 ~95~25~17 minecraft:stonebrick 0
fill ~94~27~17 ~95~28~17 minecraft:stonebrick 0
setblock ~94~31~17 minecraft:stonebrick 0
fill ~94~32~17 ~94~34~17 minecraft:stained_hardened_clay 9
setblock ~95~4~17 minecraft:log 1
fill ~95~21~17 ~95~21~37 minecraft:stained_hardened_clay 9
setblock ~95~24~17 minecraft:stonebrick 0
fill ~95~26~17 ~95~26~20 minecraft:stonebrick 0
setblock ~95~32~17 minecraft:stonebrick 0
fill ~95~35~17 ~95~36~17 minecraft:stained_hardened_clay 9
setblock ~96~30~17 minecraft:stonebrick 0
fill ~96~37~17 ~96~38~17 minecraft:stained_hardened_clay 9
fill ~96~40~17 ~96~40~18 minecraft:stonebrick 0
setblock ~97~39~17 minecraft:stained_hardened_clay 9
fill ~98~40~17 ~98~41~17 minecraft:stained_hardened_clay 9
setblock ~99~41~17 minecraft:stained_hardened_clay 9
setblock ~100~42~17 minecraft:stained_hardened_clay 9
fill ~101~43~17 ~102~43~17 minecraft:stained_hardened_clay 9
fill ~103~44~17 ~104~44~17 minecraft:stained_hardened_clay 9
fill ~105~45~17 ~107~45~17 minecraft:stained_hardened_clay 9
fill ~108~45~17 ~110~45~17 minecraft:stone 6
setblock ~109~46~17 minecraft:stonebrick 0
fill ~111~45~17 ~113~45~17 minecraft:stained_hardened_clay 9
fill ~114~44~17 ~115~44~17 minecraft:stained_hardened_clay 9
fill ~116~43~17 ~117~43~17 minecraft:stained_hardened_clay 9
setblock ~118~42~17 minecraft:stained_hardened_clay 9
fill ~119~41~17 ~120~41~17 minecraft:stained_hardened_clay 9
setblock ~120~40~17 minecraft:stained_hardened_clay 9
setblock ~121~39~17 minecraft:stained_hardened_clay 9
setblock ~122~30~17 minecraft:stonebrick 0
fill ~122~37~17 ~122~38~17 minecraft:stained_hardened_clay 9
fill ~123~3~17 ~123~3~37 minecraft:grass
fill ~123~11~17 ~123~11~37 minecraft:stained_hardened_clay 9
fill ~123~21~17 ~123~21~37 minecraft:stained_hardened_clay 9
fill ~123~24~17 ~123~28~17 minecraft:stonebrick 0
setblock ~123~32~17 minecraft:stonebrick 0
fill ~123~35~17 ~123~36~17 minecraft:stained_hardened_clay 9
fill ~124~2~17 ~124~2~37 minecraft:dirt 0
fill ~124~3~17 ~124~3~19 minecraft:dirt 0
fill ~124~4~17 ~124~23~17 minecraft:stonebrick 0
setblock ~124~31~17 minecraft:stonebrick 0
fill ~124~32~17 ~124~34~17 minecraft:stained_hardened_clay 9
fill ~125~3~17 ~126~3~17 minecraft:leaves 1
setblock ~125~18~17 minecraft:leaves 2
setblock ~125~19~17 minecraft:log 1
fill ~125~21~17 ~126~21~17 minecraft:leaves 1
setblock ~125~22~17 minecraft:leaves 1
setblock ~125~26~17 minecraft:leaves 2
setblock ~125~28~17 minecraft:log 1
fill ~126~2~17 ~126~2~18 minecraft:dirt 0
setblock ~126~4~17 minecraft:log 1
fill ~126~17~17 ~126~17~19 minecraft:leaves 2
setblock ~126~18~17 minecraft:log 1
setblock ~126~19~17 minecraft:leaves 1
fill ~126~20~17 ~126~20~19 minecraft:leaves 2
fill ~126~22~17 ~126~22~19 minecraft:leaves 2
setblock ~126~27~17 minecraft:log 1
fill ~126~28~17 ~126~29~22 minecraft:stonebrick 0
fill ~127~2~17 ~138~2~19 minecraft:grass
fill ~127~18~17 ~127~18~19 minecraft:leaves 2
setblock ~127~21~17 minecraft:log 1
setblock ~127~24~17 minecraft:leaves 2
fill ~127~29~17 ~127~29~18 minecraft:leaves 2
fill ~127~30~17 ~127~30~19 minecraft:stonebrick 0
fill ~1~2~18 ~6~2~18 minecraft:grass
setblock ~5~27~18 minecraft:leaves 2
fill ~6~4~18 ~6~5~18 minecraft:leaves 2
setblock ~6~6~18 minecraft:log 1
setblock ~6~8~18 minecraft:log 1
setblock ~6~9~18 minecraft:leaves 2
setblock ~6~10~18 minecraft:log 1
fill ~6~24~18 ~7~27~19 minecraft:stonebrick 0
fill ~6~34~18 ~7~34~18 minecraft:stonebrick 0
fill ~7~2~18 ~7~2~36 minecraft:dirt 0
fill ~7~3~18 ~7~3~19 minecraft:dirt 0
fill ~7~4~18 ~7~23~19 minecraft:stonebrick 0
fill ~7~28~18 ~7~31~19 minecraft:stonebrick 0
fill ~7~32~18 ~7~32~19 minecraft:stained_hardened_clay 9
fill ~8~3~18 ~8~3~34 minecraft:grass
fill ~8~5~18 ~8~5~19 minecraft:leaves 2
setblock ~8~6~18 minecraft:leaves 2
setblock ~8~7~18 minecraft:log 1
fill ~8~8~18 ~8~10~18 minecraft:leaves 2
fill ~8~11~18 ~8~11~36 minecraft:stained_hardened_clay 9
fill ~8~21~18 ~8~21~36 minecraft:stained_hardened_clay 9
fill ~8~33~18 ~8~36~18 minecraft:stained_hardened_clay 9
setblock ~9~7~18 minecraft:leaves 2
fill ~9~37~18 ~9~38~18 minecraft:stained_hardened_clay 9
setblock ~10~39~18 minecraft:stained_hardened_clay 9
setblock ~11~40~18 minecraft:stained_hardened_clay 9
setblock ~12~41~18 minecraft:stained_hardened_clay 9
setblock ~13~42~18 minecraft:stained_hardened_clay 9
setblock ~14~43~18 minecraft:stained_hardened_clay 9
fill ~15~44~18 ~16~44~18 minecraft:stained_hardened_clay 9
fill ~17~45~18 ~20~45~18 minecraft:stained_hardened_clay 9
fill ~21~46~18 ~21~46~19 minecraft:stained_hardened_clay 9
fill ~22~46~18 ~24~46~19 minecraft:stone 6
fill ~23~47~18 ~23~47~19 minecraft:stonebrick 0
fill ~25~46~18 ~25~46~19 minecraft:stained_hardened_clay 9
fill ~26~45~18 ~29~45~18 minecraft:stained_hardened_clay 9
fill ~30~44~18 ~31~44~18 minecraft:stained_hardened_clay 9
setblock ~32~43~18 minecraft:stained_hardened_clay 9
setblock ~33~42~18 minecraft:stained_hardened_clay 9
setblock ~34~41~18 minecraft:stained_hardened_clay 9
setblock ~35~40~18 minecraft:stained_hardened_clay 9
setblock ~36~39~18 minecraft:stained_hardened_clay 9
fill ~37~3~18 ~38~3~33 minecraft:grass
fill ~37~26~18 ~37~26~20 minecraft:stonebrick 0
fill ~37~37~18 ~37~38~18 minecraft:stained_hardened_clay 9
fill ~38~11~18 ~38~11~35 minecraft:stained_hardened_clay 9
fill ~38~21~18 ~38~21~35 minecraft:stained_hardened_clay 9
fill ~38~33~18 ~38~36~18 minecraft:stained_hardened_clay 9
fill ~39~2~18 ~42~2~18 minecraft:dirt 0
fill ~39~3~18 ~39~3~19 minecraft:dirt 0
fill ~39~4~18 ~39~31~19 minecraft:stonebrick 0
fill ~39~32~18 ~39~32~19 minecraft:stained_hardened_clay 9
fill ~39~34~18 ~40~34~18 minecraft:stonebrick 0
fill ~40~3~18 ~40~6~18 minecraft:stained_glass_pane 12
setblock ~40~7~18 minecraft:wood 1
fill ~40~8~18 ~40~11~18 minecraft:stained_glass_pane 12
setblock ~40~12~18 minecraft:wood 1
fill ~40~13~18 ~40~16~18 minecraft:stained_glass_pane 12
setblock ~40~17~18 minecraft:wood 1
setblock ~40~18~18 minecraft:stained_glass_pane 12
fill ~40~24~18 ~40~26~22 minecraft:stonebrick 0
setblock ~40~27~18 minecraft:stonebrick 0
fill ~41~3~18 ~41~6~18 minecraft:wood 1
fill ~41~8~18 ~41~11~18 minecraft:wood 1
fill ~41~13~18 ~41~16~18 minecraft:wood 1
fill ~41~19~18 ~41~21~18 minecraft:stained_glass_pane 12
fill ~41~22~18 ~41~22~24 minecraft:wood 1
fill ~41~23~18 ~41~26~18 minecraft:stained_glass_pane 12
setblock ~41~27~18 minecraft:cobblestone
setblock ~41~28~18 minecraft:stone_block_slab 3
setblock ~42~3~18 minecraft:stone_brick_stairs 2
setblock ~42~6~18 minecraft:stone_brick_stairs 6
fill ~42~7~18 ~46~7~18 minecraft:wood 1
setblock ~42~8~18 minecraft:stone_brick_stairs 2
setblock ~42~11~18 minecraft:stone_brick_stairs 6
fill ~42~12~18 ~46~12~18 minecraft:wood 1
setblock ~42~13~18 minecraft:stone_brick_stairs 2
setblock ~42~16~18 minecraft:stone_brick_stairs 6
fill ~42~17~18 ~46~17~18 minecraft:wood 1
fill ~42~18~18 ~42~21~18 minecraft:wood 1
fill ~42~23~18 ~42~27~18 minecraft:wood 1
setblock ~42~28~18 minecraft:cobblestone
setblock ~42~29~18 minecraft:spruce_stairs 2
setblock ~43~2~18 minecraft:grass
fill ~43~3~18 ~45~3~18 minecraft:stone_block_slab 5
fill ~43~6~18 ~45~6~18 minecraft:stone_block_slab 13
setblock ~43~8~18 minecraft:stone_block_slab 5
setblock ~43~11~18 minecraft:stone_block_slab 13
setblock ~43~13~18 minecraft:stone_block_slab 5
setblock ~43~16~18 minecraft:stone_block_slab 13
setblock ~43~21~18 minecraft:spruce_stairs 5
fill ~43~22~18 ~45~22~18 minecraft:wood 1
setblock ~43~26~18 minecraft:spruce_stairs 5
fill ~43~27~18 ~46~27~18 minecraft:wood 1
setblock ~43~29~18 minecraft:planks 1
setblock ~43~30~18 minecraft:spruce_stairs 2
fill ~44~2~18 ~47~2~18 minecraft:dirt 0
setblock ~44~8~18 minecraft:stone_brick_stairs 2
setblock ~44~11~18 minecraft:stone_brick_stairs 6
setblock ~44~13~18 minecraft:stone_brick_stairs 2
setblock ~44~16~18 minecraft:stone_brick_stairs 6
setblock ~44~21~18 minecraft:wooden_slab 9
setblock ~44~26~18 minecraft:wooden_slab 9
setblock ~44~29~18 minecraft:cobblestone
setblock ~44~30~18 minecraft:stone_stairs 2
setblock ~45~8~18 minecraft:stone_block_slab 5
setblock ~45~11~18 minecraft:stone_block_slab 13
setblock ~45~13~18 minecraft:stone_block_slab 5
setblock ~45~16~18 minecraft:stone_block_slab 13
setblock ~45~21~18 minecraft:spruce_stairs 4
setblock ~45~26~18 minecraft:spruce_stairs 4
setblock ~45~29~18 minecraft:planks 1
setblock ~45~30~18 minecraft:spruce_stairs 2
setblock ~46~3~18 minecraft:stone_brick_stairs 2
setblock ~46~6~18 minecraft:stone_brick_stairs 6
setblock ~46~8~18 minecraft:stone_brick_stairs 2
setblock ~46~11~18 minecraft:stone_brick_stairs 6
setblock ~46~13~18 minecraft:stone_brick_stairs 2
setblock ~46~16~18 minecraft:stone_brick_stairs 6
fill ~46~18~18 ~46~21~18 minecraft:wood 1
fill ~46~23~18 ~46~26~18 minecraft:wood 1
setblock ~46~28~18 minecraft:cobblestone
setblock ~46~29~18 minecraft:spruce_stairs 2
fill ~47~3~18 ~47~6~18 minecraft:wood 1
fill ~47~8~18 ~47~11~18 minecraft:wood 1
fill ~47~13~18 ~47~16~18 minecraft:wood 1
setblock ~47~27~18 minecraft:cobblestone
setblock ~47~28~18 minecraft:stone_block_slab 3
fill ~48~2~18 ~52~2~19 minecraft:grass
fill ~48~3~18 ~48~6~18 minecraft:stained_glass_pane 12
setblock ~48~7~18 minecraft:wood 1
fill ~48~8~18 ~48~11~18 minecraft:stained_glass_pane 12
setblock ~48~12~18 minecraft:wood 1
fill ~48~13~18 ~48~16~18 minecraft:stained_glass_pane 12
setblock ~48~17~18 minecraft:wood 1
fill ~52~3~18 ~52~6~18 minecraft:stained_glass_pane 12
setblock ~52~7~18 minecraft:wood 1
fill ~52~8~18 ~52~11~18 minecraft:stained_glass_pane 12
setblock ~52~12~18 minecraft:wood 1
fill ~52~13~18 ~52~16~18 minecraft:stained_glass_pane 12
setblock ~52~17~18 minecraft:wood 1
fill ~52~19~18 ~52~19~21 minecraft:spruce_stairs 0
fill ~53~2~18 ~57~2~19 minecraft:dirt 0
fill ~53~3~18 ~53~6~18 minecraft:wood 1
fill ~53~8~18 ~53~11~18 minecraft:wood 1
fill ~53~13~18 ~53~16~18 minecraft:wood 1
fill ~53~18~18 ~53~19~18 minecraft:wood 1
fill ~53~20~18 ~53~20~22 minecraft:spruce_stairs 0
setblock ~54~3~18 minecraft:stone_brick_stairs 2
setblock ~54~6~18 minecraft:stone_brick_stairs 6
fill ~54~7~18 ~56~7~18 minecraft:wood 1
setblock ~54~8~18 minecraft:stone_brick_stairs 2
setblock ~54~11~18 minecraft:stone_brick_stairs 6
fill ~54~12~18 ~56~12~18 minecraft:wood 1
setblock ~54~16~18 minecraft:stone_brick_stairs 6
fill ~54~17~18 ~56~17~18 minecraft:wood 1
setblock ~54~20~18 minecraft:wood 1
fill ~54~21~18 ~54~21~23 minecraft:spruce_stairs 0
setblock ~55~3~18 minecraft:stone_block_slab 5
setblock ~55~6~18 minecraft:stone_block_slab 13
setblock ~55~8~18 minecraft:stone_block_slab 5
setblock ~55~11~18 minecraft:stone_block_slab 13
setblock ~55~16~18 minecraft:stone_block_slab 13
setblock ~55~21~18 minecraft:wood 1
fill ~55~22~18 ~55~22~23 minecraft:stone_block_slab 5
setblock ~56~3~18 minecraft:stone_brick_stairs 2
setblock ~56~6~18 minecraft:stone_brick_stairs 6
setblock ~56~8~18 minecraft:stone_brick_stairs 2
setblock ~56~11~18 minecraft:stone_brick_stairs 6
setblock ~56~16~18 minecraft:stone_brick_stairs 6
setblock ~56~20~18 minecraft:wood 1
fill ~56~21~18 ~56~21~23 minecraft:spruce_stairs 1
fill ~57~3~18 ~57~6~18 minecraft:wood 1
fill ~57~8~18 ~57~11~18 minecraft:wood 1
fill ~57~13~18 ~57~16~18 minecraft:wood 1
fill ~57~18~18 ~57~19~18 minecraft:wood 1
fill ~57~20~18 ~57~20~22 minecraft:spruce_stairs 1
fill ~58~2~18 ~62~2~19 minecraft:grass
fill ~58~3~18 ~58~6~18 minecraft:stained_glass_pane 12
setblock ~58~7~18 minecraft:wood 1
fill ~58~8~18 ~58~11~18 minecraft:stained_glass_pane 12
setblock ~58~12~18 minecraft:wood 1
fill ~58~13~18 ~58~16~18 minecraft:stained_glass_pane 12
setblock ~58~17~18 minecraft:wood 1
fill ~58~19~18 ~58~19~21 minecraft:spruce_stairs 1
setblock ~63~8~18 minecraft:stone_block_slab 5
setblock ~63~11~18 minecraft:stone_block_slab 13
setblock ~63~16~18 minecraft:stone_block_slab 13
setblock ~63~21~18 minecraft:wooden_slab 9
setblock ~63~23~18 minecraft:spruce_stairs 6
setblock ~63~24~18 minecraft:spruce_stairs 3
setblock ~63~26~18 minecraft:spruce_stairs 7
setblock ~63~27~18 minecraft:spruce_stairs 2
setblock ~63~32~18 minecraft:stone_brick_stairs 6
fill ~63~35~18 ~64~35~18 minecraft:planks 1
setblock ~63~36~18 minecraft:spruce_stairs 0
fill ~64~19~18 ~64~20~18 minecraft:stained_glass_pane 11
fill ~64~36~18 ~64~37~18 minecraft:planks 1
setblock ~64~38~18 minecraft:spruce_stairs 0
setblock ~65~39~18 minecraft:wooden_slab 1
setblock ~66~39~18 minecraft:double_stone_block_slab 3
setblock ~67~39~18 minecraft:wooden_slab 1
fill ~68~19~18 ~68~20~18 minecraft:stained_glass_pane 11
fill ~68~35~18 ~69~35~18 minecraft:planks 1
fill ~68~36~18 ~68~37~18 minecraft:planks 1
setblock ~68~38~18 minecraft:spruce_stairs 1
fill ~69~2~18 ~69~2~19 minecraft:grass
setblock ~69~8~18 minecraft:stone_block_slab 5
setblock ~69~11~18 minecraft:stone_block_slab 13
setblock ~69~16~18 minecraft:stone_block_slab 13
setblock ~69~21~18 minecraft:wooden_slab 9
setblock ~69~23~18 minecraft:spruce_stairs 6
setblock ~69~24~18 minecraft:spruce_stairs 3
setblock ~69~26~18 minecraft:spruce_stairs 7
setblock ~69~27~18 minecraft:spruce_stairs 2
setblock ~69~32~18 minecraft:stone_brick_stairs 6
setblock ~69~36~18 minecraft:spruce_stairs 1
fill ~71~2~18 ~74~2~20 minecraft:grass
fill ~74~3~18 ~74~6~18 minecraft:stained_glass_pane 12
setblock ~74~7~18 minecraft:wood 1
fill ~74~8~18 ~74~11~18 minecraft:stained_glass_pane 12
setblock ~74~12~18 minecraft:wood 1
