   
setblock ~1 ~0 ~3 stone_slab 5 
setblock ~1 ~0 ~8 stone_slab 5 
setblock ~1 ~0 ~13 stone_slab 5 
setblock ~1 ~0 ~30 stone_slab 5 
setblock ~1 ~0 ~35 stone_slab 5 
setblock ~1 ~0 ~40 stone_slab 5  
fill ~2 ~0 ~3 ~3 ~0 ~3 stonebrick  
fill ~2 ~0 ~8 ~3 ~0 ~8 stonebrick  
fill ~2 ~0 ~13 ~3 ~0 ~13 stonebrick 
setblock ~2 ~0 ~30 double_stone_slab 5  
fill ~2 ~0 ~35 ~3 ~0 ~35 stonebrick  
fill ~2 ~0 ~40 ~3 ~0 ~40 stonebrick  
fill ~3 ~0 ~2 ~4 ~0 ~2 stonebrick 
setblock ~3 ~0 ~4 stone_brick_stairs 3 
setblock ~3 ~0 ~5 stone_brick_stairs 2 
setblock ~3 ~0 ~6 stone_brick_stairs 3 
setblock ~3 ~0 ~7 stone_brick_stairs 2 
setblock ~3 ~0 ~9 stone_brick_stairs 3 
setblock ~3 ~0 ~10 stone_brick_stairs 2 
setblock ~3 ~0 ~11 stone_brick_stairs 3 
setblock ~3 ~0 ~12 stone_brick_stairs 2  
fill ~3 ~0 ~14 ~4 ~0 ~14 stonebrick  
fill ~3 ~0 ~29 ~4 ~0 ~29 stonebrick  
fill ~3 ~0 ~30 ~3 ~7 ~30 stonebrick 
setblock ~3 ~0 ~31 stone_brick_stairs 3 
setblock ~3 ~0 ~32 stone_brick_stairs 2 
setblock ~3 ~0 ~33 stone_brick_stairs 3 
setblock ~3 ~0 ~34 stone_brick_stairs 2 
setblock ~3 ~0 ~36 stone_brick_stairs 3 
setblock ~3 ~0 ~37 stone_brick_stairs 2 
setblock ~3 ~0 ~38 stone_brick_stairs 3 
setblock ~3 ~0 ~39 stone_brick_stairs 2  
fill ~3 ~0 ~41 ~4 ~0 ~41 stonebrick 
setblock ~4 ~0 ~0 stone_slab 5 
setblock ~4 ~0 ~1 stonebrick 0  
fill ~4 ~0 ~3 ~4 ~6 ~3 cobblestone  
fill ~4 ~0 ~4 ~4 ~0 ~7 stone  
fill ~4 ~0 ~8 ~4 ~6 ~8 cobblestone  
fill ~4 ~0 ~9 ~4 ~0 ~12 stone  
fill ~4 ~0 ~13 ~4 ~6 ~13 cobblestone 
setblock ~4 ~0 ~15 stonebrick 0 
setblock ~4 ~0 ~16 stone_slab 5 
setblock ~4 ~0 ~27 stone_slab 5 
setblock ~4 ~0 ~28 stonebrick 0  
fill ~4 ~0 ~30 ~4 ~6 ~30 cobblestone  
fill ~4 ~0 ~31 ~4 ~0 ~34 stone  
fill ~4 ~0 ~35 ~4 ~6 ~35 cobblestone  
fill ~4 ~0 ~36 ~4 ~0 ~39 stone  
fill ~4 ~0 ~40 ~4 ~6 ~40 cobblestone 
setblock ~4 ~0 ~42 stonebrick 0 
setblock ~4 ~0 ~43 stone_slab 5 
setblock ~5 ~0 ~2 stone_brick_stairs 1  
fill ~5 ~0 ~3 ~8 ~0 ~3 stone  
fill ~5 ~0 ~13 ~8 ~0 ~13 stone 
setblock ~5 ~0 ~14 stone_brick_stairs 1 
setblock ~5 ~0 ~29 stone_brick_stairs 1  
fill ~5 ~0 ~30 ~8 ~0 ~30 stone  
fill ~5 ~0 ~40 ~8 ~0 ~40 stone 
setblock ~5 ~0 ~41 stone_brick_stairs 1 
setblock ~6 ~0 ~2 stone_brick_stairs 0 
setblock ~6 ~0 ~14 stone_brick_stairs 0 
setblock ~6 ~0 ~29 stone_brick_stairs 0 
setblock ~6 ~0 ~41 stone_brick_stairs 0 
setblock ~7 ~0 ~2 stone_brick_stairs 1 
setblock ~7 ~0 ~14 stone_brick_stairs 1 
setblock ~7 ~0 ~29 stone_brick_stairs 1 
setblock ~7 ~0 ~41 stone_brick_stairs 1 
setblock ~8 ~0 ~2 stone_brick_stairs 0 
setblock ~8 ~0 ~14 stone_brick_stairs 0 
setblock ~8 ~0 ~20 stone_slab 5 
setblock ~8 ~0 ~23 stone_slab 5 
setblock ~8 ~0 ~29 stone_brick_stairs 0 
setblock ~8 ~0 ~41 stone_brick_stairs 0 
setblock ~9 ~0 ~0 stone_slab 5  
fill ~9 ~0 ~1 ~9 ~0 ~2 stonebrick  
fill ~9 ~0 ~3 ~9 ~6 ~3 cobblestone  
fill ~9 ~0 ~14 ~9 ~7 ~14 stonebrick  
fill ~9 ~0 ~15 ~10 ~0 ~15 stonebrick  
fill ~9 ~0 ~20 ~10 ~0 ~20 stonebrick  
fill ~9 ~0 ~23 ~10 ~0 ~23 stonebrick  
fill ~9 ~0 ~28 ~10 ~0 ~28 stonebrick  
fill ~9 ~0 ~29 ~9 ~7 ~29 stonebrick  
fill ~9 ~0 ~40 ~9 ~6 ~40 cobblestone  
fill ~9 ~0 ~41 ~9 ~7 ~41 stonebrick  
fill ~9 ~0 ~42 ~9 ~0 ~41 stonebrick 
setblock ~9 ~0 ~43 stone_slab 5 
setblock ~10 ~0 ~2 stone_brick_stairs 1  
fill ~10 ~0 ~3 ~13 ~0 ~3 stone 
setblock ~10 ~0 ~16 stone_brick_stairs 3 
setblock ~10 ~0 ~17 stone_brick_stairs 2 
setblock ~10 ~0 ~18 stone_brick_stairs 3 
setblock ~10 ~0 ~19 stone_brick_stairs 2  
fill ~10 ~0 ~21 ~10 ~0 ~22 stone_slab 
setblock ~10 ~0 ~24 stone_brick_stairs 3 
setblock ~10 ~0 ~25 stone_brick_stairs 2 
setblock ~10 ~0 ~26 stone_brick_stairs 3 
setblock ~10 ~0 ~27 stone_brick_stairs 2  
fill ~10 ~0 ~40 ~13 ~0 ~40 stone 
setblock ~10 ~0 ~41 stone_brick_stairs 1 
setblock ~11 ~0 ~2 stone_brick_stairs 0  
fill ~11 ~0 ~16 ~11 ~0 ~19 stone  
fill ~11 ~0 ~21 ~11 ~0 ~22 stonebrick  
fill ~11 ~0 ~24 ~11 ~0 ~27 stone 
setblock ~11 ~0 ~41 stone_brick_stairs 0 
setblock ~12 ~0 ~2 stone_brick_stairs 1 
setblock ~12 ~0 ~41 stone_brick_stairs 1 
setblock ~13 ~0 ~2 stone_brick_stairs 0 
setblock ~13 ~0 ~41 stone_brick_stairs 0 
setblock ~14 ~0 ~0 stone_slab 5  
fill ~14 ~0 ~1 ~14 ~0 ~2 stonebrick  
fill ~14 ~0 ~3 ~14 ~6 ~3 cobblestone  
fill ~14 ~0 ~40 ~14 ~6 ~40 cobblestone  
fill ~14 ~0 ~41 ~14 ~7 ~41 stonebrick  
fill ~14 ~0 ~42 ~14 ~0 ~41 stonebrick 
setblock ~14 ~0 ~43 stone_slab 5 
setblock ~15 ~0 ~2 stone_brick_stairs 1  
fill ~15 ~0 ~3 ~18 ~0 ~3 stone  
fill ~15 ~0 ~40 ~18 ~0 ~40 stone 
setblock ~15 ~0 ~41 stone_brick_stairs 1 
setblock ~16 ~0 ~2 stone_brick_stairs 0 
setblock ~16 ~0 ~41 stone_brick_stairs 0 
setblock ~17 ~0 ~2 stone_brick_stairs 1 
setblock ~17 ~0 ~41 stone_brick_stairs 1 
setblock ~18 ~0 ~2 stone_brick_stairs 0 
setblock ~18 ~0 ~41 stone_brick_stairs 0 
setblock ~19 ~0 ~0 stone_slab 5  
fill ~19 ~0 ~1 ~19 ~0 ~2 stonebrick  
fill ~19 ~0 ~3 ~19 ~6 ~3 cobblestone  
fill ~19 ~0 ~40 ~19 ~6 ~40 cobblestone  
fill ~19 ~0 ~41 ~19 ~7 ~41 stonebrick  
fill ~19 ~0 ~42 ~19 ~0 ~41 stonebrick 
setblock ~19 ~0 ~43 stone_slab 5 
setblock ~20 ~0 ~2 stone_brick_stairs 1  
fill ~20 ~0 ~3 ~23 ~0 ~3 stone  
fill ~20 ~0 ~40 ~23 ~0 ~40 stone 
setblock ~20 ~0 ~41 stone_brick_stairs 1 
setblock ~21 ~0 ~2 stone_brick_stairs 0 
setblock ~21 ~0 ~41 stone_brick_stairs 0 
setblock ~22 ~0 ~2 stone_brick_stairs 1 
setblock ~22 ~0 ~41 stone_brick_stairs 1 
setblock ~23 ~0 ~2 stone_brick_stairs 0 
setblock ~23 ~0 ~41 stone_brick_stairs 0 
setblock ~24 ~0 ~0 stone_slab 5  
fill ~24 ~0 ~1 ~24 ~0 ~2 stonebrick  
fill ~24 ~0 ~3 ~24 ~6 ~3 cobblestone  
fill ~24 ~0 ~40 ~24 ~6 ~40 cobblestone  
fill ~24 ~0 ~41 ~24 ~7 ~41 stonebrick  
fill ~24 ~0 ~42 ~24 ~0 ~41 stonebrick 
setblock ~24 ~0 ~43 stone_slab 5 
setblock ~25 ~0 ~2 stone_brick_stairs 1  
fill ~25 ~0 ~3 ~28 ~0 ~3 stone  
fill ~25 ~0 ~40 ~28 ~0 ~40 stone 
setblock ~25 ~0 ~41 stone_brick_stairs 1 
setblock ~26 ~0 ~2 stone_brick_stairs 0 
setblock ~26 ~0 ~41 stone_brick_stairs 0 
setblock ~27 ~0 ~2 stone_brick_stairs 1 
setblock ~27 ~0 ~41 stone_brick_stairs 1 
setblock ~28 ~0 ~2 stone_brick_stairs 0  
fill ~28 ~0 ~14 ~28 ~6 ~14 cobblestone  
fill ~28 ~0 ~15 ~28 ~0 ~18 stone  
fill ~28 ~0 ~19 ~28 ~6 ~19 cobblestone  
fill ~28 ~0 ~20 ~28 ~0 ~23 stone  
fill ~28 ~0 ~24 ~28 ~6 ~24 cobblestone  
fill ~28 ~0 ~25 ~28 ~0 ~28 stone  
fill ~28 ~0 ~29 ~28 ~6 ~29 cobblestone 
setblock ~28 ~0 ~41 stone_brick_stairs 0 
setblock ~29 ~0 ~0 stone_slab 5  
fill ~29 ~0 ~1 ~29 ~0 ~2 stonebrick  
fill ~29 ~0 ~3 ~29 ~6 ~3 cobblestone  
fill ~29 ~0 ~4 ~29 ~0 ~12 stone  
fill ~29 ~0 ~13 ~29 ~6 ~13 cobblestone  
fill ~29 ~0 ~14 ~30 ~0 ~14 stonebrick 
setblock ~29 ~0 ~15 stone_brick_stairs 3 
setblock ~29 ~0 ~16 stone_brick_stairs 2 
setblock ~29 ~0 ~17 stone_brick_stairs 3 
setblock ~29 ~0 ~18 stone_brick_stairs 2  
fill ~29 ~0 ~19 ~30 ~0 ~19 stonebrick 
setblock ~29 ~0 ~20 stone_brick_stairs 3 
setblock ~29 ~0 ~21 stone_brick_stairs 2 
setblock ~29 ~0 ~22 stone_brick_stairs 3 
setblock ~29 ~0 ~23 stone_brick_stairs 2  
fill ~29 ~0 ~24 ~30 ~0 ~24 stonebrick 
setblock ~29 ~0 ~25 stone_brick_stairs 3 
setblock ~29 ~0 ~26 stone_brick_stairs 2 
setblock ~29 ~0 ~27 stone_brick_stairs 3 
setblock ~29 ~0 ~28 stone_brick_stairs 2  
fill ~29 ~0 ~29 ~30 ~0 ~29 stonebrick  
fill ~29 ~0 ~30 ~29 ~6 ~30 cobblestone  
fill ~29 ~0 ~31 ~29 ~0 ~39 stone  
fill ~29 ~0 ~40 ~29 ~6 ~40 cobblestone  
fill ~29 ~0 ~41 ~30 ~0 ~41 stonebrick  
fill ~29 ~0 ~42 ~29 ~0 ~41 stonebrick 
setblock ~29 ~0 ~43 stone_slab 5  
fill ~30 ~0 ~2 ~30 ~1 ~2 stonebrick  
fill ~30 ~0 ~3 ~31 ~0 ~3 stonebrick 
setblock ~30 ~0 ~4 stone_brick_stairs 3 
setblock ~30 ~0 ~7 stone_brick_stairs 2  
fill ~30 ~0 ~8 ~30 ~7 ~8 stonebrick 
setblock ~30 ~0 ~9 stone_brick_stairs 3 
setblock ~30 ~0 ~12 stone_brick_stairs 2  
fill ~30 ~0 ~13 ~31 ~0 ~13 stonebrick  
fill ~30 ~0 ~30 ~31 ~0 ~30 stonebrick 
setblock ~30 ~0 ~31 stone_brick_stairs 3 
setblock ~30 ~0 ~34 stone_brick_stairs 2  
fill ~30 ~0 ~35 ~30 ~7 ~35 stonebrick 
setblock ~30 ~0 ~36 stone_brick_stairs 3 
setblock ~30 ~0 ~39 stone_brick_stairs 2  
fill ~30 ~0 ~40 ~31 ~0 ~40 stonebrick 
setblock ~31 ~0 ~8 stone_brick_stairs 1 
setblock ~31 ~0 ~19 stone_slab 5 
setblock ~31 ~0 ~24 stone_slab 5 
setblock ~31 ~0 ~35 stone_brick_stairs 1 
setblock ~32 ~0 ~3 stone_slab 5 
setblock ~32 ~0 ~13 stone_slab 5 
setblock ~32 ~0 ~30 stone_slab 5 
setblock ~32 ~0 ~40 stone_slab 5 
setblock ~2 ~1 ~3 stone_brick_stairs 4 
setblock ~2 ~1 ~8 stone_brick_stairs 4 
setblock ~2 ~1 ~13 stone_brick_stairs 4 
setblock ~2 ~1 ~30 stone_brick_stairs 4 
setblock ~2 ~1 ~35 stone_brick_stairs 4 
setblock ~2 ~1 ~40 stone_brick_stairs 4  
fill ~3 ~1 ~2 ~4 ~1 ~2 stonebrick  
fill ~3 ~1 ~3 ~3 ~7 ~3 stonebrick 
setblock ~3 ~1 ~4 stone_slab 5  
fill ~3 ~1 ~5 ~3 ~1 ~6 stone_slab 
setblock ~3 ~1 ~7 stone_slab 5  
fill ~3 ~1 ~8 ~3 ~7 ~8 stonebrick 
setblock ~3 ~1 ~9 stone_slab 5  
fill ~3 ~1 ~10 ~3 ~1 ~11 stone_slab 
setblock ~3 ~1 ~12 stone_slab 5  
fill ~3 ~1 ~13 ~3 ~7 ~13 stonebrick  
fill ~3 ~1 ~14 ~4 ~1 ~14 stonebrick  
fill ~3 ~1 ~29 ~4 ~1 ~29 stonebrick 
setblock ~3 ~1 ~31 stone_slab 5  
fill ~3 ~1 ~32 ~3 ~1 ~33 stone_slab 
setblock ~3 ~1 ~34 stone_slab 5  
fill ~3 ~1 ~35 ~3 ~7 ~35 stonebrick 
setblock ~3 ~1 ~36 stone_slab 5  
fill ~3 ~1 ~37 ~3 ~1 ~38 stone_slab 
setblock ~3 ~1 ~39 stone_slab 5  
fill ~3 ~1 ~40 ~3 ~7 ~40 stonebrick  
fill ~3 ~1 ~41 ~4 ~1 ~41 stonebrick 
setblock ~4 ~1 ~1 stone_brick_stairs 6  
fill ~4 ~1 ~4 ~4 ~2 ~4 cobblestone  
fill ~4 ~1 ~5 ~4 ~1 ~6 stone  
fill ~4 ~1 ~7 ~4 ~2 ~7 cobblestone  
fill ~4 ~1 ~9 ~4 ~2 ~9 cobblestone  
fill ~4 ~1 ~10 ~4 ~1 ~11 stone  
fill ~4 ~1 ~12 ~4 ~2 ~12 cobblestone 
setblock ~4 ~1 ~15 stone_brick_stairs 7 
setblock ~4 ~1 ~28 stone_brick_stairs 6  
fill ~4 ~1 ~31 ~4 ~2 ~31 cobblestone  
fill ~4 ~1 ~32 ~4 ~1 ~33 stone  
fill ~4 ~1 ~34 ~4 ~2 ~34 cobblestone  
fill ~4 ~1 ~36 ~4 ~2 ~36 cobblestone  
fill ~4 ~1 ~37 ~4 ~1 ~38 stone  
fill ~4 ~1 ~39 ~4 ~2 ~39 cobblestone 
setblock ~4 ~1 ~42 stone_brick_stairs 7 
setblock ~5 ~1 ~2 stone_slab 5  
fill ~5 ~1 ~3 ~5 ~2 ~3 cobblestone  
fill ~5 ~1 ~13 ~5 ~2 ~13 cobblestone 
setblock ~5 ~1 ~14 stone_slab 5 
setblock ~5 ~1 ~29 stone_slab 5  
fill ~5 ~1 ~30 ~5 ~2 ~30 cobblestone  
fill ~5 ~1 ~40 ~5 ~2 ~40 cobblestone 
setblock ~5 ~1 ~41 stone_slab 5  
fill ~6 ~1 ~2 ~7 ~1 ~2 stone_slab  
fill ~6 ~1 ~3 ~7 ~1 ~3 stone  
fill ~6 ~1 ~13 ~7 ~1 ~13 stone  
fill ~6 ~1 ~14 ~7 ~1 ~14 stone_slab  
fill ~6 ~1 ~29 ~7 ~1 ~29 stone_slab  
fill ~6 ~1 ~30 ~7 ~1 ~30 stone  
fill ~6 ~1 ~40 ~7 ~1 ~40 stone  
fill ~6 ~1 ~41 ~7 ~1 ~41 stone_slab 
setblock ~8 ~1 ~2 stone_slab 5  
fill ~8 ~1 ~3 ~8 ~2 ~3 cobblestone  
fill ~8 ~1 ~13 ~8 ~2 ~13 cobblestone 
setblock ~8 ~1 ~14 stone_slab 5 
setblock ~8 ~1 ~29 stone_slab 5  
fill ~8 ~1 ~30 ~8 ~2 ~30 cobblestone  
fill ~8 ~1 ~40 ~8 ~2 ~40 cobblestone 
setblock ~8 ~1 ~41 stone_slab 5 
setblock ~9 ~1 ~1 stone_brick_stairs 6  
fill ~9 ~1 ~2 ~9 ~7 ~2 stonebrick  
fill ~9 ~1 ~15 ~10 ~1 ~15 stonebrick 
setblock ~9 ~1 ~20 stone_brick_stairs 4 
setblock ~9 ~1 ~23 stone_brick_stairs 4  
fill ~9 ~1 ~28 ~10 ~1 ~28 stonebrick 
setblock ~9 ~1 ~42 stone_brick_stairs 7 
setblock ~10 ~1 ~2 stone_slab 5  
fill ~10 ~1 ~3 ~10 ~2 ~3 cobblestone 
setblock ~10 ~1 ~16 stone_slab 5  
fill ~10 ~1 ~17 ~10 ~1 ~18 stone_slab 
setblock ~10 ~1 ~19 stone_slab 5  
fill ~10 ~1 ~20 ~10 ~7 ~20 stonebrick  
fill ~10 ~1 ~23 ~10 ~7 ~23 stonebrick 
setblock ~10 ~1 ~24 stone_slab 5  
fill ~10 ~1 ~25 ~10 ~1 ~26 stone_slab 
setblock ~10 ~1 ~27 stone_slab 5  
fill ~10 ~1 ~40 ~10 ~2 ~40 cobblestone 
setblock ~10 ~1 ~41 stone_slab 5  
fill ~11 ~1 ~2 ~12 ~1 ~2 stone_slab  
fill ~11 ~1 ~3 ~12 ~1 ~3 stone  
fill ~11 ~1 ~16 ~11 ~2 ~16 cobblestone  
fill ~11 ~1 ~17 ~11 ~1 ~18 stone  
fill ~11 ~1 ~19 ~11 ~2 ~19 cobblestone 
setblock ~11 ~1 ~21 wooden_door 0 
setblock ~11 ~1 ~22 wooden_door 7  
fill ~11 ~1 ~24 ~11 ~2 ~24 cobblestone  
fill ~11 ~1 ~25 ~11 ~1 ~26 stone  
fill ~11 ~1 ~27 ~11 ~2 ~27 cobblestone  
fill ~11 ~1 ~40 ~12 ~1 ~40 stone  
fill ~11 ~1 ~41 ~12 ~1 ~41 stone_slab 
setblock ~13 ~1 ~2 stone_slab 5  
fill ~13 ~1 ~3 ~13 ~2 ~3 cobblestone  
fill ~13 ~1 ~40 ~13 ~2 ~40 cobblestone 
setblock ~13 ~1 ~41 stone_slab 5 
setblock ~14 ~1 ~1 stone_brick_stairs 6  
fill ~14 ~1 ~2 ~14 ~7 ~2 stonebrick 
setblock ~14 ~1 ~42 stone_brick_stairs 7 
setblock ~15 ~1 ~2 stone_slab 5  
fill ~15 ~1 ~3 ~15 ~2 ~3 cobblestone  
fill ~15 ~1 ~40 ~15 ~2 ~40 cobblestone 
setblock ~15 ~1 ~41 stone_slab 5  
fill ~16 ~1 ~2 ~17 ~1 ~2 stone_slab  
fill ~16 ~1 ~3 ~17 ~1 ~3 stone  
fill ~16 ~1 ~40 ~17 ~1 ~40 stone  
fill ~16 ~1 ~41 ~17 ~1 ~41 stone_slab 
setblock ~18 ~1 ~2 stone_slab 5  
fill ~18 ~1 ~3 ~18 ~2 ~3 cobblestone  
fill ~18 ~1 ~40 ~18 ~2 ~40 cobblestone 
setblock ~18 ~1 ~41 stone_slab 5 
setblock ~19 ~1 ~1 stone_brick_stairs 6  
fill ~19 ~1 ~2 ~19 ~7 ~2 stonebrick 
setblock ~19 ~1 ~42 stone_brick_stairs 7 
setblock ~20 ~1 ~2 stone_slab 5  
fill ~20 ~1 ~3 ~20 ~2 ~3 cobblestone  
fill ~20 ~1 ~40 ~20 ~2 ~40 cobblestone 
setblock ~20 ~1 ~41 stone_slab 5  
fill ~21 ~1 ~2 ~22 ~1 ~2 stone_slab  
fill ~21 ~1 ~3 ~22 ~1 ~3 stone  
fill ~21 ~1 ~40 ~22 ~1 ~40 stone  
fill ~21 ~1 ~41 ~22 ~1 ~41 stone_slab 
setblock ~23 ~1 ~2 stone_slab 5  
fill ~23 ~1 ~3 ~23 ~2 ~3 cobblestone  
fill ~23 ~1 ~40 ~23 ~2 ~40 cobblestone 
setblock ~23 ~1 ~41 stone_slab 5 
setblock ~24 ~1 ~1 stone_brick_stairs 6  
fill ~24 ~1 ~2 ~24 ~7 ~2 stonebrick 
setblock ~24 ~1 ~42 stone_brick_stairs 7 
setblock ~25 ~1 ~2 stone_slab 5  
fill ~25 ~1 ~3 ~25 ~2 ~3 cobblestone  
fill ~25 ~1 ~40 ~25 ~2 ~40 cobblestone 
setblock ~25 ~1 ~41 stone_slab 5  
fill ~26 ~1 ~2 ~27 ~1 ~2 stone_slab  
fill ~26 ~1 ~3 ~27 ~1 ~3 stone  
fill ~26 ~1 ~40 ~27 ~1 ~40 stone  
fill ~26 ~1 ~41 ~27 ~1 ~41 stone_slab 
setblock ~28 ~1 ~2 stone_slab 5  
fill ~28 ~1 ~3 ~28 ~2 ~3 cobblestone  
fill ~28 ~1 ~15 ~28 ~2 ~15 cobblestone  
fill ~28 ~1 ~16 ~28 ~1 ~17 stone  
fill ~28 ~1 ~18 ~28 ~2 ~18 cobblestone  
fill ~28 ~1 ~20 ~28 ~2 ~20 cobblestone  
fill ~28 ~1 ~21 ~28 ~1 ~22 stone  
fill ~28 ~1 ~23 ~28 ~2 ~23 cobblestone  
fill ~28 ~1 ~25 ~28 ~2 ~25 cobblestone  
fill ~28 ~1 ~26 ~28 ~1 ~27 stone  
fill ~28 ~1 ~28 ~28 ~2 ~28 cobblestone  
fill ~28 ~1 ~40 ~28 ~2 ~40 cobblestone 
setblock ~28 ~1 ~41 stone_slab 5 
setblock ~29 ~1 ~1 stone_brick_stairs 6  
fill ~29 ~1 ~2 ~29 ~7 ~2 stonebrick  
fill ~29 ~1 ~4 ~29 ~2 ~4 cobblestone  
fill ~29 ~1 ~5 ~29 ~1 ~6 stone  
fill ~29 ~1 ~7 ~29 ~2 ~7 cobblestone 
setblock ~29 ~1 ~8 stone 0  
fill ~29 ~1 ~9 ~29 ~2 ~9 cobblestone  
fill ~29 ~1 ~10 ~29 ~1 ~11 stone  
fill ~29 ~1 ~12 ~29 ~2 ~12 cobblestone  
fill ~29 ~1 ~14 ~30 ~1 ~14 stonebrick 
setblock ~29 ~1 ~15 stone_slab 5  
fill ~29 ~1 ~16 ~29 ~1 ~17 stone_slab 
setblock ~29 ~1 ~18 stone_slab 5  
fill ~29 ~1 ~19 ~29 ~7 ~19 stonebrick 
setblock ~29 ~1 ~20 stone_slab 5  
fill ~29 ~1 ~21 ~29 ~1 ~22 stone_slab 
setblock ~29 ~1 ~23 stone_slab 5  
fill ~29 ~1 ~24 ~29 ~7 ~24 stonebrick 
setblock ~29 ~1 ~25 stone_slab 5  
fill ~29 ~1 ~26 ~29 ~1 ~27 stone_slab 
setblock ~29 ~1 ~28 stone_slab 5  
fill ~29 ~1 ~29 ~30 ~1 ~29 stonebrick  
fill ~29 ~1 ~31 ~29 ~2 ~31 cobblestone  
fill ~29 ~1 ~32 ~29 ~1 ~33 stone  
fill ~29 ~1 ~34 ~29 ~2 ~34 cobblestone 
setblock ~29 ~1 ~35 stone 0  
fill ~29 ~1 ~36 ~29 ~2 ~36 cobblestone  
fill ~29 ~1 ~37 ~29 ~1 ~38 stone  
fill ~29 ~1 ~39 ~29 ~2 ~39 cobblestone  
fill ~29 ~1 ~41 ~30 ~1 ~41 stonebrick 
setblock ~29 ~1 ~42 stone_brick_stairs 7  
fill ~30 ~1 ~3 ~30 ~7 ~3 stonebrick 
setblock ~30 ~1 ~4 stone_slab 5  
fill ~30 ~1 ~5 ~30 ~1 ~6 stone_slab 
setblock ~30 ~1 ~7 stone_slab 5 
setblock ~30 ~1 ~9 stone_slab 5  
fill ~30 ~1 ~10 ~30 ~1 ~11 stone_slab 
setblock ~30 ~1 ~12 stone_slab 5  
fill ~30 ~1 ~13 ~30 ~7 ~13 stonebrick 
setblock ~30 ~1 ~19 stone_brick_stairs 5 
setblock ~30 ~1 ~24 stone_brick_stairs 5  
fill ~30 ~1 ~30 ~30 ~7 ~30 stonebrick 
setblock ~30 ~1 ~31 stone_slab 5  
fill ~30 ~1 ~32 ~30 ~1 ~33 stone_slab 
setblock ~30 ~1 ~34 stone_slab 5 
setblock ~30 ~1 ~36 stone_slab 5  
fill ~30 ~1 ~37 ~30 ~1 ~38 stone_slab 
setblock ~30 ~1 ~39 stone_slab 5  
fill ~30 ~1 ~40 ~30 ~7 ~40 stonebrick 
setblock ~31 ~1 ~3 stone_brick_stairs 5 
setblock ~31 ~1 ~8 stone_brick_stairs 5 
setblock ~31 ~1 ~13 stone_brick_stairs 5 
setblock ~31 ~1 ~30 stone_brick_stairs 5 
setblock ~31 ~1 ~35 stone_brick_stairs 5 
setblock ~31 ~1 ~40 stone_brick_stairs 5 
setblock ~2 ~2 ~3 cobblestone_wall 0 
setblock ~2 ~2 ~8 cobblestone_wall 0 
setblock ~2 ~2 ~13 cobblestone_wall 0 
setblock ~2 ~2 ~30 cobblestone_wall 0 
setblock ~2 ~2 ~35 cobblestone_wall 0 
setblock ~2 ~2 ~40 cobblestone_wall 0  
fill ~3 ~2 ~2 ~3 ~6 ~2 cobblestone_wall  
fill ~3 ~2 ~14 ~3 ~6 ~14 cobblestone_wall  
fill ~3 ~2 ~29 ~3 ~6 ~29 cobblestone_wall  
fill ~3 ~2 ~41 ~3 ~6 ~41 cobblestone_wall 
setblock ~4 ~2 ~1 cobblestone_wall 0  
fill ~4 ~2 ~2 ~4 ~7 ~2 stonebrick  
fill ~4 ~2 ~5 ~4 ~2 ~6 stone_stairs  
fill ~4 ~2 ~10 ~4 ~2 ~11 stone_stairs  
fill ~4 ~2 ~14 ~4 ~7 ~14 stonebrick 
setblock ~4 ~2 ~15 cobblestone_wall 0 
setblock ~4 ~2 ~28 cobblestone_wall 0  
fill ~4 ~2 ~29 ~4 ~7 ~29 stonebrick  
fill ~4 ~2 ~32 ~4 ~2 ~33 stone_stairs  
fill ~4 ~2 ~37 ~4 ~2 ~38 stone_stairs  
fill ~4 ~2 ~41 ~4 ~7 ~41 stonebrick 
setblock ~4 ~2 ~42 cobblestone_wall 0  
fill ~6 ~2 ~3 ~7 ~2 ~3 stone_stairs  
fill ~6 ~2 ~13 ~7 ~2 ~13 stone_stairs  
fill ~6 ~2 ~30 ~7 ~2 ~30 stone_stairs  
fill ~6 ~2 ~40 ~7 ~2 ~40 stone_stairs 
setblock ~9 ~2 ~1 cobblestone_wall 0  
fill ~9 ~2 ~15 ~9 ~6 ~15 cobblestone_wall 
setblock ~9 ~2 ~20 cobblestone_wall 0 
setblock ~9 ~2 ~23 cobblestone_wall 0  
fill ~9 ~2 ~28 ~9 ~6 ~28 cobblestone_wall 
setblock ~9 ~2 ~42 cobblestone_wall 0  
fill ~10 ~2 ~15 ~10 ~7 ~15 stonebrick  
fill ~10 ~2 ~28 ~10 ~7 ~28 stonebrick  
fill ~11 ~2 ~3 ~12 ~2 ~3 stone_stairs  
fill ~11 ~2 ~17 ~11 ~2 ~18 stone_stairs  
fill ~11 ~2 ~21 ~11 ~2 ~22 wooden_door  
fill ~11 ~2 ~25 ~11 ~2 ~26 stone_stairs  
fill ~11 ~2 ~40 ~12 ~2 ~40 stone_stairs 
setblock ~14 ~2 ~1 cobblestone_wall 0 
setblock ~14 ~2 ~42 cobblestone_wall 0  
fill ~16 ~2 ~3 ~17 ~2 ~3 stone_stairs  
fill ~16 ~2 ~40 ~17 ~2 ~40 stone_stairs 
setblock ~19 ~2 ~1 cobblestone_wall 0 
setblock ~19 ~2 ~42 cobblestone_wall 0  
fill ~21 ~2 ~3 ~22 ~2 ~3 stone_stairs  
fill ~21 ~2 ~40 ~22 ~2 ~40 stone_stairs 
setblock ~24 ~2 ~1 cobblestone_wall 0 
setblock ~24 ~2 ~42 cobblestone_wall 0  
fill ~26 ~2 ~3 ~27 ~2 ~3 stone_stairs  
fill ~26 ~2 ~40 ~27 ~2 ~40 stone_stairs  
fill ~28 ~2 ~16 ~28 ~2 ~17 stone_stairs  
fill ~28 ~2 ~21 ~28 ~2 ~22 stone_stairs  
fill ~28 ~2 ~26 ~28 ~2 ~27 stone_stairs 
setblock ~29 ~2 ~1 cobblestone_wall 0  
fill ~29 ~2 ~5 ~29 ~2 ~6 stone_stairs  
fill ~29 ~2 ~8 ~29 ~6 ~8 cobblestone  
fill ~29 ~2 ~10 ~29 ~2 ~11 stone_stairs  
fill ~29 ~2 ~14 ~29 ~7 ~14 stonebrick  
fill ~29 ~2 ~29 ~29 ~7 ~29 stonebrick  
fill ~29 ~2 ~32 ~29 ~2 ~33 stone_stairs  
fill ~29 ~2 ~35 ~29 ~6 ~35 cobblestone  
fill ~29 ~2 ~37 ~29 ~2 ~38 stone_stairs  
fill ~29 ~2 ~41 ~29 ~7 ~41 stonebrick 
setblock ~29 ~2 ~42 cobblestone_wall 0  
fill ~30 ~2 ~2 ~30 ~6 ~2 cobblestone_wall  
fill ~30 ~2 ~14 ~30 ~6 ~14 cobblestone_wall 
setblock ~30 ~2 ~19 cobblestone_wall 0 
setblock ~30 ~2 ~24 cobblestone_wall 0  
fill ~30 ~2 ~29 ~30 ~6 ~29 cobblestone_wall  
fill ~30 ~2 ~41 ~30 ~6 ~41 cobblestone_wall 
setblock ~31 ~2 ~3 cobblestone_wall 0 
setblock ~31 ~2 ~8 cobblestone_wall 0 
setblock ~31 ~2 ~13 cobblestone_wall 0 
setblock ~31 ~2 ~30 cobblestone_wall 0 
setblock ~31 ~2 ~35 cobblestone_wall 0 
setblock ~31 ~2 ~40 cobblestone_wall 0 
setblock ~4 ~3 ~4 stone_stairs 3 
setblock ~4 ~3 ~7 stone_stairs 2 
setblock ~4 ~3 ~9 stone_stairs 3 
setblock ~4 ~3 ~12 stone_stairs 2 
setblock ~4 ~3 ~31 stone_stairs 3 
setblock ~4 ~3 ~34 stone_stairs 2 
setblock ~4 ~3 ~36 stone_stairs 3 
setblock ~4 ~3 ~39 stone_stairs 2 
setblock ~5 ~3 ~3 stone_stairs 1  
fill ~5 ~3 ~4 ~8 ~3 ~4 stone  
fill ~5 ~3 ~5 ~5 ~5 ~5 stone  
fill ~5 ~3 ~6 ~5 ~5 ~6 stone  
fill ~5 ~3 ~7 ~5 ~5 ~7 stone  
fill ~5 ~3 ~9 ~5 ~5 ~9 stone  
fill ~5 ~3 ~10 ~5 ~5 ~10 stone  
fill ~5 ~3 ~11 ~5 ~5 ~11 stone  
fill ~5 ~3 ~12 ~8 ~3 ~12 stone 
setblock ~5 ~3 ~13 stone_stairs 1 
setblock ~5 ~3 ~30 stone_stairs 1  
fill ~5 ~3 ~31 ~8 ~3 ~31 stone  
fill ~5 ~3 ~32 ~5 ~5 ~32 stone  
fill ~5 ~3 ~33 ~5 ~5 ~33 stone  
fill ~5 ~3 ~34 ~5 ~5 ~34 stone  
fill ~5 ~3 ~36 ~5 ~5 ~36 stone  
fill ~5 ~3 ~37 ~5 ~5 ~37 stone  
fill ~5 ~3 ~38 ~5 ~5 ~38 stone  
fill ~5 ~3 ~39 ~8 ~3 ~39 stone 
setblock ~5 ~3 ~40 stone_stairs 1 
setblock ~8 ~3 ~3 stone_stairs 0 
setblock ~8 ~3 ~13 stone_stairs 0 
setblock ~8 ~3 ~30 stone_stairs 0 
setblock ~8 ~3 ~40 stone_stairs 0 
setblock ~9 ~3 ~20 torch 5 
setblock ~9 ~3 ~23 torch 5 
setblock ~10 ~3 ~3 stone_stairs 1  
fill ~10 ~3 ~4 ~13 ~3 ~4 stone  
fill ~10 ~3 ~39 ~13 ~3 ~39 stone 
setblock ~10 ~3 ~40 stone_stairs 1 
setblock ~11 ~3 ~16 stone_stairs 3 
setblock ~11 ~3 ~19 stone_stairs 2  
fill ~11 ~3 ~21 ~11 ~6 ~21 cobblestone  
fill ~11 ~3 ~22 ~11 ~6 ~22 cobblestone 
setblock ~11 ~3 ~24 stone_stairs 3 
setblock ~11 ~3 ~27 stone_stairs 2  
fill ~12 ~3 ~16 ~12 ~4 ~16 stone  
fill ~12 ~3 ~17 ~12 ~5 ~17 stone  
fill ~12 ~3 ~18 ~12 ~5 ~18 stone  
fill ~12 ~3 ~19 ~12 ~4 ~19 stone  
fill ~12 ~3 ~24 ~12 ~4 ~24 stone  
fill ~12 ~3 ~25 ~12 ~5 ~25 stone  
fill ~12 ~3 ~26 ~12 ~5 ~26 stone  
fill ~12 ~3 ~27 ~12 ~4 ~27 stone 
setblock ~13 ~3 ~3 stone_stairs 0 
setblock ~13 ~3 ~40 stone_stairs 0 
setblock ~15 ~3 ~3 stone_stairs 1  
fill ~15 ~3 ~4 ~18 ~3 ~4 stone  
fill ~15 ~3 ~39 ~18 ~3 ~39 stone 
setblock ~15 ~3 ~40 stone_stairs 1 
setblock ~18 ~3 ~3 stone_stairs 0 
setblock ~18 ~3 ~40 stone_stairs 0 
setblock ~20 ~3 ~3 stone_stairs 1  
fill ~20 ~3 ~4 ~23 ~3 ~4 stone  
fill ~20 ~3 ~39 ~23 ~3 ~39 stone 
setblock ~20 ~3 ~40 stone_stairs 1 
setblock ~23 ~3 ~3 stone_stairs 0 
setblock ~23 ~3 ~40 stone_stairs 0 
setblock ~25 ~3 ~3 stone_stairs 1  
fill ~25 ~3 ~4 ~28 ~3 ~4 stone  
fill ~25 ~3 ~39 ~28 ~3 ~39 stone 
setblock ~25 ~3 ~40 stone_stairs 1  
fill ~27 ~3 ~15 ~27 ~5 ~15 stone  
fill ~27 ~3 ~16 ~27 ~5 ~16 stone  
fill ~27 ~3 ~17 ~27 ~5 ~17 stone  
fill ~27 ~3 ~18 ~27 ~5 ~18 stone  
fill ~27 ~3 ~20 ~27 ~5 ~20 stone  
fill ~27 ~3 ~21 ~27 ~5 ~21 stone  
fill ~27 ~3 ~22 ~27 ~5 ~22 stone  
fill ~27 ~3 ~23 ~27 ~5 ~23 stone  
fill ~27 ~3 ~25 ~27 ~5 ~25 stone  
fill ~27 ~3 ~26 ~27 ~5 ~26 stone  
fill ~27 ~3 ~27 ~27 ~5 ~27 stone  
fill ~27 ~3 ~28 ~27 ~5 ~28 stone 
setblock ~28 ~3 ~3 stone_stairs 0  
fill ~28 ~3 ~5 ~28 ~5 ~5 stone  
fill ~28 ~3 ~6 ~28 ~5 ~6 stone  
fill ~28 ~3 ~7 ~28 ~5 ~7 stone  
fill ~28 ~3 ~9 ~28 ~5 ~9 stone  
fill ~28 ~3 ~10 ~28 ~5 ~10 stone  
fill ~28 ~3 ~11 ~28 ~5 ~11 stone  
fill ~28 ~3 ~12 ~28 ~5 ~12 stone 
setblock ~28 ~3 ~15 stone_stairs 3 
setblock ~28 ~3 ~18 stone_stairs 2 
setblock ~28 ~3 ~20 stone_stairs 3 
setblock ~28 ~3 ~23 stone_stairs 2 
setblock ~28 ~3 ~25 stone_stairs 3 
setblock ~28 ~3 ~28 stone_stairs 2  
fill ~28 ~3 ~31 ~28 ~5 ~31 stone  
fill ~28 ~3 ~32 ~28 ~5 ~32 stone  
fill ~28 ~3 ~33 ~28 ~5 ~33 stone  
fill ~28 ~3 ~34 ~28 ~5 ~34 stone  
fill ~28 ~3 ~36 ~28 ~5 ~36 stone  
fill ~28 ~3 ~37 ~28 ~5 ~37 stone  
fill ~28 ~3 ~38 ~28 ~5 ~38 stone 
setblock ~28 ~3 ~40 stone_stairs 0 
setblock ~29 ~3 ~4 stone_stairs 3 
setblock ~29 ~3 ~7 stone_stairs 2 
setblock ~29 ~3 ~9 stone_stairs 3 
setblock ~29 ~3 ~12 stone_stairs 2 
setblock ~29 ~3 ~31 stone_stairs 3 
setblock ~29 ~3 ~34 stone_stairs 2 
setblock ~29 ~3 ~36 stone_stairs 3 
setblock ~29 ~3 ~39 stone_stairs 2  
fill ~4 ~4 ~4 ~4 ~6 ~4 cobblestone  
fill ~4 ~4 ~7 ~4 ~6 ~7 cobblestone  
fill ~4 ~4 ~9 ~4 ~6 ~9 cobblestone  
fill ~4 ~4 ~12 ~4 ~6 ~12 cobblestone  
fill ~4 ~4 ~31 ~4 ~6 ~31 cobblestone  
fill ~4 ~4 ~34 ~4 ~6 ~34 cobblestone  
fill ~4 ~4 ~36 ~4 ~6 ~36 cobblestone  
fill ~4 ~4 ~39 ~4 ~6 ~39 cobblestone  
fill ~5 ~4 ~3 ~5 ~6 ~3 cobblestone  
fill ~5 ~4 ~4 ~8 ~4 ~4 stone  
fill ~5 ~4 ~12 ~8 ~4 ~12 stone  
fill ~5 ~4 ~13 ~5 ~6 ~13 cobblestone  
fill ~5 ~4 ~30 ~5 ~6 ~30 cobblestone  
fill ~5 ~4 ~31 ~8 ~4 ~31 stone  
fill ~5 ~4 ~39 ~8 ~4 ~39 stone  
fill ~5 ~4 ~40 ~5 ~6 ~40 cobblestone  
fill ~8 ~4 ~3 ~8 ~6 ~3 cobblestone  
fill ~8 ~4 ~13 ~8 ~6 ~13 cobblestone  
fill ~8 ~4 ~30 ~8 ~6 ~30 cobblestone  
fill ~8 ~4 ~40 ~8 ~6 ~40 cobblestone  
fill ~10 ~4 ~3 ~10 ~6 ~3 cobblestone  
fill ~10 ~4 ~4 ~13 ~4 ~4 stone  
fill ~10 ~4 ~21 ~10 ~5 ~21 stone_brick_stairs  
fill ~10 ~4 ~22 ~10 ~5 ~22 stone_brick_stairs  
fill ~10 ~4 ~39 ~13 ~4 ~39 stone  
fill ~10 ~4 ~40 ~10 ~6 ~40 cobblestone  
fill ~11 ~4 ~16 ~11 ~6 ~16 cobblestone  
fill ~11 ~4 ~19 ~11 ~6 ~19 cobblestone  
fill ~11 ~4 ~24 ~11 ~6 ~24 cobblestone  
fill ~11 ~4 ~27 ~11 ~6 ~27 cobblestone  
fill ~13 ~4 ~3 ~13 ~6 ~3 cobblestone  
fill ~13 ~4 ~40 ~13 ~6 ~40 cobblestone  
fill ~15 ~4 ~3 ~15 ~6 ~3 cobblestone  
fill ~15 ~4 ~4 ~18 ~4 ~4 stone  
fill ~15 ~4 ~39 ~18 ~4 ~39 stone  
fill ~15 ~4 ~40 ~15 ~6 ~40 cobblestone  
fill ~18 ~4 ~3 ~18 ~6 ~3 cobblestone  
fill ~18 ~4 ~40 ~18 ~6 ~40 cobblestone  
fill ~20 ~4 ~3 ~20 ~6 ~3 cobblestone  
fill ~20 ~4 ~4 ~23 ~4 ~4 stone  
fill ~20 ~4 ~39 ~23 ~4 ~39 stone  
fill ~20 ~4 ~40 ~20 ~6 ~40 cobblestone  
fill ~23 ~4 ~3 ~23 ~6 ~3 cobblestone  
fill ~23 ~4 ~40 ~23 ~6 ~40 cobblestone  
fill ~25 ~4 ~3 ~25 ~6 ~3 cobblestone  
fill ~25 ~4 ~4 ~28 ~4 ~4 stone  
fill ~25 ~4 ~39 ~28 ~4 ~39 stone  
fill ~25 ~4 ~40 ~25 ~6 ~40 cobblestone  
fill ~28 ~4 ~3 ~28 ~6 ~3 cobblestone  
fill ~28 ~4 ~15 ~28 ~6 ~15 cobblestone  
fill ~28 ~4 ~18 ~28 ~6 ~18 cobblestone  
fill ~28 ~4 ~20 ~28 ~6 ~20 cobblestone  
fill ~28 ~4 ~23 ~28 ~6 ~23 cobblestone  
fill ~28 ~4 ~25 ~28 ~6 ~25 cobblestone  
fill ~28 ~4 ~28 ~28 ~6 ~28 cobblestone  
fill ~28 ~4 ~40 ~28 ~6 ~40 cobblestone  
fill ~29 ~4 ~4 ~29 ~6 ~4 cobblestone  
fill ~29 ~4 ~7 ~29 ~6 ~7 cobblestone  
fill ~29 ~4 ~9 ~29 ~6 ~9 cobblestone  
fill ~29 ~4 ~12 ~29 ~6 ~12 cobblestone  
fill ~29 ~4 ~31 ~29 ~6 ~31 cobblestone  
fill ~29 ~4 ~34 ~29 ~6 ~34 cobblestone  
fill ~29 ~4 ~36 ~29 ~6 ~36 cobblestone  
fill ~29 ~4 ~39 ~29 ~6 ~39 cobblestone 
setblock ~2 ~5 ~3 stone_brick_stairs 0 
setblock ~2 ~5 ~8 stone_brick_stairs 0 
setblock ~2 ~5 ~13 stone_brick_stairs 0 
setblock ~2 ~5 ~30 stone_brick_stairs 0 
setblock ~2 ~5 ~35 stone_brick_stairs 0 
setblock ~2 ~5 ~40 stone_brick_stairs 0 
setblock ~3 ~5 ~4 stone_slab 13 
setblock ~3 ~5 ~7 stone_slab 13 
setblock ~3 ~5 ~9 stone_slab 13 
setblock ~3 ~5 ~12 stone_slab 13 
setblock ~3 ~5 ~31 stone_slab 13 
setblock ~3 ~5 ~34 stone_slab 13 
setblock ~3 ~5 ~36 stone_slab 13 
setblock ~3 ~5 ~39 stone_slab 13 
setblock ~4 ~5 ~1 stone_brick_stairs 2 
setblock ~4 ~5 ~5 stone_stairs 7 
setblock ~4 ~5 ~6 stone_stairs 6 
setblock ~4 ~5 ~10 stone_stairs 7 
setblock ~4 ~5 ~11 stone_stairs 6 
setblock ~4 ~5 ~15 stone_brick_stairs 3 
setblock ~4 ~5 ~28 stone_brick_stairs 2 
setblock ~4 ~5 ~32 stone_stairs 7 
setblock ~4 ~5 ~33 stone_stairs 6 
setblock ~4 ~5 ~37 stone_stairs 7 
setblock ~4 ~5 ~38 stone_stairs 6 
setblock ~4 ~5 ~42 stone_brick_stairs 3 
setblock ~5 ~5 ~2 stone_slab 13  
fill ~5 ~5 ~4 ~8 ~5 ~4 stone  
fill ~5 ~5 ~12 ~7 ~5 ~12 stone 
setblock ~5 ~5 ~14 stone_slab 13 
setblock ~5 ~5 ~29 stone_slab 13  
fill ~5 ~5 ~31 ~7 ~5 ~31 stone  
fill ~5 ~5 ~39 ~8 ~5 ~39 stone 
setblock ~5 ~5 ~41 stone_slab 13 
setblock ~6 ~5 ~3 stone_stairs 5 
setblock ~6 ~5 ~13 stone_stairs 5 
setblock ~6 ~5 ~30 stone_stairs 5 
setblock ~6 ~5 ~40 stone_stairs 5 
setblock ~7 ~5 ~3 stone_stairs 4 
setblock ~7 ~5 ~13 stone_stairs 4 
setblock ~7 ~5 ~30 stone_stairs 4 
setblock ~7 ~5 ~40 stone_stairs 4 
setblock ~8 ~5 ~2 stone_slab 13 
setblock ~8 ~5 ~14 stone_slab 13 
setblock ~8 ~5 ~29 stone_slab 13 
setblock ~8 ~5 ~41 stone_slab 13 
setblock ~9 ~5 ~1 stone_brick_stairs 2 
setblock ~9 ~5 ~20 stone_brick_stairs 0 
setblock ~9 ~5 ~23 stone_brick_stairs 0 
setblock ~9 ~5 ~42 stone_brick_stairs 3 
setblock ~10 ~5 ~2 stone_slab 13  
fill ~10 ~5 ~4 ~13 ~5 ~4 stone 
setblock ~10 ~5 ~16 stone_slab 13 
setblock ~10 ~5 ~19 stone_slab 13 
setblock ~10 ~5 ~24 stone_slab 13 
setblock ~10 ~5 ~27 stone_slab 13  
fill ~10 ~5 ~39 ~13 ~5 ~39 stone 
setblock ~10 ~5 ~41 stone_slab 13 
setblock ~11 ~5 ~3 stone_stairs 5 
setblock ~11 ~5 ~17 stone_stairs 7 
setblock ~11 ~5 ~18 stone_stairs 6 
setblock ~11 ~5 ~25 stone_stairs 7 
setblock ~11 ~5 ~26 stone_stairs 6 
setblock ~11 ~5 ~40 stone_stairs 5 
setblock ~12 ~5 ~3 stone_stairs 4 
setblock ~12 ~5 ~40 stone_stairs 4 
setblock ~13 ~5 ~2 stone_slab 13 
setblock ~13 ~5 ~41 stone_slab 13 
setblock ~14 ~5 ~1 stone_brick_stairs 2 
setblock ~14 ~5 ~42 stone_brick_stairs 3 
setblock ~15 ~5 ~2 stone_slab 13  
fill ~15 ~5 ~4 ~18 ~5 ~4 stone  
fill ~15 ~5 ~39 ~18 ~5 ~39 stone 
setblock ~15 ~5 ~41 stone_slab 13 
setblock ~16 ~5 ~3 stone_stairs 5 
setblock ~16 ~5 ~40 stone_stairs 5 
setblock ~17 ~5 ~3 stone_stairs 4 
setblock ~17 ~5 ~40 stone_stairs 4 
setblock ~18 ~5 ~2 stone_slab 13 
setblock ~18 ~5 ~41 stone_slab 13 
setblock ~19 ~5 ~1 stone_brick_stairs 2 
setblock ~19 ~5 ~42 stone_brick_stairs 3 
setblock ~20 ~5 ~2 stone_slab 13  
fill ~20 ~5 ~4 ~23 ~5 ~4 stone  
fill ~20 ~5 ~39 ~23 ~5 ~39 stone 
setblock ~20 ~5 ~41 stone_slab 13 
setblock ~21 ~5 ~3 stone_stairs 5 
setblock ~21 ~5 ~40 stone_stairs 5 
setblock ~22 ~5 ~3 stone_stairs 4 
setblock ~22 ~5 ~40 stone_stairs 4 
setblock ~23 ~5 ~2 stone_slab 13 
setblock ~23 ~5 ~41 stone_slab 13 
setblock ~24 ~5 ~1 stone_brick_stairs 2 
setblock ~24 ~5 ~42 stone_brick_stairs 3 
setblock ~25 ~5 ~2 stone_slab 13  
fill ~25 ~5 ~4 ~28 ~5 ~4 stone  
fill ~25 ~5 ~39 ~28 ~5 ~39 stone 
setblock ~25 ~5 ~41 stone_slab 13 
setblock ~26 ~5 ~3 stone_stairs 5 
setblock ~26 ~5 ~40 stone_stairs 5 
setblock ~27 ~5 ~3 stone_stairs 4 
setblock ~27 ~5 ~40 stone_stairs 4 
setblock ~28 ~5 ~2 stone_slab 13 
setblock ~28 ~5 ~16 stone_stairs 7 
setblock ~28 ~5 ~17 stone_stairs 6 
setblock ~28 ~5 ~21 stone_stairs 7 
setblock ~28 ~5 ~22 stone_stairs 6 
setblock ~28 ~5 ~26 stone_stairs 7 
setblock ~28 ~5 ~27 stone_stairs 6 
setblock ~28 ~5 ~41 stone_slab 13 
setblock ~29 ~5 ~1 stone_brick_stairs 2 
setblock ~29 ~5 ~5 stone_stairs 7 
setblock ~29 ~5 ~6 stone_stairs 6 
setblock ~29 ~5 ~10 stone_stairs 7 
setblock ~29 ~5 ~11 stone_stairs 6 
setblock ~29 ~5 ~15 stone_slab 13 
setblock ~29 ~5 ~18 stone_slab 13 
setblock ~29 ~5 ~20 stone_slab 13 
setblock ~29 ~5 ~23 stone_slab 13 
setblock ~29 ~5 ~25 stone_slab 13 
setblock ~29 ~5 ~28 stone_slab 13 
setblock ~29 ~5 ~32 stone_stairs 7 
setblock ~29 ~5 ~33 stone_stairs 6 
setblock ~29 ~5 ~37 stone_stairs 7 
setblock ~29 ~5 ~38 stone_stairs 6 
setblock ~29 ~5 ~42 stone_brick_stairs 3 
setblock ~30 ~5 ~4 stone_slab 13 
setblock ~30 ~5 ~7 stone_slab 13 
setblock ~30 ~5 ~9 stone_slab 13 
setblock ~30 ~5 ~12 stone_slab 13 
setblock ~30 ~5 ~19 stone_brick_stairs 1 
setblock ~30 ~5 ~24 stone_brick_stairs 1 
setblock ~30 ~5 ~31 stone_slab 13 
setblock ~30 ~5 ~34 stone_slab 13 
setblock ~30 ~5 ~36 stone_slab 13 
setblock ~30 ~5 ~39 stone_slab 13 
setblock ~31 ~5 ~3 stone_brick_stairs 1 
setblock ~31 ~5 ~8 stone_brick_stairs 1 
setblock ~31 ~5 ~13 stone_brick_stairs 1 
setblock ~31 ~5 ~30 stone_brick_stairs 1 
setblock ~31 ~5 ~35 stone_brick_stairs 1 
setblock ~31 ~5 ~40 stone_brick_stairs 1 
setblock ~2 ~6 ~3 stone_brick_stairs 4 
setblock ~2 ~6 ~8 stone_brick_stairs 4 
setblock ~2 ~6 ~13 stone_brick_stairs 4 
setblock ~2 ~6 ~30 stone_brick_stairs 4 
setblock ~2 ~6 ~35 stone_brick_stairs 4 
setblock ~2 ~6 ~40 stone_brick_stairs 4 
setblock ~3 ~6 ~4 stone_brick_stairs 7 
setblock ~3 ~6 ~7 stone_brick_stairs 6 
setblock ~3 ~6 ~9 stone_brick_stairs 7 
setblock ~3 ~6 ~12 stone_brick_stairs 6 
setblock ~3 ~6 ~31 stone_brick_stairs 7 
setblock ~3 ~6 ~34 stone_brick_stairs 6 
setblock ~3 ~6 ~36 stone_brick_stairs 7 
setblock ~3 ~6 ~39 stone_brick_stairs 6 
setblock ~4 ~6 ~1 stone_brick_stairs 6  
fill ~4 ~6 ~5 ~4 ~6 ~13 cobblestone 
setblock ~4 ~6 ~15 stone_brick_stairs 7 
setblock ~4 ~6 ~28 stone_brick_stairs 6  
fill ~4 ~6 ~32 ~4 ~6 ~40 cobblestone 
setblock ~4 ~6 ~42 stone_brick_stairs 7 
setblock ~5 ~6 ~2 stone_brick_stairs 5 
setblock ~5 ~6 ~14 stone_brick_stairs 5 
setblock ~5 ~6 ~29 stone_brick_stairs 5  

KittysCommands:  
setblock ~5 ~6 ~41 stone_brick_stairs 5  
fill ~6 ~6 ~3 ~29 ~6 ~3 cobblestone  
fill ~6 ~6 ~13 ~8 ~6 ~13 cobblestone  
fill ~6 ~6 ~30 ~8 ~6 ~30 cobblestone  
fill ~6 ~6 ~40 ~29 ~6 ~40 cobblestone 
setblock ~8 ~6 ~2 stone_brick_stairs 4 
setblock ~8 ~6 ~14 stone_brick_stairs 4 
setblock ~8 ~6 ~29 stone_brick_stairs 4 
setblock ~8 ~6 ~41 stone_brick_stairs 4 
setblock ~9 ~6 ~1 stone_brick_stairs 6 
setblock ~9 ~6 ~20 stone_brick_stairs 4 
setblock ~9 ~6 ~23 stone_brick_stairs 4 
setblock ~9 ~6 ~42 stone_brick_stairs 7 
setblock ~10 ~6 ~2 stone_brick_stairs 5 
setblock ~10 ~6 ~16 stone_brick_stairs 7 
setblock ~10 ~6 ~19 stone_brick_stairs 6  
fill ~10 ~6 ~21 ~10 ~6 ~22 cobblestone_wall 
setblock ~10 ~6 ~24 stone_brick_stairs 7 
setblock ~10 ~6 ~27 stone_brick_stairs 6 
setblock ~10 ~6 ~41 stone_brick_stairs 5  
fill ~11 ~6 ~17 ~11 ~6 ~19 cobblestone  
fill ~11 ~6 ~25 ~11 ~6 ~27 cobblestone 
setblock ~13 ~6 ~2 stone_brick_stairs 4 
setblock ~13 ~6 ~41 stone_brick_stairs 4 
setblock ~14 ~6 ~1 stone_brick_stairs 6 
setblock ~14 ~6 ~42 stone_brick_stairs 7 
setblock ~15 ~6 ~2 stone_brick_stairs 5 
setblock ~15 ~6 ~41 stone_brick_stairs 5 
setblock ~18 ~6 ~2 stone_brick_stairs 4 
setblock ~18 ~6 ~41 stone_brick_stairs 4 
setblock ~19 ~6 ~1 stone_brick_stairs 6 
setblock ~19 ~6 ~42 stone_brick_stairs 7 
setblock ~20 ~6 ~2 stone_brick_stairs 5 
setblock ~20 ~6 ~41 stone_brick_stairs 5 
setblock ~23 ~6 ~2 stone_brick_stairs 4 
setblock ~23 ~6 ~41 stone_brick_stairs 4 
setblock ~24 ~6 ~1 stone_brick_stairs 6 
setblock ~24 ~6 ~42 stone_brick_stairs 7 
setblock ~25 ~6 ~2 stone_brick_stairs 5 
setblock ~25 ~6 ~41 stone_brick_stairs 5 
setblock ~28 ~6 ~2 stone_brick_stairs 4  
fill ~28 ~6 ~16 ~28 ~6 ~29 cobblestone 
setblock ~28 ~6 ~41 stone_brick_stairs 4 
setblock ~29 ~6 ~1 stone_brick_stairs 6  
fill ~29 ~6 ~5 ~29 ~6 ~13 cobblestone 
setblock ~29 ~6 ~15 stone_brick_stairs 7 
setblock ~29 ~6 ~18 stone_brick_stairs 6 
setblock ~29 ~6 ~20 stone_brick_stairs 7 
setblock ~29 ~6 ~23 stone_brick_stairs 6 
setblock ~29 ~6 ~25 stone_brick_stairs 7 
setblock ~29 ~6 ~28 stone_brick_stairs 6  
fill ~29 ~6 ~32 ~29 ~6 ~40 cobblestone 
setblock ~29 ~6 ~42 stone_brick_stairs 7 
setblock ~30 ~6 ~4 stone_brick_stairs 7 
setblock ~30 ~6 ~7 stone_brick_stairs 6 
setblock ~30 ~6 ~9 stone_brick_stairs 7 
setblock ~30 ~6 ~12 stone_brick_stairs 6 
setblock ~30 ~6 ~19 stone_brick_stairs 5 
setblock ~30 ~6 ~24 stone_brick_stairs 5 
setblock ~30 ~6 ~31 stone_brick_stairs 7 
setblock ~30 ~6 ~34 stone_brick_stairs 6 
setblock ~30 ~6 ~36 stone_brick_stairs 7 
setblock ~30 ~6 ~39 stone_brick_stairs 6 
setblock ~31 ~6 ~3 stone_brick_stairs 5 
setblock ~31 ~6 ~8 stone_brick_stairs 5 
setblock ~31 ~6 ~13 stone_brick_stairs 5 
setblock ~31 ~6 ~30 stone_brick_stairs 5 
setblock ~31 ~6 ~35 stone_brick_stairs 5 
setblock ~31 ~6 ~40 stone_brick_stairs 5 
setblock ~1 ~7 ~8 stone_brick_stairs 4 
setblock ~1 ~7 ~35 stone_brick_stairs 4 
setblock ~2 ~7 ~2 stone_brick_stairs 6 
setblock ~2 ~7 ~3 double_stone_slab 5 
setblock ~2 ~7 ~4 stone_slab 13 
setblock ~2 ~7 ~7 stone_slab 13 
setblock ~2 ~7 ~8 double_stone_slab 5 
setblock ~2 ~7 ~9 stone_slab 13 
setblock ~2 ~7 ~12 stone_slab 13 
setblock ~2 ~7 ~13 double_stone_slab 5 
setblock ~2 ~7 ~14 stone_brick_stairs 7 
setblock ~2 ~7 ~29 stone_brick_stairs 6 
setblock ~2 ~7 ~30 double_stone_slab 5 
setblock ~2 ~7 ~31 stone_slab 13 
setblock ~2 ~7 ~34 stone_slab 13 
setblock ~2 ~7 ~35 double_stone_slab 5 
setblock ~2 ~7 ~36 stone_slab 13 
setblock ~2 ~7 ~39 stone_slab 13 
setblock ~2 ~7 ~40 double_stone_slab 5 
setblock ~2 ~7 ~41 stone_brick_stairs 7 
setblock ~2 ~7 ~42 stone_slab 13 
setblock ~3 ~7 ~1 stone_brick_stairs 4 
setblock ~3 ~7 ~2 stonebrick 0  
fill ~3 ~7 ~4 ~30 ~7 ~4 stonebrick  
fill ~3 ~7 ~5 ~30 ~7 ~5 stonebrick  
fill ~3 ~7 ~6 ~30 ~7 ~6 stonebrick  
fill ~3 ~7 ~7 ~30 ~7 ~7 stonebrick  
fill ~3 ~7 ~9 ~30 ~7 ~9 stonebrick  
fill ~3 ~7 ~10 ~30 ~7 ~10 stonebrick  
fill ~3 ~7 ~11 ~30 ~7 ~11 stonebrick  
fill ~3 ~7 ~12 ~30 ~7 ~12 stonebrick 
setblock ~3 ~7 ~14 stonebrick 0 
setblock ~3 ~7 ~15 stone_brick_stairs 4 
setblock ~3 ~7 ~28 stone_brick_stairs 4 
setblock ~3 ~7 ~29 stonebrick 0  
fill ~3 ~7 ~31 ~30 ~7 ~31 stonebrick  
fill ~3 ~7 ~32 ~30 ~7 ~32 stonebrick  
fill ~3 ~7 ~33 ~30 ~7 ~33 stonebrick  
fill ~3 ~7 ~34 ~30 ~7 ~34 stonebrick  
fill ~3 ~7 ~36 ~30 ~7 ~36 stonebrick  
fill ~3 ~7 ~37 ~30 ~7 ~37 stonebrick  
fill ~3 ~7 ~38 ~30 ~7 ~38 stonebrick  
fill ~3 ~7 ~39 ~30 ~7 ~39 stonebrick 
setblock ~3 ~7 ~41 stonebrick 0 
setblock ~3 ~7 ~42 stone_brick_stairs 4 
setblock ~4 ~7 ~1 double_stone_slab 5  
fill ~4 ~7 ~3 ~30 ~7 ~3 stonebrick  
fill ~4 ~7 ~8 ~31 ~7 ~8 stonebrick  
fill ~4 ~7 ~13 ~30 ~7 ~13 stonebrick 
setblock ~4 ~7 ~15 double_stone_slab 5 
setblock ~4 ~7 ~28 double_stone_slab 5  
fill ~4 ~7 ~30 ~30 ~7 ~30 stonebrick  
fill ~4 ~7 ~35 ~31 ~7 ~35 stonebrick  
fill ~4 ~7 ~40 ~30 ~7 ~40 stonebrick 
setblock ~4 ~7 ~42 double_stone_slab 5 
setblock ~5 ~7 ~1 stone_slab 13  
fill ~5 ~7 ~2 ~30 ~7 ~2 stonebrick  
fill ~5 ~7 ~14 ~29 ~7 ~14 stonebrick 
setblock ~5 ~7 ~15 stone_slab 13 
setblock ~5 ~7 ~28 stone_slab 13  
fill ~5 ~7 ~29 ~29 ~7 ~29 stonebrick  
fill ~5 ~7 ~41 ~30 ~7 ~41 stonebrick 
setblock ~5 ~7 ~42 stone_slab 13 
setblock ~8 ~7 ~1 stone_slab 13 
setblock ~8 ~7 ~15 stone_slab 13 
setblock ~8 ~7 ~28 stone_slab 13 
setblock ~8 ~7 ~42 stone_slab 13 
setblock ~9 ~7 ~1 double_stone_slab 5 
setblock ~9 ~7 ~15 double_stone_slab 5 
setblock ~9 ~7 ~16 stone_slab 13 
setblock ~9 ~7 ~19 stone_slab 13 
setblock ~9 ~7 ~20 double_stone_slab 5  
fill ~9 ~7 ~21 ~9 ~7 ~22 stone_slab 
setblock ~9 ~7 ~23 double_stone_slab 5 
setblock ~9 ~7 ~24 stone_slab 13 
setblock ~9 ~7 ~27 stone_slab 13 
setblock ~9 ~7 ~28 double_stone_slab 5 
setblock ~9 ~7 ~42 double_stone_slab 5 
setblock ~10 ~7 ~1 stone_slab 13  
fill ~10 ~7 ~16 ~29 ~7 ~16 stonebrick  
fill ~10 ~7 ~17 ~29 ~7 ~17 stonebrick  
fill ~10 ~7 ~18 ~29 ~7 ~18 stonebrick  
fill ~10 ~7 ~19 ~29 ~7 ~19 stonebrick  
fill ~10 ~7 ~21 ~29 ~7 ~21 stonebrick  
fill ~10 ~7 ~22 ~29 ~7 ~22 stonebrick  
fill ~10 ~7 ~24 ~29 ~7 ~24 stonebrick  
fill ~10 ~7 ~25 ~29 ~7 ~25 stonebrick  
fill ~10 ~7 ~26 ~29 ~7 ~26 stonebrick  
fill ~10 ~7 ~27 ~29 ~7 ~27 stonebrick 
setblock ~10 ~7 ~42 stone_slab 13  
fill ~11 ~7 ~15 ~29 ~7 ~15 stonebrick  
fill ~11 ~7 ~20 ~29 ~7 ~20 stonebrick  
fill ~11 ~7 ~23 ~29 ~7 ~23 stonebrick  
fill ~11 ~7 ~28 ~29 ~7 ~28 stonebrick 
setblock ~13 ~7 ~1 stone_slab 13 
setblock ~13 ~7 ~42 stone_slab 13 
setblock ~14 ~7 ~1 double_stone_slab 5 
setblock ~14 ~7 ~42 double_stone_slab 5 
setblock ~15 ~7 ~1 stone_slab 13 
setblock ~15 ~7 ~42 stone_slab 13 
setblock ~18 ~7 ~1 stone_slab 13 
setblock ~18 ~7 ~42 stone_slab 13 
setblock ~19 ~7 ~1 double_stone_slab 5 
setblock ~19 ~7 ~42 double_stone_slab 5 
setblock ~20 ~7 ~1 stone_slab 13 
setblock ~20 ~7 ~42 stone_slab 13 
setblock ~23 ~7 ~1 stone_slab 13 
setblock ~23 ~7 ~42 stone_slab 13 
setblock ~24 ~7 ~1 double_stone_slab 5 
setblock ~24 ~7 ~42 double_stone_slab 5 
setblock ~25 ~7 ~1 stone_slab 13 
setblock ~25 ~7 ~42 stone_slab 13 
setblock ~28 ~7 ~1 stone_slab 13 
setblock ~28 ~7 ~42 stone_slab 13 
setblock ~29 ~7 ~1 double_stone_slab 5 
setblock ~29 ~7 ~42 double_stone_slab 5 
setblock ~30 ~7 ~1 stone_brick_stairs 5 
setblock ~30 ~7 ~14 double_stone_slab 5 
setblock ~30 ~7 ~15 stone_slab 13 
setblock ~30 ~7 ~18 stone_slab 13 
setblock ~30 ~7 ~19 double_stone_slab 5 
setblock ~30 ~7 ~20 stone_slab 13 
setblock ~30 ~7 ~23 stone_slab 13 
setblock ~30 ~7 ~24 double_stone_slab 5 
setblock ~30 ~7 ~25 stone_slab 13 
setblock ~30 ~7 ~28 stone_slab 13 
setblock ~30 ~7 ~29 double_stone_slab 5 
setblock ~30 ~7 ~42 stone_brick_stairs 5 
setblock ~31 ~7 ~2 stone_brick_stairs 6 
setblock ~31 ~7 ~3 double_stone_slab 5 
setblock ~31 ~7 ~4 stone_slab 13 
setblock ~31 ~7 ~7 stone_slab 13 
setblock ~31 ~7 ~9 stone_slab 13 
setblock ~31 ~7 ~12 stone_slab 13 
setblock ~31 ~7 ~13 double_stone_slab 5 
setblock ~31 ~7 ~14 stone_slab 13 
setblock ~31 ~7 ~29 stone_slab 13 
setblock ~31 ~7 ~30 double_stone_slab 5 
setblock ~31 ~7 ~31 stone_slab 13 
setblock ~31 ~7 ~34 stone_slab 13 
setblock ~31 ~7 ~36 stone_slab 13 
setblock ~31 ~7 ~39 stone_slab 13 
setblock ~31 ~7 ~40 double_stone_slab 5 
setblock ~31 ~7 ~41 stone_brick_stairs 7 
setblock ~32 ~7 ~8 stone_brick_stairs 5 
setblock ~32 ~7 ~35 stone_brick_stairs 5 
setblock ~1 ~8 ~8 stone_brick_stairs 0 
setblock ~1 ~8 ~35 stone_brick_stairs 0  
fill ~2 ~8 ~1 ~2 ~10 ~1 stonebrick  
fill ~2 ~8 ~2 ~2 ~8 ~7 stone_brick_stairs  
fill ~2 ~8 ~8 ~2 ~9 ~8 stonebrick  
fill ~2 ~8 ~9 ~2 ~8 ~14 stone_brick_stairs  
fill ~2 ~8 ~15 ~2 ~9 ~15 stonebrick  
fill ~2 ~8 ~28 ~2 ~9 ~28 stonebrick  
fill ~2 ~8 ~29 ~2 ~8 ~34 stone_brick_stairs  
fill ~2 ~8 ~35 ~2 ~9 ~35 stonebrick  
fill ~2 ~8 ~36 ~2 ~8 ~41 stone_brick_stairs  
fill ~2 ~8 ~42 ~2 ~10 ~42 stonebrick  
fill ~3 ~8 ~1 ~16 ~8 ~1 stone_brick_stairs  
fill ~3 ~8 ~15 ~6 ~8 ~15 stone_brick_stairs  
fill ~3 ~8 ~28 ~6 ~8 ~28 stone_brick_stairs  
fill ~3 ~8 ~42 ~16 ~8 ~42 stone_brick_stairs  
fill ~4 ~8 ~3 ~4 ~15 ~3 log  
fill ~4 ~8 ~6 ~4 ~15 ~6 log  
fill ~4 ~8 ~10 ~4 ~15 ~10 log  
fill ~4 ~8 ~13 ~4 ~15 ~13 log  
fill ~4 ~8 ~30 ~4 ~15 ~30 log  
fill ~4 ~8 ~33 ~4 ~15 ~33 log  
fill ~4 ~8 ~37 ~4 ~15 ~37 log  
fill ~4 ~8 ~40 ~4 ~15 ~40 log  
fill ~5 ~8 ~4 ~28 ~8 ~4 wool  
fill ~5 ~8 ~5 ~5 ~15 ~5 wool  
fill ~5 ~8 ~6 ~5 ~15 ~6 wool  
fill ~5 ~8 ~7 ~5 ~15 ~7 wool  
fill ~5 ~8 ~8 ~5 ~11 ~8 wool  
fill ~5 ~8 ~9 ~5 ~15 ~9 wool  
fill ~5 ~8 ~10 ~5 ~15 ~10 wool  
fill ~5 ~8 ~11 ~5 ~15 ~11 wool  
fill ~5 ~8 ~12 ~5 ~11 ~12 wool  
fill ~5 ~8 ~31 ~5 ~11 ~31 wool  
fill ~5 ~8 ~32 ~5 ~15 ~32 wool  
fill ~5 ~8 ~33 ~5 ~15 ~33 wool  
fill ~5 ~8 ~34 ~5 ~15 ~34 wool  
fill ~5 ~8 ~35 ~5 ~11 ~35 wool  
fill ~5 ~8 ~36 ~5 ~15 ~36 wool  
fill ~5 ~8 ~37 ~5 ~15 ~37 wool  
fill ~5 ~8 ~38 ~5 ~15 ~38 wool  
fill ~5 ~8 ~39 ~28 ~8 ~39 wool  
fill ~6 ~8 ~3 ~6 ~15 ~3 log  
fill ~6 ~8 ~12 ~6 ~11 ~12 log  
fill ~6 ~8 ~31 ~6 ~11 ~31 log  
fill ~6 ~8 ~40 ~6 ~15 ~40 log  
fill ~7 ~8 ~12 ~8 ~8 ~12 wool  
fill ~7 ~8 ~15 ~8 ~8 ~15 stone_brick_stairs  
fill ~7 ~8 ~28 ~8 ~8 ~28 stone_brick_stairs  
fill ~7 ~8 ~31 ~8 ~8 ~31 wool  
fill ~9 ~8 ~12 ~9 ~11 ~12 log  
fill ~9 ~8 ~15 ~9 ~9 ~15 stonebrick  
fill ~9 ~8 ~16 ~9 ~8 ~21 stone_brick_stairs  
fill ~9 ~8 ~22 ~9 ~8 ~27 stone_brick_stairs  
fill ~9 ~8 ~28 ~9 ~9 ~28 stonebrick  
fill ~9 ~8 ~31 ~9 ~11 ~31 log  
fill ~10 ~8 ~3 ~10 ~15 ~3 log  
fill ~10 ~8 ~12 ~12 ~8 ~12 wool  
fill ~10 ~8 ~31 ~12 ~8 ~31 wool  
fill ~10 ~8 ~40 ~10 ~15 ~40 log  
fill ~11 ~8 ~13 ~11 ~15 ~13 log  
fill ~11 ~8 ~15 ~11 ~14 ~15 log  
fill ~11 ~8 ~19 ~11 ~14 ~19 log  
fill ~11 ~8 ~24 ~11 ~14 ~24 log  
fill ~11 ~8 ~28 ~11 ~14 ~28 log  
fill ~11 ~8 ~30 ~11 ~15 ~30 log  
fill ~12 ~8 ~13 ~12 ~15 ~13 wool  
fill ~12 ~8 ~14 ~12 ~15 ~14 wool  
fill ~12 ~8 ~15 ~12 ~15 ~15 wool  
fill ~12 ~8 ~16 ~12 ~15 ~16 wool  
fill ~12 ~8 ~17 ~12 ~11 ~17 wool  
fill ~12 ~8 ~18 ~12 ~15 ~18 wool  
fill ~12 ~8 ~19 ~12 ~15 ~19 wool  
fill ~12 ~8 ~20 ~12 ~15 ~20 wool  
fill ~12 ~8 ~21 ~12 ~11 ~21 wool  
fill ~12 ~8 ~22 ~12 ~11 ~22 wool  
fill ~12 ~8 ~23 ~12 ~15 ~23 wool  
fill ~12 ~8 ~24 ~12 ~15 ~24 wool  
fill ~12 ~8 ~25 ~12 ~15 ~25 wool  
fill ~12 ~8 ~26 ~12 ~11 ~26 wool  
fill ~12 ~8 ~27 ~12 ~15 ~27 wool  
fill ~12 ~8 ~28 ~12 ~15 ~28 wool  
fill ~12 ~8 ~29 ~12 ~15 ~29 wool  
fill ~12 ~8 ~30 ~12 ~15 ~30 wool  
fill ~14 ~8 ~3 ~14 ~15 ~3 log  
fill ~14 ~8 ~40 ~14 ~15 ~40 log  
fill ~17 ~8 ~1 ~30 ~8 ~1 stone_brick_stairs  
fill ~17 ~8 ~42 ~30 ~8 ~42 stone_brick_stairs  
fill ~19 ~8 ~3 ~19 ~15 ~3 log  
fill ~19 ~8 ~40 ~19 ~15 ~40 log  
fill ~23 ~8 ~3 ~23 ~15 ~3 log  
fill ~23 ~8 ~40 ~23 ~15 ~40 log  
fill ~27 ~8 ~3 ~27 ~15 ~3 log  
fill ~27 ~8 ~14 ~27 ~15 ~14 wool  
fill ~27 ~8 ~15 ~27 ~15 ~15 wool  
fill ~27 ~8 ~16 ~27 ~11 ~16 wool  
fill ~27 ~8 ~17 ~27 ~11 ~17 wool  
fill ~27 ~8 ~18 ~27 ~15 ~18 wool  
fill ~27 ~8 ~19 ~27 ~15 ~19 wool  
fill ~27 ~8 ~20 ~27 ~15 ~20 wool  
fill ~27 ~8 ~21 ~27 ~11 ~21 wool  
fill ~27 ~8 ~22 ~27 ~11 ~22 wool  
fill ~27 ~8 ~23 ~27 ~15 ~23 wool  
fill ~27 ~8 ~24 ~27 ~15 ~24 wool  
fill ~27 ~8 ~25 ~27 ~15 ~25 wool  
fill ~27 ~8 ~26 ~27 ~11 ~26 wool  
fill ~27 ~8 ~27 ~27 ~11 ~27 wool  
fill ~27 ~8 ~28 ~27 ~15 ~28 wool  
fill ~27 ~8 ~29 ~27 ~15 ~29 wool  
fill ~27 ~8 ~40 ~27 ~15 ~40 log  
fill ~28 ~8 ~5 ~28 ~11 ~5 wool  
fill ~28 ~8 ~6 ~28 ~15 ~6 wool  
fill ~28 ~8 ~7 ~28 ~15 ~7 wool  
fill ~28 ~8 ~8 ~28 ~15 ~8 wool  
fill ~28 ~8 ~9 ~28 ~15 ~9 wool  
fill ~28 ~8 ~10 ~28 ~15 ~10 wool  
fill ~28 ~8 ~11 ~28 ~11 ~11 wool  
fill ~28 ~8 ~12 ~28 ~15 ~12 wool  
fill ~28 ~8 ~13 ~28 ~15 ~13 wool  
fill ~28 ~8 ~14 ~28 ~15 ~14 log  
fill ~28 ~8 ~19 ~28 ~14 ~19 log  
fill ~28 ~8 ~24 ~28 ~14 ~24 log  
fill ~28 ~8 ~29 ~28 ~15 ~29 log  
fill ~28 ~8 ~30 ~28 ~15 ~30 wool  
fill ~28 ~8 ~31 ~28 ~15 ~31 wool  
fill ~28 ~8 ~32 ~28 ~11 ~32 wool  
fill ~28 ~8 ~33 ~28 ~15 ~33 wool  
fill ~28 ~8 ~34 ~28 ~15 ~34 wool  
fill ~28 ~8 ~35 ~28 ~15 ~35 wool  
fill ~28 ~8 ~36 ~28 ~15 ~36 wool  
fill ~28 ~8 ~37 ~28 ~15 ~37 wool  
fill ~28 ~8 ~38 ~28 ~11 ~38 wool  
fill ~29 ~8 ~3 ~29 ~15 ~3 log  
fill ~29 ~8 ~7 ~29 ~14 ~7 log  
fill ~29 ~8 ~9 ~29 ~14 ~9 log  
fill ~29 ~8 ~13 ~29 ~15 ~13 log  
fill ~29 ~8 ~30 ~29 ~15 ~30 log  
fill ~29 ~8 ~34 ~29 ~14 ~34 log  
fill ~29 ~8 ~36 ~29 ~14 ~36 log  
fill ~29 ~8 ~40 ~29 ~15 ~40 log  
fill ~30 ~8 ~14 ~31 ~8 ~14 stonebrick  
fill ~30 ~8 ~15 ~30 ~8 ~21 stone_brick_stairs  
fill ~30 ~8 ~22 ~30 ~8 ~28 stone_brick_stairs  
fill ~30 ~8 ~29 ~31 ~8 ~29 stonebrick  
fill ~31 ~8 ~1 ~31 ~10 ~1 stonebrick  
fill ~31 ~8 ~2 ~31 ~8 ~7 stone_brick_stairs  
fill ~31 ~8 ~8 ~31 ~9 ~8 stonebrick  
fill ~31 ~8 ~9 ~31 ~8 ~13 stone_brick_stairs  
fill ~31 ~8 ~30 ~31 ~8 ~34 stone_brick_stairs  
fill ~31 ~8 ~35 ~31 ~9 ~35 stonebrick  
fill ~31 ~8 ~36 ~31 ~8 ~41 stone_brick_stairs  
fill ~31 ~8 ~42 ~31 ~10 ~42 stonebrick 
setblock ~32 ~8 ~8 stone_brick_stairs 1 
setblock ~32 ~8 ~35 stone_brick_stairs 1 
setblock ~1 ~9 ~8 stone_brick_stairs 4 
setblock ~1 ~9 ~35 stone_brick_stairs 4  
fill ~2 ~9 ~2 ~2 ~9 ~7 stone_brick_stairs  
fill ~2 ~9 ~9 ~2 ~9 ~14 stone_brick_stairs  
fill ~2 ~9 ~29 ~2 ~9 ~34 stone_brick_stairs  
fill ~2 ~9 ~36 ~2 ~9 ~41 stone_brick_stairs  
fill ~3 ~9 ~1 ~16 ~9 ~1 stone_brick_stairs  
fill ~3 ~9 ~15 ~6 ~9 ~15 stone_brick_stairs  
fill ~3 ~9 ~28 ~6 ~9 ~28 stone_brick_stairs  
fill ~3 ~9 ~42 ~16 ~9 ~42 stone_brick_stairs  
fill ~5 ~9 ~4 ~28 ~9 ~4 wool  
fill ~5 ~9 ~13 ~5 ~10 ~13 cobblestone_wall  
fill ~5 ~9 ~30 ~5 ~10 ~30 cobblestone_wall  
fill ~5 ~9 ~39 ~28 ~9 ~39 wool  
fill ~7 ~9 ~12 ~8 ~9 ~12 wool  
fill ~7 ~9 ~15 ~8 ~9 ~15 stone_brick_stairs  
fill ~7 ~9 ~28 ~8 ~9 ~28 stone_brick_stairs  
fill ~7 ~9 ~31 ~8 ~9 ~31 wool  
fill ~9 ~9 ~16 ~9 ~9 ~21 stone_brick_stairs  
fill ~9 ~9 ~22 ~9 ~9 ~27 stone_brick_stairs  
fill ~10 ~9 ~12 ~12 ~9 ~12 wool  
fill ~10 ~9 ~13 ~10 ~10 ~13 cobblestone_wall  
fill ~10 ~9 ~30 ~10 ~10 ~30 cobblestone_wall  
fill ~10 ~9 ~31 ~12 ~9 ~31 wool  
fill ~17 ~9 ~1 ~30 ~9 ~1 stone_brick_stairs  
fill ~17 ~9 ~42 ~30 ~9 ~42 stone_brick_stairs  
fill ~30 ~9 ~14 ~31 ~9 ~14 stonebrick  
fill ~30 ~9 ~15 ~30 ~9 ~21 stone_brick_stairs  
fill ~30 ~9 ~22 ~30 ~9 ~28 stone_brick_stairs  
fill ~30 ~9 ~29 ~31 ~9 ~29 stonebrick  
fill ~31 ~9 ~2 ~31 ~9 ~7 stone_brick_stairs  
fill ~31 ~9 ~9 ~31 ~9 ~13 stone_brick_stairs  
fill ~31 ~9 ~30 ~31 ~9 ~34 stone_brick_stairs  
fill ~31 ~9 ~36 ~31 ~9 ~41 stone_brick_stairs 
setblock ~32 ~9 ~8 stone_brick_stairs 5 
setblock ~32 ~9 ~35 stone_brick_stairs 5 
setblock ~1 ~10 ~8 cobblestone_wall 0 
setblock ~1 ~10 ~35 cobblestone_wall 0 
setblock ~2 ~10 ~15 cobblestone_wall 0 
setblock ~2 ~10 ~28 cobblestone_wall 0  
fill ~4 ~10 ~4 ~4 ~10 ~5 log  
fill ~4 ~10 ~7 ~4 ~10 ~9 log  
fill ~4 ~10 ~11 ~4 ~10 ~12 log  
fill ~4 ~10 ~31 ~4 ~10 ~32 log  
fill ~4 ~10 ~34 ~4 ~10 ~36 log  
fill ~4 ~10 ~38 ~4 ~10 ~39 log 
setblock ~5 ~10 ~3 log 5  
fill ~5 ~10 ~4 ~28 ~10 ~4 wool  
fill ~5 ~10 ~39 ~28 ~10 ~39 wool 
setblock ~5 ~10 ~40 log 5 
setblock ~6 ~10 ~13 stone_slab 12 
setblock ~6 ~10 ~30 stone_slab 12  
fill ~7 ~10 ~3 ~9 ~10 ~3 log  
fill ~7 ~10 ~12 ~8 ~10 ~12 wool  
fill ~7 ~10 ~13 ~8 ~10 ~13 stone_slab  
fill ~7 ~10 ~30 ~8 ~10 ~30 stone_slab  
fill ~7 ~10 ~31 ~8 ~10 ~31 wool  
fill ~7 ~10 ~40 ~9 ~10 ~40 log 
setblock ~9 ~10 ~13 stone_slab 12 
setblock ~9 ~10 ~15 cobblestone_wall 0 
setblock ~9 ~10 ~28 cobblestone_wall 0 
setblock ~9 ~10 ~30 stone_slab 12  
fill ~10 ~10 ~12 ~12 ~10 ~12 wool  
fill ~10 ~10 ~31 ~12 ~10 ~31 wool  
fill ~11 ~10 ~3 ~13 ~10 ~3 log 
setblock ~11 ~10 ~14 log 9  
fill ~11 ~10 ~16 ~11 ~10 ~18 log  
fill ~11 ~10 ~20 ~11 ~10 ~23 log  
fill ~11 ~10 ~25 ~11 ~10 ~27 log 
setblock ~11 ~10 ~29 log 9  
fill ~11 ~10 ~40 ~13 ~10 ~40 log  
fill ~15 ~10 ~3 ~18 ~10 ~3 log  
fill ~15 ~10 ~40 ~18 ~10 ~40 log  
fill ~20 ~10 ~3 ~22 ~10 ~3 log  
fill ~20 ~10 ~40 ~22 ~10 ~40 log  
fill ~24 ~10 ~3 ~26 ~10 ~3 log  
fill ~24 ~10 ~40 ~26 ~10 ~40 log 
setblock ~28 ~10 ~3 log 5  
fill ~28 ~10 ~15 ~28 ~10 ~18 log  
fill ~28 ~10 ~20 ~28 ~10 ~23 log  
fill ~28 ~10 ~25 ~28 ~10 ~28 log 
setblock ~28 ~10 ~40 log 5  
fill ~29 ~10 ~4 ~29 ~10 ~6 log 
setblock ~29 ~10 ~8 log 9  
fill ~29 ~10 ~10 ~29 ~10 ~12 log  
fill ~29 ~10 ~31 ~29 ~10 ~33 log 
setblock ~29 ~10 ~35 log 9  
fill ~29 ~10 ~37 ~29 ~10 ~39 log 
setblock ~31 ~10 ~14 cobblestone_wall 0 
setblock ~31 ~10 ~29 cobblestone_wall 0 
setblock ~32 ~10 ~8 cobblestone_wall 0 
setblock ~32 ~10 ~35 cobblestone_wall 0 
setblock ~1 ~11 ~8 fence 0 
setblock ~1 ~11 ~35 fence 0 
setblock ~2 ~11 ~1 cobblestone_wall 0 
setblock ~2 ~11 ~15 fence 0 
setblock ~2 ~11 ~28 fence 0 
setblock ~2 ~11 ~42 cobblestone_wall 0  
fill ~4 ~11 ~4 ~4 ~11 ~5 stone_slab 
setblock ~4 ~11 ~7 oak_stairs 7 
setblock ~4 ~11 ~8 stone_slab 5 
setblock ~4 ~11 ~9 oak_stairs 6  
fill ~4 ~11 ~11 ~4 ~11 ~12 stone_slab  
fill ~4 ~11 ~31 ~4 ~11 ~32 stone_slab 
setblock ~4 ~11 ~34 oak_stairs 7 
setblock ~4 ~11 ~35 stone_slab 5 
setblock ~4 ~11 ~36 oak_stairs 6  
fill ~4 ~11 ~38 ~4 ~11 ~39 stone_slab 
setblock ~5 ~11 ~3 stone_slab 5  
fill ~5 ~11 ~4 ~28 ~11 ~4 wool 
setblock ~5 ~11 ~13 stone_slab 4 
setblock ~5 ~11 ~30 stone_slab 4  
fill ~5 ~11 ~39 ~28 ~11 ~39 wool 
setblock ~5 ~11 ~40 stone_slab 5 
setblock ~7 ~11 ~3 oak_stairs 5  
fill ~7 ~11 ~12 ~8 ~11 ~12 wool  
fill ~7 ~11 ~13 ~8 ~11 ~13 stone_slab  
fill ~7 ~11 ~30 ~8 ~11 ~30 stone_slab  
fill ~7 ~11 ~31 ~8 ~11 ~31 wool 
setblock ~7 ~11 ~40 oak_stairs 5 
setblock ~8 ~11 ~3 stone_slab 5 
setblock ~8 ~11 ~40 stone_slab 5 
setblock ~9 ~11 ~3 oak_stairs 4 
setblock ~9 ~11 ~15 fence 0 
setblock ~9 ~11 ~28 fence 0 
setblock ~9 ~11 ~40 oak_stairs 4  
fill ~10 ~11 ~12 ~12 ~11 ~12 wool 
setblock ~10 ~11 ~13 stone_slab 4 
setblock ~10 ~11 ~30 stone_slab 4  
fill ~10 ~11 ~31 ~12 ~11 ~31 wool 
setblock ~11 ~11 ~3 oak_stairs 5 
setblock ~11 ~11 ~14 stone_slab 5 
setblock ~11 ~11 ~16 oak_stairs 7 
setblock ~11 ~11 ~17 stone_slab 0 
setblock ~11 ~11 ~18 oak_stairs 6 
setblock ~11 ~11 ~20 cobblestone_wall 0 
setblock ~11 ~11 ~23 cobblestone_wall 0 
setblock ~11 ~11 ~25 oak_stairs 7 
setblock ~11 ~11 ~26 stone_slab 0 
setblock ~11 ~11 ~27 oak_stairs 6 
setblock ~11 ~11 ~29 stone_slab 5 
setblock ~11 ~11 ~40 oak_stairs 5 
setblock ~12 ~11 ~3 stone_slab 0 
setblock ~12 ~11 ~40 stone_slab 0 
setblock ~13 ~11 ~3 oak_stairs 4 
setblock ~13 ~11 ~40 oak_stairs 4 
setblock ~15 ~11 ~3 cobblestone_wall 0 
setblock ~15 ~11 ~40 cobblestone_wall 0 
setblock ~18 ~11 ~3 cobblestone_wall 0 
setblock ~18 ~11 ~40 cobblestone_wall 0 
setblock ~20 ~11 ~3 oak_stairs 5 
setblock ~20 ~11 ~40 oak_stairs 5 
setblock ~21 ~11 ~3 stone_slab 0 
setblock ~21 ~11 ~40 stone_slab 0 
setblock ~22 ~11 ~3 oak_stairs 4 
setblock ~22 ~11 ~40 oak_stairs 4 
setblock ~24 ~11 ~3 oak_stairs 5 
setblock ~24 ~11 ~40 oak_stairs 5 
setblock ~25 ~11 ~3 stone_slab 5 
setblock ~25 ~11 ~40 stone_slab 5 
setblock ~26 ~11 ~3 oak_stairs 4 
setblock ~26 ~11 ~40 oak_stairs 4 
setblock ~28 ~11 ~3 stone_slab 5 
setblock ~28 ~11 ~15 oak_stairs 7  
fill ~28 ~11 ~16 ~28 ~11 ~17 stone_slab 
setblock ~28 ~11 ~18 oak_stairs 6 
setblock ~28 ~11 ~20 stone_brick_stairs 3 
setblock ~28 ~11 ~23 stone_brick_stairs 2 
setblock ~28 ~11 ~25 oak_stairs 7  
fill ~28 ~11 ~26 ~28 ~11 ~27 stone_slab 
setblock ~28 ~11 ~28 oak_stairs 6 
setblock ~28 ~11 ~40 stone_slab 5 
setblock ~29 ~11 ~4 stone_brick_stairs 3 
setblock ~29 ~11 ~6 stone_brick_stairs 2 
setblock ~29 ~11 ~8 oak_stairs 1 
setblock ~29 ~11 ~10 stone_brick_stairs 3 
setblock ~29 ~11 ~12 stone_brick_stairs 2 
setblock ~29 ~11 ~31 stone_brick_stairs 3 
setblock ~29 ~11 ~33 stone_brick_stairs 2 
setblock ~29 ~11 ~35 oak_stairs 1 
setblock ~29 ~11 ~37 stone_brick_stairs 3 
setblock ~29 ~11 ~39 stone_brick_stairs 2 
setblock ~31 ~11 ~1 cobblestone_wall 0 
setblock ~31 ~11 ~14 fence 0 
setblock ~31 ~11 ~29 fence 0 
setblock ~31 ~11 ~42 cobblestone_wall 0 
setblock ~32 ~11 ~8 fence 0 
setblock ~32 ~11 ~35 fence 0 
setblock ~2 ~12 ~1 fence 0 
setblock ~2 ~12 ~42 fence 0  
fill ~4 ~12 ~4 ~4 ~12 ~5 fence  
fill ~4 ~12 ~7 ~4 ~13 ~7 cobblestone_wall  
fill ~4 ~12 ~9 ~4 ~13 ~9 cobblestone_wall  
fill ~4 ~12 ~11 ~4 ~12 ~12 fence  
fill ~4 ~12 ~31 ~4 ~12 ~32 fence  
fill ~4 ~12 ~34 ~4 ~13 ~34 cobblestone_wall  
fill ~4 ~12 ~36 ~4 ~13 ~36 cobblestone_wall  
fill ~4 ~12 ~38 ~4 ~12 ~39 fence  
fill ~5 ~12 ~4 ~7 ~12 ~4 wool  
fill ~5 ~12 ~8 ~5 ~13 ~8 glass_pane 
setblock ~5 ~12 ~12 log 5 
setblock ~5 ~12 ~31 log 5  
fill ~5 ~12 ~35 ~5 ~13 ~35 glass_pane  
fill ~5 ~12 ~39 ~7 ~12 ~39 wool 
setblock ~6 ~12 ~12 log 9 
setblock ~6 ~12 ~13 stone_button 3 
setblock ~6 ~12 ~30 stone_button 4 
setblock ~6 ~12 ~31 log 9  
fill ~7 ~12 ~3 ~7 ~13 ~3 cobblestone_wall  
fill ~7 ~12 ~12 ~8 ~12 ~12 log  
fill ~7 ~12 ~31 ~8 ~12 ~31 log  
fill ~7 ~12 ~40 ~7 ~13 ~40 cobblestone_wall  
fill ~8 ~12 ~4 ~8 ~13 ~4 glass_pane  
fill ~8 ~12 ~39 ~8 ~13 ~39 glass_pane  
fill ~9 ~12 ~3 ~9 ~13 ~3 cobblestone_wall  
fill ~9 ~12 ~4 ~11 ~12 ~4 wool 
setblock ~9 ~12 ~12 log 9 
setblock ~9 ~12 ~13 stone_button 3 
setblock ~9 ~12 ~30 stone_button 4 
setblock ~9 ~12 ~31 log 9  
fill ~9 ~12 ~39 ~11 ~12 ~39 wool  
fill ~9 ~12 ~40 ~9 ~13 ~40 cobblestone_wall 
setblock ~10 ~12 ~12 log 5 
setblock ~10 ~12 ~31 log 5  
fill ~11 ~12 ~3 ~11 ~13 ~3 fence  
fill ~11 ~12 ~12 ~12 ~12 ~12 wool  
fill ~11 ~12 ~16 ~11 ~13 ~16 fence  
fill ~11 ~12 ~18 ~11 ~13 ~18 fence  
fill ~11 ~12 ~20 ~11 ~13 ~20 fence  
fill ~11 ~12 ~23 ~11 ~13 ~23 fence  
fill ~11 ~12 ~25 ~11 ~13 ~25 fence  
fill ~11 ~12 ~27 ~11 ~13 ~27 fence  
fill ~11 ~12 ~31 ~12 ~12 ~31 wool  
fill ~11 ~12 ~40 ~11 ~13 ~40 fence  
fill ~12 ~12 ~4 ~12 ~13 ~4 glass_pane  
fill ~12 ~12 ~17 ~12 ~13 ~17 glass_pane  
fill ~12 ~12 ~21 ~12 ~13 ~21 glass_pane  
fill ~12 ~12 ~22 ~12 ~13 ~22 glass_pane  
fill ~12 ~12 ~26 ~12 ~13 ~26 glass_pane  
fill ~12 ~12 ~39 ~12 ~13 ~39 glass_pane  
fill ~13 ~12 ~3 ~13 ~13 ~3 fence  
fill ~13 ~12 ~4 ~15 ~12 ~4 wool  
fill ~13 ~12 ~39 ~15 ~12 ~39 wool  
fill ~13 ~12 ~40 ~13 ~13 ~40 fence  
fill ~15 ~12 ~3 ~15 ~13 ~3 fence  
fill ~15 ~12 ~40 ~15 ~13 ~40 fence  
fill ~16 ~12 ~4 ~17 ~12 ~4 glass_pane  
fill ~16 ~12 ~39 ~17 ~12 ~39 glass_pane  
fill ~18 ~12 ~3 ~18 ~13 ~3 fence  
fill ~18 ~12 ~4 ~20 ~12 ~4 wool  
fill ~18 ~12 ~39 ~20 ~12 ~39 wool  
fill ~18 ~12 ~40 ~18 ~13 ~40 fence  
fill ~20 ~12 ~3 ~20 ~13 ~3 fence  
fill ~20 ~12 ~40 ~20 ~13 ~40 fence  
fill ~21 ~12 ~4 ~21 ~13 ~4 glass_pane  
fill ~21 ~12 ~39 ~21 ~13 ~39 glass_pane  
fill ~22 ~12 ~3 ~22 ~13 ~3 fence  
fill ~22 ~12 ~4 ~24 ~12 ~4 wool  
fill ~22 ~12 ~39 ~24 ~12 ~39 wool  
fill ~22 ~12 ~40 ~22 ~13 ~40 fence  
fill ~24 ~12 ~3 ~24 ~13 ~3 cobblestone_wall  
fill ~24 ~12 ~40 ~24 ~13 ~40 cobblestone_wall  
fill ~25 ~12 ~4 ~25 ~13 ~4 glass_pane  
fill ~25 ~12 ~39 ~25 ~13 ~39 glass_pane  
fill ~26 ~12 ~3 ~26 ~13 ~3 cobblestone_wall  
fill ~26 ~12 ~4 ~28 ~12 ~4 wool  
fill ~26 ~12 ~39 ~28 ~12 ~39 wool  
fill ~26 ~12 ~40 ~26 ~13 ~40 cobblestone_wall  
fill ~27 ~12 ~16 ~27 ~13 ~16 glass_pane  
fill ~27 ~12 ~17 ~27 ~13 ~17 glass_pane  
fill ~27 ~12 ~21 ~27 ~13 ~21 glass_pane  
fill ~27 ~12 ~22 ~27 ~13 ~22 glass_pane  
fill ~27 ~12 ~26 ~27 ~13 ~26 glass_pane  
fill ~27 ~12 ~27 ~27 ~13 ~27 glass_pane  
fill ~28 ~12 ~5 ~28 ~13 ~5 fence  
fill ~28 ~12 ~11 ~28 ~13 ~11 fence  
fill ~28 ~12 ~15 ~28 ~13 ~15 cobblestone_wall  
fill ~28 ~12 ~18 ~28 ~13 ~18 cobblestone_wall 
setblock ~28 ~12 ~20 stone_slab 5 
setblock ~28 ~12 ~23 stone_slab 5  
fill ~28 ~12 ~25 ~28 ~13 ~25 cobblestone_wall  
fill ~28 ~12 ~28 ~28 ~13 ~28 cobblestone_wall  
fill ~28 ~12 ~32 ~28 ~13 ~32 fence  
fill ~28 ~12 ~38 ~28 ~13 ~38 fence 
setblock ~29 ~12 ~4 stone_brick_stairs 7 
setblock ~29 ~12 ~6 stone_brick_stairs 6 
setblock ~29 ~12 ~8 oak_stairs 5 
setblock ~29 ~12 ~10 stone_brick_stairs 7 
setblock ~29 ~12 ~12 stone_brick_stairs 6 
setblock ~29 ~12 ~31 stone_brick_stairs 7 
setblock ~29 ~12 ~33 stone_brick_stairs 6 
setblock ~29 ~12 ~35 oak_stairs 5 
setblock ~29 ~12 ~37 stone_brick_stairs 7 
setblock ~29 ~12 ~39 stone_brick_stairs 6 
setblock ~31 ~12 ~1 fence 0 
setblock ~31 ~12 ~42 fence 0  
fill ~4 ~13 ~4 ~4 ~13 ~5 log  
fill ~4 ~13 ~11 ~4 ~13 ~12 log  
fill ~4 ~13 ~31 ~4 ~13 ~32 log  
fill ~4 ~13 ~38 ~4 ~13 ~39 log  
fill ~5 ~13 ~3 ~5 ~14 ~3 fence  
fill ~5 ~13 ~4 ~7 ~13 ~4 wool  
fill ~5 ~13 ~12 ~5 ~15 ~12 wool  
fill ~5 ~13 ~31 ~5 ~15 ~31 wool  
fill ~5 ~13 ~39 ~7 ~13 ~39 wool  
fill ~5 ~13 ~40 ~5 ~14 ~40 fence  
fill ~6 ~13 ~12 ~6 ~14 ~12 log  
fill ~6 ~13 ~13 ~6 ~14 ~13 fence  
fill ~6 ~13 ~30 ~6 ~14 ~30 fence  
fill ~6 ~13 ~31 ~6 ~14 ~31 log  
fill ~7 ~13 ~12 ~8 ~13 ~12 wool  
fill ~7 ~13 ~31 ~8 ~13 ~31 wool  
fill ~9 ~13 ~4 ~11 ~13 ~4 wool  
fill ~9 ~13 ~12 ~9 ~14 ~12 log  
fill ~9 ~13 ~13 ~9 ~14 ~13 fence  
fill ~9 ~13 ~30 ~9 ~14 ~30 fence  
fill ~9 ~13 ~31 ~9 ~14 ~31 log  
fill ~9 ~13 ~39 ~11 ~13 ~39 wool  
fill ~10 ~13 ~12 ~12 ~13 ~12 wool  
fill ~10 ~13 ~31 ~12 ~13 ~31 wool  
fill ~11 ~13 ~14 ~11 ~14 ~14 fence  
fill ~11 ~13 ~29 ~11 ~14 ~29 fence  
fill ~13 ~13 ~4 ~15 ~13 ~4 wool  
fill ~13 ~13 ~39 ~15 ~13 ~39 wool  
fill ~16 ~13 ~4 ~17 ~13 ~4 glass_pane  
fill ~16 ~13 ~39 ~17 ~13 ~39 glass_pane  
fill ~18 ~13 ~4 ~20 ~13 ~4 wool  
fill ~18 ~13 ~39 ~20 ~13 ~39 wool  
fill ~22 ~13 ~4 ~24 ~13 ~4 wool  
fill ~22 ~13 ~39 ~24 ~13 ~39 wool  
fill ~26 ~13 ~4 ~28 ~13 ~4 wool  
fill ~26 ~13 ~39 ~28 ~13 ~39 wool  
fill ~28 ~13 ~3 ~28 ~14 ~3 fence 
setblock ~28 ~13 ~20 fence 0 
setblock ~28 ~13 ~23 fence 0  
fill ~28 ~13 ~40 ~28 ~14 ~40 fence  
fill ~29 ~13 ~4 ~29 ~14 ~4 cobblestone_wall  
fill ~29 ~13 ~6 ~29 ~14 ~6 cobblestone_wall 
setblock ~29 ~13 ~8 fence 0  
fill ~29 ~13 ~10 ~29 ~14 ~10 cobblestone_wall  
fill ~29 ~13 ~12 ~29 ~14 ~12 cobblestone_wall  
fill ~29 ~13 ~31 ~29 ~14 ~31 cobblestone_wall  
fill ~29 ~13 ~33 ~29 ~14 ~33 cobblestone_wall 
setblock ~29 ~13 ~35 fence 0  
fill ~29 ~13 ~37 ~29 ~14 ~37 cobblestone_wall  
fill ~29 ~13 ~39 ~29 ~14 ~39 cobblestone_wall  
fill ~4 ~14 ~4 ~4 ~14 ~5 iron_bars 
setblock ~4 ~14 ~7 stone_slab 4 
setblock ~4 ~14 ~8 stone_slab 12 
setblock ~4 ~14 ~9 stone_slab 4  
fill ~4 ~14 ~11 ~4 ~14 ~12 iron_bars  
fill ~4 ~14 ~31 ~4 ~14 ~32 iron_bars 
setblock ~4 ~14 ~34 stone_slab 4 
setblock ~4 ~14 ~35 stone_slab 12 
setblock ~4 ~14 ~36 stone_slab 4  
fill ~4 ~14 ~38 ~4 ~14 ~39 iron_bars  
fill ~5 ~14 ~4 ~28 ~14 ~4 wool  
fill ~5 ~14 ~8 ~5 ~15 ~8 wool 
setblock ~5 ~14 ~13 fence 0 
setblock ~5 ~14 ~30 fence 0  
fill ~5 ~14 ~35 ~5 ~15 ~35 wool  
fill ~5 ~14 ~39 ~28 ~14 ~39 wool 
setblock ~7 ~14 ~3 stone_slab 4  
fill ~7 ~14 ~12 ~8 ~14 ~12 wool  
fill ~7 ~14 ~13 ~10 ~14 ~13 fence  
fill ~7 ~14 ~30 ~10 ~14 ~30 fence  
fill ~7 ~14 ~31 ~8 ~14 ~31 wool 
setblock ~7 ~14 ~40 stone_slab 4 
setblock ~8 ~14 ~3 stone_slab 12 
setblock ~8 ~14 ~40 stone_slab 12 
setblock ~9 ~14 ~3 stone_slab 4 
setblock ~9 ~14 ~40 stone_slab 4  
fill ~10 ~14 ~12 ~12 ~14 ~12 wool  
fill ~10 ~14 ~31 ~12 ~14 ~31 wool 
setblock ~11 ~14 ~3 stone_slab 5 
setblock ~11 ~14 ~16 stone_slab 5 
setblock ~11 ~14 ~17 stone_slab 13 
setblock ~11 ~14 ~18 stone_slab 5 
setblock ~11 ~14 ~20 stone_stairs 3  
fill ~11 ~14 ~21 ~11 ~14 ~22 stone_slab 
setblock ~11 ~14 ~23 stone_stairs 2 
setblock ~11 ~14 ~25 stone_slab 5 
setblock ~11 ~14 ~26 stone_slab 13 
setblock ~11 ~14 ~27 stone_slab 5 
setblock ~11 ~14 ~40 stone_slab 5 
setblock ~12 ~14 ~3 stone_slab 13  
fill ~12 ~14 ~17 ~12 ~15 ~17 wool  
fill ~12 ~14 ~21 ~12 ~15 ~21 wool  
fill ~12 ~14 ~22 ~12 ~15 ~22 wool  
fill ~12 ~14 ~26 ~12 ~15 ~26 wool 
setblock ~12 ~14 ~40 stone_slab 13 
setblock ~13 ~14 ~3 stone_slab 5 
setblock ~13 ~14 ~40 stone_slab 5 
setblock ~15 ~14 ~3 stone_stairs 1 
setblock ~15 ~14 ~40 stone_stairs 1  
fill ~16 ~14 ~3 ~17 ~14 ~3 stone_slab  
fill ~16 ~14 ~40 ~17 ~14 ~40 stone_slab 
setblock ~18 ~14 ~3 stone_stairs 0 
setblock ~18 ~14 ~40 stone_stairs 0 
setblock ~20 ~14 ~3 stone_slab 5 
setblock ~20 ~14 ~40 stone_slab 5 
setblock ~21 ~14 ~3 stone_slab 13 
setblock ~21 ~14 ~40 stone_slab 13 
setblock ~22 ~14 ~3 stone_slab 5 
setblock ~22 ~14 ~40 stone_slab 5 
setblock ~24 ~14 ~3 stone_slab 4 
setblock ~24 ~14 ~40 stone_slab 4 
setblock ~25 ~14 ~3 stone_slab 12 
setblock ~25 ~14 ~40 stone_slab 12 
setblock ~26 ~14 ~3 stone_slab 4 
setblock ~26 ~14 ~40 stone_slab 4  
fill ~27 ~14 ~16 ~27 ~15 ~16 wool  
fill ~27 ~14 ~17 ~27 ~15 ~17 wool  
fill ~27 ~14 ~21 ~27 ~15 ~21 wool  
fill ~27 ~14 ~22 ~27 ~15 ~22 wool  
fill ~27 ~14 ~26 ~27 ~15 ~26 wool  
fill ~27 ~14 ~27 ~27 ~15 ~27 wool  
fill ~28 ~14 ~5 ~28 ~15 ~5 wool  
fill ~28 ~14 ~11 ~28 ~15 ~11 wool  
fill ~28 ~14 ~15 ~28 ~14 ~18 fence 
setblock ~28 ~14 ~20 stone_slab 4  
fill ~28 ~14 ~21 ~28 ~14 ~22 stone_slab 
setblock ~28 ~14 ~23 stone_slab 4  
fill ~28 ~14 ~25 ~28 ~14 ~28 fence  
fill ~28 ~14 ~32 ~28 ~15 ~32 wool  
fill ~28 ~14 ~38 ~28 ~15 ~38 wool 
setblock ~29 ~14 ~8 trapdoor 7 
setblock ~29 ~14 ~35 trapdoor 7 
setblock ~3 ~15 ~3 log 4 
setblock ~3 ~15 ~6 log 4 
setblock ~3 ~15 ~10 log 4 
setblock ~3 ~15 ~13 log 4 
setblock ~3 ~15 ~30 log 4 
setblock ~3 ~15 ~33 log 4 
setblock ~3 ~15 ~37 log 4 
setblock ~3 ~15 ~40 log 4 
setblock ~4 ~15 ~2 log 8  
fill ~4 ~15 ~4 ~4 ~15 ~5 log  
fill ~4 ~15 ~7 ~4 ~15 ~9 log  
fill ~4 ~15 ~11 ~4 ~15 ~12 log 
setblock ~4 ~15 ~14 log 8 
setblock ~4 ~15 ~29 log 8  
fill ~4 ~15 ~31 ~4 ~15 ~32 log  
fill ~4 ~15 ~34 ~4 ~15 ~36 log  
fill ~4 ~15 ~38 ~4 ~15 ~39 log 
setblock ~4 ~15 ~41 log 8 
setblock ~5 ~15 ~3 log 4  
fill ~5 ~15 ~4 ~28 ~15 ~4 wool  
fill ~5 ~15 ~13 ~10 ~15 ~13 log  
fill ~5 ~15 ~30 ~10 ~15 ~30 log  
fill ~5 ~15 ~39 ~28 ~15 ~39 wool 
setblock ~5 ~15 ~40 log 4 
setblock ~6 ~15 ~2 log 8  
fill ~6 ~15 ~12 ~12 ~15 ~12 wool  
fill ~6 ~15 ~31 ~12 ~15 ~31 wool 
setblock ~6 ~15 ~41 log 8  
fill ~7 ~15 ~3 ~9 ~15 ~3 log  
fill ~7 ~15 ~40 ~9 ~15 ~40 log 
setblock ~10 ~15 ~2 log 8 
setblock ~10 ~15 ~15 log 4 
setblock ~10 ~15 ~19 log 4 
setblock ~10 ~15 ~24 log 4 
setblock ~10 ~15 ~28 log 4 
setblock ~10 ~15 ~41 log 8  
fill ~11 ~15 ~3 ~13 ~15 ~3 log  
fill ~11 ~15 ~14 ~11 ~15 ~29 log  
fill ~11 ~15 ~40 ~13 ~15 ~40 log 
setblock ~14 ~15 ~2 log 8 
setblock ~14 ~15 ~41 log 8  
fill ~15 ~15 ~3 ~18 ~15 ~3 log  
fill ~15 ~15 ~40 ~18 ~15 ~40 log 
setblock ~19 ~15 ~2 log 8 
setblock ~19 ~15 ~41 log 8  
fill ~20 ~15 ~3 ~22 ~15 ~3 log  
fill ~20 ~15 ~40 ~22 ~15 ~40 log 
setblock ~23 ~15 ~2 log 8 
setblock ~23 ~15 ~41 log 8  
fill ~24 ~15 ~3 ~26 ~15 ~3 log  
fill ~24 ~15 ~40 ~26 ~15 ~40 log 
setblock ~27 ~15 ~2 log 8 
setblock ~27 ~15 ~41 log 8 
setblock ~28 ~15 ~3 log 4  
fill ~28 ~15 ~15 ~28 ~15 ~28 log 
setblock ~28 ~15 ~40 log 4 
setblock ~29 ~15 ~2 log 8  
fill ~29 ~15 ~4 ~29 ~15 ~12 log 
setblock ~29 ~15 ~14 log 8 
setblock ~29 ~15 ~19 log 4 
setblock ~29 ~15 ~24 log 4 
setblock ~29 ~15 ~29 log 8  
fill ~29 ~15 ~31 ~29 ~15 ~39 log 
setblock ~29 ~15 ~41 log 8 
setblock ~30 ~15 ~3 log 4 
setblock ~30 ~15 ~7 log 4 
setblock ~30 ~15 ~9 log 4 
setblock ~30 ~15 ~13 log 4 
setblock ~30 ~15 ~30 log 4 
setblock ~30 ~15 ~34 log 4 
setblock ~30 ~15 ~36 log 4 
setblock ~30 ~15 ~40 log 4  

KittysCommands:  
setblock ~3 ~16 ~2 double_stone_slab 5 
setblock ~3 ~16 ~3 stone_slab 5 
setblock ~3 ~16 ~4 double_stone_slab 5 
setblock ~3 ~16 ~5 stone_slab 5 
setblock ~3 ~16 ~6 double_stone_slab 5 
setblock ~3 ~16 ~7 stone_slab 5 
setblock ~3 ~16 ~8 double_stone_slab 5 
setblock ~3 ~16 ~9 stone_slab 5 
setblock ~3 ~16 ~10 double_stone_slab 5 
setblock ~3 ~16 ~11 stone_slab 5 
setblock ~3 ~16 ~12 double_stone_slab 5 
setblock ~3 ~16 ~13 stone_slab 5 
setblock ~3 ~16 ~14 double_stone_slab 5 
setblock ~3 ~16 ~29 double_stone_slab 5 
setblock ~3 ~16 ~30 stone_slab 5 
setblock ~3 ~16 ~31 double_stone_slab 5 
setblock ~3 ~16 ~32 stone_slab 5 
setblock ~3 ~16 ~33 double_stone_slab 5 
setblock ~3 ~16 ~34 stone_slab 5 
setblock ~3 ~16 ~35 double_stone_slab 5 
setblock ~3 ~16 ~36 stone_slab 5 
setblock ~3 ~16 ~37 double_stone_slab 5 
setblock ~3 ~16 ~38 stone_slab 5 
setblock ~3 ~16 ~39 double_stone_slab 5 
setblock ~3 ~16 ~40 stone_slab 5 
setblock ~3 ~16 ~41 double_stone_slab 5 
setblock ~4 ~16 ~2 stone_slab 5  
fill ~4 ~16 ~3 ~29 ~16 ~3 wool  
fill ~4 ~16 ~4 ~4 ~19 ~4 wool  
fill ~4 ~16 ~5 ~4 ~19 ~5 wool  
fill ~4 ~16 ~6 ~4 ~19 ~6 wool  
fill ~4 ~16 ~7 ~4 ~19 ~7 wool  
fill ~4 ~16 ~8 ~4 ~19 ~8 wool  
fill ~4 ~16 ~9 ~4 ~19 ~9 wool  
fill ~4 ~16 ~10 ~4 ~19 ~10 wool  
fill ~4 ~16 ~11 ~4 ~19 ~11 wool  
fill ~4 ~16 ~12 ~4 ~19 ~12 wool  
fill ~4 ~16 ~13 ~11 ~16 ~13 wool 
setblock ~4 ~16 ~14 stone_slab 5 
setblock ~4 ~16 ~29 stone_slab 5  
fill ~4 ~16 ~30 ~11 ~16 ~30 wool  
fill ~4 ~16 ~31 ~4 ~19 ~31 wool  
fill ~4 ~16 ~32 ~4 ~19 ~32 wool  
fill ~4 ~16 ~33 ~4 ~19 ~33 wool  
fill ~4 ~16 ~34 ~4 ~19 ~34 wool  
fill ~4 ~16 ~35 ~4 ~19 ~35 wool  
fill ~4 ~16 ~36 ~4 ~19 ~36 wool  
fill ~4 ~16 ~37 ~4 ~19 ~37 wool  
fill ~4 ~16 ~38 ~4 ~19 ~38 wool  
fill ~4 ~16 ~39 ~4 ~19 ~39 wool  
fill ~4 ~16 ~40 ~29 ~16 ~40 wool 
setblock ~4 ~16 ~41 stone_slab 5 
setblock ~5 ~16 ~2 double_stone_slab 5 
setblock ~5 ~16 ~14 double_stone_slab 5 
setblock ~5 ~16 ~29 double_stone_slab 5 
setblock ~5 ~16 ~41 double_stone_slab 5 
setblock ~6 ~16 ~2 stone_slab 5 
setblock ~6 ~16 ~14 stone_slab 5 
setblock ~6 ~16 ~29 stone_slab 5 
setblock ~6 ~16 ~41 stone_slab 5 
setblock ~7 ~16 ~2 double_stone_slab 5 
setblock ~7 ~16 ~14 double_stone_slab 5 
setblock ~7 ~16 ~29 double_stone_slab 5 
setblock ~7 ~16 ~41 double_stone_slab 5 
setblock ~8 ~16 ~2 stone_slab 5 
setblock ~8 ~16 ~14 stone_slab 5 
setblock ~8 ~16 ~29 stone_slab 5 
setblock ~8 ~16 ~41 stone_slab 5 
setblock ~9 ~16 ~2 double_stone_slab 5 
setblock ~9 ~16 ~14 double_stone_slab 5 
setblock ~9 ~16 ~29 double_stone_slab 5 
setblock ~9 ~16 ~41 double_stone_slab 5 
setblock ~10 ~16 ~2 stone_slab 5 
setblock ~10 ~16 ~14 stone_slab 5 
setblock ~10 ~16 ~15 double_stone_slab 5 
setblock ~10 ~16 ~16 stone_slab 5 
setblock ~10 ~16 ~17 double_stone_slab 5 
setblock ~10 ~16 ~18 stone_slab 5 
setblock ~10 ~16 ~19 double_stone_slab 5 
setblock ~10 ~16 ~20 stone_slab 5  
fill ~10 ~16 ~21 ~10 ~16 ~22 double_stone_slab 
setblock ~10 ~16 ~23 stone_slab 5 
setblock ~10 ~16 ~24 double_stone_slab 5 
setblock ~10 ~16 ~25 stone_slab 5 
setblock ~10 ~16 ~26 double_stone_slab 5 
setblock ~10 ~16 ~27 stone_slab 5 
setblock ~10 ~16 ~28 double_stone_slab 5 
setblock ~10 ~16 ~29 stone_slab 5 
setblock ~10 ~16 ~41 stone_slab 5 
setblock ~11 ~16 ~2 double_stone_slab 5  
fill ~11 ~16 ~14 ~11 ~19 ~14 wool  
fill ~11 ~16 ~15 ~11 ~19 ~15 wool  
fill ~11 ~16 ~16 ~11 ~19 ~16 wool  
fill ~11 ~16 ~17 ~11 ~19 ~17 wool  
fill ~11 ~16 ~18 ~11 ~19 ~18 wool  
fill ~11 ~16 ~19 ~11 ~19 ~19 wool  
fill ~11 ~16 ~20 ~11 ~19 ~20 wool  
fill ~11 ~16 ~21 ~11 ~19 ~21 wool  
fill ~11 ~16 ~22 ~11 ~19 ~22 wool  
fill ~11 ~16 ~23 ~11 ~19 ~23 wool  
fill ~11 ~16 ~24 ~11 ~19 ~24 wool  
fill ~11 ~16 ~25 ~11 ~19 ~25 wool  
fill ~11 ~16 ~26 ~11 ~19 ~26 wool  
fill ~11 ~16 ~27 ~11 ~19 ~27 wool  
fill ~11 ~16 ~28 ~11 ~19 ~28 wool  
fill ~11 ~16 ~29 ~11 ~19 ~29 wool 
setblock ~11 ~16 ~41 double_stone_slab 5 
setblock ~12 ~16 ~2 stone_slab 5 
setblock ~12 ~16 ~41 stone_slab 5 
setblock ~13 ~16 ~2 double_stone_slab 5 
setblock ~13 ~16 ~41 double_stone_slab 5 
setblock ~14 ~16 ~2 stone_slab 5 
setblock ~14 ~16 ~41 stone_slab 5 
setblock ~15 ~16 ~2 double_stone_slab 5 
setblock ~15 ~16 ~41 double_stone_slab 5  
fill ~16 ~16 ~2 ~17 ~16 ~2 stone_slab  
fill ~16 ~16 ~41 ~17 ~16 ~41 stone_slab 
setblock ~18 ~16 ~2 double_stone_slab 5 
setblock ~18 ~16 ~41 double_stone_slab 5 
setblock ~19 ~16 ~2 stone_slab 5 
setblock ~19 ~16 ~41 stone_slab 5 
setblock ~20 ~16 ~2 double_stone_slab 5 
setblock ~20 ~16 ~41 double_stone_slab 5 
setblock ~21 ~16 ~2 stone_slab 5 
setblock ~21 ~16 ~41 stone_slab 5 
setblock ~22 ~16 ~2 double_stone_slab 5 
setblock ~22 ~16 ~41 double_stone_slab 5 
setblock ~23 ~16 ~2 stone_slab 5 
setblock ~23 ~16 ~41 stone_slab 5 
setblock ~24 ~16 ~2 double_stone_slab 5 
setblock ~24 ~16 ~41 double_stone_slab 5 
setblock ~25 ~16 ~2 stone_slab 5 
setblock ~25 ~16 ~41 stone_slab 5 
setblock ~26 ~16 ~2 double_stone_slab 5 
setblock ~26 ~16 ~41 double_stone_slab 5 
setblock ~27 ~16 ~2 stone_slab 5 
setblock ~27 ~16 ~41 stone_slab 5 
setblock ~28 ~16 ~2 double_stone_slab 5  
fill ~28 ~16 ~14 ~28 ~19 ~14 wool  
fill ~28 ~16 ~15 ~28 ~19 ~15 wool  
fill ~28 ~16 ~16 ~28 ~19 ~16 wool  
fill ~28 ~16 ~17 ~28 ~19 ~17 wool  
fill ~28 ~16 ~18 ~28 ~19 ~18 wool  
fill ~28 ~16 ~19 ~28 ~19 ~19 wool  
fill ~28 ~16 ~20 ~28 ~19 ~20 wool  
fill ~28 ~16 ~21 ~28 ~19 ~21 wool  
fill ~28 ~16 ~22 ~28 ~19 ~22 wool  
fill ~28 ~16 ~23 ~28 ~19 ~23 wool  
fill ~28 ~16 ~24 ~28 ~19 ~24 wool  
fill ~28 ~16 ~25 ~28 ~19 ~25 wool  
fill ~28 ~16 ~26 ~28 ~19 ~26 wool  
fill ~28 ~16 ~27 ~28 ~19 ~27 wool  
fill ~28 ~16 ~28 ~28 ~19 ~28 wool  
fill ~28 ~16 ~29 ~28 ~19 ~29 wool 
setblock ~28 ~16 ~41 double_stone_slab 5 
setblock ~29 ~16 ~2 stone_slab 5  
fill ~29 ~16 ~4 ~29 ~19 ~4 wool  
fill ~29 ~16 ~5 ~29 ~19 ~5 wool  
fill ~29 ~16 ~6 ~29 ~19 ~6 wool  
fill ~29 ~16 ~7 ~29 ~19 ~7 wool  
fill ~29 ~16 ~8 ~29 ~19 ~8 wool  
fill ~29 ~16 ~9 ~29 ~19 ~9 wool  
fill ~29 ~16 ~10 ~29 ~19 ~10 wool  
fill ~29 ~16 ~11 ~29 ~19 ~11 wool  
fill ~29 ~16 ~12 ~29 ~19 ~12 wool  
fill ~29 ~16 ~13 ~29 ~19 ~13 wool 
setblock ~29 ~16 ~14 double_stone_slab 5 
setblock ~29 ~16 ~15 stone_slab 5 
setblock ~29 ~16 ~16 double_stone_slab 5 
setblock ~29 ~16 ~17 stone_slab 5 
setblock ~29 ~16 ~18 double_stone_slab 5 
setblock ~29 ~16 ~19 stone_slab 5 
setblock ~29 ~16 ~20 double_stone_slab 5  
fill ~29 ~16 ~21 ~29 ~16 ~22 stone_slab 
setblock ~29 ~16 ~23 double_stone_slab 5 
setblock ~29 ~16 ~24 stone_slab 5 
setblock ~29 ~16 ~25 double_stone_slab 5 
setblock ~29 ~16 ~26 stone_slab 5 
setblock ~29 ~16 ~27 double_stone_slab 5 
setblock ~29 ~16 ~28 stone_slab 5 
setblock ~29 ~16 ~29 double_stone_slab 5  
fill ~29 ~16 ~30 ~29 ~19 ~30 wool  
fill ~29 ~16 ~31 ~29 ~19 ~31 wool  
fill ~29 ~16 ~32 ~29 ~19 ~32 wool  
fill ~29 ~16 ~33 ~29 ~19 ~33 wool  
fill ~29 ~16 ~34 ~29 ~19 ~34 wool  
fill ~29 ~16 ~35 ~29 ~19 ~35 wool  
fill ~29 ~16 ~36 ~29 ~19 ~36 wool  
fill ~29 ~16 ~37 ~29 ~19 ~37 wool  
fill ~29 ~16 ~38 ~29 ~19 ~38 wool  
fill ~29 ~16 ~39 ~29 ~19 ~39 wool 
setblock ~29 ~16 ~41 stone_slab 5 
setblock ~30 ~16 ~2 double_stone_slab 5 
setblock ~30 ~16 ~3 stone_slab 5 
setblock ~30 ~16 ~4 double_stone_slab 5 
setblock ~30 ~16 ~5 stone_slab 5 
setblock ~30 ~16 ~6 double_stone_slab 5 
setblock ~30 ~16 ~7 stone_slab 5 
setblock ~30 ~16 ~8 double_stone_slab 5 
setblock ~30 ~16 ~9 stone_slab 5 
setblock ~30 ~16 ~10 double_stone_slab 5 
setblock ~30 ~16 ~11 stone_slab 5 
setblock ~30 ~16 ~12 double_stone_slab 5 
setblock ~30 ~16 ~13 stone_slab 5 
setblock ~30 ~16 ~30 stone_slab 5 
setblock ~30 ~16 ~31 double_stone_slab 5 
setblock ~30 ~16 ~32 stone_slab 5 
setblock ~30 ~16 ~33 double_stone_slab 5 
setblock ~30 ~16 ~34 stone_slab 5 
setblock ~30 ~16 ~35 double_stone_slab 5 
setblock ~30 ~16 ~36 stone_slab 5 
setblock ~30 ~16 ~37 double_stone_slab 5 
setblock ~30 ~16 ~38 stone_slab 5 
setblock ~30 ~16 ~39 double_stone_slab 5 
setblock ~30 ~16 ~40 stone_slab 5 
setblock ~30 ~16 ~41 double_stone_slab 5  
fill ~3 ~17 ~2 ~3 ~18 ~2 cobblestone_wall  
fill ~3 ~17 ~4 ~3 ~18 ~4 cobblestone_wall  
fill ~3 ~17 ~6 ~3 ~18 ~6 cobblestone_wall  
fill ~3 ~17 ~8 ~3 ~18 ~8 cobblestone_wall  
fill ~3 ~17 ~10 ~3 ~18 ~10 cobblestone_wall  
fill ~3 ~17 ~12 ~3 ~18 ~12 cobblestone_wall  
fill ~3 ~17 ~14 ~3 ~18 ~14 cobblestone_wall  
fill ~3 ~17 ~29 ~3 ~18 ~29 cobblestone_wall  
fill ~3 ~17 ~31 ~3 ~18 ~31 cobblestone_wall  
fill ~3 ~17 ~33 ~3 ~18 ~33 cobblestone_wall  
fill ~3 ~17 ~35 ~3 ~18 ~35 cobblestone_wall  
fill ~3 ~17 ~37 ~3 ~18 ~37 cobblestone_wall  
fill ~3 ~17 ~39 ~3 ~18 ~39 cobblestone_wall  
fill ~3 ~17 ~41 ~3 ~18 ~41 cobblestone_wall  
fill ~4 ~17 ~3 ~29 ~17 ~3 wool  
fill ~4 ~17 ~13 ~11 ~17 ~13 wool  
fill ~4 ~17 ~30 ~11 ~17 ~30 wool  
fill ~4 ~17 ~40 ~29 ~17 ~40 wool  
fill ~5 ~17 ~2 ~5 ~18 ~2 cobblestone_wall  
fill ~5 ~17 ~14 ~5 ~18 ~14 cobblestone_wall  
fill ~5 ~17 ~29 ~5 ~18 ~29 cobblestone_wall  
fill ~5 ~17 ~41 ~5 ~18 ~41 cobblestone_wall  
fill ~7 ~17 ~2 ~7 ~18 ~2 cobblestone_wall  
fill ~7 ~17 ~14 ~7 ~18 ~14 cobblestone_wall  
fill ~7 ~17 ~29 ~7 ~18 ~29 cobblestone_wall  
fill ~7 ~17 ~41 ~7 ~18 ~41 cobblestone_wall  
fill ~9 ~17 ~2 ~9 ~18 ~2 cobblestone_wall  
fill ~9 ~17 ~14 ~9 ~18 ~14 cobblestone_wall  
fill ~9 ~17 ~29 ~9 ~18 ~29 cobblestone_wall  
fill ~9 ~17 ~41 ~9 ~18 ~41 cobblestone_wall  
fill ~10 ~17 ~15 ~10 ~18 ~15 cobblestone_wall  
fill ~10 ~17 ~17 ~10 ~18 ~17 cobblestone_wall  
fill ~10 ~17 ~19 ~10 ~18 ~19 cobblestone_wall  
fill ~10 ~17 ~21 ~10 ~18 ~21 cobblestone_wall  
fill ~10 ~17 ~22 ~10 ~18 ~22 cobblestone_wall  
fill ~10 ~17 ~24 ~10 ~18 ~24 cobblestone_wall  
fill ~10 ~17 ~26 ~10 ~18 ~26 cobblestone_wall  
fill ~10 ~17 ~28 ~10 ~18 ~28 cobblestone_wall  
fill ~11 ~17 ~2 ~11 ~18 ~2 cobblestone_wall  
fill ~11 ~17 ~41 ~11 ~18 ~41 cobblestone_wall  
fill ~13 ~17 ~2 ~13 ~18 ~2 cobblestone_wall  
fill ~13 ~17 ~41 ~13 ~18 ~41 cobblestone_wall  
fill ~15 ~17 ~2 ~15 ~18 ~2 cobblestone_wall  
fill ~15 ~17 ~41 ~15 ~18 ~41 cobblestone_wall  
fill ~18 ~17 ~2 ~18 ~18 ~2 cobblestone_wall  
fill ~18 ~17 ~41 ~18 ~18 ~41 cobblestone_wall  
fill ~20 ~17 ~2 ~20 ~18 ~2 cobblestone_wall  
fill ~20 ~17 ~41 ~20 ~18 ~41 cobblestone_wall  
fill ~22 ~17 ~2 ~22 ~18 ~2 cobblestone_wall  
fill ~22 ~17 ~41 ~22 ~18 ~41 cobblestone_wall  
fill ~24 ~17 ~2 ~24 ~18 ~2 cobblestone_wall  
fill ~24 ~17 ~41 ~24 ~18 ~41 cobblestone_wall  
fill ~26 ~17 ~2 ~26 ~18 ~2 cobblestone_wall  
fill ~26 ~17 ~41 ~26 ~18 ~41 cobblestone_wall  
fill ~28 ~17 ~2 ~28 ~18 ~2 cobblestone_wall  
fill ~28 ~17 ~41 ~28 ~18 ~41 cobblestone_wall  
fill ~29 ~17 ~14 ~29 ~18 ~14 cobblestone_wall  
fill ~29 ~17 ~16 ~29 ~18 ~16 cobblestone_wall  
fill ~29 ~17 ~18 ~29 ~18 ~18 cobblestone_wall  
fill ~29 ~17 ~20 ~29 ~18 ~20 cobblestone_wall  
fill ~29 ~17 ~23 ~29 ~18 ~23 cobblestone_wall  
fill ~29 ~17 ~25 ~29 ~18 ~25 cobblestone_wall  
fill ~29 ~17 ~27 ~29 ~18 ~27 cobblestone_wall  
fill ~29 ~17 ~29 ~29 ~18 ~29 cobblestone_wall  
fill ~30 ~17 ~2 ~30 ~18 ~2 cobblestone_wall  
fill ~30 ~17 ~4 ~30 ~18 ~4 cobblestone_wall  
fill ~30 ~17 ~6 ~30 ~18 ~6 cobblestone_wall  
fill ~30 ~17 ~8 ~30 ~18 ~8 cobblestone_wall  
fill ~30 ~17 ~10 ~30 ~18 ~10 cobblestone_wall  
fill ~30 ~17 ~12 ~30 ~18 ~12 cobblestone_wall  
fill ~30 ~17 ~31 ~30 ~18 ~31 cobblestone_wall  
fill ~30 ~17 ~33 ~30 ~18 ~33 cobblestone_wall  
fill ~30 ~17 ~35 ~30 ~18 ~35 cobblestone_wall  
fill ~30 ~17 ~37 ~30 ~18 ~37 cobblestone_wall  
fill ~30 ~17 ~39 ~30 ~18 ~39 cobblestone_wall  
fill ~30 ~17 ~41 ~30 ~18 ~41 cobblestone_wall  
fill ~4 ~18 ~3 ~29 ~18 ~3 wool  
fill ~4 ~18 ~13 ~11 ~18 ~13 wool  
fill ~4 ~18 ~30 ~11 ~18 ~30 wool  
fill ~4 ~18 ~40 ~29 ~18 ~40 wool 
setblock ~3 ~19 ~2 stonebrick 0  
fill ~3 ~19 ~3 ~3 ~20 ~3 stone_slab 
setblock ~3 ~19 ~4 stonebrick 0  
fill ~3 ~19 ~5 ~3 ~20 ~5 stone_slab 
setblock ~3 ~19 ~6 stonebrick 0  
fill ~3 ~19 ~7 ~3 ~20 ~7 stone_slab 
setblock ~3 ~19 ~8 stonebrick 0  
fill ~3 ~19 ~9 ~3 ~20 ~9 stone_slab 
setblock ~3 ~19 ~10 stonebrick 0  
fill ~3 ~19 ~11 ~3 ~20 ~11 stone_slab 
setblock ~3 ~19 ~12 stonebrick 0  
fill ~3 ~19 ~13 ~3 ~20 ~13 stone_slab 
setblock ~3 ~19 ~14 stonebrick 0 
setblock ~3 ~19 ~29 stonebrick 0  
fill ~3 ~19 ~30 ~3 ~20 ~30 stone_slab 
setblock ~3 ~19 ~31 stonebrick 0  
fill ~3 ~19 ~32 ~3 ~20 ~32 stone_slab 
setblock ~3 ~19 ~33 stonebrick 0  
fill ~3 ~19 ~34 ~3 ~20 ~34 stone_slab 
setblock ~3 ~19 ~35 stonebrick 0  
fill ~3 ~19 ~36 ~3 ~20 ~36 stone_slab 
setblock ~3 ~19 ~37 stonebrick 0  
fill ~3 ~19 ~38 ~3 ~20 ~38 stone_slab 
setblock ~3 ~19 ~39 stonebrick 0  
fill ~3 ~19 ~40 ~3 ~20 ~40 stone_slab 
setblock ~3 ~19 ~41 stonebrick 0  
fill ~4 ~19 ~2 ~4 ~20 ~2 stone_slab  
fill ~4 ~19 ~3 ~29 ~19 ~3 wool  
fill ~4 ~19 ~13 ~11 ~19 ~13 wool  
fill ~4 ~19 ~14 ~4 ~20 ~14 stone_slab  
fill ~4 ~19 ~29 ~4 ~20 ~29 stone_slab  
fill ~4 ~19 ~30 ~11 ~19 ~30 wool  
fill ~4 ~19 ~40 ~29 ~19 ~40 wool  
fill ~4 ~19 ~41 ~4 ~20 ~41 stone_slab 
setblock ~5 ~19 ~2 stonebrick 0 
setblock ~5 ~19 ~14 stonebrick 0 
setblock ~5 ~19 ~29 stonebrick 0 
setblock ~5 ~19 ~41 stonebrick 0  
fill ~6 ~19 ~2 ~6 ~20 ~2 stone_slab  
fill ~6 ~19 ~14 ~6 ~20 ~14 stone_slab  
fill ~6 ~19 ~29 ~6 ~20 ~29 stone_slab  
fill ~6 ~19 ~41 ~6 ~20 ~41 stone_slab 
setblock ~7 ~19 ~2 stonebrick 0 
setblock ~7 ~19 ~14 stonebrick 0 
setblock ~7 ~19 ~29 stonebrick 0 
setblock ~7 ~19 ~41 stonebrick 0  
fill ~8 ~19 ~2 ~8 ~20 ~2 stone_slab  
fill ~8 ~19 ~14 ~8 ~20 ~14 stone_slab  
fill ~8 ~19 ~29 ~8 ~20 ~29 stone_slab  
fill ~8 ~19 ~41 ~8 ~20 ~41 stone_slab 
setblock ~9 ~19 ~2 stonebrick 0  
fill ~9 ~19 ~14 ~9 ~20 ~14 double_stone_slab  
fill ~9 ~19 ~29 ~9 ~20 ~29 double_stone_slab 
setblock ~9 ~19 ~41 stonebrick 0  
fill ~10 ~19 ~2 ~10 ~20 ~2 stone_slab  
fill ~10 ~19 ~14 ~10 ~20 ~14 stone_slab  
fill ~10 ~19 ~15 ~10 ~20 ~15 double_stone_slab  
fill ~10 ~19 ~16 ~10 ~20 ~16 stone_slab 
setblock ~10 ~19 ~17 stonebrick 0  
fill ~10 ~19 ~18 ~10 ~20 ~18 stone_slab  
fill ~10 ~19 ~19 ~10 ~20 ~19 stonebrick  
fill ~10 ~19 ~20 ~10 ~20 ~20 stone_slab  
fill ~10 ~19 ~21 ~10 ~19 ~22 stonebrick  
fill ~10 ~19 ~23 ~10 ~20 ~23 stone_slab  
fill ~10 ~19 ~24 ~10 ~20 ~24 stonebrick  
fill ~10 ~19 ~25 ~10 ~20 ~25 stone_slab 
setblock ~10 ~19 ~26 stonebrick 0  
fill ~10 ~19 ~27 ~10 ~20 ~27 stone_slab  
fill ~10 ~19 ~28 ~10 ~20 ~28 double_stone_slab  
fill ~10 ~19 ~29 ~10 ~20 ~29 stone_slab  
fill ~10 ~19 ~41 ~10 ~20 ~41 stone_slab  
fill ~11 ~19 ~2 ~11 ~22 ~2 stonebrick  
fill ~11 ~19 ~41 ~11 ~22 ~41 stonebrick  
fill ~12 ~19 ~2 ~12 ~20 ~2 stone_slab  
fill ~12 ~19 ~41 ~12 ~20 ~41 stone_slab  
fill ~13 ~19 ~2 ~13 ~20 ~2 stonebrick  
fill ~13 ~19 ~41 ~13 ~20 ~41 stonebrick  
fill ~14 ~19 ~2 ~14 ~20 ~2 stone_slab  
fill ~14 ~19 ~41 ~14 ~20 ~41 stone_slab  
fill ~15 ~19 ~2 ~15 ~20 ~2 stonebrick  
fill ~15 ~19 ~41 ~15 ~20 ~41 stonebrick  
fill ~16 ~19 ~2 ~17 ~19 ~2 stone_slab  
fill ~16 ~19 ~41 ~17 ~19 ~41 stone_slab  
fill ~18 ~19 ~2 ~18 ~20 ~2 stonebrick  
fill ~18 ~19 ~41 ~18 ~20 ~41 stonebrick  
fill ~19 ~19 ~2 ~19 ~20 ~2 stone_slab  
fill ~19 ~19 ~41 ~19 ~20 ~41 stone_slab  
fill ~20 ~19 ~2 ~20 ~20 ~2 stonebrick  
fill ~20 ~19 ~41 ~20 ~20 ~41 stonebrick  
fill ~21 ~19 ~2 ~21 ~20 ~2 stone_slab  
fill ~21 ~19 ~41 ~21 ~20 ~41 stone_slab  
fill ~22 ~19 ~2 ~22 ~20 ~2 stonebrick  
fill ~22 ~19 ~41 ~22 ~20 ~41 stonebrick  
fill ~23 ~19 ~2 ~23 ~20 ~2 stone_slab  
fill ~23 ~19 ~41 ~23 ~20 ~41 stone_slab  
fill ~24 ~19 ~2 ~24 ~20 ~2 stonebrick  
fill ~24 ~19 ~41 ~24 ~20 ~41 stonebrick  
fill ~25 ~19 ~2 ~25 ~20 ~2 stone_slab  
fill ~25 ~19 ~41 ~25 ~20 ~41 stone_slab  
fill ~26 ~19 ~2 ~26 ~20 ~2 stonebrick  
fill ~26 ~19 ~41 ~26 ~20 ~41 stonebrick  
fill ~27 ~19 ~2 ~27 ~20 ~2 stone_slab  
fill ~27 ~19 ~41 ~27 ~20 ~41 stone_slab  
fill ~28 ~19 ~2 ~28 ~20 ~2 stonebrick  
fill ~28 ~19 ~41 ~28 ~20 ~41 stonebrick  
fill ~29 ~19 ~2 ~29 ~20 ~2 stone_slab 
setblock ~29 ~19 ~14 stonebrick 0  
fill ~29 ~19 ~15 ~29 ~20 ~15 stone_slab 
setblock ~29 ~19 ~16 stonebrick 0  
fill ~29 ~19 ~17 ~29 ~20 ~17 stone_slab 
setblock ~29 ~19 ~18 stonebrick 0  
fill ~29 ~19 ~19 ~29 ~20 ~19 stone_slab 
setblock ~29 ~19 ~20 stonebrick 0  
fill ~29 ~19 ~21 ~29 ~20 ~21 stone_slab  
fill ~29 ~19 ~22 ~29 ~20 ~22 stone_slab 
setblock ~29 ~19 ~23 stonebrick 0  
fill ~29 ~19 ~24 ~29 ~20 ~24 stone_slab 
setblock ~29 ~19 ~25 stonebrick 0  
fill ~29 ~19 ~26 ~29 ~20 ~26 stone_slab 
setblock ~29 ~19 ~27 stonebrick 0  
fill ~29 ~19 ~28 ~29 ~20 ~28 stone_slab 
setblock ~29 ~19 ~29 stonebrick 0  
fill ~29 ~19 ~41 ~29 ~20 ~41 stone_slab  
fill ~30 ~19 ~2 ~30 ~20 ~2 stonebrick  
fill ~30 ~19 ~3 ~30 ~20 ~3 stone_slab  
fill ~30 ~19 ~4 ~30 ~20 ~4 stonebrick  
fill ~30 ~19 ~5 ~30 ~20 ~5 stone_slab  
fill ~30 ~19 ~6 ~30 ~20 ~6 stonebrick  
fill ~30 ~19 ~7 ~30 ~20 ~7 stone_slab  
fill ~30 ~19 ~8 ~30 ~20 ~8 stonebrick  
fill ~30 ~19 ~9 ~30 ~20 ~9 stone_slab  
fill ~30 ~19 ~10 ~30 ~20 ~10 stonebrick  
fill ~30 ~19 ~11 ~30 ~20 ~11 stone_slab  
fill ~30 ~19 ~12 ~30 ~20 ~12 stonebrick  
fill ~30 ~19 ~13 ~30 ~20 ~13 stone_slab  
fill ~30 ~19 ~30 ~30 ~20 ~30 stone_slab  
fill ~30 ~19 ~31 ~30 ~20 ~31 stonebrick  
fill ~30 ~19 ~32 ~30 ~20 ~32 stone_slab  
fill ~30 ~19 ~33 ~30 ~20 ~33 stonebrick  
fill ~30 ~19 ~34 ~30 ~20 ~34 stone_slab  
fill ~30 ~19 ~35 ~30 ~20 ~35 stonebrick  
fill ~30 ~19 ~36 ~30 ~20 ~36 stone_slab  
fill ~30 ~19 ~37 ~30 ~20 ~37 stonebrick  
fill ~30 ~19 ~38 ~30 ~20 ~38 stone_slab  
fill ~30 ~19 ~39 ~30 ~20 ~39 stonebrick  
fill ~30 ~19 ~40 ~30 ~20 ~40 stone_slab  
fill ~30 ~19 ~41 ~30 ~20 ~41 stonebrick 
setblock ~3 ~20 ~2 double_stone_slab 5 
setblock ~3 ~20 ~4 double_stone_slab 5 
setblock ~3 ~20 ~6 double_stone_slab 5 
setblock ~3 ~20 ~8 double_stone_slab 5 
setblock ~3 ~20 ~10 double_stone_slab 5 
setblock ~3 ~20 ~12 double_stone_slab 5 
setblock ~3 ~20 ~14 double_stone_slab 5 
setblock ~3 ~20 ~29 double_stone_slab 5 
setblock ~3 ~20 ~31 double_stone_slab 5 
setblock ~3 ~20 ~33 double_stone_slab 5 
setblock ~3 ~20 ~35 double_stone_slab 5 
setblock ~3 ~20 ~37 double_stone_slab 5 
setblock ~3 ~20 ~39 double_stone_slab 5 
setblock ~3 ~20 ~41 double_stone_slab 5  
fill ~4 ~20 ~3 ~29 ~20 ~3 log  
fill ~4 ~20 ~4 ~4 ~20 ~13 log  
fill ~4 ~20 ~30 ~11 ~20 ~30 log  
fill ~4 ~20 ~31 ~4 ~20 ~40 log 
setblock ~5 ~20 ~2 double_stone_slab 5  
fill ~5 ~20 ~13 ~11 ~20 ~13 log 
setblock ~5 ~20 ~14 double_stone_slab 5 
setblock ~5 ~20 ~29 double_stone_slab 5  
fill ~5 ~20 ~40 ~29 ~20 ~40 log 
setblock ~5 ~20 ~41 double_stone_slab 5 
setblock ~7 ~20 ~2 double_stone_slab 5 
setblock ~7 ~20 ~14 double_stone_slab 5 
setblock ~7 ~20 ~29 double_stone_slab 5 
setblock ~7 ~20 ~41 double_stone_slab 5 
setblock ~9 ~20 ~2 double_stone_slab 5 
setblock ~9 ~20 ~41 double_stone_slab 5 
setblock ~10 ~20 ~17 double_stone_slab 5  
fill ~10 ~20 ~21 ~10 ~20 ~22 double_stone_slab 
setblock ~10 ~20 ~26 double_stone_slab 5  
fill ~11 ~20 ~14 ~11 ~20 ~30 log  
fill ~16 ~20 ~2 ~17 ~20 ~2 stone_slab  
fill ~16 ~20 ~41 ~17 ~20 ~41 stone_slab  
fill ~28 ~20 ~14 ~28 ~20 ~29 log  
fill ~29 ~20 ~4 ~29 ~20 ~13 log 
setblock ~29 ~20 ~14 double_stone_slab 5 
setblock ~29 ~20 ~16 double_stone_slab 5 
setblock ~29 ~20 ~18 double_stone_slab 5 
setblock ~29 ~20 ~20 double_stone_slab 5 
setblock ~29 ~20 ~23 double_stone_slab 5 
setblock ~29 ~20 ~25 double_stone_slab 5 
setblock ~29 ~20 ~27 double_stone_slab 5 
setblock ~29 ~20 ~29 double_stone_slab 5  
fill ~29 ~20 ~30 ~29 ~20 ~40 log 
setblock ~3 ~21 ~2 stone_brick_stairs 6 
setblock ~3 ~21 ~3 stone_brick_stairs 7 
setblock ~3 ~21 ~5 stone_brick_stairs 0 
setblock ~3 ~21 ~7 stone_stairs 2 
setblock ~3 ~21 ~9 stone_stairs 3 
setblock ~3 ~21 ~11 stone_brick_stairs 0 
setblock ~3 ~21 ~13 stone_brick_stairs 6 
setblock ~3 ~21 ~14 stone_brick_stairs 7 
setblock ~3 ~21 ~29 stone_brick_stairs 6 
setblock ~3 ~21 ~30 stone_brick_stairs 7 
setblock ~3 ~21 ~32 stone_brick_stairs 0 
setblock ~3 ~21 ~34 stone_stairs 2 
setblock ~3 ~21 ~36 stone_stairs 3 
setblock ~3 ~21 ~38 stone_brick_stairs 0 
setblock ~3 ~21 ~40 stone_brick_stairs 6 
setblock ~3 ~21 ~41 stone_brick_stairs 7 
setblock ~4 ~21 ~3 cobblestone 0  
fill ~4 ~21 ~4 ~4 ~21 ~12 sandstone 
setblock ~4 ~21 ~13 cobblestone 0 
setblock ~4 ~21 ~30 cobblestone 0  
fill ~4 ~21 ~31 ~4 ~21 ~39 sandstone 
setblock ~4 ~21 ~40 cobblestone 0  
fill ~5 ~21 ~3 ~7 ~21 ~3 brick_stairs  
fill ~5 ~21 ~13 ~7 ~21 ~13 brick_stairs  
fill ~5 ~21 ~30 ~7 ~21 ~30 brick_stairs  
fill ~5 ~21 ~40 ~7 ~21 ~40 brick_stairs 
setblock ~8 ~21 ~2 stone_brick_stairs 6 
setblock ~8 ~21 ~3 stone_brick_stairs 7 
setblock ~8 ~21 ~5 stone_brick_stairs 0 
setblock ~8 ~21 ~7 stone_stairs 2 
setblock ~8 ~21 ~9 stone_stairs 3 
setblock ~8 ~21 ~11 stone_brick_stairs 0 
setblock ~8 ~21 ~13 stone_brick_stairs 6 
setblock ~8 ~21 ~14 stone_brick_stairs 7 
setblock ~8 ~21 ~29 stone_brick_stairs 6 
setblock ~8 ~21 ~30 stone_brick_stairs 7 
setblock ~8 ~21 ~32 stone_brick_stairs 0 
setblock ~8 ~21 ~34 stone_stairs 2 
setblock ~8 ~21 ~36 stone_stairs 3 
setblock ~8 ~21 ~38 stone_brick_stairs 0 
setblock ~8 ~21 ~40 stone_brick_stairs 6 
setblock ~8 ~21 ~41 stone_brick_stairs 7  
fill ~9 ~21 ~3 ~10 ~21 ~3 brick_stairs  
fill ~9 ~21 ~13 ~10 ~21 ~13 brick_stairs  
fill ~9 ~21 ~30 ~10 ~21 ~30 brick_stairs  
fill ~9 ~21 ~40 ~10 ~21 ~40 brick_stairs 
setblock ~10 ~21 ~2 stone_brick_stairs 0 
setblock ~10 ~21 ~41 stone_brick_stairs 0 
setblock ~11 ~21 ~3 stonebrick 0 
setblock ~11 ~21 ~8 brick_stairs 0 
setblock ~11 ~21 ~13 brick_stairs 0  
fill ~11 ~21 ~14 ~11 ~22 ~14 stonebrick  
fill ~11 ~21 ~15 ~11 ~21 ~18 brick_stairs  
fill ~11 ~21 ~19 ~11 ~22 ~19 stonebrick  
fill ~11 ~21 ~20 ~11 ~21 ~23 brick_stairs  
fill ~11 ~21 ~24 ~11 ~22 ~24 stonebrick  
fill ~11 ~21 ~25 ~11 ~21 ~28 brick_stairs  
fill ~11 ~21 ~29 ~11 ~22 ~29 stonebrick 
setblock ~11 ~21 ~30 brick_stairs 0 
setblock ~11 ~21 ~35 brick_stairs 0 
setblock ~11 ~21 ~40 stonebrick 0  
fill ~12 ~21 ~3 ~19 ~21 ~3 stone_brick_stairs  
fill ~12 ~21 ~4 ~28 ~21 ~4 sandstone 
setblock ~12 ~21 ~5 stone_brick_stairs 0 
setblock ~12 ~21 ~7 stone_stairs 2 
setblock ~12 ~21 ~9 stone_stairs 3 
setblock ~12 ~21 ~11 stone_brick_stairs 0 
setblock ~12 ~21 ~13 stone_brick_stairs 6 
setblock ~12 ~21 ~30 stone_brick_stairs 7 
setblock ~12 ~21 ~32 stone_brick_stairs 0 
setblock ~12 ~21 ~34 stone_stairs 2 
setblock ~12 ~21 ~36 stone_stairs 3 
setblock ~12 ~21 ~38 stone_brick_stairs 0  
fill ~12 ~21 ~39 ~28 ~21 ~39 sandstone  
fill ~12 ~21 ~40 ~19 ~21 ~40 stone_brick_stairs 
setblock ~20 ~21 ~3 double_stone_slab 5 
setblock ~20 ~21 ~40 double_stone_slab 5  
fill ~21 ~21 ~3 ~28 ~21 ~3 stone_brick_stairs  
fill ~21 ~21 ~40 ~28 ~21 ~40 stone_brick_stairs  
fill ~29 ~21 ~2 ~29 ~22 ~2 stonebrick  
fill ~29 ~21 ~3 ~29 ~21 ~4 stonebrick  
fill ~29 ~21 ~5 ~29 ~21 ~8 brick_stairs  
fill ~29 ~21 ~9 ~29 ~22 ~9 stonebrick  
fill ~29 ~21 ~10 ~29 ~21 ~13 brick_stairs  
fill ~29 ~21 ~14 ~29 ~22 ~14 stonebrick  
fill ~29 ~21 ~15 ~29 ~21 ~18 brick_stairs  
fill ~29 ~21 ~19 ~29 ~22 ~19 stonebrick  
fill ~29 ~21 ~20 ~29 ~21 ~23 brick_stairs  
fill ~29 ~21 ~24 ~29 ~22 ~24 stonebrick  
fill ~29 ~21 ~25 ~29 ~21 ~28 brick_stairs  
fill ~29 ~21 ~29 ~29 ~22 ~29 stonebrick  
fill ~29 ~21 ~30 ~29 ~21 ~33 brick_stairs  
fill ~29 ~21 ~34 ~29 ~22 ~34 stonebrick  
fill ~29 ~21 ~35 ~29 ~21 ~38 brick_stairs  
fill ~29 ~21 ~39 ~29 ~22 ~39 stonebrick  
fill ~29 ~21 ~40 ~29 ~21 ~41 stonebrick 
setblock ~30 ~21 ~2 stone_brick_stairs 1 
setblock ~30 ~21 ~41 stone_brick_stairs 1 
setblock ~3 ~22 ~2 anvil 2 
setblock ~3 ~22 ~3 stonebrick 0 
setblock ~3 ~22 ~4 stone_brick_stairs 3  
fill ~3 ~22 ~5 ~3 ~23 ~5 fence 
setblock ~3 ~22 ~7 stone_stairs 6 
setblock ~3 ~22 ~8 stone_slab 3 
setblock ~3 ~22 ~9 stone_stairs 7  
fill ~3 ~22 ~11 ~3 ~23 ~11 fence 
setblock ~3 ~22 ~12 stone_brick_stairs 2 
setblock ~3 ~22 ~13 stonebrick 0 
setblock ~3 ~22 ~14 anvil 2 
setblock ~3 ~22 ~29 anvil 2 
setblock ~3 ~22 ~30 stonebrick 0 
setblock ~3 ~22 ~31 stone_brick_stairs 3  
fill ~3 ~22 ~32 ~3 ~23 ~32 fence 
setblock ~3 ~22 ~34 stone_stairs 6 
setblock ~3 ~22 ~35 stone_slab 3 
setblock ~3 ~22 ~36 stone_stairs 7  
fill ~3 ~22 ~38 ~3 ~23 ~38 fence 
setblock ~3 ~22 ~39 stone_brick_stairs 2 
setblock ~3 ~22 ~40 stonebrick 0 
setblock ~3 ~22 ~41 anvil 2  
fill ~4 ~22 ~3 ~7 ~22 ~3 stone_stairs  
fill ~4 ~22 ~4 ~4 ~23 ~4 cobblestone  
fill ~4 ~22 ~5 ~4 ~23 ~5 sandstone 
setblock ~4 ~22 ~6 sandstone 1  
fill ~4 ~22 ~7 ~4 ~27 ~7 sandstone  
fill ~4 ~22 ~8 ~4 ~22 ~9 sandstone 
setblock ~4 ~22 ~10 sandstone 1  
fill ~4 ~22 ~11 ~4 ~23 ~11 sandstone  
fill ~4 ~22 ~12 ~4 ~23 ~12 cobblestone  
fill ~4 ~22 ~13 ~7 ~22 ~13 stone_stairs  
fill ~4 ~22 ~30 ~7 ~22 ~30 stone_stairs  
fill ~4 ~22 ~31 ~4 ~23 ~31 cobblestone  
fill ~4 ~22 ~32 ~4 ~23 ~32 sandstone 
setblock ~4 ~22 ~33 sandstone 1  
fill ~4 ~22 ~34 ~4 ~27 ~34 sandstone  
fill ~4 ~22 ~35 ~4 ~22 ~36 sandstone 
setblock ~4 ~22 ~37 sandstone 1  
fill ~4 ~22 ~38 ~4 ~23 ~38 sandstone  
fill ~4 ~22 ~39 ~4 ~23 ~39 cobblestone  
fill ~4 ~22 ~40 ~7 ~22 ~40 stone_stairs  
fill ~5 ~22 ~4 ~7 ~22 ~4 brick_block  
fill ~5 ~22 ~12 ~7 ~22 ~12 brick_block  
fill ~5 ~22 ~31 ~7 ~22 ~31 brick_block  
fill ~5 ~22 ~39 ~7 ~22 ~39 brick_block 
setblock ~8 ~22 ~3 stonebrick 0 
setblock ~8 ~22 ~4 stone_brick_stairs 3  
fill ~8 ~22 ~5 ~8 ~23 ~5 fence 
setblock ~8 ~22 ~7 stone_stairs 6 
setblock ~8 ~22 ~8 stone_slab 3 
setblock ~8 ~22 ~9 stone_stairs 7  
fill ~8 ~22 ~11 ~8 ~23 ~11 fence 
setblock ~8 ~22 ~12 stone_brick_stairs 2 
setblock ~8 ~22 ~13 stonebrick 0 
setblock ~8 ~22 ~30 stonebrick 0 
setblock ~8 ~22 ~31 stone_brick_stairs 3  
fill ~8 ~22 ~32 ~8 ~23 ~32 fence 
setblock ~8 ~22 ~34 stone_stairs 6 
setblock ~8 ~22 ~35 stone_slab 3 
setblock ~8 ~22 ~36 stone_stairs 7  
fill ~8 ~22 ~38 ~8 ~23 ~38 fence 
setblock ~8 ~22 ~39 stone_brick_stairs 2 
setblock ~8 ~22 ~40 stonebrick 0  
fill ~9 ~22 ~3 ~10 ~22 ~3 stone_stairs  
fill ~9 ~22 ~4 ~10 ~22 ~4 brick_block  
fill ~9 ~22 ~12 ~10 ~22 ~12 brick_block  
fill ~9 ~22 ~13 ~10 ~22 ~13 stone_stairs  
fill ~9 ~22 ~30 ~10 ~22 ~30 stone_stairs  
fill ~9 ~22 ~31 ~10 ~22 ~31 brick_block  
fill ~9 ~22 ~39 ~10 ~22 ~39 brick_block  
fill ~9 ~22 ~40 ~10 ~22 ~40 stone_stairs 
setblock ~10 ~22 ~2 stone_slab 5 
setblock ~10 ~22 ~41 stone_slab 5 
setblock ~11 ~22 ~3 stone_stairs 4 
setblock ~11 ~22 ~8 stone_stairs 4 
setblock ~11 ~22 ~13 stone_stairs 4  
fill ~11 ~22 ~15 ~11 ~22 ~18 stone_stairs  
fill ~11 ~22 ~20 ~11 ~22 ~23 stone_stairs  
fill ~11 ~22 ~25 ~11 ~22 ~28 stone_stairs 
setblock ~11 ~22 ~30 stone_stairs 4 
setblock ~11 ~22 ~35 stone_stairs 4 
setblock ~11 ~22 ~40 stone_stairs 4 
setblock ~12 ~22 ~2 stone_brick_stairs 1  
fill ~12 ~22 ~3 ~12 ~23 ~3 stonebrick  
fill ~12 ~22 ~4 ~28 ~22 ~4 sandstone  
fill ~12 ~22 ~5 ~12 ~23 ~5 fence 
setblock ~12 ~22 ~6 brick_block 0 
setblock ~12 ~22 ~7 stone_stairs 6 
setblock ~12 ~22 ~8 stone_slab 3 
setblock ~12 ~22 ~9 stone_stairs 7  
fill ~12 ~22 ~11 ~12 ~23 ~11 fence 
setblock ~12 ~22 ~12 stone_brick_stairs 2 
setblock ~12 ~22 ~13 stonebrick 0  
fill ~12 ~22 ~15 ~12 ~22 ~18 brick_block 
setblock ~12 ~22 ~19 cobblestone 0  
fill ~12 ~22 ~20 ~12 ~22 ~23 brick_block 
setblock ~12 ~22 ~24 cobblestone 0  
fill ~12 ~22 ~25 ~12 ~22 ~28 brick_block 
setblock ~12 ~22 ~30 stonebrick 0 
setblock ~12 ~22 ~31 stone_brick_stairs 3  
fill ~12 ~22 ~32 ~12 ~23 ~32 fence 
setblock ~12 ~22 ~34 stone_stairs 6 
setblock ~12 ~22 ~35 stone_slab 3 
setblock ~12 ~22 ~36 stone_stairs 7 
setblock ~12 ~22 ~37 brick_block 0  
fill ~12 ~22 ~38 ~12 ~23 ~38 fence  
fill ~12 ~22 ~39 ~28 ~22 ~39 sandstone  
fill ~12 ~22 ~40 ~12 ~23 ~40 stonebrick 
setblock ~12 ~22 ~41 stone_brick_stairs 1  
fill ~13 ~22 ~3 ~19 ~22 ~3 stone_brick_stairs  
fill ~13 ~22 ~40 ~19 ~22 ~40 stone_brick_stairs  
fill ~20 ~22 ~3 ~20 ~23 ~3 stonebrick  
fill ~20 ~22 ~40 ~20 ~23 ~40 stonebrick  
fill ~21 ~22 ~3 ~27 ~22 ~3 stone_brick_stairs  
fill ~21 ~22 ~40 ~27 ~22 ~40 stone_brick_stairs 
setblock ~28 ~22 ~2 stone_brick_stairs 0  
fill ~28 ~22 ~3 ~28 ~23 ~3 stonebrick  
fill ~28 ~22 ~5 ~28 ~22 ~8 brick_block 
setblock ~28 ~22 ~9 cobblestone 0  
fill ~28 ~22 ~10 ~28 ~22 ~13 brick_block 
setblock ~28 ~22 ~14 cobblestone 0  
fill ~28 ~22 ~15 ~28 ~22 ~18 brick_block 
setblock ~28 ~22 ~19 cobblestone 0  
fill ~28 ~22 ~20 ~28 ~22 ~23 brick_block 
setblock ~28 ~22 ~24 cobblestone 0  
fill ~28 ~22 ~25 ~28 ~22 ~28 brick_block 
setblock ~28 ~22 ~29 cobblestone 0  
fill ~28 ~22 ~30 ~28 ~22 ~33 brick_block 
setblock ~28 ~22 ~34 cobblestone 0  
fill ~28 ~22 ~35 ~28 ~22 ~38 brick_block  
fill ~28 ~22 ~40 ~28 ~23 ~40 stonebrick 
setblock ~28 ~22 ~41 stone_brick_stairs 0 
setblock ~29 ~22 ~3 brick_stairs 1 
setblock ~29 ~22 ~4 stonebrick 0  
fill ~29 ~22 ~5 ~29 ~22 ~8 stone_stairs  
fill ~29 ~22 ~10 ~29 ~22 ~13 stone_stairs  
fill ~29 ~22 ~15 ~29 ~22 ~18 stone_stairs  
fill ~29 ~22 ~20 ~29 ~22 ~23 stone_stairs  
fill ~29 ~22 ~25 ~29 ~22 ~28 stone_stairs  
fill ~29 ~22 ~30 ~29 ~22 ~33 stone_stairs  
fill ~29 ~22 ~35 ~29 ~22 ~38 stone_stairs 
setblock ~29 ~22 ~40 brick_stairs 1 
setblock ~29 ~22 ~41 stonebrick 0 
setblock ~30 ~22 ~2 stone_slab 5 
setblock ~30 ~22 ~41 stone_slab 5 
setblock ~3 ~23 ~2 cobblestone_wall 0 
setblock ~3 ~23 ~3 stone_brick_stairs 6 
setblock ~3 ~23 ~4 stone_brick_stairs 7  
fill ~3 ~23 ~6 ~3 ~24 ~6 fence  
fill ~3 ~23 ~7 ~3 ~24 ~7 cobblestone_wall  
fill ~3 ~23 ~9 ~3 ~24 ~9 cobblestone_wall  
fill ~3 ~23 ~10 ~3 ~24 ~10 fence 
setblock ~3 ~23 ~12 stone_brick_stairs 6 
setblock ~3 ~23 ~13 stone_brick_stairs 7 
setblock ~3 ~23 ~14 cobblestone_wall 0 
setblock ~3 ~23 ~29 cobblestone_wall 0 
setblock ~3 ~23 ~30 stone_brick_stairs 6 
setblock ~3 ~23 ~31 stone_brick_stairs 7  
fill ~3 ~23 ~33 ~3 ~24 ~33 fence  
fill ~3 ~23 ~34 ~3 ~24 ~34 cobblestone_wall  
fill ~3 ~23 ~36 ~3 ~24 ~36 cobblestone_wall  
fill ~3 ~23 ~37 ~3 ~24 ~37 fence 
setblock ~3 ~23 ~39 stone_brick_stairs 6 
setblock ~3 ~23 ~40 stone_brick_stairs 7 
setblock ~3 ~23 ~41 cobblestone_wall 0  
fill ~4 ~23 ~6 ~4 ~25 ~6 sandstone  
fill ~4 ~23 ~8 ~4 ~24 ~8 iron_bars  
fill ~4 ~23 ~9 ~4 ~27 ~9 sandstone  
fill ~4 ~23 ~10 ~4 ~25 ~10 sandstone  
fill ~4 ~23 ~33 ~4 ~25 ~33 sandstone  
fill ~4 ~23 ~35 ~4 ~24 ~35 iron_bars  
fill ~4 ~23 ~36 ~4 ~27 ~36 sandstone  
fill ~4 ~23 ~37 ~4 ~25 ~37 sandstone  
fill ~5 ~23 ~4 ~7 ~23 ~4 brick_stairs  
fill ~5 ~23 ~12 ~7 ~23 ~12 brick_stairs  
fill ~5 ~23 ~31 ~7 ~23 ~31 brick_stairs  
fill ~5 ~23 ~39 ~7 ~23 ~39 brick_stairs 
setblock ~8 ~23 ~3 stone_brick_stairs 6 
setblock ~8 ~23 ~4 stone_brick_stairs 7  
fill ~8 ~23 ~6 ~8 ~24 ~6 fence  
fill ~8 ~23 ~7 ~8 ~24 ~7 cobblestone_wall  
fill ~8 ~23 ~9 ~8 ~24 ~9 cobblestone_wall  
fill ~8 ~23 ~10 ~8 ~24 ~10 fence 
setblock ~8 ~23 ~12 stone_brick_stairs 6 
setblock ~8 ~23 ~13 stone_brick_stairs 7 
setblock ~8 ~23 ~30 stone_brick_stairs 6 
setblock ~8 ~23 ~31 stone_brick_stairs 7  
fill ~8 ~23 ~33 ~8 ~24 ~33 fence  
fill ~8 ~23 ~34 ~8 ~24 ~34 cobblestone_wall  
fill ~8 ~23 ~36 ~8 ~24 ~36 cobblestone_wall  
fill ~8 ~23 ~37 ~8 ~24 ~37 fence 
setblock ~8 ~23 ~39 stone_brick_stairs 6 
setblock ~8 ~23 ~40 stone_brick_stairs 7  
fill ~9 ~23 ~4 ~11 ~23 ~4 brick_stairs  
fill ~9 ~23 ~12 ~11 ~23 ~12 brick_stairs  
fill ~9 ~23 ~31 ~11 ~23 ~31 brick_stairs  
fill ~9 ~23 ~39 ~11 ~23 ~39 brick_stairs 
setblock ~11 ~23 ~2 stone_brick_stairs 0 
setblock ~11 ~23 ~14 stone_brick_stairs 4 
setblock ~11 ~23 ~19 stone_brick_stairs 4 
setblock ~11 ~23 ~24 stone_brick_stairs 4 
setblock ~11 ~23 ~29 stone_brick_stairs 4 
setblock ~11 ~23 ~41 stone_brick_stairs 0  
fill ~12 ~23 ~2 ~12 ~24 ~2 stonebrick 
setblock ~12 ~23 ~4 brick_block 0  
fill ~12 ~23 ~6 ~12 ~24 ~6 fence  
fill ~12 ~23 ~7 ~12 ~24 ~7 cobblestone_wall 
setblock ~12 ~23 ~8 brick_stairs 0  
fill ~12 ~23 ~9 ~12 ~24 ~9 cobblestone_wall  
fill ~12 ~23 ~10 ~12 ~24 ~10 fence 
setblock ~12 ~23 ~12 stone_brick_stairs 6 
setblock ~12 ~23 ~13 stone_brick_stairs 7  
fill ~12 ~23 ~14 ~12 ~24 ~14 stonebrick  
fill ~12 ~23 ~15 ~12 ~23 ~18 brick_stairs  
fill ~12 ~23 ~19 ~12 ~24 ~19 stonebrick  

KittysCommands:   
fill ~12 ~23 ~20 ~12 ~23 ~23 brick_stairs  
fill ~12 ~23 ~24 ~12 ~24 ~24 stonebrick  
fill ~12 ~23 ~25 ~12 ~23 ~28 brick_stairs  
fill ~12 ~23 ~29 ~12 ~24 ~29 stonebrick 
setblock ~12 ~23 ~30 stone_brick_stairs 6 
setblock ~12 ~23 ~31 stone_brick_stairs 7  
fill ~12 ~23 ~33 ~12 ~24 ~33 fence  
fill ~12 ~23 ~34 ~12 ~24 ~34 cobblestone_wall 
setblock ~12 ~23 ~35 brick_stairs 0  
fill ~12 ~23 ~36 ~12 ~24 ~36 cobblestone_wall  
fill ~12 ~23 ~37 ~12 ~24 ~37 fence 
setblock ~12 ~23 ~39 brick_block 0  
fill ~12 ~23 ~41 ~12 ~24 ~41 stonebrick  
fill ~13 ~23 ~4 ~15 ~23 ~4 sandstone 
setblock ~13 ~23 ~13 stonebrick 0 
setblock ~13 ~23 ~30 stonebrick 0  
fill ~13 ~23 ~39 ~15 ~23 ~39 sandstone 
setblock ~14 ~23 ~3 cobblestone_wall 0 
setblock ~14 ~23 ~40 cobblestone_wall 0 
setblock ~16 ~23 ~3 cobblestone_wall 0  
fill ~16 ~23 ~4 ~16 ~25 ~4 sandstone  
fill ~16 ~23 ~39 ~16 ~25 ~39 sandstone 
setblock ~16 ~23 ~40 cobblestone_wall 0  
fill ~17 ~23 ~4 ~23 ~23 ~4 sandstone  
fill ~17 ~23 ~39 ~23 ~23 ~39 sandstone 
setblock ~19 ~23 ~3 stone_slab 13 
setblock ~19 ~23 ~40 stone_slab 13 
setblock ~21 ~23 ~3 stone_slab 13 
setblock ~21 ~23 ~40 stone_slab 13 
setblock ~24 ~23 ~3 cobblestone_wall 0  
fill ~24 ~23 ~4 ~24 ~25 ~4 sandstone  
fill ~24 ~23 ~39 ~24 ~25 ~39 sandstone 
setblock ~24 ~23 ~40 cobblestone_wall 0  
fill ~25 ~23 ~4 ~27 ~23 ~4 sandstone  
fill ~25 ~23 ~39 ~27 ~23 ~39 sandstone 
setblock ~26 ~23 ~3 cobblestone_wall 0 
setblock ~26 ~23 ~40 cobblestone_wall 0  
fill ~28 ~23 ~2 ~28 ~24 ~2 stonebrick  
fill ~28 ~23 ~4 ~28 ~24 ~4 stonebrick  
fill ~28 ~23 ~5 ~28 ~23 ~8 brick_stairs  
fill ~28 ~23 ~9 ~28 ~24 ~9 stonebrick  
fill ~28 ~23 ~10 ~28 ~23 ~13 brick_stairs  
fill ~28 ~23 ~14 ~28 ~24 ~14 stonebrick  
fill ~28 ~23 ~15 ~28 ~23 ~18 brick_stairs  
fill ~28 ~23 ~19 ~28 ~24 ~19 stonebrick  
fill ~28 ~23 ~20 ~28 ~23 ~23 brick_stairs  
fill ~28 ~23 ~24 ~28 ~24 ~24 stonebrick  
fill ~28 ~23 ~25 ~28 ~23 ~28 brick_stairs  
fill ~28 ~23 ~29 ~28 ~24 ~29 stonebrick  
fill ~28 ~23 ~30 ~28 ~23 ~33 brick_stairs  
fill ~28 ~23 ~34 ~28 ~24 ~34 stonebrick  
fill ~28 ~23 ~35 ~28 ~23 ~38 brick_stairs  
fill ~28 ~23 ~39 ~28 ~24 ~39 stonebrick  
fill ~28 ~23 ~41 ~28 ~24 ~41 stonebrick 
setblock ~29 ~23 ~2 stone_brick_stairs 1 
setblock ~29 ~23 ~4 stone_brick_stairs 5 
setblock ~29 ~23 ~9 stone_brick_stairs 5 
setblock ~29 ~23 ~14 stone_brick_stairs 5 
setblock ~29 ~23 ~19 stone_brick_stairs 5 
setblock ~29 ~23 ~24 stone_brick_stairs 5 
setblock ~29 ~23 ~29 stone_brick_stairs 5 
setblock ~29 ~23 ~34 stone_brick_stairs 5 
setblock ~29 ~23 ~39 stone_brick_stairs 5 
setblock ~29 ~23 ~41 stone_brick_stairs 1  
fill ~3 ~24 ~2 ~3 ~25 ~2 fence 
setblock ~3 ~24 ~4 stonebrick 0 
setblock ~3 ~24 ~5 stone_brick_stairs 3 
setblock ~3 ~24 ~11 stone_brick_stairs 2 
setblock ~3 ~24 ~12 stonebrick 0  
fill ~3 ~24 ~14 ~3 ~25 ~14 fence  
fill ~3 ~24 ~29 ~3 ~25 ~29 fence 
setblock ~3 ~24 ~31 stonebrick 0 
setblock ~3 ~24 ~32 stone_brick_stairs 3 
setblock ~3 ~24 ~38 stone_brick_stairs 2 
setblock ~3 ~24 ~39 stonebrick 0  
fill ~3 ~24 ~41 ~3 ~25 ~41 fence  
fill ~4 ~24 ~4 ~7 ~24 ~4 stone_stairs  
fill ~4 ~24 ~5 ~4 ~25 ~5 cobblestone  
fill ~4 ~24 ~11 ~4 ~25 ~11 cobblestone  
fill ~4 ~24 ~12 ~7 ~24 ~12 stone_stairs  
fill ~4 ~24 ~31 ~7 ~24 ~31 stone_stairs  
fill ~4 ~24 ~32 ~4 ~25 ~32 cobblestone  
fill ~4 ~24 ~38 ~4 ~25 ~38 cobblestone  
fill ~4 ~24 ~39 ~7 ~24 ~39 stone_stairs  
fill ~5 ~24 ~5 ~7 ~24 ~5 brick_block  
fill ~5 ~24 ~11 ~7 ~24 ~11 brick_block  
fill ~5 ~24 ~32 ~7 ~24 ~32 brick_block  
fill ~5 ~24 ~38 ~7 ~24 ~38 brick_block 
setblock ~8 ~24 ~4 stonebrick 0 
setblock ~8 ~24 ~5 stone_brick_stairs 3 
setblock ~8 ~24 ~11 stone_brick_stairs 2 
setblock ~8 ~24 ~12 stonebrick 0 
setblock ~8 ~24 ~31 stonebrick 0 
setblock ~8 ~24 ~32 stone_brick_stairs 3 
setblock ~8 ~24 ~38 stone_brick_stairs 2 
setblock ~8 ~24 ~39 stonebrick 0  
fill ~9 ~24 ~4 ~11 ~24 ~4 stone_stairs  
fill ~9 ~24 ~12 ~11 ~24 ~12 stone_stairs  
fill ~9 ~24 ~31 ~11 ~24 ~31 stone_stairs  
fill ~9 ~24 ~39 ~11 ~24 ~39 stone_stairs 
setblock ~11 ~24 ~2 stone_slab 5 
setblock ~11 ~24 ~41 stone_slab 5 
setblock ~12 ~24 ~3 brick_stairs 0 
setblock ~12 ~24 ~4 stonebrick 0 
setblock ~12 ~24 ~5 stone_brick_stairs 3 
setblock ~12 ~24 ~8 brick_stairs 4 
setblock ~12 ~24 ~11 stone_brick_stairs 2 
setblock ~12 ~24 ~12 stonebrick 0  
fill ~12 ~24 ~15 ~12 ~24 ~18 brick_stairs  
fill ~12 ~24 ~20 ~12 ~24 ~23 brick_stairs  
fill ~12 ~24 ~25 ~12 ~24 ~28 brick_stairs 
setblock ~12 ~24 ~31 stonebrick 0 
setblock ~12 ~24 ~32 stone_brick_stairs 3 
setblock ~12 ~24 ~35 brick_stairs 4 
setblock ~12 ~24 ~38 stone_brick_stairs 2 
setblock ~12 ~24 ~39 stonebrick 0 
setblock ~12 ~24 ~40 brick_stairs 0  
