    
fill ~3 ~0 ~5 ~4 ~0 ~5 stonebrick  
fill ~3 ~0 ~11 ~4 ~0 ~11 stonebrick  
fill ~3 ~0 ~33 ~4 ~0 ~33 stonebrick  
fill ~3 ~0 ~39 ~4 ~0 ~39 stonebrick 
setblock ~4 ~0 ~4 stonebrick 0 
setblock ~4 ~0 ~6 stone_brick_stairs 3 
setblock ~4 ~0 ~7 stone_brick_stairs 4 
setblock ~4 ~0 ~8 cobblestone_wall 0 
setblock ~4 ~0 ~9 stone_brick_stairs 4 
setblock ~4 ~0 ~10 stone_brick_stairs 2  
fill ~4 ~0 ~12 ~6 ~0 ~12 stonebrick  
fill ~4 ~0 ~32 ~6 ~0 ~32 stonebrick 
setblock ~4 ~0 ~34 stone_brick_stairs 3 
setblock ~4 ~0 ~35 stone_brick_stairs 4 
setblock ~4 ~0 ~36 cobblestone_wall 0 
setblock ~4 ~0 ~37 stone_brick_stairs 4 
setblock ~4 ~0 ~38 stone_brick_stairs 2 
setblock ~4 ~0 ~40 stonebrick 0 
setblock ~5 ~0 ~5 stone_brick_stairs 1  
fill ~5 ~0 ~6 ~9 ~0 ~6 brick_block  
fill ~5 ~0 ~7 ~5 ~1 ~7 brick_block  
fill ~5 ~0 ~8 ~5 ~1 ~8 brick_block  
fill ~5 ~0 ~9 ~5 ~1 ~9 brick_block  
fill ~5 ~0 ~10 ~9 ~0 ~10 brick_block 
setblock ~5 ~0 ~11 stone_brick_stairs 1  
fill ~5 ~0 ~13 ~6 ~0 ~13 stonebrick  
fill ~5 ~0 ~19 ~6 ~0 ~19 stonebrick 
setblock ~5 ~0 ~20 stone_stairs 2 
setblock ~5 ~0 ~21 stone_slab 5 
setblock ~5 ~0 ~23 stone_slab 5 
setblock ~5 ~0 ~24 stone_stairs 3  
fill ~5 ~0 ~25 ~6 ~0 ~25 stonebrick  
fill ~5 ~0 ~31 ~6 ~0 ~31 stonebrick 
setblock ~5 ~0 ~33 stone_brick_stairs 1  
fill ~5 ~0 ~34 ~9 ~0 ~34 brick_block  
fill ~5 ~0 ~35 ~5 ~1 ~35 brick_block  
fill ~5 ~0 ~36 ~5 ~1 ~36 brick_block  
fill ~5 ~0 ~37 ~5 ~1 ~37 brick_block  
fill ~5 ~0 ~38 ~9 ~0 ~38 brick_block 
setblock ~5 ~0 ~39 stone_brick_stairs 1 
setblock ~6 ~0 ~5 stone_brick_stairs 6  
fill ~6 ~0 ~7 ~8 ~0 ~7 stained_hardened_clay  
fill ~6 ~0 ~8 ~6 ~5 ~8 stained_hardened_clay  
fill ~6 ~0 ~9 ~8 ~0 ~9 stained_hardened_clay  
fill ~6 ~0 ~11 ~6 ~5 ~11 stonebrick 
setblock ~6 ~0 ~14 stonebrick 0 
setblock ~6 ~0 ~15 stone_brick_stairs 4 
setblock ~6 ~0 ~16 cobblestone_wall 0 
setblock ~6 ~0 ~17 stone_brick_stairs 4 
setblock ~6 ~0 ~18 stonebrick 0 
setblock ~6 ~0 ~20 double_stone_slab 3 
setblock ~6 ~0 ~21 double_stone_slab 5 
setblock ~6 ~0 ~22 stone_brick_stairs 0 
setblock ~6 ~0 ~23 double_stone_slab 5 
setblock ~6 ~0 ~24 double_stone_slab 3 
setblock ~6 ~0 ~26 stonebrick 0 
setblock ~6 ~0 ~27 stone_brick_stairs 4 
setblock ~6 ~0 ~28 cobblestone_wall 0 
setblock ~6 ~0 ~29 stone_brick_stairs 4 
setblock ~6 ~0 ~30 stonebrick 0 
setblock ~6 ~0 ~33 stone_brick_stairs 6  
fill ~6 ~0 ~35 ~8 ~0 ~35 stained_hardened_clay  
fill ~6 ~0 ~36 ~6 ~5 ~36 stained_hardened_clay  
fill ~6 ~0 ~37 ~8 ~0 ~37 stained_hardened_clay 
setblock ~6 ~0 ~39 stone_brick_stairs 7 
setblock ~7 ~0 ~5 cobblestone_wall 0 
setblock ~7 ~0 ~11 cobblestone_wall 0  
fill ~7 ~0 ~12 ~7 ~3 ~12 brick_block  
fill ~7 ~0 ~13 ~7 ~4 ~13 brick_block  
fill ~7 ~0 ~14 ~7 ~4 ~14 brick_block  
fill ~7 ~0 ~15 ~7 ~1 ~15 brick_block  
fill ~7 ~0 ~16 ~7 ~1 ~16 brick_block  
fill ~7 ~0 ~17 ~7 ~1 ~17 brick_block  
fill ~7 ~0 ~18 ~7 ~4 ~18 brick_block  
fill ~7 ~0 ~19 ~7 ~4 ~19 brick_block  
fill ~7 ~0 ~20 ~7 ~1 ~20 brick_block  
fill ~7 ~0 ~21 ~7 ~0 ~32 brick_block 
setblock ~7 ~0 ~33 cobblestone_wall 0 
setblock ~7 ~0 ~39 cobblestone_wall 0 
setblock ~8 ~0 ~5 stone_brick_stairs 6  
fill ~8 ~0 ~8 ~8 ~5 ~8 stained_hardened_clay 
setblock ~8 ~0 ~11 stone_brick_stairs 7  
fill ~8 ~0 ~20 ~8 ~1 ~20 stained_hardened_clay  
fill ~8 ~0 ~21 ~8 ~4 ~21 stained_hardened_clay  
fill ~8 ~0 ~22 ~8 ~1 ~22 stained_hardened_clay  
fill ~8 ~0 ~23 ~8 ~4 ~23 stained_hardened_clay  
fill ~8 ~0 ~24 ~8 ~1 ~24 stained_hardened_clay 
setblock ~8 ~0 ~33 stone_brick_stairs 6  
fill ~8 ~0 ~36 ~8 ~5 ~36 stained_hardened_clay 
setblock ~8 ~0 ~39 stone_brick_stairs 7 
setblock ~9 ~0 ~5 stone_brick_stairs 0  
fill ~9 ~0 ~7 ~9 ~1 ~7 brick_block  
fill ~9 ~0 ~8 ~9 ~1 ~8 brick_block  
fill ~9 ~0 ~9 ~9 ~1 ~9 brick_block  
fill ~9 ~0 ~11 ~31 ~0 ~11 stonebrick 
setblock ~9 ~0 ~12 stone_brick_stairs 0  
fill ~9 ~0 ~22 ~10 ~0 ~22 stonebrick 
setblock ~9 ~0 ~31 stone_brick_stairs 0  
fill ~9 ~0 ~32 ~12 ~0 ~32 stonebrick 
setblock ~9 ~0 ~33 stone_brick_stairs 0  
fill ~9 ~0 ~35 ~9 ~1 ~35 brick_block  
fill ~9 ~0 ~36 ~9 ~1 ~36 brick_block  
fill ~9 ~0 ~37 ~9 ~1 ~37 brick_block 
setblock ~9 ~0 ~39 stone_brick_stairs 0  
fill ~10 ~0 ~4 ~10 ~0 ~5 stonebrick 
setblock ~10 ~0 ~6 stone_brick_stairs 3 
setblock ~10 ~0 ~7 stone_brick_stairs 5 
setblock ~10 ~0 ~8 cobblestone_wall 0 
setblock ~10 ~0 ~9 stone_brick_stairs 5 
setblock ~10 ~0 ~10 stone_brick_stairs 2  
fill ~10 ~0 ~12 ~12 ~0 ~12 stonebrick 
setblock ~10 ~0 ~13 stonebrick 3  
fill ~10 ~0 ~14 ~10 ~3 ~14 stonebrick  
fill ~10 ~0 ~15 ~10 ~2 ~15 stonebrick  
fill ~10 ~0 ~16 ~10 ~4 ~16 stonebrick  
fill ~10 ~0 ~17 ~10 ~2 ~17 stonebrick  
fill ~10 ~0 ~18 ~10 ~3 ~18 stonebrick  
fill ~10 ~0 ~19 ~13 ~0 ~19 stonebrick  
fill ~10 ~0 ~20 ~10 ~6 ~20 stonebrick  
fill ~10 ~0 ~21 ~10 ~1 ~21 stonebrick  
fill ~10 ~0 ~23 ~10 ~1 ~23 stonebrick  
fill ~10 ~0 ~24 ~10 ~6 ~24 stonebrick  
fill ~10 ~0 ~25 ~13 ~0 ~25 stonebrick  
fill ~10 ~0 ~26 ~10 ~3 ~26 stonebrick  
fill ~10 ~0 ~27 ~10 ~2 ~27 stonebrick  
fill ~10 ~0 ~28 ~10 ~4 ~28 stonebrick  
fill ~10 ~0 ~29 ~10 ~2 ~29 stonebrick  
fill ~10 ~0 ~30 ~10 ~3 ~30 stonebrick  
fill ~10 ~0 ~31 ~11 ~0 ~31 stonebrick  
fill ~10 ~0 ~33 ~37 ~0 ~33 stonebrick 
setblock ~10 ~0 ~34 stone_brick_stairs 3 
setblock ~10 ~0 ~35 stone_brick_stairs 5 
setblock ~10 ~0 ~36 cobblestone_wall 0 
setblock ~10 ~0 ~37 stone_brick_stairs 5 
setblock ~10 ~0 ~38 stone_brick_stairs 2  
fill ~10 ~0 ~39 ~11 ~0 ~39 stonebrick  
fill ~10 ~0 ~40 ~11 ~0 ~40 stonebrick 
setblock ~10 ~0 ~41 stone_slab 5 
setblock ~10 ~0 ~42 stone_brick_stairs 0 
setblock ~11 ~0 ~5 stonebrick 0 
setblock ~11 ~0 ~6 stone_brick_stairs 0  
fill ~11 ~0 ~7 ~24 ~0 ~7 stonebrick  
fill ~11 ~0 ~13 ~11 ~1 ~13 stonebrick 
setblock ~11 ~0 ~14 stone_brick_stairs 3 
setblock ~11 ~0 ~15 cobblestone_wall 6 
setblock ~11 ~0 ~16 stone_brick_stairs 1 
setblock ~11 ~0 ~17 cobblestone_wall 6 
setblock ~11 ~0 ~18 stone_brick_stairs 2 
setblock ~11 ~0 ~26 stone_brick_stairs 3 
setblock ~11 ~0 ~27 cobblestone_wall 6 
setblock ~11 ~0 ~28 stone_brick_stairs 1 
setblock ~11 ~0 ~29 cobblestone_wall 6 
setblock ~11 ~0 ~30 stone_brick_stairs 2 
setblock ~11 ~0 ~41 stonebrick 3  
fill ~11 ~0 ~42 ~11 ~1 ~42 stonebrick 
setblock ~11 ~0 ~43 stone_slab 5 
setblock ~11 ~0 ~44 stone_brick_stairs 0 
setblock ~12 ~0 ~5 stone_brick_stairs 2 
setblock ~12 ~0 ~6 stone_slab 5 
setblock ~12 ~0 ~13 stonebrick 3  
fill ~12 ~0 ~20 ~12 ~0 ~24 stone_slab 
setblock ~12 ~0 ~26 cobblestone_wall 0 
setblock ~12 ~0 ~31 stonebrick 3 
setblock ~12 ~0 ~43 stonebrick 3  
fill ~12 ~0 ~44 ~12 ~1 ~44 stonebrick 
setblock ~12 ~0 ~45 stone_slab 5 
setblock ~12 ~0 ~46 stone_brick_stairs 0 
setblock ~13 ~0 ~6 stone_brick_stairs 1 
setblock ~13 ~0 ~12 stone_brick_stairs 1  
fill ~13 ~0 ~20 ~13 ~0 ~24 stone_slab 
setblock ~13 ~0 ~32 stone_brick_stairs 1 
setblock ~13 ~0 ~45 stonebrick 3  
fill ~13 ~0 ~46 ~13 ~1 ~46 stonebrick 
setblock ~13 ~0 ~47 stone_slab 5 
setblock ~13 ~0 ~48 stone_brick_stairs 0 
setblock ~14 ~0 ~6 cobblestone_wall 0 
setblock ~14 ~0 ~12 cobblestone_wall 0 
setblock ~14 ~0 ~19 cobblestone_wall 0 
setblock ~14 ~0 ~25 cobblestone_wall 0 
setblock ~14 ~0 ~32 cobblestone_wall 0 
setblock ~14 ~0 ~47 stonebrick 3  
fill ~14 ~0 ~48 ~14 ~1 ~48 stonebrick 
setblock ~14 ~0 ~49 stone_slab 5 
setblock ~14 ~0 ~50 stone_brick_stairs 0 
setblock ~14 ~0 ~53 stone_brick_stairs 0 
setblock ~14 ~0 ~59 stone_brick_stairs 0 
setblock ~14 ~0 ~65 stone_brick_stairs 0 
setblock ~15 ~0 ~6 stone_brick_stairs 0 
setblock ~15 ~0 ~12 stone_brick_stairs 3 
setblock ~15 ~0 ~14 stonebrick 0 
setblock ~15 ~0 ~30 stonebrick 0 
setblock ~15 ~0 ~32 stone_brick_stairs 2 
setblock ~15 ~0 ~49 stonebrick 3  
fill ~15 ~0 ~50 ~15 ~1 ~50 stonebrick 
setblock ~15 ~0 ~51 stone_slab 5 
setblock ~15 ~0 ~52 stone_brick_stairs 2  
fill ~15 ~0 ~53 ~15 ~1 ~53 stonebrick 
setblock ~15 ~0 ~54 stone_brick_stairs 3 
setblock ~15 ~0 ~55 stone_brick_stairs 2 
setblock ~15 ~0 ~56 cobblestone_wall 0 
setblock ~15 ~0 ~57 stone_brick_stairs 3 
setblock ~15 ~0 ~58 stone_brick_stairs 2  
fill ~15 ~0 ~59 ~16 ~0 ~59 stonebrick 
setblock ~15 ~0 ~60 stone_brick_stairs 3 
setblock ~15 ~0 ~61 stone_brick_stairs 2 
setblock ~15 ~0 ~62 cobblestone_wall 0 
setblock ~15 ~0 ~63 stone_brick_stairs 3 
setblock ~15 ~0 ~64 stone_brick_stairs 2  
fill ~15 ~0 ~65 ~15 ~1 ~65 stonebrick 
setblock ~15 ~0 ~66 stone_brick_stairs 3 
setblock ~16 ~0 ~6 stone_slab 5 
setblock ~16 ~0 ~12 cobblestone_wall 0 
setblock ~16 ~0 ~32 cobblestone_wall 0 
setblock ~16 ~0 ~51 stonebrick 3  
fill ~16 ~0 ~52 ~16 ~4 ~52 stonebrick 
setblock ~16 ~0 ~53 stone_brick_stairs 1  
fill ~16 ~0 ~54 ~26 ~0 ~54 stonebrick  
fill ~16 ~0 ~55 ~16 ~0 ~64 stonebrick 
setblock ~16 ~0 ~65 stone_brick_stairs 1 
setblock ~17 ~0 ~6 stone_brick_stairs 1 
setblock ~17 ~0 ~12 stone_brick_stairs 0 
setblock ~17 ~0 ~32 stone_brick_stairs 0 
setblock ~17 ~0 ~53 stone_brick_stairs 0  
fill ~17 ~0 ~64 ~25 ~0 ~64 stonebrick 
setblock ~17 ~0 ~65 stone_brick_stairs 0 
setblock ~18 ~0 ~6 cobblestone_wall 0  
fill ~18 ~0 ~12 ~20 ~0 ~12 stonebrick 
setblock ~18 ~0 ~13 stonebrick 3 
setblock ~18 ~0 ~31 stonebrick 3  
fill ~18 ~0 ~32 ~20 ~0 ~32 stonebrick 
setblock ~18 ~0 ~53 cobblestone_wall 0 
setblock ~18 ~0 ~65 cobblestone_wall 0 
setblock ~19 ~0 ~6 stone_brick_stairs 0  
fill ~19 ~0 ~13 ~19 ~1 ~13 stonebrick 
setblock ~19 ~0 ~14 stone_brick_stairs 3 
setblock ~19 ~0 ~30 stone_brick_stairs 2  
fill ~19 ~0 ~31 ~19 ~1 ~31 stonebrick 
setblock ~19 ~0 ~53 stone_brick_stairs 1 
setblock ~19 ~0 ~65 stone_brick_stairs 1 
setblock ~20 ~0 ~6 stone_slab 5 
setblock ~20 ~0 ~13 stonebrick 3 
setblock ~20 ~0 ~31 stonebrick 3 
setblock ~20 ~0 ~53 stone_brick_stairs 0 
setblock ~20 ~0 ~65 stone_brick_stairs 0 
setblock ~21 ~0 ~6 stone_brick_stairs 1 
setblock ~21 ~0 ~12 stone_brick_stairs 1 
setblock ~21 ~0 ~32 stone_brick_stairs 1 
setblock ~21 ~0 ~52 stone_brick_stairs 2  
fill ~21 ~0 ~53 ~21 ~1 ~53 stonebrick 
setblock ~21 ~0 ~59 stained_hardened_clay 14  
fill ~21 ~0 ~65 ~21 ~1 ~65 stonebrick 
setblock ~21 ~0 ~66 stone_brick_stairs 3 
setblock ~22 ~0 ~6 cobblestone_wall 0 
setblock ~22 ~0 ~12 cobblestone_wall 0 
setblock ~22 ~0 ~32 cobblestone_wall 0 
setblock ~22 ~0 ~53 stone_brick_stairs 1 
setblock ~22 ~0 ~65 stone_brick_stairs 1 
setblock ~23 ~0 ~6 stone_brick_stairs 0 
setblock ~23 ~0 ~12 stone_brick_stairs 3 
setblock ~23 ~0 ~14 stonebrick 0 
setblock ~23 ~0 ~30 stonebrick 0 
setblock ~23 ~0 ~32 stone_brick_stairs 2 
setblock ~23 ~0 ~53 stone_brick_stairs 0 
setblock ~23 ~0 ~65 stone_brick_stairs 0 
setblock ~24 ~0 ~2 stone_brick_stairs 0 
setblock ~24 ~0 ~6 stone_slab 5 
setblock ~24 ~0 ~12 cobblestone_wall 0 
setblock ~24 ~0 ~32 cobblestone_wall 0 
setblock ~24 ~0 ~53 cobblestone_wall 0 
setblock ~24 ~0 ~65 cobblestone_wall 0 
setblock ~25 ~0 ~1 stone_brick_stairs 2  
fill ~25 ~0 ~2 ~25 ~2 ~2 stonebrick 
setblock ~25 ~0 ~3 stone_slab 5 
setblock ~25 ~0 ~4 double_stone_slab 5 
setblock ~25 ~0 ~5 stone_slab 5 
setblock ~25 ~0 ~6 double_stone_slab 5 
setblock ~25 ~0 ~7 stone_slab 5  
fill ~25 ~0 ~8 ~25 ~1 ~8 stonebrick 
setblock ~25 ~0 ~9 stone_brick_stairs 3 
setblock ~25 ~0 ~12 stone_brick_stairs 0 
setblock ~25 ~0 ~32 stone_brick_stairs 0 
setblock ~25 ~0 ~53 stone_brick_stairs 1 
setblock ~25 ~0 ~65 stone_brick_stairs 1 
setblock ~26 ~0 ~2 stone_slab 5 
setblock ~26 ~0 ~3 planks 5  
fill ~26 ~0 ~4 ~26 ~1 ~4 stonebrick 
setblock ~26 ~0 ~5 planks 5  
fill ~26 ~0 ~6 ~26 ~1 ~6 stonebrick 
setblock ~26 ~0 ~7 planks 5 
setblock ~26 ~0 ~8 stone_slab 5  
fill ~26 ~0 ~12 ~28 ~0 ~12 stonebrick 
setblock ~26 ~0 ~13 stonebrick 3 
setblock ~26 ~0 ~31 stonebrick 3  
fill ~26 ~0 ~32 ~28 ~0 ~32 stonebrick 
setblock ~26 ~0 ~53 stone_brick_stairs 0  
fill ~26 ~0 ~55 ~26 ~0 ~63 stonebrick 
setblock ~26 ~0 ~64 cobblestone_wall 0 
setblock ~26 ~0 ~65 stone_brick_stairs 0 
setblock ~27 ~0 ~2 double_stone_slab 5  
fill ~27 ~0 ~3 ~27 ~1 ~3 stonebrick  
fill ~27 ~0 ~7 ~27 ~1 ~7 stonebrick 
setblock ~27 ~0 ~8 double_stone_slab 5  
fill ~27 ~0 ~13 ~27 ~1 ~13 stonebrick 
setblock ~27 ~0 ~14 stone_brick_stairs 3 
setblock ~27 ~0 ~30 stone_brick_stairs 2  
fill ~27 ~0 ~31 ~27 ~1 ~31 stonebrick 
setblock ~27 ~0 ~52 stone_brick_stairs 2  
fill ~27 ~0 ~53 ~27 ~1 ~53 stonebrick 
setblock ~27 ~0 ~54 stone_brick_stairs 3 
setblock ~27 ~0 ~55 stone_brick_stairs 2 
setblock ~27 ~0 ~56 cobblestone_wall 0 
setblock ~27 ~0 ~57 stone_brick_stairs 3 
setblock ~27 ~0 ~58 stone_brick_stairs 2  
fill ~27 ~0 ~59 ~27 ~1 ~59 stonebrick 
setblock ~27 ~0 ~60 stone_brick_stairs 3 
setblock ~27 ~0 ~61 stone_brick_stairs 2 
setblock ~27 ~0 ~62 cobblestone_wall 0 
setblock ~27 ~0 ~63 stone_brick_stairs 3  
fill ~27 ~0 ~64 ~29 ~0 ~64 stonebrick  
fill ~27 ~0 ~65 ~27 ~1 ~65 cobblestone_wall 
setblock ~27 ~0 ~66 stone_brick_stairs 3 
setblock ~28 ~0 ~2 stone_slab 5 
setblock ~28 ~0 ~3 planks 5 
setblock ~28 ~0 ~7 planks 5 
setblock ~28 ~0 ~8 stone_slab 5 
setblock ~28 ~0 ~13 stonebrick 3 
setblock ~28 ~0 ~31 stonebrick 3 
setblock ~28 ~0 ~53 stone_brick_stairs 1 
setblock ~28 ~0 ~59 stone_brick_stairs 1  
fill ~28 ~0 ~63 ~49 ~0 ~63 cobblestone 
setblock ~28 ~0 ~65 stonebrick 0 
setblock ~28 ~0 ~66 cobblestone_wall 0 
setblock ~29 ~0 ~2 double_stone_slab 5  
fill ~29 ~0 ~3 ~29 ~1 ~3 stonebrick  
fill ~29 ~0 ~7 ~29 ~1 ~7 stonebrick 
setblock ~29 ~0 ~8 double_stone_slab 5 
setblock ~29 ~0 ~12 stone_brick_stairs 1 
setblock ~29 ~0 ~32 stone_brick_stairs 1  
fill ~29 ~0 ~65 ~29 ~1 ~65 cobblestone_wall 
setblock ~30 ~0 ~2 stone_slab 5 
setblock ~30 ~0 ~3 planks 5  
fill ~30 ~0 ~4 ~30 ~1 ~4 stonebrick 
setblock ~30 ~0 ~5 planks 5  
fill ~30 ~0 ~6 ~30 ~1 ~6 stonebrick 
setblock ~30 ~0 ~7 planks 5 
setblock ~30 ~0 ~8 stone_slab 5 
setblock ~30 ~0 ~12 cobblestone_wall 0 
setblock ~30 ~0 ~32 cobblestone_wall 0 
setblock ~30 ~0 ~64 cobblestone_wall 0 
setblock ~31 ~0 ~1 stone_brick_stairs 2  
fill ~31 ~0 ~2 ~31 ~2 ~2 stonebrick 
setblock ~31 ~0 ~3 stone_slab 5 
setblock ~31 ~0 ~4 double_stone_slab 5  
fill ~31 ~0 ~5 ~32 ~0 ~5 stone_slab 
setblock ~31 ~0 ~6 double_stone_slab 5  
fill ~31 ~0 ~7 ~32 ~0 ~7 stone_slab  
fill ~31 ~0 ~8 ~31 ~2 ~8 stonebrick 
setblock ~31 ~0 ~9 stone_brick_stairs 3 
setblock ~31 ~0 ~12 stone_brick_stairs 3 
setblock ~31 ~0 ~14 stonebrick 0 
setblock ~31 ~0 ~30 stonebrick 0 
setblock ~31 ~0 ~32 stone_brick_stairs 2  
fill ~31 ~0 ~64 ~32 ~0 ~64 stone_brick_stairs 
setblock ~32 ~0 ~2 stone_brick_stairs 1  
fill ~32 ~0 ~6 ~34 ~0 ~6 stonebrick 
setblock ~32 ~0 ~8 stone_brick_stairs 1 
setblock ~32 ~0 ~10 stone_brick_stairs 0 
setblock ~32 ~0 ~12 cobblestone_wall 0 
setblock ~32 ~0 ~32 cobblestone_wall 0 
setblock ~33 ~0 ~5 stonebrick 0 
setblock ~33 ~0 ~7 stonebrick 0 
setblock ~33 ~0 ~9 stone_brick_stairs 2 
setblock ~33 ~0 ~11 stone_brick_stairs 3 
setblock ~33 ~0 ~12 stone_brick_stairs 0 
setblock ~33 ~0 ~32 stone_brick_stairs 0 
setblock ~33 ~0 ~64 cobblestone_wall 0 
setblock ~34 ~0 ~5 stone_slab 5 
setblock ~34 ~0 ~7 stone_slab 5 
setblock ~34 ~0 ~10 stone_brick_stairs 1  
fill ~34 ~0 ~12 ~36 ~0 ~12 stonebrick 
setblock ~34 ~0 ~13 stonebrick 3 
setblock ~34 ~0 ~31 stonebrick 3  
fill ~34 ~0 ~32 ~37 ~0 ~32 stonebrick  
fill ~34 ~0 ~64 ~36 ~0 ~64 stonebrick  
fill ~34 ~0 ~65 ~34 ~1 ~65 cobblestone_wall  
fill ~35 ~0 ~6 ~37 ~0 ~6 iron_bars 
setblock ~35 ~0 ~10 stone_brick_stairs 0  
fill ~35 ~0 ~13 ~35 ~1 ~13 stonebrick 
setblock ~35 ~0 ~14 stone_brick_stairs 3 
setblock ~35 ~0 ~30 stone_brick_stairs 2  
fill ~35 ~0 ~31 ~36 ~0 ~31 stonebrick 
setblock ~35 ~0 ~65 stonebrick 0 
setblock ~35 ~0 ~66 cobblestone_wall 0 
setblock ~36 ~0 ~9 stone_brick_stairs 2 
setblock ~36 ~0 ~11 stone_brick_stairs 3 
setblock ~36 ~0 ~13 stonebrick 3  
fill ~36 ~0 ~14 ~38 ~0 ~14 stonebrick  
fill ~36 ~0 ~30 ~36 ~11 ~30 stonebrick  
fill ~36 ~0 ~65 ~36 ~1 ~65 cobblestone_wall 
setblock ~37 ~0 ~10 stone_brick_stairs 1 
setblock ~37 ~0 ~12 stone_brick_stairs 1 
setblock ~37 ~0 ~15 stonebrick 0 
setblock ~37 ~0 ~19 stone_brick_stairs 5 
setblock ~37 ~0 ~20 stone_brick_stairs 7 
setblock ~37 ~0 ~24 stone_brick_stairs 2  
fill ~37 ~0 ~25 ~38 ~0 ~25 stone_brick_stairs 
setblock ~37 ~0 ~29 stone_brick_stairs 6 
setblock ~37 ~0 ~30 stone_brick_stairs 1 
setblock ~37 ~0 ~64 cobblestone_wall 0 
setblock ~38 ~0 ~5 stone_slab 5  
fill ~38 ~0 ~6 ~40 ~0 ~6 stonebrick 
setblock ~38 ~0 ~7 stone_slab 5 
setblock ~38 ~0 ~10 stone_brick_stairs 0 
setblock ~38 ~0 ~15 stone_brick_stairs 4 
setblock ~38 ~0 ~16 stone_slab 5 
setblock ~38 ~0 ~17 double_stone_slab 5 
setblock ~38 ~0 ~18 stone_slab 5  
fill ~38 ~0 ~19 ~39 ~0 ~19 stonebrick  
fill ~38 ~0 ~20 ~39 ~0 ~20 stonebrick 
setblock ~38 ~0 ~21 stone_slab 5 
setblock ~38 ~0 ~22 double_stone_slab 5 
setblock ~38 ~0 ~23 stone_slab 5 
setblock ~38 ~0 ~24 stone_brick_stairs 4 
setblock ~38 ~0 ~26 stone_slab 5 
setblock ~38 ~0 ~27 double_stone_slab 5 
setblock ~38 ~0 ~28 stone_slab 5  
fill ~38 ~0 ~29 ~39 ~0 ~29 stonebrick  
fill ~38 ~0 ~30 ~38 ~0 ~29 stonebrick  
fill ~38 ~0 ~64 ~39 ~0 ~64 stone_brick_stairs 
setblock ~39 ~0 ~5 stonebrick 0 
setblock ~39 ~0 ~7 stonebrick 0 
setblock ~39 ~0 ~9 stone_brick_stairs 2 
setblock ~39 ~0 ~11 stone_brick_stairs 3  
fill ~39 ~0 ~15 ~39 ~9 ~15 stonebrick  
fill ~39 ~0 ~16 ~51 ~0 ~16 stonebrick  
fill ~39 ~0 ~17 ~39 ~2 ~17 stonebrick  
fill ~39 ~0 ~18 ~39 ~4 ~18 stonebrick  
fill ~39 ~0 ~21 ~39 ~4 ~21 stonebrick  
fill ~39 ~0 ~22 ~39 ~2 ~22 stonebrick  
fill ~39 ~0 ~23 ~39 ~4 ~23 stonebrick  
fill ~39 ~0 ~24 ~39 ~8 ~24 stonebrick  
fill ~39 ~0 ~25 ~39 ~8 ~25 stonebrick  
fill ~39 ~0 ~26 ~39 ~4 ~26 stonebrick  
fill ~39 ~0 ~27 ~39 ~2 ~27 stonebrick  
fill ~39 ~0 ~28 ~51 ~0 ~28 stonebrick 
setblock ~40 ~0 ~5 stone_slab 5 
setblock ~40 ~0 ~7 stone_slab 5 
setblock ~40 ~0 ~10 stone_brick_stairs 1 
setblock ~40 ~0 ~15 double_stone_slab 5 
setblock ~40 ~0 ~29 double_stone_slab 5 
setblock ~40 ~0 ~64 cobblestone_wall 0  
fill ~41 ~0 ~6 ~43 ~0 ~6 iron_bars 
setblock ~41 ~0 ~10 stone_brick_stairs 0 
setblock ~41 ~0 ~13 stone_brick_stairs 0 
setblock ~41 ~0 ~15 stone_slab 5 
setblock ~41 ~0 ~29 stone_slab 5  
fill ~41 ~0 ~64 ~43 ~0 ~64 stonebrick  
fill ~41 ~0 ~65 ~41 ~1 ~65 cobblestone_wall 
setblock ~42 ~0 ~9 stone_brick_stairs 2 
setblock ~42 ~0 ~11 stone_brick_stairs 3 
setblock ~42 ~0 ~12 stone_brick_stairs 2 
setblock ~42 ~0 ~14 stone_brick_stairs 3  
fill ~42 ~0 ~15 ~43 ~0 ~15 stonebrick 
setblock ~42 ~0 ~29 stonebrick 0  
fill ~42 ~0 ~30 ~43 ~0 ~30 stone_brick_stairs 
setblock ~42 ~0 ~65 stonebrick 0 
setblock ~42 ~0 ~66 cobblestone_wall 0 
setblock ~43 ~0 ~10 stone_brick_stairs 1 
setblock ~43 ~0 ~13 stone_brick_stairs 1 
setblock ~43 ~0 ~29 stone_brick_stairs 3  
fill ~43 ~0 ~65 ~43 ~1 ~65 cobblestone_wall 
setblock ~44 ~0 ~5 stone_slab 5  
fill ~44 ~0 ~6 ~46 ~0 ~6 stonebrick 
setblock ~44 ~0 ~7 stone_slab 5 
setblock ~44 ~0 ~11 stone_slab 5  
fill ~44 ~0 ~12 ~46 ~0 ~12 stonebrick 
setblock ~44 ~0 ~13 stone_slab 5 
setblock ~44 ~0 ~15 stone_slab 5 
setblock ~44 ~0 ~29 stone_slab 5  
fill ~44 ~0 ~35 ~44 ~2 ~35 piston  
fill ~44 ~0 ~36 ~44 ~2 ~36 piston  
fill ~44 ~0 ~37 ~44 ~2 ~37 piston 
setblock ~44 ~0 ~64 cobblestone_wall 0 
setblock ~45 ~0 ~5 stonebrick 0 
setblock ~45 ~0 ~7 stonebrick 0 
setblock ~45 ~0 ~8 stone_slab 5  
fill ~45 ~0 ~9 ~45 ~3 ~9 iron_bars 
setblock ~45 ~0 ~10 stone_slab 5 
setblock ~45 ~0 ~11 stonebrick 0 
setblock ~45 ~0 ~13 stonebrick 0  
fill ~45 ~0 ~14 ~45 ~3 ~14 iron_bars 
setblock ~45 ~0 ~15 double_stone_slab 5 
setblock ~45 ~0 ~29 double_stone_slab 5  
fill ~45 ~0 ~30 ~46 ~0 ~30 stonebrick  
fill ~45 ~0 ~31 ~45 ~4 ~31 stonebrick  
fill ~45 ~0 ~32 ~45 ~4 ~32 stonebrick  
fill ~45 ~0 ~33 ~45 ~4 ~33 stonebrick  
fill ~45 ~0 ~34 ~45 ~1 ~34 stonebrick 
setblock ~45 ~0 ~35 stone_brick_stairs 3 
setblock ~45 ~0 ~37 stone_brick_stairs 2  
fill ~45 ~0 ~38 ~45 ~1 ~38 stonebrick  
fill ~45 ~0 ~39 ~45 ~4 ~39 stonebrick  
fill ~45 ~0 ~40 ~45 ~4 ~40 stonebrick  
fill ~45 ~0 ~41 ~45 ~4 ~41 stonebrick  
fill ~45 ~0 ~42 ~55 ~0 ~42 stonebrick  
fill ~45 ~0 ~64 ~46 ~0 ~64 stone_brick_stairs 
setblock ~46 ~0 ~5 stone_slab 5 
setblock ~46 ~0 ~7 stone_slab 5 
setblock ~46 ~0 ~11 stone_slab 5 
setblock ~46 ~0 ~13 stone_slab 5 
setblock ~46 ~0 ~15 stone_slab 5 
setblock ~46 ~0 ~29 stone_slab 5  
fill ~46 ~0 ~31 ~46 ~2 ~31 nether_brick_fence 
setblock ~46 ~0 ~32 cobblestone_wall 6  
fill ~46 ~0 ~33 ~46 ~8 ~33 stonebrick 
setblock ~46 ~0 ~34 cobblestone_wall 6 
setblock ~46 ~0 ~38 cobblestone_wall 6  
fill ~46 ~0 ~39 ~46 ~8 ~39 stonebrick 
setblock ~46 ~0 ~40 cobblestone_wall 6  
fill ~46 ~0 ~41 ~46 ~2 ~41 nether_brick_fence 
setblock ~47 ~0 ~14 stone_brick_stairs 2 
setblock ~47 ~0 ~15 stone_brick_stairs 5  
fill ~47 ~0 ~29 ~48 ~0 ~29 stonebrick 
setblock ~47 ~0 ~30 stone_brick_stairs 7  
fill ~47 ~0 ~33 ~47 ~1 ~33 cobblestone_wall  
fill ~47 ~0 ~39 ~47 ~1 ~39 cobblestone_wall 
setblock ~47 ~0 ~41 cobblestone_wall 6 
setblock ~47 ~0 ~64 cobblestone_wall 0  
fill ~48 ~0 ~14 ~48 ~0 ~16 stonebrick 
setblock ~48 ~0 ~30 stonebrick 0 
setblock ~48 ~0 ~40 cobblestone_wall 6  
fill ~48 ~0 ~41 ~48 ~8 ~41 stonebrick  
fill ~48 ~0 ~64 ~50 ~0 ~64 stonebrick  
fill ~48 ~0 ~65 ~48 ~1 ~65 cobblestone_wall 
setblock ~49 ~0 ~15 stone_slab 5 
setblock ~49 ~0 ~29 stone_slab 5  
fill ~49 ~0 ~41 ~50 ~0 ~41 cobblestone_wall 
setblock ~49 ~0 ~61 stone_slab 5  
fill ~49 ~0 ~62 ~50 ~0 ~62 stonebrick 
setblock ~49 ~0 ~65 stone_slab 5 
setblock ~49 ~0 ~66 cobblestone_wall 0 
setblock ~50 ~0 ~15 double_stone_slab 5 
setblock ~50 ~0 ~29 double_stone_slab 5 
setblock ~50 ~0 ~59 stone_brick_stairs 0 
setblock ~50 ~0 ~60 stone_slab 5  
fill ~50 ~0 ~61 ~50 ~5 ~61 stonebrick  
fill ~50 ~0 ~63 ~50 ~1 ~63 stonebrick  
fill ~50 ~0 ~65 ~50 ~5 ~65 stonebrick 
setblock ~50 ~0 ~66 stone_slab 5 
setblock ~50 ~0 ~67 stone_brick_stairs 0 
setblock ~51 ~0 ~15 stone_slab 5  
fill ~51 ~0 ~17 ~51 ~2 ~17 stonebrick  
fill ~51 ~0 ~18 ~51 ~4 ~18 stonebrick  
fill ~51 ~0 ~19 ~52 ~0 ~19 stonebrick  
fill ~51 ~0 ~20 ~53 ~0 ~20 stonebrick  
fill ~51 ~0 ~21 ~51 ~4 ~21 stonebrick  
fill ~51 ~0 ~22 ~51 ~2 ~22 stonebrick  
fill ~51 ~0 ~23 ~51 ~4 ~23 stonebrick  
fill ~51 ~0 ~24 ~52 ~0 ~24 stonebrick  
fill ~51 ~0 ~25 ~52 ~0 ~25 stonebrick  
fill ~51 ~0 ~26 ~51 ~4 ~26 stonebrick  
fill ~51 ~0 ~27 ~51 ~2 ~27 stonebrick 
setblock ~51 ~0 ~29 stone_slab 5 
setblock ~51 ~0 ~40 cobblestone_wall 6  
fill ~51 ~0 ~41 ~51 ~7 ~41 stonebrick 
setblock ~51 ~0 ~58 stone_slab 5  
fill ~51 ~0 ~59 ~51 ~3 ~59 stonebrick  
fill ~51 ~0 ~60 ~51 ~0 ~59 stonebrick  
fill ~51 ~0 ~66 ~51 ~0 ~67 stonebrick 
setblock ~51 ~0 ~68 stone_slab 5 
setblock ~52 ~0 ~14 stonebrick 0 
setblock ~52 ~0 ~15 stone_brick_stairs 3 
setblock ~52 ~0 ~16 stone_slab 5 
setblock ~52 ~0 ~17 double_stone_slab 5 
setblock ~52 ~0 ~18 stone_slab 5 
setblock ~52 ~0 ~21 stone_slab 5 
setblock ~52 ~0 ~22 double_stone_slab 5 
setblock ~52 ~0 ~23 stone_slab 5 
setblock ~52 ~0 ~26 stone_slab 5 
setblock ~52 ~0 ~27 double_stone_slab 5 
setblock ~52 ~0 ~28 stone_slab 5 
setblock ~52 ~0 ~29 stone_brick_stairs 2  
fill ~52 ~0 ~30 ~53 ~0 ~30 stonebrick  
fill ~52 ~0 ~41 ~53 ~0 ~41 cobblestone_wall 
setblock ~52 ~0 ~57 stone_slab 5 
setblock ~52 ~0 ~58 stonebrick 0 
setblock ~52 ~0 ~68 stonebrick 0 
setblock ~52 ~0 ~69 stone_slab 5 
setblock ~53 ~0 ~14 stone_brick_stairs 1 
setblock ~53 ~0 ~15 stonebrick 0 
setblock ~53 ~0 ~19 stone_brick_stairs 4 
setblock ~53 ~0 ~24 stone_brick_stairs 7 
setblock ~53 ~0 ~25 stone_brick_stairs 5 
setblock ~53 ~0 ~29 stonebrick 0 
setblock ~53 ~0 ~40 stone_brick_stairs 0 
setblock ~53 ~0 ~46 stone_brick_stairs 0 
setblock ~53 ~0 ~56 stone_brick_stairs 2  
fill ~53 ~0 ~57 ~54 ~0 ~57 stonebrick  
fill ~53 ~0 ~69 ~54 ~0 ~69 stonebrick 
setblock ~53 ~0 ~70 stone_brick_stairs 3  
fill ~54 ~0 ~40 ~54 ~2 ~40 stonebrick  
fill ~54 ~0 ~41 ~54 ~5 ~41 stonebrick 
setblock ~54 ~0 ~43 stone_slab 5 
setblock ~54 ~0 ~44 double_stone_slab 5 
setblock ~54 ~0 ~45 stone_slab 5  
fill ~54 ~0 ~46 ~54 ~2 ~46 stonebrick 
setblock ~54 ~0 ~47 stone_brick_stairs 3 
setblock ~54 ~0 ~56 stone_slab 5 
setblock ~54 ~0 ~70 stone_slab 5 
setblock ~55 ~0 ~40 stone_slab 5 
setblock ~55 ~0 ~41 cobblestone_wall 6 
setblock ~55 ~0 ~43 planks 5  
fill ~55 ~0 ~44 ~59 ~0 ~44 stonebrick 
setblock ~55 ~0 ~45 planks 5 
setblock ~55 ~0 ~46 stone_slab 5 
setblock ~55 ~0 ~55 stone_slab 5  
fill ~55 ~0 ~56 ~55 ~5 ~56 stonebrick  
fill ~55 ~0 ~70 ~55 ~5 ~70 stonebrick 
setblock ~55 ~0 ~71 stone_slab 5 
setblock ~56 ~0 ~40 double_stone_slab 5  
fill ~56 ~0 ~41 ~56 ~1 ~41 stonebrick  
fill ~56 ~0 ~45 ~56 ~1 ~45 stonebrick 
setblock ~56 ~0 ~46 double_stone_slab 5 
setblock ~56 ~0 ~54 stone_brick_stairs 2  
fill ~56 ~0 ~55 ~56 ~2 ~55 stonebrick  
fill ~56 ~0 ~56 ~58 ~0 ~56 stonebrick  
fill ~56 ~0 ~70 ~58 ~0 ~70 stonebrick  
fill ~56 ~0 ~71 ~56 ~2 ~71 stonebrick 
setblock ~56 ~0 ~72 stone_brick_stairs 3 
setblock ~57 ~0 ~40 stone_slab 5 
setblock ~57 ~0 ~41 planks 5 
setblock ~57 ~0 ~45 planks 5 
setblock ~57 ~0 ~46 stone_slab 5  
fill ~57 ~0 ~47 ~57 ~2 ~47 cobblestone  
fill ~57 ~0 ~48 ~57 ~2 ~48 cobblestone  
fill ~57 ~0 ~49 ~57 ~2 ~49 cobblestone  
fill ~57 ~0 ~50 ~57 ~2 ~50 cobblestone  
fill ~57 ~0 ~51 ~57 ~2 ~51 cobblestone  
fill ~57 ~0 ~52 ~57 ~2 ~52 cobblestone  
fill ~57 ~0 ~53 ~57 ~2 ~53 cobblestone  
fill ~57 ~0 ~54 ~57 ~2 ~54 cobblestone  
fill ~57 ~0 ~55 ~57 ~2 ~55 cobblestone 
setblock ~57 ~0 ~71 cobblestone_wall 0 
setblock ~58 ~0 ~40 double_stone_slab 5  
fill ~58 ~0 ~41 ~58 ~1 ~41 stonebrick  
fill ~58 ~0 ~45 ~58 ~1 ~45 stonebrick 
setblock ~58 ~0 ~46 double_stone_slab 5 
setblock ~58 ~0 ~47 stone_brick_stairs 1  
fill ~58 ~0 ~48 ~58 ~2 ~48 stonebrick 
setblock ~58 ~0 ~49 stone_brick_stairs 1  
fill ~58 ~0 ~50 ~58 ~2 ~50 stonebrick 
setblock ~58 ~0 ~51 stone_brick_stairs 1  
fill ~58 ~0 ~52 ~58 ~2 ~52 stonebrick 
setblock ~58 ~0 ~53 stone_brick_stairs 1  
fill ~58 ~0 ~54 ~58 ~2 ~54 stonebrick 
setblock ~58 ~0 ~55 stone_brick_stairs 1  
fill ~58 ~0 ~71 ~58 ~2 ~71 stonebrick 
setblock ~58 ~0 ~72 stone_brick_stairs 3 
setblock ~59 ~0 ~40 stone_slab 5 
setblock ~59 ~0 ~41 planks 5  
fill ~59 ~0 ~42 ~59 ~1 ~42 stonebrick 
setblock ~59 ~0 ~43 planks 5 
setblock ~59 ~0 ~45 planks 5 
setblock ~59 ~0 ~46 stone_slab 5 
setblock ~59 ~0 ~55 stone_slab 5  
fill ~59 ~0 ~56 ~59 ~5 ~56 stonebrick  
fill ~59 ~0 ~70 ~59 ~5 ~70 stonebrick 
setblock ~59 ~0 ~71 stone_slab 5 
setblock ~60 ~0 ~39 stone_brick_stairs 2  
fill ~60 ~0 ~40 ~60 ~2 ~40 stonebrick 
setblock ~60 ~0 ~41 stone_slab 5 
setblock ~60 ~0 ~42 double_stone_slab 5 
setblock ~60 ~0 ~43 stone_slab 5 
setblock ~60 ~0 ~44 double_stone_slab 5 
setblock ~60 ~0 ~45 stone_slab 5  
fill ~60 ~0 ~46 ~60 ~2 ~46 stonebrick 
setblock ~60 ~0 ~47 stone_brick_stairs 3 
setblock ~60 ~0 ~56 stone_slab 5  
fill ~60 ~0 ~57 ~61 ~0 ~57 stonebrick  
fill ~60 ~0 ~69 ~61 ~0 ~69 stonebrick 
setblock ~60 ~0 ~70 stone_slab 5 
setblock ~61 ~0 ~40 stone_brick_stairs 1 
setblock ~61 ~0 ~46 stone_brick_stairs 1 
setblock ~61 ~0 ~56 stone_brick_stairs 2 
setblock ~61 ~0 ~70 stone_brick_stairs 3 
setblock ~62 ~0 ~57 stone_slab 5 
setblock ~62 ~0 ~58 stonebrick 0 
setblock ~62 ~0 ~68 stonebrick 0 
setblock ~62 ~0 ~69 stone_slab 5 
setblock ~63 ~0 ~58 stone_slab 5  
fill ~63 ~0 ~59 ~63 ~3 ~59 stonebrick  
fill ~63 ~0 ~60 ~63 ~0 ~59 stonebrick  
fill ~63 ~0 ~66 ~63 ~0 ~67 stonebrick 
setblock ~63 ~0 ~68 stone_slab 5 
setblock ~64 ~0 ~59 stone_brick_stairs 1 
setblock ~64 ~0 ~60 stone_slab 5  
fill ~64 ~0 ~61 ~64 ~5 ~61 stonebrick  
fill ~64 ~0 ~62 ~65 ~0 ~62 stonebrick  
fill ~64 ~0 ~63 ~64 ~1 ~63 stonebrick  
fill ~64 ~0 ~64 ~65 ~0 ~64 stonebrick  
fill ~64 ~0 ~65 ~64 ~5 ~65 stonebrick 
setblock ~64 ~0 ~66 stone_slab 5 
setblock ~64 ~0 ~67 stone_brick_stairs 1 
setblock ~65 ~0 ~61 stone_slab 5 
setblock ~65 ~0 ~63 cobblestone_wall 0 
setblock ~65 ~0 ~65 stone_slab 5 
setblock ~66 ~0 ~62 stone_brick_stairs 1 
setblock ~66 ~0 ~64 stone_brick_stairs 1 
setblock ~3 ~1 ~5 stone_brick_stairs 0 
setblock ~3 ~1 ~11 stone_brick_stairs 0 
setblock ~3 ~1 ~33 stone_brick_stairs 0 
setblock ~3 ~1 ~39 stone_brick_stairs 0 
setblock ~4 ~1 ~4 stone_brick_stairs 2  
fill ~4 ~1 ~5 ~4 ~5 ~5 stonebrick  
fill ~4 ~1 ~6 ~4 ~1 ~10 stone_slab  
fill ~4 ~1 ~11 ~4 ~5 ~11 stonebrick 
setblock ~4 ~1 ~12 stone_brick_stairs 3 
setblock ~4 ~1 ~32 stone_brick_stairs 2  
fill ~4 ~1 ~33 ~4 ~9 ~33 stonebrick  
fill ~4 ~1 ~34 ~4 ~1 ~38 stone_slab  
fill ~4 ~1 ~39 ~4 ~9 ~39 stonebrick 
setblock ~4 ~1 ~40 stone_brick_stairs 3  
fill ~5 ~1 ~5 ~9 ~1 ~5 stone_slab  
fill ~5 ~1 ~6 ~9 ~1 ~6 brick_block  
fill ~5 ~1 ~10 ~9 ~1 ~10 brick_block 
setblock ~5 ~1 ~11 stone_slab 3  
fill ~5 ~1 ~12 ~5 ~3 ~12 stonebrick 
setblock ~5 ~1 ~13 stone_brick_stairs 0 
setblock ~5 ~1 ~19 stone_brick_stairs 0 
setblock ~5 ~1 ~25 stone_brick_stairs 0 
setblock ~5 ~1 ~31 stone_brick_stairs 0  
fill ~5 ~1 ~32 ~6 ~1 ~32 stonebrick 
setblock ~5 ~1 ~33 stone_slab 3  
fill ~5 ~1 ~34 ~9 ~1 ~34 brick_block  
fill ~5 ~1 ~38 ~9 ~1 ~38 brick_block  
fill ~5 ~1 ~39 ~9 ~1 ~39 stone_slab  
fill ~6 ~1 ~7 ~8 ~1 ~7 stained_hardened_clay  
fill ~6 ~1 ~9 ~8 ~1 ~9 stained_hardened_clay 
setblock ~6 ~1 ~12 stone_brick_stairs 2  
fill ~6 ~1 ~13 ~6 ~6 ~13 stonebrick 
setblock ~6 ~1 ~14 stone_brick_stairs 3  
fill ~6 ~1 ~15 ~6 ~1 ~17 stone_slab 
setblock ~6 ~1 ~18 stone_brick_stairs 2  
fill ~6 ~1 ~19 ~6 ~6 ~19 stonebrick 
setblock ~6 ~1 ~20 stone_slab 3 
setblock ~6 ~1 ~24 stone_slab 3  
fill ~6 ~1 ~25 ~6 ~6 ~25 stonebrick 
setblock ~6 ~1 ~26 stone_brick_stairs 3  
fill ~6 ~1 ~27 ~6 ~1 ~29 stone_slab 
setblock ~6 ~1 ~30 stone_brick_stairs 2  
fill ~6 ~1 ~31 ~6 ~6 ~31 stonebrick  
fill ~6 ~1 ~33 ~6 ~5 ~33 stonebrick  
fill ~6 ~1 ~35 ~8 ~1 ~35 stained_hardened_clay  
fill ~6 ~1 ~37 ~8 ~1 ~37 stained_hardened_clay  
fill ~7 ~1 ~11 ~8 ~1 ~11 stone_slab 
setblock ~7 ~1 ~21 stone_slab 5 
setblock ~7 ~1 ~22 stone_brick_stairs 0 
setblock ~7 ~1 ~23 stone_slab 5  
fill ~7 ~1 ~24 ~7 ~1 ~32 brick_block  
fill ~7 ~1 ~33 ~9 ~1 ~33 stone_slab  
fill ~9 ~1 ~11 ~31 ~1 ~11 stonebrick 
setblock ~9 ~1 ~12 stone_brick_stairs 4  
fill ~9 ~1 ~22 ~10 ~1 ~22 stonebrick 
setblock ~9 ~1 ~24 stone_brick_stairs 2 
setblock ~9 ~1 ~31 stone_brick_stairs 4  
fill ~9 ~1 ~32 ~10 ~1 ~32 stonebrick 
setblock ~10 ~1 ~4 stone_brick_stairs 2  
fill ~10 ~1 ~5 ~10 ~6 ~5 stonebrick  
fill ~10 ~1 ~6 ~10 ~1 ~10 stone_slab  
fill ~10 ~1 ~12 ~10 ~0 ~12 stonebrick  
fill ~10 ~1 ~13 ~10 ~2 ~13 cobblestone_wall  
fill ~10 ~1 ~19 ~12 ~1 ~19 stonebrick  
fill ~10 ~1 ~25 ~12 ~1 ~25 stonebrick  
fill ~10 ~1 ~31 ~11 ~1 ~31 stonebrick  
fill ~10 ~1 ~33 ~37 ~1 ~33 stonebrick  
fill ~10 ~1 ~34 ~10 ~1 ~38 stone_slab  
fill ~10 ~1 ~39 ~10 ~9 ~39 stonebrick 
setblock ~10 ~1 ~40 stone_brick_stairs 3 
setblock ~10 ~1 ~42 stone_brick_stairs 4 
setblock ~11 ~1 ~5 stone_brick_stairs 1 
setblock ~11 ~1 ~6 stone_slab 5 
setblock ~11 ~1 ~7 stone_brick_stairs 0  
fill ~11 ~1 ~8 ~24 ~1 ~8 planks 
setblock ~11 ~1 ~14 stone_brick_stairs 7 
setblock ~11 ~1 ~15 stone_brick_stairs 3 
setblock ~11 ~1 ~16 double_stone_slab 5 
setblock ~11 ~1 ~17 stone_brick_stairs 2 
setblock ~11 ~1 ~18 stone_brick_stairs 6  
fill ~11 ~1 ~20 ~11 ~1 ~24 stone_slab 
setblock ~11 ~1 ~26 stone_brick_stairs 7 
setblock ~11 ~1 ~27 stone_brick_stairs 3 
setblock ~11 ~1 ~28 double_stone_slab 5 
setblock ~11 ~1 ~29 stone_brick_stairs 2 
setblock ~11 ~1 ~30 stone_brick_stairs 6 
setblock ~11 ~1 ~39 stone_brick_stairs 1  
fill ~11 ~1 ~40 ~11 ~4 ~40 stonebrick  
fill ~11 ~1 ~41 ~11 ~1 ~40 stonebrick 
setblock ~11 ~1 ~44 stone_brick_stairs 4 
setblock ~12 ~1 ~6 stone_brick_stairs 2 
setblock ~12 ~1 ~7 stonebrick 0 
setblock ~12 ~1 ~12 stonebrick 0  
fill ~12 ~1 ~13 ~12 ~2 ~13 cobblestone_wall  
fill ~12 ~1 ~31 ~12 ~2 ~31 cobblestone_wall 
setblock ~12 ~1 ~32 stonebrick 0 
setblock ~12 ~1 ~43 stonebrick 0 
setblock ~12 ~1 ~46 stone_brick_stairs 4  
fill ~13 ~1 ~6 ~15 ~1 ~6 stone_slab 
setblock ~13 ~1 ~7 stone_brick_stairs 1 
setblock ~13 ~1 ~12 stone_brick_stairs 5 
setblock ~13 ~1 ~19 cobblestone_wall 0 
setblock ~13 ~1 ~25 cobblestone_wall 0  

KittysCommands:  
setblock ~13 ~1 ~32 stone_brick_stairs 5 
setblock ~13 ~1 ~45 stonebrick 0 
setblock ~13 ~1 ~48 stone_brick_stairs 4 
setblock ~14 ~1 ~12 stone_brick_stairs 1 
setblock ~14 ~1 ~32 stone_brick_stairs 1 
setblock ~14 ~1 ~47 stonebrick 0 
setblock ~14 ~1 ~50 stone_brick_stairs 4 
setblock ~14 ~1 ~53 stone_brick_stairs 4 
setblock ~14 ~1 ~59 stone_brick_stairs 4 
setblock ~14 ~1 ~65 stone_brick_stairs 4 
setblock ~15 ~1 ~7 stone_brick_stairs 0 
setblock ~15 ~1 ~12 stone_slab 5 
setblock ~15 ~1 ~14 cobblestone_wall 6 
setblock ~15 ~1 ~30 cobblestone_wall 6 
setblock ~15 ~1 ~32 stone_slab 5 
setblock ~15 ~1 ~49 stonebrick 0 
setblock ~15 ~1 ~52 stone_brick_stairs 6 
setblock ~15 ~1 ~54 stone_brick_stairs 7  
fill ~15 ~1 ~55 ~15 ~1 ~57 stone_slab 
setblock ~15 ~1 ~58 stone_brick_stairs 6  
fill ~15 ~1 ~59 ~16 ~1 ~59 stonebrick 
setblock ~15 ~1 ~60 stone_brick_stairs 7  
fill ~15 ~1 ~61 ~15 ~1 ~63 stone_slab 
setblock ~15 ~1 ~64 stone_brick_stairs 6 
setblock ~15 ~1 ~66 stone_brick_stairs 7 
setblock ~16 ~1 ~6 stone_brick_stairs 2 
setblock ~16 ~1 ~7 stonebrick 0 
setblock ~16 ~1 ~12 stone_brick_stairs 0 
setblock ~16 ~1 ~32 stone_brick_stairs 0 
setblock ~16 ~1 ~51 stonebrick 0 
setblock ~16 ~1 ~53 stone_brick_stairs 5  
fill ~16 ~1 ~54 ~16 ~6 ~54 log2  
fill ~16 ~1 ~55 ~16 ~1 ~57 planks  
fill ~16 ~1 ~58 ~16 ~6 ~58 log2  
fill ~16 ~1 ~60 ~16 ~7 ~60 log2  
fill ~16 ~1 ~61 ~16 ~1 ~63 planks  
fill ~16 ~1 ~64 ~16 ~7 ~64 log2 
setblock ~16 ~1 ~65 stone_brick_stairs 5  
fill ~17 ~1 ~6 ~19 ~1 ~6 stone_slab 
setblock ~17 ~1 ~7 stone_brick_stairs 1 
setblock ~17 ~1 ~12 stone_brick_stairs 4 
setblock ~17 ~1 ~32 stone_brick_stairs 4  
fill ~17 ~1 ~53 ~19 ~1 ~53 stone_slab  
fill ~17 ~1 ~54 ~19 ~1 ~54 planks  
fill ~17 ~1 ~64 ~19 ~1 ~64 planks  
fill ~17 ~1 ~65 ~19 ~1 ~65 stone_slab  
fill ~18 ~1 ~12 ~18 ~0 ~12 stonebrick  
fill ~18 ~1 ~13 ~18 ~2 ~13 cobblestone_wall  
fill ~18 ~1 ~31 ~18 ~2 ~31 cobblestone_wall  
fill ~18 ~1 ~32 ~18 ~0 ~32 stonebrick 
setblock ~19 ~1 ~7 stone_brick_stairs 0 
setblock ~19 ~1 ~14 stone_brick_stairs 7 
setblock ~19 ~1 ~30 stone_brick_stairs 6 
setblock ~20 ~1 ~6 stone_brick_stairs 2 
setblock ~20 ~1 ~7 stonebrick 0 
setblock ~20 ~1 ~12 stonebrick 0  
fill ~20 ~1 ~13 ~20 ~2 ~13 cobblestone_wall  
fill ~20 ~1 ~31 ~20 ~2 ~31 cobblestone_wall 
setblock ~20 ~1 ~32 stonebrick 0 
setblock ~20 ~1 ~53 stone_brick_stairs 4  
fill ~20 ~1 ~54 ~20 ~7 ~54 log2  
fill ~20 ~1 ~64 ~20 ~6 ~64 log2 
setblock ~20 ~1 ~65 stone_brick_stairs 4  
fill ~21 ~1 ~6 ~23 ~1 ~6 stone_slab 
setblock ~21 ~1 ~7 stone_brick_stairs 1 
setblock ~21 ~1 ~12 stone_brick_stairs 5 
setblock ~21 ~1 ~32 stone_brick_stairs 5 
setblock ~21 ~1 ~52 stone_brick_stairs 6  
fill ~21 ~1 ~54 ~21 ~7 ~54 stonebrick  
fill ~21 ~1 ~64 ~21 ~7 ~64 stonebrick 
setblock ~21 ~1 ~66 stone_brick_stairs 7 
setblock ~22 ~1 ~12 stone_brick_stairs 1 
setblock ~22 ~1 ~32 stone_brick_stairs 1 
setblock ~22 ~1 ~53 stone_brick_stairs 5  
fill ~22 ~1 ~54 ~22 ~6 ~54 log2  
fill ~22 ~1 ~64 ~22 ~7 ~64 log2 
setblock ~22 ~1 ~65 stone_brick_stairs 5 
setblock ~23 ~1 ~7 stone_brick_stairs 0 
setblock ~23 ~1 ~12 stone_slab 5 
setblock ~23 ~1 ~14 cobblestone_wall 6 
setblock ~23 ~1 ~30 cobblestone_wall 6 
setblock ~23 ~1 ~32 stone_slab 5  
fill ~23 ~1 ~53 ~25 ~1 ~53 stone_slab  
fill ~23 ~1 ~54 ~25 ~1 ~54 planks  
fill ~23 ~1 ~64 ~25 ~1 ~64 planks  
fill ~23 ~1 ~65 ~25 ~1 ~65 stone_slab 
setblock ~24 ~1 ~6 stone_brick_stairs 2 
setblock ~24 ~1 ~12 stone_brick_stairs 0 
setblock ~24 ~1 ~32 stone_brick_stairs 0 
setblock ~25 ~1 ~3 stone_brick_stairs 3 
setblock ~25 ~1 ~4 stone_slab 5 
setblock ~25 ~1 ~5 stone_brick_stairs 0 
setblock ~25 ~1 ~6 stone_slab 5 
setblock ~25 ~1 ~7 stone_brick_stairs 2 
setblock ~25 ~1 ~12 stone_brick_stairs 4 
setblock ~25 ~1 ~32 stone_brick_stairs 4 
setblock ~26 ~1 ~2 stone_brick_stairs 1  
fill ~26 ~1 ~3 ~26 ~15 ~3 stonebrick  
fill ~26 ~1 ~5 ~26 ~2 ~5 stonebrick  
fill ~26 ~1 ~7 ~26 ~15 ~7 stonebrick 
setblock ~26 ~1 ~8 stone_brick_stairs 1  
fill ~26 ~1 ~12 ~26 ~0 ~12 stonebrick  
fill ~26 ~1 ~13 ~26 ~2 ~13 cobblestone_wall  
fill ~26 ~1 ~31 ~26 ~2 ~31 cobblestone_wall  
fill ~26 ~1 ~32 ~26 ~0 ~32 stonebrick 
setblock ~26 ~1 ~53 stone_brick_stairs 4  
fill ~26 ~1 ~54 ~26 ~6 ~54 log2  
fill ~26 ~1 ~55 ~26 ~1 ~57 planks  
fill ~26 ~1 ~58 ~26 ~7 ~58 log2  
fill ~26 ~1 ~59 ~26 ~7 ~59 stonebrick  
fill ~26 ~1 ~60 ~26 ~6 ~60 log2  
fill ~26 ~1 ~61 ~26 ~1 ~63 planks  
fill ~26 ~1 ~64 ~26 ~6 ~64 log2 
setblock ~26 ~1 ~65 stone_brick_stairs 4 
setblock ~27 ~1 ~2 stone_slab 5 
setblock ~27 ~1 ~8 stone_slab 5 
setblock ~27 ~1 ~14 stone_brick_stairs 7 
setblock ~27 ~1 ~30 stone_brick_stairs 6 
setblock ~27 ~1 ~52 stone_brick_stairs 6 
setblock ~27 ~1 ~54 stone_brick_stairs 7  
fill ~27 ~1 ~55 ~27 ~1 ~57 stone_slab 
setblock ~27 ~1 ~58 stone_brick_stairs 6 
setblock ~27 ~1 ~60 stone_brick_stairs 7  
fill ~27 ~1 ~61 ~27 ~1 ~63 stone_slab 
setblock ~27 ~1 ~64 stone_brick_stairs 0 
setblock ~27 ~1 ~66 stone_brick_stairs 7 
setblock ~28 ~1 ~2 stone_brick_stairs 2  
fill ~28 ~1 ~3 ~28 ~2 ~3 stonebrick  
fill ~28 ~1 ~7 ~28 ~2 ~7 stonebrick 
setblock ~28 ~1 ~8 stone_brick_stairs 3 
setblock ~28 ~1 ~12 stonebrick 0  
fill ~28 ~1 ~13 ~28 ~2 ~13 cobblestone_wall  
fill ~28 ~1 ~31 ~28 ~2 ~31 cobblestone_wall 
setblock ~28 ~1 ~32 stonebrick 0 
setblock ~28 ~1 ~53 stone_brick_stairs 5 
setblock ~28 ~1 ~59 stone_brick_stairs 5  
fill ~28 ~1 ~63 ~49 ~1 ~63 cobblestone  
fill ~28 ~1 ~64 ~28 ~2 ~64 stonebrick 
setblock ~28 ~1 ~65 stone_brick_stairs 3 
setblock ~29 ~1 ~2 stone_slab 5 
setblock ~29 ~1 ~8 stone_slab 5 
setblock ~29 ~1 ~12 stone_brick_stairs 5 
setblock ~29 ~1 ~32 stone_brick_stairs 5 
setblock ~29 ~1 ~64 stone_brick_stairs 1 
setblock ~30 ~1 ~2 stone_brick_stairs 0  
fill ~30 ~1 ~3 ~30 ~15 ~3 stonebrick  
fill ~30 ~1 ~5 ~30 ~2 ~5 stonebrick  
fill ~30 ~1 ~7 ~30 ~15 ~7 stonebrick 
setblock ~30 ~1 ~8 stone_brick_stairs 0 
setblock ~30 ~1 ~12 stone_brick_stairs 1 
setblock ~30 ~1 ~32 stone_brick_stairs 1  
fill ~30 ~1 ~64 ~33 ~1 ~64 stone_slab 
setblock ~31 ~1 ~3 stone_brick_stairs 3 
setblock ~31 ~1 ~4 stone_slab 5 
setblock ~31 ~1 ~5 stone_brick_stairs 1 
setblock ~31 ~1 ~6 stone_slab 5 
setblock ~31 ~1 ~7 stone_brick_stairs 2 
setblock ~31 ~1 ~12 stone_slab 5 
setblock ~31 ~1 ~14 cobblestone_wall 6 
setblock ~31 ~1 ~30 cobblestone_wall 6 
setblock ~31 ~1 ~32 stone_slab 5 
setblock ~32 ~1 ~6 stone_brick_stairs 4 
setblock ~32 ~1 ~10 stone_brick_stairs 4 
setblock ~32 ~1 ~12 stone_brick_stairs 0 
setblock ~32 ~1 ~32 stone_brick_stairs 0 
setblock ~33 ~1 ~5 stone_brick_stairs 6 
setblock ~33 ~1 ~6 stonebrick 0 
setblock ~33 ~1 ~7 stone_brick_stairs 7 
setblock ~33 ~1 ~9 stone_brick_stairs 6 
setblock ~33 ~1 ~11 stone_brick_stairs 7 
setblock ~33 ~1 ~12 stone_brick_stairs 4 
setblock ~33 ~1 ~32 stone_brick_stairs 4 
setblock ~34 ~1 ~6 stone_brick_stairs 5 
setblock ~34 ~1 ~10 stone_brick_stairs 5  
fill ~34 ~1 ~12 ~34 ~0 ~12 stonebrick  
fill ~34 ~1 ~13 ~34 ~2 ~13 cobblestone_wall  
fill ~34 ~1 ~31 ~34 ~2 ~31 cobblestone_wall  
fill ~34 ~1 ~32 ~34 ~0 ~32 stonebrick 
setblock ~34 ~1 ~64 stone_brick_stairs 0  
fill ~35 ~1 ~6 ~37 ~1 ~6 iron_bars 
setblock ~35 ~1 ~10 stone_brick_stairs 4 
setblock ~35 ~1 ~14 stone_brick_stairs 7 
setblock ~35 ~1 ~30 stone_brick_stairs 6  
fill ~35 ~1 ~31 ~36 ~1 ~31 stonebrick  
fill ~35 ~1 ~64 ~35 ~2 ~64 stonebrick 
setblock ~35 ~1 ~65 stone_brick_stairs 3 
setblock ~36 ~1 ~9 stone_brick_stairs 6 
setblock ~36 ~1 ~11 stone_brick_stairs 7 
setblock ~36 ~1 ~12 stonebrick 0  
fill ~36 ~1 ~13 ~36 ~2 ~13 cobblestone_wall  
fill ~36 ~1 ~14 ~36 ~10 ~14 stonebrick  
fill ~36 ~1 ~32 ~37 ~1 ~32 stonebrick 
setblock ~36 ~1 ~64 stone_brick_stairs 1 
setblock ~37 ~1 ~10 stone_brick_stairs 5 
setblock ~37 ~1 ~12 stone_brick_stairs 5  
fill ~37 ~1 ~14 ~38 ~1 ~14 cobblestone_wall 
setblock ~37 ~1 ~15 cobblestone_wall 1  
fill ~37 ~1 ~19 ~38 ~1 ~19 cobblestone_wall 
setblock ~37 ~1 ~20 cobblestone_wall 1  
fill ~37 ~1 ~24 ~37 ~1 ~25 cobblestone_wall 
setblock ~37 ~1 ~29 cobblestone_wall 0 
setblock ~37 ~1 ~30 stone_brick_stairs 5  
fill ~37 ~1 ~64 ~40 ~1 ~64 stone_slab 
setblock ~38 ~1 ~6 stone_brick_stairs 4 
setblock ~38 ~1 ~10 stone_brick_stairs 4 
setblock ~38 ~1 ~15 cobblestone_wall 0 
setblock ~38 ~1 ~17 cobblestone_wall 6 
setblock ~38 ~1 ~20 cobblestone_wall 0 
setblock ~38 ~1 ~22 cobblestone_wall 6 
setblock ~38 ~1 ~24 cobblestone_wall 1 
setblock ~38 ~1 ~25 cobblestone_wall 0 
setblock ~38 ~1 ~27 cobblestone_wall 6 
setblock ~38 ~1 ~29 cobblestone_wall 1 
setblock ~38 ~1 ~30 cobblestone_wall 0 
setblock ~39 ~1 ~5 stone_brick_stairs 6 
setblock ~39 ~1 ~6 stonebrick 0 
setblock ~39 ~1 ~7 stone_brick_stairs 7 
setblock ~39 ~1 ~9 stone_brick_stairs 6 
setblock ~39 ~1 ~11 stone_brick_stairs 7  
fill ~39 ~1 ~16 ~51 ~1 ~16 stonebrick  
fill ~39 ~1 ~19 ~39 ~8 ~19 stonebrick  
fill ~39 ~1 ~20 ~39 ~8 ~20 stonebrick  
fill ~39 ~1 ~28 ~51 ~1 ~28 stonebrick  
fill ~39 ~1 ~29 ~39 ~9 ~29 stonebrick 
setblock ~40 ~1 ~6 stone_brick_stairs 5 
setblock ~40 ~1 ~10 stone_brick_stairs 5 
setblock ~40 ~1 ~15 cobblestone_wall 6 
setblock ~40 ~1 ~29 cobblestone_wall 6  
fill ~41 ~1 ~6 ~43 ~1 ~6 iron_bars 
setblock ~41 ~1 ~10 stone_brick_stairs 4 
setblock ~41 ~1 ~13 stone_brick_stairs 4 
setblock ~41 ~1 ~64 stone_brick_stairs 0 
setblock ~42 ~1 ~9 stone_brick_stairs 6 
setblock ~42 ~1 ~11 stone_brick_stairs 7 
setblock ~42 ~1 ~12 stone_brick_stairs 6 
setblock ~42 ~1 ~14 stone_brick_stairs 7  
fill ~42 ~1 ~15 ~43 ~1 ~15 cobblestone_wall  
fill ~42 ~1 ~29 ~42 ~1 ~30 cobblestone_wall  
fill ~42 ~1 ~64 ~42 ~2 ~64 stonebrick 
setblock ~42 ~1 ~65 stone_brick_stairs 3 
setblock ~43 ~1 ~10 stone_brick_stairs 5 
setblock ~43 ~1 ~13 stone_brick_stairs 5 
setblock ~43 ~1 ~29 cobblestone_wall 1 
setblock ~43 ~1 ~30 cobblestone_wall 0 
setblock ~43 ~1 ~64 stone_brick_stairs 1 
setblock ~44 ~1 ~6 stone_brick_stairs 4 
setblock ~44 ~1 ~12 stone_brick_stairs 4  
fill ~44 ~1 ~64 ~47 ~1 ~64 stone_slab 
setblock ~45 ~1 ~5 stone_brick_stairs 6 
setblock ~45 ~1 ~6 stonebrick 0 
setblock ~45 ~1 ~7 stone_brick_stairs 7  
fill ~45 ~1 ~8 ~45 ~3 ~8 iron_bars  
fill ~45 ~1 ~10 ~45 ~3 ~10 iron_bars 
setblock ~45 ~1 ~11 stone_brick_stairs 6 
setblock ~45 ~1 ~12 stonebrick 0 
setblock ~45 ~1 ~13 stone_brick_stairs 7 
setblock ~45 ~1 ~15 cobblestone_wall 6  
fill ~45 ~1 ~29 ~46 ~1 ~29 stonebrick  
fill ~45 ~1 ~30 ~46 ~1 ~30 stonebrick  
fill ~45 ~1 ~35 ~45 ~2 ~35 stone_brick_stairs  
fill ~45 ~1 ~37 ~45 ~2 ~37 stone_brick_stairs  
fill ~45 ~1 ~42 ~55 ~1 ~42 stonebrick 
setblock ~46 ~1 ~6 stone_brick_stairs 5 
setblock ~46 ~1 ~12 stone_brick_stairs 5 
setblock ~47 ~1 ~14 cobblestone_wall 1  
fill ~47 ~1 ~15 ~48 ~1 ~15 cobblestone_wall  
fill ~47 ~1 ~29 ~48 ~1 ~29 cobblestone_wall  
fill ~47 ~1 ~30 ~48 ~1 ~30 cobblestone_wall 
setblock ~47 ~1 ~41 stone_slab 5 
setblock ~48 ~1 ~14 cobblestone_wall 0 
setblock ~48 ~1 ~64 stone_brick_stairs 0  
fill ~49 ~1 ~41 ~50 ~1 ~41 stone_slab  
fill ~49 ~1 ~62 ~50 ~1 ~62 stonebrick  
fill ~49 ~1 ~64 ~50 ~1 ~64 stonebrick 
setblock ~49 ~1 ~65 stone_brick_stairs 3 
setblock ~50 ~1 ~15 cobblestone_wall 6 
setblock ~50 ~1 ~29 cobblestone_wall 6  
fill ~51 ~1 ~19 ~51 ~8 ~19 stonebrick  
fill ~51 ~1 ~20 ~51 ~8 ~20 stonebrick  
fill ~51 ~1 ~24 ~51 ~8 ~24 stonebrick  
fill ~51 ~1 ~25 ~51 ~8 ~25 stonebrick 
setblock ~51 ~1 ~60 stone_brick_stairs 2 
setblock ~51 ~1 ~66 stone_brick_stairs 3  
fill ~51 ~1 ~67 ~51 ~3 ~67 stonebrick  
fill ~52 ~1 ~14 ~53 ~1 ~14 cobblestone_wall 
setblock ~52 ~1 ~15 cobblestone_wall 1 
setblock ~52 ~1 ~17 cobblestone_wall 6  
fill ~52 ~1 ~19 ~53 ~1 ~19 cobblestone_wall  
fill ~52 ~1 ~20 ~53 ~1 ~20 cobblestone_wall 
setblock ~52 ~1 ~22 cobblestone_wall 6  
fill ~52 ~1 ~24 ~53 ~1 ~24 cobblestone_wall  
fill ~52 ~1 ~25 ~53 ~1 ~25 cobblestone_wall 
setblock ~52 ~1 ~27 cobblestone_wall 6  
fill ~52 ~1 ~29 ~53 ~1 ~29 cobblestone_wall  
fill ~52 ~1 ~30 ~53 ~1 ~30 cobblestone_wall  
fill ~52 ~1 ~41 ~53 ~1 ~41 stone_slab  
fill ~52 ~1 ~58 ~52 ~3 ~58 cobblestone_wall  
fill ~52 ~1 ~59 ~52 ~3 ~59 double_stone_slab  
fill ~52 ~1 ~60 ~52 ~3 ~60 stained_hardened_clay  
fill ~52 ~1 ~66 ~52 ~3 ~66 stained_hardened_clay  
fill ~52 ~1 ~67 ~52 ~3 ~67 double_stone_slab  
fill ~52 ~1 ~68 ~52 ~3 ~68 cobblestone_wall 
setblock ~53 ~1 ~15 cobblestone_wall 0  
fill ~53 ~1 ~57 ~53 ~3 ~57 stonebrick  
fill ~53 ~1 ~58 ~53 ~3 ~58 double_stone_slab  
fill ~53 ~1 ~68 ~53 ~3 ~68 double_stone_slab  
fill ~53 ~1 ~69 ~53 ~3 ~69 stonebrick 
setblock ~54 ~1 ~43 stone_brick_stairs 0 
setblock ~54 ~1 ~44 stone_slab 5 
setblock ~54 ~1 ~45 stone_brick_stairs 2 
setblock ~54 ~1 ~57 stone_brick_stairs 0  
fill ~54 ~1 ~58 ~54 ~3 ~58 stained_hardened_clay  
fill ~54 ~1 ~68 ~54 ~3 ~68 stained_hardened_clay 
setblock ~54 ~1 ~69 stone_brick_stairs 0 
setblock ~55 ~1 ~40 stone_brick_stairs 1  
fill ~55 ~1 ~41 ~55 ~3 ~41 stonebrick  
fill ~55 ~1 ~43 ~55 ~2 ~43 stonebrick  
fill ~55 ~1 ~44 ~55 ~0 ~44 stonebrick  
fill ~55 ~1 ~45 ~55 ~15 ~45 stonebrick 
setblock ~55 ~1 ~46 stone_brick_stairs 1 
setblock ~56 ~1 ~40 stone_slab 5 
setblock ~56 ~1 ~46 stone_slab 5  
fill ~56 ~1 ~56 ~58 ~1 ~56 stonebrick  
fill ~56 ~1 ~70 ~58 ~1 ~70 stonebrick 
setblock ~57 ~1 ~40 stone_brick_stairs 2  
fill ~57 ~1 ~41 ~57 ~2 ~41 stonebrick  
fill ~57 ~1 ~45 ~57 ~2 ~45 stonebrick 
setblock ~57 ~1 ~46 stone_brick_stairs 3 
setblock ~58 ~1 ~40 stone_slab 5 
setblock ~58 ~1 ~46 stone_slab 5 
setblock ~59 ~1 ~40 stone_brick_stairs 0  
fill ~59 ~1 ~41 ~59 ~15 ~41 stonebrick  
fill ~59 ~1 ~43 ~59 ~2 ~43 stonebrick  
fill ~59 ~1 ~44 ~59 ~1 ~45 stonebrick 
setblock ~59 ~1 ~46 stone_brick_stairs 0 
setblock ~60 ~1 ~41 stone_brick_stairs 3 
setblock ~60 ~1 ~42 stone_slab 5 
setblock ~60 ~1 ~43 stone_brick_stairs 1 
setblock ~60 ~1 ~44 stone_slab 5 
setblock ~60 ~1 ~45 stone_brick_stairs 2 
setblock ~60 ~1 ~57 stone_brick_stairs 1  
fill ~60 ~1 ~58 ~60 ~3 ~58 stained_hardened_clay  
fill ~60 ~1 ~68 ~60 ~3 ~68 stained_hardened_clay 
setblock ~60 ~1 ~69 stone_brick_stairs 1  
fill ~61 ~1 ~57 ~61 ~3 ~57 stonebrick  
fill ~61 ~1 ~58 ~61 ~3 ~58 double_stone_slab  
fill ~61 ~1 ~68 ~61 ~3 ~68 double_stone_slab  
fill ~61 ~1 ~69 ~61 ~3 ~69 stonebrick  
fill ~62 ~1 ~58 ~62 ~3 ~58 cobblestone_wall  
fill ~62 ~1 ~59 ~62 ~3 ~59 double_stone_slab  
fill ~62 ~1 ~60 ~62 ~3 ~60 stained_hardened_clay  
fill ~62 ~1 ~66 ~62 ~3 ~66 stained_hardened_clay  
fill ~62 ~1 ~67 ~62 ~3 ~67 double_stone_slab  
fill ~62 ~1 ~68 ~62 ~3 ~68 cobblestone_wall 
setblock ~63 ~1 ~60 stone_brick_stairs 2 
setblock ~63 ~1 ~66 stone_brick_stairs 3  
fill ~63 ~1 ~67 ~63 ~3 ~67 stonebrick  
fill ~64 ~1 ~62 ~65 ~1 ~62 stonebrick  
fill ~64 ~1 ~64 ~65 ~1 ~64 stonebrick 
setblock ~3 ~2 ~5 stone_brick_stairs 4 
setblock ~3 ~2 ~11 stone_brick_stairs 4 
setblock ~3 ~2 ~33 stone_brick_stairs 4 
setblock ~3 ~2 ~39 stone_brick_stairs 4 
setblock ~4 ~2 ~4 stone_brick_stairs 6 
setblock ~4 ~2 ~6 stone_brick_stairs 3 
setblock ~4 ~2 ~10 stone_brick_stairs 2  
fill ~4 ~2 ~12 ~4 ~3 ~12 cobblestone_wall 
setblock ~4 ~2 ~32 stone_brick_stairs 6 
setblock ~4 ~2 ~34 stone_brick_stairs 3 
setblock ~4 ~2 ~38 stone_brick_stairs 2 
setblock ~4 ~2 ~40 stone_brick_stairs 7 
setblock ~5 ~2 ~5 stone_brick_stairs 1  
fill ~5 ~2 ~6 ~5 ~5 ~6 brick_block  
fill ~5 ~2 ~7 ~5 ~3 ~7 brick_stairs  
fill ~5 ~2 ~9 ~5 ~3 ~9 brick_stairs  
fill ~5 ~2 ~10 ~5 ~5 ~10 brick_block 
setblock ~5 ~2 ~11 stone_brick_stairs 1  
fill ~5 ~2 ~13 ~5 ~3 ~13 cobblestone_wall  
fill ~5 ~2 ~19 ~5 ~3 ~19 cobblestone_wall  
fill ~5 ~2 ~25 ~5 ~3 ~25 cobblestone_wall  
fill ~5 ~2 ~31 ~5 ~3 ~31 cobblestone_wall  
fill ~5 ~2 ~32 ~6 ~2 ~32 stonebrick 
setblock ~5 ~2 ~33 stone_brick_stairs 1  
fill ~5 ~2 ~34 ~5 ~5 ~34 brick_block  
fill ~5 ~2 ~35 ~5 ~3 ~35 brick_stairs  
fill ~5 ~2 ~37 ~5 ~3 ~37 brick_stairs  
fill ~5 ~2 ~38 ~5 ~5 ~38 brick_block 
setblock ~5 ~2 ~39 stone_brick_stairs 1  
fill ~6 ~2 ~6 ~6 ~3 ~6 brick_stairs  
fill ~6 ~2 ~7 ~8 ~2 ~7 stained_hardened_clay  
fill ~6 ~2 ~9 ~8 ~2 ~9 stained_hardened_clay  
fill ~6 ~2 ~10 ~6 ~3 ~10 brick_stairs  
fill ~6 ~2 ~12 ~6 ~3 ~12 cobblestone_wall 
setblock ~6 ~2 ~14 stone_brick_stairs 7 
setblock ~6 ~2 ~18 stone_brick_stairs 6  
fill ~6 ~2 ~20 ~6 ~3 ~20 cobblestone_wall  
fill ~6 ~2 ~24 ~6 ~3 ~24 cobblestone_wall 
setblock ~6 ~2 ~26 stone_brick_stairs 7 
setblock ~6 ~2 ~30 stone_brick_stairs 6  
fill ~6 ~2 ~34 ~6 ~3 ~34 brick_stairs  
fill ~6 ~2 ~35 ~8 ~2 ~35 stained_hardened_clay  
fill ~6 ~2 ~37 ~8 ~2 ~37 stained_hardened_clay  
fill ~6 ~2 ~38 ~6 ~3 ~38 brick_stairs 
setblock ~7 ~2 ~15 brick_stairs 3 
setblock ~7 ~2 ~17 brick_stairs 2 
setblock ~7 ~2 ~20 brick_stairs 3 
setblock ~7 ~2 ~24 brick_stairs 2  
fill ~7 ~2 ~25 ~7 ~4 ~25 brick_block  
fill ~7 ~2 ~26 ~7 ~4 ~26 brick_block 
setblock ~7 ~2 ~27 brick_stairs 3 
setblock ~7 ~2 ~29 brick_stairs 2  
fill ~7 ~2 ~30 ~7 ~4 ~30 brick_block  
fill ~7 ~2 ~31 ~7 ~4 ~31 brick_block  
fill ~7 ~2 ~32 ~7 ~4 ~32 brick_block  
fill ~8 ~2 ~6 ~8 ~3 ~6 brick_stairs  
fill ~8 ~2 ~10 ~8 ~3 ~10 brick_stairs  
fill ~8 ~2 ~15 ~8 ~3 ~15 stained_hardened_clay  
fill ~8 ~2 ~16 ~8 ~3 ~16 stained_hardened_clay  
fill ~8 ~2 ~17 ~8 ~3 ~17 stained_hardened_clay  
fill ~8 ~2 ~20 ~8 ~3 ~20 stained_hardened_clay 
setblock ~8 ~2 ~22 wooden_door 4  
fill ~8 ~2 ~24 ~8 ~3 ~24 stained_hardened_clay  
fill ~8 ~2 ~27 ~8 ~3 ~27 stained_hardened_clay  
fill ~8 ~2 ~28 ~8 ~3 ~28 stained_hardened_clay  
fill ~8 ~2 ~29 ~8 ~3 ~29 stained_hardened_clay  
fill ~8 ~2 ~34 ~8 ~3 ~34 brick_stairs  
fill ~8 ~2 ~38 ~8 ~3 ~38 brick_stairs 
setblock ~9 ~2 ~5 stone_brick_stairs 0  
fill ~9 ~2 ~6 ~9 ~5 ~6 brick_block  
fill ~9 ~2 ~7 ~9 ~3 ~7 brick_stairs  
fill ~9 ~2 ~9 ~9 ~3 ~9 brick_stairs  
fill ~9 ~2 ~10 ~9 ~5 ~10 brick_block  
fill ~9 ~2 ~11 ~31 ~2 ~11 stonebrick 
setblock ~9 ~2 ~12 cobblestone_wall 0 
setblock ~9 ~2 ~17 stone_brick_stairs 5 
setblock ~9 ~2 ~21 stone_brick_stairs 3 
setblock ~9 ~2 ~23 stone_brick_stairs 2 
setblock ~9 ~2 ~29 stone_brick_stairs 5 
setblock ~9 ~2 ~31 cobblestone_wall 0  
fill ~9 ~2 ~32 ~10 ~2 ~32 stonebrick 
setblock ~9 ~2 ~33 stone_brick_stairs 0  
fill ~9 ~2 ~34 ~9 ~5 ~34 brick_block  
fill ~9 ~2 ~35 ~9 ~3 ~35 brick_stairs  
fill ~9 ~2 ~37 ~9 ~3 ~37 brick_stairs  
fill ~9 ~2 ~38 ~9 ~5 ~38 brick_block 
setblock ~9 ~2 ~39 stone_brick_stairs 0 
setblock ~10 ~2 ~4 stone_brick_stairs 6 
setblock ~10 ~2 ~6 stone_brick_stairs 3 
setblock ~10 ~2 ~10 stone_brick_stairs 2  
fill ~10 ~2 ~12 ~10 ~10 ~12 cobblestone  
fill ~10 ~2 ~19 ~10 ~6 ~19 stonebrick 
setblock ~10 ~2 ~21 stone_brick_stairs 1 
setblock ~10 ~2 ~23 stone_brick_stairs 1  
fill ~10 ~2 ~25 ~10 ~6 ~25 stonebrick  
fill ~10 ~2 ~31 ~11 ~2 ~31 cobblestone  
fill ~10 ~2 ~33 ~37 ~2 ~33 stonebrick 
setblock ~10 ~2 ~34 stone_brick_stairs 3 
setblock ~10 ~2 ~38 stone_brick_stairs 2 
setblock ~10 ~2 ~40 stone_brick_stairs 7 
setblock ~10 ~2 ~42 cobblestone_wall 0 
setblock ~11 ~2 ~5 stone_brick_stairs 5 
setblock ~11 ~2 ~7 stone_slab 5  
fill ~11 ~2 ~8 ~13 ~2 ~8 planks  
fill ~11 ~2 ~13 ~11 ~10 ~13 cobblestone  
fill ~11 ~2 ~16 ~11 ~3 ~16 cobblestone_wall  
fill ~11 ~2 ~18 ~11 ~2 ~19 cobblestone_wall  
fill ~11 ~2 ~20 ~11 ~3 ~20 cobblestone_wall  
fill ~11 ~2 ~24 ~11 ~3 ~24 cobblestone_wall 
setblock ~11 ~2 ~25 cobblestone_wall 0  
fill ~11 ~2 ~28 ~11 ~3 ~28 cobblestone_wall 
setblock ~11 ~2 ~30 cobblestone_wall 0 
setblock ~11 ~2 ~39 stone_brick_stairs 5  
fill ~11 ~2 ~41 ~11 ~2 ~42 stone_brick_stairs 
setblock ~11 ~2 ~44 cobblestone_wall 0 
setblock ~12 ~2 ~6 stone_brick_stairs 6  
fill ~12 ~2 ~7 ~12 ~6 ~7 stonebrick  
fill ~12 ~2 ~12 ~12 ~10 ~12 cobblestone  
fill ~12 ~2 ~19 ~12 ~3 ~19 cobblestone_wall  
fill ~12 ~2 ~25 ~12 ~3 ~25 cobblestone_wall  
fill ~12 ~2 ~32 ~12 ~10 ~32 cobblestone  
fill ~12 ~2 ~41 ~12 ~2 ~42 brick_block  
fill ~12 ~2 ~43 ~12 ~2 ~44 stone_brick_stairs 
setblock ~12 ~2 ~46 cobblestone_wall 0 
setblock ~13 ~2 ~7 stone_slab 5  
fill ~13 ~2 ~9 ~15 ~2 ~9 planks 
setblock ~13 ~2 ~12 cobblestone_wall 0 
setblock ~13 ~2 ~32 cobblestone_wall 0  
fill ~13 ~2 ~43 ~13 ~2 ~44 brick_block  
fill ~13 ~2 ~45 ~13 ~2 ~46 stone_brick_stairs 
setblock ~13 ~2 ~48 cobblestone_wall 0 
setblock ~14 ~2 ~8 dropper 5 
setblock ~14 ~2 ~14 stone_slab 13 
setblock ~14 ~2 ~30 stone_slab 13  
fill ~14 ~2 ~45 ~14 ~2 ~46 brick_block  
fill ~14 ~2 ~47 ~14 ~2 ~48 stone_brick_stairs 
setblock ~14 ~2 ~50 cobblestone_wall 0  
fill ~14 ~2 ~53 ~14 ~4 ~53 cobblestone_wall  
fill ~14 ~2 ~59 ~14 ~4 ~59 cobblestone_wall  
fill ~14 ~2 ~65 ~14 ~4 ~65 cobblestone_wall 
setblock ~15 ~2 ~7 stone_slab 5  
fill ~15 ~2 ~8 ~17 ~2 ~8 planks 
setblock ~15 ~2 ~13 stone_slab 13 
setblock ~15 ~2 ~14 stonebrick 3 
setblock ~15 ~2 ~15 stone_slab 13 
setblock ~15 ~2 ~29 stone_slab 13 
setblock ~15 ~2 ~30 stonebrick 3 
setblock ~15 ~2 ~31 stone_slab 13  
fill ~15 ~2 ~47 ~15 ~2 ~48 brick_block  
fill ~15 ~2 ~49 ~15 ~2 ~50 stone_brick_stairs  
fill ~15 ~2 ~52 ~15 ~4 ~52 cobblestone_wall  
fill ~15 ~2 ~53 ~15 ~5 ~53 stonebrick 
setblock ~15 ~2 ~54 cobblestone_wall 0 
setblock ~15 ~2 ~58 cobblestone_wall 0  
fill ~15 ~2 ~59 ~15 ~5 ~59 stonebrick 
setblock ~15 ~2 ~60 cobblestone_wall 0 
setblock ~15 ~2 ~64 cobblestone_wall 0  
fill ~15 ~2 ~65 ~15 ~5 ~65 stonebrick  
fill ~15 ~2 ~66 ~15 ~4 ~66 cobblestone_wall 
setblock ~16 ~2 ~6 stone_brick_stairs 6  
fill ~16 ~2 ~7 ~16 ~6 ~7 stonebrick 
setblock ~16 ~2 ~14 stone_slab 13 
setblock ~16 ~2 ~30 stone_slab 13  
fill ~16 ~2 ~49 ~16 ~2 ~50 brick_block 
setblock ~16 ~2 ~51 stone_brick_stairs 7 
setblock ~16 ~2 ~53 cobblestone_wall 0 
setblock ~16 ~2 ~55 dropper 0 
setblock ~16 ~2 ~57 dropper 0  
fill ~16 ~2 ~59 ~16 ~7 ~59 stonebrick 
setblock ~16 ~2 ~61 dropper 0 
setblock ~16 ~2 ~63 dropper 0 
setblock ~16 ~2 ~65 cobblestone_wall 0 
setblock ~17 ~2 ~7 stone_slab 5  
fill ~17 ~2 ~9 ~19 ~2 ~9 planks 
setblock ~17 ~2 ~12 cobblestone_wall 0 
setblock ~17 ~2 ~32 cobblestone_wall 0 
setblock ~17 ~2 ~51 brick_block 0 
setblock ~17 ~2 ~54 dropper 0  
fill ~17 ~2 ~55 ~19 ~2 ~55 planks  
fill ~17 ~2 ~56 ~17 ~2 ~57 planks  
fill ~17 ~2 ~61 ~17 ~6 ~61 planks  
fill ~17 ~2 ~62 ~17 ~2 ~63 planks 
setblock ~17 ~2 ~64 dropper 0 
setblock ~18 ~2 ~8 dropper 5  
fill ~18 ~2 ~12 ~18 ~10 ~12 cobblestone  
fill ~18 ~2 ~32 ~18 ~10 ~32 cobblestone  
fill ~18 ~2 ~63 ~19 ~2 ~63 planks 
setblock ~19 ~2 ~7 stone_slab 5  
fill ~19 ~2 ~8 ~21 ~2 ~8 planks  
fill ~19 ~2 ~13 ~19 ~10 ~13 cobblestone 
setblock ~19 ~2 ~14 cobblestone_wall 0 
setblock ~19 ~2 ~30 cobblestone_wall 0  
fill ~19 ~2 ~31 ~19 ~10 ~31 cobblestone 
setblock ~19 ~2 ~54 dropper 0 
setblock ~19 ~2 ~64 dropper 0 
setblock ~20 ~2 ~6 stone_brick_stairs 6  
fill ~20 ~2 ~7 ~20 ~6 ~7 stonebrick  
fill ~20 ~2 ~12 ~20 ~10 ~12 cobblestone  
fill ~20 ~2 ~32 ~20 ~10 ~32 cobblestone 
setblock ~20 ~2 ~53 cobblestone_wall 0 
setblock ~20 ~2 ~65 cobblestone_wall 0 
setblock ~21 ~2 ~7 stone_slab 5  
fill ~21 ~2 ~9 ~24 ~2 ~9 planks 
setblock ~21 ~2 ~12 cobblestone_wall 0 
setblock ~21 ~2 ~32 cobblestone_wall 0  
fill ~21 ~2 ~52 ~21 ~4 ~52 cobblestone_wall  
fill ~21 ~2 ~53 ~21 ~5 ~53 stonebrick  
fill ~21 ~2 ~65 ~21 ~5 ~65 stonebrick  
fill ~21 ~2 ~66 ~21 ~4 ~66 cobblestone_wall 
setblock ~22 ~2 ~8 dropper 5 
setblock ~22 ~2 ~14 stone_slab 13 
setblock ~22 ~2 ~30 stone_slab 13 
setblock ~22 ~2 ~53 cobblestone_wall 0 
setblock ~22 ~2 ~65 cobblestone_wall 0 
setblock ~23 ~2 ~7 stone_slab 5  
fill ~23 ~2 ~8 ~25 ~2 ~8 planks 
setblock ~23 ~2 ~13 stone_slab 13 
setblock ~23 ~2 ~14 stonebrick 3 
setblock ~23 ~2 ~15 stone_slab 13 
setblock ~23 ~2 ~29 stone_slab 13 
setblock ~23 ~2 ~30 stonebrick 3 
setblock ~23 ~2 ~31 stone_slab 13 
setblock ~23 ~2 ~54 dropper 0  
fill ~23 ~2 ~55 ~25 ~2 ~55 planks  
fill ~23 ~2 ~63 ~25 ~2 ~63 planks 
setblock ~23 ~2 ~64 dropper 0 
setblock ~24 ~2 ~6 stone_brick_stairs 6  
fill ~24 ~2 ~7 ~24 ~6 ~7 stonebrick 
setblock ~24 ~2 ~14 stone_slab 13 
setblock ~24 ~2 ~30 stone_slab 13  
fill ~25 ~2 ~3 ~25 ~3 ~3 cobblestone_wall 
setblock ~25 ~2 ~5 stone_brick_stairs 4 
setblock ~25 ~2 ~7 stone_slab 5 
setblock ~25 ~2 ~12 cobblestone_wall 0 
setblock ~25 ~2 ~32 cobblestone_wall 0 
setblock ~25 ~2 ~54 dropper 0  
fill ~25 ~2 ~56 ~25 ~2 ~57 planks  
fill ~25 ~2 ~61 ~25 ~6 ~61 planks  
fill ~25 ~2 ~62 ~25 ~2 ~61 planks 
setblock ~25 ~2 ~64 dropper 0  
fill ~26 ~2 ~2 ~26 ~3 ~2 cobblestone_wall 
setblock ~26 ~2 ~4 stone_brick_stairs 2 
setblock ~26 ~2 ~6 stone_brick_stairs 3  
fill ~26 ~2 ~8 ~26 ~3 ~8 cobblestone_wall  
fill ~26 ~2 ~12 ~26 ~10 ~12 cobblestone  
fill ~26 ~2 ~32 ~26 ~10 ~32 cobblestone 
setblock ~26 ~2 ~53 cobblestone_wall 0 
setblock ~26 ~2 ~55 dropper 0 
setblock ~26 ~2 ~57 dropper 0 
setblock ~26 ~2 ~61 dropper 0 
setblock ~26 ~2 ~63 dropper 0 
setblock ~26 ~2 ~65 cobblestone_wall 0 
setblock ~27 ~2 ~3 stone_brick_stairs 0  
fill ~27 ~2 ~4 ~27 ~5 ~4 stained_hardened_clay  
fill ~27 ~2 ~6 ~27 ~5 ~6 stained_hardened_clay 
setblock ~27 ~2 ~7 stone_brick_stairs 0  
fill ~27 ~2 ~13 ~27 ~10 ~13 cobblestone 
setblock ~27 ~2 ~14 cobblestone_wall 0 
setblock ~27 ~2 ~30 cobblestone_wall 0  
fill ~27 ~2 ~31 ~27 ~10 ~31 cobblestone  
fill ~27 ~2 ~52 ~27 ~4 ~52 cobblestone_wall  
fill ~27 ~2 ~53 ~27 ~5 ~53 stonebrick 
setblock ~27 ~2 ~54 cobblestone_wall 0 
setblock ~27 ~2 ~58 cobblestone_wall 0  
fill ~27 ~2 ~59 ~27 ~5 ~59 stonebrick 
setblock ~27 ~2 ~60 cobblestone_wall 0 
setblock ~27 ~2 ~64 stone_brick_stairs 4  
fill ~27 ~2 ~65 ~27 ~5 ~65 stonebrick  
fill ~27 ~2 ~66 ~27 ~4 ~66 cobblestone_wall 
setblock ~28 ~2 ~2 stone_brick_stairs 6 
setblock ~28 ~2 ~8 stone_brick_stairs 7  
fill ~28 ~2 ~12 ~28 ~10 ~12 cobblestone  
fill ~28 ~2 ~32 ~28 ~10 ~32 cobblestone  
fill ~28 ~2 ~53 ~28 ~4 ~53 cobblestone_wall  
fill ~28 ~2 ~59 ~28 ~4 ~59 cobblestone_wall  
fill ~28 ~2 ~63 ~29 ~2 ~63 cobblestone 
setblock ~28 ~2 ~65 stone_brick_stairs 7 
setblock ~29 ~2 ~3 stone_brick_stairs 1  
fill ~29 ~2 ~4 ~29 ~5 ~4 stained_hardened_clay  
fill ~29 ~2 ~6 ~29 ~5 ~6 stained_hardened_clay 
setblock ~29 ~2 ~7 stone_brick_stairs 1 
setblock ~29 ~2 ~12 cobblestone_wall 0 
setblock ~29 ~2 ~32 cobblestone_wall 0 
setblock ~29 ~2 ~64 stone_brick_stairs 5  
fill ~30 ~2 ~2 ~30 ~3 ~2 cobblestone_wall 
setblock ~30 ~2 ~4 stone_brick_stairs 2 
setblock ~30 ~2 ~6 stone_brick_stairs 3  
fill ~30 ~2 ~8 ~30 ~3 ~8 cobblestone_wall 
setblock ~30 ~2 ~14 stone_slab 13 
setblock ~30 ~2 ~30 stone_slab 13  
fill ~30 ~2 ~62 ~30 ~6 ~62 planks 
setblock ~30 ~2 ~63 stone_stairs 0  
fill ~31 ~2 ~3 ~31 ~3 ~3 cobblestone_wall 
setblock ~31 ~2 ~5 stone_brick_stairs 5  
fill ~31 ~2 ~7 ~31 ~3 ~7 cobblestone_wall 
setblock ~31 ~2 ~13 stone_slab 13 
setblock ~31 ~2 ~14 stonebrick 3 
setblock ~31 ~2 ~15 stone_slab 13 
setblock ~31 ~2 ~29 stone_slab 13 
setblock ~31 ~2 ~30 stonebrick 3 
setblock ~31 ~2 ~31 stone_slab 13  
fill ~31 ~2 ~62 ~32 ~2 ~62 planks 
setblock ~31 ~2 ~63 stone_stairs 5 
setblock ~32 ~2 ~6 cobblestone_wall 0 
setblock ~32 ~2 ~10 stone_brick_stairs 0 
setblock ~32 ~2 ~14 stone_slab 13 
setblock ~32 ~2 ~30 stone_slab 13 
setblock ~32 ~2 ~63 stone_stairs 4  
fill ~33 ~2 ~5 ~33 ~3 ~5 cobblestone_wall  
fill ~33 ~2 ~6 ~33 ~6 ~6 stonebrick 
setblock ~33 ~2 ~7 cobblestone_wall 0 
setblock ~33 ~2 ~9 stone_brick_stairs 2 
setblock ~33 ~2 ~11 stone_brick_stairs 3 
setblock ~33 ~2 ~12 cobblestone_wall 0 
setblock ~33 ~2 ~32 cobblestone_wall 0  
fill ~33 ~2 ~62 ~33 ~6 ~62 planks 
setblock ~33 ~2 ~63 stone_stairs 1 
setblock ~34 ~2 ~6 cobblestone_wall 0 
setblock ~34 ~2 ~10 stone_brick_stairs 1  
fill ~34 ~2 ~12 ~34 ~10 ~12 cobblestone  
fill ~34 ~2 ~32 ~34 ~10 ~32 cobblestone  
fill ~34 ~2 ~63 ~36 ~2 ~63 cobblestone 
setblock ~34 ~2 ~64 stone_brick_stairs 4  
fill ~35 ~2 ~6 ~37 ~2 ~6 iron_bars 
setblock ~35 ~2 ~10 stone_brick_stairs 0  
fill ~35 ~2 ~13 ~35 ~10 ~13 cobblestone 
setblock ~35 ~2 ~14 cobblestone_wall 0 
setblock ~35 ~2 ~30 cobblestone_wall 0  
fill ~35 ~2 ~31 ~35 ~10 ~31 cobblestone 
setblock ~35 ~2 ~65 stone_brick_stairs 7 
setblock ~36 ~2 ~9 stone_brick_stairs 2 
setblock ~36 ~2 ~11 stone_brick_stairs 3  
fill ~36 ~2 ~12 ~36 ~10 ~12 cobblestone  
fill ~36 ~2 ~31 ~36 ~11 ~31 stonebrick  
fill ~36 ~2 ~32 ~36 ~10 ~32 cobblestone 
setblock ~36 ~2 ~64 stone_brick_stairs 5 
setblock ~37 ~2 ~10 stone_brick_stairs 1 
setblock ~37 ~2 ~12 cobblestone_wall 0 
setblock ~37 ~2 ~14 stonebrick 0 
setblock ~37 ~2 ~15 stone_brick_stairs 0 
setblock ~37 ~2 ~19 stone_brick_stairs 2 
setblock ~37 ~2 ~20 stone_brick_stairs 8 
setblock ~37 ~2 ~24 stone_brick_stairs 5  
fill ~37 ~2 ~25 ~39 ~2 ~25 stonebrick  
fill ~37 ~2 ~29 ~39 ~2 ~29 stonebrick 
setblock ~37 ~2 ~30 cobblestone_wall 0  
fill ~37 ~2 ~32 ~37 ~12 ~32 stonebrick  
fill ~37 ~2 ~62 ~37 ~6 ~62 planks 
setblock ~37 ~2 ~63 stone_stairs 0 
setblock ~38 ~2 ~6 cobblestone_wall 0 
setblock ~38 ~2 ~10 stone_brick_stairs 0 
setblock ~38 ~2 ~14 stone_brick_stairs 4 
setblock ~38 ~2 ~15 stone_brick_stairs 8 
setblock ~38 ~2 ~16 stone_slab 13 
setblock ~38 ~2 ~17 stone_slab 5 
setblock ~38 ~2 ~18 stone_slab 13 
setblock ~38 ~2 ~19 stone_brick_stairs 8 
setblock ~38 ~2 ~20 stonebrick 0 
setblock ~38 ~2 ~21 stone_slab 13 
setblock ~38 ~2 ~22 stone_slab 5 
setblock ~38 ~2 ~23 stone_slab 13 
setblock ~38 ~2 ~24 stone_brick_stairs 8 
setblock ~38 ~2 ~26 stone_slab 13 
setblock ~38 ~2 ~27 stone_slab 5 
setblock ~38 ~2 ~28 stone_slab 13 
setblock ~38 ~2 ~30 stonebrick 0  
fill ~38 ~2 ~62 ~39 ~2 ~62 planks 
setblock ~38 ~2 ~63 stone_stairs 5  
fill ~39 ~2 ~5 ~39 ~3 ~5 cobblestone_wall  
fill ~39 ~2 ~6 ~39 ~6 ~6 stonebrick 
setblock ~39 ~2 ~7 cobblestone_wall 0 
setblock ~39 ~2 ~9 stone_brick_stairs 2 
setblock ~39 ~2 ~11 stone_brick_stairs 3  
fill ~39 ~2 ~16 ~51 ~2 ~16 stonebrick  
fill ~39 ~2 ~28 ~51 ~2 ~28 stonebrick 
setblock ~39 ~2 ~63 stone_stairs 4 
setblock ~40 ~2 ~6 cobblestone_wall 0 
setblock ~40 ~2 ~10 stone_brick_stairs 1 
setblock ~40 ~2 ~15 stone_slab 5 
setblock ~40 ~2 ~29 stone_slab 5  
fill ~40 ~2 ~62 ~40 ~6 ~62 planks 
setblock ~40 ~2 ~63 stone_stairs 1  
fill ~41 ~2 ~6 ~43 ~2 ~6 iron_bars 
setblock ~41 ~2 ~10 stone_brick_stairs 0 
setblock ~41 ~2 ~13 stone_brick_stairs 0 
setblock ~41 ~2 ~15 stone_slab 13 
setblock ~41 ~2 ~29 stone_slab 13  
fill ~41 ~2 ~63 ~43 ~2 ~63 cobblestone 
setblock ~41 ~2 ~64 stone_brick_stairs 4 
setblock ~42 ~2 ~9 stone_brick_stairs 2 
setblock ~42 ~2 ~11 stone_brick_stairs 3 
setblock ~42 ~2 ~12 stone_brick_stairs 2 
setblock ~42 ~2 ~14 stone_brick_stairs 3 
setblock ~42 ~2 ~15 stonebrick 2 
setblock ~42 ~2 ~29 stone_brick_stairs 6 
setblock ~42 ~2 ~30 stone_brick_stairs 7 
setblock ~42 ~2 ~65 stone_brick_stairs 7 
setblock ~43 ~2 ~10 stone_brick_stairs 1 
setblock ~43 ~2 ~13 stone_brick_stairs 1 
setblock ~43 ~2 ~15 stonebrick 0  
fill ~43 ~2 ~29 ~43 ~3 ~29 stone_brick_stairs 
setblock ~43 ~2 ~30 stonebrick 2 
setblock ~43 ~2 ~64 stone_brick_stairs 5 
setblock ~44 ~2 ~6 cobblestone_wall 0 
setblock ~44 ~2 ~12 cobblestone_wall 0 
setblock ~44 ~2 ~15 stone_slab 13 
setblock ~44 ~2 ~29 stone_slab 13  
fill ~44 ~2 ~34 ~44 ~3 ~34 stained_hardened_clay  
fill ~44 ~2 ~38 ~44 ~3 ~38 stained_hardened_clay  
fill ~44 ~2 ~62 ~44 ~6 ~62 planks 
setblock ~44 ~2 ~63 stone_stairs 0  
fill ~45 ~2 ~5 ~45 ~3 ~5 cobblestone_wall  
fill ~45 ~2 ~6 ~45 ~6 ~6 stonebrick 
setblock ~45 ~2 ~7 cobblestone_wall 0 
setblock ~45 ~2 ~11 cobblestone_wall 0  
fill ~45 ~2 ~12 ~45 ~6 ~12 stonebrick 
setblock ~45 ~2 ~13 cobblestone_wall 0 
setblock ~45 ~2 ~15 stone_slab 5  
fill ~45 ~2 ~29 ~45 ~4 ~29 stonebrick  
fill ~45 ~2 ~30 ~47 ~2 ~30 stonebrick 
setblock ~45 ~2 ~34 stone_brick_stairs 3 
setblock ~45 ~2 ~38 stone_brick_stairs 2  
fill ~45 ~2 ~42 ~54 ~2 ~42 stonebrick  
fill ~45 ~2 ~62 ~46 ~2 ~62 planks 
setblock ~45 ~2 ~63 stone_stairs 5  
fill ~46 ~2 ~6 ~46 ~3 ~6 cobblestone_wall  
fill ~46 ~2 ~12 ~46 ~3 ~12 cobblestone_wall 
setblock ~46 ~2 ~15 stone_slab 13 
setblock ~46 ~2 ~29 stone_slab 13 
setblock ~46 ~2 ~63 stone_stairs 4  
fill ~47 ~2 ~14 ~48 ~2 ~14 stonebrick 
setblock ~47 ~2 ~15 stone_brick_stairs 2  
fill ~47 ~2 ~29 ~47 ~3 ~29 stonebrick  
fill ~47 ~2 ~62 ~47 ~6 ~62 planks  

KittysCommands:  
setblock ~47 ~2 ~63 stone_stairs 1 
setblock ~48 ~2 ~15 stone_brick_stairs 8 
setblock ~48 ~2 ~29 stone_brick_stairs 7 
setblock ~48 ~2 ~30 stone_brick_stairs 2  
fill ~48 ~2 ~63 ~49 ~2 ~63 cobblestone 
setblock ~48 ~2 ~64 stone_brick_stairs 4 
setblock ~49 ~2 ~15 stone_slab 13 
setblock ~49 ~2 ~29 stone_slab 13  
fill ~49 ~2 ~62 ~50 ~2 ~62 stonebrick  
fill ~49 ~2 ~64 ~50 ~2 ~64 stonebrick 
setblock ~49 ~2 ~65 stone_brick_stairs 7 
setblock ~50 ~2 ~15 stone_slab 5 
setblock ~50 ~2 ~29 stone_slab 5  
fill ~50 ~2 ~63 ~50 ~3 ~63 iron_bars 
setblock ~51 ~2 ~15 stone_slab 13 
setblock ~51 ~2 ~29 stone_slab 13  
fill ~51 ~2 ~60 ~51 ~3 ~60 stone_brick_stairs  
fill ~51 ~2 ~66 ~51 ~3 ~66 stone_brick_stairs  
fill ~52 ~2 ~14 ~53 ~2 ~14 stonebrick 
setblock ~52 ~2 ~15 stone_brick_stairs 7 
setblock ~52 ~2 ~16 stone_slab 13 
setblock ~52 ~2 ~17 stone_slab 5 
setblock ~52 ~2 ~18 stone_slab 13  
fill ~52 ~2 ~19 ~53 ~2 ~19 stonebrick 
setblock ~52 ~2 ~20 stone_brick_stairs 7 
setblock ~52 ~2 ~21 stone_slab 13 
setblock ~52 ~2 ~22 stone_slab 5 
setblock ~52 ~2 ~23 stone_slab 13  
fill ~52 ~2 ~24 ~52 ~3 ~24 stonebrick 
setblock ~52 ~2 ~25 stone_brick_stairs 6 
setblock ~52 ~2 ~26 stone_slab 13 
setblock ~52 ~2 ~27 stone_slab 5 
setblock ~52 ~2 ~28 stone_slab 13  
fill ~52 ~2 ~29 ~53 ~2 ~29 stone_brick_stairs 
setblock ~52 ~2 ~30 stone_brick_stairs 4 
setblock ~53 ~2 ~15 stonebrick 0 
setblock ~53 ~2 ~20 stone_brick_stairs 3 
setblock ~53 ~2 ~24 stone_brick_stairs 2 
setblock ~53 ~2 ~25 stone_brick_stairs 8 
setblock ~53 ~2 ~30 stone_brick_stairs 7 
setblock ~54 ~2 ~43 stone_brick_stairs 4  
fill ~54 ~2 ~45 ~54 ~3 ~45 cobblestone_wall  
fill ~54 ~2 ~57 ~54 ~3 ~57 stone_brick_stairs  
fill ~54 ~2 ~69 ~54 ~3 ~69 stone_brick_stairs  
fill ~55 ~2 ~40 ~55 ~3 ~40 cobblestone_wall 
setblock ~55 ~2 ~42 stone_brick_stairs 2 
setblock ~55 ~2 ~44 stone_brick_stairs 3  
fill ~55 ~2 ~46 ~55 ~3 ~46 cobblestone_wall 
setblock ~56 ~2 ~41 stone_brick_stairs 0  
fill ~56 ~2 ~42 ~56 ~5 ~42 stained_hardened_clay  
fill ~56 ~2 ~44 ~56 ~5 ~44 stained_hardened_clay 
setblock ~56 ~2 ~45 stone_brick_stairs 0  
fill ~56 ~2 ~56 ~56 ~4 ~56 stonebrick  
fill ~56 ~2 ~70 ~56 ~4 ~70 stonebrick 
setblock ~57 ~2 ~40 stone_brick_stairs 6 
setblock ~57 ~2 ~46 stone_brick_stairs 7 
setblock ~57 ~2 ~56 iron_bars 0  
fill ~57 ~2 ~70 ~57 ~3 ~70 iron_bars 
setblock ~58 ~2 ~41 stone_brick_stairs 1  
fill ~58 ~2 ~42 ~58 ~5 ~42 stained_hardened_clay  
fill ~58 ~2 ~44 ~58 ~5 ~44 stained_hardened_clay 
setblock ~58 ~2 ~45 stone_brick_stairs 1  
fill ~58 ~2 ~56 ~58 ~4 ~56 stonebrick  
fill ~58 ~2 ~70 ~58 ~4 ~70 stonebrick  
fill ~59 ~2 ~40 ~59 ~3 ~40 cobblestone_wall 
setblock ~59 ~2 ~42 stone_brick_stairs 2 
setblock ~59 ~2 ~44 stone_brick_stairs 3  
fill ~59 ~2 ~45 ~59 ~15 ~45 stonebrick  
fill ~59 ~2 ~46 ~59 ~3 ~46 cobblestone_wall  
fill ~60 ~2 ~41 ~60 ~3 ~41 cobblestone_wall 
setblock ~60 ~2 ~43 stone_brick_stairs 5  
fill ~60 ~2 ~45 ~60 ~3 ~45 cobblestone_wall  
fill ~60 ~2 ~57 ~60 ~3 ~57 stone_brick_stairs  
fill ~60 ~2 ~69 ~60 ~3 ~69 stone_brick_stairs  
fill ~63 ~2 ~60 ~63 ~3 ~60 stone_brick_stairs  
fill ~63 ~2 ~66 ~63 ~3 ~66 stone_brick_stairs  
fill ~64 ~2 ~62 ~65 ~2 ~62 stonebrick  
fill ~64 ~2 ~63 ~64 ~3 ~63 iron_bars  
fill ~64 ~2 ~64 ~65 ~2 ~64 stonebrick  
fill ~3 ~3 ~5 ~3 ~4 ~5 cobblestone_wall  
fill ~3 ~3 ~11 ~3 ~4 ~11 cobblestone_wall  
fill ~3 ~3 ~33 ~3 ~4 ~33 cobblestone_wall  
fill ~3 ~3 ~39 ~3 ~4 ~39 cobblestone_wall  
fill ~4 ~3 ~4 ~4 ~4 ~4 cobblestone_wall 
setblock ~4 ~3 ~6 stone_brick_stairs 7 
setblock ~4 ~3 ~10 stone_brick_stairs 6  
fill ~4 ~3 ~32 ~4 ~4 ~32 cobblestone_wall 
setblock ~4 ~3 ~34 stone_brick_stairs 7 
setblock ~4 ~3 ~38 stone_brick_stairs 6  
fill ~4 ~3 ~40 ~4 ~4 ~40 cobblestone_wall 
setblock ~5 ~3 ~5 stone_brick_stairs 5 
setblock ~5 ~3 ~11 stone_brick_stairs 5  
fill ~5 ~3 ~32 ~6 ~3 ~32 stonebrick 
setblock ~5 ~3 ~33 stone_brick_stairs 5 
setblock ~5 ~3 ~39 stone_brick_stairs 5  
fill ~6 ~3 ~7 ~8 ~3 ~7 stained_hardened_clay  
fill ~6 ~3 ~9 ~8 ~3 ~9 stained_hardened_clay 
setblock ~6 ~3 ~14 stone_slab 5 
setblock ~6 ~3 ~15 stone_slab 13 
setblock ~6 ~3 ~17 stone_slab 13 
setblock ~6 ~3 ~18 stone_slab 5 
setblock ~6 ~3 ~26 stone_slab 5 
setblock ~6 ~3 ~27 stone_slab 13 
setblock ~6 ~3 ~29 stone_slab 13 
setblock ~6 ~3 ~30 stone_slab 5  
fill ~6 ~3 ~35 ~8 ~3 ~35 stained_hardened_clay  
fill ~6 ~3 ~37 ~8 ~3 ~37 stained_hardened_clay  
fill ~7 ~3 ~15 ~7 ~4 ~15 brick_block 
setblock ~7 ~3 ~16 stone_slab 12  
fill ~7 ~3 ~17 ~7 ~4 ~17 brick_block 
setblock ~7 ~3 ~20 brick_stairs 7 
setblock ~7 ~3 ~24 brick_stairs 6  
fill ~7 ~3 ~27 ~7 ~4 ~27 brick_block 
setblock ~7 ~3 ~28 stone_slab 12  
fill ~7 ~3 ~29 ~7 ~4 ~29 brick_block 
setblock ~8 ~3 ~22 wooden_door 8 
setblock ~9 ~3 ~5 stone_brick_stairs 4  
fill ~9 ~3 ~11 ~12 ~3 ~11 stonebrick 
setblock ~9 ~3 ~21 stone_brick_stairs 7 
setblock ~9 ~3 ~23 stone_brick_stairs 6  
fill ~9 ~3 ~32 ~10 ~3 ~32 stonebrick 
setblock ~9 ~3 ~33 stone_brick_stairs 4 
setblock ~9 ~3 ~39 stone_brick_stairs 4  
fill ~10 ~3 ~4 ~10 ~4 ~4 cobblestone_wall 
setblock ~10 ~3 ~6 stone_brick_stairs 7 
setblock ~10 ~3 ~10 stone_brick_stairs 6 
setblock ~10 ~3 ~13 stonebrick 0 
setblock ~10 ~3 ~15 stone_brick_stairs 1 
setblock ~10 ~3 ~17 stone_brick_stairs 1  
fill ~10 ~3 ~21 ~10 ~4 ~21 stone_brick_stairs  
fill ~10 ~3 ~23 ~10 ~4 ~23 stone_brick_stairs 
setblock ~10 ~3 ~27 stone_brick_stairs 1 
setblock ~10 ~3 ~29 stone_brick_stairs 1  
fill ~10 ~3 ~31 ~11 ~3 ~31 cobblestone  
fill ~10 ~3 ~33 ~12 ~3 ~33 stonebrick 
setblock ~10 ~3 ~34 stone_brick_stairs 7 
setblock ~10 ~3 ~38 stone_brick_stairs 6  
fill ~10 ~3 ~40 ~10 ~4 ~40 cobblestone_wall  
fill ~10 ~3 ~41 ~10 ~3 ~42 stone_slab  
fill ~11 ~3 ~5 ~11 ~4 ~5 cobblestone_wall  
fill ~11 ~3 ~8 ~12 ~3 ~8 planks  
fill ~11 ~3 ~39 ~11 ~4 ~39 cobblestone_wall 
setblock ~11 ~3 ~41 stone_brick_stairs 3  
fill ~11 ~3 ~42 ~11 ~3 ~44 stone_slab 
setblock ~12 ~3 ~6 cobblestone_wall 0  
fill ~12 ~3 ~41 ~12 ~3 ~42 planks  
fill ~12 ~3 ~43 ~12 ~3 ~45 stone_slab 
setblock ~12 ~3 ~46 stone_brick_stairs 0  
fill ~13 ~3 ~8 ~13 ~4 ~8 dark_oak_stairs  
fill ~13 ~3 ~9 ~15 ~3 ~9 planks  
fill ~13 ~3 ~11 ~13 ~8 ~11 stone_brick_stairs 
setblock ~13 ~3 ~25 nether_brick_fence 0  
fill ~13 ~3 ~33 ~13 ~8 ~33 stone_brick_stairs  
fill ~13 ~3 ~43 ~13 ~3 ~44 planks 
setblock ~13 ~3 ~45 stone_brick_stairs 2  
fill ~13 ~3 ~46 ~13 ~4 ~46 stonebrick 
setblock ~13 ~3 ~47 stone_brick_stairs 3  
fill ~13 ~3 ~48 ~14 ~3 ~48 stone_slab  
fill ~14 ~3 ~10 ~16 ~3 ~10 double_stone_slab 
setblock ~14 ~3 ~14 torch 5 
setblock ~14 ~3 ~30 torch 5  
fill ~14 ~3 ~34 ~16 ~3 ~34 double_stone_slab  
fill ~14 ~3 ~44 ~14 ~3 ~46 planks 
setblock ~14 ~3 ~47 stone_slab 5  
fill ~14 ~3 ~49 ~15 ~3 ~49 stone_slab  
fill ~14 ~3 ~50 ~15 ~3 ~50 stone_slab  
fill ~15 ~3 ~8 ~15 ~4 ~8 dark_oak_stairs 
setblock ~15 ~3 ~11 stonebrick 0 
setblock ~15 ~3 ~13 torch 5 
setblock ~15 ~3 ~14 stone_slab 0 
setblock ~15 ~3 ~15 torch 5 
setblock ~15 ~3 ~29 torch 5 
setblock ~15 ~3 ~30 stone_slab 0 
setblock ~15 ~3 ~31 torch 5 
setblock ~15 ~3 ~33 stonebrick 0  
fill ~15 ~3 ~47 ~15 ~3 ~48 planks 
setblock ~15 ~3 ~51 stone_slab 5 
setblock ~16 ~3 ~6 cobblestone_wall 0  
fill ~16 ~3 ~8 ~16 ~5 ~8 planks 
setblock ~16 ~3 ~14 torch 5 
setblock ~16 ~3 ~30 torch 5  
fill ~16 ~3 ~49 ~16 ~3 ~50 planks 
setblock ~16 ~3 ~51 stone_brick_stairs 2  
fill ~17 ~3 ~8 ~17 ~4 ~8 dark_oak_stairs  
fill ~17 ~3 ~9 ~19 ~3 ~9 planks  
fill ~17 ~3 ~11 ~17 ~8 ~11 stone_brick_stairs  
fill ~17 ~3 ~33 ~17 ~8 ~33 stone_brick_stairs  
fill ~17 ~3 ~50 ~17 ~3 ~51 planks  
fill ~17 ~3 ~55 ~17 ~6 ~55 planks  
fill ~17 ~3 ~57 ~17 ~6 ~57 planks  
fill ~17 ~3 ~63 ~17 ~6 ~63 planks  
fill ~18 ~3 ~11 ~20 ~3 ~11 stonebrick  
fill ~18 ~3 ~33 ~20 ~3 ~33 stonebrick  
fill ~18 ~3 ~56 ~18 ~4 ~56 planks  
fill ~18 ~3 ~62 ~18 ~4 ~62 planks  
fill ~19 ~3 ~8 ~19 ~4 ~8 dark_oak_stairs  
fill ~19 ~3 ~55 ~19 ~6 ~55 planks  
fill ~19 ~3 ~63 ~19 ~6 ~63 planks 
setblock ~20 ~3 ~6 cobblestone_wall 0  
fill ~20 ~3 ~8 ~20 ~5 ~8 planks  
fill ~21 ~3 ~8 ~21 ~4 ~8 dark_oak_stairs  
fill ~21 ~3 ~9 ~24 ~3 ~9 planks  
fill ~21 ~3 ~11 ~21 ~8 ~11 stone_brick_stairs  
fill ~21 ~3 ~33 ~21 ~8 ~33 stone_brick_stairs  
fill ~22 ~3 ~10 ~24 ~3 ~10 double_stone_slab 
setblock ~22 ~3 ~14 torch 5 
setblock ~22 ~3 ~30 torch 5  
fill ~22 ~3 ~34 ~24 ~3 ~34 double_stone_slab  
fill ~23 ~3 ~8 ~23 ~4 ~8 dark_oak_stairs 
setblock ~23 ~3 ~11 stonebrick 0 
setblock ~23 ~3 ~13 torch 5 
setblock ~23 ~3 ~14 stone_slab 0 
setblock ~23 ~3 ~15 torch 5 
setblock ~23 ~3 ~29 torch 5 
setblock ~23 ~3 ~30 stone_slab 0 
setblock ~23 ~3 ~31 torch 5 
setblock ~23 ~3 ~33 stonebrick 0  
fill ~23 ~3 ~55 ~23 ~6 ~55 planks  
fill ~23 ~3 ~63 ~23 ~6 ~63 planks 
setblock ~24 ~3 ~6 cobblestone_wall 0  
fill ~24 ~3 ~8 ~24 ~4 ~8 dark_oak_stairs 
setblock ~24 ~3 ~14 torch 5 
setblock ~24 ~3 ~30 torch 5  
fill ~24 ~3 ~56 ~24 ~4 ~56 planks  
fill ~24 ~3 ~62 ~24 ~4 ~62 planks  
fill ~25 ~3 ~2 ~25 ~8 ~2 cobblestone_wall 
setblock ~25 ~3 ~5 cobblestone_wall 6  
fill ~25 ~3 ~8 ~25 ~5 ~8 planks  
fill ~25 ~3 ~11 ~25 ~8 ~11 stone_brick_stairs  
fill ~25 ~3 ~33 ~25 ~8 ~33 stone_brick_stairs  
fill ~25 ~3 ~55 ~25 ~6 ~55 planks  
fill ~25 ~3 ~57 ~25 ~6 ~57 planks  
fill ~25 ~3 ~63 ~25 ~6 ~63 planks 
setblock ~26 ~3 ~4 stone_brick_stairs 6 
setblock ~26 ~3 ~5 cobblestone 0 
setblock ~26 ~3 ~6 stone_brick_stairs 7  
fill ~26 ~3 ~11 ~28 ~3 ~11 stonebrick  
fill ~26 ~3 ~33 ~28 ~3 ~33 stonebrick 
setblock ~27 ~3 ~3 stone_brick_stairs 4 
setblock ~27 ~3 ~7 stone_brick_stairs 4 
setblock ~27 ~3 ~64 cobblestone_wall 0 
setblock ~28 ~3 ~2 cobblestone_wall 6 
setblock ~28 ~3 ~3 cobblestone 0 
setblock ~28 ~3 ~7 cobblestone 0 
setblock ~28 ~3 ~8 cobblestone_wall 6  
fill ~28 ~3 ~63 ~29 ~3 ~63 cobblestone  
fill ~28 ~3 ~64 ~28 ~6 ~64 stonebrick  
fill ~28 ~3 ~65 ~28 ~5 ~65 cobblestone_wall 
setblock ~29 ~3 ~3 stone_brick_stairs 5 
setblock ~29 ~3 ~7 stone_brick_stairs 5  
fill ~29 ~3 ~11 ~29 ~8 ~11 stone_brick_stairs  
fill ~29 ~3 ~33 ~29 ~8 ~33 stone_brick_stairs 
setblock ~29 ~3 ~64 cobblestone_wall 0 
setblock ~30 ~3 ~4 stone_brick_stairs 6 
setblock ~30 ~3 ~5 cobblestone 0 
setblock ~30 ~3 ~6 stone_brick_stairs 7  
fill ~30 ~3 ~10 ~31 ~3 ~10 double_stone_slab 
setblock ~30 ~3 ~14 torch 5 
setblock ~30 ~3 ~30 torch 5  
fill ~30 ~3 ~34 ~32 ~3 ~34 double_stone_slab  
fill ~31 ~3 ~2 ~31 ~8 ~2 cobblestone_wall 
setblock ~31 ~3 ~5 cobblestone_wall 6  
fill ~31 ~3 ~8 ~31 ~7 ~8 cobblestone_wall 
setblock ~31 ~3 ~11 stonebrick 0 
setblock ~31 ~3 ~13 torch 5 
setblock ~31 ~3 ~14 stone_slab 0 
setblock ~31 ~3 ~15 torch 5 
setblock ~31 ~3 ~29 torch 5 
setblock ~31 ~3 ~30 stone_slab 0 
setblock ~31 ~3 ~31 torch 5 
setblock ~31 ~3 ~33 stonebrick 0  
fill ~31 ~3 ~62 ~33 ~3 ~62 planks 
setblock ~32 ~3 ~10 stone_brick_stairs 4 
setblock ~32 ~3 ~14 torch 5 
setblock ~32 ~3 ~30 torch 5 
setblock ~33 ~3 ~9 stone_brick_stairs 6 
setblock ~33 ~3 ~11 stone_brick_stairs 7  
fill ~33 ~3 ~33 ~33 ~8 ~33 stone_brick_stairs  
fill ~34 ~3 ~6 ~38 ~3 ~6 iron_bars 
setblock ~34 ~3 ~10 stone_brick_stairs 5  
fill ~34 ~3 ~33 ~37 ~3 ~33 stonebrick  
fill ~34 ~3 ~63 ~36 ~3 ~63 cobblestone 
setblock ~34 ~3 ~64 cobblestone_wall 0 
setblock ~35 ~3 ~10 stone_brick_stairs 4  
fill ~35 ~3 ~64 ~35 ~6 ~64 stonebrick  
fill ~35 ~3 ~65 ~35 ~5 ~65 cobblestone_wall 
setblock ~36 ~3 ~9 stone_brick_stairs 6 
setblock ~36 ~3 ~11 stone_brick_stairs 7 
setblock ~36 ~3 ~13 stonebrick 0 
setblock ~36 ~3 ~64 cobblestone_wall 0 
setblock ~37 ~3 ~10 stone_brick_stairs 5 
setblock ~37 ~3 ~14 stone_brick_stairs 0 
setblock ~37 ~3 ~15 stone_brick_stairs 4 
setblock ~37 ~3 ~19 stone_brick_stairs 7 
setblock ~37 ~3 ~20 stonebrick 0  
fill ~37 ~3 ~24 ~39 ~3 ~24 stonebrick 
setblock ~37 ~3 ~25 stone_brick_stairs 7  
fill ~37 ~3 ~29 ~37 ~2 ~29 stonebrick  
fill ~37 ~3 ~30 ~37 ~3 ~29 stonebrick 
setblock ~38 ~3 ~10 stone_brick_stairs 4 
setblock ~38 ~3 ~14 stonebrick 0 
setblock ~38 ~3 ~15 stone_brick_stairs 2 
setblock ~38 ~3 ~19 stone_brick_stairs 5 
setblock ~38 ~3 ~20 stone_brick_stairs 3 
setblock ~38 ~3 ~25 stone_brick_stairs 2 
setblock ~38 ~3 ~29 stone_brick_stairs 4 
setblock ~38 ~3 ~30 stone_brick_stairs 3  
fill ~38 ~3 ~62 ~40 ~3 ~62 planks 
setblock ~39 ~3 ~9 stone_brick_stairs 6 
setblock ~39 ~3 ~11 stone_brick_stairs 7  
fill ~39 ~3 ~16 ~39 ~4 ~16 stonebrick 
setblock ~39 ~3 ~17 stone_brick_stairs 4 
setblock ~39 ~3 ~22 stone_brick_stairs 4 
setblock ~39 ~3 ~27 stone_brick_stairs 4  
fill ~39 ~3 ~28 ~39 ~4 ~28 stonebrick  
fill ~40 ~3 ~6 ~44 ~3 ~6 iron_bars 
setblock ~40 ~3 ~10 stone_brick_stairs 5 
setblock ~40 ~3 ~16 stone_brick_stairs 6 
setblock ~40 ~3 ~28 stone_brick_stairs 7 
setblock ~41 ~3 ~10 stone_brick_stairs 4 
setblock ~41 ~3 ~13 stone_brick_stairs 4  
fill ~41 ~3 ~16 ~44 ~3 ~16 stonebrick  
fill ~41 ~3 ~28 ~44 ~3 ~28 stonebrick  
fill ~41 ~3 ~63 ~43 ~3 ~63 cobblestone 
setblock ~41 ~3 ~64 cobblestone_wall 0 
setblock ~42 ~3 ~9 stone_brick_stairs 6 
setblock ~42 ~3 ~11 stone_brick_stairs 7 
setblock ~42 ~3 ~12 stone_brick_stairs 6 
setblock ~42 ~3 ~14 stone_brick_stairs 7 
setblock ~42 ~3 ~15 stonebrick 0 
setblock ~42 ~3 ~29 stone_brick_stairs 5  
fill ~42 ~3 ~30 ~43 ~3 ~30 stonebrick  
fill ~42 ~3 ~64 ~42 ~6 ~64 stonebrick  
fill ~42 ~3 ~65 ~42 ~5 ~65 cobblestone_wall 
setblock ~43 ~3 ~10 stone_brick_stairs 5 
setblock ~43 ~3 ~13 stone_brick_stairs 5 
setblock ~43 ~3 ~15 stone_brick_stairs 8 
setblock ~43 ~3 ~64 cobblestone_wall 0  
fill ~44 ~3 ~35 ~44 ~3 ~38 stained_hardened_clay 
setblock ~45 ~3 ~7 iron_bars 0 
setblock ~45 ~3 ~11 iron_bars 0 
setblock ~45 ~3 ~13 iron_bars 0 
setblock ~45 ~3 ~15 iron_bars 0 
setblock ~45 ~3 ~16 stone_brick_stairs 6 
setblock ~45 ~3 ~28 stone_brick_stairs 7  
fill ~45 ~3 ~30 ~46 ~3 ~30 stonebrick 
setblock ~45 ~3 ~34 stone_brick_stairs 7 
setblock ~45 ~3 ~35 stone_brick_stairs 6 
setblock ~45 ~3 ~36 stone_slab 5 
setblock ~45 ~3 ~37 stone_brick_stairs 7 
setblock ~45 ~3 ~38 stone_brick_stairs 6  
fill ~45 ~3 ~42 ~54 ~3 ~42 stonebrick  
fill ~45 ~3 ~62 ~47 ~3 ~62 planks  
fill ~46 ~3 ~16 ~49 ~3 ~16 stonebrick  
fill ~46 ~3 ~28 ~49 ~3 ~28 stonebrick  
fill ~46 ~3 ~29 ~46 ~3 ~28 stonebrick 
setblock ~46 ~3 ~31 stone_slab 5 
setblock ~46 ~3 ~32 stone_slab 13 
setblock ~46 ~3 ~40 stone_slab 13 
setblock ~46 ~3 ~41 stone_slab 5  
fill ~47 ~3 ~14 ~47 ~2 ~14 stonebrick 
setblock ~47 ~3 ~15 stone_brick_stairs 0 
setblock ~47 ~3 ~30 stone_brick_stairs 5 
setblock ~47 ~3 ~41 stone_slab 13 
setblock ~48 ~3 ~14 stone_brick_stairs 5 
setblock ~48 ~3 ~15 stonebrick 2  
fill ~48 ~3 ~29 ~48 ~3 ~30 stonebrick  
fill ~48 ~3 ~63 ~49 ~3 ~63 cobblestone 
setblock ~48 ~3 ~64 cobblestone_wall 0 
setblock ~49 ~3 ~62 stone_brick_stairs 0 
setblock ~49 ~3 ~64 stone_brick_stairs 0  
fill ~49 ~3 ~65 ~49 ~5 ~65 cobblestone_wall 
setblock ~50 ~3 ~16 stone_brick_stairs 6 
setblock ~50 ~3 ~28 stone_brick_stairs 7  
fill ~50 ~3 ~62 ~50 ~4 ~62 stonebrick  
fill ~50 ~3 ~64 ~50 ~4 ~64 stonebrick  
fill ~51 ~3 ~16 ~51 ~4 ~16 stonebrick 
setblock ~51 ~3 ~17 stone_brick_stairs 5 
setblock ~51 ~3 ~22 stone_brick_stairs 5 
setblock ~51 ~3 ~27 stone_brick_stairs 5  
fill ~51 ~3 ~28 ~51 ~4 ~28 stonebrick  
fill ~52 ~3 ~14 ~52 ~2 ~14 stonebrick  
fill ~52 ~3 ~15 ~52 ~3 ~14 stonebrick  
fill ~52 ~3 ~19 ~53 ~3 ~19 stonebrick 
setblock ~52 ~3 ~20 stone_brick_stairs 4 
setblock ~52 ~3 ~25 stone_brick_stairs 7 
setblock ~52 ~3 ~29 stone_brick_stairs 0 
setblock ~52 ~3 ~30 stonebrick 0 
setblock ~53 ~3 ~14 stone_brick_stairs 2 
setblock ~53 ~3 ~15 stone_brick_stairs 7 
setblock ~53 ~3 ~20 stone_brick_stairs 5 
setblock ~53 ~3 ~24 stone_brick_stairs 0 
setblock ~53 ~3 ~25 stonebrick 0 
setblock ~53 ~3 ~29 stone_brick_stairs 3 
setblock ~53 ~3 ~30 stone_brick_stairs 5 
setblock ~54 ~3 ~40 cobblestone_wall 0 
setblock ~54 ~3 ~43 cobblestone_wall 6  
fill ~54 ~3 ~46 ~54 ~8 ~46 cobblestone_wall 
setblock ~55 ~3 ~42 stone_brick_stairs 6 
setblock ~55 ~3 ~43 cobblestone 0 
setblock ~55 ~3 ~44 stone_brick_stairs 7 
setblock ~56 ~3 ~41 stone_brick_stairs 4 
setblock ~56 ~3 ~45 stone_brick_stairs 4 
setblock ~56 ~3 ~55 stone_brick_stairs 2 
setblock ~56 ~3 ~71 stone_brick_stairs 3 
setblock ~57 ~3 ~40 cobblestone_wall 6 
setblock ~57 ~3 ~41 cobblestone 0 
setblock ~57 ~3 ~45 cobblestone 0  
fill ~57 ~3 ~46 ~57 ~8 ~46 stained_hardened_clay  
fill ~57 ~3 ~47 ~57 ~8 ~47 stained_hardened_clay  
fill ~57 ~3 ~48 ~57 ~5 ~48 stained_hardened_clay  
fill ~57 ~3 ~49 ~57 ~8 ~49 stained_hardened_clay  
fill ~57 ~3 ~50 ~57 ~8 ~50 stained_hardened_clay  
fill ~57 ~3 ~51 ~57 ~8 ~51 stained_hardened_clay  
fill ~57 ~3 ~52 ~57 ~8 ~52 stained_hardened_clay  
fill ~57 ~3 ~53 ~57 ~8 ~53 stained_hardened_clay  
fill ~57 ~3 ~54 ~57 ~5 ~54 stained_hardened_clay  
fill ~57 ~3 ~55 ~57 ~8 ~55 stained_hardened_clay  
fill ~57 ~3 ~56 ~57 ~8 ~56 stained_hardened_clay  
fill ~57 ~3 ~57 ~57 ~8 ~57 stained_hardened_clay 
setblock ~58 ~3 ~41 stone_brick_stairs 5 
setblock ~58 ~3 ~45 stone_brick_stairs 5 
setblock ~58 ~3 ~46 stone_slab 5 
setblock ~58 ~3 ~47 stone_brick_stairs 1 
setblock ~58 ~3 ~48 stone_slab 5 
setblock ~58 ~3 ~49 stone_brick_stairs 1 
setblock ~58 ~3 ~50 stone_slab 5 
setblock ~58 ~3 ~51 stone_brick_stairs 1 
setblock ~58 ~3 ~52 stone_slab 5 
setblock ~58 ~3 ~53 stone_brick_stairs 1 
setblock ~58 ~3 ~54 stone_slab 5 
setblock ~58 ~3 ~55 stone_brick_stairs 1 
setblock ~58 ~3 ~71 stone_brick_stairs 3 
setblock ~59 ~3 ~42 stone_brick_stairs 6 
setblock ~59 ~3 ~43 cobblestone 0 
setblock ~59 ~3 ~44 stone_brick_stairs 7  
fill ~60 ~3 ~40 ~60 ~8 ~40 cobblestone_wall 
setblock ~60 ~3 ~43 cobblestone_wall 6  
fill ~60 ~3 ~46 ~60 ~8 ~46 cobblestone_wall  
fill ~64 ~3 ~62 ~64 ~4 ~62 stonebrick  
fill ~64 ~3 ~64 ~64 ~4 ~64 stonebrick 
setblock ~65 ~3 ~62 stone_brick_stairs 1 
setblock ~65 ~3 ~64 stone_brick_stairs 1 
setblock ~4 ~4 ~6 stone_slab 5 
setblock ~4 ~4 ~7 stone_slab 13 
setblock ~4 ~4 ~9 stone_slab 13 
setblock ~4 ~4 ~10 stone_slab 5  
fill ~4 ~4 ~12 ~5 ~4 ~12 stone_stairs 
setblock ~4 ~4 ~34 stone_slab 5 
setblock ~4 ~4 ~35 stone_slab 13 
setblock ~4 ~4 ~37 stone_slab 13 
setblock ~4 ~4 ~38 stone_slab 5 
setblock ~5 ~4 ~5 stone_slab 5  
fill ~5 ~4 ~7 ~5 ~5 ~7 brick_block 
setblock ~5 ~4 ~8 stone_slab 12  
fill ~5 ~4 ~9 ~5 ~5 ~9 brick_block 
setblock ~5 ~4 ~11 stone_slab 5  
fill ~5 ~4 ~13 ~5 ~4 ~19 stone_stairs 
setblock ~5 ~4 ~20 stone_stairs 7 
setblock ~5 ~4 ~24 stone_stairs 6  
fill ~5 ~4 ~25 ~5 ~4 ~31 stone_stairs  
fill ~5 ~4 ~32 ~6 ~4 ~32 stonebrick 
setblock ~5 ~4 ~33 stone_slab 5  
fill ~5 ~4 ~35 ~5 ~5 ~35 brick_block 
setblock ~5 ~4 ~36 stone_slab 12  
fill ~5 ~4 ~37 ~5 ~5 ~37 brick_block 
setblock ~5 ~4 ~39 stone_slab 5 
setblock ~6 ~4 ~5 stone_slab 13  
fill ~6 ~4 ~6 ~6 ~5 ~6 brick_block  
fill ~6 ~4 ~7 ~8 ~4 ~7 stained_hardened_clay  
fill ~6 ~4 ~9 ~8 ~4 ~9 stained_hardened_clay  
fill ~6 ~4 ~10 ~6 ~5 ~10 brick_block  
fill ~6 ~4 ~12 ~7 ~4 ~12 stone_stairs  
fill ~6 ~4 ~14 ~6 ~4 ~15 stonebrick 
setblock ~6 ~4 ~16 double_stone_slab 5 
setblock ~6 ~4 ~17 stonebrick 0 
setblock ~6 ~4 ~18 stone_stairs 6 
setblock ~6 ~4 ~20 stonebrick 0 
setblock ~6 ~4 ~24 stonebrick 0  
fill ~6 ~4 ~26 ~6 ~4 ~27 stonebrick 
setblock ~6 ~4 ~28 double_stone_slab 5 
setblock ~6 ~4 ~29 stonebrick 0 
setblock ~6 ~4 ~30 stone_stairs 6  
fill ~6 ~4 ~34 ~6 ~5 ~34 brick_block  
fill ~6 ~4 ~35 ~8 ~4 ~35 stained_hardened_clay  
fill ~6 ~4 ~37 ~8 ~4 ~37 stained_hardened_clay  
fill ~6 ~4 ~38 ~6 ~5 ~38 brick_block 
setblock ~6 ~4 ~39 stone_slab 13 
setblock ~7 ~4 ~6 stone_slab 12 
setblock ~7 ~4 ~10 stone_slab 12 
setblock ~7 ~4 ~16 brick_block 0 
setblock ~7 ~4 ~20 brick_block 0 
setblock ~7 ~4 ~21 stone_slab 12 
setblock ~7 ~4 ~23 stone_slab 12 
setblock ~7 ~4 ~24 brick_block 0 
setblock ~7 ~4 ~28 brick_block 0 
setblock ~7 ~4 ~34 stone_slab 12 
setblock ~7 ~4 ~38 stone_slab 12 
setblock ~8 ~4 ~5 stone_slab 13  
fill ~8 ~4 ~6 ~8 ~5 ~6 brick_block  
fill ~8 ~4 ~10 ~8 ~5 ~10 brick_block 
setblock ~8 ~4 ~11 stone_slab 13 
setblock ~8 ~4 ~12 stone_stairs 7 
setblock ~8 ~4 ~20 stained_hardened_clay 7 
setblock ~8 ~4 ~22 stained_hardened_clay 7 
setblock ~8 ~4 ~24 stained_hardened_clay 7 
setblock ~8 ~4 ~33 stone_slab 13  
fill ~8 ~4 ~34 ~8 ~5 ~34 brick_block  
fill ~8 ~4 ~38 ~8 ~5 ~38 brick_block 
setblock ~8 ~4 ~39 stone_slab 13 
setblock ~9 ~4 ~5 stone_slab 5  
fill ~9 ~4 ~7 ~9 ~5 ~7 brick_block 
setblock ~9 ~4 ~8 stone_slab 12  
fill ~9 ~4 ~9 ~9 ~5 ~9 brick_block  
fill ~9 ~4 ~11 ~12 ~4 ~11 stonebrick 
setblock ~9 ~4 ~22 stonebrick 0  
fill ~9 ~4 ~32 ~10 ~4 ~32 stonebrick 
setblock ~9 ~4 ~33 stone_slab 5  
fill ~9 ~4 ~35 ~9 ~5 ~35 brick_block 
setblock ~9 ~4 ~36 stone_slab 12  
fill ~9 ~4 ~37 ~9 ~5 ~37 brick_block 
setblock ~9 ~4 ~39 stone_slab 5 
setblock ~10 ~4 ~6 stone_slab 5 
setblock ~10 ~4 ~7 stone_slab 13 
setblock ~10 ~4 ~9 stone_slab 13 
setblock ~10 ~4 ~10 stone_slab 5  
fill ~10 ~4 ~13 ~10 ~5 ~13 stone_slab 
setblock ~10 ~4 ~14 stone_brick_stairs 5 
setblock ~10 ~4 ~15 stonebrick 0 
setblock ~10 ~4 ~17 stonebrick 0 
setblock ~10 ~4 ~18 stone_brick_stairs 5 
setblock ~10 ~4 ~22 stone_brick_stairs 1 
setblock ~10 ~4 ~26 stone_brick_stairs 5 
setblock ~10 ~4 ~27 stonebrick 0 
setblock ~10 ~4 ~29 stonebrick 0 
setblock ~10 ~4 ~30 stone_brick_stairs 5  
fill ~10 ~4 ~31 ~11 ~4 ~31 cobblestone  
fill ~10 ~4 ~33 ~12 ~4 ~33 stonebrick 
setblock ~10 ~4 ~34 stone_slab 5 
setblock ~10 ~4 ~35 stone_slab 13 
setblock ~10 ~4 ~37 stone_slab 13 
setblock ~10 ~4 ~38 stone_slab 5  
fill ~11 ~4 ~8 ~12 ~4 ~8 planks 
setblock ~11 ~4 ~16 stone_brick_stairs 1 
setblock ~11 ~4 ~19 stone_slab 5 
setblock ~11 ~4 ~20 stone_brick_stairs 2 
setblock ~11 ~4 ~24 stone_brick_stairs 3 
setblock ~11 ~4 ~25 stone_slab 5 
setblock ~11 ~4 ~28 stone_brick_stairs 1 
setblock ~11 ~4 ~41 stone_brick_stairs 7 
setblock ~12 ~4 ~6 stone_button 4  
fill ~12 ~4 ~13 ~12 ~5 ~13 stone_slab 
setblock ~12 ~4 ~14 stone_slab 5 
setblock ~12 ~4 ~19 stonebrick 3 
setblock ~12 ~4 ~20 stone_slab 5 
setblock ~12 ~4 ~24 stone_slab 5 
setblock ~12 ~4 ~25 stonebrick 3 
setblock ~12 ~4 ~26 stone_slab 5  
fill ~12 ~4 ~31 ~12 ~5 ~31 stone_slab 
setblock ~12 ~4 ~41 spruce_stairs 3 
setblock ~12 ~4 ~46 stone_brick_stairs 4 
setblock ~13 ~4 ~7 stone_button 1  
fill ~13 ~4 ~9 ~15 ~4 ~9 planks 
setblock ~13 ~4 ~19 stone_slab 5 
setblock ~13 ~4 ~25 stone_slab 5  
fill ~13 ~4 ~41 ~13 ~9 ~41 planks  
fill ~13 ~4 ~42 ~13 ~4 ~41 planks 
setblock ~13 ~4 ~45 stone_brick_stairs 6 
setblock ~13 ~4 ~47 stone_brick_stairs 7  
fill ~14 ~4 ~10 ~16 ~4 ~10 double_stone_slab  
fill ~14 ~4 ~34 ~16 ~4 ~34 double_stone_slab 
setblock ~14 ~4 ~43 planks 5 
setblock ~14 ~4 ~45 spruce_stairs 2  
fill ~14 ~4 ~46 ~14 ~10 ~46 planks 
setblock ~15 ~4 ~7 stone_button 2  
fill ~15 ~4 ~11 ~15 ~6 ~11 cobblestone_wall  
fill ~15 ~4 ~33 ~15 ~6 ~33 cobblestone_wall  
fill ~15 ~4 ~44 ~15 ~4 ~45 planks 
setblock ~15 ~4 ~47 spruce_stairs 7 
setblock ~16 ~4 ~6 stone_button 4  
fill ~16 ~4 ~47 ~16 ~8 ~47 planks  
fill ~16 ~4 ~48 ~16 ~4 ~47 planks 
setblock ~16 ~4 ~51 stone_brick_stairs 6 
setblock ~16 ~4 ~53 planks 1 
setblock ~17 ~4 ~7 stone_button 1  
fill ~17 ~4 ~9 ~19 ~4 ~9 planks 
setblock ~17 ~4 ~49 planks 5 
setblock ~17 ~4 ~51 spruce_stairs 2  
fill ~17 ~4 ~52 ~17 ~8 ~52 planks  
fill ~18 ~4 ~11 ~20 ~4 ~11 stonebrick  
fill ~18 ~4 ~13 ~18 ~5 ~13 stone_slab  
fill ~18 ~4 ~31 ~18 ~5 ~31 stone_slab  
fill ~18 ~4 ~33 ~20 ~4 ~33 stonebrick  
fill ~18 ~4 ~50 ~18 ~4 ~51 planks 
setblock ~19 ~4 ~7 stone_button 2 
setblock ~20 ~4 ~6 stone_button 4  
fill ~20 ~4 ~13 ~20 ~5 ~13 stone_slab  
fill ~20 ~4 ~31 ~20 ~5 ~31 stone_slab 
setblock ~21 ~4 ~7 stone_button 1  
fill ~21 ~4 ~9 ~24 ~4 ~9 planks  
fill ~22 ~4 ~10 ~24 ~4 ~10 double_stone_slab  
fill ~22 ~4 ~34 ~24 ~4 ~34 double_stone_slab 
setblock ~23 ~4 ~7 stone_button 2  
fill ~23 ~4 ~11 ~23 ~6 ~11 cobblestone_wall  
fill ~23 ~4 ~33 ~23 ~6 ~33 cobblestone_wall 
setblock ~24 ~4 ~6 stone_button 4 
setblock ~25 ~4 ~5 stone_brick_stairs 4 
setblock ~25 ~4 ~7 stone_button 1 
setblock ~26 ~4 ~4 stone_brick_stairs 2  
fill ~26 ~4 ~5 ~26 ~6 ~5 stonebrick 
setblock ~26 ~4 ~6 stone_brick_stairs 3  
fill ~26 ~4 ~11 ~28 ~4 ~11 stonebrick  
fill ~26 ~4 ~13 ~26 ~5 ~13 stone_slab  
fill ~26 ~4 ~31 ~26 ~5 ~31 stone_slab  
fill ~26 ~4 ~33 ~28 ~4 ~33 stonebrick 
setblock ~27 ~4 ~3 stone_brick_stairs 0 
setblock ~27 ~4 ~7 stone_brick_stairs 0 
setblock ~28 ~4 ~2 stone_brick_stairs 6  
fill ~28 ~4 ~3 ~28 ~6 ~3 stonebrick  
fill ~28 ~4 ~7 ~28 ~6 ~7 stonebrick 
setblock ~28 ~4 ~8 stone_brick_stairs 7  
fill ~28 ~4 ~13 ~28 ~5 ~13 stone_slab  
fill ~28 ~4 ~31 ~28 ~5 ~31 stone_slab  
fill ~28 ~4 ~63 ~29 ~4 ~63 cobblestone 
setblock ~29 ~4 ~3 stone_brick_stairs 1 
setblock ~29 ~4 ~7 stone_brick_stairs 1 
setblock ~30 ~4 ~4 stone_brick_stairs 2  
fill ~30 ~4 ~5 ~30 ~6 ~5 stonebrick 
setblock ~30 ~4 ~6 stone_brick_stairs 3  
fill ~30 ~4 ~10 ~31 ~4 ~10 double_stone_slab  
fill ~30 ~4 ~34 ~32 ~4 ~34 double_stone_slab 
setblock ~30 ~4 ~63 stone_stairs 4 
setblock ~31 ~4 ~5 stone_brick_stairs 5  
fill ~31 ~4 ~11 ~31 ~6 ~11 cobblestone_wall  
fill ~31 ~4 ~33 ~31 ~6 ~33 cobblestone_wall  
fill ~31 ~4 ~62 ~33 ~4 ~62 planks 
setblock ~31 ~4 ~63 stone_stairs 5 
setblock ~32 ~4 ~10 stone_brick_stairs 0 
setblock ~32 ~4 ~63 stone_stairs 4 
setblock ~33 ~4 ~9 stone_brick_stairs 2 
setblock ~33 ~4 ~11 stone_brick_stairs 3 
setblock ~33 ~4 ~63 stone_stairs 5 
setblock ~34 ~4 ~10 stone_brick_stairs 1  
fill ~34 ~4 ~13 ~34 ~5 ~13 stone_slab  
fill ~34 ~4 ~31 ~34 ~5 ~31 stone_slab  
fill ~34 ~4 ~33 ~37 ~4 ~33 stonebrick  
fill ~34 ~4 ~63 ~36 ~4 ~63 cobblestone 
setblock ~35 ~4 ~10 stone_brick_stairs 0 
setblock ~36 ~4 ~9 stone_brick_stairs 2 
setblock ~36 ~4 ~11 stone_brick_stairs 3  
fill ~36 ~4 ~13 ~36 ~5 ~13 stone_slab 
setblock ~37 ~4 ~10 stone_brick_stairs 1  
fill ~37 ~4 ~14 ~38 ~4 ~14 cobblestone_wall  
fill ~37 ~4 ~15 ~38 ~4 ~15 cobblestone_wall 
setblock ~37 ~4 ~19 cobblestone_wall 1  
fill ~37 ~4 ~20 ~38 ~4 ~20 cobblestone_wall  
fill ~37 ~4 ~24 ~38 ~4 ~24 cobblestone_wall  
fill ~37 ~4 ~25 ~38 ~4 ~25 cobblestone_wall  
fill ~37 ~4 ~29 ~38 ~4 ~29 cobblestone_wall  
fill ~37 ~4 ~30 ~38 ~4 ~30 cobblestone_wall 
setblock ~37 ~4 ~63 stone_stairs 4 
setblock ~38 ~4 ~10 stone_brick_stairs 0 
setblock ~38 ~4 ~19 cobblestone_wall 0  
fill ~38 ~4 ~62 ~40 ~4 ~62 planks 
setblock ~38 ~4 ~63 stone_stairs 5 
setblock ~39 ~4 ~9 stone_brick_stairs 2 
setblock ~39 ~4 ~11 stone_brick_stairs 3 
setblock ~39 ~4 ~17 stone_slab 5 
setblock ~39 ~4 ~22 stone_slab 5 
setblock ~39 ~4 ~27 stone_slab 5 
setblock ~39 ~4 ~63 stone_stairs 4 
setblock ~40 ~4 ~10 stone_brick_stairs 1 
setblock ~40 ~4 ~16 stone_slab 5  
fill ~40 ~4 ~17 ~40 ~6 ~17 planks  
fill ~40 ~4 ~22 ~40 ~6 ~22 planks  
fill ~40 ~4 ~27 ~40 ~6 ~27 planks 
setblock ~40 ~4 ~28 stone_slab 5 
setblock ~40 ~4 ~63 stone_stairs 5 
setblock ~41 ~4 ~10 stone_brick_stairs 0 
setblock ~41 ~4 ~13 stone_brick_stairs 0  
fill ~41 ~4 ~16 ~44 ~4 ~16 stonebrick  
fill ~41 ~4 ~28 ~44 ~4 ~28 stonebrick  
fill ~41 ~4 ~63 ~43 ~4 ~63 cobblestone 
setblock ~42 ~4 ~9 stone_brick_stairs 2 
setblock ~42 ~4 ~11 stone_brick_stairs 3 
setblock ~42 ~4 ~12 stone_brick_stairs 2 
setblock ~42 ~4 ~14 stone_brick_stairs 3  
fill ~42 ~4 ~15 ~43 ~4 ~15 cobblestone_wall 
setblock ~42 ~4 ~29 cobblestone_wall 1  
fill ~42 ~4 ~30 ~43 ~4 ~30 cobblestone_wall 
setblock ~43 ~4 ~10 stone_brick_stairs 1 
setblock ~43 ~4 ~13 stone_brick_stairs 1 
setblock ~43 ~4 ~29 cobblestone_wall 0 
setblock ~44 ~4 ~63 stone_stairs 4 
setblock ~45 ~4 ~16 stone_slab 5  
fill ~45 ~4 ~17 ~45 ~6 ~17 planks  
fill ~45 ~4 ~27 ~45 ~6 ~27 planks  
fill ~45 ~4 ~30 ~46 ~4 ~30 stonebrick  
fill ~45 ~4 ~34 ~45 ~4 ~42 stonebrick  
fill ~45 ~4 ~62 ~47 ~4 ~62 planks 
setblock ~45 ~4 ~63 stone_stairs 5  
fill ~46 ~4 ~16 ~49 ~4 ~16 stonebrick  
fill ~46 ~4 ~28 ~49 ~4 ~28 stonebrick 
setblock ~46 ~4 ~29 stone_slab 13 
setblock ~46 ~4 ~31 stone_slab 13 
setblock ~46 ~4 ~32 stone_brick_stairs 6 
setblock ~46 ~4 ~34 stone_brick_stairs 7  
fill ~46 ~4 ~35 ~46 ~4 ~37 stone_slab 
setblock ~46 ~4 ~38 stone_brick_stairs 6 
setblock ~46 ~4 ~40 stone_brick_stairs 7 
setblock ~46 ~4 ~41 stone_slab 13  
fill ~46 ~4 ~42 ~54 ~4 ~42 stonebrick 
setblock ~46 ~4 ~63 stone_stairs 4  
fill ~47 ~4 ~14 ~48 ~4 ~14 cobblestone_wall  
fill ~47 ~4 ~15 ~48 ~4 ~15 cobblestone_wall  
fill ~47 ~4 ~29 ~48 ~4 ~29 cobblestone_wall  
fill ~47 ~4 ~30 ~47 ~4 ~29 cobblestone_wall 
setblock ~47 ~4 ~33 stone_brick_stairs 5 
setblock ~47 ~4 ~39 stone_brick_stairs 5 
setblock ~47 ~4 ~41 stone_brick_stairs 4 
setblock ~47 ~4 ~63 stone_stairs 5 
setblock ~48 ~4 ~30 cobblestone_wall 1 
setblock ~48 ~4 ~40 stone_brick_stairs 6  
fill ~48 ~4 ~63 ~49 ~4 ~63 cobblestone 
setblock ~49 ~4 ~41 stone_brick_stairs 5  
fill ~49 ~4 ~64 ~49 ~6 ~64 stonebrick 
setblock ~50 ~4 ~16 stone_slab 5  
fill ~50 ~4 ~17 ~50 ~6 ~17 planks  
fill ~50 ~4 ~22 ~50 ~6 ~22 planks  
fill ~50 ~4 ~27 ~50 ~6 ~27 planks 
setblock ~50 ~4 ~28 stone_slab 5 
setblock ~50 ~4 ~41 stone_brick_stairs 4 
setblock ~50 ~4 ~63 stone_brick_stairs 0 
setblock ~51 ~4 ~17 stone_slab 5 
setblock ~51 ~4 ~22 stone_slab 5 
setblock ~51 ~4 ~27 stone_slab 5 
setblock ~51 ~4 ~40 stone_brick_stairs 6 
setblock ~51 ~4 ~59 stone_brick_stairs 0 
setblock ~51 ~4 ~60 stonebrick 0 
setblock ~51 ~4 ~66 stonebrick 0 
setblock ~51 ~4 ~67 stone_brick_stairs 0  
fill ~52 ~4 ~14 ~53 ~4 ~14 cobblestone_wall  
fill ~52 ~4 ~15 ~52 ~4 ~14 cobblestone_wall 
setblock ~52 ~4 ~19 cobblestone_wall 1  
fill ~52 ~4 ~20 ~53 ~4 ~20 cobblestone_wall  
fill ~52 ~4 ~24 ~53 ~4 ~24 cobblestone_wall  
fill ~52 ~4 ~25 ~52 ~4 ~24 cobblestone_wall  
fill ~52 ~4 ~29 ~53 ~4 ~29 cobblestone_wall  
fill ~52 ~4 ~30 ~53 ~4 ~30 cobblestone_wall 
setblock ~52 ~4 ~41 stone_brick_stairs 5 
setblock ~52 ~4 ~58 stonebrick 0 
setblock ~52 ~4 ~68 stonebrick 0 
setblock ~53 ~4 ~15 cobblestone_wall 1 
setblock ~53 ~4 ~19 cobblestone_wall 0 
setblock ~53 ~4 ~25 cobblestone_wall 1 
setblock ~53 ~4 ~41 stone_brick_stairs 4 
setblock ~53 ~4 ~57 stone_brick_stairs 2 
setblock ~53 ~4 ~69 stone_brick_stairs 3 
setblock ~54 ~4 ~40 stone_brick_stairs 6 
setblock ~54 ~4 ~43 stone_brick_stairs 4 
setblock ~54 ~4 ~57 stonebrick 0 
setblock ~54 ~4 ~69 stonebrick 0 
setblock ~55 ~4 ~41 stone_brick_stairs 5 
setblock ~55 ~4 ~42 stone_brick_stairs 2  
fill ~55 ~4 ~43 ~55 ~6 ~43 stonebrick 
setblock ~55 ~4 ~44 stone_brick_stairs 3 
setblock ~56 ~4 ~41 stone_brick_stairs 0 
setblock ~56 ~4 ~45 stone_brick_stairs 0 
setblock ~57 ~4 ~40 stone_brick_stairs 6  
fill ~57 ~4 ~41 ~57 ~6 ~41 stonebrick  
fill ~57 ~4 ~45 ~57 ~6 ~45 stonebrick 
setblock ~57 ~4 ~70 stone_brick_stairs 3 
setblock ~58 ~4 ~41 stone_brick_stairs 1 
setblock ~58 ~4 ~45 stone_brick_stairs 1 
setblock ~58 ~4 ~47 stone_brick_stairs 5 
setblock ~58 ~4 ~49 stone_brick_stairs 5 
setblock ~58 ~4 ~51 stone_brick_stairs 5 
setblock ~58 ~4 ~53 stone_brick_stairs 5 
setblock ~58 ~4 ~55 stone_brick_stairs 5 
setblock ~59 ~4 ~42 stone_brick_stairs 2  
fill ~59 ~4 ~43 ~59 ~6 ~43 stonebrick 
setblock ~59 ~4 ~44 stone_brick_stairs 3 
setblock ~60 ~4 ~43 stone_brick_stairs 5 
setblock ~60 ~4 ~57 stonebrick 0 
setblock ~60 ~4 ~69 stonebrick 0 
setblock ~61 ~4 ~57 stone_brick_stairs 2 
setblock ~61 ~4 ~69 stone_brick_stairs 3 
setblock ~62 ~4 ~58 stonebrick 0 
setblock ~62 ~4 ~68 stonebrick 0 
setblock ~63 ~4 ~59 stone_brick_stairs 1 
setblock ~63 ~4 ~60 stonebrick 0 
setblock ~63 ~4 ~66 stonebrick 0 
setblock ~63 ~4 ~67 stone_brick_stairs 1 
setblock ~64 ~4 ~63 stone_brick_stairs 1  
fill ~3 ~5 ~4 ~3 ~5 ~11 stone_stairs 
setblock ~3 ~5 ~12 stone_stairs 7 
setblock ~3 ~5 ~32 stone_stairs 6  
fill ~3 ~5 ~33 ~3 ~5 ~39 stone_stairs  
fill ~3 ~5 ~40 ~10 ~5 ~40 stone_stairs  
fill ~4 ~5 ~4 ~10 ~5 ~4 stone_stairs  
fill ~4 ~5 ~6 ~4 ~5 ~11 stonebrick 
setblock ~4 ~5 ~12 stone_stairs 1 
setblock ~4 ~5 ~32 stone_stairs 1  
fill ~4 ~5 ~34 ~4 ~5 ~39 stonebrick  
fill ~5 ~5 ~5 ~10 ~5 ~5 stonebrick 
setblock ~5 ~5 ~8 brick_block 0 
setblock ~5 ~5 ~11 stonebrick 0  

KittysCommands:  
setblock ~5 ~5 ~13 stone_brick_stairs 0 
setblock ~5 ~5 ~19 stone_brick_stairs 0 
setblock ~5 ~5 ~20 stone_slab 3 
setblock ~5 ~5 ~21 stone_stairs 7 
setblock ~5 ~5 ~23 stone_stairs 6 
setblock ~5 ~5 ~24 stone_slab 3 
setblock ~5 ~5 ~25 stone_brick_stairs 0 
setblock ~5 ~5 ~31 stone_brick_stairs 0 
setblock ~5 ~5 ~33 stonebrick 0 
setblock ~5 ~5 ~36 brick_block 0  
fill ~5 ~5 ~39 ~10 ~5 ~39 stonebrick  
fill ~6 ~5 ~7 ~8 ~5 ~7 stained_hardened_clay  
fill ~6 ~5 ~9 ~8 ~5 ~9 stained_hardened_clay 
setblock ~6 ~5 ~12 stone_brick_stairs 2 
setblock ~6 ~5 ~14 stone_brick_stairs 3 
setblock ~6 ~5 ~18 stone_brick_stairs 2 
setblock ~6 ~5 ~20 double_stone_slab 3 
setblock ~6 ~5 ~24 double_stone_slab 3 
setblock ~6 ~5 ~26 stone_brick_stairs 3 
setblock ~6 ~5 ~30 stone_brick_stairs 2 
setblock ~6 ~5 ~32 stone_brick_stairs 3  
fill ~6 ~5 ~35 ~8 ~5 ~35 stained_hardened_clay  
fill ~6 ~5 ~37 ~8 ~5 ~37 stained_hardened_clay 
setblock ~7 ~5 ~6 brick_block 0 
setblock ~7 ~5 ~10 brick_block 0  
fill ~7 ~5 ~12 ~7 ~6 ~12 planks  
fill ~7 ~5 ~13 ~7 ~11 ~13 planks  
fill ~7 ~5 ~14 ~7 ~6 ~14 planks 
setblock ~7 ~5 ~15 spruce_stairs 3 
setblock ~7 ~5 ~16 dropper 0 
setblock ~7 ~5 ~17 spruce_stairs 2  
fill ~7 ~5 ~18 ~7 ~6 ~18 planks  
fill ~7 ~5 ~19 ~7 ~11 ~19 planks  
fill ~7 ~5 ~20 ~7 ~7 ~20 planks 
setblock ~7 ~5 ~21 brick_stairs 7 
setblock ~7 ~5 ~23 brick_stairs 6  
fill ~7 ~5 ~24 ~7 ~7 ~24 planks  
fill ~7 ~5 ~25 ~7 ~11 ~25 planks  
fill ~7 ~5 ~26 ~7 ~6 ~26 planks 
setblock ~7 ~5 ~27 spruce_stairs 3 
setblock ~7 ~5 ~28 dropper 0 
setblock ~7 ~5 ~29 spruce_stairs 2  
fill ~7 ~5 ~30 ~7 ~6 ~30 planks  
fill ~7 ~5 ~31 ~7 ~11 ~31 planks  
fill ~7 ~5 ~32 ~8 ~5 ~32 stone_stairs  
fill ~7 ~5 ~33 ~12 ~5 ~33 stonebrick 
setblock ~7 ~5 ~34 brick_block 0 
setblock ~7 ~5 ~36 stained_hardened_clay 9 
setblock ~7 ~5 ~38 brick_block 0  
fill ~8 ~5 ~11 ~12 ~5 ~11 stonebrick  
fill ~8 ~5 ~12 ~8 ~5 ~31 log2 
setblock ~9 ~5 ~8 brick_block 0 
setblock ~9 ~5 ~12 stone_stairs 7 
setblock ~9 ~5 ~15 stained_hardened_clay 6 
setblock ~9 ~5 ~17 stained_hardened_clay 6 
setblock ~9 ~5 ~27 stained_hardened_clay 6 
setblock ~9 ~5 ~29 stained_hardened_clay 6  
fill ~9 ~5 ~32 ~10 ~5 ~32 stonebrick 
setblock ~9 ~5 ~36 brick_block 0  
fill ~10 ~5 ~6 ~10 ~5 ~11 stonebrick  
fill ~10 ~5 ~14 ~10 ~6 ~14 stonebrick  
fill ~10 ~5 ~15 ~10 ~6 ~15 cobblestone  
fill ~10 ~5 ~16 ~10 ~6 ~16 cobblestone  
fill ~10 ~5 ~17 ~10 ~6 ~17 cobblestone  
fill ~10 ~5 ~18 ~10 ~6 ~18 stonebrick  
fill ~10 ~5 ~21 ~10 ~6 ~21 stonebrick  
fill ~10 ~5 ~22 ~10 ~7 ~22 stonebrick  
fill ~10 ~5 ~23 ~10 ~6 ~23 stonebrick  
fill ~10 ~5 ~26 ~10 ~6 ~26 stonebrick  
fill ~10 ~5 ~27 ~10 ~6 ~27 cobblestone  
fill ~10 ~5 ~28 ~10 ~6 ~28 cobblestone  
fill ~10 ~5 ~29 ~10 ~6 ~29 cobblestone  
fill ~10 ~5 ~30 ~10 ~6 ~30 stonebrick  
fill ~10 ~5 ~31 ~11 ~5 ~31 cobblestone  
fill ~10 ~5 ~34 ~10 ~5 ~39 stonebrick  
fill ~11 ~5 ~4 ~11 ~5 ~6 stone_stairs 
setblock ~11 ~5 ~7 stone_slab 13  
fill ~11 ~5 ~8 ~13 ~5 ~8 planks  
fill ~11 ~5 ~9 ~11 ~5 ~10 stone_stairs 
setblock ~11 ~5 ~15 stone_brick_stairs 3 
setblock ~11 ~5 ~17 stone_brick_stairs 2 
setblock ~11 ~5 ~20 stone_brick_stairs 6 
setblock ~11 ~5 ~21 stone_brick_stairs 7 
setblock ~11 ~5 ~23 stone_brick_stairs 6 
setblock ~11 ~5 ~24 stone_brick_stairs 7 
setblock ~11 ~5 ~27 stone_brick_stairs 3 
setblock ~11 ~5 ~29 stone_brick_stairs 2  
fill ~11 ~5 ~34 ~11 ~5 ~39 stone_stairs  
fill ~11 ~5 ~40 ~11 ~8 ~40 stonebrick 
setblock ~11 ~5 ~41 cobblestone_wall 0 
setblock ~12 ~5 ~6 stone_slab 13  
fill ~12 ~5 ~19 ~12 ~7 ~19 cobblestone_wall  
fill ~12 ~5 ~25 ~12 ~7 ~25 cobblestone_wall 
setblock ~12 ~5 ~41 spruce_stairs 7  
fill ~12 ~5 ~46 ~12 ~7 ~46 cobblestone_wall 
setblock ~13 ~5 ~7 stone_slab 13 
setblock ~13 ~5 ~42 dark_oak_stairs 3 
setblock ~13 ~5 ~45 cobblestone_wall 0  
fill ~13 ~5 ~46 ~13 ~8 ~46 stonebrick 
setblock ~13 ~5 ~47 cobblestone_wall 0 
setblock ~14 ~5 ~8 dark_oak_stairs 6  
fill ~14 ~5 ~10 ~16 ~5 ~10 double_stone_slab  
fill ~14 ~5 ~34 ~16 ~5 ~34 double_stone_slab  
fill ~14 ~5 ~42 ~14 ~8 ~42 planks 
setblock ~14 ~5 ~45 spruce_stairs 6 
setblock ~14 ~5 ~53 stone_brick_stairs 0 
setblock ~14 ~5 ~59 stone_brick_stairs 0 
setblock ~14 ~5 ~65 stone_brick_stairs 0 
setblock ~15 ~5 ~7 stone_slab 13 
setblock ~15 ~5 ~8 planks 5  
fill ~15 ~5 ~43 ~15 ~8 ~43 planks 
setblock ~15 ~5 ~44 dark_oak_stairs 2  
fill ~15 ~5 ~45 ~15 ~8 ~45 planks 
setblock ~15 ~5 ~47 spruce_stairs 3 
setblock ~15 ~5 ~52 stone_brick_stairs 2 
setblock ~15 ~5 ~54 stone_slab 13 
setblock ~15 ~5 ~58 stone_slab 13 
setblock ~15 ~5 ~60 stone_slab 13 
setblock ~15 ~5 ~64 stone_brick_stairs 2 
