fill ~1 ~0 ~3 ~3 ~0 ~3 stained_glass 4  
fill ~1 ~0 ~10 ~2 ~0 ~10 stained_glass 4  
fill ~2 ~0 ~4 ~2 ~1 ~4 stained_glass 4  
fill ~2 ~0 ~5 ~3 ~0 ~5 stained_glass 4  
fill ~2 ~0 ~6 ~3 ~0 ~6 stained_glass 4  
fill ~2 ~0 ~9 ~2 ~4 ~9 stained_glass 4  
fill ~4 ~0 ~8 ~5 ~0 ~8 stained_glass 4  
fill ~4 ~0 ~9 ~6 ~0 ~9 stained_glass 4  
fill ~4 ~0 ~12 ~6 ~0 ~12 stained_glass 4  
fill ~4 ~0 ~15 ~4 ~2 ~15 stained_glass 4  
fill ~5 ~0 ~2 ~6 ~0 ~2 stained_glass 4  
fill ~5 ~0 ~5 ~6 ~0 ~5 stained_glass 4  
fill ~5 ~0 ~6 ~5 ~0 ~9 stained_glass 4  
fill ~6 ~0 ~1 ~7 ~0 ~1 stained_glass 4 
setblock ~6 ~0 ~7 stained_glass 4  
fill ~6 ~0 ~10 ~7 ~0 ~10 stained_glass 4  
fill ~6 ~0 ~13 ~6 ~2 ~13 stained_glass 4  
fill ~7 ~0 ~8 ~7 ~5 ~8 stained_glass 4  
fill ~7 ~0 ~11 ~8 ~0 ~11 stained_glass 4  
fill ~8 ~0 ~0 ~9 ~0 ~0 stained_glass 4  
fill ~10 ~0 ~2 ~11 ~0 ~2 stained_glass 4  
fill ~14 ~0 ~6 ~14 ~1 ~6 stained_glass 4  
fill ~-1 ~1 ~7 ~-1 ~3 ~7 stained_glass 4  
fill ~0 ~1 ~3 ~2 ~1 ~3 stained_glass 4  
fill ~0 ~1 ~4 ~2 ~1 ~4 stained_glass 4  
fill ~0 ~1 ~5 ~1 ~1 ~5 stained_glass 4  
fill ~1 ~1 ~6 ~3 ~1 ~6 stained_glass 4  
fill ~2 ~1 ~7 ~3 ~1 ~7 stained_glass 4  
fill ~2 ~1 ~8 ~7 ~1 ~8 stained_glass 4  
fill ~3 ~1 ~2 ~7 ~1 ~2 stained_glass 4  
fill ~3 ~1 ~9 ~5 ~1 ~9 stained_glass 4  
fill ~3 ~1 ~10 ~4 ~1 ~10 stained_glass 4  
fill ~3 ~1 ~13 ~7 ~1 ~13 stained_glass 4  
fill ~3 ~1 ~15 ~3 ~3 ~15 stained_glass 4  
fill ~3 ~1 ~17 ~5 ~1 ~17 stained_glass 4  
fill ~3 ~1 ~18 ~3 ~1 ~17 stained_glass 4  
fill ~4 ~1 ~1 ~7 ~1 ~1 stained_glass 4  
fill ~4 ~1 ~5 ~4 ~2 ~5 stained_glass 4  
fill ~4 ~1 ~11 ~4 ~1 ~17 stained_glass 4  
fill ~5 ~1 ~12 ~7 ~1 ~12 stained_glass 4  
fill ~5 ~1 ~14 ~6 ~1 ~14 stained_glass 4  
fill ~5 ~1 ~16 ~5 ~2 ~16 stained_glass 4  
fill ~5 ~1 ~18 ~5 ~3 ~18 stained_glass 4  
fill ~6 ~1 ~0 ~6 ~5 ~0 stained_glass 4 
setblock ~6 ~1 ~4 stained_glass 4  
fill ~7 ~1 ~5 ~9 ~1 ~5 stained_glass 4  
fill ~7 ~1 ~6 ~7 ~1 ~5 stained_glass 4  
fill ~7 ~1 ~10 ~10 ~1 ~10 stained_glass 4  
fill ~8 ~1 ~0 ~9 ~1 ~0 stained_glass 4  
fill ~8 ~1 ~3 ~8 ~1 ~5 stained_glass 4  
fill ~8 ~1 ~7 ~8 ~5 ~7 stained_glass 4  
fill ~8 ~1 ~11 ~10 ~1 ~11 stained_glass 4  
fill ~9 ~1 ~2 ~10 ~1 ~2 stained_glass 4  
fill ~9 ~1 ~6 ~9 ~5 ~6 stained_glass 4  
fill ~9 ~1 ~9 ~10 ~1 ~9 stained_glass 4  
fill ~9 ~1 ~12 ~10 ~1 ~12 stained_glass 4  
fill ~9 ~1 ~13 ~10 ~1 ~13 stained_glass 4  
fill ~9 ~1 ~14 ~10 ~1 ~14 stained_glass 4  
fill ~10 ~1 ~15 ~10 ~2 ~15 stained_glass 4  
fill ~11 ~1 ~4 ~11 ~3 ~4 stained_glass 4 
setblock ~13 ~1 ~11 stained_glass 4  
fill ~13 ~1 ~14 ~13 ~3 ~14 stained_glass 4 
setblock ~14 ~1 ~2 stained_glass 4  
fill ~14 ~1 ~5 ~15 ~1 ~5 stained_glass 4  
fill ~-1 ~2 ~5 ~-1 ~2 ~8 stained_glass 4  
fill ~-1 ~2 ~11 ~0 ~2 ~11 stained_glass 4  
fill ~0 ~2 ~3 ~1 ~2 ~3 stained_glass 4  
fill ~0 ~2 ~4 ~0 ~1 ~4 stained_glass 4  
fill ~0 ~2 ~9 ~0 ~14 ~9 stained_glass 4  
fill ~0 ~2 ~10 ~4 ~2 ~10 stained_glass 4  
fill ~1 ~2 ~2 ~2 ~2 ~2 stained_glass 4  
fill ~1 ~2 ~6 ~2 ~2 ~6 stained_glass 4  
fill ~1 ~2 ~7 ~6 ~2 ~7 stained_glass 4  
fill ~1 ~2 ~12 ~3 ~2 ~12 stained_glass 4  
fill ~1 ~2 ~13 ~4 ~2 ~13 stained_glass 4  
fill ~1 ~2 ~14 ~4 ~2 ~14 stained_glass 4  
fill ~2 ~2 ~1 ~2 ~3 ~1 stained_glass 4  
fill ~2 ~2 ~8 ~2 ~3 ~8 stained_glass 4  
fill ~2 ~2 ~11 ~3 ~2 ~11 stained_glass 4  
fill ~2 ~2 ~15 ~2 ~3 ~15 stained_glass 4  
fill ~2 ~2 ~16 ~6 ~2 ~16 stained_glass 4  
fill ~3 ~2 ~9 ~3 ~3 ~9 stained_glass 4  
fill ~3 ~2 ~17 ~6 ~2 ~17 stained_glass 4 
setblock ~3 ~2 ~18 stained_glass 1  
fill ~3 ~2 ~19 ~6 ~2 ~19 stained_glass 4  
fill ~4 ~2 ~0 ~8 ~2 ~0 stained_glass 4  
fill ~4 ~2 ~6 ~5 ~2 ~6 stained_glass 4  
fill ~4 ~2 ~8 ~8 ~2 ~8 stained_glass 4 
setblock ~4 ~2 ~18 stained_glass 4  
fill ~5 ~2 ~-1 ~5 ~4 ~-1 stained_glass 4  
fill ~5 ~2 ~5 ~5 ~4 ~5 stained_glass 4  
fill ~5 ~2 ~9 ~7 ~2 ~9 stained_glass 4  
fill ~5 ~2 ~15 ~6 ~2 ~15 stained_glass 4  
fill ~6 ~2 ~10 ~6 ~5 ~10 stained_glass 4  
fill ~6 ~2 ~11 ~6 ~3 ~11 stained_glass 4  
fill ~6 ~2 ~12 ~7 ~2 ~12 stained_glass 4 
setblock ~6 ~2 ~14 stained_glass 4 
setblock ~6 ~2 ~18 stained_glass 4  
fill ~6 ~2 ~20 ~7 ~2 ~20 stained_glass 4  
fill ~7 ~2 ~2 ~10 ~2 ~2 stained_glass 4  
fill ~7 ~2 ~13 ~8 ~2 ~13 stained_glass 4 
setblock ~7 ~2 ~18 stained_hardened_clay 4  
fill ~8 ~2 ~5 ~8 ~3 ~5 stained_glass 4  
fill ~8 ~2 ~6 ~8 ~3 ~6 stained_glass 4  
fill ~8 ~2 ~14 ~15 ~2 ~14 stained_glass 4  
fill ~8 ~2 ~15 ~12 ~2 ~15 stained_glass 4  
fill ~8 ~2 ~16 ~13 ~2 ~16 stained_glass 4  
fill ~8 ~2 ~17 ~9 ~2 ~17 stained_glass 4  
fill ~8 ~2 ~18 ~9 ~2 ~18 stained_glass 4  
fill ~9 ~2 ~1 ~10 ~2 ~1 stained_glass 4  
fill ~9 ~2 ~9 ~17 ~2 ~9 stained_glass 4  
fill ~10 ~2 ~-1 ~11 ~2 ~-1 stained_glass 4  
fill ~10 ~2 ~0 ~11 ~2 ~0 stained_glass 4  
fill ~10 ~2 ~4 ~10 ~5 ~4 stained_glass 4  
fill ~10 ~2 ~8 ~15 ~2 ~8 stained_glass 4  
fill ~10 ~2 ~10 ~12 ~2 ~10 stained_glass 4  
fill ~10 ~2 ~11 ~12 ~2 ~11 stained_glass 4  
fill ~10 ~2 ~12 ~12 ~2 ~12 stained_glass 4  
fill ~11 ~2 ~17 ~11 ~3 ~17 stained_glass 4  
fill ~11 ~2 ~18 ~11 ~3 ~18 stained_glass 4  
fill ~12 ~2 ~3 ~13 ~2 ~3 stained_glass 4  
fill ~12 ~2 ~4 ~13 ~2 ~4 stained_glass 4  
fill ~12 ~2 ~7 ~13 ~2 ~7 stained_glass 4  
fill ~12 ~2 ~13 ~14 ~2 ~13 stained_glass 4  
fill ~13 ~2 ~5 ~14 ~2 ~5 stained_glass 4  
fill ~13 ~2 ~17 ~13 ~2 ~18 stained_glass 4  
fill ~14 ~2 ~10 ~15 ~2 ~10 stained_glass 4  
fill ~15 ~2 ~6 ~15 ~3 ~6 stained_glass 4  
fill ~17 ~2 ~8 ~17 ~4 ~8 stained_glass 4  
fill ~17 ~2 ~13 ~18 ~2 ~13 stained_glass 4  
fill ~18 ~2 ~14 ~19 ~2 ~14 stained_glass 4  
fill ~19 ~2 ~15 ~19 ~4 ~15 stained_glass 4  
fill ~-2 ~3 ~11 ~3 ~3 ~11 stained_glass 4  
fill ~-2 ~3 ~12 ~5 ~3 ~12 stained_glass 4  
fill ~-1 ~3 ~9 ~-1 ~10 ~9 stained_glass 4  
fill ~-1 ~3 ~10 ~6 ~3 ~10 stained_glass 4  
fill ~0 ~3 ~3 ~1 ~3 ~3 stained_glass 4  
fill ~0 ~3 ~5 ~1 ~3 ~5 stained_glass 4  
fill ~0 ~3 ~7 ~6 ~3 ~7 stained_glass 4  
fill ~0 ~3 ~8 ~18 ~3 ~8 stained_glass 4  
fill ~0 ~3 ~13 ~4 ~3 ~13 stained_glass 4  
fill ~0 ~3 ~14 ~2 ~3 ~14 stained_glass 4  
fill ~0 ~3 ~15 ~3 ~3 ~15 stained_glass 4 
setblock ~1 ~3 ~4 stained_glass 4  
fill ~1 ~3 ~9 ~1 ~4 ~9 stained_glass 4  
fill ~1 ~3 ~16 ~2 ~3 ~16 stained_glass 4  
fill ~1 ~3 ~17 ~2 ~3 ~17 stained_glass 4  
fill ~1 ~3 ~18 ~2 ~3 ~18 stained_glass 4  
fill ~2 ~3 ~2 ~2 ~6 ~2 stained_glass 4  
fill ~2 ~3 ~6 ~5 ~3 ~6 stained_glass 4  
fill ~2 ~3 ~19 ~8 ~3 ~19 stained_glass 4  
fill ~2 ~3 ~20 ~12 ~3 ~20 stained_glass 4  
fill ~2 ~3 ~21 ~12 ~3 ~21 stained_glass 4  
fill ~3 ~3 ~0 ~4 ~3 ~0 stained_glass 4  
fill ~3 ~3 ~5 ~3 ~4 ~5 stained_glass 4 
setblock ~3 ~3 ~14 stained_hardened_clay 4  
fill ~3 ~3 ~22 ~7 ~3 ~22 stained_glass 4  
fill ~3 ~3 ~23 ~7 ~3 ~23 stained_glass 4  
fill ~3 ~3 ~24 ~4 ~3 ~24 stained_glass 4  
fill ~4 ~3 ~1 ~4 ~5 ~1 stained_glass 4  
fill ~4 ~3 ~9 ~7 ~3 ~9 stained_glass 4 
setblock ~4 ~3 ~17 stained_hardened_clay 4  
fill ~6 ~3 ~-1 ~8 ~3 ~-1 stained_glass 4  
fill ~6 ~3 ~5 ~14 ~3 ~5 stained_glass 4  
fill ~6 ~3 ~15 ~7 ~3 ~15 stained_glass 4  
fill ~6 ~3 ~17 ~12 ~3 ~17 stained_glass 4 
setblock ~6 ~3 ~18 stained_glass 1  
fill ~7 ~3 ~-2 ~8 ~3 ~-2 stained_glass 4  
fill ~7 ~3 ~0 ~8 ~3 ~0 stained_glass 4  
fill ~7 ~3 ~2 ~7 ~5 ~2 stained_glass 4  
fill ~7 ~3 ~3 ~7 ~3 ~5 stained_glass 4  
fill ~7 ~3 ~24 ~8 ~3 ~24 stained_glass 4  
fill ~8 ~3 ~4 ~8 ~4 ~4 stained_glass 4 
setblock ~8 ~3 ~16 stained_glass 1  
fill ~9 ~3 ~1 ~9 ~14 ~1 stained_glass 4  
fill ~9 ~3 ~9 ~10 ~3 ~9 stained_glass 4  
fill ~9 ~3 ~10 ~21 ~3 ~10 stained_glass 4 
setblock ~9 ~3 ~14 stained_glass 1 
setblock ~9 ~3 ~19 stained_hardened_clay 4  
fill ~10 ~3 ~2 ~11 ~3 ~2 stained_glass 4  
fill ~10 ~3 ~3 ~11 ~3 ~3 stained_glass 4  
fill ~10 ~3 ~6 ~15 ~3 ~6 stained_glass 4  
fill ~10 ~3 ~11 ~12 ~3 ~11 stained_glass 4 
setblock ~10 ~3 ~15 stained_hardened_clay 4  
fill ~10 ~3 ~19 ~12 ~3 ~19 stained_glass 4  
fill ~11 ~3 ~7 ~14 ~3 ~7 stained_glass 4  
fill ~11 ~3 ~22 ~11 ~4 ~22 stained_glass 4  
fill ~12 ~3 ~4 ~12 ~4 ~4 stained_glass 4 
setblock ~12 ~3 ~9 stained_glass 4  
fill ~12 ~3 ~12 ~18 ~3 ~12 stained_glass 4  
fill ~12 ~3 ~18 ~14 ~3 ~18 stained_glass 4  
fill ~13 ~3 ~13 ~18 ~3 ~13 stained_glass 4  
fill ~13 ~3 ~15 ~16 ~3 ~15 stained_glass 4  
fill ~13 ~3 ~16 ~15 ~3 ~16 stained_glass 4  
fill ~14 ~3 ~4 ~14 ~5 ~4 stained_glass 4  
fill ~14 ~3 ~9 ~17 ~3 ~9 stained_glass 4  
fill ~14 ~3 ~11 ~19 ~3 ~11 stained_glass 4  
fill ~14 ~3 ~14 ~16 ~3 ~14 stained_glass 4  
fill ~14 ~3 ~17 ~16 ~3 ~17 stained_glass 4  
fill ~15 ~3 ~23 ~15 ~6 ~23 stained_glass 4  
fill ~16 ~3 ~18 ~16 ~6 ~18 stained_glass 4  
fill ~17 ~3 ~7 ~17 ~5 ~7 stained_glass 4  
fill ~18 ~3 ~14 ~19 ~3 ~14 stained_glass 4  
fill ~18 ~3 ~17 ~18 ~5 ~17 stained_glass 4  
fill ~20 ~3 ~9 ~21 ~3 ~9 stained_glass 4  
fill ~21 ~3 ~11 ~21 ~5 ~11 stained_glass 4  
fill ~-2 ~4 ~11 ~-2 ~10 ~11 stained_glass 4  
fill ~-2 ~4 ~12 ~-1 ~4 ~12 stained_glass 4  
fill ~-2 ~4 ~13 ~0 ~4 ~13 stained_glass 4  
fill ~-1 ~4 ~6 ~0 ~4 ~6 stained_glass 4  
fill ~-1 ~4 ~10 ~1 ~4 ~10 stained_glass 4  
fill ~-1 ~4 ~14 ~-1 ~6 ~14 stained_glass 4  
fill ~-1 ~4 ~15 ~0 ~4 ~15 stained_glass 4  
fill ~0 ~4 ~5 ~1 ~4 ~5 stained_glass 4  
fill ~0 ~4 ~7 ~0 ~9 ~7 stained_glass 4  
fill ~0 ~4 ~8 ~1 ~4 ~8 stained_glass 4  
fill ~0 ~4 ~16 ~1 ~4 ~16 stained_glass 4  
fill ~0 ~4 ~19 ~1 ~4 ~19 stained_glass 4  
fill ~1 ~4 ~2 ~1 ~4 ~3 stained_glass 4 
setblock ~1 ~4 ~12 stained_hardened_clay 4  
fill ~1 ~4 ~17 ~1 ~3 ~17 stained_glass 4  
fill ~1 ~4 ~18 ~1 ~3 ~18 stained_glass 4  
fill ~1 ~4 ~20 ~2 ~4 ~20 stained_glass 4  
fill ~1 ~4 ~22 ~2 ~4 ~22 stained_glass 4  
fill ~1 ~4 ~23 ~1 ~10 ~23 stained_glass 4  
fill ~2 ~4 ~0 ~6 ~4 ~0 stained_glass 4  
fill ~2 ~4 ~3 ~2 ~7 ~3 stained_glass 4  
fill ~2 ~4 ~6 ~7 ~4 ~6 stained_glass 4 
setblock ~2 ~4 ~7 stained_hardened_clay 4 
setblock ~2 ~4 ~16 stained_hardened_clay 4  
fill ~2 ~4 ~21 ~4 ~4 ~21 stained_glass 4  
fill ~3 ~4 ~1 ~3 ~5 ~1 stained_glass 4  
fill ~3 ~4 ~4 ~6 ~4 ~4 stained_glass 4  
fill ~3 ~4 ~11 ~4 ~4 ~11 stained_glass 4  
fill ~3 ~4 ~12 ~3 ~4 ~11 stained_glass 4 
setblock ~3 ~4 ~19 stained_glass 4 
setblock ~3 ~4 ~22 stained_hardened_clay 4  
fill ~3 ~4 ~23 ~3 ~3 ~23 stained_glass 4  
fill ~4 ~4 ~2 ~5 ~4 ~2 stained_glass 4  
fill ~4 ~4 ~3 ~6 ~4 ~3 stained_glass 4  
fill ~4 ~4 ~5 ~4 ~5 ~5 stained_glass 4 
setblock ~4 ~4 ~10 stained_hardened_clay 4 
setblock ~4 ~4 ~20 stained_glass 1  
fill ~4 ~4 ~24 ~9 ~4 ~24 stained_glass 4  
fill ~4 ~4 ~25 ~4 ~6 ~25 stained_glass 4  
fill ~5 ~4 ~1 ~5 ~6 ~1 stained_glass 4 
setblock ~5 ~4 ~7 stained_glass 1 
setblock ~5 ~4 ~22 stained_glass 4 
setblock ~5 ~4 ~23 stained_glass 1  
fill ~6 ~4 ~5 ~7 ~4 ~5 stained_glass 4  
fill ~6 ~4 ~7 ~8 ~4 ~7 stained_glass 4  
fill ~6 ~4 ~8 ~6 ~4 ~10 stained_glass 4 
setblock ~6 ~4 ~15 stained_hardened_clay 4 
setblock ~6 ~4 ~20 stained_hardened_clay 4  
fill ~6 ~4 ~25 ~8 ~4 ~25 stained_glass 4  
fill ~7 ~4 ~-1 ~8 ~4 ~-1 stained_glass 4  
fill ~7 ~4 ~9 ~7 ~5 ~9 stained_glass 4 
setblock ~7 ~4 ~17 stained_hardened_clay 4  
fill ~8 ~4 ~0 ~9 ~4 ~0 stained_glass 4  
fill ~8 ~4 ~1 ~8 ~16 ~1 stained_glass 4  
fill ~8 ~4 ~2 ~12 ~4 ~2 stained_glass 4  
fill ~8 ~4 ~8 ~9 ~4 ~8 stained_glass 4  
fill ~8 ~4 ~22 ~12 ~4 ~22 stained_glass 4  
fill ~8 ~4 ~23 ~8 ~5 ~23 stained_glass 4 
setblock ~9 ~4 ~5 stained_glass 4  
fill ~9 ~4 ~9 ~9 ~1 ~9 stained_glass 4  
fill ~9 ~4 ~10 ~9 ~3 ~10 stained_glass 4  
fill ~10 ~4 ~6 ~10 ~3 ~6 stained_glass 4 
setblock ~10 ~4 ~11 stained_glass 1 
setblock ~10 ~4 ~19 stained_hardened_clay 4 
setblock ~10 ~4 ~20 stained_glass 4  
fill ~11 ~4 ~1 ~11 ~6 ~1 stained_glass 4  
fill ~11 ~4 ~3 ~12 ~4 ~3 stained_glass 4 
setblock ~11 ~4 ~10 stained_glass 1 
setblock ~11 ~4 ~11 stained_hardened_clay 4 
setblock ~11 ~4 ~18 stained_hardened_clay 4  
fill ~11 ~4 ~21 ~12 ~4 ~21 stained_glass 4  
fill ~11 ~4 ~23 ~13 ~4 ~23 stained_glass 4  
fill ~12 ~4 ~5 ~14 ~4 ~5 stained_glass 4  
fill ~12 ~4 ~6 ~14 ~4 ~6 stained_glass 4  
fill ~12 ~4 ~18 ~13 ~4 ~18 stained_glass 4  
fill ~12 ~4 ~19 ~16 ~4 ~19 stained_glass 4  
fill ~12 ~4 ~20 ~13 ~4 ~20 stained_glass 4  
fill ~13 ~4 ~4 ~13 ~5 ~4 stained_glass 4  
fill ~13 ~4 ~7 ~17 ~4 ~7 stained_glass 4  
fill ~13 ~4 ~8 ~15 ~4 ~8 stained_glass 4  
fill ~13 ~4 ~9 ~13 ~4 ~4 stained_glass 4  
fill ~13 ~4 ~12 ~14 ~4 ~12 stained_hardened_clay 4  
fill ~13 ~4 ~15 ~19 ~4 ~15 stained_glass 4  
fill ~13 ~4 ~16 ~18 ~4 ~16 stained_glass 4  
fill ~14 ~4 ~14 ~15 ~4 ~14 stained_glass 4  
fill ~14 ~4 ~17 ~18 ~4 ~17 stained_glass 4 
setblock ~14 ~4 ~18 glowstone 0 
setblock ~15 ~4 ~10 stained_glass 1  
fill ~15 ~4 ~11 ~16 ~4 ~11 stained_glass 4  
fill ~15 ~4 ~12 ~15 ~4 ~19 stained_glass 4 
setblock ~17 ~4 ~12 stained_glass 4  
fill ~17 ~4 ~13 ~18 ~4 ~13 stained_hardened_clay 4  
fill ~17 ~4 ~14 ~22 ~4 ~14 stained_glass 4 
setblock ~17 ~4 ~18 stained_glass 4  
fill ~17 ~4 ~23 ~17 ~6 ~23 stained_glass 4  
fill ~18 ~4 ~8 ~18 ~5 ~8 stained_glass 4  
fill ~18 ~4 ~9 ~21 ~4 ~9 stained_glass 4  
fill ~18 ~4 ~10 ~21 ~4 ~10 stained_glass 4  
fill ~18 ~4 ~11 ~22 ~4 ~11 stained_glass 4  
fill ~19 ~4 ~12 ~23 ~4 ~12 stained_glass 4  
fill ~19 ~4 ~13 ~23 ~4 ~13 stained_glass 4 
setblock ~21 ~4 ~15 stained_glass 4  
fill ~-3 ~5 ~11 ~-3 ~7 ~11 stained_glass 4  
fill ~-2 ~5 ~9 ~-2 ~5 ~14 stained_glass 4  
fill ~-1 ~5 ~6 ~1 ~5 ~6 stained_glass 4  
fill ~-1 ~5 ~10 ~0 ~5 ~10 stained_glass 4  
fill ~-1 ~5 ~15 ~-1 ~7 ~15 stained_glass 4  
fill ~-1 ~5 ~16 ~0 ~5 ~16 stained_glass 4  
fill ~0 ~5 ~4 ~4 ~5 ~4 stained_glass 4  
fill ~0 ~5 ~5 ~1 ~5 ~5 stained_glass 4  
fill ~0 ~5 ~8 ~1 ~5 ~8 stained_glass 4 
setblock ~0 ~5 ~11 stained_hardened_clay 4 
setblock ~0 ~5 ~15 stained_hardened_clay 4  
fill ~0 ~5 ~17 ~0 ~7 ~17 stained_glass 4  
fill ~0 ~5 ~18 ~0 ~6 ~18 stained_glass 4  
fill ~0 ~5 ~19 ~1 ~5 ~19 stained_glass 4  
fill ~0 ~5 ~20 ~2 ~5 ~20 stained_glass 4 
setblock ~1 ~5 ~3 stained_glass 4 
setblock ~1 ~5 ~7 stained_glass 4 
setblock ~1 ~5 ~17 glowstone 0  
fill ~1 ~5 ~24 ~4 ~5 ~24 stained_glass 4  
fill ~1 ~5 ~25 ~1 ~5 ~23 stained_glass 4 
setblock ~2 ~5 ~1 stained_glass 4  
fill ~2 ~5 ~21 ~3 ~5 ~21 stained_glass 4  
fill ~2 ~5 ~22 ~2 ~6 ~22 stained_glass 4 
setblock ~3 ~5 ~0 stained_glass 4 
setblock ~3 ~5 ~19 stained_glass 1  
fill ~3 ~5 ~25 ~3 ~10 ~25 stained_glass 4  
fill ~3 ~5 ~26 ~3 ~11 ~26 stained_glass 4  
fill ~4 ~5 ~2 ~8 ~5 ~2 stained_glass 4  
fill ~4 ~5 ~3 ~9 ~5 ~3 stained_glass 4  
fill ~5 ~5 ~0 ~5 ~6 ~0 stained_glass 4 
setblock ~5 ~5 ~24 stained_hardened_clay 4  
fill ~5 ~5 ~25 ~10 ~5 ~25 stained_glass 4  
fill ~5 ~5 ~26 ~9 ~5 ~26 stained_glass 4 
setblock ~6 ~5 ~-1 stained_glass 4  
fill ~6 ~5 ~1 ~6 ~11 ~1 stained_glass 4 
setblock ~6 ~5 ~5 glowstone 0  
fill ~6 ~5 ~7 ~7 ~5 ~7 stained_glass 1 
setblock ~6 ~5 ~9 stained_glass 1 
setblock ~6 ~5 ~24 stained_glass 4  
fill ~6 ~5 ~27 ~8 ~5 ~27 stained_glass 4  
fill ~7 ~5 ~0 ~7 ~7 ~0 stained_glass 4 
setblock ~7 ~5 ~6 stained_glass 4  
fill ~7 ~5 ~10 ~8 ~5 ~10 stained_glass 4 
setblock ~7 ~5 ~23 stained_hardened_clay 4  
fill ~8 ~5 ~8 ~9 ~5 ~8 stained_glass 4  
fill ~8 ~5 ~9 ~9 ~5 ~9 stained_hardened_clay 4  
fill ~8 ~5 ~22 ~8 ~4 ~22 stained_glass 4  
fill ~8 ~5 ~24 ~13 ~5 ~24 stained_glass 4  
fill ~9 ~5 ~0 ~9 ~7 ~0 stained_glass 4  
fill ~9 ~5 ~23 ~13 ~5 ~23 stained_glass 4  
fill ~10 ~5 ~1 ~10 ~10 ~1 stained_glass 4 
setblock ~10 ~5 ~6 stained_hardened_clay 4  
fill ~11 ~5 ~3 ~11 ~3 ~3 stained_glass 4  
fill ~12 ~5 ~0 ~12 ~16 ~0 stained_glass 4  
fill ~12 ~5 ~1 ~12 ~5 ~2 stained_glass 4 
setblock ~12 ~5 ~6 stained_hardened_clay 4  
fill ~12 ~5 ~21 ~15 ~5 ~21 stained_glass 4  
fill ~12 ~5 ~22 ~14 ~5 ~22 stained_glass 4  
fill ~12 ~5 ~25 ~12 ~7 ~25 stained_glass 4  
fill ~13 ~5 ~2 ~14 ~5 ~2 stained_glass 4  
fill ~13 ~5 ~3 ~14 ~5 ~3 stained_glass 4  
fill ~13 ~5 ~5 ~15 ~5 ~5 stained_glass 4 
setblock ~13 ~5 ~9 stained_hardened_clay 4 
setblock ~13 ~5 ~20 stained_hardened_clay 4  
fill ~14 ~5 ~1 ~15 ~5 ~1 stained_glass 4  
fill ~14 ~5 ~6 ~15 ~5 ~6 stained_glass 4  
fill ~14 ~5 ~8 ~16 ~5 ~8 stained_glass 4  
fill ~14 ~5 ~14 ~15 ~5 ~14 stained_glass 1  
fill ~14 ~5 ~19 ~17 ~5 ~19 stained_glass 4  
fill ~14 ~5 ~20 ~17 ~5 ~20 stained_glass 4 
setblock ~15 ~5 ~4 stained_glass 4  
fill ~15 ~5 ~7 ~19 ~5 ~7 stained_glass 4 
setblock ~15 ~5 ~16 stained_hardened_clay 4 
setblock ~15 ~5 ~17 stained_glass 1 
setblock ~15 ~5 ~25 stained_glass 4  
fill ~16 ~5 ~16 ~16 ~5 ~20 stained_glass 4  
fill ~16 ~5 ~23 ~16 ~7 ~23 stained_glass 4 
setblock ~17 ~5 ~17 stained_glass 4  
fill ~17 ~5 ~21 ~17 ~6 ~21 stained_glass 4  
fill ~17 ~5 ~22 ~17 ~6 ~22 stained_glass 4  
fill ~17 ~5 ~24 ~18 ~5 ~24 stained_glass 4  
fill ~17 ~5 ~25 ~17 ~7 ~25 stained_glass 4  
fill ~18 ~5 ~5 ~18 ~5 ~9 stained_glass 4 
setblock ~18 ~5 ~11 stained_glass 1  
fill ~18 ~5 ~16 ~22 ~5 ~16 stained_glass 4  
fill ~18 ~5 ~23 ~18 ~7 ~23 stained_glass 4  
fill ~19 ~5 ~8 ~21 ~5 ~8 stained_glass 4  
fill ~19 ~5 ~9 ~21 ~5 ~9 stained_glass 4 
setblock ~19 ~5 ~11 glowstone 0  
fill ~19 ~5 ~14 ~21 ~5 ~14 stained_glass 4  
fill ~19 ~5 ~17 ~20 ~5 ~17 stained_glass 4  
fill ~19 ~5 ~21 ~22 ~5 ~21 stained_glass 4  
fill ~19 ~5 ~22 ~19 ~7 ~22 stained_glass 4  
fill ~20 ~5 ~10 ~23 ~5 ~10 stained_glass 4  
fill ~20 ~5 ~11 ~20 ~5 ~8 stained_glass 4 
setblock ~20 ~5 ~12 stained_hardened_clay 4 
setblock ~20 ~5 ~15 stained_glass 4  
fill ~21 ~5 ~7 ~21 ~6 ~7 stained_glass 4  
fill ~21 ~5 ~20 ~24 ~5 ~20 stained_glass 4  
fill ~22 ~5 ~11 ~25 ~5 ~11 stained_glass 4  
fill ~22 ~5 ~12 ~22 ~5 ~10 stained_glass 4  
fill ~22 ~5 ~15 ~25 ~5 ~15 stained_glass 4  
fill ~22 ~5 ~17 ~22 ~6 ~17 stained_glass 4  
fill ~23 ~5 ~13 ~26 ~5 ~13 stained_glass 4  
fill ~24 ~5 ~12 ~25 ~5 ~12 stained_glass 4  
fill ~24 ~5 ~14 ~24 ~7 ~14 stained_glass 4  
fill ~25 ~5 ~10 ~25 ~6 ~10 stained_glass 4  
fill ~25 ~5 ~16 ~25 ~7 ~16 stained_glass 4  
fill ~-3 ~6 ~12 ~-2 ~6 ~12 stained_glass 4  
fill ~-3 ~6 ~13 ~-2 ~6 ~13 stained_glass 4  
fill ~-2 ~6 ~10 ~0 ~6 ~10 stained_glass 4  
fill ~-2 ~6 ~14 ~-2 ~12 ~14 stained_glass 4  
fill ~-2 ~6 ~15 ~-2 ~11 ~15 stained_glass 4  
fill ~0 ~6 ~8 ~1 ~6 ~8 stained_glass 4  
fill ~0 ~6 ~16 ~0 ~7 ~16 stained_glass 4  
fill ~0 ~6 ~19 ~0 ~7 ~19 stained_glass 4  
fill ~0 ~6 ~20 ~0 ~8 ~20 stained_glass 4  
fill ~0 ~6 ~21 ~2 ~6 ~21 stained_glass 4  
fill ~0 ~6 ~22 ~2 ~6 ~22 stained_glass 4  
fill ~0 ~6 ~23 ~0 ~14 ~23 stained_glass 4 
setblock ~1 ~6 ~2 stained_glass 4  
fill ~1 ~6 ~5 ~1 ~8 ~5 stained_glass 4  
fill ~1 ~6 ~6 ~1 ~6 ~5 stained_glass 4 
setblock ~1 ~6 ~17 stained_hardened_clay 4  
fill ~1 ~6 ~24 ~3 ~6 ~24 stained_glass 4  
fill ~2 ~6 ~4 ~2 ~11 ~4 stained_glass 4  
fill ~2 ~6 ~25 ~2 ~7 ~25 stained_glass 4  
fill ~2 ~6 ~26 ~2 ~6 ~24 stained_glass 4  
fill ~3 ~6 ~2 ~6 ~6 ~2 stained_glass 4  
fill ~3 ~6 ~3 ~4 ~6 ~3 stained_glass 4 
setblock ~4 ~6 ~0 stained_glass 4 
setblock ~4 ~6 ~4 stained_hardened_clay 4  
fill ~4 ~6 ~23 ~4 ~6 ~24 stained_glass 1  
fill ~4 ~6 ~26 ~6 ~6 ~26 stained_glass 4  
fill ~5 ~6 ~25 ~6 ~6 ~25 stained_glass 4  
fill ~6 ~6 ~3 ~8 ~6 ~3 stained_glass 4  
fill ~7 ~6 ~1 ~7 ~7 ~1 stained_glass 4 
setblock ~7 ~6 ~4 stained_glass 1  
fill ~7 ~6 ~27 ~7 ~7 ~27 stained_glass 4  
fill ~8 ~6 ~0 ~8 ~10 ~0 stained_glass 4 
setblock ~8 ~6 ~2 stained_glass 4 
setblock ~8 ~6 ~7 stained_hardened_clay 4  
fill ~8 ~6 ~24 ~8 ~7 ~24 stained_glass 1  
fill ~8 ~6 ~25 ~8 ~6 ~26 stained_glass 4  
fill ~8 ~6 ~28 ~10 ~6 ~28 stained_glass 4  
fill ~9 ~6 ~26 ~12 ~6 ~26 stained_glass 4  
fill ~9 ~6 ~27 ~10 ~6 ~27 stained_glass 4  
fill ~10 ~6 ~0 ~12 ~6 ~0 stained_glass 4 
setblock ~10 ~6 ~4 stained_hardened_clay 4  
fill ~10 ~6 ~25 ~14 ~6 ~25 stained_glass 4 
setblock ~11 ~6 ~-1 stained_glass 4  
fill ~11 ~6 ~23 ~19 ~6 ~23 stained_glass 4  
fill ~11 ~6 ~24 ~14 ~6 ~24 stained_glass 4 
setblock ~12 ~6 ~1 stained_hardened_clay 4  
fill ~13 ~6 ~-1 ~14 ~6 ~-1 stained_glass 4  
fill ~13 ~6 ~2 ~13 ~5 ~2 stained_glass 4 
setblock ~13 ~6 ~6 glowstone 0 
setblock ~13 ~6 ~22 stained_glass 1  
fill ~14 ~6 ~1 ~14 ~5 ~1 stained_glass 4  
fill ~14 ~6 ~3 ~15 ~6 ~3 stained_glass 4  
fill ~14 ~6 ~6 ~21 ~6 ~6 stained_glass 4  
fill ~14 ~6 ~7 ~15 ~6 ~7 stained_glass 4  
fill ~14 ~6 ~8 ~15 ~6 ~8 stained_glass 4  
fill ~14 ~6 ~9 ~14 ~6 ~6 stained_glass 4  
fill ~14 ~6 ~26 ~15 ~6 ~26 stained_glass 4  
fill ~15 ~6 ~0 ~15 ~8 ~0 stained_glass 4 
setblock ~15 ~6 ~2 stained_glass 4  
fill ~15 ~6 ~5 ~16 ~6 ~5 stained_glass 4 
setblock ~15 ~6 ~18 stained_glass 4  
fill ~15 ~6 ~21 ~15 ~6 ~23 stained_glass 4 
setblock ~16 ~6 ~4 stained_glass 4  
fill ~16 ~6 ~19 ~17 ~6 ~19 stained_glass 4  
fill ~16 ~6 ~20 ~25 ~6 ~20 stained_glass 4 
setblock ~16 ~6 ~22 stained_glass 4  
fill ~16 ~6 ~25 ~16 ~7 ~25 stained_glass 4 
setblock ~17 ~6 ~16 stained_glass 1  
fill ~17 ~6 ~18 ~19 ~6 ~18 stained_glass 4  
fill ~17 ~6 ~24 ~18 ~6 ~24 stained_glass 4  
fill ~17 ~6 ~27 ~17 ~8 ~27 stained_glass 4 
setblock ~18 ~6 ~8 stained_glass 1 
setblock ~18 ~6 ~15 stained_glass 1  
fill ~18 ~6 ~16 ~18 ~4 ~16 stained_glass 4 
setblock ~18 ~6 ~19 stained_hardened_clay 4  
fill ~18 ~6 ~22 ~18 ~7 ~22 stained_glass 4  
fill ~18 ~6 ~25 ~19 ~6 ~25 stained_glass 4  
fill ~19 ~6 ~7 ~22 ~6 ~7 stained_glass 4  
fill ~19 ~6 ~8 ~19 ~5 ~8 stained_glass 4  
fill ~19 ~6 ~9 ~20 ~6 ~9 stained_hardened_clay 4  
fill ~19 ~6 ~17 ~19 ~5 ~17 stained_glass 4  
fill ~19 ~6 ~19 ~27 ~6 ~19 stained_glass 4  
fill ~19 ~6 ~21 ~22 ~6 ~21 stained_glass 4  
fill ~19 ~6 ~26 ~20 ~6 ~26 stained_glass 4 
setblock ~20 ~6 ~11 stained_glass 1 
setblock ~20 ~6 ~18 stained_hardened_clay 4  
fill ~20 ~6 ~22 ~22 ~6 ~22 stained_glass 4 
setblock ~20 ~6 ~27 stained_glass 4  
fill ~21 ~6 ~5 ~21 ~7 ~5 stained_glass 4  
fill ~21 ~6 ~8 ~22 ~6 ~8 stained_glass 4  
fill ~21 ~6 ~9 ~25 ~6 ~9 stained_glass 4 
setblock ~21 ~6 ~15 stained_hardened_clay 4 
setblock ~21 ~6 ~17 stained_hardened_clay 4  
fill ~21 ~6 ~18 ~25 ~6 ~18 stained_glass 4  
fill ~21 ~6 ~23 ~21 ~7 ~23 stained_glass 4  
fill ~21 ~6 ~24 ~21 ~7 ~24 stained_glass 4  
fill ~21 ~6 ~25 ~22 ~6 ~25 stained_glass 4 
setblock ~22 ~6 ~14 stained_hardened_clay 4  
fill ~22 ~6 ~15 ~26 ~6 ~15 stained_glass 4  
fill ~23 ~6 ~10 ~26 ~6 ~10 stained_glass 4 
setblock ~23 ~6 ~12 stained_hardened_clay 4  
fill ~23 ~6 ~13 ~26 ~6 ~13 stained_glass 4  
fill ~23 ~6 ~14 ~23 ~6 ~13 stained_glass 4  
fill ~23 ~6 ~16 ~26 ~6 ~16 stained_glass 4  
fill ~23 ~6 ~17 ~24 ~6 ~17 stained_glass 4  
fill ~24 ~6 ~21 ~27 ~6 ~21 stained_glass 4  
fill ~25 ~6 ~12 ~25 ~10 ~12 stained_glass 4  
fill ~25 ~6 ~14 ~26 ~6 ~14 stained_glass 4  
fill ~26 ~6 ~11 ~26 ~7 ~11 stained_glass 4  
fill ~27 ~6 ~22 ~27 ~10 ~22 stained_glass 4  
fill ~27 ~6 ~23 ~27 ~11 ~23 stained_glass 4 
setblock ~28 ~6 ~17 stained_glass 4  
fill ~-3 ~7 ~9 ~0 ~7 ~9 stained_glass 4  
fill ~-3 ~7 ~12 ~-3 ~7 ~12 stained_glass 4  
fill ~-3 ~7 ~13 ~-3 ~8 ~13 stained_glass 4  
fill ~-3 ~7 ~14 ~-3 ~8 ~14 stained_glass 4  
fill ~-2 ~7 ~10 ~-2 ~9 ~10 stained_glass 4  
fill ~-2 ~7 ~16 ~0 ~7 ~16 stained_glass 4  
fill ~-1 ~7 ~8 ~0 ~7 ~8 stained_glass 4  
fill ~-1 ~7 ~17 ~-1 ~12 ~17 stained_glass 4  
fill ~-1 ~7 ~18 ~-1 ~8 ~18 stained_glass 4  
fill ~-1 ~7 ~21 ~0 ~7 ~21 stained_glass 4  
fill ~-1 ~7 ~22 ~-1 ~9 ~22 stained_glass 4  
fill ~0 ~7 ~3 ~4 ~7 ~3 stained_glass 4  
fill ~0 ~7 ~4 ~0 ~7 ~10 stained_glass 4 
setblock ~0 ~7 ~15 stained_hardened_clay 4  
fill ~1 ~7 ~24 ~2 ~7 ~24 stained_glass 4  
fill ~2 ~7 ~1 ~3 ~7 ~1 stained_glass 4  
fill ~2 ~7 ~5 ~2 ~12 ~5 stained_glass 4  
fill ~2 ~7 ~6 ~2 ~11 ~6 stained_glass 4 
setblock ~3 ~7 ~0 stained_glass 4  
fill ~3 ~7 ~2 ~3 ~9 ~2 stained_glass 4  
fill ~3 ~7 ~4 ~3 ~8 ~4 stained_glass 4  
fill ~4 ~7 ~26 ~5 ~7 ~26 stained_glass 4  
fill ~4 ~7 ~27 ~4 ~10 ~27 stained_glass 4  
fill ~5 ~7 ~2 ~6 ~7 ~2 stained_glass 4  
fill ~5 ~7 ~28 ~8 ~7 ~28 stained_glass 4  
fill ~6 ~7 ~-1 ~6 ~7 ~2 stained_glass 4 
setblock ~6 ~7 ~27 stained_glass 4  
fill ~8 ~7 ~-1 ~9 ~7 ~-1 stained_glass 4  
fill ~8 ~7 ~29 ~10 ~7 ~29 stained_glass 4  
fill ~10 ~7 ~0 ~12 ~7 ~0 stained_glass 4 
setblock ~10 ~7 ~25 stained_hardened_clay 4 
setblock ~10 ~7 ~26 stained_glass 1  
fill ~10 ~7 ~27 ~17 ~7 ~27 stained_glass 4  
fill ~10 ~7 ~28 ~13 ~7 ~28 stained_glass 4  
fill ~10 ~7 ~30 ~10 ~9 ~30 stained_glass 4  
fill ~11 ~7 ~25 ~11 ~7 ~28 stained_glass 4  
fill ~12 ~7 ~26 ~18 ~7 ~26 stained_glass 4  
fill ~13 ~7 ~-2 ~14 ~7 ~-2 stained_glass 4  
fill ~13 ~7 ~-1 ~15 ~7 ~-1 stained_glass 4  
fill ~13 ~7 ~25 ~14 ~7 ~25 stained_glass 4  
fill ~13 ~7 ~29 ~13 ~8 ~29 stained_glass 4 
setblock ~14 ~7 ~1 stained_hardened_clay 4  
fill ~14 ~7 ~22 ~14 ~7 ~27 stained_glass 4  
fill ~15 ~7 ~1 ~17 ~7 ~1 stained_glass 4  
fill ~15 ~7 ~5 ~22 ~7 ~5 stained_glass 4  
fill ~15 ~7 ~6 ~17 ~7 ~6 stained_glass 4 
setblock ~15 ~7 ~8 stained_glass 1  
fill ~16 ~7 ~2 ~17 ~7 ~2 stained_glass 4  
fill ~16 ~7 ~3 ~21 ~7 ~3 stained_glass 4  
fill ~16 ~7 ~7 ~17 ~7 ~7 stained_glass 4  
fill ~16 ~7 ~24 ~23 ~7 ~24 stained_glass 4 
setblock ~16 ~7 ~28 stained_glass 4  
fill ~17 ~7 ~4 ~22 ~7 ~4 stained_glass 4 
setblock ~17 ~7 ~22 stained_hardened_clay 4 
setblock ~17 ~7 ~23 glowstone 0  
fill ~18 ~7 ~28 ~19 ~7 ~28 stained_glass 4  
fill ~19 ~7 ~19 ~19 ~6 ~19 stained_glass 4  
fill ~19 ~7 ~21 ~20 ~7 ~21 stained_glass 4 
setblock ~19 ~7 ~23 stained_glass 4  
fill ~19 ~7 ~25 ~23 ~7 ~25 stained_glass 4  
fill ~19 ~7 ~29 ~20 ~7 ~29 stained_glass 4  
fill ~20 ~7 ~6 ~25 ~7 ~6 stained_glass 4 
setblock ~20 ~7 ~20 stained_hardened_clay 4  
fill ~20 ~7 ~22 ~27 ~7 ~22 stained_glass 4  
fill ~20 ~7 ~26 ~20 ~8 ~26 stained_glass 4 
setblock ~21 ~7 ~2 stained_glass 4  
fill ~21 ~7 ~18 ~21 ~6 ~18 stained_glass 4  
fill ~21 ~7 ~19 ~21 ~7 ~18 stained_glass 4  
fill ~22 ~7 ~2 ~22 ~8 ~2 stained_glass 1  
fill ~22 ~7 ~7 ~24 ~7 ~7 stained_glass 4 
setblock ~22 ~7 ~17 stained_hardened_clay 4  
fill ~22 ~7 ~20 ~22 ~7 ~25 stained_glass 4  
fill ~23 ~7 ~8 ~26 ~7 ~8 stained_glass 4 
setblock ~23 ~7 ~9 stained_glass 1  
fill ~23 ~7 ~21 ~24 ~7 ~21 stained_glass 4  
fill ~23 ~7 ~23 ~27 ~7 ~23 stained_glass 4 
setblock ~24 ~7 ~9 stained_glass 4  
fill ~24 ~7 ~16 ~24 ~7 ~18 stained_glass 4 
setblock ~24 ~7 ~19 stained_hardened_clay 4 
setblock ~24 ~7 ~20 stained_glass 4  
fill ~25 ~7 ~11 ~25 ~11 ~11 stained_glass 4  
fill ~25 ~7 ~14 ~26 ~7 ~14 stained_glass 4  
fill ~25 ~7 ~17 ~26 ~7 ~17 stained_glass 4  
fill ~25 ~7 ~18 ~26 ~7 ~18 stained_glass 4  
fill ~25 ~7 ~19 ~27 ~7 ~19 stained_glass 4  
fill ~26 ~7 ~9 ~26 ~9 ~9 stained_glass 4  
fill ~26 ~7 ~10 ~26 ~9 ~10 stained_glass 4  
fill ~26 ~7 ~12 ~26 ~7 ~19 stained_glass 4  
fill ~26 ~7 ~21 ~27 ~7 ~21 stained_glass 4  
fill ~27 ~7 ~11 ~27 ~9 ~11 stained_glass 4 
setblock ~29 ~7 ~17 stained_glass 4  
fill ~-3 ~8 ~12 ~-2 ~8 ~12 stained_glass 4  
fill ~-2 ~8 ~16 ~-1 ~8 ~16 stained_glass 4 
setblock ~-1 ~8 ~12 stained_hardened_clay 4  
fill ~-1 ~8 ~19 ~-1 ~8 ~23 stained_glass 4  
fill ~0 ~8 ~8 ~1 ~8 ~8 stained_glass 4  
fill ~0 ~8 ~21 ~0 ~10 ~21 stained_glass 4  
fill ~0 ~8 ~24 ~2 ~8 ~24 stained_glass 4 
setblock ~1 ~8 ~4 stained_glass 4  
fill ~1 ~8 ~6 ~1 ~8 ~8 stained_glass 4 
setblock ~1 ~8 ~9 stained_hardened_clay 4  
fill ~1 ~8 ~25 ~1 ~9 ~25 stained_glass 4  
fill ~2 ~8 ~2 ~2 ~9 ~2 stained_glass 4 
setblock ~2 ~8 ~7 stained_hardened_clay 4 
setblock ~3 ~8 ~1 stained_glass 4  
fill ~3 ~8 ~3 ~4 ~8 ~3 stained_glass 4  
fill ~3 ~8 ~5 ~3 ~21 ~5 stained_glass 4  
fill ~4 ~8 ~2 ~7 ~8 ~2 stained_glass 4  
fill ~4 ~8 ~4 ~4 ~16 ~4 stained_glass 4 
setblock ~4 ~8 ~5 stained_glass 1 
setblock ~4 ~8 ~26 stained_hardened_clay 4 
setblock ~5 ~8 ~1 stained_glass 4  
fill ~6 ~8 ~0 ~6 ~10 ~0 stained_glass 4  
fill ~6 ~8 ~28 ~6 ~9 ~28 stained_glass 4  
fill ~6 ~8 ~29 ~14 ~8 ~29 stained_glass 4  
fill ~6 ~8 ~30 ~7 ~8 ~30 stained_glass 4  
fill ~9 ~8 ~30 ~9 ~11 ~30 stained_glass 4  
fill ~10 ~8 ~0 ~16 ~8 ~0 stained_glass 4  
fill ~11 ~8 ~17 ~21 ~8 ~17 stone 0  
fill ~11 ~8 ~18 ~21 ~8 ~18 stone 0  
fill ~11 ~8 ~19 ~21 ~8 ~19 stone 0  
fill ~11 ~8 ~20 ~21 ~8 ~20 stone 0  
fill ~11 ~8 ~21 ~21 ~8 ~21 stone 0  
fill ~11 ~8 ~30 ~11 ~9 ~30 stained_glass 4  
fill ~11 ~8 ~31 ~12 ~8 ~31 stained_glass 4  
fill ~12 ~8 ~15 ~20 ~8 ~15 stone 0  
fill ~12 ~8 ~16 ~20 ~8 ~16 stone 0  
fill ~12 ~8 ~22 ~20 ~8 ~22 stone 0  
fill ~12 ~8 ~23 ~20 ~8 ~23 stone 0  
fill ~12 ~8 ~28 ~13 ~8 ~28 stained_glass 4  
fill ~13 ~8 ~-2 ~13 ~13 ~-2 stained_glass 4  
fill ~13 ~8 ~-1 ~13 ~16 ~-1 stained_glass 4  
fill ~13 ~8 ~30 ~13 ~9 ~30 stained_glass 4  
fill ~14 ~8 ~14 ~18 ~8 ~14 stone 0  
fill ~14 ~8 ~24 ~18 ~8 ~24 stone 0 
setblock ~14 ~8 ~26 stained_hardened_clay 4 
setblock ~14 ~8 ~27 stained_glass 4  
fill ~14 ~8 ~28 ~14 ~9 ~28 stained_glass 1  
fill ~15 ~8 ~-1 ~16 ~8 ~-1 stained_glass 4  
fill ~15 ~8 ~1 ~17 ~8 ~1 stained_glass 4 
setblock ~15 ~8 ~5 stained_hardened_clay 4 
setblock ~15 ~8 ~28 stained_glass 4  
fill ~16 ~8 ~2 ~16 ~7 ~2 stained_glass 4  
fill ~16 ~8 ~5 ~17 ~8 ~5 stained_glass 4  
fill ~16 ~8 ~7 ~16 ~7 ~7 stained_glass 4 
setblock ~16 ~8 ~27 stained_glass 4  
fill ~16 ~8 ~28 ~16 ~9 ~28 stained_glass 1  
fill ~17 ~8 ~4 ~18 ~8 ~4 stained_glass 4 
setblock ~17 ~8 ~6 stained_glass 4 
setblock ~17 ~8 ~26 stained_glass 4  
fill ~17 ~8 ~29 ~17 ~9 ~29 stained_glass 1  
fill ~17 ~8 ~30 ~18 ~8 ~30 stained_glass 1  
fill ~18 ~8 ~0 ~18 ~8 ~1 stained_glass 1 
setblock ~18 ~8 ~2 stained_glass 4  
fill ~18 ~8 ~27 ~24 ~8 ~27 stained_glass 4  
fill ~18 ~8 ~28 ~18 ~7 ~28 stained_glass 4  
fill ~19 ~8 ~1 ~19 ~9 ~1 stained_glass 1  
fill ~19 ~8 ~4 ~20 ~8 ~4 stained_glass 1 
setblock ~19 ~8 ~26 stained_glass 4  
fill ~19 ~8 ~29 ~19 ~9 ~29 stained_glass 1  
fill ~20 ~8 ~2 ~20 ~11 ~2 stained_glass 4  
fill ~21 ~8 ~3 ~21 ~11 ~3 stained_glass 4  
fill ~21 ~8 ~4 ~24 ~8 ~4 stained_glass 4 
setblock ~21 ~8 ~5 stained_hardened_clay 4 
setblock ~21 ~8 ~24 stained_hardened_clay 4  
fill ~21 ~8 ~25 ~22 ~8 ~25 stained_glass 4  
fill ~21 ~8 ~26 ~23 ~8 ~26 stained_glass 4 
setblock ~22 ~8 ~3 stained_glass 1 
setblock ~23 ~8 ~13 stained_glass 1  
fill ~24 ~8 ~6 ~26 ~8 ~6 stained_glass 4 
setblock ~24 ~8 ~9 stained_glass 1 
setblock ~24 ~8 ~13 stained_glass 4 
setblock ~24 ~8 ~22 stained_hardened_clay 4 
setblock ~25 ~8 ~5 stained_glass 4  
fill ~25 ~8 ~7 ~25 ~8 ~9 stained_glass 4 
setblock ~25 ~8 ~17 stained_hardened_clay 4  
fill ~25 ~8 ~23 ~27 ~8 ~23 stained_glass 4  
fill ~25 ~8 ~26 ~25 ~9 ~26 stained_glass 4 
setblock ~26 ~8 ~8 stained_glass 4  
fill ~26 ~8 ~13 ~27 ~8 ~13 stained_glass 4  
fill ~26 ~8 ~14 ~27 ~8 ~14 stained_glass 4  
fill ~26 ~8 ~16 ~26 ~8 ~19 stained_glass 4  
fill ~26 ~8 ~24 ~27 ~8 ~24 stained_glass 4  
fill ~27 ~8 ~12 ~27 ~11 ~12 stained_glass 4  
fill ~27 ~8 ~15 ~27 ~11 ~15 stained_glass 4  
fill ~27 ~8 ~17 ~28 ~8 ~17 stained_glass 4  
fill ~27 ~8 ~19 ~27 ~10 ~19 stained_glass 4  
fill ~27 ~8 ~20 ~27 ~10 ~20 stained_glass 4  
fill ~27 ~8 ~21 ~27 ~10 ~21 stained_glass 4  
fill ~-3 ~9 ~12 ~-2 ~9 ~12 stained_glass 4 
setblock ~-3 ~9 ~13 stained_hardened_clay 4  
fill ~-2 ~9 ~17 ~-2 ~9 ~19 stained_glass 4  
fill ~-1 ~9 ~10 ~-1 ~9 ~11 stained_glass 4  
fill ~-1 ~9 ~16 ~0 ~9 ~16 stained_glass 4  
fill ~-1 ~9 ~20 ~-1 ~9 ~22 stained_glass 4  
fill ~0 ~9 ~8 ~2 ~9 ~8 stained_glass 4 
setblock ~0 ~9 ~11 stained_glass 1  
fill ~0 ~9 ~22 ~0 ~10 ~22 stained_glass 4  
fill ~0 ~9 ~24 ~2 ~9 ~24 stained_glass 4  
fill ~1 ~9 ~3 ~2 ~9 ~3 stained_glass 4  
fill ~1 ~9 ~7 ~2 ~9 ~7 stained_glass 4 
setblock ~1 ~9 ~16 stained_hardened_clay 4 
setblock ~1 ~9 ~19 stained_glass 1  
fill ~2 ~9 ~25 ~2 ~13 ~25 stained_glass 4  
fill ~3 ~9 ~6 ~3 ~20 ~6 stained_glass 4 
setblock ~3 ~9 ~7 stained_hardened_clay 4  
fill ~3 ~9 ~27 ~3 ~14 ~27 stained_glass 4  
fill ~3 ~9 ~28 ~6 ~9 ~28 stained_glass 4  
fill ~4 ~9 ~2 ~4 ~15 ~2 stained_glass 4  
fill ~4 ~9 ~3 ~7 ~9 ~3 stained_glass 4  
fill ~4 ~9 ~5 ~4 ~10 ~5 stained_glass 4 
setblock ~5 ~9 ~0 stained_glass 4  
fill ~5 ~9 ~29 ~5 ~10 ~29 stained_glass 4  
fill ~5 ~9 ~30 ~16 ~9 ~30 stained_glass 4 
setblock ~6 ~9 ~27 glowstone 0  
fill ~6 ~9 ~31 ~6 ~10 ~31 stained_glass 4  
fill ~7 ~9 ~1 ~7 ~9 ~4 stained_glass 4 
setblock ~7 ~9 ~27 stained_hardened_clay 4 
setblock ~7 ~9 ~28 stained_glass 1  
fill ~7 ~9 ~29 ~9 ~9 ~29 stained_glass 4   
fill ~8 ~9 ~2 ~10 ~9 ~2 stained_glass 4  
fill ~8 ~9 ~4 ~8 ~9 ~5 stained_hardened_clay 4 
setblock ~8 ~9 ~28 stained_hardened_clay 4  
fill ~8 ~9 ~31 ~8 ~13 ~31 stained_glass 4  
fill ~9 ~9 ~17 ~10 ~9 ~17 stone 0  
fill ~9 ~9 ~18 ~10 ~9 ~18 stone 0  
fill ~9 ~9 ~19 ~10 ~9 ~19 stone 0  
fill ~9 ~9 ~20 ~10 ~9 ~20 stone 0  
fill ~9 ~9 ~21 ~10 ~9 ~21 stone 0  
fill ~10 ~9 ~14 ~13 ~9 ~14 stone 0  
fill ~10 ~9 ~15 ~11 ~9 ~15 stone 0  
fill ~10 ~9 ~16 ~11 ~9 ~16 stone 0  
fill ~10 ~9 ~22 ~11 ~9 ~22 stone 0  
fill ~10 ~9 ~23 ~11 ~9 ~23 stone 0  
fill ~10 ~9 ~24 ~13 ~9 ~24 stone 0  
fill ~11 ~9 ~0 ~11 ~10 ~0 stained_glass 4  
fill ~11 ~9 ~13 ~21 ~9 ~13 stone 0  
fill ~11 ~9 ~25 ~21 ~9 ~25 stone 0  
fill ~11 ~9 ~31 ~13 ~9 ~31 stained_glass 4  
fill ~11 ~9 ~32 ~11 ~9 ~30 stained_glass 4 
setblock ~12 ~9 ~1 stained_hardened_clay 4 
setblock ~13 ~9 ~0 stained_glass 4 
setblock ~13 ~9 ~28 stained_hardened_clay 4  
fill ~13 ~9 ~32 ~13 ~10 ~32 stained_glass 4  
fill ~14 ~9 ~-1 ~16 ~9 ~-1 stained_glass 4  
fill ~14 ~9 ~12 ~18 ~9 ~12 stone 0  
fill ~14 ~9 ~26 ~18 ~9 ~26 stone 0  
fill ~14 ~9 ~29 ~15 ~9 ~29 stained_glass 1 
setblock ~15 ~9 ~28 stained_glass 1  
fill ~16 ~9 ~0 ~16 ~10 ~0 stained_glass 4  
fill ~16 ~9 ~1 ~17 ~9 ~1 stained_glass 4 
setblock ~16 ~9 ~5 stained_glass 1 
setblock ~16 ~9 ~7 stained_glass 1  
fill ~16 ~9 ~32 ~16 ~10 ~32 stained_glass 4 
setblock ~17 ~9 ~5 stained_hardened_clay 4  
fill ~17 ~9 ~28 ~21 ~9 ~28 stained_glass 1  
fill ~17 ~9 ~30 ~19 ~9 ~30 stained_glass 1 
setblock ~18 ~9 ~1 stained_glass 1  
fill ~18 ~9 ~31 ~19 ~9 ~31 stained_glass 1  
fill ~18 ~9 ~32 ~18 ~9 ~33 stained_glass 1  
fill ~19 ~9 ~14 ~22 ~9 ~14 stone 0  
fill ~19 ~9 ~24 ~22 ~9 ~24 stone 0 
setblock ~20 ~9 ~1 stained_glass 1 
setblock ~20 ~9 ~3 stained_glass 4  
fill ~20 ~9 ~29 ~21 ~9 ~29 stained_glass 1 
setblock ~21 ~9 ~2 stained_glass 4 
setblock ~21 ~9 ~4 stained_glass 1  
fill ~21 ~9 ~15 ~22 ~9 ~15 stone 0  
fill ~21 ~9 ~16 ~22 ~9 ~16 stone 0  
fill ~21 ~9 ~22 ~22 ~9 ~22 stone 0  
fill ~21 ~9 ~23 ~22 ~9 ~23 stone 0  
fill ~22 ~9 ~17 ~23 ~9 ~17 stone 0  
fill ~22 ~9 ~18 ~23 ~9 ~18 stone 0  
fill ~22 ~9 ~19 ~23 ~9 ~19 stone 0  
fill ~22 ~9 ~20 ~23 ~9 ~20 stone 0  
fill ~22 ~9 ~21 ~23 ~9 ~21 stone 0  
fill ~22 ~9 ~27 ~24 ~9 ~27 stained_glass 4  
fill ~22 ~9 ~31 ~22 ~12 ~31 stained_glass 1  
fill ~23 ~9 ~3 ~23 ~9 ~4 stained_glass 1 
setblock ~23 ~9 ~6 stained_hardened_clay 4  
fill ~23 ~9 ~26 ~26 ~9 ~26 stained_glass 4  
fill ~24 ~9 ~6 ~26 ~9 ~6 stained_glass 4 
setblock ~24 ~9 ~12 stained_glass 1 
setblock ~24 ~9 ~20 glowstone 0 
setblock ~25 ~9 ~9 stained_glass 1 
setblock ~25 ~9 ~21 stained_hardened_clay 4  
fill ~25 ~9 ~24 ~27 ~9 ~24 stained_glass 4  
fill ~25 ~9 ~25 ~27 ~9 ~25 stained_glass 4  
fill ~26 ~9 ~7 ~27 ~9 ~7 stained_glass 4 
setblock ~26 ~9 ~8 stained_hardened_clay 4  
fill ~26 ~9 ~12 ~26 ~10 ~12 stained_glass 4  
fill ~26 ~9 ~13 ~27 ~9 ~13 stained_glass 4  
fill ~26 ~9 ~14 ~27 ~9 ~14 stained_glass 4  
fill ~26 ~9 ~15 ~26 ~10 ~15 stained_glass 4  
fill ~26 ~9 ~17 ~28 ~9 ~17 stained_glass 4  
fill ~26 ~9 ~19 ~26 ~10 ~19 stained_glass 4  
fill ~26 ~9 ~20 ~26 ~10 ~20 stained_glass 4  
fill ~26 ~9 ~21 ~26 ~10 ~21 stained_glass 4  
fill ~26 ~9 ~27 ~26 ~10 ~27 stained_glass 4  
fill ~27 ~9 ~9 ~27 ~10 ~9 stained_glass 4  
fill ~27 ~9 ~10 ~28 ~9 ~10 stained_glass 4  
fill ~27 ~9 ~18 ~28 ~9 ~18 stained_glass 4  
fill ~28 ~9 ~16 ~28 ~11 ~16 stained_glass 4  
fill ~28 ~9 ~20 ~28 ~9 ~22 stained_glass 4  
fill ~30 ~9 ~15 ~30 ~14 ~15 stained_glass 4  
fill ~30 ~9 ~18 ~30 ~10 ~18 stained_glass 4  
fill ~-3 ~10 ~12 ~-3 ~10 ~12 stained_glass 4 
setblock ~-3 ~10 ~13 stained_glass 4 
setblock ~-2 ~10 ~13 stained_hardened_clay 4  
fill ~-2 ~10 ~19 ~1 ~10 ~19 stained_glass 4  
fill ~-1 ~10 ~11 ~-1 ~14 ~11 stained_glass 4  
fill ~-1 ~10 ~16 ~0 ~10 ~16 stained_glass 4  
fill ~-1 ~10 ~18 ~0 ~10 ~18 stained_glass 4  
fill ~-1 ~10 ~23 ~-1 ~11 ~23 stained_glass 4  
fill ~-1 ~10 ~24 ~2 ~10 ~24 stained_glass 4  
fill ~0 ~10 ~10 ~0 ~21 ~10 stained_glass 4  
fill ~0 ~10 ~20 ~1 ~10 ~20 stained_glass 4  
fill ~1 ~10 ~4 ~1 ~11 ~4 stained_glass 4  
fill ~1 ~10 ~5 ~1 ~12 ~5 stained_glass 4  
fill ~1 ~10 ~7 ~3 ~10 ~7 stained_glass 4  
fill ~1 ~10 ~8 ~2 ~10 ~8 stained_glass 4  
fill ~1 ~10 ~9 ~1 ~16 ~9 stained_glass 4  
fill ~1 ~10 ~22 ~1 ~12 ~22 stained_glass 4  
fill ~2 ~10 ~3 ~7 ~10 ~3 stained_glass 4 
setblock ~2 ~10 ~23 stained_hardened_clay 4  
fill ~2 ~10 ~26 ~2 ~13 ~26 stained_glass 4  
fill ~3 ~10 ~4 ~3 ~12 ~4 stained_glass 4  
fill ~3 ~10 ~28 ~4 ~10 ~28 stained_glass 4 
setblock ~4 ~10 ~6 stained_glass 1  
fill ~4 ~10 ~8 ~4 ~12 ~8 stained_glass 4  
fill ~4 ~10 ~9 ~4 ~10 ~8 stained_glass 4 
setblock ~4 ~10 ~25 stained_glass 1  
fill ~4 ~10 ~29 ~4 ~13 ~29 stained_glass 4  
fill ~4 ~10 ~30 ~7 ~10 ~30 stained_glass 4 
setblock ~5 ~10 ~28 stained_glass 1  
fill ~7 ~10 ~2 ~10 ~10 ~2 stained_glass 4 
setblock ~7 ~10 ~4 stained_glass 4  
fill ~7 ~10 ~17 ~8 ~10 ~17 stone 0  
fill ~7 ~10 ~18 ~8 ~10 ~18 stone 0  
fill ~7 ~10 ~19 ~8 ~10 ~19 stone 0  
fill ~7 ~10 ~20 ~8 ~10 ~20 stone 0  
fill ~7 ~10 ~21 ~8 ~10 ~21 stone 0  
fill ~8 ~10 ~14 ~9 ~10 ~14 stone 0  
fill ~8 ~10 ~15 ~9 ~10 ~15 stone 0  
fill ~8 ~10 ~16 ~9 ~10 ~16 stone 0  
fill ~8 ~10 ~22 ~9 ~10 ~22 stone 0  
fill ~8 ~10 ~23 ~9 ~10 ~23 stone 0  
fill ~8 ~10 ~24 ~9 ~10 ~24 stone 0 
setblock ~9 ~10 ~0 stained_glass 4  
fill ~9 ~10 ~13 ~10 ~10 ~13 stone 0  
fill ~9 ~10 ~25 ~10 ~10 ~25 stone 0  
fill ~9 ~10 ~29 ~9 ~11 ~29 stained_glass 4  
fill ~10 ~10 ~12 ~13 ~10 ~12 stone 0  
fill ~10 ~10 ~26 ~13 ~10 ~26 stone 0 
setblock ~10 ~10 ~29 stained_hardened_clay 4  
fill ~10 ~10 ~31 ~11 ~10 ~31 stained_glass 4  
fill ~11 ~10 ~1 ~11 ~13 ~1 stained_glass 1  
fill ~11 ~10 ~2 ~11 ~10 ~1 stained_glass 1 
setblock ~11 ~10 ~3 stained_glass 4 
setblock ~11 ~10 ~4 stained_hardened_clay 4  
fill ~11 ~10 ~11 ~21 ~10 ~11 stone 0  
fill ~11 ~10 ~27 ~21 ~10 ~27 stone 0  
fill ~12 ~10 ~-1 ~12 ~11 ~-1 stained_glass 4 
setblock ~12 ~10 ~1 stained_glass 4  
fill ~13 ~10 ~31 ~13 ~11 ~31 stained_glass 4  
fill ~14 ~10 ~-2 ~14 ~10 ~-1 stained_glass 4  
fill ~14 ~10 ~10 ~18 ~10 ~10 stone 0  
fill ~14 ~10 ~28 ~18 ~10 ~28 stone 0  
fill ~14 ~10 ~32 ~16 ~10 ~32 stained_glass 4  
fill ~15 ~10 ~-1 ~15 ~10 ~0 stained_glass 4  
fill ~16 ~10 ~1 ~16 ~7 ~1 stained_glass 4  
fill ~16 ~10 ~30 ~17 ~10 ~30 stained_glass 1 
setblock ~16 ~10 ~33 stained_glass 1  
fill ~17 ~10 ~1 ~17 ~12 ~1 stained_glass 1 
setblock ~17 ~10 ~29 glowstone 0 
setblock ~17 ~10 ~31 stained_glass 1  
fill ~18 ~10 ~2 ~19 ~10 ~2 stained_glass 1  
fill ~19 ~10 ~12 ~22 ~10 ~12 stone 0  
fill ~19 ~10 ~26 ~22 ~10 ~26 stone 0  
fill ~19 ~10 ~28 ~22 ~10 ~28 stained_glass 1  
fill ~19 ~10 ~31 ~23 ~10 ~31 stained_glass 1  
fill ~19 ~10 ~32 ~19 ~10 ~31 stained_glass 1 
setblock ~20 ~10 ~3 stained_glass 1  
fill ~21 ~10 ~29 ~22 ~10 ~29 stained_glass 1  
fill ~22 ~10 ~3 ~23 ~10 ~3 stained_glass 4  
fill ~22 ~10 ~13 ~23 ~10 ~13 stone 0  
fill ~22 ~10 ~25 ~23 ~10 ~25 stone 0  
fill ~23 ~10 ~14 ~24 ~10 ~14 stone 0  
fill ~23 ~10 ~15 ~24 ~10 ~15 stone 0  
fill ~23 ~10 ~16 ~24 ~10 ~16 stone 0  
fill ~23 ~10 ~22 ~24 ~10 ~22 stone 0  
fill ~23 ~10 ~23 ~24 ~10 ~23 stone 0  
fill ~23 ~10 ~24 ~24 ~10 ~24 stone 0  
fill ~23 ~10 ~29 ~26 ~10 ~29 stained_glass 4  
fill ~23 ~10 ~30 ~26 ~10 ~30 stained_glass 4 
setblock ~23 ~10 ~32 stained_glass 1 
setblock ~24 ~10 ~3 stained_glass 1 
setblock ~24 ~10 ~4 stained_glass 4  
fill ~24 ~10 ~5 ~25 ~10 ~5 stained_glass 1  
fill ~24 ~10 ~6 ~24 ~10 ~5 stained_glass 1 
setblock ~24 ~10 ~11 stained_glass 1  
fill ~24 ~10 ~17 ~25 ~10 ~17 stone 0  
fill ~24 ~10 ~18 ~25 ~10 ~18 stone 0  
fill ~24 ~10 ~19 ~25 ~10 ~19 stone 0  
fill ~24 ~10 ~20 ~25 ~10 ~20 stone 0  
fill ~24 ~10 ~21 ~25 ~10 ~21 stone 0  
fill ~25 ~10 ~6 ~26 ~10 ~6 stained_glass 4 
setblock ~25 ~10 ~9 glowstone 0 
setblock ~25 ~10 ~10 stained_glass 1 
setblock ~25 ~10 ~13 stained_hardened_clay 4 
setblock ~25 ~10 ~15 stained_hardened_clay 4 
setblock ~25 ~10 ~16 stained_glass 4  
fill ~25 ~10 ~28 ~26 ~10 ~28 stained_glass 4  
fill ~26 ~10 ~7 ~27 ~10 ~7 stained_glass 4  
fill ~26 ~10 ~11 ~26 ~11 ~11 stained_glass 4  
fill ~26 ~10 ~13 ~26 ~5 ~13 stained_glass 4  
fill ~26 ~10 ~14 ~27 ~10 ~14 stained_glass 4 
setblock ~26 ~10 ~23 stained_hardened_clay 4 
setblock ~26 ~10 ~24 stained_glass 4 
setblock ~26 ~10 ~26 stained_glass 4  
fill ~27 ~10 ~8 ~28 ~10 ~8 stained_glass 4  
fill ~27 ~10 ~10 ~31 ~10 ~10 stained_glass 4  
fill ~27 ~10 ~17 ~29 ~10 ~17 stained_glass 4  
fill ~27 ~10 ~18 ~30 ~10 ~18 stained_glass 4  
fill ~27 ~10 ~25 ~29 ~10 ~25 stained_glass 4  
fill ~27 ~10 ~27 ~27 ~11 ~27 stained_glass 4  
fill ~28 ~10 ~9 ~28 ~14 ~9 stained_glass 4 
setblock ~28 ~10 ~15 stained_glass 4  
fill ~28 ~10 ~19 ~29 ~10 ~19 stained_glass 4  
fill ~28 ~10 ~21 ~28 ~11 ~21 stained_glass 4  
fill ~28 ~10 ~22 ~28 ~11 ~22 stained_glass 4  
fill ~28 ~10 ~23 ~28 ~11 ~23 stained_glass 4 
setblock ~29 ~10 ~16 stained_glass 4  
fill ~29 ~10 ~24 ~29 ~13 ~24 stained_glass 4  
fill ~30 ~10 ~11 ~30 ~11 ~11 stained_glass 4  
fill ~-3 ~11 ~12 ~-1 ~11 ~12 stained_glass 4  
fill ~-2 ~11 ~13 ~-1 ~11 ~13 stained_glass 4  
fill ~-1 ~11 ~14 ~-1 ~16 ~14 stained_glass 4  
fill ~-1 ~11 ~15 ~-1 ~16 ~15 stained_glass 4  
fill ~-1 ~11 ~16 ~-1 ~13 ~16 stained_glass 4  
fill ~-1 ~11 ~18 ~0 ~11 ~18 stained_glass 4  
fill ~-1 ~11 ~19 ~-1 ~11 ~23 stained_glass 4  
fill ~0 ~11 ~6 ~0 ~11 ~10 stained_glass 4 
setblock ~0 ~11 ~14 stained_glass 1 
setblock ~0 ~11 ~15 stained_hardened_clay 4  
fill ~0 ~11 ~17 ~0 ~12 ~17 stained_glass 4  
fill ~1 ~11 ~7 ~2 ~11 ~7 stained_glass 4  
fill ~1 ~11 ~8 ~4 ~11 ~8 stained_glass 4  
fill ~1 ~11 ~19 ~1 ~13 ~19 stained_glass 4  
fill ~1 ~11 ~20 ~1 ~14 ~20 stained_glass 4  
fill ~1 ~11 ~21 ~1 ~14 ~21 stained_glass 4  
fill ~1 ~11 ~24 ~2 ~11 ~24 stained_glass 4  
fill ~2 ~11 ~3 ~6 ~11 ~3 stained_glass 4 
setblock ~2 ~11 ~9 stained_hardened_clay 4 
setblock ~2 ~11 ~20 stained_hardened_clay 4  
fill ~2 ~11 ~27 ~2 ~12 ~27 stained_glass 4  
fill ~2 ~11 ~28 ~3 ~11 ~28 stained_glass 4 
setblock ~3 ~11 ~9 stained_glass 4  
fill ~4 ~11 ~6 ~4 ~12 ~6 stained_glass 4  
fill ~4 ~11 ~30 ~7 ~11 ~30 stained_glass 4  
fill ~5 ~11 ~1 ~5 ~11 ~3 stained_glass 4  
fill ~5 ~11 ~16 ~7 ~11 ~16 stone 0  
fill ~5 ~11 ~17 ~6 ~11 ~17 stone 0  
fill ~5 ~11 ~18 ~6 ~11 ~18 stone 0  
fill ~5 ~11 ~19 ~6 ~11 ~19 stone 0  
fill ~5 ~11 ~20 ~6 ~11 ~20 stone 0  
fill ~5 ~11 ~21 ~6 ~11 ~21 stone 0  
fill ~5 ~11 ~22 ~7 ~11 ~22 stone 0  
fill ~6 ~11 ~2 ~6 ~18 ~2 stained_glass 4 
setblock ~6 ~11 ~4 stained_glass 4 
setblock ~6 ~11 ~5 stained_hardened_clay 4  
fill ~6 ~11 ~13 ~8 ~11 ~13 stone 0  
fill ~6 ~11 ~14 ~7 ~11 ~14 stone 0  
fill ~6 ~11 ~15 ~7 ~11 ~15 stone 0  
fill ~6 ~11 ~23 ~7 ~11 ~23 stone 0  
fill ~6 ~11 ~24 ~7 ~11 ~24 stone 0  
fill ~6 ~11 ~25 ~8 ~11 ~25 stone 0  
fill ~7 ~11 ~0 ~7 ~12 ~0 stained_glass 4  
fill ~7 ~11 ~1 ~7 ~17 ~1 stained_glass 4  
fill ~7 ~11 ~12 ~9 ~11 ~12 stone 0  
fill ~7 ~11 ~26 ~9 ~11 ~26 stone 0  
fill ~7 ~11 ~31 ~7 ~14 ~31 stained_glass 4  
fill ~8 ~11 ~11 ~10 ~11 ~11 stone 0  
fill ~8 ~11 ~27 ~10 ~11 ~27 stone 0  
fill ~9 ~11 ~2 ~9 ~12 ~2 stained_glass 4  
fill ~9 ~11 ~10 ~13 ~11 ~10 stone 0  
fill ~9 ~11 ~28 ~13 ~11 ~28 stone 0  
fill ~9 ~11 ~31 ~14 ~11 ~31 stained_glass 4  
fill ~10 ~11 ~0 ~10 ~12 ~0 stained_glass 4  
fill ~10 ~11 ~1 ~10 ~13 ~1 stained_glass 1  
fill ~10 ~11 ~9 ~22 ~11 ~9 stone 0  
fill ~10 ~11 ~29 ~22 ~11 ~29 stone 0  
fill ~10 ~11 ~32 ~11 ~11 ~32 stained_glass 4  
fill ~13 ~11 ~8 ~19 ~11 ~8 stone 0  
fill ~13 ~11 ~30 ~19 ~11 ~30 stone 0  
fill ~13 ~11 ~33 ~13 ~13 ~33 stained_glass 1  
fill ~14 ~11 ~-1 ~14 ~13 ~-1 stained_glass 4  
fill ~14 ~11 ~34 ~14 ~14 ~34 stained_glass 1  
fill ~15 ~11 ~-1 ~16 ~11 ~-1 stained_glass 1 
setblock ~15 ~11 ~31 stained_glass 1  
fill ~15 ~11 ~33 ~15 ~13 ~33 stained_glass 1  
fill ~16 ~11 ~0 ~16 ~12 ~0 stained_glass 1  
fill ~16 ~11 ~1 ~16 ~14 ~1 stained_glass 1  
fill ~17 ~11 ~2 ~17 ~12 ~2 stained_glass 1 
setblock ~17 ~11 ~3 stained_hardened_clay 1 
setblock ~17 ~11 ~31 stained_glass 4  
fill ~17 ~11 ~32 ~18 ~11 ~32 stained_glass 1  
fill ~17 ~11 ~33 ~17 ~11 ~34 stained_glass 1  
fill ~18 ~11 ~1 ~18 ~14 ~1 stained_glass 1  
fill ~18 ~11 ~31 ~26 ~11 ~31 stained_glass 1  
fill ~19 ~11 ~2 ~19 ~17 ~2 stained_glass 1  
fill ~19 ~11 ~10 ~23 ~11 ~10 stone 0  
fill ~19 ~11 ~28 ~23 ~11 ~28 stone 0 
setblock ~20 ~11 ~3 stained_hardened_clay 4  
fill ~20 ~11 ~30 ~23 ~11 ~30 stained_glass 1  
fill ~21 ~11 ~2 ~21 ~13 ~2 stained_glass 4  
fill ~22 ~11 ~3 ~23 ~11 ~3 stained_glass 4  
fill ~22 ~11 ~4 ~23 ~11 ~4 stained_hardened_clay 4  
fill ~22 ~11 ~11 ~24 ~11 ~11 stone 0  
fill ~22 ~11 ~27 ~24 ~11 ~27 stone 0  
fill ~23 ~11 ~12 ~25 ~11 ~12 stone 0  
fill ~23 ~11 ~26 ~25 ~11 ~26 stone 0  
fill ~24 ~11 ~4 ~24 ~15 ~4 stained_glass 1 
setblock ~24 ~11 ~5 stained_hardened_clay 1 
setblock ~24 ~11 ~8 stained_glass 1  
fill ~24 ~11 ~13 ~26 ~11 ~13 stone 0  
fill ~24 ~11 ~25 ~26 ~11 ~25 stone 0  
fill ~24 ~11 ~30 ~25 ~11 ~30 stained_glass 4  
fill ~25 ~11 ~5 ~25 ~14 ~5 stained_glass 4  
fill ~25 ~11 ~14 ~26 ~11 ~14 stone 0  
fill ~25 ~11 ~15 ~26 ~11 ~15 stone 0  
fill ~25 ~11 ~16 ~27 ~11 ~16 stone 0  
fill ~25 ~11 ~22 ~27 ~11 ~22 stone 0  
fill ~25 ~11 ~23 ~26 ~11 ~23 stone 0  
fill ~25 ~11 ~24 ~26 ~11 ~24 stone 0 
setblock ~25 ~11 ~27 glowstone 0  
fill ~26 ~11 ~6 ~27 ~11 ~6 stained_glass 4 
setblock ~26 ~11 ~8 stained_glass 1  
fill ~26 ~11 ~17 ~27 ~11 ~17 stone 0  
fill ~26 ~11 ~18 ~27 ~11 ~18 stone 0  
fill ~26 ~11 ~19 ~27 ~11 ~19 stone 0  
fill ~26 ~11 ~20 ~27 ~11 ~20 stone 0  
fill ~26 ~11 ~21 ~27 ~11 ~21 stone 0  
fill ~26 ~11 ~29 ~28 ~11 ~29 stained_glass 4  
fill ~27 ~11 ~7 ~27 ~15 ~7 stained_glass 1  
fill ~27 ~11 ~8 ~29 ~11 ~8 stained_glass 4  
fill ~27 ~11 ~13 ~27 ~11 ~15 stained_glass 4  
fill ~27 ~11 ~24 ~29 ~11 ~24 stained_glass 4  
fill ~27 ~11 ~25 ~28 ~11 ~25 stained_glass 4  
fill ~27 ~11 ~26 ~27 ~11 ~23 stained_glass 4  
fill ~28 ~11 ~12 ~29 ~11 ~12 stained_glass 4  
fill ~28 ~11 ~14 ~29 ~11 ~14 stained_glass 4  
fill ~28 ~11 ~17 ~30 ~11 ~17 stained_glass 4  
fill ~28 ~11 ~20 ~29 ~11 ~20 stained_glass 4  
fill ~28 ~11 ~27 ~28 ~11 ~29 stained_glass 4 
setblock ~29 ~11 ~9 stained_glass 4  
fill ~29 ~11 ~13 ~31 ~11 ~13 stained_glass 4  
fill ~29 ~11 ~18 ~29 ~12 ~18 stained_glass 4  
fill ~29 ~11 ~19 ~31 ~11 ~19 stained_glass 4  
fill ~30 ~11 ~10 ~31 ~11 ~10 stained_glass 4 
setblock ~31 ~11 ~11 stained_glass 4  
fill ~-3 ~12 ~12 ~0 ~12 ~12 stained_glass 4  
fill ~-2 ~12 ~13 ~-1 ~12 ~13 stained_glass 4  
fill ~-1 ~12 ~8 ~6 ~12 ~8 stained_glass 4  
fill ~-1 ~12 ~10 ~-1 ~17 ~10 stained_glass 4  
fill ~-1 ~12 ~20 ~1 ~12 ~20 stained_glass 4  
fill ~-1 ~12 ~24 ~1 ~12 ~24 stained_glass 4 
setblock ~0 ~12 ~16 stained_glass 4  
fill ~0 ~12 ~18 ~1 ~12 ~18 stained_glass 4  
fill ~0 ~12 ~22 ~0 ~16 ~22 stained_glass 4  
fill ~1 ~12 ~6 ~1 ~12 ~9 stained_glass 4 
setblock ~1 ~12 ~12 stained_hardened_clay 4  
fill ~1 ~12 ~23 ~1 ~15 ~23 stained_glass 4  
fill ~1 ~12 ~25 ~1 ~12 ~26 stained_glass 4  
fill ~2 ~12 ~7 ~2 ~14 ~7 stained_glass 4  
fill ~2 ~12 ~9 ~2 ~13 ~9 stained_glass 4 
setblock ~2 ~12 ~10 stained_hardened_clay 4 
setblock ~2 ~12 ~18 stained_hardened_clay 4  
fill ~3 ~12 ~3 ~7 ~12 ~3 stained_glass 4 
setblock ~3 ~12 ~26 stained_hardened_clay 4  
fill ~3 ~12 ~28 ~3 ~14 ~28 stained_glass 4  
fill ~3 ~12 ~29 ~3 ~15 ~29 stained_glass 4  
fill ~4 ~12 ~0 ~4 ~12 ~6 stained_glass 4  
fill ~4 ~12 ~14 ~5 ~12 ~14 stone 0  
fill ~4 ~12 ~15 ~5 ~12 ~15 stone 0  
fill ~4 ~12 ~16 ~4 ~13 ~16 stone 0  
fill ~4 ~12 ~17 ~4 ~13 ~17 stone 0  
fill ~4 ~12 ~18 ~4 ~13 ~18 stone 0  
fill ~4 ~12 ~19 ~4 ~13 ~19 stone 0  
fill ~4 ~12 ~20 ~4 ~13 ~20 stone 0  
fill ~4 ~12 ~21 ~4 ~13 ~21 stone 0  
fill ~4 ~12 ~22 ~4 ~13 ~22 stone 0  
fill ~4 ~12 ~23 ~5 ~12 ~23 stone 0  
fill ~4 ~12 ~24 ~5 ~12 ~24 stone 0  
fill ~5 ~12 ~2 ~5 ~16 ~2 stained_glass 4  
fill ~5 ~12 ~12 ~7 ~12 ~12 stone 0  
fill ~5 ~12 ~13 ~6 ~12 ~13 stone 0  
fill ~5 ~12 ~25 ~5 ~12 ~26 stone 0 
setblock ~5 ~12 ~29 stained_hardened_clay 4 
setblock ~5 ~12 ~30 stained_glass 4 
setblock ~6 ~12 ~6 stained_hardened_clay 4  
fill ~6 ~12 ~11 ~8 ~12 ~11 stone 0  
fill ~6 ~12 ~26 ~7 ~12 ~26 stone 0  
fill ~6 ~12 ~27 ~7 ~12 ~27 stone 0  
fill ~6 ~12 ~31 ~6 ~14 ~31 stained_glass 4  
fill ~7 ~12 ~2 ~7 ~13 ~2 stained_glass 4  
fill ~7 ~12 ~10 ~9 ~12 ~10 stone 0  
fill ~7 ~12 ~28 ~8 ~12 ~28 stone 0 
setblock ~7 ~12 ~29 stained_glass 4 
setblock ~7 ~12 ~32 stained_glass 4 
setblock ~8 ~12 ~0 stained_glass 4 
setblock ~8 ~12 ~3 stained_hardened_clay 4  
fill ~8 ~12 ~9 ~9 ~12 ~9 stone 0  
fill ~8 ~12 ~29 ~9 ~12 ~29 stone 0 
setblock ~8 ~12 ~30 stained_glass 4 
setblock ~9 ~12 ~3 stained_glass 4  
fill ~9 ~12 ~8 ~12 ~12 ~8 stone 0  
fill ~9 ~12 ~30 ~12 ~12 ~30 stone 0  
fill ~9 ~12 ~31 ~10 ~12 ~31 stained_glass 4 
setblock ~10 ~12 ~2 stained_hardened_clay 1  
fill ~10 ~12 ~32 ~12 ~12 ~32 stained_glass 4  
fill ~11 ~12 ~-2 ~11 ~12 ~-1 stained_glass 4 
setblock ~11 ~12 ~0 stained_glass 1  
fill ~11 ~12 ~2 ~12 ~12 ~2 stained_glass 4  
fill ~11 ~12 ~7 ~21 ~12 ~7 stone 0  
fill ~11 ~12 ~31 ~21 ~12 ~31 stone 0  
fill ~12 ~12 ~1 ~12 ~15 ~1 stained_glass 1 
setblock ~13 ~12 ~-3 stained_glass 4 
setblock ~13 ~12 ~32 stained_glass 1 
setblock ~14 ~12 ~-2 stained_glass 4  
fill ~14 ~12 ~33 ~14 ~13 ~33 stained_glass 1  
fill ~15 ~12 ~-1 ~15 ~13 ~-1 stained_glass 4  
fill ~16 ~12 ~32 ~17 ~12 ~32 stained_glass 4  
fill ~16 ~12 ~33 ~16 ~13 ~33 stained_glass 1  
fill ~16 ~12 ~34 ~16 ~14 ~34 stained_glass 1  
fill ~16 ~12 ~35 ~16 ~12 ~36 stained_glass 1 
setblock ~17 ~12 ~33 stained_glass 4  
fill ~18 ~12 ~32 ~22 ~12 ~32 stained_glass 1  
fill ~18 ~12 ~34 ~18 ~14 ~34 stained_glass 1 
setblock ~19 ~12 ~1 stained_glass 1  
fill ~20 ~12 ~2 ~20 ~13 ~2 stained_glass 1  
fill ~20 ~12 ~4 ~20 ~13 ~4 stained_glass 1  
fill ~20 ~12 ~8 ~24 ~12 ~8 stone 0  
fill ~20 ~12 ~30 ~22 ~12 ~30 stone 0  
fill ~20 ~12 ~33 ~20 ~12 ~34 stained_glass 4 
setblock ~20 ~12 ~35 stained_glass 1  
fill ~22 ~12 ~3 ~23 ~12 ~3 stained_glass 4  
fill ~22 ~12 ~29 ~24 ~12 ~29 stone 0  
fill ~23 ~12 ~9 ~25 ~12 ~9 stone 0  
fill ~23 ~12 ~10 ~26 ~12 ~10 stone 0  
fill ~23 ~12 ~28 ~25 ~12 ~28 stone 0 
setblock ~23 ~12 ~31 stained_glass 1  
fill ~23 ~12 ~33 ~23 ~13 ~33 stained_glass 1  
fill ~24 ~12 ~5 ~24 ~14 ~5 stained_glass 1 
setblock ~24 ~12 ~7 stained_hardened_clay 1  
fill ~24 ~12 ~30 ~27 ~12 ~30 stained_glass 1  
fill ~25 ~12 ~7 ~25 ~13 ~7 stained_glass 1  
fill ~25 ~12 ~11 ~27 ~12 ~11 stone 0  
fill ~25 ~12 ~12 ~27 ~12 ~12 stone 0  
fill ~25 ~12 ~26 ~27 ~12 ~26 stone 0  
fill ~25 ~12 ~27 ~26 ~12 ~27 stone 0  
fill ~26 ~12 ~6 ~26 ~15 ~6 stained_glass 1  
fill ~26 ~12 ~13 ~27 ~12 ~13 stone 0  
fill ~26 ~12 ~28 ~27 ~12 ~28 stained_glass 1 
setblock ~27 ~12 ~10 stained_glass 4  
fill ~27 ~12 ~14 ~28 ~12 ~14 stone 0  
fill ~27 ~12 ~15 ~28 ~12 ~15 stone 0  
fill ~27 ~12 ~23 ~28 ~12 ~23 stone 0  
fill ~27 ~12 ~24 ~28 ~12 ~24 stone 0  
fill ~27 ~12 ~25 ~27 ~12 ~23 stone 0 
setblock ~27 ~12 ~27 stained_glass 1  
fill ~27 ~12 ~29 ~28 ~12 ~29 stained_glass 4  
fill ~28 ~12 ~8 ~28 ~13 ~8 stained_glass 4  
fill ~28 ~12 ~11 ~29 ~12 ~11 stained_glass 4 
setblock ~28 ~12 ~13 stained_glass 4  
fill ~28 ~12 ~16 ~28 ~13 ~16 stone 0  
fill ~28 ~12 ~17 ~28 ~13 ~17 stone 0  
fill ~28 ~12 ~18 ~28 ~13 ~18 stone 0  
fill ~28 ~12 ~19 ~28 ~13 ~19 stone 0  
fill ~28 ~12 ~20 ~28 ~13 ~20 stone 0  
fill ~28 ~12 ~21 ~28 ~13 ~21 stone 0  
fill ~28 ~12 ~22 ~28 ~13 ~22 stone 0  
fill ~28 ~12 ~25 ~29 ~12 ~25 stained_glass 4  
fill ~28 ~12 ~26 ~28 ~12 ~25 stained_glass 4  
fill ~29 ~12 ~10 ~29 ~14 ~10 stained_glass 4  
fill ~29 ~12 ~12 ~29 ~14 ~12 stained_glass 4  
fill ~29 ~12 ~14 ~29 ~13 ~14 stained_glass 4  
fill ~29 ~12 ~16 ~30 ~12 ~16 stained_glass 4  
fill ~29 ~12 ~17 ~29 ~12 ~16 stained_glass 4  
fill ~29 ~12 ~19 ~29 ~10 ~19 stained_glass 4  
fill ~29 ~12 ~20 ~29 ~12 ~25 stained_glass 4  
fill ~30 ~12 ~18 ~31 ~12 ~18 stained_glass 4  
fill ~30 ~12 ~21 ~32 ~12 ~21 stained_glass 4  
fill ~30 ~12 ~22 ~31 ~12 ~22 stained_glass 4  
fill ~-2 ~13 ~11 ~-2 ~14 ~11 stained_glass 4  
fill ~-2 ~13 ~20 ~-2 ~15 ~20 stained_glass 4  
fill ~-1 ~13 ~8 ~1 ~13 ~8 stained_glass 4  
fill ~-1 ~13 ~9 ~-1 ~15 ~9 stained_glass 4  
fill ~-1 ~13 ~12 ~0 ~13 ~12 stained_glass 4  
fill ~-1 ~13 ~13 ~0 ~13 ~13 stained_glass 4  
fill ~-1 ~13 ~22 ~-1 ~17 ~22 stained_glass 4  
fill ~-1 ~13 ~23 ~-1 ~13 ~24 stained_glass 4 
setblock ~0 ~13 ~16 stained_hardened_clay 4  
fill ~0 ~13 ~20 ~0 ~13 ~23 stained_glass 4  
fill ~1 ~13 ~7 ~1 ~18 ~7 stained_glass 4 
setblock ~1 ~13 ~10 stained_hardened_clay 4 
setblock ~1 ~13 ~13 stained_hardened_clay 4  
fill ~1 ~13 ~18 ~1 ~14 ~18 stained_glass 4  
fill ~1 ~13 ~24 ~1 ~16 ~24 stained_glass 4 
setblock ~2 ~13 ~11 glowstone 0 
setblock ~2 ~13 ~23 stained_hardened_clay 4  
fill ~3 ~13 ~3 ~4 ~13 ~3 stained_glass 4 
setblock ~3 ~13 ~7 stained_hardened_clay 4 
setblock ~3 ~13 ~11 stained_hardened_clay 4  
fill ~3 ~13 ~15 ~4 ~13 ~15 stone 0  
fill ~3 ~13 ~16 ~3 ~16 ~16 stone 0  
fill ~3 ~13 ~17 ~3 ~16 ~17 stone 0  
fill ~3 ~13 ~18 ~3 ~16 ~18 stone 0  
fill ~3 ~13 ~19 ~3 ~16 ~19 stone 0  
fill ~3 ~13 ~20 ~3 ~16 ~20 stone 0  
fill ~3 ~13 ~21 ~3 ~16 ~21 stone 0  
fill ~3 ~13 ~22 ~3 ~16 ~22 stone 0  
fill ~3 ~13 ~23 ~4 ~13 ~23 stone 0 
setblock ~3 ~13 ~24 stained_glass 4  
fill ~3 ~13 ~26 ~3 ~14 ~26 stained_glass 4 
setblock ~3 ~13 ~30 stained_glass 4 
setblock ~4 ~13 ~1 stained_glass 4  
fill ~4 ~13 ~5 ~4 ~21 ~5 stained_glass 4  
fill ~4 ~13 ~12 ~5 ~13 ~12 stone 0  
fill ~4 ~13 ~13 ~4 ~13 ~26 stone 0 
setblock ~4 ~13 ~27 stained_glass 4  
fill ~5 ~13 ~4 ~6 ~13 ~4 stained_glass 4  
fill ~5 ~13 ~8 ~6 ~13 ~8 stained_glass 4  
fill ~5 ~13 ~11 ~6 ~13 ~11 stone 0  
fill ~5 ~13 ~27 ~6 ~13 ~27 stone 0 
setblock ~5 ~13 ~29 stained_glass 4 
setblock ~5 ~13 ~31 stained_glass 4  
fill ~6 ~13 ~1 ~6 ~15 ~1 stained_glass 4  
fill ~6 ~13 ~3 ~6 ~16 ~3 stained_glass 4  
fill ~6 ~13 ~5 ~6 ~14 ~5 stained_glass 4  
fill ~6 ~13 ~6 ~7 ~13 ~6 stained_glass 4  
fill ~6 ~13 ~9 ~8 ~13 ~9 stone 0  
fill ~6 ~13 ~10 ~7 ~13 ~10 stone 0  
fill ~6 ~13 ~28 ~6 ~13 ~29 stone 0  
fill ~6 ~13 ~30 ~7 ~13 ~30 stained_glass 4 
setblock ~7 ~13 ~29 stone 0 
setblock ~8 ~13 ~8 stone 0 
setblock ~8 ~13 ~30 stone 0  
fill ~8 ~13 ~32 ~11 ~13 ~32 stained_glass 4  
fill ~9 ~13 ~7 ~23 ~13 ~7 stone 0  
fill ~9 ~13 ~31 ~11 ~13 ~31 stone 0  
fill ~11 ~13 ~2 ~11 ~19 ~2 stained_glass 1  
fill ~11 ~13 ~34 ~11 ~16 ~34 stained_glass 4  
fill ~12 ~13 ~6 ~20 ~13 ~6 stone 0  
fill ~12 ~13 ~32 ~20 ~13 ~32 stone 0 
setblock ~12 ~13 ~33 stained_glass 4 
setblock ~13 ~13 ~1 stained_glass 4  
fill ~13 ~13 ~2 ~13 ~13 ~3 stained_glass 1 
setblock ~13 ~13 ~4 stained_hardened_clay 1  
fill ~13 ~13 ~34 ~13 ~15 ~34 stained_glass 1  
fill ~14 ~13 ~0 ~15 ~13 ~0 stained_glass 1  
fill ~15 ~13 ~34 ~15 ~14 ~34 stained_glass 1 
setblock ~16 ~13 ~3 glowstone 0  
fill ~17 ~13 ~3 ~17 ~15 ~3 stained_glass 1  
fill ~18 ~13 ~2 ~18 ~14 ~2 stained_glass 1 
setblock ~18 ~13 ~3 stained_hardened_clay 1 
setblock ~18 ~13 ~33 stained_glass 1 
setblock ~18 ~13 ~35 stained_glass 1  
fill ~19 ~13 ~0 ~19 ~13 ~1 stained_glass 4 
setblock ~19 ~13 ~4 stained_hardened_clay 1 
setblock ~19 ~13 ~33 stained_glass 4  
fill ~19 ~13 ~34 ~19 ~15 ~34 stained_glass 1  
fill ~20 ~13 ~3 ~21 ~13 ~3 stained_glass 1  
fill ~20 ~13 ~33 ~21 ~13 ~33 stained_glass 1  
fill ~21 ~13 ~31 ~22 ~13 ~31 stone 0  
fill ~21 ~13 ~34 ~24 ~13 ~34 stained_glass 1  
fill ~22 ~13 ~3 ~22 ~14 ~3 stained_glass 4 
setblock ~22 ~13 ~5 stained_hardened_clay 1  
fill ~22 ~13 ~32 ~22 ~13 ~33 stained_glass 4  
fill ~23 ~13 ~3 ~23 ~18 ~3 stained_glass 1 
setblock ~23 ~13 ~5 stained_glass 1  
fill ~23 ~13 ~30 ~24 ~13 ~30 stone 0  
fill ~23 ~13 ~31 ~24 ~13 ~31 stained_glass 4  
fill ~23 ~13 ~32 ~23 ~14 ~32 stained_glass 1  
fill ~24 ~13 ~8 ~25 ~13 ~8 stone 0  
fill ~24 ~13 ~9 ~26 ~13 ~9 stone 0  
fill ~24 ~13 ~29 ~25 ~13 ~29 stone 0  
fill ~24 ~13 ~35 ~25 ~13 ~35 stained_glass 1 
setblock ~25 ~13 ~30 stained_glass 1  
fill ~26 ~13 ~10 ~27 ~13 ~10 stone 0  
fill ~26 ~13 ~11 ~27 ~13 ~11 stone 0  
fill ~26 ~13 ~27 ~27 ~13 ~27 stone 0  
fill ~26 ~13 ~28 ~26 ~13 ~27 stone 0  
fill ~26 ~13 ~30 ~26 ~13 ~31 stained_glass 4  
fill ~27 ~13 ~12 ~28 ~13 ~12 stone 0  
fill ~27 ~13 ~26 ~28 ~13 ~26 stone 0  
fill ~27 ~13 ~28 ~28 ~13 ~28 stained_glass 1  
fill ~27 ~13 ~29 ~27 ~13 ~28 stained_glass 1  
fill ~27 ~13 ~31 ~27 ~15 ~31 stained_glass 1  
fill ~28 ~13 ~10 ~28 ~13 ~11 stained_glass 4  
fill ~28 ~13 ~13 ~28 ~14 ~13 stone 0  
fill ~28 ~13 ~14 ~28 ~13 ~26 stone 0 
setblock ~28 ~13 ~27 stained_glass 4  
fill ~29 ~13 ~9 ~29 ~15 ~9 stained_glass 4  
fill ~29 ~13 ~11 ~30 ~13 ~11 stained_glass 4  
fill ~29 ~13 ~13 ~30 ~13 ~13 stained_glass 4  
fill ~29 ~13 ~15 ~29 ~16 ~15 stone 0  
fill ~29 ~13 ~16 ~29 ~16 ~16 stone 0  
fill ~29 ~13 ~17 ~29 ~16 ~17 stone 0  
fill ~29 ~13 ~18 ~29 ~16 ~18 stone 0  
fill ~29 ~13 ~19 ~29 ~16 ~19 stone 0  
fill ~29 ~13 ~20 ~29 ~16 ~20 stone 0  
fill ~29 ~13 ~21 ~29 ~16 ~21 stone 0  
fill ~29 ~13 ~22 ~29 ~16 ~22 stone 0  
fill ~29 ~13 ~23 ~29 ~16 ~23 stone 0  
fill ~29 ~13 ~26 ~29 ~14 ~26 stained_glass 1  
fill ~30 ~13 ~14 ~30 ~14 ~14 stained_glass 4  
fill ~30 ~13 ~17 ~31 ~13 ~17 stained_glass 4  
fill ~30 ~13 ~18 ~32 ~13 ~18 stained_glass 4  
fill ~30 ~13 ~19 ~30 ~13 ~21 stained_glass 4 
setblock ~30 ~13 ~22 glowstone 0  
fill ~30 ~13 ~23 ~30 ~14 ~23 stained_glass 4  
fill ~30 ~13 ~24 ~30 ~14 ~24 stained_glass 4  
fill ~30 ~13 ~25 ~30 ~15 ~25 stained_glass 4  
fill ~30 ~13 ~26 ~30 ~13 ~23 stained_glass 4  
fill ~31 ~13 ~15 ~31 ~13 ~18 stained_glass 4  
fill ~31 ~13 ~21 ~31 ~14 ~21 stained_glass 4  
fill ~31 ~13 ~22 ~31 ~15 ~22 stained_glass 4 
setblock ~-2 ~14 ~10 stained_glass 4 
setblock ~-2 ~14 ~21 stained_glass 4  
fill ~-1 ~14 ~13 ~0 ~14 ~13 stained_glass 4  
fill ~-1 ~14 ~17 ~1 ~14 ~17 stained_glass 4  
fill ~0 ~14 ~7 ~0 ~15 ~7 stained_glass 4  
fill ~0 ~14 ~8 ~2 ~14 ~8 stained_glass 4  
fill ~0 ~14 ~11 ~2 ~14 ~11 stained_glass 4  
fill ~0 ~14 ~12 ~0 ~18 ~12 stained_glass 4  
fill ~0 ~14 ~14 ~0 ~17 ~14 stained_glass 4  
fill ~0 ~14 ~15 ~0 ~17 ~15 stained_glass 4  
fill ~0 ~14 ~16 ~0 ~14 ~7 stained_glass 4 
setblock ~0 ~14 ~19 stained_glass 4  
fill ~0 ~14 ~20 ~0 ~15 ~20 stained_glass 1 
setblock ~0 ~14 ~21 stained_glass 4 
setblock ~1 ~14 ~6 stained_glass 4 
setblock ~1 ~14 ~16 stained_hardened_clay 4 
setblock ~1 ~14 ~22 stained_glass 4 
setblock ~1 ~14 ~27 stained_glass 4  
fill ~2 ~14 ~5 ~2 ~15 ~5 stained_glass 4  
fill ~2 ~14 ~13 ~2 ~15 ~13 stained_glass 4  
fill ~2 ~14 ~16 ~2 ~16 ~16 stone 0  
fill ~2 ~14 ~17 ~2 ~16 ~17 stone 0  
fill ~2 ~14 ~18 ~2 ~16 ~18 stone 0  
fill ~2 ~14 ~19 ~2 ~16 ~19 stone 0  
fill ~2 ~14 ~20 ~2 ~16 ~20 stone 0  
fill ~2 ~14 ~21 ~2 ~16 ~21 stone 0  
fill ~2 ~14 ~22 ~2 ~16 ~22 stone 0  
fill ~2 ~14 ~23 ~2 ~14 ~24 stained_glass 4  
fill ~3 ~14 ~4 ~3 ~15 ~4 stained_glass 4  
fill ~3 ~14 ~7 ~3 ~15 ~7 stained_glass 4  
fill ~3 ~14 ~13 ~3 ~16 ~13 stone 0  
fill ~3 ~14 ~14 ~3 ~16 ~14 stone 0  
fill ~3 ~14 ~15 ~3 ~16 ~15 stone 0  
fill ~3 ~14 ~23 ~3 ~16 ~23 stone 0  
fill ~3 ~14 ~24 ~3 ~16 ~24 stone 0  
fill ~3 ~14 ~25 ~3 ~16 ~25 stone 0  
fill ~4 ~14 ~3 ~7 ~14 ~3 stained_glass 4  
fill ~4 ~14 ~11 ~4 ~14 ~12 stone 0  
fill ~4 ~14 ~26 ~4 ~14 ~27 stone 0  
fill ~4 ~14 ~30 ~5 ~14 ~30 stained_glass 4  
fill ~4 ~14 ~31 ~4 ~14 ~32 stained_glass 4 
setblock ~5 ~14 ~1 stained_glass 4  
fill ~5 ~14 ~4 ~6 ~14 ~4 stained_glass 4  
fill ~5 ~14 ~5 ~5 ~14 ~1 stained_glass 4  
fill ~5 ~14 ~9 ~6 ~14 ~9 stone 0  
fill ~5 ~14 ~10 ~5 ~14 ~9 stone 0  
fill ~5 ~14 ~28 ~5 ~14 ~29 stone 0 
setblock ~6 ~14 ~0 stained_glass 4  
fill ~6 ~14 ~6 ~6 ~13 ~6 stained_glass 4  
fill ~6 ~14 ~8 ~7 ~14 ~8 stone 0  
fill ~6 ~14 ~30 ~7 ~14 ~30 stone 0  
fill ~8 ~14 ~2 ~9 ~14 ~2 stained_glass 4 
setblock ~8 ~14 ~3 stained_hardened_clay 4  
fill ~8 ~14 ~5 ~8 ~15 ~5 stained_glass 4  
fill ~8 ~14 ~7 ~10 ~14 ~7 stone 0  
fill ~8 ~14 ~31 ~9 ~14 ~31 stone 0  
fill ~8 ~14 ~32 ~9 ~14 ~32 stained_glass 4  
fill ~9 ~14 ~0 ~9 ~15 ~0 stained_glass 4  
fill ~9 ~14 ~33 ~10 ~14 ~33 stained_glass 4  
fill ~10 ~14 ~6 ~23 ~14 ~6 stone 0  
fill ~10 ~14 ~32 ~22 ~14 ~32 stone 0 
setblock ~12 ~14 ~33 stained_glass 1  
fill ~13 ~14 ~1 ~13 ~22 ~1 stained_glass 1  
fill ~13 ~14 ~5 ~19 ~14 ~5 stone 0  
fill ~13 ~14 ~33 ~19 ~14 ~33 stone 0  
fill ~14 ~14 ~0 ~16 ~14 ~0 stained_glass 1  
fill ~16 ~14 ~2 ~19 ~14 ~2 stained_glass 1 
setblock ~16 ~14 ~3 stained_hardened_clay 1 
setblock ~17 ~14 ~1 stained_glass 1 
setblock ~17 ~14 ~4 stained_hardened_clay 1  
fill ~17 ~14 ~34 ~17 ~14 ~35 stained_glass 1  
fill ~19 ~14 ~1 ~19 ~15 ~1 stained_glass 4  
fill ~19 ~14 ~35 ~19 ~14 ~36 stained_glass 1  
fill ~20 ~14 ~3 ~21 ~14 ~3 stained_glass 1  
fill ~20 ~14 ~33 ~22 ~14 ~33 stained_glass 1 
setblock ~21 ~14 ~4 stained_glass 1  
fill ~21 ~14 ~34 ~24 ~14 ~34 stained_glass 1  
fill ~22 ~14 ~2 ~22 ~15 ~2 stained_glass 4  
fill ~22 ~14 ~7 ~25 ~14 ~7 stone 0  
fill ~22 ~14 ~31 ~23 ~14 ~31 stone 0  
fill ~22 ~14 ~35 ~22 ~16 ~35 stained_glass 1  
fill ~23 ~14 ~2 ~23 ~18 ~2 stained_glass 1 
setblock ~23 ~14 ~4 stained_glass 1 
setblock ~23 ~14 ~33 glowstone 0  
fill ~24 ~14 ~30 ~26 ~14 ~30 stone 0  
fill ~24 ~14 ~31 ~29 ~14 ~31 stained_glass 1  
fill ~24 ~14 ~32 ~24 ~14 ~34 stained_glass 1 
setblock ~24 ~14 ~35 stained_glass 4  
fill ~25 ~14 ~2 ~25 ~16 ~2 stained_glass 1  
fill ~25 ~14 ~4 ~26 ~14 ~4 stained_glass 1  
fill ~25 ~14 ~8 ~26 ~14 ~8 stone 0 
setblock ~25 ~14 ~35 stained_glass 1 
setblock ~26 ~14 ~3 stained_glass 1  
fill ~26 ~14 ~5 ~26 ~17 ~5 stained_glass 1  
fill ~26 ~14 ~9 ~27 ~14 ~9 stone 0  
fill ~26 ~14 ~29 ~27 ~14 ~29 stone 0  
fill ~27 ~14 ~6 ~27 ~16 ~6 stained_glass 1 
setblock ~27 ~14 ~8 stained_glass 4  
fill ~27 ~14 ~10 ~28 ~14 ~10 stone 0 
setblock ~27 ~14 ~28 stone 0 
setblock ~27 ~14 ~30 stained_glass 1  
fill ~27 ~14 ~32 ~28 ~14 ~32 stained_glass 1  
fill ~27 ~14 ~34 ~28 ~14 ~34 stained_glass 1  
fill ~28 ~14 ~7 ~28 ~16 ~7 stained_glass 1  
fill ~28 ~14 ~11 ~28 ~14 ~13 stone 0  
fill ~28 ~14 ~26 ~28 ~14 ~27 stone 0  
fill ~28 ~14 ~28 ~28 ~14 ~29 stained_glass 4  
fill ~29 ~14 ~11 ~30 ~14 ~11 stained_glass 4  
fill ~29 ~14 ~13 ~29 ~16 ~13 stone 0  
fill ~29 ~14 ~14 ~29 ~16 ~14 stone 0  
fill ~29 ~14 ~24 ~29 ~16 ~24 stone 0  
fill ~29 ~14 ~25 ~29 ~16 ~25 stone 0  
fill ~29 ~14 ~27 ~30 ~14 ~27 stained_glass 1  
fill ~30 ~14 ~12 ~30 ~15 ~12 stained_glass 4  
fill ~30 ~14 ~13 ~30 ~14 ~11 stained_glass 4  
fill ~30 ~14 ~16 ~30 ~16 ~16 stone 0  
fill ~30 ~14 ~17 ~30 ~16 ~17 stone 0  
fill ~30 ~14 ~18 ~30 ~16 ~18 stone 0  
fill ~30 ~14 ~19 ~30 ~16 ~19 stone 0  
fill ~30 ~14 ~20 ~30 ~16 ~20 stone 0  
fill ~30 ~14 ~21 ~30 ~16 ~21 stone 0  
fill ~30 ~14 ~22 ~30 ~16 ~22 stone 0  
fill ~31 ~14 ~16 ~31 ~15 ~16 stained_glass 4  
fill ~31 ~14 ~17 ~31 ~14 ~22 stained_glass 4  
fill ~32 ~14 ~15 ~32 ~17 ~15 stained_glass 4  
fill ~32 ~14 ~18 ~33 ~14 ~18 stained_glass 4  
fill ~32 ~14 ~19 ~32 ~15 ~19 stained_glass 4  
fill ~32 ~14 ~21 ~32 ~16 ~21 stained_glass 4  
fill ~-2 ~15 ~12 ~1 ~15 ~12 stained_glass 4  
fill ~-2 ~15 ~19 ~-2 ~16 ~19 stained_glass 4  
fill ~-1 ~15 ~17 ~0 ~15 ~17 stained_glass 4  
fill ~-1 ~15 ~19 ~0 ~15 ~19 stained_glass 1  
fill ~-1 ~15 ~20 ~-1 ~16 ~20 stained_glass 1  
fill ~-1 ~15 ~24 ~1 ~15 ~24 stained_glass 4 
setblock ~0 ~15 ~6 stained_glass 4 
setblock ~0 ~15 ~18 stained_glass 4  
fill ~0 ~15 ~25 ~2 ~15 ~25 stained_glass 4  
fill ~0 ~15 ~26 ~0 ~15 ~24 stained_glass 4  
fill ~1 ~15 ~8 ~3 ~15 ~8 stained_glass 4  
fill ~1 ~15 ~10 ~1 ~17 ~10 stained_glass 4  
fill ~1 ~15 ~11 ~1 ~17 ~11 stained_glass 4 
setblock ~1 ~15 ~13 stained_glass 4  
fill ~1 ~15 ~15 ~1 ~15 ~16 stained_glass 4  
fill ~1 ~15 ~17 ~1 ~17 ~17 stone 0  
fill ~1 ~15 ~18 ~1 ~17 ~18 stone 0  
fill ~1 ~15 ~19 ~1 ~17 ~19 stone 0  
fill ~1 ~15 ~20 ~1 ~17 ~20 stone 0  
fill ~1 ~15 ~21 ~1 ~17 ~21 stone 0 
setblock ~2 ~15 ~4 stained_glass 4  
fill ~2 ~15 ~14 ~2 ~16 ~14 stone 0  
fill ~2 ~15 ~15 ~2 ~16 ~15 stone 0  
fill ~2 ~15 ~23 ~2 ~16 ~23 stone 0   
fill ~2 ~15 ~24 ~2 ~16 ~24 stone 0  
fill ~2 ~15 ~26 ~2 ~15 ~28 stained_glass 4  
fill ~3 ~15 ~10 ~4 ~15 ~10 stone 0  
fill ~3 ~15 ~11 ~3 ~16 ~11 stone 0  
fill ~3 ~15 ~12 ~3 ~16 ~12 stone 0  
fill ~3 ~15 ~26 ~3 ~16 ~26 stone 0  
fill ~3 ~15 ~27 ~3 ~16 ~27 stone 0  
fill ~3 ~15 ~28 ~4 ~15 ~28 stone 0  
fill ~4 ~15 ~3 ~7 ~15 ~3 stained_glass 4 
setblock ~4 ~15 ~7 stained_hardened_clay 4 
setblock ~4 ~15 ~9 stone 0  
fill ~4 ~15 ~29 ~5 ~15 ~29 stone 0  
fill ~4 ~15 ~30 ~4 ~14 ~30 stained_glass 4  
fill ~4 ~15 ~32 ~4 ~17 ~32 stained_glass 4  
fill ~5 ~15 ~4 ~5 ~19 ~4 stained_glass 4 
setblock ~5 ~15 ~8 stone 0  
fill ~5 ~15 ~30 ~6 ~15 ~30 stone 0 
setblock ~5 ~15 ~31 stained_glass 4  
fill ~6 ~15 ~7 ~7 ~15 ~7 stone 0  
fill ~6 ~15 ~31 ~7 ~15 ~31 stone 0 
setblock ~6 ~15 ~32 stained_glass 4  
fill ~7 ~15 ~2 ~9 ~15 ~2 stained_glass 4 
setblock ~7 ~15 ~4 stained_glass 4  
fill ~7 ~15 ~6 ~25 ~15 ~6 stone 0  
fill ~7 ~15 ~32 ~25 ~15 ~32 stone 0  
fill ~7 ~15 ~33 ~10 ~15 ~33 stained_glass 4  
fill ~7 ~15 ~34 ~7 ~15 ~33 stained_glass 4 
setblock ~9 ~15 ~-1 stained_glass 4 
setblock ~9 ~15 ~1 stained_glass 1  
fill ~9 ~15 ~34 ~9 ~16 ~34 stained_glass 1 
setblock ~10 ~15 ~1 stained_glass 4  
fill ~10 ~15 ~2 ~10 ~22 ~2 stained_glass 1 
setblock ~11 ~15 ~3 stained_hardened_clay 1  
fill ~11 ~15 ~5 ~21 ~15 ~5 stone 0  
fill ~11 ~15 ~33 ~21 ~15 ~33 stone 0 
setblock ~12 ~15 ~34 stained_glass 1  
fill ~13 ~15 ~0 ~14 ~15 ~0 stained_glass 4  
fill ~14 ~15 ~4 ~18 ~15 ~4 stone 0  
fill ~14 ~15 ~34 ~18 ~15 ~34 stone 0  
fill ~14 ~15 ~35 ~18 ~15 ~35 stained_glass 1  
fill ~15 ~15 ~0 ~16 ~15 ~0 stained_glass 1  
fill ~15 ~15 ~1 ~15 ~21 ~1 stained_glass 1  
fill ~16 ~15 ~2 ~16 ~14 ~2 stained_glass 1  
fill ~16 ~15 ~3 ~16 ~15 ~2 stained_glass 1  
fill ~17 ~15 ~36 ~17 ~16 ~36 stained_glass 1  
fill ~18 ~15 ~3 ~21 ~15 ~3 stained_glass 1 
setblock ~19 ~15 ~4 stained_hardened_clay 1  
fill ~20 ~15 ~34 ~20 ~15 ~35 stained_glass 1 
setblock ~21 ~15 ~1 stained_glass 4 
setblock ~21 ~15 ~2 stained_glass 1  
fill ~22 ~15 ~33 ~22 ~15 ~35 stained_glass 1 
setblock ~23 ~15 ~1 stained_glass 1  
fill ~23 ~15 ~34 ~27 ~15 ~34 stained_glass 1  
fill ~23 ~15 ~35 ~23 ~15 ~34 stained_glass 1  
fill ~24 ~15 ~3 ~25 ~15 ~3 stained_glass 1  
fill ~24 ~15 ~31 ~26 ~15 ~31 stone 0  
fill ~24 ~15 ~33 ~25 ~15 ~33 stained_glass 1  
fill ~25 ~15 ~7 ~26 ~15 ~7 stone 0 
setblock ~25 ~15 ~35 stained_glass 4  
fill ~26 ~15 ~4 ~26 ~16 ~4 stained_glass 1 
setblock ~26 ~15 ~32 stained_glass 4  
fill ~27 ~15 ~8 ~27 ~16 ~8 stone 0 
setblock ~27 ~15 ~30 stone 0  
fill ~27 ~15 ~33 ~27 ~16 ~33 stained_glass 1  
fill ~28 ~15 ~6 ~28 ~18 ~6 stained_glass 1  
fill ~28 ~15 ~8 ~29 ~15 ~8 stained_glass 4  
fill ~28 ~15 ~9 ~28 ~16 ~9 stone 0  
fill ~28 ~15 ~10 ~29 ~15 ~10 stone 0  
fill ~28 ~15 ~28 ~29 ~15 ~28 stone 0  
fill ~28 ~15 ~29 ~28 ~15 ~28 stone 0 
setblock ~28 ~15 ~30 stained_glass 4  
fill ~28 ~15 ~31 ~29 ~15 ~31 stained_glass 1  
fill ~29 ~15 ~7 ~29 ~18 ~7 stained_glass 1  
fill ~29 ~15 ~11 ~29 ~16 ~11 stone 0  
fill ~29 ~15 ~12 ~29 ~16 ~12 stone 0  
fill ~29 ~15 ~26 ~29 ~16 ~26 stone 0  
fill ~29 ~15 ~27 ~29 ~16 ~27 stone 0  
fill ~29 ~15 ~29 ~30 ~15 ~29 stained_glass 1  
fill ~30 ~15 ~10 ~30 ~16 ~10 stained_glass 4  
fill ~30 ~15 ~11 ~31 ~15 ~11 stained_glass 4  
fill ~30 ~15 ~14 ~30 ~16 ~14 stone 0  
fill ~30 ~15 ~15 ~30 ~16 ~15 stone 0  
fill ~30 ~15 ~23 ~30 ~16 ~23 stone 0  
fill ~30 ~15 ~24 ~30 ~16 ~24 stone 0  
fill ~30 ~15 ~26 ~30 ~15 ~30 stained_glass 1  
fill ~30 ~15 ~34 ~30 ~17 ~34 stained_glass 1  
fill ~31 ~15 ~13 ~31 ~16 ~13 stained_glass 4  
fill ~31 ~15 ~14 ~31 ~15 ~16 stained_glass 4  
fill ~31 ~15 ~17 ~31 ~17 ~17 stone 0  
fill ~31 ~15 ~18 ~31 ~16 ~18 stone 0  
fill ~31 ~15 ~19 ~31 ~16 ~19 stone 0  
fill ~31 ~15 ~20 ~31 ~17 ~20 stone 0  
fill ~31 ~15 ~21 ~31 ~16 ~21 stone 0  
fill ~31 ~15 ~23 ~32 ~15 ~23 stained_glass 4  
fill ~31 ~15 ~24 ~32 ~15 ~24 stained_glass 4  
fill ~31 ~15 ~25 ~31 ~16 ~25 stained_glass 4  
fill ~31 ~15 ~26 ~31 ~15 ~22 stained_glass 4 
setblock ~31 ~15 ~30 stained_glass 1  
fill ~32 ~15 ~16 ~32 ~16 ~16 stained_glass 4  
fill ~32 ~15 ~17 ~32 ~16 ~17 stained_glass 4  
fill ~32 ~15 ~20 ~33 ~15 ~20 stained_glass 4  
fill ~32 ~15 ~22 ~32 ~16 ~22 stained_glass 4 
setblock ~33 ~15 ~15 stained_glass 4  
fill ~33 ~15 ~18 ~33 ~16 ~18 stained_glass 4  
fill ~-3 ~16 ~18 ~-2 ~16 ~18 stained_glass 4  
fill ~-2 ~16 ~9 ~-2 ~16 ~12 stained_glass 4  
fill ~-2 ~16 ~17 ~-2 ~17 ~17 stained_glass 4  
fill ~-1 ~16 ~11 ~1 ~16 ~11 stained_glass 4  
fill ~-1 ~16 ~12 ~-1 ~16 ~10 stained_glass 4  
fill ~-1 ~16 ~19 ~-1 ~15 ~19 stained_glass 1 
setblock ~-1 ~16 ~21 stained_glass 4  
fill ~-1 ~16 ~26 ~-1 ~21 ~26 stained_glass 4  
fill ~0 ~16 ~9 ~0 ~21 ~9 stained_glass 4  
fill ~0 ~16 ~13 ~0 ~17 ~13 stained_glass 4 
setblock ~0 ~16 ~16 stained_glass 4  
fill ~0 ~16 ~17 ~0 ~17 ~17 stone 0  
fill ~0 ~16 ~18 ~0 ~17 ~18 stone 0  
fill ~0 ~16 ~19 ~0 ~17 ~19 stone 0  
fill ~0 ~16 ~20 ~0 ~17 ~20 stone 0  
fill ~0 ~16 ~21 ~0 ~17 ~21 stone 0  
fill ~0 ~16 ~23 ~0 ~17 ~23 stained_glass 4  
fill ~0 ~16 ~24 ~0 ~17 ~24 stained_glass 4  
fill ~1 ~16 ~8 ~3 ~16 ~8 stained_glass 4 
setblock ~1 ~16 ~12 stained_glass 4  
fill ~1 ~16 ~15 ~1 ~17 ~15 stone 0  
fill ~1 ~16 ~16 ~1 ~17 ~16 stone 0  
fill ~1 ~16 ~22 ~1 ~17 ~22 stone 0  
fill ~1 ~16 ~23 ~1 ~17 ~23 stone 0  
fill ~1 ~16 ~25 ~1 ~16 ~27 stained_glass 4 
setblock ~2 ~16 ~7 stained_glass 4  
fill ~2 ~16 ~11 ~2 ~17 ~11 stone 0  
fill ~2 ~16 ~12 ~2 ~16 ~27 stone 0  
fill ~2 ~16 ~28 ~2 ~16 ~29 stained_glass 4  
fill ~3 ~16 ~9 ~3 ~16 ~29 stone 0  
fill ~3 ~16 ~30 ~3 ~16 ~31 stained_glass 4 
setblock ~4 ~16 ~8 stone 0  
fill ~4 ~16 ~29 ~4 ~15 ~29 stone 0  
fill ~4 ~16 ~30 ~5 ~16 ~30 stone 0  
fill ~5 ~16 ~1 ~5 ~17 ~1 stained_glass 4  
fill ~5 ~16 ~3 ~5 ~17 ~3 stained_glass 4  
fill ~5 ~16 ~7 ~6 ~16 ~7 stone 0 
setblock ~5 ~16 ~31 stone 0  
fill ~5 ~16 ~32 ~5 ~16 ~33 stained_glass 4  
fill ~6 ~16 ~6 ~26 ~16 ~6 stone 0  
fill ~6 ~16 ~32 ~26 ~16 ~32 stone 0  
fill ~6 ~16 ~33 ~7 ~16 ~33 stained_glass 4  
fill ~6 ~16 ~34 ~6 ~16 ~33 stained_glass 4  
fill ~6 ~16 ~35 ~7 ~16 ~35 stained_glass 1  
fill ~7 ~16 ~0 ~7 ~17 ~0 stained_glass 4  
fill ~7 ~16 ~2 ~9 ~16 ~2 stained_glass 4  
fill ~7 ~16 ~34 ~9 ~16 ~34 stained_glass 1  
fill ~8 ~16 ~3 ~8 ~16 ~4 stained_glass 4  
fill ~8 ~16 ~5 ~25 ~16 ~5 stone 0  
fill ~8 ~16 ~33 ~24 ~16 ~33 stone 0  
fill ~9 ~16 ~1 ~9 ~20 ~1 stained_glass 4 
setblock ~9 ~16 ~3 stained_hardened_clay 4 
setblock ~9 ~16 ~4 stained_glass 4  
fill ~10 ~16 ~0 ~14 ~16 ~0 stained_glass 4 
setblock ~10 ~16 ~34 stained_glass 4 
setblock ~11 ~16 ~1 stained_glass 4 
setblock ~11 ~16 ~35 stained_glass 4  
fill ~11 ~16 ~36 ~12 ~16 ~36 stained_glass 1  
fill ~12 ~16 ~2 ~12 ~18 ~2 stained_glass 1  
fill ~12 ~16 ~4 ~20 ~16 ~4 stone 0  
fill ~12 ~16 ~34 ~20 ~16 ~34 stone 0  
fill ~12 ~16 ~35 ~14 ~16 ~35 stained_glass 1  
fill ~15 ~16 ~0 ~17 ~16 ~0 stained_glass 1  
fill ~15 ~16 ~3 ~17 ~16 ~3 stone 0  
fill ~15 ~16 ~35 ~17 ~16 ~35 stone 0  
fill ~15 ~16 ~36 ~18 ~16 ~36 stained_glass 1  
fill ~15 ~16 ~37 ~15 ~24 ~37 stained_glass 1  
fill ~16 ~16 ~1 ~16 ~23 ~1 stained_glass 1  
fill ~17 ~16 ~2 ~20 ~16 ~2 stained_glass 1  
fill ~18 ~16 ~3 ~18 ~15 ~3 stained_glass 1  
fill ~18 ~16 ~35 ~19 ~16 ~35 stained_glass 4 
setblock ~19 ~16 ~0 stained_glass 4  
fill ~19 ~16 ~1 ~20 ~16 ~1 stained_glass 1  
fill ~20 ~16 ~3 ~26 ~16 ~3 stained_glass 1  
fill ~20 ~16 ~35 ~22 ~16 ~35 stained_glass 1  
fill ~21 ~16 ~34 ~26 ~16 ~34 stained_glass 1  
fill ~21 ~16 ~36 ~22 ~16 ~36 stained_glass 1 
setblock ~22 ~16 ~2 stained_glass 1  
fill ~24 ~16 ~0 ~24 ~16 ~3 stained_glass 1  
fill ~25 ~16 ~4 ~25 ~17 ~4 stained_glass 1 
setblock ~26 ~16 ~33 stained_glass 1  
fill ~26 ~16 ~35 ~27 ~16 ~35 stained_glass 1 
setblock ~26 ~16 ~36 stained_glass 4  
fill ~27 ~16 ~7 ~27 ~18 ~7 stone 0 
setblock ~27 ~16 ~31 stone 0  
fill ~27 ~16 ~32 ~28 ~16 ~32 stained_glass 1  
fill ~28 ~16 ~8 ~28 ~18 ~8 stone 0 
setblock ~28 ~16 ~30 stone 0 
setblock ~28 ~16 ~31 stained_glass 4 
setblock ~29 ~16 ~8 stained_glass 4  
fill ~29 ~16 ~9 ~29 ~18 ~9 stone 0  
fill ~29 ~16 ~10 ~29 ~16 ~9 stone 0  
fill ~29 ~16 ~28 ~29 ~16 ~29 stone 0  
fill ~29 ~16 ~30 ~30 ~16 ~30 stained_glass 1  
fill ~29 ~16 ~31 ~31 ~16 ~31 stained_glass 1  
fill ~30 ~16 ~7 ~30 ~19 ~7 stained_glass 1 
setblock ~30 ~16 ~9 stained_glass 4  
fill ~30 ~16 ~11 ~30 ~18 ~11 stone 0  
fill ~30 ~16 ~12 ~30 ~16 ~27 stone 0 
setblock ~30 ~16 ~28 glowstone 0 
setblock ~30 ~16 ~29 stained_glass 1  
fill ~30 ~16 ~33 ~30 ~18 ~33 stained_glass 1  
fill ~31 ~16 ~10 ~31 ~17 ~10 stained_glass 1  
fill ~31 ~16 ~11 ~31 ~16 ~13 stained_glass 4  
fill ~31 ~16 ~15 ~31 ~17 ~15 stone 0  
fill ~31 ~16 ~16 ~31 ~17 ~16 stone 0  
fill ~31 ~16 ~22 ~31 ~17 ~22 stone 0  
fill ~31 ~16 ~23 ~31 ~17 ~23 stone 0  
fill ~31 ~16 ~24 ~32 ~16 ~24 stained_glass 4  
fill ~31 ~16 ~26 ~31 ~16 ~28 stained_glass 1  
fill ~32 ~16 ~14 ~33 ~16 ~14 stained_glass 4  
fill ~32 ~16 ~18 ~32 ~17 ~18 stone 0  
fill ~32 ~16 ~19 ~32 ~17 ~19 stone 0  
fill ~32 ~16 ~20 ~32 ~17 ~20 stone 0 
setblock ~33 ~16 ~17 stained_glass 4  
fill ~33 ~16 ~19 ~33 ~16 ~23 stained_glass 4 
setblock ~34 ~16 ~22 stained_glass 4 
setblock ~-3 ~17 ~17 stained_glass 1  
fill ~-2 ~17 ~10 ~-2 ~18 ~10 stained_glass 4  
fill ~-2 ~17 ~16 ~-1 ~17 ~16 stained_glass 1  
fill ~-2 ~17 ~18 ~-2 ~18 ~18 stained_glass 1  
fill ~-2 ~17 ~19 ~-2 ~21 ~19 stained_glass 1  
fill ~-2 ~17 ~20 ~-2 ~17 ~21 stained_glass 4  
fill ~-2 ~17 ~23 ~0 ~17 ~23 stained_glass 4 
setblock ~-2 ~17 ~26 stained_glass 4  
fill ~-1 ~17 ~17 ~-1 ~23 ~17 stone 0  
fill ~-1 ~17 ~18 ~-1 ~23 ~18 stone 0  
fill ~-1 ~17 ~19 ~-1 ~23 ~19 stone 0  
fill ~-1 ~17 ~20 ~-1 ~23 ~20 stone 0  
fill ~-1 ~17 ~21 ~-1 ~23 ~21 stone 0  
fill ~0 ~17 ~8 ~2 ~17 ~8 stained_glass 4 
setblock ~0 ~17 ~11 stained_glass 4  
fill ~0 ~17 ~16 ~0 ~18 ~16 stone 0  
fill ~0 ~17 ~22 ~0 ~18 ~22 stone 0 
setblock ~0 ~17 ~25 stained_glass 4  
fill ~1 ~17 ~12 ~1 ~18 ~12 stone 0  
fill ~1 ~17 ~13 ~1 ~17 ~26 stone 0  
fill ~1 ~17 ~27 ~1 ~17 ~31 stained_glass 4  
fill ~2 ~17 ~4 ~2 ~17 ~6 stained_glass 4  
fill ~2 ~17 ~9 ~2 ~22 ~9 stone 0  
fill ~2 ~17 ~10 ~2 ~18 ~10 stone 0  
fill ~2 ~17 ~27 ~2 ~17 ~29 stone 0  
fill ~2 ~17 ~30 ~2 ~18 ~30 stained_glass 4  
fill ~2 ~17 ~31 ~2 ~21 ~31 stained_glass 4  
fill ~2 ~17 ~32 ~4 ~17 ~32 stained_glass 4  
fill ~3 ~17 ~8 ~3 ~23 ~8 stone 0  
fill ~3 ~17 ~30 ~3 ~23 ~30 stone 0 
setblock ~4 ~17 ~6 stained_hardened_clay 4  
fill ~4 ~17 ~7 ~4 ~23 ~7 stone 0  
fill ~4 ~17 ~31 ~4 ~23 ~31 stone 0  
fill ~5 ~17 ~5 ~5 ~20 ~5 stained_glass 4  
fill ~5 ~17 ~6 ~5 ~23 ~6 stone 0 
setblock ~5 ~17 ~32 stone 0  
fill ~5 ~17 ~33 ~5 ~17 ~34 stained_glass 4 
setblock ~6 ~17 ~1 stained_glass 4  
fill ~6 ~17 ~4 ~8 ~17 ~4 stained_glass 4  
fill ~6 ~17 ~5 ~8 ~17 ~5 stone 0  
fill ~6 ~17 ~33 ~9 ~17 ~33 stone 0  
fill ~6 ~17 ~34 ~8 ~17 ~34 stained_glass 1 
setblock ~7 ~17 ~-1 stained_glass 4  
fill ~7 ~17 ~2 ~8 ~17 ~2 stained_glass 4  
fill ~7 ~17 ~36 ~7 ~19 ~36 stained_glass 1  
fill ~8 ~17 ~35 ~10 ~17 ~35 stained_glass 1  
fill ~9 ~17 ~-1 ~9 ~17 ~1 stained_glass 4  
fill ~9 ~17 ~4 ~24 ~17 ~4 stone 0  
fill ~9 ~17 ~34 ~23 ~17 ~34 stone 0  
fill ~9 ~17 ~36 ~9 ~21 ~36 stained_glass 1 
setblock ~10 ~17 ~3 stained_hardened_clay 1  
fill ~11 ~17 ~36 ~11 ~22 ~36 stained_glass 1  
fill ~12 ~17 ~35 ~12 ~16 ~35 stained_glass 1  
fill ~13 ~17 ~0 ~14 ~17 ~0 stained_glass 4  
fill ~13 ~17 ~3 ~19 ~17 ~3 stone 0  
fill ~13 ~17 ~35 ~19 ~17 ~35 stone 0  
fill ~13 ~17 ~36 ~13 ~17 ~37 stained_glass 1  
fill ~14 ~17 ~1 ~14 ~19 ~1 stained_glass 1  
fill ~14 ~17 ~2 ~18 ~17 ~2 stone 0  
fill ~14 ~17 ~36 ~18 ~17 ~36 stone 0  
fill ~14 ~17 ~37 ~14 ~23 ~37 stained_glass 1  
fill ~15 ~17 ~0 ~15 ~19 ~0 stained_glass 1  
fill ~16 ~17 ~37 ~18 ~17 ~37 stained_glass 1  
fill ~16 ~17 ~38 ~16 ~17 ~37 stained_glass 1  
fill ~17 ~17 ~0 ~18 ~17 ~0 stained_glass 1  
fill ~17 ~17 ~1 ~18 ~17 ~1 stained_glass 1 
setblock ~19 ~17 ~36 stained_glass 4 
setblock ~20 ~17 ~0 stained_glass 4  
fill ~20 ~17 ~1 ~21 ~17 ~1 stained_glass 1  
fill ~20 ~17 ~35 ~20 ~15 ~35 stained_glass 1  
fill ~20 ~17 ~36 ~20 ~18 ~36 stained_glass 1  
fill ~21 ~17 ~2 ~21 ~22 ~2 stained_glass 1  
fill ~21 ~17 ~3 ~24 ~17 ~3 stained_glass 1 
setblock ~22 ~17 ~35 stained_glass 4  
fill ~22 ~17 ~36 ~26 ~17 ~36 stained_glass 1  
fill ~22 ~17 ~37 ~23 ~17 ~37 stained_glass 1  
fill ~23 ~17 ~0 ~23 ~17 ~1 stained_glass 4  
fill ~23 ~17 ~35 ~23 ~18 ~35 stained_glass 1  
fill ~24 ~17 ~2 ~24 ~22 ~2 stained_glass 1  
fill ~24 ~17 ~33 ~26 ~17 ~33 stone 0  
fill ~24 ~17 ~34 ~25 ~17 ~34 stained_glass 1  
fill ~25 ~17 ~5 ~25 ~18 ~5 stone 0  
fill ~25 ~17 ~35 ~25 ~19 ~35 stained_glass 1  
fill ~26 ~17 ~6 ~27 ~17 ~6 stone 0  
fill ~27 ~17 ~5 ~27 ~23 ~5 stained_glass 1  
fill ~27 ~17 ~32 ~27 ~23 ~32 stone 0 
setblock ~27 ~17 ~33 stained_glass 4  
fill ~27 ~17 ~34 ~30 ~17 ~34 stained_glass 1  
fill ~27 ~17 ~35 ~27 ~19 ~35 stained_glass 1  
fill ~28 ~17 ~7 ~28 ~23 ~7 stone 0  
fill ~28 ~17 ~31 ~28 ~23 ~31 stone 0 
setblock ~28 ~17 ~32 stained_glass 4  
fill ~28 ~17 ~33 ~31 ~17 ~33 stained_glass 1 
setblock ~28 ~17 ~35 stained_glass 4  
fill ~29 ~17 ~8 ~29 ~23 ~8 stone 0  
fill ~29 ~17 ~30 ~29 ~23 ~30 stone 0  
fill ~29 ~17 ~31 ~32 ~17 ~31 stained_glass 1  
fill ~29 ~17 ~32 ~29 ~19 ~32 stained_glass 1  
fill ~29 ~17 ~38 ~29 ~19 ~38 stained_glass 1  
fill ~29 ~17 ~39 ~29 ~17 ~38 stained_glass 1  
fill ~30 ~17 ~8 ~31 ~17 ~8 stained_glass 4  
fill ~30 ~17 ~10 ~30 ~18 ~10 stone 0  
fill ~30 ~17 ~26 ~31 ~17 ~26 stone 0  
fill ~30 ~17 ~27 ~30 ~18 ~27 stone 0  
fill ~30 ~17 ~28 ~30 ~18 ~28 stone 0  
fill ~30 ~17 ~29 ~30 ~23 ~29 stone 0  
fill ~30 ~17 ~30 ~30 ~19 ~30 stained_glass 1 
setblock ~31 ~17 ~9 stained_glass 4  
fill ~31 ~17 ~12 ~31 ~18 ~12 stone 0  
fill ~31 ~17 ~13 ~31 ~17 ~17 stone 0  
fill ~31 ~17 ~24 ~31 ~17 ~26 stone 0  
fill ~31 ~17 ~27 ~31 ~17 ~29 stained_glass 1  
fill ~31 ~17 ~32 ~33 ~17 ~32 stained_glass 1  
fill ~32 ~17 ~11 ~32 ~18 ~11 stained_glass 1  
fill ~32 ~17 ~12 ~32 ~18 ~12 stained_glass 4  
fill ~32 ~17 ~13 ~32 ~17 ~15 stained_glass 4  
fill ~32 ~17 ~16 ~32 ~18 ~16 stone 0  
fill ~32 ~17 ~17 ~33 ~17 ~17 stone 0  
fill ~32 ~17 ~21 ~33 ~17 ~21 stone 0  
fill ~32 ~17 ~22 ~32 ~18 ~22 stone 0  
fill ~32 ~17 ~23 ~34 ~17 ~23 stained_glass 4  
fill ~32 ~17 ~24 ~32 ~17 ~26 stained_glass 4 
setblock ~32 ~17 ~28 stained_glass 1  
fill ~33 ~17 ~14 ~33 ~17 ~16 stained_glass 4  
fill ~33 ~17 ~18 ~33 ~23 ~18 stone 0  
fill ~33 ~17 ~19 ~33 ~23 ~19 stone 0  
fill ~33 ~17 ~20 ~33 ~23 ~20 stone 0 
setblock ~33 ~17 ~26 stained_glass 1  
fill ~34 ~17 ~17 ~34 ~18 ~17 stained_glass 4  
fill ~34 ~17 ~18 ~36 ~17 ~18 stained_glass 4  
fill ~34 ~17 ~19 ~34 ~21 ~19 stained_glass 4  
fill ~34 ~17 ~20 ~35 ~17 ~20 stained_glass 4  
fill ~34 ~17 ~21 ~34 ~17 ~17 stained_glass 4  
fill ~-3 ~18 ~11 ~-2 ~18 ~11 stained_glass 4 
setblock ~-3 ~18 ~18 stained_glass 1  
fill ~-2 ~18 ~12 ~0 ~18 ~12 stained_glass 4  
fill ~-2 ~18 ~14 ~-1 ~18 ~14 stained_glass 4  
fill ~-2 ~18 ~15 ~-1 ~18 ~15 stained_glass 4  
fill ~-2 ~18 ~16 ~-2 ~20 ~16 stained_glass 1  
fill ~-2 ~18 ~17 ~-2 ~22 ~17 stained_glass 1  
fill ~-2 ~18 ~20 ~-2 ~20 ~20 stained_glass 1  
fill ~-2 ~18 ~21 ~-2 ~19 ~21 stained_glass 4  
fill ~-2 ~18 ~22 ~-2 ~19 ~22 stained_glass 1  
fill ~-2 ~18 ~23 ~-1 ~18 ~23 stained_glass 4  
fill ~-1 ~18 ~13 ~-1 ~20 ~13 stained_glass 4  
fill ~-1 ~18 ~16 ~-1 ~22 ~16 stone 0  
fill ~-1 ~18 ~22 ~-1 ~22 ~22 stone 0  
fill ~-1 ~18 ~24 ~-1 ~20 ~24 stained_glass 1  
fill ~-1 ~18 ~25 ~-1 ~22 ~25 stained_glass 1  
fill ~-1 ~18 ~27 ~0 ~18 ~27 stained_glass 4  
fill ~0 ~18 ~13 ~0 ~22 ~13 stone 0  
fill ~0 ~18 ~14 ~0 ~22 ~14 stone 0  
fill ~0 ~18 ~15 ~0 ~22 ~15 stone 0  
fill ~0 ~18 ~23 ~0 ~22 ~23 stone 0  
fill ~0 ~18 ~24 ~0 ~22 ~24 stone 0  
fill ~0 ~18 ~25 ~0 ~22 ~25 stone 0 
setblock ~0 ~18 ~26 stained_glass 4  
fill ~0 ~18 ~29 ~1 ~18 ~29 stained_glass 4  
fill ~1 ~18 ~8 ~2 ~18 ~8 stained_glass 4  
fill ~1 ~18 ~10 ~1 ~22 ~10 stone 0  
fill ~1 ~18 ~11 ~1 ~18 ~10 stone 0  
fill ~1 ~18 ~26 ~1 ~18 ~28 stone 0  
fill ~2 ~18 ~6 ~2 ~18 ~8 stained_glass 4  
fill ~2 ~18 ~28 ~2 ~18 ~29 stone 0 
setblock ~3 ~18 ~7 stained_glass 4  
fill ~3 ~18 ~32 ~3 ~22 ~32 stained_glass 4  
fill ~3 ~18 ~33 ~4 ~18 ~33 stained_glass 4  
fill ~4 ~18 ~4 ~4 ~19 ~4 stained_glass 4  
fill ~4 ~18 ~32 ~4 ~22 ~32 stone 0  
fill ~5 ~18 ~33 ~9 ~18 ~33 stone 0  
fill ~5 ~18 ~34 ~5 ~19 ~34 stained_glass 4  
fill ~6 ~18 ~3 ~7 ~18 ~3 stained_glass 4  
fill ~6 ~18 ~4 ~6 ~20 ~4 stained_glass 4  
fill ~6 ~18 ~5 ~7 ~18 ~5 stone 0  
fill ~6 ~18 ~34 ~6 ~24 ~34 stained_glass 1  
fill ~7 ~18 ~2 ~8 ~18 ~2 stained_glass 4  
fill ~7 ~18 ~4 ~9 ~18 ~4 stone 0  
fill ~7 ~18 ~34 ~9 ~18 ~34 stone 0 
setblock ~8 ~18 ~35 glowstone 0  
fill ~8 ~18 ~36 ~8 ~19 ~36 stained_glass 1 
setblock ~9 ~18 ~0 stained_glass 4 
setblock ~9 ~18 ~35 stained_glass 1  
fill ~10 ~18 ~1 ~10 ~19 ~1 stained_glass 4  
fill ~10 ~18 ~3 ~13 ~18 ~3 stone 0  
fill ~10 ~18 ~35 ~13 ~18 ~35 stone 0  
fill ~10 ~18 ~36 ~10 ~20 ~36 stained_glass 1  
fill ~11 ~18 ~0 ~11 ~18 ~2 stained_glass 1  
fill ~12 ~18 ~1 ~12 ~21 ~1 stained_glass 1 
setblock ~12 ~18 ~36 stained_glass 1  
fill ~13 ~18 ~2 ~19 ~18 ~2 stone 0  
fill ~13 ~18 ~36 ~19 ~18 ~36 stone 0  
fill ~13 ~18 ~37 ~13 ~22 ~37 stained_glass 1  
fill ~16 ~18 ~37 ~19 ~18 ~37 stained_glass 1  
fill ~17 ~18 ~-1 ~17 ~18 ~0 stained_glass 1  
fill ~17 ~18 ~38 ~18 ~18 ~38 stained_glass 1  
fill ~18 ~18 ~0 ~18 ~18 ~1 stained_glass 1  
fill ~18 ~18 ~3 ~22 ~18 ~3 stone 0  
fill ~19 ~18 ~1 ~20 ~18 ~1 stained_glass 1  
fill ~19 ~18 ~35 ~22 ~18 ~35 stone 0  
fill ~20 ~18 ~0 ~21 ~18 ~0 stained_glass 1 
setblock ~20 ~18 ~37 stained_glass 4 
setblock ~21 ~18 ~-1 stained_glass 4  
fill ~21 ~18 ~36 ~27 ~18 ~36 stained_glass 1  
fill ~21 ~18 ~37 ~23 ~18 ~37 stained_glass 1  
fill ~22 ~18 ~2 ~22 ~23 ~2 stained_glass 1  
fill ~23 ~18 ~1 ~24 ~18 ~1 stained_glass 1  
fill ~23 ~18 ~4 ~25 ~18 ~4 stone 0  
fill ~23 ~18 ~34 ~24 ~18 ~34 stone 0 
setblock ~23 ~18 ~38 stained_glass 1  
fill ~24 ~18 ~33 ~26 ~18 ~33 stone 0 
setblock ~24 ~18 ~35 stained_glass 1 
setblock ~25 ~18 ~3 stained_glass 4  
fill ~25 ~18 ~34 ~26 ~18 ~34 stained_glass 1  
fill ~25 ~18 ~37 ~26 ~18 ~37 stained_glass 1  
fill ~26 ~18 ~4 ~26 ~19 ~4 stained_glass 1  
fill ~26 ~18 ~5 ~26 ~22 ~5 stone 0  
fill ~26 ~18 ~35 ~26 ~19 ~35 stained_glass 1  
fill ~26 ~18 ~39 ~26 ~22 ~39 stained_glass 1 
setblock ~27 ~18 ~4 stained_glass 4  
fill ~27 ~18 ~6 ~27 ~23 ~6 stone 0  
fill ~27 ~18 ~33 ~30 ~18 ~33 stained_glass 1  
fill ~28 ~18 ~5 ~28 ~22 ~5 stained_glass 1 
setblock ~28 ~18 ~32 stained_glass 1  
fill ~28 ~18 ~34 ~29 ~18 ~34 stained_glass 1 
setblock ~29 ~18 ~5 stained_glass 4  
fill ~29 ~18 ~31 ~29 ~14 ~31 stained_glass 1  
fill ~29 ~18 ~37 ~29 ~22 ~37 stained_glass 1  
fill ~30 ~18 ~8 ~30 ~17 ~8 stained_glass 4  
fill ~30 ~18 ~9 ~30 ~22 ~9 stone 0  
fill ~30 ~18 ~26 ~31 ~18 ~26 stone 0  
fill ~30 ~18 ~32 ~31 ~18 ~32 stained_glass 1  
fill ~31 ~18 ~7 ~31 ~19 ~7 stained_glass 4  
fill ~31 ~18 ~9 ~31 ~23 ~9 stained_glass 1  
fill ~31 ~18 ~10 ~31 ~22 ~10 stone 0  
fill ~31 ~18 ~11 ~31 ~18 ~10 stone 0  
fill ~31 ~18 ~27 ~31 ~18 ~28 stone 0  
fill ~31 ~18 ~30 ~34 ~18 ~30 stained_glass 1  
fill ~32 ~18 ~10 ~32 ~22 ~10 stained_glass 1  
fill ~32 ~18 ~13 ~32 ~22 ~13 stone 0  
fill ~32 ~18 ~14 ~32 ~22 ~14 stone 0  
fill ~32 ~18 ~15 ~32 ~22 ~15 stone 0  
fill ~32 ~18 ~23 ~32 ~22 ~23 stone 0  
fill ~32 ~18 ~24 ~32 ~22 ~24 stone 0  
fill ~32 ~18 ~25 ~32 ~22 ~25 stone 0  
fill ~32 ~18 ~27 ~32 ~18 ~29 stained_glass 4  
fill ~32 ~18 ~34 ~32 ~21 ~34 stained_glass 1  
fill ~33 ~18 ~11 ~33 ~20 ~11 stained_glass 1  
fill ~33 ~18 ~13 ~34 ~18 ~13 stained_glass 4  
fill ~33 ~18 ~15 ~34 ~18 ~15 stained_glass 4  
fill ~33 ~18 ~16 ~33 ~22 ~16 stone 0  
fill ~33 ~18 ~17 ~33 ~23 ~17 stone 0  
fill ~33 ~18 ~21 ~33 ~23 ~21 stone 0  
fill ~33 ~18 ~22 ~33 ~22 ~22 stone 0  
fill ~33 ~18 ~23 ~36 ~18 ~23 stained_glass 4  
fill ~33 ~18 ~24 ~33 ~18 ~25 stained_glass 4  
fill ~33 ~18 ~29 ~33 ~19 ~29 stained_glass 1 
setblock ~34 ~18 ~16 stained_glass 4  
fill ~34 ~18 ~22 ~35 ~18 ~22 stained_glass 4 
setblock ~34 ~18 ~24 stained_glass 1  
fill ~34 ~18 ~25 ~34 ~19 ~25 stained_glass 4  
fill ~34 ~18 ~28 ~35 ~18 ~28 stained_glass 1  
fill ~35 ~18 ~17 ~35 ~19 ~17 stained_glass 4  
fill ~35 ~18 ~20 ~35 ~19 ~20 stained_glass 4  
fill ~35 ~18 ~21 ~35 ~19 ~21 stained_glass 4 
setblock ~35 ~18 ~24 stained_glass 4  
fill ~35 ~18 ~27 ~36 ~18 ~27 stained_glass 1 
setblock ~-3 ~19 ~18 stained_glass 4 
setblock ~-3 ~19 ~19 stained_glass 1  
fill ~-2 ~19 ~14 ~-1 ~19 ~14 stained_glass 4 
setblock ~-2 ~19 ~15 stained_glass 1 
setblock ~-2 ~19 ~18 glowstone 0 
setblock ~-2 ~19 ~23 stained_glass 1 
setblock ~-2 ~19 ~26 stained_glass 4  
fill ~-2 ~19 ~28 ~0 ~19 ~28 stained_glass 4 
setblock ~-1 ~19 ~9 stained_glass 4  
fill ~-1 ~19 ~11 ~-1 ~21 ~11 stained_glass 4  
fill ~-1 ~19 ~12 ~-1 ~19 ~11 stained_glass 4  
fill ~-1 ~19 ~15 ~-1 ~21 ~15 stone 0  
fill ~-1 ~19 ~23 ~-1 ~21 ~23 stone 0  
fill ~0 ~19 ~11 ~0 ~21 ~11 stone 0  
fill ~0 ~19 ~12 ~0 ~21 ~12 stone 0  
fill ~0 ~19 ~26 ~0 ~21 ~26 stone 0  
fill ~0 ~19 ~27 ~0 ~21 ~27 stone 0  
fill ~0 ~19 ~29 ~0 ~21 ~29 stained_glass 4  
fill ~1 ~19 ~8 ~2 ~19 ~8 stained_glass 4  
fill ~1 ~19 ~9 ~1 ~20 ~9 stained_glass 4  
fill ~1 ~19 ~28 ~1 ~22 ~28 stone 0  
fill ~1 ~19 ~30 ~1 ~23 ~30 stained_glass 4  
fill ~1 ~19 ~31 ~1 ~19 ~30 stained_glass 4  
fill ~2 ~19 ~7 ~2 ~21 ~7 stained_glass 4  
fill ~2 ~19 ~29 ~2 ~23 ~29 stone 0  
fill ~2 ~19 ~30 ~2 ~21 ~30 stone 0  
fill ~3 ~19 ~7 ~3 ~21 ~7 stone 0  
fill ~3 ~19 ~31 ~3 ~21 ~31 stone 0  
fill ~3 ~19 ~33 ~3 ~20 ~33 stained_glass 4  
fill ~4 ~19 ~6 ~4 ~21 ~6 stone 0 
setblock ~4 ~19 ~33 stained_glass 1  
fill ~5 ~19 ~33 ~6 ~19 ~33 stone 0  
fill ~6 ~19 ~5 ~6 ~22 ~5 stone 0  
fill ~7 ~19 ~2 ~9 ~19 ~2 stained_glass 4  
fill ~7 ~19 ~3 ~7 ~21 ~3 stained_glass 4  
fill ~7 ~19 ~4 ~7 ~22 ~4 stone 0  
fill ~7 ~19 ~34 ~7 ~22 ~34 stone 0  
fill ~7 ~19 ~35 ~7 ~23 ~35 stained_glass 1  
fill ~8 ~19 ~3 ~12 ~19 ~3 stone 0  
fill ~8 ~19 ~35 ~12 ~19 ~35 stone 0 
setblock ~8 ~19 ~37 stained_glass 1 
setblock ~10 ~19 ~37 stained_glass 1  
fill ~11 ~19 ~1 ~11 ~20 ~1 stained_glass 1  
fill ~12 ~19 ~2 ~20 ~19 ~2 stone 0  
fill ~12 ~19 ~36 ~20 ~19 ~36 stone 0  
fill ~12 ~19 ~37 ~12 ~23 ~37 stained_glass 1 
setblock ~13 ~19 ~38 stained_glass 4 
setblock ~14 ~19 ~0 stained_glass 1  
fill ~14 ~19 ~38 ~22 ~19 ~38 stained_glass 1 
setblock ~15 ~19 ~39 stained_glass 4  
fill ~16 ~19 ~37 ~29 ~19 ~37 stained_glass 1  
fill ~16 ~19 ~39 ~16 ~21 ~39 stained_glass 1  
fill ~17 ~19 ~1 ~17 ~23 ~1 stained_glass 1 
setblock ~18 ~19 ~1 stained_glass 4  
fill ~19 ~19 ~1 ~20 ~19 ~1 stained_glass 1 
setblock ~20 ~19 ~0 stained_glass 4  
fill ~20 ~19 ~3 ~24 ~19 ~3 stone 0  
fill ~20 ~19 ~35 ~24 ~19 ~35 stone 0  
fill ~20 ~19 ~39 ~20 ~20 ~39 stained_glass 1  
fill ~21 ~19 ~36 ~22 ~19 ~36 stained_glass 1  
fill ~23 ~19 ~0 ~23 ~19 ~1 stained_glass 1 
setblock ~24 ~19 ~0 stained_glass 4 
setblock ~24 ~19 ~36 stained_glass 1  
fill ~24 ~19 ~38 ~26 ~19 ~38 stained_glass 1  
fill ~25 ~19 ~3 ~26 ~19 ~3 stained_glass 1  
fill ~25 ~19 ~4 ~25 ~22 ~4 stone 0  
fill ~25 ~19 ~34 ~25 ~21 ~34 stone 0  
fill ~25 ~19 ~39 ~25 ~21 ~39 stained_glass 1 
setblock ~26 ~19 ~2 stained_glass 1  
fill ~26 ~19 ~33 ~26 ~23 ~33 stone 0 
setblock ~26 ~19 ~34 stained_glass 1 
setblock ~26 ~19 ~36 stained_hardened_clay 1 
setblock ~27 ~19 ~3 stained_glass 4 
setblock ~27 ~19 ~4 stained_glass 1  
fill ~27 ~19 ~33 ~29 ~19 ~33 stained_glass 1  
fill ~27 ~19 ~36 ~29 ~19 ~36 stained_glass 1  
fill ~28 ~19 ~6 ~28 ~21 ~6 stone 0  
fill ~28 ~19 ~32 ~28 ~21 ~32 stone 0  
fill ~28 ~19 ~34 ~28 ~22 ~34 stained_glass 1  
fill ~28 ~19 ~35 ~28 ~22 ~35 stained_glass 1  
fill ~28 ~19 ~38 ~28 ~22 ~38 stained_glass 1  
fill ~29 ~19 ~6 ~29 ~20 ~6 stained_glass 1  
fill ~29 ~19 ~7 ~29 ~21 ~7 stone 0  
fill ~29 ~19 ~31 ~29 ~21 ~31 stone 0 
setblock ~29 ~19 ~34 stained_glass 4 
setblock ~30 ~19 ~6 stained_glass 4  
fill ~30 ~19 ~8 ~30 ~21 ~8 stained_glass 1  
fill ~30 ~19 ~31 ~30 ~20 ~31 stained_glass 1  
fill ~30 ~19 ~32 ~31 ~19 ~32 stained_glass 1  
fill ~31 ~19 ~28 ~31 ~22 ~28 stone 0 
setblock ~31 ~19 ~29 stained_glass 4  
fill ~31 ~19 ~34 ~31 ~21 ~34 stained_glass 1  
fill ~32 ~19 ~11 ~32 ~21 ~11 stone 0  
fill ~32 ~19 ~12 ~32 ~21 ~12 stone 0  
fill ~32 ~19 ~26 ~32 ~21 ~26 stone 0  
fill ~32 ~19 ~27 ~32 ~21 ~27 stone 0  
fill ~32 ~19 ~28 ~35 ~19 ~28 stained_glass 1  
fill ~32 ~19 ~30 ~33 ~19 ~30 stained_glass 1  
fill ~32 ~19 ~31 ~33 ~19 ~31 stained_glass 1  
fill ~32 ~19 ~35 ~32 ~20 ~35 stained_glass 1  
fill ~33 ~19 ~12 ~33 ~21 ~12 stained_glass 4  
fill ~33 ~19 ~13 ~33 ~22 ~13 stained_glass 4  
fill ~33 ~19 ~14 ~34 ~19 ~14 stained_glass 4  
fill ~33 ~19 ~15 ~33 ~21 ~15 stone 0  
fill ~33 ~19 ~23 ~33 ~21 ~23 stone 0 
setblock ~33 ~19 ~25 stained_glass 1  
fill ~33 ~19 ~26 ~33 ~19 ~27 stained_glass 4  
fill ~33 ~19 ~39 ~33 ~20 ~39 stained_glass 14  
fill ~34 ~19 ~15 ~34 ~21 ~15 stained_glass 4  
fill ~34 ~19 ~18 ~35 ~19 ~18 stained_glass 4  
fill ~34 ~19 ~20 ~34 ~21 ~20 stained_glass 4  
fill ~34 ~19 ~21 ~34 ~21 ~21 stained_glass 4  
fill ~34 ~19 ~22 ~34 ~20 ~22 stained_glass 4  
fill ~34 ~19 ~26 ~34 ~21 ~26 stained_glass 1  
fill ~34 ~19 ~27 ~35 ~19 ~27 stained_glass 1  
fill ~34 ~19 ~29 ~34 ~23 ~29 stained_glass 1 
setblock ~35 ~19 ~16 stained_glass 4 
setblock ~35 ~19 ~23 stained_glass 4  
fill ~-3 ~20 ~22 ~-2 ~20 ~22 stained_glass 4 
setblock ~-2 ~20 ~11 stained_glass 4  
fill ~-2 ~20 ~14 ~-1 ~20 ~14 stained_glass 4  
fill ~-2 ~20 ~15 ~-2 ~20 ~14 stained_glass 4  
fill ~-2 ~20 ~18 ~-2 ~22 ~18 stained_glass 1 
setblock ~-2 ~20 ~21 stained_glass 1  
fill ~-2 ~20 ~23 ~-2 ~21 ~23 stained_glass 4  
fill ~-1 ~20 ~27 ~-1 ~21 ~27 stained_glass 4 
setblock ~-1 ~20 ~28 stained_glass 1 
setblock ~0 ~20 ~28 glowstone 0  
fill ~1 ~20 ~29 ~1 ~23 ~29 stained_glass 4 
setblock ~2 ~20 ~8 stained_glass 4  
fill ~4 ~20 ~33 ~4 ~22 ~33 stained_glass 4  
fill ~5 ~20 ~3 ~7 ~20 ~3 stained_glass 4  
fill ~5 ~20 ~33 ~6 ~20 ~33 stone 0 
setblock ~5 ~20 ~34 stained_glass 1 
setblock ~6 ~20 ~2 stained_glass 4  
fill ~8 ~20 ~2 ~8 ~21 ~2 stained_glass 1  
fill ~8 ~20 ~3 ~12 ~20 ~3 stone 0  
fill ~8 ~20 ~35 ~12 ~20 ~35 stone 0  
fill ~9 ~20 ~2 ~9 ~23 ~2 stained_glass 4 
setblock ~9 ~20 ~37 stained_glass 1  
fill ~10 ~20 ~0 ~11 ~20 ~0 stained_glass 4 
setblock ~10 ~20 ~37 stained_glass 4 
setblock ~11 ~20 ~38 stained_glass 4  
fill ~12 ~20 ~2 ~20 ~20 ~2 stone 0  
fill ~12 ~20 ~36 ~20 ~20 ~36 stone 0 
setblock ~12 ~20 ~38 stained_glass 1 
setblock ~13 ~20 ~0 stained_glass 1  
fill ~14 ~20 ~38 ~15 ~20 ~38 stained_glass 1  
fill ~15 ~20 ~-1 ~15 ~20 ~0 stained_glass 4  
fill ~16 ~20 ~37 ~19 ~20 ~37 stained_glass 1 
setblock ~17 ~20 ~0 stained_glass 4  
fill ~18 ~20 ~1 ~24 ~20 ~1 stained_glass 1  
fill ~18 ~20 ~38 ~19 ~20 ~38 stained_glass 1  
fill ~18 ~20 ~39 ~26 ~20 ~39 stained_glass 1  
fill ~18 ~20 ~40 ~20 ~20 ~40 stained_glass 1  
fill ~20 ~20 ~3 ~24 ~20 ~3 stone 0  
fill ~20 ~20 ~35 ~24 ~20 ~35 stone 0  
fill ~21 ~20 ~0 ~23 ~20 ~0 stained_glass 4  
fill ~21 ~20 ~36 ~21 ~18 ~36 stained_glass 1  
fill ~21 ~20 ~37 ~21 ~20 ~39 stained_glass 1  
fill ~22 ~20 ~38 ~26 ~20 ~38 stained_glass 1 
setblock ~22 ~20 ~40 stained_glass 1  
fill ~23 ~20 ~2 ~23 ~24 ~2 stained_glass 1 
setblock ~23 ~20 ~36 stained_glass 4  
fill ~23 ~20 ~37 ~24 ~20 ~37 stained_glass 1  
fill ~25 ~20 ~3 ~26 ~20 ~3 stained_glass 1 
setblock ~25 ~20 ~35 stained_hardened_clay 1  
fill ~25 ~20 ~40 ~25 ~21 ~40 stained_glass 1  
fill ~25 ~20 ~41 ~25 ~22 ~41 stained_glass 1  
fill ~25 ~20 ~42 ~25 ~20 ~38 stained_glass 1 
setblock ~26 ~20 ~34 stained_glass 4  
fill ~27 ~20 ~33 ~28 ~20 ~33 stained_glass 1  
fill ~27 ~20 ~34 ~27 ~24 ~34 stained_glass 1 
setblock ~27 ~20 ~35 stained_hardened_clay 1  
fill ~27 ~20 ~36 ~27 ~18 ~36 stained_glass 1  
fill ~27 ~20 ~37 ~30 ~20 ~37 stained_glass 1 
setblock ~28 ~20 ~4 stained_glass 1 
setblock ~28 ~20 ~39 stained_glass 1 
setblock ~29 ~20 ~5 stained_glass 4 
setblock ~29 ~20 ~32 stained_glass 4  
fill ~29 ~20 ~34 ~29 ~22 ~34 stained_glass 1  
fill ~29 ~20 ~35 ~29 ~20 ~37 stained_glass 1 
setblock ~29 ~20 ~38 stained_glass 14 
setblock ~29 ~20 ~40 stained_glass 14 
setblock ~30 ~20 ~30 stained_glass 4  
fill ~30 ~20 ~32 ~32 ~20 ~32 stained_glass 1  
fill ~30 ~20 ~33 ~33 ~20 ~33 stained_glass 1  
fill ~30 ~20 ~36 ~31 ~20 ~36 stained_glass 1  
fill ~30 ~20 ~38 ~30 ~22 ~38 stained_glass 1  
fill ~31 ~20 ~29 ~31 ~21 ~29 stained_glass 1  
fill ~31 ~20 ~31 ~33 ~20 ~31 stained_glass 1  
fill ~31 ~20 ~35 ~31 ~23 ~35 stained_glass 1  
fill ~32 ~20 ~28 ~32 ~21 ~28 stained_glass 1  
fill ~32 ~20 ~30 ~32 ~23 ~30 stained_glass 1  
fill ~32 ~20 ~38 ~32 ~22 ~38 stained_glass 1  
fill ~32 ~20 ~39 ~32 ~22 ~39 stained_glass 1  
fill ~33 ~20 ~14 ~33 ~22 ~14 stained_glass 4  
fill ~33 ~20 ~24 ~34 ~20 ~24 stained_glass 4  
fill ~33 ~20 ~26 ~33 ~21 ~26 stained_glass 1  
fill ~33 ~20 ~27 ~35 ~20 ~27 stained_glass 1  
fill ~33 ~20 ~36 ~33 ~23 ~36 stained_glass 1  
fill ~34 ~20 ~16 ~34 ~22 ~16 stained_glass 4  
fill ~34 ~20 ~17 ~34 ~23 ~17 stained_glass 4  
fill ~34 ~20 ~18 ~34 ~19 ~18 stained_glass 4 
setblock ~34 ~20 ~23 stained_glass 4  
fill ~34 ~20 ~25 ~35 ~20 ~25 stained_glass 1  
fill ~34 ~20 ~28 ~36 ~20 ~28 stained_glass 1  
fill ~34 ~20 ~34 ~34 ~23 ~34 stained_glass 1  
fill ~35 ~20 ~22 ~35 ~21 ~22 stained_glass 4 
setblock ~35 ~20 ~24 stained_glass 1  
fill ~35 ~20 ~26 ~35 ~21 ~26 stained_glass 1  
fill ~35 ~20 ~29 ~35 ~24 ~29 stained_glass 1  
fill ~35 ~20 ~33 ~35 ~23 ~33 stained_glass 1 
setblock ~35 ~20 ~34 stained_glass 14 
setblock ~36 ~20 ~33 stained_glass 14 
setblock ~-3 ~21 ~19 stained_glass 4 
setblock ~-2 ~21 ~15 stained_glass 1 
setblock ~-2 ~21 ~16 stained_glass 4  
fill ~-2 ~21 ~20 ~-2 ~22 ~20 stained_glass 4  
fill ~-2 ~21 ~21 ~-2 ~22 ~21 stained_glass 4  
fill ~-2 ~21 ~22 ~-2 ~22 ~22 stained_glass 1 
setblock ~-2 ~21 ~25 stained_glass 1  
fill ~-1 ~21 ~12 ~-1 ~22 ~12 stained_glass 4  
fill ~-1 ~21 ~14 ~-1 ~22 ~14 stained_glass 1 
setblock ~-1 ~21 ~24 stained_glass 4  
fill ~0 ~21 ~28 ~0 ~23 ~28 stained_glass 4 
setblock ~1 ~21 ~9 stained_glass 1 
setblock ~2 ~21 ~6 stained_glass 4  
fill ~2 ~21 ~8 ~2 ~22 ~8 stained_glass 1 
setblock ~3 ~21 ~6 glowstone 0  
fill ~4 ~21 ~34 ~5 ~21 ~34 stained_glass 4 
setblock ~5 ~21 ~4 stained_glass 4 
setblock ~5 ~21 ~5 stained_glass 1  
fill ~5 ~21 ~33 ~6 ~21 ~33 stone 0 
setblock ~6 ~21 ~3 stained_glass 4 
setblock ~6 ~21 ~4 stained_glass 1  
fill ~8 ~21 ~3 ~12 ~21 ~3 stone 0  
fill ~8 ~21 ~35 ~12 ~21 ~35 stone 0  
fill ~8 ~21 ~36 ~8 ~21 ~37 stained_glass 1 
setblock ~11 ~21 ~2 stained_glass 1 
setblock ~11 ~21 ~37 stained_glass 1  
fill ~12 ~21 ~2 ~20 ~21 ~2 stone 0  
fill ~12 ~21 ~36 ~20 ~21 ~36 stone 0  
fill ~14 ~21 ~38 ~14 ~19 ~38 stained_glass 1 
setblock ~16 ~21 ~0 stained_glass 4  
fill ~16 ~21 ~37 ~18 ~21 ~37 stained_glass 1  
fill ~16 ~21 ~38 ~16 ~23 ~38 stained_glass 1  
fill ~18 ~21 ~0 ~19 ~21 ~0 stained_glass 1  
fill ~18 ~21 ~1 ~21 ~21 ~1 stained_glass 1 
setblock ~19 ~21 ~37 stained_glass 4  
fill ~20 ~21 ~3 ~24 ~21 ~3 stone 0  
fill ~20 ~21 ~35 ~24 ~21 ~35 stone 0  
fill ~20 ~21 ~37 ~20 ~32 ~37 stained_glass 1  
fill ~22 ~21 ~36 ~22 ~24 ~36 stained_glass 1  
fill ~22 ~21 ~37 ~22 ~22 ~37 stained_glass 1  
fill ~22 ~21 ~38 ~22 ~25 ~38 stained_glass 1 
setblock ~23 ~21 ~0 stained_glass 4 
setblock ~23 ~21 ~1 stained_glass 1  
fill ~24 ~21 ~37 ~24 ~21 ~41 stained_glass 1  
fill ~25 ~21 ~2 ~25 ~22 ~2 stained_glass 1  
fill ~25 ~21 ~3 ~26 ~21 ~3 stained_glass 1 
setblock ~25 ~21 ~35 stained_glass 4 
setblock ~25 ~21 ~38 stained_hardened_clay 1  
fill ~26 ~21 ~4 ~27 ~21 ~4 stained_glass 1  
fill ~26 ~21 ~34 ~26 ~23 ~34 stained_glass 1  
fill ~26 ~21 ~38 ~32 ~21 ~38 stained_glass 1  
fill ~26 ~21 ~40 ~30 ~21 ~40 stained_glass 1  
fill ~26 ~21 ~41 ~26 ~24 ~41 stained_glass 1  
fill ~27 ~21 ~33 ~31 ~21 ~33 stained_glass 1  
fill ~27 ~21 ~35 ~27 ~22 ~35 stained_glass 1 
setblock ~27 ~21 ~39 stained_glass 1   

KittysCommands:  
setblock ~27 ~21 ~42 stained_glass 14 
setblock ~28 ~21 ~4 stained_glass 4  
fill ~28 ~21 ~36 ~28 ~22 ~36 stained_glass 1  
fill ~28 ~21 ~37 ~28 ~21 ~33 stained_glass 1 
setblock ~28 ~21 ~39 stained_glass 4  
fill ~29 ~21 ~6 ~29 ~22 ~6 stained_glass 4  
fill ~29 ~21 ~32 ~34 ~21 ~32 stained_glass 1 
setblock ~29 ~21 ~39 stained_glass 1  
fill ~30 ~21 ~7 ~30 ~22 ~7 stained_glass 1  
fill ~30 ~21 ~34 ~30 ~21 ~38 stained_glass 1 
setblock ~30 ~21 ~39 stained_glass 14  
fill ~30 ~21 ~41 ~30 ~24 ~41 stained_glass 1  
fill ~31 ~21 ~31 ~33 ~21 ~31 stained_glass 1  
fill ~31 ~21 ~36 ~31 ~22 ~36 stained_glass 1 
setblock ~31 ~21 ~37 stained_glass 14  
fill ~32 ~21 ~29 ~35 ~21 ~29 stained_glass 1 
setblock ~32 ~21 ~35 stained_glass 14  
fill ~32 ~21 ~37 ~32 ~22 ~37 stained_glass 1  
fill ~33 ~21 ~11 ~33 ~22 ~11 stained_glass 4  
fill ~33 ~21 ~24 ~33 ~23 ~24 stained_glass 1  
fill ~33 ~21 ~27 ~34 ~21 ~27 stained_glass 1  
fill ~33 ~21 ~33 ~36 ~21 ~33 stained_glass 1  
fill ~33 ~21 ~34 ~33 ~24 ~34 stained_glass 1  
fill ~34 ~21 ~23 ~34 ~22 ~23 stained_glass 1  
fill ~34 ~21 ~30 ~36 ~21 ~30 stained_glass 1 
setblock ~35 ~21 ~17 stained_glass 4  
fill ~35 ~21 ~20 ~35 ~21 ~22 stained_glass 4  
fill ~35 ~21 ~28 ~38 ~21 ~28 stained_glass 1  
fill ~35 ~21 ~31 ~35 ~23 ~31 stained_glass 1  
fill ~35 ~21 ~34 ~36 ~21 ~34 stained_glass 1  
fill ~36 ~21 ~26 ~37 ~21 ~26 stained_glass 4  
fill ~36 ~21 ~32 ~36 ~23 ~32 stained_glass 1 
setblock ~36 ~21 ~35 stained_glass 14  
fill ~36 ~21 ~37 ~36 ~24 ~37 stained_glass 1  
fill ~-2 ~22 ~16 ~-2 ~23 ~16 stained_glass 1  
fill ~-2 ~22 ~19 ~-2 ~23 ~19 stained_glass 4  
fill ~-2 ~22 ~23 ~-2 ~22 ~24 stained_glass 1 
setblock ~-1 ~22 ~13 stained_glass 4 
setblock ~-1 ~22 ~15 stained_glass 1  
fill ~-1 ~22 ~23 ~-1 ~24 ~23 stained_glass 4 
setblock ~-1 ~22 ~24 stained_glass 1 
setblock ~0 ~22 ~9 stained_glass 1  
fill ~0 ~22 ~11 ~0 ~22 ~12 stained_glass 4  
fill ~0 ~22 ~16 ~1 ~22 ~16 stone 0  
fill ~0 ~22 ~17 ~0 ~23 ~17 stone 0  
fill ~0 ~22 ~18 ~0 ~24 ~18 stone 0  
fill ~0 ~22 ~19 ~0 ~24 ~19 stone 0  
fill ~0 ~22 ~20 ~0 ~24 ~20 stone 0  
fill ~0 ~22 ~21 ~1 ~22 ~21 stone 0  
fill ~0 ~22 ~22 ~1 ~22 ~22 stone 0  
fill ~0 ~22 ~26 ~0 ~23 ~26 stained_glass 4  
fill ~0 ~22 ~27 ~0 ~23 ~27 stained_glass 1  
fill ~1 ~22 ~8 ~1 ~22 ~9 stained_glass 4  
fill ~1 ~22 ~11 ~2 ~22 ~11 stone 0  
fill ~1 ~22 ~12 ~1 ~23 ~12 stone 0  
fill ~1 ~22 ~13 ~1 ~23 ~13 stone 0  
fill ~1 ~22 ~14 ~1 ~23 ~14 stone 0  
fill ~1 ~22 ~15 ~1 ~24 ~15 stone 0  
fill ~1 ~22 ~23 ~1 ~23 ~23 stone 0  
fill ~1 ~22 ~24 ~1 ~23 ~24 stone 0  
fill ~1 ~22 ~25 ~1 ~23 ~25 stone 0  
fill ~1 ~22 ~26 ~2 ~22 ~26 stone 0  
fill ~1 ~22 ~27 ~2 ~22 ~27 stone 0  
fill ~2 ~22 ~10 ~2 ~23 ~10 stone 0  
fill ~2 ~22 ~28 ~2 ~23 ~28 stone 0  
fill ~2 ~22 ~30 ~2 ~23 ~30 stained_glass 4  
fill ~3 ~22 ~6 ~4 ~22 ~6 stained_glass 4  
fill ~3 ~22 ~7 ~3 ~23 ~7 stained_glass 4  
fill ~3 ~22 ~31 ~3 ~23 ~31 stained_glass 1  
fill ~5 ~22 ~4 ~5 ~23 ~4 stained_glass 1  
fill ~5 ~22 ~5 ~5 ~23 ~5 stained_glass 4  
fill ~5 ~22 ~32 ~5 ~23 ~32 stone 0  
fill ~5 ~22 ~33 ~8 ~22 ~33 stone 0 
setblock ~5 ~22 ~34 stained_glass 1 
setblock ~6 ~22 ~4 stained_glass 4  
fill ~7 ~22 ~3 ~8 ~22 ~3 stained_glass 1  
fill ~7 ~22 ~5 ~7 ~23 ~5 stone 0  
fill ~8 ~22 ~4 ~12 ~22 ~4 stone 0  
fill ~8 ~22 ~34 ~13 ~22 ~34 stone 0  
fill ~8 ~22 ~35 ~9 ~22 ~35 stained_glass 1 
setblock ~10 ~22 ~1 stained_glass 1  
fill ~10 ~22 ~3 ~22 ~22 ~3 stone 0  
fill ~10 ~22 ~35 ~22 ~22 ~35 stone 0  
fill ~10 ~22 ~36 ~10 ~23 ~36 stained_glass 1  
fill ~10 ~22 ~37 ~10 ~22 ~36 stained_glass 1  
fill ~12 ~22 ~2 ~12 ~23 ~2 stained_glass 1 
setblock ~12 ~22 ~36 stained_glass 1  
fill ~13 ~22 ~2 ~19 ~22 ~2 stone 0  
fill ~13 ~22 ~36 ~19 ~22 ~36 stone 0  
fill ~14 ~22 ~1 ~14 ~24 ~1 stained_glass 1  
fill ~16 ~22 ~37 ~16 ~24 ~37 stained_glass 1 
setblock ~17 ~22 ~0 stained_glass 4  
fill ~17 ~22 ~37 ~17 ~23 ~37 stained_glass 4  
fill ~18 ~22 ~0 ~19 ~22 ~0 stained_glass 1  
fill ~18 ~22 ~37 ~22 ~22 ~37 stained_glass 1 
setblock ~19 ~22 ~-1 stained_glass 4  
fill ~19 ~22 ~1 ~19 ~23 ~1 stained_glass 1  
fill ~19 ~22 ~4 ~25 ~22 ~4 stone 0  
fill ~19 ~22 ~38 ~20 ~22 ~38 stained_glass 1  
fill ~20 ~22 ~2 ~20 ~23 ~2 stained_glass 1  
fill ~20 ~22 ~34 ~24 ~22 ~34 stone 0  
fill ~22 ~22 ~1 ~22 ~23 ~1 stained_glass 4  
fill ~22 ~22 ~39 ~22 ~23 ~39 stained_glass 1  
fill ~23 ~22 ~3 ~25 ~22 ~3 stained_glass 1  
fill ~23 ~22 ~35 ~25 ~22 ~35 stained_glass 1  
fill ~24 ~22 ~1 ~25 ~22 ~1 stained_glass 4  
fill ~24 ~22 ~33 ~26 ~22 ~33 stone 0 
setblock ~24 ~22 ~37 stained_hardened_clay 1  
fill ~24 ~22 ~38 ~24 ~22 ~40 stained_glass 1  
fill ~25 ~22 ~5 ~25 ~23 ~5 stone 0 
setblock ~25 ~22 ~36 stained_glass 1 
setblock ~26 ~22 ~2 stained_glass 1  
