fill ~1 ~-29 ~1 ~181 ~-29 ~1 dirt 0  
fill ~1 ~-29 ~2 ~181 ~-29 ~2 dirt 0  
fill ~1 ~-29 ~3 ~181 ~-29 ~3 dirt 0  
fill ~1 ~-29 ~4 ~181 ~-29 ~4 dirt 0  
fill ~1 ~-29 ~5 ~181 ~-29 ~5 dirt 0  
fill ~1 ~-29 ~6 ~181 ~-29 ~6 dirt 0  
fill ~1 ~-29 ~7 ~181 ~-29 ~7 dirt 0  
fill ~1 ~-29 ~8 ~181 ~-29 ~8 dirt 0  
fill ~1 ~-29 ~9 ~181 ~-29 ~9 dirt 0  
fill ~1 ~-29 ~10 ~181 ~-29 ~10 dirt 0  
fill ~1 ~-29 ~11 ~181 ~-29 ~11 dirt 0  
fill ~1 ~-29 ~12 ~181 ~-29 ~12 dirt 0  
fill ~1 ~-29 ~13 ~181 ~-29 ~13 dirt 0  
fill ~1 ~-29 ~14 ~181 ~-29 ~14 dirt 0  
fill ~1 ~-29 ~15 ~181 ~-29 ~15 dirt 0  
fill ~1 ~-29 ~16 ~181 ~-29 ~16 dirt 0  
fill ~1 ~-29 ~17 ~181 ~-29 ~17 dirt 0  
fill ~1 ~-29 ~18 ~181 ~-29 ~18 dirt 0  
fill ~1 ~-29 ~19 ~181 ~-29 ~19 dirt 0  
fill ~1 ~-29 ~20 ~181 ~-29 ~20 dirt 0  
fill ~1 ~-29 ~21 ~181 ~-29 ~21 dirt 0  
fill ~1 ~-29 ~22 ~31 ~-29 ~22 dirt 0  
fill ~1 ~-29 ~23 ~31 ~-29 ~23 dirt 0  
fill ~1 ~-29 ~24 ~31 ~-29 ~24 dirt 0  
fill ~1 ~-29 ~25 ~31 ~-29 ~25 dirt 0  
fill ~1 ~-29 ~26 ~31 ~-29 ~26 dirt 0  
fill ~1 ~-29 ~27 ~31 ~-29 ~27 dirt 0  
fill ~1 ~-29 ~28 ~31 ~-29 ~28 dirt 0  
fill ~1 ~-29 ~29 ~31 ~-29 ~29 dirt 0  
fill ~1 ~-29 ~30 ~31 ~-29 ~30 dirt 0  
fill ~1 ~-29 ~31 ~31 ~-29 ~31 dirt 0  
fill ~1 ~-29 ~32 ~31 ~-29 ~32 dirt 0  
fill ~1 ~-29 ~33 ~31 ~-29 ~33 dirt 0  
fill ~1 ~-29 ~34 ~31 ~-29 ~34 dirt 0  
fill ~1 ~-29 ~35 ~31 ~-29 ~35 dirt 0  
fill ~1 ~-29 ~36 ~31 ~-29 ~36 dirt 0  
fill ~1 ~-29 ~37 ~31 ~-29 ~37 dirt 0  
fill ~1 ~-29 ~38 ~31 ~-29 ~38 dirt 0  
fill ~1 ~-29 ~39 ~31 ~-29 ~39 dirt 0  
fill ~1 ~-29 ~40 ~31 ~-29 ~40 dirt 0  
fill ~1 ~-29 ~41 ~31 ~-29 ~41 dirt 0  
fill ~1 ~-29 ~42 ~31 ~-29 ~42 dirt 0  
fill ~1 ~-29 ~43 ~31 ~-29 ~43 dirt 0  
fill ~1 ~-29 ~44 ~31 ~-29 ~44 dirt 0  
fill ~1 ~-29 ~45 ~31 ~-29 ~45 dirt 0  
fill ~1 ~-29 ~46 ~31 ~-29 ~46 dirt 0  
fill ~1 ~-29 ~47 ~31 ~-29 ~47 dirt 0  
fill ~1 ~-29 ~48 ~31 ~-29 ~48 dirt 0  
fill ~1 ~-29 ~49 ~31 ~-29 ~49 dirt 0  
fill ~1 ~-29 ~50 ~31 ~-29 ~50 dirt 0  
fill ~1 ~-29 ~51 ~31 ~-29 ~51 dirt 0  
fill ~1 ~-29 ~52 ~31 ~-29 ~52 dirt 0  
fill ~1 ~-29 ~53 ~31 ~-29 ~53 dirt 0  
fill ~1 ~-29 ~54 ~31 ~-29 ~54 dirt 0  
fill ~1 ~-29 ~55 ~31 ~-29 ~55 dirt 0  
fill ~1 ~-29 ~56 ~31 ~-29 ~56 dirt 0  
fill ~1 ~-29 ~57 ~31 ~-29 ~57 dirt 0  
fill ~1 ~-29 ~58 ~31 ~-29 ~58 dirt 0  
fill ~1 ~-29 ~59 ~31 ~-29 ~59 dirt 0  
fill ~1 ~-29 ~60 ~31 ~-29 ~60 dirt 0  
fill ~1 ~-29 ~61 ~31 ~-29 ~61 dirt 0  
fill ~1 ~-29 ~62 ~31 ~-29 ~62 dirt 0  
fill ~1 ~-29 ~63 ~31 ~-29 ~63 dirt 0  
fill ~1 ~-29 ~64 ~31 ~-29 ~64 dirt 0  
fill ~1 ~-29 ~65 ~31 ~-29 ~65 dirt 0  
fill ~1 ~-29 ~66 ~31 ~-29 ~66 dirt 0  
fill ~1 ~-29 ~67 ~31 ~-29 ~67 dirt 0  
fill ~1 ~-29 ~68 ~31 ~-29 ~68 dirt 0  
fill ~1 ~-29 ~69 ~31 ~-29 ~69 dirt 0  
fill ~1 ~-29 ~70 ~31 ~-29 ~70 dirt 0  
fill ~1 ~-29 ~71 ~31 ~-29 ~71 dirt 0  
fill ~1 ~-29 ~72 ~31 ~-29 ~72 dirt 0  
fill ~1 ~-29 ~73 ~31 ~-29 ~73 dirt 0  
fill ~1 ~-29 ~74 ~31 ~-29 ~74 dirt 0  
fill ~1 ~-29 ~75 ~31 ~-29 ~75 dirt 0  
fill ~1 ~-29 ~76 ~31 ~-29 ~76 dirt 0  
fill ~1 ~-29 ~77 ~31 ~-29 ~77 dirt 0  
fill ~1 ~-29 ~78 ~31 ~-29 ~78 dirt 0  
fill ~1 ~-29 ~79 ~31 ~-29 ~79 dirt 0  
fill ~1 ~-29 ~80 ~31 ~-29 ~80 dirt 0  
fill ~1 ~-29 ~81 ~31 ~-29 ~81 dirt 0  
fill ~1 ~-29 ~82 ~31 ~-29 ~82 dirt 0  
fill ~1 ~-29 ~83 ~31 ~-29 ~83 dirt 0  
fill ~1 ~-29 ~84 ~31 ~-29 ~84 dirt 0  
fill ~1 ~-29 ~85 ~31 ~-29 ~85 dirt 0  
fill ~1 ~-29 ~86 ~181 ~-29 ~86 dirt 0  
fill ~1 ~-29 ~87 ~181 ~-29 ~87 dirt 0  
fill ~1 ~-29 ~88 ~181 ~-29 ~88 dirt 0  
fill ~1 ~-29 ~89 ~181 ~-29 ~89 dirt 0  
fill ~1 ~-29 ~90 ~181 ~-29 ~90 dirt 0  
fill ~1 ~-29 ~91 ~181 ~-29 ~91 dirt 0  
fill ~1 ~-29 ~92 ~181 ~-29 ~92 dirt 0  
fill ~1 ~-29 ~93 ~181 ~-29 ~93 dirt 0  
fill ~1 ~-29 ~94 ~181 ~-29 ~94 dirt 0  
fill ~1 ~-29 ~95 ~181 ~-29 ~95 dirt 0  
fill ~1 ~-29 ~96 ~181 ~-29 ~96 dirt 0  
fill ~1 ~-29 ~97 ~181 ~-29 ~97 dirt 0  
fill ~1 ~-29 ~98 ~181 ~-29 ~98 dirt 0  
fill ~1 ~-29 ~99 ~181 ~-29 ~99 dirt 0  
fill ~1 ~-29 ~100 ~181 ~-29 ~100 dirt 0  
fill ~32 ~-29 ~22 ~106 ~-29 ~22 stone 0  
fill ~32 ~-29 ~23 ~106 ~-29 ~23 stone 0  
fill ~32 ~-29 ~24 ~106 ~-29 ~24 stone 0  
fill ~32 ~-29 ~25 ~106 ~-29 ~25 stone 0  
fill ~32 ~-29 ~26 ~106 ~-29 ~26 stone 0  
fill ~32 ~-29 ~27 ~106 ~-29 ~27 stone 0  
fill ~32 ~-29 ~28 ~106 ~-29 ~28 stone 0  
fill ~32 ~-29 ~29 ~106 ~-29 ~29 stone 0  
fill ~32 ~-29 ~30 ~106 ~-29 ~30 stone 0  
fill ~32 ~-29 ~31 ~106 ~-29 ~31 stone 0  
fill ~32 ~-29 ~32 ~106 ~-29 ~32 stone 0  
fill ~32 ~-29 ~33 ~106 ~-29 ~33 stone 0  
fill ~32 ~-29 ~34 ~106 ~-29 ~34 stone 0  
fill ~32 ~-29 ~35 ~106 ~-29 ~35 stone 0  
fill ~32 ~-29 ~36 ~106 ~-29 ~36 stone 0  
fill ~32 ~-29 ~37 ~106 ~-29 ~37 stone 0  
fill ~32 ~-29 ~38 ~106 ~-29 ~38 stone 0  
fill ~32 ~-29 ~39 ~106 ~-29 ~39 stone 0  
fill ~32 ~-29 ~40 ~106 ~-29 ~40 stone 0  
fill ~32 ~-29 ~41 ~106 ~-29 ~41 stone 0  
fill ~32 ~-29 ~42 ~106 ~-29 ~42 stone 0  
fill ~32 ~-29 ~43 ~106 ~-29 ~43 stone 0  
fill ~32 ~-29 ~44 ~106 ~-29 ~44 stone 0  
fill ~32 ~-29 ~45 ~106 ~-29 ~45 stone 0  
fill ~32 ~-29 ~46 ~106 ~-29 ~46 stone 0  
fill ~32 ~-29 ~47 ~106 ~-29 ~47 stone 0  
fill ~32 ~-29 ~48 ~106 ~-29 ~48 stone 0  
fill ~32 ~-29 ~49 ~106 ~-29 ~49 stone 0  
fill ~32 ~-29 ~50 ~106 ~-29 ~50 stone 0  
fill ~32 ~-29 ~51 ~106 ~-29 ~51 stone 0  
fill ~32 ~-29 ~52 ~106 ~-29 ~52 stone 0  
fill ~32 ~-29 ~53 ~106 ~-29 ~53 stone 0  
fill ~32 ~-29 ~54 ~106 ~-29 ~54 stone 0  
fill ~32 ~-29 ~55 ~106 ~-29 ~55 stone 0  
fill ~32 ~-29 ~56 ~106 ~-29 ~56 stone 0  
fill ~32 ~-29 ~57 ~106 ~-29 ~57 stone 0  
fill ~32 ~-29 ~58 ~106 ~-29 ~58 stone 0  
fill ~32 ~-29 ~59 ~106 ~-29 ~59 stone 0  
fill ~32 ~-29 ~60 ~106 ~-29 ~60 stone 0  
fill ~32 ~-29 ~61 ~106 ~-29 ~61 stone 0  
fill ~32 ~-29 ~62 ~106 ~-29 ~62 stone 0  
fill ~32 ~-29 ~63 ~106 ~-29 ~63 stone 0  
fill ~32 ~-29 ~64 ~106 ~-29 ~64 stone 0  
fill ~32 ~-29 ~65 ~106 ~-29 ~65 stone 0  
fill ~32 ~-29 ~66 ~106 ~-29 ~66 stone 0  
fill ~32 ~-29 ~67 ~106 ~-29 ~67 stone 0  
fill ~32 ~-29 ~68 ~106 ~-29 ~68 stone 0  
fill ~32 ~-29 ~69 ~106 ~-29 ~69 stone 0  
fill ~32 ~-29 ~70 ~106 ~-29 ~70 stone 0  
fill ~32 ~-29 ~71 ~106 ~-29 ~71 stone 0  
fill ~32 ~-29 ~72 ~106 ~-29 ~72 stone 0  
fill ~32 ~-29 ~73 ~106 ~-29 ~73 stone 0  
fill ~32 ~-29 ~74 ~106 ~-29 ~74 stone 0  
fill ~32 ~-29 ~75 ~106 ~-29 ~75 stone 0  
fill ~32 ~-29 ~76 ~106 ~-29 ~76 stone 0  
fill ~32 ~-29 ~77 ~106 ~-29 ~77 stone 0  
fill ~32 ~-29 ~78 ~106 ~-29 ~78 stone 0  
fill ~32 ~-29 ~79 ~106 ~-29 ~79 stone 0  
fill ~32 ~-29 ~80 ~106 ~-29 ~80 stone 0  
fill ~32 ~-29 ~81 ~106 ~-29 ~81 stone 0  
fill ~32 ~-29 ~82 ~106 ~-29 ~82 stone 0  
fill ~32 ~-29 ~83 ~106 ~-29 ~83 stone 0  
fill ~32 ~-29 ~84 ~106 ~-29 ~84 stone 0  
fill ~32 ~-29 ~85 ~106 ~-29 ~85 stone 0  
fill ~107 ~-29 ~22 ~181 ~-29 ~22 dirt 0  
fill ~107 ~-29 ~23 ~181 ~-29 ~23 dirt 0  
fill ~107 ~-29 ~24 ~181 ~-29 ~24 dirt 0  
fill ~107 ~-29 ~25 ~181 ~-29 ~25 dirt 0  
fill ~107 ~-29 ~26 ~181 ~-29 ~26 dirt 0  
fill ~107 ~-29 ~27 ~181 ~-29 ~27 dirt 0  
fill ~107 ~-29 ~28 ~181 ~-29 ~28 dirt 0  
fill ~107 ~-29 ~29 ~181 ~-29 ~29 dirt 0  
fill ~107 ~-29 ~30 ~181 ~-29 ~30 dirt 0  
fill ~107 ~-29 ~31 ~181 ~-29 ~31 dirt 0  
fill ~107 ~-29 ~32 ~181 ~-29 ~32 dirt 0  
fill ~107 ~-29 ~33 ~181 ~-29 ~33 dirt 0  
fill ~107 ~-29 ~34 ~181 ~-29 ~34 dirt 0  
fill ~107 ~-29 ~35 ~181 ~-29 ~35 dirt 0  
fill ~107 ~-29 ~36 ~181 ~-29 ~36 dirt 0  
fill ~107 ~-29 ~37 ~181 ~-29 ~37 dirt 0  
fill ~107 ~-29 ~38 ~181 ~-29 ~38 dirt 0  
fill ~107 ~-29 ~39 ~181 ~-29 ~39 dirt 0  
fill ~107 ~-29 ~40 ~181 ~-29 ~40 dirt 0  
fill ~107 ~-29 ~41 ~181 ~-29 ~41 dirt 0  
fill ~107 ~-29 ~42 ~181 ~-29 ~42 dirt 0  
fill ~107 ~-29 ~43 ~181 ~-29 ~43 dirt 0  
fill ~107 ~-29 ~44 ~181 ~-29 ~44 dirt 0  
fill ~107 ~-29 ~45 ~181 ~-29 ~45 dirt 0  
fill ~107 ~-29 ~46 ~181 ~-29 ~46 dirt 0  
fill ~107 ~-29 ~47 ~181 ~-29 ~47 dirt 0  
fill ~107 ~-29 ~48 ~181 ~-29 ~48 dirt 0  
fill ~107 ~-29 ~49 ~181 ~-29 ~49 dirt 0  
fill ~107 ~-29 ~50 ~181 ~-29 ~50 dirt 0  
fill ~107 ~-29 ~51 ~181 ~-29 ~51 dirt 0  
fill ~107 ~-29 ~52 ~181 ~-29 ~52 dirt 0  
fill ~107 ~-29 ~53 ~181 ~-29 ~53 dirt 0  
fill ~107 ~-29 ~54 ~181 ~-29 ~54 dirt 0  
fill ~107 ~-29 ~55 ~181 ~-29 ~55 dirt 0  
fill ~107 ~-29 ~56 ~181 ~-29 ~56 dirt 0  
fill ~107 ~-29 ~57 ~181 ~-29 ~57 dirt 0  
fill ~107 ~-29 ~58 ~181 ~-29 ~58 dirt 0  
fill ~107 ~-29 ~59 ~181 ~-29 ~59 dirt 0  
fill ~107 ~-29 ~60 ~181 ~-29 ~60 dirt 0  
fill ~107 ~-29 ~61 ~181 ~-29 ~61 dirt 0  
fill ~107 ~-29 ~62 ~181 ~-29 ~62 dirt 0  
fill ~107 ~-29 ~63 ~181 ~-29 ~63 dirt 0  
fill ~107 ~-29 ~64 ~181 ~-29 ~64 dirt 0  
fill ~107 ~-29 ~65 ~181 ~-29 ~65 dirt 0  
fill ~107 ~-29 ~66 ~181 ~-29 ~66 dirt 0  
fill ~107 ~-29 ~67 ~181 ~-29 ~67 dirt 0  
fill ~107 ~-29 ~68 ~181 ~-29 ~68 dirt 0  
fill ~107 ~-29 ~69 ~181 ~-29 ~69 dirt 0  
fill ~107 ~-29 ~70 ~181 ~-29 ~70 dirt 0  
fill ~107 ~-29 ~71 ~181 ~-29 ~71 dirt 0  
fill ~107 ~-29 ~72 ~181 ~-29 ~72 dirt 0  
fill ~107 ~-29 ~73 ~181 ~-29 ~73 dirt 0  
fill ~107 ~-29 ~74 ~181 ~-29 ~74 dirt 0  
fill ~107 ~-29 ~75 ~181 ~-29 ~75 dirt 0  
fill ~107 ~-29 ~76 ~181 ~-29 ~76 dirt 0  
fill ~107 ~-29 ~77 ~181 ~-29 ~77 dirt 0  
fill ~107 ~-29 ~78 ~181 ~-29 ~78 dirt 0  
fill ~107 ~-29 ~79 ~181 ~-29 ~79 dirt 0  
fill ~107 ~-29 ~80 ~181 ~-29 ~80 dirt 0  
fill ~107 ~-29 ~81 ~181 ~-29 ~81 dirt 0  
fill ~107 ~-29 ~82 ~181 ~-29 ~82 dirt 0  
fill ~107 ~-29 ~83 ~181 ~-29 ~83 dirt 0  
fill ~107 ~-29 ~84 ~181 ~-29 ~84 dirt 0  
fill ~107 ~-29 ~85 ~181 ~-29 ~85 dirt 0  
fill ~1 ~-28 ~1 ~181 ~-28 ~1 dirt 0  
fill ~1 ~-28 ~2 ~181 ~-28 ~2 dirt 0  
fill ~1 ~-28 ~3 ~181 ~-28 ~3 dirt 0  
fill ~1 ~-28 ~4 ~181 ~-28 ~4 dirt 0  
fill ~1 ~-28 ~5 ~181 ~-28 ~5 dirt 0  
fill ~1 ~-28 ~6 ~181 ~-28 ~6 dirt 0  
fill ~1 ~-28 ~7 ~181 ~-28 ~7 dirt 0  
fill ~1 ~-28 ~8 ~181 ~-28 ~8 dirt 0  
fill ~1 ~-28 ~9 ~181 ~-28 ~9 dirt 0  
fill ~1 ~-28 ~10 ~181 ~-28 ~10 dirt 0  
fill ~1 ~-28 ~11 ~181 ~-28 ~11 dirt 0  
fill ~1 ~-28 ~12 ~181 ~-28 ~12 dirt 0  
fill ~1 ~-28 ~13 ~181 ~-28 ~13 dirt 0  
fill ~1 ~-28 ~14 ~181 ~-28 ~14 dirt 0  
fill ~1 ~-28 ~15 ~181 ~-28 ~15 dirt 0  
fill ~1 ~-28 ~16 ~181 ~-28 ~16 dirt 0  
fill ~1 ~-28 ~17 ~181 ~-28 ~17 dirt 0  
fill ~1 ~-28 ~18 ~181 ~-28 ~18 dirt 0  
fill ~1 ~-28 ~19 ~181 ~-28 ~19 dirt 0  
fill ~1 ~-28 ~20 ~181 ~-28 ~20 dirt 0  
fill ~1 ~-28 ~21 ~181 ~-28 ~21 dirt 0  
fill ~1 ~-28 ~22 ~31 ~-28 ~22 dirt 0  
fill ~1 ~-28 ~23 ~31 ~-28 ~23 dirt 0  
fill ~1 ~-28 ~24 ~31 ~-28 ~24 dirt 0  
fill ~1 ~-28 ~25 ~31 ~-28 ~25 dirt 0  
fill ~1 ~-28 ~26 ~31 ~-28 ~26 dirt 0  
fill ~1 ~-28 ~27 ~31 ~-28 ~27 dirt 0  
fill ~1 ~-28 ~28 ~31 ~-28 ~28 dirt 0  
fill ~1 ~-28 ~29 ~31 ~-28 ~29 dirt 0  
fill ~1 ~-28 ~30 ~31 ~-28 ~30 dirt 0  
fill ~1 ~-28 ~31 ~31 ~-28 ~31 dirt 0  
fill ~1 ~-28 ~32 ~31 ~-28 ~32 dirt 0  
fill ~1 ~-28 ~33 ~31 ~-28 ~33 dirt 0  
fill ~1 ~-28 ~34 ~31 ~-28 ~34 dirt 0  
fill ~1 ~-28 ~35 ~31 ~-28 ~35 dirt 0  
fill ~1 ~-28 ~36 ~31 ~-28 ~36 dirt 0  
fill ~1 ~-28 ~37 ~31 ~-28 ~37 dirt 0  
fill ~1 ~-28 ~38 ~31 ~-28 ~38 dirt 0  
fill ~1 ~-28 ~39 ~31 ~-28 ~39 dirt 0  
fill ~1 ~-28 ~40 ~31 ~-28 ~40 dirt 0  
fill ~1 ~-28 ~41 ~31 ~-28 ~41 dirt 0  
fill ~1 ~-28 ~42 ~31 ~-28 ~42 dirt 0  
fill ~1 ~-28 ~43 ~31 ~-28 ~43 dirt 0  
fill ~1 ~-28 ~44 ~31 ~-28 ~44 dirt 0  
fill ~1 ~-28 ~45 ~31 ~-28 ~45 dirt 0  
fill ~1 ~-28 ~46 ~31 ~-28 ~46 dirt 0  
fill ~1 ~-28 ~47 ~31 ~-28 ~47 dirt 0  
fill ~1 ~-28 ~48 ~31 ~-28 ~48 dirt 0  
fill ~1 ~-28 ~49 ~31 ~-28 ~49 dirt 0  
fill ~1 ~-28 ~50 ~31 ~-28 ~50 dirt 0  
fill ~1 ~-28 ~51 ~31 ~-28 ~51 dirt 0  
fill ~1 ~-28 ~52 ~31 ~-28 ~52 dirt 0  
fill ~1 ~-28 ~53 ~31 ~-28 ~53 dirt 0  
fill ~1 ~-28 ~54 ~31 ~-28 ~54 dirt 0  
fill ~1 ~-28 ~55 ~31 ~-28 ~55 dirt 0  
fill ~1 ~-28 ~56 ~31 ~-28 ~56 dirt 0  
fill ~1 ~-28 ~57 ~31 ~-28 ~57 dirt 0  
fill ~1 ~-28 ~58 ~31 ~-28 ~58 dirt 0  
fill ~1 ~-28 ~59 ~31 ~-28 ~59 dirt 0  
fill ~1 ~-28 ~60 ~31 ~-28 ~60 dirt 0  
fill ~1 ~-28 ~61 ~31 ~-28 ~61 dirt 0  
fill ~1 ~-28 ~62 ~31 ~-28 ~62 dirt 0  
fill ~1 ~-28 ~63 ~31 ~-28 ~63 dirt 0  
fill ~1 ~-28 ~64 ~31 ~-28 ~64 dirt 0  
fill ~1 ~-28 ~65 ~31 ~-28 ~65 dirt 0  
fill ~1 ~-28 ~66 ~31 ~-28 ~66 dirt 0  
fill ~1 ~-28 ~67 ~31 ~-28 ~67 dirt 0  
fill ~1 ~-28 ~68 ~31 ~-28 ~68 dirt 0  
fill ~1 ~-28 ~69 ~31 ~-28 ~69 dirt 0  
fill ~1 ~-28 ~70 ~31 ~-28 ~70 dirt 0  
fill ~1 ~-28 ~71 ~31 ~-28 ~71 dirt 0  
fill ~1 ~-28 ~72 ~31 ~-28 ~72 dirt 0  
fill ~1 ~-28 ~73 ~31 ~-28 ~73 dirt 0  
fill ~1 ~-28 ~74 ~31 ~-28 ~74 dirt 0  
fill ~1 ~-28 ~75 ~31 ~-28 ~75 dirt 0  
fill ~1 ~-28 ~76 ~31 ~-28 ~76 dirt 0  
fill ~1 ~-28 ~77 ~31 ~-28 ~77 dirt 0  
fill ~1 ~-28 ~78 ~31 ~-28 ~78 dirt 0  
fill ~1 ~-28 ~79 ~31 ~-28 ~79 dirt 0  
fill ~1 ~-28 ~80 ~31 ~-28 ~80 dirt 0  
fill ~1 ~-28 ~81 ~31 ~-28 ~81 dirt 0  
fill ~1 ~-28 ~82 ~31 ~-28 ~82 dirt 0  
fill ~1 ~-28 ~83 ~31 ~-28 ~83 dirt 0  
fill ~1 ~-28 ~84 ~31 ~-28 ~84 dirt 0  
fill ~1 ~-28 ~85 ~31 ~-28 ~85 dirt 0  
fill ~1 ~-28 ~86 ~181 ~-28 ~86 dirt 0  
fill ~1 ~-28 ~87 ~181 ~-28 ~87 dirt 0  
fill ~1 ~-28 ~88 ~181 ~-28 ~88 dirt 0  
fill ~1 ~-28 ~89 ~181 ~-28 ~89 dirt 0  
fill ~1 ~-28 ~90 ~181 ~-28 ~90 dirt 0  
fill ~1 ~-28 ~91 ~181 ~-28 ~91 dirt 0  
fill ~1 ~-28 ~92 ~181 ~-28 ~92 dirt 0  
fill ~1 ~-28 ~93 ~181 ~-28 ~93 dirt 0  
fill ~1 ~-28 ~94 ~181 ~-28 ~94 dirt 0  
fill ~1 ~-28 ~95 ~181 ~-28 ~95 dirt 0  
fill ~1 ~-28 ~96 ~181 ~-28 ~96 dirt 0  
fill ~1 ~-28 ~97 ~181 ~-28 ~97 dirt 0  
fill ~1 ~-28 ~98 ~181 ~-28 ~98 dirt 0  
fill ~1 ~-28 ~99 ~181 ~-28 ~99 dirt 0  
fill ~1 ~-28 ~100 ~181 ~-28 ~100 dirt 0  
fill ~32 ~-28 ~22 ~106 ~-28 ~22 stone 0  
fill ~32 ~-28 ~23 ~106 ~-28 ~23 stone 0  
fill ~32 ~-28 ~24 ~106 ~-28 ~24 stone 0  
fill ~32 ~-28 ~25 ~106 ~-28 ~25 stone 0  
fill ~32 ~-28 ~26 ~106 ~-28 ~26 stone 0  
fill ~32 ~-28 ~27 ~106 ~-28 ~27 stone 0  
fill ~32 ~-28 ~28 ~106 ~-28 ~28 stone 0  
fill ~32 ~-28 ~29 ~106 ~-28 ~29 stone 0  
fill ~32 ~-28 ~30 ~106 ~-28 ~30 stone 0  
fill ~32 ~-28 ~31 ~106 ~-28 ~31 stone 0  
fill ~32 ~-28 ~32 ~106 ~-28 ~32 stone 0  
fill ~32 ~-28 ~33 ~106 ~-28 ~33 stone 0  
fill ~32 ~-28 ~34 ~106 ~-28 ~34 stone 0  
fill ~32 ~-28 ~35 ~106 ~-28 ~35 stone 0  
fill ~32 ~-28 ~36 ~106 ~-28 ~36 stone 0  
fill ~32 ~-28 ~37 ~106 ~-28 ~37 stone 0  
fill ~32 ~-28 ~38 ~106 ~-28 ~38 stone 0  
fill ~32 ~-28 ~39 ~106 ~-28 ~39 stone 0  
fill ~32 ~-28 ~40 ~106 ~-28 ~40 stone 0  
fill ~32 ~-28 ~41 ~81 ~-28 ~41 stone 0  
fill ~32 ~-28 ~42 ~80 ~-28 ~42 stone 0  
fill ~32 ~-28 ~43 ~81 ~-28 ~43 stone 0  
fill ~32 ~-28 ~44 ~78 ~-28 ~44 stone 0  
fill ~32 ~-28 ~45 ~78 ~-28 ~45 stone 0  
fill ~32 ~-28 ~46 ~106 ~-28 ~46 stone 0  
fill ~32 ~-28 ~47 ~106 ~-28 ~47 stone 0  
fill ~32 ~-28 ~48 ~106 ~-28 ~48 stone 0  
fill ~32 ~-28 ~49 ~106 ~-28 ~49 stone 0  
fill ~32 ~-28 ~50 ~106 ~-28 ~50 stone 0  
fill ~32 ~-28 ~51 ~106 ~-28 ~51 stone 0  
fill ~32 ~-28 ~52 ~106 ~-28 ~52 stone 0  
fill ~32 ~-28 ~53 ~106 ~-28 ~53 stone 0  
fill ~32 ~-28 ~54 ~106 ~-28 ~54 stone 0  
fill ~32 ~-28 ~55 ~106 ~-28 ~55 stone 0  
fill ~32 ~-28 ~56 ~106 ~-28 ~56 stone 0  
fill ~32 ~-28 ~57 ~106 ~-28 ~57 stone 0  
fill ~32 ~-28 ~58 ~106 ~-28 ~58 stone 0  
fill ~32 ~-28 ~59 ~106 ~-28 ~59 stone 0  
fill ~32 ~-28 ~60 ~106 ~-28 ~60 stone 0  
fill ~32 ~-28 ~61 ~64 ~-28 ~61 stone 0  
fill ~32 ~-28 ~62 ~64 ~-28 ~62 stone 0  
fill ~32 ~-28 ~63 ~106 ~-28 ~63 stone 0  
fill ~32 ~-28 ~64 ~54 ~-28 ~64 stone 0  
fill ~32 ~-28 ~65 ~54 ~-28 ~65 stone 0  
fill ~32 ~-28 ~66 ~54 ~-28 ~66 stone 0  
fill ~32 ~-28 ~67 ~54 ~-28 ~67 stone 0  
fill ~32 ~-28 ~68 ~54 ~-28 ~68 stone 0  
fill ~32 ~-28 ~69 ~54 ~-28 ~69 stone 0  
fill ~32 ~-28 ~70 ~54 ~-28 ~70 stone 0  
fill ~32 ~-28 ~71 ~54 ~-28 ~71 stone 0  
fill ~32 ~-28 ~72 ~54 ~-28 ~72 stone 0  
fill ~32 ~-28 ~73 ~54 ~-28 ~73 stone 0  
fill ~32 ~-28 ~74 ~54 ~-28 ~74 stone 0  
fill ~32 ~-28 ~75 ~54 ~-28 ~75 stone 0  
fill ~32 ~-28 ~76 ~54 ~-28 ~76 stone 0  
fill ~32 ~-28 ~77 ~54 ~-28 ~77 stone 0  
fill ~32 ~-28 ~78 ~54 ~-28 ~78 stone 0  
fill ~32 ~-28 ~79 ~106 ~-28 ~79 stone 0  
fill ~32 ~-28 ~80 ~106 ~-28 ~80 stone 0  
fill ~32 ~-28 ~81 ~106 ~-28 ~81 stone 0  
fill ~32 ~-28 ~82 ~106 ~-28 ~82 stone 0  
fill ~32 ~-28 ~83 ~106 ~-28 ~83 stone 0  
fill ~32 ~-28 ~84 ~106 ~-28 ~84 stone 0  
fill ~32 ~-28 ~85 ~106 ~-28 ~85 stone 0  
fill ~55 ~-28 ~64 ~55 ~-28 ~78 dirt 0  
fill ~56 ~-28 ~64 ~106 ~-28 ~64 stone 0  
fill ~56 ~-28 ~65 ~106 ~-28 ~65 stone 0  
fill ~56 ~-28 ~66 ~106 ~-28 ~66 stone 0  
fill ~56 ~-28 ~67 ~106 ~-28 ~67 stone 0  
fill ~56 ~-28 ~68 ~106 ~-28 ~68 stone 0  
fill ~56 ~-28 ~69 ~106 ~-28 ~69 stone 0  
fill ~56 ~-28 ~70 ~106 ~-28 ~70 stone 0  
fill ~56 ~-28 ~71 ~106 ~-28 ~71 stone 0  
fill ~56 ~-28 ~72 ~106 ~-28 ~72 stone 0  
fill ~56 ~-28 ~73 ~106 ~-28 ~73 stone 0  
fill ~56 ~-28 ~74 ~106 ~-28 ~74 stone 0  
fill ~56 ~-28 ~75 ~106 ~-28 ~75 stone 0  
fill ~56 ~-28 ~76 ~106 ~-28 ~76 stone 0  
fill ~56 ~-28 ~77 ~106 ~-28 ~77 stone 0  
fill ~56 ~-28 ~78 ~106 ~-28 ~78 stone 0  
fill ~65 ~-28 ~61 ~65 ~-28 ~62 lava 2  
fill ~66 ~-28 ~61 ~66 ~-23 ~61 lava 10  
fill ~66 ~-28 ~62 ~66 ~-22 ~62 lava 12  
fill ~67 ~-28 ~61 ~106 ~-28 ~61 stone 0  
fill ~67 ~-28 ~62 ~106 ~-28 ~62 stone 0  
fill ~79 ~-28 ~44 ~79 ~-25 ~44 lava 14  
fill ~79 ~-28 ~45 ~80 ~-28 ~45 lava 2 
setblock ~80 ~-28 ~44 lava 10 
setblock ~81 ~-28 ~42 lava 10  
fill ~81 ~-28 ~44 ~106 ~-28 ~44 stone 0  
fill ~81 ~-28 ~45 ~106 ~-28 ~45 stone 0 
setblock ~82 ~-28 ~41 lava 4 
setblock ~82 ~-28 ~42 lava 2 
setblock ~82 ~-28 ~43 lava 10  
fill ~83 ~-28 ~41 ~106 ~-28 ~41 stone 0 
setblock ~83 ~-28 ~42 lava 4  
fill ~83 ~-28 ~43 ~106 ~-28 ~43 stone 0  
fill ~84 ~-28 ~42 ~106 ~-28 ~42 stone 0  
fill ~107 ~-28 ~22 ~181 ~-28 ~22 dirt 0  
fill ~107 ~-28 ~23 ~181 ~-28 ~23 dirt 0  
fill ~107 ~-28 ~24 ~181 ~-28 ~24 dirt 0  
fill ~107 ~-28 ~25 ~181 ~-28 ~25 dirt 0  
fill ~107 ~-28 ~26 ~159 ~-28 ~26 dirt 0  
fill ~107 ~-28 ~27 ~181 ~-28 ~27 dirt 0  
fill ~107 ~-28 ~28 ~181 ~-28 ~28 dirt 0  
fill ~107 ~-28 ~29 ~181 ~-28 ~29 dirt 0  
fill ~107 ~-28 ~30 ~181 ~-28 ~30 dirt 0  
fill ~107 ~-28 ~31 ~181 ~-28 ~31 dirt 0  
fill ~107 ~-28 ~32 ~181 ~-28 ~32 dirt 0  
fill ~107 ~-28 ~33 ~181 ~-28 ~33 dirt 0  
fill ~107 ~-28 ~34 ~181 ~-28 ~34 dirt 0  
fill ~107 ~-28 ~35 ~181 ~-28 ~35 dirt 0  
fill ~107 ~-28 ~36 ~181 ~-28 ~36 dirt 0  
fill ~107 ~-28 ~37 ~181 ~-28 ~37 dirt 0  
fill ~107 ~-28 ~38 ~181 ~-28 ~38 dirt 0  
fill ~107 ~-28 ~39 ~181 ~-28 ~39 dirt 0  
fill ~107 ~-28 ~40 ~181 ~-28 ~40 dirt 0  
fill ~107 ~-28 ~41 ~181 ~-28 ~41 dirt 0  
fill ~107 ~-28 ~42 ~181 ~-28 ~42 dirt 0  
fill ~107 ~-28 ~43 ~181 ~-28 ~43 dirt 0  
fill ~107 ~-28 ~44 ~181 ~-28 ~44 dirt 0  
fill ~107 ~-28 ~45 ~181 ~-28 ~45 dirt 0  
fill ~107 ~-28 ~46 ~181 ~-28 ~46 dirt 0  
fill ~107 ~-28 ~47 ~181 ~-28 ~47 dirt 0  
fill ~107 ~-28 ~48 ~181 ~-28 ~48 dirt 0  
fill ~107 ~-28 ~49 ~181 ~-28 ~49 dirt 0  
fill ~107 ~-28 ~50 ~181 ~-28 ~50 dirt 0  
fill ~107 ~-28 ~51 ~181 ~-28 ~51 dirt 0  
fill ~107 ~-28 ~52 ~181 ~-28 ~52 dirt 0  
fill ~107 ~-28 ~53 ~181 ~-28 ~53 dirt 0  
fill ~107 ~-28 ~54 ~181 ~-28 ~54 dirt 0  
fill ~107 ~-28 ~55 ~181 ~-28 ~55 dirt 0  
fill ~107 ~-28 ~56 ~160 ~-28 ~56 dirt 0  
fill ~107 ~-28 ~57 ~181 ~-28 ~57 dirt 0  
fill ~107 ~-28 ~58 ~181 ~-28 ~58 dirt 0  
fill ~107 ~-28 ~59 ~181 ~-28 ~59 dirt 0  
fill ~107 ~-28 ~60 ~181 ~-28 ~60 dirt 0  
fill ~107 ~-28 ~61 ~181 ~-28 ~61 dirt 0  
fill ~107 ~-28 ~62 ~160 ~-28 ~62 dirt 0  
fill ~107 ~-28 ~63 ~181 ~-28 ~63 dirt 0  
fill ~107 ~-28 ~64 ~181 ~-28 ~64 dirt 0  
fill ~107 ~-28 ~65 ~181 ~-28 ~65 dirt 0  
fill ~107 ~-28 ~66 ~181 ~-28 ~66 dirt 0  
fill ~107 ~-28 ~67 ~181 ~-28 ~67 dirt 0  
fill ~107 ~-28 ~68 ~181 ~-28 ~68 dirt 0  
fill ~107 ~-28 ~69 ~181 ~-28 ~69 dirt 0  
fill ~107 ~-28 ~70 ~181 ~-28 ~70 dirt 0  
fill ~107 ~-28 ~71 ~181 ~-28 ~71 dirt 0  
fill ~107 ~-28 ~72 ~181 ~-28 ~72 dirt 0  
fill ~107 ~-28 ~73 ~181 ~-28 ~73 dirt 0  
fill ~107 ~-28 ~74 ~181 ~-28 ~74 dirt 0  
fill ~107 ~-28 ~75 ~181 ~-28 ~75 dirt 0  
fill ~107 ~-28 ~76 ~181 ~-28 ~76 dirt 0  
fill ~107 ~-28 ~77 ~135 ~-28 ~77 dirt 0  
fill ~107 ~-28 ~78 ~181 ~-28 ~78 dirt 0  
fill ~107 ~-28 ~79 ~181 ~-28 ~79 dirt 0  
fill ~107 ~-28 ~80 ~181 ~-28 ~80 dirt 0  
fill ~107 ~-28 ~81 ~181 ~-28 ~81 dirt 0  
fill ~107 ~-28 ~82 ~181 ~-28 ~82 dirt 0  
fill ~107 ~-28 ~83 ~181 ~-28 ~83 dirt 0  
fill ~107 ~-28 ~84 ~181 ~-28 ~84 dirt 0  
fill ~107 ~-28 ~85 ~181 ~-28 ~85 dirt 0 
setblock ~136 ~-28 ~77 stone 0  
fill ~137 ~-28 ~77 ~181 ~-28 ~77 dirt 0 
setblock ~160 ~-28 ~26 stone 0  
fill ~161 ~-28 ~26 ~181 ~-28 ~26 dirt 0 
setblock ~161 ~-28 ~56 stone 0 
setblock ~161 ~-28 ~62 stone 0  
fill ~162 ~-28 ~56 ~181 ~-28 ~56 dirt 0  
fill ~162 ~-28 ~62 ~181 ~-28 ~62 dirt 0  
fill ~1 ~-27 ~1 ~181 ~-27 ~1 dirt 0  
fill ~1 ~-27 ~2 ~181 ~-27 ~2 dirt 0  
fill ~1 ~-27 ~3 ~181 ~-27 ~3 dirt 0  
fill ~1 ~-27 ~4 ~181 ~-27 ~4 dirt 0  
fill ~1 ~-27 ~5 ~181 ~-27 ~5 dirt 0  
fill ~1 ~-27 ~6 ~181 ~-27 ~6 dirt 0  
fill ~1 ~-27 ~7 ~181 ~-27 ~7 dirt 0  
fill ~1 ~-27 ~8 ~181 ~-27 ~8 dirt 0  
fill ~1 ~-27 ~9 ~181 ~-27 ~9 dirt 0  
fill ~1 ~-27 ~10 ~181 ~-27 ~10 dirt 0  
fill ~1 ~-27 ~11 ~181 ~-27 ~11 dirt 0  
fill ~1 ~-27 ~12 ~181 ~-27 ~12 dirt 0  
fill ~1 ~-27 ~13 ~181 ~-27 ~13 dirt 0  
fill ~1 ~-27 ~14 ~181 ~-27 ~14 dirt 0  
fill ~1 ~-27 ~15 ~181 ~-27 ~15 dirt 0  
fill ~1 ~-27 ~16 ~181 ~-27 ~16 dirt 0  
fill ~1 ~-27 ~17 ~181 ~-27 ~17 dirt 0  
fill ~1 ~-27 ~18 ~181 ~-27 ~18 dirt 0  
fill ~1 ~-27 ~19 ~158 ~-27 ~19 dirt 0  
fill ~1 ~-27 ~20 ~181 ~-27 ~20 dirt 0  
fill ~1 ~-27 ~21 ~181 ~-27 ~21 dirt 0  
fill ~1 ~-27 ~22 ~31 ~-27 ~22 dirt 0  
fill ~1 ~-27 ~23 ~31 ~-27 ~23 dirt 0  
fill ~1 ~-27 ~24 ~31 ~-27 ~24 dirt 0  
fill ~1 ~-27 ~25 ~31 ~-27 ~25 dirt 0  
fill ~1 ~-27 ~26 ~31 ~-27 ~26 dirt 0  
fill ~1 ~-27 ~27 ~31 ~-27 ~27 dirt 0  
fill ~1 ~-27 ~28 ~31 ~-27 ~28 dirt 0  
fill ~1 ~-27 ~29 ~31 ~-27 ~29 dirt 0  
fill ~1 ~-27 ~30 ~31 ~-27 ~30 dirt 0  
fill ~1 ~-27 ~31 ~31 ~-27 ~31 dirt 0  
fill ~1 ~-27 ~32 ~31 ~-27 ~32 dirt 0  
fill ~1 ~-27 ~33 ~31 ~-27 ~33 dirt 0  
fill ~1 ~-27 ~34 ~31 ~-27 ~34 dirt 0  
fill ~1 ~-27 ~35 ~31 ~-27 ~35 dirt 0  
fill ~1 ~-27 ~36 ~31 ~-27 ~36 dirt 0  
fill ~1 ~-27 ~37 ~31 ~-27 ~37 dirt 0  
fill ~1 ~-27 ~38 ~31 ~-27 ~38 dirt 0  
fill ~1 ~-27 ~39 ~31 ~-27 ~39 dirt 0  
fill ~1 ~-27 ~40 ~31 ~-27 ~40 dirt 0  
fill ~1 ~-27 ~41 ~31 ~-27 ~41 dirt 0  
fill ~1 ~-27 ~42 ~31 ~-27 ~42 dirt 0  
fill ~1 ~-27 ~43 ~31 ~-27 ~43 dirt 0  
fill ~1 ~-27 ~44 ~31 ~-27 ~44 dirt 0  
fill ~1 ~-27 ~45 ~31 ~-27 ~45 dirt 0  
fill ~1 ~-27 ~46 ~31 ~-27 ~46 dirt 0  
fill ~1 ~-27 ~47 ~31 ~-27 ~47 dirt 0  
fill ~1 ~-27 ~48 ~31 ~-27 ~48 dirt 0  
fill ~1 ~-27 ~49 ~31 ~-27 ~49 dirt 0  
fill ~1 ~-27 ~50 ~31 ~-27 ~50 dirt 0  
fill ~1 ~-27 ~51 ~31 ~-27 ~51 dirt 0  
fill ~1 ~-27 ~52 ~31 ~-27 ~52 dirt 0  
fill ~1 ~-27 ~53 ~31 ~-27 ~53 dirt 0  
fill ~1 ~-27 ~54 ~31 ~-27 ~54 dirt 0  
fill ~1 ~-27 ~55 ~31 ~-27 ~55 dirt 0  
fill ~1 ~-27 ~56 ~31 ~-27 ~56 dirt 0  
fill ~1 ~-27 ~57 ~31 ~-27 ~57 dirt 0  
fill ~1 ~-27 ~58 ~31 ~-27 ~58 dirt 0  
fill ~1 ~-27 ~59 ~31 ~-27 ~59 dirt 0  
fill ~1 ~-27 ~60 ~31 ~-27 ~60 dirt 0  
fill ~1 ~-27 ~61 ~31 ~-27 ~61 dirt 0  
fill ~1 ~-27 ~62 ~31 ~-27 ~62 dirt 0  
fill ~1 ~-27 ~63 ~31 ~-27 ~63 dirt 0  
fill ~1 ~-27 ~64 ~31 ~-27 ~64 dirt 0  
fill ~1 ~-27 ~65 ~31 ~-27 ~65 dirt 0  
fill ~1 ~-27 ~66 ~31 ~-27 ~66 dirt 0  
fill ~1 ~-27 ~67 ~31 ~-27 ~67 dirt 0  
fill ~1 ~-27 ~68 ~31 ~-27 ~68 dirt 0  
fill ~1 ~-27 ~69 ~31 ~-27 ~69 dirt 0  
fill ~1 ~-27 ~70 ~31 ~-27 ~70 dirt 0  
fill ~1 ~-27 ~71 ~31 ~-27 ~71 dirt 0  
fill ~1 ~-27 ~72 ~31 ~-27 ~72 dirt 0  
fill ~1 ~-27 ~73 ~31 ~-27 ~73 dirt 0  
fill ~1 ~-27 ~74 ~31 ~-27 ~74 dirt 0  
fill ~1 ~-27 ~75 ~31 ~-27 ~75 dirt 0  
fill ~1 ~-27 ~76 ~31 ~-27 ~76 dirt 0  
fill ~1 ~-27 ~77 ~31 ~-27 ~77 dirt 0  
fill ~1 ~-27 ~78 ~31 ~-27 ~78 dirt 0  
fill ~1 ~-27 ~79 ~31 ~-27 ~79 dirt 0  
fill ~1 ~-27 ~80 ~31 ~-27 ~80 dirt 0  
fill ~1 ~-27 ~81 ~31 ~-27 ~81 dirt 0  
fill ~1 ~-27 ~82 ~31 ~-27 ~82 dirt 0  
fill ~1 ~-27 ~83 ~31 ~-27 ~83 dirt 0  
fill ~1 ~-27 ~84 ~31 ~-27 ~84 dirt 0  
fill ~1 ~-27 ~85 ~31 ~-27 ~85 dirt 0  
fill ~1 ~-27 ~86 ~181 ~-27 ~86 dirt 0  
fill ~1 ~-27 ~87 ~181 ~-27 ~87 dirt 0  
fill ~1 ~-27 ~88 ~181 ~-27 ~88 dirt 0  
fill ~1 ~-27 ~89 ~181 ~-27 ~89 dirt 0  
fill ~1 ~-27 ~90 ~181 ~-27 ~90 dirt 0  
fill ~1 ~-27 ~91 ~181 ~-27 ~91 dirt 0  
fill ~1 ~-27 ~92 ~181 ~-27 ~92 dirt 0  
fill ~1 ~-27 ~93 ~181 ~-27 ~93 dirt 0  
fill ~1 ~-27 ~94 ~181 ~-27 ~94 dirt 0  
fill ~1 ~-27 ~95 ~181 ~-27 ~95 dirt 0  
fill ~1 ~-27 ~96 ~181 ~-27 ~96 dirt 0  
fill ~1 ~-27 ~97 ~181 ~-27 ~97 dirt 0  
fill ~1 ~-27 ~98 ~181 ~-27 ~98 dirt 0  
fill ~1 ~-27 ~99 ~181 ~-27 ~99 dirt 0  
fill ~1 ~-27 ~100 ~181 ~-27 ~100 dirt 0  
fill ~32 ~-27 ~22 ~106 ~-27 ~22 stone 0  
fill ~32 ~-27 ~23 ~106 ~-27 ~23 stone 0  
fill ~32 ~-27 ~24 ~106 ~-27 ~24 stone 0  
fill ~32 ~-27 ~25 ~106 ~-27 ~25 stone 0  
fill ~32 ~-27 ~26 ~106 ~-27 ~26 stone 0  
fill ~32 ~-27 ~27 ~106 ~-27 ~27 stone 0  
fill ~32 ~-27 ~28 ~106 ~-27 ~28 stone 0  
fill ~32 ~-27 ~29 ~106 ~-27 ~29 stone 0  
fill ~32 ~-27 ~30 ~106 ~-27 ~30 stone 0  
fill ~32 ~-27 ~31 ~106 ~-27 ~31 stone 0  
fill ~32 ~-27 ~32 ~106 ~-27 ~32 stone 0  
fill ~32 ~-27 ~33 ~106 ~-27 ~33 stone 0  
fill ~32 ~-27 ~34 ~106 ~-27 ~34 stone 0  
fill ~32 ~-27 ~35 ~106 ~-27 ~35 stone 0  
fill ~32 ~-27 ~36 ~106 ~-27 ~36 stone 0  
fill ~32 ~-27 ~37 ~106 ~-27 ~37 stone 0  
fill ~32 ~-27 ~38 ~106 ~-27 ~38 stone 0  
fill ~32 ~-27 ~39 ~58 ~-27 ~39 stone 0  
fill ~32 ~-27 ~40 ~58 ~-27 ~40 stone 0  
fill ~32 ~-27 ~41 ~58 ~-27 ~41 stone 0  
fill ~32 ~-27 ~42 ~72 ~-27 ~42 stone 0  
fill ~32 ~-27 ~43 ~78 ~-27 ~43 stone 0  
fill ~32 ~-27 ~44 ~77 ~-27 ~44 stone 0  
fill ~32 ~-27 ~45 ~77 ~-27 ~45 stone 0  
fill ~32 ~-27 ~46 ~78 ~-27 ~46 stone 0  
fill ~32 ~-27 ~47 ~106 ~-27 ~47 stone 0  
fill ~32 ~-27 ~48 ~106 ~-27 ~48 stone 0  
fill ~32 ~-27 ~49 ~106 ~-27 ~49 stone 0  
fill ~32 ~-27 ~50 ~106 ~-27 ~50 stone 0  
fill ~32 ~-27 ~51 ~70 ~-27 ~51 stone 0  
fill ~32 ~-27 ~52 ~69 ~-27 ~52 stone 0  
fill ~32 ~-27 ~53 ~70 ~-27 ~53 stone 0  
fill ~32 ~-27 ~54 ~72 ~-27 ~54 stone 0  
fill ~32 ~-27 ~55 ~66 ~-27 ~55 stone 0  
fill ~32 ~-27 ~56 ~66 ~-27 ~56 stone 0  
fill ~32 ~-27 ~57 ~53 ~-27 ~57 stone 0  
fill ~32 ~-27 ~58 ~53 ~-27 ~58 stone 0  
fill ~32 ~-27 ~59 ~53 ~-27 ~59 stone 0  
fill ~32 ~-27 ~60 ~53 ~-27 ~60 stone 0  
fill ~32 ~-27 ~61 ~53 ~-27 ~61 stone 0  
fill ~32 ~-27 ~62 ~53 ~-27 ~62 stone 0  
fill ~32 ~-27 ~63 ~53 ~-27 ~63 stone 0  
fill ~32 ~-27 ~64 ~53 ~-27 ~64 stone 0  
fill ~32 ~-27 ~65 ~53 ~-27 ~65 stone 0  
fill ~32 ~-27 ~66 ~53 ~-27 ~66 stone 0  
fill ~32 ~-27 ~67 ~53 ~-27 ~67 stone 0  
fill ~32 ~-27 ~68 ~53 ~-27 ~68 stone 0  
fill ~32 ~-27 ~69 ~53 ~-27 ~69 stone 0  
fill ~32 ~-27 ~70 ~53 ~-27 ~70 stone 0  
fill ~32 ~-27 ~71 ~53 ~-27 ~71 stone 0  
fill ~32 ~-27 ~72 ~106 ~-27 ~72 stone 0  
fill ~32 ~-27 ~73 ~106 ~-27 ~73 stone 0  
fill ~32 ~-27 ~74 ~106 ~-27 ~74 stone 0  
fill ~32 ~-27 ~75 ~106 ~-27 ~75 stone 0  
fill ~32 ~-27 ~76 ~106 ~-27 ~76 stone 0  
fill ~32 ~-27 ~77 ~106 ~-27 ~77 stone 0  
fill ~32 ~-27 ~78 ~106 ~-27 ~78 stone 0  
fill ~32 ~-27 ~79 ~106 ~-27 ~79 stone 0  
fill ~32 ~-27 ~80 ~106 ~-27 ~80 stone 0  
fill ~32 ~-27 ~81 ~106 ~-27 ~81 stone 0  
fill ~32 ~-27 ~82 ~106 ~-27 ~82 stone 0  
fill ~32 ~-27 ~83 ~106 ~-27 ~83 stone 0  
fill ~32 ~-27 ~84 ~106 ~-27 ~84 stone 0  
fill ~32 ~-27 ~85 ~106 ~-27 ~85 stone 0  
fill ~54 ~-27 ~57 ~54 ~-27 ~71 dirt 0  
fill ~55 ~-27 ~57 ~106 ~-27 ~57 stone 0  
fill ~55 ~-27 ~58 ~106 ~-27 ~58 stone 0  
fill ~55 ~-27 ~59 ~106 ~-27 ~59 stone 0  
fill ~55 ~-27 ~60 ~64 ~-27 ~60 stone 0  
fill ~55 ~-27 ~61 ~63 ~-27 ~61 stone 0  
fill ~55 ~-27 ~62 ~63 ~-27 ~62 stone 0  
fill ~55 ~-27 ~63 ~64 ~-27 ~63 stone 0  
fill ~55 ~-27 ~64 ~106 ~-27 ~64 stone 0  
fill ~55 ~-27 ~65 ~106 ~-27 ~65 stone 0  
fill ~55 ~-27 ~66 ~106 ~-27 ~66 stone 0  
fill ~55 ~-27 ~67 ~106 ~-27 ~67 stone 0  
fill ~55 ~-27 ~68 ~106 ~-27 ~68 stone 0  
fill ~55 ~-27 ~69 ~106 ~-27 ~69 stone 0  
fill ~55 ~-27 ~70 ~106 ~-27 ~70 stone 0  
fill ~55 ~-27 ~71 ~106 ~-27 ~71 stone 0  
fill ~59 ~-27 ~39 ~60 ~-27 ~39 lava 10  
fill ~59 ~-27 ~40 ~60 ~-27 ~40 lava 10  
fill ~59 ~-27 ~41 ~60 ~-27 ~41 lava 10  
fill ~61 ~-27 ~39 ~106 ~-27 ~39 stone 0  
fill ~61 ~-27 ~40 ~106 ~-27 ~40 stone 0  
fill ~61 ~-27 ~41 ~72 ~-27 ~41 stone 0  
fill ~64 ~-27 ~61 ~65 ~-27 ~61 air  
fill ~64 ~-27 ~62 ~65 ~-27 ~62 air  
fill ~65 ~-27 ~60 ~65 ~-26 ~60 air  
fill ~65 ~-27 ~63 ~66 ~-27 ~63 air  
fill ~66 ~-27 ~60 ~66 ~-25 ~60 lava 8  
fill ~67 ~-27 ~55 ~67 ~-26 ~55 lava 10  
fill ~67 ~-27 ~56 ~68 ~-27 ~56 lava 8  
fill ~67 ~-27 ~60 ~106 ~-27 ~60 stone 0  
fill ~67 ~-27 ~61 ~67 ~-25 ~61 lava 8  
fill ~67 ~-27 ~62 ~67 ~-23 ~62 lava 10  
fill ~67 ~-27 ~63 ~106 ~-27 ~63 stone 0  
fill ~68 ~-27 ~55 ~68 ~-26 ~55 lava 8  
fill ~68 ~-27 ~61 ~106 ~-27 ~61 stone 0  
fill ~68 ~-27 ~62 ~106 ~-27 ~62 stone 0  
fill ~69 ~-27 ~55 ~72 ~-27 ~55 stone 0  
fill ~69 ~-27 ~56 ~106 ~-27 ~56 stone 0  
fill ~70 ~-27 ~52 ~70 ~-26 ~52 lava 8  
fill ~71 ~-27 ~51 ~71 ~-26 ~51 lava 8  
fill ~71 ~-27 ~52 ~71 ~-26 ~52 lava 10  
fill ~71 ~-27 ~53 ~71 ~-26 ~53 lava 8  
fill ~72 ~-27 ~51 ~106 ~-27 ~51 stone 0  
fill ~72 ~-27 ~52 ~72 ~-26 ~52 lava 8  
fill ~72 ~-27 ~53 ~106 ~-27 ~53 stone 0  
fill ~73 ~-27 ~41 ~74 ~-27 ~41 lava 8  
fill ~73 ~-27 ~42 ~74 ~-27 ~42 lava 8  
fill ~73 ~-27 ~52 ~106 ~-27 ~52 stone 0  
fill ~73 ~-27 ~54 ~73 ~-27 ~55 netherrack 0  
fill ~74 ~-27 ~54 ~74 ~-26 ~54 lava 8  
fill ~74 ~-27 ~55 ~74 ~-26 ~55 lava 8  
fill ~75 ~-27 ~41 ~80 ~-27 ~41 stone 0  
fill ~75 ~-27 ~42 ~80 ~-27 ~42 stone 0  
fill ~75 ~-27 ~54 ~106 ~-27 ~54 stone 0  
fill ~75 ~-27 ~55 ~106 ~-27 ~55 stone 0  
fill ~78 ~-27 ~44 ~78 ~-27 ~45 netherrack 0  
fill ~79 ~-27 ~43 ~79 ~-26 ~43 air  
fill ~79 ~-27 ~45 ~81 ~-27 ~45 air  
fill ~79 ~-27 ~46 ~80 ~-27 ~46 netherrack 0  
fill ~80 ~-27 ~43 ~80 ~-25 ~43 lava 10 
setblock ~80 ~-27 ~44 lava 2  
fill ~81 ~-27 ~41 ~83 ~-27 ~41 air 
setblock ~81 ~-27 ~42 lava 2 
setblock ~81 ~-27 ~43 lava 0  
fill ~81 ~-27 ~44 ~81 ~-26 ~44 lava 10  
fill ~81 ~-27 ~46 ~106 ~-27 ~46 stone 0  
fill ~82 ~-27 ~42 ~83 ~-27 ~42 air 
setblock ~82 ~-27 ~43 lava 2  
fill ~82 ~-27 ~44 ~106 ~-27 ~44 stone 0  
fill ~82 ~-27 ~45 ~106 ~-27 ~45 stone 0 
setblock ~83 ~-27 ~43 air  
fill ~84 ~-27 ~41 ~106 ~-27 ~41 stone 0  
fill ~84 ~-27 ~42 ~106 ~-27 ~42 stone 0  
fill ~84 ~-27 ~43 ~106 ~-27 ~43 stone 0  
fill ~107 ~-27 ~22 ~181 ~-27 ~22 dirt 0  
fill ~107 ~-27 ~23 ~181 ~-27 ~23 dirt 0  
fill ~107 ~-27 ~24 ~181 ~-27 ~24 dirt 0  
fill ~107 ~-27 ~25 ~181 ~-27 ~25 dirt 0  
fill ~107 ~-27 ~26 ~181 ~-27 ~26 dirt 0  
fill ~107 ~-27 ~27 ~181 ~-27 ~27 dirt 0  
fill ~107 ~-27 ~28 ~181 ~-27 ~28 dirt 0  
fill ~107 ~-27 ~29 ~181 ~-27 ~29 dirt 0  
fill ~107 ~-27 ~30 ~181 ~-27 ~30 dirt 0  
fill ~107 ~-27 ~31 ~181 ~-27 ~31 dirt 0  
fill ~107 ~-27 ~32 ~181 ~-27 ~32 dirt 0  
fill ~107 ~-27 ~33 ~181 ~-27 ~33 dirt 0  
fill ~107 ~-27 ~34 ~181 ~-27 ~34 dirt 0  
fill ~107 ~-27 ~35 ~181 ~-27 ~35 dirt 0  
fill ~107 ~-27 ~36 ~181 ~-27 ~36 dirt 0  
fill ~107 ~-27 ~37 ~181 ~-27 ~37 dirt 0  
fill ~107 ~-27 ~38 ~181 ~-27 ~38 dirt 0  
fill ~107 ~-27 ~39 ~181 ~-27 ~39 dirt 0  
fill ~107 ~-27 ~40 ~181 ~-27 ~40 dirt 0  
fill ~107 ~-27 ~41 ~181 ~-27 ~41 dirt 0  
fill ~107 ~-27 ~42 ~181 ~-27 ~42 dirt 0  
fill ~107 ~-27 ~43 ~181 ~-27 ~43 dirt 0  
fill ~107 ~-27 ~44 ~181 ~-27 ~44 dirt 0  
fill ~107 ~-27 ~45 ~181 ~-27 ~45 dirt 0  
fill ~107 ~-27 ~46 ~181 ~-27 ~46 dirt 0  
fill ~107 ~-27 ~47 ~181 ~-27 ~47 dirt 0  
fill ~107 ~-27 ~48 ~181 ~-27 ~48 dirt 0  
fill ~107 ~-27 ~49 ~159 ~-27 ~49 dirt 0  
fill ~107 ~-27 ~50 ~181 ~-27 ~50 dirt 0  
fill ~107 ~-27 ~51 ~181 ~-27 ~51 dirt 0  
fill ~107 ~-27 ~52 ~181 ~-27 ~52 dirt 0  
fill ~107 ~-27 ~53 ~181 ~-27 ~53 dirt 0  
fill ~107 ~-27 ~54 ~181 ~-27 ~54 dirt 0  
fill ~107 ~-27 ~55 ~159 ~-27 ~55 dirt 0  
fill ~107 ~-27 ~56 ~181 ~-27 ~56 dirt 0  
fill ~107 ~-27 ~57 ~181 ~-27 ~57 dirt 0  
fill ~107 ~-27 ~58 ~181 ~-27 ~58 dirt 0  
fill ~107 ~-27 ~59 ~181 ~-27 ~59 dirt 0  
fill ~107 ~-27 ~60 ~181 ~-27 ~60 dirt 0  
fill ~107 ~-27 ~61 ~181 ~-27 ~61 dirt 0  
fill ~107 ~-27 ~62 ~181 ~-27 ~62 dirt 0  
fill ~107 ~-27 ~63 ~181 ~-27 ~63 dirt 0  
fill ~107 ~-27 ~64 ~181 ~-27 ~64 dirt 0  
fill ~107 ~-27 ~65 ~181 ~-27 ~65 dirt 0  
fill ~107 ~-27 ~66 ~125 ~-27 ~66 dirt 0  
fill ~107 ~-27 ~67 ~181 ~-27 ~67 dirt 0  
summon Sheep ~9.20046160969 ~0.914296876072 ~65.5342193042 
summon Wolf ~10.0776854815 ~0.0 ~67.4485340551 
summon Chicken ~15.6064659107 ~0.0 ~68.0115159589 
summon Pig ~17.1444827089 ~0.0 ~62.7298801228 
summon Wolf ~13.5627292483 ~0.0 ~75.6297380252 
summon Chicken ~23.8477864988 ~0.0 ~80.6567165846 
summon Chicken ~20.8323536416 ~0.0 ~77.5529761599 
summon Sheep ~18.4094597671 ~0.0 ~78.7346385367 
summon Chicken ~24.2819349041 ~0.0 ~86.486430636 
summon Wolf ~40.3544645562 ~0.0 ~69.5975181534 
summon Wolf ~37.6582005254 ~0.0 ~77.0550769797 
summon Chicken ~87.5009535251 ~0.509854812579 ~82.8503418087 
summon Chicken ~106.034453446 ~4.0 ~61.4780177536 
summon Pig ~101.952714398 ~4.0 ~62.2454539069 
summon Sheep ~109.86571461 ~0.0 ~70.2284382279 
summon Sheep ~110.74047572 ~0.0 ~73.6492807356 
summon Sheep ~112.5 ~0.0 ~78.5 
summon Sheep ~110.5 ~0.0 ~77.5 
summon Cow ~157.22080497 ~0.0 ~71.7883691943 
summon Cow ~158.452439283 ~0.0 ~73.3139012129  
fill ~107 ~-27 ~68 ~181 ~-27 ~68 dirt 0  
fill ~107 ~-27 ~69 ~181 ~-27 ~69 dirt 0  
fill ~107 ~-27 ~70 ~134 ~-27 ~70 dirt 0  
fill ~107 ~-27 ~71 ~181 ~-27 ~71 dirt 0  
fill ~107 ~-27 ~72 ~181 ~-27 ~72 dirt 0  
fill ~107 ~-27 ~73 ~181 ~-27 ~73 dirt 0  
fill ~107 ~-27 ~74 ~181 ~-27 ~74 dirt 0  
fill ~107 ~-27 ~75 ~181 ~-27 ~75 dirt 0  
fill ~107 ~-27 ~76 ~181 ~-27 ~76 dirt 0  
fill ~107 ~-27 ~77 ~181 ~-27 ~77 dirt 0  
fill ~107 ~-27 ~78 ~181 ~-27 ~78 dirt 0  
fill ~107 ~-27 ~79 ~181 ~-27 ~79 dirt 0  
fill ~107 ~-27 ~80 ~181 ~-27 ~80 dirt 0  
fill ~107 ~-27 ~81 ~181 ~-27 ~81 dirt 0  
fill ~107 ~-27 ~82 ~181 ~-27 ~82 dirt 0  
fill ~107 ~-27 ~83 ~181 ~-27 ~83 dirt 0  
fill ~107 ~-27 ~84 ~181 ~-27 ~84 dirt 0  
fill ~107 ~-27 ~85 ~181 ~-27 ~85 dirt 0 
setblock ~126 ~-27 ~66 stone 0  
fill ~127 ~-27 ~66 ~181 ~-27 ~66 dirt 0 
setblock ~135 ~-27 ~70 stone 0  
fill ~136 ~-27 ~70 ~181 ~-27 ~70 dirt 0 
setblock ~159 ~-27 ~19 stone 0  
fill ~160 ~-27 ~19 ~181 ~-27 ~19 dirt 0 
setblock ~160 ~-27 ~49 stone 0 
setblock ~160 ~-27 ~55 stone 0  
fill ~161 ~-27 ~49 ~181 ~-27 ~49 dirt 0  
fill ~161 ~-27 ~55 ~181 ~-27 ~55 dirt 0  
fill ~1 ~-26 ~1 ~181 ~-26 ~1 dirt 0  
fill ~1 ~-26 ~2 ~181 ~-26 ~2 dirt 0  
fill ~1 ~-26 ~3 ~181 ~-26 ~3 dirt 0  
fill ~1 ~-26 ~4 ~181 ~-26 ~4 dirt 0  
fill ~1 ~-26 ~5 ~181 ~-26 ~5 dirt 0  
fill ~1 ~-26 ~6 ~181 ~-26 ~6 dirt 0  
fill ~1 ~-26 ~7 ~181 ~-26 ~7 dirt 0  
fill ~1 ~-26 ~8 ~181 ~-26 ~8 dirt 0  
fill ~1 ~-26 ~9 ~181 ~-26 ~9 dirt 0  
fill ~1 ~-26 ~10 ~181 ~-26 ~10 dirt 0  
fill ~1 ~-26 ~11 ~181 ~-26 ~11 dirt 0  
fill ~1 ~-26 ~12 ~181 ~-26 ~12 dirt 0  
fill ~1 ~-26 ~13 ~181 ~-26 ~13 dirt 0  
fill ~1 ~-26 ~14 ~181 ~-26 ~14 dirt 0  
fill ~1 ~-26 ~15 ~181 ~-26 ~15 dirt 0  
fill ~1 ~-26 ~16 ~181 ~-26 ~16 dirt 0  
fill ~1 ~-26 ~17 ~181 ~-26 ~17 dirt 0  
fill ~1 ~-26 ~18 ~181 ~-26 ~18 dirt 0  
fill ~1 ~-26 ~19 ~181 ~-26 ~19 dirt 0  
fill ~1 ~-26 ~20 ~181 ~-26 ~20 dirt 0  
fill ~1 ~-26 ~21 ~181 ~-26 ~21 dirt 0  
fill ~1 ~-26 ~22 ~31 ~-26 ~22 dirt 0  
fill ~1 ~-26 ~23 ~31 ~-26 ~23 dirt 0  
fill ~1 ~-26 ~24 ~31 ~-26 ~24 dirt 0  
fill ~1 ~-26 ~25 ~31 ~-26 ~25 dirt 0  
fill ~1 ~-26 ~26 ~31 ~-26 ~26 dirt 0  
fill ~1 ~-26 ~27 ~31 ~-26 ~27 dirt 0  
fill ~1 ~-26 ~28 ~31 ~-26 ~28 dirt 0  
fill ~1 ~-26 ~29 ~31 ~-26 ~29 dirt 0  
fill ~1 ~-26 ~30 ~31 ~-26 ~30 dirt 0  
fill ~1 ~-26 ~31 ~31 ~-26 ~31 dirt 0  
fill ~1 ~-26 ~32 ~31 ~-26 ~32 dirt 0  
fill ~1 ~-26 ~33 ~31 ~-26 ~33 dirt 0  
fill ~1 ~-26 ~34 ~31 ~-26 ~34 dirt 0  
fill ~1 ~-26 ~35 ~31 ~-26 ~35 dirt 0  
fill ~1 ~-26 ~36 ~31 ~-26 ~36 dirt 0  
fill ~1 ~-26 ~37 ~31 ~-26 ~37 dirt 0  
fill ~1 ~-26 ~38 ~31 ~-26 ~38 dirt 0  
fill ~1 ~-26 ~39 ~31 ~-26 ~39 dirt 0  
fill ~1 ~-26 ~40 ~31 ~-26 ~40 dirt 0  
fill ~1 ~-26 ~41 ~31 ~-26 ~41 dirt 0  
fill ~1 ~-26 ~42 ~31 ~-26 ~42 dirt 0  
fill ~1 ~-26 ~43 ~31 ~-26 ~43 dirt 0  
fill ~1 ~-26 ~44 ~31 ~-26 ~44 dirt 0  
fill ~1 ~-26 ~45 ~31 ~-26 ~45 dirt 0  
fill ~1 ~-26 ~46 ~31 ~-26 ~46 dirt 0  
fill ~1 ~-26 ~47 ~31 ~-26 ~47 dirt 0  
fill ~1 ~-26 ~48 ~31 ~-26 ~48 dirt 0  
fill ~1 ~-26 ~49 ~31 ~-26 ~49 dirt 0  
fill ~1 ~-26 ~50 ~31 ~-26 ~50 dirt 0  
fill ~1 ~-26 ~51 ~31 ~-26 ~51 dirt 0  
fill ~1 ~-26 ~52 ~31 ~-26 ~52 dirt 0  
fill ~1 ~-26 ~53 ~31 ~-26 ~53 dirt 0  
fill ~1 ~-26 ~54 ~31 ~-26 ~54 dirt 0  
fill ~1 ~-26 ~55 ~31 ~-26 ~55 dirt 0  
fill ~1 ~-26 ~56 ~31 ~-26 ~56 dirt 0  
fill ~1 ~-26 ~57 ~31 ~-26 ~57 dirt 0  
fill ~1 ~-26 ~58 ~31 ~-26 ~58 dirt 0  
fill ~1 ~-26 ~59 ~31 ~-26 ~59 dirt 0  
fill ~1 ~-26 ~60 ~31 ~-26 ~60 dirt 0  
fill ~1 ~-26 ~61 ~31 ~-26 ~61 dirt 0  
fill ~1 ~-26 ~62 ~31 ~-26 ~62 dirt 0  
fill ~1 ~-26 ~63 ~31 ~-26 ~63 dirt 0  
fill ~1 ~-26 ~64 ~31 ~-26 ~64 dirt 0  
fill ~1 ~-26 ~65 ~31 ~-26 ~65 dirt 0  
fill ~1 ~-26 ~66 ~31 ~-26 ~66 dirt 0  
fill ~1 ~-26 ~67 ~31 ~-26 ~67 dirt 0  
fill ~1 ~-26 ~68 ~31 ~-26 ~68 dirt 0  
fill ~1 ~-26 ~69 ~31 ~-26 ~69 dirt 0  
fill ~1 ~-26 ~70 ~31 ~-26 ~70 dirt 0  
fill ~1 ~-26 ~71 ~31 ~-26 ~71 dirt 0  
fill ~1 ~-26 ~72 ~31 ~-26 ~72 dirt 0  
fill ~1 ~-26 ~73 ~31 ~-26 ~73 dirt 0  
fill ~1 ~-26 ~74 ~31 ~-26 ~74 dirt 0  
fill ~1 ~-26 ~75 ~31 ~-26 ~75 dirt 0  
fill ~1 ~-26 ~76 ~31 ~-26 ~76 dirt 0  
fill ~1 ~-26 ~77 ~31 ~-26 ~77 dirt 0  
fill ~1 ~-26 ~78 ~31 ~-26 ~78 dirt 0  
fill ~1 ~-26 ~79 ~31 ~-26 ~79 dirt 0  
fill ~1 ~-26 ~80 ~31 ~-26 ~80 dirt 0  
fill ~1 ~-26 ~81 ~31 ~-26 ~81 dirt 0  
fill ~1 ~-26 ~82 ~31 ~-26 ~82 dirt 0  
fill ~1 ~-26 ~83 ~31 ~-26 ~83 dirt 0  
fill ~1 ~-26 ~84 ~31 ~-26 ~84 dirt 0  
fill ~1 ~-26 ~85 ~31 ~-26 ~85 dirt 0  
fill ~1 ~-26 ~86 ~181 ~-26 ~86 dirt 0  
fill ~1 ~-26 ~87 ~181 ~-26 ~87 dirt 0  
fill ~1 ~-26 ~88 ~181 ~-26 ~88 dirt 0  
fill ~1 ~-26 ~89 ~181 ~-26 ~89 dirt 0  
fill ~1 ~-26 ~90 ~181 ~-26 ~90 dirt 0  
fill ~1 ~-26 ~91 ~181 ~-26 ~91 dirt 0  
fill ~1 ~-26 ~92 ~181 ~-26 ~92 dirt 0  
fill ~1 ~-26 ~93 ~181 ~-26 ~93 dirt 0  
fill ~1 ~-26 ~94 ~181 ~-26 ~94 dirt 0  
fill ~1 ~-26 ~95 ~181 ~-26 ~95 dirt 0  
fill ~1 ~-26 ~96 ~181 ~-26 ~96 dirt 0  
fill ~1 ~-26 ~97 ~181 ~-26 ~97 dirt 0  
fill ~1 ~-26 ~98 ~181 ~-26 ~98 dirt 0  
fill ~1 ~-26 ~99 ~181 ~-26 ~99 dirt 0  
fill ~1 ~-26 ~100 ~181 ~-26 ~100 dirt 0  
fill ~32 ~-26 ~22 ~106 ~-26 ~22 stone 0  
fill ~32 ~-26 ~23 ~106 ~-26 ~23 stone 0  
fill ~32 ~-26 ~24 ~106 ~-26 ~24 stone 0  
fill ~32 ~-26 ~25 ~106 ~-26 ~25 stone 0  
fill ~32 ~-26 ~26 ~106 ~-26 ~26 stone 0  
fill ~32 ~-26 ~27 ~106 ~-26 ~27 stone 0  
fill ~32 ~-26 ~28 ~106 ~-26 ~28 stone 0  
fill ~32 ~-26 ~29 ~106 ~-26 ~29 stone 0  
fill ~32 ~-26 ~30 ~52 ~-26 ~30 stone 0  
fill ~32 ~-26 ~31 ~52 ~-26 ~31 stone 0  
fill ~32 ~-26 ~32 ~52 ~-26 ~32 stone 0  
fill ~32 ~-26 ~33 ~52 ~-26 ~33 stone 0  
fill ~32 ~-26 ~34 ~52 ~-26 ~34 stone 0  
fill ~32 ~-26 ~35 ~52 ~-26 ~35 stone 0  
fill ~32 ~-26 ~36 ~52 ~-26 ~36 stone 0  
fill ~32 ~-26 ~37 ~52 ~-26 ~37 stone 0  
fill ~32 ~-26 ~38 ~52 ~-26 ~38 stone 0  
fill ~32 ~-26 ~39 ~52 ~-26 ~39 stone 0  
fill ~32 ~-26 ~40 ~52 ~-26 ~40 stone 0  
fill ~32 ~-26 ~41 ~52 ~-26 ~41 stone 0  
fill ~32 ~-26 ~42 ~52 ~-26 ~42 stone 0  
fill ~32 ~-26 ~43 ~52 ~-26 ~43 stone 0  
fill ~32 ~-26 ~44 ~52 ~-26 ~44 stone 0  
fill ~32 ~-26 ~45 ~52 ~-26 ~45 stone 0  
fill ~32 ~-26 ~46 ~52 ~-26 ~46 stone 0  
fill ~32 ~-26 ~47 ~52 ~-26 ~47 stone 0  
fill ~32 ~-26 ~48 ~52 ~-26 ~48 stone 0  
fill ~32 ~-26 ~49 ~52 ~-26 ~49 stone 0  
fill ~32 ~-26 ~50 ~52 ~-26 ~50 stone 0  
fill ~32 ~-26 ~51 ~52 ~-26 ~51 stone 0  
fill ~32 ~-26 ~52 ~52 ~-26 ~52 stone 0  
fill ~32 ~-26 ~53 ~52 ~-26 ~53 stone 0  
fill ~32 ~-26 ~54 ~52 ~-26 ~54 stone 0  
fill ~32 ~-26 ~55 ~52 ~-26 ~55 stone 0  
fill ~32 ~-26 ~56 ~52 ~-26 ~56 stone 0  
fill ~32 ~-26 ~57 ~52 ~-26 ~57 stone 0  
fill ~32 ~-26 ~58 ~52 ~-26 ~58 stone 0  
fill ~32 ~-26 ~59 ~52 ~-26 ~59 stone 0  
fill ~32 ~-26 ~60 ~52 ~-26 ~60 stone 0  
fill ~32 ~-26 ~61 ~46 ~-26 ~61 stone 0  
fill ~32 ~-26 ~62 ~46 ~-26 ~62 stone 0  
fill ~32 ~-26 ~63 ~46 ~-26 ~63 stone 0  
fill ~32 ~-26 ~64 ~52 ~-26 ~64 stone 0  
fill ~32 ~-26 ~65 ~52 ~-26 ~65 stone 0  
fill ~32 ~-26 ~66 ~52 ~-26 ~66 stone 0  
fill ~32 ~-26 ~67 ~52 ~-26 ~67 stone 0  
fill ~32 ~-26 ~68 ~52 ~-26 ~68 stone 0  
fill ~32 ~-26 ~69 ~52 ~-26 ~69 stone 0  
fill ~32 ~-26 ~70 ~52 ~-26 ~70 stone 0  
fill ~32 ~-26 ~71 ~106 ~-26 ~71 stone 0  
fill ~32 ~-26 ~72 ~106 ~-26 ~72 stone 0  
fill ~32 ~-26 ~73 ~106 ~-26 ~73 stone 0  
fill ~32 ~-26 ~74 ~106 ~-26 ~74 stone 0  
fill ~32 ~-26 ~75 ~106 ~-26 ~75 stone 0  
fill ~32 ~-26 ~76 ~106 ~-26 ~76 stone 0  
fill ~32 ~-26 ~77 ~106 ~-26 ~77 stone 0  
fill ~32 ~-26 ~78 ~106 ~-26 ~78 stone 0  
fill ~32 ~-26 ~79 ~106 ~-26 ~79 stone 0  
fill ~32 ~-26 ~80 ~106 ~-26 ~80 stone 0  
fill ~32 ~-26 ~81 ~106 ~-26 ~81 stone 0  
fill ~32 ~-26 ~82 ~106 ~-26 ~82 stone 0  
fill ~32 ~-26 ~83 ~106 ~-26 ~83 stone 0  
fill ~32 ~-26 ~84 ~106 ~-26 ~84 stone 0  
fill ~32 ~-26 ~85 ~106 ~-26 ~85 stone 0 
setblock ~47 ~-26 ~61 lava 4 
setblock ~47 ~-26 ~62 lava 6  
fill ~47 ~-26 ~63 ~47 ~-20 ~63 air 
setblock ~48 ~-26 ~61 lava 2 
setblock ~48 ~-26 ~62 lava 4 
setblock ~48 ~-26 ~63 lava 6 
setblock ~49 ~-26 ~61 lava 12 
setblock ~49 ~-26 ~62 lava 2 
setblock ~49 ~-26 ~63 lava 4  
fill ~50 ~-26 ~61 ~52 ~-26 ~61 stone 0 
setblock ~50 ~-26 ~62 lava 12  
fill ~50 ~-26 ~63 ~52 ~-26 ~63 stone 0  
fill ~51 ~-26 ~62 ~52 ~-26 ~62 stone 0  
fill ~53 ~-26 ~30 ~87 ~-26 ~30 netherrack 0  
fill ~53 ~-26 ~31 ~87 ~-26 ~31 netherrack 0  
fill ~53 ~-26 ~32 ~63 ~-26 ~32 netherrack 0  
fill ~53 ~-26 ~33 ~87 ~-26 ~33 netherrack 0  
fill ~53 ~-26 ~34 ~87 ~-26 ~34 netherrack 0  
fill ~53 ~-26 ~35 ~75 ~-26 ~35 netherrack 0  
fill ~53 ~-26 ~36 ~87 ~-26 ~36 netherrack 0  
fill ~53 ~-26 ~37 ~87 ~-26 ~37 netherrack 0  
fill ~53 ~-26 ~38 ~60 ~-26 ~38 netherrack 0  
fill ~53 ~-26 ~39 ~58 ~-26 ~39 netherrack 0  
fill ~53 ~-26 ~40 ~58 ~-26 ~40 netherrack 0  
fill ~53 ~-26 ~41 ~58 ~-26 ~41 netherrack 0  
fill ~53 ~-26 ~42 ~58 ~-26 ~42 netherrack 0  
fill ~53 ~-26 ~43 ~63 ~-26 ~43 netherrack 0  
fill ~53 ~-26 ~44 ~63 ~-26 ~44 netherrack 0  
fill ~53 ~-26 ~45 ~63 ~-26 ~45 netherrack 0  
fill ~53 ~-26 ~46 ~68 ~-26 ~46 netherrack 0  
fill ~53 ~-26 ~47 ~53 ~-26 ~54 netherrack 0  
fill ~53 ~-26 ~55 ~53 ~-22 ~55 lava 10 
setblock ~53 ~-26 ~56 lava 2  
fill ~53 ~-26 ~57 ~53 ~-24 ~57 lava 10  
fill ~53 ~-26 ~58 ~87 ~-26 ~58 netherrack 0  
fill ~53 ~-26 ~59 ~87 ~-26 ~59 netherrack 0  
fill ~53 ~-26 ~60 ~60 ~-26 ~60 netherrack 0  
fill ~53 ~-26 ~61 ~63 ~-26 ~61 netherrack 0  
fill ~53 ~-26 ~62 ~63 ~-26 ~62 netherrack 0  
fill ~53 ~-26 ~63 ~64 ~-26 ~63 netherrack 0  
fill ~53 ~-26 ~64 ~87 ~-26 ~64 netherrack 0  
fill ~53 ~-26 ~65 ~87 ~-26 ~65 netherrack 0  
fill ~53 ~-26 ~66 ~87 ~-26 ~66 netherrack 0  
fill ~53 ~-26 ~67 ~87 ~-26 ~67 netherrack 0  
fill ~53 ~-26 ~68 ~87 ~-26 ~68 netherrack 0  
fill ~53 ~-26 ~69 ~87 ~-26 ~69 netherrack 0  
fill ~53 ~-26 ~70 ~87 ~-26 ~70 netherrack 0 
setblock ~54 ~-26 ~47 lava 10 
setblock ~54 ~-26 ~48 lava 2 
setblock ~54 ~-26 ~49 lava 4  
fill ~54 ~-26 ~50 ~63 ~-26 ~50 netherrack 0  
fill ~54 ~-26 ~51 ~64 ~-26 ~51 netherrack 0  
fill ~54 ~-26 ~52 ~68 ~-26 ~52 netherrack 0  
fill ~54 ~-26 ~53 ~68 ~-26 ~53 netherrack 0  
fill ~54 ~-26 ~54 ~66 ~-26 ~54 netherrack 0  
fill ~54 ~-26 ~55 ~65 ~-26 ~55 netherrack 0  
fill ~54 ~-26 ~56 ~65 ~-26 ~56 netherrack 0  
fill ~54 ~-26 ~57 ~66 ~-26 ~57 netherrack 0  
fill ~55 ~-26 ~47 ~58 ~-26 ~47 netherrack 0  
fill ~55 ~-26 ~48 ~58 ~-26 ~48 netherrack 0 
setblock ~55 ~-26 ~49 lava 6 
setblock ~56 ~-26 ~49 netherrack 0 
setblock ~57 ~-26 ~49 glowstone 0 
setblock ~58 ~-26 ~49 netherrack 0  
fill ~59 ~-26 ~39 ~61 ~-26 ~39 lava 10  
fill ~59 ~-26 ~40 ~59 ~-27 ~40 lava 10  
fill ~59 ~-26 ~41 ~59 ~-27 ~41 lava 10 
setblock ~59 ~-26 ~42 lava 12  
fill ~59 ~-26 ~47 ~60 ~-26 ~47 lava 10 
setblock ~59 ~-26 ~48 lava 12  
fill ~59 ~-26 ~49 ~60 ~-26 ~49 lava 10  
fill ~60 ~-26 ~40 ~60 ~-26 ~41 lava 2  
fill ~60 ~-26 ~42 ~61 ~-26 ~42 lava 10 
setblock ~60 ~-26 ~48 lava 10  
fill ~61 ~-26 ~38 ~61 ~-25 ~38 lava 10  
fill ~61 ~-26 ~40 ~61 ~-26 ~42 lava 10  
fill ~61 ~-26 ~47 ~68 ~-26 ~47 netherrack 0  
fill ~61 ~-26 ~48 ~67 ~-26 ~48 netherrack 0  
fill ~61 ~-26 ~49 ~64 ~-26 ~49 netherrack 0 
setblock ~61 ~-26 ~60 stone 0  
fill ~62 ~-26 ~38 ~87 ~-26 ~38 netherrack 0  
fill ~62 ~-26 ~39 ~87 ~-26 ~39 netherrack 0  
fill ~62 ~-26 ~40 ~72 ~-26 ~40 netherrack 0  
fill ~62 ~-26 ~41 ~71 ~-26 ~41 netherrack 0  
fill ~62 ~-26 ~42 ~71 ~-26 ~42 netherrack 0  
fill ~62 ~-26 ~60 ~64 ~-26 ~60 netherrack 0 
setblock ~64 ~-26 ~32 stone 0 
setblock ~64 ~-26 ~43 lava 2  
fill ~64 ~-26 ~44 ~67 ~-26 ~44 lava 8  
fill ~64 ~-26 ~45 ~64 ~-25 ~45 lava 8  
fill ~64 ~-26 ~50 ~66 ~-26 ~50 lava 8  
fill ~64 ~-26 ~61 ~65 ~-26 ~61 air  
fill ~64 ~-26 ~62 ~65 ~-26 ~62 air  
fill ~65 ~-26 ~32 ~87 ~-26 ~32 netherrack 0 
setblock ~65 ~-26 ~43 netherrack 0  
fill ~65 ~-26 ~45 ~65 ~-24 ~45 netherrack 0  
fill ~65 ~-26 ~49 ~65 ~-25 ~49 lava 8  
fill ~65 ~-26 ~51 ~65 ~-25 ~51 lava 8  
fill ~65 ~-26 ~63 ~66 ~-26 ~63 air  
fill ~66 ~-26 ~43 ~66 ~-24 ~43 lava 8 
setblock ~66 ~-26 ~45 lava 8  
fill ~66 ~-26 ~49 ~67 ~-26 ~49 netherrack 0  
fill ~66 ~-26 ~51 ~67 ~-26 ~51 netherrack 0  
fill ~66 ~-26 ~55 ~66 ~-24 ~55 lava 10  
fill ~66 ~-26 ~56 ~68 ~-26 ~56 lava 8  
fill ~67 ~-26 ~43 ~72 ~-26 ~43 netherrack 0  
fill ~67 ~-26 ~45 ~70 ~-26 ~45 netherrack 0 
setblock ~67 ~-26 ~50 netherrack 0  
fill ~67 ~-26 ~54 ~67 ~-25 ~54 lava 10  
fill ~67 ~-26 ~57 ~68 ~-26 ~57 lava 10  
fill ~67 ~-26 ~60 ~87 ~-26 ~60 netherrack 0  
fill ~67 ~-26 ~63 ~87 ~-26 ~63 netherrack 0  
fill ~68 ~-26 ~44 ~77 ~-26 ~44 netherrack 0  
fill ~68 ~-26 ~48 ~68 ~-26 ~51 lava 10  
fill ~68 ~-26 ~54 ~68 ~-25 ~54 lava 8  
fill ~68 ~-26 ~61 ~87 ~-26 ~61 netherrack 0  
fill ~68 ~-26 ~62 ~87 ~-26 ~62 netherrack 0  
fill ~69 ~-26 ~46 ~70 ~-26 ~46 lava 10  
fill ~69 ~-26 ~47 ~69 ~-26 ~46 lava 10  
fill ~69 ~-26 ~48 ~70 ~-26 ~48 lava 2  
fill ~69 ~-26 ~49 ~70 ~-26 ~49 lava 2  
fill ~69 ~-26 ~50 ~69 ~-26 ~48 lava 2  
fill ~69 ~-26 ~51 ~70 ~-26 ~51 lava 10  
fill ~69 ~-26 ~52 ~69 ~-26 ~53 lava 8  
fill ~69 ~-26 ~54 ~71 ~-26 ~54 netherrack 0 
setblock ~69 ~-26 ~55 lava 10  
fill ~69 ~-26 ~56 ~69 ~-25 ~56 lava 0  
fill ~69 ~-26 ~57 ~87 ~-26 ~57 netherrack 0 
setblock ~70 ~-26 ~47 lava 2 
setblock ~70 ~-26 ~50 lava 10 
setblock ~70 ~-26 ~53 lava 8  
fill ~70 ~-26 ~55 ~71 ~-26 ~55 netherrack 0  
fill ~70 ~-26 ~56 ~72 ~-26 ~56 netherrack 0  
fill ~71 ~-26 ~45 ~73 ~-26 ~45 lava 10 
setblock ~71 ~-26 ~46 lava 2  
fill ~71 ~-26 ~47 ~71 ~-26 ~48 lava 10  
fill ~71 ~-26 ~49 ~71 ~-25 ~49 netherrack 0  
fill ~71 ~-26 ~50 ~71 ~-25 ~50 lava 0  
fill ~72 ~-26 ~41 ~75 ~-26 ~41 lava 8  
fill ~72 ~-26 ~42 ~75 ~-26 ~42 lava 8 
setblock ~72 ~-26 ~46 lava 10  
fill ~72 ~-26 ~47 ~76 ~-26 ~47 lava 8  
fill ~72 ~-26 ~48 ~73 ~-26 ~48 lava 8  
fill ~72 ~-26 ~49 ~76 ~-26 ~49 lava 8  
fill ~72 ~-26 ~50 ~75 ~-26 ~50 lava 8  
fill ~72 ~-26 ~51 ~73 ~-26 ~51 lava 8  
fill ~72 ~-26 ~53 ~73 ~-26 ~53 lava 10 
setblock ~72 ~-26 ~54 lava 12  
fill ~72 ~-26 ~55 ~73 ~-26 ~55 lava 10  
fill ~73 ~-26 ~40 ~74 ~-26 ~40 lava 10  
fill ~73 ~-26 ~43 ~74 ~-26 ~43 lava 10  
fill ~73 ~-26 ~46 ~75 ~-26 ~46 lava 8  
fill ~73 ~-26 ~52 ~75 ~-26 ~52 lava 8 
setblock ~73 ~-26 ~54 lava 10 
setblock ~73 ~-26 ~56 lava 2 
setblock ~74 ~-26 ~45 lava 8  
fill ~74 ~-26 ~48 ~74 ~-25 ~48 lava 0  
fill ~74 ~-26 ~51 ~74 ~-25 ~51 lava 0 
setblock ~74 ~-26 ~53 lava 8 
setblock ~74 ~-26 ~56 lava 10  
fill ~75 ~-26 ~40 ~87 ~-26 ~40 netherrack 0  
fill ~75 ~-26 ~43 ~78 ~-26 ~43 netherrack 0  
fill ~75 ~-26 ~45 ~77 ~-26 ~45 netherrack 0  
fill ~75 ~-26 ~48 ~76 ~-26 ~48 lava 8 
setblock ~75 ~-26 ~51 lava 8  
fill ~75 ~-26 ~53 ~75 ~-25 ~53 netherrack 0  
fill ~75 ~-26 ~54 ~75 ~-25 ~54 lava 10  
fill ~75 ~-26 ~55 ~75 ~-25 ~55 lava 8 
setblock ~75 ~-26 ~56 netherrack 0 
setblock ~76 ~-26 ~35 stone 0  
fill ~76 ~-26 ~41 ~81 ~-26 ~41 netherrack 0  
fill ~76 ~-26 ~42 ~80 ~-26 ~42 netherrack 0 
setblock ~76 ~-26 ~46 lava 10  
fill ~76 ~-26 ~50 ~76 ~-26 ~53 lava 10  
fill ~76 ~-26 ~54 ~87 ~-26 ~54 netherrack 0  
fill ~76 ~-26 ~55 ~87 ~-26 ~55 netherrack 0 
setblock ~76 ~-26 ~56 stone 0  
fill ~77 ~-26 ~35 ~87 ~-26 ~35 netherrack 0  
fill ~77 ~-26 ~46 ~78 ~-26 ~46 netherrack 0  
fill ~77 ~-26 ~47 ~87 ~-26 ~47 netherrack 0  
fill ~77 ~-26 ~48 ~77 ~-26 ~49 lava 10  
fill ~77 ~-26 ~50 ~77 ~-26 ~51 lava 2  
fill ~77 ~-26 ~52 ~87 ~-26 ~52 netherrack 0  
fill ~77 ~-26 ~53 ~87 ~-26 ~53 netherrack 0  
fill ~77 ~-26 ~56 ~87 ~-26 ~56 netherrack 0 
setblock ~78 ~-26 ~44 lava 10 
setblock ~78 ~-26 ~45 fire 15  
fill ~78 ~-26 ~48 ~87 ~-26 ~48 netherrack 0  
fill ~78 ~-26 ~49 ~87 ~-26 ~49 netherrack 0  
fill ~78 ~-26 ~50 ~87 ~-26 ~50 netherrack 0  
fill ~78 ~-26 ~51 ~78 ~-26 ~46 netherrack 0  
fill ~79 ~-26 ~45 ~81 ~-26 ~45 air 
setblock ~79 ~-26 ~46 fire 15 
setblock ~79 ~-26 ~51 glowstone 0  
fill ~80 ~-26 ~44 ~80 ~-11 ~44 air  
fill ~80 ~-26 ~46 ~80 ~-12 ~46 air  
fill ~80 ~-26 ~51 ~87 ~-26 ~51 netherrack 0  
fill ~81 ~-26 ~42 ~83 ~-26 ~42 air 
setblock ~81 ~-26 ~43 netherrack 0 
setblock ~81 ~-26 ~46 glowstone 0 
setblock ~82 ~-26 ~41 air 
setblock ~82 ~-26 ~43 air  
fill ~82 ~-26 ~44 ~82 ~-29 ~44 stone 0  
fill ~82 ~-26 ~45 ~82 ~-29 ~45 stone 0  
fill ~82 ~-26 ~46 ~87 ~-26 ~46 netherrack 0  
fill ~83 ~-26 ~41 ~87 ~-26 ~41 netherrack 0  
fill ~83 ~-26 ~43 ~87 ~-26 ~43 netherrack 0  
fill ~83 ~-26 ~44 ~87 ~-26 ~44 netherrack 0  
fill ~83 ~-26 ~45 ~87 ~-26 ~45 netherrack 0  
fill ~84 ~-26 ~42 ~84 ~-25 ~42 netherrack 0 
setblock ~85 ~-26 ~42 stone 0  
fill ~86 ~-26 ~42 ~87 ~-26 ~42 netherrack 0  
fill ~88 ~-26 ~30 ~106 ~-26 ~30 stone 0  
fill ~88 ~-26 ~31 ~106 ~-26 ~31 stone 0  
fill ~88 ~-26 ~32 ~106 ~-26 ~32 stone 0  
fill ~88 ~-26 ~33 ~106 ~-26 ~33 stone 0  
fill ~88 ~-26 ~34 ~106 ~-26 ~34 stone 0  
fill ~88 ~-26 ~35 ~106 ~-26 ~35 stone 0  
fill ~88 ~-26 ~36 ~106 ~-26 ~36 stone 0  
fill ~88 ~-26 ~37 ~106 ~-26 ~37 stone 0  
fill ~88 ~-26 ~38 ~106 ~-26 ~38 stone 0  
fill ~88 ~-26 ~39 ~106 ~-26 ~39 stone 0  
fill ~88 ~-26 ~40 ~106 ~-26 ~40 stone 0  
fill ~88 ~-26 ~41 ~106 ~-26 ~41 stone 0  
fill ~88 ~-26 ~42 ~106 ~-26 ~42 stone 0  
fill ~88 ~-26 ~43 ~106 ~-26 ~43 stone 0  
fill ~88 ~-26 ~44 ~106 ~-26 ~44 stone 0  
fill ~88 ~-26 ~45 ~106 ~-26 ~45 stone 0  
fill ~88 ~-26 ~46 ~106 ~-26 ~46 stone 0  
fill ~88 ~-26 ~47 ~106 ~-26 ~47 stone 0  
fill ~88 ~-26 ~48 ~106 ~-26 ~48 stone 0  
fill ~88 ~-26 ~49 ~106 ~-26 ~49 stone 0  
fill ~88 ~-26 ~50 ~106 ~-26 ~50 stone 0  
fill ~88 ~-26 ~51 ~106 ~-26 ~51 stone 0  
fill ~88 ~-26 ~52 ~106 ~-26 ~52 stone 0  
fill ~88 ~-26 ~53 ~106 ~-26 ~53 stone 0  
fill ~88 ~-26 ~54 ~106 ~-26 ~54 stone 0  
fill ~88 ~-26 ~55 ~106 ~-26 ~55 stone 0  
fill ~88 ~-26 ~56 ~106 ~-26 ~56 stone 0  
fill ~88 ~-26 ~57 ~106 ~-26 ~57 stone 0  
fill ~88 ~-26 ~58 ~106 ~-26 ~58 stone 0  
fill ~88 ~-26 ~59 ~106 ~-26 ~59 stone 0  
fill ~88 ~-26 ~60 ~106 ~-26 ~60 stone 0  
fill ~88 ~-26 ~61 ~106 ~-26 ~61 stone 0  
fill ~88 ~-26 ~62 ~106 ~-26 ~62 stone 0  
fill ~88 ~-26 ~63 ~106 ~-26 ~63 stone 0  
fill ~88 ~-26 ~64 ~106 ~-26 ~64 stone 0  
fill ~88 ~-26 ~65 ~106 ~-26 ~65 stone 0  
fill ~88 ~-26 ~66 ~106 ~-26 ~66 stone 0  
fill ~88 ~-26 ~67 ~106 ~-26 ~67 stone 0  
fill ~88 ~-26 ~68 ~106 ~-26 ~68 stone 0  
fill ~88 ~-26 ~69 ~106 ~-26 ~69 stone 0  
fill ~88 ~-26 ~70 ~106 ~-26 ~70 stone 0  
fill ~107 ~-26 ~22 ~181 ~-26 ~22 dirt 0  
fill ~107 ~-26 ~23 ~181 ~-26 ~23 dirt 0  
fill ~107 ~-26 ~24 ~181 ~-26 ~24 dirt 0  
fill ~107 ~-26 ~25 ~181 ~-26 ~25 dirt 0  
fill ~107 ~-26 ~26 ~181 ~-26 ~26 dirt 0  
fill ~107 ~-26 ~27 ~181 ~-26 ~27 dirt 0  
fill ~107 ~-26 ~28 ~181 ~-26 ~28 dirt 0  
fill ~107 ~-26 ~29 ~181 ~-26 ~29 dirt 0  
fill ~107 ~-26 ~30 ~181 ~-26 ~30 dirt 0  
fill ~107 ~-26 ~31 ~181 ~-26 ~31 dirt 0  
fill ~107 ~-26 ~32 ~181 ~-26 ~32 dirt 0  
fill ~107 ~-26 ~33 ~181 ~-26 ~33 dirt 0  
fill ~107 ~-26 ~34 ~181 ~-26 ~34 dirt 0  
fill ~107 ~-26 ~35 ~181 ~-26 ~35 dirt 0  
fill ~107 ~-26 ~36 ~181 ~-26 ~36 dirt 0  
fill ~107 ~-26 ~37 ~181 ~-26 ~37 dirt 0  
fill ~107 ~-26 ~38 ~181 ~-26 ~38 dirt 0  
fill ~107 ~-26 ~39 ~181 ~-26 ~39 dirt 0  
fill ~107 ~-26 ~40 ~181 ~-26 ~40 dirt 0  
fill ~107 ~-26 ~41 ~181 ~-26 ~41 dirt 0  
fill ~107 ~-26 ~42 ~181 ~-26 ~42 dirt 0  
fill ~107 ~-26 ~43 ~181 ~-26 ~43 dirt 0  
fill ~107 ~-26 ~44 ~181 ~-26 ~44 dirt 0  
fill ~107 ~-26 ~45 ~181 ~-26 ~45 dirt 0  
fill ~107 ~-26 ~46 ~181 ~-26 ~46 dirt 0  
fill ~107 ~-26 ~47 ~181 ~-26 ~47 dirt 0  
fill ~107 ~-26 ~48 ~181 ~-26 ~48 dirt 0  
fill ~107 ~-26 ~49 ~181 ~-26 ~49 dirt 0  
fill ~107 ~-26 ~50 ~181 ~-26 ~50 dirt 0  
fill ~107 ~-26 ~51 ~181 ~-26 ~51 dirt 0  
fill ~107 ~-26 ~52 ~181 ~-26 ~52 dirt 0  
fill ~107 ~-26 ~53 ~181 ~-26 ~53 dirt 0  
fill ~107 ~-26 ~54 ~181 ~-26 ~54 dirt 0  
fill ~107 ~-26 ~55 ~181 ~-26 ~55 dirt 0  
fill ~107 ~-26 ~56 ~181 ~-26 ~56 dirt 0  
fill ~107 ~-26 ~57 ~181 ~-26 ~57 dirt 0  
fill ~107 ~-26 ~58 ~181 ~-26 ~58 dirt 0  
fill ~107 ~-26 ~59 ~124 ~-26 ~59 dirt 0  
fill ~107 ~-26 ~60 ~181 ~-26 ~60 dirt 0  
fill ~107 ~-26 ~61 ~181 ~-26 ~61 dirt 0  
fill ~107 ~-26 ~62 ~181 ~-26 ~62 dirt 0  
fill ~107 ~-26 ~63 ~181 ~-26 ~63 dirt 0  
fill ~107 ~-26 ~64 ~181 ~-26 ~64 dirt 0  
fill ~107 ~-26 ~65 ~181 ~-26 ~65 dirt 0  
fill ~107 ~-26 ~66 ~181 ~-26 ~66 dirt 0  
fill ~107 ~-26 ~67 ~181 ~-26 ~67 dirt 0  
fill ~107 ~-26 ~68 ~181 ~-26 ~68 dirt 0  
fill ~107 ~-26 ~69 ~181 ~-26 ~69 dirt 0  
fill ~107 ~-26 ~70 ~181 ~-26 ~70 dirt 0  
fill ~107 ~-26 ~71 ~181 ~-26 ~71 dirt 0  
fill ~107 ~-26 ~72 ~181 ~-26 ~72 dirt 0  
fill ~107 ~-26 ~73 ~181 ~-26 ~73 dirt 0  
fill ~107 ~-26 ~74 ~181 ~-26 ~74 dirt 0  
fill ~107 ~-26 ~75 ~181 ~-26 ~75 dirt 0  
fill ~107 ~-26 ~76 ~181 ~-26 ~76 dirt 0  
fill ~107 ~-26 ~77 ~181 ~-26 ~77 dirt 0  
fill ~107 ~-26 ~78 ~181 ~-26 ~78 dirt 0  
fill ~107 ~-26 ~79 ~181 ~-26 ~79 dirt 0  
fill ~107 ~-26 ~80 ~181 ~-26 ~80 dirt 0  
fill ~107 ~-26 ~81 ~181 ~-26 ~81 dirt 0  
fill ~107 ~-26 ~82 ~181 ~-26 ~82 dirt 0  
fill ~107 ~-26 ~83 ~181 ~-26 ~83 dirt 0  
fill ~107 ~-26 ~84 ~181 ~-26 ~84 dirt 0  
fill ~107 ~-26 ~85 ~181 ~-26 ~85 dirt 0 
setblock ~125 ~-26 ~59 stone 0  
fill ~126 ~-26 ~59 ~181 ~-26 ~59 dirt 0  
fill ~1 ~-25 ~1 ~181 ~-25 ~1 dirt 0  
fill ~1 ~-25 ~2 ~181 ~-25 ~2 dirt 0  
fill ~1 ~-25 ~3 ~181 ~-25 ~3 dirt 0  
fill ~1 ~-25 ~4 ~181 ~-25 ~4 dirt 0  
fill ~1 ~-25 ~5 ~181 ~-25 ~5 dirt 0  
fill ~1 ~-25 ~6 ~181 ~-25 ~6 dirt 0  
fill ~1 ~-25 ~7 ~181 ~-25 ~7 dirt 0  
fill ~1 ~-25 ~8 ~181 ~-25 ~8 dirt 0  
fill ~1 ~-25 ~9 ~181 ~-25 ~9 dirt 0  
fill ~1 ~-25 ~10 ~181 ~-25 ~10 dirt 0  
fill ~1 ~-25 ~11 ~181 ~-25 ~11 dirt 0  
fill ~1 ~-25 ~12 ~181 ~-25 ~12 dirt 0  
fill ~1 ~-25 ~13 ~181 ~-25 ~13 dirt 0  
fill ~1 ~-25 ~14 ~181 ~-25 ~14 dirt 0  
fill ~1 ~-25 ~15 ~181 ~-25 ~15 dirt 0  
fill ~1 ~-25 ~16 ~181 ~-25 ~16 dirt 0  
fill ~1 ~-25 ~17 ~97 ~-25 ~17 dirt 0  
fill ~1 ~-25 ~18 ~181 ~-25 ~18 dirt 0  
fill ~1 ~-25 ~19 ~181 ~-25 ~19 dirt 0  
fill ~1 ~-25 ~20 ~181 ~-25 ~20 dirt 0  
fill ~1 ~-25 ~21 ~181 ~-25 ~21 dirt 0  
fill ~1 ~-25 ~22 ~31 ~-25 ~22 dirt 0  
fill ~1 ~-25 ~23 ~31 ~-25 ~23 dirt 0  
fill ~1 ~-25 ~24 ~31 ~-25 ~24 dirt 0  
fill ~1 ~-25 ~25 ~31 ~-25 ~25 dirt 0  
fill ~1 ~-25 ~26 ~31 ~-25 ~26 dirt 0  
fill ~1 ~-25 ~27 ~31 ~-25 ~27 dirt 0  
fill ~1 ~-25 ~28 ~31 ~-25 ~28 dirt 0  
fill ~1 ~-25 ~29 ~31 ~-25 ~29 dirt 0  
fill ~1 ~-25 ~30 ~31 ~-25 ~30 dirt 0  
fill ~1 ~-25 ~31 ~31 ~-25 ~31 dirt 0  
fill ~1 ~-25 ~32 ~31 ~-25 ~32 dirt 0  
fill ~1 ~-25 ~33 ~31 ~-25 ~33 dirt 0  
fill ~1 ~-25 ~34 ~31 ~-25 ~34 dirt 0  
fill ~1 ~-25 ~35 ~31 ~-25 ~35 dirt 0  
fill ~1 ~-25 ~36 ~31 ~-25 ~36 dirt 0  
fill ~1 ~-25 ~37 ~31 ~-25 ~37 dirt 0  
fill ~1 ~-25 ~38 ~31 ~-25 ~38 dirt 0  
fill ~1 ~-25 ~39 ~31 ~-25 ~39 dirt 0  
fill ~1 ~-25 ~40 ~31 ~-25 ~40 dirt 0  
fill ~1 ~-25 ~41 ~31 ~-25 ~41 dirt 0  
fill ~1 ~-25 ~42 ~31 ~-25 ~42 dirt 0  
fill ~1 ~-25 ~43 ~31 ~-25 ~43 dirt 0  
fill ~1 ~-25 ~44 ~31 ~-25 ~44 dirt 0  
fill ~1 ~-25 ~45 ~31 ~-25 ~45 dirt 0  
fill ~1 ~-25 ~46 ~31 ~-25 ~46 dirt 0  
fill ~1 ~-25 ~47 ~31 ~-25 ~47 dirt 0  
fill ~1 ~-25 ~48 ~31 ~-25 ~48 dirt 0  
fill ~1 ~-25 ~49 ~31 ~-25 ~49 dirt 0  
fill ~1 ~-25 ~50 ~31 ~-25 ~50 dirt 0  
fill ~1 ~-25 ~51 ~31 ~-25 ~51 dirt 0  
fill ~1 ~-25 ~52 ~31 ~-25 ~52 dirt 0  
fill ~1 ~-25 ~53 ~31 ~-25 ~53 dirt 0  
fill ~1 ~-25 ~54 ~31 ~-25 ~54 dirt 0  
fill ~1 ~-25 ~55 ~31 ~-25 ~55 dirt 0  
fill ~1 ~-25 ~56 ~31 ~-25 ~56 dirt 0  
fill ~1 ~-25 ~57 ~31 ~-25 ~57 dirt 0  
fill ~1 ~-25 ~58 ~31 ~-25 ~58 dirt 0  
fill ~1 ~-25 ~59 ~31 ~-25 ~59 dirt 0  
fill ~1 ~-25 ~60 ~31 ~-25 ~60 dirt 0  
fill ~1 ~-25 ~61 ~31 ~-25 ~61 dirt 0  
fill ~1 ~-25 ~62 ~31 ~-25 ~62 dirt 0  
fill ~1 ~-25 ~63 ~31 ~-25 ~63 dirt 0  
fill ~1 ~-25 ~64 ~31 ~-25 ~64 dirt 0  
fill ~1 ~-25 ~65 ~31 ~-25 ~65 dirt 0  
fill ~1 ~-25 ~66 ~31 ~-25 ~66 dirt 0  
fill ~1 ~-25 ~67 ~31 ~-25 ~67 dirt 0  
fill ~1 ~-25 ~68 ~31 ~-25 ~68 dirt 0  
fill ~1 ~-25 ~69 ~31 ~-25 ~69 dirt 0  
fill ~1 ~-25 ~70 ~31 ~-25 ~70 dirt 0  
fill ~1 ~-25 ~71 ~31 ~-25 ~71 dirt 0  
fill ~1 ~-25 ~72 ~31 ~-25 ~72 dirt 0  
fill ~1 ~-25 ~73 ~31 ~-25 ~73 dirt 0  
fill ~1 ~-25 ~74 ~31 ~-25 ~74 dirt 0  
fill ~1 ~-25 ~75 ~31 ~-25 ~75 dirt 0  
fill ~1 ~-25 ~76 ~31 ~-25 ~76 dirt 0  
fill ~1 ~-25 ~77 ~31 ~-25 ~77 dirt 0  
fill ~1 ~-25 ~78 ~31 ~-25 ~78 dirt 0  
fill ~1 ~-25 ~79 ~31 ~-25 ~79 dirt 0  
fill ~1 ~-25 ~80 ~31 ~-25 ~80 dirt 0  
fill ~1 ~-25 ~81 ~31 ~-25 ~81 dirt 0  
fill ~1 ~-25 ~82 ~31 ~-25 ~82 dirt 0  
fill ~1 ~-25 ~83 ~31 ~-25 ~83 dirt 0  
fill ~1 ~-25 ~84 ~31 ~-25 ~84 dirt 0  
fill ~1 ~-25 ~85 ~31 ~-25 ~85 dirt 0  
fill ~1 ~-25 ~86 ~181 ~-25 ~86 dirt 0  
fill ~1 ~-25 ~87 ~181 ~-25 ~87 dirt 0  
fill ~1 ~-25 ~88 ~181 ~-25 ~88 dirt 0  
fill ~1 ~-25 ~89 ~181 ~-25 ~89 dirt 0  
fill ~1 ~-25 ~90 ~181 ~-25 ~90 dirt 0  
fill ~1 ~-25 ~91 ~181 ~-25 ~91 dirt 0  
fill ~1 ~-25 ~92 ~181 ~-25 ~92 dirt 0  
fill ~1 ~-25 ~93 ~181 ~-25 ~93 dirt 0  
fill ~1 ~-25 ~94 ~181 ~-25 ~94 dirt 0  
fill ~1 ~-25 ~95 ~181 ~-25 ~95 dirt 0  
fill ~1 ~-25 ~96 ~181 ~-25 ~96 dirt 0  
fill ~1 ~-25 ~97 ~181 ~-25 ~97 dirt 0  
fill ~1 ~-25 ~98 ~181 ~-25 ~98 dirt 0  
fill ~1 ~-25 ~99 ~181 ~-25 ~99 dirt 0  
fill ~1 ~-25 ~100 ~181 ~-25 ~100 dirt 0  
fill ~32 ~-25 ~22 ~106 ~-25 ~22 stone 0  
fill ~32 ~-25 ~23 ~106 ~-25 ~23 stone 0  
fill ~32 ~-25 ~24 ~106 ~-25 ~24 stone 0  
fill ~32 ~-25 ~25 ~106 ~-25 ~25 stone 0  
fill ~32 ~-25 ~26 ~106 ~-25 ~26 stone 0  
fill ~32 ~-25 ~27 ~106 ~-25 ~27 stone 0  
fill ~32 ~-25 ~28 ~106 ~-25 ~28 stone 0  
fill ~32 ~-25 ~29 ~106 ~-25 ~29 stone 0  
fill ~32 ~-25 ~30 ~52 ~-25 ~30 stone 0  
fill ~32 ~-25 ~31 ~52 ~-25 ~31 stone 0  
fill ~32 ~-25 ~32 ~52 ~-25 ~32 stone 0  
fill ~32 ~-25 ~33 ~52 ~-25 ~33 stone 0  
fill ~32 ~-25 ~34 ~52 ~-25 ~34 stone 0  
fill ~32 ~-25 ~35 ~52 ~-25 ~35 stone 0  
fill ~32 ~-25 ~36 ~52 ~-25 ~36 stone 0  
fill ~32 ~-25 ~37 ~52 ~-25 ~37 stone 0  
fill ~32 ~-25 ~38 ~52 ~-25 ~38 stone 0  
fill ~32 ~-25 ~39 ~52 ~-25 ~39 stone 0  
fill ~32 ~-25 ~40 ~52 ~-25 ~40 stone 0  
fill ~32 ~-25 ~41 ~52 ~-25 ~41 stone 0  
fill ~32 ~-25 ~42 ~52 ~-25 ~42 stone 0  
fill ~32 ~-25 ~43 ~52 ~-25 ~43 stone 0  
fill ~32 ~-25 ~44 ~52 ~-25 ~44 stone 0  
fill ~32 ~-25 ~45 ~52 ~-25 ~45 stone 0  
fill ~32 ~-25 ~46 ~52 ~-25 ~46 stone 0  
fill ~32 ~-25 ~47 ~52 ~-25 ~47 stone 0  
fill ~32 ~-25 ~48 ~52 ~-25 ~48 stone 0  
fill ~32 ~-25 ~49 ~52 ~-25 ~49 stone 0  
fill ~32 ~-25 ~50 ~52 ~-25 ~50 stone 0  
fill ~32 ~-25 ~51 ~52 ~-25 ~51 stone 0  
fill ~32 ~-25 ~52 ~52 ~-25 ~52 stone 0  
fill ~32 ~-25 ~53 ~52 ~-25 ~53 stone 0  
fill ~32 ~-25 ~54 ~52 ~-25 ~54 stone 0  
fill ~32 ~-25 ~55 ~52 ~-25 ~55 stone 0  
fill ~32 ~-25 ~56 ~51 ~-25 ~56 stone 0  
fill ~32 ~-25 ~57 ~52 ~-25 ~57 stone 0  
fill ~32 ~-25 ~58 ~52 ~-25 ~58 stone 0  
fill ~32 ~-25 ~59 ~52 ~-25 ~59 stone 0  
fill ~32 ~-25 ~60 ~45 ~-25 ~60 stone 0  
fill ~32 ~-25 ~61 ~45 ~-25 ~61 stone 0  
fill ~32 ~-25 ~62 ~45 ~-25 ~62 stone 0  
fill ~32 ~-25 ~63 ~45 ~-25 ~63 stone 0  
fill ~32 ~-25 ~64 ~45 ~-25 ~64 stone 0  
fill ~32 ~-25 ~65 ~52 ~-25 ~65 stone 0  
fill ~32 ~-25 ~66 ~52 ~-25 ~66 stone 0  
fill ~32 ~-25 ~67 ~52 ~-25 ~67 stone 0  
fill ~32 ~-25 ~68 ~52 ~-25 ~68 stone 0  
fill ~32 ~-25 ~69 ~52 ~-25 ~69 stone 0  
fill ~32 ~-25 ~70 ~52 ~-25 ~70 stone 0  
fill ~32 ~-25 ~71 ~106 ~-25 ~71 stone 0  
fill ~32 ~-25 ~72 ~106 ~-25 ~72 stone 0  
fill ~32 ~-25 ~73 ~106 ~-25 ~73 stone 0  
fill ~32 ~-25 ~74 ~106 ~-25 ~74 stone 0  
fill ~32 ~-25 ~75 ~106 ~-25 ~75 stone 0  
fill ~32 ~-25 ~76 ~106 ~-25 ~76 stone 0  
fill ~32 ~-25 ~77 ~106 ~-25 ~77 stone 0  
fill ~32 ~-25 ~78 ~106 ~-25 ~78 stone 0  
fill ~32 ~-25 ~79 ~106 ~-25 ~79 stone 0  
fill ~32 ~-25 ~80 ~106 ~-25 ~80 stone 0  
fill ~32 ~-25 ~81 ~106 ~-25 ~81 stone 0  
fill ~32 ~-25 ~82 ~106 ~-25 ~82 stone 0  
fill ~32 ~-25 ~83 ~106 ~-25 ~83 stone 0  
fill ~32 ~-25 ~84 ~106 ~-25 ~84 stone 0  
fill ~32 ~-25 ~85 ~106 ~-25 ~85 stone 0  
fill ~46 ~-25 ~60 ~48 ~-25 ~60 air  
fill ~46 ~-25 ~61 ~48 ~-25 ~61 air  
fill ~46 ~-25 ~62 ~49 ~-25 ~62 air  
fill ~46 ~-25 ~63 ~46 ~-21 ~63 air  
fill ~46 ~-25 ~64 ~50 ~-25 ~64 air  
fill ~48 ~-25 ~63 ~50 ~-25 ~63 air 
setblock ~49 ~-25 ~60 lava 2 
setblock ~49 ~-25 ~61 lava 4 
setblock ~50 ~-25 ~60 lava 12 
setblock ~50 ~-25 ~61 lava 2 
setblock ~50 ~-25 ~62 lava 4  
fill ~51 ~-25 ~60 ~52 ~-25 ~60 stone 0  
fill ~51 ~-25 ~61 ~52 ~-25 ~61 air  
fill ~51 ~-25 ~62 ~52 ~-25 ~62 stone 0  
fill ~51 ~-25 ~63 ~52 ~-25 ~63 stone 0  
fill ~51 ~-25 ~64 ~52 ~-25 ~64 stone 0  
fill ~52 ~-25 ~56 ~53 ~-25 ~56 air  
fill ~53 ~-25 ~30 ~87 ~-25 ~30 netherrack 0  
fill ~53 ~-25 ~31 ~87 ~-25 ~31 netherrack 0  
fill ~53 ~-25 ~32 ~87 ~-25 ~32 netherrack 0  
fill ~53 ~-25 ~33 ~87 ~-25 ~33 netherrack 0  
fill ~53 ~-25 ~34 ~87 ~-25 ~34 netherrack 0  
fill ~53 ~-25 ~35 ~83 ~-25 ~35 netherrack 0  
fill ~53 ~-25 ~36 ~87 ~-25 ~36 netherrack 0  
fill ~53 ~-25 ~37 ~87 ~-25 ~37 netherrack 0  
fill ~53 ~-25 ~38 ~60 ~-25 ~38 netherrack 0  
fill ~53 ~-25 ~39 ~57 ~-25 ~39 netherrack 0  
fill ~53 ~-25 ~40 ~57 ~-25 ~40 netherrack 0  
fill ~53 ~-25 ~41 ~57 ~-25 ~41 netherrack 0  
fill ~53 ~-25 ~42 ~56 ~-25 ~42 netherrack 0  
fill ~53 ~-25 ~43 ~56 ~-25 ~43 netherrack 0  
fill ~53 ~-25 ~44 ~56 ~-25 ~44 netherrack 0  
fill ~53 ~-25 ~45 ~55 ~-25 ~45 netherrack 0  
fill ~53 ~-25 ~46 ~53 ~-24 ~46 lava 10  
fill ~53 ~-25 ~47 ~53 ~-24 ~47 lava 10  
fill ~53 ~-25 ~48 ~53 ~-21 ~48 netherrack 0  
fill ~53 ~-25 ~49 ~53 ~-20 ~49 netherrack 0  
fill ~53 ~-25 ~50 ~58 ~-25 ~50 netherrack 0  
fill ~53 ~-25 ~51 ~62 ~-25 ~51 netherrack 0  
fill ~53 ~-25 ~52 ~61 ~-25 ~52 netherrack 0  
fill ~53 ~-25 ~53 ~62 ~-25 ~53 netherrack 0  
fill ~53 ~-25 ~54 ~56 ~-25 ~54 netherrack 0  
fill ~53 ~-25 ~58 ~69 ~-25 ~58 netherrack 0  
fill ~53 ~-25 ~59 ~68 ~-25 ~59 netherrack 0  
fill ~53 ~-25 ~60 ~65 ~-25 ~60 netherrack 0  
fill ~53 ~-25 ~61 ~64 ~-25 ~61 netherrack 0  
fill ~53 ~-25 ~62 ~64 ~-25 ~62 netherrack 0  
fill ~53 ~-25 ~63 ~65 ~-25 ~63 netherrack 0  
fill ~53 ~-25 ~64 ~87 ~-25 ~64 netherrack 0  
fill ~53 ~-25 ~65 ~87 ~-25 ~65 netherrack 0  
fill ~53 ~-25 ~66 ~87 ~-25 ~66 netherrack 0  
fill ~53 ~-25 ~67 ~87 ~-25 ~67 netherrack 0  
fill ~53 ~-25 ~68 ~87 ~-25 ~68 netherrack 0  
fill ~53 ~-25 ~69 ~87 ~-25 ~69 netherrack 0  
fill ~53 ~-25 ~70 ~87 ~-25 ~70 netherrack 0  
fill ~54 ~-25 ~46 ~55 ~-25 ~46 netherrack 0 
setblock ~54 ~-25 ~47 lava 2  
fill ~54 ~-25 ~48 ~54 ~-25 ~49 air  
fill ~54 ~-25 ~55 ~55 ~-25 ~55 netherrack 0  
fill ~54 ~-25 ~56 ~56 ~-25 ~56 netherrack 0  
fill ~54 ~-25 ~57 ~54 ~-24 ~57 netherrack 0 
setblock ~55 ~-25 ~47 glowstone 0  
fill ~55 ~-25 ~48 ~55 ~-26 ~48 netherrack 0  
fill ~55 ~-25 ~49 ~55 ~-25 ~48 netherrack 0 
setblock ~55 ~-25 ~57 glowstone 0 
setblock ~56 ~-25 ~45 glowstone 0  
fill ~56 ~-25 ~46 ~56 ~-25 ~49 lava 10 
setblock ~56 ~-25 ~55 glowstone 0  
fill ~56 ~-25 ~57 ~66 ~-25 ~57 netherrack 0  
fill ~57 ~-25 ~42 ~57 ~-25 ~45 lava 10  
fill ~57 ~-25 ~46 ~58 ~-25 ~46 lava 2 
setblock ~57 ~-25 ~47 netherrack 0  
fill ~57 ~-25 ~48 ~58 ~-25 ~48 lava 2  
fill ~57 ~-25 ~49 ~58 ~-25 ~49 lava 10 
setblock ~57 ~-25 ~54 glowstone 0  
fill ~57 ~-25 ~55 ~65 ~-25 ~55 netherrack 0 
setblock ~57 ~-25 ~56 lava 10  
fill ~58 ~-25 ~39 ~60 ~-25 ~39 lava 10  
fill ~58 ~-25 ~40 ~58 ~-25 ~39 lava 10 
setblock ~58 ~-25 ~41 lava 12  
fill ~58 ~-25 ~42 ~58 ~-25 ~44 lava 2 
setblock ~58 ~-25 ~45 lava 10 
setblock ~58 ~-25 ~47 lava 4  
fill ~58 ~-25 ~54 ~65 ~-25 ~54 netherrack 0  
fill ~58 ~-25 ~56 ~58 ~-24 ~56 lava 12  
fill ~59 ~-25 ~40 ~59 ~-25 ~41 lava 2 
setblock ~59 ~-25 ~42 lava 4 
setblock ~59 ~-25 ~43 lava 2 
setblock ~59 ~-25 ~44 lava 10  
fill ~59 ~-25 ~45 ~62 ~-25 ~45 netherrack 0  
fill ~59 ~-25 ~46 ~60 ~-25 ~46 lava 10 
setblock ~59 ~-25 ~47 lava 2 
setblock ~59 ~-25 ~48 lava 4 
setblock ~59 ~-25 ~49 lava 2  
fill ~59 ~-25 ~50 ~60 ~-25 ~50 lava 10  
fill ~59 ~-25 ~56 ~65 ~-25 ~56 netherrack 0  
fill ~60 ~-25 ~40 ~60 ~-1 ~40 air  
fill ~60 ~-25 ~41 ~60 ~-1 ~41 air 
setblock ~60 ~-25 ~42 lava 2  
fill ~60 ~-25 ~43 ~60 ~-24 ~43 lava 10  
fill ~60 ~-25 ~44 ~62 ~-25 ~44 netherrack 0 
setblock ~60 ~-25 ~47 lava 10 
setblock ~60 ~-25 ~48 lava 2  
fill ~60 ~-25 ~49 ~60 ~-24 ~49 lava 10  
fill ~61 ~-25 ~39 ~61 ~-25 ~41 lava 2  
fill ~61 ~-25 ~42 ~61 ~-24 ~42 lava 10   
fill ~61 ~-25 ~43 ~64 ~-25 ~43 netherrack 0  
fill ~61 ~-25 ~46 ~61 ~-24 ~46 lava 8  
fill ~61 ~-25 ~47 ~61 ~-25 ~46 lava 8 
setblock ~61 ~-25 ~48 lava 0  
fill ~61 ~-25 ~49 ~61 ~-24 ~49 lava 8 
setblock ~61 ~-25 ~50 lava 0  
fill ~62 ~-25 ~38 ~87 ~-25 ~38 netherrack 0  
fill ~62 ~-25 ~39 ~62 ~-24 ~39 lava 10  
fill ~62 ~-25 ~40 ~62 ~-24 ~40 lava 12 
setblock ~62 ~-25 ~41 lava 0  
fill ~62 ~-25 ~42 ~68 ~-25 ~42 netherrack 0  
fill ~62 ~-25 ~46 ~64 ~-25 ~46 netherrack 0  
fill ~62 ~-25 ~47 ~64 ~-25 ~47 netherrack 0  
fill ~62 ~-25 ~48 ~63 ~-25 ~48 netherrack 0  
fill ~62 ~-25 ~49 ~63 ~-25 ~49 netherrack 0  
fill ~62 ~-25 ~50 ~63 ~-25 ~50 netherrack 0  
fill ~62 ~-25 ~52 ~63 ~-25 ~52 lava 8  
fill ~63 ~-25 ~39 ~87 ~-25 ~39 netherrack 0  
fill ~63 ~-25 ~40 ~67 ~-25 ~40 netherrack 0  
fill ~63 ~-25 ~41 ~70 ~-25 ~41 netherrack 0  
fill ~63 ~-25 ~44 ~63 ~-25 ~45 lava 8  
fill ~63 ~-25 ~51 ~63 ~-24 ~51 lava 8  
fill ~63 ~-25 ~53 ~63 ~-24 ~53 lava 8 
setblock ~64 ~-25 ~44 lava 0  
fill ~64 ~-25 ~48 ~64 ~-24 ~48 lava 0  
fill ~64 ~-25 ~49 ~64 ~-25 ~50 lava 8  
fill ~64 ~-25 ~51 ~64 ~-25 ~70 netherrack 0  
fill ~65 ~-25 ~43 ~65 ~-24 ~43 lava 8  
fill ~65 ~-25 ~44 ~65 ~-25 ~43 lava 8  
fill ~65 ~-25 ~46 ~68 ~-25 ~46 lava 0  
fill ~65 ~-25 ~47 ~68 ~-25 ~47 lava 0 
setblock ~65 ~-25 ~48 lava 8  
fill ~65 ~-25 ~50 ~67 ~-25 ~50 lava 0 
setblock ~65 ~-25 ~52 lava 8  
fill ~65 ~-25 ~53 ~65 ~-24 ~53 lava 0  
fill ~65 ~-25 ~61 ~65 ~-24 ~61 air  
fill ~65 ~-25 ~62 ~65 ~-24 ~62 air  
fill ~66 ~-25 ~44 ~66 ~-25 ~48 lava 0  
fill ~66 ~-25 ~49 ~66 ~-26 ~49 netherrack 0  
fill ~66 ~-25 ~51 ~67 ~-25 ~51 netherrack 0  
fill ~66 ~-25 ~52 ~70 ~-25 ~52 lava 0 
setblock ~66 ~-25 ~53 netherrack 0 
setblock ~66 ~-25 ~54 lava 0  
fill ~66 ~-25 ~56 ~66 ~-24 ~56 lava 8  
fill ~66 ~-25 ~63 ~67 ~-25 ~63 air  
fill ~67 ~-25 ~43 ~67 ~-24 ~43 lava 8  
fill ~67 ~-25 ~44 ~67 ~-25 ~43 lava 8  
fill ~67 ~-25 ~45 ~70 ~-25 ~45 lava 0 
setblock ~67 ~-25 ~48 netherrack 0 
setblock ~67 ~-25 ~49 lava 0  
fill ~67 ~-25 ~53 ~68 ~-25 ~53 lava 0 
setblock ~67 ~-25 ~55 lava 2  
fill ~67 ~-25 ~56 ~71 ~-25 ~56 lava 0 
setblock ~67 ~-25 ~57 lava 2  
fill ~67 ~-25 ~60 ~67 ~-24 ~60 lava 0 
setblock ~68 ~-25 ~40 stone 0  
fill ~68 ~-25 ~43 ~72 ~-25 ~43 lava 0  
fill ~68 ~-25 ~44 ~76 ~-25 ~44 lava 0  
fill ~68 ~-25 ~48 ~68 ~-25 ~51 lava 2 
setblock ~68 ~-25 ~55 lava 0 
setblock ~68 ~-25 ~57 lava 10  
fill ~68 ~-25 ~60 ~69 ~-25 ~60 netherrack 0 
setblock ~68 ~-25 ~61 lava 0  
fill ~68 ~-25 ~62 ~68 ~-23 ~62 lava 10  
fill ~68 ~-25 ~63 ~87 ~-25 ~63 netherrack 0  
fill ~69 ~-25 ~40 ~72 ~-25 ~40 netherrack 0  
fill ~69 ~-25 ~42 ~72 ~-25 ~42 lava 8  
fill ~69 ~-25 ~46 ~70 ~-25 ~46 lava 2  
fill ~69 ~-25 ~47 ~69 ~-25 ~46 lava 2  
fill ~69 ~-25 ~48 ~70 ~-25 ~48 air  
fill ~69 ~-25 ~49 ~70 ~-25 ~49 air  
fill ~69 ~-25 ~50 ~69 ~-21 ~50 air  
fill ~69 ~-25 ~51 ~70 ~-25 ~51 lava 2 
setblock ~69 ~-25 ~53 lava 8  
fill ~69 ~-25 ~54 ~70 ~-25 ~54 lava 0 
setblock ~69 ~-25 ~55 lava 2  
fill ~69 ~-25 ~57 ~76 ~-25 ~57 lava 0  
fill ~69 ~-25 ~59 ~71 ~-25 ~59 lava 0  
fill ~69 ~-25 ~61 ~73 ~-25 ~61 netherrack 0  
fill ~69 ~-25 ~62 ~73 ~-25 ~62 netherrack 0  
fill ~70 ~-25 ~47 ~70 ~-20 ~47 air 
setblock ~70 ~-25 ~50 lava 2  
fill ~70 ~-25 ~53 ~71 ~-25 ~53 lava 0  
fill ~70 ~-25 ~55 ~71 ~-25 ~55 lava 0  
fill ~70 ~-25 ~58 ~74 ~-25 ~58 lava 0 
setblock ~70 ~-25 ~60 lava 0  
fill ~71 ~-25 ~41 ~72 ~-25 ~41 lava 8  
fill ~71 ~-25 ~45 ~73 ~-25 ~45 lava 2  
fill ~71 ~-25 ~46 ~71 ~-20 ~46 air  
fill ~71 ~-25 ~47 ~71 ~-25 ~48 lava 2  
fill ~71 ~-25 ~51 ~75 ~-25 ~51 lava 0 
setblock ~71 ~-25 ~52 lava 2 
setblock ~71 ~-25 ~54 lava 2  
fill ~71 ~-25 ~60 ~87 ~-25 ~60 netherrack 0 
setblock ~72 ~-25 ~46 lava 2  
fill ~72 ~-25 ~47 ~76 ~-25 ~47 lava 0  
fill ~72 ~-25 ~48 ~76 ~-25 ~48 lava 0  
fill ~72 ~-25 ~49 ~76 ~-25 ~49 lava 0  
fill ~72 ~-25 ~50 ~75 ~-25 ~50 lava 0  
fill ~72 ~-25 ~52 ~75 ~-25 ~52 lava 0  
fill ~72 ~-25 ~53 ~73 ~-25 ~53 lava 2 
setblock ~72 ~-25 ~54 lava 4  
fill ~72 ~-25 ~55 ~73 ~-25 ~55 lava 2  
fill ~72 ~-25 ~56 ~73 ~-25 ~56 netherrack 0  
fill ~72 ~-25 ~59 ~76 ~-25 ~59 netherrack 0  
fill ~73 ~-25 ~40 ~74 ~-25 ~40 lava 10  
fill ~73 ~-25 ~41 ~74 ~-25 ~41 lava 0  
fill ~73 ~-25 ~42 ~74 ~-25 ~42 lava 0  
fill ~73 ~-25 ~43 ~74 ~-25 ~43 lava 2  
fill ~73 ~-25 ~46 ~75 ~-25 ~46 lava 0 
setblock ~73 ~-25 ~54 lava 2  
fill ~74 ~-25 ~45 ~76 ~-25 ~45 lava 0  
fill ~74 ~-25 ~53 ~74 ~-25 ~55 lava 0 
setblock ~74 ~-25 ~56 lava 2  
fill ~74 ~-25 ~61 ~75 ~-25 ~61 lava 8  
fill ~74 ~-25 ~62 ~75 ~-25 ~62 lava 10  
fill ~75 ~-25 ~40 ~87 ~-25 ~40 netherrack 0  
fill ~75 ~-25 ~41 ~75 ~-24 ~41 lava 8  
fill ~75 ~-25 ~42 ~76 ~-25 ~42 lava 8  
fill ~75 ~-25 ~43 ~76 ~-25 ~43 lava 0  
fill ~75 ~-25 ~56 ~76 ~-25 ~56 lava 0 
setblock ~75 ~-25 ~58 netherrack 0  
fill ~76 ~-25 ~41 ~87 ~-25 ~41 netherrack 0 
setblock ~76 ~-25 ~46 lava 2  
fill ~76 ~-25 ~50 ~76 ~-25 ~53 lava 2 
setblock ~76 ~-25 ~54 lava 0 
setblock ~76 ~-25 ~55 lava 8 
setblock ~76 ~-25 ~58 lava 0  
fill ~76 ~-25 ~61 ~87 ~-25 ~61 netherrack 0  
fill ~76 ~-25 ~62 ~87 ~-25 ~62 netherrack 0  
fill ~77 ~-25 ~42 ~87 ~-25 ~42 netherrack 0 
setblock ~77 ~-25 ~43 lava 10  
fill ~77 ~-25 ~44 ~78 ~-25 ~44 lava 2  
fill ~77 ~-25 ~45 ~77 ~-25 ~47 fire 15  
fill ~77 ~-25 ~48 ~77 ~-25 ~49 lava 2  
fill ~77 ~-25 ~50 ~77 ~-17 ~50 air  
fill ~77 ~-25 ~51 ~77 ~-17 ~51 air  
fill ~77 ~-25 ~52 ~80 ~-25 ~52 fire 15 
setblock ~77 ~-25 ~53 lava 4 
setblock ~77 ~-25 ~54 lava 2 
setblock ~77 ~-25 ~55 lava 0  
fill ~77 ~-25 ~56 ~77 ~-25 ~58 lava 2 
setblock ~77 ~-25 ~59 lava 10 
setblock ~78 ~-25 ~43 lava 12  
fill ~78 ~-25 ~45 ~82 ~-25 ~45 air  
fill ~78 ~-25 ~46 ~78 ~-25 ~52 fire 15 
setblock ~78 ~-25 ~53 lava 6 
setblock ~78 ~-25 ~54 lava 4 
setblock ~78 ~-25 ~55 lava 2 
setblock ~78 ~-25 ~56 lava 4  
fill ~78 ~-25 ~57 ~85 ~-25 ~57 netherrack 0 
setblock ~78 ~-25 ~58 lava 4  
fill ~78 ~-25 ~59 ~87 ~-25 ~59 netherrack 0 
setblock ~79 ~-25 ~43 netherrack 0  
fill ~79 ~-25 ~46 ~79 ~-14 ~46 air  
fill ~79 ~-25 ~47 ~80 ~-25 ~47 fire 15  
fill ~79 ~-25 ~48 ~81 ~-25 ~48 fire 15  
fill ~79 ~-25 ~49 ~81 ~-25 ~49 fire 15  
fill ~79 ~-25 ~50 ~81 ~-25 ~50 fire 15  
fill ~79 ~-25 ~51 ~79 ~-14 ~51 air  
fill ~79 ~-25 ~53 ~80 ~-25 ~53 fire 15  
fill ~79 ~-25 ~54 ~79 ~-25 ~55 fire 15  
fill ~79 ~-25 ~56 ~85 ~-25 ~56 netherrack 0  
fill ~79 ~-25 ~58 ~87 ~-25 ~58 netherrack 0  
fill ~80 ~-25 ~51 ~81 ~-25 ~51 fire 15 
setblock ~80 ~-25 ~54 stone 0  
fill ~80 ~-25 ~55 ~87 ~-25 ~55 netherrack 0  
fill ~81 ~-25 ~43 ~81 ~-24 ~43 lava 14 
setblock ~81 ~-25 ~44 lava 2  
fill ~81 ~-25 ~46 ~81 ~-11 ~46 air  
fill ~81 ~-25 ~47 ~87 ~-25 ~47 netherrack 0  
fill ~81 ~-25 ~52 ~84 ~-25 ~52 netherrack 0  
fill ~81 ~-25 ~53 ~87 ~-25 ~53 netherrack 0  
fill ~81 ~-25 ~54 ~87 ~-25 ~54 netherrack 0  
fill ~82 ~-25 ~43 ~82 ~-24 ~43 stone 0  
fill ~82 ~-25 ~44 ~82 ~-8 ~44 air  
fill ~82 ~-25 ~46 ~87 ~-25 ~46 netherrack 0  
fill ~82 ~-25 ~48 ~87 ~-25 ~48 netherrack 0  
fill ~82 ~-25 ~49 ~82 ~-25 ~70 netherrack 0  
fill ~83 ~-25 ~43 ~87 ~-25 ~43 netherrack 0  
fill ~83 ~-25 ~44 ~83 ~-25 ~45 stone 0 
setblock ~83 ~-25 ~49 lava 2 
setblock ~83 ~-25 ~50 lava 4  
fill ~83 ~-25 ~51 ~87 ~-25 ~51 netherrack 0 
setblock ~84 ~-25 ~35 stone 0  
fill ~84 ~-25 ~44 ~87 ~-25 ~44 netherrack 0  
fill ~84 ~-25 ~45 ~87 ~-25 ~45 netherrack 0 
setblock ~84 ~-25 ~49 lava 10 
setblock ~84 ~-25 ~50 lava 2  
fill ~85 ~-25 ~35 ~87 ~-25 ~35 netherrack 0  
fill ~85 ~-25 ~49 ~87 ~-25 ~49 netherrack 0 
setblock ~85 ~-25 ~50 stone 0 
setblock ~85 ~-25 ~52 stone 0  
fill ~86 ~-25 ~50 ~87 ~-25 ~50 netherrack 0  
fill ~86 ~-25 ~52 ~87 ~-25 ~52 netherrack 0  
fill ~86 ~-25 ~56 ~106 ~-25 ~56 stone 0  
fill ~86 ~-25 ~57 ~106 ~-25 ~57 stone 0  
fill ~88 ~-25 ~30 ~106 ~-25 ~30 stone 0  
fill ~88 ~-25 ~31 ~106 ~-25 ~31 stone 0  
fill ~88 ~-25 ~32 ~106 ~-25 ~32 stone 0  
fill ~88 ~-25 ~33 ~106 ~-25 ~33 stone 0  
fill ~88 ~-25 ~34 ~106 ~-25 ~34 stone 0  
fill ~88 ~-25 ~35 ~106 ~-25 ~35 stone 0  
fill ~88 ~-25 ~36 ~106 ~-25 ~36 stone 0  
fill ~88 ~-25 ~37 ~106 ~-25 ~37 stone 0  
fill ~88 ~-25 ~38 ~106 ~-25 ~38 stone 0  
fill ~88 ~-25 ~39 ~106 ~-25 ~39 stone 0  
fill ~88 ~-25 ~40 ~106 ~-25 ~40 stone 0  
fill ~88 ~-25 ~41 ~106 ~-25 ~41 stone 0  
fill ~88 ~-25 ~42 ~106 ~-25 ~42 stone 0  
fill ~88 ~-25 ~43 ~106 ~-25 ~43 stone 0  
fill ~88 ~-25 ~44 ~106 ~-25 ~44 stone 0  
fill ~88 ~-25 ~45 ~106 ~-25 ~45 stone 0  
fill ~88 ~-25 ~46 ~106 ~-25 ~46 stone 0  
fill ~88 ~-25 ~47 ~106 ~-25 ~47 stone 0  
fill ~88 ~-25 ~48 ~106 ~-25 ~48 stone 0  
fill ~88 ~-25 ~49 ~106 ~-25 ~49 stone 0  
fill ~88 ~-25 ~50 ~106 ~-25 ~50 stone 0  
fill ~88 ~-25 ~51 ~106 ~-25 ~51 stone 0  
fill ~88 ~-25 ~52 ~106 ~-25 ~52 stone 0  
fill ~88 ~-25 ~53 ~106 ~-25 ~53 stone 0  
fill ~88 ~-25 ~54 ~106 ~-25 ~54 stone 0  
fill ~88 ~-25 ~55 ~106 ~-25 ~55 stone 0  
fill ~88 ~-25 ~58 ~106 ~-25 ~58 stone 0  
fill ~88 ~-25 ~59 ~106 ~-25 ~59 stone 0  
fill ~88 ~-25 ~60 ~106 ~-25 ~60 stone 0  
fill ~88 ~-25 ~61 ~106 ~-25 ~61 stone 0  
fill ~88 ~-25 ~62 ~106 ~-25 ~62 stone 0  
fill ~88 ~-25 ~63 ~106 ~-25 ~63 stone 0  
fill ~88 ~-25 ~64 ~106 ~-25 ~64 stone 0  
fill ~88 ~-25 ~65 ~106 ~-25 ~65 stone 0  
fill ~88 ~-25 ~66 ~106 ~-25 ~66 stone 0  
fill ~88 ~-25 ~67 ~106 ~-25 ~67 stone 0  
fill ~88 ~-25 ~68 ~106 ~-25 ~68 stone 0  
fill ~88 ~-25 ~69 ~106 ~-25 ~69 stone 0  
fill ~88 ~-25 ~70 ~106 ~-25 ~70 stone 0 
setblock ~98 ~-25 ~17 stone 0  
fill ~99 ~-25 ~17 ~181 ~-25 ~17 dirt 0  
fill ~107 ~-25 ~22 ~181 ~-25 ~22 dirt 0  
fill ~107 ~-25 ~23 ~181 ~-25 ~23 dirt 0  
fill ~107 ~-25 ~24 ~181 ~-25 ~24 dirt 0  
fill ~107 ~-25 ~25 ~181 ~-25 ~25 dirt 0  
fill ~107 ~-25 ~26 ~181 ~-25 ~26 dirt 0  
fill ~107 ~-25 ~27 ~181 ~-25 ~27 dirt 0  
fill ~107 ~-25 ~28 ~181 ~-25 ~28 dirt 0  
fill ~107 ~-25 ~29 ~181 ~-25 ~29 dirt 0  
fill ~107 ~-25 ~30 ~181 ~-25 ~30 dirt 0  
fill ~107 ~-25 ~31 ~181 ~-25 ~31 dirt 0  
fill ~107 ~-25 ~32 ~181 ~-25 ~32 dirt 0  
fill ~107 ~-25 ~33 ~181 ~-25 ~33 dirt 0  
fill ~107 ~-25 ~34 ~181 ~-25 ~34 dirt 0  
fill ~107 ~-25 ~35 ~181 ~-25 ~35 dirt 0  
fill ~107 ~-25 ~36 ~181 ~-25 ~36 dirt 0  
fill ~107 ~-25 ~37 ~181 ~-25 ~37 dirt 0  
fill ~107 ~-25 ~38 ~181 ~-25 ~38 dirt 0  
fill ~107 ~-25 ~39 ~181 ~-25 ~39 dirt 0  
fill ~107 ~-25 ~40 ~181 ~-25 ~40 dirt 0  
fill ~107 ~-25 ~41 ~181 ~-25 ~41 dirt 0  
fill ~107 ~-25 ~42 ~181 ~-25 ~42 dirt 0  
fill ~107 ~-25 ~43 ~181 ~-25 ~43 dirt 0  
fill ~107 ~-25 ~44 ~181 ~-25 ~44 dirt 0  
fill ~107 ~-25 ~45 ~181 ~-25 ~45 dirt 0  
fill ~107 ~-25 ~46 ~181 ~-25 ~46 dirt 0  
fill ~107 ~-25 ~47 ~181 ~-25 ~47 dirt 0  
fill ~107 ~-25 ~48 ~181 ~-25 ~48 dirt 0  
fill ~107 ~-25 ~49 ~181 ~-25 ~49 dirt 0  
fill ~107 ~-25 ~50 ~181 ~-25 ~50 dirt 0  
fill ~107 ~-25 ~51 ~181 ~-25 ~51 dirt 0  
fill ~107 ~-25 ~52 ~181 ~-25 ~52 dirt 0  
fill ~107 ~-25 ~53 ~161 ~-25 ~53 dirt 0  
fill ~107 ~-25 ~54 ~181 ~-25 ~54 dirt 0  
fill ~107 ~-25 ~55 ~181 ~-25 ~55 dirt 0  
fill ~107 ~-25 ~56 ~181 ~-25 ~56 dirt 0  
fill ~107 ~-25 ~57 ~181 ~-25 ~57 dirt 0  
fill ~107 ~-25 ~58 ~181 ~-25 ~58 dirt 0  
fill ~107 ~-25 ~59 ~181 ~-25 ~59 dirt 0  
fill ~107 ~-25 ~60 ~181 ~-25 ~60 dirt 0  
fill ~107 ~-25 ~61 ~181 ~-25 ~61 dirt 0  
fill ~107 ~-25 ~62 ~181 ~-25 ~62 dirt 0  
fill ~107 ~-25 ~63 ~181 ~-25 ~63 dirt 0  
fill ~107 ~-25 ~64 ~181 ~-25 ~64 dirt 0  
fill ~107 ~-25 ~65 ~181 ~-25 ~65 dirt 0  
fill ~107 ~-25 ~66 ~155 ~-25 ~66 dirt 0  
fill ~107 ~-25 ~67 ~181 ~-25 ~67 dirt 0  
fill ~107 ~-25 ~68 ~181 ~-25 ~68 dirt 0  
fill ~107 ~-25 ~69 ~181 ~-25 ~69 dirt 0  
fill ~107 ~-25 ~70 ~181 ~-25 ~70 dirt 0  
fill ~107 ~-25 ~71 ~181 ~-25 ~71 dirt 0  
fill ~107 ~-25 ~72 ~181 ~-25 ~72 dirt 0  
fill ~107 ~-25 ~73 ~181 ~-25 ~73 dirt 0  
fill ~107 ~-25 ~74 ~181 ~-25 ~74 dirt 0  
fill ~107 ~-25 ~75 ~181 ~-25 ~75 dirt 0  
fill ~107 ~-25 ~76 ~181 ~-25 ~76 dirt 0  
fill ~107 ~-25 ~77 ~181 ~-25 ~77 dirt 0  
fill ~107 ~-25 ~78 ~181 ~-25 ~78 dirt 0  
fill ~107 ~-25 ~79 ~181 ~-25 ~79 dirt 0  
fill ~107 ~-25 ~80 ~181 ~-25 ~80 dirt 0  
fill ~107 ~-25 ~81 ~181 ~-25 ~81 dirt 0  
fill ~107 ~-25 ~82 ~181 ~-25 ~82 dirt 0  
fill ~107 ~-25 ~83 ~181 ~-25 ~83 dirt 0  
fill ~107 ~-25 ~84 ~181 ~-25 ~84 dirt 0  
fill ~107 ~-25 ~85 ~181 ~-25 ~85 dirt 0 
setblock ~156 ~-25 ~66 stone 0  
fill ~157 ~-25 ~66 ~181 ~-25 ~66 dirt 0 
setblock ~162 ~-25 ~53 stone 0  
fill ~163 ~-25 ~53 ~181 ~-25 ~53 dirt 0  
fill ~1 ~-24 ~1 ~181 ~-24 ~1 dirt 0  
fill ~1 ~-24 ~2 ~181 ~-24 ~2 dirt 0  
fill ~1 ~-24 ~3 ~181 ~-24 ~3 dirt 0  
fill ~1 ~-24 ~4 ~181 ~-24 ~4 dirt 0  
fill ~1 ~-24 ~5 ~181 ~-24 ~5 dirt 0  
fill ~1 ~-24 ~6 ~181 ~-24 ~6 dirt 0  
fill ~1 ~-24 ~7 ~181 ~-24 ~7 dirt 0  
fill ~1 ~-24 ~8 ~181 ~-24 ~8 dirt 0  
fill ~1 ~-24 ~9 ~181 ~-24 ~9 dirt 0  
fill ~1 ~-24 ~10 ~181 ~-24 ~10 dirt 0  
fill ~1 ~-24 ~11 ~181 ~-24 ~11 dirt 0  
fill ~1 ~-24 ~12 ~181 ~-24 ~12 dirt 0  
fill ~1 ~-24 ~13 ~181 ~-24 ~13 dirt 0  
fill ~1 ~-24 ~14 ~181 ~-24 ~14 dirt 0  
fill ~1 ~-24 ~15 ~181 ~-24 ~15 dirt 0  
fill ~1 ~-24 ~16 ~181 ~-24 ~16 dirt 0  
fill ~1 ~-24 ~17 ~181 ~-24 ~17 dirt 0  
fill ~1 ~-24 ~18 ~181 ~-24 ~18 dirt 0  
fill ~1 ~-24 ~19 ~181 ~-24 ~19 dirt 0  
fill ~1 ~-24 ~20 ~181 ~-24 ~20 dirt 0  
fill ~1 ~-24 ~21 ~181 ~-24 ~21 dirt 0  
fill ~1 ~-24 ~22 ~31 ~-24 ~22 dirt 0  
fill ~1 ~-24 ~23 ~31 ~-24 ~23 dirt 0  
fill ~1 ~-24 ~24 ~31 ~-24 ~24 dirt 0  
fill ~1 ~-24 ~25 ~31 ~-24 ~25 dirt 0  
fill ~1 ~-24 ~26 ~31 ~-24 ~26 dirt 0  
fill ~1 ~-24 ~27 ~31 ~-24 ~27 dirt 0  
fill ~1 ~-24 ~28 ~31 ~-24 ~28 dirt 0  
fill ~1 ~-24 ~29 ~31 ~-24 ~29 dirt 0  
fill ~1 ~-24 ~30 ~31 ~-24 ~30 dirt 0  
fill ~1 ~-24 ~31 ~31 ~-24 ~31 dirt 0  
fill ~1 ~-24 ~32 ~31 ~-24 ~32 dirt 0  
fill ~1 ~-24 ~33 ~31 ~-24 ~33 dirt 0  
fill ~1 ~-24 ~34 ~31 ~-24 ~34 dirt 0  
fill ~1 ~-24 ~35 ~31 ~-24 ~35 dirt 0  
fill ~1 ~-24 ~36 ~31 ~-24 ~36 dirt 0  
fill ~1 ~-24 ~37 ~31 ~-24 ~37 dirt 0  
fill ~1 ~-24 ~38 ~31 ~-24 ~38 dirt 0  
fill ~1 ~-24 ~39 ~31 ~-24 ~39 dirt 0  
fill ~1 ~-24 ~40 ~31 ~-24 ~40 dirt 0  
fill ~1 ~-24 ~41 ~31 ~-24 ~41 dirt 0  
fill ~1 ~-24 ~42 ~31 ~-24 ~42 dirt 0  
fill ~1 ~-24 ~43 ~31 ~-24 ~43 dirt 0  
fill ~1 ~-24 ~44 ~31 ~-24 ~44 dirt 0  
fill ~1 ~-24 ~45 ~31 ~-24 ~45 dirt 0  
fill ~1 ~-24 ~46 ~31 ~-24 ~46 dirt 0  
fill ~1 ~-24 ~47 ~31 ~-24 ~47 dirt 0  
fill ~1 ~-24 ~48 ~31 ~-24 ~48 dirt 0  
fill ~1 ~-24 ~49 ~31 ~-24 ~49 dirt 0  
fill ~1 ~-24 ~50 ~31 ~-24 ~50 dirt 0  
fill ~1 ~-24 ~51 ~31 ~-24 ~51 dirt 0  
fill ~1 ~-24 ~52 ~31 ~-24 ~52 dirt 0  
fill ~1 ~-24 ~53 ~31 ~-24 ~53 dirt 0  
fill ~1 ~-24 ~54 ~31 ~-24 ~54 dirt 0  
fill ~1 ~-24 ~55 ~31 ~-24 ~55 dirt 0  
fill ~1 ~-24 ~56 ~31 ~-24 ~56 dirt 0  
fill ~1 ~-24 ~57 ~31 ~-24 ~57 dirt 0  
fill ~1 ~-24 ~58 ~31 ~-24 ~58 dirt 0  
fill ~1 ~-24 ~59 ~31 ~-24 ~59 dirt 0  
fill ~1 ~-24 ~60 ~31 ~-24 ~60 dirt 0  
fill ~1 ~-24 ~61 ~31 ~-24 ~61 dirt 0  
fill ~1 ~-24 ~62 ~31 ~-24 ~62 dirt 0  
fill ~1 ~-24 ~63 ~31 ~-24 ~63 dirt 0  
fill ~1 ~-24 ~64 ~31 ~-24 ~64 dirt 0  
fill ~1 ~-24 ~65 ~31 ~-24 ~65 dirt 0  
fill ~1 ~-24 ~66 ~31 ~-24 ~66 dirt 0  
fill ~1 ~-24 ~67 ~31 ~-24 ~67 dirt 0  
fill ~1 ~-24 ~68 ~31 ~-24 ~68 dirt 0  
fill ~1 ~-24 ~69 ~31 ~-24 ~69 dirt 0  
fill ~1 ~-24 ~70 ~31 ~-24 ~70 dirt 0  
fill ~1 ~-24 ~71 ~31 ~-24 ~71 dirt 0  
fill ~1 ~-24 ~72 ~31 ~-24 ~72 dirt 0  
fill ~1 ~-24 ~73 ~31 ~-24 ~73 dirt 0  
fill ~1 ~-24 ~74 ~31 ~-24 ~74 dirt 0  
fill ~1 ~-24 ~75 ~31 ~-24 ~75 dirt 0  
fill ~1 ~-24 ~76 ~31 ~-24 ~76 dirt 0  
fill ~1 ~-24 ~77 ~31 ~-24 ~77 dirt 0  
fill ~1 ~-24 ~78 ~31 ~-24 ~78 dirt 0  
fill ~1 ~-24 ~79 ~31 ~-24 ~79 dirt 0  
fill ~1 ~-24 ~80 ~31 ~-24 ~80 dirt 0  
fill ~1 ~-24 ~81 ~31 ~-24 ~81 dirt 0  
fill ~1 ~-24 ~82 ~31 ~-24 ~82 dirt 0  
fill ~1 ~-24 ~83 ~31 ~-24 ~83 dirt 0  
fill ~1 ~-24 ~84 ~31 ~-24 ~84 dirt 0  
fill ~1 ~-24 ~85 ~31 ~-24 ~85 dirt 0  
fill ~1 ~-24 ~86 ~181 ~-24 ~86 dirt 0  
fill ~1 ~-24 ~87 ~181 ~-24 ~87 dirt 0  
fill ~1 ~-24 ~88 ~181 ~-24 ~88 dirt 0  
fill ~1 ~-24 ~89 ~181 ~-24 ~89 dirt 0  
fill ~1 ~-24 ~90 ~181 ~-24 ~90 dirt 0  
fill ~1 ~-24 ~91 ~181 ~-24 ~91 dirt 0  
fill ~1 ~-24 ~92 ~181 ~-24 ~92 dirt 0  
fill ~1 ~-24 ~93 ~181 ~-24 ~93 dirt 0  
fill ~1 ~-24 ~94 ~181 ~-24 ~94 dirt 0  
fill ~1 ~-24 ~95 ~181 ~-24 ~95 dirt 0  
fill ~1 ~-24 ~96 ~181 ~-24 ~96 dirt 0  
fill ~1 ~-24 ~97 ~181 ~-24 ~97 dirt 0  
fill ~1 ~-24 ~98 ~181 ~-24 ~98 dirt 0  
fill ~1 ~-24 ~99 ~181 ~-24 ~99 dirt 0  
fill ~1 ~-24 ~100 ~181 ~-24 ~100 dirt 0  
fill ~32 ~-24 ~22 ~106 ~-24 ~22 stone 0  
fill ~32 ~-24 ~23 ~106 ~-24 ~23 stone 0  
fill ~32 ~-24 ~24 ~106 ~-24 ~24 stone 0  
fill ~32 ~-24 ~25 ~106 ~-24 ~25 stone 0  
fill ~32 ~-24 ~26 ~106 ~-24 ~26 stone 0  
fill ~32 ~-24 ~27 ~106 ~-24 ~27 stone 0  
fill ~32 ~-24 ~28 ~106 ~-24 ~28 stone 0  
fill ~32 ~-24 ~29 ~106 ~-24 ~29 stone 0  
fill ~32 ~-24 ~30 ~52 ~-24 ~30 stone 0  
fill ~32 ~-24 ~31 ~52 ~-24 ~31 stone 0  
fill ~32 ~-24 ~32 ~52 ~-24 ~32 stone 0  
fill ~32 ~-24 ~33 ~52 ~-24 ~33 stone 0  
fill ~32 ~-24 ~34 ~52 ~-24 ~34 stone 0  
fill ~32 ~-24 ~35 ~52 ~-24 ~35 stone 0  
fill ~32 ~-24 ~36 ~52 ~-24 ~36 stone 0  
fill ~32 ~-24 ~37 ~52 ~-24 ~37 stone 0  
fill ~32 ~-24 ~38 ~52 ~-24 ~38 stone 0  
fill ~32 ~-24 ~39 ~52 ~-24 ~39 stone 0  
fill ~32 ~-24 ~40 ~52 ~-24 ~40 stone 0  
fill ~32 ~-24 ~41 ~52 ~-24 ~41 stone 0  
fill ~32 ~-24 ~42 ~52 ~-24 ~42 stone 0  
fill ~32 ~-24 ~43 ~52 ~-24 ~43 stone 0  
fill ~32 ~-24 ~44 ~52 ~-24 ~44 stone 0  
fill ~32 ~-24 ~45 ~52 ~-24 ~45 stone 0  
fill ~32 ~-24 ~46 ~51 ~-24 ~46 stone 0  
fill ~32 ~-24 ~47 ~51 ~-24 ~47 stone 0  
fill ~32 ~-24 ~48 ~51 ~-24 ~48 stone 0  
fill ~32 ~-24 ~49 ~52 ~-24 ~49 stone 0  
fill ~32 ~-24 ~50 ~52 ~-24 ~50 stone 0  
fill ~32 ~-24 ~51 ~52 ~-24 ~51 stone 0  
fill ~32 ~-24 ~52 ~52 ~-24 ~52 stone 0  
fill ~32 ~-24 ~53 ~52 ~-24 ~53 stone 0  
fill ~32 ~-24 ~54 ~52 ~-24 ~54 stone 0  
fill ~32 ~-24 ~55 ~52 ~-24 ~55 stone 0  
fill ~32 ~-24 ~56 ~51 ~-24 ~56 stone 0  
fill ~32 ~-24 ~57 ~52 ~-24 ~57 stone 0  
fill ~32 ~-24 ~58 ~49 ~-24 ~58 stone 0  
fill ~32 ~-24 ~59 ~47 ~-24 ~59 stone 0  
fill ~32 ~-24 ~60 ~45 ~-24 ~60 stone 0  
fill ~32 ~-24 ~61 ~44 ~-24 ~61 stone 0  
fill ~32 ~-24 ~62 ~44 ~-24 ~62 stone 0  
fill ~32 ~-24 ~63 ~44 ~-24 ~63 stone 0  
fill ~32 ~-24 ~64 ~45 ~-24 ~64 stone 0  
fill ~32 ~-24 ~65 ~46 ~-24 ~65 stone 0  
fill ~32 ~-24 ~66 ~52 ~-24 ~66 stone 0  
fill ~32 ~-24 ~67 ~52 ~-24 ~67 stone 0  
fill ~32 ~-24 ~68 ~52 ~-24 ~68 stone 0  
fill ~32 ~-24 ~69 ~52 ~-24 ~69 stone 0  
fill ~32 ~-24 ~70 ~52 ~-24 ~70 stone 0  
fill ~32 ~-24 ~71 ~106 ~-24 ~71 stone 0  
fill ~32 ~-24 ~72 ~106 ~-24 ~72 stone 0  
fill ~32 ~-24 ~73 ~106 ~-24 ~73 stone 0  
fill ~32 ~-24 ~74 ~106 ~-24 ~74 stone 0  
fill ~32 ~-24 ~75 ~106 ~-24 ~75 stone 0  
fill ~32 ~-24 ~76 ~106 ~-24 ~76 stone 0  
fill ~32 ~-24 ~77 ~106 ~-24 ~77 stone 0  
fill ~32 ~-24 ~78 ~106 ~-24 ~78 stone 0  
fill ~32 ~-24 ~79 ~106 ~-24 ~79 stone 0  
fill ~32 ~-24 ~80 ~106 ~-24 ~80 stone 0  
fill ~32 ~-24 ~81 ~106 ~-24 ~81 stone 0  
fill ~32 ~-24 ~82 ~106 ~-24 ~82 stone 0  
fill ~32 ~-24 ~83 ~106 ~-24 ~83 stone 0  
fill ~32 ~-24 ~84 ~106 ~-24 ~84 stone 0  
fill ~32 ~-24 ~85 ~106 ~-24 ~85 stone 0  
fill ~45 ~-24 ~61 ~52 ~-24 ~61 air  
fill ~45 ~-24 ~62 ~50 ~-24 ~62 air  
fill ~45 ~-24 ~63 ~45 ~-22 ~63 air  
fill ~46 ~-24 ~60 ~49 ~-24 ~60 air  
fill ~46 ~-24 ~64 ~50 ~-24 ~64 air  
fill ~47 ~-24 ~65 ~49 ~-24 ~65 air  
fill ~48 ~-24 ~59 ~49 ~-24 ~59 air  
fill ~48 ~-24 ~63 ~51 ~-24 ~63 air  
fill ~50 ~-24 ~58 ~51 ~-24 ~58 lava 10 
setblock ~50 ~-24 ~59 lava 2 
setblock ~50 ~-24 ~60 lava 4  
fill ~50 ~-24 ~65 ~52 ~-24 ~65 stone 0  
fill ~51 ~-24 ~59 ~52 ~-24 ~59 stone 0  
fill ~51 ~-24 ~60 ~51 ~-19 ~60 air  
fill ~51 ~-24 ~62 ~52 ~-24 ~62 stone 0  
fill ~51 ~-24 ~64 ~52 ~-24 ~64 stone 0  
fill ~52 ~-24 ~46 ~52 ~-20 ~46 air  
fill ~52 ~-24 ~47 ~52 ~-20 ~47 air  
fill ~52 ~-24 ~48 ~52 ~-20 ~48 air  
fill ~52 ~-24 ~56 ~53 ~-24 ~56 air  
fill ~52 ~-24 ~58 ~52 ~-21 ~58 stone 0  
fill ~52 ~-24 ~60 ~52 ~-19 ~60 stone 0  
fill ~52 ~-24 ~63 ~52 ~-23 ~63 stone 0  
fill ~53 ~-24 ~30 ~87 ~-24 ~30 netherrack 0  
fill ~53 ~-24 ~31 ~87 ~-24 ~31 netherrack 0  
fill ~53 ~-24 ~32 ~87 ~-24 ~32 netherrack 0  
fill ~53 ~-24 ~33 ~64 ~-24 ~33 netherrack 0  
fill ~53 ~-24 ~34 ~64 ~-24 ~34 netherrack 0  
fill ~53 ~-24 ~35 ~64 ~-24 ~35 netherrack 0  
fill ~53 ~-24 ~36 ~87 ~-24 ~36 netherrack 0  
fill ~53 ~-24 ~37 ~60 ~-24 ~37 netherrack 0  
fill ~53 ~-24 ~38 ~57 ~-24 ~38 netherrack 0  
fill ~53 ~-24 ~39 ~56 ~-24 ~39 netherrack 0  
fill ~53 ~-24 ~40 ~56 ~-24 ~40 netherrack 0  
fill ~53 ~-24 ~41 ~56 ~-24 ~41 netherrack 0  
fill ~53 ~-24 ~42 ~55 ~-24 ~42 netherrack 0  
fill ~53 ~-24 ~43 ~55 ~-24 ~43 netherrack 0  
fill ~53 ~-24 ~44 ~55 ~-24 ~44 netherrack 0  
fill ~53 ~-24 ~45 ~54 ~-24 ~45 netherrack 0  
fill ~53 ~-24 ~50 ~53 ~-21 ~50 netherrack 0  
fill ~53 ~-24 ~51 ~56 ~-24 ~51 netherrack 0  
fill ~53 ~-24 ~52 ~59 ~-24 ~52 netherrack 0  
fill ~53 ~-24 ~53 ~59 ~-24 ~53 netherrack 0  
fill ~53 ~-24 ~54 ~56 ~-24 ~54 netherrack 0  
fill ~53 ~-24 ~58 ~56 ~-24 ~58 netherrack 0  
fill ~53 ~-24 ~59 ~57 ~-24 ~59 netherrack 0  
fill ~53 ~-24 ~60 ~55 ~-24 ~60 netherrack 0  
fill ~53 ~-24 ~61 ~64 ~-24 ~61 netherrack 0  
fill ~53 ~-24 ~62 ~64 ~-24 ~62 netherrack 0  
fill ~53 ~-24 ~63 ~65 ~-24 ~63 netherrack 0  
fill ~53 ~-24 ~64 ~87 ~-24 ~64 netherrack 0  
fill ~53 ~-24 ~65 ~87 ~-24 ~65 netherrack 0  
fill ~53 ~-24 ~66 ~87 ~-24 ~66 netherrack 0  
fill ~53 ~-24 ~67 ~87 ~-24 ~67 netherrack 0  
fill ~53 ~-24 ~68 ~87 ~-24 ~68 netherrack 0  
fill ~53 ~-24 ~69 ~87 ~-24 ~69 netherrack 0  
fill ~53 ~-24 ~70 ~87 ~-24 ~70 netherrack 0  
fill ~54 ~-24 ~46 ~54 ~-26 ~46 netherrack 0  
fill ~54 ~-24 ~47 ~54 ~-24 ~49 netherrack 0 
setblock ~54 ~-24 ~50 lava 10  
fill ~54 ~-24 ~55 ~55 ~-24 ~55 netherrack 0  
fill ~54 ~-24 ~56 ~54 ~-23 ~56 netherrack 0  
fill ~55 ~-24 ~45 ~55 ~-22 ~45 lava 8  
fill ~55 ~-24 ~46 ~55 ~-22 ~46 lava 10  
fill ~55 ~-24 ~47 ~55 ~-24 ~49 lava 10 
setblock ~55 ~-24 ~50 lava 2  
fill ~55 ~-24 ~56 ~56 ~-24 ~56 lava 10  
fill ~55 ~-24 ~57 ~55 ~-23 ~57 lava 10  
fill ~56 ~-24 ~42 ~56 ~-24 ~45 lava 10  
fill ~56 ~-24 ~46 ~56 ~-24 ~48 lava 2  
fill ~56 ~-24 ~49 ~58 ~-24 ~49 lava 10  
fill ~56 ~-24 ~50 ~58 ~-24 ~50 netherrack 0 
setblock ~56 ~-24 ~55 lava 0  
fill ~56 ~-24 ~57 ~56 ~-26 ~57 netherrack 0 
setblock ~56 ~-24 ~60 air  
fill ~57 ~-24 ~39 ~57 ~-24 ~40 lava 10  
fill ~57 ~-24 ~41 ~57 ~-24 ~45 lava 2  
fill ~57 ~-24 ~46 ~58 ~-24 ~46 air 
setblock ~57 ~-24 ~47 fire 15  
fill ~57 ~-24 ~48 ~60 ~-24 ~48 air 
setblock ~57 ~-24 ~51 glowstone 0 
setblock ~57 ~-24 ~54 lava 12  
fill ~57 ~-24 ~55 ~58 ~-24 ~55 lava 2  
fill ~57 ~-24 ~56 ~57 ~-24 ~55 lava 2 
setblock ~57 ~-24 ~57 lava 12 
setblock ~57 ~-24 ~58 lava 10  
fill ~57 ~-24 ~60 ~60 ~-24 ~60 netherrack 0  
fill ~58 ~-24 ~38 ~60 ~-24 ~38 lava 10  
fill ~58 ~-24 ~39 ~60 ~-24 ~39 lava 2  
fill ~58 ~-24 ~40 ~58 ~-24 ~39 lava 2 
setblock ~58 ~-24 ~41 lava 4  
fill ~58 ~-24 ~42 ~60 ~-24 ~42 air  
fill ~58 ~-24 ~43 ~59 ~-24 ~43 air  
fill ~58 ~-24 ~44 ~58 ~-1 ~44 air 
setblock ~58 ~-24 ~45 lava 2  
fill ~58 ~-24 ~47 ~59 ~-24 ~47 air 
setblock ~58 ~-24 ~51 netherrack 0 
setblock ~58 ~-24 ~54 lava 0  
fill ~58 ~-24 ~57 ~58 ~-24 ~58 lava 2  
fill ~58 ~-24 ~59 ~60 ~-24 ~59 lava 10  
fill ~59 ~-24 ~40 ~59 ~-1 ~40 air  
fill ~59 ~-24 ~41 ~59 ~-1 ~41 air 
setblock ~59 ~-24 ~44 lava 2 
setblock ~59 ~-24 ~45 lava 0 
setblock ~59 ~-24 ~46 lava 2  
fill ~59 ~-24 ~49 ~59 ~-15 ~49 air  
fill ~59 ~-24 ~50 ~59 ~-25 ~50 lava 10 
setblock ~59 ~-24 ~51 lava 12 
setblock ~59 ~-24 ~54 netherrack 0 
setblock ~59 ~-24 ~55 lava 0  
fill ~59 ~-24 ~56 ~63 ~-24 ~56 netherrack 0 
setblock ~59 ~-24 ~57 lava 12 
setblock ~59 ~-24 ~58 lava 2  
fill ~60 ~-24 ~44 ~60 ~-24 ~46 lava 10 
setblock ~60 ~-24 ~47 lava 2 
setblock ~60 ~-24 ~50 lava 2  
fill ~60 ~-24 ~51 ~60 ~-24 ~53 lava 10 
setblock ~60 ~-24 ~54 lava 0  
fill ~60 ~-24 ~55 ~63 ~-24 ~55 netherrack 0  
fill ~60 ~-24 ~57 ~60 ~-24 ~59 lava 10  
fill ~61 ~-24 ~37 ~62 ~-24 ~37 lava 10 
setblock ~61 ~-24 ~38 lava 2  
fill ~61 ~-24 ~39 ~61 ~-1 ~39 air  
fill ~61 ~-24 ~40 ~61 ~-8 ~40 air  
fill ~61 ~-24 ~41 ~61 ~-11 ~41 air  
fill ~61 ~-24 ~43 ~63 ~-24 ~43 netherrack 0  
fill ~61 ~-24 ~44 ~62 ~-24 ~44 netherrack 0  
fill ~61 ~-24 ~45 ~62 ~-24 ~45 netherrack 0  
fill ~61 ~-24 ~47 ~64 ~-24 ~47 lava 0 
setblock ~61 ~-24 ~48 lava 10 
setblock ~61 ~-24 ~50 lava 10  
fill ~61 ~-24 ~51 ~61 ~-24 ~52 netherrack 0  
fill ~61 ~-24 ~53 ~63 ~-24 ~53 lava 8  
fill ~61 ~-24 ~54 ~62 ~-24 ~54 netherrack 0  
fill ~61 ~-24 ~57 ~63 ~-24 ~57 lava 8  
fill ~61 ~-24 ~58 ~63 ~-24 ~58 lava 8  
fill ~61 ~-24 ~59 ~63 ~-24 ~59 lava 8  
fill ~61 ~-24 ~60 ~61 ~-23 ~60 lava 8  
fill ~62 ~-24 ~38 ~62 ~-23 ~38 lava 10 
setblock ~62 ~-24 ~41 lava 10  
fill ~62 ~-24 ~42 ~64 ~-24 ~42 netherrack 0  
fill ~62 ~-24 ~46 ~62 ~-23 ~46 lava 8  
fill ~62 ~-24 ~48 ~65 ~-24 ~48 lava 0  
fill ~62 ~-24 ~49 ~65 ~-24 ~49 lava 0  
fill ~62 ~-24 ~50 ~64 ~-24 ~50 lava 0  
fill ~62 ~-24 ~51 ~62 ~-23 ~51 lava 0  
fill ~62 ~-24 ~52 ~62 ~-25 ~52 lava 8  
fill ~62 ~-24 ~60 ~65 ~-24 ~60 netherrack 0  
fill ~63 ~-24 ~37 ~87 ~-24 ~37 netherrack 0  
fill ~63 ~-24 ~38 ~87 ~-24 ~38 netherrack 0  
fill ~63 ~-24 ~39 ~68 ~-24 ~39 netherrack 0  
fill ~63 ~-24 ~40 ~66 ~-24 ~40 netherrack 0  
fill ~63 ~-24 ~41 ~65 ~-24 ~41 netherrack 0 
setblock ~63 ~-24 ~44 lava 0  
fill ~63 ~-24 ~45 ~63 ~-23 ~45 lava 8 
setblock ~63 ~-24 ~46 netherrack 0 
setblock ~63 ~-24 ~52 lava 0  
fill ~63 ~-24 ~54 ~63 ~-23 ~54 lava 8 
setblock ~64 ~-24 ~43 lava 0 
setblock ~64 ~-24 ~44 lava 2  
fill ~64 ~-24 ~45 ~64 ~-24 ~51 lava 0 
setblock ~64 ~-24 ~52 lava 2  
fill ~64 ~-24 ~53 ~64 ~-24 ~56 lava 0  
fill ~64 ~-24 ~57 ~64 ~-24 ~70 netherrack 0  
fill ~65 ~-24 ~33 ~66 ~-24 ~33 lava 10  
fill ~65 ~-24 ~34 ~65 ~-21 ~34 lava 10  
fill ~65 ~-24 ~35 ~65 ~-22 ~35 lava 10  
fill ~65 ~-24 ~42 ~67 ~-24 ~42 lava 8 
setblock ~65 ~-24 ~44 lava 0  
fill ~65 ~-24 ~46 ~65 ~-24 ~47 lava 2 
setblock ~65 ~-24 ~50 lava 2  
fill ~65 ~-24 ~51 ~65 ~-24 ~57 lava 0  
fill ~65 ~-24 ~58 ~65 ~-24 ~60 netherrack 0  
fill ~66 ~-24 ~34 ~66 ~-24 ~35 lava 2  
fill ~66 ~-24 ~41 ~67 ~-24 ~41 lava 8 
setblock ~66 ~-24 ~44 lava 10  
fill ~66 ~-24 ~45 ~66 ~-20 ~45 air  
fill ~66 ~-24 ~46 ~81 ~-24 ~46 air  
fill ~66 ~-24 ~47 ~80 ~-24 ~47 air  
fill ~66 ~-24 ~48 ~66 ~-24 ~49 lava 2 
setblock ~66 ~-24 ~50 lava 4  
fill ~66 ~-24 ~51 ~66 ~-24 ~54 lava 2  
fill ~66 ~-24 ~57 ~67 ~-24 ~57 netherrack 0  
fill ~66 ~-24 ~58 ~69 ~-24 ~58 lava 0 
setblock ~66 ~-24 ~59 netherrack 0 
setblock ~66 ~-24 ~60 lava 0  
fill ~66 ~-24 ~63 ~67 ~-24 ~63 air 
setblock ~67 ~-24 ~33 stone 0  
fill ~67 ~-24 ~34 ~67 ~-23 ~34 lava 10  
fill ~67 ~-24 ~35 ~67 ~-24 ~34 lava 10 
setblock ~67 ~-24 ~40 lava 10 
setblock ~67 ~-24 ~44 lava 0 
setblock ~67 ~-24 ~45 lava 2 
setblock ~67 ~-24 ~48 fire 15 
setblock ~67 ~-24 ~49 lava 4  
fill ~67 ~-24 ~50 ~81 ~-24 ~50 air 
setblock ~67 ~-24 ~51 fire 15  
fill ~67 ~-24 ~52 ~67 ~-21 ~52 air  
fill ~67 ~-24 ~53 ~67 ~-24 ~54 lava 2  
fill ~67 ~-24 ~55 ~67 ~-20 ~55 air 
setblock ~67 ~-24 ~56 lava 10  
fill ~67 ~-24 ~59 ~68 ~-24 ~59 lava 0 
setblock ~67 ~-24 ~61 lava 0  
fill ~68 ~-24 ~33 ~87 ~-24 ~33 netherrack 0  
fill ~68 ~-24 ~34 ~87 ~-24 ~34 netherrack 0  
fill ~68 ~-24 ~35 ~87 ~-24 ~35 netherrack 0  
fill ~68 ~-24 ~40 ~68 ~-16 ~40 air  
fill ~68 ~-24 ~41 ~68 ~-24 ~42 lava 0  
fill ~68 ~-24 ~43 ~69 ~-24 ~43 lava 10 
setblock ~68 ~-24 ~44 lava 2  
fill ~68 ~-24 ~45 ~82 ~-24 ~45 air  
fill ~68 ~-24 ~48 ~81 ~-24 ~48 air  
fill ~68 ~-24 ~49 ~70 ~-24 ~49 air  
fill ~68 ~-24 ~51 ~81 ~-24 ~51 air  
fill ~68 ~-24 ~52 ~69 ~-24 ~52 lava 2  
fill ~68 ~-24 ~53 ~69 ~-24 ~53 lava 0  
fill ~68 ~-24 ~54 ~68 ~-24 ~53 lava 0 
setblock ~68 ~-24 ~55 lava 2  
fill ~68 ~-24 ~56 ~71 ~-24 ~56 air  
fill ~68 ~-24 ~57 ~69 ~-24 ~57 lava 2  
fill ~68 ~-24 ~60 ~68 ~-26 ~60 netherrack 0 
setblock ~68 ~-24 ~61 lava 10  
fill ~68 ~-24 ~63 ~73 ~-24 ~63 netherrack 0 
setblock ~69 ~-24 ~39 lava 12 
setblock ~69 ~-24 ~40 lava 10  
fill ~69 ~-24 ~41 ~69 ~-24 ~42 lava 8  
fill ~69 ~-24 ~44 ~78 ~-24 ~44 air 
setblock ~69 ~-24 ~54 lava 2  
fill ~69 ~-24 ~55 ~73 ~-24 ~55 air 
setblock ~69 ~-24 ~59 lava 2 
setblock ~69 ~-24 ~60 lava 0  
fill ~69 ~-24 ~61 ~72 ~-24 ~61 netherrack 0  
fill ~69 ~-24 ~62 ~72 ~-24 ~62 netherrack 0  
fill ~70 ~-24 ~39 ~70 ~-24 ~40 fire 15  
fill ~70 ~-24 ~41 ~70 ~-24 ~42 lava 0  
fill ~70 ~-24 ~43 ~72 ~-24 ~43 lava 2  
fill ~70 ~-24 ~52 ~80 ~-24 ~52 air 
setblock ~70 ~-24 ~53 lava 2  
fill ~70 ~-24 ~54 ~74 ~-24 ~54 air  
fill ~70 ~-24 ~57 ~74 ~-24 ~57 air 
setblock ~70 ~-24 ~58 lava 2  
fill ~70 ~-24 ~59 ~70 ~-18 ~59 air 
setblock ~70 ~-24 ~60 lava 10 
setblock ~71 ~-24 ~39 lava 12 
setblock ~71 ~-24 ~40 lava 10  
fill ~71 ~-24 ~41 ~71 ~-25 ~41 lava 8  
fill ~71 ~-24 ~42 ~72 ~-24 ~42 lava 0 
setblock ~71 ~-24 ~49 fire 15  
fill ~71 ~-24 ~53 ~74 ~-24 ~53 air  
fill ~71 ~-24 ~58 ~71 ~-19 ~58 air 
setblock ~71 ~-24 ~59 lava 2  
fill ~71 ~-24 ~60 ~76 ~-24 ~60 lava 0 
setblock ~72 ~-24 ~39 fire 15  
fill ~72 ~-24 ~40 ~72 ~-15 ~40 air 
setblock ~72 ~-24 ~41 lava 0  
fill ~72 ~-24 ~49 ~81 ~-24 ~49 air  
fill ~72 ~-24 ~56 ~73 ~-24 ~56 fire 15  
fill ~72 ~-24 ~58 ~74 ~-24 ~58 lava 2  
fill ~72 ~-24 ~59 ~76 ~-24 ~59 lava 0  
fill ~73 ~-24 ~39 ~76 ~-24 ~39 lava 12  
fill ~73 ~-24 ~40 ~74 ~-24 ~40 lava 2  
fill ~73 ~-24 ~41 ~73 ~-24 ~42 lava 2  
fill ~73 ~-24 ~43 ~74 ~-24 ~43 air  
fill ~73 ~-24 ~61 ~76 ~-24 ~61 lava 0 
setblock ~73 ~-24 ~62 lava 12 
setblock ~74 ~-24 ~41 lava 10 
setblock ~74 ~-24 ~42 lava 2 
setblock ~74 ~-24 ~55 lava 2  
fill ~74 ~-24 ~56 ~74 ~-18 ~56 air  
fill ~74 ~-24 ~62 ~75 ~-24 ~62 lava 2  
fill ~74 ~-24 ~63 ~74 ~-23 ~63 lava 10  
fill ~75 ~-24 ~40 ~76 ~-24 ~40 lava 10 
setblock ~75 ~-24 ~42 lava 0 
setblock ~75 ~-24 ~43 lava 2 
setblock ~75 ~-24 ~53 fire 15  
fill ~75 ~-24 ~54 ~76 ~-24 ~54 lava 2  
fill ~75 ~-24 ~55 ~76 ~-24 ~55 lava 0  
fill ~75 ~-24 ~56 ~76 ~-24 ~56 lava 2  
fill ~75 ~-24 ~57 ~75 ~-24 ~56 lava 2 
setblock ~75 ~-24 ~58 lava 0  
fill ~75 ~-24 ~63 ~75 ~-22 ~63 lava 14  
fill ~76 ~-24 ~41 ~76 ~-24 ~42 lava 8 
setblock ~76 ~-24 ~43 lava 10  
fill ~76 ~-24 ~53 ~80 ~-24 ~53 air  
fill ~76 ~-24 ~57 ~77 ~-24 ~57 air 
setblock ~76 ~-24 ~58 lava 2 
setblock ~76 ~-24 ~62 lava 10  
fill ~76 ~-24 ~63 ~87 ~-24 ~63 netherrack 0  
fill ~77 ~-24 ~39 ~87 ~-24 ~39 netherrack 0  
fill ~77 ~-24 ~40 ~78 ~-24 ~40 lava 12  
fill ~77 ~-24 ~41 ~77 ~-24 ~42 lava 10 
setblock ~77 ~-24 ~43 lava 2  
fill ~77 ~-24 ~54 ~80 ~-24 ~54 air 
setblock ~77 ~-24 ~55 lava 2  
fill ~77 ~-24 ~56 ~78 ~-24 ~56 air  
fill ~77 ~-24 ~58 ~78 ~-24 ~58 air  
fill ~77 ~-24 ~59 ~77 ~-24 ~60 lava 2  
fill ~77 ~-24 ~61 ~78 ~-24 ~61 fire 15 
setblock ~77 ~-24 ~62 lava 12  
fill ~78 ~-24 ~41 ~78 ~-24 ~42 lava 2  
fill ~78 ~-24 ~43 ~79 ~-24 ~43 lava 4  
fill ~78 ~-24 ~55 ~79 ~-24 ~55 air  
fill ~78 ~-24 ~57 ~80 ~-24 ~57 fire 15 
setblock ~78 ~-24 ~59 fire 15  
fill ~78 ~-24 ~60 ~83 ~-24 ~60 netherrack 0  
fill ~78 ~-24 ~62 ~87 ~-24 ~62 netherrack 0  
fill ~79 ~-24 ~40 ~87 ~-24 ~40 netherrack 0 
setblock ~79 ~-24 ~41 lava 14 
setblock ~79 ~-24 ~42 lava 2 
setblock ~79 ~-24 ~44 lava 6  
fill ~79 ~-24 ~56 ~81 ~-24 ~56 fire 15 
setblock ~79 ~-24 ~58 fire 15  
fill ~79 ~-24 ~59 ~83 ~-24 ~59 netherrack 0  
fill ~79 ~-24 ~61 ~87 ~-24 ~61 netherrack 0  
fill ~80 ~-24 ~41 ~83 ~-24 ~41 netherrack 0 
setblock ~80 ~-24 ~42 lava 14 
setblock ~80 ~-24 ~43 lava 2  
fill ~80 ~-24 ~55 ~82 ~-24 ~55 fire 15 
setblock ~80 ~-24 ~58 glowstone 0  
fill ~81 ~-24 ~42 ~83 ~-24 ~42 netherrack 0  
fill ~81 ~-24 ~44 ~81 ~-10 ~44 air  
fill ~81 ~-24 ~47 ~83 ~-24 ~47 fire 15  
fill ~81 ~-24 ~52 ~83 ~-24 ~52 fire 15  
fill ~81 ~-24 ~53 ~82 ~-24 ~53 fire 15  
fill ~81 ~-24 ~54 ~82 ~-24 ~54 fire 15  
fill ~81 ~-24 ~57 ~83 ~-24 ~57 netherrack 0  
fill ~81 ~-24 ~58 ~83 ~-24 ~58 netherrack 0 
setblock ~82 ~-24 ~46 fire 15   
fill ~82 ~-24 ~48 ~83 ~-24 ~48 fire 15  
fill ~82 ~-24 ~49 ~82 ~-24 ~50 fire 15 
setblock ~82 ~-24 ~51 stone 0 
setblock ~82 ~-24 ~56 netherrack 0  
fill ~83 ~-24 ~43 ~87 ~-24 ~43 netherrack 0  
fill ~83 ~-24 ~44 ~87 ~-24 ~44 netherrack 0  
fill ~83 ~-24 ~45 ~84 ~-24 ~45 netherrack 0 
setblock ~83 ~-24 ~46 lava 6  
fill ~83 ~-24 ~49 ~83 ~-9 ~49 air  
fill ~83 ~-24 ~50 ~85 ~-24 ~50 air  
fill ~83 ~-24 ~51 ~84 ~-24 ~51 fire 15 
setblock ~83 ~-24 ~53 lava 6  
fill ~83 ~-24 ~54 ~84 ~-24 ~54 netherrack 0  
fill ~83 ~-24 ~55 ~83 ~-24 ~54 netherrack 0 
setblock ~83 ~-24 ~56 stone 0  
fill ~84 ~-24 ~41 ~85 ~-24 ~41 lava 10 
setblock ~84 ~-24 ~42 lava 2 
setblock ~84 ~-24 ~46 lava 4 
setblock ~84 ~-24 ~47 netherrack 0 
setblock ~84 ~-24 ~48 lava 10 
setblock ~84 ~-24 ~49 lava 2 
setblock ~84 ~-24 ~52 stone 0 
setblock ~84 ~-24 ~53 lava 4 
setblock ~84 ~-24 ~55 stone 0  
fill ~84 ~-24 ~56 ~84 ~-23 ~56 netherrack 0  
fill ~84 ~-24 ~57 ~85 ~-24 ~57 stone 0 
setblock ~84 ~-24 ~58 lava 12 
setblock ~84 ~-24 ~59 lava 2 
setblock ~84 ~-24 ~60 stone 0 
setblock ~85 ~-24 ~42 lava 10 
setblock ~85 ~-24 ~45 lava 10 
setblock ~85 ~-24 ~46 lava 2 
setblock ~85 ~-24 ~47 lava 10  
fill ~85 ~-24 ~48 ~87 ~-24 ~48 netherrack 0 
setblock ~85 ~-24 ~49 lava 10 
setblock ~85 ~-24 ~51 stone 0  
fill ~85 ~-24 ~52 ~85 ~-8 ~52 air 
setblock ~85 ~-24 ~53 lava 2 
setblock ~85 ~-24 ~54 lava 10 
setblock ~85 ~-24 ~55 netherrack 0 
setblock ~85 ~-24 ~56 stone 0 
setblock ~85 ~-24 ~58 lava 2 
setblock ~85 ~-24 ~59 lava 4  
fill ~85 ~-24 ~60 ~87 ~-24 ~60 netherrack 0  
fill ~86 ~-24 ~41 ~87 ~-24 ~41 netherrack 0  
fill ~86 ~-24 ~42 ~87 ~-24 ~42 netherrack 0  
fill ~86 ~-24 ~45 ~87 ~-24 ~45 netherrack 0 
setblock ~86 ~-24 ~46 lava 10  
fill ~86 ~-24 ~47 ~87 ~-24 ~47 netherrack 0  
fill ~86 ~-24 ~49 ~87 ~-24 ~49 netherrack 0  
fill ~86 ~-24 ~50 ~86 ~-23 ~50 stone 0  
fill ~86 ~-24 ~51 ~87 ~-24 ~51 netherrack 0 
setblock ~86 ~-24 ~52 stone 0 
setblock ~86 ~-24 ~53 lava 10  
fill ~86 ~-24 ~54 ~87 ~-24 ~54 netherrack 0  
fill ~86 ~-24 ~55 ~106 ~-24 ~55 stone 0  
fill ~86 ~-24 ~56 ~87 ~-24 ~56 air  
fill ~86 ~-24 ~57 ~87 ~-24 ~57 air  
fill ~86 ~-24 ~58 ~106 ~-24 ~58 stone 0  
fill ~86 ~-24 ~59 ~86 ~-24 ~58 stone 0  
fill ~87 ~-24 ~46 ~87 ~-23 ~46 netherrack 0 
setblock ~87 ~-24 ~50 netherrack 0  
fill ~87 ~-24 ~52 ~87 ~-24 ~54 netherrack 0 
setblock ~87 ~-24 ~59 netherrack 0  
fill ~88 ~-24 ~30 ~106 ~-24 ~30 stone 0  
fill ~88 ~-24 ~31 ~106 ~-24 ~31 stone 0  
fill ~88 ~-24 ~32 ~106 ~-24 ~32 stone 0  
fill ~88 ~-24 ~33 ~106 ~-24 ~33 stone 0  
fill ~88 ~-24 ~34 ~106 ~-24 ~34 stone 0  
fill ~88 ~-24 ~35 ~106 ~-24 ~35 stone 0  
fill ~88 ~-24 ~36 ~106 ~-24 ~36 stone 0  
fill ~88 ~-24 ~37 ~106 ~-24 ~37 stone 0  
fill ~88 ~-24 ~38 ~106 ~-24 ~38 stone 0  
fill ~88 ~-24 ~39 ~106 ~-24 ~39 stone 0  
fill ~88 ~-24 ~40 ~106 ~-24 ~40 stone 0  
fill ~88 ~-24 ~41 ~106 ~-24 ~41 stone 0  
fill ~88 ~-24 ~42 ~106 ~-24 ~42 stone 0  
fill ~88 ~-24 ~43 ~106 ~-24 ~43 stone 0  
fill ~88 ~-24 ~44 ~106 ~-24 ~44 stone 0  
fill ~88 ~-24 ~45 ~106 ~-24 ~45 stone 0  
fill ~88 ~-24 ~46 ~106 ~-24 ~46 stone 0  
fill ~88 ~-24 ~47 ~106 ~-24 ~47 stone 0  
fill ~88 ~-24 ~48 ~106 ~-24 ~48 stone 0  
fill ~88 ~-24 ~49 ~106 ~-24 ~49 stone 0  
fill ~88 ~-24 ~50 ~106 ~-24 ~50 stone 0  
fill ~88 ~-24 ~51 ~106 ~-24 ~51 stone 0  
fill ~88 ~-24 ~52 ~106 ~-24 ~52 stone 0  
fill ~88 ~-24 ~53 ~106 ~-24 ~53 stone 0  
fill ~88 ~-24 ~54 ~106 ~-24 ~54 stone 0  
fill ~88 ~-24 ~56 ~106 ~-24 ~56 stone 0  
fill ~88 ~-24 ~57 ~106 ~-24 ~57 stone 0  
fill ~88 ~-24 ~59 ~106 ~-24 ~59 stone 0  
fill ~88 ~-24 ~60 ~106 ~-24 ~60 stone 0  
fill ~88 ~-24 ~61 ~106 ~-24 ~61 stone 0  
fill ~88 ~-24 ~62 ~106 ~-24 ~62 stone 0  
fill ~88 ~-24 ~63 ~106 ~-24 ~63 stone 0  
fill ~88 ~-24 ~64 ~106 ~-24 ~64 stone 0  
fill ~88 ~-24 ~65 ~106 ~-24 ~65 stone 0  
fill ~88 ~-24 ~66 ~106 ~-24 ~66 stone 0  
fill ~88 ~-24 ~67 ~106 ~-24 ~67 stone 0  
fill ~88 ~-24 ~68 ~106 ~-24 ~68 stone 0  
fill ~88 ~-24 ~69 ~106 ~-24 ~69 stone 0  
fill ~88 ~-24 ~70 ~106 ~-24 ~70 stone 0  
fill ~107 ~-24 ~22 ~181 ~-24 ~22 dirt 0  
fill ~107 ~-24 ~23 ~181 ~-24 ~23 dirt 0  
fill ~107 ~-24 ~24 ~181 ~-24 ~24 dirt 0  
fill ~107 ~-24 ~25 ~181 ~-24 ~25 dirt 0  
fill ~107 ~-24 ~26 ~181 ~-24 ~26 dirt 0  
fill ~107 ~-24 ~27 ~160 ~-24 ~27 dirt 0  
fill ~107 ~-24 ~28 ~181 ~-24 ~28 dirt 0  
