fill ~37 ~0 ~31 ~38 ~0 ~31 stone_slab 11  
fill ~37 ~0 ~33 ~38 ~0 ~33 stone_slab 11 
setblock ~40 ~0 ~31 stone_slab 11 
setblock ~40 ~0 ~33 stone_slab 11 
setblock ~35 ~1 ~31 stone_slab 3 
setblock ~35 ~1 ~33 stone_slab 3 
setblock ~36 ~1 ~31 double_stone_slab 3 
setblock ~36 ~1 ~32 double_stone_slab 5 
setblock ~36 ~1 ~33 double_stone_slab 3 
setblock ~37 ~1 ~31 stone_stairs 1 
setblock ~37 ~1 ~32 stone_slab 3 
setblock ~37 ~1 ~33 stone_stairs 1  
fill ~38 ~1 ~31 ~42 ~1 ~31 stone_slab 3  
fill ~38 ~1 ~33 ~42 ~1 ~33 stone_slab 3  
fill ~24 ~2 ~30 ~25 ~2 ~30 stone_slab 13  
fill ~24 ~2 ~34 ~25 ~2 ~34 stone_slab 13 
setblock ~26 ~2 ~31 stone_slab 13 
setblock ~26 ~2 ~33 stone_slab 13  
fill ~27 ~2 ~32 ~33 ~2 ~32 stone_slab 13 
setblock ~30 ~2 ~23 stone_slab 13  
fill ~31 ~2 ~24 ~31 ~2 ~25 stone_slab 13  
fill ~31 ~2 ~41 ~31 ~2 ~42 stone_slab 13 
setblock ~32 ~2 ~26 stone_slab 13  
fill ~32 ~2 ~39 ~32 ~2 ~40 stone_slab 13  
fill ~33 ~2 ~27 ~33 ~2 ~28 stone_slab 13  
fill ~33 ~2 ~37 ~33 ~2 ~38 stone_slab 13  
fill ~34 ~2 ~29 ~35 ~2 ~29 stone_slab 13  
fill ~34 ~2 ~30 ~34 ~2 ~29 stone_slab 13  
fill ~34 ~2 ~34 ~34 ~2 ~36 stone_slab 13  
fill ~35 ~2 ~31 ~35 ~2 ~33 stone_slab 8  
fill ~36 ~2 ~27 ~36 ~2 ~28 stone_slab 13  
fill ~36 ~2 ~30 ~40 ~2 ~30 stone_slab 8  
fill ~36 ~2 ~32 ~36 ~3 ~32 double_stone_slab 0  
fill ~36 ~2 ~34 ~40 ~2 ~34 stone_slab 8 
setblock ~37 ~2 ~26 stone_slab 13 
setblock ~37 ~2 ~35 stone_slab 13  
fill ~38 ~2 ~24 ~38 ~2 ~25 stone_slab 13  
fill ~38 ~2 ~31 ~40 ~2 ~31 stained_glass 7  
fill ~38 ~2 ~32 ~40 ~2 ~32 stained_glass 7  
fill ~38 ~2 ~33 ~40 ~2 ~33 stained_glass 7  
fill ~38 ~2 ~36 ~38 ~2 ~37 stone_slab 13 
setblock ~39 ~2 ~23 stone_slab 13  
fill ~39 ~2 ~38 ~39 ~2 ~39 stone_slab 13 
setblock ~40 ~2 ~40 stone_slab 13  
fill ~41 ~2 ~31 ~41 ~2 ~33 stone_slab 8 
setblock ~23 ~3 ~34 lever 2  
fill ~24 ~3 ~29 ~27 ~3 ~29 double_stone_slab 0  
fill ~24 ~3 ~30 ~44 ~3 ~30 double_stone_slab 0  
fill ~24 ~3 ~31 ~37 ~3 ~31 double_stone_slab 0  
fill ~24 ~3 ~32 ~37 ~3 ~32 double_stone_slab 0  
fill ~24 ~3 ~33 ~37 ~3 ~33 double_stone_slab 0  
fill ~24 ~3 ~34 ~29 ~3 ~34 double_stone_slab 0  
fill ~24 ~3 ~35 ~34 ~3 ~35 double_stone_slab 0  
fill ~25 ~3 ~27 ~26 ~3 ~27 double_stone_slab 0  
fill ~25 ~3 ~28 ~31 ~3 ~28 double_stone_slab 0  
fill ~25 ~3 ~36 ~25 ~9 ~36 double_stone_slab 0  
fill ~25 ~3 ~37 ~25 ~9 ~37 double_stone_slab 0  
fill ~26 ~3 ~26 ~28 ~3 ~26 double_stone_slab 5  
fill ~26 ~3 ~36 ~27 ~3 ~36 double_stone_slab 5  
fill ~26 ~3 ~37 ~29 ~3 ~37 double_stone_slab 5  
fill ~26 ~3 ~38 ~30 ~3 ~38 double_stone_slab 5  
fill ~27 ~3 ~25 ~29 ~3 ~25 double_stone_slab 5 
setblock ~27 ~3 ~27 double_stone_slab 5  
fill ~27 ~3 ~39 ~30 ~3 ~39 double_stone_slab 5 
setblock ~28 ~3 ~24 double_stone_slab 5  
fill ~28 ~3 ~27 ~43 ~3 ~27 double_stone_slab 0 
setblock ~28 ~3 ~29 stone_slab 5  
fill ~28 ~3 ~36 ~34 ~3 ~36 double_stone_slab 0  
fill ~28 ~3 ~40 ~31 ~3 ~40 double_stone_slab 5  
fill ~29 ~3 ~23 ~39 ~3 ~23 double_stone_slab 0  
fill ~29 ~3 ~24 ~35 ~3 ~24 double_stone_slab 0  
fill ~29 ~3 ~26 ~42 ~3 ~26 double_stone_slab 0  
fill ~29 ~3 ~29 ~44 ~3 ~29 double_stone_slab 0  
fill ~29 ~3 ~41 ~31 ~3 ~41 double_stone_slab 5  
fill ~30 ~3 ~25 ~41 ~3 ~25 double_stone_slab 0 
setblock ~30 ~3 ~34 stone_slab 5  
fill ~30 ~3 ~37 ~33 ~3 ~37 double_stone_slab 0  
fill ~31 ~3 ~22 ~37 ~3 ~22 double_stone_slab 0  
fill ~31 ~3 ~34 ~34 ~3 ~34 double_stone_slab 0  
fill ~31 ~3 ~38 ~42 ~3 ~38 double_stone_slab 0  
fill ~31 ~3 ~39 ~34 ~3 ~39 double_stone_slab 0  
fill ~31 ~3 ~42 ~37 ~3 ~42 double_stone_slab 0 
setblock ~32 ~3 ~2 stone_slab 13  
fill ~32 ~3 ~19 ~32 ~3 ~21 stone_slab 13 
setblock ~32 ~3 ~28 stone_slab 5  
fill ~32 ~3 ~40 ~40 ~3 ~40 double_stone_slab 0  
fill ~32 ~3 ~41 ~39 ~3 ~41 double_stone_slab 0  
fill ~32 ~3 ~49 ~32 ~3 ~51 stone_slab 13 
setblock ~33 ~3 ~1 stone_slab 13  
fill ~33 ~3 ~3 ~33 ~3 ~7 stone_slab 13 
setblock ~33 ~3 ~18 stone_slab 13  
fill ~33 ~3 ~21 ~34 ~3 ~21 lever 7  
fill ~33 ~3 ~28 ~39 ~3 ~28 double_stone_slab 0  
fill ~33 ~3 ~43 ~33 ~3 ~48 stone_slab 13  
fill ~33 ~3 ~51 ~37 ~3 ~51 stone_slab 13 
setblock ~34 ~3 ~2 stone_slab 13  
fill ~34 ~3 ~8 ~34 ~3 ~12 stone_slab 13  
fill ~34 ~3 ~17 ~35 ~3 ~17 stone_slab 13  
fill ~34 ~3 ~37 ~35 ~3 ~37 stained_hardened_clay 14  
fill ~34 ~3 ~50 ~35 ~3 ~50 lever 7  
fill ~34 ~3 ~52 ~35 ~3 ~52 lever 15  
fill ~35 ~3 ~6 ~35 ~3 ~7 lever 0  
fill ~35 ~3 ~13 ~35 ~3 ~21 stone_slab 13  
fill ~35 ~3 ~34 ~35 ~3 ~37 stained_hardened_clay 14 
setblock ~35 ~3 ~39 stone_slab 5  
fill ~36 ~3 ~6 ~36 ~3 ~7 stone_slab 13 
setblock ~36 ~3 ~24 stone_slab 5  
fill ~36 ~3 ~34 ~44 ~3 ~34 double_stone_slab 0  
fill ~36 ~3 ~35 ~36 ~3 ~36 stained_hardened_clay 14  
fill ~36 ~3 ~37 ~43 ~3 ~37 double_stone_slab 0  
fill ~36 ~3 ~39 ~41 ~3 ~39 double_stone_slab 0  
fill ~37 ~3 ~6 ~37 ~3 ~7 lever 8  
fill ~37 ~3 ~24 ~40 ~3 ~24 double_stone_slab 0  
fill ~37 ~3 ~35 ~44 ~3 ~35 double_stone_slab 0  
fill ~37 ~3 ~36 ~43 ~3 ~36 double_stone_slab 0 
setblock ~40 ~3 ~28 stone_slab 5  
fill ~41 ~3 ~28 ~43 ~3 ~28 double_stone_slab 0  
fill ~41 ~3 ~31 ~44 ~3 ~31 double_stone_slab 0  
fill ~41 ~3 ~32 ~44 ~3 ~32 double_stone_slab 0  
fill ~41 ~3 ~33 ~44 ~3 ~33 double_stone_slab 0  
fill ~45 ~3 ~29 ~48 ~3 ~29 stone_slab 8  
fill ~45 ~3 ~30 ~48 ~3 ~30 stone_slab 8  
fill ~45 ~3 ~31 ~48 ~3 ~31 stone_slab 8  
fill ~45 ~3 ~32 ~48 ~3 ~32 stone_slab 8  
fill ~45 ~3 ~33 ~48 ~3 ~33 stone_slab 8  
fill ~45 ~3 ~34 ~48 ~3 ~34 stone_slab 8  
fill ~45 ~3 ~35 ~48 ~3 ~35 stone_slab 8 
setblock ~46 ~3 ~36 stone_button 0 
setblock ~47 ~3 ~28 stone_button 0 
setblock ~51 ~3 ~29 stone_button 0  
fill ~51 ~3 ~32 ~51 ~3 ~33 lever 0 
setblock ~52 ~3 ~30 stone_button 0  
fill ~52 ~3 ~32 ~52 ~3 ~33 stone_slab 13 
setblock ~52 ~3 ~35 stone_button 0  
fill ~53 ~3 ~32 ~53 ~3 ~33 lever 8  
fill ~69 ~3 ~31 ~71 ~3 ~31 stone_slab 13  
fill ~69 ~3 ~32 ~71 ~3 ~32 stone_slab 13  
fill ~69 ~3 ~33 ~71 ~3 ~33 stone_slab 13  
fill ~72 ~3 ~31 ~74 ~3 ~31 double_stone_slab 5  
fill ~72 ~3 ~32 ~74 ~3 ~32 double_stone_slab 5  
fill ~72 ~3 ~33 ~74 ~3 ~33 double_stone_slab 5  
fill ~75 ~3 ~31 ~75 ~3 ~33 stone_brick_stairs 5  
fill ~17 ~4 ~16 ~30 ~4 ~16 stone_slab 8  
fill ~17 ~4 ~17 ~30 ~4 ~17 stone_slab 8  
fill ~17 ~4 ~18 ~30 ~4 ~18 stone_slab 8  
fill ~17 ~4 ~19 ~18 ~4 ~19 stone_slab 8  
fill ~17 ~4 ~20 ~18 ~4 ~20 stone_slab 8  
fill ~17 ~4 ~21 ~18 ~4 ~21 stone_slab 8  
fill ~17 ~4 ~22 ~18 ~4 ~22 stone_slab 8  
fill ~17 ~4 ~23 ~28 ~4 ~23 stone_slab 8  
fill ~17 ~4 ~24 ~27 ~4 ~24 stone_slab 8  
fill ~17 ~4 ~25 ~26 ~4 ~25 stone_slab 8  
fill ~17 ~4 ~26 ~25 ~4 ~26 stone_slab 8  
fill ~17 ~4 ~27 ~24 ~4 ~27 stone_slab 8  
fill ~17 ~4 ~28 ~24 ~4 ~28 stone_slab 8  
fill ~17 ~4 ~29 ~23 ~4 ~29 stone_slab 8  
fill ~17 ~4 ~30 ~23 ~4 ~30 stone_slab 8  
fill ~17 ~4 ~31 ~23 ~4 ~31 stone_slab 8  
fill ~17 ~4 ~32 ~23 ~4 ~32 stone_slab 8  
fill ~17 ~4 ~33 ~23 ~4 ~33 stone_slab 8  
fill ~17 ~4 ~34 ~23 ~4 ~34 stone_slab 8  
fill ~17 ~4 ~35 ~23 ~4 ~35 stone_slab 8  
fill ~17 ~4 ~36 ~24 ~4 ~36 stone_slab 8  
fill ~17 ~4 ~37 ~24 ~4 ~37 stone_slab 8  
fill ~17 ~4 ~38 ~25 ~4 ~38 stone_slab 8  
fill ~17 ~4 ~39 ~26 ~4 ~39 stone_slab 8  
fill ~17 ~4 ~40 ~27 ~4 ~40 stone_slab 8  
fill ~17 ~4 ~41 ~28 ~4 ~41 stone_slab 8  
fill ~17 ~4 ~42 ~18 ~4 ~42 stone_slab 8  
fill ~17 ~4 ~43 ~18 ~4 ~43 stone_slab 8  
fill ~17 ~4 ~44 ~18 ~4 ~44 stone_slab 8  
fill ~17 ~4 ~45 ~18 ~4 ~45 stone_slab 8  
fill ~17 ~4 ~46 ~30 ~4 ~46 stone_slab 8  
fill ~17 ~4 ~47 ~30 ~4 ~47 stone_slab 8  
fill ~17 ~4 ~48 ~30 ~4 ~48 stone_slab 8  
fill ~19 ~4 ~19 ~26 ~4 ~19 stone_slab 13  
fill ~19 ~4 ~20 ~26 ~4 ~20 stone_slab 13  
fill ~19 ~4 ~21 ~26 ~4 ~21 stone_slab 13  
fill ~19 ~4 ~22 ~26 ~4 ~22 stone_slab 13  
fill ~19 ~4 ~42 ~26 ~4 ~42 stone_slab 13  
fill ~19 ~4 ~43 ~26 ~4 ~43 stone_slab 13  
fill ~19 ~4 ~44 ~26 ~4 ~44 stone_slab 13  
fill ~19 ~4 ~45 ~26 ~4 ~45 stone_slab 13  
fill ~24 ~4 ~29 ~24 ~9 ~29 double_stone_slab 0  
fill ~24 ~4 ~30 ~24 ~9 ~30 double_stone_slab 0  
fill ~24 ~4 ~31 ~24 ~9 ~31 double_stone_slab 0  
fill ~24 ~4 ~32 ~24 ~3 ~32 double_stone_slab 0  
fill ~24 ~4 ~33 ~24 ~3 ~33 double_stone_slab 0  
fill ~24 ~4 ~34 ~24 ~9 ~34 double_stone_slab 0  
fill ~24 ~4 ~35 ~24 ~9 ~35 double_stone_slab 0  
fill ~25 ~4 ~27 ~25 ~9 ~27 double_stone_slab 0  
fill ~25 ~4 ~28 ~25 ~9 ~28 double_stone_slab 0  
fill ~26 ~4 ~26 ~26 ~8 ~26 double_stone_slab 0  
fill ~26 ~4 ~38 ~26 ~9 ~38 double_stone_slab 0  
fill ~27 ~4 ~19 ~30 ~4 ~19 stone_slab 8  
fill ~27 ~4 ~20 ~30 ~4 ~20 stone_slab 8  
fill ~27 ~4 ~21 ~30 ~4 ~21 stone_slab 8  
fill ~27 ~4 ~22 ~30 ~4 ~22 stone_slab 8  
fill ~27 ~4 ~25 ~27 ~8 ~25 double_stone_slab 0  
fill ~27 ~4 ~39 ~27 ~9 ~39 double_stone_slab 0  
fill ~27 ~4 ~42 ~30 ~4 ~42 stone_slab 8  
fill ~27 ~4 ~43 ~30 ~4 ~43 stone_slab 8  
fill ~27 ~4 ~44 ~30 ~4 ~44 stone_slab 8  
fill ~27 ~4 ~45 ~30 ~4 ~45 stone_slab 8  
fill ~28 ~4 ~24 ~28 ~8 ~24 double_stone_slab 0  
fill ~28 ~4 ~40 ~28 ~9 ~40 double_stone_slab 0  
fill ~29 ~4 ~23 ~30 ~4 ~23 double_stone_slab 0  
fill ~29 ~4 ~41 ~30 ~4 ~41 double_stone_slab 0 
setblock ~31 ~4 ~0 stone_slab 8  
fill ~31 ~4 ~1 ~37 ~4 ~1 double_stone_slab 0  
fill ~31 ~4 ~2 ~32 ~4 ~2 double_stone_slab 0  
fill ~31 ~4 ~3 ~37 ~4 ~3 double_stone_slab 0  
fill ~31 ~4 ~4 ~37 ~4 ~4 double_stone_slab 0  
fill ~31 ~4 ~5 ~37 ~4 ~5 double_stone_slab 0  
fill ~31 ~4 ~6 ~37 ~4 ~6 double_stone_slab 0  
fill ~31 ~4 ~7 ~37 ~4 ~7 double_stone_slab 0  
fill ~31 ~4 ~8 ~37 ~4 ~8 double_stone_slab 0  
fill ~31 ~4 ~9 ~37 ~4 ~9 double_stone_slab 0  
fill ~31 ~4 ~10 ~37 ~4 ~10 double_stone_slab 0  
fill ~31 ~4 ~11 ~37 ~4 ~11 double_stone_slab 0  
fill ~31 ~4 ~12 ~37 ~4 ~12 double_stone_slab 0  
fill ~31 ~4 ~13 ~37 ~4 ~13 double_stone_slab 0  
fill ~31 ~4 ~14 ~37 ~4 ~14 double_stone_slab 0  
fill ~31 ~4 ~15 ~37 ~4 ~15 double_stone_slab 0  
fill ~31 ~4 ~16 ~37 ~4 ~16 double_stone_slab 0  
fill ~31 ~4 ~17 ~37 ~4 ~17 double_stone_slab 0  
fill ~31 ~4 ~18 ~37 ~4 ~18 double_stone_slab 0  
fill ~31 ~4 ~19 ~37 ~4 ~19 double_stone_slab 0  
fill ~31 ~4 ~20 ~37 ~4 ~20 double_stone_slab 0  
fill ~31 ~4 ~21 ~37 ~4 ~21 double_stone_slab 0  
fill ~31 ~4 ~22 ~37 ~4 ~22 double_stone_slab 0  
fill ~31 ~4 ~42 ~37 ~4 ~42 double_stone_slab 0  
fill ~31 ~4 ~43 ~32 ~4 ~43 double_stone_slab 0  
fill ~31 ~4 ~44 ~32 ~4 ~44 double_stone_slab 0  
fill ~31 ~4 ~45 ~32 ~4 ~45 double_stone_slab 0  
fill ~31 ~4 ~46 ~32 ~4 ~46 double_stone_slab 0  
fill ~31 ~4 ~47 ~32 ~4 ~47 double_stone_slab 0  
fill ~31 ~4 ~48 ~32 ~4 ~48 double_stone_slab 0  
fill ~31 ~4 ~49 ~31 ~5 ~49 double_stone_slab 0  
fill ~31 ~4 ~50 ~31 ~5 ~50 double_stone_slab 0  
fill ~31 ~4 ~51 ~31 ~5 ~51 double_stone_slab 0  
fill ~31 ~4 ~52 ~31 ~5 ~52 double_stone_slab 0  
fill ~31 ~4 ~53 ~31 ~5 ~53 double_stone_slab 0  
fill ~31 ~4 ~54 ~31 ~5 ~54 double_stone_slab 0  
fill ~31 ~4 ~55 ~32 ~4 ~55 double_stone_slab 0  
fill ~31 ~4 ~56 ~32 ~4 ~56 double_stone_slab 0  
fill ~31 ~4 ~57 ~32 ~4 ~57 double_stone_slab 0  
fill ~31 ~4 ~58 ~32 ~4 ~58 double_stone_slab 0  
fill ~31 ~4 ~59 ~32 ~4 ~59 double_stone_slab 0  
fill ~31 ~4 ~60 ~32 ~4 ~60 double_stone_slab 0  
fill ~31 ~4 ~61 ~32 ~4 ~61 double_stone_slab 0  
fill ~31 ~4 ~62 ~32 ~4 ~62 double_stone_slab 0  
fill ~31 ~4 ~63 ~37 ~4 ~63 double_stone_slab 0 
setblock ~31 ~4 ~64 stone_slab 8  
fill ~32 ~4 ~0 ~36 ~4 ~0 double_stone_slab 0  
fill ~32 ~4 ~32 ~32 ~4 ~33 wool 8  
fill ~32 ~4 ~49 ~32 ~4 ~54 stonebrick 0  
fill ~32 ~4 ~64 ~36 ~4 ~64 double_stone_slab 0 
setblock ~33 ~4 ~2 wool 15  
fill ~33 ~4 ~31 ~35 ~4 ~31 wool 8  
fill ~33 ~4 ~34 ~35 ~4 ~34 wool 8  
fill ~33 ~4 ~43 ~33 ~4 ~48 stonebrick 0  
fill ~33 ~4 ~49 ~37 ~4 ~49 double_stone_slab 0  
fill ~33 ~4 ~50 ~37 ~4 ~50 double_stone_slab 0  
fill ~33 ~4 ~51 ~36 ~4 ~51 double_stone_slab 0  
fill ~33 ~4 ~52 ~36 ~4 ~52 double_stone_slab 0  
fill ~33 ~4 ~53 ~36 ~4 ~53 double_stone_slab 0  
fill ~33 ~4 ~54 ~33 ~4 ~55 stonebrick 0  
fill ~33 ~4 ~56 ~35 ~4 ~56 concrete 7  
fill ~33 ~4 ~57 ~35 ~4 ~57 concrete 7  
fill ~33 ~4 ~58 ~35 ~4 ~58 concrete 7  
fill ~33 ~4 ~59 ~35 ~4 ~59 concrete 7  
fill ~33 ~4 ~60 ~35 ~4 ~60 concrete 7  
fill ~33 ~4 ~61 ~35 ~4 ~61 concrete 7  
fill ~33 ~4 ~62 ~35 ~4 ~62 concrete 7  
fill ~34 ~4 ~2 ~37 ~4 ~2 double_stone_slab 0  
fill ~34 ~4 ~32 ~34 ~16 ~32 ladder 3  
fill ~34 ~4 ~43 ~37 ~4 ~43 double_stone_slab 0  
fill ~34 ~4 ~44 ~37 ~4 ~44 double_stone_slab 0  
fill ~34 ~4 ~45 ~37 ~4 ~45 double_stone_slab 0  
fill ~34 ~4 ~46 ~37 ~4 ~46 double_stone_slab 0  
fill ~34 ~4 ~47 ~37 ~4 ~47 double_stone_slab 0  
fill ~34 ~4 ~48 ~37 ~4 ~48 double_stone_slab 0  
fill ~34 ~4 ~54 ~36 ~4 ~54 double_stone_slab 0  
fill ~34 ~4 ~55 ~36 ~4 ~55 double_stone_slab 0  
fill ~36 ~4 ~30 ~41 ~4 ~30 double_stone_slab 0  
fill ~36 ~4 ~34 ~41 ~4 ~34 double_stone_slab 0 
setblock ~36 ~4 ~56 double_stone_slab 0 
setblock ~36 ~4 ~57 stonebrick 0  
fill ~36 ~4 ~58 ~37 ~4 ~58 double_stone_slab 0  
fill ~36 ~4 ~59 ~37 ~4 ~59 double_stone_slab 0  
fill ~36 ~4 ~60 ~37 ~4 ~60 double_stone_slab 0  
fill ~36 ~4 ~61 ~37 ~4 ~61 double_stone_slab 0  
fill ~36 ~4 ~62 ~37 ~4 ~62 double_stone_slab 0 
setblock ~37 ~4 ~0 stone_slab 8  
fill ~37 ~4 ~51 ~37 ~4 ~56 stonebrick 0  
fill ~37 ~4 ~57 ~37 ~5 ~57 double_stone_slab 0 
setblock ~37 ~4 ~64 stone_slab 8  
fill ~38 ~4 ~16 ~51 ~4 ~16 stone_slab 8  
fill ~38 ~4 ~17 ~51 ~4 ~17 stone_slab 8  
fill ~38 ~4 ~18 ~51 ~4 ~18 stone_slab 8  
fill ~38 ~4 ~19 ~40 ~4 ~19 stone_slab 8  
fill ~38 ~4 ~20 ~40 ~4 ~20 stone_slab 8  
fill ~38 ~4 ~21 ~40 ~4 ~21 stone_slab 8  
fill ~38 ~4 ~22 ~40 ~4 ~22 stone_slab 8  
fill ~38 ~4 ~23 ~39 ~4 ~23 double_stone_slab 0  
fill ~38 ~4 ~41 ~39 ~4 ~41 double_stone_slab 0  
fill ~38 ~4 ~42 ~40 ~4 ~42 stone_slab 8  
fill ~38 ~4 ~43 ~40 ~4 ~43 stone_slab 8  
fill ~38 ~4 ~44 ~40 ~4 ~44 stone_slab 8  
fill ~38 ~4 ~45 ~40 ~4 ~45 stone_slab 8  
fill ~38 ~4 ~46 ~51 ~4 ~46 stone_slab 8  
fill ~38 ~4 ~47 ~51 ~4 ~47 stone_slab 8  
fill ~38 ~4 ~48 ~51 ~4 ~48 stone_slab 8 
setblock ~39 ~4 ~31 lever 3 
setblock ~39 ~4 ~33 lever 12  
fill ~40 ~4 ~23 ~51 ~4 ~23 stone_slab 8  
fill ~40 ~4 ~24 ~40 ~8 ~24 double_stone_slab 0 
setblock ~40 ~4 ~32 lever 2  
fill ~40 ~4 ~40 ~40 ~9 ~40 double_stone_slab 0  
fill ~40 ~4 ~41 ~51 ~4 ~41 stone_slab 8  
fill ~41 ~4 ~19 ~46 ~4 ~19 stone_slab 13  
fill ~41 ~4 ~20 ~46 ~4 ~20 stone_slab 13  
fill ~41 ~4 ~21 ~46 ~4 ~21 stone_slab 13  
fill ~41 ~4 ~22 ~46 ~4 ~22 stone_slab 13  
fill ~41 ~4 ~24 ~51 ~4 ~24 stone_slab 8  
fill ~41 ~4 ~25 ~41 ~8 ~25 double_stone_slab 0  
fill ~41 ~4 ~31 ~41 ~5 ~31 double_stone_slab 0  
fill ~41 ~4 ~32 ~41 ~5 ~32 double_stone_slab 0  
fill ~41 ~4 ~33 ~41 ~5 ~33 double_stone_slab 0  
fill ~41 ~4 ~39 ~41 ~9 ~39 double_stone_slab 0  
fill ~41 ~4 ~40 ~51 ~4 ~40 stone_slab 8  
fill ~41 ~4 ~42 ~46 ~4 ~42 stone_slab 13  
fill ~41 ~4 ~43 ~46 ~4 ~43 stone_slab 13  
fill ~41 ~4 ~44 ~46 ~4 ~44 stone_slab 13  
fill ~41 ~4 ~45 ~46 ~4 ~45 stone_slab 13  
fill ~42 ~4 ~25 ~51 ~4 ~25 stone_slab 8  
fill ~42 ~4 ~26 ~42 ~8 ~26 double_stone_slab 0  
fill ~42 ~4 ~38 ~42 ~9 ~38 double_stone_slab 0  
fill ~42 ~4 ~39 ~51 ~4 ~39 stone_slab 8  
fill ~43 ~4 ~26 ~51 ~4 ~26 stone_slab 8  
fill ~43 ~4 ~27 ~43 ~8 ~27 double_stone_slab 0  
fill ~43 ~4 ~28 ~48 ~4 ~28 double_stone_slab 0  
fill ~43 ~4 ~36 ~48 ~4 ~36 double_stone_slab 0  
fill ~43 ~4 ~37 ~43 ~9 ~37 double_stone_slab 0  
fill ~43 ~4 ~38 ~51 ~4 ~38 stone_slab 8  
fill ~44 ~4 ~27 ~51 ~4 ~27 stone_slab 8  
fill ~44 ~4 ~29 ~44 ~8 ~29 double_stone_slab 0  
fill ~44 ~4 ~30 ~44 ~8 ~30 double_stone_slab 0  
fill ~44 ~4 ~31 ~44 ~8 ~31 double_stone_slab 0  
fill ~44 ~4 ~32 ~44 ~8 ~32 double_stone_slab 0  
fill ~44 ~4 ~33 ~44 ~8 ~33 double_stone_slab 0  
fill ~44 ~4 ~34 ~44 ~9 ~34 double_stone_slab 0  
fill ~44 ~4 ~35 ~44 ~9 ~35 double_stone_slab 0  
fill ~44 ~4 ~37 ~51 ~4 ~37 stone_slab 8  
fill ~47 ~4 ~19 ~51 ~4 ~19 stone_slab 8  
fill ~47 ~4 ~20 ~51 ~4 ~20 stone_slab 8  
fill ~47 ~4 ~21 ~51 ~4 ~21 stone_slab 8  
fill ~47 ~4 ~22 ~51 ~4 ~22 stone_slab 8  
fill ~47 ~4 ~42 ~51 ~4 ~42 stone_slab 8  
fill ~47 ~4 ~43 ~51 ~4 ~43 stone_slab 8  
fill ~47 ~4 ~44 ~51 ~4 ~44 stone_slab 8  
fill ~47 ~4 ~45 ~51 ~4 ~45 stone_slab 8  
fill ~48 ~4 ~29 ~52 ~4 ~29 stone_slab 0  
fill ~48 ~4 ~30 ~48 ~4 ~35 stone_slab 0  
fill ~49 ~4 ~28 ~52 ~4 ~28 stone_slab 8  
fill ~49 ~4 ~30 ~53 ~4 ~30 stone_slab 5  
fill ~49 ~4 ~31 ~52 ~4 ~31 stone_slab 5  
fill ~49 ~4 ~32 ~50 ~4 ~32 stone_slab 0  
fill ~49 ~4 ~33 ~50 ~4 ~33 stone_slab 0  
fill ~49 ~4 ~34 ~52 ~4 ~34 stone_slab 0  
fill ~49 ~4 ~35 ~52 ~4 ~35 stone_slab 0  
fill ~49 ~4 ~36 ~52 ~4 ~36 stone_slab 8  
fill ~51 ~4 ~32 ~52 ~4 ~32 stone_slab 5  
fill ~51 ~4 ~33 ~52 ~4 ~33 stone_slab 5 
setblock ~53 ~4 ~29 double_stone_slab 0  
fill ~53 ~4 ~31 ~53 ~4 ~35 double_stone_slab 0  
fill ~54 ~4 ~29 ~58 ~4 ~29 stone_slab 8 
setblock ~54 ~4 ~30 stone_slab 13  
fill ~54 ~4 ~31 ~58 ~4 ~31 stone_slab 8  
fill ~54 ~4 ~32 ~58 ~4 ~32 stone_slab 8  
fill ~54 ~4 ~33 ~55 ~4 ~33 stone_slab 8  
fill ~54 ~4 ~34 ~55 ~4 ~34 stone_slab 8  
fill ~54 ~4 ~35 ~55 ~4 ~35 stone_slab 8 
setblock ~55 ~4 ~30 stone_brick_stairs 4 
setblock ~55 ~4 ~36 stone_button 0  
fill ~56 ~4 ~30 ~58 ~4 ~30 stone_brick_stairs 6  
fill ~56 ~4 ~33 ~58 ~4 ~33 stone_slab 13  
fill ~56 ~4 ~34 ~58 ~4 ~34 stone_brick_stairs 6  
fill ~56 ~4 ~35 ~58 ~4 ~35 stone_brick_stairs 7 
setblock ~57 ~4 ~36 stone_button 0 
setblock ~60 ~4 ~33 stone_button 0 
setblock ~62 ~4 ~30 stone_button 0  
fill ~62 ~4 ~31 ~62 ~4 ~33 lever 0 
setblock ~63 ~4 ~29 stone_button 0  
fill ~63 ~4 ~31 ~65 ~4 ~31 stone_slab 13  
fill ~63 ~4 ~32 ~65 ~4 ~32 stone_slab 13  
fill ~63 ~4 ~33 ~65 ~4 ~33 stone_slab 13  
fill ~66 ~4 ~31 ~75 ~4 ~31 double_stone_slab 5  
fill ~66 ~4 ~32 ~74 ~4 ~32 double_stone_slab 5  
fill ~66 ~4 ~33 ~75 ~4 ~33 double_stone_slab 5 
setblock ~75 ~4 ~32 double_stone_slab 0  
fill ~16 ~5 ~15 ~29 ~5 ~15 stone_brick_stairs 6  
fill ~16 ~5 ~16 ~16 ~5 ~49 stone_brick_stairs 4  
fill ~17 ~5 ~49 ~29 ~5 ~49 stone_brick_stairs 7  
fill ~29 ~5 ~23 ~30 ~5 ~23 double_stone_slab 0  
fill ~29 ~5 ~41 ~30 ~5 ~41 double_stone_slab 0  
fill ~30 ~5 ~0 ~30 ~5 ~14 stone_slab 8  
fill ~30 ~5 ~15 ~31 ~5 ~15 double_stone_slab 0  
fill ~30 ~5 ~16 ~31 ~5 ~16 double_stone_slab 0  
fill ~30 ~5 ~17 ~31 ~5 ~17 double_stone_slab 0  
fill ~30 ~5 ~18 ~31 ~5 ~18 double_stone_slab 0  
fill ~30 ~5 ~19 ~31 ~5 ~19 double_stone_slab 0  
fill ~30 ~5 ~20 ~31 ~5 ~20 double_stone_slab 0  
fill ~30 ~5 ~21 ~31 ~5 ~21 double_stone_slab 0  
fill ~30 ~5 ~22 ~38 ~5 ~22 double_stone_slab 0  
fill ~30 ~5 ~42 ~38 ~5 ~42 double_stone_slab 0  
fill ~30 ~5 ~43 ~31 ~5 ~43 double_stone_slab 0  
fill ~30 ~5 ~44 ~31 ~5 ~44 double_stone_slab 0  
fill ~30 ~5 ~45 ~31 ~5 ~45 double_stone_slab 0  
fill ~30 ~5 ~46 ~31 ~5 ~46 double_stone_slab 0  
fill ~30 ~5 ~47 ~31 ~5 ~47 double_stone_slab 0  
fill ~30 ~5 ~48 ~31 ~5 ~48 double_stone_slab 0  
fill ~30 ~5 ~49 ~30 ~6 ~49 double_stone_slab 0  
fill ~30 ~5 ~50 ~30 ~5 ~64 stone_slab 8  
fill ~31 ~5 ~0 ~37 ~5 ~0 double_stone_slab 0  
fill ~31 ~5 ~1 ~31 ~4 ~1 double_stone_slab 0  
fill ~31 ~5 ~2 ~31 ~4 ~2 double_stone_slab 0  
fill ~31 ~5 ~3 ~31 ~4 ~3 double_stone_slab 0  
fill ~31 ~5 ~4 ~31 ~4 ~4 double_stone_slab 0  
fill ~31 ~5 ~5 ~31 ~4 ~5 double_stone_slab 0  
fill ~31 ~5 ~6 ~31 ~4 ~6 double_stone_slab 0  
fill ~31 ~5 ~7 ~31 ~4 ~7 double_stone_slab 0  
fill ~31 ~5 ~8 ~31 ~4 ~8 double_stone_slab 0  
fill ~31 ~5 ~9 ~31 ~4 ~9 double_stone_slab 0  
fill ~31 ~5 ~10 ~31 ~4 ~10 double_stone_slab 0  
fill ~31 ~5 ~11 ~31 ~4 ~11 double_stone_slab 0  
fill ~31 ~5 ~12 ~31 ~4 ~12 double_stone_slab 0  
fill ~31 ~5 ~13 ~31 ~4 ~13 double_stone_slab 0  
fill ~31 ~5 ~14 ~31 ~4 ~14 double_stone_slab 0  
fill ~31 ~5 ~55 ~31 ~4 ~55 double_stone_slab 0  
fill ~31 ~5 ~56 ~31 ~4 ~56 double_stone_slab 0  
fill ~31 ~5 ~57 ~31 ~4 ~57 double_stone_slab 0  
fill ~31 ~5 ~58 ~31 ~4 ~58 double_stone_slab 0  
fill ~31 ~5 ~59 ~31 ~4 ~59 double_stone_slab 0  
fill ~31 ~5 ~60 ~31 ~4 ~60 double_stone_slab 0  
fill ~31 ~5 ~61 ~31 ~4 ~61 double_stone_slab 0  
fill ~31 ~5 ~62 ~31 ~4 ~62 double_stone_slab 0  
fill ~31 ~5 ~63 ~31 ~4 ~63 double_stone_slab 0  
fill ~31 ~5 ~64 ~37 ~5 ~64 double_stone_slab 0 
setblock ~32 ~5 ~32 sea_lantern 0  
fill ~32 ~5 ~33 ~32 ~9 ~33 wool 8  
fill ~32 ~5 ~50 ~36 ~5 ~50 concrete 7  
fill ~32 ~5 ~51 ~36 ~5 ~51 concrete 7  
fill ~32 ~5 ~52 ~36 ~5 ~52 concrete 7  
fill ~32 ~5 ~53 ~36 ~5 ~53 concrete 7  
fill ~32 ~5 ~54 ~36 ~5 ~54 concrete 7  
fill ~32 ~5 ~55 ~36 ~5 ~55 concrete 7  
fill ~32 ~5 ~56 ~36 ~5 ~56 concrete 7  
fill ~32 ~5 ~57 ~36 ~5 ~57 concrete 7  
fill ~32 ~5 ~58 ~36 ~5 ~58 concrete 7  
fill ~32 ~5 ~59 ~36 ~5 ~59 concrete 7  
fill ~32 ~5 ~60 ~36 ~5 ~60 concrete 7  
fill ~32 ~5 ~61 ~36 ~5 ~61 concrete 7  
fill ~32 ~5 ~62 ~36 ~5 ~62 concrete 7  
fill ~33 ~5 ~-2 ~35 ~5 ~-2 double_stone_slab 0  
fill ~33 ~5 ~-1 ~35 ~5 ~-1 double_stone_slab 0  
fill ~33 ~5 ~31 ~35 ~5 ~31 wool 8  
fill ~33 ~5 ~34 ~35 ~5 ~34 wool 8  
fill ~33 ~5 ~65 ~35 ~5 ~65 double_stone_slab 0  
fill ~33 ~5 ~66 ~35 ~5 ~66 double_stone_slab 0  
fill ~36 ~5 ~30 ~41 ~5 ~30 double_stone_slab 0  
fill ~36 ~5 ~34 ~41 ~5 ~34 double_stone_slab 0  
fill ~37 ~5 ~1 ~37 ~5 ~22 double_stone_slab 0  
fill ~37 ~5 ~43 ~38 ~5 ~43 double_stone_slab 0  
fill ~37 ~5 ~44 ~38 ~5 ~44 double_stone_slab 0  
fill ~37 ~5 ~45 ~38 ~5 ~45 double_stone_slab 0  
fill ~37 ~5 ~46 ~38 ~5 ~46 double_stone_slab 0  
fill ~37 ~5 ~47 ~38 ~5 ~47 double_stone_slab 0  
fill ~37 ~5 ~48 ~38 ~5 ~48 double_stone_slab 0  
fill ~37 ~5 ~49 ~38 ~5 ~49 double_stone_slab 0  
fill ~37 ~5 ~50 ~37 ~5 ~54 double_stone_slab 0  
fill ~37 ~5 ~55 ~37 ~5 ~56 double_stone_slab 5  
fill ~37 ~5 ~58 ~37 ~5 ~64 double_stone_slab 0  
fill ~38 ~5 ~0 ~38 ~5 ~14 stone_slab 8  
fill ~38 ~5 ~15 ~38 ~6 ~15 double_stone_slab 0  
fill ~38 ~5 ~16 ~38 ~6 ~16 double_stone_slab 0  
fill ~38 ~5 ~17 ~38 ~6 ~17 double_stone_slab 0  
fill ~38 ~5 ~18 ~38 ~6 ~18 double_stone_slab 0  
fill ~38 ~5 ~19 ~38 ~6 ~19 double_stone_slab 0  
fill ~38 ~5 ~20 ~38 ~6 ~20 double_stone_slab 0  
fill ~38 ~5 ~21 ~38 ~6 ~21 double_stone_slab 0  
fill ~38 ~5 ~23 ~39 ~5 ~23 double_stone_slab 0  
fill ~38 ~5 ~41 ~39 ~5 ~41 double_stone_slab 0  
fill ~38 ~5 ~50 ~38 ~5 ~54 stone_slab 8  
fill ~38 ~5 ~55 ~38 ~5 ~56 stone_slab 13  
fill ~38 ~5 ~57 ~38 ~5 ~64 stone_slab 8  
fill ~39 ~5 ~15 ~51 ~5 ~15 stone_brick_stairs 6  
fill ~39 ~5 ~49 ~52 ~5 ~49 stone_brick_stairs 7  
fill ~43 ~5 ~28 ~43 ~8 ~28 double_stone_slab 0  
fill ~43 ~5 ~36 ~43 ~9 ~36 double_stone_slab 0  
fill ~47 ~5 ~27 ~47 ~7 ~27 glowstone 0  
fill ~49 ~5 ~28 ~52 ~5 ~28 stone_slab 0  
fill ~49 ~5 ~36 ~52 ~5 ~36 stone_slab 0  
fill ~52 ~5 ~15 ~52 ~5 ~27 stone_brick_stairs 5  
fill ~52 ~5 ~37 ~52 ~5 ~48 stone_brick_stairs 5  
fill ~53 ~5 ~28 ~57 ~5 ~28 double_stone_slab 0  
fill ~53 ~5 ~36 ~57 ~5 ~36 double_stone_slab 0  
fill ~58 ~5 ~28 ~62 ~5 ~28 stone_slab 8  
fill ~58 ~5 ~29 ~60 ~5 ~29 stone_slab 0  
fill ~58 ~5 ~30 ~59 ~5 ~30 stone_slab 0  
fill ~58 ~5 ~31 ~59 ~5 ~31 stone_slab 0  
fill ~58 ~5 ~32 ~59 ~5 ~32 stone_slab 0  
fill ~58 ~5 ~33 ~58 ~5 ~35 stone_slab 0  
fill ~58 ~5 ~36 ~62 ~5 ~36 stone_slab 8  
fill ~59 ~5 ~33 ~61 ~5 ~33 stone_slab 5  
fill ~59 ~5 ~34 ~62 ~5 ~34 stone_slab 0  
fill ~59 ~5 ~35 ~59 ~5 ~34 stone_slab 0  
fill ~60 ~5 ~30 ~63 ~5 ~30 stone_slab 5  
fill ~60 ~5 ~31 ~60 ~5 ~33 stone_slab 5 
setblock ~60 ~5 ~35 stone_slab 5  
fill ~61 ~5 ~29 ~61 ~8 ~29 double_stone_slab 0  
fill ~61 ~5 ~31 ~62 ~5 ~31 stone_slab 0 
setblock ~61 ~5 ~32 stone_slab 5  
fill ~61 ~5 ~35 ~62 ~5 ~35 stone_slab 0 
setblock ~62 ~5 ~29 stone_slab 0  
fill ~62 ~5 ~32 ~62 ~5 ~35 stone_slab 0  
fill ~63 ~5 ~29 ~63 ~6 ~29 double_stone_slab 0  
fill ~63 ~5 ~31 ~63 ~6 ~31 double_stone_slab 0  
fill ~63 ~5 ~32 ~63 ~6 ~32 double_stone_slab 0  
fill ~63 ~5 ~33 ~63 ~6 ~33 double_stone_slab 0  
fill ~63 ~5 ~34 ~63 ~6 ~34 double_stone_slab 0  
fill ~63 ~5 ~35 ~63 ~6 ~35 double_stone_slab 0  
fill ~64 ~5 ~29 ~68 ~5 ~29 stone_slab 8  
fill ~64 ~5 ~30 ~68 ~5 ~30 stone_slab 8  
fill ~64 ~5 ~31 ~75 ~5 ~31 double_stone_slab 5  
fill ~64 ~5 ~32 ~75 ~5 ~32 double_stone_slab 5  
fill ~64 ~5 ~33 ~75 ~5 ~33 double_stone_slab 5  
fill ~64 ~5 ~34 ~68 ~5 ~34 stone_slab 8  
fill ~64 ~5 ~35 ~68 ~5 ~35 stone_slab 8 
setblock ~67 ~5 ~28 stone_button 0 
setblock ~73 ~5 ~30 lever 4 
setblock ~73 ~5 ~34 lever 3  
fill ~76 ~5 ~31 ~76 ~5 ~33 stone_brick_stairs 5  
fill ~8 ~6 ~23 ~8 ~6 ~36 stone_slab 8 
setblock ~8 ~6 ~37 stone_slab 13  
fill ~8 ~6 ~38 ~11 ~6 ~38 stone_slab 8  
fill ~8 ~6 ~39 ~11 ~6 ~39 stone_slab 8  
fill ~8 ~6 ~40 ~10 ~6 ~40 stone_slab 8  
fill ~8 ~6 ~41 ~11 ~6 ~41 stone_slab 8  
fill ~9 ~6 ~20 ~12 ~6 ~20 stone_slab 8  
fill ~9 ~6 ~21 ~12 ~6 ~21 stone_slab 8  
fill ~9 ~6 ~22 ~12 ~6 ~22 stone_slab 8 
setblock ~9 ~6 ~23 stone_slab 13  
fill ~9 ~6 ~24 ~11 ~6 ~24 stone_slab 8  
fill ~9 ~6 ~25 ~11 ~6 ~25 stone_slab 8  
fill ~9 ~6 ~26 ~11 ~6 ~26 stone_slab 8  
fill ~9 ~6 ~27 ~11 ~6 ~27 stone_slab 8  
fill ~9 ~6 ~28 ~9 ~6 ~32 stone_slab 8 
setblock ~9 ~6 ~33 stone_slab 13  
fill ~9 ~6 ~34 ~11 ~6 ~34 stone_slab 8  
fill ~9 ~6 ~35 ~11 ~6 ~35 stone_slab 8  
fill ~9 ~6 ~36 ~11 ~6 ~36 stone_slab 8  
fill ~9 ~6 ~37 ~11 ~6 ~37 stone_slab 8  
fill ~9 ~6 ~42 ~12 ~6 ~42 stone_slab 8  
fill ~9 ~6 ~43 ~11 ~6 ~43 stone_slab 8  
fill ~9 ~6 ~44 ~11 ~6 ~44 stone_slab 8  
fill ~10 ~6 ~18 ~14 ~6 ~18 stone_slab 8  
fill ~10 ~6 ~19 ~13 ~6 ~19 stone_slab 8  
fill ~10 ~6 ~23 ~11 ~6 ~23 stone_slab 8  
fill ~10 ~6 ~28 ~11 ~6 ~28 stone_slab 13  
fill ~10 ~6 ~29 ~11 ~6 ~29 stone_slab 8  
fill ~10 ~6 ~30 ~11 ~6 ~30 stone_slab 8  
fill ~10 ~6 ~31 ~11 ~6 ~31 stone_slab 8  
fill ~10 ~6 ~32 ~11 ~6 ~32 stone_slab 8  
fill ~10 ~6 ~33 ~11 ~6 ~33 stone_slab 8  
fill ~10 ~6 ~45 ~13 ~6 ~45 stone_slab 8  
fill ~10 ~6 ~46 ~14 ~6 ~46 stone_slab 8  
fill ~11 ~6 ~17 ~15 ~6 ~17 stone_slab 8 
setblock ~11 ~6 ~40 stone_slab 13  
fill ~11 ~6 ~47 ~15 ~6 ~47 stone_slab 8  
fill ~12 ~6 ~16 ~15 ~6 ~16 stone_slab 8  
fill ~12 ~6 ~23 ~14 ~6 ~23 stone_slab 0  
fill ~12 ~6 ~24 ~14 ~6 ~24 stone_slab 0  
fill ~12 ~6 ~25 ~15 ~6 ~25 stone_slab 0  
fill ~12 ~6 ~26 ~15 ~6 ~26 stone_slab 0  
fill ~12 ~6 ~27 ~15 ~6 ~27 stone_slab 0  
fill ~12 ~6 ~28 ~12 ~6 ~39 stone_slab 0  
fill ~12 ~6 ~40 ~15 ~6 ~40 stone_slab 5  
fill ~12 ~6 ~41 ~15 ~6 ~41 stone_slab 0  
fill ~12 ~6 ~43 ~12 ~6 ~44 stone_slab 13  
fill ~12 ~6 ~48 ~15 ~6 ~48 stone_slab 8  
fill ~13 ~6 ~15 ~14 ~6 ~15 stone_slab 8 
setblock ~13 ~6 ~20 stone_slab 13  
fill ~13 ~6 ~21 ~14 ~6 ~21 stone_slab 0  
fill ~13 ~6 ~22 ~14 ~6 ~22 stone_slab 0 
setblock ~13 ~6 ~28 stone_slab 5  
fill ~13 ~6 ~29 ~15 ~6 ~29 stone_slab 0  
fill ~13 ~6 ~30 ~15 ~6 ~30 stone_slab 0  
fill ~13 ~6 ~31 ~15 ~6 ~31 stone_slab 0  
fill ~13 ~6 ~32 ~13 ~6 ~36 stone_slab 0 
setblock ~13 ~6 ~37 stone_slab 5  
fill ~13 ~6 ~38 ~15 ~6 ~38 stone_slab 0  
fill ~13 ~6 ~39 ~15 ~6 ~39 stone_slab 0  
fill ~13 ~6 ~42 ~15 ~6 ~42 stone_slab 0 
setblock ~13 ~6 ~43 stone_slab 5 
setblock ~13 ~6 ~44 stone_slab 8  
fill ~13 ~6 ~49 ~15 ~6 ~49 stone_slab 8  
fill ~14 ~6 ~14 ~18 ~6 ~14 stone_slab 8  
fill ~14 ~6 ~19 ~15 ~6 ~19 stone_slab 0  
fill ~14 ~6 ~20 ~15 ~6 ~20 stone_slab 0  
fill ~14 ~6 ~28 ~15 ~6 ~28 stone_slab 0 
setblock ~14 ~6 ~32 stone_slab 5  
fill ~14 ~6 ~33 ~15 ~6 ~33 stone_slab 0  
fill ~14 ~6 ~34 ~15 ~6 ~34 stone_slab 0  
fill ~14 ~6 ~35 ~15 ~6 ~35 stone_slab 0  
fill ~14 ~6 ~36 ~15 ~6 ~36 stone_slab 0  
fill ~14 ~6 ~37 ~15 ~6 ~37 stone_slab 0  
fill ~14 ~6 ~43 ~15 ~6 ~43 stone_slab 0  
fill ~14 ~6 ~44 ~15 ~6 ~44 stone_slab 0  
fill ~14 ~6 ~45 ~15 ~6 ~45 stone_slab 0 
setblock ~14 ~6 ~50 stone_slab 13  
fill ~15 ~6 ~13 ~19 ~6 ~13 stone_slab 8 
setblock ~15 ~6 ~15 stone_slab 13 
setblock ~15 ~6 ~18 stone_slab 0  
fill ~15 ~6 ~21 ~15 ~6 ~24 stone_slab 5 
setblock ~15 ~6 ~32 stone_slab 0 
setblock ~15 ~6 ~46 stone_slab 0  
fill ~15 ~6 ~50 ~18 ~6 ~50 stone_slab 8  
fill ~15 ~6 ~51 ~19 ~6 ~51 stone_slab 8  
fill ~16 ~6 ~12 ~21 ~6 ~12 stone_slab 8  
fill ~16 ~6 ~15 ~18 ~6 ~15 stone_slab 5  
fill ~16 ~6 ~16 ~16 ~6 ~17 stone_slab 5  
fill ~16 ~6 ~18 ~16 ~6 ~25 wool 2  
fill ~16 ~6 ~26 ~16 ~6 ~31 wool 13 
setblock ~16 ~6 ~32 wool 2  
fill ~16 ~6 ~33 ~16 ~6 ~38 wool 13  
fill ~16 ~6 ~39 ~16 ~6 ~46 wool 2  
fill ~16 ~6 ~47 ~16 ~6 ~49 stone_slab 5  
fill ~16 ~6 ~52 ~17 ~6 ~52 stone_slab 8  
fill ~17 ~6 ~11 ~23 ~6 ~11 stone_slab 8  
fill ~17 ~6 ~49 ~18 ~6 ~49 stone_slab 5  
fill ~17 ~6 ~53 ~23 ~6 ~53 stone_slab 8  
fill ~18 ~6 ~10 ~19 ~6 ~10 stone_slab 13 
setblock ~18 ~6 ~52 stone_slab 13  
fill ~18 ~6 ~54 ~27 ~6 ~54 stone_slab 8  
fill ~19 ~6 ~9 ~29 ~6 ~9 stone_slab 8  
fill ~19 ~6 ~14 ~21 ~6 ~14 stone_slab 0  
fill ~19 ~6 ~15 ~26 ~6 ~15 wool 2  
fill ~19 ~6 ~49 ~26 ~6 ~49 wool 2  
fill ~19 ~6 ~50 ~25 ~6 ~50 stone_slab 0  
fill ~19 ~6 ~52 ~21 ~6 ~52 stone_slab 8  
fill ~19 ~6 ~55 ~20 ~6 ~55 stone_slab 8  
fill ~20 ~6 ~10 ~24 ~6 ~10 stone_slab 8  
fill ~20 ~6 ~13 ~24 ~6 ~13 stone_slab 0 
setblock ~20 ~6 ~51 stone_slab 0  
fill ~21 ~6 ~8 ~29 ~6 ~8 stone_slab 8 
setblock ~21 ~6 ~51 stone_slab 5  
fill ~21 ~6 ~55 ~22 ~6 ~55 stone_slab 13  
fill ~21 ~6 ~56 ~29 ~6 ~56 stone_slab 8  
fill ~22 ~6 ~12 ~25 ~6 ~12 stone_slab 0 
setblock ~22 ~6 ~14 stone_slab 5  
fill ~22 ~6 ~51 ~25 ~6 ~51 stone_slab 0  
fill ~22 ~6 ~52 ~25 ~6 ~52 stone_slab 0  
fill ~23 ~6 ~14 ~29 ~6 ~14 stone_slab 0  
fill ~23 ~6 ~55 ~29 ~6 ~55 stone_slab 8  
fill ~24 ~6 ~7 ~27 ~6 ~7 stone_slab 8  
fill ~24 ~6 ~11 ~26 ~6 ~11 stone_slab 0  
fill ~24 ~6 ~53 ~26 ~6 ~53 stone_slab 0  
fill ~24 ~6 ~57 ~29 ~6 ~57 stone_slab 8 
setblock ~25 ~6 ~10 stone_slab 13  
fill ~25 ~6 ~13 ~26 ~6 ~13 stone_slab 5  
fill ~26 ~6 ~10 ~29 ~6 ~10 stone_slab 8 
setblock ~26 ~6 ~12 stone_slab 5  
fill ~26 ~6 ~50 ~29 ~6 ~50 stained_hardened_clay 14  
fill ~26 ~6 ~51 ~29 ~6 ~51 stained_hardened_clay 14  
fill ~26 ~6 ~52 ~29 ~6 ~52 stained_hardened_clay 14  
fill ~27 ~6 ~11 ~28 ~6 ~11 double_stone_slab 0  
fill ~27 ~6 ~12 ~29 ~6 ~12 stone_slab 0  
fill ~27 ~6 ~13 ~28 ~6 ~13 stone_slab 0  
fill ~27 ~6 ~53 ~30 ~6 ~53 double_stone_slab 0 
setblock ~28 ~6 ~7 stone_slab 13 
setblock ~28 ~6 ~54 stone_slab 13 
setblock ~29 ~6 ~7 stone_slab 8 
setblock ~29 ~6 ~11 stone_slab 0 
setblock ~29 ~6 ~13 stone_slab 5  
fill ~29 ~6 ~23 ~30 ~6 ~23 double_stone_slab 0  
fill ~29 ~6 ~41 ~30 ~6 ~41 double_stone_slab 0 
setblock ~29 ~6 ~49 stained_hardened_clay 14 
setblock ~29 ~6 ~54 stone_slab 8  
fill ~30 ~6 ~0 ~32 ~6 ~0 double_stone_slab 0  
fill ~30 ~6 ~1 ~30 ~6 ~23 double_stone_slab 0  
fill ~30 ~6 ~42 ~38 ~6 ~42 double_stone_slab 0  
fill ~30 ~6 ~43 ~30 ~5 ~43 double_stone_slab 0  
fill ~30 ~6 ~44 ~30 ~5 ~44 double_stone_slab 0  
fill ~30 ~6 ~45 ~30 ~5 ~45 double_stone_slab 0  
fill ~30 ~6 ~46 ~30 ~5 ~46 double_stone_slab 0  
fill ~30 ~6 ~47 ~30 ~5 ~47 double_stone_slab 0  
fill ~30 ~6 ~48 ~30 ~5 ~48 double_stone_slab 0  
fill ~30 ~6 ~50 ~30 ~6 ~64 double_stone_slab 0  
fill ~31 ~6 ~-2 ~37 ~6 ~-2 double_stone_slab 0  
fill ~31 ~6 ~-1 ~37 ~6 ~-1 double_stone_slab 0  
fill ~31 ~6 ~22 ~38 ~6 ~22 double_stone_slab 0  
fill ~31 ~6 ~59 ~37 ~6 ~59 concrete 7  
fill ~31 ~6 ~64 ~32 ~6 ~64 double_stone_slab 0  
fill ~31 ~6 ~65 ~37 ~6 ~65 double_stone_slab 0  
fill ~31 ~6 ~66 ~37 ~6 ~66 double_stone_slab 0  
fill ~32 ~6 ~32 ~33 ~6 ~32 wool 8 
setblock ~32 ~6 ~62 sticky_piston 0  
fill ~33 ~6 ~-4 ~35 ~6 ~-4 double_stone_slab 0  
fill ~33 ~6 ~-3 ~35 ~6 ~-3 double_stone_slab 0  
fill ~33 ~6 ~31 ~36 ~6 ~31 wool 8  
fill ~33 ~6 ~33 ~36 ~6 ~33 wool 8  
fill ~33 ~6 ~34 ~35 ~6 ~34 wool 8  
fill ~33 ~6 ~67 ~35 ~6 ~67 double_stone_slab 0  
fill ~33 ~6 ~68 ~35 ~6 ~68 double_stone_slab 0  
fill ~34 ~6 ~35 ~34 ~9 ~35 wool 8  
fill ~35 ~6 ~32 ~36 ~6 ~32 wool 8  
fill ~36 ~6 ~0 ~38 ~6 ~0 double_stone_slab 0 
setblock ~36 ~6 ~62 sticky_piston 0  
fill ~36 ~6 ~64 ~38 ~6 ~64 double_stone_slab 0  
fill ~37 ~6 ~31 ~40 ~6 ~31 stone_slab 0  
fill ~37 ~6 ~32 ~40 ~6 ~32 stone_slab 0  
fill ~37 ~6 ~33 ~40 ~6 ~33 stone_slab 0  
fill ~38 ~6 ~1 ~38 ~6 ~23 double_stone_slab 0  
fill ~38 ~6 ~41 ~39 ~6 ~41 double_stone_slab 0  
fill ~38 ~6 ~43 ~38 ~6 ~54 double_stone_slab 0  
summon minecraft:item_frame ~18.5 ~11.5 ~-1.03125 
summon minecraft:item_frame ~18.5 ~12.5 ~-1.03125 
summon minecraft:item_frame ~12.96875 ~12.5 ~1.5 
summon minecraft:item_frame ~12.96875 ~13.5 ~1.5 
summon minecraft:item_frame ~12.5 ~13.5 ~1.96875 
summon minecraft:item_frame ~12.5 ~12.5 ~1.96875 
summon minecraft:item_frame ~10.96875 ~12.5 ~3.5 
summon minecraft:item_frame ~9.03125 ~10.5 ~19.5 
summon minecraft:item_frame ~9.03125 ~11.5 ~19.5 
summon minecraft:item_frame ~9.03125 ~12.5 ~19.5 
summon minecraft:item_frame ~9.03125 ~13.5 ~19.5 
summon minecraft:item_frame ~9.03125 ~14.5 ~19.5 
summon minecraft:item_frame ~9.03125 ~10.5 ~17.5 
summon minecraft:item_frame ~9.03125 ~11.5 ~17.5 
summon minecraft:item_frame ~9.03125 ~13.5 ~17.5 
summon minecraft:item_frame ~9.03125 ~12.5 ~17.5 
summon minecraft:item_frame ~9.03125 ~14.5 ~17.5 
summon minecraft:item_frame ~8.5 ~10.5 ~20.03125 
summon minecraft:item_frame ~8.5 ~11.5 ~20.03125 
summon minecraft:item_frame ~8.5 ~12.5 ~20.03125 
summon minecraft:item_frame ~8.5 ~13.5 ~20.03125 
summon minecraft:item_frame ~8.5 ~14.5 ~20.03125 
summon minecraft:item_frame ~8.03125 ~10.5 ~20.5 
summon minecraft:item_frame ~8.03125 ~11.5 ~20.5 
summon minecraft:item_frame ~8.03125 ~13.5 ~20.5 
summon minecraft:item_frame ~8.03125 ~12.5 ~20.5 
summon minecraft:item_frame ~8.03125 ~14.5 ~20.5 
summon minecraft:item_frame ~8.03125 ~10.5 ~22.5 
summon minecraft:item_frame ~8.03125 ~11.5 ~22.5 
summon minecraft:item_frame ~8.03125 ~12.5 ~22.5 
summon minecraft:item_frame ~8.03125 ~13.5 ~22.5 
summon minecraft:item_frame ~8.03125 ~14.5 ~22.5 
summon minecraft:item_frame ~7.5 ~14.5 ~23.03125 
summon minecraft:item_frame ~7.5 ~13.5 ~23.03125 
summon minecraft:item_frame ~7.5 ~12.5 ~23.03125 
summon minecraft:item_frame ~7.5 ~11.5 ~23.03125 
summon minecraft:item_frame ~7.5 ~10.5 ~23.03125 
summon minecraft:item_frame ~7.03125 ~14.5 ~23.5 
summon minecraft:item_frame ~7.03125 ~13.5 ~23.5 
summon minecraft:item_frame ~7.03125 ~12.5 ~23.5 
summon minecraft:item_frame ~7.03125 ~11.5 ~23.5 
summon minecraft:item_frame ~7.03125 ~10.5 ~23.5 
summon minecraft:item_frame ~7.03125 ~10.5 ~25.5 
summon minecraft:item_frame ~7.03125 ~11.5 ~25.5 
summon minecraft:item_frame ~7.03125 ~14.5 ~25.5 
summon minecraft:item_frame ~7.03125 ~10.5 ~39.5 
summon minecraft:item_frame ~7.03125 ~11.5 ~39.5 
summon minecraft:item_frame ~7.03125 ~12.5 ~39.5 
summon minecraft:item_frame ~7.03125 ~13.5 ~39.5 
summon minecraft:item_frame ~7.03125 ~14.5 ~39.5 
summon minecraft:item_frame ~7.03125 ~12.5 ~25.5 
summon minecraft:item_frame ~7.03125 ~13.5 ~25.5 
summon minecraft:item_frame ~9.03125 ~11.5 ~47.5 
summon minecraft:item_frame ~9.03125 ~12.5 ~47.5 
summon minecraft:item_frame ~9.03125 ~13.5 ~47.5 
summon minecraft:item_frame ~9.03125 ~14.5 ~47.5 
summon minecraft:item_frame ~9.03125 ~14.5 ~45.5 
summon minecraft:item_frame ~9.03125 ~13.5 ~45.5 
summon minecraft:item_frame ~9.03125 ~12.5 ~45.5 
summon minecraft:item_frame ~9.03125 ~11.5 ~45.5 
summon minecraft:item_frame ~9.03125 ~10.5 ~45.5 
summon minecraft:item_frame ~8.03125 ~10.5 ~44.5 
summon minecraft:item_frame ~8.03125 ~11.5 ~44.5 
summon minecraft:item_frame ~8.03125 ~12.5 ~44.5 
summon minecraft:item_frame ~8.03125 ~13.5 ~44.5 
summon minecraft:item_frame ~8.03125 ~14.5 ~44.5 
summon minecraft:item_frame ~8.03125 ~14.5 ~42.5 
summon minecraft:item_frame ~8.03125 ~13.5 ~42.5 
summon minecraft:item_frame ~8.03125 ~12.5 ~42.5 
summon minecraft:item_frame ~8.03125 ~11.5 ~42.5 
summon minecraft:item_frame ~8.03125 ~10.5 ~42.5 
summon minecraft:item_frame ~7.5 ~10.5 ~41.96875 
summon minecraft:item_frame ~7.5 ~11.5 ~41.96875 
summon minecraft:item_frame ~7.5 ~12.5 ~41.96875 
summon minecraft:item_frame ~7.5 ~13.5 ~41.96875 
summon minecraft:item_frame ~7.5 ~14.5 ~41.96875 
summon minecraft:item_frame ~8.5 ~10.5 ~44.96875 
summon minecraft:item_frame ~8.5 ~11.5 ~44.96875 
summon minecraft:item_frame ~8.5 ~12.5 ~44.96875 
summon minecraft:item_frame ~8.5 ~13.5 ~44.96875 
summon minecraft:item_frame ~8.5 ~14.5 ~44.96875 
summon minecraft:item_frame ~7.03125 ~10.5 ~41.5 
summon minecraft:item_frame ~7.03125 ~11.5 ~41.5 
summon minecraft:item_frame ~7.03125 ~12.5 ~41.5 
summon minecraft:item_frame ~7.03125 ~13.5 ~41.5 
summon minecraft:item_frame ~7.03125 ~14.5 ~41.5 
summon minecraft:item_frame ~9.03125 ~10.5 ~47.5 
summon minecraft:item_frame ~12.5 ~12.5 ~63.03125 
summon minecraft:item_frame ~12.96875 ~12.5 ~63.5 
summon minecraft:item_frame ~13.5 ~12.5 ~64.03125 
summon minecraft:item_frame ~14.5 ~12.5 ~64.03125 
summon minecraft:item_frame ~14.96875 ~12.5 ~64.5 
summon minecraft:item_frame ~18.5 ~13.5 ~66.03125 
summon minecraft:item_frame ~18.96875 ~13.5 ~66.5 
summon minecraft:item_frame ~25.5 ~10.5 ~-4.03125 
summon minecraft:item_frame ~25.5 ~9.5 ~-4.03125 
summon minecraft:item_frame ~25.5 ~11.5 ~-4.03125 
summon minecraft:item_frame ~25.5 ~12.5 ~-4.03125 
summon minecraft:item_frame ~33.5 ~12.5 ~-3.03125 
summon minecraft:item_frame ~32.5 ~12.5 ~-3.03125 
summon minecraft:item_frame ~35.5 ~8.5 ~-3.03125 
summon minecraft:item_frame ~22.5 ~13.5 ~68.03125 
summon minecraft:item_frame ~22.5 ~12.5 ~68.03125 
summon minecraft:item_frame ~45.5 ~11.5 ~-3.03125 
summon minecraft:item_frame ~45.03125 ~11.5 ~-3.5 
summon minecraft:item_frame ~45.5 ~12.5 ~-3.03125 
summon minecraft:item_frame ~45.03125 ~12.5 ~-3.5 
summon minecraft:item_frame ~52.5 ~11.5 ~32.96875 
summon minecraft:item_frame ~51.5 ~11.5 ~32.96875 
summon minecraft:item_frame ~42.03125 ~11.5 ~32.5 
summon minecraft:item_frame ~42.03125 ~10.5 ~32.5 
summon minecraft:item_frame ~42.03125 ~12.5 ~32.5 
summon minecraft:item_frame ~42.03125 ~13.5 ~32.5 
summon minecraft:item_frame ~42.03125 ~14.5 ~32.5 
summon minecraft:item_frame ~42.03125 ~14.5 ~30.5 
summon minecraft:item_frame ~42.03125 ~13.5 ~30.5 
summon minecraft:item_frame ~42.03125 ~12.5 ~30.5 
summon minecraft:item_frame ~42.03125 ~11.5 ~30.5 
summon minecraft:item_frame ~42.03125 ~10.5 ~30.5 
summon minecraft:item_frame ~52.5 ~13.5 ~33.96875 
summon minecraft:item_frame ~52.5 ~14.5 ~33.96875 
summon minecraft:item_frame ~42.03125 ~15.5 ~32.5 
summon minecraft:item_frame ~42.03125 ~15.5 ~30.5 
summon minecraft:item_frame ~52.5 ~15.5 ~33.96875 
summon minecraft:item_frame ~46.5 ~12.5 ~68.03125 
summon minecraft:item_frame ~46.5 ~11.5 ~68.03125 
summon minecraft:item_frame ~46.5 ~10.5 ~68.03125 
summon minecraft:item_frame ~46.5 ~9.5 ~68.03125 
summon minecraft:item_frame ~46.5 ~13.5 ~68.03125 
summon minecraft:item_frame ~63.5 ~11.5 ~6.96875 
summon minecraft:item_frame ~63.5 ~12.5 ~6.96875 
summon minecraft:item_frame ~62.5 ~11.5 ~5.96875 
summon minecraft:item_frame ~62.5 ~12.5 ~5.96875 
summon minecraft:item_frame ~59.96875 ~10.5 ~20.5 
summon minecraft:item_frame ~59.96875 ~11.5 ~20.5 
summon minecraft:item_frame ~59.96875 ~12.5 ~20.5 
summon minecraft:item_frame ~59.96875 ~13.5 ~20.5 
summon minecraft:item_frame ~59.96875 ~14.5 ~20.5 
summon minecraft:item_frame ~54.5 ~12.5 ~19.03125 
summon minecraft:item_frame ~54.5 ~11.5 ~19.03125 
summon minecraft:item_frame ~54.5 ~10.5 ~19.03125 
summon minecraft:item_frame ~60.96875 ~13.5 ~23.5 
summon minecraft:item_frame ~60.96875 ~13.5 ~21.5 
summon minecraft:item_frame ~60.96875 ~13.5 ~19.5 
summon minecraft:item_frame ~60.96875 ~14.5 ~23.5 
summon minecraft:item_frame ~60.96875 ~14.5 ~21.5 
summon minecraft:item_frame ~60.96875 ~14.5 ~19.5 
summon minecraft:item_frame ~59.96875 ~10.5 ~22.5 
summon minecraft:item_frame ~59.96875 ~11.5 ~22.5 
summon minecraft:item_frame ~59.96875 ~13.5 ~22.5 
summon minecraft:item_frame ~59.96875 ~14.5 ~22.5 
summon minecraft:item_frame ~53.5 ~11.5 ~32.96875 
summon minecraft:item_frame ~53.96875 ~11.5 ~32.5 
summon minecraft:item_frame ~54.5 ~11.5 ~31.96875 
summon minecraft:item_frame ~54.96875 ~11.5 ~31.5 
summon minecraft:item_frame ~55.5 ~11.5 ~30.96875 
summon minecraft:item_frame ~55.96875 ~11.5 ~30.5 
summon minecraft:item_frame ~56.5 ~11.5 ~29.96875 
summon minecraft:item_frame ~56.96875 ~11.5 ~29.5 
summon minecraft:item_frame ~56.96875 ~11.5 ~28.5 
summon minecraft:item_frame ~56.96875 ~11.5 ~27.5 
summon minecraft:item_frame ~59.96875 ~12.5 ~24.5 
summon minecraft:item_frame ~59.96875 ~13.5 ~24.5 
summon minecraft:item_frame ~59.96875 ~14.5 ~24.5 
summon minecraft:item_frame ~59.96875 ~11.5 ~24.5 
summon minecraft:item_frame ~59.96875 ~10.5 ~24.5 
summon minecraft:item_frame ~54.5 ~14.5 ~33.96875 
summon minecraft:item_frame ~54.5 ~13.5 ~33.96875 
summon minecraft:item_frame ~53.5 ~13.5 ~33.96875 
summon minecraft:item_frame ~60.96875 ~13.5 ~25.5 
summon minecraft:item_frame ~60.96875 ~14.5 ~25.5 
summon minecraft:item_frame ~55.5 ~15.5 ~33.96875 
summon minecraft:item_frame ~54.5 ~15.5 ~33.96875 
summon minecraft:item_frame ~66.5 ~12.5 ~56.03125 
summon minecraft:item_frame ~67.5 ~12.5 ~56.03125 
summon minecraft:item_frame ~63.03125 ~11.5 ~58.5 
summon minecraft:item_frame ~62.5 ~11.5 ~59.03125 
summon minecraft:item_frame ~67.5 ~13.5 ~60.03125 
summon minecraft:item_frame ~66.5 ~13.5 ~60.03125 
summon minecraft:item_frame ~65.5 ~13.5 ~60.03125 
summon minecraft:item_frame ~65.5 ~14.5 ~60.03125 
summon minecraft:item_frame ~66.5 ~14.5 ~60.03125 
summon minecraft:item_frame ~67.5 ~14.5 ~60.03125 
summon minecraft:item_frame ~67.96875 ~14.5 ~60.5 
summon minecraft:item_frame ~67.96875 ~13.5 ~60.5 
summon minecraft:item_frame ~68.5 ~14.5 ~61.03125 
summon minecraft:item_frame ~68.5 ~13.5 ~61.03125 
summon minecraft:item_frame ~65.5 ~13.5 ~68.96875 
summon minecraft:item_frame ~65.5 ~14.5 ~68.96875 
summon minecraft:item_frame ~66.5 ~13.5 ~68.96875 
summon minecraft:item_frame ~66.5 ~14.5 ~68.96875 
summon minecraft:item_frame ~67.5 ~13.5 ~68.96875 
summon minecraft:item_frame ~67.5 ~14.5 ~68.96875 
summon minecraft:item_frame ~68.5 ~13.5 ~67.96875 
summon minecraft:item_frame ~67.96875 ~14.5 ~68.5 
summon minecraft:item_frame ~67.96875 ~13.5 ~68.5 
summon minecraft:item_frame ~68.5 ~14.5 ~67.96875 
summon minecraft:item_frame ~68.5 ~12.5 ~61.03125 
summon minecraft:item_frame ~68.5 ~12.5 ~67.96875 
summon minecraft:item_frame ~65.03125 ~16.5 ~66.5 
summon minecraft:item_frame ~84.5 ~11.5 ~15.96875 
summon minecraft:item_frame ~84.5 ~10.5 ~15.96875 
summon minecraft:item_frame ~75.5 ~12.5 ~11.96875 
summon minecraft:item_frame ~81.5 ~10.5 ~25.03125 
summon minecraft:item_frame ~81.5 ~11.5 ~25.03125 
summon minecraft:item_frame ~81.5 ~12.5 ~25.03125 
summon minecraft:item_frame ~79.5 ~10.5 ~25.03125 
summon minecraft:item_frame ~79.5 ~11.5 ~25.03125 
summon minecraft:item_frame ~79.5 ~12.5 ~25.03125 
summon minecraft:item_frame ~75.5 ~10.5 ~24.03125 
summon minecraft:item_frame ~79.5 ~10.5 ~39.96875 
summon minecraft:item_frame ~71.03125 ~14.5 ~32.5 
summon minecraft:item_frame ~71.03125 ~14.5 ~30.5 
summon minecraft:item_frame ~71.03125 ~13.5 ~32.5 
summon minecraft:item_frame ~71.03125 ~14.5 ~31.5 
summon minecraft:item_frame ~76.5 ~12.5 ~52.03125 
summon minecraft:item_frame ~73.5 ~10.5 ~54.03125 
summon minecraft:item_frame ~72.5 ~10.5 ~54.03125 
summon minecraft:item_frame ~71.5 ~10.5 ~54.03125 
summon minecraft:item_frame ~74.03125 ~10.5 ~53.5 
summon minecraft:item_frame ~71.5 ~12.5 ~54.03125 
summon minecraft:item_frame ~72.5 ~12.5 ~54.03125 
summon minecraft:item_frame ~73.5 ~12.5 ~54.03125 
summon minecraft:item_frame ~74.03125 ~12.5 ~53.5 
summon minecraft:item_frame ~69.5 ~13.5 ~61.03125 
summon minecraft:item_frame ~69.5 ~14.5 ~61.03125 
summon minecraft:item_frame ~70.5 ~13.5 ~61.03125 
summon minecraft:item_frame ~70.5 ~14.5 ~61.03125 
summon minecraft:item_frame ~69.5 ~13.5 ~67.96875 
summon minecraft:item_frame ~69.5 ~14.5 ~67.96875 
summon minecraft:item_frame ~70.5 ~13.5 ~67.96875 
summon minecraft:item_frame ~70.5 ~14.5 ~67.96875 
summon minecraft:item_frame ~70.5 ~12.5 ~61.03125 
summon minecraft:item_frame ~69.5 ~12.5 ~61.03125 
summon minecraft:item_frame ~70.96875 ~12.5 ~61.5 
summon minecraft:item_frame ~70.96875 ~13.5 ~61.5 
summon minecraft:item_frame ~70.96875 ~14.5 ~61.5 
summon minecraft:item_frame ~69.5 ~12.5 ~67.96875 
summon minecraft:item_frame ~70.5 ~12.5 ~67.96875 
summon minecraft:item_frame ~70.96875 ~12.5 ~67.5 
summon minecraft:item_frame ~70.96875 ~13.5 ~67.5 
summon minecraft:item_frame ~70.96875 ~14.5 ~67.5 
summon minecraft:item_frame ~72.5 ~14.5 ~62.03125 
summon minecraft:item_frame ~71.5 ~14.5 ~62.03125 
summon minecraft:item_frame ~72.5 ~13.5 ~62.03125 
summon minecraft:item_frame ~71.5 ~14.5 ~66.96875 
summon minecraft:item_frame ~72.5 ~14.5 ~66.96875 
summon minecraft:item_frame ~72.5 ~13.5 ~66.96875 
summon minecraft:item_frame ~73.5 ~13.5 ~66.96875 
summon minecraft:item_frame ~73.5 ~12.5 ~65.96875 
summon minecraft:item_frame ~72.5 ~12.5 ~65.96875 
summon minecraft:item_frame ~73.5 ~12.5 ~63.03125 
summon minecraft:item_frame ~72.5 ~12.5 ~63.03125 
summon minecraft:item_frame ~73.96875 ~12.5 ~65.5 
summon minecraft:item_frame ~73.96875 ~12.5 ~63.5 
summon minecraft:item_frame ~85.5 ~10.5 ~15.96875 
summon minecraft:item_frame ~86.03125 ~10.5 ~16.5 
summon minecraft:item_frame ~93.5 ~12.5 ~18.96875 
summon minecraft:item_frame ~94.03125 ~12.5 ~19.5 
summon minecraft:item_frame ~94.5 ~12.5 ~19.96875 
summon minecraft:item_frame ~100.5 ~10.5 ~27.03125 
summon minecraft:item_frame ~95.5 ~10.5 ~37.96875 
summon minecraft:item_frame ~95.5 ~11.5 ~37.96875 
summon minecraft:item_frame ~89.5 ~12.5 ~37.96875 
summon minecraft:item_frame ~89.5 ~11.5 ~37.96875 
summon minecraft:item_frame ~89.5 ~10.5 ~37.96875 
summon minecraft:item_frame ~87.96875 ~12.5 ~38.5 
summon minecraft:item_frame ~96.5 ~10.5 ~44.03125 
summon minecraft:item_frame ~97.5 ~10.5 ~44.03125 
summon minecraft:item_frame ~85.5 ~10.5 ~49.03125 
summon minecraft:item_frame ~102.5 ~12.5 ~22.96875 
summon minecraft:item_frame ~101.5 ~12.5 ~22.96875 
summon minecraft:item_frame ~103.5 ~12.5 ~22.96875 
summon minecraft:item_frame ~106.5 ~11.5 ~24.96875 
summon minecraft:item_frame ~102.5 ~12.5 ~27.03125 
summon minecraft:item_frame ~105.5 ~12.5 ~37.96875 
summon minecraft:item_frame ~106.5 ~12.5 ~37.96875 
summon minecraft:item_frame ~107.5 ~12.5 ~37.96875 
summon minecraft:item_frame ~102.5 ~11.5 ~42.03125 
summon minecraft:item_frame ~102.5 ~12.5 ~42.03125 
summon minecraft:item_frame ~102.5 ~10.5 ~42.03125  
fill ~38 ~6 ~55 ~38 ~6 ~56 stonebrick 0  
fill ~38 ~6 ~57 ~38 ~6 ~64 double_stone_slab 0  
fill ~39 ~6 ~7 ~44 ~6 ~7 stone_slab 8  
fill ~39 ~6 ~8 ~47 ~6 ~8 stone_slab 8  
fill ~39 ~6 ~9 ~49 ~6 ~9 stone_slab 8  
fill ~39 ~6 ~10 ~39 ~6 ~7 stone_slab 8  
fill ~39 ~6 ~11 ~41 ~6 ~11 double_stone_slab 0  
fill ~39 ~6 ~12 ~39 ~7 ~12 double_stone_slab 0  
fill ~39 ~6 ~13 ~39 ~7 ~13 double_stone_slab 0  
fill ~39 ~6 ~14 ~39 ~7 ~14 double_stone_slab 0  
fill ~39 ~6 ~23 ~39 ~8 ~23 double_stone_slab 0  
fill ~39 ~6 ~50 ~49 ~6 ~50 stone_slab 0  
fill ~39 ~6 ~51 ~48 ~6 ~51 stone_slab 0  
fill ~39 ~6 ~52 ~46 ~6 ~52 stone_slab 0  
fill ~39 ~6 ~53 ~39 ~6 ~50 stone_slab 0  
fill ~39 ~6 ~54 ~50 ~6 ~54 stone_slab 8  
fill ~39 ~6 ~55 ~43 ~6 ~55 stone_slab 8  
fill ~39 ~6 ~56 ~47 ~6 ~56 stone_slab 8  
fill ~39 ~6 ~57 ~44 ~6 ~57 stone_slab 8  
fill ~40 ~6 ~10 ~41 ~6 ~10 stone_slab 13  
fill ~40 ~6 ~12 ~46 ~6 ~12 stone_slab 0  
fill ~40 ~6 ~13 ~42 ~6 ~13 stone_slab 0  
fill ~40 ~6 ~14 ~49 ~6 ~14 stone_slab 0  
fill ~40 ~6 ~53 ~41 ~6 ~53 double_stone_slab 0  
fill ~42 ~6 ~10 ~48 ~6 ~10 stone_slab 8  
fill ~42 ~6 ~11 ~44 ~6 ~11 stone_slab 0  
fill ~42 ~6 ~15 ~49 ~6 ~15 wool 2  
fill ~42 ~6 ~49 ~49 ~6 ~49 wool 2  
fill ~42 ~6 ~53 ~44 ~6 ~53 stone_slab 0 
setblock ~43 ~6 ~13 stone_slab 5  
fill ~44 ~6 ~13 ~48 ~6 ~13 stone_slab 0 
setblock ~44 ~6 ~55 stone_slab 13  
fill ~45 ~6 ~11 ~51 ~6 ~11 stone_slab 8  
fill ~45 ~6 ~53 ~51 ~6 ~53 stone_slab 8  
fill ~45 ~6 ~55 ~49 ~6 ~55 stone_slab 8  
fill ~47 ~6 ~12 ~52 ~6 ~12 stone_slab 8  
fill ~47 ~6 ~52 ~52 ~6 ~52 stone_slab 8  
fill ~48 ~6 ~27 ~48 ~7 ~27 glowstone 0  
fill ~48 ~6 ~28 ~49 ~6 ~28 concrete 15 
setblock ~49 ~6 ~10 stone_slab 13  
fill ~49 ~6 ~13 ~53 ~6 ~13 stone_slab 8  
fill ~49 ~6 ~51 ~50 ~6 ~51 stone_slab 8 
setblock ~50 ~6 ~10 stone_slab 8  
fill ~50 ~6 ~14 ~54 ~6 ~14 stone_slab 8  
fill ~50 ~6 ~15 ~52 ~6 ~15 stone_slab 5  
fill ~50 ~6 ~49 ~52 ~6 ~49 stone_slab 5  
fill ~50 ~6 ~50 ~54 ~6 ~50 stone_slab 8 
setblock ~51 ~6 ~51 stone_slab 13  
fill ~52 ~6 ~16 ~52 ~6 ~17 stone_slab 5  
fill ~52 ~6 ~18 ~52 ~6 ~21 wool 2 
setblock ~52 ~6 ~27 wool 13  
fill ~52 ~6 ~37 ~52 ~6 ~38 wool 13  
fill ~52 ~6 ~39 ~52 ~6 ~46 wool 2  
fill ~52 ~6 ~47 ~52 ~6 ~49 stone_slab 5  
fill ~52 ~6 ~51 ~53 ~6 ~51 stone_slab 8  
fill ~53 ~6 ~15 ~53 ~6 ~17 stone_slab 8  
fill ~53 ~6 ~18 ~53 ~6 ~27 stone_slab 0  
fill ~53 ~6 ~37 ~56 ~6 ~37 stone_slab 0  
fill ~53 ~6 ~38 ~56 ~6 ~38 stone_slab 0  
fill ~53 ~6 ~39 ~56 ~6 ~39 stone_slab 0  
fill ~53 ~6 ~40 ~56 ~6 ~40 stone_slab 0  
fill ~53 ~6 ~41 ~56 ~6 ~41 stone_slab 0  
fill ~53 ~6 ~42 ~55 ~6 ~42 stone_slab 0  
fill ~53 ~6 ~43 ~55 ~6 ~43 stone_slab 0  
fill ~53 ~6 ~44 ~54 ~6 ~44 stone_slab 0  
fill ~53 ~6 ~45 ~54 ~6 ~45 stone_slab 0  
fill ~53 ~6 ~46 ~53 ~6 ~37 stone_slab 0  
fill ~53 ~6 ~47 ~57 ~6 ~47 stone_slab 8  
fill ~53 ~6 ~48 ~56 ~6 ~48 stone_slab 8  
fill ~53 ~6 ~49 ~55 ~6 ~49 stone_slab 8  
fill ~54 ~6 ~15 ~54 ~6 ~16 stone_slab 13  
fill ~54 ~6 ~17 ~57 ~6 ~17 stone_slab 8  
fill ~54 ~6 ~18 ~58 ~6 ~18 stone_slab 8  
fill ~54 ~6 ~19 ~54 ~6 ~22 stone_slab 0 
setblock ~54 ~6 ~23 stone_slab 5  
fill ~54 ~6 ~24 ~56 ~6 ~24 stone_slab 0  
fill ~54 ~6 ~25 ~56 ~6 ~25 stone_slab 0  
fill ~54 ~6 ~26 ~55 ~6 ~26 stone_slab 0  
fill ~54 ~6 ~27 ~56 ~6 ~27 stone_slab 0  
fill ~54 ~6 ~46 ~58 ~6 ~46 stone_slab 8  
fill ~55 ~6 ~15 ~55 ~6 ~20 stone_slab 8  
fill ~55 ~6 ~21 ~55 ~6 ~27 stone_slab 0  
fill ~55 ~6 ~44 ~55 ~6 ~45 stone_slab 13 
setblock ~56 ~6 ~16 stone_slab 8  
fill ~56 ~6 ~19 ~58 ~6 ~19 stone_slab 8  
fill ~56 ~6 ~20 ~59 ~6 ~20 stone_slab 8  
fill ~56 ~6 ~21 ~59 ~6 ~21 stone_slab 8  
fill ~56 ~6 ~22 ~59 ~6 ~22 stone_slab 8 
setblock ~56 ~6 ~23 stone_slab 0 
setblock ~56 ~6 ~26 stone_slab 5  
fill ~56 ~6 ~42 ~59 ~6 ~42 stone_slab 8  
fill ~56 ~6 ~43 ~59 ~6 ~43 stone_slab 8  
fill ~56 ~6 ~44 ~59 ~6 ~44 stone_slab 8  
fill ~56 ~6 ~45 ~58 ~6 ~45 stone_slab 8  
fill ~57 ~6 ~23 ~60 ~6 ~23 stone_slab 8  
fill ~57 ~6 ~24 ~57 ~6 ~27 stone_slab 8  
fill ~57 ~6 ~28 ~60 ~6 ~28 stone_slab 0  
fill ~57 ~6 ~36 ~60 ~6 ~36 stone_slab 0  
fill ~57 ~6 ~37 ~60 ~6 ~37 stone_slab 8  
fill ~57 ~6 ~38 ~60 ~6 ~38 stone_slab 8  
fill ~57 ~6 ~39 ~60 ~6 ~39 stone_slab 8  
fill ~57 ~6 ~40 ~57 ~6 ~47 stone_slab 8 
setblock ~58 ~6 ~24 stone_slab 13  
fill ~58 ~6 ~25 ~60 ~6 ~25 stone_slab 8  
fill ~58 ~6 ~26 ~60 ~6 ~26 stone_slab 8  
fill ~58 ~6 ~27 ~60 ~6 ~27 stone_slab 8 
setblock ~58 ~6 ~40 stone_slab 13  
fill ~58 ~6 ~41 ~60 ~6 ~41 stone_slab 8  
fill ~59 ~6 ~24 ~60 ~6 ~24 stone_slab 8  
fill ~59 ~6 ~40 ~60 ~6 ~40 stone_slab 8  
fill ~61 ~6 ~28 ~68 ~6 ~28 double_stone_slab 0  
fill ~61 ~6 ~30 ~70 ~6 ~30 double_stone_slab 0  
fill ~61 ~6 ~31 ~70 ~6 ~31 double_stone_slab 0  
fill ~61 ~6 ~32 ~70 ~6 ~32 double_stone_slab 0  
fill ~61 ~6 ~33 ~70 ~6 ~33 double_stone_slab 0  
fill ~61 ~6 ~34 ~70 ~6 ~34 double_stone_slab 0  
fill ~61 ~6 ~35 ~70 ~6 ~35 double_stone_slab 0  
fill ~61 ~6 ~36 ~68 ~6 ~36 double_stone_slab 0  
fill ~61 ~6 ~37 ~61 ~6 ~28 double_stone_slab 0 
setblock ~62 ~6 ~29 double_stone_slab 0  
fill ~64 ~6 ~29 ~70 ~6 ~29 double_stone_slab 0 
setblock ~69 ~6 ~28 stone_slab 8 
setblock ~69 ~6 ~36 stone_slab 8  
fill ~70 ~6 ~28 ~70 ~10 ~28 double_stone_slab 0  
fill ~70 ~6 ~36 ~70 ~15 ~36 double_stone_slab 0  
fill ~71 ~6 ~28 ~72 ~6 ~28 stone_slab 8  
fill ~71 ~6 ~29 ~72 ~6 ~29 stone_slab 0  
fill ~71 ~6 ~30 ~72 ~6 ~30 stone_slab 0  
fill ~71 ~6 ~31 ~72 ~6 ~31 stone_slab 0  
fill ~71 ~6 ~32 ~72 ~6 ~32 stone_slab 0  
fill ~71 ~6 ~33 ~72 ~6 ~33 stone_slab 0  
fill ~71 ~6 ~34 ~72 ~6 ~34 stone_slab 0  
fill ~71 ~6 ~35 ~72 ~6 ~35 stone_slab 5 
setblock ~71 ~6 ~36 stone_slab 13 
setblock ~72 ~6 ~36 stone_slab 8 
setblock ~73 ~6 ~28 stone_button 0  
fill ~73 ~6 ~29 ~73 ~6 ~34 double_stone_slab 0 
setblock ~73 ~6 ~35 double_stone_slab 5  
fill ~74 ~6 ~29 ~78 ~6 ~29 stone_slab 8  
fill ~74 ~6 ~30 ~76 ~6 ~30 stone_slab 8  
fill ~74 ~6 ~31 ~76 ~6 ~31 double_stone_slab 5  
fill ~74 ~6 ~32 ~75 ~6 ~32 double_stone_slab 5  
fill ~74 ~6 ~33 ~76 ~6 ~33 double_stone_slab 5  
fill ~74 ~6 ~34 ~78 ~6 ~34 stone_slab 8  
fill ~74 ~6 ~35 ~75 ~6 ~35 stone_slab 13 
setblock ~76 ~6 ~32 stone_slab 0  
fill ~76 ~6 ~35 ~78 ~6 ~35 stone_slab 8  
fill ~77 ~6 ~30 ~78 ~6 ~30 stone_brick_stairs 6  
fill ~77 ~6 ~31 ~78 ~6 ~31 stone_slab 8  
fill ~77 ~6 ~32 ~78 ~6 ~32 stone_slab 8  
fill ~77 ~6 ~33 ~78 ~6 ~33 stone_slab 8 
setblock ~79 ~6 ~30 stone_brick_stairs 5 
setblock ~79 ~6 ~34 stone_slab 13 
setblock ~79 ~6 ~35 lever 15  
fill ~81 ~6 ~31 ~81 ~6 ~32 stone_button 0 
setblock ~83 ~6 ~34 stone_button 0  
fill ~0 ~7 ~22 ~3 ~7 ~22 stone_slab 8  
fill ~0 ~7 ~23 ~3 ~7 ~23 stone_slab 8  
fill ~0 ~7 ~24 ~0 ~7 ~34 stone_slab 8 
setblock ~0 ~7 ~35 stone_slab 13  
fill ~0 ~7 ~36 ~3 ~7 ~36 stone_slab 8  
fill ~0 ~7 ~37 ~3 ~7 ~37 stone_slab 8  
fill ~0 ~7 ~38 ~3 ~7 ~38 stone_slab 8  
fill ~0 ~7 ~39 ~3 ~7 ~39 stone_slab 8  
fill ~0 ~7 ~40 ~3 ~7 ~40 stone_slab 8  
fill ~0 ~7 ~41 ~3 ~7 ~41 stone_slab 8  
fill ~0 ~7 ~42 ~0 ~7 ~36 stone_slab 8  
fill ~1 ~7 ~19 ~3 ~7 ~19 stone_slab 8  
fill ~1 ~7 ~20 ~3 ~7 ~20 stone_slab 8  
fill ~1 ~7 ~21 ~4 ~7 ~21 stone_slab 8 
setblock ~1 ~7 ~24 stone_slab 13  
fill ~1 ~7 ~25 ~3 ~7 ~25 stone_slab 8  
fill ~1 ~7 ~26 ~3 ~7 ~26 stone_slab 8  
fill ~1 ~7 ~27 ~3 ~7 ~27 stone_slab 8  
fill ~1 ~7 ~28 ~3 ~7 ~28 stone_slab 8  
fill ~1 ~7 ~29 ~2 ~7 ~29 stone_slab 8  
fill ~1 ~7 ~30 ~3 ~7 ~30 stone_slab 8  
fill ~1 ~7 ~31 ~3 ~7 ~31 stone_slab 8  
fill ~1 ~7 ~32 ~3 ~7 ~32 stone_slab 8  
fill ~1 ~7 ~33 ~3 ~7 ~33 stone_slab 8  
fill ~1 ~7 ~34 ~3 ~7 ~34 stone_slab 8  
fill ~1 ~7 ~35 ~3 ~7 ~35 stone_slab 8  
fill ~1 ~7 ~42 ~1 ~7 ~43 stone_slab 13  
fill ~1 ~7 ~44 ~4 ~7 ~44 stone_slab 8  
fill ~1 ~7 ~45 ~4 ~7 ~45 stone_slab 8  
fill ~2 ~7 ~17 ~5 ~7 ~17 stone_slab 8  
fill ~2 ~7 ~18 ~5 ~7 ~18 stone_slab 8  
fill ~2 ~7 ~24 ~3 ~7 ~24 stone_slab 8  
fill ~2 ~7 ~42 ~3 ~7 ~42 stone_slab 8  
fill ~2 ~7 ~43 ~4 ~7 ~43 stone_slab 8  
fill ~2 ~7 ~46 ~5 ~7 ~46 stone_slab 8  
fill ~2 ~7 ~47 ~5 ~7 ~47 stone_slab 8  
fill ~3 ~7 ~15 ~6 ~7 ~15 stone_slab 8  
fill ~3 ~7 ~16 ~6 ~7 ~16 stone_slab 8 
setblock ~3 ~7 ~29 stone_slab 13  
fill ~3 ~7 ~48 ~6 ~7 ~48 stone_slab 8  
fill ~3 ~7 ~49 ~5 ~7 ~49 stone_slab 8  
fill ~4 ~7 ~14 ~7 ~7 ~14 stone_slab 8  
fill ~4 ~7 ~19 ~4 ~7 ~20 stone_slab 13  
fill ~4 ~7 ~22 ~8 ~7 ~22 stone_slab 0  
fill ~4 ~7 ~23 ~7 ~7 ~23 stone_slab 0  
fill ~4 ~7 ~24 ~6 ~7 ~24 stone_slab 0  
fill ~4 ~7 ~25 ~6 ~7 ~25 stone_slab 0  
fill ~4 ~7 ~26 ~7 ~7 ~26 stone_slab 0  
fill ~4 ~7 ~27 ~6 ~7 ~27 stone_slab 0 
setblock ~4 ~7 ~28 stone_slab 5  
fill ~4 ~7 ~29 ~6 ~7 ~29 stone_slab 0  
fill ~4 ~7 ~30 ~7 ~7 ~30 stone_slab 0  
fill ~4 ~7 ~31 ~6 ~7 ~31 stone_slab 0  
fill ~4 ~7 ~32 ~5 ~7 ~32 stone_slab 0  
fill ~4 ~7 ~33 ~6 ~7 ~33 stone_slab 0  
fill ~4 ~7 ~34 ~7 ~7 ~34 stone_slab 0  
fill ~4 ~7 ~35 ~6 ~7 ~35 stone_slab 0  
fill ~4 ~7 ~36 ~5 ~7 ~36 stone_slab 0  
fill ~4 ~7 ~37 ~5 ~7 ~37 stone_slab 0  
fill ~4 ~7 ~38 ~4 ~7 ~42 stone_slab 0  
fill ~4 ~7 ~50 ~7 ~7 ~50 stone_slab 8 
setblock ~5 ~7 ~13 stone_slab 13  
fill ~5 ~7 ~19 ~9 ~7 ~19 stone_slab 0  
fill ~5 ~7 ~20 ~8 ~7 ~20 stone_slab 0  
fill ~5 ~7 ~21 ~8 ~7 ~21 stone_slab 0 
setblock ~5 ~7 ~28 stone_slab 0  
fill ~5 ~7 ~38 ~6 ~7 ~38 stone_slab 5  
fill ~5 ~7 ~39 ~6 ~7 ~39 stone_slab 5  
fill ~5 ~7 ~40 ~7 ~7 ~40 stone_slab 0  
fill ~5 ~7 ~41 ~7 ~7 ~41 stone_slab 0  
fill ~5 ~7 ~42 ~8 ~7 ~42 stone_slab 0  
fill ~5 ~7 ~43 ~8 ~7 ~43 stone_slab 0  
fill ~5 ~7 ~44 ~8 ~7 ~44 stone_slab 0  
fill ~5 ~7 ~45 ~9 ~7 ~45 stone_slab 0  
fill ~5 ~7 ~51 ~8 ~7 ~51 stone_slab 8  
fill ~6 ~7 ~12 ~9 ~7 ~12 stone_slab 8  
fill ~6 ~7 ~13 ~8 ~7 ~13 stone_slab 8  
fill ~6 ~7 ~17 ~10 ~7 ~17 stone_slab 0  
fill ~6 ~7 ~18 ~6 ~7 ~17 stone_slab 0  
fill ~6 ~7 ~28 ~6 ~8 ~28 double_stone_slab 0  
fill ~6 ~7 ~32 ~6 ~8 ~32 double_stone_slab 0  
fill ~6 ~7 ~36 ~6 ~8 ~36 double_stone_slab 0 
setblock ~6 ~7 ~37 stone_slab 5  
fill ~6 ~7 ~46 ~7 ~7 ~46 stone_slab 0  
fill ~6 ~7 ~47 ~10 ~7 ~47 stone_slab 0 
setblock ~6 ~7 ~49 stone_slab 13  
fill ~6 ~7 ~52 ~9 ~7 ~52 stone_slab 8  
fill ~7 ~7 ~11 ~10 ~7 ~11 stone_slab 8  
fill ~7 ~7 ~15 ~12 ~7 ~15 stone_slab 0  
fill ~7 ~7 ~16 ~11 ~7 ~16 stone_slab 0  
fill ~7 ~7 ~18 ~9 ~7 ~18 stone_slab 5  
fill ~7 ~7 ~24 ~7 ~7 ~25 stone_slab 5  
fill ~7 ~7 ~27 ~7 ~8 ~27 double_stone_slab 0  
fill ~7 ~7 ~28 ~9 ~7 ~28 stone_slab 0  
fill ~7 ~7 ~29 ~7 ~8 ~29 double_stone_slab 0  
fill ~7 ~7 ~31 ~7 ~8 ~31 double_stone_slab 0  
fill ~7 ~7 ~32 ~9 ~7 ~32 stone_slab 0  
fill ~7 ~7 ~33 ~7 ~8 ~33 double_stone_slab 0  
fill ~7 ~7 ~35 ~7 ~8 ~35 double_stone_slab 0  
fill ~7 ~7 ~36 ~9 ~7 ~36 stone_slab 0  
fill ~7 ~7 ~37 ~7 ~8 ~37 double_stone_slab 0  
fill ~7 ~7 ~38 ~7 ~7 ~49 stone_slab 0  
fill ~7 ~7 ~53 ~10 ~7 ~53 stone_slab 8  
fill ~8 ~7 ~10 ~11 ~7 ~10 stone_slab 8  
fill ~8 ~7 ~14 ~13 ~7 ~14 stone_slab 0  
fill ~8 ~7 ~26 ~8 ~8 ~26 double_stone_slab 0 
setblock ~8 ~7 ~27 stone_slab 0 
setblock ~8 ~7 ~29 stone_slab 0  
fill ~8 ~7 ~30 ~8 ~8 ~30 double_stone_slab 0 
setblock ~8 ~7 ~31 stone_slab 0 
setblock ~8 ~7 ~33 stone_slab 0  
fill ~8 ~7 ~34 ~8 ~8 ~34 double_stone_slab 0 
setblock ~8 ~7 ~35 stone_slab 0 
setblock ~8 ~7 ~37 stone_slab 0  
fill ~8 ~7 ~38 ~8 ~8 ~38 double_stone_slab 0 
setblock ~8 ~7 ~46 stone_slab 5  
fill ~8 ~7 ~48 ~11 ~7 ~48 stone_slab 0  
fill ~8 ~7 ~49 ~12 ~7 ~49 stone_slab 0  
fill ~8 ~7 ~50 ~13 ~7 ~50 stone_slab 0  
fill ~8 ~7 ~54 ~11 ~7 ~54 stone_slab 8  
fill ~9 ~7 ~9 ~12 ~7 ~9 stone_slab 8  
fill ~9 ~7 ~13 ~14 ~7 ~13 stone_slab 0  
fill ~9 ~7 ~27 ~9 ~8 ~27 double_stone_slab 0  
fill ~9 ~7 ~29 ~9 ~8 ~29 double_stone_slab 0  
fill ~9 ~7 ~31 ~9 ~8 ~31 double_stone_slab 0  
fill ~9 ~7 ~33 ~9 ~8 ~33 double_stone_slab 0  
fill ~9 ~7 ~35 ~9 ~8 ~35 double_stone_slab 0  
fill ~9 ~7 ~37 ~9 ~8 ~37 double_stone_slab 0 
setblock ~9 ~7 ~46 stone_slab 0 
setblock ~9 ~7 ~51 stone_slab 5  
fill ~9 ~7 ~55 ~10 ~7 ~55 stone_slab 8  
fill ~10 ~7 ~8 ~13 ~7 ~8 stone_slab 8  
fill ~10 ~7 ~12 ~11 ~7 ~12 stone_slab 0  
fill ~10 ~7 ~28 ~10 ~8 ~28 double_stone_slab 0  
fill ~10 ~7 ~32 ~10 ~8 ~32 double_stone_slab 0  
fill ~10 ~7 ~36 ~10 ~8 ~36 double_stone_slab 0  
fill ~10 ~7 ~51 ~14 ~7 ~51 stone_slab 0  
fill ~10 ~7 ~52 ~14 ~7 ~52 stone_slab 0  
fill ~10 ~7 ~56 ~13 ~7 ~56 stone_slab 8 
setblock ~11 ~7 ~7 stone_slab 8  
fill ~11 ~7 ~11 ~16 ~7 ~11 stone_slab 0  
fill ~11 ~7 ~53 ~16 ~7 ~53 stone_slab 0 
setblock ~11 ~7 ~55 stone_slab 13  
fill ~11 ~7 ~57 ~14 ~7 ~57 stone_slab 8  
fill ~12 ~7 ~6 ~15 ~7 ~6 stone_slab 8 
setblock ~12 ~7 ~7 stone_slab 13  
fill ~12 ~7 ~10 ~17 ~7 ~10 stone_slab 0 
setblock ~12 ~7 ~12 stone_slab 5  
fill ~12 ~7 ~54 ~17 ~7 ~54 stone_slab 0 
setblock ~12 ~7 ~55 stone_slab 8  
fill ~12 ~7 ~58 ~15 ~7 ~58 stone_slab 8  
fill ~13 ~7 ~5 ~17 ~7 ~5 stone_slab 8  
fill ~13 ~7 ~7 ~14 ~7 ~7 stone_slab 8  
fill ~13 ~7 ~9 ~18 ~7 ~9 stone_slab 0  
fill ~13 ~7 ~12 ~14 ~7 ~12 stone_slab 0  
fill ~13 ~7 ~55 ~18 ~7 ~55 stone_slab 0  
fill ~13 ~7 ~59 ~17 ~7 ~59 stone_slab 8  
fill ~14 ~7 ~4 ~19 ~7 ~4 stone_slab 8  
fill ~14 ~7 ~8 ~20 ~7 ~8 stone_slab 0  
fill ~14 ~7 ~56 ~20 ~7 ~56 stone_slab 0  
fill ~14 ~7 ~60 ~19 ~7 ~60 stone_slab 8  
fill ~15 ~7 ~3 ~18 ~7 ~3 stone_slab 8  
fill ~15 ~7 ~7 ~16 ~7 ~7 stone_slab 0 
setblock ~15 ~7 ~12 stone_slab 5 
setblock ~15 ~7 ~52 stone_slab 5  
fill ~15 ~7 ~57 ~18 ~7 ~57 stone_slab 0  
fill ~15 ~7 ~61 ~16 ~7 ~61 stone_slab 8  
fill ~16 ~7 ~2 ~18 ~7 ~2 stone_slab 8  
fill ~16 ~7 ~6 ~27 ~7 ~6 stone_slab 0  
fill ~16 ~7 ~58 ~28 ~7 ~58 stone_slab 0  
fill ~16 ~7 ~62 ~17 ~7 ~62 stone_slab 8  
fill ~17 ~7 ~7 ~18 ~7 ~7 stone_slab 5  
fill ~17 ~7 ~61 ~18 ~7 ~61 stone_slab 13  
fill ~18 ~7 ~1 ~24 ~7 ~1 stone_slab 8  
fill ~18 ~7 ~5 ~22 ~7 ~5 stone_slab 0  
fill ~18 ~7 ~59 ~22 ~7 ~59 stone_slab 0 
setblock ~18 ~7 ~62 stone_slab 13  
fill ~18 ~7 ~63 ~24 ~7 ~63 stone_slab 8  
fill ~19 ~7 ~2 ~19 ~7 ~3 stone_slab 13  
fill ~19 ~7 ~7 ~23 ~7 ~7 stone_slab 0 
setblock ~19 ~7 ~57 stone_slab 5  
fill ~19 ~7 ~61 ~22 ~7 ~61 stone_slab 8  
fill ~19 ~7 ~62 ~28 ~7 ~62 stone_slab 8  
fill ~20 ~7 ~0 ~28 ~7 ~0 stone_slab 8  
fill ~20 ~7 ~2 ~28 ~7 ~2 stone_slab 8  
fill ~20 ~7 ~3 ~22 ~7 ~3 stone_slab 8  
fill ~20 ~7 ~4 ~28 ~7 ~4 stone_slab 0 
setblock ~20 ~7 ~49 redstone_block 0  
fill ~20 ~7 ~57 ~23 ~7 ~57 stone_slab 0  
fill ~20 ~7 ~60 ~28 ~7 ~60 stone_slab 0  
fill ~20 ~7 ~64 ~28 ~7 ~64 stone_slab 8  
fill ~23 ~7 ~-1 ~27 ~7 ~-1 stone_slab 8  
fill ~23 ~7 ~3 ~26 ~7 ~3 stone_slab 0 
setblock ~23 ~7 ~5 stone_slab 5  
fill ~23 ~7 ~59 ~24 ~7 ~59 stone_slab 5  
fill ~23 ~7 ~61 ~26 ~7 ~61 stone_slab 0  
fill ~23 ~7 ~65 ~27 ~7 ~65 stone_slab 8  
fill ~24 ~7 ~5 ~28 ~7 ~5 stone_slab 0 
setblock ~25 ~7 ~1 stone_slab 13  
fill ~25 ~7 ~59 ~28 ~7 ~59 stone_slab 0 
setblock ~25 ~7 ~63 stone_slab 13  
fill ~26 ~7 ~1 ~28 ~7 ~1 stone_slab 8  
fill ~26 ~7 ~63 ~28 ~7 ~63 stone_slab 8  
fill ~27 ~7 ~3 ~29 ~7 ~3 double_stone_slab 0  
fill ~27 ~7 ~7 ~28 ~7 ~7 stone_slab 0  
fill ~27 ~7 ~57 ~28 ~7 ~57 stone_slab 0  
fill ~27 ~7 ~61 ~29 ~7 ~61 double_stone_slab 0 
setblock ~28 ~7 ~6 stone_slab 5  
fill ~29 ~7 ~0 ~30 ~7 ~0 double_stone_slab 0  
fill ~29 ~7 ~1 ~29 ~7 ~23 double_stone_slab 0  
fill ~29 ~7 ~41 ~30 ~7 ~41 double_stone_slab 0  
fill ~29 ~7 ~42 ~29 ~7 ~64 double_stone_slab 0  
fill ~30 ~7 ~-2 ~32 ~7 ~-2 double_stone_slab 0  
fill ~30 ~7 ~-1 ~32 ~7 ~-1 double_stone_slab 0  
fill ~30 ~7 ~23 ~30 ~9 ~23 double_stone_slab 0  
fill ~30 ~7 ~59 ~38 ~7 ~59 concrete 7  
fill ~30 ~7 ~63 ~38 ~7 ~63 stone_slab 8  
fill ~30 ~7 ~64 ~30 ~7 ~66 double_stone_slab 0  
fill ~31 ~7 ~-4 ~32 ~7 ~-4 double_stone_slab 0  
fill ~31 ~7 ~-3 ~32 ~7 ~-3 double_stone_slab 0  
fill ~31 ~7 ~22 ~37 ~7 ~22 double_stone_slab 0  
fill ~31 ~7 ~42 ~37 ~7 ~42 double_stone_slab 0  
fill ~31 ~7 ~65 ~32 ~7 ~65 double_stone_slab 0  
fill ~31 ~7 ~66 ~32 ~7 ~66 double_stone_slab 0  
fill ~31 ~7 ~67 ~32 ~7 ~67 double_stone_slab 0  
fill ~31 ~7 ~68 ~32 ~7 ~68 double_stone_slab 0  
fill ~32 ~7 ~32 ~32 ~10 ~32 wool 8 
setblock ~33 ~7 ~-4 lever 4  
fill ~33 ~7 ~-3 ~35 ~7 ~-3 stained_hardened_clay 9  
fill ~33 ~7 ~31 ~35 ~7 ~31 wool 8  
fill ~33 ~7 ~34 ~33 ~9 ~34 wool 8  
fill ~33 ~7 ~67 ~35 ~7 ~67 stained_hardened_clay 9  
fill ~33 ~7 ~68 ~34 ~7 ~68 lever 11  
fill ~34 ~7 ~65 ~34 ~11 ~65 nether_brick_fence 0  
fill ~35 ~7 ~34 ~35 ~9 ~34 wool 8  
fill ~36 ~7 ~-4 ~37 ~7 ~-4 double_stone_slab 0  
fill ~36 ~7 ~-3 ~37 ~7 ~-3 double_stone_slab 0  
fill ~36 ~7 ~-2 ~38 ~7 ~-2 double_stone_slab 0  
fill ~36 ~7 ~-1 ~38 ~7 ~-1 double_stone_slab 0  
fill ~36 ~7 ~32 ~36 ~10 ~32 wool 8  
fill ~36 ~7 ~33 ~36 ~9 ~33 wool 8  
fill ~36 ~7 ~65 ~38 ~7 ~65 double_stone_slab 0  
fill ~36 ~7 ~66 ~38 ~7 ~66 double_stone_slab 0  
fill ~36 ~7 ~67 ~37 ~7 ~67 double_stone_slab 0  
fill ~36 ~7 ~68 ~37 ~7 ~68 double_stone_slab 0  
fill ~38 ~7 ~0 ~39 ~7 ~0 double_stone_slab 0  
fill ~38 ~7 ~23 ~38 ~9 ~23 double_stone_slab 0  
fill ~38 ~7 ~41 ~39 ~7 ~41 double_stone_slab 0  
fill ~38 ~7 ~64 ~39 ~7 ~64 double_stone_slab 0  
fill ~39 ~7 ~1 ~39 ~7 ~23 double_stone_slab 0  
fill ~39 ~7 ~42 ~39 ~7 ~64 double_stone_slab 0  
fill ~40 ~7 ~0 ~48 ~7 ~0 stone_slab 8  
fill ~40 ~7 ~1 ~50 ~7 ~1 stone_slab 8  
fill ~40 ~7 ~2 ~46 ~7 ~2 stone_slab 8  
fill ~40 ~7 ~3 ~41 ~7 ~3 double_stone_slab 0  
fill ~40 ~7 ~4 ~48 ~7 ~4 stone_slab 0  
fill ~40 ~7 ~5 ~50 ~7 ~5 stone_slab 0  
fill ~40 ~7 ~6 ~43 ~7 ~6 stone_slab 0  
fill ~40 ~7 ~7 ~41 ~7 ~7 stone_slab 0 
setblock ~40 ~7 ~16 concrete 7  
fill ~40 ~7 ~57 ~41 ~7 ~57 stone_slab 0  
fill ~40 ~7 ~58 ~52 ~7 ~58 stone_slab 0  
fill ~40 ~7 ~59 ~41 ~7 ~59 stone_slab 0  
fill ~40 ~7 ~60 ~41 ~7 ~60 stone_slab 0  
fill ~40 ~7 ~61 ~41 ~7 ~61 double_stone_slab 0  
fill ~40 ~7 ~62 ~52 ~7 ~62 stone_slab 8  
fill ~40 ~7 ~63 ~44 ~7 ~63 stone_slab 8  
fill ~40 ~7 ~64 ~48 ~7 ~64 stone_slab 8  
fill ~41 ~7 ~-1 ~45 ~7 ~-1 stone_slab 8  
fill ~41 ~7 ~19 ~45 ~7 ~19 concrete 7  
fill ~41 ~7 ~20 ~45 ~7 ~20 concrete 7  
fill ~41 ~7 ~21 ~45 ~7 ~21 concrete 7  
fill ~41 ~7 ~65 ~45 ~7 ~65 stone_slab 8  
fill ~42 ~7 ~3 ~45 ~7 ~3 stone_slab 0  
fill ~42 ~7 ~18 ~44 ~7 ~18 concrete 7  
fill ~42 ~7 ~22 ~44 ~7 ~22 concrete 7  
fill ~42 ~7 ~59 ~42 ~7 ~60 stone_slab 5  
fill ~42 ~7 ~61 ~45 ~7 ~61 stone_slab 0  
fill ~43 ~7 ~59 ~50 ~7 ~59 stone_slab 0  
fill ~43 ~7 ~60 ~48 ~7 ~60 stone_slab 0 
setblock ~44 ~7 ~6 stone_slab 5  
fill ~45 ~7 ~6 ~52 ~7 ~6 stone_slab 0  
fill ~45 ~7 ~7 ~53 ~7 ~7 stone_slab 0  
fill ~45 ~7 ~57 ~53 ~7 ~57 stone_slab 0 
setblock ~45 ~7 ~63 stone_slab 13  
fill ~46 ~7 ~3 ~53 ~7 ~3 stone_slab 8  
fill ~46 ~7 ~61 ~53 ~7 ~61 stone_slab 8  
fill ~46 ~7 ~63 ~50 ~7 ~63 stone_slab 8 
setblock ~47 ~7 ~2 stone_slab 13 
setblock ~47 ~7 ~16 concrete 7  
fill ~47 ~7 ~26 ~47 ~8 ~26 concrete 15  
fill ~47 ~7 ~28 ~49 ~7 ~28 concrete 15  
fill ~48 ~7 ~2 ~52 ~7 ~2 stone_slab 8  
fill ~48 ~7 ~8 ~54 ~7 ~8 stone_slab 0  
fill ~48 ~7 ~19 ~52 ~7 ~19 concrete 7  
fill ~48 ~7 ~20 ~52 ~7 ~20 concrete 7  
fill ~48 ~7 ~21 ~52 ~7 ~21 concrete 7  
fill ~48 ~7 ~56 ~49 ~7 ~56 stone_slab 0  
fill ~49 ~7 ~4 ~54 ~7 ~4 stone_slab 8  
fill ~49 ~7 ~18 ~51 ~7 ~18 concrete 7  
fill ~49 ~7 ~22 ~51 ~7 ~22 concrete 7  
fill ~49 ~7 ~60 ~54 ~7 ~60 stone_slab 8  
fill ~50 ~7 ~9 ~55 ~7 ~9 stone_slab 0  
fill ~50 ~7 ~55 ~55 ~7 ~55 stone_slab 0 
setblock ~50 ~7 ~56 stone_slab 5  
fill ~51 ~7 ~5 ~55 ~7 ~5 stone_slab 8  
fill ~51 ~7 ~10 ~56 ~7 ~10 stone_slab 0  
fill ~51 ~7 ~54 ~56 ~7 ~54 stone_slab 0  
fill ~51 ~7 ~56 ~54 ~7 ~56 stone_slab 0  
fill ~51 ~7 ~59 ~55 ~7 ~59 stone_slab 8  
fill ~52 ~7 ~11 ~57 ~7 ~11 stone_slab 0  
fill ~52 ~7 ~53 ~57 ~7 ~53 stone_slab 0  
fill ~53 ~7 ~6 ~56 ~7 ~6 stone_slab 8  
fill ~53 ~7 ~12 ~55 ~7 ~12 stone_slab 0  
fill ~53 ~7 ~23 ~57 ~7 ~23 concrete 7  
fill ~53 ~7 ~24 ~57 ~7 ~24 concrete 7  
fill ~53 ~7 ~52 ~54 ~7 ~52 stone_slab 0  
fill ~53 ~7 ~58 ~56 ~7 ~58 stone_slab 8  
fill ~54 ~7 ~7 ~55 ~7 ~7 stone_slab 8  
fill ~54 ~7 ~13 ~59 ~7 ~13 stone_slab 0  
fill ~54 ~7 ~22 ~56 ~7 ~22 concrete 7  
fill ~54 ~7 ~25 ~56 ~7 ~25 concrete 7 
setblock ~54 ~7 ~51 stone_slab 0  
fill ~54 ~7 ~57 ~57 ~7 ~57 stone_slab 8  
fill ~55 ~7 ~8 ~58 ~7 ~8 stone_slab 8  
fill ~55 ~7 ~14 ~60 ~7 ~14 stone_slab 0 
setblock ~55 ~7 ~18 concrete 7  
fill ~55 ~7 ~50 ~60 ~7 ~50 stone_slab 0  
fill ~55 ~7 ~51 ~56 ~7 ~51 stone_slab 5  
fill ~55 ~7 ~52 ~56 ~7 ~52 stone_slab 5 
setblock ~55 ~7 ~56 stone_slab 8 
setblock ~56 ~7 ~7 stone_slab 13  
fill ~56 ~7 ~9 ~59 ~7 ~9 stone_slab 8 
setblock ~56 ~7 ~12 stone_slab 5  
fill ~56 ~7 ~15 ~61 ~7 ~15 stone_slab 0  
fill ~56 ~7 ~49 ~61 ~7 ~49 stone_slab 0  
fill ~56 ~7 ~55 ~59 ~7 ~55 stone_slab 8 
setblock ~56 ~7 ~56 stone_slab 13 
setblock ~57 ~7 ~7 stone_slab 8  
fill ~57 ~7 ~10 ~60 ~7 ~10 stone_slab 8  
fill ~57 ~7 ~12 ~58 ~7 ~12 stone_slab 0  
fill ~57 ~7 ~16 ~61 ~7 ~16 stone_slab 0 
setblock ~57 ~7 ~18 concrete 7  
fill ~57 ~7 ~48 ~61 ~7 ~48 stone_slab 0  
fill ~57 ~7 ~51 ~59 ~7 ~51 stone_slab 0  
fill ~57 ~7 ~52 ~58 ~7 ~52 stone_slab 0  
fill ~57 ~7 ~54 ~60 ~7 ~54 stone_slab 8  
fill ~57 ~7 ~56 ~58 ~7 ~56 stone_slab 8  
fill ~58 ~7 ~11 ~61 ~7 ~11 stone_slab 8  
fill ~58 ~7 ~17 ~62 ~7 ~17 stone_slab 0  
fill ~58 ~7 ~47 ~62 ~7 ~47 stone_slab 0  
fill ~58 ~7 ~53 ~61 ~7 ~53 stone_slab 8  
fill ~59 ~7 ~12 ~62 ~7 ~12 stone_slab 8  
fill ~59 ~7 ~18 ~62 ~7 ~18 stone_slab 0  
fill ~59 ~7 ~19 ~63 ~7 ~19 double_stone_slab 0  
fill ~59 ~7 ~20 ~59 ~7 ~27 double_stone_slab 0  
fill ~59 ~7 ~45 ~63 ~7 ~45 stone_slab 0  
fill ~59 ~7 ~46 ~62 ~7 ~46 stone_slab 0  
fill ~59 ~7 ~52 ~61 ~7 ~52 stone_slab 8  
fill ~60 ~7 ~13 ~63 ~7 ~13 stone_slab 8 
setblock ~60 ~7 ~20 stone_slab 0  
fill ~60 ~7 ~21 ~61 ~7 ~21 double_stone_slab 0  
fill ~60 ~7 ~22 ~61 ~7 ~22 double_stone_slab 0  
fill ~60 ~7 ~23 ~61 ~7 ~23 double_stone_slab 0  
fill ~60 ~7 ~25 ~61 ~7 ~25 double_stone_slab 0 
setblock ~60 ~7 ~26 stone_slab 0  
fill ~60 ~7 ~27 ~61 ~7 ~27 double_stone_slab 0  
fill ~60 ~7 ~42 ~64 ~7 ~42 stone_slab 0  
fill ~60 ~7 ~43 ~63 ~7 ~43 stone_slab 0  
fill ~60 ~7 ~44 ~60 ~7 ~42 stone_slab 0  
fill ~60 ~7 ~51 ~63 ~7 ~51 stone_slab 8  
fill ~61 ~7 ~14 ~64 ~7 ~14 stone_slab 8  
fill ~61 ~7 ~20 ~63 ~7 ~20 double_stone_slab 0 
setblock ~61 ~7 ~24 double_stone_slab 0 
setblock ~61 ~7 ~26 double_stone_slab 0 
setblock ~61 ~7 ~28 concrete 7  
fill ~61 ~7 ~30 ~61 ~8 ~30 double_stone_slab 0  
fill ~61 ~7 ~31 ~61 ~8 ~31 double_stone_slab 0  
fill ~61 ~7 ~32 ~61 ~8 ~32 double_stone_slab 0  
fill ~61 ~7 ~33 ~61 ~8 ~33 double_stone_slab 0  
fill ~61 ~7 ~34 ~61 ~8 ~34 double_stone_slab 0  
fill ~61 ~7 ~35 ~61 ~8 ~35 double_stone_slab 0  
fill ~61 ~7 ~36 ~77 ~7 ~36 double_stone_slab 0 
setblock ~61 ~7 ~38 stone_slab 5  
fill ~61 ~7 ~39 ~64 ~7 ~39 stone_slab 0  
fill ~61 ~7 ~40 ~64 ~7 ~40 stone_slab 0  
fill ~61 ~7 ~41 ~64 ~7 ~41 stone_slab 0 
setblock ~61 ~7 ~44 stone_slab 5  
fill ~61 ~7 ~50 ~64 ~7 ~50 stone_slab 8  
fill ~62 ~7 ~15 ~65 ~7 ~15 stone_slab 8  
fill ~62 ~7 ~16 ~62 ~7 ~12 stone_slab 8  
fill ~62 ~7 ~21 ~63 ~7 ~21 stone_slab 0  
fill ~62 ~7 ~22 ~64 ~7 ~22 stone_slab 0 
setblock ~62 ~7 ~23 stone_slab 5  
fill ~62 ~7 ~24 ~64 ~7 ~24 stone_slab 0  
fill ~62 ~7 ~25 ~64 ~7 ~25 stone_slab 0  
fill ~62 ~7 ~26 ~63 ~7 ~26 stone_slab 0  
fill ~62 ~7 ~27 ~64 ~7 ~27 stone_slab 0  
fill ~62 ~7 ~28 ~77 ~7 ~28 double_stone_slab 0  
fill ~62 ~7 ~37 ~64 ~7 ~37 stone_slab 0  
fill ~62 ~7 ~38 ~64 ~7 ~38 stone_slab 0  
fill ~62 ~7 ~44 ~63 ~7 ~44 stone_slab 0  
fill ~62 ~7 ~48 ~65 ~7 ~48 stone_slab 8  
fill ~62 ~7 ~49 ~65 ~7 ~49 stone_slab 8 
setblock ~62 ~7 ~52 stone_slab 13 
setblock ~63 ~7 ~16 stone_slab 13  
fill ~63 ~7 ~17 ~66 ~7 ~17 stone_slab 8  
fill ~63 ~7 ~18 ~66 ~7 ~18 stone_slab 8  
fill ~63 ~7 ~23 ~64 ~7 ~23 stone_slab 0  
fill ~63 ~7 ~46 ~63 ~7 ~51 stone_slab 8  
fill ~64 ~7 ~16 ~65 ~7 ~16 stone_slab 8  
fill ~64 ~7 ~19 ~67 ~7 ~19 stone_slab 8  
fill ~64 ~7 ~20 ~67 ~7 ~20 stone_slab 8  
fill ~64 ~7 ~21 ~67 ~7 ~21 stone_slab 8 
setblock ~64 ~7 ~26 double_stone_slab 0  
fill ~64 ~7 ~43 ~67 ~7 ~43 stone_slab 8  
fill ~64 ~7 ~44 ~67 ~7 ~44 stone_slab 8  
fill ~64 ~7 ~45 ~67 ~7 ~45 stone_slab 8 
setblock ~64 ~7 ~46 stone_slab 13  
fill ~64 ~7 ~47 ~66 ~7 ~47 stone_slab 8  
fill ~65 ~7 ~22 ~66 ~7 ~22 stone_slab 8  
fill ~65 ~7 ~23 ~68 ~7 ~23 stone_slab 8  
fill ~65 ~7 ~24 ~68 ~7 ~24 stone_slab 8  
fill ~65 ~7 ~25 ~68 ~7 ~25 stone_slab 8  
fill ~65 ~7 ~26 ~68 ~7 ~26 stone_slab 8  
fill ~65 ~7 ~27 ~68 ~7 ~27 stone_slab 8 
setblock ~65 ~7 ~30 stone_brick_stairs 6 
setblock ~65 ~7 ~31 stone_brick_stairs 3 
setblock ~65 ~7 ~33 stone_brick_stairs 2 
setblock ~65 ~7 ~34 stone_brick_stairs 7 
setblock ~65 ~7 ~35 anvil 2  
fill ~65 ~7 ~37 ~68 ~7 ~37 stone_slab 8  
fill ~65 ~7 ~38 ~65 ~7 ~49 stone_slab 8  
fill ~66 ~7 ~38 ~67 ~7 ~38 stone_slab 13  
fill ~66 ~7 ~39 ~68 ~7 ~39 stone_slab 8  
fill ~66 ~7 ~40 ~68 ~7 ~40 stone_slab 8  
fill ~66 ~7 ~41 ~68 ~7 ~41 stone_slab 8  
fill ~66 ~7 ~42 ~68 ~7 ~42 stone_slab 8 
setblock ~66 ~7 ~46 stone_slab 8 
setblock ~67 ~7 ~22 stone_slab 13 
setblock ~68 ~7 ~22 stone_slab 8 
setblock ~68 ~7 ~38 stone_slab 8  
fill ~69 ~7 ~29 ~69 ~14 ~29 stained_hardened_clay 9  
fill ~69 ~7 ~30 ~69 ~9 ~30 stained_hardened_clay 9  
fill ~69 ~7 ~31 ~69 ~7 ~35 stained_hardened_clay 9  
fill ~70 ~7 ~29 ~70 ~9 ~29 double_stone_slab 0  
fill ~70 ~7 ~30 ~70 ~9 ~30 double_stone_slab 0  
fill ~70 ~7 ~31 ~70 ~7 ~33 double_stone_slab 0  
fill ~70 ~7 ~34 ~70 ~8 ~34 stained_hardened_clay 9  
fill ~70 ~7 ~35 ~70 ~9 ~35 double_stone_slab 0 
setblock ~71 ~7 ~29 stone_brick_stairs 5 
setblock ~71 ~7 ~30 stone_button 1  
fill ~71 ~7 ~31 ~79 ~7 ~31 wool 7  
fill ~71 ~7 ~32 ~79 ~7 ~32 stone_slab 5  
fill ~71 ~7 ~33 ~79 ~7 ~33 wool 7 
setblock ~71 ~7 ~35 stone_button 1  
fill ~78 ~7 ~28 ~83 ~7 ~28 stone_slab 8  
fill ~78 ~7 ~29 ~83 ~7 ~29 stone_slab 0  
fill ~78 ~7 ~30 ~79 ~7 ~30 stone_slab 0  
fill ~78 ~7 ~34 ~79 ~7 ~34 stone_slab 0  
fill ~78 ~7 ~35 ~83 ~7 ~35 stone_slab 0  
fill ~78 ~7 ~36 ~83 ~7 ~36 stone_slab 8  
fill ~80 ~7 ~30 ~83 ~7 ~30 stone_slab 5  
fill ~80 ~7 ~31 ~83 ~7 ~31 stone_slab 0  
fill ~80 ~7 ~32 ~82 ~7 ~32 wool 7  
fill ~80 ~7 ~33 ~83 ~7 ~33 stone_slab 0  
fill ~80 ~7 ~34 ~83 ~7 ~34 stone_slab 5 
setblock ~83 ~7 ~32 stone_slab 0  
fill ~84 ~7 ~29 ~84 ~7 ~35 stone_brick_stairs 5  
fill ~-5 ~8 ~24 ~-4 ~8 ~24 stone_slab 8  
fill ~-5 ~8 ~25 ~-5 ~8 ~40 stone_slab 8  
fill ~-4 ~8 ~20 ~-3 ~8 ~20 stone_slab 8  
fill ~-4 ~8 ~21 ~-4 ~8 ~24 stone_slab 8  
fill ~-4 ~8 ~25 ~-3 ~8 ~25 stone_slab 0  
fill ~-4 ~8 ~26 ~-4 ~8 ~39 stone_slab 0  
fill ~-4 ~8 ~40 ~-4 ~8 ~44 stone_slab 8  
fill ~-3 ~8 ~17 ~-2 ~8 ~17 stone_slab 8  
fill ~-3 ~8 ~18 ~-3 ~8 ~20 stone_slab 8  
fill ~-3 ~8 ~21 ~-2 ~8 ~21 stone_slab 0  
fill ~-3 ~8 ~22 ~-3 ~8 ~25 stone_slab 0  
fill ~-3 ~8 ~26 ~-3 ~8 ~37 double_stone_slab 0 
setblock ~-3 ~8 ~38 double_stone_slab 5  
fill ~-3 ~8 ~39 ~-3 ~8 ~43 stone_slab 0  
fill ~-3 ~8 ~44 ~-3 ~8 ~47 stone_slab 8  
fill ~-2 ~8 ~15 ~-1 ~8 ~15 stone_slab 8  
fill ~-2 ~8 ~16 ~-2 ~8 ~15 stone_slab 8  
fill ~-2 ~8 ~18 ~-1 ~8 ~18 stone_slab 0  
fill ~-2 ~8 ~19 ~-2 ~8 ~21 stone_slab 0  
fill ~-2 ~8 ~22 ~-2 ~8 ~25 double_stone_slab 0  
fill ~-2 ~8 ~26 ~-2 ~8 ~31 stone_slab 0 
setblock ~-2 ~8 ~32 stone_slab 5  
fill ~-2 ~8 ~33 ~-2 ~8 ~38 stone_slab 0  
fill ~-2 ~8 ~39 ~-2 ~8 ~42 double_stone_slab 0  
fill ~-2 ~8 ~43 ~-2 ~8 ~46 stone_slab 0  
fill ~-2 ~8 ~47 ~-2 ~8 ~49 stone_slab 8  
fill ~-1 ~8 ~13 ~0 ~8 ~13 stone_slab 8  
fill ~-1 ~8 ~14 ~-1 ~8 ~13 stone_slab 8  
fill ~-1 ~8 ~16 ~0 ~8 ~16 stone_slab 0  
fill ~-1 ~8 ~17 ~-1 ~8 ~16 stone_slab 0  
fill ~-1 ~8 ~19 ~-1 ~8 ~20 double_stone_slab 5 
setblock ~-1 ~8 ~21 double_stone_slab 0  
fill ~-1 ~8 ~22 ~-1 ~8 ~25 stone_slab 0 
setblock ~-1 ~8 ~26 stone_slab 5  
fill ~-1 ~8 ~27 ~-1 ~8 ~38 double_stone_slab 0  
fill ~-1 ~8 ~39 ~-1 ~8 ~41 stone_slab 0 
setblock ~-1 ~8 ~42 stone_slab 5  
fill ~-1 ~8 ~43 ~0 ~8 ~43 stained_hardened_clay 14  
fill ~-1 ~8 ~44 ~0 ~8 ~44 stained_hardened_clay 14  
fill ~-1 ~8 ~45 ~0 ~8 ~45 stained_hardened_clay 14  
fill ~-1 ~8 ~46 ~-1 ~8 ~48 stone_slab 0  
fill ~-1 ~8 ~49 ~-1 ~8 ~51 stone_slab 8  
fill ~0 ~8 ~11 ~1 ~8 ~11 stone_slab 8  
fill ~0 ~8 ~12 ~0 ~8 ~11 stone_slab 8  
fill ~0 ~8 ~14 ~1 ~8 ~14 stone_slab 0  
fill ~0 ~8 ~15 ~0 ~8 ~14 stone_slab 0  
fill ~0 ~8 ~17 ~0 ~8 ~18 double_stone_slab 0  
fill ~0 ~8 ~19 ~0 ~8 ~21 stone_slab 0  
fill ~0 ~8 ~22 ~0 ~8 ~25 double_stone_slab 0  
fill ~0 ~8 ~26 ~1 ~8 ~26 wool 8  
fill ~0 ~8 ~27 ~1 ~8 ~27 wool 8  
fill ~0 ~8 ~28 ~1 ~8 ~28 wool 8  
fill ~0 ~8 ~29 ~1 ~8 ~29 wool 8  
fill ~0 ~8 ~30 ~3 ~8 ~30 wool 8  
fill ~0 ~8 ~31 ~3 ~8 ~31 wool 8  
fill ~0 ~8 ~32 ~2 ~8 ~32 wool 8  
fill ~0 ~8 ~33 ~1 ~8 ~33 wool 8  
fill ~0 ~8 ~34 ~1 ~8 ~34 wool 8  
fill ~0 ~8 ~35 ~1 ~8 ~35 wool 8  
fill ~0 ~8 ~36 ~1 ~8 ~36 wool 8  
fill ~0 ~8 ~37 ~1 ~8 ~37 wool 8  
fill ~0 ~8 ~38 ~1 ~8 ~38 wool 8  
fill ~0 ~8 ~39 ~0 ~8 ~42 double_stone_slab 0  
fill ~0 ~8 ~46 ~0 ~8 ~47 double_stone_slab 0  
fill ~0 ~8 ~48 ~0 ~8 ~50 stone_slab 0  
fill ~0 ~8 ~51 ~0 ~8 ~53 stone_slab 8  
fill ~1 ~8 ~9 ~2 ~8 ~9 stone_slab 8  
fill ~1 ~8 ~10 ~1 ~8 ~9 stone_slab 8  
fill ~1 ~8 ~12 ~2 ~8 ~12 stone_slab 0  
fill ~1 ~8 ~13 ~1 ~8 ~12 stone_slab 0  
fill ~1 ~8 ~15 ~1 ~8 ~16 double_stone_slab 0  
fill ~1 ~8 ~17 ~1 ~8 ~18 stone_slab 0  
fill ~1 ~8 ~19 ~1 ~8 ~21 double_stone_slab 0  
fill ~1 ~8 ~22 ~3 ~8 ~22 wool 8  
fill ~1 ~8 ~23 ~1 ~8 ~42 wool 8  
fill ~1 ~8 ~43 ~1 ~8 ~45 double_stone_slab 0  
fill ~1 ~8 ~46 ~1 ~8 ~47 stone_slab 0 
setblock ~1 ~8 ~48 double_stone_slab 5 
setblock ~1 ~8 ~49 double_stone_slab 0  
fill ~1 ~8 ~50 ~1 ~8 ~52 stone_slab 0  
fill ~1 ~8 ~53 ~1 ~8 ~55 stone_slab 8  
fill ~2 ~8 ~8 ~3 ~8 ~8 stone_slab 8  
fill ~2 ~8 ~10 ~2 ~8 ~12 stone_slab 0  
fill ~2 ~8 ~13 ~2 ~8 ~14 double_stone_slab 0  
fill ~2 ~8 ~15 ~2 ~8 ~16 stone_slab 0  
fill ~2 ~8 ~17 ~2 ~8 ~18 double_stone_slab 0  
fill ~2 ~8 ~19 ~4 ~8 ~19 wool 8  
fill ~2 ~8 ~20 ~4 ~8 ~20 wool 8  
fill ~2 ~8 ~21 ~3 ~8 ~21 wool 8 
setblock ~2 ~8 ~29 concrete 15  
fill ~2 ~8 ~42 ~3 ~8 ~42 wool 8  
fill ~2 ~8 ~43 ~3 ~8 ~43 wool 8  
fill ~2 ~8 ~44 ~2 ~8 ~45 wool 8  
fill ~2 ~8 ~46 ~2 ~8 ~47 double_stone_slab 0  
fill ~2 ~8 ~48 ~2 ~8 ~49 stone_slab 0  
fill ~2 ~8 ~50 ~2 ~8 ~51 double_stone_slab 0  
fill ~2 ~8 ~52 ~2 ~8 ~54 stone_slab 0  
fill ~2 ~8 ~55 ~2 ~8 ~56 stone_slab 8  
fill ~3 ~8 ~7 ~4 ~8 ~7 stone_slab 8  
fill ~3 ~8 ~9 ~4 ~8 ~9 stone_slab 0 
setblock ~3 ~8 ~10 stone_slab 5  
fill ~3 ~8 ~11 ~3 ~8 ~12 double_stone_slab 0  
fill ~3 ~8 ~13 ~4 ~8 ~13 stone_slab 0  
fill ~3 ~8 ~14 ~3 ~8 ~13 stone_slab 0  
fill ~3 ~8 ~15 ~3 ~8 ~16 double_stone_slab 0  
fill ~3 ~8 ~17 ~4 ~8 ~17 wool 8  
fill ~3 ~8 ~18 ~4 ~8 ~18 wool 8  
fill ~3 ~8 ~45 ~3 ~8 ~47 wool 8  
fill ~3 ~8 ~48 ~3 ~8 ~49 double_stone_slab 0  
fill ~3 ~8 ~50 ~3 ~8 ~51 stone_slab 0  
fill ~3 ~8 ~52 ~3 ~8 ~53 double_stone_slab 0  
fill ~3 ~8 ~54 ~3 ~8 ~55 stone_slab 0  
fill ~3 ~8 ~56 ~3 ~8 ~57 stone_slab 8  
fill ~4 ~8 ~6 ~5 ~8 ~6 stone_slab 8  
fill ~4 ~8 ~8 ~5 ~8 ~8 stone_slab 0 
setblock ~4 ~8 ~10 double_stone_slab 0  
fill ~4 ~8 ~11 ~4 ~8 ~13 stone_slab 0 
setblock ~4 ~8 ~14 double_stone_slab 0  
fill ~4 ~8 ~15 ~5 ~8 ~15 wool 8  
fill ~4 ~8 ~16 ~4 ~8 ~15 wool 8  
fill ~4 ~8 ~47 ~4 ~8 ~49 wool 8  
fill ~4 ~8 ~50 ~4 ~8 ~51 double_stone_slab 0 
setblock ~4 ~8 ~52 stone_slab 5 
setblock ~4 ~8 ~53 stone_slab 0 
setblock ~4 ~8 ~54 double_stone_slab 0  
fill ~4 ~8 ~55 ~4 ~8 ~56 stone_slab 0  
fill ~4 ~8 ~57 ~4 ~8 ~58 stone_slab 8  
fill ~5 ~8 ~5 ~6 ~8 ~5 stone_slab 8  
fill ~5 ~8 ~7 ~6 ~8 ~7 stone_slab 0 
setblock ~5 ~8 ~9 double_stone_slab 0 
setblock ~5 ~8 ~10 stone_slab 0  
fill ~5 ~8 ~11 ~7 ~8 ~11 double_stone_slab 0  
fill ~5 ~8 ~12 ~5 ~8 ~13 double_stone_slab 0  
fill ~5 ~8 ~14 ~6 ~8 ~14 wool 8  
fill ~5 ~8 ~24 ~5 ~14 ~24 sea_lantern 0  
fill ~5 ~8 ~40 ~5 ~14 ~40 sea_lantern 0  
fill ~5 ~8 ~49 ~5 ~8 ~51 wool 8  
fill ~5 ~8 ~52 ~5 ~8 ~53 double_stone_slab 0 
setblock ~5 ~8 ~54 stone_slab 0 
setblock ~5 ~8 ~55 double_stone_slab 0 
setblock ~5 ~8 ~56 stone_slab 5  
fill ~5 ~8 ~57 ~6 ~8 ~57 stone_slab 0  
fill ~5 ~8 ~58 ~5 ~8 ~59 stone_slab 8  
fill ~6 ~8 ~4 ~7 ~8 ~4 stone_slab 8 
setblock ~6 ~8 ~6 stone_slab 0 
setblock ~6 ~8 ~8 double_stone_slab 0   

KittysCommands:  
setblock ~6 ~8 ~9 stone_slab 0  
fill ~6 ~8 ~10 ~8 ~8 ~10 double_stone_slab 0  
fill ~6 ~8 ~12 ~8 ~8 ~12 wool 8  
fill ~6 ~8 ~13 ~6 ~8 ~12 wool 8  
fill ~6 ~8 ~21 ~6 ~14 ~21 sea_lantern 0  
fill ~6 ~8 ~51 ~7 ~8 ~51 wool 8  
fill ~6 ~8 ~52 ~7 ~8 ~52 wool 8  
fill ~6 ~8 ~53 ~6 ~8 ~54 double_stone_slab 0 
setblock ~6 ~8 ~55 stone_slab 0 
setblock ~6 ~8 ~56 double_stone_slab 0 
setblock ~6 ~8 ~58 stone_slab 0  
fill ~6 ~8 ~59 ~6 ~8 ~60 stone_slab 8  
fill ~7 ~8 ~3 ~8 ~8 ~3 stone_slab 8 
setblock ~7 ~8 ~5 stone_slab 0  
fill ~7 ~8 ~6 ~7 ~8 ~7 double_stone_slab 0 
setblock ~7 ~8 ~8 stone_slab 0  
fill ~7 ~8 ~9 ~9 ~8 ~9 double_stone_slab 0 
setblock ~7 ~8 ~53 wool 8  
fill ~7 ~8 ~54 ~7 ~8 ~55 double_stone_slab 0 
setblock ~7 ~8 ~56 stone_slab 0  
fill ~7 ~8 ~57 ~7 ~8 ~58 double_stone_slab 0 
setblock ~7 ~8 ~59 stone_slab 0  
fill ~7 ~8 ~60 ~7 ~8 ~61 stone_slab 8  
fill ~8 ~8 ~4 ~9 ~8 ~4 stone_slab 0  
fill ~8 ~8 ~5 ~9 ~8 ~5 double_stone_slab 0  
fill ~8 ~8 ~6 ~8 ~8 ~7 stone_slab 0  
fill ~8 ~8 ~8 ~10 ~8 ~8 double_stone_slab 0 
setblock ~8 ~8 ~11 wool 8 
setblock ~8 ~8 ~54 wool 8  
fill ~8 ~8 ~55 ~8 ~8 ~56 double_stone_slab 0  
fill ~8 ~8 ~57 ~8 ~8 ~58 stone_slab 0  
fill ~8 ~8 ~59 ~12 ~8 ~59 double_stone_slab 0  
fill ~8 ~8 ~60 ~9 ~8 ~60 stone_slab 0 
setblock ~8 ~8 ~61 stone_slab 8  
fill ~9 ~8 ~3 ~10 ~8 ~3 stone_slab 0  
fill ~9 ~8 ~6 ~9 ~8 ~9 double_stone_slab 0 
setblock ~9 ~8 ~55 wool 8  
fill ~9 ~8 ~56 ~9 ~8 ~59 double_stone_slab 0  
fill ~9 ~8 ~61 ~10 ~8 ~61 stone_slab 0  
fill ~10 ~8 ~2 ~11 ~8 ~2 stone_slab 0  
fill ~10 ~8 ~4 ~10 ~14 ~4 double_stone_slab 0  
fill ~10 ~8 ~5 ~12 ~8 ~5 stone_slab 0 
setblock ~10 ~8 ~6 stone_slab 5 
setblock ~10 ~8 ~7 double_stone_slab 0 
setblock ~10 ~8 ~56 wool 8  
fill ~10 ~8 ~57 ~10 ~8 ~60 double_stone_slab 0  
fill ~10 ~8 ~62 ~11 ~8 ~62 stone_slab 0  
fill ~11 ~8 ~1 ~12 ~8 ~1 stone_slab 0  
fill ~11 ~8 ~3 ~11 ~10 ~3 double_stone_slab 0  
fill ~11 ~8 ~4 ~13 ~8 ~4 stone_slab 0 
setblock ~11 ~8 ~6 stone_slab 0 
setblock ~11 ~8 ~58 stone_slab 0 
setblock ~11 ~8 ~60 stone_slab 5  
fill ~11 ~8 ~61 ~11 ~10 ~61 double_stone_slab 0  
fill ~11 ~8 ~63 ~12 ~8 ~63 stone_slab 0  
fill ~12 ~8 ~0 ~14 ~8 ~0 stone_slab 0 
setblock ~12 ~8 ~2 double_stone_slab 0  
fill ~12 ~8 ~3 ~14 ~8 ~3 stone_slab 0  
fill ~12 ~8 ~60 ~13 ~8 ~60 stone_slab 0  
fill ~12 ~8 ~61 ~14 ~8 ~61 stone_slab 0  
fill ~12 ~8 ~62 ~12 ~10 ~62 double_stone_slab 0  
fill ~12 ~8 ~64 ~14 ~8 ~64 stone_slab 0 
setblock ~13 ~8 ~1 double_stone_slab 5  
fill ~13 ~8 ~2 ~15 ~8 ~2 stone_slab 0  
fill ~13 ~8 ~59 ~14 ~8 ~59 redstone_wire 0  
fill ~13 ~8 ~62 ~15 ~8 ~62 stone_slab 0  
fill ~13 ~8 ~63 ~14 ~8 ~63 double_stone_slab 0  
fill ~14 ~8 ~-1 ~16 ~8 ~-1 stone_slab 0  
fill ~14 ~8 ~1 ~14 ~10 ~1 double_stone_slab 0  
fill ~14 ~8 ~60 ~15 ~8 ~60 redstone_wire 0  
fill ~14 ~8 ~65 ~16 ~8 ~65 stone_slab 0  
fill ~15 ~8 ~0 ~16 ~8 ~0 double_stone_slab 0  
fill ~15 ~8 ~1 ~17 ~8 ~1 stone_slab 0  
fill ~15 ~8 ~61 ~16 ~8 ~61 redstone_wire 0 
setblock ~15 ~8 ~63 stone_slab 5  
fill ~15 ~8 ~64 ~16 ~8 ~64 double_stone_slab 0  
fill ~16 ~8 ~-2 ~18 ~8 ~-2 stone_slab 0 
setblock ~16 ~8 ~62 redstone_wire 0  
fill ~16 ~8 ~63 ~17 ~8 ~63 stone_slab 0  
fill ~16 ~8 ~66 ~17 ~8 ~66 stone_slab 0  
fill ~17 ~8 ~-1 ~18 ~8 ~-1 double_stone_slab 0  
fill ~17 ~8 ~0 ~19 ~8 ~0 stone_slab 0 
setblock ~17 ~8 ~62 unpowered_repeater 3  
fill ~17 ~8 ~64 ~19 ~8 ~64 stone_slab 0  
fill ~17 ~8 ~65 ~18 ~8 ~65 double_stone_slab 0  
fill ~18 ~8 ~-3 ~20 ~8 ~-3 stone_slab 0  
fill ~18 ~8 ~62 ~18 ~8 ~63 redstone_wire 0 
setblock ~18 ~8 ~66 stone_slab 5  
fill ~18 ~8 ~67 ~20 ~8 ~67 stone_slab 0  
fill ~19 ~8 ~-2 ~20 ~8 ~-2 double_stone_slab 0  
fill ~19 ~8 ~-1 ~22 ~8 ~-1 stone_slab 0  
fill ~19 ~8 ~49 ~20 ~8 ~49 stone 6  
fill ~19 ~8 ~63 ~20 ~8 ~63 redstone_wire 0  
fill ~19 ~8 ~65 ~22 ~8 ~65 stone_slab 0  
fill ~19 ~8 ~66 ~20 ~8 ~66 double_stone_slab 0  
fill ~20 ~8 ~-4 ~21 ~8 ~-4 stone_slab 0  
fill ~20 ~8 ~64 ~23 ~8 ~64 redstone_wire 0  
fill ~20 ~8 ~68 ~23 ~8 ~68 stone_slab 0  
fill ~21 ~8 ~-3 ~23 ~8 ~-3 double_stone_slab 0  
fill ~21 ~8 ~-2 ~26 ~8 ~-2 stone_slab 0  
fill ~21 ~8 ~66 ~26 ~8 ~66 stone_slab 0  
fill ~21 ~8 ~67 ~23 ~8 ~67 double_stone_slab 0  
fill ~22 ~8 ~-4 ~23 ~8 ~-4 stone_slab 5  
fill ~23 ~8 ~-5 ~26 ~8 ~-5 stone_slab 0 
setblock ~23 ~8 ~65 redstone_wire 0  
fill ~23 ~8 ~69 ~26 ~8 ~69 stone_slab 0  
fill ~24 ~8 ~-4 ~27 ~8 ~-4 double_stone_slab 0  
fill ~24 ~8 ~-3 ~26 ~8 ~-3 stone_slab 0 
setblock ~24 ~8 ~65 unpowered_repeater 3 
setblock ~24 ~8 ~67 stone_slab 0  
fill ~24 ~8 ~68 ~27 ~8 ~68 double_stone_slab 0  
fill ~25 ~8 ~65 ~26 ~8 ~65 redstone_wire 0 
setblock ~25 ~8 ~67 stone_slab 5  
fill ~26 ~8 ~64 ~27 ~8 ~64 redstone_wire 0 
setblock ~26 ~8 ~67 stone_slab 0 
setblock ~27 ~8 ~-5 double_stone_slab 0  
fill ~27 ~8 ~-3 ~27 ~10 ~-3 double_stone_slab 0 
setblock ~27 ~8 ~-2 stone_slab 5  
fill ~27 ~8 ~-1 ~27 ~14 ~-1 double_stone_slab 0  
fill ~27 ~8 ~63 ~28 ~8 ~63 redstone_wire 0  
fill ~27 ~8 ~65 ~27 ~14 ~65 double_stone_slab 0  
fill ~27 ~8 ~66 ~27 ~14 ~66 double_stone_slab 0  
fill ~27 ~8 ~67 ~27 ~14 ~67 double_stone_slab 0 
setblock ~27 ~8 ~69 double_stone_slab 0  
fill ~28 ~8 ~0 ~29 ~8 ~0 double_stone_slab 0  
fill ~28 ~8 ~1 ~28 ~8 ~10 stone_slab 8  
fill ~28 ~8 ~19 ~28 ~8 ~23 stone_slab 8  
fill ~28 ~8 ~41 ~28 ~8 ~62 stone_slab 8  
fill ~28 ~8 ~64 ~29 ~8 ~64 double_stone_slab 0  
fill ~29 ~8 ~-2 ~30 ~8 ~-2 double_stone_slab 0  
fill ~29 ~8 ~-1 ~30 ~8 ~-1 double_stone_slab 0  
fill ~29 ~8 ~1 ~29 ~8 ~15 stone_slab 0  
fill ~29 ~8 ~17 ~29 ~8 ~22 stone_slab 0  
fill ~29 ~8 ~23 ~29 ~9 ~23 double_stone_slab 0  
fill ~29 ~8 ~41 ~30 ~8 ~41 double_stone_slab 0  
fill ~29 ~8 ~42 ~29 ~8 ~62 stone_slab 0  
fill ~29 ~8 ~63 ~29 ~9 ~63 double_stone_slab 0  
fill ~29 ~8 ~65 ~30 ~8 ~65 double_stone_slab 0  
fill ~29 ~8 ~66 ~30 ~8 ~66 double_stone_slab 0  
fill ~30 ~8 ~-4 ~30 ~9 ~-4 double_stone_slab 0  
fill ~30 ~8 ~-3 ~30 ~9 ~-3 double_stone_slab 0  
fill ~30 ~8 ~59 ~38 ~8 ~59 concrete 7 
setblock ~30 ~8 ~63 unpowered_repeater 3  
fill ~30 ~8 ~67 ~30 ~9 ~67 double_stone_slab 0  
fill ~30 ~8 ~68 ~30 ~9 ~68 double_stone_slab 0 
setblock ~31 ~8 ~-4 stone_brick_stairs 1  
fill ~31 ~8 ~-3 ~37 ~8 ~-3 stained_hardened_clay 9  
fill ~31 ~8 ~22 ~37 ~8 ~22 double_stone_slab 0  
fill ~31 ~8 ~42 ~37 ~8 ~42 double_stone_slab 0  
fill ~31 ~8 ~63 ~38 ~8 ~63 redstone_wire 0  
fill ~31 ~8 ~67 ~33 ~8 ~67 stained_hardened_clay 9  
fill ~32 ~8 ~48 ~35 ~8 ~48 concrete 7  
fill ~32 ~8 ~49 ~35 ~8 ~49 concrete 7  
fill ~32 ~8 ~50 ~35 ~8 ~50 concrete 7  
fill ~32 ~8 ~51 ~35 ~8 ~51 concrete 7  
fill ~32 ~8 ~52 ~35 ~8 ~52 concrete 7  
fill ~32 ~8 ~53 ~35 ~8 ~53 concrete 7  
fill ~32 ~8 ~54 ~35 ~8 ~54 concrete 7  
fill ~32 ~8 ~55 ~35 ~8 ~55 concrete 7  
fill ~32 ~8 ~56 ~35 ~8 ~56 concrete 7  
fill ~32 ~8 ~57 ~35 ~8 ~57 concrete 7  
fill ~32 ~8 ~58 ~35 ~8 ~58 concrete 7  
fill ~32 ~8 ~68 ~32 ~9 ~68 nether_brick_fence 0 
setblock ~33 ~8 ~-4 iron_bars 0  
fill ~33 ~8 ~31 ~35 ~8 ~31 wool 8 
setblock ~33 ~8 ~68 stone_button 3 
setblock ~34 ~8 ~-4 stone_brick_stairs 2 
setblock ~34 ~8 ~67 dispenser 3  
fill ~35 ~8 ~67 ~37 ~8 ~67 stained_hardened_clay 9 
setblock ~36 ~8 ~-4 lever 4  
fill ~36 ~8 ~68 ~36 ~9 ~68 nether_brick_fence 0  
fill ~38 ~8 ~-4 ~38 ~9 ~-4 double_stone_slab 0  
fill ~38 ~8 ~-3 ~38 ~9 ~-3 double_stone_slab 0  
fill ~38 ~8 ~-2 ~39 ~8 ~-2 double_stone_slab 0  
fill ~38 ~8 ~-1 ~39 ~8 ~-1 double_stone_slab 0  
fill ~38 ~8 ~41 ~39 ~8 ~41 double_stone_slab 0  
fill ~38 ~8 ~65 ~39 ~8 ~65 double_stone_slab 0  
fill ~38 ~8 ~66 ~39 ~8 ~66 double_stone_slab 0  
fill ~38 ~8 ~67 ~38 ~9 ~67 double_stone_slab 0  
fill ~38 ~8 ~68 ~38 ~9 ~68 double_stone_slab 0  
fill ~39 ~8 ~0 ~40 ~8 ~0 double_stone_slab 0  
fill ~39 ~8 ~1 ~39 ~8 ~8 stone_slab 0  
fill ~39 ~8 ~10 ~39 ~8 ~22 stone_slab 0  
fill ~39 ~8 ~42 ~39 ~8 ~62 stone_slab 0  
fill ~39 ~8 ~63 ~39 ~8 ~66 double_stone_slab 0  
fill ~40 ~8 ~1 ~40 ~7 ~1 stone_slab 8  
fill ~40 ~8 ~2 ~40 ~7 ~2 stone_slab 8  
fill ~40 ~8 ~3 ~40 ~8 ~1 stone_slab 8  
fill ~40 ~8 ~11 ~40 ~8 ~17 stone_slab 8  
fill ~40 ~8 ~19 ~40 ~8 ~21 sea_lantern 0  
fill ~40 ~8 ~22 ~40 ~8 ~23 stone_slab 8  
fill ~40 ~8 ~41 ~40 ~8 ~62 stone_slab 8 
setblock ~40 ~8 ~63 unpowered_repeater 3  
fill ~40 ~8 ~64 ~40 ~12 ~64 double_stone_slab 0  
fill ~41 ~8 ~-5 ~41 ~8 ~-1 double_stone_slab 0  
fill ~41 ~8 ~18 ~41 ~9 ~18 concrete 7  
fill ~41 ~8 ~19 ~41 ~8 ~21 stained_glass 5  
fill ~41 ~8 ~22 ~41 ~9 ~22 concrete 7  
fill ~41 ~8 ~63 ~42 ~8 ~63 redstone_wire 0  
fill ~41 ~8 ~65 ~41 ~14 ~65 double_stone_slab 0  
fill ~41 ~8 ~66 ~41 ~14 ~66 double_stone_slab 0  
fill ~41 ~8 ~67 ~41 ~14 ~67 double_stone_slab 0  
fill ~41 ~8 ~68 ~44 ~8 ~68 double_stone_slab 0  
fill ~41 ~8 ~69 ~41 ~8 ~65 double_stone_slab 0  
fill ~42 ~8 ~-5 ~45 ~8 ~-5 stone_slab 0  
fill ~42 ~8 ~-4 ~44 ~8 ~-4 double_stone_slab 0  
fill ~42 ~8 ~-3 ~44 ~8 ~-3 stone_slab 0  
fill ~42 ~8 ~-2 ~47 ~8 ~-2 stone_slab 0  
fill ~42 ~8 ~17 ~44 ~8 ~17 sea_lantern 0  
fill ~42 ~8 ~18 ~44 ~8 ~18 stained_glass 5  
fill ~42 ~8 ~20 ~43 ~8 ~20 nether_brick_fence 0  
fill ~42 ~8 ~22 ~44 ~8 ~22 stained_glass 5  
fill ~42 ~8 ~23 ~44 ~8 ~23 sea_lantern 0 
setblock ~42 ~8 ~64 unpowered_repeater 0  
fill ~42 ~8 ~65 ~45 ~8 ~65 redstone_wire 0  
fill ~42 ~8 ~66 ~47 ~8 ~66 stone_slab 0  
fill ~42 ~8 ~67 ~44 ~8 ~67 stone_slab 0  
fill ~42 ~8 ~69 ~45 ~8 ~69 stone_slab 0 
setblock ~43 ~8 ~19 anvil 2  
fill ~43 ~8 ~21 ~44 ~8 ~21 nether_brick_fence 0  
fill ~45 ~8 ~-4 ~48 ~8 ~-4 stone_slab 0 
setblock ~45 ~8 ~-3 double_stone_slab 5  
fill ~45 ~8 ~18 ~45 ~9 ~18 concrete 7  
fill ~45 ~8 ~19 ~45 ~8 ~21 stained_glass 5  
fill ~45 ~8 ~22 ~45 ~9 ~22 concrete 7  
fill ~45 ~8 ~64 ~47 ~8 ~64 redstone_wire 0  
fill ~45 ~8 ~67 ~47 ~8 ~67 double_stone_slab 0  
fill ~45 ~8 ~68 ~48 ~8 ~68 stone_slab 0  
fill ~46 ~8 ~-3 ~47 ~8 ~-3 double_stone_slab 0  
fill ~46 ~8 ~-1 ~49 ~8 ~-1 stone_slab 0  
fill ~46 ~8 ~19 ~47 ~8 ~19 sea_lantern 0  
fill ~46 ~8 ~20 ~47 ~8 ~20 sea_lantern 0  
fill ~46 ~8 ~21 ~47 ~8 ~21 sea_lantern 0  
fill ~46 ~8 ~26 ~46 ~8 ~27 concrete 15  
fill ~46 ~8 ~65 ~49 ~8 ~65 stone_slab 0  
fill ~47 ~8 ~16 ~47 ~8 ~17 stone_slab 8  
fill ~47 ~8 ~22 ~47 ~8 ~23 stone_slab 8  
fill ~47 ~8 ~27 ~48 ~8 ~27 stained_glass 5  
fill ~47 ~8 ~28 ~49 ~8 ~28 concrete 15  
fill ~47 ~8 ~62 ~47 ~8 ~64 redstone_wire 0  
fill ~48 ~8 ~-3 ~50 ~8 ~-3 stone_slab 0  
fill ~48 ~8 ~-2 ~49 ~8 ~-2 double_stone_slab 0  
fill ~48 ~8 ~18 ~48 ~9 ~18 concrete 7  
fill ~48 ~8 ~19 ~48 ~8 ~21 stained_glass 5  
fill ~48 ~8 ~22 ~48 ~9 ~22 concrete 7 
setblock ~48 ~8 ~26 concrete 15 
setblock ~48 ~8 ~62 unpowered_repeater 3  
fill ~48 ~8 ~66 ~49 ~8 ~66 double_stone_slab 0  
fill ~48 ~8 ~67 ~50 ~8 ~67 stone_slab 0  
fill ~49 ~8 ~0 ~51 ~8 ~0 stone_slab 0  
fill ~49 ~8 ~17 ~51 ~8 ~17 sea_lantern 0  
fill ~49 ~8 ~18 ~51 ~8 ~18 stained_glass 5  
fill ~49 ~8 ~20 ~50 ~8 ~20 nether_brick_fence 0  
fill ~49 ~8 ~22 ~51 ~8 ~22 stained_glass 5  
fill ~49 ~8 ~23 ~52 ~8 ~23 sea_lantern 0 
setblock ~49 ~8 ~27 concrete 15  
fill ~49 ~8 ~62 ~50 ~8 ~62 redstone_wire 0  
fill ~49 ~8 ~64 ~51 ~8 ~64 stone_slab 0  
fill ~50 ~8 ~-2 ~52 ~8 ~-2 stone_slab 0  
fill ~50 ~8 ~-1 ~51 ~8 ~-1 double_stone_slab 0  
fill ~50 ~8 ~61 ~52 ~8 ~61 redstone_wire 0  
fill ~50 ~8 ~65 ~67 ~8 ~65 double_stone_slab 0  
fill ~50 ~8 ~66 ~52 ~8 ~66 stone_slab 0  
fill ~51 ~8 ~1 ~53 ~8 ~1 stone_slab 0  
fill ~51 ~8 ~20 ~51 ~8 ~21 anvil 0  
fill ~51 ~8 ~63 ~53 ~8 ~63 stone_slab 0  
fill ~52 ~8 ~-1 ~54 ~8 ~-1 stone_slab 0  
fill ~52 ~8 ~0 ~53 ~8 ~0 double_stone_slab 0  
fill ~52 ~8 ~18 ~52 ~9 ~18 concrete 7  
fill ~52 ~8 ~19 ~52 ~8 ~21 stained_glass 5  
fill ~52 ~8 ~22 ~53 ~8 ~22 concrete 7 
setblock ~52 ~8 ~24 sea_lantern 0  
fill ~52 ~8 ~60 ~53 ~8 ~60 redstone_wire 0  
fill ~52 ~8 ~64 ~53 ~8 ~64 double_stone_slab 0  
fill ~53 ~8 ~2 ~55 ~8 ~2 stone_slab 0  
fill ~53 ~8 ~18 ~53 ~8 ~21 sea_lantern 0  
fill ~53 ~8 ~23 ~53 ~8 ~24 stained_glass 5  
fill ~53 ~8 ~25 ~53 ~9 ~25 concrete 7  
fill ~53 ~8 ~59 ~55 ~8 ~59 redstone_wire 0  
fill ~53 ~8 ~62 ~55 ~8 ~62 stone_slab 0 
setblock ~54 ~8 ~0 stone_slab 5  
fill ~54 ~8 ~1 ~55 ~8 ~1 double_stone_slab 0  
fill ~54 ~8 ~3 ~56 ~8 ~3 stone_slab 0  
fill ~54 ~8 ~21 ~56 ~8 ~21 sea_lantern 0  
fill ~54 ~8 ~22 ~56 ~8 ~22 stained_glass 5  
fill ~54 ~8 ~24 ~55 ~8 ~24 nether_brick_fence 0  
fill ~54 ~8 ~25 ~56 ~8 ~25 stained_glass 5  
fill ~54 ~8 ~26 ~56 ~8 ~26 sea_lantern 0  
fill ~54 ~8 ~61 ~56 ~8 ~61 stone_slab 0  
fill ~54 ~8 ~63 ~67 ~8 ~63 double_stone_slab 0 
setblock ~54 ~8 ~64 wool 2  
fill ~55 ~8 ~0 ~56 ~8 ~0 stone_slab 0  
fill ~55 ~8 ~4 ~57 ~8 ~4 stone_slab 0 
setblock ~55 ~8 ~18 sea_lantern 0 
setblock ~55 ~8 ~23 nether_brick_fence 0  
fill ~55 ~8 ~56 ~58 ~8 ~56 redstone_wire 0  
fill ~55 ~8 ~57 ~55 ~8 ~56 redstone_wire 0 
setblock ~55 ~8 ~58 unpowered_repeater 2  
fill ~55 ~8 ~60 ~57 ~8 ~60 stone_slab 0  
fill ~55 ~8 ~64 ~67 ~8 ~64 double_stone_slab 0  
fill ~56 ~8 ~1 ~57 ~8 ~1 stone_slab 0  
fill ~56 ~8 ~2 ~56 ~14 ~2 double_stone_slab 0  
fill ~56 ~8 ~5 ~58 ~8 ~5 stone_slab 0  
fill ~56 ~8 ~23 ~56 ~8 ~24 anvil 0  
fill ~56 ~8 ~59 ~58 ~8 ~59 stone_slab 0 
setblock ~56 ~8 ~62 double_stone_slab 0  
fill ~57 ~8 ~2 ~58 ~8 ~2 stone_slab 0  
fill ~57 ~8 ~3 ~57 ~14 ~3 double_stone_slab 0  
fill ~57 ~8 ~6 ~59 ~8 ~6 stone_slab 0 
setblock ~57 ~8 ~18 sea_lantern 0  
fill ~57 ~8 ~22 ~57 ~9 ~22 concrete 7  
fill ~57 ~8 ~23 ~57 ~8 ~24 stained_glass 5  
fill ~57 ~8 ~25 ~57 ~9 ~25 concrete 7  
fill ~57 ~8 ~58 ~60 ~8 ~58 stone_slab 0 
setblock ~57 ~8 ~61 stone_slab 5  
fill ~57 ~8 ~62 ~58 ~8 ~62 stone_slab 0  
fill ~58 ~8 ~3 ~59 ~8 ~3 stone_slab 0  
fill ~58 ~8 ~4 ~58 ~14 ~4 double_stone_slab 0 
setblock ~58 ~8 ~7 stone_slab 0  
fill ~58 ~8 ~23 ~58 ~8 ~24 sea_lantern 0  
fill ~58 ~8 ~57 ~60 ~8 ~57 stone_slab 0  
fill ~58 ~8 ~60 ~58 ~10 ~60 double_stone_slab 0  
fill ~58 ~8 ~61 ~59 ~8 ~61 stone_slab 0  
fill ~59 ~8 ~4 ~60 ~8 ~4 stone_slab 0  
fill ~59 ~8 ~5 ~60 ~8 ~5 double_stone_slab 0  
fill ~59 ~8 ~7 ~60 ~8 ~7 stone_slab 5  
fill ~59 ~8 ~8 ~61 ~8 ~8 stone_slab 0 
setblock ~59 ~8 ~18 sea_lantern 0 
setblock ~59 ~8 ~19 redstone_wire 15 
setblock ~59 ~8 ~20 powered_repeater 4 
setblock ~59 ~8 ~21 redstone_wire 15 
setblock ~59 ~8 ~22 powered_repeater 4 
setblock ~59 ~8 ~23 redstone_wire 15 
setblock ~59 ~8 ~24 powered_repeater 4 
setblock ~59 ~8 ~25 redstone_wire 13 
setblock ~59 ~8 ~26 redstone_wire 14 
setblock ~59 ~8 ~27 redstone_wire 15  
fill ~59 ~8 ~29 ~60 ~8 ~29 concrete 7  
fill ~59 ~8 ~56 ~62 ~8 ~56 double_stone_slab 0  
fill ~59 ~8 ~59 ~60 ~8 ~59 double_stone_slab 0  
fill ~59 ~8 ~60 ~60 ~8 ~60 stone_slab 0 
setblock ~60 ~8 ~6 stone_slab 5  
fill ~60 ~8 ~9 ~62 ~8 ~9 stone_slab 0 
setblock ~60 ~8 ~19 powered_repeater 1 
setblock ~60 ~8 ~21 powered_repeater 1 
setblock ~60 ~8 ~23 powered_repeater 1 
setblock ~60 ~8 ~25 powered_repeater 1 
setblock ~60 ~8 ~27 powered_repeater 3 
setblock ~60 ~8 ~28 concrete 7  
fill ~60 ~8 ~55 ~62 ~8 ~55 stone_slab 0 
setblock ~61 ~8 ~5 stone_slab 0  
fill ~61 ~8 ~6 ~61 ~13 ~6 double_stone_slab 0  
fill ~61 ~8 ~7 ~62 ~8 ~7 double_stone_slab 0  
fill ~61 ~8 ~10 ~63 ~8 ~10 stone_slab 0 
setblock ~61 ~8 ~19 sticky_piston 9 
setblock ~61 ~8 ~21 sticky_piston 9 
setblock ~61 ~8 ~23 sticky_piston 9 
setblock ~61 ~8 ~25 sticky_piston 9 
setblock ~61 ~8 ~27 redstone_wire 10 
setblock ~61 ~8 ~28 redstone_wire 11  
fill ~61 ~8 ~36 ~70 ~8 ~36 double_stone_slab 0  
fill ~61 ~8 ~54 ~63 ~8 ~54 stone_slab 0  
fill ~61 ~8 ~57 ~61 ~13 ~57 double_stone_slab 0  
fill ~61 ~8 ~58 ~61 ~10 ~58 double_stone_slab 0  
fill ~61 ~8 ~59 ~61 ~9 ~59 stone_slab 0 
setblock ~62 ~8 ~6 stone_slab 0 
setblock ~62 ~8 ~8 double_stone_slab 0  
fill ~62 ~8 ~11 ~64 ~8 ~11 stone_slab 0  
fill ~62 ~8 ~28 ~68 ~8 ~28 double_stone_slab 0  
fill ~62 ~8 ~53 ~64 ~8 ~53 stone_slab 0  
fill ~62 ~8 ~57 ~63 ~8 ~57 stone_slab 0  
fill ~62 ~8 ~58 ~62 ~8 ~57 stone_slab 0  
fill ~63 ~8 ~7 ~63 ~8 ~8 stone_slab 0 
setblock ~63 ~8 ~9 double_stone_slab 0  
fill ~63 ~8 ~12 ~64 ~8 ~12 stone_slab 0  
fill ~63 ~8 ~52 ~64 ~8 ~52 stone_slab 0 
setblock ~63 ~8 ~55 double_stone_slab 0  
fill ~63 ~8 ~56 ~64 ~8 ~56 stone_slab 0  
fill ~64 ~8 ~8 ~64 ~8 ~9 stone_slab 0 
setblock ~64 ~8 ~10 double_stone_slab 0  
fill ~64 ~8 ~13 ~65 ~8 ~13 stone_slab 0  
fill ~64 ~8 ~51 ~65 ~8 ~51 stone_slab 0 
setblock ~64 ~8 ~54 double_stone_slab 5  
fill ~64 ~8 ~55 ~65 ~8 ~55 stone_slab 0  
fill ~65 ~8 ~9 ~65 ~8 ~10 stone_slab 0  
fill ~65 ~8 ~11 ~65 ~8 ~12 double_stone_slab 0 
setblock ~65 ~8 ~14 stone_slab 0 
setblock ~65 ~8 ~29 stone_brick_stairs 6 
setblock ~65 ~8 ~30 stone_brick_stairs 3 
setblock ~65 ~8 ~34 stone_brick_stairs 2 
setblock ~65 ~8 ~35 stone_brick_stairs 7 
setblock ~65 ~8 ~50 stone_slab 0  
fill ~65 ~8 ~52 ~65 ~14 ~52 double_stone_slab 0  
fill ~65 ~8 ~53 ~65 ~14 ~53 double_stone_slab 0  
fill ~65 ~8 ~54 ~66 ~8 ~54 stone_slab 0 
setblock ~66 ~8 ~10 stone_slab 0 
setblock ~66 ~8 ~11 stone_slab 5  
fill ~66 ~8 ~12 ~67 ~8 ~12 stone_slab 0  
fill ~66 ~8 ~13 ~66 ~11 ~13 double_stone_slab 0  
fill ~66 ~8 ~14 ~66 ~9 ~14 double_stone_slab 0  
fill ~66 ~8 ~15 ~66 ~8 ~16 stone_slab 0  
fill ~66 ~8 ~48 ~66 ~8 ~49 stone_slab 0  
fill ~66 ~8 ~50 ~66 ~8 ~51 double_stone_slab 0  
fill ~66 ~8 ~52 ~67 ~8 ~52 stone_slab 0  
fill ~66 ~8 ~53 ~66 ~8 ~52 stone_slab 0  
fill ~67 ~8 ~13 ~67 ~8 ~14 stone_slab 0  
fill ~67 ~8 ~15 ~67 ~8 ~16 double_stone_slab 0  
fill ~67 ~8 ~17 ~67 ~8 ~18 stone_slab 0  
fill ~67 ~8 ~46 ~67 ~8 ~47 stone_slab 5 
setblock ~67 ~8 ~48 double_stone_slab 5 
setblock ~67 ~8 ~49 double_stone_slab 0  
fill ~67 ~8 ~50 ~68 ~8 ~50 stone_slab 0  
fill ~67 ~8 ~51 ~67 ~8 ~50 stone_slab 0  
fill ~68 ~8 ~14 ~68 ~8 ~16 stone_slab 0  
fill ~68 ~8 ~17 ~68 ~8 ~18 double_stone_slab 0  
fill ~68 ~8 ~19 ~68 ~8 ~21 stone_slab 0  
fill ~68 ~8 ~26 ~70 ~8 ~26 stone_slab 0  
fill ~68 ~8 ~43 ~68 ~8 ~45 stone_slab 0  
fill ~68 ~8 ~46 ~68 ~8 ~47 double_stone_slab 0  
fill ~68 ~8 ~48 ~69 ~8 ~48 stone_slab 0  
fill ~68 ~8 ~49 ~68 ~8 ~48 stone_slab 0  
fill ~68 ~8 ~63 ~68 ~8 ~65 stone_slab 8 
setblock ~69 ~8 ~14 stone_button 0  
fill ~69 ~8 ~16 ~69 ~8 ~18 stone_slab 0 
setblock ~69 ~8 ~19 double_stone_slab 0 
setblock ~69 ~8 ~20 double_stone_slab 5 
setblock ~69 ~8 ~21 double_stone_slab 0  
fill ~69 ~8 ~22 ~69 ~8 ~27 stone_slab 0  
fill ~69 ~8 ~34 ~69 ~9 ~34 stained_hardened_clay 9  
fill ~69 ~8 ~35 ~69 ~14 ~35 stained_hardened_clay 9  
fill ~69 ~8 ~37 ~69 ~8 ~42 stone_slab 0  
fill ~69 ~8 ~43 ~69 ~8 ~45 double_stone_slab 0  
fill ~69 ~8 ~46 ~70 ~8 ~46 stone_slab 0  
fill ~69 ~8 ~47 ~69 ~8 ~46 stone_slab 0 
setblock ~69 ~8 ~64 stone_slab 8  
fill ~70 ~8 ~18 ~70 ~8 ~21 stone_slab 0  
fill ~70 ~8 ~22 ~70 ~14 ~22 double_stone_slab 0  
fill ~70 ~8 ~23 ~70 ~14 ~23 double_stone_slab 0  
fill ~70 ~8 ~24 ~70 ~13 ~24 double_stone_slab 0  
fill ~70 ~8 ~25 ~70 ~14 ~25 double_stone_slab 0 
setblock ~70 ~8 ~27 stone_slab 0  
fill ~70 ~8 ~31 ~70 ~8 ~32 stained_hardened_clay 9  
fill ~70 ~8 ~33 ~70 ~11 ~33 double_stone_slab 0  
fill ~70 ~8 ~37 ~71 ~8 ~37 double_stone_slab 0  
fill ~70 ~8 ~38 ~70 ~14 ~38 double_stone_slab 0  
fill ~70 ~8 ~39 ~70 ~14 ~39 double_stone_slab 0  
fill ~70 ~8 ~40 ~70 ~14 ~40 double_stone_slab 0  
fill ~70 ~8 ~41 ~70 ~14 ~41 double_stone_slab 0  
fill ~70 ~8 ~42 ~70 ~13 ~42 double_stone_slab 0  
fill ~70 ~8 ~43 ~71 ~8 ~43 stone_slab 0 
setblock ~70 ~8 ~44 stone_slab 5 
setblock ~70 ~8 ~45 stone_slab 0 
setblock ~70 ~8 ~52 stone_button 0  
fill ~71 ~8 ~21 ~71 ~8 ~24 stone_slab 0 
setblock ~71 ~8 ~25 stone_slab 5  
fill ~71 ~8 ~26 ~71 ~14 ~26 double_stone_slab 0  
fill ~71 ~8 ~27 ~71 ~14 ~27 double_stone_slab 0 
setblock ~71 ~8 ~29 stone_brick_stairs 1  
fill ~71 ~8 ~31 ~71 ~9 ~31 iron_bars 0 
setblock ~71 ~8 ~34 stone_button 1 
setblock ~71 ~8 ~38 double_stone_slab 5  
fill ~71 ~8 ~39 ~72 ~8 ~39 stone_slab 0  
fill ~71 ~8 ~40 ~71 ~8 ~43 stone_slab 0  
fill ~72 ~8 ~25 ~72 ~8 ~27 stone_slab 0  
fill ~72 ~8 ~37 ~72 ~8 ~39 stone_slab 0 
setblock ~73 ~8 ~44 stone_button 0 
setblock ~77 ~8 ~13 stone_button 0 
setblock ~77 ~8 ~44 stone_button 0 
setblock ~78 ~8 ~14 stone_button 0  
fill ~78 ~8 ~28 ~83 ~8 ~28 stone_slab 0  
fill ~78 ~8 ~36 ~83 ~8 ~36 stone_slab 0 
setblock ~80 ~8 ~49 stone_button 0 
setblock ~82 ~8 ~18 stone_button 0 
setblock ~82 ~8 ~24 stone_button 0 
setblock ~82 ~8 ~47 stone_button 0  
fill ~83 ~8 ~18 ~83 ~8 ~19 stone_slab 13 
setblock ~84 ~8 ~19 lever 8 
setblock ~84 ~8 ~28 stone_brick_stairs 5  
fill ~84 ~8 ~29 ~84 ~8 ~35 double_stone_slab 0 
setblock ~84 ~8 ~36 stone_brick_stairs 5 
setblock ~85 ~8 ~30 stone_button 1  
fill ~85 ~8 ~32 ~85 ~8 ~33 lever 9 
setblock ~86 ~8 ~46 stone_button 0 
setblock ~88 ~8 ~24 stone_button 0 
setblock ~88 ~8 ~43 stone_button 0 
setblock ~90 ~8 ~39 stone_button 0  
fill ~96 ~8 ~40 ~98 ~8 ~40 lever 7  
fill ~96 ~8 ~41 ~98 ~8 ~41 stone_slab 13  
fill ~96 ~8 ~42 ~98 ~8 ~42 lever 15 
setblock ~97 ~8 ~38 stone_button 0 
setblock ~100 ~8 ~22 stone_button 0 
setblock ~100 ~8 ~38 stone_button 0 
setblock ~101 ~8 ~25 stone_button 0 
setblock ~101 ~8 ~40 stone_button 0 
setblock ~106 ~8 ~25 stone_slab 13 
setblock ~106 ~8 ~38 stone_button 0 
setblock ~107 ~8 ~25 lever 8  
fill ~-4 ~9 ~26 ~-4 ~13 ~26 iron_bars 0  
fill ~-4 ~9 ~27 ~-4 ~13 ~27 iron_bars 0  
fill ~-4 ~9 ~28 ~-4 ~13 ~28 iron_bars 0  
fill ~-4 ~9 ~29 ~-4 ~13 ~29 iron_bars 0  
fill ~-4 ~9 ~30 ~-4 ~13 ~30 iron_bars 0  
fill ~-4 ~9 ~31 ~-4 ~13 ~31 iron_bars 0  
fill ~-4 ~9 ~32 ~-4 ~13 ~32 iron_bars 0  
fill ~-4 ~9 ~33 ~-4 ~13 ~33 iron_bars 0  
fill ~-4 ~9 ~34 ~-4 ~13 ~34 iron_bars 0  
fill ~-4 ~9 ~35 ~-4 ~13 ~35 iron_bars 0  
fill ~-4 ~9 ~36 ~-4 ~13 ~36 iron_bars 0  
fill ~-4 ~9 ~37 ~-4 ~13 ~37 iron_bars 0  
fill ~-4 ~9 ~38 ~-4 ~13 ~38 iron_bars 0  
fill ~-3 ~9 ~22 ~-3 ~13 ~22 iron_bars 0  
fill ~-3 ~9 ~23 ~-3 ~13 ~23 iron_bars 0  
fill ~-3 ~9 ~24 ~-3 ~13 ~24 iron_bars 0  
fill ~-3 ~9 ~25 ~-3 ~13 ~25 iron_bars 0  
fill ~-3 ~9 ~26 ~-3 ~13 ~26 stained_glass 11  
fill ~-3 ~9 ~27 ~-3 ~13 ~27 stained_glass 11  
fill ~-3 ~9 ~28 ~-3 ~13 ~28 stained_glass 11  
fill ~-3 ~9 ~29 ~-3 ~13 ~29 stained_glass 11  
fill ~-3 ~9 ~30 ~-3 ~13 ~30 stained_glass 11  
fill ~-3 ~9 ~31 ~-3 ~13 ~31 stained_glass 11  
fill ~-3 ~9 ~32 ~-3 ~13 ~32 stained_glass 11  
fill ~-3 ~9 ~33 ~-3 ~13 ~33 stained_glass 11  
fill ~-3 ~9 ~34 ~-3 ~13 ~34 stained_glass 11  
fill ~-3 ~9 ~35 ~-3 ~13 ~35 stained_glass 11  
fill ~-3 ~9 ~36 ~-3 ~13 ~36 stained_glass 11  
fill ~-3 ~9 ~37 ~-3 ~13 ~37 stained_glass 11  
