fill ~1 ~-1 ~1 ~20 ~-1 ~1 sand 0  
fill ~1 ~-1 ~2 ~2 ~-1 ~2 sand 0  
fill ~1 ~-1 ~3 ~1 ~-1 ~3 sand 0  
fill ~1 ~-1 ~4 ~1 ~-1 ~4 sand 0  
fill ~1 ~-1 ~5 ~1 ~-1 ~5 sand 0  
fill ~1 ~-1 ~6 ~1 ~-1 ~6 sand 0  
fill ~1 ~-1 ~7 ~1 ~-1 ~7 sand 0  
fill ~1 ~-1 ~8 ~1 ~-1 ~8 sand 0  
fill ~1 ~-1 ~9 ~1 ~-1 ~9 sand 0  
fill ~1 ~-1 ~10 ~1 ~-1 ~10 sand 0  
fill ~1 ~-1 ~11 ~2 ~-1 ~11 sand 0  
fill ~1 ~-1 ~12 ~2 ~-1 ~12 sand 0  
fill ~1 ~-1 ~13 ~2 ~-1 ~13 sand 0  
fill ~1 ~-1 ~14 ~20 ~-1 ~14 sand 0  
fill ~1 ~-1 ~15 ~20 ~-1 ~15 sand 0  
fill ~2 ~-1 ~3 ~2 ~-1 ~10 sandstone 2  
fill ~3 ~-1 ~2 ~7 ~-1 ~2 sandstone 2  
fill ~3 ~-1 ~4 ~3 ~-1 ~5 chest 5  
fill ~3 ~-1 ~7 ~3 ~-1 ~8 chest 5  
fill ~3 ~-1 ~10 ~5 ~-1 ~10 wooden_slab 2  
fill ~3 ~-1 ~11 ~7 ~-1 ~11 planks 0  
fill ~3 ~-1 ~12 ~13 ~-1 ~12 planks 0  
fill ~3 ~-1 ~13 ~13 ~-1 ~13 planks 0  
fill ~4 ~-1 ~3 ~5 ~-1 ~3 chest 3  
fill ~6 ~-1 ~8 ~7 ~-1 ~8 fence 0  
fill ~6 ~-1 ~9 ~7 ~-1 ~9 fence 0  
fill ~6 ~-1 ~10 ~7 ~-1 ~10 planks 0  
fill ~7 ~-1 ~3 ~7 ~-1 ~4 chest 4  
fill ~7 ~-1 ~6 ~7 ~-1 ~7 chest 4  
fill ~8 ~-1 ~2 ~20 ~-1 ~2 sand 0  
fill ~8 ~-1 ~3 ~8 ~-1 ~9 sandstone 2  
fill ~8 ~-1 ~10 ~11 ~-1 ~10 sand 0  
fill ~8 ~-1 ~11 ~11 ~-1 ~11 sand 0  
fill ~9 ~-1 ~3 ~16 ~-1 ~3 sand 0 
setblock ~9 ~-1 ~4 glowstone 0  
fill ~9 ~-1 ~5 ~16 ~-1 ~5 sand 0 
setblock ~9 ~-1 ~6 glowstone 0  
fill ~9 ~-1 ~7 ~14 ~-1 ~7 sand 0  
fill ~9 ~-1 ~8 ~12 ~-1 ~8 sand 0  
fill ~9 ~-1 ~9 ~11 ~-1 ~9 sand 0  
fill ~10 ~-1 ~4 ~16 ~-1 ~4 sand 0  
fill ~10 ~-1 ~6 ~15 ~-1 ~6 sand 0  
fill ~12 ~-1 ~9 ~13 ~-1 ~9 sandstone 2  
fill ~12 ~-1 ~10 ~12 ~-1 ~9 sandstone 2 
setblock ~12 ~-1 ~11 planks 0  
fill ~13 ~-1 ~8 ~15 ~-1 ~8 sandstone 2  
fill ~13 ~-1 ~10 ~18 ~-1 ~10 sand 0  
fill ~13 ~-1 ~11 ~18 ~-1 ~11 sand 0  
fill ~14 ~-1 ~9 ~15 ~-1 ~9 sand 0  
fill ~14 ~-1 ~12 ~18 ~-1 ~12 sand 0  
fill ~14 ~-1 ~13 ~20 ~-1 ~13 sand 0  
fill ~15 ~-1 ~7 ~16 ~-1 ~7 sandstone 2  
fill ~16 ~-1 ~6 ~17 ~-1 ~6 sandstone 2  
fill ~16 ~-1 ~8 ~20 ~-1 ~8 sand 0  
fill ~16 ~-1 ~9 ~19 ~-1 ~9 water 0  
fill ~17 ~-1 ~3 ~18 ~-1 ~3 sandstone 2  
fill ~17 ~-1 ~4 ~19 ~-1 ~4 sandstone 2  
fill ~17 ~-1 ~5 ~18 ~-1 ~5 sandstone 2  
fill ~17 ~-1 ~7 ~20 ~-1 ~7 sand 0  
fill ~18 ~-1 ~6 ~20 ~-1 ~6 sand 0  
fill ~19 ~-1 ~3 ~20 ~-1 ~3 sand 0  
fill ~19 ~-1 ~5 ~20 ~-1 ~5 sand 0  
fill ~19 ~-1 ~10 ~20 ~-1 ~10 water 0  
fill ~19 ~-1 ~11 ~20 ~-1 ~11 water 0  
fill ~19 ~-1 ~12 ~20 ~-1 ~12 water 0  
fill ~20 ~-1 ~4 ~20 ~-1 ~4 sand 0  
fill ~20 ~-1 ~9 ~20 ~-1 ~9 sand 0  
fill ~2 ~0 ~2 ~9 ~0 ~2 snow 0  
fill ~2 ~0 ~3 ~2 ~1 ~3 snow 0  
fill ~2 ~0 ~4 ~2 ~1 ~4 snow 0  
fill ~2 ~0 ~5 ~2 ~1 ~5 snow 0  
fill ~2 ~0 ~6 ~2 ~1 ~6 snow 0  
fill ~2 ~0 ~7 ~2 ~1 ~7 snow 0  
fill ~2 ~0 ~8 ~2 ~4 ~8 snow 0  
fill ~2 ~0 ~9 ~2 ~1 ~9 snow 0  
fill ~2 ~0 ~10 ~2 ~1 ~10 snow 0  
fill ~2 ~0 ~11 ~2 ~1 ~11 snow 0  
fill ~2 ~0 ~12 ~2 ~1 ~12 snow 0  
fill ~2 ~0 ~13 ~2 ~1 ~13 snow 0  
fill ~2 ~0 ~14 ~20 ~0 ~14 snow 0  
fill ~6 ~0 ~8 ~7 ~0 ~8 fence 0  
fill ~6 ~0 ~9 ~7 ~0 ~9 oak_stairs 3  
fill ~8 ~0 ~3 ~8 ~1 ~3 snow 0  
fill ~8 ~0 ~4 ~8 ~1 ~4 snow 0  
fill ~8 ~0 ~5 ~8 ~1 ~5 snow 0  
fill ~8 ~0 ~6 ~8 ~1 ~6 snow 0  
fill ~8 ~0 ~7 ~8 ~1 ~7 snow 0  
fill ~8 ~0 ~8 ~9 ~0 ~8 snow 0  
fill ~8 ~0 ~9 ~8 ~0 ~11 snow 0  
fill ~9 ~0 ~3 ~9 ~0 ~7 water 8  
fill ~9 ~0 ~9 ~9 ~0 ~10 leaves 12  
fill ~9 ~0 ~11 ~11 ~0 ~11 snow 0 
setblock ~10 ~0 ~2 glowstone 0  
fill ~10 ~0 ~3 ~10 ~0 ~7 water 9 
setblock ~10 ~0 ~8 glowstone 0  
fill ~10 ~0 ~9 ~10 ~0 ~10 wooden_slab 0  
fill ~11 ~0 ~2 ~14 ~0 ~2 snow 0  
fill ~11 ~0 ~3 ~11 ~0 ~7 wooden_slab 0 
setblock ~12 ~0 ~11 wooden_door 1  
fill ~13 ~0 ~10 ~14 ~0 ~10 vine 1  
fill ~13 ~0 ~11 ~14 ~0 ~11 snow 0  
fill ~14 ~0 ~12 ~14 ~0 ~14 snow 0  
fill ~15 ~0 ~2 ~17 ~0 ~2 fence 0  
fill ~15 ~0 ~9 ~15 ~2 ~9 reeds 0  
fill ~15 ~0 ~11 ~15 ~2 ~11 vine 2 
setblock ~15 ~0 ~13 wall_sign 4  
fill ~16 ~0 ~11 ~17 ~0 ~11 stone_slab 1  
fill ~16 ~0 ~13 ~17 ~0 ~13 sandstone_stairs 2 
setblock ~18 ~0 ~2 fence_gate 0 
setblock ~18 ~0 ~9 waterlily 0 
setblock ~18 ~0 ~13 wall_sign 5  
fill ~19 ~0 ~2 ~20 ~0 ~2 fence 0  
fill ~19 ~0 ~9 ~19 ~0 ~13 glass_pane 0 
setblock ~20 ~0 ~3 fence 0 
setblock ~20 ~0 ~4 fence_gate 1  
fill ~20 ~0 ~5 ~20 ~0 ~7 fence 0  
fill ~20 ~0 ~8 ~20 ~0 ~14 snow 0  
fill ~2 ~1 ~2 ~11 ~1 ~2 snow 0  
fill ~2 ~1 ~14 ~4 ~1 ~14 snow 0  
fill ~3 ~1 ~3 ~7 ~1 ~3 planks 0  
fill ~3 ~1 ~4 ~7 ~1 ~4 planks 0  
fill ~3 ~1 ~5 ~4 ~1 ~5 planks 0  
fill ~3 ~1 ~6 ~7 ~1 ~6 planks 0  
fill ~3 ~1 ~7 ~7 ~1 ~7 planks 0  
fill ~3 ~1 ~8 ~5 ~1 ~8 planks 0 
setblock ~5 ~1 ~5 glowstone 0  
fill ~5 ~1 ~14 ~9 ~1 ~14 glass_pane 0  
fill ~6 ~1 ~5 ~7 ~1 ~5 planks 0  
fill ~6 ~1 ~8 ~7 ~1 ~8 oak_stairs 3 
setblock ~8 ~1 ~8 double_wooden_slab 0  
fill ~8 ~1 ~9 ~8 ~2 ~9 glass_pane 0  
fill ~8 ~1 ~10 ~8 ~2 ~10 glass_pane 0  
fill ~8 ~1 ~11 ~8 ~3 ~11 snow 0  
fill ~9 ~1 ~3 ~9 ~1 ~7 water 0  
fill ~9 ~1 ~8 ~10 ~1 ~8 wooden_slab 0  
fill ~9 ~1 ~11 ~10 ~1 ~11 glass_pane 0  
fill ~10 ~1 ~3 ~10 ~1 ~7 water 1  
fill ~10 ~1 ~14 ~10 ~2 ~14 snow 0  
fill ~11 ~1 ~11 ~11 ~2 ~11 snow 0  
fill ~11 ~1 ~14 ~13 ~1 ~14 glass_pane 0  
fill ~12 ~1 ~2 ~14 ~1 ~2 wooden_slab 0 
setblock ~12 ~1 ~11 wooden_door 8  
fill ~13 ~1 ~11 ~14 ~1 ~11 snow 0  
fill ~14 ~1 ~10 ~14 ~2 ~10 vine 1  
fill ~14 ~1 ~12 ~14 ~1 ~13 glass_pane 0  
fill ~14 ~1 ~14 ~14 ~2 ~14 snow 0  
fill ~15 ~1 ~12 ~15 ~2 ~12 vine 2  
fill ~15 ~1 ~14 ~17 ~1 ~14 glass_pane 0 
setblock ~16 ~1 ~2 torch 5  
fill ~18 ~1 ~14 ~18 ~2 ~14 snow 0  
fill ~19 ~1 ~14 ~19 ~2 ~14 glass_pane 0 
setblock ~20 ~1 ~2 torch 5 
setblock ~20 ~1 ~5 torch 5  
fill ~20 ~1 ~8 ~20 ~1 ~10 wooden_slab 1  
fill ~20 ~1 ~11 ~20 ~1 ~14 snow 0  
fill ~2 ~2 ~2 ~2 ~3 ~2 snow 0  
fill ~2 ~2 ~3 ~2 ~3 ~3 glass_pane 0  
fill ~2 ~2 ~4 ~2 ~3 ~4 glass_pane 0  
fill ~2 ~2 ~5 ~2 ~3 ~5 glass_pane 0  
fill ~2 ~2 ~6 ~2 ~3 ~6 glass_pane 0  
fill ~2 ~2 ~7 ~2 ~3 ~7 glass_pane 0  
fill ~2 ~2 ~9 ~2 ~3 ~9 glass_pane 0  
fill ~2 ~2 ~10 ~2 ~3 ~10 glass_pane 0  
fill ~2 ~2 ~11 ~2 ~3 ~11 glass_pane 0  
fill ~2 ~2 ~12 ~2 ~3 ~12 glass_pane 0  
fill ~2 ~2 ~13 ~2 ~3 ~13 glass_pane 0  
fill ~2 ~2 ~14 ~4 ~2 ~14 snow 0  
fill ~3 ~2 ~2 ~7 ~2 ~2 glass_pane 0  
fill ~3 ~2 ~3 ~3 ~2 ~4 bed 9 
setblock ~3 ~2 ~5 fence 0 
setblock ~3 ~2 ~6 furnace 5 
setblock ~3 ~2 ~7 crafting_table 0 
setblock ~3 ~2 ~8 furnace 5  
fill ~4 ~2 ~3 ~4 ~2 ~4 bed 1  
fill ~5 ~2 ~14 ~9 ~2 ~14 glass_pane 0 
setblock ~6 ~2 ~3 wall_sign 2  
fill ~6 ~2 ~4 ~6 ~2 ~5 sandstone_stairs 1 
setblock ~6 ~2 ~6 wall_sign 3  
fill ~8 ~2 ~2 ~9 ~2 ~2 snow 0  
fill ~8 ~2 ~3 ~8 ~3 ~3 glass_pane 0  
fill ~8 ~2 ~4 ~8 ~3 ~4 glass_pane 0  
fill ~8 ~2 ~5 ~8 ~3 ~5 glass_pane 0  
fill ~8 ~2 ~6 ~8 ~3 ~6 glass_pane 0  
fill ~8 ~2 ~7 ~8 ~3 ~7 glass_pane 0  
fill ~8 ~2 ~8 ~8 ~4 ~8 snow 0  
fill ~9 ~2 ~8 ~9 ~3 ~8 vine 2  
fill ~9 ~2 ~9 ~9 ~3 ~9 vine 2  
fill ~9 ~2 ~11 ~10 ~2 ~11 glass_pane 0  
fill ~10 ~2 ~2 ~11 ~2 ~2 wooden_slab 0  
fill ~11 ~2 ~14 ~14 ~2 ~14 snow 0  
fill ~12 ~2 ~11 ~14 ~2 ~11 snow 0  
fill ~14 ~2 ~12 ~14 ~2 ~14 snow 0  
fill ~15 ~2 ~14 ~17 ~2 ~14 wooden_slab 1  
fill ~20 ~2 ~11 ~20 ~2 ~12 wooden_slab 1  
fill ~20 ~2 ~13 ~20 ~2 ~14 snow 0  
fill ~2 ~3 ~14 ~8 ~3 ~14 snow 0  
fill ~3 ~3 ~2 ~7 ~3 ~2 glass_pane 0 
setblock ~3 ~3 ~5 wooden_pressure_plate 0  
fill ~8 ~3 ~2 ~8 ~0 ~2 snow 0  
fill ~8 ~3 ~9 ~8 ~3 ~15 snow 0 
setblock ~9 ~3 ~2 wooden_slab 0  
fill ~9 ~3 ~10 ~15 ~3 ~10 wooden_slab 2  
fill ~9 ~3 ~11 ~15 ~3 ~11 wooden_slab 2  
fill ~9 ~3 ~12 ~11 ~3 ~12 wooden_slab 2  
fill ~9 ~3 ~13 ~15 ~3 ~13 wooden_slab 2  
fill ~9 ~3 ~14 ~15 ~3 ~14 wooden_slab 2  
fill ~9 ~3 ~15 ~15 ~3 ~15 wooden_slab 2 
setblock ~12 ~3 ~12 glowstone 0  
fill ~13 ~3 ~12 ~15 ~3 ~12 wooden_slab 2  
fill ~18 ~3 ~14 ~20 ~3 ~14 wooden_slab 1 
setblock ~20 ~3 ~13 wooden_slab 1  
fill ~1 ~4 ~1 ~9 ~4 ~1 wooden_slab 2  
fill ~1 ~4 ~2 ~9 ~4 ~2 wooden_slab 2  
fill ~1 ~4 ~3 ~9 ~4 ~3 wooden_slab 2  
fill ~1 ~4 ~4 ~3 ~4 ~4 wooden_slab 2  
fill ~1 ~4 ~5 ~9 ~4 ~5 wooden_slab 2  
fill ~1 ~4 ~6 ~9 ~4 ~6 wooden_slab 2  
fill ~1 ~4 ~7 ~9 ~4 ~7 wooden_slab 2  
fill ~2 ~4 ~9 ~2 ~4 ~14 snow 0  
fill ~3 ~4 ~14 ~4 ~4 ~14 snow 0 
setblock ~4 ~4 ~4 glowstone 0  
fill ~5 ~4 ~4 ~9 ~4 ~4 wooden_slab 2  
fill ~5 ~4 ~14 ~8 ~4 ~14 glass_pane 0  
fill ~8 ~4 ~9 ~8 ~4 ~14 glass_pane 0 
setblock ~8 ~4 ~15 snow 0  
fill ~9 ~4 ~8 ~9 ~5 ~8 wooden_slab 2  
fill ~1 ~5 ~7 ~9 ~5 ~7 wooden_slab 2  
fill ~1 ~5 ~8 ~9 ~5 ~8 wooden_slab 2  
fill ~1 ~5 ~9 ~9 ~5 ~9 wooden_slab 2  
fill ~1 ~5 ~10 ~9 ~5 ~10 wooden_slab 2  
fill ~1 ~5 ~11 ~9 ~5 ~11 wooden_slab 2  
fill ~1 ~5 ~12 ~4 ~5 ~12 wooden_slab 2  
fill ~1 ~5 ~13 ~9 ~5 ~13 wooden_slab 2  
fill ~1 ~5 ~14 ~9 ~5 ~14 wooden_slab 2  
fill ~1 ~5 ~15 ~9 ~5 ~15 wooden_slab 2 
setblock ~5 ~5 ~12 glowstone 0  
fill ~6 ~5 ~12 ~9 ~5 ~12 wooden_slab 2    