setblock ~80 ~6 ~22 chest 2
setblock ~80 ~7 ~22 chest 2
setblock ~81 ~6 ~22 furnace 2
setblock ~82 ~6 ~22 chest 2
setblock ~82 ~7 ~22 chest 2
setblock ~82 ~9 ~28 chest 5
setblock ~82 ~9 ~29 chest 5
setblock ~84 ~9 ~19 furnace 4
setblock ~84 ~9 ~28 chest 4
setblock ~84 ~9 ~29 chest 4
setblock ~91 ~12 ~30 chest 2
setblock ~92 ~9 ~27 furnace 5
setblock ~92 ~9 ~29 furnace 5
setblock ~95 ~12 ~30 chest 2
setblock ~99 ~7 ~13 furnace 5
setblock ~99 ~7 ~14 furnace 5
setblock ~111 ~9 ~34 furnace 3
setblock ~112 ~9 ~34 furnace 3
setblock ~114 ~9 ~34 chest 3
setblock ~115 ~12 ~33 chest 4
setblock ~115 ~12 ~35 chest 4
setblock ~115 ~12 ~37 chest 4
setblock ~115 ~12 ~39 chest 4
fill ~1 ~0 ~26 ~2 ~0 ~26 grass 0  
fill ~1 ~0 ~27 ~1 ~0 ~43 grass 0  
fill ~2 ~0 ~25 ~3 ~0 ~25 grass 0  
fill ~2 ~0 ~27 ~12 ~0 ~27 stone 0  
fill ~2 ~0 ~28 ~12 ~0 ~28 stone 0  
fill ~2 ~0 ~29 ~12 ~0 ~29 stone 0  
fill ~2 ~0 ~30 ~12 ~0 ~30 stone 0  
fill ~2 ~0 ~31 ~11 ~0 ~31 stone 0  
fill ~2 ~0 ~32 ~10 ~0 ~32 stone 0  
fill ~2 ~0 ~33 ~10 ~0 ~33 stone 0  
fill ~2 ~0 ~34 ~10 ~0 ~34 stone 0  
fill ~2 ~0 ~35 ~2 ~0 ~35 dirt 0  
fill ~2 ~0 ~36 ~3 ~0 ~36 dirt 0  
fill ~2 ~0 ~37 ~118 ~0 ~37 dirt 0  
fill ~2 ~0 ~38 ~118 ~0 ~38 dirt 0  
fill ~2 ~0 ~39 ~92 ~0 ~39 dirt 0  
fill ~2 ~0 ~40 ~117 ~0 ~40 dirt 0  
fill ~2 ~0 ~41 ~2 ~0 ~51 grass 0  
fill ~3 ~0 ~24 ~4 ~0 ~24 grass 0  
fill ~3 ~0 ~26 ~12 ~0 ~26 stone 0  
fill ~3 ~0 ~35 ~10 ~0 ~35 stone 0  
fill ~3 ~0 ~41 ~116 ~0 ~41 dirt 0  
fill ~3 ~0 ~42 ~116 ~0 ~42 dirt 0  
fill ~3 ~0 ~43 ~115 ~0 ~43 dirt 0  
fill ~3 ~0 ~44 ~114 ~0 ~44 dirt 0  
fill ~3 ~0 ~45 ~114 ~0 ~45 dirt 0  
fill ~3 ~0 ~46 ~114 ~0 ~46 dirt 0  
fill ~3 ~0 ~47 ~114 ~0 ~47 dirt 0  
fill ~3 ~0 ~48 ~114 ~0 ~48 dirt 0  
fill ~3 ~0 ~49 ~4 ~0 ~49 dirt 0  
fill ~3 ~0 ~50 ~113 ~0 ~50 dirt 0  
fill ~3 ~0 ~51 ~3 ~0 ~52 grass 0  
fill ~4 ~0 ~23 ~5 ~0 ~23 grass 0  
fill ~4 ~0 ~25 ~5 ~0 ~25 stone 0  
fill ~4 ~0 ~36 ~9 ~0 ~36 stone 0  
fill ~4 ~0 ~51 ~113 ~0 ~51 dirt 0  
fill ~4 ~0 ~52 ~4 ~0 ~53 grass 0  
fill ~5 ~0 ~24 ~12 ~0 ~24 stone 0  
fill ~5 ~0 ~52 ~7 ~0 ~52 dirt 0  
fill ~5 ~0 ~53 ~5 ~0 ~55 grass 0  
fill ~6 ~0 ~23 ~11 ~0 ~23 stone 0  
fill ~6 ~0 ~49 ~113 ~0 ~49 dirt 0  
fill ~6 ~0 ~53 ~110 ~0 ~53 dirt 0  
fill ~6 ~0 ~54 ~6 ~0 ~56 grass 0  
fill ~7 ~0 ~22 ~8 ~0 ~22 grass 0  
fill ~7 ~0 ~25 ~12 ~0 ~25 stone 0  
fill ~7 ~0 ~54 ~109 ~0 ~54 dirt 0  
fill ~7 ~0 ~55 ~108 ~0 ~55 dirt 0 
setblock ~7 ~0 ~56 grass 0  
fill ~8 ~0 ~56 ~107 ~0 ~56 dirt 0  
fill ~8 ~0 ~57 ~8 ~0 ~58 grass 0 
setblock ~9 ~0 ~21 grass 0  
fill ~9 ~0 ~22 ~10 ~0 ~22 stone 0  
fill ~9 ~0 ~57 ~107 ~0 ~57 dirt 0  
fill ~9 ~0 ~58 ~9 ~0 ~60 grass 0 
setblock ~10 ~0 ~20 grass 0  
fill ~10 ~0 ~21 ~11 ~0 ~21 stone 0  
fill ~10 ~0 ~36 ~118 ~0 ~36 dirt 0 
setblock ~10 ~0 ~52 grass 0  
fill ~10 ~0 ~58 ~107 ~0 ~58 dirt 0  
fill ~10 ~0 ~59 ~107 ~0 ~59 dirt 0  
fill ~10 ~0 ~60 ~10 ~0 ~61 grass 0 
setblock ~11 ~0 ~19 grass 0  
fill ~11 ~0 ~20 ~13 ~0 ~20 dirt 0 
setblock ~11 ~0 ~22 grass 0  
fill ~11 ~0 ~32 ~118 ~0 ~32 dirt 0  
fill ~11 ~0 ~33 ~118 ~0 ~33 dirt 0  
fill ~11 ~0 ~34 ~118 ~0 ~34 dirt 0  
fill ~11 ~0 ~35 ~118 ~0 ~35 dirt 0  
fill ~11 ~0 ~52 ~113 ~0 ~52 dirt 0  
fill ~11 ~0 ~60 ~107 ~0 ~60 dirt 0  
fill ~11 ~0 ~61 ~11 ~0 ~62 grass 0  
fill ~12 ~0 ~17 ~13 ~0 ~17 grass 0  
fill ~12 ~0 ~18 ~13 ~0 ~18 grass 0  
fill ~12 ~0 ~19 ~113 ~0 ~19 dirt 0  
fill ~12 ~0 ~21 ~12 ~2 ~21 dirt 0  
fill ~12 ~0 ~22 ~115 ~0 ~22 dirt 0  
fill ~12 ~0 ~23 ~115 ~0 ~23 dirt 0  
fill ~12 ~0 ~31 ~118 ~0 ~31 dirt 0  
fill ~12 ~0 ~61 ~108 ~0 ~61 dirt 0  
fill ~12 ~0 ~62 ~13 ~0 ~62 grass 0  
fill ~12 ~0 ~63 ~14 ~0 ~63 grass 0  
fill ~13 ~0 ~16 ~15 ~0 ~16 grass 0 
setblock ~13 ~0 ~21 grass 0  
fill ~13 ~0 ~24 ~116 ~0 ~24 dirt 0  
fill ~13 ~0 ~25 ~116 ~0 ~25 dirt 0  
fill ~13 ~0 ~26 ~116 ~0 ~26 dirt 0  
fill ~13 ~0 ~27 ~117 ~0 ~27 dirt 0  
fill ~13 ~0 ~28 ~117 ~0 ~28 dirt 0  
fill ~13 ~0 ~29 ~118 ~0 ~29 dirt 0  
fill ~13 ~0 ~30 ~118 ~0 ~30 dirt 0  
fill ~13 ~0 ~64 ~16 ~0 ~64 grass 0  
fill ~14 ~0 ~15 ~16 ~0 ~15 grass 0  
fill ~14 ~0 ~17 ~112 ~0 ~17 dirt 0  
fill ~14 ~0 ~18 ~14 ~1 ~18 dirt 0 
setblock ~14 ~0 ~20 grass 0  
fill ~14 ~0 ~21 ~114 ~0 ~21 dirt 0  
fill ~14 ~0 ~62 ~109 ~0 ~62 dirt 0  
fill ~15 ~0 ~14 ~16 ~0 ~14 grass 0  
fill ~15 ~0 ~20 ~113 ~0 ~20 dirt 0  
fill ~15 ~0 ~63 ~108 ~0 ~63 dirt 0  
fill ~16 ~0 ~13 ~18 ~0 ~13 grass 0  
fill ~16 ~0 ~18 ~113 ~0 ~18 dirt 0  
fill ~17 ~0 ~14 ~19 ~0 ~14 dirt 0  
fill ~17 ~0 ~15 ~18 ~0 ~15 dirt 0  
fill ~17 ~0 ~64 ~76 ~0 ~64 dirt 0 
setblock ~18 ~0 ~16 grass 0 
setblock ~18 ~0 ~65 grass 0 
setblock ~19 ~0 ~12 grass 0  
fill ~19 ~0 ~13 ~20 ~0 ~13 dirt 0  
fill ~19 ~0 ~16 ~79 ~0 ~16 dirt 0  
fill ~19 ~0 ~65 ~63 ~0 ~65 dirt 0 
setblock ~20 ~0 ~11 grass 0  
fill ~20 ~0 ~12 ~20 ~0 ~12 dirt 0  
fill ~20 ~0 ~15 ~24 ~0 ~15 dirt 0  
fill ~20 ~0 ~66 ~106 ~0 ~66 dirt 0  
fill ~21 ~0 ~10 ~23 ~0 ~10 grass 0  
fill ~21 ~0 ~11 ~23 ~0 ~11 dirt 0 
setblock ~21 ~0 ~13 grass 0  
fill ~21 ~0 ~14 ~23 ~0 ~14 dirt 0  
fill ~21 ~0 ~67 ~69 ~0 ~67 dirt 0  
fill ~22 ~0 ~13 ~23 ~0 ~13 dirt 0  
fill ~24 ~0 ~9 ~34 ~0 ~9 grass 0  
fill ~24 ~0 ~10 ~26 ~0 ~10 stone 0  
fill ~24 ~0 ~11 ~24 ~1 ~11 stone 0 
setblock ~24 ~0 ~12 grass 0  
fill ~24 ~0 ~13 ~41 ~0 ~13 stone 0  
fill ~24 ~0 ~14 ~40 ~0 ~14 stone 0  
fill ~24 ~0 ~68 ~59 ~0 ~68 dirt 0  
fill ~25 ~0 ~12 ~32 ~0 ~12 stone 0  
fill ~25 ~0 ~15 ~36 ~0 ~15 stone 0  
fill ~26 ~0 ~11 ~31 ~0 ~11 stone 0  
fill ~26 ~0 ~69 ~57 ~0 ~69 dirt 0  
fill ~28 ~0 ~10 ~52 ~0 ~10 stone 0  
fill ~28 ~0 ~70 ~30 ~0 ~70 grass 0  
fill ~30 ~0 ~71 ~31 ~0 ~71 grass 0  
fill ~31 ~0 ~70 ~55 ~0 ~70 dirt 0  
fill ~31 ~0 ~72 ~33 ~0 ~72 grass 0  
fill ~32 ~0 ~71 ~53 ~0 ~71 dirt 0  
fill ~33 ~0 ~11 ~33 ~2 ~11 stone 0 
setblock ~33 ~0 ~12 grass 0  
fill ~33 ~0 ~73 ~49 ~0 ~73 grass 0  
fill ~34 ~0 ~72 ~48 ~0 ~72 dirt 0  
fill ~35 ~0 ~8 ~37 ~0 ~8 grass 0  
fill ~35 ~0 ~9 ~39 ~0 ~9 stone 0  
fill ~37 ~0 ~7 ~39 ~0 ~7 grass 0 
setblock ~37 ~0 ~12 grass 0  
fill ~37 ~0 ~15 ~112 ~0 ~15 dirt 0  
fill ~38 ~0 ~8 ~73 ~0 ~8 stone 0 
setblock ~38 ~0 ~11 grass 0  
fill ~38 ~0 ~12 ~44 ~0 ~12 stone 0  
fill ~39 ~0 ~11 ~49 ~0 ~11 stone 0  
fill ~40 ~0 ~7 ~74 ~0 ~7 stone 0 
setblock ~40 ~0 ~9 grass 0  
fill ~41 ~0 ~5 ~44 ~0 ~5 grass 0  
fill ~41 ~0 ~6 ~41 ~0 ~5 grass 0  
fill ~41 ~0 ~9 ~67 ~0 ~9 stone 0  
fill ~41 ~0 ~14 ~112 ~0 ~14 dirt 0  
fill ~42 ~0 ~6 ~75 ~0 ~6 stone 0  
fill ~42 ~0 ~13 ~112 ~0 ~13 dirt 0  
fill ~45 ~0 ~5 ~47 ~0 ~5 stone 0  
fill ~45 ~0 ~12 ~113 ~0 ~12 dirt 0  
fill ~48 ~0 ~4 ~49 ~0 ~4 grass 0  
fill ~48 ~0 ~5 ~48 ~0 ~4 grass 0  
fill ~49 ~0 ~3 ~51 ~0 ~3 grass 0  
fill ~49 ~0 ~5 ~76 ~0 ~5 stone 0  
fill ~49 ~0 ~72 ~54 ~0 ~72 grass 0  
fill ~50 ~0 ~4 ~76 ~0 ~4 stone 0  
fill ~50 ~0 ~11 ~112 ~0 ~11 dirt 0  
fill ~51 ~0 ~2 ~56 ~0 ~2 grass 0  
fill ~52 ~0 ~3 ~76 ~0 ~3 stone 0  
fill ~53 ~0 ~10 ~111 ~0 ~10 dirt 0  
fill ~54 ~0 ~71 ~56 ~0 ~71 grass 0  
fill ~55 ~0 ~1 ~57 ~0 ~1 grass 0  
fill ~56 ~0 ~70 ~58 ~0 ~70 grass 0  
fill ~57 ~0 ~2 ~63 ~0 ~2 stone 0  
fill ~58 ~0 ~1 ~61 ~0 ~1 stone 0  
fill ~58 ~0 ~69 ~60 ~0 ~69 grass 0  
fill ~60 ~0 ~0 ~62 ~0 ~0 grass 0  
fill ~60 ~0 ~68 ~70 ~0 ~68 grass 0  
fill ~62 ~0 ~1 ~68 ~0 ~1 grass 0  
fill ~64 ~0 ~2 ~66 ~0 ~2 grass 0  
fill ~66 ~0 ~65 ~66 ~2 ~65 dirt 0  
fill ~67 ~0 ~2 ~69 ~0 ~2 stone 0 
setblock ~67 ~0 ~65 grass 0  
fill ~68 ~0 ~9 ~101 ~0 ~9 dirt 0  
fill ~68 ~0 ~65 ~106 ~0 ~65 dirt 0  
fill ~70 ~0 ~2 ~74 ~0 ~2 grass 0  
fill ~70 ~0 ~67 ~106 ~0 ~67 grass 0  
fill ~73 ~0 ~1 ~83 ~0 ~1 grass 0  
fill ~74 ~0 ~8 ~99 ~0 ~8 dirt 0  
fill ~75 ~0 ~2 ~76 ~0 ~2 stone 0  
fill ~75 ~0 ~7 ~98 ~0 ~7 dirt 0  
fill ~76 ~0 ~6 ~97 ~0 ~6 dirt 0  
fill ~77 ~0 ~2 ~96 ~0 ~2 dirt 0  
fill ~77 ~0 ~3 ~96 ~0 ~3 dirt 0  
fill ~77 ~0 ~4 ~96 ~0 ~4 dirt 0  
fill ~77 ~0 ~5 ~96 ~0 ~5 dirt 0 
setblock ~77 ~0 ~64 grass 0  
fill ~78 ~0 ~64 ~84 ~0 ~64 dirt 0  
fill ~81 ~0 ~16 ~112 ~0 ~16 dirt 0 
setblock ~84 ~0 ~0 stone_stairs 2 
setblock ~84 ~0 ~1 cobblestone 0  
fill ~85 ~0 ~1 ~89 ~0 ~1 stone_stairs 2 
setblock ~85 ~0 ~64 grass 0  
fill ~86 ~0 ~64 ~107 ~0 ~64 dirt 0 
setblock ~90 ~0 ~0 stone_stairs 2 
setblock ~90 ~0 ~1 cobblestone 0  
fill ~91 ~0 ~1 ~102 ~0 ~1 grass 0  
fill ~95 ~0 ~39 ~117 ~0 ~39 dirt 0  
fill ~97 ~0 ~2 ~101 ~0 ~2 stone 0  
fill ~97 ~0 ~3 ~103 ~0 ~3 stone 0  
fill ~97 ~0 ~4 ~104 ~0 ~4 stone 0  
fill ~97 ~0 ~5 ~104 ~0 ~5 stone 0  
fill ~98 ~0 ~6 ~105 ~0 ~6 stone 0  
fill ~99 ~0 ~7 ~106 ~0 ~7 stone 0  
fill ~100 ~0 ~8 ~107 ~0 ~8 stone 0  
fill ~102 ~0 ~2 ~104 ~0 ~2 grass 0  
fill ~102 ~0 ~9 ~106 ~0 ~9 stone 0  
fill ~104 ~0 ~3 ~105 ~0 ~3 grass 0  
fill ~105 ~0 ~4 ~106 ~0 ~4 grass 0  
fill ~105 ~0 ~5 ~107 ~0 ~5 grass 0  
fill ~106 ~0 ~6 ~107 ~0 ~6 grass 0  
fill ~107 ~0 ~7 ~109 ~0 ~7 grass 0  
fill ~107 ~0 ~9 ~111 ~0 ~9 dirt 0  
fill ~107 ~0 ~65 ~108 ~0 ~65 grass 0  
fill ~107 ~0 ~66 ~107 ~0 ~65 grass 0  
fill ~108 ~0 ~8 ~109 ~0 ~8 dirt 0  
fill ~108 ~0 ~56 ~116 ~0 ~56 stone 0  
fill ~108 ~0 ~57 ~115 ~0 ~57 stone 0  
fill ~108 ~0 ~58 ~114 ~0 ~58 stone 0  
fill ~108 ~0 ~59 ~113 ~0 ~59 stone 0  
fill ~108 ~0 ~60 ~112 ~0 ~60 stone 0  
fill ~108 ~0 ~64 ~109 ~0 ~64 grass 0  
fill ~109 ~0 ~55 ~114 ~0 ~55 stone 0  
fill ~109 ~0 ~61 ~110 ~0 ~61 stone 0  
fill ~109 ~0 ~63 ~110 ~0 ~63 grass 0  
fill ~110 ~0 ~8 ~111 ~0 ~8 grass 0  
fill ~110 ~0 ~54 ~118 ~0 ~54 stone 0  
fill ~110 ~0 ~62 ~111 ~0 ~62 grass 0  
fill ~111 ~0 ~53 ~114 ~0 ~53 stone 0  
fill ~111 ~0 ~61 ~113 ~0 ~61 grass 0  
fill ~112 ~0 ~9 ~112 ~11 ~9 log 0 
setblock ~112 ~0 ~10 grass 0  
fill ~113 ~0 ~10 ~113 ~11 ~10 log 0 
setblock ~113 ~0 ~11 grass 0  
fill ~113 ~0 ~13 ~114 ~0 ~13 stone 0  
fill ~113 ~0 ~14 ~115 ~0 ~14 stone 0  
fill ~113 ~0 ~15 ~115 ~0 ~15 stone 0  
fill ~113 ~0 ~16 ~116 ~0 ~16 stone 0  
fill ~113 ~0 ~17 ~118 ~0 ~17 stone 0  
fill ~113 ~0 ~60 ~114 ~0 ~60 grass 0 
setblock ~114 ~0 ~11 cobblestone 0  
fill ~114 ~0 ~12 ~114 ~0 ~12 stone 0  
fill ~114 ~0 ~18 ~119 ~0 ~18 stone 0  
fill ~114 ~0 ~19 ~120 ~0 ~19 stone 0  
fill ~114 ~0 ~20 ~121 ~0 ~20 stone 0  
fill ~114 ~0 ~49 ~118 ~0 ~49 stone 0  
fill ~114 ~0 ~50 ~120 ~0 ~50 stone 0  
fill ~114 ~0 ~51 ~120 ~0 ~51 stone 0  
fill ~114 ~0 ~52 ~115 ~0 ~52 stone 0  
fill ~114 ~0 ~59 ~115 ~0 ~59 grass 0  
fill ~115 ~0 ~12 ~115 ~11 ~12 log 0 
setblock ~115 ~0 ~13 grass 0  
fill ~115 ~0 ~21 ~121 ~0 ~21 stone 0  
fill ~115 ~0 ~44 ~121 ~0 ~44 stone 0  
fill ~115 ~0 ~45 ~118 ~0 ~45 stone 0  
fill ~115 ~0 ~46 ~119 ~0 ~46 stone 0  
fill ~115 ~0 ~47 ~120 ~0 ~47 stone 0  
fill ~115 ~0 ~48 ~120 ~0 ~48 stone 0 
setblock ~115 ~0 ~53 grass 0 
setblock ~115 ~0 ~55 grass 0  
fill ~115 ~0 ~58 ~116 ~0 ~58 grass 0  
fill ~116 ~0 ~13 ~116 ~11 ~13 log 0 
setblock ~116 ~0 ~14 cobblestone 0  
fill ~116 ~0 ~15 ~116 ~11 ~15 log 0  
fill ~116 ~0 ~22 ~121 ~0 ~22 stone 0  
fill ~116 ~0 ~23 ~122 ~0 ~23 stone 0  
fill ~116 ~0 ~43 ~122 ~0 ~43 stone 0 
setblock ~116 ~0 ~52 grass 0  
fill ~116 ~0 ~53 ~118 ~0 ~53 stone 0  
fill ~116 ~0 ~55 ~117 ~0 ~55 stone 0  
fill ~116 ~0 ~57 ~117 ~0 ~57 grass 0  
fill ~117 ~0 ~16 ~117 ~11 ~16 log 0  
fill ~117 ~0 ~24 ~122 ~0 ~24 stone 0  
fill ~117 ~0 ~25 ~123 ~0 ~25 stone 0  
fill ~117 ~0 ~26 ~124 ~0 ~26 stone 0  
fill ~117 ~0 ~41 ~123 ~0 ~41 stone 0  
fill ~117 ~0 ~42 ~123 ~0 ~42 stone 0  
fill ~117 ~0 ~52 ~119 ~0 ~52 stone 0  
fill ~117 ~0 ~56 ~118 ~0 ~56 grass 0  
fill ~118 ~0 ~27 ~124 ~0 ~27 stone 0  
fill ~118 ~0 ~28 ~125 ~0 ~28 stone 0  
fill ~118 ~0 ~39 ~123 ~0 ~39 stone 0  
fill ~118 ~0 ~40 ~123 ~0 ~40 stone 0  
fill ~118 ~0 ~55 ~119 ~0 ~55 grass 0  
fill ~119 ~0 ~29 ~125 ~0 ~29 stone 0  
fill ~119 ~0 ~30 ~125 ~0 ~30 stone 0  
fill ~119 ~0 ~31 ~125 ~0 ~31 stone 0  
fill ~119 ~0 ~32 ~125 ~0 ~32 stone 0  
fill ~119 ~0 ~33 ~125 ~0 ~33 stone 0  
fill ~119 ~0 ~34 ~123 ~0 ~34 stone 0  
fill ~119 ~0 ~35 ~123 ~0 ~35 stone 0  
fill ~119 ~0 ~36 ~123 ~0 ~36 stone 0  
fill ~119 ~0 ~37 ~123 ~0 ~37 stone 0  
fill ~119 ~0 ~38 ~123 ~0 ~38 stone 0 
setblock ~119 ~0 ~45 grass 0  
fill ~119 ~0 ~53 ~120 ~0 ~53 grass 0  
fill ~119 ~0 ~54 ~119 ~0 ~53 grass 0  
fill ~120 ~0 ~49 ~120 ~0 ~49 stone 0 
setblock ~120 ~0 ~52 grass 0  
fill ~121 ~0 ~45 ~121 ~0 ~45 stone 0  
fill ~121 ~0 ~46 ~121 ~0 ~46 stone 0  
fill ~121 ~0 ~47 ~121 ~0 ~51 grass 0  
fill ~2 ~1 ~27 ~3 ~1 ~27 grass 0  
fill ~2 ~1 ~28 ~2 ~1 ~40 grass 0  
fill ~3 ~1 ~26 ~4 ~1 ~26 grass 0  
fill ~3 ~1 ~28 ~13 ~1 ~28 stone 0  
fill ~3 ~1 ~29 ~13 ~1 ~29 stone 0  
fill ~3 ~1 ~30 ~13 ~1 ~30 stone 0  
fill ~3 ~1 ~31 ~12 ~1 ~31 stone 0  
fill ~3 ~1 ~32 ~11 ~1 ~32 stone 0  
fill ~3 ~1 ~33 ~11 ~1 ~33 stone 0  
fill ~3 ~1 ~34 ~11 ~1 ~34 stone 0  
fill ~3 ~1 ~35 ~11 ~1 ~35 stone 0  
fill ~3 ~1 ~36 ~11 ~1 ~36 stone 0  
fill ~3 ~1 ~37 ~4 ~1 ~37 dirt 0  
fill ~3 ~1 ~38 ~118 ~1 ~38 dirt 0  
fill ~3 ~1 ~39 ~92 ~1 ~39 dirt 0  
fill ~3 ~1 ~40 ~3 ~1 ~50 grass 0  
fill ~4 ~1 ~25 ~5 ~1 ~25 grass 0  
fill ~4 ~1 ~27 ~13 ~1 ~27 stone 0  
fill ~4 ~1 ~40 ~116 ~1 ~40 dirt 0  
fill ~4 ~1 ~41 ~116 ~1 ~41 dirt 0  
fill ~4 ~1 ~42 ~115 ~1 ~42 dirt 0  
fill ~4 ~1 ~43 ~114 ~1 ~43 dirt 0  
fill ~4 ~1 ~44 ~114 ~1 ~44 dirt 0  
fill ~4 ~1 ~45 ~113 ~1 ~45 dirt 0  
fill ~4 ~1 ~46 ~113 ~1 ~46 dirt 0  
fill ~4 ~1 ~47 ~113 ~1 ~47 dirt 0  
fill ~4 ~1 ~48 ~113 ~1 ~48 dirt 0  
fill ~4 ~1 ~49 ~112 ~1 ~49 dirt 0  
fill ~4 ~1 ~50 ~4 ~1 ~51 grass 0  
fill ~5 ~1 ~24 ~8 ~1 ~24 grass 0  
fill ~5 ~1 ~26 ~13 ~1 ~26 stone 0  
fill ~5 ~1 ~37 ~10 ~1 ~37 stone 0  
fill ~5 ~1 ~50 ~112 ~1 ~50 dirt 0  
fill ~5 ~1 ~51 ~5 ~1 ~52 grass 0  
fill ~6 ~1 ~23 ~9 ~1 ~23 grass 0  
fill ~6 ~1 ~51 ~112 ~1 ~51 dirt 0  
fill ~6 ~1 ~52 ~6 ~1 ~53 grass 0  
fill ~7 ~1 ~25 ~13 ~1 ~25 stone 0 
setblock ~7 ~1 ~52 dirt 0  
fill ~7 ~1 ~53 ~7 ~1 ~55 grass 0  
fill ~8 ~1 ~53 ~12 ~1 ~53 dirt 0  
fill ~8 ~1 ~54 ~12 ~1 ~54 dirt 0  
fill ~8 ~1 ~55 ~8 ~1 ~56 grass 0 
setblock ~9 ~1 ~22 grass 0  
fill ~9 ~1 ~24 ~12 ~1 ~24 stone 0  
fill ~9 ~1 ~52 ~9 ~3 ~52 dirt 0  
fill ~9 ~1 ~55 ~12 ~1 ~55 dirt 0  
fill ~9 ~1 ~56 ~9 ~1 ~57 grass 0 
setblock ~10 ~1 ~21 grass 0  
fill ~10 ~1 ~22 ~10 ~1 ~37 stone 0  
fill ~10 ~1 ~56 ~13 ~1 ~56 dirt 0  
fill ~10 ~1 ~57 ~106 ~1 ~57 dirt 0  
fill ~10 ~1 ~58 ~10 ~1 ~59 grass 0 
setblock ~11 ~1 ~20 grass 0 
setblock ~11 ~1 ~21 stone 0  
fill ~11 ~1 ~23 ~12 ~1 ~23 stone 0  
fill ~11 ~1 ~37 ~118 ~1 ~37 dirt 0  
fill ~11 ~1 ~52 ~13 ~1 ~52 dirt 0  
fill ~11 ~1 ~58 ~106 ~1 ~58 dirt 0  
fill ~11 ~1 ~59 ~11 ~1 ~60 grass 0 
setblock ~12 ~1 ~19 grass 0  
fill ~12 ~1 ~20 ~13 ~1 ~20 dirt 0 
setblock ~12 ~1 ~22 grass 0  
fill ~12 ~1 ~32 ~118 ~1 ~32 dirt 0  
fill ~12 ~1 ~33 ~118 ~1 ~33 dirt 0  
fill ~12 ~1 ~34 ~118 ~1 ~34 dirt 0  
fill ~12 ~1 ~35 ~118 ~1 ~35 dirt 0  
fill ~12 ~1 ~36 ~118 ~1 ~36 dirt 0  
fill ~12 ~1 ~59 ~106 ~1 ~59 dirt 0  
fill ~12 ~1 ~60 ~12 ~1 ~61 grass 0  
fill ~13 ~1 ~19 ~14 ~1 ~19 dirt 0  
fill ~13 ~1 ~22 ~115 ~1 ~22 dirt 0  
fill ~13 ~1 ~23 ~115 ~1 ~23 dirt 0  
fill ~13 ~1 ~24 ~116 ~1 ~24 dirt 0  
fill ~13 ~1 ~31 ~118 ~1 ~31 dirt 0  
fill ~13 ~1 ~53 ~17 ~1 ~53 stone 0  
fill ~13 ~1 ~54 ~17 ~1 ~54 stone 0  
fill ~13 ~1 ~55 ~17 ~1 ~55 stone 0  
fill ~13 ~1 ~60 ~106 ~1 ~60 dirt 0  
fill ~13 ~1 ~61 ~14 ~1 ~61 grass 0 
setblock ~14 ~1 ~17 grass 0  
fill ~14 ~1 ~21 ~114 ~1 ~21 dirt 0  
fill ~14 ~1 ~25 ~116 ~1 ~25 dirt 0  
fill ~14 ~1 ~26 ~116 ~1 ~26 dirt 0  
fill ~14 ~1 ~27 ~117 ~1 ~27 dirt 0  
fill ~14 ~1 ~28 ~117 ~1 ~28 dirt 0  
fill ~14 ~1 ~29 ~117 ~1 ~29 dirt 0  
fill ~14 ~1 ~30 ~118 ~1 ~30 dirt 0  
fill ~14 ~1 ~52 ~16 ~1 ~52 stone 0  
fill ~14 ~1 ~56 ~16 ~1 ~56 stone 0  
fill ~14 ~1 ~62 ~16 ~1 ~62 grass 0  
fill ~15 ~1 ~17 ~113 ~1 ~17 dirt 0 
setblock ~15 ~1 ~19 grass 0  
fill ~15 ~1 ~20 ~113 ~1 ~20 dirt 0  
fill ~15 ~1 ~61 ~107 ~1 ~61 dirt 0  
fill ~15 ~1 ~63 ~17 ~1 ~63 grass 0  
fill ~16 ~1 ~18 ~113 ~1 ~18 dirt 0  
fill ~16 ~1 ~19 ~113 ~1 ~19 dirt 0  
fill ~17 ~1 ~14 ~18 ~1 ~14 grass 0  
fill ~17 ~1 ~15 ~18 ~1 ~15 dirt 0  
fill ~17 ~1 ~52 ~110 ~1 ~52 dirt 0  
fill ~17 ~1 ~56 ~106 ~1 ~56 dirt 0  
fill ~17 ~1 ~62 ~108 ~1 ~62 dirt 0  
fill ~17 ~1 ~64 ~18 ~1 ~64 grass 0  
fill ~18 ~1 ~53 ~109 ~1 ~53 dirt 0  
fill ~18 ~1 ~54 ~108 ~1 ~54 dirt 0  
fill ~18 ~1 ~55 ~107 ~1 ~55 dirt 0  
fill ~18 ~1 ~63 ~106 ~1 ~63 dirt 0 
setblock ~19 ~1 ~13 grass 0 
setblock ~19 ~1 ~14 dirt 0  
fill ~19 ~1 ~16 ~24 ~1 ~16 dirt 0  
fill ~19 ~1 ~64 ~76 ~1 ~64 dirt 0  
fill ~19 ~1 ~65 ~20 ~1 ~65 grass 0 
setblock ~20 ~1 ~12 grass 0 
setblock ~20 ~1 ~13 dirt 0  
fill ~20 ~1 ~15 ~23 ~1 ~15 dirt 0  
fill ~20 ~1 ~66 ~21 ~1 ~66 grass 0  
fill ~21 ~1 ~11 ~23 ~1 ~11 grass 0  
fill ~21 ~1 ~14 ~22 ~1 ~14 dirt 0  
fill ~21 ~1 ~65 ~66 ~1 ~65 dirt 0  
fill ~21 ~1 ~67 ~23 ~1 ~67 grass 0  
fill ~22 ~1 ~13 ~22 ~0 ~13 dirt 0  
fill ~22 ~1 ~66 ~72 ~1 ~66 dirt 0  
fill ~23 ~1 ~13 ~44 ~1 ~13 stone 0  
fill ~23 ~1 ~14 ~41 ~1 ~14 stone 0  
fill ~24 ~1 ~10 ~26 ~1 ~10 grass 0  
fill ~24 ~1 ~15 ~39 ~1 ~15 stone 0  
fill ~24 ~1 ~67 ~64 ~1 ~67 dirt 0  
fill ~24 ~1 ~68 ~26 ~1 ~68 grass 0  
fill ~25 ~1 ~12 ~32 ~1 ~12 stone 0  
fill ~25 ~1 ~16 ~36 ~1 ~16 stone 0  
fill ~26 ~1 ~11 ~31 ~1 ~11 stone 0  
fill ~26 ~1 ~69 ~28 ~1 ~69 grass 0  
fill ~27 ~1 ~68 ~59 ~1 ~68 dirt 0  
fill ~28 ~1 ~10 ~29 ~1 ~10 stone 0  
fill ~29 ~1 ~69 ~57 ~1 ~69 dirt 0  
fill ~30 ~1 ~10 ~33 ~1 ~10 grass 0  
fill ~31 ~1 ~70 ~55 ~1 ~70 dirt 0  
fill ~32 ~1 ~71 ~53 ~1 ~71 dirt 0  
fill ~34 ~1 ~10 ~59 ~1 ~10 stone 0  
fill ~34 ~1 ~72 ~48 ~1 ~72 grass 0  
fill ~35 ~1 ~9 ~37 ~1 ~9 grass 0  
fill ~37 ~1 ~16 ~79 ~1 ~16 dirt 0  
fill ~38 ~1 ~8 ~39 ~1 ~8 grass 0  
fill ~38 ~1 ~9 ~39 ~1 ~9 stone 0  
fill ~38 ~1 ~12 ~45 ~1 ~12 stone 0  
fill ~39 ~1 ~11 ~49 ~1 ~11 stone 0  
fill ~40 ~1 ~7 ~41 ~1 ~7 grass 0  
fill ~40 ~1 ~8 ~73 ~1 ~8 stone 0  
fill ~40 ~1 ~15 ~112 ~1 ~15 dirt 0  
fill ~41 ~1 ~9 ~68 ~1 ~9 stone 0  
fill ~42 ~1 ~6 ~44 ~1 ~6 grass 0  
fill ~42 ~1 ~7 ~74 ~1 ~7 stone 0  
fill ~42 ~1 ~14 ~112 ~1 ~14 dirt 0  
fill ~45 ~1 ~5 ~47 ~1 ~5 grass 0  
fill ~45 ~1 ~6 ~47 ~1 ~6 stone 0  
fill ~45 ~1 ~13 ~113 ~1 ~13 dirt 0  
fill ~46 ~1 ~12 ~112 ~1 ~12 dirt 0  
fill ~48 ~1 ~6 ~49 ~1 ~6 grass 0  
fill ~49 ~1 ~5 ~50 ~1 ~5 grass 0  
fill ~50 ~1 ~4 ~52 ~1 ~4 grass 0  
fill ~50 ~1 ~6 ~75 ~1 ~6 stone 0  
fill ~50 ~1 ~11 ~110 ~1 ~11 dirt 0  
fill ~51 ~1 ~5 ~76 ~1 ~5 stone 0  
fill ~52 ~1 ~3 ~56 ~1 ~3 grass 0  
fill ~53 ~1 ~4 ~76 ~1 ~4 stone 0  
fill ~57 ~1 ~2 ~58 ~1 ~2 grass 0  
fill ~57 ~1 ~3 ~62 ~1 ~3 stone 0  
fill ~58 ~1 ~1 ~61 ~1 ~1 grass 0  
fill ~59 ~1 ~2 ~61 ~1 ~2 stone 0 
setblock ~60 ~1 ~10 dirt 0  
fill ~61 ~1 ~10 ~65 ~1 ~10 stone 0  
fill ~62 ~1 ~2 ~63 ~1 ~2 grass 0  
fill ~63 ~1 ~3 ~67 ~1 ~3 grass 0  
fill ~65 ~1 ~67 ~69 ~1 ~67 grass 0  
fill ~66 ~1 ~10 ~84 ~1 ~10 dirt 0  
fill ~67 ~1 ~2 ~69 ~1 ~2 grass 0  
fill ~68 ~1 ~3 ~70 ~1 ~3 stone 0  
fill ~68 ~1 ~65 ~106 ~1 ~65 dirt 0  
fill ~69 ~1 ~9 ~84 ~1 ~9 dirt 0  
fill ~71 ~1 ~3 ~74 ~1 ~3 grass 0  
fill ~73 ~1 ~66 ~106 ~1 ~66 grass 0  
fill ~74 ~1 ~8 ~84 ~1 ~8 dirt 0  
fill ~75 ~1 ~2 ~83 ~1 ~2 grass 0  
fill ~75 ~1 ~3 ~76 ~1 ~3 stone 0  
fill ~75 ~1 ~7 ~84 ~1 ~7 dirt 0  
fill ~76 ~1 ~6 ~84 ~1 ~6 dirt 0  
fill ~77 ~1 ~3 ~96 ~1 ~3 dirt 0  
fill ~77 ~1 ~4 ~84 ~1 ~4 dirt 0  
fill ~77 ~1 ~5 ~84 ~1 ~5 dirt 0  
fill ~78 ~1 ~64 ~84 ~1 ~64 dirt 0  
fill ~81 ~1 ~16 ~112 ~1 ~16 dirt 0 
setblock ~84 ~1 ~1 stone_stairs 2 
setblock ~84 ~1 ~2 cobblestone 0  
fill ~85 ~1 ~2 ~89 ~1 ~2 stone_stairs 2  
fill ~85 ~1 ~4 ~86 ~1 ~4 grass 0  
fill ~85 ~1 ~5 ~86 ~1 ~5 grass 0  
fill ~85 ~1 ~6 ~86 ~1 ~6 grass 0  
fill ~85 ~1 ~7 ~86 ~1 ~7 grass 0  
fill ~85 ~1 ~8 ~86 ~1 ~8 grass 0  
fill ~85 ~1 ~9 ~86 ~1 ~9 grass 0  
fill ~85 ~1 ~10 ~85 ~1 ~4 grass 0  
fill ~86 ~1 ~10 ~107 ~1 ~10 dirt 0  
fill ~86 ~1 ~64 ~106 ~1 ~64 dirt 0  
fill ~87 ~1 ~4 ~96 ~1 ~4 dirt 0  
fill ~87 ~1 ~5 ~96 ~1 ~5 dirt 0  
fill ~87 ~1 ~6 ~97 ~1 ~6 dirt 0  
fill ~87 ~1 ~7 ~98 ~1 ~7 dirt 0  
fill ~87 ~1 ~8 ~99 ~1 ~8 dirt 0  
fill ~87 ~1 ~9 ~101 ~1 ~9 dirt 0 
setblock ~90 ~1 ~1 stone_stairs 2 
setblock ~90 ~1 ~2 cobblestone 0  
fill ~91 ~1 ~2 ~101 ~1 ~2 grass 0  
fill ~95 ~1 ~39 ~117 ~1 ~39 dirt 0  
fill ~97 ~1 ~3 ~100 ~1 ~3 stone 0  
fill ~97 ~1 ~4 ~102 ~1 ~4 stone 0  
fill ~97 ~1 ~5 ~102 ~1 ~5 stone 0  
fill ~98 ~1 ~6 ~103 ~1 ~6 stone 0  
fill ~99 ~1 ~7 ~105 ~1 ~7 stone 0  
fill ~100 ~1 ~8 ~105 ~1 ~8 stone 0  
fill ~101 ~1 ~3 ~103 ~1 ~3 grass 0  
fill ~102 ~1 ~9 ~106 ~1 ~9 stone 0  
fill ~103 ~1 ~4 ~104 ~1 ~4 grass 0  
fill ~103 ~1 ~5 ~104 ~1 ~5 grass 0  
fill ~104 ~1 ~6 ~105 ~1 ~6 grass 0  
fill ~106 ~1 ~7 ~106 ~11 ~7 log 0 
setblock ~106 ~1 ~8 grass 0  
fill ~107 ~1 ~8 ~109 ~1 ~8 log 0  
fill ~107 ~1 ~9 ~109 ~1 ~9 grass 0  
fill ~107 ~1 ~56 ~115 ~1 ~56 stone 0  
fill ~107 ~1 ~57 ~114 ~1 ~57 stone 0  
fill ~107 ~1 ~58 ~113 ~1 ~58 stone 0  
fill ~107 ~1 ~59 ~112 ~1 ~59 stone 0  
fill ~107 ~1 ~60 ~110 ~1 ~60 stone 0  
fill ~107 ~1 ~63 ~108 ~1 ~63 grass 0  
fill ~107 ~1 ~64 ~107 ~1 ~63 grass 0  
fill ~108 ~1 ~10 ~111 ~1 ~10 grass 0  
fill ~108 ~1 ~55 ~114 ~1 ~55 stone 0  
fill ~108 ~1 ~61 ~109 ~1 ~61 stone 0  
fill ~109 ~1 ~54 ~117 ~1 ~54 stone 0 
setblock ~109 ~1 ~62 grass 0  
fill ~110 ~1 ~9 ~112 ~1 ~9 log 0  
fill ~110 ~1 ~53 ~114 ~1 ~53 stone 0 
setblock ~110 ~1 ~61 grass 0  
fill ~111 ~1 ~11 ~112 ~1 ~11 grass 0  
fill ~111 ~1 ~52 ~115 ~1 ~52 stone 0  
fill ~111 ~1 ~60 ~112 ~1 ~60 grass 0  
fill ~113 ~1 ~12 ~114 ~1 ~12 grass 0  
fill ~113 ~1 ~14 ~114 ~1 ~14 stone 0  
fill ~113 ~1 ~15 ~114 ~1 ~15 stone 0  
fill ~113 ~1 ~16 ~115 ~1 ~16 stone 0  
fill ~113 ~1 ~49 ~118 ~1 ~49 stone 0  
fill ~113 ~1 ~50 ~119 ~1 ~50 stone 0  
fill ~113 ~1 ~51 ~119 ~1 ~51 stone 0 
setblock ~113 ~1 ~59 grass 0 
setblock ~114 ~1 ~11 log 0 
setblock ~114 ~1 ~13 grass 0  
fill ~114 ~1 ~17 ~117 ~1 ~17 stone 0  
fill ~114 ~1 ~18 ~117 ~1 ~18 stone 0  
fill ~114 ~1 ~19 ~118 ~1 ~19 stone 0  
fill ~114 ~1 ~20 ~119 ~1 ~20 stone 0  
fill ~114 ~1 ~45 ~118 ~1 ~45 stone 0  
fill ~114 ~1 ~46 ~119 ~1 ~46 stone 0  
fill ~114 ~1 ~47 ~120 ~1 ~47 stone 0  
fill ~114 ~1 ~48 ~120 ~1 ~48 stone 0 
setblock ~114 ~1 ~58 grass 0  
fill ~115 ~1 ~14 ~115 ~1 ~15 grass 0  
fill ~115 ~1 ~21 ~119 ~1 ~21 stone 0  
fill ~115 ~1 ~43 ~122 ~1 ~43 stone 0  
fill ~115 ~1 ~44 ~121 ~1 ~44 stone 0 
setblock ~115 ~1 ~57 grass 0 
setblock ~116 ~1 ~14 log 0 
setblock ~116 ~1 ~16 grass 0  
fill ~116 ~1 ~22 ~120 ~1 ~22 stone 0  
fill ~116 ~1 ~23 ~120 ~1 ~23 stone 0  
fill ~116 ~1 ~42 ~123 ~1 ~42 stone 0  
fill ~116 ~1 ~53 ~117 ~1 ~53 stone 0  
fill ~116 ~1 ~55 ~116 ~0 ~55 stone 0 
setblock ~116 ~1 ~56 grass 0  
fill ~117 ~1 ~24 ~120 ~1 ~24 stone 0  
fill ~117 ~1 ~25 ~121 ~1 ~25 stone 0  
fill ~117 ~1 ~26 ~122 ~1 ~26 stone 0  
fill ~117 ~1 ~40 ~123 ~1 ~40 stone 0  
fill ~117 ~1 ~41 ~123 ~1 ~41 stone 0  
fill ~117 ~1 ~52 ~118 ~1 ~52 stone 0 
setblock ~117 ~1 ~55 grass 0  
fill ~118 ~1 ~17 ~118 ~1 ~18 grass 0  
fill ~118 ~1 ~27 ~123 ~1 ~27 stone 0  
fill ~118 ~1 ~28 ~124 ~1 ~28 stone 0  
fill ~118 ~1 ~29 ~124 ~1 ~29 stone 0  
fill ~118 ~1 ~39 ~123 ~1 ~39 stone 0  
fill ~118 ~1 ~53 ~118 ~1 ~54 grass 0  
fill ~119 ~1 ~18 ~119 ~1 ~19 grass 0  
fill ~119 ~1 ~30 ~124 ~1 ~30 stone 0  
fill ~119 ~1 ~31 ~124 ~1 ~31 stone 0  
fill ~119 ~1 ~32 ~124 ~1 ~32 stone 0  
fill ~119 ~1 ~33 ~123 ~1 ~33 stone 0  
fill ~119 ~1 ~34 ~123 ~1 ~34 stone 0  
fill ~119 ~1 ~35 ~123 ~1 ~35 stone 0  
fill ~119 ~1 ~36 ~123 ~1 ~36 stone 0  
fill ~119 ~1 ~37 ~123 ~1 ~37 stone 0  
fill ~119 ~1 ~38 ~123 ~1 ~38 stone 0 
setblock ~119 ~1 ~52 grass 0  
fill ~120 ~1 ~19 ~120 ~1 ~21 grass 0  
fill ~120 ~1 ~49 ~120 ~1 ~51 grass 0  
fill ~121 ~1 ~20 ~121 ~1 ~24 grass 0  
fill ~121 ~1 ~45 ~121 ~1 ~46 grass 0  
fill ~122 ~1 ~23 ~122 ~1 ~25 grass 0  
fill ~123 ~1 ~25 ~123 ~1 ~26 grass 0  
fill ~124 ~1 ~26 ~124 ~1 ~27 grass 0  
fill ~124 ~1 ~33 ~125 ~1 ~33 grass 0  
fill ~125 ~1 ~28 ~125 ~1 ~33 grass 0  
fill ~3 ~2 ~28 ~4 ~2 ~28 grass 0  
fill ~3 ~2 ~29 ~4 ~2 ~29 grass 0  
fill ~3 ~2 ~30 ~4 ~2 ~30 grass 0  
fill ~3 ~2 ~31 ~4 ~2 ~31 grass 0  
fill ~3 ~2 ~32 ~3 ~2 ~39 grass 0  
fill ~4 ~2 ~27 ~5 ~2 ~27 grass 0  
fill ~4 ~2 ~32 ~12 ~2 ~32 stone 0  
fill ~4 ~2 ~33 ~12 ~2 ~33 stone 0  
fill ~4 ~2 ~34 ~12 ~2 ~34 stone 0  
fill ~4 ~2 ~35 ~12 ~2 ~35 stone 0  
fill ~4 ~2 ~36 ~12 ~2 ~36 stone 0  
fill ~4 ~2 ~37 ~12 ~2 ~37 stone 0  
fill ~4 ~2 ~38 ~5 ~2 ~38 dirt 0  
fill ~4 ~2 ~39 ~92 ~2 ~39 dirt 0  
fill ~4 ~2 ~40 ~4 ~2 ~49 grass 0  
fill ~5 ~2 ~26 ~6 ~2 ~26 grass 0  
fill ~5 ~2 ~28 ~14 ~2 ~28 stone 0  
fill ~5 ~2 ~29 ~14 ~2 ~29 stone 0  
fill ~5 ~2 ~30 ~13 ~2 ~30 stone 0  
fill ~5 ~2 ~31 ~13 ~2 ~31 stone 0  
fill ~5 ~2 ~40 ~116 ~2 ~40 dirt 0  
fill ~5 ~2 ~41 ~116 ~2 ~41 dirt 0  
fill ~5 ~2 ~42 ~115 ~2 ~42 dirt 0  
fill ~5 ~2 ~43 ~114 ~2 ~43 dirt 0  
fill ~5 ~2 ~44 ~113 ~2 ~44 dirt 0  
fill ~5 ~2 ~45 ~113 ~2 ~45 dirt 0  
fill ~5 ~2 ~46 ~113 ~2 ~46 dirt 0  
fill ~5 ~2 ~47 ~113 ~2 ~47 dirt 0  
fill ~5 ~2 ~48 ~112 ~2 ~48 dirt 0  
fill ~5 ~2 ~49 ~5 ~2 ~50 grass 0  
fill ~6 ~2 ~25 ~8 ~2 ~25 grass 0  
fill ~6 ~2 ~27 ~14 ~2 ~27 stone 0  
fill ~6 ~2 ~38 ~11 ~2 ~38 stone 0  
fill ~6 ~2 ~49 ~112 ~2 ~49 dirt 0  
fill ~6 ~2 ~50 ~111 ~2 ~50 dirt 0 
setblock ~6 ~2 ~51 grass 0  
fill ~7 ~2 ~26 ~13 ~2 ~26 stone 0  
fill ~7 ~2 ~51 ~12 ~2 ~51 dirt 0 
setblock ~7 ~2 ~52 grass 0 
setblock ~8 ~2 ~52 dirt 0  
fill ~8 ~2 ~53 ~8 ~2 ~54 grass 0 
setblock ~9 ~2 ~24 grass 0  
fill ~9 ~2 ~25 ~13 ~2 ~25 stone 0  
fill ~9 ~2 ~53 ~11 ~2 ~53 dirt 0  
fill ~9 ~2 ~54 ~9 ~2 ~55 grass 0  
fill ~10 ~2 ~22 ~11 ~2 ~22 grass 0  
fill ~10 ~2 ~23 ~12 ~2 ~23 stone 0  
fill ~10 ~2 ~24 ~13 ~2 ~24 stone 0  
fill ~10 ~2 ~52 ~11 ~2 ~52 dirt 0  
fill ~10 ~2 ~54 ~11 ~2 ~54 dirt 0  
fill ~10 ~2 ~55 ~10 ~2 ~57 grass 0 
setblock ~11 ~2 ~21 grass 0  
fill ~11 ~2 ~55 ~11 ~2 ~56 dirt 0  
fill ~11 ~2 ~57 ~11 ~2 ~58 grass 0 
setblock ~12 ~2 ~20 grass 0  
fill ~12 ~2 ~38 ~118 ~2 ~38 dirt 0  
fill ~12 ~2 ~52 ~18 ~2 ~52 stone 0  
fill ~12 ~2 ~53 ~19 ~2 ~53 stone 0  
fill ~12 ~2 ~54 ~19 ~2 ~54 stone 0  
fill ~12 ~2 ~55 ~19 ~2 ~55 stone 0  
fill ~12 ~2 ~56 ~18 ~2 ~56 stone 0  
fill ~12 ~2 ~57 ~12 ~2 ~58 dirt 0  
fill ~12 ~2 ~59 ~13 ~2 ~59 grass 0 
setblock ~13 ~2 ~19 grass 0 
setblock ~13 ~2 ~20 dirt 0  
fill ~13 ~2 ~22 ~115 ~2 ~22 dirt 0  
fill ~13 ~2 ~23 ~115 ~2 ~23 dirt 0  
fill ~13 ~2 ~32 ~118 ~2 ~32 dirt 0  
fill ~13 ~2 ~33 ~118 ~2 ~33 dirt 0  
fill ~13 ~2 ~34 ~118 ~2 ~34 dirt 0  
fill ~13 ~2 ~35 ~119 ~2 ~35 dirt 0  
fill ~13 ~2 ~36 ~119 ~2 ~36 dirt 0  
fill ~13 ~2 ~37 ~119 ~2 ~37 dirt 0  
fill ~13 ~2 ~51 ~17 ~2 ~51 stone 0  
fill ~13 ~2 ~57 ~17 ~2 ~57 stone 0  
fill ~13 ~2 ~58 ~104 ~2 ~58 dirt 0  
fill ~13 ~2 ~60 ~15 ~2 ~60 grass 0 
setblock ~14 ~2 ~18 grass 0 
setblock ~14 ~2 ~19 dirt 0  
fill ~14 ~2 ~21 ~114 ~2 ~21 dirt 0  
fill ~14 ~2 ~24 ~116 ~2 ~24 dirt 0  
fill ~14 ~2 ~25 ~116 ~2 ~25 dirt 0  
fill ~14 ~2 ~26 ~116 ~2 ~26 dirt 0  
fill ~14 ~2 ~30 ~118 ~2 ~30 dirt 0  
fill ~14 ~2 ~31 ~119 ~2 ~31 dirt 0  
fill ~14 ~2 ~59 ~104 ~2 ~59 dirt 0 
setblock ~15 ~2 ~17 grass 0  
fill ~15 ~2 ~20 ~114 ~2 ~20 dirt 0  
fill ~15 ~2 ~27 ~117 ~2 ~27 dirt 0  
fill ~15 ~2 ~28 ~117 ~2 ~28 dirt 0  
fill ~15 ~2 ~29 ~117 ~2 ~29 dirt 0  
fill ~15 ~2 ~61 ~17 ~2 ~61 grass 0 
setblock ~16 ~2 ~16 grass 0  
fill ~16 ~2 ~17 ~25 ~2 ~17 dirt 0  
fill ~16 ~2 ~18 ~113 ~2 ~18 dirt 0  
fill ~16 ~2 ~19 ~113 ~2 ~19 dirt 0  
fill ~16 ~2 ~60 ~104 ~2 ~60 dirt 0  
fill ~17 ~2 ~15 ~18 ~2 ~15 grass 0  
fill ~17 ~2 ~62 ~18 ~2 ~62 grass 0  
fill ~18 ~2 ~51 ~111 ~2 ~51 dirt 0  
fill ~18 ~2 ~57 ~105 ~2 ~57 dirt 0  
fill ~18 ~2 ~61 ~105 ~2 ~61 dirt 0  
fill ~18 ~2 ~63 ~19 ~2 ~63 grass 0 
setblock ~19 ~2 ~14 grass 0  
fill ~19 ~2 ~16 ~23 ~2 ~16 dirt 0  
fill ~19 ~2 ~52 ~109 ~2 ~52 dirt 0  
fill ~19 ~2 ~56 ~106 ~2 ~56 dirt 0  
fill ~19 ~2 ~62 ~106 ~2 ~62 dirt 0  
fill ~19 ~2 ~64 ~21 ~2 ~64 grass 0 
setblock ~20 ~2 ~13 grass 0  
fill ~20 ~2 ~15 ~22 ~2 ~15 dirt 0  
fill ~20 ~2 ~53 ~108 ~2 ~53 dirt 0  
fill ~20 ~2 ~54 ~107 ~2 ~54 dirt 0  
fill ~20 ~2 ~55 ~106 ~2 ~55 dirt 0  
fill ~20 ~2 ~63 ~106 ~2 ~63 dirt 0  
fill ~21 ~2 ~12 ~23 ~2 ~12 grass 0  
fill ~21 ~2 ~14 ~22 ~2 ~14 dirt 0  
fill ~21 ~2 ~65 ~23 ~2 ~65 grass 0  
fill ~22 ~2 ~13 ~47 ~2 ~13 stone 0  
fill ~22 ~2 ~64 ~106 ~2 ~64 dirt 0  
fill ~22 ~2 ~66 ~26 ~2 ~66 grass 0  
fill ~23 ~2 ~14 ~43 ~2 ~14 stone 0  
fill ~23 ~2 ~15 ~40 ~2 ~15 stone 0 
setblock ~24 ~2 ~11 grass 0  
fill ~24 ~2 ~16 ~37 ~2 ~16 stone 0  
fill ~24 ~2 ~65 ~71 ~2 ~65 dirt 0  
fill ~24 ~2 ~67 ~28 ~2 ~67 grass 0  
fill ~25 ~2 ~12 ~32 ~2 ~12 stone 0  
fill ~26 ~2 ~11 ~31 ~2 ~11 stone 0  
fill ~26 ~2 ~17 ~35 ~2 ~17 stone 0  
fill ~27 ~2 ~10 ~29 ~2 ~10 grass 0  
fill ~27 ~2 ~66 ~64 ~2 ~66 dirt 0  
fill ~27 ~2 ~68 ~30 ~2 ~68 grass 0  
fill ~29 ~2 ~67 ~59 ~2 ~67 dirt 0  
fill ~29 ~2 ~69 ~31 ~2 ~69 grass 0  
fill ~31 ~2 ~68 ~57 ~2 ~68 dirt 0  
fill ~31 ~2 ~70 ~32 ~2 ~70 grass 0  
fill ~32 ~2 ~69 ~36 ~2 ~69 dirt 0  
fill ~32 ~2 ~71 ~53 ~2 ~71 grass 0  
fill ~33 ~2 ~70 ~50 ~2 ~70 dirt 0  
fill ~34 ~2 ~10 ~37 ~2 ~10 grass 0  
fill ~36 ~2 ~17 ~113 ~2 ~17 dirt 0  
fill ~38 ~2 ~9 ~39 ~2 ~9 grass 0  
fill ~38 ~2 ~10 ~66 ~2 ~10 stone 0  
fill ~38 ~2 ~12 ~48 ~2 ~12 stone 0  
fill ~38 ~2 ~16 ~79 ~2 ~16 dirt 0  
fill ~38 ~2 ~69 ~38 ~3 ~69 dirt 0  
fill ~39 ~2 ~11 ~58 ~2 ~11 stone 0 
setblock ~39 ~2 ~69 grass 0  
fill ~40 ~2 ~8 ~41 ~2 ~8 grass 0  
fill ~40 ~2 ~69 ~55 ~2 ~69 dirt 0  
fill ~41 ~2 ~9 ~68 ~2 ~9 stone 0  
fill ~41 ~2 ~15 ~92 ~2 ~15 dirt 0  
fill ~42 ~2 ~7 ~43 ~2 ~7 grass 0  
fill ~42 ~2 ~8 ~73 ~2 ~8 stone 0  
fill ~44 ~2 ~7 ~48 ~2 ~7 stone 0  
fill ~44 ~2 ~14 ~112 ~2 ~14 dirt 0  
fill ~45 ~2 ~6 ~47 ~2 ~6 grass 0  
fill ~48 ~2 ~13 ~111 ~2 ~13 dirt 0 
setblock ~49 ~2 ~7 grass 0  
fill ~49 ~2 ~12 ~107 ~2 ~12 dirt 0  
fill ~50 ~2 ~6 ~52 ~2 ~6 grass 0  
fill ~50 ~2 ~7 ~74 ~2 ~7 stone 0  
fill ~51 ~2 ~5 ~53 ~2 ~5 grass 0  
fill ~51 ~2 ~70 ~55 ~2 ~70 grass 0  
fill ~53 ~2 ~4 ~56 ~2 ~4 grass 0  
fill ~53 ~2 ~6 ~75 ~2 ~6 stone 0  
fill ~54 ~2 ~5 ~76 ~2 ~5 stone 0  
fill ~56 ~2 ~69 ~57 ~2 ~69 grass 0  
fill ~57 ~2 ~3 ~62 ~2 ~3 grass 0  
fill ~57 ~2 ~4 ~61 ~2 ~4 stone 0  
fill ~58 ~2 ~68 ~59 ~2 ~68 grass 0  
fill ~59 ~2 ~2 ~61 ~2 ~2 grass 0  
fill ~59 ~2 ~11 ~106 ~2 ~11 dirt 0  
fill ~60 ~2 ~67 ~64 ~2 ~67 grass 0  
fill ~62 ~2 ~4 ~68 ~2 ~4 grass 0  
fill ~65 ~2 ~66 ~72 ~2 ~66 grass 0  
fill ~67 ~2 ~10 ~84 ~2 ~10 dirt 0  
fill ~68 ~2 ~3 ~70 ~2 ~3 grass 0  
fill ~69 ~2 ~4 ~70 ~2 ~4 stone 0  
fill ~69 ~2 ~9 ~84 ~2 ~9 dirt 0  
fill ~71 ~2 ~4 ~79 ~2 ~4 grass 0  
fill ~72 ~2 ~65 ~106 ~2 ~65 grass 0  
fill ~74 ~2 ~8 ~84 ~2 ~8 dirt 0  
fill ~75 ~2 ~3 ~83 ~2 ~3 grass 0  
fill ~75 ~2 ~7 ~84 ~2 ~7 dirt 0  
fill ~76 ~2 ~6 ~84 ~2 ~6 dirt 0  
fill ~77 ~2 ~5 ~84 ~2 ~5 dirt 0  
fill ~80 ~2 ~4 ~80 ~13 ~4 log 0  
fill ~81 ~2 ~4 ~81 ~3 ~4 cobblestone 0  
fill ~81 ~2 ~16 ~113 ~2 ~16 dirt 0  
fill ~82 ~2 ~4 ~84 ~2 ~4 dirt 0 
setblock ~84 ~2 ~2 stone_stairs 2 
setblock ~84 ~2 ~3 cobblestone 0  
fill ~85 ~2 ~3 ~89 ~2 ~3 stone_stairs 2  
fill ~86 ~2 ~9 ~86 ~2 ~10 glowstone 0  
fill ~87 ~2 ~4 ~88 ~2 ~4 grass 0  
fill ~87 ~2 ~5 ~96 ~2 ~5 dirt 0  
fill ~87 ~2 ~6 ~97 ~2 ~6 dirt 0  
fill ~87 ~2 ~7 ~98 ~2 ~7 dirt 0  
fill ~87 ~2 ~8 ~99 ~2 ~8 dirt 0  
fill ~87 ~2 ~9 ~101 ~2 ~9 dirt 0  
fill ~87 ~2 ~10 ~105 ~2 ~10 dirt 0  
fill ~89 ~2 ~4 ~96 ~2 ~4 dirt 0 
setblock ~90 ~2 ~2 stone_stairs 2 
setblock ~90 ~2 ~3 cobblestone 0  
fill ~91 ~2 ~3 ~100 ~2 ~3 grass 0  
fill ~94 ~2 ~15 ~113 ~2 ~15 dirt 0  
fill ~95 ~2 ~39 ~117 ~2 ~39 dirt 0  
fill ~97 ~2 ~4 ~99 ~2 ~4 stone 0  
fill ~97 ~2 ~5 ~100 ~2 ~5 stone 0  
fill ~98 ~2 ~6 ~101 ~2 ~6 stone 0  
fill ~99 ~2 ~7 ~102 ~2 ~7 stone 0  
fill ~100 ~2 ~4 ~102 ~2 ~4 grass 0  
fill ~100 ~2 ~8 ~103 ~2 ~8 stone 0  
fill ~101 ~2 ~5 ~102 ~2 ~5 grass 0  
fill ~102 ~2 ~6 ~103 ~2 ~6 grass 0  
fill ~102 ~2 ~9 ~104 ~2 ~9 stone 0  
fill ~104 ~2 ~7 ~104 ~11 ~7 log 0  
fill ~104 ~2 ~8 ~105 ~2 ~8 grass 0  
fill ~105 ~2 ~7 ~105 ~3 ~7 cobblestone 0  
fill ~105 ~2 ~9 ~106 ~2 ~9 grass 0  
fill ~105 ~2 ~58 ~112 ~2 ~58 stone 0  
fill ~105 ~2 ~59 ~111 ~2 ~59 stone 0  
fill ~105 ~2 ~60 ~108 ~2 ~60 stone 0  
fill ~106 ~2 ~10 ~107 ~2 ~10 grass 0  
fill ~106 ~2 ~57 ~113 ~2 ~57 stone 0  
fill ~106 ~2 ~61 ~107 ~2 ~61 stone 0  
fill ~107 ~2 ~8 ~107 ~11 ~8 log 0  
fill ~107 ~2 ~11 ~110 ~2 ~11 grass 0  
fill ~107 ~2 ~55 ~115 ~2 ~55 stone 0  
fill ~107 ~2 ~56 ~114 ~2 ~56 stone 0  
fill ~107 ~2 ~62 ~108 ~2 ~62 grass 0  
fill ~108 ~2 ~8 ~108 ~3 ~8 cobblestone 0  
fill ~108 ~2 ~12 ~112 ~2 ~12 grass 0  
fill ~108 ~2 ~54 ~116 ~2 ~54 stone 0  
fill ~108 ~2 ~61 ~109 ~2 ~61 grass 0  
fill ~109 ~2 ~8 ~109 ~11 ~8 log 0  
fill ~109 ~2 ~53 ~117 ~2 ~53 stone 0  
fill ~109 ~2 ~60 ~110 ~2 ~60 grass 0  
fill ~110 ~2 ~9 ~110 ~11 ~9 log 0  
fill ~110 ~2 ~52 ~115 ~2 ~52 stone 0  
fill ~111 ~2 ~9 ~111 ~3 ~9 cobblestone 0  
fill ~112 ~2 ~13 ~113 ~2 ~13 grass 0  
fill ~112 ~2 ~50 ~118 ~2 ~50 stone 0  
fill ~112 ~2 ~51 ~118 ~2 ~51 stone 0 
setblock ~112 ~2 ~59 grass 0  
fill ~113 ~2 ~14 ~114 ~2 ~14 grass 0  
fill ~113 ~2 ~48 ~119 ~2 ~48 stone 0  
fill ~113 ~2 ~49 ~119 ~2 ~49 stone 0 
setblock ~113 ~2 ~58 grass 0  
fill ~114 ~2 ~11 ~114 ~3 ~11 cobblestone 0  
fill ~114 ~2 ~15 ~114 ~2 ~16 grass 0  
fill ~114 ~2 ~17 ~114 ~0 ~17 stone 0  
fill ~114 ~2 ~18 ~115 ~2 ~18 stone 0  
fill ~114 ~2 ~19 ~116 ~2 ~19 stone 0  
fill ~114 ~2 ~44 ~120 ~2 ~44 stone 0  
fill ~114 ~2 ~45 ~118 ~2 ~45 stone 0  
fill ~114 ~2 ~46 ~119 ~2 ~46 stone 0  
fill ~114 ~2 ~47 ~119 ~2 ~47 stone 0 
setblock ~114 ~2 ~57 grass 0  
fill ~115 ~2 ~16 ~115 ~2 ~17 grass 0  
fill ~115 ~2 ~20 ~118 ~2 ~20 stone 0  
fill ~115 ~2 ~21 ~118 ~2 ~21 stone 0  
fill ~115 ~2 ~43 ~120 ~2 ~43 stone 0 
setblock ~115 ~2 ~56 grass 0  
fill ~116 ~2 ~14 ~116 ~3 ~14 cobblestone 0  
fill ~116 ~2 ~17 ~116 ~2 ~18 grass 0  
fill ~116 ~2 ~22 ~118 ~2 ~22 stone 0  
fill ~116 ~2 ~23 ~119 ~2 ~23 stone 0  
fill ~116 ~2 ~42 ~121 ~2 ~42 stone 0 
setblock ~116 ~2 ~55 grass 0  
fill ~117 ~2 ~17 ~117 ~3 ~17 cobblestone 0  
fill ~117 ~2 ~18 ~117 ~11 ~18 log 0 
setblock ~117 ~2 ~19 grass 0  
fill ~117 ~2 ~24 ~120 ~2 ~24 stone 0  
fill ~117 ~2 ~25 ~118 ~2 ~25 stone 0  
fill ~117 ~2 ~26 ~119 ~2 ~26 stone 0  
fill ~117 ~2 ~40 ~122 ~2 ~40 stone 0  
fill ~117 ~2 ~41 ~122 ~2 ~41 stone 0  
fill ~117 ~2 ~52 ~117 ~0 ~52 stone 0 
setblock ~117 ~2 ~54 grass 0  
fill ~118 ~2 ~19 ~118 ~11 ~19 log 0  
fill ~118 ~2 ~27 ~122 ~2 ~27 stone 0  
fill ~118 ~2 ~28 ~122 ~2 ~28 stone 0  
fill ~118 ~2 ~29 ~122 ~2 ~29 stone 0  
fill ~118 ~2 ~39 ~122 ~2 ~39 stone 0 
setblock ~118 ~2 ~52 grass 0  
fill ~119 ~2 ~20 ~119 ~2 ~21 grass 0  
fill ~119 ~2 ~22 ~119 ~11 ~22 log 0  
fill ~119 ~2 ~25 ~120 ~2 ~25 grass 0  
fill ~119 ~2 ~30 ~122 ~2 ~30 stone 0  
fill ~119 ~2 ~32 ~122 ~2 ~32 stone 0  
fill ~119 ~2 ~33 ~122 ~2 ~33 stone 0  
fill ~119 ~2 ~34 ~122 ~2 ~34 stone 0  
fill ~119 ~2 ~38 ~122 ~2 ~38 stone 0 
setblock ~119 ~2 ~45 log 0  
fill ~119 ~2 ~50 ~119 ~2 ~51 grass 0  
fill ~120 ~2 ~22 ~120 ~2 ~23 grass 0  
fill ~120 ~2 ~26 ~121 ~2 ~26 grass 0  
fill ~120 ~2 ~31 ~122 ~2 ~31 stone 0  
fill ~120 ~2 ~35 ~122 ~2 ~35 stone 0  
fill ~120 ~2 ~36 ~122 ~2 ~36 stone 0  
fill ~120 ~2 ~37 ~122 ~2 ~37 stone 0  
fill ~120 ~2 ~45 ~120 ~2 ~48 grass 0  
fill ~121 ~2 ~25 ~121 ~3 ~25 cobblestone 0  
fill ~121 ~2 ~43 ~122 ~2 ~43 grass 0  
fill ~121 ~2 ~44 ~121 ~2 ~43 grass 0  
fill ~122 ~2 ~26 ~122 ~17 ~26 log 0  
fill ~122 ~2 ~42 ~123 ~2 ~42 grass 0  
fill ~123 ~2 ~27 ~123 ~2 ~42 grass 0  
fill ~124 ~2 ~28 ~124 ~2 ~32 grass 0  
fill ~4 ~3 ~32 ~5 ~3 ~32 grass 0  
fill ~4 ~3 ~33 ~4 ~3 ~39 grass 0  
fill ~5 ~3 ~28 ~7 ~3 ~28 grass 0  
fill ~5 ~3 ~29 ~6 ~3 ~29 grass 0  
fill ~5 ~3 ~30 ~5 ~3 ~32 grass 0  
fill ~5 ~3 ~33 ~13 ~3 ~33 stone 0  
fill ~5 ~3 ~34 ~13 ~3 ~34 stone 0  
fill ~5 ~3 ~35 ~13 ~3 ~35 stone 0  
fill ~5 ~3 ~36 ~13 ~3 ~36 stone 0  
fill ~5 ~3 ~37 ~13 ~3 ~37 stone 0  
fill ~5 ~3 ~38 ~13 ~3 ~38 stone 0  
fill ~5 ~3 ~39 ~6 ~3 ~39 dirt 0  
fill ~5 ~3 ~40 ~116 ~3 ~40 dirt 0  
fill ~5 ~3 ~41 ~5 ~3 ~48 grass 0  
fill ~6 ~3 ~27 ~8 ~3 ~27 grass 0  
fill ~6 ~3 ~30 ~14 ~3 ~30 stone 0  
fill ~6 ~3 ~31 ~13 ~3 ~31 stone 0  
fill ~6 ~3 ~32 ~12 ~3 ~32 stone 0  
fill ~6 ~3 ~41 ~116 ~3 ~41 dirt 0  
fill ~6 ~3 ~42 ~115 ~3 ~42 dirt 0  
fill ~6 ~3 ~43 ~114 ~3 ~43 dirt 0  
fill ~6 ~3 ~44 ~113 ~3 ~44 dirt 0  
fill ~6 ~3 ~45 ~113 ~3 ~45 dirt 0  
fill ~6 ~3 ~46 ~113 ~3 ~46 dirt 0  
fill ~6 ~3 ~47 ~113 ~3 ~47 dirt 0  
fill ~6 ~3 ~48 ~6 ~3 ~50 grass 0  
fill ~7 ~3 ~26 ~8 ~3 ~26 grass 0  
fill ~7 ~3 ~29 ~14 ~3 ~29 stone 0  
fill ~7 ~3 ~39 ~12 ~3 ~39 stone 0  
fill ~7 ~3 ~48 ~112 ~3 ~48 dirt 0  
fill ~7 ~3 ~49 ~111 ~3 ~49 dirt 0  
fill ~7 ~3 ~50 ~7 ~3 ~51 grass 0  
fill ~8 ~3 ~28 ~15 ~3 ~28 stone 0  
fill ~8 ~3 ~50 ~12 ~3 ~50 dirt 0  
fill ~8 ~3 ~51 ~8 ~3 ~52 grass 0 
setblock ~9 ~3 ~25 grass 0  
fill ~9 ~3 ~26 ~16 ~3 ~26 stone 0  
fill ~9 ~3 ~27 ~16 ~3 ~27 stone 0  
fill ~9 ~3 ~51 ~11 ~3 ~51 dirt 0  
fill ~9 ~3 ~53 ~10 ~3 ~53 grass 0  
fill ~10 ~3 ~23 ~11 ~3 ~23 grass 0  
fill ~10 ~3 ~24 ~15 ~3 ~24 stone 0  
fill ~10 ~3 ~25 ~16 ~3 ~25 stone 0  
fill ~10 ~3 ~52 ~10 ~2 ~52 dirt 0  
fill ~10 ~3 ~54 ~12 ~3 ~54 grass 0  
fill ~11 ~3 ~52 ~20 ~3 ~52 stone 0  
fill ~11 ~3 ~53 ~20 ~3 ~53 stone 0  
fill ~11 ~3 ~55 ~12 ~3 ~55 grass 0  
fill ~11 ~3 ~56 ~12 ~3 ~56 grass 0  
fill ~12 ~3 ~21 ~13 ~3 ~21 grass 0  
fill ~12 ~3 ~23 ~12 ~4 ~23 stone 0  
fill ~12 ~3 ~51 ~19 ~3 ~51 stone 0  
fill ~12 ~3 ~57 ~13 ~3 ~57 grass 0  
fill ~12 ~3 ~58 ~14 ~3 ~58 grass 0 
setblock ~13 ~3 ~20 grass 0  
fill ~13 ~3 ~22 ~91 ~3 ~22 dirt 0  
fill ~13 ~3 ~23 ~115 ~3 ~23 dirt 0  
fill ~13 ~3 ~32 ~115 ~3 ~32 dirt 0  
fill ~13 ~3 ~39 ~92 ~3 ~39 dirt 0  
fill ~13 ~3 ~50 ~17 ~3 ~50 stone 0  
fill ~13 ~3 ~54 ~20 ~3 ~54 stone 0  
fill ~13 ~3 ~55 ~20 ~3 ~55 stone 0  
fill ~13 ~3 ~56 ~20 ~3 ~56 stone 0  
fill ~14 ~3 ~19 ~15 ~3 ~19 grass 0  
fill ~14 ~3 ~21 ~90 ~3 ~21 dirt 0  
fill ~14 ~3 ~31 ~115 ~3 ~31 dirt 0  
fill ~14 ~3 ~33 ~114 ~3 ~33 dirt 0  
fill ~14 ~3 ~34 ~70 ~3 ~34 dirt 0  
fill ~14 ~3 ~35 ~112 ~3 ~35 dirt 0  
fill ~14 ~3 ~36 ~112 ~3 ~36 dirt 0  
fill ~14 ~3 ~37 ~113 ~3 ~37 dirt 0  
fill ~14 ~3 ~38 ~115 ~3 ~38 dirt 0  
fill ~14 ~3 ~57 ~19 ~3 ~57 stone 0  
fill ~14 ~3 ~59 ~15 ~3 ~59 grass 0  
fill ~15 ~3 ~18 ~16 ~3 ~18 grass 0  
fill ~15 ~3 ~20 ~113 ~3 ~20 dirt 0  
fill ~15 ~3 ~29 ~111 ~3 ~29 dirt 0  
fill ~15 ~3 ~30 ~112 ~3 ~30 dirt 0  
fill ~15 ~3 ~58 ~17 ~3 ~58 stone 0 
setblock ~16 ~3 ~17 grass 0  
fill ~16 ~3 ~19 ~113 ~3 ~19 dirt 0  
fill ~16 ~3 ~24 ~115 ~3 ~24 dirt 0  
fill ~16 ~3 ~28 ~111 ~3 ~28 dirt 0  
fill ~16 ~3 ~59 ~99 ~3 ~59 dirt 0  
fill ~16 ~3 ~60 ~17 ~3 ~60 grass 0  
fill ~17 ~3 ~16 ~18 ~3 ~16 grass 0  
fill ~17 ~3 ~17 ~24 ~3 ~17 dirt 0  
fill ~17 ~3 ~18 ~112 ~3 ~18 dirt 0  
fill ~17 ~3 ~25 ~114 ~3 ~25 dirt 0  
fill ~17 ~3 ~26 ~113 ~3 ~26 dirt 0  
fill ~17 ~3 ~27 ~112 ~3 ~27 dirt 0  
fill ~18 ~3 ~50 ~111 ~3 ~50 dirt 0  
fill ~18 ~3 ~58 ~100 ~3 ~58 dirt 0  
fill ~18 ~3 ~60 ~99 ~3 ~60 dirt 0  
fill ~18 ~3 ~61 ~19 ~3 ~61 grass 0 
setblock ~19 ~3 ~15 grass 0  
fill ~19 ~3 ~16 ~23 ~3 ~16 dirt 0  
fill ~19 ~3 ~62 ~20 ~3 ~62 grass 0 
setblock ~20 ~3 ~14 grass 0  
fill ~20 ~3 ~15 ~22 ~3 ~15 dirt 0  
fill ~20 ~3 ~51 ~110 ~3 ~51 dirt 0  
fill ~20 ~3 ~57 ~103 ~3 ~57 dirt 0  
fill ~20 ~3 ~61 ~99 ~3 ~61 dirt 0  
fill ~20 ~3 ~63 ~21 ~3 ~63 grass 0  
fill ~21 ~3 ~13 ~22 ~3 ~13 grass 0  
fill ~21 ~3 ~14 ~21 ~0 ~14 dirt 0  
fill ~21 ~3 ~52 ~109 ~3 ~52 dirt 0  
fill ~21 ~3 ~53 ~108 ~3 ~53 dirt 0  
fill ~21 ~3 ~54 ~107 ~3 ~54 dirt 0  
fill ~21 ~3 ~55 ~106 ~3 ~55 dirt 0  
fill ~21 ~3 ~56 ~104 ~3 ~56 dirt 0  
fill ~21 ~3 ~62 ~100 ~3 ~62 dirt 0  
fill ~22 ~3 ~14 ~48 ~3 ~14 stone 0  
fill ~22 ~3 ~63 ~106 ~3 ~63 dirt 0  
fill ~22 ~3 ~64 ~24 ~3 ~64 grass 0  
fill ~23 ~3 ~13 ~49 ~3 ~13 stone 0  
fill ~23 ~3 ~15 ~40 ~3 ~15 stone 0  
fill ~24 ~3 ~16 ~37 ~3 ~16 stone 0  
fill ~24 ~3 ~65 ~27 ~3 ~65 grass 0  
fill ~25 ~3 ~11 ~37 ~3 ~11 grass 0  
fill ~25 ~3 ~12 ~33 ~3 ~12 stone 0  
fill ~25 ~3 ~17 ~36 ~3 ~17 stone 0  
fill ~25 ~3 ~64 ~74 ~3 ~64 dirt 0  
fill ~27 ~3 ~66 ~29 ~3 ~66 grass 0  
fill ~28 ~3 ~65 ~64 ~3 ~65 dirt 0  
fill ~29 ~3 ~67 ~30 ~3 ~67 grass 0  
fill ~30 ~3 ~66 ~59 ~3 ~66 dirt 0  
fill ~31 ~3 ~67 ~56 ~3 ~67 dirt 0  
fill ~31 ~3 ~68 ~32 ~3 ~68 grass 0  
fill ~32 ~3 ~69 ~34 ~3 ~69 grass 0  
fill ~33 ~3 ~68 ~51 ~3 ~68 dirt 0  
fill ~33 ~3 ~70 ~50 ~3 ~70 grass 0  
fill ~35 ~3 ~69 ~38 ~3 ~69 dirt 0  
fill ~37 ~3 ~17 ~112 ~3 ~17 dirt 0  
fill ~38 ~3 ~10 ~39 ~3 ~10 grass 0  
fill ~38 ~3 ~12 ~55 ~3 ~12 stone 0  
fill ~38 ~3 ~16 ~79 ~3 ~16 dirt 0  
fill ~39 ~3 ~11 ~59 ~3 ~11 stone 0 
setblock ~40 ~3 ~9 grass 0  
fill ~40 ~3 ~10 ~66 ~3 ~10 stone 0  
fill ~40 ~3 ~69 ~47 ~3 ~69 dirt 0  
fill ~41 ~3 ~9 ~68 ~3 ~9 stone 0  
fill ~41 ~3 ~15 ~92 ~3 ~15 dirt 0 
setblock ~42 ~3 ~8 grass 0  
fill ~43 ~3 ~8 ~47 ~3 ~8 stone 0  
fill ~44 ~3 ~7 ~48 ~3 ~7 grass 0 
setblock ~48 ~3 ~8 grass 0  
fill ~48 ~3 ~69 ~55 ~3 ~69 grass 0  
fill ~49 ~3 ~8 ~69 ~3 ~8 stone 0  
fill ~49 ~3 ~14 ~105 ~3 ~14 dirt 0  
fill ~50 ~3 ~7 ~68 ~3 ~7 stone 0  
fill ~50 ~3 ~13 ~105 ~3 ~13 dirt 0  
fill ~52 ~3 ~68 ~57 ~3 ~68 grass 0  
fill ~53 ~3 ~6 ~56 ~3 ~6 grass 0  
fill ~54 ~3 ~5 ~58 ~3 ~5 grass 0  
fill ~56 ~3 ~12 ~104 ~3 ~12 dirt 0  
fill ~57 ~3 ~4 ~61 ~3 ~4 grass 0  
fill ~57 ~3 ~6 ~68 ~3 ~6 stone 0  
fill ~57 ~3 ~67 ~59 ~3 ~67 grass 0  
fill ~59 ~3 ~5 ~63 ~3 ~5 stone 0  
fill ~60 ~3 ~11 ~103 ~3 ~11 dirt 0  
fill ~60 ~3 ~66 ~64 ~3 ~66 grass 0  
fill ~64 ~3 ~5 ~66 ~3 ~5 grass 0  
fill ~65 ~3 ~65 ~71 ~3 ~65 grass 0  
fill ~67 ~3 ~5 ~68 ~3 ~5 stone 0  
fill ~67 ~3 ~10 ~84 ~3 ~10 dirt 0  
fill ~69 ~3 ~4 ~70 ~3 ~4 grass 0  
fill ~69 ~3 ~5 ~78 ~3 ~5 grass 0  
fill ~69 ~3 ~6 ~74 ~3 ~6 grass 0  
fill ~69 ~3 ~7 ~69 ~3 ~4 grass 0  
fill ~69 ~3 ~9 ~69 ~5 ~9 dirt 0  
fill ~70 ~3 ~7 ~74 ~3 ~7 stone 0  
fill ~70 ~3 ~8 ~71 ~3 ~8 grass 0  
fill ~70 ~3 ~9 ~71 ~3 ~9 grass 0 
setblock ~71 ~3 ~34 grass 0 
setblock ~72 ~3 ~8 stone 0  
fill ~72 ~3 ~9 ~84 ~3 ~9 dirt 0  
fill ~72 ~3 ~34 ~113 ~3 ~34 dirt 0  
fill ~73 ~3 ~8 ~84 ~3 ~8 dirt 0 
setblock ~75 ~3 ~6 stone 0  
fill ~75 ~3 ~7 ~84 ~3 ~7 dirt 0  
fill ~75 ~3 ~64 ~106 ~3 ~64 grass 0  
fill ~76 ~3 ~6 ~84 ~3 ~6 dirt 0 
setblock ~79 ~3 ~5 cobblestone 0  
fill ~80 ~3 ~5 ~82 ~3 ~5 grass 0  
fill ~81 ~3 ~16 ~104 ~3 ~16 dirt 0  
fill ~82 ~3 ~4 ~82 ~13 ~4 log 0 
setblock ~83 ~3 ~4 grass 0 
setblock ~83 ~3 ~5 cobblestone 0 
setblock ~84 ~3 ~3 stone_stairs 2 
setblock ~84 ~3 ~4 cobblestone 0 
setblock ~84 ~3 ~5 dirt 0  
fill ~85 ~3 ~4 ~89 ~3 ~4 stone_stairs 2 
setblock ~87 ~3 ~5 grass 0  
fill ~87 ~3 ~6 ~97 ~3 ~6 dirt 0  
fill ~87 ~3 ~7 ~98 ~3 ~7 dirt 0  
fill ~87 ~3 ~8 ~100 ~3 ~8 dirt 0  
fill ~87 ~3 ~9 ~101 ~3 ~9 dirt 0  
fill ~87 ~3 ~10 ~102 ~3 ~10 dirt 0  
fill ~88 ~3 ~5 ~90 ~3 ~5 dirt 0 
setblock ~90 ~3 ~3 stone_stairs 2 
setblock ~90 ~3 ~4 cobblestone 0 
setblock ~91 ~3 ~4 grass 0 
setblock ~91 ~3 ~5 cobblestone 0  
fill ~92 ~3 ~4 ~92 ~13 ~4 log 0  
fill ~92 ~3 ~5 ~93 ~3 ~5 grass 0  
fill ~92 ~3 ~21 ~115 ~3 ~21 dirt 0 
setblock ~93 ~3 ~4 cobblestone 0  
fill ~93 ~3 ~22 ~115 ~3 ~22 dirt 0  
fill ~94 ~3 ~4 ~94 ~13 ~4 log 0  
fill ~94 ~3 ~5 ~96 ~3 ~5 dirt 0  
fill ~94 ~3 ~15 ~104 ~3 ~15 dirt 0  
fill ~95 ~3 ~4 ~99 ~3 ~4 grass 0  
fill ~95 ~3 ~39 ~117 ~3 ~39 dirt 0  
fill ~97 ~3 ~5 ~100 ~3 ~5 grass 0  
fill ~98 ~3 ~6 ~99 ~3 ~6 stone 0  
fill ~99 ~3 ~7 ~101 ~3 ~7 stone 0  
fill ~100 ~3 ~6 ~101 ~3 ~6 grass 0  
fill ~100 ~3 ~59 ~107 ~3 ~59 stone 0  
fill ~100 ~3 ~60 ~107 ~3 ~60 stone 0  
fill ~100 ~3 ~61 ~107 ~3 ~61 stone 0  
fill ~101 ~3 ~8 ~103 ~3 ~8 grass 0  
fill ~101 ~3 ~58 ~111 ~3 ~58 stone 0  
fill ~101 ~3 ~62 ~103 ~3 ~62 stone 0  
fill ~102 ~3 ~7 ~102 ~11 ~7 log 0  
fill ~102 ~3 ~9 ~104 ~3 ~9 grass 0 
setblock ~103 ~3 ~7 cobblestone 0  
fill ~103 ~3 ~10 ~105 ~3 ~10 grass 0  
fill ~104 ~3 ~11 ~106 ~3 ~11 grass 0  
fill ~104 ~3 ~57 ~112 ~3 ~57 stone 0 
setblock ~104 ~3 ~62 dirt 0  
fill ~105 ~3 ~12 ~107 ~3 ~12 grass 0  
fill ~105 ~3 ~15 ~106 ~3 ~15 grass 0  
fill ~105 ~3 ~16 ~105 ~3 ~15 grass 0  
fill ~105 ~3 ~56 ~113 ~3 ~56 stone 0  
fill ~105 ~3 ~62 ~106 ~3 ~62 stone 0  
fill ~106 ~3 ~13 ~111 ~3 ~13 grass 0  
fill ~106 ~3 ~14 ~112 ~3 ~14 grass 0  
fill ~106 ~3 ~16 ~112 ~3 ~16 dirt 0  
fill ~107 ~3 ~15 ~111 ~3 ~15 dirt 0  
fill ~107 ~3 ~55 ~114 ~3 ~55 stone 0 
setblock ~108 ~3 ~11 torch 5  
fill ~108 ~3 ~54 ~115 ~3 ~54 stone 0  
fill ~108 ~3 ~59 ~111 ~3 ~59 grass 0  
fill ~108 ~3 ~60 ~108 ~3 ~59 grass 0  
fill ~109 ~3 ~53 ~116 ~3 ~53 stone 0  
fill ~110 ~3 ~52 ~116 ~3 ~52 stone 0  
fill ~111 ~3 ~51 ~117 ~3 ~51 stone 0  
fill ~112 ~3 ~15 ~113 ~3 ~15 grass 0  
fill ~112 ~3 ~28 ~115 ~3 ~28 grass 0  
fill ~112 ~3 ~29 ~116 ~3 ~29 grass 0  
fill ~112 ~3 ~49 ~119 ~3 ~49 stone 0  
fill ~112 ~3 ~50 ~118 ~3 ~50 stone 0 
setblock ~112 ~3 ~58 grass 0  
fill ~113 ~3 ~16 ~113 ~3 ~18 grass 0  
fill ~113 ~3 ~27 ~115 ~3 ~27 grass 0  
fill ~113 ~3 ~30 ~117 ~3 ~30 grass 0  
fill ~113 ~3 ~35 ~118 ~3 ~35 grass 0  
fill ~113 ~3 ~36 ~118 ~3 ~36 grass 0  
fill ~113 ~3 ~48 ~119 ~3 ~48 stone 0 
setblock ~113 ~3 ~57 grass 0 
setblock ~114 ~3 ~14 torch 5  
fill ~114 ~3 ~17 ~114 ~3 ~20 grass 0  
fill ~114 ~3 ~26 ~115 ~3 ~26 grass 0  
fill ~114 ~3 ~34 ~118 ~3 ~34 grass 0  
fill ~114 ~3 ~37 ~118 ~3 ~37 grass 0  
fill ~114 ~3 ~44 ~119 ~3 ~44 stone 0  
fill ~114 ~3 ~45 ~119 ~3 ~45 stone 0  
fill ~114 ~3 ~46 ~119 ~3 ~46 stone 0  
fill ~114 ~3 ~47 ~119 ~3 ~47 stone 0 
setblock ~114 ~3 ~56 grass 0  
fill ~115 ~3 ~18 ~115 ~3 ~20 grass 0  
fill ~115 ~3 ~25 ~116 ~3 ~25 grass 0  
fill ~115 ~3 ~33 ~118 ~3 ~33 grass 0  
fill ~115 ~3 ~43 ~119 ~3 ~43 stone 0 
setblock ~115 ~3 ~55 grass 0  
fill ~116 ~3 ~19 ~116 ~3 ~25 grass 0  
fill ~116 ~3 ~26 ~116 ~3 ~28 dirt 0  
fill ~116 ~3 ~31 ~118 ~3 ~31 grass 0  
fill ~116 ~3 ~32 ~118 ~3 ~32 grass 0  
fill ~116 ~3 ~38 ~117 ~3 ~38 grass 0  
fill ~116 ~3 ~42 ~119 ~3 ~42 stone 0 
setblock ~116 ~3 ~54 grass 0  
fill ~117 ~3 ~20 ~117 ~3 ~24 grass 0  
fill ~117 ~3 ~25 ~117 ~0 ~25 stone 0  
fill ~117 ~3 ~26 ~119 ~3 ~26 grass 0  
fill ~117 ~3 ~27 ~121 ~3 ~27 grass 0  
fill ~117 ~3 ~28 ~121 ~3 ~28 grass 0 
setblock ~117 ~3 ~29 dirt 0  
fill ~117 ~3 ~40 ~121 ~3 ~40 stone 0  
fill ~117 ~3 ~41 ~119 ~3 ~41 stone 0  
fill ~117 ~3 ~52 ~117 ~3 ~53 grass 0 
setblock ~118 ~3 ~20 cobblestone 0  
fill ~118 ~3 ~21 ~118 ~11 ~21 log 0  
fill ~118 ~3 ~22 ~118 ~3 ~23 grass 0 
setblock ~118 ~3 ~24 stone 0 
setblock ~118 ~3 ~25 grass 0  
fill ~118 ~3 ~29 ~120 ~3 ~29 grass 0 
setblock ~118 ~3 ~30 dirt 0 
setblock ~118 ~3 ~38 dirt 0  
fill ~118 ~3 ~39 ~121 ~3 ~39 stone 0 
setblock ~118 ~3 ~51 grass 0 
setblock ~119 ~3 ~23 cobblestone 0  
fill ~119 ~3 ~24 ~120 ~3 ~24 log 0  
fill ~119 ~3 ~30 ~120 ~3 ~30 stone 0  
fill ~119 ~3 ~31 ~119 ~3 ~37 dirt 0  
fill ~119 ~3 ~38 ~121 ~3 ~38 stone 0  
fill ~120 ~3 ~31 ~122 ~3 ~31 grass 0  
fill ~120 ~3 ~32 ~122 ~3 ~32 grass 0  
fill ~120 ~3 ~33 ~122 ~3 ~33 grass 0  
fill ~120 ~3 ~34 ~122 ~3 ~34 grass 0  
fill ~120 ~3 ~35 ~122 ~3 ~35 grass 0  
fill ~120 ~3 ~36 ~122 ~3 ~36 grass 0  
fill ~120 ~3 ~37 ~122 ~3 ~37 grass 0  
fill ~120 ~3 ~41 ~122 ~3 ~41 grass 0  
fill ~120 ~3 ~42 ~121 ~3 ~42 grass 0  
fill ~120 ~3 ~43 ~120 ~3 ~44 grass 0 
setblock ~121 ~3 ~29 stone 0  
fill ~121 ~3 ~30 ~122 ~3 ~30 grass 0 
setblock ~122 ~3 ~27 cobblestone 0  
fill ~122 ~3 ~28 ~122 ~17 ~28 log 0 
setblock ~122 ~3 ~29 grass 0  
fill ~122 ~3 ~38 ~122 ~3 ~41 grass 0  
fill ~5 ~4 ~33 ~6 ~4 ~33 grass 0  
fill ~5 ~4 ~34 ~5 ~4 ~40 grass 0  
fill ~6 ~4 ~30 ~7 ~4 ~30 grass 0  
fill ~6 ~4 ~31 ~7 ~4 ~31 grass 0  
fill ~6 ~4 ~32 ~6 ~4 ~30 grass 0  
fill ~6 ~4 ~34 ~14 ~4 ~34 stone 0  
fill ~6 ~4 ~35 ~14 ~4 ~35 stone 0  
fill ~6 ~4 ~36 ~14 ~4 ~36 stone 0  
fill ~6 ~4 ~37 ~14 ~4 ~37 stone 0  
fill ~6 ~4 ~38 ~14 ~4 ~38 stone 0  
fill ~6 ~4 ~39 ~13 ~4 ~39 stone 0  
fill ~6 ~4 ~40 ~7 ~4 ~40 dirt 0  
fill ~6 ~4 ~41 ~6 ~4 ~47 grass 0  
fill ~7 ~4 ~29 ~8 ~4 ~29 grass 0  
fill ~7 ~4 ~32 ~13 ~4 ~32 stone 0  
fill ~7 ~4 ~33 ~13 ~4 ~33 stone 0  
fill ~7 ~4 ~41 ~116 ~4 ~41 dirt 0  
fill ~7 ~4 ~42 ~115 ~4 ~42 dirt 0  
fill ~7 ~4 ~43 ~8 ~4 ~43 dirt 0  
fill ~7 ~4 ~44 ~7 ~4 ~46 dirt 0  
fill ~7 ~4 ~47 ~7 ~4 ~49 grass 0  
fill ~8 ~4 ~28 ~9 ~4 ~28 grass 0  
fill ~8 ~4 ~30 ~15 ~4 ~30 stone 0  
fill ~8 ~4 ~31 ~14 ~4 ~31 stone 0  
fill ~8 ~4 ~40 ~12 ~4 ~40 stone 0  
fill ~8 ~4 ~44 ~12 ~4 ~44 stone 0  
fill ~8 ~4 ~45 ~12 ~4 ~45 stone 0  
fill ~8 ~4 ~46 ~13 ~4 ~46 stone 0  
fill ~8 ~4 ~47 ~8 ~4 ~48 dirt 0  
fill ~8 ~4 ~49 ~8 ~4 ~50 grass 0  
fill ~9 ~4 ~26 ~9 ~4 ~28 grass 0  
fill ~9 ~4 ~29 ~16 ~4 ~29 stone 0  
fill ~9 ~4 ~43 ~11 ~4 ~43 stone 0  
fill ~9 ~4 ~47 ~14 ~4 ~47 stone 0  
fill ~9 ~4 ~48 ~9 ~4 ~50 dirt 0  
fill ~9 ~4 ~51 ~9 ~4 ~52 grass 0  
fill ~10 ~4 ~24 ~11 ~4 ~24 grass 0  
fill ~10 ~4 ~25 ~10 ~4 ~24 grass 0  
fill ~10 ~4 ~26 ~17 ~4 ~26 stone 0  
fill ~10 ~4 ~27 ~17 ~4 ~27 stone 0  
fill ~10 ~4 ~28 ~17 ~4 ~28 stone 0  
fill ~10 ~4 ~48 ~14 ~4 ~48 stone 0  
fill ~10 ~4 ~49 ~16 ~4 ~49 stone 0  
fill ~10 ~4 ~50 ~10 ~4 ~51 dirt 0 
setblock ~10 ~4 ~52 grass 0  
fill ~11 ~4 ~25 ~17 ~4 ~25 stone 0 
setblock ~11 ~4 ~50 grass 0  
fill ~11 ~4 ~51 ~11 ~5 ~51 stone 0  
fill ~11 ~4 ~52 ~21 ~4 ~52 stone 0  
fill ~11 ~4 ~53 ~13 ~4 ~53 grass 0  
fill ~12 ~4 ~22 ~13 ~4 ~22 grass 0  
fill ~12 ~4 ~24 ~17 ~4 ~24 stone 0  
fill ~12 ~4 ~43 ~114 ~4 ~43 dirt 0  
fill ~12 ~4 ~50 ~19 ~4 ~50 stone 0  
fill ~13 ~4 ~23 ~16 ~4 ~23 stone 0  
fill ~13 ~4 ~40 ~115 ~4 ~40 dirt 0  
fill ~13 ~4 ~44 ~113 ~4 ~44 dirt 0  
fill ~13 ~4 ~45 ~113 ~4 ~45 dirt 0  
fill ~13 ~4 ~51 ~20 ~4 ~51 stone 0  
fill ~13 ~4 ~54 ~14 ~4 ~54 grass 0  
fill ~13 ~4 ~55 ~14 ~4 ~55 grass 0  
fill ~13 ~4 ~56 ~14 ~4 ~56 grass 0  
fill ~14 ~4 ~20 ~15 ~4 ~20 grass 0  
fill ~14 ~4 ~21 ~16 ~4 ~21 dirt 0  
fill ~14 ~4 ~22 ~16 ~4 ~22 dirt 0  
fill ~14 ~4 ~32 ~76 ~4 ~32 dirt 0  
fill ~14 ~4 ~33 ~109 ~4 ~33 dirt 0  
fill ~14 ~4 ~39 ~92 ~4 ~39 dirt 0  
fill ~14 ~4 ~46 ~113 ~4 ~46 dirt 0  
fill ~14 ~4 ~53 ~21 ~4 ~53 stone 0 
setblock ~14 ~4 ~57 grass 0  
fill ~15 ~4 ~31 ~76 ~4 ~31 dirt 0  
fill ~15 ~4 ~34 ~70 ~4 ~34 dirt 0  
fill ~15 ~4 ~35 ~109 ~4 ~35 dirt 0  
fill ~15 ~4 ~36 ~109 ~4 ~36 dirt 0  
fill ~15 ~4 ~37 ~109 ~4 ~37 dirt 0  
fill ~15 ~4 ~38 ~91 ~4 ~38 dirt 0  
fill ~15 ~4 ~47 ~113 ~4 ~47 dirt 0  
fill ~15 ~4 ~48 ~112 ~4 ~48 dirt 0  
fill ~15 ~4 ~54 ~22 ~4 ~54 stone 0  
fill ~15 ~4 ~55 ~22 ~4 ~55 stone 0  
fill ~15 ~4 ~56 ~22 ~4 ~56 stone 0  
fill ~15 ~4 ~57 ~21 ~4 ~57 stone 0 
setblock ~15 ~4 ~58 grass 0 
setblock ~16 ~4 ~19 grass 0 
setblock ~16 ~4 ~20 dirt 0  
fill ~16 ~4 ~30 ~76 ~4 ~30 dirt 0  
fill ~16 ~4 ~58 ~19 ~4 ~58 stone 0  
fill ~16 ~4 ~59 ~17 ~4 ~59 grass 0  
fill ~17 ~4 ~17 ~18 ~4 ~17 grass 0  
fill ~17 ~4 ~18 ~18 ~4 ~18 dirt 0  
fill ~17 ~4 ~19 ~17 ~4 ~18 dirt 0  
fill ~17 ~4 ~20 ~22 ~4 ~20 stone 0  
fill ~17 ~4 ~21 ~22 ~4 ~21 stone 0  
fill ~17 ~4 ~22 ~21 ~4 ~22 stone 0 
setblock ~17 ~4 ~23 dirt 0  
fill ~17 ~4 ~29 ~76 ~4 ~29 dirt 0  
fill ~17 ~4 ~49 ~111 ~4 ~49 dirt 0  
fill ~18 ~4 ~19 ~22 ~4 ~19 stone 0  
fill ~18 ~4 ~23 ~20 ~4 ~23 stone 0  
fill ~18 ~4 ~24 ~90 ~4 ~24 dirt 0  
fill ~18 ~4 ~25 ~90 ~4 ~25 dirt 0  
fill ~18 ~4 ~26 ~78 ~4 ~26 dirt 0  
fill ~18 ~4 ~27 ~76 ~4 ~27 dirt 0  
fill ~18 ~4 ~28 ~76 ~4 ~28 dirt 0  
fill ~18 ~4 ~59 ~86 ~4 ~59 dirt 0  
fill ~18 ~4 ~60 ~19 ~4 ~60 grass 0 
setblock ~19 ~4 ~16 grass 0  
fill ~19 ~4 ~17 ~23 ~4 ~17 dirt 0  
fill ~19 ~4 ~18 ~21 ~4 ~18 stone 0 
setblock ~20 ~4 ~15 grass 0  
fill ~20 ~4 ~16 ~22 ~4 ~16 dirt 0  
fill ~20 ~4 ~50 ~111 ~4 ~50 dirt 0  
fill ~20 ~4 ~58 ~86 ~4 ~58 dirt 0  
fill ~20 ~4 ~60 ~86 ~4 ~60 dirt 0  
fill ~20 ~4 ~61 ~21 ~4 ~61 grass 0  
fill ~21 ~4 ~14 ~22 ~4 ~14 grass 0  
fill ~21 ~4 ~15 ~22 ~4 ~15 dirt 0  
fill ~21 ~4 ~23 ~90 ~4 ~23 dirt 0  
fill ~21 ~4 ~51 ~110 ~4 ~51 dirt 0 
setblock ~21 ~4 ~62 grass 0  
fill ~22 ~4 ~18 ~24 ~4 ~18 dirt 0  
fill ~22 ~4 ~22 ~90 ~4 ~22 dirt 0  
fill ~22 ~4 ~52 ~109 ~4 ~52 dirt 0  
fill ~22 ~4 ~53 ~108 ~4 ~53 dirt 0  
fill ~22 ~4 ~57 ~87 ~4 ~57 dirt 0  
fill ~22 ~4 ~61 ~87 ~4 ~61 dirt 0  
fill ~22 ~4 ~62 ~98 ~4 ~62 dirt 0  
fill ~22 ~4 ~63 ~24 ~4 ~63 grass 0 
setblock ~23 ~4 ~13 grass 0  
fill ~23 ~4 ~14 ~49 ~4 ~14 stone 0  
fill ~23 ~4 ~15 ~40 ~4 ~15 stone 0  
fill ~23 ~4 ~16 ~37 ~4 ~16 stone 0  
fill ~23 ~4 ~19 ~102 ~4 ~19 dirt 0  
fill ~23 ~4 ~20 ~108 ~4 ~20 dirt 0  
fill ~23 ~4 ~21 ~90 ~4 ~21 dirt 0  
fill ~23 ~4 ~54 ~106 ~4 ~54 dirt 0  
fill ~23 ~4 ~55 ~104 ~4 ~55 dirt 0  
fill ~23 ~4 ~56 ~102 ~4 ~56 dirt 0  
fill ~24 ~4 ~12 ~26 ~4 ~12 grass 0  
fill ~24 ~4 ~13 ~50 ~4 ~13 stone 0  
fill ~24 ~4 ~17 ~36 ~4 ~17 stone 0  
fill ~25 ~4 ~18 ~30 ~4 ~18 stone 0  
fill ~25 ~4 ~63 ~75 ~4 ~63 dirt 0  
fill ~25 ~4 ~64 ~27 ~4 ~64 grass 0  
fill ~27 ~4 ~12 ~28 ~4 ~12 stone 0  
fill ~28 ~4 ~64 ~65 ~4 ~64 dirt 0  
fill ~28 ~4 ~65 ~29 ~4 ~65 grass 0  
fill ~29 ~4 ~12 ~37 ~4 ~12 grass 0  
fill ~30 ~4 ~65 ~58 ~4 ~65 dirt 0  
fill ~30 ~4 ~66 ~31 ~4 ~66 grass 0  
fill ~31 ~4 ~18 ~102 ~4 ~18 dirt 0  
fill ~31 ~4 ~67 ~33 ~4 ~67 grass 0  
fill ~32 ~4 ~66 ~56 ~4 ~66 dirt 0  
fill ~33 ~4 ~68 ~35 ~4 ~68 grass 0  
fill ~34 ~4 ~67 ~50 ~4 ~67 dirt 0  
fill ~35 ~4 ~69 ~47 ~4 ~69 grass 0  
fill ~36 ~4 ~68 ~46 ~4 ~68 dirt 0  
fill ~37 ~4 ~17 ~102 ~4 ~17 dirt 0  
fill ~38 ~4 ~11 ~39 ~4 ~11 grass 0  
fill ~38 ~4 ~12 ~56 ~4 ~12 stone 0  
fill ~38 ~4 ~16 ~79 ~4 ~16 dirt 0  
fill ~40 ~4 ~10 ~66 ~4 ~10 stone 0  
fill ~40 ~4 ~11 ~59 ~4 ~11 stone 0  
fill ~41 ~4 ~9 ~42 ~4 ~9 grass 0  
fill ~41 ~4 ~15 ~43 ~4 ~15 dirt 0  
fill ~43 ~4 ~8 ~47 ~4 ~8 grass 0  
fill ~43 ~4 ~9 ~46 ~4 ~9 stone 0  
fill ~44 ~4 ~15 ~48 ~4 ~15 stone 0 
setblock ~47 ~4 ~9 grass 0  
fill ~47 ~4 ~68 ~51 ~4 ~68 grass 0  
fill ~48 ~4 ~9 ~67 ~4 ~9 stone 0  
fill ~49 ~4 ~8 ~68 ~4 ~8 stone 0  
fill ~49 ~4 ~15 ~92 ~4 ~15 dirt 0  
fill ~50 ~4 ~7 ~54 ~4 ~7 stone 0  
fill ~50 ~4 ~14 ~102 ~4 ~14 dirt 0  
fill ~51 ~4 ~13 ~102 ~4 ~13 dirt 0  
fill ~51 ~4 ~67 ~56 ~4 ~67 grass 0 
setblock ~55 ~4 ~7 grass 0  
fill ~56 ~4 ~7 ~63 ~4 ~7 stone 0  
fill ~57 ~4 ~6 ~58 ~4 ~6 grass 0  
fill ~57 ~4 ~12 ~102 ~4 ~12 dirt 0  
fill ~57 ~4 ~66 ~59 ~4 ~66 grass 0  
fill ~59 ~4 ~5 ~63 ~4 ~5 grass 0  
fill ~59 ~4 ~6 ~62 ~4 ~6 stone 0  
fill ~59 ~4 ~65 ~64 ~4 ~65 grass 0  
fill ~60 ~4 ~11 ~102 ~4 ~11 dirt 0  
fill ~63 ~4 ~6 ~68 ~4 ~6 grass 0  
fill ~64 ~4 ~7 ~68 ~4 ~7 grass 0  
fill ~66 ~4 ~64 ~74 ~4 ~64 grass 0  
fill ~67 ~4 ~5 ~68 ~4 ~5 grass 0  
fill ~67 ~4 ~10 ~79 ~4 ~10 dirt 0  
fill ~68 ~4 ~9 ~68 ~5 ~9 dirt 0  
fill ~69 ~4 ~8 ~69 ~11 ~8 log 0  
fill ~70 ~4 ~7 ~70 ~11 ~7 log 0  
fill ~71 ~4 ~7 ~71 ~6 ~7 cobblestone 0  
fill ~72 ~4 ~7 ~72 ~11 ~7 log 0  
fill ~72 ~4 ~8 ~77 ~4 ~8 dirt 0  
fill ~72 ~4 ~9 ~78 ~4 ~9 dirt 0  
fill ~72 ~4 ~34 ~109 ~4 ~34 dirt 0  
fill ~73 ~4 ~7 ~73 ~6 ~7 cobblestone 0  
fill ~74 ~4 ~7 ~74 ~11 ~7 log 0  
fill ~75 ~4 ~6 ~77 ~4 ~6 grass 0  
fill ~75 ~4 ~7 ~77 ~4 ~7 dirt 0  
fill ~76 ~4 ~63 ~106 ~4 ~63 grass 0  
fill ~77 ~4 ~27 ~87 ~4 ~27 cobblestone 0  
fill ~77 ~4 ~28 ~86 ~4 ~28 cobblestone 0  
fill ~77 ~4 ~29 ~86 ~4 ~29 cobblestone 0  
fill ~77 ~4 ~30 ~86 ~4 ~30 cobblestone 0  
fill ~77 ~4 ~31 ~86 ~4 ~31 cobblestone 0  
fill ~77 ~4 ~32 ~86 ~4 ~32 cobblestone 0  
fill ~78 ~4 ~6 ~78 ~13 ~6 log 0  
fill ~78 ~4 ~7 ~78 ~6 ~7 cobblestone 0 
setblock ~78 ~4 ~8 log 1 
setblock ~79 ~4 ~5 log 0  
fill ~79 ~4 ~6 ~83 ~4 ~6 dirt 0  
fill ~79 ~4 ~7 ~84 ~4 ~7 dirt 0  
fill ~79 ~4 ~8 ~83 ~4 ~8 dirt 0  
fill ~79 ~4 ~9 ~79 ~6 ~9 cobblestone 0  
fill ~79 ~4 ~26 ~85 ~4 ~26 cobblestone 0  
fill ~80 ~4 ~9 ~84 ~4 ~9 dirt 0 
setblock ~80 ~4 ~10 log 1 
setblock ~81 ~4 ~4 log 0 
setblock ~81 ~4 ~10 dirt 0  
fill ~81 ~4 ~16 ~102 ~4 ~16 dirt 0 
setblock ~82 ~4 ~10 log 1 
setblock ~83 ~4 ~5 log 0  
fill ~83 ~4 ~10 ~84 ~4 ~10 grass 0 
setblock ~84 ~4 ~4 stone_stairs 2 
setblock ~84 ~4 ~5 cobblestone 0  
fill ~84 ~4 ~6 ~84 ~13 ~6 log 0 
setblock ~84 ~4 ~8 log 1  
fill ~85 ~4 ~5 ~89 ~4 ~5 stone_stairs 2  
fill ~86 ~4 ~26 ~90 ~4 ~26 dirt 0  
fill ~87 ~4 ~6 ~89 ~4 ~6 grass 0  
fill ~87 ~4 ~7 ~89 ~4 ~7 grass 0  
fill ~87 ~4 ~8 ~89 ~4 ~8 grass 0  
fill ~87 ~4 ~9 ~89 ~4 ~9 grass 0  
fill ~87 ~4 ~10 ~91 ~4 ~10 grass 0  
fill ~87 ~4 ~28 ~90 ~4 ~28 dirt 0  
fill ~87 ~4 ~29 ~108 ~4 ~29 dirt 0  
fill ~87 ~4 ~30 ~108 ~4 ~30 dirt 0  
fill ~87 ~4 ~31 ~109 ~4 ~31 dirt 0  
fill ~87 ~4 ~32 ~109 ~4 ~32 dirt 0  
fill ~87 ~4 ~58 ~96 ~4 ~58 stone 0  
fill ~87 ~4 ~59 ~96 ~4 ~59 stone 0  
fill ~87 ~4 ~60 ~96 ~4 ~60 stone 0  
fill ~88 ~4 ~27 ~90 ~4 ~27 dirt 0  
fill ~88 ~4 ~57 ~95 ~4 ~57 stone 0  
fill ~88 ~4 ~61 ~95 ~4 ~61 stone 0 
setblock ~90 ~4 ~4 stone_stairs 2 
setblock ~90 ~4 ~5 cobblestone 0  
fill ~90 ~4 ~6 ~90 ~13 ~6 log 0  
fill ~90 ~4 ~7 ~90 ~4 ~9 dirt 0 
setblock ~91 ~4 ~5 log 0  
fill ~91 ~4 ~6 ~95 ~4 ~6 grass 0  
fill ~91 ~4 ~7 ~94 ~4 ~7 grass 0  
fill ~91 ~4 ~8 ~93 ~4 ~8 grass 0  
fill ~91 ~4 ~9 ~92 ~4 ~9 grass 0  
fill ~91 ~4 ~21 ~92 ~4 ~21 cobblestone 0  
fill ~91 ~4 ~22 ~92 ~4 ~22 cobblestone 0  
fill ~91 ~4 ~23 ~92 ~4 ~23 cobblestone 0  
fill ~91 ~4 ~24 ~92 ~4 ~24 cobblestone 0  
fill ~91 ~4 ~25 ~92 ~4 ~25 cobblestone 0  
fill ~91 ~4 ~26 ~92 ~4 ~26 cobblestone 0  
fill ~91 ~4 ~27 ~102 ~4 ~27 cobblestone 0  
fill ~91 ~4 ~28 ~102 ~4 ~28 cobblestone 0  
fill ~92 ~4 ~10 ~98 ~4 ~10 dirt 0  
fill ~92 ~4 ~38 ~98 ~4 ~38 grass 0 
setblock ~93 ~4 ~4 log 0  
fill ~93 ~4 ~9 ~97 ~4 ~9 dirt 0 
setblock ~93 ~4 ~15 glowstone 0  
fill ~93 ~4 ~21 ~109 ~4 ~21 dirt 0  
fill ~93 ~4 ~22 ~109 ~4 ~22 dirt 0  
fill ~93 ~4 ~23 ~112 ~4 ~23 dirt 0  
fill ~93 ~4 ~24 ~93 ~4 ~26 dirt 0 
setblock ~94 ~4 ~5 grass 0 
setblock ~94 ~4 ~8 dirt 0  
fill ~94 ~4 ~15 ~102 ~4 ~15 dirt 0  
fill ~94 ~4 ~24 ~96 ~4 ~24 cobblestone 0  
fill ~94 ~4 ~25 ~96 ~4 ~25 cobblestone 0  
fill ~94 ~4 ~26 ~95 ~4 ~26 dirt 0 
setblock ~95 ~4 ~5 log 0  
fill ~95 ~4 ~7 ~99 ~4 ~7 dirt 0 
setblock ~95 ~4 ~8 grass 0  
fill ~95 ~4 ~39 ~113 ~4 ~39 dirt 0 
setblock ~96 ~4 ~5 grass 0 
setblock ~96 ~4 ~6 dirt 0 
setblock ~96 ~4 ~8 dirt 0 
setblock ~96 ~4 ~26 cobblestone 0  
fill ~96 ~4 ~57 ~99 ~4 ~57 dirt 0  
fill ~96 ~4 ~61 ~98 ~4 ~61 dirt 0  
fill ~97 ~4 ~6 ~99 ~4 ~6 grass 0  
fill ~97 ~4 ~8 ~100 ~4 ~8 grass 0 
setblock ~97 ~4 ~24 dirt 0  
fill ~97 ~4 ~26 ~99 ~4 ~26 dirt 0  
fill ~97 ~4 ~58 ~98 ~4 ~58 dirt 0  
fill ~97 ~4 ~59 ~98 ~4 ~59 dirt 0  
fill ~97 ~4 ~60 ~98 ~4 ~60 dirt 0  
fill ~98 ~4 ~9 ~101 ~4 ~9 grass 0  
fill ~98 ~4 ~24 ~100 ~4 ~24 cobblestone 0  
fill ~98 ~4 ~25 ~100 ~4 ~25 cobblestone 0  
fill ~99 ~4 ~10 ~102 ~4 ~10 grass 0  
fill ~99 ~4 ~38 ~101 ~4 ~38 dirt 0  
fill ~99 ~4 ~58 ~111 ~4 ~58 stone 0  
fill ~99 ~4 ~59 ~107 ~4 ~59 stone 0  
fill ~99 ~4 ~60 ~107 ~4 ~60 stone 0  
fill ~99 ~4 ~61 ~107 ~4 ~61 stone 0  
fill ~99 ~4 ~62 ~105 ~4 ~62 stone 0  
fill ~100 ~4 ~7 ~106 ~4 ~7 log 0 
setblock ~100 ~4 ~26 cobblestone 0  
fill ~100 ~4 ~57 ~112 ~4 ~57 stone 0  
fill ~101 ~4 ~24 ~112 ~4 ~24 dirt 0  
fill ~101 ~4 ~25 ~109 ~4 ~25 dirt 0  
fill ~101 ~4 ~26 ~109 ~4 ~26 dirt 0 
setblock ~102 ~4 ~38 grass 0 
setblock ~103 ~4 ~9 torch 5  
fill ~103 ~4 ~11 ~103 ~4 ~19 grass 0  
fill ~103 ~4 ~27 ~109 ~4 ~27 dirt 0  
fill ~103 ~4 ~28 ~109 ~4 ~28 dirt 0  
fill ~103 ~4 ~38 ~111 ~4 ~38 dirt 0  
fill ~103 ~4 ~56 ~113 ~4 ~56 stone 0  
fill ~104 ~4 ~12 ~104 ~4 ~19 grass 0  
fill ~105 ~4 ~13 ~105 ~4 ~14 grass 0  
fill ~105 ~4 ~17 ~112 ~4 ~17 grass 0  
fill ~105 ~4 ~18 ~112 ~4 ~18 grass 0  
fill ~105 ~4 ~19 ~113 ~4 ~19 grass 0  
fill ~105 ~4 ~55 ~114 ~4 ~55 stone 0  
fill ~106 ~4 ~16 ~112 ~4 ~16 grass 0 
setblock ~106 ~4 ~62 grass 0 
setblock ~107 ~4 ~12 torch 5  
fill ~107 ~4 ~15 ~111 ~4 ~15 grass 0  
fill ~107 ~4 ~54 ~115 ~4 ~54 stone 0 
setblock ~108 ~4 ~8 log 0  
fill ~109 ~4 ~20 ~113 ~4 ~20 grass 0  
fill ~109 ~4 ~29 ~111 ~4 ~29 grass 0  
fill ~109 ~4 ~30 ~112 ~4 ~30 grass 0  
fill ~109 ~4 ~53 ~115 ~4 ~53 stone 0  
fill ~110 ~4 ~21 ~115 ~4 ~21 grass 0  
fill ~110 ~4 ~22 ~115 ~4 ~22 grass 0  
fill ~110 ~4 ~25 ~114 ~4 ~25 grass 0  
fill ~110 ~4 ~26 ~113 ~4 ~26 grass 0  
fill ~110 ~4 ~27 ~112 ~4 ~27 grass 0  
fill ~110 ~4 ~28 ~111 ~4 ~28 grass 0  
fill ~110 ~4 ~31 ~115 ~4 ~31 grass 0  
fill ~110 ~4 ~32 ~115 ~4 ~32 grass 0  
fill ~110 ~4 ~33 ~114 ~4 ~33 grass 0  
fill ~110 ~4 ~34 ~113 ~4 ~34 grass 0  
fill ~110 ~4 ~35 ~112 ~4 ~35 grass 0  
fill ~110 ~4 ~36 ~112 ~4 ~36 grass 0  
fill ~110 ~4 ~37 ~113 ~4 ~37 grass 0  
fill ~110 ~4 ~52 ~116 ~4 ~52 stone 0 
setblock ~111 ~4 ~9 log 0  
fill ~111 ~4 ~51 ~116 ~4 ~51 stone 0  
fill ~112 ~4 ~38 ~115 ~4 ~38 grass 0  
fill ~112 ~4 ~49 ~119 ~4 ~49 stone 0  
fill ~112 ~4 ~50 ~118 ~4 ~50 stone 0  
fill ~113 ~4 ~23 ~115 ~4 ~23 grass 0  
fill ~113 ~4 ~24 ~115 ~4 ~24 grass 0  
fill ~113 ~4 ~48 ~119 ~4 ~48 stone 0 
setblock ~114 ~4 ~11 log 0  
fill ~114 ~4 ~39 ~118 ~4 ~39 grass 0  
fill ~114 ~4 ~44 ~119 ~4 ~44 stone 0  
fill ~114 ~4 ~45 ~119 ~4 ~45 stone 0  
fill ~114 ~4 ~46 ~119 ~4 ~46 stone 0  
fill ~114 ~4 ~47 ~119 ~4 ~47 stone 0  
fill ~115 ~4 ~43 ~118 ~4 ~43 stone 0 
setblock ~116 ~4 ~14 log 0  
fill ~116 ~4 ~26 ~116 ~17 ~26 log 0  
fill ~116 ~4 ~27 ~116 ~6 ~27 cobblestone 0  
fill ~116 ~4 ~28 ~116 ~17 ~28 log 0  
fill ~116 ~4 ~40 ~118 ~4 ~40 grass 0  
fill ~116 ~4 ~42 ~118 ~4 ~42 stone 0 
setblock ~116 ~4 ~53 grass 0 
setblock ~117 ~4 ~17 log 0 
setblock ~117 ~4 ~20 torch 5  
fill ~117 ~4 ~25 ~117 ~6 ~25 cobblestone 0  
fill ~117 ~4 ~29 ~117 ~6 ~29 cobblestone 0 
setblock ~117 ~4 ~41 grass 0 
setblock ~117 ~4 ~51 grass 0 
setblock ~118 ~4 ~20 log 0  
fill ~118 ~4 ~24 ~120 ~4 ~24 log 0  
fill ~118 ~4 ~30 ~120 ~4 ~30 log 0 
setblock ~118 ~4 ~33 torch 5 
setblock ~118 ~4 ~38 grass 0 
setblock ~118 ~4 ~41 stone 0 
setblock ~119 ~4 ~23 log 0  
fill ~119 ~4 ~31 ~119 ~4 ~38 log 0  
fill ~119 ~4 ~39 ~119 ~4 ~40 stone 0  
fill ~119 ~4 ~41 ~119 ~4 ~43 grass 0 
setblock ~120 ~4 ~27 glowstone 0  
fill ~120 ~4 ~38 ~121 ~4 ~38 grass 0  
fill ~120 ~4 ~39 ~121 ~4 ~39 grass 0  
fill ~120 ~4 ~40 ~121 ~4 ~40 grass 0 
setblock ~121 ~4 ~25 log 0 
setblock ~121 ~4 ~29 log 0 
setblock ~122 ~4 ~27 log 0  
fill ~6 ~5 ~34 ~7 ~5 ~34 grass 0  
fill ~6 ~5 ~35 ~7 ~5 ~35 grass 0  
fill ~6 ~5 ~36 ~6 ~5 ~40 grass 0  
fill ~7 ~5 ~32 ~9 ~5 ~32 grass 0  
fill ~7 ~5 ~33 ~8 ~5 ~33 grass 0  
fill ~7 ~5 ~36 ~15 ~5 ~36 stone 0  
fill ~7 ~5 ~37 ~15 ~5 ~37 stone 0  
fill ~7 ~5 ~38 ~14 ~5 ~38 stone 0  
fill ~7 ~5 ~39 ~7 ~5 ~46 grass 0  
fill ~8 ~5 ~30 ~9 ~5 ~30 grass 0  
fill ~8 ~5 ~31 ~9 ~5 ~31 grass 0  
fill ~8 ~5 ~34 ~14 ~5 ~34 stone 0  
fill ~8 ~5 ~35 ~15 ~5 ~35 stone 0  
fill ~8 ~5 ~39 ~14 ~5 ~39 stone 0  
fill ~8 ~5 ~40 ~13 ~5 ~40 stone 0 
setblock ~8 ~5 ~41 dirt 0  
fill ~8 ~5 ~42 ~12 ~5 ~42 stone 0  
fill ~8 ~5 ~43 ~13 ~5 ~43 stone 0  
fill ~8 ~5 ~44 ~13 ~5 ~44 stone 0  
fill ~8 ~5 ~45 ~8 ~5 ~48 grass 0 
setblock ~9 ~5 ~29 grass 0  
fill ~9 ~5 ~33 ~14 ~5 ~33 stone 0  
fill ~9 ~5 ~41 ~11 ~5 ~41 stone 0  
fill ~9 ~5 ~45 ~14 ~5 ~45 stone 0  
fill ~9 ~5 ~46 ~15 ~5 ~46 stone 0  
fill ~9 ~5 ~47 ~15 ~5 ~47 stone 0  
fill ~9 ~5 ~48 ~15 ~5 ~48 stone 0  
fill ~9 ~5 ~49 ~18 ~5 ~49 stone 0 
setblock ~9 ~5 ~50 grass 0  
fill ~10 ~5 ~26 ~11 ~5 ~26 grass 0  
fill ~10 ~5 ~27 ~18 ~5 ~27 stone 0  
fill ~10 ~5 ~28 ~18 ~5 ~28 stone 0  
fill ~10 ~5 ~29 ~17 ~5 ~29 stone 0  
fill ~10 ~5 ~30 ~16 ~5 ~30 stone 0  
fill ~10 ~5 ~31 ~15 ~5 ~31 stone 0  
fill ~10 ~5 ~32 ~14 ~5 ~32 stone 0 
setblock ~10 ~5 ~50 stone 0 
setblock ~10 ~5 ~51 grass 0 
setblock ~11 ~5 ~25 grass 0 
setblock ~11 ~5 ~52 grass 0  
fill ~12 ~5 ~23 ~13 ~5 ~23 grass 0  
fill ~12 ~5 ~24 ~12 ~5 ~23 grass 0  
fill ~12 ~5 ~25 ~18 ~5 ~25 stone 0  
fill ~12 ~5 ~26 ~18 ~5 ~26 stone 0  
fill ~12 ~5 ~41 ~115 ~5 ~41 dirt 0  
fill ~12 ~5 ~50 ~20 ~5 ~50 stone 0  
fill ~12 ~5 ~52 ~22 ~5 ~52 stone 0  
fill ~13 ~5 ~24 ~21 ~5 ~24 stone 0  
fill ~13 ~5 ~42 ~115 ~5 ~42 dirt 0  
fill ~13 ~5 ~51 ~21 ~5 ~51 stone 0  
fill ~14 ~5 ~21 ~15 ~5 ~21 grass 0  
fill ~14 ~5 ~22 ~23 ~5 ~22 stone 0  
fill ~14 ~5 ~23 ~22 ~5 ~23 stone 0  
fill ~14 ~5 ~40 ~112 ~5 ~40 dirt 0  
fill ~14 ~5 ~43 ~114 ~5 ~43 dirt 0  
fill ~14 ~5 ~44 ~114 ~5 ~44 dirt 0 
setblock ~14 ~5 ~53 grass 0  
fill ~15 ~5 ~32 ~76 ~5 ~32 dirt 0  
fill ~15 ~5 ~33 ~107 ~5 ~33 dirt 0  
fill ~15 ~5 ~34 ~107 ~5 ~34 dirt 0  
fill ~15 ~5 ~38 ~74 ~5 ~38 dirt 0  
fill ~15 ~5 ~39 ~75 ~5 ~39 dirt 0  
fill ~15 ~5 ~45 ~113 ~5 ~45 dirt 0  
fill ~15 ~5 ~53 ~23 ~5 ~53 stone 0  
fill ~15 ~5 ~54 ~23 ~5 ~54 stone 0  
fill ~15 ~5 ~55 ~24 ~5 ~55 stone 0  
fill ~15 ~5 ~56 ~15 ~5 ~57 grass 0 
setblock ~16 ~5 ~20 grass 0  
fill ~16 ~5 ~21 ~23 ~5 ~21 stone 0  
fill ~16 ~5 ~31 ~76 ~5 ~31 dirt 0  
fill ~16 ~5 ~35 ~107 ~5 ~35 dirt 0  
fill ~16 ~5 ~36 ~107 ~5 ~36 dirt 0  
fill ~16 ~5 ~37 ~75 ~5 ~37 dirt 0  
fill ~16 ~5 ~46 ~113 ~5 ~46 dirt 0  
fill ~16 ~5 ~47 ~113 ~5 ~47 dirt 0  
fill ~16 ~5 ~48 ~112 ~5 ~48 dirt 0  
fill ~16 ~5 ~56 ~24 ~5 ~56 stone 0  
fill ~16 ~5 ~57 ~17 ~5 ~57 grass 0  
fill ~16 ~5 ~58 ~17 ~5 ~58 grass 0  
fill ~17 ~5 ~18 ~18 ~5 ~18 grass 0  
fill ~17 ~5 ~19 ~29 ~5 ~19 stone 0  
fill ~17 ~5 ~20 ~25 ~5 ~20 stone 0  
fill ~17 ~5 ~30 ~76 ~5 ~30 dirt 0  
fill ~18 ~5 ~29 ~76 ~5 ~29 dirt 0  
fill ~18 ~5 ~57 ~24 ~5 ~57 stone 0  
fill ~18 ~5 ~58 ~23 ~5 ~58 stone 0  
fill ~18 ~5 ~59 ~20 ~5 ~59 grass 0 
setblock ~19 ~5 ~17 grass 0  
fill ~19 ~5 ~18 ~34 ~5 ~18 stone 0  
fill ~19 ~5 ~25 ~89 ~5 ~25 dirt 0  
fill ~19 ~5 ~26 ~76 ~5 ~26 dirt 0  
fill ~19 ~5 ~27 ~68 ~5 ~27 dirt 0  
fill ~19 ~5 ~28 ~76 ~5 ~28 dirt 0  
fill ~19 ~5 ~49 ~111 ~5 ~49 dirt 0 
setblock ~20 ~5 ~16 grass 0  
fill ~20 ~5 ~17 ~36 ~5 ~17 stone 0  
fill ~20 ~5 ~60 ~21 ~5 ~60 grass 0  
fill ~21 ~5 ~15 ~22 ~5 ~15 grass 0  
fill ~21 ~5 ~16 ~22 ~5 ~16 dirt 0  
fill ~21 ~5 ~50 ~111 ~5 ~50 dirt 0  
fill ~21 ~5 ~59 ~50 ~5 ~59 dirt 0  
fill ~22 ~5 ~24 ~89 ~5 ~24 dirt 0  
fill ~22 ~5 ~51 ~110 ~5 ~51 dirt 0  
fill ~22 ~5 ~60 ~50 ~5 ~60 dirt 0  
fill ~22 ~5 ~61 ~22 ~5 ~62 grass 0 
setblock ~23 ~5 ~14 grass 0  
fill ~23 ~5 ~15 ~49 ~5 ~15 stone 0  
fill ~23 ~5 ~16 ~42 ~5 ~16 stone 0  
fill ~23 ~5 ~23 ~89 ~5 ~23 dirt 0  
fill ~23 ~5 ~52 ~109 ~5 ~52 dirt 0  
fill ~23 ~5 ~61 ~44 ~5 ~61 dirt 0  
fill ~23 ~5 ~62 ~25 ~5 ~62 grass 0  
fill ~24 ~5 ~13 ~26 ~5 ~13 grass 0  
fill ~24 ~5 ~14 ~50 ~5 ~14 stone 0  
fill ~24 ~5 ~21 ~79 ~5 ~21 dirt 0  
fill ~24 ~5 ~22 ~79 ~5 ~22 dirt 0  
fill ~24 ~5 ~53 ~107 ~5 ~53 dirt 0  
fill ~24 ~5 ~54 ~105 ~5 ~54 dirt 0  
fill ~24 ~5 ~58 ~51 ~5 ~58 dirt 0  
fill ~25 ~5 ~55 ~102 ~5 ~55 dirt 0  
fill ~25 ~5 ~56 ~61 ~5 ~56 dirt 0  
fill ~25 ~5 ~57 ~55 ~5 ~57 dirt 0  
fill ~25 ~5 ~63 ~27 ~5 ~63 grass 0  
fill ~26 ~5 ~20 ~79 ~5 ~20 dirt 0  
fill ~26 ~5 ~62 ~43 ~5 ~62 dirt 0  
fill ~27 ~5 ~12 ~28 ~5 ~12 grass 0  
fill ~27 ~5 ~13 ~32 ~5 ~13 stone 0  
fill ~28 ~5 ~63 ~43 ~5 ~63 dirt 0  
fill ~28 ~5 ~64 ~30 ~5 ~64 grass 0  
fill ~30 ~5 ~19 ~79 ~5 ~19 dirt 0  
fill ~30 ~5 ~65 ~31 ~5 ~65 grass 0  
fill ~31 ~5 ~64 ~43 ~5 ~64 dirt 0  
fill ~32 ~5 ~65 ~44 ~5 ~65 dirt 0  
fill ~32 ~5 ~66 ~33 ~5 ~66 grass 0  
fill ~33 ~5 ~13 ~38 ~5 ~13 grass 0  
fill ~34 ~5 ~66 ~50 ~5 ~66 dirt 0  
fill ~34 ~5 ~67 ~36 ~5 ~67 grass 0  
fill ~35 ~5 ~18 ~79 ~5 ~18 dirt 0  
fill ~36 ~5 ~68 ~46 ~5 ~68 grass 0  
fill ~37 ~5 ~17 ~79 ~5 ~17 dirt 0  
fill ~37 ~5 ~67 ~46 ~5 ~67 dirt 0  
fill ~38 ~5 ~12 ~39 ~5 ~12 grass 0  
fill ~39 ~5 ~13 ~51 ~5 ~13 stone 0  
fill ~40 ~5 ~10 ~41 ~5 ~10 grass 0  
fill ~40 ~5 ~11 ~59 ~5 ~11 stone 0  
fill ~40 ~5 ~12 ~56 ~5 ~12 stone 0  
fill ~42 ~5 ~10 ~46 ~5 ~10 stone 0 
setblock ~43 ~5 ~9 grass 0  
fill ~43 ~5 ~16 ~44 ~5 ~16 dirt 0  
fill ~44 ~5 ~9 ~45 ~5 ~9 stone 0  
fill ~44 ~5 ~62 ~48 ~5 ~62 stone 0  
fill ~44 ~5 ~63 ~48 ~5 ~63 stone 0  
fill ~44 ~5 ~64 ~48 ~5 ~64 stone 0  
fill ~45 ~5 ~16 ~47 ~5 ~16 stone 0  
fill ~45 ~5 ~61 ~47 ~5 ~61 stone 0  
fill ~45 ~5 ~65 ~47 ~5 ~65 stone 0 
setblock ~46 ~5 ~9 grass 0 
setblock ~47 ~5 ~10 grass 0  
fill ~47 ~5 ~67 ~50 ~5 ~67 grass 0  
fill ~48 ~5 ~9 ~67 ~5 ~9 stone 0  
fill ~48 ~5 ~10 ~65 ~5 ~10 stone 0  
fill ~48 ~5 ~16 ~79 ~5 ~16 dirt 0  
fill ~48 ~5 ~61 ~50 ~5 ~61 dirt 0  
fill ~48 ~5 ~65 ~55 ~5 ~65 dirt 0  
fill ~49 ~5 ~8 ~62 ~5 ~8 stone 0  
fill ~49 ~5 ~62 ~51 ~5 ~62 dirt 0  
fill ~49 ~5 ~63 ~65 ~5 ~63 dirt 0  
fill ~49 ~5 ~64 ~57 ~5 ~64 dirt 0 
setblock ~50 ~5 ~7 grass 0  
fill ~50 ~5 ~15 ~91 ~5 ~15 dirt 0  
fill ~51 ~5 ~7 ~53 ~5 ~7 stone 0  
fill ~51 ~5 ~14 ~92 ~5 ~14 dirt 0  
fill ~51 ~5 ~59 ~75 ~5 ~59 stone 0  
fill ~51 ~5 ~60 ~74 ~5 ~60 stone 0  
fill ~51 ~5 ~61 ~61 ~5 ~61 stone 0  
fill ~51 ~5 ~66 ~56 ~5 ~66 grass 0  
fill ~52 ~5 ~13 ~102 ~5 ~13 dirt 0  
fill ~52 ~5 ~58 ~75 ~5 ~58 stone 0  
fill ~52 ~5 ~62 ~56 ~5 ~62 stone 0 
setblock ~54 ~5 ~7 grass 0  
fill ~56 ~5 ~7 ~58 ~5 ~7 grass 0  
fill ~56 ~5 ~57 ~75 ~5 ~57 stone 0  
fill ~56 ~5 ~65 ~58 ~5 ~65 grass 0  
fill ~57 ~5 ~12 ~102 ~5 ~12 dirt 0  
fill ~57 ~5 ~62 ~86 ~5 ~62 dirt 0  
fill ~58 ~5 ~64 ~65 ~5 ~64 grass 0  
fill ~59 ~5 ~6 ~62 ~5 ~6 grass 0  
fill ~59 ~5 ~7 ~61 ~5 ~7 stone 0  
fill ~60 ~5 ~11 ~61 ~5 ~11 dirt 0  
fill ~62 ~5 ~7 ~63 ~5 ~7 grass 0  
fill ~62 ~5 ~11 ~62 ~6 ~11 cobblestone 0  
fill ~62 ~5 ~56 ~74 ~5 ~56 stone 0  
fill ~62 ~5 ~61 ~84 ~5 ~61 dirt 0  
fill ~63 ~5 ~8 ~64 ~5 ~8 grass 0  
fill ~63 ~5 ~11 ~102 ~5 ~11 dirt 0  
fill ~65 ~5 ~8 ~65 ~11 ~8 log 0  
fill ~66 ~5 ~8 ~66 ~6 ~8 cobblestone 0  
fill ~66 ~5 ~10 ~79 ~5 ~10 dirt 0  
fill ~66 ~5 ~63 ~75 ~5 ~63 grass 0  
fill ~67 ~5 ~8 ~67 ~11 ~8 log 0  
fill ~68 ~5 ~8 ~68 ~6 ~8 cobblestone 0 
setblock ~69 ~5 ~27 grass 0  
fill ~70 ~5 ~8 ~77 ~5 ~8 dirt 0  
fill ~70 ~5 ~9 ~78 ~5 ~9 dirt 0  
fill ~70 ~5 ~27 ~75 ~5 ~27 dirt 0  
fill ~75 ~5 ~7 ~75 ~6 ~7 cobblestone 0  
fill ~75 ~5 ~38 ~75 ~8 ~38 cobblestone 0  
fill ~75 ~5 ~56 ~86 ~5 ~56 dirt 0  
fill ~75 ~5 ~60 ~83 ~5 ~60 dirt 0  
fill ~76 ~5 ~7 ~76 ~11 ~7 log 0  
fill ~76 ~5 ~27 ~86 ~5 ~27 cobblestone 0  
fill ~76 ~5 ~37 ~76 ~11 ~37 cobblestone 0  
fill ~76 ~5 ~39 ~76 ~8 ~39 cobblestone 0  
fill ~76 ~5 ~57 ~84 ~5 ~57 dirt 0  
fill ~76 ~5 ~58 ~83 ~5 ~58 dirt 0  
fill ~76 ~5 ~59 ~83 ~5 ~59 dirt 0  
fill ~77 ~5 ~7 ~77 ~6 ~7 cobblestone 0  
fill ~77 ~5 ~26 ~87 ~5 ~26 cobblestone 0  
fill ~77 ~5 ~28 ~87 ~5 ~28 cobblestone 0  
fill ~77 ~5 ~29 ~86 ~5 ~29 cobblestone 0  
fill ~77 ~5 ~30 ~86 ~5 ~30 cobblestone 0  
fill ~77 ~5 ~31 ~86 ~5 ~31 cobblestone 0  
fill ~77 ~5 ~32 ~86 ~5 ~32 cobblestone 0  
fill ~77 ~5 ~37 ~107 ~5 ~37 dirt 0  
fill ~77 ~5 ~38 ~77 ~8 ~38 cobblestone 0  
fill ~77 ~5 ~39 ~90 ~5 ~39 dirt 0  
fill ~78 ~5 ~8 ~78 ~13 ~8 log 0  
fill ~78 ~5 ~38 ~87 ~5 ~38 dirt 0  
fill ~79 ~5 ~5 ~83 ~5 ~5 cobblestone 0  
fill ~79 ~5 ~6 ~83 ~5 ~6 cobblestone 0  
fill ~79 ~5 ~7 ~84 ~5 ~7 cobblestone 0  
fill ~79 ~5 ~8 ~80 ~5 ~8 cobblestone 0  
fill ~80 ~5 ~9 ~83 ~5 ~9 cobblestone 0  
fill ~80 ~5 ~10 ~80 ~13 ~10 log 0  
fill ~80 ~5 ~17 ~80 ~5 ~22 double_stone_slab 0  
fill ~81 ~5 ~4 ~81 ~6 ~4 cobblestone 0 
setblock ~81 ~5 ~8 double_stone_slab 3  
fill ~81 ~5 ~10 ~81 ~6 ~10 cobblestone 0  
fill ~81 ~5 ~16 ~92 ~5 ~16 dirt 0  
fill ~81 ~5 ~17 ~102 ~5 ~17 dirt 0  
fill ~81 ~5 ~18 ~102 ~5 ~18 dirt 0  
fill ~81 ~5 ~19 ~84 ~5 ~19 double_stone_slab 0  
fill ~81 ~5 ~20 ~84 ~5 ~20 double_stone_slab 0  
fill ~81 ~5 ~21 ~84 ~5 ~21 double_stone_slab 0  
fill ~81 ~5 ~22 ~84 ~5 ~22 double_stone_slab 0  
fill ~82 ~5 ~8 ~83 ~5 ~8 cobblestone 0  
fill ~82 ~5 ~10 ~82 ~13 ~10 log 0  
fill ~83 ~5 ~10 ~84 ~5 ~10 redstone_wire 0 
setblock ~84 ~5 ~5 stone_stairs 2  
fill ~84 ~5 ~8 ~84 ~13 ~8 log 0 
setblock ~84 ~5 ~9 dirt 0  
fill ~84 ~5 ~58 ~110 ~5 ~58 stone 0  
fill ~84 ~5 ~59 ~107 ~5 ~59 stone 0  
fill ~84 ~5 ~60 ~107 ~5 ~60 stone 0  
fill ~85 ~5 ~6 ~89 ~5 ~6 stone_stairs 2  
fill ~85 ~5 ~19 ~102 ~5 ~19 dirt 0  
fill ~85 ~5 ~20 ~108 ~5 ~20 dirt 0  
fill ~85 ~5 ~21 ~90 ~5 ~21 dirt 0  
fill ~85 ~5 ~22 ~89 ~5 ~22 dirt 0  
fill ~85 ~5 ~57 ~112 ~5 ~57 stone 0  
fill ~85 ~5 ~61 ~101 ~5 ~61 stone 0  
fill ~87 ~5 ~8 ~89 ~5 ~8 wool 0  
fill ~87 ~5 ~9 ~89 ~5 ~9 powered_repeater 0 
setblock ~87 ~5 ~10 redstone_wire 13 
setblock ~87 ~5 ~27 water 0  
fill ~87 ~5 ~29 ~90 ~5 ~29 dirt 0  
fill ~87 ~5 ~30 ~100 ~5 ~30 dirt 0  
fill ~87 ~5 ~31 ~107 ~5 ~31 dirt 0  
fill ~87 ~5 ~32 ~107 ~5 ~32 dirt 0  
fill ~87 ~5 ~56 ~97 ~5 ~56 stone 0  
fill ~87 ~5 ~62 ~96 ~5 ~62 stone 0 
setblock ~88 ~5 ~10 redstone_wire 14  
fill ~88 ~5 ~26 ~89 ~5 ~26 dirt 0  
fill ~88 ~5 ~27 ~88 ~8 ~27 cobblestone 0  
fill ~88 ~5 ~28 ~89 ~5 ~28 dirt 0  
fill ~88 ~5 ~38 ~91 ~5 ~38 grass 0 
setblock ~89 ~5 ~10 redstone_wire 15  
fill ~89 ~5 ~27 ~89 ~6 ~27 dirt 0 
setblock ~90 ~5 ~5 stone_stairs 2  
fill ~90 ~5 ~7 ~90 ~6 ~7 cobblestone 0  
fill ~90 ~5 ~8 ~90 ~13 ~8 log 0 
setblock ~90 ~5 ~9 dirt 0 
setblock ~90 ~5 ~10 powered_repeater 3  
fill ~90 ~5 ~22 ~90 ~7 ~22 cobblestone 0  
fill ~90 ~5 ~23 ~90 ~8 ~23 cobblestone 0  
fill ~90 ~5 ~24 ~90 ~8 ~24 cobblestone 0  
fill ~90 ~5 ~25 ~90 ~8 ~25 cobblestone 0  
fill ~90 ~5 ~26 ~90 ~8 ~26 cobblestone 0  
fill ~90 ~5 ~27 ~90 ~8 ~27 cobblestone 0  
fill ~90 ~5 ~28 ~90 ~8 ~28 cobblestone 0  
fill ~91 ~5 ~5 ~91 ~6 ~5 cobblestone 0 
setblock ~91 ~5 ~9 redstone_wire 9 
setblock ~91 ~5 ~10 redstone_wire 8  
fill ~91 ~5 ~22 ~92 ~5 ~22 stone_stairs 3  
fill ~91 ~5 ~23 ~92 ~5 ~23 stone_pressure_plate 0  
fill ~91 ~5 ~24 ~92 ~5 ~24 iron_door 1  
fill ~91 ~5 ~25 ~92 ~5 ~25 stone_pressure_plate 0  
fill ~91 ~5 ~29 ~100 ~5 ~29 cobblestone 0  
fill ~91 ~5 ~39 ~92 ~5 ~39 grass 0 
setblock ~92 ~5 ~9 redstone_wire 10  
fill ~92 ~5 ~10 ~92 ~13 ~10 log 0  
fill ~92 ~5 ~15 ~92 ~6 ~15 stonebrick 0 
setblock ~92 ~5 ~21 cobblestone 0  
fill ~93 ~5 ~4 ~93 ~6 ~4 cobblestone 0  
fill ~93 ~5 ~9 ~95 ~5 ~9 cobblestone 0  
fill ~93 ~5 ~10 ~93 ~9 ~10 cobblestone 0  
fill ~93 ~5 ~14 ~93 ~6 ~14 stonebrick 0 
setblock ~93 ~5 ~15 stone_slab 13  
fill ~93 ~5 ~16 ~93 ~6 ~16 stonebrick 0  
fill ~93 ~5 ~21 ~109 ~5 ~21 dirt 0  
fill ~93 ~5 ~22 ~102 ~5 ~22 cobblestone 0  
fill ~93 ~5 ~23 ~103 ~5 ~23 cobblestone 0  
fill ~93 ~5 ~24 ~93 ~8 ~24 cobblestone 0  
fill ~93 ~5 ~25 ~93 ~8 ~25 cobblestone 0  
fill ~93 ~5 ~26 ~95 ~5 ~26 cobblestone 0  
fill ~94 ~5 ~8 ~94 ~9 ~8 cobblestone 0  
fill ~94 ~5 ~10 ~94 ~13 ~10 log 0  
fill ~94 ~5 ~14 ~102 ~5 ~14 dirt 0  
fill ~94 ~5 ~15 ~94 ~6 ~15 stonebrick 0  
fill ~94 ~5 ~16 ~102 ~5 ~16 dirt 0 
setblock ~94 ~5 ~24 bed 8 
setblock ~94 ~5 ~25 bed 0  
fill ~95 ~5 ~5 ~95 ~6 ~5 cobblestone 0  
fill ~95 ~5 ~7 ~97 ~5 ~7 cobblestone 0  
fill ~95 ~5 ~10 ~98 ~5 ~10 dirt 0  
fill ~95 ~5 ~15 ~102 ~5 ~15 dirt 0  
fill ~95 ~5 ~39 ~109 ~5 ~39 dirt 0  
fill ~96 ~5 ~6 ~96 ~13 ~6 log 0  
fill ~96 ~5 ~8 ~96 ~13 ~8 log 0  
fill ~96 ~5 ~9 ~97 ~5 ~9 dirt 0 
setblock ~96 ~5 ~26 iron_door 3  
fill ~97 ~5 ~24 ~97 ~8 ~24 cobblestone 0  
fill ~97 ~5 ~25 ~97 ~8 ~25 cobblestone 0  
fill ~97 ~5 ~26 ~99 ~5 ~26 cobblestone 0 
setblock ~97 ~5 ~62 dirt 0  
fill ~98 ~5 ~7 ~98 ~11 ~7 log 0 
setblock ~98 ~5 ~24 bed 8 
setblock ~98 ~5 ~25 bed 0  
fill ~98 ~5 ~56 ~99 ~5 ~56 dirt 0 
setblock ~98 ~5 ~62 stone 0  
fill ~99 ~5 ~7 ~99 ~6 ~7 cobblestone 0  
fill ~99 ~5 ~38 ~101 ~5 ~38 dirt 0  
fill ~99 ~5 ~62 ~105 ~5 ~62 grass 0  
fill ~100 ~5 ~7 ~100 ~11 ~7 log 0 
setblock ~100 ~5 ~9 torch 5 
setblock ~100 ~5 ~26 iron_door 3  
fill ~100 ~5 ~56 ~112 ~5 ~56 stone 0  
fill ~101 ~5 ~7 ~101 ~6 ~7 cobblestone 0  
fill ~101 ~5 ~24 ~103 ~5 ~24 cobblestone 0  
fill ~101 ~5 ~25 ~103 ~5 ~25 cobblestone 0  
fill ~101 ~5 ~26 ~102 ~5 ~26 cobblestone 0 
setblock ~101 ~5 ~29 iron_door 1  
fill ~102 ~5 ~29 ~102 ~6 ~29 cobblestone 0  
fill ~102 ~5 ~30 ~107 ~5 ~30 dirt 0  
fill ~102 ~5 ~61 ~107 ~5 ~61 grass 0  
fill ~103 ~5 ~7 ~103 ~6 ~7 cobblestone 0  
fill ~103 ~5 ~22 ~109 ~5 ~22 dirt 0  
fill ~103 ~5 ~26 ~107 ~5 ~26 dirt 0  
fill ~103 ~5 ~27 ~103 ~8 ~27 cobblestone 0  
fill ~103 ~5 ~28 ~103 ~8 ~28 cobblestone 0  
fill ~103 ~5 ~29 ~107 ~5 ~29 dirt 0  
fill ~103 ~5 ~38 ~108 ~5 ~38 dirt 0  
fill ~103 ~5 ~55 ~114 ~5 ~55 stone 0  
fill ~104 ~5 ~23 ~107 ~5 ~23 dirt 0  
fill ~104 ~5 ~24 ~107 ~5 ~24 dirt 0  
fill ~104 ~5 ~25 ~107 ~5 ~25 dirt 0  
fill ~104 ~5 ~27 ~107 ~5 ~27 dirt 0  
fill ~104 ~5 ~28 ~107 ~5 ~28 dirt 0  
fill ~105 ~5 ~7 ~105 ~6 ~7 cobblestone 0  
fill ~106 ~5 ~54 ~115 ~5 ~54 stone 0  
fill ~108 ~5 ~8 ~108 ~6 ~8 cobblestone 0  
fill ~108 ~5 ~23 ~109 ~5 ~23 grass 0  
fill ~108 ~5 ~24 ~109 ~5 ~24 grass 0  
fill ~108 ~5 ~25 ~109 ~5 ~25 grass 0  
fill ~108 ~5 ~26 ~109 ~5 ~26 grass 0  
fill ~108 ~5 ~27 ~109 ~5 ~27 grass 0  
fill ~108 ~5 ~28 ~109 ~5 ~28 grass 0  
fill ~108 ~5 ~29 ~108 ~5 ~37 grass 0  
fill ~108 ~5 ~53 ~115 ~5 ~53 stone 0  
fill ~109 ~5 ~31 ~109 ~5 ~38 grass 0 
setblock ~110 ~5 ~16 torch 5  
fill ~110 ~5 ~23 ~112 ~5 ~23 cobblestone 0  
fill ~110 ~5 ~24 ~112 ~5 ~24 cobblestone 0  
fill ~110 ~5 ~38 ~111 ~5 ~38 grass 0  
fill ~110 ~5 ~39 ~113 ~5 ~39 grass 0  
fill ~110 ~5 ~52 ~115 ~5 ~52 stone 0  
fill ~111 ~5 ~9 ~111 ~6 ~9 cobblestone 0  
fill ~111 ~5 ~51 ~116 ~5 ~51 stone 0 
setblock ~111 ~5 ~58 grass 0 
setblock ~112 ~5 ~26 torch 5  
fill ~112 ~5 ~49 ~118 ~5 ~49 stone 0  
fill ~112 ~5 ~50 ~118 ~5 ~50 stone 0 
setblock ~113 ~5 ~22 torch 5 
setblock ~113 ~5 ~32 torch 5  
fill ~113 ~5 ~40 ~115 ~5 ~40 grass 0  
fill ~113 ~5 ~48 ~118 ~5 ~48 stone 0 
setblock ~113 ~5 ~56 grass 0  
fill ~114 ~5 ~11 ~114 ~6 ~11 cobblestone 0  
fill ~114 ~5 ~45 ~118 ~5 ~45 stone 0  
fill ~114 ~5 ~46 ~118 ~5 ~46 stone 0  
fill ~114 ~5 ~47 ~118 ~5 ~47 stone 0 
setblock ~115 ~5 ~38 torch 5  
fill ~115 ~5 ~43 ~116 ~5 ~43 stone 0  
fill ~115 ~5 ~44 ~117 ~5 ~44 stone 0  
fill ~116 ~5 ~14 ~116 ~6 ~14 cobblestone 0  
fill ~116 ~5 ~41 ~116 ~5 ~42 grass 0 
setblock ~116 ~5 ~52 grass 0  
fill ~117 ~5 ~17 ~117 ~6 ~17 cobblestone 0  
fill ~117 ~5 ~42 ~117 ~5 ~43 grass 0  
fill ~118 ~5 ~20 ~118 ~6 ~20 cobblestone 0  
fill ~118 ~5 ~24 ~120 ~5 ~24 log 0  
fill ~118 ~5 ~30 ~118 ~17 ~30 log 0  
fill ~118 ~5 ~41 ~118 ~11 ~41 log 0  
fill ~118 ~5 ~42 ~118 ~6 ~42 cobblestone 0  
fill ~118 ~5 ~43 ~118 ~11 ~43 log 0  
fill ~118 ~5 ~44 ~119 ~5 ~44 grass 0  
fill ~119 ~5 ~23 ~119 ~6 ~23 cobblestone 0  
fill ~119 ~5 ~30 ~119 ~6 ~30 cobblestone 0  
fill ~119 ~5 ~31 ~119 ~6 ~31 cobblestone 0  
fill ~119 ~5 ~32 ~119 ~11 ~32 log 0  
fill ~119 ~5 ~33 ~119 ~6 ~33 cobblestone 0  
fill ~119 ~5 ~34 ~119 ~11 ~34 log 0  
fill ~119 ~5 ~35 ~119 ~6 ~35 cobblestone 0  
fill ~119 ~5 ~36 ~119 ~11 ~36 log 0  
fill ~119 ~5 ~37 ~119 ~6 ~37 cobblestone 0  
fill ~119 ~5 ~38 ~119 ~11 ~38 log 0  
fill ~119 ~5 ~39 ~119 ~6 ~39 cobblestone 0  
fill ~119 ~5 ~40 ~119 ~11 ~40 log 0  
fill ~119 ~5 ~45 ~119 ~5 ~49 grass 0  
fill ~120 ~5 ~30 ~120 ~17 ~30 log 0  
fill ~121 ~5 ~25 ~121 ~6 ~25 cobblestone 0  
fill ~121 ~5 ~29 ~121 ~6 ~29 cobblestone 0  
fill ~122 ~5 ~27 ~122 ~6 ~27 cobblestone 0  
fill ~7 ~6 ~36 ~9 ~6 ~36 grass 0  
fill ~7 ~6 ~37 ~9 ~6 ~37 grass 0  
fill ~7 ~6 ~38 ~9 ~6 ~38 grass 0  
fill ~8 ~6 ~34 ~9 ~6 ~34 grass 0  
fill ~8 ~6 ~35 ~9 ~6 ~35 grass 0  
fill ~8 ~6 ~39 ~9 ~6 ~39 grass 0  
fill ~8 ~6 ~40 ~9 ~6 ~40 grass 0  
fill ~8 ~6 ~41 ~9 ~6 ~41 grass 0  
fill ~8 ~6 ~42 ~9 ~6 ~42 grass 0  
fill ~8 ~6 ~43 ~9 ~6 ~43 grass 0  
fill ~8 ~6 ~44 ~9 ~6 ~44 grass 0 
setblock ~9 ~6 ~33 grass 0  
fill ~9 ~6 ~45 ~9 ~6 ~49 grass 0  
fill ~10 ~6 ~27 ~11 ~6 ~27 grass 0  
fill ~10 ~6 ~28 ~11 ~6 ~28 grass 0  
fill ~10 ~6 ~29 ~18 ~6 ~29 stone 0  
fill ~10 ~6 ~30 ~17 ~6 ~30 stone 0  
fill ~10 ~6 ~31 ~16 ~6 ~31 stone 0  
fill ~10 ~6 ~32 ~15 ~6 ~32 stone 0  
fill ~10 ~6 ~33 ~14 ~6 ~33 stone 0  
fill ~10 ~6 ~34 ~15 ~6 ~34 stone 0  
fill ~10 ~6 ~35 ~15 ~6 ~35 stone 0  
fill ~10 ~6 ~36 ~15 ~6 ~36 stone 0  
fill ~10 ~6 ~37 ~15 ~6 ~37 stone 0  
fill ~10 ~6 ~38 ~15 ~6 ~38 stone 0  
fill ~10 ~6 ~39 ~14 ~6 ~39 stone 0  
fill ~10 ~6 ~40 ~13 ~6 ~40 stone 0  
fill ~10 ~6 ~41 ~12 ~6 ~41 stone 0  
fill ~10 ~6 ~42 ~13 ~6 ~42 stone 0  
fill ~10 ~6 ~43 ~14 ~6 ~43 stone 0  
fill ~10 ~6 ~44 ~14 ~6 ~44 stone 0  
fill ~10 ~6 ~45 ~15 ~6 ~45 stone 0  
fill ~10 ~6 ~46 ~16 ~6 ~46 stone 0  
fill ~10 ~6 ~47 ~16 ~6 ~47 stone 0  
fill ~10 ~6 ~48 ~16 ~6 ~48 stone 0  
fill ~10 ~6 ~49 ~19 ~6 ~49 stone 0 
setblock ~10 ~6 ~50 grass 0  
fill ~11 ~6 ~50 ~20 ~6 ~50 stone 0 
setblock ~11 ~6 ~51 grass 0 
setblock ~12 ~6 ~25 grass 0  
fill ~12 ~6 ~26 ~19 ~6 ~26 stone 0  
fill ~12 ~6 ~27 ~19 ~6 ~27 stone 0  
fill ~12 ~6 ~28 ~18 ~6 ~28 stone 0  
fill ~12 ~6 ~51 ~22 ~6 ~51 stone 0  
fill ~12 ~6 ~52 ~13 ~6 ~52 grass 0 
setblock ~13 ~6 ~24 grass 0  
fill ~13 ~6 ~25 ~21 ~6 ~25 stone 0  
fill ~13 ~6 ~41 ~115 ~6 ~41 dirt 0  
fill ~14 ~6 ~22 ~15 ~6 ~22 grass 0  
fill ~14 ~6 ~23 ~14 ~6 ~22 grass 0  
fill ~14 ~6 ~24 ~22 ~6 ~24 stone 0  
fill ~14 ~6 ~40 ~112 ~6 ~40 dirt 0  
fill ~14 ~6 ~42 ~115 ~6 ~42 dirt 0  
fill ~14 ~6 ~52 ~23 ~6 ~52 stone 0  
fill ~15 ~6 ~23 ~23 ~6 ~23 stone 0  
fill ~15 ~6 ~33 ~100 ~6 ~33 dirt 0  
fill ~15 ~6 ~39 ~75 ~6 ~39 dirt 0  
fill ~15 ~6 ~43 ~115 ~6 ~43 dirt 0  
fill ~15 ~6 ~44 ~103 ~6 ~44 dirt 0  
fill ~15 ~6 ~53 ~24 ~6 ~53 stone 0  
fill ~15 ~6 ~54 ~25 ~6 ~54 stone 0  
fill ~15 ~6 ~55 ~17 ~6 ~55 grass 0 
setblock ~16 ~6 ~21 grass 0  
fill ~16 ~6 ~22 ~24 ~6 ~22 stone 0  
fill ~16 ~6 ~32 ~76 ~6 ~32 dirt 0  
fill ~16 ~6 ~34 ~100 ~6 ~34 dirt 0  
fill ~16 ~6 ~35 ~101 ~6 ~35 dirt 0  
fill ~16 ~6 ~36 ~102 ~6 ~36 dirt 0  
fill ~16 ~6 ~37 ~75 ~6 ~37 dirt 0  
fill ~16 ~6 ~38 ~74 ~6 ~38 dirt 0  
fill ~16 ~6 ~45 ~114 ~6 ~45 dirt 0  
fill ~16 ~6 ~56 ~17 ~6 ~56 grass 0  
fill ~17 ~6 ~19 ~18 ~6 ~19 grass 0  
fill ~17 ~6 ~20 ~27 ~6 ~20 stone 0  
fill ~17 ~6 ~21 ~26 ~6 ~21 stone 0  
fill ~17 ~6 ~31 ~76 ~6 ~31 dirt 0  
fill ~17 ~6 ~46 ~114 ~6 ~46 dirt 0  
fill ~17 ~6 ~47 ~113 ~6 ~47 dirt 0  
fill ~17 ~6 ~48 ~112 ~6 ~48 dirt 0  
fill ~18 ~6 ~30 ~76 ~6 ~30 dirt 0  
fill ~18 ~6 ~55 ~25 ~6 ~55 stone 0  
fill ~18 ~6 ~56 ~26 ~6 ~56 stone 0  
fill ~18 ~6 ~57 ~26 ~6 ~57 stone 0  
fill ~18 ~6 ~58 ~21 ~6 ~58 grass 0 
setblock ~19 ~6 ~18 grass 0  
fill ~19 ~6 ~19 ~35 ~6 ~19 stone 0  
fill ~19 ~6 ~28 ~76 ~6 ~28 dirt 0  
fill ~19 ~6 ~29 ~76 ~6 ~29 dirt 0 
setblock ~20 ~6 ~17 grass 0  
fill ~20 ~6 ~18 ~36 ~6 ~18 stone 0  
fill ~20 ~6 ~26 ~76 ~6 ~26 dirt 0  
fill ~20 ~6 ~27 ~68 ~6 ~27 dirt 0  
fill ~20 ~6 ~49 ~112 ~6 ~49 dirt 0  
fill ~21 ~6 ~16 ~22 ~6 ~16 grass 0  
fill ~21 ~6 ~17 ~43 ~6 ~17 stone 0  
fill ~21 ~6 ~50 ~111 ~6 ~50 dirt 0 
setblock ~21 ~6 ~59 grass 0  
fill ~22 ~6 ~25 ~89 ~6 ~25 dirt 0  
fill ~22 ~6 ~58 ~32 ~6 ~58 stone 0  
fill ~22 ~6 ~59 ~25 ~6 ~59 stone 0 
setblock ~22 ~6 ~60 grass 0  
fill ~23 ~6 ~15 ~24 ~6 ~15 grass 0  
fill ~23 ~6 ~16 ~48 ~6 ~16 stone 0  
fill ~23 ~6 ~24 ~89 ~6 ~24 dirt 0  
fill ~23 ~6 ~51 ~110 ~6 ~51 dirt 0  
fill ~23 ~6 ~60 ~26 ~6 ~60 dirt 0  
fill ~23 ~6 ~61 ~26 ~6 ~61 grass 0  
fill ~24 ~6 ~14 ~26 ~6 ~14 grass 0  
fill ~24 ~6 ~23 ~79 ~6 ~23 dirt 0  
fill ~24 ~6 ~52 ~109 ~6 ~52 dirt 0  
fill ~25 ~6 ~15 ~49 ~6 ~15 stone 0  
fill ~25 ~6 ~22 ~75 ~6 ~22 dirt 0  
fill ~25 ~6 ~53 ~107 ~6 ~53 dirt 0  
fill ~26 ~6 ~54 ~103 ~6 ~54 dirt 0  
fill ~26 ~6 ~55 ~60 ~6 ~55 dirt 0 
setblock ~26 ~6 ~59 dirt 0  
fill ~26 ~6 ~62 ~29 ~6 ~62 grass 0  
fill ~27 ~6 ~13 ~32 ~6 ~13 grass 0  
fill ~27 ~6 ~14 ~50 ~6 ~14 stone 0  
fill ~27 ~6 ~21 ~70 ~6 ~21 dirt 0  
fill ~27 ~6 ~56 ~54 ~6 ~56 dirt 0  
fill ~27 ~6 ~57 ~27 ~6 ~21 dirt 0  
fill ~27 ~6 ~59 ~36 ~6 ~59 stone 0  
fill ~27 ~6 ~60 ~40 ~6 ~60 stone 0 
setblock ~27 ~6 ~61 dirt 0  
fill ~28 ~6 ~20 ~65 ~6 ~20 dirt 0  
fill ~28 ~6 ~57 ~30 ~6 ~57 stone 0  
fill ~28 ~6 ~61 ~75 ~6 ~61 stone 0  
fill ~28 ~6 ~63 ~30 ~6 ~63 grass 0  
fill ~30 ~6 ~62 ~62 ~6 ~62 stone 0  
fill ~31 ~6 ~57 ~50 ~6 ~57 dirt 0  
fill ~31 ~6 ~63 ~32 ~6 ~63 dirt 0  
fill ~31 ~6 ~64 ~32 ~6 ~64 grass 0  
fill ~32 ~6 ~65 ~34 ~6 ~65 grass 0  
fill ~33 ~6 ~58 ~49 ~6 ~58 dirt 0  
fill ~33 ~6 ~63 ~56 ~6 ~63 stone 0  
fill ~33 ~6 ~64 ~35 ~6 ~64 dirt 0  
fill ~34 ~6 ~66 ~36 ~6 ~66 grass 0  
fill ~35 ~6 ~65 ~39 ~6 ~65 dirt 0  
fill ~36 ~6 ~19 ~64 ~6 ~19 dirt 0  
fill ~36 ~6 ~64 ~49 ~6 ~64 stone 0  
fill ~37 ~6 ~18 ~64 ~6 ~18 dirt 0  
fill ~37 ~6 ~59 ~46 ~6 ~59 dirt 0  
fill ~37 ~6 ~66 ~43 ~6 ~66 dirt 0  
fill ~37 ~6 ~67 ~46 ~6 ~67 grass 0 
setblock ~39 ~6 ~13 grass 0  
fill ~40 ~6 ~11 ~41 ~6 ~11 grass 0  
fill ~40 ~6 ~12 ~56 ~6 ~12 stone 0  
fill ~40 ~6 ~13 ~51 ~6 ~13 stone 0  
fill ~40 ~6 ~65 ~49 ~6 ~65 stone 0  
fill ~41 ~6 ~60 ~43 ~6 ~60 dirt 0 
setblock ~42 ~6 ~10 grass 0  
fill ~42 ~6 ~11 ~58 ~6 ~11 stone 0  
fill ~43 ~6 ~10 ~45 ~6 ~10 stone 0  
fill ~44 ~6 ~9 ~45 ~6 ~9 grass 0  
fill ~44 ~6 ~17 ~64 ~6 ~17 dirt 0  
fill ~44 ~6 ~60 ~105 ~6 ~60 stone 0  
fill ~44 ~6 ~66 ~46 ~6 ~66 stone 0 
setblock ~46 ~6 ~10 grass 0  
fill ~47 ~6 ~59 ~107 ~6 ~59 stone 0  
fill ~47 ~6 ~66 ~50 ~6 ~66 grass 0  
fill ~48 ~6 ~9 ~49 ~6 ~9 grass 0  
fill ~48 ~6 ~10 ~48 ~0 ~10 stone 0 
setblock ~49 ~6 ~8 grass 0 
setblock ~49 ~6 ~10 dirt 0  
fill ~49 ~6 ~16 ~64 ~6 ~16 dirt 0  
fill ~50 ~6 ~8 ~54 ~6 ~8 stone 0  
fill ~50 ~6 ~9 ~55 ~6 ~9 stone 0  
fill ~50 ~6 ~10 ~61 ~6 ~10 stone 0  
fill ~50 ~6 ~15 ~63 ~6 ~15 dirt 0  
fill ~50 ~6 ~58 ~108 ~6 ~58 stone 0  
fill ~50 ~6 ~64 ~54 ~6 ~64 dirt 0  
fill ~50 ~6 ~65 ~55 ~6 ~65 grass 0  
fill ~51 ~6 ~7 ~53 ~6 ~7 grass 0  
fill ~51 ~6 ~14 ~63 ~6 ~14 dirt 0  
fill ~51 ~6 ~57 ~110 ~6 ~57 stone 0  
fill ~52 ~6 ~13 ~62 ~6 ~13 dirt 0  
fill ~55 ~6 ~8 ~60 ~6 ~8 grass 0  
fill ~55 ~6 ~56 ~112 ~6 ~56 stone 0  
fill ~55 ~6 ~64 ~57 ~6 ~64 grass 0 
setblock ~56 ~6 ~9 dirt 0 
setblock ~57 ~6 ~9 grass 0  
fill ~57 ~6 ~12 ~62 ~6 ~12 dirt 0  
fill ~57 ~6 ~63 ~65 ~6 ~63 grass 0 
setblock ~58 ~6 ~9 dirt 0  
fill ~59 ~6 ~7 ~61 ~6 ~7 grass 0 
setblock ~59 ~6 ~9 grass 0  
fill ~59 ~6 ~11 ~61 ~6 ~11 dirt 0  
fill ~60 ~6 ~9 ~62 ~6 ~9 stone 0 
setblock ~61 ~6 ~8 dirt 0  
fill ~61 ~6 ~55 ~75 ~6 ~55 stone 0 
setblock ~62 ~6 ~8 grass 0 
setblock ~62 ~6 ~10 cobblestone 0 
setblock ~63 ~6 ~9 cobblestone 0  
fill ~63 ~6 ~10 ~64 ~6 ~10 double_stone_slab 3  
fill ~63 ~6 ~11 ~64 ~6 ~11 double_stone_slab 3  
fill ~63 ~6 ~12 ~63 ~6 ~13 cobblestone 0  
fill ~63 ~6 ~62 ~64 ~6 ~62 dirt 0  
fill ~64 ~6 ~9 ~64 ~11 ~9 log 0  
fill ~64 ~6 ~12 ~64 ~6 ~13 double_stone_slab 3  
fill ~64 ~6 ~14 ~64 ~11 ~14 cobblestone 0  
fill ~64 ~6 ~15 ~64 ~12 ~15 cobblestone 0  
fill ~65 ~6 ~9 ~69 ~6 ~9 gravel 0  
fill ~65 ~6 ~10 ~69 ~6 ~10 gravel 0  
fill ~65 ~6 ~11 ~69 ~6 ~11 gravel 0  
fill ~65 ~6 ~12 ~69 ~6 ~12 gravel 0  
fill ~65 ~6 ~13 ~69 ~6 ~13 gravel 0  
fill ~65 ~6 ~14 ~70 ~6 ~14 gravel 0  
fill ~65 ~6 ~15 ~70 ~6 ~15 gravel 0  
fill ~65 ~6 ~16 ~70 ~6 ~16 gravel 0  
fill ~65 ~6 ~17 ~69 ~6 ~17 gravel 0  
fill ~65 ~6 ~18 ~69 ~6 ~18 gravel 0  
fill ~65 ~6 ~19 ~69 ~6 ~19 gravel 0  
fill ~65 ~6 ~62 ~98 ~6 ~62 grass 0  
fill ~66 ~6 ~20 ~69 ~6 ~20 gravel 0  
fill ~70 ~6 ~8 ~77 ~6 ~8 cobblestone 0  
fill ~70 ~6 ~9 ~79 ~6 ~9 cobblestone 0  
fill ~70 ~6 ~10 ~79 ~6 ~10 cobblestone 0  
fill ~70 ~6 ~11 ~98 ~6 ~11 cobblestone 0  
fill ~70 ~6 ~12 ~92 ~6 ~12 cobblestone 0  
fill ~70 ~6 ~13 ~91 ~6 ~13 cobblestone 0  
fill ~70 ~6 ~17 ~79 ~6 ~17 cobblestone 0  
fill ~70 ~6 ~18 ~79 ~6 ~18 cobblestone 0  
fill ~70 ~6 ~19 ~78 ~6 ~19 cobblestone 0  
fill ~70 ~6 ~20 ~78 ~6 ~20 cobblestone 0  
fill ~70 ~6 ~27 ~75 ~6 ~27 dirt 0  
fill ~71 ~6 ~14 ~90 ~6 ~14 cobblestone 0  
fill ~71 ~6 ~15 ~89 ~6 ~15 cobblestone 0  
fill ~71 ~6 ~16 ~79 ~6 ~16 cobblestone 0  
fill ~71 ~6 ~21 ~78 ~6 ~21 cobblestone 0  
fill ~76 ~6 ~22 ~78 ~6 ~22 cobblestone 0  
fill ~76 ~6 ~27 ~86 ~6 ~27 cobblestone 0  
fill ~76 ~6 ~55 ~86 ~6 ~55 dirt 0  
fill ~76 ~6 ~61 ~82 ~6 ~61 dirt 0  
fill ~77 ~6 ~26 ~87 ~6 ~26 cobblestone 0  
fill ~77 ~6 ~28 ~87 ~6 ~28 cobblestone 0  
fill ~77 ~6 ~29 ~86 ~6 ~29 cobblestone 0  
fill ~77 ~6 ~30 ~86 ~6 ~30 cobblestone 0  
fill ~77 ~6 ~31 ~86 ~6 ~31 cobblestone 0  
fill ~77 ~6 ~32 ~86 ~6 ~32 cobblestone 0  
fill ~77 ~6 ~37 ~89 ~6 ~37 dirt 0  
fill ~77 ~6 ~39 ~90 ~6 ~39 dirt 0  
fill ~78 ~6 ~38 ~87 ~6 ~38 dirt 0  
fill ~79 ~6 ~5 ~79 ~5 ~5 cobblestone 0  
fill ~79 ~6 ~7 ~79 ~13 ~7 ladder 5  
fill ~79 ~6 ~19 ~79 ~6 ~22 mossy_cobblestone 0  
fill ~80 ~6 ~9 ~82 ~6 ~9 stone_slab 3 
setblock ~80 ~6 ~16 stone_stairs 3  
fill ~80 ~6 ~23 ~84 ~6 ~23 mossy_cobblestone 0  
fill ~81 ~6 ~16 ~90 ~6 ~16 cobblestone 0  
fill ~81 ~6 ~17 ~91 ~6 ~17 cobblestone 0  
fill ~81 ~6 ~18 ~84 ~6 ~18 mossy_cobblestone 0  
fill ~81 ~6 ~19 ~81 ~7 ~19 fence 0 
setblock ~83 ~6 ~5 cobblestone 0  
fill ~83 ~6 ~9 ~90 ~6 ~9 cobblestone 0  
fill ~83 ~6 ~10 ~91 ~6 ~10 cobblestone 0 
setblock ~83 ~6 ~19 bed 0 
setblock ~83 ~6 ~22 oak_stairs 1  
fill ~83 ~6 ~61 ~98 ~6 ~61 stone 0 
setblock ~84 ~6 ~7 cobblestone 0 
setblock ~84 ~6 ~19 bed 8 
setblock ~84 ~6 ~22 fence 0  
fill ~85 ~6 ~7 ~89 ~6 ~7 stone_stairs 2  
fill ~85 ~6 ~8 ~89 ~6 ~8 cobblestone 0  
fill ~85 ~6 ~18 ~92 ~6 ~18 cobblestone 0  
fill ~85 ~6 ~19 ~85 ~6 ~22 mossy_cobblestone 0  
fill ~85 ~6 ~23 ~89 ~6 ~23 dirt 0  
fill ~86 ~6 ~19 ~117 ~6 ~19 cobblestone 0  
fill ~86 ~6 ~20 ~118 ~6 ~20 cobblestone 0  
fill ~86 ~6 ~21 ~90 ~6 ~21 cobblestone 0  
fill ~86 ~6 ~22 ~90 ~6 ~22 cobblestone 0  
fill ~87 ~6 ~29 ~90 ~6 ~29 dirt 0  
fill ~87 ~6 ~30 ~100 ~6 ~30 dirt 0  
fill ~87 ~6 ~31 ~103 ~6 ~31 dirt 0  
fill ~87 ~6 ~32 ~101 ~6 ~32 dirt 0  
fill ~87 ~6 ~55 ~98 ~6 ~55 stone 0  
fill ~88 ~6 ~26 ~89 ~6 ~26 dirt 0  
fill ~88 ~6 ~28 ~89 ~6 ~28 dirt 0 
setblock ~90 ~6 ~15 stonebrick 0  
fill ~90 ~6 ~37 ~91 ~6 ~37 cobblestone 0  
fill ~91 ~6 ~14 ~95 ~6 ~14 stonebrick 0 
setblock ~91 ~6 ~15 cobblestone 0  
fill ~91 ~6 ~16 ~95 ~6 ~16 stonebrick 0  
fill ~91 ~6 ~21 ~92 ~6 ~21 stone_stairs 3 
setblock ~91 ~6 ~24 iron_door 9  
fill ~91 ~6 ~29 ~100 ~6 ~29 cobblestone 0 
setblock ~92 ~6 ~13 stonebrick 0 
setblock ~92 ~6 ~17 stonebrick 0 
setblock ~92 ~6 ~24 iron_door 8  
fill ~92 ~6 ~37 ~104 ~6 ~37 dirt 0  
fill ~93 ~6 ~7 ~93 ~6 ~8 cobblestone 0 
setblock ~93 ~6 ~9 redstone_wire 11 
setblock ~93 ~6 ~12 stonebrick 0 
setblock ~93 ~6 ~13 cobblestone 0  
fill ~93 ~6 ~15 ~93 ~9 ~15 water 8 
setblock ~93 ~6 ~17 cobblestone 0 
setblock ~93 ~6 ~18 stonebrick 0  
fill ~93 ~6 ~21 ~93 ~6 ~22 double_stone_slab 3  
fill ~93 ~6 ~23 ~103 ~6 ~23 cobblestone 0  
fill ~93 ~6 ~26 ~93 ~7 ~26 cobblestone 0  
fill ~93 ~6 ~38 ~93 ~7 ~38 dirt 0  
fill ~93 ~6 ~39 ~109 ~6 ~39 dirt 0  
fill ~94 ~6 ~9 ~109 ~6 ~9 cobblestone 0  
fill ~94 ~6 ~12 ~114 ~6 ~12 cobblestone 0 
setblock ~94 ~6 ~13 double_stone_slab 5 
setblock ~94 ~6 ~17 stonebrick 0  
fill ~94 ~6 ~18 ~116 ~6 ~18 cobblestone 0  
fill ~94 ~6 ~21 ~117 ~6 ~21 cobblestone 0  
fill ~94 ~6 ~22 ~112 ~6 ~22 cobblestone 0 
setblock ~94 ~6 ~26 iron_bars 0  
fill ~95 ~6 ~7 ~97 ~6 ~7 cobblestone 0  
fill ~95 ~6 ~8 ~95 ~6 ~7 cobblestone 0  
fill ~95 ~6 ~10 ~112 ~6 ~10 cobblestone 0  
fill ~95 ~6 ~13 ~115 ~6 ~13 cobblestone 0 
setblock ~95 ~6 ~15 cobblestone 0  
fill ~95 ~6 ~17 ~117 ~6 ~17 cobblestone 0  
fill ~95 ~6 ~26 ~95 ~7 ~26 cobblestone 0  
fill ~95 ~6 ~38 ~108 ~6 ~38 dirt 0  
fill ~96 ~6 ~14 ~116 ~6 ~14 cobblestone 0 
setblock ~96 ~6 ~15 stonebrick 0  
fill ~96 ~6 ~16 ~116 ~6 ~16 cobblestone 0 
setblock ~96 ~6 ~26 iron_door 8  
fill ~97 ~6 ~8 ~106 ~6 ~8 cobblestone 0  
fill ~97 ~6 ~15 ~115 ~6 ~15 cobblestone 0  
fill ~97 ~6 ~26 ~97 ~8 ~26 cobblestone 0 
setblock ~97 ~6 ~27 stone_button 3 
setblock ~98 ~6 ~26 iron_bars 0 
setblock ~99 ~6 ~11 netherrack 0  
fill ~99 ~6 ~26 ~99 ~8 ~26 cobblestone 0  
fill ~99 ~6 ~55 ~100 ~6 ~55 dirt 0  
fill ~99 ~6 ~61 ~101 ~6 ~61 grass 0  
fill ~100 ~6 ~11 ~114 ~6 ~11 cobblestone 0 
setblock ~100 ~6 ~26 iron_door 8  
fill ~101 ~6 ~24 ~103 ~6 ~24 cobblestone 0  
fill ~101 ~6 ~25 ~103 ~6 ~25 cobblestone 0  
fill ~101 ~6 ~26 ~102 ~6 ~26 cobblestone 0 
setblock ~101 ~6 ~27 stone_button 3 
setblock ~101 ~6 ~29 iron_door 8  
fill ~101 ~6 ~33 ~106 ~6 ~33 cobblestone 0  
fill ~101 ~6 ~34 ~106 ~6 ~34 cobblestone 0  
fill ~101 ~6 ~55 ~112 ~6 ~55 stone 0  
fill ~102 ~6 ~30 ~103 ~6 ~30 dirt 0  
fill ~102 ~6 ~32 ~106 ~6 ~32 cobblestone 0  
fill ~102 ~6 ~35 ~106 ~6 ~35 cobblestone 0  
fill ~103 ~6 ~26 ~105 ~6 ~26 dirt 0  
fill ~103 ~6 ~29 ~103 ~0 ~29 dirt 0  
fill ~103 ~6 ~36 ~106 ~6 ~36 cobblestone 0  
fill ~104 ~6 ~23 ~104 ~0 ~23 dirt 0  
fill ~104 ~6 ~24 ~105 ~6 ~24 dirt 0  
fill ~104 ~6 ~25 ~105 ~6 ~25 dirt 0  
fill ~104 ~6 ~27 ~105 ~6 ~27 dirt 0  
fill ~104 ~6 ~28 ~106 ~6 ~28 cobblestone 0  
fill ~104 ~6 ~29 ~106 ~6 ~29 cobblestone 0  
fill ~104 ~6 ~30 ~106 ~6 ~30 cobblestone 0  
fill ~104 ~6 ~31 ~106 ~6 ~31 cobblestone 0 
setblock ~104 ~6 ~44 grass 0  
fill ~104 ~6 ~54 ~113 ~6 ~54 stone 0  
fill ~105 ~6 ~23 ~106 ~6 ~23 cobblestone 0  
fill ~105 ~6 ~37 ~106 ~6 ~37 cobblestone 0  
fill ~105 ~6 ~44 ~114 ~6 ~44 dirt 0  
fill ~106 ~6 ~24 ~106 ~8 ~24 cobblestone 0  
fill ~106 ~6 ~25 ~106 ~8 ~25 cobblestone 0  
fill ~106 ~6 ~26 ~106 ~8 ~26 cobblestone 0  
fill ~106 ~6 ~27 ~106 ~8 ~27 cobblestone 0  
fill ~106 ~6 ~60 ~107 ~6 ~60 grass 0  
fill ~107 ~6 ~23 ~107 ~6 ~53 dirt 0 
setblock ~108 ~6 ~24 torch 5 
setblock ~108 ~6 ~28 torch 5 
setblock ~108 ~6 ~34 torch 5  
fill ~108 ~6 ~53 ~115 ~6 ~53 stone 0  
fill ~109 ~6 ~58 ~110 ~6 ~58 grass 0  
fill ~110 ~6 ~23 ~112 ~6 ~23 cobblestone 0  
fill ~110 ~6 ~24 ~112 ~6 ~24 cobblestone 0  
fill ~110 ~6 ~52 ~115 ~6 ~52 stone 0 
setblock ~111 ~6 ~38 torch 5  
fill ~111 ~6 ~51 ~116 ~6 ~51 stone 0  
fill ~111 ~6 ~57 ~112 ~6 ~57 grass 0  
fill ~112 ~6 ~50 ~117 ~6 ~50 stone 0  
fill ~113 ~6 ~22 ~113 ~10 ~22 log 0  
fill ~113 ~6 ~48 ~117 ~6 ~48 stone 0  
fill ~113 ~6 ~49 ~117 ~6 ~49 stone 0  
fill ~113 ~6 ~55 ~114 ~6 ~55 grass 0 
setblock ~114 ~6 ~10 stone_stairs 6  
fill ~114 ~6 ~22 ~118 ~6 ~22 cobblestone 0  
fill ~114 ~6 ~47 ~117 ~6 ~47 stone 0  
fill ~114 ~6 ~54 ~115 ~6 ~54 grass 0 
setblock ~115 ~6 ~11 stone_stairs 5  
fill ~115 ~6 ~44 ~116 ~6 ~44 stone 0  
fill ~115 ~6 ~45 ~117 ~6 ~45 stone 0  
fill ~115 ~6 ~46 ~117 ~6 ~46 stone 0 
setblock ~116 ~6 ~42 torch 1 
setblock ~116 ~6 ~43 stone 0  
fill ~117 ~6 ~44 ~117 ~11 ~44 log 0  
fill ~118 ~6 ~24 ~120 ~6 ~24 log 0 
setblock ~118 ~6 ~45 dirt 0  
fill ~118 ~6 ~46 ~118 ~6 ~50 grass 0  
fill ~10 ~7 ~29 ~10 ~7 ~30 grass 0  
fill ~10 ~7 ~31 ~16 ~7 ~31 stone 0  
fill ~10 ~7 ~32 ~15 ~7 ~32 stone 0  
fill ~10 ~7 ~33 ~14 ~7 ~33 stone 0 
setblock ~10 ~7 ~34 grass 0  
fill ~10 ~7 ~35 ~15 ~7 ~35 stone 0  
fill ~10 ~7 ~36 ~15 ~7 ~36 stone 0  
fill ~10 ~7 ~37 ~15 ~7 ~37 stone 0  
fill ~10 ~7 ~38 ~15 ~7 ~38 stone 0  
fill ~10 ~7 ~39 ~14 ~7 ~39 stone 0  
fill ~10 ~7 ~40 ~13 ~7 ~40 stone 0  
fill ~10 ~7 ~41 ~13 ~7 ~41 stone 0  
fill ~10 ~7 ~42 ~14 ~7 ~42 stone 0  
fill ~10 ~7 ~43 ~14 ~7 ~43 stone 0  
fill ~10 ~7 ~44 ~15 ~7 ~44 stone 0  
fill ~10 ~7 ~45 ~16 ~7 ~45 stone 0  
fill ~10 ~7 ~46 ~16 ~7 ~46 stone 0  
fill ~10 ~7 ~47 ~17 ~7 ~47 stone 0  
fill ~10 ~7 ~48 ~10 ~7 ~49 grass 0  
fill ~11 ~7 ~29 ~18 ~7 ~29 stone 0  
fill ~11 ~7 ~30 ~17 ~7 ~30 stone 0  
fill ~11 ~7 ~34 ~15 ~7 ~34 stone 0  
fill ~11 ~7 ~48 ~17 ~7 ~48 stone 0  
fill ~11 ~7 ~49 ~19 ~7 ~49 stone 0 
setblock ~11 ~7 ~50 grass 0  
fill ~12 ~7 ~26 ~13 ~7 ~26 grass 0  
fill ~12 ~7 ~27 ~12 ~7 ~26 grass 0  
fill ~12 ~7 ~28 ~19 ~7 ~28 stone 0  
fill ~12 ~7 ~50 ~21 ~7 ~50 stone 0 
setblock ~12 ~7 ~51 grass 0 
setblock ~13 ~7 ~25 grass 0  
fill ~13 ~7 ~27 ~19 ~7 ~27 stone 0 
setblock ~13 ~7 ~51 dirt 0 
setblock ~14 ~7 ~24 grass 0  
fill ~14 ~7 ~25 ~22 ~7 ~25 stone 0  
fill ~14 ~7 ~26 ~20 ~7 ~26 stone 0  
fill ~14 ~7 ~40 ~101 ~7 ~40 dirt 0  
fill ~14 ~7 ~41 ~105 ~7 ~41 dirt 0  
fill ~14 ~7 ~51 ~23 ~7 ~51 stone 0  
fill ~14 ~7 ~52 ~24 ~7 ~52 stone 0 
setblock ~15 ~7 ~23 grass 0  
fill ~15 ~7 ~24 ~23 ~7 ~24 stone 0  
fill ~15 ~7 ~33 ~87 ~7 ~33 dirt 0  
fill ~15 ~7 ~39 ~75 ~7 ~39 dirt 0  
fill ~15 ~7 ~42 ~106 ~7 ~42 dirt 0  
fill ~15 ~7 ~43 ~93 ~7 ~43 dirt 0  
fill ~15 ~7 ~53 ~25 ~7 ~53 stone 0 
setblock ~15 ~7 ~54 grass 0 
setblock ~16 ~7 ~22 grass 0  
fill ~16 ~7 ~23 ~24 ~7 ~23 stone 0  
fill ~16 ~7 ~32 ~72 ~7 ~32 dirt 0  
fill ~16 ~7 ~34 ~91 ~7 ~34 dirt 0  
fill ~16 ~7 ~35 ~94 ~7 ~35 dirt 0  
fill ~16 ~7 ~36 ~95 ~7 ~36 dirt 0  
fill ~16 ~7 ~37 ~75 ~7 ~37 dirt 0  
fill ~16 ~7 ~38 ~74 ~7 ~38 dirt 0  
fill ~16 ~7 ~44 ~103 ~7 ~44 dirt 0  
fill ~16 ~7 ~54 ~16 ~9 ~54 stone 0  
fill ~17 ~7 ~20 ~20 ~7 ~20 grass 0  
fill ~17 ~7 ~21 ~17 ~7 ~20 grass 0  
fill ~17 ~7 ~22 ~26 ~7 ~22 stone 0  
fill ~17 ~7 ~31 ~71 ~7 ~31 dirt 0  
fill ~17 ~7 ~45 ~114 ~7 ~45 dirt 0  
fill ~17 ~7 ~46 ~114 ~7 ~46 dirt 0  
fill ~17 ~7 ~54 ~17 ~11 ~54 cobblestone 0  
fill ~18 ~7 ~21 ~27 ~7 ~21 stone 0  
fill ~18 ~7 ~30 ~70 ~7 ~30 dirt 0  
fill ~18 ~7 ~47 ~113 ~7 ~47 dirt 0  
fill ~18 ~7 ~48 ~113 ~7 ~48 dirt 0  
fill ~18 ~7 ~54 ~26 ~7 ~54 stone 0  
fill ~18 ~7 ~55 ~19 ~7 ~55 grass 0  
fill ~18 ~7 ~56 ~19 ~7 ~56 grass 0  
fill ~18 ~7 ~57 ~21 ~7 ~57 grass 0  
fill ~19 ~7 ~19 ~21 ~7 ~19 grass 0  
fill ~19 ~7 ~29 ~70 ~7 ~29 dirt 0  
fill ~20 ~7 ~18 ~21 ~7 ~18 grass 0  
fill ~20 ~7 ~27 ~68 ~7 ~27 dirt 0  
fill ~20 ~7 ~28 ~70 ~7 ~28 dirt 0  
fill ~20 ~7 ~49 ~112 ~7 ~49 dirt 0  
fill ~20 ~7 ~55 ~27 ~7 ~55 stone 0  
fill ~20 ~7 ~56 ~31 ~7 ~56 stone 0  
fill ~21 ~7 ~17 ~23 ~7 ~17 grass 0  
fill ~21 ~7 ~20 ~35 ~7 ~20 stone 0  
fill ~21 ~7 ~26 ~68 ~7 ~26 dirt 0  
fill ~22 ~7 ~18 ~43 ~7 ~18 stone 0  
fill ~22 ~7 ~19 ~36 ~7 ~19 stone 0  
fill ~22 ~7 ~50 ~111 ~7 ~50 dirt 0  
fill ~22 ~7 ~57 ~33 ~7 ~57 stone 0  
fill ~22 ~7 ~58 ~22 ~7 ~59 grass 0  
fill ~23 ~7 ~16 ~25 ~7 ~16 grass 0  
fill ~23 ~7 ~25 ~68 ~7 ~25 dirt 0  
fill ~23 ~7 ~58 ~37 ~7 ~58 stone 0  
fill ~23 ~7 ~59 ~23 ~7 ~60 grass 0  
fill ~24 ~7 ~17 ~45 ~7 ~17 stone 0  
fill ~24 ~7 ~24 ~68 ~7 ~24 dirt 0  
fill ~24 ~7 ~51 ~110 ~7 ~51 dirt 0  
fill ~24 ~7 ~59 ~41 ~7 ~59 stone 0  
fill ~24 ~7 ~60 ~26 ~7 ~60 grass 0  
fill ~25 ~7 ~15 ~27 ~7 ~15 grass 0  
fill ~25 ~7 ~23 ~68 ~7 ~23 dirt 0  
fill ~25 ~7 ~52 ~109 ~7 ~52 dirt 0  
fill ~26 ~7 ~16 ~48 ~7 ~16 stone 0  
fill ~26 ~7 ~53 ~107 ~7 ~53 dirt 0  
fill ~27 ~7 ~14 ~32 ~7 ~14 grass 0  
fill ~27 ~7 ~22 ~68 ~7 ~22 dirt 0  
fill ~27 ~7 ~54 ~60 ~7 ~54 dirt 0  
fill ~27 ~7 ~60 ~27 ~6 ~60 stone 0  
fill ~27 ~7 ~61 ~29 ~7 ~61 grass 0  
fill ~28 ~7 ~15 ~50 ~7 ~15 stone 0  
fill ~28 ~7 ~21 ~65 ~7 ~21 dirt 0  
fill ~28 ~7 ~55 ~54 ~7 ~55 dirt 0  
fill ~28 ~7 ~60 ~29 ~7 ~60 grass 0  
fill ~30 ~7 ~60 ~97 ~7 ~60 stone 0  
fill ~30 ~7 ~61 ~54 ~7 ~61 stone 0 
setblock ~30 ~7 ~62 grass 0  
fill ~31 ~7 ~62 ~53 ~7 ~62 stone 0  
fill ~31 ~7 ~63 ~32 ~7 ~63 grass 0  
fill ~32 ~7 ~56 ~50 ~7 ~56 dirt 0  
fill ~33 ~7 ~14 ~51 ~7 ~14 stone 0  
fill ~33 ~7 ~63 ~50 ~7 ~63 stone 0  
fill ~33 ~7 ~64 ~35 ~7 ~64 grass 0  
fill ~34 ~7 ~57 ~49 ~7 ~57 dirt 0  
fill ~35 ~7 ~65 ~37 ~7 ~65 grass 0  
fill ~36 ~7 ~20 ~64 ~7 ~20 dirt 0  
fill ~36 ~7 ~64 ~46 ~7 ~64 stone 0  
fill ~37 ~7 ~19 ~62 ~7 ~19 dirt 0  
fill ~37 ~7 ~66 ~46 ~7 ~66 grass 0  
fill ~38 ~7 ~58 ~45 ~7 ~58 dirt 0  
fill ~38 ~7 ~65 ~40 ~7 ~65 stone 0 
setblock ~40 ~7 ~12 grass 0  
fill ~40 ~7 ~13 ~51 ~7 ~13 stone 0  
fill ~41 ~7 ~12 ~57 ~7 ~12 stone 0  
fill ~41 ~7 ~65 ~49 ~7 ~65 grass 0 
setblock ~42 ~7 ~11 grass 0  
fill ~42 ~7 ~59 ~43 ~7 ~59 dirt 0  
fill ~43 ~7 ~10 ~45 ~7 ~10 grass 0  
fill ~43 ~7 ~11 ~44 ~7 ~11 stone 0  
fill ~44 ~7 ~18 ~59 ~7 ~18 dirt 0  
fill ~44 ~7 ~59 ~105 ~7 ~59 stone 0 
setblock ~45 ~7 ~11 grass 0  
fill ~46 ~7 ~11 ~50 ~7 ~11 stone 0  
fill ~46 ~7 ~17 ~55 ~7 ~17 dirt 0  
fill ~46 ~7 ~58 ~107 ~7 ~58 stone 0 
setblock ~48 ~7 ~10 grass 0  
fill ~48 ~7 ~64 ~54 ~7 ~64 grass 0 
setblock ~49 ~7 ~10 stone_stairs 6  
fill ~49 ~7 ~16 ~54 ~7 ~16 dirt 0  
fill ~50 ~7 ~8 ~54 ~7 ~8 grass 0  
fill ~50 ~7 ~9 ~55 ~7 ~9 grass 0  
fill ~50 ~7 ~10 ~50 ~7 ~8 grass 0  
fill ~50 ~7 ~57 ~108 ~7 ~57 stone 0 
setblock ~51 ~7 ~10 stone 0  
fill ~51 ~7 ~11 ~53 ~7 ~11 log 0  
fill ~51 ~7 ~15 ~53 ~7 ~15 dirt 0  
fill ~51 ~7 ~56 ~110 ~7 ~56 stone 0  
fill ~51 ~7 ~63 ~56 ~7 ~63 grass 0 
setblock ~52 ~7 ~10 grass 0  
fill ~52 ~7 ~13 ~53 ~7 ~13 dirt 0  
fill ~52 ~7 ~14 ~53 ~7 ~14 dirt 0 
setblock ~53 ~7 ~10 stone 0 
setblock ~54 ~7 ~10 grass 0  
fill ~54 ~7 ~11 ~57 ~7 ~11 stone 0  
fill ~54 ~7 ~13 ~62 ~7 ~13 stone 0  
fill ~54 ~7 ~14 ~63 ~7 ~14 stone 0  
fill ~54 ~7 ~15 ~63 ~7 ~15 stone 0  
fill ~54 ~7 ~62 ~64 ~7 ~62 grass 0  
fill ~55 ~7 ~10 ~59 ~7 ~10 log 0  
fill ~55 ~7 ~16 ~63 ~7 ~16 stone 0  
fill ~55 ~7 ~55 ~112 ~7 ~55 stone 0  
fill ~55 ~7 ~61 ~98 ~7 ~61 grass 0 
setblock ~56 ~7 ~9 stone_stairs 6  
fill ~56 ~7 ~17 ~63 ~7 ~17 stone 0 
setblock ~58 ~7 ~9 stone_stairs 6  
fill ~58 ~7 ~11 ~60 ~7 ~11 dirt 0  
fill ~58 ~7 ~12 ~61 ~7 ~12 dirt 0  
fill ~60 ~7 ~9 ~64 ~7 ~9 log 0  
fill ~60 ~7 ~10 ~60 ~9 ~10 dirt 0  
fill ~60 ~7 ~18 ~63 ~7 ~18 stone 0 
setblock ~61 ~7 ~8 stone_stairs 6  
fill ~61 ~7 ~10 ~61 ~9 ~10 stone 0  
fill ~61 ~7 ~11 ~61 ~9 ~11 stone 0  
fill ~61 ~7 ~54 ~75 ~7 ~54 stone 0  
fill ~62 ~7 ~12 ~62 ~9 ~12 stone 0 
setblock ~63 ~7 ~8 stone_stairs 6  
fill ~63 ~7 ~19 ~63 ~9 ~19 stone 0  
fill ~64 ~7 ~10 ~64 ~9 ~10 cobblestone 0  
fill ~64 ~7 ~11 ~64 ~9 ~11 cobblestone 0  
fill ~64 ~7 ~12 ~64 ~10 ~12 cobblestone 0  
fill ~64 ~7 ~13 ~64 ~10 ~13 cobblestone 0  
fill ~64 ~7 ~16 ~64 ~11 ~16 cobblestone 0  
fill ~64 ~7 ~17 ~64 ~10 ~17 cobblestone 0  
fill ~64 ~7 ~18 ~64 ~10 ~18 cobblestone 0  
fill ~64 ~7 ~19 ~64 ~10 ~19 cobblestone 0  
fill ~65 ~7 ~13 ~65 ~10 ~13 log 0  
fill ~65 ~7 ~17 ~65 ~10 ~17 log 0  
fill ~65 ~7 ~20 ~65 ~9 ~20 cobblestone 0 
setblock ~66 ~7 ~7 stone_stairs 6 
setblock ~66 ~7 ~8 log 0  
fill ~66 ~7 ~13 ~67 ~7 ~13 planks 0  
fill ~66 ~7 ~17 ~67 ~7 ~17 planks 0  
fill ~66 ~7 ~21 ~75 ~7 ~21 cobblestone 0 
setblock ~68 ~7 ~7 stone_stairs 6 
setblock ~68 ~7 ~8 log 0 
setblock ~68 ~7 ~13 fence_gate 2 
setblock ~68 ~7 ~17 fence_gate 4 
setblock ~69 ~7 ~13 planks 0 
setblock ~69 ~7 ~17 planks 0  
fill ~69 ~7 ~22 ~79 ~7 ~22 cobblestone 0  
fill ~69 ~7 ~23 ~90 ~7 ~23 cobblestone 0  
fill ~69 ~7 ~24 ~93 ~7 ~24 cobblestone 0  
fill ~69 ~7 ~25 ~90 ~7 ~25 cobblestone 0  
fill ~69 ~7 ~26 ~90 ~7 ~26 cobblestone 0  
fill ~70 ~7 ~8 ~70 ~8 ~8 planks 0  
fill ~70 ~7 ~9 ~70 ~8 ~9 planks 0  
fill ~70 ~7 ~10 ~70 ~8 ~10 planks 0  
fill ~70 ~7 ~11 ~70 ~8 ~11 planks 0  
fill ~70 ~7 ~12 ~70 ~9 ~12 planks 0  
fill ~70 ~7 ~13 ~70 ~10 ~13 log 0  
fill ~70 ~7 ~17 ~70 ~10 ~17 log 0  
fill ~70 ~7 ~18 ~70 ~9 ~18 planks 0  
fill ~70 ~7 ~19 ~70 ~8 ~19 planks 0  
fill ~70 ~7 ~20 ~70 ~8 ~20 planks 0  
fill ~70 ~7 ~27 ~90 ~7 ~27 cobblestone 0 
setblock ~71 ~7 ~6 stone_stairs 6 
setblock ~71 ~7 ~7 log 0  
fill ~71 ~7 ~8 ~71 ~9 ~8 fence 0  
