summon minecraft:pig ~32~2~22  
summon minecraft:item ~32~2~22  
summon minecraft:turtle ~27~6~33  
summon minecraft:tropicalfish ~27~9~35  
summon minecraft:tropicalfish ~29~7~34  
summon minecraft:tropicalfish ~28~4~36  
summon minecraft:turtle ~27~3~36  
summon minecraft:tropicalfish ~29~2~34  
summon minecraft:pig ~34~2~24  
summon minecraft:item ~43~2~24  
summon minecraft:item ~43~2~24  
summon minecraft:item ~45~4~22  
summon minecraft:item ~45~4~22  
summon minecraft:item ~36~2~23  
summon minecraft:item ~38~2~24  
summon minecraft:item ~38~2~24  
summon minecraft:item ~41~2~25  
summon minecraft:item ~41~2~25  
summon minecraft:item ~48~2~23  
summon minecraft:item ~48~2~23  
summon minecraft:hopper_minecart ~44~7~46  
summon minecraft:hopper_minecart ~42~7~50  
summon minecraft:armor_stand ~52~9~33  
summon minecraft:armor_stand ~52~9~37  
setblock ~0~0~0 minecraft:air
fill ~52~0~1 ~52~0~2 minecraft:grass
fill ~53~0~1 ~74~0~2 minecraft:dirt 0
fill ~53~1~1 ~54~1~2 minecraft:grass
fill ~55~1~1 ~66~1~3 minecraft:dirt 0
fill ~55~2~1 ~57~2~2 minecraft:grass
fill ~58~2~1 ~60~2~3 minecraft:dirt 0
fill ~58~3~1 ~60~3~2 minecraft:grass
fill ~61~2~1 ~66~2~1 minecraft:grass
fill ~67~1~1 ~74~1~1 minecraft:grass
setblock ~74~2~1 minecraft:double_plant 2
fill ~75~0~1 ~78~0~3 minecraft:grass
fill ~61~2~2 ~61~2~3 minecraft:dirt 0
setblock ~61~3~2 minecraft:grass
fill ~62~2~2 ~67~2~2 minecraft:grass
fill ~67~1~2 ~67~1~5 minecraft:dirt 0
fill ~68~1~2 ~74~1~2 minecraft:grass
setblock ~68~2~2 minecraft:tallgrass 1
fill ~50~0~3 ~51~0~4 minecraft:grass
fill ~52~0~3 ~58~0~3 minecraft:dirt 0
fill ~52~1~3 ~53~1~3 minecraft:grass
fill ~54~1~3 ~54~1~6 minecraft:dirt 0
fill ~54~2~3 ~55~2~4 minecraft:grass
fill ~56~2~3 ~57~2~5 minecraft:dirt 0
fill ~56~3~3 ~58~3~3 minecraft:grass
fill ~59~0~3 ~61~0~51 minecraft:stone 0
fill ~59~3~3 ~61~3~4 minecraft:dirt 0
fill ~59~4~3 ~61~4~3 minecraft:grass
fill ~62~0~3 ~74~0~3 minecraft:dirt 0
fill ~62~2~3 ~65~2~3 minecraft:dirt 0
fill ~62~3~3 ~65~3~3 minecraft:grass
setblock ~65~4~3 minecraft:tallgrass 1
fill ~66~2~3 ~69~2~3 minecraft:grass
fill ~68~1~3 ~69~1~5 minecraft:dirt 0
fill ~70~1~3 ~74~1~3 minecraft:grass
fill ~28~0~4 ~40~0~4 minecraft:grass
fill ~49~0~4 ~49~0~6 minecraft:grass
fill ~52~0~4 ~56~0~5 minecraft:dirt 0
fill ~52~1~4 ~52~1~5 minecraft:grass
fill ~53~1~4 ~53~1~7 minecraft:dirt 0
fill ~53~2~4 ~53~2~6 minecraft:grass
fill ~55~1~4 ~57~1~4 minecraft:dirt 0
fill ~56~3~4 ~56~3~5 minecraft:grass
fill ~57~0~4 ~58~0~55 minecraft:stone 0
fill ~57~3~4 ~58~3~5 minecraft:dirt 0
setblock ~57~4~4 minecraft:grass
fill ~58~1~4 ~64~1~36 minecraft:stone 0
setblock ~58~2~4 minecraft:dirt 0
fill ~58~4~4 ~64~4~5 minecraft:dirt 0
setblock ~58~5~4 minecraft:grass
fill ~59~2~4 ~63~2~36 minecraft:stone 0
fill ~59~5~4 ~63~5~6 minecraft:dirt 0
fill ~59~6~4 ~63~6~4 minecraft:grass
fill ~62~0~4 ~66~0~35 minecraft:stone 0
fill ~62~3~4 ~66~3~4 minecraft:dirt 0
fill ~64~2~4 ~67~2~4 minecraft:dirt 0
setblock ~64~5~4 minecraft:grass
fill ~65~1~4 ~66~1~4 minecraft:dirt 0
fill ~65~4~4 ~66~4~4 minecraft:grass
fill ~67~0~4 ~74~0~4 minecraft:dirt 0
setblock ~67~3~4 minecraft:grass
fill ~68~2~4 ~70~2~4 minecraft:grass
fill ~70~1~4 ~70~1~7 minecraft:dirt 0
fill ~71~1~4 ~74~1~6 minecraft:grass
setblock ~72~2~4 minecraft:tallgrass 1
fill ~75~0~4 ~77~0~7 minecraft:grass
fill ~23~0~5 ~29~0~5 minecraft:grass
fill ~30~0~5 ~39~0~6 minecraft:dirt 0
fill ~30~1~5 ~39~1~5 minecraft:grass
fill ~36~2~5 ~36~2~6 minecraft:tallgrass 1
fill ~40~0~5 ~42~0~5 minecraft:grass
fill ~48~0~5 ~48~0~6 minecraft:grass
fill ~50~0~5 ~51~0~7 minecraft:dirt 0
fill ~50~1~5 ~51~1~6 minecraft:grass
setblock ~54~2~5 minecraft:grass
fill ~55~1~5 ~56~1~6 minecraft:dirt 0
fill ~55~2~5 ~55~2~6 minecraft:dirt 0
fill ~55~3~5 ~55~3~6 minecraft:grass
fill ~57~1~5 ~57~1~19 minecraft:stone 0
fill ~57~4~5 ~57~4~7 minecraft:dirt 0
setblock ~57~5~5 minecraft:grass
fill ~58~2~5 ~58~2~52 minecraft:stone 0
fill ~58~5~5 ~58~5~7 minecraft:dirt 0
setblock ~58~6~5 minecraft:grass
fill ~59~3~5 ~64~3~36 minecraft:stone 0
fill ~59~6~5 ~64~6~9 minecraft:dirt 0
fill ~59~7~5 ~64~7~5 minecraft:grass
fill ~64~2~5 ~65~2~42 minecraft:stone 0
fill ~64~5~5 ~65~5~7 minecraft:dirt 0
fill ~65~1~5 ~66~1~41 minecraft:stone 0
fill ~65~3~5 ~67~3~5 minecraft:dirt 0
fill ~65~4~5 ~66~4~6 minecraft:dirt 0
setblock ~65~6~5 minecraft:grass
fill ~66~2~5 ~68~2~5 minecraft:dirt 0
setblock ~66~5~5 minecraft:grass
fill ~67~0~5 ~67~0~36 minecraft:stone 0
setblock ~67~4~5 minecraft:grass
fill ~68~0~5 ~74~0~5 minecraft:dirt 0
setblock ~68~3~5 minecraft:grass
fill ~69~2~5 ~70~2~5 minecraft:grass
setblock ~69~3~5 minecraft:tallgrass 1
fill ~22~0~6 ~26~0~6 minecraft:grass
fill ~27~0~6 ~29~0~8 minecraft:dirt 0
fill ~27~1~6 ~34~1~6 minecraft:grass
setblock ~35~1~6 minecraft:dirt 0
setblock ~35~2~6 minecraft:grass
fill ~36~1~6 ~41~1~6 minecraft:grass
fill ~40~0~6 ~41~0~6 minecraft:dirt 0
fill ~42~0~6 ~46~0~6 minecraft:grass
fill ~52~0~6 ~55~0~6 minecraft:dirt 0
fill ~52~1~6 ~52~1~7 minecraft:dirt 0
setblock ~52~2~6 minecraft:grass
fill ~54~2~6 ~54~2~7 minecraft:dirt 0
setblock ~54~3~6 minecraft:grass
fill ~56~0~6 ~56~0~57 minecraft:stone 0
fill ~56~2~6 ~56~3~6 minecraft:dirt 0
setblock ~56~4~6 minecraft:grass
fill ~57~2~6 ~57~2~19 minecraft:stone 0
setblock ~57~3~6 minecraft:dirt 0
fill ~57~5~6 ~57~5~8 minecraft:dirt 0
setblock ~57~6~6 minecraft:grass
fill ~58~3~6 ~58~3~16 minecraft:stone 0
setblock ~58~4~6 minecraft:dirt 0
fill ~58~6~6 ~58~6~9 minecraft:dirt 0
setblock ~58~7~6 minecraft:grass
fill ~59~4~6 ~64~4~15 minecraft:stone 0
fill ~59~7~6 ~64~7~11 minecraft:dirt 0
fill ~59~8~6 ~64~8~6 minecraft:grass
fill ~65~3~6 ~66~3~40 minecraft:stone 0
fill ~65~6~6 ~66~6~12 minecraft:dirt 0
fill ~65~7~6 ~66~7~6 minecraft:grass
fill ~66~2~6 ~67~2~40 minecraft:stone 0
fill ~66~5~6 ~67~5~9 minecraft:dirt 0
fill ~67~1~6 ~68~1~40 minecraft:stone 0
fill ~67~3~6 ~68~4~6 minecraft:dirt 0
setblock ~67~6~6 minecraft:grass
fill ~68~0~6 ~68~0~40 minecraft:stone 0
fill ~68~2~6 ~69~2~6 minecraft:dirt 0
setblock ~68~5~6 minecraft:grass
fill ~69~0~6 ~74~0~6 minecraft:dirt 0
setblock ~69~1~6 minecraft:dirt 0
setblock ~69~3~6 minecraft:grass
setblock ~70~2~6 minecraft:grass
setblock ~71~2~6 minecraft:double_plant 2
fill ~21~0~7 ~22~0~7 minecraft:grass
fill ~23~0~7 ~26~0~12 minecraft:dirt 0
fill ~23~1~7 ~28~1~7 minecraft:grass
fill ~29~1~7 ~34~1~7 minecraft:dirt 0
fill ~29~2~7 ~32~2~7 minecraft:grass
fill ~30~0~7 ~32~0~7 minecraft:dirt 0
fill ~33~0~7 ~40~0~10 minecraft:stone 0
fill ~33~2~7 ~40~2~7 minecraft:dirt 0
fill ~33~3~7 ~34~3~7 minecraft:grass
fill ~35~1~7 ~39~1~10 minecraft:stone 0
fill ~35~3~7 ~39~3~7 minecraft:dirt 0
fill ~35~4~7 ~39~4~7 minecraft:grass
fill ~40~1~7 ~42~1~7 minecraft:dirt 0
setblock ~40~3~7 minecraft:grass
fill ~41~0~7 ~45~0~7 minecraft:dirt 0
fill ~41~2~7 ~42~2~7 minecraft:grass
fill ~43~1~7 ~45~1~7 minecraft:grass
fill ~46~0~7 ~47~0~7 minecraft:grass
fill ~48~0~7 ~49~0~7 minecraft:dirt 0
setblock ~48~1~7 minecraft:grass
fill ~49~1~7 ~51~1~7 minecraft:dirt 0
fill ~49~2~7 ~50~2~7 minecraft:grass
fill ~51~2~7 ~53~2~7 minecraft:dirt 0
fill ~51~3~7 ~52~3~7 minecraft:grass
setblock ~52~0~7 minecraft:dirt 0
fill ~53~0~7 ~55~0~18 minecraft:stone 0
fill ~53~3~7 ~56~3~7 minecraft:dirt 0
setblock ~53~4~7 minecraft:grass
fill ~54~1~7 ~56~1~14 minecraft:stone 0
fill ~54~4~7 ~56~4~7 minecraft:dirt 0
setblock ~54~5~7 minecraft:grass
fill ~55~2~7 ~56~2~12 minecraft:stone 0
fill ~55~5~7 ~56~5~8 minecraft:dirt 0
fill ~55~6~7 ~56~6~7 minecraft:grass
fill ~57~3~7 ~57~3~16 minecraft:stone 0
fill ~57~6~7 ~57~6~9 minecraft:dirt 0
setblock ~57~7~7 minecraft:grass
fill ~58~4~7 ~58~4~16 minecraft:stone 0
fill ~58~7~7 ~58~7~11 minecraft:dirt 0
fill ~58~8~7 ~61~8~7 minecraft:grass
fill ~59~5~7 ~61~5~7 minecraft:dirt 0
fill ~62~5~7 ~63~5~41 minecraft:stone 0
fill ~62~8~7 ~63~8~12 minecraft:dirt 0
fill ~62~9~7 ~63~9~9 minecraft:grass
fill ~64~8~7 ~65~8~7 minecraft:grass
fill ~65~4~7 ~65~4~41 minecraft:stone 0
fill ~65~7~7 ~65~7~13 minecraft:dirt 0
fill ~66~4~7 ~69~4~7 minecraft:dirt 0
fill ~66~7~7 ~67~7~7 minecraft:grass
setblock ~66~8~7 minecraft:tallgrass 1
fill ~67~3~7 ~67~3~39 minecraft:stone 0
fill ~67~6~7 ~67~6~13 minecraft:dirt 0
fill ~68~2~7 ~68~2~40 minecraft:stone 0
fill ~68~3~7 ~70~3~7 minecraft:dirt 0
fill ~68~5~7 ~68~5~12 minecraft:dirt 0
setblock ~68~6~7 minecraft:grass
setblock ~68~7~7 minecraft:tallgrass 1
fill ~69~0~7 ~69~1~39 minecraft:stone 0
fill ~69~2~7 ~70~2~7 minecraft:dirt 0
setblock ~69~5~7 minecraft:grass
fill ~70~0~7 ~74~0~7 minecraft:dirt 0
setblock ~70~4~7 minecraft:grass
setblock ~70~5~7 minecraft:tallgrass 1
fill ~71~1~7 ~72~1~8 minecraft:dirt 0
fill ~71~2~7 ~72~2~7 minecraft:grass
fill ~73~1~7 ~74~1~7 minecraft:grass
fill ~78~0~7 ~78~0~13 minecraft:grass
setblock ~78~1~7 minecraft:double_plant 2
fill ~20~0~8 ~21~0~8 minecraft:grass
fill ~22~0~8 ~22~0~14 minecraft:dirt 0
fill ~22~1~8 ~25~1~8 minecraft:grass
fill ~26~1~8 ~30~1~8 minecraft:dirt 0
fill ~26~2~8 ~29~2~8 minecraft:grass
setblock ~30~0~8 minecraft:dirt 0
fill ~30~2~8 ~31~2~8 minecraft:dirt 0
setblock ~30~3~8 minecraft:grass
fill ~31~0~8 ~32~1~16 minecraft:stone 0
fill ~31~3~8 ~32~3~8 minecraft:dirt 0
setblock ~31~4~8 minecraft:grass
fill ~32~2~8 ~41~2~11 minecraft:stone 0
fill ~32~4~8 ~33~4~8 minecraft:dirt 0
setblock ~32~5~8 minecraft:grass
fill ~33~1~8 ~34~1~15 minecraft:stone 0
fill ~33~3~8 ~39~3~15 minecraft:stone 0
fill ~33~5~8 ~41~5~8 minecraft:dirt 0
setblock ~33~6~8 minecraft:grass
fill ~34~4~8 ~39~4~16 minecraft:stone 0
fill ~34~6~8 ~39~6~8 minecraft:dirt 0
fill ~34~7~8 ~39~7~8 minecraft:grass
setblock ~34~8~8 minecraft:double_plant 2
setblock ~35~8~8 minecraft:tallgrass 1
fill ~40~1~8 ~42~1~21 minecraft:stone 0
fill ~40~3~8 ~43~3~8 minecraft:dirt 0
fill ~40~4~8 ~42~4~8 minecraft:dirt 0
fill ~40~6~8 ~41~6~8 minecraft:grass
fill ~41~0~8 ~43~0~19 minecraft:stone 0
fill ~42~2~8 ~45~2~8 minecraft:dirt 0
setblock ~42~5~8 minecraft:grass
fill ~43~1~8 ~46~1~8 minecraft:dirt 0
setblock ~43~4~8 minecraft:grass
fill ~44~0~8 ~48~0~8 minecraft:dirt 0
fill ~44~3~8 ~45~3~8 minecraft:grass
setblock ~46~2~8 minecraft:grass
setblock ~47~1~8 minecraft:grass
fill ~48~1~8 ~49~1~8 minecraft:dirt 0
setblock ~48~2~8 minecraft:grass
fill ~49~0~8 ~52~0~17 minecraft:stone 0
fill ~49~2~8 ~50~3~8 minecraft:dirt 0
setblock ~49~4~8 minecraft:grass
fill ~50~1~8 ~53~1~15 minecraft:stone 0
fill ~50~4~8 ~54~4~8 minecraft:dirt 0
setblock ~50~5~8 minecraft:grass
fill ~51~2~8 ~54~2~13 minecraft:stone 0
fill ~51~3~8 ~52~3~8 minecraft:dirt 0
fill ~51~5~8 ~54~5~8 minecraft:dirt 0
fill ~51~6~8 ~52~6~8 minecraft:grass
fill ~53~3~8 ~56~3~12 minecraft:stone 0
fill ~53~6~8 ~56~6~9 minecraft:dirt 0
fill ~53~7~8 ~54~7~8 minecraft:grass
fill ~55~4~8 ~57~4~15 minecraft:stone 0
fill ~55~7~8 ~57~7~10 minecraft:dirt 0
fill ~55~8~8 ~57~8~8 minecraft:grass
fill ~58~5~8 ~61~5~45 minecraft:stone 0
fill ~58~8~8 ~61~8~11 minecraft:dirt 0
fill ~58~9~8 ~61~9~9 minecraft:grass
setblock ~58~10~8 minecraft:double_plant 2
fill ~64~5~8 ~64~5~15 minecraft:stone 0
fill ~64~8~8 ~64~8~13 minecraft:dirt 0
fill ~64~9~8 ~64~9~11 minecraft:grass
setblock ~65~5~8 minecraft:dirt 0
fill ~65~8~8 ~66~8~8 minecraft:grass
fill ~66~4~8 ~66~4~40 minecraft:stone 0
fill ~66~7~8 ~66~7~14 minecraft:dirt 0
fill ~67~4~8 ~70~4~8 minecraft:dirt 0
fill ~67~7~8 ~68~7~8 minecraft:grass
fill ~68~3~8 ~68~3~39 minecraft:stone 0
fill ~68~6~8 ~68~6~14 minecraft:dirt 0
fill ~69~2~8 ~69~2~22 minecraft:stone 0
fill ~69~3~8 ~71~3~8 minecraft:dirt 0
fill ~69~5~8 ~69~5~12 minecraft:dirt 0
setblock ~69~6~8 minecraft:grass
fill ~70~0~8 ~70~1~38 minecraft:stone 0
fill ~70~2~8 ~72~2~8 minecraft:dirt 0
setblock ~70~5~8 minecraft:grass
fill ~71~0~8 ~75~0~8 minecraft:dirt 0
setblock ~71~4~8 minecraft:grass
setblock ~72~3~8 minecraft:grass
fill ~73~1~8 ~73~1~9 minecraft:dirt 0
setblock ~73~2~8 minecraft:grass
fill ~74~1~8 ~75~1~8 minecraft:grass
fill ~76~0~8 ~77~0~8 minecraft:grass
fill ~17~0~9 ~20~0~9 minecraft:grass
fill ~21~0~9 ~21~0~15 minecraft:dirt 0
fill ~21~1~9 ~22~1~9 minecraft:grass
fill ~23~1~9 ~29~1~9 minecraft:dirt 0
fill ~23~2~9 ~27~2~9 minecraft:grass
fill ~27~0~9 ~28~0~9 minecraft:dirt 0
fill ~28~2~9 ~30~2~9 minecraft:dirt 0
setblock ~28~3~9 minecraft:grass
fill ~29~0~9 ~30~0~17 minecraft:stone 0
fill ~29~3~9 ~31~3~9 minecraft:dirt 0
setblock ~29~4~9 minecraft:grass
fill ~30~1~9 ~30~1~17 minecraft:stone 0
fill ~30~4~9 ~31~4~9 minecraft:dirt 0
setblock ~30~5~9 minecraft:grass
fill ~31~2~9 ~31~2~17 minecraft:stone 0
fill ~31~5~9 ~32~5~9 minecraft:dirt 0
setblock ~31~6~9 minecraft:grass
fill ~32~3~9 ~32~4~16 minecraft:stone 0
fill ~32~6~9 ~33~6~9 minecraft:dirt 0
setblock ~32~7~9 minecraft:grass
setblock ~32~8~9 minecraft:double_plant 2
fill ~33~4~9 ~33~5~16 minecraft:stone 0
fill ~33~7~9 ~41~7~9 minecraft:dirt 0
setblock ~33~8~9 minecraft:grass
fill ~34~5~9 ~39~5~18 minecraft:stone 0
fill ~34~6~9 ~38~6~25 minecraft:stone 0
fill ~34~8~9 ~39~8~10 minecraft:dirt 0
fill ~34~9~9 ~39~9~9 minecraft:grass
setblock ~35~10~9 minecraft:double_plant 2
fill ~39~6~9 ~42~6~9 minecraft:dirt 0
setblock ~39~10~9 minecraft:double_plant 2
fill ~40~3~9 ~42~3~20 minecraft:stone 0
fill ~40~4~9 ~41~4~20 minecraft:stone 0
fill ~40~5~9 ~44~5~9 minecraft:dirt 0
fill ~40~8~9 ~41~8~9 minecraft:grass
fill ~42~2~9 ~44~2~20 minecraft:stone 0
fill ~42~4~9 ~45~4~9 minecraft:dirt 0
setblock ~42~7~9 minecraft:grass
fill ~43~1~9 ~45~1~18 minecraft:stone 0
fill ~43~3~9 ~46~3~9 minecraft:dirt 0
fill ~43~6~9 ~44~6~9 minecraft:grass
fill ~44~0~9 ~46~0~17 minecraft:stone 0
fill ~45~2~9 ~48~2~9 minecraft:dirt 0
setblock ~45~5~9 minecraft:grass
fill ~46~1~9 ~47~1~9 minecraft:dirt 0
setblock ~46~4~9 minecraft:grass
setblock ~47~0~9 minecraft:dirt 0
setblock ~47~3~9 minecraft:grass
fill ~48~0~9 ~48~1~17 minecraft:stone 0
fill ~48~3~9 ~49~4~9 minecraft:dirt 0
setblock ~48~5~9 minecraft:grass
fill ~49~1~9 ~49~1~69 minecraft:stone 0
fill ~49~2~9 ~50~2~25 minecraft:stone 0
fill ~49~5~9 ~53~5~9 minecraft:dirt 0
setblock ~49~6~9 minecraft:grass
fill ~50~3~9 ~52~3~15 minecraft:stone 0
setblock ~50~4~9 minecraft:dirt 0
fill ~50~6~9 ~52~6~10 minecraft:dirt 0
setblock ~50~7~9 minecraft:grass
fill ~51~4~9 ~54~4~14 minecraft:stone 0
fill ~51~7~9 ~54~7~11 minecraft:dirt 0
fill ~51~8~9 ~53~8~9 minecraft:grass
fill ~54~5~9 ~57~5~45 minecraft:stone 0
fill ~54~8~9 ~57~8~11 minecraft:dirt 0
fill ~54~9~9 ~57~9~9 minecraft:grass
setblock ~63~10~9 minecraft:tallgrass 1
fill ~65~5~9 ~65~5~14 minecraft:stone 0
fill ~65~8~9 ~65~8~14 minecraft:dirt 0
fill ~65~9~9 ~65~9~13 minecraft:grass
fill ~66~8~9 ~68~8~9 minecraft:grass
fill ~67~4~9 ~68~4~39 minecraft:stone 0
fill ~67~7~9 ~68~7~15 minecraft:dirt 0
fill ~69~3~9 ~70~3~20 minecraft:stone 0
fill ~69~4~9 ~72~4~9 minecraft:dirt 0
fill ~69~6~9 ~70~6~16 minecraft:dirt 0
fill ~69~7~9 ~70~7~9 minecraft:grass
setblock ~69~8~9 minecraft:tallgrass 1
fill ~70~2~9 ~71~2~22 minecraft:stone 0
fill ~70~5~9 ~71~5~12 minecraft:dirt 0
fill ~71~0~9 ~72~1~39 minecraft:stone 0
fill ~71~3~9 ~72~3~9 minecraft:dirt 0
setblock ~71~6~9 minecraft:grass
fill ~72~2~9 ~73~2~9 minecraft:dirt 0
setblock ~72~5~9 minecraft:grass
fill ~73~0~9 ~76~0~9 minecraft:dirt 0
setblock ~73~3~9 minecraft:grass
fill ~74~1~9 ~74~1~12 minecraft:dirt 0
fill ~74~2~9 ~74~2~10 minecraft:grass
fill ~75~1~9 ~76~1~10 minecraft:grass
fill ~77~0~9 ~77~0~10 minecraft:grass
setblock ~78~1~9 minecraft:double_plant 2
fill ~15~0~10 ~18~0~10 minecraft:grass
fill ~19~0~10 ~20~0~12 minecraft:dirt 0
fill ~19~1~10 ~21~1~10 minecraft:grass
fill ~22~1~10 ~28~1~10 minecraft:dirt 0
fill ~22~2~10 ~26~2~10 minecraft:grass
setblock ~27~0~10 minecraft:dirt 0
fill ~27~2~10 ~28~2~11 minecraft:dirt 0
fill ~27~3~10 ~27~3~14 minecraft:grass
fill ~28~0~10 ~28~0~19 minecraft:stone 0
fill ~28~3~10 ~29~3~10 minecraft:dirt 0
fill ~28~4~10 ~28~4~11 minecraft:grass
fill ~29~1~10 ~29~2~18 minecraft:stone 0
fill ~29~4~10 ~29~4~11 minecraft:dirt 0
setblock ~29~5~10 minecraft:grass
fill ~30~2~10 ~30~4~17 minecraft:stone 0
fill ~30~5~10 ~30~6~11 minecraft:dirt 0
fill ~30~7~10 ~30~7~11 minecraft:grass
fill ~31~3~10 ~31~5~17 minecraft:stone 0
fill ~31~6~10 ~31~7~11 minecraft:dirt 0
fill ~31~8~10 ~31~8~11 minecraft:grass
fill ~32~5~10 ~32~6~18 minecraft:stone 0
fill ~32~7~10 ~33~8~10 minecraft:dirt 0
fill ~32~9~10 ~33~9~10 minecraft:grass
fill ~33~6~10 ~33~6~25 minecraft:stone 0
fill ~34~7~10 ~37~7~23 minecraft:stone 0
fill ~34~9~10 ~40~9~11 minecraft:dirt 0
fill ~34~10~10 ~40~10~10 minecraft:grass
fill ~38~7~10 ~43~7~10 minecraft:dirt 0
fill ~39~6~10 ~40~6~25 minecraft:stone 0
fill ~40~5~10 ~42~5~13 minecraft:stone 0
fill ~40~8~10 ~42~8~11 minecraft:dirt 0
fill ~41~6~10 ~45~6~10 minecraft:dirt 0
fill ~41~9~10 ~42~9~10 minecraft:grass
fill ~42~4~10 ~43~4~13 minecraft:stone 0
setblock ~42~10~10 minecraft:double_plant 2
fill ~43~3~10 ~45~3~20 minecraft:stone 0
fill ~43~5~10 ~46~5~10 minecraft:dirt 0
setblock ~43~8~10 minecraft:grass
fill ~44~4~10 ~48~4~10 minecraft:dirt 0
fill ~44~7~10 ~45~7~10 minecraft:grass
fill ~45~2~10 ~46~2~20 minecraft:stone 0
fill ~46~1~10 ~47~1~18 minecraft:stone 0
fill ~46~3~10 ~47~3~10 minecraft:dirt 0
setblock ~46~6~10 minecraft:grass
fill ~47~0~10 ~47~0~17 minecraft:stone 0
setblock ~47~2~10 minecraft:dirt 0
setblock ~47~5~10 minecraft:grass
fill ~48~2~10 ~48~3~20 minecraft:stone 0
fill ~48~5~10 ~50~5~10 minecraft:dirt 0
fill ~48~6~10 ~49~6~11 minecraft:dirt 0
setblock ~48~7~10 minecraft:grass
fill ~49~3~10 ~49~4~25 minecraft:stone 0
fill ~49~7~10 ~50~7~11 minecraft:dirt 0
fill ~49~8~10 ~50~8~10 minecraft:grass
setblock ~49~9~10 minecraft:double_plant 2
fill ~50~4~10 ~50~4~26 minecraft:stone 0
fill ~51~5~10 ~51~5~24 minecraft:stone 0
fill ~51~8~10 ~53~8~11 minecraft:dirt 0
fill ~51~9~10 ~54~9~10 minecraft:grass
setblock ~52~5~10 minecraft:dirt 0
fill ~53~5~10 ~53~5~24 minecraft:stone 0
fill ~53~6~10 ~54~6~10 minecraft:dirt 0
fill ~55~6~10 ~62~6~27 minecraft:stone 0
fill ~55~9~10 ~62~9~11 minecraft:dirt 0
fill ~55~10~10 ~62~10~10 minecraft:grass
fill ~63~6~10 ~64~6~10 minecraft:dirt 0
setblock ~63~9~10 minecraft:grass
fill ~66~5~10 ~67~5~38 minecraft:stone 0
fill ~66~8~10 ~67~8~16 minecraft:dirt 0
fill ~66~9~10 ~67~9~14 minecraft:grass
fill ~68~8~10 ~70~8~14 minecraft:grass
fill ~69~4~10 ~70~4~20 minecraft:stone 0
fill ~69~7~10 ~70~7~19 minecraft:dirt 0
setblock ~70~9~10 minecraft:tallgrass 1
fill ~71~3~10 ~71~3~30 minecraft:stone 0
fill ~71~4~10 ~73~4~11 minecraft:dirt 0
fill ~71~6~10 ~71~6~18 minecraft:dirt 0
fill ~71~7~10 ~71~7~16 minecraft:grass
fill ~72~2~10 ~72~2~38 minecraft:stone 0
fill ~72~3~10 ~73~3~11 minecraft:dirt 0
fill ~72~5~10 ~72~5~17 minecraft:dirt 0
fill ~72~6~10 ~72~6~12 minecraft:grass
fill ~73~0~10 ~73~1~37 minecraft:stone 0
fill ~73~2~10 ~73~2~12 minecraft:dirt 0
fill ~73~5~10 ~73~5~12 minecraft:grass
fill ~74~0~10 ~76~0~11 minecraft:dirt 0
fill ~79~0~10 ~79~0~14 minecraft:grass
fill ~14~0~11 ~16~0~11 minecraft:grass
fill ~17~0~11 ~18~0~13 minecraft:dirt 0
fill ~17~1~11 ~20~1~11 minecraft:grass
fill ~21~1~11 ~27~1~14 minecraft:dirt 0
fill ~21~2~11 ~25~2~12 minecraft:grass
fill ~26~2~11 ~26~2~14 minecraft:dirt 0
fill ~26~3~11 ~26~3~14 minecraft:grass
fill ~27~0~11 ~27~0~37 minecraft:stone 0
fill ~28~1~11 ~28~1~19 minecraft:stone 0
fill ~28~3~11 ~28~3~13 minecraft:dirt 0
fill ~29~3~11 ~29~3~18 minecraft:stone 0
fill ~29~5~11 ~29~5~13 minecraft:dirt 0
setblock ~29~6~11 minecraft:grass
fill ~32~7~11 ~32~8~11 minecraft:dirt 0
setblock ~32~9~11 minecraft:grass
fill ~33~0~11 ~35~0~15 minecraft:stone 0
fill ~33~7~11 ~33~7~22 minecraft:stone 0
fill ~33~8~11 ~33~9~11 minecraft:dirt 0
setblock ~33~10~11 minecraft:grass
fill ~34~8~11 ~36~8~22 minecraft:stone 0
fill ~34~10~11 ~40~10~11 minecraft:dirt 0
fill ~34~11~11 ~40~11~11 minecraft:grass
fill ~35~1~11 ~35~1~15 minecraft:stone 0
fill ~36~0~11 ~37~1~12 minecraft:copper_ore
setblock ~36~12~11 minecraft:double_plant 2
fill ~37~8~11 ~39~8~11 minecraft:dirt 0
fill ~38~0~11 ~40~0~30 minecraft:stone 0
fill ~38~1~11 ~39~1~17 minecraft:stone 0
fill ~38~7~11 ~40~7~19 minecraft:stone 0
setblock ~40~12~11 minecraft:double_plant 2
fill ~41~6~11 ~42~6~13 minecraft:stone 0
fill ~41~7~11 ~46~7~11 minecraft:dirt 0
fill ~41~9~11 ~42~9~11 minecraft:dirt 0
fill ~41~10~11 ~42~10~11 minecraft:grass
setblock ~42~11~11 minecraft:double_plant 2
fill ~43~5~11 ~44~5~12 minecraft:stone 0
fill ~43~6~11 ~47~6~11 minecraft:dirt 0
fill ~43~8~11 ~44~8~11 minecraft:dirt 0
fill ~43~9~11 ~44~9~11 minecraft:grass
fill ~44~4~11 ~45~4~13 minecraft:stone 0
fill ~45~5~11 ~48~5~11 minecraft:dirt 0
fill ~45~8~11 ~46~8~11 minecraft:grass
fill ~46~3~11 ~47~3~20 minecraft:stone 0
fill ~46~4~11 ~48~4~11 minecraft:dirt 0
fill ~47~2~11 ~47~2~21 minecraft:stone 0
setblock ~47~7~11 minecraft:grass
setblock ~48~7~11 minecraft:dirt 0
setblock ~48~8~11 minecraft:grass
fill ~49~5~11 ~50~5~25 minecraft:stone 0
fill ~49~8~11 ~50~9~11 minecraft:dirt 0
fill ~49~10~11 ~50~10~11 minecraft:grass
fill ~50~6~11 ~54~6~38 minecraft:stone 0
fill ~51~9~11 ~54~10~11 minecraft:dirt 0
fill ~51~11~11 ~56~11~11 minecraft:grass
fill ~52~5~11 ~52~5~24 minecraft:stone 0
fill ~55~7~11 ~56~7~27 minecraft:stone 0
fill ~55~10~11 ~56~10~12 minecraft:dirt 0
setblock ~57~7~11 minecraft:dirt 0
fill ~57~10~11 ~63~10~11 minecraft:grass
fill ~63~6~11 ~63~6~40 minecraft:stone 0
fill ~63~9~11 ~63~9~14 minecraft:dirt 0
setblock ~64~6~11 minecraft:dirt 0
setblock ~69~9~11 minecraft:tallgrass 1
fill ~74~2~11 ~74~2~13 minecraft:dirt 0
setblock ~74~3~11 minecraft:grass
fill ~75~1~11 ~75~1~12 minecraft:dirt 0
fill ~75~2~11 ~75~2~12 minecraft:grass
fill ~76~1~11 ~77~1~12 minecraft:grass
setblock ~76~2~11 minecraft:double_plant 2
fill ~77~0~11 ~77~0~14 minecraft:dirt 0
fill ~13~0~12 ~15~0~12 minecraft:grass
fill ~16~0~12 ~16~0~14 minecraft:dirt 0
fill ~16~1~12 ~19~1~12 minecraft:grass
fill ~20~1~12 ~20~1~18 minecraft:dirt 0
fill ~20~2~12 ~20~2~16 minecraft:grass
fill ~27~2~12 ~27~2~14 minecraft:dirt 0
fill ~28~2~12 ~28~2~19 minecraft:stone 0
fill ~28~4~12 ~28~4~14 minecraft:dirt 0
fill ~28~5~12 ~28~5~13 minecraft:grass
fill ~29~4~12 ~29~4~19 minecraft:stone 0
fill ~29~6~12 ~30~6~12 minecraft:dirt 0
fill ~29~7~12 ~29~7~13 minecraft:grass
fill ~30~5~12 ~30~5~19 minecraft:stone 0
fill ~30~7~12 ~31~7~12 minecraft:dirt 0
setblock ~30~8~12 minecraft:grass
fill ~31~6~12 ~31~6~25 minecraft:stone 0
fill ~31~8~12 ~32~8~12 minecraft:dirt 0
setblock ~31~9~12 minecraft:grass
setblock ~31~10~12 minecraft:double_plant 2
fill ~32~2~12 ~36~2~15 minecraft:stone 0
fill ~32~7~12 ~32~7~23 minecraft:stone 0
fill ~32~9~12 ~33~9~12 minecraft:dirt 0
setblock ~32~10~12 minecraft:grass
fill ~33~8~12 ~33~8~23 minecraft:stone 0
setblock ~33~10~12 minecraft:dirt 0
setblock ~33~11~12 minecraft:grass
fill ~34~9~12 ~41~9~23 minecraft:stone 0
fill ~34~10~12 ~37~10~19 minecraft:stone 0
fill ~34~11~12 ~59~11~12 minecraft:dirt 0
fill ~34~12~12 ~41~12~12 minecraft:dirt 0
setblock ~34~13~12 minecraft:grass
fill ~35~13~12 ~37~13~13 minecraft:dirt 0
fill ~35~14~12 ~37~14~12 minecraft:grass
setblock ~37~2~12 minecraft:copper_ore
fill ~37~8~12 ~43~8~19 minecraft:stone 0
setblock ~37~15~12 minecraft:double_plant 2
fill ~38~2~12 ~41~2~17 minecraft:stone 0
fill ~38~10~12 ~54~10~12 minecraft:dirt 0
fill ~38~13~12 ~41~13~12 minecraft:grass
fill ~41~7~12 ~54~7~13 minecraft:stone 0
setblock ~41~14~12 minecraft:red_flower 8
fill ~42~9~12 ~49~9~12 minecraft:dirt 0
fill ~42~12~12 ~47~12~12 minecraft:grass
fill ~43~6~12 ~49~6~12 minecraft:stone 0
fill ~44~8~12 ~47~8~12 minecraft:dirt 0
fill ~45~5~12 ~48~5~14 minecraft:stone 0
fill ~46~4~12 ~48~4~20 minecraft:stone 0
fill ~48~8~12 ~59~8~17 minecraft:stone 0
fill ~48~12~12 ~56~12~13 minecraft:dirt 0
fill ~48~13~12 ~49~13~12 minecraft:grass
fill ~50~9~12 ~56~9~17 minecraft:stone 0
fill ~50~13~12 ~53~13~13 minecraft:dirt 0
fill ~50~14~12 ~53~14~12 minecraft:grass
fill ~54~13~12 ~56~13~12 minecraft:grass
fill ~57~7~12 ~61~7~27 minecraft:stone 0
fill ~57~9~12 ~62~9~12 minecraft:dirt 0
fill ~57~10~12 ~61~10~12 minecraft:dirt 0
fill ~57~12~12 ~59~12~12 minecraft:grass
fill ~60~8~12 ~61~8~12 minecraft:dirt 0
fill ~60~11~12 ~61~11~12 minecraft:grass
fill ~62~7~12 ~64~7~12 minecraft:dirt 0
fill ~62~10~12 ~64~10~12 minecraft:grass
fill ~64~6~12 ~64~6~14 minecraft:stone 0
fill ~64~9~12 ~64~9~14 minecraft:dirt 0
setblock ~65~10~12 minecraft:double_plant 2
fill ~71~4~12 ~71~4~30 minecraft:stone 0
fill ~72~3~12 ~72~3~29 minecraft:stone 0
fill ~72~4~12 ~73~4~13 minecraft:dirt 0
fill ~73~3~12 ~74~3~12 minecraft:dirt 0
fill ~74~0~12 ~74~0~37 minecraft:stone 0
setblock ~74~4~12 minecraft:grass
fill ~75~0~12 ~76~0~12 minecraft:dirt 0
fill ~12~0~13 ~14~0~13 minecraft:grass
fill ~15~0~13 ~15~0~15 minecraft:dirt 0
fill ~15~1~13 ~18~1~13 minecraft:grass
setblock ~19~0~13 minecraft:stone 0
fill ~19~1~13 ~19~1~20 minecraft:dirt 0
fill ~19~2~13 ~19~2~18 minecraft:grass
fill ~20~0~13 ~20~0~16 minecraft:dirt 0
fill ~21~2~13 ~24~2~13 minecraft:grass
fill ~23~0~13 ~24~0~13 minecraft:dirt 0
fill ~25~0~13 ~26~0~23 minecraft:stone 0
fill ~25~2~13 ~25~2~15 minecraft:dirt 0
fill ~25~3~13 ~25~3~14 minecraft:grass
fill ~29~6~13 ~29~6~14 minecraft:dirt 0
fill ~30~6~13 ~30~6~32 minecraft:stone 0
fill ~30~7~13 ~30~8~14 minecraft:dirt 0
fill ~30~9~13 ~30~9~14 minecraft:grass
fill ~31~7~13 ~31~7~23 minecraft:stone 0
fill ~31~8~13 ~31~9~14 minecraft:dirt 0
fill ~31~10~13 ~31~10~14 minecraft:grass
fill ~32~8~13 ~32~8~23 minecraft:stone 0
fill ~32~9~13 ~32~10~14 minecraft:dirt 0
fill ~32~11~13 ~32~11~14 minecraft:grass
fill ~33~9~13 ~33~10~22 minecraft:stone 0
fill ~33~11~13 ~34~12~13 minecraft:dirt 0
setblock ~33~13~13 minecraft:grass
fill ~34~13~13 ~34~13~14 minecraft:dirt 0
setblock ~34~14~13 minecraft:grass
fill ~35~11~13 ~41~11~15 minecraft:stone 0
fill ~35~12~13 ~36~12~19 minecraft:stone 0
fill ~35~14~13 ~41~14~15 minecraft:dirt 0
fill ~35~15~13 ~36~15~17 minecraft:dirt 0
fill ~35~16~13 ~36~16~13 minecraft:grass
fill ~36~0~13 ~37~0~16 minecraft:stone 0
fill ~36~1~13 ~37~1~15 minecraft:stone 0
fill ~37~2~13 ~37~2~15 minecraft:stone 0
fill ~37~12~13 ~47~12~13 minecraft:dirt 0
fill ~37~15~13 ~41~15~13 minecraft:grass
fill ~38~10~13 ~42~10~19 minecraft:stone 0
fill ~38~13~13 ~49~13~14 minecraft:dirt 0
setblock ~41~16~13 minecraft:red_flower 8
fill ~42~9~13 ~49~9~18 minecraft:stone 0
fill ~42~11~13 ~49~11~13 minecraft:dirt 0
fill ~42~14~13 ~47~14~13 minecraft:grass
fill ~43~5~13 ~43~6~20 minecraft:dirt 0
fill ~43~10~13 ~47~10~13 minecraft:dirt 0
fill ~44~5~13 ~44~6~13 minecraft:stone 0
fill ~44~8~13 ~47~8~18 minecraft:stone 0
setblock ~44~15~13 minecraft:red_flower 8
fill ~45~6~13 ~49~6~14 minecraft:stone 0
setblock ~46~15~13 minecraft:red_flower 8
fill ~48~10~13 ~58~10~19 minecraft:stone 0
fill ~48~14~13 ~55~14~16 minecraft:dirt 0
fill ~48~15~13 ~49~15~13 minecraft:grass
fill ~50~11~13 ~53~11~22 minecraft:stone 0
fill ~50~15~13 ~53~15~17 minecraft:dirt 0
fill ~50~16~13 ~53~16~13 minecraft:grass
fill ~53~3~13 ~54~3~13 minecraft:stone 0
setblock ~54~11~13 minecraft:dirt 0
fill ~54~13~13 ~58~13~15 minecraft:dirt 0
fill ~54~15~13 ~55~15~13 minecraft:grass
fill ~55~2~13 ~55~3~20 minecraft:dirt 0
fill ~55~11~13 ~55~11~32 minecraft:stone 0
fill ~56~2~13 ~56~3~19 minecraft:stone 0
fill ~56~11~13 ~62~11~13 minecraft:dirt 0
fill ~56~14~13 ~58~14~13 minecraft:grass
fill ~57~9~13 ~60~9~36 minecraft:stone 0
fill ~57~12~13 ~60~12~14 minecraft:dirt 0
setblock ~57~15~13 minecraft:double_plant 2
fill ~59~10~13 ~63~10~13 minecraft:dirt 0
fill ~59~13~13 ~60~13~13 minecraft:grass
fill ~60~8~13 ~62~8~38 minecraft:stone 0
fill ~61~9~13 ~62~9~13 minecraft:dirt 0
fill ~61~12~13 ~62~12~13 minecraft:grass
fill ~62~7~13 ~64~7~37 minecraft:stone 0
setblock ~63~8~13 minecraft:dirt 0
setblock ~63~11~13 minecraft:grass
setblock ~63~12~13 minecraft:double_plant 2
setblock ~64~10~13 minecraft:grass
setblock ~65~6~13 minecraft:stone 0
setblock ~66~6~13 minecraft:dirt 0
fill ~68~5~13 ~70~5~36 minecraft:stone 0
fill ~71~5~13 ~71~5~16 minecraft:dirt 0
setblock ~71~8~13 minecraft:tallgrass 1
fill ~72~6~13 ~72~6~19 minecraft:dirt 0
fill ~72~7~13 ~72~7~18 minecraft:grass
fill ~73~2~13 ~73~2~30 minecraft:stone 0
fill ~73~3~13 ~73~3~29 minecraft:stone 0
fill ~73~5~13 ~73~5~18 minecraft:dirt 0
fill ~73~6~13 ~73~6~15 minecraft:grass
fill ~74~1~13 ~75~1~31 minecraft:stone 0
fill ~74~3~13 ~75~3~14 minecraft:dirt 0
fill ~74~4~13 ~74~4~16 minecraft:dirt 0
fill ~74~5~13 ~74~5~14 minecraft:grass
fill ~75~0~13 ~75~0~31 minecraft:stone 0
setblock ~75~2~13 minecraft:dirt 0
setblock ~75~4~13 minecraft:grass
fill ~76~0~13 ~76~1~13 minecraft:dirt 0
setblock ~76~2~13 minecraft:grass
setblock ~77~1~13 minecraft:grass
fill ~7~0~14 ~12~0~14 minecraft:grass
fill ~13~0~14 ~14~0~17 minecraft:dirt 0
fill ~13~1~14 ~16~1~14 minecraft:grass
fill ~17~0~14 ~18~0~14 minecraft:stone 0
fill ~17~1~14 ~18~1~21 minecraft:dirt 0
fill ~17~2~14 ~18~2~18 minecraft:grass
setblock ~19~0~14 minecraft:dirt 0
fill ~21~2~14 ~23~2~14 minecraft:grass
setblock ~23~0~14 minecraft:dirt 0
fill ~24~0~14 ~24~0~25 minecraft:stone 0
fill ~24~2~14 ~24~2~16 minecraft:dirt 0
fill ~24~3~14 ~24~3~15 minecraft:grass
fill ~28~3~14 ~28~3~19 minecraft:stone 0
fill ~28~5~14 ~28~5~15 minecraft:dirt 0
setblock ~28~6~14 minecraft:grass
fill ~29~5~14 ~29~5~26 minecraft:stone 0
fill ~29~7~14 ~29~7~15 minecraft:dirt 0
setblock ~29~8~14 minecraft:grass
setblock ~32~12~14 minecraft:double_plant 2
fill ~33~11~14 ~33~13~14 minecraft:dirt 0
setblock ~33~14~14 minecraft:grass
fill ~34~11~14 ~34~12~23 minecraft:stone 0
fill ~34~14~14 ~34~15~16 minecraft:dirt 0
setblock ~34~16~14 minecraft:grass
fill ~35~13~14 ~37~13~14 minecraft:stone 0
fill ~35~16~14 ~37~16~19 minecraft:dirt 0
fill ~35~17~14 ~37~17~15 minecraft:grass
fill ~37~12~14 ~41~12~15 minecraft:stone 0
fill ~37~15~14 ~42~15~17 minecraft:dirt 0
fill ~38~16~14 ~42~16~14 minecraft:grass
fill ~40~5~14 ~41~5~21 minecraft:stone 0
fill ~41~6~14 ~41~6~25 minecraft:stone 0
fill ~41~7~14 ~41~7~19 minecraft:stone 0
fill ~42~4~14 ~44~4~18 minecraft:dirt 0
fill ~42~5~14 ~42~6~20 minecraft:dirt 0
fill ~42~7~14 ~44~7~18 minecraft:dirt 0
fill ~42~11~14 ~42~11~23 minecraft:stone 0
fill ~42~12~14 ~47~12~14 minecraft:dirt 0
fill ~42~14~14 ~47~14~16 minecraft:dirt 0
fill ~43~10~14 ~47~10~23 minecraft:stone 0
setblock ~43~11~14 minecraft:dirt 0
setblock ~43~15~14 minecraft:grass
setblock ~43~16~14 minecraft:red_flower 8
fill ~44~5~14 ~44~6~20 minecraft:dirt 0
fill ~44~11~14 ~49~11~19 minecraft:stone 0
fill ~44~15~14 ~49~15~16 minecraft:dirt 0
fill ~44~16~14 ~47~16~14 minecraft:grass
fill ~45~4~14 ~45~4~16 minecraft:stone 0
fill ~45~7~14 ~54~7~16 minecraft:stone 0
fill ~48~12~14 ~56~12~14 minecraft:stone 0
fill ~48~16~14 ~53~16~17 minecraft:dirt 0
fill ~48~17~14 ~50~17~14 minecraft:grass
setblock ~50~13~14 minecraft:dirt 0
fill ~51~2~14 ~53~2~14 minecraft:stone 0
fill ~51~13~14 ~51~13~34 minecraft:stone 0
fill ~51~17~14 ~51~17~18 minecraft:dirt 0
fill ~51~18~14 ~51~18~16 minecraft:grass
fill ~52~13~14 ~53~13~15 minecraft:dirt 0
fill ~52~17~14 ~53~17~15 minecraft:grass
setblock ~53~3~14 minecraft:stone 0
fill ~54~2~14 ~54~3~20 minecraft:dirt 0
fill ~54~11~14 ~54~11~32 minecraft:stone 0
fill ~54~15~14 ~56~15~18 minecraft:dirt 0
fill ~54~16~14 ~56~16~14 minecraft:grass
setblock ~55~17~14 minecraft:red_flower 8
fill ~56~11~14 ~58~11~35 minecraft:stone 0
fill ~56~14~14 ~58~14~17 minecraft:dirt 0
fill ~57~15~14 ~58~15~14 minecraft:grass
fill ~57~16~14 ~58~16~14 minecraft:red_flower 8
fill ~59~10~14 ~60~10~37 minecraft:stone 0
fill ~59~11~14 ~63~11~14 minecraft:dirt 0
fill ~59~13~14 ~60~13~16 minecraft:dirt 0
fill ~59~14~14 ~60~14~14 minecraft:grass
setblock ~59~15~14 minecraft:tallgrass 1
fill ~61~9~14 ~62~9~38 minecraft:stone 0
fill ~61~10~14 ~64~10~14 minecraft:dirt 0
fill ~61~12~14 ~62~12~16 minecraft:dirt 0
fill ~61~13~14 ~62~13~14 minecraft:grass
fill ~63~8~14 ~64~8~35 minecraft:stone 0
setblock ~63~12~14 minecraft:grass
setblock ~63~13~14 minecraft:double_plant 2
setblock ~64~11~14 minecraft:grass
fill ~65~6~14 ~65~6~16 minecraft:copper_ore
setblock ~65~7~14 minecraft:stone 0
fill ~65~9~14 ~65~9~15 minecraft:dirt 0
setblock ~65~10~14 minecraft:grass
fill ~66~6~14 ~67~6~33 minecraft:stone 0
fill ~72~4~14 ~72~4~29 minecraft:stone 0
fill ~73~4~14 ~73~4~15 minecraft:dirt 0
fill ~74~2~14 ~75~2~30 minecraft:stone 0
fill ~75~4~14 ~75~4~16 minecraft:dirt 0
fill ~75~5~14 ~75~5~15 minecraft:grass
fill ~76~0~14 ~76~1~30 minecraft:stone 0
fill ~76~2~14 ~76~3~15 minecraft:dirt 0
fill ~76~4~14 ~76~4~15 minecraft:grass
setblock ~76~5~14 minecraft:tallgrass 1
fill ~77~1~14 ~77~1~15 minecraft:dirt 0
setblock ~77~2~14 minecraft:grass
fill ~78~0~14 ~78~0~15 minecraft:dirt 0
fill ~78~1~14 ~78~1~15 minecraft:grass
fill ~8~0~15 ~12~0~15 minecraft:grass
fill ~13~1~15 ~15~1~15 minecraft:grass
fill ~16~0~15 ~17~0~15 minecraft:copper_ore
fill ~16~1~15 ~16~1~23 minecraft:dirt 0
fill ~16~2~15 ~16~2~20 minecraft:grass
fill ~18~0~15 ~19~0~15 minecraft:stone 0
fill ~21~1~15 ~24~1~15 minecraft:dirt 0
setblock ~21~2~15 minecraft:grass
fill ~22~0~15 ~23~0~26 minecraft:stone 0
fill ~22~2~15 ~23~2~17 minecraft:dirt 0
fill ~22~3~15 ~23~3~16 minecraft:grass
fill ~25~1~15 ~27~1~22 minecraft:stone 0
fill ~25~3~15 ~27~3~15 minecraft:dirt 0
setblock ~25~4~15 minecraft:grass
fill ~26~2~15 ~27~2~32 minecraft:stone 0
fill ~26~4~15 ~27~4~15 minecraft:dirt 0
fill ~26~5~15 ~27~5~15 minecraft:grass
fill ~28~4~15 ~28~4~32 minecraft:stone 0
setblock ~28~6~15 minecraft:dirt 0
setblock ~28~7~15 minecraft:grass
fill ~29~6~15 ~29~6~32 minecraft:stone 0
fill ~29~8~15 ~30~8~15 minecraft:dirt 0
setblock ~29~9~15 minecraft:grass
fill ~30~7~15 ~30~7~23 minecraft:stone 0
setblock ~30~9~15 minecraft:dirt 0
setblock ~30~10~15 minecraft:grass
fill ~31~8~15 ~31~9~23 minecraft:stone 0
fill ~31~10~15 ~31~11~15 minecraft:dirt 0
setblock ~31~12~15 minecraft:grass
fill ~32~9~15 ~32~11~23 minecraft:stone 0
fill ~32~12~15 ~32~13~15 minecraft:dirt 0
setblock ~32~14~15 minecraft:grass
fill ~33~11~15 ~33~12~23 minecraft:stone 0
fill ~33~13~15 ~33~15~15 minecraft:dirt 0
setblock ~33~16~15 minecraft:grass
fill ~34~13~15 ~37~13~15 minecraft:coal_ore
fill ~34~16~15 ~34~16~19 minecraft:dirt 0
fill ~34~17~15 ~34~17~16 minecraft:grass
setblock ~35~18~15 minecraft:red_flower 8
fill ~38~13~15 ~39~13~20 minecraft:stone 0
fill ~38~16~15 ~41~16~18 minecraft:dirt 0
fill ~38~17~15 ~41~17~15 minecraft:grass
setblock ~40~13~15 minecraft:dirt 0
fill ~40~18~15 ~40~18~16 minecraft:red_flower 8
setblock ~41~13~15 minecraft:stone 0
fill ~42~12~15 ~46~13~15 minecraft:dirt 0
fill ~42~16~15 ~46~16~15 minecraft:grass
fill ~43~11~15 ~43~11~25 minecraft:stone 0
fill ~43~15~15 ~43~15~17 minecraft:dirt 0
fill ~45~5~15 ~45~6~20 minecraft:dirt 0
fill ~46~5~15 ~48~6~18 minecraft:stone 0
fill ~47~12~15 ~54~12~20 minecraft:stone 0
fill ~47~13~15 ~49~13~15 minecraft:dirt 0
fill ~47~16~15 ~47~16~17 minecraft:dirt 0
fill ~47~17~15 ~49~17~15 minecraft:grass
fill ~49~6~15 ~49~6~25 minecraft:stone 0
fill ~50~13~15 ~50~13~34 minecraft:stone 0
fill ~50~17~15 ~50~17~18 minecraft:dirt 0
fill ~50~18~15 ~50~18~16 minecraft:grass
fill ~51~2~15 ~52~2~15 minecraft:stone 0
fill ~51~4~15 ~53~4~15 minecraft:stone 0
fill ~53~2~15 ~53~3~20 minecraft:dirt 0
fill ~53~18~15 ~53~18~16 minecraft:red_flower 8
fill ~54~1~15 ~54~1~20 minecraft:dirt 0
fill ~54~4~15 ~54~4~20 minecraft:dirt 0
fill ~54~16~15 ~54~16~19 minecraft:dirt 0
fill ~54~17~15 ~54~17~16 minecraft:grass
fill ~55~1~15 ~56~1~15 minecraft:stone 0
setblock ~55~12~15 minecraft:dirt 0
fill ~55~16~15 ~57~16~15 minecraft:grass
fill ~56~12~15 ~57~12~35 minecraft:stone 0
fill ~57~15~15 ~57~15~23 minecraft:dirt 0
fill ~58~12~15 ~60~12~15 minecraft:dirt 0
fill ~58~15~15 ~60~15~15 minecraft:grass
fill ~59~11~15 ~60~11~37 minecraft:stone 0
fill ~59~14~15 ~60~14~18 minecraft:dirt 0
fill ~61~10~15 ~63~10~33 minecraft:stone 0
fill ~61~11~15 ~64~11~15 minecraft:dirt 0
fill ~61~13~15 ~62~13~17 minecraft:dirt 0
fill ~61~14~15 ~62~14~15 minecraft:grass
fill ~63~9~15 ~64~9~33 minecraft:stone 0
fill ~63~12~15 ~63~12~17 minecraft:dirt 0
setblock ~63~13~15 minecraft:grass
setblock ~63~14~15 minecraft:double_plant 2
setblock ~64~6~15 minecraft:copper_ore
fill ~64~10~15 ~65~10~15 minecraft:dirt 0
setblock ~64~12~15 minecraft:grass
fill ~65~5~15 ~65~5~16 minecraft:copper_ore
setblock ~65~7~15 minecraft:copper_ore
fill ~65~8~15 ~65~8~34 minecraft:stone 0
setblock ~65~11~15 minecraft:grass
fill ~66~7~15 ~66~7~36 minecraft:stone 0
fill ~66~9~15 ~66~9~17 minecraft:dirt 0
fill ~66~10~15 ~66~10~16 minecraft:grass
setblock ~66~11~15 minecraft:double_plant 2
fill ~67~9~15 ~68~9~15 minecraft:grass
fill ~68~6~15 ~68~6~33 minecraft:stone 0
fill ~68~8~15 ~68~8~20 minecraft:dirt 0
fill ~69~8~15 ~70~8~16 minecraft:grass
fill ~74~3~15 ~74~3~30 minecraft:stone 0
fill ~74~5~15 ~74~5~16 minecraft:dirt 0
fill ~74~6~15 ~74~6~16 minecraft:grass
setblock ~75~3~15 minecraft:dirt 0
setblock ~77~0~15 minecraft:coal_ore
fill ~77~2~15 ~77~2~16 minecraft:dirt 0
setblock ~77~3~15 minecraft:grass
fill ~79~0~15 ~79~0~17 minecraft:dirt 0
fill ~79~1~15 ~79~1~16 minecraft:grass
fill ~8~0~16 ~11~0~16 minecraft:grass
setblock ~8~1~16 minecraft:tallgrass 1
fill ~12~0~16 ~12~0~20 minecraft:dirt 0
fill ~12~1~16 ~14~1~17 minecraft:grass
fill ~15~0~16 ~18~0~19 minecraft:stone 0
fill ~15~1~16 ~15~1~27 minecraft:dirt 0
fill ~15~2~16 ~15~2~22 minecraft:grass
fill ~19~0~16 ~19~0~17 minecraft:dirt 0
fill ~21~0~16 ~21~0~34 minecraft:stone 0
fill ~21~1~16 ~23~1~16 minecraft:dirt 0
fill ~21~2~16 ~21~2~18 minecraft:dirt 0
fill ~21~3~16 ~21~3~18 minecraft:grass
fill ~24~1~16 ~24~1~24 minecraft:stone 0
setblock ~24~3~16 minecraft:dirt 0
setblock ~24~4~16 minecraft:grass
fill ~25~2~16 ~25~3~22 minecraft:stone 0
fill ~25~4~16 ~25~5~16 minecraft:dirt 0
setblock ~25~6~16 minecraft:grass
fill ~26~3~16 ~27~3~32 minecraft:stone 0
fill ~26~4~16 ~27~4~21 minecraft:stone 0
fill ~26~5~16 ~27~6~16 minecraft:dirt 0
fill ~26~7~16 ~27~7~16 minecraft:grass
fill ~28~5~16 ~28~6~32 minecraft:stone 0
fill ~28~7~16 ~28~8~16 minecraft:dirt 0
setblock ~28~9~16 minecraft:grass
fill ~29~7~16 ~29~8~23 minecraft:stone 0
fill ~29~9~16 ~29~10~16 minecraft:dirt 0
setblock ~29~11~16 minecraft:grass
fill ~30~8~16 ~30~10~23 minecraft:stone 0
fill ~30~11~16 ~30~12~16 minecraft:dirt 0
setblock ~30~13~16 minecraft:grass
fill ~31~10~16 ~31~11~23 minecraft:stone 0
fill ~31~12~16 ~31~13~16 minecraft:dirt 0
setblock ~31~14~16 minecraft:grass
setblock ~32~2~16 minecraft:stone 0
fill ~32~12~16 ~32~12~46 minecraft:stone 0
fill ~32~13~16 ~32~15~16 minecraft:dirt 0
setblock ~32~16~16 minecraft:grass
setblock ~33~0~16 minecraft:stone 0
fill ~33~1~16 ~37~2~20 minecraft:stone 1
setblock ~33~3~16 minecraft:stone 0
fill ~33~13~16 ~36~13~16 minecraft:coal_ore
fill ~33~14~16 ~33~16~17 minecraft:dirt 0
fill ~33~17~16 ~33~17~17 minecraft:grass
setblock ~33~18~16 minecraft:red_flower 8
fill ~34~0~16 ~35~0~20 minecraft:stone 1
fill ~34~3~16 ~35~3~20 minecraft:stone 1
fill ~35~11~16 ~36~11~19 minecraft:stone 0
fill ~35~14~16 ~36~14~16 minecraft:coal_ore
fill ~35~17~16 ~39~17~19 minecraft:dirt 0
fill ~35~18~16 ~39~18~17 minecraft:grass
fill ~36~3~16 ~39~3~16 minecraft:stone 0
fill ~37~11~16 ~38~12~17 minecraft:copper_ore
fill ~37~13~16 ~37~14~20 minecraft:stone 0
fill ~38~14~16 ~39~14~16 minecraft:stone 0
fill ~39~11~16 ~41~12~19 minecraft:stone 0
setblock ~39~19~16 minecraft:red_flower 8
fill ~40~13~16 ~40~13~21 minecraft:stone 0
fill ~40~14~16 ~41~14~17 minecraft:dirt 0
fill ~40~17~16 ~42~17~16 minecraft:grass
fill ~41~13~16 ~46~13~16 minecraft:dirt 0
fill ~42~12~16 ~42~12~45 minecraft:stone 0
fill ~42~16~16 ~42~16~18 minecraft:dirt 0
setblock ~43~12~16 minecraft:dirt 0
setblock ~43~16~16 minecraft:grass
fill ~44~12~16 ~46~12~21 minecraft:stone 0
fill ~44~16~16 ~46~16~17 minecraft:dirt 0
fill ~44~17~16 ~46~17~16 minecraft:grass
setblock ~45~18~16 minecraft:red_flower 8
fill ~47~13~16 ~49~13~34 minecraft:stone 0
fill ~47~17~16 ~49~17~17 minecraft:dirt 0
fill ~47~18~16 ~49~18~16 minecraft:grass
setblock ~49~19~16 minecraft:red_flower 8
fill ~50~1~16 ~52~1~16 minecraft:stone 0
fill ~50~3~16 ~51~3~18 minecraft:stone 0
fill ~51~2~16 ~51~2~18 minecraft:stone 0
fill ~51~4~16 ~52~4~16 minecraft:stone 0
fill ~52~2~16 ~52~3~20 minecraft:dirt 0
fill ~52~13~16 ~52~13~35 minecraft:stone 0
fill ~52~17~16 ~52~17~18 minecraft:dirt 0
fill ~52~18~16 ~52~18~17 minecraft:grass
fill ~53~1~16 ~53~1~20 minecraft:dirt 0
fill ~53~4~16 ~53~4~20 minecraft:dirt 0
fill ~53~13~16 ~54~13~16 minecraft:dirt 0
setblock ~53~17~16 minecraft:grass
fill ~55~1~16 ~55~1~18 minecraft:dirt 0
fill ~55~4~16 ~55~4~18 minecraft:dirt 0
fill ~55~12~16 ~55~13~30 minecraft:stone 0
fill ~55~16~16 ~56~16~20 minecraft:dirt 0
fill ~55~17~16 ~56~17~17 minecraft:grass
fill ~55~18~16 ~55~18~17 minecraft:red_flower 8
fill ~56~1~16 ~56~1~18 minecraft:stone 0
fill ~56~4~16 ~57~4~16 minecraft:stone 0
fill ~56~13~16 ~56~13~36 minecraft:stone 0
fill ~57~13~16 ~58~13~16 minecraft:dirt 0
fill ~57~16~16 ~59~16~16 minecraft:grass
fill ~58~12~16 ~60~12~37 minecraft:stone 0
fill ~58~15~16 ~59~15~23 minecraft:dirt 0
fill ~59~4~16 ~63~4~43 minecraft:stone 0
fill ~60~15~16 ~61~15~16 minecraft:grass
fill ~61~11~16 ~63~11~32 minecraft:stone 0
fill ~61~14~16 ~61~14~26 minecraft:dirt 0
fill ~62~14~16 ~63~14~16 minecraft:grass
fill ~63~13~16 ~63~13~25 minecraft:dirt 0
fill ~64~4~16 ~64~5~16 minecraft:copper_ore
fill ~64~6~16 ~64~6~39 minecraft:stone 0
fill ~64~10~16 ~64~10~32 minecraft:stone 0
fill ~64~11~16 ~65~11~17 minecraft:dirt 0
fill ~64~12~16 ~64~12~23 minecraft:dirt 0
fill ~64~13~16 ~64~13~17 minecraft:grass
fill ~65~7~16 ~65~7~37 minecraft:stone 0
fill ~65~9~16 ~65~9~33 minecraft:stone 0
fill ~65~10~16 ~65~10~17 minecraft:dirt 0
fill ~65~12~16 ~65~12~17 minecraft:grass
fill ~67~7~16 ~67~7~33 minecraft:stone 0
fill ~67~9~16 ~67~9~20 minecraft:dirt 0
fill ~67~10~16 ~67~10~18 minecraft:grass
fill ~68~7~16 ~68~7~17 minecraft:dirt 0
fill ~68~9~16 ~68~9~17 minecraft:grass
fill ~73~4~16 ~73~4~29 minecraft:stone 0
fill ~73~6~16 ~73~6~18 minecraft:dirt 0
fill ~73~7~16 ~73~7~18 minecraft:grass
fill ~75~3~16 ~75~3~29 minecraft:stone 0
fill ~75~5~16 ~75~5~18 minecraft:dirt 0
fill ~75~6~16 ~75~6~17 minecraft:grass
fill ~76~2~16 ~76~2~30 minecraft:stone 0
fill ~76~3~16 ~77~3~16 minecraft:dirt 0
setblock ~76~4~16 minecraft:dirt 0
setblock ~76~5~16 minecraft:grass
fill ~77~0~16 ~78~0~29 minecraft:stone 0
fill ~77~1~16 ~77~1~29 minecraft:stone 0
setblock ~77~4~16 minecraft:grass
fill ~78~1~16 ~78~2~16 minecraft:dirt 0
setblock ~78~3~16 minecraft:grass
fill ~3~0~17 ~3~0~26 minecraft:grass
fill ~9~0~17 ~11~0~18 minecraft:grass
setblock ~9~1~17 minecraft:double_plant 2
fill ~20~0~17 ~20~0~49 minecraft:stone 0
fill ~20~2~17 ~20~2~19 minecraft:dirt 0
fill ~20~3~17 ~20~3~18 minecraft:grass
fill ~21~1~17 ~22~1~17 minecraft:dirt 0
setblock ~22~3~17 minecraft:grass
fill ~23~1~17 ~23~1~25 minecraft:stone 0
fill ~23~3~17 ~23~3~18 minecraft:dirt 0
setblock ~23~4~17 minecraft:grass
fill ~24~2~17 ~24~3~24 minecraft:stone 0
fill ~24~4~17 ~24~5~17 minecraft:dirt 0
setblock ~24~6~17 minecraft:grass
fill ~25~4~17 ~25~4~26 minecraft:stone 0
fill ~25~5~17 ~25~6~17 minecraft:dirt 0
setblock ~25~7~17 minecraft:grass
fill ~26~5~17 ~27~5~23 minecraft:stone 0
fill ~26~6~17 ~26~7~17 minecraft:dirt 0
setblock ~26~8~17 minecraft:grass
fill ~27~6~17 ~27~6~32 minecraft:stone 0
fill ~27~7~17 ~27~8~17 minecraft:dirt 0
setblock ~27~9~17 minecraft:grass
fill ~28~7~17 ~28~7~27 minecraft:stone 0
fill ~28~8~17 ~28~9~17 minecraft:dirt 0
setblock ~28~10~17 minecraft:grass
fill ~29~9~17 ~29~10~23 minecraft:stone 0
fill ~29~11~17 ~29~12~17 minecraft:dirt 0
setblock ~29~13~17 minecraft:grass
fill ~30~11~17 ~30~12~23 minecraft:stone 0
fill ~30~13~17 ~30~14~17 minecraft:dirt 0
setblock ~30~15~17 minecraft:grass
fill ~31~0~17 ~31~1~17 minecraft:stone 0
fill ~31~12~17 ~31~13~46 minecraft:stone 0
fill ~31~14~17 ~32~15~17 minecraft:dirt 0
setblock ~31~16~17 minecraft:grass
fill ~32~0~17 ~33~0~20 minecraft:stone 1
fill ~32~1~17 ~32~3~20 minecraft:stone 1
setblock ~32~4~17 minecraft:stone 0
fill ~32~13~17 ~36~13~20 minecraft:stone 0
fill ~32~16~17 ~32~16~19 minecraft:dirt 0
setblock ~32~17~17 minecraft:grass
fill ~33~3~17 ~33~4~20 minecraft:stone 1
fill ~33~5~17 ~33~5~18 minecraft:stone 0
fill ~34~4~17 ~36~4~20 minecraft:stone 1
fill ~34~14~17 ~36~14~37 minecraft:stone 0
fill ~34~15~17 ~34~15~18 minecraft:dirt 0
fill ~34~17~17 ~34~17~19 minecraft:dirt 0
fill ~34~18~17 ~34~18~18 minecraft:grass
fill ~36~0~17 ~37~0~20 minecraft:stone 1
fill ~36~3~17 ~37~3~20 minecraft:stone 1
fill ~37~4~17 ~39~4~20 minecraft:stone 0
fill ~38~3~17 ~39~3~20 minecraft:stone 0
fill ~38~14~17 ~38~14~37 minecraft:stone 0
fill ~39~14~17 ~39~14~18 minecraft:dirt 0
fill ~40~17~17 ~42~17~18 minecraft:dirt 0
fill ~40~18~17 ~42~18~17 minecraft:grass
fill ~41~13~17 ~42~13~22 minecraft:stone 0
fill ~42~14~17 ~44~14~17 minecraft:dirt 0
fill ~43~12~17 ~43~12~45 minecraft:stone 0
setblock ~43~13~17 minecraft:dirt 0
setblock ~43~16~17 minecraft:dirt 0
setblock ~43~17~17 minecraft:grass
fill ~44~13~17 ~46~13~35 minecraft:stone 0
fill ~44~15~17 ~45~15~17 minecraft:dirt 0
fill ~44~17~17 ~46~17~17 minecraft:dirt 0
setblock ~44~18~17 minecraft:grass
fill ~45~4~17 ~45~4~20 minecraft:dirt 0
fill ~45~7~17 ~45~7~20 minecraft:dirt 0
fill ~45~14~17 ~51~14~33 minecraft:stone 0
fill ~45~18~17 ~51~18~17 minecraft:dirt 0
fill ~45~19~17 ~46~19~17 minecraft:grass
fill ~46~7~17 ~54~7~18 minecraft:stone 0
fill ~46~15~17 ~49~15~33 minecraft:stone 0
fill ~47~19~17 ~49~19~19 minecraft:dirt 0
fill ~47~20~17 ~49~20~17 minecraft:grass
setblock ~48~21~17 minecraft:red_flower 8
fill ~50~1~17 ~51~1~24 minecraft:stone 0
fill ~50~19~17 ~51~19~17 minecraft:grass
fill ~51~4~17 ~51~4~26 minecraft:stone 0
fill ~52~1~17 ~52~1~20 minecraft:dirt 0
fill ~52~4~17 ~52~4~20 minecraft:dirt 0
fill ~52~14~17 ~53~14~17 minecraft:dirt 0
fill ~53~13~17 ~54~13~35 minecraft:stone 0
fill ~53~17~17 ~54~17~19 minecraft:dirt 0
fill ~53~18~17 ~54~18~17 minecraft:grass
fill ~54~14~17 ~54~14~36 minecraft:stone 0
setblock ~55~14~17 minecraft:dirt 0
fill ~56~4~17 ~56~4~52 minecraft:stone 0
fill ~57~3~17 ~58~4~19 minecraft:coal_ore
fill ~57~13~17 ~57~13~37 minecraft:stone 0
fill ~57~16~17 ~57~16~23 minecraft:dirt 0
fill ~57~17~17 ~57~17~22 minecraft:grass
fill ~58~13~17 ~59~13~17 minecraft:dirt 0
fill ~58~16~17 ~60~16~17 minecraft:grass
setblock ~59~17~17 minecraft:red_flower 8
fill ~60~13~17 ~60~13~22 minecraft:stone 0
fill ~60~15~17 ~60~15~29 minecraft:dirt 0
fill ~61~12~17 ~62~12~32 minecraft:stone 0
fill ~61~15~17 ~62~15~17 minecraft:grass
setblock ~61~16~17 minecraft:red_flower 8
fill ~62~14~17 ~62~14~29 minecraft:dirt 0
setblock ~63~14~17 minecraft:grass
setblock ~63~15~17 minecraft:red_flower 8
fill ~64~4~17 ~64~4~41 minecraft:stone 0
setblock ~64~5~17 minecraft:copper_ore
fill ~65~5~17 ~65~5~40 minecraft:stone 0
fill ~65~6~17 ~65~6~38 minecraft:stone 0
fill ~66~8~17 ~66~8~34 minecraft:stone 0
fill ~66~10~17 ~66~10~20 minecraft:dirt 0
setblock ~66~11~17 minecraft:grass
fill ~67~8~17 ~67~8~18 minecraft:dirt 0
fill ~69~6~17 ~69~6~35 minecraft:stone 0
fill ~69~8~17 ~69~8~20 minecraft:dirt 0
fill ~69~9~17 ~69~9~19 minecraft:grass
fill ~70~6~17 ~70~6~18 minecraft:dirt 0
fill ~70~8~17 ~71~8~18 minecraft:grass
fill ~71~5~17 ~71~5~34 minecraft:stone 0
fill ~71~7~17 ~71~7~19 minecraft:dirt 0
fill ~74~4~17 ~76~4~27 minecraft:stone 0
fill ~74~5~17 ~74~5~30 minecraft:stone 0
fill ~74~6~17 ~74~6~19 minecraft:dirt 0
fill ~74~7~17 ~74~7~19 minecraft:grass
fill ~76~3~17 ~76~3~29 minecraft:stone 0
fill ~76~5~17 ~76~5~21 minecraft:dirt 0
fill ~76~6~17 ~76~6~21 minecraft:grass
fill ~77~2~17 ~77~2~29 minecraft:stone 0
fill ~77~3~17 ~78~3~17 minecraft:dirt 0
fill ~77~4~17 ~77~4~21 minecraft:dirt 0
fill ~77~5~17 ~77~5~21 minecraft:grass
fill ~78~1~17 ~78~1~29 minecraft:stone 0
setblock ~78~2~17 minecraft:dirt 0
setblock ~78~4~17 minecraft:grass
setblock ~79~1~17 minecraft:dirt 0
setblock ~79~2~17 minecraft:grass
fill ~2~0~18 ~2~0~26 minecraft:grass
fill ~4~0~18 ~4~0~22 minecraft:grass
fill ~12~1~18 ~13~1~19 minecraft:grass
fill ~13~0~18 ~13~0~19 minecraft:dirt 0
fill ~14~0~18 ~14~0~20 minecraft:stone 0
fill ~14~1~18 ~14~1~28 minecraft:dirt 0
fill ~14~2~18 ~14~2~22 minecraft:grass
setblock ~15~3~18 minecraft:double_plant 2
fill ~19~0~18 ~19~0~52 minecraft:stone 0
setblock ~21~1~18 minecraft:dirt 0
fill ~22~1~18 ~22~1~34 minecraft:stone 0
fill ~22~2~18 ~22~3~18 minecraft:dirt 0
setblock ~22~4~18 minecraft:grass
fill ~23~2~18 ~23~2~25 minecraft:stone 0
setblock ~23~4~18 minecraft:dirt 0
setblock ~23~5~18 minecraft:grass
fill ~24~4~18 ~24~4~26 minecraft:stone 0
fill ~24~5~18 ~24~6~18 minecraft:dirt 0
setblock ~24~7~18 minecraft:grass
fill ~25~5~18 ~25~5~68 minecraft:stone 0
fill ~25~6~18 ~25~7~18 minecraft:dirt 0
setblock ~25~8~18 minecraft:grass
fill ~26~6~18 ~26~6~41 minecraft:stone 0
fill ~26~7~18 ~26~8~18 minecraft:dirt 0
setblock ~26~9~18 minecraft:grass
fill ~27~7~18 ~27~7~32 minecraft:stone 0
fill ~27~8~18 ~27~9~18 minecraft:dirt 0
setblock ~27~10~18 minecraft:grass
fill ~28~8~18 ~28~8~28 minecraft:stone 0
fill ~28~9~18 ~28~9~27 minecraft:stone 0
fill ~28~10~18 ~28~11~18 minecraft:dirt 0
setblock ~28~12~18 minecraft:grass
setblock ~29~0~18 minecraft:stone 0
fill ~29~11~18 ~29~11~23 minecraft:stone 0
fill ~29~12~18 ~29~13~18 minecraft:dirt 0
setblock ~29~14~18 minecraft:grass
fill ~30~0~18 ~31~3~20 minecraft:stone 1
fill ~30~4~18 ~31~4~18 minecraft:stone 0
fill ~30~13~18 ~30~13~41 minecraft:stone 0
fill ~30~14~18 ~31~15~18 minecraft:dirt 0
setblock ~30~16~18 minecraft:grass
fill ~31~5~18 ~31~5~19 minecraft:stone 0
fill ~31~16~18 ~31~16~19 minecraft:dirt 0
setblock ~31~17~18 minecraft:grass
fill ~32~4~18 ~32~4~20 minecraft:stone 1
fill ~32~14~18 ~33~14~61 minecraft:stone 0
fill ~32~15~18 ~33~15~18 minecraft:dirt 0
fill ~32~17~18 ~33~17~19 minecraft:dirt 0
fill ~32~18~18 ~33~18~18 minecraft:grass
fill ~33~16~18 ~33~16~19 minecraft:dirt 0
setblock ~33~19~18 minecraft:red_flower 8
fill ~35~15~18 ~37~15~37 minecraft:stone 0
fill ~35~18~18 ~38~18~20 minecraft:dirt 0
fill ~35~19~18 ~38~19~19 minecraft:grass
fill ~37~11~18 ~38~12~19 minecraft:stone 0
fill ~38~1~18 ~38~2~19 minecraft:stone 1
fill ~38~15~18 ~41~15~18 minecraft:dirt 0
setblock ~38~20~18 minecraft:red_flower 8
fill ~39~1~18 ~39~2~21 minecraft:stone 0
setblock ~39~18~18 minecraft:grass
setblock ~39~19~18 minecraft:red_flower 8
fill ~40~2~18 ~41~2~20 minecraft:stone 0
fill ~40~14~18 ~44~14~33 minecraft:stone 0
fill ~40~18~18 ~46~18~18 minecraft:dirt 0
fill ~40~19~18 ~42~19~18 minecraft:grass
fill ~42~15~18 ~45~15~33 minecraft:stone 0
fill ~43~13~18 ~43~13~33 minecraft:stone 0
fill ~43~16~18 ~51~16~28 minecraft:stone 0
fill ~43~17~18 ~44~17~18 minecraft:dirt 0
fill ~43~19~18 ~46~19~19 minecraft:dirt 0
fill ~43~20~18 ~44~20~18 minecraft:grass
setblock ~44~0~18 minecraft:stone 0
fill ~45~0~18 ~49~0~20 minecraft:dirt 0
fill ~45~17~18 ~47~17~29 minecraft:stone 0
fill ~45~20~18 ~51~20~20 minecraft:dirt 0
fill ~45~21~18 ~46~21~18 minecraft:grass
fill ~47~18~18 ~47~18~29 minecraft:stone 0
fill ~47~21~18 ~47~21~22 minecraft:dirt 0
fill ~47~22~18 ~47~22~19 minecraft:grass
setblock ~47~23~18 minecraft:red_flower 8
setblock ~48~1~18 minecraft:stone 0
fill ~48~8~18 ~49~8~18 minecraft:stone 0
fill ~48~17~18 ~49~18~18 minecraft:dirt 0
fill ~48~21~18 ~51~21~18 minecraft:grass
fill ~50~0~18 ~52~0~18 minecraft:stone 0
fill ~50~8~18 ~51~9~20 minecraft:gravel
fill ~50~15~18 ~53~15~44 minecraft:stone 0
fill ~50~18~18 ~53~18~18 minecraft:dirt 0
fill ~50~19~18 ~52~19~20 minecraft:dirt 0
fill ~52~8~18 ~59~8~27 minecraft:stone 0
fill ~52~9~18 ~56~9~32 minecraft:stone 0
fill ~52~14~18 ~53~14~36 minecraft:stone 0
fill ~52~16~18 ~53~16~18 minecraft:dirt 0
setblock ~52~20~18 minecraft:grass
setblock ~52~21~18 minecraft:red_flower 8
setblock ~53~19~18 minecraft:grass
fill ~54~18~18 ~56~18~18 minecraft:grass
setblock ~54~19~18 minecraft:red_flower 8
fill ~55~14~18 ~56~14~37 minecraft:stone 0
fill ~55~17~18 ~56~17~21 minecraft:dirt 0
fill ~57~14~18 ~58~14~22 minecraft:dirt 0
setblock ~57~18~18 minecraft:red_flower 8
fill ~58~13~18 ~58~13~37 minecraft:stone 0
fill ~58~16~18 ~58~16~25 minecraft:dirt 0
fill ~58~17~18 ~58~17~23 minecraft:grass
setblock ~59~13~18 minecraft:dirt 0
fill ~59~16~18 ~61~16~18 minecraft:grass
setblock ~60~17~18 minecraft:red_flower 8
fill ~61~13~18 ~61~13~33 minecraft:stone 0
fill ~61~15~18 ~61~15~33 minecraft:dirt 0
fill ~62~13~18 ~62~13~24 minecraft:dirt 0
fill ~62~15~18 ~63~15~19 minecraft:grass
fill ~63~12~18 ~63~12~19 minecraft:stone 0
fill ~63~14~18 ~63~14~19 minecraft:dirt 0
fill ~64~5~18 ~64~5~41 minecraft:stone 0
fill ~64~11~18 ~64~11~31 minecraft:stone 0
fill ~64~13~18 ~64~13~31 minecraft:dirt 0
fill ~64~14~18 ~64~14~23 minecraft:grass
setblock ~64~15~18 minecraft:red_flower 8
fill ~65~10~18 ~65~10~32 minecraft:stone 0
fill ~65~11~18 ~66~11~22 minecraft:dirt 0
fill ~65~12~18 ~65~12~25 minecraft:dirt 0
fill ~65~13~18 ~65~13~22 minecraft:grass
fill ~66~9~18 ~66~9~32 minecraft:stone 0
fill ~66~12~18 ~66~12~20 minecraft:grass
fill ~68~7~18 ~68~7~33 minecraft:stone 0
fill ~68~9~18 ~68~9~20 minecraft:dirt 0
fill ~68~10~18 ~68~10~20 minecraft:grass
fill ~72~5~18 ~72~5~30 minecraft:stone 0
fill ~75~6~18 ~75~6~21 minecraft:dirt 0
fill ~75~7~18 ~75~7~21 minecraft:grass
fill ~77~3~18 ~77~3~28 minecraft:stone 0
fill ~78~2~18 ~78~2~29 minecraft:stone 0
fill ~78~3~18 ~79~3~18 minecraft:dirt 0
fill ~78~4~18 ~78~4~20 minecraft:dirt 0
fill ~78~5~18 ~78~5~20 minecraft:grass
fill ~79~0~18 ~79~1~29 minecraft:stone 0
setblock ~79~2~18 minecraft:dirt 0
fill ~79~4~18 ~79~4~20 minecraft:grass
fill ~5~0~19 ~5~0~23 minecraft:grass
setblock ~5~1~19 minecraft:tallgrass 1
fill ~8~0~19 ~10~0~19 minecraft:grass
fill ~11~0~19 ~11~0~24 minecraft:dirt 0
fill ~11~1~19 ~11~1~22 minecraft:grass
setblock ~17~2~19 minecraft:grass
fill ~18~2~19 ~19~2~21 minecraft:dirt 0
fill ~18~3~19 ~19~3~20 minecraft:grass
fill ~20~1~19 ~21~1~31 minecraft:stone 0
fill ~20~3~19 ~21~3~19 minecraft:dirt 0
setblock ~20~4~19 minecraft:grass
fill ~21~2~19 ~22~2~32 minecraft:stone 0
fill ~21~4~19 ~22~4~19 minecraft:dirt 0
setblock ~21~5~19 minecraft:grass
fill ~22~3~19 ~23~3~26 minecraft:stone 0
setblock ~22~5~19 minecraft:dirt 0
setblock ~22~6~19 minecraft:grass
fill ~23~4~19 ~23~4~66 minecraft:stone 0
fill ~23~5~19 ~24~5~65 minecraft:stone 0
fill ~23~6~19 ~23~7~19 minecraft:dirt 0
setblock ~23~8~19 minecraft:grass
fill ~24~6~19 ~25~6~65 minecraft:stone 0
fill ~24~7~19 ~24~8~19 minecraft:dirt 0
setblock ~24~9~19 minecraft:grass
fill ~25~7~19 ~26~7~40 minecraft:stone 0
fill ~25~8~19 ~25~9~19 minecraft:dirt 0
setblock ~25~10~19 minecraft:grass
fill ~26~8~19 ~27~8~32 minecraft:stone 0
fill ~26~9~19 ~26~10~19 minecraft:dirt 0
setblock ~26~11~19 minecraft:grass
fill ~27~9~19 ~27~9~32 minecraft:stone 0
fill ~27~10~19 ~27~11~19 minecraft:dirt 0
setblock ~27~12~19 minecraft:grass
fill ~28~10~19 ~28~11~28 minecraft:stone 0
fill ~28~12~19 ~28~13~19 minecraft:dirt 0
setblock ~28~14~19 minecraft:grass
fill ~29~0~19 ~29~3~20 minecraft:stone 1
fill ~29~12~19 ~29~12~47 minecraft:stone 0
fill ~29~13~19 ~29~13~40 minecraft:stone 0
fill ~29~14~19 ~29~15~19 minecraft:dirt 0
setblock ~29~16~19 minecraft:grass
fill ~30~4~19 ~31~4~20 minecraft:stone 1
fill ~30~14~19 ~31~14~42 minecraft:stone 0
fill ~30~15~19 ~30~16~19 minecraft:dirt 0
setblock ~30~17~19 minecraft:grass
fill ~31~15~19 ~34~15~43 minecraft:stone 0
fill ~31~17~19 ~31~18~19 minecraft:dirt 0
fill ~31~19~19 ~34~19~19 minecraft:grass
fill ~32~5~19 ~35~5~20 minecraft:stone 1
fill ~32~6~19 ~32~6~25 minecraft:stone 0
fill ~32~18~19 ~34~18~20 minecraft:dirt 0
setblock ~34~20~19 minecraft:red_flower 8
fill ~36~5~19 ~39~5~21 minecraft:stone 0
setblock ~37~20~19 minecraft:red_flower 8
fill ~38~15~19 ~38~15~36 minecraft:stone 0
fill ~38~16~19 ~40~16~19 minecraft:dirt 0
fill ~39~14~19 ~39~14~34 minecraft:stone 0
setblock ~39~15~19 minecraft:dirt 0
fill ~39~18~19 ~42~18~19 minecraft:dirt 0
setblock ~39~19~19 minecraft:grass
fill ~40~15~19 ~41~15~33 minecraft:stone 0
fill ~40~17~19 ~41~17~19 minecraft:dirt 0
fill ~40~19~19 ~42~19~19 minecraft:dirt 0
setblock ~40~20~19 minecraft:grass
fill ~41~16~19 ~42~16~33 minecraft:stone 0
fill ~41~20~19 ~44~20~20 minecraft:dirt 0
fill ~41~21~19 ~42~21~19 minecraft:grass
fill ~42~4~19 ~42~4~20 minecraft:stone 0
setblock ~42~7~19 minecraft:stone 0
fill ~42~9~19 ~48~9~19 minecraft:stone 0
fill ~42~17~19 ~44~17~33 minecraft:stone 0
fill ~43~1~19 ~44~1~19 minecraft:stone 0
fill ~43~4~19 ~44~4~20 minecraft:dirt 0
fill ~43~7~19 ~44~7~20 minecraft:dirt 0
fill ~43~18~19 ~46~18~28 minecraft:stone 0
fill ~43~21~19 ~46~21~21 minecraft:dirt 0
fill ~43~22~19 ~46~22~19 minecraft:grass
setblock ~43~23~19 minecraft:red_flower 8
fill ~44~0~19 ~44~0~20 minecraft:dirt 0
fill ~44~8~19 ~46~8~19 minecraft:stone 0
fill ~45~1~19 ~48~1~19 minecraft:dirt 0
fill ~46~5~19 ~46~6~19 minecraft:dirt 0
fill ~46~7~19 ~48~7~19 minecraft:stone 0
fill ~47~5~19 ~48~5~21 minecraft:stone 0
fill ~47~6~19 ~48~6~19 minecraft:stone 0
fill ~47~8~19 ~49~8~20 minecraft:gravel
fill ~48~17~19 ~52~17~26 minecraft:stone 0
fill ~48~18~19 ~50~18~26 minecraft:stone 0
fill ~48~21~19 ~51~21~23 minecraft:dirt 0
fill ~48~22~19 ~51~22~19 minecraft:grass
fill ~49~7~19 ~50~7~20 minecraft:gravel
fill ~49~9~19 ~49~9~20 minecraft:gravel
setblock ~50~0~19 minecraft:dirt 0
fill ~50~3~19 ~50~3~26 minecraft:stone 0
fill ~51~0~19 ~53~0~67 minecraft:stone 0
fill ~51~2~19 ~51~3~19 minecraft:dirt 0
fill ~51~7~19 ~54~7~32 minecraft:stone 0
fill ~51~18~19 ~54~18~19 minecraft:dirt 0
fill ~52~16~19 ~53~16~44 minecraft:stone 0
fill ~52~20~19 ~52~20~22 minecraft:dirt 0
setblock ~52~21~19 minecraft:grass
fill ~53~19~19 ~53~19~22 minecraft:dirt 0
setblock ~53~20~19 minecraft:grass
fill ~54~0~19 ~55~0~19 minecraft:copper_ore
fill ~54~15~19 ~54~15~44 minecraft:stone 0
setblock ~54~19~19 minecraft:grass
fill ~55~1~19 ~56~1~20 minecraft:copper_ore
fill ~55~4~19 ~55~4~46 minecraft:stone 0
fill ~55~15~19 ~56~15~19 minecraft:dirt 0
fill ~55~18~19 ~56~18~19 minecraft:grass
fill ~56~19~19 ~56~19~20 minecraft:red_flower 8
fill ~59~13~19 ~59~13~39 minecraft:stone 0
setblock ~59~14~19 minecraft:stone 0
fill ~59~16~19 ~59~16~39 minecraft:dirt 0
fill ~59~17~19 ~59~17~27 minecraft:grass
fill ~60~14~19 ~60~14~24 minecraft:dirt 0
fill ~60~16~19 ~61~16~24 minecraft:grass
setblock ~63~16~19 minecraft:red_flower 8
fill ~67~8~19 ~67~8~33 minecraft:stone 0
fill ~67~10~19 ~67~10~23 minecraft:dirt 0
fill ~67~11~19 ~67~11~20 minecraft:grass
fill ~70~6~19 ~71~6~32 minecraft:stone 0
fill ~70~8~19 ~70~8~20 minecraft:dirt 0
fill ~70~9~19 ~70~9~20 minecraft:grass
fill ~71~8~19 ~73~8~19 minecraft:grass
fill ~72~7~19 ~73~7~20 minecraft:dirt 0
fill ~73~5~19 ~73~5~30 minecraft:stone 0
fill ~73~6~19 ~73~6~26 minecraft:stone 0
fill ~75~5~19 ~75~5~26 minecraft:stone 0
fill ~78~3~19 ~78~3~20 minecraft:stone 0
fill ~79~2~19 ~79~2~20 minecraft:stone 0
fill ~79~3~19 ~79~3~20 minecraft:dirt 0
fill ~0~0~20 ~1~0~25 minecraft:grass
fill ~6~0~20 ~6~0~22 minecraft:grass
fill ~8~0~20 ~9~0~20 minecraft:grass
fill ~10~0~20 ~10~0~24 minecraft:dirt 0
fill ~10~1~20 ~10~1~22 minecraft:grass
setblock ~12~1~20 minecraft:grass
fill ~13~0~20 ~13~0~21 minecraft:stone 0
fill ~13~1~20 ~13~1~29 minecraft:dirt 0
fill ~13~2~20 ~13~2~23 minecraft:grass
setblock ~15~0~20 minecraft:stone 0
setblock ~16~0~20 minecraft:dirt 0
fill ~17~0~20 ~18~0~52 minecraft:stone 0
fill ~17~2~20 ~17~2~23 minecraft:dirt 0
fill ~17~3~20 ~17~3~22 minecraft:grass
fill ~20~2~20 ~20~2~31 minecraft:stone 0
fill ~20~3~20 ~20~4~20 minecraft:dirt 0
setblock ~20~5~20 minecraft:grass
fill ~21~3~20 ~21~3~65 minecraft:stone 0
fill ~21~4~20 ~22~4~64 minecraft:stone 0
fill ~21~5~20 ~21~6~20 minecraft:dirt 0
setblock ~21~7~20 minecraft:grass
fill ~22~5~20 ~22~5~64 minecraft:stone 0
fill ~22~6~20 ~22~7~20 minecraft:dirt 0
setblock ~22~8~20 minecraft:grass
fill ~23~6~20 ~23~6~63 minecraft:stone 0
fill ~23~7~20 ~23~8~20 minecraft:dirt 0
setblock ~23~9~20 minecraft:grass
fill ~24~7~20 ~24~7~63 minecraft:stone 0
fill ~24~8~20 ~24~9~20 minecraft:dirt 0
setblock ~24~10~20 minecraft:grass
fill ~25~8~20 ~25~8~62 minecraft:stone 0
fill ~25~9~20 ~26~9~34 minecraft:stone 0
fill ~25~10~20 ~25~11~20 minecraft:dirt 0
setblock ~25~12~20 minecraft:grass
fill ~26~10~20 ~27~10~32 minecraft:stone 0
fill ~26~11~20 ~26~12~20 minecraft:dirt 0
setblock ~26~13~20 minecraft:grass
fill ~27~11~20 ~27~12~32 minecraft:stone 0
fill ~27~13~20 ~27~14~20 minecraft:dirt 0
setblock ~27~15~20 minecraft:grass
fill ~28~0~20 ~28~3~20 minecraft:stone 1
fill ~28~12~20 ~28~13~34 minecraft:stone 0
fill ~28~14~20 ~28~15~20 minecraft:dirt 0
setblock ~28~16~20 minecraft:grass
setblock ~29~4~20 minecraft:stone 1
fill ~29~14~20 ~29~14~40 minecraft:stone 0
fill ~29~15~20 ~29~16~20 minecraft:dirt 0
setblock ~29~17~20 minecraft:grass
fill ~30~5~20 ~31~5~20 minecraft:stone 1
fill ~30~15~20 ~30~15~42 minecraft:stone 0
fill ~30~16~20 ~30~18~20 minecraft:dirt 0
setblock ~30~19~20 minecraft:grass
fill ~31~16~20 ~40~16~33 minecraft:stone 0
fill ~31~17~20 ~38~17~36 minecraft:stone 0
fill ~31~18~20 ~31~20~20 minecraft:dirt 0
fill ~31~21~20 ~39~21~20 minecraft:grass
fill ~32~19~20 ~41~19~20 minecraft:dirt 0
fill ~32~20~20 ~40~20~21 minecraft:dirt 0
fill ~34~10~20 ~35~10~22 minecraft:stone 0
fill ~35~11~20 ~39~12~20 minecraft:dirt 0
fill ~36~10~20 ~39~10~20 minecraft:dirt 0
fill ~37~8~20 ~39~8~23 minecraft:stone 0
fill ~38~1~20 ~38~1~21 minecraft:stone 0
setblock ~38~2~20 minecraft:stone 0
fill ~38~7~20 ~39~7~23 minecraft:stone 0
fill ~39~15~20 ~39~15~33 minecraft:stone 0
fill ~39~17~20 ~39~18~20 minecraft:dirt 0
setblock ~39~22~20 minecraft:red_flower 8
fill ~40~7~20 ~42~8~20 minecraft:gravel
fill ~40~10~20 ~42~10~23 minecraft:stone 0
fill ~40~11~20 ~41~12~23 minecraft:stone 0
fill ~40~17~20 ~41~17~33 minecraft:stone 0
fill ~40~18~20 ~41~18~20 minecraft:dirt 0
fill ~40~21~20 ~42~21~21 minecraft:dirt 0
fill ~40~22~20 ~41~22~20 minecraft:grass
fill ~41~0~20 ~42~0~30 minecraft:stone 0
setblock ~41~23~20 minecraft:red_flower 8
fill ~42~9~20 ~45~9~23 minecraft:stone 0
fill ~42~18~20 ~42~18~33 minecraft:stone 0
fill ~42~19~20 ~49~19~20 minecraft:stone 0
fill ~42~22~20 ~49~22~24 minecraft:dirt 0
fill ~42~23~20 ~49~23~20 minecraft:grass
setblock ~42~24~20 minecraft:red_flower 8
setblock ~43~0~20 minecraft:dirt 0
fill ~43~1~20 ~43~1~22 minecraft:stone 0
fill ~43~8~20 ~45~8~23 minecraft:stone 0
fill ~44~1~20 ~47~1~20 minecraft:dirt 0
fill ~44~11~20 ~48~11~20 minecraft:stone 0
fill ~46~5~20 ~46~6~21 minecraft:stone 0
fill ~46~7~20 ~48~7~20 minecraft:gravel
fill ~46~8~20 ~46~9~20 minecraft:gravel
setblock ~46~24~20 minecraft:red_flower 8
fill ~47~6~20 ~47~6~25 minecraft:stone 0
fill ~47~9~20 ~48~9~20 minecraft:gravel
fill ~48~1~20 ~48~1~21 minecraft:stone 0
setblock ~48~6~20 minecraft:gravel
fill ~48~10~20 ~49~10~20 minecraft:gravel
setblock ~49~11~20 minecraft:dirt 0
fill ~50~0~20 ~50~0~71 minecraft:stone 0
fill ~50~10~20 ~58~10~22 minecraft:stone 0
fill ~50~22~20 ~52~22~20 minecraft:grass
fill ~51~2~20 ~51~3~26 minecraft:stone 0
fill ~51~18~20 ~52~18~48 minecraft:stone 0
fill ~52~21~20 ~52~21~24 minecraft:dirt 0
fill ~53~17~20 ~53~17~45 minecraft:stone 0
fill ~53~18~20 ~55~18~20 minecraft:dirt 0
fill ~53~20~20 ~53~20~23 minecraft:dirt 0
setblock ~53~21~20 minecraft:grass
setblock ~53~22~20 minecraft:red_flower 8
fill ~54~0~20 ~55~0~20 minecraft:stone 0
fill ~54~16~20 ~54~16~44 minecraft:stone 0
setblock ~54~17~20 minecraft:dirt 0
fill ~54~19~20 ~54~19~22 minecraft:dirt 0
setblock ~54~20~20 minecraft:grass
setblock ~54~21~20 minecraft:red_flower 8
fill ~55~15~20 ~55~15~46 minecraft:stone 0
setblock ~55~19~20 minecraft:grass
setblock ~55~20~20 minecraft:red_flower 8
fill ~56~2~20 ~57~2~20 minecraft:copper_ore
fill ~56~3~20 ~57~3~52 minecraft:stone 0
fill ~56~15~20 ~56~15~21 minecraft:dirt 0
fill ~56~18~20 ~56~18~21 minecraft:grass
setblock ~57~1~20 minecraft:copper_ore
fill ~57~4~20 ~57~4~49 minecraft:stone 0
fill ~58~3~20 ~58~4~21 minecraft:coal_ore
fill ~59~14~20 ~59~14~23 minecraft:dirt 0
setblock ~59~18~20 minecraft:red_flower 8
fill ~62~15~20 ~62~15~24 minecraft:grass
fill ~63~12~20 ~63~12~22 minecraft:dirt 0
fill ~63~14~20 ~63~14~22 minecraft:grass
setblock ~65~14~20 minecraft:red_flower 8
setblock ~68~11~20 minecraft:double_plant 2
fill ~69~7~20 ~71~7~28 minecraft:stone 0
fill ~69~9~20 ~69~9~21 minecraft:dirt 0
fill ~69~10~20 ~69~10~21 minecraft:grass
fill ~71~8~20 ~71~8~21 minecraft:dirt 0
fill ~71~9~20 ~71~9~21 minecraft:grass
fill ~72~6~20 ~72~6~31 minecraft:stone 0
fill ~72~8~20 ~74~8~20 minecraft:grass
fill ~74~6~20 ~74~6~27 minecraft:stone 0
fill ~74~7~20 ~74~7~27 minecraft:dirt 0
fill ~7~0~21 ~8~0~21 minecraft:grass
fill ~9~0~21 ~9~0~25 minecraft:dirt 0
fill ~9~1~21 ~9~1~22 minecraft:grass
setblock ~12~0~21 minecraft:stone 0
fill ~12~1~21 ~12~1~29 minecraft:dirt 0
fill ~12~2~21 ~12~2~23 minecraft:grass
fill ~14~0~21 ~15~0~22 minecraft:dirt 0
fill ~16~0~21 ~16~0~64 minecraft:stone 0
fill ~16~2~21 ~16~2~24 minecraft:dirt 0
fill ~16~3~21 ~16~3~23 minecraft:grass
setblock ~18~3~21 minecraft:grass
fill ~19~1~21 ~19~1~31 minecraft:stone 0
fill ~19~3~21 ~19~3~22 minecraft:dirt 0
setblock ~19~4~21 minecraft:grass
fill ~20~3~21 ~20~3~55 minecraft:stone 0
fill ~20~4~21 ~20~5~21 minecraft:dirt 0
setblock ~20~6~21 minecraft:grass
fill ~21~5~21 ~21~5~56 minecraft:stone 0
fill ~21~6~21 ~21~7~21 minecraft:dirt 0
setblock ~21~8~21 minecraft:grass
fill ~22~6~21 ~22~6~57 minecraft:stone 0
fill ~22~7~21 ~22~8~21 minecraft:dirt 0
setblock ~22~9~21 minecraft:grass
fill ~23~7~21 ~23~7~57 minecraft:stone 0
fill ~23~8~21 ~23~9~22 minecraft:dirt 0
fill ~23~10~21 ~23~10~22 minecraft:grass
fill ~24~8~21 ~24~8~58 minecraft:stone 0
fill ~24~9~21 ~24~10~21 minecraft:dirt 0
setblock ~24~11~21 minecraft:grass
fill ~25~10~21 ~25~10~57 minecraft:stone 0
fill ~25~11~21 ~26~11~37 minecraft:stone 0
fill ~25~12~21 ~25~13~21 minecraft:dirt 0
setblock ~25~14~21 minecraft:grass
fill ~26~12~21 ~26~12~37 minecraft:stone 0
fill ~27~13~21 ~27~13~40 minecraft:stone 0
fill ~27~14~21 ~27~15~21 minecraft:dirt 0
setblock ~27~16~21 minecraft:grass
fill ~28~0~21 ~37~0~25 minecraft:stone 0
fill ~28~1~21 ~37~1~21 minecraft:stone 0
fill ~28~2~21 ~31~3~21 minecraft:stone 0
fill ~28~14~21 ~28~14~40 minecraft:stone 0
fill ~28~15~21 ~29~15~35 minecraft:stone 0
fill ~28~16~21 ~28~17~21 minecraft:dirt 0
setblock ~28~18~21 minecraft:grass
fill ~29~4~21 ~31~4~21 minecraft:stone 0
fill ~29~16~21 ~30~16~40 minecraft:stone 0
fill ~29~17~21 ~29~18~21 minecraft:dirt 0
setblock ~29~19~21 minecraft:grass
fill ~30~5~21 ~35~5~21 minecraft:stone 0
fill ~30~17~21 ~30~17~55 minecraft:stone 0
fill ~30~18~21 ~41~18~33 minecraft:stone 0
fill ~30~19~21 ~30~20~21 minecraft:dirt 0
setblock ~30~21~21 minecraft:grass
fill ~31~19~21 ~37~19~37 minecraft:stone 0
fill ~31~20~21 ~31~22~21 minecraft:dirt 0
fill ~31~23~21 ~40~23~21 minecraft:grass
setblock ~32~2~21 minecraft:stone 6
setblock ~32~3~21 minecraft:stone 0
setblock ~32~4~21 minecraft:stone 6
fill ~32~13~21 ~35~13~37 minecraft:stone 0
fill ~32~21~21 ~39~22~22 minecraft:dirt 0
setblock ~32~24~21 minecraft:red_flower 8
setblock ~33~2~21 minecraft:stone 0
setblock ~33~3~21 minecraft:stone 6
setblock ~33~4~21 minecraft:stone 0
setblock ~34~2~21 minecraft:stone 6
setblock ~34~3~21 minecraft:stone 0
setblock ~34~4~21 minecraft:stone 6
setblock ~35~2~21 minecraft:stone 0
setblock ~35~3~21 minecraft:stone 6
setblock ~35~4~21 minecraft:stone 0
fill ~35~11~21 ~39~12~23 minecraft:stone 0
setblock ~35~24~21 minecraft:red_flower 8
setblock ~36~2~21 minecraft:stone 6
fill ~36~3~21 ~38~3~21 minecraft:stone 0
setblock ~36~4~21 minecraft:stone 6
fill ~36~10~21 ~39~10~23 minecraft:stone 0
fill ~36~13~21 ~39~13~21 minecraft:dirt 0
setblock ~37~2~21 minecraft:stone 0
setblock ~37~4~21 minecraft:stone 0
fill ~37~14~21 ~37~14~37 minecraft:stone 0
setblock ~38~2~21 minecraft:stone 6
setblock ~38~4~21 minecraft:stone 6
fill ~38~19~21 ~40~19~21 minecraft:dirt 0
setblock ~39~3~21 minecraft:stone 6
setblock ~39~4~21 minecraft:stone 0
fill ~39~17~21 ~39~17~33 minecraft:stone 0
setblock ~40~2~21 minecraft:stone 6
setblock ~40~3~21 minecraft:stone 0
setblock ~40~4~21 minecraft:stone 6
fill ~40~7~21 ~50~7~23 minecraft:stone 0
fill ~40~8~21 ~42~8~23 minecraft:stone 0
fill ~40~22~21 ~41~22~24 minecraft:dirt 0
setblock ~41~2~21 minecraft:stone 0
setblock ~41~3~21 minecraft:stone 6
setblock ~41~4~21 minecraft:stone 0
fill ~41~19~21 ~48~19~26 minecraft:stone 0
setblock ~41~20~21 minecraft:stone 0
fill ~41~23~21 ~46~23~27 minecraft:dirt 0
fill ~41~24~21 ~46~24~21 minecraft:grass
setblock ~42~2~21 minecraft:stone 6
fill ~42~3~21 ~44~3~21 minecraft:stone 0
setblock ~42~4~21 minecraft:stone 6
fill ~42~5~21 ~45~6~21 minecraft:stone 0
setblock ~42~20~21 minecraft:dirt 0
fill ~43~0~21 ~49~0~22 minecraft:stone 0
setblock ~43~2~21 minecraft:stone 0
setblock ~43~4~21 minecraft:stone 0
fill ~43~20~21 ~46~20~26 minecraft:stone 0
fill ~44~1~21 ~47~1~21 minecraft:stone 0
setblock ~44~2~21 minecraft:stone 6
setblock ~44~4~21 minecraft:stone 6
fill ~44~11~21 ~46~11~23 minecraft:stone 0
setblock ~45~2~21 minecraft:stone 0
setblock ~45~3~21 minecraft:stone 6
setblock ~45~4~21 minecraft:stone 0
setblock ~46~2~21 minecraft:stone 6
setblock ~46~3~21 minecraft:stone 0
setblock ~46~4~21 minecraft:stone 6
fill ~46~8~21 ~51~9~22 minecraft:stone 0
setblock ~47~3~21 minecraft:stone 6
setblock ~47~4~21 minecraft:stone 0
fill ~47~11~21 ~49~12~21 minecraft:coal_ore
fill ~47~20~21 ~51~20~21 minecraft:dirt 0
fill ~47~23~21 ~51~23~21 minecraft:grass
setblock ~48~2~21 minecraft:stone 6
setblock ~48~3~21 minecraft:stone 0
setblock ~48~4~21 minecraft:stone 6
fill ~48~6~21 ~48~6~25 minecraft:stone 0
fill ~48~10~21 ~49~10~22 minecraft:stone 0
fill ~49~19~21 ~51~19~21 minecraft:copper_ore
fill ~50~12~21 ~54~12~22 minecraft:stone 0
fill ~50~22~21 ~51~22~25 minecraft:dirt 0
setblock ~51~24~21 minecraft:red_flower 8
fill ~52~1~21 ~52~1~65 minecraft:stone 0
fill ~52~2~21 ~52~2~63 minecraft:stone 0
fill ~52~3~21 ~54~3~21 minecraft:sponge 0
fill ~52~4~21 ~52~4~24 minecraft:stone 0
setblock ~52~19~21 minecraft:dirt 0
fill ~52~22~21 ~53~22~21 minecraft:grass
setblock ~52~23~21 minecraft:red_flower 8
fill ~53~1~21 ~55~1~21 minecraft:sponge 0
fill ~53~2~21 ~54~2~22 minecraft:sponge 0
setblock ~53~4~21 minecraft:sponge 0
fill ~53~18~21 ~53~18~47 minecraft:stone 0
fill ~53~21~21 ~53~21~24 minecraft:dirt 0
fill ~54~4~21 ~54~4~46 minecraft:stone 0
fill ~54~17~21 ~54~17~45 minecraft:stone 0
fill ~54~18~21 ~55~18~21 minecraft:dirt 0
fill ~54~20~21 ~54~20~23 minecraft:dirt 0
setblock ~54~21~21 minecraft:grass
setblock ~55~0~21 minecraft:stone 0
fill ~55~2~21 ~57~2~21 minecraft:stone 0
fill ~55~3~21 ~55~3~23 minecraft:stone 0
fill ~55~16~21 ~55~16~40 minecraft:stone 0
fill ~55~19~21 ~55~19~23 minecraft:dirt 0
setblock ~55~20~21 minecraft:grass
setblock ~55~21~21 minecraft:red_flower 8
fill ~56~1~21 ~57~1~54 minecraft:stone 0
fill ~56~16~21 ~56~16~22 minecraft:dirt 0
setblock ~58~18~21 minecraft:red_flower 8
fill ~66~10~21 ~66~10~31 minecraft:stone 0
fill ~66~12~21 ~66~12~31 minecraft:dirt 0
fill ~66~13~21 ~66~13~24 minecraft:grass
fill ~67~9~21 ~68~9~30 minecraft:stone 0
fill ~67~11~21 ~67~11~24 minecraft:dirt 0
fill ~67~12~21 ~67~12~23 minecraft:grass
fill ~68~8~21 ~70~8~26 minecraft:stone 0
setblock ~68~10~21 minecraft:dirt 0
setblock ~68~11~21 minecraft:grass
fill ~69~3~21 ~70~3~24 minecraft:coal_ore
fill ~69~4~21 ~70~4~22 minecraft:coal_ore
fill ~70~9~21 ~70~9~22 minecraft:dirt 0
fill ~70~10~21 ~70~10~22 minecraft:grass
fill ~72~7~21 ~72~7~26 minecraft:stone 0
fill ~72~8~21 ~72~8~30 minecraft:dirt 0
fill ~72~9~21 ~72~9~30 minecraft:grass
setblock ~73~7~21 minecraft:dirt 0
fill ~73~8~21 ~74~8~21 minecraft:grass
fill ~78~3~21 ~78~3~22 minecraft:dirt 0
fill ~78~4~21 ~78~4~22 minecraft:grass
fill ~79~2~21 ~79~2~22 minecraft:dirt 0
fill ~79~3~21 ~79~3~22 minecraft:grass
setblock ~7~0~22 minecraft:grass
fill ~8~0~22 ~8~0~27 minecraft:dirt 0
fill ~8~1~22 ~8~1~23 minecraft:grass
fill ~12~0~22 ~13~0~23 minecraft:dirt 0
setblock ~17~1~22 minecraft:dirt 0
fill ~18~1~22 ~18~1~31 minecraft:stone 0
fill ~18~2~22 ~18~3~22 minecraft:dirt 0
setblock ~18~4~22 minecraft:grass
fill ~19~2~22 ~19~2~31 minecraft:stone 0
setblock ~19~4~22 minecraft:dirt 0
setblock ~19~5~22 minecraft:grass
fill ~20~4~22 ~20~4~59 minecraft:stone 0
fill ~20~5~22 ~20~6~22 minecraft:dirt 0
setblock ~20~7~22 minecraft:grass
fill ~21~6~22 ~21~6~55 minecraft:stone 0
fill ~21~7~22 ~21~8~23 minecraft:dirt 0
fill ~21~9~22 ~21~9~23 minecraft:grass
fill ~22~7~22 ~22~7~57 minecraft:stone 0
fill ~22~8~22 ~22~9~23 minecraft:dirt 0
fill ~22~10~22 ~22~10~23 minecraft:grass
fill ~24~9~22 ~24~9~57 minecraft:stone 0
fill ~24~10~22 ~24~10~55 minecraft:stone 0
fill ~24~11~22 ~24~12~27 minecraft:dirt 0
fill ~24~13~22 ~24~13~24 minecraft:grass
fill ~25~12~22 ~25~12~55 minecraft:stone 0
fill ~25~13~22 ~25~14~23 minecraft:dirt 0
fill ~25~15~22 ~25~15~23 minecraft:grass
setblock ~26~4~22 minecraft:stone 0
fill ~26~13~22 ~26~14~40 minecraft:stone 0
fill ~26~15~22 ~26~16~24 minecraft:dirt 0
fill ~26~17~22 ~26~17~23 minecraft:grass
fill ~27~4~22 ~27~4~23 minecraft:copper_ore
fill ~27~14~22 ~27~14~55 minecraft:stone 0
fill ~27~15~22 ~27~15~34 minecraft:stone 0
fill ~27~16~22 ~27~17~24 minecraft:dirt 0
fill ~27~18~22 ~27~18~23 minecraft:grass
fill ~28~1~22 ~31~1~22 minecraft:stone 0
fill ~28~2~22 ~30~3~26 minecraft:stone 0
fill ~28~16~22 ~28~16~38 minecraft:stone 0
fill ~28~17~22 ~28~18~22 minecraft:dirt 0
setblock ~28~19~22 minecraft:grass
fill ~29~4~22 ~30~4~26 minecraft:stone 0
fill ~29~17~22 ~29~18~53 minecraft:stone 0
fill ~29~19~22 ~29~20~22 minecraft:dirt 0
setblock ~29~21~22 minecraft:grass
fill ~30~5~22 ~30~5~26 minecraft:stone 0
fill ~30~19~22 ~30~19~53 minecraft:stone 0
fill ~30~20~22 ~39~20~33 minecraft:stone 0
fill ~30~21~22 ~31~22~22 minecraft:dirt 0
setblock ~30~23~22 minecraft:grass
setblock ~30~24~22 minecraft:red_flower 8
setblock ~31~2~22 minecraft:wood 1
fill ~31~3~22 ~31~4~22 minecraft:wood 1
setblock ~31~5~22 minecraft:wood 1
fill ~31~23~22 ~40~23~23 minecraft:dirt 0
fill ~31~24~22 ~41~24~22 minecraft:grass
setblock ~32~1~22 minecraft:grass
setblock ~32~2~22 minecraft:tallgrass 1
fill ~32~3~22 ~36~3~44 minecraft:sponge 0
fill ~32~4~22 ~33~4~22 minecraft:spruce_trapdoor 2
fill ~32~5~22 ~36~5~22 minecraft:barrel 3
fill ~32~25~22 ~33~25~22 minecraft:red_flower 8
fill ~33~1~22 ~35~1~23 minecraft:dirt 0
fill ~33~2~22 ~35~2~23 minecraft:sponge 0
setblock ~34~4~22 minecraft:wooden_slab 9
setblock ~35~4~22 minecraft:spruce_trapdoor 2
setblock ~36~1~22 minecraft:grass
setblock ~36~2~22 minecraft:tallgrass 1
setblock ~36~4~22 minecraft:spruce_trapdoor 1
fill ~36~13~22 ~36~13~38 minecraft:stone 0
setblock ~37~1~22 minecraft:stone 0
setblock ~37~2~22 minecraft:wood 1
fill ~37~3~22 ~37~5~22 minecraft:wood 1
fill ~37~13~22 ~40~13~22 minecraft:dirt 0
fill ~37~25~22 ~38~25~22 minecraft:red_flower 8
setblock ~38~1~22 minecraft:grass
setblock ~38~2~22 minecraft:tallgrass 1
fill ~38~3~22 ~42~3~33 minecraft:sponge 0
fill ~38~4~22 ~39~4~22 minecraft:spruce_trapdoor 2
fill ~38~5~22 ~42~5~22 minecraft:barrel 3
fill ~38~19~22 ~40~19~33 minecraft:stone 0
fill ~39~1~22 ~41~1~22 minecraft:dirt 0
fill ~39~2~22 ~41~2~22 minecraft:sponge 0
setblock ~40~4~22 minecraft:wooden_slab 9
fill ~40~20~22 ~41~21~22 minecraft:dirt 0
setblock ~41~4~22 minecraft:spruce_trapdoor 2
setblock ~42~1~22 minecraft:grass
setblock ~42~2~22 minecraft:tallgrass 1
setblock ~42~4~22 minecraft:spruce_trapdoor 1
fill ~42~6~22 ~46~6~25 minecraft:stone 0
fill ~42~20~22 ~42~21~26 minecraft:stone 0
fill ~42~24~22 ~44~24~30 minecraft:dirt 0
fill ~42~25~22 ~44~25~24 minecraft:grass
fill ~43~2~22 ~43~3~22 minecraft:wood 1
setblock ~43~4~22 minecraft:wood 1
setblock ~43~5~22 minecraft:wood 1
fill ~43~21~22 ~44~21~26 minecraft:stone 0
fill ~44~1~22 ~48~1~22 minecraft:dirt 0
fill ~44~2~22 ~48~3~22 minecraft:sponge 0
fill ~44~4~22 ~45~4~22 minecraft:spruce_trapdoor 2
fill ~44~5~22 ~48~5~22 minecraft:barrel 3
fill ~44~12~22 ~45~12~47 minecraft:stone 0
fill ~45~21~22 ~46~21~22 minecraft:dirt 0
fill ~45~24~22 ~50~24~22 minecraft:grass
setblock ~46~4~22 minecraft:wooden_slab 9
fill ~46~12~22 ~48~12~22 minecraft:coal_ore
setblock ~47~4~22 minecraft:spruce_trapdoor 2
fill ~47~11~22 ~48~11~22 minecraft:coal_ore
fill ~47~20~22 ~49~20~28 minecraft:stone 0
fill ~47~23~22 ~50~23~27 minecraft:dirt 0
setblock ~47~25~22 minecraft:red_flower 8
setblock ~48~4~22 minecraft:spruce_trapdoor 1
fill ~49~11~22 ~49~12~22 minecraft:stone 0
fill ~49~19~22 ~49~19~48 minecraft:stone 0
fill ~49~25~22 ~49~25~23 minecraft:red_flower 8
fill ~50~19~22 ~52~19~22 minecraft:copper_ore
setblock ~50~20~22 minecraft:copper_ore
setblock ~51~20~22 minecraft:dirt 0
fill ~51~23~22 ~52~23~22 minecraft:grass
fill ~52~3~22 ~52~3~62 minecraft:stone 0
fill ~52~22~22 ~52~22~27 minecraft:dirt 0
setblock ~52~24~22 minecraft:red_flower 8
fill ~53~1~22 ~53~1~63 minecraft:stone 0
fill ~53~3~22 ~54~3~22 minecraft:sponge 0
fill ~53~4~22 ~53~4~24 minecraft:stone 0
fill ~53~22~22 ~54~22~22 minecraft:grass
fill ~54~1~22 ~55~1~23 minecraft:sponge 0
fill ~54~18~22 ~54~18~45 minecraft:stone 0
fill ~54~21~22 ~54~21~25 minecraft:dirt 0
fill ~55~2~22 ~55~2~24 minecraft:sponge 0
fill ~55~17~22 ~55~17~43 minecraft:stone 0
fill ~55~18~22 ~56~18~22 minecraft:dirt 0
fill ~55~20~22 ~55~20~24 minecraft:dirt 0
setblock ~55~21~22 minecraft:grass
setblock ~55~22~22 minecraft:red_flower 8
fill ~56~2~22 ~57~2~53 minecraft:stone 0
fill ~56~15~22 ~56~15~43 minecraft:stone 0
setblock ~56~17~22 minecraft:dirt 0
setblock ~56~19~22 minecraft:grass
fill ~58~3~22 ~58~3~52 minecraft:stone 0
fill ~58~4~22 ~58~4~48 minecraft:stone 0
setblock ~59~18~22 minecraft:red_flower 8
setblock ~63~15~22 minecraft:red_flower 8
setblock ~65~14~22 minecraft:double_plant 2
fill ~68~10~22 ~68~10~25 minecraft:stone 0
fill ~68~11~22 ~68~11~30 minecraft:dirt 0
fill ~68~12~22 ~68~12~30 minecraft:grass
fill ~69~9~22 ~69~9~24 minecraft:stone 0
fill ~69~10~22 ~69~10~25 minecraft:dirt 0
fill ~69~11~22 ~69~11~25 minecraft:grass
fill ~71~8~22 ~71~8~25 minecraft:stone 0
fill ~71~9~22 ~71~9~28 minecraft:dirt 0
fill ~71~10~22 ~71~10~28 minecraft:grass
fill ~73~7~22 ~73~7~26 minecraft:stone 0
fill ~73~8~22 ~73~8~26 minecraft:dirt 0
fill ~73~9~22 ~73~9~26 minecraft:grass
fill ~74~8~22 ~75~8~22 minecraft:grass
setblock ~75~6~22 minecraft:stone 0
setblock ~75~7~22 minecraft:dirt 0
setblock ~76~5~22 minecraft:stone 0
setblock ~76~6~22 minecraft:dirt 0
setblock ~76~7~22 minecraft:grass
fill ~77~4~22 ~77~4~26 minecraft:stone 0
fill ~77~5~22 ~77~5~26 minecraft:dirt 0
fill ~77~6~22 ~77~6~26 minecraft:grass
setblock ~4~0~23 minecraft:dirt 0
setblock ~5~1~23 minecraft:tallgrass 1
fill ~6~0~23 ~7~0~30 minecraft:dirt 0
fill ~6~1~23 ~7~1~24 minecraft:grass
fill ~9~1~23 ~11~1~29 minecraft:dirt 0
fill ~9~2~23 ~11~2~24 minecraft:grass
fill ~14~0~23 ~15~0~63 minecraft:stone 0
fill ~14~2~23 ~15~2~31 minecraft:dirt 0
fill ~14~3~23 ~15~3~27 minecraft:grass
fill ~17~1~23 ~17~1~31 minecraft:stone 0
fill ~17~3~23 ~17~3~24 minecraft:dirt 0
setblock ~17~4~23 minecraft:grass
fill ~18~2~23 ~18~3~31 minecraft:stone 0
fill ~18~4~23 ~18~5~23 minecraft:dirt 0
setblock ~18~6~23 minecraft:grass
fill ~19~3~23 ~19~4~55 minecraft:stone 0
fill ~19~5~23 ~19~6~23 minecraft:dirt 0
setblock ~19~7~23 minecraft:grass
fill ~20~5~23 ~20~5~30 minecraft:stone 0
fill ~20~6~23 ~20~7~23 minecraft:dirt 0
setblock ~20~8~23 minecraft:grass
fill ~23~8~23 ~23~8~57 minecraft:stone 0
fill ~23~9~23 ~23~10~25 minecraft:dirt 0
fill ~23~11~23 ~23~11~24 minecraft:grass
fill ~25~1~23 ~25~2~29 minecraft:stone 1
setblock ~25~3~23 minecraft:stone 0
fill ~26~1~23 ~30~1~27 minecraft:stone 0
setblock ~26~4~23 minecraft:copper_ore
fill ~28~17~23 ~28~17~52 minecraft:stone 0
fill ~28~18~23 ~28~18~27 minecraft:stone 0
fill ~28~19~23 ~28~20~23 minecraft:dirt 0
setblock ~28~21~23 minecraft:grass
fill ~29~19~23 ~29~19~43 minecraft:stone 0
fill ~29~20~23 ~29~20~41 minecraft:stone 0
fill ~29~21~23 ~29~22~23 minecraft:dirt 0
setblock ~29~23~23 minecraft:grass
fill ~30~21~23 ~41~21~26 minecraft:stone 0
fill ~30~22~23 ~39~22~23 minecraft:dirt 0
fill ~30~23~23 ~30~23~25 minecraft:dirt 0
setblock ~30~24~23 minecraft:grass
fill ~31~1~23 ~32~1~24 minecraft:dirt 0
fill ~31~2~23 ~32~2~24 minecraft:sponge 0
fill ~31~3~23 ~31~5~25 minecraft:sponge 0
fill ~31~24~23 ~41~24~31 minecraft:dirt 0
fill ~31~25~23 ~41~25~23 minecraft:grass
fill ~32~4~23 ~48~5~25 minecraft:sponge 0
setblock ~33~7~23 minecraft:stone_block_slab4 2
setblock ~33~9~23 minecraft:stone_block_slab4 2
setblock ~33~10~23 minecraft:stone 0
setblock ~34~8~23 minecraft:lantern 0
setblock ~34~10~23 minecraft:lantern 0
fill ~35~8~23 ~36~8~23 minecraft:stone 0
setblock ~35~10~23 minecraft:stone 0
fill ~36~1~23 ~39~1~23 minecraft:dirt 0
fill ~36~2~23 ~36~2~25 minecraft:sponge 0
setblock ~36~26~23 minecraft:red_flower 8
setblock ~37~2~23 minecraft:fence 1
fill ~37~3~23 ~37~3~25 minecraft:sponge 0
fill ~37~13~23 ~37~13~38 minecraft:stone 0
fill ~38~2~23 ~39~2~23 minecraft:sponge 0
fill ~38~13~23 ~41~13~23 minecraft:dirt 0
setblock ~39~26~23 minecraft:red_flower 8
fill ~40~1~23 ~40~1~25 minecraft:grass
setblock ~40~2~23 minecraft:tallgrass 1
fill ~40~20~23 ~41~20~26 minecraft:stone 0
fill ~41~1~23 ~47~1~25 minecraft:dirt 0
fill ~41~2~23 ~42~2~25 minecraft:sponge 0
fill ~42~13~23 ~42~13~36 minecraft:stone 0
fill ~43~0~23 ~44~0~23 minecraft:stone 0
setblock ~43~2~23 minecraft:fence 1
fill ~43~3~23 ~48~3~25 minecraft:sponge 0
setblock ~43~26~23 minecraft:red_flower 8
fill ~44~2~23 ~47~2~25 minecraft:sponge 0
fill ~45~0~23 ~45~0~25 minecraft:coal_ore
fill ~45~21~23 ~47~21~27 minecraft:stone 0
fill ~45~24~23 ~47~24~29 minecraft:dirt 0
fill ~45~25~23 ~47~25~24 minecraft:grass
fill ~46~0~23 ~49~0~23 minecraft:stone 0
fill ~46~8~23 ~48~8~23 minecraft:stone 0
fill ~46~9~23 ~47~9~23 minecraft:stone 0
fill ~46~12~23 ~47~12~23 minecraft:coal_ore
setblock ~47~11~23 minecraft:stone 0
setblock ~48~1~23 minecraft:grass
setblock ~48~2~23 minecraft:tallgrass 1
fill ~48~9~23 ~50~12~23 minecraft:sponge 0
fill ~48~24~23 ~52~24~23 minecraft:grass
setblock ~49~8~23 minecraft:sponge 0
fill ~50~8~23 ~51~8~26 minecraft:stone 0
fill ~50~19~23 ~54~19~44 minecraft:stone 0
fill ~50~20~23 ~52~20~47 minecraft:stone 0
setblock ~50~25~23 minecraft:red_flower 8
fill ~51~9~23 ~51~10~27 minecraft:stone 0
setblock ~51~11~23 minecraft:sponge 0
fill ~51~12~23 ~54~12~41 minecraft:stone 0
fill ~51~23~23 ~52~23~28 minecraft:dirt 0
fill ~52~10~23 ~58~10~32 minecraft:stone 0
fill ~52~11~23 ~53~11~32 minecraft:stone 0
fill ~53~2~23 ~53~3~49 minecraft:stone 0
fill ~53~22~23 ~54~22~27 minecraft:dirt 0
fill ~53~23~23 ~54~23~23 minecraft:grass
fill ~53~24~23 ~54~24~23 minecraft:red_flower 8
fill ~54~0~23 ~54~0~66 minecraft:stone 0
fill ~54~2~23 ~54~3~23 minecraft:sponge 0
fill ~55~18~23 ~55~18~43 minecraft:stone 0
fill ~55~21~23 ~55~21~25 minecraft:dirt 0
setblock ~55~22~23 minecraft:grass
fill ~56~16~23 ~56~17~39 minecraft:stone 0
fill ~56~18~23 ~56~20~23 minecraft:dirt 0
setblock ~56~21~23 minecraft:grass
setblock ~56~22~23 minecraft:red_flower 8
fill ~57~14~23 ~57~14~39 minecraft:stone 0
fill ~57~17~23 ~57~17~24 minecraft:dirt 0
setblock ~57~18~23 minecraft:grass
setblock ~58~14~23 minecraft:dirt 0
setblock ~60~13~23 minecraft:dirt 0
setblock ~61~17~23 minecraft:red_flower 8
fill ~63~12~23 ~63~12~31 minecraft:stone 0
fill ~63~14~23 ~63~14~31 minecraft:dirt 0
fill ~63~15~23 ~63~15~25 minecraft:grass
fill ~65~11~23 ~65~11~31 minecraft:stone 0
fill ~65~13~23 ~65~13~31 minecraft:dirt 0
fill ~65~14~23 ~65~14~25 minecraft:grass
fill ~66~11~23 ~66~11~24 minecraft:dirt 0
fill ~69~2~23 ~70~2~23 minecraft:coal_ore
fill ~69~4~23 ~70~4~38 minecraft:stone 0
fill ~70~9~23 ~70~9~25 minecraft:stone 0
fill ~70~10~23 ~70~10~26 minecraft:dirt 0
fill ~70~11~23 ~70~11~26 minecraft:grass
fill ~71~2~23 ~71~2~39 minecraft:stone 0
fill ~74~8~23 ~74~8~27 minecraft:grass
fill ~75~6~23 ~75~6~26 minecraft:dirt 0
fill ~75~7~23 ~75~7~26 minecraft:grass
fill ~76~5~23 ~76~5~27 minecraft:dirt 0
fill ~76~6~23 ~76~6~27 minecraft:grass
fill ~78~3~23 ~78~3~28 minecraft:stone 0
fill ~78~4~23 ~78~4~28 minecraft:dirt 0
fill ~78~5~23 ~78~5~28 minecraft:grass
fill ~79~2~23 ~79~2~28 minecraft:stone 0
fill ~79~3~23 ~79~3~24 minecraft:dirt 0
fill ~79~4~23 ~79~4~24 minecraft:grass
setblock ~4~0~24 minecraft:grass
fill ~5~0~24 ~5~0~33 minecraft:dirt 0
fill ~5~1~24 ~5~1~27 minecraft:grass
fill ~8~1~24 ~8~1~32 minecraft:dirt 0
fill ~8~2~24 ~8~2~27 minecraft:grass
fill ~12~0~24 ~13~0~64 minecraft:stone 0
fill ~12~2~24 ~13~2~31 minecraft:dirt 0
fill ~12~3~24 ~13~3~29 minecraft:grass
fill ~16~1~24 ~16~1~31 minecraft:stone 0
fill ~16~3~24 ~16~3~25 minecraft:dirt 0
setblock ~16~4~24 minecraft:grass
fill ~17~2~24 ~17~2~31 minecraft:stone 0
fill ~17~4~24 ~17~4~25 minecraft:dirt 0
setblock ~17~5~24 minecraft:grass
fill ~18~4~24 ~18~4~29 minecraft:stone 0
fill ~18~5~24 ~18~6~24 minecraft:dirt 0
setblock ~18~7~24 minecraft:grass
fill ~19~5~24 ~19~5~29 minecraft:stone 0
fill ~19~6~24 ~19~7~25 minecraft:dirt 0
fill ~19~8~24 ~19~8~25 minecraft:grass
fill ~20~6~24 ~20~6~29 minecraft:stone 0
fill ~20~7~24 ~20~8~24 minecraft:dirt 0
setblock ~20~9~24 minecraft:grass
fill ~21~7~24 ~21~7~28 minecraft:stone 0
fill ~21~8~24 ~21~9~25 minecraft:dirt 0
fill ~21~10~24 ~21~10~25 minecraft:grass
fill ~22~8~24 ~22~8~26 minecraft:stone 0
fill ~22~9~24 ~22~10~30 minecraft:dirt 0
fill ~22~11~24 ~22~11~30 minecraft:grass
setblock ~24~14~24 minecraft:red_flower 8
fill ~25~0~24 ~25~0~29 minecraft:stone 1
fill ~25~3~24 ~25~3~29 minecraft:stone 1
setblock ~25~13~24 minecraft:stone 0
fill ~25~14~24 ~25~15~30 minecraft:dirt 0
fill ~25~16~24 ~25~16~25 minecraft:grass
fill ~26~0~24 ~26~0~37 minecraft:stone 0
fill ~26~4~24 ~27~4~32 minecraft:stone 0
fill ~26~5~24 ~27~5~24 minecraft:copper_ore
fill ~26~17~24 ~26~17~25 minecraft:dirt 0
setblock ~26~18~24 minecraft:grass
setblock ~26~19~24 minecraft:red_flower 8
setblock ~27~18~24 minecraft:dirt 0
setblock ~27~19~24 minecraft:grass
setblock ~27~20~24 minecraft:red_flower 8
fill ~28~19~24 ~28~19~27 minecraft:stone 0
fill ~28~20~24 ~28~21~24 minecraft:dirt 0
setblock ~28~22~24 minecraft:grass
fill ~29~7~24 ~29~8~24 minecraft:wood 1
fill ~29~9~24 ~29~11~24 minecraft:wood 1
fill ~29~21~24 ~29~21~33 minecraft:stone 0
fill ~29~22~24 ~30~22~24 minecraft:dirt 0
fill ~29~23~24 ~29~23~37 minecraft:dirt 0
fill ~29~24~24 ~29~24~25 minecraft:grass
fill ~30~7~24 ~30~11~24 minecraft:ladder 5
fill ~30~12~24 ~30~12~46 minecraft:stone 0
fill ~30~24~24 ~30~24~40 minecraft:dirt 0
fill ~30~25~24 ~30~25~25 minecraft:grass
setblock ~30~26~24 minecraft:red_flower 8
setblock ~31~7~24 minecraft:composter 0
fill ~31~8~24 ~31~8~31 minecraft:sponge 0
fill ~31~9~24 ~31~9~26 minecraft:wooden_slab 9
setblock ~31~10~24 minecraft:composter 0
fill ~31~11~24 ~31~11~25 minecraft:sponge 0
fill ~31~22~24 ~31~22~32 minecraft:stone 0
fill ~31~23~24 ~31~23~25 minecraft:stone 0
fill ~31~25~24 ~31~25~32 minecraft:dirt 0
fill ~31~26~24 ~31~26~32 minecraft:grass
fill ~32~7~24 ~36~7~25 minecraft:farmland 7
fill ~32~8~24 ~36~8~25 minecraft:wheat 7
fill ~32~9~24 ~36~9~25 minecraft:farmland 7
fill ~32~10~24 ~36~10~25 minecraft:carrots 7
fill ~32~11~24 ~36~11~24 minecraft:barrel 3
fill ~32~22~24 ~32~23~24 minecraft:dirt 0
fill ~32~25~24 ~41~25~24 minecraft:grass
fill ~33~1~24 ~33~1~25 minecraft:dirt 0
fill ~33~2~24 ~33~2~25 minecraft:sponge 0
fill ~33~12~24 ~41~12~45 minecraft:stone 0
fill ~33~22~24 ~34~22~52 minecraft:stone 0
fill ~33~23~24 ~40~23~24 minecraft:dirt 0
fill ~34~1~24 ~35~1~24 minecraft:grass
fill ~34~2~24 ~34~2~25 minecraft:tallgrass 1
fill ~35~2~24 ~35~2~25 minecraft:sponge 0
fill ~35~22~24 ~39~22~24 minecraft:dirt 0
setblock ~35~26~24 minecraft:red_flower 8
fill ~36~1~24 ~37~1~25 minecraft:dirt 0
setblock ~37~2~24 minecraft:spruce_fence_gate 3
fill ~37~7~24 ~37~11~25 minecraft:stone 0
setblock ~38~1~24 minecraft:grass
setblock ~38~2~24 minecraft:tallgrass 1
setblock ~38~7~24 minecraft:netherite_block
setblock ~38~8~24 minecraft:stone 6
setblock ~38~9~24 minecraft:netherite_block
setblock ~38~10~24 minecraft:stone 6
fill ~38~11~24 ~42~11~24 minecraft:sponge 0
fill ~38~13~24 ~41~13~36 minecraft:stone 0
fill ~39~1~24 ~39~1~25 minecraft:dirt 0
fill ~39~2~24 ~40~2~24 minecraft:sponge 0
setblock ~39~7~24 minecraft:stone 6
setblock ~39~8~24 minecraft:netherite_block
fill ~39~9~24 ~39~9~25 minecraft:stone 6
setblock ~39~10~24 minecraft:netherite_block
setblock ~40~7~24 minecraft:netherite_block
fill ~40~8~24 ~40~8~25 minecraft:stone 6
setblock ~40~9~24 minecraft:netherite_block
setblock ~40~10~24 minecraft:stone 6
setblock ~41~7~24 minecraft:stone 6
setblock ~41~8~24 minecraft:netherite_block
fill ~41~9~24 ~41~9~25 minecraft:stone 6
setblock ~41~10~24 minecraft:netherite_block
setblock ~42~7~24 minecraft:netherite_block
setblock ~42~8~24 minecraft:stone 6
setblock ~42~9~24 minecraft:netherite_block
setblock ~42~10~24 minecraft:stone 6
fill ~43~0~24 ~43~0~30 minecraft:stone 0
setblock ~43~2~24 minecraft:spruce_fence_gate 3
fill ~43~7~24 ~43~10~25 minecraft:stone 0
setblock ~44~0~24 minecraft:coal_ore
fill ~44~7~24 ~47~7~25 minecraft:soul_sand
fill ~44~8~24 ~47~8~25 minecraft:nether_wart 3
fill ~44~9~24 ~47~9~25 minecraft:soul_sand
fill ~44~10~24 ~47~10~25 minecraft:nether_wart 3
fill ~44~11~24 ~47~11~24 minecraft:barrel 3
setblock ~45~26~24 minecraft:red_flower 8
fill ~46~0~24 ~48~0~26 minecraft:coal_ore
fill ~46~12~24 ~47~12~47 minecraft:stone 0
fill ~48~1~24 ~48~1~25 minecraft:dirt 0
fill ~48~2~24 ~48~2~25 minecraft:sponge 0
fill ~48~7~24 ~50~7~24 minecraft:stone 0
fill ~48~8~24 ~49~11~24 minecraft:stone 0
setblock ~48~12~24 minecraft:sponge 0
fill ~48~21~24 ~51~21~29 minecraft:stone 0
fill ~48~24~24 ~51~24~29 minecraft:dirt 0
fill ~48~25~24 ~51~25~24 minecraft:grass
setblock ~48~26~24 minecraft:red_flower 8
setblock ~49~0~24 minecraft:stone 0
fill ~49~12~24 ~50~12~44 minecraft:stone 0
fill ~50~9~24 ~50~11~26 minecraft:stone 0
fill ~50~26~24 ~50~26~25 minecraft:red_flower 8
fill ~51~11~24 ~51~11~32 minecraft:stone 0
fill ~52~24~24 ~54~24~24 minecraft:grass
setblock ~52~25~24 minecraft:red_flower 8
fill ~53~20~24 ~54~20~41 minecraft:stone 0
fill ~53~23~24 ~54~23~41 minecraft:dirt 0
fill ~54~1~24 ~54~1~49 minecraft:stone 0
fill ~54~2~24 ~54~3~47 minecraft:stone 0
setblock ~55~1~24 minecraft:sponge 0
setblock ~55~3~24 minecraft:sponge 0
fill ~55~19~24 ~55~19~42 minecraft:stone 0
fill ~55~22~24 ~55~22~33 minecraft:dirt 0
setblock ~55~23~24 minecraft:grass
fill ~56~18~24 ~56~18~41 minecraft:stone 0
fill ~56~19~24 ~57~19~25 minecraft:dirt 0
fill ~56~20~24 ~56~21~26 minecraft:dirt 0
fill ~56~22~24 ~56~22~25 minecraft:grass
fill ~57~15~24 ~58~15~39 minecraft:stone 0
fill ~57~16~24 ~57~16~40 minecraft:stone 0
setblock ~57~18~24 minecraft:dirt 0
setblock ~57~20~24 minecraft:grass
fill ~58~14~24 ~59~14~39 minecraft:stone 0
fill ~58~17~24 ~58~17~29 minecraft:dirt 0
fill ~58~18~24 ~58~18~25 minecraft:grass
fill ~59~15~24 ~59~15~27 minecraft:dirt 0
fill ~60~13~24 ~60~13~39 minecraft:stone 0
fill ~64~12~24 ~64~12~30 minecraft:stone 0
fill ~64~14~24 ~64~14~30 minecraft:dirt 0
fill ~64~15~24 ~64~15~30 minecraft:grass
fill ~67~10~24 ~67~10~28 minecraft:stone 0
fill ~67~12~24 ~67~12~28 minecraft:dirt 0
fill ~67~13~24 ~67~13~28 minecraft:grass
setblock ~69~2~24 minecraft:coal_ore
fill ~70~2~24 ~70~2~39 minecraft:stone 0
setblock ~72~10~24 minecraft:double_plant 2
fill ~4~0~25 ~4~0~32 minecraft:dirt 0
fill ~4~1~25 ~4~1~30 minecraft:grass
setblock ~6~1~25 minecraft:grass
fill ~7~1~25 ~7~1~33 minecraft:dirt 0
fill ~7~2~25 ~7~2~30 minecraft:grass
setblock ~9~2~25 minecraft:grass
fill ~10~0~25 ~11~0~66 minecraft:stone 0
fill ~10~2~25 ~11~2~31 minecraft:dirt 0
fill ~10~3~25 ~11~3~29 minecraft:grass
fill ~16~2~25 ~16~2~31 minecraft:stone 0
fill ~16~4~25 ~16~4~34 minecraft:dirt 0
setblock ~16~5~25 minecraft:grass
fill ~17~3~25 ~17~3~62 minecraft:stone 0
fill ~17~5~25 ~17~5~34 minecraft:dirt 0
setblock ~17~6~25 minecraft:grass
fill ~18~5~25 ~18~5~28 minecraft:stone 0
fill ~18~6~25 ~18~6~29 minecraft:dirt 0
fill ~18~7~25 ~18~7~28 minecraft:dirt 0
fill ~18~8~25 ~18~8~28 minecraft:grass
fill ~20~7~25 ~20~7~28 minecraft:stone 0
fill ~20~8~25 ~20~8~29 minecraft:dirt 0
fill ~20~9~25 ~20~9~28 minecraft:dirt 0
fill ~20~10~25 ~20~10~28 minecraft:grass
fill ~23~11~25 ~23~11~30 minecraft:dirt 0
setblock ~23~12~25 minecraft:grass
fill ~24~1~25 ~24~2~29 minecraft:stone 1
setblock ~24~3~25 minecraft:stone 0
fill ~24~13~25 ~25~13~25 minecraft:dirt 0
fill ~24~14~25 ~24~14~27 minecraft:grass
setblock ~26~5~25 minecraft:copper_ore
fill ~26~15~25 ~26~15~34 minecraft:stone 0
setblock ~26~16~25 minecraft:dirt 0
fill ~26~18~25 ~26~18~31 minecraft:dirt 0
setblock ~26~19~25 minecraft:grass
fill ~27~5~25 ~27~5~32 minecraft:stone 0
fill ~27~16~25 ~27~17~39 minecraft:stone 0
fill ~27~18~25 ~27~18~27 minecraft:stone 0
fill ~27~19~25 ~27~20~26 minecraft:dirt 0
setblock ~27~21~25 minecraft:grass
fill ~28~20~25 ~28~20~33 minecraft:stone 0
fill ~28~21~25 ~28~22~25 minecraft:dirt 0
setblock ~28~23~25 minecraft:grass
fill ~29~7~25 ~30~8~25 minecraft:sponge 0
fill ~29~9~25 ~30~9~26 minecraft:wooden_slab 9
fill ~29~10~25 ~31~10~25 minecraft:sponge 0
fill ~29~11~25 ~30~11~26 minecraft:sponge 0
setblock ~29~22~25 minecraft:dirt 0
setblock ~29~25~25 minecraft:red_flower 8
fill ~30~22~25 ~30~22~28 minecraft:stone 0
fill ~31~1~25 ~32~1~25 minecraft:grass
fill ~31~2~25 ~32~2~25 minecraft:tallgrass 1
setblock ~31~7~25 minecraft:spruce_trapdoor 1
fill ~32~11~25 ~36~11~25 minecraft:sponge 0
fill ~32~22~25 ~32~22~51 minecraft:stone 0
fill ~32~23~25 ~32~23~28 minecraft:dirt 0
fill ~32~25~25 ~37~25~35 minecraft:dirt 0
fill ~32~26~25 ~37~26~29 minecraft:grass
fill ~33~23~25 ~34~23~25 minecraft:stone 0
setblock ~34~1~25 minecraft:grass
setblock ~35~1~25 minecraft:dirt 0
fill ~35~22~25 ~37~22~37 minecraft:stone 0
fill ~35~23~25 ~40~23~25 minecraft:dirt 0
fill ~35~27~25 ~35~27~26 minecraft:red_flower 8
setblock ~37~2~25 minecraft:fence 1
setblock ~38~1~25 minecraft:dirt 0
fill ~38~2~25 ~39~2~25 minecraft:sponge 0
fill ~38~7~25 ~42~7~25 minecraft:stone_block_slab4 2
fill ~38~8~25 ~39~8~44 minecraft:sponge 0
fill ~38~9~25 ~38~10~44 minecraft:sponge 0
fill ~38~11~25 ~42~11~25 minecraft:stone 0
fill ~38~22~25 ~40~22~25 minecraft:dirt 0
fill ~38~25~25 ~40~25~25 minecraft:grass
fill ~39~10~25 ~41~10~25 minecraft:skull 1
setblock ~40~2~25 minecraft:tallgrass 1
setblock ~40~9~25 minecraft:stone 6
fill ~41~8~25 ~42~8~44 minecraft:sponge 0
fill ~41~22~25 ~48~22~26 minecraft:stone 0
fill ~41~25~25 ~48~25~29 minecraft:dirt 0
fill ~41~26~25 ~48~26~27 minecraft:grass
fill ~42~9~25 ~42~10~44 minecraft:sponge 0
setblock ~42~27~25 minecraft:red_flower 8
setblock ~43~2~25 minecraft:fence 1
fill ~44~0~25 ~44~0~30 minecraft:stone 0
fill ~44~11~25 ~45~11~25 minecraft:sponge 0
setblock ~46~11~25 minecraft:lantern 1
setblock ~47~11~25 minecraft:sponge 0
fill ~48~7~25 ~48~11~25 minecraft:ladder 3
fill ~48~12~25 ~48~12~47 minecraft:stone 0
setblock ~49~0~25 minecraft:coal_ore
fill ~49~7~25 ~50~7~25 minecraft:stone 0
fill ~49~8~25 ~49~11~25 minecraft:stone 0
setblock ~49~22~25 minecraft:dirt 0
fill ~49~25~25 ~53~25~25 minecraft:grass
fill ~50~1~25 ~50~1~26 minecraft:coal_ore
fill ~51~1~25 ~51~1~66 minecraft:stone 0
setblock ~51~5~25 minecraft:lever 4
setblock ~51~26~25 minecraft:red_flower 8
setblock ~52~4~25 minecraft:lever 4
fill ~52~5~25 ~53~5~25 minecraft:sponge 0
fill ~52~21~25 ~53~21~42 minecraft:stone 0
fill ~52~24~25 ~53~24~42 minecraft:dirt 0
fill ~53~4~25 ~53~4~26 minecraft:sponge 0
setblock ~53~26~25 minecraft:red_flower 8
fill ~54~24~25 ~55~24~25 minecraft:grass
fill ~55~1~25 ~55~1~48 minecraft:stone 0
fill ~55~2~25 ~55~3~47 minecraft:stone 0
fill ~55~20~25 ~55~20~41 minecraft:stone 0
fill ~55~23~25 ~55~23~40 minecraft:dirt 0
fill ~57~17~25 ~57~17~40 minecraft:stone 0
setblock ~57~18~25 minecraft:stone 0
fill ~57~20~25 ~57~20~39 minecraft:dirt 0
fill ~57~21~25 ~57~21~39 minecraft:grass
setblock ~57~22~25 minecraft:red_flower 8
fill ~60~14~25 ~60~14~33 minecraft:stone 0
fill ~60~16~25 ~60~16~33 minecraft:dirt 0
fill ~60~17~25 ~60~17~29 minecraft:grass
fill ~61~16~25 ~62~16~26 minecraft:grass
fill ~61~17~25 ~62~17~25 minecraft:red_flower 8
fill ~62~13~25 ~62~13~31 minecraft:stone 0
fill ~62~15~25 ~62~15~31 minecraft:dirt 0
fill ~66~11~25 ~67~11~25 minecraft:stone 0
fill ~66~13~25 ~66~13~30 minecraft:dirt 0
fill ~66~14~25 ~66~14~30 minecraft:grass
setblock ~66~15~25 minecraft:double_plant 2
fill ~69~2~25 ~69~2~39 minecraft:stone 0
setblock ~69~3~25 minecraft:coal_ore
setblock ~69~9~25 minecraft:dirt 0
fill ~70~3~25 ~70~3~39 minecraft:stone 0
fill ~79~3~25 ~79~3~27 minecraft:stone 0
fill ~79~4~25 ~79~4~27 minecraft:dirt 0
fill ~79~5~25 ~79~5~27 minecraft:grass
fill ~0~0~26 ~0~0~44 minecraft:grass
fill ~1~0~26 ~1~0~31 minecraft:dirt 0
fill ~1~1~26 ~1~1~31 minecraft:grass
fill ~6~1~26 ~6~1~34 minecraft:dirt 0
fill ~6~2~26 ~6~2~30 minecraft:grass
fill ~9~0~26 ~9~0~68 minecraft:stone 0
fill ~9~2~26 ~9~2~33 minecraft:dirt 0
fill ~9~3~26 ~9~3~31 minecraft:grass
setblock ~16~3~26 minecraft:stone 0
setblock ~16~5~26 minecraft:dirt 0
setblock ~16~6~26 minecraft:grass
fill ~17~4~26 ~17~4~28 minecraft:stone 0
fill ~17~6~26 ~17~6~28 minecraft:dirt 0
fill ~17~7~26 ~17~7~28 minecraft:grass
fill ~19~6~26 ~19~6~27 minecraft:stone 0
fill ~19~7~26 ~19~7~29 minecraft:dirt 0
fill ~19~8~26 ~19~8~27 minecraft:dirt 0
fill ~19~9~26 ~19~9~27 minecraft:grass
setblock ~19~10~26 minecraft:double_plant 2
fill ~21~8~26 ~21~8~27 minecraft:stone 0
fill ~21~9~26 ~21~9~33 minecraft:dirt 0
fill ~21~10~26 ~21~10~28 minecraft:dirt 0
fill ~21~11~26 ~21~11~28 minecraft:grass
fill ~23~1~26 ~23~2~29 minecraft:stone 1
fill ~23~9~26 ~23~9~53 minecraft:stone 0
fill ~23~10~26 ~23~10~30 minecraft:dirt 0
fill ~23~12~26 ~23~12~31 minecraft:dirt 0
fill ~23~13~26 ~23~13~30 minecraft:grass
fill ~24~0~26 ~24~0~29 minecraft:stone 1
fill ~24~3~26 ~24~3~29 minecraft:stone 1
fill ~24~13~26 ~24~13~31 minecraft:dirt 0
fill ~25~13~26 ~25~13~54 minecraft:stone 0
fill ~25~16~26 ~25~16~34 minecraft:dirt 0
fill ~25~17~26 ~25~17~30 minecraft:grass
fill ~26~5~26 ~26~5~34 minecraft:stone 0
fill ~26~16~26 ~26~16~51 minecraft:stone 0
fill ~26~17~26 ~26~17~49 minecraft:stone 0
fill ~26~19~26 ~26~20~35 minecraft:dirt 0
fill ~26~21~26 ~26~21~34 minecraft:grass
fill ~27~21~26 ~27~21~35 minecraft:dirt 0
fill ~27~22~26 ~27~22~34 minecraft:grass
fill ~28~0~26 ~29~0~38 minecraft:stone 0
fill ~28~21~26 ~28~21~29 minecraft:stone 0
fill ~28~22~26 ~28~22~36 minecraft:dirt 0
fill ~28~23~26 ~28~23~32 minecraft:dirt 0
fill ~28~24~26 ~28~24~32 minecraft:grass
setblock ~29~7~26 minecraft:composter 0
fill ~29~8~26 ~30~8~26 minecraft:sponge 0
setblock ~29~10~26 minecraft:composter 0
fill ~29~22~26 ~29~22~28 minecraft:stone 0
fill ~29~24~26 ~29~24~31 minecraft:dirt 0
fill ~29~25~26 ~29~25~31 minecraft:grass
setblock ~30~0~26 minecraft:emerald_ore
setblock ~30~7~26 minecraft:spruce_trapdoor 3
setblock ~30~10~26 minecraft:sponge 0
fill ~30~23~26 ~30~23~27 minecraft:stone 0
fill ~30~25~26 ~30~25~28 minecraft:dirt 0
fill ~30~26~26 ~30~26~28 minecraft:grass
fill ~31~0~26 ~37~0~30 minecraft:stone 0
fill ~31~1~26 ~48~1~28 minecraft:stone 0
setblock ~31~2~26 minecraft:wood 1
fill ~31~3~26 ~31~6~26 minecraft:wood 1
setblock ~31~7~26 minecraft:sponge 0
fill ~31~10~26 ~31~11~26 minecraft:wood 1
fill ~31~23~26 ~31~23~28 minecraft:dirt 0
fill ~31~27~26 ~31~27~27 minecraft:red_flower 8
setblock ~32~2~26 minecraft:spruce_fence_gate 2
fill ~32~4~26 ~36~4~44 minecraft:sponge 0
fill ~32~5~26 ~33~5~44 minecraft:sponge 0
fill ~32~6~26 ~36~6~26 minecraft:double_wooden_slab 1
fill ~32~7~26 ~36~7~26 minecraft:spruce_trapdoor 2
fill ~32~8~26 ~36~8~44 minecraft:sponge 0
fill ~32~9~26 ~36~9~26 minecraft:spruce_trapdoor 2
fill ~32~10~26 ~36~10~44 minecraft:sponge 0
fill ~32~11~26 ~36~11~26 minecraft:wooden_slab 9
setblock ~33~2~26 minecraft:fence 1
setblock ~33~23~26 minecraft:dirt 0
setblock ~34~2~26 minecraft:spruce_fence_gate 2
setblock ~34~5~26 minecraft:lantern 1
fill ~34~23~26 ~35~23~26 minecraft:stone 0
setblock ~35~2~26 minecraft:fence 1
fill ~35~5~26 ~36~5~44 minecraft:sponge 0
setblock ~36~2~26 minecraft:spruce_fence_gate 2
fill ~36~23~26 ~40~23~28 minecraft:dirt 0
fill ~37~2~26 ~37~8~26 minecraft:wood 1
fill ~37~9~26 ~37~11~26 minecraft:wood 1
setblock ~37~27~26 minecraft:red_flower 8
setblock ~38~2~26 minecraft:spruce_fence_gate 2
fill ~38~4~26 ~42~4~33 minecraft:sponge 0
fill ~38~5~26 ~39~5~33 minecraft:sponge 0
