fill ~56~0~1 ~58~0~1 minecraft:stone_block_slab 1
fill ~56~0~2 ~57~0~4 minecraft:grass
setblock ~58~0~2 minecraft:red_mushroom_block 15
fill ~59~0~2 ~59~0~3 minecraft:stone_block_slab 1
fill ~20~1~3 ~21~1~4 minecraft:grass
fill ~23~0~3 ~23~0~4 minecraft:grass
setblock ~44~0~3 minecraft:tallgrass 0
fill ~58~0~3 ~58~0~5 minecraft:sandstone 3
fill ~20~0~4 ~21~0~4 minecraft:dirt 0
setblock ~22~0~4 minecraft:grass
fill ~24~0~4 ~25~0~6 minecraft:red_mushroom_block 15
setblock ~43~0~4 minecraft:tallgrass 0
setblock ~55~0~4 minecraft:sea_lantern
fill ~59~0~4 ~59~0~5 minecraft:red_mushroom_block 15
fill ~18~2~5 ~18~2~12 minecraft:grass
setblock ~18~3~5 minecraft:tallgrass 0
fill ~19~1~5 ~20~1~10 minecraft:grass
setblock ~21~0~5 minecraft:red_mushroom_block 15
fill ~22~0~5 ~23~0~5 minecraft:dirt 0
fill ~22~1~5 ~25~1~5 minecraft:red_mushroom_block 15
fill ~25~2~5 ~25~2~6 minecraft:red_mushroom_block 15
fill ~26~0~5 ~26~0~7 minecraft:red_mushroom_block 15
fill ~54~0~5 ~56~0~12 minecraft:grass
setblock ~57~0~5 minecraft:sandstone 3
fill ~21~1~6 ~21~1~7 minecraft:grass
setblock ~22~0~6 minecraft:bone_block 0
fill ~22~1~6 ~23~1~6 minecraft:red_mushroom_block 15
setblock ~23~0~6 minecraft:dirt 0
fill ~23~2~6 ~24~2~6 minecraft:red_mushroom_block 15
setblock ~23~3~6 minecraft:bone_block 0
setblock ~24~1~6 minecraft:bone_block 0
fill ~24~3~6 ~26~3~6 minecraft:red_mushroom_block 15
fill ~25~1~6 ~26~1~6 minecraft:red_mushroom_block 15
setblock ~26~2~6 minecraft:red_mushroom_block 15
setblock ~27~52~6 minecraft:blue_glazed_terracotta 2
setblock ~27~53~6 minecraft:stained_glass 0
setblock ~27~54~6 minecraft:concrete 0
setblock ~27~55~6 minecraft:stained_glass 0
setblock ~27~56~6 minecraft:concrete 11
setblock ~27~57~6 minecraft:blue_glazed_terracotta 2
setblock ~27~58~6 minecraft:stained_glass 0
setblock ~27~59~6 minecraft:concrete 0
setblock ~27~60~6 minecraft:stained_glass 0
setblock ~27~61~6 minecraft:concrete 11
fill ~28~52~6 ~28~54~6 minecraft:wool 11
setblock ~28~55~6 minecraft:concrete 0
fill ~28~56~6 ~28~59~6 minecraft:wool 11
setblock ~28~60~6 minecraft:concrete 0
setblock ~28~61~6 minecraft:wool 11
setblock ~28~62~6 minecraft:stained_glass 0
setblock ~29~52~6 minecraft:concrete 0
setblock ~29~53~6 minecraft:concrete 11
setblock ~29~54~6 minecraft:stained_glass 3
setblock ~29~55~6 minecraft:concrete 11
setblock ~29~56~6 minecraft:stained_glass 3
setblock ~29~57~6 minecraft:concrete 0
setblock ~29~58~6 minecraft:concrete 11
setblock ~29~59~6 minecraft:stained_glass 3
setblock ~29~60~6 minecraft:concrete 11
setblock ~29~61~6 minecraft:stained_glass 3
setblock ~29~62~6 minecraft:concrete 0
setblock ~29~63~6 minecraft:stained_glass 0
fill ~30~52~6 ~31~52~6 minecraft:stained_glass 3
setblock ~30~53~6 minecraft:stained_glass 0
setblock ~30~54~6 minecraft:concrete 11
setblock ~30~55~6 minecraft:stained_glass 0
setblock ~30~56~6 minecraft:wool 11
fill ~30~57~6 ~31~57~6 minecraft:stained_glass 3
setblock ~30~58~6 minecraft:stained_glass 0
setblock ~30~59~6 minecraft:sea_lantern
setblock ~30~60~6 minecraft:stained_glass 0
setblock ~30~61~6 minecraft:wool 11
setblock ~30~62~6 minecraft:stained_glass 0
setblock ~30~63~6 minecraft:blue_glazed_terracotta 2
fill ~31~53~6 ~31~54~6 minecraft:wool 11
setblock ~31~55~6 minecraft:concrete 3
setblock ~31~56~6 minecraft:stained_glass 3
fill ~31~58~6 ~31~59~6 minecraft:wool 11
setblock ~31~60~6 minecraft:concrete 3
setblock ~31~61~6 minecraft:stained_glass 3
setblock ~31~62~6 minecraft:wool 11
setblock ~31~63~6 minecraft:concrete 11
setblock ~32~52~6 minecraft:concrete 3
setblock ~32~53~6 minecraft:concrete 0
setblock ~32~54~6 minecraft:blue_glazed_terracotta 2
setblock ~32~55~6 minecraft:wool 11
fill ~32~56~6 ~33~56~6 minecraft:blue_glazed_terracotta 2
setblock ~32~57~6 minecraft:concrete 3
setblock ~32~58~6 minecraft:concrete 0
fill ~32~59~6 ~33~59~6 minecraft:blue_glazed_terracotta 2
setblock ~32~60~6 minecraft:wool 11
fill ~32~61~6 ~33~61~6 minecraft:blue_glazed_terracotta 2
setblock ~32~62~6 minecraft:stained_glass 3
setblock ~32~63~6 minecraft:wool 11
setblock ~33~52~6 minecraft:wool 11
setblock ~33~53~6 minecraft:stained_glass 3
setblock ~33~54~6 minecraft:sea_lantern
setblock ~33~55~6 minecraft:concrete 11
setblock ~33~57~6 minecraft:wool 11
setblock ~33~58~6 minecraft:stained_glass 3
setblock ~33~60~6 minecraft:concrete 11
setblock ~33~62~6 minecraft:blue_glazed_terracotta 2
setblock ~33~63~6 minecraft:concrete 11
fill ~34~52~6 ~35~52~6 minecraft:blue_glazed_terracotta 2
setblock ~34~53~6 minecraft:blue_glazed_terracotta 2
setblock ~34~54~6 minecraft:concrete 0
setblock ~34~55~6 minecraft:wool 11
setblock ~34~56~6 minecraft:concrete 0
fill ~34~57~6 ~35~57~6 minecraft:blue_glazed_terracotta 2
setblock ~34~58~6 minecraft:blue_glazed_terracotta 2
setblock ~34~59~6 minecraft:concrete 0
setblock ~34~60~6 minecraft:wool 11
setblock ~34~61~6 minecraft:concrete 0
setblock ~34~62~6 minecraft:concrete 3
setblock ~35~53~6 minecraft:concrete 0
setblock ~35~54~6 minecraft:concrete 3
setblock ~35~55~6 minecraft:concrete 0
setblock ~35~56~6 minecraft:concrete 3
setblock ~35~58~6 minecraft:concrete 0
setblock ~35~59~6 minecraft:concrete 3
setblock ~35~60~6 minecraft:sea_lantern
setblock ~35~61~6 minecraft:concrete 3
fill ~40~0~6 ~41~0~6 minecraft:tallgrass 0
setblock ~43~0~6 minecraft:bone_block 0
fill ~44~0~6 ~45~0~6 minecraft:red_mushroom_block 15
fill ~46~0~6 ~47~0~6 minecraft:bone_block 0
setblock ~47~1~6 minecraft:leaves 0
setblock ~47~2~6 minecraft:air
fill ~53~0~6 ~53~0~18 minecraft:grass
setblock ~57~0~6 minecraft:red_mushroom_block 15
fill ~58~0~6 ~59~0~6 minecraft:bone_block 0
setblock ~17~42~7 minecraft:concrete 0
setblock ~17~43~7 minecraft:concrete 11
setblock ~17~44~7 minecraft:blue_glazed_terracotta 2
setblock ~18~41~7 minecraft:stained_glass 0
fill ~18~42~7 ~19~42~7 minecraft:blue_glazed_terracotta 2
setblock ~18~43~7 minecraft:stained_glass 3
setblock ~18~44~7 minecraft:stained_glass 0
setblock ~18~45~7 minecraft:concrete 3
setblock ~19~41~7 minecraft:concrete 11
setblock ~19~43~7 minecraft:blue_glazed_terracotta 2
setblock ~19~44~7 minecraft:concrete 11
setblock ~19~45~7 minecraft:blue_glazed_terracotta 2
setblock ~20~41~7 minecraft:wool 11
setblock ~20~42~7 minecraft:concrete 11
setblock ~20~43~7 minecraft:stained_glass 0
fill ~20~44~7 ~20~45~7 minecraft:concrete 3
setblock ~21~2~7 minecraft:tallgrass 0
setblock ~21~41~7 minecraft:stained_glass 0
setblock ~21~42~7 minecraft:concrete 3
setblock ~21~43~7 minecraft:wool 11
setblock ~21~44~7 minecraft:stained_glass 0
fill ~22~0~7 ~22~0~8 minecraft:dirt 0
fill ~22~1~7 ~22~1~8 minecraft:red_mushroom_block 15
setblock ~22~2~7 minecraft:red_mushroom_block 10
fill ~22~3~7 ~22~3~11 minecraft:red_mushroom_block 15
fill ~23~0~7 ~23~0~9 minecraft:grass
fill ~23~4~7 ~24~4~7 minecraft:bone_block 0
fill ~24~52~7 ~25~52~7 minecraft:wool 11
setblock ~24~53~7 minecraft:concrete 0
setblock ~24~54~7 minecraft:stained_glass 3
setblock ~24~55~7 minecraft:concrete 11
setblock ~24~56~7 minecraft:stained_glass 3
setblock ~24~57~7 minecraft:sea_lantern
setblock ~24~58~7 minecraft:concrete 0
setblock ~24~59~7 minecraft:stained_glass 3
setblock ~24~60~7 minecraft:concrete 11
setblock ~24~61~7 minecraft:stained_glass 3
fill ~24~62~7 ~25~62~7 minecraft:wool 11
fill ~25~4~7 ~26~4~7 minecraft:red_mushroom_block 15
setblock ~25~53~7 minecraft:wool 11
setblock ~25~54~7 minecraft:concrete 3
setblock ~25~55~7 minecraft:concrete 0
fill ~25~56~7 ~26~56~7 minecraft:concrete 3
fill ~25~57~7 ~25~58~7 minecraft:wool 11
setblock ~25~59~7 minecraft:concrete 3
setblock ~25~60~7 minecraft:concrete 0
fill ~25~61~7 ~26~61~7 minecraft:concrete 3
fill ~25~63~7 ~26~63~7 minecraft:stained_glass 3
setblock ~26~52~7 minecraft:stained_glass 0
setblock ~26~53~7 minecraft:concrete 3
fill ~26~54~7 ~26~55~7 minecraft:wool 11
setblock ~26~57~7 minecraft:stained_glass 0
setblock ~26~58~7 minecraft:concrete 3
fill ~26~59~7 ~26~60~7 minecraft:wool 11
setblock ~26~62~7 minecraft:stained_glass 0
setblock ~26~64~7 minecraft:blue_glazed_terracotta 2
fill ~27~0~7 ~27~0~8 minecraft:bone_block 0
fill ~27~1~7 ~27~2~8 minecraft:red_mushroom_block 15
setblock ~27~3~7 minecraft:bone_block 0
setblock ~27~62~7 minecraft:concrete 11
setblock ~27~63~7 minecraft:blue_glazed_terracotta 2
fill ~27~64~7 ~28~64~7 minecraft:concrete 0
setblock ~27~65~7 minecraft:concrete 0
setblock ~28~63~7 minecraft:concrete 0
fill ~28~65~7 ~29~65~7 minecraft:wool 11
setblock ~28~66~7 minecraft:concrete 3
setblock ~29~64~7 minecraft:sea_lantern
fill ~29~66~7 ~30~66~7 minecraft:concrete 11
setblock ~30~64~7 minecraft:concrete 3
setblock ~30~65~7 minecraft:blue_glazed_terracotta 2
setblock ~31~64~7 minecraft:blue_glazed_terracotta 2
fill ~31~65~7 ~32~65~7 minecraft:concrete 3
setblock ~31~66~7 minecraft:concrete 3
setblock ~32~64~7 minecraft:concrete 0
fill ~32~66~7 ~33~66~7 minecraft:concrete 11
setblock ~33~64~7 minecraft:concrete 11
setblock ~33~65~7 minecraft:stained_glass 0
setblock ~34~63~7 minecraft:concrete 3
setblock ~34~64~7 minecraft:stained_glass 3
fill ~34~65~7 ~34~66~7 minecraft:wool 11
fill ~35~62~7 ~36~62~7 minecraft:concrete 3
fill ~35~63~7 ~36~63~7 minecraft:wool 11
setblock ~35~64~7 minecraft:wool 11
setblock ~35~65~7 minecraft:blue_glazed_terracotta 2
fill ~36~52~7 ~36~53~7 minecraft:concrete 3
setblock ~36~54~7 minecraft:concrete 0
setblock ~36~55~7 minecraft:stained_glass 3
setblock ~36~56~7 minecraft:concrete 0
fill ~36~57~7 ~36~58~7 minecraft:concrete 3
setblock ~36~59~7 minecraft:concrete 0
setblock ~36~60~7 minecraft:stained_glass 3
setblock ~36~61~7 minecraft:concrete 0
setblock ~36~64~7 minecraft:concrete 0
setblock ~37~52~7 minecraft:blue_glazed_terracotta 2
setblock ~37~53~7 minecraft:stained_glass 3
setblock ~37~54~7 minecraft:concrete 11
setblock ~37~55~7 minecraft:concrete 3
setblock ~37~56~7 minecraft:wool 11
setblock ~37~57~7 minecraft:blue_glazed_terracotta 2
setblock ~37~58~7 minecraft:stained_glass 3
setblock ~37~59~7 minecraft:concrete 11
setblock ~37~60~7 minecraft:concrete 3
setblock ~37~61~7 minecraft:wool 11
setblock ~37~62~7 minecraft:blue_glazed_terracotta 2
setblock ~37~63~7 minecraft:stained_glass 3
fill ~38~52~7 ~38~53~7 minecraft:concrete 3
setblock ~38~54~7 minecraft:wool 11
setblock ~38~55~7 minecraft:concrete 11
setblock ~38~56~7 minecraft:concrete 0
fill ~38~57~7 ~38~58~7 minecraft:concrete 3
setblock ~38~59~7 minecraft:wool 11
setblock ~38~60~7 minecraft:concrete 11
setblock ~38~61~7 minecraft:concrete 0
setblock ~38~62~7 minecraft:concrete 11
fill ~43~0~7 ~44~0~7 minecraft:red_mushroom_block 15
setblock ~43~1~7 minecraft:bone_block 0
fill ~44~1~7 ~46~1~7 minecraft:red_mushroom_block 15
setblock ~45~0~7 minecraft:bone_block 0
setblock ~46~0~7 minecraft:red_mushroom_block 15
fill ~47~0~7 ~49~0~8 minecraft:dirt 0
setblock ~47~1~7 minecraft:bone_block 0
fill ~47~2~7 ~48~2~7 minecraft:leaves 0
fill ~48~1~7 ~49~1~7 minecraft:red_mushroom_block 15
fill ~50~0~7 ~52~0~7 minecraft:grass
setblock ~55~1~7 minecraft:tallgrass 0
setblock ~57~0~7 minecraft:grass
setblock ~58~0~7 minecraft:red_mushroom_block 15
setblock ~59~0~7 minecraft:sandstone 3
setblock ~60~0~7 minecraft:stone_block_slab 1
fill ~16~41~8 ~17~41~8 minecraft:wool 11
setblock ~16~42~8 minecraft:stained_glass 0
setblock ~16~43~8 minecraft:concrete 11
setblock ~16~44~8 minecraft:sea_lantern
setblock ~16~45~8 minecraft:concrete 3
setblock ~17~45~8 minecraft:stained_glass 0
fill ~17~46~8 ~18~46~8 minecraft:concrete 3
setblock ~19~46~8 minecraft:stained_glass 0
setblock ~20~46~8 minecraft:stained_glass 3
setblock ~21~0~8 minecraft:grass
fill ~21~45~8 ~21~46~8 minecraft:concrete 11
setblock ~22~2~8 minecraft:bone_block 0
setblock ~22~41~8 minecraft:concrete 11
setblock ~22~42~8 minecraft:wool 11
fill ~22~43~8 ~22~44~8 minecraft:concrete 3
setblock ~22~45~8 minecraft:blue_glazed_terracotta 2
setblock ~22~52~8 minecraft:stained_glass 0
setblock ~22~53~8 minecraft:wool 11
fill ~22~54~8 ~23~54~8 minecraft:concrete 0
setblock ~22~55~8 minecraft:concrete 0
setblock ~22~56~8 minecraft:concrete 11
setblock ~22~57~8 minecraft:stained_glass 0
setblock ~22~58~8 minecraft:wool 11
fill ~22~59~8 ~23~59~8 minecraft:concrete 0
setblock ~22~60~8 minecraft:concrete 0
setblock ~22~61~8 minecraft:concrete 11
setblock ~22~62~8 minecraft:concrete 0
fill ~23~4~8 ~23~4~9 minecraft:red_mushroom_block 15
fill ~23~52~8 ~23~53~8 minecraft:blue_glazed_terracotta 2
fill ~23~55~8 ~23~58~8 minecraft:blue_glazed_terracotta 2
fill ~23~60~8 ~23~63~8 minecraft:blue_glazed_terracotta 2
setblock ~23~64~8 minecraft:stained_glass 3
setblock ~24~4~8 minecraft:bone_block 0
setblock ~24~63~8 minecraft:wool 11
setblock ~24~64~8 minecraft:sea_lantern
setblock ~24~65~8 minecraft:concrete 3
fill ~25~5~8 ~26~5~8 minecraft:bone_block 0
setblock ~25~64~8 minecraft:concrete 11
setblock ~25~65~8 minecraft:stained_glass 0
fill ~25~66~8 ~27~66~8 minecraft:concrete 3
setblock ~26~4~8 minecraft:red_mushroom_block 15
setblock ~26~65~8 minecraft:wool 11
setblock ~26~67~8 minecraft:blue_glazed_terracotta 2
setblock ~27~3~8 minecraft:red_mushroom_block 15
setblock ~27~4~8 minecraft:bone_block 0
setblock ~27~67~8 minecraft:stained_glass 0
setblock ~28~0~8 minecraft:bone_block 0
fill ~28~1~8 ~29~1~8 minecraft:red_mushroom_block 15
setblock ~28~2~8 minecraft:bone_block 0
setblock ~28~67~8 minecraft:concrete 3
setblock ~28~68~8 minecraft:concrete 11
fill ~29~0~8 ~29~0~9 minecraft:red_mushroom_block 15
fill ~29~67~8 ~29~68~8 minecraft:blue_glazed_terracotta 2
setblock ~30~67~8 minecraft:wool 11
fill ~30~68~8 ~31~68~8 minecraft:blue_glazed_terracotta 2
setblock ~31~67~8 minecraft:concrete 11
setblock ~32~67~8 minecraft:wool 11
setblock ~32~68~8 minecraft:concrete 3
setblock ~33~67~8 minecraft:concrete 11
setblock ~33~68~8 minecraft:wool 11
setblock ~34~67~8 minecraft:stained_glass 0
setblock ~34~68~8 minecraft:concrete 3
setblock ~35~66~8 minecraft:stained_glass 0
fill ~35~67~8 ~36~67~8 minecraft:concrete 3
setblock ~36~65~8 minecraft:wool 11
setblock ~36~66~8 minecraft:concrete 0
setblock ~37~64~8 minecraft:concrete 0
fill ~37~65~8 ~37~66~8 minecraft:concrete 3
fill ~38~63~8 ~39~63~8 minecraft:concrete 0
setblock ~38~64~8 minecraft:stained_glass 0
setblock ~38~65~8 minecraft:stained_glass 3
setblock ~39~52~8 minecraft:wool 11
setblock ~39~53~8 minecraft:blue_glazed_terracotta 2
setblock ~39~54~8 minecraft:concrete 3
fill ~39~55~8 ~39~56~8 minecraft:concrete 0
setblock ~39~57~8 minecraft:wool 11
setblock ~39~58~8 minecraft:blue_glazed_terracotta 2
setblock ~39~59~8 minecraft:concrete 3
fill ~39~60~8 ~39~62~8 minecraft:concrete 0
setblock ~39~64~8 minecraft:wool 11
setblock ~40~52~8 minecraft:stained_glass 3
setblock ~40~53~8 minecraft:wool 11
setblock ~40~54~8 minecraft:concrete 11
fill ~40~55~8 ~40~56~8 minecraft:stained_glass 0
setblock ~40~57~8 minecraft:stained_glass 3
setblock ~40~58~8 minecraft:wool 11
setblock ~40~59~8 minecraft:concrete 11
fill ~40~60~8 ~40~61~8 minecraft:stained_glass 0
setblock ~40~62~8 minecraft:blue_glazed_terracotta 2
fill ~41~0~8 ~42~1~8 minecraft:red_mushroom_block 15
fill ~41~3~8 ~41~3~9 minecraft:leaves 0
setblock ~42~2~8 minecraft:red_mushroom_block 15
setblock ~43~2~8 minecraft:bone_block 0
fill ~44~2~8 ~47~2~8 minecraft:red_mushroom_block 15
fill ~45~0~8 ~46~0~10 minecraft:grass
fill ~46~3~8 ~48~3~8 minecraft:leaves 0
setblock ~47~1~8 minecraft:red_mushroom_block 15
fill ~48~1~8 ~48~2~8 minecraft:bone_block 0
fill ~49~1~8 ~50~1~8 minecraft:red_mushroom_block 15
setblock ~50~0~8 minecraft:dirt 0
fill ~51~0~8 ~52~0~8 minecraft:grass
setblock ~57~0~8 minecraft:red_mushroom_block 15
fill ~58~0~8 ~59~0~8 minecraft:bone_block 0
fill ~60~0~8 ~60~0~9 minecraft:red_mushroom_block 15
setblock ~61~0~8 minecraft:stone_block_slab 1
setblock ~15~41~9 minecraft:stained_glass 3
setblock ~15~42~9 minecraft:blue_glazed_terracotta 2
setblock ~15~43~9 minecraft:stained_glass 0
setblock ~15~44~9 minecraft:concrete 11
setblock ~15~45~9 minecraft:concrete 0
setblock ~16~46~9 minecraft:wool 11
fill ~17~2~9 ~17~2~16 minecraft:grass
fill ~17~41~9 ~17~41~10 minecraft:leaves 0
fill ~17~42~9 ~20~42~9 minecraft:leaves 0
fill ~17~47~9 ~17~47~10 minecraft:wool 11
fill ~18~43~9 ~19~43~9 minecraft:leaves 0
setblock ~18~47~9 minecraft:concrete 11
setblock ~19~44~9 minecraft:leaves 0
setblock ~19~47~9 minecraft:stained_glass 3
setblock ~20~47~9 minecraft:wool 11
setblock ~20~52~9 minecraft:stained_glass 0
fill ~20~53~9 ~20~54~9 minecraft:concrete 3
setblock ~20~55~9 minecraft:stained_glass 0
setblock ~20~56~9 minecraft:stained_glass 3
setblock ~20~57~9 minecraft:stained_glass 0
fill ~20~58~9 ~20~59~9 minecraft:concrete 3
setblock ~20~60~9 minecraft:stained_glass 0
setblock ~20~61~9 minecraft:stained_glass 3
setblock ~20~62~9 minecraft:blue_glazed_terracotta 2
fill ~21~1~9 ~21~1~10 minecraft:red_mushroom_block 15
setblock ~21~2~9 minecraft:red_mushroom_block 15
setblock ~21~47~9 minecraft:blue_glazed_terracotta 2
setblock ~21~52~9 minecraft:concrete 11
setblock ~21~53~9 minecraft:blue_glazed_terracotta 2
setblock ~21~54~9 minecraft:concrete 0
setblock ~21~55~9 minecraft:blue_glazed_terracotta 2
setblock ~21~56~9 minecraft:stained_glass 0
setblock ~21~57~9 minecraft:concrete 11
setblock ~21~58~9 minecraft:blue_glazed_terracotta 2
setblock ~21~59~9 minecraft:concrete 0
setblock ~21~60~9 minecraft:blue_glazed_terracotta 2
setblock ~21~61~9 minecraft:stained_glass 0
setblock ~21~62~9 minecraft:wool 11
fill ~21~63~9 ~22~63~9 minecraft:concrete 11
setblock ~21~64~9 minecraft:concrete 0
fill ~22~0~9 ~22~0~11 minecraft:grass
setblock ~22~46~9 minecraft:concrete 11
setblock ~22~64~9 minecraft:concrete 3
fill ~22~65~9 ~22~66~9 minecraft:wool 11
setblock ~23~41~9 minecraft:concrete 11
setblock ~23~42~9 minecraft:stained_glass 3
setblock ~23~43~9 minecraft:wool 11
setblock ~23~44~9 minecraft:blue_glazed_terracotta 2
setblock ~23~45~9 minecraft:stained_glass 3
fill ~23~65~9 ~23~66~9 minecraft:concrete 11
setblock ~23~67~9 minecraft:blue_glazed_terracotta 2
setblock ~24~5~9 minecraft:red_mushroom_block 15
setblock ~24~66~9 minecraft:stained_glass 0
fill ~24~67~9 ~25~67~9 minecraft:concrete 0
setblock ~24~68~9 minecraft:wool 11
setblock ~25~5~9 minecraft:bone_block 0
fill ~25~6~9 ~25~6~10 minecraft:red_mushroom_block 15
setblock ~25~68~9 minecraft:stained_glass 3
setblock ~26~5~9 minecraft:red_mushroom_block 15
setblock ~26~68~9 minecraft:concrete 11
setblock ~26~69~9 minecraft:stained_glass 0
setblock ~27~4~9 minecraft:red_mushroom_block 15
setblock ~27~68~9 minecraft:concrete 0
fill ~27~69~9 ~28~69~9 minecraft:wool 11
setblock ~28~3~9 minecraft:bone_block 0
setblock ~28~70~9 minecraft:wool 11
setblock ~28~71~9 minecraft:concrete 3
fill ~29~1~9 ~29~1~10 minecraft:red_mushroom_block 15
setblock ~29~2~9 minecraft:bone_block 0
setblock ~29~69~9 minecraft:concrete 3
setblock ~29~70~9 minecraft:blue_glazed_terracotta 2
setblock ~29~71~9 minecraft:stained_glass 3
setblock ~30~0~9 minecraft:red_mushroom_block 15
setblock ~30~69~9 minecraft:blue_glazed_terracotta 2
setblock ~30~70~9 minecraft:stained_glass 0
fill ~30~71~9 ~31~71~9 minecraft:concrete 11
setblock ~31~69~9 minecraft:concrete 11
setblock ~31~70~9 minecraft:concrete 0
setblock ~32~69~9 minecraft:concrete 0
setblock ~32~70~9 minecraft:stained_glass 3
setblock ~32~71~9 minecraft:stained_glass 0
setblock ~33~69~9 minecraft:stained_glass 3
fill ~33~70~9 ~34~70~9 minecraft:concrete 3
setblock ~33~71~9 minecraft:concrete 11
fill ~34~69~9 ~35~69~9 minecraft:concrete 3
setblock ~34~71~9 minecraft:concrete 3
setblock ~35~68~9 minecraft:stained_glass 0
setblock ~36~68~9 minecraft:concrete 0
setblock ~36~69~9 minecraft:wool 11
setblock ~37~67~9 minecraft:stained_glass 3
setblock ~37~68~9 minecraft:wool 11
setblock ~38~66~9 minecraft:wool 11
setblock ~38~67~9 minecraft:blue_glazed_terracotta 2
setblock ~38~68~9 minecraft:stained_glass 0
setblock ~39~65~9 minecraft:concrete 11
setblock ~39~66~9 minecraft:stained_glass 0
setblock ~39~67~9 minecraft:concrete 11
setblock ~40~0~9 minecraft:bone_block 0
setblock ~40~1~9 minecraft:red_mushroom_block 15
fill ~40~3~9 ~40~3~10 minecraft:leaves 0
fill ~40~63~9 ~41~63~9 minecraft:blue_glazed_terracotta 2
setblock ~40~64~9 minecraft:wool 11
setblock ~40~65~9 minecraft:concrete 0
setblock ~40~66~9 minecraft:concrete 11
setblock ~41~0~9 minecraft:red_mushroom_block 15
setblock ~41~2~9 minecraft:red_mushroom_block 15
setblock ~41~52~9 minecraft:concrete 11
setblock ~41~53~9 minecraft:concrete 0
setblock ~41~54~9 minecraft:stained_glass 0
setblock ~41~55~9 minecraft:concrete 3
setblock ~41~56~9 minecraft:stained_glass 3
setblock ~41~57~9 minecraft:concrete 11
setblock ~41~58~9 minecraft:concrete 0
setblock ~41~59~9 minecraft:stained_glass 0
setblock ~41~60~9 minecraft:concrete 3
setblock ~41~61~9 minecraft:stained_glass 3
setblock ~41~62~9 minecraft:sea_lantern
setblock ~41~64~9 minecraft:concrete 3
fill ~42~0~9 ~44~0~10 minecraft:grass
setblock ~42~3~9 minecraft:red_mushroom_block 15
fill ~42~4~9 ~43~4~9 minecraft:leaves 0
setblock ~42~52~9 minecraft:stained_glass 3
setblock ~42~53~9 minecraft:concrete 11
setblock ~42~54~9 minecraft:concrete 0
setblock ~42~55~9 minecraft:sea_lantern
setblock ~42~56~9 minecraft:wool 11
setblock ~42~57~9 minecraft:stained_glass 3
setblock ~42~58~9 minecraft:concrete 11
setblock ~42~59~9 minecraft:concrete 0
setblock ~42~60~9 minecraft:concrete 11
setblock ~42~61~9 minecraft:wool 11
setblock ~42~62~9 minecraft:blue_glazed_terracotta 2
setblock ~43~3~9 minecraft:bone_block 0
fill ~44~3~9 ~46~3~9 minecraft:red_mushroom_block 15
fill ~45~4~9 ~46~4~9 minecraft:leaves 0
fill ~47~0~9 ~48~0~10 minecraft:grass
setblock ~47~3~9 minecraft:bone_block 0
fill ~48~2~9 ~48~2~10 minecraft:red_mushroom_block 15
setblock ~49~1~9 minecraft:bone_block 0
setblock ~50~1~9 minecraft:red_mushroom_block 15
setblock ~51~0~9 minecraft:red_mushroom_block 15
fill ~52~0~9 ~52~0~13 minecraft:grass
setblock ~57~0~9 minecraft:dirt 0
fill ~57~1~9 ~58~1~9 minecraft:stone_block_slab 1
setblock ~58~0~9 minecraft:red_mushroom_block 15
setblock ~59~0~9 minecraft:bone_block 0
fill ~61~0~9 ~61~0~10 minecraft:red_mushroom_block 15
fill ~10~2~10 ~10~2~12 minecraft:grass
setblock ~14~42~10 minecraft:concrete 3
fill ~14~43~10 ~14~43~13 minecraft:stained_glass 0
setblock ~14~44~10 minecraft:wool 11
setblock ~15~41~10 minecraft:stained_glass 0
setblock ~15~45~10 minecraft:wool 11
setblock ~15~46~10 minecraft:blue_glazed_terracotta 2
fill ~16~2~10 ~16~2~15 minecraft:grass
setblock ~16~47~10 minecraft:concrete 0
fill ~17~39~10 ~17~40~10 minecraft:leaves 0
setblock ~18~43~10 minecraft:bone_block 0
setblock ~18~48~10 minecraft:stained_glass 0
fill ~19~42~10 ~19~42~12 minecraft:red_mushroom_block 15
fill ~19~43~10 ~20~45~10 minecraft:red_mushroom_block 15
setblock ~19~48~10 minecraft:concrete 11
setblock ~19~52~10 minecraft:concrete 3
fill ~19~53~10 ~19~54~10 minecraft:stained_glass 3
setblock ~19~55~10 minecraft:concrete 0
setblock ~19~56~10 minecraft:stained_glass 3
setblock ~19~57~10 minecraft:concrete 3
fill ~19~58~10 ~19~59~10 minecraft:stained_glass 3
setblock ~19~60~10 minecraft:sea_lantern
setblock ~19~61~10 minecraft:stained_glass 3
fill ~19~62~10 ~19~63~10 minecraft:concrete 11
fill ~20~41~10 ~20~42~10 minecraft:leaves 0
fill ~20~46~10 ~20~46~14 minecraft:red_mushroom_block 15
fill ~20~48~10 ~20~48~11 minecraft:stained_glass 0
setblock ~20~63~10 minecraft:concrete 11
setblock ~20~64~10 minecraft:stained_glass 3
setblock ~20~65~10 minecraft:concrete 3
setblock ~21~2~10 minecraft:bone_block 0
setblock ~21~30~10 minecraft:spruce_trapdoor 3
fill ~21~45~10 ~21~45~11 minecraft:red_mushroom_block 15
fill ~21~47~10 ~22~47~10 minecraft:stained_glass 3
setblock ~21~65~10 minecraft:concrete 11
setblock ~21~66~10 minecraft:wool 11
fill ~21~67~10 ~22~67~10 minecraft:concrete 0
setblock ~21~68~10 minecraft:concrete 11
fill ~22~4~10 ~22~4~11 minecraft:bone_block 0
setblock ~22~68~10 minecraft:blue_glazed_terracotta 2
setblock ~22~69~10 minecraft:concrete 0
setblock ~22~70~10 minecraft:blue_glazed_terracotta 2
setblock ~23~5~10 minecraft:bone_block 0
setblock ~23~45~10 minecraft:concrete 11
setblock ~23~46~10 minecraft:concrete 3
fill ~23~68~10 ~23~69~10 minecraft:stained_glass 0
setblock ~23~70~10 minecraft:concrete 3
setblock ~24~6~10 minecraft:red_mushroom_block 15
setblock ~24~41~10 minecraft:stained_glass 0
setblock ~24~42~10 minecraft:concrete 3
fill ~24~43~10 ~24~43~11 minecraft:stained_glass 3
setblock ~24~44~10 minecraft:concrete 3
setblock ~24~69~10 minecraft:concrete 0
setblock ~24~70~10 minecraft:stained_glass 0
fill ~25~7~10 ~26~7~10 minecraft:red_mushroom_block 15
setblock ~25~69~10 minecraft:stained_glass 3
setblock ~25~70~10 minecraft:blue_glazed_terracotta 2
fill ~25~71~10 ~25~71~11 minecraft:concrete 0
setblock ~26~6~10 minecraft:red_mushroom_block 15
setblock ~26~70~10 minecraft:concrete 0
fill ~26~71~10 ~26~71~11 minecraft:blue_glazed_terracotta 2
setblock ~27~5~10 minecraft:red_mushroom_block 15
setblock ~27~6~10 minecraft:bone_block 0
setblock ~27~70~10 minecraft:wool 11
setblock ~27~71~10 minecraft:concrete 0
setblock ~27~72~10 minecraft:concrete 11
setblock ~28~3~10 minecraft:red_mushroom_block 15
fill ~28~4~10 ~28~4~11 minecraft:leaves 0
setblock ~28~5~10 minecraft:air
fill ~28~71~10 ~28~72~10 minecraft:stained_glass 3
fill ~29~2~10 ~29~2~11 minecraft:red_mushroom_block 15
setblock ~29~72~10 minecraft:stained_glass 3
setblock ~29~73~10 minecraft:concrete 3
fill ~30~0~10 ~30~0~11 minecraft:bone_block 0
fill ~30~71~10 ~31~71~10 minecraft:concrete 3
setblock ~30~72~10 minecraft:concrete 0
setblock ~30~73~10 minecraft:blue_glazed_terracotta 2
setblock ~31~72~10 minecraft:blue_glazed_terracotta 2
setblock ~31~73~10 minecraft:sea_lantern
setblock ~32~71~10 minecraft:concrete 11
setblock ~32~72~10 minecraft:stained_glass 3
setblock ~32~73~10 minecraft:concrete 0
fill ~33~72~10 ~34~72~10 minecraft:concrete 3
setblock ~33~73~10 minecraft:concrete 11
setblock ~34~71~10 minecraft:stained_glass 3
setblock ~34~73~10 minecraft:blue_glazed_terracotta 2
fill ~35~70~10 ~35~71~10 minecraft:blue_glazed_terracotta 2
setblock ~35~72~10 minecraft:concrete 11
fill ~36~70~10 ~37~71~10 minecraft:wool 11
setblock ~36~72~10 minecraft:concrete 0
fill ~37~69~10 ~38~69~10 minecraft:stained_glass 3
setblock ~39~0~10 minecraft:bone_block 0
setblock ~39~1~10 minecraft:red_mushroom_block 15
setblock ~39~3~10 minecraft:leaves 0
setblock ~39~68~10 minecraft:concrete 0
setblock ~39~69~10 minecraft:blue_glazed_terracotta 2
setblock ~40~2~10 minecraft:red_mushroom_block 15
setblock ~40~67~10 minecraft:concrete 11
setblock ~40~68~10 minecraft:stained_glass 3
setblock ~40~69~10 minecraft:stained_glass 0
setblock ~41~0~10 minecraft:grass
setblock ~41~3~10 minecraft:bone_block 0
setblock ~41~65~10 minecraft:stained_glass 3
setblock ~41~66~10 minecraft:stained_glass 0
setblock ~41~67~10 minecraft:stained_glass 3
setblock ~41~68~10 minecraft:wool 11
setblock ~42~4~10 minecraft:red_mushroom_block 15
setblock ~42~63~10 minecraft:concrete 3
setblock ~42~64~10 minecraft:stained_glass 0
setblock ~42~65~10 minecraft:blue_glazed_terracotta 2
fill ~43~4~10 ~43~4~11 minecraft:leaves 0
setblock ~43~52~10 minecraft:concrete 3
setblock ~43~53~10 minecraft:blue_glazed_terracotta 2
setblock ~43~54~10 minecraft:wool 11
setblock ~43~55~10 minecraft:concrete 3
setblock ~43~56~10 minecraft:concrete 11
setblock ~43~57~10 minecraft:concrete 3
setblock ~43~58~10 minecraft:blue_glazed_terracotta 2
setblock ~43~59~10 minecraft:wool 11
setblock ~43~60~10 minecraft:concrete 3
setblock ~43~61~10 minecraft:concrete 11
setblock ~43~62~10 minecraft:blue_glazed_terracotta 2
setblock ~43~63~10 minecraft:stained_glass 3
fill ~44~4~10 ~45~4~10 minecraft:red_mushroom_block 15
fill ~44~5~10 ~45~5~10 minecraft:leaves 0
fill ~46~3~10 ~47~3~10 minecraft:red_mushroom_block 15
setblock ~46~4~10 minecraft:bone_block 0
setblock ~49~1~10 minecraft:red_mushroom_block 15
setblock ~50~0~10 minecraft:red_mushroom_block 15
setblock ~51~0~10 minecraft:dirt 0
fill ~57~1~10 ~58~1~10 minecraft:sandstone 3
fill ~59~0~10 ~59~0~11 minecraft:red_mushroom_block 15
fill ~59~1~10 ~59~1~11 minecraft:stone_block_slab 1
setblock ~60~0~10 minecraft:bone_block 0
fill ~9~2~11 ~9~2~12 minecraft:grass
fill ~11~2~11 ~11~2~13 minecraft:grass
setblock ~14~41~11 minecraft:concrete 3
setblock ~14~42~11 minecraft:concrete 0
fill ~14~44~11 ~14~45~11 minecraft:stained_glass 0
fill ~15~2~11 ~15~2~14 minecraft:grass
setblock ~15~46~11 minecraft:stained_glass 3
fill ~16~38~11 ~17~38~11 minecraft:leaves 0
fill ~16~47~11 ~16~47~12 minecraft:stained_glass 0
fill ~17~36~11 ~17~36~12 minecraft:leaves 0
setblock ~17~37~11 minecraft:leaves 0
setblock ~17~39~11 minecraft:leaves 3
setblock ~17~48~11 minecraft:concrete 11
fill ~18~39~11 ~19~39~13 minecraft:red_mushroom_block 15
fill ~18~40~11 ~19~41~11 minecraft:red_mushroom_block 15
fill ~18~42~11 ~18~42~13 minecraft:bone_block 0
fill ~18~43~11 ~18~43~14 minecraft:red_mushroom_block 15
fill ~18~44~11 ~21~44~11 minecraft:red_mushroom_block 15
fill ~18~45~11 ~18~45~13 minecraft:red_mushroom_block 15
setblock ~18~48~11 minecraft:stained_glass 3
setblock ~18~52~11 minecraft:stained_glass 0
fill ~18~53~11 ~18~54~11 minecraft:blue_glazed_terracotta 2
setblock ~18~55~11 minecraft:wool 11
setblock ~18~56~11 minecraft:sea_lantern
setblock ~18~57~11 minecraft:stained_glass 0
fill ~18~58~11 ~18~59~11 minecraft:blue_glazed_terracotta 2
setblock ~18~60~11 minecraft:wool 11
setblock ~18~61~11 minecraft:concrete 3
fill ~18~62~11 ~18~63~11 minecraft:concrete 0
setblock ~18~64~11 minecraft:wool 11
fill ~19~2~11 ~19~2~17 minecraft:grass
setblock ~19~38~11 minecraft:red_mushroom_block 15
setblock ~19~43~11 minecraft:bone_block 0
fill ~19~45~11 ~20~45~12 minecraft:bone_block 0
setblock ~19~46~11 minecraft:red_mushroom_block 15
setblock ~19~48~11 minecraft:sea_lantern
setblock ~19~64~11 minecraft:concrete 0
setblock ~19~65~11 minecraft:stained_glass 0
setblock ~19~66~11 minecraft:stained_glass 3
fill ~20~1~11 ~20~1~16 minecraft:grass
setblock ~20~30~11 minecraft:spruce_trapdoor 1
fill ~20~39~11 ~20~39~12 minecraft:bone_block 0
fill ~20~40~11 ~20~41~11 minecraft:bone_block 0
fill ~20~42~11 ~20~43~11 minecraft:red_mushroom_block 15
fill ~20~66~11 ~20~68~11 minecraft:concrete 3
setblock ~20~69~11 minecraft:concrete 11
setblock ~21~1~11 minecraft:bone_block 0
setblock ~21~29~11 minecraft:double_wooden_slab 5
setblock ~21~30~11 minecraft:sea_lantern
setblock ~21~31~11 minecraft:leaves 3
setblock ~21~32~11 minecraft:azalea_leaves 0
setblock ~21~33~11 minecraft:air
fill ~21~40~11 ~22~40~11 minecraft:leaves 0
setblock ~21~41~11 minecraft:leaves 3
setblock ~21~46~11 minecraft:bone_block 0
setblock ~21~48~11 minecraft:concrete 3
setblock ~21~68~11 minecraft:concrete 0
setblock ~21~69~11 minecraft:concrete 3
setblock ~21~70~11 minecraft:stained_glass 0
fill ~22~2~11 ~22~2~13 minecraft:red_mushroom_block 15
fill ~22~29~11 ~23~29~14 minecraft:wooden_slab 5
setblock ~22~30~11 minecraft:spruce_trapdoor 1
fill ~22~39~11 ~22~39~12 minecraft:leaves 0
setblock ~22~41~11 minecraft:air
setblock ~22~47~11 minecraft:concrete 3
setblock ~22~68~11 minecraft:wool 11
setblock ~22~71~11 minecraft:concrete 3
fill ~23~0~11 ~23~0~14 minecraft:grass
fill ~23~5~11 ~23~5~14 minecraft:red_mushroom_block 15
setblock ~23~46~11 minecraft:stained_glass 0
setblock ~23~69~11 minecraft:blue_glazed_terracotta 2
setblock ~23~71~11 minecraft:stained_glass 0
setblock ~23~72~11 minecraft:blue_glazed_terracotta 2
fill ~24~6~11 ~24~7~11 minecraft:bone_block 0
setblock ~24~41~11 minecraft:concrete 0
setblock ~24~42~11 minecraft:blue_glazed_terracotta 2
fill ~24~44~11 ~24~44~13 minecraft:blue_glazed_terracotta 2
setblock ~24~45~11 minecraft:wool 11
fill ~24~70~11 ~24~71~11 minecraft:wool 11
fill ~24~72~11 ~25~72~11 minecraft:concrete 11
fill ~24~73~11 ~25~73~11 minecraft:stained_glass 0
setblock ~25~8~11 minecraft:bone_block 0
setblock ~26~8~11 minecraft:red_mushroom_block 15
fill ~26~72~11 ~26~72~12 minecraft:stained_glass 3
setblock ~26~73~11 minecraft:concrete 11
setblock ~27~7~11 minecraft:red_mushroom_block 15
setblock ~27~72~11 minecraft:concrete 0
setblock ~27~73~11 minecraft:wool 11
fill ~28~5~11 ~28~7~11 minecraft:leaves 0
setblock ~28~8~11 minecraft:air
setblock ~28~72~11 minecraft:concrete 3
setblock ~28~73~11 minecraft:concrete 0
setblock ~28~74~11 minecraft:concrete 11
fill ~29~3~11 ~29~3~12 minecraft:leaves 0
setblock ~29~4~11 minecraft:leaves2 3
setblock ~29~5~11 minecraft:air
setblock ~29~74~11 minecraft:blue_glazed_terracotta 2
fill ~30~1~11 ~30~1~14 minecraft:red_mushroom_block 15
setblock ~30~71~11 minecraft:concrete 3
setblock ~30~74~11 minecraft:wool 11
setblock ~31~74~11 minecraft:concrete 0
setblock ~32~74~11 minecraft:concrete 3
fill ~33~74~11 ~34~74~11 minecraft:stained_glass 3
setblock ~35~72~11 minecraft:stained_glass 0
fill ~35~73~11 ~36~73~11 minecraft:concrete 11
setblock ~35~74~11 minecraft:blue_glazed_terracotta 2
setblock ~36~71~11 minecraft:concrete 0
fill ~36~72~11 ~38~72~11 minecraft:concrete 3
setblock ~37~71~11 minecraft:concrete 3
setblock ~37~73~11 minecraft:stained_glass 0
setblock ~38~0~11 minecraft:red_mushroom_block 15
setblock ~38~1~11 minecraft:bone_block 0
setblock ~38~3~11 minecraft:leaves 0
setblock ~38~4~11 minecraft:air
fill ~38~70~11 ~38~71~11 minecraft:concrete 0
setblock ~38~73~11 minecraft:concrete 11
fill ~39~2~11 ~39~3~11 minecraft:red_mushroom_block 15
setblock ~39~70~11 minecraft:stained_glass 0
setblock ~39~71~11 minecraft:blue_glazed_terracotta 2
setblock ~39~72~11 minecraft:stained_glass 0
setblock ~40~2~11 minecraft:sea_lantern
fill ~40~3~11 ~40~4~11 minecraft:red_mushroom_block 15
setblock ~40~69~11 minecraft:wool 11
setblock ~40~70~11 minecraft:concrete 3
fill ~41~4~11 ~41~5~11 minecraft:red_mushroom_block 15
setblock ~41~69~11 minecraft:blue_glazed_terracotta 2
setblock ~41~70~11 minecraft:concrete 0
setblock ~42~5~11 minecraft:red_mushroom_block 15
setblock ~42~66~11 minecraft:wool 11
setblock ~42~67~11 minecraft:stained_glass 3
setblock ~42~68~11 minecraft:concrete 11
setblock ~42~69~11 minecraft:concrete 0
fill ~43~5~11 ~44~5~12 minecraft:leaves 0
fill ~43~64~11 ~44~64~11 minecraft:wool 11
setblock ~43~65~11 minecraft:stained_glass 0
setblock ~43~66~11 minecraft:concrete 3
fill ~43~67~11 ~43~67~12 minecraft:concrete 0
setblock ~43~68~11 minecraft:wool 11
setblock ~44~0~11 minecraft:tallgrass 0
setblock ~44~52~11 minecraft:wool 11
setblock ~44~53~11 minecraft:stained_glass 0
setblock ~44~54~11 minecraft:concrete 0
setblock ~44~55~11 minecraft:blue_glazed_terracotta 2
fill ~44~56~11 ~44~57~11 minecraft:wool 11
setblock ~44~58~11 minecraft:stained_glass 0
setblock ~44~59~11 minecraft:concrete 0
setblock ~44~60~11 minecraft:blue_glazed_terracotta 2
setblock ~44~61~11 minecraft:wool 11
setblock ~44~62~11 minecraft:concrete 0
setblock ~44~63~11 minecraft:stained_glass 3
setblock ~45~4~11 minecraft:bone_block 0
setblock ~45~5~11 minecraft:red_mushroom_block 15
fill ~46~0~11 ~47~0~11 minecraft:grass
fill ~46~3~11 ~46~3~12 minecraft:bone_block 0
setblock ~47~2~11 minecraft:red_mushroom_block 15
setblock ~48~1~11 minecraft:red_mushroom_block 15
setblock ~49~0~11 minecraft:bone_block 0
fill ~50~0~11 ~51~0~12 minecraft:grass
fill ~57~0~11 ~57~0~12 minecraft:dirt 0
fill ~57~1~11 ~57~1~12 minecraft:grass
setblock ~58~1~11 minecraft:red_mushroom_block 15
fill ~60~0~11 ~61~0~11 minecraft:bone_block 0
fill ~8~3~12 ~8~3~13 minecraft:grass
fill ~12~2~12 ~14~2~13 minecraft:grass
setblock ~14~41~12 minecraft:stained_glass 3
setblock ~14~42~12 minecraft:wool 11
fill ~14~44~12 ~14~44~13 minecraft:concrete 3
setblock ~14~45~12 minecraft:concrete 0
setblock ~15~46~12 minecraft:wool 11
setblock ~17~3~12 minecraft:tallgrass 0
fill ~17~34~12 ~17~35~12 minecraft:leaves 0
fill ~17~48~12 ~17~48~13 minecraft:blue_glazed_terracotta 2
setblock ~17~52~12 minecraft:wool 11
setblock ~17~53~12 minecraft:blue_glazed_terracotta 2
setblock ~17~54~12 minecraft:stained_glass 3
setblock ~17~55~12 minecraft:wool 11
setblock ~17~56~12 minecraft:concrete 11
setblock ~17~57~12 minecraft:wool 11
setblock ~17~58~12 minecraft:blue_glazed_terracotta 2
setblock ~17~59~12 minecraft:stained_glass 3
setblock ~17~60~12 minecraft:wool 11
setblock ~17~61~12 minecraft:concrete 11
setblock ~17~62~12 minecraft:stained_glass 3
setblock ~17~63~12 minecraft:sea_lantern
setblock ~17~64~12 minecraft:concrete 3
fill ~18~38~12 ~19~38~12 minecraft:bone_block 0
fill ~18~40~12 ~18~41~13 minecraft:red_mushroom_block 15
fill ~18~44~12 ~20~44~12 minecraft:red_mushroom_block 15
setblock ~18~46~12 minecraft:red_mushroom_block 15
fill ~18~48~12 ~19~48~12 minecraft:wool 11
setblock ~18~65~12 minecraft:wool 11
setblock ~18~66~12 minecraft:concrete 11
fill ~19~35~12 ~21~36~12 minecraft:red_mushroom_block 15
setblock ~19~37~12 minecraft:red_mushroom_block 15
fill ~19~40~12 ~19~40~13 minecraft:bone_block 0
setblock ~19~41~12 minecraft:bone_block 0
fill ~19~43~12 ~20~43~14 minecraft:red_mushroom_block 15
fill ~19~46~12 ~19~46~13 minecraft:bone_block 0
setblock ~19~67~12 minecraft:wool 11
setblock ~19~68~12 minecraft:blue_glazed_terracotta 3
fill ~20~29~12 ~21~29~12 minecraft:wooden_slab 5
setblock ~20~37~12 minecraft:bone_block 0
fill ~20~38~12 ~20~38~14 minecraft:red_mushroom_block 15
fill ~20~40~12 ~20~41~12 minecraft:red_mushroom_block 15
setblock ~20~42~12 minecraft:bone_block 0
fill ~20~47~12 ~20~47~14 minecraft:red_mushroom_block 15
setblock ~20~48~12 minecraft:concrete 3
fill ~20~68~12 ~20~69~12 minecraft:concrete 3
setblock ~20~70~12 minecraft:stained_glass 3
setblock ~21~1~12 minecraft:grass
setblock ~21~30~12 minecraft:spruce_trapdoor 2
setblock ~21~37~12 minecraft:red_mushroom_block 15
setblock ~21~45~12 minecraft:bone_block 0
fill ~21~46~12 ~21~46~13 minecraft:red_mushroom_block 15
setblock ~21~48~12 minecraft:wool 11
setblock ~21~68~12 minecraft:blue_glazed_terracotta 2
setblock ~21~71~12 minecraft:concrete 11
setblock ~22~1~12 minecraft:red_mushroom_block 15
fill ~22~3~12 ~22~3~13 minecraft:bone_block 0
setblock ~22~47~12 minecraft:stained_glass 3
setblock ~22~72~12 minecraft:concrete 11
fill ~23~4~12 ~23~4~13 minecraft:red_mushroom_block 15
fill ~23~6~12 ~23~6~14 minecraft:red_mushroom_block 15
setblock ~23~46~12 minecraft:stained_glass 3
setblock ~23~71~12 minecraft:concrete 3
setblock ~23~73~12 minecraft:wool 11
fill ~24~7~12 ~24~7~17 minecraft:red_mushroom_block 15
setblock ~24~8~12 minecraft:red_mushroom_block 15
fill ~24~29~12 ~24~29~14 minecraft:wooden_slab 13
setblock ~24~41~12 minecraft:stained_glass 0
setblock ~24~42~12 minecraft:wool 11
setblock ~24~43~12 minecraft:concrete 3
setblock ~24~45~12 minecraft:stained_glass 0
setblock ~24~72~12 minecraft:stained_glass 3
setblock ~24~73~12 minecraft:concrete 0
setblock ~25~9~12 minecraft:red_mushroom_block 15
fill ~25~30~12 ~25~30~16 minecraft:wooden_slab 5
fill ~25~74~12 ~26~74~12 minecraft:concrete 0
setblock ~26~9~12 minecraft:bone_block 0
setblock ~26~10~12 minecraft:red_mushroom_block 15
setblock ~26~75~12 minecraft:concrete 11
fill ~27~8~12 ~27~9~12 minecraft:red_mushroom_block 15
setblock ~27~74~12 minecraft:blue_glazed_terracotta 2
setblock ~27~75~12 minecraft:stained_glass 3
setblock ~28~6~12 minecraft:red_mushroom_block 15
fill ~28~7~12 ~28~9~12 minecraft:leaves 0
setblock ~28~10~12 minecraft:air
setblock ~28~32~12 minecraft:spruce_trapdoor 3
setblock ~28~75~12 minecraft:concrete 11
setblock ~29~2~12 minecraft:bone_block 0
setblock ~29~4~12 minecraft:bone_block 0
setblock ~29~5~12 minecraft:red_mushroom_block 15
setblock ~29~75~12 minecraft:stained_glass 0
fill ~30~0~12 ~30~0~16 minecraft:red_mushroom_block 15
fill ~30~3~12 ~30~3~13 minecraft:leaves 0
setblock ~30~75~12 minecraft:concrete 11
setblock ~31~75~12 minecraft:wool 11
setblock ~32~75~12 minecraft:stained_glass 0
setblock ~33~75~12 minecraft:stained_glass 3
setblock ~34~75~12 minecraft:concrete 0
setblock ~35~75~12 minecraft:stained_glass 0
setblock ~36~73~12 minecraft:stained_glass 0
fill ~36~74~12 ~37~74~12 minecraft:blue_glazed_terracotta 2
setblock ~37~0~12 minecraft:red_mushroom_block 15
fill ~37~4~12 ~37~5~12 minecraft:leaves 0
setblock ~37~6~12 minecraft:air
setblock ~37~73~12 minecraft:blue_glazed_terracotta 2
fill ~38~1~12 ~38~3~12 minecraft:red_mushroom_block 15
setblock ~38~4~12 minecraft:leaves2 3
setblock ~38~5~12 minecraft:air
setblock ~38~72~12 minecraft:concrete 11
setblock ~38~74~12 minecraft:concrete 3
setblock ~39~4~12 minecraft:bone_block 0
fill ~39~5~12 ~40~5~12 minecraft:red_mushroom_block 15
setblock ~39~70~12 minecraft:blue_glazed_terracotta 2
fill ~39~72~12 ~39~73~12 minecraft:concrete 0
setblock ~40~6~12 minecraft:bone_block 0
setblock ~40~71~12 minecraft:blue_glazed_terracotta 2
fill ~41~6~12 ~42~6~12 minecraft:red_mushroom_block 15
setblock ~41~7~12 minecraft:red_mushroom_block 15
setblock ~41~70~12 minecraft:blue_glazed_terracotta 2
setblock ~41~71~12 minecraft:concrete 3
setblock ~42~7~12 minecraft:bone_block 0
setblock ~42~69~12 minecraft:blue_glazed_terracotta 2
setblock ~42~70~12 minecraft:stained_glass 0
setblock ~43~6~12 minecraft:bone_block 0
setblock ~43~68~12 minecraft:concrete 0
setblock ~43~69~12 minecraft:concrete 3
setblock ~44~6~12 minecraft:leaves 0
setblock ~44~7~12 minecraft:air
setblock ~44~65~12 minecraft:blue_glazed_terracotta 2
setblock ~44~66~12 minecraft:stained_glass 3
setblock ~44~67~12 minecraft:concrete 3
setblock ~44~68~12 minecraft:wool 11
setblock ~45~4~12 minecraft:red_mushroom_block 15
setblock ~45~52~12 minecraft:blue_glazed_terracotta 2
setblock ~45~53~12 minecraft:stained_glass 0
setblock ~45~54~12 minecraft:concrete 3
setblock ~45~55~12 minecraft:concrete 11
setblock ~45~56~12 minecraft:stained_glass 3
setblock ~45~57~12 minecraft:blue_glazed_terracotta 2
setblock ~45~58~12 minecraft:stained_glass 0
setblock ~45~59~12 minecraft:concrete 3
setblock ~45~60~12 minecraft:concrete 11
fill ~45~61~12 ~45~62~12 minecraft:stained_glass 3
setblock ~45~63~12 minecraft:concrete 3
setblock ~45~64~12 minecraft:sea_lantern
setblock ~46~2~12 minecraft:bone_block 0
setblock ~47~1~12 minecraft:red_mushroom_block 15
setblock ~48~0~12 minecraft:red_mushroom_block 15
setblock ~49~0~12 minecraft:grass
setblock ~52~1~12 minecraft:tallgrass 0
fill ~58~1~12 ~58~1~17 minecraft:grass
setblock ~59~1~12 minecraft:bone_block 0
setblock ~60~0~12 minecraft:bone_block 0
fill ~60~1~12 ~61~1~12 minecraft:stone_block_slab 1
setblock ~61~0~12 minecraft:red_mushroom_block 15
setblock ~7~3~13 minecraft:grass
fill ~9~2~13 ~10~2~13 minecraft:red_mushroom_block 15
setblock ~14~41~13 minecraft:concrete 11
setblock ~14~42~13 minecraft:concrete 3
setblock ~14~45~13 minecraft:concrete 3
fill ~15~46~13 ~15~46~14 minecraft:stained_glass 0
setblock ~16~47~13 minecraft:stained_glass 3
setblock ~16~52~13 minecraft:blue_glazed_terracotta 2
setblock ~16~53~13 minecraft:wool 11
setblock ~16~54~13 minecraft:concrete 11
setblock ~16~55~13 minecraft:wool 11
setblock ~16~56~13 minecraft:concrete 0
setblock ~16~57~13 minecraft:blue_glazed_terracotta 2
setblock ~16~58~13 minecraft:wool 11
setblock ~16~59~13 minecraft:concrete 11
setblock ~16~60~13 minecraft:wool 11
setblock ~16~61~13 minecraft:concrete 0
setblock ~16~62~13 minecraft:concrete 11
setblock ~16~63~13 minecraft:wool 11
fill ~16~64~13 ~16~64~14 minecraft:stained_glass 0
fill ~17~65~13 ~17~66~13 minecraft:concrete 0
setblock ~18~34~13 minecraft:leaves 3
fill ~18~35~13 ~18~38~14 minecraft:red_mushroom_block 15
fill ~18~44~13 ~18~44~14 minecraft:bone_block 0
setblock ~18~46~13 minecraft:bone_block 0
setblock ~18~48~13 minecraft:blue_glazed_terracotta 2
setblock ~18~67~13 minecraft:wool 11
fill ~18~68~13 ~18~68~14 minecraft:concrete 0
fill ~18~69~13 ~20~69~13 minecraft:stained_glass 3
fill ~19~28~13 ~20~28~13 minecraft:wooden_slab 13
fill ~19~34~13 ~19~35~13 minecraft:bone_block 0
fill ~19~36~13 ~22~36~14 minecraft:red_mushroom_block 15
fill ~19~37~13 ~19~37~14 minecraft:bone_block 0
setblock ~19~38~13 minecraft:red_mushroom_block 15
fill ~19~41~13 ~20~41~13 minecraft:red_mushroom_block 15
fill ~19~42~13 ~19~42~14 minecraft:bone_block 0
fill ~19~44~13 ~20~44~14 minecraft:red_mushroom_block 15
fill ~19~45~13 ~19~45~14 minecraft:red_mushroom_block 15
setblock ~19~47~13 minecraft:bone_block 0
setblock ~19~48~13 minecraft:concrete 3
setblock ~19~70~13 minecraft:stained_glass 3
setblock ~20~2~13 minecraft:tallgrass 0
fill ~20~33~13 ~20~33~14 minecraft:bone_block 0
fill ~20~34~13 ~20~35~13 minecraft:red_mushroom_block 15
fill ~20~37~13 ~20~37~14 minecraft:red_mushroom_block 15
fill ~20~39~13 ~22~39~14 minecraft:red_mushroom_block 15
setblock ~20~40~13 minecraft:bone_block 0
setblock ~20~42~13 minecraft:red_mushroom_block 10
setblock ~20~45~13 minecraft:bone_block 0
fill ~20~48~13 ~21~48~13 minecraft:stained_glass 0
setblock ~20~70~13 minecraft:concrete 3
setblock ~20~71~13 minecraft:wool 11
setblock ~21~29~13 minecraft:wooden_slab 5
fill ~21~33~13 ~22~33~15 minecraft:red_mushroom_block 15
fill ~21~34~13 ~22~34~13 minecraft:bone_block 0
fill ~21~35~13 ~22~35~16 minecraft:red_mushroom_block 15
fill ~21~37~13 ~21~38~13 minecraft:bone_block 0
fill ~21~40~13 ~21~40~14 minecraft:red_mushroom_block 15
setblock ~21~45~13 minecraft:red_mushroom_block 15
setblock ~21~47~13 minecraft:bone_block 0
setblock ~21~72~13 minecraft:concrete 11
setblock ~22~1~13 minecraft:bone_block 0
fill ~22~37~13 ~22~37~16 minecraft:red_mushroom_block 15
setblock ~22~40~13 minecraft:air
setblock ~22~47~13 minecraft:concrete 11
setblock ~22~73~13 minecraft:wool 11
fill ~23~38~13 ~23~38~14 minecraft:leaves 0
setblock ~23~39~13 minecraft:leaves 3
setblock ~23~46~13 minecraft:concrete 11
setblock ~23~74~13 minecraft:stained_glass 0
fill ~24~8~13 ~24~9~13 minecraft:bone_block 0
setblock ~24~41~13 minecraft:concrete 0
setblock ~24~42~13 minecraft:concrete 11
fill ~24~43~13 ~24~43~14 minecraft:wool 11
setblock ~24~45~13 minecraft:blue_glazed_terracotta 2
setblock ~24~74~13 minecraft:blue_glazed_terracotta 2
setblock ~25~10~13 minecraft:bone_block 0
setblock ~25~75~13 minecraft:concrete 3
setblock ~26~0~13 minecraft:sea_lantern
fill ~26~11~13 ~26~12~13 minecraft:bone_block 0
fill ~26~30~13 ~26~30~17 minecraft:wooden_slab 13
setblock ~26~76~13 minecraft:concrete 0
fill ~27~10~13 ~27~16~13 minecraft:leaves 0
setblock ~27~17~13 minecraft:air
setblock ~27~32~13 minecraft:spruce_trapdoor 1
setblock ~27~76~13 minecraft:stained_glass 3
setblock ~28~7~13 minecraft:red_mushroom_block 15
setblock ~28~8~13 minecraft:bone_block 0
setblock ~28~9~13 minecraft:red_mushroom_block 15
setblock ~28~10~13 minecraft:leaves2 3
setblock ~28~11~13 minecraft:air
fill ~28~31~13 ~28~31~17 minecraft:wooden_slab 13
setblock ~28~32~13 minecraft:sea_lantern
setblock ~28~33~13 minecraft:azalea_leaves_flowered 0
setblock ~28~34~13 minecraft:azalea_leaves 0
setblock ~28~35~13 minecraft:air
setblock ~28~76~13 minecraft:stained_glass 0
fill ~29~3~13 ~29~4~13 minecraft:red_mushroom_block 15
setblock ~29~5~13 minecraft:bone_block 0
fill ~29~6~13 ~29~6~15 minecraft:red_mushroom_block 15
setblock ~29~32~13 minecraft:spruce_trapdoor 1
setblock ~29~76~13 minecraft:wool 11
fill ~30~2~13 ~30~2~15 minecraft:red_mushroom_block 15
fill ~30~4~13 ~30~4~14 minecraft:leaves 0
fill ~30~76~13 ~31~76~13 minecraft:stained_glass 3
setblock ~32~76~13 minecraft:stained_glass 0
setblock ~33~76~13 minecraft:concrete 0
fill ~34~76~13 ~35~76~13 minecraft:stained_glass 0
fill ~36~0~13 ~36~0~14 minecraft:red_mushroom_block 15
setblock ~36~75~13 minecraft:concrete 0
setblock ~37~1~13 minecraft:bone_block 0
setblock ~37~2~13 minecraft:red_mushroom_block 15
setblock ~37~3~13 minecraft:bone_block 0
fill ~37~5~13 ~37~7~13 minecraft:leaves 0
setblock ~37~8~13 minecraft:air
setblock ~37~75~13 minecraft:concrete 3
setblock ~38~4~13 minecraft:bone_block 0
fill ~38~5~13 ~38~6~13 minecraft:red_mushroom_block 15
fill ~38~74~13 ~39~74~13 minecraft:stained_glass 3
fill ~39~6~13 ~39~7~13 minecraft:red_mushroom_block 15
setblock ~39~8~13 minecraft:bone_block 0
setblock ~39~73~13 minecraft:concrete 0
setblock ~40~7~13 minecraft:bone_block 0
fill ~40~8~13 ~41~8~13 minecraft:red_mushroom_block 15
setblock ~40~71~13 minecraft:concrete 0
setblock ~40~72~13 minecraft:stained_glass 3
setblock ~41~72~13 minecraft:blue_glazed_terracotta 2
setblock ~42~7~13 minecraft:red_mushroom_block 15
setblock ~42~8~13 minecraft:bone_block 0
setblock ~42~70~13 minecraft:concrete 0
fill ~42~71~13 ~43~71~13 minecraft:concrete 3
setblock ~43~6~13 minecraft:leaves 0
setblock ~43~68~13 minecraft:concrete 11
fill ~43~69~13 ~43~69~14 minecraft:concrete 0
setblock ~43~70~13 minecraft:blue_glazed_terracotta 2
fill ~44~4~13 ~44~4~14 minecraft:red_mushroom_block 15
setblock ~44~5~13 minecraft:red_mushroom_block 15
setblock ~44~6~13 minecraft:leaves2 3
fill ~44~67~13 ~45~67~13 minecraft:stained_glass 0
setblock ~44~69~13 minecraft:concrete 3
setblock ~45~3~13 minecraft:red_mushroom_block 15
setblock ~45~65~13 minecraft:concrete 11
setblock ~45~66~13 minecraft:blue_glazed_terracotta 2
setblock ~45~68~13 minecraft:stained_glass 3
setblock ~46~1~13 minecraft:bone_block 0
setblock ~46~2~13 minecraft:red_mushroom_block 15
fill ~46~52~13 ~46~54~13 minecraft:concrete 0
fill ~46~55~13 ~46~56~13 minecraft:stained_glass 0
setblock ~46~57~13 minecraft:concrete 0
setblock ~46~58~13 minecraft:sea_lantern
setblock ~46~59~13 minecraft:concrete 0
fill ~46~60~13 ~46~61~13 minecraft:stained_glass 0
setblock ~46~62~13 minecraft:concrete 11
setblock ~46~63~13 minecraft:stained_glass 0
setblock ~46~64~13 minecraft:concrete 0
setblock ~47~0~13 minecraft:red_mushroom_block 15
setblock ~48~0~13 minecraft:tallgrass 0
fill ~51~0~13 ~51~0~14 minecraft:grass
fill ~54~0~13 ~55~0~19 minecraft:grass
fill ~57~0~13 ~57~0~14 minecraft:grass
fill ~59~1~13 ~59~1~14 minecraft:red_mushroom_block 15
setblock ~60~1~13 minecraft:bone_block 0
setblock ~61~1~13 minecraft:sandstone 3
fill ~6~3~14 ~7~3~14 minecraft:leaves 0
setblock ~7~4~14 minecraft:air
fill ~8~3~14 ~9~3~14 minecraft:bone_block 0
fill ~8~4~14 ~11~4~14 minecraft:leaves 0
setblock ~8~5~14 minecraft:air
fill ~10~3~14 ~11~3~14 minecraft:red_mushroom_block 15
setblock ~10~5~14 minecraft:air
fill ~11~5~14 ~12~5~14 minecraft:leaves 0
setblock ~11~6~14 minecraft:air
setblock ~12~2~14 minecraft:red_mushroom_block 15
fill ~13~2~14 ~14~2~14 minecraft:grass
setblock ~14~42~14 minecraft:stained_glass 3
setblock ~14~43~14 minecraft:concrete 11
setblock ~14~44~14 minecraft:stained_glass 3
setblock ~15~41~14 minecraft:concrete 11
setblock ~15~45~14 minecraft:blue_glazed_terracotta 2
setblock ~15~52~14 minecraft:wool 11
setblock ~15~53~14 minecraft:concrete 3
setblock ~15~54~14 minecraft:blue_glazed_terracotta 2
setblock ~15~55~14 minecraft:stained_glass 0
setblock ~15~56~14 minecraft:stained_glass 3
setblock ~15~57~14 minecraft:wool 11
setblock ~15~58~14 minecraft:concrete 3
setblock ~15~59~14 minecraft:blue_glazed_terracotta 2
setblock ~15~60~14 minecraft:stained_glass 0
setblock ~15~61~14 minecraft:stained_glass 3
setblock ~15~62~14 minecraft:concrete 11
setblock ~15~63~14 minecraft:stained_glass 3
setblock ~16~47~14 minecraft:concrete 11
setblock ~16~65~14 minecraft:wool 11
setblock ~16~66~14 minecraft:stained_glass 3
setblock ~17~47~14 minecraft:blue_glazed_terracotta 2
fill ~17~67~14 ~17~68~14 minecraft:stained_glass 3
setblock ~17~69~14 minecraft:stained_glass 0
fill ~18~2~14 ~18~2~16 minecraft:grass
fill ~18~28~14 ~20~28~15 minecraft:wooden_slab 5
setblock ~18~45~14 minecraft:bone_block 0
setblock ~18~48~14 minecraft:stained_glass 0
setblock ~18~70~14 minecraft:stained_glass 3
fill ~19~33~14 ~19~33~16 minecraft:red_mushroom_block 15
setblock ~19~34~14 minecraft:red_mushroom_block 10
fill ~19~35~14 ~19~35~16 minecraft:red_mushroom_block 15
fill ~19~38~14 ~19~38~15 minecraft:bone_block 0
setblock ~19~39~14 minecraft:bone_block 0
setblock ~19~46~14 minecraft:red_mushroom_block 15
setblock ~19~48~14 minecraft:concrete 11
setblock ~19~71~14 minecraft:sea_lantern
fill ~20~32~14 ~21~32~14 minecraft:bone_block 0
fill ~20~34~14 ~20~35~14 minecraft:bone_block 0
setblock ~20~40~14 minecraft:red_mushroom_block 15
setblock ~20~45~14 minecraft:red_mushroom_block 10
setblock ~20~48~14 minecraft:concrete 3
setblock ~20~72~14 minecraft:concrete 11
fill ~21~1~14 ~21~1~18 minecraft:grass
fill ~21~28~14 ~21~28~15 minecraft:wooden_slab 13
fill ~21~34~14 ~23~34~14 minecraft:red_mushroom_block 15
fill ~21~37~14 ~21~38~15 minecraft:red_mushroom_block 15
setblock ~21~46~14 minecraft:bone_block 0
setblock ~21~47~14 minecraft:concrete 3
setblock ~21~73~14 minecraft:blue_glazed_terracotta 2
setblock ~22~1~14 minecraft:red_mushroom_block 15
setblock ~22~32~14 minecraft:red_mushroom_block 15
setblock ~22~38~14 minecraft:red_mushroom_block 15
setblock ~22~47~14 minecraft:blue_glazed_terracotta 2
setblock ~22~74~14 minecraft:stained_glass 3
fill ~23~2~14 ~23~2~16 minecraft:red_mushroom_block 15
fill ~23~3~14 ~23~3~15 minecraft:red_mushroom_block 15
fill ~23~4~14 ~23~4~15 minecraft:bone_block 0
setblock ~23~33~14 minecraft:bone_block 0
setblock ~23~35~14 minecraft:bone_block 0
fill ~23~37~14 ~23~37~16 minecraft:leaves 0
setblock ~23~39~14 minecraft:air
setblock ~23~45~14 minecraft:concrete 11
setblock ~23~46~14 minecraft:concrete 0
setblock ~23~75~14 minecraft:stained_glass 0
fill ~24~0~14 ~24~0~16 minecraft:grass
setblock ~24~8~14 minecraft:red_mushroom_block 10
fill ~24~9~14 ~24~9~16 minecraft:red_mushroom_block 15
setblock ~24~10~14 minecraft:red_mushroom_block 15
setblock ~24~41~14 minecraft:stained_glass 3
setblock ~24~42~14 minecraft:concrete 3
setblock ~24~44~14 minecraft:concrete 0
setblock ~24~75~14 minecraft:wool 11
setblock ~24~76~14 minecraft:stained_glass 0
fill ~25~11~14 ~25~12~14 minecraft:red_mushroom_block 15
setblock ~25~76~14 minecraft:blue_glazed_terracotta 2
setblock ~26~13~14 minecraft:bone_block 0
fill ~26~14~14 ~27~14~14 minecraft:red_mushroom_block 15
setblock ~26~15~14 minecraft:bone_block 0
fill ~26~17~14 ~26~19~14 minecraft:leaves 0
setblock ~26~20~14 minecraft:air
setblock ~26~77~14 minecraft:stained_glass 3
setblock ~27~13~14 minecraft:red_mushroom_block 15
setblock ~27~15~14 minecraft:red_mushroom_block 15
setblock ~27~17~14 minecraft:leaves2 3
fill ~27~31~14 ~27~31~17 minecraft:wooden_slab 5
setblock ~27~77~14 minecraft:concrete 11
fill ~28~10~14 ~28~12~14 minecraft:red_mushroom_block 15
setblock ~28~32~14 minecraft:spruce_trapdoor 2
fill ~28~77~14 ~29~77~14 minecraft:concrete 3
setblock ~29~4~14 minecraft:red_mushroom_block 15
setblock ~29~5~14 minecraft:red_mushroom_block 10
fill ~29~7~14 ~29~7~15 minecraft:bone_block 0
setblock ~29~8~14 minecraft:red_mushroom_block 15
fill ~29~9~14 ~29~9~16 minecraft:bone_block 0
setblock ~29~31~14 minecraft:wooden_slab 13
fill ~29~32~14 ~29~32~17 minecraft:wooden_slab 5
setblock ~30~3~14 minecraft:bone_block 0
setblock ~30~77~14 minecraft:stained_glass 0
setblock ~31~77~14 minecraft:stained_glass 3
fill ~32~77~14 ~33~77~14 minecraft:concrete 3
setblock ~34~77~14 minecraft:wool 11
setblock ~35~77~14 minecraft:blue_glazed_terracotta 2
setblock ~36~1~14 minecraft:bone_block 0
fill ~36~2~14 ~36~3~14 minecraft:red_mushroom_block 15
fill ~36~8~14 ~36~9~14 minecraft:leaves 0
setblock ~36~10~14 minecraft:air
setblock ~36~76~14 minecraft:concrete 3
fill ~37~4~14 ~37~6~14 minecraft:bone_block 0
setblock ~37~7~14 minecraft:red_mushroom_block 15
setblock ~37~8~14 minecraft:leaves2 3
setblock ~37~36~14 minecraft:spruce_trapdoor 3
setblock ~37~76~14 minecraft:concrete 11
setblock ~38~7~14 minecraft:bone_block 0
fill ~38~8~14 ~38~9~14 minecraft:red_mushroom_block 15
setblock ~38~10~14 minecraft:bone_block 0
setblock ~38~75~14 minecraft:stained_glass 0
setblock ~39~9~14 minecraft:bone_block 0
fill ~39~10~14 ~41~10~14 minecraft:red_mushroom_block 15
setblock ~39~11~14 minecraft:bone_block 0
setblock ~39~74~14 minecraft:wool 11
setblock ~39~75~14 minecraft:stained_glass 3
setblock ~40~0~14 minecraft:tallgrass 0
fill ~40~9~14 ~41~9~14 minecraft:red_mushroom_block 15
fill ~40~73~14 ~40~73~15 minecraft:stained_glass 0
setblock ~41~73~14 minecraft:stained_glass 3
fill ~42~7~14 ~43~7~14 minecraft:leaves 0
fill ~42~8~14 ~42~8~15 minecraft:leaves 0
setblock ~42~72~14 minecraft:stained_glass 0
setblock ~42~73~14 minecraft:blue_glazed_terracotta 2
fill ~43~5~14 ~43~5~15 minecraft:red_mushroom_block 15
setblock ~43~6~14 minecraft:red_mushroom_block 15
setblock ~43~72~14 minecraft:concrete 3
setblock ~44~3~14 minecraft:red_mushroom_block 15
setblock ~44~68~14 minecraft:blue_glazed_terracotta 2
fill ~44~70~14 ~44~71~14 minecraft:wool 11
fill ~45~1~14 ~45~2~14 minecraft:red_mushroom_block 15
fill ~45~68~14 ~45~69~14 minecraft:stained_glass 0
setblock ~46~0~14 minecraft:red_mushroom_block 15
fill ~46~64~14 ~46~65~14 minecraft:stained_glass 0
fill ~46~66~14 ~46~67~14 minecraft:concrete 0
setblock ~47~52~14 minecraft:wool 11
setblock ~47~53~14 minecraft:sea_lantern
setblock ~47~54~14 minecraft:concrete 0
setblock ~47~55~14 minecraft:concrete 3
setblock ~47~56~14 minecraft:concrete 11
fill ~47~57~14 ~47~58~14 minecraft:wool 11
setblock ~47~59~14 minecraft:concrete 0
setblock ~47~60~14 minecraft:concrete 3
setblock ~47~61~14 minecraft:concrete 11
setblock ~47~62~14 minecraft:blue_glazed_terracotta 2
setblock ~47~63~14 minecraft:concrete 0
setblock ~52~0~14 minecraft:dirt 0
fill ~56~0~14 ~56~0~15 minecraft:grass
fill ~60~1~14 ~61~1~14 minecraft:red_mushroom_block 15
setblock ~5~3~15 minecraft:grass
fill ~6~4~15 ~6~4~18 minecraft:grass
fill ~7~4~15 ~9~4~15 minecraft:red_mushroom_block 15
setblock ~9~3~15 minecraft:dirt 0
fill ~10~2~15 ~11~2~16 minecraft:grass
fill ~10~4~15 ~11~5~15 minecraft:bone_block 0
setblock ~12~3~15 minecraft:red_mushroom_block 15
setblock ~12~4~15 minecraft:red_mushroom_block 10
setblock ~12~5~15 minecraft:red_mushroom_block 15
fill ~13~3~15 ~13~4~15 minecraft:bone_block 0
setblock ~13~6~15 minecraft:leaves 0
setblock ~14~3~15 minecraft:red_mushroom_block 15
setblock ~14~52~15 minecraft:concrete 0
setblock ~14~53~15 minecraft:stained_glass 0
setblock ~14~54~15 minecraft:concrete 11
setblock ~14~55~15 minecraft:blue_glazed_terracotta 2
setblock ~14~56~15 minecraft:stained_glass 0
setblock ~14~57~15 minecraft:concrete 0
setblock ~14~58~15 minecraft:stained_glass 0
setblock ~14~59~15 minecraft:concrete 11
setblock ~14~60~15 minecraft:blue_glazed_terracotta 2
setblock ~14~61~15 minecraft:stained_glass 0
setblock ~14~62~15 minecraft:concrete 3
setblock ~15~2~15 minecraft:bone_block 0
setblock ~15~41~15 minecraft:concrete 3
fill ~15~42~15 ~15~43~15 minecraft:wool 11
setblock ~15~44~15 minecraft:stained_glass 0
setblock ~15~45~15 minecraft:concrete 0
fill ~15~63~15 ~15~65~15 minecraft:concrete 0
setblock ~16~46~15 minecraft:concrete 11
setblock ~16~66~15 minecraft:wool 11
setblock ~16~67~15 minecraft:concrete 0
setblock ~16~68~15 minecraft:wool 11
setblock ~16~69~15 minecraft:stained_glass 3
setblock ~17~28~15 minecraft:wooden_slab 5
setblock ~17~47~15 minecraft:wool 11
setblock ~17~69~15 minecraft:blue_glazed_terracotta 2
setblock ~17~70~15 minecraft:concrete 0
setblock ~18~3~15 minecraft:tallgrass 0
setblock ~18~27~15 minecraft:wooden_slab 13
fill ~18~35~15 ~18~36~15 minecraft:bone_block 0
fill ~18~37~15 ~19~37~15 minecraft:red_mushroom_block 15
setblock ~18~47~15 minecraft:concrete 3
setblock ~18~71~15 minecraft:concrete 3
setblock ~19~34~15 minecraft:bone_block 0
fill ~19~36~15 ~19~36~16 minecraft:bone_block 0
setblock ~19~39~15 minecraft:carpet 11
setblock ~19~47~15 minecraft:wool 11
setblock ~19~72~15 minecraft:wool 11
setblock ~20~32~15 minecraft:bone_block 0
fill ~20~33~15 ~20~36~15 minecraft:red_mushroom_block 15
fill ~20~37~15 ~20~37~16 minecraft:bone_block 0
setblock ~20~38~15 minecraft:bone_block 0
fill ~20~39~15 ~21~39~15 minecraft:red_mushroom_block 15
setblock ~20~47~15 minecraft:blue_glazed_terracotta 2
setblock ~20~73~15 minecraft:concrete 0
fill ~21~30~15 ~23~30~16 minecraft:red_mushroom_block 15
fill ~21~31~15 ~21~31~16 minecraft:red_mushroom_block 15
setblock ~21~32~15 minecraft:red_mushroom_block 10
fill ~21~34~15 ~21~34~18 minecraft:red_mushroom_block 15
fill ~21~36~15 ~23~36~15 minecraft:red_mushroom_block 15
setblock ~21~47~15 minecraft:stained_glass 0
setblock ~21~74~15 minecraft:concrete 3
setblock ~22~0~15 minecraft:grass
fill ~22~29~15 ~22~29~17 minecraft:red_mushroom_block 15
fill ~22~31~15 ~22~32~15 minecraft:bone_block 0
setblock ~22~34~15 minecraft:bone_block 0
setblock ~22~46~15 minecraft:blue_glazed_terracotta 2
setblock ~22~75~15 minecraft:stained_glass 3
fill ~23~1~15 ~23~1~16 minecraft:red_mushroom_block 15
setblock ~23~5~15 minecraft:bone_block 0
setblock ~23~29~15 minecraft:wooden_slab 5
fill ~23~33~15 ~23~35~15 minecraft:red_mushroom_block 15
setblock ~23~38~15 minecraft:air
setblock ~23~41~15 minecraft:sea_lantern
setblock ~23~42~15 minecraft:blue_glazed_terracotta 2
setblock ~23~43~15 minecraft:concrete 3
setblock ~23~44~15 minecraft:wool 11
setblock ~23~45~15 minecraft:blue_glazed_terracotta 2
setblock ~23~76~15 minecraft:stained_glass 3
setblock ~24~6~15 minecraft:red_mushroom_block 15
fill ~24~8~15 ~24~8~17 minecraft:red_mushroom_block 15
fill ~24~10~15 ~24~10~16 minecraft:bone_block 0
setblock ~24~11~15 minecraft:red_mushroom_block 15
setblock ~24~29~15 minecraft:double_wooden_slab 5
setblock ~24~77~15 minecraft:sea_lantern
fill ~25~12~15 ~25~12~19 minecraft:red_mushroom_block 15
fill ~25~13~15 ~25~13~18 minecraft:red_mushroom_block 15
fill ~25~14~15 ~25~14~18 minecraft:bone_block 0
fill ~25~15~15 ~25~15~17 minecraft:red_mushroom_block 15
fill ~25~19~15 ~26~19~15 minecraft:leaves 0
fill ~25~20~15 ~25~20~16 minecraft:leaves 0
setblock ~25~77~15 minecraft:wool 11
setblock ~25~78~15 minecraft:concrete 0
fill ~26~16~15 ~28~16~15 minecraft:red_mushroom_block 15
setblock ~26~17~15 minecraft:red_mushroom_block 15
setblock ~26~78~15 minecraft:concrete 3
setblock ~27~17~15 minecraft:bone_block 0
setblock ~27~18~15 minecraft:red_mushroom_block 15
setblock ~27~19~15 minecraft:red_mushroom_block 10
setblock ~27~20~15 minecraft:red_mushroom_block 15
setblock ~27~78~15 minecraft:stained_glass 0
fill ~28~13~15 ~28~14~15 minecraft:red_mushroom_block 15
setblock ~28~15~15 minecraft:bone_block 0
setblock ~28~78~15 minecraft:stained_glass 3
fill ~29~8~15 ~29~8~16 minecraft:bone_block 0
fill ~29~10~15 ~29~10~16 minecraft:red_mushroom_block 15
fill ~29~11~15 ~29~12~15 minecraft:bone_block 0
setblock ~29~78~15 minecraft:concrete 11
fill ~30~1~15 ~30~1~16 minecraft:bone_block 0
setblock ~30~3~15 minecraft:red_mushroom_block 15
fill ~30~4~15 ~30~4~18 minecraft:bone_block 0
setblock ~30~5~15 minecraft:red_mushroom_block 15
fill ~30~32~15 ~30~32~17 minecraft:wooden_slab 13
setblock ~30~78~15 minecraft:blue_glazed_terracotta 2
fill ~31~5~15 ~31~7~15 minecraft:leaves 0
setblock ~31~8~15 minecraft:air
fill ~31~33~15 ~32~33~17 minecraft:wooden_slab 5
setblock ~31~78~15 minecraft:concrete 0
setblock ~32~78~15 minecraft:stained_glass 3
fill ~33~33~15 ~33~33~17 minecraft:wooden_slab 13
setblock ~33~78~15 minecraft:concrete 3
fill ~34~34~15 ~34~34~18 minecraft:wooden_slab 5
setblock ~34~78~15 minecraft:stained_glass 0
fill ~35~0~15 ~35~1~15 minecraft:red_mushroom_block 15
setblock ~35~2~15 minecraft:bone_block 0
fill ~35~9~15 ~36~9~15 minecraft:leaves 0
fill ~35~10~15 ~35~11~15 minecraft:leaves 0
setblock ~35~12~15 minecraft:air
setblock ~35~78~15 minecraft:concrete 0
setblock ~36~3~15 minecraft:bone_block 0
setblock ~36~4~15 minecraft:red_mushroom_block 15
fill ~36~5~15 ~36~6~15 minecraft:red_mushroom_block 10
setblock ~36~7~15 minecraft:red_mushroom_block 15
setblock ~36~36~15 minecraft:spruce_trapdoor 1
setblock ~36~77~15 minecraft:stained_glass 3
setblock ~36~78~15 minecraft:blue_glazed_terracotta 2
fill ~37~8~15 ~37~10~15 minecraft:bone_block 0
fill ~37~11~15 ~37~12~15 minecraft:red_mushroom_block 15
fill ~37~35~15 ~37~35~19 minecraft:wooden_slab 13
setblock ~37~36~15 minecraft:sea_lantern
setblock ~37~37~15 minecraft:azalea_leaves_flowered 0
setblock ~37~38~15 minecraft:azalea_leaves 0
setblock ~37~39~15 minecraft:air
setblock ~37~77~15 minecraft:stained_glass 0
setblock ~38~11~15 minecraft:bone_block 0
setblock ~38~12~15 minecraft:red_mushroom_block 15
setblock ~38~13~15 minecraft:red_mushroom_block 10
setblock ~38~14~15 minecraft:red_mushroom_block 15
setblock ~38~36~15 minecraft:spruce_trapdoor 1
fill ~38~76~15 ~38~77~15 minecraft:stained_glass 3
fill ~39~12~15 ~39~13~15 minecraft:bone_block 0
setblock ~39~76~15 minecraft:concrete 3
setblock ~40~9~15 minecraft:sea_lantern
setblock ~40~11~15 minecraft:red_mushroom_block 15
setblock ~40~74~15 minecraft:stained_glass 3
setblock ~40~75~15 minecraft:concrete 3
fill ~41~9~15 ~42~9~15 minecraft:leaves 0
setblock ~41~10~15 minecraft:bone_block 0
setblock ~41~74~15 minecraft:blue_glazed_terracotta 2
fill ~42~0~15 ~43~0~15 minecraft:tallgrass 0
fill ~42~6~15 ~42~6~16 minecraft:red_mushroom_block 15
setblock ~42~7~15 minecraft:red_mushroom_block 15
setblock ~42~10~15 minecraft:air
setblock ~42~74~15 minecraft:stained_glass 3
setblock ~43~4~15 minecraft:red_mushroom_block 15
setblock ~43~73~15 minecraft:concrete 0
setblock ~44~1~15 minecraft:red_mushroom_block 15
fill ~44~2~15 ~44~3~15 minecraft:bone_block 0
setblock ~44~69~15 minecraft:concrete 3
setblock ~44~71~15 minecraft:stained_glass 0
setblock ~44~72~15 minecraft:concrete 0
setblock ~45~0~15 minecraft:red_mushroom_block 15
fill ~45~68~15 ~45~68~16 minecraft:concrete 3
setblock ~45~70~15 minecraft:concrete 0
setblock ~46~67~15 minecraft:concrete 0
setblock ~46~68~15 minecraft:blue_glazed_terracotta 2
setblock ~46~69~15 minecraft:concrete 11
setblock ~47~0~15 minecraft:tallgrass 0
setblock ~47~63~15 minecraft:wool 11
setblock ~47~64~15 minecraft:stained_glass 0
fill ~47~65~15 ~47~65~16 minecraft:blue_glazed_terracotta 2
fill ~47~66~15 ~47~67~15 minecraft:blue_glazed_terracotta 2
fill ~48~52~15 ~48~53~15 minecraft:concrete 0
setblock ~48~54~15 minecraft:blue_glazed_terracotta 2
setblock ~48~55~15 minecraft:stained_glass 3
setblock ~48~56~15 minecraft:wool 11
fill ~48~57~15 ~48~58~15 minecraft:concrete 0
setblock ~48~59~15 minecraft:blue_glazed_terracotta 2
setblock ~48~60~15 minecraft:stained_glass 3
setblock ~48~61~15 minecraft:wool 11
setblock ~48~62~15 minecraft:stained_glass 3
fill ~52~0~15 ~52~0~17 minecraft:grass
fill ~57~1~15 ~57~1~17 minecraft:grass
setblock ~57~2~15 minecraft:spruce_trapdoor 3
setblock ~59~1~15 minecraft:bone_block 0
fill ~60~1~15 ~61~1~15 minecraft:sandstone 3
fill ~5~4~16 ~5~4~18 minecraft:grass
setblock ~6~5~16 minecraft:tallgrass 0
setblock ~7~4~16 minecraft:red_mushroom_block 15
fill ~8~3~16 ~9~3~16 minecraft:grass
fill ~8~5~16 ~9~5~16 minecraft:red_mushroom_block 15
fill ~10~6~16 ~11~6~16 minecraft:red_mushroom_block 15
fill ~12~2~16 ~14~2~19 minecraft:grass
fill ~12~6~16 ~12~7~16 minecraft:leaves 0
fill ~13~5~16 ~16~5~16 minecraft:red_mushroom_block 15
fill ~13~6~16 ~14~7~16 minecraft:red_mushroom_block 15
setblock ~14~4~16 minecraft:bone_block 0
fill ~14~52~16 ~14~53~16 minecraft:wool 11
fill ~14~54~16 ~14~55~16 minecraft:concrete 3
fill ~14~56~16 ~14~58~16 minecraft:wool 11
fill ~14~59~16 ~14~60~16 minecraft:concrete 3
setblock ~14~61~16 minecraft:wool 11
setblock ~14~62~16 minecraft:blue_glazed_terracotta 2
fill ~14~63~16 ~14~64~16 minecraft:wool 11
setblock ~15~3~16 minecraft:bone_block 0
setblock ~15~4~16 minecraft:red_mushroom_block 15
setblock ~15~6~16 minecraft:bone_block 0
fill ~15~65~16 ~15~66~16 minecraft:concrete 3
fill ~15~67~16 ~15~68~16 minecraft:stained_glass 3
setblock ~15~69~16 minecraft:concrete 0
setblock ~16~3~16 minecraft:red_mushroom_block 15
setblock ~16~4~16 minecraft:bone_block 0
setblock ~16~6~16 minecraft:red_mushroom_block 10
setblock ~16~7~16 minecraft:red_mushroom_block 15
setblock ~16~41~16 minecraft:blue_glazed_terracotta 2
setblock ~16~42~16 minecraft:concrete 11
setblock ~16~43~16 minecraft:wool 11
fill ~16~44~16 ~16~45~16 minecraft:concrete 0
setblock ~16~68~16 minecraft:concrete 0
setblock ~16~69~16 minecraft:concrete 3
fill ~16~70~16 ~16~70~17 minecraft:concrete 11
setblock ~17~27~16 minecraft:wooden_slab 13
setblock ~17~41~16 minecraft:concrete 3
setblock ~17~45~16 minecraft:concrete 0
fill ~17~46~16 ~18~46~16 minecraft:concrete 3
fill ~17~71~16 ~17~71~17 minecraft:stained_glass 0
setblock ~18~27~16 minecraft:double_wooden_slab 5
setblock ~18~72~16 minecraft:concrete 11
fill ~19~27~16 ~20~27~16 minecraft:wooden_slab 13
fill ~19~34~16 ~20~34~16 minecraft:red_mushroom_block 15
setblock ~19~37~16 minecraft:bone_block 0
setblock ~19~46~16 minecraft:concrete 0
setblock ~19~73~16 minecraft:concrete 3
setblock ~20~31~16 minecraft:bone_block 0
fill ~20~32~16 ~20~32~17 minecraft:red_mushroom_block 15
fill ~20~33~16 ~23~33~16 minecraft:bone_block 0
setblock ~20~35~16 minecraft:bone_block 0
fill ~20~36~16 ~20~36~17 minecraft:red_mushroom_block 15
fill ~20~46~16 ~21~46~16 minecraft:concrete 3
setblock ~20~74~16 minecraft:concrete 0
setblock ~21~29~16 minecraft:red_mushroom_block 15
fill ~21~32~16 ~21~32~18 minecraft:bone_block 0
fill ~21~36~16 ~21~37~16 minecraft:bone_block 0
setblock ~21~41~16 minecraft:concrete 0
setblock ~21~45~16 minecraft:concrete 0
setblock ~21~75~16 minecraft:stained_glass 3
fill ~22~1~16 ~22~1~19 minecraft:grass
fill ~22~31~16 ~23~31~18 minecraft:red_mushroom_block 15
fill ~22~32~16 ~24~32~16 minecraft:red_mushroom_block 15
fill ~22~34~16 ~24~34~16 minecraft:red_mushroom_block 15
fill ~22~36~16 ~23~36~16 minecraft:leaves 0
setblock ~22~41~16 minecraft:stained_glass 0
setblock ~22~42~16 minecraft:wool 11
setblock ~22~43~16 minecraft:concrete 0
setblock ~22~44~16 minecraft:blue_glazed_terracotta 2
setblock ~22~45~16 minecraft:wool 11
setblock ~22~76~16 minecraft:concrete 3
setblock ~23~28~16 minecraft:bone_block 0
setblock ~23~29~16 minecraft:red_mushroom_block 15
fill ~23~35~16 ~23~35~17 minecraft:bone_block 0
fill ~23~77~16 ~23~77~17 minecraft:stained_glass 0
fill ~24~3~16 ~24~4~16 minecraft:bone_block 0
fill ~24~5~16 ~24~5~17 minecraft:red_mushroom_block 15
setblock ~24~6~16 minecraft:bone_block 0
setblock ~24~29~16 minecraft:bone_block 0
fill ~24~30~16 ~24~30~17 minecraft:red_mushroom_block 15
fill ~24~33~16 ~24~33~17 minecraft:red_mushroom_block 15
fill ~24~35~16 ~24~35~18 minecraft:red_mushroom_block 15
setblock ~24~36~16 minecraft:bone_block 0
setblock ~24~37~16 minecraft:carpet 11
setblock ~24~78~16 minecraft:concrete 11
fill ~25~0~16 ~25~0~18 minecraft:grass
fill ~25~11~16 ~25~11~17 minecraft:red_mushroom_block 15
fill ~25~16~16 ~25~17~17 minecraft:red_mushroom_block 15
setblock ~25~21~16 minecraft:leaves 0
setblock ~25~22~16 minecraft:air
setblock ~25~78~16 minecraft:stained_glass 0
setblock ~26~18~16 minecraft:bone_block 0
setblock ~26~19~16 minecraft:red_mushroom_block 15
setblock ~26~20~16 minecraft:bone_block 0
setblock ~26~79~16 minecraft:concrete 0
setblock ~27~17~16 minecraft:sea_lantern
fill ~27~21~16 ~28~21~16 minecraft:bone_block 0
fill ~27~22~16 ~27~23~16 minecraft:bone_block 0
setblock ~27~24~16 minecraft:red_mushroom_block 15
setblock ~27~25~16 minecraft:bone_block 0
fill ~27~79~16 ~27~79~17 minecraft:concrete 3
setblock ~28~17~16 minecraft:red_mushroom_block 15
fill ~28~18~16 ~28~19~16 minecraft:red_mushroom_block 10
setblock ~28~20~16 minecraft:red_mushroom_block 15
setblock ~28~22~16 minecraft:red_mushroom_block 15
setblock ~28~79~16 minecraft:stained_glass 3
setblock ~29~11~16 minecraft:red_mushroom_block 10
fill ~29~12~16 ~29~12~17 minecraft:red_mushroom_block 15
setblock ~29~13~16 minecraft:bone_block 0
fill ~29~14~16 ~29~14~17 minecraft:red_mushroom_block 15
fill ~29~15~16 ~29~16~17 minecraft:bone_block 0
fill ~29~43~16 ~34~44~17 minecraft:stained_glass 3
setblock ~29~79~16 minecraft:concrete 0
fill ~30~2~16 ~30~3~16 minecraft:bone_block 0
fill ~30~5~16 ~30~5~17 minecraft:bone_block 0
fill ~30~6~16 ~30~7~16 minecraft:red_mushroom_block 15
fill ~30~42~16 ~33~42~17 minecraft:stained_glass 3
fill ~30~45~16 ~33~45~17 minecraft:stained_glass 3
setblock ~30~79~16 minecraft:concrete 3
fill ~31~7~16 ~31~10~16 minecraft:leaves 0
fill ~31~41~16 ~32~41~17 minecraft:stained_glass 3
fill ~31~46~16 ~32~46~17 minecraft:stained_glass 3
setblock ~31~79~16 minecraft:stained_glass 0
setblock ~32~79~16 minecraft:concrete 11
setblock ~33~79~16 minecraft:wool 11
fill ~34~0~16 ~34~0~17 minecraft:red_mushroom_block 15
fill ~34~11~16 ~34~13~16 minecraft:leaves 0
setblock ~34~79~16 minecraft:stained_glass 0
setblock ~35~1~16 minecraft:red_mushroom_block 15
setblock ~35~2~16 minecraft:red_mushroom_block 10
setblock ~35~3~16 minecraft:red_mushroom_block 15
setblock ~35~4~16 minecraft:bone_block 0
setblock ~35~5~16 minecraft:red_mushroom_block 10
fill ~35~6~16 ~35~7~16 minecraft:red_mushroom_block 15
fill ~35~34~16 ~35~34~19 minecraft:wooden_slab 13
setblock ~35~79~16 minecraft:concrete 3
fill ~36~8~16 ~36~9~16 minecraft:red_mushroom_block 15
setblock ~36~10~16 minecraft:bone_block 0
setblock ~36~11~16 minecraft:red_mushroom_block 15
setblock ~36~12~16 minecraft:bone_block 0
fill ~36~13~16 ~37~14~16 minecraft:red_mushroom_block 15
setblock ~36~15~16 minecraft:bone_block 0
fill ~36~35~16 ~36~35~19 minecraft:wooden_slab 5
setblock ~36~79~16 minecraft:wool 11
fill ~37~15~16 ~38~15~16 minecraft:red_mushroom_block 15
fill ~37~16~16 ~37~17~16 minecraft:red_mushroom_block 10
setblock ~37~18~16 minecraft:red_mushroom_block 15
setblock ~37~36~16 minecraft:spruce_trapdoor 2
setblock ~37~78~16 minecraft:stained_glass 3
setblock ~37~79~16 minecraft:concrete 11
setblock ~38~16~16 minecraft:bone_block 0
fill ~38~36~16 ~38~36~19 minecraft:wooden_slab 5
setblock ~38~78~16 minecraft:concrete 11
setblock ~39~14~16 minecraft:bone_block 0
setblock ~39~77~16 minecraft:concrete 11
setblock ~40~11~16 minecraft:bone_block 0
fill ~40~12~16 ~40~13~16 minecraft:red_mushroom_block 15
setblock ~40~76~16 minecraft:sea_lantern
fill ~41~7~16 ~41~8~16 minecraft:bone_block 0
fill ~41~9~16 ~41~10~16 minecraft:leaves 0
setblock ~41~75~16 minecraft:blue_glazed_terracotta 2
setblock ~42~4~16 minecraft:red_mushroom_block 15
setblock ~42~5~16 minecraft:red_mushroom_block 10
setblock ~42~75~16 minecraft:concrete 3
setblock ~43~0~16 minecraft:bone_block 0
setblock ~43~1~16 minecraft:red_mushroom_block 15
setblock ~43~2~16 minecraft:red_mushroom_block 10
setblock ~43~3~16 minecraft:red_mushroom_block 15
setblock ~43~74~16 minecraft:concrete 11
setblock ~44~0~16 minecraft:red_mushroom_block 15
setblock ~44~72~16 minecraft:stained_glass 3
fill ~44~73~16 ~44~73~17 minecraft:concrete 11
fill ~45~69~16 ~46~69~16 minecraft:concrete 0
fill ~45~70~16 ~45~71~16 minecraft:concrete 3
setblock ~47~66~16 minecraft:wool 11
setblock ~47~67~16 minecraft:blue_glazed_terracotta 2
fill ~47~68~16 ~47~68~17 minecraft:wool 11
setblock ~48~52~16 minecraft:stained_glass 0
fill ~48~53~16 ~48~54~16 minecraft:concrete 0
setblock ~48~55~16 minecraft:concrete 11
fill ~48~56~16 ~48~57~16 minecraft:stained_glass 0
fill ~48~58~16 ~48~59~16 minecraft:concrete 0
setblock ~48~60~16 minecraft:concrete 11
setblock ~48~61~16 minecraft:stained_glass 0
setblock ~48~62~16 minecraft:blue_glazed_terracotta 2
fill ~48~63~16 ~48~64~16 minecraft:stained_glass 3
setblock ~56~0~16 minecraft:dirt 0
setblock ~56~1~16 minecraft:grass
setblock ~56~2~16 minecraft:spruce_trapdoor 1
setblock ~57~2~16 minecraft:sea_lantern
setblock ~57~3~16 minecraft:azalea_leaves 0
setblock ~57~4~16 minecraft:azalea_leaves_flowered 0
setblock ~57~5~16 minecraft:air
setblock ~58~2~16 minecraft:spruce_trapdoor 1
fill ~59~1~16 ~59~1~17 minecraft:sandstone 3
setblock ~60~1~16 minecraft:red_mushroom_block 15
setblock ~61~1~16 minecraft:bone_block 0
setblock ~7~3~17 minecraft:red_mushroom_block 15
setblock ~8~4~17 minecraft:red_mushroom_block 15
fill ~9~3~17 ~10~3~17 minecraft:grass
setblock ~9~5~17 minecraft:bone_block 0
setblock ~10~6~17 minecraft:red_mushroom_block 15
setblock ~11~2~17 minecraft:grass
setblock ~11~7~17 minecraft:bone_block 0
fill ~12~7~17 ~12~8~17 minecraft:leaves 0
setblock ~12~9~17 minecraft:air
setblock ~13~8~17 minecraft:bone_block 0
fill ~13~52~17 ~13~53~17 minecraft:concrete 11
setblock ~13~54~17 minecraft:sea_lantern
setblock ~13~55~17 minecraft:concrete 3
setblock ~13~56~17 minecraft:concrete 0
fill ~13~57~17 ~13~58~17 minecraft:concrete 11
fill ~13~59~17 ~13~60~17 minecraft:concrete 3
fill ~13~61~17 ~13~62~17 minecraft:concrete 0
fill ~14~8~17 ~15~9~17 minecraft:red_mushroom_block 15
setblock ~14~63~17 minecraft:blue_glazed_terracotta 2
setblock ~14~64~17 minecraft:concrete 11
setblock ~14~65~17 minecraft:concrete 3
setblock ~14~66~17 minecraft:concrete 11
fill ~15~2~17 ~15~2~19 minecraft:grass
setblock ~15~7~17 minecraft:red_mushroom_block 15
setblock ~15~10~17 minecraft:red_mushroom_block 15
setblock ~15~67~17 minecraft:stained_glass 0
setblock ~15~68~17 minecraft:stained_glass 3
setblock ~15~69~17 minecraft:wool 11
fill ~16~8~17 ~16~9~17 minecraft:bone_block 0
setblock ~16~27~17 minecraft:spruce_trapdoor 3
fill ~17~3~17 ~18~3~17 minecraft:red_mushroom_block 15
fill ~17~4~17 ~17~5~17 minecraft:bone_block 0
setblock ~17~6~17 minecraft:red_mushroom_block 15
setblock ~17~7~17 minecraft:red_mushroom_block 10
setblock ~17~8~17 minecraft:red_mushroom_block 15
setblock ~17~10~17 minecraft:leaves 0
setblock ~17~26~17 minecraft:wooden_slab 13
fill ~17~27~17 ~20~27~17 minecraft:wooden_slab 5
setblock ~17~42~17 minecraft:concrete 11
fill ~17~43~17 ~17~44~17 minecraft:wool 11
setblock ~17~70~17 minecraft:stained_glass 3
setblock ~17~72~17 minecraft:blue_glazed_terracotta 2
setblock ~18~4~17 minecraft:red_mushroom_block 10
setblock ~18~5~17 minecraft:red_mushroom_block 15
fill ~18~15~17 ~19~15~17 minecraft:leaves 0
fill ~18~16~17 ~18~18~17 minecraft:leaves 0
fill ~18~41~17 ~19~41~17 minecraft:concrete 0
fill ~18~42~17 ~19~42~17 minecraft:blue_glazed_terracotta 2
setblock ~18~43~17 minecraft:stained_glass 0
setblock ~18~44~17 minecraft:stained_glass 3
setblock ~18~45~17 minecraft:concrete 0
setblock ~18~71~17 minecraft:concrete 3
setblock ~18~73~17 minecraft:concrete 11
setblock ~19~14~17 minecraft:leaves 0
setblock ~19~16~17 minecraft:air
setblock ~19~43~17 minecraft:concrete 0
setblock ~19~44~17 minecraft:concrete 3
setblock ~19~45~17 minecraft:stained_glass 3
setblock ~19~72~17 minecraft:concrete 0
setblock ~19~74~17 minecraft:stained_glass 0
setblock ~20~2~17 minecraft:grass
fill ~20~33~17 ~23~33~17 minecraft:red_mushroom_block 15
setblock ~20~34~17 minecraft:bone_block 0
setblock ~20~35~17 minecraft:red_mushroom_block 15
setblock ~20~41~17 minecraft:stained_glass 3
fill ~20~42~17 ~20~43~17 minecraft:stained_glass 0
setblock ~20~44~17 minecraft:concrete 11
setblock ~20~45~17 minecraft:wool 11
setblock ~20~75~17 minecraft:blue_glazed_terracotta 2
setblock ~21~30~17 minecraft:red_mushroom_block 15
setblock ~21~31~17 minecraft:bone_block 0
fill ~21~35~17 ~21~36~18 minecraft:leaves 0
setblock ~21~42~17 minecraft:concrete 0
fill ~21~43~17 ~21~44~17 minecraft:wool 11
setblock ~21~76~17 minecraft:stained_glass 0
fill ~22~28~17 ~24~28~17 minecraft:red_mushroom_block 15
setblock ~22~30~17 minecraft:bone_block 0
setblock ~22~32~17 minecraft:bone_block 0
fill ~22~34~17 ~22~35~18 minecraft:red_mushroom_block 15
setblock ~22~36~17 minecraft:leaves 0
setblock ~22~77~17 minecraft:concrete 3
setblock ~23~0~17 minecraft:grass
setblock ~23~29~17 minecraft:bone_block 0
fill ~23~30~17 ~23~30~21 minecraft:red_mushroom_block 15
fill ~23~32~17 ~24~32~17 minecraft:red_mushroom_block 15
setblock ~23~34~17 minecraft:bone_block 0
fill ~23~36~17 ~24~36~18 minecraft:red_mushroom_block 15
fill ~24~1~17 ~24~1~18 minecraft:red_mushroom_block 15
setblock ~24~2~17 minecraft:bone_block 0
fill ~24~3~17 ~24~4~17 minecraft:red_mushroom_block 15
setblock ~24~6~17 minecraft:red_mushroom_block 10
fill ~24~19~17 ~24~19~18 minecraft:leaves 0
setblock ~24~20~17 minecraft:leaves 0
setblock ~24~21~17 minecraft:air
fill ~24~29~17 ~24~29~20 minecraft:red_mushroom_block 15
fill ~24~31~17 ~25~31~17 minecraft:red_mushroom_block 15
fill ~24~34~17 ~25~34~20 minecraft:red_mushroom_block 15
setblock ~24~78~17 minecraft:stained_glass 0
setblock ~24~79~17 minecraft:concrete 3
setblock ~25~9~17 minecraft:bone_block 0
setblock ~25~10~17 minecraft:red_mushroom_block 15
fill ~25~18~17 ~25~19~18 minecraft:red_mushroom_block 15
setblock ~25~21~17 minecraft:leaves2 3
setblock ~25~30~17 minecraft:red_mushroom_block 15
setblock ~25~32~17 minecraft:bone_block 0
fill ~25~33~17 ~25~33~18 minecraft:red_mushroom_block 15
fill ~25~79~17 ~26~79~17 minecraft:concrete 11
fill ~26~20~17 ~26~21~18 minecraft:red_mushroom_block 15
setblock ~26~22~17 minecraft:red_mushroom_block 10
fill ~26~23~17 ~26~24~18 minecraft:red_mushroom_block 15
setblock ~26~25~17 minecraft:red_mushroom_block 15
setblock ~27~26~17 minecraft:bone_block 0
setblock ~27~43~17 minecraft:bone_block 0
setblock ~27~44~17 minecraft:concrete 3
fill ~28~23~17 ~28~24~17 minecraft:red_mushroom_block 15
setblock ~28~25~17 minecraft:bone_block 0
setblock ~28~41~17 minecraft:bone_block 0
setblock ~28~42~17 minecraft:concrete 3
fill ~28~43~17 ~28~44~17 minecraft:stained_glass 3
setblock ~28~45~17 minecraft:stained_glass 0
setblock ~28~46~17 minecraft:concrete 0
setblock ~28~79~17 minecraft:stained_glass 0
setblock ~29~13~17 minecraft:red_mushroom_block 15
setblock ~29~17~17 minecraft:bone_block 0
fill ~29~18~17 ~29~19~19 minecraft:red_mushroom_block 15
fill ~29~20~17 ~29~20~18 minecraft:red_mushroom_block 15
setblock ~29~21~17 minecraft:red_mushroom_block 15
setblock ~29~22~17 minecraft:bone_block 0
setblock ~29~40~17 minecraft:stained_glass 0
fill ~29~41~17 ~30~41~17 minecraft:stained_glass 3
setblock ~29~42~17 minecraft:stained_glass 3
fill ~29~45~17 ~29~46~17 minecraft:stained_glass 3
fill ~29~47~17 ~29~47~20 minecraft:red_mushroom_block 15
setblock ~29~80~17 minecraft:concrete 0
fill ~30~0~17 ~30~0~18 minecraft:bone_block 0
setblock ~30~1~17 minecraft:red_mushroom_block 15
setblock ~30~2~17 minecraft:red_mushroom_block 10
setblock ~30~3~17 minecraft:red_mushroom_block 15
fill ~30~6~17 ~30~6~18 minecraft:bone_block 0
fill ~30~7~17 ~30~9~17 minecraft:red_mushroom_block 15
setblock ~30~10~17 minecraft:bone_block 0
fill ~30~11~17 ~30~13~17 minecraft:leaves 0
setblock ~30~40~17 minecraft:red_mushroom_block 15
setblock ~30~46~17 minecraft:stained_glass 3
setblock ~30~47~17 minecraft:wool 11
setblock ~30~80~17 minecraft:concrete 11
setblock ~31~11~17 minecraft:leaves2 3
setblock ~31~12~17 minecraft:air
setblock ~31~39~17 minecraft:concrete 3
fill ~31~40~17 ~32~40~17 minecraft:stained_glass 3
fill ~31~47~17 ~32~47~17 minecraft:stained_glass 3
setblock ~31~48~17 minecraft:concrete 11
fill ~31~64~17 ~32~64~17 minecraft:leaves 0
setblock ~31~80~17 minecraft:stained_glass 3
setblock ~32~39~17 minecraft:wool 11
fill ~32~48~17 ~32~48~18 minecraft:concrete 3
fill ~32~65~17 ~32~66~17 minecraft:leaves 0
setblock ~32~80~17 minecraft:concrete 3
fill ~33~14~17 ~33~17~17 minecraft:leaves 0
setblock ~33~18~17 minecraft:air
fill ~33~21~17 ~33~21~18 minecraft:leaves 0
fill ~33~22~17 ~33~23~17 minecraft:leaves 0
setblock ~33~24~17 minecraft:air
setblock ~33~40~17 minecraft:stained_glass 0
fill ~33~41~17 ~34~41~17 minecraft:stained_glass 3
fill ~33~46~17 ~34~46~17 minecraft:stained_glass 3
setblock ~33~47~17 minecraft:stained_glass 0
fill ~33~66~17 ~33~67~17 minecraft:leaves 0
setblock ~33~68~17 minecraft:air
setblock ~33~80~17 minecraft:concrete 0
setblock ~34~1~17 minecraft:bone_block 0
setblock ~34~2~17 minecraft:red_mushroom_block 15
setblock ~34~3~17 minecraft:bone_block 0
setblock ~34~4~17 minecraft:red_mushroom_block 15
fill ~34~5~17 ~34~7~17 minecraft:bone_block 0
setblock ~34~14~17 minecraft:leaves2 3
setblock ~34~15~17 minecraft:air
fill ~34~23~17 ~34~25~17 minecraft:leaves 0
setblock ~34~26~17 minecraft:air
setblock ~34~40~17 minecraft:wool 11
setblock ~34~42~17 minecraft:stained_glass 3
setblock ~34~45~17 minecraft:stained_glass 3
setblock ~34~47~17 minecraft:bone_block 0
setblock ~34~80~17 minecraft:blue_glazed_terracotta 2
fill ~35~8~17 ~35~11~17 minecraft:bone_block 0
setblock ~35~12~17 minecraft:red_mushroom_block 15
setblock ~35~13~17 minecraft:red_mushroom_block 10
fill ~35~14~17 ~35~15~17 minecraft:red_mushroom_block 15
setblock ~35~16~17 minecraft:bone_block 0
fill ~35~17~17 ~35~18~17 minecraft:red_mushroom_block 15
setblock ~35~41~17 minecraft:concrete 3
setblock ~35~42~17 minecraft:stained_glass 0
fill ~35~43~17 ~35~44~17 minecraft:stained_glass 3
setblock ~35~45~17 minecraft:concrete 11
setblock ~35~46~17 minecraft:bone_block 0
setblock ~35~80~17 minecraft:concrete 3
setblock ~36~16~17 minecraft:red_mushroom_block 15
setblock ~36~17~17 minecraft:bone_block 0
fill ~36~18~17 ~36~21~17 minecraft:red_mushroom_block 15
fill ~36~22~17 ~36~23~17 minecraft:bone_block 0
setblock ~36~43~17 minecraft:stained_glass 0
setblock ~36~44~17 minecraft:concrete 3
setblock ~36~80~17 minecraft:stained_glass 0
fill ~37~19~17 ~38~19~17 minecraft:red_mushroom_block 15
setblock ~37~20~17 minecraft:red_mushroom_block 15
setblock ~37~21~17 minecraft:bone_block 0
setblock ~37~22~17 minecraft:red_mushroom_block 15
setblock ~37~80~17 minecraft:concrete 0
setblock ~38~17~17 minecraft:red_mushroom_block 15
setblock ~38~18~17 minecraft:bone_block 0
setblock ~38~79~17 minecraft:stained_glass 0
fill ~39~14~17 ~39~14~18 minecraft:red_mushroom_block 15
fill ~39~15~17 ~39~16~17 minecraft:red_mushroom_block 15
setblock ~39~24~17 minecraft:planks 5
setblock ~39~25~17 minecraft:iron_bars
fill ~39~26~17 ~39~35~17 minecraft:chain 0
setblock ~39~36~17 minecraft:double_wooden_slab 5
fill ~39~78~17 ~39~78~18 minecraft:wool 11
setblock ~39~79~17 minecraft:concrete 11
fill ~40~9~17 ~40~9~18 minecraft:bone_block 0
setblock ~40~10~17 minecraft:red_mushroom_block 15
fill ~40~11~17 ~40~14~17 minecraft:leaves 0
fill ~40~24~17 ~43~24~22 minecraft:wooden_slab 13
setblock ~40~77~17 minecraft:concrete 0
setblock ~41~4~17 minecraft:red_mushroom_block 15
fill ~41~5~17 ~41~7~17 minecraft:red_mushroom_block 10
setblock ~41~8~17 minecraft:red_mushroom_block 15
setblock ~41~11~17 minecraft:leaves2 3
setblock ~41~12~17 minecraft:air
fill ~41~76~17 ~42~76~17 minecraft:concrete 0
setblock ~42~0~17 minecraft:red_mushroom_block 15
fill ~42~1~17 ~42~2~17 minecraft:red_mushroom_block 10
setblock ~42~3~17 minecraft:red_mushroom_block 15
setblock ~43~0~17 minecraft:tallgrass 0
setblock ~43~75~17 minecraft:stained_glass 3
setblock ~45~71~17 minecraft:stained_glass 0
setblock ~45~72~17 minecraft:concrete 11
setblock ~46~68~17 minecraft:blue_glazed_terracotta 2
setblock ~46~69~17 minecraft:stained_glass 3
fill ~46~70~17 ~46~70~18 minecraft:concrete 11
setblock ~47~67~17 minecraft:stained_glass 0
setblock ~48~63~17 minecraft:wool 11
setblock ~48~64~17 minecraft:blue_glazed_terracotta 2
setblock ~48~65~17 minecraft:sea_lantern
setblock ~48~66~17 minecraft:concrete 3
setblock ~48~67~17 minecraft:wool 11
setblock ~49~52~17 minecraft:wool 11
setblock ~49~53~17 minecraft:blue_glazed_terracotta 2
setblock ~49~54~17 minecraft:wool 11
fill ~49~55~17 ~49~56~17 minecraft:concrete 11
setblock ~49~57~17 minecraft:wool 11
setblock ~49~58~17 minecraft:blue_glazed_terracotta 2
setblock ~49~59~17 minecraft:wool 11
fill ~49~60~17 ~49~61~17 minecraft:concrete 11
fill ~49~62~17 ~49~62~18 minecraft:blue_glazed_terracotta 2
fill ~56~0~17 ~56~0~20 minecraft:grass
setblock ~57~2~17 minecraft:spruce_trapdoor 2
setblock ~60~1~17 minecraft:sea_lantern
setblock ~61~1~17 minecraft:red_mushroom_block 15
fill ~4~3~18 ~4~3~19 minecraft:grass
fill ~7~3~18 ~7~3~21 minecraft:grass
setblock ~8~3~18 minecraft:red_mushroom_block 15
setblock ~9~4~18 minecraft:red_mushroom_block 15
fill ~10~3~18 ~11~3~18 minecraft:grass
setblock ~10~5~18 minecraft:red_mushroom_block 15
fill ~11~6~18 ~11~7~18 minecraft:red_mushroom_block 15
fill ~11~8~18 ~12~8~18 minecraft:leaves 0
setblock ~13~8~18 minecraft:sea_lantern
fill ~13~9~18 ~13~9~19 minecraft:red_mushroom_block 15
setblock ~13~52~18 minecraft:wool 11
fill ~13~53~18 ~13~54~18 minecraft:blue_glazed_terracotta 2
setblock ~13~55~18 minecraft:concrete 0
setblock ~13~56~18 minecraft:concrete 11
setblock ~13~57~18 minecraft:wool 11
fill ~13~58~18 ~13~59~18 minecraft:blue_glazed_terracotta 2
setblock ~13~60~18 minecraft:concrete 0
setblock ~13~61~18 minecraft:concrete 11
setblock ~13~62~18 minecraft:concrete 3
setblock ~13~63~18 minecraft:concrete 11
setblock ~13~64~18 minecraft:concrete 3
setblock ~14~10~18 minecraft:red_mushroom_block 15
setblock ~14~65~18 minecraft:wool 11
setblock ~14~66~18 minecraft:stained_glass 0
setblock ~14~67~18 minecraft:stained_glass 3
fill ~14~68~18 ~14~68~19 minecraft:blue_glazed_terracotta 2
setblock ~15~11~18 minecraft:bone_block 0
setblock ~15~27~18 minecraft:spruce_trapdoor 1
setblock ~15~68~18 minecraft:stained_glass 0
setblock ~15~69~18 minecraft:blue_glazed_terracotta 2
fill ~16~2~18 ~17~2~21 minecraft:grass
fill ~16~10~18 ~18~12~18 minecraft:red_mushroom_block 15
fill ~16~13~18 ~17~13~18 minecraft:bone_block 0
fill ~16~26~18 ~17~26~18 minecraft:double_wooden_slab 5
setblock ~16~27~18 minecraft:sea_lantern
fill ~16~28~18 ~16~29~18 minecraft:azalea_leaves 0
setblock ~16~30~18 minecraft:air
setblock ~16~70~18 minecraft:stained_glass 3
fill ~16~71~18 ~17~71~18 minecraft:blue_glazed_terracotta 2
fill ~17~9~18 ~18~9~18 minecraft:bone_block 0
setblock ~17~14~18 minecraft:red_mushroom_block 15
fill ~17~19~18 ~17~19~19 minecraft:leaves 0
setblock ~17~27~18 minecraft:spruce_trapdoor 1
setblock ~17~72~18 minecraft:concrete 11
fill ~18~6~18 ~18~8~18 minecraft:red_mushroom_block 15
setblock ~18~13~18 minecraft:red_mushroom_block 15
setblock ~18~14~18 minecraft:leaves 0
setblock ~18~19~18 minecraft:azalea_leaves 0
fill ~18~26~18 ~20~26~18 minecraft:wooden_slab 13
fill ~18~72~18 ~18~73~18 minecraft:stained_glass 0
fill ~19~3~18 ~20~3~18 minecraft:red_mushroom_block 15
setblock ~19~4~18 minecraft:bone_block 0
setblock ~19~5~18 minecraft:red_mushroom_block 15
setblock ~19~6~18 minecraft:bone_block 0
fill ~19~7~18 ~19~9~18 minecraft:red_mushroom_block 15
setblock ~19~10~18 minecraft:bone_block 0
setblock ~19~73~18 minecraft:stained_glass 3
setblock ~19~74~18 minecraft:blue_glazed_terracotta 2
setblock ~19~75~18 minecraft:concrete 0
setblock ~20~0~18 minecraft:grass
setblock ~20~2~18 minecraft:red_mushroom_block 15
setblock ~20~4~18 minecraft:red_mushroom_block 15
fill ~20~13~18 ~22~13~18 minecraft:leaves 0
setblock ~20~14~18 minecraft:leaves 3
setblock ~20~15~18 minecraft:air
setblock ~20~34~18 minecraft:red_mushroom_block 15
fill ~20~35~18 ~20~36~18 minecraft:leaves 0
setblock ~20~37~18 minecraft:air
setblock ~20~76~18 minecraft:wool 11
setblock ~21~33~18 minecraft:red_mushroom_block 15
fill ~21~77~18 ~21~77~19 minecraft:stained_glass 3
fill ~22~14~18 ~23~14~18 minecraft:leaves 0
setblock ~22~15~18 minecraft:air
setblock ~22~29~18 minecraft:bone_block 0
fill ~22~30~18 ~22~30~19 minecraft:red_mushroom_block 15
fill ~22~32~18 ~22~32~20 minecraft:red_mushroom_block 15
fill ~22~33~18 ~24~33~18 minecraft:bone_block 0
fill ~22~36~18 ~22~36~19 minecraft:red_mushroom_block 15
setblock ~22~77~18 minecraft:wool 11
fill ~23~1~18 ~23~1~19 minecraft:grass
fill ~23~28~18 ~23~29~18 minecraft:red_mushroom_block 15
fill ~23~32~18 ~24~32~19 minecraft:bone_block 0
fill ~23~34~18 ~23~34~19 minecraft:red_mushroom_block 15
setblock ~23~35~18 minecraft:red_mushroom_block 15
setblock ~23~78~18 minecraft:blue_glazed_terracotta 2
setblock ~24~2~18 minecraft:red_mushroom_block 15
fill ~24~15~18 ~24~18~18 minecraft:leaves 0
setblock ~24~20~18 minecraft:air
fill ~24~26~18 ~25~26~18 minecraft:red_mushroom_block 15
fill ~24~27~18 ~24~27~21 minecraft:red_mushroom_block 15
fill ~24~30~18 ~25~31~18 minecraft:bone_block 0
fill ~24~79~18 ~24~80~18 minecraft:stained_glass 0
setblock ~25~3~18 minecraft:red_mushroom_block 15
fill ~25~4~18 ~25~4~19 minecraft:bone_block 0
fill ~25~5~18 ~25~9~19 minecraft:red_mushroom_block 15
fill ~25~10~18 ~25~11~19 minecraft:bone_block 0
fill ~25~15~18 ~25~16~18 minecraft:bone_block 0
setblock ~25~17~18 minecraft:red_mushroom_block 15
fill ~25~25~18 ~26~25~18 minecraft:bone_block 0
setblock ~25~27~18 minecraft:bone_block 0
fill ~25~28~18 ~29~28~18 minecraft:red_mushroom_block 15
fill ~25~29~18 ~25~29~20 minecraft:red_mushroom_block 15
fill ~25~32~18 ~26~32~19 minecraft:red_mushroom_block 15
setblock ~25~80~18 minecraft:concrete 0
setblock ~26~22~18 minecraft:bone_block 0
setblock ~26~26~18 minecraft:bone_block 0
fill ~26~27~18 ~27~27~19 minecraft:red_mushroom_block 15
setblock ~26~29~18 minecraft:bone_block 0
fill ~26~30~18 ~26~30~20 minecraft:red_mushroom_block 15
fill ~26~31~18 ~27~31~18 minecraft:bone_block 0
fill ~26~80~18 ~27~80~18 minecraft:concrete 11
setblock ~26~81~18 minecraft:stained_glass 3
fill ~27~25~18 ~27~26~18 minecraft:red_mushroom_block 15
fill ~27~43~18 ~27~44~19 minecraft:red_mushroom_block 15
setblock ~27~81~18 minecraft:stained_glass 0
setblock ~28~26~18 minecraft:red_mushroom_block 15
setblock ~28~27~18 minecraft:bone_block 0
setblock ~28~29~18 minecraft:red_mushroom_block 15
setblock ~28~30~18 minecraft:red_mushroom_block 10
setblock ~28~31~18 minecraft:red_mushroom_block 15
setblock ~28~32~18 minecraft:bone_block 0
setblock ~28~41~18 minecraft:stained_glass 0
setblock ~28~42~18 minecraft:concrete 0
setblock ~28~45~18 minecraft:wool 11
setblock ~28~46~18 minecraft:concrete 11
fill ~28~62~18 ~29~62~18 minecraft:leaves 0
setblock ~28~63~18 minecraft:air
setblock ~28~80~18 minecraft:concrete 0
setblock ~28~81~18 minecraft:stained_glass 3
setblock ~28~82~18 minecraft:stained_glass 0
fill ~29~0~18 ~29~2~19 minecraft:red_mushroom_block 15
fill ~29~3~18 ~29~3~20 minecraft:sandstone 3
fill ~29~17~18 ~29~17~19 minecraft:red_mushroom_block 15
fill ~29~21~18 ~29~21~19 minecraft:bone_block 0
setblock ~29~22~18 minecraft:red_mushroom_block 15
fill ~29~23~18 ~29~24~18 minecraft:bone_block 0
fill ~29~25~18 ~29~25~20 minecraft:red_mushroom_block 15
fill ~29~30~18 ~29~31~18 minecraft:bone_block 0
fill ~29~32~18 ~33~32~18 minecraft:red_mushroom_block 15
fill ~29~40~18 ~29~40~19 minecraft:red_mushroom_block 15
fill ~29~63~18 ~30~63~18 minecraft:leaves 0
setblock ~29~81~18 minecraft:stained_glass 0
setblock ~29~82~18 minecraft:concrete 0
setblock ~30~3~18 minecraft:bone_block 0
fill ~30~5~18 ~30~5~19 minecraft:red_mushroom_block 15
fill ~30~7~18 ~30~7~19 minecraft:bone_block 0
fill ~30~8~18 ~30~8~19 minecraft:red_mushroom_block 15
setblock ~30~9~18 minecraft:bone_block 0
fill ~30~10~18 ~30~10~19 minecraft:red_mushroom_block 15
setblock ~30~11~18 minecraft:bone_block 0
fill ~30~12~18 ~30~12~23 minecraft:red_mushroom_block 15
fill ~30~13~18 ~30~15~18 minecraft:leaves 0
setblock ~30~16~18 minecraft:red_mushroom_block 15
fill ~30~30~18 ~31~30~18 minecraft:red_mushroom_block 15
setblock ~30~31~18 minecraft:bone_block 0
setblock ~30~40~18 minecraft:stained_glass 3
setblock ~30~47~18 minecraft:blue_glazed_terracotta 2
setblock ~30~64~18 minecraft:air
setblock ~30~81~18 minecraft:stained_glass 3
setblock ~30~82~18 minecraft:stained_glass 0
setblock ~31~31~18 minecraft:red_mushroom_block 10
fill ~31~33~18 ~33~33~18 minecraft:bone_block 0
setblock ~31~34~18 minecraft:bone_block 0
setblock ~31~39~18 minecraft:stained_glass 3
setblock ~31~48~18 minecraft:stained_glass 3
setblock ~31~64~18 minecraft:leaves 3
setblock ~31~81~18 minecraft:stained_glass 0
setblock ~31~82~18 minecraft:concrete 3
fill ~32~34~18 ~33~34~18 minecraft:red_mushroom_block 15
setblock ~32~39~18 minecraft:blue_glazed_terracotta 2
fill ~32~64~18 ~34~65~18 minecraft:red_mushroom_block 15
setblock ~32~66~18 minecraft:red_mushroom_block 15
setblock ~32~81~18 minecraft:stained_glass 3
setblock ~33~0~18 minecraft:bone_block 0
fill ~33~1~18 ~33~1~19 minecraft:red_mushroom_block 15
setblock ~33~2~18 minecraft:red_mushroom_block 10
fill ~33~3~18 ~33~5~19 minecraft:red_mushroom_block 15
fill ~33~18~18 ~33~20~18 minecraft:leaves 0
setblock ~33~22~18 minecraft:air
fill ~33~37~18 ~34~39~18 minecraft:red_mushroom_block 15
setblock ~33~47~18 minecraft:wool 11
fill ~33~66~18 ~34~66~18 minecraft:bone_block 0
setblock ~33~81~18 minecraft:blue_glazed_terracotta 2
setblock ~34~6~18 minecraft:red_mushroom_block 15
setblock ~34~7~18 minecraft:bone_block 0
setblock ~34~8~18 minecraft:red_mushroom_block 15
fill ~34~9~18 ~34~10~18 minecraft:bone_block 0
setblock ~34~11~18 minecraft:red_mushroom_block 15
setblock ~34~12~18 minecraft:bone_block 0
setblock ~34~13~18 minecraft:red_mushroom_block 15
setblock ~34~14~18 minecraft:red_mushroom_block 10
fill ~34~15~18 ~34~16~18 minecraft:red_mushroom_block 15
setblock ~34~17~18 minecraft:bone_block 0
setblock ~34~18~18 minecraft:red_mushroom_block 15
setblock ~34~19~18 minecraft:bone_block 0
fill ~34~20~18 ~35~20~18 minecraft:red_mushroom_block 15
fill ~34~47~18 ~34~47~19 minecraft:red_mushroom_block 15
setblock ~34~48~18 minecraft:carpet 11
fill ~34~68~18 ~34~69~18 minecraft:leaves 0
setblock ~34~70~18 minecraft:air
setblock ~34~81~18 minecraft:concrete 11
setblock ~35~0~18 minecraft:sandstone 3
setblock ~35~19~18 minecraft:red_mushroom_block 15
fill ~35~21~18 ~35~23~18 minecraft:red_mushroom_block 10
fill ~35~24~18 ~36~25~18 minecraft:red_mushroom_block 15
fill ~35~26~18 ~35~28~18 minecraft:leaves 0
setblock ~35~29~18 minecraft:air
fill ~35~38~18 ~35~39~18 minecraft:bone_block 0
setblock ~35~40~18 minecraft:red_mushroom_block 15
setblock ~35~41~18 minecraft:red_mushroom_block 10
setblock ~35~42~18 minecraft:red_mushroom_block 15
setblock ~35~45~18 minecraft:stained_glass 0
setblock ~35~46~18 minecraft:red_mushroom_block 15
setblock ~35~47~18 minecraft:carpet 11
setblock ~35~81~18 minecraft:concrete 0
fill ~36~28~18 ~36~29~18 minecraft:leaves 0
setblock ~36~43~18 minecraft:concrete 0
setblock ~36~44~18 minecraft:blue_glazed_terracotta 2
setblock ~36~81~18 minecraft:stained_glass 3
fill ~37~23~18 ~37~23~20 minecraft:red_mushroom_block 15
fill ~37~24~18 ~39~24~18 minecraft:wooden_slab 13
setblock ~37~80~18 minecraft:stained_glass 0
fill ~38~16~18 ~39~16~18 minecraft:leaves 0
setblock ~38~17~18 minecraft:bone_block 0
fill ~38~18~18 ~38~20~19 minecraft:red_mushroom_block 15
fill ~38~21~18 ~38~22~18 minecraft:bone_block 0
setblock ~38~80~18 minecraft:wool 11
fill ~39~10~18 ~39~10~19 minecraft:bone_block 0
fill ~39~11~18 ~39~12~18 minecraft:bone_block 0
setblock ~39~13~18 minecraft:red_mushroom_block 15
setblock ~39~15~18 minecraft:leaves 0
fill ~39~36~18 ~39~36~20 minecraft:wooden_slab 13
setblock ~39~79~18 minecraft:concrete 3
fill ~40~3~18 ~41~3~18 minecraft:red_mushroom_block 15
fill ~40~4~18 ~40~6~18 minecraft:red_mushroom_block 10
setblock ~40~7~18 minecraft:red_mushroom_block 15
setblock ~40~8~18 minecraft:bone_block 0
setblock ~40~15~18 minecraft:leaves2 3
setblock ~40~16~18 minecraft:air
fill ~40~37~18 ~40~37~21 minecraft:wooden_slab 5
setblock ~40~77~18 minecraft:concrete 11
fill ~41~0~18 ~41~1~18 minecraft:red_mushroom_block 15
setblock ~41~2~18 minecraft:bone_block 0
fill ~41~27~18 ~41~27~19 minecraft:warped_stairs 0
fill ~41~37~18 ~41~37~22 minecraft:wooden_slab 13
setblock ~41~77~18 minecraft:stained_glass 3
fill ~42~27~18 ~44~27~18 minecraft:warped_stairs 2
setblock ~42~76~18 minecraft:blue_glazed_terracotta 2
setblock ~43~75~18 minecraft:wool 11
setblock ~43~76~18 minecraft:concrete 11
fill ~44~24~18 ~44~24~30 minecraft:wooden_slab 13
setblock ~44~74~18 minecraft:wool 11
setblock ~45~27~18 minecraft:warped_stairs 1
setblock ~45~71~18 minecraft:stained_glass 3
setblock ~45~72~18 minecraft:wool 11
setblock ~45~73~18 minecraft:concrete 0
fill ~46~71~18 ~46~71~20 minecraft:concrete 11
setblock ~47~68~18 minecraft:concrete 3
setblock ~47~69~18 minecraft:concrete 0
setblock ~48~65~18 minecraft:stained_glass 3
setblock ~48~66~18 minecraft:wool 11
fill ~48~67~18 ~48~68~18 minecraft:stained_glass 0
setblock ~49~0~18 minecraft:tallgrass 0
setblock ~49~52~18 minecraft:stained_glass 3
setblock ~49~53~18 minecraft:concrete 0
setblock ~49~54~18 minecraft:stained_glass 3
setblock ~49~55~18 minecraft:wool 11
setblock ~49~56~18 minecraft:blue_glazed_terracotta 2
setblock ~49~57~18 minecraft:stained_glass 3
setblock ~49~58~18 minecraft:concrete 0
setblock ~49~59~18 minecraft:stained_glass 3
setblock ~49~60~18 minecraft:wool 11
setblock ~49~61~18 minecraft:blue_glazed_terracotta 2
setblock ~49~63~18 minecraft:concrete 11
fill ~49~64~18 ~49~64~19 minecraft:stained_glass 3
fill ~50~2~18 ~50~2~19 minecraft:leaves 0
fill ~57~0~18 ~57~0~21 minecraft:grass
