setblock ~6 ~3 ~52 nether_brick_stairs 4 
setblock ~50 ~3 ~6 nether_brick_stairs 6 
setblock ~52 ~3 ~96 nether_brick_stairs 7 
setblock ~96 ~3 ~50 nether_brick_stairs 5  
fill ~6 ~4 ~52 ~6 ~42 ~52 red_nether_brick 0  
fill ~50 ~4 ~6 ~50 ~42 ~6 red_nether_brick 0  
fill ~52 ~4 ~96 ~52 ~42 ~96 red_nether_brick 0  
fill ~96 ~4 ~50 ~96 ~42 ~50 red_nether_brick 0 
setblock ~5 ~7 ~52 nether_brick_stairs 4 
setblock ~50 ~7 ~5 nether_brick_stairs 6 
setblock ~52 ~7 ~97 nether_brick_stairs 7 
setblock ~97 ~7 ~50 nether_brick_stairs 5  
fill ~5 ~8 ~52 ~5 ~45 ~52 red_nether_brick 0  
fill ~50 ~8 ~5 ~50 ~45 ~5 red_nether_brick 0  
fill ~52 ~8 ~97 ~52 ~45 ~97 red_nether_brick 0  
fill ~97 ~8 ~50 ~97 ~45 ~50 red_nether_brick 0 
setblock ~6 ~11 ~51 nether_brick_stairs 4 
setblock ~6 ~11 ~53 nether_brick_stairs 4 
setblock ~49 ~11 ~6 nether_brick_stairs 6 
setblock ~51 ~11 ~6 nether_brick_stairs 6 
setblock ~51 ~11 ~96 nether_brick_stairs 7 
setblock ~53 ~11 ~96 nether_brick_stairs 7 
setblock ~96 ~11 ~49 nether_brick_stairs 5 
setblock ~96 ~11 ~51 nether_brick_stairs 5  
fill ~4 ~12 ~45 ~4 ~19 ~45 nether_brick_fence 0 
setblock ~4 ~12 ~52 nether_brick_stairs 4  
fill ~4 ~12 ~57 ~4 ~19 ~57 nether_brick_fence 0  
fill ~6 ~12 ~51 ~6 ~39 ~51 red_nether_brick 0  
fill ~6 ~12 ~53 ~6 ~39 ~53 red_nether_brick 0  
fill ~45 ~12 ~4 ~45 ~19 ~4 nether_brick_fence 0  
fill ~45 ~12 ~98 ~45 ~19 ~98 nether_brick_fence 0  
fill ~49 ~12 ~6 ~49 ~39 ~6 red_nether_brick 0 
setblock ~50 ~12 ~4 nether_brick_stairs 6  
fill ~51 ~12 ~6 ~51 ~39 ~6 red_nether_brick 0  
fill ~51 ~12 ~96 ~51 ~39 ~96 red_nether_brick 0 
setblock ~52 ~12 ~98 nether_brick_stairs 7  
fill ~53 ~12 ~96 ~53 ~39 ~96 red_nether_brick 0  
fill ~57 ~12 ~4 ~57 ~19 ~4 nether_brick_fence 0  
fill ~57 ~12 ~98 ~57 ~19 ~98 nether_brick_fence 0  
fill ~96 ~12 ~49 ~96 ~39 ~49 red_nether_brick 0  
fill ~96 ~12 ~51 ~96 ~39 ~51 red_nether_brick 0  
fill ~98 ~12 ~45 ~98 ~19 ~45 nether_brick_fence 0 
setblock ~98 ~12 ~50 nether_brick_stairs 5  
fill ~98 ~12 ~57 ~98 ~19 ~57 nether_brick_fence 0  
fill ~4 ~13 ~52 ~4 ~31 ~52 red_nether_brick 0 
setblock ~23 ~13 ~52 nether_brick_stairs 4  
fill ~50 ~13 ~4 ~50 ~31 ~4 red_nether_brick 0 
setblock ~50 ~13 ~23 nether_brick_stairs 6 
setblock ~52 ~13 ~79 nether_brick_stairs 7  
fill ~52 ~13 ~98 ~52 ~31 ~98 red_nether_brick 0 
setblock ~79 ~13 ~50 nether_brick_stairs 5  
fill ~98 ~13 ~50 ~98 ~31 ~50 red_nether_brick 0 
setblock ~5 ~14 ~51 nether_brick_stairs 4 
setblock ~5 ~14 ~53 nether_brick_stairs 4 
setblock ~21 ~14 ~52 nether_brick_stairs 4 
setblock ~22 ~14 ~51 nether_brick_stairs 4  
fill ~22 ~14 ~52 ~23 ~14 ~52 red_nether_brick 0 
setblock ~22 ~14 ~53 nether_brick_stairs 4 
setblock ~49 ~14 ~5 nether_brick_stairs 6 
setblock ~49 ~14 ~22 nether_brick_stairs 6 
setblock ~50 ~14 ~21 nether_brick_stairs 6  
fill ~50 ~14 ~22 ~50 ~53 ~22 red_nether_brick 0  
fill ~50 ~14 ~23 ~50 ~58 ~23 red_nether_brick 0 
setblock ~51 ~14 ~5 nether_brick_stairs 6 
setblock ~51 ~14 ~22 nether_brick_stairs 6 
setblock ~51 ~14 ~80 nether_brick_stairs 7 
setblock ~51 ~14 ~97 nether_brick_stairs 7  
fill ~52 ~14 ~79 ~52 ~58 ~79 red_nether_brick 0  
fill ~52 ~14 ~80 ~52 ~53 ~80 red_nether_brick 0 
setblock ~52 ~14 ~81 nether_brick_stairs 7 
setblock ~53 ~14 ~80 nether_brick_stairs 7 
setblock ~53 ~14 ~97 nether_brick_stairs 7  
fill ~79 ~14 ~50 ~80 ~14 ~50 red_nether_brick 0 
setblock ~80 ~14 ~49 nether_brick_stairs 5 
setblock ~80 ~14 ~51 nether_brick_stairs 5 
setblock ~81 ~14 ~50 nether_brick_stairs 5 
setblock ~97 ~14 ~49 nether_brick_stairs 5 
setblock ~97 ~14 ~51 nether_brick_stairs 5  
fill ~5 ~15 ~51 ~5 ~43 ~51 red_nether_brick 0  
fill ~5 ~15 ~53 ~5 ~43 ~53 red_nether_brick 0  
fill ~21 ~15 ~52 ~23 ~15 ~52 red_nether_brick 0  
fill ~22 ~15 ~51 ~22 ~44 ~51 red_nether_brick 0  
fill ~22 ~15 ~53 ~22 ~44 ~53 red_nether_brick 0  
fill ~49 ~15 ~5 ~49 ~43 ~5 red_nether_brick 0  
fill ~49 ~15 ~22 ~49 ~44 ~22 red_nether_brick 0  
fill ~50 ~15 ~21 ~50 ~46 ~21 red_nether_brick 0  
fill ~51 ~15 ~5 ~51 ~43 ~5 red_nether_brick 0  
fill ~51 ~15 ~22 ~51 ~44 ~22 red_nether_brick 0  
fill ~51 ~15 ~80 ~51 ~44 ~80 red_nether_brick 0  
fill ~51 ~15 ~97 ~51 ~43 ~97 red_nether_brick 0  
fill ~52 ~15 ~81 ~52 ~46 ~81 red_nether_brick 0  
fill ~53 ~15 ~80 ~53 ~44 ~80 red_nether_brick 0  
fill ~53 ~15 ~97 ~53 ~43 ~97 red_nether_brick 0  
fill ~79 ~15 ~50 ~81 ~15 ~50 red_nether_brick 0  
fill ~80 ~15 ~49 ~80 ~44 ~49 red_nether_brick 0  
fill ~80 ~15 ~51 ~80 ~44 ~51 red_nether_brick 0  
fill ~97 ~15 ~49 ~97 ~43 ~49 red_nether_brick 0  
fill ~97 ~15 ~51 ~97 ~43 ~51 red_nether_brick 0 
setblock ~7 ~16 ~52 nether_brick_stairs 5 
setblock ~21 ~16 ~51 nether_brick_stairs 4  
fill ~21 ~16 ~52 ~23 ~16 ~52 red_nether_brick 0 
setblock ~21 ~16 ~53 nether_brick_stairs 4 
setblock ~49 ~16 ~21 nether_brick_stairs 6 
setblock ~50 ~16 ~7 nether_brick_stairs 7 
setblock ~51 ~16 ~21 nether_brick_stairs 6 
setblock ~51 ~16 ~81 nether_brick_stairs 7 
setblock ~52 ~16 ~95 nether_brick_stairs 6 
setblock ~53 ~16 ~81 nether_brick_stairs 7  
fill ~79 ~16 ~50 ~81 ~16 ~50 red_nether_brick 0 
setblock ~81 ~16 ~49 nether_brick_stairs 5 
setblock ~81 ~16 ~51 nether_brick_stairs 5 
setblock ~95 ~16 ~50 nether_brick_stairs 4 
setblock ~4 ~17 ~51 nether_brick_stairs 4 
setblock ~4 ~17 ~53 nether_brick_stairs 4  
fill ~7 ~17 ~52 ~7 ~39 ~52 red_nether_brick 0 
setblock ~19 ~17 ~52 nether_brick_stairs 4 
setblock ~20 ~17 ~51 nether_brick_stairs 4  
fill ~20 ~17 ~52 ~23 ~17 ~52 red_nether_brick 0 
setblock ~20 ~17 ~53 nether_brick_stairs 4  
fill ~21 ~17 ~51 ~21 ~39 ~51 red_nether_brick 0  
fill ~21 ~17 ~53 ~21 ~39 ~53 red_nether_brick 0 
setblock ~49 ~17 ~4 nether_brick_stairs 6 
setblock ~49 ~17 ~20 nether_brick_stairs 6  
fill ~49 ~17 ~21 ~49 ~39 ~21 red_nether_brick 0  
fill ~50 ~17 ~7 ~50 ~39 ~7 red_nether_brick 0 
setblock ~50 ~17 ~19 nether_brick_stairs 6  
fill ~50 ~17 ~20 ~50 ~38 ~20 red_nether_brick 0 
setblock ~51 ~17 ~4 nether_brick_stairs 6 
setblock ~51 ~17 ~20 nether_brick_stairs 6  
fill ~51 ~17 ~21 ~51 ~39 ~21 red_nether_brick 0  
fill ~51 ~17 ~81 ~51 ~39 ~81 red_nether_brick 0 
setblock ~51 ~17 ~82 nether_brick_stairs 7 
setblock ~51 ~17 ~98 nether_brick_stairs 7  
fill ~52 ~17 ~82 ~52 ~38 ~82 red_nether_brick 0 
setblock ~52 ~17 ~83 nether_brick_stairs 7  
fill ~52 ~17 ~95 ~52 ~39 ~95 red_nether_brick 0  
fill ~53 ~17 ~81 ~53 ~39 ~81 red_nether_brick 0 
setblock ~53 ~17 ~82 nether_brick_stairs 7 
setblock ~53 ~17 ~98 nether_brick_stairs 7  
fill ~79 ~17 ~50 ~82 ~17 ~50 red_nether_brick 0  
fill ~81 ~17 ~49 ~81 ~39 ~49 red_nether_brick 0  
fill ~81 ~17 ~51 ~81 ~39 ~51 red_nether_brick 0 
setblock ~82 ~17 ~49 nether_brick_stairs 5 
setblock ~82 ~17 ~51 nether_brick_stairs 5 
setblock ~83 ~17 ~50 nether_brick_stairs 5  
fill ~95 ~17 ~50 ~95 ~39 ~50 red_nether_brick 0 
setblock ~98 ~17 ~49 nether_brick_stairs 5 
setblock ~98 ~17 ~51 nether_brick_stairs 5 
setblock ~3 ~18 ~45 nether_brick_fence 0 
setblock ~3 ~18 ~52 nether_brick_stairs 4 
setblock ~3 ~18 ~57 nether_brick_fence 0  
fill ~4 ~18 ~51 ~4 ~29 ~51 red_nether_brick 0  
fill ~4 ~18 ~53 ~4 ~29 ~53 red_nether_brick 0 
setblock ~18 ~18 ~52 nether_brick_stairs 4 
setblock ~19 ~18 ~51 nether_brick_stairs 4  
fill ~19 ~18 ~52 ~23 ~18 ~52 red_nether_brick 0 
setblock ~19 ~18 ~53 nether_brick_stairs 4  
fill ~20 ~18 ~51 ~20 ~35 ~51 red_nether_brick 0  
fill ~20 ~18 ~53 ~20 ~35 ~53 red_nether_brick 0 
setblock ~21 ~18 ~54 nether_brick_stairs 7 
setblock ~45 ~18 ~3 nether_brick_fence 0 
setblock ~45 ~18 ~99 nether_brick_fence 0 
setblock ~48 ~18 ~21 nether_brick_stairs 4  
fill ~49 ~18 ~4 ~49 ~29 ~4 red_nether_brick 0 
setblock ~49 ~18 ~19 nether_brick_stairs 6  
fill ~49 ~18 ~20 ~49 ~35 ~20 red_nether_brick 0 
setblock ~50 ~18 ~3 nether_brick_stairs 6 
setblock ~50 ~18 ~18 nether_brick_stairs 6  
fill ~50 ~18 ~19 ~50 ~35 ~19 red_nether_brick 0  
fill ~51 ~18 ~4 ~51 ~29 ~4 red_nether_brick 0 
setblock ~51 ~18 ~19 nether_brick_stairs 6  
fill ~51 ~18 ~20 ~51 ~35 ~20 red_nether_brick 0  
fill ~51 ~18 ~82 ~51 ~35 ~82 red_nether_brick 0 
setblock ~51 ~18 ~83 nether_brick_stairs 7  
fill ~51 ~18 ~98 ~51 ~29 ~98 red_nether_brick 0  
fill ~52 ~18 ~83 ~52 ~35 ~83 red_nether_brick 0 
setblock ~52 ~18 ~84 nether_brick_stairs 7 
setblock ~52 ~18 ~99 nether_brick_stairs 7  
fill ~53 ~18 ~82 ~53 ~35 ~82 red_nether_brick 0 
setblock ~53 ~18 ~83 nether_brick_stairs 7  
fill ~53 ~18 ~98 ~53 ~29 ~98 red_nether_brick 0 
setblock ~54 ~18 ~81 nether_brick_stairs 5 
setblock ~57 ~18 ~3 nether_brick_fence 0 
setblock ~57 ~18 ~99 nether_brick_fence 0  
fill ~79 ~18 ~50 ~83 ~18 ~50 red_nether_brick 0 
setblock ~81 ~18 ~48 nether_brick_stairs 6  
fill ~82 ~18 ~49 ~82 ~35 ~49 red_nether_brick 0  
fill ~82 ~18 ~51 ~82 ~35 ~51 red_nether_brick 0 
setblock ~83 ~18 ~49 nether_brick_stairs 5 
setblock ~83 ~18 ~51 nether_brick_stairs 5 
setblock ~84 ~18 ~50 nether_brick_stairs 5  
fill ~98 ~18 ~49 ~98 ~29 ~49 red_nether_brick 0  
fill ~98 ~18 ~51 ~98 ~29 ~51 red_nether_brick 0 
setblock ~99 ~18 ~45 nether_brick_fence 0 
setblock ~99 ~18 ~50 nether_brick_stairs 5 
setblock ~99 ~18 ~57 nether_brick_fence 0 
setblock ~3 ~19 ~45 nether_brick_stairs 4  
fill ~3 ~19 ~52 ~3 ~29 ~52 red_nether_brick 0 
setblock ~3 ~19 ~57 nether_brick_stairs 4 
setblock ~8 ~19 ~52 nether_brick_stairs 5 
setblock ~17 ~19 ~52 nether_brick_stairs 4  
fill ~18 ~19 ~51 ~22 ~19 ~51 red_nether_brick 0  
fill ~18 ~19 ~52 ~23 ~19 ~52 red_nether_brick 0  
fill ~18 ~19 ~53 ~22 ~19 ~53 red_nether_brick 0 
setblock ~20 ~19 ~50 nether_brick_stairs 4  
fill ~21 ~19 ~50 ~21 ~32 ~50 red_nether_brick 0  
fill ~21 ~19 ~54 ~21 ~32 ~54 red_nether_brick 0 
setblock ~23 ~19 ~51 nether_brick_stairs 5 
setblock ~23 ~19 ~53 nether_brick_stairs 5 
setblock ~45 ~19 ~3 nether_brick_stairs 6 
setblock ~45 ~19 ~99 nether_brick_stairs 7  
fill ~48 ~19 ~21 ~48 ~32 ~21 red_nether_brick 0  
fill ~49 ~19 ~18 ~51 ~19 ~18 red_nether_brick 0  
fill ~49 ~19 ~19 ~49 ~33 ~19 red_nether_brick 0 
setblock ~49 ~19 ~23 nether_brick_stairs 7  
fill ~50 ~19 ~3 ~50 ~29 ~3 red_nether_brick 0 
setblock ~50 ~19 ~8 nether_brick_stairs 7 
setblock ~50 ~19 ~17 nether_brick_stairs 6  
fill ~50 ~19 ~81 ~50 ~32 ~81 red_nether_brick 0 
setblock ~50 ~19 ~82 nether_brick_stairs 7  
fill ~51 ~19 ~19 ~51 ~33 ~19 red_nether_brick 0 
setblock ~51 ~19 ~23 nether_brick_stairs 7 
setblock ~51 ~19 ~79 nether_brick_stairs 6  
fill ~51 ~19 ~83 ~51 ~33 ~83 red_nether_brick 0  
fill ~51 ~19 ~84 ~53 ~19 ~84 red_nether_brick 0 
setblock ~52 ~19 ~20 nether_brick_stairs 6  
fill ~52 ~19 ~21 ~52 ~21 ~21 red_nether_brick 0 
setblock ~52 ~19 ~85 nether_brick_stairs 7 
setblock ~52 ~19 ~94 nether_brick_stairs 6  
fill ~52 ~19 ~99 ~52 ~29 ~99 red_nether_brick 0 
setblock ~53 ~19 ~79 nether_brick_stairs 6  
fill ~53 ~19 ~83 ~53 ~33 ~83 red_nether_brick 0  
fill ~54 ~19 ~81 ~54 ~32 ~81 red_nether_brick 0 
setblock ~57 ~19 ~3 nether_brick_stairs 6 
setblock ~57 ~19 ~99 nether_brick_stairs 7 
setblock ~79 ~19 ~49 nether_brick_stairs 4  
fill ~79 ~19 ~50 ~84 ~19 ~50 red_nether_brick 0 
setblock ~79 ~19 ~51 nether_brick_stairs 4  
fill ~81 ~19 ~48 ~81 ~32 ~48 red_nether_brick 0  
fill ~81 ~19 ~52 ~81 ~32 ~52 red_nether_brick 0 
setblock ~82 ~19 ~52 nether_brick_stairs 5  
fill ~83 ~19 ~49 ~84 ~19 ~49 red_nether_brick 0  
fill ~83 ~19 ~51 ~84 ~19 ~51 red_nether_brick 0 
setblock ~85 ~19 ~50 nether_brick_stairs 5 
setblock ~94 ~19 ~50 nether_brick_stairs 4 
setblock ~99 ~19 ~45 nether_brick_stairs 5  
fill ~99 ~19 ~50 ~99 ~29 ~50 red_nether_brick 0 
setblock ~99 ~19 ~57 nether_brick_stairs 5  
fill ~2 ~20 ~45 ~2 ~26 ~45 stone_slab 7  
fill ~2 ~20 ~57 ~2 ~26 ~57 stone_slab 7  
fill ~3 ~20 ~45 ~3 ~28 ~45 red_nether_brick 0  
fill ~3 ~20 ~57 ~3 ~28 ~57 red_nether_brick 0  
fill ~4 ~20 ~45 ~4 ~28 ~45 grass_path 4  
fill ~4 ~20 ~57 ~4 ~28 ~57 grass_path 4 
setblock ~7 ~20 ~51 nether_brick_stairs 5 
setblock ~7 ~20 ~53 nether_brick_stairs 5  
fill ~8 ~20 ~52 ~8 ~37 ~52 red_nether_brick 0 
setblock ~16 ~20 ~52 nether_brick_stairs 4 
setblock ~17 ~20 ~51 nether_brick_stairs 4  
fill ~17 ~20 ~52 ~23 ~20 ~52 red_nether_brick 0 
setblock ~17 ~20 ~53 nether_brick_stairs 4  
fill ~18 ~20 ~51 ~23 ~20 ~51 red_nether_brick 0  
fill ~18 ~20 ~53 ~23 ~20 ~53 red_nether_brick 0 
setblock ~19 ~20 ~50 nether_brick_stairs 4 
setblock ~19 ~20 ~54 nether_brick_stairs 4  
fill ~20 ~20 ~50 ~20 ~32 ~50 red_nether_brick 0  
fill ~20 ~20 ~54 ~20 ~32 ~54 red_nether_brick 0 
setblock ~24 ~20 ~52 nether_brick_stairs 5  
fill ~45 ~20 ~2 ~45 ~26 ~2 stone_slab 7  
fill ~45 ~20 ~3 ~45 ~28 ~3 red_nether_brick 0  
fill ~45 ~20 ~4 ~45 ~28 ~4 grass_path 2  
fill ~45 ~20 ~98 ~45 ~28 ~98 grass_path 3  
fill ~45 ~20 ~99 ~45 ~28 ~99 red_nether_brick 0  
fill ~45 ~20 ~100 ~45 ~26 ~100 stone_slab 7 
setblock ~48 ~20 ~19 nether_brick_stairs 6  
fill ~48 ~20 ~20 ~48 ~32 ~20 red_nether_brick 0 
setblock ~49 ~20 ~7 nether_brick_stairs 7 
setblock ~49 ~20 ~17 nether_brick_stairs 6  
fill ~49 ~20 ~18 ~51 ~20 ~18 red_nether_brick 0  
fill ~49 ~20 ~23 ~49 ~55 ~23 red_nether_brick 0  
fill ~50 ~20 ~8 ~50 ~37 ~8 red_nether_brick 0 
setblock ~50 ~20 ~16 nether_brick_stairs 6  
fill ~50 ~20 ~17 ~50 ~32 ~17 red_nether_brick 0 
setblock ~50 ~20 ~24 nether_brick_stairs 7  
fill ~50 ~20 ~82 ~50 ~32 ~82 red_nether_brick 0 
setblock ~50 ~20 ~83 nether_brick_stairs 7 
setblock ~51 ~20 ~7 nether_brick_stairs 7 
setblock ~51 ~20 ~17 nether_brick_stairs 6  
fill ~51 ~20 ~23 ~51 ~55 ~23 red_nether_brick 0  
fill ~51 ~20 ~79 ~51 ~55 ~79 red_nether_brick 0  
fill ~51 ~20 ~84 ~53 ~20 ~84 red_nether_brick 0 
setblock ~51 ~20 ~85 nether_brick_stairs 7 
setblock ~51 ~20 ~95 nether_brick_stairs 6 
setblock ~52 ~20 ~19 nether_brick_stairs 6  
fill ~52 ~20 ~20 ~52 ~32 ~20 red_nether_brick 0 
setblock ~52 ~20 ~78 nether_brick_stairs 6  
fill ~52 ~20 ~85 ~52 ~32 ~85 red_nether_brick 0 
setblock ~52 ~20 ~86 nether_brick_stairs 7  
fill ~52 ~20 ~94 ~52 ~37 ~94 red_nether_brick 0  
fill ~53 ~20 ~79 ~53 ~55 ~79 red_nether_brick 0 
setblock ~53 ~20 ~85 nether_brick_stairs 7 
setblock ~53 ~20 ~95 nether_brick_stairs 6  
fill ~54 ~20 ~82 ~54 ~32 ~82 red_nether_brick 0 
setblock ~54 ~20 ~83 nether_brick_stairs 7  
fill ~57 ~20 ~2 ~57 ~26 ~2 stone_slab 7  
fill ~57 ~20 ~3 ~57 ~28 ~3 red_nether_brick 0  
fill ~57 ~20 ~4 ~57 ~28 ~4 grass_path 2  
fill ~57 ~20 ~98 ~57 ~28 ~98 grass_path 3  
fill ~57 ~20 ~99 ~57 ~28 ~99 red_nether_brick 0  
fill ~57 ~20 ~100 ~57 ~26 ~100 stone_slab 7 
setblock ~78 ~20 ~50 nether_brick_stairs 4  
fill ~79 ~20 ~49 ~79 ~55 ~49 red_nether_brick 0  
fill ~79 ~20 ~50 ~85 ~20 ~50 red_nether_brick 0  
fill ~79 ~20 ~51 ~79 ~55 ~51 red_nether_brick 0  
fill ~82 ~20 ~48 ~82 ~32 ~48 red_nether_brick 0  
fill ~82 ~20 ~52 ~82 ~32 ~52 red_nether_brick 0 
setblock ~83 ~20 ~48 nether_brick_stairs 5  
fill ~83 ~20 ~49 ~84 ~20 ~49 red_nether_brick 0  
fill ~83 ~20 ~51 ~84 ~20 ~51 red_nether_brick 0 
setblock ~83 ~20 ~52 nether_brick_stairs 5 
setblock ~85 ~20 ~49 nether_brick_stairs 5 
setblock ~85 ~20 ~51 nether_brick_stairs 5 
setblock ~86 ~20 ~50 nether_brick_stairs 5  
fill ~94 ~20 ~50 ~94 ~37 ~50 red_nether_brick 0 
setblock ~95 ~20 ~49 nether_brick_stairs 4 
setblock ~95 ~20 ~51 nether_brick_stairs 4  
fill ~98 ~20 ~45 ~98 ~28 ~45 grass_path 5  
fill ~98 ~20 ~57 ~98 ~28 ~57 grass_path 5  
fill ~99 ~20 ~45 ~99 ~28 ~45 red_nether_brick 0  
fill ~99 ~20 ~57 ~99 ~28 ~57 red_nether_brick 0  
fill ~100 ~20 ~45 ~100 ~26 ~45 stone_slab 7  
fill ~100 ~20 ~57 ~100 ~26 ~57 stone_slab 7  
fill ~7 ~21 ~51 ~7 ~37 ~51 red_nether_brick 0  
fill ~7 ~21 ~53 ~7 ~37 ~53 red_nether_brick 0 
setblock ~8 ~21 ~53 nether_brick_stairs 5 
setblock ~9 ~21 ~52 nether_brick_stairs 5 
setblock ~11 ~21 ~52 nether_brick_stairs 4  
fill ~12 ~21 ~52 ~24 ~21 ~52 red_nether_brick 0 
setblock ~13 ~21 ~51 nether_brick_stairs 4 
setblock ~13 ~21 ~53 nether_brick_stairs 4  
fill ~14 ~21 ~51 ~23 ~21 ~51 red_nether_brick 0  
fill ~14 ~21 ~53 ~23 ~21 ~53 red_nether_brick 0 
setblock ~17 ~21 ~54 nether_brick_stairs 0  
fill ~18 ~21 ~50 ~21 ~21 ~50 red_nether_brick 0  
fill ~18 ~21 ~54 ~21 ~21 ~54 red_nether_brick 0  
fill ~22 ~21 ~50 ~22 ~22 ~50 nether_brick_stairs 5 
setblock ~48 ~21 ~17 nether_brick_stairs 2  
fill ~48 ~21 ~18 ~52 ~21 ~18 red_nether_brick 0  
fill ~48 ~21 ~19 ~48 ~32 ~19 red_nether_brick 0  
fill ~49 ~21 ~7 ~49 ~37 ~7 red_nether_brick 0 
setblock ~49 ~21 ~8 nether_brick_stairs 7 
setblock ~49 ~21 ~13 nether_brick_stairs 6  
fill ~49 ~21 ~14 ~51 ~21 ~14 red_nether_brick 0  
fill ~49 ~21 ~15 ~51 ~21 ~15 red_nether_brick 0  
fill ~49 ~21 ~16 ~51 ~21 ~16 red_nether_brick 0  
fill ~49 ~21 ~17 ~49 ~32 ~17 red_nether_brick 0 
setblock ~50 ~21 ~9 nether_brick_stairs 7 
setblock ~50 ~21 ~11 nether_brick_stairs 6  
fill ~50 ~21 ~12 ~50 ~32 ~12 red_nether_brick 0  
fill ~50 ~21 ~13 ~50 ~32 ~13 red_nether_brick 0  
fill ~50 ~21 ~24 ~50 ~62 ~24 red_nether_brick 0  
fill ~50 ~21 ~80 ~50 ~22 ~80 nether_brick_stairs 6  
fill ~50 ~21 ~83 ~50 ~32 ~83 red_nether_brick 0  
fill ~50 ~21 ~84 ~54 ~21 ~84 red_nether_brick 0  
fill ~51 ~21 ~7 ~51 ~37 ~7 red_nether_brick 0 
setblock ~51 ~21 ~13 nether_brick_stairs 6  
fill ~51 ~21 ~17 ~51 ~32 ~17 red_nether_brick 0  
fill ~51 ~21 ~85 ~51 ~32 ~85 red_nether_brick 0  
fill ~51 ~21 ~86 ~53 ~21 ~86 red_nether_brick 0  
fill ~51 ~21 ~87 ~53 ~21 ~87 red_nether_brick 0  
fill ~51 ~21 ~88 ~53 ~21 ~88 red_nether_brick 0 
setblock ~51 ~21 ~89 nether_brick_stairs 7  
fill ~51 ~21 ~95 ~51 ~37 ~95 red_nether_brick 0  
fill ~52 ~21 ~19 ~52 ~32 ~19 red_nether_brick 0  
fill ~52 ~21 ~78 ~52 ~62 ~78 red_nether_brick 0  
fill ~52 ~21 ~89 ~52 ~32 ~89 red_nether_brick 0  
fill ~52 ~21 ~90 ~52 ~32 ~90 red_nether_brick 0 
setblock ~52 ~21 ~91 nether_brick_stairs 7 
setblock ~52 ~21 ~93 nether_brick_stairs 6  
fill ~53 ~21 ~85 ~53 ~32 ~85 red_nether_brick 0 
setblock ~53 ~21 ~89 nether_brick_stairs 7 
setblock ~53 ~21 ~94 nether_brick_stairs 6  
fill ~53 ~21 ~95 ~53 ~37 ~95 red_nether_brick 0  
fill ~54 ~21 ~83 ~54 ~32 ~83 red_nether_brick 0 
setblock ~54 ~21 ~85 nether_brick_stairs 3  
fill ~78 ~21 ~50 ~90 ~21 ~50 red_nether_brick 0  
fill ~80 ~21 ~52 ~80 ~22 ~52 nether_brick_stairs 4  
fill ~83 ~21 ~48 ~84 ~21 ~48 red_nether_brick 0  
fill ~83 ~21 ~49 ~88 ~21 ~49 red_nether_brick 0  
fill ~83 ~21 ~51 ~88 ~21 ~51 red_nether_brick 0  
fill ~83 ~21 ~52 ~84 ~21 ~52 red_nether_brick 0 
setblock ~85 ~21 ~48 nether_brick_stairs 1 
setblock ~89 ~21 ~49 nether_brick_stairs 5 
setblock ~89 ~21 ~51 nether_brick_stairs 5 
setblock ~91 ~21 ~50 nether_brick_stairs 5 
setblock ~93 ~21 ~50 nether_brick_stairs 4 
setblock ~94 ~21 ~49 nether_brick_stairs 4  
fill ~95 ~21 ~49 ~95 ~37 ~49 red_nether_brick 0  
fill ~95 ~21 ~51 ~95 ~37 ~51 red_nether_brick 0  
fill ~8 ~22 ~51 ~8 ~35 ~51 red_nether_brick 0  
fill ~8 ~22 ~53 ~8 ~35 ~53 red_nether_brick 0 
setblock ~9 ~22 ~51 nether_brick_stairs 5  
fill ~9 ~22 ~52 ~24 ~22 ~52 red_nether_brick 0 
setblock ~9 ~22 ~53 nether_brick_stairs 5 
setblock ~10 ~22 ~51 nether_brick_stairs 4 
setblock ~10 ~22 ~53 nether_brick_stairs 4  
fill ~11 ~22 ~51 ~23 ~22 ~51 red_nether_brick 0  
fill ~11 ~22 ~53 ~23 ~22 ~53 red_nether_brick 0 
setblock ~12 ~22 ~44 stone_slab 15  
fill ~12 ~22 ~45 ~14 ~22 ~45 red_nether_brick 0  
fill ~12 ~22 ~46 ~14 ~22 ~46 red_nether_brick 0  
fill ~12 ~22 ~47 ~14 ~22 ~47 red_nether_brick 0  
fill ~12 ~22 ~48 ~14 ~22 ~48 red_nether_brick 0  
fill ~12 ~22 ~49 ~14 ~22 ~49 red_nether_brick 0  
fill ~12 ~22 ~50 ~21 ~22 ~50 red_nether_brick 0  
fill ~12 ~22 ~54 ~21 ~22 ~54 red_nether_brick 0  
fill ~12 ~22 ~55 ~14 ~22 ~55 red_nether_brick 0  
fill ~12 ~22 ~56 ~14 ~22 ~56 red_nether_brick 0  
fill ~12 ~22 ~57 ~14 ~22 ~57 red_nether_brick 0 
setblock ~12 ~22 ~58 stone_slab 15 
setblock ~13 ~22 ~40 stone_slab 15  
fill ~13 ~22 ~41 ~15 ~22 ~41 red_nether_brick 0  
fill ~13 ~22 ~42 ~15 ~22 ~42 red_nether_brick 0  
fill ~13 ~22 ~43 ~15 ~22 ~43 red_nether_brick 0  
fill ~13 ~22 ~44 ~15 ~22 ~44 red_nether_brick 0  
fill ~13 ~22 ~58 ~15 ~22 ~58 red_nether_brick 0  
fill ~13 ~22 ~59 ~15 ~22 ~59 red_nether_brick 0  
fill ~13 ~22 ~60 ~15 ~22 ~60 red_nether_brick 0  
fill ~13 ~22 ~61 ~15 ~22 ~61 red_nether_brick 0 
setblock ~13 ~22 ~62 stone_slab 15 
setblock ~14 ~22 ~37 stone_slab 15  
fill ~14 ~22 ~38 ~16 ~22 ~38 red_nether_brick 0  
fill ~14 ~22 ~39 ~16 ~22 ~39 red_nether_brick 0  
fill ~14 ~22 ~40 ~16 ~22 ~40 red_nether_brick 0  
fill ~14 ~22 ~62 ~16 ~22 ~62 red_nether_brick 0  
fill ~15 ~22 ~35 ~16 ~22 ~35 red_nether_brick 0  
fill ~15 ~22 ~36 ~17 ~22 ~36 red_nether_brick 0  
fill ~15 ~22 ~37 ~17 ~22 ~37 red_nether_brick 0  
fill ~16 ~22 ~46 ~21 ~22 ~46 red_nether_brick 0  
fill ~16 ~22 ~47 ~21 ~22 ~47 red_nether_brick 0  
fill ~16 ~22 ~48 ~21 ~22 ~48 red_nether_brick 0  
fill ~16 ~22 ~49 ~21 ~22 ~49 red_nether_brick 0  
fill ~16 ~22 ~55 ~21 ~22 ~55 red_nether_brick 0  
fill ~16 ~22 ~56 ~21 ~22 ~56 red_nether_brick 0  
fill ~17 ~22 ~41 ~18 ~22 ~41 red_nether_brick 0  
fill ~17 ~22 ~42 ~22 ~22 ~42 red_nether_brick 0  
fill ~17 ~22 ~43 ~22 ~22 ~43 red_nether_brick 0  
fill ~17 ~22 ~44 ~21 ~22 ~44 red_nether_brick 0  
fill ~17 ~22 ~45 ~21 ~22 ~45 red_nether_brick 0  
fill ~17 ~22 ~57 ~21 ~22 ~57 red_nether_brick 0  
fill ~17 ~22 ~58 ~21 ~22 ~58 red_nether_brick 0  
fill ~17 ~22 ~59 ~21 ~22 ~59 red_nether_brick 0 
setblock ~18 ~22 ~35 red_nether_brick 0  
fill ~18 ~22 ~38 ~18 ~22 ~59 red_nether_brick 0  
fill ~19 ~22 ~36 ~20 ~22 ~36 red_nether_brick 0  
fill ~19 ~22 ~37 ~24 ~22 ~37 red_nether_brick 0  
fill ~19 ~22 ~39 ~23 ~22 ~39 red_nether_brick 0  
fill ~19 ~22 ~40 ~23 ~22 ~40 red_nether_brick 0  
fill ~20 ~22 ~35 ~24 ~22 ~35 red_nether_brick 0  
fill ~20 ~22 ~38 ~23 ~22 ~38 red_nether_brick 0  
fill ~20 ~22 ~41 ~22 ~22 ~41 red_nether_brick 0 
setblock ~21 ~22 ~25 stone_slab 15 
setblock ~22 ~22 ~24 stone_slab 15  
fill ~22 ~22 ~25 ~24 ~22 ~25 red_nether_brick 0  
fill ~22 ~22 ~26 ~22 ~22 ~25 red_nether_brick 0 
setblock ~22 ~22 ~28 red_nether_brick 0  
fill ~22 ~22 ~31 ~23 ~22 ~31 red_nether_brick 0  
fill ~22 ~22 ~32 ~26 ~22 ~32 red_nether_brick 0  
fill ~22 ~22 ~33 ~24 ~22 ~33 red_nether_brick 0  
fill ~22 ~22 ~36 ~24 ~22 ~36 red_nether_brick 0 
setblock ~22 ~22 ~44 nether_brick_stairs 7  
fill ~22 ~22 ~45 ~22 ~22 ~50 nether_brick_stairs 5  
fill ~22 ~22 ~54 ~22 ~22 ~58 nether_brick_stairs 5 
setblock ~22 ~22 ~59 nether_brick_stairs 6  
fill ~22 ~22 ~60 ~22 ~22 ~67 red_nether_brick 0  
fill ~22 ~22 ~69 ~24 ~22 ~69 red_nether_brick 0  
fill ~22 ~22 ~70 ~26 ~22 ~70 red_nether_brick 0  
fill ~22 ~22 ~71 ~23 ~22 ~71 red_nether_brick 0 
setblock ~22 ~22 ~74 red_nether_brick 0  
fill ~22 ~22 ~76 ~22 ~22 ~77 red_nether_brick 0 
setblock ~22 ~22 ~78 stone_slab 15 
setblock ~23 ~22 ~23 stone_slab 15  
fill ~23 ~22 ~24 ~26 ~22 ~24 red_nether_brick 0 
setblock ~23 ~22 ~27 red_nether_brick 0  
fill ~23 ~22 ~30 ~25 ~22 ~30 red_nether_brick 0  
fill ~23 ~22 ~34 ~25 ~22 ~34 red_nether_brick 0  
fill ~23 ~22 ~41 ~23 ~22 ~44 nether_brick_stairs 5  
fill ~23 ~22 ~59 ~23 ~22 ~60 nether_brick_stairs 5 
setblock ~23 ~22 ~61 nether_brick_stairs 6  
fill ~23 ~22 ~62 ~23 ~22 ~72 red_nether_brick 0 
setblock ~23 ~22 ~75 red_nether_brick 0  
fill ~23 ~22 ~77 ~24 ~22 ~77 red_nether_brick 0  
fill ~23 ~22 ~78 ~26 ~22 ~78 red_nether_brick 0 
setblock ~23 ~22 ~79 stone_slab 15 
setblock ~24 ~22 ~22 stone_slab 15  
fill ~24 ~22 ~23 ~25 ~22 ~23 red_nether_brick 0 
setblock ~24 ~22 ~26 red_nether_brick 0  
fill ~24 ~22 ~28 ~24 ~22 ~30 red_nether_brick 0 
setblock ~24 ~22 ~38 nether_brick_stairs 7  
fill ~24 ~22 ~39 ~24 ~22 ~40 nether_brick_stairs 5 
setblock ~24 ~22 ~41 nether_brick_stairs 7 
setblock ~24 ~22 ~51 nether_brick_stairs 5 
setblock ~24 ~22 ~53 nether_brick_stairs 5  
fill ~24 ~22 ~61 ~24 ~22 ~63 nether_brick_stairs 5 
setblock ~24 ~22 ~64 nether_brick_stairs 6  
fill ~24 ~22 ~65 ~24 ~22 ~70 red_nether_brick 0  
fill ~24 ~22 ~72 ~25 ~22 ~72 red_nether_brick 0  
fill ~24 ~22 ~73 ~26 ~22 ~73 red_nether_brick 0  
fill ~24 ~22 ~74 ~24 ~22 ~72 red_nether_brick 0 
setblock ~24 ~22 ~76 red_nether_brick 0  
fill ~24 ~22 ~79 ~25 ~22 ~79 red_nether_brick 0 
setblock ~24 ~22 ~80 stone_slab 15 
setblock ~25 ~22 ~21 stone_slab 15  
fill ~25 ~22 ~22 ~26 ~22 ~22 red_nether_brick 0 
setblock ~25 ~22 ~27 red_nether_brick 0  
fill ~25 ~22 ~29 ~26 ~22 ~29 red_nether_brick 0  
fill ~25 ~22 ~31 ~27 ~22 ~31 red_nether_brick 0 
setblock ~25 ~22 ~35 nether_brick_stairs 3  
fill ~25 ~22 ~36 ~26 ~22 ~36 nether_brick_stairs 7  
fill ~25 ~22 ~37 ~25 ~22 ~38 nether_brick_stairs 5  
fill ~25 ~22 ~64 ~25 ~22 ~65 nether_brick_stairs 5 
setblock ~25 ~22 ~66 nether_brick_stairs 6 
setblock ~25 ~22 ~67 nether_brick_stairs 1 
setblock ~25 ~22 ~68 red_nether_brick 0  
fill ~25 ~22 ~71 ~28 ~22 ~71 red_nether_brick 0 
setblock ~25 ~22 ~75 red_nether_brick 0  
fill ~25 ~22 ~80 ~26 ~22 ~80 red_nether_brick 0  
fill ~26 ~22 ~21 ~29 ~22 ~21 red_nether_brick 0 
setblock ~26 ~22 ~26 red_nether_brick 0  
fill ~26 ~22 ~28 ~27 ~22 ~28 red_nether_brick 0 
setblock ~26 ~22 ~33 red_nether_brick 0  
fill ~26 ~22 ~34 ~26 ~22 ~35 nether_brick_stairs 5  
fill ~26 ~22 ~66 ~26 ~22 ~67 nether_brick_stairs 5 
setblock ~26 ~22 ~68 nether_brick_stairs 6 
setblock ~26 ~22 ~69 red_nether_brick 0  
fill ~26 ~22 ~74 ~27 ~22 ~74 red_nether_brick 0 
setblock ~26 ~22 ~76 red_nether_brick 0  
fill ~27 ~22 ~20 ~27 ~24 ~20 red_nether_brick 0 
setblock ~27 ~22 ~23 red_nether_brick 0 
setblock ~27 ~22 ~25 red_nether_brick 0  
fill ~27 ~22 ~27 ~28 ~22 ~27 red_nether_brick 0  
fill ~27 ~22 ~30 ~29 ~22 ~30 red_nether_brick 0 
setblock ~27 ~22 ~32 nether_brick_stairs 1 
setblock ~27 ~22 ~33 nether_brick_stairs 5 
setblock ~27 ~22 ~34 nether_brick_stairs 7 
setblock ~27 ~22 ~68 nether_brick_stairs 5 
setblock ~27 ~22 ~69 nether_brick_stairs 6 
setblock ~27 ~22 ~70 nether_brick_stairs 2  
fill ~27 ~22 ~72 ~29 ~22 ~72 red_nether_brick 0  
fill ~27 ~22 ~75 ~28 ~22 ~75 red_nether_brick 0 
setblock ~27 ~22 ~77 red_nether_brick 0 
setblock ~27 ~22 ~79 red_nether_brick 0  
fill ~28 ~22 ~19 ~33 ~22 ~19 red_nether_brick 0 
setblock ~28 ~22 ~22 red_nether_brick 0  
fill ~28 ~22 ~24 ~30 ~22 ~24 red_nether_brick 0  
fill ~28 ~22 ~26 ~29 ~22 ~26 red_nether_brick 0  
fill ~28 ~22 ~29 ~30 ~22 ~29 red_nether_brick 0 
setblock ~28 ~22 ~31 nether_brick_stairs 1 
setblock ~28 ~22 ~32 nether_brick_stairs 5 
setblock ~28 ~22 ~33 nether_brick_stairs 7 
setblock ~28 ~22 ~69 nether_brick_stairs 5 
setblock ~28 ~22 ~70 nether_brick_stairs 6  
fill ~28 ~22 ~73 ~30 ~22 ~73 red_nether_brick 0  
fill ~28 ~22 ~76 ~29 ~22 ~76 red_nether_brick 0  
fill ~28 ~22 ~78 ~30 ~22 ~78 red_nether_brick 0 
setblock ~28 ~22 ~80 red_nether_brick 0 
setblock ~29 ~22 ~18 stone_slab 15  
fill ~29 ~22 ~20 ~31 ~22 ~20 red_nether_brick 0  
fill ~29 ~22 ~25 ~32 ~22 ~25 red_nether_brick 0  
fill ~29 ~22 ~28 ~31 ~22 ~28 red_nether_brick 0 
setblock ~29 ~22 ~31 nether_brick_stairs 5 
setblock ~29 ~22 ~32 nether_brick_stairs 7 
setblock ~29 ~22 ~70 nether_brick_stairs 5 
setblock ~29 ~22 ~71 nether_brick_stairs 6  
fill ~29 ~22 ~74 ~30 ~22 ~74 red_nether_brick 0  
fill ~29 ~22 ~77 ~32 ~22 ~77 red_nether_brick 0  
fill ~30 ~22 ~18 ~30 ~24 ~18 red_nether_brick 0  
fill ~30 ~22 ~23 ~40 ~22 ~23 red_nether_brick 0  
fill ~30 ~22 ~27 ~31 ~22 ~27 red_nether_brick 0 
setblock ~30 ~22 ~30 nether_brick_stairs 5 
setblock ~30 ~22 ~31 nether_brick_stairs 7 
setblock ~30 ~22 ~71 nether_brick_stairs 5 
setblock ~30 ~22 ~72 nether_brick_stairs 6  
fill ~30 ~22 ~75 ~31 ~22 ~75 red_nether_brick 0  
fill ~30 ~22 ~79 ~40 ~22 ~79 red_nether_brick 0  
fill ~31 ~22 ~17 ~34 ~22 ~17 red_nether_brick 0  
fill ~31 ~22 ~22 ~33 ~22 ~22 red_nether_brick 0  
fill ~31 ~22 ~26 ~33 ~22 ~26 red_nether_brick 0 
setblock ~31 ~22 ~29 nether_brick_stairs 5 
setblock ~31 ~22 ~30 nether_brick_stairs 7 
setblock ~31 ~22 ~72 nether_brick_stairs 5 
setblock ~31 ~22 ~73 nether_brick_stairs 6 
setblock ~31 ~22 ~74 nether_brick_stairs 2  
fill ~31 ~22 ~76 ~33 ~22 ~76 red_nether_brick 0  
fill ~31 ~22 ~80 ~33 ~22 ~80 red_nether_brick 0 
setblock ~32 ~22 ~18 red_nether_brick 0  
fill ~32 ~22 ~24 ~37 ~22 ~24 red_nether_brick 0 
setblock ~32 ~22 ~27 nether_brick_stairs 1 
setblock ~32 ~22 ~28 nether_brick_stairs 5 
setblock ~32 ~22 ~29 nether_brick_stairs 7 
setblock ~32 ~22 ~73 nether_brick_stairs 5 
setblock ~32 ~22 ~74 nether_brick_stairs 6 
setblock ~32 ~22 ~75 nether_brick_stairs 2  
fill ~32 ~22 ~78 ~37 ~22 ~78 red_nether_brick 0  
fill ~33 ~22 ~16 ~40 ~22 ~16 red_nether_brick 0  
fill ~33 ~22 ~21 ~35 ~22 ~21 red_nether_brick 0 
setblock ~33 ~22 ~27 nether_brick_stairs 5 
setblock ~33 ~22 ~28 nether_brick_stairs 7 
setblock ~33 ~22 ~74 nether_brick_stairs 5 
setblock ~33 ~22 ~75 nether_brick_stairs 6  
fill ~34 ~22 ~18 ~35 ~22 ~18 red_nether_brick 0  
fill ~34 ~22 ~20 ~68 ~22 ~20 red_nether_brick 0 
setblock ~34 ~22 ~25 red_nether_brick 0 
setblock ~34 ~22 ~26 nether_brick_stairs 5 
setblock ~34 ~22 ~27 nether_brick_stairs 7 
setblock ~34 ~22 ~75 nether_brick_stairs 5  
fill ~34 ~22 ~76 ~35 ~22 ~76 nether_brick_stairs 6 
setblock ~34 ~22 ~77 red_nether_brick 0  
fill ~34 ~22 ~81 ~35 ~22 ~81 red_nether_brick 0  
fill ~34 ~22 ~82 ~68 ~22 ~82 red_nether_brick 0  
fill ~34 ~22 ~84 ~35 ~22 ~84 red_nether_brick 0  
fill ~34 ~22 ~85 ~34 ~22 ~86 red_nether_brick 0  
fill ~35 ~22 ~15 ~44 ~22 ~15 red_nether_brick 0  
fill ~35 ~22 ~22 ~42 ~22 ~22 red_nether_brick 0 
setblock ~35 ~22 ~25 nether_brick_stairs 3  
fill ~35 ~22 ~26 ~36 ~22 ~26 nether_brick_stairs 7 
setblock ~35 ~22 ~77 nether_brick_stairs 1  
fill ~35 ~22 ~80 ~43 ~22 ~80 red_nether_brick 0  
fill ~35 ~22 ~86 ~40 ~22 ~86 red_nether_brick 0  
fill ~35 ~22 ~87 ~44 ~22 ~87 red_nether_brick 0  
fill ~36 ~22 ~17 ~37 ~22 ~17 red_nether_brick 0  
fill ~36 ~22 ~19 ~37 ~22 ~19 red_nether_brick 0 
setblock ~36 ~22 ~25 nether_brick_stairs 5  
fill ~36 ~22 ~76 ~36 ~22 ~77 nether_brick_stairs 5  
fill ~36 ~22 ~83 ~37 ~22 ~83 red_nether_brick 0  
fill ~36 ~22 ~85 ~37 ~22 ~85 red_nether_brick 0 
setblock ~37 ~22 ~14 stone_slab 15  
fill ~37 ~22 ~21 ~51 ~22 ~21 red_nether_brick 0  
fill ~37 ~22 ~25 ~38 ~22 ~25 nether_brick_stairs 7  
fill ~37 ~22 ~77 ~38 ~22 ~77 nether_brick_stairs 6  
fill ~37 ~22 ~81 ~65 ~22 ~81 red_nether_brick 0 
setblock ~37 ~22 ~88 stone_slab 15  
fill ~38 ~22 ~14 ~64 ~22 ~14 red_nether_brick 0  
fill ~38 ~22 ~18 ~64 ~22 ~18 red_nether_brick 0 
setblock ~38 ~22 ~24 nether_brick_stairs 5 
setblock ~38 ~22 ~78 nether_brick_stairs 5  
fill ~38 ~22 ~84 ~64 ~22 ~84 red_nether_brick 0  
fill ~38 ~22 ~88 ~64 ~22 ~88 red_nether_brick 0  
fill ~39 ~22 ~19 ~40 ~22 ~19 red_nether_brick 0  
fill ~39 ~22 ~24 ~41 ~22 ~24 nether_brick_stairs 7  
fill ~39 ~22 ~78 ~40 ~22 ~78 nether_brick_stairs 6  
fill ~39 ~22 ~83 ~40 ~22 ~83 red_nether_brick 0 
setblock ~40 ~22 ~13 stone_slab 15 
setblock ~40 ~22 ~89 stone_slab 15  
fill ~41 ~22 ~13 ~61 ~22 ~13 red_nether_brick 0  
fill ~41 ~22 ~17 ~61 ~22 ~17 red_nether_brick 0 
setblock ~41 ~22 ~23 nether_brick_stairs 5 
setblock ~41 ~22 ~78 nether_brick_stairs 5  
fill ~41 ~22 ~79 ~44 ~22 ~79 nether_brick_stairs 6  
fill ~41 ~22 ~85 ~61 ~22 ~85 red_nether_brick 0  
fill ~41 ~22 ~89 ~61 ~22 ~89 red_nether_brick 0  
fill ~42 ~22 ~19 ~60 ~22 ~19 red_nether_brick 0  
fill ~42 ~22 ~23 ~43 ~22 ~23 nether_brick_stairs 7  
fill ~42 ~22 ~83 ~60 ~22 ~83 red_nether_brick 0 
setblock ~43 ~22 ~22 nether_brick_stairs 5 
setblock ~44 ~22 ~12 stone_slab 15  
fill ~44 ~22 ~22 ~48 ~22 ~22 nether_brick_stairs 7 
setblock ~44 ~22 ~80 nether_brick_stairs 5 
setblock ~44 ~22 ~90 stone_slab 15  
fill ~45 ~22 ~12 ~57 ~22 ~12 red_nether_brick 0  
fill ~45 ~22 ~80 ~50 ~22 ~80 nether_brick_stairs 6  
fill ~45 ~22 ~90 ~57 ~22 ~90 red_nether_brick 0  
fill ~46 ~22 ~16 ~56 ~22 ~16 red_nether_brick 0  
fill ~46 ~22 ~86 ~56 ~22 ~86 red_nether_brick 0  
fill ~48 ~22 ~15 ~52 ~22 ~15 red_nether_brick 0  
fill ~49 ~22 ~8 ~49 ~35 ~8 red_nether_brick 0 
setblock ~49 ~22 ~9 nether_brick_stairs 7 
setblock ~49 ~22 ~10 nether_brick_stairs 6 
fill ~49 ~22 ~11 ~51 ~22 ~11 red_nether_brick 0 
setblock ~49 ~22 ~24 nether_brick_stairs 7  
fill ~50 ~22 ~9 ~50 ~34 ~9 red_nether_brick 0  
fill ~50 ~22 ~10 ~50 ~33 ~10 red_nether_brick 0  
fill ~50 ~22 ~87 ~54 ~22 ~87 red_nether_brick 0  
fill ~51 ~22 ~8 ~51 ~35 ~8 red_nether_brick 0 
setblock ~51 ~22 ~9 nether_brick_stairs 7 
setblock ~51 ~22 ~10 nether_brick_stairs 6 
setblock ~51 ~22 ~24 nether_brick_stairs 7 
setblock ~51 ~22 ~78 nether_brick_stairs 6  
fill ~51 ~22 ~91 ~53 ~22 ~91 red_nether_brick 0 
setblock ~51 ~22 ~92 nether_brick_stairs 7 
setblock ~51 ~22 ~93 nether_brick_stairs 6  
fill ~51 ~22 ~94 ~51 ~35 ~94 red_nether_brick 0  
fill ~52 ~22 ~22 ~57 ~22 ~22 nether_brick_stairs 7  
fill ~52 ~22 ~92 ~52 ~33 ~92 red_nether_brick 0  
fill ~52 ~22 ~93 ~52 ~34 ~93 red_nether_brick 0  
fill ~53 ~22 ~21 ~65 ~22 ~21 red_nether_brick 0 
setblock ~53 ~22 ~78 nether_brick_stairs 6 
setblock ~53 ~22 ~92 nether_brick_stairs 7 
setblock ~53 ~22 ~93 nether_brick_stairs 6  
fill ~53 ~22 ~94 ~53 ~35 ~94 red_nether_brick 0  
fill ~54 ~22 ~80 ~58 ~22 ~80 nether_brick_stairs 6 
setblock ~58 ~22 ~12 stone_slab 15  
fill ~58 ~22 ~15 ~67 ~22 ~15 red_nether_brick 0 
setblock ~58 ~22 ~22 nether_brick_stairs 4  
fill ~58 ~22 ~23 ~61 ~22 ~23 nether_brick_stairs 7  
fill ~58 ~22 ~87 ~67 ~22 ~87 red_nether_brick 0 
setblock ~58 ~22 ~90 stone_slab 15  
fill ~59 ~22 ~22 ~67 ~22 ~22 red_nether_brick 0  
fill ~59 ~22 ~79 ~60 ~22 ~79 nether_brick_stairs 6 
setblock ~59 ~22 ~80 nether_brick_stairs 4  
fill ~60 ~22 ~80 ~67 ~22 ~80 red_nether_brick 0 
setblock ~61 ~22 ~24 nether_brick_stairs 4  
fill ~61 ~22 ~78 ~63 ~22 ~78 nether_brick_stairs 6 
setblock ~61 ~22 ~79 nether_brick_stairs 4 
setblock ~62 ~22 ~13 stone_slab 15  
fill ~62 ~22 ~16 ~69 ~22 ~16 red_nether_brick 0  
fill ~62 ~22 ~19 ~63 ~22 ~19 red_nether_brick 0  
fill ~62 ~22 ~23 ~72 ~22 ~23 red_nether_brick 0  
fill ~62 ~22 ~24 ~63 ~22 ~24 nether_brick_stairs 7  
fill ~62 ~22 ~79 ~72 ~22 ~79 red_nether_brick 0  
fill ~62 ~22 ~83 ~63 ~22 ~83 red_nether_brick 0  
fill ~62 ~22 ~86 ~69 ~22 ~86 red_nether_brick 0 
setblock ~62 ~22 ~89 stone_slab 15 
setblock ~64 ~22 ~24 nether_brick_stairs 4  
fill ~64 ~22 ~25 ~65 ~22 ~25 nether_brick_stairs 7  
fill ~64 ~22 ~77 ~65 ~22 ~77 nether_brick_stairs 6 
setblock ~64 ~22 ~78 nether_brick_stairs 4 
setblock ~65 ~22 ~14 stone_slab 15  
fill ~65 ~22 ~17 ~66 ~22 ~17 red_nether_brick 0  
fill ~65 ~22 ~19 ~66 ~22 ~19 red_nether_brick 0  
fill ~65 ~22 ~24 ~70 ~22 ~24 red_nether_brick 0  
fill ~65 ~22 ~78 ~70 ~22 ~78 red_nether_brick 0  
fill ~65 ~22 ~83 ~66 ~22 ~83 red_nether_brick 0  
fill ~65 ~22 ~85 ~66 ~22 ~85 red_nether_brick 0 
setblock ~65 ~22 ~88 stone_slab 15  
fill ~66 ~22 ~25 ~66 ~22 ~26 nether_brick_stairs 4  
fill ~66 ~22 ~76 ~67 ~22 ~76 nether_brick_stairs 6 
setblock ~66 ~22 ~77 nether_brick_stairs 4  
fill ~67 ~22 ~18 ~68 ~22 ~18 red_nether_brick 0  
fill ~67 ~22 ~21 ~69 ~22 ~21 red_nether_brick 0 
setblock ~67 ~22 ~25 nether_brick_stairs 0  
fill ~67 ~22 ~26 ~68 ~22 ~26 nether_brick_stairs 7 
setblock ~67 ~22 ~77 nether_brick_stairs 2  
fill ~67 ~22 ~81 ~69 ~22 ~81 red_nether_brick 0  
fill ~67 ~22 ~84 ~68 ~22 ~84 red_nether_brick 0  
fill ~68 ~22 ~17 ~71 ~22 ~17 red_nether_brick 0 
setblock ~68 ~22 ~25 red_nether_brick 0 
setblock ~68 ~22 ~27 nether_brick_stairs 4 
setblock ~68 ~22 ~75 nether_brick_stairs 6 
setblock ~68 ~22 ~76 nether_brick_stairs 4 
setblock ~68 ~22 ~77 red_nether_brick 0  
fill ~68 ~22 ~85 ~71 ~22 ~85 red_nether_brick 0  
fill ~69 ~22 ~19 ~74 ~22 ~19 red_nether_brick 0  
fill ~69 ~22 ~22 ~71 ~22 ~22 red_nether_brick 0  
fill ~69 ~22 ~26 ~71 ~22 ~26 red_nether_brick 0 
setblock ~69 ~22 ~27 nether_brick_stairs 7 
setblock ~69 ~22 ~28 nether_brick_stairs 4 
setblock ~69 ~22 ~74 nether_brick_stairs 6 
setblock ~69 ~22 ~75 nether_brick_stairs 4  
fill ~69 ~22 ~76 ~71 ~22 ~76 red_nether_brick 0  
fill ~69 ~22 ~80 ~71 ~22 ~80 red_nether_brick 0  
fill ~69 ~22 ~83 ~74 ~22 ~83 red_nether_brick 0 
setblock ~70 ~22 ~18 red_nether_brick 0  
fill ~70 ~22 ~25 ~73 ~22 ~25 red_nether_brick 0 
setblock ~70 ~22 ~27 nether_brick_stairs 3 
setblock ~70 ~22 ~28 nether_brick_stairs 7 
setblock ~70 ~22 ~29 nether_brick_stairs 4 
setblock ~70 ~22 ~73 nether_brick_stairs 6 
setblock ~70 ~22 ~74 nether_brick_stairs 4 
setblock ~70 ~22 ~75 nether_brick_stairs 0  
fill ~70 ~22 ~77 ~73 ~22 ~77 red_nether_brick 0 
setblock ~70 ~22 ~84 red_nether_brick 0  
fill ~71 ~22 ~20 ~73 ~22 ~20 red_nether_brick 0  
fill ~71 ~22 ~27 ~72 ~22 ~27 red_nether_brick 0 
setblock ~71 ~22 ~28 nether_brick_stairs 3 
setblock ~71 ~22 ~29 nether_brick_stairs 7 
setblock ~71 ~22 ~30 nether_brick_stairs 4 
setblock ~71 ~22 ~72 nether_brick_stairs 6 
setblock ~71 ~22 ~73 nether_brick_stairs 4  
fill ~71 ~22 ~74 ~73 ~22 ~74 red_nether_brick 0  
fill ~71 ~22 ~75 ~72 ~22 ~75 red_nether_brick 0  
fill ~71 ~22 ~82 ~73 ~22 ~82 red_nether_brick 0  
fill ~72 ~22 ~18 ~72 ~24 ~18 red_nether_brick 0  
fill ~72 ~22 ~24 ~74 ~22 ~24 red_nether_brick 0  
fill ~72 ~22 ~28 ~73 ~22 ~28 red_nether_brick 0  
fill ~72 ~22 ~29 ~74 ~22 ~29 red_nether_brick 0 
setblock ~72 ~22 ~30 nether_brick_stairs 7 
setblock ~72 ~22 ~31 nether_brick_stairs 4 
setblock ~72 ~22 ~71 nether_brick_stairs 6 
setblock ~72 ~22 ~72 nether_brick_stairs 4  
fill ~72 ~22 ~73 ~74 ~22 ~73 red_nether_brick 0  
fill ~72 ~22 ~78 ~74 ~22 ~78 red_nether_brick 0  
fill ~72 ~22 ~84 ~72 ~24 ~84 red_nether_brick 0 
setblock ~73 ~22 ~18 stone_slab 15  
fill ~73 ~22 ~21 ~76 ~22 ~21 red_nether_brick 0  
fill ~73 ~22 ~26 ~74 ~22 ~26 red_nether_brick 0  
fill ~73 ~22 ~30 ~75 ~22 ~30 red_nether_brick 0 
setblock ~73 ~22 ~31 nether_brick_stairs 7 
setblock ~73 ~22 ~32 nether_brick_stairs 4 
setblock ~73 ~22 ~70 nether_brick_stairs 6 
setblock ~73 ~22 ~71 nether_brick_stairs 4  
fill ~73 ~22 ~72 ~75 ~22 ~72 red_nether_brick 0  
fill ~73 ~22 ~76 ~74 ~22 ~76 red_nether_brick 0  
fill ~73 ~22 ~81 ~76 ~22 ~81 red_nether_brick 0 
setblock ~73 ~22 ~84 stone_slab 15 
setblock ~74 ~22 ~22 red_nether_brick 0  
fill ~74 ~22 ~27 ~75 ~22 ~27 red_nether_brick 0  
fill ~74 ~22 ~31 ~77 ~22 ~31 red_nether_brick 0 
setblock ~74 ~22 ~32 nether_brick_stairs 7 
setblock ~74 ~22 ~33 nether_brick_stairs 4 
setblock ~74 ~22 ~69 nether_brick_stairs 6 
setblock ~74 ~22 ~70 nether_brick_stairs 4 
setblock ~74 ~22 ~71 nether_brick_stairs 0  
fill ~74 ~22 ~75 ~75 ~22 ~75 red_nether_brick 0 
setblock ~74 ~22 ~80 red_nether_brick 0  
fill ~75 ~22 ~20 ~75 ~24 ~20 red_nether_brick 0 
setblock ~75 ~22 ~23 red_nether_brick 0 
setblock ~75 ~22 ~25 red_nether_brick 0  
fill ~75 ~22 ~28 ~76 ~22 ~28 red_nether_brick 0 
setblock ~75 ~22 ~32 nether_brick_stairs 3 
setblock ~75 ~22 ~33 nether_brick_stairs 7 
setblock ~75 ~22 ~34 nether_brick_stairs 4 
setblock ~75 ~22 ~68 nether_brick_stairs 6 
setblock ~75 ~22 ~69 nether_brick_stairs 4 
setblock ~75 ~22 ~70 nether_brick_stairs 0  
fill ~75 ~22 ~71 ~77 ~22 ~71 red_nether_brick 0  
fill ~75 ~22 ~74 ~76 ~22 ~74 red_nether_brick 0 
setblock ~75 ~22 ~77 red_nether_brick 0 
setblock ~75 ~22 ~79 red_nether_brick 0  
fill ~75 ~22 ~82 ~75 ~24 ~82 red_nether_brick 0  
fill ~76 ~22 ~22 ~77 ~22 ~22 red_nether_brick 0  
fill ~76 ~22 ~24 ~79 ~22 ~24 red_nether_brick 0 
setblock ~76 ~22 ~26 red_nether_brick 0  
fill ~76 ~22 ~29 ~78 ~22 ~29 red_nether_brick 0  
fill ~76 ~22 ~32 ~80 ~22 ~32 red_nether_brick 0  
fill ~76 ~22 ~33 ~76 ~22 ~31 red_nether_brick 0 
setblock ~76 ~22 ~34 nether_brick_stairs 7  
fill ~76 ~22 ~35 ~76 ~22 ~36 nether_brick_stairs 4  
fill ~76 ~22 ~66 ~77 ~22 ~66 nether_brick_stairs 6  
fill ~76 ~22 ~67 ~76 ~22 ~68 nether_brick_stairs 4  
fill ~76 ~22 ~69 ~76 ~22 ~71 red_nether_brick 0  
fill ~76 ~22 ~73 ~78 ~22 ~73 red_nether_brick 0 
setblock ~76 ~22 ~76 red_nether_brick 0  
fill ~76 ~22 ~78 ~79 ~22 ~78 red_nether_brick 0  
fill ~76 ~22 ~80 ~77 ~22 ~80 red_nether_brick 0 
setblock ~77 ~22 ~21 stone_slab 15  
fill ~77 ~22 ~23 ~78 ~22 ~23 red_nether_brick 0 
setblock ~77 ~22 ~27 red_nether_brick 0  
fill ~77 ~22 ~30 ~79 ~22 ~30 red_nether_brick 0  
fill ~77 ~22 ~34 ~79 ~22 ~34 red_nether_brick 0 
setblock ~77 ~22 ~35 nether_brick_stairs 0 
setblock ~77 ~22 ~36 nether_brick_stairs 7  
fill ~77 ~22 ~37 ~77 ~22 ~38 nether_brick_stairs 4  
fill ~77 ~22 ~64 ~77 ~22 ~65 nether_brick_stairs 4 
setblock ~77 ~22 ~67 nether_brick_stairs 2  
fill ~77 ~22 ~68 ~79 ~22 ~68 red_nether_brick 0  
fill ~77 ~22 ~70 ~80 ~22 ~70 red_nether_brick 0  
fill ~77 ~22 ~72 ~79 ~22 ~72 red_nether_brick 0 
setblock ~77 ~22 ~75 red_nether_brick 0  
fill ~77 ~22 ~79 ~78 ~22 ~79 red_nether_brick 0 
setblock ~77 ~22 ~81 stone_slab 15 
setblock ~78 ~22 ~22 stone_slab 15  
fill ~78 ~22 ~25 ~80 ~22 ~25 red_nether_brick 0  
fill ~78 ~22 ~26 ~78 ~22 ~23 red_nether_brick 0 
setblock ~78 ~22 ~28 red_nether_brick 0  
fill ~78 ~22 ~33 ~81 ~22 ~33 red_nether_brick 0  
fill ~78 ~22 ~35 ~82 ~22 ~35 red_nether_brick 0  
fill ~78 ~22 ~36 ~80 ~22 ~36 red_nether_brick 0  
fill ~78 ~22 ~37 ~83 ~22 ~37 red_nether_brick 0 
setblock ~78 ~22 ~38 nether_brick_stairs 7  
fill ~78 ~22 ~39 ~78 ~22 ~41 nether_brick_stairs 4 
setblock ~78 ~22 ~49 nether_brick_stairs 4  
fill ~78 ~22 ~50 ~99 ~22 ~50 red_nether_brick 0 
setblock ~78 ~22 ~51 nether_brick_stairs 4 
setblock ~78 ~22 ~61 nether_brick_stairs 6  
fill ~78 ~22 ~62 ~78 ~22 ~63 nether_brick_stairs 4 
setblock ~78 ~22 ~64 nether_brick_stairs 6  
fill ~78 ~22 ~65 ~83 ~22 ~65 red_nether_brick 0  
fill ~78 ~22 ~66 ~80 ~22 ~66 red_nether_brick 0  
fill ~78 ~22 ~67 ~82 ~22 ~67 red_nether_brick 0  
fill ~78 ~22 ~69 ~81 ~22 ~69 red_nether_brick 0 
setblock ~78 ~22 ~74 red_nether_brick 0  
fill ~78 ~22 ~76 ~78 ~22 ~79 red_nether_brick 0 
setblock ~78 ~22 ~80 stone_slab 15 
setblock ~79 ~22 ~23 stone_slab 15 
setblock ~79 ~22 ~27 red_nether_brick 0  
fill ~79 ~22 ~31 ~80 ~22 ~31 red_nether_brick 0  
fill ~79 ~22 ~38 ~82 ~22 ~38 red_nether_brick 0  
fill ~79 ~22 ~39 ~84 ~22 ~39 red_nether_brick 0  
fill ~79 ~22 ~40 ~84 ~22 ~40 red_nether_brick 0 
setblock ~79 ~22 ~41 nether_brick_stairs 7  
fill ~79 ~22 ~42 ~79 ~22 ~43 nether_brick_stairs 4  
fill ~79 ~22 ~58 ~79 ~22 ~61 nether_brick_stairs 4  
fill ~79 ~22 ~62 ~84 ~22 ~62 red_nether_brick 0  
fill ~79 ~22 ~63 ~84 ~22 ~63 red_nether_brick 0  
fill ~79 ~22 ~64 ~82 ~22 ~64 red_nether_brick 0  
fill ~79 ~22 ~71 ~80 ~22 ~71 red_nether_brick 0 
setblock ~79 ~22 ~75 red_nether_brick 0  
fill ~79 ~22 ~77 ~80 ~22 ~77 red_nether_brick 0 
setblock ~79 ~22 ~79 stone_slab 15 
setblock ~80 ~22 ~24 stone_slab 15  
fill ~80 ~22 ~26 ~81 ~22 ~26 red_nether_brick 0  
fill ~80 ~22 ~28 ~81 ~22 ~28 red_nether_brick 0  
fill ~80 ~22 ~41 ~82 ~22 ~41 red_nether_brick 0  
fill ~80 ~22 ~42 ~85 ~22 ~42 red_nether_brick 0 
setblock ~80 ~22 ~43 nether_brick_stairs 7  
fill ~80 ~22 ~44 ~80 ~22 ~48 nether_brick_stairs 4  
fill ~80 ~22 ~53 ~80 ~22 ~57 nether_brick_stairs 4 
setblock ~80 ~22 ~58 nether_brick_stairs 6  
fill ~80 ~22 ~59 ~85 ~22 ~59 red_nether_brick 0  
fill ~80 ~22 ~60 ~85 ~22 ~60 red_nether_brick 0  
fill ~80 ~22 ~61 ~82 ~22 ~61 red_nether_brick 0  
fill ~80 ~22 ~74 ~81 ~22 ~74 red_nether_brick 0  
fill ~80 ~22 ~76 ~81 ~22 ~76 red_nether_brick 0 
setblock ~80 ~22 ~78 stone_slab 15 
setblock ~81 ~22 ~25 stone_slab 15  
fill ~81 ~22 ~27 ~82 ~22 ~27 red_nether_brick 0  
fill ~81 ~22 ~29 ~83 ~22 ~29 red_nether_brick 0  
fill ~81 ~22 ~34 ~82 ~22 ~34 red_nether_brick 0  
fill ~81 ~22 ~43 ~85 ~22 ~43 red_nether_brick 0  
fill ~81 ~22 ~44 ~85 ~22 ~44 red_nether_brick 0  
fill ~81 ~22 ~45 ~85 ~22 ~45 red_nether_brick 0  
fill ~81 ~22 ~46 ~86 ~22 ~46 red_nether_brick 0  
fill ~81 ~22 ~47 ~86 ~22 ~47 red_nether_brick 0  
fill ~81 ~22 ~53 ~86 ~22 ~53 red_nether_brick 0  
fill ~81 ~22 ~54 ~86 ~22 ~54 red_nether_brick 0  
fill ~81 ~22 ~55 ~86 ~22 ~55 red_nether_brick 0  
fill ~81 ~22 ~56 ~86 ~22 ~56 red_nether_brick 0  
fill ~81 ~22 ~57 ~85 ~22 ~57 red_nether_brick 0  
fill ~81 ~22 ~58 ~85 ~22 ~58 red_nether_brick 0  
fill ~81 ~22 ~68 ~82 ~22 ~68 red_nether_brick 0  
fill ~81 ~22 ~73 ~83 ~22 ~73 red_nether_brick 0  
fill ~81 ~22 ~75 ~82 ~22 ~75 red_nether_brick 0 
setblock ~81 ~22 ~77 stone_slab 15  
fill ~82 ~22 ~30 ~84 ~22 ~30 red_nether_brick 0  
fill ~82 ~22 ~31 ~83 ~22 ~31 red_nether_brick 0  
fill ~82 ~22 ~36 ~83 ~22 ~36 red_nether_brick 0  
fill ~82 ~22 ~66 ~83 ~22 ~66 red_nether_brick 0  
fill ~82 ~22 ~71 ~83 ~22 ~71 red_nether_brick 0  
fill ~82 ~22 ~72 ~84 ~22 ~72 red_nether_brick 0  
fill ~83 ~22 ~28 ~83 ~26 ~28 red_nether_brick 0  
fill ~83 ~22 ~32 ~85 ~22 ~32 red_nether_brick 0  
fill ~83 ~22 ~33 ~83 ~22 ~28 red_nether_brick 0  
fill ~83 ~22 ~48 ~90 ~22 ~48 red_nether_brick 0  
fill ~83 ~22 ~49 ~91 ~22 ~49 red_nether_brick 0  
fill ~83 ~22 ~51 ~91 ~22 ~51 red_nether_brick 0  
fill ~83 ~22 ~52 ~90 ~22 ~52 red_nether_brick 0  
fill ~83 ~22 ~69 ~83 ~22 ~74 red_nether_brick 0 
setblock ~84 ~22 ~29 stone_slab 15  
fill ~84 ~22 ~34 ~86 ~22 ~34 red_nether_brick 0  
fill ~84 ~22 ~35 ~84 ~22 ~34 red_nether_brick 0 
setblock ~84 ~22 ~38 red_nether_brick 0  
fill ~84 ~22 ~41 ~85 ~22 ~41 red_nether_brick 0  
fill ~84 ~22 ~61 ~85 ~22 ~61 red_nether_brick 0 
setblock ~84 ~22 ~64 red_nether_brick 0  
fill ~84 ~22 ~67 ~84 ~22 ~68 red_nether_brick 0  
fill ~84 ~22 ~70 ~85 ~22 ~70 red_nether_brick 0 
setblock ~84 ~22 ~73 stone_slab 15  
fill ~85 ~22 ~31 ~85 ~27 ~31 red_nether_brick 0  
fill ~85 ~22 ~33 ~86 ~22 ~33 red_nether_brick 0  
fill ~85 ~22 ~36 ~87 ~22 ~36 red_nether_brick 0  
fill ~85 ~22 ~37 ~87 ~22 ~37 red_nether_brick 0  
fill ~85 ~22 ~65 ~87 ~22 ~65 red_nether_brick 0  
fill ~85 ~22 ~66 ~87 ~22 ~66 red_nether_brick 0  
fill ~85 ~22 ~68 ~86 ~22 ~68 red_nether_brick 0  
fill ~85 ~22 ~69 ~86 ~22 ~69 red_nether_brick 0  
fill ~85 ~22 ~71 ~85 ~27 ~71 red_nether_brick 0  
fill ~86 ~22 ~35 ~87 ~22 ~35 red_nether_brick 0  
fill ~86 ~22 ~38 ~88 ~22 ~38 red_nether_brick 0  
fill ~86 ~22 ~39 ~88 ~22 ~39 red_nether_brick 0  
fill ~86 ~22 ~40 ~88 ~22 ~40 red_nether_brick 0  
fill ~86 ~22 ~62 ~88 ~22 ~62 red_nether_brick 0  
fill ~86 ~22 ~63 ~88 ~22 ~63 red_nether_brick 0  
fill ~86 ~22 ~64 ~88 ~22 ~64 red_nether_brick 0  
fill ~86 ~22 ~67 ~87 ~22 ~67 red_nether_brick 0  
fill ~87 ~22 ~41 ~89 ~22 ~41 red_nether_brick 0  
fill ~87 ~22 ~42 ~89 ~22 ~42 red_nether_brick 0  
fill ~87 ~22 ~43 ~89 ~22 ~43 red_nether_brick 0  
fill ~87 ~22 ~44 ~89 ~22 ~44 red_nether_brick 0  
fill ~87 ~22 ~58 ~89 ~22 ~58 red_nether_brick 0  
fill ~87 ~22 ~59 ~89 ~22 ~59 red_nether_brick 0  
fill ~87 ~22 ~60 ~89 ~22 ~60 red_nether_brick 0  
fill ~87 ~22 ~61 ~89 ~22 ~61 red_nether_brick 0 
setblock ~88 ~22 ~37 stone_slab 15  
fill ~88 ~22 ~45 ~90 ~22 ~45 red_nether_brick 0  
fill ~88 ~22 ~46 ~90 ~22 ~46 red_nether_brick 0  
fill ~88 ~22 ~47 ~90 ~22 ~47 red_nether_brick 0  
fill ~88 ~22 ~53 ~90 ~22 ~53 red_nether_brick 0  
fill ~88 ~22 ~54 ~90 ~22 ~54 red_nether_brick 0  
fill ~88 ~22 ~55 ~90 ~22 ~55 red_nether_brick 0  
fill ~88 ~22 ~56 ~90 ~22 ~56 red_nether_brick 0  
fill ~88 ~22 ~57 ~90 ~22 ~57 red_nether_brick 0 
setblock ~88 ~22 ~65 stone_slab 15 
setblock ~89 ~22 ~40 stone_slab 15 
setblock ~89 ~22 ~62 stone_slab 15 
setblock ~90 ~22 ~44 stone_slab 15 
setblock ~90 ~22 ~58 stone_slab 15 
setblock ~92 ~22 ~49 nether_brick_stairs 5 
setblock ~92 ~22 ~51 nether_brick_stairs 5 
setblock ~93 ~22 ~49 nether_brick_stairs 4 
setblock ~93 ~22 ~51 nether_brick_stairs 4  
fill ~94 ~22 ~49 ~94 ~35 ~49 red_nether_brick 0  
fill ~94 ~22 ~51 ~94 ~35 ~51 red_nether_brick 0 
setblock ~3 ~23 ~51 nether_brick_stairs 4 
setblock ~3 ~23 ~53 nether_brick_stairs 4  
fill ~9 ~23 ~51 ~24 ~23 ~51 red_nether_brick 0  
fill ~9 ~23 ~52 ~24 ~23 ~52 red_nether_brick 0  
fill ~9 ~23 ~53 ~24 ~23 ~53 red_nether_brick 0  
fill ~11 ~23 ~50 ~22 ~23 ~50 red_nether_brick 0  
fill ~11 ~23 ~54 ~22 ~23 ~54 red_nether_brick 0 
setblock ~12 ~23 ~43 stone_slab 15  
fill ~12 ~23 ~44 ~12 ~32 ~44 red_nether_brick 0  
fill ~12 ~23 ~45 ~12 ~28 ~45 red_nether_brick 0  
fill ~12 ~23 ~46 ~12 ~27 ~46 red_nether_brick 0  
fill ~12 ~23 ~47 ~12 ~26 ~47 red_nether_brick 0  
fill ~12 ~23 ~48 ~12 ~25 ~48 red_nether_brick 0  
fill ~12 ~23 ~49 ~12 ~24 ~49 red_nether_brick 0  
fill ~12 ~23 ~55 ~12 ~26 ~55 red_nether_brick 0  
fill ~12 ~23 ~56 ~12 ~27 ~56 red_nether_brick 0  
fill ~12 ~23 ~57 ~12 ~28 ~57 red_nether_brick 0  
fill ~12 ~23 ~58 ~12 ~32 ~58 red_nether_brick 0 
setblock ~12 ~23 ~59 stone_slab 15 
setblock ~13 ~23 ~39 stone_slab 15  
fill ~13 ~23 ~40 ~13 ~32 ~40 red_nether_brick 0  
fill ~13 ~23 ~41 ~13 ~26 ~41 red_nether_brick 0  
fill ~13 ~23 ~42 ~13 ~24 ~42 red_nether_brick 0  
fill ~13 ~23 ~43 ~13 ~22 ~43 red_nether_brick 0  
fill ~13 ~23 ~59 ~13 ~22 ~59 red_nether_brick 0  
fill ~13 ~23 ~60 ~13 ~24 ~60 red_nether_brick 0  
fill ~13 ~23 ~61 ~13 ~26 ~61 red_nether_brick 0  
fill ~13 ~23 ~62 ~13 ~32 ~62 red_nether_brick 0 
setblock ~13 ~23 ~63 stone_slab 15  
fill ~14 ~23 ~37 ~14 ~32 ~37 red_nether_brick 0  
fill ~14 ~23 ~38 ~14 ~25 ~38 red_nether_brick 0  
fill ~14 ~23 ~39 ~14 ~22 ~39 red_nether_brick 0  
fill ~14 ~23 ~63 ~14 ~23 ~65 red_nether_brick 0 
setblock ~15 ~23 ~34 stone_slab 15  
fill ~15 ~23 ~35 ~15 ~27 ~35 red_nether_brick 0  
fill ~15 ~23 ~36 ~15 ~24 ~36 red_nether_brick 0  
fill ~15 ~23 ~66 ~15 ~24 ~66 red_nether_brick 0  
fill ~15 ~23 ~67 ~15 ~27 ~67 red_nether_brick 0 
setblock ~15 ~23 ~68 stone_slab 15 
setblock ~16 ~23 ~32 stone_slab 15  
fill ~16 ~23 ~33 ~16 ~26 ~33 red_nether_brick 0  
fill ~16 ~23 ~34 ~16 ~23 ~33 red_nether_brick 0  
fill ~16 ~23 ~68 ~16 ~23 ~69 red_nether_brick 0 
setblock ~16 ~23 ~70 stone_slab 15  
fill ~17 ~23 ~31 ~17 ~27 ~31 red_nether_brick 0  
fill ~17 ~23 ~32 ~17 ~23 ~31 red_nether_brick 0  
fill ~17 ~23 ~70 ~17 ~23 ~71 red_nether_brick 0  
fill ~18 ~23 ~29 ~18 ~30 ~29 red_nether_brick 0  
fill ~18 ~23 ~30 ~18 ~24 ~30 red_nether_brick 0  
fill ~18 ~23 ~72 ~18 ~24 ~72 red_nether_brick 0  
fill ~18 ~23 ~73 ~18 ~30 ~73 red_nether_brick 0  
fill ~19 ~23 ~28 ~19 ~26 ~28 red_nether_brick 0  
fill ~19 ~23 ~74 ~19 ~26 ~74 red_nether_brick 0 
setblock ~20 ~23 ~26 stone_slab 15  
fill ~20 ~23 ~27 ~20 ~24 ~27 red_nether_brick 0  
fill ~20 ~23 ~75 ~20 ~24 ~75 red_nether_brick 0 
setblock ~20 ~23 ~76 stone_slab 15  
fill ~21 ~23 ~25 ~21 ~29 ~25 red_nether_brick 0  
fill ~21 ~23 ~26 ~21 ~23 ~25 red_nether_brick 0  
fill ~21 ~23 ~76 ~21 ~23 ~77 red_nether_brick 0  
fill ~22 ~23 ~24 ~22 ~27 ~24 red_nether_brick 0  
fill ~22 ~23 ~45 ~22 ~32 ~45 red_nether_brick 0  
fill ~22 ~23 ~46 ~22 ~31 ~46 red_nether_brick 0  
fill ~22 ~23 ~47 ~22 ~31 ~47 red_nether_brick 0  
fill ~22 ~23 ~48 ~22 ~31 ~48 red_nether_brick 0  
fill ~22 ~23 ~49 ~22 ~31 ~49 red_nether_brick 0  
fill ~22 ~23 ~55 ~22 ~31 ~55 red_nether_brick 0  
fill ~22 ~23 ~56 ~22 ~31 ~56 red_nether_brick 0  
fill ~22 ~23 ~57 ~22 ~32 ~57 red_nether_brick 0  
fill ~22 ~23 ~58 ~22 ~32 ~58 red_nether_brick 0  
fill ~22 ~23 ~78 ~22 ~27 ~78 red_nether_brick 0  
fill ~23 ~23 ~23 ~23 ~27 ~23 red_nether_brick 0  
fill ~23 ~23 ~42 ~23 ~31 ~42 red_nether_brick 0  
fill ~23 ~23 ~43 ~23 ~31 ~43 red_nether_brick 0  
fill ~23 ~23 ~44 ~23 ~31 ~44 red_nether_brick 0  
fill ~23 ~23 ~59 ~23 ~31 ~59 red_nether_brick 0  
fill ~23 ~23 ~60 ~23 ~31 ~60 red_nether_brick 0  
fill ~23 ~23 ~79 ~23 ~27 ~79 red_nether_brick 0  
fill ~24 ~23 ~22 ~24 ~27 ~22 red_nether_brick 0  
fill ~24 ~23 ~39 ~24 ~30 ~39 red_nether_brick 0  
fill ~24 ~23 ~40 ~24 ~31 ~40 red_nether_brick 0  
fill ~24 ~23 ~41 ~24 ~31 ~41 red_nether_brick 0  
fill ~24 ~23 ~61 ~24 ~31 ~61 red_nether_brick 0  
fill ~24 ~23 ~62 ~24 ~31 ~62 red_nether_brick 0  
fill ~24 ~23 ~63 ~24 ~30 ~63 red_nether_brick 0  
fill ~24 ~23 ~80 ~24 ~27 ~80 red_nether_brick 0  
fill ~25 ~23 ~21 ~26 ~23 ~21 red_nether_brick 0  
fill ~25 ~23 ~37 ~25 ~30 ~37 red_nether_brick 0  
fill ~25 ~23 ~38 ~25 ~31 ~38 red_nether_brick 0  
fill ~25 ~23 ~64 ~25 ~31 ~64 red_nether_brick 0  
fill ~25 ~23 ~65 ~25 ~30 ~65 red_nether_brick 0  
fill ~25 ~23 ~81 ~26 ~23 ~81 red_nether_brick 0 
setblock ~26 ~23 ~20 stone_slab 15  
fill ~26 ~23 ~35 ~26 ~32 ~35 red_nether_brick 0  
fill ~26 ~23 ~36 ~26 ~31 ~36 red_nether_brick 0  
fill ~26 ~23 ~66 ~26 ~31 ~66 red_nether_brick 0  
fill ~26 ~23 ~67 ~26 ~32 ~67 red_nether_brick 0 
setblock ~26 ~23 ~82 stone_slab 15  
fill ~27 ~23 ~34 ~27 ~31 ~34 red_nether_brick 0  
fill ~27 ~23 ~68 ~27 ~31 ~68 red_nether_brick 0  
fill ~27 ~23 ~82 ~27 ~24 ~82 red_nether_brick 0  
fill ~28 ~23 ~19 ~28 ~26 ~19 red_nether_brick 0  
fill ~28 ~23 ~33 ~28 ~31 ~33 red_nether_brick 0  
fill ~28 ~23 ~69 ~28 ~31 ~69 red_nether_brick 0  
fill ~28 ~23 ~83 ~28 ~26 ~83 red_nether_brick 0  
fill ~29 ~23 ~18 ~29 ~30 ~18 red_nether_brick 0  
fill ~29 ~23 ~32 ~29 ~31 ~32 red_nether_brick 0  
fill ~29 ~23 ~70 ~29 ~31 ~70 red_nether_brick 0  
fill ~29 ~23 ~84 ~30 ~23 ~84 red_nether_brick 0  
fill ~30 ~23 ~31 ~30 ~31 ~31 red_nether_brick 0  
fill ~30 ~23 ~71 ~30 ~31 ~71 red_nether_brick 0  
fill ~31 ~23 ~17 ~32 ~23 ~17 red_nether_brick 0  
fill ~31 ~23 ~30 ~31 ~31 ~30 red_nether_brick 0  
fill ~31 ~23 ~72 ~31 ~31 ~72 red_nether_brick 0  
fill ~31 ~23 ~85 ~32 ~23 ~85 red_nether_brick 0 
setblock ~32 ~23 ~16 stone_slab 15  
fill ~32 ~23 ~29 ~32 ~31 ~29 red_nether_brick 0  
fill ~32 ~23 ~73 ~32 ~31 ~73 red_nether_brick 0 
setblock ~32 ~23 ~86 stone_slab 15  
fill ~33 ~23 ~16 ~34 ~23 ~16 red_nether_brick 0  
fill ~33 ~23 ~28 ~33 ~31 ~28 red_nether_brick 0  
fill ~33 ~23 ~74 ~33 ~31 ~74 red_nether_brick 0  
fill ~33 ~23 ~86 ~34 ~23 ~86 red_nether_brick 0 
setblock ~34 ~23 ~15 stone_slab 15  
fill ~34 ~23 ~27 ~34 ~31 ~27 red_nether_brick 0  
fill ~34 ~23 ~75 ~34 ~31 ~75 red_nether_brick 0 
setblock ~34 ~23 ~87 stone_slab 15  
fill ~35 ~23 ~15 ~36 ~23 ~15 red_nether_brick 0  
fill ~35 ~23 ~26 ~36 ~23 ~26 red_nether_brick 0  
fill ~35 ~23 ~76 ~36 ~23 ~76 red_nether_brick 0  
fill ~35 ~23 ~87 ~36 ~23 ~87 red_nether_brick 0  
fill ~37 ~23 ~14 ~39 ~23 ~14 red_nether_brick 0  
fill ~37 ~23 ~25 ~38 ~23 ~25 red_nether_brick 0  
fill ~37 ~23 ~77 ~38 ~23 ~77 red_nether_brick 0  
fill ~37 ~23 ~88 ~39 ~23 ~88 red_nether_brick 0 
setblock ~39 ~23 ~13 stone_slab 15  
fill ~39 ~23 ~24 ~41 ~23 ~24 red_nether_brick 0  
fill ~39 ~23 ~78 ~41 ~23 ~78 red_nether_brick 0 
setblock ~39 ~23 ~89 stone_slab 15  
fill ~40 ~23 ~13 ~43 ~23 ~13 red_nether_brick 0  
fill ~40 ~23 ~89 ~43 ~23 ~89 red_nether_brick 0  
fill ~42 ~23 ~23 ~43 ~23 ~23 red_nether_brick 0  
fill ~42 ~23 ~79 ~44 ~23 ~79 red_nether_brick 0 
setblock ~43 ~23 ~12 stone_slab 15 
setblock ~43 ~23 ~90 stone_slab 15  
fill ~44 ~23 ~12 ~58 ~23 ~12 red_nether_brick 0  
fill ~44 ~23 ~22 ~57 ~23 ~22 red_nether_brick 0  
fill ~44 ~23 ~90 ~58 ~23 ~90 red_nether_brick 0  
fill ~45 ~23 ~80 ~58 ~23 ~80 red_nether_brick 0  
fill ~48 ~23 ~11 ~52 ~23 ~11 red_nether_brick 0  
fill ~48 ~23 ~13 ~52 ~23 ~13 red_nether_brick 0  
fill ~48 ~23 ~14 ~52 ~23 ~14 red_nether_brick 0  
fill ~48 ~23 ~15 ~52 ~23 ~15 red_nether_brick 0  
fill ~48 ~23 ~16 ~52 ~23 ~16 red_nether_brick 0  
fill ~48 ~23 ~17 ~48 ~31 ~17 red_nether_brick 0  
fill ~48 ~23 ~18 ~52 ~23 ~18 red_nether_brick 0 
setblock ~49 ~23 ~3 nether_brick_stairs 6  
fill ~49 ~23 ~9 ~49 ~33 ~9 red_nether_brick 0  
fill ~49 ~23 ~10 ~49 ~33 ~10 red_nether_brick 0  
fill ~49 ~23 ~24 ~49 ~40 ~24 red_nether_brick 0  
fill ~50 ~23 ~84 ~54 ~23 ~84 red_nether_brick 0  
fill ~50 ~23 ~85 ~50 ~31 ~85 red_nether_brick 0  
fill ~50 ~23 ~86 ~54 ~23 ~86 red_nether_brick 0  
fill ~50 ~23 ~87 ~54 ~23 ~87 red_nether_brick 0  
fill ~50 ~23 ~88 ~54 ~23 ~88 red_nether_brick 0  
fill ~50 ~23 ~89 ~54 ~23 ~89 red_nether_brick 0  
fill ~50 ~23 ~91 ~54 ~23 ~91 red_nether_brick 0 
setblock ~51 ~23 ~3 nether_brick_stairs 6  
fill ~51 ~23 ~9 ~51 ~33 ~9 red_nether_brick 0  
fill ~51 ~23 ~10 ~51 ~33 ~10 red_nether_brick 0  
fill ~51 ~23 ~24 ~51 ~40 ~24 red_nether_brick 0  
fill ~51 ~23 ~78 ~51 ~40 ~78 red_nether_brick 0  
fill ~51 ~23 ~92 ~51 ~33 ~92 red_nether_brick 0  
fill ~51 ~23 ~93 ~51 ~33 ~93 red_nether_brick 0 
setblock ~51 ~23 ~99 nether_brick_stairs 7  
fill ~52 ~23 ~17 ~52 ~31 ~17 red_nether_brick 0  
fill ~52 ~23 ~21 ~52 ~32 ~21 red_nether_brick 0  
fill ~53 ~23 ~78 ~53 ~40 ~78 red_nether_brick 0  
fill ~53 ~23 ~92 ~53 ~33 ~92 red_nether_brick 0  
fill ~53 ~23 ~93 ~53 ~33 ~93 red_nether_brick 0 
setblock ~53 ~23 ~99 nether_brick_stairs 7  
fill ~54 ~23 ~85 ~54 ~31 ~85 red_nether_brick 0  
fill ~58 ~23 ~23 ~60 ~23 ~23 red_nether_brick 0 
setblock ~59 ~23 ~12 stone_slab 15  
fill ~59 ~23 ~13 ~62 ~23 ~13 red_nether_brick 0  
fill ~59 ~23 ~79 ~60 ~23 ~79 red_nether_brick 0  
fill ~59 ~23 ~89 ~62 ~23 ~89 red_nether_brick 0 
setblock ~59 ~23 ~90 stone_slab 15  
fill ~61 ~23 ~24 ~63 ~23 ~24 red_nether_brick 0  
fill ~61 ~23 ~78 ~63 ~23 ~78 red_nether_brick 0 
setblock ~63 ~23 ~13 stone_slab 15  
fill ~63 ~23 ~14 ~65 ~23 ~14 red_nether_brick 0  
fill ~63 ~23 ~88 ~65 ~23 ~88 red_nether_brick 0 
setblock ~63 ~23 ~89 stone_slab 15  
fill ~64 ~23 ~25 ~65 ~23 ~25 red_nether_brick 0  
fill ~64 ~23 ~77 ~65 ~23 ~77 red_nether_brick 0  
fill ~66 ~23 ~15 ~67 ~23 ~15 red_nether_brick 0  
fill ~66 ~23 ~26 ~67 ~23 ~26 red_nether_brick 0  
fill ~66 ~23 ~76 ~67 ~23 ~76 red_nether_brick 0  
fill ~66 ~23 ~87 ~67 ~23 ~87 red_nether_brick 0 
setblock ~68 ~23 ~15 stone_slab 15  
fill ~68 ~23 ~16 ~69 ~23 ~16 red_nether_brick 0  
fill ~68 ~23 ~27 ~68 ~31 ~27 red_nether_brick 0  
fill ~68 ~23 ~75 ~68 ~31 ~75 red_nether_brick 0  
fill ~68 ~23 ~86 ~69 ~23 ~86 red_nether_brick 0 
setblock ~68 ~23 ~87 stone_slab 15  
fill ~69 ~23 ~28 ~69 ~31 ~28 red_nether_brick 0  
fill ~69 ~23 ~74 ~69 ~31 ~74 red_nether_brick 0 
setblock ~70 ~23 ~16 stone_slab 15  
fill ~70 ~23 ~17 ~71 ~23 ~17 red_nether_brick 0  
fill ~70 ~23 ~29 ~70 ~31 ~29 red_nether_brick 0  
fill ~70 ~23 ~73 ~70 ~31 ~73 red_nether_brick 0  
fill ~70 ~23 ~85 ~71 ~23 ~85 red_nether_brick 0 
setblock ~70 ~23 ~86 stone_slab 15  
fill ~71 ~23 ~30 ~71 ~31 ~30 red_nether_brick 0  
fill ~71 ~23 ~72 ~71 ~31 ~72 red_nether_brick 0  
fill ~72 ~23 ~31 ~72 ~31 ~31 red_nether_brick 0  
fill ~72 ~23 ~71 ~72 ~31 ~71 red_nether_brick 0  
fill ~73 ~23 ~18 ~73 ~30 ~18 red_nether_brick 0  
fill ~73 ~23 ~32 ~73 ~31 ~32 red_nether_brick 0  
fill ~73 ~23 ~70 ~73 ~31 ~70 red_nether_brick 0  
fill ~73 ~23 ~84 ~73 ~30 ~84 red_nether_brick 0  
fill ~74 ~23 ~19 ~74 ~26 ~19 red_nether_brick 0  
fill ~74 ~23 ~33 ~74 ~31 ~33 red_nether_brick 0  
fill ~74 ~23 ~69 ~74 ~31 ~69 red_nether_brick 0  
fill ~74 ~23 ~83 ~74 ~26 ~83 red_nether_brick 0  
fill ~75 ~23 ~34 ~75 ~31 ~34 red_nether_brick 0  
fill ~75 ~23 ~68 ~75 ~31 ~68 red_nether_brick 0 
setblock ~76 ~23 ~20 stone_slab 15  
fill ~76 ~23 ~21 ~77 ~23 ~21 red_nether_brick 0  
fill ~76 ~23 ~35 ~76 ~32 ~35 red_nether_brick 0  
fill ~76 ~23 ~36 ~76 ~31 ~36 red_nether_brick 0  
fill ~76 ~23 ~66 ~76 ~31 ~66 red_nether_brick 0  
fill ~76 ~23 ~67 ~76 ~32 ~67 red_nether_brick 0  
fill ~76 ~23 ~81 ~77 ~23 ~81 red_nether_brick 0 
setblock ~76 ~23 ~82 stone_slab 15  
fill ~77 ~23 ~37 ~77 ~30 ~37 red_nether_brick 0  
fill ~77 ~23 ~38 ~77 ~31 ~38 red_nether_brick 0  
fill ~77 ~23 ~64 ~77 ~31 ~64 red_nether_brick 0  
fill ~77 ~23 ~65 ~77 ~30 ~65 red_nether_brick 0  
fill ~78 ~23 ~22 ~78 ~27 ~22 red_nether_brick 0  
fill ~78 ~23 ~39 ~78 ~30 ~39 red_nether_brick 0  
fill ~78 ~23 ~40 ~78 ~31 ~40 red_nether_brick 0  
fill ~78 ~23 ~41 ~78 ~31 ~41 red_nether_brick 0  
fill ~78 ~23 ~49 ~78 ~40 ~49 red_nether_brick 0  
fill ~78 ~23 ~50 ~99 ~23 ~50 red_nether_brick 0  
fill ~78 ~23 ~51 ~78 ~40 ~51 red_nether_brick 0  
fill ~78 ~23 ~61 ~78 ~31 ~61 red_nether_brick 0  
fill ~78 ~23 ~62 ~78 ~31 ~62 red_nether_brick 0  
fill ~78 ~23 ~63 ~78 ~30 ~63 red_nether_brick 0  
fill ~78 ~23 ~80 ~78 ~27 ~80 red_nether_brick 0  
fill ~79 ~23 ~23 ~79 ~27 ~23 red_nether_brick 0  
fill ~79 ~23 ~42 ~79 ~31 ~42 red_nether_brick 0  
fill ~79 ~23 ~43 ~79 ~31 ~43 red_nether_brick 0  
fill ~79 ~23 ~58 ~79 ~31 ~58 red_nether_brick 0  
fill ~79 ~23 ~59 ~79 ~31 ~59 red_nether_brick 0  
fill ~79 ~23 ~60 ~79 ~31 ~60 red_nether_brick 0  
fill ~79 ~23 ~79 ~79 ~27 ~79 red_nether_brick 0  
fill ~80 ~23 ~24 ~80 ~27 ~24 red_nether_brick 0  
fill ~80 ~23 ~44 ~80 ~32 ~44 red_nether_brick 0  
fill ~80 ~23 ~45 ~80 ~32 ~45 red_nether_brick 0  
fill ~80 ~23 ~46 ~80 ~31 ~46 red_nether_brick 0  
fill ~80 ~23 ~47 ~80 ~31 ~47 red_nether_brick 0  
fill ~80 ~23 ~48 ~80 ~32 ~48 red_nether_brick 0  
fill ~80 ~23 ~52 ~80 ~32 ~52 red_nether_brick 0  
fill ~80 ~23 ~53 ~80 ~31 ~53 red_nether_brick 0  
fill ~80 ~23 ~54 ~80 ~31 ~54 red_nether_brick 0  
fill ~80 ~23 ~55 ~80 ~31 ~55 red_nether_brick 0  
fill ~80 ~23 ~56 ~80 ~31 ~56 red_nether_brick 0  
fill ~80 ~23 ~57 ~80 ~32 ~57 red_nether_brick 0  
fill ~80 ~23 ~78 ~80 ~27 ~78 red_nether_brick 0  
fill ~81 ~23 ~25 ~81 ~29 ~25 red_nether_brick 0  
fill ~81 ~23 ~26 ~81 ~23 ~25 red_nether_brick 0  
fill ~81 ~23 ~76 ~81 ~23 ~77 red_nether_brick 0 
setblock ~82 ~23 ~26 stone_slab 15  
fill ~82 ~23 ~27 ~82 ~24 ~27 red_nether_brick 0  
fill ~82 ~23 ~75 ~82 ~24 ~75 red_nether_brick 0 
setblock ~82 ~23 ~76 stone_slab 15  
fill ~83 ~23 ~48 ~91 ~23 ~48 red_nether_brick 0  
fill ~83 ~23 ~49 ~98 ~23 ~49 red_nether_brick 0  
fill ~83 ~23 ~51 ~98 ~23 ~51 red_nether_brick 0  
fill ~83 ~23 ~52 ~91 ~23 ~52 red_nether_brick 0  
fill ~83 ~23 ~74 ~83 ~26 ~74 red_nether_brick 0  
fill ~84 ~23 ~29 ~84 ~30 ~29 red_nether_brick 0  
fill ~84 ~23 ~30 ~84 ~24 ~30 red_nether_brick 0  
fill ~84 ~23 ~72 ~84 ~24 ~72 red_nether_brick 0  
fill ~84 ~23 ~73 ~84 ~30 ~73 red_nether_brick 0 
setblock ~85 ~23 ~32 red_nether_brick 0 
setblock ~85 ~23 ~70 red_nether_brick 0 
setblock ~86 ~23 ~32 stone_slab 15  
fill ~86 ~23 ~33 ~86 ~26 ~33 red_nether_brick 0  
fill ~86 ~23 ~34 ~86 ~23 ~33 red_nether_brick 0  
fill ~86 ~23 ~68 ~86 ~23 ~69 red_nether_brick 0 
setblock ~86 ~23 ~70 stone_slab 15 
setblock ~87 ~23 ~34 stone_slab 15  
fill ~87 ~23 ~35 ~87 ~27 ~35 red_nether_brick 0  
fill ~87 ~23 ~36 ~87 ~24 ~36 red_nether_brick 0  
fill ~87 ~23 ~66 ~87 ~24 ~66 red_nether_brick 0  
fill ~87 ~23 ~67 ~87 ~27 ~67 red_nether_brick 0 
setblock ~87 ~23 ~68 stone_slab 15  
fill ~88 ~23 ~37 ~88 ~30 ~37 red_nether_brick 0  
fill ~88 ~23 ~38 ~88 ~25 ~38 red_nether_brick 0  
fill ~88 ~23 ~39 ~88 ~23 ~37 red_nether_brick 0  
fill ~88 ~23 ~63 ~88 ~23 ~65 red_nether_brick 0 
setblock ~89 ~23 ~39 stone_slab 15  
fill ~89 ~23 ~40 ~89 ~32 ~40 red_nether_brick 0  
fill ~89 ~23 ~41 ~89 ~26 ~41 red_nether_brick 0  
fill ~89 ~23 ~42 ~89 ~24 ~42 red_nether_brick 0  
fill ~89 ~23 ~43 ~89 ~23 ~40 red_nether_brick 0  
fill ~89 ~23 ~59 ~89 ~23 ~62 red_nether_brick 0 
setblock ~89 ~23 ~63 stone_slab 15 
setblock ~90 ~23 ~43 stone_slab 15  
fill ~90 ~23 ~44 ~90 ~32 ~44 red_nether_brick 0  
fill ~90 ~23 ~45 ~90 ~28 ~45 red_nether_brick 0  
fill ~90 ~23 ~46 ~90 ~27 ~46 red_nether_brick 0  
fill ~90 ~23 ~47 ~90 ~26 ~47 red_nether_brick 0  
fill ~90 ~23 ~53 ~90 ~24 ~53 red_nether_brick 0  
fill ~90 ~23 ~54 ~90 ~25 ~54 red_nether_brick 0  
fill ~90 ~23 ~55 ~90 ~26 ~55 red_nether_brick 0  
fill ~90 ~23 ~56 ~90 ~27 ~56 red_nether_brick 0  
fill ~90 ~23 ~57 ~90 ~28 ~57 red_nether_brick 0  
fill ~90 ~23 ~58 ~90 ~32 ~58 red_nether_brick 0 
setblock ~90 ~23 ~59 stone_slab 15 
setblock ~99 ~23 ~49 nether_brick_stairs 5 
setblock ~99 ~23 ~51 nether_brick_stairs 5  
fill ~3 ~24 ~51 ~3 ~28 ~51 red_nether_brick 0  
fill ~3 ~24 ~53 ~3 ~28 ~53 red_nether_brick 0  
fill ~9 ~24 ~50 ~22 ~24 ~50 red_nether_brick 0  
fill ~9 ~24 ~51 ~24 ~24 ~51 red_nether_brick 0  
fill ~9 ~24 ~52 ~24 ~24 ~52 red_nether_brick 0  
fill ~9 ~24 ~53 ~24 ~24 ~53 red_nether_brick 0  
fill ~9 ~24 ~54 ~22 ~24 ~54 red_nether_brick 0 
setblock ~11 ~24 ~49 stone_slab 15 
setblock ~12 ~24 ~42 stone_slab 15  
fill ~12 ~24 ~43 ~12 ~32 ~43 red_nether_brick 0  
fill ~12 ~24 ~59 ~12 ~32 ~59 red_nether_brick 0 
setblock ~12 ~24 ~60 stone_slab 15  
fill ~13 ~24 ~39 ~13 ~32 ~39 red_nether_brick 0  
fill ~13 ~24 ~63 ~13 ~32 ~63 red_nether_brick 0 
setblock ~14 ~24 ~36 stone_slab 15  
fill ~14 ~24 ~64 ~14 ~25 ~64 red_nether_brick 0  
fill ~14 ~24 ~65 ~14 ~30 ~65 red_nether_brick 0 
setblock ~14 ~24 ~66 stone_slab 15 
fill ~15 ~24 ~34 ~15 ~32 ~34 red_nether_brick 0  
fill ~15 ~24 ~68 ~15 ~32 ~68 red_nether_brick 0  
fill ~16 ~24 ~32 ~16 ~32 ~32 red_nether_brick 0  
fill ~16 ~24 ~69 ~16 ~26 ~69 red_nether_brick 0  
fill ~16 ~24 ~70 ~16 ~32 ~70 red_nether_brick 0 
setblock ~17 ~24 ~30 stone_slab 15  
fill ~17 ~24 ~71 ~17 ~27 ~71 red_nether_brick 0 
setblock ~17 ~24 ~72 stone_slab 15 
setblock ~19 ~24 ~27 stone_slab 15 
setblock ~19 ~24 ~75 stone_slab 15  
fill ~20 ~24 ~26 ~20 ~32 ~26 red_nether_brick 0  
fill ~20 ~24 ~76 ~20 ~32 ~76 red_nether_brick 0  
fill ~21 ~24 ~77 ~21 ~29 ~77 red_nether_brick 0  
fill ~25 ~24 ~21 ~25 ~29 ~21 red_nether_brick 0  
fill ~25 ~24 ~81 ~25 ~29 ~81 red_nether_brick 0  
fill ~26 ~24 ~20 ~26 ~32 ~20 red_nether_brick 0  
fill ~26 ~24 ~82 ~26 ~32 ~82 red_nether_brick 0 
setblock ~27 ~24 ~19 stone_slab 15 
setblock ~27 ~24 ~83 stone_slab 15  
fill ~29 ~24 ~84 ~30 ~24 ~84 red_nether_brick 0 
setblock ~30 ~24 ~17 stone_slab 15 
setblock ~30 ~24 ~85 stone_slab 15  
fill ~31 ~24 ~17 ~31 ~27 ~17 red_nether_brick 0  
fill ~31 ~24 ~85 ~31 ~27 ~85 red_nether_brick 0  
fill ~32 ~24 ~16 ~33 ~24 ~16 red_nether_brick 0  
fill ~32 ~24 ~86 ~33 ~24 ~86 red_nether_brick 0  
fill ~34 ~24 ~15 ~36 ~24 ~15 red_nether_brick 0  
fill ~34 ~24 ~87 ~36 ~24 ~87 red_nether_brick 0  
fill ~35 ~24 ~26 ~36 ~24 ~26 red_nether_brick 0  
fill ~35 ~24 ~76 ~36 ~24 ~76 red_nether_brick 0 
setblock ~36 ~24 ~14 stone_slab 15 
setblock ~36 ~24 ~88 stone_slab 15  
fill ~37 ~24 ~14 ~38 ~24 ~14 red_nether_brick 0  
fill ~37 ~24 ~25 ~38 ~24 ~25 red_nether_brick 0  
fill ~37 ~24 ~77 ~38 ~24 ~77 red_nether_brick 0  
fill ~37 ~24 ~88 ~38 ~24 ~88 red_nether_brick 0  
fill ~39 ~24 ~13 ~42 ~24 ~13 red_nether_brick 0  
fill ~39 ~24 ~24 ~41 ~24 ~24 red_nether_brick 0  
fill ~39 ~24 ~78 ~41 ~24 ~78 red_nether_brick 0  
fill ~39 ~24 ~89 ~42 ~24 ~89 red_nether_brick 0 
setblock ~42 ~24 ~12 stone_slab 15  
fill ~42 ~24 ~23 ~43 ~24 ~23 red_nether_brick 0  
fill ~42 ~24 ~79 ~44 ~24 ~79 red_nether_brick 0 
setblock ~42 ~24 ~90 stone_slab 15  
fill ~43 ~24 ~12 ~59 ~24 ~12 red_nether_brick 0  
fill ~43 ~24 ~90 ~59 ~24 ~90 red_nether_brick 0  
fill ~44 ~24 ~22 ~57 ~24 ~22 red_nether_brick 0  
fill ~45 ~24 ~80 ~58 ~24 ~80 red_nether_brick 0  
fill ~48 ~24 ~9 ~48 ~30 ~9 red_nether_brick 0  
fill ~48 ~24 ~10 ~48 ~30 ~10 red_nether_brick 0  
fill ~48 ~24 ~11 ~52 ~24 ~11 red_nether_brick 0  
fill ~48 ~24 ~13 ~52 ~24 ~13 red_nether_brick 0  
fill ~48 ~24 ~14 ~52 ~24 ~14 red_nether_brick 0  
fill ~48 ~24 ~15 ~52 ~24 ~15 red_nether_brick 0  
fill ~48 ~24 ~16 ~52 ~24 ~16 red_nether_brick 0  
fill ~48 ~24 ~18 ~52 ~24 ~18 red_nether_brick 0  
fill ~49 ~24 ~3 ~49 ~28 ~3 red_nether_brick 0 
setblock ~49 ~24 ~91 stone_slab 15  
fill ~50 ~24 ~84 ~54 ~24 ~84 red_nether_brick 0  
fill ~50 ~24 ~86 ~54 ~24 ~86 red_nether_brick 0  
fill ~50 ~24 ~87 ~54 ~24 ~87 red_nether_brick 0  
fill ~50 ~24 ~88 ~54 ~24 ~88 red_nether_brick 0  
fill ~50 ~24 ~89 ~54 ~24 ~89 red_nether_brick 0  
fill ~50 ~24 ~91 ~54 ~24 ~91 red_nether_brick 0  
fill ~50 ~24 ~92 ~50 ~30 ~92 red_nether_brick 0  
fill ~50 ~24 ~93 ~50 ~30 ~93 red_nether_brick 0  
fill ~51 ~24 ~3 ~51 ~28 ~3 red_nether_brick 0  
fill ~51 ~24 ~99 ~51 ~28 ~99 red_nether_brick 0  
fill ~52 ~24 ~9 ~52 ~30 ~9 red_nether_brick 0  
fill ~52 ~24 ~10 ~52 ~30 ~10 red_nether_brick 0 
setblock ~53 ~24 ~11 stone_slab 15  
fill ~53 ~24 ~99 ~53 ~28 ~99 red_nether_brick 0  
fill ~54 ~24 ~92 ~54 ~30 ~92 red_nether_brick 0  
fill ~54 ~24 ~93 ~54 ~30 ~93 red_nether_brick 0  
fill ~58 ~24 ~23 ~60 ~24 ~23 red_nether_brick 0  
fill ~59 ~24 ~79 ~60 ~24 ~79 red_nether_brick 0 
setblock ~60 ~24 ~12 stone_slab 15  
fill ~60 ~24 ~13 ~63 ~24 ~13 red_nether_brick 0  
fill ~60 ~24 ~89 ~63 ~24 ~89 red_nether_brick 0 
setblock ~60 ~24 ~90 stone_slab 15  
fill ~61 ~24 ~24 ~63 ~24 ~24 red_nether_brick 0  
fill ~61 ~24 ~78 ~63 ~24 ~78 red_nether_brick 0  
fill ~64 ~24 ~14 ~65 ~24 ~14 red_nether_brick 0  
fill ~64 ~24 ~25 ~65 ~24 ~25 red_nether_brick 0  
fill ~64 ~24 ~77 ~65 ~24 ~77 red_nether_brick 0  
fill ~64 ~24 ~88 ~65 ~24 ~88 red_nether_brick 0 
setblock ~66 ~24 ~14 stone_slab 15  
fill ~66 ~24 ~15 ~68 ~24 ~15 red_nether_brick 0  
fill ~66 ~24 ~26 ~67 ~24 ~26 red_nether_brick 0  
fill ~66 ~24 ~76 ~67 ~24 ~76 red_nether_brick 0  
fill ~66 ~24 ~87 ~68 ~24 ~87 red_nether_brick 0 
setblock ~66 ~24 ~88 stone_slab 15  
fill ~69 ~24 ~16 ~70 ~24 ~16 red_nether_brick 0  
fill ~69 ~24 ~86 ~70 ~24 ~86 red_nether_brick 0  
fill ~71 ~24 ~17 ~71 ~27 ~17 red_nether_brick 0  
fill ~71 ~24 ~85 ~71 ~27 ~85 red_nether_brick 0 
setblock ~72 ~24 ~17 stone_slab 15 
setblock ~72 ~24 ~85 stone_slab 15 
setblock ~75 ~24 ~19 stone_slab 15 
setblock ~75 ~24 ~83 stone_slab 15  
fill ~76 ~24 ~20 ~76 ~32 ~20 red_nether_brick 0  
fill ~76 ~24 ~82 ~76 ~32 ~82 red_nether_brick 0  
fill ~77 ~24 ~21 ~77 ~29 ~21 red_nether_brick 0  
fill ~77 ~24 ~81 ~77 ~29 ~81 red_nether_brick 0  
fill ~78 ~24 ~50 ~99 ~24 ~50 red_nether_brick 0  
fill ~81 ~24 ~77 ~81 ~29 ~77 red_nether_brick 0  
fill ~82 ~24 ~26 ~82 ~32 ~26 red_nether_brick 0  
fill ~82 ~24 ~76 ~82 ~32 ~76 red_nether_brick 0 
setblock ~83 ~24 ~27 stone_slab 15  
fill ~83 ~24 ~48 ~93 ~24 ~48 red_nether_brick 0  
fill ~83 ~24 ~49 ~99 ~24 ~49 red_nether_brick 0  
fill ~83 ~24 ~51 ~99 ~24 ~51 red_nether_brick 0  
fill ~83 ~24 ~52 ~93 ~24 ~52 red_nether_brick 0 
setblock ~83 ~24 ~75 stone_slab 15 
setblock ~85 ~24 ~30 stone_slab 15 
setblock ~85 ~24 ~72 stone_slab 15  
fill ~86 ~24 ~32 ~86 ~32 ~32 red_nether_brick 0  
fill ~86 ~24 ~69 ~86 ~26 ~69 red_nether_brick 0  
fill ~86 ~24 ~70 ~86 ~32 ~70 red_nether_brick 0  
fill ~87 ~24 ~34 ~87 ~32 ~34 red_nether_brick 0  
fill ~87 ~24 ~68 ~87 ~32 ~68 red_nether_brick 0 
setblock ~88 ~24 ~36 stone_slab 15  
fill ~88 ~24 ~64 ~88 ~25 ~64 red_nether_brick 0  
fill ~88 ~24 ~65 ~88 ~32 ~65 red_nether_brick 0 
setblock ~88 ~24 ~66 stone_slab 15  
fill ~89 ~24 ~39 ~89 ~32 ~39 red_nether_brick 0  
fill ~89 ~24 ~60 ~89 ~24 ~63 red_nether_brick 0 
setblock ~90 ~24 ~42 stone_slab 15  
fill ~90 ~24 ~43 ~90 ~32 ~43 red_nether_brick 0  
fill ~90 ~24 ~59 ~90 ~32 ~59 red_nether_brick 0 
setblock ~90 ~24 ~60 stone_slab 15 
setblock ~91 ~24 ~53 stone_slab 15  
fill ~2 ~25 ~52 ~2 ~27 ~52 red_nether_brick 0  
fill ~7 ~25 ~50 ~22 ~25 ~50 red_nether_brick 0  
fill ~7 ~25 ~54 ~22 ~25 ~54 red_nether_brick 0  
fill ~9 ~25 ~51 ~24 ~25 ~51 red_nether_brick 0  
fill ~9 ~25 ~52 ~24 ~25 ~52 red_nether_brick 0  
fill ~9 ~25 ~53 ~24 ~25 ~53 red_nether_brick 0 
setblock ~11 ~25 ~48 stone_slab 15  
fill ~11 ~25 ~49 ~11 ~32 ~49 red_nether_brick 0  
fill ~12 ~25 ~42 ~12 ~32 ~42 red_nether_brick 0  
fill ~12 ~25 ~60 ~12 ~32 ~60 red_nether_brick 0 
setblock ~13 ~25 ~38 stone_slab 15 
setblock ~13 ~25 ~64 stone_slab 15  
fill ~14 ~25 ~36 ~14 ~32 ~36 red_nether_brick 0  
fill ~14 ~25 ~66 ~14 ~32 ~66 red_nether_brick 0  
fill ~17 ~25 ~30 ~17 ~32 ~30 red_nether_brick 0  
fill ~17 ~25 ~72 ~17 ~32 ~72 red_nether_brick 0  
fill ~19 ~25 ~27 ~19 ~32 ~27 red_nether_brick 0  
fill ~19 ~25 ~75 ~19 ~32 ~75 red_nether_brick 0  
fill ~22 ~25 ~44 ~22 ~32 ~44 red_nether_brick 0  
fill ~23 ~25 ~41 ~23 ~32 ~41 red_nether_brick 0  
fill ~23 ~25 ~61 ~23 ~32 ~61 red_nether_brick 0  
fill ~24 ~25 ~46 ~78 ~25 ~46 red_nether_brick 0  
fill ~24 ~25 ~47 ~78 ~25 ~47 red_nether_brick 0  
fill ~24 ~25 ~48 ~76 ~25 ~48 red_nether_brick 0  
fill ~24 ~25 ~49 ~76 ~25 ~49 red_nether_brick 0  
fill ~24 ~25 ~55 ~78 ~25 ~55 red_nether_brick 0  
fill ~24 ~25 ~56 ~78 ~25 ~56 red_nether_brick 0  
fill ~24 ~25 ~57 ~77 ~25 ~57 red_nether_brick 0  
fill ~25 ~25 ~43 ~77 ~25 ~43 red_nether_brick 0  
fill ~25 ~25 ~44 ~77 ~25 ~44 red_nether_brick 0  
fill ~25 ~25 ~45 ~78 ~25 ~45 red_nether_brick 0  
fill ~25 ~25 ~58 ~77 ~25 ~58 red_nether_brick 0  
fill ~25 ~25 ~59 ~77 ~25 ~59 red_nether_brick 0  
fill ~26 ~25 ~40 ~76 ~25 ~40 red_nether_brick 0  
fill ~26 ~25 ~41 ~76 ~25 ~41 red_nether_brick 0  
fill ~26 ~25 ~42 ~76 ~25 ~42 red_nether_brick 0  
fill ~26 ~25 ~50 ~76 ~25 ~50 red_nether_brick 0  
fill ~26 ~25 ~51 ~76 ~25 ~51 red_nether_brick 0  
fill ~26 ~25 ~52 ~76 ~25 ~52 red_nether_brick 0  
fill ~26 ~25 ~53 ~78 ~25 ~53 red_nether_brick 0  
fill ~26 ~25 ~54 ~78 ~25 ~54 red_nether_brick 0  
fill ~26 ~25 ~60 ~76 ~25 ~60 red_nether_brick 0  
fill ~26 ~25 ~61 ~76 ~25 ~61 red_nether_brick 0  
fill ~26 ~25 ~62 ~76 ~25 ~62 red_nether_brick 0  
fill ~27 ~25 ~19 ~27 ~32 ~19 red_nether_brick 0  
fill ~27 ~25 ~38 ~75 ~25 ~38 red_nether_brick 0  
fill ~27 ~25 ~39 ~75 ~25 ~39 red_nether_brick 0  
fill ~27 ~25 ~63 ~75 ~25 ~63 red_nether_brick 0  
fill ~27 ~25 ~64 ~75 ~25 ~64 red_nether_brick 0  
fill ~27 ~25 ~83 ~27 ~32 ~83 red_nether_brick 0  
fill ~28 ~25 ~32 ~28 ~32 ~32 red_nether_brick 0  
fill ~28 ~25 ~36 ~74 ~25 ~36 red_nether_brick 0  
fill ~28 ~25 ~37 ~74 ~25 ~37 red_nether_brick 0  
fill ~28 ~25 ~65 ~74 ~25 ~65 red_nether_brick 0  
fill ~28 ~25 ~66 ~74 ~25 ~66 red_nether_brick 0  
fill ~28 ~25 ~70 ~28 ~32 ~70 red_nether_brick 0  
fill ~29 ~25 ~31 ~29 ~30 ~31 red_nether_brick 0  
fill ~29 ~25 ~35 ~73 ~25 ~35 red_nether_brick 0  
fill ~29 ~25 ~67 ~73 ~25 ~67 red_nether_brick 0  
fill ~29 ~25 ~71 ~29 ~30 ~71 red_nether_brick 0  
fill ~29 ~25 ~84 ~29 ~30 ~84 red_nether_brick 0  
fill ~30 ~25 ~17 ~30 ~32 ~17 red_nether_brick 0  
fill ~30 ~25 ~30 ~30 ~30 ~30 red_nether_brick 0  
fill ~30 ~25 ~34 ~72 ~25 ~34 red_nether_brick 0  
fill ~30 ~25 ~68 ~72 ~25 ~68 red_nether_brick 0  
fill ~30 ~25 ~72 ~30 ~30 ~72 red_nether_brick 0  
fill ~30 ~25 ~85 ~30 ~32 ~85 red_nether_brick 0  
fill ~31 ~25 ~29 ~31 ~30 ~29 red_nether_brick 0  
fill ~31 ~25 ~33 ~71 ~25 ~33 red_nether_brick 0  
fill ~31 ~25 ~69 ~71 ~25 ~69 red_nether_brick 0  
fill ~31 ~25 ~73 ~31 ~30 ~73 red_nether_brick 0  
fill ~32 ~25 ~16 ~33 ~25 ~16 red_nether_brick 0  
fill ~32 ~25 ~28 ~32 ~32 ~28 red_nether_brick 0  
fill ~32 ~25 ~32 ~70 ~25 ~32 red_nether_brick 0  
fill ~32 ~25 ~70 ~70 ~25 ~70 red_nether_brick 0  
fill ~32 ~25 ~74 ~32 ~32 ~74 red_nether_brick 0  
fill ~32 ~25 ~86 ~33 ~25 ~86 red_nether_brick 0  
fill ~33 ~25 ~31 ~69 ~25 ~31 red_nether_brick 0  
fill ~33 ~25 ~71 ~69 ~25 ~71 red_nether_brick 0  
fill ~34 ~25 ~15 ~35 ~25 ~15 red_nether_brick 0  
fill ~34 ~25 ~30 ~68 ~25 ~30 red_nether_brick 0  
fill ~34 ~25 ~72 ~68 ~25 ~72 red_nether_brick 0  
fill ~34 ~25 ~87 ~35 ~25 ~87 red_nether_brick 0  
fill ~35 ~25 ~26 ~36 ~25 ~26 red_nether_brick 0  
fill ~35 ~25 ~29 ~67 ~25 ~29 red_nether_brick 0  
fill ~35 ~25 ~73 ~67 ~25 ~73 red_nether_brick 0  
fill ~35 ~25 ~76 ~36 ~25 ~76 red_nether_brick 0  
fill ~36 ~25 ~14 ~38 ~25 ~14 red_nether_brick 0  
fill ~36 ~25 ~28 ~66 ~25 ~28 red_nether_brick 0  
fill ~36 ~25 ~74 ~66 ~25 ~74 red_nether_brick 0  
fill ~36 ~25 ~88 ~38 ~25 ~88 red_nether_brick 0  
fill ~37 ~25 ~25 ~38 ~25 ~25 red_nether_brick 0  
fill ~37 ~25 ~77 ~38 ~25 ~77 red_nether_brick 0 
setblock ~38 ~25 ~13 stone_slab 15  
fill ~38 ~25 ~27 ~64 ~25 ~27 red_nether_brick 0  
fill ~38 ~25 ~75 ~64 ~25 ~75 red_nether_brick 0 
setblock ~38 ~25 ~89 stone_slab 15  
fill ~39 ~25 ~13 ~41 ~25 ~13 red_nether_brick 0  
fill ~39 ~25 ~24 ~41 ~25 ~24 red_nether_brick 0  
fill ~39 ~25 ~78 ~41 ~25 ~78 red_nether_brick 0  
fill ~39 ~25 ~89 ~41 ~25 ~89 red_nether_brick 0  
fill ~40 ~25 ~26 ~62 ~25 ~26 red_nether_brick 0  
fill ~40 ~25 ~76 ~62 ~25 ~76 red_nether_brick 0  
fill ~41 ~25 ~23 ~43 ~25 ~23 red_nether_brick 0  
fill ~41 ~25 ~79 ~44 ~25 ~79 red_nether_brick 0  
fill ~42 ~25 ~12 ~52 ~25 ~12 red_nether_brick 0  
fill ~42 ~25 ~90 ~48 ~25 ~90 red_nether_brick 0  
fill ~43 ~25 ~25 ~47 ~25 ~25 red_nether_brick 0  
fill ~43 ~25 ~77 ~49 ~25 ~77 red_nether_brick 0  
fill ~44 ~25 ~22 ~58 ~25 ~22 red_nether_brick 0  
fill ~44 ~25 ~80 ~58 ~25 ~80 red_nether_brick 0  
fill ~45 ~25 ~24 ~47 ~25 ~24 red_nether_brick 0  
fill ~46 ~25 ~78 ~49 ~25 ~78 red_nether_brick 0  
fill ~48 ~25 ~7 ~48 ~29 ~7 red_nether_brick 0  
fill ~48 ~25 ~8 ~48 ~29 ~8 red_nether_brick 0  
fill ~48 ~25 ~11 ~53 ~25 ~11 red_nether_brick 0  
fill ~48 ~25 ~13 ~52 ~25 ~13 red_nether_brick 0  
fill ~48 ~25 ~14 ~52 ~25 ~14 red_nether_brick 0  
fill ~48 ~25 ~15 ~52 ~25 ~15 red_nether_brick 0  
fill ~48 ~25 ~16 ~52 ~25 ~16 red_nether_brick 0  
fill ~48 ~25 ~18 ~52 ~25 ~18 red_nether_brick 0 
setblock ~48 ~25 ~91 stone_slab 15  
fill ~49 ~25 ~91 ~54 ~25 ~91 red_nether_brick 0  
fill ~50 ~25 ~2 ~50 ~27 ~2 red_nether_brick 0  
fill ~50 ~25 ~84 ~54 ~25 ~84 red_nether_brick 0  
fill ~50 ~25 ~86 ~54 ~25 ~86 red_nether_brick 0  
fill ~50 ~25 ~87 ~54 ~25 ~87 red_nether_brick 0  
fill ~50 ~25 ~88 ~54 ~25 ~88 red_nether_brick 0  
fill ~50 ~25 ~89 ~54 ~25 ~89 red_nether_brick 0  
fill ~50 ~25 ~90 ~60 ~25 ~90 red_nether_brick 0  
fill ~50 ~25 ~94 ~50 ~29 ~94 red_nether_brick 0  
fill ~50 ~25 ~95 ~50 ~29 ~95 red_nether_brick 0  
fill ~52 ~25 ~7 ~52 ~29 ~7 red_nether_brick 0  
fill ~52 ~25 ~8 ~52 ~29 ~8 red_nether_brick 0  
fill ~52 ~25 ~100 ~52 ~27 ~100 red_nether_brick 0  
fill ~53 ~25 ~24 ~56 ~25 ~24 red_nether_brick 0  
fill ~53 ~25 ~25 ~59 ~25 ~25 red_nether_brick 0 
setblock ~54 ~25 ~11 stone_slab 15  
fill ~54 ~25 ~12 ~60 ~25 ~12 red_nether_brick 0  
fill ~54 ~25 ~94 ~54 ~29 ~94 red_nether_brick 0  
fill ~54 ~25 ~95 ~54 ~29 ~95 red_nether_brick 0  
fill ~55 ~25 ~77 ~59 ~25 ~77 red_nether_brick 0  
fill ~55 ~25 ~78 ~57 ~25 ~78 red_nether_brick 0  
fill ~58 ~25 ~23 ~61 ~25 ~23 red_nether_brick 0  
fill ~59 ~25 ~79 ~61 ~25 ~79 red_nether_brick 0  
fill ~61 ~25 ~13 ~63 ~25 ~13 red_nether_brick 0  
fill ~61 ~25 ~24 ~63 ~25 ~24 red_nether_brick 0  
fill ~61 ~25 ~78 ~63 ~25 ~78 red_nether_brick 0  
fill ~61 ~25 ~89 ~63 ~25 ~89 red_nether_brick 0 
setblock ~64 ~25 ~13 stone_slab 15  
fill ~64 ~25 ~14 ~66 ~25 ~14 red_nether_brick 0  
fill ~64 ~25 ~25 ~65 ~25 ~25 red_nether_brick 0  
fill ~64 ~25 ~77 ~65 ~25 ~77 red_nether_brick 0  
fill ~64 ~25 ~88 ~66 ~25 ~88 red_nether_brick 0 
setblock ~64 ~25 ~89 stone_slab 15  
fill ~66 ~25 ~26 ~67 ~25 ~26 red_nether_brick 0  
fill ~66 ~25 ~76 ~67 ~25 ~76 red_nether_brick 0  
fill ~67 ~25 ~15 ~68 ~25 ~15 red_nether_brick 0  
fill ~67 ~25 ~87 ~68 ~25 ~87 red_nether_brick 0  
fill ~69 ~25 ~16 ~70 ~25 ~16 red_nether_brick 0  
fill ~69 ~25 ~86 ~70 ~25 ~86 red_nether_brick 0  
fill ~70 ~25 ~28 ~70 ~32 ~28 red_nether_brick 0  
fill ~70 ~25 ~74 ~70 ~32 ~74 red_nether_brick 0  
fill ~71 ~25 ~29 ~71 ~30 ~29 red_nether_brick 0  
fill ~71 ~25 ~73 ~71 ~30 ~73 red_nether_brick 0  
fill ~72 ~25 ~17 ~72 ~32 ~17 red_nether_brick 0  
fill ~72 ~25 ~30 ~72 ~30 ~30 red_nether_brick 0  
fill ~72 ~25 ~72 ~72 ~30 ~72 red_nether_brick 0  
fill ~72 ~25 ~85 ~72 ~32 ~85 red_nether_brick 0  
fill ~73 ~25 ~31 ~73 ~30 ~31 red_nether_brick 0  
fill ~73 ~25 ~71 ~73 ~30 ~71 red_nether_brick 0  
fill ~74 ~25 ~32 ~74 ~32 ~32 red_nether_brick 0  
fill ~74 ~25 ~70 ~74 ~32 ~70 red_nether_brick 0  
fill ~75 ~25 ~19 ~75 ~32 ~19 red_nether_brick 0  
fill ~75 ~25 ~83 ~75 ~32 ~83 red_nether_brick 0  
fill ~78 ~25 ~50 ~100 ~25 ~50 red_nether_brick 0  
fill ~79 ~25 ~41 ~79 ~32 ~41 red_nether_brick 0  
fill ~79 ~25 ~61 ~79 ~32 ~61 red_nether_brick 0  
fill ~80 ~25 ~58 ~80 ~32 ~58 red_nether_brick 0  
fill ~83 ~25 ~27 ~83 ~32 ~27 red_nether_brick 0  
fill ~83 ~25 ~48 ~95 ~25 ~48 red_nether_brick 0  
fill ~83 ~25 ~49 ~99 ~25 ~49 red_nether_brick 0  
fill ~83 ~25 ~51 ~99 ~25 ~51 red_nether_brick 0  
fill ~83 ~25 ~52 ~95 ~25 ~52 red_nether_brick 0  
fill ~83 ~25 ~75 ~83 ~32 ~75 red_nether_brick 0  
fill ~85 ~25 ~30 ~85 ~32 ~30 red_nether_brick 0  
fill ~85 ~25 ~72 ~85 ~32 ~72 red_nether_brick 0  
fill ~88 ~25 ~36 ~88 ~32 ~36 red_nether_brick 0  
fill ~88 ~25 ~66 ~88 ~32 ~66 red_nether_brick 0 
setblock ~89 ~25 ~38 stone_slab 15  
fill ~89 ~25 ~61 ~89 ~26 ~61 red_nether_brick 0  
fill ~89 ~25 ~62 ~89 ~32 ~62 red_nether_brick 0  
fill ~89 ~25 ~63 ~89 ~32 ~63 red_nether_brick 0 
setblock ~89 ~25 ~64 stone_slab 15  
fill ~90 ~25 ~42 ~90 ~32 ~42 red_nether_brick 0  
fill ~90 ~25 ~60 ~90 ~32 ~60 red_nether_brick 0  
fill ~91 ~25 ~53 ~91 ~32 ~53 red_nether_brick 0 
setblock ~91 ~25 ~54 stone_slab 15 
setblock ~4 ~26 ~50 nether_brick_stairs 4  
fill ~5 ~26 ~50 ~22 ~26 ~50 red_nether_brick 0  
fill ~5 ~26 ~54 ~22 ~26 ~54 red_nether_brick 0  
fill ~9 ~26 ~51 ~24 ~26 ~51 red_nether_brick 0  
fill ~9 ~26 ~52 ~24 ~26 ~52 red_nether_brick 0  
fill ~9 ~26 ~53 ~24 ~26 ~53 red_nether_brick 0 
setblock ~11 ~26 ~47 stone_slab 15  
fill ~11 ~26 ~48 ~11 ~32 ~48 red_nether_brick 0 
setblock ~11 ~26 ~55 stone_slab 15 
setblock ~12 ~26 ~41 stone_slab 15 
setblock ~12 ~26 ~61 stone_slab 15  
fill ~13 ~26 ~38 ~13 ~32 ~38 red_nether_brick 0  
fill ~13 ~26 ~64 ~13 ~32 ~64 red_nether_brick 0 
setblock ~15 ~26 ~33 stone_slab 15 
setblock ~15 ~26 ~69 stone_slab 15 
setblock ~18 ~26 ~28 stone_slab 15 
setblock ~18 ~26 ~74 stone_slab 15  
fill ~21 ~26 ~49 ~21 ~32 ~49 red_nether_brick 0  
fill ~22 ~26 ~43 ~22 ~32 ~43 red_nether_brick 0  
fill ~22 ~26 ~59 ~22 ~32 ~59 red_nether_brick 0  
fill ~23 ~26 ~40 ~23 ~32 ~40 red_nether_brick 0  
fill ~23 ~26 ~62 ~23 ~32 ~62 red_nether_brick 0  
fill ~24 ~26 ~38 ~24 ~32 ~38 red_nether_brick 0  
fill ~24 ~26 ~64 ~24 ~32 ~64 red_nether_brick 0  
fill ~25 ~26 ~36 ~25 ~32 ~36 red_nether_brick 0  
fill ~25 ~26 ~66 ~25 ~32 ~66 red_nether_brick 0  
fill ~27 ~26 ~33 ~27 ~32 ~33 red_nether_brick 0  
fill ~27 ~26 ~69 ~27 ~32 ~69 red_nether_brick 0 
setblock ~28 ~26 ~18 stone_slab 15 
setblock ~28 ~26 ~84 stone_slab 15  
fill ~32 ~26 ~16 ~33 ~26 ~16 red_nether_brick 0  
fill ~32 ~26 ~86 ~33 ~26 ~86 red_nether_brick 0 
setblock ~33 ~26 ~15 stone_slab 15  
fill ~33 ~26 ~27 ~33 ~32 ~27 red_nether_brick 0  
fill ~33 ~26 ~75 ~33 ~32 ~75 red_nether_brick 0 
setblock ~33 ~26 ~87 stone_slab 15  
fill ~34 ~26 ~15 ~35 ~26 ~15 red_nether_brick 0  
fill ~34 ~26 ~87 ~35 ~26 ~87 red_nether_brick 0  
fill ~35 ~26 ~26 ~36 ~26 ~26 red_nether_brick 0  
fill ~35 ~26 ~76 ~36 ~26 ~76 red_nether_brick 0  
fill ~36 ~26 ~14 ~37 ~26 ~14 red_nether_brick 0  
fill ~36 ~26 ~25 ~38 ~26 ~25 red_nether_brick 0  
fill ~36 ~26 ~77 ~38 ~26 ~77 red_nether_brick 0  
fill ~36 ~26 ~88 ~37 ~26 ~88 red_nether_brick 0  
fill ~38 ~26 ~13 ~41 ~26 ~13 red_nether_brick 0  
fill ~38 ~26 ~24 ~41 ~26 ~24 red_nether_brick 0  
fill ~38 ~26 ~78 ~41 ~26 ~78 red_nether_brick 0  
fill ~38 ~26 ~89 ~41 ~26 ~89 red_nether_brick 0  
fill ~40 ~26 ~23 ~43 ~26 ~23 red_nether_brick 0  
fill ~40 ~26 ~79 ~44 ~26 ~79 red_nether_brick 0 
setblock ~41 ~26 ~12 stone_slab 15 
setblock ~41 ~26 ~90 stone_slab 15  
fill ~42 ~26 ~12 ~52 ~26 ~12 red_nether_brick 0  
fill ~42 ~26 ~90 ~47 ~26 ~90 red_nether_brick 0  
fill ~43 ~26 ~22 ~59 ~26 ~22 red_nether_brick 0  
fill ~43 ~26 ~80 ~59 ~26 ~80 red_nether_brick 0 
setblock ~47 ~26 ~11 stone_slab 15 
setblock ~47 ~26 ~91 stone_slab 15  
fill ~48 ~26 ~5 ~48 ~27 ~5 red_nether_brick 0  
fill ~48 ~26 ~6 ~48 ~28 ~6 red_nether_brick 0  
fill ~48 ~26 ~11 ~54 ~26 ~11 red_nether_brick 0  
fill ~48 ~26 ~13 ~52 ~26 ~13 red_nether_brick 0  
fill ~48 ~26 ~14 ~52 ~26 ~14 red_nether_brick 0  
fill ~48 ~26 ~15 ~52 ~26 ~15 red_nether_brick 0  
fill ~48 ~26 ~16 ~52 ~26 ~16 red_nether_brick 0  
fill ~48 ~26 ~18 ~52 ~26 ~18 red_nether_brick 0  
fill ~48 ~26 ~91 ~54 ~26 ~91 red_nether_brick 0  
fill ~49 ~26 ~81 ~49 ~32 ~81 red_nether_brick 0  
fill ~50 ~26 ~84 ~54 ~26 ~84 red_nether_brick 0  
fill ~50 ~26 ~86 ~54 ~26 ~86 red_nether_brick 0  
fill ~50 ~26 ~87 ~54 ~26 ~87 red_nether_brick 0  
fill ~50 ~26 ~88 ~54 ~26 ~88 red_nether_brick 0  
fill ~50 ~26 ~89 ~54 ~26 ~89 red_nether_brick 0  
fill ~50 ~26 ~90 ~60 ~26 ~90 red_nether_brick 0  
fill ~50 ~26 ~96 ~50 ~28 ~96 red_nether_brick 0  
fill ~50 ~26 ~97 ~50 ~27 ~97 red_nether_brick 0 
setblock ~50 ~26 ~98 nether_brick_stairs 7 
setblock ~52 ~26 ~4 nether_brick_stairs 6  
fill ~52 ~26 ~5 ~52 ~27 ~5 red_nether_brick 0  
fill ~52 ~26 ~6 ~52 ~28 ~6 red_nether_brick 0  
fill ~53 ~26 ~21 ~53 ~32 ~21 red_nether_brick 0  
fill ~54 ~26 ~96 ~54 ~28 ~96 red_nether_brick 0  
fill ~54 ~26 ~97 ~54 ~27 ~97 red_nether_brick 0 
setblock ~55 ~26 ~11 stone_slab 15  
fill ~55 ~26 ~12 ~60 ~26 ~12 red_nether_brick 0 
setblock ~55 ~26 ~91 stone_slab 15  
fill ~58 ~26 ~23 ~62 ~26 ~23 red_nether_brick 0  
fill ~59 ~26 ~79 ~62 ~26 ~79 red_nether_brick 0 
setblock ~61 ~26 ~12 stone_slab 15  
fill ~61 ~26 ~13 ~64 ~26 ~13 red_nether_brick 0  
fill ~61 ~26 ~24 ~64 ~26 ~24 red_nether_brick 0  
fill ~61 ~26 ~78 ~64 ~26 ~78 red_nether_brick 0  
fill ~61 ~26 ~89 ~64 ~26 ~89 red_nether_brick 0 
setblock ~61 ~26 ~90 stone_slab 15  
fill ~64 ~26 ~25 ~66 ~26 ~25 red_nether_brick 0  
fill ~64 ~26 ~77 ~66 ~26 ~77 red_nether_brick 0  
fill ~65 ~26 ~14 ~66 ~26 ~14 red_nether_brick 0  
fill ~65 ~26 ~88 ~66 ~26 ~88 red_nether_brick 0  
fill ~66 ~26 ~26 ~67 ~26 ~26 red_nether_brick 0  
fill ~66 ~26 ~76 ~67 ~26 ~76 red_nether_brick 0  
fill ~67 ~26 ~15 ~68 ~26 ~15 red_nether_brick 0  
fill ~67 ~26 ~87 ~68 ~26 ~87 red_nether_brick 0 
setblock ~69 ~26 ~15 stone_slab 15  
fill ~69 ~26 ~16 ~70 ~26 ~16 red_nether_brick 0  
fill ~69 ~26 ~27 ~69 ~32 ~27 red_nether_brick 0  
fill ~69 ~26 ~75 ~69 ~32 ~75 red_nether_brick 0  
fill ~69 ~26 ~86 ~70 ~26 ~86 red_nether_brick 0 
setblock ~69 ~26 ~87 stone_slab 15 
setblock ~74 ~26 ~18 stone_slab 15 
setblock ~74 ~26 ~84 stone_slab 15  
fill ~75 ~26 ~33 ~75 ~32 ~33 red_nether_brick 0  
fill ~75 ~26 ~69 ~75 ~32 ~69 red_nether_brick 0  
fill ~77 ~26 ~36 ~77 ~32 ~36 red_nether_brick 0  
fill ~77 ~26 ~66 ~77 ~32 ~66 red_nether_brick 0  
fill ~78 ~26 ~38 ~78 ~32 ~38 red_nether_brick 0  
fill ~78 ~26 ~50 ~100 ~26 ~50 red_nether_brick 0  
fill ~78 ~26 ~64 ~78 ~32 ~64 red_nether_brick 0  
fill ~79 ~26 ~40 ~79 ~32 ~40 red_nether_brick 0  
fill ~79 ~26 ~62 ~79 ~32 ~62 red_nether_brick 0  
fill ~80 ~26 ~43 ~80 ~32 ~43 red_nether_brick 0  
fill ~80 ~26 ~59 ~80 ~32 ~59 red_nether_brick 0  
fill ~81 ~26 ~53 ~81 ~32 ~53 red_nether_brick 0  
fill ~83 ~26 ~48 ~97 ~26 ~48 red_nether_brick 0  
fill ~83 ~26 ~49 ~99 ~26 ~49 red_nether_brick 0  
fill ~83 ~26 ~51 ~99 ~26 ~51 red_nether_brick 0  
fill ~83 ~26 ~52 ~97 ~26 ~52 red_nether_brick 0 
setblock ~84 ~26 ~28 stone_slab 15 
setblock ~84 ~26 ~74 stone_slab 15 
setblock ~87 ~26 ~33 stone_slab 15 
setblock ~87 ~26 ~69 stone_slab 15  
fill ~89 ~26 ~38 ~89 ~32 ~38 red_nether_brick 0  
fill ~89 ~26 ~64 ~89 ~32 ~64 red_nether_brick 0 
setblock ~90 ~26 ~41 stone_slab 15 
setblock ~90 ~26 ~61 stone_slab 15 
setblock ~91 ~26 ~47 stone_slab 15  
fill ~91 ~26 ~54 ~91 ~32 ~54 red_nether_brick 0 
setblock ~91 ~26 ~55 stone_slab 15 
setblock ~98 ~26 ~52 nether_brick_stairs 5 
setblock ~2 ~27 ~45 nether_brick_stairs 4 
setblock ~2 ~27 ~57 nether_brick_stairs 4 
setblock ~4 ~27 ~50 nether_brick_stairs 0  
fill ~5 ~27 ~50 ~22 ~27 ~50 red_nether_brick 0  
fill ~5 ~27 ~54 ~22 ~27 ~54 red_nether_brick 0  
fill ~9 ~27 ~51 ~24 ~27 ~51 red_nether_brick 0  
fill ~9 ~27 ~52 ~24 ~27 ~52 red_nether_brick 0  
fill ~9 ~27 ~53 ~24 ~27 ~53 red_nether_brick 0 
setblock ~11 ~27 ~46 stone_slab 15  
fill ~11 ~27 ~47 ~11 ~32 ~47 red_nether_brick 0  
fill ~11 ~27 ~55 ~11 ~32 ~55 red_nether_brick 0 
setblock ~11 ~27 ~56 stone_slab 15  
fill ~12 ~27 ~41 ~12 ~32 ~41 red_nether_brick 0  
fill ~12 ~27 ~61 ~12 ~32 ~61 red_nether_brick 0 
setblock ~14 ~27 ~35 stone_slab 15 
setblock ~14 ~27 ~67 stone_slab 15  
fill ~15 ~27 ~33 ~15 ~32 ~33 red_nether_brick 0  
fill ~15 ~27 ~69 ~15 ~32 ~69 red_nether_brick 0 
setblock ~16 ~27 ~31 stone_slab 15 
setblock ~16 ~27 ~71 stone_slab 15  
fill ~18 ~27 ~28 ~18 ~32 ~28 red_nether_brick 0  
fill ~18 ~27 ~74 ~18 ~32 ~74 red_nether_brick 0 
setblock ~21 ~27 ~24 stone_slab 15  
fill ~21 ~27 ~48 ~21 ~32 ~48 red_nether_brick 0 
setblock ~21 ~27 ~78 stone_slab 15 
setblock ~22 ~27 ~23 stone_slab 15 
setblock ~22 ~27 ~79 stone_slab 15 
setblock ~23 ~27 ~22 stone_slab 15 
setblock ~23 ~27 ~80 stone_slab 15 
setblock ~24 ~27 ~21 stone_slab 15 
setblock ~24 ~27 ~81 stone_slab 15  
fill ~26 ~27 ~34 ~26 ~32 ~34 red_nether_brick 0  
fill ~26 ~27 ~68 ~26 ~32 ~68 red_nether_brick 0  
fill ~28 ~27 ~18 ~28 ~32 ~18 red_nether_brick 0  
fill ~28 ~27 ~84 ~28 ~32 ~84 red_nether_brick 0 
setblock ~31 ~27 ~16 stone_slab 15 
setblock ~31 ~27 ~86 stone_slab 15  
fill ~32 ~27 ~16 ~32 ~32 ~16 red_nether_brick 0  
fill ~32 ~27 ~86 ~32 ~32 ~86 red_nether_brick 0  
fill ~33 ~27 ~15 ~35 ~27 ~15 red_nether_brick 0  
fill ~33 ~27 ~87 ~35 ~27 ~87 red_nether_brick 0  
fill ~34 ~27 ~26 ~36 ~27 ~26 red_nether_brick 0  
fill ~34 ~27 ~76 ~36 ~27 ~76 red_nether_brick 0 
setblock ~35 ~27 ~14 stone_slab 15 
setblock ~35 ~27 ~88 stone_slab 15  
fill ~36 ~27 ~14 ~37 ~27 ~14 red_nether_brick 0  
fill ~36 ~27 ~25 ~38 ~27 ~25 red_nether_brick 0  
fill ~36 ~27 ~77 ~38 ~27 ~77 red_nether_brick 0  
fill ~36 ~27 ~88 ~37 ~27 ~88 red_nether_brick 0  
fill ~38 ~27 ~13 ~40 ~27 ~13 red_nether_brick 0  
fill ~38 ~27 ~24 ~41 ~27 ~24 red_nether_brick 0  
fill ~38 ~27 ~78 ~41 ~27 ~78 red_nether_brick 0  
fill ~38 ~27 ~89 ~40 ~27 ~89 red_nether_brick 0  
fill ~40 ~27 ~23 ~43 ~27 ~23 red_nether_brick 0  
fill ~40 ~27 ~79 ~44 ~27 ~79 red_nether_brick 0  
fill ~41 ~27 ~12 ~46 ~27 ~12 red_nether_brick 0  
fill ~41 ~27 ~90 ~46 ~27 ~90 red_nether_brick 0  
fill ~43 ~27 ~22 ~59 ~27 ~22 red_nether_brick 0  
fill ~43 ~27 ~80 ~59 ~27 ~80 red_nether_brick 0 
setblock ~45 ~27 ~2 nether_brick_stairs 6 
setblock ~45 ~27 ~100 nether_brick_stairs 7 
setblock ~46 ~27 ~11 stone_slab 15 
setblock ~46 ~27 ~91 stone_slab 15  
fill ~47 ~27 ~11 ~55 ~27 ~11 red_nether_brick 0  
fill ~47 ~27 ~91 ~55 ~27 ~91 red_nether_brick 0  
fill ~48 ~27 ~12 ~52 ~27 ~12 red_nether_brick 0  
fill ~48 ~27 ~13 ~52 ~27 ~13 red_nether_brick 0  
fill ~48 ~27 ~14 ~52 ~27 ~14 red_nether_brick 0  
fill ~48 ~27 ~15 ~52 ~27 ~15 red_nether_brick 0  
fill ~48 ~27 ~16 ~52 ~27 ~16 red_nether_brick 0  
fill ~48 ~27 ~18 ~52 ~27 ~18 red_nether_brick 0  
fill ~48 ~27 ~81 ~48 ~32 ~81 red_nether_brick 0  
fill ~50 ~27 ~84 ~54 ~27 ~84 red_nether_brick 0  
fill ~50 ~27 ~86 ~54 ~27 ~86 red_nether_brick 0  
fill ~50 ~27 ~87 ~54 ~27 ~87 red_nether_brick 0  
fill ~50 ~27 ~88 ~54 ~27 ~88 red_nether_brick 0  
fill ~50 ~27 ~89 ~54 ~27 ~89 red_nether_brick 0  
fill ~50 ~27 ~90 ~54 ~27 ~90 red_nether_brick 0 
setblock ~50 ~27 ~98 nether_brick_stairs 3 
setblock ~52 ~27 ~4 nether_brick_stairs 2  
fill ~54 ~27 ~21 ~54 ~32 ~21 red_nether_brick 0 
setblock ~56 ~27 ~11 stone_slab 15  
fill ~56 ~27 ~12 ~61 ~27 ~12 red_nether_brick 0  
fill ~56 ~27 ~90 ~61 ~27 ~90 red_nether_brick 0 
setblock ~56 ~27 ~91 stone_slab 15 
setblock ~57 ~27 ~2 nether_brick_stairs 6 
setblock ~57 ~27 ~100 nether_brick_stairs 7  
fill ~58 ~27 ~23 ~62 ~27 ~23 red_nether_brick 0  
fill ~59 ~27 ~79 ~62 ~27 ~79 red_nether_brick 0  
fill ~61 ~27 ~24 ~64 ~27 ~24 red_nether_brick 0  
fill ~61 ~27 ~78 ~64 ~27 ~78 red_nether_brick 0  
fill ~62 ~27 ~13 ~64 ~27 ~13 red_nether_brick 0  
fill ~62 ~27 ~89 ~64 ~27 ~89 red_nether_brick 0  
fill ~64 ~27 ~25 ~66 ~27 ~25 red_nether_brick 0  
fill ~64 ~27 ~77 ~66 ~27 ~77 red_nether_brick 0  
fill ~65 ~27 ~14 ~66 ~27 ~14 red_nether_brick 0  
fill ~65 ~27 ~88 ~66 ~27 ~88 red_nether_brick 0  
fill ~66 ~27 ~26 ~68 ~27 ~26 red_nether_brick 0  
fill ~66 ~27 ~76 ~68 ~27 ~76 red_nether_brick 0 
setblock ~67 ~27 ~14 stone_slab 15  
fill ~67 ~27 ~15 ~69 ~27 ~15 red_nether_brick 0  
fill ~67 ~27 ~87 ~69 ~27 ~87 red_nether_brick 0 
setblock ~67 ~27 ~88 stone_slab 15  
fill ~70 ~27 ~16 ~70 ~32 ~16 red_nether_brick 0  
fill ~70 ~27 ~86 ~70 ~32 ~86 red_nether_brick 0 
setblock ~71 ~27 ~16 stone_slab 15 
setblock ~71 ~27 ~86 stone_slab 15  
fill ~74 ~27 ~18 ~74 ~32 ~18 red_nether_brick 0  
fill ~74 ~27 ~84 ~74 ~32 ~84 red_nether_brick 0  
fill ~76 ~27 ~34 ~76 ~32 ~34 red_nether_brick 0  
fill ~76 ~27 ~68 ~76 ~32 ~68 red_nether_brick 0 
setblock ~78 ~27 ~21 stone_slab 15  
fill ~78 ~27 ~50 ~100 ~27 ~50 red_nether_brick 0 
setblock ~78 ~27 ~81 stone_slab 15 
setblock ~79 ~27 ~22 stone_slab 15 
setblock ~79 ~27 ~80 stone_slab 15 
setblock ~80 ~27 ~23 stone_slab 15 
setblock ~80 ~27 ~79 stone_slab 15 
setblock ~81 ~27 ~24 stone_slab 15  
fill ~81 ~27 ~54 ~81 ~32 ~54 red_nether_brick 0 
setblock ~81 ~27 ~78 stone_slab 15  
fill ~83 ~27 ~48 ~97 ~27 ~48 red_nether_brick 0  
fill ~83 ~27 ~49 ~99 ~27 ~49 red_nether_brick 0  
fill ~83 ~27 ~51 ~99 ~27 ~51 red_nether_brick 0  
fill ~83 ~27 ~52 ~97 ~27 ~52 red_nether_brick 0  
fill ~84 ~27 ~28 ~84 ~32 ~28 red_nether_brick 0  
fill ~84 ~27 ~74 ~84 ~32 ~74 red_nether_brick 0 
setblock ~86 ~27 ~31 stone_slab 15 
setblock ~86 ~27 ~71 stone_slab 15  
fill ~87 ~27 ~33 ~87 ~32 ~33 red_nether_brick 0  
fill ~87 ~27 ~69 ~87 ~32 ~69 red_nether_brick 0 
setblock ~88 ~27 ~35 stone_slab 15 
setblock ~88 ~27 ~67 stone_slab 15  
fill ~90 ~27 ~41 ~90 ~32 ~41 red_nether_brick 0  
fill ~90 ~27 ~61 ~90 ~32 ~61 red_nether_brick 0 
setblock ~91 ~27 ~46 stone_slab 15  
fill ~91 ~27 ~47 ~91 ~32 ~47 red_nether_brick 0  
fill ~91 ~27 ~55 ~91 ~32 ~55 red_nether_brick 0 
setblock ~91 ~27 ~56 stone_slab 15 
setblock ~98 ~27 ~52 nether_brick_stairs 1 
setblock ~100 ~27 ~45 nether_brick_stairs 5 
setblock ~100 ~27 ~57 nether_brick_stairs 5  
fill ~1 ~28 ~45 ~1 ~36 ~45 stone_slab 7  
fill ~1 ~28 ~57 ~1 ~36 ~57 stone_slab 7  
fill ~2 ~28 ~45 ~2 ~36 ~45 red_nether_brick 0 
setblock ~2 ~28 ~52 nether_brick_stairs 0  
fill ~2 ~28 ~57 ~2 ~36 ~57 red_nether_brick 0 
setblock ~5 ~28 ~50 nether_brick_stairs 0 
setblock ~5 ~28 ~54 nether_brick_stairs 0  
fill ~6 ~28 ~50 ~22 ~28 ~50 red_nether_brick 0  
fill ~6 ~28 ~54 ~22 ~28 ~54 red_nether_brick 0  
fill ~9 ~28 ~51 ~24 ~28 ~51 red_nether_brick 0  
fill ~9 ~28 ~52 ~24 ~28 ~52 red_nether_brick 0  
fill ~9 ~28 ~53 ~24 ~28 ~53 red_nether_brick 0 
setblock ~11 ~28 ~45 stone_slab 15  
fill ~11 ~28 ~46 ~11 ~32 ~46 red_nether_brick 0  
fill ~11 ~28 ~56 ~11 ~32 ~56 red_nether_brick 0 
setblock ~11 ~28 ~57 stone_slab 15  
fill ~14 ~28 ~35 ~14 ~32 ~35 red_nether_brick 0  
fill ~14 ~28 ~67 ~14 ~32 ~67 red_nether_brick 0  
fill ~16 ~28 ~31 ~16 ~32 ~31 red_nether_brick 0  
fill ~16 ~28 ~71 ~16 ~32 ~71 red_nether_brick 0  
fill ~21 ~28 ~24 ~21 ~32 ~24 red_nether_brick 0  
fill ~21 ~28 ~47 ~21 ~32 ~47 red_nether_brick 0  
fill ~21 ~28 ~55 ~21 ~32 ~55 red_nether_brick 0  
fill ~21 ~28 ~78 ~21 ~32 ~78 red_nether_brick 0  
fill ~22 ~28 ~23 ~22 ~32 ~23 red_nether_brick 0  
fill ~22 ~28 ~79 ~22 ~32 ~79 red_nether_brick 0  
fill ~23 ~28 ~22 ~23 ~32 ~22 red_nether_brick 0 
setblock ~23 ~28 ~50 nether_brick_stairs 5 
setblock ~23 ~28 ~54 nether_brick_stairs 5  
fill ~23 ~28 ~80 ~23 ~32 ~80 red_nether_brick 0  
fill ~24 ~28 ~21 ~24 ~32 ~21 red_nether_brick 0  
fill ~24 ~28 ~81 ~24 ~32 ~81 red_nether_brick 0 
setblock ~25 ~28 ~52 nether_brick_stairs 5  
fill ~31 ~28 ~16 ~31 ~32 ~16 red_nether_brick 0  
fill ~31 ~28 ~86 ~31 ~32 ~86 red_nether_brick 0  
fill ~33 ~28 ~15 ~34 ~28 ~15 red_nether_brick 0  
fill ~33 ~28 ~87 ~34 ~28 ~87 red_nether_brick 0  
fill ~34 ~28 ~26 ~36 ~28 ~26 red_nether_brick 0  
fill ~34 ~28 ~76 ~36 ~28 ~76 red_nether_brick 0  
fill ~35 ~28 ~14 ~37 ~28 ~14 red_nether_brick 0  
fill ~35 ~28 ~88 ~37 ~28 ~88 red_nether_brick 0  
fill ~36 ~28 ~25 ~38 ~28 ~25 red_nether_brick 0  
fill ~36 ~28 ~77 ~38 ~28 ~77 red_nether_brick 0  
fill ~38 ~28 ~13 ~40 ~28 ~13 red_nether_brick 0  
fill ~38 ~28 ~24 ~41 ~28 ~24 red_nether_brick 0  
fill ~38 ~28 ~78 ~41 ~28 ~78 red_nether_brick 0  
fill ~38 ~28 ~89 ~40 ~28 ~89 red_nether_brick 0  
fill ~40 ~28 ~23 ~43 ~28 ~23 red_nether_brick 0  
fill ~40 ~28 ~79 ~44 ~28 ~79 red_nether_brick 0  
fill ~41 ~28 ~12 ~45 ~28 ~12 red_nether_brick 0  
fill ~41 ~28 ~90 ~45 ~28 ~90 red_nether_brick 0  
fill ~43 ~28 ~22 ~59 ~28 ~22 red_nether_brick 0  
fill ~43 ~28 ~80 ~59 ~28 ~80 red_nether_brick 0  
fill ~45 ~28 ~1 ~45 ~36 ~1 stone_slab 7  
fill ~45 ~28 ~2 ~45 ~36 ~2 red_nether_brick 0 
setblock ~45 ~28 ~11 stone_slab 15 
setblock ~45 ~28 ~91 stone_slab 15  
fill ~45 ~28 ~100 ~45 ~36 ~100 red_nether_brick 0  
fill ~45 ~28 ~101 ~45 ~36 ~101 stone_slab 7  
fill ~46 ~28 ~11 ~56 ~28 ~11 red_nether_brick 0  
fill ~46 ~28 ~91 ~56 ~28 ~91 red_nether_brick 0  
fill ~47 ~28 ~21 ~47 ~32 ~21 red_nether_brick 0  
fill ~47 ~28 ~81 ~47 ~32 ~81 red_nether_brick 0   

KittysCommands:  
setblock ~48 ~28 ~5 nether_brick_stairs 2  
fill ~48 ~28 ~12 ~52 ~28 ~12 red_nether_brick 0  
fill ~48 ~28 ~13 ~52 ~28 ~13 red_nether_brick 0  
fill ~48 ~28 ~14 ~52 ~28 ~14 red_nether_brick 0  
fill ~48 ~28 ~15 ~52 ~28 ~15 red_nether_brick 0  
fill ~48 ~28 ~16 ~52 ~28 ~16 red_nether_brick 0  
fill ~48 ~28 ~18 ~52 ~28 ~18 red_nether_brick 0 
setblock ~48 ~28 ~23 nether_brick_stairs 7 
setblock ~50 ~28 ~2 nether_brick_stairs 2 
setblock ~50 ~28 ~25 nether_brick_stairs 7 
setblock ~50 ~28 ~79 nether_brick_stairs 6  
fill ~50 ~28 ~84 ~54 ~28 ~84 red_nether_brick 0  
fill ~50 ~28 ~86 ~54 ~28 ~86 red_nether_brick 0  
fill ~50 ~28 ~87 ~54 ~28 ~87 red_nether_brick 0  
fill ~50 ~28 ~88 ~54 ~28 ~88 red_nether_brick 0  
fill ~50 ~28 ~89 ~54 ~28 ~89 red_nether_brick 0  
fill ~50 ~28 ~90 ~54 ~28 ~90 red_nether_brick 0 
setblock ~50 ~28 ~97 nether_brick_stairs 3 
setblock ~52 ~28 ~5 nether_brick_stairs 2 
setblock ~52 ~28 ~23 nether_brick_stairs 7 
setblock ~52 ~28 ~77 nether_brick_stairs 6 
setblock ~52 ~28 ~100 nether_brick_stairs 3 
setblock ~54 ~28 ~79 nether_brick_stairs 6 
setblock ~54 ~28 ~97 nether_brick_stairs 3  
fill ~55 ~28 ~21 ~55 ~32 ~21 red_nether_brick 0  
fill ~55 ~28 ~81 ~55 ~32 ~81 red_nether_brick 0  
fill ~57 ~28 ~1 ~57 ~36 ~1 stone_slab 7  
fill ~57 ~28 ~2 ~57 ~36 ~2 red_nether_brick 0 
setblock ~57 ~28 ~11 stone_slab 15  
fill ~57 ~28 ~12 ~61 ~28 ~12 red_nether_brick 0  
fill ~57 ~28 ~90 ~61 ~28 ~90 red_nether_brick 0 
setblock ~57 ~28 ~91 stone_slab 15  
fill ~57 ~28 ~100 ~57 ~36 ~100 red_nether_brick 0  
fill ~57 ~28 ~101 ~57 ~36 ~101 stone_slab 7  
fill ~58 ~28 ~23 ~62 ~28 ~23 red_nether_brick 0  
fill ~59 ~28 ~79 ~62 ~28 ~79 red_nether_brick 0  
fill ~61 ~28 ~24 ~64 ~28 ~24 red_nether_brick 0  
fill ~61 ~28 ~78 ~64 ~28 ~78 red_nether_brick 0  
fill ~62 ~28 ~13 ~64 ~28 ~13 red_nether_brick 0  
fill ~62 ~28 ~89 ~64 ~28 ~89 red_nether_brick 0  
fill ~64 ~28 ~25 ~66 ~28 ~25 red_nether_brick 0  
fill ~64 ~28 ~77 ~66 ~28 ~77 red_nether_brick 0  
fill ~65 ~28 ~14 ~67 ~28 ~14 red_nether_brick 0  
fill ~65 ~28 ~88 ~67 ~28 ~88 red_nether_brick 0  
fill ~66 ~28 ~26 ~68 ~28 ~26 red_nether_brick 0  
fill ~66 ~28 ~76 ~68 ~28 ~76 red_nether_brick 0  
fill ~68 ~28 ~15 ~69 ~28 ~15 red_nether_brick 0  
fill ~68 ~28 ~87 ~69 ~28 ~87 red_nether_brick 0  
fill ~71 ~28 ~16 ~71 ~32 ~16 red_nether_brick 0  
fill ~71 ~28 ~86 ~71 ~32 ~86 red_nether_brick 0 
setblock ~77 ~28 ~50 nether_brick_stairs 4  
fill ~78 ~28 ~21 ~78 ~32 ~21 red_nether_brick 0  
fill ~78 ~28 ~50 ~99 ~28 ~50 red_nether_brick 0  
fill ~78 ~28 ~81 ~78 ~32 ~81 red_nether_brick 0  
fill ~79 ~28 ~22 ~79 ~32 ~22 red_nether_brick 0 
setblock ~79 ~28 ~48 nether_brick_stairs 4 
setblock ~79 ~28 ~52 nether_brick_stairs 4  
fill ~79 ~28 ~80 ~79 ~32 ~80 red_nether_brick 0  
fill ~80 ~28 ~23 ~80 ~32 ~23 red_nether_brick 0  
fill ~80 ~28 ~79 ~80 ~32 ~79 red_nether_brick 0  
fill ~81 ~28 ~24 ~81 ~32 ~24 red_nether_brick 0  
fill ~81 ~28 ~47 ~81 ~32 ~47 red_nether_brick 0  
fill ~81 ~28 ~55 ~81 ~32 ~55 red_nether_brick 0  
fill ~81 ~28 ~78 ~81 ~32 ~78 red_nether_brick 0  
fill ~83 ~28 ~48 ~96 ~28 ~48 red_nether_brick 0  
fill ~83 ~28 ~49 ~99 ~28 ~49 red_nether_brick 0  
fill ~83 ~28 ~51 ~99 ~28 ~51 red_nether_brick 0  
fill ~83 ~28 ~52 ~96 ~28 ~52 red_nether_brick 0  
fill ~86 ~28 ~31 ~86 ~32 ~31 red_nether_brick 0  
fill ~86 ~28 ~71 ~86 ~32 ~71 red_nether_brick 0  
fill ~88 ~28 ~35 ~88 ~32 ~35 red_nether_brick 0  
fill ~88 ~28 ~67 ~88 ~32 ~67 red_nether_brick 0 
setblock ~91 ~28 ~45 stone_slab 15  
fill ~91 ~28 ~46 ~91 ~32 ~46 red_nether_brick 0  
fill ~91 ~28 ~56 ~91 ~32 ~56 red_nether_brick 0 
setblock ~91 ~28 ~57 stone_slab 15 
setblock ~97 ~28 ~48 nether_brick_stairs 1 
setblock ~97 ~28 ~52 nether_brick_stairs 1  
fill ~100 ~28 ~45 ~100 ~36 ~45 red_nether_brick 0 
setblock ~100 ~28 ~50 nether_brick_stairs 1  
fill ~100 ~28 ~57 ~100 ~36 ~57 red_nether_brick 0  
fill ~101 ~28 ~45 ~101 ~36 ~45 stone_slab 7  
fill ~101 ~28 ~57 ~101 ~36 ~57 stone_slab 7 
setblock ~3 ~29 ~45 nether_brick_stairs 1 
setblock ~3 ~29 ~51 nether_brick_stairs 0 
setblock ~3 ~29 ~53 nether_brick_stairs 0 
setblock ~3 ~29 ~57 nether_brick_stairs 1 
setblock ~6 ~29 ~50 nether_brick_stairs 0 
setblock ~6 ~29 ~54 nether_brick_stairs 0  
fill ~7 ~29 ~50 ~23 ~29 ~50 red_nether_brick 0  
fill ~7 ~29 ~54 ~23 ~29 ~54 red_nether_brick 0  
fill ~9 ~29 ~51 ~24 ~29 ~51 red_nether_brick 0  
fill ~9 ~29 ~52 ~25 ~29 ~52 red_nether_brick 0  
fill ~9 ~29 ~53 ~24 ~29 ~53 red_nether_brick 0  
fill ~11 ~29 ~45 ~11 ~32 ~45 red_nether_brick 0  
fill ~11 ~29 ~57 ~11 ~32 ~57 red_nether_brick 0 
setblock ~20 ~29 ~25 stone_slab 15 
setblock ~20 ~29 ~77 stone_slab 15  
fill ~21 ~29 ~46 ~21 ~32 ~46 red_nether_brick 0  
