setblock ~19 ~0 ~18 chest 2  
setblock ~20 ~0 ~18 chest 2  
setblock ~18 ~0 ~19 chest 4  
setblock ~18 ~0 ~20 chest 4  
setblock ~27 ~0 ~20 chest 4  
setblock ~27 ~0 ~21 chest 4  
setblock ~20 ~23 ~21 chest 4  
setblock ~25 ~23 ~21 chest 2  
setblock ~26 ~23 ~21 chest 2  
setblock ~25 ~24 ~21 chest 2  
setblock ~26 ~24 ~21 chest 2  
setblock ~26 ~36 ~21 chest 3  
setblock ~27 ~36 ~21 chest 3  
setblock ~22 ~60 ~21 chest 3  
setblock ~20 ~23 ~22 chest 4  
setblock ~24 ~42 ~22 chest 3  
setblock ~25 ~42 ~22 chest 3  
setblock ~27 ~42 ~22 chest 5  
setblock ~24 ~44 ~22 chest 5  
setblock ~27 ~42 ~23 chest 5  
setblock ~24 ~44 ~23 chest 5  
setblock ~24 ~18 ~24 chest 2  
setblock ~23 ~54 ~24 chest 5  
setblock ~21 ~36 ~25 chest 3  
setblock ~22 ~36 ~25 chest 3  
setblock ~24 ~42 ~25 chest 5  
setblock ~24 ~48 ~25 chest 3  
setblock ~25 ~48 ~25 chest 3  
setblock ~27 ~48 ~25 chest 3  
setblock ~24 ~49 ~25 chest 3  
setblock ~25 ~49 ~25 chest 3  
setblock ~24 ~50 ~25 chest 3  
setblock ~25 ~50 ~25 chest 3  
setblock ~24 ~51 ~25 chest 3  
setblock ~25 ~51 ~25 chest 3  
setblock ~27 ~57 ~25 chest 5  
setblock ~19 ~7 ~26 chest 4  
setblock ~25 ~7 ~26 chest 3  
setblock ~25 ~18 ~26 chest 5  
setblock ~20 ~23 ~26 chest 4  
setblock ~24 ~42 ~26 chest 5  
setblock ~27 ~57 ~26 chest 5  
setblock ~19 ~7 ~27 chest 4  
setblock ~25 ~18 ~27 chest 5  
setblock ~20 ~23 ~27 chest 4  
setblock ~30 ~23 ~18 chest 3  
setblock ~31 ~23 ~18 chest 3  
setblock ~29 ~48 ~24 chest 4  
setblock ~28 ~36 ~25 chest 5  
setblock ~29 ~55 ~25 chest 4  
setblock ~28 ~56 ~25 chest 4  
setblock ~28 ~28 ~26 chest 3  
setblock ~29 ~28 ~26 chest 3  
setblock ~28 ~36 ~26 chest 5  
setblock ~29 ~48 ~26 chest 3  
setblock ~29 ~55 ~26 chest 4  
setblock ~28 ~56 ~26 chest 4  
setblock ~26 ~36 ~28 chest 4  
setblock ~26 ~37 ~28 chest 4  
setblock ~26 ~38 ~28 chest 4  
setblock ~26 ~39 ~28 chest 4  
setblock ~23 ~54 ~28 chest 4  
setblock ~25 ~60 ~28 chest 3  
setblock ~26 ~60 ~28 chest 3  
setblock ~23 ~7 ~29 chest 5  
setblock ~26 ~36 ~29 chest 4  
setblock ~26 ~37 ~29 chest 4  
setblock ~26 ~38 ~29 chest 4  
setblock ~26 ~39 ~29 chest 4  
setblock ~23 ~7 ~30 chest 5  
setblock ~25 ~48 ~30 chest 5  
setblock ~25 ~36 ~31 chest 4  
setblock ~25 ~48 ~31 chest 5  
setblock ~25 ~36 ~32 chest 4  
setblock ~20 ~12 ~34 chest 2  
setblock ~28 ~38 ~28 chest 3  
setblock ~29 ~38 ~28 chest 3  
setblock ~31 ~48 ~28 chest 4  
setblock ~30 ~12 ~29 chest 5  
setblock ~30 ~13 ~29 chest 5  
setblock ~28 ~39 ~29 chest 3  
setblock ~29 ~39 ~29 chest 3  
setblock ~28 ~60 ~29 chest 2  
setblock ~30 ~12 ~30 chest 5  
setblock ~30 ~13 ~30 chest 5  
setblock ~28 ~28 ~30 chest 5  
setblock ~28 ~42 ~32 chest 2  
setblock ~29 ~42 ~32 chest 2  
setblock ~31 ~0 ~33 chest 5  
setblock ~31 ~1 ~33 chest 5  
setblock ~31 ~0 ~34 chest 5  
setblock ~31 ~1 ~34 chest 5  
setblock ~33 ~18 ~29 chest 4  
fill ~1 ~-2 ~1 ~50 ~-2 ~1 dirt 0  
fill ~1 ~-2 ~2 ~50 ~-2 ~2 dirt 0  
fill ~1 ~-2 ~3 ~50 ~-2 ~3 dirt 0  
fill ~1 ~-2 ~4 ~50 ~-2 ~4 dirt 0  
fill ~1 ~-2 ~5 ~50 ~-2 ~5 dirt 0  
fill ~1 ~-2 ~6 ~50 ~-2 ~6 dirt 0  
fill ~1 ~-2 ~7 ~50 ~-2 ~7 dirt 0  
fill ~1 ~-2 ~8 ~50 ~-2 ~8 dirt 0  
fill ~1 ~-2 ~9 ~50 ~-2 ~9 dirt 0  
fill ~1 ~-2 ~10 ~50 ~-2 ~10 dirt 0  
fill ~1 ~-2 ~11 ~50 ~-2 ~11 dirt 0  
fill ~1 ~-2 ~12 ~50 ~-2 ~12 dirt 0  
fill ~1 ~-2 ~13 ~50 ~-2 ~13 dirt 0  
fill ~1 ~-2 ~14 ~50 ~-2 ~14 dirt 0  
fill ~1 ~-2 ~15 ~50 ~-2 ~15 dirt 0  
fill ~1 ~-2 ~16 ~50 ~-2 ~16 dirt 0  
fill ~1 ~-2 ~17 ~50 ~-2 ~17 dirt 0  
fill ~1 ~-2 ~18 ~50 ~-2 ~18 dirt 0  
fill ~1 ~-2 ~19 ~24 ~-2 ~19 dirt 0  
fill ~1 ~-2 ~20 ~23 ~-2 ~20 dirt 0  
fill ~1 ~-2 ~21 ~23 ~-2 ~21 dirt 0  
fill ~1 ~-2 ~22 ~23 ~-2 ~22 dirt 0  
fill ~1 ~-2 ~23 ~23 ~-2 ~23 dirt 0  
fill ~1 ~-2 ~24 ~23 ~-2 ~24 dirt 0  
fill ~1 ~-2 ~25 ~24 ~-2 ~25 dirt 0  
fill ~1 ~-2 ~26 ~50 ~-2 ~26 dirt 0  
fill ~1 ~-2 ~27 ~50 ~-2 ~27 dirt 0  
fill ~1 ~-2 ~28 ~50 ~-2 ~28 dirt 0  
fill ~1 ~-2 ~29 ~50 ~-2 ~29 dirt 0  
fill ~1 ~-2 ~30 ~50 ~-2 ~30 dirt 0  
fill ~1 ~-2 ~31 ~50 ~-2 ~31 dirt 0  
fill ~1 ~-2 ~32 ~50 ~-2 ~32 dirt 0  
fill ~1 ~-2 ~33 ~50 ~-2 ~33 dirt 0  
fill ~1 ~-2 ~34 ~50 ~-2 ~34 dirt 0  
fill ~1 ~-2 ~35 ~7 ~-2 ~35 dirt 0  
fill ~1 ~-2 ~36 ~7 ~-2 ~36 dirt 0  
fill ~1 ~-2 ~37 ~7 ~-2 ~37 dirt 0  
fill ~1 ~-2 ~38 ~7 ~-2 ~38 dirt 0  
fill ~1 ~-2 ~39 ~7 ~-2 ~39 dirt 0  
fill ~1 ~-2 ~40 ~7 ~-2 ~40 dirt 0  
fill ~1 ~-2 ~41 ~7 ~-2 ~41 dirt 0  
fill ~1 ~-2 ~42 ~7 ~-2 ~42 dirt 0  
fill ~1 ~-2 ~43 ~7 ~-2 ~43 dirt 0  
fill ~1 ~-2 ~44 ~50 ~-2 ~44 dirt 0  
fill ~1 ~-2 ~45 ~50 ~-2 ~45 dirt 0  
fill ~1 ~-2 ~46 ~50 ~-2 ~46 dirt 0  
fill ~1 ~-2 ~47 ~50 ~-2 ~47 dirt 0  
fill ~1 ~-2 ~48 ~50 ~-2 ~48 dirt 0  
fill ~1 ~-2 ~49 ~50 ~-2 ~49 dirt 0  
fill ~8 ~-2 ~35 ~8 ~-2 ~35 stone 0  
fill ~8 ~-2 ~36 ~8 ~-2 ~36 stone 0  
fill ~8 ~-2 ~37 ~8 ~-2 ~37 stone 0  
fill ~8 ~-2 ~38 ~8 ~-2 ~38 stone 0  
fill ~8 ~-2 ~39 ~9 ~-2 ~39 stone 0  
fill ~8 ~-2 ~40 ~9 ~-2 ~40 stone 0  
fill ~8 ~-2 ~41 ~9 ~-2 ~41 stone 0  
fill ~8 ~-2 ~42 ~8 ~-2 ~42 stone 0  
fill ~8 ~-2 ~43 ~8 ~-2 ~43 stone 0  
fill ~9 ~-2 ~35 ~50 ~-2 ~35 dirt 0  
fill ~9 ~-2 ~36 ~50 ~-2 ~36 dirt 0  
fill ~9 ~-2 ~37 ~50 ~-2 ~37 dirt 0  
fill ~9 ~-2 ~38 ~50 ~-2 ~38 dirt 0  
fill ~9 ~-2 ~42 ~9 ~-2 ~42 coal_ore 0  
fill ~9 ~-2 ~43 ~50 ~-2 ~43 dirt 0  
fill ~10 ~-2 ~39 ~50 ~-2 ~39 dirt 0  
fill ~10 ~-2 ~40 ~50 ~-2 ~40 dirt 0  
fill ~10 ~-2 ~41 ~50 ~-2 ~41 dirt 0  
fill ~10 ~-2 ~42 ~50 ~-2 ~42 dirt 0  
fill ~24 ~-2 ~20 ~24 ~-1 ~20 stonebrick 0  
fill ~24 ~-2 ~21 ~24 ~-1 ~21 stonebrick 0  
fill ~24 ~-2 ~22 ~24 ~-1 ~22 stonebrick 0  
fill ~24 ~-2 ~23 ~24 ~-1 ~23 stonebrick 0  
fill ~24 ~-2 ~24 ~24 ~-1 ~24 stonebrick 0  
fill ~25 ~-2 ~19 ~28 ~-2 ~19 stonebrick 0  
fill ~25 ~-2 ~25 ~28 ~-2 ~25 stonebrick 0  
fill ~27 ~-2 ~22 ~28 ~-2 ~22 stonebrick 0  
fill ~28 ~-2 ~20 ~28 ~-2 ~21 stone_brick_stairs 4  
fill ~28 ~-2 ~23 ~28 ~-2 ~24 stone_brick_stairs 0  
fill ~29 ~-2 ~19 ~50 ~-2 ~19 dirt 0  
fill ~29 ~-2 ~20 ~50 ~-2 ~20 dirt 0  
fill ~29 ~-2 ~21 ~50 ~-2 ~21 dirt 0  
fill ~29 ~-2 ~22 ~50 ~-2 ~22 dirt 0 
setblock ~29 ~-2 ~23 grass 0  
fill ~29 ~-2 ~24 ~50 ~-2 ~24 dirt 0  
fill ~29 ~-2 ~25 ~50 ~-2 ~25 dirt 0  
fill ~30 ~-2 ~23 ~50 ~-2 ~23 dirt 0  
fill ~1 ~-1 ~1 ~20 ~-1 ~1 grass 0  
fill ~1 ~-1 ~2 ~17 ~-1 ~2 grass 0  
fill ~1 ~-1 ~3 ~14 ~-1 ~3 grass 0  
fill ~1 ~-1 ~4 ~13 ~-1 ~4 grass 0  
fill ~1 ~-1 ~5 ~11 ~-1 ~5 grass 0  
fill ~1 ~-1 ~6 ~10 ~-1 ~6 grass 0  
fill ~1 ~-1 ~7 ~8 ~-1 ~7 grass 0  
fill ~1 ~-1 ~8 ~7 ~-1 ~8 grass 0  
fill ~1 ~-1 ~9 ~6 ~-1 ~9 grass 0  
fill ~1 ~-1 ~10 ~6 ~-1 ~10 grass 0  
fill ~1 ~-1 ~11 ~5 ~-1 ~11 grass 0  
fill ~1 ~-1 ~12 ~4 ~-1 ~12 grass 0  
fill ~1 ~-1 ~13 ~4 ~-1 ~13 grass 0  
fill ~1 ~-1 ~14 ~3 ~-1 ~14 grass 0  
fill ~1 ~-1 ~15 ~2 ~-1 ~15 grass 0  
fill ~1 ~-1 ~16 ~2 ~-1 ~16 grass 0  
fill ~1 ~-1 ~17 ~2 ~-1 ~17 grass 0  
fill ~1 ~-1 ~18 ~1 ~-1 ~18 grass 0  
fill ~1 ~-1 ~19 ~1 ~-1 ~19 grass 0  
fill ~1 ~-1 ~20 ~1 ~-1 ~20 grass 0  
fill ~1 ~-1 ~21 ~6 ~-1 ~21 stonebrick 0  
fill ~1 ~-1 ~22 ~6 ~-1 ~22 stonebrick 0  
fill ~1 ~-1 ~23 ~24 ~-1 ~23 stonebrick 0  
fill ~1 ~-1 ~24 ~4 ~-1 ~24 stonebrick 0  
fill ~1 ~-1 ~25 ~4 ~-1 ~25 stonebrick 0  
fill ~1 ~-1 ~26 ~4 ~-1 ~26 stonebrick 0  
fill ~1 ~-1 ~27 ~7 ~-1 ~27 stonebrick 0  
fill ~1 ~-1 ~28 ~1 ~-1 ~30 stonebrick 0  
fill ~1 ~-1 ~31 ~1 ~-1 ~31 grass 0  
fill ~1 ~-1 ~32 ~1 ~-1 ~32 grass 0  
fill ~1 ~-1 ~33 ~1 ~-1 ~33 grass 0  
fill ~1 ~-1 ~34 ~2 ~-1 ~34 grass 0  
fill ~1 ~-1 ~35 ~2 ~-1 ~35 grass 0  
fill ~1 ~-1 ~36 ~2 ~-1 ~36 grass 0  
fill ~1 ~-1 ~37 ~3 ~-1 ~37 grass 0  
fill ~1 ~-1 ~38 ~4 ~-1 ~38 grass 0  
fill ~1 ~-1 ~39 ~4 ~-1 ~39 grass 0  
fill ~1 ~-1 ~40 ~5 ~-1 ~40 grass 0  
fill ~1 ~-1 ~41 ~6 ~-1 ~41 grass 0  
fill ~1 ~-1 ~42 ~6 ~-1 ~42 grass 0  
fill ~1 ~-1 ~43 ~7 ~-1 ~43 grass 0  
fill ~1 ~-1 ~44 ~8 ~-1 ~44 grass 0  
fill ~1 ~-1 ~45 ~10 ~-1 ~45 grass 0  
fill ~1 ~-1 ~46 ~11 ~-1 ~46 grass 0  
fill ~1 ~-1 ~47 ~13 ~-1 ~47 grass 0  
fill ~1 ~-1 ~48 ~14 ~-1 ~48 grass 0  
fill ~1 ~-1 ~49 ~4 ~-1 ~49 grass 0  
fill ~2 ~-1 ~18 ~4 ~-1 ~18 stonebrick 0  
fill ~2 ~-1 ~19 ~5 ~-1 ~19 stonebrick 0  
fill ~2 ~-1 ~20 ~5 ~-1 ~20 stonebrick 0  
fill ~2 ~-1 ~28 ~3 ~-1 ~28 stonebrick 1  
fill ~2 ~-1 ~29 ~2 ~-1 ~33 stonebrick 0  
fill ~3 ~-1 ~15 ~42 ~-1 ~15 stonebrick 0  
fill ~3 ~-1 ~16 ~5 ~-1 ~16 stonebrick 0  
fill ~3 ~-1 ~17 ~4 ~-1 ~17 stonebrick 0 
setblock ~3 ~-1 ~29 stonebrick 1  
fill ~3 ~-1 ~30 ~9 ~-1 ~30 stonebrick 0  
fill ~3 ~-1 ~31 ~8 ~-1 ~31 stonebrick 0  
fill ~3 ~-1 ~32 ~5 ~-1 ~32 stonebrick 0  
fill ~3 ~-1 ~33 ~4 ~-1 ~33 stonebrick 0  
fill ~3 ~-1 ~34 ~4 ~-1 ~34 stonebrick 0  
fill ~3 ~-1 ~35 ~5 ~-1 ~35 stonebrick 0  
fill ~3 ~-1 ~36 ~5 ~-1 ~36 stonebrick 0  
fill ~4 ~-1 ~14 ~39 ~-1 ~14 stonebrick 0  
fill ~4 ~-1 ~28 ~39 ~-1 ~28 stonebrick 0  
fill ~4 ~-1 ~29 ~40 ~-1 ~29 stonebrick 0  
fill ~4 ~-1 ~37 ~6 ~-1 ~37 stonebrick 0  
fill ~5 ~-1 ~12 ~7 ~-1 ~12 stonebrick 0  
fill ~5 ~-1 ~13 ~6 ~-1 ~13 stonebrick 0  
fill ~5 ~-1 ~17 ~6 ~-1 ~17 stonebrick 2  
fill ~5 ~-1 ~18 ~9 ~-1 ~18 stonebrick 2  
fill ~5 ~-1 ~24 ~7 ~-1 ~24 stonebrick 2  
fill ~5 ~-1 ~25 ~7 ~-1 ~25 stonebrick 2  
fill ~5 ~-1 ~26 ~8 ~-1 ~26 stonebrick 2  
fill ~5 ~-1 ~33 ~9 ~-1 ~33 stonebrick 2  
fill ~5 ~-1 ~34 ~9 ~-1 ~34 stonebrick 2  
fill ~5 ~-1 ~38 ~40 ~-1 ~38 stonebrick 0  
fill ~5 ~-1 ~39 ~11 ~-1 ~39 stonebrick 0 
setblock ~5 ~-1 ~49 dirt 0  
fill ~6 ~-1 ~11 ~7 ~-1 ~11 stonebrick 0  
fill ~6 ~-1 ~16 ~8 ~-1 ~16 stonebrick 2  
fill ~6 ~-1 ~19 ~9 ~-1 ~19 stonebrick 2  
fill ~6 ~-1 ~20 ~8 ~-1 ~20 stonebrick 2  
fill ~6 ~-1 ~32 ~7 ~-1 ~32 stonebrick 2  
fill ~6 ~-1 ~35 ~8 ~-1 ~35 stonebrick 2  
fill ~6 ~-1 ~36 ~6 ~-1 ~32 stonebrick 2  
fill ~6 ~-1 ~40 ~13 ~-1 ~40 stonebrick 0  
fill ~6 ~-1 ~49 ~17 ~-1 ~49 grass 0  
fill ~7 ~-1 ~9 ~13 ~-1 ~9 stonebrick 0  
fill ~7 ~-1 ~10 ~10 ~-1 ~10 stonebrick 0  
fill ~7 ~-1 ~13 ~9 ~-1 ~13 stonebrick 2  
fill ~7 ~-1 ~17 ~8 ~-1 ~17 stonebrick 0  
fill ~7 ~-1 ~21 ~8 ~-1 ~21 stonebrick 2  
fill ~7 ~-1 ~22 ~7 ~-1 ~18 stonebrick 2  
fill ~7 ~-1 ~36 ~7 ~-1 ~37 stonebrick 1  
fill ~7 ~-1 ~41 ~8 ~-1 ~41 stonebrick 0  
fill ~7 ~-1 ~42 ~9 ~-1 ~42 stonebrick 0  
fill ~8 ~-1 ~8 ~12 ~-1 ~8 stonebrick 0  
fill ~8 ~-1 ~11 ~8 ~-1 ~13 stonebrick 2  
fill ~8 ~-1 ~22 ~24 ~-1 ~22 stonebrick 0  
fill ~8 ~-1 ~24 ~24 ~-1 ~24 stonebrick 0  
fill ~8 ~-1 ~25 ~38 ~-1 ~25 stonebrick 0  
fill ~8 ~-1 ~27 ~11 ~-1 ~27 stonebrick 2  
fill ~8 ~-1 ~32 ~42 ~-1 ~32 stonebrick 0  
fill ~8 ~-1 ~36 ~43 ~-1 ~36 stonebrick 0 
setblock ~8 ~-1 ~37 stonebrick 1  
fill ~8 ~-1 ~43 ~9 ~-1 ~43 stonebrick 0  
fill ~9 ~-1 ~7 ~14 ~-1 ~7 stonebrick 0  
fill ~9 ~-1 ~11 ~10 ~-1 ~11 stonebrick 0 
setblock ~9 ~-1 ~12 stonebrick 2  
fill ~9 ~-1 ~16 ~43 ~-1 ~16 stonebrick 0  
fill ~9 ~-1 ~17 ~10 ~-1 ~17 stonebrick 1  
fill ~9 ~-1 ~20 ~24 ~-1 ~20 stonebrick 0  
fill ~9 ~-1 ~21 ~24 ~-1 ~21 stonebrick 0 
setblock ~9 ~-1 ~26 stonebrick 0  
fill ~9 ~-1 ~31 ~10 ~-1 ~31 stonebrick 1  
fill ~9 ~-1 ~35 ~44 ~-1 ~35 stonebrick 0  
fill ~9 ~-1 ~37 ~39 ~-1 ~37 stonebrick 0  
fill ~9 ~-1 ~41 ~11 ~-1 ~41 stonebrick 2  
fill ~9 ~-1 ~44 ~15 ~-1 ~44 stonebrick 0  
fill ~10 ~-1 ~12 ~11 ~-1 ~12 stonebrick 0  
fill ~10 ~-1 ~13 ~40 ~-1 ~13 stonebrick 0  
fill ~10 ~-1 ~18 ~41 ~-1 ~18 stonebrick 0  
fill ~10 ~-1 ~19 ~42 ~-1 ~19 stonebrick 0  
fill ~10 ~-1 ~26 ~12 ~-1 ~26 stonebrick 2 
setblock ~10 ~-1 ~30 stonebrick 1  
fill ~10 ~-1 ~33 ~45 ~-1 ~33 stonebrick 0  
fill ~10 ~-1 ~34 ~45 ~-1 ~34 stonebrick 0  
fill ~10 ~-1 ~42 ~12 ~-1 ~42 stonebrick 2  
fill ~10 ~-1 ~43 ~11 ~-1 ~43 stonebrick 2  
fill ~11 ~-1 ~6 ~19 ~-1 ~6 stonebrick 0  
fill ~11 ~-1 ~10 ~12 ~-1 ~10 stonebrick 1  
fill ~11 ~-1 ~11 ~11 ~-1 ~10 stonebrick 1  
fill ~11 ~-1 ~17 ~41 ~-1 ~17 stonebrick 0  
fill ~11 ~-1 ~30 ~42 ~-1 ~30 stonebrick 0  
fill ~11 ~-1 ~31 ~41 ~-1 ~31 stonebrick 0  
fill ~11 ~-1 ~45 ~14 ~-1 ~45 stonebrick 0  
fill ~12 ~-1 ~5 ~20 ~-1 ~5 stonebrick 0  
fill ~12 ~-1 ~11 ~23 ~-1 ~11 stonebrick 0 
setblock ~12 ~-1 ~12 netherrack 0  
fill ~12 ~-1 ~27 ~44 ~-1 ~27 stonebrick 0 
setblock ~12 ~-1 ~39 netherrack 0  
fill ~12 ~-1 ~41 ~13 ~-1 ~41 stonebrick 0  
fill ~12 ~-1 ~43 ~15 ~-1 ~43 stonebrick 0  
fill ~12 ~-1 ~46 ~15 ~-1 ~46 stonebrick 0  
fill ~13 ~-1 ~8 ~16 ~-1 ~8 stonebrick 2  
fill ~13 ~-1 ~10 ~16 ~-1 ~10 stonebrick 0  
fill ~13 ~-1 ~12 ~38 ~-1 ~12 stonebrick 0  
fill ~13 ~-1 ~26 ~39 ~-1 ~26 stonebrick 0  
fill ~13 ~-1 ~39 ~38 ~-1 ~39 stonebrick 0  
fill ~13 ~-1 ~42 ~23 ~-1 ~42 stonebrick 0  
fill ~14 ~-1 ~4 ~16 ~-1 ~4 stonebrick 0  
fill ~14 ~-1 ~9 ~15 ~-1 ~9 stonebrick 2  
fill ~14 ~-1 ~40 ~15 ~-1 ~40 stonebrick 1  
fill ~14 ~-1 ~41 ~14 ~-1 ~40 stonebrick 1  
fill ~14 ~-1 ~47 ~22 ~-1 ~47 stonebrick 0  
fill ~15 ~-1 ~3 ~16 ~-1 ~3 stonebrick 0  
fill ~15 ~-1 ~7 ~20 ~-1 ~7 stonebrick 2  
fill ~15 ~-1 ~41 ~24 ~-1 ~41 stonebrick 0  
fill ~15 ~-1 ~45 ~17 ~-1 ~45 stonebrick 2  
fill ~15 ~-1 ~48 ~24 ~-1 ~48 stonebrick 0 
setblock ~16 ~-1 ~9 stonebrick 0  
fill ~16 ~-1 ~40 ~40 ~-1 ~40 stonebrick 0  
fill ~16 ~-1 ~43 ~16 ~-1 ~46 stonebrick 2  
fill ~17 ~-1 ~3 ~17 ~-1 ~4 stonebrick 1 
setblock ~17 ~-1 ~8 stonebrick 0  
fill ~17 ~-1 ~9 ~18 ~-1 ~9 stonebrick 1  
fill ~17 ~-1 ~10 ~17 ~-1 ~9 stonebrick 1  
fill ~17 ~-1 ~43 ~22 ~-1 ~43 stonebrick 0 
setblock ~17 ~-1 ~44 stonebrick 2 
setblock ~17 ~-1 ~46 stonebrick 2  
fill ~18 ~-1 ~2 ~24 ~-1 ~2 stonebrick 0  
fill ~18 ~-1 ~3 ~23 ~-1 ~3 stonebrick 0 
setblock ~18 ~-1 ~4 stonebrick 1 
setblock ~18 ~-1 ~8 stonebrick 2  
fill ~18 ~-1 ~10 ~24 ~-1 ~10 stonebrick 0 
setblock ~18 ~-1 ~44 stonebrick 1  
fill ~18 ~-1 ~45 ~18 ~-1 ~49 stonebrick 0  
fill ~19 ~-1 ~4 ~28 ~-1 ~4 stonebrick 0  
fill ~19 ~-1 ~8 ~19 ~-1 ~44 stonebrick 0 
setblock ~19 ~-1 ~45 stonebrick 1  
fill ~19 ~-1 ~46 ~21 ~-1 ~46 stonebrick 0  
fill ~19 ~-1 ~49 ~33 ~-1 ~49 stonebrick 0  
fill ~20 ~-1 ~6 ~21 ~-1 ~6 stonebrick 2  
fill ~20 ~-1 ~8 ~26 ~-1 ~8 stonebrick 2 
setblock ~20 ~-1 ~9 stonebrick 0  
fill ~20 ~-1 ~44 ~20 ~-1 ~49 stonebrick 0  
fill ~21 ~-1 ~1 ~30 ~-1 ~1 stonebrick 0 
setblock ~21 ~-1 ~5 stonebrick 2  
fill ~21 ~-1 ~7 ~22 ~-1 ~7 stonebrick 0  
fill ~21 ~-1 ~9 ~22 ~-1 ~9 stonebrick 2  
fill ~21 ~-1 ~44 ~30 ~-1 ~44 stonebrick 2  
fill ~21 ~-1 ~45 ~28 ~-1 ~45 stonebrick 2  
fill ~22 ~-1 ~5 ~30 ~-1 ~5 stonebrick 0  
fill ~22 ~-1 ~6 ~22 ~-1 ~1 stonebrick 0  
fill ~22 ~-1 ~46 ~27 ~-1 ~46 stonebrick 2  
fill ~23 ~-1 ~6 ~23 ~-1 ~8 stonebrick 2 
setblock ~23 ~-1 ~9 stonebrick 0  
fill ~23 ~-1 ~43 ~26 ~-1 ~43 stonebrick 2  
fill ~23 ~-1 ~47 ~26 ~-1 ~47 stonebrick 2  
fill ~24 ~-1 ~3 ~25 ~-1 ~3 stonebrick 1  
fill ~24 ~-1 ~6 ~32 ~-1 ~6 stonebrick 0  
fill ~24 ~-1 ~7 ~32 ~-1 ~7 stonebrick 0  
fill ~24 ~-1 ~9 ~26 ~-1 ~9 stonebrick 2  
fill ~24 ~-1 ~11 ~25 ~-1 ~11 stonebrick 2  
fill ~24 ~-1 ~42 ~26 ~-1 ~42 stonebrick 2 
setblock ~25 ~-1 ~2 stonebrick 1  
fill ~25 ~-1 ~10 ~26 ~-1 ~10 stonebrick 2 
setblock ~25 ~-1 ~41 stonebrick 2  
fill ~25 ~-1 ~48 ~27 ~-1 ~48 stonebrick 2  
fill ~26 ~-1 ~2 ~33 ~-1 ~2 stonebrick 0  
fill ~26 ~-1 ~3 ~29 ~-1 ~3 stonebrick 0  
fill ~26 ~-1 ~11 ~45 ~-1 ~11 stonebrick 0 
setblock ~26 ~-1 ~21 glowstone 0 
setblock ~26 ~-1 ~22 redstone_torch 2  
fill ~26 ~-1 ~41 ~32 ~-1 ~41 stonebrick 0  
fill ~27 ~-1 ~8 ~33 ~-1 ~8 stonebrick 0  
fill ~27 ~-1 ~9 ~29 ~-1 ~9 stonebrick 0  
fill ~27 ~-1 ~10 ~29 ~-1 ~10 stonebrick 0  
fill ~27 ~-1 ~20 ~27 ~-1 ~21 stone_brick_stairs 4  
fill ~27 ~-1 ~22 ~47 ~-1 ~22 stonebrick 0  
fill ~27 ~-1 ~42 ~27 ~-1 ~43 stonebrick 0  
fill ~27 ~-1 ~47 ~31 ~-1 ~47 stonebrick 0  
fill ~28 ~-1 ~20 ~38 ~-1 ~20 stonebrick 0  
fill ~28 ~-1 ~21 ~47 ~-1 ~21 stonebrick 0  
fill ~28 ~-1 ~42 ~29 ~-1 ~42 stonebrick 2  
fill ~28 ~-1 ~43 ~29 ~-1 ~43 stonebrick 2  
fill ~28 ~-1 ~46 ~29 ~-1 ~46 stonebrick 0  
fill ~28 ~-1 ~48 ~31 ~-1 ~48 stonebrick 0  
fill ~29 ~-1 ~4 ~34 ~-1 ~4 stonebrick 2  
fill ~29 ~-1 ~23 ~29 ~-1 ~24 stone_brick_stairs 0 
setblock ~29 ~-1 ~45 stonebrick 0  
fill ~30 ~-1 ~3 ~31 ~-1 ~3 stonebrick 1  
fill ~30 ~-1 ~9 ~30 ~-1 ~10 stonebrick 1  
fill ~30 ~-1 ~23 ~48 ~-1 ~23 stonebrick 0  
fill ~30 ~-1 ~24 ~39 ~-1 ~24 stonebrick 0  
fill ~30 ~-1 ~42 ~31 ~-1 ~42 stonebrick 0  
fill ~30 ~-1 ~43 ~32 ~-1 ~43 stonebrick 0  
fill ~30 ~-1 ~45 ~31 ~-1 ~45 stonebrick 2  
fill ~30 ~-1 ~46 ~30 ~-1 ~44 stonebrick 2  
fill ~31 ~-1 ~1 ~50 ~-1 ~1 grass 0  
fill ~31 ~-1 ~5 ~35 ~-1 ~5 stonebrick 2  
fill ~31 ~-1 ~9 ~44 ~-1 ~9 stonebrick 0  
fill ~31 ~-1 ~10 ~32 ~-1 ~10 stonebrick 1  
fill ~31 ~-1 ~44 ~37 ~-1 ~44 stonebrick 0  
fill ~31 ~-1 ~46 ~39 ~-1 ~46 stonebrick 0 
setblock ~32 ~-1 ~3 stonebrick 0  
fill ~32 ~-1 ~42 ~33 ~-1 ~42 stonebrick 1  
fill ~32 ~-1 ~45 ~36 ~-1 ~45 stonebrick 0  
fill ~32 ~-1 ~47 ~32 ~-1 ~48 stonebrick 1 
setblock ~33 ~-1 ~3 stonebrick 2  
fill ~33 ~-1 ~6 ~34 ~-1 ~6 stonebrick 2  
fill ~33 ~-1 ~7 ~36 ~-1 ~7 stonebrick 2  
fill ~33 ~-1 ~10 ~44 ~-1 ~10 stonebrick 0 
setblock ~33 ~-1 ~41 stonebrick 1 
setblock ~33 ~-1 ~43 stonebrick 1  
fill ~33 ~-1 ~47 ~37 ~-1 ~47 stonebrick 0  
fill ~33 ~-1 ~48 ~36 ~-1 ~48 stonebrick 0  
fill ~34 ~-1 ~2 ~50 ~-1 ~2 grass 0  
fill ~34 ~-1 ~3 ~36 ~-1 ~3 stonebrick 0  
fill ~34 ~-1 ~8 ~35 ~-1 ~8 stonebrick 2  
fill ~34 ~-1 ~41 ~38 ~-1 ~41 stonebrick 0  
fill ~34 ~-1 ~42 ~37 ~-1 ~42 stonebrick 0  
fill ~34 ~-1 ~43 ~37 ~-1 ~43 stonebrick 0  
fill ~34 ~-1 ~49 ~48 ~-1 ~49 grass 0  
fill ~35 ~-1 ~4 ~37 ~-1 ~4 stonebrick 0  
fill ~35 ~-1 ~6 ~40 ~-1 ~6 stonebrick 0  
fill ~36 ~-1 ~5 ~39 ~-1 ~5 stonebrick 0  
fill ~36 ~-1 ~8 ~43 ~-1 ~8 stonebrick 0  
fill ~37 ~-1 ~3 ~50 ~-1 ~3 grass 0  
fill ~37 ~-1 ~7 ~38 ~-1 ~7 stonebrick 0  
fill ~37 ~-1 ~45 ~38 ~-1 ~45 stonebrick 1  
fill ~37 ~-1 ~48 ~50 ~-1 ~48 grass 0  
fill ~38 ~-1 ~4 ~49 ~-1 ~4 grass 0  
fill ~38 ~-1 ~42 ~43 ~-1 ~42 stonebrick 2  
fill ~38 ~-1 ~43 ~40 ~-1 ~43 stonebrick 2 
setblock ~38 ~-1 ~44 stonebrick 1  
fill ~38 ~-1 ~47 ~50 ~-1 ~47 grass 0  
fill ~39 ~-1 ~7 ~40 ~-1 ~7 stonebrick 1 
setblock ~39 ~-1 ~12 netherrack 0  
fill ~39 ~-1 ~20 ~40 ~-1 ~20 stonebrick 1  
fill ~39 ~-1 ~25 ~45 ~-1 ~25 stonebrick 2 
setblock ~39 ~-1 ~39 netherrack 0  
fill ~39 ~-1 ~41 ~43 ~-1 ~41 stonebrick 2  
fill ~39 ~-1 ~44 ~39 ~-1 ~46 stonebrick 0  
fill ~40 ~-1 ~5 ~50 ~-1 ~5 grass 0  
fill ~40 ~-1 ~12 ~46 ~-1 ~12 stonebrick 0  
fill ~40 ~-1 ~14 ~41 ~-1 ~14 stonebrick 1  
fill ~40 ~-1 ~24 ~41 ~-1 ~24 stonebrick 2  
fill ~40 ~-1 ~26 ~41 ~-1 ~26 stonebrick 2  
fill ~40 ~-1 ~28 ~41 ~-1 ~28 stonebrick 1  
fill ~40 ~-1 ~37 ~41 ~-1 ~37 stonebrick 1  
fill ~40 ~-1 ~39 ~41 ~-1 ~39 stonebrick 0 
setblock ~40 ~-1 ~44 stonebrick 2 
setblock ~40 ~-1 ~45 stonebrick 0  
fill ~40 ~-1 ~46 ~50 ~-1 ~46 grass 0  
fill ~41 ~-1 ~6 ~50 ~-1 ~6 grass 0  
fill ~41 ~-1 ~7 ~42 ~-1 ~7 stonebrick 0 
setblock ~41 ~-1 ~13 stonebrick 1  
fill ~41 ~-1 ~20 ~49 ~-1 ~20 stonebrick 0 
setblock ~41 ~-1 ~29 stonebrick 1 
setblock ~41 ~-1 ~38 stonebrick 1  
fill ~41 ~-1 ~40 ~43 ~-1 ~40 stonebrick 2  
fill ~41 ~-1 ~43 ~43 ~-1 ~43 stonebrick 0  
fill ~41 ~-1 ~44 ~42 ~-1 ~44 stonebrick 0  
fill ~41 ~-1 ~45 ~50 ~-1 ~45 grass 0  
fill ~42 ~-1 ~13 ~42 ~-1 ~14 stonebrick 2  
fill ~42 ~-1 ~17 ~47 ~-1 ~17 stonebrick 2  
fill ~42 ~-1 ~18 ~46 ~-1 ~18 stonebrick 2 
setblock ~42 ~-1 ~24 stonebrick 0 
setblock ~42 ~-1 ~26 stonebrick 0  
fill ~42 ~-1 ~28 ~42 ~-1 ~30 stonebrick 0  
fill ~42 ~-1 ~31 ~46 ~-1 ~31 stonebrick 2  
fill ~42 ~-1 ~37 ~42 ~-1 ~38 stonebrick 0  
fill ~42 ~-1 ~39 ~43 ~-1 ~39 stonebrick 2  
fill ~43 ~-1 ~7 ~50 ~-1 ~7 grass 0  
fill ~43 ~-1 ~13 ~46 ~-1 ~13 stonebrick 0  
fill ~43 ~-1 ~14 ~43 ~-1 ~15 stonebrick 2  
fill ~43 ~-1 ~19 ~46 ~-1 ~19 stonebrick 2  
fill ~43 ~-1 ~24 ~44 ~-1 ~24 stonebrick 2 
setblock ~43 ~-1 ~26 stonebrick 2  
fill ~43 ~-1 ~28 ~43 ~-1 ~32 stonebrick 2  
fill ~43 ~-1 ~37 ~45 ~-1 ~37 stonebrick 2  
fill ~43 ~-1 ~38 ~44 ~-1 ~38 stonebrick 2  
fill ~43 ~-1 ~44 ~50 ~-1 ~44 grass 0  
fill ~44 ~-1 ~8 ~46 ~-1 ~8 grass 0  
fill ~44 ~-1 ~14 ~47 ~-1 ~14 stonebrick 0  
fill ~44 ~-1 ~15 ~44 ~-1 ~19 stonebrick 2 
setblock ~44 ~-1 ~26 stonebrick 0  
fill ~44 ~-1 ~28 ~45 ~-1 ~28 stonebrick 0  
fill ~44 ~-1 ~29 ~45 ~-1 ~29 stonebrick 0 
setblock ~44 ~-1 ~30 stonebrick 2  
fill ~44 ~-1 ~32 ~49 ~-1 ~32 stonebrick 0  
fill ~44 ~-1 ~36 ~46 ~-1 ~36 stonebrick 2  
fill ~44 ~-1 ~39 ~46 ~-1 ~39 stonebrick 0  
fill ~44 ~-1 ~40 ~45 ~-1 ~40 stonebrick 0  
fill ~44 ~-1 ~41 ~44 ~-1 ~42 stonebrick 0  
fill ~44 ~-1 ~43 ~50 ~-1 ~43 grass 0  
fill ~45 ~-1 ~9 ~50 ~-1 ~9 grass 0  
fill ~45 ~-1 ~10 ~49 ~-1 ~10 grass 0  
fill ~45 ~-1 ~15 ~48 ~-1 ~15 stonebrick 0  
fill ~45 ~-1 ~16 ~46 ~-1 ~16 stonebrick 2  
fill ~45 ~-1 ~24 ~50 ~-1 ~24 stonebrick 0  
fill ~45 ~-1 ~26 ~48 ~-1 ~26 stonebrick 2  
fill ~45 ~-1 ~27 ~49 ~-1 ~27 stonebrick 2 
setblock ~45 ~-1 ~30 stonebrick 0  
fill ~45 ~-1 ~35 ~47 ~-1 ~35 stonebrick 2  
fill ~45 ~-1 ~38 ~46 ~-1 ~38 stonebrick 0  
fill ~45 ~-1 ~41 ~50 ~-1 ~41 grass 0  
fill ~45 ~-1 ~42 ~50 ~-1 ~42 grass 0  
fill ~46 ~-1 ~11 ~50 ~-1 ~11 grass 0  
fill ~46 ~-1 ~25 ~50 ~-1 ~25 stonebrick 0  
fill ~46 ~-1 ~28 ~47 ~-1 ~28 stonebrick 2  
fill ~46 ~-1 ~29 ~47 ~-1 ~29 stonebrick 2  
fill ~46 ~-1 ~30 ~46 ~-1 ~26 stonebrick 2  
fill ~46 ~-1 ~33 ~46 ~-1 ~36 stonebrick 2  
fill ~46 ~-1 ~37 ~47 ~-1 ~37 stonebrick 0  
fill ~46 ~-1 ~40 ~50 ~-1 ~40 grass 0 
setblock ~47 ~-1 ~8 dirt 0  
fill ~47 ~-1 ~12 ~50 ~-1 ~12 grass 0  
fill ~47 ~-1 ~13 ~50 ~-1 ~13 grass 0  
fill ~47 ~-1 ~16 ~48 ~-1 ~16 stonebrick 0  
fill ~47 ~-1 ~18 ~49 ~-1 ~18 stonebrick 0  
fill ~47 ~-1 ~19 ~49 ~-1 ~19 stonebrick 0  
fill ~47 ~-1 ~30 ~47 ~-1 ~33 stonebrick 0 
setblock ~47 ~-1 ~34 stonebrick 2  
fill ~47 ~-1 ~36 ~48 ~-1 ~36 stonebrick 0  
fill ~47 ~-1 ~38 ~50 ~-1 ~38 grass 0  
fill ~47 ~-1 ~39 ~50 ~-1 ~39 grass 0  
fill ~48 ~-1 ~8 ~50 ~-1 ~8 grass 0  
fill ~48 ~-1 ~14 ~50 ~-1 ~14 grass 0 
setblock ~48 ~-1 ~17 stonebrick 0  
fill ~48 ~-1 ~21 ~48 ~-1 ~22 stonebrick 1  
fill ~48 ~-1 ~28 ~50 ~-1 ~28 stonebrick 0  
fill ~48 ~-1 ~29 ~50 ~-1 ~29 stonebrick 0  
fill ~48 ~-1 ~30 ~48 ~-1 ~31 stonebrick 1  
fill ~48 ~-1 ~33 ~49 ~-1 ~33 stonebrick 0  
fill ~48 ~-1 ~34 ~48 ~-1 ~36 stonebrick 0  
fill ~48 ~-1 ~37 ~50 ~-1 ~37 grass 0  
fill ~49 ~-1 ~15 ~50 ~-1 ~15 grass 0  
fill ~49 ~-1 ~16 ~50 ~-1 ~16 grass 0  
fill ~49 ~-1 ~17 ~50 ~-1 ~17 grass 0  
fill ~49 ~-1 ~21 ~50 ~-1 ~21 stonebrick 0  
fill ~49 ~-1 ~22 ~49 ~-1 ~23 stonebrick 1  
fill ~49 ~-1 ~26 ~50 ~-1 ~26 stonebrick 0  
fill ~49 ~-1 ~30 ~50 ~-1 ~30 stonebrick 0 
setblock ~49 ~-1 ~31 stonebrick 1  
fill ~49 ~-1 ~34 ~50 ~-1 ~34 grass 0  
fill ~49 ~-1 ~35 ~50 ~-1 ~35 grass 0  
fill ~49 ~-1 ~36 ~50 ~-1 ~36 grass 0 
setblock ~49 ~-1 ~49 dirt 0 
setblock ~50 ~-1 ~4 dirt 0 
setblock ~50 ~-1 ~10 dirt 0  
fill ~50 ~-1 ~18 ~50 ~-1 ~18 grass 0  
fill ~50 ~-1 ~19 ~50 ~-1 ~19 grass 0  
fill ~50 ~-1 ~20 ~50 ~-1 ~20 grass 0  
fill ~50 ~-1 ~22 ~50 ~-1 ~30 stonebrick 0  
fill ~50 ~-1 ~31 ~50 ~-1 ~31 grass 0  
fill ~50 ~-1 ~32 ~50 ~-1 ~32 grass 0  
fill ~50 ~-1 ~33 ~50 ~-1 ~33 grass 0  
fill ~50 ~-1 ~49 ~50 ~-1 ~49 grass 0  
fill ~1 ~0 ~1 ~1 ~0 ~1 tallgrass 1  
fill ~1 ~0 ~2 ~3 ~0 ~2 tallgrass 1 
setblock ~1 ~0 ~3 yellow_flower 0  
fill ~1 ~0 ~4 ~1 ~0 ~5 tallgrass 1  
fill ~1 ~0 ~9 ~1 ~0 ~10 tallgrass 1 
setblock ~1 ~0 ~11 red_flower 0  
fill ~1 ~0 ~12 ~2 ~0 ~12 tallgrass 1  
fill ~1 ~0 ~13 ~1 ~0 ~15 tallgrass 1 
setblock ~1 ~0 ~16 yellow_flower 0 
setblock ~1 ~0 ~17 red_flower 0  
fill ~1 ~0 ~18 ~1 ~0 ~18 tallgrass 1  
fill ~1 ~0 ~19 ~1 ~0 ~19 tallgrass 1 
setblock ~1 ~0 ~20 yellow_flower 0 
setblock ~1 ~0 ~21 stone_brick_stairs 0 
setblock ~1 ~0 ~30 stone_brick_stairs 0  
fill ~1 ~0 ~31 ~1 ~0 ~35 tallgrass 1 
setblock ~1 ~0 ~36 red_flower 0  
fill ~1 ~0 ~38 ~1 ~0 ~38 tallgrass 1  
fill ~1 ~0 ~39 ~4 ~0 ~39 tallgrass 1 
setblock ~1 ~0 ~40 yellow_flower 0 
setblock ~1 ~0 ~42 tallgrass 1  
fill ~1 ~0 ~44 ~1 ~0 ~44 tallgrass 1  
fill ~1 ~0 ~47 ~1 ~0 ~49 tallgrass 1 
setblock ~2 ~0 ~1 red_flower 0 
setblock ~2 ~0 ~3 tallgrass 1  
fill ~2 ~0 ~8 ~4 ~0 ~8 tallgrass 1 
setblock ~2 ~0 ~9 red_flower 0  
fill ~2 ~0 ~10 ~5 ~0 ~10 tallgrass 1 
setblock ~2 ~0 ~11 yellow_flower 0 
setblock ~2 ~0 ~13 yellow_flower 0  
fill ~2 ~0 ~14 ~3 ~0 ~14 tallgrass 1  
fill ~2 ~0 ~15 ~2 ~0 ~14 tallgrass 1 
setblock ~2 ~0 ~16 red_flower 0 
setblock ~2 ~0 ~17 tallgrass 1 
setblock ~2 ~0 ~20 stone_brick_stairs 2  
fill ~2 ~0 ~21 ~2 ~4 ~21 stonebrick 0 
setblock ~2 ~0 ~22 stone_brick_stairs 3 
setblock ~2 ~0 ~29 stone_brick_stairs 2 
setblock ~2 ~0 ~30 stonebrick 0 
setblock ~2 ~0 ~31 stone_brick_stairs 3 
setblock ~2 ~0 ~34 yellow_flower 0  
fill ~2 ~0 ~35 ~2 ~0 ~37 tallgrass 1  
fill ~2 ~0 ~40 ~4 ~0 ~40 tallgrass 1  
fill ~2 ~0 ~41 ~3 ~0 ~41 tallgrass 1  
fill ~2 ~0 ~43 ~4 ~0 ~43 tallgrass 1 
setblock ~2 ~0 ~44 red_flower 0  
fill ~2 ~0 ~46 ~11 ~0 ~46 tallgrass 1  
fill ~2 ~0 ~48 ~9 ~0 ~48 tallgrass 1  
fill ~2 ~0 ~49 ~4 ~0 ~49 tallgrass 1 
setblock ~3 ~0 ~1 tallgrass 1  
fill ~3 ~0 ~9 ~6 ~0 ~9 tallgrass 1  
fill ~3 ~0 ~11 ~5 ~0 ~11 tallgrass 1 
setblock ~3 ~0 ~12 yellow_flower 0  
fill ~3 ~0 ~13 ~4 ~0 ~13 tallgrass 1 
setblock ~3 ~0 ~21 stone_brick_stairs 1 
setblock ~3 ~0 ~30 stone_brick_stairs 1  
fill ~3 ~0 ~37 ~3 ~0 ~41 tallgrass 1  
fill ~3 ~0 ~44 ~3 ~0 ~49 tallgrass 1 
setblock ~4 ~0 ~5 yellow_flower 0 
setblock ~4 ~0 ~38 tallgrass 1 
setblock ~4 ~0 ~41 red_flower 0  
fill ~4 ~0 ~42 ~5 ~0 ~42 tallgrass 1 
setblock ~4 ~0 ~44 yellow_flower 0  
fill ~4 ~0 ~45 ~5 ~0 ~45 tallgrass 1  
fill ~4 ~0 ~47 ~13 ~0 ~47 tallgrass 1 
setblock ~5 ~0 ~2 tallgrass 1  
fill ~5 ~0 ~4 ~5 ~0 ~7 tallgrass 1  
fill ~5 ~0 ~8 ~6 ~0 ~8 red_flower 0 
setblock ~5 ~0 ~12 stone_brick_stairs 0 
setblock ~5 ~0 ~39 stone_brick_stairs 0 
setblock ~5 ~0 ~41 tallgrass 1 
setblock ~5 ~0 ~43 yellow_flower 0  
fill ~5 ~0 ~44 ~7 ~0 ~44 tallgrass 1  
fill ~5 ~0 ~49 ~5 ~7 ~49 log 0 
setblock ~6 ~0 ~3 tallgrass 1  
fill ~6 ~0 ~5 ~11 ~0 ~5 tallgrass 1  
fill ~6 ~0 ~6 ~7 ~0 ~6 tallgrass 1  
fill ~6 ~0 ~7 ~8 ~0 ~7 tallgrass 1 
setblock ~6 ~0 ~11 stone_brick_stairs 2  
fill ~6 ~0 ~12 ~6 ~4 ~12 stonebrick 0 
setblock ~6 ~0 ~13 stone_brick_stairs 3 
setblock ~6 ~0 ~38 stone_brick_stairs 2  
fill ~6 ~0 ~39 ~6 ~4 ~39 stonebrick 0 
setblock ~6 ~0 ~40 stone_brick_stairs 3  
fill ~6 ~0 ~43 ~7 ~0 ~43 tallgrass 1 
setblock ~6 ~0 ~45 red_flower 0  
fill ~7 ~0 ~1 ~7 ~0 ~1 tallgrass 1  
fill ~7 ~0 ~4 ~13 ~0 ~4 tallgrass 1 
setblock ~7 ~0 ~8 tallgrass 1 
setblock ~7 ~0 ~12 stone_brick_stairs 1 
setblock ~7 ~0 ~39 stone_brick_stairs 1  
fill ~7 ~0 ~45 ~8 ~0 ~45 tallgrass 1  
fill ~7 ~0 ~49 ~16 ~0 ~49 tallgrass 1  
fill ~8 ~0 ~2 ~15 ~0 ~2 tallgrass 1  
fill ~8 ~0 ~3 ~13 ~0 ~3 tallgrass 1 
setblock ~8 ~0 ~6 yellow_flower 0  
fill ~9 ~0 ~1 ~11 ~0 ~1 tallgrass 1 
setblock ~9 ~0 ~6 tallgrass 1 
setblock ~9 ~0 ~45 red_flower 0 
setblock ~10 ~0 ~6 red_flower 0 
setblock ~10 ~0 ~45 yellow_flower 0 
setblock ~10 ~0 ~48 yellow_flower 0 
setblock ~11 ~0 ~6 stone_brick_stairs 0 
setblock ~11 ~0 ~13 stonebrick 0 
setblock ~11 ~0 ~21 stonebrick 0  
fill ~11 ~0 ~22 ~14 ~0 ~22 obsidian 0  
fill ~11 ~0 ~29 ~14 ~0 ~29 obsidian 0  
fill ~11 ~0 ~30 ~11 ~4 ~30 stonebrick 0 
setblock ~11 ~0 ~38 stonebrick 0 
setblock ~11 ~0 ~45 stone_brick_stairs 0  
fill ~11 ~0 ~48 ~14 ~0 ~48 tallgrass 1 
setblock ~12 ~0 ~1 yellow_flower 0 
setblock ~12 ~0 ~5 stone_brick_stairs 2  
fill ~12 ~0 ~6 ~12 ~4 ~6 stonebrick 0 
setblock ~12 ~0 ~7 stone_brick_stairs 3 
setblock ~12 ~0 ~12 fire 15  
fill ~12 ~0 ~13 ~13 ~0 ~13 stained_hardened_clay 15  
fill ~12 ~0 ~14 ~12 ~4 ~14 iron_bars 0  
fill ~12 ~0 ~15 ~12 ~7 ~15 iron_bars 0  
fill ~12 ~0 ~16 ~12 ~9 ~16 iron_bars 0  
fill ~12 ~0 ~17 ~12 ~11 ~17 iron_bars 0  
fill ~12 ~0 ~18 ~12 ~9 ~18 iron_bars 0  
fill ~12 ~0 ~19 ~12 ~7 ~19 iron_bars 0  
fill ~12 ~0 ~20 ~12 ~4 ~20 iron_bars 0  
fill ~12 ~0 ~21 ~13 ~0 ~21 stained_hardened_clay 15  
fill ~12 ~0 ~30 ~13 ~0 ~30 stained_hardened_clay 15  
fill ~12 ~0 ~31 ~12 ~4 ~31 iron_bars 0  
fill ~12 ~0 ~32 ~12 ~7 ~32 iron_bars 0  
fill ~12 ~0 ~33 ~12 ~9 ~33 iron_bars 0  
fill ~12 ~0 ~34 ~12 ~11 ~34 iron_bars 0  
fill ~12 ~0 ~35 ~12 ~9 ~35 iron_bars 0  
fill ~12 ~0 ~36 ~12 ~7 ~36 iron_bars 0  
fill ~12 ~0 ~37 ~12 ~4 ~37 iron_bars 0  
fill ~12 ~0 ~38 ~13 ~0 ~38 stained_hardened_clay 15 
setblock ~12 ~0 ~39 fire 15 
setblock ~12 ~0 ~44 stone_brick_stairs 2  
fill ~12 ~0 ~45 ~12 ~4 ~45 stonebrick 0 
setblock ~12 ~0 ~46 stone_brick_stairs 3  
fill ~13 ~0 ~1 ~18 ~0 ~1 tallgrass 1 
setblock ~13 ~0 ~6 stone_brick_stairs 1  
fill ~13 ~0 ~11 ~13 ~2 ~11 stonebrick 2  
fill ~13 ~0 ~12 ~13 ~4 ~12 stained_hardened_clay 15  
fill ~13 ~0 ~39 ~13 ~4 ~39 stained_hardened_clay 15 
setblock ~13 ~0 ~40 stonebrick 0 
setblock ~13 ~0 ~45 stone_brick_stairs 1  
fill ~14 ~0 ~12 ~20 ~0 ~12 iron_bars 0  
fill ~14 ~0 ~14 ~21 ~0 ~14 stonebrick 0  
fill ~14 ~0 ~15 ~14 ~0 ~21 stonebrick 0  
fill ~14 ~0 ~31 ~14 ~5 ~31 stonebrick 0  
fill ~14 ~0 ~32 ~14 ~0 ~37 stonebrick 0  
fill ~14 ~0 ~39 ~20 ~0 ~39 iron_bars 0  
fill ~15 ~0 ~23 ~15 ~2 ~23 cobblestone 0  
fill ~15 ~0 ~24 ~15 ~4 ~24 cobblestone 0  
fill ~15 ~0 ~27 ~15 ~4 ~27 cobblestone 0  
fill ~15 ~0 ~28 ~15 ~2 ~28 cobblestone 0  
fill ~15 ~0 ~30 ~16 ~0 ~30 nether_brick 0  
fill ~15 ~0 ~31 ~15 ~4 ~31 log 1  
fill ~15 ~0 ~32 ~15 ~0 ~35 log 1 
setblock ~15 ~0 ~36 torch 5  
fill ~15 ~0 ~37 ~20 ~0 ~37 stonebrick 0  
fill ~16 ~0 ~21 ~19 ~0 ~21 nether_brick 0  
fill ~16 ~0 ~36 ~20 ~0 ~36 log 1 
setblock ~18 ~0 ~18 glowstone 0  
fill ~18 ~0 ~30 ~19 ~0 ~30 nether_brick 0  
fill ~19 ~0 ~19 ~30 ~0 ~19 nether_brick 0  
fill ~19 ~0 ~20 ~19 ~5 ~20 nether_brick 0  
fill ~19 ~0 ~22 ~19 ~5 ~22 nether_brick 0  
fill ~19 ~0 ~23 ~19 ~5 ~23 nether_brick 0  
fill ~19 ~0 ~24 ~19 ~5 ~24 nether_brick 0  
fill ~19 ~0 ~25 ~19 ~5 ~25 nether_brick 0  
fill ~19 ~0 ~26 ~19 ~5 ~26 nether_brick 0  
fill ~19 ~0 ~27 ~19 ~5 ~27 nether_brick 0  
fill ~19 ~0 ~28 ~24 ~0 ~28 nether_brick 0  
fill ~19 ~0 ~29 ~19 ~5 ~29 nether_brick 0  
fill ~19 ~0 ~31 ~19 ~5 ~31 nether_brick 0  
fill ~19 ~0 ~32 ~19 ~5 ~32 nether_brick 0 
setblock ~20 ~0 ~2 stone_brick_stairs 0  
fill ~20 ~0 ~20 ~20 ~5 ~20 bookshelf 0  
fill ~20 ~0 ~21 ~20 ~5 ~21 bookshelf 0  
fill ~20 ~0 ~22 ~20 ~5 ~22 bookshelf 0  
fill ~20 ~0 ~23 ~20 ~5 ~23 bookshelf 0  
fill ~20 ~0 ~24 ~20 ~5 ~24 bookshelf 0  
fill ~20 ~0 ~25 ~20 ~5 ~25 bookshelf 0  
fill ~20 ~0 ~26 ~20 ~5 ~26 bookshelf 0  
fill ~20 ~0 ~27 ~20 ~5 ~27 bookshelf 0 
setblock ~20 ~0 ~49 stone_brick_stairs 0 
setblock ~21 ~0 ~1 stone_brick_stairs 2  
fill ~21 ~0 ~2 ~21 ~4 ~2 stonebrick 0 
setblock ~21 ~0 ~3 stone_brick_stairs 3  
fill ~21 ~0 ~11 ~21 ~4 ~11 stonebrick 0  
fill ~21 ~0 ~12 ~21 ~4 ~12 stained_hardened_clay 15  
fill ~21 ~0 ~13 ~21 ~3 ~13 stained_hardened_clay 15  
fill ~21 ~0 ~16 ~21 ~5 ~16 nether_brick 0  
fill ~21 ~0 ~17 ~21 ~5 ~17 nether_brick 0  
fill ~21 ~0 ~18 ~21 ~5 ~18 nether_brick 0  
fill ~21 ~0 ~32 ~27 ~0 ~32 nether_brick 0  
fill ~21 ~0 ~33 ~21 ~5 ~33 nether_brick 0  
fill ~21 ~0 ~34 ~21 ~5 ~34 nether_brick 0  
fill ~21 ~0 ~35 ~21 ~5 ~35 nether_brick 0  
fill ~21 ~0 ~36 ~21 ~5 ~36 nether_brick 0  
fill ~21 ~0 ~38 ~21 ~3 ~38 stained_hardened_clay 15  
fill ~21 ~0 ~39 ~21 ~4 ~39 stained_hardened_clay 15  
fill ~21 ~0 ~40 ~21 ~4 ~40 stonebrick 0 
setblock ~21 ~0 ~48 stone_brick_stairs 2  
fill ~21 ~0 ~49 ~21 ~4 ~49 stonebrick 0 
setblock ~22 ~0 ~2 stone_brick_stairs 1  
fill ~22 ~0 ~11 ~22 ~2 ~11 obsidian 0  
fill ~22 ~0 ~12 ~22 ~2 ~12 obsidian 0  
fill ~22 ~0 ~13 ~22 ~2 ~13 obsidian 0  
fill ~22 ~0 ~14 ~22 ~4 ~14 obsidian 0  
fill ~22 ~0 ~37 ~22 ~4 ~37 obsidian 0  
fill ~22 ~0 ~38 ~22 ~2 ~38 obsidian 0  
fill ~22 ~0 ~39 ~22 ~2 ~39 obsidian 0  
fill ~22 ~0 ~40 ~22 ~2 ~40 obsidian 0 
setblock ~22 ~0 ~49 stone_brick_stairs 1  
fill ~23 ~0 ~15 ~24 ~0 ~15 cobblestone 0  
fill ~23 ~0 ~36 ~24 ~0 ~36 cobblestone 0  
fill ~24 ~0 ~20 ~24 ~10 ~20 nether_brick 0  
fill ~24 ~0 ~21 ~24 ~10 ~21 nether_brick 0  
fill ~24 ~0 ~22 ~24 ~10 ~22 nether_brick 0  
fill ~24 ~0 ~23 ~24 ~10 ~23 nether_brick 0  
fill ~24 ~0 ~24 ~24 ~10 ~24 nether_brick 0 
setblock ~24 ~0 ~25 dispenser 1  
fill ~25 ~0 ~25 ~32 ~0 ~25 nether_brick 0  
fill ~26 ~0 ~26 ~26 ~5 ~26 nether_brick 0  
fill ~26 ~0 ~28 ~26 ~5 ~28 nether_brick 0  
fill ~26 ~0 ~29 ~26 ~5 ~29 nether_brick 0  
fill ~26 ~0 ~30 ~26 ~5 ~30 nether_brick 0  
fill ~26 ~0 ~31 ~26 ~5 ~31 nether_brick 0  
fill ~27 ~0 ~15 ~28 ~0 ~15 cobblestone 0   
fill ~27 ~0 ~22 ~29 ~0 ~22 iron_bars 0  
fill ~27 ~0 ~36 ~28 ~0 ~36 cobblestone 0  
fill ~28 ~0 ~20 ~28 ~0 ~21 spruce_stairs 4 
setblock ~29 ~0 ~2 stone_brick_stairs 0  
fill ~29 ~0 ~11 ~29 ~2 ~11 obsidian 0  
fill ~29 ~0 ~12 ~29 ~2 ~12 obsidian 0  
fill ~29 ~0 ~13 ~29 ~2 ~13 obsidian 0  
fill ~29 ~0 ~14 ~29 ~4 ~14 obsidian 0  
fill ~29 ~0 ~20 ~29 ~0 ~21 spruce_stairs 1  
fill ~29 ~0 ~32 ~33 ~0 ~32 nether_brick 0  
fill ~29 ~0 ~37 ~29 ~4 ~37 obsidian 0  
fill ~29 ~0 ~38 ~29 ~2 ~38 obsidian 0  
fill ~29 ~0 ~39 ~29 ~2 ~39 obsidian 0  
fill ~29 ~0 ~40 ~29 ~2 ~40 obsidian 0 
setblock ~29 ~0 ~49 stone_brick_stairs 0 
setblock ~30 ~0 ~1 stone_brick_stairs 2  
fill ~30 ~0 ~2 ~30 ~4 ~2 stonebrick 0 
setblock ~30 ~0 ~3 stone_brick_stairs 3 
setblock ~30 ~0 ~11 stonebrick 0  
fill ~30 ~0 ~12 ~30 ~4 ~12 stained_hardened_clay 15  
fill ~30 ~0 ~13 ~30 ~3 ~13 stained_hardened_clay 15  
fill ~30 ~0 ~15 ~30 ~5 ~15 nether_brick 0  
fill ~30 ~0 ~16 ~30 ~5 ~16 nether_brick 0  
fill ~30 ~0 ~17 ~30 ~5 ~17 nether_brick 0  
fill ~30 ~0 ~18 ~30 ~5 ~18 nether_brick 0  
fill ~30 ~0 ~33 ~30 ~5 ~33 nether_brick 0  
fill ~30 ~0 ~34 ~30 ~5 ~34 nether_brick 0  
fill ~30 ~0 ~35 ~30 ~5 ~35 nether_brick 0  
fill ~30 ~0 ~36 ~30 ~5 ~36 nether_brick 0  
fill ~30 ~0 ~38 ~30 ~3 ~38 stained_hardened_clay 15  
fill ~30 ~0 ~39 ~30 ~4 ~39 stained_hardened_clay 15  
fill ~30 ~0 ~40 ~30 ~1 ~40 stonebrick 0 
setblock ~30 ~0 ~48 stone_brick_stairs 2  
fill ~30 ~0 ~49 ~30 ~4 ~49 stonebrick 0  
fill ~31 ~0 ~1 ~33 ~0 ~1 tallgrass 1 
setblock ~31 ~0 ~2 stone_brick_stairs 1  
fill ~31 ~0 ~12 ~37 ~0 ~12 iron_bars 0  
fill ~31 ~0 ~14 ~37 ~0 ~14 stonebrick 0  
fill ~31 ~0 ~15 ~36 ~0 ~15 bookshelf 0 
setblock ~31 ~0 ~35 crafting_table 0  
fill ~31 ~0 ~36 ~36 ~0 ~36 bookshelf 0  
fill ~31 ~0 ~37 ~37 ~0 ~37 stonebrick 0  
fill ~31 ~0 ~39 ~37 ~0 ~39 iron_bars 0 
setblock ~31 ~0 ~49 stone_brick_stairs 1  
fill ~32 ~0 ~19 ~32 ~10 ~19 nether_brick 0  
fill ~32 ~0 ~20 ~32 ~10 ~20 nether_brick 0  
fill ~32 ~0 ~21 ~35 ~0 ~21 nether_brick 0  
fill ~32 ~0 ~22 ~32 ~10 ~22 nether_brick 0  
fill ~32 ~0 ~23 ~32 ~10 ~23 nether_brick 0  
fill ~32 ~0 ~24 ~32 ~10 ~24 nether_brick 0  
fill ~32 ~0 ~26 ~32 ~5 ~26 nether_brick 0  
fill ~32 ~0 ~27 ~32 ~5 ~27 nether_brick 0  
fill ~32 ~0 ~28 ~32 ~5 ~28 nether_brick 0  
fill ~32 ~0 ~29 ~32 ~5 ~29 nether_brick 0  
fill ~32 ~0 ~30 ~36 ~0 ~30 nether_brick 0 
setblock ~33 ~0 ~20 dispenser 1 
setblock ~33 ~0 ~34 glowstone 0 
setblock ~34 ~0 ~1 red_flower 0 
setblock ~34 ~0 ~2 yellow_flower 0  
fill ~34 ~0 ~49 ~34 ~0 ~49 tallgrass 1  
fill ~35 ~0 ~1 ~38 ~0 ~1 tallgrass 1  
fill ~35 ~0 ~2 ~38 ~0 ~2 tallgrass 1  
fill ~36 ~0 ~23 ~36 ~2 ~23 cobblestone 0  
fill ~36 ~0 ~24 ~36 ~4 ~24 cobblestone 0  
fill ~36 ~0 ~27 ~36 ~4 ~27 cobblestone 0  
fill ~36 ~0 ~28 ~36 ~2 ~28 cobblestone 0 
setblock ~36 ~0 ~49 yellow_flower 0  
fill ~37 ~0 ~15 ~37 ~0 ~21 stonebrick 0  
fill ~37 ~0 ~22 ~40 ~0 ~22 obsidian 0  
fill ~37 ~0 ~29 ~40 ~0 ~29 obsidian 0  
fill ~37 ~0 ~31 ~37 ~5 ~31 stonebrick 0  
fill ~37 ~0 ~32 ~37 ~0 ~37 stonebrick 0 
setblock ~38 ~0 ~6 stone_brick_stairs 0  
fill ~38 ~0 ~11 ~38 ~1 ~11 stonebrick 0  
fill ~38 ~0 ~12 ~38 ~4 ~12 stained_hardened_clay 15  
fill ~38 ~0 ~13 ~39 ~0 ~13 stained_hardened_clay 15  
fill ~38 ~0 ~21 ~39 ~0 ~21 stained_hardened_clay 15  
fill ~38 ~0 ~30 ~39 ~0 ~30 stained_hardened_clay 15  
fill ~38 ~0 ~38 ~39 ~0 ~38 stained_hardened_clay 15  
fill ~38 ~0 ~39 ~38 ~4 ~39 stained_hardened_clay 15 
setblock ~38 ~0 ~40 stonebrick 0 
setblock ~38 ~0 ~45 stone_brick_stairs 0  
fill ~38 ~0 ~47 ~40 ~0 ~47 tallgrass 1  
fill ~38 ~0 ~49 ~39 ~0 ~49 tallgrass 1  
fill ~39 ~0 ~3 ~44 ~0 ~3 tallgrass 1  
fill ~39 ~0 ~4 ~39 ~0 ~3 tallgrass 1 
setblock ~39 ~0 ~5 stone_brick_stairs 2  
fill ~39 ~0 ~6 ~39 ~4 ~6 stonebrick 0 
setblock ~39 ~0 ~7 stone_brick_stairs 3 
setblock ~39 ~0 ~12 fire 15  
fill ~39 ~0 ~14 ~39 ~4 ~14 iron_bars 0  
fill ~39 ~0 ~15 ~39 ~7 ~15 iron_bars 0  
fill ~39 ~0 ~16 ~39 ~9 ~16 iron_bars 0  
fill ~39 ~0 ~17 ~39 ~11 ~17 iron_bars 0  
fill ~39 ~0 ~18 ~39 ~9 ~18 iron_bars 0  
fill ~39 ~0 ~19 ~39 ~7 ~19 iron_bars 0  
fill ~39 ~0 ~20 ~39 ~4 ~20 iron_bars 0  
fill ~39 ~0 ~31 ~39 ~4 ~31 iron_bars 0  
fill ~39 ~0 ~32 ~39 ~7 ~32 iron_bars 0  
fill ~39 ~0 ~33 ~39 ~9 ~33 iron_bars 0  
fill ~39 ~0 ~34 ~39 ~11 ~34 iron_bars 0  
fill ~39 ~0 ~35 ~39 ~9 ~35 iron_bars 0  
fill ~39 ~0 ~36 ~39 ~7 ~36 iron_bars 0  
fill ~39 ~0 ~37 ~39 ~4 ~37 iron_bars 0 
setblock ~39 ~0 ~39 fire 15 
setblock ~39 ~0 ~44 stone_brick_stairs 2  
fill ~39 ~0 ~45 ~39 ~4 ~45 stonebrick 0 
setblock ~39 ~0 ~46 stone_brick_stairs 3 
setblock ~39 ~0 ~48 yellow_flower 0  
fill ~40 ~0 ~1 ~44 ~0 ~1 tallgrass 1  
fill ~40 ~0 ~2 ~42 ~0 ~2 tallgrass 1  
fill ~40 ~0 ~5 ~42 ~0 ~5 tallgrass 1 
setblock ~40 ~0 ~6 stone_brick_stairs 1  
fill ~40 ~0 ~13 ~40 ~1 ~13 stonebrick 2  
fill ~40 ~0 ~21 ~40 ~2 ~21 stonebrick 0  
fill ~40 ~0 ~30 ~40 ~2 ~30 stonebrick 2  
fill ~40 ~0 ~38 ~40 ~2 ~38 stonebrick 0 
setblock ~40 ~0 ~45 stone_brick_stairs 1 
setblock ~40 ~0 ~46 tallgrass 1  
fill ~40 ~0 ~48 ~42 ~0 ~48 tallgrass 1 
setblock ~40 ~0 ~49 red_flower 0  
fill ~41 ~0 ~4 ~42 ~0 ~4 tallgrass 1  
fill ~41 ~0 ~6 ~42 ~0 ~6 tallgrass 1 
setblock ~41 ~0 ~45 tallgrass 1 
setblock ~41 ~0 ~47 yellow_flower 0  
fill ~41 ~0 ~49 ~47 ~0 ~49 tallgrass 1 
setblock ~42 ~0 ~47 tallgrass 1 
setblock ~43 ~0 ~2 red_flower 0  
fill ~43 ~0 ~4 ~43 ~0 ~5 yellow_flower 0 
setblock ~43 ~0 ~6 red_flower 0  
fill ~43 ~0 ~7 ~46 ~0 ~7 tallgrass 1  
fill ~43 ~0 ~44 ~49 ~0 ~44 tallgrass 1  
fill ~43 ~0 ~45 ~50 ~0 ~45 tallgrass 1  
fill ~43 ~0 ~46 ~50 ~0 ~46 tallgrass 1  
fill ~44 ~0 ~2 ~47 ~0 ~2 tallgrass 1  
fill ~44 ~0 ~4 ~49 ~0 ~4 tallgrass 1 
setblock ~44 ~0 ~5 yellow_flower 0  
fill ~44 ~0 ~6 ~45 ~0 ~6 tallgrass 1 
setblock ~44 ~0 ~12 stone_brick_stairs 0 
setblock ~44 ~0 ~39 stone_brick_stairs 0  
fill ~44 ~0 ~43 ~46 ~0 ~43 tallgrass 1  
fill ~44 ~0 ~47 ~49 ~0 ~47 tallgrass 1  
fill ~44 ~0 ~48 ~44 ~0 ~43 tallgrass 1  
fill ~45 ~0 ~5 ~50 ~0 ~5 tallgrass 1  
fill ~45 ~0 ~9 ~47 ~0 ~9 tallgrass 1  
fill ~45 ~0 ~10 ~47 ~0 ~10 tallgrass 1 
setblock ~45 ~0 ~11 stone_brick_stairs 2  
fill ~45 ~0 ~12 ~45 ~4 ~12 stonebrick 0 
setblock ~45 ~0 ~13 stone_brick_stairs 3 
setblock ~45 ~0 ~38 stone_brick_stairs 2  
fill ~45 ~0 ~39 ~45 ~4 ~39 stonebrick 0 
setblock ~45 ~0 ~40 stone_brick_stairs 3 
setblock ~45 ~0 ~48 red_flower 0  
fill ~46 ~0 ~1 ~46 ~0 ~1 tallgrass 1  
fill ~46 ~0 ~3 ~48 ~0 ~3 tallgrass 1 
setblock ~46 ~0 ~8 tallgrass 1 
setblock ~46 ~0 ~11 tallgrass 1 
setblock ~46 ~0 ~12 stone_brick_stairs 1 
setblock ~46 ~0 ~39 stone_brick_stairs 1 
setblock ~46 ~0 ~40 tallgrass 1 
setblock ~46 ~0 ~42 tallgrass 1 
setblock ~46 ~0 ~48 tallgrass 1 
setblock ~47 ~0 ~1 yellow_flower 0 
setblock ~47 ~0 ~6 tallgrass 1  
fill ~47 ~0 ~8 ~47 ~2 ~8 log2 0 
setblock ~47 ~0 ~13 tallgrass 1 
setblock ~47 ~0 ~39 tallgrass 1 
setblock ~47 ~0 ~42 yellow_flower 0 
setblock ~47 ~0 ~43 red_flower 0 
setblock ~47 ~0 ~48 red_flower 0 
setblock ~48 ~0 ~2 yellow_flower 0  
fill ~48 ~0 ~8 ~49 ~0 ~8 tallgrass 1 
setblock ~48 ~0 ~9 yellow_flower 0  
fill ~48 ~0 ~11 ~50 ~0 ~11 tallgrass 1  
fill ~48 ~0 ~12 ~48 ~0 ~11 tallgrass 1  
fill ~48 ~0 ~14 ~50 ~0 ~14 tallgrass 1 
setblock ~48 ~0 ~21 stone_brick_stairs 0 
setblock ~48 ~0 ~30 stone_brick_stairs 0  
fill ~48 ~0 ~37 ~50 ~0 ~37 tallgrass 1  
fill ~48 ~0 ~40 ~50 ~0 ~40 tallgrass 1  
fill ~48 ~0 ~42 ~49 ~0 ~42 tallgrass 1  
fill ~48 ~0 ~43 ~48 ~0 ~42 tallgrass 1  
fill ~49 ~0 ~1 ~49 ~0 ~1 tallgrass 1  
fill ~49 ~0 ~6 ~50 ~0 ~6 tallgrass 1  
fill ~49 ~0 ~7 ~50 ~0 ~7 tallgrass 1 
setblock ~49 ~0 ~12 red_flower 0  
fill ~49 ~0 ~13 ~50 ~0 ~13 tallgrass 1  
fill ~49 ~0 ~15 ~50 ~0 ~15 tallgrass 1 
setblock ~49 ~0 ~17 tallgrass 1 
setblock ~49 ~0 ~20 stone_brick_stairs 2  
fill ~49 ~0 ~21 ~49 ~4 ~21 stonebrick 0 
setblock ~49 ~0 ~22 stone_brick_stairs 3 
setblock ~49 ~0 ~29 stone_brick_stairs 2  
fill ~49 ~0 ~30 ~49 ~4 ~30 stonebrick 0 
setblock ~49 ~0 ~31 stone_brick_stairs 3  
fill ~49 ~0 ~38 ~50 ~0 ~38 tallgrass 1  
fill ~49 ~0 ~39 ~50 ~0 ~39 tallgrass 1  
fill ~49 ~0 ~41 ~50 ~0 ~41 tallgrass 1 
setblock ~49 ~0 ~43 yellow_flower 0 
setblock ~49 ~0 ~48 tallgrass 1  
fill ~49 ~0 ~49 ~49 ~5 ~49 log2 0  
fill ~50 ~0 ~2 ~50 ~0 ~2 tallgrass 1  
fill ~50 ~0 ~4 ~50 ~3 ~4 log2 0 
setblock ~50 ~0 ~9 tallgrass 1  
fill ~50 ~0 ~10 ~50 ~3 ~10 log2 0  
fill ~50 ~0 ~12 ~50 ~0 ~12 tallgrass 1  
fill ~50 ~0 ~16 ~50 ~0 ~16 tallgrass 1 
setblock ~50 ~0 ~21 stone_brick_stairs 1 
setblock ~50 ~0 ~30 stone_brick_stairs 1  
fill ~50 ~0 ~32 ~50 ~0 ~32 tallgrass 1  
fill ~50 ~0 ~33 ~50 ~0 ~33 tallgrass 1  
fill ~50 ~0 ~34 ~50 ~0 ~41 tallgrass 1 
setblock ~50 ~0 ~47 yellow_flower 0 
setblock ~50 ~0 ~49 tallgrass 1  
fill ~2 ~1 ~30 ~2 ~3 ~30 stonebrick 2  
fill ~11 ~1 ~13 ~11 ~3 ~13 stonebrick 2  
fill ~11 ~1 ~21 ~11 ~3 ~21 stonebrick 2  
fill ~11 ~1 ~22 ~14 ~1 ~22 obsidian 0  
fill ~11 ~1 ~29 ~14 ~1 ~29 obsidian 0  
fill ~11 ~1 ~38 ~11 ~3 ~38 stonebrick 2  
fill ~12 ~1 ~13 ~13 ~1 ~13 stained_hardened_clay 15  
fill ~12 ~1 ~21 ~13 ~1 ~21 stained_hardened_clay 15  
fill ~12 ~1 ~30 ~13 ~1 ~30 stained_hardened_clay 15  
fill ~12 ~1 ~38 ~13 ~1 ~38 stained_hardened_clay 15  
fill ~13 ~1 ~40 ~13 ~2 ~40 stonebrick 2  
fill ~14 ~1 ~12 ~20 ~1 ~12 iron_bars 0  
fill ~14 ~1 ~14 ~14 ~4 ~14 stonebrick 0  
fill ~14 ~1 ~15 ~14 ~1 ~19 stone_brick_stairs 0  
fill ~14 ~1 ~20 ~14 ~5 ~20 stonebrick 0  
fill ~14 ~1 ~21 ~14 ~4 ~21 stonebrick 0 
setblock ~14 ~1 ~32 stone_brick_stairs 3  
fill ~14 ~1 ~33 ~14 ~1 ~35 stone_brick_stairs 0 
setblock ~14 ~1 ~36 stone_brick_stairs 2  
fill ~14 ~1 ~37 ~14 ~4 ~37 stonebrick 0  
fill ~14 ~1 ~39 ~20 ~1 ~39 iron_bars 0  
fill ~15 ~1 ~14 ~19 ~1 ~14 stone_brick_stairs 2  
fill ~15 ~1 ~30 ~16 ~1 ~30 nether_brick 0  
fill ~15 ~1 ~32 ~15 ~3 ~32 bookshelf 0  
fill ~15 ~1 ~33 ~15 ~3 ~33 bookshelf 0  
fill ~15 ~1 ~34 ~15 ~3 ~34 bookshelf 0  
fill ~15 ~1 ~35 ~15 ~4 ~35 log 1  
fill ~15 ~1 ~37 ~19 ~1 ~37 stone_brick_stairs 3  
fill ~16 ~1 ~21 ~19 ~1 ~21 nether_brick 0  
fill ~16 ~1 ~36 ~16 ~4 ~36 log 1  
fill ~17 ~1 ~36 ~19 ~1 ~36 bookshelf 0  
fill ~18 ~1 ~30 ~19 ~1 ~30 nether_brick 0  
fill ~19 ~1 ~19 ~30 ~1 ~19 nether_brick 0  
fill ~19 ~1 ~28 ~24 ~1 ~28 nether_brick 0  
fill ~20 ~1 ~14 ~21 ~1 ~14 stonebrick 0  
fill ~20 ~1 ~36 ~20 ~4 ~36 log 1  
fill ~20 ~1 ~37 ~20 ~5 ~37 stonebrick 0  
fill ~21 ~1 ~32 ~27 ~1 ~32 nether_brick 0  
fill ~23 ~1 ~15 ~24 ~1 ~15 cobblestone 0  
fill ~23 ~1 ~36 ~24 ~1 ~36 cobblestone 0 
setblock ~24 ~1 ~25 redstone_torch 5  
fill ~25 ~1 ~25 ~32 ~1 ~25 nether_brick 0  
fill ~27 ~1 ~15 ~28 ~1 ~15 cobblestone 0  
fill ~27 ~1 ~20 ~27 ~1 ~21 spruce_stairs 4  
fill ~27 ~1 ~22 ~29 ~1 ~22 iron_bars 0  
fill ~27 ~1 ~36 ~28 ~1 ~36 cobblestone 0  
fill ~28 ~1 ~20 ~28 ~1 ~21 spruce_stairs 1  
fill ~29 ~1 ~32 ~33 ~1 ~32 nether_brick 0  
fill ~30 ~1 ~11 ~30 ~2 ~11 stonebrick 2  
fill ~31 ~1 ~12 ~37 ~1 ~12 iron_bars 0  
fill ~31 ~1 ~14 ~31 ~5 ~14 stonebrick 0  
fill ~31 ~1 ~15 ~36 ~1 ~15 bookshelf 0 
setblock ~31 ~1 ~35 redstone_torch 5  
fill ~31 ~1 ~36 ~36 ~1 ~36 bookshelf 0  
fill ~31 ~1 ~37 ~31 ~5 ~37 stonebrick 0  
fill ~31 ~1 ~39 ~37 ~1 ~39 iron_bars 0  
fill ~32 ~1 ~14 ~36 ~1 ~14 stone_brick_stairs 2  
fill ~32 ~1 ~21 ~35 ~1 ~21 nether_brick 0  
fill ~32 ~1 ~30 ~36 ~1 ~30 nether_brick 0  
fill ~32 ~1 ~37 ~36 ~1 ~37 stone_brick_stairs 3 
setblock ~33 ~1 ~20 redstone_torch 5  
fill ~37 ~1 ~14 ~37 ~4 ~14 stonebrick 0  
fill ~37 ~1 ~15 ~37 ~1 ~19 stone_brick_stairs 1  
fill ~37 ~1 ~20 ~37 ~5 ~20 stonebrick 0  
fill ~37 ~1 ~21 ~37 ~2 ~21 stonebrick 0  
fill ~37 ~1 ~22 ~40 ~1 ~22 obsidian 0  
fill ~37 ~1 ~29 ~40 ~1 ~29 obsidian 0  
fill ~37 ~1 ~32 ~37 ~1 ~36 stone_brick_stairs 1  
fill ~37 ~1 ~37 ~37 ~4 ~37 stonebrick 0  
fill ~38 ~1 ~13 ~39 ~1 ~13 stained_hardened_clay 15  
fill ~38 ~1 ~21 ~39 ~1 ~21 stained_hardened_clay 15  
fill ~38 ~1 ~30 ~39 ~1 ~30 stained_hardened_clay 15  
fill ~38 ~1 ~38 ~39 ~1 ~38 stained_hardened_clay 15  
fill ~38 ~1 ~40 ~38 ~2 ~40 stonebrick 2 
setblock ~47 ~1 ~9 log2 0  
fill ~11 ~2 ~22 ~14 ~2 ~22 obsidian 0  
fill ~11 ~2 ~29 ~14 ~2 ~29 obsidian 0  
fill ~12 ~2 ~13 ~13 ~2 ~13 stained_hardened_clay 15  
fill ~12 ~2 ~21 ~13 ~2 ~21 stained_hardened_clay 15  
fill ~12 ~2 ~30 ~13 ~2 ~30 stained_hardened_clay 15  
fill ~12 ~2 ~38 ~13 ~2 ~38 stained_hardened_clay 15  
fill ~14 ~2 ~12 ~20 ~2 ~12 iron_bars 0 
setblock ~14 ~2 ~15 stone_brick_stairs 7  
fill ~14 ~2 ~16 ~14 ~2 ~18 stone_brick_stairs 4 
setblock ~14 ~2 ~19 stone_brick_stairs 6  
fill ~14 ~2 ~32 ~14 ~7 ~32 stonebrick 0  
fill ~14 ~2 ~33 ~14 ~2 ~35 stone_brick_stairs 4  
fill ~14 ~2 ~36 ~14 ~7 ~36 stonebrick 0  
fill ~14 ~2 ~39 ~20 ~2 ~39 iron_bars 0 
setblock ~15 ~2 ~14 stone_brick_stairs 5  
fill ~15 ~2 ~30 ~16 ~2 ~30 nether_brick 0 
setblock ~15 ~2 ~37 stone_brick_stairs 5  
fill ~16 ~2 ~14 ~18 ~2 ~14 stone_brick_stairs 6  
fill ~16 ~2 ~21 ~19 ~2 ~21 nether_brick 0  
fill ~16 ~2 ~37 ~18 ~2 ~37 stone_brick_stairs 7  
fill ~17 ~2 ~36 ~19 ~2 ~36 bookshelf 0  
fill ~18 ~2 ~30 ~19 ~2 ~30 nether_brick 0 
setblock ~19 ~2 ~14 stone_brick_stairs 4  
fill ~19 ~2 ~19 ~30 ~2 ~19 nether_brick 0  
fill ~19 ~2 ~28 ~24 ~2 ~28 nether_brick 0 
setblock ~19 ~2 ~37 stone_brick_stairs 4  
fill ~20 ~2 ~14 ~21 ~2 ~14 stonebrick 0  
fill ~21 ~2 ~32 ~27 ~2 ~32 nether_brick 0  
fill ~23 ~2 ~15 ~24 ~2 ~15 cobblestone 0  
fill ~23 ~2 ~36 ~24 ~2 ~36 cobblestone 0  
fill ~25 ~2 ~20 ~25 ~2 ~21 spruce_stairs 5  
fill ~25 ~2 ~22 ~26 ~2 ~22 spruce_stairs 7 
setblock ~25 ~2 ~24 redstone_torch 1  
fill ~25 ~2 ~25 ~32 ~2 ~25 nether_brick 0  
fill ~26 ~2 ~20 ~26 ~2 ~21 spruce_stairs 4  
fill ~27 ~2 ~15 ~28 ~2 ~15 cobblestone 0  
fill ~27 ~2 ~20 ~27 ~2 ~21 spruce_stairs 1  
fill ~27 ~2 ~22 ~29 ~2 ~22 iron_bars 0  
fill ~27 ~2 ~36 ~28 ~2 ~36 cobblestone 0  
fill ~29 ~2 ~32 ~33 ~2 ~32 nether_brick 0  
fill ~30 ~2 ~40 ~30 ~3 ~40 stonebrick 2  
fill ~31 ~2 ~12 ~37 ~2 ~12 iron_bars 0  
fill ~31 ~2 ~15 ~36 ~2 ~15 bookshelf 0  
fill ~31 ~2 ~36 ~36 ~2 ~36 bookshelf 0  
fill ~31 ~2 ~39 ~37 ~2 ~39 iron_bars 0 
setblock ~32 ~2 ~14 stone_brick_stairs 5  
fill ~32 ~2 ~21 ~35 ~2 ~21 nether_brick 0  
fill ~32 ~2 ~30 ~36 ~2 ~30 nether_brick 0 
setblock ~32 ~2 ~37 stone_brick_stairs 5  
fill ~33 ~2 ~14 ~35 ~2 ~14 stone_brick_stairs 6  
fill ~33 ~2 ~37 ~35 ~2 ~37 stone_brick_stairs 7 
setblock ~36 ~2 ~14 stone_brick_stairs 4 
setblock ~36 ~2 ~37 stone_brick_stairs 4 
setblock ~37 ~2 ~15 stone_brick_stairs 7  
fill ~37 ~2 ~16 ~37 ~2 ~18 stone_brick_stairs 5 
setblock ~37 ~2 ~19 stone_brick_stairs 6  
fill ~37 ~2 ~22 ~40 ~2 ~22 obsidian 0  
fill ~37 ~2 ~29 ~40 ~2 ~29 obsidian 0 
setblock ~37 ~2 ~32 stone_brick_stairs 7  
fill ~37 ~2 ~33 ~37 ~2 ~35 stone_brick_stairs 5 
setblock ~37 ~2 ~36 stone_brick_stairs 6  
fill ~38 ~2 ~11 ~38 ~3 ~11 stonebrick 2  
fill ~38 ~2 ~13 ~39 ~2 ~13 stained_hardened_clay 15  
fill ~38 ~2 ~21 ~39 ~2 ~21 stained_hardened_clay 15  
fill ~38 ~2 ~30 ~39 ~2 ~30 stained_hardened_clay 15  
fill ~38 ~2 ~38 ~39 ~2 ~38 stained_hardened_clay 15  
fill ~40 ~2 ~13 ~40 ~4 ~13 stonebrick 0 
setblock ~47 ~2 ~10 log2 0  
fill ~1 ~3 ~48 ~1 ~3 ~48 leaves2 0  
fill ~1 ~3 ~49 ~2 ~3 ~49 leaves2 0  
fill ~11 ~3 ~23 ~14 ~3 ~23 obsidian 0  
fill ~11 ~3 ~28 ~14 ~3 ~28 obsidian 0  
fill ~12 ~3 ~13 ~13 ~3 ~13 stained_hardened_clay 15  
fill ~12 ~3 ~21 ~13 ~3 ~21 stained_hardened_clay 15  
fill ~12 ~3 ~30 ~13 ~3 ~30 stained_hardened_clay 15  
fill ~12 ~3 ~38 ~13 ~3 ~38 stained_hardened_clay 15  
fill ~13 ~3 ~11 ~13 ~4 ~11 stonebrick 0  
fill ~13 ~3 ~22 ~13 ~4 ~22 stained_hardened_clay 15  
fill ~13 ~3 ~29 ~13 ~4 ~29 stained_hardened_clay 15  
fill ~13 ~3 ~40 ~13 ~4 ~40 stonebrick 0  
fill ~14 ~3 ~12 ~20 ~3 ~12 iron_bars 0  
fill ~14 ~3 ~15 ~14 ~7 ~15 stonebrick 0  
fill ~14 ~3 ~16 ~14 ~3 ~21 stonebrick 0  
fill ~14 ~3 ~22 ~14 ~4 ~22 obsidian 0  
fill ~14 ~3 ~29 ~14 ~4 ~29 obsidian 0 
setblock ~14 ~3 ~30 stonebrick 0  
fill ~14 ~3 ~33 ~14 ~3 ~37 stonebrick 0  
fill ~14 ~3 ~39 ~20 ~3 ~39 iron_bars 0  
fill ~15 ~3 ~14 ~20 ~3 ~14 stonebrick 0  
fill ~15 ~3 ~21 ~19 ~3 ~21 nether_brick 0 
setblock ~15 ~3 ~25 stone_stairs 7 
setblock ~15 ~3 ~26 stone_stairs 6  
fill ~15 ~3 ~30 ~19 ~3 ~30 nether_brick 0  
fill ~15 ~3 ~36 ~15 ~4 ~36 torch 1  
fill ~15 ~3 ~37 ~20 ~3 ~37 stonebrick 0  
fill ~17 ~3 ~36 ~19 ~3 ~36 bookshelf 0  
fill ~19 ~3 ~19 ~32 ~3 ~19 nether_brick 0  
fill ~19 ~3 ~28 ~26 ~3 ~28 nether_brick 0 
setblock ~20 ~3 ~31 redstone_torch 4  
fill ~20 ~3 ~32 ~33 ~3 ~32 nether_brick 0  
fill ~21 ~3 ~15 ~21 ~5 ~15 nether_brick 0  
fill ~22 ~3 ~13 ~22 ~4 ~13 stained_hardened_clay 15  
fill ~22 ~3 ~38 ~22 ~4 ~38 stained_hardened_clay 15  
fill ~23 ~3 ~11 ~23 ~4 ~11 obsidian 0  
fill ~23 ~3 ~12 ~23 ~4 ~12 obsidian 0  
fill ~23 ~3 ~13 ~23 ~4 ~13 obsidian 0  
fill ~23 ~3 ~14 ~23 ~4 ~14 obsidian 0  
fill ~23 ~3 ~37 ~23 ~4 ~37 obsidian 0  
fill ~23 ~3 ~38 ~23 ~4 ~38 obsidian 0  
fill ~23 ~3 ~39 ~23 ~4 ~39 obsidian 0  
fill ~23 ~3 ~40 ~23 ~4 ~40 obsidian 0  
fill ~24 ~3 ~15 ~24 ~4 ~15 cobblestone 0  
fill ~24 ~3 ~36 ~24 ~4 ~36 cobblestone 0 
setblock ~25 ~3 ~15 stone_stairs 5  
fill ~25 ~3 ~22 ~26 ~3 ~22 spruce_stairs 2  
fill ~25 ~3 ~23 ~26 ~3 ~23 spruce_stairs 7  
fill ~25 ~3 ~24 ~26 ~3 ~24 spruce_stairs 6  
fill ~25 ~3 ~25 ~32 ~3 ~25 nether_brick 0 
setblock ~25 ~3 ~29 redstone_torch 3 
setblock ~25 ~3 ~36 stone_stairs 5 
setblock ~26 ~3 ~15 stone_stairs 4  
fill ~26 ~3 ~27 ~26 ~5 ~27 nether_brick 0 
setblock ~26 ~3 ~36 stone_stairs 4  
fill ~27 ~3 ~15 ~27 ~4 ~15 cobblestone 0  
fill ~27 ~3 ~22 ~29 ~3 ~22 iron_bars 0  
fill ~27 ~3 ~23 ~27 ~3 ~24 wooden_slab 9 
setblock ~27 ~3 ~27 redstone_torch 1  
fill ~27 ~3 ~36 ~27 ~4 ~36 cobblestone 0  
fill ~28 ~3 ~11 ~28 ~4 ~11 obsidian 0  
fill ~28 ~3 ~12 ~28 ~4 ~12 obsidian 0  
fill ~28 ~3 ~13 ~28 ~4 ~13 obsidian 0  
fill ~28 ~3 ~14 ~28 ~4 ~14 obsidian 0  
fill ~28 ~3 ~37 ~28 ~4 ~37 obsidian 0  
fill ~28 ~3 ~38 ~28 ~4 ~38 obsidian 0  
fill ~28 ~3 ~39 ~28 ~4 ~39 obsidian 0  
fill ~28 ~3 ~40 ~28 ~4 ~40 obsidian 0  
fill ~29 ~3 ~13 ~29 ~4 ~13 stained_hardened_clay 15  
fill ~29 ~3 ~38 ~29 ~4 ~38 stained_hardened_clay 15 
setblock ~30 ~3 ~11 stonebrick 0  
fill ~31 ~3 ~12 ~37 ~3 ~12 iron_bars 0  
fill ~31 ~3 ~15 ~36 ~3 ~15 bookshelf 0 
setblock ~31 ~3 ~31 redstone_torch 2  
fill ~31 ~3 ~36 ~36 ~3 ~36 bookshelf 0  
fill ~31 ~3 ~39 ~37 ~3 ~39 iron_bars 0  
fill ~32 ~3 ~14 ~37 ~3 ~14 stonebrick 0  
fill ~32 ~3 ~21 ~36 ~3 ~21 nether_brick 0  
fill ~32 ~3 ~30 ~36 ~3 ~30 nether_brick 0  
fill ~32 ~3 ~31 ~32 ~5 ~31 nether_brick 0  
fill ~32 ~3 ~37 ~37 ~3 ~37 stonebrick 0 
setblock ~36 ~3 ~25 stone_stairs 7 
setblock ~36 ~3 ~26 stone_stairs 6  
fill ~37 ~3 ~15 ~37 ~7 ~15 stonebrick 0  
fill ~37 ~3 ~16 ~37 ~3 ~20 stonebrick 0  
fill ~37 ~3 ~21 ~37 ~4 ~21 obsidian 0  
fill ~37 ~3 ~22 ~37 ~4 ~22 obsidian 0  
fill ~37 ~3 ~23 ~40 ~3 ~23 obsidian 0  
fill ~37 ~3 ~28 ~40 ~3 ~28 obsidian 0  
fill ~37 ~3 ~29 ~37 ~4 ~29 obsidian 0  
fill ~37 ~3 ~32 ~37 ~7 ~32 stonebrick 0  
fill ~37 ~3 ~33 ~37 ~3 ~37 stonebrick 0  
fill ~38 ~3 ~13 ~39 ~3 ~13 stained_hardened_clay 15  
fill ~38 ~3 ~21 ~39 ~3 ~21 stained_hardened_clay 15  
fill ~38 ~3 ~22 ~38 ~4 ~22 stained_hardened_clay 15  
fill ~38 ~3 ~29 ~38 ~4 ~29 stained_hardened_clay 15  
fill ~38 ~3 ~30 ~39 ~3 ~30 stained_hardened_clay 15  
fill ~38 ~3 ~38 ~39 ~3 ~38 stained_hardened_clay 15  
fill ~38 ~3 ~40 ~38 ~4 ~40 stonebrick 0  
fill ~40 ~3 ~21 ~40 ~4 ~21 stonebrick 2  
fill ~40 ~3 ~30 ~40 ~4 ~30 stonebrick 0  
fill ~40 ~3 ~38 ~40 ~4 ~38 stonebrick 2  
fill ~45 ~3 ~10 ~49 ~3 ~10 leaves2 0  
fill ~45 ~3 ~11 ~46 ~3 ~11 leaves2 0  
fill ~46 ~3 ~8 ~46 ~4 ~8 log2 0  
fill ~46 ~3 ~9 ~48 ~3 ~9 leaves2 0  
fill ~46 ~3 ~12 ~49 ~3 ~12 leaves2 0  
fill ~46 ~3 ~13 ~48 ~3 ~13 leaves2 0 
setblock ~47 ~3 ~11 log2 0  
fill ~48 ~3 ~11 ~50 ~3 ~11 leaves2 0 
setblock ~50 ~3 ~5 log2 0  
fill ~50 ~3 ~9 ~50 ~3 ~9 leaves2 0  
fill ~1 ~4 ~7 ~1 ~4 ~7 log2 0  
fill ~1 ~4 ~49 ~1 ~4 ~49 leaves2 0 
setblock ~2 ~4 ~30 stonebrick 0  
fill ~6 ~4 ~48 ~7 ~4 ~48 log 4  
fill ~6 ~4 ~49 ~6 ~5 ~49 log 4 
setblock ~11 ~4 ~13 stonebrick 0 
setblock ~11 ~4 ~14 stone_brick_stairs 7 
setblock ~11 ~4 ~20 stone_brick_stairs 6 
setblock ~11 ~4 ~21 stonebrick 0  
fill ~11 ~4 ~23 ~14 ~4 ~23 obsidian 0  
fill ~11 ~4 ~28 ~14 ~4 ~28 obsidian 0 
setblock ~11 ~4 ~31 stone_brick_stairs 7 
setblock ~11 ~4 ~37 stone_brick_stairs 6 
setblock ~11 ~4 ~38 stonebrick 0  
fill ~12 ~4 ~13 ~12 ~0 ~13 stained_hardened_clay 15  
fill ~12 ~4 ~21 ~12 ~0 ~21 stained_hardened_clay 15  
fill ~12 ~4 ~30 ~12 ~0 ~30 stained_hardened_clay 15  
fill ~12 ~4 ~38 ~12 ~0 ~38 stained_hardened_clay 15 
setblock ~13 ~4 ~13 netherrack 0 
setblock ~13 ~4 ~14 stone_brick_stairs 7 
setblock ~13 ~4 ~20 stone_brick_stairs 6 
setblock ~13 ~4 ~21 netherrack 0 
setblock ~13 ~4 ~30 netherrack 0 
setblock ~13 ~4 ~31 stone_brick_stairs 7 
setblock ~13 ~4 ~37 stone_brick_stairs 6 
setblock ~13 ~4 ~38 netherrack 0 
setblock ~14 ~4 ~11 stone_brick_stairs 5  
fill ~14 ~4 ~12 ~20 ~4 ~12 iron_bars 0 
setblock ~14 ~4 ~13 stone_brick_stairs 5  
fill ~14 ~4 ~16 ~14 ~4 ~18 stone_brick_stairs 0  
fill ~14 ~4 ~19 ~14 ~7 ~19 stonebrick 0  
fill ~14 ~4 ~33 ~14 ~4 ~35 stone_brick_stairs 0 
setblock ~14 ~4 ~38 stone_brick_stairs 5  
fill ~14 ~4 ~39 ~20 ~4 ~39 iron_bars 0 
setblock ~14 ~4 ~40 stone_brick_stairs 5  
fill ~15 ~4 ~14 ~15 ~7 ~14 stonebrick 0  
fill ~15 ~4 ~21 ~19 ~4 ~21 nether_brick 0  
fill ~15 ~4 ~25 ~15 ~6 ~25 cobblestone 0  
fill ~15 ~4 ~26 ~15 ~6 ~26 cobblestone 0  
fill ~15 ~4 ~30 ~19 ~4 ~30 nether_brick 0  
fill ~15 ~4 ~32 ~15 ~4 ~35 log 1  
fill ~15 ~4 ~37 ~15 ~7 ~37 stonebrick 0  
fill ~16 ~4 ~14 ~18 ~4 ~14 stone_brick_stairs 2  
fill ~16 ~4 ~37 ~18 ~4 ~37 stone_brick_stairs 3  
fill ~17 ~4 ~36 ~20 ~4 ~36 log 1  
fill ~19 ~4 ~14 ~20 ~4 ~14 stonebrick 0  
fill ~19 ~4 ~19 ~32 ~4 ~19 nether_brick 0  
fill ~19 ~4 ~28 ~26 ~4 ~28 nether_brick 0  
fill ~19 ~4 ~37 ~19 ~7 ~37 stonebrick 0 
setblock ~20 ~4 ~11 stone_brick_stairs 4 
setblock ~20 ~4 ~13 stone_brick_stairs 4  
fill ~20 ~4 ~32 ~33 ~4 ~32 nether_brick 0 
setblock ~20 ~4 ~38 stone_brick_stairs 4 
setblock ~20 ~4 ~40 stone_brick_stairs 4 
setblock ~21 ~4 ~13 netherrack 0 
setblock ~21 ~4 ~38 netherrack 0  
fill ~25 ~4 ~15 ~27 ~4 ~15 cobblestone 0  
fill ~25 ~4 ~25 ~32 ~4 ~25 nether_brick 0  
fill ~25 ~4 ~36 ~27 ~4 ~36 cobblestone 0  
fill ~27 ~4 ~22 ~29 ~4 ~22 iron_bars 0  
fill ~27 ~4 ~23 ~27 ~4 ~24 spruce_stairs 0  
fill ~28 ~4 ~23 ~28 ~4 ~24 spruce_stairs 5 
setblock ~30 ~4 ~11 stonebrick 2 
setblock ~30 ~4 ~13 netherrack 0 
setblock ~30 ~4 ~38 netherrack 0 
setblock ~30 ~4 ~40 stonebrick 0 
setblock ~31 ~4 ~11 stone_brick_stairs 5  
fill ~31 ~4 ~12 ~37 ~4 ~12 iron_bars 0 
setblock ~31 ~4 ~13 stone_brick_stairs 5  
fill ~31 ~4 ~15 ~36 ~4 ~15 bookshelf 0  
fill ~31 ~4 ~36 ~36 ~4 ~36 bookshelf 0 
setblock ~31 ~4 ~38 stone_brick_stairs 5  
fill ~31 ~4 ~39 ~37 ~4 ~39 iron_bars 0 
setblock ~31 ~4 ~40 stone_brick_stairs 5  
fill ~32 ~4 ~14 ~32 ~7 ~14 stonebrick 0  
fill ~32 ~4 ~21 ~36 ~4 ~21 nether_brick 0  
fill ~32 ~4 ~30 ~36 ~4 ~30 nether_brick 0  
fill ~32 ~4 ~37 ~32 ~7 ~37 stonebrick 0  
fill ~33 ~4 ~14 ~35 ~4 ~14 stone_brick_stairs 2  
fill ~33 ~4 ~37 ~35 ~4 ~37 stone_brick_stairs 3  
fill ~36 ~4 ~14 ~36 ~7 ~14 stonebrick 0  
fill ~36 ~4 ~25 ~36 ~6 ~25 cobblestone 0  
fill ~36 ~4 ~26 ~36 ~6 ~26 cobblestone 0  
fill ~36 ~4 ~37 ~36 ~7 ~37 stonebrick 0 
setblock ~37 ~4 ~11 stone_brick_stairs 4 
setblock ~37 ~4 ~13 stone_brick_stairs 4  
fill ~37 ~4 ~16 ~37 ~4 ~18 stone_brick_stairs 1  
fill ~37 ~4 ~19 ~37 ~7 ~19 stonebrick 0  
fill ~37 ~4 ~23 ~40 ~4 ~23 obsidian 0  
fill ~37 ~4 ~28 ~40 ~4 ~28 obsidian 0  
fill ~37 ~4 ~33 ~37 ~4 ~35 stone_brick_stairs 1  
fill ~37 ~4 ~36 ~37 ~7 ~36 stonebrick 0 
setblock ~37 ~4 ~38 stone_brick_stairs 4 
setblock ~37 ~4 ~40 stone_brick_stairs 4 
setblock ~38 ~4 ~11 stonebrick 0 
setblock ~38 ~4 ~13 netherrack 0 
setblock ~38 ~4 ~14 stone_brick_stairs 7 
setblock ~38 ~4 ~20 stone_brick_stairs 6 
setblock ~38 ~4 ~21 netherrack 0 
setblock ~38 ~4 ~30 netherrack 0 
setblock ~38 ~4 ~31 stone_brick_stairs 7 
setblock ~38 ~4 ~37 stone_brick_stairs 6 
setblock ~38 ~4 ~38 netherrack 0 
setblock ~39 ~4 ~13 stained_hardened_clay 15 
setblock ~39 ~4 ~21 stained_hardened_clay 15 
setblock ~39 ~4 ~30 stained_hardened_clay 15 
setblock ~39 ~4 ~38 stained_hardened_clay 15 
setblock ~40 ~4 ~14 stone_brick_stairs 7 
setblock ~40 ~4 ~20 stone_brick_stairs 6 
setblock ~40 ~4 ~31 stone_brick_stairs 7 
setblock ~40 ~4 ~37 stone_brick_stairs 6  
fill ~43 ~4 ~6 ~49 ~4 ~6 leaves2 0  
fill ~43 ~4 ~7 ~50 ~4 ~7 leaves2 0  
fill ~43 ~4 ~8 ~45 ~4 ~8 leaves2 0  
fill ~43 ~4 ~9 ~49 ~4 ~9 leaves2 0  
fill ~43 ~4 ~10 ~49 ~4 ~10 leaves2 0  
fill ~44 ~4 ~5 ~50 ~4 ~5 leaves2 0  
fill ~44 ~4 ~11 ~48 ~4 ~11 leaves2 0  
fill ~46 ~4 ~2 ~50 ~4 ~2 leaves2 0  
fill ~46 ~4 ~3 ~50 ~4 ~3 leaves2 0  
fill ~46 ~4 ~4 ~48 ~4 ~4 leaves2 0  
fill ~46 ~4 ~12 ~48 ~4 ~12 leaves2 0  
fill ~47 ~4 ~1 ~50 ~4 ~1 leaves2 0  
fill ~47 ~4 ~8 ~50 ~4 ~8 leaves2 0 
setblock ~49 ~4 ~4 log2 0  
fill ~49 ~4 ~42 ~50 ~4 ~42 leaves2 0  
fill ~49 ~4 ~43 ~50 ~4 ~43 leaves2 0  
fill ~49 ~4 ~44 ~50 ~4 ~44 leaves2 0  
fill ~49 ~4 ~45 ~50 ~4 ~45 leaves2 0  
fill ~49 ~4 ~46 ~50 ~4 ~46 leaves2 0  
fill ~50 ~4 ~4 ~50 ~4 ~4 leaves2 0 
setblock ~50 ~4 ~6 log2 0  
fill ~50 ~4 ~9 ~50 ~6 ~9 log2 0  
fill ~50 ~4 ~41 ~50 ~4 ~41 leaves2 0  
fill ~50 ~4 ~47 ~50 ~4 ~47 leaves2 0  
fill ~1 ~5 ~20 ~2 ~5 ~20 stone_brick_stairs 6 
setblock ~1 ~5 ~21 stone_brick_stairs 4  
fill ~1 ~5 ~22 ~3 ~5 ~22 stone_brick_stairs 7  
fill ~1 ~5 ~29 ~2 ~5 ~29 stone_brick_stairs 6 
setblock ~1 ~5 ~30 stone_brick_stairs 4  
fill ~1 ~5 ~31 ~3 ~5 ~31 stone_brick_stairs 7 
setblock ~2 ~5 ~7 log2 0  
fill ~2 ~5 ~21 ~2 ~6 ~21 netherrack 0  
fill ~2 ~5 ~30 ~2 ~6 ~30 netherrack 0  
fill ~3 ~5 ~2 ~9 ~5 ~2 leaves2 0  
fill ~3 ~5 ~20 ~3 ~5 ~21 stone_brick_stairs 5  
fill ~3 ~5 ~29 ~3 ~5 ~30 stone_brick_stairs 5 
setblock ~3 ~5 ~48 log 4  
fill ~4 ~5 ~3 ~8 ~5 ~3 leaves2 0 
setblock ~4 ~5 ~49 log 4  
fill ~5 ~5 ~1 ~9 ~5 ~1 leaves2 0  
fill ~5 ~5 ~11 ~6 ~5 ~11 stone_brick_stairs 6 
setblock ~5 ~5 ~12 stone_brick_stairs 4  
fill ~5 ~5 ~13 ~7 ~5 ~13 stone_brick_stairs 7  
fill ~5 ~5 ~38 ~6 ~5 ~38 stone_brick_stairs 6 
setblock ~5 ~5 ~39 stone_brick_stairs 4  
fill ~5 ~5 ~40 ~7 ~5 ~40 stone_brick_stairs 7  
fill ~6 ~5 ~12 ~6 ~6 ~12 netherrack 0  
fill ~6 ~5 ~39 ~6 ~6 ~39 netherrack 0  
fill ~7 ~5 ~11 ~7 ~5 ~12 stone_brick_stairs 5  
fill ~7 ~5 ~38 ~7 ~5 ~39 stone_brick_stairs 5 
setblock ~7 ~5 ~49 log 4 
setblock ~8 ~5 ~48 log 4  
fill ~11 ~5 ~5 ~12 ~5 ~5 stone_brick_stairs 6 
setblock ~11 ~5 ~6 stone_brick_stairs 4  
fill ~11 ~5 ~7 ~13 ~5 ~7 stone_brick_stairs 7 
setblock ~11 ~5 ~13 stone_brick_stairs 2  
fill ~11 ~5 ~14 ~11 ~7 ~14 stonebrick 2  
fill ~11 ~5 ~20 ~11 ~7 ~20 stonebrick 0 
setblock ~11 ~5 ~21 stone_brick_stairs 3  
fill ~11 ~5 ~24 ~14 ~5 ~24 obsidian 0  
fill ~11 ~5 ~27 ~14 ~5 ~27 obsidian 0 
setblock ~11 ~5 ~30 stone_brick_stairs 2  
fill ~11 ~5 ~31 ~11 ~7 ~31 stonebrick 2  
fill ~11 ~5 ~37 ~11 ~7 ~37 stonebrick 0 
setblock ~11 ~5 ~38 stone_brick_stairs 3  
fill ~11 ~5 ~44 ~12 ~5 ~44 stone_brick_stairs 6 
setblock ~11 ~5 ~45 stone_brick_stairs 4  
fill ~11 ~5 ~46 ~13 ~5 ~46 stone_brick_stairs 7  
fill ~12 ~5 ~6 ~12 ~6 ~6 netherrack 0  
fill ~12 ~5 ~14 ~13 ~5 ~14 stained_hardened_clay 15  
fill ~12 ~5 ~20 ~13 ~5 ~20 stained_hardened_clay 15  
fill ~12 ~5 ~31 ~13 ~5 ~31 stained_hardened_clay 15  
fill ~12 ~5 ~37 ~13 ~5 ~37 stained_hardened_clay 15  
fill ~12 ~5 ~45 ~12 ~6 ~45 netherrack 0  
fill ~13 ~5 ~5 ~13 ~5 ~6 stone_brick_stairs 5 
setblock ~13 ~5 ~11 stone_brick_stairs 0 
setblock ~13 ~5 ~13 fire 15 
setblock ~13 ~5 ~21 fire 15 
setblock ~13 ~5 ~30 fire 15 
setblock ~13 ~5 ~38 fire 15 
setblock ~13 ~5 ~40 stone_brick_stairs 0  
fill ~13 ~5 ~44 ~13 ~5 ~45 stone_brick_stairs 5  
fill ~14 ~5 ~11 ~14 ~7 ~11 stonebrick 0  
fill ~14 ~5 ~12 ~14 ~7 ~12 stained_hardened_clay 15  
fill ~14 ~5 ~13 ~14 ~7 ~13 stained_hardened_clay 15 
setblock ~14 ~5 ~16 stone_brick_stairs 7 
setblock ~14 ~5 ~17 stone_brick_stairs 4 
setblock ~14 ~5 ~18 stone_brick_stairs 6  
fill ~14 ~5 ~21 ~14 ~7 ~21 stained_hardened_clay 15  
fill ~14 ~5 ~22 ~14 ~7 ~22 stained_hardened_clay 15  
fill ~14 ~5 ~23 ~14 ~7 ~23 stained_hardened_clay 15  
fill ~14 ~5 ~28 ~14 ~7 ~28 stained_hardened_clay 15  
fill ~14 ~5 ~29 ~14 ~7 ~29 stained_hardened_clay 15  
fill ~14 ~5 ~30 ~14 ~7 ~30 stained_hardened_clay 15 
setblock ~14 ~5 ~33 stone_brick_stairs 7 
setblock ~14 ~5 ~34 stone_brick_stairs 4 
setblock ~14 ~5 ~35 stone_brick_stairs 6  
fill ~14 ~5 ~38 ~14 ~7 ~38 stained_hardened_clay 15  
fill ~14 ~5 ~39 ~14 ~7 ~39 stained_hardened_clay 15  
fill ~14 ~5 ~40 ~14 ~7 ~40 stonebrick 2  
fill ~15 ~5 ~12 ~19 ~5 ~12 iron_bars 0  
fill ~15 ~5 ~21 ~19 ~5 ~21 nether_brick 0 
setblock ~15 ~5 ~24 torch 1 
setblock ~15 ~5 ~27 torch 1  
fill ~15 ~5 ~30 ~19 ~5 ~30 nether_brick 0  
fill ~15 ~5 ~39 ~19 ~5 ~39 iron_bars 0 
setblock ~16 ~5 ~14 stone_brick_stairs 5 
setblock ~16 ~5 ~37 stone_brick_stairs 5 
setblock ~17 ~5 ~14 stone_brick_stairs 6 
setblock ~17 ~5 ~37 stone_brick_stairs 7 
setblock ~18 ~5 ~14 stone_brick_stairs 4 
setblock ~18 ~5 ~19 redstone_torch 2 
setblock ~18 ~5 ~37 stone_brick_stairs 4  
fill ~19 ~5 ~14 ~20 ~5 ~14 stonebrick 0 
setblock ~19 ~5 ~18 redstone_torch 4  
fill ~19 ~5 ~19 ~32 ~5 ~19 nether_brick 0  
fill ~19 ~5 ~28 ~26 ~5 ~28 nether_brick 0  
fill ~20 ~5 ~1 ~21 ~5 ~1 stone_brick_stairs 6 
setblock ~20 ~5 ~2 stone_brick_stairs 4  
fill ~20 ~5 ~3 ~22 ~5 ~3 stone_brick_stairs 7  
fill ~20 ~5 ~11 ~20 ~7 ~11 stonebrick 2  
fill ~20 ~5 ~12 ~20 ~7 ~12 stained_hardened_clay 15  
fill ~20 ~5 ~13 ~20 ~7 ~13 stained_hardened_clay 15  
fill ~20 ~5 ~32 ~33 ~5 ~32 nether_brick 0  
fill ~20 ~5 ~38 ~20 ~7 ~38 stained_hardened_clay 15  
fill ~20 ~5 ~39 ~20 ~7 ~39 stained_hardened_clay 15 
setblock ~20 ~5 ~40 stonebrick 0  
fill ~20 ~5 ~48 ~21 ~5 ~48 stone_brick_stairs 6 
setblock ~20 ~5 ~49 stone_brick_stairs 4  
fill ~21 ~5 ~2 ~21 ~6 ~2 netherrack 0 
setblock ~21 ~5 ~11 stone_brick_stairs 1 
setblock ~21 ~5 ~13 fire 15  
fill ~21 ~5 ~14 ~23 ~5 ~14 stained_hardened_clay 15  
fill ~21 ~5 ~37 ~23 ~5 ~37 stained_hardened_clay 15 
setblock ~21 ~5 ~38 fire 15 
setblock ~21 ~5 ~40 stone_brick_stairs 1  
fill ~21 ~5 ~49 ~21 ~6 ~49 netherrack 0  
fill ~22 ~5 ~1 ~22 ~5 ~2 stone_brick_stairs 5 
setblock ~22 ~5 ~20 redstone_torch 3  
fill ~22 ~5 ~48 ~22 ~5 ~49 stone_brick_stairs 5  
fill ~24 ~5 ~11 ~24 ~6 ~11 obsidian 0  
fill ~24 ~5 ~12 ~24 ~6 ~12 obsidian 0  
fill ~24 ~5 ~13 ~24 ~6 ~13 obsidian 0  
fill ~24 ~5 ~14 ~24 ~6 ~14 obsidian 0 
setblock ~24 ~5 ~15 torch 3 
setblock ~24 ~5 ~36 torch 4  
fill ~24 ~5 ~37 ~24 ~6 ~37 obsidian 0  
fill ~24 ~5 ~38 ~24 ~6 ~38 obsidian 0  
fill ~24 ~5 ~39 ~24 ~6 ~39 obsidian 0  
fill ~24 ~5 ~40 ~24 ~6 ~40 obsidian 0  
fill ~25 ~5 ~15 ~26 ~5 ~15 cobblestone 0  
fill ~25 ~5 ~25 ~32 ~5 ~25 nether_brick 0  
fill ~25 ~5 ~36 ~26 ~5 ~36 cobblestone 0  
fill ~27 ~5 ~11 ~27 ~6 ~11 obsidian 0  
fill ~27 ~5 ~12 ~27 ~6 ~12 obsidian 0  
fill ~27 ~5 ~13 ~27 ~6 ~13 obsidian 0  
fill ~27 ~5 ~14 ~27 ~6 ~14 obsidian 0 
setblock ~27 ~5 ~15 torch 3  
fill ~27 ~5 ~22 ~29 ~5 ~22 iron_bars 0 
setblock ~27 ~5 ~36 torch 4  
fill ~27 ~5 ~37 ~27 ~6 ~37 obsidian 0  
fill ~27 ~5 ~38 ~27 ~6 ~38 obsidian 0  
fill ~27 ~5 ~39 ~27 ~6 ~39 obsidian 0  
fill ~27 ~5 ~40 ~27 ~6 ~40 obsidian 0  
fill ~28 ~5 ~14 ~30 ~5 ~14 stained_hardened_clay 15  
fill ~28 ~5 ~23 ~28 ~5 ~24 spruce_stairs 0  
fill ~28 ~5 ~37 ~30 ~5 ~37 stained_hardened_clay 15  
fill ~29 ~5 ~1 ~30 ~5 ~1 stone_brick_stairs 6 
setblock ~29 ~5 ~2 stone_brick_stairs 4  
fill ~29 ~5 ~3 ~31 ~5 ~3 stone_brick_stairs 7  
fill ~29 ~5 ~23 ~29 ~5 ~24 spruce_stairs 5  
fill ~29 ~5 ~48 ~30 ~5 ~48 stone_brick_stairs 6 
setblock ~29 ~5 ~49 stone_brick_stairs 4  
fill ~30 ~5 ~2 ~30 ~6 ~2 netherrack 0 
setblock ~30 ~5 ~11 stone_brick_stairs 0 
setblock ~30 ~5 ~13 fire 15 
setblock ~30 ~5 ~38 fire 15 
setblock ~30 ~5 ~40 stone_brick_stairs 0  
fill ~30 ~5 ~49 ~30 ~6 ~49 netherrack 0   
fill ~31 ~5 ~1 ~31 ~5 ~2 stone_brick_stairs 5  
fill ~31 ~5 ~11 ~31 ~6 ~11 stonebrick 2  
fill ~31 ~5 ~12 ~31 ~7 ~12 stained_hardened_clay 15  
fill ~31 ~5 ~13 ~31 ~7 ~13 stained_hardened_clay 15  
fill ~31 ~5 ~15 ~36 ~5 ~15 bookshelf 0  
fill ~31 ~5 ~38 ~31 ~7 ~38 stained_hardened_clay 15  
fill ~31 ~5 ~39 ~31 ~7 ~39 stained_hardened_clay 15  
fill ~31 ~5 ~40 ~31 ~7 ~40 stonebrick 2  
fill ~31 ~5 ~48 ~31 ~5 ~49 stone_brick_stairs 5  
fill ~32 ~5 ~12 ~36 ~5 ~12 iron_bars 0  
fill ~32 ~5 ~21 ~36 ~5 ~21 nether_brick 0  
fill ~32 ~5 ~30 ~36 ~5 ~30 nether_brick 0 
setblock ~32 ~5 ~36 redstone_torch 5  
fill ~32 ~5 ~39 ~36 ~5 ~39 iron_bars 0 
setblock ~33 ~5 ~14 stone_brick_stairs 5 
setblock ~33 ~5 ~37 stone_brick_stairs 5 
setblock ~34 ~5 ~14 stone_brick_stairs 6  
fill ~34 ~5 ~37 ~35 ~5 ~37 stone_brick_stairs 7 
setblock ~35 ~5 ~14 stone_brick_stairs 4 
setblock ~35 ~5 ~36 redstone_torch 5 
setblock ~36 ~5 ~24 torch 2 
setblock ~36 ~5 ~27 torch 2 
setblock ~37 ~5 ~11 stonebrick 0  
fill ~37 ~5 ~12 ~37 ~7 ~12 stained_hardened_clay 15  
fill ~37 ~5 ~13 ~37 ~7 ~13 stained_hardened_clay 15 
setblock ~37 ~5 ~16 stone_brick_stairs 7 
setblock ~37 ~5 ~17 stone_brick_stairs 5 
setblock ~37 ~5 ~18 stone_brick_stairs 6  
fill ~37 ~5 ~21 ~37 ~7 ~21 stained_hardened_clay 15  
fill ~37 ~5 ~22 ~37 ~7 ~22 stained_hardened_clay 15  
fill ~37 ~5 ~23 ~37 ~7 ~23 stained_hardened_clay 15  
fill ~37 ~5 ~24 ~40 ~5 ~24 obsidian 0  
fill ~37 ~5 ~27 ~40 ~5 ~27 obsidian 0  
fill ~37 ~5 ~28 ~37 ~7 ~28 stained_hardened_clay 15  
fill ~37 ~5 ~29 ~37 ~7 ~29 stained_hardened_clay 15  
fill ~37 ~5 ~30 ~37 ~7 ~30 stained_hardened_clay 15 
setblock ~37 ~5 ~33 stone_brick_stairs 7  
fill ~37 ~5 ~34 ~37 ~5 ~35 stone_brick_stairs 5  
fill ~37 ~5 ~38 ~37 ~7 ~38 stained_hardened_clay 15  
fill ~37 ~5 ~39 ~37 ~7 ~39 stained_hardened_clay 15  
fill ~37 ~5 ~40 ~37 ~7 ~40 stonebrick 0  
fill ~38 ~5 ~5 ~39 ~5 ~5 stone_brick_stairs 6 
setblock ~38 ~5 ~6 stone_brick_stairs 4  
fill ~38 ~5 ~7 ~40 ~5 ~7 stone_brick_stairs 7 
setblock ~38 ~5 ~11 stone_brick_stairs 1 
setblock ~38 ~5 ~13 fire 15  
fill ~38 ~5 ~14 ~39 ~5 ~14 stained_hardened_clay 15  
fill ~38 ~5 ~20 ~39 ~5 ~20 stained_hardened_clay 15 
setblock ~38 ~5 ~21 fire 15 
setblock ~38 ~5 ~30 fire 15  
fill ~38 ~5 ~31 ~39 ~5 ~31 stained_hardened_clay 15  
fill ~38 ~5 ~37 ~39 ~5 ~37 stained_hardened_clay 15 
setblock ~38 ~5 ~38 fire 15 
setblock ~38 ~5 ~40 stone_brick_stairs 1  
fill ~38 ~5 ~44 ~39 ~5 ~44 stone_brick_stairs 6 
setblock ~38 ~5 ~45 stone_brick_stairs 4  
fill ~38 ~5 ~46 ~40 ~5 ~46 stone_brick_stairs 7  
fill ~39 ~5 ~6 ~39 ~6 ~6 netherrack 0  
fill ~39 ~5 ~45 ~39 ~6 ~45 netherrack 0  
fill ~40 ~5 ~5 ~40 ~5 ~6 stone_brick_stairs 5 
setblock ~40 ~5 ~13 stone_brick_stairs 2  
fill ~40 ~5 ~14 ~40 ~7 ~14 stonebrick 0  
fill ~40 ~5 ~20 ~40 ~7 ~20 stonebrick 2 
setblock ~40 ~5 ~21 stone_brick_stairs 3 
setblock ~40 ~5 ~30 stone_brick_stairs 2  
fill ~40 ~5 ~31 ~40 ~7 ~31 stonebrick 2 
setblock ~40 ~5 ~37 stonebrick 2 
setblock ~40 ~5 ~38 stone_brick_stairs 3  
fill ~40 ~5 ~44 ~40 ~5 ~45 stone_brick_stairs 5  
fill ~44 ~5 ~8 ~48 ~5 ~8 leaves2 0  
fill ~44 ~5 ~11 ~45 ~5 ~11 stone_brick_stairs 6 
setblock ~44 ~5 ~12 stone_brick_stairs 4  
fill ~44 ~5 ~13 ~46 ~5 ~13 stone_brick_stairs 7  
fill ~44 ~5 ~38 ~45 ~5 ~38 stone_brick_stairs 6 
setblock ~44 ~5 ~39 stone_brick_stairs 4  
fill ~44 ~5 ~40 ~46 ~5 ~40 stone_brick_stairs 7  
fill ~45 ~5 ~7 ~47 ~5 ~7 leaves2 0  
fill ~45 ~5 ~9 ~47 ~5 ~9 leaves2 0  
fill ~45 ~5 ~12 ~45 ~6 ~12 netherrack 0  
fill ~45 ~5 ~39 ~45 ~6 ~39 netherrack 0 
setblock ~46 ~5 ~6 leaves2 0 
setblock ~46 ~5 ~10 leaves2 0  
fill ~46 ~5 ~11 ~46 ~5 ~12 stone_brick_stairs 5  
fill ~46 ~5 ~38 ~46 ~5 ~39 stone_brick_stairs 5  
fill ~47 ~5 ~4 ~50 ~5 ~4 leaves2 0  
fill ~48 ~5 ~3 ~50 ~5 ~3 leaves2 0  
fill ~48 ~5 ~5 ~50 ~5 ~5 leaves2 0  
fill ~48 ~5 ~20 ~49 ~5 ~20 stone_brick_stairs 6 
setblock ~48 ~5 ~21 stone_brick_stairs 4  
fill ~48 ~5 ~22 ~50 ~5 ~22 stone_brick_stairs 7  
fill ~48 ~5 ~29 ~49 ~5 ~29 stone_brick_stairs 6 
setblock ~48 ~5 ~30 stone_brick_stairs 4  
fill ~48 ~5 ~31 ~50 ~5 ~31 stone_brick_stairs 7  
fill ~48 ~5 ~49 ~48 ~5 ~49 leaves2 0 
setblock ~49 ~5 ~2 leaves2 0  
fill ~49 ~5 ~6 ~50 ~5 ~6 leaves2 0  
fill ~49 ~5 ~7 ~50 ~5 ~7 leaves2 0  
fill ~49 ~5 ~21 ~49 ~6 ~21 netherrack 0  
fill ~49 ~5 ~30 ~49 ~6 ~30 netherrack 0  
fill ~50 ~5 ~20 ~50 ~5 ~21 stone_brick_stairs 5  
fill ~50 ~5 ~29 ~50 ~5 ~30 stone_brick_stairs 5  
fill ~50 ~5 ~44 ~50 ~5 ~44 leaves2 0  
fill ~50 ~5 ~49 ~50 ~5 ~49 leaves2 0  
fill ~1 ~6 ~6 ~5 ~6 ~6 leaves2 0  
fill ~1 ~6 ~7 ~2 ~6 ~7 leaves2 0  
fill ~1 ~6 ~8 ~5 ~6 ~8 leaves2 0  
fill ~1 ~6 ~20 ~2 ~6 ~20 stone_brick_stairs 2 
setblock ~1 ~6 ~21 stone_brick_stairs 0  
fill ~1 ~6 ~22 ~3 ~6 ~22 stone_brick_stairs 3  
fill ~1 ~6 ~29 ~2 ~6 ~29 stone_brick_stairs 2 
setblock ~1 ~6 ~30 stone_brick_stairs 0  
fill ~1 ~6 ~31 ~3 ~6 ~31 stone_brick_stairs 3  
fill ~2 ~6 ~5 ~4 ~6 ~5 leaves2 0  
fill ~2 ~6 ~9 ~4 ~6 ~9 leaves2 0 
setblock ~3 ~6 ~7 log2 0  
fill ~3 ~6 ~20 ~3 ~6 ~21 stone_brick_stairs 1  
fill ~3 ~6 ~29 ~3 ~6 ~30 stone_brick_stairs 1  
fill ~4 ~6 ~7 ~5 ~6 ~7 leaves2 0  
fill ~5 ~6 ~1 ~7 ~6 ~1 leaves2 0  
fill ~5 ~6 ~11 ~6 ~6 ~11 stone_brick_stairs 2 
setblock ~5 ~6 ~12 stone_brick_stairs 0  
fill ~5 ~6 ~13 ~7 ~6 ~13 stone_brick_stairs 3  
fill ~5 ~6 ~38 ~6 ~6 ~38 stone_brick_stairs 2 
setblock ~5 ~6 ~39 stone_brick_stairs 0  
fill ~5 ~6 ~40 ~7 ~6 ~40 stone_brick_stairs 3 
setblock ~6 ~6 ~2 leaves2 0  
fill ~7 ~6 ~11 ~7 ~6 ~12 stone_brick_stairs 1  
fill ~7 ~6 ~38 ~7 ~6 ~39 stone_brick_stairs 1 
setblock ~8 ~6 ~49 log 4  
fill ~11 ~6 ~5 ~12 ~6 ~5 stone_brick_stairs 2 
setblock ~11 ~6 ~6 stone_brick_stairs 0  
fill ~11 ~6 ~7 ~13 ~6 ~7 stone_brick_stairs 3  
fill ~11 ~6 ~24 ~14 ~6 ~24 obsidian 0  
fill ~11 ~6 ~27 ~14 ~6 ~27 obsidian 0  
fill ~11 ~6 ~44 ~12 ~6 ~44 stone_brick_stairs 2 
setblock ~11 ~6 ~45 stone_brick_stairs 0  
fill ~11 ~6 ~46 ~13 ~6 ~46 stone_brick_stairs 3  
fill ~12 ~6 ~14 ~13 ~6 ~14 stained_hardened_clay 15  
fill ~12 ~6 ~20 ~13 ~6 ~20 stained_hardened_clay 15  
fill ~12 ~6 ~31 ~13 ~6 ~31 stained_hardened_clay 15  
fill ~12 ~6 ~37 ~13 ~6 ~37 stained_hardened_clay 15  
fill ~13 ~6 ~5 ~13 ~6 ~6 stone_brick_stairs 1  
fill ~13 ~6 ~44 ~13 ~6 ~45 stone_brick_stairs 1  
fill ~14 ~6 ~16 ~14 ~6 ~19 stonebrick 0  
fill ~14 ~6 ~33 ~14 ~6 ~36 stonebrick 0  
fill ~15 ~6 ~12 ~19 ~6 ~12 iron_bars 0  
fill ~15 ~6 ~15 ~24 ~6 ~15 planks 1  
fill ~15 ~6 ~16 ~36 ~6 ~16 planks 1  
fill ~15 ~6 ~17 ~36 ~6 ~17 planks 1  
fill ~15 ~6 ~18 ~36 ~6 ~18 planks 1  
fill ~15 ~6 ~19 ~23 ~6 ~19 planks 1  
fill ~15 ~6 ~20 ~23 ~6 ~20 planks 1  
fill ~15 ~6 ~21 ~23 ~6 ~21 planks 1  
fill ~15 ~6 ~22 ~23 ~6 ~22 planks 1  
fill ~15 ~6 ~23 ~23 ~6 ~23 planks 1  
fill ~15 ~6 ~24 ~23 ~6 ~24 planks 1  
fill ~15 ~6 ~27 ~36 ~6 ~27 planks 1  
fill ~15 ~6 ~28 ~36 ~6 ~28 planks 1  
fill ~15 ~6 ~29 ~36 ~6 ~29 planks 1  
fill ~15 ~6 ~30 ~36 ~6 ~30 planks 1  
fill ~15 ~6 ~31 ~36 ~6 ~31 planks 1  
fill ~15 ~6 ~32 ~36 ~6 ~32 planks 1  
fill ~15 ~6 ~33 ~36 ~6 ~33 planks 1  
fill ~15 ~6 ~34 ~36 ~6 ~34 planks 1  
fill ~15 ~6 ~35 ~36 ~6 ~35 planks 1  
fill ~15 ~6 ~36 ~24 ~6 ~36 planks 1  
fill ~15 ~6 ~39 ~19 ~6 ~39 iron_bars 0  
fill ~16 ~6 ~14 ~19 ~6 ~14 stonebrick 0  
fill ~16 ~6 ~25 ~24 ~6 ~25 planks 1  
fill ~16 ~6 ~26 ~35 ~6 ~26 planks 1  
fill ~16 ~6 ~37 ~19 ~6 ~37 stonebrick 0  
fill ~20 ~6 ~1 ~21 ~6 ~1 stone_brick_stairs 2 
setblock ~20 ~6 ~2 stone_brick_stairs 0  
fill ~20 ~6 ~3 ~22 ~6 ~3 stone_brick_stairs 3  
fill ~20 ~6 ~40 ~20 ~7 ~40 stonebrick 2  
fill ~20 ~6 ~48 ~21 ~6 ~48 stone_brick_stairs 2 
setblock ~20 ~6 ~49 stone_brick_stairs 0  
fill ~21 ~6 ~14 ~23 ~6 ~14 stained_hardened_clay 15  
fill ~21 ~6 ~37 ~23 ~6 ~37 stained_hardened_clay 15  
fill ~22 ~6 ~1 ~22 ~6 ~2 stone_brick_stairs 1  
fill ~22 ~6 ~48 ~22 ~6 ~49 stone_brick_stairs 1  
fill ~24 ~6 ~19 ~32 ~6 ~19 nether_brick 0  
fill ~25 ~6 ~15 ~26 ~6 ~15 cobblestone 0  
fill ~25 ~6 ~25 ~29 ~6 ~25 nether_brick 0  
fill ~25 ~6 ~36 ~26 ~6 ~36 cobblestone 0  
fill ~27 ~6 ~15 ~36 ~6 ~15 planks 1  
fill ~27 ~6 ~22 ~29 ~6 ~22 iron_bars 0  
fill ~27 ~6 ~36 ~36 ~6 ~36 planks 1  
fill ~28 ~6 ~14 ~30 ~6 ~14 stained_hardened_clay 15  
fill ~28 ~6 ~37 ~30 ~6 ~37 stained_hardened_clay 15  
fill ~29 ~6 ~1 ~30 ~6 ~1 stone_brick_stairs 2 
setblock ~29 ~6 ~2 stone_brick_stairs 0  
fill ~29 ~6 ~3 ~31 ~6 ~3 stone_brick_stairs 3  
fill ~29 ~6 ~23 ~29 ~6 ~24 spruce_stairs 0  
fill ~29 ~6 ~48 ~30 ~6 ~48 stone_brick_stairs 2 
setblock ~29 ~6 ~49 stone_brick_stairs 0  
fill ~30 ~6 ~22 ~31 ~6 ~22 wooden_slab 9  
fill ~30 ~6 ~23 ~30 ~6 ~25 spruce_stairs 5  
fill ~31 ~6 ~1 ~31 ~6 ~2 stone_brick_stairs 1  
fill ~31 ~6 ~23 ~31 ~6 ~25 spruce_stairs 4  
fill ~31 ~6 ~48 ~31 ~6 ~49 stone_brick_stairs 1  
fill ~32 ~6 ~12 ~36 ~6 ~12 iron_bars 0  
fill ~32 ~6 ~21 ~32 ~10 ~21 nether_brick 0  
fill ~32 ~6 ~25 ~32 ~10 ~25 nether_brick 0  
fill ~32 ~6 ~39 ~36 ~6 ~39 iron_bars 0  
fill ~33 ~6 ~14 ~36 ~6 ~14 stonebrick 0  
fill ~33 ~6 ~19 ~36 ~6 ~19 planks 1  
fill ~33 ~6 ~20 ~36 ~6 ~20 planks 1  
fill ~33 ~6 ~21 ~36 ~6 ~21 planks 1  
fill ~33 ~6 ~22 ~36 ~6 ~22 planks 1  
fill ~33 ~6 ~23 ~36 ~6 ~23 planks 1  
fill ~33 ~6 ~24 ~36 ~6 ~24 planks 1  
fill ~33 ~6 ~25 ~35 ~6 ~25 planks 1  
fill ~33 ~6 ~37 ~36 ~6 ~37 stonebrick 0  
fill ~37 ~6 ~11 ~37 ~7 ~11 stonebrick 2  
fill ~37 ~6 ~16 ~37 ~6 ~19 stonebrick 0  
fill ~37 ~6 ~24 ~40 ~6 ~24 obsidian 0  
fill ~37 ~6 ~27 ~40 ~6 ~27 obsidian 0  
fill ~37 ~6 ~33 ~37 ~6 ~36 stonebrick 0  
fill ~38 ~6 ~5 ~39 ~6 ~5 stone_brick_stairs 2 
setblock ~38 ~6 ~6 stone_brick_stairs 0  
fill ~38 ~6 ~7 ~40 ~6 ~7 stone_brick_stairs 3  
fill ~38 ~6 ~14 ~39 ~6 ~14 stained_hardened_clay 15  
fill ~38 ~6 ~20 ~39 ~6 ~20 stained_hardened_clay 15  
fill ~38 ~6 ~31 ~39 ~6 ~31 stained_hardened_clay 15  
fill ~38 ~6 ~37 ~39 ~6 ~37 stained_hardened_clay 15  
fill ~38 ~6 ~44 ~39 ~6 ~44 stone_brick_stairs 2 
setblock ~38 ~6 ~45 stone_brick_stairs 0  
fill ~38 ~6 ~46 ~40 ~6 ~46 stone_brick_stairs 3  
fill ~40 ~6 ~5 ~40 ~6 ~6 stone_brick_stairs 1  
fill ~40 ~6 ~37 ~40 ~7 ~37 stonebrick 0  
fill ~40 ~6 ~44 ~40 ~6 ~45 stone_brick_stairs 1  
fill ~44 ~6 ~11 ~45 ~6 ~11 stone_brick_stairs 2 
setblock ~44 ~6 ~12 stone_brick_stairs 0  
fill ~44 ~6 ~13 ~46 ~6 ~13 stone_brick_stairs 3  
fill ~44 ~6 ~38 ~45 ~6 ~38 stone_brick_stairs 2 
setblock ~44 ~6 ~39 stone_brick_stairs 0  
fill ~44 ~6 ~40 ~46 ~6 ~40 stone_brick_stairs 3  
fill ~46 ~6 ~11 ~46 ~6 ~12 stone_brick_stairs 1  
fill ~46 ~6 ~38 ~46 ~6 ~39 stone_brick_stairs 1  
fill ~47 ~6 ~1 ~49 ~6 ~1 leaves2 0  
fill ~47 ~6 ~7 ~50 ~6 ~7 leaves2 0  
fill ~47 ~6 ~8 ~50 ~6 ~8 leaves2 0  
fill ~47 ~6 ~9 ~49 ~6 ~9 leaves2 0  
fill ~47 ~6 ~10 ~50 ~6 ~10 leaves2 0  
fill ~47 ~6 ~11 ~50 ~6 ~11 leaves2 0  
fill ~48 ~6 ~6 ~50 ~6 ~6 leaves2 0  
fill ~48 ~6 ~12 ~50 ~6 ~12 leaves2 0  
fill ~48 ~6 ~20 ~49 ~6 ~20 stone_brick_stairs 2 
setblock ~48 ~6 ~21 stone_brick_stairs 0  
fill ~48 ~6 ~22 ~50 ~6 ~22 stone_brick_stairs 3  
fill ~48 ~6 ~29 ~49 ~6 ~29 stone_brick_stairs 2 
setblock ~48 ~6 ~30 stone_brick_stairs 0  
fill ~48 ~6 ~31 ~50 ~6 ~31 stone_brick_stairs 3  
fill ~48 ~6 ~49 ~48 ~7 ~49 log2 0  
fill ~50 ~6 ~13 ~50 ~6 ~13 leaves2 0  
fill ~50 ~6 ~14 ~50 ~6 ~14 leaves2 0  
fill ~50 ~6 ~15 ~50 ~6 ~15 leaves2 0  
fill ~50 ~6 ~16 ~50 ~6 ~16 leaves2 0  
fill ~50 ~6 ~17 ~50 ~6 ~17 leaves2 0  
fill ~50 ~6 ~20 ~50 ~6 ~21 stone_brick_stairs 1  
fill ~50 ~6 ~29 ~50 ~6 ~30 stone_brick_stairs 1  
fill ~1 ~7 ~2 ~2 ~7 ~2 leaves2 0  
fill ~1 ~7 ~3 ~3 ~7 ~3 leaves2 0  
fill ~1 ~7 ~4 ~3 ~7 ~4 leaves2 0  
fill ~1 ~7 ~5 ~3 ~7 ~5 leaves2 0  
fill ~1 ~7 ~6 ~4 ~7 ~6 leaves2 0  
fill ~1 ~7 ~7 ~4 ~7 ~7 leaves2 0  
fill ~1 ~7 ~8 ~4 ~7 ~8 leaves2 0 
setblock ~2 ~7 ~21 fire 15 
setblock ~2 ~7 ~30 fire 15 
setblock ~6 ~7 ~12 fire 15 
setblock ~6 ~7 ~39 fire 15  
fill ~11 ~7 ~25 ~15 ~7 ~25 obsidian 0  
fill ~11 ~7 ~26 ~15 ~7 ~26 obsidian 0 
setblock ~12 ~7 ~6 fire 15  
fill ~12 ~7 ~14 ~13 ~7 ~14 stained_hardened_clay 15  
fill ~12 ~7 ~20 ~13 ~7 ~20 stained_hardened_clay 15  
fill ~12 ~7 ~31 ~13 ~7 ~31 stained_hardened_clay 15  
fill ~12 ~7 ~37 ~13 ~7 ~37 stained_hardened_clay 15 
setblock ~12 ~7 ~45 fire 15 
setblock ~14 ~7 ~14 netherrack 0 
setblock ~14 ~7 ~16 stone_brick_stairs 3 
setblock ~14 ~7 ~17 stone_brick_stairs 0 
setblock ~14 ~7 ~18 stone_brick_stairs 2 
setblock ~14 ~7 ~20 netherrack 0 
setblock ~14 ~7 ~24 stained_hardened_clay 15 
setblock ~14 ~7 ~27 stained_hardened_clay 15 
setblock ~14 ~7 ~31 netherrack 0 
setblock ~14 ~7 ~33 stone_brick_stairs 3 
setblock ~14 ~7 ~34 stone_brick_stairs 0 
setblock ~14 ~7 ~35 stone_brick_stairs 2 
setblock ~14 ~7 ~37 netherrack 0  
fill ~15 ~7 ~12 ~19 ~7 ~12 iron_bars 0  
fill ~15 ~7 ~15 ~18 ~7 ~15 bookshelf 0  
fill ~15 ~7 ~16 ~15 ~9 ~16 bookshelf 0  
fill ~15 ~7 ~17 ~15 ~10 ~17 bookshelf 0  
fill ~15 ~7 ~18 ~15 ~9 ~18 bookshelf 0  
fill ~15 ~7 ~19 ~16 ~7 ~19 obsidian 0  
fill ~15 ~7 ~20 ~15 ~8 ~20 obsidian 0  
fill ~15 ~7 ~21 ~15 ~8 ~21 obsidian 0  
fill ~15 ~7 ~22 ~21 ~7 ~22 nether_brick 0  
fill ~15 ~7 ~23 ~15 ~8 ~23 obsidian 0  
fill ~15 ~7 ~24 ~15 ~8 ~24 obsidian 0  
fill ~15 ~7 ~27 ~15 ~8 ~27 obsidian 0  
fill ~15 ~7 ~28 ~15 ~8 ~28 obsidian 0  
fill ~15 ~7 ~29 ~15 ~8 ~29 obsidian 0  
fill ~15 ~7 ~30 ~15 ~8 ~30 obsidian 0  
fill ~15 ~7 ~31 ~15 ~8 ~31 obsidian 0  
fill ~15 ~7 ~32 ~15 ~8 ~32 nether_brick 0  
fill ~15 ~7 ~33 ~15 ~9 ~33 nether_brick 0  
fill ~15 ~7 ~34 ~15 ~10 ~34 bookshelf 0  
fill ~15 ~7 ~35 ~15 ~9 ~35 bookshelf 0  
fill ~15 ~7 ~36 ~17 ~7 ~36 bookshelf 0  
fill ~15 ~7 ~39 ~19 ~7 ~39 iron_bars 0 
setblock ~16 ~7 ~14 stone_brick_stairs 1  
fill ~16 ~7 ~16 ~16 ~10 ~16 obsidian 0  
fill ~16 ~7 ~20 ~16 ~9 ~20 bookshelf 0  
fill ~16 ~7 ~21 ~16 ~9 ~21 bookshelf 0  
fill ~16 ~7 ~23 ~19 ~7 ~23 bookshelf 0 
setblock ~16 ~7 ~37 stone_brick_stairs 1 
setblock ~17 ~7 ~14 stone_brick_stairs 2  
fill ~17 ~7 ~33 ~28 ~7 ~33 nether_brick 0 
setblock ~17 ~7 ~37 stone_brick_stairs 3 
setblock ~18 ~7 ~14 stone_brick_stairs 0 
setblock ~18 ~7 ~18 crafting_table 0 
setblock ~18 ~7 ~26 glowstone 0  
fill ~18 ~7 ~28 ~27 ~7 ~28 nether_brick 0  
fill ~18 ~7 ~29 ~18 ~10 ~29 nether_brick 0  
fill ~18 ~7 ~30 ~18 ~10 ~30 nether_brick 0  
fill ~18 ~7 ~31 ~18 ~10 ~31 nether_brick 0  
fill ~18 ~7 ~32 ~18 ~10 ~32 nether_brick 0  
fill ~18 ~7 ~36 ~18 ~9 ~36 nether_brick 0 
setblock ~18 ~7 ~37 stone_brick_stairs 0 
setblock ~19 ~7 ~14 stonebrick 0  
fill ~19 ~7 ~15 ~32 ~7 ~15 obsidian 0  
fill ~19 ~7 ~16 ~19 ~10 ~16 obsidian 0 
setblock ~19 ~7 ~32 stonebrick 3  
fill ~19 ~7 ~35 ~19 ~9 ~35 nether_brick 0  
fill ~19 ~7 ~36 ~32 ~7 ~36 obsidian 0 
setblock ~20 ~7 ~14 netherrack 0  
fill ~20 ~7 ~16 ~21 ~7 ~16 bookshelf 0  
fill ~20 ~7 ~23 ~20 ~10 ~23 nether_brick 0  
fill ~20 ~7 ~24 ~20 ~10 ~24 nether_brick 0  
fill ~20 ~7 ~25 ~20 ~10 ~25 nether_brick 0  
fill ~20 ~7 ~26 ~20 ~10 ~26 nether_brick 0  
fill ~20 ~7 ~27 ~20 ~10 ~27 nether_brick 0 
setblock ~20 ~7 ~37 netherrack 0 
setblock ~21 ~7 ~2 fire 15  
fill ~21 ~7 ~14 ~24 ~7 ~14 stained_hardened_clay 15  
fill ~21 ~7 ~23 ~21 ~10 ~23 bookshelf 0  
fill ~21 ~7 ~29 ~21 ~7 ~30 spruce_stairs 0  
fill ~21 ~7 ~37 ~24 ~7 ~37 stained_hardened_clay 15 
setblock ~21 ~7 ~49 fire 15  
fill ~22 ~7 ~16 ~22 ~9 ~16 nether_brick 0  
fill ~22 ~7 ~17 ~22 ~10 ~17 nether_brick 0  
fill ~22 ~7 ~18 ~22 ~10 ~18 nether_brick 0  
fill ~22 ~7 ~19 ~22 ~10 ~19 nether_brick 0  
fill ~22 ~7 ~29 ~22 ~7 ~30 spruce_stairs 5  
fill ~23 ~7 ~22 ~23 ~10 ~22 nether_brick 0  
fill ~23 ~7 ~23 ~23 ~10 ~23 bookshelf 0  
fill ~24 ~7 ~19 ~32 ~7 ~19 nether_brick 0  
fill ~24 ~7 ~25 ~29 ~7 ~25 nether_brick 0  
fill ~24 ~7 ~26 ~24 ~10 ~26 nether_brick 0 
setblock ~24 ~7 ~30 glowstone 0  
fill ~25 ~7 ~11 ~26 ~7 ~11 obsidian 0  
fill ~25 ~7 ~12 ~26 ~7 ~12 obsidian 0  
fill ~25 ~7 ~13 ~26 ~7 ~13 obsidian 0  
fill ~25 ~7 ~14 ~26 ~7 ~14 obsidian 0 
setblock ~25 ~7 ~27 glowstone 0  
fill ~25 ~7 ~37 ~26 ~7 ~37 obsidian 0  
fill ~25 ~7 ~38 ~26 ~7 ~38 obsidian 0  
fill ~25 ~7 ~39 ~26 ~7 ~39 obsidian 0  
fill ~25 ~7 ~40 ~26 ~7 ~40 obsidian 0  
fill ~27 ~7 ~14 ~30 ~7 ~14 stained_hardened_clay 15  
fill ~27 ~7 ~22 ~29 ~7 ~22 iron_bars 0  
fill ~27 ~7 ~29 ~27 ~10 ~29 nether_brick 0  
fill ~27 ~7 ~30 ~27 ~10 ~30 nether_brick 0  
fill ~27 ~7 ~37 ~30 ~7 ~37 stained_hardened_clay 15  
fill ~29 ~7 ~20 ~29 ~7 ~21 wooden_slab 9  
fill ~29 ~7 ~26 ~29 ~10 ~26 nether_brick 0  
fill ~29 ~7 ~27 ~29 ~10 ~27 nether_brick 0  
fill ~29 ~7 ~28 ~29 ~10 ~28 nether_brick 0  
fill ~29 ~7 ~29 ~29 ~10 ~29 nether_brick 0  
fill ~29 ~7 ~30 ~29 ~10 ~30 nether_brick 0  
fill ~29 ~7 ~31 ~29 ~10 ~31 nether_brick 0  
fill ~29 ~7 ~32 ~32 ~7 ~32 nether_brick 0 
setblock ~30 ~7 ~2 fire 15  
fill ~30 ~7 ~20 ~31 ~7 ~20 spruce_stairs 7  
fill ~30 ~7 ~21 ~31 ~7 ~21 spruce_stairs 6  
fill ~30 ~7 ~22 ~31 ~7 ~22 spruce_stairs 3 
setblock ~30 ~7 ~49 fire 15 
setblock ~31 ~7 ~11 stonebrick 0 
setblock ~31 ~7 ~14 netherrack 0 
setblock ~31 ~7 ~37 netherrack 0  
fill ~32 ~7 ~12 ~36 ~7 ~12 iron_bars 0  
fill ~32 ~7 ~16 ~32 ~9 ~16 nether_brick 0  
fill ~32 ~7 ~18 ~32 ~10 ~18 nether_brick 0  
fill ~32 ~7 ~34 ~32 ~10 ~34 nether_brick 0  
fill ~32 ~7 ~35 ~33 ~7 ~35 nether_brick 0  
fill ~32 ~7 ~39 ~36 ~7 ~39 iron_bars 0 
setblock ~33 ~7 ~14 stone_brick_stairs 1  
fill ~33 ~7 ~15 ~36 ~7 ~15 nether_brick 0  
fill ~33 ~7 ~16 ~33 ~10 ~16 obsidian 0  
fill ~33 ~7 ~36 ~33 ~9 ~36 nether_brick 0 
setblock ~33 ~7 ~37 stone_brick_stairs 1 
setblock ~34 ~7 ~14 stone_brick_stairs 2  
fill ~34 ~7 ~16 ~34 ~10 ~16 bookshelf 0  
fill ~34 ~7 ~36 ~36 ~7 ~36 bookshelf 0 
setblock ~34 ~7 ~37 stone_brick_stairs 3 
setblock ~35 ~7 ~14 stone_brick_stairs 0  
fill ~35 ~7 ~16 ~35 ~10 ~16 obsidian 0  
fill ~35 ~7 ~17 ~35 ~10 ~17 bookshelf 0  
fill ~35 ~7 ~18 ~35 ~10 ~18 obsidian 0  
fill ~35 ~7 ~19 ~35 ~9 ~19 nether_brick 0  
fill ~35 ~7 ~32 ~36 ~7 ~32 nether_brick 0  
fill ~35 ~7 ~33 ~36 ~7 ~33 nether_brick 0  
fill ~35 ~7 ~35 ~36 ~7 ~35 bookshelf 0 
setblock ~35 ~7 ~37 stone_brick_stairs 0  
fill ~36 ~7 ~16 ~36 ~9 ~16 nether_brick 0  
fill ~36 ~7 ~17 ~36 ~11 ~17 nether_brick 0  
fill ~36 ~7 ~18 ~36 ~9 ~18 nether_brick 0  
fill ~36 ~7 ~19 ~36 ~8 ~19 obsidian 0  
fill ~36 ~7 ~20 ~36 ~8 ~20 obsidian 0  
fill ~36 ~7 ~21 ~36 ~8 ~21 obsidian 0  
fill ~36 ~7 ~22 ~36 ~8 ~22 obsidian 0  
fill ~36 ~7 ~23 ~36 ~8 ~23 obsidian 0  
fill ~36 ~7 ~24 ~36 ~8 ~24 obsidian 0  
fill ~36 ~7 ~25 ~40 ~7 ~25 obsidian 0  
fill ~36 ~7 ~26 ~40 ~7 ~26 obsidian 0  
fill ~36 ~7 ~27 ~36 ~8 ~27 obsidian 0  
fill ~36 ~7 ~28 ~36 ~8 ~28 obsidian 0  
fill ~36 ~7 ~29 ~36 ~8 ~29 obsidian 0  
fill ~36 ~7 ~30 ~36 ~8 ~30 obsidian 0  
fill ~36 ~7 ~31 ~36 ~8 ~31 obsidian 0  
fill ~36 ~7 ~34 ~36 ~10 ~34 bookshelf 0 
setblock ~37 ~7 ~14 netherrack 0 
setblock ~37 ~7 ~16 stone_brick_stairs 3 
setblock ~37 ~7 ~17 stone_brick_stairs 1 
setblock ~37 ~7 ~18 stone_brick_stairs 2 
setblock ~37 ~7 ~20 netherrack 0 
setblock ~37 ~7 ~24 stained_hardened_clay 15 
setblock ~37 ~7 ~27 stained_hardened_clay 15 
setblock ~37 ~7 ~31 netherrack 0 
setblock ~37 ~7 ~33 stone_brick_stairs 3 
setblock ~37 ~7 ~34 stone_brick_stairs 1 
setblock ~37 ~7 ~35 stone_brick_stairs 2 
setblock ~37 ~7 ~37 netherrack 0  
fill ~38 ~7 ~14 ~39 ~7 ~14 stained_hardened_clay 15  
fill ~38 ~7 ~20 ~39 ~7 ~20 stained_hardened_clay 15  
fill ~38 ~7 ~31 ~39 ~7 ~31 stained_hardened_clay 15  
fill ~38 ~7 ~37 ~39 ~7 ~37 stained_hardened_clay 15 
setblock ~39 ~7 ~6 fire 15 
setblock ~39 ~7 ~45 fire 15  
fill ~44 ~7 ~1 ~50 ~7 ~1 leaves2 0  
fill ~44 ~7 ~2 ~50 ~7 ~2 leaves2 0  
fill ~45 ~7 ~3 ~49 ~7 ~3 leaves2 0 
setblock ~45 ~7 ~12 fire 15 
setblock ~45 ~7 ~39 fire 15  
fill ~45 ~7 ~47 ~50 ~7 ~47 leaves2 0  
fill ~45 ~7 ~48 ~50 ~7 ~48 leaves2 0  
fill ~45 ~7 ~49 ~47 ~7 ~49 leaves2 0  
fill ~46 ~7 ~46 ~50 ~7 ~46 leaves2 0  
fill ~48 ~7 ~9 ~50 ~7 ~9 leaves2 0  
fill ~49 ~7 ~8 ~50 ~7 ~8 leaves2 0  
fill ~49 ~7 ~10 ~50 ~7 ~10 leaves2 0 
setblock ~49 ~7 ~21 fire 15 
setblock ~49 ~7 ~30 fire 15  
fill ~49 ~7 ~49 ~50 ~7 ~49 leaves2 0 
setblock ~50 ~7 ~7 leaves2 0 
setblock ~50 ~7 ~11 leaves2 0  
fill ~1 ~8 ~4 ~1 ~8 ~4 leaves2 0  
fill ~1 ~8 ~5 ~2 ~8 ~5 leaves2 0  
fill ~1 ~8 ~6 ~1 ~8 ~6 leaves2 0 
setblock ~11 ~8 ~14 stone_brick_stairs 2  
fill ~11 ~8 ~15 ~11 ~9 ~15 stonebrick 0  
fill ~11 ~8 ~19 ~11 ~9 ~19 stonebrick 0 
setblock ~11 ~8 ~20 stone_brick_stairs 3 
setblock ~11 ~8 ~31 stone_brick_stairs 2  
fill ~11 ~8 ~32 ~11 ~9 ~32 stonebrick 0  
fill ~11 ~8 ~36 ~11 ~9 ~36 stonebrick 0 
setblock ~11 ~8 ~37 stone_brick_stairs 3  
fill ~12 ~8 ~15 ~14 ~8 ~15 stained_hardened_clay 15  
fill ~12 ~8 ~19 ~14 ~8 ~19 stained_hardened_clay 15  
fill ~12 ~8 ~32 ~14 ~8 ~32 stained_hardened_clay 15  
fill ~12 ~8 ~36 ~14 ~8 ~36 stained_hardened_clay 15 
setblock ~14 ~8 ~11 stone_brick_stairs 0 
setblock ~14 ~8 ~14 fire 15  
fill ~14 ~8 ~16 ~14 ~9 ~16 stonebrick 0 
setblock ~14 ~8 ~17 stone_brick_stairs 4  
fill ~14 ~8 ~18 ~14 ~9 ~18 stonebrick 0 
setblock ~14 ~8 ~20 fire 15 
setblock ~14 ~8 ~31 fire 15  
fill ~14 ~8 ~33 ~14 ~9 ~33 stonebrick 0 
setblock ~14 ~8 ~34 stone_brick_stairs 4  
fill ~14 ~8 ~35 ~14 ~9 ~35 stonebrick 0 
setblock ~14 ~8 ~37 fire 15 
setblock ~14 ~8 ~40 stone_brick_stairs 0  
fill ~15 ~8 ~11 ~15 ~9 ~11 stonebrick 0  
fill ~15 ~8 ~12 ~15 ~9 ~12 stained_hardened_clay 15  
fill ~15 ~8 ~13 ~15 ~9 ~13 stained_hardened_clay 15  
fill ~15 ~8 ~14 ~15 ~9 ~14 stained_hardened_clay 15  
fill ~15 ~8 ~15 ~18 ~8 ~15 bookshelf 0  
fill ~15 ~8 ~19 ~16 ~8 ~19 obsidian 0 
setblock ~15 ~8 ~22 obsidian 0  
fill ~15 ~8 ~25 ~15 ~8 ~31 obsidian 0  
fill ~15 ~8 ~36 ~17 ~8 ~36 bookshelf 0  
fill ~15 ~8 ~37 ~15 ~9 ~37 stained_hardened_clay 15  
fill ~15 ~8 ~38 ~15 ~9 ~38 stained_hardened_clay 15  
fill ~15 ~8 ~39 ~15 ~9 ~39 stained_hardened_clay 15  
fill ~15 ~8 ~40 ~15 ~9 ~40 stonebrick 0  
fill ~16 ~8 ~12 ~18 ~8 ~12 iron_bars 0  
fill ~16 ~8 ~14 ~16 ~9 ~14 stonebrick 0  
fill ~16 ~8 ~22 ~21 ~8 ~22 nether_brick 0  
fill ~16 ~8 ~23 ~19 ~8 ~23 bookshelf 0  
fill ~16 ~8 ~37 ~16 ~9 ~37 stonebrick 0  
fill ~16 ~8 ~39 ~18 ~8 ~39 iron_bars 0 
setblock ~17 ~8 ~14 stone_brick_stairs 6  
fill ~17 ~8 ~33 ~28 ~8 ~33 nether_brick 0 
setblock ~17 ~8 ~37 stone_brick_stairs 7  
fill ~18 ~8 ~14 ~18 ~9 ~14 stonebrick 0 
setblock ~18 ~8 ~18 torch 5  
fill ~18 ~8 ~28 ~27 ~8 ~28 nether_brick 0  
fill ~18 ~8 ~37 ~18 ~9 ~37 stonebrick 0  
fill ~19 ~8 ~11 ~19 ~9 ~11 stonebrick 0  
fill ~19 ~8 ~12 ~19 ~9 ~12 stained_hardened_clay 15  
fill ~19 ~8 ~13 ~19 ~9 ~13 stained_hardened_clay 15  
fill ~19 ~8 ~14 ~19 ~9 ~14 stained_hardened_clay 15  
fill ~19 ~8 ~15 ~32 ~8 ~15 obsidian 0 
setblock ~19 ~8 ~32 redstone_torch 5  
fill ~19 ~8 ~36 ~32 ~8 ~36 obsidian 0  
fill ~19 ~8 ~37 ~19 ~9 ~37 stained_hardened_clay 15  
fill ~19 ~8 ~38 ~19 ~9 ~38 stained_hardened_clay 15  
fill ~19 ~8 ~39 ~19 ~9 ~39 stained_hardened_clay 15  
fill ~19 ~8 ~40 ~19 ~9 ~40 stonebrick 2 
setblock ~20 ~8 ~11 stone_brick_stairs 1 
setblock ~20 ~8 ~14 fire 15  
fill ~20 ~8 ~16 ~21 ~8 ~16 bookshelf 0 
setblock ~20 ~8 ~37 fire 15 
setblock ~20 ~8 ~40 stone_brick_stairs 1  
fill ~22 ~8 ~29 ~22 ~8 ~30 spruce_stairs 0  
fill ~23 ~8 ~29 ~23 ~8 ~30 spruce_stairs 5  
fill ~24 ~8 ~19 ~32 ~8 ~19 nether_brick 0  
fill ~24 ~8 ~25 ~29 ~8 ~25 nether_brick 0  
fill ~27 ~8 ~22 ~29 ~8 ~22 iron_bars 0  
fill ~28 ~8 ~20 ~28 ~8 ~21 spruce_stairs 4  
fill ~29 ~8 ~20 ~29 ~8 ~21 spruce_stairs 1  
fill ~29 ~8 ~32 ~32 ~8 ~32 nether_brick 0 
setblock ~31 ~8 ~11 stone_brick_stairs 0 
setblock ~31 ~8 ~14 fire 15 
setblock ~31 ~8 ~37 fire 15 
setblock ~31 ~8 ~40 stone_brick_stairs 0  
fill ~32 ~8 ~11 ~32 ~9 ~11 stonebrick 0  
fill ~32 ~8 ~12 ~32 ~9 ~12 stained_hardened_clay 15  
fill ~32 ~8 ~13 ~32 ~9 ~13 stained_hardened_clay 15  
fill ~32 ~8 ~14 ~32 ~9 ~14 stained_hardened_clay 15  
fill ~32 ~8 ~35 ~33 ~8 ~35 nether_brick 0  
fill ~32 ~8 ~37 ~32 ~9 ~37 stained_hardened_clay 15  
fill ~32 ~8 ~38 ~32 ~9 ~38 stained_hardened_clay 15  
fill ~32 ~8 ~39 ~32 ~9 ~39 stained_hardened_clay 15  
fill ~32 ~8 ~40 ~32 ~9 ~40 stonebrick 0  
fill ~33 ~8 ~12 ~35 ~8 ~12 iron_bars 0  
fill ~33 ~8 ~14 ~33 ~9 ~14 stonebrick 0  
fill ~33 ~8 ~15 ~36 ~8 ~15 nether_brick 0  
fill ~33 ~8 ~37 ~33 ~9 ~37 stonebrick 0  
fill ~33 ~8 ~39 ~35 ~8 ~39 iron_bars 0 
setblock ~34 ~8 ~14 stone_brick_stairs 6  
fill ~34 ~8 ~36 ~36 ~8 ~36 bookshelf 0 
setblock ~34 ~8 ~37 stone_brick_stairs 7  
fill ~35 ~8 ~14 ~35 ~9 ~14 stonebrick 0  
fill ~35 ~8 ~32 ~35 ~9 ~32 nether_brick 0  
fill ~35 ~8 ~33 ~36 ~8 ~33 nether_brick 0  
fill ~35 ~8 ~35 ~36 ~8 ~35 bookshelf 0  
fill ~35 ~8 ~37 ~35 ~9 ~37 stonebrick 0  
fill ~36 ~8 ~11 ~36 ~9 ~11 stonebrick 0  
fill ~36 ~8 ~12 ~36 ~9 ~12 stained_hardened_clay 15  
fill ~36 ~8 ~13 ~36 ~9 ~13 stained_hardened_clay 15  
fill ~36 ~8 ~14 ~36 ~9 ~14 stained_hardened_clay 15  
fill ~36 ~8 ~25 ~36 ~7 ~25 obsidian 0  
fill ~36 ~8 ~26 ~36 ~7 ~26 obsidian 0 
setblock ~36 ~8 ~32 obsidian 0  
fill ~36 ~8 ~37 ~36 ~9 ~37 stained_hardened_clay 15  
fill ~36 ~8 ~38 ~36 ~9 ~38 stained_hardened_clay 15  
fill ~36 ~8 ~39 ~36 ~9 ~39 stained_hardened_clay 15  
fill ~36 ~8 ~40 ~36 ~9 ~40 stonebrick 0 
setblock ~37 ~8 ~11 stone_brick_stairs 1 
setblock ~37 ~8 ~14 fire 15  
fill ~37 ~8 ~15 ~39 ~8 ~15 stained_hardened_clay 15  
fill ~37 ~8 ~16 ~37 ~9 ~16 stonebrick 0 
setblock ~37 ~8 ~17 stone_brick_stairs 5  
fill ~37 ~8 ~18 ~37 ~9 ~18 stonebrick 0  
fill ~37 ~8 ~19 ~39 ~8 ~19 stained_hardened_clay 15 
setblock ~37 ~8 ~20 fire 15 
setblock ~37 ~8 ~31 fire 15  
fill ~37 ~8 ~32 ~39 ~8 ~32 stained_hardened_clay 15  
fill ~37 ~8 ~33 ~37 ~9 ~33 stonebrick 0 
setblock ~37 ~8 ~34 stone_brick_stairs 5  
fill ~37 ~8 ~35 ~37 ~9 ~35 stonebrick 0  
fill ~37 ~8 ~36 ~39 ~8 ~36 stained_hardened_clay 15 
setblock ~37 ~8 ~37 fire 15 
setblock ~37 ~8 ~40 stone_brick_stairs 1 
setblock ~40 ~8 ~14 stone_brick_stairs 2  
fill ~40 ~8 ~15 ~40 ~9 ~15 stonebrick 0  
fill ~40 ~8 ~19 ~40 ~9 ~19 stonebrick 0 
setblock ~40 ~8 ~20 stone_brick_stairs 3 
setblock ~40 ~8 ~31 stone_brick_stairs 2  
fill ~40 ~8 ~32 ~40 ~9 ~32 stonebrick 0  
fill ~40 ~8 ~36 ~40 ~9 ~36 stonebrick 0 
setblock ~40 ~8 ~37 stone_brick_stairs 3  
fill ~46 ~8 ~1 ~48 ~8 ~1 leaves2 0  
fill ~46 ~8 ~49 ~50 ~8 ~49 leaves2 0 
setblock ~47 ~8 ~2 leaves2 0  
fill ~47 ~8 ~48 ~49 ~8 ~48 leaves2 0 
setblock ~48 ~8 ~47 leaves2 0 
setblock ~11 ~9 ~16 stone_brick_stairs 7 
setblock ~11 ~9 ~18 stone_brick_stairs 6 
setblock ~11 ~9 ~33 stone_brick_stairs 7 
setblock ~11 ~9 ~35 stone_brick_stairs 6  
fill ~12 ~9 ~15 ~14 ~9 ~15 stained_hardened_clay 15  
fill ~12 ~9 ~19 ~14 ~9 ~19 stained_hardened_clay 15  
fill ~12 ~9 ~32 ~14 ~9 ~32 stained_hardened_clay 15  
fill ~12 ~9 ~36 ~14 ~9 ~36 stained_hardened_clay 15 
setblock ~13 ~9 ~16 stone_brick_stairs 7 
setblock ~13 ~9 ~18 stone_brick_stairs 6 
setblock ~13 ~9 ~33 stone_brick_stairs 7 
setblock ~13 ~9 ~35 stone_brick_stairs 6  
fill ~14 ~9 ~17 ~14 ~11 ~17 stonebrick 0  
fill ~14 ~9 ~34 ~14 ~11 ~34 stonebrick 0 
setblock ~15 ~9 ~15 netherrack 0 
setblock ~15 ~9 ~19 netherrack 0  
fill ~15 ~9 ~20 ~15 ~9 ~31 stained_hardened_clay 15 
setblock ~15 ~9 ~32 netherrack 0 
setblock ~15 ~9 ~36 netherrack 0 
setblock ~16 ~9 ~11 stone_brick_stairs 5  
fill ~16 ~9 ~12 ~18 ~9 ~12 iron_bars 0 
setblock ~16 ~9 ~13 stone_brick_stairs 5  
fill ~16 ~9 ~15 ~18 ~9 ~15 bookshelf 0  
fill ~16 ~9 ~19 ~16 ~10 ~19 obsidian 0  
fill ~16 ~9 ~22 ~21 ~9 ~22 nether_brick 0  
fill ~16 ~9 ~23 ~19 ~9 ~23 bookshelf 0  
fill ~16 ~9 ~32 ~18 ~9 ~32 nether_brick 0  
fill ~16 ~9 ~33 ~28 ~9 ~33 nether_brick 0  
fill ~16 ~9 ~36 ~17 ~9 ~36 bookshelf 0 
setblock ~16 ~9 ~38 stone_brick_stairs 5  
fill ~16 ~9 ~39 ~18 ~9 ~39 iron_bars 0 
setblock ~16 ~9 ~40 stone_brick_stairs 5  
fill ~17 ~9 ~14 ~17 ~11 ~14 stonebrick 0  
fill ~17 ~9 ~37 ~17 ~11 ~37 stonebrick 0 
setblock ~18 ~9 ~11 stone_brick_stairs 4 
setblock ~18 ~9 ~13 stone_brick_stairs 4  
fill ~18 ~9 ~28 ~29 ~9 ~28 nether_brick 0 
setblock ~18 ~9 ~34 redstone_torch 2 
setblock ~18 ~9 ~38 stone_brick_stairs 4 
setblock ~18 ~9 ~40 stone_brick_stairs 4 
setblock ~19 ~9 ~15 netherrack 0  
fill ~19 ~9 ~34 ~19 ~10 ~34 nether_brick 0 
setblock ~19 ~9 ~36 netherrack 0  
fill ~20 ~9 ~15 ~31 ~9 ~15 stained_hardened_clay 15  
fill ~20 ~9 ~16 ~21 ~9 ~16 bookshelf 0 
setblock ~20 ~9 ~34 redstone_torch 1  
fill ~20 ~9 ~36 ~31 ~9 ~36 stained_hardened_clay 15  
fill ~23 ~9 ~29 ~23 ~9 ~30 spruce_stairs 0  
fill ~24 ~9 ~19 ~32 ~9 ~19 nether_brick 0  
fill ~24 ~9 ~25 ~29 ~9 ~25 nether_brick 0  
fill ~24 ~9 ~27 ~24 ~10 ~27 nether_brick 0  
fill ~24 ~9 ~29 ~24 ~9 ~30 spruce_stairs 5 
setblock ~25 ~9 ~27 redstone_torch 1  
fill ~27 ~9 ~20 ~27 ~9 ~21 spruce_stairs 4  
fill ~27 ~9 ~22 ~29 ~9 ~22 iron_bars 0  
fill ~28 ~9 ~20 ~28 ~9 ~21 spruce_stairs 1  
fill ~28 ~9 ~29 ~28 ~10 ~29 nether_brick 0  
fill ~28 ~9 ~30 ~28 ~10 ~30 nether_brick 0 
setblock ~28 ~9 ~31 redstone_torch 3  
fill ~29 ~9 ~32 ~32 ~9 ~32 nether_brick 0 
setblock ~32 ~9 ~15 netherrack 0  
fill ~32 ~9 ~35 ~33 ~9 ~35 nether_brick 0 
setblock ~32 ~9 ~36 netherrack 0 
setblock ~33 ~9 ~11 stone_brick_stairs 5  
fill ~33 ~9 ~12 ~35 ~9 ~12 iron_bars 0 
setblock ~33 ~9 ~13 stone_brick_stairs 5  
fill ~33 ~9 ~15 ~35 ~9 ~15 nether_brick 0 
setblock ~33 ~9 ~38 stone_brick_stairs 5  
fill ~33 ~9 ~39 ~35 ~9 ~39 iron_bars 0 
setblock ~33 ~9 ~40 stone_brick_stairs 5  
fill ~34 ~9 ~14 ~34 ~11 ~14 stonebrick 0  
fill ~34 ~9 ~36 ~35 ~9 ~36 bookshelf 0  
fill ~34 ~9 ~37 ~34 ~11 ~37 stonebrick 0 
setblock ~35 ~9 ~11 stone_brick_stairs 4 
setblock ~35 ~9 ~13 stone_brick_stairs 4  
fill ~35 ~9 ~33 ~36 ~9 ~33 nether_brick 0  
fill ~35 ~9 ~35 ~36 ~9 ~35 bookshelf 0 
setblock ~35 ~9 ~38 stone_brick_stairs 4 
setblock ~35 ~9 ~40 stone_brick_stairs 4 
setblock ~36 ~9 ~15 netherrack 0 
setblock ~36 ~9 ~19 netherrack 0  
fill ~36 ~9 ~20 ~36 ~9 ~31 stained_hardened_clay 15 
setblock ~36 ~9 ~32 netherrack 0 
setblock ~36 ~9 ~36 netherrack 0  
fill ~37 ~9 ~15 ~39 ~9 ~15 stained_hardened_clay 15  
fill ~37 ~9 ~17 ~37 ~11 ~17 stonebrick 0  
fill ~37 ~9 ~19 ~39 ~9 ~19 stained_hardened_clay 15  
fill ~37 ~9 ~32 ~39 ~9 ~32 stained_hardened_clay 15  
fill ~37 ~9 ~34 ~37 ~11 ~34 stonebrick 0  
fill ~37 ~9 ~36 ~39 ~9 ~36 stained_hardened_clay 15 
setblock ~38 ~9 ~16 stone_brick_stairs 7 
setblock ~38 ~9 ~18 stone_brick_stairs 6 
setblock ~38 ~9 ~33 stone_brick_stairs 7 
setblock ~38 ~9 ~35 stone_brick_stairs 6 
setblock ~40 ~9 ~16 stone_brick_stairs 7 
setblock ~40 ~9 ~18 stone_brick_stairs 6 
setblock ~40 ~9 ~33 stone_brick_stairs 7 
setblock ~40 ~9 ~35 stone_brick_stairs 6 
setblock ~11 ~10 ~15 stone_brick_stairs 2  
fill ~11 ~10 ~16 ~11 ~11 ~16 stonebrick 0  
fill ~11 ~10 ~18 ~11 ~11 ~18 stonebrick 0 
setblock ~11 ~10 ~19 stone_brick_stairs 3 
setblock ~11 ~10 ~32 stone_brick_stairs 2  
fill ~11 ~10 ~33 ~11 ~11 ~33 stonebrick 2  
fill ~11 ~10 ~35 ~11 ~11 ~35 stonebrick 0 
setblock ~11 ~10 ~36 stone_brick_stairs 3  
fill ~12 ~10 ~16 ~15 ~10 ~16 stained_hardened_clay 15  
fill ~12 ~10 ~18 ~15 ~10 ~18 stained_hardened_clay 15  
fill ~12 ~10 ~33 ~15 ~10 ~33 stained_hardened_clay 15  
fill ~12 ~10 ~35 ~15 ~10 ~35 stained_hardened_clay 15 
setblock ~15 ~10 ~11 stone_brick_stairs 0 
setblock ~15 ~10 ~15 fire 15 
setblock ~15 ~10 ~19 fire 15 
setblock ~15 ~10 ~32 fire 15 
setblock ~15 ~10 ~36 fire 15 
setblock ~15 ~10 ~40 stone_brick_stairs 0  
fill ~16 ~10 ~11 ~16 ~11 ~11 stonebrick 0  
fill ~16 ~10 ~12 ~16 ~11 ~12 stained_hardened_clay 15  
fill ~16 ~10 ~13 ~16 ~11 ~13 stained_hardened_clay 15  
fill ~16 ~10 ~14 ~16 ~11 ~14 stained_hardened_clay 15  
fill ~16 ~10 ~15 ~16 ~11 ~15 stained_hardened_clay 15  
fill ~16 ~10 ~17 ~16 ~10 ~33 obsidian 0  
fill ~16 ~10 ~34 ~17 ~10 ~34 planks 1  
fill ~16 ~10 ~35 ~17 ~10 ~35 planks 1  
fill ~16 ~10 ~36 ~16 ~11 ~36 stained_hardened_clay 15  
fill ~16 ~10 ~37 ~16 ~11 ~37 stained_hardened_clay 15  
fill ~16 ~10 ~38 ~16 ~11 ~38 stained_hardened_clay 15  
fill ~16 ~10 ~39 ~16 ~11 ~39 stained_hardened_clay 15  
fill ~16 ~10 ~40 ~16 ~11 ~40 stonebrick 2  
fill ~17 ~10 ~12 ~17 ~11 ~12 iron_bars 0 
setblock ~17 ~10 ~15 bookshelf 0   
fill ~17 ~10 ~16 ~33 ~10 ~16 obsidian 0  
fill ~17 ~10 ~22 ~24 ~10 ~22 nether_brick 0 
setblock ~17 ~10 ~31 redstone_torch 4  
fill ~17 ~10 ~32 ~17 ~10 ~33 nether_brick 0 
setblock ~17 ~10 ~36 bookshelf 0  
fill ~17 ~10 ~39 ~17 ~11 ~39 iron_bars 0  
fill ~18 ~10 ~11 ~18 ~11 ~11 stonebrick 0  
fill ~18 ~10 ~12 ~18 ~11 ~12 stained_hardened_clay 15  
fill ~18 ~10 ~13 ~18 ~11 ~13 stained_hardened_clay 15  
fill ~18 ~10 ~14 ~18 ~11 ~14 stained_hardened_clay 15  
fill ~18 ~10 ~15 ~18 ~11 ~15 stained_hardened_clay 15  
fill ~18 ~10 ~28 ~29 ~10 ~28 nether_brick 0  
fill ~18 ~10 ~33 ~28 ~10 ~33 nether_brick 0  
fill ~18 ~10 ~34 ~18 ~10 ~35 nether_brick 0  
fill ~18 ~10 ~36 ~18 ~11 ~36 stained_hardened_clay 15  
fill ~18 ~10 ~37 ~18 ~11 ~37 stained_hardened_clay 15  
fill ~18 ~10 ~38 ~18 ~11 ~38 stained_hardened_clay 15  
fill ~18 ~10 ~39 ~18 ~11 ~39 stained_hardened_clay 15  
fill ~18 ~10 ~40 ~18 ~11 ~40 stonebrick 0 
setblock ~19 ~10 ~11 stone_brick_stairs 1 
setblock ~19 ~10 ~15 fire 15 
setblock ~19 ~10 ~27 redstone_torch 4  
fill ~19 ~10 ~35 ~32 ~10 ~35 obsidian 0 
setblock ~19 ~10 ~36 fire 15 
setblock ~19 ~10 ~40 stone_brick_stairs 1 
setblock ~22 ~10 ~21 redstone_torch 4 
setblock ~22 ~10 ~23 redstone_torch 3 
setblock ~22 ~10 ~27 redstone_torch 4  
fill ~23 ~10 ~19 ~34 ~10 ~19 nether_brick 0  
fill ~24 ~10 ~25 ~32 ~10 ~25 nether_brick 0  
fill ~24 ~10 ~29 ~24 ~10 ~30 spruce_stairs 0 
setblock ~25 ~10 ~20 torch 1 
setblock ~25 ~10 ~24 torch 1  
fill ~25 ~10 ~29 ~25 ~10 ~30 spruce_stairs 5  
fill ~26 ~10 ~20 ~26 ~10 ~21 spruce_stairs 4  
fill ~27 ~10 ~20 ~27 ~10 ~21 spruce_stairs 1  
fill ~27 ~10 ~22 ~29 ~10 ~22 iron_bars 0  
fill ~29 ~10 ~32 ~34 ~10 ~32 nether_brick 0 
setblock ~29 ~10 ~33 redstone_torch 1 
setblock ~31 ~10 ~17 redstone_torch 2 
setblock ~32 ~10 ~11 stone_brick_stairs 0 
setblock ~32 ~10 ~15 fire 15 
setblock ~32 ~10 ~17 nether_brick 0 
setblock ~32 ~10 ~33 nether_brick 0 
setblock ~32 ~10 ~36 fire 15 
setblock ~32 ~10 ~40 stone_brick_stairs 0  
fill ~33 ~10 ~11 ~33 ~11 ~11 stonebrick 2  
fill ~33 ~10 ~12 ~33 ~11 ~12 stained_hardened_clay 15  
fill ~33 ~10 ~13 ~33 ~11 ~13 stained_hardened_clay 15  
fill ~33 ~10 ~14 ~33 ~11 ~14 stained_hardened_clay 15  
fill ~33 ~10 ~15 ~33 ~11 ~15 stained_hardened_clay 15 
setblock ~33 ~10 ~17 redstone_torch 3 
setblock ~33 ~10 ~31 redstone_torch 4 
setblock ~33 ~10 ~35 nether_brick 0  
fill ~33 ~10 ~36 ~33 ~11 ~36 stained_hardened_clay 15  
fill ~33 ~10 ~37 ~33 ~11 ~37 stained_hardened_clay 15  
fill ~33 ~10 ~38 ~33 ~11 ~38 stained_hardened_clay 15  
fill ~33 ~10 ~39 ~33 ~11 ~39 stained_hardened_clay 15  
fill ~33 ~10 ~40 ~33 ~11 ~40 stonebrick 0  
fill ~34 ~10 ~12 ~34 ~11 ~12 iron_bars 0  
fill ~34 ~10 ~15 ~34 ~11 ~15 nether_brick 0 
setblock ~34 ~10 ~18 redstone_torch 2 
setblock ~34 ~10 ~35 redstone_torch 2  
fill ~34 ~10 ~36 ~34 ~7 ~36 bookshelf 0  
fill ~34 ~10 ~39 ~34 ~11 ~39 iron_bars 0  
fill ~35 ~10 ~11 ~35 ~11 ~11 stonebrick 0  
fill ~35 ~10 ~12 ~35 ~11 ~12 stained_hardened_clay 15  
fill ~35 ~10 ~13 ~35 ~11 ~13 stained_hardened_clay 15  
fill ~35 ~10 ~14 ~35 ~11 ~14 stained_hardened_clay 15  
fill ~35 ~10 ~15 ~35 ~11 ~15 stained_hardened_clay 15  
fill ~35 ~10 ~19 ~35 ~10 ~32 obsidian 0  
fill ~35 ~10 ~33 ~35 ~7 ~33 nether_brick 0 
setblock ~35 ~10 ~34 redstone_torch 4  
fill ~35 ~10 ~35 ~35 ~7 ~35 bookshelf 0  
fill ~35 ~10 ~36 ~35 ~11 ~36 stained_hardened_clay 15  
fill ~35 ~10 ~37 ~35 ~11 ~37 stained_hardened_clay 15  
fill ~35 ~10 ~38 ~35 ~11 ~38 stained_hardened_clay 15  
fill ~35 ~10 ~39 ~35 ~11 ~39 stained_hardened_clay 15  
fill ~35 ~10 ~40 ~35 ~11 ~40 stonebrick 0 
setblock ~36 ~10 ~11 stone_brick_stairs 1 
setblock ~36 ~10 ~15 fire 15  
fill ~36 ~10 ~16 ~39 ~10 ~16 stained_hardened_clay 15  
fill ~36 ~10 ~18 ~39 ~10 ~18 stained_hardened_clay 15 
setblock ~36 ~10 ~19 fire 15 
setblock ~36 ~10 ~32 fire 15  
fill ~36 ~10 ~33 ~39 ~10 ~33 stained_hardened_clay 15  
fill ~36 ~10 ~35 ~39 ~10 ~35 stained_hardened_clay 15 
setblock ~36 ~10 ~36 fire 15 
setblock ~36 ~10 ~40 stone_brick_stairs 1 
setblock ~40 ~10 ~15 stone_brick_stairs 2  
fill ~40 ~10 ~16 ~40 ~11 ~16 stonebrick 2  
fill ~40 ~10 ~18 ~40 ~11 ~18 stonebrick 0 
setblock ~40 ~10 ~19 stone_brick_stairs 3 
setblock ~40 ~10 ~32 stone_brick_stairs 2  
fill ~40 ~10 ~33 ~40 ~11 ~33 stonebrick 0  
fill ~40 ~10 ~35 ~40 ~11 ~35 stonebrick 0 
setblock ~40 ~10 ~36 stone_brick_stairs 3  
fill ~12 ~11 ~16 ~15 ~11 ~16 stained_hardened_clay 15  
fill ~12 ~11 ~18 ~15 ~11 ~18 stained_hardened_clay 15  
fill ~12 ~11 ~33 ~15 ~11 ~33 stained_hardened_clay 15  
fill ~12 ~11 ~35 ~15 ~11 ~35 stained_hardened_clay 15  
fill ~15 ~11 ~17 ~35 ~11 ~17 planks 1  
fill ~15 ~11 ~34 ~36 ~11 ~34 planks 1 
setblock ~16 ~11 ~16 netherrack 0 
