fill ~3 ~0 ~30 ~3 ~0 ~35 planks  
fill ~4 ~0 ~28 ~4 ~0 ~29 planks  
fill ~4 ~0 ~36 ~4 ~0 ~37 planks  
fill ~5 ~0 ~26 ~5 ~0 ~27 planks  
fill ~5 ~0 ~38 ~5 ~0 ~39 planks 
setblock ~6 ~0 ~25 planks 1 
setblock ~6 ~0 ~40 planks 1 
setblock ~7 ~0 ~24 planks 1 
setblock ~7 ~0 ~41 planks 1 
setblock ~8 ~0 ~23 planks 1 
setblock ~8 ~0 ~42 planks 1  
fill ~9 ~0 ~22 ~10 ~0 ~22 planks  
fill ~9 ~0 ~43 ~10 ~0 ~43 planks  
fill ~11 ~0 ~21 ~12 ~0 ~21 planks  
fill ~11 ~0 ~44 ~12 ~0 ~44 planks  
fill ~13 ~0 ~20 ~16 ~0 ~20 planks  
fill ~13 ~0 ~45 ~16 ~0 ~45 planks  
fill ~16 ~0 ~15 ~16 ~5 ~15 log  
fill ~16 ~0 ~16 ~16 ~0 ~30 planks  
fill ~16 ~0 ~31 ~16 ~5 ~31 log  
fill ~16 ~0 ~32 ~16 ~0 ~33 fence_gate  
fill ~16 ~0 ~34 ~16 ~5 ~34 log  
fill ~16 ~0 ~35 ~16 ~0 ~54 planks  
fill ~16 ~0 ~55 ~16 ~6 ~55 log  
fill ~17 ~0 ~15 ~43 ~0 ~15 planks  
fill ~17 ~0 ~55 ~43 ~0 ~55 planks  
fill ~26 ~0 ~25 ~26 ~26 ~25 log  
fill ~26 ~0 ~45 ~26 ~26 ~45 log  
fill ~44 ~0 ~5 ~44 ~5 ~5 log  
fill ~44 ~0 ~6 ~44 ~0 ~14 planks  
fill ~44 ~0 ~15 ~44 ~5 ~15 log  
fill ~44 ~0 ~55 ~44 ~5 ~55 log  
fill ~44 ~0 ~56 ~44 ~0 ~59 planks  
fill ~44 ~0 ~60 ~44 ~5 ~60 log  
fill ~45 ~0 ~5 ~59 ~0 ~5 planks  
fill ~45 ~0 ~60 ~83 ~0 ~60 planks  
fill ~49 ~0 ~20 ~49 ~11 ~20 log  
fill ~49 ~0 ~50 ~49 ~11 ~50 log  
fill ~54 ~0 ~25 ~54 ~19 ~25 log  
fill ~54 ~0 ~45 ~54 ~19 ~45 log  
fill ~60 ~0 ~1 ~60 ~5 ~1 log  
fill ~60 ~0 ~2 ~60 ~0 ~4 planks  
fill ~60 ~0 ~5 ~60 ~5 ~5 log 
setblock ~61 ~0 ~1 planks 1  
fill ~62 ~0 ~1 ~62 ~5 ~1 log  
fill ~63 ~0 ~1 ~63 ~2 ~1 planks 
setblock ~64 ~0 ~1 wooden_door 1  
fill ~65 ~0 ~1 ~65 ~2 ~1 planks  
fill ~66 ~0 ~1 ~66 ~5 ~1 log 
setblock ~67 ~0 ~1 planks 1  
fill ~68 ~0 ~1 ~68 ~5 ~1 log  
fill ~68 ~0 ~2 ~68 ~0 ~4 planks  
fill ~68 ~0 ~5 ~68 ~5 ~5 log  
fill ~69 ~0 ~5 ~83 ~0 ~5 planks  
fill ~74 ~0 ~25 ~74 ~19 ~25 log  
fill ~74 ~0 ~45 ~74 ~19 ~45 log  
fill ~79 ~0 ~20 ~79 ~11 ~20 log  
fill ~79 ~0 ~49 ~79 ~11 ~49 log  
fill ~84 ~0 ~5 ~84 ~5 ~5 log  
fill ~84 ~0 ~6 ~84 ~0 ~14 planks  
fill ~84 ~0 ~15 ~84 ~5 ~15 log  
fill ~84 ~0 ~54 ~84 ~5 ~54 log  
fill ~84 ~0 ~55 ~84 ~0 ~59 planks  
fill ~84 ~0 ~60 ~84 ~5 ~60 log  
fill ~85 ~0 ~15 ~113 ~0 ~15 planks  
fill ~85 ~0 ~54 ~113 ~0 ~54 planks  
fill ~104 ~0 ~25 ~104 ~26 ~25 log  
fill ~104 ~0 ~45 ~104 ~26 ~45 log  
fill ~109 ~0 ~29 ~109 ~11 ~29 log  
fill ~109 ~0 ~41 ~109 ~11 ~41 log  
fill ~114 ~0 ~15 ~114 ~5 ~15 log  
fill ~114 ~0 ~16 ~114 ~0 ~22 planks  
fill ~114 ~0 ~23 ~114 ~5 ~23 log  
fill ~114 ~0 ~47 ~114 ~5 ~47 log  
fill ~114 ~0 ~48 ~114 ~0 ~53 planks  
fill ~114 ~0 ~54 ~114 ~5 ~54 log  
fill ~115 ~0 ~23 ~118 ~0 ~23 planks  
fill ~115 ~0 ~47 ~118 ~0 ~47 planks  
fill ~119 ~0 ~23 ~119 ~5 ~23 log  
fill ~119 ~0 ~24 ~119 ~0 ~33 planks  
fill ~119 ~0 ~37 ~125 ~0 ~37 planks  
fill ~119 ~0 ~38 ~119 ~0 ~46 planks  
fill ~119 ~0 ~47 ~119 ~5 ~47 log  
fill ~120 ~0 ~33 ~125 ~0 ~33 planks  
fill ~126 ~0 ~33 ~126 ~4 ~33 log 
setblock ~126 ~0 ~34 planks 1 
setblock ~126 ~0 ~35 wooden_door 2 
setblock ~126 ~0 ~36 planks 1  
fill ~126 ~0 ~37 ~126 ~4 ~37 log  
fill ~3 ~1 ~30 ~3 ~2 ~30 planks  
fill ~3 ~1 ~31 ~3 ~2 ~31 planks  
fill ~3 ~1 ~32 ~3 ~2 ~32 planks  
fill ~3 ~1 ~33 ~3 ~2 ~33 planks  
fill ~3 ~1 ~34 ~3 ~2 ~34 planks  
fill ~3 ~1 ~35 ~3 ~2 ~35 planks  
fill ~4 ~1 ~28 ~4 ~2 ~28 planks  
fill ~4 ~1 ~29 ~4 ~2 ~29 planks  
fill ~4 ~1 ~36 ~4 ~2 ~36 planks  
fill ~4 ~1 ~37 ~4 ~2 ~37 planks  
fill ~5 ~1 ~26 ~5 ~2 ~26 planks  
fill ~5 ~1 ~27 ~5 ~2 ~27 planks  
fill ~5 ~1 ~38 ~5 ~2 ~38 planks  
fill ~5 ~1 ~39 ~5 ~2 ~39 planks  
fill ~6 ~1 ~25 ~6 ~2 ~25 planks  
fill ~6 ~1 ~40 ~6 ~2 ~40 planks  
fill ~7 ~1 ~24 ~7 ~2 ~24 planks  
fill ~7 ~1 ~41 ~7 ~2 ~41 planks  
fill ~8 ~1 ~23 ~8 ~2 ~23 planks  
fill ~8 ~1 ~42 ~8 ~2 ~42 planks  
fill ~9 ~1 ~22 ~10 ~1 ~22 planks  
fill ~9 ~1 ~43 ~10 ~1 ~43 planks  
fill ~11 ~1 ~21 ~12 ~1 ~21 planks  
fill ~11 ~1 ~44 ~12 ~1 ~44 planks  
fill ~13 ~1 ~20 ~16 ~1 ~20 planks  
fill ~13 ~1 ~45 ~16 ~1 ~45 planks  
fill ~16 ~1 ~16 ~16 ~2 ~16 planks  
fill ~16 ~1 ~17 ~16 ~2 ~17 planks  
fill ~16 ~1 ~18 ~16 ~2 ~18 planks  
fill ~16 ~1 ~19 ~16 ~2 ~19 planks  
fill ~16 ~1 ~21 ~16 ~2 ~21 nether_brick_fence  
fill ~16 ~1 ~22 ~16 ~2 ~22 nether_brick_fence  
fill ~16 ~1 ~23 ~16 ~2 ~23 nether_brick_fence  
fill ~16 ~1 ~24 ~16 ~2 ~24 nether_brick_fence  
fill ~16 ~1 ~25 ~16 ~2 ~25 nether_brick_fence  
fill ~16 ~1 ~26 ~16 ~2 ~26 nether_brick_fence  
fill ~16 ~1 ~27 ~16 ~2 ~27 nether_brick_fence  
fill ~16 ~1 ~28 ~16 ~2 ~28 nether_brick_fence  
fill ~16 ~1 ~29 ~16 ~2 ~29 nether_brick_fence  
fill ~16 ~1 ~30 ~16 ~2 ~30 nether_brick_fence  
fill ~16 ~1 ~35 ~16 ~2 ~35 planks  
fill ~16 ~1 ~36 ~16 ~2 ~36 planks  
fill ~16 ~1 ~37 ~16 ~2 ~37 planks  
fill ~16 ~1 ~38 ~16 ~2 ~38 planks  
fill ~16 ~1 ~39 ~16 ~2 ~39 planks  
fill ~16 ~1 ~40 ~16 ~2 ~40 planks  
fill ~16 ~1 ~41 ~16 ~2 ~41 planks  
fill ~16 ~1 ~42 ~16 ~2 ~42 planks  
fill ~16 ~1 ~43 ~16 ~2 ~43 planks  
fill ~16 ~1 ~44 ~16 ~2 ~44 planks  
fill ~16 ~1 ~46 ~16 ~2 ~46 planks  
fill ~16 ~1 ~47 ~16 ~2 ~47 planks  
fill ~16 ~1 ~48 ~16 ~2 ~48 planks  
fill ~16 ~1 ~49 ~16 ~2 ~49 planks  
fill ~16 ~1 ~50 ~16 ~2 ~50 planks  
fill ~16 ~1 ~51 ~16 ~2 ~51 planks  
fill ~16 ~1 ~52 ~16 ~2 ~52 planks  
fill ~16 ~1 ~53 ~16 ~2 ~53 planks  
fill ~16 ~1 ~54 ~16 ~2 ~54 planks  
fill ~17 ~1 ~15 ~43 ~1 ~15 planks 
setblock ~17 ~1 ~16 torch 3 
setblock ~17 ~1 ~31 torch 1 
setblock ~17 ~1 ~34 torch 1 
setblock ~17 ~1 ~54 torch 4  
fill ~17 ~1 ~55 ~43 ~1 ~55 planks 
setblock ~25 ~1 ~25 torch 2 
setblock ~25 ~1 ~45 torch 2 
setblock ~26 ~1 ~24 torch 4 
setblock ~26 ~1 ~26 torch 3 
setblock ~26 ~1 ~44 torch 4 
setblock ~26 ~1 ~46 torch 3 
setblock ~27 ~1 ~25 torch 1 
setblock ~27 ~1 ~45 torch 1  
fill ~44 ~1 ~6 ~44 ~2 ~6 planks  
fill ~44 ~1 ~7 ~44 ~2 ~7 planks  
fill ~44 ~1 ~8 ~44 ~2 ~8 planks  
fill ~44 ~1 ~9 ~44 ~2 ~9 planks  
fill ~44 ~1 ~10 ~44 ~2 ~10 planks  
fill ~44 ~1 ~11 ~44 ~2 ~11 planks  
fill ~44 ~1 ~12 ~44 ~2 ~12 planks  
fill ~44 ~1 ~13 ~44 ~2 ~13 planks  
fill ~44 ~1 ~14 ~44 ~2 ~14 planks 
setblock ~44 ~1 ~16 torch 3 
setblock ~44 ~1 ~54 torch 4  
fill ~44 ~1 ~56 ~44 ~2 ~56 planks  
fill ~44 ~1 ~57 ~44 ~2 ~57 planks  
fill ~44 ~1 ~58 ~44 ~2 ~58 planks  
fill ~44 ~1 ~59 ~44 ~2 ~59 planks  
fill ~45 ~1 ~5 ~59 ~1 ~5 planks 
setblock ~45 ~1 ~6 torch 1 
setblock ~45 ~1 ~15 torch 1 
setblock ~45 ~1 ~55 torch 1  
fill ~45 ~1 ~60 ~83 ~1 ~60 planks 
setblock ~48 ~1 ~20 torch 2 
setblock ~48 ~1 ~50 torch 2 
setblock ~49 ~1 ~19 torch 4 
setblock ~49 ~1 ~21 torch 3 
setblock ~49 ~1 ~49 torch 4 
setblock ~49 ~1 ~51 torch 3 
setblock ~50 ~1 ~20 torch 1 
setblock ~50 ~1 ~50 torch 1 
setblock ~53 ~1 ~25 torch 2 
setblock ~53 ~1 ~45 torch 2 
setblock ~54 ~1 ~24 torch 4 
setblock ~54 ~1 ~26 torch 3 
setblock ~54 ~1 ~44 torch 4 
setblock ~54 ~1 ~46 torch 3 
setblock ~54 ~1 ~59 torch 4 
setblock ~55 ~1 ~25 torch 1 
setblock ~55 ~1 ~45 torch 1  
fill ~60 ~1 ~2 ~60 ~2 ~2 planks  
fill ~60 ~1 ~3 ~60 ~2 ~3 planks  
fill ~60 ~1 ~4 ~60 ~2 ~4 planks 
setblock ~60 ~1 ~6 torch 3  
fill ~61 ~1 ~1 ~61 ~2 ~1 planks 
setblock ~61 ~1 ~5 torch 1 
setblock ~62 ~1 ~2 torch 3 
setblock ~64 ~1 ~1 wooden_door 8 
setblock ~66 ~1 ~2 torch 3  
fill ~67 ~1 ~1 ~67 ~2 ~1 planks 
setblock ~67 ~1 ~5 torch 2  
fill ~68 ~1 ~2 ~68 ~2 ~2 planks  
fill ~68 ~1 ~3 ~68 ~2 ~3 planks  
fill ~68 ~1 ~4 ~68 ~2 ~4 planks 
setblock ~68 ~1 ~6 torch 3  
fill ~69 ~1 ~5 ~83 ~1 ~5 planks 
setblock ~73 ~1 ~25 torch 2 
setblock ~73 ~1 ~45 torch 2 
setblock ~74 ~1 ~24 torch 4 
setblock ~74 ~1 ~26 torch 3 
setblock ~74 ~1 ~44 torch 4 
setblock ~74 ~1 ~46 torch 3 
setblock ~74 ~1 ~59 torch 4 
setblock ~75 ~1 ~25 torch 1 
setblock ~75 ~1 ~45 torch 1 
setblock ~78 ~1 ~20 torch 2 
setblock ~78 ~1 ~49 torch 2 
setblock ~79 ~1 ~19 torch 4 
setblock ~79 ~1 ~21 torch 3 
setblock ~79 ~1 ~48 torch 4 
setblock ~79 ~1 ~50 torch 3 
setblock ~80 ~1 ~20 torch 1 
setblock ~80 ~1 ~49 torch 1 
setblock ~83 ~1 ~6 torch 2 
setblock ~83 ~1 ~15 torch 2 
setblock ~83 ~1 ~54 torch 2  
fill ~84 ~1 ~6 ~84 ~2 ~6 planks  
fill ~84 ~1 ~7 ~84 ~2 ~7 planks  
fill ~84 ~1 ~8 ~84 ~2 ~8 planks  
fill ~84 ~1 ~9 ~84 ~2 ~9 planks  
fill ~84 ~1 ~10 ~84 ~2 ~10 planks  
fill ~84 ~1 ~11 ~84 ~2 ~11 planks  
fill ~84 ~1 ~12 ~84 ~2 ~12 planks  
fill ~84 ~1 ~13 ~84 ~2 ~13 planks  
fill ~84 ~1 ~14 ~84 ~2 ~14 planks 
setblock ~84 ~1 ~16 torch 3 
setblock ~84 ~1 ~53 torch 4  
fill ~84 ~1 ~55 ~84 ~2 ~55 planks  
fill ~84 ~1 ~56 ~84 ~2 ~56 planks  
fill ~84 ~1 ~57 ~84 ~2 ~57 planks  
fill ~84 ~1 ~58 ~84 ~2 ~58 planks  
fill ~84 ~1 ~59 ~84 ~2 ~59 planks  
fill ~85 ~1 ~15 ~113 ~1 ~15 planks  
fill ~85 ~1 ~54 ~113 ~1 ~54 planks 
setblock ~97 ~1 ~16 torch 3 
setblock ~97 ~1 ~53 torch 4 
setblock ~103 ~1 ~25 torch 2 
setblock ~103 ~1 ~45 torch 2 
setblock ~104 ~1 ~24 torch 4 
setblock ~104 ~1 ~26 torch 3 
setblock ~104 ~1 ~44 torch 4 
setblock ~104 ~1 ~46 torch 3 
setblock ~105 ~1 ~25 torch 1 
setblock ~105 ~1 ~45 torch 1 
setblock ~108 ~1 ~29 torch 2 
setblock ~108 ~1 ~41 torch 2 
setblock ~109 ~1 ~28 torch 4 
setblock ~109 ~1 ~30 torch 3 
setblock ~109 ~1 ~40 torch 4 
setblock ~109 ~1 ~42 torch 3 
setblock ~110 ~1 ~29 torch 1 
setblock ~110 ~1 ~41 torch 1 
setblock ~113 ~1 ~16 torch 2 
setblock ~113 ~1 ~23 torch 2 
setblock ~113 ~1 ~47 torch 2 
setblock ~113 ~1 ~53 torch 2  
fill ~114 ~1 ~16 ~114 ~2 ~16 planks  
fill ~114 ~1 ~17 ~114 ~2 ~17 planks  
fill ~114 ~1 ~18 ~114 ~2 ~18 planks  
fill ~114 ~1 ~19 ~114 ~2 ~19 planks  
fill ~114 ~1 ~20 ~114 ~2 ~20 planks  
fill ~114 ~1 ~21 ~114 ~2 ~21 planks  
fill ~114 ~1 ~22 ~114 ~2 ~22 planks 
setblock ~114 ~1 ~24 torch 3 
setblock ~114 ~1 ~46 torch 4  
fill ~114 ~1 ~48 ~114 ~2 ~48 planks  
fill ~114 ~1 ~49 ~114 ~2 ~49 planks  
fill ~114 ~1 ~50 ~114 ~2 ~50 planks  
fill ~114 ~1 ~51 ~114 ~2 ~51 planks  
fill ~114 ~1 ~52 ~114 ~2 ~52 planks  
fill ~114 ~1 ~53 ~114 ~2 ~53 planks  
fill ~115 ~1 ~23 ~118 ~1 ~23 planks  
fill ~115 ~1 ~47 ~118 ~1 ~47 planks 
setblock ~118 ~1 ~24 torch 2 
setblock ~118 ~1 ~46 torch 2  
fill ~119 ~1 ~24 ~119 ~2 ~24 planks  
fill ~119 ~1 ~25 ~119 ~2 ~25 planks  
fill ~119 ~1 ~26 ~119 ~2 ~26 planks  
fill ~119 ~1 ~27 ~119 ~2 ~27 planks  
fill ~119 ~1 ~28 ~119 ~2 ~28 planks  
fill ~119 ~1 ~29 ~119 ~2 ~29 planks  
fill ~119 ~1 ~30 ~119 ~2 ~30 planks  
fill ~119 ~1 ~31 ~119 ~2 ~31 planks  
fill ~119 ~1 ~32 ~119 ~2 ~32 planks  
fill ~119 ~1 ~33 ~125 ~1 ~33 planks  
fill ~119 ~1 ~37 ~125 ~1 ~37 planks  
fill ~119 ~1 ~38 ~119 ~2 ~38 planks  
fill ~119 ~1 ~39 ~119 ~2 ~39 planks  
fill ~119 ~1 ~40 ~119 ~2 ~40 planks  
fill ~119 ~1 ~41 ~119 ~2 ~41 planks  
fill ~119 ~1 ~42 ~119 ~2 ~42 planks  
fill ~119 ~1 ~43 ~119 ~2 ~43 planks  
fill ~119 ~1 ~44 ~119 ~2 ~44 planks  
fill ~119 ~1 ~45 ~119 ~2 ~45 planks  
fill ~119 ~1 ~46 ~119 ~2 ~46 planks  
fill ~126 ~1 ~34 ~126 ~2 ~34 planks 
setblock ~126 ~1 ~35 wooden_door 8  
fill ~126 ~1 ~36 ~126 ~2 ~36 planks  
fill ~9 ~2 ~22 ~10 ~2 ~22 planks  
fill ~9 ~2 ~43 ~10 ~2 ~43 planks  
fill ~11 ~2 ~21 ~12 ~2 ~21 planks  
fill ~11 ~2 ~44 ~12 ~2 ~44 planks  
fill ~13 ~2 ~20 ~16 ~2 ~20 planks  
fill ~13 ~2 ~45 ~16 ~2 ~45 planks  
fill ~17 ~2 ~15 ~43 ~2 ~15 planks  
fill ~17 ~2 ~55 ~43 ~2 ~55 planks  
fill ~45 ~2 ~5 ~59 ~2 ~5 planks  
fill ~45 ~2 ~60 ~83 ~2 ~60 planks 
setblock ~64 ~2 ~1 planks 3  
fill ~69 ~2 ~5 ~83 ~2 ~5 planks  
fill ~85 ~2 ~15 ~113 ~2 ~15 planks  
fill ~85 ~2 ~54 ~113 ~2 ~54 planks  
fill ~115 ~2 ~23 ~118 ~2 ~23 planks  
fill ~115 ~2 ~47 ~118 ~2 ~47 planks  
fill ~119 ~2 ~33 ~125 ~2 ~33 planks  
fill ~119 ~2 ~37 ~125 ~2 ~37 planks 
setblock ~126 ~2 ~35 planks 3  
fill ~3 ~3 ~30 ~3 ~3 ~35 planks  
fill ~4 ~3 ~28 ~4 ~3 ~29 planks 
setblock ~4 ~3 ~32 torch 1  
fill ~4 ~3 ~36 ~4 ~3 ~37 planks  
fill ~5 ~3 ~26 ~5 ~3 ~27 planks  
fill ~5 ~3 ~38 ~5 ~3 ~39 planks 
setblock ~6 ~3 ~25 planks 1 
setblock ~6 ~3 ~40 planks 1 
setblock ~7 ~3 ~24 planks 1 
setblock ~7 ~3 ~41 planks 1 
setblock ~8 ~3 ~23 planks 1 
setblock ~8 ~3 ~42 planks 1  
fill ~9 ~3 ~22 ~10 ~3 ~22 planks  
fill ~9 ~3 ~43 ~10 ~3 ~43 planks  
fill ~11 ~3 ~21 ~12 ~3 ~21 planks  
fill ~11 ~3 ~44 ~12 ~3 ~44 planks  
fill ~13 ~3 ~20 ~16 ~3 ~20 planks  
fill ~13 ~3 ~45 ~16 ~3 ~45 planks  
fill ~16 ~3 ~16 ~16 ~3 ~30 planks  
fill ~16 ~3 ~35 ~16 ~3 ~54 planks  
fill ~17 ~3 ~15 ~43 ~3 ~15 planks  
fill ~17 ~3 ~55 ~43 ~3 ~55 planks  
fill ~44 ~3 ~6 ~44 ~3 ~14 planks  
fill ~44 ~3 ~56 ~44 ~3 ~59 planks  
fill ~45 ~3 ~5 ~59 ~3 ~5 planks  
fill ~45 ~3 ~60 ~83 ~3 ~60 planks  
fill ~60 ~3 ~2 ~60 ~3 ~4 planks 
setblock ~61 ~3 ~0 torch 4 
setblock ~61 ~3 ~1 planks 1  
fill ~63 ~3 ~1 ~65 ~3 ~1 planks 
setblock ~67 ~3 ~0 torch 4 
setblock ~67 ~3 ~1 planks 1  
fill ~68 ~3 ~2 ~68 ~3 ~4 planks  
fill ~69 ~3 ~5 ~83 ~3 ~5 planks  
fill ~84 ~3 ~6 ~84 ~3 ~14 planks  
fill ~84 ~3 ~55 ~84 ~3 ~59 planks  
fill ~85 ~3 ~15 ~113 ~3 ~15 planks  
fill ~85 ~3 ~54 ~113 ~3 ~54 planks  
fill ~114 ~3 ~16 ~114 ~3 ~22 planks  
fill ~114 ~3 ~48 ~114 ~3 ~53 planks  
fill ~115 ~3 ~23 ~118 ~3 ~23 planks  
fill ~115 ~3 ~47 ~118 ~3 ~47 planks  
fill ~119 ~3 ~24 ~119 ~3 ~33 planks  
fill ~119 ~3 ~37 ~125 ~3 ~37 planks  
fill ~119 ~3 ~38 ~119 ~3 ~46 planks  
fill ~120 ~3 ~33 ~125 ~3 ~33 planks  
fill ~126 ~3 ~34 ~126 ~3 ~36 planks  
fill ~3 ~4 ~30 ~3 ~5 ~30 nether_brick_fence  
fill ~3 ~4 ~31 ~3 ~5 ~31 nether_brick_fence  
fill ~3 ~4 ~32 ~3 ~5 ~32 nether_brick_fence  
fill ~3 ~4 ~33 ~3 ~5 ~33 nether_brick_fence  
fill ~3 ~4 ~34 ~3 ~5 ~34 nether_brick_fence  
fill ~3 ~4 ~35 ~3 ~5 ~35 nether_brick_fence  
fill ~4 ~4 ~28 ~4 ~5 ~28 nether_brick_fence  
fill ~4 ~4 ~29 ~4 ~5 ~29 nether_brick_fence  
fill ~4 ~4 ~36 ~4 ~5 ~36 nether_brick_fence  
fill ~4 ~4 ~37 ~4 ~5 ~37 nether_brick_fence  
fill ~5 ~4 ~26 ~5 ~5 ~26 nether_brick_fence  
fill ~5 ~4 ~27 ~5 ~5 ~27 nether_brick_fence  
fill ~5 ~4 ~38 ~5 ~5 ~38 nether_brick_fence  
fill ~5 ~4 ~39 ~5 ~5 ~39 nether_brick_fence  
fill ~6 ~4 ~25 ~6 ~5 ~25 nether_brick_fence  
fill ~6 ~4 ~40 ~6 ~5 ~40 nether_brick_fence  
fill ~7 ~4 ~24 ~7 ~5 ~24 nether_brick_fence  
fill ~7 ~4 ~41 ~7 ~5 ~41 nether_brick_fence  
fill ~8 ~4 ~23 ~8 ~5 ~23 nether_brick_fence  
fill ~8 ~4 ~42 ~8 ~5 ~42 nether_brick_fence  
fill ~9 ~4 ~22 ~10 ~4 ~22 nether_brick_fence  
fill ~9 ~4 ~43 ~10 ~4 ~43 nether_brick_fence  
fill ~11 ~4 ~21 ~12 ~4 ~21 nether_brick_fence  
fill ~11 ~4 ~44 ~12 ~4 ~44 nether_brick_fence  
fill ~13 ~4 ~20 ~13 ~5 ~20 nether_brick_fence  
fill ~13 ~4 ~45 ~13 ~5 ~45 nether_brick_fence 
setblock ~14 ~4 ~20 torch 5  
fill ~15 ~4 ~20 ~15 ~5 ~20 nether_brick_fence 
setblock ~15 ~4 ~31 torch 2 
setblock ~15 ~4 ~34 torch 2  
fill ~15 ~4 ~45 ~15 ~5 ~45 nether_brick_fence  
fill ~16 ~4 ~17 ~16 ~5 ~17 nether_brick_fence  
fill ~16 ~4 ~19 ~16 ~5 ~19 nether_brick_fence  
fill ~16 ~4 ~21 ~16 ~5 ~21 nether_brick_fence  
fill ~16 ~4 ~23 ~16 ~5 ~23 nether_brick_fence  
fill ~16 ~4 ~25 ~16 ~5 ~25 nether_brick_fence  
fill ~16 ~4 ~27 ~16 ~5 ~27 nether_brick_fence  
fill ~16 ~4 ~29 ~16 ~5 ~29 nether_brick_fence  
fill ~16 ~4 ~36 ~16 ~5 ~36 nether_brick_fence  
fill ~16 ~4 ~38 ~16 ~5 ~38 nether_brick_fence  
fill ~16 ~4 ~40 ~16 ~5 ~40 nether_brick_fence  
fill ~16 ~4 ~42 ~16 ~5 ~42 nether_brick_fence  
fill ~16 ~4 ~44 ~16 ~5 ~44 nether_brick_fence 
setblock ~16 ~4 ~45 torch 5  
fill ~16 ~4 ~46 ~16 ~5 ~46 nether_brick_fence  
fill ~16 ~4 ~48 ~16 ~5 ~48 nether_brick_fence  
fill ~16 ~4 ~50 ~16 ~5 ~50 nether_brick_fence  
fill ~16 ~4 ~52 ~16 ~5 ~52 nether_brick_fence  
fill ~16 ~4 ~54 ~16 ~5 ~54 nether_brick_fence 
setblock ~17 ~4 ~31 torch 1 
setblock ~17 ~4 ~34 torch 1  
fill ~17 ~4 ~55 ~17 ~5 ~55 nether_brick_fence  
fill ~18 ~4 ~15 ~18 ~5 ~15 nether_brick_fence  
fill ~19 ~4 ~55 ~19 ~5 ~55 nether_brick_fence  
fill ~20 ~4 ~15 ~20 ~5 ~15 nether_brick_fence  
fill ~21 ~4 ~55 ~21 ~5 ~55 nether_brick_fence  
fill ~22 ~4 ~15 ~22 ~5 ~15 nether_brick_fence  
fill ~23 ~4 ~55 ~23 ~5 ~55 nether_brick_fence  
fill ~24 ~4 ~15 ~24 ~5 ~15 nether_brick_fence  
fill ~25 ~4 ~55 ~25 ~5 ~55 nether_brick_fence  
fill ~26 ~4 ~15 ~26 ~5 ~15 nether_brick_fence  
fill ~27 ~4 ~55 ~27 ~5 ~55 nether_brick_fence  
fill ~28 ~4 ~15 ~28 ~5 ~15 nether_brick_fence  
fill ~29 ~4 ~55 ~29 ~5 ~55 nether_brick_fence  
fill ~30 ~4 ~15 ~30 ~5 ~15 nether_brick_fence  
fill ~31 ~4 ~55 ~31 ~5 ~55 nether_brick_fence  
fill ~32 ~4 ~15 ~32 ~5 ~15 nether_brick_fence  
fill ~33 ~4 ~55 ~33 ~5 ~55 nether_brick_fence  
fill ~34 ~4 ~15 ~34 ~5 ~15 nether_brick_fence  
fill ~35 ~4 ~55 ~35 ~5 ~55 nether_brick_fence  
fill ~36 ~4 ~15 ~36 ~5 ~15 nether_brick_fence  
fill ~37 ~4 ~55 ~37 ~5 ~55 nether_brick_fence  
fill ~38 ~4 ~15 ~38 ~5 ~15 nether_brick_fence  
fill ~39 ~4 ~55 ~39 ~5 ~55 nether_brick_fence  
fill ~40 ~4 ~15 ~40 ~5 ~15 nether_brick_fence  
fill ~41 ~4 ~55 ~41 ~5 ~55 nether_brick_fence  
fill ~42 ~4 ~15 ~42 ~5 ~15 nether_brick_fence  
fill ~43 ~4 ~55 ~43 ~5 ~55 nether_brick_fence  
fill ~44 ~4 ~7 ~44 ~5 ~7 nether_brick_fence  
fill ~44 ~4 ~9 ~44 ~5 ~9 nether_brick_fence  
fill ~44 ~4 ~11 ~44 ~5 ~11 nether_brick_fence  
fill ~44 ~4 ~13 ~44 ~5 ~13 nether_brick_fence  
fill ~44 ~4 ~56 ~44 ~5 ~56 nether_brick_fence  
fill ~44 ~4 ~58 ~44 ~5 ~58 nether_brick_fence  
fill ~46 ~4 ~5 ~46 ~5 ~5 nether_brick_fence  
fill ~46 ~4 ~60 ~46 ~5 ~60 nether_brick_fence  
fill ~48 ~4 ~5 ~48 ~5 ~5 nether_brick_fence  
fill ~48 ~4 ~60 ~48 ~5 ~60 nether_brick_fence  
fill ~50 ~4 ~5 ~50 ~5 ~5 nether_brick_fence  
fill ~50 ~4 ~60 ~50 ~5 ~60 nether_brick_fence  
fill ~52 ~4 ~5 ~52 ~5 ~5 nether_brick_fence  
fill ~52 ~4 ~60 ~52 ~5 ~60 nether_brick_fence  
fill ~54 ~4 ~5 ~54 ~5 ~5 nether_brick_fence  
fill ~54 ~4 ~60 ~54 ~5 ~60 nether_brick_fence  
fill ~56 ~4 ~5 ~56 ~5 ~5 nether_brick_fence  
fill ~56 ~4 ~60 ~56 ~5 ~60 nether_brick_fence  
fill ~58 ~4 ~5 ~58 ~5 ~5 nether_brick_fence  
fill ~58 ~4 ~60 ~58 ~5 ~60 nether_brick_fence  
fill ~60 ~4 ~3 ~60 ~5 ~3 nether_brick_fence  
fill ~60 ~4 ~60 ~60 ~5 ~60 nether_brick_fence  
fill ~61 ~4 ~1 ~61 ~5 ~1 nether_brick_fence  
fill ~62 ~4 ~60 ~62 ~5 ~60 nether_brick_fence  
fill ~63 ~4 ~1 ~65 ~4 ~1 nether_brick_fence  
fill ~64 ~4 ~60 ~64 ~5 ~60 nether_brick_fence  
fill ~66 ~4 ~60 ~66 ~5 ~60 nether_brick_fence  
fill ~67 ~4 ~1 ~67 ~5 ~1 nether_brick_fence  
fill ~68 ~4 ~3 ~68 ~5 ~3 nether_brick_fence  
fill ~68 ~4 ~60 ~68 ~5 ~60 nether_brick_fence  
fill ~70 ~4 ~5 ~70 ~5 ~5 nether_brick_fence  
fill ~70 ~4 ~60 ~70 ~5 ~60 nether_brick_fence  
fill ~72 ~4 ~5 ~72 ~5 ~5 nether_brick_fence  
fill ~72 ~4 ~60 ~72 ~5 ~60 nether_brick_fence  
fill ~74 ~4 ~5 ~74 ~5 ~5 nether_brick_fence  
fill ~74 ~4 ~60 ~74 ~5 ~60 nether_brick_fence  
fill ~76 ~4 ~5 ~76 ~5 ~5 nether_brick_fence  
fill ~76 ~4 ~60 ~76 ~5 ~60 nether_brick_fence  
fill ~78 ~4 ~5 ~78 ~5 ~5 nether_brick_fence  
fill ~78 ~4 ~60 ~78 ~5 ~60 nether_brick_fence  
fill ~80 ~4 ~5 ~80 ~5 ~5 nether_brick_fence  
fill ~80 ~4 ~60 ~80 ~5 ~60 nether_brick_fence  
fill ~82 ~4 ~5 ~82 ~5 ~5 nether_brick_fence  
fill ~82 ~4 ~60 ~82 ~5 ~60 nether_brick_fence  
fill ~84 ~4 ~7 ~84 ~5 ~7 nether_brick_fence  
fill ~84 ~4 ~9 ~84 ~5 ~9 nether_brick_fence  
fill ~84 ~4 ~11 ~84 ~5 ~11 nether_brick_fence  
fill ~84 ~4 ~13 ~84 ~5 ~13 nether_brick_fence  
fill ~84 ~4 ~56 ~84 ~5 ~56 nether_brick_fence  
fill ~84 ~4 ~58 ~84 ~5 ~58 nether_brick_fence  
fill ~86 ~4 ~15 ~86 ~5 ~15 nether_brick_fence  
fill ~86 ~4 ~54 ~86 ~5 ~54 nether_brick_fence  
fill ~88 ~4 ~15 ~88 ~5 ~15 nether_brick_fence  
fill ~88 ~4 ~54 ~88 ~5 ~54 nether_brick_fence  
fill ~90 ~4 ~15 ~90 ~5 ~15 nether_brick_fence  
fill ~90 ~4 ~54 ~90 ~5 ~54 nether_brick_fence  
fill ~92 ~4 ~15 ~92 ~5 ~15 nether_brick_fence  
fill ~92 ~4 ~54 ~92 ~5 ~54 nether_brick_fence  
fill ~94 ~4 ~15 ~94 ~5 ~15 nether_brick_fence  
fill ~94 ~4 ~54 ~94 ~5 ~54 nether_brick_fence  
fill ~96 ~4 ~15 ~96 ~5 ~15 nether_brick_fence  
fill ~96 ~4 ~54 ~96 ~5 ~54 nether_brick_fence  
fill ~98 ~4 ~15 ~98 ~5 ~15 nether_brick_fence  
fill ~98 ~4 ~54 ~98 ~5 ~54 nether_brick_fence  
fill ~100 ~4 ~15 ~100 ~5 ~15 nether_brick_fence  
fill ~100 ~4 ~54 ~100 ~5 ~54 nether_brick_fence  
fill ~102 ~4 ~15 ~102 ~5 ~15 nether_brick_fence  
fill ~102 ~4 ~54 ~102 ~5 ~54 nether_brick_fence  
fill ~104 ~4 ~15 ~104 ~5 ~15 nether_brick_fence  
fill ~104 ~4 ~54 ~104 ~5 ~54 nether_brick_fence  
fill ~106 ~4 ~15 ~106 ~5 ~15 nether_brick_fence  
fill ~106 ~4 ~54 ~106 ~5 ~54 nether_brick_fence  
fill ~108 ~4 ~15 ~108 ~5 ~15 nether_brick_fence  
fill ~108 ~4 ~54 ~108 ~5 ~54 nether_brick_fence  
fill ~110 ~4 ~15 ~110 ~5 ~15 nether_brick_fence  
fill ~110 ~4 ~54 ~110 ~5 ~54 nether_brick_fence  
fill ~112 ~4 ~15 ~112 ~5 ~15 nether_brick_fence  
fill ~112 ~4 ~54 ~112 ~5 ~54 nether_brick_fence  
fill ~114 ~4 ~16 ~114 ~5 ~16 nether_brick_fence  
fill ~114 ~4 ~18 ~114 ~5 ~18 nether_brick_fence  
fill ~114 ~4 ~20 ~114 ~5 ~20 nether_brick_fence  
fill ~114 ~4 ~22 ~114 ~5 ~22 nether_brick_fence  
fill ~114 ~4 ~48 ~114 ~5 ~48 nether_brick_fence  
fill ~114 ~4 ~50 ~114 ~5 ~50 nether_brick_fence  
fill ~114 ~4 ~52 ~114 ~5 ~52 nether_brick_fence  
fill ~115 ~4 ~23 ~115 ~5 ~23 nether_brick_fence  
fill ~115 ~4 ~47 ~115 ~5 ~47 nether_brick_fence  
fill ~117 ~4 ~23 ~117 ~5 ~23 nether_brick_fence  
fill ~117 ~4 ~47 ~117 ~5 ~47 nether_brick_fence  
fill ~119 ~4 ~25 ~119 ~5 ~25 nether_brick_fence  
fill ~119 ~4 ~27 ~119 ~5 ~27 nether_brick_fence  
fill ~119 ~4 ~29 ~119 ~5 ~29 nether_brick_fence  
fill ~119 ~4 ~31 ~119 ~5 ~31 nether_brick_fence  
fill ~119 ~4 ~33 ~119 ~5 ~33 nether_brick_fence  
fill ~119 ~4 ~37 ~119 ~5 ~37 nether_brick_fence  
fill ~119 ~4 ~39 ~119 ~5 ~39 nether_brick_fence  
fill ~119 ~4 ~41 ~119 ~5 ~41 nether_brick_fence  
fill ~119 ~4 ~43 ~119 ~5 ~43 nether_brick_fence  
fill ~119 ~4 ~45 ~119 ~5 ~45 nether_brick_fence  
fill ~121 ~4 ~33 ~121 ~5 ~33 nether_brick_fence  
fill ~121 ~4 ~37 ~121 ~5 ~37 nether_brick_fence  
fill ~123 ~4 ~33 ~123 ~5 ~33 nether_brick_fence  
fill ~123 ~4 ~37 ~123 ~5 ~37 nether_brick_fence  
fill ~125 ~4 ~33 ~125 ~5 ~33 nether_brick_fence  
fill ~125 ~4 ~37 ~125 ~5 ~37 nether_brick_fence 
setblock ~126 ~4 ~34 planks 3 
setblock ~126 ~4 ~35 planks 1 
setblock ~126 ~4 ~36 planks 3  
fill ~1 ~5 ~30 ~1 ~5 ~35 nether_brick_stairs  
fill ~2 ~5 ~28 ~2 ~5 ~29 nether_brick_stairs 
setblock ~2 ~5 ~36 nether_brick_stairs 3  
fill ~2 ~5 ~37 ~2 ~5 ~38 nether_brick_stairs  
fill ~3 ~5 ~26 ~3 ~5 ~27 nether_brick_stairs 
setblock ~3 ~5 ~39 nether_brick_stairs 0 
setblock ~4 ~5 ~25 nether_brick_stairs 0 
setblock ~4 ~5 ~40 nether_brick_stairs 0 
setblock ~5 ~5 ~24 nether_brick_stairs 0 
setblock ~5 ~5 ~41 nether_brick_stairs 0 
setblock ~6 ~5 ~23 nether_brick_stairs 0 
setblock ~6 ~5 ~42 nether_brick_stairs 0 
setblock ~7 ~5 ~22 nether_brick_stairs 0 
setblock ~7 ~5 ~43 nether_brick_stairs 0 
setblock ~8 ~5 ~21 nether_brick_stairs 2 
setblock ~8 ~5 ~44 nether_brick_stairs 0 
setblock ~9 ~5 ~20 nether_brick_stairs 2  
fill ~9 ~5 ~22 ~10 ~5 ~22 nether_brick_fence  
fill ~9 ~5 ~43 ~10 ~5 ~43 nether_brick_fence 
setblock ~9 ~5 ~45 nether_brick_stairs 3 
setblock ~10 ~5 ~20 nether_brick_stairs 0 
setblock ~10 ~5 ~45 nether_brick_stairs 0 
setblock ~11 ~5 ~19 nether_brick_stairs 2  
fill ~11 ~5 ~21 ~12 ~5 ~21 nether_brick_fence  
fill ~11 ~5 ~44 ~12 ~5 ~44 nether_brick_fence 
setblock ~11 ~5 ~46 nether_brick_stairs 3 
setblock ~12 ~5 ~19 nether_brick_stairs 0 
setblock ~12 ~5 ~46 nether_brick_stairs 0 
setblock ~13 ~5 ~18 nether_brick_stairs 2  
fill ~13 ~5 ~47 ~14 ~5 ~47 nether_brick_stairs  
fill ~14 ~5 ~13 ~14 ~5 ~18 nether_brick_stairs  
fill ~14 ~5 ~48 ~14 ~5 ~56 nether_brick_stairs  
fill ~14 ~5 ~57 ~42 ~5 ~57 nether_brick_stairs  
fill ~15 ~5 ~13 ~41 ~5 ~13 nether_brick_stairs  
fill ~15 ~5 ~14 ~42 ~5 ~14 planks  
fill ~42 ~5 ~3 ~42 ~5 ~13 nether_brick_stairs 
setblock ~42 ~5 ~50 nether_brick_fence 0  
fill ~42 ~5 ~58 ~42 ~5 ~62 nether_brick_stairs  
fill ~43 ~5 ~3 ~57 ~5 ~3 nether_brick_stairs  
fill ~43 ~5 ~62 ~86 ~5 ~62 nether_brick_stairs  
fill ~44 ~5 ~4 ~58 ~5 ~4 planks  
fill ~58 ~5 ~0 ~58 ~5 ~3 nether_brick_stairs  
fill ~63 ~5 ~1 ~65 ~5 ~1 nether_brick_fence  
fill ~70 ~5 ~0 ~70 ~5 ~3 nether_brick_stairs  
fill ~71 ~5 ~3 ~85 ~5 ~3 nether_brick_stairs  
fill ~86 ~5 ~3 ~86 ~5 ~13 nether_brick_stairs  
fill ~86 ~5 ~56 ~86 ~5 ~61 nether_brick_stairs  
fill ~87 ~5 ~13 ~116 ~5 ~13 nether_brick_stairs  
fill ~87 ~5 ~56 ~115 ~5 ~56 nether_brick_stairs  
fill ~116 ~5 ~14 ~116 ~5 ~21 nether_brick_stairs  
fill ~116 ~5 ~22 ~121 ~5 ~22 nether_brick_stairs  
fill ~116 ~5 ~48 ~121 ~5 ~48 nether_brick_stairs  
fill ~116 ~5 ~49 ~116 ~5 ~56 nether_brick_stairs  
fill ~121 ~5 ~23 ~121 ~5 ~31 nether_brick_stairs  
fill ~121 ~5 ~39 ~121 ~5 ~47 nether_brick_stairs  
fill ~122 ~5 ~31 ~126 ~5 ~31 nether_brick_stairs  
fill ~122 ~5 ~39 ~126 ~5 ~39 nether_brick_stairs 
setblock ~126 ~5 ~32 planks 1 
setblock ~126 ~5 ~33 planks 3 
setblock ~126 ~5 ~34 planks 1 
setblock ~126 ~5 ~35 planks 3 
setblock ~126 ~5 ~36 planks 1 
setblock ~126 ~5 ~37 planks 3 
setblock ~126 ~5 ~38 planks 1  
fill ~2 ~6 ~30 ~2 ~6 ~35 nether_brick_stairs 
setblock ~3 ~6 ~28 nether_brick_stairs 0 
setblock ~3 ~6 ~29 nether_brick_stairs 2  
fill ~3 ~6 ~30 ~3 ~6 ~35 planks  
fill ~3 ~6 ~36 ~3 ~6 ~38 nether_brick_stairs 
setblock ~4 ~6 ~26 nether_brick_stairs 0 
setblock ~4 ~6 ~27 nether_brick_stairs 2  
fill ~4 ~6 ~28 ~4 ~6 ~29 planks 
setblock ~4 ~6 ~30 torch 1 
setblock ~4 ~6 ~35 torch 1  
fill ~4 ~6 ~36 ~4 ~6 ~38 planks 
setblock ~4 ~6 ~39 nether_brick_stairs 0 
setblock ~5 ~6 ~25 nether_brick_stairs 0  
fill ~5 ~6 ~26 ~5 ~6 ~27 planks  
fill ~5 ~6 ~38 ~5 ~6 ~39 planks 
setblock ~5 ~6 ~40 nether_brick_stairs 0 
setblock ~6 ~6 ~24 nether_brick_stairs 0 
setblock ~6 ~6 ~25 planks 1 
setblock ~6 ~6 ~27 torch 1 
setblock ~6 ~6 ~38 torch 1 
setblock ~6 ~6 ~40 planks 1 
setblock ~6 ~6 ~41 nether_brick_stairs 0 
setblock ~7 ~6 ~23 nether_brick_stairs 0 
setblock ~7 ~6 ~24 planks 1 
setblock ~7 ~6 ~41 planks 1 
setblock ~7 ~6 ~42 nether_brick_stairs 0 
setblock ~8 ~6 ~22 nether_brick_stairs 0 
setblock ~8 ~6 ~23 planks 1 
setblock ~8 ~6 ~24 torch 1 
setblock ~8 ~6 ~41 torch 1 
setblock ~8 ~6 ~42 planks 1 
setblock ~8 ~6 ~43 nether_brick_stairs 0  
fill ~9 ~6 ~21 ~10 ~6 ~21 nether_brick_stairs  
fill ~9 ~6 ~22 ~10 ~6 ~22 planks  
fill ~9 ~6 ~43 ~10 ~6 ~43 planks 
setblock ~9 ~6 ~44 nether_brick_stairs 3 
setblock ~10 ~6 ~44 nether_brick_stairs 0 
setblock ~11 ~6 ~20 nether_brick_stairs 2  
fill ~11 ~6 ~21 ~12 ~6 ~21 planks 
setblock ~11 ~6 ~22 torch 1 
setblock ~11 ~6 ~43 torch 1 
setblock ~11 ~6 ~44 planks 3 
setblock ~11 ~6 ~45 nether_brick_stairs 3 
setblock ~12 ~6 ~20 nether_brick_stairs 0 
setblock ~12 ~6 ~44 planks 1 
setblock ~12 ~6 ~45 nether_brick_stairs 0  
fill ~13 ~6 ~19 ~14 ~6 ~19 nether_brick_stairs  
fill ~13 ~6 ~20 ~16 ~6 ~20 planks  
fill ~13 ~6 ~45 ~16 ~6 ~45 planks  
fill ~13 ~6 ~46 ~15 ~6 ~46 nether_brick_stairs  
fill ~15 ~6 ~14 ~42 ~6 ~14 nether_brick_stairs  
fill ~15 ~6 ~15 ~15 ~6 ~19 nether_brick_stairs 
setblock ~15 ~6 ~21 torch 2 
setblock ~15 ~6 ~31 torch 2 
setblock ~15 ~6 ~34 torch 2 
setblock ~15 ~6 ~44 torch 2  
fill ~15 ~6 ~47 ~15 ~6 ~55 nether_brick_stairs  
fill ~15 ~6 ~56 ~42 ~6 ~56 nether_brick_stairs  
fill ~16 ~6 ~15 ~44 ~6 ~15 planks  
fill ~16 ~6 ~16 ~16 ~6 ~50 planks  
fill ~16 ~6 ~51 ~16 ~6 ~54 planks  
fill ~17 ~6 ~55 ~44 ~6 ~55 planks  
fill ~43 ~6 ~4 ~59 ~6 ~4 nether_brick_stairs  
fill ~43 ~6 ~5 ~43 ~6 ~14 nether_brick_stairs  
fill ~43 ~6 ~52 ~43 ~6 ~54 nether_brick_stairs  
fill ~43 ~6 ~56 ~43 ~6 ~60 nether_brick_stairs  
fill ~43 ~6 ~61 ~85 ~6 ~61 nether_brick_stairs  
fill ~44 ~6 ~5 ~60 ~6 ~5 planks  
fill ~44 ~6 ~6 ~44 ~6 ~15 planks  
fill ~44 ~6 ~56 ~44 ~6 ~60 planks  
fill ~45 ~6 ~60 ~52 ~6 ~60 planks  
fill ~54 ~6 ~60 ~84 ~6 ~60 planks  
fill ~59 ~6 ~0 ~59 ~6 ~3 nether_brick_stairs  
fill ~60 ~6 ~1 ~68 ~6 ~1 planks  
fill ~60 ~6 ~2 ~60 ~6 ~5 planks  
fill ~68 ~6 ~2 ~68 ~6 ~5 planks  
fill ~69 ~6 ~0 ~69 ~6 ~4 nether_brick_stairs  
fill ~69 ~6 ~5 ~84 ~6 ~5 planks  
fill ~70 ~6 ~4 ~84 ~6 ~4 nether_brick_stairs  
fill ~84 ~6 ~6 ~84 ~6 ~15 planks  
fill ~84 ~6 ~54 ~84 ~6 ~60 planks  
fill ~85 ~6 ~4 ~85 ~6 ~14 nether_brick_stairs  
fill ~85 ~6 ~15 ~114 ~6 ~15 planks  
fill ~85 ~6 ~54 ~113 ~6 ~54 planks  
fill ~85 ~6 ~55 ~114 ~6 ~55 nether_brick_stairs  
fill ~85 ~6 ~56 ~85 ~6 ~60 nether_brick_stairs  
fill ~86 ~6 ~14 ~114 ~6 ~14 nether_brick_stairs  
fill ~114 ~6 ~16 ~114 ~6 ~24 planks  
fill ~114 ~6 ~47 ~114 ~6 ~54 planks  
fill ~115 ~6 ~14 ~115 ~6 ~22 nether_brick_stairs  
fill ~115 ~6 ~23 ~119 ~6 ~23 nether_brick_stairs  
fill ~115 ~6 ~24 ~119 ~6 ~24 planks  
fill ~115 ~6 ~47 ~115 ~6 ~55 nether_brick_stairs  
fill ~116 ~6 ~47 ~119 ~6 ~47 nether_brick_stairs  
fill ~119 ~6 ~25 ~119 ~6 ~33 planks  
fill ~119 ~6 ~37 ~120 ~6 ~37 planks  
fill ~119 ~6 ~38 ~119 ~6 ~46 planks  
fill ~120 ~6 ~23 ~120 ~6 ~32 nether_brick_stairs  
fill ~120 ~6 ~33 ~126 ~6 ~33 planks  
fill ~120 ~6 ~38 ~120 ~6 ~47 nether_brick_stairs  
fill ~121 ~6 ~32 ~126 ~6 ~32 nether_brick_stairs  
fill ~121 ~6 ~38 ~126 ~6 ~38 nether_brick_stairs  
fill ~122 ~6 ~37 ~126 ~6 ~37 planks 
setblock ~126 ~6 ~34 planks 3 
setblock ~126 ~6 ~35 planks 1 
setblock ~126 ~6 ~36 planks 3  
fill ~3 ~7 ~30 ~3 ~7 ~35 nether_brick_stairs 
setblock ~4 ~7 ~28 nether_brick_stairs 0 
setblock ~4 ~7 ~29 nether_brick_stairs 2  
fill ~4 ~7 ~30 ~4 ~7 ~35 planks  
fill ~4 ~7 ~36 ~4 ~7 ~38 nether_brick_stairs 
setblock ~5 ~7 ~26 nether_brick_stairs 0 
setblock ~5 ~7 ~27 nether_brick_stairs 2  
fill ~5 ~7 ~28 ~5 ~7 ~29 planks  
fill ~5 ~7 ~36 ~5 ~7 ~38 planks 
setblock ~5 ~7 ~39 nether_brick_stairs 0 
setblock ~6 ~7 ~25 nether_brick_stairs 0  
fill ~6 ~7 ~26 ~6 ~7 ~27 planks 
setblock ~6 ~7 ~39 planks 3 
setblock ~6 ~7 ~40 nether_brick_stairs 0 
setblock ~7 ~7 ~24 nether_brick_stairs 0 
setblock ~7 ~7 ~25 planks 3 
setblock ~7 ~7 ~40 planks 3 
setblock ~7 ~7 ~41 nether_brick_stairs 0 
setblock ~8 ~7 ~23 nether_brick_stairs 0 
setblock ~8 ~7 ~24 planks 3 
setblock ~8 ~7 ~41 planks 3 
setblock ~8 ~7 ~42 nether_brick_stairs 0  
fill ~9 ~7 ~22 ~10 ~7 ~22 nether_brick_stairs  
fill ~9 ~7 ~23 ~10 ~7 ~23 planks  
fill ~9 ~7 ~42 ~10 ~7 ~42 planks 
setblock ~9 ~7 ~43 nether_brick_stairs 3 
setblock ~10 ~7 ~43 nether_brick_stairs 0 
setblock ~11 ~7 ~21 nether_brick_stairs 2  
fill ~11 ~7 ~22 ~12 ~7 ~22 planks  
fill ~11 ~7 ~43 ~12 ~7 ~43 planks 
setblock ~11 ~7 ~44 nether_brick_stairs 3 
setblock ~12 ~7 ~21 nether_brick_stairs 0 
setblock ~12 ~7 ~44 nether_brick_stairs 0  
fill ~13 ~7 ~20 ~15 ~7 ~20 nether_brick_stairs  
fill ~13 ~7 ~21 ~16 ~7 ~21 planks  
fill ~13 ~7 ~44 ~17 ~7 ~44 planks  
fill ~13 ~7 ~45 ~15 ~7 ~45 nether_brick_stairs  
fill ~15 ~7 ~22 ~16 ~7 ~22 nether_brick_fence  
fill ~16 ~7 ~15 ~43 ~7 ~15 nether_brick_stairs  
fill ~16 ~7 ~16 ~16 ~7 ~20 nether_brick_stairs  
fill ~16 ~7 ~23 ~16 ~8 ~23 nether_brick_fence  
fill ~16 ~7 ~24 ~16 ~9 ~24 nether_brick_fence  
fill ~16 ~7 ~25 ~16 ~10 ~25 nether_brick_fence  
fill ~16 ~7 ~26 ~16 ~11 ~26 nether_brick_fence  
fill ~16 ~7 ~27 ~16 ~12 ~27 nether_brick_fence  
fill ~16 ~7 ~28 ~16 ~13 ~28 nether_brick_fence  
fill ~16 ~7 ~29 ~16 ~14 ~29 nether_brick_fence  
fill ~16 ~7 ~30 ~16 ~14 ~30 nether_brick_fence  
fill ~16 ~7 ~31 ~16 ~17 ~31 nether_brick_fence  
fill ~16 ~7 ~32 ~16 ~17 ~32 nether_brick_fence  
fill ~16 ~7 ~33 ~16 ~17 ~33 nether_brick_fence  
fill ~16 ~7 ~34 ~16 ~17 ~34 nether_brick_fence  
fill ~16 ~7 ~35 ~16 ~14 ~35 nether_brick_fence  
fill ~16 ~7 ~36 ~16 ~14 ~36 nether_brick_fence  
fill ~16 ~7 ~37 ~16 ~13 ~37 nether_brick_fence  
fill ~16 ~7 ~38 ~16 ~12 ~38 nether_brick_fence  
fill ~16 ~7 ~39 ~16 ~11 ~39 nether_brick_fence  
fill ~16 ~7 ~40 ~16 ~10 ~40 nether_brick_fence  
fill ~16 ~7 ~41 ~16 ~9 ~41 nether_brick_fence  
fill ~16 ~7 ~42 ~16 ~8 ~42 nether_brick_fence  
fill ~16 ~7 ~43 ~16 ~7 ~22 nether_brick_fence  
fill ~16 ~7 ~45 ~16 ~7 ~55 nether_brick_stairs  
fill ~17 ~7 ~45 ~17 ~7 ~54 planks  
fill ~17 ~7 ~55 ~43 ~7 ~55 nether_brick_stairs  
fill ~18 ~7 ~54 ~44 ~7 ~54 planks  
fill ~44 ~7 ~5 ~44 ~7 ~15 nether_brick_stairs  
fill ~44 ~7 ~55 ~44 ~7 ~60 nether_brick_stairs  
fill ~45 ~7 ~5 ~59 ~7 ~5 nether_brick_stairs  
fill ~45 ~7 ~60 ~84 ~7 ~60 nether_brick_stairs   
fill ~60 ~7 ~0 ~60 ~7 ~5 nether_brick_stairs 
setblock ~61 ~7 ~1 planks 3 
setblock ~62 ~7 ~1 planks 1 
setblock ~63 ~7 ~1 planks 3 
setblock ~64 ~7 ~1 planks 1 
setblock ~65 ~7 ~1 planks 3 
setblock ~66 ~7 ~1 planks 1 
setblock ~67 ~7 ~1 planks 3  
fill ~68 ~7 ~0 ~68 ~7 ~4 nether_brick_stairs  
fill ~68 ~7 ~5 ~83 ~7 ~5 nether_brick_stairs  
fill ~84 ~7 ~5 ~84 ~7 ~14 nether_brick_stairs  
fill ~84 ~7 ~15 ~113 ~7 ~15 nether_brick_stairs  
fill ~84 ~7 ~54 ~113 ~7 ~54 nether_brick_stairs  
fill ~84 ~7 ~55 ~84 ~7 ~59 nether_brick_stairs  
fill ~114 ~7 ~15 ~114 ~7 ~23 nether_brick_stairs  
fill ~114 ~7 ~24 ~118 ~7 ~24 nether_brick_stairs  
fill ~114 ~7 ~46 ~118 ~7 ~46 nether_brick_stairs  
fill ~114 ~7 ~47 ~114 ~7 ~54 nether_brick_stairs  
fill ~119 ~7 ~24 ~119 ~7 ~32 nether_brick_stairs  
fill ~119 ~7 ~33 ~126 ~7 ~33 nether_brick_stairs  
fill ~119 ~7 ~37 ~126 ~7 ~37 nether_brick_stairs  
fill ~119 ~7 ~38 ~119 ~7 ~46 nether_brick_stairs 
setblock ~126 ~7 ~34 planks 1 
setblock ~126 ~7 ~35 planks 3 
setblock ~126 ~7 ~36 planks 1  
fill ~4 ~8 ~30 ~4 ~8 ~35 nether_brick_stairs 
setblock ~5 ~8 ~28 nether_brick_stairs 0 
setblock ~5 ~8 ~29 nether_brick_stairs 2  
fill ~5 ~8 ~30 ~5 ~8 ~35 planks  
fill ~5 ~8 ~36 ~5 ~8 ~38 nether_brick_stairs 
setblock ~6 ~8 ~26 nether_brick_stairs 0 
setblock ~6 ~8 ~27 nether_brick_stairs 2  
fill ~6 ~8 ~28 ~6 ~8 ~29 planks 
setblock ~6 ~8 ~30 torch 1 
setblock ~6 ~8 ~35 torch 1  
fill ~6 ~8 ~36 ~6 ~8 ~38 planks 
setblock ~6 ~8 ~39 nether_brick_stairs 0 
setblock ~7 ~8 ~25 nether_brick_stairs 0  
fill ~7 ~8 ~26 ~7 ~8 ~27 planks 
setblock ~7 ~8 ~39 planks 3 
setblock ~7 ~8 ~40 nether_brick_stairs 0 
setblock ~8 ~8 ~24 nether_brick_stairs 0 
setblock ~8 ~8 ~25 planks 3 
setblock ~8 ~8 ~40 planks 3 
setblock ~8 ~8 ~41 nether_brick_stairs 0 
setblock ~9 ~8 ~23 nether_brick_stairs 0  
fill ~9 ~8 ~24 ~10 ~8 ~24 planks  
fill ~9 ~8 ~41 ~10 ~8 ~41 planks 
setblock ~9 ~8 ~42 nether_brick_stairs 3 
setblock ~10 ~8 ~23 nether_brick_stairs 2 
setblock ~10 ~8 ~42 nether_brick_stairs 0 
setblock ~11 ~8 ~22 nether_brick_stairs 2  
fill ~11 ~8 ~23 ~12 ~8 ~23 planks  
fill ~11 ~8 ~42 ~12 ~8 ~42 planks 
setblock ~11 ~8 ~43 nether_brick_stairs 3 
setblock ~12 ~8 ~22 nether_brick_stairs 0 
setblock ~12 ~8 ~43 nether_brick_stairs 0  
fill ~13 ~8 ~21 ~16 ~8 ~21 nether_brick_stairs  
fill ~13 ~8 ~22 ~17 ~8 ~22 planks  
fill ~13 ~8 ~43 ~19 ~8 ~43 planks  
fill ~13 ~8 ~44 ~16 ~8 ~44 nether_brick_stairs  
fill ~17 ~8 ~16 ~44 ~8 ~16 nether_brick_stairs  
fill ~17 ~8 ~17 ~17 ~8 ~21 nether_brick_stairs  
fill ~17 ~8 ~44 ~17 ~8 ~54 nether_brick_stairs  
fill ~18 ~8 ~54 ~44 ~8 ~54 nether_brick_stairs  
fill ~45 ~8 ~6 ~60 ~8 ~6 nether_brick_stairs  
fill ~45 ~8 ~7 ~45 ~8 ~16 nether_brick_stairs  
fill ~45 ~8 ~54 ~45 ~8 ~59 nether_brick_stairs  
fill ~46 ~8 ~59 ~82 ~8 ~59 nether_brick_stairs  
fill ~61 ~8 ~0 ~61 ~8 ~6 nether_brick_stairs 
setblock ~62 ~8 ~1 planks 3 
setblock ~63 ~8 ~1 planks 1 
setblock ~64 ~8 ~1 planks 3 
setblock ~65 ~8 ~1 planks 1 
setblock ~66 ~8 ~1 planks 3  
fill ~67 ~8 ~0 ~67 ~8 ~6 nether_brick_stairs  
fill ~68 ~8 ~6 ~83 ~8 ~6 nether_brick_stairs  
fill ~83 ~8 ~7 ~83 ~8 ~16 nether_brick_stairs  
fill ~83 ~8 ~53 ~83 ~8 ~59 nether_brick_stairs  
fill ~84 ~8 ~16 ~113 ~8 ~16 nether_brick_stairs  
fill ~84 ~8 ~53 ~113 ~8 ~53 nether_brick_stairs  
fill ~113 ~8 ~17 ~113 ~8 ~24 nether_brick_stairs  
fill ~113 ~8 ~25 ~117 ~8 ~25 nether_brick_stairs  
fill ~113 ~8 ~45 ~118 ~8 ~45 nether_brick_stairs  
fill ~113 ~8 ~46 ~113 ~8 ~52 nether_brick_stairs  
fill ~118 ~8 ~25 ~118 ~8 ~33 nether_brick_stairs  
fill ~118 ~8 ~34 ~126 ~8 ~34 nether_brick_stairs 
setblock ~118 ~8 ~35 nether_brick_stairs 1  
fill ~118 ~8 ~36 ~126 ~8 ~36 nether_brick_stairs  
fill ~118 ~8 ~37 ~118 ~8 ~44 nether_brick_stairs 
setblock ~126 ~8 ~35 planks 1  
fill ~5 ~9 ~30 ~5 ~9 ~35 nether_brick_stairs 
setblock ~6 ~9 ~28 nether_brick_stairs 0 
setblock ~6 ~9 ~29 nether_brick_stairs 2  
fill ~6 ~9 ~30 ~6 ~9 ~35 planks  
fill ~6 ~9 ~36 ~6 ~9 ~38 nether_brick_stairs 
setblock ~7 ~9 ~26 nether_brick_stairs 0 
setblock ~7 ~9 ~27 nether_brick_stairs 2  
fill ~7 ~9 ~28 ~7 ~9 ~29 planks 
setblock ~7 ~9 ~30 torch 1 
setblock ~7 ~9 ~35 torch 1  
fill ~7 ~9 ~36 ~7 ~9 ~38 planks 
setblock ~7 ~9 ~39 nether_brick_stairs 0 
setblock ~8 ~9 ~25 nether_brick_stairs 0  
fill ~8 ~9 ~26 ~8 ~9 ~27 planks 
setblock ~8 ~9 ~39 planks 3 
setblock ~8 ~9 ~40 nether_brick_stairs 0 
setblock ~9 ~9 ~24 nether_brick_stairs 0  
fill ~9 ~9 ~25 ~10 ~9 ~25 planks  
fill ~9 ~9 ~40 ~10 ~9 ~40 planks 
setblock ~9 ~9 ~41 nether_brick_stairs 3 
setblock ~10 ~9 ~24 nether_brick_stairs 2 
setblock ~10 ~9 ~41 nether_brick_stairs 0 
setblock ~11 ~9 ~23 nether_brick_stairs 2  
fill ~11 ~9 ~24 ~12 ~9 ~24 planks  
fill ~11 ~9 ~41 ~12 ~9 ~41 planks 
setblock ~11 ~9 ~42 nether_brick_stairs 3 
setblock ~12 ~9 ~23 nether_brick_stairs 0 
setblock ~12 ~9 ~42 nether_brick_stairs 0  
fill ~13 ~9 ~22 ~17 ~9 ~22 nether_brick_stairs  
fill ~13 ~9 ~23 ~18 ~9 ~23 planks  
fill ~13 ~9 ~42 ~19 ~9 ~42 planks  
fill ~13 ~9 ~43 ~18 ~9 ~43 nether_brick_stairs  
fill ~18 ~9 ~17 ~45 ~9 ~17 nether_brick_stairs  
fill ~18 ~9 ~18 ~18 ~9 ~22 nether_brick_stairs  
fill ~18 ~9 ~44 ~18 ~9 ~52 nether_brick_stairs  
fill ~18 ~9 ~53 ~45 ~9 ~53 nether_brick_stairs  
fill ~19 ~9 ~43 ~19 ~9 ~52 planks  
fill ~20 ~9 ~52 ~46 ~9 ~52 planks  
fill ~46 ~9 ~7 ~62 ~9 ~7 nether_brick_stairs  
fill ~46 ~9 ~8 ~46 ~9 ~17 nether_brick_stairs  
fill ~46 ~9 ~53 ~46 ~9 ~57 nether_brick_stairs  
fill ~46 ~9 ~58 ~82 ~9 ~58 nether_brick_stairs  
fill ~62 ~9 ~0 ~62 ~9 ~6 nether_brick_stairs 
setblock ~63 ~9 ~1 planks 3 
setblock ~64 ~9 ~1 planks 1 
setblock ~65 ~9 ~1 planks 3  
fill ~66 ~9 ~0 ~66 ~9 ~7 nether_brick_stairs  
fill ~67 ~9 ~7 ~82 ~9 ~7 nether_brick_stairs  
fill ~82 ~9 ~8 ~82 ~9 ~17 nether_brick_stairs  
fill ~82 ~9 ~52 ~111 ~9 ~52 nether_brick_stairs  
fill ~82 ~9 ~53 ~82 ~9 ~57 nether_brick_stairs  
fill ~83 ~9 ~17 ~112 ~9 ~17 nether_brick_stairs  
fill ~112 ~9 ~18 ~112 ~9 ~25 nether_brick_stairs  
fill ~112 ~9 ~26 ~117 ~9 ~26 nether_brick_stairs  
fill ~112 ~9 ~44 ~116 ~9 ~44 nether_brick_stairs  
fill ~112 ~9 ~45 ~112 ~9 ~52 nether_brick_stairs  
fill ~117 ~9 ~27 ~117 ~9 ~34 nether_brick_stairs  
fill ~117 ~9 ~35 ~126 ~9 ~35 nether_brick  
fill ~117 ~9 ~36 ~117 ~9 ~44 nether_brick_stairs  
fill ~6 ~10 ~30 ~6 ~10 ~35 nether_brick_stairs 
setblock ~7 ~10 ~28 nether_brick_stairs 0 
setblock ~7 ~10 ~29 nether_brick_stairs 2  
fill ~7 ~10 ~30 ~7 ~10 ~35 planks 
setblock ~7 ~10 ~36 nether_brick_stairs 3  
fill ~7 ~10 ~37 ~7 ~10 ~38 nether_brick_stairs 
setblock ~8 ~10 ~26 nether_brick_stairs 0 
setblock ~8 ~10 ~27 nether_brick_stairs 2  
fill ~8 ~10 ~28 ~8 ~10 ~29 planks 
setblock ~8 ~10 ~30 torch 1 
setblock ~8 ~10 ~35 torch 1  
fill ~8 ~10 ~36 ~8 ~10 ~38 planks 
setblock ~8 ~10 ~39 nether_brick_stairs 0 
setblock ~9 ~10 ~25 nether_brick_stairs 2  
fill ~9 ~10 ~26 ~10 ~10 ~26 planks  
fill ~9 ~10 ~27 ~9 ~10 ~26 planks  
fill ~9 ~10 ~39 ~10 ~10 ~39 planks 
setblock ~9 ~10 ~40 nether_brick_stairs 3 
setblock ~10 ~10 ~25 nether_brick_stairs 0 
setblock ~10 ~10 ~40 nether_brick_stairs 0 
setblock ~11 ~10 ~24 nether_brick_stairs 2  
fill ~11 ~10 ~25 ~12 ~10 ~25 planks  
fill ~11 ~10 ~40 ~12 ~10 ~40 planks 
setblock ~11 ~10 ~41 nether_brick_stairs 3 
setblock ~12 ~10 ~24 nether_brick_stairs 0 
setblock ~12 ~10 ~41 nether_brick_stairs 0  
fill ~13 ~10 ~23 ~18 ~10 ~23 nether_brick_stairs  
fill ~13 ~10 ~24 ~19 ~10 ~24 planks  
fill ~13 ~10 ~41 ~19 ~10 ~41 planks  
fill ~13 ~10 ~42 ~19 ~10 ~42 nether_brick_stairs  
fill ~19 ~10 ~18 ~46 ~10 ~18 nether_brick_stairs  
fill ~19 ~10 ~19 ~19 ~10 ~23 nether_brick_stairs  
fill ~19 ~10 ~43 ~19 ~10 ~52 nether_brick_stairs  
fill ~20 ~10 ~52 ~46 ~10 ~52 nether_brick_stairs  
fill ~47 ~10 ~8 ~47 ~10 ~18 nether_brick_stairs  
fill ~47 ~10 ~52 ~47 ~10 ~57 nether_brick_stairs  
fill ~48 ~10 ~8 ~63 ~10 ~8 nether_brick_stairs  
fill ~48 ~10 ~57 ~81 ~10 ~57 nether_brick_stairs  
fill ~63 ~10 ~0 ~63 ~10 ~7 nether_brick_stairs 
setblock ~64 ~10 ~1 planks 3 
setblock ~64 ~10 ~2 torch 3  
fill ~65 ~10 ~0 ~65 ~10 ~8 nether_brick_stairs  
fill ~66 ~10 ~8 ~81 ~10 ~8 nether_brick_stairs  
fill ~81 ~10 ~9 ~81 ~10 ~18 nether_brick_stairs  
fill ~81 ~10 ~51 ~110 ~10 ~51 nether_brick_stairs  
fill ~81 ~10 ~52 ~81 ~10 ~56 nether_brick_stairs  
fill ~82 ~10 ~18 ~111 ~10 ~18 nether_brick_stairs  
fill ~111 ~10 ~19 ~111 ~10 ~26 nether_brick_stairs  
fill ~111 ~10 ~27 ~115 ~10 ~27 nether_brick_stairs  
fill ~111 ~10 ~43 ~116 ~10 ~43 nether_brick_stairs  
fill ~111 ~10 ~44 ~111 ~10 ~51 nether_brick_stairs  
fill ~116 ~10 ~27 ~116 ~10 ~42 nether_brick_stairs  
fill ~126 ~10 ~35 ~126 ~12 ~35 nether_brick_fence  
fill ~7 ~11 ~30 ~7 ~11 ~35 nether_brick_stairs 
setblock ~8 ~11 ~28 nether_brick_stairs 0 
setblock ~8 ~11 ~29 nether_brick_stairs 2  
fill ~8 ~11 ~30 ~8 ~11 ~35 planks 
setblock ~8 ~11 ~36 nether_brick_stairs 3  
fill ~8 ~11 ~37 ~8 ~11 ~38 nether_brick_stairs 
setblock ~9 ~11 ~26 nether_brick_stairs 2 
setblock ~9 ~11 ~27 nether_brick_stairs 0  
fill ~9 ~11 ~28 ~9 ~11 ~29 planks 
setblock ~9 ~11 ~30 torch 1 
setblock ~9 ~11 ~35 torch 1  
fill ~9 ~11 ~36 ~9 ~11 ~38 planks 
setblock ~9 ~11 ~39 nether_brick_stairs 3 
setblock ~10 ~11 ~26 nether_brick_stairs 0 
setblock ~10 ~11 ~27 planks 3 
setblock ~10 ~11 ~38 planks 3 
setblock ~10 ~11 ~39 nether_brick_stairs 0 
setblock ~11 ~11 ~25 nether_brick_stairs 2  
fill ~11 ~11 ~26 ~12 ~11 ~26 planks  
fill ~11 ~11 ~39 ~12 ~11 ~39 planks 
setblock ~11 ~11 ~40 nether_brick_stairs 3 
setblock ~12 ~11 ~25 nether_brick_stairs 0 
setblock ~12 ~11 ~40 nether_brick_stairs 0  
fill ~13 ~11 ~24 ~19 ~11 ~24 nether_brick_stairs  
fill ~13 ~11 ~25 ~19 ~11 ~25 planks  
fill ~13 ~11 ~40 ~20 ~11 ~40 planks  
fill ~13 ~11 ~41 ~19 ~11 ~41 nether_brick_stairs  
fill ~20 ~11 ~19 ~47 ~11 ~19 nether_brick_stairs  
fill ~20 ~11 ~20 ~20 ~11 ~24 nether_brick_stairs  
fill ~20 ~11 ~41 ~20 ~11 ~51 nether_brick_stairs  
fill ~21 ~11 ~51 ~48 ~11 ~51 nether_brick_stairs  
fill ~48 ~11 ~9 ~63 ~11 ~9 nether_brick_stairs  
fill ~48 ~11 ~10 ~48 ~11 ~19 nether_brick_stairs  
fill ~48 ~11 ~52 ~48 ~11 ~55 nether_brick_stairs  
fill ~48 ~11 ~56 ~79 ~11 ~56 nether_brick_stairs  
fill ~64 ~11 ~0 ~64 ~11 ~9 nether_brick  
fill ~65 ~11 ~9 ~80 ~11 ~9 nether_brick_stairs  
fill ~80 ~11 ~10 ~80 ~11 ~19 nether_brick_stairs  
fill ~80 ~11 ~50 ~80 ~11 ~56 nether_brick_stairs  
fill ~81 ~11 ~19 ~110 ~11 ~19 nether_brick_stairs  
fill ~81 ~11 ~50 ~109 ~11 ~50 nether_brick_stairs  
fill ~110 ~11 ~20 ~110 ~11 ~27 nether_brick_stairs  
fill ~110 ~11 ~28 ~114 ~11 ~28 nether_brick_stairs  
fill ~110 ~11 ~42 ~110 ~11 ~50 nether_brick_stairs  
fill ~111 ~11 ~42 ~115 ~11 ~42 nether_brick_stairs  
fill ~114 ~11 ~29 ~114 ~11 ~40 planks  
fill ~115 ~11 ~28 ~115 ~11 ~41 nether_brick_stairs 
setblock ~126 ~11 ~34 nether_brick_fence 0 
setblock ~126 ~11 ~36 nether_brick_fence 0  
fill ~8 ~12 ~30 ~8 ~12 ~35 nether_brick_stairs 
setblock ~9 ~12 ~28 nether_brick_stairs 0 
setblock ~9 ~12 ~29 nether_brick_stairs 2  
fill ~9 ~12 ~30 ~9 ~12 ~35 planks 
setblock ~9 ~12 ~36 nether_brick_stairs 3 
setblock ~9 ~12 ~37 nether_brick_stairs 0 
setblock ~9 ~12 ~38 nether_brick_stairs 3 
setblock ~10 ~12 ~27 nether_brick_stairs 0  
fill ~10 ~12 ~28 ~10 ~12 ~29 planks 
setblock ~10 ~12 ~30 torch 1 
setblock ~10 ~12 ~35 torch 1  
fill ~10 ~12 ~36 ~10 ~12 ~37 planks 
setblock ~10 ~12 ~38 nether_brick_stairs 0 
setblock ~11 ~12 ~26 nether_brick_stairs 2  
fill ~11 ~12 ~27 ~12 ~12 ~27 planks  
fill ~11 ~12 ~38 ~12 ~12 ~38 planks 
setblock ~11 ~12 ~39 nether_brick_stairs 3 
setblock ~12 ~12 ~26 nether_brick_stairs 0 
setblock ~12 ~12 ~39 nether_brick_stairs 0  
fill ~13 ~12 ~25 ~20 ~12 ~25 nether_brick_stairs  
fill ~13 ~12 ~26 ~20 ~12 ~26 planks  
fill ~13 ~12 ~39 ~20 ~12 ~39 planks  
fill ~13 ~12 ~40 ~19 ~12 ~40 nether_brick_stairs  
fill ~21 ~12 ~20 ~49 ~12 ~20 planks  
fill ~21 ~12 ~21 ~21 ~12 ~26 planks 
setblock ~21 ~12 ~27 torch 3 
setblock ~21 ~12 ~38 torch 4  
fill ~21 ~12 ~39 ~21 ~12 ~50 planks  
fill ~22 ~12 ~50 ~49 ~12 ~50 planks  
fill ~49 ~12 ~10 ~63 ~12 ~10 planks  
fill ~49 ~12 ~11 ~49 ~12 ~20 planks 
setblock ~49 ~12 ~21 torch 3  
fill ~49 ~12 ~51 ~49 ~12 ~55 planks 
setblock ~50 ~12 ~20 torch 1  
fill ~50 ~12 ~55 ~79 ~12 ~55 planks  
fill ~64 ~12 ~0 ~64 ~14 ~0 nether_brick_fence  
fill ~64 ~12 ~10 ~64 ~29 ~10 planks  
fill ~65 ~12 ~10 ~79 ~12 ~10 planks 
setblock ~78 ~12 ~20 torch 2  
fill ~79 ~12 ~11 ~79 ~12 ~20 planks 
setblock ~79 ~12 ~21 torch 3  
fill ~79 ~12 ~49 ~109 ~12 ~49 planks  
fill ~79 ~12 ~50 ~79 ~12 ~55 planks  
fill ~80 ~12 ~20 ~109 ~12 ~20 planks 
setblock ~98 ~12 ~21 torch 3 
setblock ~108 ~12 ~21 torch 3 
setblock ~108 ~12 ~48 torch 4  
fill ~109 ~12 ~21 ~109 ~12 ~29 planks  
fill ~109 ~12 ~41 ~109 ~12 ~49 planks  
fill ~110 ~12 ~29 ~114 ~12 ~29 nether_brick_stairs  
fill ~110 ~12 ~41 ~114 ~12 ~41 nether_brick_stairs  
fill ~113 ~12 ~30 ~113 ~12 ~40 planks  
fill ~114 ~12 ~30 ~114 ~12 ~40 nether_brick_stairs  
fill ~9 ~13 ~30 ~9 ~13 ~35 nether_brick_stairs 
setblock ~10 ~13 ~28 nether_brick_stairs 0 
setblock ~10 ~13 ~29 nether_brick_stairs 2  
fill ~10 ~13 ~30 ~10 ~13 ~35 planks 
setblock ~10 ~13 ~36 nether_brick_stairs 3 
setblock ~10 ~13 ~37 nether_brick_stairs 0 
setblock ~11 ~13 ~27 nether_brick_stairs 2  
fill ~11 ~13 ~28 ~12 ~13 ~28 planks  
fill ~11 ~13 ~29 ~11 ~13 ~28 planks 
setblock ~11 ~13 ~30 torch 1 
setblock ~11 ~13 ~35 torch 1  
fill ~11 ~13 ~36 ~11 ~13 ~37 planks 
setblock ~11 ~13 ~38 nether_brick_stairs 3 
setblock ~12 ~13 ~27 nether_brick_stairs 0  
fill ~12 ~13 ~37 ~13 ~13 ~37 planks 
setblock ~12 ~13 ~38 nether_brick_stairs 0  
fill ~13 ~13 ~26 ~19 ~13 ~26 nether_brick_stairs  
fill ~13 ~13 ~27 ~19 ~13 ~27 planks  
fill ~13 ~13 ~38 ~19 ~13 ~38 planks  
fill ~13 ~13 ~39 ~19 ~13 ~39 nether_brick_stairs  
fill ~19 ~13 ~18 ~19 ~13 ~25 nether_brick_stairs  
fill ~19 ~13 ~40 ~19 ~13 ~52 nether_brick_stairs  
fill ~20 ~13 ~18 ~46 ~13 ~18 nether_brick_stairs  
fill ~20 ~13 ~26 ~21 ~13 ~26 nether_brick_fence  
fill ~20 ~13 ~39 ~21 ~13 ~39 nether_brick_fence  
fill ~20 ~13 ~52 ~46 ~13 ~52 nether_brick_stairs  
fill ~21 ~13 ~20 ~49 ~13 ~20 nether_brick_fence  
fill ~21 ~13 ~21 ~21 ~13 ~26 nether_brick_fence  
fill ~21 ~13 ~40 ~21 ~13 ~50 nether_brick_fence  
fill ~22 ~13 ~50 ~49 ~13 ~50 nether_brick_fence  
fill ~47 ~13 ~10 ~47 ~13 ~18 nether_brick_stairs  
fill ~47 ~13 ~52 ~47 ~13 ~55 nether_brick_stairs  
fill ~49 ~13 ~10 ~63 ~13 ~10 nether_brick_fence  
fill ~49 ~13 ~11 ~49 ~13 ~20 nether_brick_fence  
fill ~49 ~13 ~51 ~49 ~13 ~55 nether_brick_fence  
fill ~50 ~13 ~55 ~79 ~13 ~55 nether_brick_fence 
setblock ~63 ~13 ~0 nether_brick_fence 0 
setblock ~65 ~13 ~0 nether_brick_fence 0  
fill ~65 ~13 ~10 ~79 ~13 ~10 nether_brick_fence  
fill ~79 ~13 ~11 ~79 ~13 ~20 nether_brick_fence  
fill ~79 ~13 ~49 ~109 ~13 ~49 nether_brick_fence  
fill ~79 ~13 ~50 ~79 ~13 ~55 nether_brick_fence  
fill ~80 ~13 ~20 ~109 ~13 ~20 nether_brick_fence  
fill ~81 ~13 ~10 ~81 ~13 ~18 nether_brick_stairs  
fill ~81 ~13 ~52 ~81 ~13 ~55 nether_brick_stairs  
fill ~82 ~13 ~18 ~110 ~13 ~18 nether_brick_stairs  
fill ~82 ~13 ~52 ~110 ~13 ~52 nether_brick_stairs  
fill ~109 ~13 ~21 ~109 ~13 ~29 nether_brick_fence  
fill ~109 ~13 ~41 ~109 ~13 ~49 nether_brick_fence  
fill ~111 ~13 ~18 ~111 ~13 ~30 nether_brick_stairs  
fill ~111 ~13 ~40 ~113 ~13 ~40 nether_brick_stairs  
fill ~111 ~13 ~41 ~111 ~13 ~52 nether_brick_stairs  
fill ~112 ~13 ~30 ~113 ~13 ~30 nether_brick_stairs  
fill ~113 ~13 ~31 ~113 ~13 ~39 nether_brick_fence  
fill ~10 ~14 ~30 ~10 ~14 ~35 nether_brick_stairs 
setblock ~11 ~14 ~28 nether_brick_stairs 2 
setblock ~11 ~14 ~29 nether_brick_stairs 0  
fill ~11 ~14 ~30 ~12 ~14 ~30 planks  
fill ~11 ~14 ~31 ~11 ~14 ~35 planks 
setblock ~11 ~14 ~36 nether_brick_stairs 3 
setblock ~11 ~14 ~37 nether_brick_stairs 0 
setblock ~12 ~14 ~28 nether_brick_stairs 0  
fill ~12 ~14 ~29 ~13 ~14 ~29 planks 
setblock ~12 ~14 ~31 torch 1 
setblock ~12 ~14 ~34 torch 1  
fill ~12 ~14 ~35 ~12 ~14 ~36 planks 
setblock ~12 ~14 ~37 nether_brick_stairs 3  
fill ~13 ~14 ~27 ~20 ~14 ~27 nether_brick_stairs  
fill ~13 ~14 ~28 ~20 ~14 ~28 planks  
fill ~13 ~14 ~36 ~13 ~15 ~36 planks 
setblock ~13 ~14 ~37 nether_brick 0 
setblock ~13 ~14 ~38 nether_brick_stairs 0  
fill ~14 ~14 ~37 ~20 ~14 ~37 planks  
fill ~14 ~14 ~38 ~20 ~14 ~38 nether_brick_stairs  
fill ~20 ~14 ~19 ~47 ~14 ~19 nether_brick_stairs  
fill ~20 ~14 ~20 ~20 ~14 ~26 nether_brick_stairs  
fill ~20 ~14 ~39 ~20 ~14 ~51 nether_brick_stairs  
fill ~21 ~14 ~20 ~49 ~14 ~20 planks  
fill ~21 ~14 ~21 ~21 ~14 ~28 planks 
setblock ~21 ~14 ~29 torch 3 
setblock ~21 ~14 ~36 torch 4  
fill ~21 ~14 ~37 ~21 ~14 ~50 planks  
fill ~21 ~14 ~51 ~48 ~14 ~51 nether_brick_stairs 
setblock ~22 ~14 ~21 torch 3 
setblock ~22 ~14 ~49 torch 1  
fill ~22 ~14 ~50 ~49 ~14 ~50 planks 
setblock ~27 ~14 ~49 torch 4 
setblock ~37 ~14 ~21 torch 3 
setblock ~39 ~14 ~49 torch 4  
fill ~48 ~14 ~10 ~48 ~14 ~19 nether_brick_stairs  
fill ~48 ~14 ~52 ~48 ~14 ~55 nether_brick_stairs  
fill ~49 ~14 ~10 ~63 ~14 ~10 planks  
fill ~49 ~14 ~11 ~49 ~14 ~20 planks 
setblock ~49 ~14 ~21 torch 3  
fill ~49 ~14 ~51 ~49 ~14 ~55 planks 
setblock ~50 ~14 ~11 torch 3 
setblock ~50 ~14 ~20 torch 1 
setblock ~50 ~14 ~50 torch 1 
setblock ~50 ~14 ~54 torch 1  
fill ~50 ~14 ~55 ~79 ~14 ~55 planks 
setblock ~64 ~14 ~11 torch 3 
setblock ~64 ~14 ~54 torch 4  
fill ~65 ~14 ~10 ~79 ~14 ~10 planks 
setblock ~78 ~14 ~11 torch 3 
setblock ~78 ~14 ~20 torch 2 
setblock ~78 ~14 ~49 torch 2 
setblock ~78 ~14 ~54 torch 2  
fill ~79 ~14 ~11 ~79 ~14 ~20 planks 
setblock ~79 ~14 ~21 torch 3  
fill ~79 ~14 ~49 ~109 ~14 ~49 planks  
fill ~79 ~14 ~50 ~79 ~14 ~55 planks  
fill ~80 ~14 ~10 ~80 ~14 ~19 nether_brick_stairs  
fill ~80 ~14 ~20 ~109 ~14 ~20 planks  
fill ~80 ~14 ~51 ~109 ~14 ~51 nether_brick_stairs  
fill ~80 ~14 ~52 ~80 ~14 ~55 nether_brick_stairs  
fill ~81 ~14 ~19 ~110 ~14 ~19 nether_brick_stairs 
setblock ~98 ~14 ~21 torch 3 
setblock ~108 ~14 ~21 torch 3 
setblock ~108 ~14 ~48 torch 4  
fill ~109 ~14 ~21 ~109 ~14 ~31 planks  
fill ~109 ~14 ~39 ~109 ~14 ~49 planks  
fill ~110 ~14 ~20 ~110 ~14 ~30 nether_brick_stairs  
fill ~110 ~14 ~31 ~113 ~14 ~31 nether_brick_stairs  
fill ~110 ~14 ~39 ~113 ~14 ~39 nether_brick_stairs  
fill ~110 ~14 ~40 ~110 ~14 ~51 nether_brick_stairs  
fill ~113 ~14 ~32 ~113 ~14 ~38 nether_brick_fence  
fill ~11 ~15 ~30 ~11 ~15 ~35 nether_brick_stairs 
setblock ~12 ~15 ~29 nether_brick_stairs 0 
setblock ~12 ~15 ~30 nether_brick 0  
fill ~12 ~15 ~31 ~13 ~15 ~31 planks  
fill ~12 ~15 ~32 ~13 ~15 ~32 planks  
fill ~12 ~15 ~33 ~13 ~15 ~33 planks  
fill ~12 ~15 ~34 ~13 ~15 ~34 planks 
setblock ~12 ~15 ~35 nether_brick 0 
setblock ~12 ~15 ~36 nether_brick_stairs 3  
fill ~13 ~15 ~28 ~21 ~15 ~28 nether_brick_stairs  
fill ~13 ~15 ~29 ~21 ~15 ~29 planks  
fill ~13 ~15 ~30 ~21 ~15 ~30 planks  
fill ~13 ~15 ~35 ~21 ~15 ~35 planks  
fill ~13 ~15 ~37 ~20 ~15 ~37 nether_brick_stairs  
fill ~14 ~15 ~36 ~21 ~15 ~36 planks  
fill ~21 ~15 ~20 ~48 ~15 ~20 nether_brick_stairs  
fill ~21 ~15 ~21 ~21 ~15 ~27 nether_brick_stairs 
setblock ~21 ~15 ~31 torch 3 
setblock ~21 ~15 ~34 torch 4  
fill ~21 ~15 ~37 ~21 ~15 ~50 nether_brick_stairs  
fill ~22 ~15 ~49 ~49 ~15 ~49 planks  
fill ~22 ~15 ~50 ~49 ~15 ~50 nether_brick_stairs  
fill ~49 ~15 ~10 ~49 ~15 ~20 nether_brick_stairs  
fill ~49 ~15 ~51 ~49 ~15 ~55 nether_brick_stairs  
fill ~50 ~15 ~10 ~78 ~15 ~10 planks  
fill ~50 ~15 ~55 ~78 ~15 ~55 planks  
fill ~79 ~15 ~10 ~79 ~15 ~20 nether_brick_stairs  
fill ~79 ~15 ~49 ~108 ~15 ~49 planks  
fill ~79 ~15 ~50 ~108 ~15 ~50 nether_brick_stairs  
fill ~79 ~15 ~51 ~79 ~15 ~55 nether_brick_stairs  
fill ~80 ~15 ~20 ~109 ~15 ~20 nether_brick_stairs  
fill ~109 ~15 ~21 ~109 ~15 ~32 nether_brick_stairs  
fill ~109 ~15 ~38 ~109 ~15 ~50 nether_brick_stairs  
fill ~110 ~15 ~32 ~113 ~15 ~32 nether_brick_stairs  
fill ~110 ~15 ~38 ~113 ~15 ~38 nether_brick_stairs  
fill ~113 ~15 ~33 ~113 ~15 ~37 nether_brick_fence  
fill ~12 ~16 ~30 ~12 ~16 ~35 nether_brick_stairs  
fill ~13 ~16 ~29 ~21 ~16 ~29 nether_brick_stairs  
fill ~13 ~16 ~30 ~22 ~16 ~30 nether_brick  
fill ~13 ~16 ~31 ~13 ~17 ~31 nether_brick  
fill ~13 ~16 ~32 ~13 ~17 ~32 nether_brick  
fill ~13 ~16 ~33 ~13 ~17 ~33 nether_brick  
fill ~13 ~16 ~34 ~13 ~17 ~34 nether_brick  
fill ~13 ~16 ~35 ~22 ~16 ~35 nether_brick  
fill ~13 ~16 ~36 ~22 ~16 ~36 nether_brick_stairs  
fill ~22 ~16 ~21 ~22 ~16 ~29 nether_brick_stairs  
fill ~22 ~16 ~37 ~22 ~16 ~48 nether_brick_stairs  
fill ~22 ~16 ~49 ~50 ~16 ~49 nether_brick_stairs  
fill ~23 ~16 ~21 ~49 ~16 ~21 nether_brick_stairs 
setblock ~25 ~16 ~25 torch 2 
setblock ~25 ~16 ~45 torch 2 
setblock ~26 ~16 ~24 torch 4 
setblock ~26 ~16 ~26 torch 3 
setblock ~26 ~16 ~44 torch 4 
setblock ~26 ~16 ~46 torch 3 
setblock ~27 ~16 ~25 torch 1 
setblock ~27 ~16 ~45 torch 1  
fill ~50 ~16 ~10 ~50 ~16 ~21 nether_brick_stairs  
fill ~50 ~16 ~50 ~50 ~16 ~55 nether_brick_stairs  
fill ~51 ~16 ~10 ~77 ~16 ~10 planks  
fill ~51 ~16 ~55 ~77 ~16 ~55 planks  
fill ~78 ~16 ~10 ~78 ~16 ~20 nether_brick_stairs  
fill ~78 ~16 ~21 ~108 ~16 ~21 nether_brick_stairs  
fill ~78 ~16 ~49 ~108 ~16 ~49 nether_brick_stairs  
fill ~78 ~16 ~50 ~78 ~16 ~55 nether_brick_stairs  
fill ~108 ~16 ~22 ~108 ~16 ~32 nether_brick_stairs  
fill ~108 ~16 ~33 ~113 ~16 ~33 nether_brick_stairs  
fill ~108 ~16 ~37 ~113 ~16 ~37 nether_brick_stairs  
fill ~108 ~16 ~38 ~108 ~16 ~48 nether_brick_stairs  
fill ~113 ~16 ~34 ~113 ~16 ~36 nether_brick_fence  
fill ~13 ~17 ~30 ~23 ~17 ~30 nether_brick  
fill ~13 ~17 ~35 ~23 ~17 ~35 nether_brick  
fill ~23 ~17 ~22 ~50 ~17 ~22 nether_brick_stairs  
fill ~23 ~17 ~23 ~23 ~17 ~29 nether_brick_stairs  
fill ~23 ~17 ~36 ~23 ~17 ~48 nether_brick_stairs  
fill ~24 ~17 ~48 ~51 ~17 ~48 nether_brick_stairs  
fill ~51 ~17 ~10 ~51 ~17 ~22 nether_brick_stairs  
fill ~51 ~17 ~49 ~51 ~17 ~55 nether_brick_stairs  
fill ~52 ~17 ~10 ~76 ~17 ~10 planks  
fill ~52 ~17 ~55 ~76 ~17 ~55 planks  
fill ~77 ~17 ~10 ~77 ~17 ~21 nether_brick_stairs  
fill ~77 ~17 ~22 ~106 ~17 ~22 nether_brick_stairs  
fill ~77 ~17 ~48 ~107 ~17 ~48 nether_brick_stairs  
fill ~77 ~17 ~49 ~77 ~17 ~55 nether_brick_stairs  
fill ~107 ~17 ~22 ~107 ~17 ~33 nether_brick_stairs  
fill ~107 ~17 ~34 ~113 ~17 ~34 nether_brick_stairs  
fill ~107 ~17 ~36 ~113 ~17 ~36 nether_brick_stairs  
fill ~107 ~17 ~37 ~107 ~17 ~47 nether_brick_stairs 
setblock ~113 ~17 ~35 nether_brick_fence 0  
fill ~13 ~18 ~30 ~18 ~18 ~30 planks  
fill ~13 ~18 ~31 ~13 ~18 ~35 planks 
setblock ~14 ~18 ~31 glowstone 0 
setblock ~14 ~18 ~34 glowstone 0  
fill ~14 ~18 ~35 ~18 ~18 ~35 planks  
fill ~16 ~18 ~31 ~16 ~18 ~34 planks  
fill ~19 ~18 ~30 ~24 ~18 ~30 nether_brick_stairs  
fill ~19 ~18 ~35 ~24 ~18 ~35 nether_brick_stairs  
fill ~24 ~18 ~23 ~51 ~18 ~23 nether_brick_stairs  
fill ~24 ~18 ~24 ~24 ~18 ~29 nether_brick_stairs  
fill ~24 ~18 ~36 ~24 ~18 ~47 nether_brick_stairs  
fill ~25 ~18 ~47 ~52 ~18 ~47 nether_brick_stairs  
fill ~52 ~18 ~10 ~52 ~18 ~23 nether_brick_stairs  
fill ~52 ~18 ~48 ~52 ~18 ~55 nether_brick_stairs 
setblock ~53 ~18 ~10 planks 1  
fill ~53 ~18 ~55 ~75 ~18 ~55 planks  
fill ~54 ~18 ~10 ~54 ~19 ~10 planks 
setblock ~55 ~18 ~10 planks 1  
fill ~56 ~18 ~10 ~56 ~21 ~10 planks 
setblock ~57 ~18 ~10 planks 1  
fill ~58 ~18 ~10 ~58 ~23 ~10 planks 
setblock ~59 ~18 ~10 planks 1  
fill ~60 ~18 ~10 ~60 ~25 ~10 planks 
setblock ~61 ~18 ~10 planks 1  
fill ~62 ~18 ~10 ~62 ~27 ~10 planks 
setblock ~63 ~18 ~10 planks 1 
setblock ~65 ~18 ~10 planks 1  
fill ~66 ~18 ~10 ~66 ~27 ~10 planks 
setblock ~67 ~18 ~10 planks 1  
fill ~68 ~18 ~10 ~68 ~25 ~10 planks 
setblock ~69 ~18 ~10 planks 1  
fill ~70 ~18 ~10 ~70 ~23 ~10 planks 
setblock ~71 ~18 ~10 planks 1  
fill ~72 ~18 ~10 ~72 ~21 ~10 planks 
setblock ~73 ~18 ~10 planks 1  
fill ~74 ~18 ~10 ~74 ~19 ~10 planks 
setblock ~75 ~18 ~10 planks 1  
fill ~76 ~18 ~10 ~76 ~18 ~22 nether_brick_stairs  
fill ~76 ~18 ~23 ~106 ~18 ~23 nether_brick_stairs  
fill ~76 ~18 ~47 ~106 ~18 ~47 nether_brick_stairs  
fill ~76 ~18 ~48 ~76 ~18 ~55 nether_brick_stairs  
fill ~106 ~18 ~24 ~106 ~18 ~34 nether_brick_stairs  
fill ~106 ~18 ~35 ~113 ~18 ~35 nether_brick  
fill ~106 ~18 ~36 ~106 ~18 ~46 nether_brick_stairs  
fill ~13 ~19 ~30 ~18 ~19 ~30 nether_brick_fence  
fill ~13 ~19 ~31 ~13 ~19 ~35 nether_brick_fence  
fill ~14 ~19 ~35 ~18 ~19 ~35 nether_brick_fence  
fill ~18 ~19 ~31 ~18 ~19 ~35 nether_brick_fence  
fill ~19 ~19 ~31 ~19 ~19 ~34 nether_brick_stairs  
fill ~20 ~19 ~31 ~25 ~19 ~31 nether_brick_stairs  
fill ~20 ~19 ~34 ~25 ~19 ~34 nether_brick_stairs  
fill ~25 ~19 ~24 ~25 ~19 ~30 nether_brick_stairs  
fill ~25 ~19 ~35 ~25 ~19 ~46 nether_brick_stairs  
fill ~26 ~19 ~24 ~53 ~19 ~24 nether_brick_stairs  
fill ~26 ~19 ~46 ~53 ~19 ~46 nether_brick_stairs  
fill ~53 ~19 ~10 ~53 ~19 ~23 nether_brick_stairs  
fill ~53 ~19 ~47 ~53 ~19 ~55 nether_brick_stairs  
fill ~54 ~19 ~11 ~54 ~19 ~24 log  
fill ~54 ~19 ~46 ~54 ~19 ~54 log  
fill ~54 ~19 ~55 ~74 ~19 ~55 planks  
fill ~55 ~19 ~10 ~55 ~20 ~10 planks 
setblock ~55 ~19 ~11 torch 1  
fill ~57 ~19 ~10 ~57 ~21 ~10 planks  
fill ~59 ~19 ~10 ~59 ~21 ~10 planks  
fill ~61 ~19 ~10 ~61 ~21 ~10 planks  
fill ~63 ~19 ~10 ~63 ~21 ~10 planks  
fill ~65 ~19 ~10 ~65 ~21 ~10 planks  
fill ~67 ~19 ~10 ~67 ~21 ~10 planks  
fill ~69 ~19 ~10 ~69 ~21 ~10 planks  
fill ~71 ~19 ~10 ~71 ~21 ~10 planks  
fill ~73 ~19 ~10 ~73 ~20 ~10 planks 
setblock ~73 ~19 ~11 torch 2  
fill ~74 ~19 ~11 ~74 ~19 ~24 log  
fill ~74 ~19 ~46 ~74 ~19 ~54 log  
fill ~75 ~19 ~10 ~75 ~19 ~24 nether_brick_stairs 
setblock ~75 ~19 ~44 torch 4  
fill ~75 ~19 ~45 ~103 ~19 ~45 planks  
fill ~75 ~19 ~46 ~105 ~19 ~46 nether_brick_stairs  
fill ~75 ~19 ~47 ~75 ~19 ~55 nether_brick_stairs  
fill ~76 ~19 ~24 ~105 ~19 ~24 nether_brick_stairs 
setblock ~104 ~19 ~26 torch 3 
setblock ~104 ~19 ~44 torch 4  
fill ~105 ~19 ~25 ~105 ~19 ~45 nether_brick_stairs  
fill ~113 ~19 ~35 ~113 ~21 ~35 nether_brick_fence  
fill ~13 ~20 ~30 ~18 ~20 ~30 planks  
fill ~13 ~20 ~31 ~13 ~21 ~31 planks  
fill ~13 ~20 ~32 ~13 ~21 ~32 planks  
fill ~13 ~20 ~33 ~13 ~21 ~33 planks  
fill ~13 ~20 ~34 ~13 ~21 ~34 planks  
fill ~13 ~20 ~35 ~18 ~20 ~35 planks  
fill ~18 ~20 ~31 ~18 ~21 ~31 planks  
fill ~18 ~20 ~32 ~18 ~21 ~32 planks  
fill ~18 ~20 ~33 ~18 ~21 ~33 planks  
fill ~18 ~20 ~34 ~18 ~21 ~34 planks  
fill ~20 ~20 ~32 ~20 ~20 ~33 nether_brick_stairs  
fill ~21 ~20 ~32 ~25 ~20 ~32 nether_brick_stairs  
fill ~21 ~20 ~33 ~25 ~20 ~33 nether_brick_stairs  
fill ~26 ~20 ~26 ~26 ~20 ~44 planks  
fill ~27 ~20 ~25 ~54 ~20 ~25 planks 
setblock ~27 ~20 ~31 torch 1 
setblock ~27 ~20 ~34 torch 1  
fill ~27 ~20 ~45 ~54 ~20 ~45 planks  
fill ~54 ~20 ~10 ~54 ~20 ~24 nether_brick_stairs 
setblock ~54 ~20 ~26 torch 3 
setblock ~54 ~20 ~44 torch 4  
fill ~54 ~20 ~46 ~54 ~20 ~55 nether_brick_stairs  
fill ~55 ~20 ~55 ~73 ~20 ~55 planks  
fill ~74 ~20 ~10 ~74 ~20 ~24 nether_brick_stairs  
fill ~74 ~20 ~25 ~103 ~20 ~25 planks 
setblock ~74 ~20 ~26 torch 3 
setblock ~74 ~20 ~44 torch 4  
fill ~74 ~20 ~45 ~103 ~20 ~45 planks  
fill ~74 ~20 ~46 ~74 ~20 ~55 nether_brick_stairs  
fill ~104 ~20 ~26 ~104 ~20 ~44 planks 
setblock ~113 ~20 ~34 nether_brick_fence 0 
setblock ~113 ~20 ~36 nether_brick_fence 0 
setblock ~12 ~21 ~29 nether_brick_stairs 4  
fill ~12 ~21 ~30 ~12 ~21 ~35 nether_brick_stairs 
setblock ~12 ~21 ~36 nether_brick_stairs 7  
fill ~13 ~21 ~29 ~18 ~21 ~29 nether_brick_stairs  
fill ~13 ~21 ~30 ~18 ~21 ~30 planks  
fill ~13 ~21 ~35 ~18 ~21 ~35 planks  
fill ~13 ~21 ~36 ~18 ~21 ~36 nether_brick_stairs 
setblock ~19 ~21 ~29 nether_brick_stairs 5  
fill ~19 ~21 ~30 ~19 ~21 ~35 nether_brick_stairs 
setblock ~19 ~21 ~36 nether_brick_stairs 7 
setblock ~26 ~21 ~26 planks 1  
fill ~26 ~21 ~27 ~26 ~28 ~27 planks 
setblock ~26 ~21 ~28 planks 1  
fill ~26 ~21 ~29 ~26 ~30 ~29 planks 
setblock ~26 ~21 ~30 planks 1  
fill ~26 ~21 ~31 ~26 ~32 ~31 planks 
setblock ~26 ~21 ~32 planks 1  
fill ~26 ~21 ~33 ~26 ~34 ~33 planks 
setblock ~26 ~21 ~34 planks 1  
fill ~26 ~21 ~35 ~26 ~36 ~35 planks 
setblock ~26 ~21 ~36 planks 1  
fill ~26 ~21 ~37 ~26 ~34 ~37 planks 
setblock ~26 ~21 ~38 planks 1  
fill ~26 ~21 ~39 ~26 ~32 ~39 planks 
setblock ~26 ~21 ~40 planks 1  
fill ~26 ~21 ~41 ~26 ~30 ~41 planks 
setblock ~26 ~21 ~42 planks 1  
fill ~26 ~21 ~43 ~26 ~28 ~43 planks 
setblock ~26 ~21 ~44 planks 1  
fill ~27 ~21 ~25 ~55 ~21 ~25 planks  
fill ~27 ~21 ~45 ~55 ~21 ~45 planks  
fill ~55 ~21 ~10 ~55 ~21 ~24 nether_brick_stairs 
setblock ~55 ~21 ~26 torch 3 
setblock ~55 ~21 ~44 torch 4  
fill ~55 ~21 ~46 ~55 ~21 ~55 nether_brick_stairs  
fill ~56 ~21 ~55 ~72 ~21 ~55 planks  
fill ~73 ~21 ~10 ~73 ~21 ~24 nether_brick_stairs  
fill ~73 ~21 ~25 ~103 ~21 ~25 planks 
setblock ~73 ~21 ~26 torch 3 
setblock ~73 ~21 ~44 torch 4  
fill ~73 ~21 ~45 ~103 ~21 ~45 planks  
fill ~73 ~21 ~46 ~73 ~21 ~55 nether_brick_stairs  
fill ~104 ~21 ~26 ~104 ~22 ~26 planks  
fill ~104 ~21 ~27 ~104 ~22 ~27 planks  
fill ~104 ~21 ~28 ~104 ~22 ~28 planks  
fill ~104 ~21 ~29 ~104 ~22 ~29 planks  
fill ~104 ~21 ~30 ~104 ~22 ~30 planks  
fill ~104 ~21 ~31 ~104 ~22 ~31 planks  
fill ~104 ~21 ~32 ~104 ~22 ~32 planks  
fill ~104 ~21 ~33 ~104 ~22 ~33 planks  
fill ~104 ~21 ~34 ~104 ~22 ~34 planks  
fill ~104 ~21 ~35 ~104 ~22 ~35 planks  
fill ~104 ~21 ~36 ~104 ~22 ~36 planks  
fill ~104 ~21 ~37 ~104 ~22 ~37 planks  
fill ~104 ~21 ~38 ~104 ~22 ~38 planks  
fill ~104 ~21 ~39 ~104 ~22 ~39 planks  
fill ~104 ~21 ~40 ~104 ~22 ~40 planks  
fill ~104 ~21 ~41 ~104 ~22 ~41 planks  
fill ~104 ~21 ~42 ~104 ~22 ~42 planks  
fill ~104 ~21 ~43 ~104 ~22 ~43 planks  
fill ~104 ~21 ~44 ~104 ~22 ~44 planks  
fill ~13 ~22 ~30 ~18 ~22 ~30 nether_brick  
fill ~13 ~22 ~31 ~13 ~22 ~35 nether_brick  
fill ~14 ~22 ~35 ~18 ~22 ~35 nether_brick  
fill ~18 ~22 ~31 ~18 ~22 ~35 nether_brick 
setblock ~26 ~22 ~26 planks 3 
setblock ~26 ~22 ~28 planks 3 
setblock ~26 ~22 ~30 planks 3 
setblock ~26 ~22 ~32 planks 3 
setblock ~26 ~22 ~34 planks 3 
setblock ~26 ~22 ~36 planks 3 
setblock ~26 ~22 ~38 planks 3 
setblock ~26 ~22 ~40 planks 3 
setblock ~26 ~22 ~42 planks 3 
setblock ~26 ~22 ~44 planks 3  
fill ~27 ~22 ~25 ~56 ~22 ~25 planks  
fill ~27 ~22 ~45 ~56 ~22 ~45 planks  
fill ~56 ~22 ~10 ~56 ~22 ~24 nether_brick_stairs 
setblock ~56 ~22 ~26 torch 3 
setblock ~56 ~22 ~44 torch 4  
fill ~56 ~22 ~46 ~56 ~22 ~55 nether_brick_stairs 
setblock ~57 ~22 ~10 planks 1  
fill ~57 ~22 ~55 ~71 ~22 ~55 planks 
setblock ~59 ~22 ~10 planks 1 
setblock ~61 ~22 ~10 planks 1 
setblock ~63 ~22 ~10 planks 1 
setblock ~65 ~22 ~10 planks 1 
setblock ~67 ~22 ~10 planks 1 
setblock ~69 ~22 ~10 planks 1 
setblock ~71 ~22 ~10 planks 1  
fill ~72 ~22 ~10 ~72 ~22 ~24 nether_brick_stairs  
fill ~72 ~22 ~25 ~103 ~22 ~25 planks 
setblock ~72 ~22 ~26 torch 3 
setblock ~72 ~22 ~44 torch 4  
fill ~72 ~22 ~45 ~103 ~22 ~45 planks  
fill ~72 ~22 ~46 ~72 ~22 ~55 nether_brick_stairs 
setblock ~13 ~23 ~30 nether_brick_stairs 4  
fill ~13 ~23 ~31 ~13 ~23 ~34 nether_brick_stairs 
setblock ~13 ~23 ~35 nether_brick_stairs 7  
fill ~14 ~23 ~30 ~17 ~23 ~30 nether_brick_stairs  
fill ~14 ~23 ~31 ~17 ~23 ~31 planks  
fill ~14 ~23 ~32 ~14 ~23 ~34 planks  
fill ~14 ~23 ~35 ~17 ~23 ~35 nether_brick_stairs  
fill ~15 ~23 ~34 ~17 ~23 ~34 planks  
fill ~17 ~23 ~32 ~17 ~23 ~34 planks 
setblock ~18 ~23 ~30 nether_brick_stairs 6  
fill ~18 ~23 ~31 ~18 ~23 ~34 nether_brick_stairs 
setblock ~18 ~23 ~35 nether_brick_stairs 7 
setblock ~26 ~23 ~26 planks 1 
setblock ~26 ~23 ~28 planks 1 
setblock ~26 ~23 ~30 planks 1 
setblock ~26 ~23 ~32 planks 1 
setblock ~26 ~23 ~34 planks 1 
setblock ~26 ~23 ~36 planks 1 
setblock ~26 ~23 ~38 planks 1 
setblock ~26 ~23 ~40 planks 1 
setblock ~26 ~23 ~42 planks 1 
setblock ~26 ~23 ~44 planks 1  
fill ~27 ~23 ~25 ~57 ~23 ~25 planks  
fill ~27 ~23 ~45 ~57 ~23 ~45 planks  
fill ~57 ~23 ~10 ~57 ~23 ~24 nether_brick_stairs  
setblock ~57 ~23 ~26 torch 3 
setblock ~57 ~23 ~44 torch 4  
fill ~57 ~23 ~46 ~57 ~23 ~55 nether_brick_stairs  
fill ~58 ~23 ~55 ~70 ~23 ~55 planks  
fill ~59 ~23 ~10 ~59 ~24 ~10 planks  
fill ~61 ~23 ~10 ~61 ~25 ~10 planks  
fill ~63 ~23 ~10 ~63 ~25 ~10 planks  
fill ~65 ~23 ~10 ~65 ~25 ~10 planks  
fill ~67 ~23 ~10 ~67 ~25 ~10 planks  
fill ~69 ~23 ~10 ~69 ~24 ~10 planks  
fill ~71 ~23 ~10 ~71 ~23 ~24 nether_brick_stairs  
fill ~71 ~23 ~25 ~103 ~23 ~25 planks 
setblock ~71 ~23 ~26 torch 3 
setblock ~71 ~23 ~44 torch 4  
fill ~71 ~23 ~45 ~103 ~23 ~45 planks  
fill ~71 ~23 ~46 ~71 ~23 ~55 nether_brick_stairs  
fill ~104 ~23 ~26 ~104 ~23 ~44 planks  
fill ~14 ~24 ~31 ~17 ~24 ~31 nether_brick  
fill ~14 ~24 ~32 ~14 ~24 ~34 nether_brick  
fill ~15 ~24 ~32 ~16 ~24 ~32 glowstone  
fill ~15 ~24 ~33 ~16 ~24 ~33 glowstone  
fill ~15 ~24 ~34 ~17 ~24 ~34 nether_brick  
fill ~17 ~24 ~32 ~17 ~24 ~34 nether_brick  
fill ~26 ~24 ~22 ~58 ~24 ~22 nether_brick_stairs 
setblock ~26 ~24 ~26 planks 3 
setblock ~26 ~24 ~28 planks 3 
setblock ~26 ~24 ~30 planks 3 
setblock ~26 ~24 ~32 planks 3 
setblock ~26 ~24 ~34 planks 3 
setblock ~26 ~24 ~36 planks 3 
setblock ~26 ~24 ~38 planks 3 
setblock ~26 ~24 ~40 planks 3 
setblock ~26 ~24 ~42 planks 3 
setblock ~26 ~24 ~44 planks 3  
fill ~26 ~24 ~48 ~58 ~24 ~48 nether_brick_stairs  
fill ~27 ~24 ~25 ~58 ~24 ~25 planks  
fill ~27 ~24 ~45 ~58 ~24 ~45 planks  
fill ~58 ~24 ~10 ~58 ~24 ~21 nether_brick_stairs  
fill ~58 ~24 ~23 ~58 ~24 ~24 nether_brick_stairs 
setblock ~58 ~24 ~26 torch 3 
setblock ~58 ~24 ~44 torch 4  
fill ~58 ~24 ~46 ~58 ~24 ~47 nether_brick_stairs  
fill ~58 ~24 ~49 ~58 ~24 ~55 nether_brick_stairs  
fill ~59 ~24 ~55 ~69 ~24 ~55 planks  
fill ~70 ~24 ~10 ~70 ~24 ~21 nether_brick_stairs  
fill ~70 ~24 ~22 ~104 ~24 ~22 nether_brick_stairs  
fill ~70 ~24 ~23 ~70 ~24 ~24 nether_brick_stairs  
fill ~70 ~24 ~25 ~103 ~24 ~25 planks 
setblock ~70 ~24 ~26 torch 3 
setblock ~70 ~24 ~44 torch 4  
fill ~70 ~24 ~45 ~103 ~24 ~45 planks  
fill ~70 ~24 ~46 ~70 ~24 ~47 nether_brick_stairs  
fill ~70 ~24 ~48 ~104 ~24 ~48 nether_brick_stairs  
fill ~70 ~24 ~49 ~70 ~24 ~55 nether_brick_stairs  
fill ~104 ~24 ~26 ~104 ~25 ~26 planks  
fill ~104 ~24 ~27 ~104 ~25 ~27 planks  
fill ~104 ~24 ~28 ~104 ~25 ~28 planks  
fill ~104 ~24 ~29 ~104 ~25 ~29 planks  
fill ~104 ~24 ~30 ~104 ~25 ~30 planks  
fill ~104 ~24 ~31 ~104 ~25 ~31 planks  
fill ~104 ~24 ~32 ~104 ~25 ~32 planks  
fill ~104 ~24 ~33 ~104 ~25 ~33 planks  
fill ~104 ~24 ~34 ~104 ~25 ~34 planks  
fill ~104 ~24 ~35 ~104 ~25 ~35 planks  
fill ~104 ~24 ~36 ~104 ~25 ~36 planks  
fill ~104 ~24 ~37 ~104 ~25 ~37 planks  
fill ~104 ~24 ~38 ~104 ~25 ~38 planks  
fill ~104 ~24 ~39 ~104 ~25 ~39 planks  
fill ~104 ~24 ~40 ~104 ~25 ~40 planks  
fill ~104 ~24 ~41 ~104 ~25 ~41 planks  
fill ~104 ~24 ~42 ~104 ~25 ~42 planks  
fill ~104 ~24 ~43 ~104 ~25 ~43 planks  
fill ~104 ~24 ~44 ~104 ~25 ~44 planks 
setblock ~14 ~25 ~31 nether_brick_stairs 4  
fill ~14 ~25 ~32 ~14 ~25 ~33 nether_brick_stairs 
setblock ~14 ~25 ~34 nether_brick_stairs 7  
fill ~15 ~25 ~31 ~16 ~25 ~31 nether_brick_stairs  
fill ~15 ~25 ~32 ~16 ~25 ~32 nether_brick  
fill ~15 ~25 ~33 ~16 ~25 ~33 nether_brick  
fill ~15 ~25 ~34 ~16 ~25 ~34 nether_brick_stairs 
setblock ~17 ~25 ~31 nether_brick_stairs 5  
fill ~17 ~25 ~32 ~17 ~25 ~33 nether_brick_stairs 
setblock ~17 ~25 ~34 nether_brick_stairs 7  
fill ~26 ~25 ~23 ~59 ~25 ~23 nether_brick_stairs 
setblock ~26 ~25 ~26 planks 1 
setblock ~26 ~25 ~28 planks 1 
setblock ~26 ~25 ~30 planks 1 
setblock ~26 ~25 ~32 planks 1 
setblock ~26 ~25 ~34 planks 1 
setblock ~26 ~25 ~36 planks 1 
setblock ~26 ~25 ~38 planks 1 
setblock ~26 ~25 ~40 planks 1 
setblock ~26 ~25 ~42 planks 1 
setblock ~26 ~25 ~44 planks 1  
fill ~26 ~25 ~47 ~59 ~25 ~47 nether_brick_stairs  
fill ~27 ~25 ~25 ~59 ~25 ~25 planks  
fill ~27 ~25 ~45 ~59 ~25 ~45 planks  
fill ~59 ~25 ~10 ~59 ~25 ~22 nether_brick_stairs 
setblock ~59 ~25 ~24 nether_brick_stairs 0 
setblock ~59 ~25 ~26 torch 3 
setblock ~59 ~25 ~44 torch 4 
setblock ~59 ~25 ~46 nether_brick_stairs 0  
fill ~59 ~25 ~48 ~59 ~25 ~55 nether_brick_stairs  
fill ~60 ~25 ~55 ~68 ~25 ~55 planks  
fill ~69 ~25 ~10 ~69 ~25 ~22 nether_brick_stairs  
fill ~69 ~25 ~23 ~104 ~25 ~23 nether_brick_stairs 
setblock ~69 ~25 ~24 nether_brick_stairs 1  
fill ~69 ~25 ~25 ~103 ~25 ~25 planks 
setblock ~69 ~25 ~26 torch 3 
setblock ~69 ~25 ~44 torch 4  
fill ~69 ~25 ~45 ~103 ~25 ~45 planks 
setblock ~69 ~25 ~46 nether_brick_stairs 1  
fill ~69 ~25 ~47 ~104 ~25 ~47 nether_brick_stairs  
fill ~69 ~25 ~48 ~69 ~25 ~55 nether_brick_stairs  
fill ~15 ~26 ~32 ~16 ~26 ~32 nether_brick  
fill ~15 ~26 ~33 ~16 ~26 ~33 nether_brick  
fill ~26 ~26 ~24 ~59 ~26 ~24 nether_brick_stairs  
fill ~26 ~26 ~26 ~26 ~27 ~26 planks  
fill ~26 ~26 ~28 ~26 ~27 ~28 planks  
fill ~26 ~26 ~30 ~26 ~27 ~30 planks  
fill ~26 ~26 ~32 ~26 ~27 ~32 planks  
fill ~26 ~26 ~34 ~26 ~27 ~34 planks  
fill ~26 ~26 ~36 ~26 ~27 ~36 planks  
fill ~26 ~26 ~38 ~26 ~27 ~38 planks  
fill ~26 ~26 ~40 ~26 ~27 ~40 planks  
fill ~26 ~26 ~42 ~26 ~27 ~42 planks  
fill ~26 ~26 ~44 ~26 ~27 ~44 planks  
fill ~26 ~26 ~46 ~60 ~26 ~46 nether_brick_stairs  
fill ~27 ~26 ~25 ~103 ~26 ~25 log  
fill ~27 ~26 ~26 ~27 ~26 ~44 log  
fill ~27 ~26 ~45 ~103 ~26 ~45 log 
setblock ~28 ~26 ~26 torch 1 
setblock ~28 ~26 ~35 torch 1 
setblock ~28 ~26 ~44 torch 1  
fill ~40 ~26 ~26 ~40 ~26 ~44 log 
setblock ~51 ~26 ~26 torch 3 
setblock ~51 ~26 ~44 torch 4  
fill ~52 ~26 ~26 ~52 ~26 ~44 log  
fill ~60 ~26 ~10 ~60 ~26 ~24 nether_brick_stairs  
fill ~60 ~26 ~26 ~60 ~26 ~44 log  
fill ~60 ~26 ~47 ~60 ~26 ~55 nether_brick_stairs 
setblock ~61 ~26 ~10 planks 1  
fill ~61 ~26 ~11 ~61 ~26 ~15 log  
fill ~61 ~26 ~16 ~67 ~26 ~16 log  
fill ~61 ~26 ~17 ~61 ~26 ~24 log 
setblock ~61 ~26 ~26 torch 3  
fill ~61 ~26 ~55 ~67 ~26 ~55 planks 
setblock ~63 ~26 ~10 planks 1 
setblock ~65 ~26 ~10 planks 1 
setblock ~65 ~26 ~26 torch 3 
setblock ~67 ~26 ~10 planks 1  
fill ~67 ~26 ~11 ~67 ~26 ~15 log  
fill ~67 ~26 ~17 ~67 ~26 ~24 log  
fill ~68 ~26 ~10 ~68 ~26 ~24 nether_brick_stairs 
setblock ~68 ~26 ~26 torch 3 
setblock ~68 ~26 ~44 torch 4  
fill ~68 ~26 ~46 ~104 ~26 ~46 nether_brick_stairs  
fill ~68 ~26 ~47 ~68 ~26 ~55 nether_brick_stairs  
fill ~69 ~26 ~24 ~104 ~26 ~24 nether_brick_stairs  
fill ~69 ~26 ~26 ~69 ~26 ~44 log 
setblock ~70 ~26 ~26 torch 3 
setblock ~70 ~26 ~44 torch 4  
fill ~76 ~26 ~26 ~76 ~26 ~44 log 
setblock ~77 ~26 ~26 torch 3 
setblock ~77 ~26 ~44 torch 1  
fill ~90 ~26 ~26 ~90 ~26 ~44 log 
setblock ~91 ~26 ~26 torch 3 
setblock ~91 ~26 ~44 torch 4  
fill ~103 ~26 ~26 ~103 ~26 ~44 log  
fill ~104 ~26 ~26 ~104 ~26 ~44 planks 
setblock ~15 ~27 ~32 nether_brick_stairs 2 
setblock ~15 ~27 ~33 nether_brick_stairs 0 
setblock ~16 ~27 ~32 nether_brick_stairs 1 
setblock ~16 ~27 ~33 nether_brick_stairs 3  
fill ~26 ~27 ~25 ~61 ~27 ~25 nether_brick_stairs  
fill ~26 ~27 ~45 ~61 ~27 ~45 nether_brick_stairs 
setblock ~27 ~27 ~26 torch 1  
fill ~27 ~27 ~30 ~27 ~31 ~30 log  
fill ~27 ~27 ~40 ~27 ~31 ~40 log 
setblock ~27 ~27 ~44 torch 1 
setblock ~40 ~27 ~26 torch 5  
fill ~40 ~27 ~30 ~40 ~31 ~30 log 
setblock ~40 ~27 ~31 torch 5 
setblock ~40 ~27 ~39 torch 5  
fill ~40 ~27 ~40 ~40 ~31 ~40 log  
fill ~52 ~27 ~30 ~52 ~45 ~30 log 
setblock ~52 ~27 ~31 torch 5 
setblock ~52 ~27 ~39 torch 5  
fill ~52 ~27 ~40 ~52 ~45 ~40 log  
fill ~60 ~27 ~30 ~60 ~31 ~30 log 
setblock ~60 ~27 ~31 torch 5 
setblock ~60 ~27 ~39 torch 5  
fill ~60 ~27 ~40 ~60 ~31 ~40 log  
fill ~61 ~27 ~10 ~61 ~27 ~24 nether_brick_stairs  
fill ~61 ~27 ~46 ~61 ~27 ~55 nether_brick_stairs  
fill ~62 ~27 ~55 ~66 ~27 ~55 planks  
fill ~63 ~27 ~10 ~63 ~28 ~10 planks 
setblock ~64 ~27 ~16 glowstone 0 
setblock ~64 ~27 ~45 torch 5  
fill ~65 ~27 ~10 ~65 ~28 ~10 planks  
fill ~67 ~27 ~10 ~67 ~27 ~24 nether_brick_stairs  
fill ~67 ~27 ~25 ~104 ~27 ~25 nether_brick_stairs  
fill ~67 ~27 ~45 ~104 ~27 ~45 nether_brick_stairs  
fill ~67 ~27 ~46 ~67 ~27 ~55 nether_brick_stairs  
fill ~69 ~27 ~30 ~69 ~31 ~30 log 
setblock ~69 ~27 ~31 torch 5 
setblock ~69 ~27 ~39 torch 5  
fill ~69 ~27 ~40 ~69 ~31 ~40 log  
fill ~76 ~27 ~30 ~76 ~45 ~30 log 
setblock ~76 ~27 ~31 torch 5 
setblock ~76 ~27 ~39 torch 5  
fill ~76 ~27 ~40 ~76 ~45 ~40 log  
fill ~90 ~27 ~30 ~90 ~31 ~30 log 
setblock ~90 ~27 ~31 torch 5 
setblock ~90 ~27 ~39 torch 5  
fill ~90 ~27 ~40 ~90 ~31 ~40 log 
setblock ~103 ~27 ~26 torch 5  
fill ~103 ~27 ~30 ~103 ~31 ~30 log 
setblock ~103 ~27 ~31 torch 5 
setblock ~103 ~27 ~39 torch 5  
fill ~103 ~27 ~40 ~103 ~31 ~40 log 
setblock ~103 ~27 ~44 torch 5 
setblock ~104 ~27 ~26 planks 3 
setblock ~104 ~27 ~27 planks 1 
setblock ~104 ~27 ~28 planks 3 
setblock ~104 ~27 ~29 planks 1 
setblock ~104 ~27 ~30 planks 3 
setblock ~104 ~27 ~31 planks 1 
setblock ~104 ~27 ~32 planks 3 
setblock ~104 ~27 ~33 planks 1 
setblock ~104 ~27 ~34 planks 3 
setblock ~104 ~27 ~35 planks 1 
setblock ~104 ~27 ~36 planks 3 
setblock ~104 ~27 ~37 planks 1 
setblock ~104 ~27 ~38 planks 3 
setblock ~104 ~27 ~39 planks 1 
setblock ~104 ~27 ~40 planks 3 
setblock ~104 ~27 ~41 planks 1 
setblock ~104 ~27 ~42 planks 3 
setblock ~104 ~27 ~43 planks 1 
setblock ~104 ~27 ~44 planks 3  
fill ~26 ~28 ~26 ~62 ~28 ~26 nether_brick_stairs 
setblock ~26 ~28 ~28 planks 1 
setblock ~26 ~28 ~30 planks 1 
setblock ~26 ~28 ~32 planks 1 
setblock ~26 ~28 ~34 planks 1 
setblock ~26 ~28 ~36 planks 1 
setblock ~26 ~28 ~38 planks 1 
setblock ~26 ~28 ~40 planks 1 
setblock ~26 ~28 ~42 planks 1  
fill ~26 ~28 ~44 ~62 ~28 ~44 nether_brick_stairs 
setblock ~27 ~28 ~27 torch 1 
setblock ~27 ~28 ~43 torch 1  
fill ~62 ~28 ~10 ~62 ~28 ~25 nether_brick_stairs  
fill ~62 ~28 ~45 ~62 ~28 ~55 nether_brick_stairs  
fill ~63 ~28 ~55 ~65 ~28 ~55 planks  
fill ~66 ~28 ~10 ~66 ~28 ~26 nether_brick_stairs  
fill ~66 ~28 ~44 ~104 ~28 ~44 nether_brick_stairs  
fill ~66 ~28 ~45 ~66 ~28 ~55 nether_brick_stairs  
fill ~67 ~28 ~26 ~104 ~28 ~26 nether_brick_stairs 
setblock ~104 ~28 ~27 planks 3 
setblock ~104 ~28 ~28 planks 1 
setblock ~104 ~28 ~29 planks 3 
setblock ~104 ~28 ~30 planks 1 
setblock ~104 ~28 ~31 planks 3 
setblock ~104 ~28 ~32 planks 1 
setblock ~104 ~28 ~33 planks 3 
setblock ~104 ~28 ~34 planks 1 
setblock ~104 ~28 ~35 planks 3 
setblock ~104 ~28 ~36 planks 1 
setblock ~104 ~28 ~37 planks 3 
setblock ~104 ~28 ~38 planks 1 
setblock ~104 ~28 ~39 planks 3 
setblock ~104 ~28 ~40 planks 1 
setblock ~104 ~28 ~41 planks 3 
setblock ~104 ~28 ~42 planks 1 
setblock ~104 ~28 ~43 planks 3  
fill ~26 ~29 ~27 ~63 ~29 ~27 nether_brick_stairs 
setblock ~26 ~29 ~28 planks 3  
fill ~26 ~29 ~30 ~26 ~30 ~30 planks  
fill ~26 ~29 ~32 ~26 ~30 ~32 planks  
fill ~26 ~29 ~34 ~26 ~30 ~34 planks  
fill ~26 ~29 ~36 ~26 ~30 ~36 planks  
fill ~26 ~29 ~38 ~26 ~30 ~38 planks  
fill ~26 ~29 ~40 ~26 ~30 ~40 planks 
setblock ~26 ~29 ~42 planks 3  
fill ~26 ~29 ~43 ~62 ~29 ~43 nether_brick_stairs 
setblock ~27 ~29 ~28 torch 1 
setblock ~27 ~29 ~42 torch 1  
fill ~63 ~29 ~10 ~63 ~29 ~26 nether_brick_stairs  
fill ~63 ~29 ~43 ~63 ~29 ~55 nether_brick_stairs 
setblock ~64 ~29 ~54 torch 4 
setblock ~64 ~29 ~55 planks 3  
fill ~65 ~29 ~10 ~65 ~29 ~26 nether_brick_stairs  
fill ~65 ~29 ~27 ~104 ~29 ~27 nether_brick_stairs  
fill ~65 ~29 ~43 ~65 ~29 ~55 nether_brick_stairs  
fill ~66 ~29 ~43 ~104 ~29 ~43 nether_brick_stairs 
setblock ~104 ~29 ~28 planks 3 
setblock ~104 ~29 ~29 planks 1 
setblock ~104 ~29 ~30 planks 3 
setblock ~104 ~29 ~31 planks 1 
setblock ~104 ~29 ~32 planks 3 
setblock ~104 ~29 ~33 planks 1 
setblock ~104 ~29 ~34 planks 3 
setblock ~104 ~29 ~35 planks 1 
setblock ~104 ~29 ~36 planks 3 
setblock ~104 ~29 ~37 planks 1 
setblock ~104 ~29 ~38 planks 3 
setblock ~104 ~29 ~39 planks 1 
setblock ~104 ~29 ~40 planks 3 
setblock ~104 ~29 ~41 planks 1 
setblock ~104 ~29 ~42 planks 3  
fill ~26 ~30 ~28 ~63 ~30 ~28 nether_brick_stairs  
fill ~26 ~30 ~42 ~63 ~30 ~42 nether_brick_stairs 
setblock ~27 ~30 ~29 torch 1 
setblock ~27 ~30 ~41 torch 1  
fill ~64 ~30 ~10 ~64 ~30 ~28 nether_brick  
fill ~64 ~30 ~42 ~64 ~30 ~55 nether_brick  
fill ~65 ~30 ~28 ~104 ~30 ~28 nether_brick_stairs  
fill ~65 ~30 ~42 ~104 ~30 ~42 nether_brick_stairs 
setblock ~104 ~30 ~29 planks 3 
setblock ~104 ~30 ~30 planks 1 
setblock ~104 ~30 ~31 planks 3 
setblock ~104 ~30 ~32 planks 1 
setblock ~104 ~30 ~33 planks 3 
setblock ~104 ~30 ~34 planks 1 
setblock ~104 ~30 ~35 planks 3 
setblock ~104 ~30 ~36 planks 1 
setblock ~104 ~30 ~37 planks 3 
setblock ~104 ~30 ~38 planks 1 
setblock ~104 ~30 ~39 planks 3 
setblock ~104 ~30 ~40 planks 1 
setblock ~104 ~30 ~41 planks 3  
fill ~26 ~31 ~29 ~104 ~31 ~29 nether_brick_stairs 
setblock ~26 ~31 ~30 planks 1 
setblock ~26 ~31 ~32 planks 1 
setblock ~26 ~31 ~34 planks 1 
setblock ~26 ~31 ~36 planks 1 
setblock ~26 ~31 ~38 planks 1 
setblock ~26 ~31 ~40 planks 1  
fill ~26 ~31 ~41 ~104 ~31 ~41 nether_brick_stairs 
setblock ~28 ~31 ~30 torch 1 
setblock ~28 ~31 ~40 torch 1 
setblock ~53 ~31 ~30 torch 3  
fill ~64 ~31 ~10 ~64 ~33 ~10 nether_brick_fence 
setblock ~67 ~31 ~30 torch 3 
setblock ~104 ~31 ~30 planks 3 
setblock ~104 ~31 ~31 planks 1 
setblock ~104 ~31 ~32 planks 3 
setblock ~104 ~31 ~33 planks 1 
setblock ~104 ~31 ~34 planks 3 
setblock ~104 ~31 ~35 planks 1 
setblock ~104 ~31 ~36 planks 3 
setblock ~104 ~31 ~37 planks 1 
setblock ~104 ~31 ~38 planks 3 
setblock ~104 ~31 ~39 planks 1 
setblock ~104 ~31 ~40 planks 3  
fill ~26 ~32 ~30 ~51 ~32 ~30 nether_brick_stairs 
setblock ~26 ~32 ~32 planks 3 
setblock ~26 ~32 ~34 planks 3 
setblock ~26 ~32 ~36 planks 3 
setblock ~26 ~32 ~38 planks 3 
setblock ~26 ~32 ~40 nether_brick_stairs 3 
setblock ~27 ~32 ~31 torch 1 
setblock ~27 ~32 ~39 torch 1 
setblock ~27 ~32 ~40 log 5  
fill ~28 ~32 ~40 ~51 ~32 ~40 nether_brick_stairs 
setblock ~52 ~32 ~31 torch 3 
setblock ~52 ~32 ~39 torch 4 
setblock ~53 ~32 ~30 planks 1 
setblock ~53 ~32 ~40 planks 1  
fill ~54 ~32 ~30 ~54 ~45 ~30 planks  
fill ~54 ~32 ~40 ~54 ~46 ~40 planks 
setblock ~55 ~32 ~30 planks 1 
setblock ~55 ~32 ~40 planks 1  
fill ~56 ~32 ~30 ~56 ~45 ~30 planks  
fill ~56 ~32 ~40 ~56 ~46 ~40 planks 
setblock ~57 ~32 ~30 planks 1 
setblock ~57 ~32 ~40 planks 1  
fill ~58 ~32 ~30 ~58 ~45 ~30 planks  
fill ~58 ~32 ~40 ~58 ~46 ~40 planks 
setblock ~59 ~32 ~30 planks 1 
setblock ~59 ~32 ~40 planks 1  
fill ~60 ~32 ~30 ~60 ~45 ~30 planks  
fill ~60 ~32 ~40 ~60 ~46 ~40 planks 
setblock ~61 ~32 ~30 planks 1 
setblock ~61 ~32 ~40 planks 1  
fill ~62 ~32 ~30 ~62 ~45 ~30 planks  
fill ~62 ~32 ~40 ~62 ~46 ~40 planks 
setblock ~63 ~32 ~10 nether_brick_fence 0 
setblock ~63 ~32 ~30 planks 1 
setblock ~63 ~32 ~40 planks 1  
fill ~64 ~32 ~30 ~64 ~45 ~30 planks  
fill ~64 ~32 ~40 ~64 ~46 ~40 planks 
setblock ~65 ~32 ~10 nether_brick_fence 0 
setblock ~65 ~32 ~30 planks 1 
setblock ~65 ~32 ~40 planks 1  
fill ~66 ~32 ~30 ~66 ~45 ~30 planks  
fill ~66 ~32 ~40 ~66 ~46 ~40 planks 
setblock ~67 ~32 ~30 planks 1 
setblock ~67 ~32 ~40 planks 1  
fill ~68 ~32 ~30 ~68 ~45 ~30 planks  
fill ~68 ~32 ~40 ~68 ~46 ~40 planks 
setblock ~69 ~32 ~30 planks 1 
setblock ~69 ~32 ~40 planks 1  
fill ~70 ~32 ~30 ~70 ~45 ~30 planks  
fill ~70 ~32 ~40 ~70 ~46 ~40 planks 
setblock ~71 ~32 ~30 planks 1 
setblock ~71 ~32 ~40 planks 1  
fill ~72 ~32 ~30 ~72 ~45 ~30 planks  
fill ~72 ~32 ~40 ~72 ~46 ~40 planks 
setblock ~73 ~32 ~30 planks 1 
setblock ~73 ~32 ~40 planks 1  
fill ~74 ~32 ~30 ~74 ~45 ~30 planks  
fill ~74 ~32 ~40 ~74 ~46 ~40 planks 
setblock ~75 ~32 ~30 planks 1 
setblock ~75 ~32 ~40 planks 1 
setblock ~76 ~32 ~31 torch 3  
fill ~77 ~32 ~30 ~104 ~32 ~30 nether_brick_stairs  
fill ~77 ~32 ~40 ~104 ~32 ~40 nether_brick_stairs 
setblock ~104 ~32 ~31 planks 3 
setblock ~104 ~32 ~32 planks 1 
setblock ~104 ~32 ~33 planks 3 
setblock ~104 ~32 ~34 planks 1 
setblock ~104 ~32 ~35 planks 3 
setblock ~104 ~32 ~36 planks 1 
setblock ~104 ~32 ~37 planks 3 
setblock ~104 ~32 ~38 planks 1 
setblock ~104 ~32 ~39 planks 3  
fill ~26 ~33 ~31 ~51 ~33 ~31 nether_brick_stairs 
setblock ~26 ~33 ~32 planks 1 
setblock ~26 ~33 ~34 planks 1 
setblock ~26 ~33 ~36 planks 1 
setblock ~26 ~33 ~38 planks 1  
fill ~26 ~33 ~39 ~51 ~33 ~39 nether_brick_stairs 
setblock ~27 ~33 ~32 torch 1 
setblock ~27 ~33 ~38 torch 1 
setblock ~52 ~33 ~31 planks 1 
setblock ~52 ~33 ~32 torch 3 
setblock ~52 ~33 ~38 torch 4 
setblock ~52 ~33 ~39 planks 1  
fill ~53 ~33 ~30 ~53 ~37 ~30 planks  
fill ~53 ~33 ~40 ~53 ~37 ~40 planks  
fill ~55 ~33 ~30 ~55 ~37 ~30 planks  
fill ~55 ~33 ~40 ~55 ~37 ~40 planks  
fill ~57 ~33 ~30 ~57 ~37 ~30 planks  
fill ~57 ~33 ~40 ~57 ~37 ~40 planks  
fill ~59 ~33 ~30 ~59 ~37 ~30 planks  
fill ~59 ~33 ~40 ~59 ~37 ~40 planks  
fill ~61 ~33 ~30 ~61 ~37 ~30 planks  
fill ~61 ~33 ~40 ~61 ~37 ~40 planks  
fill ~63 ~33 ~30 ~63 ~37 ~30 planks  
fill ~63 ~33 ~40 ~63 ~37 ~40 planks  
fill ~65 ~33 ~30 ~65 ~37 ~30 planks  
fill ~65 ~33 ~40 ~65 ~37 ~40 planks  
fill ~67 ~33 ~30 ~67 ~37 ~30 planks  
fill ~67 ~33 ~40 ~67 ~37 ~40 planks  
fill ~69 ~33 ~30 ~69 ~37 ~30 planks  
fill ~69 ~33 ~40 ~69 ~37 ~40 planks  
fill ~71 ~33 ~30 ~71 ~37 ~30 planks  
fill ~71 ~33 ~40 ~71 ~37 ~40 planks  
fill ~73 ~33 ~30 ~73 ~37 ~30 planks  
fill ~73 ~33 ~40 ~73 ~37 ~40 planks  
fill ~75 ~33 ~30 ~75 ~37 ~30 planks  
fill ~75 ~33 ~40 ~75 ~37 ~40 planks 
setblock ~76 ~33 ~31 planks 1 
setblock ~76 ~33 ~38 torch 4 
setblock ~76 ~33 ~39 planks 1  
fill ~77 ~33 ~31 ~104 ~33 ~31 nether_brick_stairs  
fill ~77 ~33 ~39 ~104 ~33 ~39 nether_brick_stairs 
setblock ~104 ~33 ~32 planks 3 
setblock ~104 ~33 ~33 planks 1 
setblock ~104 ~33 ~34 planks 3 
setblock ~104 ~33 ~35 planks 1 
setblock ~104 ~33 ~36 planks 3 
setblock ~104 ~33 ~37 planks 1 
setblock ~104 ~33 ~38 planks 3  
fill ~26 ~34 ~32 ~51 ~34 ~32 nether_brick_stairs 
setblock ~26 ~34 ~34 planks 3 
setblock ~26 ~34 ~36 planks 3  
fill ~26 ~34 ~38 ~51 ~34 ~38 nether_brick_stairs 
setblock ~27 ~34 ~33 torch 1 
setblock ~27 ~34 ~37 torch 1 
setblock ~52 ~34 ~31 planks 3 
setblock ~52 ~34 ~32 planks 1 
setblock ~52 ~34 ~33 torch 3 
setblock ~52 ~34 ~37 torch 4 
setblock ~52 ~34 ~38 planks 1 
setblock ~52 ~34 ~39 planks 3 
setblock ~76 ~34 ~31 planks 3 
setblock ~76 ~34 ~32 planks 1 
setblock ~76 ~34 ~33 torch 3  
fill ~76 ~34 ~37 ~77 ~34 ~37 torch 
setblock ~76 ~34 ~38 planks 1 
setblock ~76 ~34 ~39 planks 3  
fill ~77 ~34 ~32 ~104 ~34 ~32 nether_brick_stairs  
fill ~77 ~34 ~38 ~104 ~34 ~38 nether_brick_stairs 
setblock ~103 ~34 ~33 torch 3 
setblock ~103 ~34 ~37 torch 4 
setblock ~104 ~34 ~33 planks 3 
setblock ~104 ~34 ~34 planks 1 
setblock ~104 ~34 ~35 planks 3 
setblock ~104 ~34 ~36 planks 1 
setblock ~104 ~34 ~37 planks 3  
fill ~26 ~35 ~33 ~51 ~35 ~33 nether_brick_stairs 
setblock ~26 ~35 ~34 planks 1 
setblock ~26 ~35 ~36 planks 1  
fill ~26 ~35 ~37 ~51 ~35 ~37 nether_brick_stairs 
setblock ~27 ~35 ~34 torch 1 
setblock ~27 ~35 ~36 torch 1 
setblock ~52 ~35 ~31 planks 1 
setblock ~52 ~35 ~32 planks 3 
setblock ~52 ~35 ~33 planks 1 
setblock ~52 ~35 ~34 torch 3 
setblock ~52 ~35 ~36 torch 4 
setblock ~52 ~35 ~37 planks 1 
setblock ~52 ~35 ~38 planks 3 
setblock ~52 ~35 ~39 planks 1 
setblock ~76 ~35 ~31 planks 1 
setblock ~76 ~35 ~32 planks 3 
setblock ~76 ~35 ~33 planks 1 
setblock ~76 ~35 ~34 torch 3 
setblock ~76 ~35 ~36 torch 4  
fill ~76 ~35 ~37 ~76 ~36 ~37 planks  
fill ~76 ~35 ~38 ~76 ~35 ~37 planks 
setblock ~76 ~35 ~39 planks 1  
fill ~77 ~35 ~33 ~104 ~35 ~33 nether_brick_stairs  
fill ~77 ~35 ~37 ~104 ~35 ~37 nether_brick_stairs 
setblock ~104 ~35 ~34 planks 3 
setblock ~104 ~35 ~35 planks 1 
setblock ~104 ~35 ~36 planks 3  
fill ~26 ~36 ~34 ~51 ~36 ~34 nether_brick_stairs  
fill ~26 ~36 ~36 ~51 ~36 ~36 nether_brick_stairs 
setblock ~27 ~36 ~35 torch 1 
setblock ~52 ~36 ~31 planks 3 
setblock ~52 ~36 ~32 planks 1 
setblock ~52 ~36 ~33 planks 3 
setblock ~52 ~36 ~34 planks 1 
setblock ~52 ~36 ~36 planks 1 
setblock ~52 ~36 ~37 planks 3 
setblock ~52 ~36 ~38 planks 1 
setblock ~52 ~36 ~39 planks 3 
setblock ~76 ~36 ~31 planks 3 
setblock ~76 ~36 ~32 planks 1 
setblock ~76 ~36 ~33 planks 3 
setblock ~76 ~36 ~34 planks 1 
setblock ~76 ~36 ~36 planks 1 
setblock ~76 ~36 ~38 planks 1 
setblock ~76 ~36 ~39 planks 3  
fill ~77 ~36 ~34 ~104 ~36 ~34 nether_brick_stairs  
fill ~77 ~36 ~36 ~104 ~36 ~36 nether_brick_stairs 
setblock ~104 ~36 ~35 planks 3  
fill ~26 ~37 ~35 ~51 ~37 ~35 nether_brick 
setblock ~52 ~37 ~31 planks 1 
setblock ~52 ~37 ~32 planks 3 
setblock ~52 ~37 ~33 planks 1 
setblock ~52 ~37 ~34 planks 3 
setblock ~52 ~37 ~35 planks 1 
setblock ~52 ~37 ~36 planks 3 
setblock ~52 ~37 ~37 planks 1 
setblock ~52 ~37 ~38 planks 3 
setblock ~52 ~37 ~39 planks 1 
setblock ~53 ~37 ~35 torch 1 
setblock ~76 ~37 ~31 planks 1 
setblock ~76 ~37 ~32 planks 3 
setblock ~76 ~37 ~33 planks 1 
setblock ~76 ~37 ~34 planks 3 
setblock ~76 ~37 ~35 planks 1 
setblock ~76 ~37 ~36 planks 3 
setblock ~76 ~37 ~37 planks 1 
setblock ~76 ~37 ~38 planks 3 
setblock ~76 ~37 ~39 planks 1  
fill ~77 ~37 ~35 ~104 ~37 ~35 nether_brick 
setblock ~25 ~38 ~35 nether_brick_stairs 4  
fill ~26 ~38 ~35 ~27 ~38 ~35 nether_brick 
setblock ~28 ~38 ~35 nether_brick_stairs 1 
setblock ~52 ~38 ~31 planks 3 
setblock ~52 ~38 ~32 planks 1 
setblock ~52 ~38 ~33 planks 3 
setblock ~52 ~38 ~34 planks 1 
setblock ~52 ~38 ~35 planks 3 
setblock ~52 ~38 ~36 planks 1 
setblock ~52 ~38 ~37 planks 3 
setblock ~52 ~38 ~38 planks 1 
setblock ~52 ~38 ~39 planks 3 
setblock ~53 ~38 ~30 planks 1 
setblock ~53 ~38 ~40 planks 1 
setblock ~55 ~38 ~30 planks 1 
setblock ~55 ~38 ~40 planks 1 
setblock ~57 ~38 ~30 planks 1 
setblock ~57 ~38 ~40 planks 1 
setblock ~59 ~38 ~30 planks 1 
setblock ~59 ~38 ~40 planks 1 
setblock ~61 ~38 ~30 planks 1 
setblock ~61 ~38 ~40 planks 1 
setblock ~63 ~38 ~30 planks 1 
setblock ~63 ~38 ~40 planks 1 
setblock ~65 ~38 ~30 planks 1 
setblock ~65 ~38 ~40 planks 1 
setblock ~67 ~38 ~30 planks 1 
setblock ~67 ~38 ~40 planks 1 
setblock ~69 ~38 ~30 planks 1 
setblock ~69 ~38 ~40 planks 1 
setblock ~71 ~38 ~30 planks 1 
setblock ~71 ~38 ~40 planks 1 
setblock ~73 ~38 ~30 planks 1 
setblock ~73 ~38 ~40 planks 1 
setblock ~75 ~38 ~30 planks 1 
setblock ~75 ~38 ~40 planks 1 
setblock ~76 ~38 ~31 planks 3 
setblock ~76 ~38 ~32 planks 1 
setblock ~76 ~38 ~33 planks 3 
setblock ~76 ~38 ~34 planks 1 
setblock ~76 ~38 ~35 planks 3 
setblock ~76 ~38 ~36 planks 1 
setblock ~76 ~38 ~37 planks 3 
setblock ~76 ~38 ~38 planks 1 
setblock ~76 ~38 ~39 planks 3 
setblock ~102 ~38 ~35 nether_brick_stairs 0  
fill ~103 ~38 ~35 ~104 ~38 ~35 nether_brick 
setblock ~105 ~38 ~35 nether_brick_stairs 5 
setblock ~23 ~39 ~35 nether_brick_stairs 5 
setblock ~24 ~39 ~35 nether_brick_stairs 4 
setblock ~25 ~39 ~35 nether_brick_stairs 1 
setblock ~52 ~39 ~31 planks 1 
setblock ~52 ~39 ~32 planks 3 
setblock ~52 ~39 ~33 planks 1 
setblock ~52 ~39 ~34 planks 3 
setblock ~52 ~39 ~35 planks 1 
setblock ~52 ~39 ~36 planks 3 
setblock ~52 ~39 ~37 planks 1 
setblock ~52 ~39 ~38 planks 3 
setblock ~52 ~39 ~39 planks 1  
fill ~53 ~39 ~30 ~53 ~41 ~30 planks  
fill ~53 ~39 ~40 ~53 ~41 ~40 planks 
setblock ~55 ~39 ~30 planks 3 
setblock ~55 ~39 ~40 planks 3  
fill ~57 ~39 ~30 ~57 ~41 ~30 planks  
fill ~57 ~39 ~40 ~57 ~41 ~40 planks  
fill ~59 ~39 ~30 ~59 ~41 ~30 planks  
fill ~59 ~39 ~40 ~59 ~41 ~40 planks 
setblock ~61 ~39 ~30 planks 3 
setblock ~61 ~39 ~40 planks 3  
fill ~63 ~39 ~30 ~63 ~41 ~30 planks  
fill ~63 ~39 ~40 ~63 ~41 ~40 planks  
fill ~65 ~39 ~30 ~65 ~41 ~30 planks  
fill ~65 ~39 ~40 ~65 ~41 ~40 planks 
setblock ~67 ~39 ~30 planks 3 
setblock ~67 ~39 ~40 planks 3  
fill ~69 ~39 ~30 ~69 ~41 ~30 planks  
fill ~69 ~39 ~40 ~69 ~41 ~40 planks  
fill ~71 ~39 ~30 ~71 ~41 ~30 planks  
fill ~71 ~39 ~40 ~71 ~41 ~40 planks 
setblock ~73 ~39 ~30 planks 3 
setblock ~73 ~39 ~40 planks 3  
fill ~75 ~39 ~30 ~75 ~41 ~30 planks  
fill ~75 ~39 ~40 ~75 ~41 ~40 planks 
setblock ~76 ~39 ~31 planks 1 
setblock ~76 ~39 ~32 planks 3 
setblock ~76 ~39 ~33 planks 1 
setblock ~76 ~39 ~34 planks 3 
setblock ~76 ~39 ~35 planks 1 
setblock ~76 ~39 ~36 planks 3 
setblock ~76 ~39 ~37 planks 1 
setblock ~76 ~39 ~38 planks 3 
setblock ~76 ~39 ~39 planks 1 
setblock ~105 ~39 ~35 nether_brick_stairs 0 
setblock ~106 ~39 ~35 nether_brick_stairs 5 
setblock ~107 ~39 ~35 nether_brick_stairs 4 
setblock ~21 ~40 ~35 nether_brick_stairs 4  
fill ~22 ~40 ~35 ~23 ~40 ~35 nether_brick 
setblock ~24 ~40 ~35 nether_brick_stairs 1 
setblock ~52 ~40 ~31 planks 3 
setblock ~52 ~40 ~32 planks 1 
setblock ~52 ~40 ~33 planks 3 
setblock ~52 ~40 ~34 planks 1 
setblock ~52 ~40 ~35 planks 3 
setblock ~52 ~40 ~36 planks 1 
setblock ~52 ~40 ~37 planks 3 
setblock ~52 ~40 ~38 planks 1 
setblock ~52 ~40 ~39 planks 3 
setblock ~76 ~40 ~31 planks 3 
setblock ~76 ~40 ~32 planks 1 
setblock ~76 ~40 ~33 planks 3 
setblock ~76 ~40 ~34 planks 1 
setblock ~76 ~40 ~35 planks 3 
setblock ~76 ~40 ~36 planks 1 
setblock ~76 ~40 ~37 planks 3 
setblock ~76 ~40 ~38 planks 1 
setblock ~76 ~40 ~39 planks 3 
setblock ~106 ~40 ~35 nether_brick_stairs 0  
fill ~107 ~40 ~35 ~108 ~40 ~35 nether_brick 
setblock ~109 ~40 ~35 nether_brick_stairs 5 
setblock ~20 ~41 ~35 nether_brick_stairs 4 
setblock ~21 ~41 ~35 nether_brick_stairs 1 
setblock ~23 ~41 ~35 nether_brick_stairs 1 
setblock ~52 ~41 ~31 planks 1 
setblock ~52 ~41 ~32 planks 3 
setblock ~52 ~41 ~33 planks 1 
setblock ~52 ~41 ~34 planks 3 
setblock ~52 ~41 ~35 planks 1 
setblock ~52 ~41 ~36 planks 3 
setblock ~52 ~41 ~37 planks 1 
setblock ~52 ~41 ~38 planks 3 
setblock ~52 ~41 ~39 planks 1 
setblock ~55 ~41 ~30 planks 3 
setblock ~55 ~41 ~40 planks 3 
setblock ~61 ~41 ~30 planks 3 
setblock ~61 ~41 ~40 planks 3 
setblock ~67 ~41 ~30 planks 3 
setblock ~67 ~41 ~40 planks 3 
setblock ~73 ~41 ~30 planks 3 
setblock ~73 ~41 ~40 planks 3 
setblock ~76 ~41 ~31 planks 1 
setblock ~76 ~41 ~32 planks 3 
setblock ~76 ~41 ~33 planks 1 
setblock ~76 ~41 ~34 planks 3 
setblock ~76 ~41 ~35 planks 1 
setblock ~76 ~41 ~36 planks 3 
setblock ~76 ~41 ~37 planks 1 
setblock ~76 ~41 ~38 planks 3 
setblock ~76 ~41 ~39 planks 1 
setblock ~107 ~41 ~35 nether_brick_stairs 0 
setblock ~109 ~41 ~35 nether_brick_stairs 0 
setblock ~110 ~41 ~35 nether_brick_stairs 5 
setblock ~20 ~42 ~35 glowstone 0 
setblock ~52 ~42 ~31 planks 3 
setblock ~52 ~42 ~32 planks 1 
setblock ~52 ~42 ~33 planks 3 
setblock ~52 ~42 ~34 planks 1 
setblock ~52 ~42 ~35 planks 3 
setblock ~52 ~42 ~36 planks 1 
setblock ~52 ~42 ~37 planks 3 
setblock ~52 ~42 ~38 planks 1 
setblock ~52 ~42 ~39 planks 3 
setblock ~53 ~42 ~30 planks 1 
setblock ~53 ~42 ~40 planks 1 
setblock ~55 ~42 ~30 planks 1 
setblock ~55 ~42 ~40 planks 1 
setblock ~57 ~42 ~30 planks 1 
setblock ~57 ~42 ~40 planks 1 
setblock ~59 ~42 ~30 planks 1 
setblock ~59 ~42 ~40 planks 1 
setblock ~61 ~42 ~30 planks 1 
setblock ~61 ~42 ~40 planks 1 
setblock ~63 ~42 ~30 planks 1 
setblock ~63 ~42 ~40 planks 1 
setblock ~65 ~42 ~30 planks 1 
setblock ~65 ~42 ~40 planks 1 
setblock ~67 ~42 ~30 planks 1 
setblock ~67 ~42 ~40 planks 1 
setblock ~69 ~42 ~30 planks 1 
setblock ~69 ~42 ~40 planks 1 
setblock ~71 ~42 ~30 planks 1 
setblock ~71 ~42 ~40 planks 1 
setblock ~73 ~42 ~30 planks 1 
setblock ~73 ~42 ~40 planks 1 
setblock ~75 ~42 ~30 planks 1 
setblock ~75 ~42 ~40 planks 1 
setblock ~76 ~42 ~31 planks 3 
setblock ~76 ~42 ~32 planks 1 
setblock ~76 ~42 ~33 planks 3 
setblock ~76 ~42 ~34 planks 1 
setblock ~76 ~42 ~35 planks 3 
setblock ~76 ~42 ~36 planks 1 
setblock ~76 ~42 ~37 planks 3 
setblock ~76 ~42 ~38 planks 1 
setblock ~76 ~42 ~39 planks 3 
setblock ~110 ~42 ~35 glowstone 0 
setblock ~52 ~43 ~31 planks 1 
setblock ~52 ~43 ~32 planks 3 
setblock ~52 ~43 ~33 planks 1 
setblock ~52 ~43 ~34 planks 3 
setblock ~52 ~43 ~35 planks 1 
setblock ~52 ~43 ~36 planks 3 
setblock ~52 ~43 ~37 planks 1  
fill ~52 ~43 ~38 ~52 ~45 ~38 planks 
setblock ~52 ~43 ~39 planks 1  
fill ~53 ~43 ~30 ~53 ~45 ~30 planks  
fill ~53 ~43 ~40 ~53 ~46 ~40 planks  
fill ~55 ~43 ~30 ~55 ~45 ~30 planks  
fill ~55 ~43 ~40 ~55 ~46 ~40 planks  
fill ~57 ~43 ~30 ~57 ~45 ~30 planks  
fill ~57 ~43 ~40 ~57 ~46 ~40 planks  
fill ~59 ~43 ~30 ~59 ~45 ~30 planks  
fill ~59 ~43 ~40 ~59 ~46 ~40 planks  
fill ~61 ~43 ~30 ~61 ~45 ~30 planks  
fill ~61 ~43 ~40 ~61 ~46 ~40 planks  
fill ~63 ~43 ~30 ~63 ~45 ~30 planks  
fill ~63 ~43 ~40 ~63 ~46 ~40 planks  
fill ~65 ~43 ~30 ~65 ~45 ~30 planks  
fill ~65 ~43 ~40 ~65 ~46 ~40 planks  
fill ~67 ~43 ~30 ~67 ~45 ~30 planks  
fill ~67 ~43 ~40 ~67 ~46 ~40 planks  
fill ~69 ~43 ~30 ~69 ~45 ~30 planks  
fill ~69 ~43 ~40 ~69 ~46 ~40 planks  
fill ~71 ~43 ~30 ~71 ~45 ~30 planks  
fill ~71 ~43 ~40 ~71 ~46 ~40 planks  
fill ~73 ~43 ~30 ~73 ~45 ~30 planks  
fill ~73 ~43 ~40 ~73 ~46 ~40 planks  
fill ~75 ~43 ~30 ~75 ~45 ~30 planks  
fill ~75 ~43 ~40 ~75 ~46 ~40 planks 
setblock ~76 ~43 ~31 planks 1 
setblock ~76 ~43 ~32 planks 3 
setblock ~76 ~43 ~33 planks 1 
setblock ~76 ~43 ~34 planks 3 
setblock ~76 ~43 ~35 planks 1 
setblock ~76 ~43 ~36 planks 3 
setblock ~76 ~43 ~37 planks 1 
setblock ~76 ~43 ~38 planks 3 
setblock ~76 ~43 ~39 planks 1 
setblock ~52 ~44 ~31 planks 3 
setblock ~52 ~44 ~32 planks 1 
setblock ~52 ~44 ~33 planks 3 
setblock ~52 ~44 ~34 planks 1 
setblock ~52 ~44 ~35 planks 3 
setblock ~52 ~44 ~36 planks 1 
setblock ~52 ~44 ~37 planks 3 
setblock ~52 ~44 ~39 planks 3 
setblock ~76 ~44 ~31 planks 3 
setblock ~76 ~44 ~32 planks 1 
setblock ~76 ~44 ~33 planks 3 
setblock ~76 ~44 ~34 planks 1 
setblock ~76 ~44 ~35 planks 3 
setblock ~76 ~44 ~36 planks 1 
setblock ~76 ~44 ~37 planks 3 
setblock ~76 ~44 ~38 planks 1 
setblock ~76 ~44 ~39 planks 3  
fill ~52 ~45 ~28 ~76 ~45 ~28 nether_brick_stairs  
fill ~52 ~45 ~31 ~52 ~46 ~31 planks 
setblock ~52 ~45 ~32 planks 3  
fill ~52 ~45 ~33 ~52 ~46 ~33 planks 
setblock ~52 ~45 ~34 planks 3  
fill ~52 ~45 ~35 ~52 ~46 ~35 planks 
setblock ~52 ~45 ~36 planks 3  
fill ~52 ~45 ~37 ~52 ~46 ~37 planks  
fill ~52 ~45 ~39 ~52 ~46 ~39 planks  
fill ~52 ~45 ~42 ~76 ~45 ~42 nether_brick_stairs  
fill ~76 ~45 ~31 ~76 ~46 ~31 planks 
setblock ~76 ~45 ~32 planks 3  
fill ~76 ~45 ~33 ~76 ~46 ~33 planks 
setblock ~76 ~45 ~34 planks 3  
fill ~76 ~45 ~35 ~76 ~46 ~35 planks 
setblock ~76 ~45 ~36 planks 3  
fill ~76 ~45 ~37 ~76 ~46 ~37 planks 
setblock ~76 ~45 ~38 planks 3  
fill ~76 ~45 ~39 ~76 ~46 ~39 planks  
fill ~52 ~46 ~29 ~76 ~46 ~29 nether_brick_stairs  
fill ~52 ~46 ~30 ~76 ~46 ~30 planks 
setblock ~52 ~46 ~32 planks 1 
setblock ~52 ~46 ~34 planks 1 
setblock ~52 ~46 ~36 planks 1 
setblock ~52 ~46 ~38 planks 1 
setblock ~52 ~46 ~40 planks 1  
fill ~52 ~46 ~41 ~76 ~46 ~41 nether_brick_stairs 
setblock ~76 ~46 ~32 planks 1 
setblock ~76 ~46 ~34 planks 1 
setblock ~76 ~46 ~36 planks 1 
setblock ~76 ~46 ~38 planks 1 
setblock ~76 ~46 ~40 planks 1  
fill ~52 ~47 ~30 ~76 ~47 ~30 nether_brick_stairs  
fill ~52 ~47 ~31 ~52 ~47 ~39 planks  
fill ~52 ~47 ~40 ~76 ~47 ~40 nether_brick_stairs  
fill ~60 ~47 ~31 ~60 ~47 ~39 log  
fill ~61 ~47 ~31 ~67 ~47 ~31 log  
fill ~61 ~47 ~39 ~67 ~47 ~39 log  
fill ~68 ~47 ~31 ~68 ~47 ~39 log  
fill ~76 ~47 ~31 ~76 ~47 ~39 planks  
fill ~52 ~48 ~31 ~59 ~48 ~31 nether_brick_stairs  
fill ~52 ~48 ~32 ~52 ~48 ~38 planks  
fill ~52 ~48 ~39 ~59 ~48 ~39 nether_brick_stairs  
fill ~60 ~48 ~31 ~60 ~54 ~31 log 
setblock ~60 ~48 ~32 torch 3 
setblock ~60 ~48 ~38 torch 4  
fill ~60 ~48 ~39 ~60 ~54 ~39 log 
setblock ~61 ~48 ~31 planks 3 
setblock ~61 ~48 ~39 planks 3 
setblock ~62 ~48 ~31 planks 1 
setblock ~62 ~48 ~39 planks 1 
setblock ~63 ~48 ~31 planks 3 
setblock ~63 ~48 ~39 planks 3 
setblock ~64 ~48 ~31 planks 1 
setblock ~64 ~48 ~39 planks 1 
setblock ~65 ~48 ~31 planks 3 
setblock ~65 ~48 ~39 planks 3 
setblock ~66 ~48 ~31 planks 1 
setblock ~66 ~48 ~39 planks 1 
setblock ~67 ~48 ~31 planks 3 
setblock ~67 ~48 ~39 planks 3  
fill ~68 ~48 ~31 ~68 ~54 ~31 log 
setblock ~68 ~48 ~32 torch 3 
setblock ~68 ~48 ~38 torch 4  
fill ~68 ~48 ~39 ~68 ~54 ~39 log  
fill ~69 ~48 ~31 ~76 ~48 ~31 nether_brick_stairs   
fill ~69 ~48 ~39 ~76 ~48 ~39 nether_brick_stairs  
fill ~76 ~48 ~32 ~76 ~48 ~38 planks  
fill ~52 ~49 ~32 ~59 ~49 ~32 nether_brick_stairs  
fill ~52 ~49 ~33 ~52 ~49 ~37 planks  
fill ~52 ~49 ~38 ~59 ~49 ~38 nether_brick_stairs 
setblock ~60 ~49 ~32 planks 3 
setblock ~60 ~49 ~33 torch 3 
setblock ~60 ~49 ~37 torch 4 
setblock ~60 ~49 ~38 planks 3 
setblock ~61 ~49 ~31 planks 1 
setblock ~61 ~49 ~39 planks 1 
setblock ~62 ~49 ~31 planks 3 
setblock ~62 ~49 ~39 planks 3 
setblock ~63 ~49 ~31 planks 1 
setblock ~63 ~49 ~39 planks 1 
setblock ~64 ~49 ~31 planks 3 
setblock ~64 ~49 ~39 planks 3 
setblock ~65 ~49 ~31 planks 1 
setblock ~65 ~49 ~39 planks 1 
setblock ~66 ~49 ~31 planks 3 
setblock ~66 ~49 ~39 planks 3 
setblock ~67 ~49 ~31 planks 1 
setblock ~67 ~49 ~39 planks 1 
setblock ~68 ~49 ~32 planks 1 
setblock ~68 ~49 ~33 torch 3 
setblock ~68 ~49 ~37 torch 4 
setblock ~68 ~49 ~38 planks 1  
fill ~69 ~49 ~32 ~76 ~49 ~32 nether_brick_stairs  
fill ~69 ~49 ~38 ~76 ~49 ~38 nether_brick_stairs  
fill ~76 ~49 ~33 ~76 ~49 ~37 planks  
fill ~52 ~50 ~33 ~59 ~50 ~33 nether_brick_stairs  
fill ~52 ~50 ~34 ~52 ~50 ~36 planks  
fill ~52 ~50 ~37 ~59 ~50 ~37 nether_brick_stairs 
setblock ~60 ~50 ~32 planks 1 
setblock ~60 ~50 ~33 planks 3 
setblock ~60 ~50 ~34 torch 3 
setblock ~60 ~50 ~36 torch 4 
setblock ~60 ~50 ~37 planks 3 
setblock ~60 ~50 ~38 planks 1 
setblock ~61 ~50 ~31 planks 3 
setblock ~61 ~50 ~39 planks 3 
setblock ~62 ~50 ~31 planks 1 
setblock ~62 ~50 ~39 planks 1 
setblock ~63 ~50 ~31 planks 3 
setblock ~63 ~50 ~39 planks 3 
setblock ~64 ~50 ~31 planks 1 
setblock ~64 ~50 ~39 planks 1 
setblock ~65 ~50 ~31 planks 3 
setblock ~65 ~50 ~39 planks 3 
setblock ~66 ~50 ~31 planks 1 
setblock ~66 ~50 ~39 planks 1 
setblock ~67 ~50 ~31 planks 3 
setblock ~67 ~50 ~39 planks 3 
setblock ~68 ~50 ~32 planks 3 
setblock ~68 ~50 ~33 planks 1 
setblock ~68 ~50 ~34 torch 3 
setblock ~68 ~50 ~36 torch 4 
setblock ~68 ~50 ~37 planks 1 
setblock ~68 ~50 ~38 planks 3  
fill ~69 ~50 ~33 ~76 ~50 ~33 nether_brick_stairs  
fill ~69 ~50 ~37 ~76 ~50 ~37 nether_brick_stairs  
fill ~76 ~50 ~34 ~76 ~50 ~36 planks  
fill ~52 ~51 ~34 ~59 ~51 ~34 nether_brick_stairs 
setblock ~52 ~51 ~35 planks 3  
fill ~52 ~51 ~36 ~59 ~51 ~36 nether_brick_stairs 
setblock ~60 ~51 ~32 planks 3 
setblock ~60 ~51 ~33 planks 1 
setblock ~60 ~51 ~34 planks 3 
setblock ~60 ~51 ~36 planks 3 
setblock ~60 ~51 ~37 planks 1 
setblock ~60 ~51 ~38 planks 3 
setblock ~61 ~51 ~31 planks 1 
setblock ~61 ~51 ~39 planks 1 
setblock ~62 ~51 ~31 planks 3 
setblock ~62 ~51 ~39 planks 3 
setblock ~63 ~51 ~31 planks 1 
setblock ~63 ~51 ~39 planks 1 
setblock ~64 ~51 ~31 planks 3 
setblock ~64 ~51 ~39 planks 3 
setblock ~65 ~51 ~31 planks 1 
setblock ~65 ~51 ~39 planks 1 
setblock ~66 ~51 ~31 planks 3 
setblock ~66 ~51 ~39 planks 3 
setblock ~67 ~51 ~31 planks 1 
setblock ~67 ~51 ~39 planks 1 
setblock ~68 ~51 ~32 planks 1 
setblock ~68 ~51 ~33 planks 3 
setblock ~68 ~51 ~34 planks 1 
setblock ~68 ~51 ~36 planks 1 
setblock ~68 ~51 ~37 planks 3 
setblock ~68 ~51 ~38 planks 1  
fill ~69 ~51 ~34 ~76 ~51 ~34 nether_brick_stairs  
fill ~69 ~51 ~36 ~76 ~51 ~36 nether_brick_stairs 
setblock ~76 ~51 ~35 planks 3  
fill ~52 ~52 ~35 ~59 ~52 ~35 nether_brick 
setblock ~60 ~52 ~32 planks 1 
setblock ~60 ~52 ~33 planks 3 
setblock ~60 ~52 ~34 planks 1 
setblock ~60 ~52 ~35 glowstone 0 
setblock ~60 ~52 ~36 planks 1 
setblock ~60 ~52 ~37 planks 3 
setblock ~60 ~52 ~38 planks 1 
setblock ~61 ~52 ~31 planks 3 
setblock ~61 ~52 ~39 planks 3 
setblock ~62 ~52 ~31 planks 1 
setblock ~62 ~52 ~39 planks 1 
setblock ~63 ~52 ~31 planks 3 
setblock ~63 ~52 ~39 planks 3 
setblock ~64 ~52 ~31 planks 1 
setblock ~64 ~52 ~39 planks 1 
setblock ~65 ~52 ~31 planks 3 
setblock ~65 ~52 ~39 planks 3 
setblock ~66 ~52 ~31 planks 1 
setblock ~66 ~52 ~39 planks 1 
setblock ~67 ~52 ~31 planks 3 
setblock ~67 ~52 ~39 planks 3 
setblock ~68 ~52 ~32 planks 3 
setblock ~68 ~52 ~33 planks 1 
setblock ~68 ~52 ~34 planks 3 
setblock ~68 ~52 ~35 glowstone 0 
setblock ~68 ~52 ~36 planks 3 
setblock ~68 ~52 ~37 planks 1 
setblock ~68 ~52 ~38 planks 3  
fill ~69 ~52 ~35 ~76 ~52 ~35 nether_brick 
setblock ~51 ~53 ~35 nether_brick_stairs 4  
fill ~52 ~53 ~35 ~53 ~53 ~35 nether_brick 
setblock ~54 ~53 ~35 nether_brick_stairs 1 
setblock ~60 ~53 ~32 planks 3 
setblock ~60 ~53 ~33 planks 1 
setblock ~60 ~53 ~34 planks 3 
setblock ~60 ~53 ~35 planks 1 
setblock ~60 ~53 ~36 planks 3 
setblock ~60 ~53 ~37 planks 1 
setblock ~60 ~53 ~38 planks 3 
setblock ~61 ~53 ~31 planks 1 
setblock ~61 ~53 ~39 planks 1 
setblock ~62 ~53 ~31 planks 3 
setblock ~62 ~53 ~39 planks 3 
setblock ~63 ~53 ~31 planks 1 
setblock ~63 ~53 ~39 planks 1 
setblock ~64 ~53 ~31 planks 3 
