fill ~-4 ~0 ~-19 ~-2 ~0 ~-19 sea_lantern 0  
fill ~-3 ~0 ~-20 ~-3 ~119 ~-20 sea_lantern 0  
fill ~-3 ~0 ~-18 ~-3 ~119 ~-18 sea_lantern 0  
fill ~-4 ~1 ~-19 ~-2 ~1 ~-19 sea_lantern 0  
fill ~-4 ~2 ~-19 ~-2 ~2 ~-19 sea_lantern 0  
fill ~-4 ~3 ~-19 ~-2 ~3 ~-19 sea_lantern 0  
fill ~-4 ~4 ~-19 ~-2 ~4 ~-19 sea_lantern 0  
fill ~-4 ~5 ~-19 ~-2 ~5 ~-19 sea_lantern 0  
fill ~-4 ~6 ~-19 ~-2 ~6 ~-19 sea_lantern 0  
fill ~-4 ~7 ~-19 ~-2 ~7 ~-19 sea_lantern 0  
fill ~-4 ~8 ~-19 ~-2 ~8 ~-19 sea_lantern 0  
fill ~-4 ~9 ~-19 ~-2 ~9 ~-19 sea_lantern 0  
fill ~-4 ~10 ~-19 ~-2 ~10 ~-19 sea_lantern 0  
fill ~-4 ~11 ~-19 ~-2 ~11 ~-19 sea_lantern 0  
fill ~-4 ~12 ~-19 ~-2 ~12 ~-19 sea_lantern 0  
fill ~-4 ~13 ~-19 ~-2 ~13 ~-19 sea_lantern 0  
fill ~-4 ~14 ~-19 ~-2 ~14 ~-19 sea_lantern 0  
fill ~-4 ~15 ~-19 ~-2 ~15 ~-19 sea_lantern 0  
fill ~-4 ~16 ~-19 ~-2 ~16 ~-19 sea_lantern 0  
fill ~-4 ~17 ~-19 ~-2 ~17 ~-19 sea_lantern 0  
fill ~-4 ~18 ~-19 ~-2 ~18 ~-19 sea_lantern 0  
fill ~-4 ~19 ~-19 ~-2 ~19 ~-19 sea_lantern 0  
fill ~-4 ~20 ~-19 ~-2 ~20 ~-19 sea_lantern 0  
fill ~-4 ~21 ~-19 ~-2 ~21 ~-19 sea_lantern 0  
fill ~-4 ~22 ~-19 ~-2 ~22 ~-19 sea_lantern 0  
fill ~-4 ~23 ~-19 ~-2 ~23 ~-19 sea_lantern 0  
fill ~-4 ~24 ~-19 ~-2 ~24 ~-19 sea_lantern 0  
fill ~-4 ~25 ~-19 ~-2 ~25 ~-19 sea_lantern 0  
fill ~-4 ~26 ~-19 ~-2 ~26 ~-19 sea_lantern 0  
fill ~-4 ~27 ~-19 ~-2 ~27 ~-19 sea_lantern 0  
fill ~-4 ~28 ~-19 ~-2 ~28 ~-19 sea_lantern 0  
fill ~-4 ~29 ~-19 ~-2 ~29 ~-19 sea_lantern 0  
fill ~-4 ~30 ~-19 ~-2 ~30 ~-19 sea_lantern 0  
fill ~-4 ~31 ~-19 ~-2 ~31 ~-19 sea_lantern 0  
fill ~-4 ~32 ~-19 ~-2 ~32 ~-19 sea_lantern 0  
fill ~-4 ~33 ~-19 ~-2 ~33 ~-19 sea_lantern 0  
fill ~-4 ~34 ~-19 ~-2 ~34 ~-19 sea_lantern 0  
fill ~-4 ~35 ~-19 ~-2 ~35 ~-19 sea_lantern 0  
fill ~-4 ~36 ~-19 ~-2 ~36 ~-19 sea_lantern 0  
fill ~-4 ~37 ~-19 ~-2 ~37 ~-19 sea_lantern 0  
fill ~-4 ~38 ~-19 ~-2 ~38 ~-19 sea_lantern 0  
fill ~-4 ~39 ~-19 ~-2 ~39 ~-19 sea_lantern 0  
fill ~-4 ~40 ~-19 ~-2 ~40 ~-19 sea_lantern 0  
fill ~-4 ~41 ~-19 ~-2 ~41 ~-19 sea_lantern 0  
fill ~-4 ~42 ~-19 ~-2 ~42 ~-19 sea_lantern 0  
fill ~-4 ~43 ~-19 ~-2 ~43 ~-19 sea_lantern 0  
fill ~-4 ~44 ~-19 ~-2 ~44 ~-19 sea_lantern 0  
fill ~-4 ~45 ~-19 ~-2 ~45 ~-19 sea_lantern 0  
fill ~-4 ~46 ~-19 ~-2 ~46 ~-19 sea_lantern 0  
fill ~-4 ~47 ~-19 ~-2 ~47 ~-19 sea_lantern 0  
fill ~-4 ~48 ~-19 ~-2 ~48 ~-19 sea_lantern 0  
fill ~-4 ~49 ~-19 ~-2 ~49 ~-19 sea_lantern 0  
fill ~-4 ~50 ~-19 ~-2 ~50 ~-19 sea_lantern 0  
fill ~-4 ~51 ~-19 ~-2 ~51 ~-19 sea_lantern 0  
fill ~-4 ~52 ~-19 ~-2 ~52 ~-19 sea_lantern 0  
fill ~-4 ~53 ~-19 ~-2 ~53 ~-19 sea_lantern 0  
fill ~-4 ~54 ~-19 ~-2 ~54 ~-19 sea_lantern 0  
fill ~-4 ~55 ~-19 ~-2 ~55 ~-19 sea_lantern 0  
fill ~-4 ~56 ~-19 ~-2 ~56 ~-19 sea_lantern 0  
fill ~-4 ~57 ~-19 ~-2 ~57 ~-19 sea_lantern 0  
fill ~-4 ~58 ~-19 ~-2 ~58 ~-19 sea_lantern 0  
fill ~-4 ~59 ~-19 ~-2 ~59 ~-19 sea_lantern 0  
fill ~-4 ~60 ~-19 ~-2 ~60 ~-19 sea_lantern 0  
fill ~-4 ~61 ~-19 ~-2 ~61 ~-19 sea_lantern 0  
fill ~-4 ~62 ~-19 ~-2 ~62 ~-19 sea_lantern 0  
fill ~-4 ~63 ~-19 ~-2 ~63 ~-19 sea_lantern 0  
fill ~-4 ~64 ~-19 ~-2 ~64 ~-19 sea_lantern 0  
fill ~-4 ~65 ~-19 ~-2 ~65 ~-19 sea_lantern 0  
fill ~-4 ~66 ~-19 ~-2 ~66 ~-19 sea_lantern 0  
fill ~-4 ~67 ~-19 ~-2 ~67 ~-19 sea_lantern 0  
fill ~-4 ~68 ~-19 ~-2 ~68 ~-19 sea_lantern 0  
fill ~-4 ~69 ~-19 ~-2 ~69 ~-19 sea_lantern 0  
fill ~-7 ~70 ~-19 ~1 ~70 ~-19 sea_lantern 0  
fill ~-6 ~70 ~-21 ~0 ~70 ~-21 sea_lantern 0  
fill ~-6 ~70 ~-20 ~0 ~70 ~-20 sea_lantern 0  
fill ~-6 ~70 ~-18 ~0 ~70 ~-18 sea_lantern 0  
fill ~-6 ~70 ~-17 ~0 ~70 ~-17 sea_lantern 0  
fill ~-5 ~70 ~-22 ~-1 ~70 ~-22 sea_lantern 0  
fill ~-5 ~70 ~-16 ~-1 ~70 ~-16 sea_lantern 0 
setblock ~-3 ~70 ~-23 sea_lantern 0 
setblock ~-3 ~70 ~-15 sea_lantern 0  
fill ~-4 ~71 ~-19 ~-2 ~71 ~-19 sea_lantern 0  
fill ~-4 ~72 ~-19 ~-2 ~72 ~-19 sea_lantern 0  
fill ~-4 ~73 ~-19 ~-2 ~73 ~-19 sea_lantern 0  
fill ~-4 ~74 ~-19 ~-2 ~74 ~-19 sea_lantern 0  
fill ~-12 ~75 ~-20 ~6 ~75 ~-20 sea_lantern 0  
fill ~-12 ~75 ~-19 ~6 ~75 ~-19 sea_lantern 0  
fill ~-12 ~75 ~-18 ~6 ~75 ~-18 sea_lantern 0  
fill ~-11 ~75 ~-23 ~5 ~75 ~-23 sea_lantern 0  
fill ~-11 ~75 ~-22 ~5 ~75 ~-22 sea_lantern 0  
fill ~-11 ~75 ~-21 ~5 ~75 ~-21 sea_lantern 0  
fill ~-11 ~75 ~-17 ~5 ~75 ~-17 sea_lantern 0  
fill ~-11 ~75 ~-16 ~5 ~75 ~-16 sea_lantern 0  
fill ~-11 ~75 ~-15 ~5 ~75 ~-15 sea_lantern 0  
fill ~-10 ~75 ~-24 ~4 ~75 ~-24 sea_lantern 0  
fill ~-10 ~75 ~-14 ~4 ~75 ~-14 sea_lantern 0  
fill ~-9 ~75 ~-25 ~3 ~75 ~-25 sea_lantern 0  
fill ~-9 ~75 ~-13 ~3 ~75 ~-13 sea_lantern 0  
fill ~-8 ~75 ~-26 ~2 ~75 ~-26 sea_lantern 0  
fill ~-8 ~75 ~-12 ~2 ~75 ~-12 sea_lantern 0  
fill ~-7 ~75 ~-27 ~1 ~75 ~-27 sea_lantern 0  
fill ~-7 ~75 ~-11 ~1 ~75 ~-11 sea_lantern 0  
fill ~-4 ~75 ~-28 ~-2 ~75 ~-28 sea_lantern 0  
fill ~-4 ~75 ~-10 ~-2 ~75 ~-10 sea_lantern 0  
fill ~-4 ~76 ~-19 ~-2 ~76 ~-19 sea_lantern 0  
fill ~-4 ~77 ~-19 ~-2 ~77 ~-19 sea_lantern 0  
fill ~-4 ~78 ~-19 ~-2 ~78 ~-19 sea_lantern 0  
fill ~-4 ~79 ~-19 ~-2 ~79 ~-19 sea_lantern 0  
fill ~-7 ~80 ~-21 ~1 ~80 ~-21 sea_lantern 0  
fill ~-7 ~80 ~-20 ~1 ~80 ~-20 sea_lantern 0  
fill ~-7 ~80 ~-19 ~1 ~80 ~-19 sea_lantern 0  
fill ~-7 ~80 ~-18 ~1 ~80 ~-18 sea_lantern 0  
fill ~-7 ~80 ~-17 ~1 ~80 ~-17 sea_lantern 0  
fill ~-6 ~80 ~-22 ~0 ~80 ~-22 sea_lantern 0  
fill ~-6 ~80 ~-16 ~0 ~80 ~-16 sea_lantern 0  
fill ~-5 ~80 ~-23 ~-1 ~80 ~-23 sea_lantern 0  
fill ~-5 ~80 ~-15 ~-1 ~80 ~-15 sea_lantern 0  
fill ~-7 ~81 ~-21 ~1 ~81 ~-21 sea_lantern 0  
fill ~-7 ~81 ~-20 ~1 ~81 ~-20 sea_lantern 0  
fill ~-7 ~81 ~-19 ~1 ~81 ~-19 sea_lantern 0  
fill ~-7 ~81 ~-18 ~1 ~81 ~-18 sea_lantern 0  
fill ~-7 ~81 ~-17 ~1 ~81 ~-17 sea_lantern 0  
fill ~-6 ~81 ~-22 ~0 ~81 ~-22 sea_lantern 0  
fill ~-6 ~81 ~-16 ~0 ~81 ~-16 sea_lantern 0  
fill ~-5 ~81 ~-23 ~-1 ~81 ~-23 sea_lantern 0  
fill ~-5 ~81 ~-15 ~-1 ~81 ~-15 sea_lantern 0  
fill ~-11 ~82 ~-20 ~5 ~82 ~-20 sea_lantern 0  
fill ~-11 ~82 ~-19 ~5 ~82 ~-19 sea_lantern 0  
fill ~-11 ~82 ~-18 ~5 ~82 ~-18 sea_lantern 0  
fill ~-10 ~82 ~-23 ~4 ~82 ~-23 sea_lantern 0  
fill ~-10 ~82 ~-22 ~4 ~82 ~-22 sea_lantern 0  
fill ~-10 ~82 ~-21 ~4 ~82 ~-21 sea_lantern 0  
fill ~-10 ~82 ~-17 ~4 ~82 ~-17 sea_lantern 0  
fill ~-10 ~82 ~-16 ~4 ~82 ~-16 sea_lantern 0  
fill ~-10 ~82 ~-15 ~4 ~82 ~-15 sea_lantern 0  
fill ~-9 ~82 ~-25 ~2 ~82 ~-25 sea_lantern 0  
fill ~-9 ~82 ~-24 ~2 ~82 ~-24 sea_lantern 0  
fill ~-9 ~82 ~-14 ~2 ~82 ~-14 sea_lantern 0  
fill ~-7 ~82 ~-26 ~1 ~82 ~-26 sea_lantern 0  
fill ~-7 ~82 ~-13 ~1 ~82 ~-13 sea_lantern 0  
fill ~-7 ~82 ~-12 ~1 ~82 ~-12 sea_lantern 0  
fill ~-4 ~82 ~-27 ~-2 ~82 ~-27 sea_lantern 0  
fill ~-4 ~82 ~-11 ~-2 ~82 ~-11 sea_lantern 0  
fill ~-12 ~83 ~-23 ~6 ~83 ~-23 sea_lantern 0  
fill ~-12 ~83 ~-22 ~6 ~83 ~-22 sea_lantern 0  
fill ~-12 ~83 ~-21 ~6 ~83 ~-21 sea_lantern 0  
fill ~-12 ~83 ~-20 ~6 ~83 ~-20 sea_lantern 0  
fill ~-12 ~83 ~-19 ~6 ~83 ~-19 sea_lantern 0  
fill ~-12 ~83 ~-18 ~6 ~83 ~-18 sea_lantern 0  
fill ~-12 ~83 ~-17 ~6 ~83 ~-17 sea_lantern 0  
fill ~-12 ~83 ~-16 ~6 ~83 ~-16 sea_lantern 0  
fill ~-12 ~83 ~-15 ~6 ~83 ~-15 sea_lantern 0  
fill ~-11 ~83 ~-25 ~5 ~83 ~-25 sea_lantern 0  
fill ~-11 ~83 ~-24 ~5 ~83 ~-24 sea_lantern 0  
fill ~-11 ~83 ~-14 ~5 ~83 ~-14 sea_lantern 0  
fill ~-10 ~83 ~-26 ~4 ~83 ~-26 sea_lantern 0  
fill ~-10 ~83 ~-13 ~4 ~83 ~-13 sea_lantern 0  
fill ~-10 ~83 ~-12 ~4 ~83 ~-12 sea_lantern 0  
fill ~-9 ~83 ~-27 ~2 ~83 ~-27 sea_lantern 0  
fill ~-9 ~83 ~-11 ~2 ~83 ~-11 sea_lantern 0  
fill ~-7 ~83 ~-28 ~1 ~83 ~-28 sea_lantern 0  
fill ~-7 ~83 ~-10 ~1 ~83 ~-10 sea_lantern 0  
fill ~-15 ~84 ~-21 ~8 ~84 ~-21 sea_lantern 0  
fill ~-15 ~84 ~-20 ~8 ~84 ~-20 sea_lantern 0  
fill ~-15 ~84 ~-19 ~8 ~84 ~-19 sea_lantern 0  
fill ~-15 ~84 ~-18 ~8 ~84 ~-18 sea_lantern 0  
fill ~-15 ~84 ~-17 ~8 ~84 ~-17 sea_lantern 0  
fill ~-13 ~84 ~-25 ~7 ~84 ~-25 sea_lantern 0  
fill ~-13 ~84 ~-24 ~7 ~84 ~-24 sea_lantern 0  
fill ~-13 ~84 ~-23 ~7 ~84 ~-23 sea_lantern 0  
fill ~-13 ~84 ~-22 ~7 ~84 ~-22 sea_lantern 0  
fill ~-13 ~84 ~-16 ~7 ~84 ~-16 sea_lantern 0  
fill ~-13 ~84 ~-15 ~7 ~84 ~-15 sea_lantern 0  
fill ~-13 ~84 ~-14 ~7 ~84 ~-14 sea_lantern 0  
fill ~-12 ~84 ~-26 ~6 ~84 ~-26 sea_lantern 0  
fill ~-12 ~84 ~-13 ~6 ~84 ~-13 sea_lantern 0  
fill ~-12 ~84 ~-12 ~6 ~84 ~-12 sea_lantern 0  
fill ~-11 ~84 ~-27 ~5 ~84 ~-27 sea_lantern 0  
fill ~-11 ~84 ~-11 ~5 ~84 ~-11 sea_lantern 0  
fill ~-10 ~84 ~-28 ~4 ~84 ~-28 sea_lantern 0  
fill ~-10 ~84 ~-10 ~4 ~84 ~-10 sea_lantern 0  
fill ~-9 ~84 ~-29 ~2 ~84 ~-29 sea_lantern 0  
fill ~-9 ~84 ~-9 ~2 ~84 ~-9 sea_lantern 0  
fill ~-5 ~84 ~-31 ~-1 ~84 ~-31 sea_lantern 0  
fill ~-5 ~84 ~-30 ~-1 ~84 ~-30 sea_lantern 0  
fill ~-5 ~84 ~-8 ~-1 ~84 ~-8 sea_lantern 0  
fill ~-16 ~85 ~-21 ~10 ~85 ~-21 sea_lantern 0  
fill ~-16 ~85 ~-20 ~10 ~85 ~-20 sea_lantern 0  
fill ~-16 ~85 ~-19 ~10 ~85 ~-19 sea_lantern 0  
fill ~-16 ~85 ~-18 ~10 ~85 ~-18 sea_lantern 0  
fill ~-16 ~85 ~-17 ~10 ~85 ~-17 sea_lantern 0  
fill ~-15 ~85 ~-25 ~8 ~85 ~-25 sea_lantern 0  
fill ~-15 ~85 ~-24 ~8 ~85 ~-24 sea_lantern 0  
fill ~-15 ~85 ~-23 ~8 ~85 ~-23 sea_lantern 0  
fill ~-15 ~85 ~-22 ~8 ~85 ~-22 sea_lantern 0  
fill ~-15 ~85 ~-16 ~8 ~85 ~-16 sea_lantern 0  
fill ~-15 ~85 ~-15 ~8 ~85 ~-15 sea_lantern 0  
fill ~-15 ~85 ~-14 ~8 ~85 ~-14 sea_lantern 0  
fill ~-13 ~85 ~-27 ~7 ~85 ~-27 sea_lantern 0  
fill ~-13 ~85 ~-26 ~7 ~85 ~-26 sea_lantern 0  
fill ~-13 ~85 ~-13 ~7 ~85 ~-13 sea_lantern 0  
fill ~-13 ~85 ~-12 ~7 ~85 ~-12 sea_lantern 0  
fill ~-13 ~85 ~-11 ~7 ~85 ~-11 sea_lantern 0  
fill ~-12 ~85 ~-28 ~6 ~85 ~-28 sea_lantern 0  
fill ~-12 ~85 ~-10 ~6 ~85 ~-10 sea_lantern 0  
fill ~-11 ~85 ~-29 ~5 ~85 ~-29 sea_lantern 0  
fill ~-11 ~85 ~-9 ~5 ~85 ~-9 sea_lantern 0  
fill ~-9 ~85 ~-31 ~2 ~85 ~-31 sea_lantern 0  
fill ~-9 ~85 ~-30 ~2 ~85 ~-30 sea_lantern 0  
fill ~-9 ~85 ~-8 ~2 ~85 ~-8 sea_lantern 0  
fill ~-5 ~85 ~-32 ~-1 ~85 ~-32 sea_lantern 0  
fill ~-5 ~85 ~-7 ~-1 ~85 ~-7 sea_lantern 0  
fill ~-5 ~85 ~-6 ~-1 ~85 ~-6 sea_lantern 0  
fill ~-17 ~86 ~-21 ~11 ~86 ~-21 sea_lantern 0  
fill ~-17 ~86 ~-20 ~11 ~86 ~-20 sea_lantern 0  
fill ~-17 ~86 ~-19 ~11 ~86 ~-19 sea_lantern 0  
fill ~-17 ~86 ~-18 ~11 ~86 ~-18 sea_lantern 0  
fill ~-17 ~86 ~-17 ~11 ~86 ~-17 sea_lantern 0  
fill ~-16 ~86 ~-25 ~10 ~86 ~-25 sea_lantern 0  
fill ~-16 ~86 ~-24 ~10 ~86 ~-24 sea_lantern 0  
fill ~-16 ~86 ~-23 ~10 ~86 ~-23 sea_lantern 0  
fill ~-16 ~86 ~-22 ~10 ~86 ~-22 sea_lantern 0  
fill ~-16 ~86 ~-16 ~10 ~86 ~-16 sea_lantern 0  
fill ~-16 ~86 ~-15 ~10 ~86 ~-15 sea_lantern 0  
fill ~-16 ~86 ~-14 ~10 ~86 ~-14 sea_lantern 0  
fill ~-15 ~86 ~-27 ~8 ~86 ~-27 sea_lantern 0  
fill ~-15 ~86 ~-26 ~8 ~86 ~-26 sea_lantern 0  
fill ~-15 ~86 ~-13 ~8 ~86 ~-13 sea_lantern 0  
fill ~-15 ~86 ~-12 ~8 ~86 ~-12 sea_lantern 0  
fill ~-15 ~86 ~-11 ~8 ~86 ~-11 sea_lantern 0  
fill ~-13 ~86 ~-28 ~7 ~86 ~-28 sea_lantern 0  
fill ~-13 ~86 ~-10 ~7 ~86 ~-10 sea_lantern 0  
fill ~-12 ~86 ~-29 ~6 ~86 ~-29 sea_lantern 0  
fill ~-12 ~86 ~-9 ~6 ~86 ~-9 sea_lantern 0  
fill ~-11 ~86 ~-31 ~5 ~86 ~-31 sea_lantern 0  
fill ~-11 ~86 ~-30 ~5 ~86 ~-30 sea_lantern 0  
fill ~-11 ~86 ~-8 ~5 ~86 ~-8 sea_lantern 0  
fill ~-9 ~86 ~-32 ~2 ~86 ~-32 sea_lantern 0  
fill ~-9 ~86 ~-7 ~2 ~86 ~-7 sea_lantern 0  
fill ~-9 ~86 ~-6 ~2 ~86 ~-6 sea_lantern 0  
fill ~-5 ~86 ~-33 ~-1 ~86 ~-33 sea_lantern 0  
fill ~-5 ~86 ~-5 ~-1 ~86 ~-5 sea_lantern 0  
fill ~-17 ~87 ~-21 ~11 ~87 ~-21 sea_lantern 0  
fill ~-17 ~87 ~-20 ~11 ~87 ~-20 sea_lantern 0  
fill ~-17 ~87 ~-19 ~11 ~87 ~-19 sea_lantern 0  
fill ~-17 ~87 ~-18 ~11 ~87 ~-18 sea_lantern 0  
fill ~-17 ~87 ~-17 ~11 ~87 ~-17 sea_lantern 0  
fill ~-16 ~87 ~-25 ~10 ~87 ~-25 sea_lantern 0  
fill ~-16 ~87 ~-24 ~10 ~87 ~-24 sea_lantern 0  
fill ~-16 ~87 ~-23 ~10 ~87 ~-23 sea_lantern 0  
fill ~-16 ~87 ~-22 ~10 ~87 ~-22 sea_lantern 0  
fill ~-16 ~87 ~-16 ~10 ~87 ~-16 sea_lantern 0  
fill ~-16 ~87 ~-15 ~10 ~87 ~-15 sea_lantern 0  
fill ~-16 ~87 ~-14 ~10 ~87 ~-14 sea_lantern 0  
fill ~-15 ~87 ~-27 ~8 ~87 ~-27 sea_lantern 0  
fill ~-15 ~87 ~-26 ~8 ~87 ~-26 sea_lantern 0  
fill ~-15 ~87 ~-13 ~8 ~87 ~-13 sea_lantern 0  
fill ~-15 ~87 ~-12 ~8 ~87 ~-12 sea_lantern 0  
fill ~-15 ~87 ~-11 ~8 ~87 ~-11 sea_lantern 0  
fill ~-13 ~87 ~-28 ~7 ~87 ~-28 sea_lantern 0  
fill ~-13 ~87 ~-10 ~7 ~87 ~-10 sea_lantern 0  
fill ~-12 ~87 ~-29 ~6 ~87 ~-29 sea_lantern 0  
fill ~-12 ~87 ~-9 ~6 ~87 ~-9 sea_lantern 0  
fill ~-11 ~87 ~-31 ~5 ~87 ~-31 sea_lantern 0  
fill ~-11 ~87 ~-30 ~5 ~87 ~-30 sea_lantern 0  
fill ~-11 ~87 ~-8 ~5 ~87 ~-8 sea_lantern 0  
fill ~-9 ~87 ~-32 ~2 ~87 ~-32 sea_lantern 0  
fill ~-9 ~87 ~-7 ~2 ~87 ~-7 sea_lantern 0  
fill ~-9 ~87 ~-6 ~2 ~87 ~-6 sea_lantern 0  
fill ~-5 ~87 ~-33 ~-1 ~87 ~-33 sea_lantern 0  
fill ~-5 ~87 ~-5 ~-1 ~87 ~-5 sea_lantern 0  
fill ~-17 ~88 ~-25 ~11 ~88 ~-25 sea_lantern 0  
fill ~-17 ~88 ~-24 ~11 ~88 ~-24 sea_lantern 0  
fill ~-17 ~88 ~-23 ~11 ~88 ~-23 sea_lantern 0  
fill ~-17 ~88 ~-22 ~11 ~88 ~-22 sea_lantern 0  
fill ~-17 ~88 ~-21 ~11 ~88 ~-21 sea_lantern 0  
fill ~-17 ~88 ~-20 ~11 ~88 ~-20 sea_lantern 0  
fill ~-17 ~88 ~-19 ~11 ~88 ~-19 sea_lantern 0  
fill ~-17 ~88 ~-18 ~11 ~88 ~-18 sea_lantern 0  
fill ~-17 ~88 ~-17 ~11 ~88 ~-17 sea_lantern 0  
fill ~-17 ~88 ~-16 ~11 ~88 ~-16 sea_lantern 0  
fill ~-17 ~88 ~-15 ~11 ~88 ~-15 sea_lantern 0  
fill ~-17 ~88 ~-14 ~11 ~88 ~-14 sea_lantern 0  
fill ~-16 ~88 ~-27 ~10 ~88 ~-27 sea_lantern 0  
fill ~-16 ~88 ~-26 ~10 ~88 ~-26 sea_lantern 0  
fill ~-16 ~88 ~-13 ~10 ~88 ~-13 sea_lantern 0  
fill ~-16 ~88 ~-12 ~10 ~88 ~-12 sea_lantern 0  
fill ~-16 ~88 ~-11 ~10 ~88 ~-11 sea_lantern 0  
fill ~-15 ~88 ~-28 ~8 ~88 ~-28 sea_lantern 0  
fill ~-15 ~88 ~-10 ~8 ~88 ~-10 sea_lantern 0  
fill ~-13 ~88 ~-29 ~7 ~88 ~-29 sea_lantern 0  
fill ~-13 ~88 ~-9 ~7 ~88 ~-9 sea_lantern 0  
fill ~-12 ~88 ~-31 ~6 ~88 ~-31 sea_lantern 0  
fill ~-12 ~88 ~-30 ~6 ~88 ~-30 sea_lantern 0  
fill ~-12 ~88 ~-8 ~6 ~88 ~-8 sea_lantern 0  
fill ~-11 ~88 ~-32 ~5 ~88 ~-32 sea_lantern 0  
fill ~-11 ~88 ~-7 ~5 ~88 ~-7 sea_lantern 0  
fill ~-11 ~88 ~-6 ~5 ~88 ~-6 sea_lantern 0  
fill ~-9 ~88 ~-33 ~2 ~88 ~-33 sea_lantern 0  
fill ~-9 ~88 ~-5 ~2 ~88 ~-5 sea_lantern 0  
fill ~-18 ~89 ~-23 ~12 ~89 ~-23 sea_lantern 0  
fill ~-18 ~89 ~-22 ~12 ~89 ~-22 sea_lantern 0  
fill ~-18 ~89 ~-21 ~12 ~89 ~-21 sea_lantern 0  
fill ~-18 ~89 ~-20 ~12 ~89 ~-20 sea_lantern 0  
fill ~-18 ~89 ~-19 ~12 ~89 ~-19 sea_lantern 0  
fill ~-18 ~89 ~-18 ~12 ~89 ~-18 sea_lantern 0  
fill ~-18 ~89 ~-17 ~12 ~89 ~-17 sea_lantern 0  
fill ~-18 ~89 ~-16 ~12 ~89 ~-16 sea_lantern 0  
fill ~-18 ~89 ~-15 ~12 ~89 ~-15 sea_lantern 0  
fill ~-17 ~89 ~-26 ~11 ~89 ~-26 sea_lantern 0  
fill ~-17 ~89 ~-25 ~11 ~89 ~-25 sea_lantern 0  
fill ~-17 ~89 ~-24 ~11 ~89 ~-24 sea_lantern 0  
fill ~-17 ~89 ~-14 ~11 ~89 ~-14 sea_lantern 0  
fill ~-17 ~89 ~-13 ~11 ~89 ~-13 sea_lantern 0  
fill ~-17 ~89 ~-12 ~11 ~89 ~-12 sea_lantern 0  
fill ~-16 ~89 ~-28 ~10 ~89 ~-28 sea_lantern 0  
fill ~-16 ~89 ~-27 ~10 ~89 ~-27 sea_lantern 0  
fill ~-16 ~89 ~-11 ~10 ~89 ~-11 sea_lantern 0  
fill ~-16 ~89 ~-10 ~10 ~89 ~-10 sea_lantern 0  
fill ~-15 ~89 ~-29 ~8 ~89 ~-29 sea_lantern 0  
fill ~-15 ~89 ~-9 ~8 ~89 ~-9 sea_lantern 0  
fill ~-13 ~89 ~-31 ~7 ~89 ~-31 sea_lantern 0  
fill ~-13 ~89 ~-30 ~7 ~89 ~-30 sea_lantern 0  
fill ~-13 ~89 ~-8 ~7 ~89 ~-8 sea_lantern 0  
fill ~-12 ~89 ~-32 ~6 ~89 ~-32 sea_lantern 0  
fill ~-12 ~89 ~-7 ~6 ~89 ~-7 sea_lantern 0  
fill ~-12 ~89 ~-6 ~6 ~89 ~-6 sea_lantern 0  
fill ~-10 ~89 ~-33 ~4 ~89 ~-33 sea_lantern 0  
fill ~-10 ~89 ~-5 ~4 ~89 ~-5 sea_lantern 0  
fill ~-7 ~89 ~-34 ~1 ~89 ~-34 sea_lantern 0  
fill ~-7 ~89 ~-4 ~1 ~89 ~-4 sea_lantern 0  
fill ~-19 ~90 ~-20 ~13 ~90 ~-20 sea_lantern 0  
fill ~-19 ~90 ~-19 ~13 ~90 ~-19 sea_lantern 0  
fill ~-19 ~90 ~-18 ~13 ~90 ~-18 sea_lantern 0  
fill ~-18 ~90 ~-25 ~12 ~90 ~-25 sea_lantern 0  
fill ~-18 ~90 ~-24 ~12 ~90 ~-24 sea_lantern 0  
fill ~-18 ~90 ~-23 ~12 ~90 ~-23 sea_lantern 0  
fill ~-18 ~90 ~-22 ~12 ~90 ~-22 sea_lantern 0  
fill ~-18 ~90 ~-21 ~12 ~90 ~-21 sea_lantern 0  
fill ~-18 ~90 ~-17 ~12 ~90 ~-17 sea_lantern 0  
fill ~-18 ~90 ~-16 ~12 ~90 ~-16 sea_lantern 0  
fill ~-18 ~90 ~-15 ~12 ~90 ~-15 sea_lantern 0  
fill ~-18 ~90 ~-14 ~12 ~90 ~-14 sea_lantern 0  
fill ~-17 ~90 ~-27 ~11 ~90 ~-27 sea_lantern 0  
fill ~-17 ~90 ~-26 ~11 ~90 ~-26 sea_lantern 0  
fill ~-17 ~90 ~-13 ~11 ~90 ~-13 sea_lantern 0  
fill ~-17 ~90 ~-12 ~11 ~90 ~-12 sea_lantern 0  
fill ~-17 ~90 ~-11 ~11 ~90 ~-11 sea_lantern 0  
fill ~-16 ~90 ~-29 ~10 ~90 ~-29 sea_lantern 0  
fill ~-16 ~90 ~-28 ~10 ~90 ~-28 sea_lantern 0  
fill ~-16 ~90 ~-10 ~10 ~90 ~-10 sea_lantern 0  
fill ~-16 ~90 ~-9 ~10 ~90 ~-9 sea_lantern 0  
fill ~-15 ~90 ~-31 ~8 ~90 ~-31 sea_lantern 0  
fill ~-15 ~90 ~-30 ~8 ~90 ~-30 sea_lantern 0  
fill ~-15 ~90 ~-8 ~8 ~90 ~-8 sea_lantern 0  
fill ~-13 ~90 ~-32 ~7 ~90 ~-32 sea_lantern 0  
fill ~-13 ~90 ~-7 ~7 ~90 ~-7 sea_lantern 0  
fill ~-13 ~90 ~-6 ~7 ~90 ~-6 sea_lantern 0  
fill ~-11 ~90 ~-33 ~5 ~90 ~-33 sea_lantern 0  
fill ~-11 ~90 ~-5 ~5 ~90 ~-5 sea_lantern 0  
fill ~-9 ~90 ~-34 ~2 ~90 ~-34 sea_lantern 0  
fill ~-9 ~90 ~-4 ~2 ~90 ~-4 sea_lantern 0  
fill ~-4 ~90 ~-35 ~-2 ~90 ~-35 sea_lantern 0  
fill ~-4 ~90 ~-3 ~-2 ~90 ~-3 sea_lantern 0  
fill ~-19 ~91 ~-23 ~13 ~91 ~-23 sea_lantern 0  
fill ~-19 ~91 ~-22 ~13 ~91 ~-22 sea_lantern 0  
fill ~-19 ~91 ~-21 ~13 ~91 ~-21 sea_lantern 0  
fill ~-19 ~91 ~-20 ~13 ~91 ~-20 sea_lantern 0  
fill ~-19 ~91 ~-19 ~13 ~91 ~-19 sea_lantern 0  
fill ~-19 ~91 ~-18 ~13 ~91 ~-18 sea_lantern 0  
fill ~-19 ~91 ~-17 ~13 ~91 ~-17 sea_lantern 0  
fill ~-19 ~91 ~-16 ~13 ~91 ~-16 sea_lantern 0  
fill ~-19 ~91 ~-15 ~13 ~91 ~-15 sea_lantern 0  
fill ~-18 ~91 ~-26 ~12 ~91 ~-26 sea_lantern 0  
fill ~-18 ~91 ~-25 ~12 ~91 ~-25 sea_lantern 0  
fill ~-18 ~91 ~-24 ~12 ~91 ~-24 sea_lantern 0  
fill ~-18 ~91 ~-14 ~12 ~91 ~-14 sea_lantern 0  
fill ~-18 ~91 ~-13 ~12 ~91 ~-13 sea_lantern 0  
fill ~-18 ~91 ~-12 ~12 ~91 ~-12 sea_lantern 0  
fill ~-17 ~91 ~-28 ~11 ~91 ~-28 sea_lantern 0  
fill ~-17 ~91 ~-27 ~11 ~91 ~-27 sea_lantern 0  
fill ~-17 ~91 ~-11 ~11 ~91 ~-11 sea_lantern 0  
fill ~-17 ~91 ~-10 ~11 ~91 ~-10 sea_lantern 0  
fill ~-16 ~91 ~-29 ~10 ~91 ~-29 sea_lantern 0  
fill ~-16 ~91 ~-9 ~10 ~91 ~-9 sea_lantern 0  
fill ~-15 ~91 ~-31 ~8 ~91 ~-31 sea_lantern 0  
fill ~-15 ~91 ~-30 ~8 ~91 ~-30 sea_lantern 0  
fill ~-15 ~91 ~-8 ~8 ~91 ~-8 sea_lantern 0  
fill ~-13 ~91 ~-32 ~7 ~91 ~-32 sea_lantern 0  
fill ~-13 ~91 ~-7 ~7 ~91 ~-7 sea_lantern 0  
fill ~-13 ~91 ~-6 ~7 ~91 ~-6 sea_lantern 0  
fill ~-12 ~91 ~-33 ~6 ~91 ~-33 sea_lantern 0  
fill ~-12 ~91 ~-5 ~6 ~91 ~-5 sea_lantern 0  
fill ~-10 ~91 ~-34 ~4 ~91 ~-34 sea_lantern 0  
fill ~-10 ~91 ~-4 ~4 ~91 ~-4 sea_lantern 0  
fill ~-7 ~91 ~-35 ~1 ~91 ~-35 sea_lantern 0  
fill ~-7 ~91 ~-3 ~1 ~91 ~-3 sea_lantern 0  
fill ~-19 ~92 ~-25 ~13 ~92 ~-25 sea_lantern 0  
fill ~-19 ~92 ~-24 ~13 ~92 ~-24 sea_lantern 0  
fill ~-19 ~92 ~-23 ~13 ~92 ~-23 sea_lantern 0  
fill ~-19 ~92 ~-22 ~13 ~92 ~-22 sea_lantern 0  
fill ~-19 ~92 ~-21 ~13 ~92 ~-21 sea_lantern 0  
fill ~-19 ~92 ~-20 ~13 ~92 ~-20 sea_lantern 0  
fill ~-19 ~92 ~-19 ~13 ~92 ~-19 sea_lantern 0  
fill ~-19 ~92 ~-18 ~13 ~92 ~-18 sea_lantern 0  
fill ~-19 ~92 ~-17 ~13 ~92 ~-17 sea_lantern 0  
fill ~-19 ~92 ~-16 ~13 ~92 ~-16 sea_lantern 0  
fill ~-19 ~92 ~-15 ~13 ~92 ~-15 sea_lantern 0  
fill ~-19 ~92 ~-14 ~13 ~92 ~-14 sea_lantern 0  
fill ~-18 ~92 ~-27 ~12 ~92 ~-27 sea_lantern 0  
fill ~-18 ~92 ~-26 ~12 ~92 ~-26 sea_lantern 0  
fill ~-18 ~92 ~-13 ~12 ~92 ~-13 sea_lantern 0  
fill ~-18 ~92 ~-12 ~12 ~92 ~-12 sea_lantern 0  
fill ~-18 ~92 ~-11 ~12 ~92 ~-11 sea_lantern 0  
fill ~-17 ~92 ~-29 ~11 ~92 ~-29 sea_lantern 0  
fill ~-17 ~92 ~-28 ~11 ~92 ~-28 sea_lantern 0  
fill ~-17 ~92 ~-10 ~11 ~92 ~-10 sea_lantern 0  
fill ~-17 ~92 ~-9 ~11 ~92 ~-9 sea_lantern 0  
fill ~-16 ~92 ~-31 ~10 ~92 ~-31 sea_lantern 0  
fill ~-16 ~92 ~-30 ~10 ~92 ~-30 sea_lantern 0  
fill ~-16 ~92 ~-8 ~10 ~92 ~-8 sea_lantern 0  
fill ~-15 ~92 ~-32 ~8 ~92 ~-32 sea_lantern 0  
fill ~-15 ~92 ~-7 ~8 ~92 ~-7 sea_lantern 0  
fill ~-15 ~92 ~-6 ~8 ~92 ~-6 sea_lantern 0  
fill ~-13 ~92 ~-33 ~7 ~92 ~-33 sea_lantern 0  
fill ~-13 ~92 ~-5 ~7 ~92 ~-5 sea_lantern 0  
fill ~-11 ~92 ~-34 ~5 ~92 ~-34 sea_lantern 0  
fill ~-11 ~92 ~-4 ~5 ~92 ~-4 sea_lantern 0  
fill ~-9 ~92 ~-35 ~2 ~92 ~-35 sea_lantern 0  
fill ~-9 ~92 ~-3 ~2 ~92 ~-3 sea_lantern 0  
fill ~-19 ~93 ~-25 ~13 ~93 ~-25 sea_lantern 0  
fill ~-19 ~93 ~-24 ~13 ~93 ~-24 sea_lantern 0  
fill ~-19 ~93 ~-23 ~13 ~93 ~-23 sea_lantern 0  
fill ~-19 ~93 ~-22 ~13 ~93 ~-22 sea_lantern 0  
fill ~-19 ~93 ~-21 ~13 ~93 ~-21 sea_lantern 0  
fill ~-19 ~93 ~-20 ~13 ~93 ~-20 sea_lantern 0  
fill ~-19 ~93 ~-19 ~13 ~93 ~-19 sea_lantern 0  
fill ~-19 ~93 ~-18 ~13 ~93 ~-18 sea_lantern 0  
fill ~-19 ~93 ~-17 ~13 ~93 ~-17 sea_lantern 0  
fill ~-19 ~93 ~-16 ~13 ~93 ~-16 sea_lantern 0  
fill ~-19 ~93 ~-15 ~13 ~93 ~-15 sea_lantern 0  
fill ~-19 ~93 ~-14 ~13 ~93 ~-14 sea_lantern 0  
fill ~-18 ~93 ~-27 ~12 ~93 ~-27 sea_lantern 0  
fill ~-18 ~93 ~-26 ~12 ~93 ~-26 sea_lantern 0  
fill ~-18 ~93 ~-13 ~12 ~93 ~-13 sea_lantern 0  
fill ~-18 ~93 ~-12 ~12 ~93 ~-12 sea_lantern 0  
fill ~-18 ~93 ~-11 ~12 ~93 ~-11 sea_lantern 0  
fill ~-17 ~93 ~-29 ~11 ~93 ~-29 sea_lantern 0  
fill ~-17 ~93 ~-28 ~11 ~93 ~-28 sea_lantern 0  
fill ~-17 ~93 ~-10 ~11 ~93 ~-10 sea_lantern 0  
fill ~-17 ~93 ~-9 ~11 ~93 ~-9 sea_lantern 0  
fill ~-16 ~93 ~-31 ~10 ~93 ~-31 sea_lantern 0  
fill ~-16 ~93 ~-30 ~10 ~93 ~-30 sea_lantern 0  
fill ~-16 ~93 ~-8 ~10 ~93 ~-8 sea_lantern 0  
fill ~-15 ~93 ~-32 ~8 ~93 ~-32 sea_lantern 0  
fill ~-15 ~93 ~-7 ~8 ~93 ~-7 sea_lantern 0  
fill ~-15 ~93 ~-6 ~8 ~93 ~-6 sea_lantern 0  
fill ~-13 ~93 ~-33 ~7 ~93 ~-33 sea_lantern 0  
fill ~-13 ~93 ~-5 ~7 ~93 ~-5 sea_lantern 0  
fill ~-11 ~93 ~-34 ~5 ~93 ~-34 sea_lantern 0  
fill ~-11 ~93 ~-4 ~5 ~93 ~-4 sea_lantern 0  
fill ~-9 ~93 ~-35 ~2 ~93 ~-35 sea_lantern 0  
fill ~-9 ~93 ~-3 ~2 ~93 ~-3 sea_lantern 0  
fill ~-21 ~94 ~-21 ~14 ~94 ~-21 sea_lantern 0  
fill ~-21 ~94 ~-20 ~14 ~94 ~-20 sea_lantern 0  
fill ~-21 ~94 ~-19 ~14 ~94 ~-19 sea_lantern 0  
fill ~-21 ~94 ~-18 ~14 ~94 ~-18 sea_lantern 0  
fill ~-21 ~94 ~-17 ~14 ~94 ~-17 sea_lantern 0  
fill ~-19 ~94 ~-26 ~13 ~94 ~-26 sea_lantern 0  
fill ~-19 ~94 ~-25 ~13 ~94 ~-25 sea_lantern 0  
fill ~-19 ~94 ~-24 ~13 ~94 ~-24 sea_lantern 0  
fill ~-19 ~94 ~-23 ~13 ~94 ~-23 sea_lantern 0  
fill ~-19 ~94 ~-22 ~13 ~94 ~-22 sea_lantern 0  
fill ~-19 ~94 ~-16 ~13 ~94 ~-16 sea_lantern 0  
fill ~-19 ~94 ~-15 ~13 ~94 ~-15 sea_lantern 0  
fill ~-19 ~94 ~-14 ~13 ~94 ~-14 sea_lantern 0  
fill ~-19 ~94 ~-13 ~13 ~94 ~-13 sea_lantern 0  
fill ~-19 ~94 ~-12 ~13 ~94 ~-12 sea_lantern 0  
fill ~-18 ~94 ~-28 ~12 ~94 ~-28 sea_lantern 0  
fill ~-18 ~94 ~-27 ~12 ~94 ~-27 sea_lantern 0  
fill ~-18 ~94 ~-11 ~12 ~94 ~-11 sea_lantern 0  
fill ~-18 ~94 ~-10 ~12 ~94 ~-10 sea_lantern 0  
fill ~-17 ~94 ~-29 ~11 ~94 ~-29 sea_lantern 0  
fill ~-17 ~94 ~-9 ~11 ~94 ~-9 sea_lantern 0  
fill ~-16 ~94 ~-31 ~10 ~94 ~-31 sea_lantern 0  
fill ~-16 ~94 ~-30 ~10 ~94 ~-30 sea_lantern 0  
fill ~-16 ~94 ~-8 ~10 ~94 ~-8 sea_lantern 0  
fill ~-15 ~94 ~-32 ~8 ~94 ~-32 sea_lantern 0  
fill ~-15 ~94 ~-7 ~8 ~94 ~-7 sea_lantern 0  
fill ~-15 ~94 ~-6 ~8 ~94 ~-6 sea_lantern 0  
fill ~-13 ~94 ~-33 ~7 ~94 ~-33 sea_lantern 0  
fill ~-13 ~94 ~-5 ~7 ~94 ~-5 sea_lantern 0  
fill ~-12 ~94 ~-34 ~6 ~94 ~-34 sea_lantern 0  
fill ~-12 ~94 ~-4 ~6 ~94 ~-4 sea_lantern 0  
fill ~-10 ~94 ~-35 ~4 ~94 ~-35 sea_lantern 0  
fill ~-10 ~94 ~-3 ~4 ~94 ~-3 sea_lantern 0  
fill ~-5 ~94 ~-37 ~-1 ~94 ~-37 sea_lantern 0  
fill ~-5 ~94 ~-36 ~-1 ~94 ~-36 sea_lantern 0  
fill ~-5 ~94 ~-2 ~-1 ~94 ~-2 sea_lantern 0  
fill ~-21 ~95 ~-22 ~14 ~95 ~-22 sea_lantern 0  
fill ~-21 ~95 ~-21 ~14 ~95 ~-21 sea_lantern 0  
fill ~-21 ~95 ~-20 ~14 ~95 ~-20 sea_lantern 0  
fill ~-21 ~95 ~-19 ~14 ~95 ~-19 sea_lantern 0  
fill ~-21 ~95 ~-18 ~14 ~95 ~-18 sea_lantern 0  
fill ~-21 ~95 ~-17 ~14 ~95 ~-17 sea_lantern 0  
fill ~-21 ~95 ~-16 ~14 ~95 ~-16 sea_lantern 0  
fill ~-19 ~95 ~-26 ~13 ~95 ~-26 sea_lantern 0  
fill ~-19 ~95 ~-25 ~13 ~95 ~-25 sea_lantern 0  
fill ~-19 ~95 ~-24 ~13 ~95 ~-24 sea_lantern 0  
fill ~-19 ~95 ~-23 ~13 ~95 ~-23 sea_lantern 0  
fill ~-19 ~95 ~-15 ~13 ~95 ~-15 sea_lantern 0  
fill ~-19 ~95 ~-14 ~13 ~95 ~-14 sea_lantern 0  
fill ~-19 ~95 ~-13 ~13 ~95 ~-13 sea_lantern 0  
fill ~-19 ~95 ~-12 ~13 ~95 ~-12 sea_lantern 0  
fill ~-18 ~95 ~-28 ~12 ~95 ~-28 sea_lantern 0  
fill ~-18 ~95 ~-27 ~12 ~95 ~-27 sea_lantern 0  
fill ~-18 ~95 ~-11 ~12 ~95 ~-11 sea_lantern 0  
fill ~-18 ~95 ~-10 ~12 ~95 ~-10 sea_lantern 0  
fill ~-17 ~95 ~-29 ~11 ~95 ~-29 sea_lantern 0  
fill ~-17 ~95 ~-9 ~11 ~95 ~-9 sea_lantern 0  
fill ~-16 ~95 ~-31 ~10 ~95 ~-31 sea_lantern 0  
fill ~-16 ~95 ~-30 ~10 ~95 ~-30 sea_lantern 0  
fill ~-16 ~95 ~-8 ~10 ~95 ~-8 sea_lantern 0  
fill ~-15 ~95 ~-32 ~8 ~95 ~-32 sea_lantern 0  
fill ~-15 ~95 ~-7 ~8 ~95 ~-7 sea_lantern 0  
fill ~-15 ~95 ~-6 ~8 ~95 ~-6 sea_lantern 0  
fill ~-13 ~95 ~-33 ~7 ~95 ~-33 sea_lantern 0  
fill ~-13 ~95 ~-5 ~7 ~95 ~-5 sea_lantern 0  
fill ~-12 ~95 ~-34 ~6 ~95 ~-34 sea_lantern 0  
fill ~-12 ~95 ~-4 ~6 ~95 ~-4 sea_lantern 0  
fill ~-10 ~95 ~-35 ~4 ~95 ~-35 sea_lantern 0  
fill ~-10 ~95 ~-3 ~4 ~95 ~-3 sea_lantern 0  
fill ~-6 ~95 ~-37 ~0 ~95 ~-37 sea_lantern 0  
fill ~-6 ~95 ~-36 ~0 ~95 ~-36 sea_lantern 0  
fill ~-6 ~95 ~-2 ~0 ~95 ~-2 sea_lantern 0  
fill ~-21 ~96 ~-23 ~14 ~96 ~-23 sea_lantern 0  
fill ~-21 ~96 ~-22 ~14 ~96 ~-22 sea_lantern 0  
fill ~-21 ~96 ~-21 ~14 ~96 ~-21 sea_lantern 0  
fill ~-21 ~96 ~-20 ~14 ~96 ~-20 sea_lantern 0  
fill ~-21 ~96 ~-19 ~14 ~96 ~-19 sea_lantern 0  
fill ~-21 ~96 ~-18 ~14 ~96 ~-18 sea_lantern 0  
fill ~-21 ~96 ~-17 ~14 ~96 ~-17 sea_lantern 0  
fill ~-21 ~96 ~-16 ~14 ~96 ~-16 sea_lantern 0  
fill ~-21 ~96 ~-15 ~14 ~96 ~-15 sea_lantern 0  
fill ~-19 ~96 ~-26 ~13 ~96 ~-26 sea_lantern 0  
fill ~-19 ~96 ~-25 ~13 ~96 ~-25 sea_lantern 0  
fill ~-19 ~96 ~-24 ~13 ~96 ~-24 sea_lantern 0  
fill ~-19 ~96 ~-14 ~13 ~96 ~-14 sea_lantern 0  
fill ~-19 ~96 ~-13 ~13 ~96 ~-13 sea_lantern 0  
fill ~-19 ~96 ~-12 ~13 ~96 ~-12 sea_lantern 0  
fill ~-18 ~96 ~-28 ~12 ~96 ~-28 sea_lantern 0  
fill ~-18 ~96 ~-27 ~12 ~96 ~-27 sea_lantern 0  
fill ~-18 ~96 ~-11 ~12 ~96 ~-11 sea_lantern 0  
fill ~-18 ~96 ~-10 ~12 ~96 ~-10 sea_lantern 0  
fill ~-17 ~96 ~-31 ~11 ~96 ~-31 sea_lantern 0  
fill ~-17 ~96 ~-30 ~11 ~96 ~-30 sea_lantern 0  
fill ~-17 ~96 ~-29 ~11 ~96 ~-29 sea_lantern 0  
fill ~-17 ~96 ~-9 ~11 ~96 ~-9 sea_lantern 0  
fill ~-17 ~96 ~-8 ~11 ~96 ~-8 sea_lantern 0  
fill ~-16 ~96 ~-32 ~10 ~96 ~-32 sea_lantern 0  
fill ~-16 ~96 ~-7 ~10 ~96 ~-7 sea_lantern 0  
fill ~-16 ~96 ~-6 ~10 ~96 ~-6 sea_lantern 0  
fill ~-15 ~96 ~-33 ~8 ~96 ~-33 sea_lantern 0  
fill ~-15 ~96 ~-5 ~8 ~96 ~-5 sea_lantern 0  
fill ~-12 ~96 ~-34 ~6 ~96 ~-34 sea_lantern 0  
fill ~-12 ~96 ~-4 ~6 ~96 ~-4 sea_lantern 0  
fill ~-10 ~96 ~-35 ~4 ~96 ~-35 sea_lantern 0  
fill ~-10 ~96 ~-3 ~4 ~96 ~-3 sea_lantern 0  
fill ~-7 ~96 ~-37 ~1 ~96 ~-37 sea_lantern 0  
fill ~-7 ~96 ~-36 ~1 ~96 ~-36 sea_lantern 0  
fill ~-7 ~96 ~-2 ~1 ~96 ~-2 sea_lantern 0  
fill ~-21 ~97 ~-23 ~14 ~97 ~-23 sea_lantern 0  
fill ~-21 ~97 ~-22 ~14 ~97 ~-22 sea_lantern 0  
fill ~-21 ~97 ~-21 ~14 ~97 ~-21 sea_lantern 0  
fill ~-21 ~97 ~-20 ~14 ~97 ~-20 sea_lantern 0  
fill ~-21 ~97 ~-19 ~14 ~97 ~-19 sea_lantern 0  
fill ~-21 ~97 ~-18 ~14 ~97 ~-18 sea_lantern 0  
fill ~-21 ~97 ~-17 ~14 ~97 ~-17 sea_lantern 0  
fill ~-21 ~97 ~-16 ~14 ~97 ~-16 sea_lantern 0  
fill ~-21 ~97 ~-15 ~14 ~97 ~-15 sea_lantern 0  
fill ~-19 ~97 ~-27 ~13 ~97 ~-27 sea_lantern 0  
fill ~-19 ~97 ~-26 ~13 ~97 ~-26 sea_lantern 0  
fill ~-19 ~97 ~-25 ~13 ~97 ~-25 sea_lantern 0  
fill ~-19 ~97 ~-24 ~13 ~97 ~-24 sea_lantern 0  
fill ~-19 ~97 ~-14 ~13 ~97 ~-14 sea_lantern 0  
fill ~-19 ~97 ~-13 ~13 ~97 ~-13 sea_lantern 0  
fill ~-19 ~97 ~-12 ~13 ~97 ~-12 sea_lantern 0  
fill ~-19 ~97 ~-11 ~13 ~97 ~-11 sea_lantern 0  
fill ~-18 ~97 ~-28 ~12 ~97 ~-28 sea_lantern 0  
fill ~-18 ~97 ~-10 ~12 ~97 ~-10 sea_lantern 0  
fill ~-17 ~97 ~-31 ~11 ~97 ~-31 sea_lantern 0  
fill ~-17 ~97 ~-30 ~11 ~97 ~-30 sea_lantern 0  
fill ~-17 ~97 ~-29 ~11 ~97 ~-29 sea_lantern 0  
fill ~-17 ~97 ~-9 ~11 ~97 ~-9 sea_lantern 0  
fill ~-17 ~97 ~-8 ~11 ~97 ~-8 sea_lantern 0  
fill ~-16 ~97 ~-32 ~10 ~97 ~-32 sea_lantern 0  
fill ~-16 ~97 ~-7 ~10 ~97 ~-7 sea_lantern 0  
fill ~-16 ~97 ~-6 ~10 ~97 ~-6 sea_lantern 0  
fill ~-15 ~97 ~-33 ~8 ~97 ~-33 sea_lantern 0  
fill ~-15 ~97 ~-5 ~8 ~97 ~-5 sea_lantern 0  
fill ~-12 ~97 ~-34 ~6 ~97 ~-34 sea_lantern 0  
fill ~-12 ~97 ~-4 ~6 ~97 ~-4 sea_lantern 0  
fill ~-11 ~97 ~-35 ~5 ~97 ~-35 sea_lantern 0  
fill ~-11 ~97 ~-3 ~5 ~97 ~-3 sea_lantern 0  
fill ~-7 ~97 ~-37 ~1 ~97 ~-37 sea_lantern 0  
fill ~-7 ~97 ~-36 ~1 ~97 ~-36 sea_lantern 0  
fill ~-7 ~97 ~-2 ~1 ~97 ~-2 sea_lantern 0  
fill ~-21 ~98 ~-23 ~14 ~98 ~-23 sea_lantern 0  
fill ~-21 ~98 ~-22 ~14 ~98 ~-22 sea_lantern 0  
fill ~-21 ~98 ~-21 ~14 ~98 ~-21 sea_lantern 0  
fill ~-21 ~98 ~-20 ~14 ~98 ~-20 sea_lantern 0  
fill ~-21 ~98 ~-19 ~14 ~98 ~-19 sea_lantern 0  
fill ~-21 ~98 ~-18 ~14 ~98 ~-18 sea_lantern 0  
fill ~-21 ~98 ~-17 ~14 ~98 ~-17 sea_lantern 0  
fill ~-21 ~98 ~-16 ~14 ~98 ~-16 sea_lantern 0  
fill ~-21 ~98 ~-15 ~14 ~98 ~-15 sea_lantern 0  
fill ~-19 ~98 ~-27 ~13 ~98 ~-27 sea_lantern 0  
fill ~-19 ~98 ~-26 ~13 ~98 ~-26 sea_lantern 0  
fill ~-19 ~98 ~-25 ~13 ~98 ~-25 sea_lantern 0  
fill ~-19 ~98 ~-24 ~13 ~98 ~-24 sea_lantern 0  
fill ~-19 ~98 ~-14 ~13 ~98 ~-14 sea_lantern 0  
fill ~-19 ~98 ~-13 ~13 ~98 ~-13 sea_lantern 0  
fill ~-19 ~98 ~-12 ~13 ~98 ~-12 sea_lantern 0  
fill ~-19 ~98 ~-11 ~13 ~98 ~-11 sea_lantern 0  
fill ~-18 ~98 ~-28 ~12 ~98 ~-28 sea_lantern 0  
fill ~-18 ~98 ~-10 ~12 ~98 ~-10 sea_lantern 0  
fill ~-17 ~98 ~-31 ~11 ~98 ~-31 sea_lantern 0  
fill ~-17 ~98 ~-30 ~11 ~98 ~-30 sea_lantern 0  
fill ~-17 ~98 ~-29 ~11 ~98 ~-29 sea_lantern 0  
fill ~-17 ~98 ~-9 ~11 ~98 ~-9 sea_lantern 0  
fill ~-17 ~98 ~-8 ~11 ~98 ~-8 sea_lantern 0  
fill ~-16 ~98 ~-32 ~10 ~98 ~-32 sea_lantern 0  
fill ~-16 ~98 ~-7 ~10 ~98 ~-7 sea_lantern 0  
fill ~-16 ~98 ~-6 ~10 ~98 ~-6 sea_lantern 0  
fill ~-15 ~98 ~-33 ~8 ~98 ~-33 sea_lantern 0  
fill ~-15 ~98 ~-5 ~8 ~98 ~-5 sea_lantern 0  
fill ~-12 ~98 ~-34 ~6 ~98 ~-34 sea_lantern 0  
fill ~-12 ~98 ~-4 ~6 ~98 ~-4 sea_lantern 0  
fill ~-11 ~98 ~-35 ~5 ~98 ~-35 sea_lantern 0  
fill ~-11 ~98 ~-3 ~5 ~98 ~-3 sea_lantern 0  
fill ~-7 ~98 ~-37 ~1 ~98 ~-37 sea_lantern 0  
fill ~-7 ~98 ~-36 ~1 ~98 ~-36 sea_lantern 0  
fill ~-7 ~98 ~-2 ~1 ~98 ~-2 sea_lantern 0  
fill ~-21 ~99 ~-23 ~14 ~99 ~-23 sea_lantern 0  
fill ~-21 ~99 ~-22 ~14 ~99 ~-22 sea_lantern 0  
fill ~-21 ~99 ~-21 ~14 ~99 ~-21 sea_lantern 0  
fill ~-21 ~99 ~-20 ~14 ~99 ~-20 sea_lantern 0  
fill ~-21 ~99 ~-19 ~14 ~99 ~-19 sea_lantern 0  
fill ~-21 ~99 ~-18 ~14 ~99 ~-18 sea_lantern 0  
fill ~-21 ~99 ~-17 ~14 ~99 ~-17 sea_lantern 0  
fill ~-21 ~99 ~-16 ~14 ~99 ~-16 sea_lantern 0  
fill ~-21 ~99 ~-15 ~14 ~99 ~-15 sea_lantern 0  
fill ~-19 ~99 ~-27 ~13 ~99 ~-27 sea_lantern 0  
fill ~-19 ~99 ~-26 ~13 ~99 ~-26 sea_lantern 0  
fill ~-19 ~99 ~-25 ~13 ~99 ~-25 sea_lantern 0  
fill ~-19 ~99 ~-24 ~13 ~99 ~-24 sea_lantern 0  
fill ~-19 ~99 ~-14 ~13 ~99 ~-14 sea_lantern 0  
fill ~-19 ~99 ~-13 ~13 ~99 ~-13 sea_lantern 0  
fill ~-19 ~99 ~-12 ~13 ~99 ~-12 sea_lantern 0  
fill ~-19 ~99 ~-11 ~13 ~99 ~-11 sea_lantern 0  
fill ~-18 ~99 ~-28 ~12 ~99 ~-28 sea_lantern 0  
fill ~-18 ~99 ~-10 ~12 ~99 ~-10 sea_lantern 0  
fill ~-17 ~99 ~-31 ~11 ~99 ~-31 sea_lantern 0  
fill ~-17 ~99 ~-30 ~11 ~99 ~-30 sea_lantern 0  
fill ~-17 ~99 ~-29 ~11 ~99 ~-29 sea_lantern 0  
fill ~-17 ~99 ~-9 ~11 ~99 ~-9 sea_lantern 0  
fill ~-17 ~99 ~-8 ~11 ~99 ~-8 sea_lantern 0  
fill ~-16 ~99 ~-32 ~10 ~99 ~-32 sea_lantern 0  
fill ~-16 ~99 ~-7 ~10 ~99 ~-7 sea_lantern 0  
fill ~-16 ~99 ~-6 ~10 ~99 ~-6 sea_lantern 0  
fill ~-15 ~99 ~-33 ~8 ~99 ~-33 sea_lantern 0  
fill ~-15 ~99 ~-5 ~8 ~99 ~-5 sea_lantern 0  
fill ~-12 ~99 ~-34 ~6 ~99 ~-34 sea_lantern 0  
fill ~-12 ~99 ~-4 ~6 ~99 ~-4 sea_lantern 0  
fill ~-11 ~99 ~-35 ~5 ~99 ~-35 sea_lantern 0  
fill ~-11 ~99 ~-3 ~5 ~99 ~-3 sea_lantern 0    
fill ~-7 ~99 ~-37 ~1 ~99 ~-37 sea_lantern 0  
fill ~-7 ~99 ~-36 ~1 ~99 ~-36 sea_lantern 0  
fill ~-7 ~99 ~-2 ~1 ~99 ~-2 sea_lantern 0  
fill ~-21 ~100 ~-23 ~14 ~100 ~-23 sea_lantern 0  
fill ~-21 ~100 ~-22 ~14 ~100 ~-22 sea_lantern 0  
fill ~-21 ~100 ~-21 ~14 ~100 ~-21 sea_lantern 0  
fill ~-21 ~100 ~-20 ~14 ~100 ~-20 sea_lantern 0  
fill ~-21 ~100 ~-19 ~14 ~100 ~-19 sea_lantern 0  
fill ~-21 ~100 ~-18 ~14 ~100 ~-18 sea_lantern 0  
fill ~-21 ~100 ~-17 ~14 ~100 ~-17 sea_lantern 0  
fill ~-21 ~100 ~-16 ~14 ~100 ~-16 sea_lantern 0  
fill ~-21 ~100 ~-15 ~14 ~100 ~-15 sea_lantern 0  
fill ~-19 ~100 ~-26 ~13 ~100 ~-26 sea_lantern 0  
fill ~-19 ~100 ~-25 ~13 ~100 ~-25 sea_lantern 0  
fill ~-19 ~100 ~-24 ~13 ~100 ~-24 sea_lantern 0  
fill ~-19 ~100 ~-14 ~13 ~100 ~-14 sea_lantern 0  
fill ~-19 ~100 ~-13 ~13 ~100 ~-13 sea_lantern 0  
fill ~-19 ~100 ~-12 ~13 ~100 ~-12 sea_lantern 0  
fill ~-18 ~100 ~-28 ~12 ~100 ~-28 sea_lantern 0  
fill ~-18 ~100 ~-27 ~12 ~100 ~-27 sea_lantern 0  
fill ~-18 ~100 ~-11 ~12 ~100 ~-11 sea_lantern 0  
fill ~-18 ~100 ~-10 ~12 ~100 ~-10 sea_lantern 0  
fill ~-17 ~100 ~-31 ~11 ~100 ~-31 sea_lantern 0  
fill ~-17 ~100 ~-30 ~11 ~100 ~-30 sea_lantern 0  
fill ~-17 ~100 ~-29 ~11 ~100 ~-29 sea_lantern 0  
fill ~-17 ~100 ~-9 ~11 ~100 ~-9 sea_lantern 0  
fill ~-17 ~100 ~-8 ~11 ~100 ~-8 sea_lantern 0  
fill ~-16 ~100 ~-32 ~10 ~100 ~-32 sea_lantern 0  
fill ~-16 ~100 ~-7 ~10 ~100 ~-7 sea_lantern 0  
fill ~-16 ~100 ~-6 ~10 ~100 ~-6 sea_lantern 0  
fill ~-15 ~100 ~-33 ~8 ~100 ~-33 sea_lantern 0  
fill ~-15 ~100 ~-5 ~8 ~100 ~-5 sea_lantern 0  
fill ~-12 ~100 ~-34 ~6 ~100 ~-34 sea_lantern 0  
fill ~-12 ~100 ~-4 ~6 ~100 ~-4 sea_lantern 0  
fill ~-10 ~100 ~-35 ~4 ~100 ~-35 sea_lantern 0  
fill ~-10 ~100 ~-3 ~4 ~100 ~-3 sea_lantern 0  
fill ~-7 ~100 ~-37 ~1 ~100 ~-37 sea_lantern 0  
fill ~-7 ~100 ~-36 ~1 ~100 ~-36 sea_lantern 0  
fill ~-7 ~100 ~-2 ~1 ~100 ~-2 sea_lantern 0  
fill ~-21 ~101 ~-22 ~14 ~101 ~-22 sea_lantern 0  
fill ~-21 ~101 ~-21 ~14 ~101 ~-21 sea_lantern 0  
fill ~-21 ~101 ~-20 ~14 ~101 ~-20 sea_lantern 0  
fill ~-21 ~101 ~-19 ~14 ~101 ~-19 sea_lantern 0  
fill ~-21 ~101 ~-18 ~14 ~101 ~-18 sea_lantern 0  
fill ~-21 ~101 ~-17 ~14 ~101 ~-17 sea_lantern 0  
fill ~-21 ~101 ~-16 ~14 ~101 ~-16 sea_lantern 0  
fill ~-19 ~101 ~-26 ~13 ~101 ~-26 sea_lantern 0  
fill ~-19 ~101 ~-25 ~13 ~101 ~-25 sea_lantern 0  
fill ~-19 ~101 ~-24 ~13 ~101 ~-24 sea_lantern 0  
fill ~-19 ~101 ~-23 ~13 ~101 ~-23 sea_lantern 0  
fill ~-19 ~101 ~-15 ~13 ~101 ~-15 sea_lantern 0  
fill ~-19 ~101 ~-14 ~13 ~101 ~-14 sea_lantern 0  
fill ~-19 ~101 ~-13 ~13 ~101 ~-13 sea_lantern 0  
fill ~-19 ~101 ~-12 ~13 ~101 ~-12 sea_lantern 0  
fill ~-18 ~101 ~-28 ~12 ~101 ~-28 sea_lantern 0  
fill ~-18 ~101 ~-27 ~12 ~101 ~-27 sea_lantern 0  
fill ~-18 ~101 ~-11 ~12 ~101 ~-11 sea_lantern 0  
fill ~-18 ~101 ~-10 ~12 ~101 ~-10 sea_lantern 0  
fill ~-17 ~101 ~-29 ~11 ~101 ~-29 sea_lantern 0  
fill ~-17 ~101 ~-9 ~11 ~101 ~-9 sea_lantern 0  
fill ~-16 ~101 ~-31 ~10 ~101 ~-31 sea_lantern 0  
fill ~-16 ~101 ~-30 ~10 ~101 ~-30 sea_lantern 0  
fill ~-16 ~101 ~-8 ~10 ~101 ~-8 sea_lantern 0  
fill ~-15 ~101 ~-32 ~8 ~101 ~-32 sea_lantern 0  
fill ~-15 ~101 ~-7 ~8 ~101 ~-7 sea_lantern 0  
fill ~-15 ~101 ~-6 ~8 ~101 ~-6 sea_lantern 0  
fill ~-13 ~101 ~-33 ~7 ~101 ~-33 sea_lantern 0  
fill ~-13 ~101 ~-5 ~7 ~101 ~-5 sea_lantern 0  
fill ~-12 ~101 ~-34 ~6 ~101 ~-34 sea_lantern 0  
fill ~-12 ~101 ~-4 ~6 ~101 ~-4 sea_lantern 0  
fill ~-10 ~101 ~-35 ~4 ~101 ~-35 sea_lantern 0  
fill ~-10 ~101 ~-3 ~4 ~101 ~-3 sea_lantern 0  
fill ~-6 ~101 ~-37 ~0 ~101 ~-37 sea_lantern 0  
fill ~-6 ~101 ~-36 ~0 ~101 ~-36 sea_lantern 0  
fill ~-6 ~101 ~-2 ~0 ~101 ~-2 sea_lantern 0  
fill ~-21 ~102 ~-21 ~14 ~102 ~-21 sea_lantern 0  
fill ~-21 ~102 ~-20 ~14 ~102 ~-20 sea_lantern 0  
fill ~-21 ~102 ~-19 ~14 ~102 ~-19 sea_lantern 0  
fill ~-21 ~102 ~-18 ~14 ~102 ~-18 sea_lantern 0  
fill ~-21 ~102 ~-17 ~14 ~102 ~-17 sea_lantern 0  
fill ~-19 ~102 ~-26 ~13 ~102 ~-26 sea_lantern 0  
fill ~-19 ~102 ~-25 ~13 ~102 ~-25 sea_lantern 0  
fill ~-19 ~102 ~-24 ~13 ~102 ~-24 sea_lantern 0  
fill ~-19 ~102 ~-23 ~13 ~102 ~-23 sea_lantern 0  
fill ~-19 ~102 ~-22 ~13 ~102 ~-22 sea_lantern 0  
fill ~-19 ~102 ~-16 ~13 ~102 ~-16 sea_lantern 0  
fill ~-19 ~102 ~-15 ~13 ~102 ~-15 sea_lantern 0  
fill ~-19 ~102 ~-14 ~13 ~102 ~-14 sea_lantern 0  
fill ~-19 ~102 ~-13 ~13 ~102 ~-13 sea_lantern 0  
fill ~-19 ~102 ~-12 ~13 ~102 ~-12 sea_lantern 0  
fill ~-18 ~102 ~-28 ~12 ~102 ~-28 sea_lantern 0  
fill ~-18 ~102 ~-27 ~12 ~102 ~-27 sea_lantern 0  
fill ~-18 ~102 ~-11 ~12 ~102 ~-11 sea_lantern 0  
fill ~-18 ~102 ~-10 ~12 ~102 ~-10 sea_lantern 0  
fill ~-17 ~102 ~-29 ~11 ~102 ~-29 sea_lantern 0  
fill ~-17 ~102 ~-9 ~11 ~102 ~-9 sea_lantern 0  
fill ~-16 ~102 ~-31 ~10 ~102 ~-31 sea_lantern 0  
fill ~-16 ~102 ~-30 ~10 ~102 ~-30 sea_lantern 0  
fill ~-16 ~102 ~-8 ~10 ~102 ~-8 sea_lantern 0  
fill ~-15 ~102 ~-32 ~8 ~102 ~-32 sea_lantern 0  
fill ~-15 ~102 ~-7 ~8 ~102 ~-7 sea_lantern 0  
fill ~-15 ~102 ~-6 ~8 ~102 ~-6 sea_lantern 0  
fill ~-13 ~102 ~-33 ~7 ~102 ~-33 sea_lantern 0  
fill ~-13 ~102 ~-5 ~7 ~102 ~-5 sea_lantern 0  
fill ~-12 ~102 ~-34 ~6 ~102 ~-34 sea_lantern 0  
fill ~-12 ~102 ~-4 ~6 ~102 ~-4 sea_lantern 0  
fill ~-10 ~102 ~-35 ~4 ~102 ~-35 sea_lantern 0  
fill ~-10 ~102 ~-3 ~4 ~102 ~-3 sea_lantern 0  
fill ~-5 ~102 ~-37 ~-1 ~102 ~-37 sea_lantern 0  
fill ~-5 ~102 ~-36 ~-1 ~102 ~-36 sea_lantern 0  
fill ~-5 ~102 ~-2 ~-1 ~102 ~-2 sea_lantern 0  
fill ~-19 ~103 ~-25 ~13 ~103 ~-25 sea_lantern 0  
fill ~-19 ~103 ~-24 ~13 ~103 ~-24 sea_lantern 0  
fill ~-19 ~103 ~-23 ~13 ~103 ~-23 sea_lantern 0  
fill ~-19 ~103 ~-22 ~13 ~103 ~-22 sea_lantern 0  
fill ~-19 ~103 ~-21 ~13 ~103 ~-21 sea_lantern 0  
fill ~-19 ~103 ~-20 ~13 ~103 ~-20 sea_lantern 0  
fill ~-19 ~103 ~-19 ~13 ~103 ~-19 sea_lantern 0  
fill ~-19 ~103 ~-18 ~13 ~103 ~-18 sea_lantern 0  
fill ~-19 ~103 ~-17 ~13 ~103 ~-17 sea_lantern 0  
fill ~-19 ~103 ~-16 ~13 ~103 ~-16 sea_lantern 0  
fill ~-19 ~103 ~-15 ~13 ~103 ~-15 sea_lantern 0  
fill ~-19 ~103 ~-14 ~13 ~103 ~-14 sea_lantern 0  
fill ~-18 ~103 ~-27 ~12 ~103 ~-27 sea_lantern 0  
fill ~-18 ~103 ~-26 ~12 ~103 ~-26 sea_lantern 0  
fill ~-18 ~103 ~-13 ~12 ~103 ~-13 sea_lantern 0  
fill ~-18 ~103 ~-12 ~12 ~103 ~-12 sea_lantern 0  
fill ~-18 ~103 ~-11 ~12 ~103 ~-11 sea_lantern 0  
fill ~-17 ~103 ~-29 ~11 ~103 ~-29 sea_lantern 0  
fill ~-17 ~103 ~-28 ~11 ~103 ~-28 sea_lantern 0  
fill ~-17 ~103 ~-10 ~11 ~103 ~-10 sea_lantern 0  
fill ~-17 ~103 ~-9 ~11 ~103 ~-9 sea_lantern 0  
fill ~-16 ~103 ~-31 ~10 ~103 ~-31 sea_lantern 0  
fill ~-16 ~103 ~-30 ~10 ~103 ~-30 sea_lantern 0  
fill ~-16 ~103 ~-8 ~10 ~103 ~-8 sea_lantern 0  
fill ~-15 ~103 ~-32 ~8 ~103 ~-32 sea_lantern 0  
fill ~-15 ~103 ~-7 ~8 ~103 ~-7 sea_lantern 0  
fill ~-15 ~103 ~-6 ~8 ~103 ~-6 sea_lantern 0  
fill ~-13 ~103 ~-33 ~7 ~103 ~-33 sea_lantern 0  
fill ~-13 ~103 ~-5 ~7 ~103 ~-5 sea_lantern 0  
fill ~-11 ~103 ~-34 ~5 ~103 ~-34 sea_lantern 0  
fill ~-11 ~103 ~-4 ~5 ~103 ~-4 sea_lantern 0  
fill ~-9 ~103 ~-35 ~2 ~103 ~-35 sea_lantern 0  
fill ~-9 ~103 ~-3 ~2 ~103 ~-3 sea_lantern 0  
fill ~-19 ~104 ~-23 ~13 ~104 ~-23 sea_lantern 0  
fill ~-19 ~104 ~-22 ~13 ~104 ~-22 sea_lantern 0  
fill ~-19 ~104 ~-21 ~13 ~104 ~-21 sea_lantern 0  
fill ~-19 ~104 ~-20 ~13 ~104 ~-20 sea_lantern 0  
fill ~-19 ~104 ~-19 ~13 ~104 ~-19 sea_lantern 0  
fill ~-19 ~104 ~-18 ~13 ~104 ~-18 sea_lantern 0  
fill ~-19 ~104 ~-17 ~13 ~104 ~-17 sea_lantern 0  
fill ~-19 ~104 ~-16 ~13 ~104 ~-16 sea_lantern 0  
fill ~-19 ~104 ~-15 ~13 ~104 ~-15 sea_lantern 0  
fill ~-18 ~104 ~-26 ~12 ~104 ~-26 sea_lantern 0  
fill ~-18 ~104 ~-25 ~12 ~104 ~-25 sea_lantern 0  
fill ~-18 ~104 ~-24 ~12 ~104 ~-24 sea_lantern 0  
fill ~-18 ~104 ~-14 ~12 ~104 ~-14 sea_lantern 0  
fill ~-18 ~104 ~-13 ~12 ~104 ~-13 sea_lantern 0  
fill ~-18 ~104 ~-12 ~12 ~104 ~-12 sea_lantern 0  
fill ~-17 ~104 ~-28 ~11 ~104 ~-28 sea_lantern 0  
fill ~-17 ~104 ~-27 ~11 ~104 ~-27 sea_lantern 0  
fill ~-17 ~104 ~-11 ~11 ~104 ~-11 sea_lantern 0  
fill ~-17 ~104 ~-10 ~11 ~104 ~-10 sea_lantern 0  
fill ~-16 ~104 ~-29 ~10 ~104 ~-29 sea_lantern 0  
fill ~-16 ~104 ~-9 ~10 ~104 ~-9 sea_lantern 0  
fill ~-15 ~104 ~-31 ~8 ~104 ~-31 sea_lantern 0  
fill ~-15 ~104 ~-30 ~8 ~104 ~-30 sea_lantern 0  
fill ~-15 ~104 ~-8 ~8 ~104 ~-8 sea_lantern 0  
fill ~-13 ~104 ~-32 ~7 ~104 ~-32 sea_lantern 0  
fill ~-13 ~104 ~-7 ~7 ~104 ~-7 sea_lantern 0  
fill ~-13 ~104 ~-6 ~7 ~104 ~-6 sea_lantern 0  
fill ~-12 ~104 ~-33 ~6 ~104 ~-33 sea_lantern 0  
fill ~-12 ~104 ~-5 ~6 ~104 ~-5 sea_lantern 0  
fill ~-10 ~104 ~-34 ~4 ~104 ~-34 sea_lantern 0  
fill ~-10 ~104 ~-4 ~4 ~104 ~-4 sea_lantern 0  
fill ~-7 ~104 ~-35 ~1 ~104 ~-35 sea_lantern 0  
fill ~-7 ~104 ~-3 ~1 ~104 ~-3 sea_lantern 0  
fill ~-19 ~105 ~-23 ~13 ~105 ~-23 sea_lantern 0  
fill ~-19 ~105 ~-22 ~13 ~105 ~-22 sea_lantern 0  
fill ~-19 ~105 ~-21 ~13 ~105 ~-21 sea_lantern 0  
fill ~-19 ~105 ~-20 ~13 ~105 ~-20 sea_lantern 0  
fill ~-19 ~105 ~-19 ~13 ~105 ~-19 sea_lantern 0  
fill ~-19 ~105 ~-18 ~13 ~105 ~-18 sea_lantern 0  
fill ~-19 ~105 ~-17 ~13 ~105 ~-17 sea_lantern 0  
fill ~-19 ~105 ~-16 ~13 ~105 ~-16 sea_lantern 0  
fill ~-19 ~105 ~-15 ~13 ~105 ~-15 sea_lantern 0  
fill ~-18 ~105 ~-26 ~12 ~105 ~-26 sea_lantern 0  
fill ~-18 ~105 ~-25 ~12 ~105 ~-25 sea_lantern 0  
fill ~-18 ~105 ~-24 ~12 ~105 ~-24 sea_lantern 0  
fill ~-18 ~105 ~-14 ~12 ~105 ~-14 sea_lantern 0  
fill ~-18 ~105 ~-13 ~12 ~105 ~-13 sea_lantern 0  
fill ~-18 ~105 ~-12 ~12 ~105 ~-12 sea_lantern 0  
fill ~-17 ~105 ~-28 ~11 ~105 ~-28 sea_lantern 0  
fill ~-17 ~105 ~-27 ~11 ~105 ~-27 sea_lantern 0  
fill ~-17 ~105 ~-11 ~11 ~105 ~-11 sea_lantern 0  
fill ~-17 ~105 ~-10 ~11 ~105 ~-10 sea_lantern 0  
fill ~-16 ~105 ~-29 ~10 ~105 ~-29 sea_lantern 0  
fill ~-16 ~105 ~-9 ~10 ~105 ~-9 sea_lantern 0  
fill ~-15 ~105 ~-31 ~8 ~105 ~-31 sea_lantern 0  
fill ~-15 ~105 ~-30 ~8 ~105 ~-30 sea_lantern 0  
fill ~-15 ~105 ~-8 ~8 ~105 ~-8 sea_lantern 0  
fill ~-13 ~105 ~-32 ~7 ~105 ~-32 sea_lantern 0  
fill ~-13 ~105 ~-7 ~7 ~105 ~-7 sea_lantern 0  
fill ~-13 ~105 ~-6 ~7 ~105 ~-6 sea_lantern 0  
fill ~-12 ~105 ~-33 ~6 ~105 ~-33 sea_lantern 0  
fill ~-12 ~105 ~-5 ~6 ~105 ~-5 sea_lantern 0  
fill ~-10 ~105 ~-34 ~4 ~105 ~-34 sea_lantern 0  
fill ~-10 ~105 ~-4 ~4 ~105 ~-4 sea_lantern 0  
fill ~-7 ~105 ~-35 ~1 ~105 ~-35 sea_lantern 0  
fill ~-7 ~105 ~-3 ~1 ~105 ~-3 sea_lantern 0  
fill ~-19 ~106 ~-20 ~13 ~106 ~-20 sea_lantern 0  
fill ~-19 ~106 ~-19 ~13 ~106 ~-19 sea_lantern 0  
fill ~-19 ~106 ~-18 ~13 ~106 ~-18 sea_lantern 0  
fill ~-18 ~106 ~-25 ~12 ~106 ~-25 sea_lantern 0  
fill ~-18 ~106 ~-24 ~12 ~106 ~-24 sea_lantern 0  
fill ~-18 ~106 ~-23 ~12 ~106 ~-23 sea_lantern 0  
fill ~-18 ~106 ~-22 ~12 ~106 ~-22 sea_lantern 0  
fill ~-18 ~106 ~-21 ~12 ~106 ~-21 sea_lantern 0  
fill ~-18 ~106 ~-17 ~12 ~106 ~-17 sea_lantern 0  
fill ~-18 ~106 ~-16 ~12 ~106 ~-16 sea_lantern 0  
fill ~-18 ~106 ~-15 ~12 ~106 ~-15 sea_lantern 0  
fill ~-18 ~106 ~-14 ~12 ~106 ~-14 sea_lantern 0  
fill ~-17 ~106 ~-27 ~11 ~106 ~-27 sea_lantern 0  
fill ~-17 ~106 ~-26 ~11 ~106 ~-26 sea_lantern 0  
fill ~-17 ~106 ~-13 ~11 ~106 ~-13 sea_lantern 0  
fill ~-17 ~106 ~-12 ~11 ~106 ~-12 sea_lantern 0  
fill ~-17 ~106 ~-11 ~11 ~106 ~-11 sea_lantern 0  
fill ~-16 ~106 ~-29 ~10 ~106 ~-29 sea_lantern 0  
fill ~-16 ~106 ~-28 ~10 ~106 ~-28 sea_lantern 0  
fill ~-16 ~106 ~-10 ~10 ~106 ~-10 sea_lantern 0  
fill ~-16 ~106 ~-9 ~10 ~106 ~-9 sea_lantern 0  
fill ~-15 ~106 ~-31 ~8 ~106 ~-31 sea_lantern 0  
fill ~-15 ~106 ~-30 ~8 ~106 ~-30 sea_lantern 0  
fill ~-15 ~106 ~-8 ~8 ~106 ~-8 sea_lantern 0  
fill ~-13 ~106 ~-32 ~7 ~106 ~-32 sea_lantern 0  
fill ~-13 ~106 ~-7 ~7 ~106 ~-7 sea_lantern 0  
fill ~-13 ~106 ~-6 ~7 ~106 ~-6 sea_lantern 0  
fill ~-11 ~106 ~-33 ~5 ~106 ~-33 sea_lantern 0  
fill ~-11 ~106 ~-5 ~5 ~106 ~-5 sea_lantern 0  
fill ~-9 ~106 ~-34 ~2 ~106 ~-34 sea_lantern 0  
fill ~-9 ~106 ~-4 ~2 ~106 ~-4 sea_lantern 0  
fill ~-4 ~106 ~-35 ~-2 ~106 ~-35 sea_lantern 0  
fill ~-4 ~106 ~-3 ~-2 ~106 ~-3 sea_lantern 0  
fill ~-18 ~107 ~-23 ~12 ~107 ~-23 sea_lantern 0  
fill ~-18 ~107 ~-22 ~12 ~107 ~-22 sea_lantern 0  
fill ~-18 ~107 ~-21 ~12 ~107 ~-21 sea_lantern 0  
fill ~-18 ~107 ~-20 ~12 ~107 ~-20 sea_lantern 0  
fill ~-18 ~107 ~-19 ~12 ~107 ~-19 sea_lantern 0  
fill ~-18 ~107 ~-18 ~12 ~107 ~-18 sea_lantern 0  
fill ~-18 ~107 ~-17 ~12 ~107 ~-17 sea_lantern 0  
fill ~-18 ~107 ~-16 ~12 ~107 ~-16 sea_lantern 0  
fill ~-18 ~107 ~-15 ~12 ~107 ~-15 sea_lantern 0  
fill ~-17 ~107 ~-26 ~11 ~107 ~-26 sea_lantern 0  
fill ~-17 ~107 ~-25 ~11 ~107 ~-25 sea_lantern 0  
fill ~-17 ~107 ~-24 ~11 ~107 ~-24 sea_lantern 0  
fill ~-17 ~107 ~-14 ~11 ~107 ~-14 sea_lantern 0  
fill ~-17 ~107 ~-13 ~11 ~107 ~-13 sea_lantern 0  
fill ~-17 ~107 ~-12 ~11 ~107 ~-12 sea_lantern 0  
fill ~-16 ~107 ~-28 ~10 ~107 ~-28 sea_lantern 0  
fill ~-16 ~107 ~-27 ~10 ~107 ~-27 sea_lantern 0  
fill ~-16 ~107 ~-11 ~10 ~107 ~-11 sea_lantern 0  
fill ~-16 ~107 ~-10 ~10 ~107 ~-10 sea_lantern 0  
fill ~-15 ~107 ~-29 ~8 ~107 ~-29 sea_lantern 0  
fill ~-15 ~107 ~-9 ~8 ~107 ~-9 sea_lantern 0  
fill ~-13 ~107 ~-31 ~7 ~107 ~-31 sea_lantern 0  
fill ~-13 ~107 ~-30 ~7 ~107 ~-30 sea_lantern 0  
fill ~-13 ~107 ~-8 ~7 ~107 ~-8 sea_lantern 0  
fill ~-12 ~107 ~-32 ~6 ~107 ~-32 sea_lantern 0  
fill ~-12 ~107 ~-7 ~6 ~107 ~-7 sea_lantern 0  
fill ~-12 ~107 ~-6 ~6 ~107 ~-6 sea_lantern 0  
fill ~-10 ~107 ~-33 ~4 ~107 ~-33 sea_lantern 0  
fill ~-10 ~107 ~-5 ~4 ~107 ~-5 sea_lantern 0  
fill ~-7 ~107 ~-34 ~1 ~107 ~-34 sea_lantern 0  
fill ~-7 ~107 ~-4 ~1 ~107 ~-4 sea_lantern 0  
fill ~-17 ~108 ~-25 ~11 ~108 ~-25 sea_lantern 0  
fill ~-17 ~108 ~-24 ~11 ~108 ~-24 sea_lantern 0  
fill ~-17 ~108 ~-23 ~11 ~108 ~-23 sea_lantern 0  
fill ~-17 ~108 ~-22 ~11 ~108 ~-22 sea_lantern 0  
fill ~-17 ~108 ~-21 ~11 ~108 ~-21 sea_lantern 0  
fill ~-17 ~108 ~-20 ~11 ~108 ~-20 sea_lantern 0  
fill ~-17 ~108 ~-19 ~11 ~108 ~-19 sea_lantern 0  
fill ~-17 ~108 ~-18 ~11 ~108 ~-18 sea_lantern 0  
fill ~-17 ~108 ~-17 ~11 ~108 ~-17 sea_lantern 0  
fill ~-17 ~108 ~-16 ~11 ~108 ~-16 sea_lantern 0  
fill ~-17 ~108 ~-15 ~11 ~108 ~-15 sea_lantern 0  
fill ~-17 ~108 ~-14 ~11 ~108 ~-14 sea_lantern 0  
fill ~-16 ~108 ~-27 ~10 ~108 ~-27 sea_lantern 0  
fill ~-16 ~108 ~-26 ~10 ~108 ~-26 sea_lantern 0  
fill ~-16 ~108 ~-13 ~10 ~108 ~-13 sea_lantern 0  
fill ~-16 ~108 ~-12 ~10 ~108 ~-12 sea_lantern 0  
fill ~-16 ~108 ~-11 ~10 ~108 ~-11 sea_lantern 0  
fill ~-15 ~108 ~-28 ~8 ~108 ~-28 sea_lantern 0  
fill ~-15 ~108 ~-10 ~8 ~108 ~-10 sea_lantern 0  
fill ~-13 ~108 ~-29 ~7 ~108 ~-29 sea_lantern 0  
fill ~-13 ~108 ~-9 ~7 ~108 ~-9 sea_lantern 0  
fill ~-12 ~108 ~-31 ~6 ~108 ~-31 sea_lantern 0  
fill ~-12 ~108 ~-30 ~6 ~108 ~-30 sea_lantern 0  
fill ~-12 ~108 ~-8 ~6 ~108 ~-8 sea_lantern 0  
fill ~-11 ~108 ~-32 ~5 ~108 ~-32 sea_lantern 0  
fill ~-11 ~108 ~-7 ~5 ~108 ~-7 sea_lantern 0  
fill ~-11 ~108 ~-6 ~5 ~108 ~-6 sea_lantern 0  
fill ~-9 ~108 ~-33 ~2 ~108 ~-33 sea_lantern 0  
fill ~-9 ~108 ~-5 ~2 ~108 ~-5 sea_lantern 0  
fill ~-17 ~109 ~-21 ~11 ~109 ~-21 sea_lantern 0  
fill ~-17 ~109 ~-20 ~11 ~109 ~-20 sea_lantern 0  
fill ~-17 ~109 ~-19 ~11 ~109 ~-19 sea_lantern 0  
fill ~-17 ~109 ~-18 ~11 ~109 ~-18 sea_lantern 0  
fill ~-17 ~109 ~-17 ~11 ~109 ~-17 sea_lantern 0  
fill ~-16 ~109 ~-25 ~10 ~109 ~-25 sea_lantern 0  
fill ~-16 ~109 ~-24 ~10 ~109 ~-24 sea_lantern 0  
fill ~-16 ~109 ~-23 ~10 ~109 ~-23 sea_lantern 0  
fill ~-16 ~109 ~-22 ~10 ~109 ~-22 sea_lantern 0  
fill ~-16 ~109 ~-16 ~10 ~109 ~-16 sea_lantern 0  
fill ~-16 ~109 ~-15 ~10 ~109 ~-15 sea_lantern 0  
fill ~-16 ~109 ~-14 ~10 ~109 ~-14 sea_lantern 0  
fill ~-15 ~109 ~-27 ~8 ~109 ~-27 sea_lantern 0  
fill ~-15 ~109 ~-26 ~8 ~109 ~-26 sea_lantern 0  
fill ~-15 ~109 ~-13 ~8 ~109 ~-13 sea_lantern 0  
fill ~-15 ~109 ~-12 ~8 ~109 ~-12 sea_lantern 0  
fill ~-15 ~109 ~-11 ~8 ~109 ~-11 sea_lantern 0  
fill ~-13 ~109 ~-28 ~7 ~109 ~-28 sea_lantern 0  
fill ~-13 ~109 ~-10 ~7 ~109 ~-10 sea_lantern 0  
fill ~-12 ~109 ~-29 ~6 ~109 ~-29 sea_lantern 0  
fill ~-12 ~109 ~-9 ~6 ~109 ~-9 sea_lantern 0  
fill ~-11 ~109 ~-31 ~5 ~109 ~-31 sea_lantern 0  
fill ~-11 ~109 ~-30 ~5 ~109 ~-30 sea_lantern 0  
fill ~-11 ~109 ~-8 ~5 ~109 ~-8 sea_lantern 0  
fill ~-9 ~109 ~-32 ~2 ~109 ~-32 sea_lantern 0  
fill ~-9 ~109 ~-7 ~2 ~109 ~-7 sea_lantern 0  
fill ~-9 ~109 ~-6 ~2 ~109 ~-6 sea_lantern 0  
fill ~-5 ~109 ~-33 ~-1 ~109 ~-33 sea_lantern 0  
fill ~-5 ~109 ~-5 ~-1 ~109 ~-5 sea_lantern 0  
fill ~-16 ~110 ~-21 ~10 ~110 ~-21 sea_lantern 0  
fill ~-16 ~110 ~-20 ~10 ~110 ~-20 sea_lantern 0  
fill ~-16 ~110 ~-19 ~10 ~110 ~-19 sea_lantern 0  
fill ~-16 ~110 ~-18 ~10 ~110 ~-18 sea_lantern 0  
fill ~-16 ~110 ~-17 ~10 ~110 ~-17 sea_lantern 0  
fill ~-15 ~110 ~-25 ~8 ~110 ~-25 sea_lantern 0  
fill ~-15 ~110 ~-24 ~8 ~110 ~-24 sea_lantern 0  
fill ~-15 ~110 ~-23 ~8 ~110 ~-23 sea_lantern 0  
fill ~-15 ~110 ~-22 ~8 ~110 ~-22 sea_lantern 0  
fill ~-15 ~110 ~-16 ~8 ~110 ~-16 sea_lantern 0  
fill ~-15 ~110 ~-15 ~8 ~110 ~-15 sea_lantern 0  
fill ~-15 ~110 ~-14 ~8 ~110 ~-14 sea_lantern 0  
fill ~-13 ~110 ~-27 ~7 ~110 ~-27 sea_lantern 0  
fill ~-13 ~110 ~-26 ~7 ~110 ~-26 sea_lantern 0  
fill ~-13 ~110 ~-13 ~7 ~110 ~-13 sea_lantern 0  
fill ~-13 ~110 ~-12 ~7 ~110 ~-12 sea_lantern 0  
fill ~-13 ~110 ~-11 ~7 ~110 ~-11 sea_lantern 0  
fill ~-12 ~110 ~-28 ~6 ~110 ~-28 sea_lantern 0  
fill ~-12 ~110 ~-10 ~6 ~110 ~-10 sea_lantern 0  
fill ~-11 ~110 ~-29 ~5 ~110 ~-29 sea_lantern 0  
fill ~-11 ~110 ~-9 ~5 ~110 ~-9 sea_lantern 0  
fill ~-9 ~110 ~-31 ~2 ~110 ~-31 sea_lantern 0  
fill ~-9 ~110 ~-30 ~2 ~110 ~-30 sea_lantern 0  
fill ~-9 ~110 ~-8 ~2 ~110 ~-8 sea_lantern 0  
fill ~-5 ~110 ~-32 ~-1 ~110 ~-32 sea_lantern 0  
fill ~-5 ~110 ~-7 ~-1 ~110 ~-7 sea_lantern 0  
fill ~-5 ~110 ~-6 ~-1 ~110 ~-6 sea_lantern 0  
fill ~-16 ~111 ~-21 ~10 ~111 ~-21 sea_lantern 0  
fill ~-16 ~111 ~-20 ~10 ~111 ~-20 sea_lantern 0  
fill ~-16 ~111 ~-19 ~10 ~111 ~-19 sea_lantern 0  
fill ~-16 ~111 ~-18 ~10 ~111 ~-18 sea_lantern 0  
fill ~-16 ~111 ~-17 ~10 ~111 ~-17 sea_lantern 0  
fill ~-15 ~111 ~-25 ~8 ~111 ~-25 sea_lantern 0  
fill ~-15 ~111 ~-24 ~8 ~111 ~-24 sea_lantern 0  
fill ~-15 ~111 ~-23 ~8 ~111 ~-23 sea_lantern 0  
fill ~-15 ~111 ~-22 ~8 ~111 ~-22 sea_lantern 0  
fill ~-15 ~111 ~-16 ~8 ~111 ~-16 sea_lantern 0  
fill ~-15 ~111 ~-15 ~8 ~111 ~-15 sea_lantern 0  
fill ~-15 ~111 ~-14 ~8 ~111 ~-14 sea_lantern 0  
fill ~-13 ~111 ~-27 ~7 ~111 ~-27 sea_lantern 0  
fill ~-13 ~111 ~-26 ~7 ~111 ~-26 sea_lantern 0  
fill ~-13 ~111 ~-13 ~7 ~111 ~-13 sea_lantern 0  
fill ~-13 ~111 ~-12 ~7 ~111 ~-12 sea_lantern 0  
fill ~-13 ~111 ~-11 ~7 ~111 ~-11 sea_lantern 0  
fill ~-12 ~111 ~-28 ~6 ~111 ~-28 sea_lantern 0  
fill ~-12 ~111 ~-10 ~6 ~111 ~-10 sea_lantern 0  
fill ~-11 ~111 ~-29 ~5 ~111 ~-29 sea_lantern 0  
fill ~-11 ~111 ~-9 ~5 ~111 ~-9 sea_lantern 0  
fill ~-9 ~111 ~-31 ~2 ~111 ~-31 sea_lantern 0  
fill ~-9 ~111 ~-30 ~2 ~111 ~-30 sea_lantern 0  
fill ~-9 ~111 ~-8 ~2 ~111 ~-8 sea_lantern 0  
fill ~-5 ~111 ~-32 ~-1 ~111 ~-32 sea_lantern 0  
fill ~-5 ~111 ~-7 ~-1 ~111 ~-7 sea_lantern 0  
fill ~-5 ~111 ~-6 ~-1 ~111 ~-6 sea_lantern 0  
fill ~-15 ~112 ~-21 ~8 ~112 ~-21 sea_lantern 0  
fill ~-15 ~112 ~-20 ~8 ~112 ~-20 sea_lantern 0  
fill ~-15 ~112 ~-19 ~8 ~112 ~-19 sea_lantern 0  
fill ~-15 ~112 ~-18 ~8 ~112 ~-18 sea_lantern 0  
fill ~-15 ~112 ~-17 ~8 ~112 ~-17 sea_lantern 0  
fill ~-13 ~112 ~-25 ~7 ~112 ~-25 sea_lantern 0  
fill ~-13 ~112 ~-24 ~7 ~112 ~-24 sea_lantern 0  
fill ~-13 ~112 ~-23 ~7 ~112 ~-23 sea_lantern 0  
fill ~-13 ~112 ~-22 ~7 ~112 ~-22 sea_lantern 0  
fill ~-13 ~112 ~-16 ~7 ~112 ~-16 sea_lantern 0  
fill ~-13 ~112 ~-15 ~7 ~112 ~-15 sea_lantern 0  
fill ~-13 ~112 ~-14 ~7 ~112 ~-14 sea_lantern 0  
fill ~-12 ~112 ~-26 ~6 ~112 ~-26 sea_lantern 0  
fill ~-12 ~112 ~-13 ~6 ~112 ~-13 sea_lantern 0  
fill ~-12 ~112 ~-12 ~6 ~112 ~-12 sea_lantern 0  
fill ~-11 ~112 ~-27 ~5 ~112 ~-27 sea_lantern 0  
fill ~-11 ~112 ~-11 ~5 ~112 ~-11 sea_lantern 0  
fill ~-10 ~112 ~-28 ~4 ~112 ~-28 sea_lantern 0  
fill ~-10 ~112 ~-10 ~4 ~112 ~-10 sea_lantern 0  
fill ~-9 ~112 ~-29 ~2 ~112 ~-29 sea_lantern 0  
fill ~-9 ~112 ~-9 ~2 ~112 ~-9 sea_lantern 0  
fill ~-5 ~112 ~-31 ~-1 ~112 ~-31 sea_lantern 0  
fill ~-5 ~112 ~-30 ~-1 ~112 ~-30 sea_lantern 0  
fill ~-5 ~112 ~-8 ~-1 ~112 ~-8 sea_lantern 0  
fill ~-12 ~113 ~-23 ~6 ~113 ~-23 sea_lantern 0  
fill ~-12 ~113 ~-22 ~6 ~113 ~-22 sea_lantern 0  
fill ~-12 ~113 ~-21 ~6 ~113 ~-21 sea_lantern 0  
fill ~-12 ~113 ~-20 ~6 ~113 ~-20 sea_lantern 0  
fill ~-12 ~113 ~-19 ~6 ~113 ~-19 sea_lantern 0  
fill ~-12 ~113 ~-18 ~6 ~113 ~-18 sea_lantern 0  
fill ~-12 ~113 ~-17 ~6 ~113 ~-17 sea_lantern 0  
fill ~-12 ~113 ~-16 ~6 ~113 ~-16 sea_lantern 0  
fill ~-12 ~113 ~-15 ~6 ~113 ~-15 sea_lantern 0  
fill ~-11 ~113 ~-25 ~5 ~113 ~-25 sea_lantern 0  
fill ~-11 ~113 ~-24 ~5 ~113 ~-24 sea_lantern 0  
fill ~-11 ~113 ~-14 ~5 ~113 ~-14 sea_lantern 0  
fill ~-10 ~113 ~-26 ~4 ~113 ~-26 sea_lantern 0  
fill ~-10 ~113 ~-13 ~4 ~113 ~-13 sea_lantern 0  
fill ~-10 ~113 ~-12 ~4 ~113 ~-12 sea_lantern 0  
fill ~-9 ~113 ~-27 ~2 ~113 ~-27 sea_lantern 0  
fill ~-9 ~113 ~-11 ~2 ~113 ~-11 sea_lantern 0  
fill ~-7 ~113 ~-28 ~1 ~113 ~-28 sea_lantern 0  
fill ~-7 ~113 ~-10 ~1 ~113 ~-10 sea_lantern 0  
fill ~-11 ~114 ~-20 ~5 ~114 ~-20 sea_lantern 0  
fill ~-11 ~114 ~-19 ~5 ~114 ~-19 sea_lantern 0  
fill ~-11 ~114 ~-18 ~5 ~114 ~-18 sea_lantern 0  
fill ~-10 ~114 ~-23 ~4 ~114 ~-23 sea_lantern 0  
fill ~-10 ~114 ~-22 ~4 ~114 ~-22 sea_lantern 0  
fill ~-10 ~114 ~-21 ~4 ~114 ~-21 sea_lantern 0  
fill ~-10 ~114 ~-17 ~4 ~114 ~-17 sea_lantern 0  
fill ~-10 ~114 ~-16 ~4 ~114 ~-16 sea_lantern 0  
fill ~-10 ~114 ~-15 ~4 ~114 ~-15 sea_lantern 0  
fill ~-9 ~114 ~-25 ~2 ~114 ~-25 sea_lantern 0  
fill ~-9 ~114 ~-24 ~2 ~114 ~-24 sea_lantern 0  
fill ~-9 ~114 ~-14 ~2 ~114 ~-14 sea_lantern 0  
fill ~-7 ~114 ~-26 ~1 ~114 ~-26 sea_lantern 0  
fill ~-7 ~114 ~-13 ~1 ~114 ~-13 sea_lantern 0  
fill ~-7 ~114 ~-12 ~1 ~114 ~-12 sea_lantern 0  
fill ~-4 ~114 ~-27 ~-2 ~114 ~-27 sea_lantern 0  
fill ~-4 ~114 ~-11 ~-2 ~114 ~-11 sea_lantern 0  
fill ~-8 ~115 ~-19 ~1 ~115 ~-19 sea_lantern 0  
fill ~-8 ~115 ~-18 ~1 ~115 ~-18 sea_lantern 0  
fill ~-7 ~115 ~-21 ~1 ~115 ~-21 sea_lantern 0  
fill ~-7 ~115 ~-20 ~1 ~115 ~-20 sea_lantern 0  
fill ~-7 ~115 ~-17 ~1 ~115 ~-17 sea_lantern 0  
fill ~-7 ~115 ~-16 ~0 ~115 ~-16 sea_lantern 0  
fill ~-6 ~115 ~-22 ~0 ~115 ~-22 sea_lantern 0  
fill ~-6 ~115 ~-15 ~-1 ~115 ~-15 sea_lantern 0  
fill ~-5 ~115 ~-23 ~-1 ~115 ~-23 sea_lantern 0  
fill ~-7 ~116 ~-20 ~0 ~116 ~-20 sea_lantern 0  
fill ~-7 ~116 ~-19 ~0 ~116 ~-19 sea_lantern 0  
fill ~-7 ~116 ~-18 ~0 ~116 ~-18 sea_lantern 0  
fill ~-7 ~116 ~-17 ~0 ~116 ~-17 sea_lantern 0  
fill ~-6 ~116 ~-21 ~-1 ~116 ~-21 sea_lantern 0  
fill ~-6 ~116 ~-16 ~-1 ~116 ~-16 sea_lantern 0  
fill ~-5 ~116 ~-22 ~-2 ~116 ~-22 sea_lantern 0  
fill ~-5 ~116 ~-15 ~-2 ~116 ~-15 sea_lantern 0  
fill ~-7 ~117 ~-20 ~0 ~117 ~-20 sea_lantern 0  
fill ~-7 ~117 ~-19 ~0 ~117 ~-19 sea_lantern 0  
fill ~-7 ~117 ~-18 ~0 ~117 ~-18 sea_lantern 0  
fill ~-6 ~117 ~-21 ~-1 ~117 ~-21 sea_lantern 0  
fill ~-6 ~117 ~-17 ~-1 ~117 ~-17 sea_lantern 0  
fill ~-6 ~117 ~-16 ~-1 ~117 ~-16 sea_lantern 0  
fill ~-5 ~117 ~-22 ~-3 ~117 ~-22 sea_lantern 0  
fill ~-5 ~117 ~-15 ~-3 ~117 ~-15 sea_lantern 0  
fill ~-6 ~118 ~-20 ~-1 ~118 ~-20 sea_lantern 0  
fill ~-6 ~118 ~-19 ~-1 ~118 ~-19 sea_lantern 0  
fill ~-6 ~118 ~-18 ~-1 ~118 ~-18 sea_lantern 0  
fill ~-5 ~118 ~-21 ~-3 ~118 ~-21 sea_lantern 0  
fill ~-5 ~118 ~-17 ~-2 ~118 ~-17 sea_lantern 0  
fill ~-5 ~118 ~-16 ~-3 ~118 ~-16 sea_lantern 0  
fill ~-5 ~119 ~-27 ~-4 ~119 ~-27 stained_hardened_clay 9  
fill ~-5 ~119 ~-11 ~-4 ~119 ~-11 stained_hardened_clay 9  
fill ~-4 ~119 ~-19 ~-2 ~119 ~-19 sea_lantern 0 
setblock ~-3 ~119 ~-27 sea_lantern 0 
setblock ~-3 ~119 ~-11 sea_lantern 0  
fill ~-2 ~119 ~-27 ~-1 ~119 ~-27 stained_hardened_clay 9  
fill ~-2 ~119 ~-11 ~-1 ~119 ~-11 stained_hardened_clay 9 
setblock ~-6 ~120 ~-26 stained_hardened_clay 9 
setblock ~-6 ~120 ~-12 stained_hardened_clay 9  
fill ~-5 ~120 ~-26 ~-1 ~120 ~-26 glass 5  
fill ~-5 ~120 ~-12 ~-1 ~120 ~-12 glass 5  
fill ~-4 ~120 ~-19 ~-4 ~121 ~-19 stained_hardened_clay 9  
fill ~-3 ~120 ~-20 ~-3 ~121 ~-20 stained_hardened_clay 9  
fill ~-3 ~120 ~-18 ~-3 ~121 ~-18 stained_hardened_clay 9  
fill ~-2 ~120 ~-19 ~-2 ~121 ~-19 stained_hardened_clay 9 
setblock ~0 ~120 ~-26 stained_hardened_clay 9 
setblock ~0 ~120 ~-12 stained_hardened_clay 9  
fill ~-6 ~121 ~-24 ~-6 ~121 ~-23 stained_hardened_clay 9  
fill ~-6 ~121 ~-15 ~-6 ~121 ~-14 stained_hardened_clay 9  
fill ~-5 ~121 ~-25 ~-4 ~121 ~-25 stained_hardened_clay 9  
fill ~-5 ~121 ~-24 ~-1 ~121 ~-24 glass 4  
fill ~-5 ~121 ~-23 ~-1 ~121 ~-23 glass 5  
fill ~-5 ~121 ~-15 ~-1 ~121 ~-15 glass 5  
fill ~-5 ~121 ~-14 ~-1 ~121 ~-14 glass 4  
fill ~-5 ~121 ~-13 ~-4 ~121 ~-13 stained_hardened_clay 9 
setblock ~-3 ~121 ~-25 sea_lantern 0 
setblock ~-3 ~121 ~-13 sea_lantern 0  
fill ~-2 ~121 ~-25 ~-1 ~121 ~-25 stained_hardened_clay 9  
fill ~-2 ~121 ~-13 ~-1 ~121 ~-13 stained_hardened_clay 9  
fill ~0 ~121 ~-24 ~0 ~121 ~-23 stained_hardened_clay 9  
fill ~0 ~121 ~-15 ~0 ~121 ~-14 stained_hardened_clay 9  
fill ~-6 ~122 ~-21 ~-6 ~122 ~-17 stained_hardened_clay 9  
fill ~-5 ~122 ~-22 ~-4 ~122 ~-22 stained_hardened_clay 9  
fill ~-5 ~122 ~-21 ~-1 ~122 ~-21 glass 4  
fill ~-5 ~122 ~-20 ~-4 ~122 ~-20 glass 5 
setblock ~-5 ~122 ~-19 glass 4  
fill ~-5 ~122 ~-18 ~-4 ~122 ~-18 glass 5  
fill ~-5 ~122 ~-17 ~-1 ~122 ~-17 glass 4  
fill ~-5 ~122 ~-16 ~-4 ~122 ~-16 stained_hardened_clay 9 
setblock ~-4 ~122 ~-19 sea_lantern 0 
setblock ~-3 ~122 ~-22 sea_lantern 0 
setblock ~-3 ~122 ~-20 sea_lantern 0 
setblock ~-3 ~122 ~-18 sea_lantern 0 
setblock ~-3 ~122 ~-16 sea_lantern 0  
fill ~-2 ~122 ~-22 ~-1 ~122 ~-22 stained_hardened_clay 9  
fill ~-2 ~122 ~-20 ~-1 ~122 ~-20 glass 5 
setblock ~-2 ~122 ~-19 sea_lantern 0  
fill ~-2 ~122 ~-18 ~-1 ~122 ~-18 glass 5  
fill ~-2 ~122 ~-16 ~-1 ~122 ~-16 stained_hardened_clay 9 
setblock ~-1 ~122 ~-19 glass 4  
fill ~0 ~122 ~-21 ~0 ~122 ~-17 stained_hardened_clay 9  
fill ~-4 ~123 ~-19 ~-4 ~132 ~-19 stained_hardened_clay 9  
fill ~-3 ~123 ~-20 ~-3 ~132 ~-20 stained_hardened_clay 9  
fill ~-3 ~123 ~-18 ~-3 ~132 ~-18 stained_hardened_clay 9  
fill ~-2 ~123 ~-19 ~-2 ~132 ~-19 stained_hardened_clay 9  
fill ~-5 ~129 ~-33 ~-4 ~129 ~-33 stained_hardened_clay 9  
fill ~-5 ~129 ~-5 ~-4 ~129 ~-5 stained_hardened_clay 9 
setblock ~-3 ~129 ~-33 sea_lantern 0 
setblock ~-3 ~129 ~-5 sea_lantern 0  
fill ~-2 ~129 ~-33 ~-1 ~129 ~-33 stained_hardened_clay 9  
fill ~-2 ~129 ~-5 ~-1 ~129 ~-5 stained_hardened_clay 9 
setblock ~-6 ~130 ~-32 stained_hardened_clay 9 
setblock ~-6 ~130 ~-6 stained_hardened_clay 9  
fill ~-5 ~130 ~-32 ~-1 ~130 ~-32 glass 4  
fill ~-5 ~130 ~-6 ~-1 ~130 ~-6 glass 4 
setblock ~0 ~130 ~-32 stained_hardened_clay 9 
setblock ~0 ~130 ~-6 stained_hardened_clay 9  
fill ~-6 ~131 ~-30 ~-6 ~131 ~-29 stained_hardened_clay 9  
fill ~-6 ~131 ~-9 ~-6 ~131 ~-8 stained_hardened_clay 9  
fill ~-5 ~131 ~-31 ~-4 ~131 ~-31 stained_hardened_clay 9  
fill ~-5 ~131 ~-30 ~-1 ~131 ~-30 glass 5  
fill ~-5 ~131 ~-29 ~-1 ~131 ~-29 glass 4  
fill ~-5 ~131 ~-9 ~-1 ~131 ~-9 glass 4  
fill ~-5 ~131 ~-8 ~-1 ~131 ~-8 glass 5  
fill ~-5 ~131 ~-7 ~-4 ~131 ~-7 stained_hardened_clay 9 
setblock ~-3 ~131 ~-31 sea_lantern 0 
setblock ~-3 ~131 ~-7 sea_lantern 0  
fill ~-2 ~131 ~-31 ~-1 ~131 ~-31 stained_hardened_clay 9  
fill ~-2 ~131 ~-7 ~-1 ~131 ~-7 stained_hardened_clay 9  
fill ~0 ~131 ~-30 ~0 ~131 ~-29 stained_hardened_clay 9  
fill ~0 ~131 ~-9 ~0 ~131 ~-8 stained_hardened_clay 9  
fill ~-6 ~132 ~-27 ~-6 ~132 ~-25 stained_hardened_clay 9  
fill ~-6 ~132 ~-13 ~-6 ~132 ~-11 stained_hardened_clay 9  
fill ~-5 ~132 ~-28 ~-4 ~132 ~-28 stained_hardened_clay 9  
fill ~-5 ~132 ~-27 ~-1 ~132 ~-27 glass 5  
fill ~-5 ~132 ~-26 ~-1 ~132 ~-26 glass 4  
fill ~-5 ~132 ~-25 ~-1 ~132 ~-25 glass 5  
fill ~-5 ~132 ~-13 ~-1 ~132 ~-13 glass 5  
fill ~-5 ~132 ~-12 ~-1 ~132 ~-12 glass 4  
fill ~-5 ~132 ~-11 ~-1 ~132 ~-11 glass 5  
fill ~-5 ~132 ~-10 ~-4 ~132 ~-10 stained_hardened_clay 9 
setblock ~-3 ~132 ~-28 sea_lantern 0 
setblock ~-3 ~132 ~-10 sea_lantern 0  
fill ~-2 ~132 ~-28 ~-1 ~132 ~-28 stained_hardened_clay 9  
fill ~-2 ~132 ~-10 ~-1 ~132 ~-10 stained_hardened_clay 9  
fill ~0 ~132 ~-27 ~0 ~132 ~-25 stained_hardened_clay 9  
fill ~0 ~132 ~-13 ~0 ~132 ~-11 stained_hardened_clay 9  
fill ~-6 ~133 ~-23 ~-6 ~133 ~-15 stained_hardened_clay 9  
fill ~-5 ~133 ~-24 ~-4 ~133 ~-24 stained_hardened_clay 9  
fill ~-5 ~133 ~-23 ~-1 ~133 ~-23 glass 4  
fill ~-5 ~133 ~-22 ~-1 ~133 ~-22 glass 5  
fill ~-5 ~133 ~-21 ~-1 ~133 ~-21 glass 4  
fill ~-5 ~133 ~-20 ~-4 ~133 ~-20 glass 5 
setblock ~-5 ~133 ~-19 glass 4  
fill ~-5 ~133 ~-18 ~-4 ~133 ~-18 glass 5  
fill ~-5 ~133 ~-17 ~-1 ~133 ~-17 glass 4  
fill ~-5 ~133 ~-16 ~-1 ~133 ~-16 glass 5  
fill ~-5 ~133 ~-15 ~-1 ~133 ~-15 glass 4  
fill ~-5 ~133 ~-14 ~-4 ~133 ~-14 stained_hardened_clay 9 
setblock ~-4 ~133 ~-19 sea_lantern 0 
setblock ~-3 ~133 ~-24 sea_lantern 0 
setblock ~-3 ~133 ~-20 sea_lantern 0 
setblock ~-3 ~133 ~-18 sea_lantern 0 
setblock ~-3 ~133 ~-14 sea_lantern 0  
fill ~-2 ~133 ~-24 ~-1 ~133 ~-24 stained_hardened_clay 9  
fill ~-2 ~133 ~-20 ~-1 ~133 ~-20 glass 5 
setblock ~-2 ~133 ~-19 sea_lantern 0  
fill ~-2 ~133 ~-18 ~-1 ~133 ~-18 glass 5  
fill ~-2 ~133 ~-14 ~-1 ~133 ~-14 stained_hardened_clay 9 
setblock ~-1 ~133 ~-19 glass 4  
fill ~0 ~133 ~-23 ~0 ~133 ~-15 stained_hardened_clay 9  
fill ~-4 ~134 ~-19 ~-4 ~143 ~-19 stained_hardened_clay 9  
fill ~-3 ~134 ~-20 ~-3 ~143 ~-20 stained_hardened_clay 9  
fill ~-3 ~134 ~-18 ~-3 ~143 ~-18 stained_hardened_clay 9  
fill ~-2 ~134 ~-19 ~-2 ~143 ~-19 stained_hardened_clay 9  
fill ~-5 ~137 ~-47 ~-4 ~137 ~-47 stained_hardened_clay 9  
fill ~-5 ~137 ~9 ~-4 ~137 ~9 stained_hardened_clay 9 
setblock ~-3 ~137 ~-47 sea_lantern 0 
setblock ~-3 ~137 ~9 sea_lantern 0  
fill ~-2 ~137 ~-47 ~-1 ~137 ~-47 stained_hardened_clay 9  
fill ~-2 ~137 ~9 ~-1 ~137 ~9 stained_hardened_clay 9 
setblock ~-6 ~138 ~-46 stained_hardened_clay 9 
setblock ~-6 ~138 ~8 stained_hardened_clay 9  
fill ~-5 ~138 ~-46 ~-1 ~138 ~-46 glass 5  
fill ~-5 ~138 ~8 ~-1 ~138 ~8 glass 5 
setblock ~0 ~138 ~-46 stained_hardened_clay 9 
setblock ~0 ~138 ~8 stained_hardened_clay 9 
setblock ~-6 ~139 ~-45 stained_hardened_clay 9 
setblock ~-6 ~139 ~7 stained_hardened_clay 9  
fill ~-5 ~139 ~-45 ~-1 ~139 ~-45 glass 4  
fill ~-5 ~139 ~7 ~-1 ~139 ~7 glass 4 
setblock ~0 ~139 ~-45 stained_hardened_clay 9 
setblock ~0 ~139 ~7 stained_hardened_clay 9  
fill ~-6 ~140 ~-43 ~-6 ~140 ~-42 stained_hardened_clay 9  
fill ~-6 ~140 ~4 ~-6 ~140 ~5 stained_hardened_clay 9  
fill ~-5 ~140 ~-44 ~-4 ~140 ~-44 stained_hardened_clay 9  
fill ~-5 ~140 ~-43 ~-1 ~140 ~-43 glass 5  
fill ~-5 ~140 ~-42 ~-1 ~140 ~-42 glass 4  
fill ~-5 ~140 ~4 ~-1 ~140 ~4 glass 4  
fill ~-5 ~140 ~5 ~-1 ~140 ~5 glass 5  
fill ~-5 ~140 ~6 ~-4 ~140 ~6 stained_hardened_clay 9 
setblock ~-3 ~140 ~-44 sea_lantern 0 
setblock ~-3 ~140 ~6 sea_lantern 0  
fill ~-2 ~140 ~-44 ~-1 ~140 ~-44 stained_hardened_clay 9  
fill ~-2 ~140 ~6 ~-1 ~140 ~6 stained_hardened_clay 9  
fill ~0 ~140 ~-43 ~0 ~140 ~-42 stained_hardened_clay 9  
fill ~0 ~140 ~4 ~0 ~140 ~5 stained_hardened_clay 9  
fill ~-6 ~141 ~-40 ~-6 ~141 ~-39 stained_hardened_clay 9  
fill ~-6 ~141 ~1 ~-6 ~141 ~2 stained_hardened_clay 9  
fill ~-5 ~141 ~-41 ~-4 ~141 ~-41 stained_hardened_clay 9  
fill ~-5 ~141 ~-40 ~-1 ~141 ~-40 glass 5  
fill ~-5 ~141 ~-39 ~-1 ~141 ~-39 glass 4  
fill ~-5 ~141 ~1 ~-1 ~141 ~1 glass 4  
fill ~-5 ~141 ~2 ~-1 ~141 ~2 glass 5  
fill ~-5 ~141 ~3 ~-4 ~141 ~3 stained_hardened_clay 9 
setblock ~-3 ~141 ~-41 sea_lantern 0 
setblock ~-3 ~141 ~3 sea_lantern 0  
fill ~-2 ~141 ~-41 ~-1 ~141 ~-41 stained_hardened_clay 9  
fill ~-2 ~141 ~3 ~-1 ~141 ~3 stained_hardened_clay 9  
fill ~0 ~141 ~-40 ~0 ~141 ~-39 stained_hardened_clay 9  
fill ~0 ~141 ~1 ~0 ~141 ~2 stained_hardened_clay 9  
fill ~-6 ~142 ~-37 ~-6 ~142 ~-35 stained_hardened_clay 9    
fill ~-6 ~142 ~-3 ~-6 ~142 ~-1 stained_hardened_clay 9  
fill ~-5 ~142 ~-38 ~-4 ~142 ~-38 stained_hardened_clay 9  
fill ~-5 ~142 ~-37 ~-1 ~142 ~-37 glass 5  
fill ~-5 ~142 ~-36 ~-1 ~142 ~-36 glass 4  
fill ~-5 ~142 ~-35 ~-1 ~142 ~-35 glass 5  
fill ~-5 ~142 ~-3 ~-1 ~142 ~-3 glass 5  
fill ~-5 ~142 ~-2 ~-1 ~142 ~-2 glass 4  
fill ~-5 ~142 ~-1 ~-1 ~142 ~-1 glass 5  
fill ~-5 ~142 ~0 ~-4 ~142 ~0 stained_hardened_clay 9 
setblock ~-3 ~142 ~-38 sea_lantern 0 
setblock ~-3 ~142 ~0 sea_lantern 0  
fill ~-2 ~142 ~-38 ~-1 ~142 ~-38 stained_hardened_clay 9  
fill ~-2 ~142 ~0 ~-1 ~142 ~0 stained_hardened_clay 9  
fill ~0 ~142 ~-37 ~0 ~142 ~-35 stained_hardened_clay 9  
fill ~0 ~142 ~-3 ~0 ~142 ~-1 stained_hardened_clay 9  
fill ~-6 ~143 ~-33 ~-6 ~143 ~-28 stained_hardened_clay 9  
fill ~-6 ~143 ~-10 ~-6 ~143 ~-5 stained_hardened_clay 9  
fill ~-5 ~143 ~-34 ~-4 ~143 ~-34 stained_hardened_clay 9  
fill ~-5 ~143 ~-33 ~-1 ~143 ~-33 glass 5  
fill ~-5 ~143 ~-32 ~-1 ~143 ~-32 glass 4  
fill ~-5 ~143 ~-31 ~-1 ~143 ~-31 glass 5  
fill ~-5 ~143 ~-30 ~-1 ~143 ~-30 glass 4  
fill ~-5 ~143 ~-29 ~-1 ~143 ~-29 glass 5  
fill ~-5 ~143 ~-28 ~-1 ~143 ~-28 glass 4  
fill ~-5 ~143 ~-10 ~-1 ~143 ~-10 glass 5  
fill ~-5 ~143 ~-9 ~-1 ~143 ~-9 glass 4  
fill ~-5 ~143 ~-8 ~-1 ~143 ~-8 glass 5  
fill ~-5 ~143 ~-7 ~-1 ~143 ~-7 glass 4  
fill ~-5 ~143 ~-6 ~-1 ~143 ~-6 glass 5  
fill ~-5 ~143 ~-5 ~-1 ~143 ~-5 glass 4  
fill ~-5 ~143 ~-4 ~-4 ~143 ~-4 stained_hardened_clay 9 
setblock ~-3 ~143 ~-34 sea_lantern 0 
setblock ~-3 ~143 ~-4 sea_lantern 0  
fill ~-2 ~143 ~-34 ~-1 ~143 ~-34 stained_hardened_clay 9  
fill ~-2 ~143 ~-4 ~-1 ~143 ~-4 stained_hardened_clay 9  
fill ~0 ~143 ~-33 ~0 ~143 ~-28 stained_hardened_clay 9  
fill ~0 ~143 ~-10 ~0 ~143 ~-5 stained_hardened_clay 9  
fill ~-6 ~144 ~-26 ~-6 ~144 ~-12 stained_hardened_clay 9  
fill ~-5 ~144 ~-27 ~-4 ~144 ~-27 stained_hardened_clay 9  
fill ~-5 ~144 ~-26 ~-1 ~144 ~-26 glass 5  
fill ~-5 ~144 ~-25 ~-1 ~144 ~-25 glass 4  
fill ~-5 ~144 ~-24 ~-1 ~144 ~-24 glass 5  
fill ~-5 ~144 ~-23 ~-1 ~144 ~-23 glass 4  
fill ~-5 ~144 ~-22 ~-1 ~144 ~-22 glass 5  
fill ~-5 ~144 ~-21 ~-1 ~144 ~-21 glass 4  
fill ~-5 ~144 ~-20 ~-4 ~144 ~-20 glass 5 
setblock ~-5 ~144 ~-19 glass 4  
fill ~-5 ~144 ~-18 ~-4 ~144 ~-18 glass 5  
fill ~-5 ~144 ~-17 ~-1 ~144 ~-17 glass 4  
fill ~-5 ~144 ~-16 ~-1 ~144 ~-16 glass 5  
fill ~-5 ~144 ~-15 ~-1 ~144 ~-15 glass 4  
fill ~-5 ~144 ~-14 ~-1 ~144 ~-14 glass 5  
fill ~-5 ~144 ~-13 ~-1 ~144 ~-13 glass 4  
fill ~-5 ~144 ~-12 ~-1 ~144 ~-12 glass 5  
fill ~-5 ~144 ~-11 ~-4 ~144 ~-11 stained_hardened_clay 9 
setblock ~-4 ~144 ~-19 sea_lantern 0 
setblock ~-3 ~144 ~-27 sea_lantern 0 
setblock ~-3 ~144 ~-20 sea_lantern 0 
setblock ~-3 ~144 ~-18 sea_lantern 0 
setblock ~-3 ~144 ~-11 sea_lantern 0  
fill ~-2 ~144 ~-27 ~-1 ~144 ~-27 stained_hardened_clay 9  
fill ~-2 ~144 ~-20 ~-1 ~144 ~-20 glass 5 
setblock ~-2 ~144 ~-19 sea_lantern 0  
fill ~-2 ~144 ~-18 ~-1 ~144 ~-18 glass 5  
fill ~-2 ~144 ~-11 ~-1 ~144 ~-11 stained_hardened_clay 9 
setblock ~-1 ~144 ~-19 glass 4  
fill ~0 ~144 ~-26 ~0 ~144 ~-12 stained_hardened_clay 9  
fill ~-4 ~145 ~-19 ~-4 ~146 ~-19 stained_hardened_clay 9  
fill ~-3 ~145 ~-20 ~-3 ~146 ~-20 stained_hardened_clay 9  
fill ~-3 ~145 ~-18 ~-3 ~146 ~-18 stained_hardened_clay 9  
fill ~-2 ~145 ~-19 ~-2 ~146 ~-19 stained_hardened_clay 9  
fill ~-6 ~146 ~-20 ~-6 ~146 ~-18 stained_hardened_clay 9  
fill ~-4 ~146 ~-22 ~-2 ~146 ~-22 stained_hardened_clay 9  
fill ~-4 ~146 ~-20 ~-4 ~147 ~-20 stained_hardened_clay 9  
fill ~-4 ~146 ~-18 ~-4 ~147 ~-18 stained_hardened_clay 9  
fill ~-4 ~146 ~-16 ~-2 ~146 ~-16 stained_hardened_clay 9  
fill ~-2 ~146 ~-20 ~-2 ~147 ~-20 stained_hardened_clay 9  
fill ~-2 ~146 ~-18 ~-2 ~147 ~-18 stained_hardened_clay 9  
fill ~0 ~146 ~-20 ~0 ~146 ~-18 stained_hardened_clay 9  
fill ~-8 ~147 ~-19 ~-6 ~147 ~-19 glass 9  
fill ~-6 ~147 ~-21 ~-6 ~149 ~-21 stained_hardened_clay 9  
fill ~-6 ~147 ~-17 ~-6 ~149 ~-17 stained_hardened_clay 9  
fill ~-5 ~147 ~-22 ~-5 ~149 ~-22 stained_hardened_clay 9  
fill ~-5 ~147 ~-20 ~-5 ~149 ~-20 stained_hardened_clay 9  
fill ~-5 ~147 ~-19 ~-5 ~147 ~-18 stained_hardened_clay 9  
fill ~-5 ~147 ~-16 ~-5 ~149 ~-16 stained_hardened_clay 9  
fill ~-4 ~147 ~-21 ~-2 ~147 ~-21 stained_hardened_clay 9 
setblock ~-4 ~147 ~-19 sea_lantern 0  
fill ~-4 ~147 ~-17 ~-2 ~147 ~-17 stained_hardened_clay 9  
fill ~-3 ~147 ~-24 ~-3 ~147 ~-22 glass 9 
setblock ~-3 ~147 ~-20 sea_lantern 0 
setblock ~-3 ~147 ~-18 sea_lantern 0  
fill ~-3 ~147 ~-16 ~-3 ~147 ~-14 glass 9 
setblock ~-2 ~147 ~-19 sea_lantern 0  
fill ~-1 ~147 ~-22 ~-1 ~149 ~-22 stained_hardened_clay 9  
fill ~-1 ~147 ~-20 ~-1 ~149 ~-20 stained_hardened_clay 9  
fill ~-1 ~147 ~-19 ~-1 ~147 ~-18 stained_hardened_clay 9  
fill ~-1 ~147 ~-16 ~-1 ~149 ~-16 stained_hardened_clay 9  
fill ~0 ~147 ~-21 ~0 ~149 ~-21 stained_hardened_clay 9  
fill ~0 ~147 ~-19 ~2 ~147 ~-19 glass 9  
fill ~0 ~147 ~-17 ~0 ~149 ~-17 stained_hardened_clay 9 
setblock ~-9 ~148 ~-19 glass 9  
fill ~-8 ~148 ~-20 ~-6 ~148 ~-20 glass 9  
fill ~-8 ~148 ~-19 ~-5 ~148 ~-19 sea_lantern 0  
fill ~-8 ~148 ~-18 ~-6 ~148 ~-18 glass 9  
fill ~-5 ~148 ~-18 ~-5 ~149 ~-18 stained_hardened_clay 9  
fill ~-4 ~148 ~-24 ~-4 ~148 ~-22 glass 9  
fill ~-4 ~148 ~-21 ~-4 ~149 ~-21 stained_hardened_clay 9 
setblock ~-4 ~148 ~-20 sea_lantern 0 
setblock ~-4 ~148 ~-18 sea_lantern 0  
fill ~-4 ~148 ~-17 ~-4 ~149 ~-17 stained_hardened_clay 9  
fill ~-4 ~148 ~-16 ~-4 ~148 ~-14 glass 9 
setblock ~-3 ~148 ~-25 glass 9  
fill ~-3 ~148 ~-24 ~-3 ~148 ~-22 sea_lantern 0  
fill ~-3 ~148 ~-17 ~-3 ~148 ~-14 sea_lantern 0 
setblock ~-3 ~148 ~-13 glass 9  
fill ~-2 ~148 ~-24 ~-2 ~148 ~-22 glass 9  
fill ~-2 ~148 ~-21 ~-2 ~149 ~-21 stained_hardened_clay 9 
setblock ~-2 ~148 ~-20 sea_lantern 0 
setblock ~-2 ~148 ~-18 sea_lantern 0  
fill ~-2 ~148 ~-17 ~-2 ~149 ~-17 stained_hardened_clay 9  
fill ~-2 ~148 ~-16 ~-2 ~148 ~-14 glass 9  
fill ~-1 ~148 ~-18 ~-1 ~149 ~-18 stained_hardened_clay 9  
fill ~0 ~148 ~-20 ~2 ~148 ~-20 glass 9  
fill ~0 ~148 ~-19 ~2 ~148 ~-19 sea_lantern 0  
fill ~0 ~148 ~-18 ~2 ~148 ~-18 glass 9 
setblock ~3 ~148 ~-19 glass 9 
setblock ~-10 ~149 ~-19 glass 9 
setblock ~-9 ~149 ~-20 glass 9 
setblock ~-9 ~149 ~-19 sea_lantern 0 
setblock ~-9 ~149 ~-18 glass 9  
fill ~-8 ~149 ~-19 ~-6 ~149 ~-19 glass 9 
setblock ~-5 ~149 ~-19 stained_hardened_clay 9 
setblock ~-4 ~149 ~-25 glass 9  
fill ~-4 ~149 ~-20 ~-4 ~153 ~-20 stained_hardened_clay 9 
setblock ~-4 ~149 ~-19 sea_lantern 0  
fill ~-4 ~149 ~-18 ~-4 ~153 ~-18 stained_hardened_clay 9 
setblock ~-4 ~149 ~-13 glass 9 
setblock ~-3 ~149 ~-26 glass 9 
setblock ~-3 ~149 ~-25 sea_lantern 0  
fill ~-3 ~149 ~-24 ~-3 ~149 ~-22 glass 9 
setblock ~-3 ~149 ~-21 stained_hardened_clay 9 
setblock ~-3 ~149 ~-20 sea_lantern 0 
setblock ~-3 ~149 ~-18 sea_lantern 0 
setblock ~-3 ~149 ~-17 stained_hardened_clay 9  
fill ~-3 ~149 ~-16 ~-3 ~149 ~-14 glass 9 
setblock ~-3 ~149 ~-13 sea_lantern 0 
setblock ~-3 ~149 ~-12 glass 9 
setblock ~-2 ~149 ~-25 glass 9  
fill ~-2 ~149 ~-20 ~-2 ~153 ~-20 stained_hardened_clay 9 
setblock ~-2 ~149 ~-19 sea_lantern 0  
fill ~-2 ~149 ~-18 ~-2 ~153 ~-18 stained_hardened_clay 9 
setblock ~-2 ~149 ~-13 glass 9 
setblock ~-1 ~149 ~-19 stained_hardened_clay 9  
fill ~0 ~149 ~-19 ~2 ~149 ~-19 glass 9 
setblock ~3 ~149 ~-20 glass 9 
setblock ~3 ~149 ~-19 sea_lantern 0 
setblock ~3 ~149 ~-18 glass 9 
setblock ~4 ~149 ~-19 glass 9 
setblock ~-11 ~150 ~-19 glass 9 
setblock ~-10 ~150 ~-20 glass 9 
setblock ~-10 ~150 ~-19 sea_lantern 0 
setblock ~-10 ~150 ~-18 glass 9 
setblock ~-9 ~150 ~-19 glass 9  
fill ~-6 ~150 ~-20 ~-6 ~150 ~-18 stained_hardened_clay 9 
setblock ~-4 ~150 ~-26 glass 9  
fill ~-4 ~150 ~-22 ~-2 ~150 ~-22 stained_hardened_clay 9 
setblock ~-4 ~150 ~-19 stained_hardened_clay 9  
fill ~-4 ~150 ~-16 ~-2 ~150 ~-16 stained_hardened_clay 9 
setblock ~-4 ~150 ~-12 glass 9 
setblock ~-3 ~150 ~-27 glass 9 
setblock ~-3 ~150 ~-26 sea_lantern 0 
setblock ~-3 ~150 ~-25 glass 9 
setblock ~-3 ~150 ~-20 stained_hardened_clay 9 
setblock ~-3 ~150 ~-18 stained_hardened_clay 9 
setblock ~-3 ~150 ~-13 glass 9 
setblock ~-3 ~150 ~-12 sea_lantern 0 
setblock ~-3 ~150 ~-11 glass 9 
setblock ~-2 ~150 ~-26 glass 9 
setblock ~-2 ~150 ~-19 stained_hardened_clay 9 
setblock ~-2 ~150 ~-12 glass 9  
fill ~0 ~150 ~-20 ~0 ~150 ~-18 stained_hardened_clay 9 
setblock ~3 ~150 ~-19 glass 9 
setblock ~4 ~150 ~-20 glass 9 
setblock ~4 ~150 ~-19 sea_lantern 0 
setblock ~4 ~150 ~-18 glass 9 
setblock ~5 ~150 ~-19 glass 9  
fill ~-12 ~151 ~-19 ~-12 ~152 ~-19 glass 9  
fill ~-11 ~151 ~-20 ~-11 ~152 ~-20 glass 9  
fill ~-11 ~151 ~-19 ~-11 ~162 ~-19 sea_lantern 0  
fill ~-11 ~151 ~-18 ~-11 ~152 ~-18 glass 9  
fill ~-10 ~151 ~-19 ~-10 ~152 ~-19 glass 9  
fill ~-4 ~151 ~-27 ~-4 ~152 ~-27 glass 9  
fill ~-4 ~151 ~-19 ~-4 ~152 ~-19 glass 4  
fill ~-4 ~151 ~-11 ~-4 ~152 ~-11 glass 9  
fill ~-3 ~151 ~-28 ~-3 ~152 ~-28 glass 9  
fill ~-3 ~151 ~-27 ~-3 ~162 ~-27 sea_lantern 0  
fill ~-3 ~151 ~-26 ~-3 ~152 ~-26 glass 9  
fill ~-3 ~151 ~-20 ~-3 ~152 ~-20 glass 4  
fill ~-3 ~151 ~-18 ~-3 ~152 ~-18 glass 4  
fill ~-3 ~151 ~-12 ~-3 ~152 ~-12 glass 9  
fill ~-3 ~151 ~-11 ~-3 ~162 ~-11 sea_lantern 0  
fill ~-3 ~151 ~-10 ~-3 ~152 ~-10 glass 9  
fill ~-2 ~151 ~-27 ~-2 ~152 ~-27 glass 9  
fill ~-2 ~151 ~-19 ~-2 ~152 ~-19 glass 4  
fill ~-2 ~151 ~-11 ~-2 ~152 ~-11 glass 9  
fill ~4 ~151 ~-19 ~4 ~152 ~-19 glass 9  
fill ~5 ~151 ~-20 ~5 ~152 ~-20 glass 9  
fill ~5 ~151 ~-19 ~5 ~162 ~-19 sea_lantern 0  
fill ~5 ~151 ~-18 ~5 ~152 ~-18 glass 9  
fill ~6 ~151 ~-19 ~6 ~152 ~-19 glass 9  
fill ~-12 ~153 ~-20 ~-10 ~153 ~-20 stained_hardened_clay 8  
fill ~-12 ~153 ~-19 ~-12 ~153 ~-18 stained_hardened_clay 8  
fill ~-11 ~153 ~-18 ~-10 ~153 ~-18 stained_hardened_clay 8 
setblock ~-10 ~153 ~-19 stained_hardened_clay 8  
fill ~-4 ~153 ~-28 ~-2 ~153 ~-28 stained_hardened_clay 8  
fill ~-4 ~153 ~-27 ~-4 ~153 ~-26 stained_hardened_clay 8  
fill ~-4 ~153 ~-12 ~-2 ~153 ~-12 stained_hardened_clay 8  
fill ~-4 ~153 ~-11 ~-4 ~153 ~-10 stained_hardened_clay 8  
fill ~-3 ~153 ~-26 ~-2 ~153 ~-26 stained_hardened_clay 8 
setblock ~-3 ~153 ~-20 stained_hardened_clay 9 
setblock ~-3 ~153 ~-18 stained_hardened_clay 9  
fill ~-3 ~153 ~-10 ~-2 ~153 ~-10 stained_hardened_clay 8 
setblock ~-2 ~153 ~-27 stained_hardened_clay 8 
setblock ~-2 ~153 ~-19 stained_hardened_clay 9 
setblock ~-2 ~153 ~-11 stained_hardened_clay 8  
fill ~4 ~153 ~-20 ~6 ~153 ~-20 stained_hardened_clay 8  
fill ~4 ~153 ~-19 ~4 ~153 ~-18 stained_hardened_clay 8  
fill ~5 ~153 ~-18 ~6 ~153 ~-18 stained_hardened_clay 8 
setblock ~6 ~153 ~-19 stained_hardened_clay 8  
fill ~-13 ~154 ~-20 ~-13 ~154 ~-18 stained_hardened_clay 8  
fill ~-12 ~154 ~-21 ~-10 ~154 ~-21 stained_hardened_clay 8  
fill ~-12 ~154 ~-20 ~-10 ~154 ~-20 sea_lantern 0  
fill ~-12 ~154 ~-19 ~-12 ~162 ~-19 sea_lantern 0  
fill ~-12 ~154 ~-18 ~-10 ~154 ~-18 sea_lantern 0  
fill ~-12 ~154 ~-17 ~-10 ~154 ~-17 stained_hardened_clay 8  
fill ~-10 ~154 ~-19 ~-10 ~162 ~-19 sea_lantern 0  
fill ~-9 ~154 ~-20 ~-9 ~154 ~-18 stained_hardened_clay 8  
fill ~-5 ~154 ~-28 ~-5 ~154 ~-26 stained_hardened_clay 8  
fill ~-5 ~154 ~-20 ~-5 ~154 ~-18 stained_hardened_clay 9  
fill ~-5 ~154 ~-12 ~-5 ~154 ~-10 stained_hardened_clay 8  
fill ~-4 ~154 ~-29 ~-2 ~154 ~-29 stained_hardened_clay 8  
fill ~-4 ~154 ~-28 ~-2 ~154 ~-28 sea_lantern 0  
fill ~-4 ~154 ~-27 ~-4 ~162 ~-27 sea_lantern 0  
fill ~-4 ~154 ~-26 ~-2 ~154 ~-26 sea_lantern 0  
fill ~-4 ~154 ~-25 ~-2 ~154 ~-25 stained_hardened_clay 8  
fill ~-4 ~154 ~-21 ~-2 ~154 ~-21 stained_hardened_clay 9  
fill ~-4 ~154 ~-20 ~-2 ~154 ~-20 sea_lantern 0  
fill ~-4 ~154 ~-19 ~-2 ~154 ~-19 sea_lantern 0  
fill ~-4 ~154 ~-18 ~-2 ~154 ~-18 sea_lantern 0  
fill ~-4 ~154 ~-17 ~-2 ~154 ~-17 stained_hardened_clay 9  
fill ~-4 ~154 ~-13 ~-2 ~154 ~-13 stained_hardened_clay 8  
fill ~-4 ~154 ~-12 ~-2 ~154 ~-12 sea_lantern 0  
fill ~-4 ~154 ~-11 ~-4 ~162 ~-11 sea_lantern 0  
fill ~-4 ~154 ~-10 ~-2 ~154 ~-10 sea_lantern 0  
fill ~-4 ~154 ~-9 ~-2 ~154 ~-9 stained_hardened_clay 8  
fill ~-2 ~154 ~-27 ~-2 ~162 ~-27 sea_lantern 0  
fill ~-2 ~154 ~-11 ~-2 ~162 ~-11 sea_lantern 0  
fill ~-1 ~154 ~-28 ~-1 ~154 ~-26 stained_hardened_clay 8  
fill ~-1 ~154 ~-20 ~-1 ~154 ~-18 stained_hardened_clay 9  
fill ~-1 ~154 ~-12 ~-1 ~154 ~-10 stained_hardened_clay 8  
fill ~3 ~154 ~-20 ~3 ~154 ~-18 stained_hardened_clay 8  
fill ~4 ~154 ~-21 ~6 ~154 ~-21 stained_hardened_clay 8  
fill ~4 ~154 ~-20 ~6 ~154 ~-20 sea_lantern 0  
fill ~4 ~154 ~-19 ~4 ~162 ~-19 sea_lantern 0  
fill ~4 ~154 ~-18 ~6 ~154 ~-18 sea_lantern 0  
fill ~4 ~154 ~-17 ~6 ~154 ~-17 stained_hardened_clay 8  
fill ~6 ~154 ~-19 ~6 ~162 ~-19 sea_lantern 0  
fill ~7 ~154 ~-20 ~7 ~154 ~-18 stained_hardened_clay 8  
fill ~-13 ~155 ~-21 ~-13 ~156 ~-21 stained_hardened_clay 8  
fill ~-13 ~155 ~-20 ~-13 ~156 ~-20 glass 9  
fill ~-13 ~155 ~-19 ~-13 ~156 ~-19 glass 9  
fill ~-13 ~155 ~-18 ~-13 ~156 ~-18 glass 9  
fill ~-13 ~155 ~-17 ~-13 ~156 ~-17 stained_hardened_clay 8  
fill ~-12 ~155 ~-21 ~-10 ~155 ~-21 glass 9  
fill ~-12 ~155 ~-20 ~-10 ~155 ~-20 sea_lantern 0  
fill ~-12 ~155 ~-18 ~-10 ~155 ~-18 sea_lantern 0  
fill ~-12 ~155 ~-17 ~-10 ~155 ~-17 glass 9  
fill ~-9 ~155 ~-21 ~-9 ~156 ~-21 stained_hardened_clay 8  
fill ~-9 ~155 ~-20 ~-9 ~156 ~-20 glass 9  
fill ~-9 ~155 ~-19 ~-9 ~156 ~-19 glass 9  
fill ~-9 ~155 ~-18 ~-9 ~156 ~-18 glass 9  
fill ~-9 ~155 ~-17 ~-9 ~156 ~-17 stained_hardened_clay 8  
fill ~-5 ~155 ~-29 ~-5 ~156 ~-29 stained_hardened_clay 8  
fill ~-5 ~155 ~-28 ~-5 ~156 ~-28 glass 9  
fill ~-5 ~155 ~-27 ~-5 ~156 ~-27 glass 9  
fill ~-5 ~155 ~-26 ~-5 ~156 ~-26 glass 9  
fill ~-5 ~155 ~-25 ~-5 ~156 ~-25 stained_hardened_clay 8  
fill ~-5 ~155 ~-21 ~-5 ~162 ~-21 stained_hardened_clay 9  
fill ~-5 ~155 ~-20 ~-5 ~156 ~-20 glass 4  
fill ~-5 ~155 ~-19 ~-5 ~156 ~-19 glass 4  
fill ~-5 ~155 ~-18 ~-5 ~156 ~-18 glass 4  
fill ~-5 ~155 ~-17 ~-5 ~162 ~-17 stained_hardened_clay 9  
fill ~-5 ~155 ~-13 ~-5 ~156 ~-13 stained_hardened_clay 8  
fill ~-5 ~155 ~-12 ~-5 ~156 ~-12 glass 9  
fill ~-5 ~155 ~-11 ~-5 ~156 ~-11 glass 9  
fill ~-5 ~155 ~-10 ~-5 ~156 ~-10 glass 9  
fill ~-5 ~155 ~-9 ~-5 ~156 ~-9 stained_hardened_clay 8  
fill ~-4 ~155 ~-29 ~-2 ~155 ~-29 glass 9  
fill ~-4 ~155 ~-28 ~-2 ~155 ~-28 sea_lantern 0  
fill ~-4 ~155 ~-26 ~-2 ~155 ~-26 sea_lantern 0  
fill ~-4 ~155 ~-25 ~-2 ~155 ~-25 glass 9  
fill ~-4 ~155 ~-21 ~-2 ~155 ~-21 glass 4  
fill ~-4 ~155 ~-20 ~-2 ~155 ~-20 sea_lantern 0  
fill ~-4 ~155 ~-19 ~-2 ~155 ~-19 sea_lantern 0  
fill ~-4 ~155 ~-18 ~-2 ~155 ~-18 sea_lantern 0  
fill ~-4 ~155 ~-17 ~-2 ~155 ~-17 glass 4  
fill ~-4 ~155 ~-13 ~-2 ~155 ~-13 glass 9  
fill ~-4 ~155 ~-12 ~-2 ~155 ~-12 sea_lantern 0  
fill ~-4 ~155 ~-10 ~-2 ~155 ~-10 sea_lantern 0  
fill ~-4 ~155 ~-9 ~-2 ~155 ~-9 glass 9  
fill ~-1 ~155 ~-29 ~-1 ~156 ~-29 stained_hardened_clay 8  
fill ~-1 ~155 ~-28 ~-1 ~156 ~-28 glass 9  
fill ~-1 ~155 ~-27 ~-1 ~156 ~-27 glass 9  
fill ~-1 ~155 ~-26 ~-1 ~156 ~-26 glass 9  
fill ~-1 ~155 ~-25 ~-1 ~156 ~-25 stained_hardened_clay 8  
fill ~-1 ~155 ~-21 ~-1 ~162 ~-21 stained_hardened_clay 9  
fill ~-1 ~155 ~-20 ~-1 ~156 ~-20 glass 4  
fill ~-1 ~155 ~-19 ~-1 ~156 ~-19 glass 4  
fill ~-1 ~155 ~-18 ~-1 ~156 ~-18 glass 4  
fill ~-1 ~155 ~-17 ~-1 ~162 ~-17 stained_hardened_clay 9  
fill ~-1 ~155 ~-13 ~-1 ~156 ~-13 stained_hardened_clay 8  
fill ~-1 ~155 ~-12 ~-1 ~156 ~-12 glass 9  
fill ~-1 ~155 ~-11 ~-1 ~156 ~-11 glass 9  
fill ~-1 ~155 ~-10 ~-1 ~156 ~-10 glass 9  
fill ~-1 ~155 ~-9 ~-1 ~156 ~-9 stained_hardened_clay 8  
fill ~3 ~155 ~-21 ~3 ~156 ~-21 stained_hardened_clay 8  
fill ~3 ~155 ~-20 ~3 ~156 ~-20 glass 9  
fill ~3 ~155 ~-19 ~3 ~156 ~-19 glass 9  
fill ~3 ~155 ~-18 ~3 ~156 ~-18 glass 9  
fill ~3 ~155 ~-17 ~3 ~156 ~-17 stained_hardened_clay 8  
fill ~4 ~155 ~-21 ~6 ~155 ~-21 glass 9  
fill ~4 ~155 ~-20 ~6 ~155 ~-20 sea_lantern 0  
fill ~4 ~155 ~-18 ~6 ~155 ~-18 sea_lantern 0  
fill ~4 ~155 ~-17 ~6 ~155 ~-17 glass 9  
fill ~7 ~155 ~-21 ~7 ~156 ~-21 stained_hardened_clay 8  
fill ~7 ~155 ~-20 ~7 ~156 ~-20 glass 9  
fill ~7 ~155 ~-19 ~7 ~156 ~-19 glass 9  
fill ~7 ~155 ~-18 ~7 ~156 ~-18 glass 9  
fill ~7 ~155 ~-17 ~7 ~156 ~-17 stained_hardened_clay 8  
fill ~-12 ~156 ~-21 ~-10 ~156 ~-21 glass 9  
fill ~-12 ~156 ~-20 ~-10 ~156 ~-20 sea_lantern 0  
fill ~-12 ~156 ~-18 ~-10 ~156 ~-18 sea_lantern 0  
fill ~-12 ~156 ~-17 ~-10 ~156 ~-17 glass 9  
fill ~-4 ~156 ~-29 ~-2 ~156 ~-29 glass 9  
fill ~-4 ~156 ~-28 ~-2 ~156 ~-28 sea_lantern 0  
fill ~-4 ~156 ~-26 ~-2 ~156 ~-26 sea_lantern 0  
fill ~-4 ~156 ~-25 ~-2 ~156 ~-25 glass 9  
fill ~-4 ~156 ~-21 ~-2 ~156 ~-21 glass 4  
fill ~-4 ~156 ~-20 ~-2 ~156 ~-20 sea_lantern 0  
fill ~-4 ~156 ~-19 ~-2 ~156 ~-19 sea_lantern 0  
fill ~-4 ~156 ~-18 ~-2 ~156 ~-18 sea_lantern 0  
fill ~-4 ~156 ~-17 ~-2 ~156 ~-17 glass 4  
fill ~-4 ~156 ~-13 ~-2 ~156 ~-13 glass 9  
fill ~-4 ~156 ~-12 ~-2 ~156 ~-12 sea_lantern 0  
fill ~-4 ~156 ~-10 ~-2 ~156 ~-10 sea_lantern 0  
fill ~-4 ~156 ~-9 ~-2 ~156 ~-9 glass 9  
fill ~4 ~156 ~-21 ~6 ~156 ~-21 glass 9  
fill ~4 ~156 ~-20 ~6 ~156 ~-20 sea_lantern 0  
fill ~4 ~156 ~-18 ~6 ~156 ~-18 sea_lantern 0  
fill ~4 ~156 ~-17 ~6 ~156 ~-17 glass 9  
fill ~-13 ~157 ~-20 ~-13 ~157 ~-18 stained_hardened_clay 8  
fill ~-12 ~157 ~-21 ~-10 ~157 ~-21 stained_hardened_clay 8  
fill ~-12 ~157 ~-20 ~-10 ~157 ~-20 sea_lantern 0  
fill ~-12 ~157 ~-18 ~-10 ~157 ~-18 sea_lantern 0  
fill ~-12 ~157 ~-17 ~-10 ~157 ~-17 stained_hardened_clay 8  
fill ~-9 ~157 ~-20 ~-9 ~157 ~-18 stained_hardened_clay 8 
setblock ~-8 ~157 ~-20 stained_hardened_clay 4 
setblock ~-8 ~157 ~-18 stained_hardened_clay 4 
setblock ~-7 ~157 ~-19 stained_hardened_clay 4 
setblock ~-6 ~157 ~-20 stained_hardened_clay 4 
setblock ~-6 ~157 ~-18 stained_hardened_clay 4  
fill ~-5 ~157 ~-28 ~-5 ~157 ~-26 stained_hardened_clay 8  
fill ~-5 ~157 ~-20 ~-5 ~157 ~-17 stained_hardened_clay 9  
fill ~-5 ~157 ~-12 ~-5 ~157 ~-10 stained_hardened_clay 8  
fill ~-4 ~157 ~-29 ~-2 ~157 ~-29 stained_hardened_clay 8  
fill ~-4 ~157 ~-28 ~-2 ~157 ~-28 sea_lantern 0  
fill ~-4 ~157 ~-26 ~-2 ~157 ~-26 sea_lantern 0  
fill ~-4 ~157 ~-25 ~-2 ~157 ~-25 stained_hardened_clay 8 
setblock ~-4 ~157 ~-24 stained_hardened_clay 4 
setblock ~-4 ~157 ~-22 stained_hardened_clay 4  
fill ~-4 ~157 ~-21 ~-1 ~157 ~-21 stained_hardened_clay 9  
fill ~-4 ~157 ~-20 ~-2 ~157 ~-20 sea_lantern 0  
fill ~-4 ~157 ~-19 ~-2 ~157 ~-19 sea_lantern 0  
fill ~-4 ~157 ~-18 ~-2 ~157 ~-18 sea_lantern 0  
fill ~-4 ~157 ~-17 ~-1 ~157 ~-17 stained_hardened_clay 9 
setblock ~-4 ~157 ~-16 stained_hardened_clay 4 
setblock ~-4 ~157 ~-14 stained_hardened_clay 4  
fill ~-4 ~157 ~-13 ~-2 ~157 ~-13 stained_hardened_clay 8  
fill ~-4 ~157 ~-12 ~-2 ~157 ~-12 sea_lantern 0  
fill ~-4 ~157 ~-10 ~-2 ~157 ~-10 sea_lantern 0  
fill ~-4 ~157 ~-9 ~-2 ~157 ~-9 stained_hardened_clay 8 
setblock ~-3 ~157 ~-23 stained_hardened_clay 4 
setblock ~-3 ~157 ~-15 stained_hardened_clay 4 
setblock ~-2 ~157 ~-24 stained_hardened_clay 4 
setblock ~-2 ~157 ~-22 stained_hardened_clay 4 
setblock ~-2 ~157 ~-16 stained_hardened_clay 4 
setblock ~-2 ~157 ~-14 stained_hardened_clay 4  
fill ~-1 ~157 ~-28 ~-1 ~157 ~-26 stained_hardened_clay 8  
fill ~-1 ~157 ~-20 ~-1 ~157 ~-17 stained_hardened_clay 9  
fill ~-1 ~157 ~-12 ~-1 ~157 ~-10 stained_hardened_clay 8 
setblock ~0 ~157 ~-20 stained_hardened_clay 4 
setblock ~0 ~157 ~-18 stained_hardened_clay 4 
setblock ~1 ~157 ~-19 stained_hardened_clay 4 
setblock ~2 ~157 ~-20 stained_hardened_clay 4 
setblock ~2 ~157 ~-18 stained_hardened_clay 4  
fill ~3 ~157 ~-20 ~3 ~157 ~-18 stained_hardened_clay 8  
fill ~4 ~157 ~-21 ~6 ~157 ~-21 stained_hardened_clay 8  
fill ~4 ~157 ~-20 ~6 ~157 ~-20 sea_lantern 0  
fill ~4 ~157 ~-18 ~6 ~157 ~-18 sea_lantern 0  
fill ~4 ~157 ~-17 ~6 ~157 ~-17 stained_hardened_clay 8  
fill ~7 ~157 ~-20 ~7 ~157 ~-18 stained_hardened_clay 8  
fill ~-13 ~158 ~-21 ~-13 ~159 ~-21 stained_hardened_clay 8  
fill ~-13 ~158 ~-20 ~-13 ~159 ~-20 glass 9  
fill ~-13 ~158 ~-19 ~-13 ~159 ~-19 glass 9  
fill ~-13 ~158 ~-18 ~-13 ~159 ~-18 glass 9  
fill ~-13 ~158 ~-17 ~-13 ~159 ~-17 stained_hardened_clay 8  
fill ~-12 ~158 ~-21 ~-10 ~158 ~-21 glass 9  
fill ~-12 ~158 ~-20 ~-10 ~158 ~-20 sea_lantern 0  
fill ~-12 ~158 ~-18 ~-10 ~158 ~-18 sea_lantern 0  
fill ~-12 ~158 ~-17 ~-10 ~158 ~-17 glass 9  
fill ~-9 ~158 ~-21 ~-9 ~159 ~-21 stained_hardened_clay 8  
fill ~-9 ~158 ~-20 ~-9 ~159 ~-20 glass 9  
fill ~-9 ~158 ~-19 ~-9 ~159 ~-19 glass 9  
fill ~-9 ~158 ~-18 ~-9 ~159 ~-18 glass 9  
fill ~-9 ~158 ~-17 ~-9 ~159 ~-17 stained_hardened_clay 8  
fill ~-5 ~158 ~-29 ~-5 ~159 ~-29 stained_hardened_clay 8  
fill ~-5 ~158 ~-28 ~-5 ~159 ~-28 glass 9  
fill ~-5 ~158 ~-27 ~-5 ~159 ~-27 glass 9  
fill ~-5 ~158 ~-26 ~-5 ~159 ~-26 glass 9  
fill ~-5 ~158 ~-25 ~-5 ~159 ~-25 stained_hardened_clay 8  
fill ~-5 ~158 ~-20 ~-5 ~159 ~-20 glass 5  
fill ~-5 ~158 ~-19 ~-5 ~159 ~-19 glass 5  
fill ~-5 ~158 ~-18 ~-5 ~159 ~-18 glass 5  
fill ~-5 ~158 ~-13 ~-5 ~159 ~-13 stained_hardened_clay 8  
fill ~-5 ~158 ~-12 ~-5 ~159 ~-12 glass 9  
fill ~-5 ~158 ~-11 ~-5 ~159 ~-11 glass 9  
fill ~-5 ~158 ~-10 ~-5 ~159 ~-10 glass 9  
fill ~-5 ~158 ~-9 ~-5 ~159 ~-9 stained_hardened_clay 8  
fill ~-4 ~158 ~-29 ~-2 ~158 ~-29 glass 9  
fill ~-4 ~158 ~-28 ~-2 ~158 ~-28 sea_lantern 0  
fill ~-4 ~158 ~-26 ~-2 ~158 ~-26 sea_lantern 0  
fill ~-4 ~158 ~-25 ~-2 ~158 ~-25 glass 9  
fill ~-4 ~158 ~-21 ~-2 ~158 ~-21 glass 5  
fill ~-4 ~158 ~-20 ~-2 ~158 ~-20 sea_lantern 0  
fill ~-4 ~158 ~-19 ~-2 ~158 ~-19 sea_lantern 0  
fill ~-4 ~158 ~-18 ~-2 ~158 ~-18 sea_lantern 0  
fill ~-4 ~158 ~-17 ~-2 ~158 ~-17 glass 5  
fill ~-4 ~158 ~-13 ~-2 ~158 ~-13 glass 9  
fill ~-4 ~158 ~-12 ~-2 ~158 ~-12 sea_lantern 0  
fill ~-4 ~158 ~-10 ~-2 ~158 ~-10 sea_lantern 0  
fill ~-4 ~158 ~-9 ~-2 ~158 ~-9 glass 9  
fill ~-1 ~158 ~-29 ~-1 ~159 ~-29 stained_hardened_clay 8  
fill ~-1 ~158 ~-28 ~-1 ~159 ~-28 glass 9  
fill ~-1 ~158 ~-27 ~-1 ~159 ~-27 glass 9  
fill ~-1 ~158 ~-26 ~-1 ~159 ~-26 glass 9  
fill ~-1 ~158 ~-25 ~-1 ~159 ~-25 stained_hardened_clay 8  
fill ~-1 ~158 ~-20 ~-1 ~159 ~-20 glass 5  
fill ~-1 ~158 ~-19 ~-1 ~159 ~-19 glass 5  
fill ~-1 ~158 ~-18 ~-1 ~159 ~-18 glass 5  
fill ~-1 ~158 ~-13 ~-1 ~159 ~-13 stained_hardened_clay 8  
fill ~-1 ~158 ~-12 ~-1 ~159 ~-12 glass 9  
fill ~-1 ~158 ~-11 ~-1 ~159 ~-11 glass 9  
fill ~-1 ~158 ~-10 ~-1 ~159 ~-10 glass 9  
fill ~-1 ~158 ~-9 ~-1 ~159 ~-9 stained_hardened_clay 8  
fill ~3 ~158 ~-21 ~3 ~159 ~-21 stained_hardened_clay 8  
fill ~3 ~158 ~-20 ~3 ~159 ~-20 glass 9  
fill ~3 ~158 ~-19 ~3 ~159 ~-19 glass 9  
fill ~3 ~158 ~-18 ~3 ~159 ~-18 glass 9  
fill ~3 ~158 ~-17 ~3 ~159 ~-17 stained_hardened_clay 8  
fill ~4 ~158 ~-21 ~6 ~158 ~-21 glass 9  
fill ~4 ~158 ~-20 ~6 ~158 ~-20 sea_lantern 0  
fill ~4 ~158 ~-18 ~6 ~158 ~-18 sea_lantern 0  
fill ~4 ~158 ~-17 ~6 ~158 ~-17 glass 9  
fill ~7 ~158 ~-21 ~7 ~159 ~-21 stained_hardened_clay 8  
fill ~7 ~158 ~-20 ~7 ~159 ~-20 glass 9  
fill ~7 ~158 ~-19 ~7 ~159 ~-19 glass 9  
fill ~7 ~158 ~-18 ~7 ~159 ~-18 glass 9  
fill ~7 ~158 ~-17 ~7 ~159 ~-17 stained_hardened_clay 8  
fill ~-12 ~159 ~-21 ~-10 ~159 ~-21 glass 9  
fill ~-12 ~159 ~-20 ~-10 ~159 ~-20 sea_lantern 0  
fill ~-12 ~159 ~-18 ~-10 ~159 ~-18 sea_lantern 0  
fill ~-12 ~159 ~-17 ~-10 ~159 ~-17 glass 9  
fill ~-4 ~159 ~-29 ~-2 ~159 ~-29 glass 9  
fill ~-4 ~159 ~-28 ~-2 ~159 ~-28 sea_lantern 0  
fill ~-4 ~159 ~-26 ~-2 ~159 ~-26 sea_lantern 0  
fill ~-4 ~159 ~-25 ~-2 ~159 ~-25 glass 9  
fill ~-4 ~159 ~-21 ~-2 ~159 ~-21 glass 5  
fill ~-4 ~159 ~-20 ~-2 ~159 ~-20 sea_lantern 0  
fill ~-4 ~159 ~-19 ~-2 ~159 ~-19 sea_lantern 0  
fill ~-4 ~159 ~-18 ~-2 ~159 ~-18 sea_lantern 0  
fill ~-4 ~159 ~-17 ~-2 ~159 ~-17 glass 5  
fill ~-4 ~159 ~-13 ~-2 ~159 ~-13 glass 9  
fill ~-4 ~159 ~-12 ~-2 ~159 ~-12 sea_lantern 0  
fill ~-4 ~159 ~-10 ~-2 ~159 ~-10 sea_lantern 0  
fill ~-4 ~159 ~-9 ~-2 ~159 ~-9 glass 9  
fill ~4 ~159 ~-21 ~6 ~159 ~-21 glass 9  
fill ~4 ~159 ~-20 ~6 ~159 ~-20 sea_lantern 0  
fill ~4 ~159 ~-18 ~6 ~159 ~-18 sea_lantern 0  
fill ~4 ~159 ~-17 ~6 ~159 ~-17 glass 9  
fill ~-13 ~160 ~-20 ~-13 ~160 ~-18 stained_hardened_clay 8  
fill ~-12 ~160 ~-21 ~-10 ~160 ~-21 stained_hardened_clay 8  
fill ~-12 ~160 ~-20 ~-10 ~160 ~-20 sea_lantern 0  
fill ~-12 ~160 ~-18 ~-10 ~160 ~-18 sea_lantern 0  
fill ~-12 ~160 ~-17 ~-10 ~160 ~-17 stained_hardened_clay 8  
fill ~-9 ~160 ~-20 ~-9 ~160 ~-18 stained_hardened_clay 8 
setblock ~-8 ~160 ~-20 stained_hardened_clay 4 
setblock ~-8 ~160 ~-18 stained_hardened_clay 4 
setblock ~-7 ~160 ~-19 stained_hardened_clay 4 
setblock ~-6 ~160 ~-20 stained_hardened_clay 4 
setblock ~-6 ~160 ~-18 stained_hardened_clay 4  
fill ~-5 ~160 ~-28 ~-5 ~160 ~-26 stained_hardened_clay 8  
fill ~-5 ~160 ~-20 ~-5 ~160 ~-17 stained_hardened_clay 9  
fill ~-5 ~160 ~-12 ~-5 ~160 ~-10 stained_hardened_clay 8  
fill ~-4 ~160 ~-29 ~-2 ~160 ~-29 stained_hardened_clay 8  
fill ~-4 ~160 ~-28 ~-2 ~160 ~-28 sea_lantern 0  
fill ~-4 ~160 ~-26 ~-2 ~160 ~-26 sea_lantern 0  
fill ~-4 ~160 ~-25 ~-2 ~160 ~-25 stained_hardened_clay 8 
setblock ~-4 ~160 ~-24 stained_hardened_clay 4 
setblock ~-4 ~160 ~-22 stained_hardened_clay 4  
fill ~-4 ~160 ~-21 ~-1 ~160 ~-21 stained_hardened_clay 9  
fill ~-4 ~160 ~-20 ~-2 ~160 ~-20 sea_lantern 0  
fill ~-4 ~160 ~-19 ~-2 ~160 ~-19 sea_lantern 0  
fill ~-4 ~160 ~-18 ~-2 ~160 ~-18 sea_lantern 0  
fill ~-4 ~160 ~-17 ~-1 ~160 ~-17 stained_hardened_clay 9 
setblock ~-4 ~160 ~-16 stained_hardened_clay 4 
setblock ~-4 ~160 ~-14 stained_hardened_clay 4  
fill ~-4 ~160 ~-13 ~-2 ~160 ~-13 stained_hardened_clay 8  
fill ~-4 ~160 ~-12 ~-2 ~160 ~-12 sea_lantern 0  
fill ~-4 ~160 ~-10 ~-2 ~160 ~-10 sea_lantern 0  
fill ~-4 ~160 ~-9 ~-2 ~160 ~-9 stained_hardened_clay 8 
setblock ~-3 ~160 ~-23 stained_hardened_clay 4 
setblock ~-3 ~160 ~-15 stained_hardened_clay 4 
setblock ~-2 ~160 ~-24 stained_hardened_clay 4 
setblock ~-2 ~160 ~-22 stained_hardened_clay 4 
setblock ~-2 ~160 ~-16 stained_hardened_clay 4 
setblock ~-2 ~160 ~-14 stained_hardened_clay 4  
fill ~-1 ~160 ~-28 ~-1 ~160 ~-26 stained_hardened_clay 8  
fill ~-1 ~160 ~-20 ~-1 ~160 ~-17 stained_hardened_clay 9  
fill ~-1 ~160 ~-12 ~-1 ~160 ~-10 stained_hardened_clay 8 
setblock ~0 ~160 ~-20 stained_hardened_clay 4 
setblock ~0 ~160 ~-18 stained_hardened_clay 4 
setblock ~1 ~160 ~-19 stained_hardened_clay 4 
setblock ~2 ~160 ~-20 stained_hardened_clay 4 
setblock ~2 ~160 ~-18 stained_hardened_clay 4  
fill ~3 ~160 ~-20 ~3 ~160 ~-18 stained_hardened_clay 8  
fill ~4 ~160 ~-21 ~6 ~160 ~-21 stained_hardened_clay 8  
fill ~4 ~160 ~-20 ~6 ~160 ~-20 sea_lantern 0  
fill ~4 ~160 ~-18 ~6 ~160 ~-18 sea_lantern 0  
fill ~4 ~160 ~-17 ~6 ~160 ~-17 stained_hardened_clay 8  
fill ~7 ~160 ~-20 ~7 ~160 ~-18 stained_hardened_clay 8  
fill ~-13 ~161 ~-21 ~-13 ~162 ~-21 stained_hardened_clay 8  
fill ~-13 ~161 ~-20 ~-13 ~162 ~-20 glass 9  
fill ~-13 ~161 ~-19 ~-13 ~162 ~-19 glass 9  
fill ~-13 ~161 ~-18 ~-13 ~162 ~-18 glass 9  
fill ~-13 ~161 ~-17 ~-13 ~162 ~-17 stained_hardened_clay 8  
fill ~-12 ~161 ~-21 ~-10 ~161 ~-21 glass 9  
fill ~-12 ~161 ~-20 ~-10 ~161 ~-20 sea_lantern 0  
fill ~-12 ~161 ~-18 ~-10 ~161 ~-18 sea_lantern 0  
fill ~-12 ~161 ~-17 ~-10 ~161 ~-17 glass 9  
fill ~-9 ~161 ~-21 ~-9 ~162 ~-21 stained_hardened_clay 8  
fill ~-9 ~161 ~-20 ~-9 ~162 ~-20 glass 9  
fill ~-9 ~161 ~-19 ~-9 ~162 ~-19 glass 9  
fill ~-9 ~161 ~-18 ~-9 ~162 ~-18 glass 9  
fill ~-9 ~161 ~-17 ~-9 ~162 ~-17 stained_hardened_clay 8  
fill ~-5 ~161 ~-29 ~-5 ~162 ~-29 stained_hardened_clay 8  
fill ~-5 ~161 ~-28 ~-5 ~162 ~-28 glass 9  
fill ~-5 ~161 ~-27 ~-5 ~162 ~-27 glass 9  
fill ~-5 ~161 ~-26 ~-5 ~162 ~-26 glass 9  
fill ~-5 ~161 ~-25 ~-5 ~162 ~-25 stained_hardened_clay 8  
fill ~-5 ~161 ~-20 ~-5 ~162 ~-20 glass 0  
fill ~-5 ~161 ~-19 ~-5 ~162 ~-19 glass 0  
fill ~-5 ~161 ~-18 ~-5 ~162 ~-18 glass 0  
fill ~-5 ~161 ~-13 ~-5 ~162 ~-13 stained_hardened_clay 8  
fill ~-5 ~161 ~-12 ~-5 ~162 ~-12 glass 9  
fill ~-5 ~161 ~-11 ~-5 ~162 ~-11 glass 9  
fill ~-5 ~161 ~-10 ~-5 ~162 ~-10 glass 9  
fill ~-5 ~161 ~-9 ~-5 ~162 ~-9 stained_hardened_clay 8  
fill ~-4 ~161 ~-29 ~-2 ~161 ~-29 glass 9  
fill ~-4 ~161 ~-28 ~-2 ~161 ~-28 sea_lantern 0  
fill ~-4 ~161 ~-26 ~-2 ~161 ~-26 sea_lantern 0  
fill ~-4 ~161 ~-25 ~-2 ~161 ~-25 glass 9  
fill ~-4 ~161 ~-21 ~-2 ~161 ~-21 glass 0  
fill ~-4 ~161 ~-20 ~-2 ~161 ~-20 sea_lantern 0  
fill ~-4 ~161 ~-19 ~-2 ~161 ~-19 sea_lantern 0  
fill ~-4 ~161 ~-18 ~-2 ~161 ~-18 sea_lantern 0  
fill ~-4 ~161 ~-17 ~-2 ~161 ~-17 glass 0  
fill ~-4 ~161 ~-13 ~-2 ~161 ~-13 glass 9  
fill ~-4 ~161 ~-12 ~-2 ~161 ~-12 sea_lantern 0  
fill ~-4 ~161 ~-10 ~-2 ~161 ~-10 sea_lantern 0  
fill ~-4 ~161 ~-9 ~-2 ~161 ~-9 glass 9  
fill ~-1 ~161 ~-29 ~-1 ~162 ~-29 stained_hardened_clay 8  
fill ~-1 ~161 ~-28 ~-1 ~162 ~-28 glass 9  
fill ~-1 ~161 ~-27 ~-1 ~162 ~-27 glass 9  
fill ~-1 ~161 ~-26 ~-1 ~162 ~-26 glass 9  
fill ~-1 ~161 ~-25 ~-1 ~162 ~-25 stained_hardened_clay 8  
fill ~-1 ~161 ~-20 ~-1 ~162 ~-20 glass 0  
fill ~-1 ~161 ~-19 ~-1 ~162 ~-19 glass 0  
fill ~-1 ~161 ~-18 ~-1 ~162 ~-18 glass 0  
fill ~-1 ~161 ~-13 ~-1 ~162 ~-13 stained_hardened_clay 8  
fill ~-1 ~161 ~-12 ~-1 ~162 ~-12 glass 9  
fill ~-1 ~161 ~-11 ~-1 ~162 ~-11 glass 9  
fill ~-1 ~161 ~-10 ~-1 ~162 ~-10 glass 9  
fill ~-1 ~161 ~-9 ~-1 ~162 ~-9 stained_hardened_clay 8  
fill ~3 ~161 ~-21 ~3 ~162 ~-21 stained_hardened_clay 8  
fill ~3 ~161 ~-20 ~3 ~162 ~-20 glass 9  
fill ~3 ~161 ~-19 ~3 ~162 ~-19 glass 9  
fill ~3 ~161 ~-18 ~3 ~162 ~-18 glass 9  
fill ~3 ~161 ~-17 ~3 ~162 ~-17 stained_hardened_clay 8  
fill ~4 ~161 ~-21 ~6 ~161 ~-21 glass 9  
fill ~4 ~161 ~-20 ~6 ~161 ~-20 sea_lantern 0  
fill ~4 ~161 ~-18 ~6 ~161 ~-18 sea_lantern 0  
fill ~4 ~161 ~-17 ~6 ~161 ~-17 glass 9  
fill ~7 ~161 ~-21 ~7 ~162 ~-21 stained_hardened_clay 8  
fill ~7 ~161 ~-20 ~7 ~162 ~-20 glass 9  
fill ~7 ~161 ~-19 ~7 ~162 ~-19 glass 9  
fill ~7 ~161 ~-18 ~7 ~162 ~-18 glass 9  
fill ~7 ~161 ~-17 ~7 ~162 ~-17 stained_hardened_clay 8  
fill ~-12 ~162 ~-21 ~-10 ~162 ~-21 glass 9  
fill ~-12 ~162 ~-20 ~-10 ~162 ~-20 sea_lantern 0  
fill ~-12 ~162 ~-18 ~-10 ~162 ~-18 sea_lantern 0  
fill ~-12 ~162 ~-17 ~-10 ~162 ~-17 glass 9  
fill ~-4 ~162 ~-29 ~-2 ~162 ~-29 glass 9  
fill ~-4 ~162 ~-28 ~-2 ~162 ~-28 sea_lantern 0  
fill ~-4 ~162 ~-26 ~-2 ~162 ~-26 sea_lantern 0  
fill ~-4 ~162 ~-25 ~-2 ~162 ~-25 glass 9  
fill ~-4 ~162 ~-21 ~-2 ~162 ~-21 glass 0  
fill ~-4 ~162 ~-20 ~-2 ~162 ~-20 sea_lantern 0  
fill ~-4 ~162 ~-19 ~-2 ~162 ~-19 sea_lantern 0  
fill ~-4 ~162 ~-18 ~-2 ~162 ~-18 sea_lantern 0  
fill ~-4 ~162 ~-17 ~-2 ~162 ~-17 glass 0  
fill ~-4 ~162 ~-13 ~-2 ~162 ~-13 glass 9  
fill ~-4 ~162 ~-12 ~-2 ~162 ~-12 sea_lantern 0  
fill ~-4 ~162 ~-10 ~-2 ~162 ~-10 sea_lantern 0  
fill ~-4 ~162 ~-9 ~-2 ~162 ~-9 glass 9  
fill ~4 ~162 ~-21 ~6 ~162 ~-21 glass 9  
fill ~4 ~162 ~-20 ~6 ~162 ~-20 sea_lantern 0  
fill ~4 ~162 ~-18 ~6 ~162 ~-18 sea_lantern 0  
fill ~4 ~162 ~-17 ~6 ~162 ~-17 glass 9  
fill ~-13 ~163 ~-20 ~-13 ~163 ~-18 stained_hardened_clay 8  
fill ~-12 ~163 ~-21 ~-10 ~163 ~-21 stained_hardened_clay 8  
fill ~-12 ~163 ~-20 ~-10 ~163 ~-20 glass 9  
fill ~-12 ~163 ~-19 ~-10 ~163 ~-19 glass 9  
fill ~-12 ~163 ~-18 ~-10 ~163 ~-18 glass 9  
fill ~-12 ~163 ~-17 ~-10 ~163 ~-17 stained_hardened_clay 8  
fill ~-9 ~163 ~-20 ~-9 ~163 ~-18 stained_hardened_clay 8  
fill ~-5 ~163 ~-28 ~-5 ~163 ~-26 stained_hardened_clay 8  
fill ~-5 ~163 ~-20 ~-5 ~163 ~-18 stained_hardened_clay 9  
fill ~-5 ~163 ~-12 ~-5 ~163 ~-10 stained_hardened_clay 8  
fill ~-4 ~163 ~-29 ~-2 ~163 ~-29 stained_hardened_clay 8  
fill ~-4 ~163 ~-28 ~-2 ~163 ~-28 glass 9  
fill ~-4 ~163 ~-27 ~-2 ~163 ~-27 glass 9  
fill ~-4 ~163 ~-26 ~-2 ~163 ~-26 glass 9  
fill ~-4 ~163 ~-25 ~-2 ~163 ~-25 stained_hardened_clay 8  
fill ~-4 ~163 ~-21 ~-2 ~163 ~-21 stained_hardened_clay 9  
fill ~-4 ~163 ~-20 ~-2 ~163 ~-20 sea_lantern 0  
fill ~-4 ~163 ~-19 ~-2 ~163 ~-19 sea_lantern 0  
fill ~-4 ~163 ~-18 ~-2 ~163 ~-18 sea_lantern 0    
fill ~-4 ~163 ~-17 ~-2 ~163 ~-17 stained_hardened_clay 9  
fill ~-4 ~163 ~-13 ~-2 ~163 ~-13 stained_hardened_clay 8  
fill ~-4 ~163 ~-12 ~-2 ~163 ~-12 glass 9  
fill ~-4 ~163 ~-11 ~-2 ~163 ~-11 glass 9  
fill ~-4 ~163 ~-10 ~-2 ~163 ~-10 glass 9  
fill ~-4 ~163 ~-9 ~-2 ~163 ~-9 stained_hardened_clay 8  
fill ~-1 ~163 ~-28 ~-1 ~163 ~-26 stained_hardened_clay 8  
fill ~-1 ~163 ~-20 ~-1 ~163 ~-18 stained_hardened_clay 9  
fill ~-1 ~163 ~-12 ~-1 ~163 ~-10 stained_hardened_clay 8  
fill ~3 ~163 ~-20 ~3 ~163 ~-18 stained_hardened_clay 8  
fill ~4 ~163 ~-21 ~6 ~163 ~-21 stained_hardened_clay 8  
fill ~4 ~163 ~-20 ~6 ~163 ~-20 glass 9  
fill ~4 ~163 ~-19 ~6 ~163 ~-19 glass 9  
fill ~4 ~163 ~-18 ~6 ~163 ~-18 glass 9  
fill ~4 ~163 ~-17 ~6 ~163 ~-17 stained_hardened_clay 8  
fill ~7 ~163 ~-20 ~7 ~163 ~-18 stained_hardened_clay 8 
setblock ~-5 ~164 ~-20 stained_hardened_clay 4 
setblock ~-5 ~164 ~-18 stained_hardened_clay 4 
setblock ~-4 ~164 ~-21 stained_hardened_clay 4  
fill ~-4 ~164 ~-20 ~-2 ~164 ~-20 stained_hardened_clay 9  
fill ~-4 ~164 ~-19 ~-2 ~164 ~-19 stained_hardened_clay 9  
fill ~-4 ~164 ~-18 ~-2 ~164 ~-18 stained_hardened_clay 9 
setblock ~-4 ~164 ~-17 stained_hardened_clay 4 
setblock ~-2 ~164 ~-21 stained_hardened_clay 4 
setblock ~-2 ~164 ~-17 stained_hardened_clay 4 
setblock ~-1 ~164 ~-20 stained_hardened_clay 4 
setblock ~-1 ~164 ~-18 stained_hardened_clay 4  
fill ~-5 ~165 ~-19 ~-5 ~166 ~-19 stained_hardened_clay 4  
fill ~-4 ~165 ~-19 ~-4 ~175 ~-19 prismarine 1  
fill ~-3 ~165 ~-21 ~-3 ~166 ~-21 stained_hardened_clay 4  
fill ~-3 ~165 ~-20 ~-3 ~175 ~-20 prismarine 1  
fill ~-3 ~165 ~-18 ~-3 ~175 ~-18 prismarine 1  
fill ~-3 ~165 ~-17 ~-3 ~166 ~-17 stained_hardened_clay 4  
fill ~-2 ~165 ~-19 ~-2 ~175 ~-19 prismarine 1  
fill ~-1 ~165 ~-19 ~-1 ~166 ~-19 stained_hardened_clay 4  
fill ~-5 ~167 ~-20 ~-5 ~168 ~-20 stained_hardened_clay 4  
fill ~-5 ~167 ~-18 ~-5 ~168 ~-18 stained_hardened_clay 4  
fill ~-4 ~167 ~-21 ~-4 ~168 ~-21 stained_hardened_clay 4  
fill ~-4 ~167 ~-17 ~-4 ~168 ~-17 stained_hardened_clay 4  
fill ~-2 ~167 ~-21 ~-2 ~168 ~-21 stained_hardened_clay 4  
fill ~-2 ~167 ~-17 ~-2 ~168 ~-17 stained_hardened_clay 4  
fill ~-1 ~167 ~-20 ~-1 ~168 ~-20 stained_hardened_clay 4  
fill ~-1 ~167 ~-18 ~-1 ~168 ~-18 stained_hardened_clay 4  
fill ~-5 ~169 ~-19 ~-5 ~170 ~-19 stained_hardened_clay 4  
fill ~-3 ~169 ~-21 ~-3 ~170 ~-21 stained_hardened_clay 4  
fill ~-3 ~169 ~-17 ~-3 ~170 ~-17 stained_hardened_clay 4  
fill ~-1 ~169 ~-19 ~-1 ~170 ~-19 stained_hardened_clay 4  
fill ~-5 ~171 ~-20 ~-5 ~172 ~-20 stained_hardened_clay 4  
fill ~-5 ~171 ~-18 ~-5 ~172 ~-18 stained_hardened_clay 4  
fill ~-4 ~171 ~-21 ~-4 ~172 ~-21 stained_hardened_clay 4  
fill ~-4 ~171 ~-17 ~-4 ~172 ~-17 stained_hardened_clay 4  
fill ~-2 ~171 ~-21 ~-2 ~172 ~-21 stained_hardened_clay 4  
fill ~-2 ~171 ~-17 ~-2 ~172 ~-17 stained_hardened_clay 4  
fill ~-1 ~171 ~-20 ~-1 ~172 ~-20 stained_hardened_clay 4  
fill ~-1 ~171 ~-18 ~-1 ~172 ~-18 stained_hardened_clay 4  
fill ~-5 ~173 ~-19 ~-5 ~174 ~-19 stained_hardened_clay 4  
fill ~-3 ~173 ~-21 ~-3 ~174 ~-21 stained_hardened_clay 4  
fill ~-3 ~173 ~-17 ~-3 ~174 ~-17 stained_hardened_clay 4  
fill ~-1 ~173 ~-19 ~-1 ~174 ~-19 stained_hardened_clay 4  
fill ~-6 ~175 ~-98 ~-6 ~175 ~-86 stained_hardened_clay 0  
fill ~-6 ~175 ~-84 ~-6 ~175 ~-72 stained_hardened_clay 0  
fill ~-6 ~175 ~-70 ~-6 ~175 ~-58 stained_hardened_clay 0  
fill ~-6 ~175 ~-56 ~-6 ~175 ~-44 stained_hardened_clay 0  
fill ~-6 ~175 ~-42 ~-6 ~175 ~-30 stained_hardened_clay 0  
fill ~-6 ~175 ~-8 ~-6 ~175 ~4 stained_hardened_clay 0  
fill ~-6 ~175 ~6 ~-6 ~175 ~18 stained_hardened_clay 0  
fill ~-6 ~175 ~20 ~-6 ~175 ~32 stained_hardened_clay 0  
fill ~-6 ~175 ~34 ~-6 ~175 ~46 stained_hardened_clay 0  
fill ~-6 ~175 ~48 ~-6 ~175 ~60 stained_hardened_clay 0 
setblock ~-5 ~175 ~-20 stained_hardened_clay 4 
setblock ~-5 ~175 ~-18 stained_hardened_clay 4 
setblock ~-4 ~175 ~-21 stained_hardened_clay 4 
setblock ~-4 ~175 ~-17 stained_hardened_clay 4 
setblock ~-2 ~175 ~-21 stained_hardened_clay 4 
setblock ~-2 ~175 ~-17 stained_hardened_clay 4 
setblock ~-1 ~175 ~-20 stained_hardened_clay 4 
setblock ~-1 ~175 ~-18 stained_hardened_clay 4 
setblock ~-5 ~176 ~-99 stained_hardened_clay 0  
fill ~-5 ~176 ~-98 ~-5 ~176 ~-97 wool 11  
fill ~-5 ~176 ~-96 ~-5 ~176 ~-93 lapis_block 0 
setblock ~-5 ~176 ~-92 wool 11  
fill ~-5 ~176 ~-91 ~-5 ~176 ~-86 lapis_block 0 
setblock ~-5 ~176 ~-85 stained_hardened_clay 0  
fill ~-5 ~176 ~-84 ~-5 ~176 ~-82 lapis_block 0 
setblock ~-5 ~176 ~-81 wool 11  
fill ~-5 ~176 ~-80 ~-5 ~176 ~-78 lapis_block 0  
fill ~-5 ~176 ~-77 ~-5 ~176 ~-75 wool 11  
fill ~-5 ~176 ~-74 ~-5 ~176 ~-72 lapis_block 0 
