fill ~1 ~0 ~16 ~23 ~0 ~16 stone 0  
fill ~1 ~0 ~17 ~23 ~0 ~17 stone 0  
fill ~1 ~0 ~18 ~23 ~0 ~18 stone 0  
fill ~1 ~0 ~19 ~23 ~0 ~19 stone 0  
fill ~1 ~0 ~20 ~23 ~0 ~20 stone 0  
fill ~1 ~0 ~21 ~23 ~0 ~21 stone 0  
fill ~1 ~0 ~22 ~23 ~0 ~22 stone 0  
fill ~1 ~0 ~23 ~48 ~0 ~23 stonebrick 3  
fill ~1 ~0 ~24 ~48 ~0 ~24 stonebrick 3  
fill ~1 ~0 ~25 ~23 ~0 ~25 stone 0  
fill ~1 ~0 ~26 ~23 ~0 ~26 stone 0  
fill ~1 ~0 ~27 ~23 ~0 ~27 stone 0  
fill ~1 ~0 ~28 ~23 ~0 ~28 stone 0  
fill ~1 ~0 ~29 ~23 ~0 ~29 stone 0  
fill ~1 ~0 ~30 ~23 ~0 ~30 stone 0  
fill ~1 ~0 ~31 ~23 ~0 ~31 stone 0  
fill ~17 ~0 ~0 ~23 ~0 ~0 stone 0  
fill ~17 ~0 ~1 ~23 ~0 ~1 stone 0  
fill ~17 ~0 ~2 ~23 ~0 ~2 stone 0  
fill ~17 ~0 ~3 ~23 ~0 ~3 stone 0  
fill ~17 ~0 ~4 ~23 ~0 ~4 stone 0  
fill ~17 ~0 ~5 ~23 ~0 ~5 stone 0  
fill ~17 ~0 ~6 ~23 ~0 ~6 stone 0  
fill ~17 ~0 ~7 ~23 ~0 ~7 stone 0  
fill ~17 ~0 ~8 ~23 ~0 ~8 stone 0  
fill ~17 ~0 ~9 ~23 ~0 ~9 stone 0  
fill ~17 ~0 ~10 ~23 ~0 ~10 stone 0  
fill ~17 ~0 ~11 ~23 ~0 ~11 stone 0  
fill ~17 ~0 ~12 ~23 ~0 ~12 stone 0  
fill ~17 ~0 ~13 ~23 ~0 ~13 stone 0  
fill ~17 ~0 ~14 ~23 ~0 ~14 stone 0  
fill ~17 ~0 ~15 ~23 ~0 ~15 stone 0  
fill ~17 ~0 ~32 ~23 ~0 ~32 stone 0  
fill ~17 ~0 ~33 ~23 ~0 ~33 stone 0  
fill ~17 ~0 ~34 ~23 ~0 ~34 stone 0  
fill ~17 ~0 ~35 ~23 ~0 ~35 stone 0  
fill ~17 ~0 ~36 ~23 ~0 ~36 stone 0  
fill ~17 ~0 ~37 ~23 ~0 ~37 stone 0  
fill ~17 ~0 ~38 ~23 ~0 ~38 stone 0  
fill ~17 ~0 ~39 ~23 ~0 ~39 stone 0  
fill ~17 ~0 ~40 ~23 ~0 ~40 stone 0  
fill ~17 ~0 ~41 ~23 ~0 ~41 stone 0  
fill ~17 ~0 ~42 ~23 ~0 ~42 stone 0  
fill ~17 ~0 ~43 ~23 ~0 ~43 stone 0  
fill ~17 ~0 ~44 ~23 ~0 ~44 stone 0  
fill ~17 ~0 ~45 ~23 ~0 ~45 stone 0  
fill ~17 ~0 ~46 ~23 ~0 ~46 stone 0  
fill ~17 ~0 ~47 ~23 ~0 ~47 stone 0  
fill ~24 ~0 ~0 ~25 ~0 ~0 stonebrick 3  
fill ~24 ~0 ~1 ~25 ~0 ~1 stonebrick 3  
fill ~24 ~0 ~2 ~25 ~0 ~2 stonebrick 3  
fill ~24 ~0 ~3 ~25 ~0 ~3 stonebrick 3  
fill ~24 ~0 ~4 ~25 ~0 ~4 stonebrick 3  
fill ~24 ~0 ~5 ~25 ~0 ~5 stonebrick 3  
fill ~24 ~0 ~6 ~25 ~0 ~6 stonebrick 3  
fill ~24 ~0 ~7 ~25 ~0 ~7 stonebrick 3  
fill ~24 ~0 ~8 ~25 ~0 ~8 stonebrick 3  
fill ~24 ~0 ~9 ~25 ~0 ~9 stonebrick 3  
fill ~24 ~0 ~10 ~25 ~0 ~10 stonebrick 3  
fill ~24 ~0 ~11 ~25 ~0 ~11 stonebrick 3  
fill ~24 ~0 ~12 ~25 ~0 ~12 stonebrick 3  
fill ~24 ~0 ~13 ~25 ~0 ~13 stonebrick 3  
fill ~24 ~0 ~14 ~25 ~0 ~14 stonebrick 3  
fill ~24 ~0 ~15 ~25 ~0 ~15 stonebrick 3  
fill ~24 ~0 ~16 ~25 ~0 ~16 stonebrick 3  
fill ~24 ~0 ~17 ~25 ~0 ~17 stonebrick 3  
fill ~24 ~0 ~18 ~25 ~0 ~18 stonebrick 3  
fill ~24 ~0 ~19 ~25 ~0 ~19 stonebrick 3  
fill ~24 ~0 ~20 ~25 ~0 ~20 stonebrick 3  
fill ~24 ~0 ~21 ~25 ~0 ~21 stonebrick 3  
fill ~24 ~0 ~22 ~25 ~0 ~22 stonebrick 3  
fill ~24 ~0 ~25 ~25 ~0 ~25 stonebrick 3  
fill ~24 ~0 ~26 ~25 ~0 ~26 stonebrick 3  
fill ~24 ~0 ~27 ~25 ~0 ~27 stonebrick 3  
fill ~24 ~0 ~28 ~25 ~0 ~28 stonebrick 3  
fill ~24 ~0 ~29 ~25 ~0 ~29 stonebrick 3  
fill ~24 ~0 ~30 ~25 ~0 ~30 stonebrick 3  
fill ~24 ~0 ~31 ~25 ~0 ~31 stonebrick 3  
fill ~24 ~0 ~32 ~25 ~0 ~32 stonebrick 3  
fill ~24 ~0 ~33 ~25 ~0 ~33 stonebrick 3  
fill ~24 ~0 ~34 ~25 ~0 ~34 stonebrick 3  
fill ~24 ~0 ~35 ~25 ~0 ~35 stonebrick 3  
fill ~24 ~0 ~36 ~25 ~0 ~36 stonebrick 3  
fill ~24 ~0 ~37 ~25 ~0 ~37 stonebrick 3  
fill ~24 ~0 ~38 ~25 ~0 ~38 stonebrick 3  
fill ~24 ~0 ~39 ~25 ~0 ~39 stonebrick 3  
fill ~24 ~0 ~40 ~25 ~0 ~40 stonebrick 3  
fill ~24 ~0 ~41 ~25 ~0 ~41 stonebrick 3  
fill ~24 ~0 ~42 ~25 ~0 ~42 stonebrick 3  
fill ~24 ~0 ~43 ~25 ~0 ~43 stonebrick 3  
fill ~24 ~0 ~44 ~25 ~0 ~44 stonebrick 3  
fill ~24 ~0 ~45 ~25 ~0 ~45 stonebrick 3  
fill ~24 ~0 ~46 ~25 ~0 ~46 stonebrick 3  
fill ~24 ~0 ~47 ~25 ~0 ~47 stonebrick 3  
fill ~26 ~0 ~0 ~32 ~0 ~0 stone 0  
fill ~26 ~0 ~1 ~32 ~0 ~1 stone 0  
fill ~26 ~0 ~2 ~32 ~0 ~2 stone 0  
fill ~26 ~0 ~3 ~32 ~0 ~3 stone 0  
fill ~26 ~0 ~4 ~32 ~0 ~4 stone 0  
fill ~26 ~0 ~5 ~32 ~0 ~5 stone 0  
fill ~26 ~0 ~6 ~32 ~0 ~6 stone 0  
fill ~26 ~0 ~7 ~32 ~0 ~7 stone 0  
fill ~26 ~0 ~8 ~32 ~0 ~8 stone 0  
fill ~26 ~0 ~9 ~32 ~0 ~9 stone 0  
fill ~26 ~0 ~10 ~32 ~0 ~10 stone 0  
fill ~26 ~0 ~11 ~32 ~0 ~11 stone 0  
fill ~26 ~0 ~12 ~32 ~0 ~12 stone 0  
fill ~26 ~0 ~13 ~32 ~0 ~13 stone 0  
fill ~26 ~0 ~14 ~32 ~0 ~14 stone 0  
fill ~26 ~0 ~15 ~32 ~0 ~15 stone 0  
fill ~26 ~0 ~16 ~48 ~0 ~16 stone 0  
fill ~26 ~0 ~17 ~48 ~0 ~17 stone 0  
fill ~26 ~0 ~18 ~48 ~0 ~18 stone 0  
fill ~26 ~0 ~19 ~48 ~0 ~19 stone 0  
fill ~26 ~0 ~20 ~48 ~0 ~20 stone 0  
fill ~26 ~0 ~21 ~48 ~0 ~21 stone 0  
fill ~26 ~0 ~22 ~48 ~0 ~22 stone 0  
fill ~26 ~0 ~25 ~48 ~0 ~25 stone 0  
fill ~26 ~0 ~26 ~48 ~0 ~26 stone 0  
fill ~26 ~0 ~27 ~48 ~0 ~27 stone 0  
fill ~26 ~0 ~28 ~48 ~0 ~28 stone 0  
fill ~26 ~0 ~29 ~48 ~0 ~29 stone 0  
fill ~26 ~0 ~30 ~48 ~0 ~30 stone 0  
fill ~26 ~0 ~31 ~48 ~0 ~31 stone 0  
fill ~26 ~0 ~32 ~32 ~0 ~32 stone 0  
fill ~26 ~0 ~33 ~32 ~0 ~33 stone 0  
fill ~26 ~0 ~34 ~32 ~0 ~34 stone 0  
fill ~26 ~0 ~35 ~32 ~0 ~35 stone 0  
fill ~26 ~0 ~36 ~32 ~0 ~36 stone 0  
fill ~26 ~0 ~37 ~32 ~0 ~37 stone 0  
fill ~26 ~0 ~38 ~32 ~0 ~38 stone 0  
fill ~26 ~0 ~39 ~32 ~0 ~39 stone 0  
fill ~26 ~0 ~40 ~32 ~0 ~40 stone 0  
fill ~26 ~0 ~41 ~32 ~0 ~41 stone 0  
fill ~26 ~0 ~42 ~32 ~0 ~42 stone 0  
fill ~26 ~0 ~43 ~32 ~0 ~43 stone 0  
fill ~26 ~0 ~44 ~32 ~0 ~44 stone 0  
fill ~26 ~0 ~45 ~32 ~0 ~45 stone 0  
fill ~26 ~0 ~46 ~32 ~0 ~46 stone 0  
fill ~26 ~0 ~47 ~32 ~0 ~47 stone 0  
fill ~1 ~1 ~18 ~5 ~1 ~18 stonebrick 3  
fill ~1 ~1 ~20 ~4 ~1 ~20 stonebrick 3  
fill ~1 ~1 ~22 ~4 ~1 ~22 stonebrick 3  
fill ~1 ~1 ~25 ~4 ~1 ~25 stonebrick 3  
fill ~1 ~1 ~27 ~4 ~1 ~27 stonebrick 3  
fill ~1 ~1 ~29 ~5 ~1 ~29 stonebrick 3  
fill ~2 ~1 ~16 ~2 ~8 ~16 stonebrick 3  
fill ~2 ~1 ~17 ~2 ~9 ~17 stonebrick 3  
fill ~2 ~1 ~30 ~2 ~9 ~30 stonebrick 3  
fill ~2 ~1 ~31 ~2 ~8 ~31 stonebrick 3  
fill ~4 ~1 ~16 ~4 ~19 ~16 stonebrick 3  
fill ~4 ~1 ~17 ~4 ~20 ~17 stonebrick 3  
fill ~4 ~1 ~19 ~4 ~21 ~19 stonebrick 3  
fill ~4 ~1 ~21 ~4 ~21 ~21 stonebrick 3  
fill ~4 ~1 ~23 ~4 ~21 ~23 stonebrick 3  
fill ~4 ~1 ~24 ~4 ~21 ~24 stonebrick 3  
fill ~4 ~1 ~26 ~4 ~21 ~26 stonebrick 3  
fill ~4 ~1 ~28 ~4 ~21 ~28 stonebrick 3  
fill ~4 ~1 ~30 ~4 ~20 ~30 stonebrick 3  
fill ~4 ~1 ~31 ~4 ~19 ~31 stonebrick 3  
fill ~6 ~1 ~16 ~6 ~19 ~16 stonebrick 3  
fill ~6 ~1 ~17 ~6 ~20 ~17 stonebrick 3  
fill ~6 ~1 ~30 ~6 ~20 ~30 stonebrick 3  
fill ~6 ~1 ~31 ~6 ~19 ~31 stonebrick 3  
fill ~7 ~1 ~18 ~7 ~21 ~18 stonebrick 3  
fill ~7 ~1 ~29 ~7 ~21 ~29 stonebrick 3  
fill ~8 ~1 ~16 ~8 ~19 ~16 stonebrick 3  
fill ~8 ~1 ~17 ~8 ~20 ~17 stonebrick 3  
fill ~8 ~1 ~30 ~8 ~20 ~30 stonebrick 3  
fill ~8 ~1 ~31 ~8 ~19 ~31 stonebrick 3  
fill ~9 ~1 ~18 ~9 ~21 ~18 stonebrick 3  
fill ~9 ~1 ~29 ~9 ~21 ~29 stonebrick 3  
fill ~10 ~1 ~16 ~10 ~19 ~16 stonebrick 3  
fill ~10 ~1 ~17 ~10 ~20 ~17 stonebrick 3  
fill ~10 ~1 ~30 ~10 ~20 ~30 stonebrick 3  
fill ~10 ~1 ~31 ~10 ~19 ~31 stonebrick 3  
fill ~11 ~1 ~18 ~11 ~21 ~18 stonebrick 3  
fill ~11 ~1 ~29 ~11 ~21 ~29 stonebrick 3  
fill ~12 ~1 ~16 ~12 ~19 ~16 stonebrick 3  
fill ~12 ~1 ~17 ~12 ~20 ~17 stonebrick 3  
fill ~12 ~1 ~30 ~12 ~20 ~30 stonebrick 3  
fill ~12 ~1 ~31 ~12 ~19 ~31 stonebrick 3  
fill ~13 ~1 ~18 ~13 ~21 ~18 stonebrick 3  
fill ~13 ~1 ~29 ~13 ~21 ~29 stonebrick 3  
fill ~14 ~1 ~16 ~14 ~19 ~16 stonebrick 3  
fill ~14 ~1 ~17 ~14 ~20 ~17 stonebrick 3  
fill ~14 ~1 ~30 ~14 ~20 ~30 stonebrick 3  
fill ~14 ~1 ~31 ~14 ~19 ~31 stonebrick 3  
fill ~15 ~1 ~18 ~15 ~21 ~18 stonebrick 3 
setblock ~15 ~-2 ~19 torch 5 
setblock ~15 ~-2 ~28 torch 5  
fill ~15 ~1 ~29 ~15 ~21 ~29 stonebrick 3  
fill ~16 ~1 ~17 ~16 ~21 ~17 stonebrick 3  
fill ~16 ~1 ~30 ~16 ~21 ~30 stonebrick 3  
fill ~17 ~1 ~1 ~19 ~1 ~1 stonebrick 3  
fill ~17 ~1 ~3 ~32 ~1 ~3 stonebrick 3  
fill ~17 ~1 ~5 ~18 ~1 ~5 stonebrick 3  
fill ~17 ~1 ~7 ~18 ~1 ~7 stonebrick 3  
fill ~17 ~1 ~9 ~18 ~1 ~9 stonebrick 3  
fill ~17 ~1 ~11 ~18 ~1 ~11 stonebrick 3  
fill ~17 ~1 ~13 ~18 ~1 ~13 stonebrick 3  
fill ~17 ~1 ~16 ~17 ~21 ~16 stonebrick 3  
fill ~17 ~1 ~31 ~17 ~21 ~31 stonebrick 3  
fill ~17 ~1 ~34 ~18 ~1 ~34 stonebrick 3  
fill ~17 ~1 ~36 ~18 ~1 ~36 stonebrick 3  
fill ~17 ~1 ~38 ~18 ~1 ~38 stonebrick 3  
fill ~17 ~1 ~40 ~18 ~1 ~40 stonebrick 3  
fill ~17 ~1 ~42 ~18 ~1 ~42 stonebrick 3  
fill ~17 ~1 ~44 ~32 ~1 ~44 stonebrick 3  
fill ~17 ~1 ~46 ~19 ~1 ~46 stonebrick 3  
fill ~18 ~1 ~15 ~18 ~21 ~15 stonebrick 3  
fill ~18 ~1 ~32 ~18 ~21 ~32 stonebrick 3  
fill ~19 ~1 ~0 ~19 ~12 ~0 stonebrick 3  
fill ~19 ~1 ~2 ~19 ~18 ~2 stonebrick 3  
fill ~19 ~1 ~4 ~19 ~21 ~4 stonebrick 3  
fill ~19 ~1 ~6 ~19 ~21 ~6 stonebrick 3  
fill ~19 ~1 ~8 ~19 ~21 ~8 stonebrick 3  
fill ~19 ~1 ~10 ~19 ~21 ~10 stonebrick 3  
fill ~19 ~1 ~12 ~19 ~21 ~12 stonebrick 3  
fill ~19 ~1 ~14 ~19 ~21 ~14 stonebrick 3  
fill ~19 ~1 ~33 ~19 ~21 ~33 stonebrick 3  
fill ~19 ~1 ~35 ~19 ~21 ~35 stonebrick 3  
fill ~19 ~1 ~37 ~19 ~21 ~37 stonebrick 3  
fill ~19 ~1 ~39 ~19 ~21 ~39 stonebrick 3  
fill ~19 ~1 ~41 ~19 ~21 ~41 stonebrick 3  
fill ~19 ~1 ~43 ~19 ~21 ~43 stonebrick 3  
fill ~19 ~1 ~45 ~19 ~18 ~45 stonebrick 3  
fill ~19 ~1 ~47 ~19 ~12 ~47 stonebrick 3 
setblock ~20 ~-2 ~14 torch 5 
setblock ~20 ~-2 ~33 torch 5  
fill ~21 ~1 ~0 ~21 ~12 ~0 stonebrick 3  
fill ~21 ~1 ~1 ~21 ~14 ~1 stonebrick 3  
fill ~21 ~1 ~2 ~21 ~19 ~2 stonebrick 3  
fill ~21 ~1 ~45 ~21 ~19 ~45 stonebrick 3  
fill ~21 ~1 ~46 ~21 ~14 ~46 stonebrick 3  
fill ~21 ~1 ~47 ~21 ~12 ~47 stonebrick 3  
fill ~23 ~1 ~0 ~23 ~12 ~0 stonebrick 3  
fill ~23 ~1 ~1 ~23 ~14 ~1 stonebrick 3  
fill ~23 ~1 ~2 ~23 ~20 ~2 stonebrick 3  
fill ~23 ~1 ~45 ~23 ~20 ~45 stonebrick 3  
fill ~23 ~1 ~46 ~23 ~14 ~46 stonebrick 3  
fill ~23 ~1 ~47 ~23 ~12 ~47 stonebrick 3  
fill ~26 ~1 ~0 ~26 ~12 ~0 stonebrick 3  
fill ~26 ~1 ~1 ~26 ~14 ~1 stonebrick 3  
fill ~26 ~1 ~2 ~26 ~20 ~2 stonebrick 3  
fill ~26 ~1 ~45 ~26 ~20 ~45 stonebrick 3  
fill ~26 ~1 ~46 ~26 ~14 ~46 stonebrick 3  
fill ~26 ~1 ~47 ~26 ~12 ~47 stonebrick 3  
fill ~28 ~1 ~0 ~28 ~12 ~0 stonebrick 3  
fill ~28 ~1 ~1 ~28 ~14 ~1 stonebrick 3  
fill ~28 ~1 ~2 ~28 ~19 ~2 stonebrick 3  
fill ~28 ~1 ~45 ~28 ~19 ~45 stonebrick 3  
fill ~28 ~1 ~46 ~28 ~14 ~46 stonebrick 3  
fill ~28 ~1 ~47 ~28 ~12 ~47 stonebrick 3 
setblock ~29 ~-2 ~14 torch 5 
setblock ~29 ~-2 ~33 torch 5  
fill ~30 ~1 ~0 ~30 ~12 ~0 stonebrick 3  
fill ~30 ~1 ~1 ~32 ~1 ~1 stonebrick 3  
fill ~30 ~1 ~2 ~30 ~18 ~2 stonebrick 3  
fill ~30 ~1 ~4 ~30 ~21 ~4 stonebrick 3  
fill ~30 ~1 ~6 ~30 ~21 ~6 stonebrick 3  
fill ~30 ~1 ~8 ~30 ~21 ~8 stonebrick 3  
fill ~30 ~1 ~10 ~30 ~21 ~10 stonebrick 3  
fill ~30 ~1 ~12 ~30 ~21 ~12 stonebrick 3  
fill ~30 ~1 ~14 ~30 ~21 ~14 stonebrick 3  
fill ~30 ~1 ~33 ~30 ~21 ~33 stonebrick 3  
fill ~30 ~1 ~35 ~30 ~21 ~35 stonebrick 3  
fill ~30 ~1 ~37 ~30 ~21 ~37 stonebrick 3  
fill ~30 ~1 ~39 ~30 ~21 ~39 stonebrick 3  
fill ~30 ~1 ~41 ~30 ~21 ~41 stonebrick 3  
fill ~30 ~1 ~43 ~30 ~21 ~43 stonebrick 3  
fill ~30 ~1 ~45 ~30 ~18 ~45 stonebrick 3  
fill ~30 ~1 ~46 ~32 ~1 ~46 stonebrick 3  
fill ~30 ~1 ~47 ~30 ~12 ~47 stonebrick 3  
fill ~31 ~1 ~5 ~32 ~1 ~5 stonebrick 3  
fill ~31 ~1 ~7 ~32 ~1 ~7 stonebrick 3  
fill ~31 ~1 ~9 ~32 ~1 ~9 stonebrick 3  
fill ~31 ~1 ~11 ~32 ~1 ~11 stonebrick 3  
fill ~31 ~1 ~13 ~32 ~1 ~13 stonebrick 3  
fill ~31 ~1 ~15 ~31 ~21 ~15 stonebrick 3  
fill ~31 ~1 ~32 ~31 ~21 ~32 stonebrick 3  
fill ~31 ~1 ~34 ~32 ~1 ~34 stonebrick 3  
fill ~31 ~1 ~36 ~32 ~1 ~36 stonebrick 3  
fill ~31 ~1 ~38 ~32 ~1 ~38 stonebrick 3  
fill ~31 ~1 ~40 ~32 ~1 ~40 stonebrick 3  
fill ~31 ~1 ~42 ~32 ~1 ~42 stonebrick 3  
fill ~32 ~1 ~16 ~32 ~21 ~16 stonebrick 3  
fill ~32 ~1 ~31 ~32 ~21 ~31 stonebrick 3  
fill ~33 ~1 ~17 ~33 ~21 ~17 stonebrick 3  
fill ~33 ~1 ~30 ~33 ~21 ~30 stonebrick 3  
fill ~34 ~1 ~18 ~34 ~21 ~18 stonebrick 3 
setblock ~34 ~-2 ~19 torch 5 
setblock ~34 ~-2 ~28 torch 5  
fill ~34 ~1 ~29 ~34 ~21 ~29 stonebrick 3  
fill ~35 ~1 ~16 ~35 ~19 ~16 stonebrick 3  
fill ~35 ~1 ~17 ~35 ~20 ~17 stonebrick 3  
fill ~35 ~1 ~30 ~35 ~20 ~30 stonebrick 3  
fill ~35 ~1 ~31 ~35 ~19 ~31 stonebrick 3  
fill ~36 ~1 ~18 ~36 ~21 ~18 stonebrick 3  
fill ~36 ~1 ~29 ~36 ~21 ~29 stonebrick 3  
fill ~37 ~1 ~16 ~37 ~19 ~16 stonebrick 3  
fill ~37 ~1 ~17 ~37 ~20 ~17 stonebrick 3  
fill ~37 ~1 ~30 ~37 ~20 ~30 stonebrick 3  
fill ~37 ~1 ~31 ~37 ~19 ~31 stonebrick 3  
fill ~38 ~1 ~18 ~38 ~21 ~18 stonebrick 3  
fill ~38 ~1 ~29 ~38 ~21 ~29 stonebrick 3  
fill ~39 ~1 ~16 ~39 ~19 ~16 stonebrick 3  
fill ~39 ~1 ~17 ~39 ~20 ~17 stonebrick 3  
fill ~39 ~1 ~30 ~39 ~20 ~30 stonebrick 3  
fill ~39 ~1 ~31 ~39 ~19 ~31 stonebrick 3  
fill ~40 ~1 ~18 ~40 ~21 ~18 stonebrick 3  
fill ~40 ~1 ~29 ~40 ~21 ~29 stonebrick 3  
fill ~41 ~1 ~16 ~41 ~19 ~16 stonebrick 3  
fill ~41 ~1 ~17 ~41 ~20 ~17 stonebrick 3  
fill ~41 ~1 ~30 ~41 ~20 ~30 stonebrick 3  
fill ~41 ~1 ~31 ~41 ~19 ~31 stonebrick 3  
fill ~42 ~1 ~18 ~42 ~21 ~18 stonebrick 3  
fill ~42 ~1 ~29 ~42 ~21 ~29 stonebrick 3  
fill ~43 ~1 ~16 ~43 ~19 ~16 stonebrick 3  
fill ~43 ~1 ~17 ~43 ~20 ~17 stonebrick 3  
fill ~43 ~1 ~30 ~43 ~20 ~30 stonebrick 3  
fill ~43 ~1 ~31 ~43 ~19 ~31 stonebrick 3  
fill ~44 ~1 ~18 ~48 ~1 ~18 stonebrick 3  
fill ~44 ~1 ~29 ~48 ~1 ~29 stonebrick 3  
fill ~45 ~1 ~16 ~45 ~19 ~16 stonebrick 3  
fill ~45 ~1 ~17 ~45 ~20 ~17 stonebrick 3  
fill ~45 ~1 ~19 ~45 ~21 ~19 stonebrick 3  
fill ~45 ~1 ~20 ~48 ~1 ~20 stonebrick 3  
fill ~45 ~1 ~21 ~45 ~21 ~21 stonebrick 3  
fill ~45 ~1 ~22 ~48 ~1 ~22 stonebrick 3  
fill ~45 ~1 ~23 ~45 ~21 ~23 stonebrick 3  
fill ~45 ~1 ~24 ~45 ~21 ~24 stonebrick 3  
fill ~45 ~1 ~25 ~48 ~1 ~25 stonebrick 3  
fill ~45 ~1 ~26 ~45 ~21 ~26 stonebrick 3  
fill ~45 ~1 ~27 ~48 ~1 ~27 stonebrick 3  
fill ~45 ~1 ~28 ~45 ~21 ~28 stonebrick 3  
fill ~45 ~1 ~30 ~45 ~20 ~30 stonebrick 3  
fill ~45 ~1 ~31 ~45 ~19 ~31 stonebrick 3  
fill ~47 ~1 ~16 ~47 ~8 ~16 stonebrick 3  
fill ~47 ~1 ~17 ~47 ~9 ~17 stonebrick 3  
fill ~47 ~1 ~30 ~47 ~9 ~30 stonebrick 3  
fill ~47 ~1 ~31 ~47 ~8 ~31 stonebrick 3  
fill ~1 ~2 ~18 ~5 ~2 ~18 stonebrick 3  
fill ~1 ~2 ~20 ~4 ~2 ~20 stonebrick 3  
fill ~1 ~2 ~22 ~4 ~2 ~22 stonebrick 3  
fill ~1 ~2 ~25 ~4 ~2 ~25 stonebrick 3  
fill ~1 ~2 ~27 ~4 ~2 ~27 stonebrick 3  
fill ~1 ~2 ~29 ~5 ~2 ~29 stonebrick 3  
fill ~17 ~2 ~1 ~19 ~2 ~1 stonebrick 3  
fill ~17 ~2 ~3 ~32 ~2 ~3 stonebrick 3  
fill ~17 ~2 ~5 ~18 ~2 ~5 stonebrick 3  
fill ~17 ~2 ~7 ~18 ~2 ~7 stonebrick 3  
fill ~17 ~2 ~9 ~18 ~2 ~9 stonebrick 3  
fill ~17 ~2 ~11 ~18 ~2 ~11 stonebrick 3  
fill ~17 ~2 ~13 ~18 ~2 ~13 stonebrick 3  
fill ~17 ~2 ~34 ~18 ~2 ~34 stonebrick 3  
fill ~17 ~2 ~36 ~18 ~2 ~36 stonebrick 3  
fill ~17 ~2 ~38 ~18 ~2 ~38 stonebrick 3  
fill ~17 ~2 ~40 ~18 ~2 ~40 stonebrick 3  
fill ~17 ~2 ~42 ~18 ~2 ~42 stonebrick 3  
fill ~17 ~2 ~44 ~32 ~2 ~44 stonebrick 3  
fill ~17 ~2 ~46 ~19 ~2 ~46 stonebrick 3  
fill ~30 ~2 ~1 ~32 ~2 ~1 stonebrick 3  
fill ~30 ~2 ~46 ~32 ~2 ~46 stonebrick 3  
fill ~31 ~2 ~5 ~32 ~2 ~5 stonebrick 3  
fill ~31 ~2 ~7 ~32 ~2 ~7 stonebrick 3  
fill ~31 ~2 ~9 ~32 ~2 ~9 stonebrick 3  
fill ~31 ~2 ~11 ~32 ~2 ~11 stonebrick 3  
fill ~31 ~2 ~13 ~32 ~2 ~13 stonebrick 3  
fill ~31 ~2 ~34 ~32 ~2 ~34 stonebrick 3  
fill ~31 ~2 ~36 ~32 ~2 ~36 stonebrick 3  
fill ~31 ~2 ~38 ~32 ~2 ~38 stonebrick 3  
fill ~31 ~2 ~40 ~32 ~2 ~40 stonebrick 3  
fill ~31 ~2 ~42 ~32 ~2 ~42 stonebrick 3  
fill ~44 ~2 ~18 ~48 ~2 ~18 stonebrick 3  
fill ~44 ~2 ~29 ~48 ~2 ~29 stonebrick 3  
fill ~45 ~2 ~20 ~48 ~2 ~20 stonebrick 3  
fill ~45 ~2 ~22 ~48 ~2 ~22 stonebrick 3  
fill ~45 ~2 ~25 ~48 ~2 ~25 stonebrick 3  
fill ~45 ~2 ~27 ~48 ~2 ~27 stonebrick 3  
fill ~1 ~3 ~18 ~5 ~3 ~18 stonebrick 3  
fill ~1 ~3 ~20 ~4 ~3 ~20 stonebrick 3  
fill ~1 ~3 ~22 ~4 ~3 ~22 stonebrick 3  
fill ~1 ~3 ~25 ~4 ~3 ~25 stonebrick 3  
fill ~1 ~3 ~27 ~4 ~3 ~27 stonebrick 3  
fill ~1 ~3 ~29 ~5 ~3 ~29 stonebrick 3  
fill ~17 ~3 ~1 ~19 ~3 ~1 stonebrick 3  
fill ~17 ~3 ~3 ~32 ~3 ~3 stonebrick 3  
fill ~17 ~3 ~5 ~18 ~3 ~5 stonebrick 3  
fill ~17 ~3 ~7 ~18 ~3 ~7 stonebrick 3  
fill ~17 ~3 ~9 ~18 ~3 ~9 stonebrick 3  
fill ~17 ~3 ~11 ~18 ~3 ~11 stonebrick 3  
fill ~17 ~3 ~13 ~18 ~3 ~13 stonebrick 3  
fill ~17 ~3 ~34 ~18 ~3 ~34 stonebrick 3  
fill ~17 ~3 ~36 ~18 ~3 ~36 stonebrick 3  
fill ~17 ~3 ~38 ~18 ~3 ~38 stonebrick 3  
fill ~17 ~3 ~40 ~18 ~3 ~40 stonebrick 3  
fill ~17 ~3 ~42 ~18 ~3 ~42 stonebrick 3  
fill ~17 ~3 ~44 ~32 ~3 ~44 stonebrick 3  
fill ~17 ~3 ~46 ~19 ~3 ~46 stonebrick 3  
fill ~30 ~3 ~1 ~32 ~3 ~1 stonebrick 3  
fill ~30 ~3 ~46 ~32 ~3 ~46 stonebrick 3  
fill ~31 ~3 ~5 ~32 ~3 ~5 stonebrick 3  
fill ~31 ~3 ~7 ~32 ~3 ~7 stonebrick 3  
fill ~31 ~3 ~9 ~32 ~3 ~9 stonebrick 3  
fill ~31 ~3 ~11 ~32 ~3 ~11 stonebrick 3  
fill ~31 ~3 ~13 ~32 ~3 ~13 stonebrick 3  
fill ~31 ~3 ~34 ~32 ~3 ~34 stonebrick 3  
fill ~31 ~3 ~36 ~32 ~3 ~36 stonebrick 3  
fill ~31 ~3 ~38 ~32 ~3 ~38 stonebrick 3  
fill ~31 ~3 ~40 ~32 ~3 ~40 stonebrick 3  
fill ~31 ~3 ~42 ~32 ~3 ~42 stonebrick 3  
fill ~44 ~3 ~18 ~48 ~3 ~18 stonebrick 3  
fill ~44 ~3 ~29 ~48 ~3 ~29 stonebrick 3  
fill ~45 ~3 ~20 ~48 ~3 ~20 stonebrick 3  
fill ~45 ~3 ~22 ~48 ~3 ~22 stonebrick 3  
fill ~45 ~3 ~25 ~48 ~3 ~25 stonebrick 3  
fill ~45 ~3 ~27 ~48 ~3 ~27 stonebrick 3  
fill ~1 ~4 ~18 ~5 ~4 ~18 stonebrick 3  
fill ~1 ~4 ~20 ~4 ~4 ~20 stonebrick 3  
fill ~1 ~4 ~22 ~4 ~4 ~22 stonebrick 3  
fill ~1 ~4 ~25 ~4 ~4 ~25 stonebrick 3  
fill ~1 ~4 ~27 ~4 ~4 ~27 stonebrick 3  
fill ~1 ~4 ~29 ~5 ~4 ~29 stonebrick 3  
fill ~17 ~4 ~1 ~19 ~4 ~1 stonebrick 3  
fill ~17 ~4 ~3 ~32 ~4 ~3 stonebrick 3  
fill ~17 ~4 ~5 ~18 ~4 ~5 stonebrick 3  
fill ~17 ~4 ~7 ~18 ~4 ~7 stonebrick 3  
fill ~17 ~4 ~9 ~18 ~4 ~9 stonebrick 3  
fill ~17 ~4 ~11 ~18 ~4 ~11 stonebrick 3  
fill ~17 ~4 ~13 ~18 ~4 ~13 stonebrick 3  
fill ~17 ~4 ~34 ~18 ~4 ~34 stonebrick 3  
fill ~17 ~4 ~36 ~18 ~4 ~36 stonebrick 3  
fill ~17 ~4 ~38 ~18 ~4 ~38 stonebrick 3  
fill ~17 ~4 ~40 ~18 ~4 ~40 stonebrick 3  
fill ~17 ~4 ~42 ~18 ~4 ~42 stonebrick 3  
fill ~17 ~4 ~44 ~32 ~4 ~44 stonebrick 3  
fill ~17 ~4 ~46 ~19 ~4 ~46 stonebrick 3  
fill ~30 ~4 ~1 ~32 ~4 ~1 stonebrick 3  
fill ~30 ~4 ~46 ~32 ~4 ~46 stonebrick 3  
fill ~31 ~4 ~5 ~32 ~4 ~5 stonebrick 3  
fill ~31 ~4 ~7 ~32 ~4 ~7 stonebrick 3  
fill ~31 ~4 ~9 ~32 ~4 ~9 stonebrick 3  
fill ~31 ~4 ~11 ~32 ~4 ~11 stonebrick 3  
fill ~31 ~4 ~13 ~32 ~4 ~13 stonebrick 3  
fill ~31 ~4 ~34 ~32 ~4 ~34 stonebrick 3  
fill ~31 ~4 ~36 ~32 ~4 ~36 stonebrick 3  
fill ~31 ~4 ~38 ~32 ~4 ~38 stonebrick 3  
fill ~31 ~4 ~40 ~32 ~4 ~40 stonebrick 3  
fill ~31 ~4 ~42 ~32 ~4 ~42 stonebrick 3  
fill ~44 ~4 ~18 ~48 ~4 ~18 stonebrick 3  
fill ~44 ~4 ~29 ~48 ~4 ~29 stonebrick 3  
fill ~45 ~4 ~20 ~48 ~4 ~20 stonebrick 3  
fill ~45 ~4 ~22 ~48 ~4 ~22 stonebrick 3  
fill ~45 ~4 ~25 ~48 ~4 ~25 stonebrick 3  
fill ~45 ~4 ~27 ~48 ~4 ~27 stonebrick 3  
fill ~1 ~5 ~18 ~5 ~5 ~18 stonebrick 3  
fill ~1 ~5 ~20 ~4 ~5 ~20 stonebrick 3  
fill ~1 ~5 ~22 ~4 ~5 ~22 stonebrick 3  
fill ~1 ~5 ~25 ~4 ~5 ~25 stonebrick 3  
fill ~1 ~5 ~27 ~4 ~5 ~27 stonebrick 3  
fill ~1 ~5 ~29 ~5 ~5 ~29 stonebrick 3  
fill ~17 ~5 ~1 ~19 ~5 ~1 stonebrick 3  
fill ~17 ~5 ~3 ~32 ~5 ~3 stonebrick 3  
fill ~17 ~5 ~5 ~18 ~5 ~5 stonebrick 3  
fill ~17 ~5 ~7 ~18 ~5 ~7 stonebrick 3  
fill ~17 ~5 ~9 ~18 ~5 ~9 stonebrick 3  
fill ~17 ~5 ~11 ~18 ~5 ~11 stonebrick 3  
fill ~17 ~5 ~13 ~18 ~5 ~13 stonebrick 3  
fill ~17 ~5 ~34 ~18 ~5 ~34 stonebrick 3  
fill ~17 ~5 ~36 ~18 ~5 ~36 stonebrick 3  
fill ~17 ~5 ~38 ~18 ~5 ~38 stonebrick 3  
fill ~17 ~5 ~40 ~18 ~5 ~40 stonebrick 3  
fill ~17 ~5 ~42 ~18 ~5 ~42 stonebrick 3  
fill ~17 ~5 ~44 ~32 ~5 ~44 stonebrick 3  
fill ~17 ~5 ~46 ~19 ~5 ~46 stonebrick 3  
fill ~30 ~5 ~1 ~32 ~5 ~1 stonebrick 3  
fill ~30 ~5 ~46 ~32 ~5 ~46 stonebrick 3  
fill ~31 ~5 ~5 ~32 ~5 ~5 stonebrick 3  
fill ~31 ~5 ~7 ~32 ~5 ~7 stonebrick 3  
fill ~31 ~5 ~9 ~32 ~5 ~9 stonebrick 3  
fill ~31 ~5 ~11 ~32 ~5 ~11 stonebrick 3  
fill ~31 ~5 ~13 ~32 ~5 ~13 stonebrick 3  
fill ~31 ~5 ~34 ~32 ~5 ~34 stonebrick 3  
fill ~31 ~5 ~36 ~32 ~5 ~36 stonebrick 3  
fill ~31 ~5 ~38 ~32 ~5 ~38 stonebrick 3  
fill ~31 ~5 ~40 ~32 ~5 ~40 stonebrick 3  
fill ~31 ~5 ~42 ~32 ~5 ~42 stonebrick 3  
fill ~44 ~5 ~18 ~48 ~5 ~18 stonebrick 3  
fill ~44 ~5 ~29 ~48 ~5 ~29 stonebrick 3  
fill ~45 ~5 ~20 ~48 ~5 ~20 stonebrick 3  
fill ~45 ~5 ~22 ~48 ~5 ~22 stonebrick 3  
fill ~45 ~5 ~25 ~48 ~5 ~25 stonebrick 3  
fill ~45 ~5 ~27 ~48 ~5 ~27 stonebrick 3  
fill ~1 ~6 ~18 ~5 ~6 ~18 stonebrick 3  
fill ~1 ~6 ~20 ~4 ~6 ~20 stonebrick 3  
fill ~1 ~6 ~22 ~4 ~6 ~22 stonebrick 3  
fill ~1 ~6 ~25 ~4 ~6 ~25 stonebrick 3  
fill ~1 ~6 ~27 ~4 ~6 ~27 stonebrick 3  
fill ~1 ~6 ~29 ~5 ~6 ~29 stonebrick 3  
fill ~17 ~6 ~1 ~19 ~6 ~1 stonebrick 3  
fill ~17 ~6 ~3 ~32 ~6 ~3 stonebrick 3  
fill ~17 ~6 ~5 ~18 ~6 ~5 stonebrick 3  
fill ~17 ~6 ~7 ~18 ~6 ~7 stonebrick 3  
fill ~17 ~6 ~9 ~18 ~6 ~9 stonebrick 3  
fill ~17 ~6 ~11 ~18 ~6 ~11 stonebrick 3  
fill ~17 ~6 ~13 ~18 ~6 ~13 stonebrick 3  
fill ~17 ~6 ~34 ~18 ~6 ~34 stonebrick 3  
fill ~17 ~6 ~36 ~18 ~6 ~36 stonebrick 3  
fill ~17 ~6 ~38 ~18 ~6 ~38 stonebrick 3  
fill ~17 ~6 ~40 ~18 ~6 ~40 stonebrick 3  
fill ~17 ~6 ~42 ~18 ~6 ~42 stonebrick 3  
fill ~17 ~6 ~44 ~32 ~6 ~44 stonebrick 3  
fill ~17 ~6 ~46 ~19 ~6 ~46 stonebrick 3  
fill ~30 ~6 ~1 ~32 ~6 ~1 stonebrick 3  
fill ~30 ~6 ~46 ~32 ~6 ~46 stonebrick 3  
fill ~31 ~6 ~5 ~32 ~6 ~5 stonebrick 3  
fill ~31 ~6 ~7 ~32 ~6 ~7 stonebrick 3  
fill ~31 ~6 ~9 ~32 ~6 ~9 stonebrick 3  
fill ~31 ~6 ~11 ~32 ~6 ~11 stonebrick 3  
fill ~31 ~6 ~13 ~32 ~6 ~13 stonebrick 3  
fill ~31 ~6 ~34 ~32 ~6 ~34 stonebrick 3  
fill ~31 ~6 ~36 ~32 ~6 ~36 stonebrick 3  
fill ~31 ~6 ~38 ~32 ~6 ~38 stonebrick 3  
fill ~31 ~6 ~40 ~32 ~6 ~40 stonebrick 3  
fill ~31 ~6 ~42 ~32 ~6 ~42 stonebrick 3  
fill ~44 ~6 ~18 ~48 ~6 ~18 stonebrick 3  
fill ~44 ~6 ~29 ~48 ~6 ~29 stonebrick 3  
fill ~45 ~6 ~20 ~48 ~6 ~20 stonebrick 3  
fill ~45 ~6 ~22 ~48 ~6 ~22 stonebrick 3  
fill ~45 ~6 ~25 ~48 ~6 ~25 stonebrick 3  
fill ~45 ~6 ~27 ~48 ~6 ~27 stonebrick 3  
fill ~1 ~7 ~18 ~5 ~7 ~18 stonebrick 3  
fill ~1 ~7 ~20 ~4 ~7 ~20 stonebrick 3  
fill ~1 ~7 ~22 ~4 ~7 ~22 stonebrick 3  
fill ~1 ~7 ~25 ~4 ~7 ~25 stonebrick 3  
fill ~1 ~7 ~27 ~4 ~7 ~27 stonebrick 3  
fill ~1 ~7 ~29 ~5 ~7 ~29 stonebrick 3  
fill ~17 ~7 ~1 ~19 ~7 ~1 stonebrick 3  
fill ~17 ~7 ~3 ~32 ~7 ~3 stonebrick 3  
fill ~17 ~7 ~5 ~18 ~7 ~5 stonebrick 3  
fill ~17 ~7 ~7 ~18 ~7 ~7 stonebrick 3  
fill ~17 ~7 ~9 ~18 ~7 ~9 stonebrick 3  
fill ~17 ~7 ~11 ~18 ~7 ~11 stonebrick 3  
fill ~17 ~7 ~13 ~18 ~7 ~13 stonebrick 3  
fill ~17 ~7 ~34 ~18 ~7 ~34 stonebrick 3  
fill ~17 ~7 ~36 ~18 ~7 ~36 stonebrick 3  
fill ~17 ~7 ~38 ~18 ~7 ~38 stonebrick 3  
fill ~17 ~7 ~40 ~18 ~7 ~40 stonebrick 3  
fill ~17 ~7 ~42 ~18 ~7 ~42 stonebrick 3  
fill ~17 ~7 ~44 ~32 ~7 ~44 stonebrick 3  
fill ~17 ~7 ~46 ~19 ~7 ~46 stonebrick 3  
fill ~30 ~7 ~1 ~32 ~7 ~1 stonebrick 3  
fill ~30 ~7 ~46 ~32 ~7 ~46 stonebrick 3  
fill ~31 ~7 ~5 ~32 ~7 ~5 stonebrick 3  
fill ~31 ~7 ~7 ~32 ~7 ~7 stonebrick 3  
fill ~31 ~7 ~9 ~32 ~7 ~9 stonebrick 3  
fill ~31 ~7 ~11 ~32 ~7 ~11 stonebrick 3  
fill ~31 ~7 ~13 ~32 ~7 ~13 stonebrick 3  
fill ~31 ~7 ~34 ~32 ~7 ~34 stonebrick 3  
fill ~31 ~7 ~36 ~32 ~7 ~36 stonebrick 3  
fill ~31 ~7 ~38 ~32 ~7 ~38 stonebrick 3  
fill ~31 ~7 ~40 ~32 ~7 ~40 stonebrick 3  
fill ~31 ~7 ~42 ~32 ~7 ~42 stonebrick 3  
fill ~44 ~7 ~18 ~48 ~7 ~18 stonebrick 3  
fill ~44 ~7 ~29 ~48 ~7 ~29 stonebrick 3  
fill ~45 ~7 ~20 ~48 ~7 ~20 stonebrick 3  
fill ~45 ~7 ~22 ~48 ~7 ~22 stonebrick 3  
fill ~45 ~7 ~25 ~48 ~7 ~25 stonebrick 3  
fill ~45 ~7 ~27 ~48 ~7 ~27 stonebrick 3  
fill ~1 ~8 ~18 ~5 ~8 ~18 stonebrick 3  
fill ~1 ~8 ~20 ~4 ~8 ~20 stonebrick 3  
fill ~1 ~8 ~22 ~4 ~8 ~22 stonebrick 3  
fill ~1 ~8 ~25 ~4 ~8 ~25 stonebrick 3  
fill ~1 ~8 ~27 ~4 ~8 ~27 stonebrick 3  
fill ~1 ~8 ~29 ~5 ~8 ~29 stonebrick 3  
fill ~17 ~8 ~1 ~19 ~8 ~1 stonebrick 3  
fill ~17 ~8 ~3 ~32 ~8 ~3 stonebrick 3  
fill ~17 ~8 ~5 ~18 ~8 ~5 stonebrick 3  
fill ~17 ~8 ~7 ~18 ~8 ~7 stonebrick 3  
fill ~17 ~8 ~9 ~18 ~8 ~9 stonebrick 3  
fill ~17 ~8 ~11 ~18 ~8 ~11 stonebrick 3  
fill ~17 ~8 ~13 ~18 ~8 ~13 stonebrick 3  
fill ~17 ~8 ~34 ~18 ~8 ~34 stonebrick 3  
fill ~17 ~8 ~36 ~18 ~8 ~36 stonebrick 3  
fill ~17 ~8 ~38 ~18 ~8 ~38 stonebrick 3  
fill ~17 ~8 ~40 ~18 ~8 ~40 stonebrick 3  
fill ~17 ~8 ~42 ~18 ~8 ~42 stonebrick 3  
fill ~17 ~8 ~44 ~32 ~8 ~44 stonebrick 3  
fill ~17 ~8 ~46 ~19 ~8 ~46 stonebrick 3  
fill ~30 ~8 ~1 ~32 ~8 ~1 stonebrick 3  
fill ~30 ~8 ~46 ~32 ~8 ~46 stonebrick 3  
fill ~31 ~8 ~5 ~32 ~8 ~5 stonebrick 3  
fill ~31 ~8 ~7 ~32 ~8 ~7 stonebrick 3  
fill ~31 ~8 ~9 ~32 ~8 ~9 stonebrick 3  
fill ~31 ~8 ~11 ~32 ~8 ~11 stonebrick 3  
fill ~31 ~8 ~13 ~32 ~8 ~13 stonebrick 3  
fill ~31 ~8 ~34 ~32 ~8 ~34 stonebrick 3  
fill ~31 ~8 ~36 ~32 ~8 ~36 stonebrick 3  
fill ~31 ~8 ~38 ~32 ~8 ~38 stonebrick 3  
fill ~31 ~8 ~40 ~32 ~8 ~40 stonebrick 3  
fill ~31 ~8 ~42 ~32 ~8 ~42 stonebrick 3  
fill ~44 ~8 ~18 ~48 ~8 ~18 stonebrick 3  
fill ~44 ~8 ~29 ~48 ~8 ~29 stonebrick 3  
fill ~45 ~8 ~20 ~48 ~8 ~20 stonebrick 3  
fill ~45 ~8 ~22 ~48 ~8 ~22 stonebrick 3  
fill ~45 ~8 ~25 ~48 ~8 ~25 stonebrick 3  
fill ~45 ~8 ~27 ~48 ~8 ~27 stonebrick 3  
fill ~1 ~9 ~18 ~5 ~9 ~18 stonebrick 3  
fill ~1 ~9 ~20 ~4 ~9 ~20 stonebrick 3  
fill ~1 ~9 ~22 ~4 ~9 ~22 stonebrick 3  
fill ~1 ~9 ~25 ~4 ~9 ~25 stonebrick 3  
fill ~1 ~9 ~27 ~4 ~9 ~27 stonebrick 3  
fill ~1 ~9 ~29 ~5 ~9 ~29 stonebrick 3 
setblock ~2 ~6 ~16 stone_brick_stairs 2 
setblock ~2 ~6 ~31 stone_brick_stairs 3 
setblock ~17 ~6 ~1 stone_brick_stairs 0  
fill ~17 ~9 ~3 ~32 ~9 ~3 stonebrick 3  
fill ~17 ~9 ~5 ~18 ~9 ~5 stonebrick 3  
fill ~17 ~9 ~7 ~18 ~9 ~7 stonebrick 3  
fill ~17 ~9 ~9 ~18 ~9 ~9 stonebrick 3  
fill ~17 ~9 ~11 ~18 ~9 ~11 stonebrick 3  
fill ~17 ~9 ~13 ~18 ~9 ~13 stonebrick 3  
fill ~17 ~9 ~34 ~18 ~9 ~34 stonebrick 3  
fill ~17 ~9 ~36 ~18 ~9 ~36 stonebrick 3  
fill ~17 ~9 ~38 ~18 ~9 ~38 stonebrick 3  
fill ~17 ~9 ~40 ~18 ~9 ~40 stonebrick 3  
fill ~17 ~9 ~42 ~18 ~9 ~42 stonebrick 3  
fill ~17 ~9 ~44 ~32 ~9 ~44 stonebrick 3 
setblock ~17 ~6 ~46 stone_brick_stairs 0  
fill ~18 ~9 ~1 ~19 ~9 ~1 stonebrick 3  
fill ~18 ~9 ~46 ~19 ~9 ~46 stonebrick 3  
fill ~30 ~9 ~1 ~31 ~9 ~1 stonebrick 3  
fill ~30 ~9 ~46 ~31 ~9 ~46 stonebrick 3  
fill ~31 ~9 ~5 ~32 ~9 ~5 stonebrick 3  
fill ~31 ~9 ~7 ~32 ~9 ~7 stonebrick 3  
fill ~31 ~9 ~9 ~32 ~9 ~9 stonebrick 3  
fill ~31 ~9 ~11 ~32 ~9 ~11 stonebrick 3  
fill ~31 ~9 ~13 ~32 ~9 ~13 stonebrick 3  
fill ~31 ~9 ~34 ~32 ~9 ~34 stonebrick 3  
fill ~31 ~9 ~36 ~32 ~9 ~36 stonebrick 3  
fill ~31 ~9 ~38 ~32 ~9 ~38 stonebrick 3  
fill ~31 ~9 ~40 ~32 ~9 ~40 stonebrick 3  
fill ~31 ~9 ~42 ~32 ~9 ~42 stonebrick 3 
setblock ~32 ~6 ~1 stone_brick_stairs 1 
setblock ~32 ~6 ~46 stone_brick_stairs 1  
fill ~44 ~9 ~18 ~48 ~9 ~18 stonebrick 3  
fill ~44 ~9 ~29 ~48 ~9 ~29 stonebrick 3  
fill ~45 ~9 ~20 ~48 ~9 ~20 stonebrick 3  
fill ~45 ~9 ~22 ~48 ~9 ~22 stonebrick 3  
fill ~45 ~9 ~25 ~48 ~9 ~25 stonebrick 3  
fill ~45 ~9 ~27 ~48 ~9 ~27 stonebrick 3 
setblock ~47 ~6 ~16 stone_brick_stairs 2 
setblock ~47 ~6 ~31 stone_brick_stairs 3  
fill ~1 ~10 ~18 ~5 ~10 ~18 stonebrick 3  
fill ~1 ~10 ~20 ~4 ~10 ~20 stonebrick 3  
fill ~1 ~10 ~22 ~4 ~10 ~22 stonebrick 3  
fill ~1 ~10 ~25 ~4 ~10 ~25 stonebrick 3  
fill ~1 ~10 ~27 ~4 ~10 ~27 stonebrick 3  
fill ~1 ~10 ~29 ~5 ~10 ~29 stonebrick 3 
setblock ~2 ~7 ~17 stone_brick_stairs 2 
setblock ~2 ~7 ~30 stone_brick_stairs 3  
fill ~17 ~10 ~3 ~32 ~10 ~3 stonebrick 3  
fill ~17 ~10 ~5 ~18 ~10 ~5 stonebrick 3  
fill ~17 ~10 ~7 ~18 ~10 ~7 stonebrick 3  
fill ~17 ~10 ~9 ~18 ~10 ~9 stonebrick 3  
fill ~17 ~10 ~11 ~18 ~10 ~11 stonebrick 3  
fill ~17 ~10 ~13 ~18 ~10 ~13 stonebrick 3  
fill ~17 ~10 ~34 ~18 ~10 ~34 stonebrick 3  
fill ~17 ~10 ~36 ~18 ~10 ~36 stonebrick 3  
fill ~17 ~10 ~38 ~18 ~10 ~38 stonebrick 3  
fill ~17 ~10 ~40 ~18 ~10 ~40 stonebrick 3  
fill ~17 ~10 ~42 ~18 ~10 ~42 stonebrick 3  
fill ~17 ~10 ~44 ~32 ~10 ~44 stonebrick 3 
setblock ~18 ~7 ~1 stone_brick_stairs 0 
setblock ~18 ~7 ~46 stone_brick_stairs 0  
fill ~19 ~10 ~1 ~19 ~14 ~1 stonebrick 3  
fill ~19 ~10 ~46 ~19 ~14 ~46 stonebrick 3  
fill ~30 ~10 ~1 ~30 ~14 ~1 stonebrick 3  
fill ~30 ~10 ~46 ~30 ~14 ~46 stonebrick 3 
setblock ~31 ~7 ~1 stone_brick_stairs 1  
fill ~31 ~10 ~5 ~32 ~10 ~5 stonebrick 3  
fill ~31 ~10 ~7 ~32 ~10 ~7 stonebrick 3  
fill ~31 ~10 ~9 ~32 ~10 ~9 stonebrick 3  
fill ~31 ~10 ~11 ~32 ~10 ~11 stonebrick 3  
fill ~31 ~10 ~13 ~32 ~10 ~13 stonebrick 3  
fill ~31 ~10 ~34 ~32 ~10 ~34 stonebrick 3  
fill ~31 ~10 ~36 ~32 ~10 ~36 stonebrick 3  
fill ~31 ~10 ~38 ~32 ~10 ~38 stonebrick 3  
fill ~31 ~10 ~40 ~32 ~10 ~40 stonebrick 3  
fill ~31 ~10 ~42 ~32 ~10 ~42 stonebrick 3 
setblock ~31 ~7 ~46 stone_brick_stairs 1  
fill ~44 ~10 ~18 ~48 ~10 ~18 stonebrick 3  
fill ~44 ~10 ~29 ~48 ~10 ~29 stonebrick 3  
fill ~45 ~10 ~20 ~48 ~10 ~20 stonebrick 3  
fill ~45 ~10 ~22 ~48 ~10 ~22 stonebrick 3  
fill ~45 ~10 ~25 ~48 ~10 ~25 stonebrick 3  
fill ~45 ~10 ~27 ~48 ~10 ~27 stonebrick 3 
setblock ~47 ~7 ~17 stone_brick_stairs 2 
setblock ~47 ~7 ~30 stone_brick_stairs 3  
fill ~1 ~11 ~18 ~5 ~11 ~18 stonebrick 3  
fill ~1 ~11 ~20 ~4 ~11 ~20 stonebrick 3  
fill ~1 ~11 ~22 ~4 ~11 ~22 stonebrick 3  
fill ~1 ~11 ~25 ~4 ~11 ~25 stonebrick 3  
fill ~1 ~11 ~27 ~4 ~11 ~27 stonebrick 3  
fill ~1 ~11 ~29 ~5 ~11 ~29 stonebrick 3  
fill ~17 ~11 ~3 ~32 ~11 ~3 stonebrick 3  
fill ~17 ~11 ~5 ~18 ~11 ~5 stonebrick 3  
fill ~17 ~11 ~7 ~18 ~11 ~7 stonebrick 3  
fill ~17 ~11 ~9 ~18 ~11 ~9 stonebrick 3  
fill ~17 ~11 ~11 ~18 ~11 ~11 stonebrick 3  
fill ~17 ~11 ~13 ~18 ~11 ~13 stonebrick 3  
fill ~17 ~11 ~34 ~18 ~11 ~34 stonebrick 3  
fill ~17 ~11 ~36 ~18 ~11 ~36 stonebrick 3  
fill ~17 ~11 ~38 ~18 ~11 ~38 stonebrick 3  
fill ~17 ~11 ~40 ~18 ~11 ~40 stonebrick 3  
fill ~17 ~11 ~42 ~18 ~11 ~42 stonebrick 3  
fill ~17 ~11 ~44 ~32 ~11 ~44 stonebrick 3  
fill ~31 ~11 ~5 ~32 ~11 ~5 stonebrick 3  
fill ~31 ~11 ~7 ~32 ~11 ~7 stonebrick 3  
fill ~31 ~11 ~9 ~32 ~11 ~9 stonebrick 3  
fill ~31 ~11 ~11 ~32 ~11 ~11 stonebrick 3  
fill ~31 ~11 ~13 ~32 ~11 ~13 stonebrick 3  
fill ~31 ~11 ~34 ~32 ~11 ~34 stonebrick 3  
fill ~31 ~11 ~36 ~32 ~11 ~36 stonebrick 3  
fill ~31 ~11 ~38 ~32 ~11 ~38 stonebrick 3  
fill ~31 ~11 ~40 ~32 ~11 ~40 stonebrick 3  
fill ~31 ~11 ~42 ~32 ~11 ~42 stonebrick 3  
fill ~44 ~11 ~18 ~48 ~11 ~18 stonebrick 3  
fill ~44 ~11 ~29 ~48 ~11 ~29 stonebrick 3  
fill ~45 ~11 ~20 ~48 ~11 ~20 stonebrick 3  
fill ~45 ~11 ~22 ~48 ~11 ~22 stonebrick 3  
fill ~45 ~11 ~25 ~48 ~11 ~25 stonebrick 3  
fill ~45 ~11 ~27 ~48 ~11 ~27 stonebrick 3  
fill ~1 ~12 ~18 ~5 ~12 ~18 stonebrick 3  
fill ~1 ~12 ~20 ~4 ~12 ~20 stonebrick 3  
fill ~1 ~12 ~22 ~4 ~12 ~22 stonebrick 3  
fill ~1 ~12 ~25 ~4 ~12 ~25 stonebrick 3  
fill ~1 ~12 ~27 ~4 ~12 ~27 stonebrick 3  
fill ~1 ~12 ~29 ~5 ~12 ~29 stonebrick 3  
fill ~17 ~12 ~3 ~32 ~12 ~3 stonebrick 3  
fill ~17 ~12 ~5 ~18 ~12 ~5 stonebrick 3  
fill ~17 ~12 ~7 ~18 ~12 ~7 stonebrick 3  
fill ~17 ~12 ~9 ~18 ~12 ~9 stonebrick 3  
fill ~17 ~12 ~11 ~18 ~12 ~11 stonebrick 3  
fill ~17 ~12 ~13 ~18 ~12 ~13 stonebrick 3  
fill ~17 ~12 ~34 ~18 ~12 ~34 stonebrick 3  
fill ~17 ~12 ~36 ~18 ~12 ~36 stonebrick 3  
fill ~17 ~12 ~38 ~18 ~12 ~38 stonebrick 3  
fill ~17 ~12 ~40 ~18 ~12 ~40 stonebrick 3  
fill ~17 ~12 ~42 ~18 ~12 ~42 stonebrick 3  
fill ~17 ~12 ~44 ~32 ~12 ~44 stonebrick 3  
fill ~31 ~12 ~5 ~32 ~12 ~5 stonebrick 3  
fill ~31 ~12 ~7 ~32 ~12 ~7 stonebrick 3  
fill ~31 ~12 ~9 ~32 ~12 ~9 stonebrick 3  
fill ~31 ~12 ~11 ~32 ~12 ~11 stonebrick 3  
fill ~31 ~12 ~13 ~32 ~12 ~13 stonebrick 3  
fill ~31 ~12 ~34 ~32 ~12 ~34 stonebrick 3  
fill ~31 ~12 ~36 ~32 ~12 ~36 stonebrick 3  
fill ~31 ~12 ~38 ~32 ~12 ~38 stonebrick 3  
fill ~31 ~12 ~40 ~32 ~12 ~40 stonebrick 3  
fill ~31 ~12 ~42 ~32 ~12 ~42 stonebrick 3  
fill ~44 ~12 ~18 ~48 ~12 ~18 stonebrick 3  
fill ~44 ~12 ~29 ~48 ~12 ~29 stonebrick 3  
fill ~45 ~12 ~20 ~48 ~12 ~20 stonebrick 3  
fill ~45 ~12 ~22 ~48 ~12 ~22 stonebrick 3  
fill ~45 ~12 ~25 ~48 ~12 ~25 stonebrick 3  
fill ~45 ~12 ~27 ~48 ~12 ~27 stonebrick 3 
setblock ~1 ~10 ~18 stone_brick_stairs 0 
setblock ~1 ~10 ~20 stone_brick_stairs 0 
setblock ~1 ~10 ~22 stone_brick_stairs 0 
setblock ~1 ~10 ~25 stone_brick_stairs 0 
setblock ~1 ~10 ~27 stone_brick_stairs 0   

KittysCommands:  
setblock ~1 ~10 ~29 stone_brick_stairs 0  
fill ~2 ~13 ~18 ~5 ~13 ~18 stonebrick 3  
fill ~2 ~13 ~20 ~4 ~13 ~20 stonebrick 3  
fill ~2 ~13 ~22 ~4 ~13 ~22 stonebrick 3  
fill ~2 ~13 ~25 ~4 ~13 ~25 stonebrick 3  
fill ~2 ~13 ~27 ~4 ~13 ~27 stonebrick 3  
fill ~2 ~13 ~29 ~5 ~13 ~29 stonebrick 3  
fill ~17 ~13 ~3 ~32 ~13 ~3 stonebrick 3  
fill ~17 ~13 ~5 ~18 ~13 ~5 stonebrick 3  
fill ~17 ~13 ~7 ~18 ~13 ~7 stonebrick 3  
fill ~17 ~13 ~9 ~18 ~13 ~9 stonebrick 3  
fill ~17 ~13 ~11 ~18 ~13 ~11 stonebrick 3  
fill ~17 ~13 ~13 ~18 ~13 ~13 stonebrick 3  
fill ~17 ~13 ~34 ~18 ~13 ~34 stonebrick 3  
fill ~17 ~13 ~36 ~18 ~13 ~36 stonebrick 3  
fill ~17 ~13 ~38 ~18 ~13 ~38 stonebrick 3  
fill ~17 ~13 ~40 ~18 ~13 ~40 stonebrick 3  
fill ~17 ~13 ~42 ~18 ~13 ~42 stonebrick 3  
fill ~17 ~13 ~44 ~32 ~13 ~44 stonebrick 3 
setblock ~19 ~10 ~0 stone_brick_stairs 2 
setblock ~19 ~10 ~47 stone_brick_stairs 3 
setblock ~21 ~10 ~0 stone_brick_stairs 2 
setblock ~21 ~10 ~47 stone_brick_stairs 3 
setblock ~23 ~10 ~0 stone_brick_stairs 2 
setblock ~23 ~10 ~47 stone_brick_stairs 3 
setblock ~26 ~10 ~0 stone_brick_stairs 2 
setblock ~26 ~10 ~47 stone_brick_stairs 3 
setblock ~28 ~10 ~0 stone_brick_stairs 2 
setblock ~28 ~10 ~47 stone_brick_stairs 3 
setblock ~30 ~10 ~0 stone_brick_stairs 2 
setblock ~30 ~10 ~47 stone_brick_stairs 3  
fill ~31 ~13 ~5 ~32 ~13 ~5 stonebrick 3  
fill ~31 ~13 ~7 ~32 ~13 ~7 stonebrick 3  
fill ~31 ~13 ~9 ~32 ~13 ~9 stonebrick 3  
fill ~31 ~13 ~11 ~32 ~13 ~11 stonebrick 3  
fill ~31 ~13 ~13 ~32 ~13 ~13 stonebrick 3  
fill ~31 ~13 ~34 ~32 ~13 ~34 stonebrick 3  
fill ~31 ~13 ~36 ~32 ~13 ~36 stonebrick 3  
fill ~31 ~13 ~38 ~32 ~13 ~38 stonebrick 3  
fill ~31 ~13 ~40 ~32 ~13 ~40 stonebrick 3  
fill ~31 ~13 ~42 ~32 ~13 ~42 stonebrick 3  
fill ~44 ~13 ~18 ~47 ~13 ~18 stonebrick 3  
fill ~44 ~13 ~29 ~47 ~13 ~29 stonebrick 3  
fill ~45 ~13 ~20 ~47 ~13 ~20 stonebrick 3  
fill ~45 ~13 ~22 ~47 ~13 ~22 stonebrick 3  
fill ~45 ~13 ~25 ~47 ~13 ~25 stonebrick 3  
fill ~45 ~13 ~27 ~47 ~13 ~27 stonebrick 3 
setblock ~48 ~10 ~18 stone_brick_stairs 1 
setblock ~48 ~10 ~20 stone_brick_stairs 1 
setblock ~48 ~10 ~22 stone_brick_stairs 1 
setblock ~48 ~10 ~25 stone_brick_stairs 1 
setblock ~48 ~10 ~27 stone_brick_stairs 1 
setblock ~48 ~10 ~29 stone_brick_stairs 1  
fill ~2 ~14 ~18 ~5 ~14 ~18 stonebrick 3  
fill ~2 ~14 ~19 ~4 ~14 ~19 stonebrick 3  
fill ~2 ~14 ~20 ~4 ~14 ~20 stonebrick 3  
fill ~2 ~14 ~21 ~4 ~14 ~21 stonebrick 3  
fill ~2 ~14 ~22 ~4 ~14 ~22 stonebrick 3  
fill ~2 ~14 ~23 ~4 ~14 ~23 stonebrick 3  
fill ~2 ~14 ~24 ~4 ~14 ~24 stonebrick 3  
fill ~2 ~14 ~25 ~4 ~14 ~25 stonebrick 3  
fill ~2 ~14 ~26 ~4 ~14 ~26 stonebrick 3  
fill ~2 ~14 ~27 ~4 ~14 ~27 stonebrick 3  
fill ~2 ~14 ~28 ~4 ~14 ~28 stonebrick 3  
fill ~2 ~14 ~29 ~5 ~14 ~29 stonebrick 3  
fill ~17 ~14 ~3 ~32 ~14 ~3 stonebrick 3  
fill ~17 ~14 ~5 ~18 ~14 ~5 stonebrick 3  
fill ~17 ~14 ~7 ~18 ~14 ~7 stonebrick 3  
fill ~17 ~14 ~9 ~18 ~14 ~9 stonebrick 3  
fill ~17 ~14 ~11 ~18 ~14 ~11 stonebrick 3  
fill ~17 ~14 ~13 ~18 ~14 ~13 stonebrick 3  
fill ~17 ~14 ~34 ~18 ~14 ~34 stonebrick 3  
fill ~17 ~14 ~36 ~18 ~14 ~36 stonebrick 3  
fill ~17 ~14 ~38 ~18 ~14 ~38 stonebrick 3  
fill ~17 ~14 ~40 ~18 ~14 ~40 stonebrick 3  
fill ~17 ~14 ~42 ~18 ~14 ~42 stonebrick 3  
fill ~17 ~14 ~44 ~32 ~14 ~44 stonebrick 3  
fill ~20 ~14 ~1 ~20 ~14 ~3 stonebrick 3  
fill ~20 ~14 ~45 ~20 ~15 ~45 stonebrick 3  
fill ~20 ~14 ~46 ~20 ~14 ~44 stonebrick 3  
fill ~22 ~14 ~1 ~22 ~14 ~3 stonebrick 3  
fill ~22 ~14 ~45 ~22 ~15 ~45 stonebrick 3  
fill ~22 ~14 ~46 ~22 ~14 ~44 stonebrick 3  
fill ~24 ~14 ~1 ~30 ~14 ~1 stonebrick 3  
fill ~24 ~14 ~2 ~30 ~14 ~2 stonebrick 3  
fill ~24 ~14 ~45 ~30 ~14 ~45 stonebrick 3  
fill ~24 ~14 ~46 ~30 ~14 ~46 stonebrick 3  
fill ~31 ~14 ~5 ~32 ~14 ~5 stonebrick 3  
fill ~31 ~14 ~7 ~32 ~14 ~7 stonebrick 3  
fill ~31 ~14 ~9 ~32 ~14 ~9 stonebrick 3  
fill ~31 ~14 ~11 ~32 ~14 ~11 stonebrick 3  
fill ~31 ~14 ~13 ~32 ~14 ~13 stonebrick 3  
fill ~31 ~14 ~34 ~32 ~14 ~34 stonebrick 3  
fill ~31 ~14 ~36 ~32 ~14 ~36 stonebrick 3  
fill ~31 ~14 ~38 ~32 ~14 ~38 stonebrick 3  
fill ~31 ~14 ~40 ~32 ~14 ~40 stonebrick 3  
fill ~31 ~14 ~42 ~32 ~14 ~42 stonebrick 3  
fill ~44 ~14 ~18 ~47 ~14 ~18 stonebrick 3  
fill ~44 ~14 ~29 ~47 ~14 ~29 stonebrick 3  
fill ~45 ~14 ~20 ~47 ~14 ~20 stonebrick 3  
fill ~45 ~14 ~22 ~47 ~14 ~22 stonebrick 3  
fill ~45 ~14 ~25 ~47 ~14 ~25 stonebrick 3  
fill ~45 ~14 ~27 ~47 ~14 ~27 stonebrick 3  
fill ~46 ~14 ~19 ~47 ~14 ~19 stonebrick 3  
fill ~46 ~14 ~21 ~47 ~14 ~21 stonebrick 3  
fill ~46 ~14 ~23 ~47 ~14 ~23 stonebrick 3  
fill ~46 ~14 ~24 ~47 ~14 ~24 stonebrick 3  
fill ~46 ~14 ~26 ~47 ~14 ~26 stonebrick 3  
fill ~46 ~14 ~28 ~47 ~14 ~28 stonebrick 3 
setblock ~2 ~12 ~18 stone_brick_stairs 0 
setblock ~2 ~12 ~20 stone_brick_stairs 0 
setblock ~2 ~12 ~22 stone_brick_stairs 0 
setblock ~2 ~12 ~25 stone_brick_stairs 0 
setblock ~2 ~12 ~27 stone_brick_stairs 0 
setblock ~2 ~12 ~29 stone_brick_stairs 0  
fill ~3 ~15 ~18 ~5 ~15 ~18 stonebrick 3  
fill ~3 ~15 ~19 ~3 ~15 ~29 stonebrick 3  
fill ~4 ~15 ~20 ~4 ~21 ~20 stonebrick 3  
fill ~4 ~15 ~22 ~4 ~21 ~22 stonebrick 3  
fill ~4 ~15 ~25 ~4 ~21 ~25 stonebrick 3  
fill ~4 ~15 ~27 ~4 ~21 ~27 stonebrick 3  
fill ~4 ~15 ~29 ~5 ~15 ~29 stonebrick 3  
fill ~17 ~15 ~3 ~32 ~15 ~3 stonebrick 3  
fill ~17 ~15 ~5 ~18 ~15 ~5 stonebrick 3  
fill ~17 ~15 ~7 ~18 ~15 ~7 stonebrick 3  
fill ~17 ~15 ~9 ~18 ~15 ~9 stonebrick 3  
fill ~17 ~15 ~11 ~18 ~15 ~11 stonebrick 3  
fill ~17 ~15 ~13 ~18 ~15 ~13 stonebrick 3  
fill ~17 ~15 ~34 ~18 ~15 ~34 stonebrick 3  
fill ~17 ~15 ~36 ~18 ~15 ~36 stonebrick 3  
fill ~17 ~15 ~38 ~18 ~15 ~38 stonebrick 3  
fill ~17 ~15 ~40 ~18 ~15 ~40 stonebrick 3  
fill ~17 ~15 ~42 ~18 ~15 ~42 stonebrick 3  
fill ~17 ~15 ~44 ~32 ~15 ~44 stonebrick 3 
setblock ~19 ~12 ~1 stone_brick_stairs 2 
setblock ~19 ~12 ~46 stone_brick_stairs 3 
setblock ~20 ~12 ~2 stonebrick 3 
setblock ~21 ~12 ~1 stone_brick_stairs 2 
setblock ~21 ~12 ~46 stone_brick_stairs 3 
setblock ~22 ~12 ~2 stonebrick 3 
setblock ~23 ~12 ~1 stone_brick_stairs 2 
setblock ~23 ~12 ~46 stone_brick_stairs 3  
fill ~24 ~15 ~2 ~30 ~15 ~2 stonebrick 3  
fill ~24 ~15 ~45 ~30 ~15 ~45 stonebrick 3 
setblock ~26 ~12 ~1 stone_brick_stairs 2 
setblock ~26 ~12 ~46 stone_brick_stairs 3 
setblock ~28 ~12 ~1 stone_brick_stairs 2 
setblock ~28 ~12 ~46 stone_brick_stairs 3 
setblock ~30 ~12 ~1 stone_brick_stairs 2 
setblock ~30 ~12 ~46 stone_brick_stairs 3  
fill ~31 ~15 ~5 ~32 ~15 ~5 stonebrick 3  
fill ~31 ~15 ~7 ~32 ~15 ~7 stonebrick 3  
fill ~31 ~15 ~9 ~32 ~15 ~9 stonebrick 3  
fill ~31 ~15 ~11 ~32 ~15 ~11 stonebrick 3  
fill ~31 ~15 ~13 ~32 ~15 ~13 stonebrick 3  
fill ~31 ~15 ~34 ~32 ~15 ~34 stonebrick 3  
fill ~31 ~15 ~36 ~32 ~15 ~36 stonebrick 3  
fill ~31 ~15 ~38 ~32 ~15 ~38 stonebrick 3  
fill ~31 ~15 ~40 ~32 ~15 ~40 stonebrick 3  
fill ~31 ~15 ~42 ~32 ~15 ~42 stonebrick 3  
fill ~44 ~15 ~18 ~46 ~15 ~18 stonebrick 3  
fill ~44 ~15 ~29 ~46 ~15 ~29 stonebrick 3  
fill ~45 ~15 ~20 ~46 ~15 ~20 stonebrick 3  
fill ~45 ~15 ~22 ~46 ~15 ~22 stonebrick 3  
fill ~45 ~15 ~25 ~46 ~15 ~25 stonebrick 3  
fill ~45 ~15 ~27 ~46 ~15 ~27 stonebrick 3  
fill ~46 ~15 ~19 ~46 ~14 ~19 stonebrick 3  
fill ~46 ~15 ~21 ~46 ~14 ~21 stonebrick 3  
fill ~46 ~15 ~23 ~46 ~14 ~23 stonebrick 3  
fill ~46 ~15 ~24 ~46 ~14 ~24 stonebrick 3  
fill ~46 ~15 ~26 ~46 ~14 ~26 stonebrick 3  
fill ~46 ~15 ~28 ~46 ~14 ~28 stonebrick 3 
setblock ~47 ~12 ~18 stone_brick_stairs 1 
setblock ~47 ~12 ~20 stone_brick_stairs 1 
setblock ~47 ~12 ~22 stone_brick_stairs 1 
setblock ~47 ~12 ~25 stone_brick_stairs 1 
setblock ~47 ~12 ~27 stone_brick_stairs 1 
setblock ~47 ~12 ~29 stone_brick_stairs 1  
fill ~3 ~16 ~18 ~5 ~16 ~18 stonebrick 3  
fill ~3 ~16 ~20 ~3 ~19 ~20 stonebrick 3  
fill ~3 ~16 ~22 ~3 ~20 ~22 stonebrick 3  
fill ~3 ~16 ~25 ~3 ~20 ~25 stonebrick 3  
fill ~3 ~16 ~27 ~3 ~19 ~27 stonebrick 3  
fill ~3 ~16 ~29 ~5 ~16 ~29 stonebrick 3  
fill ~17 ~16 ~3 ~32 ~16 ~3 stonebrick 3  
fill ~17 ~16 ~5 ~18 ~16 ~5 stonebrick 3  
fill ~17 ~16 ~7 ~18 ~16 ~7 stonebrick 3  
fill ~17 ~16 ~9 ~18 ~16 ~9 stonebrick 3  
fill ~17 ~16 ~11 ~18 ~16 ~11 stonebrick 3  
fill ~17 ~16 ~13 ~18 ~16 ~13 stonebrick 3  
fill ~17 ~16 ~34 ~18 ~16 ~34 stonebrick 3  
fill ~17 ~16 ~36 ~18 ~16 ~36 stonebrick 3  
fill ~17 ~16 ~38 ~18 ~16 ~38 stonebrick 3  
fill ~17 ~16 ~40 ~18 ~16 ~40 stonebrick 3  
fill ~17 ~16 ~42 ~18 ~16 ~42 stonebrick 3  
fill ~17 ~16 ~44 ~32 ~16 ~44 stonebrick 3  
fill ~31 ~16 ~5 ~32 ~16 ~5 stonebrick 3  
fill ~31 ~16 ~7 ~32 ~16 ~7 stonebrick 3  
fill ~31 ~16 ~9 ~32 ~16 ~9 stonebrick 3  
fill ~31 ~16 ~11 ~32 ~16 ~11 stonebrick 3  
fill ~31 ~16 ~13 ~32 ~16 ~13 stonebrick 3  
fill ~31 ~16 ~34 ~32 ~16 ~34 stonebrick 3  
fill ~31 ~16 ~36 ~32 ~16 ~36 stonebrick 3  
fill ~31 ~16 ~38 ~32 ~16 ~38 stonebrick 3  
fill ~31 ~16 ~40 ~32 ~16 ~40 stonebrick 3  
fill ~31 ~16 ~42 ~32 ~16 ~42 stonebrick 3  
fill ~44 ~16 ~18 ~46 ~16 ~18 stonebrick 3  
fill ~44 ~16 ~29 ~46 ~16 ~29 stonebrick 3  
fill ~45 ~16 ~20 ~46 ~16 ~20 stonebrick 3  
fill ~45 ~16 ~22 ~46 ~16 ~22 stonebrick 3  
fill ~45 ~16 ~25 ~46 ~16 ~25 stonebrick 3  
fill ~45 ~16 ~27 ~46 ~16 ~27 stonebrick 3  
fill ~3 ~17 ~18 ~5 ~17 ~18 stonebrick 3  
fill ~3 ~17 ~29 ~5 ~17 ~29 stonebrick 3  
fill ~17 ~17 ~3 ~32 ~17 ~3 stonebrick 3  
fill ~17 ~17 ~5 ~18 ~17 ~5 stonebrick 3  
fill ~17 ~17 ~7 ~18 ~17 ~7 stonebrick 3  
fill ~17 ~17 ~9 ~18 ~17 ~9 stonebrick 3  
fill ~17 ~17 ~11 ~18 ~17 ~11 stonebrick 3  
fill ~17 ~17 ~13 ~18 ~17 ~13 stonebrick 3  
fill ~17 ~17 ~34 ~18 ~17 ~34 stonebrick 3  
fill ~17 ~17 ~36 ~18 ~17 ~36 stonebrick 3  
fill ~17 ~17 ~38 ~18 ~17 ~38 stonebrick 3  
fill ~17 ~17 ~40 ~18 ~17 ~40 stonebrick 3  
fill ~17 ~17 ~42 ~18 ~17 ~42 stonebrick 3  
fill ~17 ~17 ~44 ~32 ~17 ~44 stonebrick 3  
fill ~31 ~17 ~5 ~32 ~17 ~5 stonebrick 3  
fill ~31 ~17 ~7 ~32 ~17 ~7 stonebrick 3  
fill ~31 ~17 ~9 ~32 ~17 ~9 stonebrick 3  
fill ~31 ~17 ~11 ~32 ~17 ~11 stonebrick 3  
fill ~31 ~17 ~13 ~32 ~17 ~13 stonebrick 3  
fill ~31 ~17 ~34 ~32 ~17 ~34 stonebrick 3  
fill ~31 ~17 ~36 ~32 ~17 ~36 stonebrick 3  
fill ~31 ~17 ~38 ~32 ~17 ~38 stonebrick 3  
fill ~31 ~17 ~40 ~32 ~17 ~40 stonebrick 3  
fill ~31 ~17 ~42 ~32 ~17 ~42 stonebrick 3  
fill ~44 ~17 ~18 ~46 ~17 ~18 stonebrick 3  
fill ~44 ~17 ~29 ~46 ~17 ~29 stonebrick 3  
fill ~45 ~17 ~20 ~46 ~17 ~20 stonebrick 3  
fill ~45 ~17 ~22 ~46 ~17 ~22 stonebrick 3  
fill ~45 ~17 ~25 ~46 ~17 ~25 stonebrick 3  
fill ~45 ~17 ~27 ~46 ~17 ~27 stonebrick 3  
fill ~3 ~18 ~18 ~5 ~18 ~18 stonebrick 3  
fill ~3 ~18 ~29 ~5 ~18 ~29 stonebrick 3  
fill ~17 ~18 ~3 ~32 ~18 ~3 stonebrick 3  
fill ~17 ~18 ~5 ~18 ~18 ~5 stonebrick 3  
fill ~17 ~18 ~7 ~18 ~18 ~7 stonebrick 3  
fill ~17 ~18 ~9 ~18 ~18 ~9 stonebrick 3  
fill ~17 ~18 ~11 ~18 ~18 ~11 stonebrick 3  
fill ~17 ~18 ~13 ~18 ~18 ~13 stonebrick 3  
fill ~17 ~18 ~34 ~18 ~18 ~34 stonebrick 3  
fill ~17 ~18 ~36 ~18 ~18 ~36 stonebrick 3  
fill ~17 ~18 ~38 ~18 ~18 ~38 stonebrick 3  
fill ~17 ~18 ~40 ~18 ~18 ~40 stonebrick 3  
fill ~17 ~18 ~42 ~18 ~18 ~42 stonebrick 3  
fill ~17 ~18 ~44 ~32 ~18 ~44 stonebrick 3  
fill ~31 ~18 ~5 ~32 ~18 ~5 stonebrick 3  
fill ~31 ~18 ~7 ~32 ~18 ~7 stonebrick 3  
fill ~31 ~18 ~9 ~32 ~18 ~9 stonebrick 3  
fill ~31 ~18 ~11 ~32 ~18 ~11 stonebrick 3  
fill ~31 ~18 ~13 ~32 ~18 ~13 stonebrick 3  
fill ~31 ~18 ~34 ~32 ~18 ~34 stonebrick 3  
fill ~31 ~18 ~36 ~32 ~18 ~36 stonebrick 3  
fill ~31 ~18 ~38 ~32 ~18 ~38 stonebrick 3  
fill ~31 ~18 ~40 ~32 ~18 ~40 stonebrick 3  
fill ~31 ~18 ~42 ~32 ~18 ~42 stonebrick 3  
fill ~44 ~18 ~18 ~46 ~18 ~18 stonebrick 3  
fill ~44 ~18 ~29 ~46 ~18 ~29 stonebrick 3  
fill ~45 ~18 ~20 ~46 ~18 ~20 stonebrick 3  
fill ~45 ~18 ~22 ~46 ~18 ~22 stonebrick 3  
fill ~45 ~18 ~25 ~46 ~18 ~25 stonebrick 3  
fill ~45 ~18 ~27 ~46 ~18 ~27 stonebrick 3 
setblock ~3 ~16 ~18 stone_brick_stairs 0 
setblock ~3 ~16 ~29 stone_brick_stairs 0  
fill ~4 ~19 ~18 ~5 ~19 ~18 stonebrick 3  
fill ~4 ~19 ~29 ~5 ~19 ~29 stonebrick 3  
fill ~17 ~19 ~3 ~32 ~19 ~3 stonebrick 3  
fill ~17 ~19 ~5 ~18 ~19 ~5 stonebrick 3  
fill ~17 ~19 ~7 ~18 ~19 ~7 stonebrick 3  
fill ~17 ~19 ~9 ~18 ~19 ~9 stonebrick 3  
fill ~17 ~19 ~11 ~18 ~19 ~11 stonebrick 3  
fill ~17 ~19 ~13 ~18 ~19 ~13 stonebrick 3  
fill ~17 ~19 ~34 ~18 ~19 ~34 stonebrick 3  
fill ~17 ~19 ~36 ~18 ~19 ~36 stonebrick 3  
fill ~17 ~19 ~38 ~18 ~19 ~38 stonebrick 3  
fill ~17 ~19 ~40 ~18 ~19 ~40 stonebrick 3  
fill ~17 ~19 ~42 ~18 ~19 ~42 stonebrick 3  
fill ~17 ~19 ~44 ~32 ~19 ~44 stonebrick 3 
setblock ~19 ~16 ~2 stone_brick_stairs 2 
setblock ~19 ~16 ~45 stone_brick_stairs 3 
setblock ~30 ~16 ~2 stone_brick_stairs 2 
setblock ~30 ~16 ~45 stone_brick_stairs 3  
fill ~31 ~19 ~5 ~32 ~19 ~5 stonebrick 3  
fill ~31 ~19 ~7 ~32 ~19 ~7 stonebrick 3  
fill ~31 ~19 ~9 ~32 ~19 ~9 stonebrick 3  
fill ~31 ~19 ~11 ~32 ~19 ~11 stonebrick 3  
fill ~31 ~19 ~13 ~32 ~19 ~13 stonebrick 3  
fill ~31 ~19 ~34 ~32 ~19 ~34 stonebrick 3  
fill ~31 ~19 ~36 ~32 ~19 ~36 stonebrick 3  
fill ~31 ~19 ~38 ~32 ~19 ~38 stonebrick 3  
fill ~31 ~19 ~40 ~32 ~19 ~40 stonebrick 3  
fill ~31 ~19 ~42 ~32 ~19 ~42 stonebrick 3  
fill ~44 ~19 ~18 ~45 ~19 ~18 stonebrick 3  
fill ~44 ~19 ~29 ~45 ~19 ~29 stonebrick 3  
fill ~45 ~19 ~20 ~46 ~19 ~20 stonebrick 3  
fill ~45 ~19 ~22 ~46 ~19 ~22 stonebrick 3  
fill ~45 ~19 ~25 ~46 ~19 ~25 stonebrick 3  
fill ~45 ~19 ~27 ~46 ~19 ~27 stonebrick 3 
setblock ~46 ~16 ~18 stone_brick_stairs 1 
setblock ~46 ~16 ~29 stone_brick_stairs 1 
setblock ~3 ~17 ~20 stone_brick_stairs 0 
setblock ~3 ~17 ~27 stone_brick_stairs 0 
setblock ~4 ~17 ~16 stone_brick_stairs 2  
fill ~4 ~20 ~18 ~5 ~20 ~18 stonebrick 3  
fill ~4 ~20 ~29 ~5 ~20 ~29 stonebrick 3 
setblock ~4 ~17 ~31 stone_brick_stairs 3 
setblock ~6 ~17 ~16 stone_brick_stairs 2 
setblock ~6 ~17 ~31 stone_brick_stairs 3 
setblock ~8 ~17 ~16 stone_brick_stairs 2 
setblock ~8 ~17 ~31 stone_brick_stairs 3 
setblock ~10 ~17 ~16 stone_brick_stairs 2 
setblock ~10 ~17 ~31 stone_brick_stairs 3 
setblock ~12 ~17 ~16 stone_brick_stairs 2 
setblock ~12 ~17 ~31 stone_brick_stairs 3 
setblock ~14 ~17 ~16 stone_brick_stairs 2 
setblock ~14 ~17 ~31 stone_brick_stairs 3 
setblock ~17 ~17 ~3 stone_brick_stairs 0 
setblock ~17 ~17 ~5 stone_brick_stairs 0 
setblock ~17 ~17 ~7 stone_brick_stairs 0 
setblock ~17 ~17 ~9 stone_brick_stairs 0 
setblock ~17 ~17 ~11 stone_brick_stairs 0 
setblock ~17 ~17 ~13 stone_brick_stairs 0 
setblock ~17 ~17 ~34 stone_brick_stairs 0 
setblock ~17 ~17 ~36 stone_brick_stairs 0 
setblock ~17 ~17 ~38 stone_brick_stairs 0 
setblock ~17 ~17 ~40 stone_brick_stairs 0 
setblock ~17 ~17 ~42 stone_brick_stairs 0 
setblock ~17 ~17 ~44 stone_brick_stairs 0  
fill ~18 ~20 ~3 ~31 ~20 ~3 stonebrick 3 
setblock ~18 ~17 ~5 stonebrick 3 
setblock ~18 ~17 ~7 stonebrick 3 
setblock ~18 ~17 ~9 stonebrick 3 
setblock ~18 ~17 ~11 stonebrick 3 
setblock ~18 ~17 ~13 stonebrick 3 
setblock ~18 ~17 ~34 stonebrick 3 
setblock ~18 ~17 ~36 stonebrick 3 
setblock ~18 ~17 ~38 stonebrick 3 
setblock ~18 ~17 ~40 stonebrick 3 
setblock ~18 ~17 ~42 stonebrick 3  
fill ~18 ~20 ~44 ~31 ~20 ~44 stonebrick 3 
setblock ~21 ~17 ~2 stone_brick_stairs 2 
setblock ~21 ~17 ~45 stone_brick_stairs 3 
setblock ~28 ~17 ~2 stone_brick_stairs 2 
setblock ~28 ~17 ~45 stone_brick_stairs 3  
fill ~31 ~20 ~5 ~31 ~1 ~5 stonebrick 3  
fill ~31 ~20 ~7 ~31 ~1 ~7 stonebrick 3  
fill ~31 ~20 ~9 ~31 ~1 ~9 stonebrick 3  
fill ~31 ~20 ~11 ~31 ~1 ~11 stonebrick 3  
fill ~31 ~20 ~13 ~31 ~1 ~13 stonebrick 3  
fill ~31 ~20 ~34 ~31 ~1 ~34 stonebrick 3  
fill ~31 ~20 ~36 ~31 ~1 ~36 stonebrick 3  
fill ~31 ~20 ~38 ~31 ~1 ~38 stonebrick 3  
fill ~31 ~20 ~40 ~31 ~1 ~40 stonebrick 3  
fill ~31 ~20 ~42 ~31 ~1 ~42 stonebrick 3 
setblock ~32 ~17 ~3 stone_brick_stairs 1 
setblock ~32 ~17 ~5 stone_brick_stairs 1 
setblock ~32 ~17 ~7 stone_brick_stairs 1 
setblock ~32 ~17 ~9 stone_brick_stairs 1 
setblock ~32 ~17 ~11 stone_brick_stairs 1 
setblock ~32 ~17 ~13 stone_brick_stairs 1 
setblock ~32 ~17 ~34 stone_brick_stairs 1 
setblock ~32 ~17 ~36 stone_brick_stairs 1 
setblock ~32 ~17 ~38 stone_brick_stairs 1 
setblock ~32 ~17 ~40 stone_brick_stairs 1 
setblock ~32 ~17 ~42 stone_brick_stairs 1 
setblock ~32 ~17 ~44 stone_brick_stairs 1 
setblock ~35 ~17 ~16 stone_brick_stairs 2 
setblock ~35 ~17 ~31 stone_brick_stairs 3 
setblock ~37 ~17 ~16 stone_brick_stairs 2 
setblock ~37 ~17 ~31 stone_brick_stairs 3 
setblock ~39 ~17 ~16 stone_brick_stairs 2 
setblock ~39 ~17 ~31 stone_brick_stairs 3 
setblock ~41 ~17 ~16 stone_brick_stairs 2 
setblock ~41 ~17 ~31 stone_brick_stairs 3 
setblock ~43 ~17 ~16 stone_brick_stairs 2 
setblock ~43 ~17 ~31 stone_brick_stairs 3  
fill ~44 ~20 ~18 ~45 ~20 ~18 stonebrick 3  
fill ~44 ~20 ~29 ~45 ~20 ~29 stonebrick 3 
setblock ~45 ~17 ~16 stone_brick_stairs 2  
fill ~45 ~20 ~20 ~45 ~21 ~20 stonebrick 3  
fill ~45 ~20 ~22 ~46 ~20 ~22 stonebrick 3  
fill ~45 ~20 ~25 ~46 ~20 ~25 stonebrick 3  
fill ~45 ~20 ~27 ~45 ~21 ~27 stonebrick 3 
setblock ~45 ~17 ~31 stone_brick_stairs 3 
setblock ~46 ~17 ~20 stone_brick_stairs 1 
setblock ~46 ~17 ~27 stone_brick_stairs 1 
setblock ~3 ~18 ~22 stone_brick_stairs 0 
setblock ~3 ~18 ~25 stone_brick_stairs 0 
setblock ~4 ~18 ~17 stone_brick_stairs 2  
fill ~4 ~21 ~18 ~15 ~21 ~18 stonebrick 3  
fill ~4 ~21 ~29 ~15 ~21 ~29 stonebrick 3 
setblock ~4 ~18 ~30 stone_brick_stairs 3 
setblock ~6 ~18 ~17 stone_brick_stairs 2 
setblock ~6 ~18 ~30 stone_brick_stairs 3 
setblock ~8 ~18 ~17 stone_brick_stairs 2 
setblock ~8 ~18 ~30 stone_brick_stairs 3 
setblock ~10 ~18 ~17 stone_brick_stairs 2 
setblock ~10 ~18 ~30 stone_brick_stairs 3 
setblock ~12 ~18 ~17 stone_brick_stairs 2 
setblock ~12 ~18 ~30 stone_brick_stairs 3 
setblock ~14 ~18 ~17 stone_brick_stairs 2 
setblock ~14 ~18 ~30 stone_brick_stairs 3 
setblock ~18 ~18 ~3 stone_brick_stairs 0 
setblock ~18 ~18 ~5 stone_brick_stairs 0 
setblock ~18 ~18 ~7 stone_brick_stairs 0 
setblock ~18 ~18 ~9 stone_brick_stairs 0 
setblock ~18 ~18 ~11 stone_brick_stairs 0 
setblock ~18 ~18 ~13 stone_brick_stairs 0 
setblock ~18 ~18 ~34 stone_brick_stairs 0 
setblock ~18 ~18 ~36 stone_brick_stairs 0 
setblock ~18 ~18 ~38 stone_brick_stairs 0 
setblock ~18 ~18 ~40 stone_brick_stairs 0 
setblock ~18 ~18 ~42 stone_brick_stairs 0 
setblock ~18 ~18 ~44 stone_brick_stairs 0  
fill ~19 ~21 ~3 ~30 ~21 ~3 stonebrick 3 
setblock ~19 ~18 ~5 stonebrick 3 
setblock ~19 ~18 ~7 stonebrick 3 
setblock ~19 ~18 ~9 stonebrick 3 
setblock ~19 ~18 ~11 stonebrick 3 
setblock ~19 ~18 ~13 stonebrick 3 
setblock ~19 ~18 ~34 stonebrick 3 
setblock ~19 ~18 ~36 stonebrick 3 
setblock ~19 ~18 ~38 stonebrick 3 
setblock ~19 ~18 ~40 stonebrick 3 
setblock ~19 ~18 ~42 stonebrick 3  
fill ~19 ~21 ~44 ~30 ~21 ~44 stonebrick 3 
setblock ~23 ~18 ~2 stone_brick_stairs 2 
setblock ~23 ~18 ~45 stone_brick_stairs 3 
setblock ~26 ~18 ~2 stone_brick_stairs 2 
setblock ~26 ~18 ~45 stone_brick_stairs 3 
setblock ~30 ~18 ~5 stonebrick 3 
setblock ~30 ~18 ~7 stonebrick 3 
setblock ~30 ~18 ~9 stonebrick 3 
setblock ~30 ~18 ~11 stonebrick 3 
setblock ~30 ~18 ~13 stonebrick 3 
setblock ~30 ~18 ~34 stonebrick 3 
setblock ~30 ~18 ~36 stonebrick 3 
setblock ~30 ~18 ~38 stonebrick 3 
setblock ~30 ~18 ~40 stonebrick 3 
setblock ~30 ~18 ~42 stonebrick 3 
setblock ~31 ~18 ~3 stone_brick_stairs 1 
setblock ~31 ~18 ~5 stone_brick_stairs 1 
setblock ~31 ~18 ~7 stone_brick_stairs 1 
setblock ~31 ~18 ~9 stone_brick_stairs 1 
setblock ~31 ~18 ~11 stone_brick_stairs 1 
setblock ~31 ~18 ~13 stone_brick_stairs 1 
setblock ~31 ~18 ~34 stone_brick_stairs 1 
setblock ~31 ~18 ~36 stone_brick_stairs 1 
setblock ~31 ~18 ~38 stone_brick_stairs 1 
setblock ~31 ~18 ~40 stone_brick_stairs 1 
setblock ~31 ~18 ~42 stone_brick_stairs 1 
setblock ~31 ~18 ~44 stone_brick_stairs 1 
setblock ~35 ~18 ~17 stone_brick_stairs 2 
setblock ~35 ~18 ~18 stonebrick 3 
setblock ~35 ~18 ~29 stonebrick 3 
setblock ~35 ~18 ~30 stone_brick_stairs 3 
setblock ~37 ~18 ~17 stone_brick_stairs 2 
setblock ~37 ~18 ~18 stonebrick 3 
setblock ~37 ~18 ~29 stonebrick 3 
setblock ~37 ~18 ~30 stone_brick_stairs 3 
setblock ~39 ~18 ~17 stone_brick_stairs 2 
setblock ~39 ~18 ~18 stonebrick 3 
setblock ~39 ~18 ~29 stonebrick 3 
setblock ~39 ~18 ~30 stone_brick_stairs 3 
setblock ~41 ~18 ~17 stone_brick_stairs 2 
setblock ~41 ~18 ~18 stonebrick 3 
setblock ~41 ~18 ~29 stonebrick 3 
setblock ~41 ~18 ~30 stone_brick_stairs 3 
setblock ~43 ~18 ~17 stone_brick_stairs 2  
fill ~43 ~21 ~18 ~45 ~21 ~18 stonebrick 3  
fill ~43 ~21 ~29 ~45 ~21 ~29 stonebrick 3 
setblock ~43 ~18 ~30 stone_brick_stairs 3 
setblock ~45 ~18 ~17 stone_brick_stairs 2  
fill ~45 ~21 ~22 ~45 ~1 ~22 stonebrick 3  
fill ~45 ~21 ~25 ~45 ~1 ~25 stonebrick 3 
setblock ~45 ~18 ~30 stone_brick_stairs 3 
setblock ~46 ~18 ~22 stone_brick_stairs 1 
setblock ~46 ~18 ~25 stone_brick_stairs 1  
fill ~5 ~22 ~19 ~16 ~22 ~19 stonebrick 3  
fill ~5 ~22 ~20 ~5 ~22 ~28 stonebrick 3  
fill ~6 ~22 ~28 ~16 ~22 ~28 stonebrick 3  
fill ~16 ~22 ~18 ~17 ~22 ~18 stonebrick 3  
fill ~16 ~22 ~29 ~17 ~22 ~29 stonebrick 3  
fill ~17 ~22 ~17 ~18 ~22 ~17 stonebrick 3  
fill ~17 ~22 ~30 ~18 ~22 ~30 stonebrick 3  
fill ~18 ~22 ~16 ~19 ~22 ~16 stonebrick 3  
fill ~18 ~22 ~31 ~19 ~22 ~31 stonebrick 3  
fill ~19 ~22 ~15 ~20 ~22 ~15 stonebrick 3  
fill ~19 ~22 ~32 ~20 ~22 ~32 stonebrick 3  
fill ~20 ~22 ~4 ~29 ~22 ~4 stonebrick 3  
fill ~20 ~22 ~5 ~20 ~22 ~15 stonebrick 3  
fill ~20 ~22 ~33 ~20 ~40 ~33 stonebrick 3  
fill ~20 ~22 ~34 ~20 ~22 ~43 stonebrick 3  
fill ~21 ~22 ~43 ~29 ~22 ~43 stonebrick 3  
fill ~29 ~22 ~5 ~29 ~22 ~15 stonebrick 3  
fill ~29 ~22 ~32 ~30 ~22 ~32 stonebrick 3  
fill ~29 ~22 ~33 ~29 ~40 ~33 stonebrick 3  
fill ~29 ~22 ~34 ~29 ~22 ~43 stonebrick 3  
fill ~30 ~22 ~15 ~30 ~25 ~15 stonebrick 3  
fill ~30 ~22 ~16 ~31 ~22 ~16 stonebrick 3  
fill ~30 ~22 ~31 ~31 ~22 ~31 stonebrick 3  
fill ~31 ~22 ~17 ~32 ~22 ~17 stonebrick 3  
fill ~31 ~22 ~30 ~32 ~22 ~30 stonebrick 3  
fill ~32 ~22 ~18 ~33 ~22 ~18 stonebrick 3  
fill ~32 ~22 ~29 ~33 ~22 ~29 stonebrick 3  
fill ~33 ~22 ~19 ~44 ~22 ~19 stonebrick 3  
fill ~33 ~22 ~28 ~44 ~22 ~28 stonebrick 3  
fill ~44 ~22 ~20 ~44 ~22 ~28 stonebrick 3 
setblock ~4 ~20 ~20 stone_brick_stairs 4 
setblock ~4 ~20 ~22 stone_brick_stairs 4 
setblock ~4 ~20 ~25 stone_brick_stairs 4 
setblock ~4 ~20 ~27 stone_brick_stairs 4  
fill ~5 ~23 ~19 ~5 ~35 ~19 stonebrick 3  
fill ~5 ~23 ~21 ~5 ~35 ~21 stonebrick 3  
fill ~5 ~23 ~23 ~5 ~35 ~23 stonebrick 3  
fill ~5 ~23 ~24 ~5 ~35 ~24 stonebrick 3  
fill ~5 ~23 ~26 ~5 ~35 ~26 stonebrick 3  
fill ~5 ~23 ~28 ~5 ~35 ~28 stonebrick 3 
setblock ~6 ~20 ~18 stone_brick_stairs 6 
setblock ~6 ~20 ~29 stone_brick_stairs 7  
fill ~7 ~23 ~19 ~7 ~35 ~19 stonebrick 3  
fill ~7 ~23 ~28 ~7 ~35 ~28 stonebrick 3 
setblock ~8 ~20 ~18 stone_brick_stairs 6 
setblock ~8 ~20 ~29 stone_brick_stairs 7  
fill ~9 ~23 ~19 ~9 ~35 ~19 stonebrick 3  
fill ~9 ~23 ~28 ~9 ~35 ~28 stonebrick 3 
setblock ~10 ~20 ~18 stone_brick_stairs 6 
setblock ~10 ~20 ~29 stone_brick_stairs 7  
fill ~11 ~23 ~19 ~11 ~35 ~19 stonebrick 3  
fill ~11 ~23 ~28 ~11 ~35 ~28 stonebrick 3 
setblock ~12 ~20 ~18 stone_brick_stairs 6 
setblock ~12 ~20 ~29 stone_brick_stairs 7  
fill ~13 ~23 ~19 ~13 ~35 ~19 stonebrick 3  
fill ~13 ~23 ~28 ~13 ~35 ~28 stonebrick 3 
setblock ~14 ~20 ~18 stone_brick_stairs 6 
setblock ~14 ~20 ~29 stone_brick_stairs 7  
fill ~15 ~23 ~19 ~16 ~23 ~19 stonebrick 3  
fill ~15 ~23 ~28 ~16 ~23 ~28 stonebrick 3  
fill ~16 ~23 ~18 ~17 ~23 ~18 stonebrick 3  
fill ~16 ~23 ~29 ~17 ~23 ~29 stonebrick 3  
fill ~17 ~23 ~17 ~18 ~23 ~17 stonebrick 3  
fill ~17 ~23 ~30 ~18 ~23 ~30 stonebrick 3  
fill ~18 ~23 ~16 ~19 ~23 ~16 stonebrick 3  
fill ~18 ~23 ~31 ~19 ~23 ~31 stonebrick 3 
setblock ~19 ~20 ~5 stone_brick_stairs 4 
setblock ~19 ~20 ~7 stone_brick_stairs 4 
setblock ~19 ~20 ~9 stone_brick_stairs 4 
setblock ~19 ~20 ~11 stone_brick_stairs 4 
setblock ~19 ~20 ~13 stone_brick_stairs 4  
fill ~19 ~23 ~15 ~20 ~23 ~15 stonebrick 3  
fill ~19 ~23 ~32 ~20 ~23 ~32 stonebrick 3 
setblock ~19 ~20 ~34 stone_brick_stairs 4 
setblock ~19 ~20 ~36 stone_brick_stairs 4 
setblock ~19 ~20 ~38 stone_brick_stairs 4 
setblock ~19 ~20 ~40 stone_brick_stairs 4 
setblock ~19 ~20 ~42 stone_brick_stairs 4  
fill ~20 ~23 ~4 ~20 ~35 ~4 stonebrick 3  
fill ~20 ~23 ~6 ~20 ~35 ~6 stonebrick 3  
fill ~20 ~23 ~8 ~20 ~35 ~8 stonebrick 3  
fill ~20 ~23 ~10 ~20 ~35 ~10 stonebrick 3  
fill ~20 ~23 ~12 ~20 ~35 ~12 stonebrick 3  
fill ~20 ~23 ~14 ~20 ~40 ~14 stonebrick 3  
fill ~20 ~23 ~35 ~20 ~35 ~35 stonebrick 3  
fill ~20 ~23 ~37 ~20 ~35 ~37 stonebrick 3  
fill ~20 ~23 ~39 ~20 ~35 ~39 stonebrick 3  
fill ~20 ~23 ~41 ~20 ~35 ~41 stonebrick 3  
fill ~20 ~23 ~43 ~20 ~35 ~43 stonebrick 3 
setblock ~21 ~20 ~3 stone_brick_stairs 6 
setblock ~21 ~20 ~44 stone_brick_stairs 7  
fill ~22 ~23 ~4 ~22 ~35 ~4 stonebrick 3  
fill ~22 ~23 ~43 ~22 ~35 ~43 stonebrick 3 
setblock ~23 ~20 ~3 stone_brick_stairs 6 
setblock ~23 ~20 ~44 stone_brick_stairs 7  
fill ~24 ~23 ~4 ~25 ~23 ~4 stonebrick 3  
fill ~24 ~23 ~43 ~25 ~23 ~43 stonebrick 3 
setblock ~26 ~20 ~3 stone_brick_stairs 6 
setblock ~26 ~20 ~44 stone_brick_stairs 7  
fill ~27 ~23 ~4 ~27 ~35 ~4 stonebrick 3  
fill ~27 ~23 ~43 ~27 ~35 ~43 stonebrick 3 
setblock ~28 ~20 ~3 stone_brick_stairs 6 
setblock ~28 ~20 ~44 stone_brick_stairs 7  
fill ~29 ~23 ~4 ~29 ~35 ~4 stonebrick 3  
fill ~29 ~23 ~6 ~29 ~35 ~6 stonebrick 3  
fill ~29 ~23 ~8 ~29 ~35 ~8 stonebrick 3  
fill ~29 ~23 ~10 ~29 ~35 ~10 stonebrick 3  
fill ~29 ~23 ~12 ~29 ~35 ~12 stonebrick 3  
fill ~29 ~23 ~14 ~29 ~40 ~14 stonebrick 3  
fill ~29 ~23 ~15 ~29 ~30 ~15 stonebrick 3  
fill ~29 ~23 ~32 ~30 ~23 ~32 stonebrick 3  
fill ~29 ~23 ~35 ~29 ~35 ~35 stonebrick 3  
fill ~29 ~23 ~37 ~29 ~35 ~37 stonebrick 3  
fill ~29 ~23 ~39 ~29 ~35 ~39 stonebrick 3  
fill ~29 ~23 ~41 ~29 ~35 ~41 stonebrick 3  
fill ~29 ~23 ~43 ~29 ~35 ~43 stonebrick 3 
setblock ~30 ~20 ~5 stone_brick_stairs 5 
setblock ~30 ~20 ~7 stone_brick_stairs 5 
setblock ~30 ~20 ~9 stone_brick_stairs 5 
setblock ~30 ~20 ~11 stone_brick_stairs 5 
setblock ~30 ~20 ~13 stone_brick_stairs 5  
fill ~30 ~23 ~16 ~31 ~23 ~16 stonebrick 3  
fill ~30 ~23 ~31 ~31 ~23 ~31 stonebrick 3 
setblock ~30 ~20 ~34 stone_brick_stairs 5 
setblock ~30 ~20 ~36 stone_brick_stairs 5 
setblock ~30 ~20 ~38 stone_brick_stairs 5 
setblock ~30 ~20 ~40 stone_brick_stairs 5 
setblock ~30 ~20 ~42 stone_brick_stairs 5  
fill ~31 ~23 ~17 ~32 ~23 ~17 stonebrick 3  
fill ~31 ~23 ~30 ~32 ~23 ~30 stonebrick 3  
fill ~32 ~23 ~18 ~33 ~23 ~18 stonebrick 3  
fill ~32 ~23 ~29 ~33 ~23 ~29 stonebrick 3  
fill ~33 ~23 ~19 ~34 ~23 ~19 stonebrick 3  
fill ~33 ~23 ~28 ~34 ~23 ~28 stonebrick 3 
setblock ~35 ~20 ~18 stone_brick_stairs 6 
setblock ~35 ~20 ~29 stone_brick_stairs 7  
fill ~36 ~23 ~19 ~36 ~35 ~19 stonebrick 3  
fill ~36 ~23 ~28 ~36 ~35 ~28 stonebrick 3 
setblock ~37 ~20 ~18 stone_brick_stairs 6 
setblock ~37 ~20 ~29 stone_brick_stairs 7  
fill ~38 ~23 ~19 ~38 ~35 ~19 stonebrick 3  
fill ~38 ~23 ~28 ~38 ~35 ~28 stonebrick 3 
setblock ~39 ~20 ~18 stone_brick_stairs 6 
setblock ~39 ~20 ~29 stone_brick_stairs 7  
fill ~40 ~23 ~19 ~40 ~35 ~19 stonebrick 3  
fill ~40 ~23 ~28 ~40 ~35 ~28 stonebrick 3 
setblock ~41 ~20 ~18 stone_brick_stairs 6 
setblock ~41 ~20 ~29 stone_brick_stairs 7  
fill ~42 ~23 ~19 ~42 ~35 ~19 stonebrick 3  
fill ~42 ~23 ~28 ~42 ~35 ~28 stonebrick 3 
setblock ~43 ~20 ~18 stone_brick_stairs 6 
setblock ~43 ~20 ~29 stone_brick_stairs 7  
fill ~44 ~23 ~19 ~44 ~35 ~19 stonebrick 3  
fill ~44 ~23 ~21 ~44 ~35 ~21 stonebrick 3  
fill ~44 ~23 ~23 ~44 ~35 ~23 stonebrick 3  
fill ~44 ~23 ~24 ~44 ~35 ~24 stonebrick 3  
fill ~44 ~23 ~26 ~44 ~35 ~26 stonebrick 3  
fill ~44 ~23 ~28 ~44 ~35 ~28 stonebrick 3 
setblock ~45 ~20 ~20 stone_brick_stairs 5 
setblock ~45 ~20 ~22 stone_brick_stairs 5 
setblock ~45 ~20 ~25 stone_brick_stairs 5 
setblock ~45 ~20 ~27 stone_brick_stairs 5 
setblock ~3 ~21 ~20 stone_brick_stairs 4 
setblock ~3 ~21 ~22 stone_brick_stairs 4 
setblock ~3 ~21 ~25 stone_brick_stairs 4 
setblock ~3 ~21 ~27 stone_brick_stairs 4  
fill ~4 ~24 ~20 ~4 ~32 ~20 stonebrick 3  
fill ~4 ~24 ~22 ~4 ~32 ~22 stonebrick 3  
fill ~4 ~24 ~25 ~4 ~32 ~25 stonebrick 3  
fill ~4 ~24 ~27 ~4 ~32 ~27 stonebrick 3 
setblock ~6 ~21 ~17 stone_brick_stairs 6  
fill ~6 ~24 ~18 ~6 ~32 ~18 stonebrick 3  
fill ~6 ~24 ~29 ~6 ~32 ~29 stonebrick 3 
setblock ~6 ~21 ~30 stone_brick_stairs 7 
setblock ~8 ~21 ~17 stone_brick_stairs 6  
fill ~8 ~24 ~18 ~8 ~32 ~18 stonebrick 3  
fill ~8 ~24 ~29 ~8 ~32 ~29 stonebrick 3 
setblock ~8 ~21 ~30 stone_brick_stairs 7 
setblock ~10 ~21 ~17 stone_brick_stairs 6  
fill ~10 ~24 ~18 ~10 ~32 ~18 stonebrick 3  
fill ~10 ~24 ~29 ~10 ~32 ~29 stonebrick 3 
setblock ~10 ~21 ~30 stone_brick_stairs 7 
setblock ~12 ~21 ~17 stone_brick_stairs 6  
fill ~12 ~24 ~18 ~12 ~32 ~18 stonebrick 3  
fill ~12 ~24 ~29 ~12 ~32 ~29 stonebrick 3 
setblock ~12 ~21 ~30 stone_brick_stairs 7 
setblock ~14 ~21 ~17 stone_brick_stairs 6  
fill ~14 ~24 ~18 ~14 ~32 ~18 stonebrick 3  
fill ~14 ~24 ~29 ~14 ~32 ~29 stonebrick 3 
setblock ~14 ~21 ~30 stone_brick_stairs 7  
fill ~15 ~24 ~19 ~16 ~24 ~19 stonebrick 3  
fill ~15 ~24 ~28 ~16 ~24 ~28 stonebrick 3  
fill ~16 ~24 ~18 ~17 ~24 ~18 stonebrick 3  
fill ~16 ~24 ~29 ~17 ~24 ~29 stonebrick 3  
fill ~17 ~24 ~17 ~18 ~24 ~17 stonebrick 3  
fill ~17 ~24 ~30 ~18 ~24 ~30 stonebrick 3 
setblock ~18 ~21 ~5 stone_brick_stairs 4 
setblock ~18 ~21 ~7 stone_brick_stairs 4 
setblock ~18 ~21 ~9 stone_brick_stairs 4 
setblock ~18 ~21 ~11 stone_brick_stairs 4 
setblock ~18 ~21 ~13 stone_brick_stairs 4  
fill ~18 ~24 ~16 ~19 ~24 ~16 stonebrick 3  
fill ~18 ~24 ~31 ~19 ~24 ~31 stonebrick 3 
setblock ~18 ~21 ~34 stone_brick_stairs 4 
setblock ~18 ~21 ~36 stone_brick_stairs 4 
setblock ~18 ~21 ~38 stone_brick_stairs 4 
setblock ~18 ~21 ~40 stone_brick_stairs 4 
setblock ~18 ~21 ~42 stone_brick_stairs 4  
fill ~19 ~24 ~5 ~19 ~32 ~5 stonebrick 3  
fill ~19 ~24 ~7 ~19 ~32 ~7 stonebrick 3  
fill ~19 ~24 ~9 ~19 ~32 ~9 stonebrick 3  
fill ~19 ~24 ~11 ~19 ~32 ~11 stonebrick 3  
fill ~19 ~24 ~13 ~19 ~32 ~13 stonebrick 3  
fill ~19 ~24 ~15 ~20 ~24 ~15 stonebrick 3  
fill ~19 ~24 ~32 ~20 ~24 ~32 stonebrick 3  
fill ~19 ~24 ~34 ~19 ~32 ~34 stonebrick 3  
fill ~19 ~24 ~36 ~19 ~32 ~36 stonebrick 3  
fill ~19 ~24 ~38 ~19 ~32 ~38 stonebrick 3  
fill ~19 ~24 ~40 ~19 ~32 ~40 stonebrick 3  
fill ~19 ~24 ~42 ~19 ~32 ~42 stonebrick 3 
setblock ~21 ~21 ~2 stone_brick_stairs 6  
fill ~21 ~24 ~3 ~21 ~32 ~3 stonebrick 3  
fill ~21 ~24 ~44 ~21 ~32 ~44 stonebrick 3 
setblock ~21 ~21 ~45 stone_brick_stairs 7 
setblock ~23 ~21 ~2 stone_brick_stairs 6  
fill ~23 ~24 ~3 ~23 ~32 ~3 stonebrick 3  
fill ~23 ~24 ~44 ~23 ~32 ~44 stonebrick 3 
setblock ~23 ~21 ~45 stone_brick_stairs 7  
fill ~24 ~24 ~4 ~25 ~24 ~4 stonebrick 3  
fill ~24 ~24 ~43 ~25 ~24 ~43 stonebrick 3 
setblock ~26 ~21 ~2 stone_brick_stairs 6  
fill ~26 ~24 ~3 ~26 ~32 ~3 stonebrick 3  
fill ~26 ~24 ~44 ~26 ~32 ~44 stonebrick 3 
setblock ~26 ~21 ~45 stone_brick_stairs 7 
setblock ~28 ~21 ~2 stone_brick_stairs 6  
fill ~28 ~24 ~3 ~28 ~32 ~3 stonebrick 3  
fill ~28 ~24 ~44 ~28 ~32 ~44 stonebrick 3 
setblock ~28 ~21 ~45 stone_brick_stairs 7  
fill ~29 ~24 ~32 ~30 ~24 ~32 stonebrick 3  
fill ~30 ~24 ~5 ~30 ~32 ~5 stonebrick 3  
fill ~30 ~24 ~7 ~30 ~32 ~7 stonebrick 3  
fill ~30 ~24 ~9 ~30 ~32 ~9 stonebrick 3  
fill ~30 ~24 ~11 ~30 ~32 ~11 stonebrick 3  
fill ~30 ~24 ~13 ~30 ~32 ~13 stonebrick 3  
fill ~30 ~24 ~16 ~31 ~24 ~16 stonebrick 3  
fill ~30 ~24 ~31 ~31 ~24 ~31 stonebrick 3  
fill ~30 ~24 ~34 ~30 ~32 ~34 stonebrick 3  
fill ~30 ~24 ~36 ~30 ~32 ~36 stonebrick 3  
fill ~30 ~24 ~38 ~30 ~32 ~38 stonebrick 3  
fill ~30 ~24 ~40 ~30 ~32 ~40 stonebrick 3  
fill ~30 ~24 ~42 ~30 ~32 ~42 stonebrick 3 
setblock ~31 ~21 ~5 stone_brick_stairs 5 
setblock ~31 ~21 ~7 stone_brick_stairs 5 
setblock ~31 ~21 ~9 stone_brick_stairs 5 
setblock ~31 ~21 ~11 stone_brick_stairs 5 
setblock ~31 ~21 ~13 stone_brick_stairs 5  
fill ~31 ~24 ~17 ~32 ~24 ~17 stonebrick 3  
fill ~31 ~24 ~30 ~32 ~24 ~30 stonebrick 3 
setblock ~31 ~21 ~34 stone_brick_stairs 5 
setblock ~31 ~21 ~36 stone_brick_stairs 5 
setblock ~31 ~21 ~38 stone_brick_stairs 5 
setblock ~31 ~21 ~40 stone_brick_stairs 5 
setblock ~31 ~21 ~42 stone_brick_stairs 5  
fill ~32 ~24 ~18 ~33 ~24 ~18 stonebrick 3  
fill ~32 ~24 ~29 ~33 ~24 ~29 stonebrick 3  
fill ~33 ~24 ~19 ~34 ~24 ~19 stonebrick 3  
fill ~33 ~24 ~28 ~34 ~24 ~28 stonebrick 3 
setblock ~35 ~21 ~17 stone_brick_stairs 6  
fill ~35 ~24 ~18 ~35 ~32 ~18 stonebrick 3  
fill ~35 ~24 ~29 ~35 ~32 ~29 stonebrick 3 
setblock ~35 ~21 ~30 stone_brick_stairs 7 
setblock ~37 ~21 ~17 stone_brick_stairs 6  
fill ~37 ~24 ~18 ~37 ~32 ~18 stonebrick 3  
fill ~37 ~24 ~29 ~37 ~32 ~29 stonebrick 3 
setblock ~37 ~21 ~30 stone_brick_stairs 7 
setblock ~39 ~21 ~17 stone_brick_stairs 6  
fill ~39 ~24 ~18 ~39 ~32 ~18 stonebrick 3  
fill ~39 ~24 ~29 ~39 ~32 ~29 stonebrick 3 
setblock ~39 ~21 ~30 stone_brick_stairs 7 
setblock ~41 ~21 ~17 stone_brick_stairs 6  
fill ~41 ~24 ~18 ~41 ~32 ~18 stonebrick 3  
fill ~41 ~24 ~29 ~41 ~32 ~29 stonebrick 3 
setblock ~41 ~21 ~30 stone_brick_stairs 7 
setblock ~43 ~21 ~17 stone_brick_stairs 6  
fill ~43 ~24 ~18 ~43 ~32 ~18 stonebrick 3  
fill ~43 ~24 ~29 ~43 ~32 ~29 stonebrick 3 
setblock ~43 ~21 ~30 stone_brick_stairs 7  
fill ~45 ~24 ~20 ~45 ~32 ~20 stonebrick 3  
fill ~45 ~24 ~22 ~45 ~32 ~22 stonebrick 3  
fill ~45 ~24 ~25 ~45 ~32 ~25 stonebrick 3  
fill ~45 ~24 ~27 ~45 ~32 ~27 stonebrick 3 
setblock ~46 ~21 ~20 stone_brick_stairs 5 
setblock ~46 ~21 ~22 stone_brick_stairs 5 
setblock ~46 ~21 ~25 stone_brick_stairs 5 
setblock ~46 ~21 ~27 stone_brick_stairs 5 
setblock ~3 ~22 ~20 stonebrick 3 
setblock ~3 ~22 ~22 stonebrick 3 
setblock ~3 ~22 ~25 stonebrick 3 
setblock ~3 ~22 ~27 stonebrick 3 
setblock ~6 ~22 ~17 stonebrick 3 
setblock ~6 ~22 ~30 stonebrick 3 
setblock ~8 ~22 ~17 stonebrick 3 
setblock ~8 ~22 ~30 stonebrick 3 
setblock ~10 ~22 ~17 stonebrick 3 
setblock ~10 ~22 ~30 stonebrick 3 
setblock ~12 ~22 ~17 stonebrick 3 
setblock ~12 ~22 ~30 stonebrick 3 
setblock ~14 ~22 ~17 stonebrick 3 
setblock ~14 ~22 ~30 stonebrick 3  
fill ~15 ~25 ~19 ~16 ~25 ~19 stonebrick 3  
fill ~15 ~25 ~28 ~16 ~25 ~28 stonebrick 3  
fill ~16 ~25 ~18 ~17 ~25 ~18 stonebrick 3  
fill ~16 ~25 ~29 ~17 ~25 ~29 stonebrick 3  
fill ~17 ~25 ~17 ~18 ~25 ~17 stonebrick 3  
fill ~17 ~25 ~30 ~18 ~25 ~30 stonebrick 3 
setblock ~18 ~22 ~5 stonebrick 3 
setblock ~18 ~22 ~7 stonebrick 3 
setblock ~18 ~22 ~9 stonebrick 3 
setblock ~18 ~22 ~11 stonebrick 3 
setblock ~18 ~22 ~13 stonebrick 3  
fill ~18 ~25 ~16 ~19 ~25 ~16 stonebrick 3  
fill ~18 ~25 ~31 ~19 ~25 ~31 stonebrick 3 
setblock ~18 ~22 ~34 stonebrick 3 
setblock ~18 ~22 ~36 stonebrick 3 
setblock ~18 ~22 ~38 stonebrick 3 
setblock ~18 ~22 ~40 stonebrick 3 
setblock ~18 ~22 ~42 stonebrick 3  
fill ~19 ~25 ~15 ~20 ~25 ~15 stonebrick 3  
fill ~19 ~25 ~32 ~20 ~25 ~32 stonebrick 3 
setblock ~21 ~22 ~2 stonebrick 3 
setblock ~21 ~22 ~45 stonebrick 3 
setblock ~23 ~22 ~2 stonebrick 3 
setblock ~23 ~22 ~45 stonebrick 3  
fill ~24 ~25 ~4 ~25 ~25 ~4 stonebrick 3  
fill ~24 ~25 ~43 ~25 ~25 ~43 stonebrick 3 
setblock ~26 ~22 ~2 stonebrick 3 
setblock ~26 ~22 ~45 stonebrick 3 
setblock ~28 ~22 ~2 stonebrick 3 
setblock ~28 ~22 ~45 stonebrick 3  
fill ~29 ~25 ~32 ~30 ~25 ~32 stonebrick 3  
fill ~30 ~25 ~16 ~31 ~25 ~16 stonebrick 3  
fill ~30 ~25 ~31 ~31 ~25 ~31 stonebrick 3 
setblock ~31 ~22 ~5 stonebrick 3 
setblock ~31 ~22 ~7 stonebrick 3 
setblock ~31 ~22 ~9 stonebrick 3 
setblock ~31 ~22 ~11 stonebrick 3 
setblock ~31 ~22 ~13 stonebrick 3  
fill ~31 ~25 ~17 ~32 ~25 ~17 stonebrick 3  
fill ~31 ~25 ~30 ~32 ~25 ~30 stonebrick 3 
setblock ~31 ~22 ~34 stonebrick 3 
setblock ~31 ~22 ~36 stonebrick 3 
setblock ~31 ~22 ~38 stonebrick 3 
setblock ~31 ~22 ~40 stonebrick 3 
setblock ~31 ~22 ~42 stonebrick 3  
fill ~32 ~25 ~18 ~33 ~25 ~18 stonebrick 3  
fill ~32 ~25 ~29 ~33 ~25 ~29 stonebrick 3  
fill ~33 ~25 ~19 ~34 ~25 ~19 stonebrick 3  
fill ~33 ~25 ~28 ~34 ~25 ~28 stonebrick 3 
setblock ~35 ~22 ~17 stonebrick 3 
setblock ~35 ~22 ~30 stonebrick 3 
setblock ~37 ~22 ~17 stonebrick 3 
setblock ~37 ~22 ~30 stonebrick 3 
setblock ~39 ~22 ~17 stonebrick 3 
setblock ~39 ~22 ~30 stonebrick 3 
setblock ~41 ~22 ~17 stonebrick 3 
setblock ~41 ~22 ~30 stonebrick 3 
setblock ~43 ~22 ~17 stonebrick 3 
setblock ~43 ~22 ~30 stonebrick 3 
setblock ~46 ~22 ~20 stonebrick 3 
setblock ~46 ~22 ~22 stonebrick 3 
setblock ~46 ~22 ~25 stonebrick 3 
setblock ~46 ~22 ~27 stonebrick 3 
setblock ~3 ~23 ~20 stone_brick_stairs 0 
setblock ~3 ~23 ~22 stone_brick_stairs 0 
setblock ~3 ~23 ~25 stone_brick_stairs 0 
setblock ~3 ~23 ~27 stone_brick_stairs 0 
setblock ~6 ~23 ~17 stone_brick_stairs 2 
setblock ~6 ~23 ~30 stone_brick_stairs 3 
setblock ~8 ~23 ~17 stone_brick_stairs 2 
setblock ~8 ~23 ~30 stone_brick_stairs 3 
setblock ~10 ~23 ~17 stone_brick_stairs 2 
setblock ~10 ~23 ~30 stone_brick_stairs 3 
setblock ~12 ~23 ~17 stone_brick_stairs 2 
setblock ~12 ~23 ~30 stone_brick_stairs 3 
setblock ~14 ~23 ~17 stone_brick_stairs 2 
setblock ~14 ~23 ~30 stone_brick_stairs 3  
fill ~15 ~26 ~19 ~16 ~26 ~19 stonebrick 3  
fill ~15 ~26 ~28 ~16 ~26 ~28 stonebrick 3  
fill ~17 ~26 ~18 ~17 ~30 ~18 stonebrick 3  
fill ~17 ~26 ~29 ~17 ~30 ~29 stonebrick 3 
setblock ~18 ~23 ~5 stone_brick_stairs 0 
setblock ~18 ~23 ~7 stone_brick_stairs 0 
setblock ~18 ~23 ~9 stone_brick_stairs 0 
setblock ~18 ~23 ~11 stone_brick_stairs 0 
setblock ~18 ~23 ~13 stone_brick_stairs 0  
fill ~18 ~26 ~17 ~18 ~30 ~17 stonebrick 3  
fill ~18 ~26 ~30 ~18 ~30 ~30 stonebrick 3 
setblock ~18 ~23 ~34 stone_brick_stairs 0 
setblock ~18 ~23 ~36 stone_brick_stairs 0 
setblock ~18 ~23 ~38 stone_brick_stairs 0 
setblock ~18 ~23 ~40 stone_brick_stairs 0 
setblock ~18 ~23 ~42 stone_brick_stairs 0  
fill ~19 ~26 ~16 ~19 ~30 ~16 stonebrick 3  
fill ~19 ~26 ~31 ~19 ~30 ~31 stonebrick 3  
fill ~20 ~26 ~15 ~20 ~30 ~15 stonebrick 3  
fill ~20 ~26 ~32 ~20 ~30 ~32 stonebrick 3 
setblock ~21 ~23 ~2 stone_brick_stairs 2 
setblock ~21 ~23 ~45 stone_brick_stairs 3 
setblock ~23 ~23 ~2 stone_brick_stairs 2 
setblock ~23 ~23 ~45 stone_brick_stairs 3  
fill ~24 ~26 ~4 ~25 ~26 ~4 stonebrick 3  
fill ~24 ~26 ~43 ~25 ~26 ~43 stonebrick 3 
setblock ~26 ~23 ~2 stone_brick_stairs 2 
setblock ~26 ~23 ~45 stone_brick_stairs 3 
setblock ~28 ~23 ~2 stone_brick_stairs 2 
setblock ~28 ~23 ~45 stone_brick_stairs 3  
fill ~29 ~26 ~32 ~29 ~30 ~32 stonebrick 3  
fill ~30 ~26 ~16 ~30 ~30 ~16 stonebrick 3  
fill ~30 ~26 ~31 ~30 ~30 ~31 stonebrick 3 
setblock ~31 ~23 ~5 stone_brick_stairs 1 
setblock ~31 ~23 ~7 stone_brick_stairs 1 
setblock ~31 ~23 ~9 stone_brick_stairs 1 
setblock ~31 ~23 ~11 stone_brick_stairs 1 
setblock ~31 ~23 ~13 stone_brick_stairs 1  
fill ~31 ~26 ~17 ~31 ~30 ~17 stonebrick 3  
fill ~31 ~26 ~30 ~31 ~30 ~30 stonebrick 3 
setblock ~31 ~23 ~34 stone_brick_stairs 1 
setblock ~31 ~23 ~36 stone_brick_stairs 1 
setblock ~31 ~23 ~38 stone_brick_stairs 1 
setblock ~31 ~23 ~40 stone_brick_stairs 1 
setblock ~31 ~23 ~42 stone_brick_stairs 1  
fill ~32 ~26 ~18 ~32 ~30 ~18 stonebrick 3  
fill ~32 ~26 ~29 ~32 ~30 ~29 stonebrick 3  
fill ~33 ~26 ~19 ~34 ~26 ~19 stonebrick 3  
fill ~33 ~26 ~28 ~34 ~26 ~28 stonebrick 3 
setblock ~35 ~23 ~17 stone_brick_stairs 2 
setblock ~35 ~23 ~30 stone_brick_stairs 3 
setblock ~37 ~23 ~17 stone_brick_stairs 2 
setblock ~37 ~23 ~30 stone_brick_stairs 3 
setblock ~39 ~23 ~17 stone_brick_stairs 2 
setblock ~39 ~23 ~30 stone_brick_stairs 3 
setblock ~41 ~23 ~17 stone_brick_stairs 2 
setblock ~41 ~23 ~30 stone_brick_stairs 3 
setblock ~43 ~23 ~17 stone_brick_stairs 2 
setblock ~43 ~23 ~30 stone_brick_stairs 3 
setblock ~46 ~23 ~20 stone_brick_stairs 1 
setblock ~46 ~23 ~22 stone_brick_stairs 1 
setblock ~46 ~23 ~25 stone_brick_stairs 1 
setblock ~46 ~23 ~27 stone_brick_stairs 1  
fill ~15 ~27 ~19 ~16 ~27 ~19 stonebrick 3  
fill ~15 ~27 ~28 ~16 ~27 ~28 stonebrick 3  
fill ~24 ~27 ~4 ~25 ~27 ~4 stonebrick 3  
fill ~24 ~27 ~43 ~25 ~27 ~43 stonebrick 3  
fill ~33 ~27 ~19 ~34 ~27 ~19 stonebrick 3  
fill ~33 ~27 ~28 ~34 ~27 ~28 stonebrick 3 
setblock ~3 ~25 ~20 stone_brick_stairs 4 
setblock ~3 ~25 ~22 stone_brick_stairs 4 
setblock ~3 ~25 ~25 stone_brick_stairs 4 
setblock ~3 ~25 ~27 stone_brick_stairs 4 
setblock ~6 ~25 ~17 stone_brick_stairs 6 
setblock ~6 ~25 ~30 stone_brick_stairs 7 
setblock ~8 ~25 ~17 stone_brick_stairs 6 
setblock ~8 ~25 ~30 stone_brick_stairs 7 
setblock ~10 ~25 ~17 stone_brick_stairs 6 
setblock ~10 ~25 ~30 stone_brick_stairs 7 
setblock ~12 ~25 ~17 stone_brick_stairs 6 
setblock ~12 ~25 ~30 stone_brick_stairs 7 
setblock ~14 ~25 ~17 stone_brick_stairs 6 
setblock ~14 ~25 ~30 stone_brick_stairs 7  
fill ~15 ~28 ~19 ~16 ~28 ~19 stonebrick 3  
fill ~15 ~28 ~28 ~16 ~28 ~28 stonebrick 3 
setblock ~18 ~25 ~5 stone_brick_stairs 4 
setblock ~18 ~25 ~7 stone_brick_stairs 4 
setblock ~18 ~25 ~9 stone_brick_stairs 4 
setblock ~18 ~25 ~11 stone_brick_stairs 4 
setblock ~18 ~25 ~13 stone_brick_stairs 4 
setblock ~18 ~25 ~34 stone_brick_stairs 4 
setblock ~18 ~25 ~36 stone_brick_stairs 4 
setblock ~18 ~25 ~38 stone_brick_stairs 4 
setblock ~18 ~25 ~40 stone_brick_stairs 4 
setblock ~18 ~25 ~42 stone_brick_stairs 4 
setblock ~21 ~25 ~2 stone_brick_stairs 6 
setblock ~21 ~25 ~45 stone_brick_stairs 7 
setblock ~23 ~25 ~2 stone_brick_stairs 6 
setblock ~23 ~25 ~45 stone_brick_stairs 7  
fill ~24 ~28 ~4 ~25 ~28 ~4 stonebrick 3  
fill ~24 ~28 ~43 ~25 ~28 ~43 stonebrick 3 
setblock ~26 ~25 ~2 stone_brick_stairs 6 
setblock ~26 ~25 ~45 stone_brick_stairs 7 
setblock ~28 ~25 ~2 stone_brick_stairs 6 
setblock ~28 ~25 ~45 stone_brick_stairs 7 
setblock ~31 ~25 ~5 stone_brick_stairs 5 
setblock ~31 ~25 ~7 stone_brick_stairs 5 
setblock ~31 ~25 ~9 stone_brick_stairs 5 
setblock ~31 ~25 ~11 stone_brick_stairs 5 
setblock ~31 ~25 ~13 stone_brick_stairs 5 
setblock ~31 ~25 ~34 stone_brick_stairs 5 
setblock ~31 ~25 ~36 stone_brick_stairs 5 
setblock ~31 ~25 ~38 stone_brick_stairs 5 
setblock ~31 ~25 ~40 stone_brick_stairs 5 
setblock ~31 ~25 ~42 stone_brick_stairs 5  
fill ~33 ~28 ~19 ~34 ~28 ~19 stonebrick 3  
fill ~33 ~28 ~28 ~34 ~28 ~28 stonebrick 3 
setblock ~35 ~25 ~17 stone_brick_stairs 6 
setblock ~35 ~25 ~30 stone_brick_stairs 7 
setblock ~37 ~25 ~17 stone_brick_stairs 6 
setblock ~37 ~25 ~30 stone_brick_stairs 7 
setblock ~39 ~25 ~17 stone_brick_stairs 6 
setblock ~39 ~25 ~30 stone_brick_stairs 7 
setblock ~41 ~25 ~17 stone_brick_stairs 6 
setblock ~41 ~25 ~30 stone_brick_stairs 7 
setblock ~43 ~25 ~17 stone_brick_stairs 6 
setblock ~43 ~25 ~30 stone_brick_stairs 7 
setblock ~46 ~25 ~20 stone_brick_stairs 5 
setblock ~46 ~25 ~22 stone_brick_stairs 5 
setblock ~46 ~25 ~25 stone_brick_stairs 5 
setblock ~46 ~25 ~27 stone_brick_stairs 5  
fill ~3 ~29 ~20 ~3 ~31 ~20 stonebrick 3  
fill ~3 ~29 ~22 ~3 ~31 ~22 stonebrick 3  
fill ~3 ~29 ~25 ~3 ~31 ~25 stonebrick 3  
fill ~3 ~29 ~27 ~3 ~31 ~27 stonebrick 3  
fill ~6 ~29 ~17 ~6 ~31 ~17 stonebrick 3  
fill ~6 ~29 ~30 ~6 ~31 ~30 stonebrick 3  
fill ~8 ~29 ~17 ~8 ~31 ~17 stonebrick 3  
fill ~8 ~29 ~30 ~8 ~31 ~30 stonebrick 3  
fill ~10 ~29 ~17 ~10 ~31 ~17 stonebrick 3  
fill ~10 ~29 ~30 ~10 ~31 ~30 stonebrick 3  
fill ~12 ~29 ~17 ~12 ~31 ~17 stonebrick 3  
fill ~12 ~29 ~30 ~12 ~31 ~30 stonebrick 3  
fill ~14 ~29 ~17 ~14 ~31 ~17 stonebrick 3  
fill ~14 ~29 ~30 ~14 ~31 ~30 stonebrick 3  
fill ~15 ~29 ~19 ~16 ~29 ~19 stonebrick 3  
fill ~15 ~29 ~28 ~16 ~29 ~28 stonebrick 3  
fill ~18 ~29 ~5 ~18 ~31 ~5 stonebrick 3  
fill ~18 ~29 ~7 ~18 ~31 ~7 stonebrick 3  
fill ~18 ~29 ~9 ~18 ~31 ~9 stonebrick 3  
fill ~18 ~29 ~11 ~18 ~31 ~11 stonebrick 3  
fill ~18 ~29 ~13 ~18 ~31 ~13 stonebrick 3  
fill ~18 ~29 ~34 ~18 ~31 ~34 stonebrick 3  
fill ~18 ~29 ~36 ~18 ~31 ~36 stonebrick 3  
fill ~18 ~29 ~38 ~18 ~31 ~38 stonebrick 3  
fill ~18 ~29 ~40 ~18 ~31 ~40 stonebrick 3  
fill ~18 ~29 ~42 ~18 ~31 ~42 stonebrick 3  
fill ~21 ~29 ~2 ~21 ~31 ~2 stonebrick 3  
fill ~21 ~29 ~45 ~21 ~31 ~45 stonebrick 3  
fill ~23 ~29 ~2 ~23 ~31 ~2 stonebrick 3  
fill ~23 ~29 ~45 ~23 ~31 ~45 stonebrick 3  
fill ~24 ~29 ~4 ~25 ~29 ~4 stonebrick 3  
fill ~24 ~29 ~43 ~25 ~29 ~43 stonebrick 3  
fill ~26 ~29 ~2 ~26 ~31 ~2 stonebrick 3  
fill ~26 ~29 ~45 ~26 ~31 ~45 stonebrick 3  
fill ~28 ~29 ~2 ~28 ~31 ~2 stonebrick 3  
fill ~28 ~29 ~45 ~28 ~31 ~45 stonebrick 3  
fill ~31 ~29 ~5 ~31 ~31 ~5 stonebrick 3  
fill ~31 ~29 ~7 ~31 ~31 ~7 stonebrick 3  
fill ~31 ~29 ~9 ~31 ~31 ~9 stonebrick 3  
fill ~31 ~29 ~11 ~31 ~31 ~11 stonebrick 3  
fill ~31 ~29 ~13 ~31 ~31 ~13 stonebrick 3  
fill ~31 ~29 ~34 ~31 ~31 ~34 stonebrick 3  
fill ~31 ~29 ~36 ~31 ~31 ~36 stonebrick 3  
fill ~31 ~29 ~38 ~31 ~31 ~38 stonebrick 3  
fill ~31 ~29 ~40 ~31 ~31 ~40 stonebrick 3  
fill ~31 ~29 ~42 ~31 ~31 ~42 stonebrick 3  
fill ~33 ~29 ~19 ~34 ~29 ~19 stonebrick 3  
fill ~33 ~29 ~28 ~34 ~29 ~28 stonebrick 3  
fill ~35 ~29 ~17 ~35 ~31 ~17 stonebrick 3  
fill ~35 ~29 ~30 ~35 ~31 ~30 stonebrick 3  
fill ~37 ~29 ~17 ~37 ~31 ~17 stonebrick 3  
fill ~37 ~29 ~30 ~37 ~31 ~30 stonebrick 3  
fill ~39 ~29 ~17 ~39 ~31 ~17 stonebrick 3  
fill ~39 ~29 ~30 ~39 ~31 ~30 stonebrick 3  
fill ~41 ~29 ~17 ~41 ~31 ~17 stonebrick 3  
fill ~41 ~29 ~30 ~41 ~31 ~30 stonebrick 3  
fill ~43 ~29 ~17 ~43 ~31 ~17 stonebrick 3  
fill ~43 ~29 ~30 ~43 ~31 ~30 stonebrick 3  
fill ~46 ~29 ~20 ~46 ~31 ~20 stonebrick 3  
fill ~46 ~29 ~22 ~46 ~31 ~22 stonebrick 3  
fill ~46 ~29 ~25 ~46 ~31 ~25 stonebrick 3  
fill ~46 ~29 ~27 ~46 ~31 ~27 stonebrick 3  
fill ~15 ~30 ~19 ~16 ~30 ~19 stonebrick 3  
fill ~15 ~30 ~28 ~16 ~30 ~28 stonebrick 3  
fill ~24 ~30 ~4 ~25 ~30 ~4 stonebrick 3  
fill ~24 ~30 ~43 ~25 ~30 ~43 stonebrick 3  
fill ~33 ~30 ~19 ~34 ~30 ~19 stonebrick 3  
fill ~33 ~30 ~28 ~34 ~30 ~28 stonebrick 3  
fill ~15 ~31 ~19 ~15 ~40 ~19 stonebrick 3  
fill ~15 ~31 ~28 ~15 ~40 ~28 stonebrick 3  
fill ~16 ~31 ~18 ~16 ~35 ~18 stonebrick 3  
fill ~16 ~31 ~29 ~16 ~35 ~29 stonebrick 3  
fill ~17 ~31 ~17 ~17 ~35 ~17 stonebrick 3  
fill ~17 ~31 ~30 ~17 ~35 ~30 stonebrick 3  
fill ~18 ~31 ~16 ~18 ~35 ~16 stonebrick 3  
fill ~18 ~31 ~31 ~18 ~35 ~31 stonebrick 3  
fill ~19 ~31 ~15 ~19 ~35 ~15 stonebrick 3  
fill ~19 ~31 ~32 ~19 ~35 ~32 stonebrick 3  
fill ~24 ~31 ~4 ~25 ~31 ~4 stonebrick 3  
fill ~24 ~31 ~43 ~25 ~31 ~43 stonebrick 3  
fill ~30 ~31 ~15 ~30 ~35 ~15 stonebrick 3  
fill ~30 ~31 ~32 ~30 ~35 ~32 stonebrick 3  
fill ~31 ~31 ~16 ~31 ~35 ~16 stonebrick 3  
fill ~31 ~31 ~31 ~31 ~35 ~31 stonebrick 3  
fill ~32 ~31 ~17 ~32 ~35 ~17 stonebrick 3  
fill ~32 ~31 ~30 ~32 ~35 ~30 stonebrick 3  
fill ~33 ~31 ~18 ~33 ~35 ~18 stonebrick 3  
fill ~33 ~31 ~29 ~33 ~35 ~29 stonebrick 3  
fill ~34 ~31 ~19 ~34 ~40 ~19 stonebrick 3  
fill ~34 ~31 ~28 ~34 ~40 ~28 stonebrick 3 
setblock ~3 ~29 ~20 stone_brick_stairs 0 
setblock ~3 ~29 ~22 stone_brick_stairs 0 
setblock ~3 ~29 ~25 stone_brick_stairs 0 
setblock ~3 ~29 ~27 stone_brick_stairs 0 
setblock ~6 ~29 ~17 stone_brick_stairs 2 
setblock ~6 ~29 ~30 stone_brick_stairs 3 
setblock ~8 ~29 ~17 stone_brick_stairs 2 
setblock ~8 ~29 ~30 stone_brick_stairs 3 
setblock ~10 ~29 ~17 stone_brick_stairs 2 
setblock ~10 ~29 ~30 stone_brick_stairs 3 
setblock ~12 ~29 ~17 stone_brick_stairs 2 
setblock ~12 ~29 ~30 stone_brick_stairs 3 
setblock ~14 ~29 ~17 stone_brick_stairs 2 
setblock ~14 ~29 ~30 stone_brick_stairs 3 
setblock ~18 ~29 ~5 stone_brick_stairs 0 
setblock ~18 ~29 ~7 stone_brick_stairs 0 
setblock ~18 ~29 ~9 stone_brick_stairs 0 
setblock ~18 ~29 ~11 stone_brick_stairs 0 
setblock ~18 ~29 ~13 stone_brick_stairs 0 
setblock ~18 ~29 ~34 stone_brick_stairs 0 
setblock ~18 ~29 ~36 stone_brick_stairs 0 
setblock ~18 ~29 ~38 stone_brick_stairs 0 
setblock ~18 ~29 ~40 stone_brick_stairs 0 
setblock ~18 ~29 ~42 stone_brick_stairs 0 
setblock ~21 ~29 ~2 stone_brick_stairs 2 
setblock ~21 ~29 ~45 stone_brick_stairs 3 
setblock ~23 ~29 ~2 stone_brick_stairs 2 
setblock ~23 ~29 ~45 stone_brick_stairs 3  
fill ~24 ~32 ~4 ~25 ~32 ~4 stonebrick 3  
fill ~24 ~32 ~43 ~25 ~32 ~43 stonebrick 3 
setblock ~26 ~29 ~2 stone_brick_stairs 2 
setblock ~26 ~29 ~45 stone_brick_stairs 3 
setblock ~28 ~29 ~2 stone_brick_stairs 2 
setblock ~28 ~29 ~45 stone_brick_stairs 3 
setblock ~31 ~29 ~5 stone_brick_stairs 1 
setblock ~31 ~29 ~7 stone_brick_stairs 1 
setblock ~31 ~29 ~9 stone_brick_stairs 1 
setblock ~31 ~29 ~11 stone_brick_stairs 1 
setblock ~31 ~29 ~13 stone_brick_stairs 1 
setblock ~31 ~29 ~34 stone_brick_stairs 1 
setblock ~31 ~29 ~36 stone_brick_stairs 1 
setblock ~31 ~29 ~38 stone_brick_stairs 1 
setblock ~31 ~29 ~40 stone_brick_stairs 1 
setblock ~31 ~29 ~42 stone_brick_stairs 1 
setblock ~35 ~29 ~17 stone_brick_stairs 2 
setblock ~35 ~29 ~30 stone_brick_stairs 3 
setblock ~37 ~29 ~17 stone_brick_stairs 2 
setblock ~37 ~29 ~30 stone_brick_stairs 3 
setblock ~39 ~29 ~17 stone_brick_stairs 2 
setblock ~39 ~29 ~30 stone_brick_stairs 3 
setblock ~41 ~29 ~17 stone_brick_stairs 2 
setblock ~41 ~29 ~30 stone_brick_stairs 3 
setblock ~43 ~29 ~17 stone_brick_stairs 2 
setblock ~43 ~29 ~30 stone_brick_stairs 3 
setblock ~46 ~29 ~20 stone_brick_stairs 1 
setblock ~46 ~29 ~22 stone_brick_stairs 1 
setblock ~46 ~29 ~25 stone_brick_stairs 1 
setblock ~46 ~29 ~27 stone_brick_stairs 1 
setblock ~4 ~30 ~20 stone_brick_stairs 0 
setblock ~4 ~30 ~22 stone_brick_stairs 0 
setblock ~4 ~30 ~25 stone_brick_stairs 0 
setblock ~4 ~30 ~27 stone_brick_stairs 0 
setblock ~6 ~30 ~18 stone_brick_stairs 2 
setblock ~6 ~30 ~29 stone_brick_stairs 3 
setblock ~8 ~30 ~18 stone_brick_stairs 2 
setblock ~8 ~30 ~29 stone_brick_stairs 3 
setblock ~10 ~30 ~18 stone_brick_stairs 2 
setblock ~10 ~30 ~29 stone_brick_stairs 3 
setblock ~12 ~30 ~18 stone_brick_stairs 2 
setblock ~12 ~30 ~29 stone_brick_stairs 3 
setblock ~14 ~30 ~18 stone_brick_stairs 2 
setblock ~14 ~30 ~29 stone_brick_stairs 3 
setblock ~19 ~30 ~5 stone_brick_stairs 0 
setblock ~19 ~30 ~7 stone_brick_stairs 0 
setblock ~19 ~30 ~9 stone_brick_stairs 0 
setblock ~19 ~30 ~11 stone_brick_stairs 0 
setblock ~19 ~30 ~13 stone_brick_stairs 0 
setblock ~19 ~30 ~34 stone_brick_stairs 0 
setblock ~19 ~30 ~36 stone_brick_stairs 0 
setblock ~19 ~30 ~38 stone_brick_stairs 0 
setblock ~19 ~30 ~40 stone_brick_stairs 0 
setblock ~19 ~30 ~42 stone_brick_stairs 0 
setblock ~21 ~30 ~3 stone_brick_stairs 2 
setblock ~21 ~30 ~44 stone_brick_stairs 3 
setblock ~23 ~30 ~3 stone_brick_stairs 2 
setblock ~23 ~30 ~44 stone_brick_stairs 3  
fill ~24 ~33 ~4 ~25 ~33 ~4 stonebrick 3  
fill ~24 ~33 ~43 ~25 ~33 ~43 stonebrick 3 
setblock ~26 ~30 ~3 stone_brick_stairs 2 
setblock ~26 ~30 ~44 stone_brick_stairs 3 
setblock ~28 ~30 ~3 stone_brick_stairs 2 
setblock ~28 ~30 ~44 stone_brick_stairs 3 
setblock ~30 ~30 ~5 stone_brick_stairs 1 
setblock ~30 ~30 ~7 stone_brick_stairs 1 
setblock ~30 ~30 ~9 stone_brick_stairs 1 
setblock ~30 ~30 ~11 stone_brick_stairs 1 
setblock ~30 ~30 ~13 stone_brick_stairs 1 
setblock ~30 ~30 ~34 stone_brick_stairs 1 
setblock ~30 ~30 ~36 stone_brick_stairs 1 
setblock ~30 ~30 ~38 stone_brick_stairs 1 
setblock ~30 ~30 ~40 stone_brick_stairs 1 
setblock ~30 ~30 ~42 stone_brick_stairs 1 
setblock ~35 ~30 ~18 stone_brick_stairs 2 
setblock ~35 ~30 ~29 stone_brick_stairs 3 
setblock ~37 ~30 ~18 stone_brick_stairs 2 
setblock ~37 ~30 ~29 stone_brick_stairs 3 
setblock ~39 ~30 ~18 stone_brick_stairs 2 
setblock ~39 ~30 ~29 stone_brick_stairs 3 
setblock ~41 ~30 ~18 stone_brick_stairs 2 
setblock ~41 ~30 ~29 stone_brick_stairs 3 
setblock ~43 ~30 ~18 stone_brick_stairs 2 
setblock ~43 ~30 ~29 stone_brick_stairs 3 
setblock ~45 ~30 ~20 stone_brick_stairs 1 
setblock ~45 ~30 ~22 stone_brick_stairs 1 
setblock ~45 ~30 ~25 stone_brick_stairs 1 
setblock ~45 ~30 ~27 stone_brick_stairs 1 
setblock ~4 ~31 ~20 stone_brick_stairs 4 
setblock ~4 ~31 ~22 stone_brick_stairs 4 
setblock ~4 ~31 ~25 stone_brick_stairs 4 
setblock ~4 ~31 ~27 stone_brick_stairs 4 
setblock ~6 ~31 ~18 stone_brick_stairs 6 
setblock ~6 ~31 ~29 stone_brick_stairs 7 
setblock ~8 ~31 ~18 stone_brick_stairs 6 
setblock ~8 ~31 ~29 stone_brick_stairs 7 
setblock ~10 ~31 ~18 stone_brick_stairs 6 
setblock ~10 ~31 ~29 stone_brick_stairs 7 
setblock ~12 ~31 ~18 stone_brick_stairs 6 
setblock ~12 ~31 ~29 stone_brick_stairs 7 
setblock ~14 ~31 ~18 stone_brick_stairs 6 
setblock ~14 ~31 ~29 stone_brick_stairs 7 
setblock ~19 ~31 ~5 stone_brick_stairs 4 
setblock ~19 ~31 ~7 stone_brick_stairs 4 
setblock ~19 ~31 ~9 stone_brick_stairs 4 
setblock ~19 ~31 ~11 stone_brick_stairs 4 
setblock ~19 ~31 ~13 stone_brick_stairs 4 
setblock ~19 ~31 ~34 stone_brick_stairs 4 
setblock ~19 ~31 ~36 stone_brick_stairs 4 
setblock ~19 ~31 ~38 stone_brick_stairs 4 
setblock ~19 ~31 ~40 stone_brick_stairs 4 
setblock ~19 ~31 ~42 stone_brick_stairs 4 
setblock ~21 ~31 ~3 stone_brick_stairs 6 
setblock ~21 ~31 ~44 stone_brick_stairs 7 
setblock ~23 ~31 ~3 stone_brick_stairs 6 
setblock ~23 ~31 ~44 stone_brick_stairs 7  
fill ~24 ~34 ~4 ~25 ~34 ~4 stonebrick 3  
fill ~24 ~34 ~43 ~25 ~34 ~43 stonebrick 3 
setblock ~26 ~31 ~3 stone_brick_stairs 6 
setblock ~26 ~31 ~44 stone_brick_stairs 7 
setblock ~28 ~31 ~3 stone_brick_stairs 6 
setblock ~28 ~31 ~44 stone_brick_stairs 7 
setblock ~30 ~31 ~5 stone_brick_stairs 5 
setblock ~30 ~31 ~7 stone_brick_stairs 5 
setblock ~30 ~31 ~9 stone_brick_stairs 5 
setblock ~30 ~31 ~11 stone_brick_stairs 5 
setblock ~30 ~31 ~13 stone_brick_stairs 5 
setblock ~30 ~31 ~34 stone_brick_stairs 5 
setblock ~30 ~31 ~36 stone_brick_stairs 5 
setblock ~30 ~31 ~38 stone_brick_stairs 5 
setblock ~30 ~31 ~40 stone_brick_stairs 5 
setblock ~30 ~31 ~42 stone_brick_stairs 5 
setblock ~35 ~31 ~18 stone_brick_stairs 6 
setblock ~35 ~31 ~29 stone_brick_stairs 7 
setblock ~37 ~31 ~18 stone_brick_stairs 6 
setblock ~37 ~31 ~29 stone_brick_stairs 7 
setblock ~39 ~31 ~18 stone_brick_stairs 6 
setblock ~39 ~31 ~29 stone_brick_stairs 7 
setblock ~41 ~31 ~18 stone_brick_stairs 6 
setblock ~41 ~31 ~29 stone_brick_stairs 7 
setblock ~43 ~31 ~18 stone_brick_stairs 6 
setblock ~43 ~31 ~29 stone_brick_stairs 7 
setblock ~45 ~31 ~20 stone_brick_stairs 5 
setblock ~45 ~31 ~22 stone_brick_stairs 5 
setblock ~45 ~31 ~25 stone_brick_stairs 5 
setblock ~45 ~31 ~27 stone_brick_stairs 5  
fill ~4 ~35 ~19 ~4 ~35 ~28 stonebrick 3  
fill ~5 ~35 ~18 ~17 ~35 ~18 stonebrick 3 
setblock ~5 ~32 ~20 stonebrick 3 
setblock ~5 ~32 ~22 stonebrick 3 
setblock ~5 ~32 ~25 stonebrick 3 
setblock ~5 ~32 ~27 stonebrick 3  
fill ~5 ~35 ~29 ~17 ~35 ~29 stonebrick 3 
setblock ~6 ~32 ~19 stonebrick 3 
setblock ~6 ~32 ~28 stonebrick 3 
setblock ~8 ~32 ~19 stonebrick 3 
setblock ~8 ~32 ~28 stonebrick 3 
setblock ~10 ~32 ~19 stonebrick 3 
setblock ~10 ~32 ~28 stonebrick 3 
setblock ~12 ~32 ~19 stonebrick 3 
setblock ~12 ~32 ~28 stonebrick 3 
setblock ~14 ~32 ~19 stonebrick 3 
setblock ~14 ~32 ~28 stonebrick 3  
fill ~15 ~35 ~16 ~19 ~35 ~16 stonebrick 3  
fill ~15 ~35 ~17 ~18 ~35 ~17 stonebrick 3  
fill ~15 ~35 ~30 ~18 ~35 ~30 stonebrick 3  
fill ~15 ~35 ~31 ~19 ~35 ~31 stonebrick 3  
fill ~16 ~35 ~15 ~20 ~35 ~15 stonebrick 3  
fill ~16 ~35 ~19 ~16 ~40 ~19 stonebrick 3  
fill ~16 ~35 ~28 ~16 ~40 ~28 stonebrick 3  
fill ~16 ~35 ~32 ~20 ~35 ~32 stonebrick 3  
fill ~17 ~35 ~14 ~20 ~35 ~14 stonebrick 3  
fill ~17 ~35 ~33 ~20 ~35 ~33 stonebrick 3  
fill ~19 ~35 ~4 ~19 ~35 ~16 stonebrick 3  
fill ~19 ~35 ~34 ~20 ~35 ~34 stonebrick 3  
fill ~19 ~35 ~35 ~19 ~35 ~43 stonebrick 3  
fill ~20 ~35 ~3 ~29 ~35 ~3 stonebrick 3 
setblock ~20 ~32 ~5 stonebrick 3 
setblock ~20 ~32 ~7 stonebrick 3 
setblock ~20 ~32 ~9 stonebrick 3 
setblock ~20 ~32 ~11 stonebrick 3 
setblock ~20 ~32 ~13 stonebrick 3 
setblock ~20 ~32 ~36 stonebrick 3 
setblock ~20 ~32 ~38 stonebrick 3 
setblock ~20 ~32 ~40 stonebrick 3 
setblock ~20 ~32 ~42 stonebrick 3  
fill ~20 ~35 ~44 ~29 ~35 ~44 stonebrick 3 
setblock ~21 ~32 ~4 stonebrick 3 
setblock ~21 ~32 ~43 stonebrick 3  
fill ~23 ~35 ~4 ~30 ~35 ~4 stonebrick 3  
fill ~23 ~35 ~43 ~30 ~35 ~43 stonebrick 3  
fill ~29 ~35 ~5 ~30 ~35 ~5 stonebrick 3  
fill ~29 ~35 ~7 ~30 ~35 ~7 stonebrick 3  
fill ~29 ~35 ~9 ~30 ~35 ~9 stonebrick 3  
fill ~29 ~35 ~11 ~30 ~35 ~11 stonebrick 3  
fill ~29 ~35 ~13 ~30 ~35 ~13 stonebrick 3  
fill ~29 ~35 ~15 ~29 ~40 ~15 stonebrick 3  
fill ~29 ~35 ~32 ~29 ~40 ~32 stonebrick 3  
fill ~29 ~35 ~34 ~30 ~35 ~34 stonebrick 3  
fill ~29 ~35 ~36 ~30 ~35 ~36 stonebrick 3  
fill ~29 ~35 ~38 ~30 ~35 ~38 stonebrick 3  
fill ~29 ~35 ~40 ~30 ~35 ~40 stonebrick 3  
fill ~29 ~35 ~42 ~30 ~35 ~42 stonebrick 3 
setblock ~30 ~32 ~6 stonebrick 3 
setblock ~30 ~32 ~8 stonebrick 3 
setblock ~30 ~32 ~10 stonebrick 3 
setblock ~30 ~32 ~12 stonebrick 3  
fill ~30 ~35 ~14 ~32 ~35 ~14 stonebrick 3 
setblock ~30 ~32 ~16 stonebrick 3 
setblock ~30 ~32 ~31 stonebrick 3  
fill ~30 ~35 ~33 ~32 ~35 ~33 stonebrick 3 
setblock ~30 ~32 ~35 stonebrick 3 
setblock ~30 ~32 ~37 stonebrick 3 
setblock ~30 ~32 ~39 stonebrick 3 
setblock ~30 ~32 ~41 stonebrick 3  
fill ~31 ~35 ~15 ~33 ~35 ~15 stonebrick 3 
setblock ~31 ~32 ~17 stonebrick 3 
setblock ~31 ~32 ~30 stonebrick 3  
fill ~31 ~35 ~32 ~33 ~35 ~32 stonebrick 3  
fill ~32 ~35 ~16 ~34 ~35 ~16 stonebrick 3 
setblock ~32 ~32 ~18 stonebrick 3 
setblock ~32 ~32 ~29 stonebrick 3  
fill ~32 ~35 ~31 ~34 ~35 ~31 stonebrick 3  
fill ~33 ~35 ~17 ~34 ~35 ~17 stonebrick 3  
fill ~33 ~35 ~19 ~33 ~40 ~19 stonebrick 3  
fill ~33 ~35 ~28 ~33 ~40 ~28 stonebrick 3  
fill ~33 ~35 ~30 ~34 ~35 ~30 stonebrick 3  
fill ~34 ~35 ~18 ~44 ~35 ~18 stonebrick 3  
fill ~34 ~35 ~29 ~44 ~35 ~29 stonebrick 3 
setblock ~35 ~32 ~19 stonebrick 3 
setblock ~35 ~32 ~28 stonebrick 3 
setblock ~37 ~32 ~19 stonebrick 3 
setblock ~37 ~32 ~28 stonebrick 3 
setblock ~39 ~32 ~19 stonebrick 3 
setblock ~39 ~32 ~28 stonebrick 3 
setblock ~41 ~32 ~19 stonebrick 3 
setblock ~41 ~32 ~28 stonebrick 3 
setblock ~43 ~32 ~19 stonebrick 3 
setblock ~43 ~32 ~28 stonebrick 3  
fill ~44 ~35 ~20 ~45 ~35 ~20 stonebrick 3  
fill ~44 ~35 ~22 ~45 ~35 ~22 stonebrick 3  
fill ~44 ~35 ~25 ~45 ~35 ~25 stonebrick 3  
fill ~44 ~35 ~27 ~45 ~35 ~27 stonebrick 3 
setblock ~45 ~32 ~19 stonebrick 3 
setblock ~45 ~32 ~21 stonebrick 3  
fill ~45 ~35 ~23 ~45 ~35 ~28 stonebrick 3  
fill ~5 ~36 ~19 ~5 ~39 ~19 stonebrick 0  
fill ~5 ~36 ~22 ~5 ~39 ~22 stonebrick 0  
fill ~5 ~36 ~25 ~5 ~39 ~25 stonebrick 0  
fill ~5 ~36 ~28 ~5 ~39 ~28 stonebrick 0  
fill ~8 ~36 ~19 ~8 ~39 ~19 stonebrick 0  
fill ~8 ~36 ~28 ~8 ~39 ~28 stonebrick 0  
fill ~11 ~36 ~19 ~11 ~39 ~19 stonebrick 0  
fill ~11 ~36 ~28 ~11 ~39 ~28 stonebrick 0  
fill ~14 ~36 ~19 ~14 ~39 ~19 stonebrick 0  
fill ~14 ~36 ~28 ~14 ~39 ~28 stonebrick 0  
fill ~15 ~36 ~16 ~16 ~36 ~16 iron_bars 0  
fill ~15 ~36 ~17 ~15 ~36 ~16 iron_bars 0  
fill ~15 ~36 ~18 ~15 ~40 ~18 stonebrick 3  
fill ~15 ~36 ~29 ~15 ~40 ~29 stonebrick 3  
fill ~15 ~36 ~30 ~15 ~36 ~31 iron_bars 0  
fill ~16 ~36 ~15 ~17 ~36 ~15 iron_bars 0  
fill ~16 ~36 ~31 ~16 ~36 ~32 iron_bars 0  
fill ~17 ~36 ~14 ~18 ~36 ~14 iron_bars 0  
fill ~17 ~36 ~19 ~17 ~39 ~19 stonebrick 3  
fill ~17 ~36 ~28 ~17 ~39 ~28 stonebrick 3  
fill ~17 ~36 ~32 ~17 ~36 ~33 iron_bars 0 
setblock ~18 ~33 ~33 iron_bars 0  
fill ~19 ~36 ~14 ~19 ~40 ~14 stonebrick 3  
fill ~19 ~36 ~33 ~19 ~40 ~33 stonebrick 3  
fill ~20 ~36 ~4 ~20 ~39 ~4 stonebrick 0  
fill ~20 ~36 ~7 ~20 ~39 ~7 stonebrick 0  
fill ~20 ~36 ~10 ~20 ~39 ~10 stonebrick 0  
fill ~20 ~36 ~13 ~20 ~39 ~13 stonebrick 0  
fill ~20 ~36 ~15 ~20 ~40 ~15 stonebrick 3  
fill ~20 ~36 ~16 ~20 ~39 ~16 stonebrick 3  
fill ~20 ~36 ~31 ~20 ~39 ~31 stonebrick 3  
fill ~20 ~36 ~32 ~20 ~40 ~32 stonebrick 3  
fill ~20 ~36 ~34 ~20 ~39 ~34 stonebrick 0  
fill ~20 ~36 ~37 ~20 ~39 ~37 stonebrick 0  
fill ~20 ~36 ~40 ~20 ~39 ~40 stonebrick 0  
fill ~20 ~36 ~43 ~20 ~39 ~43 stonebrick 0  
fill ~23 ~36 ~4 ~23 ~39 ~4 stonebrick 0  
fill ~23 ~36 ~43 ~23 ~39 ~43 stonebrick 0  
fill ~26 ~36 ~4 ~26 ~39 ~4 stonebrick 0  
fill ~26 ~36 ~43 ~26 ~39 ~43 stonebrick 0  
fill ~29 ~36 ~4 ~29 ~39 ~4 stonebrick 0  
fill ~29 ~36 ~7 ~29 ~39 ~7 stonebrick 0  
fill ~29 ~36 ~10 ~29 ~39 ~10 stonebrick 0  
fill ~29 ~36 ~13 ~29 ~39 ~13 stonebrick 0  
fill ~29 ~36 ~16 ~29 ~39 ~16 stonebrick 3  
fill ~29 ~36 ~31 ~29 ~39 ~31 stonebrick 3  
fill ~29 ~36 ~34 ~29 ~39 ~34 stonebrick 0  
fill ~29 ~36 ~37 ~29 ~39 ~37 stonebrick 0  
fill ~29 ~36 ~40 ~29 ~39 ~40 stonebrick 0  
fill ~29 ~36 ~43 ~29 ~39 ~43 stonebrick 0  
fill ~30 ~36 ~14 ~30 ~40 ~14 stonebrick 3  
fill ~30 ~36 ~33 ~30 ~40 ~33 stonebrick 3  
fill ~31 ~36 ~14 ~32 ~36 ~14 iron_bars 0  
fill ~31 ~36 ~33 ~32 ~36 ~33 iron_bars 0  
fill ~32 ~36 ~15 ~33 ~36 ~15 iron_bars 0  
fill ~32 ~36 ~19 ~32 ~39 ~19 stonebrick 3  
fill ~32 ~36 ~28 ~32 ~39 ~28 stonebrick 3  
fill ~32 ~36 ~32 ~33 ~36 ~32 iron_bars 0  
fill ~33 ~36 ~16 ~34 ~36 ~16 iron_bars 0  
fill ~33 ~36 ~31 ~34 ~36 ~31 iron_bars 0 
setblock ~34 ~33 ~17 iron_bars 0  
fill ~34 ~36 ~18 ~34 ~40 ~18 stonebrick 3  
fill ~34 ~36 ~29 ~34 ~40 ~29 stonebrick 3 
setblock ~34 ~33 ~30 iron_bars 0  
fill ~35 ~36 ~19 ~35 ~39 ~19 stonebrick 0  
fill ~35 ~36 ~28 ~35 ~39 ~28 stonebrick 0  
fill ~38 ~36 ~19 ~38 ~39 ~19 stonebrick 0  
fill ~38 ~36 ~28 ~38 ~39 ~28 stonebrick 0  
fill ~41 ~36 ~19 ~41 ~39 ~19 stonebrick 0  
fill ~41 ~36 ~28 ~41 ~39 ~28 stonebrick 0  
fill ~44 ~36 ~19 ~44 ~39 ~19 stonebrick 0  
fill ~44 ~36 ~22 ~44 ~39 ~22 stonebrick 0  
fill ~44 ~36 ~25 ~44 ~39 ~25 stonebrick 0  
fill ~44 ~36 ~28 ~44 ~39 ~28 stonebrick 0 
setblock ~5 ~36 ~20 stone_brick_stairs 7 
setblock ~5 ~36 ~21 stone_brick_stairs 6 
setblock ~5 ~36 ~23 stone_brick_stairs 7 
setblock ~5 ~36 ~24 stone_brick_stairs 6 
setblock ~5 ~36 ~26 stone_brick_stairs 7 
setblock ~5 ~36 ~27 stone_brick_stairs 6 
setblock ~6 ~36 ~19 stone_brick_stairs 5 
setblock ~6 ~36 ~28 stone_brick_stairs 5 
setblock ~7 ~36 ~19 stone_brick_stairs 4 
setblock ~7 ~36 ~28 stone_brick_stairs 4 
setblock ~9 ~36 ~19 stone_brick_stairs 5 
setblock ~9 ~36 ~28 stone_brick_stairs 5 
setblock ~10 ~36 ~19 stone_brick_stairs 4 
setblock ~10 ~36 ~28 stone_brick_stairs 4 
setblock ~12 ~36 ~19 stone_brick_stairs 5 
setblock ~12 ~36 ~28 stone_brick_stairs 5 
setblock ~13 ~36 ~19 stone_brick_stairs 4 
setblock ~13 ~36 ~28 stone_brick_stairs 4 
setblock ~20 ~36 ~5 stone_brick_stairs 7 
setblock ~20 ~36 ~6 stone_brick_stairs 6 
setblock ~20 ~36 ~8 stone_brick_stairs 7 
setblock ~20 ~36 ~9 stone_brick_stairs 6 
setblock ~20 ~36 ~11 stone_brick_stairs 7 
setblock ~20 ~36 ~12 stone_brick_stairs 6 
setblock ~20 ~36 ~35 stone_brick_stairs 7 
setblock ~20 ~36 ~36 stone_brick_stairs 6 
setblock ~20 ~36 ~38 stone_brick_stairs 7 
setblock ~20 ~36 ~39 stone_brick_stairs 6 
setblock ~20 ~36 ~41 stone_brick_stairs 7 
setblock ~20 ~36 ~42 stone_brick_stairs 6 
setblock ~21 ~36 ~4 stone_brick_stairs 5 
setblock ~21 ~36 ~43 stone_brick_stairs 5 
setblock ~22 ~36 ~4 stone_brick_stairs 4 
setblock ~22 ~36 ~43 stone_brick_stairs 4 
setblock ~24 ~36 ~4 stone_brick_stairs 5 
setblock ~24 ~36 ~43 stone_brick_stairs 5 
setblock ~25 ~36 ~4 stone_brick_stairs 4 
setblock ~25 ~36 ~43 stone_brick_stairs 4 
setblock ~27 ~36 ~4 stone_brick_stairs 5 
setblock ~27 ~36 ~43 stone_brick_stairs 5 
setblock ~28 ~36 ~4 stone_brick_stairs 4 
setblock ~28 ~36 ~43 stone_brick_stairs 4 
setblock ~29 ~36 ~5 stone_brick_stairs 7 
setblock ~29 ~36 ~6 stone_brick_stairs 6 
setblock ~29 ~36 ~8 stone_brick_stairs 7 
setblock ~29 ~36 ~9 stone_brick_stairs 6 
setblock ~29 ~36 ~11 stone_brick_stairs 7 
setblock ~29 ~36 ~12 stone_brick_stairs 6 
setblock ~29 ~36 ~35 stone_brick_stairs 7 
setblock ~29 ~36 ~36 stone_brick_stairs 6 
setblock ~29 ~36 ~38 stone_brick_stairs 7 
setblock ~29 ~36 ~39 stone_brick_stairs 6 
setblock ~29 ~36 ~41 stone_brick_stairs 7 
setblock ~29 ~36 ~42 stone_brick_stairs 6 
setblock ~36 ~36 ~19 stone_brick_stairs 5 
setblock ~36 ~36 ~28 stone_brick_stairs 5 
setblock ~37 ~36 ~19 stone_brick_stairs 4 
setblock ~37 ~36 ~28 stone_brick_stairs 4 
setblock ~39 ~36 ~19 stone_brick_stairs 5 
setblock ~39 ~36 ~28 stone_brick_stairs 5   

KittysCommands:  
setblock ~40 ~36 ~19 stone_brick_stairs 4 
setblock ~40 ~36 ~28 stone_brick_stairs 4 
setblock ~42 ~36 ~19 stone_brick_stairs 5 
setblock ~42 ~36 ~28 stone_brick_stairs 5 
setblock ~43 ~36 ~19 stone_brick_stairs 4 
setblock ~43 ~36 ~28 stone_brick_stairs 4 
setblock ~44 ~36 ~20 stone_brick_stairs 7 
setblock ~44 ~36 ~21 stone_brick_stairs 6 
setblock ~44 ~36 ~23 stone_brick_stairs 7 
setblock ~44 ~36 ~24 stone_brick_stairs 6 
setblock ~44 ~36 ~26 stone_brick_stairs 7 
setblock ~44 ~36 ~27 stone_brick_stairs 6  
fill ~4 ~40 ~19 ~4 ~40 ~28 stone_brick_stairs 0  
fill ~5 ~40 ~18 ~14 ~40 ~18 stone_brick_stairs 2  
fill ~5 ~40 ~19 ~16 ~40 ~19 stonebrick 3  
fill ~5 ~40 ~20 ~5 ~40 ~28 stonebrick 3  
fill ~5 ~40 ~29 ~14 ~40 ~29 stone_brick_stairs 3  
fill ~6 ~40 ~28 ~16 ~40 ~28 stonebrick 3  
fill ~15 ~40 ~16 ~19 ~40 ~16 stonebrick 3  
fill ~15 ~40 ~17 ~18 ~40 ~17 stonebrick 3  
fill ~15 ~40 ~30 ~18 ~40 ~30 stonebrick 3  
fill ~15 ~40 ~31 ~19 ~40 ~31 stonebrick 3  
fill ~16 ~40 ~15 ~20 ~40 ~15 stonebrick 3  
fill ~16 ~40 ~18 ~17 ~40 ~18 stonebrick 3  
fill ~16 ~40 ~29 ~17 ~40 ~29 stonebrick 3  
fill ~16 ~40 ~32 ~20 ~40 ~32 stonebrick 3  
fill ~17 ~40 ~14 ~20 ~40 ~14 stonebrick 3  
fill ~17 ~40 ~33 ~20 ~40 ~33 stonebrick 3  
fill ~19 ~40 ~4 ~19 ~40 ~13 stone_brick_stairs 0  
fill ~19 ~40 ~34 ~19 ~40 ~43 stone_brick_stairs 0  
fill ~20 ~40 ~3 ~29 ~40 ~3 stone_brick_stairs 2  
fill ~20 ~40 ~4 ~29 ~40 ~4 stonebrick 3  
fill ~20 ~40 ~5 ~20 ~40 ~15 stonebrick 3  
fill ~20 ~40 ~34 ~20 ~40 ~43 stonebrick 3  
fill ~20 ~40 ~44 ~29 ~40 ~44 stone_brick_stairs 3  
fill ~21 ~40 ~43 ~29 ~40 ~43 stonebrick 3  
fill ~29 ~40 ~5 ~29 ~40 ~15 stonebrick 3  
fill ~29 ~40 ~34 ~29 ~40 ~43 stonebrick 3  
fill ~30 ~40 ~4 ~30 ~40 ~13 stone_brick_stairs 1  
fill ~30 ~40 ~15 ~33 ~40 ~15 stonebrick 3  
fill ~30 ~40 ~16 ~34 ~40 ~16 stonebrick 3  
fill ~30 ~40 ~31 ~34 ~40 ~31 stonebrick 3  
fill ~30 ~40 ~32 ~33 ~40 ~32 stonebrick 3  
fill ~30 ~40 ~34 ~30 ~40 ~43 stone_brick_stairs 1  
fill ~31 ~40 ~14 ~32 ~40 ~14 stonebrick 3  
fill ~31 ~40 ~17 ~34 ~40 ~17 stonebrick 3  
fill ~31 ~40 ~30 ~34 ~40 ~30 stonebrick 3  
fill ~31 ~40 ~33 ~32 ~40 ~33 stonebrick 3  
fill ~32 ~40 ~18 ~34 ~40 ~18 stonebrick 3  
fill ~32 ~40 ~29 ~34 ~40 ~29 stonebrick 3  
fill ~35 ~40 ~18 ~44 ~40 ~18 stone_brick_stairs 2  
fill ~35 ~40 ~19 ~44 ~40 ~19 stonebrick 3  
fill ~35 ~40 ~28 ~44 ~40 ~28 stonebrick 3  
fill ~35 ~40 ~29 ~44 ~40 ~29 stone_brick_stairs 3  
fill ~44 ~40 ~20 ~44 ~40 ~28 stonebrick 3  
fill ~45 ~40 ~19 ~45 ~40 ~28 stone_brick_stairs 1  
fill ~4 ~41 ~19 ~4 ~41 ~28 stone_brick_stairs 4  
fill ~5 ~41 ~19 ~17 ~41 ~19 stonebrick 0  
fill ~5 ~41 ~20 ~5 ~42 ~20 stonebrick 0  
fill ~5 ~41 ~21 ~5 ~42 ~21 stonebrick 0  
fill ~5 ~41 ~22 ~5 ~42 ~22 stonebrick 0  
fill ~5 ~41 ~23 ~5 ~42 ~23 stonebrick 0  
fill ~5 ~41 ~24 ~5 ~42 ~24 stonebrick 0  
fill ~5 ~41 ~25 ~5 ~42 ~25 stonebrick 0  
fill ~5 ~41 ~26 ~5 ~42 ~26 stonebrick 0  
fill ~5 ~41 ~27 ~5 ~42 ~27 stonebrick 0  
fill ~5 ~41 ~28 ~17 ~41 ~28 stonebrick 0  
fill ~18 ~41 ~18 ~18 ~44 ~18 stonebrick 3  
fill ~18 ~41 ~29 ~18 ~44 ~29 stonebrick 3  
fill ~19 ~41 ~17 ~19 ~44 ~17 stonebrick 3  
fill ~19 ~41 ~30 ~19 ~44 ~30 stonebrick 3  
fill ~20 ~41 ~3 ~29 ~41 ~3 stone_brick_stairs 6  
fill ~20 ~41 ~4 ~29 ~41 ~4 stonebrick 0  
fill ~20 ~41 ~5 ~20 ~42 ~5 stonebrick 0  
fill ~20 ~41 ~6 ~20 ~42 ~6 stonebrick 0  
fill ~20 ~41 ~7 ~20 ~42 ~7 stonebrick 0  
fill ~20 ~41 ~8 ~20 ~42 ~8 stonebrick 0  
fill ~20 ~41 ~9 ~20 ~42 ~9 stonebrick 0  
fill ~20 ~41 ~10 ~20 ~42 ~10 stonebrick 0  
fill ~20 ~41 ~11 ~20 ~42 ~11 stonebrick 0  
fill ~20 ~41 ~12 ~20 ~42 ~12 stonebrick 0  
fill ~20 ~41 ~13 ~20 ~42 ~13 stonebrick 0  
fill ~20 ~41 ~14 ~20 ~42 ~14 stonebrick 0  
fill ~20 ~41 ~15 ~20 ~42 ~15 stonebrick 0  
fill ~20 ~41 ~16 ~20 ~42 ~16 stonebrick 0  
fill ~20 ~41 ~31 ~20 ~42 ~31 stonebrick 0  
fill ~20 ~41 ~32 ~20 ~42 ~32 stonebrick 0  
fill ~20 ~41 ~33 ~20 ~42 ~33 stonebrick 0  
fill ~20 ~41 ~34 ~20 ~42 ~34 stonebrick 0  
fill ~20 ~41 ~35 ~20 ~42 ~35 stonebrick 0  
fill ~20 ~41 ~36 ~20 ~42 ~36 stonebrick 0  
fill ~20 ~41 ~37 ~20 ~42 ~37 stonebrick 0  
fill ~20 ~41 ~38 ~20 ~42 ~38 stonebrick 0  
fill ~20 ~41 ~39 ~20 ~42 ~39 stonebrick 0  
fill ~20 ~41 ~40 ~20 ~42 ~40 stonebrick 0  
fill ~20 ~41 ~41 ~20 ~42 ~41 stonebrick 0  
fill ~20 ~41 ~42 ~20 ~42 ~42 stonebrick 0  
fill ~20 ~41 ~43 ~29 ~41 ~43 stonebrick 0  
fill ~20 ~41 ~44 ~29 ~41 ~44 stone_brick_stairs 7  
fill ~29 ~41 ~5 ~29 ~42 ~5 stonebrick 0  
fill ~29 ~41 ~6 ~29 ~42 ~6 stonebrick 0  
fill ~29 ~41 ~7 ~29 ~42 ~7 stonebrick 0  
fill ~29 ~41 ~8 ~29 ~42 ~8 stonebrick 0  
fill ~29 ~41 ~9 ~29 ~42 ~9 stonebrick 0  
fill ~29 ~41 ~10 ~29 ~42 ~10 stonebrick 0  
fill ~29 ~41 ~11 ~29 ~42 ~11 stonebrick 0  
