fill ~32~52~1 ~33~52~1 minecraft:stained_glass 6
setblock ~32~53~1 minecraft:wool 0
fill ~32~54~1 ~32~54~2 minecraft:stained_glass 6
setblock ~33~54~1 minecraft:wool 6
fill ~34~53~1 ~34~53~2 minecraft:stained_glass 6
fill ~31~51~2 ~31~51~4 minecraft:stained_glass 6
fill ~31~52~2 ~31~53~2 minecraft:stained_hardened_clay 14
setblock ~32~52~2 minecraft:stained_glass 6
fill ~33~51~2 ~33~51~5 minecraft:stained_glass 6
setblock ~33~53~2 minecraft:stained_glass 6
setblock ~33~54~2 minecraft:wool 0
fill ~34~52~2 ~35~52~2 minecraft:stained_glass 6
fill ~34~54~2 ~34~54~3 minecraft:stained_glass 6
fill ~35~51~2 ~35~51~4 minecraft:stained_glass 6
fill ~35~53~2 ~35~53~3 minecraft:wool 6
fill ~38~58~2 ~40~58~2 minecraft:stained_glass 6
setblock ~38~59~2 minecraft:wool 6
fill ~39~55~2 ~41~55~2 minecraft:stained_glass 6
setblock ~39~59~2 minecraft:stained_glass 6
setblock ~41~54~2 minecraft:stained_glass 6
setblock ~45~54~2 minecraft:wool 0
setblock ~45~55~2 minecraft:stained_glass 6
setblock ~46~54~2 minecraft:stained_glass 6
setblock ~46~56~2 minecraft:stained_glass 6
fill ~50~57~2 ~52~57~2 minecraft:stained_glass 6
setblock ~52~55~2 minecraft:stained_hardened_clay 14
setblock ~52~56~2 minecraft:wool 0
fill ~30~56~3 ~30~56~6 minecraft:stained_glass 6
setblock ~31~55~3 minecraft:stained_hardened_clay 14
fill ~31~57~3 ~31~58~4 minecraft:stained_glass 6
setblock ~32~51~3 minecraft:stained_glass 6
setblock ~32~52~3 minecraft:stained_hardened_clay 14
setblock ~32~56~3 minecraft:stained_hardened_clay 14
setblock ~32~59~3 minecraft:stained_hardened_clay 14
fill ~33~50~3 ~33~50~4 minecraft:stained_glass 6
setblock ~33~54~3 minecraft:stained_glass 6
setblock ~33~55~3 minecraft:wool 6
setblock ~34~51~3 minecraft:wool 6
fill ~34~55~3 ~34~56~4 minecraft:stained_glass 6
setblock ~34~58~3 minecraft:stained_hardened_clay 14
fill ~34~59~3 ~36~59~3 minecraft:stained_glass 6
fill ~35~52~3 ~36~52~3 minecraft:stained_glass 6
setblock ~35~54~3 minecraft:stained_hardened_clay 14
setblock ~35~55~3 minecraft:wool 6
setblock ~35~57~3 minecraft:stained_glass 6
setblock ~36~53~3 minecraft:stained_glass 6
fill ~36~58~3 ~36~58~4 minecraft:stained_glass 6
fill ~37~56~3 ~40~56~3 minecraft:stained_glass 6
fill ~37~60~3 ~37~60~4 minecraft:stained_glass 6
fill ~38~53~3 ~38~53~6 minecraft:stained_glass 6
setblock ~38~59~3 minecraft:stained_glass 6
setblock ~38~60~3 minecraft:wool 6
setblock ~39~57~3 minecraft:stained_glass 6
fill ~39~60~3 ~39~61~3 minecraft:stained_glass 6
fill ~40~53~3 ~41~53~3 minecraft:stained_glass 6
fill ~40~55~3 ~41~55~3 minecraft:stained_glass 6
fill ~40~59~3 ~41~59~3 minecraft:stained_glass 6
setblock ~40~60~3 minecraft:wool 0
setblock ~40~61~3 minecraft:stained_glass 6
setblock ~41~52~3 minecraft:stained_glass 6
setblock ~41~57~3 minecraft:wool 0
setblock ~41~58~3 minecraft:stained_hardened_clay 14
setblock ~42~53~3 minecraft:wool 6
setblock ~42~55~3 minecraft:wool 0
fill ~42~56~3 ~42~57~3 minecraft:stained_glass 6
fill ~43~59~3 ~44~59~3 minecraft:stained_glass 6
fill ~44~54~3 ~45~54~3 minecraft:stained_glass 6
setblock ~44~55~3 minecraft:stained_glass 6
fill ~44~58~3 ~44~58~6 minecraft:stained_glass 6
setblock ~45~56~3 minecraft:stained_glass 6
setblock ~46~57~3 minecraft:stained_glass 6
setblock ~46~59~3 minecraft:stained_glass 6
setblock ~47~53~3 minecraft:wool 6
fill ~47~54~3 ~48~54~3 minecraft:stained_glass 6
fill ~47~55~3 ~47~55~5 minecraft:stained_glass 6
fill ~47~56~3 ~49~56~3 minecraft:stained_glass 6
fill ~48~57~3 ~49~57~4 minecraft:stained_glass 6
fill ~48~58~3 ~49~58~3 minecraft:stained_glass 6
setblock ~50~54~3 minecraft:wool 6
fill ~50~60~3 ~51~60~3 minecraft:stained_glass 6
fill ~51~55~3 ~54~55~3 minecraft:stained_glass 6
setblock ~51~58~3 minecraft:wool 0
setblock ~53~54~3 minecraft:wool 0
fill ~53~56~3 ~54~56~5 minecraft:stained_glass 6
setblock ~53~57~3 minecraft:stained_hardened_clay 14
setblock ~53~58~3 minecraft:stained_glass 6
setblock ~55~57~3 minecraft:stained_hardened_clay 14
fill ~56~57~3 ~56~57~5 minecraft:stained_glass 6
fill ~26~0~4 ~38~0~9 minecraft:grass
fill ~26~1~4 ~26~1~9 minecraft:tallgrass 0
setblock ~29~55~4 minecraft:stained_glass 6
fill ~30~1~4 ~31~1~4 minecraft:tallgrass 0
fill ~30~57~4 ~30~57~6 minecraft:stained_glass 6
setblock ~30~59~4 minecraft:stained_hardened_clay 14
fill ~31~53~4 ~35~53~4 minecraft:stained_glass 6
fill ~31~55~4 ~31~55~5 minecraft:stained_glass 6
fill ~32~50~4 ~32~50~5 minecraft:stained_glass 6
fill ~32~52~4 ~35~52~4 minecraft:stained_glass 6
setblock ~32~58~4 minecraft:stained_glass 6
setblock ~32~59~4 minecraft:wool 0
setblock ~33~54~4 minecraft:wool 0
setblock ~34~57~4 minecraft:stained_glass 6
setblock ~34~59~4 minecraft:stained_hardened_clay 14
fill ~35~1~4 ~35~1~6 minecraft:tallgrass 0
fill ~35~54~4 ~35~54~5 minecraft:stained_glass 6
setblock ~35~55~4 minecraft:stained_glass 6
setblock ~35~59~4 minecraft:stained_glass 6
setblock ~36~57~4 minecraft:stained_glass 6
setblock ~36~59~4 minecraft:stained_hardened_clay 14
fill ~36~60~4 ~36~60~5 minecraft:stained_glass 6
fill ~37~53~4 ~37~53~5 minecraft:stained_glass 6
setblock ~37~56~4 minecraft:stained_glass 6
fill ~37~58~4 ~39~58~4 minecraft:stained_glass 6
fill ~38~54~4 ~38~54~7 minecraft:stained_glass 6
setblock ~38~57~4 minecraft:stained_glass 6
fill ~38~60~4 ~38~60~5 minecraft:stained_glass 6
fill ~38~62~4 ~38~62~6 minecraft:stained_glass 6
fill ~39~51~4 ~39~51~5 minecraft:stained_glass 6
fill ~39~55~4 ~40~55~4 minecraft:stained_glass 6
setblock ~39~57~4 minecraft:wool 6
fill ~39~59~4 ~39~59~5 minecraft:stained_glass 6
setblock ~40~53~4 minecraft:stained_hardened_clay 14
setblock ~40~61~4 minecraft:stained_hardened_clay 14
setblock ~41~51~4 minecraft:stained_glass 6
setblock ~41~53~4 minecraft:wool 6
setblock ~41~54~4 minecraft:stained_glass 6
setblock ~41~56~4 minecraft:wool 0
fill ~41~58~4 ~43~58~4 minecraft:stained_glass 6
fill ~41~59~4 ~41~59~7 minecraft:stained_glass 6
fill ~41~61~4 ~42~61~4 minecraft:stained_glass 6
setblock ~42~52~4 minecraft:stained_hardened_clay 14
fill ~42~55~4 ~43~55~4 minecraft:stained_glass 6
fill ~42~62~4 ~44~62~4 minecraft:stained_glass 6
fill ~43~53~4 ~43~53~7 minecraft:stained_glass 6
fill ~44~56~4 ~44~56~5 minecraft:stained_glass 6
fill ~44~60~4 ~44~60~7 minecraft:stained_glass 6
fill ~44~61~4 ~45~61~4 minecraft:stained_glass 6
fill ~45~53~4 ~46~53~4 minecraft:stained_glass 6
fill ~46~52~4 ~46~52~5 minecraft:stained_glass 6
setblock ~46~60~4 minecraft:wool 0
fill ~47~59~4 ~47~59~7 minecraft:stained_glass 6
setblock ~48~55~4 minecraft:stained_glass 6
fill ~48~58~4 ~48~58~8 minecraft:stained_glass 6
fill ~48~60~4 ~48~60~7 minecraft:stained_glass 6
setblock ~48~61~4 minecraft:stained_glass 6
fill ~49~59~4 ~49~59~6 minecraft:stained_glass 6
setblock ~49~61~4 minecraft:wool 6
setblock ~50~54~4 minecraft:stained_glass 6
fill ~50~56~4 ~51~56~5 minecraft:stained_glass 6
fill ~50~57~4 ~51~57~4 minecraft:stained_glass 6
fill ~50~60~4 ~50~60~6 minecraft:stained_glass 6
fill ~50~61~4 ~52~61~4 minecraft:stained_glass 6
setblock ~51~54~4 minecraft:wool 6
fill ~51~58~4 ~51~58~5 minecraft:stained_glass 6
setblock ~51~59~4 minecraft:stained_glass 6
setblock ~52~56~4 minecraft:wool 0
fill ~53~54~4 ~57~54~4 minecraft:stained_glass 6
setblock ~53~55~4 minecraft:stained_glass 6
setblock ~54~55~4 minecraft:wool 6
fill ~54~58~4 ~54~59~4 minecraft:stained_glass 6
fill ~55~56~4 ~57~56~4 minecraft:stained_glass 6
fill ~56~55~4 ~57~55~4 minecraft:stained_glass 6
fill ~57~57~4 ~57~57~5 minecraft:stained_glass 6
fill ~24~0~5 ~25~0~9 minecraft:grass
fill ~24~1~5 ~25~1~5 minecraft:tallgrass 0
setblock ~28~55~5 minecraft:stained_glass 6
setblock ~28~57~5 minecraft:stained_hardened_clay 14
fill ~28~58~5 ~29~58~6 minecraft:stained_glass 6
fill ~28~59~5 ~30~59~5 minecraft:stained_glass 6
fill ~29~53~5 ~30~53~5 minecraft:stained_glass 6
setblock ~29~55~5 minecraft:wool 0
fill ~29~60~5 ~30~60~5 minecraft:stained_glass 6
fill ~30~52~5 ~31~52~5 minecraft:stained_glass 6
fill ~31~1~5 ~32~1~5 minecraft:tallgrass 0
fill ~31~56~5 ~31~56~7 minecraft:stained_glass 6
setblock ~31~61~5 minecraft:stained_glass 6
fill ~32~57~5 ~32~57~6 minecraft:stained_glass 6
setblock ~32~59~5 minecraft:wool 6
setblock ~32~60~5 minecraft:stained_glass 6
fill ~33~53~5 ~34~53~5 minecraft:stained_glass 6
fill ~33~55~5 ~33~56~5 minecraft:stained_glass 6
fill ~33~58~5 ~33~59~5 minecraft:stained_glass 6
setblock ~34~51~5 minecraft:stained_glass 6
setblock ~34~54~5 minecraft:wool 0
setblock ~34~57~5 minecraft:wool 6
fill ~34~59~5 ~34~60~5 minecraft:wool 6
setblock ~35~57~5 minecraft:stained_glass 6
setblock ~35~60~5 minecraft:stained_hardened_clay 14
fill ~36~53~5 ~36~54~5 minecraft:stained_glass 6
setblock ~36~57~5 minecraft:wool 6
fill ~37~1~5 ~37~1~13 minecraft:tallgrass 0
fill ~37~54~5 ~37~55~5 minecraft:stained_glass 6
fill ~37~58~5 ~37~59~5 minecraft:stained_glass 6
setblock ~37~61~5 minecraft:wool 0
fill ~38~55~5 ~38~55~8 minecraft:stained_glass 6
setblock ~38~56~5 minecraft:stained_glass 6
setblock ~38~58~5 minecraft:stained_hardened_clay 14
setblock ~38~59~5 minecraft:stained_glass 6
fill ~39~0~5 ~40~0~22 minecraft:grass
setblock ~39~52~5 minecraft:stained_glass 6
setblock ~39~53~5 minecraft:stained_hardened_clay 14
setblock ~39~54~5 minecraft:stained_glass 6
setblock ~39~57~5 minecraft:stained_glass 6
setblock ~39~58~5 minecraft:wool 0
setblock ~39~60~5 minecraft:stained_hardened_clay 14
fill ~39~62~5 ~39~63~6 minecraft:stained_glass 6
fill ~40~51~5 ~40~51~6 minecraft:stained_glass 6
fill ~40~53~5 ~40~53~6 minecraft:stained_glass 6
fill ~40~56~5 ~40~56~6 minecraft:stained_glass 6
setblock ~40~61~5 minecraft:stained_glass 6
setblock ~41~50~5 minecraft:stained_glass 6
setblock ~41~53~5 minecraft:stained_hardened_clay 14
fill ~41~55~5 ~42~55~5 minecraft:stained_glass 6
fill ~41~57~5 ~41~58~5 minecraft:stained_glass 6
fill ~41~62~5 ~41~62~8 minecraft:stained_glass 6
setblock ~42~52~5 minecraft:wool 0
setblock ~42~58~5 minecraft:stained_glass 6
fill ~42~61~5 ~42~61~7 minecraft:stained_glass 6
fill ~42~63~5 ~42~63~8 minecraft:stained_glass 6
fill ~43~50~5 ~43~51~5 minecraft:stained_glass 6
setblock ~43~55~5 minecraft:wool 6
fill ~43~56~5 ~43~56~6 minecraft:stained_glass 6
fill ~43~59~5 ~44~59~5 minecraft:stained_glass 6
fill ~43~60~5 ~43~60~11 minecraft:stained_glass 6
setblock ~43~62~5 minecraft:wool 0
setblock ~43~63~5 minecraft:stained_hardened_clay 14
fill ~44~53~5 ~45~53~6 minecraft:stained_glass 6
fill ~44~54~5 ~44~54~6 minecraft:stained_glass 6
setblock ~44~55~5 minecraft:stained_glass 6
fill ~44~61~5 ~44~62~6 minecraft:stained_glass 6
setblock ~45~52~5 minecraft:stained_glass 6
fill ~45~54~5 ~45~54~6 minecraft:wool 0
fill ~45~55~5 ~45~56~5 minecraft:wool 6
setblock ~45~58~5 minecraft:stained_glass 6
setblock ~45~61~5 minecraft:wool 0
fill ~45~63~5 ~46~63~5 minecraft:stained_glass 6
fill ~46~60~5 ~47~60~5 minecraft:stained_glass 6
setblock ~46~62~5 minecraft:stained_hardened_clay 14
fill ~47~52~5 ~47~53~5 minecraft:stained_glass 6
fill ~47~56~5 ~49~56~5 minecraft:stained_glass 6
setblock ~47~58~5 minecraft:stained_glass 6
fill ~47~61~5 ~47~61~6 minecraft:stained_glass 6
fill ~48~53~5 ~48~53~7 minecraft:stained_glass 6
setblock ~48~61~5 minecraft:wool 0
setblock ~48~62~5 minecraft:wool 6
fill ~49~54~5 ~49~54~7 minecraft:stained_glass 6
setblock ~49~60~5 minecraft:wool 6
fill ~49~61~5 ~49~61~6 minecraft:stained_glass 6
setblock ~50~58~5 minecraft:stained_glass 6
fill ~51~53~5 ~51~54~6 minecraft:stained_glass 6
setblock ~51~57~5 minecraft:wool 6
setblock ~51~59~5 minecraft:wool 0
fill ~51~60~5 ~52~60~5 minecraft:stained_glass 6
setblock ~51~61~5 minecraft:stained_glass 6
setblock ~51~62~5 minecraft:wool 6
setblock ~52~53~5 minecraft:stained_hardened_clay 14
fill ~52~55~5 ~52~57~5 minecraft:stained_glass 6
fill ~53~57~5 ~53~57~6 minecraft:stained_glass 6
setblock ~53~61~5 minecraft:stained_glass 6
fill ~54~53~5 ~54~55~5 minecraft:stained_glass 6
setblock ~54~58~5 minecraft:wool 0
setblock ~54~60~5 minecraft:wool 0
fill ~55~57~5 ~55~57~6 minecraft:stained_glass 6
setblock ~55~60~5 minecraft:stained_glass 6
fill ~56~53~5 ~56~54~6 minecraft:stained_glass 6
fill ~56~56~5 ~57~56~5 minecraft:stained_glass 6
fill ~57~54~5 ~57~55~6 minecraft:stained_glass 6
setblock ~58~57~5 minecraft:stained_hardened_clay 14
setblock ~58~58~5 minecraft:stained_glass 6
setblock ~59~56~5 minecraft:stained_glass 6
fill ~22~0~6 ~23~0~9 minecraft:grass
setblock ~22~1~6 minecraft:carpet 6
fill ~23~1~6 ~23~1~9 minecraft:tallgrass 0
setblock ~27~1~6 minecraft:double_plant 2
fill ~27~59~6 ~27~59~7 minecraft:stained_glass 6
fill ~28~55~6 ~28~55~7 minecraft:wool 0
setblock ~28~60~6 minecraft:stained_glass 6
fill ~29~54~6 ~30~54~6 minecraft:stained_glass 6
fill ~29~55~6 ~29~55~7 minecraft:stained_glass 6
setblock ~29~56~6 minecraft:stained_glass 6
fill ~29~59~6 ~30~59~6 minecraft:stained_glass 6
fill ~29~61~6 ~30~61~6 minecraft:stained_glass 6
setblock ~30~1~6 minecraft:tallgrass 0
fill ~30~52~6 ~30~52~7 minecraft:stained_glass 6
fill ~30~53~6 ~31~53~6 minecraft:stained_glass 6
setblock ~30~58~6 minecraft:wool 0
setblock ~31~54~6 minecraft:stained_hardened_clay 14
setblock ~31~57~6 minecraft:stained_glass 6
fill ~32~1~6 ~34~1~8 minecraft:tallgrass 0
setblock ~32~52~6 minecraft:wool 6
fill ~32~54~6 ~32~54~7 minecraft:stained_glass 6
setblock ~32~58~6 minecraft:stained_glass 6
fill ~32~61~6 ~33~61~6 minecraft:stained_glass 6
fill ~33~53~6 ~33~53~7 minecraft:stained_glass 6
setblock ~33~58~6 minecraft:wool 6
fill ~33~60~6 ~33~60~7 minecraft:stained_glass 6
setblock ~34~51~6 minecraft:wool 6
setblock ~34~54~6 minecraft:stained_glass 6
setblock ~34~57~6 minecraft:wool 0
fill ~34~58~6 ~36~58~6 minecraft:stained_glass 6
setblock ~35~53~6 minecraft:stained_glass 6
setblock ~35~57~6 minecraft:stained_hardened_clay 14
fill ~35~59~6 ~35~60~6 minecraft:stained_glass 6
setblock ~35~61~6 minecraft:wool 6
fill ~36~1~6 ~36~1~13 minecraft:tallgrass 0
fill ~36~56~6 ~37~56~6 minecraft:stained_glass 6
setblock ~36~57~6 minecraft:stained_glass 6
setblock ~37~53~6 minecraft:wool 0
setblock ~37~55~6 minecraft:wool 0
fill ~37~62~6 ~37~62~7 minecraft:stained_glass 6
fill ~38~1~6 ~38~1~7 minecraft:tallgrass 0
setblock ~38~61~6 minecraft:stained_glass 6
setblock ~39~50~6 minecraft:stained_glass 6
setblock ~39~53~6 minecraft:stained_glass 6
setblock ~39~54~6 minecraft:wool 0
fill ~39~55~6 ~41~55~6 minecraft:stained_glass 6
setblock ~39~56~6 minecraft:stained_glass 6
setblock ~39~60~6 minecraft:stained_glass 6
setblock ~39~61~6 minecraft:stained_hardened_clay 14
fill ~40~49~6 ~42~49~6 minecraft:stained_glass 6
setblock ~40~50~6 minecraft:wool 0
setblock ~40~61~6 minecraft:wool 6
fill ~40~62~6 ~40~62~7 minecraft:stained_glass 6
setblock ~40~63~6 minecraft:wool 6
fill ~41~0~6 ~42~0~23 minecraft:grass
fill ~41~51~6 ~41~52~6 minecraft:stained_glass 6
setblock ~41~53~6 minecraft:wool 6
setblock ~41~57~6 minecraft:wool 0
setblock ~41~61~6 minecraft:stained_glass 6
fill ~42~52~6 ~44~52~6 minecraft:stained_glass 6
setblock ~42~53~6 minecraft:stained_glass 6
setblock ~42~56~6 minecraft:stained_glass 6
setblock ~42~59~6 minecraft:wool 6
fill ~42~60~6 ~42~60~7 minecraft:stained_glass 6
setblock ~42~62~6 minecraft:wool 6
setblock ~43~51~6 minecraft:wool 6
fill ~43~57~6 ~47~57~6 minecraft:stained_glass 6
setblock ~43~62~6 minecraft:stained_glass 6
fill ~43~64~6 ~43~64~7 minecraft:stained_glass 6
setblock ~44~59~6 minecraft:stained_hardened_clay 14
fill ~44~63~6 ~44~63~8 minecraft:stained_glass 6
setblock ~45~56~6 minecraft:wool 0
setblock ~45~59~6 minecraft:stained_glass 6
fill ~45~61~6 ~45~62~6 minecraft:stained_glass 6
setblock ~45~63~6 minecraft:wool 0
fill ~46~53~6 ~46~54~6 minecraft:stained_glass 6
setblock ~46~55~6 minecraft:stained_hardened_clay 14
setblock ~46~58~6 minecraft:wool 0
setblock ~46~59~6 minecraft:stained_hardened_clay 14
setblock ~46~60~6 minecraft:stained_glass 6
setblock ~46~63~6 minecraft:stained_glass 6
setblock ~47~58~6 minecraft:stained_hardened_clay 14
fill ~47~62~6 ~48~62~6 minecraft:stained_glass 6
fill ~48~54~6 ~48~54~7 minecraft:stained_glass 6
setblock ~48~55~6 minecraft:stained_glass 6
setblock ~48~59~6 minecraft:wool 6
fill ~48~61~6 ~48~61~7 minecraft:stained_glass 6
setblock ~49~56~6 minecraft:stained_glass 6
setblock ~49~57~6 minecraft:wool 0
setblock ~50~53~6 minecraft:wool 6
setblock ~50~54~6 minecraft:stained_glass 6
fill ~50~57~6 ~51~57~8 minecraft:stained_glass 6
setblock ~50~61~6 minecraft:stained_glass 6
fill ~50~63~6 ~51~63~6 minecraft:stained_glass 6
setblock ~51~60~6 minecraft:stained_glass 6
fill ~52~58~6 ~55~58~6 minecraft:stained_glass 6
fill ~52~59~6 ~53~59~6 minecraft:stained_glass 6
setblock ~53~54~6 minecraft:stained_glass 6
setblock ~54~53~6 minecraft:wool 6
setblock ~54~55~6 minecraft:wool 0
setblock ~54~56~6 minecraft:stained_glass 6
setblock ~54~59~6 minecraft:wool 0
setblock ~54~62~6 minecraft:wool 6
setblock ~55~56~6 minecraft:wool 6
setblock ~56~58~6 minecraft:wool 6
setblock ~56~61~6 minecraft:stained_glass 6
fill ~57~60~6 ~58~60~6 minecraft:stained_glass 6
fill ~58~56~6 ~58~56~8 minecraft:stained_glass 6
fill ~58~57~6 ~59~57~6 minecraft:stained_glass 6
setblock ~59~55~6 minecraft:stained_glass 6
setblock ~59~58~6 minecraft:stained_hardened_clay 14
setblock ~59~59~6 minecraft:stained_glass 6
setblock ~59~62~6 minecraft:stained_hardened_clay 14
setblock ~60~61~6 minecraft:wool 6
fill ~60~62~6 ~60~62~9 minecraft:stained_glass 6
setblock ~61~61~6 minecraft:wool 0
fill ~20~0~7 ~21~0~10 minecraft:grass
fill ~20~1~7 ~22~1~9 minecraft:tallgrass 0
fill ~24~1~7 ~25~1~7 minecraft:tallgrass 0
fill ~26~58~7 ~26~58~10 minecraft:stained_glass 6
setblock ~26~59~7 minecraft:stained_glass 6
setblock ~27~56~7 minecraft:stained_glass 6
fill ~27~60~7 ~27~60~8 minecraft:stained_glass 6
setblock ~28~54~7 minecraft:stained_glass 6
fill ~28~59~7 ~29~59~7 minecraft:wool 6
fill ~29~1~7 ~29~1~8 minecraft:tallgrass 0
fill ~29~53~7 ~29~53~8 minecraft:stained_glass 6
setblock ~29~57~7 minecraft:stained_glass 6
setblock ~29~62~7 minecraft:stained_glass 6
setblock ~30~1~7 minecraft:double_plant 1
fill ~30~54~7 ~31~54~7 minecraft:stained_glass 6
setblock ~30~57~7 minecraft:stained_hardened_clay 14
fill ~30~60~7 ~30~61~7 minecraft:stained_glass 6
setblock ~30~62~7 minecraft:wool 0
setblock ~31~1~7 minecraft:tallgrass 0
setblock ~31~52~7 minecraft:wool 6
setblock ~31~55~7 minecraft:stained_glass 6
fill ~31~61~7 ~31~61~11 minecraft:stained_glass 6
setblock ~32~52~7 minecraft:stained_glass 6
setblock ~32~53~7 minecraft:wool 6
fill ~32~60~7 ~32~60~8 minecraft:stained_glass 6
setblock ~33~56~7 minecraft:wool 6
setblock ~33~59~7 minecraft:stained_glass 6
setblock ~34~52~7 minecraft:stained_glass 6
fill ~34~56~7 ~34~57~7 minecraft:stained_glass 6
fill ~34~60~7 ~34~60~8 minecraft:stained_glass 6
setblock ~35~55~7 minecraft:stained_glass 6
fill ~35~57~7 ~35~58~8 minecraft:stained_glass 6
setblock ~35~59~7 minecraft:stained_hardened_clay 14
setblock ~36~54~7 minecraft:stained_glass 6
setblock ~36~55~7 minecraft:stained_hardened_clay 14
fill ~36~58~7 ~36~59~8 minecraft:stained_glass 6
fill ~36~61~7 ~36~62~7 minecraft:stained_glass 6
setblock ~37~53~7 minecraft:stained_glass 6
fill ~37~59~7 ~38~59~7 minecraft:stained_glass 6
setblock ~37~61~7 minecraft:wool 6
fill ~37~63~7 ~38~63~7 minecraft:stained_glass 6
fill ~38~52~7 ~38~52~8 minecraft:stained_glass 6
setblock ~38~56~7 minecraft:stained_glass 6
setblock ~38~60~7 minecraft:stained_hardened_clay 14
setblock ~39~51~7 minecraft:wool 6
fill ~39~54~7 ~40~54~7 minecraft:stained_glass 6
setblock ~39~56~7 minecraft:wool 6
fill ~39~60~7 ~40~60~7 minecraft:wool 6
setblock ~39~61~7 minecraft:stained_glass 6
fill ~40~50~7 ~41~50~7 minecraft:stained_glass 6
fill ~40~52~7 ~41~52~7 minecraft:stained_glass 6
setblock ~40~53~7 minecraft:wool 6
setblock ~40~55~7 minecraft:wool 6
fill ~40~57~7 ~40~57~8 minecraft:stained_glass 6
setblock ~40~59~7 minecraft:stained_hardened_clay 14
setblock ~40~61~7 minecraft:stained_hardened_clay 14
setblock ~41~55~7 minecraft:wool 0
setblock ~41~60~7 minecraft:wool 0
setblock ~42~49~7 minecraft:stained_glass 6
setblock ~42~51~7 minecraft:stained_glass 6
setblock ~42~55~7 minecraft:stained_glass 6
fill ~42~58~7 ~43~58~7 minecraft:stained_glass 6
setblock ~42~59~7 minecraft:stained_glass 6
fill ~43~0~7 ~44~0~22 minecraft:grass
setblock ~43~50~7 minecraft:stained_glass 6
setblock ~43~52~7 minecraft:stained_glass 6
setblock ~43~54~7 minecraft:stained_glass 6
setblock ~43~57~7 minecraft:stained_glass 6
setblock ~43~59~7 minecraft:wool 6
setblock ~43~61~7 minecraft:stained_glass 6
setblock ~43~62~7 minecraft:stained_hardened_clay 14
setblock ~43~63~7 minecraft:stained_glass 6
setblock ~44~52~7 minecraft:wool 6
fill ~44~53~7 ~44~53~8 minecraft:stained_glass 6
fill ~44~57~7 ~45~57~7 minecraft:wool 6
fill ~44~64~7 ~44~64~9 minecraft:stained_glass 6
fill ~45~54~7 ~45~54~8 minecraft:stained_glass 6
setblock ~45~56~7 minecraft:stained_glass 6
fill ~45~58~7 ~46~58~8 minecraft:stained_glass 6
fill ~45~60~7 ~45~60~9 minecraft:stained_glass 6
setblock ~45~61~7 minecraft:wool 0
setblock ~45~63~7 minecraft:stained_glass 6
fill ~46~55~7 ~47~55~7 minecraft:stained_glass 6
setblock ~46~63~7 minecraft:stained_hardened_clay 14
setblock ~47~54~7 minecraft:stained_glass 6
setblock ~47~60~7 minecraft:stained_glass 6
setblock ~47~62~7 minecraft:wool 0
fill ~48~56~7 ~48~57~7 minecraft:stained_glass 6
setblock ~48~59~7 minecraft:stained_glass 6
setblock ~48~62~7 minecraft:wool 6
setblock ~49~55~7 minecraft:stained_glass 6
setblock ~49~57~7 minecraft:stained_glass 6
fill ~49~62~7 ~49~62~8 minecraft:stained_glass 6
setblock ~49~63~7 minecraft:stained_glass 6
setblock ~50~56~7 minecraft:stained_glass 6
setblock ~50~59~7 minecraft:wool 0
fill ~51~54~7 ~52~54~7 minecraft:stained_glass 6
setblock ~51~55~7 minecraft:stained_glass 6
setblock ~51~58~7 minecraft:wool 0
fill ~51~61~7 ~54~61~7 minecraft:stained_glass 6
setblock ~51~62~7 minecraft:wool 0
setblock ~51~63~7 minecraft:stained_glass 6
fill ~52~56~7 ~52~56~8 minecraft:stained_glass 6
setblock ~52~59~7 minecraft:stained_hardened_clay 14
fill ~53~58~7 ~53~58~8 minecraft:stained_glass 6
setblock ~53~62~7 minecraft:stained_glass 6
fill ~54~54~7 ~56~54~7 minecraft:stained_glass 6
setblock ~54~55~7 minecraft:stained_glass 6
fill ~54~56~7 ~54~57~7 minecraft:wool 0
setblock ~54~63~7 minecraft:stained_glass 6
setblock ~55~55~7 minecraft:stained_hardened_clay 14
setblock ~55~59~7 minecraft:wool 0
fill ~55~60~7 ~55~60~8 minecraft:stained_glass 6
setblock ~55~61~7 minecraft:wool 6
setblock ~55~62~7 minecraft:wool 0
setblock ~56~53~7 minecraft:wool 0
setblock ~56~57~7 minecraft:stained_glass 6
fill ~56~62~7 ~56~62~10 minecraft:stained_glass 6
setblock ~57~55~7 minecraft:stained_glass 6
setblock ~57~57~7 minecraft:wool 6
fill ~57~58~7 ~58~58~8 minecraft:stained_glass 6
setblock ~57~61~7 minecraft:stained_glass 6
fill ~58~54~7 ~59~54~8 minecraft:stained_glass 6
fill ~58~59~7 ~58~59~8 minecraft:stained_glass 6
setblock ~58~63~7 minecraft:stained_glass 6
setblock ~59~56~7 minecraft:stained_glass 6
setblock ~59~57~7 minecraft:wool 6
fill ~59~61~7 ~60~61~7 minecraft:stained_glass 6
setblock ~59~62~7 minecraft:stained_glass 6
setblock ~59~63~7 minecraft:stained_hardened_clay 14
setblock ~60~55~7 minecraft:stained_glass 6
fill ~60~57~7 ~60~58~8 minecraft:stained_glass 6
setblock ~60~60~7 minecraft:wool 6
setblock ~61~58~7 minecraft:stained_glass 6
setblock ~61~63~7 minecraft:stained_glass 6
fill ~62~59~7 ~62~59~10 minecraft:stained_glass 6
fill ~62~60~7 ~62~62~7 minecraft:stained_glass 6
fill ~19~0~8 ~19~0~40 minecraft:grass
setblock ~19~1~8 minecraft:double_plant 1
setblock ~24~1~8 minecraft:double_plant 1
fill ~24~58~8 ~25~58~8 minecraft:stained_glass 6
fill ~25~1~8 ~25~1~9 minecraft:tallgrass 0
setblock ~25~56~8 minecraft:wool 6
setblock ~25~59~8 minecraft:wool 6
fill ~26~54~8 ~26~55~8 minecraft:stained_glass 6
setblock ~26~56~8 minecraft:wool 0
fill ~26~57~8 ~26~57~10 minecraft:stained_glass 6
fill ~26~60~8 ~26~60~11 minecraft:stained_glass 6
fill ~27~55~8 ~28~55~8 minecraft:stained_glass 6
setblock ~27~58~8 minecraft:stained_glass 6
fill ~28~56~8 ~29~56~8 minecraft:stained_glass 6
setblock ~28~57~8 minecraft:stained_glass 6
fill ~28~60~8 ~29~60~8 minecraft:stained_glass 6
fill ~29~61~8 ~30~61~8 minecraft:stained_glass 6
setblock ~30~1~8 minecraft:carpet 6
setblock ~30~53~8 minecraft:wool 0
setblock ~30~62~8 minecraft:stained_glass 6
fill ~31~54~8 ~31~54~9 minecraft:stained_glass 6
fill ~31~57~8 ~31~57~10 minecraft:stained_glass 6
fill ~31~60~8 ~31~60~10 minecraft:stained_glass 6
fill ~32~55~8 ~32~55~9 minecraft:stained_glass 6
setblock ~32~57~8 minecraft:stained_hardened_clay 14
setblock ~32~61~8 minecraft:wool 0
setblock ~32~62~8 minecraft:stained_glass 6
setblock ~33~54~8 minecraft:stained_glass 6
setblock ~33~58~8 minecraft:wool 0
setblock ~33~61~8 minecraft:stained_hardened_clay 14
fill ~34~58~8 ~34~59~8 minecraft:stained_glass 6
fill ~34~61~8 ~35~61~8 minecraft:stained_glass 6
fill ~35~1~8 ~35~1~12 minecraft:tallgrass 0
fill ~35~56~8 ~36~56~8 minecraft:stained_glass 6
setblock ~35~59~8 minecraft:stained_glass 6
setblock ~35~60~8 minecraft:wool 6
fill ~36~60~8 ~37~60~8 minecraft:stained_glass 6
setblock ~36~63~8 minecraft:stained_glass 6
setblock ~37~53~8 minecraft:wool 6
setblock ~37~56~8 minecraft:wool 0
fill ~37~61~8 ~38~61~8 minecraft:stained_glass 6
setblock ~38~51~8 minecraft:stained_glass 6
fill ~38~53~8 ~40~53~8 minecraft:stained_glass 6
setblock ~38~58~8 minecraft:stained_glass 6
setblock ~38~59~8 minecraft:wool 0
fill ~38~62~8 ~39~62~8 minecraft:stained_glass 6
fill ~39~55~8 ~40~55~8 minecraft:stained_glass 6
fill ~39~63~8 ~39~63~9 minecraft:stained_glass 6
setblock ~40~1~8 minecraft:double_plant 1
fill ~40~49~8 ~41~49~8 minecraft:stained_glass 6
setblock ~40~50~8 minecraft:stained_hardened_clay 14
fill ~40~54~8 ~41~54~8 minecraft:stained_glass 6
setblock ~40~58~8 minecraft:stained_hardened_clay 14
setblock ~40~60~8 minecraft:stained_glass 6
fill ~41~51~8 ~41~51~9 minecraft:stained_glass 6
setblock ~41~55~8 minecraft:stained_hardened_clay 14
fill ~41~56~8 ~41~58~8 minecraft:stained_glass 6
fill ~41~60~8 ~41~61~8 minecraft:stained_hardened_clay 14
setblock ~42~53~8 minecraft:stained_glass 6
setblock ~42~57~8 minecraft:stained_glass 6
setblock ~43~51~8 minecraft:wool 0
setblock ~43~56~8 minecraft:stained_glass 6
fill ~43~58~8 ~44~58~8 minecraft:stained_glass 6
setblock ~44~59~8 minecraft:stained_glass 6
setblock ~44~61~8 minecraft:stained_hardened_clay 14
fill ~44~62~8 ~45~62~8 minecraft:stained_glass 6
fill ~45~0~8 ~45~0~21 minecraft:grass
setblock ~45~55~8 minecraft:wool 0
setblock ~45~64~8 minecraft:stained_hardened_clay 14
fill ~46~56~8 ~46~57~8 minecraft:stained_glass 6
setblock ~46~59~8 minecraft:stained_glass 6
fill ~46~61~8 ~47~61~8 minecraft:stained_glass 6
fill ~46~63~8 ~47~63~8 minecraft:stained_glass 6
fill ~47~55~8 ~47~56~8 minecraft:wool 0
fill ~47~57~8 ~47~58~8 minecraft:stained_glass 6
fill ~48~62~8 ~48~62~9 minecraft:stained_glass 6
setblock ~49~56~8 minecraft:wool 0
fill ~49~58~8 ~49~59~9 minecraft:stained_glass 6
setblock ~50~55~8 minecraft:stained_glass 6
setblock ~50~63~8 minecraft:stained_glass 6
setblock ~51~55~8 minecraft:wool 0
fill ~51~58~8 ~51~60~9 minecraft:stained_glass 6
fill ~51~61~8 ~51~62~8 minecraft:stained_glass 6
setblock ~52~55~8 minecraft:wool 6
setblock ~52~57~8 minecraft:stained_hardened_clay 14
setblock ~53~55~8 minecraft:stained_glass 6
setblock ~53~56~8 minecraft:wool 6
setblock ~53~57~8 minecraft:wool 0
setblock ~53~61~8 minecraft:wool 0
fill ~54~59~8 ~54~59~10 minecraft:stained_glass 6
setblock ~54~60~8 minecraft:stained_glass 6
setblock ~54~63~8 minecraft:wool 0
setblock ~55~54~8 minecraft:stained_glass 6
setblock ~55~55~8 minecraft:wool 6
setblock ~55~57~8 minecraft:wool 6
fill ~55~62~8 ~55~62~9 minecraft:stained_glass 6
fill ~55~63~8 ~56~63~8 minecraft:stained_glass 6
setblock ~56~56~8 minecraft:stained_glass 6
setblock ~56~58~8 minecraft:wool 6
fill ~56~59~8 ~56~59~12 minecraft:stained_glass 6
fill ~57~54~8 ~57~54~9 minecraft:stained_glass 6
setblock ~57~57~8 minecraft:stained_glass 6
setblock ~57~62~8 minecraft:wool 6
fill ~58~60~8 ~59~60~8 minecraft:stained_glass 6
fill ~59~55~8 ~59~55~9 minecraft:stained_glass 6
setblock ~59~57~8 minecraft:stained_glass 6
setblock ~59~59~8 minecraft:stained_hardened_clay 14
fill ~59~61~8 ~59~62~8 minecraft:wool 0
setblock ~59~64~8 minecraft:stained_glass 6
setblock ~60~56~8 minecraft:wool 0
setblock ~60~59~8 minecraft:stained_glass 6
setblock ~60~61~8 minecraft:stained_glass 6
fill ~61~57~8 ~61~57~9 minecraft:stained_glass 6
setblock ~61~61~8 minecraft:wool 0
setblock ~61~62~8 minecraft:stained_glass 6
setblock ~62~63~8 minecraft:stained_glass 6
fill ~63~60~8 ~63~60~11 minecraft:stained_glass 6
setblock ~63~62~8 minecraft:stained_glass 6
fill ~17~0~9 ~18~0~49 minecraft:grass
setblock ~19~1~9 minecraft:tallgrass 0
fill ~22~55~9 ~23~55~9 minecraft:wool 0
fill ~23~56~9 ~23~58~9 minecraft:stained_glass 6
setblock ~23~60~9 minecraft:stained_hardened_clay 14
fill ~24~58~9 ~24~59~9 minecraft:stained_glass 6
setblock ~25~59~9 minecraft:stained_glass 6
fill ~26~53~9 ~28~53~9 minecraft:stained_glass 6
setblock ~26~54~9 minecraft:stained_hardened_clay 14
setblock ~26~55~9 minecraft:wool 6
fill ~26~56~9 ~28~56~9 minecraft:stained_glass 6
setblock ~27~57~9 minecraft:stained_glass 6
setblock ~27~59~9 minecraft:wool 6
setblock ~28~54~9 minecraft:stained_glass 6
setblock ~28~55~9 minecraft:wool 6
fill ~29~58~9 ~33~58~9 minecraft:stained_glass 6
fill ~29~60~9 ~29~60~10 minecraft:stained_glass 6
setblock ~29~62~9 minecraft:stained_glass 6
setblock ~30~55~9 minecraft:wool 0
setblock ~30~57~9 minecraft:wool 6
setblock ~30~60~9 minecraft:wool 0
fill ~31~1~9 ~33~1~9 minecraft:tallgrass 0
fill ~31~59~9 ~34~59~9 minecraft:stained_glass 6
setblock ~32~54~9 minecraft:stained_glass 6
setblock ~32~56~9 minecraft:wool 0
fill ~32~61~9 ~32~61~10 minecraft:stained_glass 6
setblock ~34~57~9 minecraft:stained_glass 6
setblock ~34~61~9 minecraft:stained_glass 6
fill ~34~62~9 ~34~63~9 minecraft:stained_hardened_clay 14
setblock ~34~64~9 minecraft:wool 6
setblock ~35~60~9 minecraft:stained_glass 6
fill ~35~62~9 ~36~62~9 minecraft:stained_glass 6
setblock ~35~63~9 minecraft:stained_glass 6
setblock ~35~64~9 minecraft:stained_hardened_clay 14
fill ~36~64~9 ~37~64~9 minecraft:stained_glass 6
fill ~37~58~9 ~37~60~9 minecraft:stained_glass 6
fill ~37~63~9 ~37~63~14 minecraft:stained_glass 6
setblock ~38~1~9 minecraft:carpet 6
setblock ~38~54~9 minecraft:stained_glass 6
fill ~39~51~9 ~39~52~9 minecraft:stained_glass 6
setblock ~39~56~9 minecraft:stained_glass 6
setblock ~39~58~9 minecraft:stained_glass 6
fill ~39~62~9 ~39~62~10 minecraft:stained_glass 6
setblock ~40~51~9 minecraft:wool 6
fill ~40~52~9 ~41~52~10 minecraft:stained_glass 6
setblock ~40~54~9 minecraft:stained_hardened_clay 14
fill ~40~55~9 ~41~55~10 minecraft:stained_glass 6
setblock ~40~60~9 minecraft:stained_hardened_clay 14
fill ~41~50~9 ~42~50~9 minecraft:stained_glass 6
fill ~41~53~9 ~41~53~10 minecraft:stained_glass 6
setblock ~42~52~9 minecraft:stained_hardened_clay 14
fill ~42~59~9 ~42~61~9 minecraft:stained_glass 6
setblock ~43~52~9 minecraft:stained_glass 6
setblock ~43~57~9 minecraft:stained_hardened_clay 14
fill ~43~59~9 ~44~59~9 minecraft:wool 6
setblock ~43~61~9 minecraft:stained_glass 6
fill ~43~63~9 ~43~63~10 minecraft:stained_glass 6
fill ~44~57~9 ~45~57~9 minecraft:stained_glass 6
setblock ~44~58~9 minecraft:stained_glass 6
setblock ~44~60~9 minecraft:wool 6
setblock ~44~67~9 minecraft:stained_glass 6
fill ~45~61~9 ~45~61~10 minecraft:stained_glass 6
fill ~45~62~9 ~47~62~9 minecraft:stained_glass 6
fill ~45~63~9 ~45~65~9 minecraft:stained_glass 6
fill ~46~0~9 ~46~0~20 minecraft:grass
setblock ~46~58~9 minecraft:stained_hardened_clay 14
setblock ~46~59~9 minecraft:wool 6
fill ~46~60~9 ~49~60~9 minecraft:stained_glass 6
setblock ~46~61~9 minecraft:wool 6
setblock ~46~63~9 minecraft:stained_hardened_clay 14
setblock ~46~64~9 minecraft:wool 0
setblock ~47~58~9 minecraft:stained_glass 6
fill ~47~61~9 ~47~61~10 minecraft:stained_glass 6
setblock ~47~63~9 minecraft:stained_glass 6
setblock ~48~59~9 minecraft:stained_hardened_clay 14
setblock ~48~64~9 minecraft:stained_glass 6
setblock ~49~61~9 minecraft:stained_glass 6
fill ~49~63~9 ~49~63~10 minecraft:stained_glass 6
setblock ~49~65~9 minecraft:stained_glass 6
setblock ~50~59~9 minecraft:stained_hardened_clay 14
setblock ~50~60~9 minecraft:wool 6
setblock ~50~61~9 minecraft:stained_hardened_clay 14
fill ~50~62~9 ~51~62~9 minecraft:stained_glass 6
setblock ~50~63~9 minecraft:log 1
fill ~52~57~9 ~52~60~9 minecraft:stained_glass 6
setblock ~53~56~9 minecraft:stained_glass 6
fill ~53~60~9 ~53~62~9 minecraft:stained_glass 6
setblock ~54~57~9 minecraft:wool 0
setblock ~54~58~9 minecraft:wool 6
fill ~54~61~9 ~56~61~9 minecraft:stained_glass 6
setblock ~54~62~9 minecraft:stained_glass 6
fill ~55~55~9 ~55~56~9 minecraft:stained_glass 6
fill ~55~59~9 ~55~59~11 minecraft:stained_glass 6
setblock ~55~60~9 minecraft:wool 6
setblock ~56~55~9 minecraft:stained_hardened_clay 14
fill ~56~58~9 ~56~58~10 minecraft:stained_glass 6
setblock ~56~60~9 minecraft:stained_hardened_clay 14
fill ~56~63~9 ~56~63~13 minecraft:stained_glass 6
setblock ~57~56~9 minecraft:wool 0
setblock ~57~57~9 minecraft:wool 6
setblock ~58~55~9 minecraft:stained_hardened_clay 14
setblock ~58~65~9 minecraft:wool 6
setblock ~59~54~9 minecraft:stained_glass 6
setblock ~59~57~9 minecraft:wool 0
setblock ~59~58~9 minecraft:wool 6
fill ~59~59~9 ~59~59~10 minecraft:stained_glass 6
setblock ~59~62~9 minecraft:wool 0
fill ~59~63~9 ~59~63~10 minecraft:stained_glass 6
setblock ~60~56~9 minecraft:stained_glass 6
setblock ~60~59~9 minecraft:stained_hardened_clay 14
setblock ~60~61~9 minecraft:wool 0
fill ~60~64~9 ~61~64~9 minecraft:stained_glass 6
setblock ~60~65~9 minecraft:wool 6
setblock ~61~58~9 minecraft:stained_glass 6
fill ~61~60~9 ~61~60~10 minecraft:stained_glass 6
setblock ~61~61~9 minecraft:stained_hardened_clay 14
setblock ~62~61~9 minecraft:wool 6
setblock ~63~58~9 minecraft:stained_glass 6
setblock ~63~59~9 minecraft:wool 6
fill ~63~61~9 ~63~61~10 minecraft:stained_glass 6
fill ~63~63~9 ~64~63~9 minecraft:stained_glass 6
fill ~16~0~10 ~16~0~48 minecraft:grass
setblock ~18~1~10 minecraft:tallgrass 0
fill ~20~1~10 ~21~1~10 minecraft:tallgrass 0
setblock ~21~56~10 minecraft:wool 0
fill ~21~57~10 ~25~57~10 minecraft:stained_glass 6
setblock ~21~60~10 minecraft:stained_glass 6
fill ~22~0~10 ~28~0~11 minecraft:dirt 0
fill ~22~1~10 ~28~1~11 minecraft:log 1
fill ~22~53~10 ~23~53~10 minecraft:stained_glass 6
fill ~22~54~10 ~22~55~10 minecraft:stained_glass 6
setblock ~22~58~10 minecraft:stained_glass 6
fill ~23~55~10 ~24~55~10 minecraft:stained_glass 6
fill ~23~60~10 ~23~60~12 minecraft:stained_glass 6
setblock ~23~61~10 minecraft:wool 6
setblock ~24~53~10 minecraft:stained_hardened_clay 14
fill ~24~54~10 ~25~54~11 minecraft:stained_glass 6
setblock ~24~58~10 minecraft:wool 6
fill ~24~61~10 ~24~62~10 minecraft:stained_glass 6
setblock ~25~52~10 minecraft:stained_glass 6
setblock ~25~55~10 minecraft:wool 6
fill ~25~56~10 ~25~56~11 minecraft:stained_glass 6
setblock ~25~58~10 minecraft:stained_glass 6
setblock ~25~60~10 minecraft:wool 6
setblock ~25~61~10 minecraft:stained_hardened_clay 14
fill ~26~53~10 ~27~53~10 minecraft:stained_glass 6
setblock ~26~55~10 minecraft:wool 0
fill ~26~62~10 ~26~62~11 minecraft:stained_glass 6
setblock ~27~52~10 minecraft:wool 0
fill ~27~54~10 ~27~55~10 minecraft:wool 6
fill ~27~56~10 ~28~56~11 minecraft:stained_glass 6
setblock ~27~59~10 minecraft:stained_hardened_clay 14
fill ~27~60~10 ~27~61~11 minecraft:stained_glass 6
setblock ~28~59~10 minecraft:stained_glass 6
setblock ~28~61~10 minecraft:wool 0
setblock ~28~62~10 minecraft:stained_glass 6
fill ~29~0~10 ~38~0~10 minecraft:grass
fill ~29~54~10 ~29~55~10 minecraft:stained_glass 6
fill ~29~57~10 ~29~57~12 minecraft:stained_glass 6
setblock ~29~59~10 minecraft:stained_hardened_clay 14
fill ~30~56~10 ~31~56~10 minecraft:stained_glass 6
fill ~30~57~10 ~30~57~11 minecraft:wool 0
fill ~30~59~10 ~30~59~11 minecraft:stained_glass 6
setblock ~30~61~10 minecraft:wool 0
fill ~32~1~10 ~34~1~10 minecraft:tallgrass 0
setblock ~32~62~10 minecraft:stained_glass 6
fill ~33~56~10 ~36~56~10 minecraft:stained_glass 6
fill ~34~54~10 ~34~55~10 minecraft:stained_glass 6
setblock ~34~57~10 minecraft:wool 6
setblock ~34~58~10 minecraft:stained_glass 6
fill ~34~63~10 ~34~64~10 minecraft:stained_glass 6
setblock ~35~54~10 minecraft:wool 6
setblock ~35~57~10 minecraft:stained_glass 6
setblock ~35~58~10 minecraft:stained_hardened_clay 14
setblock ~35~59~10 minecraft:stained_glass 6
fill ~35~64~10 ~35~65~10 minecraft:stained_glass 6
setblock ~36~55~10 minecraft:stained_glass 6
fill ~36~60~10 ~36~61~10 minecraft:stained_glass 6
setblock ~37~59~10 minecraft:stained_hardened_clay 14
setblock ~37~61~10 minecraft:stained_glass 6
fill ~38~1~10 ~39~1~10 minecraft:tallgrass 0
setblock ~38~57~10 minecraft:wool 0
setblock ~38~58~10 minecraft:stained_glass 6
fill ~38~60~10 ~39~60~10 minecraft:stained_glass 6
setblock ~39~55~10 minecraft:stained_glass 6
setblock ~39~58~10 minecraft:wool 0
fill ~39~59~10 ~39~59~11 minecraft:stained_glass 6
setblock ~40~51~10 minecraft:wool 0
setblock ~40~57~10 minecraft:stained_hardened_clay 14
setblock ~40~58~10 minecraft:stained_glass 6
fill ~41~56~10 ~41~56~11 minecraft:stained_glass 6
setblock ~41~57~10 minecraft:wool 6
fill ~41~60~10 ~42~60~10 minecraft:stained_glass 6
setblock ~41~61~10 minecraft:wool 0
fill ~41~66~10 ~42~66~11 minecraft:stained_glass 6
fill ~42~51~10 ~42~53~10 minecraft:stained_glass 6
fill ~42~57~10 ~42~58~10 minecraft:stained_glass 6
fill ~42~61~10 ~42~62~10 minecraft:stained_glass 6
fill ~42~64~10 ~43~64~11 minecraft:stained_glass 6
setblock ~43~58~10 minecraft:stained_glass 6
fill ~43~61~10 ~44~61~10 minecraft:wool 0
setblock ~43~62~10 minecraft:wool 0
setblock ~43~65~10 minecraft:wool 0
setblock ~43~68~10 minecraft:stained_glass 6
setblock ~44~59~10 minecraft:stained_glass 6
setblock ~44~62~10 minecraft:wool 6
fill ~44~63~10 ~44~63~11 minecraft:stained_glass 6
setblock ~44~66~10 minecraft:stained_glass 6
fill ~45~64~10 ~45~65~10 minecraft:stained_glass 6
fill ~45~67~10 ~46~67~10 minecraft:stained_glass 6
fill ~46~60~10 ~46~60~11 minecraft:stained_glass 6
setblock ~46~66~10 minecraft:stained_glass 6
fill ~47~0~10 ~49~0~17 minecraft:grass
setblock ~47~1~10 minecraft:tallgrass 0
fill ~47~59~10 ~48~59~10 minecraft:stained_glass 6
setblock ~47~62~10 minecraft:stained_glass 6
setblock ~47~65~10 minecraft:wool 6
setblock ~48~60~10 minecraft:wool 6
setblock ~49~62~10 minecraft:stained_glass 6
fill ~49~64~10 ~50~64~10 minecraft:stained_glass 6
setblock ~50~59~10 minecraft:stained_glass 6
setblock ~50~65~10 minecraft:stained_glass 6
fill ~51~60~10 ~52~60~10 minecraft:stained_glass 6
fill ~51~63~10 ~53~63~10 minecraft:stained_glass 6
fill ~51~64~10 ~51~64~11 minecraft:wool 6
fill ~52~59~10 ~53~59~10 minecraft:stained_glass 6
setblock ~52~62~10 minecraft:stained_glass 6
setblock ~52~64~10 minecraft:stained_glass 6
setblock ~53~61~10 minecraft:wool 6
fill ~54~57~10 ~54~58~10 minecraft:stained_glass 6
fill ~54~64~10 ~54~64~11 minecraft:stained_glass 6
fill ~56~60~10 ~56~60~12 minecraft:stained_glass 6
setblock ~56~64~10 minecraft:stained_glass 6
fill ~57~55~10 ~58~55~10 minecraft:wool 6
fill ~57~62~10 ~58~62~10 minecraft:stained_glass 6
fill ~57~64~10 ~58~64~10 minecraft:wool 6
fill ~58~57~10 ~59~57~10 minecraft:stained_glass 6
fill ~58~59~10 ~58~59~11 minecraft:stained_glass 6
setblock ~58~61~10 minecraft:stained_glass 6
setblock ~58~63~10 minecraft:stained_glass 6
setblock ~58~65~10 minecraft:stained_hardened_clay 14
fill ~59~56~10 ~59~56~11 minecraft:stained_glass 6
fill ~59~64~10 ~59~64~12 minecraft:stained_glass 6
setblock ~60~56~10 minecraft:wool 6
setblock ~60~58~10 minecraft:wool 0
fill ~60~59~10 ~60~59~12 minecraft:stained_glass 6
setblock ~60~61~10 minecraft:wool 6
setblock ~60~62~10 minecraft:stained_hardened_clay 14
setblock ~60~63~10 minecraft:wool 0
setblock ~60~65~10 minecraft:stained_glass 6
fill ~61~61~10 ~61~62~10 minecraft:stained_glass 6
setblock ~61~64~10 minecraft:wool 0
setblock ~61~66~10 minecraft:wool 0
setblock ~62~57~10 minecraft:stained_glass 6
fill ~62~62~10 ~63~63~10 minecraft:stained_glass 6
setblock ~62~65~10 minecraft:stained_glass 6
setblock ~63~65~10 minecraft:stained_hardened_clay 14
setblock ~64~59~10 minecraft:stained_glass 6
fill ~64~61~10 ~65~61~10 minecraft:stained_glass 6
setblock ~65~62~10 minecraft:stained_glass 6
fill ~65~64~10 ~65~64~11 minecraft:stained_glass 6
setblock ~65~65~10 minecraft:stained_glass 6
setblock ~66~59~10 minecraft:stained_hardened_clay 14
fill ~67~59~10 ~68~59~11 minecraft:stained_glass 6
fill ~15~0~11 ~15~0~47 minecraft:grass
fill ~19~1~11 ~20~1~23 minecraft:tallgrass 0
fill ~20~0~11 ~20~0~39 minecraft:grass
fill ~20~54~11 ~21~54~11 minecraft:stained_glass 6
fill ~20~55~11 ~20~55~12 minecraft:stained_glass 6
setblock ~20~58~11 minecraft:stained_glass 6
setblock ~20~59~11 minecraft:wool 0
fill ~20~61~11 ~21~61~11 minecraft:wool 6
fill ~21~0~11 ~21~0~12 minecraft:dirt 0
fill ~21~1~11 ~21~1~12 minecraft:log 1
setblock ~21~56~11 minecraft:stained_glass 6
setblock ~21~59~11 minecraft:stained_glass 6
setblock ~22~55~11 minecraft:wool 6
setblock ~22~56~11 minecraft:stained_hardened_clay 14
fill ~22~57~11 ~25~57~11 minecraft:stained_glass 6
fill ~22~60~11 ~22~60~12 minecraft:stained_hardened_clay 14
fill ~23~2~11 ~26~2~11 minecraft:log 1
setblock ~23~53~11 minecraft:wool 6
fill ~23~55~11 ~23~55~12 minecraft:stained_glass 6
fill ~23~58~11 ~23~58~12 minecraft:stained_glass 6
fill ~23~61~11 ~23~61~12 minecraft:stained_glass 6
fill ~24~53~11 ~25~53~11 minecraft:stained_glass 6
setblock ~24~55~11 minecraft:wool 6
setblock ~24~59~11 minecraft:stained_glass 6
fill ~25~55~11 ~27~55~11 minecraft:stained_glass 6
setblock ~25~60~11 minecraft:stained_hardened_clay 14
setblock ~25~62~11 minecraft:stained_glass 6
setblock ~26~52~11 minecraft:wool 6
fill ~26~54~11 ~26~54~13 minecraft:stained_glass 6
setblock ~26~56~11 minecraft:wool 6
setblock ~26~59~11 minecraft:stained_glass 6
fill ~26~61~11 ~26~61~13 minecraft:stained_glass 6
setblock ~26~63~11 minecraft:stained_glass 6
fill ~27~52~11 ~27~52~12 minecraft:stained_glass 6
fill ~27~57~11 ~28~57~11 minecraft:stained_glass 6
setblock ~27~58~11 minecraft:stained_glass 6
setblock ~27~62~11 minecraft:stained_glass 6
setblock ~28~55~11 minecraft:stained_hardened_clay 14
setblock ~28~59~11 minecraft:wool 6
fill ~28~60~11 ~28~61~11 minecraft:stained_glass 6
setblock ~28~63~11 minecraft:stained_glass 6
fill ~29~0~11 ~30~0~11 minecraft:dirt 0
fill ~29~1~11 ~30~1~18 minecraft:log 1
setblock ~29~55~11 minecraft:stained_glass 6
fill ~29~58~11 ~31~58~11 minecraft:stained_glass 6
setblock ~29~59~11 minecraft:stained_glass 6
setblock ~29~62~11 minecraft:stained_glass 6
setblock ~29~63~11 minecraft:wool 6
fill ~30~61~11 ~30~61~13 minecraft:stained_glass 6
fill ~30~63~11 ~31~63~12 minecraft:stained_glass 6
fill ~31~0~11 ~38~0~12 minecraft:grass
fill ~31~56~11 ~31~56~16 minecraft:stained_glass 6
fill ~31~59~11 ~33~59~11 minecraft:stained_glass 6
setblock ~31~62~11 minecraft:stained_glass 6
setblock ~31~64~11 minecraft:stained_glass 6
setblock ~33~1~11 minecraft:double_plant 1
fill ~33~53~11 ~34~53~11 minecraft:stained_glass 6
setblock ~33~54~11 minecraft:stained_glass 6
setblock ~33~55~11 minecraft:stained_hardened_clay 14
fill ~33~56~11 ~34~56~11 minecraft:stained_glass 6
setblock ~33~58~11 minecraft:stained_glass 6
setblock ~33~61~11 minecraft:wool 6
setblock ~33~62~11 minecraft:wool 0
setblock ~33~63~11 minecraft:stained_glass 6
setblock ~34~1~11 minecraft:tallgrass 0
fill ~34~55~11 ~35~55~11 minecraft:wool 6
setblock ~34~59~11 minecraft:wool 6
setblock ~34~61~11 minecraft:stained_glass 6
fill ~34~64~11 ~34~64~12 minecraft:stained_glass 6
setblock ~35~53~11 minecraft:wool 6
setblock ~35~54~11 minecraft:stained_hardened_clay 14
setblock ~35~56~11 minecraft:wool 6
setblock ~35~57~11 minecraft:wool 0
fill ~35~58~11 ~37~58~11 minecraft:stained_glass 6
fill ~35~62~11 ~35~62~12 minecraft:stained_glass 6
fill ~36~53~11 ~36~54~11 minecraft:stained_glass 6
setblock ~36~55~11 minecraft:stained_hardened_clay 14
fill ~36~56~11 ~37~56~11 minecraft:stained_glass 6
fill ~36~59~11 ~38~59~11 minecraft:stained_glass 6
fill ~36~64~11 ~37~64~11 minecraft:stained_glass 6
fill ~36~65~11 ~36~65~12 minecraft:stained_glass 6
fill ~37~53~11 ~37~53~12 minecraft:stained_hardened_clay 14
setblock ~37~54~11 minecraft:wool 0
fill ~37~62~11 ~38~62~11 minecraft:stained_glass 6
setblock ~38~1~11 minecraft:double_plant 1
setblock ~38~57~11 minecraft:stained_glass 6
setblock ~38~60~11 minecraft:wool 6
fill ~38~61~11 ~38~61~14 minecraft:stained_glass 6
setblock ~38~63~11 minecraft:stained_glass 6
setblock ~39~57~11 minecraft:stained_hardened_clay 14
setblock ~39~58~11 minecraft:wool 6
setblock ~39~60~11 minecraft:stained_glass 6
setblock ~39~62~11 minecraft:wool 0
fill ~40~63~11 ~42~63~11 minecraft:stained_glass 6
fill ~40~64~11 ~41~64~11 minecraft:stained_glass 6
setblock ~41~1~11 minecraft:tallgrass 0
fill ~41~59~11 ~41~59~12 minecraft:stained_glass 6
fill ~41~60~11 ~41~61~11 minecraft:stained_glass 6
setblock ~41~65~11 minecraft:stained_glass 6
setblock ~42~58~11 minecraft:stained_glass 6
setblock ~42~60~11 minecraft:wool 6
setblock ~42~62~11 minecraft:stained_glass 6
setblock ~43~63~11 minecraft:stained_hardened_clay 14
setblock ~43~66~11 minecraft:wool 6
fill ~43~67~11 ~44~67~11 minecraft:stained_glass 6
setblock ~43~68~11 minecraft:wool 6
setblock ~44~1~11 minecraft:double_plant 1
fill ~44~58~11 ~45~58~11 minecraft:stained_glass 6
fill ~44~60~11 ~45~60~11 minecraft:stained_glass 6
setblock ~44~61~11 minecraft:stained_glass 6
fill ~44~64~11 ~44~64~12 minecraft:stained_glass 6
setblock ~44~65~11 minecraft:wool 6
fill ~44~69~11 ~44~69~12 minecraft:stained_glass 6
setblock ~45~1~11 minecraft:tallgrass 0
fill ~45~62~11 ~46~62~11 minecraft:stained_glass 6
setblock ~45~63~11 minecraft:stained_glass 6
setblock ~45~65~11 minecraft:stained_glass 6
fill ~45~68~11 ~46~68~11 minecraft:stained_glass 6
setblock ~46~59~11 minecraft:stained_hardened_clay 14
setblock ~46~61~11 minecraft:stained_hardened_clay 14
fill ~46~63~11 ~47~63~11 minecraft:stained_hardened_clay 14
fill ~47~58~11 ~47~58~12 minecraft:stained_glass 6
fill ~47~60~11 ~47~60~12 minecraft:stained_glass 6
fill ~47~62~11 ~47~62~12 minecraft:wool 0
fill ~47~65~11 ~47~65~12 minecraft:stained_glass 6
fill ~47~66~11 ~47~67~11 minecraft:stained_glass 6
setblock ~48~1~11 minecraft:tallgrass 0
setblock ~48~59~11 minecraft:wool 0
setblock ~48~61~11 minecraft:wool 0
fill ~48~62~11 ~48~64~12 minecraft:stained_glass 6
setblock ~49~65~11 minecraft:stained_glass 6
fill ~50~0~11 ~59~0~15 minecraft:grass
setblock ~50~1~11 minecraft:tallgrass 0
fill ~50~62~11 ~50~63~14 minecraft:stained_glass 6
setblock ~50~64~11 minecraft:wool 0
setblock ~50~66~11 minecraft:stained_glass 6
fill ~51~59~11 ~52~59~11 minecraft:stained_glass 6
setblock ~51~61~11 minecraft:stained_glass 6
setblock ~51~63~11 minecraft:wool 0
setblock ~52~60~11 minecraft:stained_glass 6
fill ~52~63~11 ~52~63~12 minecraft:stained_glass 6
setblock ~52~65~11 minecraft:wool 6
fill ~53~64~11 ~53~64~14 minecraft:stained_glass 6
setblock ~54~58~11 minecraft:stained_glass 6
fill ~54~60~11 ~54~60~12 minecraft:stained_glass 6
setblock ~54~61~11 minecraft:stained_glass 6
setblock ~56~1~11 minecraft:tallgrass 0
setblock ~56~58~11 minecraft:wool 6
fill ~56~61~11 ~57~61~11 minecraft:stained_glass 6
setblock ~57~56~11 minecraft:wool 0
setblock ~57~64~11 minecraft:stained_hardened_clay 14
setblock ~58~56~11 minecraft:stained_glass 6
fill ~58~60~11 ~59~60~12 minecraft:stained_glass 6
setblock ~58~61~11 minecraft:stained_hardened_clay 14
fill ~58~64~11 ~58~64~12 minecraft:stained_glass 6
setblock ~58~65~11 minecraft:stained_glass 6
fill ~59~58~11 ~59~58~12 minecraft:stained_glass 6
fill ~59~61~11 ~59~61~12 minecraft:stained_glass 6
setblock ~59~63~11 minecraft:wool 6
setblock ~60~57~11 minecraft:stained_glass 6
setblock ~60~60~11 minecraft:wool 0
setblock ~60~65~11 minecraft:wool 6
setblock ~60~66~11 minecraft:stained_glass 6
setblock ~61~59~11 minecraft:stained_glass 6
fill ~61~62~11 ~62~62~11 minecraft:stained_glass 6
fill ~61~64~11 ~63~64~11 minecraft:stained_glass 6
setblock ~61~65~11 minecraft:stained_glass 6
setblock ~62~58~11 minecraft:wool 6
setblock ~62~60~11 minecraft:stained_glass 6
setblock ~62~61~11 minecraft:stained_hardened_clay 14
setblock ~62~63~11 minecraft:stained_glass 6
setblock ~62~65~11 minecraft:wool 6
setblock ~63~59~11 minecraft:wool 0
setblock ~63~65~11 minecraft:stained_glass 6
fill ~64~61~11 ~64~62~12 minecraft:stained_glass 6
setblock ~65~58~11 minecraft:stained_glass 6
setblock ~66~57~11 minecraft:stained_glass 6
setblock ~66~58~11 minecraft:stained_hardened_clay 14
fill ~66~61~11 ~68~61~11 minecraft:stained_glass 6
setblock ~66~62~11 minecraft:wool 6
setblock ~66~63~11 minecraft:wool 0
fill ~67~58~11 ~68~58~11 minecraft:stained_glass 6
fill ~67~60~11 ~69~60~11 minecraft:stained_glass 6
fill ~68~62~11 ~69~62~12 minecraft:stained_glass 6
fill ~68~63~11 ~69~63~11 minecraft:stained_glass 6
setblock ~69~61~11 minecraft:wool 6
fill ~14~0~12 ~14~0~45 minecraft:grass
setblock ~17~1~12 minecraft:tallgrass 0
setblock ~18~1~12 minecraft:carpet 6
setblock ~20~54~12 minecraft:wool 6
setblock ~20~56~12 minecraft:wool 6
fill ~20~61~12 ~20~61~13 minecraft:stained_glass 6
fill ~21~53~12 ~21~53~13 minecraft:wool 6
fill ~21~60~12 ~21~60~13 minecraft:stained_glass 6
fill ~22~0~12 ~23~0~12 minecraft:dirt 0
fill ~22~1~12 ~23~1~12 minecraft:log 1
setblock ~22~54~12 minecraft:stained_hardened_clay 14
fill ~22~55~12 ~22~56~12 minecraft:stained_glass 6
fill ~22~58~12 ~22~59~12 minecraft:stained_glass 6
fill ~23~52~12 ~24~52~12 minecraft:stained_glass 6
fill ~23~54~12 ~23~54~13 minecraft:stained_glass 6
fill ~23~56~12 ~24~57~12 minecraft:stained_glass 6
setblock ~23~62~12 minecraft:stained_glass 6
fill ~24~0~12 ~25~0~42 minecraft:grass
fill ~24~55~12 ~24~55~14 minecraft:stained_glass 6
setblock ~24~58~12 minecraft:wool 6
fill ~24~60~12 ~25~60~12 minecraft:stained_glass 6
fill ~24~61~12 ~25~61~12 minecraft:wool 0
setblock ~24~62~12 minecraft:wool 6
setblock ~25~52~12 minecraft:wool 6
setblock ~25~53~12 minecraft:stained_glass 6
setblock ~25~57~12 minecraft:wool 0
fill ~25~58~12 ~25~58~13 minecraft:stained_glass 6
setblock ~25~59~12 minecraft:stained_glass 6
fill ~26~0~12 ~28~0~12 minecraft:dirt 0
fill ~26~1~12 ~28~1~14 minecraft:log 1
fill ~26~2~12 ~27~2~12 minecraft:log 1
fill ~26~57~12 ~27~57~12 minecraft:stained_glass 6
setblock ~26~64~12 minecraft:stained_hardened_clay 14
setblock ~27~55~12 minecraft:stained_glass 6
fill ~27~59~12 ~27~59~13 minecraft:stained_glass 6
setblock ~27~61~12 minecraft:stained_glass 6
setblock ~27~63~12 minecraft:stained_glass 6
fill ~28~52~12 ~29~52~12 minecraft:stained_glass 6
fill ~28~56~12 ~29~56~12 minecraft:stained_glass 6
setblock ~28~58~12 minecraft:stained_glass 6
fill ~28~62~12 ~28~62~13 minecraft:stained_hardened_clay 14
setblock ~28~64~12 minecraft:stained_hardened_clay 14
fill ~29~0~12 ~30~0~18 minecraft:log 1
setblock ~29~53~12 minecraft:stained_glass 6
setblock ~29~59~12 minecraft:wool 6
setblock ~29~61~12 minecraft:stained_glass 6
fill ~29~63~12 ~29~63~13 minecraft:stained_glass 6
setblock ~29~64~12 minecraft:wool 6
setblock ~29~65~12 minecraft:stained_hardened_clay 14
fill ~30~53~12 ~30~53~13 minecraft:stained_hardened_clay 14
setblock ~30~54~12 minecraft:stained_glass 6
setblock ~30~55~12 minecraft:stained_hardened_clay 14
fill ~30~62~12 ~30~62~13 minecraft:stained_glass 6
fill ~30~64~12 ~30~64~13 minecraft:stained_glass 6
setblock ~31~55~12 minecraft:wool 6
setblock ~31~57~12 minecraft:stained_glass 6
fill ~31~60~12 ~31~60~14 minecraft:stained_glass 6
setblock ~31~62~12 minecraft:wool 6
setblock ~32~54~12 minecraft:stained_glass 6
setblock ~32~61~12 minecraft:wool 6
setblock ~32~63~12 minecraft:stained_glass 6
fill ~32~65~12 ~32~65~13 minecraft:stained_glass 6
setblock ~33~53~12 minecraft:wool 0
fill ~33~59~12 ~33~60~13 minecraft:stained_glass 6
setblock ~33~64~12 minecraft:stained_glass 6
fill ~34~52~12 ~35~53~12 minecraft:stained_glass 6
fill ~34~55~12 ~34~55~14 minecraft:stained_glass 6
setblock ~34~57~12 minecraft:stained_glass 6
fill ~34~58~12 ~34~60~12 minecraft:wool 0
setblock ~35~55~12 minecraft:wool 6
fill ~35~58~12 ~35~58~15 minecraft:stained_glass 6
setblock ~35~60~12 minecraft:wool 0
fill ~35~63~12 ~36~64~12 minecraft:stained_glass 6
setblock ~35~65~12 minecraft:stained_glass 6
fill ~36~54~12 ~36~56~12 minecraft:stained_glass 6
setblock ~36~60~12 minecraft:wool 6
setblock ~36~62~12 minecraft:stained_glass 6
setblock ~37~54~12 minecraft:stained_hardened_clay 14
setblock ~37~56~12 minecraft:wool 6
fill ~37~58~12 ~37~58~13 minecraft:stained_glass 6
fill ~37~59~12 ~38~60~12 minecraft:stained_glass 6
setblock ~37~61~12 minecraft:stained_glass 6
fill ~38~1~12 ~40~1~12 minecraft:tallgrass 0
setblock ~38~62~12 minecraft:stained_glass 6
fill ~38~64~12 ~39~64~12 minecraft:wool 0
setblock ~39~57~12 minecraft:wool 6
setblock ~39~58~12 minecraft:stained_glass 6
setblock ~39~60~12 minecraft:wool 6
setblock ~39~63~12 minecraft:stained_glass 6
fill ~39~65~12 ~40~65~12 minecraft:stained_glass 6
setblock ~39~66~12 minecraft:stained_glass 6
fill ~40~57~12 ~41~57~12 minecraft:stained_glass 6
setblock ~40~60~12 minecraft:stained_glass 6
setblock ~40~64~12 minecraft:stained_glass 6
fill ~40~67~12 ~40~67~14 minecraft:stained_glass 6
setblock ~41~62~12 minecraft:wool 6
setblock ~42~61~12 minecraft:stained_glass 6
setblock ~42~62~12 minecraft:wool 0
fill ~42~65~12 ~43~65~12 minecraft:stained_glass 6
setblock ~42~66~12 minecraft:stained_glass 6
setblock ~42~68~12 minecraft:stained_glass 6
setblock ~43~62~12 minecraft:wool 6
setblock ~43~67~12 minecraft:wool 0
fill ~43~69~12 ~43~69~13 minecraft:stained_glass 6
fill ~44~60~12 ~44~60~13 minecraft:wool 0
fill ~44~67~12 ~44~67~14 minecraft:stained_glass 6
fill ~45~59~12 ~45~60~12 minecraft:stained_glass 6
fill ~45~64~12 ~46~64~12 minecraft:stained_glass 6
setblock ~45~65~12 minecraft:wool 6
setblock ~45~66~12 minecraft:stained_glass 6
setblock ~45~67~12 minecraft:stained_hardened_clay 14
setblock ~45~68~12 minecraft:stained_glass 6
fill ~46~62~12 ~46~63~12 minecraft:stained_glass 6
setblock ~46~65~12 minecraft:stained_glass 6
setblock ~46~67~12 minecraft:wool 6
fill ~47~1~12 ~47~1~14 minecraft:tallgrass 0
setblock ~47~61~12 minecraft:stained_glass 6
fill ~47~67~12 ~50~67~12 minecraft:stained_glass 6
setblock ~48~58~12 minecraft:stained_hardened_clay 14
fill ~48~66~12 ~49~66~13 minecraft:stained_glass 6
fill ~49~1~12 ~49~1~14 minecraft:tallgrass 0
setblock ~49~61~12 minecraft:stained_glass 6
setblock ~49~63~12 minecraft:wool 0
fill ~49~64~12 ~50~64~12 minecraft:stained_glass 6
setblock ~49~65~12 minecraft:stained_hardened_clay 14
setblock ~50~1~12 minecraft:double_plant 1
fill ~50~59~12 ~51~60~12 minecraft:stained_glass 6
fill ~50~65~12 ~51~65~12 minecraft:stained_glass 6
fill ~51~1~12 ~52~1~12 minecraft:tallgrass 0
fill ~51~62~12 ~51~63~12 minecraft:stained_glass 6
setblock ~51~64~12 minecraft:wool 0
setblock ~51~66~12 minecraft:stained_glass 6
setblock ~51~68~12 minecraft:stained_glass 6
setblock ~52~58~12 minecraft:wool 6
setblock ~52~64~12 minecraft:stained_hardened_clay 14
fill ~52~67~12 ~52~67~13 minecraft:wool 0
fill ~53~58~12 ~53~59~12 minecraft:wool 0
fill ~53~60~12 ~53~61~12 minecraft:stained_glass 6
setblock ~53~66~12 minecraft:stained_hardened_clay 14
fill ~54~1~12 ~54~1~15 minecraft:tallgrass 0
setblock ~54~61~12 minecraft:wool 0
setblock ~54~65~12 minecraft:wool 0
setblock ~54~66~12 minecraft:stained_glass 6
setblock ~57~1~12 minecraft:double_plant 1
setblock ~57~59~12 minecraft:wool 6
setblock ~57~61~12 minecraft:stained_glass 6
setblock ~57~63~12 minecraft:stained_glass 6
fill ~57~66~12 ~57~66~13 minecraft:stained_glass 6
fill ~58~1~12 ~59~1~13 minecraft:tallgrass 0
fill ~58~62~12 ~58~62~13 minecraft:stained_glass 6
fill ~59~66~12 ~59~66~13 minecraft:stained_glass 6
fill ~60~0~12 ~61~0~16 minecraft:grass
fill ~60~61~12 ~62~61~12 minecraft:stained_glass 6
setblock ~60~62~12 minecraft:wool 6
fill ~60~63~12 ~61~64~12 minecraft:stained_glass 6
setblock ~60~65~12 minecraft:wool 0
setblock ~60~66~12 minecraft:stained_hardened_clay 14
setblock ~61~60~12 minecraft:stained_glass 6
setblock ~62~57~12 minecraft:wool 6
fill ~62~59~12 ~63~59~12 minecraft:stained_glass 6
fill ~62~64~12 ~62~64~14 minecraft:stained_hardened_clay 14
setblock ~62~66~12 minecraft:stained_glass 6
setblock ~63~58~12 minecraft:stained_glass 6
setblock ~63~62~12 minecraft:stained_glass 6
setblock ~63~64~12 minecraft:stained_glass 6
fill ~64~60~12 ~65~60~12 minecraft:stained_glass 6
setblock ~64~66~12 minecraft:wool 6
setblock ~65~61~12 minecraft:stained_hardened_clay 14
setblock ~65~65~12 minecraft:wool 6
fill ~66~61~12 ~66~61~14 minecraft:stained_glass 6
setblock ~66~62~12 minecraft:stained_glass 6
setblock ~66~63~12 minecraft:wool 6
setblock ~67~57~12 minecraft:wool 0
fill ~67~60~12 ~67~60~13 minecraft:stained_glass 6
fill ~67~63~12 ~68~63~13 minecraft:stained_glass 6
setblock ~68~56~12 minecraft:wool 6
fill ~69~59~12 ~69~59~13 minecraft:stained_glass 6
fill ~69~61~12 ~72~61~13 minecraft:stained_glass 6
fill ~69~64~12 ~70~64~12 minecraft:stained_glass 6
setblock ~70~59~12 minecraft:wool 6
fill ~70~62~12 ~70~62~15 minecraft:stained_glass 6
setblock ~70~63~12 minecraft:wool 6
fill ~72~62~12 ~72~62~14 minecraft:stained_glass 6
setblock ~17~1~13 minecraft:double_plant 1
fill ~19~55~13 ~19~55~15 minecraft:stained_glass 6
fill ~19~56~13 ~20~56~13 minecraft:stained_glass 6
fill ~19~60~13 ~20~60~14 minecraft:stained_glass 6
fill ~20~57~13 ~21~57~15 minecraft:stained_glass 6
fill ~20~59~13 ~20~59~15 minecraft:stained_glass 6
fill ~21~0~13 ~23~0~40 minecraft:grass
setblock ~21~1~13 minecraft:tallgrass 0
setblock ~21~54~13 minecraft:stained_glass 6
setblock ~21~55~13 minecraft:wool 0
fill ~21~61~13 ~21~62~13 minecraft:stained_glass 6
setblock ~22~60~13 minecraft:stained_glass 6
setblock ~22~61~13 minecraft:wool 0
setblock ~23~52~13 minecraft:wool 6
fill ~23~57~13 ~24~57~13 minecraft:stained_glass 6
setblock ~23~59~13 minecraft:stained_glass 6
setblock ~23~60~13 minecraft:stained_hardened_clay 14
fill ~24~53~13 ~24~54~13 minecraft:stained_glass 6
fill ~24~56~13 ~24~56~14 minecraft:stained_glass 6
fill ~24~58~13 ~24~58~14 minecraft:stained_glass 6
setblock ~24~60~13 minecraft:stained_glass 6
setblock ~24~62~13 minecraft:stained_glass 6
setblock ~25~54~13 minecraft:stained_glass 6
fill ~25~60~13 ~25~61~13 minecraft:wool 6
fill ~25~63~13 ~25~63~16 minecraft:stained_glass 6
fill ~26~0~13 ~27~0~13 minecraft:dirt 0
fill ~26~55~13 ~26~55~15 minecraft:stained_glass 6
setblock ~26~56~13 minecraft:stained_glass 6
setblock ~26~58~13 minecraft:wool 6
fill ~26~59~13 ~26~59~16 minecraft:stained_glass 6
setblock ~26~60~13 minecraft:stained_glass 6
setblock ~26~62~13 minecraft:stained_glass 6
setblock ~26~63~13 minecraft:wool 0
fill ~27~2~13 ~31~2~14 minecraft:log 1
fill ~27~51~13 ~28~51~13 minecraft:stained_glass 6
fill ~27~53~13 ~28~53~13 minecraft:stained_glass 6
setblock ~27~56~13 minecraft:wool 6
setblock ~27~63~13 minecraft:stained_hardened_clay 14
fill ~27~64~13 ~29~64~13 minecraft:stained_glass 6
fill ~28~0~13 ~28~0~17 minecraft:log 1
fill ~28~56~13 ~28~57~13 minecraft:wool 0
setblock ~28~58~13 minecraft:wool 6
fill ~28~59~13 ~29~59~13 minecraft:stained_glass 6
fill ~28~60~13 ~28~60~15 minecraft:stained_glass 6
setblock ~28~63~13 minecraft:stained_glass 6
fill ~29~55~13 ~29~55~16 minecraft:stained_glass 6
setblock ~29~56~13 minecraft:stained_glass 6
fill ~29~58~13 ~29~58~15 minecraft:stained_glass 6
fill ~29~65~13 ~29~65~15 minecraft:stained_glass 6
fill ~30~51~13 ~31~51~13 minecraft:stained_glass 6
setblock ~30~60~13 minecraft:stained_glass 6
fill ~30~66~13 ~30~66~14 minecraft:stained_glass 6
fill ~31~0~13 ~32~1~19 minecraft:log 1
setblock ~31~53~13 minecraft:stained_glass 6
fill ~31~58~13 ~31~58~14 minecraft:stained_glass 6
fill ~31~61~13 ~31~63~13 minecraft:stained_glass 6
fill ~32~55~13 ~32~55~14 minecraft:wool 0
setblock ~32~57~13 minecraft:wool 6
fill ~32~59~13 ~32~59~14 minecraft:stained_glass 6
setblock ~32~60~13 minecraft:stained_glass 6
setblock ~32~61~13 minecraft:stained_hardened_clay 14
setblock ~32~66~13 minecraft:wool 6
fill ~33~0~13 ~38~0~13 minecraft:grass
setblock ~33~54~13 minecraft:wool 0
setblock ~33~55~13 minecraft:stained_glass 6
setblock ~33~56~13 minecraft:wool 6
setblock ~33~57~13 minecraft:stained_glass 6
setblock ~33~61~13 minecraft:wool 6
setblock ~34~1~13 minecraft:tallgrass 0
fill ~34~54~13 ~35~54~13 minecraft:stained_glass 6
fill ~34~59~13 ~35~59~13 minecraft:stained_glass 6
fill ~34~61~13 ~34~61~17 minecraft:stained_glass 6
fill ~35~55~13 ~38~55~13 minecraft:stained_glass 6
setblock ~35~57~13 minecraft:stained_glass 6
setblock ~35~60~13 minecraft:stained_hardened_clay 14
setblock ~35~63~13 minecraft:stained_glass 6
setblock ~36~52~13 minecraft:stained_glass 6
fill ~36~56~13 ~36~56~14 minecraft:stained_glass 6
fill ~36~60~13 ~37~60~13 minecraft:stained_glass 6
setblock ~36~61~13 minecraft:stained_glass 6
fill ~37~62~13 ~37~62~15 minecraft:stained_glass 6
fill ~38~1~13 ~38~1~14 minecraft:tallgrass 0
fill ~38~56~13 ~39~56~13 minecraft:stained_glass 6
fill ~38~57~13 ~38~57~14 minecraft:stained_glass 6
setblock ~38~59~13 minecraft:stained_glass 6
setblock ~38~63~13 minecraft:stained_hardened_clay 14
setblock ~39~59~13 minecraft:wool 6
fill ~39~60~13 ~39~60~15 minecraft:stained_glass 6
setblock ~39~61~13 minecraft:wool 6
setblock ~39~64~13 minecraft:stained_glass 6
fill ~40~1~13 ~41~1~13 minecraft:tallgrass 0
setblock ~40~57~13 minecraft:stained_glass 6
fill ~40~61~13 ~41~61~13 minecraft:stained_glass 6
setblock ~40~63~13 minecraft:wool 6
setblock ~40~66~13 minecraft:stained_hardened_clay 14
fill ~41~58~13 ~42~58~13 minecraft:stained_glass 6
fill ~41~60~13 ~42~60~13 minecraft:stained_glass 6
fill ~41~64~13 ~41~65~13 minecraft:stained_hardened_clay 14
setblock ~41~66~13 minecraft:wool 6
fill ~41~68~13 ~41~68~14 minecraft:stained_glass 6
setblock ~42~1~13 minecraft:double_plant 1
setblock ~42~56~13 minecraft:stained_glass 6
fill ~42~59~13 ~43~59~13 minecraft:stained_glass 6
setblock ~42~61~13 minecraft:stained_hardened_clay 14
setblock ~42~62~13 minecraft:stained_glass 6
setblock ~42~66~13 minecraft:stained_hardened_clay 14
setblock ~43~1~13 minecraft:carpet 6
setblock ~43~60~13 minecraft:wool 0
setblock ~43~63~13 minecraft:wool 6
setblock ~43~64~13 minecraft:stained_glass 6
setblock ~43~67~13 minecraft:stained_glass 6
setblock ~45~1~13 minecraft:tallgrass 0
setblock ~45~60~13 minecraft:wool 6
fill ~45~61~13 ~45~62~13 minecraft:stained_glass 6
fill ~46~60~13 ~46~60~14 minecraft:stained_glass 6
setblock ~46~61~13 minecraft:wool 6
fill ~46~67~13 ~47~67~13 minecraft:stained_glass 6
fill ~47~59~13 ~48~59~13 minecraft:stained_glass 6
setblock ~47~60~13 minecraft:stained_hardened_clay 14
fill ~47~62~13 ~47~62~15 minecraft:stained_glass 6
fill ~47~64~13 ~48~64~13 minecraft:stained_glass 6
setblock ~47~66~13 minecraft:stained_glass 6
fill ~48~60~13 ~48~61~14 minecraft:stained_glass 6
setblock ~49~59~13 minecraft:stained_hardened_clay 14
fill ~49~62~13 ~49~62~15 minecraft:stained_glass 6
setblock ~49~63~13 minecraft:stained_glass 6
setblock ~49~65~13 minecraft:wool 6
fill ~49~67~13 ~49~68~13 minecraft:wool 0
setblock ~50~60~13 minecraft:stained_glass 6
setblock ~50~64~13 minecraft:stained_hardened_clay 14
fill ~50~65~13 ~50~65~14 minecraft:stained_glass 6
setblock ~50~67~13 minecraft:stained_hardened_clay 14
fill ~50~68~13 ~50~69~13 minecraft:stained_glass 6
setblock ~51~1~13 minecraft:double_plant 2
fill ~51~58~13 ~51~59~13 minecraft:stained_glass 6
setblock ~51~61~13 minecraft:wool 0
setblock ~51~63~13 minecraft:stained_glass 6
setblock ~51~65~13 minecraft:wool 6
setblock ~51~67~13 minecraft:stained_glass 6
fill ~52~1~13 ~53~1~14 minecraft:tallgrass 0
setblock ~52~59~13 minecraft:wool 0
setblock ~52~60~13 minecraft:stained_glass 6
fill ~52~64~13 ~52~64~14 minecraft:stained_glass 6
setblock ~52~65~13 minecraft:stained_glass 6
setblock ~52~69~13 minecraft:stained_glass 6
setblock ~53~59~13 minecraft:stained_glass 6
setblock ~53~61~13 minecraft:stained_glass 6
fill ~54~62~13 ~54~62~14 minecraft:stained_glass 6
setblock ~54~64~13 minecraft:stained_glass 6
setblock ~54~65~13 minecraft:wool 6
fill ~55~1~13 ~57~1~13 minecraft:tallgrass 0
fill ~55~60~13 ~55~60~14 minecraft:stained_glass 6
fill ~56~64~13 ~56~65~13 minecraft:stained_hardened_clay 14
setblock ~57~63~13 minecraft:wool 0
fill ~57~64~13 ~57~65~13 minecraft:stained_glass 6
setblock ~58~64~13 minecraft:stained_hardened_clay 14
fill ~58~66~13 ~58~67~13 minecraft:stained_glass 6
setblock ~59~60~13 minecraft:stained_glass 6
setblock ~59~65~13 minecraft:stained_glass 6
fill ~60~58~13 ~61~58~13 minecraft:stained_glass 6
setblock ~60~59~13 minecraft:stained_hardened_clay 14
setblock ~60~61~13 minecraft:stained_glass 6
fill ~60~63~13 ~60~63~14 minecraft:stained_glass 6
fill ~60~67~13 ~60~67~14 minecraft:wool 6
setblock ~61~1~13 minecraft:tallgrass 0
setblock ~61~62~13 minecraft:stained_hardened_clay 14
setblock ~61~64~13 minecraft:wool 0
fill ~61~65~13 ~61~66~13 minecraft:stained_glass 6
fill ~62~0~13 ~62~0~18 minecraft:grass
setblock ~62~59~13 minecraft:wool 0
setblock ~62~61~13 minecraft:wool 6
fill ~63~59~13 ~63~61~13 minecraft:stained_glass 6
setblock ~63~62~13 minecraft:wool 6
fill ~63~66~13 ~64~66~13 minecraft:stained_glass 6
setblock ~64~60~13 minecraft:wool 0
setblock ~64~62~13 minecraft:stained_glass 6
setblock ~65~59~13 minecraft:stained_glass 6
setblock ~65~60~13 minecraft:wool 6
fill ~65~63~13 ~65~65~13 minecraft:stained_glass 6
setblock ~66~57~13 minecraft:stained_glass 6
setblock ~66~62~13 minecraft:stained_hardened_clay 14
fill ~67~56~13 ~68~56~13 minecraft:stained_glass 6
fill ~68~58~13 ~69~58~13 minecraft:stained_glass 6
fill ~68~59~13 ~68~59~16 minecraft:stained_glass 6
setblock ~68~62~13 minecraft:stained_glass 6
fill ~68~65~13 ~69~65~13 minecraft:stained_glass 6
setblock ~69~63~13 minecraft:wool 0
setblock ~70~58~13 minecraft:stained_hardened_clay 14
fill ~70~59~13 ~70~60~13 minecraft:stained_glass 6
fill ~71~57~13 ~72~57~13 minecraft:stained_glass 6
setblock ~71~58~13 minecraft:stained_glass 6
fill ~71~62~13 ~71~62~14 minecraft:stained_glass 6
setblock ~72~59~13 minecraft:stained_glass 6
setblock ~72~60~13 minecraft:wool 0
fill ~72~64~13 ~73~64~13 minecraft:stained_glass 6
setblock ~73~57~13 minecraft:wool 0
setblock ~73~59~13 minecraft:stained_hardened_clay 14
fill ~17~1~14 ~18~1~15 minecraft:tallgrass 0
fill ~17~56~14 ~17~57~16 minecraft:stained_glass 6
fill ~18~53~14 ~20~53~14 minecraft:stained_glass 6
setblock ~18~55~14 minecraft:stained_glass 6
fill ~18~58~14 ~19~59~14 minecraft:stained_glass 6
fill ~19~54~14 ~19~54~15 minecraft:stained_glass 6
fill ~20~55~14 ~21~55~15 minecraft:stained_glass 6
fill ~20~56~14 ~21~56~14 minecraft:stained_glass 6
setblock ~21~53~14 minecraft:wool 0
setblock ~21~58~14 minecraft:stained_hardened_clay 14
setblock ~21~60~14 minecraft:wool 0
fill ~21~62~14 ~22~62~14 minecraft:stained_glass 6
setblock ~22~53~14 minecraft:stained_glass 6
setblock ~22~54~14 minecraft:wool 6
fill ~22~57~14 ~23~58~14 minecraft:stained_glass 6
setblock ~22~59~14 minecraft:stained_glass 6
fill ~22~61~14 ~23~61~15 minecraft:stained_glass 6
setblock ~23~55~14 minecraft:stained_glass 6
setblock ~23~59~14 minecraft:wool 0
fill ~24~54~14 ~24~54~15 minecraft:stained_glass 6
setblock ~25~55~14 minecraft:stained_glass 6
setblock ~25~61~14 minecraft:stained_glass 6
setblock ~26~0~14 minecraft:dirt 0
fill ~26~57~14 ~27~57~14 minecraft:stained_glass 6
fill ~26~58~14 ~26~58~17 minecraft:stained_glass 6
setblock ~26~61~14 minecraft:wool 6
fill ~27~0~14 ~27~0~16 minecraft:log 1
setblock ~27~51~14 minecraft:wool 0
fill ~27~52~14 ~27~52~15 minecraft:stained_glass 6
fill ~27~54~14 ~27~55~14 minecraft:stained_glass 6
setblock ~27~59~14 minecraft:wool 6
fill ~27~62~14 ~28~62~14 minecraft:stained_glass 6
setblock ~28~50~14 minecraft:stained_glass 6
fill ~28~53~14 ~28~53~16 minecraft:stained_glass 6
fill ~28~55~14 ~28~56~16 minecraft:stained_glass 6
setblock ~28~61~14 minecraft:stained_hardened_clay 14
fill ~28~64~14 ~28~64~15 minecraft:wool 0
fill ~29~51~14 ~29~52~15 minecraft:stained_glass 6
fill ~29~54~14 ~29~54~15 minecraft:stained_glass 6
setblock ~29~56~14 minecraft:wool 6
setblock ~29~59~14 minecraft:stained_glass 6
fill ~29~61~14 ~29~61~15 minecraft:stained_glass 6
fill ~29~64~14 ~29~64~16 minecraft:stained_glass 6
setblock ~30~53~14 minecraft:stained_glass 6
fill ~30~56~14 ~30~58~14 minecraft:stained_glass 6
setblock ~30~63~14 minecraft:stained_hardened_clay 14
fill ~31~51~14 ~31~52~14 minecraft:stained_glass 6
setblock ~31~53~14 minecraft:wool 6
fill ~31~54~14 ~31~55~14 minecraft:stained_glass 6
fill ~31~57~14 ~32~57~14 minecraft:stained_glass 6
fill ~31~63~14 ~32~63~15 minecraft:stained_glass 6
fill ~31~65~14 ~31~65~16 minecraft:stained_glass 6
fill ~32~2~14 ~32~2~22 minecraft:log 1
fill ~32~53~14 ~33~53~14 minecraft:stained_glass 6
setblock ~32~54~14 minecraft:stained_hardened_clay 14
setblock ~32~56~14 minecraft:stained_glass 6
setblock ~32~61~14 minecraft:wool 6
fill ~32~64~14 ~33~64~14 minecraft:stained_glass 6
setblock ~32~65~14 minecraft:stained_hardened_clay 14
fill ~32~66~14 ~32~66~15 minecraft:stained_glass 6
fill ~33~0~14 ~33~1~21 minecraft:log 1
setblock ~33~58~14 minecraft:stained_glass 6
fill ~33~62~14 ~33~63~14 minecraft:wool 6
fill ~34~0~14 ~38~0~14 minecraft:grass
setblock ~34~52~14 minecraft:stained_glass 6
setblock ~34~60~14 minecraft:wool 6
fill ~34~62~14 ~34~62~16 minecraft:stained_glass 6
setblock ~34~63~14 minecraft:stained_glass 6
setblock ~35~53~14 minecraft:wool 6
setblock ~35~55~14 minecraft:stained_glass 6
setblock ~35~57~14 minecraft:wool 0
setblock ~35~64~14 minecraft:stained_glass 6
fill ~36~57~14 ~37~57~14 minecraft:stained_glass 6
setblock ~36~58~14 minecraft:stained_glass 6
setblock ~36~60~14 minecraft:stained_glass 6
fill ~36~63~14 ~36~63~15 minecraft:stained_glass 6
fill ~37~54~14 ~38~54~14 minecraft:stained_glass 6
setblock ~37~64~14 minecraft:stained_glass 6
fill ~38~55~14 ~38~56~14 minecraft:stained_glass 6
fill ~38~58~14 ~39~58~14 minecraft:stained_glass 6
setblock ~38~60~14 minecraft:stained_glass 6
setblock ~38~62~14 minecraft:stained_glass 6
setblock ~39~1~14 minecraft:tallgrass 0
setblock ~39~55~14 minecraft:stained_hardened_clay 14
setblock ~39~61~14 minecraft:stained_glass 6
fill ~39~63~14 ~41~63~15 minecraft:stained_glass 6
setblock ~39~65~14 minecraft:stained_glass 6
fill ~40~56~14 ~41~56~15 minecraft:stained_glass 6
setblock ~40~58~14 minecraft:wool 0
setblock ~40~60~14 minecraft:stained_hardened_clay 14
setblock ~40~64~14 minecraft:stained_glass 6
fill ~40~65~14 ~40~65~15 minecraft:stained_hardened_clay 14
fill ~40~66~14 ~41~66~14 minecraft:stained_glass 6
fill ~41~1~14 ~41~1~17 minecraft:tallgrass 0
fill ~41~57~14 ~41~57~15 minecraft:stained_glass 6
setblock ~41~58~14 minecraft:wool 6
fill ~41~59~14 ~41~59~17 minecraft:stained_glass 6
fill ~41~60~14 ~41~60~15 minecraft:stained_glass 6
setblock ~41~62~14 minecraft:wool 0
setblock ~42~65~14 minecraft:stained_hardened_clay 14
fill ~42~67~14 ~42~67~15 minecraft:stained_glass 6
setblock ~42~68~14 minecraft:stained_hardened_clay 14
fill ~43~1~14 ~44~1~15 minecraft:tallgrass 0
fill ~43~60~14 ~44~60~14 minecraft:stained_glass 6
fill ~43~61~14 ~43~62~14 minecraft:stained_glass 6
setblock ~43~64~14 minecraft:stained_hardened_clay 14
fill ~43~68~14 ~46~68~14 minecraft:stained_glass 6
fill ~44~57~14 ~44~59~14 minecraft:stained_glass 6
setblock ~44~64~14 minecraft:stained_glass 6
setblock ~45~61~14 minecraft:wool 0
setblock ~45~62~14 minecraft:wool 6
fill ~45~66~14 ~46~66~14 minecraft:stained_glass 6
fill ~46~1~14 ~46~1~16 minecraft:tallgrass 0
fill ~46~59~14 ~46~59~15 minecraft:stained_glass 6
fill ~46~61~14 ~46~61~15 minecraft:stained_glass 6
setblock ~46~62~14 minecraft:stained_glass 6
setblock ~46~63~14 minecraft:wool 6
fill ~47~60~14 ~47~60~17 minecraft:stained_glass 6
fill ~47~63~14 ~48~63~14 minecraft:stained_glass 6
setblock ~48~1~14 minecraft:tallgrass 0
fill ~48~62~14 ~48~62~15 minecraft:stained_glass 6
setblock ~48~65~14 minecraft:wool 0
fill ~49~65~14 ~49~66~14 minecraft:stained_glass 6
fill ~49~68~14 ~49~69~14 minecraft:wool 0
setblock ~50~61~14 minecraft:stained_hardened_clay 14
fill ~50~68~14 ~50~68~15 minecraft:wool 6
setblock ~51~1~14 minecraft:tallgrass 0
setblock ~51~59~14 minecraft:wool 0
fill ~51~60~14 ~51~60~15 minecraft:stained_glass 6
setblock ~51~64~14 minecraft:stained_glass 6
fill ~51~68~14 ~52~68~14 minecraft:stained_glass 6
fill ~51~69~14 ~51~70~15 minecraft:stained_glass 6
fill ~52~61~14 ~52~62~15 minecraft:stained_glass 6
setblock ~52~66~14 minecraft:wool 6
fill ~52~70~14 ~52~70~15 minecraft:stained_glass 6
setblock ~53~58~14 minecraft:wool 6
setblock ~53~59~14 minecraft:wool 0
fill ~53~63~14 ~54~63~14 minecraft:stained_glass 6
fill ~53~65~14 ~55~65~14 minecraft:stained_glass 6
fill ~53~66~14 ~53~66~15 minecraft:stained_glass 6
setblock ~53~68~14 minecraft:wool 0
setblock ~53~69~14 minecraft:stained_glass 6
setblock ~54~60~14 minecraft:wool 6
fill ~54~61~14 ~55~61~14 minecraft:stained_glass 6
setblock ~55~1~14 minecraft:carpet 6
fill ~55~62~14 ~55~62~15 minecraft:wool 0
setblock ~55~66~14 minecraft:wool 0
fill ~55~67~14 ~55~67~15 minecraft:stained_glass 6
fill ~56~1~14 ~58~1~15 minecraft:tallgrass 0
fill ~56~62~14 ~57~62~15 minecraft:stained_glass 6
setblock ~56~64~14 minecraft:stained_glass 6
fill ~57~61~14 ~57~61~15 minecraft:stained_glass 6
fill ~57~63~14 ~59~63~14 minecraft:stained_glass 6
setblock ~57~64~14 minecraft:wool 0
setblock ~57~65~14 minecraft:stained_hardened_clay 14
setblock ~58~64~14 minecraft:wool 6
fill ~58~67~14 ~58~67~15 minecraft:stained_glass 6
setblock ~59~65~14 minecraft:stained_hardened_clay 14
fill ~60~59~14 ~62~59~14 minecraft:stained_glass 6
setblock ~60~62~14 minecraft:stained_glass 6
fill ~60~64~14 ~61~64~14 minecraft:stained_glass 6
fill ~60~65~14 ~60~65~16 minecraft:stained_glass 6
fill ~60~66~14 ~60~66~15 minecraft:stained_glass 6
setblock ~61~1~14 minecraft:carpet 6
fill ~61~63~14 ~61~63~15 minecraft:stained_glass 6
setblock ~61~66~14 minecraft:stained_hardened_clay 14
setblock ~62~1~14 minecraft:tallgrass 0
fill ~62~60~14 ~62~61~15 minecraft:stained_glass 6
fill ~63~0~14 ~63~0~18 minecraft:grass
setblock ~63~61~14 minecraft:stained_glass 6
setblock ~63~62~14 minecraft:wool 0
fill ~63~63~14 ~63~63~16 minecraft:stained_glass 6
setblock ~63~64~14 minecraft:wool 6
setblock ~63~65~14 minecraft:stained_hardened_clay 14
fill ~64~58~14 ~65~58~14 minecraft:stained_glass 6
setblock ~64~60~14 minecraft:stained_glass 6
setblock ~65~57~14 minecraft:wool 0
setblock ~65~61~14 minecraft:wool 6
setblock ~65~63~14 minecraft:stained_hardened_clay 14
fill ~65~64~14 ~66~64~14 minecraft:stained_glass 6
fill ~65~65~14 ~65~65~15 minecraft:stained_glass 6
fill ~66~63~14 ~66~63~15 minecraft:stained_glass 6
fill ~67~58~14 ~67~58~16 minecraft:stained_glass 6
setblock ~67~59~14 minecraft:stained_glass 6
setblock ~67~60~14 minecraft:wool 6
setblock ~67~61~14 minecraft:wool 0
fill ~67~62~14 ~67~62~15 minecraft:stained_glass 6
setblock ~67~64~14 minecraft:wool 6
setblock ~67~65~14 minecraft:stained_glass 6
fill ~68~60~14 ~69~60~14 minecraft:stained_glass 6
setblock ~68~61~14 minecraft:stained_glass 6
setblock ~68~64~14 minecraft:stained_glass 6
fill ~69~65~14 ~69~65~15 minecraft:stained_glass 6
setblock ~70~56~14 minecraft:stained_glass 6
setblock ~71~60~14 minecraft:stained_glass 6
setblock ~71~64~14 minecraft:stained_hardened_clay 14
setblock ~72~57~14 minecraft:wool 0
fill ~72~58~14 ~73~58~14 minecraft:stained_glass 6
setblock ~72~61~14 minecraft:stained_glass 6
fill ~72~63~14 ~72~63~17 minecraft:stained_glass 6
setblock ~73~57~14 minecraft:stained_hardened_clay 14
fill ~73~60~14 ~74~60~15 minecraft:stained_glass 6
fill ~73~62~14 ~74~62~14 minecraft:stained_glass 6
setblock ~73~64~14 minecraft:stained_hardened_clay 14
fill ~74~57~14 ~74~57~15 minecraft:stained_glass 6
setblock ~74~58~14 minecraft:stained_hardened_clay 14
fill ~74~59~14 ~74~59~15 minecraft:stained_glass 6
fill ~12~56~15 ~13~57~15 minecraft:stained_glass 6
fill ~13~58~15 ~13~58~16 minecraft:stained_glass 6
setblock ~14~59~15 minecraft:stained_glass 6
fill ~15~58~15 ~15~58~18 minecraft:stained_glass 6
setblock ~15~59~15 minecraft:wool 6
setblock ~16~55~15 minecraft:stained_glass 6
setblock ~16~56~15 minecraft:wool 0
setblock ~16~58~15 minecraft:wool 0
setblock ~17~55~15 minecraft:wool 6
fill ~17~61~15 ~18~61~15 minecraft:stained_glass 6
setblock ~18~54~15 minecraft:wool 0
fill ~18~56~15 ~18~56~16 minecraft:wool 0
fill ~18~57~15 ~19~57~15 minecraft:stained_glass 6
fill ~19~52~15 ~19~53~15 minecraft:stained_glass 6
setblock ~20~52~15 minecraft:wool 6
setblock ~20~54~15 minecraft:stained_hardened_clay 14
fill ~20~58~15 ~22~58~15 minecraft:stained_glass 6
setblock ~20~60~15 minecraft:stained_glass 6
fill ~21~1~15 ~21~1~16 minecraft:tallgrass 0
setblock ~22~54~15 minecraft:stained_hardened_clay 14
fill ~22~56~15 ~22~56~16 minecraft:stained_glass 6
setblock ~23~54~15 minecraft:stained_glass 6
setblock ~23~57~15 minecraft:stained_hardened_clay 14
setblock ~23~58~15 minecraft:wool 0
fill ~23~59~15 ~23~60~15 minecraft:stained_glass 6
setblock ~24~59~15 minecraft:stained_hardened_clay 14
setblock ~24~60~15 minecraft:wool 6
fill ~25~56~15 ~27~56~15 minecraft:stained_glass 6
fill ~25~57~15 ~25~58~15 minecraft:stained_glass 6
fill ~25~62~15 ~26~62~15 minecraft:stained_glass 6
fill ~26~0~15 ~26~0~42 minecraft:grass
setblock ~26~53~15 minecraft:stained_glass 6
setblock ~26~63~15 minecraft:stained_glass 6
fill ~27~1~15 ~28~1~16 minecraft:log 1
setblock ~27~51~15 minecraft:stained_glass 6
setblock ~27~53~15 minecraft:wool 0
setblock ~27~57~15 minecraft:stained_glass 6
setblock ~27~60~15 minecraft:stained_glass 6
setblock ~27~65~15 minecraft:stained_glass 6
fill ~28~2~15 ~31~2~15 minecraft:log 1
setblock ~28~50~15 minecraft:wool 0
setblock ~28~52~15 minecraft:stained_glass 6
fill ~28~59~15 ~28~59~16 minecraft:stained_glass 6
fill ~28~61~15 ~28~63~15 minecraft:stained_glass 6
setblock ~29~53~15 minecraft:stained_glass 6
setblock ~29~57~15 minecraft:stained_glass 6
setblock ~29~60~15 minecraft:stained_glass 6
setblock ~30~50~15 minecraft:stained_glass 6
setblock ~30~52~15 minecraft:stained_glass 6
setblock ~30~54~15 minecraft:stained_glass 6
fill ~30~55~15 ~30~56~15 minecraft:wool 6
fill ~30~58~15 ~30~59~15 minecraft:stained_glass 6
fill ~30~63~15 ~30~65~15 minecraft:stained_glass 6
setblock ~31~53~15 minecraft:stained_glass 6
setblock ~31~54~15 minecraft:wool 6
setblock ~31~55~15 minecraft:stained_glass 6
fill ~31~61~15 ~31~62~15 minecraft:stained_glass 6
setblock ~31~66~15 minecraft:wool 0
setblock ~32~52~15 minecraft:stained_glass 6
fill ~32~54~15 ~32~54~16 minecraft:stained_glass 6
fill ~32~60~15 ~33~60~15 minecraft:stained_glass 6
fill ~32~62~15 ~33~62~16 minecraft:stained_glass 6
setblock ~32~65~15 minecraft:wool 6
fill ~33~2~15 ~34~2~24 minecraft:log 1
setblock ~33~53~15 minecraft:wool 6
fill ~33~59~15 ~34~59~15 minecraft:stained_glass 6
setblock ~33~61~15 minecraft:wool 0
setblock ~33~64~15 minecraft:stained_glass 6
fill ~34~0~15 ~34~1~26 minecraft:log 1
fill ~34~54~15 ~35~54~15 minecraft:stained_glass 6
setblock ~34~58~15 minecraft:stained_glass 6
setblock ~34~64~15 minecraft:stained_hardened_clay 14
fill ~35~0~15 ~38~0~15 minecraft:grass
setblock ~35~60~15 minecraft:stained_glass 6
setblock ~35~63~15 minecraft:stained_glass 6
fill ~35~65~15 ~38~65~15 minecraft:stained_glass 6
fill ~36~1~15 ~36~1~16 minecraft:tallgrass 0
fill ~36~55~15 ~37~55~15 minecraft:stained_glass 6
fill ~36~59~15 ~36~59~17 minecraft:stained_glass 6
setblock ~36~61~15 minecraft:stained_glass 6
setblock ~36~62~15 minecraft:wool 6
setblock ~36~64~15 minecraft:stained_glass 6
setblock ~37~53~15 minecraft:stained_glass 6
fill ~37~56~15 ~38~56~16 minecraft:stained_glass 6
fill ~37~57~15 ~37~57~18 minecraft:stained_glass 6
fill ~37~58~15 ~37~58~16 minecraft:stained_glass 6
setblock ~37~64~15 minecraft:wool 6
fill ~38~63~15 ~38~64~15 minecraft:stained_glass 6
setblock ~38~66~15 minecraft:stained_hardened_clay 14
fill ~38~67~15 ~38~67~16 minecraft:stained_glass 6
setblock ~39~1~15 minecraft:double_plant 2
setblock ~39~55~15 minecraft:wool 0
setblock ~39~64~15 minecraft:wool 0
fill ~40~1~15 ~40~1~17 minecraft:tallgrass 0
setblock ~40~55~15 minecraft:stained_glass 6
setblock ~40~60~15 minecraft:stained_glass 6
fill ~41~62~15 ~43~62~15 minecraft:stained_glass 6
setblock ~41~67~15 minecraft:stained_glass 6
fill ~42~59~15 ~42~59~16 minecraft:stained_glass 6
setblock ~42~60~15 minecraft:stained_glass 6
fill ~42~63~15 ~43~63~15 minecraft:stained_glass 6
fill ~42~64~15 ~42~64~16 minecraft:stained_glass 6
fill ~43~56~15 ~43~56~18 minecraft:stained_glass 6
setblock ~43~58~15 minecraft:stained_glass 6
fill ~43~59~15 ~43~60~15 minecraft:wool 0
setblock ~43~61~15 minecraft:wool 6
setblock ~43~65~15 minecraft:wool 6
fill ~43~66~15 ~44~66~15 minecraft:stained_glass 6
fill ~43~67~15 ~43~67~16 minecraft:stained_glass 6
fill ~44~59~15 ~45~59~16 minecraft:stained_glass 6
fill ~44~60~15 ~44~61~15 minecraft:stained_glass 6
fill ~44~65~15 ~45~65~15 minecraft:stained_glass 6
fill ~45~1~15 ~45~1~16 minecraft:tallgrass 0
setblock ~45~62~15 minecraft:stained_glass 6
fill ~45~64~15 ~45~64~16 minecraft:stained_glass 6
fill ~45~68~15 ~45~68~16 minecraft:stained_glass 6
setblock ~46~63~15 minecraft:wool 0
fill ~46~67~15 ~46~67~17 minecraft:stained_glass 6
setblock ~46~68~15 minecraft:wool 6
setblock ~47~1~15 minecraft:double_plant 1
fill ~47~63~15 ~47~64~15 minecraft:stained_glass 6
fill ~47~65~15 ~47~65~16 minecraft:stained_hardened_clay 14
fill ~48~61~15 ~50~61~15 minecraft:stained_glass 6
fill ~48~67~15 ~48~67~20 minecraft:stained_glass 6
fill ~49~60~15 ~50~60~15 minecraft:stained_glass 6
setblock ~49~63~15 minecraft:wool 6
setblock ~50~1~15 minecraft:tallgrass 0
fill ~50~59~15 ~51~59~16 minecraft:stained_glass 6
setblock ~50~66~15 minecraft:wool 6
setblock ~50~67~15 minecraft:stained_glass 6
setblock ~50~70~15 minecraft:stained_glass 6
fill ~51~62~15 ~51~62~16 minecraft:stained_glass 6
setblock ~52~1~15 minecraft:double_plant 1
fill ~52~60~15 ~54~60~15 minecraft:stained_glass 6
setblock ~52~63~15 minecraft:stained_hardened_clay 14
setblock ~53~1~15 minecraft:tallgrass 0
setblock ~53~63~15 minecraft:stained_glass 6
setblock ~54~61~15 minecraft:stained_glass 6
setblock ~54~66~15 minecraft:stained_hardened_clay 14
setblock ~54~67~15 minecraft:stained_glass 6
setblock ~54~68~15 minecraft:wool 0
setblock ~55~1~15 minecraft:tallgrass 0
setblock ~55~60~15 minecraft:wool 6
fill ~56~60~15 ~57~60~15 minecraft:stained_glass 6
setblock ~56~63~15 minecraft:stained_glass 6
setblock ~56~65~15 minecraft:wool 6
setblock ~56~66~15 minecraft:stained_glass 6
fill ~57~65~15 ~57~65~16 minecraft:stained_glass 6
fill ~58~61~15 ~61~61~15 minecraft:stained_glass 6
setblock ~58~62~15 minecraft:stained_glass 6
setblock ~58~63~15 minecraft:stained_hardened_clay 14
setblock ~58~64~15 minecraft:stained_glass 6
setblock ~59~63~15 minecraft:stained_glass 6
setblock ~60~1~15 minecraft:double_plant 1
setblock ~60~60~15 minecraft:stained_glass 6
fill ~61~60~15 ~61~60~17 minecraft:wool 6
setblock ~61~64~15 minecraft:stained_hardened_clay 14
setblock ~61~65~15 minecraft:wool 0
fill ~62~63~15 ~62~65~15 minecraft:stained_glass 6
fill ~63~1~15 ~64~1~16 minecraft:tallgrass 0
setblock ~63~62~15 minecraft:stained_glass 6
fill ~63~64~15 ~63~64~20 minecraft:stained_glass 6
fill ~63~65~15 ~64~65~15 minecraft:stained_glass 6
fill ~64~0~15 ~64~0~20 minecraft:grass
fill ~65~57~15 ~66~57~15 minecraft:stained_glass 6
fill ~65~58~15 ~65~59~15 minecraft:stained_glass 6
fill ~66~58~15 ~66~58~16 minecraft:wool 0
fill ~66~59~15 ~66~60~16 minecraft:stained_glass 6
setblock ~66~64~15 minecraft:stained_glass 6
fill ~67~60~15 ~68~60~15 minecraft:stained_glass 6
setblock ~67~61~15 minecraft:stained_glass 6
fill ~68~57~15 ~68~58~15 minecraft:stained_glass 6
fill ~68~62~15 ~68~62~16 minecraft:stained_glass 6
setblock ~68~65~15 minecraft:stained_hardened_clay 14
setblock ~69~57~15 minecraft:wool 6
setblock ~69~59~15 minecraft:wool 0
setblock ~69~63~15 minecraft:stained_glass 6
fill ~70~57~15 ~70~57~16 minecraft:stained_glass 6
fill ~70~58~15 ~71~58~15 minecraft:stained_glass 6
fill ~70~60~15 ~70~61~15 minecraft:stained_glass 6
setblock ~70~63~15 minecraft:wool 0
setblock ~70~64~15 minecraft:wool 6
fill ~70~65~15 ~72~65~15 minecraft:stained_glass 6
setblock ~71~55~15 minecraft:wool 0
fill ~72~56~15 ~74~56~15 minecraft:stained_glass 6
setblock ~72~57~15 minecraft:stained_glass 6
setblock ~72~59~15 minecraft:stained_glass 6
fill ~72~64~15 ~73~64~15 minecraft:stained_glass 6
setblock ~73~55~15 minecraft:stained_glass 6
setblock ~74~63~15 minecraft:stained_glass 6
setblock ~75~57~15 minecraft:stained_glass 6
fill ~75~61~15 ~75~61~16 minecraft:stained_glass 6
setblock ~75~62~15 minecraft:stained_hardened_clay 14
fill ~11~57~16 ~12~57~16 minecraft:stained_hardened_clay 14
setblock ~11~58~16 minecraft:stained_glass 6
setblock ~12~55~16 minecraft:stained_glass 6
setblock ~13~57~16 minecraft:stained_glass 6
setblock ~13~60~16 minecraft:stained_glass 6
fill ~14~56~16 ~16~56~16 minecraft:stained_glass 6
fill ~15~1~16 ~16~1~16 minecraft:tallgrass 0
setblock ~15~60~16 minecraft:stained_glass 6
setblock ~16~57~16 minecraft:stained_glass 6
setblock ~17~58~16 minecraft:wool 0
fill ~17~59~16 ~17~59~17 minecraft:stained_glass 6
setblock ~17~60~16 minecraft:wool 6
fill ~17~61~16 ~17~62~16 minecraft:stained_glass 6
setblock ~18~54~16 minecraft:stained_hardened_clay 14
setblock ~18~58~16 minecraft:stained_hardened_clay 14
setblock ~18~61~16 minecraft:stained_hardened_clay 14
fill ~19~53~16 ~19~53~17 minecraft:stained_glass 6
fill ~19~56~16 ~20~56~16 minecraft:stained_glass 6
setblock ~19~59~16 minecraft:stained_glass 6
setblock ~19~61~16 minecraft:wool 0
fill ~20~51~16 ~20~51~18 minecraft:stained_glass 6
setblock ~20~52~16 minecraft:wool 0
setblock ~20~58~16 minecraft:stained_glass 6
setblock ~20~61~16 minecraft:wool 6
setblock ~21~53~16 minecraft:stained_glass 6
fill ~21~55~16 ~24~55~16 minecraft:stained_glass 6
fill ~21~57~16 ~21~57~17 minecraft:stained_hardened_clay 14
setblock ~22~52~16 minecraft:stained_glass 6
setblock ~22~57~16 minecraft:wool 0
setblock ~22~59~16 minecraft:stained_glass 6
setblock ~23~1~16 minecraft:carpet 6
fill ~23~57~16 ~24~57~17 minecraft:stained_glass 6
fill ~23~58~16 ~23~58~18 minecraft:stained_glass 6
fill ~23~60~16 ~26~60~16 minecraft:stained_glass 6
setblock ~23~61~16 minecraft:stained_glass 6
setblock ~24~56~16 minecraft:stained_glass 6
fill ~24~61~16 ~24~62~16 minecraft:wool 6
fill ~25~62~16 ~25~62~18 minecraft:stained_glass 6
setblock ~27~54~16 minecraft:stained_glass 6
setblock ~27~55~16 minecraft:stained_hardened_clay 14
setblock ~27~56~16 minecraft:stained_glass 6
fill ~27~58~16 ~27~58~17 minecraft:stained_glass 6
fill ~28~50~16 ~29~50~16 minecraft:stained_glass 6
fill ~28~51~16 ~28~51~17 minecraft:stained_glass 6
setblock ~28~52~16 minecraft:wool 6
setblock ~28~57~16 minecraft:stained_glass 6
setblock ~28~58~16 minecraft:stained_hardened_clay 14
setblock ~28~60~16 minecraft:wool 6
setblock ~28~62~16 minecraft:stained_glass 6
setblock ~28~64~16 minecraft:wool 6
setblock ~28~65~16 minecraft:stained_hardened_clay 14
fill ~29~2~16 ~31~2~16 minecraft:log 1
setblock ~29~51~16 minecraft:wool 6
fill ~29~52~16 ~29~52~18 minecraft:stained_glass 6
setblock ~29~54~16 minecraft:wool 0
setblock ~29~56~16 minecraft:stained_glass 6
setblock ~29~59~16 minecraft:stained_glass 6
fill ~30~60~16 ~32~60~16 minecraft:stained_glass 6
setblock ~30~63~16 minecraft:wool 6
fill ~30~64~16 ~30~64~18 minecraft:stained_glass 6
setblock ~30~66~16 minecraft:stained_glass 6
setblock ~31~51~16 minecraft:stained_glass 6
setblock ~31~54~16 minecraft:stained_glass 6
fill ~31~63~16 ~31~63~19 minecraft:stained_glass 6
setblock ~31~64~16 minecraft:wool 0
setblock ~32~53~16 minecraft:wool 6
fill ~32~55~16 ~32~56~16 minecraft:stained_glass 6
setblock ~32~58~16 minecraft:stained_glass 6
setblock ~32~59~16 minecraft:wool 6
setblock ~32~61~16 minecraft:stained_glass 6
fill ~32~64~16 ~32~64~17 minecraft:stained_glass 6
fill ~33~56~16 ~33~56~17 minecraft:stained_glass 6
setblock ~33~59~16 minecraft:stained_hardened_clay 14
fill ~33~63~16 ~34~63~16 minecraft:stained_glass 6
setblock ~34~55~16 minecraft:stained_glass 6
setblock ~34~58~16 minecraft:wool 0
fill ~35~0~16 ~35~0~20 minecraft:dirt 0
fill ~35~1~16 ~35~2~40 minecraft:log 1
setblock ~35~55~16 minecraft:wool 0
setblock ~35~56~16 minecraft:stained_glass 6
setblock ~35~57~16 minecraft:stained_hardened_clay 14
setblock ~35~60~16 minecraft:wool 0
fill ~35~61~16 ~35~62~16 minecraft:stained_glass 6
setblock ~35~63~16 minecraft:stained_hardened_clay 14
setblock ~35~64~16 minecraft:stained_glass 6
fill ~36~0~16 ~38~0~19 minecraft:grass
setblock ~36~54~16 minecraft:stained_glass 6
fill ~36~58~16 ~36~58~17 minecraft:stained_glass 6
fill ~36~65~16 ~36~65~17 minecraft:stained_glass 6
setblock ~37~1~16 minecraft:tallgrass 0
fill ~37~63~16 ~37~64~16 minecraft:stained_glass 6
fill ~37~66~16 ~37~66~17 minecraft:stained_glass 6
fill ~38~57~16 ~40~57~17 minecraft:stained_glass 6
setblock ~38~59~16 minecraft:wool 6
setblock ~38~60~16 minecraft:stained_glass 6
setblock ~38~62~16 minecraft:wool 0
setblock ~39~55~16 minecraft:stained_glass 6
setblock ~39~56~16 minecraft:wool 6
fill ~39~58~16 ~39~58~17 minecraft:stained_glass 6
fill ~39~61~16 ~39~62~16 minecraft:stained_glass 6
fill ~39~64~16 ~40~64~16 minecraft:stained_glass 6
fill ~39~66~16 ~39~66~17 minecraft:stained_glass 6
setblock ~40~63~16 minecraft:stained_glass 6
setblock ~41~55~16 minecraft:stained_glass 6
setblock ~41~61~16 minecraft:stained_glass 6
setblock ~41~68~16 minecraft:stained_glass 6
fill ~42~1~16 ~43~1~17 minecraft:tallgrass 0
setblock ~42~56~16 minecraft:stained_glass 6
setblock ~42~57~16 minecraft:stained_hardened_clay 14
setblock ~42~58~16 minecraft:stained_glass 6
fill ~42~65~16 ~42~65~17 minecraft:stained_hardened_clay 14
fill ~43~55~16 ~43~55~18 minecraft:stained_glass 6
setblock ~43~57~16 minecraft:stained_glass 6
fill ~43~59~16 ~43~59~20 minecraft:stained_glass 6
setblock ~43~60~16 minecraft:wool 0
setblock ~43~63~16 minecraft:stained_glass 6
fill ~43~65~16 ~43~66~17 minecraft:stained_glass 6
fill ~43~68~16 ~44~68~16 minecraft:stained_glass 6
setblock ~43~69~16 minecraft:stained_glass 6
setblock ~44~57~16 minecraft:wool 6
fill ~44~61~16 ~45~61~16 minecraft:stained_glass 6
setblock ~44~67~16 minecraft:wool 6
setblock ~44~69~16 minecraft:wool 0
fill ~45~60~16 ~45~60~17 minecraft:stained_hardened_clay 14
fill ~45~63~16 ~46~63~16 minecraft:stained_glass 6
setblock ~45~67~16 minecraft:stained_hardened_clay 14
setblock ~46~62~16 minecraft:wool 6
fill ~46~68~16 ~47~68~16 minecraft:stained_glass 6
setblock ~46~69~16 minecraft:stained_glass 6
setblock ~47~1~16 minecraft:carpet 6
setblock ~47~58~16 minecraft:wool 6
fill ~47~59~16 ~48~59~16 minecraft:stained_glass 6
fill ~47~61~16 ~47~61~18 minecraft:stained_glass 6
setblock ~47~64~16 minecraft:stained_glass 6
setblock ~47~66~16 minecraft:stained_glass 6
setblock ~48~58~16 minecraft:stained_glass 6
fill ~48~60~16 ~48~60~17 minecraft:stained_glass 6
setblock ~48~62~16 minecraft:stained_hardened_clay 14
setblock ~49~61~16 minecraft:stained_glass 6
fill ~49~64~16 ~49~64~18 minecraft:stained_glass 6
setblock ~49~66~16 minecraft:stained_hardened_clay 14
setblock ~49~67~16 minecraft:stained_glass 6
setblock ~49~68~16 minecraft:wool 6
fill ~50~0~16 ~56~0~16 minecraft:grass
setblock ~50~58~16 minecraft:wool 0
setblock ~50~60~16 minecraft:stained_glass 6
fill ~50~63~16 ~50~63~17 minecraft:stained_glass 6
fill ~50~65~16 ~50~66~16 minecraft:stained_glass 6
setblock ~50~69~16 minecraft:stained_glass 6
setblock ~51~1~16 minecraft:tallgrass 0
setblock ~51~58~16 minecraft:stained_glass 6
fill ~51~64~16 ~51~64~17 minecraft:stained_glass 6
setblock ~51~67~16 minecraft:wool 6
setblock ~52~60~16 minecraft:stained_glass 6
fill ~52~65~16 ~56~65~16 minecraft:stained_glass 6
fill ~52~66~16 ~52~66~17 minecraft:stained_glass 6
setblock ~52~70~16 minecraft:wool 0
setblock ~53~59~16 minecraft:stained_glass 6
fill ~53~61~16 ~53~61~18 minecraft:stained_glass 6
fill ~53~64~16 ~54~64~16 minecraft:stained_glass 6
fill ~53~67~16 ~53~67~17 minecraft:stained_glass 6
setblock ~53~68~16 minecraft:wool 0
setblock ~53~69~16 minecraft:stained_hardened_clay 14
fill ~54~60~16 ~55~60~16 minecraft:stained_glass 6
fill ~54~62~16 ~54~62~18 minecraft:stained_glass 6
setblock ~54~68~16 minecraft:stained_glass 6
setblock ~55~63~16 minecraft:stained_glass 6
setblock ~56~62~16 minecraft:stained_glass 6
fill ~56~67~16 ~56~67~17 minecraft:stained_glass 6
fill ~57~0~16 ~58~1~22 minecraft:log 1
setblock ~57~61~16 minecraft:stained_hardened_clay 14
fill ~57~63~16 ~57~63~17 minecraft:stained_glass 6
setblock ~57~66~16 minecraft:wool 0
setblock ~58~61~16 minecraft:wool 0
fill ~58~68~16 ~61~68~16 minecraft:stained_glass 6
setblock ~59~0~16 minecraft:grass
fill ~59~60~16 ~59~62~16 minecraft:stained_glass 6
setblock ~59~63~16 minecraft:wool 6
fill ~59~64~16 ~61~64~16 minecraft:stained_glass 6
fill ~59~65~16 ~59~65~17 minecraft:stained_glass 6
setblock ~59~67~16 minecraft:stained_glass 6
fill ~60~59~16 ~61~59~17 minecraft:stained_glass 6
setblock ~60~62~16 minecraft:stained_glass 6
setblock ~60~63~16 minecraft:stained_hardened_clay 14
fill ~61~61~16 ~64~61~16 minecraft:stained_glass 6
setblock ~62~60~16 minecraft:wool 0
setblock ~62~66~16 minecraft:stained_glass 6
setblock ~63~60~16 minecraft:stained_glass 6
setblock ~64~62~16 minecraft:stained_hardened_clay 14
setblock ~64~63~16 minecraft:stained_glass 6
fill ~64~65~16 ~64~65~18 minecraft:stained_glass 6
fill ~65~0~16 ~65~0~21 minecraft:grass
fill ~65~1~16 ~65~1~17 minecraft:tallgrass 0
fill ~65~64~16 ~65~64~17 minecraft:stained_glass 6
setblock ~66~62~16 minecraft:stained_glass 6
setblock ~66~63~16 minecraft:wool 0
fill ~68~60~16 ~68~61~16 minecraft:stained_glass 6
fill ~69~57~16 ~69~58~17 minecraft:stained_glass 6
fill ~69~59~16 ~71~59~16 minecraft:stained_glass 6
setblock ~69~62~16 minecraft:stained_glass 6
fill ~69~64~16 ~69~64~17 minecraft:stained_glass 6
fill ~70~56~16 ~73~56~16 minecraft:stained_glass 6
setblock ~70~65~16 minecraft:stained_glass 6
fill ~71~61~16 ~71~63~16 minecraft:stained_glass 6
setblock ~72~55~16 minecraft:stained_glass 6
setblock ~72~58~16 minecraft:wool 6
fill ~72~60~16 ~72~60~18 minecraft:stained_glass 6
fill ~72~62~16 ~74~62~16 minecraft:stained_glass 6
fill ~73~57~16 ~73~57~19 minecraft:stained_glass 6
fill ~73~58~16 ~73~59~16 minecraft:stained_glass 6
fill ~73~61~16 ~74~61~16 minecraft:stained_glass 6
setblock ~74~57~16 minecraft:stained_hardened_clay 14
setblock ~74~59~16 minecraft:stained_hardened_clay 14
setblock ~75~58~16 minecraft:wool 0
setblock ~75~63~16 minecraft:wool 6
fill ~76~60~16 ~76~60~17 minecraft:stained_glass 6
setblock ~76~62~16 minecraft:stained_hardened_clay 14
fill ~10~58~17 ~10~58~19 minecraft:stained_glass 6
setblock ~12~55~17 minecraft:wool 6
setblock ~12~56~17 minecraft:wool 0
setblock ~12~57~17 minecraft:stained_glass 6
setblock ~12~58~17 minecraft:wool 6
fill ~13~0~17 ~13~0~23 minecraft:grass
fill ~13~54~17 ~14~54~17 minecraft:stained_glass 6
fill ~13~55~17 ~13~56~17 minecraft:stained_glass 6
setblock ~13~57~17 minecraft:wool 0
fill ~13~59~17 ~13~60~17 minecraft:wool 0
setblock ~14~53~17 minecraft:wool 0
fill ~14~57~17 ~15~57~17 minecraft:stained_glass 6
setblock ~14~61~17 minecraft:stained_glass 6
setblock ~15~1~17 minecraft:tallgrass 0
fill ~15~53~17 ~15~53~20 minecraft:stained_glass 6
setblock ~15~56~17 minecraft:stained_glass 6
setblock ~15~60~17 minecraft:stained_hardened_clay 14
setblock ~16~54~17 minecraft:stained_glass 6
setblock ~16~56~17 minecraft:wool 0
fill ~16~59~17 ~16~60~17 minecraft:stained_glass 6
fill ~17~1~17 ~18~1~17 minecraft:tallgrass 0
setblock ~17~57~17 minecraft:stained_hardened_clay 14
fill ~17~60~17 ~18~60~17 minecraft:stained_glass 6
fill ~17~61~17 ~17~62~17 minecraft:wool 0
fill ~18~55~17 ~21~55~17 minecraft:stained_glass 6
fill ~18~59~17 ~18~59~18 minecraft:stained_glass 6
setblock ~18~63~17 minecraft:stained_glass 6
fill ~19~50~17 ~20~50~17 minecraft:stained_glass 6
fill ~19~56~17 ~19~58~17 minecraft:stained_glass 6
fill ~19~62~17 ~19~62~18 minecraft:stained_glass 6
fill ~20~53~17 ~20~54~17 minecraft:stained_glass 6
setblock ~20~57~17 minecraft:stained_glass 6
setblock ~20~60~17 minecraft:stained_hardened_clay 14
fill ~21~58~17 ~21~59~17 minecraft:stained_glass 6
setblock ~21~61~17 minecraft:wool 6
setblock ~21~62~17 minecraft:stained_glass 6
setblock ~22~50~17 minecraft:wool 6
setblock ~22~51~17 minecraft:stained_hardened_clay 14
setblock ~22~52~17 minecraft:wool 0
setblock ~22~54~17 minecraft:stained_glass 6
setblock ~22~56~17 minecraft:wool 6
fill ~22~57~17 ~22~57~18 minecraft:stained_glass 6
setblock ~22~58~17 minecraft:wool 0
setblock ~22~60~17 minecraft:stained_glass 6
setblock ~23~51~17 minecraft:stained_glass 6
fill ~23~55~17 ~24~55~17 minecraft:stained_glass 6
fill ~24~54~17 ~24~54~20 minecraft:stained_glass 6
fill ~24~58~17 ~25~59~17 minecraft:stained_glass 6
setblock ~24~60~17 minecraft:wool 6
fill ~25~1~17 ~25~1~18 minecraft:tallgrass 0
fill ~25~55~17 ~25~55~18 minecraft:wool 6
setblock ~25~57~17 minecraft:stained_glass 6
setblock ~25~61~17 minecraft:wool 6
fill ~25~64~17 ~25~64~19 minecraft:stained_glass 6
setblock ~25~65~17 minecraft:stained_glass 6
setblock ~26~56~17 minecraft:log 1
setblock ~26~59~17 minecraft:stained_hardened_clay 14
fill ~26~60~17 ~26~60~18 minecraft:wool 6
setblock ~26~61~17 minecraft:stained_glass 6
fill ~26~66~17 ~26~66~18 minecraft:stained_glass 6
fill ~27~0~17 ~27~0~39 minecraft:grass
setblock ~27~55~17 minecraft:stained_glass 6
setblock ~27~57~17 minecraft:stained_glass 6
fill ~27~59~17 ~27~59~18 minecraft:stained_glass 6
setblock ~27~60~17 minecraft:stained_glass 6
fill ~27~62~17 ~27~62~18 minecraft:stained_glass 6
setblock ~27~63~17 minecraft:stained_glass 6
fill ~27~67~17 ~27~67~18 minecraft:stained_glass 6
setblock ~28~1~17 minecraft:log 1
setblock ~28~58~17 minecraft:wool 0
setblock ~28~61~17 minecraft:wool 0
setblock ~28~64~17 minecraft:stained_glass 6
fill ~29~51~17 ~30~51~17 minecraft:stained_glass 6
setblock ~29~54~17 minecraft:stained_hardened_clay 14
setblock ~29~56~17 minecraft:stained_hardened_clay 14
setblock ~29~58~17 minecraft:stained_hardened_clay 14
fill ~29~61~17 ~30~61~17 minecraft:stained_glass 6
fill ~29~62~17 ~29~62~18 minecraft:stained_glass 6
setblock ~29~63~17 minecraft:stained_glass 6
fill ~29~65~17 ~29~65~18 minecraft:stained_glass 6
setblock ~29~66~17 minecraft:stained_glass 6
fill ~30~2~17 ~31~2~17 minecraft:log 1
setblock ~30~52~17 minecraft:wool 0
setblock ~30~53~17 minecraft:wool 6
setblock ~30~55~17 minecraft:stained_hardened_clay 14
setblock ~30~59~17 minecraft:stained_glass 6
fill ~30~66~17 ~31~66~17 minecraft:wool 6
fill ~30~67~17 ~30~67~18 minecraft:stained_glass 6
setblock ~31~52~17 minecraft:stained_glass 6
setblock ~31~53~17 minecraft:wool 0
setblock ~31~55~17 minecraft:stained_glass 6
fill ~31~56~17 ~31~56~18 minecraft:stained_hardened_clay 14
setblock ~31~62~17 minecraft:stained_glass 6
fill ~32~3~17 ~35~3~17 minecraft:log 1
fill ~32~56~17 ~32~56~18 minecraft:stained_glass 6
fill ~32~60~17 ~33~60~17 minecraft:stained_glass 6
fill ~32~62~17 ~32~62~18 minecraft:wool 6
fill ~32~63~17 ~33~63~17 minecraft:stained_glass 6
setblock ~32~65~17 minecraft:stained_glass 6
setblock ~33~59~17 minecraft:stained_glass 6
fill ~33~61~17 ~33~61~19 minecraft:stained_glass 6
fill ~33~62~17 ~33~62~18 minecraft:stained_glass 6
fill ~34~54~17 ~38~54~26 minecraft:log 1
fill ~34~55~17 ~39~55~21 minecraft:log 1
fill ~34~56~17 ~34~56~24 minecraft:log 1
fill ~34~57~17 ~34~57~18 minecraft:log 1
fill ~34~64~17 ~34~64~18 minecraft:stained_glass 6
setblock ~35~57~17 minecraft:stained_glass 6
setblock ~35~58~17 minecraft:wool 6
setblock ~35~61~17 minecraft:stained_hardened_clay 14
