fill ~63~2~0 ~67~99~0 minecraft:barrier
fill ~61~2~1 ~62~99~1 minecraft:barrier
fill ~63~1~1 ~67~1~226 minecraft:stonebrick 0
fill ~63~2~1 ~67~2~77 minecraft:stonebrick 0
fill ~68~2~1 ~69~99~1 minecraft:barrier
fill ~60~2~2 ~60~99~2 minecraft:barrier
fill ~61~1~2 ~62~1~227 minecraft:stonebrick 0
fill ~61~2~2 ~62~2~86 minecraft:stonebrick 0
fill ~68~1~2 ~69~1~180 minecraft:stonebrick 0
fill ~68~2~2 ~69~2~76 minecraft:stonebrick 0
fill ~70~2~2 ~70~99~2 minecraft:barrier
fill ~58~2~3 ~59~99~3 minecraft:barrier
fill ~60~1~3 ~60~1~227 minecraft:stonebrick 0
fill ~60~2~3 ~60~2~86 minecraft:stonebrick 0
fill ~70~1~3 ~70~1~179 minecraft:stonebrick 0
fill ~70~2~3 ~70~2~76 minecraft:stonebrick 0
fill ~71~2~3 ~72~99~3 minecraft:barrier
fill ~55~2~4 ~57~99~4 minecraft:barrier
fill ~58~1~4 ~59~1~227 minecraft:stonebrick 0
fill ~58~2~4 ~59~2~86 minecraft:stonebrick 0
fill ~71~1~4 ~72~1~179 minecraft:stonebrick 0
fill ~71~2~4 ~72~2~76 minecraft:stonebrick 0
fill ~73~2~4 ~75~99~4 minecraft:barrier
fill ~53~2~5 ~54~99~5 minecraft:barrier
fill ~55~1~5 ~57~1~226 minecraft:stonebrick 0
fill ~55~2~5 ~57~2~86 minecraft:stonebrick 0
fill ~64~3~5 ~67~3~5 minecraft:log 0
fill ~73~1~5 ~75~1~179 minecraft:stonebrick 0
fill ~73~2~5 ~75~2~36 minecraft:stonebrick 0
fill ~76~2~5 ~77~99~5 minecraft:barrier
fill ~52~2~6 ~52~99~6 minecraft:barrier
fill ~53~1~6 ~54~2~225 minecraft:stonebrick 0
fill ~59~5~6 ~63~5~7 minecraft:leaves 0
fill ~60~6~6 ~64~6~7 minecraft:leaves 0
fill ~61~7~6 ~64~7~7 minecraft:leaves 0
fill ~62~3~6 ~64~3~6 minecraft:log 0
fill ~65~3~6 ~66~3~9 minecraft:grass
setblock ~65~4~6 minecraft:tallgrass 0
fill ~67~3~6 ~69~3~6 minecraft:log 0
fill ~68~6~6 ~72~6~7 minecraft:leaves 0
fill ~69~5~6 ~71~5~7 minecraft:leaves 0
fill ~76~1~6 ~77~1~229 minecraft:stonebrick 0
fill ~76~2~6 ~77~2~86 minecraft:stonebrick 0
fill ~78~2~6 ~78~99~6 minecraft:barrier
fill ~51~2~7 ~51~99~7 minecraft:barrier
fill ~52~1~7 ~52~1~224 minecraft:stonebrick 0
fill ~52~2~7 ~52~2~28 minecraft:stonebrick 0
fill ~59~3~7 ~62~3~7 minecraft:log 0
fill ~59~6~7 ~59~6~18 minecraft:leaves 0
fill ~60~7~7 ~60~7~9 minecraft:leaves 0
fill ~61~8~7 ~62~8~7 minecraft:leaves 0
fill ~62~9~7 ~62~9~9 minecraft:leaves 0
fill ~63~3~7 ~64~3~34 minecraft:grass
setblock ~65~4~7 minecraft:double_plant 2
fill ~66~4~7 ~66~4~9 minecraft:tallgrass 0
fill ~67~3~7 ~68~3~10 minecraft:grass
fill ~68~5~7 ~68~5~9 minecraft:leaves 0
fill ~69~3~7 ~71~3~7 minecraft:log 0
fill ~70~7~7 ~71~7~7 minecraft:leaves 0
fill ~70~8~7 ~70~8~9 minecraft:leaves 0
fill ~72~5~7 ~72~5~10 minecraft:leaves 0
fill ~78~1~7 ~78~1~228 minecraft:stonebrick 0
fill ~78~2~7 ~78~2~86 minecraft:stonebrick 0
fill ~79~2~7 ~80~99~7 minecraft:barrier
fill ~50~2~8 ~50~99~8 minecraft:barrier
fill ~51~1~8 ~51~1~223 minecraft:stonebrick 0
fill ~51~2~8 ~51~2~28 minecraft:stonebrick 0
fill ~56~3~8 ~59~3~8 minecraft:log 0
fill ~59~5~8 ~60~5~10 minecraft:leaves 0
fill ~60~3~8 ~60~3~12 minecraft:grass
fill ~60~6~8 ~61~6~12 minecraft:leaves 0
fill ~60~8~8 ~61~8~8 minecraft:leaves 0
fill ~61~3~8 ~62~3~8 minecraft:dirt 0
fill ~61~4~8 ~62~5~8 minecraft:log 0
fill ~61~7~8 ~61~7~19 minecraft:leaves 0
setblock ~61~9~8 minecraft:leaves 0
fill ~62~6~8 ~62~8~8 minecraft:log 0
fill ~63~4~8 ~65~4~8 minecraft:tallgrass 0
fill ~63~5~8 ~63~7~10 minecraft:leaves 0
fill ~63~8~8 ~67~8~8 minecraft:leaves 0
setblock ~63~9~8 minecraft:leaves 0
fill ~64~6~8 ~64~7~10 minecraft:leaves 0
fill ~65~7~8 ~69~7~10 minecraft:leaves 0
fill ~67~4~8 ~69~4~9 minecraft:tallgrass 0
fill ~68~6~8 ~69~6~9 minecraft:leaves 0
fill ~69~3~8 ~69~3~18 minecraft:grass
fill ~69~5~8 ~69~5~10 minecraft:leaves 0
fill ~69~8~8 ~69~8~14 minecraft:leaves 0
setblock ~70~3~8 minecraft:dirt 0
fill ~70~4~8 ~70~7~8 minecraft:log 0
fill ~71~3~8 ~73~3~8 minecraft:log 0
fill ~71~5~8 ~71~6~10 minecraft:leaves 0
fill ~71~7~8 ~71~7~9 minecraft:leaves 0
setblock ~71~8~8 minecraft:leaves 0
fill ~72~6~8 ~72~6~10 minecraft:leaves 0
fill ~79~1~8 ~80~1~228 minecraft:stonebrick 0
fill ~79~2~8 ~80~2~86 minecraft:stonebrick 0
fill ~81~2~8 ~82~99~8 minecraft:barrier
fill ~48~2~9 ~49~99~9 minecraft:barrier
fill ~50~1~9 ~50~2~222 minecraft:stonebrick 0
fill ~54~3~9 ~56~3~9 minecraft:log 0
fill ~57~3~9 ~59~3~11 minecraft:grass
fill ~57~4~9 ~58~4~9 minecraft:tallgrass 0
fill ~60~4~9 ~62~4~10 minecraft:tallgrass 0
fill ~61~3~9 ~62~3~16 minecraft:grass
fill ~61~5~9 ~62~5~10 minecraft:leaves 0
fill ~61~8~9 ~62~8~9 minecraft:leaves 0
fill ~62~6~9 ~62~7~14 minecraft:leaves 0
fill ~64~8~9 ~68~8~10 minecraft:leaves 0
fill ~66~9~9 ~66~10~9 minecraft:leaves 0
fill ~70~3~9 ~72~3~13 minecraft:grass
fill ~70~4~9 ~70~4~12 minecraft:tallgrass 0
fill ~70~5~9 ~70~6~10 minecraft:leaves 0
setblock ~70~7~9 minecraft:leaves 0
fill ~72~4~9 ~72~4~12 minecraft:tallgrass 0
fill ~73~3~9 ~75~3~9 minecraft:log 0
fill ~81~1~9 ~82~1~227 minecraft:stonebrick 0
fill ~81~2~9 ~82~2~86 minecraft:stonebrick 0
fill ~83~2~9 ~83~99~9 minecraft:barrier
fill ~46~2~10 ~47~99~10 minecraft:barrier
fill ~48~1~10 ~49~2~222 minecraft:stonebrick 0
fill ~53~3~10 ~54~3~10 minecraft:log 0
fill ~55~3~10 ~56~3~20 minecraft:grass
fill ~57~6~10 ~58~7~15 minecraft:leaves 0
fill ~58~4~10 ~58~4~11 minecraft:tallgrass 0
fill ~59~7~10 ~59~7~17 minecraft:leaves 0
fill ~63~4~10 ~63~4~12 minecraft:tallgrass 0
fill ~65~3~10 ~65~3~13 minecraft:grass
fill ~65~4~10 ~65~4~11 minecraft:tallgrass 0
fill ~65~9~10 ~65~9~11 minecraft:leaves 0
fill ~65~10~10 ~67~10~10 minecraft:leaves 0
setblock ~66~3~10 minecraft:dirt 0
fill ~66~4~10 ~66~6~10 minecraft:log 0
setblock ~66~9~10 minecraft:log 0
setblock ~67~4~10 minecraft:tallgrass 0
setblock ~67~9~10 minecraft:leaves 0
setblock ~68~4~10 minecraft:double_plant 2
fill ~69~4~10 ~69~4~12 minecraft:tallgrass 0
setblock ~69~6~10 minecraft:leaves 0
fill ~71~8~10 ~75~8~11 minecraft:leaves 0
fill ~72~7~10 ~74~7~11 minecraft:leaves 0
fill ~73~3~10 ~74~3~11 minecraft:grass
fill ~73~4~10 ~73~4~11 minecraft:tallgrass 0
fill ~75~3~10 ~76~3~10 minecraft:log 0
fill ~83~1~10 ~83~1~227 minecraft:stonebrick 0
fill ~83~2~10 ~83~2~86 minecraft:stonebrick 0
fill ~84~2~10 ~84~99~11 minecraft:barrier
fill ~44~2~11 ~45~99~11 minecraft:barrier
fill ~46~1~11 ~47~1~221 minecraft:stonebrick 0
fill ~46~2~11 ~47~2~171 minecraft:stonebrick 0
fill ~50~8~11 ~55~8~12 minecraft:leaves 0
fill ~51~7~11 ~56~7~12 minecraft:leaves 0
fill ~52~3~11 ~53~3~11 minecraft:log 0
fill ~54~3~11 ~54~3~12 minecraft:grass
setblock ~54~4~11 minecraft:tallgrass 0
fill ~56~4~11 ~56~4~18 minecraft:tallgrass 0
fill ~56~6~11 ~56~6~20 minecraft:leaves 0
setblock ~57~4~11 minecraft:double_plant 2
fill ~57~8~11 ~59~8~11 minecraft:leaves 0
fill ~58~9~11 ~58~9~13 minecraft:leaves 0
setblock ~59~4~11 minecraft:tallgrass 0
setblock ~60~4~11 minecraft:double_plant 2
fill ~60~7~11 ~60~7~18 minecraft:leaves 0
fill ~61~4~11 ~62~4~11 minecraft:tallgrass 0
fill ~64~4~11 ~64~4~12 minecraft:tallgrass 0
fill ~64~7~11 ~66~8~13 minecraft:leaves 0
fill ~66~3~11 ~66~3~26 minecraft:grass
fill ~66~9~11 ~66~9~12 minecraft:leaves 0
fill ~66~10~11 ~68~10~11 minecraft:leaves 0
setblock ~67~3~11 minecraft:dirt 0
fill ~67~4~11 ~67~9~11 minecraft:log 0
fill ~68~3~11 ~68~3~16 minecraft:grass
fill ~68~4~11 ~68~4~16 minecraft:tallgrass 0
fill ~68~7~11 ~69~7~13 minecraft:leaves 0
fill ~68~8~11 ~68~8~13 minecraft:leaves 0
fill ~68~9~11 ~68~9~12 minecraft:leaves 0
setblock ~71~4~11 minecraft:double_plant 2
fill ~71~7~11 ~71~7~16 minecraft:leaves 0
fill ~72~9~11 ~73~9~11 minecraft:leaves 0
fill ~73~10~11 ~73~10~16 minecraft:leaves 0
fill ~74~4~11 ~75~4~11 minecraft:tallgrass 0
fill ~75~3~11 ~75~3~27 minecraft:grass
fill ~75~7~11 ~75~7~16 minecraft:leaves 0
fill ~76~3~11 ~78~3~11 minecraft:log 0
fill ~43~2~12 ~43~99~12 minecraft:barrier
fill ~44~1~12 ~45~2~220 minecraft:stonebrick 0
fill ~50~3~12 ~52~3~12 minecraft:log 0
fill ~50~7~12 ~50~7~15 minecraft:leaves 0
fill ~52~9~12 ~54~9~12 minecraft:leaves 0
fill ~52~10~12 ~52~10~14 minecraft:leaves 0
fill ~53~3~12 ~53~3~16 minecraft:grass
fill ~54~10~12 ~54~10~14 minecraft:leaves 0
setblock ~55~4~12 minecraft:double_plant 2
fill ~56~8~12 ~57~8~15 minecraft:leaves 0
fill ~57~3~12 ~57~3~15 minecraft:grass
setblock ~57~4~12 minecraft:tallgrass 0
setblock ~57~9~12 minecraft:leaves 0
setblock ~58~3~12 minecraft:dirt 0
fill ~58~4~12 ~58~5~12 minecraft:log 0
setblock ~58~8~12 minecraft:log 0
fill ~59~3~12 ~59~3~14 minecraft:grass
fill ~59~8~12 ~61~8~14 minecraft:leaves 0
fill ~59~9~12 ~60~9~14 minecraft:leaves 0
fill ~60~4~12 ~61~4~12 minecraft:tallgrass 0
setblock ~62~4~12 minecraft:double_plant 2
fill ~63~7~12 ~63~8~21 minecraft:leaves 0
fill ~66~4~12 ~67~4~12 minecraft:tallgrass 0
fill ~67~3~12 ~67~3~23 minecraft:grass
fill ~67~7~12 ~67~8~24 minecraft:leaves 0
fill ~67~9~12 ~67~10~12 minecraft:leaves 0
fill ~68~5~12 ~72~5~13 minecraft:leaves 0
fill ~69~6~12 ~72~6~13 minecraft:leaves 0
setblock ~71~4~12 minecraft:tallgrass 0
fill ~71~8~12 ~72~8~16 minecraft:leaves 0
fill ~72~7~12 ~72~7~17 minecraft:leaves 0
fill ~72~9~12 ~72~9~13 minecraft:leaves 0
setblock ~72~10~12 minecraft:leaves 0
setblock ~73~3~12 minecraft:dirt 0
fill ~73~4~12 ~73~9~12 minecraft:log 0
fill ~74~3~12 ~74~3~21 minecraft:grass
setblock ~74~4~12 minecraft:double_plant 2
fill ~74~7~12 ~74~8~17 minecraft:leaves 0
fill ~74~9~12 ~74~10~12 minecraft:leaves 0
fill ~75~4~12 ~75~4~15 minecraft:tallgrass 0
fill ~75~8~12 ~75~8~17 minecraft:leaves 0
fill ~76~3~12 ~77~3~14 minecraft:grass
setblock ~77~4~12 minecraft:tallgrass 0
fill ~78~3~12 ~80~3~12 minecraft:log 0
fill ~84~1~12 ~84~1~226 minecraft:stonebrick 0
fill ~84~2~12 ~84~2~86 minecraft:stonebrick 0
fill ~85~2~12 ~85~99~13 minecraft:barrier
fill ~42~2~13 ~42~99~13 minecraft:barrier
fill ~43~1~13 ~43~2~219 minecraft:stonebrick 0
fill ~48~3~13 ~50~3~13 minecraft:log 0
fill ~50~8~13 ~53~8~14 minecraft:leaves 0
fill ~51~3~13 ~51~3~21 minecraft:grass
setblock ~51~4~13 minecraft:tallgrass 0
fill ~51~7~13 ~53~7~16 minecraft:leaves 0
fill ~51~9~13 ~51~10~13 minecraft:leaves 0
setblock ~52~3~13 minecraft:dirt 0
fill ~52~4~13 ~52~6~13 minecraft:log 0
setblock ~52~9~13 minecraft:log 0
fill ~53~9~13 ~53~9~14 minecraft:leaves 0
setblock ~53~10~13 minecraft:leaves 0
setblock ~54~3~13 minecraft:dirt 0
fill ~54~4~13 ~54~9~13 minecraft:log 0
fill ~55~4~13 ~55~4~16 minecraft:tallgrass 0
fill ~55~7~13 ~56~7~18 minecraft:leaves 0
fill ~55~8~13 ~55~8~19 minecraft:leaves 0
fill ~55~9~13 ~55~10~13 minecraft:leaves 0
setblock ~57~4~13 minecraft:double_plant 2
fill ~58~3~13 ~58~3~43 minecraft:grass
fill ~58~4~13 ~59~4~14 minecraft:tallgrass 0
fill ~58~8~13 ~58~8~17 minecraft:leaves 0
setblock ~60~3~13 minecraft:dirt 0
fill ~60~4~13 ~60~6~13 minecraft:log 0
setblock ~61~4~13 minecraft:double_plant 2
fill ~61~6~13 ~61~6~15 minecraft:leaves 0
setblock ~61~9~13 minecraft:leaves 0
fill ~64~9~13 ~65~9~13 minecraft:leaves 0
fill ~65~4~13 ~66~4~13 minecraft:tallgrass 0
fill ~65~10~13 ~65~10~15 minecraft:leaves 0
setblock ~67~4~13 minecraft:double_plant 2
fill ~68~6~13 ~68~6~40 minecraft:leaves 0
fill ~70~7~13 ~70~8~13 minecraft:leaves 0
fill ~73~3~13 ~73~3~14 minecraft:grass
fill ~73~4~13 ~74~4~13 minecraft:tallgrass 0
fill ~73~7~13 ~73~9~14 minecraft:leaves 0
setblock ~76~4~13 minecraft:tallgrass 0
fill ~76~6~13 ~79~7~14 minecraft:leaves 0
setblock ~77~4~13 minecraft:double_plant 2
fill ~78~3~13 ~79~3~18 minecraft:grass
fill ~79~8~13 ~82~8~14 minecraft:leaves 0
fill ~80~3~13 ~81~3~13 minecraft:log 0
fill ~80~7~13 ~81~7~14 minecraft:leaves 0
fill ~41~2~14 ~41~99~15 minecraft:barrier
fill ~42~1~14 ~42~2~218 minecraft:stonebrick 0
fill ~47~3~14 ~48~3~14 minecraft:log 0
fill ~49~3~14 ~50~3~25 minecraft:grass
fill ~52~3~14 ~52~3~24 minecraft:grass
fill ~52~4~14 ~54~4~14 minecraft:tallgrass 0
setblock ~52~9~14 minecraft:leaves 0
fill ~54~3~14 ~54~3~24 minecraft:grass
fill ~54~7~14 ~54~7~24 minecraft:leaves 0
fill ~54~8~14 ~54~8~19 minecraft:leaves 0
setblock ~54~9~14 minecraft:leaves 0
fill ~57~4~14 ~57~4~15 minecraft:tallgrass 0
fill ~59~10~14 ~59~10~16 minecraft:leaves 0
fill ~60~3~14 ~60~3~34 minecraft:grass
fill ~60~6~14 ~60~6~15 minecraft:leaves 0
setblock ~63~4~14 minecraft:tallgrass 0
fill ~64~7~14 ~64~8~22 minecraft:leaves 0
fill ~64~9~14 ~64~10~14 minecraft:leaves 0
setblock ~65~3~14 minecraft:dirt 0
fill ~65~4~14 ~65~9~14 minecraft:log 0
fill ~66~4~14 ~67~4~15 minecraft:tallgrass 0
fill ~66~7~14 ~66~7~26 minecraft:leaves 0
fill ~66~8~14 ~66~8~22 minecraft:leaves 0
fill ~66~9~14 ~66~9~15 minecraft:leaves 0
setblock ~66~10~14 minecraft:leaves 0
fill ~68~5~14 ~69~5~18 minecraft:leaves 0
setblock ~69~4~14 minecraft:tallgrass 0
fill ~69~6~14 ~69~6~18 minecraft:leaves 0
fill ~69~7~14 ~69~7~15 minecraft:leaves 0
setblock ~70~3~14 minecraft:dirt 0
fill ~70~4~14 ~70~7~14 minecraft:log 0
fill ~70~8~14 ~70~8~15 minecraft:leaves 0
fill ~71~3~14 ~72~3~30 minecraft:grass
fill ~71~5~14 ~72~6~15 minecraft:leaves 0
fill ~72~4~14 ~73~4~14 minecraft:tallgrass 0
fill ~74~9~14 ~74~9~16 minecraft:leaves 0
fill ~75~6~14 ~75~6~16 minecraft:leaves 0
setblock ~77~4~14 minecraft:tallgrass 0
fill ~77~8~14 ~78~8~14 minecraft:leaves 0
fill ~77~9~14 ~77~9~16 minecraft:leaves 0
setblock ~78~4~14 minecraft:double_plant 2
fill ~79~4~14 ~80~4~14 minecraft:tallgrass 0
fill ~79~9~14 ~81~9~14 minecraft:leaves 0
setblock ~80~3~14 minecraft:grass
fill ~80~10~14 ~80~10~16 minecraft:leaves 0
fill ~81~3~14 ~81~3~15 minecraft:log 0
fill ~82~7~14 ~82~7~17 minecraft:leaves 0
fill ~85~1~14 ~85~1~225 minecraft:stonebrick 0
fill ~85~2~14 ~85~2~107 minecraft:stonebrick 0
fill ~86~2~14 ~86~99~15 minecraft:barrier
fill ~46~3~15 ~47~3~15 minecraft:log 0
fill ~48~3~15 ~48~3~26 minecraft:grass
fill ~49~4~15 ~49~4~16 minecraft:tallgrass 0
setblock ~50~4~15 minecraft:double_plant 2
fill ~51~4~15 ~52~4~15 minecraft:tallgrass 0
fill ~51~8~15 ~53~8~16 minecraft:leaves 0
fill ~54~4~15 ~54~4~17 minecraft:tallgrass 0
fill ~55~6~15 ~55~6~23 minecraft:leaves 0
fill ~57~9~15 ~58~9~16 minecraft:leaves 0
setblock ~58~10~15 minecraft:leaves 0
setblock ~59~3~15 minecraft:dirt 0
fill ~59~4~15 ~59~5~15 minecraft:log 0
fill ~59~8~15 ~59~9~15 minecraft:log 0
setblock ~60~4~15 minecraft:tallgrass 0
fill ~60~8~15 ~62~8~16 minecraft:leaves 0
fill ~60~9~15 ~60~9~16 minecraft:leaves 0
setblock ~60~10~15 minecraft:leaves 0
fill ~62~4~15 ~62~4~16 minecraft:tallgrass 0
fill ~62~7~15 ~62~7~16 minecraft:leaves 0
fill ~64~4~15 ~65~4~15 minecraft:tallgrass 0
fill ~65~3~15 ~65~3~18 minecraft:grass
fill ~65~7~15 ~65~8~19 minecraft:leaves 0
setblock ~65~9~15 minecraft:leaves 0
fill ~66~6~15 ~67~6~19 minecraft:leaves 0
fill ~67~5~15 ~67~5~35 minecraft:leaves 0
fill ~70~3~15 ~70~3~29 minecraft:grass
fill ~70~5~15 ~70~6~21 minecraft:leaves 0
setblock ~70~7~15 minecraft:leaves 0
fill ~72~9~15 ~72~10~15 minecraft:leaves 0
setblock ~73~3~15 minecraft:dirt 0
fill ~73~4~15 ~73~9~15 minecraft:log 0
setblock ~74~10~15 minecraft:leaves 0
fill ~76~3~15 ~76~3~26 minecraft:grass
fill ~76~6~15 ~76~7~20 minecraft:leaves 0
fill ~76~8~15 ~76~8~16 minecraft:leaves 0
setblock ~76~9~15 minecraft:leaves 0
setblock ~77~3~15 minecraft:dirt 0
fill ~77~4~15 ~77~8~15 minecraft:log 0
fill ~78~4~15 ~78~4~18 minecraft:tallgrass 0
fill ~78~6~15 ~79~8~18 minecraft:leaves 0
fill ~78~9~15 ~79~9~15 minecraft:leaves 0
setblock ~79~10~15 minecraft:leaves 0
setblock ~80~3~15 minecraft:dirt 0
fill ~80~4~15 ~80~9~15 minecraft:log 0
fill ~81~7~15 ~81~8~17 minecraft:leaves 0
fill ~81~9~15 ~81~10~15 minecraft:leaves 0
fill ~82~3~15 ~82~3~16 minecraft:log 0
fill ~82~8~15 ~82~8~17 minecraft:leaves 0
fill ~40~2~16 ~40~99~16 minecraft:barrier
fill ~41~1~16 ~41~2~216 minecraft:stonebrick 0
fill ~46~3~16 ~46~3~17 minecraft:log 0
fill ~47~3~16 ~47~3~20 minecraft:grass
setblock ~48~4~16 minecraft:double_plant 2
fill ~50~4~16 ~50~4~17 minecraft:tallgrass 0
fill ~52~4~16 ~53~4~16 minecraft:tallgrass 0
fill ~52~9~16 ~54~9~16 minecraft:leaves 0
fill ~53~10~16 ~53~10~18 minecraft:leaves 0
fill ~56~8~16 ~56~8~17 minecraft:leaves 0
setblock ~56~9~16 minecraft:leaves 0
setblock ~57~3~16 minecraft:dirt 0
fill ~57~4~16 ~57~8~16 minecraft:log 0
fill ~58~6~16 ~58~6~23 minecraft:leaves 0
fill ~58~7~16 ~58~7~18 minecraft:leaves 0
fill ~59~3~16 ~59~3~36 minecraft:grass
fill ~59~8~16 ~59~8~17 minecraft:leaves 0
setblock ~59~9~16 minecraft:leaves 0
fill ~61~9~16 ~62~9~16 minecraft:leaves 0
fill ~62~10~16 ~62~10~18 minecraft:leaves 0
fill ~65~4~16 ~66~4~18 minecraft:tallgrass 0
fill ~66~5~16 ~66~5~19 minecraft:leaves 0
fill ~68~7~16 ~68~8~16 minecraft:leaves 0
fill ~69~4~16 ~72~4~16 minecraft:tallgrass 0
fill ~71~5~16 ~71~6~16 minecraft:leaves 0
setblock ~72~6~16 minecraft:leaves 0
fill ~73~3~16 ~73~3~29 minecraft:grass
setblock ~73~4~16 minecraft:double_plant 2
fill ~73~7~16 ~73~8~17 minecraft:leaves 0
setblock ~73~9~16 minecraft:leaves 0
setblock ~74~4~16 minecraft:tallgrass 0
setblock ~75~4~16 minecraft:double_plant 2
setblock ~76~4~16 minecraft:tallgrass 0
fill ~77~3~16 ~77~3~25 minecraft:grass
setblock ~77~4~16 minecraft:double_plant 2
fill ~77~6~16 ~77~7~21 minecraft:leaves 0
setblock ~77~8~16 minecraft:leaves 0
fill ~80~3~16 ~81~3~22 minecraft:grass
fill ~80~7~16 ~80~7~25 minecraft:leaves 0
fill ~80~8~16 ~80~8~17 minecraft:leaves 0
setblock ~80~9~16 minecraft:leaves 0
fill ~83~3~16 ~83~3~18 minecraft:log 0
fill ~86~1~16 ~86~2~224 minecraft:stonebrick 0
fill ~87~2~16 ~87~99~16 minecraft:barrier
fill ~38~2~17 ~39~99~17 minecraft:barrier
fill ~40~1~17 ~40~2~215 minecraft:stonebrick 0
fill ~45~3~17 ~45~3~18 minecraft:log 0
fill ~47~4~17 ~47~4~18 minecraft:double_plant 2
fill ~48~4~17 ~48~4~19 minecraft:tallgrass 0
fill ~51~7~17 ~52~7~24 minecraft:leaves 0
fill ~51~8~17 ~52~8~18 minecraft:leaves 0
fill ~52~9~17 ~52~9~18 minecraft:leaves 0
setblock ~52~10~17 minecraft:leaves 0
setblock ~53~3~17 minecraft:dirt 0
fill ~53~4~17 ~53~9~17 minecraft:log 0
fill ~54~9~17 ~54~10~17 minecraft:leaves 0
setblock ~55~4~17 minecraft:double_plant 2
fill ~57~3~17 ~57~3~23 minecraft:grass
setblock ~57~4~17 minecraft:tallgrass 0
fill ~57~6~17 ~57~6~23 minecraft:leaves 0
fill ~57~7~17 ~57~7~18 minecraft:leaves 0
fill ~57~8~17 ~57~9~17 minecraft:leaves 0
fill ~59~4~17 ~59~4~18 minecraft:tallgrass 0
fill ~60~8~17 ~61~8~18 minecraft:leaves 0
fill ~61~3~17 ~61~3~23 minecraft:grass
setblock ~61~4~17 minecraft:double_plant 2
fill ~61~9~17 ~61~9~18 minecraft:leaves 0
setblock ~61~10~17 minecraft:leaves 0
setblock ~62~3~17 minecraft:dirt 0
fill ~62~4~17 ~62~9~17 minecraft:log 0
setblock ~63~4~17 minecraft:tallgrass 0
fill ~63~9~17 ~63~9~18 minecraft:leaves 0
setblock ~63~10~17 minecraft:leaves 0
setblock ~64~4~17 minecraft:double_plant 2
fill ~67~4~17 ~67~4~18 minecraft:tallgrass 0
setblock ~68~3~17 minecraft:dirt 0
setblock ~68~4~17 minecraft:log 0
setblock ~68~7~17 minecraft:log 0
fill ~68~8~17 ~69~8~19 minecraft:leaves 0
fill ~69~4~17 ~71~4~18 minecraft:tallgrass 0
fill ~69~7~17 ~69~7~19 minecraft:leaves 0
fill ~71~6~17 ~71~6~21 minecraft:leaves 0
setblock ~72~4~17 minecraft:double_plant 2
setblock ~72~8~17 minecraft:leaves 0
fill ~73~4~17 ~73~4~20 minecraft:tallgrass 0
setblock ~74~4~17 minecraft:double_plant 2
fill ~75~4~17 ~75~4~18 minecraft:tallgrass 0
fill ~77~4~17 ~77~4~18 minecraft:tallgrass 0
fill ~79~4~17 ~81~4~17 minecraft:tallgrass 0
fill ~82~3~17 ~82~3~21 minecraft:grass
fill ~87~1~17 ~87~2~224 minecraft:stonebrick 0
fill ~88~2~17 ~91~99~17 minecraft:barrier
fill ~37~2~18 ~37~99~18 minecraft:barrier
fill ~38~1~18 ~39~2~214 minecraft:stonebrick 0
fill ~44~3~18 ~44~3~19 minecraft:log 0
fill ~46~3~18 ~46~3~55 minecraft:grass
fill ~46~4~18 ~46~4~19 minecraft:tallgrass 0
setblock ~49~4~18 minecraft:tallgrass 0
fill ~51~4~18 ~53~4~18 minecraft:tallgrass 0
fill ~53~3~18 ~53~3~21 minecraft:grass
fill ~53~7~18 ~53~7~21 minecraft:leaves 0
fill ~53~8~18 ~53~8~19 minecraft:leaves 0
setblock ~53~9~18 minecraft:leaves 0
setblock ~54~4~18 minecraft:double_plant 2
fill ~55~4~18 ~55~4~20 minecraft:tallgrass 0
setblock ~58~4~18 minecraft:tallgrass 0
fill ~61~4~18 ~61~4~19 minecraft:tallgrass 0
fill ~62~3~18 ~62~3~26 minecraft:grass
fill ~62~7~18 ~62~8~19 minecraft:leaves 0
setblock ~62~9~18 minecraft:leaves 0
fill ~65~9~18 ~66~9~19 minecraft:leaves 0
fill ~65~10~18 ~65~10~21 minecraft:leaves 0
fill ~68~3~18 ~68~3~40 minecraft:grass
fill ~68~4~18 ~68~4~25 minecraft:tallgrass 0
fill ~68~7~18 ~68~7~22 minecraft:leaves 0
fill ~70~7~18 ~70~8~22 minecraft:leaves 0
fill ~71~5~18 ~71~5~20 minecraft:leaves 0
fill ~72~4~18 ~72~4~19 minecraft:tallgrass 0
fill ~74~4~18 ~74~4~19 minecraft:tallgrass 0
setblock ~76~4~18 minecraft:tallgrass 0
fill ~77~8~18 ~77~8~25 minecraft:leaves 0
fill ~78~9~18 ~78~9~20 minecraft:leaves 0
fill ~80~4~18 ~82~4~18 minecraft:tallgrass 0
fill ~80~6~18 ~80~6~20 minecraft:leaves 0
fill ~84~3~18 ~84~3~21 minecraft:log 0
fill ~88~1~18 ~91~2~220 minecraft:stonebrick 0
fill ~92~2~18 ~93~99~18 minecraft:barrier
fill ~35~2~19 ~36~99~19 minecraft:barrier
fill ~37~1~19 ~37~2~213 minecraft:stonebrick 0
fill ~43~3~19 ~43~3~20 minecraft:log 0
fill ~45~3~19 ~45~3~34 minecraft:grass
fill ~45~8~19 ~48~8~20 minecraft:leaves 0
fill ~46~7~19 ~48~7~20 minecraft:leaves 0
setblock ~47~4~19 minecraft:tallgrass 0
setblock ~49~4~19 minecraft:double_plant 2
fill ~51~4~19 ~51~4~20 minecraft:tallgrass 0
setblock ~52~4~19 minecraft:double_plant 2
setblock ~52~8~19 minecraft:leaves 0
fill ~53~4~19 ~54~4~19 minecraft:tallgrass 0
fill ~55~5~19 ~58~5~20 minecraft:leaves 0
setblock ~57~4~19 minecraft:tallgrass 0
fill ~60~4~19 ~60~4~22 minecraft:tallgrass 0
setblock ~61~8~19 minecraft:leaves 0
fill ~63~4~19 ~64~4~19 minecraft:tallgrass 0
fill ~64~9~19 ~64~10~20 minecraft:leaves 0
fill ~65~3~19 ~65~3~20 minecraft:dirt 0
fill ~65~4~19 ~65~6~20 minecraft:log 0
setblock ~66~4~19 minecraft:tallgrass 0
fill ~66~10~19 ~66~10~20 minecraft:leaves 0
fill ~68~5~19 ~68~5~32 minecraft:leaves 0
fill ~69~3~19 ~69~3~20 minecraft:dirt 0
fill ~69~4~19 ~69~6~20 minecraft:log 0
fill ~69~9~19 ~69~10~19 minecraft:leaves 0
fill ~70~4~19 ~71~4~21 minecraft:tallgrass 0
fill ~71~7~19 ~71~7~22 minecraft:leaves 0
fill ~71~8~19 ~71~8~21 minecraft:leaves 0
setblock ~77~9~19 minecraft:leaves 0
setblock ~78~3~19 minecraft:dirt 0
fill ~78~4~19 ~78~8~19 minecraft:log 0
fill ~79~3~19 ~79~3~22 minecraft:grass
fill ~79~4~19 ~80~4~19 minecraft:tallgrass 0
fill ~79~6~19 ~79~7~21 minecraft:leaves 0
fill ~79~8~19 ~79~9~19 minecraft:leaves 0
fill ~82~4~19 ~83~4~19 minecraft:tallgrass 0
fill ~83~3~19 ~83~3~20 minecraft:grass
fill ~92~1~19 ~93~2~218 minecraft:stonebrick 0
fill ~94~2~19 ~94~99~19 minecraft:barrier
fill ~34~2~20 ~34~99~20 minecraft:barrier
fill ~35~1~20 ~36~2~211 minecraft:stonebrick 0
fill ~39~6~20 ~43~6~21 minecraft:leaves 0
fill ~39~7~20 ~42~7~26 minecraft:leaves 0
fill ~42~3~20 ~42~3~21 minecraft:log 0
fill ~44~3~20 ~44~3~28 minecraft:grass
setblock ~44~4~20 minecraft:tallgrass 0
fill ~45~7~20 ~45~7~25 minecraft:leaves 0
setblock ~46~4~20 minecraft:double_plant 2
fill ~47~9~20 ~47~10~20 minecraft:leaves 0
fill ~49~4~20 ~49~4~21 minecraft:tallgrass 0
fill ~49~6~20 ~54~6~21 minecraft:leaves 0
fill ~49~7~20 ~50~7~24 minecraft:leaves 0
fill ~49~8~20 ~49~8~22 minecraft:leaves 0
fill ~52~4~20 ~52~4~21 minecraft:tallgrass 0
setblock ~53~4~20 minecraft:double_plant 2
fill ~54~4~20 ~54~4~21 minecraft:tallgrass 0
fill ~54~5~20 ~54~5~23 minecraft:leaves 0
fill ~55~7~20 ~56~7~20 minecraft:leaves 0
setblock ~56~4~20 minecraft:tallgrass 0
fill ~56~8~20 ~56~8~26 minecraft:leaves 0
setblock ~62~4~20 minecraft:double_plant 2
fill ~63~4~20 ~63~4~21 minecraft:tallgrass 0
setblock ~64~4~20 minecraft:double_plant 2
fill ~65~7~20 ~65~9~20 minecraft:log 0
setblock ~66~9~20 minecraft:leaves 0
fill ~67~4~20 ~67~4~21 minecraft:tallgrass 0
fill ~67~6~20 ~67~6~35 minecraft:leaves 0
fill ~68~8~20 ~68~8~22 minecraft:leaves 0
fill ~68~9~20 ~68~9~21 minecraft:leaves 0
fill ~68~10~20 ~70~10~20 minecraft:leaves 0
fill ~69~7~20 ~69~9~20 minecraft:log 0
fill ~70~9~20 ~70~9~21 minecraft:leaves 0
setblock ~72~4~20 minecraft:double_plant 2
fill ~72~8~20 ~75~8~21 minecraft:leaves 0
fill ~73~7~20 ~75~7~21 minecraft:leaves 0
fill ~76~4~20 ~78~4~23 minecraft:tallgrass 0
fill ~78~3~20 ~78~3~24 minecraft:grass
fill ~78~6~20 ~78~8~21 minecraft:leaves 0
fill ~79~4~20 ~79~4~21 minecraft:double_plant 2
fill ~80~4~20 ~82~4~20 minecraft:tallgrass 0
setblock ~83~4~20 minecraft:double_plant 2
fill ~94~1~20 ~94~2~217 minecraft:stonebrick 0
fill ~95~2~20 ~96~99~20 minecraft:barrier
fill ~33~2~21 ~33~99~21 minecraft:barrier
fill ~34~1~21 ~34~2~209 minecraft:stonebrick 0
fill ~40~3~21 ~41~3~21 minecraft:log 0
fill ~41~8~21 ~42~8~21 minecraft:leaves 0
fill ~41~9~21 ~41~9~23 minecraft:leaves 0
fill ~43~3~21 ~43~3~23 minecraft:grass
fill ~43~4~21 ~43~4~23 minecraft:tallgrass 0
fill ~43~7~21 ~43~7~23 minecraft:leaves 0
fill ~45~4~21 ~46~4~22 minecraft:tallgrass 0
fill ~45~8~21 ~46~8~25 minecraft:leaves 0
fill ~46~7~21 ~46~7~26 minecraft:leaves 0
fill ~46~9~21 ~46~10~21 minecraft:leaves 0
setblock ~47~3~21 minecraft:dirt 0
fill ~47~4~21 ~47~9~21 minecraft:log 0
fill ~47~10~21 ~48~10~21 minecraft:leaves 0
fill ~48~7~21 ~48~7~26 minecraft:leaves 0
fill ~48~8~21 ~48~8~24 minecraft:leaves 0
fill ~48~9~21 ~48~9~22 minecraft:leaves 0
setblock ~50~4~21 minecraft:double_plant 2
fill ~50~8~21 ~53~8~21 minecraft:leaves 0
fill ~51~9~21 ~51~9~23 minecraft:leaves 0
setblock ~53~4~21 minecraft:tallgrass 0
fill ~53~9~21 ~53~9~23 minecraft:leaves 0
fill ~55~3~21 ~55~3~25 minecraft:grass
fill ~55~5~21 ~55~5~23 minecraft:leaves 0
fill ~55~7~21 ~55~7~26 minecraft:leaves 0
fill ~55~8~21 ~55~8~25 minecraft:leaves 0
setblock ~56~3~21 minecraft:dirt 0
fill ~56~4~21 ~56~7~21 minecraft:log 0
fill ~57~4~21 ~59~4~21 minecraft:tallgrass 0
fill ~57~5~21 ~58~5~22 minecraft:leaves 0
fill ~57~7~21 ~57~8~23 minecraft:leaves 0
fill ~61~4~21 ~62~4~21 minecraft:tallgrass 0
fill ~64~4~21 ~66~4~22 minecraft:tallgrass 0
fill ~65~3~21 ~65~3~33 minecraft:grass
fill ~65~7~21 ~65~8~22 minecraft:leaves 0
setblock ~65~9~21 minecraft:leaves 0
fill ~69~3~21 ~69~3~38 minecraft:grass
setblock ~69~4~21 minecraft:tallgrass 0
fill ~69~5~21 ~69~10~21 minecraft:leaves 0
fill ~72~4~21 ~72~4~22 minecraft:tallgrass 0
fill ~72~7~21 ~72~7~23 minecraft:leaves 0
fill ~73~9~21 ~75~9~21 minecraft:leaves 0
setblock ~74~4~21 minecraft:tallgrass 0
fill ~74~10~21 ~74~10~23 minecraft:leaves 0
fill ~76~7~21 ~76~8~24 minecraft:leaves 0
fill ~79~8~21 ~80~8~22 minecraft:leaves 0
fill ~80~4~21 ~81~4~22 minecraft:tallgrass 0
setblock ~82~4~21 minecraft:double_plant 2
fill ~83~3~21 ~83~3~22 minecraft:log 0
fill ~95~1~21 ~96~2~214 minecraft:stonebrick 0
fill ~97~2~21 ~97~99~21 minecraft:barrier
fill ~32~2~22 ~32~99~22 minecraft:barrier
fill ~33~1~22 ~33~2~206 minecraft:stonebrick 0
fill ~38~3~22 ~40~3~22 minecraft:log 0
fill ~39~6~22 ~40~6~24 minecraft:leaves 0
fill ~40~8~22 ~40~8~34 minecraft:leaves 0
setblock ~40~9~22 minecraft:leaves 0
setblock ~41~3~22 minecraft:dirt 0
fill ~41~4~22 ~41~6~22 minecraft:log 0
setblock ~41~8~22 minecraft:log 0
fill ~42~3~22 ~42~3~53 minecraft:grass
setblock ~42~4~22 minecraft:tallgrass 0
fill ~42~6~22 ~43~6~23 minecraft:leaves 0
fill ~42~8~22 ~44~8~23 minecraft:leaves 0
fill ~42~9~22 ~42~9~27 minecraft:leaves 0
setblock ~44~4~22 minecraft:double_plant 2
fill ~44~7~22 ~44~7~29 minecraft:leaves 0
fill ~46~6~22 ~52~6~23 minecraft:leaves 0
fill ~47~3~22 ~47~3~23 minecraft:grass
setblock ~47~4~22 minecraft:double_plant 2
fill ~47~7~22 ~47~9~23 minecraft:leaves 0
setblock ~47~10~22 minecraft:leaves 0
fill ~50~4~22 ~50~4~25 minecraft:tallgrass 0
fill ~50~8~22 ~50~9~22 minecraft:leaves 0
setblock ~51~3~22 minecraft:dirt 0
fill ~51~4~22 ~51~5~22 minecraft:log 0
setblock ~51~8~22 minecraft:log 0
fill ~52~8~22 ~52~8~23 minecraft:leaves 0
setblock ~52~9~22 minecraft:leaves 0
setblock ~53~3~22 minecraft:dirt 0
fill ~53~4~22 ~53~8~22 minecraft:log 0
fill ~54~6~22 ~54~6~24 minecraft:leaves 0
fill ~54~8~22 ~54~9~22 minecraft:leaves 0
fill ~55~4~22 ~56~4~22 minecraft:tallgrass 0
fill ~56~3~22 ~56~3~26 minecraft:grass
fill ~56~5~22 ~56~7~23 minecraft:leaves 0
fill ~58~7~22 ~62~8~23 minecraft:leaves 0
fill ~59~4~22 ~59~4~25 minecraft:tallgrass 0
setblock ~61~4~22 minecraft:double_plant 2
fill ~62~4~22 ~62~4~25 minecraft:tallgrass 0
setblock ~63~4~22 minecraft:double_plant 2
fill ~63~8~22 ~63~8~25 minecraft:leaves 0
fill ~66~5~22 ~66~6~26 minecraft:leaves 0
setblock ~69~4~22 minecraft:double_plant 2
fill ~69~7~22 ~69~8~22 minecraft:leaves 0
fill ~71~4~22 ~71~4~32 minecraft:tallgrass 0
fill ~72~8~22 ~73~8~24 minecraft:leaves 0
setblock ~73~4~22 minecraft:tallgrass 0
fill ~73~7~22 ~73~7~24 minecraft:leaves 0
fill ~73~9~22 ~73~10~22 minecraft:leaves 0
setblock ~74~3~22 minecraft:dirt 0
fill ~74~4~22 ~74~9~22 minecraft:log 0
fill ~75~7~22 ~75~8~24 minecraft:leaves 0
fill ~75~9~22 ~75~10~22 minecraft:leaves 0
fill ~77~7~22 ~79~7~22 minecraft:leaves 0
fill ~78~8~22 ~78~8~25 minecraft:leaves 0
fill ~79~9~22 ~79~10~22 minecraft:leaves 0
fill ~81~7~22 ~81~8~25 minecraft:leaves 0
fill ~82~3~22 ~82~3~23 minecraft:log 0
fill ~88~3~22 ~90~3~22 minecraft:log 0
fill ~97~1~22 ~97~2~211 minecraft:stonebrick 0
fill ~98~2~22 ~98~99~22 minecraft:barrier
fill ~31~2~23 ~31~99~24 minecraft:barrier
fill ~32~1~23 ~32~2~205 minecraft:stonebrick 0
fill ~37~3~23 ~38~3~23 minecraft:log 0
fill ~37~7~23 ~38~7~25 minecraft:leaves 0
fill ~38~8~23 ~39~8~27 minecraft:leaves 0
fill ~39~3~23 ~41~3~24 minecraft:grass
fill ~40~4~23 ~40~4~25 minecraft:tallgrass 0
fill ~41~6~23 ~41~6~24 minecraft:leaves 0
fill ~41~8~23 ~41~8~26 minecraft:leaves 0
setblock ~42~4~23 minecraft:double_plant 2
fill ~43~9~23 ~43~10~23 minecraft:leaves 0
fill ~44~4~23 ~45~4~23 minecraft:tallgrass 0
fill ~45~6~23 ~45~6~26 minecraft:leaves 0
fill ~47~4~23 ~48~4~23 minecraft:tallgrass 0
fill ~49~4~23 ~49~4~24 minecraft:double_plant 2
fill ~51~3~23 ~51~3~25 minecraft:grass
setblock ~51~4~23 minecraft:double_plant 2
setblock ~51~8~23 minecraft:leaves 0
fill ~52~4~23 ~54~4~23 minecraft:tallgrass 0
fill ~53~3~23 ~53~3~24 minecraft:grass
fill ~53~6~23 ~53~7~24 minecraft:leaves 0
setblock ~53~8~23 minecraft:leaves 0
fill ~56~4~23 ~58~4~23 minecraft:tallgrass 0
setblock ~57~5~23 minecraft:leaves 0
fill ~57~9~23 ~58~9~23 minecraft:leaves 0
fill ~57~10~23 ~57~10~25 minecraft:leaves 0
setblock ~60~4~23 minecraft:double_plant 2
setblock ~61~4~23 minecraft:tallgrass 0
fill ~61~9~23 ~62~9~23 minecraft:leaves 0
fill ~61~10~23 ~61~10~25 minecraft:leaves 0
fill ~63~4~23 ~63~4~26 minecraft:tallgrass 0
fill ~63~7~23 ~63~7~27 minecraft:leaves 0
setblock ~64~4~23 minecraft:double_plant 2
fill ~65~5~23 ~65~6~37 minecraft:leaves 0
setblock ~66~4~23 minecraft:tallgrass 0
fill ~69~4~23 ~70~4~24 minecraft:tallgrass 0
fill ~69~5~23 ~69~6~32 minecraft:leaves 0
fill ~74~3~23 ~74~3~27 minecraft:grass
fill ~74~7~23 ~74~8~24 minecraft:leaves 0
setblock ~74~9~23 minecraft:leaves 0
fill ~75~4~23 ~75~4~25 minecraft:tallgrass 0
fill ~77~7~23 ~78~7~24 minecraft:leaves 0
fill ~78~9~23 ~78~10~23 minecraft:leaves 0
setblock ~79~3~23 minecraft:dirt 0
fill ~79~4~23 ~79~9~23 minecraft:log 0
fill ~79~10~23 ~80~10~23 minecraft:leaves 0
fill ~80~3~23 ~81~3~23 minecraft:log 0
fill ~80~8~23 ~80~8~25 minecraft:leaves 0
fill ~80~9~23 ~80~9~24 minecraft:leaves 0
fill ~85~5~23 ~89~6~24 minecraft:leaves 0
fill ~86~3~23 ~88~3~23 minecraft:log 0
fill ~88~7~23 ~92~7~28 minecraft:leaves 0
fill ~89~3~23 ~89~3~28 minecraft:grass
fill ~90~3~23 ~91~3~23 minecraft:log 0
fill ~90~6~23 ~92~6~29 minecraft:leaves 0
fill ~98~1~23 ~98~2~210 minecraft:stonebrick 0
fill ~99~2~23 ~99~99~23 minecraft:barrier
fill ~35~6~24 ~38~6~25 minecraft:leaves 0
fill ~36~3~24 ~37~3~24 minecraft:log 0
fill ~36~5~24 ~39~5~25 minecraft:leaves 0
fill ~37~8~24 ~37~8~27 minecraft:leaves 0
fill ~38~3~24 ~38~3~42 minecraft:grass
fill ~38~4~24 ~39~4~24 minecraft:tallgrass 0
fill ~39~9~24 ~39~10~24 minecraft:leaves 0
fill ~41~4~24 ~41~4~26 minecraft:tallgrass 0
setblock ~42~6~24 minecraft:leaves 0
fill ~42~8~24 ~42~8~34 minecraft:leaves 0
fill ~42~10~24 ~44~10~24 minecraft:leaves 0
setblock ~43~3~24 minecraft:dirt 0
fill ~43~4~24 ~43~9~24 minecraft:log 0
fill ~44~8~24 ~44~8~29 minecraft:leaves 0
fill ~44~9~24 ~44~9~25 minecraft:leaves 0
setblock ~46~4~24 minecraft:tallgrass 0
fill ~46~6~24 ~46~6~26 minecraft:leaves 0
fill ~46~9~24 ~48~9~24 minecraft:leaves 0
setblock ~47~3~24 minecraft:dirt 0
fill ~47~4~24 ~47~8~24 minecraft:log 0
fill ~48~6~24 ~52~6~24 minecraft:leaves 0
fill ~53~4~24 ~54~4~24 minecraft:tallgrass 0
setblock ~55~4~24 minecraft:double_plant 2
fill ~56~4~24 ~56~4~26 minecraft:tallgrass 0
fill ~56~7~24 ~56~7~26 minecraft:leaves 0
fill ~56~9~24 ~56~9~25 minecraft:leaves 0
setblock ~56~10~24 minecraft:leaves 0
setblock ~57~3~24 minecraft:dirt 0
fill ~57~4~24 ~57~9~24 minecraft:log 0
fill ~58~4~24 ~58~4~27 minecraft:tallgrass 0
fill ~58~7~24 ~60~7~26 minecraft:leaves 0
fill ~58~8~24 ~60~8~25 minecraft:leaves 0
fill ~58~9~24 ~58~9~25 minecraft:leaves 0
setblock ~58~10~24 minecraft:leaves 0
fill ~60~4~24 ~60~4~34 minecraft:tallgrass 0
fill ~60~9~24 ~60~9~25 minecraft:leaves 0
setblock ~60~10~24 minecraft:leaves 0
setblock ~61~3~24 minecraft:dirt 0
fill ~61~4~24 ~61~9~24 minecraft:log 0
fill ~62~7~24 ~62~8~26 minecraft:leaves 0
fill ~62~9~24 ~62~9~25 minecraft:leaves 0
setblock ~62~10~24 minecraft:leaves 0
fill ~64~4~24 ~65~4~26 minecraft:tallgrass 0
fill ~66~8~24 ~66~8~31 minecraft:leaves 0
fill ~67~3~24 ~67~3~25 minecraft:dirt 0
fill ~67~4~24 ~67~4~25 minecraft:log 0
fill ~68~7~24 ~68~7~26 minecraft:leaves 0
fill ~68~8~24 ~68~8~25 minecraft:leaves 0
setblock ~72~4~24 minecraft:tallgrass 0
fill ~74~4~24 ~74~4~25 minecraft:tallgrass 0
fill ~76~4~24 ~76~4~25 minecraft:double_plant 2
setblock ~77~4~24 minecraft:tallgrass 0
setblock ~78~4~24 minecraft:double_plant 2
fill ~79~3~24 ~80~3~24 minecraft:log 0
fill ~79~7~24 ~79~8~25 minecraft:leaves 0
fill ~79~9~24 ~79~10~24 minecraft:leaves 0
fill ~85~3~24 ~86~3~24 minecraft:log 0
fill ~86~7~24 ~87~7~24 minecraft:leaves 0
fill ~87~3~24 ~88~3~24 minecraft:grass
fill ~87~4~24 ~88~4~24 minecraft:tallgrass 0
fill ~87~8~24 ~87~8~26 minecraft:leaves 0
fill ~89~8~24 ~90~8~25 minecraft:leaves 0
setblock ~90~3~24 minecraft:grass
fill ~90~5~24 ~93~5~26 minecraft:leaves 0
fill ~90~9~24 ~90~9~26 minecraft:leaves 0
fill ~91~3~24 ~92~3~24 minecraft:log 0
fill ~93~6~24 ~94~6~28 minecraft:leaves 0
fill ~99~1~24 ~99~2~208 minecraft:stonebrick 0
fill ~100~2~24 ~100~99~24 minecraft:barrier
fill ~30~2~25 ~30~99~25 minecraft:barrier
fill ~31~1~25 ~31~2~204 minecraft:stonebrick 0
fill ~35~5~25 ~35~5~28 minecraft:leaves 0
fill ~36~3~25 ~36~3~26 minecraft:log 0
setblock ~37~3~25 minecraft:grass
setblock ~38~4~25 minecraft:tallgrass 0
fill ~38~9~25 ~38~9~26 minecraft:leaves 0
fill ~38~10~25 ~40~10~25 minecraft:leaves 0
setblock ~39~3~25 minecraft:dirt 0
setblock ~39~4~25 minecraft:log 0
fill ~39~6~25 ~39~6~28 minecraft:leaves 0
setblock ~39~9~25 minecraft:log 0
fill ~40~3~25 ~41~3~26 minecraft:grass
fill ~40~9~25 ~40~9~28 minecraft:leaves 0
fill ~42~4~25 ~42~4~30 minecraft:tallgrass 0
fill ~43~3~25 ~43~3~54 minecraft:grass
setblock ~43~4~25 minecraft:double_plant 2
fill ~43~7~25 ~43~8~33 minecraft:leaves 0
fill ~43~9~25 ~43~10~25 minecraft:leaves 0
fill ~45~4~25 ~45~4~27 minecraft:tallgrass 0
fill ~47~3~25 ~47~3~27 minecraft:grass
fill ~47~6~25 ~49~6~26 minecraft:leaves 0
fill ~47~7~25 ~47~7~26 minecraft:leaves 0
fill ~47~8~25 ~47~9~25 minecraft:leaves 0
setblock ~48~4~25 minecraft:double_plant 2
setblock ~49~7~25 minecraft:leaves 0
setblock ~51~4~25 minecraft:tallgrass 0
fill ~52~3~25 ~54~3~25 minecraft:log 0
setblock ~55~4~25 minecraft:tallgrass 0
fill ~57~3~25 ~57~3~33 minecraft:grass
setblock ~57~4~25 minecraft:double_plant 2
fill ~57~7~25 ~57~8~26 minecraft:leaves 0
setblock ~57~9~25 minecraft:leaves 0
fill ~60~5~25 ~64~5~26 minecraft:leaves 0
fill ~61~3~25 ~61~3~42 minecraft:grass
fill ~61~6~25 ~63~6~26 minecraft:leaves 0
fill ~61~7~25 ~61~8~27 minecraft:leaves 0
setblock ~61~9~25 minecraft:leaves 0
setblock ~67~7~25 minecraft:log 0
fill ~67~8~25 ~67~8~27 minecraft:leaves 0
setblock ~77~4~25 minecraft:double_plant 2
fill ~78~3~25 ~79~3~25 minecraft:log 0
setblock ~78~7~25 minecraft:leaves 0
fill ~84~3~25 ~85~3~25 minecraft:log 0
fill ~85~5~25 ~86~6~26 minecraft:leaves 0
fill ~86~3~25 ~86~3~37 minecraft:grass
fill ~86~7~25 ~86~8~25 minecraft:leaves 0
setblock ~87~3~25 minecraft:dirt 0
fill ~87~4~25 ~87~7~25 minecraft:log 0
fill ~88~3~25 ~88~3~40 minecraft:grass
fill ~88~4~25 ~89~4~25 minecraft:tallgrass 0
fill ~88~5~25 ~89~6~27 minecraft:leaves 0
setblock ~88~8~25 minecraft:leaves 0
setblock ~89~9~25 minecraft:leaves 0
setblock ~90~3~25 minecraft:dirt 0
setblock ~90~4~25 minecraft:log 0
setblock ~91~3~25 minecraft:grass
fill ~91~8~25 ~92~8~32 minecraft:leaves 0
fill ~91~9~25 ~91~9~27 minecraft:leaves 0
fill ~92~3~25 ~94~3~25 minecraft:log 0
fill ~93~7~25 ~93~7~28 minecraft:leaves 0
fill ~94~5~25 ~94~5~30 minecraft:leaves 0
fill ~100~1~25 ~100~2~206 minecraft:stonebrick 0
fill ~101~2~25 ~101~99~25 minecraft:barrier
fill ~29~2~26 ~29~99~26 minecraft:barrier
fill ~30~1~26 ~30~2~203 minecraft:stonebrick 0
fill ~35~3~26 ~35~3~27 minecraft:log 0
fill ~35~6~26 ~36~6~27 minecraft:leaves 0
fill ~36~5~26 ~36~5~28 minecraft:leaves 0
fill ~36~7~26 ~36~7~27 minecraft:leaves 0
setblock ~36~8~26 minecraft:leaves 0
setblock ~37~3~26 minecraft:dirt 0
fill ~37~4~26 ~37~7~26 minecraft:log 0
fill ~38~5~26 ~39~5~28 minecraft:leaves 0
fill ~38~6~26 ~38~6~28 minecraft:leaves 0
fill ~38~7~26 ~38~7~27 minecraft:leaves 0
fill ~39~3~26 ~39~3~45 minecraft:grass
setblock ~39~4~26 minecraft:tallgrass 0
fill ~39~9~26 ~39~10~26 minecraft:leaves 0
setblock ~40~4~26 minecraft:double_plant 2
fill ~41~9~26 ~41~10~26 minecraft:leaves 0
fill ~46~4~26 ~46~4~27 minecraft:tallgrass 0
fill ~48~4~26 ~49~4~26 minecraft:tallgrass 0
setblock ~49~3~26 minecraft:grass
fill ~50~3~26 ~52~3~26 minecraft:log 0
setblock ~53~3~26 minecraft:oak_stairs 3
fill ~54~3~26 ~55~3~26 minecraft:log 0
setblock ~57~4~26 minecraft:tallgrass 0
setblock ~58~8~26 minecraft:leaves 0
fill ~60~6~26 ~60~6~29 minecraft:leaves 0
setblock ~60~8~26 minecraft:leaves 0
fill ~64~6~26 ~64~6~34 minecraft:leaves 0
fill ~65~7~26 ~65~7~30 minecraft:leaves 0
setblock ~66~4~26 minecraft:tallgrass 0
fill ~67~3~26 ~67~3~40 minecraft:grass
fill ~67~7~26 ~67~7~28 minecraft:leaves 0
fill ~69~4~26 ~70~4~26 minecraft:tallgrass 0
fill ~72~4~26 ~72~4~28 minecraft:tallgrass 0
fill ~72~5~26 ~76~5~27 minecraft:leaves 0
fill ~73~6~26 ~75~6~27 minecraft:leaves 0
setblock ~76~4~26 minecraft:tallgrass 0
fill ~77~3~26 ~78~3~26 minecraft:log 0
fill ~83~3~26 ~84~3~26 minecraft:log 0
fill ~85~3~26 ~85~3~29 minecraft:grass
fill ~85~4~26 ~87~4~26 minecraft:tallgrass 0
fill ~87~3~26 ~87~3~32 minecraft:grass
fill ~87~5~26 ~87~6~27 minecraft:leaves 0
setblock ~87~7~26 minecraft:leaves 0
fill ~89~4~26 ~90~4~28 minecraft:tallgrass 0
fill ~90~3~26 ~90~3~36 minecraft:grass
fill ~90~8~26 ~90~8~27 minecraft:leaves 0
fill ~91~3~26 ~92~3~26 minecraft:dirt 0
fill ~91~4~26 ~92~4~26 minecraft:log 0
setblock ~92~9~26 minecraft:leaves 0
fill ~93~3~26 ~93~3~28 minecraft:grass
fill ~93~8~26 ~93~8~28 minecraft:leaves 0
fill ~94~3~26 ~96~3~26 minecraft:log 0
fill ~101~1~26 ~101~2~205 minecraft:stonebrick 0
fill ~102~2~26 ~102~99~26 minecraft:barrier
fill ~28~2~27 ~28~99~28 minecraft:barrier
fill ~29~1~27 ~29~2~200 minecraft:stonebrick 0
fill ~34~3~27 ~34~3~28 minecraft:log 0
fill ~36~3~27 ~37~3~30 minecraft:grass
setblock ~37~4~27 minecraft:tallgrass 0
fill ~37~5~27 ~37~6~28 minecraft:leaves 0
setblock ~37~7~27 minecraft:leaves 0
fill ~39~7~27 ~40~7~34 minecraft:leaves 0
fill ~40~3~27 ~40~3~48 minecraft:grass
fill ~40~10~27 ~42~10~27 minecraft:leaves 0
setblock ~41~3~27 minecraft:dirt 0
fill ~41~4~27 ~41~9~27 minecraft:log 0
fill ~42~7~27 ~42~7~34 minecraft:leaves 0
fill ~43~4~27 ~44~4~27 minecraft:tallgrass 0
fill ~45~7~27 ~45~7~32 minecraft:leaves 0
fill ~45~8~27 ~45~8~31 minecraft:leaves 0
setblock ~47~4~27 minecraft:tallgrass 0
fill ~48~3~27 ~50~3~27 minecraft:log 0
fill ~55~3~27 ~56~3~27 minecraft:log 0
setblock ~59~4~27 minecraft:tallgrass 0
fill ~60~5~27 ~61~5~34 minecraft:leaves 0
setblock ~61~4~27 minecraft:tallgrass 0
fill ~61~6~27 ~61~6~34 minecraft:leaves 0
setblock ~62~3~27 minecraft:dirt 0
fill ~62~4~27 ~62~7~27 minecraft:log 0
fill ~62~8~27 ~63~8~27 minecraft:leaves 0
fill ~63~5~27 ~64~5~34 minecraft:leaves 0
fill ~63~6~27 ~63~6~40 minecraft:leaves 0
setblock ~65~4~27 minecraft:tallgrass 0
setblock ~65~8~27 minecraft:leaves 0
setblock ~66~3~27 minecraft:dirt 0
fill ~66~4~27 ~66~7~27 minecraft:log 0
fill ~72~6~27 ~72~6~39 minecraft:leaves 0
fill ~73~4~27 ~74~4~27 minecraft:tallgrass 0
fill ~73~7~27 ~75~7~27 minecraft:leaves 0
fill ~74~8~27 ~74~8~29 minecraft:leaves 0
fill ~76~3~27 ~77~3~27 minecraft:log 0
fill ~76~6~27 ~76~6~30 minecraft:leaves 0
fill ~80~6~27 ~83~6~28 minecraft:leaves 0
fill ~81~5~27 ~84~5~28 minecraft:leaves 0
fill ~82~3~27 ~83~3~27 minecraft:log 0
fill ~84~3~27 ~84~3~33 minecraft:grass
fill ~84~4~27 ~85~4~27 minecraft:tallgrass 0
fill ~85~6~27 ~86~6~29 minecraft:leaves 0
setblock ~86~5~27 minecraft:leaves 0
fill ~87~4~27 ~88~4~28 minecraft:tallgrass 0
fill ~90~5~27 ~90~5~29 minecraft:leaves 0
setblock ~91~3~27 minecraft:dirt 0
fill ~91~4~27 ~91~5~27 minecraft:log 0
fill ~92~3~27 ~92~3~32 minecraft:grass
fill ~92~5~27 ~93~5~28 minecraft:leaves 0
fill ~94~3~27 ~95~3~32 minecraft:grass
fill ~94~7~27 ~94~7~40 minecraft:leaves 0
fill ~94~8~27 ~95~8~34 minecraft:leaves 0
fill ~95~4~27 ~95~4~31 minecraft:tallgrass 0
fill ~95~5~27 ~98~6~28 minecraft:leaves 0
fill ~96~3~27 ~97~3~27 minecraft:log 0
fill ~102~1~27 ~102~2~203 minecraft:stonebrick 0
fill ~103~2~27 ~103~99~28 minecraft:barrier
fill ~33~3~28 ~33~3~29 minecraft:log 0
fill ~35~3~28 ~35~3~33 minecraft:grass
fill ~35~4~28 ~36~4~29 minecraft:tallgrass 0
setblock ~36~6~28 minecraft:leaves 0
setblock ~38~4~28 minecraft:tallgrass 0
setblock ~39~8~28 minecraft:leaves 0
fill ~41~3~28 ~41~3~31 minecraft:grass
fill ~41~7~28 ~41~8~31 minecraft:leaves 0
fill ~41~9~28 ~41~10~28 minecraft:leaves 0
setblock ~43~4~28 minecraft:tallgrass 0
fill ~43~6~28 ~46~6~29 minecraft:leaves 0
fill ~44~9~28 ~45~9~30 minecraft:leaves 0
fill ~44~10~28 ~44~10~30 minecraft:leaves 0
fill ~46~7~28 ~46~7~31 minecraft:leaves 0
fill ~46~8~28 ~46~8~30 minecraft:leaves 0
fill ~47~3~28 ~48~3~28 minecraft:log 0
fill ~55~3~28 ~55~3~30 minecraft:oak_stairs 0
fill ~56~3~28 ~56~3~31 minecraft:log 0
fill ~57~4~28 ~57~4~29 minecraft:tallgrass 0
fill ~62~3~28 ~62~3~31 minecraft:grass
fill ~62~5~28 ~62~6~31 minecraft:leaves 0
fill ~62~7~28 ~62~8~28 minecraft:leaves 0
fill ~66~3~28 ~66~3~29 minecraft:grass
fill ~66~5~28 ~66~7~29 minecraft:leaves 0
setblock ~68~4~28 minecraft:tallgrass 0
fill ~70~4~28 ~70~4~29 minecraft:tallgrass 0
fill ~70~5~28 ~73~5~29 minecraft:leaves 0
fill ~70~6~28 ~71~6~29 minecraft:leaves 0
setblock ~73~4~28 minecraft:tallgrass 0
fill ~73~6~28 ~73~6~30 minecraft:leaves 0
fill ~73~7~28 ~73~7~29 minecraft:leaves 0
setblock ~73~8~28 minecraft:leaves 0
setblock ~74~3~28 minecraft:dirt 0
fill ~74~4~28 ~74~7~28 minecraft:log 0
fill ~75~3~28 ~76~3~28 minecraft:log 0
fill ~75~5~28 ~76~5~30 minecraft:leaves 0
fill ~75~6~28 ~75~6~30 minecraft:leaves 0
fill ~75~7~28 ~75~8~28 minecraft:leaves 0
fill ~80~5~28 ~80~5~30 minecraft:leaves 0
fill ~81~3~28 ~82~3~28 minecraft:log 0
fill ~81~7~28 ~87~7~28 minecraft:leaves 0
fill ~82~8~28 ~82~8~30 minecraft:leaves 0
fill ~83~3~28 ~83~3~40 minecraft:grass
setblock ~83~4~28 minecraft:tallgrass 0
fill ~84~6~28 ~84~6~35 minecraft:leaves 0
setblock ~85~4~28 minecraft:tallgrass 0
setblock ~86~4~28 minecraft:double_plant 2
fill ~87~6~28 ~89~6~28 minecraft:leaves 0
fill ~88~8~28 ~89~8~28 minecraft:leaves 0
setblock ~89~5~28 minecraft:leaves 0
fill ~89~9~28 ~89~9~30 minecraft:leaves 0
fill ~91~3~28 ~91~3~40 minecraft:grass
setblock ~91~4~28 minecraft:tallgrass 0
fill ~91~5~28 ~91~5~29 minecraft:leaves 0
fill ~92~9~28 ~94~9~28 minecraft:leaves 0
setblock ~93~4~28 minecraft:tallgrass 0
fill ~93~10~28 ~93~10~30 minecraft:leaves 0
fill ~95~7~28 ~96~7~28 minecraft:leaves 0
setblock ~96~3~28 minecraft:grass
setblock ~96~4~28 minecraft:tallgrass 0
fill ~96~8~28 ~96~8~30 minecraft:leaves 0
fill ~97~3~28 ~98~3~28 minecraft:log 0
fill ~27~2~29 ~27~99~30 minecraft:barrier
fill ~28~1~29 ~28~2~198 minecraft:stonebrick 0
fill ~32~3~29 ~32~3~31 minecraft:log 0
fill ~34~3~29 ~34~3~35 minecraft:grass
fill ~36~7~29 ~38~8~30 minecraft:leaves 0
setblock ~37~4~29 minecraft:double_plant 2
setblock ~39~4~29 minecraft:double_plant 2
setblock ~41~4~29 minecraft:tallgrass 0
fill ~42~6~29 ~42~6~31 minecraft:leaves 0
fill ~43~9~29 ~43~9~30 minecraft:leaves 0
setblock ~43~10~29 minecraft:leaves 0
fill ~44~3~29 ~44~3~30 minecraft:dirt 0
fill ~44~4~29 ~44~5~30 minecraft:log 0
fill ~45~4~29 ~46~4~32 minecraft:tallgrass 0
setblock ~45~10~29 minecraft:leaves 0
fill ~47~3~29 ~47~3~32 minecraft:log 0
fill ~48~3~29 ~48~3~31 minecraft:oak_stairs 1
fill ~51~2~29 ~52~2~30 minecraft:sea_lantern
setblock ~58~4~29 minecraft:tallgrass 0
fill ~62~4~29 ~62~4~31 minecraft:tallgrass 0
fill ~70~7~29 ~71~7~29 minecraft:leaves 0
fill ~70~8~29 ~70~8~31 minecraft:leaves 0
fill ~74~3~29 ~75~3~29 minecraft:log 0
fill ~74~5~29 ~74~6~30 minecraft:leaves 0
setblock ~74~7~29 minecraft:leaves 0
fill ~80~6~29 ~81~6~30 minecraft:leaves 0
fill ~81~3~29 ~81~3~30 minecraft:log 0
fill ~81~5~29 ~81~5~35 minecraft:leaves 0
fill ~81~7~29 ~81~7~30 minecraft:leaves 0
setblock ~81~8~29 minecraft:leaves 0
setblock ~82~3~29 minecraft:dirt 0
fill ~82~4~29 ~82~7~29 minecraft:log 0
fill ~83~5~29 ~84~5~33 minecraft:leaves 0
fill ~83~6~29 ~83~7~40 minecraft:leaves 0
fill ~83~8~29 ~86~8~29 minecraft:leaves 0
fill ~84~4~29 ~84~4~31 minecraft:tallgrass 0
fill ~84~7~29 ~88~7~29 minecraft:leaves 0
fill ~85~9~29 ~85~9~31 minecraft:leaves 0
fill ~86~4~29 ~86~4~31 minecraft:tallgrass 0
setblock ~87~4~29 minecraft:double_plant 2
fill ~87~6~29 ~88~6~32 minecraft:leaves 0
fill ~88~4~29 ~88~4~38 minecraft:tallgrass 0
fill ~88~8~29 ~88~9~29 minecraft:leaves 0
setblock ~89~3~29 minecraft:dirt 0
fill ~89~4~29 ~89~8~29 minecraft:log 0
fill ~90~4~29 ~90~4~30 minecraft:tallgrass 0
fill ~90~7~29 ~92~7~32 minecraft:leaves 0
fill ~90~8~29 ~90~8~30 minecraft:leaves 0
setblock ~90~9~29 minecraft:leaves 0
fill ~92~4~29 ~92~4~32 minecraft:tallgrass 0
setblock ~92~5~29 minecraft:leaves 0
fill ~92~9~29 ~92~9~30 minecraft:leaves 0
setblock ~92~10~29 minecraft:leaves 0
setblock ~93~3~29 minecraft:dirt 0
fill ~93~4~29 ~93~9~29 minecraft:log 0
fill ~94~4~29 ~94~4~38 minecraft:tallgrass 0
fill ~94~6~29 ~95~6~41 minecraft:leaves 0
fill ~94~9~29 ~94~10~29 minecraft:leaves 0
fill ~95~5~29 ~95~5~31 minecraft:leaves 0
fill ~95~7~29 ~95~7~41 minecraft:leaves 0
setblock ~96~3~29 minecraft:dirt 0
fill ~96~4~29 ~96~7~29 minecraft:log 0
setblock ~97~3~29 minecraft:grass
fill ~97~5~29 ~98~6~30 minecraft:leaves 0
fill ~97~7~29 ~97~7~30 minecraft:leaves 0
setblock ~97~8~29 minecraft:leaves 0
fill ~98~3~29 ~98~3~30 minecraft:log 0
fill ~103~1~29 ~103~2~200 minecraft:stonebrick 0
fill ~104~2~29 ~105~99~29 minecraft:barrier
fill ~33~3~30 ~33~3~39 minecraft:grass
fill ~34~4~30 ~35~4~30 minecraft:tallgrass 0
fill ~35~7~30 ~35~8~38 minecraft:leaves 0
fill ~36~4~30 ~36~4~31 minecraft:double_plant 2
setblock ~37~4~30 minecraft:tallgrass 0
fill ~37~9~30 ~38~9~30 minecraft:leaves 0
fill ~37~10~30 ~37~10~32 minecraft:leaves 0
fill ~39~4~30 ~40~4~30 minecraft:tallgrass 0
fill ~39~8~30 ~39~8~34 minecraft:leaves 0
setblock ~41~4~30 minecraft:double_plant 2
setblock ~43~4~30 minecraft:double_plant 2
fill ~43~6~30 ~43~6~32 minecraft:leaves 0
fill ~44~6~30 ~44~8~30 minecraft:log 0
fill ~45~6~30 ~46~6~31 minecraft:leaves 0
fill ~59~4~30 ~59~4~31 minecraft:tallgrass 0
setblock ~63~4~30 minecraft:tallgrass 0
setblock ~65~8~30 minecraft:leaves 0
setblock ~66~3~30 minecraft:dirt 0
fill ~66~4~30 ~66~7~30 minecraft:log 0
fill ~67~7~30 ~67~7~31 minecraft:leaves 0
setblock ~67~8~30 minecraft:leaves 0
setblock ~68~4~30 minecraft:tallgrass 0
fill ~69~7~30 ~69~8~30 minecraft:leaves 0
setblock ~70~3~30 minecraft:dirt 0
fill ~70~4~30 ~70~7~30 minecraft:log 0
fill ~71~5~30 ~73~5~30 minecraft:leaves 0
fill ~71~6~30 ~71~6~40 minecraft:leaves 0
fill ~71~7~30 ~71~8~30 minecraft:leaves 0
setblock ~72~4~30 minecraft:tallgrass 0
fill ~73~3~30 ~74~3~30 minecraft:log 0
fill ~80~3~30 ~80~3~31 minecraft:log 0
fill ~82~3~30 ~82~3~33 minecraft:grass
fill ~82~4~30 ~83~4~30 minecraft:tallgrass 0
fill ~82~5~30 ~82~6~36 minecraft:leaves 0
setblock ~82~7~30 minecraft:leaves 0
fill ~84~7~30 ~84~7~35 minecraft:leaves 0
fill ~84~8~30 ~84~9~30 minecraft:leaves 0
setblock ~85~3~30 minecraft:dirt 0
fill ~85~4~30 ~85~8~30 minecraft:log 0
fill ~86~6~30 ~86~7~37 minecraft:leaves 0
fill ~86~8~30 ~86~8~31 minecraft:leaves 0
setblock ~86~9~30 minecraft:leaves 0
fill ~87~7~30 ~89~7~31 minecraft:leaves 0
fill ~89~3~30 ~89~3~41 minecraft:grass
fill ~89~4~30 ~89~4~32 minecraft:tallgrass 0
fill ~89~6~30 ~91~6~30 minecraft:leaves 0
setblock ~89~8~30 minecraft:leaves 0
setblock ~91~4~30 minecraft:double_plant 2
fill ~93~3~30 ~93~3~37 minecraft:grass
fill ~93~4~30 ~93~4~32 minecraft:tallgrass 0
fill ~93~7~30 ~93~7~37 minecraft:leaves 0
fill ~93~8~30 ~93~8~35 minecraft:leaves 0
setblock ~93~9~30 minecraft:leaves 0
setblock ~96~3~30 minecraft:grass
setblock ~96~4~30 minecraft:tallgrass 0
fill ~96~5~30 ~96~7~31 minecraft:leaves 0
fill ~97~3~30 ~97~3~31 minecraft:log 0
fill ~104~1~30 ~105~2~194 minecraft:stonebrick 0
fill ~106~2~30 ~106~99~30 minecraft:barrier
fill ~26~2~31 ~26~99~31 minecraft:barrier
fill ~27~1~31 ~27~2~198 minecraft:stonebrick 0
fill ~31~3~31 ~31~3~32 minecraft:log 0
fill ~33~4~31 ~34~4~31 minecraft:tallgrass 0
setblock ~35~4~31 minecraft:double_plant 2
fill ~36~3~31 ~36~3~50 minecraft:grass
fill ~36~7~31 ~36~8~37 minecraft:leaves 0
fill ~36~9~31 ~36~10~31 minecraft:leaves 0
setblock ~37~3~31 minecraft:dirt 0
fill ~37~4~31 ~37~9~31 minecraft:log 0
fill ~38~4~31 ~38~4~33 minecraft:tallgrass 0
fill ~38~7~31 ~38~8~33 minecraft:leaves 0
fill ~38~9~31 ~38~9~32 minecraft:leaves 0
setblock ~38~10~31 minecraft:leaves 0
fill ~40~9~31 ~41~9~31 minecraft:leaves 0
setblock ~41~4~31 minecraft:tallgrass 0
fill ~41~10~31 ~41~10~33 minecraft:leaves 0
setblock ~42~4~31 minecraft:double_plant 2
fill ~43~4~31 ~44~4~32 minecraft:tallgrass 0
fill ~44~3~31 ~44~3~54 minecraft:grass
fill ~44~6~31 ~44~6~51 minecraft:leaves 0
fill ~44~7~31 ~44~7~32 minecraft:leaves 0
fill ~44~8~31 ~44~9~31 minecraft:leaves 0
fill ~51~2~31 ~52~2~223 minecraft:stonebrick 0
fill ~55~3~31 ~55~3~32 minecraft:log 0
fill ~57~4~31 ~58~4~31 minecraft:tallgrass 0
fill ~60~6~31 ~60~6~33 minecraft:leaves 0
fill ~61~4~31 ~61~4~32 minecraft:tallgrass 0
fill ~61~7~31 ~62~7~31 minecraft:leaves 0
fill ~62~8~31 ~62~8~37 minecraft:leaves 0
fill ~66~3~31 ~66~3~40 minecraft:grass
fill ~66~5~31 ~66~5~37 minecraft:leaves 0
fill ~66~6~31 ~66~6~36 minecraft:leaves 0
setblock ~66~7~31 minecraft:leaves 0
fill ~69~4~31 ~70~4~33 minecraft:tallgrass 0
fill ~70~3~31 ~71~3~33 minecraft:grass
fill ~70~5~31 ~72~5~32 minecraft:leaves 0
fill ~70~6~31 ~70~7~33 minecraft:leaves 0
fill ~72~3~31 ~73~3~31 minecraft:log 0
fill ~79~3~31 ~79~3~32 minecraft:log 0
fill ~81~3~31 ~81~3~35 minecraft:grass
fill ~81~4~31 ~82~4~32 minecraft:tallgrass 0
fill ~81~6~31 ~81~6~35 minecraft:leaves 0
fill ~85~3~31 ~85~3~40 minecraft:grass
fill ~85~5~31 ~89~5~32 minecraft:leaves 0
fill ~85~6~31 ~85~6~42 minecraft:leaves 0
fill ~85~7~31 ~85~7~32 minecraft:leaves 0
setblock ~85~8~31 minecraft:leaves 0
fill ~89~6~31 ~90~6~31 minecraft:leaves 0
setblock ~90~4~31 minecraft:double_plant 2
fill ~91~4~31 ~91~4~35 minecraft:tallgrass 0
fill ~93~6~31 ~93~6~37 minecraft:leaves 0
fill ~96~3~31 ~96~3~33 minecraft:log 0
fill ~97~5~31 ~97~6~31 minecraft:leaves 0
setblock ~98~6~31 minecraft:leaves 0
fill ~106~1~31 ~106~2~194 minecraft:stonebrick 0
fill ~107~2~31 ~107~99~31 minecraft:barrier
fill ~25~2~32 ~25~99~32 minecraft:barrier
fill ~26~1~32 ~26~2~197 minecraft:stonebrick 0
fill ~30~3~32 ~30~3~33 minecraft:log 0
fill ~32~3~32 ~32~3~39 minecraft:grass
fill ~33~8~32 ~34~8~35 minecraft:leaves 0
setblock ~34~4~32 minecraft:double_plant 2
fill ~34~7~32 ~34~7~35 minecraft:leaves 0
fill ~35~4~32 ~37~4~32 minecraft:tallgrass 0
fill ~37~3~32 ~37~3~51 minecraft:grass
fill ~37~7~32 ~37~8~35 minecraft:leaves 0
setblock ~37~9~32 minecraft:leaves 0
fill ~39~4~32 ~39~4~36 minecraft:tallgrass 0
setblock ~40~4~32 minecraft:double_plant 2
fill ~40~9~32 ~40~10~32 minecraft:leaves 0
setblock ~41~3~32 minecraft:dirt 0
fill ~41~4~32 ~41~9~32 minecraft:log 0
fill ~42~9~32 ~42~10~32 minecraft:leaves 0
fill ~45~6~32 ~45~6~38 minecraft:leaves 0
fill ~48~3~32 ~48~3~33 minecraft:log 0
fill ~53~3~32 ~54~3~32 minecraft:log 0
fill ~55~7~32 ~59~7~33 minecraft:leaves 0
fill ~55~8~32 ~58~8~33 minecraft:leaves 0
fill ~56~3~32 ~56~3~45 minecraft:grass
fill ~56~4~32 ~57~4~33 minecraft:tallgrass 0
fill ~61~7~32 ~61~7~40 minecraft:leaves 0
fill ~61~8~32 ~61~8~39 minecraft:leaves 0
setblock ~62~3~32 minecraft:dirt 0
fill ~62~4~32 ~62~7~32 minecraft:log 0
fill ~63~7~32 ~63~8~32 minecraft:leaves 0
fill ~68~7~32 ~69~7~38 minecraft:leaves 0
fill ~71~7~32 ~72~7~35 minecraft:leaves 0
fill ~72~3~32 ~72~3~35 minecraft:log 0
fill ~77~7~32 ~80~7~33 minecraft:leaves 0
fill ~78~3~32 ~78~3~33 minecraft:log 0
fill ~78~8~32 ~81~8~33 minecraft:leaves 0
fill ~80~3~32 ~80~3~40 minecraft:grass
fill ~80~4~32 ~80~4~36 minecraft:tallgrass 0
setblock ~83~4~32 minecraft:tallgrass 0
fill ~85~4~32 ~85~4~33 minecraft:tallgrass 0
setblock ~87~4~32 minecraft:tallgrass 0
fill ~87~7~32 ~88~7~32 minecraft:leaves 0
fill ~87~8~32 ~87~8~34 minecraft:leaves 0
fill ~89~6~32 ~89~6~39 minecraft:leaves 0
fill ~90~4~32 ~90~4~36 minecraft:tallgrass 0
fill ~90~8~32 ~90~8~43 minecraft:leaves 0
fill ~91~9~32 ~93~9~32 minecraft:leaves 0
fill ~92~10~32 ~92~10~34 minecraft:leaves 0
fill ~95~9~32 ~95~9~34 minecraft:leaves 0
fill ~96~6~32 ~97~7~33 minecraft:leaves 0
fill ~96~8~32 ~96~8~33 minecraft:leaves 0
setblock ~97~3~32 minecraft:oak_stairs 1
fill ~107~1~32 ~107~2~193 minecraft:stonebrick 0
fill ~108~2~32 ~108~99~32 minecraft:barrier
fill ~24~2~33 ~24~99~34 minecraft:barrier
fill ~25~1~33 ~25~2~196 minecraft:stonebrick 0
fill ~29~3~33 ~29~3~35 minecraft:log 0
fill ~31~3~33 ~31~3~45 minecraft:grass
setblock ~32~4~33 minecraft:double_plant 2
fill ~33~4~33 ~35~4~33 minecraft:tallgrass 0
fill ~33~7~33 ~33~7~43 minecraft:leaves 0
fill ~34~9~33 ~36~9~33 minecraft:leaves 0
fill ~35~10~33 ~35~10~36 minecraft:leaves 0
setblock ~37~4~33 minecraft:double_plant 2
fill ~40~4~33 ~40~4~34 minecraft:tallgrass 0
fill ~41~3~33 ~41~3~38 minecraft:grass
fill ~41~7~33 ~41~8~34 minecraft:leaves 0
setblock ~41~9~33 minecraft:leaves 0
fill ~43~5~33 ~46~5~34 minecraft:leaves 0
fill ~44~4~33 ~44~4~34 minecraft:tallgrass 0
setblock ~46~4~33 minecraft:tallgrass 0
fill ~46~6~33 ~46~6~51 minecraft:leaves 0
fill ~47~3~33 ~47~3~35 minecraft:grass
fill ~49~3~33 ~49~3~34 minecraft:log 0
fill ~50~3~33 ~51~3~33 minecraft:oak_stairs 2
fill ~52~3~33 ~53~3~33 minecraft:log 0
fill ~52~6~33 ~57~6~34 minecraft:leaves 0
fill ~52~7~33 ~54~7~37 minecraft:leaves 0
fill ~54~3~33 ~55~3~34 minecraft:grass
fill ~54~4~33 ~55~4~34 minecraft:tallgrass 0
fill ~54~5~33 ~56~5~34 minecraft:leaves 0
fill ~56~9~33 ~58~9~33 minecraft:leaves 0
fill ~57~10~33 ~57~10~35 minecraft:leaves 0
fill ~59~4~33 ~59~4~36 minecraft:tallgrass 0
fill ~59~8~33 ~60~8~34 minecraft:leaves 0
fill ~60~7~33 ~60~7~34 minecraft:leaves 0
fill ~62~3~33 ~62~3~37 minecraft:grass
fill ~62~4~33 ~62~4~34 minecraft:tallgrass 0
fill ~62~5~33 ~62~7~37 minecraft:leaves 0
fill ~65~7~33 ~66~7~33 minecraft:leaves 0
fill ~65~8~33 ~65~8~35 minecraft:leaves 0
fill ~68~4~33 ~68~4~39 minecraft:tallgrass 0
fill ~69~6~33 ~69~6~38 minecraft:leaves 0
fill ~70~8~33 ~70~9~33 minecraft:leaves 0
setblock ~71~4~33 minecraft:double_plant 2
fill ~77~3~33 ~77~3~35 minecraft:log 0
fill ~77~8~33 ~77~8~35 minecraft:leaves 0
fill ~78~9~33 ~80~9~33 minecraft:leaves 0
setblock ~79~3~33 minecraft:grass
setblock ~79~4~33 minecraft:tallgrass 0
fill ~79~10~33 ~79~10~35 minecraft:leaves 0
fill ~80~5~33 ~80~6~35 minecraft:leaves 0
fill ~81~4~33 ~81~4~35 minecraft:tallgrass 0
fill ~81~7~33 ~82~7~35 minecraft:leaves 0
fill ~82~8~33 ~82~8~38 minecraft:leaves 0
fill ~84~8~33 ~84~8~42 minecraft:leaves 0
fill ~85~5~33 ~86~5~36 minecraft:leaves 0
setblock ~86~8~33 minecraft:leaves 0
setblock ~87~3~33 minecraft:dirt 0
fill ~87~4~33 ~87~7~33 minecraft:log 0
fill ~88~5~33 ~89~5~38 minecraft:leaves 0
fill ~88~6~33 ~88~6~38 minecraft:leaves 0
fill ~88~7~33 ~88~7~34 minecraft:leaves 0
setblock ~88~8~33 minecraft:leaves 0
fill ~90~7~33 ~91~7~34 minecraft:leaves 0
fill ~91~8~33 ~91~8~35 minecraft:leaves 0
fill ~91~9~33 ~91~9~34 minecraft:leaves 0
setblock ~91~10~33 minecraft:leaves 0
setblock ~92~3~33 minecraft:dirt 0
fill ~92~4~33 ~92~9~33 minecraft:log 0
setblock ~93~4~33 minecraft:double_plant 2
fill ~93~9~33 ~94~9~33 minecraft:leaves 0
setblock ~93~10~33 minecraft:leaves 0
fill ~94~3~33 ~94~3~44 minecraft:grass
setblock ~95~3~33 minecraft:dirt 0
fill ~95~4~33 ~95~5~33 minecraft:log 0
fill ~96~9~33 ~96~9~35 minecraft:leaves 0
fill ~97~3~33 ~97~3~34 minecraft:log 0
fill ~97~8~33 ~97~8~34 minecraft:leaves 0
fill ~98~3~33 ~99~3~33 minecraft:oak_stairs 2
fill ~98~6~33 ~98~7~35 minecraft:leaves 0
fill ~100~3~33 ~104~3~33 minecraft:log 0
fill ~108~1~33 ~108~2~192 minecraft:stonebrick 0
fill ~109~2~33 ~109~99~34 minecraft:barrier
fill ~30~3~34 ~30~3~42 minecraft:grass
fill ~31~4~34 ~33~4~34 minecraft:tallgrass 0
fill ~32~7~34 ~32~8~41 minecraft:leaves 0
setblock ~34~4~34 minecraft:double_plant 2
fill ~34~9~34 ~34~10~35 minecraft:leaves 0
setblock ~35~3~34 minecraft:dirt 0
fill ~35~4~34 ~35~6~34 minecraft:log 0
setblock ~35~9~34 minecraft:log 0
fill ~36~9~34 ~36~9~35 minecraft:leaves 0
setblock ~36~10~34 minecraft:leaves 0
fill ~37~4~34 ~37~4~35 minecraft:tallgrass 0
setblock ~38~4~34 minecraft:double_plant 2
setblock ~41~4~34 minecraft:tallgrass 0
setblock ~43~4~34 minecraft:tallgrass 0
fill ~43~6~34 ~43~6~40 minecraft:leaves 0
setblock ~43~8~34 minecraft:leaves 0
setblock ~45~4~34 minecraft:tallgrass 0
fill ~45~7~34 ~48~7~35 minecraft:leaves 0
fill ~45~8~34 ~45~8~36 minecraft:leaves 0
fill ~47~4~34 ~48~4~34 minecraft:tallgrass 0
fill ~47~5~34 ~47~6~35 minecraft:leaves 0
fill ~48~3~34 ~48~3~43 minecraft:grass
fill ~48~6~34 ~48~6~38 minecraft:leaves 0
fill ~50~3~34 ~52~3~34 minecraft:log 0
fill ~53~3~34 ~53~3~40 minecraft:grass
fill ~53~4~34 ~53~4~36 minecraft:tallgrass 0
fill ~53~5~34 ~53~5~36 minecraft:leaves 0
fill ~53~8~34 ~56~8~36 minecraft:leaves 0
fill ~54~9~34 ~54~9~36 minecraft:leaves 0
fill ~55~7~34 ~56~7~34 minecraft:leaves 0
setblock ~56~4~34 minecraft:tallgrass 0
fill ~56~9~34 ~56~10~34 minecraft:leaves 0
setblock ~57~3~34 minecraft:dirt 0
setblock ~57~4~34 minecraft:log 0
fill ~57~5~34 ~57~5~39 minecraft:leaves 0
fill ~57~7~34 ~57~9~34 minecraft:log 0
fill ~58~4~34 ~58~4~39 minecraft:tallgrass 0
fill ~58~7~34 ~59~7~36 minecraft:leaves 0
fill ~58~8~34 ~58~8~37 minecraft:leaves 0
fill ~58~9~34 ~58~9~35 minecraft:leaves 0
setblock ~58~10~34 minecraft:leaves 0
fill ~60~9~34 ~61~9~34 minecraft:leaves 0
fill ~60~10~34 ~60~10~36 minecraft:leaves 0
fill ~61~4~34 ~61~4~35 minecraft:tallgrass 0
setblock ~63~4~34 minecraft:tallgrass 0
fill ~63~7~34 ~64~7~34 minecraft:leaves 0
fill ~64~8~34 ~64~8~36 minecraft:leaves 0
setblock ~65~3~34 minecraft:dirt 0
setblock ~65~4~34 minecraft:log 0
setblock ~65~7~34 minecraft:log 0
fill ~66~7~34 ~66~7~35 minecraft:leaves 0
setblock ~66~8~34 minecraft:leaves 0
fill ~69~4~34 ~69~4~38 minecraft:tallgrass 0
fill ~69~8~34 ~69~9~34 minecraft:leaves 0
setblock ~70~3~34 minecraft:dirt 0
fill ~70~4~34 ~70~8~34 minecraft:log 0
fill ~70~9~34 ~71~9~34 minecraft:leaves 0
setblock ~71~3~34 minecraft:grass
setblock ~71~8~34 minecraft:leaves 0
fill ~77~7~34 ~78~7~36 minecraft:leaves 0
setblock ~78~3~34 minecraft:grass
fill ~78~8~34 ~78~8~36 minecraft:leaves 0
fill ~78~9~34 ~78~9~35 minecraft:leaves 0
setblock ~78~10~34 minecraft:leaves 0
setblock ~79~3~34 minecraft:dirt 0
fill ~79~4~34 ~79~9~34 minecraft:log 0
fill ~80~7~34 ~80~7~40 minecraft:leaves 0
fill ~80~8~34 ~81~8~35 minecraft:leaves 0
fill ~80~9~34 ~80~9~37 minecraft:leaves 0
setblock ~80~10~34 minecraft:leaves 0
setblock ~82~3~34 minecraft:dirt 0
setblock ~82~4~34 minecraft:log 0
fill ~83~5~34 ~83~5~36 minecraft:leaves 0
fill ~83~8~34 ~83~8~38 minecraft:leaves 0
setblock ~84~3~34 minecraft:dirt 0
fill ~84~4~34 ~84~5~34 minecraft:log 0
fill ~85~7~34 ~85~7~42 minecraft:leaves 0
setblock ~85~8~34 minecraft:leaves 0
fill ~87~3~34 ~87~3~40 minecraft:grass
fill ~87~5~34 ~87~6~35 minecraft:leaves 0
setblock ~87~7~34 minecraft:leaves 0
fill ~89~4~34 ~89~4~36 minecraft:tallgrass 0
fill ~92~3~34 ~92~3~43 minecraft:grass
fill ~92~4~34 ~93~4~35 minecraft:tallgrass 0
fill ~92~7~34 ~92~7~46 minecraft:leaves 0
fill ~92~8~34 ~92~8~35 minecraft:leaves 0
setblock ~92~9~34 minecraft:leaves 0
fill ~95~3~34 ~95~3~48 minecraft:grass
setblock ~96~3~34 minecraft:dirt 0
fill ~96~4~34 ~96~8~34 minecraft:log 0
fill ~97~6~34 ~97~7~38 minecraft:leaves 0
setblock ~97~9~34 minecraft:leaves 0
fill ~98~3~34 ~100~3~34 minecraft:log 0
fill ~101~3~34 ~103~3~36 minecraft:grass
fill ~102~4~34 ~102~4~36 minecraft:tallgrass 0
fill ~103~4~34 ~103~4~35 minecraft:double_plant 2
fill ~104~3~34 ~105~3~34 minecraft:log 0
fill ~23~2~35 ~23~99~36 minecraft:barrier
fill ~24~1~35 ~24~2~195 minecraft:stonebrick 0
fill ~28~3~35 ~28~3~36 minecraft:log 0
setblock ~30~4~35 minecraft:double_plant 2
fill ~31~4~35 ~31~4~36 minecraft:tallgrass 0
fill ~33~9~35 ~33~9~37 minecraft:leaves 0
fill ~35~3~35 ~35~3~41 minecraft:grass
fill ~35~9~35 ~35~9~36 minecraft:leaves 0
setblock ~36~4~35 minecraft:tallgrass 0
fill ~38~4~35 ~38~4~37 minecraft:tallgrass 0
fill ~43~5~35 ~44~5~41 minecraft:leaves 0
fill ~44~7~35 ~44~8~35 minecraft:leaves 0
setblock ~45~3~35 minecraft:dirt 0
fill ~45~4~35 ~45~5~35 minecraft:log 0
fill ~46~4~35 ~47~4~35 minecraft:tallgrass 0
fill ~46~5~35 ~46~5~51 minecraft:leaves 0
fill ~46~8~35 ~47~8~35 minecraft:leaves 0
fill ~47~9~35 ~47~9~37 minecraft:leaves 0
setblock ~48~4~35 minecraft:double_plant 2
fill ~49~3~35 ~52~3~44 minecraft:grass
fill ~49~4~35 ~51~4~35 minecraft:tallgrass 0
fill ~49~6~35 ~49~7~38 minecraft:leaves 0
setblock ~52~4~35 minecraft:double_plant 2
fill ~52~6~35 ~54~6~36 minecraft:leaves 0
setblock ~53~9~35 minecraft:leaves 0
fill ~54~3~35 ~55~3~35 minecraft:dirt 0
fill ~54~4~35 ~55~4~35 minecraft:log 0
fill ~54~5~35 ~54~5~37 minecraft:leaves 0
fill ~55~5~35 ~55~7~35 minecraft:log 0
setblock ~55~9~35 minecraft:leaves 0
fill ~56~5~35 ~56~6~37 minecraft:leaves 0
fill ~56~7~35 ~57~7~36 minecraft:leaves 0
fill ~57~3~35 ~57~3~44 minecraft:grass
fill ~57~4~35 ~57~4~43 minecraft:tallgrass 0
fill ~57~6~35 ~60~6~36 minecraft:leaves 0
fill ~57~8~35 ~57~8~36 minecraft:leaves 0
setblock ~57~9~35 minecraft:leaves 0
fill ~58~5~35 ~60~5~36 minecraft:leaves 0
fill ~59~8~35 ~59~8~38 minecraft:leaves 0
fill ~59~9~35 ~59~9~36 minecraft:leaves 0
setblock ~59~10~35 minecraft:leaves 0
setblock ~60~3~35 minecraft:dirt 0
setblock ~60~4~35 minecraft:log 0
fill ~60~7~35 ~60~9~35 minecraft:log 0
fill ~61~9~35 ~61~9~36 minecraft:leaves 0
setblock ~61~10~35 minecraft:leaves 0
fill ~63~3~35 ~63~3~41 minecraft:grass
fill ~63~5~35 ~63~5~37 minecraft:leaves 0
fill ~63~7~35 ~63~7~40 minecraft:leaves 0
setblock ~63~8~35 minecraft:leaves 0
setblock ~64~3~35 minecraft:dirt 0
fill ~64~4~35 ~64~7~35 minecraft:log 0
fill ~65~3~35 ~65~3~40 minecraft:grass
fill ~65~4~35 ~65~4~40 minecraft:tallgrass 0
setblock ~65~7~35 minecraft:leaves 0
setblock ~67~4~35 minecraft:tallgrass 0
fill ~70~3~35 ~70~3~37 minecraft:grass
setblock ~70~4~35 minecraft:tallgrass 0
fill ~70~6~35 ~70~6~40 minecraft:leaves 0
fill ~70~7~35 ~70~7~37 minecraft:leaves 0
fill ~70~8~35 ~70~9~35 minecraft:leaves 0
fill ~71~3~35 ~71~3~38 minecraft:log 0
fill ~78~3~35 ~78~3~36 minecraft:log 0
setblock ~79~3~35 minecraft:grass
setblock ~79~4~35 minecraft:tallgrass 0
fill ~79~7~35 ~79~7~42 minecraft:leaves 0
fill ~79~8~35 ~79~8~37 minecraft:leaves 0
setblock ~79~9~35 minecraft:leaves 0
fill ~81~9~35 ~82~9~35 minecraft:leaves 0
fill ~81~10~35 ~81~10~37 minecraft:leaves 0
fill ~82~3~35 ~82~3~42 minecraft:grass
setblock ~82~4~35 minecraft:tallgrass 0
setblock ~84~3~35 minecraft:grass
setblock ~84~5~35 minecraft:leaves 0
fill ~84~9~35 ~84~9~37 minecraft:leaves 0
fill ~85~4~35 ~86~4~35 minecraft:tallgrass 0
fill ~90~5~35 ~91~6~36 minecraft:leaves 0
fill ~91~7~35 ~91~7~40 minecraft:leaves 0
fill ~92~6~35 ~92~6~40 minecraft:leaves 0
setblock ~95~4~35 minecraft:tallgrass 0
fill ~96~3~35 ~100~3~38 minecraft:grass
fill ~96~6~35 ~96~7~41 minecraft:leaves 0
setblock ~96~8~35 minecraft:leaves 0
fill ~99~4~35 ~101~4~35 minecraft:tallgrass 0
fill ~99~8~35 ~103~8~36 minecraft:leaves 0
fill ~100~7~35 ~102~7~36 minecraft:leaves 0
fill ~104~3~35 ~104~3~46 minecraft:grass
fill ~104~4~35 ~104~4~39 minecraft:tallgrass 0
fill ~105~3~35 ~105~3~36 minecraft:log 0
fill ~109~1~35 ~109~2~192 minecraft:stonebrick 0
fill ~110~2~35 ~110~99~36 minecraft:barrier
fill ~27~3~36 ~27~3~39 minecraft:log 0
fill ~29~3~36 ~29~3~40 minecraft:grass
fill ~29~4~36 ~30~4~37 minecraft:tallgrass 0
fill ~32~4~36 ~33~4~36 minecraft:tallgrass 0
fill ~33~8~36 ~33~8~44 minecraft:leaves 0
fill ~33~10~36 ~34~10~36 minecraft:leaves 0
setblock ~34~3~36 minecraft:dirt 0
fill ~34~4~36 ~34~9~36 minecraft:log 0
setblock ~40~4~36 minecraft:double_plant 2
fill ~41~4~36 ~41~4~37 minecraft:tallgrass 0
fill ~43~4~36 ~46~4~36 minecraft:tallgrass 0
fill ~45~3~36 ~45~3~38 minecraft:grass
fill ~45~5~36 ~45~5~38 minecraft:leaves 0
fill ~45~7~36 ~46~7~38 minecraft:leaves 0
fill ~46~8~36 ~46~9~36 minecraft:leaves 0
setblock ~47~3~36 minecraft:dirt 0
fill ~47~4~36 ~47~8~36 minecraft:log 0
fill ~48~4~36 ~48~4~38 minecraft:tallgrass 0
fill ~48~7~36 ~48~7~38 minecraft:leaves 0
fill ~48~8~36 ~48~9~36 minecraft:leaves 0
setblock ~49~4~36 minecraft:double_plant 2
fill ~50~4~36 ~50~4~38 minecraft:tallgrass 0
setblock ~52~4~36 minecraft:tallgrass 0
fill ~54~3~36 ~55~3~46 minecraft:grass
fill ~54~4~36 ~56~4~36 minecraft:tallgrass 0
fill ~55~5~36 ~55~7~37 minecraft:leaves 0
fill ~60~3~36 ~60~3~42 minecraft:grass
fill ~60~7~36 ~60~7~40 minecraft:leaves 0
fill ~60~8~36 ~60~8~37 minecraft:leaves 0
setblock ~60~9~36 minecraft:leaves 0
fill ~61~5~36 ~61~6~38 minecraft:leaves 0
fill ~64~3~36 ~64~3~41 minecraft:grass
fill ~64~4~36 ~64~4~39 minecraft:tallgrass 0
fill ~64~5~36 ~64~7~37 minecraft:leaves 0
fill ~66~4~36 ~66~4~37 minecraft:tallgrass 0
setblock ~70~4~36 minecraft:double_plant 2
fill ~71~7~36 ~71~7~40 minecraft:leaves 0
fill ~72~3~36 ~72~3~37 minecraft:oak_stairs 1
fill ~79~3~36 ~79~3~40 minecraft:log 0
setblock ~80~6~36 minecraft:leaves 0
fill ~80~8~36 ~80~8~38 minecraft:leaves 0
setblock ~80~10~36 minecraft:leaves 0
setblock ~81~3~36 minecraft:dirt 0
fill ~81~4~36 ~81~9~36 minecraft:log 0
fill ~82~7~36 ~82~7~43 minecraft:leaves 0
fill ~82~9~36 ~83~9~36 minecraft:leaves 0
setblock ~82~10~36 minecraft:leaves 0
setblock ~84~3~36 minecraft:dirt 0
fill ~84~4~36 ~84~7~36 minecraft:log 0
fill ~85~4~36 ~85~4~40 minecraft:tallgrass 0
fill ~85~8~36 ~87~8~37 minecraft:leaves 0
fill ~85~9~36 ~85~9~39 minecraft:leaves 0
setblock ~87~4~36 minecraft:tallgrass 0
fill ~87~7~36 ~87~7~40 minecraft:leaves 0
fill ~89~7~36 ~90~7~36 minecraft:leaves 0
fill ~92~4~36 ~92~4~39 minecraft:tallgrass 0
fill ~92~5~36 ~92~5~39 minecraft:leaves 0
fill ~95~4~36 ~95~4~37 minecraft:double_plant 2
fill ~96~4~36 ~98~4~36 minecraft:tallgrass 0
fill ~98~7~36 ~99~7~41 minecraft:leaves 0
setblock ~99~4~36 minecraft:double_plant 2
fill ~100~4~36 ~101~4~36 minecraft:tallgrass 0
fill ~100~9~36 ~102~9~36 minecraft:leaves 0
fill ~101~10~36 ~101~10~38 minecraft:leaves 0
fill ~103~7~36 ~103~7~38 minecraft:leaves 0
fill ~106~3~36 ~106~3~38 minecraft:log 0
fill ~21~2~37 ~22~99~37 minecraft:barrier
fill ~23~1~37 ~23~2~195 minecraft:stonebrick 0
fill ~28~3~37 ~28~3~38 minecraft:grass
setblock ~28~4~37 minecraft:tallgrass 0
setblock ~31~4~37 minecraft:double_plant 2
setblock ~32~4~37 minecraft:tallgrass 0
fill ~34~3~37 ~34~3~50 minecraft:grass
fill ~34~4~37 ~35~4~39 minecraft:tallgrass 0
fill ~34~7~37 ~34~7~44 minecraft:leaves 0
fill ~34~8~37 ~34~8~38 minecraft:leaves 0
fill ~34~9~37 ~34~10~37 minecraft:leaves 0
setblock ~36~4~37 minecraft:double_plant 2
setblock ~37~4~37 minecraft:tallgrass 0
fill ~40~6~37 ~42~7~38 minecraft:leaves 0
fill ~43~4~37 ~45~4~38 minecraft:tallgrass 0
fill ~43~7~37 ~43~7~41 minecraft:leaves 0
fill ~47~3~37 ~47~3~56 minecraft:grass
fill ~47~6~37 ~47~6~41 minecraft:leaves 0
fill ~47~7~37 ~47~7~38 minecraft:leaves 0
setblock ~47~8~37 minecraft:leaves 0
fill ~53~6~37 ~54~6~37 minecraft:leaves 0
fill ~55~4~37 ~56~4~37 minecraft:tallgrass 0
fill ~57~6~37 ~58~6~38 minecraft:leaves 0
fill ~58~5~37 ~58~5~39 minecraft:leaves 0
fill ~58~7~37 ~58~7~38 minecraft:leaves 0
setblock ~59~3~37 minecraft:dirt 0
fill ~59~4~37 ~59~7~37 minecraft:log 0
fill ~60~5~37 ~60~6~39 minecraft:leaves 0
fill ~61~4~37 ~62~4~37 minecraft:tallgrass 0
fill ~62~9~37 ~62~9~39 minecraft:leaves 0
fill ~63~8~37 ~63~8~39 minecraft:leaves 0
fill ~67~4~37 ~67~4~40 minecraft:tallgrass 0
fill ~67~6~37 ~67~6~40 minecraft:leaves 0
fill ~68~5~37 ~70~5~38 minecraft:leaves 0
setblock ~70~4~37 minecraft:tallgrass 0
fill ~70~8~37 ~71~8~37 minecraft:leaves 0
fill ~70~9~37 ~70~9~39 minecraft:leaves 0
fill ~72~7~37 ~72~7~39 minecraft:leaves 0
fill ~73~2~37 ~74~2~77 minecraft:stonebrick 0
setblock ~75~2~37 minecraft:sea_lantern
fill ~78~3~37 ~78~3~39 minecraft:oak_stairs 0
setblock ~80~4~37 minecraft:double_plant 2
fill ~81~3~37 ~81~3~42 minecraft:grass
fill ~81~7~37 ~81~7~42 minecraft:leaves 0
fill ~81~8~37 ~81~8~38 minecraft:leaves 0
fill ~81~9~37 ~82~9~37 minecraft:leaves 0
fill ~82~4~37 ~84~4~38 minecraft:tallgrass 0
fill ~82~6~37 ~82~6~43 minecraft:leaves 0
fill ~84~3~37 ~84~3~41 minecraft:grass
fill ~84~6~37 ~84~7~43 minecraft:leaves 0
setblock ~86~4~37 minecraft:tallgrass 0
fill ~86~9~37 ~87~9~37 minecraft:leaves 0
fill ~86~10~37 ~86~10~39 minecraft:leaves 0
setblock ~87~4~37 minecraft:double_plant 2
fill ~88~7~37 ~89~7~38 minecraft:leaves 0
fill ~88~8~37 ~89~8~37 minecraft:leaves 0
setblock ~90~3~37 minecraft:dirt 0
fill ~90~4~37 ~90~7~37 minecraft:log 0
setblock ~91~4~37 minecraft:tallgrass 0
fill ~91~5~37 ~91~6~39 minecraft:leaves 0
fill ~91~8~37 ~94~8~37 minecraft:leaves 0
setblock ~93~4~37 minecraft:tallgrass 0
fill ~93~9~37 ~93~9~39 minecraft:leaves 0
fill ~96~4~37 ~96~4~38 minecraft:tallgrass 0
fill ~97~4~37 ~98~4~37 minecraft:double_plant 2
fill ~98~6~37 ~98~6~43 minecraft:leaves 0
fill ~99~4~37 ~100~4~37 minecraft:tallgrass 0
fill ~99~8~37 ~100~8~38 minecraft:leaves 0
fill ~100~7~37 ~100~7~39 minecraft:leaves 0
fill ~100~9~37 ~100~9~38 minecraft:leaves 0
setblock ~100~10~37 minecraft:leaves 0
setblock ~101~3~37 minecraft:dirt 0
fill ~101~4~37 ~101~9~37 minecraft:log 0
fill ~102~3~37 ~103~3~47 minecraft:grass
fill ~102~7~37 ~102~8~39 minecraft:leaves 0
fill ~102~9~37 ~102~10~37 minecraft:leaves 0
fill ~103~8~37 ~103~8~38 minecraft:leaves 0
fill ~105~3~37 ~105~3~43 minecraft:grass
fill ~110~1~37 ~110~2~191 minecraft:stonebrick 0
fill ~111~2~37 ~111~99~38 minecraft:barrier
fill ~19~2~38 ~20~6~39 minecraft:barrier
fill ~19~7~38 ~20~99~38 minecraft:barrier
fill ~21~1~38 ~22~1~195 minecraft:stonebrick 0
fill ~21~2~38 ~22~2~156 minecraft:stonebrick 0
fill ~30~4~38 ~31~4~42 minecraft:tallgrass 0
fill ~30~5~38 ~35~6~39 minecraft:leaves 0
fill ~36~4~38 ~36~4~40 minecraft:tallgrass 0
setblock ~36~8~38 minecraft:leaves 0
fill ~39~4~38 ~40~4~39 minecraft:tallgrass 0
fill ~39~6~38 ~39~7~45 minecraft:leaves 0
fill ~41~8~38 ~41~9~38 minecraft:leaves 0
fill ~42~4~38 ~42~4~39 minecraft:tallgrass 0
fill ~45~8~38 ~45~8~40 minecraft:leaves 0
fill ~47~5~38 ~47~5~41 minecraft:leaves 0
setblock ~49~4~38 minecraft:tallgrass 0
fill ~52~4~38 ~52~4~44 minecraft:tallgrass 0
setblock ~53~4~38 minecraft:double_plant 2
setblock ~54~4~38 minecraft:tallgrass 0
setblock ~56~4~38 minecraft:double_plant 2
fill ~59~3~38 ~59~3~42 minecraft:grass
setblock ~59~4~38 minecraft:tallgrass 0
fill ~59~5~38 ~59~6~39 minecraft:leaves 0
setblock ~59~7~38 minecraft:leaves 0
fill ~61~4~38 ~61~4~42 minecraft:tallgrass 0
setblock ~61~9~38 minecraft:leaves 0
setblock ~62~3~38 minecraft:dirt 0
fill ~62~4~38 ~62~8~38 minecraft:log 0
fill ~63~4~38 ~63~4~39 minecraft:tallgrass 0
setblock ~63~9~38 minecraft:leaves 0
fill ~64~6~38 ~64~7~39 minecraft:leaves 0
setblock ~66~4~38 minecraft:double_plant 2
fill ~67~5~38 ~67~5~40 minecraft:leaves 0
fill ~69~8~38 ~69~8~40 minecraft:leaves 0
setblock ~69~9~38 minecraft:leaves 0
setblock ~70~3~38 minecraft:dirt 0
setblock ~70~4~38 minecraft:log 0
fill ~70~7~38 ~70~8~38 minecraft:log 0
fill ~71~5~38 ~71~5~40 minecraft:leaves 0
fill ~71~8~38 ~71~9~38 minecraft:leaves 0
fill ~72~3~38 ~72~3~40 minecraft:log 0
fill ~75~2~38 ~75~2~91 minecraft:stonebrick 0
fill ~81~4~38 ~81~4~40 minecraft:tallgrass 0
fill ~85~8~38 ~85~8~40 minecraft:leaves 0
setblock ~85~10~38 minecraft:leaves 0
setblock ~86~3~38 minecraft:dirt 0
fill ~86~4~38 ~86~9~38 minecraft:log 0
fill ~87~4~38 ~87~4~39 minecraft:tallgrass 0
fill ~87~8~38 ~88~8~39 minecraft:leaves 0
fill ~87~9~38 ~87~9~39 minecraft:leaves 0
setblock ~87~10~38 minecraft:leaves 0
fill ~89~4~38 ~89~4~39 minecraft:tallgrass 0
fill ~90~3~38 ~90~3~41 minecraft:grass
fill ~90~5~38 ~90~7~39 minecraft:leaves 0
fill ~92~8~38 ~92~8~46 minecraft:leaves 0
setblock ~92~9~38 minecraft:leaves 0
setblock ~93~3~38 minecraft:dirt 0
fill ~93~4~38 ~93~8~38 minecraft:log 0
fill ~94~8~38 ~94~8~39 minecraft:leaves 0
setblock ~94~9~38 minecraft:leaves 0
fill ~96~8~38 ~98~8~38 minecraft:leaves 0
fill ~96~9~38 ~97~9~40 minecraft:leaves 0
setblock ~97~4~38 minecraft:tallgrass 0
setblock ~99~4~38 minecraft:tallgrass 0
fill ~99~6~38 ~99~6~44 minecraft:leaves 0
fill ~101~3~38 ~101~3~48 minecraft:grass
setblock ~101~4~38 minecraft:double_plant 2
fill ~101~7~38 ~101~8~39 minecraft:leaves 0
setblock ~101~9~38 minecraft:leaves 0
fill ~103~4~38 ~103~4~39 minecraft:double_plant 2
fill ~107~3~38 ~107~3~40 minecraft:log 0
fill ~18~7~39 ~22~7~40 minecraft:leaves 0
fill ~18~8~39 ~21~8~40 minecraft:leaves 0
fill ~19~9~39 ~20~99~39 minecraft:barrier
fill ~28~3~39 ~28~3~41 minecraft:log 0
fill ~29~4~39 ~29~4~40 minecraft:tallgrass 0
setblock ~32~4~39 minecraft:tallgrass 0
fill ~37~4~39 ~38~4~39 minecraft:tallgrass 0
fill ~40~6~39 ~40~7~48 minecraft:leaves 0
fill ~40~8~39 ~40~8~40 minecraft:leaves 0
fill ~40~9~39 ~42~9~39 minecraft:leaves 0
setblock ~41~3~39 minecraft:dirt 0
fill ~41~4~39 ~41~8~39 minecraft:log 0
fill ~42~6~39 ~42~7~41 minecraft:leaves 0
fill ~42~8~39 ~42~8~40 minecraft:leaves 0
fill ~43~4~39 ~44~4~39 minecraft:tallgrass 0
fill ~44~7~39 ~44~8~39 minecraft:leaves 0
setblock ~45~3~39 minecraft:dirt 0
fill ~45~4~39 ~45~7~39 minecraft:log 0
fill ~46~4~39 ~47~4~39 minecraft:tallgrass 0
fill ~46~7~39 ~46~7~40 minecraft:leaves 0
setblock ~46~8~39 minecraft:leaves 0
setblock ~51~4~39 minecraft:tallgrass 0
fill ~52~6~39 ~55~7~40 minecraft:leaves 0
fill ~55~4~39 ~56~4~39 minecraft:tallgrass 0
setblock ~58~6~39 minecraft:leaves 0
fill ~60~4~39 ~60~4~40 minecraft:tallgrass 0
fill ~61~6~39 ~62~6~40 minecraft:leaves 0
fill ~62~3~39 ~62~3~41 minecraft:grass
fill ~62~4~39 ~62~4~40 minecraft:double_plant 2
fill ~62~7~39 ~62~7~40 minecraft:leaves 0
setblock ~62~8~39 minecraft:leaves 0
fill ~66~4~39 ~66~4~40 minecraft:tallgrass 0
fill ~68~5~39 ~68~5~40 minecraft:leaves 0
fill ~68~7~39 ~68~7~40 minecraft:leaves 0
setblock ~68~8~39 minecraft:leaves 0
setblock ~69~3~39 minecraft:dirt 0
fill ~69~4~39 ~69~7~39 minecraft:log 0
fill ~70~3~39 ~71~3~40 minecraft:grass
fill ~70~4~39 ~71~4~40 minecraft:tallgrass 0
fill ~70~5~39 ~70~5~40 minecraft:leaves 0
fill ~70~7~39 ~70~7~40 minecraft:leaves 0
setblock ~70~8~39 minecraft:leaves 0
fill ~78~6~39 ~81~6~40 minecraft:leaves 0
fill ~78~7~39 ~78~7~41 minecraft:leaves 0
setblock ~82~4~39 minecraft:double_plant 2
fill ~83~4~39 ~84~4~39 minecraft:tallgrass 0
fill ~86~3~39 ~86~3~40 minecraft:grass
fill ~86~4~39 ~86~4~40 minecraft:tallgrass 0
fill ~86~7~39 ~86~8~40 minecraft:leaves 0
setblock ~86~9~39 minecraft:leaves 0
setblock ~88~4~39 minecraft:double_plant 2
setblock ~88~7~39 minecraft:leaves 0
setblock ~89~5~39 minecraft:leaves 0
fill ~90~4~39 ~91~4~40 minecraft:tallgrass 0
fill ~91~8~39 ~91~8~40 minecraft:leaves 0
fill ~93~3~39 ~93~3~44 minecraft:grass
setblock ~93~4~39 minecraft:tallgrass 0
fill ~93~6~39 ~93~8~40 minecraft:leaves 0
setblock ~94~4~39 minecraft:double_plant 2
setblock ~95~4~39 minecraft:tallgrass 0
fill ~95~8~39 ~96~8~39 minecraft:leaves 0
setblock ~95~9~39 minecraft:leaves 0
fill ~96~3~39 ~97~3~39 minecraft:dirt 0
fill ~96~4~39 ~97~5~39 minecraft:log 0
fill ~97~6~39 ~97~8~39 minecraft:log 0
fill ~98~3~39 ~100~3~41 minecraft:grass
fill ~98~4~39 ~99~4~39 minecraft:double_plant 2
fill ~98~8~39 ~98~9~39 minecraft:leaves 0
fill ~100~4~39 ~102~4~40 minecraft:tallgrass 0
setblock ~100~8~39 minecraft:leaves 0
fill ~105~4~39 ~105~4~43 minecraft:tallgrass 0
fill ~106~3~39 ~106~3~43 minecraft:grass
fill ~106~5~39 ~109~6~40 minecraft:leaves 0
fill ~111~1~39 ~111~2~191 minecraft:stonebrick 0
fill ~112~2~39 ~112~99~42 minecraft:barrier
fill ~17~2~40 ~18~6~40 minecraft:barrier
fill ~17~7~40 ~17~99~40 minecraft:barrier
fill ~18~9~40 ~18~99~40 minecraft:barrier
fill ~19~1~40 ~20~2~194 minecraft:stonebrick 0
fill ~19~3~40 ~21~3~40 minecraft:log 0
fill ~20~9~40 ~20~10~40 minecraft:leaves 0
fill ~22~3~40 ~23~3~40 minecraft:oak_stairs 2
fill ~22~8~40 ~22~8~46 minecraft:leaves 0
setblock ~24~3~40 minecraft:wall_sign 5
fill ~30~5~40 ~32~5~42 minecraft:leaves 0
fill ~30~6~40 ~32~6~41 minecraft:leaves 0
fill ~31~7~40 ~31~8~40 minecraft:leaves 0
fill ~32~3~40 ~33~3~40 minecraft:dirt 0
fill ~32~4~40 ~33~4~40 minecraft:log 0
fill ~33~5~40 ~33~6~40 minecraft:log 0
fill ~34~5~40 ~35~6~41 minecraft:leaves 0
fill ~34~8~40 ~36~8~41 minecraft:leaves 0
fill ~35~7~40 ~37~7~41 minecraft:leaves 0
fill ~38~4~40 ~39~4~40 minecraft:tallgrass 0
setblock ~40~4~40 minecraft:double_plant 2
fill ~41~3~40 ~41~3~53 minecraft:grass
fill ~41~4~40 ~41~4~50 minecraft:tallgrass 0
fill ~41~6~40 ~41~7~41 minecraft:leaves 0
fill ~41~8~40 ~41~9~40 minecraft:leaves 0
fill ~45~3~40 ~45~3~43 minecraft:grass
fill ~45~4~40 ~46~4~41 minecraft:tallgrass 0
fill ~45~5~40 ~45~6~45 minecraft:leaves 0
setblock ~45~7~40 minecraft:leaves 0
setblock ~48~4~40 minecraft:tallgrass 0
fill ~50~4~40 ~50~4~45 minecraft:tallgrass 0
setblock ~51~4~40 minecraft:double_plant 2
fill ~51~6~40 ~51~7~44 minecraft:leaves 0
setblock ~53~4~40 minecraft:tallgrass 0
fill ~53~8~40 ~54~8~40 minecraft:leaves 0
fill ~53~9~40 ~53~9~42 minecraft:leaves 0
setblock ~55~4~40 minecraft:tallgrass 0
fill ~59~4~40 ~59~4~42 minecraft:tallgrass 0
fill ~63~4~40 ~63~4~41 minecraft:double_plant 2
setblock ~64~7~40 minecraft:leaves 0
setblock ~69~3~40 minecraft:grass
fill ~69~5~40 ~69~7~40 minecraft:leaves 0
setblock ~73~3~40 minecraft:log 0
fill ~78~3~40 ~78~3~41 minecraft:log 0
fill ~80~8~40 ~80~9~40 minecraft:leaves 0
fill ~82~4~40 ~83~4~40 minecraft:tallgrass 0
fill ~83~8~40 ~83~9~40 minecraft:leaves 0
setblock ~87~4~40 minecraft:double_plant 2
setblock ~87~8~40 minecraft:leaves 0
setblock ~88~4~40 minecraft:tallgrass 0
setblock ~89~4~40 minecraft:double_plant 2
fill ~89~7~40 ~90~7~43 minecraft:leaves 0
fill ~89~8~40 ~89~8~42 minecraft:leaves 0
fill ~90~9~40 ~91~9~40 minecraft:leaves 0
setblock ~91~6~40 minecraft:leaves 0
fill ~91~10~40 ~91~10~42 minecraft:leaves 0
setblock ~93~4~40 minecraft:double_plant 2
fill ~96~3~40 ~97~3~45 minecraft:grass
fill ~96~8~40 ~97~8~40 minecraft:leaves 0
fill ~97~6~40 ~97~7~41 minecraft:leaves 0
fill ~98~4~40 ~99~4~40 minecraft:tallgrass 0
fill ~99~5~40 ~101~5~41 minecraft:leaves 0
fill ~100~6~40 ~101~6~41 minecraft:leaves 0
fill ~103~4~40 ~103~4~47 minecraft:tallgrass 0
setblock ~104~4~40 minecraft:double_plant 2
fill ~105~5~40 ~105~6~43 minecraft:leaves 0
fill ~106~4~40 ~106~4~43 minecraft:tallgrass 0
fill ~107~7~40 ~107~8~40 minecraft:leaves 0
fill ~108~3~40 ~108~3~43 minecraft:log 0
fill ~15~2~41 ~16~99~41 minecraft:barrier
fill ~17~1~41 ~18~2~192 minecraft:stonebrick 0
fill ~17~3~41 ~19~3~41 minecraft:log 0
fill ~18~7~41 ~19~7~49 minecraft:leaves 0
fill ~18~8~41 ~19~8~43 minecraft:leaves 0
fill ~19~9~41 ~19~10~41 minecraft:leaves 0
setblock ~20~3~41 minecraft:dirt 0
fill ~20~4~41 ~20~9~41 minecraft:log 0
fill ~20~10~41 ~21~10~41 minecraft:leaves 0
fill ~21~3~41 ~23~3~41 minecraft:log 0
fill ~21~7~41 ~22~7~50 minecraft:leaves 0
fill ~21~8~41 ~21~8~43 minecraft:leaves 0
fill ~21~9~41 ~21~9~42 minecraft:leaves 0
fill ~29~3~41 ~29~3~43 minecraft:log 0
fill ~32~3~41 ~33~3~47 minecraft:grass
fill ~32~4~41 ~32~4~43 minecraft:tallgrass 0
fill ~33~5~41 ~33~6~42 minecraft:leaves 0
fill ~34~9~41 ~35~9~41 minecraft:leaves 0
fill ~35~10~41 ~35~10~43 minecraft:leaves 0
fill ~36~6~41 ~38~6~42 minecraft:leaves 0
fill ~37~8~41 ~37~8~43 minecraft:leaves 0
fill ~38~4~41 ~38~4~42 minecraft:tallgrass 0
fill ~38~7~41 ~38~7~42 minecraft:leaves 0
setblock ~39~4~41 minecraft:double_plant 2
fill ~40~4~41 ~40~4~43 minecraft:tallgrass 0
fill ~42~4~41 ~43~4~44 minecraft:tallgrass 0
setblock ~47~4~41 minecraft:tallgrass 0
setblock ~49~4~41 minecraft:tallgrass 0
fill ~52~6~41 ~52~7~47 minecraft:leaves 0
fill ~52~8~41 ~52~9~41 minecraft:leaves 0
setblock ~53~3~41 minecraft:dirt 0
fill ~53~4~41 ~53~8~41 minecraft:log 0
setblock ~54~4~41 minecraft:tallgrass 0
fill ~54~6~41 ~55~6~43 minecraft:leaves 0
fill ~54~7~41 ~55~7~42 minecraft:leaves 0
fill ~54~8~41 ~54~9~41 minecraft:leaves 0
fill ~56~4~41 ~56~4~45 minecraft:tallgrass 0
setblock ~58~4~41 minecraft:tallgrass 0
setblock ~60~4~41 minecraft:double_plant 2
setblock ~62~4~41 minecraft:tallgrass 0
setblock ~64~4~41 minecraft:tallgrass 0
fill ~65~3~41 ~75~21~41 minecraft:stone 6
fill ~78~6~41 ~79~6~41 minecraft:leaves 0
fill ~79~3~41 ~79~3~42 minecraft:grass
fill ~79~8~41 ~79~9~41 minecraft:leaves 0
setblock ~80~3~41 minecraft:dirt 0
fill ~80~4~41 ~80~8~41 minecraft:log 0
fill ~80~9~41 ~84~9~41 minecraft:leaves 0
fill ~81~4~41 ~81~4~42 minecraft:double_plant 2
fill ~81~6~41 ~81~6~42 minecraft:leaves 0
fill ~81~8~41 ~82~8~41 minecraft:leaves 0
fill ~82~4~41 ~82~4~42 minecraft:tallgrass 0
setblock ~83~3~41 minecraft:dirt 0
fill ~83~4~41 ~83~8~41 minecraft:log 0
fill ~85~3~41 ~88~3~41 minecraft:log 0
setblock ~89~4~41 minecraft:tallgrass 0
setblock ~90~4~41 minecraft:double_plant 2
fill ~90~9~41 ~90~10~41 minecraft:leaves 0
setblock ~91~3~41 minecraft:dirt 0
fill ~91~4~41 ~91~9~41 minecraft:log 0
fill ~92~4~41 ~98~4~42 minecraft:tallgrass 0
fill ~92~9~41 ~92~9~42 minecraft:leaves 0
setblock ~92~10~41 minecraft:leaves 0
fill ~93~7~41 ~93~8~47 minecraft:leaves 0
fill ~98~5~41 ~98~5~44 minecraft:leaves 0
fill ~100~7~41 ~100~8~41 minecraft:leaves 0
fill ~102~5~41 ~102~6~43 minecraft:leaves 0
fill ~106~5~41 ~106~6~46 minecraft:leaves 0
fill ~106~7~41 ~106~7~42 minecraft:leaves 0
fill ~106~8~41 ~108~8~41 minecraft:leaves 0
setblock ~107~3~41 minecraft:dirt 0
fill ~107~4~41 ~107~7~41 minecraft:log 0
fill ~108~5~41 ~109~6~42 minecraft:leaves 0
setblock ~108~7~41 minecraft:leaves 0
fill ~12~2~42 ~14~99~42 minecraft:barrier
fill ~15~1~42 ~16~2~191 minecraft:stonebrick 0
fill ~15~3~42 ~17~3~42 minecraft:log 0
fill ~18~3~42 ~22~3~44 minecraft:grass
fill ~20~7~42 ~20~7~45 minecraft:leaves 0
fill ~20~8~42 ~20~8~43 minecraft:leaves 0
fill ~20~9~42 ~20~10~42 minecraft:leaves 0
fill ~22~4~42 ~22~4~44 minecraft:tallgrass 0
fill ~23~3~42 ~24~3~42 minecraft:log 0
fill ~31~6~42 ~32~6~42 minecraft:leaves 0
fill ~34~5~42 ~34~6~42 minecraft:leaves 0
fill ~34~8~42 ~34~8~44 minecraft:leaves 0
fill ~34~9~42 ~34~10~42 minecraft:leaves 0
setblock ~35~3~42 minecraft:dirt 0
fill ~35~4~42 ~35~9~42 minecraft:log 0
fill ~36~4~42 ~37~4~42 minecraft:tallgrass 0
fill ~36~7~42 ~37~7~45 minecraft:leaves 0
fill ~36~8~42 ~36~8~44 minecraft:leaves 0
fill ~36~9~42 ~36~9~43 minecraft:leaves 0
setblock ~36~10~42 minecraft:leaves 0
fill ~38~8~42 ~39~8~42 minecraft:leaves 0
fill ~38~9~42 ~38~9~44 minecraft:leaves 0
setblock ~39~4~42 minecraft:tallgrass 0
fill ~43~6~42 ~43~6~50 minecraft:leaves 0
fill ~44~4~42 ~44~4~44 minecraft:tallgrass 0
fill ~44~5~42 ~44~5~51 minecraft:leaves 0
fill ~47~7~42 ~49~8~44 minecraft:leaves 0
fill ~50~8~42 ~50~8~46 minecraft:leaves 0
fill ~51~4~42 ~51~4~43 minecraft:tallgrass 0
fill ~53~3~42 ~53~3~48 minecraft:grass
fill ~53~4~42 ~53~4~43 minecraft:tallgrass 0
fill ~53~6~42 ~53~7~46 minecraft:leaves 0
setblock ~53~8~42 minecraft:leaves 0
fill ~54~4~42 ~54~4~43 minecraft:double_plant 2
setblock ~58~4~42 minecraft:double_plant 2
setblock ~60~4~42 minecraft:tallgrass 0
fill ~62~3~42 ~65~21~42 minecraft:stone 6
fill ~65~23~42 ~67~23~42 minecraft:stone 6
fill ~66~6~42 ~74~6~43 minecraft:double_stone_block_slab 0
setblock ~66~22~42 minecraft:polished_andesite_stairs 5
fill ~67~22~42 ~73~22~42 minecraft:polished_andesite_stairs 7
setblock ~68~23~42 minecraft:sea_lantern
fill ~69~23~42 ~71~23~42 minecraft:stone 6
setblock ~72~23~42 minecraft:sea_lantern
fill ~73~23~42 ~75~23~42 minecraft:stone 6
setblock ~74~22~42 minecraft:polished_andesite_stairs 4
fill ~75~3~42 ~78~21~42 minecraft:stone 6
fill ~79~6~42 ~80~6~42 minecraft:leaves 0
setblock ~80~3~42 minecraft:grass
setblock ~80~4~42 minecraft:tallgrass 0
fill ~80~7~42 ~80~9~42 minecraft:leaves 0
fill ~82~8~42 ~83~8~42 minecraft:leaves 0
fill ~83~3~42 ~85~3~42 minecraft:log 0
fill ~83~6~42 ~83~7~43 minecraft:leaves 0
setblock ~83~9~42 minecraft:leaves 0
fill ~88~3~42 ~90~3~42 minecraft:log 0
setblock ~91~3~42 minecraft:grass
setblock ~91~4~42 minecraft:tallgrass 0
fill ~91~7~42 ~91~8~43 minecraft:leaves 0
setblock ~91~9~42 minecraft:leaves 0
fill ~98~3~42 ~99~3~48 minecraft:grass
fill ~99~4~42 ~99~4~44 minecraft:tallgrass 0
fill ~99~5~42 ~99~5~44 minecraft:leaves 0
fill ~99~7~42 ~99~7~48 minecraft:leaves 0
fill ~99~8~42 ~101~8~42 minecraft:leaves 0
setblock ~100~3~42 minecraft:dirt 0
fill ~100~4~42 ~100~7~42 minecraft:log 0
fill ~101~5~42 ~101~6~44 minecraft:leaves 0
setblock ~101~7~42 minecraft:leaves 0
fill ~103~6~42 ~104~6~45 minecraft:leaves 0
fill ~104~4~42 ~104~4~46 minecraft:tallgrass 0
fill ~104~5~42 ~104~5~46 minecraft:leaves 0
setblock ~107~3~42 minecraft:grass
setblock ~107~4~42 minecraft:tallgrass 0
fill ~107~5~42 ~107~6~46 minecraft:leaves 0
fill ~107~7~42 ~107~8~42 minecraft:leaves 0
fill ~10~2~43 ~11~99~43 minecraft:barrier
fill ~12~1~43 ~14~2~184 minecraft:stonebrick 0
fill ~12~3~43 ~15~3~43 minecraft:log 0
fill ~15~7~43 ~17~8~47 minecraft:leaves 0
fill ~16~3~43 ~17~3~44 minecraft:grass
fill ~21~5~43 ~24~6~44 minecraft:leaves 0
fill ~23~3~43 ~23~3~57 minecraft:grass
fill ~23~4~43 ~23~4~46 minecraft:tallgrass 0
fill ~24~3~43 ~25~3~43 minecraft:log 0
fill ~30~3~43 ~30~3~46 minecraft:log 0
fill ~31~4~43 ~31~4~44 minecraft:tallgrass 0
fill ~35~3~43 ~35~3~50 minecraft:grass
fill ~35~7~43 ~35~8~44 minecraft:leaves 0
setblock ~35~9~43 minecraft:leaves 0
fill ~36~4~43 ~36~4~49 minecraft:tallgrass 0
fill ~36~6~43 ~37~6~44 minecraft:leaves 0
setblock ~37~4~43 minecraft:double_plant 2
setblock ~37~9~43 minecraft:leaves 0
setblock ~38~3~43 minecraft:dirt 0
fill ~38~4~43 ~38~8~43 minecraft:log 0
setblock ~39~4~43 minecraft:double_plant 2
fill ~39~8~43 ~39~8~45 minecraft:leaves 0
setblock ~39~9~43 minecraft:leaves 0
fill ~43~5~43 ~43~5~51 minecraft:leaves 0
setblock ~45~4~43 minecraft:tallgrass 0
fill ~45~7~43 ~46~8~43 minecraft:leaves 0
fill ~47~5~43 ~47~6~51 minecraft:leaves 0
fill ~48~6~43 ~50~6~44 minecraft:leaves 0
fill ~48~9~43 ~48~9~46 minecraft:leaves 0
fill ~48~10~43 ~48~10~45 minecraft:leaves 0
fill ~50~7~43 ~50~7~47 minecraft:leaves 0
setblock ~54~7~43 minecraft:leaves 0
fill ~55~4~43 ~55~4~44 minecraft:tallgrass 0
setblock ~58~4~43 minecraft:tallgrass 0
fill ~59~3~43 ~62~21~43 minecraft:stone 6
fill ~62~23~43 ~63~23~43 minecraft:stone 6
fill ~63~6~43 ~65~6~44 minecraft:double_stone_block_slab 0
setblock ~63~22~43 minecraft:polished_andesite_stairs 5
fill ~64~22~43 ~65~22~43 minecraft:polished_andesite_stairs 7
setblock ~64~23~43 minecraft:sea_lantern
setblock ~65~23~43 minecraft:stone 6
setblock ~66~24~43 minecraft:polished_andesite_stairs 5
fill ~66~25~43 ~74~25~43 minecraft:stone 6
fill ~66~26~43 ~67~26~43 minecraft:stained_glass 1
fill ~66~27~43 ~67~27~43 minecraft:stained_glass 15
fill ~66~28~43 ~74~29~43 minecraft:stained_glass 4
fill ~66~30~43 ~72~30~43 minecraft:stained_glass 4
fill ~66~31~43 ~70~31~43 minecraft:stained_glass 4
fill ~66~32~43 ~68~32~43 minecraft:stained_glass 4
setblock ~66~33~43 minecraft:stained_glass 4
fill ~66~34~43 ~67~34~43 minecraft:stained_glass 15
fill ~66~35~43 ~66~36~43 minecraft:stained_glass 15
fill ~66~37~43 ~66~44~43 minecraft:stained_glass 13
fill ~66~45~43 ~66~46~43 minecraft:stained_glass 15
fill ~66~47~43 ~66~50~43 minecraft:stained_glass 10
fill ~66~51~43 ~66~53~43 minecraft:stained_glass 15
setblock ~66~54~43 minecraft:stained_glass 13
fill ~66~55~43 ~67~55~43 minecraft:stained_glass 15
setblock ~66~56~43 minecraft:stained_glass 1
setblock ~66~57~43 minecraft:stained_glass 15
setblock ~66~58~43 minecraft:stained_glass 1
fill ~66~59~43 ~66~60~43 minecraft:stained_glass 15
fill ~66~61~43 ~66~65~43 minecraft:stained_glass 13
fill ~66~66~43 ~67~67~43 minecraft:stained_glass 15
fill ~66~68~43 ~66~69~43 minecraft:stained_glass 4
fill ~66~70~43 ~66~73~43 minecraft:stained_glass 15
fill ~66~74~43 ~66~75~43 minecraft:stone 0
fill ~67~24~43 ~73~24~43 minecraft:polished_andesite_stairs 7
fill ~67~33~43 ~73~33~43 minecraft:stained_glass 15
fill ~67~35~43 ~69~36~43 minecraft:stained_glass 14
fill ~67~37~43 ~67~38~43 minecraft:stained_glass 15
fill ~67~39~43 ~67~46~43 minecraft:stained_glass 13
fill ~67~47~43 ~67~49~43 minecraft:stained_glass 15
fill ~67~50~43 ~67~53~43 minecraft:stained_glass 10
setblock ~67~54~43 minecraft:stained_glass 15
setblock ~67~56~43 minecraft:stained_glass 15
setblock ~67~57~43 minecraft:stained_glass 4
setblock ~67~58~43 minecraft:stained_glass 15
fill ~67~59~43 ~67~60~43 minecraft:stained_glass 1
fill ~67~61~43 ~67~65~43 minecraft:stained_glass 15
fill ~67~68~43 ~67~69~43 minecraft:stained_glass 15
fill ~67~70~43 ~68~70~43 minecraft:stained_glass 1
fill ~67~71~43 ~67~72~43 minecraft:stained_glass 1
fill ~67~73~43 ~67~75~43 minecraft:stained_glass 15
setblock ~67~76~43 minecraft:stone 0
fill ~68~26~43 ~72~26~43 minecraft:stained_glass 15
fill ~68~27~43 ~74~27~43 minecraft:stained_glass 4
fill ~68~34~43 ~69~34~43 minecraft:stained_glass 14
fill ~68~37~43 ~70~38~43 minecraft:stained_glass 14
fill ~68~39~43 ~68~41~43 minecraft:stained_glass 15
fill ~68~42~43 ~68~49~43 minecraft:stained_glass 13
fill ~68~50~43 ~68~53~43 minecraft:stained_glass 15
fill ~68~54~43 ~68~56~43 minecraft:stained_glass 10
fill ~68~57~43 ~69~57~43 minecraft:stained_glass 15
setblock ~68~58~43 minecraft:stained_glass 4
setblock ~68~59~43 minecraft:stained_glass 15
fill ~68~60~43 ~68~69~43 minecraft:stained_glass 1
fill ~68~71~43 ~68~72~43 minecraft:stained_glass 15
fill ~68~73~43 ~70~73~43 minecraft:stained_glass 4
fill ~68~74~43 ~69~76~43 minecraft:stained_glass 4
fill ~68~77~43 ~69~77~43 minecraft:smooth_stone
fill ~69~32~43 ~70~32~43 minecraft:stained_glass 15
fill ~69~39~43 ~70~41~43 minecraft:stained_glass 14
fill ~69~42~43 ~69~44~43 minecraft:stained_glass 15
fill ~69~45~43 ~69~53~43 minecraft:stained_glass 13
fill ~69~54~43 ~69~56~43 minecraft:stained_glass 15
setblock ~69~58~43 minecraft:stained_glass 15
setblock ~69~59~43 minecraft:stained_glass 4
fill ~69~60~43 ~69~61~43 minecraft:stained_glass 15
fill ~69~62~43 ~69~68~43 minecraft:stained_glass 1
fill ~69~69~43 ~69~70~43 minecraft:stained_glass 15
fill ~69~71~43 ~71~71~43 minecraft:stained_glass 4
fill ~69~72~43 ~70~72~43 minecraft:stained_glass 4
fill ~70~34~43 ~70~35~43 minecraft:stained_glass 15
setblock ~70~36~43 minecraft:stained_glass 14
fill ~70~42~43 ~71~44~43 minecraft:stained_glass 14
fill ~70~45~43 ~70~47~43 minecraft:stained_glass 15
fill ~70~48~43 ~70~58~43 minecraft:stained_glass 13
setblock ~70~59~43 minecraft:stained_glass 15
fill ~70~60~43 ~70~61~43 minecraft:stained_glass 4
fill ~70~62~43 ~70~68~43 minecraft:stained_glass 15
fill ~70~69~43 ~71~70~43 minecraft:stained_glass 4
fill ~70~74~43 ~70~76~43 minecraft:stained_glass 15
setblock ~70~77~43 minecraft:sea_lantern
fill ~71~31~43 ~72~31~43 minecraft:stained_glass 15
fill ~71~32~43 ~72~32~43 minecraft:stained_glass 4
fill ~71~34~43 ~72~35~43 minecraft:stained_glass 1
fill ~71~36~43 ~71~39~43 minecraft:stained_glass 15
fill ~71~40~43 ~71~41~43 minecraft:stained_glass 14
fill ~71~45~43 ~71~47~43 minecraft:stained_glass 14
fill ~71~48~43 ~71~53~43 minecraft:stained_glass 15
fill ~71~54~43 ~71~59~43 minecraft:stained_glass 13
fill ~71~60~43 ~72~60~43 minecraft:stained_glass 15
fill ~71~61~43 ~71~62~43 minecraft:stained_glass 4
fill ~71~63~43 ~71~64~43 minecraft:stained_glass 15
fill ~71~65~43 ~71~68~43 minecraft:stained_glass 4
fill ~71~72~43 ~71~73~43 minecraft:stained_glass 15
setblock ~71~74~43 minecraft:stained_glass 4
setblock ~71~75~43 minecraft:stained_glass 15
setblock ~71~76~43 minecraft:stained_glass 14
fill ~71~77~43 ~72~77~43 minecraft:smooth_stone
setblock ~72~36~43 minecraft:stained_glass 1
fill ~72~37~43 ~72~45~43 minecraft:stained_glass 15
fill ~72~46~43 ~72~53~43 minecraft:stained_glass 14
fill ~72~54~43 ~72~59~43 minecraft:stained_glass 15
setblock ~72~61~43 minecraft:stained_glass 15
fill ~72~62~43 ~72~64~43 minecraft:stained_glass 4
fill ~72~65~43 ~72~71~43 minecraft:stained_glass 15
fill ~72~72~43 ~73~72~43 minecraft:stained_glass 4
setblock ~72~73~43 minecraft:stained_glass 4
setblock ~72~74~43 minecraft:stained_glass 15
fill ~72~75~43 ~73~75~43 minecraft:stained_glass 14
setblock ~72~76~43 minecraft:stained_glass 15
fill ~73~26~43 ~74~26~43 minecraft:stained_glass 4
fill ~73~30~43 ~74~30~43 minecraft:stained_glass 15
fill ~73~31~43 ~74~31~43 minecraft:stained_glass 4
fill ~73~32~43 ~74~32~43 minecraft:stained_glass 15
fill ~73~34~43 ~73~36~43 minecraft:stained_glass 15
fill ~73~37~43 ~74~45~43 minecraft:stained_glass 10
fill ~73~46~43 ~73~52~43 minecraft:stained_glass 15
fill ~73~53~43 ~73~61~43 minecraft:stained_glass 14
fill ~73~62~43 ~74~63~43 minecraft:stained_glass 15
fill ~73~64~43 ~73~71~43 minecraft:stained_glass 4
fill ~73~73~43 ~74~73~43 minecraft:stained_glass 15
setblock ~73~74~43 minecraft:stained_glass 14
setblock ~73~76~43 minecraft:stone 0
setblock ~74~24~43 minecraft:polished_andesite_stairs 4
fill ~74~33~43 ~74~36~43 minecraft:stained_glass 10
fill ~74~46~43 ~74~48~43 minecraft:stained_glass 10
fill ~74~49~43 ~74~61~43 minecraft:stained_glass 15
fill ~74~64~43 ~74~65~43 minecraft:stained_glass 15
fill ~74~66~43 ~74~70~43 minecraft:stained_glass 4
fill ~74~71~43 ~74~72~43 minecraft:stained_glass 15
fill ~74~74~43 ~74~75~43 minecraft:stone 0
fill ~75~6~43 ~77~6~44 minecraft:double_stone_block_slab 0
fill ~75~22~43 ~76~22~43 minecraft:polished_andesite_stairs 7
setblock ~75~23~43 minecraft:stone 6
setblock ~76~23~43 minecraft:sea_lantern
setblock ~77~22~43 minecraft:polished_andesite_stairs 4
fill ~77~23~43 ~78~23~43 minecraft:stone 6
fill ~78~3~43 ~81~21~43 minecraft:stone 6
fill ~82~3~43 ~83~3~43 minecraft:log 0
fill ~90~3~43 ~91~3~43 minecraft:log 0
fill ~93~4~43 ~94~4~43 minecraft:tallgrass 0
fill ~94~7~43 ~95~8~44 minecraft:leaves 0
fill ~95~4~43 ~96~4~43 minecraft:double_plant 2
fill ~96~8~43 ~96~8~48 minecraft:leaves 0
fill ~97~4~43 ~98~4~45 minecraft:tallgrass 0
fill ~100~3~43 ~100~3~48 minecraft:grass
fill ~100~5~43 ~100~6~44 minecraft:leaves 0
fill ~100~7~43 ~100~8~43 minecraft:leaves 0
setblock ~102~4~43 minecraft:tallgrass 0
fill ~103~5~43 ~103~5~46 minecraft:leaves 0
fill ~104~7~43 ~105~7~43 minecraft:leaves 0
fill ~105~8~43 ~105~8~45 minecraft:leaves 0
fill ~107~3~43 ~107~3~44 minecraft:log 0
fill ~108~5~43 ~108~6~43 minecraft:leaves 0
setblock ~109~6~43 minecraft:leaves 0
fill ~112~1~43 ~112~2~191 minecraft:stonebrick 0
fill ~113~2~43 ~113~99~45 minecraft:barrier
fill ~9~2~44 ~9~99~44 minecraft:barrier
fill ~10~1~44 ~11~2~177 minecraft:stonebrick 0
fill ~10~3~44 ~12~3~44 minecraft:log 0
fill ~13~3~44 ~15~3~45 minecraft:grass
fill ~13~7~44 ~14~8~48 minecraft:leaves 0
fill ~15~9~44 ~17~9~44 minecraft:leaves 0
setblock ~16~4~44 minecraft:tallgrass 0
fill ~16~10~44 ~16~10~49 minecraft:leaves 0
fill ~18~8~44 ~18~8~50 minecraft:leaves 0
fill ~19~4~44 ~19~4~46 minecraft:tallgrass 0
fill ~19~6~44 ~20~6~45 minecraft:leaves 0
fill ~20~5~44 ~20~5~45 minecraft:leaves 0
fill ~24~3~44 ~24~3~55 minecraft:grass
setblock ~24~4~44 minecraft:tallgrass 0
fill ~25~3~44 ~25~3~45 minecraft:log 0
fill ~33~4~44 ~34~4~45 minecraft:tallgrass 0
fill ~38~3~44 ~38~3~51 minecraft:grass
fill ~38~4~44 ~39~4~45 minecraft:tallgrass 0
fill ~38~6~44 ~38~7~50 minecraft:leaves 0
setblock ~38~8~44 minecraft:leaves 0
setblock ~40~4~44 minecraft:double_plant 2
fill ~41~7~44 ~41~7~51 minecraft:leaves 0
fill ~44~7~44 ~44~7~49 minecraft:leaves 0
fill ~44~8~44 ~46~8~44 minecraft:leaves 0
setblock ~45~3~44 minecraft:dirt 0
setblock ~45~4~44 minecraft:log 0
setblock ~45~7~44 minecraft:log 0
fill ~46~7~44 ~46~7~46 minecraft:leaves 0
fill ~47~9~44 ~47~9~45 minecraft:leaves 0
setblock ~47~10~44 minecraft:leaves 0
fill ~48~3~44 ~48~3~45 minecraft:dirt 0
fill ~48~4~44 ~48~5~45 minecraft:log 0
setblock ~49~4~44 minecraft:tallgrass 0
fill ~49~9~44 ~49~9~45 minecraft:leaves 0
setblock ~49~10~44 minecraft:leaves 0
fill ~51~8~44 ~51~9~44 minecraft:leaves 0
fill ~54~4~44 ~54~4~47 minecraft:tallgrass 0
setblock ~57~4~44 minecraft:double_plant 2
fill ~58~3~44 ~59~21~44 minecraft:stone 6
fill ~60~6~44 ~62~6~46 minecraft:double_stone_block_slab 0
fill ~60~22~44 ~60~23~44 minecraft:stone 6
setblock ~61~22~44 minecraft:polished_andesite_stairs 5
fill ~61~23~44 ~62~23~44 minecraft:stone 6
setblock ~62~22~44 minecraft:polished_andesite_stairs 7
setblock ~63~24~44 minecraft:polished_andesite_stairs 5
fill ~63~25~44 ~65~25~44 minecraft:stone 6
fill ~63~26~44 ~63~29~44 minecraft:stone 0
setblock ~63~30~44 minecraft:sea_lantern
fill ~63~31~44 ~63~34~44 minecraft:stone 0
setblock ~63~35~44 minecraft:sea_lantern
fill ~63~36~44 ~63~39~44 minecraft:stone 0
setblock ~63~40~44 minecraft:sea_lantern
fill ~63~41~44 ~63~44~44 minecraft:stone 0
setblock ~63~45~44 minecraft:sea_lantern
fill ~63~46~44 ~63~49~44 minecraft:stone 0
setblock ~63~50~44 minecraft:sea_lantern
fill ~63~51~44 ~63~54~44 minecraft:stone 0
setblock ~63~55~44 minecraft:sea_lantern
fill ~63~56~44 ~63~59~44 minecraft:stone 0
setblock ~63~60~44 minecraft:sea_lantern
fill ~63~61~44 ~63~64~44 minecraft:stone 0
setblock ~63~65~44 minecraft:sea_lantern
fill ~63~66~44 ~64~69~44 minecraft:stone 0
setblock ~63~70~44 minecraft:sea_lantern
fill ~63~71~44 ~65~72~44 minecraft:stone 0
fill ~64~24~44 ~65~24~44 minecraft:polished_andesite_stairs 7
fill ~64~26~44 ~65~26~44 minecraft:stained_glass 1
setblock ~64~27~44 minecraft:stained_glass 1
setblock ~64~28~44 minecraft:stained_glass 15
fill ~64~29~44 ~65~33~44 minecraft:stained_glass 4
setblock ~64~34~44 minecraft:stained_glass 4
setblock ~64~35~44 minecraft:stained_glass 15
setblock ~64~36~44 minecraft:stained_glass 4
setblock ~64~37~44 minecraft:stained_glass 15
fill ~64~38~44 ~65~39~44 minecraft:stained_glass 13
fill ~64~40~44 ~64~41~44 minecraft:stained_glass 15
fill ~64~42~44 ~64~46~44 minecraft:stained_glass 10
fill ~64~47~44 ~64~48~44 minecraft:stained_glass 15
fill ~64~49~44 ~64~51~44 minecraft:stained_glass 13
fill ~64~52~44 ~64~53~44 minecraft:stained_glass 15
fill ~64~54~44 ~64~55~44 minecraft:stained_glass 1
fill ~64~56~44 ~64~57~44 minecraft:stained_glass 15
fill ~64~58~44 ~64~61~44 minecraft:stained_glass 13
fill ~64~62~44 ~64~63~44 minecraft:stained_glass 15
fill ~64~64~44 ~64~65~44 minecraft:stone 0
fill ~64~70~44 ~65~70~44 minecraft:stone 0
fill ~64~73~44 ~65~73~44 minecraft:stone 0
setblock ~65~27~44 minecraft:stained_glass 15
setblock ~65~28~44 minecraft:stained_glass 4
setblock ~65~34~44 minecraft:stained_glass 15
setblock ~65~35~44 minecraft:stained_glass 4
setblock ~65~36~44 minecraft:stained_glass 15
setblock ~65~37~44 minecraft:stained_glass 13
fill ~65~40~44 ~65~41~44 minecraft:stained_glass 13
fill ~65~42~44 ~65~44~44 minecraft:stained_glass 15
fill ~65~45~44 ~65~48~44 minecraft:stained_glass 10
fill ~65~49~44 ~65~50~44 minecraft:stained_glass 15
fill ~65~51~44 ~65~53~44 minecraft:stained_glass 13
setblock ~65~54~44 minecraft:stained_glass 15
fill ~65~55~44 ~65~56~44 minecraft:stained_glass 1
fill ~65~57~44 ~65~58~44 minecraft:stained_glass 15
fill ~65~59~44 ~65~63~44 minecraft:stained_glass 13
