fill ~-3 ~0 ~21 ~0 ~0 ~21 netherrack 0  
fill ~-3 ~0 ~22 ~14 ~0 ~22 netherrack 0  
fill ~-3 ~0 ~23 ~14 ~0 ~23 netherrack 0  
fill ~-3 ~0 ~24 ~14 ~0 ~24 netherrack 0  
fill ~-3 ~0 ~25 ~14 ~0 ~25 netherrack 0  
fill ~-3 ~0 ~26 ~15 ~0 ~26 netherrack 0  
fill ~-3 ~0 ~27 ~14 ~0 ~27 netherrack 0  
fill ~-3 ~0 ~28 ~14 ~0 ~28 netherrack 0  
fill ~-3 ~0 ~29 ~37 ~0 ~29 netherrack 0  
fill ~-2 ~0 ~18 ~0 ~0 ~18 netherrack 0  
fill ~-2 ~0 ~19 ~0 ~0 ~19 netherrack 0  
fill ~-2 ~0 ~20 ~0 ~0 ~20 netherrack 0  
fill ~-2 ~0 ~30 ~0 ~0 ~30 netherrack 0 
setblock ~-2 ~0 ~31 red_nether_brick 0 
setblock ~-2 ~0 ~32 netherrack 0  
fill ~-1 ~0 ~16 ~0 ~0 ~16 netherrack 0  
fill ~-1 ~0 ~17 ~0 ~0 ~17 netherrack 0 
setblock ~-1 ~0 ~31 netherrack 0  
fill ~-1 ~0 ~32 ~4 ~0 ~32 red_nether_brick 0  
fill ~-1 ~0 ~33 ~0 ~0 ~33 red_nether_brick 0  
fill ~-1 ~0 ~34 ~0 ~0 ~34 netherrack 0 
setblock ~0 ~0 ~14 magma 0  
fill ~0 ~0 ~15 ~1 ~0 ~15 netherrack 0 
setblock ~0 ~0 ~31 red_nether_brick 0  
fill ~0 ~0 ~35 ~3 ~0 ~35 netherrack 0  
fill ~0 ~0 ~36 ~3 ~0 ~36 netherrack 0 
setblock ~1 ~0 ~13 magma 0 
setblock ~1 ~0 ~14 netherrack 0  
fill ~1 ~0 ~16 ~2 ~0 ~16 magma 0  
fill ~1 ~0 ~17 ~2 ~0 ~17 magma 0  
fill ~1 ~0 ~18 ~1 ~0 ~16 magma 0  
fill ~1 ~0 ~19 ~3 ~0 ~19 obsidian 0  
fill ~1 ~0 ~20 ~3 ~0 ~20 obsidian 0  
fill ~1 ~0 ~21 ~3 ~0 ~21 obsidian 0  
fill ~1 ~0 ~30 ~2 ~0 ~30 red_nether_brick 0  
fill ~1 ~0 ~31 ~2 ~0 ~31 netherrack 0  
fill ~1 ~0 ~33 ~2 ~0 ~33 netherrack 0  
fill ~1 ~0 ~34 ~2 ~0 ~34 red_nether_brick 0  
fill ~1 ~0 ~37 ~5 ~0 ~37 netherrack 0  
fill ~2 ~0 ~12 ~6 ~0 ~12 netherrack 0  
fill ~2 ~0 ~13 ~3 ~0 ~13 obsidian 0  
fill ~2 ~0 ~14 ~2 ~2 ~14 obsidian 0  
fill ~2 ~0 ~15 ~3 ~0 ~15 obsidian 0  
fill ~2 ~0 ~18 ~3 ~0 ~18 obsidian 0  
fill ~2 ~0 ~38 ~7 ~0 ~38 netherrack 0  
fill ~2 ~0 ~39 ~12 ~0 ~39 netherrack 0  
fill ~3 ~0 ~11 ~4 ~0 ~11 netherrack 0  
fill ~3 ~0 ~14 ~4 ~0 ~14 magma 0  
fill ~3 ~0 ~16 ~3 ~1 ~16 obsidian 0  
fill ~3 ~0 ~17 ~16 ~0 ~17 netherrack 0  
fill ~3 ~0 ~30 ~14 ~0 ~30 netherrack 0 
setblock ~3 ~0 ~31 red_nether_brick 0 
setblock ~3 ~0 ~33 red_nether_brick 0 
setblock ~3 ~0 ~34 netherrack 0  
fill ~3 ~0 ~40 ~13 ~0 ~40 netherrack 0  
fill ~3 ~0 ~41 ~16 ~0 ~41 netherrack 0  
fill ~4 ~0 ~10 ~20 ~0 ~10 netherrack 0  
fill ~4 ~0 ~13 ~5 ~0 ~13 magma 0  
fill ~4 ~0 ~15 ~4 ~1 ~15 magma 0  
fill ~4 ~0 ~16 ~17 ~0 ~16 netherrack 0  
fill ~4 ~0 ~18 ~4 ~0 ~19 magma 0  
fill ~4 ~0 ~20 ~14 ~0 ~20 netherrack 0  
fill ~4 ~0 ~21 ~16 ~0 ~21 netherrack 0  
fill ~4 ~0 ~31 ~36 ~0 ~31 netherrack 0  
fill ~4 ~0 ~33 ~5 ~0 ~33 netherrack 0  
fill ~4 ~0 ~34 ~5 ~0 ~34 red_nether_brick 0  
fill ~4 ~0 ~35 ~6 ~0 ~35 red_nether_brick 0  
fill ~4 ~0 ~36 ~4 ~0 ~34 red_nether_brick 0  
fill ~5 ~0 ~9 ~21 ~0 ~9 netherrack 0 
setblock ~5 ~0 ~11 magma 0  
fill ~5 ~0 ~14 ~5 ~0 ~33 netherrack 0 
setblock ~5 ~0 ~36 netherrack 0  
fill ~5 ~0 ~42 ~14 ~0 ~42 netherrack 0  
fill ~6 ~0 ~8 ~24 ~0 ~8 netherrack 0  
fill ~6 ~0 ~11 ~20 ~0 ~11 netherrack 0  
fill ~6 ~0 ~13 ~20 ~0 ~13 netherrack 0  
fill ~6 ~0 ~14 ~6 ~0 ~15 magma 0  
fill ~6 ~0 ~18 ~15 ~0 ~18 netherrack 0  
fill ~6 ~0 ~19 ~14 ~0 ~19 netherrack 0  
fill ~6 ~0 ~32 ~6 ~0 ~33 red_nether_brick 0  
fill ~6 ~0 ~34 ~7 ~0 ~34 netherrack 0  
fill ~6 ~0 ~36 ~9 ~0 ~36 red_nether_brick 0  
fill ~6 ~0 ~37 ~6 ~0 ~35 red_nether_brick 0 
setblock ~7 ~0 ~12 magma 0  
fill ~7 ~0 ~14 ~34 ~0 ~14 netherrack 0  
fill ~7 ~0 ~15 ~34 ~0 ~15 netherrack 0  
fill ~7 ~0 ~32 ~14 ~0 ~32 netherrack 0 
setblock ~7 ~0 ~33 red_nether_brick 0 
setblock ~7 ~0 ~35 netherrack 0  
fill ~7 ~0 ~37 ~7 ~0 ~37 netherrack 0  
fill ~8 ~0 ~7 ~19 ~0 ~7 netherrack 0  
fill ~8 ~0 ~12 ~19 ~0 ~12 netherrack 0  
fill ~8 ~0 ~33 ~14 ~0 ~33 netherrack 0  
fill ~8 ~0 ~34 ~8 ~0 ~38 red_nether_brick 0  
fill ~8 ~0 ~43 ~26 ~0 ~43 netherrack 0  
fill ~9 ~0 ~34 ~14 ~0 ~34 netherrack 0  
fill ~9 ~0 ~35 ~11 ~0 ~35 red_nether_brick 0 
setblock ~9 ~0 ~37 netherrack 0  
fill ~9 ~0 ~38 ~12 ~0 ~38 red_nether_brick 0  
fill ~10 ~0 ~6 ~19 ~0 ~6 netherrack 0 
setblock ~10 ~0 ~36 netherrack 0  
fill ~10 ~0 ~37 ~12 ~0 ~37 red_nether_brick 0  
fill ~10 ~0 ~44 ~24 ~0 ~44 netherrack 0 
setblock ~11 ~0 ~36 red_nether_brick 0  
fill ~12 ~0 ~35 ~14 ~0 ~35 netherrack 0  
fill ~12 ~0 ~36 ~12 ~0 ~6 netherrack 0  
fill ~13 ~0 ~5 ~19 ~0 ~5 netherrack 0  
fill ~13 ~0 ~36 ~14 ~0 ~36 red_nether_brick 0  
fill ~13 ~0 ~37 ~13 ~0 ~38 netherrack 0  
fill ~13 ~0 ~39 ~15 ~0 ~39 red_nether_brick 0  
fill ~13 ~0 ~45 ~21 ~0 ~45 netherrack 0  
fill ~14 ~0 ~37 ~15 ~0 ~37 red_nether_brick 0  
fill ~14 ~0 ~38 ~15 ~0 ~38 red_nether_brick 0 
setblock ~14 ~0 ~40 red_nether_brick 0  
fill ~15 ~0 ~19 ~21 ~0 ~19 dirt 0  
fill ~15 ~0 ~20 ~17 ~0 ~20 dirt 0  
fill ~15 ~0 ~22 ~15 ~0 ~25 dirt 0  
fill ~15 ~0 ~27 ~15 ~0 ~28 dirt 0 
setblock ~15 ~0 ~30 dirt 0  
fill ~15 ~0 ~32 ~15 ~0 ~33 dirt 0  
fill ~15 ~0 ~34 ~15 ~0 ~35 red_nether_brick 0 
setblock ~15 ~0 ~36 netherrack 0 
setblock ~15 ~0 ~40 netherrack 0 
setblock ~15 ~0 ~42 dirt 0  
fill ~16 ~0 ~18 ~21 ~0 ~18 dirt 0  
fill ~16 ~0 ~22 ~16 ~1 ~22 netherrack 0  
fill ~16 ~0 ~23 ~37 ~0 ~23 netherrack 0  
fill ~16 ~0 ~24 ~16 ~0 ~26 dirt 0  
fill ~16 ~0 ~27 ~37 ~0 ~27 netherrack 0  
fill ~16 ~0 ~28 ~37 ~0 ~28 netherrack 0  
fill ~16 ~0 ~30 ~36 ~0 ~30 netherrack 0 
setblock ~16 ~0 ~32 netherrack 0  
fill ~16 ~0 ~33 ~18 ~0 ~33 dirt 0  
fill ~16 ~0 ~34 ~16 ~0 ~40 obsidian 0 
setblock ~16 ~0 ~42 netherrack 0  
fill ~17 ~0 ~17 ~21 ~0 ~17 dirt 0  
fill ~17 ~0 ~21 ~19 ~0 ~21 dirt 0  
fill ~17 ~0 ~22 ~17 ~0 ~17 dirt 0  
fill ~17 ~0 ~24 ~37 ~0 ~24 netherrack 0  
fill ~17 ~0 ~25 ~37 ~0 ~25 netherrack 0  
fill ~17 ~0 ~26 ~37 ~0 ~26 netherrack 0  
fill ~17 ~0 ~32 ~18 ~0 ~32 dirt 0  
fill ~17 ~0 ~34 ~35 ~0 ~34 netherrack 0  
fill ~17 ~0 ~35 ~17 ~0 ~36 red_nether_brick 0  
fill ~17 ~0 ~37 ~33 ~0 ~37 netherrack 0  
fill ~17 ~0 ~38 ~32 ~0 ~38 netherrack 0  
fill ~17 ~0 ~39 ~31 ~0 ~39 netherrack 0  
fill ~17 ~0 ~40 ~30 ~0 ~40 netherrack 0  
fill ~17 ~0 ~41 ~18 ~0 ~41 dirt 0  
fill ~17 ~0 ~42 ~18 ~0 ~42 dirt 0  
fill ~18 ~0 ~16 ~21 ~0 ~16 dirt 0  
fill ~18 ~0 ~20 ~18 ~2 ~20 netherrack 0  
fill ~18 ~0 ~22 ~37 ~0 ~22 netherrack 0  
fill ~18 ~0 ~35 ~34 ~0 ~35 netherrack 0  
fill ~18 ~0 ~36 ~34 ~0 ~36 netherrack 0  
fill ~19 ~0 ~20 ~20 ~0 ~20 dirt 0  
fill ~19 ~0 ~32 ~36 ~0 ~32 netherrack 0  
fill ~19 ~0 ~33 ~35 ~0 ~33 netherrack 0  
fill ~19 ~0 ~41 ~29 ~0 ~41 netherrack 0  
fill ~19 ~0 ~42 ~28 ~0 ~42 netherrack 0  
fill ~20 ~0 ~5 ~20 ~1 ~5 magma 0  
fill ~20 ~0 ~6 ~21 ~0 ~6 magma 0  
fill ~20 ~0 ~7 ~20 ~0 ~5 magma 0  
fill ~20 ~0 ~12 ~27 ~0 ~12 magma 0  
fill ~20 ~0 ~21 ~37 ~0 ~21 netherrack 0  
fill ~21 ~0 ~5 ~22 ~0 ~5 netherrack 0  
fill ~21 ~0 ~7 ~26 ~0 ~7 netherrack 0  
fill ~21 ~0 ~10 ~22 ~0 ~10 magma 0  
fill ~21 ~0 ~11 ~24 ~0 ~11 magma 0 
setblock ~21 ~0 ~13 magma 0  
fill ~21 ~0 ~20 ~36 ~0 ~20 netherrack 0  
fill ~22 ~0 ~6 ~24 ~0 ~6 netherrack 0  
fill ~22 ~0 ~9 ~24 ~0 ~9 magma 0 
setblock ~22 ~0 ~13 netherrack 0  
fill ~22 ~0 ~16 ~35 ~0 ~16 netherrack 0  
fill ~22 ~0 ~17 ~35 ~0 ~17 netherrack 0  
fill ~22 ~0 ~18 ~36 ~0 ~18 netherrack 0  
fill ~22 ~0 ~19 ~36 ~0 ~19 netherrack 0 
setblock ~23 ~0 ~10 netherrack 0 
setblock ~23 ~0 ~13 magma 0  
fill ~24 ~0 ~10 ~25 ~0 ~10 magma 0  
fill ~24 ~0 ~13 ~33 ~0 ~13 netherrack 0  
fill ~25 ~0 ~8 ~26 ~0 ~8 magma 0  
fill ~25 ~0 ~9 ~26 ~0 ~9 netherrack 0 
setblock ~25 ~0 ~11 netherrack 0 
setblock ~26 ~0 ~10 netherrack 0 
setblock ~26 ~0 ~11 magma 0  
fill ~27 ~0 ~8 ~28 ~0 ~8 netherrack 0  
fill ~27 ~0 ~9 ~27 ~0 ~10 magma 0 
setblock ~27 ~0 ~11 netherrack 0  
fill ~28 ~0 ~9 ~29 ~0 ~9 netherrack 0  
fill ~28 ~0 ~10 ~28 ~0 ~11 magma 0  
fill ~28 ~0 ~12 ~32 ~0 ~12 netherrack 0  
fill ~29 ~0 ~10 ~30 ~0 ~10 netherrack 0  
fill ~29 ~0 ~11 ~31 ~0 ~11 netherrack 0  
fill ~0 ~1 ~25 ~7 ~1 ~25 netherrack 0  
fill ~0 ~1 ~26 ~5 ~1 ~26 netherrack 0  
fill ~0 ~1 ~27 ~5 ~1 ~27 netherrack 0  
fill ~1 ~1 ~19 ~3 ~1 ~19 obsidian 0 
setblock ~1 ~1 ~20 magma 0  
fill ~1 ~1 ~21 ~2 ~1 ~21 netherrack 0  
fill ~1 ~1 ~22 ~7 ~1 ~22 netherrack 0  
fill ~1 ~1 ~23 ~7 ~1 ~23 netherrack 0  
fill ~1 ~1 ~24 ~7 ~1 ~24 netherrack 0  
fill ~1 ~1 ~28 ~3 ~1 ~28 netherrack 0  
fill ~2 ~1 ~13 ~4 ~1 ~13 obsidian 0  
fill ~2 ~1 ~15 ~3 ~1 ~15 obsidian 0  
fill ~2 ~1 ~18 ~2 ~3 ~18 obsidian 0 
setblock ~2 ~1 ~20 netherrack 0  
fill ~3 ~1 ~14 ~5 ~1 ~14 obsidian 0 
setblock ~3 ~1 ~18 magma 0 
setblock ~3 ~1 ~20 magma 0 
setblock ~3 ~1 ~21 obsidian 0  
fill ~3 ~1 ~37 ~5 ~1 ~37 netherrack 0  
fill ~3 ~1 ~38 ~6 ~1 ~38 netherrack 0  
fill ~3 ~1 ~39 ~6 ~1 ~39 netherrack 0  
fill ~3 ~1 ~40 ~7 ~1 ~40 netherrack 0  
fill ~4 ~1 ~16 ~13 ~1 ~16 netherrack 0 
setblock ~4 ~1 ~17 magma 0  
fill ~4 ~1 ~18 ~13 ~1 ~18 netherrack 0  
fill ~4 ~1 ~19 ~4 ~2 ~19 magma 0  
fill ~4 ~1 ~20 ~8 ~1 ~20 netherrack 0  
fill ~4 ~1 ~21 ~8 ~1 ~21 netherrack 0  
fill ~4 ~1 ~41 ~8 ~1 ~41 netherrack 0  
fill ~5 ~1 ~15 ~6 ~1 ~15 magma 0  
fill ~5 ~1 ~17 ~13 ~1 ~17 netherrack 0  
fill ~5 ~1 ~19 ~9 ~1 ~19 netherrack 0  
fill ~7 ~1 ~15 ~13 ~1 ~15 netherrack 0  
fill ~7 ~1 ~42 ~8 ~1 ~42 netherrack 0  
fill ~8 ~1 ~30 ~9 ~1 ~30 stained_hardened_clay 9  
fill ~9 ~1 ~13 ~16 ~1 ~13 netherrack 0  
fill ~9 ~1 ~14 ~16 ~1 ~14 netherrack 0  
fill ~9 ~1 ~29 ~10 ~1 ~29 stained_hardened_clay 9  
fill ~10 ~1 ~28 ~10 ~2 ~28 stained_hardened_clay 9  
fill ~11 ~1 ~12 ~17 ~1 ~12 netherrack 0  
fill ~11 ~1 ~28 ~11 ~1 ~30 log2 12  
fill ~12 ~1 ~27 ~15 ~1 ~27 planks 5  
fill ~12 ~1 ~28 ~15 ~1 ~28 planks 5  
fill ~12 ~1 ~29 ~12 ~3 ~29 log2 12  
fill ~12 ~1 ~30 ~15 ~1 ~30 log2 12  
fill ~12 ~1 ~31 ~14 ~1 ~31 log2 12  
fill ~13 ~1 ~8 ~16 ~1 ~8 netherrack 0  
fill ~13 ~1 ~9 ~16 ~1 ~9 netherrack 0  
fill ~13 ~1 ~29 ~14 ~1 ~29 planks 5  
fill ~13 ~1 ~32 ~13 ~2 ~32 cobblestone_wall 0  
fill ~13 ~1 ~33 ~13 ~3 ~33 cobblestone_wall 0  
fill ~13 ~1 ~41 ~13 ~3 ~41 cobblestone_wall 0  
fill ~13 ~1 ~42 ~13 ~2 ~42 cobblestone_wall 0  
fill ~13 ~1 ~47 ~13 ~2 ~47 log2 12  
fill ~14 ~1 ~6 ~16 ~1 ~6 netherrack 0  
fill ~14 ~1 ~7 ~16 ~1 ~7 netherrack 0  
fill ~14 ~1 ~10 ~19 ~1 ~10 netherrack 0  
fill ~14 ~1 ~11 ~16 ~1 ~11 netherrack 0  
fill ~14 ~1 ~21 ~19 ~1 ~21 netherrack 0  
fill ~14 ~1 ~22 ~19 ~1 ~22 netherrack 0  
fill ~14 ~1 ~25 ~16 ~1 ~25 planks 5  
fill ~14 ~1 ~26 ~16 ~1 ~26 planks 5  
fill ~14 ~1 ~32 ~15 ~1 ~32 stone 2  
fill ~14 ~1 ~33 ~15 ~1 ~33 stone 2  
fill ~14 ~1 ~34 ~15 ~1 ~34 cobblestone_wall 0  
fill ~14 ~1 ~40 ~15 ~1 ~40 cobblestone_wall 0  
fill ~14 ~1 ~41 ~15 ~1 ~41 stone 2  
fill ~14 ~1 ~42 ~15 ~1 ~42 stone 2  
fill ~14 ~1 ~43 ~15 ~1 ~43 cobblestone_wall 0 
setblock ~14 ~1 ~47 stained_glass_pane 0  
fill ~15 ~1 ~19 ~21 ~1 ~19 netherrack 0  
fill ~15 ~1 ~20 ~20 ~1 ~20 netherrack 0  
fill ~15 ~1 ~23 ~16 ~1 ~23 netherrack 0  
fill ~15 ~1 ~24 ~16 ~1 ~24 planks 5  
fill ~16 ~1 ~18 ~21 ~1 ~18 netherrack 0  
fill ~16 ~1 ~33 ~16 ~16 ~33 obsidian 0  
fill ~16 ~1 ~34 ~16 ~15 ~34 portal 2  
fill ~16 ~1 ~35 ~16 ~15 ~35 portal 2  
fill ~16 ~1 ~36 ~16 ~15 ~36 portal 2  
fill ~16 ~1 ~37 ~16 ~15 ~37 portal 2  
fill ~16 ~1 ~38 ~16 ~15 ~38 portal 2  
fill ~16 ~1 ~39 ~16 ~15 ~39 portal 2  
fill ~16 ~1 ~40 ~16 ~15 ~40 portal 2  
fill ~16 ~1 ~41 ~16 ~16 ~41 obsidian 0 
setblock ~16 ~1 ~42 stone_slab 5  
fill ~17 ~1 ~6 ~18 ~1 ~6 magma 0  
fill ~17 ~1 ~7 ~21 ~1 ~7 obsidian 0  
fill ~17 ~1 ~8 ~20 ~1 ~8 obsidian 0  
fill ~17 ~1 ~9 ~19 ~1 ~9 obsidian 0  
fill ~17 ~1 ~17 ~21 ~1 ~17 netherrack 0  
fill ~17 ~1 ~32 ~18 ~1 ~32 stone 2  
fill ~17 ~1 ~33 ~18 ~1 ~33 stone 2  
fill ~17 ~1 ~34 ~18 ~1 ~34 cobblestone_wall 0  
fill ~17 ~1 ~40 ~18 ~1 ~40 cobblestone_wall 0  
fill ~17 ~1 ~41 ~18 ~1 ~41 stone 2  
fill ~17 ~1 ~42 ~18 ~1 ~42 stone 2  
fill ~17 ~1 ~43 ~18 ~1 ~43 cobblestone_wall 0 
setblock ~18 ~1 ~5 netherrack 0  
fill ~18 ~1 ~16 ~21 ~1 ~16 netherrack 0  
fill ~19 ~1 ~5 ~19 ~2 ~5 obsidian 0  
fill ~19 ~1 ~6 ~21 ~1 ~6 obsidian 0  
fill ~19 ~1 ~32 ~19 ~2 ~32 cobblestone_wall 0  
fill ~19 ~1 ~33 ~19 ~3 ~33 cobblestone_wall 0  
fill ~19 ~1 ~41 ~19 ~3 ~41 cobblestone_wall 0  
fill ~19 ~1 ~42 ~19 ~2 ~42 cobblestone_wall 0 
setblock ~20 ~1 ~9 netherrack 0 
setblock ~20 ~1 ~10 magma 0 
setblock ~21 ~1 ~5 magma 0 
setblock ~21 ~1 ~8 netherrack 0 
setblock ~21 ~1 ~9 magma 0 
setblock ~21 ~1 ~10 netherrack 0  
fill ~22 ~1 ~6 ~22 ~0 ~6 netherrack 0  
fill ~22 ~1 ~7 ~22 ~1 ~8 magma 0  
fill ~22 ~1 ~9 ~25 ~1 ~9 obsidian 0  
fill ~22 ~1 ~10 ~26 ~1 ~10 obsidian 0  
fill ~22 ~1 ~11 ~26 ~1 ~11 obsidian 0  
fill ~22 ~1 ~38 ~29 ~1 ~38 netherrack 0  
fill ~23 ~1 ~12 ~24 ~1 ~12 obsidian 0  
fill ~23 ~1 ~34 ~31 ~1 ~34 netherrack 0  
fill ~23 ~1 ~35 ~31 ~1 ~35 netherrack 0  
fill ~23 ~1 ~36 ~31 ~1 ~36 netherrack 0  
fill ~23 ~1 ~37 ~29 ~1 ~37 netherrack 0  
fill ~23 ~1 ~39 ~27 ~1 ~39 netherrack 0  
fill ~24 ~1 ~17 ~32 ~1 ~17 netherrack 0  
fill ~24 ~1 ~40 ~26 ~1 ~40 netherrack 0  
fill ~25 ~1 ~16 ~29 ~1 ~16 netherrack 0  
fill ~25 ~1 ~18 ~32 ~1 ~18 netherrack 0  
fill ~25 ~1 ~19 ~32 ~1 ~19 netherrack 0  
fill ~25 ~1 ~20 ~32 ~1 ~20 netherrack 0  
fill ~25 ~1 ~21 ~33 ~1 ~21 netherrack 0  
fill ~25 ~1 ~33 ~31 ~1 ~33 netherrack 0  
fill ~26 ~1 ~22 ~33 ~1 ~22 netherrack 0  
fill ~26 ~1 ~23 ~31 ~1 ~23 netherrack 0  
fill ~26 ~1 ~32 ~31 ~1 ~32 netherrack 0  
fill ~28 ~1 ~24 ~32 ~1 ~24 netherrack 0  
fill ~28 ~1 ~25 ~35 ~1 ~25 netherrack 0  
fill ~28 ~1 ~26 ~35 ~1 ~26 netherrack 0  
fill ~28 ~1 ~28 ~35 ~1 ~28 netherrack 0 
setblock ~28 ~1 ~31 netherrack 0  
fill ~29 ~1 ~27 ~35 ~1 ~27 netherrack 0  
fill ~29 ~1 ~29 ~33 ~1 ~29 netherrack 0  
fill ~29 ~1 ~30 ~33 ~1 ~30 netherrack 0 
setblock ~31 ~1 ~31 netherrack 0  
fill ~34 ~1 ~24 ~35 ~1 ~24 netherrack 0 
setblock ~35 ~1 ~23 netherrack 0  
fill ~1 ~2 ~13 ~1 ~2 ~14 obsidian 0  
fill ~1 ~2 ~19 ~3 ~2 ~19 obsidian 0  
fill ~2 ~2 ~12 ~2 ~2 ~13 nether_brick 0  
fill ~2 ~2 ~15 ~3 ~2 ~15 obsidian 0  
fill ~2 ~2 ~22 ~6 ~2 ~22 netherrack 0  
fill ~2 ~2 ~23 ~6 ~2 ~23 netherrack 0  
fill ~2 ~2 ~24 ~6 ~2 ~24 netherrack 0  
fill ~2 ~2 ~25 ~5 ~2 ~25 netherrack 0  
fill ~3 ~2 ~12 ~3 ~2 ~15 obsidian 0  
fill ~3 ~2 ~21 ~6 ~2 ~21 netherrack 0 
setblock ~3 ~2 ~26 netherrack 0  
fill ~4 ~2 ~13 ~4 ~2 ~14 obsidian 0 
setblock ~4 ~2 ~18 magma 0  
fill ~4 ~2 ~20 ~8 ~2 ~20 netherrack 0  
fill ~5 ~2 ~15 ~6 ~2 ~15 netherrack 0  
fill ~5 ~2 ~16 ~9 ~2 ~16 netherrack 0  
fill ~5 ~2 ~17 ~10 ~2 ~17 netherrack 0  
fill ~5 ~2 ~18 ~10 ~2 ~18 netherrack 0  
fill ~5 ~2 ~19 ~9 ~2 ~19 netherrack 0  
fill ~9 ~2 ~14 ~9 ~0 ~14 netherrack 0  
fill ~9 ~2 ~15 ~10 ~2 ~15 netherrack 0 
setblock ~10 ~2 ~29 stained_hardened_clay 9  
fill ~11 ~2 ~28 ~11 ~3 ~28 stained_hardened_clay 9  
fill ~11 ~2 ~29 ~11 ~2 ~30 log2 12  
fill ~12 ~2 ~28 ~13 ~2 ~28 log2 12  
fill ~12 ~2 ~30 ~15 ~2 ~30 log2 12  
fill ~12 ~2 ~31 ~14 ~2 ~31 log2 12  
fill ~13 ~2 ~26 ~14 ~2 ~26 planks 5  
fill ~13 ~2 ~27 ~13 ~2 ~26 planks 5  
fill ~13 ~2 ~29 ~15 ~2 ~29 log2 12 
setblock ~13 ~2 ~46 stained_glass 14  
fill ~14 ~2 ~8 ~19 ~2 ~8 netherrack 0  
fill ~14 ~2 ~25 ~16 ~2 ~25 planks 5  
fill ~14 ~2 ~27 ~14 ~3 ~27 log2 12 
setblock ~14 ~2 ~28 planks 5  
fill ~14 ~2 ~32 ~15 ~2 ~32 stone 2  
fill ~14 ~2 ~33 ~15 ~2 ~33 stone 2  
fill ~14 ~2 ~34 ~15 ~2 ~34 cobblestone_wall 0  
fill ~14 ~2 ~40 ~15 ~2 ~40 cobblestone_wall 0  
fill ~14 ~2 ~41 ~15 ~2 ~41 stone 2  
fill ~14 ~2 ~42 ~15 ~2 ~42 stone 2  
fill ~14 ~2 ~43 ~15 ~2 ~43 cobblestone_wall 0 
setblock ~14 ~2 ~48 stained_glass_pane 0  
fill ~15 ~2 ~7 ~17 ~2 ~7 netherrack 0  
fill ~15 ~2 ~9 ~19 ~2 ~9 netherrack 0  
fill ~15 ~2 ~24 ~16 ~2 ~24 planks 5 
setblock ~15 ~2 ~26 stained_hardened_clay 15  
fill ~15 ~2 ~27 ~16 ~2 ~27 planks 5  
fill ~15 ~2 ~28 ~15 ~3 ~28 log2 12  
fill ~16 ~2 ~10 ~18 ~2 ~10 netherrack 0  
fill ~16 ~2 ~19 ~19 ~2 ~19 netherrack 0  
fill ~16 ~2 ~20 ~18 ~2 ~20 netherrack 0  
fill ~16 ~2 ~21 ~18 ~2 ~21 netherrack 0  
fill ~16 ~2 ~26 ~16 ~3 ~26 planks 5  
fill ~17 ~2 ~6 ~17 ~1 ~6 magma 0  
fill ~17 ~2 ~32 ~18 ~2 ~32 stone 2  
fill ~17 ~2 ~33 ~18 ~2 ~33 stone 2  
fill ~17 ~2 ~34 ~18 ~2 ~34 cobblestone_wall 0  
fill ~17 ~2 ~40 ~18 ~2 ~40 cobblestone_wall 0  
fill ~17 ~2 ~41 ~18 ~2 ~41 stone 2  
fill ~17 ~2 ~42 ~18 ~2 ~42 stone 2  
fill ~17 ~2 ~43 ~18 ~2 ~43 cobblestone_wall 0 
setblock ~18 ~2 ~7 magma 0  
fill ~18 ~2 ~17 ~20 ~2 ~17 netherrack 0  
fill ~18 ~2 ~18 ~20 ~2 ~18 netherrack 0  
fill ~19 ~2 ~6 ~21 ~2 ~6 obsidian 0  
fill ~19 ~2 ~7 ~21 ~2 ~7 obsidian 0  
fill ~20 ~2 ~5 ~21 ~2 ~5 obsidian 0 
setblock ~20 ~2 ~8 magma 0  
fill ~22 ~2 ~9 ~24 ~2 ~9 obsidian 0  
fill ~22 ~2 ~10 ~25 ~2 ~10 obsidian 0  
fill ~22 ~2 ~11 ~25 ~2 ~11 obsidian 0  
fill ~23 ~2 ~12 ~24 ~2 ~12 obsidian 0  
fill ~24 ~2 ~36 ~30 ~2 ~36 netherrack 0  
fill ~24 ~2 ~37 ~29 ~2 ~37 netherrack 0  
fill ~24 ~2 ~38 ~27 ~2 ~38 netherrack 0  
fill ~25 ~2 ~19 ~29 ~2 ~19 netherrack 0  
fill ~25 ~2 ~34 ~30 ~2 ~34 netherrack 0  
fill ~25 ~2 ~35 ~30 ~2 ~35 netherrack 0  
fill ~25 ~2 ~39 ~26 ~2 ~39 netherrack 0  
fill ~26 ~2 ~18 ~29 ~2 ~18 netherrack 0  
fill ~26 ~2 ~20 ~32 ~2 ~20 netherrack 0  
fill ~26 ~2 ~21 ~30 ~2 ~21 netherrack 0  
fill ~26 ~2 ~33 ~30 ~2 ~33 netherrack 0  
fill ~27 ~2 ~32 ~29 ~2 ~32 netherrack 0  
fill ~28 ~2 ~17 ~29 ~2 ~17 netherrack 0  
fill ~28 ~2 ~22 ~29 ~2 ~22 netherrack 0  
fill ~28 ~2 ~23 ~29 ~2 ~23 netherrack 0  
fill ~28 ~2 ~24 ~28 ~0 ~24 netherrack 0  
fill ~29 ~2 ~27 ~31 ~2 ~27 netherrack 0  
fill ~29 ~2 ~28 ~29 ~2 ~27 netherrack 0  
fill ~30 ~2 ~26 ~32 ~2 ~26 netherrack 0 
setblock ~31 ~2 ~19 netherrack 0 
setblock ~31 ~2 ~25 netherrack 0 
setblock ~31 ~2 ~29 netherrack 0 
setblock ~32 ~2 ~21 netherrack 0  
fill ~1 ~3 ~12 ~1 ~3 ~13 nether_brick 0 
setblock ~2 ~3 ~12 obsidian 0  
fill ~2 ~3 ~13 ~2 ~3 ~14 nether_brick 0  
fill ~2 ~3 ~19 ~2 ~4 ~19 obsidian 0 
setblock ~3 ~3 ~13 obsidian 0 
setblock ~3 ~3 ~14 nether_brick 0  
fill ~3 ~3 ~22 ~5 ~3 ~22 netherrack 0  
fill ~3 ~3 ~23 ~4 ~3 ~23 netherrack 0  
fill ~3 ~3 ~24 ~5 ~3 ~24 netherrack 0  
fill ~5 ~3 ~18 ~8 ~3 ~18 netherrack 0  
fill ~6 ~3 ~16 ~6 ~3 ~18 netherrack 0  
fill ~7 ~3 ~17 ~8 ~3 ~17 netherrack 0 
setblock ~8 ~3 ~19 netherrack 0  
fill ~12 ~3 ~27 ~14 ~3 ~27 log2 12  
fill ~12 ~3 ~28 ~15 ~3 ~28 log2 12  
fill ~12 ~3 ~30 ~14 ~3 ~30 log2 12 
setblock ~13 ~3 ~26 planks 5  
fill ~13 ~3 ~29 ~15 ~3 ~29 log2 12 
setblock ~13 ~3 ~48 log2 12  
fill ~14 ~3 ~25 ~14 ~3 ~30 log2 12  
fill ~14 ~3 ~32 ~15 ~3 ~32 stone 2  
fill ~14 ~3 ~33 ~15 ~3 ~33 stone 2  
fill ~14 ~3 ~34 ~14 ~1 ~34 cobblestone_wall 0  
fill ~14 ~3 ~40 ~14 ~1 ~40 cobblestone_wall 0  
fill ~14 ~3 ~41 ~15 ~3 ~41 stone 2  
fill ~14 ~3 ~42 ~15 ~3 ~42 stone 2  
fill ~15 ~3 ~25 ~15 ~6 ~25 planks 5 
setblock ~15 ~3 ~26 log2 12  
fill ~15 ~3 ~27 ~16 ~3 ~27 planks 5 
setblock ~15 ~3 ~43 cobblestone_wall 0  
fill ~16 ~3 ~21 ~17 ~3 ~21 planks 5  
fill ~16 ~3 ~22 ~17 ~3 ~22 planks 5  
fill ~17 ~3 ~20 ~18 ~3 ~20 planks 5  
fill ~17 ~3 ~32 ~18 ~3 ~32 stone 2  
fill ~17 ~3 ~33 ~18 ~3 ~33 stone 2  
fill ~17 ~3 ~41 ~18 ~3 ~41 stone 2  
fill ~17 ~3 ~42 ~18 ~3 ~42 stone 2  
fill ~17 ~3 ~43 ~17 ~1 ~43 cobblestone_wall 0 
setblock ~18 ~3 ~21 wooden_slab 13 
setblock ~18 ~3 ~34 cobblestone_wall 0 
setblock ~18 ~3 ~40 cobblestone_wall 0  
fill ~19 ~3 ~6 ~21 ~3 ~6 obsidian 0  
fill ~19 ~3 ~7 ~20 ~3 ~7 obsidian 0  
fill ~19 ~3 ~19 ~19 ~3 ~20 wooden_slab 13  
fill ~20 ~3 ~5 ~21 ~3 ~5 nether_brick 0  
fill ~23 ~3 ~10 ~25 ~3 ~10 obsidian 0  
fill ~23 ~3 ~11 ~23 ~4 ~11 nether_brick 0  
fill ~23 ~3 ~12 ~25 ~3 ~12 nether_brick 0  
fill ~24 ~3 ~11 ~25 ~3 ~11 obsidian 0  
fill ~26 ~3 ~34 ~28 ~3 ~34 netherrack 0  
fill ~26 ~3 ~35 ~28 ~3 ~35 netherrack 0  
fill ~26 ~3 ~36 ~28 ~3 ~36 netherrack 0  
fill ~27 ~3 ~19 ~29 ~3 ~19 netherrack 0 
setblock ~27 ~3 ~33 netherrack 0 
setblock ~27 ~3 ~37 netherrack 0  
fill ~28 ~3 ~18 ~29 ~3 ~18 netherrack 0  
fill ~28 ~3 ~20 ~28 ~3 ~21 netherrack 0  
fill ~28 ~3 ~23 ~28 ~0 ~23 netherrack 0 
setblock ~29 ~3 ~21 netherrack 0  
fill ~0 ~4 ~12 ~1 ~4 ~12 obsidian 0  
fill ~1 ~4 ~11 ~1 ~5 ~11 nether_brick 0 
setblock ~1 ~4 ~13 nether_brick 0 
setblock ~2 ~4 ~12 nether_brick 0  
fill ~12 ~4 ~26 ~14 ~4 ~26 log2 12  
fill ~12 ~4 ~27 ~13 ~4 ~27 log2 12  
fill ~12 ~4 ~28 ~14 ~4 ~28 log2 12 
setblock ~12 ~4 ~49 log2 12 
setblock ~13 ~4 ~25 log2 12  
fill ~13 ~4 ~29 ~14 ~4 ~29 log2 12  
fill ~13 ~4 ~47 ~13 ~5 ~47 log2 12  
fill ~14 ~4 ~25 ~14 ~5 ~25 planks 5  
fill ~14 ~4 ~27 ~15 ~4 ~27 planks 5  
fill ~14 ~4 ~32 ~15 ~4 ~32 stone 2  
fill ~14 ~4 ~33 ~15 ~4 ~33 stone 2  
fill ~14 ~4 ~41 ~15 ~4 ~41 stone 2  
fill ~14 ~4 ~42 ~15 ~4 ~42 stone 2  
fill ~15 ~4 ~26 ~16 ~4 ~26 stained_hardened_clay 15 
setblock ~16 ~4 ~27 stained_hardened_clay 15 
setblock ~16 ~4 ~32 stone_brick_stairs 6 
setblock ~16 ~4 ~42 stone_brick_stairs 7  
fill ~17 ~4 ~20 ~20 ~4 ~20 planks 5  
fill ~17 ~4 ~21 ~18 ~4 ~21 wooden_slab 5  
fill ~17 ~4 ~32 ~18 ~4 ~32 stone 2  
fill ~17 ~4 ~33 ~18 ~4 ~33 stone 2  
fill ~17 ~4 ~41 ~18 ~4 ~41 stone 2  
fill ~17 ~4 ~42 ~18 ~4 ~42 stone 2  
fill ~18 ~4 ~19 ~21 ~4 ~19 planks 5  
fill ~19 ~4 ~18 ~21 ~4 ~18 planks 5 
setblock ~20 ~4 ~5 obsidian 0 
setblock ~20 ~4 ~6 nether_brick 0  
fill ~20 ~4 ~16 ~20 ~5 ~16 planks 5  
fill ~20 ~4 ~17 ~21 ~4 ~17 planks 5 
setblock ~21 ~4 ~4 obsidian 0  
fill ~21 ~4 ~5 ~22 ~4 ~5 nether_brick 0 
setblock ~21 ~4 ~6 obsidian 0  
fill ~24 ~4 ~11 ~24 ~4 ~12 nether_brick 0  
fill ~25 ~4 ~11 ~25 ~5 ~11 obsidian 0 
setblock ~25 ~4 ~12 nether_brick 0  
fill ~25 ~4 ~13 ~25 ~7 ~13 obsidian 0 
setblock ~26 ~4 ~12 obsidian 0  
fill ~0 ~5 ~11 ~0 ~5 ~12 nether_brick 0 
setblock ~1 ~5 ~12 obsidian 0 
setblock ~12 ~5 ~25 log2 12  
fill ~12 ~5 ~26 ~13 ~5 ~26 stained_hardened_clay 9  
fill ~12 ~5 ~27 ~12 ~3 ~27 log2 12  
fill ~13 ~5 ~24 ~13 ~7 ~24 log2 12  
fill ~13 ~5 ~25 ~13 ~7 ~25 stained_hardened_clay 9  
fill ~13 ~5 ~27 ~13 ~6 ~27 stained_hardened_clay 9 
setblock ~13 ~5 ~28 log2 12  
fill ~14 ~5 ~26 ~14 ~6 ~26 planks 5  
fill ~14 ~5 ~27 ~16 ~5 ~27 planks 5 
setblock ~14 ~5 ~32 stone_brick_stairs 2 
setblock ~14 ~5 ~33 stone_brick_stairs 0 
setblock ~14 ~5 ~41 stone_brick_stairs 0 
setblock ~14 ~5 ~42 stone_brick_stairs 3  
fill ~15 ~5 ~26 ~16 ~5 ~26 stained_hardened_clay 15 
setblock ~15 ~5 ~32 stone_brick_stairs 1 
setblock ~15 ~5 ~33 stone_brick_stairs 3 
setblock ~15 ~5 ~41 stone_brick_stairs 2 
setblock ~15 ~5 ~42 stone_brick_stairs 1  
fill ~16 ~5 ~25 ~16 ~14 ~25 planks 5 
setblock ~16 ~5 ~32 stone_brick_stairs 2 
setblock ~16 ~5 ~42 stone_brick_stairs 3 
setblock ~17 ~5 ~32 stone_brick_stairs 0 
setblock ~17 ~5 ~33 stone_brick_stairs 3 
setblock ~17 ~5 ~41 stone_brick_stairs 2 
setblock ~17 ~5 ~42 stone_brick_stairs 0  
fill ~18 ~5 ~19 ~22 ~5 ~19 planks 5  
fill ~18 ~5 ~20 ~19 ~5 ~20 stained_hardened_clay 15 
setblock ~18 ~5 ~32 stone_brick_stairs 2 
setblock ~18 ~5 ~33 stone_brick_stairs 1 
setblock ~18 ~5 ~41 stone_brick_stairs 1 
setblock ~18 ~5 ~42 stone_brick_stairs 3  
fill ~19 ~5 ~18 ~22 ~5 ~18 planks 5  
fill ~20 ~5 ~17 ~21 ~5 ~17 planks 5  
fill ~20 ~5 ~20 ~21 ~5 ~20 planks 5  
fill ~21 ~5 ~4 ~22 ~5 ~4 nether_brick 0 
setblock ~21 ~5 ~5 obsidian 0 
setblock ~21 ~5 ~16 planks 5 
setblock ~22 ~5 ~5 nether_brick 0  
fill ~24 ~5 ~11 ~24 ~5 ~12 obsidian 0  
fill ~25 ~5 ~12 ~25 ~7 ~12 obsidian 0 
setblock ~26 ~5 ~12 nether_brick 0 
setblock ~26 ~5 ~13 obsidian 0 
setblock ~0 ~6 ~11 obsidian 0 
setblock ~12 ~6 ~25 stained_hardened_clay 9 
setblock ~12 ~6 ~27 stained_glass 14 
setblock ~12 ~6 ~28 stained_glass_pane 0 
setblock ~12 ~6 ~46 stained_glass 14 
setblock ~13 ~6 ~26 stained_hardened_clay 9  
fill ~13 ~6 ~44 ~13 ~7 ~44 log2 12  
fill ~13 ~6 ~46 ~13 ~9 ~46 log2 12  
fill ~14 ~6 ~24 ~16 ~6 ~24 log2 12 
setblock ~14 ~6 ~25 stained_hardened_clay 9  
fill ~14 ~6 ~27 ~14 ~4 ~27 planks 5 
setblock ~14 ~6 ~32 stone_brick_stairs 6 
setblock ~14 ~6 ~33 stone_brick_stairs 4 
setblock ~14 ~6 ~41 stone_brick_stairs 4 
setblock ~14 ~6 ~42 stone_brick_stairs 7 
setblock ~14 ~6 ~46 stained_glass_pane 0 
setblock ~14 ~6 ~47 stained_glass 14  
fill ~15 ~6 ~26 ~16 ~6 ~26 planks 5  
fill ~15 ~6 ~27 ~15 ~7 ~27 stained_hardened_clay 15 
setblock ~15 ~6 ~32 stone_brick_stairs 5 
setblock ~15 ~6 ~33 stone_brick_stairs 7 
setblock ~15 ~6 ~41 stone_brick_stairs 6 
setblock ~15 ~6 ~42 stone_brick_stairs 5  
fill ~16 ~6 ~27 ~16 ~18 ~27 planks 5 
setblock ~16 ~6 ~32 stone_brick_stairs 6 
setblock ~16 ~6 ~42 stone_brick_stairs 7 
setblock ~17 ~6 ~32 stone_brick_stairs 4 
setblock ~17 ~6 ~33 stone_brick_stairs 7 
setblock ~17 ~6 ~41 stone_brick_stairs 6 
setblock ~17 ~6 ~42 stone_brick_stairs 4  
fill ~18 ~6 ~19 ~20 ~6 ~19 stained_hardened_clay 15 
setblock ~18 ~6 ~32 stone_brick_stairs 6 
setblock ~18 ~6 ~33 stone_brick_stairs 5 
setblock ~18 ~6 ~41 stone_brick_stairs 5 
setblock ~18 ~6 ~42 stone_brick_stairs 7  
fill ~19 ~6 ~20 ~19 ~10 ~20 planks 5  
fill ~20 ~6 ~17 ~21 ~6 ~17 planks 5  
fill ~20 ~6 ~18 ~22 ~6 ~18 planks 5  
fill ~20 ~6 ~20 ~20 ~7 ~20 stained_hardened_clay 15  
fill ~21 ~6 ~19 ~22 ~6 ~19 planks 5  
fill ~21 ~6 ~20 ~21 ~14 ~20 planks 5 
setblock ~22 ~6 ~4 nether_brick 0  
fill ~23 ~6 ~3 ~23 ~7 ~3 obsidian 0  
fill ~26 ~6 ~12 ~26 ~7 ~12 obsidian 0 
setblock ~26 ~6 ~13 nether_brick 0 
setblock ~13 ~7 ~28 stained_glass 14  
fill ~14 ~7 ~23 ~16 ~7 ~23 log2 12  
fill ~14 ~7 ~24 ~17 ~7 ~24 log2 12  
fill ~14 ~7 ~25 ~15 ~7 ~25 log2 12 
setblock ~14 ~7 ~26 stained_hardened_clay 9  
fill ~14 ~7 ~27 ~14 ~12 ~27 stained_hardened_clay 15 
setblock ~14 ~7 ~32 stone_brick_stairs 2 
setblock ~14 ~7 ~33 stone_brick_stairs 0 
setblock ~14 ~7 ~41 stone_brick_stairs 0 
setblock ~14 ~7 ~42 stone_brick_stairs 3 
setblock ~15 ~7 ~32 stone_brick_stairs 1 
setblock ~15 ~7 ~33 stone_brick_stairs 3 
setblock ~15 ~7 ~41 stone_brick_stairs 2 
setblock ~15 ~7 ~42 stone_brick_stairs 1  
fill ~16 ~7 ~26 ~16 ~19 ~26 planks 5 
setblock ~16 ~7 ~32 stone_brick_stairs 2 
setblock ~16 ~7 ~42 stone_brick_stairs 3  
fill ~17 ~7 ~25 ~17 ~9 ~25 log2 12 
setblock ~17 ~7 ~32 stone_brick_stairs 0 
setblock ~17 ~7 ~33 stone_brick_stairs 3 
setblock ~17 ~7 ~41 stone_brick_stairs 2 
setblock ~17 ~7 ~42 stone_brick_stairs 0 
setblock ~18 ~7 ~32 stone_brick_stairs 2 
setblock ~18 ~7 ~33 stone_brick_stairs 1 
setblock ~18 ~7 ~41 stone_brick_stairs 1 
setblock ~18 ~7 ~42 stone_brick_stairs 3  
fill ~19 ~7 ~19 ~21 ~7 ~19 planks 5  
fill ~19 ~7 ~21 ~21 ~7 ~21 planks 5  
fill ~20 ~7 ~18 ~21 ~7 ~18 planks 5  
fill ~26 ~7 ~13 ~27 ~7 ~13 obsidian 0  
fill ~26 ~7 ~14 ~26 ~9 ~14 obsidian 0  
fill ~12 ~8 ~44 ~13 ~8 ~44 stained_glass_pane 0 
setblock ~13 ~8 ~45 log2 12  
fill ~14 ~8 ~24 ~17 ~8 ~24 log2 12  
fill ~14 ~8 ~25 ~14 ~7 ~25 log2 12 
setblock ~14 ~8 ~26 stained_hardened_clay 15  
fill ~14 ~8 ~32 ~15 ~8 ~32 stone 2  
fill ~14 ~8 ~33 ~15 ~8 ~33 stone 2  
fill ~14 ~8 ~41 ~15 ~8 ~41 stone 2  
fill ~14 ~8 ~42 ~15 ~8 ~42 stone 2  
fill ~15 ~8 ~23 ~16 ~8 ~23 log2 12  
fill ~15 ~8 ~25 ~15 ~14 ~25 planks 5  
fill ~15 ~8 ~27 ~15 ~9 ~27 planks 5  
fill ~17 ~8 ~26 ~18 ~8 ~26 log2 12  
fill ~17 ~8 ~32 ~18 ~8 ~32 stone 2  
fill ~17 ~8 ~33 ~18 ~8 ~33 stone 2  
fill ~17 ~8 ~41 ~18 ~8 ~41 stone 2  
fill ~17 ~8 ~42 ~18 ~8 ~42 stone 2  
fill ~18 ~8 ~25 ~18 ~9 ~25 log2 12  
fill ~19 ~8 ~19 ~21 ~8 ~19 planks 5  
fill ~19 ~8 ~21 ~21 ~8 ~21 planks 5  
fill ~20 ~8 ~18 ~21 ~8 ~18 planks 5  
fill ~20 ~8 ~20 ~20 ~13 ~20 planks 5  
fill ~20 ~8 ~22 ~20 ~9 ~22 planks 5  
fill ~26 ~8 ~13 ~27 ~8 ~13 obsidian 0  
fill ~27 ~8 ~14 ~27 ~11 ~14 obsidian 0 
setblock ~12 ~9 ~45 stained_glass 14  
fill ~13 ~9 ~26 ~14 ~9 ~26 planks 5  
fill ~13 ~9 ~32 ~14 ~9 ~32 brick_stairs 2  
fill ~13 ~9 ~42 ~14 ~9 ~42 brick_stairs 3 
setblock ~13 ~9 ~44 stained_glass 14  
fill ~14 ~9 ~25 ~14 ~14 ~25 planks 5 
setblock ~14 ~9 ~33 brick_stairs 3 
setblock ~14 ~9 ~41 brick_stairs 2  
fill ~15 ~9 ~22 ~16 ~9 ~22 log2 12  
fill ~15 ~9 ~23 ~16 ~9 ~23 log2 12  
fill ~15 ~9 ~24 ~17 ~9 ~24 log2 12  
fill ~15 ~9 ~32 ~15 ~11 ~32 stone 2  
fill ~15 ~9 ~33 ~15 ~11 ~33 stone 2 
setblock ~15 ~9 ~36 nether_brick_fence 0 
setblock ~15 ~9 ~37 nether_brick_stairs 4 
setblock ~15 ~9 ~38 nether_brick_fence 0  
fill ~15 ~9 ~41 ~15 ~11 ~41 stone 2  
fill ~15 ~9 ~42 ~15 ~11 ~42 stone 2  
fill ~17 ~9 ~26 ~18 ~9 ~26 log2 12  
fill ~17 ~9 ~27 ~18 ~9 ~27 log2 12  
fill ~17 ~9 ~28 ~18 ~9 ~28 log2 12  
fill ~17 ~9 ~32 ~17 ~11 ~32 stone 2  
fill ~17 ~9 ~33 ~17 ~11 ~33 stone 2 
setblock ~17 ~9 ~36 nether_brick_fence 0 
setblock ~17 ~9 ~37 nether_brick_stairs 5 
setblock ~17 ~9 ~38 nether_brick_fence 0  
fill ~17 ~9 ~41 ~17 ~11 ~41 stone 2  
fill ~17 ~9 ~42 ~17 ~11 ~42 stone 2  
fill ~18 ~9 ~32 ~19 ~9 ~32 brick_stairs 2 
setblock ~18 ~9 ~33 brick_stairs 3 
setblock ~18 ~9 ~41 brick_stairs 2  
fill ~18 ~9 ~42 ~19 ~9 ~42 brick_stairs 3  
fill ~19 ~9 ~19 ~21 ~9 ~19 planks 5  
fill ~19 ~9 ~21 ~22 ~9 ~21 planks 5  
fill ~21 ~9 ~22 ~21 ~12 ~22 planks 5 
setblock ~22 ~9 ~20 stained_hardened_clay 15 
setblock ~27 ~9 ~13 obsidian 0  
fill ~13 ~10 ~25 ~13 ~14 ~25 planks 5  
fill ~13 ~10 ~32 ~14 ~10 ~32 brick_stairs 2  
fill ~13 ~10 ~33 ~14 ~10 ~33 brick_stairs 7  
fill ~13 ~10 ~41 ~14 ~10 ~41 brick_stairs 6  
fill ~13 ~10 ~42 ~14 ~10 ~42 brick_stairs 3 
setblock ~13 ~10 ~47 log2 12  
fill ~14 ~10 ~26 ~14 ~12 ~26 stained_hardened_clay 15  
fill ~15 ~10 ~22 ~16 ~10 ~22 log2 12  
fill ~15 ~10 ~23 ~17 ~10 ~23 log2 12  
fill ~15 ~10 ~24 ~16 ~10 ~24 planks 5 
setblock ~15 ~10 ~26 planks 5  
fill ~15 ~10 ~27 ~15 ~11 ~27 stained_hardened_clay 15  
fill ~15 ~10 ~36 ~15 ~11 ~36 nether_brick_stairs 7 
setblock ~15 ~10 ~37 stone_slab 6  
fill ~15 ~10 ~38 ~15 ~11 ~38 nether_brick_stairs 6  
fill ~16 ~10 ~28 ~18 ~10 ~28 log2 12  
fill ~16 ~10 ~29 ~17 ~10 ~29 log2 12  
fill ~17 ~10 ~24 ~17 ~15 ~24 log2 12  
fill ~17 ~10 ~26 ~17 ~14 ~26 planks 5  
fill ~17 ~10 ~27 ~17 ~15 ~27 planks 5  
fill ~17 ~10 ~36 ~17 ~11 ~36 nether_brick_stairs 7 
setblock ~17 ~10 ~37 stone_slab 6  
fill ~17 ~10 ~38 ~17 ~11 ~38 nether_brick_stairs 6 
setblock ~18 ~10 ~27 log2 12  
fill ~18 ~10 ~32 ~19 ~10 ~32 brick_stairs 2  
fill ~18 ~10 ~33 ~19 ~10 ~33 brick_stairs 7  
fill ~18 ~10 ~41 ~19 ~10 ~41 brick_stairs 6  
fill ~18 ~10 ~42 ~19 ~10 ~42 brick_stairs 3  
fill ~19 ~10 ~21 ~19 ~12 ~21 stained_hardened_clay 15 
setblock ~19 ~10 ~22 planks 5  
fill ~19 ~10 ~23 ~19 ~16 ~23 stained_hardened_clay 15  
fill ~20 ~10 ~19 ~21 ~10 ~19 planks 5  
fill ~20 ~10 ~21 ~20 ~11 ~21 planks 5 
setblock ~20 ~10 ~22 stained_hardened_clay 15  
fill ~20 ~10 ~23 ~21 ~10 ~23 planks 5 
setblock ~21 ~10 ~21 stained_hardened_clay 15  
fill ~22 ~10 ~20 ~22 ~11 ~20 planks 5  
fill ~22 ~10 ~21 ~22 ~10 ~20 planks 5  
fill ~12 ~11 ~47 ~12 ~12 ~47 log2 12  
fill ~14 ~11 ~32 ~14 ~11 ~33 stone 2  
fill ~14 ~11 ~34 ~15 ~11 ~34 nether_brick_stairs 7  
fill ~14 ~11 ~40 ~15 ~11 ~40 nether_brick_stairs 6  
fill ~14 ~11 ~41 ~14 ~11 ~42 stone 2  
fill ~15 ~11 ~23 ~15 ~7 ~23 log2 12  
fill ~15 ~11 ~24 ~16 ~11 ~24 planks 5 
setblock ~15 ~11 ~26 stained_hardened_clay 15  
fill ~15 ~11 ~28 ~15 ~12 ~28 log2 12  
fill ~15 ~11 ~29 ~17 ~11 ~29 log2 12  
fill ~16 ~11 ~22 ~17 ~11 ~22 stained_hardened_clay 9  
fill ~16 ~11 ~23 ~16 ~13 ~23 stained_hardened_clay 9  
fill ~16 ~11 ~28 ~16 ~17 ~28 planks 5 
setblock ~17 ~11 ~23 log2 12  
fill ~17 ~11 ~25 ~17 ~13 ~25 planks 5 
setblock ~17 ~11 ~28 log2 12  
fill ~17 ~11 ~34 ~18 ~11 ~34 nether_brick_stairs 7  
fill ~17 ~11 ~40 ~18 ~11 ~40 nether_brick_stairs 6  
fill ~18 ~11 ~24 ~18 ~12 ~24 log2 12  
fill ~18 ~11 ~32 ~18 ~11 ~33 stone 2  
fill ~18 ~11 ~41 ~18 ~11 ~42 stone 2 
setblock ~19 ~11 ~20 stained_hardened_clay 15  
fill ~19 ~11 ~22 ~19 ~12 ~22 stained_hardened_clay 15  
fill ~20 ~11 ~19 ~21 ~11 ~19 planks 5  
fill ~20 ~11 ~22 ~20 ~14 ~22 planks 5 
setblock ~20 ~11 ~23 stained_hardened_clay 15  
fill ~20 ~11 ~24 ~20 ~13 ~24 planks 5 
setblock ~21 ~11 ~21 planks 5 
setblock ~21 ~11 ~23 planks 5 
setblock ~22 ~11 ~21 stained_hardened_clay 15  
fill ~22 ~11 ~22 ~22 ~12 ~22 planks 5  
fill ~13 ~12 ~26 ~13 ~14 ~26 planks 5  
fill ~14 ~12 ~24 ~16 ~12 ~24 planks 5  
fill ~14 ~12 ~29 ~16 ~12 ~29 log2 12 
setblock ~14 ~12 ~32 stone_brick_stairs 0 
setblock ~14 ~12 ~33 stone_brick_stairs 3 
setblock ~14 ~12 ~41 stone_brick_stairs 0 
setblock ~14 ~12 ~42 stone_brick_stairs 3 
setblock ~14 ~12 ~47 red_glazed_terracotta 0 
setblock ~15 ~12 ~23 stained_hardened_clay 9   
fill ~15 ~12 ~26 ~15 ~24 ~26 planks 5  
fill ~15 ~12 ~27 ~15 ~12 ~24 planks 5 
setblock ~15 ~12 ~32 stone_brick_stairs 2 
setblock ~15 ~12 ~33 stone_brick_stairs 1 
setblock ~15 ~12 ~35 stone_slab 14 
setblock ~15 ~12 ~39 stone_slab 14 
setblock ~15 ~12 ~41 stone_brick_stairs 2 
setblock ~15 ~12 ~42 stone_brick_stairs 1  
fill ~16 ~12 ~22 ~17 ~12 ~22 stained_hardened_clay 9 
setblock ~17 ~12 ~23 stained_hardened_clay 9 
setblock ~17 ~12 ~32 stone_brick_stairs 2 
setblock ~17 ~12 ~33 stone_brick_stairs 0 
setblock ~17 ~12 ~35 stone_slab 14 
setblock ~17 ~12 ~39 stone_slab 14 
setblock ~17 ~12 ~41 stone_brick_stairs 2 
setblock ~17 ~12 ~42 stone_brick_stairs 0  
fill ~18 ~12 ~25 ~18 ~18 ~25 log2 12 
setblock ~18 ~12 ~32 stone_brick_stairs 1 
setblock ~18 ~12 ~33 stone_brick_stairs 3 
setblock ~18 ~12 ~41 stone_brick_stairs 1 
setblock ~18 ~12 ~42 stone_brick_stairs 3  
fill ~20 ~12 ~19 ~21 ~12 ~19 planks 5  
fill ~20 ~12 ~21 ~21 ~12 ~21 stained_hardened_clay 15 
setblock ~20 ~12 ~23 planks 5  
fill ~21 ~12 ~23 ~22 ~12 ~23 stained_hardened_clay 15  
fill ~21 ~12 ~24 ~21 ~15 ~24 planks 5  
fill ~22 ~12 ~21 ~22 ~13 ~21 planks 5  
fill ~12 ~13 ~28 ~13 ~13 ~28 log2 12 
setblock ~12 ~13 ~47 stained_glass_pane 0  
fill ~13 ~13 ~27 ~14 ~13 ~27 planks 5  
fill ~13 ~13 ~29 ~15 ~13 ~29 log2 12  
fill ~13 ~13 ~47 ~13 ~14 ~47 log2 12  
fill ~14 ~13 ~24 ~16 ~13 ~24 planks 5 
setblock ~14 ~13 ~26 planks 5 
setblock ~14 ~13 ~28 stained_hardened_clay 15  
fill ~14 ~13 ~32 ~15 ~13 ~32 stone_slab 5  
fill ~14 ~13 ~33 ~14 ~13 ~32 stone_slab 5  
fill ~14 ~13 ~34 ~15 ~13 ~34 stone_slab 12  
fill ~14 ~13 ~40 ~15 ~13 ~40 stone_slab 12  
fill ~14 ~13 ~41 ~14 ~13 ~42 stone_slab 5 
setblock ~15 ~13 ~27 stained_hardened_clay 15 
setblock ~15 ~13 ~28 planks 5  
fill ~15 ~13 ~33 ~15 ~14 ~33 double_stone_slab 6 
setblock ~15 ~13 ~35 nether_brick_stairs 6 
setblock ~15 ~13 ~37 stone_slab 14 
setblock ~15 ~13 ~39 nether_brick_stairs 7  
fill ~15 ~13 ~41 ~15 ~14 ~41 double_stone_slab 6 
setblock ~15 ~13 ~42 stone_slab 5  
fill ~17 ~13 ~23 ~17 ~14 ~23 log2 12  
fill ~17 ~13 ~28 ~17 ~15 ~28 planks 5  
fill ~17 ~13 ~32 ~18 ~13 ~32 stone_slab 5  
fill ~17 ~13 ~33 ~17 ~14 ~33 double_stone_slab 6 
setblock ~17 ~13 ~35 nether_brick_stairs 6 
setblock ~17 ~13 ~37 stone_slab 14 
setblock ~17 ~13 ~39 nether_brick_stairs 7  
fill ~17 ~13 ~41 ~17 ~14 ~41 double_stone_slab 6  
fill ~17 ~13 ~42 ~18 ~13 ~42 stone_slab 5 
setblock ~18 ~13 ~33 stone_slab 5 
setblock ~18 ~13 ~41 stone_slab 5 
setblock ~19 ~13 ~22 planks 5  
fill ~19 ~13 ~24 ~19 ~13 ~25 planks 5  
fill ~20 ~13 ~21 ~22 ~13 ~21 planks 5  
fill ~20 ~13 ~23 ~20 ~16 ~23 stained_hardened_clay 15  
fill ~20 ~13 ~25 ~21 ~13 ~25 planks 5  
fill ~21 ~13 ~22 ~22 ~13 ~22 stained_hardened_clay 15  
fill ~21 ~13 ~23 ~21 ~16 ~23 planks 5 
setblock ~22 ~13 ~23 stained_hardened_clay 15  
fill ~22 ~13 ~24 ~22 ~15 ~24 planks 5  
fill ~12 ~14 ~26 ~12 ~16 ~26 log2 12  
fill ~12 ~14 ~27 ~13 ~14 ~27 log2 12  
fill ~12 ~14 ~28 ~13 ~14 ~28 log2 12 
setblock ~12 ~14 ~47 stained_glass 14  
fill ~13 ~14 ~29 ~13 ~13 ~29 log2 12 
setblock ~13 ~14 ~46 red_glazed_terracotta 2  
fill ~14 ~14 ~24 ~16 ~14 ~24 planks 5  
fill ~14 ~14 ~26 ~14 ~16 ~26 stained_hardened_clay 15  
fill ~14 ~14 ~27 ~17 ~14 ~27 planks 5  
fill ~14 ~14 ~28 ~14 ~14 ~27 planks 5  
fill ~14 ~14 ~32 ~15 ~14 ~32 brick_stairs 2  
fill ~14 ~14 ~34 ~15 ~14 ~34 brick_stairs 7  
fill ~14 ~14 ~40 ~15 ~14 ~40 brick_stairs 6  
fill ~14 ~14 ~42 ~18 ~14 ~42 brick_stairs 3 
setblock ~15 ~14 ~28 stained_hardened_clay 15 
setblock ~15 ~14 ~35 nether_brick_stairs 3 
setblock ~15 ~14 ~37 stone_slab 6 
setblock ~15 ~14 ~39 nether_brick_stairs 2 
setblock ~16 ~14 ~23 log2 12  
fill ~17 ~14 ~25 ~17 ~17 ~25 log2 12  
fill ~17 ~14 ~32 ~18 ~14 ~32 brick_stairs 2  
fill ~17 ~14 ~34 ~18 ~14 ~34 brick_stairs 7 
setblock ~17 ~14 ~35 nether_brick_stairs 3 
setblock ~17 ~14 ~37 stone_slab 6 
setblock ~17 ~14 ~39 nether_brick_stairs 2  
fill ~17 ~14 ~40 ~18 ~14 ~40 brick_stairs 6 
setblock ~18 ~14 ~24 planks 5 
setblock ~18 ~14 ~26 log2 12  
fill ~19 ~14 ~22 ~19 ~16 ~22 stained_hardened_clay 15  
fill ~19 ~14 ~24 ~20 ~14 ~24 stained_hardened_clay 15  
fill ~19 ~14 ~25 ~22 ~14 ~25 planks 5  
fill ~20 ~14 ~21 ~20 ~15 ~21 stained_hardened_clay 15  
fill ~20 ~14 ~26 ~20 ~15 ~26 planks 5  
fill ~21 ~14 ~21 ~21 ~14 ~25 planks 5 
setblock ~22 ~14 ~23 planks 5  
fill ~11 ~15 ~26 ~11 ~16 ~26 log2 12  
fill ~11 ~15 ~48 ~12 ~15 ~48 red_glazed_terracotta 0  
fill ~12 ~15 ~25 ~13 ~15 ~25 log2 12  
fill ~12 ~15 ~27 ~12 ~14 ~27 log2 12  
fill ~13 ~15 ~26 ~13 ~16 ~26 log2 12  
fill ~13 ~15 ~27 ~13 ~16 ~27 planks 5  
fill ~13 ~15 ~28 ~13 ~17 ~28 planks 5  
fill ~13 ~15 ~46 ~13 ~16 ~46 log2 12  
fill ~14 ~15 ~25 ~15 ~15 ~25 stained_hardened_clay 15  
fill ~14 ~15 ~27 ~15 ~15 ~27 stained_hardened_clay 15  
fill ~14 ~15 ~28 ~14 ~15 ~25 stained_hardened_clay 15  
fill ~14 ~15 ~31 ~15 ~15 ~31 brick_stairs 2 
setblock ~14 ~15 ~32 brick_stairs 3 
setblock ~14 ~15 ~33 stone_slab 4  
fill ~14 ~15 ~34 ~14 ~16 ~34 brick_block 0  
fill ~14 ~15 ~40 ~14 ~16 ~40 brick_block 0 
setblock ~14 ~15 ~41 stone_slab 4 
setblock ~14 ~15 ~42 brick_stairs 2  
fill ~14 ~15 ~43 ~15 ~15 ~43 brick_stairs 3  
fill ~15 ~15 ~28 ~15 ~19 ~28 planks 5 
setblock ~15 ~15 ~32 double_stone_slab 6 
setblock ~15 ~15 ~33 nether_brick_stairs 2  
fill ~15 ~15 ~34 ~15 ~16 ~34 stonebrick 0  
fill ~15 ~15 ~35 ~15 ~15 ~36 nether_brick_stairs 7  
fill ~15 ~15 ~38 ~15 ~15 ~39 nether_brick_stairs 6  
fill ~15 ~15 ~40 ~15 ~16 ~40 stonebrick 0 
setblock ~15 ~15 ~41 nether_brick_stairs 3  
fill ~15 ~15 ~42 ~15 ~16 ~42 double_stone_slab 6  
fill ~16 ~15 ~23 ~17 ~15 ~23 stained_hardened_clay 9  
fill ~16 ~15 ~24 ~16 ~17 ~24 stained_hardened_clay 9 
setblock ~16 ~15 ~25 log2 12  
fill ~16 ~15 ~32 ~16 ~18 ~32 brick_block 0  
fill ~16 ~15 ~42 ~16 ~18 ~42 brick_block 0  
fill ~17 ~15 ~26 ~17 ~16 ~26 log2 12  
fill ~17 ~15 ~31 ~18 ~15 ~31 brick_stairs 2  
fill ~17 ~15 ~32 ~17 ~16 ~32 double_stone_slab 6 
setblock ~17 ~15 ~33 nether_brick_stairs 2  
fill ~17 ~15 ~34 ~17 ~16 ~34 stonebrick 0  
fill ~17 ~15 ~35 ~17 ~15 ~36 nether_brick_stairs 7  
fill ~17 ~15 ~38 ~17 ~15 ~39 nether_brick_stairs 6  
fill ~17 ~15 ~40 ~17 ~16 ~40 stonebrick 0 
setblock ~17 ~15 ~41 nether_brick_stairs 3  
fill ~17 ~15 ~42 ~17 ~16 ~42 double_stone_slab 6  
fill ~17 ~15 ~43 ~18 ~15 ~43 brick_stairs 3  
fill ~18 ~15 ~24 ~19 ~15 ~24 stained_hardened_clay 15  
fill ~18 ~15 ~26 ~22 ~15 ~26 planks 5 
setblock ~18 ~15 ~27 log2 12 
setblock ~18 ~15 ~32 brick_stairs 3 
setblock ~18 ~15 ~33 stone_slab 4  
fill ~18 ~15 ~34 ~18 ~16 ~34 brick_block 0  
fill ~18 ~15 ~40 ~18 ~16 ~40 brick_block 0 
setblock ~18 ~15 ~41 stone_slab 4 
setblock ~18 ~15 ~42 brick_stairs 2 
setblock ~19 ~15 ~25 stained_hardened_clay 15  
fill ~19 ~15 ~27 ~21 ~15 ~27 planks 5 
setblock ~20 ~15 ~22 stained_hardened_clay 15  
fill ~20 ~15 ~24 ~20 ~17 ~24 planks 5  
fill ~20 ~15 ~25 ~22 ~15 ~25 planks 5 
setblock ~21 ~15 ~21 stained_hardened_clay 15  
fill ~21 ~15 ~22 ~21 ~16 ~22 planks 5  
fill ~11 ~16 ~25 ~13 ~16 ~25 log2 12  
fill ~12 ~16 ~24 ~13 ~16 ~24 log2 12  
fill ~12 ~16 ~27 ~12 ~17 ~27 planks 5  
fill ~12 ~16 ~28 ~12 ~16 ~27 planks 5  
fill ~14 ~16 ~25 ~16 ~16 ~25 planks 5  
fill ~14 ~16 ~27 ~16 ~16 ~27 planks 5  
fill ~14 ~16 ~28 ~14 ~19 ~28 planks 5  
fill ~14 ~16 ~31 ~15 ~16 ~31 brick_stairs 6 
setblock ~14 ~16 ~32 brick_stairs 7  
fill ~14 ~16 ~35 ~14 ~17 ~35 brick_block 0  
fill ~14 ~16 ~39 ~14 ~17 ~39 brick_block 0 
setblock ~14 ~16 ~42 brick_stairs 6  
fill ~14 ~16 ~43 ~15 ~16 ~43 brick_stairs 7 
setblock ~14 ~16 ~47 stained_glass_pane 0 
setblock ~15 ~16 ~32 stone_slab 6 
setblock ~15 ~16 ~33 nether_brick_stairs 6  
fill ~15 ~16 ~35 ~15 ~17 ~35 stonebrick 0 
setblock ~15 ~16 ~36 nether_brick_stairs 3 
setblock ~15 ~16 ~37 stone_slab 14 
setblock ~15 ~16 ~38 nether_brick_stairs 2  
fill ~15 ~16 ~39 ~15 ~17 ~39 stonebrick 0 
setblock ~15 ~16 ~41 nether_brick_stairs 7  
fill ~16 ~16 ~23 ~17 ~16 ~23 stained_hardened_clay 9  
fill ~16 ~16 ~34 ~16 ~16 ~41 obsidian 0 
setblock ~17 ~16 ~22 stained_hardened_clay 9 
setblock ~17 ~16 ~24 stained_hardened_clay 9 
setblock ~17 ~16 ~27 log2 12  
fill ~17 ~16 ~31 ~18 ~16 ~31 brick_stairs 6 
setblock ~17 ~16 ~33 nether_brick_stairs 6  
fill ~17 ~16 ~35 ~17 ~17 ~35 stonebrick 0 
setblock ~17 ~16 ~36 nether_brick_stairs 3 
setblock ~17 ~16 ~37 stone_slab 14 
setblock ~17 ~16 ~38 nether_brick_stairs 2  
fill ~17 ~16 ~39 ~17 ~17 ~39 stonebrick 0 
setblock ~17 ~16 ~41 nether_brick_stairs 7  
fill ~17 ~16 ~43 ~18 ~16 ~43 brick_stairs 7  
fill ~18 ~16 ~22 ~18 ~17 ~22 log2 12  
fill ~18 ~16 ~23 ~18 ~18 ~23 log2 12  
fill ~18 ~16 ~24 ~18 ~19 ~24 log2 12  
fill ~18 ~16 ~26 ~19 ~16 ~26 planks 5  
fill ~18 ~16 ~27 ~20 ~16 ~27 planks 5 
setblock ~18 ~16 ~32 brick_stairs 7  
fill ~18 ~16 ~35 ~18 ~17 ~35 brick_block 0  
fill ~18 ~16 ~39 ~18 ~17 ~39 brick_block 0 
setblock ~18 ~16 ~42 brick_stairs 6 
setblock ~19 ~16 ~24 stained_hardened_clay 15  
fill ~19 ~16 ~25 ~20 ~16 ~25 planks 5 
setblock ~20 ~16 ~22 planks 5  
fill ~20 ~16 ~26 ~21 ~16 ~26 stained_hardened_clay 15 
setblock ~20 ~16 ~28 planks 5  
fill ~21 ~16 ~24 ~21 ~16 ~28 stained_hardened_clay 15  
fill ~22 ~16 ~25 ~22 ~16 ~26 planks 5  
fill ~12 ~17 ~23 ~13 ~17 ~23 log2 12  
fill ~12 ~17 ~24 ~12 ~16 ~24 log2 12  
fill ~12 ~17 ~25 ~13 ~17 ~25 log2 12 
setblock ~12 ~17 ~26 stained_hardened_clay 15 
setblock ~12 ~17 ~28 stained_hardened_clay 15  
fill ~13 ~17 ~24 ~15 ~17 ~24 planks 5  
fill ~13 ~17 ~26 ~16 ~17 ~26 planks 5  
fill ~13 ~17 ~27 ~13 ~19 ~27 stained_hardened_clay 15  
fill ~13 ~17 ~29 ~14 ~17 ~29 planks 5 
setblock ~13 ~17 ~45 red_glazed_terracotta 2  
fill ~13 ~17 ~47 ~13 ~18 ~47 log2 12  
fill ~14 ~17 ~25 ~15 ~17 ~25 stained_hardened_clay 15  
fill ~14 ~17 ~27 ~16 ~17 ~27 planks 5  
fill ~14 ~17 ~31 ~15 ~17 ~31 brick_stairs 3  
fill ~14 ~17 ~32 ~18 ~17 ~32 brick_block 0  
fill ~14 ~17 ~36 ~15 ~17 ~36 brick_block 0  
fill ~14 ~17 ~37 ~14 ~18 ~37 stone_slab 4  
fill ~14 ~17 ~38 ~15 ~17 ~38 brick_block 0  
fill ~14 ~17 ~42 ~18 ~17 ~42 brick_block 0  
fill ~14 ~17 ~43 ~15 ~17 ~43 brick_stairs 2 
setblock ~14 ~17 ~47 red_glazed_terracotta 0 
setblock ~15 ~17 ~33 nether_brick_stairs 7 
setblock ~15 ~17 ~34 nether_brick_stairs 6 
setblock ~15 ~17 ~37 double_stone_slab 6 
setblock ~15 ~17 ~40 nether_brick_stairs 7 
setblock ~15 ~17 ~41 nether_brick_stairs 6 
setblock ~15 ~17 ~48 red_glazed_terracotta 0  
fill ~16 ~17 ~25 ~16 ~25 ~25 planks 5  
fill ~16 ~17 ~33 ~16 ~17 ~34 stained_glass 10  
fill ~16 ~17 ~35 ~16 ~17 ~39 obsidian 0  
fill ~16 ~17 ~40 ~16 ~18 ~40 stained_glass 10  
fill ~16 ~17 ~41 ~16 ~17 ~40 stained_glass 10 
setblock ~17 ~17 ~22 log2 12 
setblock ~17 ~17 ~23 stained_hardened_clay 9  
fill ~17 ~17 ~24 ~17 ~18 ~24 log2 12  
fill ~17 ~17 ~31 ~18 ~17 ~31 brick_stairs 3 
setblock ~17 ~17 ~33 nether_brick_stairs 7 
setblock ~17 ~17 ~34 nether_brick_stairs 6  
fill ~17 ~17 ~36 ~18 ~17 ~36 brick_block 0 
setblock ~17 ~17 ~37 stonebrick 0  
fill ~17 ~17 ~38 ~18 ~17 ~38 brick_block 0 
setblock ~17 ~17 ~40 nether_brick_stairs 7 
setblock ~17 ~17 ~41 nether_brick_stairs 6  
fill ~17 ~17 ~43 ~18 ~17 ~43 brick_stairs 2  
fill ~18 ~17 ~26 ~19 ~17 ~26 planks 5  
fill ~18 ~17 ~27 ~19 ~17 ~27 planks 5  
fill ~18 ~17 ~28 ~19 ~17 ~28 planks 5 
setblock ~18 ~17 ~37 brick_block 0  
fill ~19 ~17 ~24 ~19 ~18 ~24 log2 12  
fill ~19 ~17 ~25 ~21 ~17 ~25 stained_hardened_clay 15  
fill ~20 ~17 ~26 ~21 ~17 ~26 stained_hardened_clay 15  
fill ~20 ~17 ~27 ~21 ~17 ~27 stained_hardened_clay 15  
fill ~20 ~17 ~28 ~21 ~17 ~28 stained_hardened_clay 15 
setblock ~9 ~18 ~50 red_glazed_terracotta 0 
setblock ~10 ~18 ~50 stained_glass_pane 0 
setblock ~11 ~18 ~49 log2 12  
fill ~12 ~18 ~23 ~13 ~18 ~23 log2 12  
fill ~12 ~18 ~25 ~16 ~18 ~25 planks 5  
fill ~12 ~18 ~26 ~12 ~19 ~26 planks 5  
fill ~12 ~18 ~27 ~12 ~19 ~27 stained_hardened_clay 15 
setblock ~12 ~18 ~28 planks 5 
setblock ~12 ~18 ~48 log2 12  
fill ~13 ~18 ~22 ~14 ~18 ~22 log2 12 
setblock ~13 ~18 ~24 log2 12 
setblock ~13 ~18 ~26 stained_hardened_clay 15 
setblock ~13 ~18 ~28 stained_hardened_clay 15  
fill ~13 ~18 ~29 ~15 ~18 ~29 planks 5  
fill ~14 ~18 ~23 ~15 ~18 ~23 planks 5  
fill ~14 ~18 ~24 ~15 ~18 ~24 planks 5  
fill ~14 ~18 ~26 ~14 ~20 ~26 planks 5  
fill ~14 ~18 ~27 ~16 ~18 ~27 planks 5  
fill ~14 ~18 ~32 ~18 ~18 ~32 brick_block 0  
fill ~14 ~18 ~33 ~15 ~18 ~33 stone_slab 12 
setblock ~14 ~18 ~34 quartz_stairs 7 
setblock ~14 ~18 ~36 stone_slab 4 
setblock ~14 ~18 ~38 stone_slab 4 
setblock ~14 ~18 ~40 quartz_stairs 6  
fill ~14 ~18 ~41 ~15 ~18 ~41 stone_slab 12  
fill ~14 ~18 ~42 ~18 ~18 ~42 brick_block 0 
setblock ~15 ~18 ~34 nether_brick_stairs 7 
setblock ~15 ~18 ~35 nether_brick_stairs 3 
setblock ~15 ~18 ~36 nether_brick_stairs 2 
setblock ~15 ~18 ~37 nether_brick 0 
setblock ~15 ~18 ~38 nether_brick_stairs 3 
setblock ~15 ~18 ~39 nether_brick_stairs 2 
setblock ~15 ~18 ~40 nether_brick_stairs 6 
setblock ~16 ~18 ~33 obsidian 0  
fill ~16 ~18 ~34 ~16 ~18 ~36 stained_glass 10  
fill ~16 ~18 ~37 ~16 ~20 ~37 obsidian 0  
fill ~16 ~18 ~38 ~16 ~19 ~38 stained_glass 10  
fill ~16 ~18 ~39 ~16 ~19 ~39 stained_glass 10 
setblock ~16 ~18 ~41 obsidian 0  
fill ~17 ~18 ~33 ~18 ~18 ~33 stone_slab 12 
setblock ~17 ~18 ~34 nether_brick_stairs 7 
setblock ~17 ~18 ~35 nether_brick_stairs 3 
setblock ~17 ~18 ~36 nether_brick_stairs 2 
setblock ~17 ~18 ~37 nether_brick 0 
setblock ~17 ~18 ~38 nether_brick_stairs 3 
setblock ~17 ~18 ~39 nether_brick_stairs 2 
setblock ~17 ~18 ~40 nether_brick_stairs 6  
fill ~17 ~18 ~41 ~18 ~18 ~41 stone_slab 12  
fill ~18 ~18 ~28 ~21 ~18 ~28 planks 5 
setblock ~18 ~18 ~34 quartz_stairs 7  
fill ~18 ~18 ~36 ~18 ~18 ~38 stone_slab 4 
setblock ~18 ~18 ~40 quartz_stairs 6  
fill ~19 ~18 ~23 ~19 ~20 ~23 log2 12  
fill ~19 ~18 ~25 ~19 ~19 ~25 log2 12  
fill ~19 ~18 ~26 ~21 ~18 ~26 stained_hardened_clay 15  
fill ~19 ~18 ~27 ~19 ~44 ~27 planks 5  
fill ~19 ~18 ~29 ~20 ~18 ~29 planks 5  
fill ~20 ~18 ~24 ~20 ~19 ~24 log2 12  
fill ~20 ~18 ~25 ~20 ~19 ~25 stained_hardened_clay 15  
fill ~20 ~18 ~27 ~21 ~18 ~27 stained_hardened_clay 15 
setblock ~8 ~19 ~51 stained_glass_pane 0 
setblock ~9 ~19 ~52 red_glazed_terracotta 0 
setblock ~10 ~19 ~50 log2 12 
setblock ~11 ~19 ~51 stained_glass_pane 0  
fill ~12 ~19 ~23 ~13 ~19 ~23 log2 12  
fill ~12 ~19 ~24 ~12 ~21 ~24 log2 12  
fill ~12 ~19 ~25 ~16 ~19 ~25 planks 5  
fill ~13 ~19 ~22 ~14 ~19 ~22 log2 12  
fill ~13 ~19 ~24 ~16 ~19 ~24 planks 5 
setblock ~13 ~19 ~26 planks 5 
setblock ~13 ~19 ~28 planks 5  
fill ~13 ~19 ~36 ~14 ~19 ~36 quartz_stairs 6 
setblock ~13 ~19 ~37 stained_glass_pane 2  
fill ~13 ~19 ~38 ~14 ~19 ~38 quartz_stairs 7 
setblock ~13 ~19 ~46 log2 12 
setblock ~13 ~19 ~47 stained_hardened_clay 9  
fill ~14 ~19 ~23 ~15 ~19 ~23 planks 5  
fill ~14 ~19 ~27 ~15 ~19 ~27 planks 5  
fill ~14 ~19 ~33 ~18 ~19 ~33 brick_block 0 
setblock ~14 ~19 ~37 stained_glass 10  
fill ~14 ~19 ~41 ~18 ~19 ~41 brick_block 0 
setblock ~15 ~19 ~34 nether_brick 0 
setblock ~15 ~19 ~36 nether_brick_stairs 6  
fill ~15 ~19 ~38 ~15 ~20 ~38 brick_stairs 7 
setblock ~15 ~19 ~40 nether_brick 0 
setblock ~16 ~19 ~34 obsidian 0  
fill ~16 ~19 ~35 ~16 ~19 ~36 stained_glass 10 
setblock ~16 ~19 ~40 obsidian 0  
fill ~17 ~19 ~28 ~18 ~19 ~28 stained_hardened_clay 15  
fill ~17 ~19 ~29 ~17 ~22 ~29 stained_hardened_clay 15 
setblock ~17 ~19 ~34 nether_brick 0 
setblock ~17 ~19 ~36 nether_brick_stairs 6  
fill ~17 ~19 ~38 ~17 ~20 ~38 brick_stairs 7 
setblock ~17 ~19 ~40 nether_brick 0  
fill ~18 ~19 ~25 ~18 ~52 ~25 planks 5  
fill ~18 ~19 ~26 ~21 ~19 ~26 planks 5  
fill ~18 ~19 ~27 ~18 ~22 ~27 stained_hardened_clay 15  
fill ~18 ~19 ~29 ~20 ~19 ~29 planks 5  
fill ~18 ~19 ~36 ~19 ~19 ~36 quartz_stairs 6 
setblock ~18 ~19 ~37 stained_glass 10  
fill ~18 ~19 ~38 ~19 ~19 ~38 quartz_stairs 7  
fill ~19 ~19 ~24 ~19 ~24 ~24 planks 5  
fill ~19 ~19 ~28 ~20 ~19 ~28 planks 5 
setblock ~19 ~19 ~37 stained_glass_pane 2  
fill ~20 ~19 ~23 ~20 ~21 ~23 log2 12  
fill ~20 ~19 ~27 ~21 ~19 ~27 stained_hardened_clay 15 
setblock ~21 ~19 ~28 stained_hardened_clay 15 
setblock ~9 ~20 ~51 log2 12 
setblock ~10 ~20 ~50 stained_glass_pane 0 
setblock ~10 ~20 ~51 stained_glass 14  
fill ~11 ~20 ~24 ~11 ~20 ~25 log2 12  
fill ~12 ~20 ~23 ~13 ~20 ~23 log2 12  
fill ~12 ~20 ~25 ~12 ~18 ~25 planks 5  
fill ~12 ~20 ~26 ~12 ~22 ~26 log2 12  
fill ~12 ~20 ~27 ~12 ~23 ~27 log2 12  
fill ~13 ~20 ~24 ~16 ~20 ~24 planks 5  
fill ~13 ~20 ~25 ~13 ~20 ~26 stained_hardened_clay 15  
fill ~13 ~20 ~27 ~13 ~21 ~27 planks 5  
fill ~13 ~20 ~36 ~14 ~20 ~36 quartz_stairs 6  
fill ~13 ~20 ~37 ~14 ~20 ~37 stone_slab 7  
fill ~13 ~20 ~38 ~14 ~20 ~38 quartz_stairs 7  
fill ~13 ~20 ~46 ~13 ~22 ~46 stained_hardened_clay 9  
fill ~14 ~20 ~23 ~16 ~20 ~23 planks 5  
fill ~14 ~20 ~25 ~16 ~20 ~25 planks 5  
fill ~14 ~20 ~27 ~14 ~21 ~27 stained_hardened_clay 15  
fill ~14 ~20 ~33 ~15 ~20 ~33 brick_stairs 3  
fill ~14 ~20 ~34 ~18 ~20 ~34 brick_block 0  
fill ~14 ~20 ~35 ~15 ~20 ~35 stone_slab 12  
fill ~14 ~20 ~39 ~15 ~20 ~39 stone_slab 12  
fill ~14 ~20 ~40 ~18 ~20 ~40 brick_block 0  
fill ~14 ~20 ~41 ~15 ~20 ~41 brick_stairs 2 
setblock ~14 ~20 ~45 log2 12  
fill ~15 ~20 ~27 ~15 ~22 ~27 planks 5 
setblock ~15 ~20 ~36 brick_stairs 6 
setblock ~15 ~20 ~37 stone_slab 4 
setblock ~16 ~20 ~26 stained_hardened_clay 15  
fill ~16 ~20 ~35 ~16 ~20 ~39 obsidian 0  
fill ~17 ~20 ~27 ~17 ~29 ~27 stained_hardened_clay 15  
fill ~17 ~20 ~28 ~19 ~20 ~28 stained_hardened_clay 15  
fill ~17 ~20 ~33 ~18 ~20 ~33 brick_stairs 3  
fill ~17 ~20 ~35 ~18 ~20 ~35 stone_slab 12 
setblock ~17 ~20 ~36 brick_stairs 6 
setblock ~17 ~20 ~37 stone_slab 4  
fill ~17 ~20 ~39 ~18 ~20 ~39 stone_slab 12  
fill ~17 ~20 ~41 ~18 ~20 ~41 brick_stairs 2  
fill ~18 ~20 ~26 ~18 ~21 ~26 stained_hardened_clay 15  
fill ~18 ~20 ~29 ~18 ~23 ~29 stained_hardened_clay 15  
fill ~18 ~20 ~36 ~19 ~20 ~36 quartz_stairs 6  
fill ~18 ~20 ~37 ~19 ~20 ~37 stone_slab 7  
fill ~18 ~20 ~38 ~19 ~20 ~38 quartz_stairs 7  
fill ~19 ~20 ~25 ~20 ~20 ~25 planks 5  
fill ~19 ~20 ~26 ~21 ~20 ~26 planks 5  
fill ~19 ~20 ~29 ~20 ~20 ~29 planks 5  
fill ~20 ~20 ~24 ~20 ~25 ~24 planks 5  
fill ~20 ~20 ~27 ~21 ~20 ~27 planks 5  
fill ~20 ~20 ~28 ~20 ~35 ~28 planks 5  
fill ~21 ~20 ~23 ~21 ~21 ~23 log2 12  
fill ~21 ~20 ~24 ~21 ~23 ~24 log2 12  
fill ~11 ~21 ~25 ~12 ~21 ~25 log2 12  
fill ~11 ~21 ~26 ~11 ~22 ~26 log2 12  
fill ~11 ~21 ~27 ~11 ~22 ~27 log2 12  
fill ~12 ~21 ~28 ~13 ~21 ~28 log2 12  
fill ~13 ~21 ~25 ~13 ~21 ~27 planks 5  
fill ~14 ~21 ~22 ~15 ~21 ~22 planks 5  
fill ~14 ~21 ~23 ~16 ~21 ~23 planks 5  
fill ~14 ~21 ~24 ~16 ~21 ~24 planks 5  
fill ~14 ~21 ~25 ~14 ~21 ~27 stained_hardened_clay 15  
fill ~14 ~21 ~34 ~15 ~21 ~34 stone_slab 4  
fill ~14 ~21 ~35 ~18 ~21 ~35 brick_block 0  
fill ~14 ~21 ~36 ~15 ~21 ~36 brick_block 0  
fill ~14 ~21 ~37 ~15 ~21 ~37 brick_block 0  
fill ~14 ~21 ~38 ~15 ~21 ~38 brick_block 0  
fill ~14 ~21 ~39 ~18 ~21 ~39 brick_block 0  
fill ~14 ~21 ~40 ~18 ~21 ~40 stone_slab 4  
fill ~14 ~21 ~45 ~14 ~21 ~46 stained_hardened_clay 9  
fill ~15 ~21 ~25 ~15 ~24 ~25 planks 5  
fill ~16 ~21 ~26 ~16 ~22 ~26 planks 5 
setblock ~17 ~21 ~26 stained_hardened_clay 15  
fill ~17 ~21 ~28 ~19 ~21 ~28 stained_hardened_clay 15  
fill ~17 ~21 ~34 ~18 ~21 ~34 stone_slab 4  
fill ~17 ~21 ~36 ~18 ~21 ~36 brick_block 0  
fill ~17 ~21 ~37 ~18 ~21 ~37 brick_block 0  
fill ~17 ~21 ~38 ~18 ~21 ~38 brick_block 0  
fill ~19 ~21 ~25 ~21 ~21 ~25 planks 5  
fill ~19 ~21 ~26 ~21 ~21 ~26 planks 5  
fill ~19 ~21 ~29 ~20 ~21 ~29 planks 5  
fill ~20 ~21 ~27 ~21 ~21 ~27 planks 5  
fill ~12 ~22 ~23 ~17 ~22 ~23 planks 5  
fill ~12 ~22 ~24 ~16 ~22 ~24 planks 5  
fill ~12 ~22 ~25 ~12 ~25 ~25 planks 5  
fill ~12 ~22 ~28 ~14 ~22 ~28 log2 12  
fill ~12 ~22 ~29 ~14 ~22 ~29 log2 12  
fill ~13 ~22 ~22 ~17 ~22 ~22 planks 5 
setblock ~13 ~22 ~25 stained_hardened_clay 15  
fill ~13 ~22 ~26 ~13 ~26 ~26 planks 5  
fill ~13 ~22 ~27 ~13 ~24 ~27 log2 12  
fill ~13 ~22 ~30 ~14 ~22 ~30 log2 12  
fill ~13 ~22 ~31 ~13 ~24 ~31 log2 12 
setblock ~13 ~22 ~45 stained_hardened_clay 9  
fill ~14 ~22 ~21 ~15 ~22 ~21 planks 5  
fill ~14 ~22 ~25 ~14 ~28 ~25 planks 5 
setblock ~14 ~22 ~26 stained_hardened_clay 15 
setblock ~14 ~22 ~27 planks 5  
fill ~14 ~22 ~32 ~15 ~22 ~32 stained_glass 14 
setblock ~14 ~22 ~36 brick_stairs 3 
setblock ~14 ~22 ~38 brick_stairs 2  
fill ~14 ~22 ~45 ~15 ~22 ~45 log2 12 
setblock ~14 ~22 ~46 stained_hardened_clay 9  
fill ~17 ~22 ~26 ~21 ~22 ~26 planks 5  
fill ~17 ~22 ~28 ~18 ~22 ~28 stained_hardened_clay 15  
fill ~17 ~22 ~32 ~18 ~22 ~32 stained_glass 14 
setblock ~18 ~22 ~36 brick_stairs 3 
setblock ~18 ~22 ~38 brick_stairs 2  
fill ~19 ~22 ~25 ~21 ~22 ~25 planks 5  
fill ~19 ~22 ~28 ~19 ~37 ~28 planks 5  
fill ~19 ~22 ~29 ~20 ~22 ~29 stained_hardened_clay 15  
fill ~19 ~22 ~30 ~19 ~22 ~29 stained_hardened_clay 15  
fill ~20 ~22 ~27 ~21 ~22 ~27 planks 5  
fill ~20 ~22 ~30 ~20 ~23 ~30 planks 5  
fill ~21 ~22 ~28 ~21 ~34 ~28 planks 5  
fill ~22 ~22 ~24 ~22 ~24 ~24 log2 12  
fill ~22 ~22 ~25 ~22 ~23 ~25 log2 12 
setblock ~11 ~23 ~32 stained_hardened_clay 9  
fill ~12 ~23 ~22 ~17 ~23 ~22 planks 5  
fill ~12 ~23 ~23 ~17 ~23 ~23 planks 5  
fill ~12 ~23 ~24 ~17 ~23 ~24 planks 5  
fill ~12 ~23 ~28 ~15 ~23 ~28 log2 12 
setblock ~12 ~23 ~29 stained_hardened_clay 9  
fill ~12 ~23 ~30 ~14 ~23 ~30 log2 12  
fill ~12 ~23 ~31 ~12 ~23 ~32 log2 12  
fill ~12 ~23 ~33 ~12 ~25 ~33 stained_hardened_clay 9  
fill ~13 ~23 ~21 ~16 ~23 ~21 planks 5  
fill ~13 ~23 ~25 ~13 ~27 ~25 planks 5  
fill ~13 ~23 ~29 ~14 ~23 ~29 log2 12  
fill ~13 ~23 ~32 ~16 ~23 ~32 log2 12  
fill ~13 ~23 ~33 ~15 ~23 ~33 log2 12 
setblock ~13 ~23 ~46 red_glazed_terracotta 0  
fill ~14 ~23 ~26 ~14 ~24 ~26 planks 5  
fill ~14 ~23 ~27 ~15 ~23 ~27 log2 12  
fill ~14 ~23 ~31 ~14 ~24 ~31 log2 12  
fill ~14 ~23 ~44 ~15 ~23 ~44 log2 12  
fill ~14 ~23 ~45 ~15 ~23 ~45 log2 12  
fill ~15 ~23 ~20 ~15 ~33 ~20 planks 5  
fill ~16 ~23 ~27 ~16 ~25 ~27 stained_hardened_clay 15  
fill ~16 ~23 ~28 ~18 ~23 ~28 stained_hardened_clay 15  
fill ~17 ~23 ~25 ~17 ~52 ~25 planks 5  
fill ~17 ~23 ~26 ~22 ~23 ~26 planks 5  
fill ~17 ~23 ~29 ~17 ~23 ~30 planks 5  
fill ~18 ~23 ~24 ~18 ~24 ~24 stained_hardened_clay 15  
fill ~18 ~23 ~27 ~18 ~49 ~27 planks 5  
fill ~18 ~23 ~30 ~20 ~23 ~30 planks 5  
fill ~19 ~23 ~25 ~21 ~23 ~25 planks 5  
fill ~19 ~23 ~29 ~21 ~23 ~29 planks 5  
fill ~20 ~23 ~27 ~22 ~23 ~27 planks 5  
fill ~21 ~23 ~23 ~22 ~23 ~23 log2 12  
fill ~23 ~23 ~24 ~23 ~25 ~24 log2 12  
fill ~23 ~23 ~25 ~23 ~26 ~25 log2 12  
fill ~11 ~24 ~32 ~16 ~24 ~32 log2 12 
setblock ~11 ~24 ~33 stained_hardened_clay 9  
fill ~12 ~24 ~21 ~17 ~24 ~21 planks 5  
fill ~12 ~24 ~22 ~16 ~24 ~22 planks 5  
fill ~12 ~24 ~23 ~13 ~24 ~23 stained_hardened_clay 15  
fill ~12 ~24 ~24 ~12 ~26 ~24 stained_hardened_clay 15  
fill ~12 ~24 ~29 ~13 ~24 ~29 log2 12  
fill ~12 ~24 ~30 ~13 ~24 ~30 log2 12 
setblock ~12 ~24 ~31 stained_hardened_clay 9  
fill ~12 ~24 ~34 ~13 ~24 ~34 stained_hardened_clay 9 
setblock ~12 ~24 ~45 stained_glass_pane 0  
fill ~13 ~24 ~24 ~17 ~24 ~24 planks 5  
fill ~13 ~24 ~28 ~14 ~24 ~28 log2 12 
setblock ~13 ~24 ~33 stained_hardened_clay 9  
fill ~13 ~24 ~35 ~13 ~26 ~35 stained_hardened_clay 9  
fill ~13 ~24 ~44 ~15 ~24 ~44 log2 12  
fill ~13 ~24 ~45 ~14 ~24 ~45 log2 12  
fill ~14 ~24 ~20 ~14 ~30 ~20 planks 5  
fill ~14 ~24 ~23 ~16 ~24 ~23 planks 5  
fill ~14 ~24 ~27 ~15 ~24 ~27 log2 12  
fill ~14 ~24 ~33 ~16 ~24 ~33 log2 12  
fill ~14 ~24 ~34 ~16 ~24 ~34 log2 12  
fill ~14 ~24 ~35 ~14 ~24 ~31 log2 12  
fill ~15 ~24 ~31 ~16 ~24 ~31 log2 12  
fill ~16 ~24 ~20 ~16 ~33 ~20 planks 5  
fill ~16 ~24 ~28 ~17 ~24 ~28 stained_hardened_clay 15  
fill ~16 ~24 ~29 ~17 ~24 ~29 stained_hardened_clay 15  
fill ~17 ~24 ~22 ~18 ~24 ~22 stained_hardened_clay 15  
fill ~17 ~24 ~23 ~18 ~24 ~23 stained_hardened_clay 15  
fill ~17 ~24 ~26 ~22 ~24 ~26 planks 5  
fill ~17 ~24 ~30 ~17 ~26 ~30 stained_hardened_clay 15  
fill ~18 ~24 ~28 ~18 ~36 ~28 planks 5  
fill ~18 ~24 ~29 ~19 ~24 ~29 planks 5  
fill ~18 ~24 ~30 ~19 ~24 ~30 planks 5  
fill ~19 ~24 ~25 ~22 ~24 ~25 planks 5  
fill ~20 ~24 ~27 ~22 ~24 ~27 planks 5  
fill ~20 ~24 ~29 ~20 ~24 ~30 stained_hardened_clay 15  
fill ~21 ~24 ~23 ~22 ~24 ~23 log2 12  
fill ~21 ~24 ~24 ~21 ~25 ~24 planks 5  
fill ~21 ~24 ~29 ~21 ~33 ~29 planks 5  
fill ~22 ~24 ~28 ~22 ~28 ~28 planks 5  
fill ~23 ~24 ~26 ~23 ~26 ~26 log2 12 
setblock ~7 ~25 ~29 red_glazed_terracotta 0 
setblock ~8 ~25 ~30 stained_glass 14  
fill ~12 ~25 ~21 ~17 ~25 ~21 planks 5  
fill ~12 ~25 ~22 ~13 ~25 ~22 stained_hardened_clay 15  
fill ~12 ~25 ~23 ~12 ~24 ~23 stained_hardened_clay 15  
fill ~12 ~25 ~32 ~16 ~25 ~32 log2 12 
setblock ~12 ~25 ~34 concrete 7  
fill ~12 ~25 ~41 ~12 ~28 ~41 log2 12  
fill ~12 ~25 ~43 ~16 ~25 ~43 log2 12  
fill ~12 ~25 ~44 ~15 ~25 ~44 log2 12  
fill ~13 ~25 ~20 ~13 ~31 ~20 planks 5  
fill ~13 ~25 ~23 ~16 ~25 ~23 planks 5 
setblock ~13 ~25 ~24 stained_hardened_clay 15  
fill ~13 ~25 ~33 ~16 ~25 ~33 log2 12 
setblock ~13 ~25 ~34 stained_hardened_clay 9 
setblock ~13 ~25 ~36 concrete 7  
fill ~13 ~25 ~42 ~13 ~28 ~42 log2 12  
fill ~13 ~25 ~45 ~14 ~25 ~45 log2 12  
fill ~14 ~25 ~22 ~17 ~25 ~22 planks 5  
fill ~14 ~25 ~24 ~16 ~25 ~24 planks 5  
fill ~14 ~25 ~26 ~14 ~25 ~28 log2 12  
fill ~14 ~25 ~34 ~16 ~25 ~34 log2 12  
fill ~14 ~25 ~35 ~14 ~25 ~36 stained_hardened_clay 9  
fill ~15 ~25 ~19 ~15 ~31 ~19 planks 5  
fill ~15 ~25 ~25 ~15 ~29 ~25 stained_hardened_clay 15  
fill ~15 ~25 ~26 ~16 ~25 ~26 stained_hardened_clay 15 
setblock ~15 ~25 ~27 log2 12  
fill ~15 ~25 ~35 ~16 ~25 ~35 log2 12  
fill ~15 ~25 ~36 ~16 ~25 ~36 log2 12  
fill ~16 ~25 ~28 ~17 ~25 ~28 stained_hardened_clay 15  
fill ~16 ~25 ~29 ~17 ~25 ~29 stained_hardened_clay 15  
fill ~16 ~25 ~30 ~16 ~28 ~30 planks 5  
fill ~17 ~25 ~23 ~18 ~25 ~23 stained_hardened_clay 15  
fill ~17 ~25 ~24 ~17 ~25 ~23 stained_hardened_clay 15  
fill ~17 ~25 ~26 ~22 ~25 ~26 planks 5  
fill ~18 ~25 ~22 ~18 ~27 ~22 stained_hardened_clay 15 
setblock ~18 ~25 ~24 planks 5  
fill ~18 ~25 ~29 ~21 ~25 ~29 planks 5  
fill ~18 ~25 ~30 ~18 ~33 ~30 planks 5 
setblock ~19 ~25 ~24 stained_hardened_clay 15  
fill ~19 ~25 ~25 ~22 ~25 ~25 planks 5 
setblock ~19 ~25 ~30 stained_hardened_clay 15  
fill ~20 ~25 ~27 ~22 ~25 ~27 planks 5  
fill ~20 ~25 ~30 ~20 ~33 ~30 planks 5  
fill ~22 ~25 ~24 ~22 ~28 ~24 planks 5  
fill ~23 ~25 ~27 ~24 ~25 ~27 log2 12  
fill ~23 ~25 ~28 ~23 ~27 ~28 log2 12 
setblock ~24 ~25 ~26 log2 12 
setblock ~8 ~26 ~29 red_glazed_terracotta 0  
fill ~8 ~26 ~30 ~8 ~27 ~30 stained_glass_pane 0 
setblock ~8 ~26 ~33 stained_glass_pane 0  
fill ~10 ~26 ~31 ~10 ~27 ~31 stained_glass 14  
fill ~10 ~26 ~37 ~10 ~29 ~37 log2 12  
fill ~10 ~26 ~38 ~11 ~26 ~38 log2 12  
fill ~10 ~26 ~39 ~11 ~26 ~39 log2 12 
setblock ~10 ~26 ~41 stained_glass_pane 0 
setblock ~10 ~26 ~43 stained_glass_pane 0  
fill ~11 ~26 ~36 ~11 ~30 ~36 log2 12  
fill ~11 ~26 ~40 ~12 ~26 ~40 log2 12  
fill ~11 ~26 ~41 ~11 ~28 ~41 log2 12  
fill ~12 ~26 ~20 ~12 ~29 ~20 planks 5  
fill ~12 ~26 ~21 ~17 ~26 ~21 planks 5  
fill ~12 ~26 ~22 ~12 ~25 ~22 stained_hardened_clay 15  
fill ~12 ~26 ~23 ~16 ~26 ~23 planks 5  
fill ~12 ~26 ~28 ~15 ~26 ~28 log2 12  
fill ~12 ~26 ~42 ~12 ~27 ~42 log2 12  
fill ~12 ~26 ~43 ~18 ~26 ~43 log2 12  
fill ~13 ~26 ~22 ~17 ~26 ~22 planks 5  
fill ~13 ~26 ~24 ~17 ~26 ~24 planks 5  
fill ~13 ~26 ~34 ~15 ~26 ~34 log2 12  
fill ~13 ~26 ~36 ~14 ~26 ~36 stained_hardened_clay 9  
fill ~13 ~26 ~44 ~16 ~26 ~44 log2 12  
fill ~14 ~26 ~19 ~14 ~30 ~19 planks 5  
fill ~14 ~26 ~26 ~14 ~27 ~26 stained_hardened_clay 15 
setblock ~14 ~26 ~27 log2 12  
fill ~14 ~26 ~35 ~16 ~26 ~35 log2 12  
fill ~14 ~26 ~37 ~14 ~27 ~37 concrete 7 
setblock ~14 ~26 ~38 stained_hardened_clay 9  
fill ~14 ~26 ~42 ~19 ~26 ~42 log2 12  
fill ~15 ~26 ~26 ~15 ~28 ~26 nether_brick 0 
setblock ~15 ~26 ~33 log2 12  
fill ~15 ~26 ~36 ~16 ~26 ~36 log2 12  
fill ~15 ~26 ~37 ~15 ~28 ~37 stained_hardened_clay 9  
fill ~16 ~26 ~19 ~16 ~32 ~19 planks 5  
fill ~16 ~26 ~25 ~16 ~26 ~26 stained_hardened_clay 15 
setblock ~16 ~26 ~27 planks 5  
fill ~16 ~26 ~28 ~17 ~26 ~28 stained_hardened_clay 15  
fill ~16 ~26 ~29 ~16 ~27 ~29 planks 5 
setblock ~16 ~26 ~37 log2 12  
fill ~17 ~26 ~20 ~17 ~33 ~20 planks 5  
fill ~17 ~26 ~23 ~20 ~26 ~23 stained_hardened_clay 15  
fill ~17 ~26 ~26 ~22 ~26 ~26 planks 5 
setblock ~17 ~26 ~29 stained_hardened_clay 15 
setblock ~18 ~26 ~21 stained_hardened_clay 15 
setblock ~18 ~26 ~24 stained_hardened_clay 15  
fill ~18 ~26 ~29 ~22 ~26 ~29 planks 5  
fill ~18 ~26 ~31 ~19 ~26 ~31 planks 5  
fill ~18 ~26 ~41 ~19 ~26 ~41 log2 12  
fill ~19 ~26 ~24 ~19 ~34 ~24 planks 5  
fill ~19 ~26 ~25 ~22 ~26 ~25 planks 5  
fill ~19 ~26 ~30 ~19 ~33 ~30 planks 5  
fill ~19 ~26 ~39 ~19 ~28 ~39 stained_hardened_clay 9  
fill ~19 ~26 ~40 ~19 ~32 ~40 log2 12  
fill ~20 ~26 ~24 ~21 ~26 ~24 stained_hardened_clay 15  
fill ~20 ~26 ~27 ~22 ~26 ~27 planks 5  
fill ~23 ~26 ~27 ~24 ~26 ~27 log2 12  
fill ~23 ~26 ~29 ~23 ~27 ~29 log2 12 
setblock ~24 ~26 ~28 log2 12 
setblock ~5 ~27 ~28 stained_glass_pane 0 
setblock ~6 ~27 ~27 stained_glass_pane 0 
setblock ~6 ~27 ~29 red_glazed_terracotta 0  
fill ~6 ~27 ~32 ~7 ~27 ~32 stained_glass_pane 0 
setblock ~8 ~27 ~29 stained_glass 14 
setblock ~8 ~27 ~31 stained_glass 14  
fill ~8 ~27 ~32 ~9 ~27 ~32 red_glazed_terracotta 0 
setblock ~9 ~27 ~26 stained_glass_pane 0 
setblock ~9 ~27 ~30 red_glazed_terracotta 0  
fill ~9 ~27 ~37 ~9 ~28 ~37 log2 12  
fill ~9 ~27 ~38 ~11 ~27 ~38 log2 12 
setblock ~9 ~27 ~42 red_glazed_terracotta 0 
setblock ~10 ~27 ~33 stained_glass 14  
fill ~10 ~27 ~36 ~10 ~29 ~36 log2 12  
fill ~10 ~27 ~39 ~12 ~27 ~39 log2 12  
fill ~10 ~27 ~40 ~12 ~27 ~40 log2 12  
fill ~10 ~27 ~41 ~10 ~27 ~36 log2 12 
setblock ~10 ~27 ~52 stained_glass_pane 0  
fill ~11 ~27 ~29 ~11 ~28 ~29 log2 12  
fill ~11 ~27 ~35 ~11 ~30 ~35 log2 12  
fill ~11 ~27 ~37 ~11 ~29 ~37 log2 12 
setblock ~11 ~27 ~42 log2 12  
fill ~12 ~27 ~21 ~18 ~27 ~21 planks 5  
fill ~12 ~27 ~22 ~17 ~27 ~22 planks 5  
fill ~12 ~27 ~23 ~17 ~27 ~23 planks 5  
fill ~12 ~27 ~24 ~19 ~27 ~24 planks 5  
fill ~12 ~27 ~43 ~19 ~27 ~43 log2 12  
fill ~13 ~27 ~19 ~13 ~29 ~19 planks 5  
fill ~13 ~27 ~41 ~13 ~28 ~41 log2 12  
fill ~13 ~27 ~44 ~17 ~27 ~44 log2 12  
fill ~14 ~27 ~35 ~14 ~26 ~35 log2 12  
fill ~14 ~27 ~36 ~14 ~27 ~35 log2 12 
setblock ~14 ~27 ~38 log2 12  
fill ~14 ~27 ~39 ~14 ~30 ~39 stained_hardened_clay 9  
fill ~14 ~27 ~42 ~19 ~27 ~42 log2 12 
setblock ~14 ~27 ~51 stained_glass 14  
fill ~14 ~27 ~52 ~14 ~28 ~52 stained_glass_pane 0 
setblock ~14 ~27 ~54 red_glazed_terracotta 0  
fill ~15 ~27 ~18 ~16 ~27 ~18 planks 5 
setblock ~15 ~27 ~36 stained_hardened_clay 9  
fill ~15 ~27 ~38 ~15 ~28 ~38 stained_hardened_clay 9  
fill ~15 ~27 ~39 ~15 ~28 ~39 log2 12 
setblock ~15 ~27 ~40 stained_hardened_clay 9  
fill ~15 ~27 ~45 ~15 ~28 ~45 log2 12 
setblock ~16 ~27 ~25 planks 5  
fill ~16 ~27 ~26 ~17 ~27 ~26 stained_hardened_clay 15 
setblock ~16 ~27 ~27 nether_brick 0  
fill ~16 ~27 ~28 ~16 ~23 ~28 stained_hardened_clay 15 
setblock ~16 ~27 ~36 log2 12 
setblock ~16 ~27 ~37 stained_hardened_clay 9 
setblock ~16 ~27 ~47 stained_glass_pane 0  
fill ~17 ~27 ~19 ~18 ~27 ~19 planks 5  
fill ~17 ~27 ~28 ~17 ~27 ~30 planks 5  
fill ~18 ~27 ~20 ~18 ~29 ~20 planks 5 
setblock ~18 ~27 ~23 stained_hardened_clay 15  
fill ~18 ~27 ~26 ~22 ~27 ~26 planks 5  
fill ~18 ~27 ~29 ~22 ~27 ~29 planks 5  
fill ~18 ~27 ~31 ~19 ~27 ~31 planks 5  
fill ~18 ~27 ~40 ~18 ~28 ~40 log2 12  
fill ~18 ~27 ~41 ~20 ~27 ~41 log2 12  
fill ~19 ~27 ~25 ~22 ~27 ~25 planks 5  
fill ~19 ~27 ~38 ~19 ~28 ~38 stained_hardened_clay 9  
fill ~20 ~27 ~23 ~20 ~29 ~23 stained_hardened_clay 15  
fill ~20 ~27 ~24 ~20 ~26 ~24 stained_hardened_clay 15  
fill ~20 ~27 ~27 ~22 ~27 ~27 planks 5  
fill ~20 ~27 ~31 ~22 ~27 ~31 log2 12  
fill ~20 ~27 ~40 ~20 ~28 ~40 log2 12  
fill ~21 ~27 ~23 ~22 ~27 ~23 planks 5  
fill ~21 ~27 ~24 ~21 ~31 ~24 planks 5   
fill ~21 ~27 ~30 ~21 ~31 ~30 planks 5  
fill ~22 ~27 ~30 ~23 ~27 ~30 log2 12  
fill ~23 ~27 ~27 ~23 ~25 ~27 log2 12 
setblock ~3 ~28 ~16 red_glazed_terracotta 0 
setblock ~5 ~28 ~30 red_glazed_terracotta 0 
setblock ~5 ~28 ~33 red_glazed_terracotta 0 
setblock ~6 ~28 ~30 stained_glass 14  
fill ~7 ~28 ~30 ~7 ~29 ~30 red_glazed_terracotta 0  
fill ~8 ~28 ~27 ~8 ~29 ~27 red_glazed_terracotta 0 
setblock ~8 ~28 ~33 red_glazed_terracotta 0 
setblock ~9 ~28 ~27 stained_glass_pane 0 
setblock ~9 ~28 ~30 stained_glass 14 
setblock ~9 ~28 ~32 red_glazed_terracotta 0 
setblock ~9 ~28 ~33 stained_glass_pane 0 
setblock ~9 ~28 ~36 log2 12 
setblock ~9 ~28 ~39 stained_glass 14 
setblock ~9 ~28 ~42 stained_glass 14 
setblock ~9 ~28 ~50 stained_glass 14 
setblock ~10 ~28 ~30 log2 12  
fill ~10 ~28 ~31 ~10 ~29 ~31 red_glazed_terracotta 0  
fill ~10 ~28 ~35 ~10 ~29 ~35 log2 12  
fill ~10 ~28 ~52 ~10 ~29 ~52 stained_glass 14 
setblock ~11 ~28 ~28 stained_glass_pane 0  
fill ~11 ~28 ~38 ~11 ~28 ~41 log2 12 
setblock ~11 ~28 ~43 stained_glass 14 
setblock ~11 ~28 ~49 red_glazed_terracotta 0 
setblock ~11 ~28 ~51 stained_glass_pane 0  
fill ~12 ~28 ~21 ~18 ~28 ~21 planks 5  
fill ~12 ~28 ~22 ~18 ~28 ~22 planks 5  
fill ~12 ~28 ~23 ~18 ~28 ~23 planks 5  
fill ~12 ~28 ~35 ~12 ~31 ~35 log2 12  
fill ~12 ~28 ~36 ~12 ~30 ~36 log2 12  
fill ~12 ~28 ~39 ~12 ~28 ~41 log2 12 
setblock ~12 ~28 ~52 stained_glass_pane 0  
fill ~13 ~28 ~24 ~22 ~28 ~24 planks 5  
fill ~13 ~28 ~43 ~17 ~28 ~43 log2 12 
setblock ~13 ~28 ~49 stained_glass_pane 0  
fill ~13 ~28 ~53 ~13 ~28 ~54 stained_glass 14  
fill ~14 ~28 ~37 ~14 ~28 ~39 stained_hardened_clay 9  
fill ~14 ~28 ~41 ~14 ~28 ~43 log2 12 
setblock ~14 ~28 ~51 stained_glass_pane 0  
fill ~15 ~28 ~18 ~17 ~28 ~18 planks 5 
setblock ~15 ~28 ~40 log2 12  
fill ~15 ~28 ~42 ~19 ~28 ~42 log2 12  
fill ~15 ~28 ~44 ~15 ~29 ~44 log2 12  
fill ~15 ~28 ~46 ~15 ~28 ~48 log2 12  
fill ~15 ~28 ~49 ~15 ~29 ~49 stained_glass 14  
fill ~15 ~28 ~51 ~15 ~30 ~51 stained_glass 14 
setblock ~15 ~28 ~55 stained_glass_pane 0  
fill ~16 ~28 ~25 ~16 ~28 ~27 stained_hardened_clay 15  
fill ~16 ~28 ~28 ~16 ~29 ~28 nether_brick 0  
fill ~16 ~28 ~29 ~16 ~28 ~28 nether_brick 0 
setblock ~16 ~28 ~51 red_glazed_terracotta 0  
fill ~17 ~28 ~19 ~19 ~28 ~19 planks 5 
setblock ~17 ~28 ~26 stained_hardened_clay 15 
setblock ~17 ~28 ~28 stained_hardened_clay 15  
fill ~17 ~28 ~29 ~22 ~28 ~29 planks 5  
fill ~17 ~28 ~30 ~17 ~28 ~29 planks 5  
fill ~17 ~28 ~33 ~20 ~28 ~33 log2 12  
fill ~18 ~28 ~26 ~22 ~28 ~26 planks 5  
fill ~18 ~28 ~31 ~20 ~28 ~31 planks 5  
fill ~18 ~28 ~32 ~21 ~28 ~32 log2 12  
fill ~18 ~28 ~39 ~18 ~32 ~39 log2 12  
fill ~18 ~28 ~41 ~19 ~28 ~41 log2 12 
setblock ~19 ~28 ~20 stained_hardened_clay 15  
fill ~19 ~28 ~23 ~19 ~29 ~23 stained_hardened_clay 15  
fill ~19 ~28 ~25 ~21 ~28 ~25 planks 5  
fill ~20 ~28 ~22 ~20 ~30 ~22 nether_brick 0  
fill ~20 ~28 ~27 ~23 ~28 ~27 planks 5  
fill ~20 ~28 ~39 ~20 ~33 ~39 log2 12  
fill ~21 ~28 ~23 ~22 ~28 ~23 planks 5  
fill ~21 ~28 ~31 ~22 ~28 ~31 log2 12 
setblock ~22 ~28 ~25 stained_hardened_clay 15  
fill ~22 ~28 ~30 ~23 ~28 ~30 log2 12  
fill ~23 ~28 ~26 ~23 ~29 ~26 stained_hardened_clay 15 
setblock ~1 ~29 ~13 red_glazed_terracotta 0  
fill ~3 ~29 ~14 ~5 ~29 ~14 stained_glass 14 
setblock ~3 ~29 ~15 red_glazed_terracotta 0 
setblock ~3 ~29 ~16 stained_glass_pane 0  
fill ~3 ~29 ~17 ~4 ~29 ~17 stained_glass 14 
setblock ~5 ~29 ~17 stained_glass_pane 0 
setblock ~5 ~29 ~31 red_glazed_terracotta 0 
setblock ~5 ~29 ~32 stained_glass 14 
setblock ~6 ~29 ~17 stained_glass 14 
setblock ~6 ~29 ~30 stained_glass_pane 0 
setblock ~6 ~29 ~34 red_glazed_terracotta 0  
fill ~7 ~29 ~29 ~8 ~29 ~29 red_glazed_terracotta 0  
fill ~7 ~29 ~31 ~7 ~31 ~31 stained_glass 14  
fill ~8 ~29 ~30 ~8 ~29 ~31 stained_glass_pane 0 
setblock ~8 ~29 ~32 red_glazed_terracotta 0  
fill ~9 ~29 ~31 ~9 ~29 ~32 log2 12 
setblock ~9 ~29 ~49 stained_glass_pane 0 
setblock ~10 ~29 ~30 stained_glass 14 
setblock ~10 ~29 ~53 red_glazed_terracotta 0 
setblock ~10 ~29 ~54 stained_glass 14 
setblock ~11 ~29 ~32 red_glazed_terracotta 0  
fill ~11 ~29 ~34 ~18 ~29 ~34 log2 12 
setblock ~11 ~29 ~50 stained_glass_pane 0  
fill ~11 ~29 ~53 ~11 ~30 ~53 stained_glass_pane 0 
setblock ~11 ~29 ~55 stained_glass 14  
fill ~12 ~29 ~21 ~17 ~29 ~21 planks 5 
setblock ~12 ~29 ~49 stained_glass 14  
fill ~12 ~29 ~54 ~12 ~30 ~54 stained_glass_pane 0  
fill ~13 ~29 ~22 ~18 ~29 ~22 planks 5  
fill ~13 ~29 ~23 ~18 ~29 ~23 planks 5  
fill ~13 ~29 ~24 ~17 ~29 ~24 planks 5  
fill ~13 ~29 ~35 ~15 ~29 ~35 log2 12 
setblock ~13 ~29 ~48 red_glazed_terracotta 0  
fill ~13 ~29 ~51 ~14 ~29 ~51 red_glazed_terracotta 0 
setblock ~13 ~29 ~55 stained_glass_pane 0 
setblock ~14 ~29 ~38 concrete 7  
fill ~14 ~29 ~40 ~16 ~29 ~40 stained_hardened_clay 9 
setblock ~14 ~29 ~48 stained_glass 14  
fill ~14 ~29 ~49 ~14 ~29 ~50 log2 12 
setblock ~14 ~29 ~52 stained_glass 14  
fill ~15 ~29 ~18 ~17 ~29 ~18 planks 5  
fill ~15 ~29 ~26 ~16 ~29 ~26 stained_hardened_clay 15  
fill ~15 ~29 ~27 ~15 ~33 ~27 planks 5  
fill ~15 ~29 ~33 ~20 ~29 ~33 log2 12  
fill ~15 ~29 ~39 ~16 ~29 ~39 stained_hardened_clay 9 
setblock ~15 ~29 ~43 log2 12 
setblock ~15 ~29 ~46 stained_glass_pane 0  
fill ~15 ~29 ~47 ~15 ~29 ~48 log2 12 
setblock ~15 ~29 ~53 stained_glass_pane 0  
fill ~16 ~29 ~25 ~16 ~39 ~25 planks 5 
setblock ~16 ~29 ~27 stained_hardened_clay 15  
fill ~16 ~29 ~29 ~22 ~29 ~29 planks 5 
setblock ~16 ~29 ~51 stained_glass_pane 0  
fill ~17 ~29 ~19 ~19 ~29 ~19 planks 5  
fill ~17 ~29 ~26 ~22 ~29 ~26 planks 5  
fill ~17 ~29 ~28 ~17 ~38 ~28 planks 5 
setblock ~17 ~29 ~30 stained_hardened_clay 15  
fill ~17 ~29 ~32 ~21 ~29 ~32 log2 12 
setblock ~18 ~29 ~21 stained_hardened_clay 15  
fill ~18 ~29 ~31 ~20 ~29 ~31 planks 5  
fill ~19 ~29 ~20 ~19 ~30 ~20 planks 5  
fill ~19 ~29 ~22 ~19 ~30 ~22 stained_hardened_clay 15  
fill ~19 ~29 ~25 ~22 ~29 ~25 planks 5  
fill ~19 ~29 ~38 ~19 ~33 ~38 log2 12  
fill ~19 ~29 ~39 ~19 ~33 ~39 log2 12  
fill ~20 ~29 ~24 ~20 ~35 ~24 planks 5  
fill ~20 ~29 ~27 ~22 ~29 ~27 planks 5  
fill ~21 ~29 ~22 ~21 ~31 ~22 planks 5  
fill ~21 ~29 ~23 ~22 ~29 ~23 planks 5  
fill ~21 ~29 ~31 ~21 ~27 ~31 log2 12 
setblock ~22 ~29 ~24 stained_hardened_clay 15 
setblock ~22 ~29 ~28 stained_hardened_clay 15 
setblock ~23 ~29 ~25 stained_hardened_clay 15  
fill ~23 ~29 ~27 ~23 ~31 ~27 stained_hardened_clay 15  
fill ~0 ~30 ~15 ~0 ~31 ~15 stained_glass 14 
setblock ~2 ~30 ~12 red_glazed_terracotta 0 
setblock ~2 ~30 ~17 red_glazed_terracotta 0 
setblock ~3 ~30 ~12 stained_glass 14  
fill ~3 ~30 ~14 ~4 ~30 ~14 red_glazed_terracotta 0  
fill ~3 ~30 ~15 ~3 ~31 ~15 stained_glass_pane 0 
setblock ~4 ~30 ~13 stained_glass_pane 0  
fill ~5 ~30 ~14 ~6 ~30 ~14 stained_glass 14 
setblock ~5 ~30 ~15 log2 12  
fill ~5 ~30 ~16 ~6 ~30 ~16 red_glazed_terracotta 0 
setblock ~5 ~30 ~32 stained_glass_pane 0 
setblock ~6 ~30 ~15 stained_glass_pane 0 
setblock ~6 ~30 ~31 stained_glass 14 
setblock ~7 ~30 ~16 stained_glass_pane 0 
setblock ~7 ~30 ~17 stained_glass 14 
setblock ~7 ~30 ~29 stained_glass 14  
fill ~8 ~30 ~31 ~9 ~30 ~31 stained_glass 14  
fill ~8 ~30 ~32 ~8 ~30 ~31 stained_glass 14  
fill ~8 ~30 ~34 ~8 ~30 ~35 stained_glass_pane 0 
setblock ~9 ~30 ~30 red_glazed_terracotta 0  
fill ~9 ~30 ~32 ~10 ~30 ~32 stained_glass_pane 0 
setblock ~9 ~30 ~34 stained_glass 14 
setblock ~9 ~30 ~51 stained_glass_pane 0 
setblock ~10 ~30 ~29 stained_glass 14 
setblock ~10 ~30 ~33 stained_glass 14  
fill ~10 ~30 ~51 ~11 ~30 ~51 stained_glass 14 
setblock ~10 ~30 ~52 red_glazed_terracotta 0  
fill ~10 ~30 ~54 ~12 ~30 ~54 stained_glass_pane 0  
fill ~11 ~30 ~34 ~18 ~30 ~34 log2 12 
setblock ~11 ~30 ~49 red_glazed_terracotta 0  
fill ~11 ~30 ~52 ~11 ~31 ~52 stained_glass_pane 0  
fill ~12 ~30 ~48 ~13 ~30 ~48 stained_glass 14  
fill ~12 ~30 ~52 ~13 ~30 ~52 stained_glass 14  
fill ~12 ~30 ~53 ~13 ~30 ~53 stained_glass_pane 0 
setblock ~12 ~30 ~55 red_glazed_terracotta 0  
fill ~13 ~30 ~21 ~18 ~30 ~21 planks 5  
fill ~13 ~30 ~22 ~17 ~30 ~22 planks 5  
fill ~13 ~30 ~23 ~22 ~30 ~23 planks 5  
fill ~13 ~30 ~26 ~23 ~30 ~26 planks 5  
fill ~13 ~30 ~27 ~22 ~30 ~27 planks 5  
fill ~13 ~30 ~35 ~16 ~30 ~35 log2 12  
fill ~13 ~30 ~36 ~14 ~30 ~36 log2 12  
fill ~13 ~30 ~40 ~13 ~30 ~41 concrete 7 
setblock ~13 ~30 ~50 stained_glass 14  
fill ~14 ~30 ~33 ~18 ~30 ~33 log2 12  
fill ~14 ~30 ~40 ~15 ~30 ~40 stained_hardened_clay 9  
fill ~14 ~30 ~41 ~15 ~30 ~41 stained_hardened_clay 9 
setblock ~14 ~30 ~50 stained_glass_pane 0 
setblock ~14 ~30 ~51 log2 12 
setblock ~14 ~30 ~52 stained_glass_pane 0 
setblock ~15 ~30 ~24 stained_hardened_clay 15 
setblock ~15 ~30 ~25 nether_brick 0  
fill ~15 ~30 ~28 ~15 ~34 ~28 planks 5  
fill ~15 ~30 ~39 ~16 ~30 ~39 stained_hardened_clay 9 
setblock ~15 ~30 ~48 log2 12 
setblock ~15 ~30 ~50 red_glazed_terracotta 0  
fill ~16 ~30 ~18 ~17 ~30 ~18 planks 5  
fill ~16 ~30 ~24 ~22 ~30 ~24 planks 5 
setblock ~16 ~30 ~28 stained_hardened_clay 15  
fill ~16 ~30 ~32 ~19 ~30 ~32 log2 12 
setblock ~16 ~30 ~40 concrete 7 
setblock ~16 ~30 ~49 stained_glass 14  
fill ~17 ~30 ~19 ~19 ~30 ~19 planks 5 
setblock ~17 ~30 ~29 stained_hardened_clay 15  
fill ~17 ~30 ~30 ~17 ~32 ~30 planks 5  
fill ~17 ~30 ~54 ~17 ~30 ~55 red_glazed_terracotta 0 
setblock ~18 ~30 ~20 stained_hardened_clay 15 
setblock ~18 ~30 ~22 stained_hardened_clay 15  
fill ~18 ~30 ~29 ~22 ~30 ~29 planks 5 
setblock ~18 ~30 ~31 log2 12 
setblock ~18 ~30 ~50 red_glazed_terracotta 0  
fill ~19 ~30 ~25 ~21 ~30 ~25 planks 5  
fill ~19 ~30 ~31 ~20 ~30 ~31 planks 5 
setblock ~22 ~30 ~25 stained_hardened_clay 15  
fill ~22 ~30 ~28 ~23 ~30 ~28 planks 5  
fill ~23 ~30 ~24 ~23 ~31 ~24 stained_hardened_clay 15  
fill ~23 ~30 ~25 ~23 ~33 ~25 planks 5  
fill ~23 ~30 ~33 ~24 ~30 ~33 stained_glass 14 
setblock ~1 ~31 ~15 stained_glass_pane 0 
setblock ~2 ~31 ~15 stained_glass 14 
setblock ~3 ~31 ~14 stained_glass_pane 0 
setblock ~4 ~31 ~16 red_glazed_terracotta 0 
setblock ~5 ~31 ~13 stained_glass 14 
setblock ~5 ~31 ~14 red_glazed_terracotta 0 
setblock ~5 ~31 ~17 stained_glass 14  
fill ~6 ~31 ~15 ~6 ~32 ~15 log2 12 
setblock ~6 ~31 ~17 stained_glass_pane 0 
setblock ~6 ~31 ~30 stained_glass 14 
setblock ~7 ~31 ~34 stained_glass_pane 0 
setblock ~8 ~31 ~17 stained_glass_pane 0 
setblock ~8 ~31 ~28 stained_glass 14 
setblock ~8 ~31 ~29 red_glazed_terracotta 0  
fill ~8 ~31 ~30 ~9 ~31 ~30 stained_glass 14 
setblock ~9 ~31 ~17 stained_glass 14 
setblock ~9 ~31 ~33 stained_glass_pane 0  
fill ~10 ~31 ~54 ~10 ~30 ~54 stained_glass_pane 0  
fill ~11 ~31 ~51 ~13 ~31 ~51 red_glazed_terracotta 0 
setblock ~11 ~31 ~53 red_glazed_terracotta 0 
setblock ~12 ~31 ~48 stained_glass_pane 0 
setblock ~12 ~31 ~50 stained_glass_pane 0  
fill ~12 ~31 ~53 ~12 ~30 ~53 stained_glass_pane 0  
fill ~13 ~31 ~21 ~17 ~31 ~21 planks 5  
fill ~13 ~31 ~22 ~19 ~31 ~22 planks 5  
fill ~13 ~31 ~24 ~21 ~31 ~24 planks 5  
fill ~13 ~31 ~25 ~23 ~31 ~25 planks 5  
fill ~13 ~31 ~26 ~23 ~31 ~26 planks 5  
fill ~13 ~31 ~27 ~22 ~31 ~27 planks 5  
fill ~13 ~31 ~34 ~16 ~31 ~34 log2 12  
fill ~13 ~31 ~35 ~15 ~31 ~35 log2 12 
setblock ~13 ~31 ~41 concrete 7 
setblock ~13 ~31 ~49 stained_glass_pane 0  
fill ~14 ~31 ~19 ~14 ~31 ~20 stained_hardened_clay 15 
setblock ~14 ~31 ~23 stained_hardened_clay 15  
fill ~14 ~31 ~40 ~15 ~31 ~40 stained_hardened_clay 9  
fill ~14 ~31 ~41 ~15 ~31 ~41 stained_hardened_clay 9  
fill ~14 ~31 ~42 ~14 ~37 ~42 stained_hardened_clay 9 
setblock ~14 ~31 ~52 log2 12  
fill ~15 ~31 ~23 ~22 ~31 ~23 planks 5  
fill ~15 ~31 ~33 ~16 ~31 ~33 log2 12  
fill ~15 ~31 ~49 ~15 ~32 ~49 stained_glass_pane 0 
setblock ~15 ~31 ~50 stained_glass 14 
setblock ~15 ~31 ~51 red_glazed_terracotta 0 
setblock ~15 ~31 ~55 red_glazed_terracotta 0 
setblock ~15 ~31 ~57 stained_glass_pane 0  
fill ~16 ~31 ~28 ~16 ~34 ~28 planks 5  
fill ~16 ~31 ~30 ~16 ~33 ~30 stained_hardened_clay 9 
setblock ~16 ~31 ~48 stained_glass 14 
setblock ~16 ~31 ~49 red_glazed_terracotta 0 
setblock ~16 ~31 ~56 red_glazed_terracotta 0  
fill ~17 ~31 ~19 ~19 ~31 ~19 planks 5  
fill ~17 ~31 ~29 ~22 ~31 ~29 planks 5  
fill ~17 ~31 ~31 ~17 ~32 ~31 stained_hardened_clay 9 
setblock ~17 ~31 ~49 stained_glass 14 
setblock ~17 ~31 ~54 stained_glass 14  
fill ~18 ~31 ~20 ~18 ~33 ~20 planks 5  
fill ~18 ~31 ~21 ~20 ~31 ~21 stained_hardened_clay 15  
fill ~19 ~31 ~20 ~19 ~32 ~20 stained_hardened_clay 15  
fill ~20 ~31 ~22 ~20 ~33 ~22 stained_hardened_clay 15 
setblock ~20 ~31 ~34 stained_glass_pane 0 
setblock ~21 ~31 ~34 red_glazed_terracotta 0 
setblock ~22 ~31 ~24 stained_hardened_clay 15  
fill ~22 ~31 ~28 ~23 ~31 ~28 stained_hardened_clay 15 
setblock ~22 ~31 ~33 log2 12  
fill ~23 ~31 ~33 ~23 ~32 ~33 stained_glass 14  
fill ~23 ~31 ~34 ~23 ~31 ~33 stained_glass 14  
fill ~24 ~31 ~33 ~24 ~32 ~33 stained_glass_pane 0 
setblock ~24 ~31 ~35 stained_glass_pane 0 
setblock ~25 ~31 ~34 stained_glass 14 
setblock ~1 ~32 ~15 stained_glass 14 
setblock ~2 ~32 ~18 stained_glass 14 
setblock ~4 ~32 ~15 stained_glass 14  
fill ~4 ~32 ~17 ~5 ~32 ~17 red_glazed_terracotta 0 
setblock ~5 ~32 ~14 stained_glass 14 
setblock ~7 ~32 ~13 red_glazed_terracotta 0 
setblock ~7 ~32 ~18 red_glazed_terracotta 0  
fill ~8 ~32 ~15 ~8 ~33 ~15 stained_glass 14  
fill ~8 ~32 ~16 ~9 ~32 ~16 stained_glass_pane 0 
setblock ~8 ~32 ~17 red_glazed_terracotta 0 
setblock ~8 ~32 ~18 stained_glass_pane 0 
setblock ~8 ~32 ~31 red_glazed_terracotta 0 
setblock ~12 ~32 ~52 stained_glass 14  
fill ~13 ~32 ~24 ~20 ~32 ~24 planks 5  
fill ~13 ~32 ~25 ~23 ~32 ~25 planks 5  
fill ~13 ~32 ~26 ~23 ~32 ~26 planks 5  
fill ~13 ~32 ~27 ~23 ~32 ~27 planks 5 
setblock ~13 ~32 ~41 log2 12 
setblock ~13 ~32 ~42 concrete 7 
setblock ~13 ~32 ~50 stained_glass 14 
setblock ~14 ~32 ~20 stained_hardened_clay 15  
fill ~14 ~32 ~21 ~18 ~32 ~21 planks 5  
fill ~14 ~32 ~22 ~18 ~32 ~22 planks 5  
fill ~14 ~32 ~23 ~19 ~32 ~23 planks 5 
setblock ~14 ~32 ~40 concrete 7  
fill ~14 ~32 ~41 ~15 ~32 ~41 stained_hardened_clay 9  
fill ~14 ~32 ~48 ~15 ~32 ~48 stained_glass 14 
setblock ~14 ~32 ~49 stained_glass_pane 0  
fill ~14 ~32 ~50 ~14 ~33 ~50 red_glazed_terracotta 0 
setblock ~14 ~32 ~51 stained_glass_pane 0  
fill ~15 ~32 ~29 ~16 ~32 ~29 stained_hardened_clay 9  
fill ~15 ~32 ~30 ~15 ~33 ~30 stained_hardened_clay 9  
fill ~15 ~32 ~50 ~17 ~32 ~50 stained_glass_pane 0 
setblock ~15 ~32 ~54 red_glazed_terracotta 0 
setblock ~15 ~32 ~56 stained_glass 14 
setblock ~16 ~32 ~31 stained_hardened_clay 9 
setblock ~16 ~32 ~48 stained_glass_pane 0 
setblock ~16 ~32 ~53 stained_glass 14  
fill ~16 ~32 ~55 ~16 ~33 ~55 stained_glass_pane 0  
fill ~17 ~32 ~19 ~18 ~32 ~19 planks 5  
fill ~17 ~32 ~29 ~22 ~32 ~29 planks 5  
fill ~18 ~32 ~38 ~18 ~33 ~38 log2 12  
fill ~19 ~32 ~21 ~19 ~33 ~21 stained_hardened_clay 15  
fill ~19 ~32 ~22 ~19 ~32 ~20 stained_hardened_clay 15 
setblock ~19 ~32 ~37 log2 12 
setblock ~19 ~32 ~50 red_glazed_terracotta 0 
setblock ~20 ~32 ~21 planks 5 
setblock ~20 ~32 ~23 stained_hardened_clay 15  
fill ~20 ~32 ~38 ~20 ~33 ~38 log2 12  
fill ~20 ~32 ~40 ~20 ~33 ~40 log2 12 
setblock ~21 ~32 ~22 stained_hardened_clay 15  
fill ~21 ~32 ~23 ~22 ~32 ~23 planks 5  
fill ~21 ~32 ~24 ~21 ~34 ~24 stained_hardened_clay 15 
setblock ~21 ~32 ~33 stained_glass 14  
fill ~21 ~32 ~34 ~21 ~33 ~34 stained_hardened_clay 9 
setblock ~21 ~32 ~35 red_glazed_terracotta 0  
fill ~21 ~32 ~39 ~21 ~34 ~39 log2 12  
fill ~22 ~32 ~24 ~23 ~32 ~24 planks 5  
fill ~22 ~32 ~28 ~23 ~32 ~28 planks 5 
setblock ~22 ~32 ~32 stained_glass_pane 0 
setblock ~22 ~32 ~34 stained_glass_pane 0 
setblock ~1 ~33 ~17 red_glazed_terracotta 0 
setblock ~2 ~33 ~14 red_glazed_terracotta 0 
setblock ~3 ~33 ~13 red_glazed_terracotta 0 
setblock ~3 ~33 ~14 stained_glass 14 
setblock ~3 ~33 ~15 stained_glass_pane 0 
setblock ~3 ~33 ~16 stained_glass 14  
fill ~4 ~33 ~14 ~4 ~34 ~14 red_glazed_terracotta 0 
setblock ~4 ~33 ~17 stained_glass 14 
setblock ~5 ~33 ~16 stained_glass_pane 0  
fill ~6 ~33 ~15 ~7 ~33 ~15 red_glazed_terracotta 0 
setblock ~6 ~33 ~17 red_glazed_terracotta 0 
setblock ~7 ~33 ~14 stained_glass 14  
fill ~7 ~33 ~16 ~7 ~34 ~16 log2 12 
setblock ~7 ~33 ~18 stained_glass 14  
fill ~13 ~33 ~24 ~20 ~33 ~24 planks 5  
fill ~13 ~33 ~25 ~13 ~31 ~25 planks 5  
fill ~13 ~33 ~26 ~15 ~33 ~26 stained_hardened_clay 15  
fill ~13 ~33 ~27 ~13 ~35 ~27 log2 12  
fill ~13 ~33 ~28 ~13 ~35 ~28 log2 12 
setblock ~13 ~33 ~40 stained_hardened_clay 9 
setblock ~13 ~33 ~41 concrete 7 
setblock ~13 ~33 ~42 stained_hardened_clay 9  
fill ~13 ~33 ~51 ~15 ~33 ~51 stained_glass 14  
fill ~14 ~33 ~21 ~18 ~33 ~21 planks 5  
fill ~14 ~33 ~22 ~19 ~33 ~22 planks 5  
fill ~14 ~33 ~23 ~20 ~33 ~23 planks 5 
setblock ~14 ~33 ~25 stained_hardened_clay 15 
setblock ~14 ~33 ~27 planks 5  
fill ~14 ~33 ~29 ~14 ~34 ~29 log2 12 
setblock ~14 ~33 ~40 log2 12  
fill ~14 ~33 ~41 ~15 ~33 ~41 stained_hardened_clay 9 
setblock ~15 ~33 ~25 planks 5  
fill ~15 ~33 ~29 ~15 ~32 ~29 stained_hardened_clay 9  
fill ~15 ~33 ~42 ~15 ~36 ~42 stained_hardened_clay 9 
setblock ~15 ~33 ~48 stained_glass_pane 0  
fill ~15 ~33 ~49 ~15 ~33 ~50 red_glazed_terracotta 0  
fill ~16 ~33 ~26 ~23 ~33 ~26 planks 5  
fill ~16 ~33 ~27 ~23 ~33 ~27 planks 5 
setblock ~16 ~33 ~29 log2 12 
setblock ~16 ~33 ~49 stained_glass 14 
setblock ~16 ~33 ~53 stained_glass_pane 0  
fill ~17 ~33 ~29 ~21 ~33 ~29 planks 5 
setblock ~17 ~33 ~48 stained_glass_pane 0 
setblock ~17 ~33 ~51 stained_glass 14  
fill ~17 ~33 ~52 ~17 ~33 ~53 red_glazed_terracotta 0  
fill ~18 ~33 ~36 ~18 ~33 ~37 stained_hardened_clay 9 
setblock ~18 ~33 ~55 stained_glass_pane 0  
fill ~19 ~33 ~25 ~23 ~33 ~25 planks 5 
setblock ~19 ~33 ~36 log2 12 
setblock ~19 ~33 ~37 stained_hardened_clay 9 
setblock ~19 ~33 ~55 stained_glass 14 
setblock ~20 ~33 ~34 log2 12 
setblock ~20 ~33 ~35 stained_hardened_clay 9 
setblock ~20 ~33 ~37 log2 12 
setblock ~21 ~33 ~23 stained_hardened_clay 15 
setblock ~21 ~33 ~38 log2 12  
fill ~21 ~33 ~40 ~23 ~33 ~40 log2 12 
setblock ~22 ~33 ~24 stained_hardened_clay 15  
fill ~22 ~33 ~28 ~22 ~32 ~28 planks 5  
fill ~22 ~33 ~39 ~22 ~34 ~39 log2 12  
fill ~23 ~33 ~41 ~24 ~33 ~41 log2 12 
setblock ~27 ~33 ~49 stained_glass 14 
setblock ~28 ~33 ~48 red_glazed_terracotta 0 
setblock ~29 ~33 ~48 stained_glass 14 
setblock ~4 ~34 ~15 red_glazed_terracotta 0 
setblock ~4 ~34 ~16 stained_glass 14 
setblock ~6 ~34 ~14 stained_glass_pane 0  
fill ~7 ~34 ~17 ~7 ~36 ~17 log2 12  
fill ~12 ~34 ~27 ~12 ~35 ~27 log2 12  
fill ~12 ~34 ~28 ~12 ~34 ~27 log2 12  
fill ~13 ~34 ~26 ~13 ~35 ~26 log2 12  
fill ~13 ~34 ~41 ~13 ~34 ~42 log2 12  
fill ~14 ~34 ~22 ~19 ~34 ~22 planks 5  
fill ~14 ~34 ~23 ~19 ~34 ~23 planks 5  
fill ~14 ~34 ~24 ~20 ~34 ~24 planks 5  
fill ~14 ~34 ~26 ~14 ~36 ~26 planks 5  
fill ~14 ~34 ~27 ~14 ~34 ~29 log2 12  
fill ~14 ~34 ~41 ~14 ~30 ~41 stained_hardened_clay 9 
setblock ~14 ~34 ~43 stained_hardened_clay 9  
fill ~15 ~34 ~21 ~18 ~34 ~21 planks 5 
setblock ~15 ~34 ~25 double_stone_slab 6  
fill ~15 ~34 ~26 ~15 ~34 ~27 stained_hardened_clay 15 
setblock ~15 ~34 ~29 log2 12 
setblock ~15 ~34 ~50 stained_glass 14 
setblock ~15 ~34 ~51 red_glazed_terracotta 0  
fill ~16 ~34 ~20 ~17 ~34 ~20 log2 12  
fill ~16 ~34 ~26 ~22 ~34 ~26 planks 5  
fill ~16 ~34 ~27 ~21 ~34 ~27 planks 5 
setblock ~16 ~34 ~51 stained_glass 14  
fill ~17 ~34 ~29 ~20 ~34 ~29 planks 5  
fill ~17 ~34 ~37 ~18 ~34 ~37 stained_hardened_clay 9 
setblock ~18 ~34 ~38 stained_hardened_clay 9 
setblock ~18 ~34 ~52 red_glazed_terracotta 0 
setblock ~18 ~34 ~54 stained_glass_pane 0  
fill ~19 ~34 ~25 ~22 ~34 ~25 planks 5 
setblock ~19 ~34 ~36 stained_hardened_clay 9 
setblock ~20 ~34 ~23 stained_hardened_clay 15  
fill ~21 ~34 ~33 ~21 ~34 ~34 stained_glass_pane 0 
setblock ~22 ~34 ~34 red_glazed_terracotta 0 
setblock ~22 ~34 ~40 log2 12  
fill ~23 ~34 ~38 ~23 ~35 ~38 log2 12  
fill ~23 ~34 ~41 ~25 ~34 ~41 log2 12  
fill ~24 ~34 ~42 ~25 ~34 ~42 log2 12  
fill ~25 ~34 ~40 ~27 ~34 ~40 log2 12  
fill ~25 ~34 ~43 ~25 ~35 ~43 log2 12 
setblock ~26 ~34 ~46 stained_glass 14 
setblock ~27 ~34 ~44 red_glazed_terracotta 0  
fill ~27 ~34 ~47 ~28 ~34 ~47 stained_glass_pane 0 
setblock ~27 ~34 ~49 red_glazed_terracotta 0 
setblock ~29 ~34 ~48 stained_glass_pane 0 
setblock ~6 ~35 ~16 stained_glass 14 
setblock ~12 ~35 ~26 log2 12  
fill ~13 ~35 ~23 ~13 ~37 ~23 stained_hardened_clay 9  
fill ~13 ~35 ~24 ~13 ~36 ~24 stained_hardened_clay 9  
fill ~13 ~35 ~25 ~13 ~38 ~25 log2 12 
setblock ~13 ~35 ~42 stained_hardened_clay 9  
fill ~14 ~35 ~22 ~19 ~35 ~22 planks 5  
fill ~14 ~35 ~23 ~19 ~35 ~23 planks 5  
fill ~14 ~35 ~24 ~18 ~35 ~24 planks 5  
fill ~14 ~35 ~25 ~21 ~35 ~25 planks 5 
setblock ~14 ~35 ~41 log2 12 
setblock ~14 ~35 ~43 log2 12  
fill ~15 ~35 ~20 ~18 ~35 ~20 log2 12  
fill ~15 ~35 ~26 ~21 ~35 ~26 planks 5  
fill ~15 ~35 ~27 ~21 ~35 ~27 planks 5  
fill ~16 ~35 ~19 ~17 ~35 ~19 log2 12  
fill ~16 ~35 ~21 ~18 ~35 ~21 planks 5  
fill ~17 ~35 ~29 ~18 ~35 ~29 planks 5 
setblock ~17 ~35 ~37 log2 12 
setblock ~17 ~35 ~38 stained_hardened_clay 9 
setblock ~18 ~35 ~37 stained_hardened_clay 9  
fill ~19 ~35 ~24 ~19 ~37 ~24 stained_hardened_clay 15  
fill ~24 ~35 ~37 ~24 ~36 ~37 log2 12 
setblock ~25 ~35 ~42 log2 12  
fill ~26 ~35 ~43 ~26 ~35 ~44 log2 12 
setblock ~26 ~35 ~47 stained_glass_pane 0 
setblock ~27 ~35 ~40 log2 12  
fill ~27 ~35 ~43 ~28 ~35 ~43 stained_glass 14  
fill ~27 ~35 ~44 ~27 ~36 ~44 log2 12 
setblock ~27 ~35 ~45 stained_glass_pane 0 
setblock ~27 ~35 ~50 red_glazed_terracotta 0 
setblock ~27 ~35 ~51 stained_glass 14  
fill ~28 ~35 ~39 ~28 ~37 ~39 log2 12 
setblock ~28 ~35 ~48 red_glazed_terracotta 0 
setblock ~29 ~35 ~47 stained_glass_pane 0 
setblock ~30 ~35 ~50 stained_glass 14  
fill ~31 ~35 ~48 ~31 ~36 ~48 red_glazed_terracotta 0  
fill ~8 ~36 ~8 ~8 ~37 ~8 red_glazed_terracotta 0 
setblock ~8 ~36 ~9 stained_glass 14  
fill ~8 ~36 ~18 ~8 ~37 ~18 log2 12 
setblock ~11 ~36 ~19 stained_glass 14  
fill ~13 ~36 ~22 ~14 ~36 ~22 stained_hardened_clay 9  
fill ~13 ~36 ~42 ~13 ~37 ~42 log2 12  
fill ~14 ~36 ~23 ~18 ~36 ~23 planks 5  
fill ~14 ~36 ~24 ~18 ~36 ~24 planks 5  
fill ~14 ~36 ~25 ~20 ~36 ~25 planks 5 
setblock ~14 ~36 ~43 stained_hardened_clay 9  
fill ~15 ~36 ~19 ~16 ~36 ~19 log2 12  
fill ~15 ~36 ~20 ~19 ~36 ~20 log2 12  
fill ~15 ~36 ~21 ~15 ~37 ~21 log2 12  
fill ~15 ~36 ~22 ~19 ~36 ~22 planks 5  
fill ~15 ~36 ~26 ~20 ~36 ~26 planks 5  
fill ~15 ~36 ~27 ~20 ~36 ~27 planks 5  
fill ~16 ~36 ~21 ~18 ~36 ~21 planks 5  
fill ~16 ~36 ~37 ~16 ~38 ~37 log2 12  
fill ~16 ~36 ~38 ~17 ~36 ~38 log2 12 
setblock ~17 ~36 ~37 stained_hardened_clay 9 
setblock ~19 ~36 ~23 stained_hardened_clay 15 
setblock ~20 ~36 ~24 stained_hardened_clay 15 
setblock ~25 ~36 ~48 red_glazed_terracotta 0 
setblock ~25 ~36 ~49 stained_glass_pane 0 
setblock ~26 ~36 ~44 stained_glass_pane 0 
setblock ~27 ~36 ~43 stained_glass_pane 0  
fill ~27 ~36 ~45 ~27 ~37 ~45 log2 12 
setblock ~27 ~36 ~47 stained_glass_pane 0 
setblock ~28 ~36 ~44 stained_glass_pane 0 
setblock ~28 ~36 ~45 red_glazed_terracotta 0 
setblock ~28 ~36 ~47 red_glazed_terracotta 0  
fill ~28 ~36 ~50 ~28 ~38 ~50 stained_glass 14 
setblock ~29 ~36 ~47 stained_glass 14 
setblock ~29 ~36 ~51 red_glazed_terracotta 0 
setblock ~30 ~36 ~47 stained_glass_pane 0 
setblock ~31 ~36 ~49 stained_glass 14 
setblock ~7 ~37 ~9 red_glazed_terracotta 0 
setblock ~8 ~37 ~7 stained_glass_pane 0  
fill ~8 ~37 ~10 ~10 ~37 ~10 stained_glass 14  
fill ~9 ~37 ~18 ~12 ~37 ~18 log2 12 
setblock ~10 ~37 ~9 red_glazed_terracotta 0 
setblock ~10 ~37 ~19 red_glazed_terracotta 0 
setblock ~11 ~37 ~17 log2 12  
fill ~11 ~37 ~19 ~13 ~37 ~19 log2 12  
fill ~12 ~37 ~20 ~13 ~37 ~20 log2 12  
fill ~12 ~37 ~21 ~15 ~37 ~21 log2 12  
fill ~12 ~37 ~22 ~12 ~37 ~18 log2 12  
fill ~13 ~37 ~22 ~13 ~36 ~22 stained_hardened_clay 9  
fill ~14 ~37 ~22 ~14 ~38 ~22 log2 12  
fill ~14 ~37 ~23 ~19 ~37 ~23 planks 5  
fill ~14 ~37 ~24 ~18 ~37 ~24 planks 5  
fill ~14 ~37 ~25 ~19 ~37 ~25 planks 5  
fill ~14 ~37 ~43 ~14 ~39 ~43 log2 12  
fill ~15 ~37 ~22 ~19 ~37 ~22 planks 5  
fill ~15 ~37 ~36 ~15 ~39 ~36 log2 12  
fill ~15 ~37 ~37 ~15 ~38 ~37 log2 12 
setblock ~15 ~37 ~42 red_glazed_terracotta 3  
fill ~16 ~37 ~21 ~19 ~37 ~21 planks 5  
fill ~16 ~37 ~26 ~20 ~37 ~26 planks 5  
fill ~16 ~37 ~27 ~19 ~37 ~27 planks 5  
fill ~16 ~37 ~38 ~16 ~36 ~38 log2 12  
fill ~18 ~37 ~20 ~20 ~37 ~20 log2 12  
fill ~18 ~37 ~28 ~18 ~39 ~28 stained_hardened_clay 15 
setblock ~19 ~37 ~19 log2 12  
fill ~20 ~37 ~21 ~20 ~39 ~21 log2 12  
fill ~20 ~37 ~24 ~20 ~39 ~24 planks 5 
setblock ~20 ~37 ~25 stained_hardened_clay 15  
fill ~25 ~37 ~37 ~25 ~38 ~37 log2 12 
setblock ~26 ~37 ~46 stained_glass_pane 0  
fill ~27 ~37 ~46 ~27 ~38 ~46 stained_glass 14 
setblock ~27 ~37 ~49 stained_glass 14  
fill ~28 ~37 ~46 ~28 ~39 ~46 log2 12  
fill ~28 ~37 ~47 ~28 ~37 ~48 stained_glass_pane 0 
setblock ~28 ~37 ~51 stained_glass 14  
fill ~29 ~37 ~38 ~29 ~38 ~38 log2 12 
setblock ~30 ~37 ~37 stained_glass_pane 0  
fill ~6 ~38 ~16 ~7 ~38 ~16 log2 12 
setblock ~7 ~38 ~11 stained_glass_pane 0  
fill ~8 ~38 ~17 ~10 ~38 ~17 log2 12 
setblock ~9 ~38 ~12 red_glazed_terracotta 0  
fill ~9 ~38 ~18 ~12 ~38 ~18 log2 12 
setblock ~10 ~38 ~7 stained_glass_pane 0 
setblock ~10 ~38 ~9 stained_glass 14  
fill ~10 ~38 ~19 ~13 ~38 ~19 log2 12 
setblock ~10 ~38 ~20 red_glazed_terracotta 0 
setblock ~11 ~38 ~8 stained_glass 14 
setblock ~11 ~38 ~10 stained_glass 14  
fill ~11 ~38 ~20 ~11 ~38 ~21 stained_glass_pane 0  
fill ~12 ~38 ~20 ~14 ~38 ~20 log2 12  
fill ~12 ~38 ~21 ~14 ~38 ~21 log2 12 
setblock ~13 ~38 ~22 log2 12  
fill ~13 ~38 ~26 ~13 ~39 ~26 log2 12  
fill ~14 ~38 ~35 ~15 ~38 ~35 log2 12  
fill ~14 ~38 ~36 ~14 ~39 ~36 log2 12  
fill ~14 ~38 ~42 ~15 ~38 ~42 log2 12 
setblock ~15 ~38 ~21 stained_hardened_clay 15  
fill ~15 ~38 ~22 ~19 ~38 ~22 planks 5  
fill ~15 ~38 ~23 ~19 ~38 ~23 planks 5  
fill ~15 ~38 ~24 ~20 ~38 ~24 planks 5  
fill ~15 ~38 ~25 ~15 ~40 ~25 planks 5  
fill ~16 ~38 ~21 ~19 ~38 ~21 planks 5 
setblock ~16 ~38 ~26 stained_hardened_clay 15  
fill ~16 ~38 ~27 ~16 ~39 ~27 planks 5  
fill ~16 ~38 ~28 ~16 ~38 ~27 planks 5  
fill ~17 ~38 ~20 ~18 ~38 ~20 planks 5  
fill ~17 ~38 ~26 ~20 ~38 ~26 planks 5  
fill ~17 ~38 ~27 ~17 ~40 ~27 stained_hardened_clay 15  
fill ~19 ~38 ~20 ~20 ~38 ~20 log2 12  
fill ~19 ~38 ~25 ~20 ~38 ~25 planks 5 
setblock ~19 ~38 ~28 stained_hardened_clay 15 
setblock ~20 ~38 ~22 stained_hardened_clay 9 
setblock ~25 ~38 ~46 red_glazed_terracotta 0 
setblock ~27 ~38 ~47 red_glazed_terracotta 0 
setblock ~28 ~38 ~45 stained_glass_pane 0 
setblock ~28 ~38 ~47 stained_glass 14  
fill ~28 ~38 ~49 ~28 ~40 ~49 stained_glass_pane 0 
setblock ~29 ~38 ~47 stained_glass_pane 0  
fill ~29 ~38 ~49 ~29 ~39 ~49 red_glazed_terracotta 0 
setblock ~30 ~38 ~45 stained_glass 14 
setblock ~30 ~38 ~50 stained_glass_pane 0  
fill ~31 ~38 ~46 ~31 ~38 ~47 stained_glass 14 
setblock ~5 ~39 ~8 stained_glass 14 
setblock ~5 ~39 ~9 stained_glass_pane 0  
fill ~7 ~39 ~9 ~8 ~39 ~9 red_glazed_terracotta 0  
fill ~7 ~39 ~16 ~8 ~39 ~16 log2 12  
fill ~7 ~39 ~17 ~9 ~39 ~17 log2 12  
fill ~8 ~39 ~6 ~8 ~40 ~6 stained_glass_pane 0  
fill ~8 ~39 ~11 ~8 ~39 ~12 red_glazed_terracotta 0  
fill ~9 ~39 ~11 ~10 ~39 ~11 stained_glass_pane 0 
setblock ~9 ~39 ~12 stained_glass 14  
fill ~9 ~39 ~13 ~9 ~39 ~14 log2 12 
setblock ~10 ~39 ~13 stained_glass 14  
fill ~10 ~39 ~18 ~11 ~39 ~18 log2 12 
setblock ~11 ~39 ~8 stained_glass_pane 0 
setblock ~11 ~39 ~10 red_glazed_terracotta 0 
setblock ~11 ~39 ~19 stained_glass 14  
fill ~13 ~39 ~27 ~15 ~39 ~27 log2 12  
fill ~14 ~39 ~26 ~15 ~39 ~26 log2 12  
fill ~14 ~39 ~28 ~15 ~39 ~28 log2 12  
fill ~14 ~39 ~34 ~14 ~41 ~34 log2 12  
fill ~14 ~39 ~35 ~15 ~39 ~35 log2 12  
fill ~14 ~39 ~40 ~14 ~40 ~40 stained_glass_pane 0 
setblock ~14 ~39 ~41 red_glazed_terracotta 0  
fill ~14 ~39 ~44 ~14 ~40 ~44 log2 12  
fill ~15 ~39 ~21 ~19 ~39 ~21 planks 5  
fill ~15 ~39 ~22 ~16 ~39 ~22 stained_hardened_clay 15  
fill ~15 ~39 ~23 ~16 ~39 ~23 stained_hardened_clay 15  
fill ~15 ~39 ~24 ~18 ~39 ~24 planks 5  
fill ~15 ~39 ~29 ~15 ~41 ~29 log2 12 
setblock ~15 ~39 ~42 stained_glass 14  
fill ~16 ~39 ~20 ~19 ~39 ~20 planks 5 
setblock ~16 ~39 ~26 planks 5  
fill ~16 ~39 ~28 ~18 ~39 ~28 stained_hardened_clay 15  
fill ~17 ~39 ~22 ~18 ~39 ~22 planks 5  
fill ~17 ~39 ~23 ~20 ~39 ~23 planks 5 
setblock ~17 ~39 ~26 stained_hardened_clay 15  
fill ~18 ~39 ~26 ~20 ~39 ~26 planks 5 
setblock ~19 ~39 ~22 stained_hardened_clay 15 
setblock ~19 ~39 ~24 stained_hardened_clay 15  
fill ~19 ~39 ~25 ~20 ~39 ~25 planks 5  
fill ~19 ~39 ~28 ~19 ~45 ~28 planks 5  
fill ~20 ~39 ~22 ~20 ~41 ~22 planks 5  
fill ~20 ~39 ~27 ~20 ~45 ~27 planks 5  
fill ~21 ~39 ~22 ~21 ~40 ~22 stained_hardened_clay 9  
fill ~21 ~39 ~23 ~21 ~43 ~23 stained_hardened_clay 9 
setblock ~25 ~39 ~46 stained_glass_pane 0 
setblock ~25 ~39 ~47 stained_glass 14 
setblock ~25 ~39 ~48 stained_glass_pane 0 
setblock ~26 ~39 ~49 stained_glass_pane 0 
setblock ~27 ~39 ~47 stained_glass 14 
setblock ~28 ~39 ~48 stained_glass 14 
setblock ~29 ~39 ~37 stained_glass 14  
fill ~29 ~39 ~45 ~29 ~39 ~46 stained_glass_pane 0  
fill ~30 ~39 ~37 ~30 ~40 ~37 log2 12 
setblock ~30 ~39 ~38 red_glazed_terracotta 0 
setblock ~30 ~39 ~47 stained_glass 14 
setblock ~30 ~39 ~48 red_glazed_terracotta 0 
setblock ~31 ~39 ~37 red_glazed_terracotta 0 
setblock ~5 ~40 ~9 red_glazed_terracotta 0 
setblock ~6 ~40 ~7 stained_glass_pane 0  
fill ~6 ~40 ~9 ~6 ~40 ~10 stained_glass_pane 0 
setblock ~7 ~40 ~6 stained_glass_pane 0 
setblock ~7 ~40 ~8 stained_glass_pane 0 
setblock ~7 ~40 ~11 stained_glass_pane 0  
fill ~7 ~40 ~16 ~8 ~40 ~16 log2 12 
setblock ~7 ~40 ~17 stained_glass 14 
setblock ~8 ~40 ~8 stained_glass 14  
fill ~8 ~40 ~9 ~8 ~41 ~9 red_glazed_terracotta 0  
fill ~8 ~40 ~15 ~9 ~40 ~15 log2 12 
setblock ~8 ~40 ~17 log2 12 
setblock ~9 ~40 ~7 red_glazed_terracotta 0  
fill ~9 ~40 ~11 ~9 ~40 ~12 log2 12 
setblock ~10 ~40 ~7 stained_glass_pane 0 
setblock ~10 ~40 ~9 stained_glass_pane 0  
fill ~12 ~40 ~27 ~13 ~40 ~27 planks 5  
fill ~12 ~40 ~28 ~13 ~40 ~28 planks 5  
fill ~12 ~40 ~29 ~13 ~40 ~29 planks 5 
setblock ~13 ~40 ~39 stained_glass 14  
fill ~14 ~40 ~26 ~15 ~40 ~26 log2 12  
fill ~14 ~40 ~27 ~16 ~40 ~27 log2 12  
fill ~14 ~40 ~28 ~15 ~40 ~28 log2 12  
fill ~14 ~40 ~29 ~14 ~41 ~29 log2 12  
fill ~14 ~40 ~35 ~15 ~40 ~35 log2 12 
setblock ~14 ~40 ~39 stained_glass_pane 0  
fill ~14 ~40 ~45 ~14 ~41 ~45 log2 12 
setblock ~14 ~40 ~47 red_glazed_terracotta 0  
fill ~15 ~40 ~20 ~19 ~40 ~20 planks 5  
fill ~15 ~40 ~21 ~20 ~40 ~21 planks 5  
fill ~15 ~40 ~22 ~15 ~45 ~22 planks 5  
fill ~15 ~40 ~23 ~15 ~39 ~23 stained_hardened_clay 15  
fill ~15 ~40 ~24 ~15 ~41 ~24 stained_hardened_clay 15  
fill ~15 ~40 ~30 ~16 ~40 ~30 log2 12  
fill ~15 ~40 ~34 ~15 ~42 ~34 log2 12 
setblock ~15 ~40 ~40 red_glazed_terracotta 0 
setblock ~15 ~40 ~41 stained_glass 14  
fill ~15 ~40 ~42 ~15 ~41 ~42 log2 12  
fill ~15 ~40 ~43 ~15 ~40 ~44 stained_glass 14 
setblock ~15 ~40 ~47 stained_glass_pane 0 
setblock ~16 ~40 ~22 stained_hardened_clay 15  
fill ~16 ~40 ~23 ~19 ~40 ~23 planks 5  
fill ~16 ~40 ~24 ~19 ~40 ~24 planks 5  
fill ~16 ~40 ~25 ~16 ~41 ~25 stained_hardened_clay 15  
fill ~16 ~40 ~26 ~16 ~41 ~26 stained_hardened_clay 15  
fill ~16 ~40 ~28 ~20 ~40 ~28 planks 5  
fill ~16 ~40 ~29 ~16 ~50 ~29 planks 5 
setblock ~16 ~40 ~40 stained_glass 14  
fill ~17 ~40 ~22 ~20 ~40 ~22 planks 5  
fill ~17 ~40 ~26 ~20 ~40 ~26 planks 5  
fill ~17 ~40 ~41 ~17 ~41 ~41 stained_glass_pane 0 
setblock ~17 ~40 ~43 stained_glass 14  
fill ~18 ~40 ~19 ~19 ~40 ~19 planks 5  
fill ~19 ~40 ~25 ~20 ~40 ~25 planks 5 
setblock ~20 ~40 ~23 stained_hardened_clay 9 
setblock ~20 ~40 ~24 stained_hardened_clay 15 
setblock ~21 ~40 ~24 stained_hardened_clay 9  
fill ~22 ~40 ~23 ~22 ~43 ~23 stained_hardened_clay 9 
setblock ~22 ~40 ~25 stained_glass 14 
setblock ~26 ~40 ~48 stained_glass_pane 0 
setblock ~27 ~40 ~46 stained_glass 14 
setblock ~27 ~40 ~47 stained_glass_pane 0   

KittysCommands:  
setblock ~28 ~40 ~47 red_glazed_terracotta 0 
setblock ~29 ~40 ~36 stained_glass 14 
setblock ~29 ~40 ~44 stained_glass_pane 0 
setblock ~29 ~40 ~45 stained_glass 14 
setblock ~30 ~40 ~36 stained_glass_pane 0 
setblock ~30 ~40 ~38 stained_glass_pane 0 
setblock ~31 ~40 ~35 stained_glass_pane 0 
setblock ~32 ~40 ~34 stained_glass 14 
setblock ~32 ~40 ~35 red_glazed_terracotta 0 
setblock ~33 ~40 ~32 stained_glass 14  
fill ~6 ~41 ~11 ~8 ~41 ~11 red_glazed_terracotta 0 
setblock ~7 ~41 ~15 stained_glass_pane 0 
setblock ~8 ~41 ~10 stained_glass_pane 0 
setblock ~8 ~41 ~12 stained_glass_pane 0 
setblock ~8 ~41 ~15 stained_glass 14 
setblock ~9 ~41 ~12 red_glazed_terracotta 0  
fill ~9 ~41 ~14 ~9 ~41 ~15 log2 12 
setblock ~10 ~41 ~9 red_glazed_terracotta 0 
setblock ~10 ~41 ~10 stained_glass 14 
setblock ~10 ~41 ~11 stained_glass_pane 0 
setblock ~11 ~41 ~9 stained_glass 14 
setblock ~11 ~41 ~27 stained_hardened_clay 15  
fill ~11 ~41 ~28 ~11 ~41 ~29 planks 5  
fill ~12 ~41 ~21 ~21 ~41 ~21 planks 5  
fill ~12 ~41 ~22 ~13 ~41 ~22 planks 5  
fill ~12 ~41 ~23 ~13 ~41 ~23 planks 5  
fill ~12 ~41 ~26 ~13 ~41 ~26 planks 5  
fill ~12 ~41 ~27 ~14 ~41 ~27 planks 5 
setblock ~12 ~41 ~28 stained_hardened_clay 15  
fill ~12 ~41 ~29 ~13 ~41 ~29 planks 5  
fill ~12 ~41 ~30 ~13 ~41 ~30 planks 5  
fill ~12 ~41 ~42 ~12 ~42 ~42 stained_glass_pane 0 
setblock ~12 ~41 ~47 stained_glass 14  
fill ~13 ~41 ~20 ~16 ~41 ~20 planks 5  
fill ~13 ~41 ~24 ~13 ~45 ~24 planks 5  
fill ~13 ~41 ~28 ~14 ~41 ~28 planks 5 
setblock ~13 ~41 ~40 stained_glass 14 
setblock ~13 ~41 ~47 stained_glass_pane 0  
fill ~14 ~41 ~19 ~15 ~41 ~19 planks 5  
fill ~14 ~41 ~26 ~16 ~41 ~26 stained_hardened_clay 15  
fill ~14 ~41 ~35 ~15 ~41 ~35 log2 12  
fill ~14 ~41 ~42 ~14 ~42 ~42 stained_glass_pane 0 
setblock ~14 ~41 ~43 red_glazed_terracotta 0  
fill ~15 ~41 ~23 ~18 ~41 ~23 planks 5 
setblock ~15 ~41 ~25 stained_hardened_clay 15 
setblock ~15 ~41 ~27 log2 12  
fill ~15 ~41 ~30 ~17 ~41 ~30 log2 12 
setblock ~15 ~41 ~40 stained_glass 14  
fill ~16 ~41 ~22 ~21 ~41 ~22 planks 5  
fill ~16 ~41 ~24 ~21 ~41 ~24 planks 5  
fill ~16 ~41 ~27 ~20 ~41 ~27 planks 5  
fill ~16 ~41 ~28 ~20 ~41 ~28 planks 5  
fill ~16 ~41 ~31 ~17 ~41 ~31 log2 12 
setblock ~16 ~41 ~41 stained_glass_pane 0 
setblock ~16 ~41 ~42 red_glazed_terracotta 0  
fill ~16 ~41 ~44 ~16 ~41 ~45 stained_glass_pane 0 
setblock ~16 ~41 ~47 red_glazed_terracotta 0  
fill ~17 ~41 ~20 ~17 ~44 ~20 stained_hardened_clay 15  
fill ~17 ~41 ~26 ~21 ~41 ~26 planks 5  
fill ~17 ~41 ~29 ~18 ~41 ~29 planks 5 
setblock ~17 ~41 ~43 red_glazed_terracotta 0 
setblock ~17 ~41 ~44 red_glazed_terracotta 3  
fill ~18 ~41 ~19 ~19 ~41 ~19 planks 5  
fill ~18 ~41 ~20 ~21 ~41 ~20 planks 5 
setblock ~18 ~41 ~43 stained_glass_pane 0  
fill ~19 ~41 ~23 ~19 ~45 ~23 stained_hardened_clay 15  
fill ~19 ~41 ~25 ~21 ~41 ~25 planks 5 
setblock ~19 ~41 ~42 red_glazed_terracotta 0  
fill ~20 ~41 ~23 ~20 ~42 ~23 log2 12  
fill ~22 ~41 ~22 ~22 ~43 ~22 stained_hardened_clay 9 
setblock ~22 ~41 ~24 stained_hardened_clay 9 
setblock ~22 ~41 ~25 red_glazed_terracotta 0 
setblock ~23 ~41 ~24 stained_glass 14 
setblock ~27 ~41 ~46 stained_glass_pane 0 
setblock ~28 ~41 ~45 stained_glass_pane 0 
setblock ~28 ~41 ~47 stained_glass_pane 0  
fill ~30 ~41 ~35 ~30 ~43 ~35 red_glazed_terracotta 0  
fill ~30 ~41 ~36 ~30 ~42 ~36 log2 12 
setblock ~30 ~41 ~37 red_glazed_terracotta 0 
setblock ~32 ~41 ~33 stained_glass 14 
setblock ~33 ~41 ~33 red_glazed_terracotta 0 
setblock ~34 ~41 ~33 stained_glass 14 
setblock ~35 ~41 ~32 stained_glass_pane 0 
setblock ~5 ~42 ~9 stained_glass_pane 0 
setblock ~7 ~42 ~6 red_glazed_terracotta 0 
setblock ~7 ~42 ~7 stained_glass 14  
fill ~8 ~42 ~8 ~8 ~43 ~8 stained_glass_pane 0 
setblock ~8 ~42 ~10 red_glazed_terracotta 0 
setblock ~9 ~42 ~11 stained_glass 14 
setblock ~10 ~42 ~9 stained_glass_pane 0  
fill ~10 ~42 ~14 ~10 ~45 ~14 log2 12 
setblock ~10 ~42 ~28 skull 4 
setblock ~11 ~42 ~8 stained_glass 14  
fill ~11 ~42 ~21 ~12 ~42 ~21 stained_hardened_clay 15  
fill ~11 ~42 ~22 ~19 ~42 ~22 planks 5  
fill ~11 ~42 ~23 ~18 ~42 ~23 planks 5  
fill ~11 ~42 ~27 ~11 ~43 ~27 planks 5 
setblock ~11 ~42 ~28 log2 12  
fill ~11 ~42 ~29 ~19 ~42 ~29 planks 5  
fill ~12 ~42 ~20 ~15 ~42 ~20 planks 5  
fill ~12 ~42 ~24 ~12 ~44 ~24 planks 5  
fill ~12 ~42 ~26 ~14 ~42 ~26 planks 5 
setblock ~12 ~42 ~27 stained_hardened_clay 15  
fill ~12 ~42 ~28 ~20 ~42 ~28 planks 5  
fill ~12 ~42 ~30 ~14 ~42 ~30 planks 5 
setblock ~12 ~42 ~43 red_glazed_terracotta 0  
fill ~13 ~42 ~21 ~21 ~42 ~21 planks 5  
fill ~13 ~42 ~27 ~21 ~42 ~27 planks 5  
fill ~13 ~42 ~42 ~13 ~43 ~42 stained_glass 14  
fill ~13 ~42 ~44 ~13 ~43 ~44 stained_glass 14 
setblock ~13 ~42 ~46 red_glazed_terracotta 0  
