fill ~42~28~1 ~48~28~1 minecraft:wool 1
fill ~42~29~1 ~43~29~1 minecraft:planks 4
setblock ~42~30~1 minecraft:wool 1
fill ~43~25~1 ~46~25~1 minecraft:wool 1
fill ~43~26~1 ~44~26~1 minecraft:planks 4
setblock ~43~27~1 minecraft:wool 1
fill ~43~30~1 ~45~30~1 minecraft:planks 4
fill ~43~31~1 ~49~31~1 minecraft:wool 1
setblock ~43~32~1 minecraft:wool 1
setblock ~43~33~1 minecraft:planks 4
setblock ~44~23~1 minecraft:planks 4
fill ~44~24~1 ~48~24~1 minecraft:wool 1
setblock ~44~27~1 minecraft:planks 4
setblock ~44~29~1 minecraft:wool 1
fill ~44~32~1 ~45~32~1 minecraft:planks 4
fill ~44~33~1 ~45~33~1 minecraft:wool 1
setblock ~44~34~1 minecraft:planks 4
fill ~44~35~1 ~45~35~1 minecraft:wool 1
fill ~45~22~1 ~46~22~1 minecraft:planks 4
fill ~45~23~1 ~48~23~1 minecraft:wool 1
fill ~45~26~1 ~49~26~1 minecraft:wool 1
fill ~45~27~1 ~46~27~1 minecraft:wool 1
setblock ~45~29~1 minecraft:planks 4
setblock ~45~34~1 minecraft:wool 1
setblock ~45~36~1 minecraft:wool 1
fill ~46~29~1 ~46~30~1 minecraft:wool 1
fill ~46~32~1 ~48~32~1 minecraft:wool 1
fill ~46~33~1 ~47~33~1 minecraft:planks 4
fill ~46~34~1 ~46~36~1 minecraft:planks 4
setblock ~47~22~1 minecraft:wool 1
fill ~47~25~1 ~48~25~1 minecraft:planks 4
setblock ~47~27~1 minecraft:planks 4
setblock ~47~29~1 minecraft:planks 4
fill ~47~30~1 ~50~30~1 minecraft:wool 1
fill ~47~34~1 ~47~36~1 minecraft:wool 1
fill ~48~27~1 ~49~27~1 minecraft:wool 1
setblock ~48~29~1 minecraft:wool 1
fill ~48~33~1 ~49~33~1 minecraft:wool 1
setblock ~48~34~1 minecraft:planks 4
setblock ~48~35~1 minecraft:wool 1
setblock ~49~25~1 minecraft:wool 1
fill ~49~28~1 ~50~28~1 minecraft:planks 4
setblock ~49~29~1 minecraft:planks 4
setblock ~49~32~1 minecraft:planks 4
fill ~50~29~1 ~50~29~2 minecraft:wool 1
fill ~56~28~1 ~57~30~1 minecraft:wool 1
fill ~57~25~1 ~59~25~1 minecraft:wool 1
fill ~57~26~1 ~58~27~1 minecraft:wool 1
fill ~57~31~1 ~57~33~1 minecraft:wool 1
fill ~58~23~1 ~60~23~1 minecraft:wool 1
setblock ~58~24~1 minecraft:planks 4
fill ~58~28~1 ~58~28~2 minecraft:planks 4
fill ~58~29~1 ~58~31~1 minecraft:planks 4
fill ~58~32~1 ~59~33~1 minecraft:wool 1
fill ~58~34~1 ~58~35~1 minecraft:planks 4
setblock ~59~22~1 minecraft:planks 4
fill ~59~24~1 ~62~24~1 minecraft:wool 1
fill ~59~26~1 ~60~27~1 minecraft:planks 4
fill ~59~28~1 ~64~29~1 minecraft:wool 1
fill ~59~30~1 ~62~30~1 minecraft:wool 1
setblock ~59~31~1 minecraft:planks 4
fill ~59~34~1 ~61~34~1 minecraft:wool 1
fill ~59~35~1 ~60~35~1 minecraft:wool 1
setblock ~59~36~1 minecraft:planks 4
setblock ~60~22~1 minecraft:wool 1
fill ~60~25~1 ~62~25~1 minecraft:planks 4
setblock ~60~31~1 minecraft:wool 1
setblock ~60~32~1 minecraft:planks 4
fill ~60~33~1 ~63~33~1 minecraft:wool 1
fill ~60~36~1 ~61~36~1 minecraft:wool 1
fill ~61~22~1 ~61~23~1 minecraft:planks 4
fill ~61~26~1 ~63~27~1 minecraft:wool 1
setblock ~61~31~1 minecraft:planks 4
fill ~61~32~1 ~63~32~1 minecraft:wool 1
setblock ~61~35~1 minecraft:planks 4
setblock ~62~23~1 minecraft:wool 1
fill ~62~31~1 ~63~31~1 minecraft:wool 1
setblock ~62~34~1 minecraft:planks 4
setblock ~62~35~1 minecraft:wool 1
setblock ~63~25~1 minecraft:wool 1
fill ~63~30~1 ~64~30~1 minecraft:planks 4
fill ~39~28~2 ~40~28~2 minecraft:wool 1
fill ~39~29~2 ~39~30~2 minecraft:planks 4
fill ~40~25~2 ~41~27~2 minecraft:wool 1
fill ~40~29~2 ~40~33~2 minecraft:wool 1
fill ~41~23~2 ~43~23~2 minecraft:wool 1
fill ~41~24~2 ~42~24~2 minecraft:planks 4
fill ~41~28~2 ~41~29~2 minecraft:planks 4
fill ~41~30~2 ~41~30~4 minecraft:wool 1
fill ~41~31~2 ~42~33~2 minecraft:wool 1
setblock ~41~34~2 minecraft:wool 1
fill ~41~35~2 ~42~35~2 minecraft:planks 4
fill ~42~21~2 ~42~22~2 minecraft:wool 1
setblock ~42~25~2 minecraft:planks 4
fill ~42~26~2 ~42~27~2 minecraft:wool 1
setblock ~42~29~2 minecraft:planks 4
setblock ~42~34~2 minecraft:planks 4
fill ~42~36~2 ~44~36~2 minecraft:wool 1
setblock ~42~37~2 minecraft:planks 4
fill ~43~20~2 ~43~21~2 minecraft:planks 4
fill ~43~22~2 ~44~22~2 minecraft:wool 1
setblock ~43~24~2 minecraft:wool 1
fill ~43~28~2 ~44~28~4 minecraft:wool 1
setblock ~43~29~2 minecraft:wool 1
setblock ~43~30~2 minecraft:planks 4
fill ~43~34~2 ~43~35~2 minecraft:wool 1
fill ~43~37~2 ~50~37~2 minecraft:wool 1
fill ~43~38~2 ~45~38~2 minecraft:planks 4
fill ~44~20~2 ~45~20~2 minecraft:wool 1
setblock ~44~21~2 minecraft:planks 4
fill ~44~30~2 ~45~30~3 minecraft:wool 1
fill ~45~19~2 ~48~19~2 minecraft:wool 1
fill ~45~21~2 ~49~21~2 minecraft:wool 1
setblock ~45~28~2 minecraft:planks 4
setblock ~45~39~2 minecraft:wool 1
setblock ~46~20~2 minecraft:planks 4
fill ~46~28~2 ~49~28~2 minecraft:wool 1
setblock ~46~30~2 minecraft:planks 4
fill ~46~38~2 ~48~38~2 minecraft:wool 1
setblock ~46~39~2 minecraft:planks 4
setblock ~47~20~2 minecraft:wool 1
fill ~47~30~2 ~49~30~2 minecraft:wool 1
setblock ~47~39~2 minecraft:wool 1
setblock ~48~20~2 minecraft:planks 4
setblock ~48~22~2 minecraft:planks 4
fill ~48~36~2 ~50~36~2 minecraft:wool 1
setblock ~48~39~2 minecraft:planks 4
setblock ~49~20~2 minecraft:wool 1
fill ~49~22~2 ~49~23~2 minecraft:wool 1
setblock ~49~24~2 minecraft:planks 4
fill ~49~34~2 ~51~34~2 minecraft:wool 1
fill ~49~35~2 ~50~35~2 minecraft:wool 1
setblock ~49~38~2 minecraft:planks 4
fill ~50~21~2 ~50~23~2 minecraft:planks 4
fill ~50~24~2 ~50~25~2 minecraft:wool 1
setblock ~50~26~2 minecraft:planks 4
fill ~50~27~2 ~52~27~2 minecraft:wool 1
fill ~50~31~2 ~50~33~2 minecraft:wool 1
fill ~51~23~2 ~51~24~2 minecraft:planks 4
fill ~51~25~2 ~51~26~2 minecraft:wool 1
fill ~51~28~2 ~52~29~2 minecraft:wool 1
fill ~51~30~2 ~51~30~4 minecraft:wool 1
fill ~51~31~2 ~52~31~2 minecraft:planks 4
fill ~51~32~2 ~51~33~2 minecraft:wool 1
setblock ~51~35~2 minecraft:planks 4
fill ~52~30~2 ~52~30~4 minecraft:planks 4
fill ~54~27~2 ~56~27~2 minecraft:wool 1
fill ~54~28~2 ~55~28~4 minecraft:wool 1
setblock ~54~29~2 minecraft:planks 4
fill ~54~30~2 ~55~30~3 minecraft:wool 1
setblock ~54~31~2 minecraft:planks 4
fill ~55~23~2 ~57~23~2 minecraft:wool 1
fill ~55~24~2 ~55~26~2 minecraft:wool 1
fill ~55~29~2 ~56~29~2 minecraft:wool 1
fill ~55~31~2 ~56~32~2 minecraft:wool 1
setblock ~55~33~2 minecraft:wool 1
fill ~55~34~2 ~55~35~2 minecraft:planks 4
fill ~56~21~2 ~59~21~2 minecraft:wool 1
fill ~56~22~2 ~58~22~2 minecraft:wool 1
setblock ~56~24~2 minecraft:planks 4
fill ~56~25~2 ~56~26~2 minecraft:wool 1
setblock ~56~33~2 minecraft:planks 4
fill ~56~34~2 ~57~37~2 minecraft:wool 1
fill ~57~20~2 ~58~20~2 minecraft:wool 1
setblock ~57~24~2 minecraft:wool 1
setblock ~57~28~2 minecraft:planks 4
setblock ~57~30~2 minecraft:planks 4
fill ~57~38~2 ~61~38~2 minecraft:wool 1
fill ~58~19~2 ~61~19~2 minecraft:wool 1
fill ~58~30~2 ~59~30~2 minecraft:wool 1
fill ~58~36~2 ~58~37~2 minecraft:wool 1
setblock ~58~39~2 minecraft:planks 4
setblock ~59~20~2 minecraft:planks 4
setblock ~59~28~2 minecraft:planks 4
fill ~59~37~2 ~60~37~2 minecraft:wool 1
fill ~59~39~2 ~61~39~2 minecraft:wool 1
fill ~60~20~2 ~63~20~2 minecraft:wool 1
setblock ~60~21~2 minecraft:planks 4
fill ~60~28~2 ~62~28~2 minecraft:wool 1
fill ~60~30~2 ~61~30~2 minecraft:planks 4
fill ~61~21~2 ~62~21~2 minecraft:wool 1
setblock ~61~37~2 minecraft:planks 4
fill ~62~22~2 ~63~22~2 minecraft:planks 4
fill ~62~30~2 ~63~30~2 minecraft:wool 1
fill ~62~36~2 ~63~36~2 minecraft:planks 4
setblock ~62~37~2 minecraft:wool 1
setblock ~62~38~2 minecraft:planks 4
setblock ~63~21~2 minecraft:planks 4
fill ~63~23~2 ~64~24~2 minecraft:planks 4
setblock ~63~28~2 minecraft:planks 4
setblock ~63~34~2 minecraft:planks 4
fill ~63~35~2 ~65~35~2 minecraft:wool 1
setblock ~63~37~2 minecraft:planks 4
setblock ~63~38~2 minecraft:wool 1
fill ~64~21~2 ~64~22~2 minecraft:wool 1
fill ~64~25~2 ~64~27~2 minecraft:wool 1
fill ~64~29~2 ~67~29~2 minecraft:wool 1
fill ~64~31~2 ~65~31~2 minecraft:wool 1
fill ~64~32~2 ~64~34~2 minecraft:wool 1
fill ~64~36~2 ~64~37~2 minecraft:wool 1
fill ~65~23~2 ~65~24~2 minecraft:wool 1
fill ~65~25~2 ~66~26~2 minecraft:planks 4
fill ~65~27~2 ~66~28~2 minecraft:wool 1
fill ~65~30~2 ~66~30~4 minecraft:wool 1
setblock ~65~32~2 minecraft:planks 4
fill ~65~33~2 ~66~33~2 minecraft:wool 1
setblock ~65~34~2 minecraft:wool 1
setblock ~66~31~2 minecraft:planks 4
setblock ~66~32~2 minecraft:wool 1
setblock ~67~28~2 minecraft:wool 1
setblock ~67~30~2 minecraft:planks 4
fill ~37~29~3 ~39~29~3 minecraft:wool 1
fill ~38~26~3 ~38~27~4 minecraft:wool 1
setblock ~38~28~3 minecraft:wool 1
fill ~38~30~3 ~38~31~3 minecraft:wool 1
setblock ~38~32~3 minecraft:planks 4
fill ~39~23~3 ~40~23~3 minecraft:wool 1
fill ~39~24~3 ~40~24~3 minecraft:planks 4
fill ~39~25~3 ~39~25~4 minecraft:wool 1
setblock ~39~26~3 minecraft:planks 4
fill ~39~27~3 ~39~27~4 minecraft:wool 1
fill ~39~31~3 ~39~34~4 minecraft:wool 1
setblock ~39~35~3 minecraft:planks 4
fill ~40~21~3 ~41~21~3 minecraft:wool 1
fill ~40~22~3 ~41~22~3 minecraft:planks 4
fill ~40~28~3 ~42~28~3 minecraft:wool 1
setblock ~40~30~3 minecraft:wool 1
fill ~40~34~3 ~40~37~3 minecraft:wool 1
setblock ~41~19~3 minecraft:planks 4
fill ~41~20~3 ~42~20~3 minecraft:wool 1
fill ~41~36~3 ~41~39~3 minecraft:wool 1
fill ~42~18~3 ~47~18~3 minecraft:wool 1
fill ~42~19~3 ~44~19~3 minecraft:wool 1
fill ~42~30~3 ~43~30~4 minecraft:wool 1
setblock ~42~38~3 minecraft:wool 1
setblock ~42~39~3 minecraft:planks 4
setblock ~42~40~3 minecraft:wool 1
setblock ~43~39~3 minecraft:wool 1
setblock ~43~40~3 minecraft:planks 4
setblock ~44~17~3 minecraft:wool 1
setblock ~44~39~3 minecraft:planks 4
fill ~44~40~3 ~44~41~3 minecraft:wool 1
setblock ~45~17~3 minecraft:planks 4
fill ~45~28~3 ~45~28~4 minecraft:wool 1
setblock ~45~40~3 minecraft:planks 4
setblock ~45~41~3 minecraft:wool 1
fill ~46~17~3 ~48~17~3 minecraft:wool 1
setblock ~46~28~3 minecraft:planks 4
fill ~46~30~3 ~48~30~3 minecraft:wool 1
setblock ~46~40~3 minecraft:wool 1
setblock ~46~41~3 minecraft:planks 4
fill ~47~28~3 ~50~28~3 minecraft:wool 1
setblock ~47~40~3 minecraft:planks 4
fill ~47~41~3 ~48~41~3 minecraft:wool 1
setblock ~48~18~3 minecraft:planks 4
fill ~48~40~3 ~50~40~3 minecraft:wool 1
fill ~49~18~3 ~49~19~3 minecraft:wool 1
fill ~49~30~3 ~49~30~4 minecraft:planks 4
setblock ~49~39~3 minecraft:planks 4
setblock ~50~18~3 minecraft:planks 4
fill ~50~19~3 ~51~19~3 minecraft:wool 1
setblock ~50~20~3 minecraft:wool 1
fill ~50~30~3 ~50~30~4 minecraft:wool 1
setblock ~50~38~3 minecraft:planks 4
fill ~50~39~3 ~51~39~3 minecraft:wool 1
fill ~51~20~3 ~51~21~3 minecraft:planks 4
setblock ~51~22~3 minecraft:wool 1
fill ~51~28~3 ~51~28~4 minecraft:planks 4
fill ~51~36~3 ~52~36~3 minecraft:wool 1
setblock ~51~37~3 minecraft:planks 4
setblock ~51~38~3 minecraft:wool 1
setblock ~52~22~3 minecraft:planks 4
fill ~52~23~3 ~52~26~3 minecraft:wool 1
fill ~52~28~3 ~52~28~4 minecraft:wool 1
fill ~52~32~3 ~52~35~3 minecraft:wool 1
setblock ~53~25~3 minecraft:stained_hardened_clay 1
setblock ~53~26~3 minecraft:stained_hardened_clay 12
fill ~53~27~3 ~53~30~3 minecraft:stained_hardened_clay 1
setblock ~53~31~3 minecraft:stained_hardened_clay 12
setblock ~53~32~3 minecraft:stained_hardened_clay 1
setblock ~53~33~3 minecraft:stained_hardened_clay 12
fill ~54~22~3 ~55~22~3 minecraft:wool 1
fill ~54~23~3 ~54~25~3 minecraft:wool 1
fill ~54~26~3 ~54~26~4 minecraft:planks 4
fill ~54~32~3 ~54~34~4 minecraft:wool 1
fill ~54~35~3 ~54~36~3 minecraft:wool 1
fill ~55~19~3 ~57~19~3 minecraft:wool 1
setblock ~55~20~3 minecraft:wool 1
setblock ~55~21~3 minecraft:planks 4
fill ~55~36~3 ~55~37~3 minecraft:wool 1
setblock ~55~38~3 minecraft:planks 4
fill ~55~39~3 ~56~39~3 minecraft:wool 1
fill ~56~18~3 ~57~18~3 minecraft:wool 1
setblock ~56~20~3 minecraft:planks 4
fill ~56~28~3 ~61~28~3 minecraft:wool 1
setblock ~56~30~3 minecraft:planks 4
setblock ~56~38~3 minecraft:wool 1
setblock ~56~40~3 minecraft:wool 1
fill ~57~30~3 ~58~30~3 minecraft:wool 1
fill ~57~39~3 ~57~40~3 minecraft:planks 4
setblock ~58~17~3 minecraft:wool 1
setblock ~58~18~3 minecraft:planks 4
fill ~58~40~3 ~60~41~3 minecraft:wool 1
setblock ~59~17~3 minecraft:planks 4
fill ~59~18~3 ~64~18~3 minecraft:wool 1
setblock ~59~30~3 minecraft:planks 4
fill ~60~17~3 ~62~17~3 minecraft:wool 1
fill ~60~30~3 ~60~30~4 minecraft:wool 1
fill ~61~30~3 ~61~30~4 minecraft:planks 4
setblock ~61~40~3 minecraft:planks 4
fill ~61~41~3 ~62~41~3 minecraft:wool 1
fill ~62~19~3 ~63~19~3 minecraft:wool 1
fill ~62~28~3 ~62~28~4 minecraft:planks 4
fill ~62~30~3 ~62~30~4 minecraft:wool 1
fill ~62~39~3 ~62~40~3 minecraft:wool 1
fill ~63~28~3 ~63~28~4 minecraft:wool 1
setblock ~63~30~3 minecraft:planks 4
setblock ~63~39~3 minecraft:planks 4
fill ~63~40~3 ~64~40~3 minecraft:wool 1
fill ~64~19~3 ~64~20~3 minecraft:planks 4
fill ~64~28~3 ~66~28~3 minecraft:planks 4
fill ~64~30~3 ~64~30~4 minecraft:wool 1
setblock ~64~38~3 minecraft:planks 4
fill ~64~39~3 ~65~39~3 minecraft:wool 1
fill ~65~19~3 ~65~20~3 minecraft:wool 1
setblock ~65~21~3 minecraft:planks 4
fill ~65~22~3 ~66~22~3 minecraft:wool 1
fill ~65~36~3 ~66~36~3 minecraft:wool 1
fill ~65~37~3 ~65~38~3 minecraft:wool 1
setblock ~66~21~3 minecraft:wool 1
fill ~66~23~3 ~67~23~3 minecraft:wool 1
fill ~66~24~3 ~66~24~4 minecraft:wool 1
fill ~66~34~3 ~67~34~3 minecraft:planks 4
fill ~66~35~3 ~67~35~3 minecraft:wool 1
setblock ~66~37~3 minecraft:planks 4
fill ~67~24~3 ~67~24~4 minecraft:planks 4
fill ~67~25~3 ~67~25~4 minecraft:wool 1
fill ~67~26~3 ~68~27~3 minecraft:wool 1
fill ~67~29~3 ~68~29~3 minecraft:wool 1
fill ~67~31~3 ~67~32~4 minecraft:wool 1
setblock ~67~33~3 minecraft:wool 1
fill ~68~28~3 ~68~28~4 minecraft:wool 1
fill ~68~30~3 ~68~31~3 minecraft:planks 4
fill ~68~32~3 ~68~32~4 minecraft:wool 1
fill ~33~27~4 ~34~27~4 minecraft:wool 1
setblock ~33~28~4 minecraft:planks 4
fill ~33~29~4 ~37~29~4 minecraft:wool 1
fill ~33~30~4 ~35~30~5 minecraft:wool 1
fill ~33~31~4 ~34~31~5 minecraft:wool 1
fill ~34~24~4 ~34~26~5 minecraft:wool 1
fill ~34~28~4 ~35~28~5 minecraft:wool 1
fill ~34~32~4 ~35~32~5 minecraft:wool 1
fill ~34~33~4 ~34~34~5 minecraft:wool 1
setblock ~35~22~4 minecraft:planks 4
fill ~35~23~4 ~35~23~5 minecraft:wool 1
fill ~35~25~4 ~35~26~5 minecraft:wool 1
setblock ~35~33~4 minecraft:planks 4
fill ~35~35~4 ~35~35~6 minecraft:wool 1
setblock ~35~36~4 minecraft:wool 1
setblock ~37~26~4 minecraft:planks 4
fill ~37~27~4 ~37~27~5 minecraft:wool 1
setblock ~37~28~4 minecraft:wool 1
fill ~37~30~4 ~37~31~4 minecraft:wool 1
setblock ~37~32~4 minecraft:planks 4
fill ~38~22~4 ~38~22~5 minecraft:wool 1
fill ~38~23~4 ~38~24~4 minecraft:wool 1
setblock ~38~25~4 minecraft:planks 4
setblock ~38~28~4 minecraft:planks 4
setblock ~38~30~4 minecraft:planks 4
fill ~38~31~4 ~38~36~4 minecraft:wool 1
setblock ~39~20~4 minecraft:planks 4
fill ~39~21~4 ~39~21~5 minecraft:wool 1
setblock ~39~22~4 minecraft:planks 4
fill ~39~24~4 ~40~24~4 minecraft:wool 1
fill ~39~26~4 ~43~26~4 minecraft:wool 1
setblock ~39~28~4 minecraft:wool 1
setblock ~39~30~4 minecraft:wool 1
fill ~39~36~4 ~39~36~5 minecraft:planks 4
fill ~39~37~4 ~39~38~5 minecraft:wool 1
fill ~40~18~4 ~41~18~4 minecraft:wool 1
fill ~40~19~4 ~40~20~4 minecraft:wool 1
setblock ~40~25~4 minecraft:wool 1
fill ~40~27~4 ~45~27~4 minecraft:wool 1
fill ~40~28~4 ~41~28~4 minecraft:planks 4
fill ~40~30~4 ~40~32~4 minecraft:planks 4
fill ~40~33~4 ~51~33~4 minecraft:wool 1
fill ~40~34~4 ~41~34~4 minecraft:planks 4
fill ~40~38~4 ~40~39~4 minecraft:planks 4
setblock ~40~40~4 minecraft:wool 1
fill ~41~17~4 ~43~17~4 minecraft:wool 1
fill ~41~24~4 ~41~25~4 minecraft:planks 4
fill ~41~31~4 ~43~32~4 minecraft:wool 1
setblock ~41~40~4 minecraft:planks 4
fill ~41~41~4 ~43~41~4 minecraft:wool 1
setblock ~42~16~4 minecraft:planks 4
fill ~42~24~4 ~44~25~4 minecraft:wool 1
setblock ~42~28~4 minecraft:wool 1
setblock ~42~34~4 minecraft:wool 1
setblock ~42~42~4 minecraft:planks 4
setblock ~43~16~4 minecraft:wool 1
setblock ~43~34~4 minecraft:planks 4
setblock ~43~42~4 minecraft:wool 1
fill ~44~15~4 ~44~16~4 minecraft:planks 4
fill ~44~26~4 ~46~26~4 minecraft:planks 4
setblock ~44~30~4 minecraft:wool 1
fill ~44~31~4 ~45~31~4 minecraft:planks 4
fill ~44~32~4 ~45~32~4 minecraft:wool 1
setblock ~44~34~4 minecraft:wool 1
setblock ~44~42~4 minecraft:planks 4
setblock ~44~43~4 minecraft:wool 1
fill ~45~15~4 ~48~16~4 minecraft:wool 1
setblock ~45~24~4 minecraft:planks 4
fill ~45~25~4 ~52~25~4 minecraft:wool 1
setblock ~45~30~4 minecraft:planks 4
setblock ~45~34~4 minecraft:planks 4
fill ~45~42~4 ~49~42~4 minecraft:wool 1
fill ~45~43~4 ~46~43~4 minecraft:planks 4
fill ~46~24~4 ~47~24~4 minecraft:wool 1
setblock ~46~27~4 minecraft:planks 4
fill ~46~28~4 ~49~28~4 minecraft:wool 1
fill ~46~30~4 ~47~31~4 minecraft:wool 1
setblock ~46~32~4 minecraft:planks 4
setblock ~46~34~4 minecraft:wool 1
fill ~47~26~4 ~50~27~4 minecraft:wool 1
fill ~47~32~4 ~48~32~4 minecraft:wool 1
setblock ~47~34~4 minecraft:planks 4
fill ~47~43~4 ~50~43~4 minecraft:wool 1
fill ~48~24~4 ~50~24~4 minecraft:planks 4
fill ~48~30~4 ~48~31~4 minecraft:planks 4
fill ~48~34~4 ~52~34~4 minecraft:wool 1
fill ~49~15~4 ~50~15~4 minecraft:planks 4
setblock ~49~16~4 minecraft:planks 4
fill ~49~17~4 ~50~17~4 minecraft:wool 1
fill ~49~31~4 ~51~31~4 minecraft:wool 1
setblock ~49~32~4 minecraft:planks 4
fill ~49~41~4 ~51~41~4 minecraft:wool 1
fill ~50~16~4 ~51~16~4 minecraft:wool 1
setblock ~50~28~4 minecraft:planks 4
fill ~50~32~4 ~51~32~4 minecraft:wool 1
setblock ~50~42~4 minecraft:planks 4
setblock ~51~17~4 minecraft:planks 4
fill ~51~18~4 ~52~18~4 minecraft:wool 1
fill ~51~24~4 ~52~24~4 minecraft:wool 1
fill ~51~26~4 ~52~26~4 minecraft:planks 4
setblock ~51~27~4 minecraft:planks 4
fill ~51~40~4 ~52~40~4 minecraft:wool 1
setblock ~51~42~4 minecraft:wool 1
fill ~52~19~4 ~52~21~4 minecraft:wool 1
setblock ~52~27~4 minecraft:wool 1
fill ~52~31~4 ~52~33~4 minecraft:planks 4
fill ~52~37~4 ~52~37~5 minecraft:planks 4
fill ~52~38~4 ~52~38~5 minecraft:wool 1
setblock ~52~39~4 minecraft:wool 1
fill ~53~21~4 ~53~23~4 minecraft:stained_hardened_clay 12
setblock ~53~24~4 minecraft:stained_hardened_clay 1
fill ~53~34~4 ~53~35~4 minecraft:stained_hardened_clay 1
setblock ~53~36~4 minecraft:stained_hardened_clay 12
setblock ~53~37~4 minecraft:stained_hardened_clay 1
fill ~54~18~4 ~55~18~4 minecraft:wool 1
fill ~54~19~4 ~54~20~4 minecraft:wool 1
setblock ~54~21~4 minecraft:planks 4
fill ~54~24~4 ~57~24~4 minecraft:wool 1
setblock ~54~25~4 minecraft:wool 1
fill ~54~27~4 ~55~27~4 minecraft:wool 1
fill ~54~30~4 ~54~31~4 minecraft:planks 4
fill ~54~37~4 ~54~37~5 minecraft:wool 1
fill ~54~38~4 ~54~38~5 minecraft:planks 4
setblock ~54~39~4 minecraft:planks 4
fill ~54~40~4 ~55~40~4 minecraft:wool 1
setblock ~55~16~4 minecraft:wool 1
fill ~55~17~4 ~56~17~4 minecraft:planks 4
setblock ~55~25~4 minecraft:planks 4
fill ~55~26~4 ~66~26~4 minecraft:wool 1
fill ~55~30~4 ~57~30~4 minecraft:wool 1
setblock ~55~31~4 minecraft:planks 4
fill ~55~32~4 ~59~32~4 minecraft:wool 1
fill ~55~33~4 ~55~34~4 minecraft:wool 1
fill ~55~41~4 ~57~41~4 minecraft:wool 1
fill ~55~42~4 ~56~42~4 minecraft:wool 1
fill ~56~15~4 ~57~16~4 minecraft:planks 4
fill ~56~25~4 ~57~25~4 minecraft:wool 1
setblock ~56~27~4 minecraft:planks 4
fill ~56~28~4 ~58~28~4 minecraft:wool 1
fill ~56~31~4 ~58~31~4 minecraft:wool 1
fill ~56~33~4 ~56~34~4 minecraft:planks 4
fill ~56~43~4 ~59~43~4 minecraft:wool 1
setblock ~57~17~4 minecraft:wool 1
fill ~57~27~4 ~63~27~4 minecraft:wool 1
fill ~57~33~4 ~57~34~4 minecraft:wool 1
fill ~57~42~4 ~59~42~4 minecraft:planks 4
fill ~58~15~4 ~58~16~4 minecraft:wool 1
fill ~58~24~4 ~59~25~4 minecraft:planks 4
setblock ~58~30~4 minecraft:planks 4
fill ~58~33~4 ~59~33~4 minecraft:planks 4
setblock ~58~34~4 minecraft:wool 1
fill ~59~15~4 ~60~15~4 minecraft:planks 4
fill ~59~16~4 ~63~16~4 minecraft:wool 1
setblock ~59~28~4 minecraft:planks 4
setblock ~59~30~4 minecraft:wool 1
fill ~59~31~4 ~61~31~4 minecraft:planks 4
fill ~59~34~4 ~60~34~4 minecraft:planks 4
fill ~60~24~4 ~65~25~4 minecraft:wool 1
setblock ~60~28~4 minecraft:wool 1
setblock ~60~32~4 minecraft:planks 4
fill ~60~33~4 ~66~33~4 minecraft:wool 1
fill ~60~42~4 ~62~42~4 minecraft:wool 1
fill ~60~43~4 ~61~43~4 minecraft:planks 4
setblock ~61~15~4 minecraft:wool 1
setblock ~61~28~4 minecraft:planks 4
fill ~61~32~4 ~63~32~4 minecraft:wool 1
fill ~61~34~4 ~68~34~4 minecraft:wool 1
setblock ~62~15~4 minecraft:planks 4
fill ~62~31~4 ~66~31~4 minecraft:wool 1
setblock ~62~43~4 minecraft:wool 1
fill ~63~17~4 ~65~17~4 minecraft:wool 1
setblock ~63~30~4 minecraft:wool 1
fill ~63~41~4 ~64~41~4 minecraft:wool 1
fill ~63~42~4 ~64~42~4 minecraft:planks 4
setblock ~64~16~4 minecraft:planks 4
setblock ~64~27~4 minecraft:planks 4
fill ~64~28~4 ~67~28~4 minecraft:wool 1
setblock ~64~32~4 minecraft:planks 4
setblock ~65~18~4 minecraft:planks 4
fill ~65~27~4 ~69~27~4 minecraft:wool 1
setblock ~65~32~4 minecraft:wool 1
fill ~65~40~4 ~65~41~4 minecraft:planks 4
fill ~66~18~4 ~66~20~4 minecraft:wool 1
setblock ~66~25~4 minecraft:planks 4
setblock ~66~32~4 minecraft:planks 4
fill ~66~38~4 ~67~38~4 minecraft:planks 4
fill ~66~39~4 ~66~40~4 minecraft:wool 1
fill ~67~20~4 ~67~22~5 minecraft:wool 1
fill ~67~26~4 ~68~26~4 minecraft:planks 4
fill ~67~30~4 ~68~30~4 minecraft:wool 1
setblock ~67~33~4 minecraft:planks 4
fill ~67~36~4 ~68~36~5 minecraft:wool 1
fill ~67~37~4 ~67~37~5 minecraft:wool 1
fill ~68~22~4 ~68~22~5 minecraft:wool 1
setblock ~68~23~4 minecraft:planks 4
fill ~68~24~4 ~68~25~4 minecraft:wool 1
fill ~68~31~4 ~69~31~4 minecraft:planks 4
setblock ~68~33~4 minecraft:wool 1
fill ~68~35~4 ~68~35~5 minecraft:wool 1
setblock ~69~26~4 minecraft:wool 1
setblock ~69~28~4 minecraft:planks 4
setblock ~69~29~4 minecraft:wool 1
setblock ~69~30~4 minecraft:planks 4
setblock ~69~32~4 minecraft:wool 1
setblock ~71~22~4 minecraft:wool 1
setblock ~71~23~4 minecraft:planks 4
fill ~71~25~4 ~72~25~4 minecraft:wool 1
setblock ~71~26~4 minecraft:planks 4
setblock ~71~28~4 minecraft:planks 4
fill ~71~29~4 ~73~29~5 minecraft:wool 1
fill ~71~30~4 ~71~30~5 minecraft:wool 1
fill ~71~32~4 ~72~32~5 minecraft:wool 1
setblock ~71~33~4 minecraft:planks 4
fill ~71~35~4 ~71~35~6 minecraft:wool 1
setblock ~71~36~4 minecraft:wool 1
setblock ~72~24~4 minecraft:planks 4
fill ~72~26~4 ~72~28~5 minecraft:wool 1
fill ~72~30~4 ~72~30~5 minecraft:planks 4
fill ~72~31~4 ~73~31~5 minecraft:wool 1
fill ~72~33~4 ~72~33~5 minecraft:wool 1
setblock ~72~34~4 minecraft:wool 1
fill ~73~27~4 ~73~28~5 minecraft:wool 1
setblock ~73~30~4 minecraft:wool 1
fill ~31~28~5 ~33~29~5 minecraft:wool 1
fill ~31~30~5 ~32~30~5 minecraft:wool 1
fill ~32~25~5 ~32~25~6 minecraft:planks 4
setblock ~32~26~5 minecraft:planks 4
fill ~32~27~5 ~32~27~6 minecraft:wool 1
fill ~32~31~5 ~32~32~5 minecraft:planks 4
fill ~32~33~5 ~33~33~5 minecraft:wool 1
fill ~33~22~5 ~34~22~6 minecraft:wool 1
setblock ~33~23~5 minecraft:planks 4
fill ~33~24~5 ~33~24~6 minecraft:wool 1
fill ~33~25~5 ~33~26~5 minecraft:wool 1
setblock ~33~27~5 minecraft:planks 4
setblock ~33~32~5 minecraft:wool 1
fill ~33~34~5 ~33~34~6 minecraft:planks 4
fill ~33~35~5 ~33~35~6 minecraft:wool 1
setblock ~33~36~5 minecraft:wool 1
fill ~34~20~5 ~34~21~6 minecraft:wool 1
fill ~34~23~5 ~34~23~6 minecraft:wool 1
setblock ~34~27~5 minecraft:wool 1
setblock ~34~29~5 minecraft:wool 1
fill ~34~35~5 ~34~37~5 minecraft:planks 4
fill ~34~38~5 ~35~38~6 minecraft:wool 1
fill ~35~19~5 ~35~21~5 minecraft:planks 4
setblock ~35~24~5 minecraft:planks 4
setblock ~35~27~5 minecraft:planks 4
setblock ~35~29~5 minecraft:planks 4
setblock ~35~31~5 minecraft:wool 1
setblock ~35~33~5 minecraft:wool 1
setblock ~35~34~5 minecraft:planks 4
fill ~35~37~5 ~35~37~6 minecraft:wool 1
fill ~35~39~5 ~36~39~5 minecraft:wool 1
fill ~36~18~5 ~36~19~5 minecraft:wool 1
fill ~36~22~5 ~36~22~6 minecraft:stained_hardened_clay 12
setblock ~36~24~5 minecraft:stained_hardened_clay 1
setblock ~36~25~5 minecraft:stained_hardened_clay 12
fill ~36~26~5 ~36~30~5 minecraft:stained_hardened_clay 1
setblock ~36~31~5 minecraft:stained_hardened_clay 12
setblock ~36~32~5 minecraft:stained_hardened_clay 1
setblock ~36~33~5 minecraft:stained_hardened_clay 12
setblock ~36~34~5 minecraft:stained_hardened_clay 1
fill ~36~36~5 ~36~36~6 minecraft:stained_hardened_clay 1
setblock ~36~40~5 minecraft:wool 1
fill ~37~23~5 ~37~25~5 minecraft:wool 1
fill ~37~26~5 ~69~26~5 minecraft:wool 15
fill ~37~28~5 ~69~30~5 minecraft:wool 15
setblock ~37~31~5 minecraft:wool 1
fill ~37~32~5 ~69~32~5 minecraft:wool 15
setblock ~37~33~5 minecraft:wool 1
setblock ~37~34~5 minecraft:planks 4
fill ~37~35~5 ~40~35~5 minecraft:wool 1
setblock ~38~20~5 minecraft:planks 4
setblock ~38~21~5 minecraft:wool 1
setblock ~38~23~5 minecraft:planks 4
fill ~38~24~5 ~68~25~5 minecraft:wool 15
fill ~38~27~5 ~68~27~5 minecraft:wool 15
fill ~38~31~5 ~68~31~5 minecraft:wool 15
fill ~38~33~5 ~68~34~5 minecraft:wool 15
fill ~38~36~5 ~38~37~5 minecraft:planks 4
setblock ~38~38~5 minecraft:wool 1
fill ~39~18~5 ~39~20~5 minecraft:wool 1
fill ~39~22~5 ~43~22~5 minecraft:wool 1
fill ~39~23~5 ~40~23~5 minecraft:wool 1
fill ~39~39~5 ~39~39~7 minecraft:wool 1
setblock ~39~40~5 minecraft:wool 1
fill ~40~16~5 ~41~16~5 minecraft:wool 1
setblock ~40~17~5 minecraft:planks 4
fill ~40~20~5 ~44~20~5 minecraft:wool 1
setblock ~40~21~5 minecraft:planks 4
setblock ~40~36~5 minecraft:planks 4
fill ~40~37~5 ~40~38~5 minecraft:wool 1
fill ~40~41~5 ~40~42~5 minecraft:wool 1
fill ~41~15~5 ~43~15~5 minecraft:wool 1
fill ~41~21~5 ~45~21~5 minecraft:wool 1
setblock ~41~23~5 minecraft:planks 4
setblock ~41~35~5 minecraft:planks 4
fill ~41~36~5 ~43~36~5 minecraft:wool 1
setblock ~41~37~5 minecraft:planks 4
fill ~41~38~5 ~50~38~5 minecraft:wool 1
fill ~41~42~5 ~41~43~5 minecraft:planks 4
fill ~42~14~5 ~43~14~5 minecraft:wool 1
setblock ~42~23~5 minecraft:wool 1
setblock ~42~35~5 minecraft:wool 1
fill ~42~37~5 ~44~37~5 minecraft:wool 1
fill ~42~43~5 ~43~43~5 minecraft:planks 4
fill ~42~44~5 ~43~44~5 minecraft:wool 1
setblock ~43~23~5 minecraft:planks 4
setblock ~43~35~5 minecraft:planks 4
fill ~44~13~5 ~45~13~5 minecraft:wool 1
setblock ~44~14~5 minecraft:planks 4
setblock ~44~22~5 minecraft:planks 4
fill ~44~23~5 ~48~23~5 minecraft:wool 1
fill ~44~35~5 ~47~35~5 minecraft:wool 1
setblock ~44~36~5 minecraft:planks 4
fill ~44~44~5 ~46~44~5 minecraft:planks 4
setblock ~44~45~5 minecraft:planks 4
setblock ~45~14~5 minecraft:wool 1
fill ~45~20~5 ~48~20~5 minecraft:planks 4
setblock ~45~22~5 minecraft:wool 1
fill ~45~36~5 ~46~36~5 minecraft:wool 1
setblock ~45~37~5 minecraft:planks 4
fill ~45~45~5 ~50~45~5 minecraft:wool 1
fill ~46~13~5 ~46~14~5 minecraft:planks 4
fill ~46~21~5 ~46~22~5 minecraft:planks 4
fill ~46~37~5 ~47~37~5 minecraft:wool 1
fill ~47~13~5 ~49~13~5 minecraft:wool 1
fill ~47~14~5 ~48~14~5 minecraft:wool 1
setblock ~47~21~5 minecraft:wool 1
fill ~47~22~5 ~48~22~5 minecraft:planks 4
setblock ~47~36~5 minecraft:planks 4
fill ~47~44~5 ~48~44~5 minecraft:wool 1
setblock ~48~21~5 minecraft:planks 4
fill ~48~35~5 ~49~35~5 minecraft:planks 4
fill ~48~36~5 ~50~36~5 minecraft:wool 1
setblock ~48~37~5 minecraft:planks 4
setblock ~49~14~5 minecraft:planks 4
fill ~49~20~5 ~49~22~5 minecraft:wool 1
setblock ~49~23~5 minecraft:planks 4
fill ~49~37~5 ~51~37~5 minecraft:wool 1
setblock ~49~44~5 minecraft:planks 4
setblock ~50~13~5 minecraft:planks 4
fill ~50~14~5 ~51~14~5 minecraft:wool 1
setblock ~50~20~5 minecraft:planks 4
fill ~50~21~5 ~51~21~5 minecraft:wool 1
setblock ~50~22~5 minecraft:planks 4
setblock ~50~23~5 minecraft:wool 1
setblock ~50~35~5 minecraft:wool 1
fill ~50~44~5 ~51~44~5 minecraft:wool 1
fill ~51~15~5 ~52~15~5 minecraft:planks 4
fill ~51~20~5 ~52~20~5 minecraft:wool 1
setblock ~51~22~5 minecraft:wool 1
setblock ~51~23~5 minecraft:planks 4
fill ~51~35~5 ~51~36~5 minecraft:planks 4
setblock ~51~38~5 minecraft:planks 4
setblock ~51~43~5 minecraft:planks 4
fill ~52~16~5 ~52~17~5 minecraft:wool 1
fill ~52~21~5 ~52~22~5 minecraft:planks 4
setblock ~52~23~5 minecraft:wool 1
fill ~52~35~5 ~52~36~5 minecraft:wool 1
fill ~52~41~5 ~52~43~5 minecraft:wool 1
setblock ~53~17~5 minecraft:stained_hardened_clay 12
fill ~53~18~5 ~53~19~5 minecraft:stained_hardened_clay 1
setblock ~53~20~5 minecraft:stained_hardened_clay 12
fill ~53~21~5 ~53~21~6 minecraft:wool 15
fill ~53~22~5 ~53~23~5 minecraft:wool 15
fill ~53~35~5 ~53~37~5 minecraft:wool 15
fill ~53~38~5 ~53~39~5 minecraft:stained_hardened_clay 1
setblock ~53~40~5 minecraft:stained_hardened_clay 12
setblock ~53~41~5 minecraft:stained_hardened_clay 1
fill ~54~15~5 ~55~15~5 minecraft:planks 4
fill ~54~16~5 ~54~17~5 minecraft:wool 1
setblock ~54~20~5 minecraft:planks 4
fill ~54~21~5 ~58~22~5 minecraft:wool 1
setblock ~54~23~5 minecraft:wool 1
fill ~54~35~5 ~57~35~5 minecraft:wool 1
fill ~54~36~5 ~55~36~5 minecraft:planks 4
fill ~54~41~5 ~54~42~5 minecraft:planks 4
fill ~54~43~5 ~55~43~5 minecraft:wool 1
fill ~55~14~5 ~57~14~5 minecraft:wool 1
fill ~55~20~5 ~58~20~5 minecraft:wool 1
fill ~55~23~5 ~56~23~5 minecraft:planks 4
fill ~55~37~5 ~57~37~5 minecraft:wool 1
setblock ~55~38~5 minecraft:planks 4
setblock ~55~44~5 minecraft:planks 4
fill ~56~13~5 ~57~13~5 minecraft:wool 1
fill ~56~36~5 ~61~36~5 minecraft:wool 1
fill ~56~38~5 ~66~38~5 minecraft:wool 1
fill ~56~44~5 ~57~45~5 minecraft:wool 1
fill ~57~23~5 ~60~23~5 minecraft:wool 1
fill ~58~13~5 ~62~13~5 minecraft:planks 4
setblock ~58~14~5 minecraft:planks 4
setblock ~58~35~5 minecraft:planks 4
fill ~58~37~5 ~59~37~5 minecraft:planks 4
setblock ~58~44~5 minecraft:planks 4
fill ~58~45~5 ~61~45~5 minecraft:wool 1
fill ~59~14~5 ~64~14~5 minecraft:wool 1
fill ~59~20~5 ~61~20~5 minecraft:planks 4
setblock ~59~21~5 minecraft:planks 4
fill ~59~22~5 ~61~22~5 minecraft:wool 1
fill ~59~35~5 ~63~35~5 minecraft:wool 1
fill ~59~44~5 ~64~44~5 minecraft:wool 1
fill ~60~21~5 ~62~21~5 minecraft:wool 1
fill ~60~37~5 ~66~37~5 minecraft:wool 1
setblock ~61~23~5 minecraft:planks 4
fill ~62~20~5 ~66~20~5 minecraft:wool 1
setblock ~62~22~5 minecraft:planks 4
fill ~62~23~5 ~63~23~5 minecraft:wool 1
setblock ~62~36~5 minecraft:planks 4
setblock ~62~45~5 minecraft:planks 4
fill ~63~15~5 ~65~15~5 minecraft:planks 4
setblock ~63~21~5 minecraft:planks 4
setblock ~63~22~5 minecraft:wool 1
setblock ~63~36~5 minecraft:wool 1
fill ~63~43~5 ~65~43~5 minecraft:wool 1
fill ~64~21~5 ~66~21~5 minecraft:wool 1
fill ~64~22~5 ~64~23~5 minecraft:planks 4
fill ~64~35~5 ~64~36~5 minecraft:planks 4
fill ~65~16~5 ~66~16~5 minecraft:wool 1
fill ~65~22~5 ~65~23~5 minecraft:wool 1
fill ~65~35~5 ~67~35~5 minecraft:wool 1
fill ~65~36~5 ~66~36~5 minecraft:wool 1
setblock ~65~42~5 minecraft:wool 1
setblock ~66~17~5 minecraft:planks 4
setblock ~66~22~5 minecraft:planks 4
fill ~66~23~5 ~69~23~5 minecraft:wool 1
setblock ~66~41~5 minecraft:wool 1
setblock ~66~42~5 minecraft:planks 4
fill ~67~18~5 ~67~19~5 minecraft:wool 1
fill ~67~38~5 ~68~38~5 minecraft:planks 4
setblock ~67~39~5 minecraft:planks 4
setblock ~67~40~5 minecraft:wool 1
setblock ~68~20~5 minecraft:wool 1
setblock ~68~21~5 minecraft:planks 4
setblock ~68~37~5 minecraft:wool 1
fill ~69~24~5 ~69~25~5 minecraft:wool 1
setblock ~69~27~5 minecraft:wool 1
setblock ~69~31~5 minecraft:wool 1
fill ~69~33~5 ~69~35~5 minecraft:wool 1
setblock ~70~18~5 minecraft:planks 4
fill ~70~19~5 ~71~19~5 minecraft:wool 1
fill ~70~22~5 ~70~22~6 minecraft:stained_hardened_clay 12
fill ~70~24~5 ~70~25~5 minecraft:stained_hardened_clay 12
setblock ~70~26~5 minecraft:stained_hardened_clay 1
setblock ~70~28~5 minecraft:stained_hardened_clay 1
setblock ~70~29~5 minecraft:stained_hardened_clay 12
fill ~70~30~5 ~70~33~5 minecraft:stained_hardened_clay 1
setblock ~70~34~5 minecraft:stained_hardened_clay 12
fill ~70~36~5 ~70~36~6 minecraft:stained_hardened_clay 1
fill ~70~39~5 ~70~40~5 minecraft:wool 1
fill ~71~20~5 ~72~20~6 minecraft:wool 1
setblock ~71~21~5 minecraft:planks 4
fill ~71~23~5 ~73~24~5 minecraft:wool 1
setblock ~71~25~5 minecraft:planks 4
fill ~71~26~5 ~71~28~5 minecraft:wool 1
setblock ~71~31~5 minecraft:planks 4
fill ~71~33~5 ~71~34~5 minecraft:wool 1
setblock ~71~37~5 minecraft:planks 4
fill ~71~38~5 ~72~38~5 minecraft:wool 1
setblock ~71~39~5 minecraft:planks 4
fill ~72~21~5 ~72~22~6 minecraft:wool 1
setblock ~72~25~5 minecraft:wool 1
setblock ~72~34~5 minecraft:planks 4
fill ~72~35~5 ~73~36~6 minecraft:wool 1
fill ~72~37~5 ~72~37~6 minecraft:wool 1
fill ~73~22~5 ~73~22~6 minecraft:wool 1
setblock ~73~25~5 minecraft:planks 4
fill ~73~26~5 ~74~26~5 minecraft:wool 1
fill ~73~30~5 ~74~30~5 minecraft:planks 4
fill ~73~32~5 ~74~33~5 minecraft:wool 1
fill ~73~34~5 ~73~34~6 minecraft:wool 1
setblock ~74~25~5 minecraft:wool 1
fill ~74~27~5 ~74~27~6 minecraft:wool 1
fill ~74~28~5 ~75~29~5 minecraft:wool 1
fill ~74~31~5 ~74~31~6 minecraft:planks 4
fill ~75~30~5 ~75~30~6 minecraft:wool 1
fill ~29~29~6 ~30~29~6 minecraft:wool 1
fill ~30~26~6 ~32~26~6 minecraft:wool 1
fill ~30~27~6 ~30~28~6 minecraft:wool 1
setblock ~30~30~6 minecraft:planks 4
fill ~30~31~6 ~32~31~6 minecraft:wool 1
fill ~30~32~6 ~31~32~6 minecraft:wool 1
fill ~31~23~6 ~31~25~6 minecraft:wool 1
fill ~31~27~6 ~31~29~6 minecraft:planks 4
setblock ~31~30~6 minecraft:wool 1
fill ~31~33~6 ~32~33~6 minecraft:wool 1
setblock ~31~34~6 minecraft:planks 4
fill ~31~35~6 ~32~35~6 minecraft:wool 1
fill ~32~20~6 ~32~20~7 minecraft:wool 1
fill ~32~21~6 ~33~21~6 minecraft:planks 4
fill ~32~22~6 ~32~23~6 minecraft:planks 4
setblock ~32~24~6 minecraft:wool 1
fill ~32~28~6 ~36~30~6 minecraft:wool 15
setblock ~32~32~6 minecraft:planks 4
setblock ~32~34~6 minecraft:wool 1
fill ~32~36~6 ~33~36~6 minecraft:planks 4
fill ~32~37~6 ~34~37~6 minecraft:wool 1
fill ~32~38~6 ~33~38~6 minecraft:planks 4
setblock ~33~18~6 minecraft:planks 4
fill ~33~19~6 ~34~19~6 minecraft:wool 1
setblock ~33~20~6 minecraft:planks 4
setblock ~33~23~6 minecraft:wool 1
fill ~33~25~6 ~37~25~6 minecraft:wool 15
fill ~33~26~6 ~36~26~6 minecraft:wool 15
fill ~33~27~6 ~35~27~6 minecraft:wool 15
fill ~33~31~6 ~35~33~6 minecraft:wool 15
fill ~33~39~6 ~33~39~7 minecraft:planks 4
fill ~33~40~6 ~35~40~6 minecraft:wool 1
fill ~34~17~6 ~36~17~7 minecraft:wool 1
fill ~34~18~6 ~35~18~7 minecraft:wool 1
fill ~34~24~6 ~37~24~6 minecraft:wool 15
fill ~34~34~6 ~37~34~6 minecraft:wool 15
fill ~34~35~6 ~34~36~6 minecraft:wool 1
fill ~34~39~6 ~34~39~7 minecraft:wool 1
fill ~34~41~6 ~35~41~7 minecraft:wool 1
fill ~35~16~6 ~35~16~7 minecraft:wool 1
fill ~35~20~6 ~35~21~6 minecraft:planks 4
setblock ~35~22~6 minecraft:wool 1
setblock ~35~23~6 minecraft:planks 4
setblock ~35~36~6 minecraft:wool 1
fill ~35~42~6 ~35~42~7 minecraft:wool 1
setblock ~36~16~6 minecraft:planks 4
fill ~36~19~6 ~36~19~7 minecraft:wool 1
setblock ~36~20~6 minecraft:stained_hardened_clay 12
setblock ~36~21~6 minecraft:stained_hardened_clay 1
setblock ~36~23~6 minecraft:stained_hardened_clay 12
setblock ~36~27~6 minecraft:stained_hardened_clay 12
setblock ~36~31~6 minecraft:stained_hardened_clay 1
fill ~36~32~6 ~36~33~6 minecraft:wool 15
setblock ~36~35~6 minecraft:stained_hardened_clay 1
fill ~36~37~6 ~36~38~6 minecraft:stained_hardened_clay 1
fill ~36~39~6 ~36~39~7 minecraft:planks 4
fill ~36~41~6 ~36~41~7 minecraft:planks 4
setblock ~36~42~6 minecraft:planks 4
setblock ~37~18~6 minecraft:stained_hardened_clay 12
setblock ~37~20~6 minecraft:wool 1
fill ~37~21~6 ~37~22~6 minecraft:planks 4
fill ~37~23~6 ~52~23~6 minecraft:wool 15
setblock ~37~27~6 minecraft:wool 15
setblock ~37~31~6 minecraft:wool 15
setblock ~37~33~6 minecraft:wool 15
fill ~37~35~6 ~52~35~6 minecraft:wool 15
fill ~37~36~6 ~37~38~6 minecraft:wool 1
setblock ~37~40~6 minecraft:stained_hardened_clay 1
fill ~38~17~6 ~39~17~6 minecraft:wool 1
fill ~38~18~6 ~38~18~7 minecraft:wool 1
fill ~38~19~6 ~39~19~6 minecraft:wool 1
fill ~38~20~6 ~68~20~6 minecraft:wool 15
fill ~38~21~6 ~52~22~6 minecraft:wool 15
fill ~38~36~6 ~52~38~6 minecraft:wool 15
fill ~38~39~6 ~38~41~6 minecraft:wool 1
fill ~39~15~6 ~40~15~7 minecraft:wool 1
setblock ~39~16~6 minecraft:wool 1
fill ~39~41~6 ~39~43~7 minecraft:wool 1
fill ~40~14~6 ~41~14~7 minecraft:wool 1
fill ~40~19~6 ~42~19~6 minecraft:planks 4
fill ~40~39~6 ~41~39~6 minecraft:wool 1
fill ~40~43~6 ~40~43~7 minecraft:wool 1
fill ~40~44~6 ~41~44~6 minecraft:wool 1
fill ~41~13~6 ~43~13~6 minecraft:wool 1
setblock ~41~45~6 minecraft:planks 4
setblock ~42~12~6 minecraft:wool 1
setblock ~42~39~6 minecraft:planks 4
fill ~42~45~6 ~43~46~6 minecraft:wool 1
fill ~43~12~6 ~44~12~6 minecraft:planks 4
fill ~43~19~6 ~46~19~7 minecraft:wool 1
fill ~43~39~6 ~44~39~7 minecraft:wool 1
setblock ~44~46~6 minecraft:planks 4
fill ~45~11~6 ~46~12~6 minecraft:wool 1
setblock ~45~39~6 minecraft:planks 4
fill ~45~46~6 ~47~46~6 minecraft:wool 1
fill ~45~47~6 ~45~47~7 minecraft:wool 1
fill ~46~39~6 ~52~39~7 minecraft:wool 1
fill ~46~47~6 ~49~47~6 minecraft:planks 4
fill ~47~11~6 ~47~12~6 minecraft:planks 4
fill ~47~19~6 ~48~19~6 minecraft:planks 4
fill ~48~11~6 ~48~12~7 minecraft:wool 1
setblock ~48~46~6 minecraft:planks 4
fill ~49~11~6 ~49~11~7 minecraft:planks 4
setblock ~49~12~6 minecraft:wool 1
fill ~49~19~6 ~51~19~6 minecraft:wool 1
fill ~49~46~6 ~51~46~7 minecraft:wool 1
fill ~50~12~6 ~50~12~7 minecraft:planks 4
fill ~51~12~6 ~51~13~7 minecraft:wool 1
fill ~51~45~6 ~52~45~7 minecraft:wool 1
setblock ~52~13~6 minecraft:planks 4
fill ~52~14~6 ~52~14~7 minecraft:wool 1
fill ~52~17~6 ~52~18~7 minecraft:wool 1
setblock ~52~19~6 minecraft:planks 4
setblock ~52~40~6 minecraft:wool 1
setblock ~52~41~6 minecraft:planks 4
setblock ~52~44~6 minecraft:planks 4
fill ~53~14~6 ~53~16~6 minecraft:stained_hardened_clay 1
fill ~53~17~6 ~53~19~8 minecraft:wool 15
fill ~53~37~6 ~68~38~6 minecraft:wool 15
fill ~53~39~6 ~53~41~8 minecraft:wool 15
fill ~53~42~6 ~53~43~6 minecraft:stained_hardened_clay 1
setblock ~53~44~6 minecraft:stained_hardened_clay 12
fill ~54~13~6 ~54~14~7 minecraft:wool 1
fill ~54~17~6 ~54~19~7 minecraft:wool 1
fill ~54~21~6 ~68~23~6 minecraft:wool 15
fill ~54~35~6 ~69~35~6 minecraft:wool 15
fill ~54~36~6 ~68~36~6 minecraft:wool 15
fill ~54~39~6 ~56~39~6 minecraft:wool 1
setblock ~54~40~6 minecraft:planks 4
fill ~54~41~6 ~54~41~7 minecraft:wool 1
fill ~54~44~6 ~54~45~6 minecraft:wool 1
fill ~55~12~6 ~59~12~6 minecraft:wool 1
fill ~55~13~6 ~55~13~7 minecraft:planks 4
fill ~55~19~6 ~55~19~7 minecraft:wool 1
fill ~55~45~6 ~55~46~7 minecraft:wool 1
fill ~56~19~6 ~56~19~7 minecraft:planks 4
fill ~56~46~6 ~64~46~6 minecraft:wool 1
setblock ~57~11~6 minecraft:planks 4
setblock ~57~19~6 minecraft:wool 1
setblock ~57~39~6 minecraft:planks 4
fill ~57~47~6 ~61~47~6 minecraft:wool 1
fill ~58~11~6 ~61~11~6 minecraft:wool 1
setblock ~58~19~6 minecraft:planks 4
fill ~58~39~6 ~58~39~7 minecraft:wool 1
fill ~59~19~6 ~60~19~6 minecraft:wool 1
fill ~59~39~6 ~61~39~6 minecraft:planks 4
setblock ~60~12~6 minecraft:planks 4
fill ~61~12~6 ~62~12~7 minecraft:wool 1
setblock ~61~19~6 minecraft:planks 4
fill ~62~19~6 ~66~19~6 minecraft:wool 1
fill ~62~39~6 ~65~39~7 minecraft:wool 1
fill ~63~12~6 ~64~12~6 minecraft:planks 4
setblock ~63~13~6 minecraft:planks 4
fill ~63~45~6 ~65~45~6 minecraft:wool 1
fill ~64~13~6 ~65~13~6 minecraft:wool 1
setblock ~65~14~6 minecraft:wool 1
fill ~65~44~6 ~66~44~7 minecraft:wool 1
setblock ~66~14~6 minecraft:planks 4
fill ~66~15~6 ~67~15~6 minecraft:wool 1
setblock ~66~39~6 minecraft:planks 4
setblock ~66~43~6 minecraft:wool 1
fill ~67~16~6 ~67~16~7 minecraft:planks 4
fill ~67~17~6 ~68~17~6 minecraft:wool 1
fill ~67~19~6 ~67~19~7 minecraft:planks 4
fill ~67~39~6 ~68~39~7 minecraft:wool 1
fill ~67~41~6 ~68~41~6 minecraft:wool 1
fill ~67~42~6 ~67~42~7 minecraft:wool 1
fill ~67~43~6 ~67~43~7 minecraft:planks 4
fill ~68~18~6 ~68~19~7 minecraft:wool 1
fill ~68~40~6 ~68~40~7 minecraft:wool 1
fill ~69~18~6 ~69~18~7 minecraft:stained_hardened_clay 1
fill ~69~20~6 ~69~22~6 minecraft:wool 1
fill ~69~23~6 ~69~25~6 minecraft:wool 15
setblock ~69~27~6 minecraft:wool 15
setblock ~69~31~6 minecraft:wool 15
fill ~69~33~6 ~73~33~6 minecraft:wool 15
fill ~69~34~6 ~72~34~6 minecraft:wool 15
fill ~69~36~6 ~69~38~6 minecraft:wool 1
setblock ~69~40~6 minecraft:stained_hardened_clay 12
fill ~70~16~6 ~70~17~6 minecraft:wool 1
fill ~70~19~6 ~70~19~7 minecraft:wool 1
fill ~70~20~6 ~70~21~6 minecraft:stained_hardened_clay 1
setblock ~70~23~6 minecraft:stained_hardened_clay 12
fill ~70~24~6 ~72~26~6 minecraft:wool 15
setblock ~70~27~6 minecraft:stained_hardened_clay 1
fill ~70~28~6 ~74~30~6 minecraft:wool 15
setblock ~70~31~6 minecraft:stained_hardened_clay 12
fill ~70~32~6 ~73~32~6 minecraft:wool 15
setblock ~70~35~6 minecraft:stained_hardened_clay 12
setblock ~70~37~6 minecraft:stained_hardened_clay 1
setblock ~70~38~6 minecraft:stained_hardened_clay 12
fill ~70~39~6 ~70~39~7 minecraft:planks 4
fill ~70~41~6 ~70~42~7 minecraft:wool 1
fill ~71~16~6 ~71~16~7 minecraft:planks 4
fill ~71~17~6 ~72~18~6 minecraft:wool 1
fill ~71~21~6 ~71~22~6 minecraft:wool 1
fill ~71~23~6 ~72~23~6 minecraft:planks 4
fill ~71~27~6 ~73~27~6 minecraft:wool 15
fill ~71~31~6 ~73~31~6 minecraft:wool 15
setblock ~71~36~6 minecraft:planks 4
setblock ~71~37~6 minecraft:wool 1
setblock ~71~38~6 minecraft:planks 4
fill ~71~40~6 ~73~40~7 minecraft:wool 1
setblock ~71~41~6 minecraft:planks 4
setblock ~71~42~6 minecraft:wool 1
fill ~72~19~6 ~73~19~7 minecraft:wool 1
fill ~72~38~6 ~74~38~6 minecraft:wool 1
fill ~72~39~6 ~72~39~7 minecraft:wool 1
fill ~72~41~6 ~72~41~7 minecraft:wool 1
fill ~73~18~6 ~73~18~7 minecraft:wool 1
fill ~73~20~6 ~74~20~6 minecraft:wool 1
setblock ~73~21~6 minecraft:planks 4
fill ~73~23~6 ~75~24~6 minecraft:wool 1
fill ~73~25~6 ~73~26~6 minecraft:wool 15
fill ~73~37~6 ~74~37~6 minecraft:wool 1
setblock ~73~39~6 minecraft:planks 4
fill ~74~21~6 ~74~21~7 minecraft:wool 1
setblock ~74~22~6 minecraft:wool 1
setblock ~74~25~6 minecraft:planks 4
fill ~74~26~6 ~76~26~6 minecraft:wool 1
setblock ~74~32~6 minecraft:wool 1
fill ~74~33~6 ~74~34~6 minecraft:planks 4
fill ~74~35~6 ~75~35~6 minecraft:wool 1
setblock ~74~36~6 minecraft:wool 1
setblock ~75~25~6 minecraft:wool 1
setblock ~75~27~6 minecraft:planks 4
fill ~75~28~6 ~76~29~6 minecraft:wool 1
fill ~75~31~6 ~75~32~6 minecraft:planks 4
fill ~75~33~6 ~75~34~6 minecraft:wool 1
setblock ~76~27~6 minecraft:wool 1
fill ~76~30~6 ~76~32~6 minecraft:wool 1
setblock ~77~29~6 minecraft:wool 1
fill ~28~27~7 ~29~28~7 minecraft:wool 1
fill ~28~29~7 ~29~29~7 minecraft:planks 4
fill ~28~30~7 ~28~31~7 minecraft:planks 4
setblock ~29~24~7 minecraft:wool 1
setblock ~29~25~7 minecraft:planks 4
fill ~29~26~7 ~30~26~7 minecraft:wool 1
fill ~29~30~7 ~29~33~7 minecraft:wool 1
setblock ~29~34~7 minecraft:planks 4
fill ~30~21~7 ~32~21~7 minecraft:wool 1
setblock ~30~22~7 minecraft:planks 4
setblock ~30~23~7 minecraft:wool 1
setblock ~30~24~7 minecraft:planks 4
setblock ~30~25~7 minecraft:wool 1
fill ~30~27~7 ~32~27~8 minecraft:wool 15
fill ~30~28~7 ~31~31~8 minecraft:wool 15
setblock ~30~32~7 minecraft:wool 1
setblock ~30~33~7 minecraft:planks 4
setblock ~30~34~7 minecraft:wool 1
setblock ~30~35~7 minecraft:planks 4
fill ~30~36~7 ~31~37~7 minecraft:wool 1
fill ~31~18~7 ~33~18~7 minecraft:wool 1
fill ~31~19~7 ~32~19~7 minecraft:wool 1
setblock ~31~20~7 minecraft:wool 1
setblock ~31~22~7 minecraft:wool 1
setblock ~31~23~7 minecraft:planks 4
fill ~31~24~7 ~33~24~8 minecraft:wool 15
fill ~31~25~7 ~32~26~8 minecraft:wool 15
fill ~31~32~7 ~32~34~8 minecraft:wool 15
setblock ~31~35~7 minecraft:wool 1
fill ~31~38~7 ~31~40~7 minecraft:wool 1
fill ~32~16~7 ~34~16~8 minecraft:wool 1
fill ~32~17~7 ~33~17~7 minecraft:wool 1
fill ~32~22~7 ~37~22~8 minecraft:wool 15
fill ~32~23~7 ~36~23~8 minecraft:wool 15
fill ~32~31~7 ~32~31~8 minecraft:wool 15
fill ~32~35~7 ~36~36~8 minecraft:wool 15
setblock ~32~37~7 minecraft:wool 1
setblock ~32~38~7 minecraft:planks 4
fill ~32~39~7 ~32~41~7 minecraft:wool 1
setblock ~32~42~7 minecraft:planks 4
fill ~33~15~7 ~36~15~7 minecraft:wool 1
fill ~33~19~7 ~35~19~7 minecraft:planks 4
setblock ~33~20~7 minecraft:wool 1
fill ~33~21~7 ~37~21~8 minecraft:wool 15
fill ~33~34~7 ~33~34~8 minecraft:wool 15
fill ~33~37~7 ~37~37~8 minecraft:wool 15
setblock ~33~38~7 minecraft:wool 1
fill ~33~40~7 ~34~40~7 minecraft:wool 1
fill ~33~41~7 ~33~43~7 minecraft:wool 1
fill ~34~14~7 ~35~14~7 minecraft:wool 1
fill ~34~20~7 ~52~20~8 minecraft:wool 15
fill ~34~38~7 ~52~38~8 minecraft:wool 15
fill ~34~42~7 ~34~44~8 minecraft:wool 1
setblock ~35~39~7 minecraft:wool 1
fill ~35~40~7 ~36~40~7 minecraft:planks 4
fill ~35~43~7 ~36~44~7 minecraft:planks 4
fill ~36~13~7 ~36~13~8 minecraft:wool 1
setblock ~36~14~7 minecraft:planks 4
setblock ~36~16~7 minecraft:wool 1
setblock ~36~18~7 minecraft:planks 4
fill ~36~27~7 ~36~27~8 minecraft:wool 15
fill ~36~31~7 ~36~31~8 minecraft:wool 15
setblock ~36~42~7 minecraft:wool 1
fill ~36~45~7 ~36~45~8 minecraft:wool 1
fill ~37~16~7 ~37~19~7 minecraft:stained_hardened_clay 1
fill ~37~36~7 ~37~36~8 minecraft:wool 15
setblock ~37~39~7 minecraft:stained_hardened_clay 1
setblock ~37~40~7 minecraft:stained_hardened_clay 12
fill ~37~41~7 ~37~42~7 minecraft:stained_hardened_clay 1
fill ~38~15~7 ~38~15~8 minecraft:wool 1
fill ~38~16~7 ~39~17~7 minecraft:planks 4
setblock ~38~19~7 minecraft:planks 4
fill ~38~39~7 ~38~40~7 minecraft:planks 4
fill ~38~41~7 ~38~43~7 minecraft:wool 1
fill ~39~13~7 ~39~13~8 minecraft:wool 1
setblock ~39~14~7 minecraft:wool 1
fill ~39~18~7 ~43~18~7 minecraft:wool 1
fill ~39~19~7 ~42~19~7 minecraft:wool 1
setblock ~39~40~7 minecraft:planks 4
fill ~39~44~7 ~39~45~7 minecraft:wool 1
setblock ~40~12~7 minecraft:wool 1
fill ~40~13~7 ~41~13~7 minecraft:planks 4
fill ~40~16~7 ~44~16~7 minecraft:wool 1
fill ~40~17~7 ~41~17~7 minecraft:wool 1
setblock ~40~39~7 minecraft:planks 4
fill ~40~40~7 ~41~41~7 minecraft:wool 1
setblock ~40~42~7 minecraft:planks 4
fill ~40~44~7 ~40~45~7 minecraft:planks 4
setblock ~40~46~7 minecraft:wool 1
fill ~41~11~7 ~41~11~8 minecraft:wool 1
fill ~41~12~7 ~42~12~7 minecraft:planks 4
fill ~41~15~7 ~45~15~7 minecraft:wool 1
fill ~41~39~7 ~42~39~7 minecraft:wool 1
fill ~41~42~7 ~42~43~7 minecraft:wool 1
fill ~41~44~7 ~41~45~7 minecraft:wool 1
setblock ~41~46~7 minecraft:planks 4
fill ~41~47~7 ~44~47~7 minecraft:wool 1
setblock ~42~11~7 minecraft:planks 4
fill ~42~13~7 ~45~13~7 minecraft:wool 1
fill ~42~14~7 ~43~14~7 minecraft:wool 1
setblock ~42~17~7 minecraft:planks 4
setblock ~42~40~7 minecraft:planks 4
setblock ~42~41~7 minecraft:wool 1
fill ~42~44~7 ~42~45~7 minecraft:planks 4
fill ~42~46~7 ~45~46~7 minecraft:wool 1
fill ~43~10~7 ~43~12~7 minecraft:wool 1
fill ~43~17~7 ~51~17~7 minecraft:wool 1
setblock ~43~40~7 minecraft:wool 1
fill ~43~41~7 ~44~42~7 minecraft:planks 4
fill ~43~43~7 ~50~44~7 minecraft:wool 1
fill ~43~45~7 ~49~45~7 minecraft:wool 1
fill ~43~48~7 ~45~48~8 minecraft:wool 1
setblock ~44~10~7 minecraft:planks 4
fill ~44~11~7 ~45~12~7 minecraft:wool 1
fill ~44~14~7 ~46~14~7 minecraft:planks 4
setblock ~44~18~7 minecraft:planks 4
setblock ~44~40~7 minecraft:planks 4
fill ~45~10~7 ~46~10~7 minecraft:wool 1
setblock ~45~16~7 minecraft:planks 4
fill ~45~18~7 ~48~18~7 minecraft:wool 1
fill ~45~39~7 ~45~42~7 minecraft:wool 1
setblock ~46~9~7 minecraft:planks 4
setblock ~46~11~7 minecraft:planks 4
fill ~46~12~7 ~47~12~7 minecraft:wool 1
setblock ~46~13~7 minecraft:planks 4
setblock ~46~15~7 minecraft:planks 4
fill ~46~16~7 ~48~16~7 minecraft:wool 1
fill ~46~40~7 ~47~40~7 minecraft:wool 1
fill ~46~41~7 ~46~42~7 minecraft:wool 1
setblock ~46~46~7 minecraft:planks 4
fill ~46~47~7 ~48~47~7 minecraft:wool 1
setblock ~46~48~7 minecraft:planks 4
fill ~46~49~7 ~49~49~8 minecraft:wool 1
fill ~47~9~7 ~47~9~8 minecraft:wool 1
setblock ~47~10~7 minecraft:planks 4
setblock ~47~11~7 minecraft:wool 1
fill ~47~13~7 ~50~15~7 minecraft:wool 1
fill ~47~19~7 ~48~19~7 minecraft:wool 1
fill ~47~41~7 ~48~42~7 minecraft:planks 4
fill ~47~46~7 ~48~46~7 minecraft:wool 1
fill ~47~48~7 ~51~48~7 minecraft:wool 1
fill ~48~9~7 ~48~9~8 minecraft:planks 4
fill ~48~10~7 ~50~10~7 minecraft:wool 1
fill ~48~40~7 ~49~40~7 minecraft:planks 4
fill ~49~9~7 ~49~9~8 minecraft:wool 1
setblock ~49~12~7 minecraft:planks 4
setblock ~49~16~7 minecraft:planks 4
fill ~49~18~7 ~51~18~7 minecraft:planks 4
setblock ~49~19~7 minecraft:planks 4
fill ~49~41~7 ~49~42~7 minecraft:wool 1
setblock ~49~47~7 minecraft:planks 4
setblock ~50~11~7 minecraft:planks 4
setblock ~50~16~7 minecraft:wool 1
fill ~50~19~7 ~52~19~7 minecraft:wool 1
fill ~50~40~7 ~51~40~7 minecraft:wool 1
fill ~50~41~7 ~50~42~7 minecraft:planks 4
setblock ~50~45~7 minecraft:planks 4
fill ~50~47~7 ~52~47~7 minecraft:wool 1
fill ~51~10~7 ~51~10~8 minecraft:planks 4
fill ~51~11~7 ~52~11~7 minecraft:wool 1
fill ~51~14~7 ~51~16~7 minecraft:planks 4
fill ~51~41~7 ~52~42~7 minecraft:wool 1
fill ~51~43~7 ~51~44~7 minecraft:planks 4
setblock ~52~12~7 minecraft:planks 4
setblock ~52~13~7 minecraft:wool 1
setblock ~52~15~7 minecraft:planks 4
setblock ~52~16~7 minecraft:wool 1
setblock ~52~40~7 minecraft:planks 4
fill ~52~43~7 ~52~44~7 minecraft:wool 1
setblock ~52~46~7 minecraft:wool 1
setblock ~53~12~7 minecraft:stained_hardened_clay 1
setblock ~53~13~7 minecraft:stained_hardened_clay 12
fill ~53~14~7 ~53~16~8 minecraft:wool 15
fill ~53~42~7 ~53~44~8 minecraft:wool 15
fill ~53~45~7 ~53~46~7 minecraft:stained_hardened_clay 1
fill ~54~11~7 ~54~12~7 minecraft:planks 4
fill ~54~15~7 ~57~15~7 minecraft:wool 1
fill ~54~16~7 ~55~16~7 minecraft:wool 1
fill ~54~20~7 ~72~20~8 minecraft:wool 15
fill ~54~38~7 ~72~38~8 minecraft:wool 15
fill ~54~39~7 ~55~39~7 minecraft:planks 4
fill ~54~40~7 ~55~40~7 minecraft:wool 1
fill ~54~42~7 ~59~42~7 minecraft:wool 1
fill ~54~43~7 ~55~43~7 minecraft:wool 1
setblock ~54~44~7 minecraft:planks 4
fill ~54~45~7 ~54~46~7 minecraft:wool 1
setblock ~54~47~7 minecraft:planks 4
fill ~55~10~7 ~63~10~7 minecraft:wool 1
fill ~55~11~7 ~55~12~7 minecraft:wool 1
fill ~55~14~7 ~57~14~7 minecraft:wool 1
fill ~55~17~7 ~58~18~7 minecraft:wool 1
fill ~55~41~7 ~66~41~7 minecraft:wool 1
fill ~55~44~7 ~56~44~7 minecraft:wool 1
fill ~55~47~7 ~57~47~7 minecraft:wool 1
setblock ~55~48~7 minecraft:wool 1
fill ~56~11~7 ~56~12~7 minecraft:planks 4
fill ~56~13~7 ~63~13~7 minecraft:wool 1
setblock ~56~16~7 minecraft:planks 4
fill ~56~39~7 ~57~39~7 minecraft:wool 1
fill ~56~40~7 ~58~40~7 minecraft:planks 4
fill ~56~43~7 ~57~43~7 minecraft:planks 4
fill ~56~45~7 ~56~46~7 minecraft:wool 1
fill ~56~48~7 ~57~48~7 minecraft:planks 4
fill ~57~9~7 ~60~9~8 minecraft:wool 1
fill ~57~11~7 ~59~11~7 minecraft:wool 1
setblock ~57~12~7 minecraft:planks 4
fill ~57~16~7 ~59~16~7 minecraft:wool 1
setblock ~57~19~7 minecraft:planks 4
fill ~57~44~7 ~57~45~7 minecraft:planks 4
setblock ~57~46~7 minecraft:wool 1
fill ~57~49~7 ~60~49~8 minecraft:wool 1
fill ~58~12~7 ~60~12~7 minecraft:wool 1
fill ~58~14~7 ~61~14~7 minecraft:planks 4
setblock ~58~15~7 minecraft:planks 4
setblock ~58~19~7 minecraft:wool 1
fill ~58~43~7 ~59~44~7 minecraft:wool 1
fill ~58~45~7 ~58~47~7 minecraft:planks 4
fill ~58~48~7 ~63~48~7 minecraft:wool 1
fill ~59~15~7 ~61~15~7 minecraft:wool 1
setblock ~59~17~7 minecraft:planks 4
fill ~59~18~7 ~61~18~7 minecraft:wool 1
fill ~59~19~7 ~60~19~7 minecraft:planks 4
fill ~59~39~7 ~60~39~7 minecraft:wool 1
setblock ~59~40~7 minecraft:wool 1
fill ~59~45~7 ~59~47~7 minecraft:wool 1
setblock ~60~11~7 minecraft:planks 4
setblock ~60~16~7 minecraft:planks 4
setblock ~60~17~7 minecraft:wool 1
setblock ~60~40~7 minecraft:planks 4
fill ~60~42~7 ~61~42~7 minecraft:planks 4
fill ~60~43~7 ~60~47~7 minecraft:planks 4
fill ~61~11~7 ~62~11~7 minecraft:wool 1
fill ~61~16~7 ~63~16~7 minecraft:wool 1
fill ~61~17~7 ~62~17~7 minecraft:planks 4
setblock ~61~19~7 minecraft:wool 1
setblock ~61~39~7 minecraft:planks 4
fill ~61~40~7 ~67~40~7 minecraft:wool 1
fill ~61~43~7 ~65~43~7 minecraft:wool 1
fill ~61~44~7 ~64~44~7 minecraft:wool 1
setblock ~61~45~7 minecraft:planks 4
fill ~61~46~7 ~62~47~7 minecraft:wool 1
fill ~62~14~7 ~64~14~7 minecraft:wool 1
setblock ~62~15~7 minecraft:planks 4
fill ~62~18~7 ~62~19~7 minecraft:planks 4
fill ~62~42~7 ~64~42~7 minecraft:wool 1
setblock ~62~45~7 minecraft:wool 1
setblock ~63~11~7 minecraft:planks 4
fill ~63~12~7 ~66~12~7 minecraft:wool 1
fill ~63~15~7 ~65~15~7 minecraft:wool 1
fill ~63~17~7 ~64~18~7 minecraft:wool 1
setblock ~63~19~7 minecraft:planks 4
fill ~63~45~7 ~63~46~7 minecraft:planks 4
setblock ~63~47~7 minecraft:wool 1
setblock ~64~11~7 minecraft:wool 1
setblock ~64~13~7 minecraft:planks 4
setblock ~64~16~7 minecraft:planks 4
fill ~64~19~7 ~66~19~7 minecraft:wool 1
fill ~64~45~7 ~67~45~7 minecraft:wool 1
fill ~64~46~7 ~66~46~7 minecraft:wool 1
setblock ~64~47~7 minecraft:planks 4
setblock ~65~11~7 minecraft:planks 4
fill ~65~13~7 ~67~13~7 minecraft:wool 1
setblock ~65~14~7 minecraft:planks 4
fill ~65~16~7 ~66~16~7 minecraft:wool 1
setblock ~65~17~7 minecraft:planks 4
fill ~65~18~7 ~67~18~7 minecraft:wool 1
setblock ~65~42~7 minecraft:planks 4
fill ~65~47~7 ~65~47~8 minecraft:wool 1
setblock ~66~14~7 minecraft:wool 1
setblock ~66~15~7 minecraft:planks 4
setblock ~66~17~7 minecraft:wool 1
setblock ~66~39~7 minecraft:wool 1
setblock ~66~42~7 minecraft:wool 1
setblock ~66~43~7 minecraft:planks 4
setblock ~67~14~7 minecraft:planks 4
fill ~67~15~7 ~68~15~7 minecraft:wool 1
setblock ~67~17~7 minecraft:planks 4
setblock ~67~41~7 minecraft:planks 4
setblock ~67~44~7 minecraft:wool 1
fill ~68~16~7 ~68~17~7 minecraft:wool 1
setblock ~68~41~7 minecraft:wool 1
fill ~68~42~7 ~68~43~7 minecraft:planks 4
setblock ~69~16~7 minecraft:stained_hardened_clay 12
setblock ~69~17~7 minecraft:stained_hardened_clay 1
setblock ~69~19~7 minecraft:stained_hardened_clay 12
fill ~69~21~7 ~73~22~8 minecraft:wool 15
fill ~69~36~7 ~74~36~8 minecraft:wool 15
fill ~69~37~7 ~73~37~8 minecraft:wool 15
setblock ~69~39~7 minecraft:stained_hardened_clay 12
fill ~69~40~7 ~69~42~7 minecraft:stained_hardened_clay 1
setblock ~70~13~7 minecraft:planks 4
fill ~70~14~7 ~72~14~7 minecraft:wool 1
fill ~70~15~7 ~71~15~7 minecraft:wool 1
setblock ~70~16~7 minecraft:planks 4
setblock ~70~17~7 minecraft:wool 1
setblock ~70~18~7 minecraft:planks 4
fill ~70~23~7 ~74~23~8 minecraft:wool 15
fill ~70~27~7 ~70~27~8 minecraft:wool 15
fill ~70~31~7 ~70~31~8 minecraft:wool 15
fill ~70~35~7 ~74~35~8 minecraft:wool 15
setblock ~70~40~7 minecraft:wool 1
fill ~70~43~7 ~70~43~8 minecraft:wool 1
fill ~70~44~7 ~71~44~7 minecraft:planks 4
setblock ~70~45~7 minecraft:planks 4
fill ~71~17~7 ~72~17~7 minecraft:planks 4
fill ~71~18~7 ~71~19~7 minecraft:wool 1
setblock ~71~39~7 minecraft:wool 1
setblock ~71~41~7 minecraft:wool 1
fill ~71~42~7 ~71~43~7 minecraft:planks 4
setblock ~72~15~7 minecraft:planks 4
fill ~72~16~7 ~72~16~8 minecraft:wool 1
setblock ~72~18~7 minecraft:planks 4
fill ~72~42~7 ~74~42~7 minecraft:wool 1
fill ~72~43~7 ~72~44~7 minecraft:wool 1
fill ~73~15~7 ~73~15~8 minecraft:wool 1
fill ~73~16~7 ~73~16~8 minecraft:planks 4
fill ~73~17~7 ~74~17~7 minecraft:wool 1
fill ~73~20~7 ~75~20~7 minecraft:planks 4
fill ~73~24~7 ~75~24~8 minecraft:wool 15
fill ~73~34~7 ~75~34~8 minecraft:wool 15
fill ~73~38~7 ~74~38~7 minecraft:planks 4
fill ~73~39~7 ~74~39~7 minecraft:wool 1
fill ~73~41~7 ~74~41~7 minecraft:wool 1
fill ~73~43~7 ~73~43~8 minecraft:planks 4
fill ~74~16~7 ~74~16~8 minecraft:wool 1
fill ~74~18~7 ~75~19~7 minecraft:wool 1
fill ~74~22~7 ~74~22~8 minecraft:wool 15
fill ~74~25~7 ~75~27~8 minecraft:wool 15
fill ~74~31~7 ~76~31~8 minecraft:wool 15
fill ~74~32~7 ~75~33~8 minecraft:wool 15
fill ~74~37~7 ~75~37~7 minecraft:wool 1
setblock ~74~40~7 minecraft:planks 4
fill ~75~21~7 ~76~23~7 minecraft:wool 1
fill ~75~28~7 ~76~30~8 minecraft:wool 15
fill ~75~35~7 ~75~36~7 minecraft:planks 4
setblock ~75~38~7 minecraft:wool 1
setblock ~75~39~7 minecraft:planks 4
fill ~75~40~7 ~75~40~8 minecraft:wool 1
setblock ~76~24~7 minecraft:wool 1
setblock ~76~25~7 minecraft:planks 4
fill ~76~26~7 ~77~26~7 minecraft:wool 1
fill ~76~27~7 ~76~27~8 minecraft:wool 15
fill ~76~32~7 ~77~32~7 minecraft:wool 1
setblock ~76~33~7 minecraft:planks 4
fill ~76~34~7 ~77~34~7 minecraft:wool 1
setblock ~76~35~7 minecraft:wool 1
fill ~76~36~7 ~76~37~7 minecraft:planks 4
setblock ~77~24~7 minecraft:planks 4
setblock ~77~25~7 minecraft:wool 1
fill ~77~27~7 ~78~28~7 minecraft:wool 1
setblock ~77~29~7 minecraft:planks 4
fill ~77~30~7 ~78~30~7 minecraft:wool 1
setblock ~77~31~7 minecraft:wool 1
setblock ~77~33~7 minecraft:wool 1
setblock ~78~29~7 minecraft:wool 1
setblock ~78~31~7 minecraft:planks 4
fill ~27~25~8 ~28~26~8 minecraft:wool 1
fill ~27~27~8 ~27~28~8 minecraft:planks 4
fill ~27~29~8 ~27~30~8 minecraft:wool 1
fill ~27~31~8 ~27~32~8 minecraft:planks 4
fill ~27~33~8 ~28~33~8 minecraft:wool 1
fill ~28~22~8 ~28~23~8 minecraft:wool 1
setblock ~28~24~8 minecraft:planks 4
fill ~28~27~8 ~29~31~8 minecraft:wool 15
setblock ~28~32~8 minecraft:wool 1
fill ~28~34~8 ~28~36~8 minecraft:wool 1
fill ~29~19~8 ~30~19~8 minecraft:wool 1
setblock ~29~20~8 minecraft:planks 4
setblock ~29~21~8 minecraft:wool 1
setblock ~29~22~8 minecraft:planks 4
setblock ~29~23~8 minecraft:wool 1
fill ~29~24~8 ~30~26~8 minecraft:wool 15
fill ~29~32~8 ~30~34~8 minecraft:wool 15
fill ~29~35~8 ~29~38~8 minecraft:wool 1
fill ~29~39~8 ~30~39~8 minecraft:planks 4
fill ~30~17~8 ~31~18~8 minecraft:wool 1
setblock ~30~20~8 minecraft:wool 1
fill ~30~21~8 ~32~21~8 minecraft:wool 15
fill ~30~22~8 ~31~23~8 minecraft:wool 15
fill ~30~35~8 ~31~37~8 minecraft:wool 15
setblock ~30~38~8 minecraft:wool 1
fill ~30~40~8 ~31~41~8 minecraft:wool 1
fill ~31~15~8 ~32~15~8 minecraft:wool 1
setblock ~31~16~8 minecraft:wool 1
fill ~31~19~8 ~52~19~8 minecraft:wool 15
fill ~31~20~8 ~33~20~8 minecraft:wool 15
fill ~31~38~8 ~33~39~8 minecraft:wool 15
setblock ~31~42~8 minecraft:planks 4
fill ~31~43~8 ~33~43~8 minecraft:wool 1
fill ~32~14~8 ~33~14~8 minecraft:planks 4
setblock ~32~17~8 minecraft:planks 4
fill ~32~18~8 ~52~18~8 minecraft:wool 15
fill ~32~28~8 ~74~30~8 minecraft:wool 15
setblock ~32~37~8 minecraft:wool 15
fill ~32~40~8 ~52~40~8 minecraft:wool 15
setblock ~32~41~8 minecraft:planks 4
setblock ~32~42~8 minecraft:wool 1
fill ~32~44~8 ~32~44~9 minecraft:wool 1
fill ~33~13~8 ~34~13~8 minecraft:planks 4
fill ~33~15~8 ~34~15~8 minecraft:planks 4
fill ~33~17~8 ~52~17~8 minecraft:wool 15
fill ~33~25~8 ~73~26~8 minecraft:wool 15
fill ~33~27~8 ~35~27~8 minecraft:wool 15
fill ~33~31~8 ~35~33~8 minecraft:wool 15
fill ~33~41~8 ~52~41~8 minecraft:wool 15
setblock ~33~42~8 minecraft:planks 4
fill ~33~44~8 ~33~45~8 minecraft:planks 4
fill ~34~12~8 ~35~12~8 minecraft:wool 1
setblock ~34~14~8 minecraft:wool 1
fill ~34~24~8 ~72~24~8 minecraft:wool 15
fill ~34~34~8 ~72~34~8 minecraft:wool 15
fill ~34~39~8 ~52~39~8 minecraft:wool 15
fill ~34~45~8 ~34~46~9 minecraft:wool 1
setblock ~35~13~8 minecraft:wool 1
setblock ~35~14~8 minecraft:planks 4
fill ~35~15~8 ~36~15~8 minecraft:wool 1
fill ~35~16~8 ~52~16~8 minecraft:wool 15
fill ~35~42~8 ~52~42~8 minecraft:wool 15
fill ~35~43~8 ~36~44~8 minecraft:wool 1
setblock ~35~45~8 minecraft:planks 4
fill ~35~46~8 ~37~46~8 minecraft:wool 1
fill ~36~11~8 ~36~11~9 minecraft:wool 1
fill ~36~12~8 ~37~12~8 minecraft:planks 4
setblock ~36~14~8 minecraft:wool 1
fill ~36~32~8 ~73~33~8 minecraft:wool 15
setblock ~36~47~8 minecraft:wool 1
setblock ~37~11~8 minecraft:planks 4
setblock ~37~13~8 minecraft:stained_hardened_clay 12
fill ~37~14~8 ~37~15~8 minecraft:stained_hardened_clay 1
fill ~37~23~8 ~69~23~8 minecraft:wool 15
fill ~37~27~8 ~69~27~8 minecraft:wool 15
fill ~37~31~8 ~69~31~8 minecraft:wool 15
fill ~37~35~8 ~69~35~8 minecraft:wool 15
fill ~37~43~8 ~37~45~8 minecraft:stained_hardened_clay 12
setblock ~37~47~8 minecraft:planks 4
fill ~38~12~8 ~38~12~9 minecraft:stained_hardened_clay 12
fill ~38~13~8 ~38~14~8 minecraft:wool 1
fill ~38~21~8 ~68~22~8 minecraft:wool 15
fill ~38~36~8 ~68~37~8 minecraft:wool 15
fill ~38~43~8 ~38~44~8 minecraft:wool 1
fill ~38~45~8 ~39~45~8 minecraft:planks 4
setblock ~38~46~8 minecraft:stained_hardened_clay 12
fill ~39~11~8 ~40~11~8 minecraft:wool 1
setblock ~39~12~8 minecraft:wool 1
fill ~39~14~8 ~52~15~8 minecraft:wool 15
fill ~39~43~8 ~52~44~8 minecraft:wool 15
fill ~39~46~8 ~39~47~8 minecraft:wool 1
fill ~40~10~8 ~40~10~9 minecraft:wool 1
fill ~40~12~8 ~66~13~8 minecraft:wool 15
fill ~40~45~8 ~66~46~8 minecraft:wool 15
setblock ~40~47~8 minecraft:planks 4
fill ~40~48~8 ~42~48~8 minecraft:wool 1
fill ~41~9~8 ~46~9~8 minecraft:wool 1
fill ~41~10~8 ~43~10~8 minecraft:planks 4
setblock ~41~47~8 minecraft:wool 1
setblock ~41~49~8 minecraft:planks 4
fill ~42~11~8 ~51~11~8 minecraft:wool 15
fill ~42~47~8 ~51~47~8 minecraft:wool 15
fill ~42~49~8 ~45~49~8 minecraft:wool 1
fill ~44~8~8 ~45~8~8 minecraft:planks 4
fill ~44~10~8 ~45~10~8 minecraft:wool 1
fill ~44~50~8 ~44~50~9 minecraft:wool 1
setblock ~45~50~8 minecraft:planks 4
fill ~46~8~8 ~46~8~9 minecraft:wool 1
fill ~46~10~8 ~49~10~8 minecraft:wool 15
fill ~46~48~8 ~49~48~8 minecraft:wool 15
fill ~46~50~8 ~51~50~8 minecraft:wool 1
fill ~47~7~8 ~47~8~9 minecraft:planks 4
fill ~47~51~8 ~48~51~9 minecraft:wool 1
fill ~48~7~8 ~48~7~9 minecraft:wool 1
fill ~48~8~8 ~51~8~8 minecraft:wool 1
fill ~50~9~8 ~51~9~8 minecraft:planks 4
setblock ~50~10~8 minecraft:wool 1
fill ~50~48~8 ~51~48~8 minecraft:planks 4
fill ~50~49~8 ~52~49~8 minecraft:wool 1
fill ~52~9~8 ~52~9~9 minecraft:wool 1
setblock ~52~10~8 minecraft:planks 4
setblock ~52~11~8 minecraft:wool 1
setblock ~52~47~8 minecraft:planks 4
setblock ~52~48~8 minecraft:wool 1
setblock ~53~10~8 minecraft:stained_hardened_clay 12
setblock ~53~11~8 minecraft:stained_hardened_clay 1
setblock ~53~20~8 minecraft:wool 15
setblock ~53~38~8 minecraft:wool 15
fill ~53~47~8 ~53~48~8 minecraft:stained_hardened_clay 12
fill ~54~9~8 ~56~10~8 minecraft:wool 1
setblock ~54~11~8 minecraft:wool 1
fill ~54~14~8 ~67~19~8 minecraft:wool 15
fill ~54~39~8 ~75~39~8 minecraft:wool 15
fill ~54~40~8 ~74~40~8 minecraft:wool 15
fill ~54~41~8 ~73~41~8 minecraft:wool 15
fill ~54~42~8 ~71~42~8 minecraft:wool 15
fill ~54~43~8 ~67~44~8 minecraft:wool 15
fill ~54~47~8 ~54~49~8 minecraft:wool 1
fill ~55~8~8 ~56~8~8 minecraft:planks 4
fill ~55~11~8 ~64~11~8 minecraft:wool 15
fill ~55~47~8 ~64~47~8 minecraft:wool 15
fill ~55~48~8 ~56~48~8 minecraft:planks 4
fill ~55~49~8 ~56~50~8 minecraft:wool 1
fill ~57~8~8 ~59~8~8 minecraft:wool 1
fill ~57~10~8 ~60~10~8 minecraft:wool 15
fill ~57~48~8 ~60~48~8 minecraft:wool 15
fill ~57~50~8 ~62~50~9 minecraft:wool 1
setblock ~58~7~8 minecraft:wool 1
fill ~58~51~8 ~58~51~9 minecraft:wool 1
setblock ~59~7~8 minecraft:planks 4
fill ~59~51~8 ~59~51~9 minecraft:planks 4
fill ~60~8~8 ~60~8~9 minecraft:planks 4
fill ~61~8~8 ~61~8~9 minecraft:wool 1
fill ~61~9~8 ~63~10~8 minecraft:wool 1
fill ~61~48~8 ~66~48~8 minecraft:wool 1
setblock ~61~49~8 minecraft:planks 4
setblock ~62~8~8 minecraft:planks 4
fill ~62~49~8 ~65~49~8 minecraft:wool 1
fill ~64~9~8 ~64~9~9 minecraft:planks 4
fill ~64~10~8 ~66~10~8 minecraft:wool 1
setblock ~65~9~8 minecraft:wool 1
fill ~65~11~8 ~67~11~8 minecraft:wool 1
setblock ~66~47~8 minecraft:planks 4
fill ~67~12~8 ~67~13~8 minecraft:wool 1
fill ~67~45~8 ~68~45~8 minecraft:wool 1
fill ~67~46~8 ~67~47~8 minecraft:wool 1
setblock ~68~12~8 minecraft:stained_hardened_clay 12
setblock ~68~13~8 minecraft:planks 4
setblock ~68~14~8 minecraft:wool 1
setblock ~68~15~8 minecraft:planks 4
fill ~68~16~8 ~71~19~8 minecraft:wool 15
fill ~68~43~8 ~68~44~8 minecraft:wool 1
fill ~68~46~8 ~68~46~9 minecraft:stained_hardened_clay 1
fill ~69~11~8 ~70~11~8 minecraft:wool 1
setblock ~69~12~8 minecraft:planks 4
setblock ~69~13~8 minecraft:stained_hardened_clay 1
fill ~69~14~8 ~69~15~8 minecraft:stained_hardened_clay 12
fill ~69~43~8 ~69~45~8 minecraft:stained_hardened_clay 1
fill ~69~46~8 ~72~46~8 minecraft:wool 1
fill ~69~47~8 ~70~47~9 minecraft:wool 1
fill ~70~12~8 ~72~12~8 minecraft:wool 1
fill ~70~13~8 ~71~13~8 minecraft:wool 1
setblock ~70~14~8 minecraft:planks 4
setblock ~70~15~8 minecraft:wool 1
fill ~70~44~8 ~73~44~8 minecraft:wool 1
fill ~70~45~8 ~71~45~8 minecraft:wool 1
fill ~71~14~8 ~74~14~8 minecraft:wool 1
setblock ~71~15~8 minecraft:planks 4
fill ~71~27~8 ~73~27~8 minecraft:wool 15
fill ~71~31~8 ~73~31~8 minecraft:wool 15
setblock ~71~43~8 minecraft:wool 1
setblock ~72~13~8 minecraft:planks 4
setblock ~72~15~8 minecraft:wool 1
fill ~72~17~8 ~73~19~8 minecraft:wool 15
fill ~72~42~8 ~72~43~8 minecraft:planks 4
setblock ~72~45~8 minecraft:planks 4
fill ~73~13~8 ~73~13~9 minecraft:wool 1
fill ~73~20~8 ~75~20~8 minecraft:wool 15
fill ~73~38~8 ~75~38~8 minecraft:wool 15
setblock ~73~42~8 minecraft:wool 1
fill ~73~45~8 ~73~45~9 minecraft:wool 1
fill ~74~15~8 ~75~15~8 minecraft:wool 1
setblock ~74~17~8 minecraft:wool 1
fill ~74~18~8 ~74~19~8 minecraft:wool 15
fill ~74~21~8 ~76~21~8 minecraft:wool 15
fill ~74~37~8 ~76~37~8 minecraft:wool 15
setblock ~74~41~8 minecraft:wool 1
setblock ~74~42~8 minecraft:planks 4
fill ~74~43~8 ~75~43~8 minecraft:wool 1
setblock ~74~44~8 minecraft:planks 4
fill ~75~16~8 ~75~18~8 minecraft:planks 4
setblock ~75~19~8 minecraft:wool 15
fill ~75~22~8 ~76~23~8 minecraft:wool 15
fill ~75~35~8 ~76~36~8 minecraft:wool 15
setblock ~75~41~8 minecraft:planks 4
setblock ~75~42~8 minecraft:wool 1
setblock ~76~17~8 minecraft:planks 4
fill ~76~18~8 ~76~20~8 minecraft:wool 1
fill ~76~24~8 ~77~26~8 minecraft:wool 15
fill ~76~32~8 ~77~34~8 minecraft:wool 15
fill ~76~38~8 ~77~38~8 minecraft:planks 4
setblock ~76~39~8 minecraft:planks 4
fill ~76~40~8 ~76~41~8 minecraft:wool 1
setblock ~77~19~8 minecraft:wool 1
fill ~77~20~8 ~77~22~8 minecraft:planks 4
fill ~77~23~8 ~78~23~8 minecraft:wool 1
fill ~77~27~8 ~78~31~8 minecraft:wool 15
fill ~77~35~8 ~78~36~8 minecraft:wool 1
setblock ~77~37~8 minecraft:wool 1
setblock ~77~39~8 minecraft:wool 1
setblock ~78~22~8 minecraft:wool 1
fill ~78~24~8 ~78~25~8 minecraft:wool 1
setblock ~78~26~8 minecraft:planks 4
setblock ~78~32~8 minecraft:planks 4
fill ~78~33~8 ~79~33~8 minecraft:wool 1
setblock ~78~34~8 minecraft:wool 1
fill ~79~25~8 ~79~26~8 minecraft:wool 1
setblock ~79~27~8 minecraft:planks 4
fill ~79~28~8 ~79~30~8 minecraft:wool 1
setblock ~79~31~8 minecraft:planks 4
setblock ~79~32~8 minecraft:wool 1
fill ~26~24~9 ~27~24~9 minecraft:wool 1
fill ~26~25~9 ~26~25~10 minecraft:wool 1
fill ~26~26~9 ~26~30~9 minecraft:wool 1
fill ~26~31~9 ~26~32~9 minecraft:planks 4
fill ~26~33~9 ~26~33~10 minecraft:wool 1
fill ~26~34~9 ~26~34~10 minecraft:planks 4
fill ~27~21~9 ~28~21~9 minecraft:planks 4
setblock ~27~22~9 minecraft:wool 1
setblock ~27~23~9 minecraft:planks 4
fill ~27~25~9 ~28~26~9 minecraft:wool 15
fill ~27~27~9 ~27~33~9 minecraft:wool 15
fill ~27~34~9 ~27~37~9 minecraft:wool 1
setblock ~28~18~9 minecraft:planks 4
fill ~28~19~9 ~28~20~9 minecraft:wool 1
fill ~28~22~9 ~29~23~9 minecraft:wool 15
setblock ~28~24~9 minecraft:wool 15
fill ~28~32~9 ~28~36~9 minecraft:wool 15
setblock ~28~37~9 minecraft:planks 4
fill ~28~38~9 ~28~40~9 minecraft:wool 1
fill ~29~16~9 ~30~16~9 minecraft:wool 1
setblock ~29~17~9 minecraft:planks 4
setblock ~29~18~9 minecraft:wool 1
fill ~29~19~9 ~30~20~9 minecraft:wool 15
setblock ~29~21~9 minecraft:wool 15
fill ~29~35~9 ~29~39~9 minecraft:wool 15
setblock ~29~40~9 minecraft:wool 1
setblock ~29~41~9 minecraft:planks 4
setblock ~29~42~9 minecraft:wool 1
fill ~30~14~9 ~32~14~9 minecraft:planks 4
fill ~30~15~9 ~31~15~9 minecraft:wool 1
fill ~30~17~9 ~32~17~9 minecraft:wool 15
fill ~30~18~9 ~31~18~9 minecraft:wool 15
fill ~30~38~9 ~30~41~9 minecraft:wool 15
fill ~30~42~9 ~30~43~9 minecraft:planks 4
fill ~30~44~9 ~31~44~9 minecraft:wool 1
fill ~31~13~9 ~34~13~9 minecraft:wool 1
fill ~31~16~9 ~34~16~9 minecraft:wool 15
fill ~31~40~9 ~31~42~9 minecraft:wool 15
setblock ~31~43~9 minecraft:wool 1
fill ~31~45~9 ~33~45~9 minecraft:wool 1
fill ~32~12~9 ~33~12~9 minecraft:wool 1
fill ~32~15~9 ~38~15~9 minecraft:wool 15
fill ~32~41~9 ~32~43~9 minecraft:wool 15
fill ~32~46~9 ~32~46~10 minecraft:wool 1
fill ~33~11~9 ~33~11~10 minecraft:wool 1
fill ~33~14~9 ~38~14~9 minecraft:wool 15
fill ~33~42~9 ~34~44~9 minecraft:wool 15
setblock ~33~46~9 minecraft:planks 4
fill ~33~47~9 ~34~47~9 minecraft:wool 1
fill ~34~10~9 ~36~10~9 minecraft:wool 1
fill ~34~11~9 ~35~12~9 minecraft:planks 4
fill ~34~48~9 ~36~48~9 minecraft:wool 1
fill ~35~13~9 ~39~13~9 minecraft:wool 15
fill ~35~43~9 ~38~45~9 minecraft:wool 15
fill ~35~46~9 ~35~47~9 minecraft:planks 4
fill ~36~9~9 ~37~9~9 minecraft:planks 4
fill ~36~12~9 ~37~12~9 minecraft:wool 1
fill ~36~46~9 ~37~46~9 minecraft:wool 1
setblock ~36~47~9 minecraft:planks 4
fill ~36~49~9 ~37~49~9 minecraft:wool 1
setblock ~37~10~9 minecraft:planks 4
setblock ~37~11~9 minecraft:wool 1
setblock ~37~47~9 minecraft:wool 1
setblock ~37~48~9 minecraft:planks 4
fill ~38~10~9 ~38~11~9 minecraft:stained_hardened_clay 1
setblock ~38~46~9 minecraft:stained_hardened_clay 1
setblock ~38~47~9 minecraft:stained_hardened_clay 12
setblock ~38~48~9 minecraft:stained_hardened_clay 1
fill ~39~9~9 ~40~9~9 minecraft:planks 4
fill ~39~10~9 ~39~11~9 minecraft:wool 1
setblock ~39~12~9 minecraft:wool 15
fill ~39~45~9 ~39~46~9 minecraft:wool 15
fill ~39~47~9 ~39~48~9 minecraft:wool 1
setblock ~39~49~9 minecraft:planks 4
fill ~40~8~9 ~40~8~10 minecraft:wool 1
fill ~40~11~9 ~41~11~9 minecraft:wool 15
fill ~40~47~9 ~41~47~9 minecraft:wool 15
setblock ~40~48~9 minecraft:planks 4
fill ~40~49~9 ~43~49~9 minecraft:wool 1
fill ~40~50~9 ~41~50~9 minecraft:planks 4
fill ~41~8~9 ~42~8~9 minecraft:planks 4
fill ~41~9~9 ~43~9~9 minecraft:wool 1
setblock ~41~10~9 minecraft:wool 1
setblock ~41~48~9 minecraft:wool 1
fill ~42~7~9 ~43~7~9 minecraft:planks 4
fill ~42~10~9 ~45~10~9 minecraft:wool 15
fill ~42~48~9 ~45~48~9 minecraft:wool 15
fill ~42~50~9 ~43~51~9 minecraft:wool 1
fill ~43~8~9 ~45~8~9 minecraft:wool 1
fill ~44~7~9 ~46~7~9 minecraft:wool 1
fill ~44~9~9 ~50~9~9 minecraft:wool 15
fill ~44~49~9 ~50~49~9 minecraft:wool 15
fill ~44~51~9 ~45~51~9 minecraft:planks 4
fill ~45~6~9 ~46~6~10 minecraft:wool 1
fill ~45~50~9 ~46~50~9 minecraft:wool 1
setblock ~45~52~9 minecraft:wool 1
setblock ~46~51~9 minecraft:wool 1
fill ~46~52~9 ~48~52~9 minecraft:planks 4
fill ~47~6~9 ~47~6~10 minecraft:planks 4
setblock ~47~50~9 minecraft:planks 4
fill ~48~6~9 ~50~6~11 minecraft:wool 1
fill ~48~8~9 ~50~8~9 minecraft:planks 4
fill ~48~50~9 ~52~50~9 minecraft:wool 1
fill ~49~7~9 ~50~7~9 minecraft:wool 1
fill ~49~51~9 ~50~52~9 minecraft:wool 1
fill ~50~10~9 ~56~10~9 minecraft:wool 15
fill ~50~48~9 ~56~48~9 minecraft:wool 15
setblock ~51~7~9 minecraft:planks 4
fill ~51~8~9 ~51~9~9 minecraft:wool 1
setblock ~51~49~9 minecraft:planks 4
setblock ~51~51~9 minecraft:planks 4
setblock ~52~7~9 minecraft:wool 1
setblock ~52~8~9 minecraft:planks 4
fill ~52~11~9 ~54~11~9 minecraft:wool 15
fill ~52~47~9 ~54~47~9 minecraft:wool 15
setblock ~52~49~9 minecraft:wool 1
setblock ~52~51~9 minecraft:wool 1
fill ~53~8~9 ~53~9~9 minecraft:stained_hardened_clay 1
setblock ~53~49~9 minecraft:stained_hardened_clay 1
setblock ~53~50~9 minecraft:stained_hardened_clay 12
fill ~54~7~9 ~55~7~9 minecraft:wool 1
fill ~54~8~9 ~54~9~9 minecraft:wool 1
setblock ~54~49~9 minecraft:wool 1
setblock ~54~50~9 minecraft:planks 4
fill ~54~51~9 ~55~51~9 minecraft:wool 1
setblock ~55~8~9 minecraft:planks 4
setblock ~55~9~9 minecraft:wool 1
setblock ~55~49~9 minecraft:planks 4
fill ~55~50~9 ~56~50~9 minecraft:wool 1
fill ~56~6~9 ~56~6~11 minecraft:wool 1
setblock ~56~7~9 minecraft:planks 4
fill ~56~8~9 ~57~8~9 minecraft:wool 1
fill ~56~9~9 ~62~9~9 minecraft:wool 15
fill ~56~49~9 ~62~49~9 minecraft:wool 15
setblock ~56~51~9 minecraft:planks 4
fill ~56~52~9 ~61~52~9 minecraft:wool 1
fill ~57~6~9 ~57~6~10 minecraft:planks 4
setblock ~57~7~9 minecraft:wool 1
setblock ~57~51~9 minecraft:wool 1
fill ~58~6~9 ~61~6~9 minecraft:wool 1
fill ~58~7~9 ~58~8~9 minecraft:planks 4
fill ~59~7~9 ~59~8~9 minecraft:wool 1
setblock ~60~7~9 minecraft:planks 4
fill ~60~51~9 ~64~51~9 minecraft:wool 1
fill ~61~7~9 ~62~7~9 minecraft:wool 1
fill ~61~10~9 ~64~10~9 minecraft:wool 15
fill ~61~48~9 ~64~48~9 minecraft:wool 15
fill ~62~8~9 ~66~8~9 minecraft:wool 1
setblock ~63~7~9 minecraft:planks 4
setblock ~63~9~9 minecraft:wool 1
setblock ~63~49~9 minecraft:planks 4
fill ~63~50~9 ~64~50~9 minecraft:wool 1
setblock ~64~7~9 minecraft:wool 1
fill ~64~49~9 ~65~49~9 minecraft:wool 1
setblock ~65~9~9 minecraft:planks 4
fill ~65~10~9 ~67~10~9 minecraft:wool 1
fill ~65~11~9 ~66~11~9 minecraft:wool 15
fill ~65~47~9 ~66~47~9 minecraft:wool 15
setblock ~65~48~9 minecraft:planks 4
fill ~65~50~9 ~66~50~9 minecraft:planks 4
setblock ~66~9~9 minecraft:wool 1
fill ~66~48~9 ~67~48~9 minecraft:wool 1
setblock ~66~49~9 minecraft:planks 4
setblock ~67~9~9 minecraft:planks 4
setblock ~67~11~9 minecraft:wool 1
fill ~67~12~9 ~67~13~9 minecraft:wool 15
fill ~67~45~9 ~71~45~9 minecraft:wool 15
setblock ~67~46~9 minecraft:wool 15
setblock ~67~47~9 minecraft:planks 4
setblock ~67~49~9 minecraft:wool 1
setblock ~68~10~9 minecraft:stained_hardened_clay 12
fill ~68~11~9 ~68~12~9 minecraft:stained_hardened_clay 1
fill ~68~13~9 ~71~15~9 minecraft:wool 15
fill ~68~43~9 ~74~43~9 minecraft:wool 15
fill ~68~44~9 ~73~44~9 minecraft:wool 15
setblock ~68~47~9 minecraft:stained_hardened_clay 12
setblock ~68~48~9 minecraft:stained_hardened_clay 1
fill ~69~9~9 ~70~9~10 minecraft:wool 1
setblock ~69~10~9 minecraft:wool 1
fill ~69~11~9 ~70~11~9 minecraft:planks 4
fill ~69~12~9 ~70~12~9 minecraft:wool 1
setblock ~69~46~9 minecraft:wool 1
fill ~69~48~9 ~69~49~9 minecraft:planks 4
setblock ~70~10~9 minecraft:planks 4
setblock ~70~46~9 minecraft:planks 4
fill ~70~48~9 ~70~49~9 minecraft:wool 1
fill ~71~10~9 ~72~11~9 minecraft:wool 1
setblock ~71~12~9 minecraft:planks 4
fill ~71~46~9 ~73~47~9 minecraft:wool 1
setblock ~71~48~9 minecraft:planks 4
fill ~72~12~9 ~74~12~9 minecraft:wool 1
setblock ~72~13~9 minecraft:wool 1
fill ~72~14~9 ~73~16~9 minecraft:wool 15
fill ~72~42~9 ~75~42~9 minecraft:wool 15
setblock ~72~45~9 minecraft:wool 1
fill ~72~48~9 ~72~48~10 minecraft:wool 1
fill ~73~11~9 ~73~11~10 minecraft:wool 1
fill ~74~13~9 ~75~13~9 minecraft:wool 1
setblock ~74~14~9 minecraft:wool 1
fill ~74~15~9 ~74~17~9 minecraft:wool 15
fill ~74~41~9 ~76~41~9 minecraft:wool 15
fill ~74~44~9 ~76~44~9 minecraft:wool 1
fill ~74~45~9 ~74~46~9 minecraft:planks 4
setblock ~75~14~9 minecraft:planks 4
fill ~75~15~9 ~76~15~9 minecraft:wool 1
fill ~75~16~9 ~75~18~9 minecraft:wool 15
fill ~75~40~9 ~76~40~9 minecraft:wool 15
fill ~75~43~9 ~76~43~9 minecraft:wool 1
fill ~75~45~9 ~75~45~10 minecraft:wool 1
fill ~76~14~9 ~76~14~10 minecraft:wool 1
fill ~76~16~9 ~77~16~9 minecraft:wool 1
fill ~76~17~9 ~76~20~9 minecraft:wool 15
fill ~76~38~9 ~77~39~9 minecraft:wool 15
setblock ~76~42~9 minecraft:planks 4
fill ~77~17~9 ~77~18~9 minecraft:wool 1
fill ~77~19~9 ~77~23~9 minecraft:wool 15
fill ~77~35~9 ~78~36~9 minecraft:wool 15
setblock ~77~37~9 minecraft:wool 15
fill ~77~40~9 ~78~40~9 minecraft:wool 1
setblock ~77~41~9 minecraft:planks 4
setblock ~77~42~9 minecraft:wool 1
fill ~78~18~9 ~78~21~9 minecraft:wool 1
fill ~78~22~9 ~78~26~9 minecraft:wool 15
fill ~78~32~9 ~79~33~9 minecraft:wool 15
setblock ~78~34~9 minecraft:wool 15
fill ~78~37~9 ~78~39~9 minecraft:wool 1
setblock ~79~21~9 minecraft:wool 1
setblock ~79~22~9 minecraft:planks 4
setblock ~79~23~9 minecraft:wool 1
setblock ~79~24~9 minecraft:planks 4
fill ~79~25~9 ~79~25~10 minecraft:wool 15
fill ~79~26~9 ~79~31~9 minecraft:wool 15
fill ~79~34~9 ~80~34~9 minecraft:wool 1
fill ~79~35~9 ~79~36~9 minecraft:wool 1
setblock ~79~37~9 minecraft:planks 4
fill ~80~24~9 ~80~24~10 minecraft:wool 1
fill ~80~25~9 ~80~29~9 minecraft:wool 1
setblock ~80~30~9 minecraft:planks 4
setblock ~80~31~9 minecraft:wool 1
fill ~80~32~9 ~80~33~9 minecraft:planks 4
setblock ~25~25~10 minecraft:wool 1
setblock ~25~26~10 minecraft:planks 4
fill ~25~27~10 ~25~28~11 minecraft:wool 1
fill ~25~29~10 ~25~29~11 minecraft:planks 4
fill ~25~30~10 ~25~31~11 minecraft:wool 1
fill ~25~32~10 ~25~33~10 minecraft:wool 1
fill ~26~20~10 ~27~20~10 minecraft:wool 1
fill ~26~21~10 ~26~23~11 minecraft:wool 1
setblock ~26~24~10 minecraft:wool 1
fill ~26~26~10 ~26~32~11 minecraft:wool 15
fill ~26~35~10 ~26~38~10 minecraft:wool 1
fill ~27~17~10 ~28~17~10 minecraft:wool 1
fill ~27~18~10 ~27~19~10 minecraft:wool 1
fill ~27~21~10 ~28~21~10 minecraft:wool 15
fill ~27~22~10 ~27~23~11 minecraft:wool 15
fill ~27~24~10 ~27~25~10 minecraft:wool 15
fill ~27~33~10 ~27~37~10 minecraft:wool 15
setblock ~27~38~10 minecraft:planks 4
fill ~27~39~10 ~27~41~10 minecraft:wool 1
fill ~28~15~10 ~29~15~10 minecraft:wool 1
setblock ~28~16~10 minecraft:wool 1
fill ~28~18~10 ~29~18~10 minecraft:wool 15
fill ~28~19~10 ~28~20~10 minecraft:wool 15
fill ~28~37~10 ~28~40~10 minecraft:wool 15
fill ~28~41~10 ~28~43~10 minecraft:wool 1
setblock ~29~13~10 minecraft:planks 4
fill ~29~14~10 ~30~14~10 minecraft:wool 1
fill ~29~16~10 ~30~16~10 minecraft:wool 15
setblock ~29~17~10 minecraft:wool 15
fill ~29~40~10 ~29~42~10 minecraft:wool 15
fill ~29~43~10 ~29~45~10 minecraft:wool 1
fill ~30~12~10 ~30~12~11 minecraft:planks 4
setblock ~30~13~10 minecraft:wool 1
fill ~30~15~10 ~31~15~10 minecraft:wool 15
fill ~30~42~10 ~30~43~10 minecraft:wool 15
fill ~30~44~10 ~30~46~10 minecraft:wool 1
fill ~31~11~10 ~32~11~10 minecraft:wool 1
setblock ~31~12~10 minecraft:wool 1
setblock ~31~13~10 minecraft:planks 4
fill ~31~14~10 ~32~14~10 minecraft:wool 15
fill ~31~43~10 ~31~44~10 minecraft:wool 15
fill ~31~45~10 ~31~47~10 minecraft:wool 1
fill ~32~10~10 ~35~10~10 minecraft:wool 1
setblock ~32~12~10 minecraft:planks 4
fill ~32~13~10 ~34~13~10 minecraft:wool 15
fill ~32~44~10 ~32~45~10 minecraft:wool 15
fill ~32~47~10 ~32~48~10 minecraft:wool 1
fill ~33~12~10 ~38~12~10 minecraft:wool 15
fill ~33~45~10 ~34~46~10 minecraft:wool 15
setblock ~33~47~10 minecraft:planks 4
fill ~33~48~10 ~35~48~10 minecraft:wool 1
fill ~34~9~10 ~35~9~10 minecraft:wool 1
fill ~34~11~10 ~39~11~10 minecraft:wool 15
fill ~34~47~10 ~39~47~10 minecraft:wool 15
fill ~34~49~10 ~35~49~10 minecraft:wool 1
fill ~35~46~10 ~38~46~10 minecraft:wool 15
fill ~36~8~10 ~36~9~10 minecraft:planks 4
fill ~36~10~10 ~41~10~10 minecraft:wool 15
fill ~36~48~10 ~41~48~10 minecraft:wool 15
setblock ~36~49~10 minecraft:planks 4
fill ~36~50~10 ~36~50~11 minecraft:wool 1
fill ~37~8~10 ~37~9~10 minecraft:wool 1
setblock ~37~49~10 minecraft:wool 1
setblock ~37~50~10 minecraft:planks 4
setblock ~38~8~10 minecraft:stained_hardened_clay 1
setblock ~38~9~10 minecraft:stained_hardened_clay 12
fill ~38~49~10 ~38~50~10 minecraft:stained_hardened_clay 12
setblock ~39~8~10 minecraft:wool 1
fill ~39~9~10 ~43~9~10 minecraft:wool 15
fill ~39~49~10 ~43~49~10 minecraft:wool 15
setblock ~39~50~10 minecraft:wool 1
fill ~40~7~10 ~41~7~10 minecraft:wool 1
setblock ~40~50~10 minecraft:planks 4
fill ~40~51~10 ~41~51~10 minecraft:wool 1
fill ~41~6~10 ~43~6~10 minecraft:wool 1
fill ~41~8~10 ~65~8~10 minecraft:wool 15
fill ~41~50~10 ~65~50~10 minecraft:wool 15
setblock ~41~52~10 minecraft:planks 4
fill ~42~7~10 ~52~7~11 minecraft:wool 15
fill ~42~51~10 ~52~51~11 minecraft:wool 15
setblock ~42~52~10 minecraft:wool 1
setblock ~43~52~10 minecraft:planks 4
fill ~44~5~10 ~46~5~10 minecraft:wool 1
fill ~44~6~10 ~44~6~11 minecraft:planks 4
fill ~44~52~10 ~44~52~11 minecraft:wool 1
fill ~44~53~10 ~49~53~10 minecraft:wool 1
setblock ~45~52~10 minecraft:planks 4
fill ~46~52~10 ~47~52~11 minecraft:wool 1
fill ~47~5~10 ~47~5~11 minecraft:planks 4
fill ~48~5~10 ~49~5~11 minecraft:wool 1
setblock ~48~52~10 minecraft:planks 4
fill ~49~52~10 ~51~52~10 minecraft:wool 1
fill ~51~6~10 ~52~6~10 minecraft:planks 4
fill ~51~9~10 ~55~9~10 minecraft:wool 15
fill ~51~49~10 ~55~49~10 minecraft:wool 15
setblock ~52~52~10 minecraft:planks 4
setblock ~53~7~10 minecraft:stained_hardened_clay 1
setblock ~53~51~10 minecraft:stained_hardened_clay 1
fill ~54~6~10 ~55~6~11 minecraft:wool 1
fill ~54~7~10 ~64~7~11 minecraft:wool 15
fill ~54~51~10 ~64~51~11 minecraft:wool 15
setblock ~54~52~10 minecraft:wool 1
setblock ~55~52~10 minecraft:planks 4
fill ~56~52~10 ~58~52~10 minecraft:wool 1
fill ~57~5~10 ~58~5~11 minecraft:wool 1
setblock ~57~53~10 minecraft:planks 4
fill ~58~6~10 ~58~6~11 minecraft:planks 4
fill ~58~53~10 ~59~53~11 minecraft:wool 1
fill ~59~5~10 ~60~5~10 minecraft:planks 4
fill ~59~6~10 ~62~6~10 minecraft:wool 1
fill ~59~52~10 ~60~52~10 minecraft:planks 4
fill ~60~53~10 ~61~53~10 minecraft:planks 4
fill ~61~5~10 ~62~5~10 minecraft:wool 1
fill ~61~52~10 ~61~52~11 minecraft:wool 1
setblock ~62~52~10 minecraft:planks 4
setblock ~62~53~10 minecraft:wool 1
setblock ~63~6~10 minecraft:planks 4
fill ~63~9~10 ~67~9~10 minecraft:wool 15
fill ~63~49~10 ~67~49~10 minecraft:wool 15
fill ~63~52~10 ~65~52~10 minecraft:wool 1
fill ~64~6~10 ~65~6~10 minecraft:wool 1
fill ~65~7~10 ~66~7~11 minecraft:wool 1
fill ~65~10~10 ~70~10~10 minecraft:wool 15
fill ~65~48~10 ~70~48~10 minecraft:wool 15
fill ~65~51~10 ~66~51~11 minecraft:wool 1
setblock ~66~8~10 minecraft:planks 4
setblock ~66~50~10 minecraft:wool 1
setblock ~67~8~10 minecraft:wool 1
fill ~67~11~10 ~72~11~10 minecraft:wool 15
fill ~67~47~10 ~72~47~10 minecraft:wool 15
setblock ~67~50~10 minecraft:planks 4
fill ~68~8~10 ~68~9~10 minecraft:stained_hardened_clay 1
fill ~68~12~10 ~73~12~10 minecraft:wool 15
fill ~68~46~10 ~73~46~10 minecraft:wool 15
fill ~68~49~10 ~68~50~10 minecraft:stained_hardened_clay 12
fill ~69~8~10 ~70~8~10 minecraft:wool 1
fill ~69~49~10 ~70~50~10 minecraft:wool 1
setblock ~71~9~10 minecraft:planks 4
setblock ~71~10~10 minecraft:wool 1
setblock ~71~48~10 minecraft:wool 1
setblock ~71~49~10 minecraft:planks 4
fill ~72~9~10 ~72~9~11 minecraft:wool 1
fill ~72~10~10 ~73~10~10 minecraft:planks 4
fill ~72~13~10 ~74~13~10 minecraft:wool 15
fill ~72~45~10 ~74~45~10 minecraft:wool 15
fill ~72~49~10 ~72~49~11 minecraft:wool 1
fill ~73~47~10 ~75~47~10 minecraft:wool 1
setblock ~73~48~10 minecraft:planks 4
fill ~74~10~10 ~74~10~11 minecraft:wool 1
fill ~74~11~10 ~75~12~10 minecraft:wool 1
fill ~74~14~10 ~75~14~10 minecraft:wool 15
fill ~74~44~10 ~75~44~10 minecraft:wool 15
fill ~74~46~10 ~75~46~10 minecraft:wool 1
fill ~74~48~10 ~74~48~11 minecraft:wool 1
setblock ~75~13~10 minecraft:planks 4
fill ~75~15~10 ~76~15~10 minecraft:wool 15
fill ~75~43~10 ~76~43~10 minecraft:wool 15
setblock ~76~12~10 minecraft:planks 4
fill ~76~13~10 ~77~13~10 minecraft:wool 1
fill ~76~16~10 ~77~16~10 minecraft:wool 15
fill ~76~42~10 ~77~42~10 minecraft:wool 15
fill ~76~44~10 ~77~44~10 minecraft:wool 1
fill ~76~45~10 ~76~46~10 minecraft:planks 4
setblock ~77~14~10 minecraft:wool 1
setblock ~77~15~10 minecraft:planks 4
fill ~77~17~10 ~77~18~10 minecraft:wool 15
fill ~77~40~10 ~78~40~10 minecraft:wool 15
setblock ~77~41~10 minecraft:wool 15
fill ~77~43~10 ~78~43~10 minecraft:wool 1
setblock ~77~45~10 minecraft:wool 1
setblock ~78~15~10 minecraft:wool 1
setblock ~78~16~10 minecraft:planks 4
setblock ~78~17~10 minecraft:wool 1
fill ~78~18~10 ~78~21~10 minecraft:wool 15
fill ~78~37~10 ~79~37~10 minecraft:wool 15
fill ~78~38~10 ~78~39~10 minecraft:wool 15
fill ~78~41~10 ~79~41~10 minecraft:wool 1
setblock ~78~42~10 minecraft:wool 1
fill ~79~17~10 ~79~19~10 minecraft:planks 4
fill ~79~20~10 ~80~20~10 minecraft:wool 1
fill ~79~21~10 ~79~23~11 minecraft:wool 15
setblock ~79~24~10 minecraft:wool 15
fill ~79~33~10 ~79~36~10 minecraft:wool 15
fill ~79~38~10 ~80~38~10 minecraft:wool 1
setblock ~79~39~10 minecraft:planks 4
setblock ~79~40~10 minecraft:wool 1
fill ~80~21~10 ~80~22~11 minecraft:wool 1
setblock ~80~23~10 minecraft:wool 1
setblock ~80~25~10 minecraft:planks 4
fill ~80~26~10 ~80~32~11 minecraft:wool 15
fill ~80~33~10 ~81~33~10 minecraft:wool 1
setblock ~80~34~10 minecraft:planks 4
setblock ~80~35~10 minecraft:wool 1
fill ~80~36~10 ~80~36~11 minecraft:planks 4
setblock ~80~37~10 minecraft:wool 1
fill ~81~25~10 ~81~26~11 minecraft:wool 1
setblock ~81~27~10 minecraft:planks 4
fill ~81~28~10 ~81~30~10 minecraft:wool 1
setblock ~81~31~10 minecraft:planks 4
setblock ~81~32~10 minecraft:wool 1
fill ~24~27~11 ~24~28~13 minecraft:wool 1
fill ~24~29~11 ~24~31~11 minecraft:wool 1
fill ~25~22~11 ~25~22~12 minecraft:wool 1
setblock ~25~23~11 minecraft:planks 4
fill ~25~24~11 ~25~24~12 minecraft:wool 1
setblock ~25~25~11 minecraft:planks 4
setblock ~25~26~11 minecraft:wool 1
fill ~25~32~11 ~25~34~11 minecraft:planks 4
fill ~25~35~11 ~25~36~11 minecraft:wool 1
fill ~26~17~11 ~26~17~12 minecraft:wool 1
fill ~26~18~11 ~26~20~11 minecraft:wool 1
fill ~26~24~11 ~26~24~12 minecraft:wool 15
setblock ~26~25~11 minecraft:wool 15
fill ~26~33~11 ~26~34~11 minecraft:wool 15
setblock ~26~35~11 minecraft:planks 4
fill ~26~36~11 ~26~38~11 minecraft:wool 1
fill ~26~39~11 ~26~39~12 minecraft:planks 4
fill ~26~40~11 ~26~41~12 minecraft:wool 1
fill ~27~15~11 ~27~16~11 minecraft:wool 1
setblock ~27~17~11 minecraft:planks 4
fill ~27~18~11 ~27~18~13 minecraft:wool 15
fill ~27~19~11 ~27~20~12 minecraft:wool 15
setblock ~27~21~11 minecraft:wool 15
fill ~27~35~11 ~27~40~11 minecraft:wool 15
fill ~27~41~11 ~27~43~11 minecraft:wool 1
setblock ~28~13~11 minecraft:planks 4
setblock ~28~14~11 minecraft:wool 1
fill ~28~15~11 ~29~15~11 minecraft:wool 15
fill ~28~16~11 ~28~17~11 minecraft:wool 15
fill ~28~41~11 ~28~43~11 minecraft:wool 15
fill ~28~44~11 ~28~45~11 minecraft:wool 1
fill ~29~12~11 ~29~12~12 minecraft:wool 1
setblock ~29~13~11 minecraft:wool 1
fill ~29~14~11 ~30~14~11 minecraft:wool 15
fill ~29~43~11 ~29~44~11 minecraft:wool 15
setblock ~29~45~11 minecraft:planks 4
fill ~29~46~11 ~30~46~11 minecraft:wool 1
fill ~30~11~11 ~31~11~11 minecraft:wool 1
fill ~30~13~11 ~31~13~11 minecraft:wool 15
fill ~30~44~11 ~30~45~11 minecraft:wool 15
fill ~30~47~11 ~31~47~11 minecraft:planks 4
fill ~31~10~11 ~31~10~12 minecraft:planks 4
fill ~31~12~11 ~32~12~11 minecraft:wool 15
fill ~31~45~11 ~31~46~11 minecraft:wool 15
fill ~31~48~11 ~32~48~11 minecraft:wool 1
fill ~32~9~11 ~34~9~11 minecraft:wool 1
setblock ~32~10~11 minecraft:wool 1
fill ~32~11~11 ~33~11~11 minecraft:wool 15
fill ~32~46~11 ~32~47~11 minecraft:wool 15
fill ~32~49~11 ~34~49~11 minecraft:wool 1
fill ~33~10~11 ~35~10~11 minecraft:wool 15
fill ~33~47~11 ~33~48~11 minecraft:wool 15
fill ~34~8~11 ~36~8~11 minecraft:wool 1
fill ~34~48~11 ~35~48~11 minecraft:wool 15
fill ~34~50~11 ~34~50~12 minecraft:planks 4
fill ~35~9~11 ~38~9~11 minecraft:wool 15
fill ~35~49~11 ~38~49~11 minecraft:wool 15
setblock ~35~50~11 minecraft:wool 1
fill ~36~7~11 ~37~7~11 minecraft:wool 1
fill ~36~51~11 ~37~51~11 minecraft:wool 1
fill ~37~8~11 ~41~8~11 minecraft:wool 15
fill ~37~50~11 ~41~50~11 minecraft:wool 15
setblock ~38~7~11 minecraft:stained_hardened_clay 12
setblock ~38~51~11 minecraft:stained_hardened_clay 1
setblock ~39~7~11 minecraft:wool 1
fill ~39~51~11 ~40~51~11 minecraft:wool 1
fill ~40~6~11 ~40~6~12 minecraft:wool 1
fill ~40~7~11 ~41~7~11 minecraft:planks 4
fill ~40~52~11 ~40~52~12 minecraft:wool 1
setblock ~41~5~11 minecraft:planks 4
setblock ~41~51~11 minecraft:planks 4
fill ~41~53~11 ~43~53~11 minecraft:wool 1
fill ~42~5~11 ~43~5~12 minecraft:wool 1
setblock ~42~6~11 minecraft:wool 1
setblock ~42~52~11 minecraft:planks 4
fill ~43~4~11 ~43~4~12 minecraft:wool 1
setblock ~43~6~11 minecraft:planks 4
setblock ~43~52~11 minecraft:wool 1
fill ~43~54~11 ~48~54~11 minecraft:wool 1
setblock ~44~4~11 minecraft:planks 4
fill ~45~4~11 ~45~4~12 minecraft:wool 1
setblock ~45~6~11 minecraft:wool 1
setblock ~45~52~11 minecraft:wool 1
setblock ~46~4~11 minecraft:planks 4
setblock ~46~5~11 minecraft:wool 1
setblock ~46~6~11 minecraft:planks 4
fill ~46~53~11 ~47~53~11 minecraft:wool 1
fill ~47~4~11 ~50~4~11 minecraft:wool 1
setblock ~47~6~11 minecraft:wool 1
fill ~48~52~11 ~49~52~11 minecraft:wool 1
fill ~48~53~11 ~49~53~11 minecraft:planks 4
setblock ~49~54~11 minecraft:planks 4
setblock ~50~5~11 minecraft:planks 4
fill ~50~52~11 ~51~52~11 minecraft:planks 4
fill ~50~53~11 ~52~53~11 minecraft:wool 1
setblock ~50~54~11 minecraft:wool 1
fill ~51~5~11 ~52~6~11 minecraft:wool 1
setblock ~52~52~11 minecraft:wool 1
setblock ~53~6~11 minecraft:stained_hardened_clay 12
setblock ~53~7~11 minecraft:wool 15
setblock ~53~51~11 minecraft:wool 15
setblock ~53~52~11 minecraft:stained_hardened_clay 1
fill ~54~5~11 ~56~5~11 minecraft:wool 1
setblock ~54~52~11 minecraft:planks 4
fill ~54~53~11 ~57~53~11 minecraft:wool 1
setblock ~55~52~11 minecraft:wool 1
fill ~56~4~11 ~63~4~11 minecraft:wool 1
setblock ~56~52~11 minecraft:planks 4
fill ~56~54~11 ~57~54~11 minecraft:wool 1
setblock ~57~6~11 minecraft:wool 1
setblock ~57~52~11 minecraft:wool 1
setblock ~58~52~11 minecraft:planks 4
setblock ~58~54~11 minecraft:planks 4
fill ~59~5~11 ~60~5~11 minecraft:wool 1
setblock ~59~6~11 minecraft:planks 4
fill ~59~52~11 ~60~52~11 minecraft:wool 1
fill ~59~54~11 ~60~54~11 minecraft:wool 1
fill ~60~6~11 ~64~6~11 minecraft:wool 1
setblock ~60~53~11 minecraft:wool 1
fill ~61~54~11 ~62~54~11 minecraft:planks 4
setblock ~62~52~11 minecraft:wool 1
fill ~63~5~11 ~65~5~11 minecraft:wool 1
fill ~63~52~11 ~66~52~11 minecraft:planks 4
fill ~63~53~11 ~65~53~12 minecraft:wool 1
fill ~63~54~11 ~63~54~12 minecraft:wool 1
fill ~65~8~11 ~69~8~11 minecraft:wool 15
fill ~65~50~11 ~69~50~11 minecraft:wool 15
fill ~66~6~11 ~66~6~12 minecraft:wool 1
setblock ~67~7~11 minecraft:wool 1
setblock ~67~51~11 minecraft:wool 1
setblock ~68~7~11 minecraft:stained_hardened_clay 12
fill ~68~9~11 ~71~9~11 minecraft:wool 15
fill ~68~49~11 ~71~49~11 minecraft:wool 15
setblock ~68~51~11 minecraft:stained_hardened_clay 12
fill ~69~7~11 ~70~7~12 minecraft:wool 1
setblock ~69~51~11 minecraft:planks 4
fill ~70~8~11 ~71~8~11 minecraft:wool 1
fill ~70~50~11 ~70~51~11 minecraft:wool 1
fill ~71~10~11 ~73~10~11 minecraft:wool 15
fill ~71~48~11 ~73~48~11 minecraft:wool 15
setblock ~71~50~11 minecraft:planks 4
setblock ~72~8~11 minecraft:planks 4
setblock ~72~50~11 minecraft:wool 1
fill ~73~9~11 ~74~9~11 minecraft:wool 1
fill ~73~11~11 ~74~11~11 minecraft:wool 15
fill ~73~47~11 ~74~47~11 minecraft:wool 15
setblock ~73~49~11 minecraft:planks 4
fill ~74~12~11 ~75~12~11 minecraft:wool 15
fill ~74~46~11 ~75~46~11 minecraft:wool 15
fill ~74~49~11 ~74~49~12 minecraft:wool 1
fill ~75~10~11 ~75~10~12 minecraft:wool 1
fill ~75~11~11 ~76~11~11 minecraft:wool 1
fill ~75~13~11 ~76~13~11 minecraft:wool 15
fill ~75~45~11 ~76~45~11 minecraft:wool 15
setblock ~75~47~11 minecraft:planks 4
setblock ~75~48~11 minecraft:wool 1
fill ~76~12~11 ~77~12~11 minecraft:wool 1
fill ~76~14~11 ~77~14~11 minecraft:wool 15
fill ~76~44~11 ~77~44~11 minecraft:wool 15
fill ~76~46~11 ~76~47~11 minecraft:wool 1
fill ~77~13~11 ~78~13~11 minecraft:wool 1
fill ~77~15~11 ~78~15~11 minecraft:wool 15
fill ~77~43~11 ~78~43~11 minecraft:wool 15
fill ~77~45~11 ~77~46~11 minecraft:planks 4
setblock ~78~14~11 minecraft:wool 1
fill ~78~16~11 ~78~17~11 minecraft:wool 15
fill ~78~41~11 ~78~42~11 minecraft:wool 15
setblock ~78~44~11 minecraft:planks 4
fill ~78~45~11 ~78~45~12 minecraft:wool 1
fill ~79~15~11 ~79~15~12 minecraft:wool 1
fill ~79~16~11 ~79~17~11 minecraft:wool 1
fill ~79~18~11 ~79~18~13 minecraft:wool 15
fill ~79~19~11 ~79~20~12 minecraft:wool 15
fill ~79~35~11 ~79~40~11 minecraft:wool 15
fill ~79~41~11 ~79~42~11 minecraft:wool 1
setblock ~79~43~11 minecraft:planks 4
fill ~80~17~11 ~80~17~13 minecraft:wool 1
fill ~80~18~11 ~80~18~12 minecraft:planks 4
fill ~80~19~11 ~80~19~12 minecraft:wool 1
fill ~80~20~11 ~80~20~12 minecraft:planks 4
fill ~80~23~11 ~81~23~11 minecraft:planks 4
fill ~80~24~11 ~80~24~12 minecraft:wool 15
setblock ~80~25~11 minecraft:wool 15
fill ~80~33~11 ~80~34~11 minecraft:wool 15
setblock ~80~35~11 minecraft:planks 4
setblock ~80~37~11 minecraft:planks 4
fill ~80~38~11 ~80~38~12 minecraft:wool 1
setblock ~80~39~11 minecraft:wool 1
fill ~80~40~11 ~80~40~12 minecraft:planks 4
setblock ~80~41~11 minecraft:planks 4
setblock ~81~22~11 minecraft:planks 4
fill ~81~24~11 ~81~24~12 minecraft:wool 1
setblock ~81~27~11 minecraft:wool 1
setblock ~81~28~11 minecraft:planks 4
fill ~81~29~11 ~82~31~11 minecraft:wool 1
setblock ~81~32~11 minecraft:planks 4
fill ~81~33~11 ~81~36~11 minecraft:wool 1
setblock ~82~27~11 minecraft:planks 4
fill ~82~28~11 ~82~28~13 minecraft:wool 1
setblock ~24~24~12 minecraft:wool 1
setblock ~24~25~12 minecraft:planks 4
setblock ~24~26~12 minecraft:wool 1
fill ~24~29~12 ~24~29~13 minecraft:planks 4
fill ~24~30~12 ~24~34~12 minecraft:wool 1
fill ~25~19~12 ~26~20~12 minecraft:wool 1
fill ~25~21~12 ~25~21~13 minecraft:wool 1
setblock ~25~23~12 minecraft:wool 1
fill ~25~25~12 ~25~33~13 minecraft:wool 15
setblock ~25~34~12 minecraft:wool 1
setblock ~25~35~12 minecraft:planks 4
setblock ~25~36~12 minecraft:wool 1
fill ~25~37~12 ~25~37~13 minecraft:planks 4
fill ~25~38~12 ~26~38~12 minecraft:planks 4
fill ~25~39~12 ~25~39~14 minecraft:wool 1
fill ~26~15~12 ~27~15~12 minecraft:planks 4
setblock ~26~16~12 minecraft:planks 4
setblock ~26~18~12 minecraft:planks 4
fill ~26~21~12 ~26~21~13 minecraft:wool 15
fill ~26~22~12 ~26~23~12 minecraft:wool 15
fill ~26~34~12 ~26~37~12 minecraft:wool 15
fill ~26~42~12 ~26~43~13 minecraft:planks 4
fill ~27~13~12 ~28~13~12 minecraft:wool 1
setblock ~27~14~12 minecraft:wool 1
fill ~27~16~12 ~27~17~13 minecraft:wool 15
fill ~27~38~12 ~27~42~12 minecraft:wool 15
setblock ~27~43~12 minecraft:planks 4
fill ~27~44~12 ~27~45~12 minecraft:wool 1
fill ~28~12~12 ~28~12~13 minecraft:planks 4
fill ~28~14~12 ~28~15~12 minecraft:wool 15
fill ~28~43~12 ~28~44~12 minecraft:wool 15
fill ~28~45~12 ~28~46~12 minecraft:wool 1
fill ~29~11~12 ~29~11~13 minecraft:wool 1
setblock ~29~13~12 minecraft:wool 15
setblock ~29~45~12 minecraft:wool 15
setblock ~29~46~12 minecraft:wool 1
setblock ~29~47~12 minecraft:planks 4
setblock ~30~10~12 minecraft:wool 1
fill ~30~11~12 ~31~11~12 minecraft:wool 15
setblock ~30~12~12 minecraft:wool 15
fill ~30~46~12 ~30~47~12 minecraft:wool 15
fill ~30~48~12 ~31~48~12 minecraft:wool 1
fill ~31~9~12 ~32~9~12 minecraft:wool 1
setblock ~31~47~12 minecraft:wool 15
fill ~31~49~12 ~32~49~12 minecraft:wool 1
setblock ~32~8~12 minecraft:wool 1
setblock ~32~10~12 minecraft:wool 15
setblock ~32~48~12 minecraft:wool 15
setblock ~32~50~12 minecraft:planks 4
setblock ~33~8~12 minecraft:planks 4
fill ~33~9~12 ~34~9~12 minecraft:wool 15
fill ~33~49~12 ~34~49~12 minecraft:wool 15
setblock ~33~50~12 minecraft:wool 1
setblock ~34~7~12 minecraft:planks 4
setblock ~34~8~12 minecraft:wool 1
fill ~34~51~12 ~35~51~13 minecraft:wool 1
fill ~35~7~12 ~36~7~12 minecraft:wool 1
fill ~35~8~12 ~37~8~12 minecraft:wool 15
fill ~35~50~12 ~37~50~12 minecraft:wool 15
setblock ~36~51~12 minecraft:planks 4
fill ~37~6~12 ~37~6~13 minecraft:wool 1
setblock ~37~7~12 minecraft:planks 4
setblock ~37~51~12 minecraft:wool 1
setblock ~37~52~12 minecraft:planks 4
setblock ~38~6~12 minecraft:planks 4
fill ~38~7~12 ~41~7~12 minecraft:wool 15
fill ~38~51~12 ~41~51~12 minecraft:wool 15
fill ~38~52~12 ~38~52~14 minecraft:wool 1
setblock ~39~6~12 minecraft:stained_hardened_clay 1
setblock ~39~52~12 minecraft:stained_hardened_clay 1
fill ~40~5~12 ~41~5~13 minecraft:wool 1
fill ~40~53~12 ~42~53~12 minecraft:wool 1
setblock ~41~6~12 minecraft:wool 1
setblock ~41~52~12 minecraft:wool 1
setblock ~42~4~12 minecraft:planks 4
fill ~42~6~12 ~64~6~12 minecraft:wool 15
fill ~42~52~12 ~64~52~12 minecraft:wool 15
setblock ~42~54~12 minecraft:planks 4
setblock ~43~53~12 minecraft:planks 4
setblock ~43~54~12 minecraft:wool 1
fill ~44~3~12 ~45~3~12 minecraft:wool 1
setblock ~44~4~12 minecraft:wool 1
setblock ~44~5~12 minecraft:planks 4
fill ~44~53~12 ~45~53~12 minecraft:wool 1
setblock ~44~54~12 minecraft:planks 4
setblock ~45~5~12 minecraft:wool 1
fill ~45~54~12 ~45~55~12 minecraft:wool 1
setblock ~46~3~12 minecraft:planks 4
fill ~46~4~12 ~50~4~14 minecraft:wool 15
fill ~46~5~12 ~52~5~12 minecraft:wool 15
fill ~46~53~12 ~52~53~12 minecraft:wool 15
fill ~46~54~12 ~50~54~14 minecraft:wool 15
setblock ~46~55~12 minecraft:planks 4
fill ~47~3~12 ~49~3~12 minecraft:wool 1
fill ~47~55~12 ~48~55~12 minecraft:wool 1
setblock ~49~55~12 minecraft:planks 4
setblock ~50~3~12 minecraft:planks 4
fill ~50~55~12 ~51~55~12 minecraft:wool 1
fill ~51~3~12 ~51~3~14 minecraft:wool 1
setblock ~51~4~12 minecraft:wool 1
fill ~51~54~12 ~52~54~12 minecraft:wool 1
setblock ~52~4~12 minecraft:planks 4
setblock ~53~5~12 minecraft:stained_hardened_clay 12
setblock ~53~53~12 minecraft:stained_hardened_clay 1
fill ~54~4~12 ~55~4~12 minecraft:wool 1
fill ~54~5~12 ~60~5~12 minecraft:wool 15
fill ~54~53~12 ~60~53~12 minecraft:wool 15
setblock ~54~54~12 minecraft:planks 4
fill ~55~3~12 ~58~3~12 minecraft:wool 1
fill ~55~54~12 ~55~55~12 minecraft:wool 1
fill ~56~4~12 ~60~4~14 minecraft:wool 15
fill ~56~54~12 ~60~54~14 minecraft:wool 15
fill ~56~55~12 ~58~55~14 minecraft:wool 1
fill ~59~3~12 ~60~3~12 minecraft:planks 4
setblock ~59~55~12 minecraft:planks 4
fill ~60~55~12 ~61~55~12 minecraft:wool 1
fill ~61~3~12 ~62~3~13 minecraft:wool 1
fill ~61~4~12 ~64~4~12 minecraft:wool 1
setblock ~61~5~12 minecraft:wool 1
fill ~61~53~12 ~61~54~12 minecraft:wool 1
setblock ~62~5~12 minecraft:planks 4
setblock ~62~53~12 minecraft:planks 4
setblock ~62~54~12 minecraft:wool 1
setblock ~63~5~12 minecraft:wool 1
fill ~64~5~12 ~66~5~12 minecraft:planks 4
fill ~64~54~12 ~64~54~13 minecraft:planks 4
setblock ~65~6~12 minecraft:wool 1
fill ~65~7~12 ~68~7~12 minecraft:wool 15
fill ~65~51~12 ~68~51~12 minecraft:wool 15
fill ~65~52~12 ~66~52~12 minecraft:wool 1
setblock ~66~53~12 minecraft:wool 1
setblock ~67~6~12 minecraft:stained_hardened_clay 1
setblock ~67~52~12 minecraft:stained_hardened_clay 12
fill ~68~6~12 ~69~6~13 minecraft:wool 1
fill ~68~52~12 ~69~52~13 minecraft:wool 1
fill ~69~8~12 ~71~8~12 minecraft:wool 15
fill ~69~50~12 ~71~50~12 minecraft:wool 15
fill ~69~51~12 ~72~51~12 minecraft:wool 1
fill ~71~7~12 ~71~7~13 minecraft:planks 4
fill ~72~7~12 ~72~8~12 minecraft:wool 1
fill ~72~9~12 ~73~9~12 minecraft:wool 15
fill ~72~49~12 ~73~49~12 minecraft:wool 15
setblock ~72~50~12 minecraft:planks 4
fill ~73~8~12 ~74~8~12 minecraft:wool 1
setblock ~73~50~12 minecraft:wool 1
fill ~74~9~12 ~75~9~12 minecraft:wool 1
setblock ~74~10~12 minecraft:wool 15
setblock ~74~48~12 minecraft:wool 15
setblock ~74~50~12 minecraft:planks 4
fill ~75~11~12 ~76~11~12 minecraft:wool 15
fill ~75~47~12 ~76~47~12 minecraft:wool 15
setblock ~75~48~12 minecraft:planks 4
setblock ~75~49~12 minecraft:wool 1
setblock ~76~10~12 minecraft:wool 1
setblock ~76~12~12 minecraft:wool 15
setblock ~76~46~12 minecraft:wool 15
setblock ~76~48~12 minecraft:wool 1
fill ~77~11~12 ~77~11~13 minecraft:wool 1
setblock ~77~12~12 minecraft:planks 4
setblock ~77~13~12 minecraft:wool 15
setblock ~77~45~12 minecraft:wool 15
fill ~77~46~12 ~77~47~12 minecraft:planks 4
fill ~78~12~12 ~78~12~13 minecraft:wool 1
setblock ~78~13~12 minecraft:wool 1
fill ~78~14~12 ~78~15~12 minecraft:wool 15
fill ~78~43~12 ~78~44~12 minecraft:wool 15
setblock ~78~46~12 minecraft:wool 1
fill ~79~13~12 ~79~13~13 minecraft:planks 4
setblock ~79~14~12 minecraft:wool 1
fill ~79~16~12 ~79~17~13 minecraft:wool 15
fill ~79~38~12 ~79~42~12 minecraft:wool 15
fill ~79~43~12 ~80~43~12 minecraft:wool 1
fill ~79~44~12 ~79~45~12 minecraft:wool 1
fill ~80~15~12 ~80~15~13 minecraft:wool 1
fill ~80~16~12 ~80~16~13 minecraft:planks 4
fill ~80~21~12 ~80~21~13 minecraft:wool 15
fill ~80~22~12 ~80~23~12 minecraft:wool 15
fill ~80~34~12 ~80~37~12 minecraft:wool 15
fill ~80~39~12 ~81~39~12 minecraft:planks 4
fill ~80~41~12 ~80~42~12 minecraft:wool 1
fill ~81~19~12 ~81~20~12 minecraft:wool 1
fill ~81~21~12 ~81~21~13 minecraft:planks 4
fill ~81~22~12 ~81~23~12 minecraft:wool 1
fill ~81~25~12 ~81~33~13 minecraft:wool 15
fill ~81~34~12 ~82~34~12 minecraft:wool 1
fill ~81~35~12 ~81~36~12 minecraft:wool 1
setblock ~81~37~12 minecraft:planks 4
setblock ~81~38~12 minecraft:wool 1
fill ~82~24~12 ~82~27~13 minecraft:wool 1
setblock ~82~29~12 minecraft:planks 4
fill ~82~30~12 ~82~33~13 minecraft:wool 1
fill ~23~26~13 ~24~26~13 minecraft:planks 4
setblock ~23~27~13 minecraft:planks 4
fill ~23~28~13 ~23~29~14 minecraft:wool 1
fill ~23~30~13 ~23~32~13 minecraft:wool 1
fill ~24~21~13 ~24~22~13 minecraft:wool 1
fill ~24~23~13 ~24~24~13 minecraft:planks 4
setblock ~24~25~13 minecraft:wool 1
setblock ~24~30~13 minecraft:planks 4
fill ~24~31~13 ~24~36~13 minecraft:wool 1
setblock ~24~37~13 minecraft:planks 4
fill ~25~16~13 ~26~16~13 minecraft:wool 1
fill ~25~17~13 ~25~17~14 minecraft:wool 1
fill ~25~18~13 ~26~18~13 minecraft:wool 1
setblock ~25~19~13 minecraft:wool 1
setblock ~25~20~13 minecraft:planks 4
fill ~25~22~13 ~25~22~14 minecraft:wool 15
fill ~25~23~13 ~25~24~13 minecraft:wool 15
fill ~25~34~13 ~25~36~13 minecraft:wool 15
setblock ~25~38~13 minecraft:wool 1
fill ~25~40~13 ~25~41~14 minecraft:wool 1
setblock ~25~42~13 minecraft:planks 4
fill ~26~13~13 ~26~15~14 minecraft:wool 1
setblock ~26~17~13 minecraft:planks 4
