fill ~2~5~0 ~32~5~0 minecraft:border_block
setblock ~33~5~0 minecraft:border_block
fill ~1~5~1 ~1~5~25 minecraft:border_block
fill ~2~1~1 ~32~4~1 minecraft:concrete
fill ~2~5~1 ~32~5~3 minecraft:concrete 7
fill ~29~10~1 ~31~11~2 minecraft:leaves
fill ~33~5~1 ~33~5~25 minecraft:border_block
fill ~2~1~2 ~2~4~25 minecraft:concrete
setblock ~5~15~2 minecraft:glowstone
fill ~5~16~2 ~9~16~2 minecraft:iron_bars
fill ~6~17~2 ~8~17~2 minecraft:lodestone
setblock ~7~6~2 minecraft:crimson_fence
fill ~7~7~2 ~7~15~2 minecraft:iron_bars
setblock ~9~15~2 minecraft:glowstone
setblock ~22~15~2 minecraft:glowstone
fill ~22~16~2 ~26~16~2 minecraft:iron_bars
fill ~23~17~2 ~25~17~2 minecraft:lodestone
setblock ~24~6~2 minecraft:crimson_fence
fill ~24~7~2 ~24~15~2 minecraft:iron_bars
setblock ~26~15~2 minecraft:glowstone
fill ~28~10~2 ~28~10~5 minecraft:leaves
fill ~28~11~2 ~28~12~4 minecraft:leaves
fill ~29~12~2 ~31~13~2 minecraft:leaves
fill ~30~9~2 ~30~9~3 minecraft:leaves
fill ~32~1~2 ~32~4~25 minecraft:concrete
fill ~32~10~2 ~32~10~6 minecraft:leaves
fill ~32~11~2 ~32~11~4 minecraft:leaves
fill ~27~11~3 ~27~12~4 minecraft:leaves
fill ~28~13~3 ~32~13~4 minecraft:leaves
fill ~29~9~3 ~29~11~3 minecraft:leaves
fill ~29~12~3 ~30~12~3 minecraft:leaves
fill ~30~10~3 ~31~10~3 minecraft:leaves
fill ~30~11~3 ~31~11~3 minecraft:leaves
fill ~30~14~3 ~30~14~5 minecraft:leaves
fill ~31~9~3 ~31~9~7 minecraft:leaves
fill ~31~12~3 ~32~12~3 minecraft:leaves
fill ~2~5~4 ~2~5~21 minecraft:concrete 7
fill ~3~5~4 ~12~5~5 minecraft:grass
fill ~13~5~4 ~19~5~4 minecraft:concrete 7
fill ~14~9~4 ~18~9~6 minecraft:stained_hardened_clay 5
fill ~20~5~4 ~29~5~5 minecraft:grass
fill ~28~9~4 ~28~9~5 minecraft:leaves
fill ~29~9~4 ~29~9~5 minecraft:leaves
fill ~29~10~4 ~29~11~4 minecraft:leaves
setblock ~29~12~4 minecraft:leaves
setblock ~29~14~4 minecraft:leaves
setblock ~30~5~4 minecraft:grass
fill ~30~6~4 ~30~11~4 minecraft:log
setblock ~30~12~4 minecraft:leaves
fill ~31~5~4 ~32~5~22 minecraft:concrete 7
fill ~31~10~4 ~31~10~5 minecraft:leaves
fill ~31~11~4 ~31~11~5 minecraft:leaves
setblock ~31~12~4 minecraft:leaves
setblock ~31~14~4 minecraft:leaves
fill ~32~9~4 ~32~9~6 minecraft:leaves
fill ~32~12~4 ~32~12~5 minecraft:leaves
fill ~3~11~5 ~13~11~6 minecraft:stained_hardened_clay 3
fill ~3~12~5 ~3~15~21 minecraft:stained_hardened_clay 3
fill ~4~15~5 ~13~15~6 minecraft:stained_hardened_clay 3
fill ~7~12~5 ~7~14~5 minecraft:stained_hardened_clay 11
fill ~9~12~5 ~9~14~5 minecraft:stained_hardened_clay 11
setblock ~13~5~5 minecraft:concrete 7
fill ~13~12~5 ~13~12~21 minecraft:stained_hardened_clay 3
fill ~13~13~5 ~13~14~8 minecraft:stained_hardened_clay 3
setblock ~14~5~5 minecraft:grass
fill ~14~6~5 ~14~8~5 minecraft:stained_hardened_clay 5
fill ~14~10~5 ~14~10~6 minecraft:stained_hardened_clay 5
fill ~15~5~5 ~17~5~18 minecraft:stripped_crimson_stem
fill ~16~10~5 ~16~10~6 minecraft:stained_hardened_clay 5
setblock ~18~5~5 minecraft:grass
fill ~18~6~5 ~18~8~5 minecraft:stained_hardened_clay 5
fill ~18~10~5 ~18~10~6 minecraft:stained_hardened_clay 5
setblock ~19~5~5 minecraft:concrete 7
fill ~19~11~5 ~29~11~6 minecraft:stained_hardened_clay 3
fill ~19~12~5 ~19~12~21 minecraft:stained_hardened_clay 3
fill ~19~13~5 ~19~15~8 minecraft:stained_hardened_clay 3
fill ~20~15~5 ~29~15~6 minecraft:stained_hardened_clay 3
fill ~23~12~5 ~23~14~5 minecraft:stained_hardened_clay 11
fill ~25~12~5 ~25~14~5 minecraft:stained_hardened_clay 11
fill ~27~12~5 ~28~12~5 minecraft:leaves
setblock ~28~13~5 minecraft:leaves
setblock ~29~8~5 minecraft:leaves
setblock ~29~10~5 minecraft:leaves
fill ~29~12~5 ~29~14~21 minecraft:stained_hardened_clay 3
fill ~30~5~5 ~30~5~25 minecraft:grass
setblock ~30~8~5 minecraft:log
setblock ~30~9~5 minecraft:leaves
fill ~30~10~5 ~30~10~7 minecraft:leaves
fill ~30~11~5 ~30~11~6 minecraft:leaves
setblock ~30~12~5 minecraft:leaves
fill ~30~13~5 ~32~13~5 minecraft:leaves
setblock ~31~8~5 minecraft:leaves
fill ~31~12~5 ~31~12~6 minecraft:leaves
fill ~3~5~6 ~13~5~6 minecraft:grass
fill ~3~6~6 ~4~10~6 minecraft:stained_hardened_clay 3
fill ~4~12~6 ~6~14~6 minecraft:packed_ice
fill ~4~16~6 ~28~16~8 minecraft:stained_hardened_clay 3
fill ~5~6~6 ~5~6~7 minecraft:stained_hardened_clay 11
fill ~5~7~6 ~5~10~6 minecraft:stained_hardened_clay 11
fill ~6~6~6 ~10~6~6 minecraft:stained_hardened_clay 3
fill ~6~10~6 ~11~10~6 minecraft:stained_hardened_clay 11
fill ~7~17~6 ~7~20~6 minecraft:stained_hardened_clay 5
fill ~8~12~6 ~8~14~6 minecraft:packed_ice
fill ~10~12~6 ~12~14~6 minecraft:packed_ice
fill ~10~17~6 ~10~20~6 minecraft:stained_hardened_clay 5
fill ~11~6~6 ~11~9~6 minecraft:stained_hardened_clay 11
fill ~12~6~6 ~13~10~6 minecraft:stained_hardened_clay 3
fill ~13~17~6 ~13~20~6 minecraft:stained_hardened_clay 5
fill ~14~5~6 ~14~5~20 minecraft:stripped_crimson_stem
setblock ~14~11~6 minecraft:stained_hardened_clay 5
setblock ~16~11~6 minecraft:stained_hardened_clay 5
fill ~16~17~6 ~16~20~6 minecraft:stained_hardened_clay 5
fill ~18~5~6 ~18~5~20 minecraft:stripped_crimson_stem
setblock ~18~11~6 minecraft:stained_hardened_clay 5
fill ~19~5~6 ~29~5~6 minecraft:grass
fill ~19~6~6 ~20~10~6 minecraft:stained_hardened_clay 3
fill ~19~17~6 ~19~20~6 minecraft:stained_hardened_clay 5
fill ~20~12~6 ~22~14~6 minecraft:packed_ice
fill ~21~6~6 ~21~10~6 minecraft:stained_hardened_clay 11
fill ~22~6~6 ~27~6~6 minecraft:stained_hardened_clay 3
fill ~22~10~6 ~28~10~6 minecraft:stained_hardened_clay 11
fill ~22~17~6 ~22~20~6 minecraft:stained_hardened_clay 5
fill ~24~12~6 ~24~14~6 minecraft:packed_ice
fill ~25~17~6 ~25~20~6 minecraft:stained_hardened_clay 5
fill ~26~12~6 ~28~14~6 minecraft:packed_ice
fill ~28~6~6 ~28~9~6 minecraft:stained_hardened_clay 11
fill ~29~6~6 ~29~10~21 minecraft:stained_hardened_clay 3
fill ~30~8~6 ~30~9~6 minecraft:leaves
fill ~30~12~6 ~30~13~6 minecraft:leaves
fill ~31~10~6 ~31~10~7 minecraft:leaves
setblock ~31~13~6 minecraft:leaves
fill ~3~5~7 ~3~5~21 minecraft:grass
fill ~3~6~7 ~3~11~21 minecraft:stained_hardened_clay 3
setblock ~4~5~7 minecraft:grass
fill ~4~9~7 ~4~9~11 minecraft:stained_hardened_clay 3
fill ~5~5~7 ~5~5~8 minecraft:grass
fill ~5~7~7 ~11~9~7 minecraft:packed_ice
fill ~5~17~7 ~27~17~19 minecraft:stained_hardened_clay 13
fill ~5~18~7 ~27~20~7 minecraft:stained_hardened_clay 13
fill ~6~5~7 ~12~5~7 minecraft:grass
setblock ~7~21~7 minecraft:stained_hardened_clay 5
setblock ~10~21~7 minecraft:stained_hardened_clay 5
fill ~12~11~7 ~13~11~8 minecraft:stained_hardened_clay 3
fill ~13~5~7 ~13~5~8 minecraft:grass
fill ~13~6~7 ~13~10~8 minecraft:stained_hardened_clay 3
fill ~13~15~7 ~13~15~8 minecraft:stained_hardened_clay 3
setblock ~13~21~7 minecraft:stained_hardened_clay 5
setblock ~14~9~7 minecraft:sea_lantern
fill ~14~10~7 ~14~15~7 minecraft:stained_hardened_clay 13
setblock ~15~9~7 minecraft:stained_hardened_clay 5
setblock ~15~10~7 minecraft:packed_ice
setblock ~16~9~7 minecraft:sea_lantern
fill ~16~10~7 ~16~15~7 minecraft:stained_hardened_clay 13
setblock ~16~21~7 minecraft:stained_hardened_clay 5
setblock ~17~9~7 minecraft:stained_hardened_clay 5
setblock ~17~10~7 minecraft:packed_ice
setblock ~18~9~7 minecraft:sea_lantern
fill ~18~10~7 ~18~15~7 minecraft:stained_hardened_clay 13
fill ~19~5~7 ~19~5~8 minecraft:grass
fill ~19~6~7 ~19~11~8 minecraft:stained_hardened_clay 3
setblock ~19~21~7 minecraft:stained_hardened_clay 5
fill ~20~5~7 ~23~5~7 minecraft:grass
fill ~21~7~7 ~27~9~7 minecraft:packed_ice
setblock ~22~21~7 minecraft:stained_hardened_clay 5
fill ~24~5~7 ~24~5~8 minecraft:grass
fill ~24~6~7 ~24~6~8 minecraft:clay
fill ~25~5~7 ~28~5~7 minecraft:grass
setblock ~25~21~7 minecraft:stained_hardened_clay 5
fill ~29~5~7 ~29~5~21 minecraft:grass
fill ~29~11~7 ~29~11~21 minecraft:stained_hardened_clay 3
fill ~29~15~7 ~29~15~21 minecraft:stained_hardened_clay 3
setblock ~30~9~7 minecraft:leaves
setblock ~4~5~8 minecraft:grass
fill ~4~6~8 ~4~7~11 minecraft:stained_hardened_clay 3
fill ~4~8~8 ~4~8~9 minecraft:stained_hardened_clay 3
fill ~4~10~8 ~4~10~11 minecraft:stained_hardened_clay 3
fill ~4~11~8 ~4~15~8 minecraft:stained_hardened_clay 3
fill ~5~6~8 ~5~11~8 minecraft:concrete 15
fill ~5~12~8 ~12~12~21 minecraft:stained_hardened_clay 3
fill ~5~13~8 ~12~15~8 minecraft:stained_hardened_clay 3
fill ~5~18~8 ~5~20~19 minecraft:stained_hardened_clay 13
fill ~6~5~8 ~12~5~8 minecraft:grass
fill ~6~6~8 ~7~11~8 minecraft:stained_hardened_clay 3
fill ~6~20~8 ~27~20~19 minecraft:stained_hardened_clay 13
fill ~6~21~8 ~26~21~18 minecraft:stained_hardened_clay 13
fill ~7~22~8 ~7~22~18 minecraft:stained_hardened_clay 5
fill ~8~6~8 ~9~8~8 minecraft:clay
fill ~8~9~8 ~12~10~8 minecraft:stained_hardened_clay 3
fill ~8~11~8 ~11~11~8 minecraft:stained_hardened_clay 3
fill ~10~6~8 ~12~8~8 minecraft:stained_hardened_clay 3
fill ~10~22~8 ~10~22~9 minecraft:stained_hardened_clay 5
fill ~13~22~8 ~13~22~9 minecraft:stained_hardened_clay 5
fill ~14~9~8 ~18~10~8 minecraft:stained_hardened_clay 3
fill ~14~11~8 ~14~15~8 minecraft:stained_hardened_clay 13
fill ~15~11~8 ~15~15~8 minecraft:packed_ice
fill ~16~11~8 ~16~15~8 minecraft:stained_hardened_clay 5
fill ~16~22~8 ~16~22~9 minecraft:stained_hardened_clay 5
fill ~17~11~8 ~17~15~8 minecraft:packed_ice
fill ~18~11~8 ~18~15~8 minecraft:stained_hardened_clay 13
fill ~19~22~8 ~19~22~9 minecraft:stained_hardened_clay 5
fill ~20~5~8 ~23~5~8 minecraft:grass
fill ~20~6~8 ~22~15~8 minecraft:stained_hardened_clay 3
fill ~22~22~8 ~22~22~9 minecraft:stained_hardened_clay 5
fill ~23~6~8 ~23~8~8 minecraft:clay
fill ~23~9~8 ~26~15~8 minecraft:stained_hardened_clay 3
fill ~24~7~8 ~24~8~8 minecraft:clay
fill ~25~5~8 ~28~5~8 minecraft:grass
fill ~25~6~8 ~26~8~8 minecraft:stained_hardened_clay 3
fill ~25~22~8 ~25~22~18 minecraft:stained_hardened_clay 5
fill ~27~6~8 ~27~11~8 minecraft:concrete 15
fill ~27~12~8 ~28~12~21 minecraft:stained_hardened_clay 3
fill ~27~13~8 ~28~15~8 minecraft:stained_hardened_clay 3
fill ~27~18~8 ~27~19~19 minecraft:stained_hardened_clay 13
fill ~28~6~8 ~28~7~11 minecraft:stained_hardened_clay 3
fill ~28~8~8 ~28~10~9 minecraft:stained_hardened_clay 3
setblock ~28~11~8 minecraft:stained_hardened_clay 3
fill ~4~5~9 ~13~5~15 minecraft:stripped_crimson_stem
fill ~4~11~9 ~28~11~9 minecraft:sea_lantern
fill ~4~12~9 ~4~12~21 minecraft:stained_hardened_clay 3
fill ~4~13~9 ~28~13~9 minecraft:glowstone
fill ~4~16~9 ~5~16~20 minecraft:stained_hardened_clay 3
fill ~4~17~9 ~4~20~9 minecraft:stained_hardened_clay 5
setblock ~5~21~9 minecraft:stained_hardened_clay 5
setblock ~6~22~9 minecraft:stained_hardened_clay 5
fill ~8~22~9 ~9~22~9 minecraft:stained_hardened_clay 5
fill ~11~22~9 ~12~22~9 minecraft:stained_hardened_clay 5
fill ~12~6~9 ~12~6~12 minecraft:log
fill ~12~7~9 ~12~7~10 minecraft:stained_glass_pane
fill ~14~12~9 ~18~12~21 minecraft:stained_hardened_clay 3
fill ~14~22~9 ~15~22~9 minecraft:stained_hardened_clay 5
fill ~17~22~9 ~18~22~9 minecraft:stained_hardened_clay 5
fill ~19~5~9 ~28~5~15 minecraft:stripped_crimson_stem
fill ~20~6~9 ~20~6~12 minecraft:log
fill ~20~7~9 ~20~7~10 minecraft:stained_glass_pane
fill ~20~12~9 ~26~12~21 minecraft:stained_hardened_clay 3
fill ~20~22~9 ~21~22~9 minecraft:stained_hardened_clay 5
fill ~23~22~9 ~24~22~9 minecraft:stained_hardened_clay 5
setblock ~26~22~9 minecraft:stained_hardened_clay 5
fill ~27~16~9 ~28~16~20 minecraft:stained_hardened_clay 3
setblock ~27~21~9 minecraft:stained_hardened_clay 5
fill ~28~17~9 ~28~20~9 minecraft:stained_hardened_clay 5
setblock ~4~8~10 minecraft:sea_lantern
fill ~4~11~10 ~4~11~11 minecraft:sea_lantern
fill ~4~13~10 ~4~13~20 minecraft:glowstone
setblock ~8~11~10 minecraft:sea_lantern
fill ~16~11~10 ~16~11~20 minecraft:sea_lantern
setblock ~24~11~10 minecraft:sea_lantern
setblock ~28~8~10 minecraft:sea_lantern
fill ~28~9~10 ~28~10~11 minecraft:stained_hardened_clay 3
fill ~28~11~10 ~28~11~11 minecraft:sea_lantern
fill ~28~13~10 ~28~13~20 minecraft:glowstone
setblock ~4~8~11 minecraft:stained_hardened_clay 3
setblock ~7~11~11 minecraft:sea_lantern
setblock ~25~11~11 minecraft:sea_lantern
setblock ~28~8~11 minecraft:stained_hardened_clay 3
fill ~4~6~12 ~4~11~12 minecraft:concrete 15
fill ~4~17~12 ~4~20~12 minecraft:stained_hardened_clay 5
fill ~5~6~12 ~10~6~12 minecraft:log
fill ~5~7~12 ~8~7~12 minecraft:stained_glass_pane
setblock ~5~21~12 minecraft:stained_hardened_clay 5
setblock ~6~11~12 minecraft:sea_lantern
setblock ~6~22~12 minecraft:stained_hardened_clay 5
setblock ~9~7~12 minecraft:stone_block_slab
setblock ~11~6~12 minecraft:spruce_trapdoor
setblock ~21~6~12 minecraft:spruce_trapdoor
fill ~22~6~12 ~27~6~12 minecraft:log
setblock ~23~7~12 minecraft:stone_block_slab
fill ~24~7~12 ~27~7~12 minecraft:stained_glass_pane
setblock ~26~11~12 minecraft:sea_lantern
setblock ~26~22~12 minecraft:stained_hardened_clay 5
setblock ~27~21~12 minecraft:stained_hardened_clay 5
fill ~28~6~12 ~28~11~12 minecraft:concrete 15
fill ~28~17~12 ~28~20~12 minecraft:stained_hardened_clay 5
fill ~4~6~13 ~4~7~15 minecraft:stained_hardened_clay 3
fill ~4~8~13 ~4~10~13 minecraft:stained_hardened_clay 3
fill ~4~11~13 ~5~11~15 minecraft:sea_lantern
fill ~5~6~13 ~5~6~20 minecraft:log
fill ~27~6~13 ~27~6~20 minecraft:log
fill ~27~11~13 ~28~11~15 minecraft:sea_lantern
fill ~28~6~13 ~28~7~15 minecraft:stained_hardened_clay 3
fill ~28~8~13 ~28~10~13 minecraft:stained_hardened_clay 3
setblock ~4~8~14 minecraft:sea_lantern
fill ~4~9~14 ~4~10~15 minecraft:stained_hardened_clay 3
fill ~6~11~14 ~15~11~14 minecraft:sea_lantern
fill ~17~11~14 ~26~11~14 minecraft:sea_lantern
setblock ~28~8~14 minecraft:sea_lantern
fill ~28~9~14 ~28~10~15 minecraft:stained_hardened_clay 3
setblock ~4~8~15 minecraft:stained_hardened_clay 3
fill ~4~17~15 ~4~20~15 minecraft:stained_hardened_clay 5
fill ~5~7~15 ~6~7~15 minecraft:stained_glass_pane
setblock ~5~21~15 minecraft:stained_hardened_clay 5
setblock ~6~6~15 minecraft:stained_glass_pane
setblock ~6~22~15 minecraft:stained_hardened_clay 5
setblock ~17~11~15 minecraft:sea_lantern
fill ~26~6~15 ~26~7~15 minecraft:stained_glass_pane
setblock ~26~22~15 minecraft:stained_hardened_clay 5
setblock ~27~7~15 minecraft:stained_glass_pane
setblock ~27~21~15 minecraft:stained_hardened_clay 5
setblock ~28~8~15 minecraft:stained_hardened_clay 3
fill ~28~17~15 ~28~20~15 minecraft:stained_hardened_clay 5
fill ~4~5~16 ~5~5~20 minecraft:stripped_crimson_stem
fill ~4~6~16 ~4~11~16 minecraft:concrete 15
fill ~6~5~16 ~6~5~18 minecraft:glowstone
setblock ~6~11~16 minecraft:sea_lantern
fill ~7~5~16 ~13~5~18 minecraft:stripped_crimson_stem
fill ~19~5~16 ~25~5~18 minecraft:stripped_crimson_stem
fill ~26~5~16 ~26~5~18 minecraft:glowstone
setblock ~26~11~16 minecraft:sea_lantern
fill ~27~5~16 ~28~5~20 minecraft:stripped_crimson_stem
fill ~28~6~16 ~28~11~16 minecraft:concrete 15
fill ~4~6~17 ~4~7~19 minecraft:stained_hardened_clay 3
fill ~4~8~17 ~4~10~17 minecraft:stained_hardened_clay 3
fill ~4~11~17 ~4~11~19 minecraft:sea_lantern
setblock ~7~11~17 minecraft:sea_lantern
setblock ~25~11~17 minecraft:sea_lantern
fill ~28~6~17 ~28~7~19 minecraft:stained_hardened_clay 3
fill ~28~8~17 ~28~10~17 minecraft:stained_hardened_clay 3
fill ~28~11~17 ~28~11~19 minecraft:sea_lantern
setblock ~4~8~18 minecraft:sea_lantern
fill ~4~9~18 ~4~10~19 minecraft:stained_hardened_clay 3
fill ~4~17~18 ~4~20~18 minecraft:stained_hardened_clay 5
setblock ~5~21~18 minecraft:stained_hardened_clay 5
setblock ~6~22~18 minecraft:stained_hardened_clay 5
setblock ~8~11~18 minecraft:sea_lantern
fill ~8~22~18 ~24~22~18 minecraft:stained_hardened_clay 5
setblock ~24~11~18 minecraft:sea_lantern
setblock ~26~22~18 minecraft:stained_hardened_clay 5
setblock ~27~21~18 minecraft:stained_hardened_clay 5
setblock ~28~8~18 minecraft:sea_lantern
fill ~28~9~18 ~28~10~19 minecraft:stained_hardened_clay 3
fill ~28~17~18 ~28~20~18 minecraft:stained_hardened_clay 5
setblock ~4~8~19 minecraft:stained_hardened_clay 3
fill ~5~7~19 ~6~7~20 minecraft:stained_glass_pane
fill ~6~5~19 ~6~5~20 minecraft:stripped_crimson_stem
setblock ~6~6~19 minecraft:stained_glass_pane
fill ~6~16~19 ~26~16~20 minecraft:stained_hardened_clay 3
fill ~6~18~19 ~26~19~19 minecraft:stained_hardened_clay 13
fill ~7~5~19 ~9~5~19 minecraft:glowstone
setblock ~7~21~19 minecraft:stained_hardened_clay 5
fill ~9~11~19 ~9~11~20 minecraft:sea_lantern
fill ~10~5~19 ~10~5~20 minecraft:stripped_crimson_stem
fill ~10~6~19 ~10~7~19 minecraft:stained_glass_pane
setblock ~10~21~19 minecraft:stained_hardened_clay 5
fill ~11~5~19 ~13~5~19 minecraft:glowstone
setblock ~13~21~19 minecraft:stained_hardened_clay 5
fill ~14~6~19 ~14~7~19 minecraft:stained_glass_pane
fill ~15~5~19 ~17~5~19 minecraft:glowstone
setblock ~16~21~19 minecraft:stained_hardened_clay 5
fill ~18~6~19 ~18~7~19 minecraft:stained_glass_pane
fill ~19~5~19 ~21~5~19 minecraft:glowstone
setblock ~19~21~19 minecraft:stained_hardened_clay 5
fill ~22~5~19 ~22~5~20 minecraft:stripped_crimson_stem
fill ~22~6~19 ~22~7~19 minecraft:stained_glass_pane
setblock ~22~21~19 minecraft:stained_hardened_clay 5
fill ~23~5~19 ~25~5~19 minecraft:glowstone
fill ~23~11~19 ~23~11~20 minecraft:sea_lantern
setblock ~25~21~19 minecraft:stained_hardened_clay 5
fill ~26~5~19 ~26~5~20 minecraft:stripped_crimson_stem
fill ~26~6~19 ~26~7~19 minecraft:stained_glass_pane
fill ~27~7~19 ~27~7~20 minecraft:stained_glass_pane
setblock ~28~8~19 minecraft:stained_hardened_clay 3
fill ~4~6~20 ~4~11~20 minecraft:concrete 15
fill ~5~11~20 ~8~11~20 minecraft:sea_lantern
fill ~5~13~20 ~27~13~20 minecraft:glowstone
fill ~6~6~20 ~26~6~20 minecraft:log
fill ~7~5~20 ~9~5~20 minecraft:stripped_crimson_stem
fill ~7~17~20 ~7~20~20 minecraft:stained_hardened_clay 5
setblock ~10~7~20 minecraft:stained_glass_pane
fill ~10~11~20 ~15~11~20 minecraft:sea_lantern
fill ~10~17~20 ~10~20~20 minecraft:stained_hardened_clay 5
fill ~11~5~20 ~13~5~20 minecraft:stripped_crimson_stem
fill ~13~17~20 ~13~20~20 minecraft:stained_hardened_clay 5
setblock ~14~7~20 minecraft:stained_glass_pane
fill ~15~5~20 ~17~5~20 minecraft:stripped_crimson_stem
fill ~16~17~20 ~16~20~20 minecraft:stained_hardened_clay 5
fill ~17~11~20 ~22~11~20 minecraft:sea_lantern
setblock ~18~7~20 minecraft:stained_glass_pane
fill ~19~5~20 ~21~5~20 minecraft:stripped_crimson_stem
fill ~19~17~20 ~19~20~20 minecraft:stained_hardened_clay 5
setblock ~22~7~20 minecraft:stained_glass_pane
fill ~22~17~20 ~22~20~20 minecraft:stained_hardened_clay 5
fill ~23~5~20 ~25~5~20 minecraft:stripped_crimson_stem
fill ~24~11~20 ~27~11~20 minecraft:sea_lantern
fill ~25~17~20 ~25~20~20 minecraft:stained_hardened_clay 5
setblock ~26~7~20 minecraft:stained_glass_pane
fill ~28~6~20 ~28~11~20 minecraft:concrete 15
fill ~4~5~21 ~7~5~21 minecraft:grass
fill ~4~6~21 ~7~6~21 minecraft:stained_hardened_clay 3
fill ~4~7~21 ~6~7~21 minecraft:stained_hardened_clay 3
fill ~4~8~21 ~5~8~21 minecraft:stained_hardened_clay 3
fill ~4~9~21 ~4~11~21 minecraft:stained_hardened_clay 3
fill ~4~13~21 ~28~15~21 minecraft:stained_hardened_clay 3
setblock ~5~9~21 minecraft:glowstone
fill ~5~10~21 ~11~11~21 minecraft:stained_hardened_clay 3
setblock ~6~8~21 minecraft:glowstone
fill ~6~9~21 ~10~9~21 minecraft:stained_hardened_clay 3
setblock ~7~7~21 minecraft:glowstone
fill ~7~8~21 ~9~8~21 minecraft:stained_hardened_clay 3
fill ~8~5~21 ~8~5~25 minecraft:grass
setblock ~8~6~21 minecraft:glowstone
setblock ~8~7~21 minecraft:stained_hardened_clay 3
fill ~9~5~21 ~15~5~21 minecraft:grass
fill ~9~6~21 ~15~6~21 minecraft:stained_hardened_clay 3
setblock ~9~7~21 minecraft:glowstone
fill ~10~7~21 ~14~7~21 minecraft:stained_hardened_clay 3
setblock ~10~8~21 minecraft:glowstone
fill ~11~8~21 ~13~8~21 minecraft:stained_hardened_clay 3
setblock ~11~9~21 minecraft:glowstone
setblock ~12~9~21 minecraft:stained_hardened_clay 3
setblock ~12~10~21 minecraft:glowstone
fill ~12~11~21 ~28~11~21 minecraft:stained_hardened_clay 3
setblock ~13~9~21 minecraft:glowstone
fill ~13~10~21 ~19~10~21 minecraft:stained_hardened_clay 3
setblock ~14~8~21 minecraft:glowstone
fill ~14~9~21 ~18~9~21 minecraft:stained_hardened_clay 3
setblock ~15~7~21 minecraft:glowstone
fill ~15~8~21 ~17~8~21 minecraft:stained_hardened_clay 3
fill ~16~5~21 ~16~5~25 minecraft:grass
setblock ~16~6~21 minecraft:glowstone
setblock ~16~7~21 minecraft:stained_hardened_clay 3
fill ~17~5~21 ~23~5~21 minecraft:grass
fill ~17~6~21 ~23~6~21 minecraft:stained_hardened_clay 3
setblock ~17~7~21 minecraft:glowstone
fill ~18~7~21 ~22~7~21 minecraft:stained_hardened_clay 3
setblock ~18~8~21 minecraft:glowstone
fill ~19~8~21 ~21~8~21 minecraft:stained_hardened_clay 3
setblock ~19~9~21 minecraft:glowstone
setblock ~20~9~21 minecraft:stained_hardened_clay 3
setblock ~20~10~21 minecraft:glowstone
setblock ~21~9~21 minecraft:glowstone
fill ~21~10~21 ~28~10~21 minecraft:stained_hardened_clay 3
setblock ~22~8~21 minecraft:glowstone
fill ~22~9~21 ~26~9~21 minecraft:stained_hardened_clay 3
setblock ~23~7~21 minecraft:glowstone
fill ~23~8~21 ~25~8~21 minecraft:stained_hardened_clay 3
fill ~24~5~21 ~24~5~23 minecraft:grass
setblock ~24~6~21 minecraft:glowstone
setblock ~24~7~21 minecraft:stained_hardened_clay 3
fill ~25~5~21 ~28~5~21 minecraft:grass
fill ~25~6~21 ~28~6~21 minecraft:stained_hardened_clay 3
setblock ~25~7~21 minecraft:glowstone
fill ~26~7~21 ~28~7~21 minecraft:stained_hardened_clay 3
setblock ~26~8~21 minecraft:glowstone
fill ~27~8~21 ~28~8~21 minecraft:stained_hardened_clay 3
setblock ~27~9~21 minecraft:glowstone
setblock ~28~9~21 minecraft:stained_hardened_clay 3
fill ~2~5~22 ~7~5~23 minecraft:grass
fill ~3~8~22 ~7~8~23 minecraft:leaves
fill ~4~9~22 ~7~9~23 minecraft:leaves
fill ~9~5~22 ~15~5~23 minecraft:grass
fill ~11~8~22 ~13~9~23 minecraft:leaves
fill ~14~9~22 ~14~9~26 minecraft:leaves
fill ~17~5~22 ~23~5~25 minecraft:grass
fill ~23~8~22 ~26~8~23 minecraft:leaves
fill ~23~9~22 ~25~9~23 minecraft:leaves
fill ~25~5~22 ~29~5~25 minecraft:grass
fill ~3~9~23 ~3~9~25 minecraft:leaves
fill ~4~10~23 ~5~10~23 minecraft:leaves
fill ~5~11~23 ~5~11~25 minecraft:leaves
fill ~10~8~23 ~10~9~25 minecraft:leaves
fill ~11~10~23 ~12~10~23 minecraft:leaves
fill ~12~11~23 ~12~11~25 minecraft:leaves
fill ~14~8~23 ~14~8~26 minecraft:leaves
fill ~22~8~23 ~22~9~25 minecraft:leaves
fill ~24~10~23 ~25~10~23 minecraft:leaves
fill ~24~11~23 ~24~11~25 minecraft:leaves
fill ~26~9~23 ~26~9~25 minecraft:leaves
fill ~31~5~23 ~32~5~25 minecraft:grass
fill ~2~5~24 ~4~5~25 minecraft:grass
fill ~3~8~24 ~4~8~26 minecraft:leaves
fill ~4~9~24 ~4~9~26 minecraft:leaves
fill ~4~10~24 ~4~11~24 minecraft:leaves
setblock ~5~5~24 minecraft:grass
fill ~5~6~24 ~5~10~24 minecraft:log
fill ~6~5~24 ~7~5~25 minecraft:grass
fill ~6~8~24 ~7~9~25 minecraft:leaves
fill ~6~10~24 ~6~10~25 minecraft:leaves
setblock ~6~11~24 minecraft:leaves
fill ~9~5~24 ~11~5~25 minecraft:grass
fill ~11~8~24 ~11~9~26 minecraft:leaves
fill ~11~10~24 ~11~10~25 minecraft:leaves
setblock ~11~11~24 minecraft:leaves
setblock ~12~5~24 minecraft:grass
fill ~12~6~24 ~12~10~24 minecraft:log
fill ~13~5~24 ~15~5~25 minecraft:grass
fill ~13~8~24 ~13~9~26 minecraft:leaves
fill ~13~10~24 ~13~10~25 minecraft:leaves
setblock ~13~11~24 minecraft:leaves
fill ~23~8~24 ~23~9~26 minecraft:leaves
fill ~23~10~24 ~23~11~24 minecraft:leaves
setblock ~24~5~24 minecraft:grass
fill ~24~6~24 ~24~10~24 minecraft:log
fill ~25~8~24 ~26~8~26 minecraft:leaves
fill ~25~9~24 ~25~9~26 minecraft:leaves
fill ~25~10~24 ~25~11~24 minecraft:leaves
setblock ~5~5~25 minecraft:grass
fill ~5~8~25 ~5~9~26 minecraft:leaves
setblock ~5~10~25 minecraft:leaves
setblock ~12~5~25 minecraft:grass
fill ~12~8~25 ~12~9~26 minecraft:leaves