fill ~2~0~0 ~61~0~0 minecraft:planks 0
fill ~25~1~0 ~38~1~0 minecraft:planks 0
fill ~25~2~0 ~26~4~0 minecraft:log 1
fill ~25~5~0 ~38~6~0 minecraft:planks 0
fill ~25~7~0 ~26~9~0 minecraft:log 1
fill ~25~10~0 ~38~11~0 minecraft:planks 0
fill ~25~12~0 ~26~14~0 minecraft:log 1
fill ~25~15~0 ~38~16~0 minecraft:planks 0
fill ~25~17~0 ~26~19~0 minecraft:log 1
fill ~25~20~0 ~38~20~0 minecraft:planks 0
fill ~27~2~0 ~27~4~0 minecraft:glass_pane
fill ~27~7~0 ~27~9~0 minecraft:glass_pane
fill ~27~12~0 ~27~14~0 minecraft:glass_pane
fill ~27~17~0 ~27~19~0 minecraft:glass_pane
fill ~28~2~0 ~29~4~0 minecraft:log 1
fill ~28~7~0 ~29~9~0 minecraft:log 1
fill ~28~12~0 ~29~14~0 minecraft:log 1
fill ~28~17~0 ~29~19~0 minecraft:log 1
fill ~30~2~0 ~30~4~0 minecraft:glass_pane
fill ~30~7~0 ~30~9~0 minecraft:glass_pane
fill ~30~12~0 ~30~14~0 minecraft:glass_pane
fill ~30~17~0 ~30~19~0 minecraft:glass_pane
fill ~31~2~0 ~32~4~0 minecraft:log 1
fill ~31~7~0 ~32~9~0 minecraft:log 1
fill ~31~12~0 ~32~14~0 minecraft:log 1
fill ~31~17~0 ~32~19~0 minecraft:log 1
fill ~33~2~0 ~33~4~0 minecraft:glass_pane
fill ~33~7~0 ~33~9~0 minecraft:glass_pane
fill ~33~12~0 ~33~14~0 minecraft:glass_pane
fill ~33~17~0 ~33~19~0 minecraft:glass_pane
fill ~34~2~0 ~35~4~0 minecraft:log 1
fill ~34~7~0 ~35~9~0 minecraft:log 1
fill ~34~12~0 ~35~14~0 minecraft:log 1
fill ~34~17~0 ~35~19~0 minecraft:log 1
fill ~36~2~0 ~36~4~0 minecraft:glass_pane
fill ~36~7~0 ~36~9~0 minecraft:glass_pane
fill ~36~12~0 ~36~14~0 minecraft:glass_pane
fill ~36~17~0 ~36~19~0 minecraft:glass_pane
fill ~37~2~0 ~38~4~0 minecraft:log 1
fill ~37~7~0 ~38~9~0 minecraft:log 1
fill ~37~12~0 ~38~14~0 minecraft:log 1
fill ~37~17~0 ~38~19~0 minecraft:log 1
fill ~62~0~0 ~62~0~63 minecraft:grass
fill ~2~0~1 ~8~0~1 minecraft:planks 0
fill ~9~0~1 ~13~0~6 minecraft:planks 1
fill ~9~1~1 ~13~27~1 minecraft:log 1
fill ~9~28~1 ~13~32~1 minecraft:planks 0
fill ~14~0~1 ~49~0~1 minecraft:planks 0
fill ~22~1~1 ~24~1~1 minecraft:planks 0
fill ~22~2~1 ~24~4~1 minecraft:log 1
fill ~22~5~1 ~24~6~1 minecraft:planks 0
fill ~22~7~1 ~24~9~1 minecraft:log 1
fill ~22~10~1 ~24~11~1 minecraft:planks 0
fill ~22~12~1 ~24~14~1 minecraft:log 1
fill ~22~15~1 ~24~16~1 minecraft:planks 0
fill ~22~17~1 ~24~19~1 minecraft:log 1
fill ~22~20~1 ~24~20~1 minecraft:planks 0
fill ~25~5~1 ~30~5~3 minecraft:wooden_slab 8
fill ~25~9~1 ~30~9~3 minecraft:wooden_slab 8
fill ~25~13~1 ~30~13~3 minecraft:wooden_slab 8
setblock ~30~14~1 minecraft:cobblestone_wall 1
setblock ~30~15~1 minecraft:wooden_slab 0
fill ~31~1~1 ~32~15~1 minecraft:ladder 3
fill ~31~16~1 ~32~16~1 minecraft:wooden_slab 0
fill ~33~5~1 ~38~5~3 minecraft:wooden_slab 8
fill ~33~9~1 ~38~9~3 minecraft:wooden_slab 8
fill ~33~13~1 ~38~13~3 minecraft:wooden_slab 8
setblock ~33~14~1 minecraft:cobblestone_wall 1
setblock ~33~15~1 minecraft:wooden_slab 0
fill ~39~1~1 ~41~1~1 minecraft:planks 0
fill ~39~2~1 ~41~4~1 minecraft:log 1
fill ~39~5~1 ~41~6~1 minecraft:planks 0
fill ~39~7~1 ~41~9~1 minecraft:log 1
fill ~39~10~1 ~41~11~1 minecraft:planks 0
fill ~39~12~1 ~41~14~1 minecraft:log 1
fill ~39~15~1 ~41~16~1 minecraft:planks 0
fill ~39~17~1 ~41~19~1 minecraft:log 1
fill ~39~20~1 ~41~20~1 minecraft:planks 0
fill ~50~0~1 ~54~0~6 minecraft:planks 1
fill ~50~1~1 ~54~27~1 minecraft:log 1
fill ~50~28~1 ~54~32~1 minecraft:planks 0
fill ~55~0~1 ~61~0~1 minecraft:planks 0
fill ~2~0~2 ~6~0~2 minecraft:planks 0
fill ~7~0~2 ~8~0~4 minecraft:planks 1
fill ~7~1~2 ~8~26~2 minecraft:log 1
setblock ~7~27~2 minecraft:log 1
fill ~7~28~2 ~8~32~2 minecraft:planks 0
fill ~8~27~2 ~14~27~2 minecraft:planks 0
fill ~8~33~2 ~14~33~2 minecraft:planks 0
fill ~9~5~2 ~13~5~2 minecraft:wooden_slab 8
fill ~9~9~2 ~13~9~2 minecraft:wooden_slab 8
fill ~9~13~2 ~13~13~2 minecraft:wooden_slab 8
fill ~9~16~2 ~13~16~2 minecraft:wool 11
fill ~9~17~2 ~13~17~16 minecraft:cobblestone_wall 0
fill ~9~26~2 ~13~26~2 minecraft:planks 0
fill ~9~34~2 ~13~34~2 minecraft:planks 0
fill ~14~0~2 ~15~0~4 minecraft:planks 1
fill ~14~1~2 ~15~26~2 minecraft:log 1
fill ~14~28~2 ~15~32~2 minecraft:planks 0
setblock ~15~27~2 minecraft:log 1
fill ~16~0~2 ~47~0~2 minecraft:planks 0
fill ~20~1~2 ~21~1~2 minecraft:planks 0
fill ~20~2~2 ~21~4~2 minecraft:log 1
fill ~20~5~2 ~21~6~2 minecraft:planks 0
fill ~20~7~2 ~21~9~2 minecraft:log 1
fill ~20~10~2 ~21~11~2 minecraft:planks 0
fill ~20~12~2 ~21~14~2 minecraft:log 1
fill ~20~15~2 ~21~16~2 minecraft:planks 0
fill ~20~17~2 ~21~19~2 minecraft:log 1
fill ~20~20~2 ~21~20~2 minecraft:planks 0
fill ~22~5~2 ~24~5~4 minecraft:wooden_slab 8
fill ~22~9~2 ~24~9~4 minecraft:wooden_slab 8
fill ~22~13~2 ~24~13~4 minecraft:wooden_slab 8
fill ~31~5~2 ~32~5~3 minecraft:wooden_slab 8
fill ~31~9~2 ~32~9~3 minecraft:wooden_slab 8
fill ~31~13~2 ~32~13~3 minecraft:wooden_slab 8
fill ~39~5~2 ~41~5~3 minecraft:wooden_slab 8
fill ~39~9~2 ~41~9~4 minecraft:wooden_slab 8
fill ~39~13~2 ~41~13~4 minecraft:wooden_slab 8
fill ~42~1~2 ~43~1~2 minecraft:planks 0
fill ~42~2~2 ~43~4~2 minecraft:log 1
fill ~42~5~2 ~43~6~2 minecraft:planks 0
fill ~42~7~2 ~43~9~2 minecraft:log 1
fill ~42~10~2 ~43~11~2 minecraft:planks 0
fill ~42~12~2 ~43~14~2 minecraft:log 1
fill ~42~15~2 ~43~16~2 minecraft:planks 0
fill ~42~17~2 ~43~19~2 minecraft:log 1
fill ~42~20~2 ~43~20~2 minecraft:planks 0
fill ~48~0~2 ~49~0~4 minecraft:planks 1
fill ~48~1~2 ~49~26~2 minecraft:log 1
setblock ~48~27~2 minecraft:log 1
fill ~48~28~2 ~49~32~2 minecraft:planks 0
fill ~49~27~2 ~55~27~2 minecraft:planks 0
fill ~49~33~2 ~55~33~2 minecraft:planks 0
fill ~50~5~2 ~54~5~2 minecraft:wooden_slab 8
fill ~50~9~2 ~54~9~2 minecraft:wooden_slab 8
fill ~50~13~2 ~54~13~2 minecraft:wooden_slab 8
fill ~50~16~2 ~54~16~2 minecraft:wool 11
fill ~50~17~2 ~54~17~16 minecraft:cobblestone_wall 0
fill ~50~26~2 ~54~26~2 minecraft:planks 0
fill ~50~34~2 ~54~34~2 minecraft:planks 0
fill ~55~0~2 ~56~0~4 minecraft:planks 1
fill ~55~1~2 ~56~26~2 minecraft:log 1
fill ~55~28~2 ~56~32~2 minecraft:planks 0
setblock ~56~27~2 minecraft:log 1
fill ~57~0~2 ~61~0~2 minecraft:planks 0
fill ~2~0~3 ~4~0~4 minecraft:planks 0
fill ~5~0~3 ~6~0~3 minecraft:planks 1
fill ~5~1~3 ~6~26~3 minecraft:log 1
fill ~5~27~3 ~5~29~3 minecraft:log 1
fill ~5~30~3 ~6~30~3 minecraft:planks 0
fill ~6~27~3 ~7~27~3 minecraft:planks 0
fill ~6~28~3 ~6~29~3 minecraft:planks 0
fill ~6~31~3 ~6~33~3 minecraft:planks 0
fill ~7~5~3 ~9~5~3 minecraft:wooden_slab 8
fill ~7~9~3 ~9~9~3 minecraft:wooden_slab 8
fill ~7~13~3 ~9~13~3 minecraft:wooden_slab 8
fill ~7~16~3 ~8~16~3 minecraft:wool 11
fill ~7~17~3 ~8~17~15 minecraft:cobblestone_wall 0
fill ~7~26~3 ~8~26~3 minecraft:planks 0
fill ~7~33~3 ~7~34~3 minecraft:planks 0
fill ~8~25~3 ~14~25~3 minecraft:planks 0
fill ~8~34~3 ~8~35~3 minecraft:planks 0
fill ~9~16~3 ~13~16~3 minecraft:wool 2
fill ~9~35~3 ~14~35~3 minecraft:planks 0
fill ~11~24~3 ~11~24~4 minecraft:planks 0
fill ~11~36~3 ~11~36~4 minecraft:planks 0
fill ~13~5~3 ~15~5~3 minecraft:wooden_slab 8
fill ~13~9~3 ~15~9~3 minecraft:wooden_slab 8
fill ~13~13~3 ~15~13~3 minecraft:wooden_slab 8
fill ~14~16~3 ~15~16~3 minecraft:wool 11
fill ~14~17~3 ~15~17~15 minecraft:cobblestone_wall 0
fill ~14~26~3 ~15~26~3 minecraft:planks 0
fill ~14~34~3 ~15~34~3 minecraft:planks 0
fill ~15~27~3 ~16~27~3 minecraft:planks 0
fill ~15~33~3 ~16~33~3 minecraft:planks 0
fill ~16~0~3 ~17~0~3 minecraft:planks 1
fill ~16~1~3 ~17~26~3 minecraft:log 1
fill ~16~28~3 ~16~32~3 minecraft:planks 0
fill ~17~27~3 ~17~29~3 minecraft:log 1
fill ~17~30~3 ~17~30~4 minecraft:planks 0
fill ~18~0~3 ~45~0~4 minecraft:planks 0
setblock ~19~1~3 minecraft:planks 0
fill ~19~2~3 ~19~4~3 minecraft:log 1
fill ~19~5~3 ~19~6~3 minecraft:planks 0
fill ~19~7~3 ~19~9~3 minecraft:log 1
fill ~19~10~3 ~19~11~3 minecraft:planks 0
fill ~19~12~3 ~19~14~3 minecraft:log 1
fill ~19~15~3 ~19~16~3 minecraft:planks 0
fill ~19~17~3 ~19~19~3 minecraft:log 1
setblock ~19~20~3 minecraft:planks 0
fill ~20~5~3 ~21~5~5 minecraft:wooden_slab 8
fill ~20~9~3 ~21~9~5 minecraft:wooden_slab 8
fill ~20~13~3 ~21~13~5 minecraft:wooden_slab 8
setblock ~24~6~3 minecraft:cobblestone_wall 1
setblock ~24~10~3 minecraft:cobblestone_wall 1
setblock ~24~14~3 minecraft:cobblestone_wall 1
fill ~25~6~3 ~39~6~3 minecraft:cobblestone_wall 1
fill ~25~10~3 ~38~10~3 minecraft:cobblestone_wall 1
fill ~25~14~3 ~29~14~3 minecraft:cobblestone_wall 1
setblock ~30~14~3 minecraft:cobblestone_wall 1
setblock ~33~14~3 minecraft:cobblestone_wall 1
fill ~34~14~3 ~38~14~3 minecraft:cobblestone_wall 1
setblock ~39~10~3 minecraft:cobblestone_wall 1
setblock ~39~14~3 minecraft:cobblestone_wall 1
setblock ~40~6~3 minecraft:cobblestone_wall 1
fill ~42~5~3 ~43~5~5 minecraft:wooden_slab 8
fill ~42~9~3 ~43~9~5 minecraft:wooden_slab 8
fill ~42~13~3 ~43~13~5 minecraft:wooden_slab 8
setblock ~44~1~3 minecraft:planks 0
fill ~44~2~3 ~44~4~3 minecraft:log 1
fill ~44~5~3 ~44~6~3 minecraft:planks 0
fill ~44~7~3 ~44~9~3 minecraft:log 1
fill ~44~10~3 ~44~11~3 minecraft:planks 0
fill ~44~12~3 ~44~14~3 minecraft:log 1
fill ~44~15~3 ~44~16~3 minecraft:planks 0
fill ~44~17~3 ~44~19~3 minecraft:log 1
setblock ~44~20~3 minecraft:planks 0
fill ~46~0~3 ~47~0~3 minecraft:planks 1
fill ~46~1~3 ~47~26~3 minecraft:log 1
fill ~46~27~3 ~46~29~3 minecraft:log 1
fill ~46~30~3 ~47~30~3 minecraft:planks 0
fill ~47~27~3 ~48~27~3 minecraft:planks 0
fill ~47~28~3 ~47~29~3 minecraft:planks 0
fill ~47~31~3 ~47~33~3 minecraft:planks 0
fill ~48~5~3 ~50~5~3 minecraft:wooden_slab 8
fill ~48~9~3 ~50~9~3 minecraft:wooden_slab 8
fill ~48~13~3 ~50~13~3 minecraft:wooden_slab 8
fill ~48~16~3 ~49~16~3 minecraft:wool 11
fill ~48~17~3 ~49~17~15 minecraft:cobblestone_wall 0
fill ~48~26~3 ~49~26~3 minecraft:planks 0
fill ~48~33~3 ~48~34~3 minecraft:planks 0
fill ~49~25~3 ~55~25~3 minecraft:planks 0
fill ~49~34~3 ~49~35~3 minecraft:planks 0
fill ~50~16~3 ~54~16~3 minecraft:wool 2
fill ~50~35~3 ~55~35~3 minecraft:planks 0
fill ~52~24~3 ~52~24~4 minecraft:planks 0
fill ~52~36~3 ~52~36~4 minecraft:planks 0
fill ~54~5~3 ~56~5~3 minecraft:wooden_slab 8
fill ~54~9~3 ~56~9~3 minecraft:wooden_slab 8
fill ~54~13~3 ~56~13~3 minecraft:wooden_slab 8
fill ~55~16~3 ~56~16~3 minecraft:wool 11
fill ~55~17~3 ~56~17~15 minecraft:cobblestone_wall 0
fill ~55~26~3 ~56~26~3 minecraft:planks 0
fill ~55~34~3 ~56~34~3 minecraft:planks 0
fill ~56~27~3 ~57~27~3 minecraft:planks 0
fill ~56~33~3 ~57~33~3 minecraft:planks 0
fill ~57~0~3 ~58~0~3 minecraft:planks 1
fill ~57~1~3 ~58~26~3 minecraft:log 1
fill ~57~28~3 ~57~32~3 minecraft:planks 0
fill ~58~27~3 ~58~29~3 minecraft:log 1
fill ~58~30~3 ~58~30~4 minecraft:planks 0
fill ~59~0~3 ~61~0~4 minecraft:planks 0
fill ~5~0~4 ~5~0~15 minecraft:planks 1
fill ~5~1~4 ~5~26~4 minecraft:log 1
fill ~5~27~4 ~5~27~5 minecraft:planks 0
fill ~5~28~4 ~5~33~4 minecraft:planks 0
setblock ~6~0~4 minecraft:wool 11
fill ~6~5~4 ~7~5~4 minecraft:wooden_slab 8
fill ~6~9~4 ~7~9~4 minecraft:wooden_slab 8
fill ~6~13~4 ~7~13~4 minecraft:wooden_slab 8
setblock ~6~16~4 minecraft:wool 11
fill ~6~17~4 ~6~17~14 minecraft:cobblestone_wall 0
setblock ~6~26~4 minecraft:planks 0
setblock ~6~34~4 minecraft:planks 0
fill ~7~16~4 ~8~16~4 minecraft:wool 2
setblock ~7~25~4 minecraft:planks 0
setblock ~7~35~4 minecraft:planks 0
fill ~8~24~4 ~10~24~4 minecraft:planks 0
fill ~8~36~4 ~10~36~4 minecraft:planks 0
fill ~9~16~4 ~13~16~4 minecraft:wool 4
fill ~12~24~4 ~14~24~4 minecraft:planks 0
fill ~12~36~4 ~14~36~4 minecraft:planks 0
fill ~14~16~4 ~15~16~4 minecraft:wool 2
fill ~15~5~4 ~16~5~4 minecraft:wooden_slab 8
fill ~15~9~4 ~16~9~4 minecraft:wooden_slab 8
fill ~15~13~4 ~16~13~4 minecraft:wooden_slab 8
setblock ~15~25~4 minecraft:planks 0
setblock ~15~35~4 minecraft:planks 0
setblock ~16~0~4 minecraft:wool 11
setblock ~16~16~4 minecraft:wool 11
fill ~16~17~4 ~16~17~14 minecraft:cobblestone_wall 0
setblock ~16~26~4 minecraft:planks 0
setblock ~16~34~4 minecraft:planks 0
fill ~17~0~4 ~17~0~14 minecraft:planks 1
fill ~17~1~4 ~17~26~4 minecraft:log 1
fill ~17~27~4 ~17~27~5 minecraft:planks 0
fill ~17~28~4 ~17~29~4 minecraft:planks 0
fill ~17~31~4 ~17~33~4 minecraft:planks 0
setblock ~18~1~4 minecraft:planks 0
fill ~18~2~4 ~18~4~6 minecraft:log 1
fill ~18~5~4 ~18~6~4 minecraft:planks 0
fill ~18~7~4 ~18~9~4 minecraft:log 1
fill ~18~10~4 ~18~11~4 minecraft:planks 0
fill ~18~12~4 ~18~14~4 minecraft:log 1
fill ~18~15~4 ~18~16~4 minecraft:planks 0
fill ~18~17~4 ~18~19~6 minecraft:log 1
setblock ~18~20~4 minecraft:planks 0
fill ~19~5~4 ~19~5~6 minecraft:wooden_slab 8
fill ~19~9~4 ~19~9~6 minecraft:wooden_slab 8
fill ~19~13~4 ~19~13~6 minecraft:wooden_slab 8
setblock ~19~16~4 minecraft:wooden_slab 8
setblock ~21~6~4 minecraft:cobblestone_wall 1
setblock ~21~10~4 minecraft:cobblestone_wall 1
setblock ~21~14~4 minecraft:cobblestone_wall 1
fill ~22~6~4 ~23~6~4 minecraft:cobblestone_wall 1
fill ~22~10~4 ~23~10~4 minecraft:cobblestone_wall 1
fill ~22~14~4 ~23~14~4 minecraft:cobblestone_wall 1
setblock ~24~6~4 minecraft:cobblestone_wall 1
setblock ~24~10~4 minecraft:cobblestone_wall 1
setblock ~24~14~4 minecraft:cobblestone_wall 1
setblock ~30~14~4 minecraft:cobblestone_wall 1
setblock ~30~15~4 minecraft:cobblestone_wall 1
fill ~31~14~4 ~32~14~4 minecraft:birch_stairs 2
setblock ~33~14~4 minecraft:cobblestone_wall 1
setblock ~33~15~4 minecraft:cobblestone_wall 1
setblock ~39~10~4 minecraft:cobblestone_wall 1
setblock ~39~14~4 minecraft:cobblestone_wall 1
fill ~40~5~4 ~41~5~4 minecraft:wooden_slab 8
setblock ~40~6~4 minecraft:cobblestone_wall 1
fill ~40~10~4 ~41~10~4 minecraft:cobblestone_wall 1
fill ~40~14~4 ~41~14~4 minecraft:cobblestone_wall 1
setblock ~41~6~4 minecraft:cobblestone_wall 1
setblock ~42~6~4 minecraft:cobblestone_wall 1
setblock ~42~10~4 minecraft:cobblestone_wall 1
setblock ~42~14~4 minecraft:cobblestone_wall 1
fill ~44~5~4 ~44~5~6 minecraft:wooden_slab 8
fill ~44~9~4 ~44~9~6 minecraft:wooden_slab 8
fill ~44~13~4 ~44~13~6 minecraft:wooden_slab 8
setblock ~45~1~4 minecraft:planks 0
fill ~45~2~4 ~46~4~4 minecraft:log 1
fill ~45~5~4 ~45~6~4 minecraft:planks 0
fill ~45~7~4 ~46~9~4 minecraft:log 1
fill ~45~10~4 ~45~11~4 minecraft:planks 0
fill ~45~12~4 ~46~14~4 minecraft:log 1
fill ~45~15~4 ~45~16~4 minecraft:planks 0
fill ~45~17~4 ~46~19~4 minecraft:log 1
setblock ~45~20~4 minecraft:planks 0
fill ~46~0~4 ~46~0~15 minecraft:planks 1
setblock ~46~1~4 minecraft:log 1
fill ~46~5~4 ~46~6~4 minecraft:log 1
fill ~46~10~4 ~46~11~4 minecraft:log 1
fill ~46~15~4 ~46~16~4 minecraft:log 1
fill ~46~20~4 ~46~26~4 minecraft:log 1
fill ~46~27~4 ~46~27~5 minecraft:planks 0
fill ~46~28~4 ~46~33~4 minecraft:planks 0
setblock ~47~0~4 minecraft:wool 2
fill ~47~5~4 ~48~5~4 minecraft:wooden_slab 8
fill ~47~9~4 ~48~9~4 minecraft:wooden_slab 8
fill ~47~13~4 ~48~13~4 minecraft:wooden_slab 8
setblock ~47~16~4 minecraft:wool 11
fill ~47~17~4 ~47~17~14 minecraft:cobblestone_wall 0
setblock ~47~26~4 minecraft:planks 0
setblock ~47~34~4 minecraft:planks 0
fill ~48~16~4 ~49~16~4 minecraft:wool 2
setblock ~48~25~4 minecraft:planks 0
setblock ~48~35~4 minecraft:planks 0
fill ~49~24~4 ~51~24~4 minecraft:planks 0
fill ~49~36~4 ~51~36~4 minecraft:planks 0
fill ~50~16~4 ~54~16~4 minecraft:wool 4
fill ~53~24~4 ~55~24~4 minecraft:planks 0
fill ~53~36~4 ~55~36~4 minecraft:planks 0
fill ~55~16~4 ~56~16~4 minecraft:wool 2
fill ~56~5~4 ~57~5~4 minecraft:wooden_slab 8
fill ~56~9~4 ~57~9~4 minecraft:wooden_slab 8
fill ~56~13~4 ~57~13~4 minecraft:wooden_slab 8
setblock ~56~25~4 minecraft:planks 0
setblock ~56~35~4 minecraft:planks 0
setblock ~57~0~4 minecraft:wool 2
setblock ~57~16~4 minecraft:wool 11
fill ~57~17~4 ~57~17~14 minecraft:cobblestone_wall 0
setblock ~57~26~4 minecraft:planks 0
setblock ~57~34~4 minecraft:planks 0
fill ~58~0~4 ~58~0~15 minecraft:planks 1
fill ~58~1~4 ~58~26~4 minecraft:log 1
fill ~58~27~4 ~58~27~5 minecraft:planks 0
fill ~58~28~4 ~58~29~4 minecraft:planks 0
fill ~58~31~4 ~58~33~4 minecraft:planks 0
fill ~2~0~5 ~3~0~6 minecraft:planks 0
fill ~4~0~5 ~4~0~13 minecraft:planks 1
fill ~4~1~5 ~4~26~6 minecraft:log 1
setblock ~4~27~5 minecraft:log 1
fill ~4~28~5 ~4~32~6 minecraft:planks 0
fill ~5~5~5 ~6~5~5 minecraft:wooden_slab 8
fill ~5~9~5 ~6~9~5 minecraft:wooden_slab 8
fill ~5~13~5 ~6~13~5 minecraft:wooden_slab 8
fill ~5~16~5 ~5~16~6 minecraft:wool 11
fill ~5~17~5 ~5~17~13 minecraft:cobblestone_wall 0
fill ~5~26~5 ~5~26~6 minecraft:planks 0
fill ~5~33~5 ~5~34~5 minecraft:planks 0
fill ~6~0~5 ~6~0~13 minecraft:planks 1
fill ~6~16~5 ~6~16~6 minecraft:wool 2
setblock ~6~25~5 minecraft:planks 0
setblock ~6~35~5 minecraft:planks 0
setblock ~7~0~5 minecraft:wool 11
fill ~7~16~5 ~8~16~5 minecraft:wool 4
setblock ~7~22~5 minecraft:glowstone
setblock ~7~23~5 minecraft:cobblestone_wall 0
fill ~7~24~5 ~8~24~5 minecraft:planks 0
fill ~7~36~5 ~8~36~5 minecraft:planks 0
setblock ~8~0~5 minecraft:planks 1
fill ~9~16~5 ~13~16~5 minecraft:wool 14
fill ~9~23~5 ~13~23~6 minecraft:planks 0
fill ~9~37~5 ~13~37~6 minecraft:planks 0
setblock ~14~0~5 minecraft:planks 1
fill ~14~16~5 ~15~16~5 minecraft:wool 4
fill ~14~24~5 ~15~24~5 minecraft:planks 0
fill ~14~36~5 ~15~36~5 minecraft:planks 0
setblock ~15~0~5 minecraft:wool 11
setblock ~15~22~5 minecraft:glowstone
setblock ~15~23~5 minecraft:cobblestone_wall 0
fill ~16~0~5 ~16~0~13 minecraft:planks 1
fill ~16~5~5 ~17~5~5 minecraft:wooden_slab 8
fill ~16~9~5 ~17~9~5 minecraft:wooden_slab 8
fill ~16~13~5 ~17~13~5 minecraft:wooden_slab 8
fill ~16~16~5 ~16~16~6 minecraft:wool 2
setblock ~16~25~5 minecraft:planks 0
setblock ~16~35~5 minecraft:planks 0
fill ~17~16~5 ~18~16~5 minecraft:wool 11
fill ~17~17~5 ~17~17~13 minecraft:cobblestone_wall 0
fill ~17~26~5 ~17~26~6 minecraft:planks 0
fill ~17~33~5 ~17~34~5 minecraft:planks 0
fill ~18~0~5 ~18~0~13 minecraft:planks 1
fill ~18~1~5 ~18~1~6 minecraft:log 1
setblock ~18~5~5 minecraft:glowstone
setblock ~18~8~5 minecraft:wool 11
setblock ~18~9~5 minecraft:glowstone
setblock ~18~12~5 minecraft:wool 11
setblock ~18~13~5 minecraft:glowstone
fill ~18~20~5 ~18~26~6 minecraft:log 1
setblock ~18~27~5 minecraft:log 1
fill ~18~28~5 ~18~32~6 minecraft:planks 0
fill ~19~0~5 ~44~0~6 minecraft:planks 0
setblock ~20~6~5 minecraft:cobblestone_wall 1
setblock ~20~10~5 minecraft:cobblestone_wall 1
setblock ~20~14~5 minecraft:cobblestone_wall 1
setblock ~21~6~5 minecraft:cobblestone_wall 1
setblock ~21~10~5 minecraft:cobblestone_wall 1
setblock ~21~14~5 minecraft:cobblestone_wall 1
setblock ~30~14~5 minecraft:cobblestone_wall 1
setblock ~30~15~5 minecraft:cobblestone_wall 1
setblock ~30~16~5 minecraft:cobblestone_wall 1
fill ~31~14~5 ~32~14~5 minecraft:log 3
fill ~31~15~5 ~32~15~5 minecraft:birch_stairs 2
setblock ~33~14~5 minecraft:cobblestone_wall 1
setblock ~33~15~5 minecraft:cobblestone_wall 1
setblock ~33~16~5 minecraft:cobblestone_wall 1
setblock ~42~6~5 minecraft:cobblestone_wall 1
setblock ~42~10~5 minecraft:cobblestone_wall 1
setblock ~42~14~5 minecraft:cobblestone_wall 1
setblock ~43~6~5 minecraft:cobblestone_wall 1
setblock ~43~10~5 minecraft:cobblestone_wall 1
setblock ~43~14~5 minecraft:cobblestone_wall 1
fill ~45~0~5 ~45~0~13 minecraft:planks 1
fill ~45~1~5 ~45~4~6 minecraft:log 1
setblock ~45~5~5 minecraft:glowstone
setblock ~45~8~5 minecraft:wool 2
setblock ~45~9~5 minecraft:glowstone
setblock ~45~12~5 minecraft:wool 2
setblock ~45~13~5 minecraft:glowstone
setblock ~45~16~5 minecraft:wool 2
fill ~45~17~5 ~45~26~6 minecraft:log 1
setblock ~45~27~5 minecraft:log 1
fill ~45~28~5 ~45~32~6 minecraft:planks 0
fill ~46~5~5 ~47~5~5 minecraft:wooden_slab 8
fill ~46~9~5 ~47~9~5 minecraft:wooden_slab 8
fill ~46~13~5 ~47~13~5 minecraft:wooden_slab 8
fill ~46~16~5 ~46~16~6 minecraft:wool 11
fill ~46~17~5 ~46~17~13 minecraft:cobblestone_wall 0
fill ~46~26~5 ~46~26~6 minecraft:planks 0
fill ~46~33~5 ~46~34~5 minecraft:planks 0
fill ~47~0~5 ~47~0~13 minecraft:planks 1
fill ~47~16~5 ~47~16~6 minecraft:wool 2
setblock ~47~25~5 minecraft:planks 0
setblock ~47~35~5 minecraft:planks 0
setblock ~48~0~5 minecraft:wool 2
fill ~48~16~5 ~49~16~5 minecraft:wool 4
setblock ~48~22~5 minecraft:glowstone
setblock ~48~23~5 minecraft:cobblestone_wall 0
fill ~48~24~5 ~49~24~5 minecraft:planks 0
fill ~48~36~5 ~49~36~5 minecraft:planks 0
setblock ~49~0~5 minecraft:planks 1
fill ~50~16~5 ~54~16~5 minecraft:wool 14
fill ~50~23~5 ~54~23~6 minecraft:planks 0
fill ~50~37~5 ~54~37~6 minecraft:planks 0
setblock ~55~0~5 minecraft:planks 1
fill ~55~16~5 ~56~16~5 minecraft:wool 4
fill ~55~24~5 ~56~24~5 minecraft:planks 0
fill ~55~36~5 ~56~36~5 minecraft:planks 0
setblock ~56~0~5 minecraft:wool 2
setblock ~56~22~5 minecraft:glowstone
setblock ~56~23~5 minecraft:cobblestone_wall 0
fill ~57~0~5 ~57~0~13 minecraft:planks 1
fill ~57~5~5 ~58~5~5 minecraft:wooden_slab 8
fill ~57~9~5 ~58~9~5 minecraft:wooden_slab 8
fill ~57~13~5 ~58~13~5 minecraft:wooden_slab 8
fill ~57~16~5 ~57~16~6 minecraft:wool 2
setblock ~57~25~5 minecraft:planks 0
setblock ~57~35~5 minecraft:planks 0
fill ~58~16~5 ~58~16~6 minecraft:wool 11
fill ~58~17~5 ~58~17~13 minecraft:cobblestone_wall 0
fill ~58~26~5 ~58~26~6 minecraft:planks 0
fill ~58~33~5 ~58~34~5 minecraft:planks 0
fill ~59~0~5 ~59~0~13 minecraft:planks 1
fill ~59~1~5 ~59~26~6 minecraft:log 1
setblock ~59~27~5 minecraft:log 1
fill ~59~28~5 ~59~32~6 minecraft:planks 0
fill ~60~0~5 ~61~0~6 minecraft:planks 0
fill ~4~27~6 ~4~27~12 minecraft:planks 0
fill ~4~33~6 ~4~33~12 minecraft:planks 0
fill ~5~5~6 ~5~5~7 minecraft:wooden_slab 8
fill ~5~9~6 ~5~9~7 minecraft:wooden_slab 8
fill ~5~13~6 ~5~13~7 minecraft:wooden_slab 8
fill ~5~25~6 ~5~25~12 minecraft:planks 0
fill ~5~34~6 ~5~35~6 minecraft:planks 0
fill ~6~24~6 ~7~24~6 minecraft:planks 0
fill ~6~36~6 ~7~36~6 minecraft:planks 0
fill ~7~0~6 ~7~0~12 minecraft:planks 1
setblock ~7~16~6 minecraft:wool 4
setblock ~8~0~6 minecraft:wool 11
setblock ~8~16~6 minecraft:wool 14
fill ~8~23~6 ~8~23~12 minecraft:planks 0
fill ~8~37~6 ~8~37~12 minecraft:planks 0
fill ~9~16~6 ~13~16~6 minecraft:wool 11
fill ~10~38~6 ~12~38~12 minecraft:planks 0
setblock ~14~0~6 minecraft:wool 11
setblock ~14~16~6 minecraft:wool 14
fill ~14~23~6 ~14~23~12 minecraft:planks 0
fill ~14~37~6 ~14~37~12 minecraft:planks 0
fill ~15~0~6 ~15~0~12 minecraft:planks 1
setblock ~15~16~6 minecraft:wool 4
fill ~15~24~6 ~16~24~6 minecraft:planks 0
fill ~15~36~6 ~16~36~6 minecraft:planks 0
setblock ~17~16~6 minecraft:wool 11
fill ~17~25~6 ~17~25~12 minecraft:planks 0
fill ~17~34~6 ~17~35~6 minecraft:planks 0
fill ~18~5~6 ~18~16~6 minecraft:log 1
fill ~18~27~6 ~18~27~12 minecraft:planks 0
fill ~18~33~6 ~18~33~8 minecraft:planks 0
setblock ~19~6~6 minecraft:cobblestone_wall 1
setblock ~19~10~6 minecraft:cobblestone_wall 1
setblock ~19~14~6 minecraft:cobblestone_wall 1
setblock ~20~5~6 minecraft:wooden_slab 8
setblock ~20~6~6 minecraft:cobblestone_wall 1
setblock ~20~9~6 minecraft:wooden_slab 8
setblock ~20~10~6 minecraft:cobblestone_wall 1
setblock ~20~13~6 minecraft:wooden_slab 8
setblock ~20~14~6 minecraft:cobblestone_wall 1
setblock ~30~15~6 minecraft:cobblestone_wall 1
setblock ~30~16~6 minecraft:cobblestone_wall 1
setblock ~30~17~6 minecraft:cobblestone_wall 1
fill ~31~15~6 ~32~15~6 minecraft:log 3
fill ~31~16~6 ~32~16~6 minecraft:birch_stairs 2
setblock ~33~15~6 minecraft:cobblestone_wall 1
setblock ~33~16~6 minecraft:cobblestone_wall 1
setblock ~33~17~6 minecraft:cobblestone_wall 1
setblock ~43~5~6 minecraft:wooden_slab 8
setblock ~43~6~6 minecraft:cobblestone_wall 1
setblock ~43~9~6 minecraft:wooden_slab 8
setblock ~43~10~6 minecraft:cobblestone_wall 1
setblock ~43~13~6 minecraft:wooden_slab 8
setblock ~43~14~6 minecraft:cobblestone_wall 1
setblock ~44~6~6 minecraft:cobblestone_wall 1
setblock ~44~10~6 minecraft:cobblestone_wall 1
setblock ~44~14~6 minecraft:cobblestone_wall 1
fill ~45~5~6 ~45~16~6 minecraft:log 1
fill ~45~27~6 ~45~27~12 minecraft:planks 0
fill ~45~33~6 ~45~33~8 minecraft:planks 0
fill ~46~25~6 ~46~25~12 minecraft:planks 0
fill ~46~34~6 ~46~35~6 minecraft:planks 0
fill ~47~24~6 ~48~24~6 minecraft:planks 0
fill ~47~36~6 ~48~36~6 minecraft:planks 0
fill ~48~0~6 ~48~0~12 minecraft:planks 1
setblock ~48~16~6 minecraft:wool 4
setblock ~49~0~6 minecraft:wool 2
setblock ~49~16~6 minecraft:wool 14
fill ~49~23~6 ~49~23~12 minecraft:planks 0
fill ~49~37~6 ~49~37~12 minecraft:planks 0
fill ~50~16~6 ~54~16~6 minecraft:wool 11
fill ~51~38~6 ~53~38~8 minecraft:planks 0
setblock ~55~0~6 minecraft:wool 2
setblock ~55~16~6 minecraft:wool 14
fill ~55~23~6 ~55~23~12 minecraft:planks 0
fill ~55~37~6 ~55~37~12 minecraft:planks 0
fill ~56~0~6 ~56~0~12 minecraft:planks 1
setblock ~56~16~6 minecraft:wool 4
fill ~56~24~6 ~57~24~6 minecraft:planks 0
fill ~56~36~6 ~57~36~6 minecraft:planks 0
fill ~58~5~6 ~58~5~7 minecraft:wooden_slab 8
fill ~58~9~6 ~58~9~7 minecraft:wooden_slab 8
fill ~58~13~6 ~58~13~7 minecraft:wooden_slab 8
fill ~58~25~6 ~58~25~12 minecraft:planks 0
fill ~58~34~6 ~58~35~6 minecraft:planks 0
fill ~59~27~6 ~59~27~12 minecraft:planks 0
fill ~59~33~6 ~59~33~12 minecraft:planks 0
fill ~2~0~7 ~2~0~36 minecraft:planks 0
fill ~3~0~7 ~3~0~11 minecraft:planks 1
fill ~3~1~7 ~3~27~11 minecraft:log 1
fill ~3~28~7 ~3~32~11 minecraft:planks 0
fill ~4~5~7 ~4~5~11 minecraft:wooden_slab 8
fill ~4~9~7 ~4~9~11 minecraft:wooden_slab 8
fill ~4~13~7 ~4~13~11 minecraft:wooden_slab 8
fill ~4~16~7 ~4~16~11 minecraft:wool 11
fill ~4~17~7 ~4~17~11 minecraft:cobblestone_wall 0
fill ~4~26~7 ~4~26~11 minecraft:planks 0
fill ~4~34~7 ~4~34~11 minecraft:planks 0
fill ~5~16~7 ~5~16~11 minecraft:wool 2
fill ~5~35~7 ~5~35~12 minecraft:planks 0
fill ~6~16~7 ~6~16~11 minecraft:wool 4
fill ~6~24~7 ~6~24~12 minecraft:planks 0
fill ~6~36~7 ~6~36~12 minecraft:planks 0
fill ~7~16~7 ~7~16~11 minecraft:wool 14
fill ~7~23~7 ~7~23~11 minecraft:planks 0
fill ~7~37~7 ~7~37~11 minecraft:planks 0
fill ~8~0~7 ~8~0~11 minecraft:planks 1
fill ~8~16~7 ~8~16~11 minecraft:wool 11
setblock ~9~0~7 minecraft:wool 11
fill ~9~16~7 ~13~16~7 minecraft:wool 2
fill ~9~22~7 ~13~22~8 minecraft:planks 0
fill ~9~38~7 ~9~38~11 minecraft:planks 0
setblock ~10~0~7 minecraft:planks 1
fill ~10~30~7 ~12~32~7 minecraft:glowstone
fill ~11~0~7 ~11~0~8 minecraft:glass
fill ~11~39~7 ~11~40~11 minecraft:planks 0
setblock ~12~0~7 minecraft:planks 1
setblock ~13~0~7 minecraft:wool 11
fill ~13~38~7 ~13~38~11 minecraft:planks 0
fill ~14~0~7 ~14~0~11 minecraft:planks 1
fill ~14~16~7 ~14~16~11 minecraft:wool 11
fill ~15~16~7 ~15~16~11 minecraft:wool 14
fill ~15~23~7 ~15~23~11 minecraft:planks 0
fill ~15~37~7 ~15~37~11 minecraft:planks 0
fill ~16~16~7 ~16~16~11 minecraft:wool 4
fill ~16~24~7 ~16~24~12 minecraft:planks 0
fill ~16~36~7 ~16~36~12 minecraft:planks 0
fill ~17~16~7 ~17~16~11 minecraft:wool 2
fill ~17~35~7 ~17~35~12 minecraft:planks 0
fill ~18~16~7 ~18~16~11 minecraft:wool 11
fill ~18~17~7 ~18~17~11 minecraft:cobblestone_wall 0
fill ~18~26~7 ~18~26~11 minecraft:planks 0
fill ~18~34~7 ~18~34~8 minecraft:planks 0
fill ~19~0~7 ~19~0~11 minecraft:planks 1
fill ~19~1~7 ~19~4~7 minecraft:wool 11
fill ~19~5~7 ~19~16~11 minecraft:log 1
fill ~19~17~7 ~19~17~8 minecraft:log 1
fill ~19~18~7 ~19~27~7 minecraft:log 1
fill ~19~28~7 ~19~32~11 minecraft:planks 0
fill ~20~0~7 ~43~0~17 minecraft:planks 0
setblock ~30~16~7 minecraft:cobblestone_wall 1
setblock ~30~17~7 minecraft:cobblestone_wall 1
setblock ~30~18~7 minecraft:cobblestone_wall 1
fill ~31~16~7 ~32~16~7 minecraft:log 3
fill ~31~17~7 ~32~17~7 minecraft:birch_stairs 2
setblock ~33~16~7 minecraft:cobblestone_wall 1
setblock ~33~17~7 minecraft:cobblestone_wall 1
setblock ~33~18~7 minecraft:cobblestone_wall 1
fill ~44~0~7 ~44~0~11 minecraft:planks 1
fill ~44~1~7 ~44~4~7 minecraft:wool 2
fill ~44~5~7 ~44~16~11 minecraft:log 1
fill ~44~17~7 ~44~17~8 minecraft:log 1
fill ~44~18~7 ~44~27~7 minecraft:log 1
fill ~44~28~7 ~44~32~11 minecraft:planks 0
fill ~45~16~7 ~45~16~11 minecraft:wool 11
fill ~45~17~7 ~45~17~11 minecraft:cobblestone_wall 0
fill ~45~26~7 ~45~26~11 minecraft:planks 0
fill ~45~34~7 ~45~34~8 minecraft:planks 0
fill ~46~16~7 ~46~16~11 minecraft:wool 2
fill ~46~35~7 ~46~35~12 minecraft:planks 0
fill ~47~16~7 ~47~16~11 minecraft:wool 4
fill ~47~24~7 ~47~24~12 minecraft:planks 0
fill ~47~36~7 ~47~36~12 minecraft:planks 0
fill ~48~16~7 ~48~16~11 minecraft:wool 14
fill ~48~23~7 ~48~23~11 minecraft:planks 0
fill ~48~37~7 ~48~37~11 minecraft:planks 0
fill ~49~0~7 ~49~0~11 minecraft:planks 1
fill ~49~16~7 ~49~16~11 minecraft:wool 11
setblock ~50~0~7 minecraft:wool 2
fill ~50~16~7 ~54~16~7 minecraft:wool 2
fill ~50~22~7 ~54~22~8 minecraft:planks 0
fill ~50~38~7 ~50~38~11 minecraft:planks 0
setblock ~51~0~7 minecraft:planks 1
fill ~51~30~7 ~53~32~7 minecraft:glowstone
fill ~52~0~7 ~52~0~8 minecraft:glass
fill ~52~39~7 ~52~40~7 minecraft:planks 0
setblock ~53~0~7 minecraft:planks 1
setblock ~54~0~7 minecraft:wool 2
fill ~54~38~7 ~54~38~11 minecraft:planks 0
fill ~55~0~7 ~55~0~11 minecraft:planks 1
fill ~55~16~7 ~55~16~11 minecraft:wool 11
fill ~56~16~7 ~56~16~11 minecraft:wool 14
fill ~56~23~7 ~56~23~11 minecraft:planks 0
fill ~56~37~7 ~56~37~11 minecraft:planks 0
fill ~57~16~7 ~57~16~11 minecraft:wool 4
fill ~57~24~7 ~57~24~12 minecraft:planks 0
fill ~57~36~7 ~57~36~12 minecraft:planks 0
fill ~58~16~7 ~58~16~11 minecraft:wool 2
fill ~58~35~7 ~58~35~12 minecraft:planks 0
fill ~59~5~7 ~59~5~11 minecraft:wooden_slab 8
fill ~59~9~7 ~59~9~11 minecraft:wooden_slab 8
fill ~59~13~7 ~59~13~11 minecraft:wooden_slab 8
fill ~59~16~7 ~59~16~11 minecraft:wool 11
fill ~59~17~7 ~59~17~11 minecraft:cobblestone_wall 0
fill ~59~26~7 ~59~26~11 minecraft:planks 0
fill ~59~34~7 ~59~34~11 minecraft:planks 0
fill ~60~0~7 ~60~0~11 minecraft:planks 1
fill ~60~1~7 ~60~27~11 minecraft:log 1
fill ~60~28~7 ~60~32~11 minecraft:planks 0
fill ~61~0~7 ~61~0~59 minecraft:planks 0
fill ~8~38~8 ~8~38~10 minecraft:planks 0
setblock ~9~0~8 minecraft:planks 1
fill ~9~16~8 ~9~16~11 minecraft:wool 2
fill ~9~30~8 ~9~32~10 minecraft:glowstone
fill ~10~0~8 ~10~0~10 minecraft:glass
fill ~10~16~8 ~12~16~8 minecraft:wool 4
fill ~10~29~8 ~12~29~10 minecraft:glowstone
fill ~10~33~8 ~12~33~10 minecraft:glowstone
fill ~10~39~8 ~10~40~10 minecraft:planks 0
fill ~11~18~8 ~11~21~8 minecraft:log 1
fill ~11~41~8 ~11~42~10 minecraft:planks 0
fill ~12~0~8 ~12~0~10 minecraft:glass
fill ~12~39~8 ~12~40~10 minecraft:planks 0
setblock ~13~0~8 minecraft:planks 1
fill ~13~16~8 ~13~16~11 minecraft:wool 2
fill ~13~30~8 ~13~32~10 minecraft:glowstone
fill ~14~38~8 ~14~38~10 minecraft:planks 0
setblock ~19~1~8 minecraft:iron_door 0
fill ~19~3~8 ~19~3~10 minecraft:cobblestone_wall 1
fill ~19~4~8 ~19~4~11 minecraft:wool 11
fill ~19~18~8 ~19~21~8 minecraft:wool 11
fill ~19~22~8 ~19~27~11 minecraft:log 1
fill ~20~17~8 ~43~17~10 minecraft:log 3
setblock ~20~18~8 minecraft:cobblestone_wall 1
fill ~21~18~8 ~29~18~8 minecraft:cobblestone_wall 1
setblock ~30~18~8 minecraft:cobblestone_wall 1
setblock ~33~18~8 minecraft:cobblestone_wall 1
fill ~34~18~8 ~42~18~8 minecraft:cobblestone_wall 1
setblock ~43~18~8 minecraft:cobblestone_wall 1
setblock ~44~1~8 minecraft:iron_door 2
fill ~44~3~8 ~44~3~10 minecraft:cobblestone_wall 1
fill ~44~4~8 ~44~4~11 minecraft:wool 2
fill ~44~18~8 ~44~21~8 minecraft:wool 2
fill ~44~22~8 ~44~27~11 minecraft:log 1
fill ~49~38~8 ~49~38~10 minecraft:planks 0
setblock ~50~0~8 minecraft:planks 1
fill ~50~16~8 ~50~16~11 minecraft:wool 2
fill ~50~30~8 ~50~32~10 minecraft:glowstone
fill ~51~0~8 ~51~0~10 minecraft:glass
fill ~51~16~8 ~53~16~8 minecraft:wool 4
fill ~51~29~8 ~53~29~10 minecraft:glowstone
fill ~51~33~8 ~53~33~10 minecraft:glowstone
fill ~51~39~8 ~51~40~8 minecraft:planks 0
fill ~52~18~8 ~52~21~8 minecraft:log 1
fill ~52~40~8 ~53~40~10 minecraft:planks 0
fill ~52~41~8 ~52~42~10 minecraft:planks 0
fill ~53~0~8 ~53~0~10 minecraft:glass
setblock ~53~39~8 minecraft:planks 0
setblock ~54~0~8 minecraft:planks 1
fill ~54~16~8 ~54~16~11 minecraft:wool 2
fill ~54~30~8 ~54~32~10 minecraft:glowstone
fill ~55~38~8 ~55~38~10 minecraft:planks 0
setblock ~5~24~9 minecraft:planks 0
setblock ~5~36~9 minecraft:planks 0
setblock ~9~0~9 minecraft:glass
fill ~9~22~9 ~10~22~11 minecraft:planks 0
fill ~9~39~9 ~9~40~9 minecraft:planks 0
fill ~10~16~9 ~10~16~10 minecraft:wool 4
fill ~10~18~9 ~10~21~9 minecraft:log 1
fill ~10~41~9 ~10~42~9 minecraft:planks 0
setblock ~11~0~9 minecraft:glowstone
setblock ~11~15~9 minecraft:glowstone
setblock ~11~16~9 minecraft:wool 14
fill ~11~18~9 ~11~22~9 minecraft:ladder 5
fill ~11~34~9 ~11~37~9 minecraft:glowstone
fill ~11~43~9 ~11~45~9 minecraft:planks 0
fill ~12~16~9 ~12~16~10 minecraft:wool 4
fill ~12~22~9 ~13~22~11 minecraft:planks 0
fill ~12~41~9 ~12~42~9 minecraft:planks 0
setblock ~13~0~9 minecraft:glass
setblock ~13~23~9 minecraft:ladder 4
fill ~13~39~9 ~13~40~9 minecraft:planks 0
setblock ~15~24~9 minecraft:ladder 4
setblock ~16~25~9 minecraft:ladder 4
setblock ~17~24~9 minecraft:planks 0
fill ~17~26~9 ~17~27~9 minecraft:ladder 4
setblock ~17~36~9 minecraft:planks 0
setblock ~18~1~9 minecraft:iron_door 3
fill ~18~28~9 ~18~32~9 minecraft:ladder 4
setblock ~18~35~9 minecraft:wool 11
setblock ~19~17~9 minecraft:wool 11
fill ~19~21~9 ~19~21~10 minecraft:wool 11
setblock ~20~18~9 minecraft:iron_door 3
setblock ~20~22~9 minecraft:ladder 5
setblock ~20~24~9 minecraft:ladder 5
setblock ~20~26~9 minecraft:ladder 5
setblock ~20~28~9 minecraft:ladder 5
setblock ~20~30~9 minecraft:ladder 5
setblock ~20~32~9 minecraft:ladder 5
setblock ~21~32~9 minecraft:cobblestone_wall 0
setblock ~23~32~9 minecraft:cobblestone_wall 0
setblock ~25~32~9 minecraft:cobblestone_wall 0
setblock ~27~32~9 minecraft:cobblestone_wall 0
setblock ~29~32~9 minecraft:cobblestone_wall 0
setblock ~31~32~9 minecraft:cobblestone_wall 0
setblock ~33~32~9 minecraft:cobblestone_wall 0
setblock ~35~32~9 minecraft:cobblestone_wall 0
setblock ~37~32~9 minecraft:cobblestone_wall 0
setblock ~39~32~9 minecraft:cobblestone_wall 0
setblock ~41~32~9 minecraft:cobblestone_wall 0
setblock ~43~18~9 minecraft:iron_door 1
setblock ~43~22~9 minecraft:ladder 4
setblock ~43~24~9 minecraft:ladder 4
setblock ~43~26~9 minecraft:ladder 4
setblock ~43~28~9 minecraft:ladder 4
setblock ~43~30~9 minecraft:ladder 4
setblock ~43~32~9 minecraft:ladder 4
setblock ~44~17~9 minecraft:wool 2
fill ~44~21~9 ~44~21~10 minecraft:wool 2
fill ~45~28~9 ~45~32~9 minecraft:ladder 5
setblock ~45~35~9 minecraft:wool 2
setblock ~46~24~9 minecraft:planks 0
fill ~46~26~9 ~46~27~9 minecraft:ladder 5
setblock ~46~36~9 minecraft:planks 0
setblock ~47~25~9 minecraft:ladder 5
setblock ~48~24~9 minecraft:ladder 5
setblock ~50~0~9 minecraft:glass
fill ~50~22~9 ~51~22~11 minecraft:planks 0
setblock ~50~23~9 minecraft:ladder 5
fill ~50~39~9 ~50~40~9 minecraft:planks 0
fill ~51~16~9 ~51~16~10 minecraft:wool 4
fill ~51~38~9 ~51~38~12 minecraft:planks 0
fill ~51~40~9 ~51~40~10 minecraft:planks 0
fill ~51~41~9 ~51~42~9 minecraft:planks 0
setblock ~52~0~9 minecraft:glowstone
setblock ~52~15~9 minecraft:glowstone
setblock ~52~16~9 minecraft:wool 14
fill ~52~18~9 ~52~22~9 minecraft:ladder 4
fill ~52~34~9 ~52~38~9 minecraft:glowstone
fill ~52~43~9 ~52~45~9 minecraft:planks 0
fill ~53~16~9 ~53~16~10 minecraft:wool 4
fill ~53~18~9 ~53~21~9 minecraft:log 1
fill ~53~22~9 ~54~22~11 minecraft:planks 0
fill ~53~38~9 ~53~38~12 minecraft:planks 0
fill ~53~41~9 ~53~42~9 minecraft:planks 0
setblock ~54~0~9 minecraft:glass
fill ~54~39~9 ~54~40~9 minecraft:planks 0
setblock ~58~24~9 minecraft:planks 0
setblock ~58~36~9 minecraft:planks 0
setblock ~9~0~10 minecraft:planks 1
fill ~11~0~10 ~11~0~11 minecraft:glass
setblock ~11~16~10 minecraft:wool 4
fill ~11~18~10 ~11~21~10 minecraft:log 1
fill ~11~22~10 ~11~22~11 minecraft:planks 0
setblock ~13~0~10 minecraft:planks 1
fill ~18~33~10 ~18~33~12 minecraft:planks 0
fill ~18~34~10 ~18~34~11 minecraft:planks 0
setblock ~19~1~10 minecraft:iron_door 0
fill ~19~17~10 ~19~17~11 minecraft:log 1
fill ~19~18~10 ~19~20~10 minecraft:wool 11
fill ~20~18~10 ~43~18~10 minecraft:glass_pane
setblock ~44~1~10 minecraft:iron_door 2
fill ~44~17~10 ~44~17~11 minecraft:log 1
fill ~44~18~10 ~44~20~10 minecraft:wool 2
setblock ~45~1~10 minecraft:iron_door 1
fill ~45~33~10 ~45~33~12 minecraft:planks 0
fill ~45~34~10 ~45~34~11 minecraft:planks 0
setblock ~50~0~10 minecraft:planks 1
setblock ~51~39~10 minecraft:planks 0
fill ~52~0~10 ~52~0~11 minecraft:glass
setblock ~52~16~10 minecraft:wool 4
fill ~52~18~10 ~52~21~10 minecraft:log 1
fill ~52~22~10 ~52~22~11 minecraft:planks 0
fill ~52~38~10 ~52~38~12 minecraft:planks 0
setblock ~53~39~10 minecraft:planks 0
setblock ~54~0~10 minecraft:planks 1
fill ~5~5~11 ~5~5~13 minecraft:wooden_slab 8
fill ~5~9~11 ~5~9~13 minecraft:wooden_slab 8
fill ~5~13~11 ~5~13~13 minecraft:wooden_slab 8
setblock ~9~0~11 minecraft:wool 11
fill ~10~0~11 ~10~0~17 minecraft:planks 1
fill ~10~16~11 ~12~16~11 minecraft:wool 2
fill ~10~30~11 ~12~32~11 minecraft:glowstone
setblock ~11~23~11 minecraft:ladder 2
fill ~12~0~11 ~12~0~17 minecraft:planks 1
setblock ~13~0~11 minecraft:wool 11
fill ~19~1~11 ~19~3~11 minecraft:wool 11
fill ~19~18~11 ~19~21~11 minecraft:log 1
fill ~44~1~11 ~44~3~11 minecraft:wool 2
fill ~44~18~11 ~44~21~11 minecraft:log 1
setblock ~50~0~11 minecraft:wool 2
fill ~51~0~11 ~51~0~17 minecraft:planks 1
fill ~51~16~11 ~53~16~11 minecraft:wool 2
fill ~51~30~11 ~53~32~11 minecraft:glowstone
setblock ~52~23~11 minecraft:ladder 2
fill ~52~39~11 ~52~40~11 minecraft:planks 0
fill ~53~0~11 ~53~0~17 minecraft:planks 1
setblock ~54~0~11 minecraft:wool 2
fill ~58~5~11 ~58~5~13 minecraft:wooden_slab 8
fill ~58~9~11 ~58~9~13 minecraft:wooden_slab 8
fill ~58~13~11 ~58~13~13 minecraft:wooden_slab 8
fill ~3~0~12 ~3~0~39 minecraft:planks 0
fill ~4~1~12 ~4~26~13 minecraft:log 1
fill ~4~28~12 ~4~32~13 minecraft:planks 0
fill ~5~16~12 ~5~16~13 minecraft:wool 11
fill ~5~26~12 ~5~26~13 minecraft:planks 0
fill ~5~34~12 ~5~34~13 minecraft:planks 0
fill ~6~16~12 ~6~16~13 minecraft:wool 2
fill ~7~16~12 ~7~16~13 minecraft:wool 4
fill ~7~24~12 ~7~24~13 minecraft:planks 0
fill ~7~36~12 ~7~36~13 minecraft:planks 0
setblock ~8~0~12 minecraft:wool 11
setblock ~8~16~12 minecraft:wool 14
fill ~9~0~12 ~9~0~17 minecraft:planks 1
fill ~9~16~12 ~13~16~12 minecraft:wool 11
fill ~9~23~12 ~13~23~13 minecraft:planks 0
fill ~9~37~12 ~13~37~13 minecraft:planks 0
fill ~11~0~12 ~11~0~17 minecraft:planks 1
fill ~13~0~12 ~13~0~17 minecraft:planks 1
setblock ~14~0~12 minecraft:wool 11
setblock ~14~16~12 minecraft:wool 14
setblock ~15~16~12 minecraft:wool 4
fill ~15~24~12 ~15~24~13 minecraft:planks 0
fill ~15~36~12 ~15~36~13 minecraft:planks 0
setblock ~16~16~12 minecraft:wool 2
fill ~17~16~12 ~17~16~13 minecraft:wool 11
fill ~17~26~12 ~17~26~13 minecraft:planks 0
fill ~17~34~12 ~17~34~13 minecraft:planks 0
fill ~18~1~12 ~18~17~13 minecraft:log 1
fill ~18~18~12 ~18~26~12 minecraft:log 1
fill ~18~28~12 ~18~32~13 minecraft:planks 0
fill ~19~0~12 ~19~0~16 minecraft:planks 0
fill ~44~0~12 ~44~0~16 minecraft:planks 0
fill ~45~1~12 ~45~17~13 minecraft:log 1
fill ~45~18~12 ~45~26~12 minecraft:log 1
fill ~45~28~12 ~45~32~13 minecraft:planks 0
fill ~46~16~12 ~46~16~13 minecraft:wool 11
fill ~46~26~12 ~46~26~13 minecraft:planks 0
fill ~46~34~12 ~46~34~13 minecraft:planks 0
fill ~47~16~12 ~47~16~13 minecraft:wool 2
fill ~48~16~12 ~48~16~13 minecraft:wool 4
fill ~48~24~12 ~48~24~13 minecraft:planks 0
fill ~48~36~12 ~48~36~13 minecraft:planks 0
setblock ~49~0~12 minecraft:wool 2
setblock ~49~16~12 minecraft:wool 14
fill ~50~0~12 ~50~0~17 minecraft:planks 1
fill ~50~16~12 ~54~16~12 minecraft:wool 11
fill ~50~23~12 ~54~23~13 minecraft:planks 0
fill ~50~37~12 ~54~37~13 minecraft:planks 0
fill ~52~0~12 ~52~0~17 minecraft:planks 1
fill ~54~0~12 ~54~0~17 minecraft:planks 1
setblock ~55~0~12 minecraft:wool 2
setblock ~55~16~12 minecraft:wool 14
fill ~56~16~12 ~56~16~13 minecraft:wool 4
fill ~56~24~12 ~56~24~13 minecraft:planks 0
fill ~56~36~12 ~56~36~13 minecraft:planks 0
fill ~57~16~12 ~57~16~13 minecraft:wool 2
fill ~58~16~12 ~58~16~13 minecraft:wool 11
fill ~58~26~12 ~58~26~13 minecraft:planks 0
fill ~58~34~12 ~58~34~13 minecraft:planks 0
fill ~59~1~12 ~59~26~13 minecraft:log 1
fill ~59~28~12 ~59~32~13 minecraft:planks 0
fill ~60~0~12 ~60~0~47 minecraft:planks 0
setblock ~4~27~13 minecraft:log 1
fill ~5~27~13 ~5~27~14 minecraft:planks 0
fill ~5~33~13 ~5~33~14 minecraft:planks 0
fill ~6~5~13 ~6~5~14 minecraft:wooden_slab 8
fill ~6~9~13 ~6~9~14 minecraft:wooden_slab 8
fill ~6~13~13 ~6~13~14 minecraft:wooden_slab 8
setblock ~6~25~13 minecraft:planks 0
setblock ~6~35~13 minecraft:planks 0
setblock ~7~0~13 minecraft:wool 11
setblock ~7~22~13 minecraft:glowstone
setblock ~7~23~13 minecraft:cobblestone_wall 0
fill ~8~0~13 ~8~0~16 minecraft:planks 1
setblock ~8~16~13 minecraft:wool 4
fill ~8~24~13 ~8~24~14 minecraft:planks 0
fill ~8~36~13 ~8~36~14 minecraft:planks 0
fill ~9~16~13 ~13~16~13 minecraft:wool 14
setblock ~11~24~13 minecraft:ladder 2
fill ~14~0~13 ~14~0~16 minecraft:planks 1
setblock ~14~16~13 minecraft:wool 4
fill ~14~24~13 ~14~24~14 minecraft:planks 0
fill ~14~36~13 ~14~36~14 minecraft:planks 0
setblock ~15~0~13 minecraft:wool 11
fill ~15~16~13 ~15~16~14 minecraft:wool 2
setblock ~15~22~13 minecraft:glowstone
setblock ~15~23~13 minecraft:cobblestone_wall 0
fill ~16~16~13 ~16~16~14 minecraft:wool 11
setblock ~16~25~13 minecraft:planks 0
setblock ~16~35~13 minecraft:planks 0
fill ~17~27~13 ~17~27~14 minecraft:planks 0
fill ~17~33~13 ~17~33~14 minecraft:planks 0
fill ~18~18~13 ~18~21~13 minecraft:wool 11
fill ~18~22~13 ~18~27~13 minecraft:log 1
fill ~45~18~13 ~45~21~13 minecraft:wool 2
fill ~45~22~13 ~45~27~13 minecraft:log 1
fill ~46~27~13 ~46~27~14 minecraft:planks 0
fill ~46~33~13 ~46~33~14 minecraft:planks 0
setblock ~47~25~13 minecraft:planks 0
setblock ~47~35~13 minecraft:planks 0
setblock ~48~0~13 minecraft:wool 2
setblock ~48~22~13 minecraft:glowstone
setblock ~48~23~13 minecraft:cobblestone_wall 0
fill ~49~0~13 ~49~0~16 minecraft:planks 1
setblock ~49~16~13 minecraft:wool 4
fill ~49~24~13 ~49~24~14 minecraft:planks 0
fill ~49~36~13 ~49~36~14 minecraft:planks 0
fill ~50~16~13 ~54~16~13 minecraft:wool 14
setblock ~52~24~13 minecraft:ladder 2
fill ~55~0~13 ~55~0~16 minecraft:planks 1
setblock ~55~16~13 minecraft:wool 4
fill ~55~24~13 ~55~24~14 minecraft:planks 0
fill ~55~36~13 ~55~36~14 minecraft:planks 0
setblock ~56~0~13 minecraft:wool 2
setblock ~56~22~13 minecraft:glowstone
setblock ~56~23~13 minecraft:cobblestone_wall 0
fill ~57~5~13 ~57~5~14 minecraft:wooden_slab 8
fill ~57~9~13 ~57~9~14 minecraft:wooden_slab 8
fill ~57~13~13 ~57~13~14 minecraft:wooden_slab 8
setblock ~57~25~13 minecraft:planks 0
setblock ~57~35~13 minecraft:planks 0
fill ~58~27~13 ~58~27~14 minecraft:planks 0
fill ~58~33~13 ~58~33~14 minecraft:planks 0
setblock ~59~27~13 minecraft:log 1
fill ~4~0~14 ~4~0~41 minecraft:planks 0
fill ~5~1~14 ~5~26~15 minecraft:log 1
fill ~5~28~14 ~5~32~14 minecraft:planks 0
setblock ~6~0~14 minecraft:wool 11
setblock ~6~16~14 minecraft:wool 11
setblock ~6~26~14 minecraft:planks 0
setblock ~6~34~14 minecraft:planks 0
fill ~7~0~14 ~7~0~16 minecraft:planks 1
fill ~7~5~14 ~7~5~15 minecraft:wooden_slab 8
fill ~7~9~14 ~7~9~15 minecraft:wooden_slab 8
fill ~7~13~14 ~7~13~15 minecraft:wooden_slab 8
fill ~7~16~14 ~8~16~14 minecraft:wool 2
setblock ~7~25~14 minecraft:planks 0
setblock ~7~35~14 minecraft:planks 0
fill ~9~16~14 ~13~16~14 minecraft:wool 4
fill ~9~24~14 ~13~24~14 minecraft:planks 0
fill ~9~36~14 ~13~36~14 minecraft:planks 0
setblock ~11~25~14 minecraft:ladder 2
setblock ~14~16~14 minecraft:wool 2
fill ~15~0~14 ~15~0~16 minecraft:planks 1
setblock ~15~25~14 minecraft:planks 0
setblock ~15~35~14 minecraft:planks 0
setblock ~16~0~14 minecraft:wool 11
setblock ~16~26~14 minecraft:planks 0
setblock ~16~34~14 minecraft:planks 0
fill ~17~1~14 ~17~1~15 minecraft:wool 11
fill ~17~2~14 ~17~16~15 minecraft:log 1
fill ~17~17~14 ~17~17~15 minecraft:wool 14
setblock ~17~18~14 minecraft:iron_door 1
fill ~17~21~14 ~17~21~15 minecraft:wool 11
fill ~17~22~14 ~17~26~15 minecraft:log 1
fill ~17~28~14 ~17~32~14 minecraft:planks 0
fill ~18~0~14 ~18~0~15 minecraft:planks 0
setblock ~18~17~14 minecraft:wool 11
fill ~45~0~14 ~45~0~15 minecraft:planks 0
setblock ~45~17~14 minecraft:wool 2
fill ~46~1~14 ~46~1~15 minecraft:wool 2
fill ~46~2~14 ~46~16~15 minecraft:log 1
fill ~46~17~14 ~46~17~15 minecraft:wool 4
setblock ~46~18~14 minecraft:iron_door 1
fill ~46~21~14 ~46~21~15 minecraft:wool 2
fill ~46~22~14 ~46~26~15 minecraft:log 1
fill ~46~28~14 ~46~32~14 minecraft:planks 0
setblock ~47~0~14 minecraft:wool 2
setblock ~47~16~14 minecraft:wool 11
setblock ~47~26~14 minecraft:planks 0
setblock ~47~34~14 minecraft:planks 0
fill ~48~0~14 ~48~0~16 minecraft:planks 1
fill ~48~16~14 ~49~16~14 minecraft:wool 2
setblock ~48~25~14 minecraft:planks 0
setblock ~48~35~14 minecraft:planks 0
fill ~50~16~14 ~54~16~14 minecraft:wool 4
fill ~50~24~14 ~54~24~14 minecraft:planks 0
fill ~50~36~14 ~54~36~14 minecraft:planks 0
setblock ~52~25~14 minecraft:ladder 2
fill ~55~16~14 ~56~16~14 minecraft:wool 2
fill ~56~0~14 ~56~0~16 minecraft:planks 1
fill ~56~5~14 ~56~5~15 minecraft:wooden_slab 8
fill ~56~9~14 ~56~9~15 minecraft:wooden_slab 8
fill ~56~13~14 ~56~13~15 minecraft:wooden_slab 8
setblock ~56~25~14 minecraft:planks 0
setblock ~56~35~14 minecraft:planks 0
setblock ~57~0~14 minecraft:wool 2
setblock ~57~16~14 minecraft:wool 11
setblock ~57~26~14 minecraft:planks 0
setblock ~57~34~14 minecraft:planks 0
fill ~58~1~14 ~58~26~15 minecraft:log 1
fill ~58~28~14 ~58~32~14 minecraft:planks 0
fill ~59~0~14 ~59~0~45 minecraft:planks 0
fill ~5~27~15 ~5~29~15 minecraft:log 1
fill ~5~30~15 ~6~30~15 minecraft:planks 0
setblock ~6~0~15 minecraft:planks 1
fill ~6~1~15 ~6~26~15 minecraft:log 1
fill ~6~27~15 ~7~27~15 minecraft:planks 0
fill ~6~28~15 ~6~29~15 minecraft:planks 0
fill ~6~31~15 ~6~33~15 minecraft:planks 0
fill ~7~16~15 ~8~16~15 minecraft:wool 11
fill ~7~26~15 ~8~26~15 minecraft:planks 0
fill ~7~33~15 ~7~34~15 minecraft:planks 0
fill ~8~25~15 ~14~25~15 minecraft:planks 0
fill ~8~34~15 ~8~35~15 minecraft:planks 0
fill ~9~16~15 ~13~16~15 minecraft:wool 2
fill ~9~35~15 ~14~35~15 minecraft:planks 0
setblock ~11~24~15 minecraft:planks 0
fill ~11~26~15 ~11~27~15 minecraft:ladder 2
setblock ~11~36~15 minecraft:planks 0
fill ~14~16~15 ~15~16~15 minecraft:wool 11
fill ~14~26~15 ~15~26~15 minecraft:planks 0
fill ~14~34~15 ~15~34~15 minecraft:planks 0
fill ~15~27~15 ~16~27~15 minecraft:planks 0
fill ~15~33~15 ~16~33~15 minecraft:planks 0
setblock ~16~0~15 minecraft:planks 1
setblock ~16~1~15 minecraft:wool 11
fill ~16~2~15 ~16~16~15 minecraft:log 1
setblock ~16~17~15 minecraft:wool 14
setblock ~16~18~15 minecraft:iron_door 0
setblock ~16~21~15 minecraft:wool 11
fill ~16~22~15 ~16~26~15 minecraft:log 1
fill ~16~28~15 ~16~32~15 minecraft:planks 0
setblock ~17~0~15 minecraft:wool 11
fill ~17~27~15 ~17~29~15 minecraft:log 1
setblock ~17~30~15 minecraft:planks 0
setblock ~18~17~15 minecraft:log 3
setblock ~19~17~15 minecraft:wool 11
setblock ~44~17~15 minecraft:wool 2
setblock ~45~17~15 minecraft:log 3
fill ~46~27~15 ~46~29~15 minecraft:log 1
fill ~46~30~15 ~47~30~15 minecraft:planks 0
setblock ~47~0~15 minecraft:planks 1
setblock ~47~1~15 minecraft:wool 2
fill ~47~2~15 ~47~16~15 minecraft:log 1
setblock ~47~17~15 minecraft:wool 4
setblock ~47~18~15 minecraft:iron_door 2
setblock ~47~21~15 minecraft:wool 2
fill ~47~22~15 ~47~26~15 minecraft:log 1
fill ~47~27~15 ~48~27~15 minecraft:planks 0
fill ~47~28~15 ~47~29~15 minecraft:planks 0
fill ~47~31~15 ~47~33~15 minecraft:planks 0
fill ~48~16~15 ~49~16~15 minecraft:wool 11
fill ~48~26~15 ~49~26~15 minecraft:planks 0
fill ~48~33~15 ~48~34~15 minecraft:planks 0
fill ~49~25~15 ~55~25~15 minecraft:planks 0
fill ~49~34~15 ~49~35~15 minecraft:planks 0
fill ~50~16~15 ~54~16~15 minecraft:wool 2
fill ~50~35~15 ~55~35~15 minecraft:planks 0
setblock ~52~24~15 minecraft:planks 0
fill ~52~26~15 ~52~27~15 minecraft:ladder 2
setblock ~52~36~15 minecraft:planks 0
fill ~55~16~15 ~56~16~15 minecraft:wool 11
fill ~55~26~15 ~56~26~15 minecraft:planks 0
fill ~55~34~15 ~56~34~15 minecraft:planks 0
fill ~56~27~15 ~57~27~15 minecraft:planks 0
fill ~56~33~15 ~57~33~15 minecraft:planks 0
setblock ~57~0~15 minecraft:planks 1
fill ~57~1~15 ~57~26~15 minecraft:log 1
fill ~57~28~15 ~57~32~15 minecraft:planks 0
fill ~58~27~15 ~58~29~15 minecraft:log 1
setblock ~58~30~15 minecraft:planks 0
fill ~5~0~16 ~6~0~42 minecraft:planks 0
setblock ~6~1~16 minecraft:planks 0
fill ~6~2~16 ~8~4~16 minecraft:log 1
setblock ~6~5~16 minecraft:planks 0
fill ~6~6~16 ~6~8~16 minecraft:log 1
setblock ~6~9~16 minecraft:planks 0
fill ~6~10~16 ~6~12~16 minecraft:log 1
setblock ~6~13~16 minecraft:planks 0
fill ~6~14~16 ~6~16~16 minecraft:log 1
setblock ~6~17~16 minecraft:planks 0
fill ~7~1~16 ~8~1~16 minecraft:log 1
setblock ~7~5~16 minecraft:glowstone
setblock ~7~8~16 minecraft:wool 11
setblock ~7~9~16 minecraft:glowstone
fill ~7~12~16 ~8~12~16 minecraft:log 1
setblock ~7~13~16 minecraft:glowstone
setblock ~7~16~16 minecraft:wool 11
fill ~7~17~16 ~8~26~16 minecraft:log 1
setblock ~7~27~16 minecraft:log 1
fill ~7~28~16 ~8~32~16 minecraft:planks 0
fill ~8~5~16 ~8~11~16 minecraft:log 1
fill ~8~13~16 ~8~16~16 minecraft:log 1
fill ~8~27~16 ~14~27~16 minecraft:planks 0
fill ~8~33~16 ~10~33~16 minecraft:planks 0
fill ~9~16~16 ~13~16~16 minecraft:wool 11
fill ~9~26~16 ~13~26~16 minecraft:planks 0
fill ~9~34~16 ~10~34~16 minecraft:planks 0
fill ~11~28~16 ~11~32~16 minecraft:ladder 2
setblock ~11~35~16 minecraft:wool 11
setblock ~12~1~16 minecraft:iron_door 0
fill ~12~33~16 ~14~33~16 minecraft:planks 0
fill ~12~34~16 ~13~34~16 minecraft:planks 0
fill ~14~1~16 ~15~17~16 minecraft:log 1
fill ~14~18~16 ~14~26~16 minecraft:log 1
fill ~14~28~16 ~15~32~16 minecraft:planks 0
fill ~15~18~16 ~15~21~16 minecraft:wool 11
fill ~15~22~16 ~15~27~16 minecraft:log 1
fill ~16~0~16 ~17~0~43 minecraft:planks 0
setblock ~16~17~16 minecraft:wool 11
setblock ~17~17~16 minecraft:log 3
setblock ~18~0~16 minecraft:wool 11
setblock ~18~17~16 minecraft:log 3
setblock ~19~17~16 minecraft:log 3
setblock ~20~17~16 minecraft:wool 11
setblock ~43~17~16 minecraft:wool 2
fill ~44~17~16 ~45~17~16 minecraft:log 3
setblock ~45~0~16 minecraft:wool 2
fill ~46~0~16 ~47~0~43 minecraft:planks 0
setblock ~46~17~16 minecraft:log 3
setblock ~47~17~16 minecraft:wool 2
fill ~48~1~16 ~49~17~16 minecraft:log 1
fill ~48~18~16 ~48~21~16 minecraft:wool 2
fill ~48~22~16 ~49~26~16 minecraft:log 1
setblock ~48~27~16 minecraft:log 1
fill ~48~28~16 ~49~32~16 minecraft:planks 0
fill ~49~18~16 ~49~21~16 minecraft:log 1
fill ~49~27~16 ~55~27~16 minecraft:planks 0
fill ~49~33~16 ~51~33~16 minecraft:planks 0
fill ~50~16~16 ~54~16~16 minecraft:wool 11
fill ~50~26~16 ~54~26~16 minecraft:planks 0
fill ~50~34~16 ~51~34~16 minecraft:planks 0
fill ~52~28~16 ~52~32~16 minecraft:ladder 2
setblock ~52~35~16 minecraft:wool 2
setblock ~53~1~16 minecraft:iron_door 0
fill ~53~33~16 ~55~33~16 minecraft:planks 0
fill ~53~34~16 ~54~34~16 minecraft:planks 0
fill ~55~1~16 ~56~4~16 minecraft:log 1
fill ~55~5~16 ~55~26~16 minecraft:log 1
fill ~55~28~16 ~56~32~16 minecraft:planks 0
setblock ~56~5~16 minecraft:glowstone
setblock ~56~8~16 minecraft:wool 2
setblock ~56~9~16 minecraft:glowstone
setblock ~56~12~16 minecraft:wool 2
setblock ~56~13~16 minecraft:glowstone
setblock ~56~16~16 minecraft:wool 2
fill ~56~17~16 ~56~27~16 minecraft:log 1
fill ~57~0~16 ~58~0~43 minecraft:planks 0
setblock ~57~1~16 minecraft:planks 0
fill ~57~2~16 ~57~4~16 minecraft:log 1
setblock ~57~5~16 minecraft:planks 0
fill ~57~6~16 ~57~8~16 minecraft:log 1
setblock ~57~9~16 minecraft:planks 0
fill ~57~10~16 ~57~12~16 minecraft:log 1
setblock ~57~13~16 minecraft:planks 0
fill ~57~14~16 ~57~16~16 minecraft:log 1
setblock ~5~1~17 minecraft:planks 0
fill ~5~2~17 ~5~4~17 minecraft:log 1
setblock ~5~5~17 minecraft:planks 0
fill ~5~6~17 ~5~8~17 minecraft:log 1
setblock ~5~9~17 minecraft:planks 0
fill ~5~10~17 ~5~12~17 minecraft:log 1
setblock ~5~13~17 minecraft:planks 0
fill ~5~14~17 ~5~16~17 minecraft:log 1
setblock ~5~17~17 minecraft:planks 0
fill ~6~5~17 ~8~5~18 minecraft:wooden_slab 8
fill ~6~9~17 ~8~9~18 minecraft:wooden_slab 8
fill ~6~13~17 ~8~13~18 minecraft:wooden_slab 8
fill ~7~0~17 ~8~0~42 minecraft:planks 0
setblock ~8~6~17 minecraft:cobblestone_wall 1
setblock ~8~10~17 minecraft:cobblestone_wall 1
setblock ~8~14~17 minecraft:cobblestone_wall 1
fill ~9~1~17 ~9~4~17 minecraft:wool 11
fill ~9~5~17 ~13~16~17 minecraft:log 1
fill ~9~17~17 ~9~27~17 minecraft:log 1
fill ~9~28~17 ~13~32~17 minecraft:planks 0
setblock ~10~1~17 minecraft:iron_door 1
fill ~10~3~17 ~12~3~17 minecraft:cobblestone_wall 1
fill ~10~4~17 ~13~4~17 minecraft:wool 11
fill ~10~17~17 ~12~17~17 minecraft:wool 11
fill ~10~18~17 ~10~21~17 minecraft:wool 11
fill ~10~22~17 ~13~27~17 minecraft:log 1
fill ~11~21~17 ~12~21~17 minecraft:wool 11
setblock ~12~1~17 minecraft:iron_door 1
fill ~12~18~17 ~12~20~17 minecraft:wool 11
fill ~13~1~17 ~13~3~17 minecraft:wool 11
fill ~13~17~17 ~13~21~17 minecraft:log 1
fill ~14~0~17 ~15~0~42 minecraft:planks 0
setblock ~17~17~17 minecraft:wool 11
fill ~18~0~17 ~18~0~42 minecraft:planks 0
setblock ~18~17~17 minecraft:log 3
setblock ~19~0~17 minecraft:wool 11
setblock ~19~17~17 minecraft:log 3
setblock ~20~17~17 minecraft:log 3
setblock ~21~17~17 minecraft:wool 11
setblock ~42~17~17 minecraft:wool 2
fill ~43~17~17 ~44~17~17 minecraft:log 3
setblock ~44~0~17 minecraft:wool 2
fill ~45~0~17 ~45~0~42 minecraft:planks 0
setblock ~45~17~17 minecraft:log 3
setblock ~46~17~17 minecraft:wool 2
fill ~48~0~17 ~49~0~42 minecraft:planks 0
fill ~50~1~17 ~50~4~17 minecraft:wool 2
fill ~50~5~17 ~54~16~17 minecraft:log 1
fill ~50~17~17 ~51~17~17 minecraft:log 1
fill ~50~18~17 ~50~27~17 minecraft:log 1
fill ~50~28~17 ~54~32~17 minecraft:planks 0
setblock ~51~1~17 minecraft:iron_door 1
fill ~51~3~17 ~53~3~17 minecraft:cobblestone_wall 1
fill ~51~4~17 ~54~4~17 minecraft:wool 2
fill ~51~18~17 ~51~21~17 minecraft:wool 2
fill ~51~22~17 ~54~27~17 minecraft:log 1
setblock ~52~17~17 minecraft:wool 2
fill ~52~21~17 ~53~21~17 minecraft:wool 2
setblock ~53~1~17 minecraft:iron_door 1
fill ~53~17~17 ~54~17~17 minecraft:log 1
fill ~53~18~17 ~53~20~17 minecraft:wool 2
fill ~54~1~17 ~54~3~17 minecraft:wool 2
fill ~54~18~17 ~54~21~17 minecraft:log 1
fill ~55~0~17 ~56~0~42 minecraft:planks 0
fill ~55~5~17 ~57~5~18 minecraft:wooden_slab 8
setblock ~55~6~17 minecraft:cobblestone_wall 1
fill ~55~9~17 ~57~9~18 minecraft:wooden_slab 8
setblock ~55~10~17 minecraft:cobblestone_wall 1
fill ~55~13~17 ~57~13~18 minecraft:wooden_slab 8
setblock ~55~14~17 minecraft:cobblestone_wall 1
setblock ~58~1~17 minecraft:planks 0
fill ~58~2~17 ~58~4~17 minecraft:log 1
setblock ~58~5~17 minecraft:planks 0
fill ~58~6~17 ~58~8~17 minecraft:log 1
setblock ~58~9~17 minecraft:planks 0
fill ~58~10~17 ~58~12~17 minecraft:log 1
setblock ~58~13~17 minecraft:planks 0
fill ~58~14~17 ~58~16~17 minecraft:log 1
setblock ~58~17~17 minecraft:planks 0
fill ~4~1~18 ~4~1~19 minecraft:planks 0
fill ~4~2~18 ~4~4~19 minecraft:log 1
fill ~4~5~18 ~4~5~19 minecraft:planks 0
fill ~4~6~18 ~4~8~19 minecraft:log 1
fill ~4~9~18 ~4~9~19 minecraft:planks 0
fill ~4~10~18 ~4~12~19 minecraft:log 1
fill ~4~13~18 ~4~13~19 minecraft:planks 0
fill ~4~14~18 ~4~16~19 minecraft:log 1
fill ~4~17~18 ~4~17~19 minecraft:planks 0
fill ~5~5~18 ~5~5~41 minecraft:wooden_slab 8
fill ~5~9~18 ~5~9~41 minecraft:wooden_slab 8
fill ~5~13~18 ~5~13~41 minecraft:wooden_slab 8
setblock ~7~6~18 minecraft:cobblestone_wall 1
setblock ~7~10~18 minecraft:cobblestone_wall 1
setblock ~7~14~18 minecraft:cobblestone_wall 1
setblock ~8~6~18 minecraft:cobblestone_wall 1
setblock ~8~10~18 minecraft:cobblestone_wall 1
setblock ~8~14~18 minecraft:cobblestone_wall 1
fill ~9~0~18 ~13~0~41 minecraft:planks 0
fill ~10~17~18 ~12~17~41 minecraft:log 3
setblock ~10~18~18 minecraft:cobblestone_wall 1
setblock ~11~18~18 minecraft:iron_door 0
setblock ~11~22~18 minecraft:ladder 3
setblock ~11~24~18 minecraft:ladder 3
setblock ~11~26~18 minecraft:ladder 3
setblock ~11~28~18 minecraft:ladder 3
setblock ~11~30~18 minecraft:ladder 3
setblock ~11~32~18 minecraft:ladder 3
fill ~12~18~18 ~12~18~41 minecraft:glass_pane
setblock ~18~17~18 minecraft:wool 11
fill ~19~0~18 ~19~0~41 minecraft:planks 0
setblock ~19~17~18 minecraft:log 3
setblock ~20~0~18 minecraft:wool 11
setblock ~20~17~18 minecraft:log 3
fill ~21~0~18 ~42~0~18 minecraft:planks 0
setblock ~21~17~18 minecraft:log 3
setblock ~22~17~18 minecraft:wool 11
setblock ~41~17~18 minecraft:wool 2
fill ~42~17~18 ~43~17~18 minecraft:log 3
setblock ~43~0~18 minecraft:wool 2
fill ~44~0~18 ~44~0~41 minecraft:planks 0
setblock ~44~17~18 minecraft:log 3
setblock ~45~17~18 minecraft:wool 2
fill ~50~0~18 ~54~0~41 minecraft:planks 0
fill ~51~17~18 ~53~17~41 minecraft:log 3
fill ~51~18~18 ~51~18~41 minecraft:glass_pane
setblock ~52~18~18 minecraft:iron_door 0
setblock ~52~22~18 minecraft:ladder 3
setblock ~52~24~18 minecraft:ladder 3
setblock ~52~26~18 minecraft:ladder 3
setblock ~52~28~18 minecraft:ladder 3
setblock ~52~30~18 minecraft:ladder 3
setblock ~52~32~18 minecraft:ladder 3
setblock ~53~18~18 minecraft:cobblestone_wall 1
setblock ~55~6~18 minecraft:cobblestone_wall 1
setblock ~55~10~18 minecraft:cobblestone_wall 1
setblock ~55~14~18 minecraft:cobblestone_wall 1
setblock ~56~6~18 minecraft:cobblestone_wall 1
setblock ~56~10~18 minecraft:cobblestone_wall 1
setblock ~56~14~18 minecraft:cobblestone_wall 1
fill ~58~5~18 ~58~5~41 minecraft:wooden_slab 8
fill ~58~9~18 ~58~9~41 minecraft:wooden_slab 8
fill ~58~13~18 ~58~13~41 minecraft:wooden_slab 8
fill ~59~1~18 ~59~1~19 minecraft:planks 0
fill ~59~2~18 ~59~4~19 minecraft:log 1
fill ~59~5~18 ~59~5~19 minecraft:planks 0
fill ~59~6~18 ~59~8~19 minecraft:log 1
fill ~59~9~18 ~59~9~19 minecraft:planks 0
fill ~59~10~18 ~59~12~19 minecraft:log 1
fill ~59~13~18 ~59~13~19 minecraft:planks 0
fill ~59~14~18 ~59~16~19 minecraft:log 1
fill ~59~17~18 ~59~17~19 minecraft:planks 0
fill ~6~5~19 ~7~5~19 minecraft:wooden_slab 8
setblock ~6~6~19 minecraft:cobblestone_wall 1
fill ~6~9~19 ~7~9~19 minecraft:wooden_slab 8
setblock ~6~10~19 minecraft:cobblestone_wall 1
fill ~6~13~19 ~7~13~19 minecraft:wooden_slab 8
setblock ~6~14~19 minecraft:cobblestone_wall 1
setblock ~7~6~19 minecraft:cobblestone_wall 1
setblock ~7~10~19 minecraft:cobblestone_wall 1
setblock ~7~14~19 minecraft:cobblestone_wall 1
fill ~10~18~19 ~10~18~27 minecraft:cobblestone_wall 1
setblock ~19~17~19 minecraft:wool 11
fill ~20~0~19 ~20~0~40 minecraft:planks 0
setblock ~20~17~19 minecraft:log 3
setblock ~21~0~19 minecraft:wool 11
setblock ~21~17~19 minecraft:log 3
fill ~22~0~19 ~41~0~19 minecraft:planks 0
setblock ~22~17~19 minecraft:log 3
setblock ~23~17~19 minecraft:wool 11
setblock ~40~17~19 minecraft:wool 2
fill ~41~17~19 ~42~17~19 minecraft:log 3
setblock ~42~0~19 minecraft:wool 2
fill ~43~0~19 ~43~0~40 minecraft:planks 0
setblock ~43~17~19 minecraft:log 3
setblock ~44~17~19 minecraft:wool 2
setblock ~52~32~19 minecraft:cobblestone_wall 0
fill ~53~18~19 ~53~18~27 minecraft:cobblestone_wall 1
fill ~56~5~19 ~57~5~19 minecraft:wooden_slab 8
setblock ~56~6~19 minecraft:cobblestone_wall 1
fill ~56~9~19 ~57~9~19 minecraft:wooden_slab 8
setblock ~56~10~19 minecraft:cobblestone_wall 1
fill ~56~13~19 ~57~13~19 minecraft:wooden_slab 8
setblock ~56~14~19 minecraft:cobblestone_wall 1
setblock ~57~6~19 minecraft:cobblestone_wall 1
setblock ~57~10~19 minecraft:cobblestone_wall 1
setblock ~57~14~19 minecraft:cobblestone_wall 1
fill ~3~1~20 ~3~1~22 minecraft:planks 0
fill ~3~2~20 ~3~4~22 minecraft:log 1
fill ~3~5~20 ~3~5~22 minecraft:planks 0
fill ~3~6~20 ~3~8~22 minecraft:log 1
fill ~3~9~20 ~3~9~22 minecraft:planks 0
fill ~3~10~20 ~3~12~22 minecraft:log 1
fill ~3~13~20 ~3~13~22 minecraft:planks 0
fill ~3~14~20 ~3~16~22 minecraft:log 1
fill ~3~17~20 ~3~17~22 minecraft:planks 0
fill ~4~5~20 ~4~5~39 minecraft:wooden_slab 8
fill ~4~9~20 ~4~9~39 minecraft:wooden_slab 8
fill ~4~13~20 ~4~13~39 minecraft:wooden_slab 8
fill ~6~5~20 ~6~5~22 minecraft:wooden_slab 8
fill ~6~6~20 ~6~6~21 minecraft:cobblestone_wall 1
fill ~6~9~20 ~6~9~23 minecraft:wooden_slab 8
fill ~6~10~20 ~6~10~22 minecraft:cobblestone_wall 1
fill ~6~13~20 ~6~13~22 minecraft:wooden_slab 8
fill ~6~14~20 ~6~14~21 minecraft:cobblestone_wall 1
setblock ~11~32~20 minecraft:cobblestone_wall 0
setblock ~20~17~20 minecraft:wool 11
fill ~21~0~20 ~21~0~39 minecraft:planks 0
setblock ~21~17~20 minecraft:log 3
setblock ~22~0~20 minecraft:wool 11
setblock ~22~17~20 minecraft:log 3
fill ~23~0~20 ~40~0~20 minecraft:planks 0
setblock ~23~17~20 minecraft:log 3
setblock ~24~17~20 minecraft:wool 11
setblock ~39~17~20 minecraft:wool 2
fill ~40~17~20 ~41~17~20 minecraft:log 3
setblock ~41~0~20 minecraft:wool 2
fill ~42~0~20 ~42~0~39 minecraft:planks 0
setblock ~42~17~20 minecraft:log 3
setblock ~43~17~20 minecraft:wool 2
fill ~57~5~20 ~57~5~21 minecraft:wooden_slab 8
setblock ~57~6~20 minecraft:cobblestone_wall 1
fill ~57~9~20 ~57~9~21 minecraft:wooden_slab 8
setblock ~57~10~20 minecraft:cobblestone_wall 1
fill ~57~13~20 ~57~13~21 minecraft:wooden_slab 8
setblock ~57~14~20 minecraft:cobblestone_wall 1
fill ~59~5~20 ~59~5~39 minecraft:wooden_slab 8
fill ~59~9~20 ~59~9~39 minecraft:wooden_slab 8
fill ~59~13~20 ~59~13~39 minecraft:wooden_slab 8
fill ~60~1~20 ~60~1~22 minecraft:planks 0
fill ~60~2~20 ~60~4~22 minecraft:log 1
fill ~60~5~20 ~60~5~22 minecraft:planks 0
fill ~60~6~20 ~60~8~22 minecraft:log 1
fill ~60~9~20 ~60~9~22 minecraft:planks 0
fill ~60~10~20 ~60~12~22 minecraft:log 1
fill ~60~13~20 ~60~13~22 minecraft:planks 0
fill ~60~14~20 ~60~16~22 minecraft:log 1
fill ~60~17~20 ~60~17~22 minecraft:planks 0
setblock ~21~17~21 minecraft:wool 11
fill ~22~0~21 ~22~0~38 minecraft:planks 0
setblock ~22~17~21 minecraft:log 3
setblock ~23~0~21 minecraft:wool 11
setblock ~23~17~21 minecraft:log 3
fill ~24~0~21 ~39~0~21 minecraft:planks 0
setblock ~24~17~21 minecraft:log 3
setblock ~25~17~21 minecraft:wool 11
setblock ~38~17~21 minecraft:wool 2
fill ~39~17~21 ~40~17~21 minecraft:log 3
setblock ~40~0~21 minecraft:wool 2
fill ~41~0~21 ~41~0~38 minecraft:planks 0
setblock ~41~17~21 minecraft:log 3
setblock ~42~17~21 minecraft:wool 2
setblock ~52~32~21 minecraft:cobblestone_wall 0
setblock ~57~6~21 minecraft:cobblestone_wall 1
setblock ~57~10~21 minecraft:cobblestone_wall 1
setblock ~57~14~21 minecraft:cobblestone_wall 1
setblock ~58~6~21 minecraft:cobblestone_wall 1
setblock ~58~10~21 minecraft:cobblestone_wall 1
setblock ~58~14~21 minecraft:cobblestone_wall 1
setblock ~5~6~22 minecraft:cobblestone_wall 1
setblock ~5~14~22 minecraft:cobblestone_wall 1
setblock ~6~6~22 minecraft:cobblestone_wall 1
setblock ~6~14~22 minecraft:cobblestone_wall 1
setblock ~11~32~22 minecraft:cobblestone_wall 0
setblock ~22~17~22 minecraft:wool 11
fill ~23~0~22 ~23~0~37 minecraft:planks 0
setblock ~23~17~22 minecraft:log 3
setblock ~24~0~22 minecraft:wool 11
setblock ~24~17~22 minecraft:log 3
fill ~25~0~22 ~38~0~22 minecraft:planks 0
setblock ~25~17~22 minecraft:log 3
setblock ~26~17~22 minecraft:wool 11
setblock ~37~17~22 minecraft:wool 2
fill ~38~17~22 ~39~17~22 minecraft:log 3
setblock ~39~0~22 minecraft:wool 2
fill ~40~0~22 ~40~0~37 minecraft:planks 0
setblock ~40~17~22 minecraft:log 3
setblock ~41~17~22 minecraft:wool 2
fill ~58~6~22 ~58~6~35 minecraft:cobblestone_wall 1
fill ~58~10~22 ~58~10~36 minecraft:cobblestone_wall 1
fill ~58~14~22 ~58~14~27 minecraft:cobblestone_wall 1
fill ~2~1~23 ~2~1~36 minecraft:planks 0
fill ~2~2~23 ~2~4~24 minecraft:log 1
fill ~2~5~23 ~2~5~36 minecraft:planks 0
fill ~2~6~23 ~2~8~24 minecraft:log 1
fill ~2~9~23 ~2~9~36 minecraft:planks 0
fill ~2~10~23 ~2~12~24 minecraft:log 1
fill ~2~13~23 ~2~13~36 minecraft:planks 0
fill ~2~14~23 ~2~16~24 minecraft:log 1
fill ~2~17~23 ~2~17~36 minecraft:planks 0
fill ~3~5~23 ~3~5~28 minecraft:wooden_slab 8
fill ~3~9~23 ~3~9~28 minecraft:wooden_slab 8
fill ~3~13~23 ~3~13~28 minecraft:wooden_slab 8
fill ~5~6~23 ~5~6~36 minecraft:cobblestone_wall 1
setblock ~5~10~23 minecraft:cobblestone_wall 1
fill ~5~14~23 ~5~14~27 minecraft:cobblestone_wall 1
setblock ~6~10~23 minecraft:cobblestone_wall 1
setblock ~23~17~23 minecraft:wool 11
fill ~24~0~23 ~24~0~36 minecraft:planks 0
setblock ~24~17~23 minecraft:log 3
setblock ~25~0~23 minecraft:wool 11
setblock ~25~17~23 minecraft:log 3
fill ~26~0~23 ~37~0~23 minecraft:planks 0
setblock ~26~17~23 minecraft:log 3
setblock ~27~17~23 minecraft:wool 11
setblock ~36~17~23 minecraft:wool 2
fill ~37~17~23 ~38~17~23 minecraft:log 3
setblock ~38~0~23 minecraft:wool 2
fill ~39~0~23 ~39~0~36 minecraft:planks 0
setblock ~39~17~23 minecraft:log 3
setblock ~40~17~23 minecraft:wool 2
setblock ~52~32~23 minecraft:cobblestone_wall 0
fill ~60~5~23 ~60~5~28 minecraft:wooden_slab 8
fill ~60~9~23 ~60~9~28 minecraft:wooden_slab 8
fill ~60~13~23 ~60~13~28 minecraft:wooden_slab 8
fill ~61~1~23 ~61~1~36 minecraft:planks 0
fill ~61~2~23 ~61~4~24 minecraft:log 1
fill ~61~5~23 ~61~5~36 minecraft:planks 0
fill ~61~6~23 ~61~8~24 minecraft:log 1
fill ~61~9~23 ~61~9~36 minecraft:planks 0
fill ~61~10~23 ~61~12~24 minecraft:log 1
fill ~61~13~23 ~61~13~36 minecraft:planks 0
fill ~61~14~23 ~61~16~24 minecraft:log 1
fill ~61~17~23 ~61~17~36 minecraft:planks 0
fill ~5~10~24 ~5~10~35 minecraft:cobblestone_wall 1
setblock ~11~32~24 minecraft:cobblestone_wall 0
setblock ~24~17~24 minecraft:wool 11
fill ~25~0~24 ~25~0~35 minecraft:planks 0
setblock ~25~17~24 minecraft:log 3
setblock ~26~0~24 minecraft:wool 11
setblock ~26~17~24 minecraft:log 3
fill ~27~0~24 ~36~0~24 minecraft:planks 0
setblock ~27~17~24 minecraft:log 3
setblock ~28~17~24 minecraft:wool 11
setblock ~35~17~24 minecraft:wool 2
fill ~36~17~24 ~37~17~24 minecraft:log 3
setblock ~37~0~24 minecraft:wool 2
fill ~38~0~24 ~38~0~35 minecraft:planks 0
setblock ~38~17~24 minecraft:log 3
setblock ~39~17~24 minecraft:wool 2
fill ~2~2~25 ~2~4~25 minecraft:glass_pane
fill ~2~6~25 ~2~8~25 minecraft:glass_pane
fill ~2~10~25 ~2~12~25 minecraft:glass_pane
fill ~2~14~25 ~2~16~25 minecraft:glass_pane
setblock ~25~17~25 minecraft:wool 11
fill ~26~0~25 ~26~0~34 minecraft:planks 0
setblock ~26~17~25 minecraft:log 3
setblock ~27~0~25 minecraft:wool 11
setblock ~27~1~25 minecraft:cobblestone_wall 1
setblock ~27~2~25 minecraft:torch 5
setblock ~27~17~25 minecraft:log 3
fill ~28~0~25 ~35~0~25 minecraft:planks 0
fill ~28~1~25 ~29~1~25 minecraft:cobblestone_wall 1
setblock ~28~17~25 minecraft:log 3
fill ~29~17~25 ~31~17~25 minecraft:wool 11
setblock ~30~1~25 minecraft:cobblestone_wall 1
setblock ~30~12~25 minecraft:cobblestone_wall 0
fill ~30~13~25 ~33~15~25 minecraft:glass
fill ~30~16~25 ~33~16~25 minecraft:glowstone
fill ~31~12~25 ~32~12~25 minecraft:cobblestone_wall 0
fill ~32~17~25 ~34~17~25 minecraft:wool 2
setblock ~33~1~25 minecraft:cobblestone_wall 1
setblock ~33~12~25 minecraft:cobblestone_wall 0
setblock ~34~1~25 minecraft:cobblestone_wall 1
setblock ~35~1~25 minecraft:cobblestone_wall 1
fill ~35~17~25 ~36~17~25 minecraft:log 3
setblock ~36~0~25 minecraft:wool 2
setblock ~36~1~25 minecraft:cobblestone_wall 1
setblock ~36~2~25 minecraft:torch 5
fill ~37~0~25 ~37~0~34 minecraft:planks 0
setblock ~37~17~25 minecraft:log 3
setblock ~38~17~25 minecraft:wool 2
setblock ~52~32~25 minecraft:cobblestone_wall 0
fill ~61~2~25 ~61~4~25 minecraft:glass_pane
fill ~61~6~25 ~61~8~25 minecraft:glass_pane
fill ~61~10~25 ~61~12~25 minecraft:glass_pane
fill ~61~14~25 ~61~16~25 minecraft:glass_pane
fill ~2~2~26 ~2~4~27 minecraft:log 1
fill ~2~6~26 ~2~8~27 minecraft:log 1
fill ~2~10~26 ~2~12~27 minecraft:log 1
fill ~2~14~26 ~2~16~27 minecraft:log 1
setblock ~11~32~26 minecraft:cobblestone_wall 0
setblock ~26~17~26 minecraft:wool 11
fill ~27~0~26 ~27~0~33 minecraft:planks 0
fill ~27~1~26 ~27~1~27 minecraft:cobblestone_wall 1
setblock ~27~17~26 minecraft:log 3
setblock ~28~17~26 minecraft:log 3
setblock ~29~12~26 minecraft:cobblestone_wall 0
fill ~29~13~26 ~29~15~26 minecraft:glass
setblock ~29~16~26 minecraft:glowstone
setblock ~29~17~26 minecraft:log 3
fill ~30~12~26 ~33~12~33 minecraft:cobblestone_wall 0
fill ~30~17~26 ~31~17~26 minecraft:wool 11
fill ~31~16~26 ~32~16~28 minecraft:glowstone
fill ~32~17~26 ~33~17~26 minecraft:wool 2
setblock ~34~12~26 minecraft:cobblestone_wall 0
fill ~34~13~26 ~34~15~26 minecraft:glass
setblock ~34~16~26 minecraft:glowstone
fill ~34~17~26 ~35~17~26 minecraft:log 3
setblock ~35~1~26 minecraft:waterlily
fill ~36~0~26 ~36~0~33 minecraft:planks 0
setblock ~36~1~26 minecraft:cobblestone_wall 1
setblock ~36~17~26 minecraft:log 3
setblock ~37~17~26 minecraft:wool 2
fill ~61~2~26 ~61~4~27 minecraft:log 1
fill ~61~6~26 ~61~8~27 minecraft:log 1
fill ~61~10~26 ~61~12~27 minecraft:log 1
fill ~61~14~26 ~61~16~27 minecraft:log 1
fill ~27~17~27 ~27~17~29 minecraft:wool 11
setblock ~28~12~27 minecraft:cobblestone_wall 0
fill ~28~13~27 ~28~15~27 minecraft:glass
setblock ~28~16~27 minecraft:glowstone
setblock ~28~17~27 minecraft:log 3
fill ~29~12~27 ~29~12~32 minecraft:cobblestone_wall 0
setblock ~29~17~27 minecraft:log 3
setblock ~30~17~27 minecraft:log 3
setblock ~31~17~27 minecraft:wool 11
setblock ~32~17~27 minecraft:wool 2
fill ~33~17~27 ~34~17~27 minecraft:log 3
fill ~34~12~27 ~34~12~32 minecraft:cobblestone_wall 0
setblock ~35~12~27 minecraft:cobblestone_wall 0
fill ~35~13~27 ~35~15~27 minecraft:glass
setblock ~35~16~27 minecraft:glowstone
setblock ~35~17~27 minecraft:log 3
setblock ~36~1~27 minecraft:cobblestone_wall 1
fill ~36~17~27 ~36~17~29 minecraft:wool 2
setblock ~52~32~27 minecraft:cobblestone_wall 0
fill ~2~2~28 ~2~4~28 minecraft:glass_pane
fill ~2~6~28 ~2~8~28 minecraft:glass_pane
fill ~2~10~28 ~2~12~28 minecraft:glass_pane
fill ~2~14~28 ~2~16~28 minecraft:glass_pane
setblock ~3~14~28 minecraft:cobblestone_wall 1
setblock ~3~15~28 minecraft:wooden_slab 0
setblock ~5~14~28 minecraft:cobblestone_wall 1
setblock ~6~14~28 minecraft:cobblestone_wall 1
setblock ~6~15~28 minecraft:cobblestone_wall 1
setblock ~7~14~28 minecraft:cobblestone_wall 1
setblock ~7~15~28 minecraft:cobblestone_wall 1
setblock ~7~16~28 minecraft:cobblestone_wall 1
setblock ~8~15~28 minecraft:cobblestone_wall 1
setblock ~8~16~28 minecraft:cobblestone_wall 1
setblock ~8~17~28 minecraft:cobblestone_wall 1
setblock ~9~16~28 minecraft:cobblestone_wall 1
setblock ~9~17~28 minecraft:cobblestone_wall 1
setblock ~9~18~28 minecraft:cobblestone_wall 1
setblock ~10~18~28 minecraft:cobblestone_wall 1
setblock ~11~32~28 minecraft:cobblestone_wall 0
setblock ~27~1~28 minecraft:cobblestone_wall 1
setblock ~27~12~28 minecraft:cobblestone_wall 0
fill ~27~13~28 ~27~15~31 minecraft:glass
fill ~27~16~28 ~27~16~31 minecraft:glowstone
fill ~28~12~28 ~28~12~31 minecraft:cobblestone_wall 0
fill ~28~17~28 ~28~17~29 minecraft:wool 11
setblock ~29~17~28 minecraft:log 3
fill ~30~0~28 ~33~0~28 minecraft:glowstone
fill ~30~1~28 ~33~1~28 minecraft:stone_block_slab 1
setblock ~30~17~28 minecraft:log 3
fill ~31~17~28 ~31~17~31 minecraft:log 3
fill ~32~17~28 ~33~17~28 minecraft:log 3
setblock ~34~17~28 minecraft:log 3
fill ~35~12~28 ~35~12~31 minecraft:cobblestone_wall 0
fill ~35~17~28 ~35~17~29 minecraft:wool 2
setblock ~36~1~28 minecraft:cobblestone_wall 1
setblock ~36~12~28 minecraft:cobblestone_wall 0
fill ~36~13~28 ~36~15~31 minecraft:glass
fill ~36~16~28 ~36~16~31 minecraft:glowstone
setblock ~53~18~28 minecraft:cobblestone_wall 1
setblock ~54~16~28 minecraft:cobblestone_wall 1
setblock ~54~17~28 minecraft:cobblestone_wall 1
setblock ~54~18~28 minecraft:cobblestone_wall 1
setblock ~55~15~28 minecraft:cobblestone_wall 1
setblock ~55~16~28 minecraft:cobblestone_wall 1
setblock ~55~17~28 minecraft:cobblestone_wall 1
setblock ~56~14~28 minecraft:cobblestone_wall 1
setblock ~56~15~28 minecraft:cobblestone_wall 1
setblock ~56~16~28 minecraft:cobblestone_wall 1
setblock ~57~14~28 minecraft:cobblestone_wall 1
setblock ~57~15~28 minecraft:cobblestone_wall 1
setblock ~58~14~28 minecraft:cobblestone_wall 1
setblock ~60~14~28 minecraft:cobblestone_wall 1
setblock ~60~15~28 minecraft:wooden_slab 0
fill ~61~2~28 ~61~4~28 minecraft:glass_pane
fill ~61~6~28 ~61~8~28 minecraft:glass_pane
fill ~61~10~28 ~61~12~28 minecraft:glass_pane
fill ~61~14~28 ~61~16~28 minecraft:glass_pane
fill ~2~2~29 ~2~4~30 minecraft:log 1
fill ~2~6~29 ~2~8~30 minecraft:log 1
fill ~2~10~29 ~2~12~30 minecraft:log 1
fill ~2~14~29 ~2~16~30 minecraft:log 1
fill ~3~1~29 ~3~15~30 minecraft:ladder 5
fill ~3~16~29 ~3~16~30 minecraft:wooden_slab 0
fill ~6~14~29 ~6~14~30 minecraft:birch_stairs 0
fill ~7~14~29 ~7~14~30 minecraft:log 3
fill ~7~15~29 ~7~15~30 minecraft:birch_stairs 0
fill ~8~15~29 ~8~15~30 minecraft:log 3
fill ~8~16~29 ~8~16~30 minecraft:birch_stairs 0
fill ~9~16~29 ~9~16~30 minecraft:log 3
fill ~9~17~29 ~9~17~30 minecraft:birch_stairs 0
fill ~27~12~29 ~27~12~30 minecraft:cobblestone_wall 0
fill ~28~16~29 ~30~16~30 minecraft:glowstone
setblock ~29~17~29 minecraft:wool 11
fill ~30~0~29 ~30~0~31 minecraft:glowstone
fill ~30~1~29 ~30~1~31 minecraft:stone_block_slab 1
setblock ~30~17~29 minecraft:log 3
fill ~31~0~29 ~32~0~30 minecraft:planks 0
fill ~31~1~29 ~32~2~30 minecraft:log 3
setblock ~31~3~29 minecraft:torch 5
fill ~31~4~29 ~32~4~30 minecraft:log 3
fill ~31~5~29 ~31~6~29 minecraft:log 3
setblock ~31~7~29 minecraft:torch 5
fill ~31~8~29 ~32~8~30 minecraft:log 3
fill ~31~9~29 ~31~11~29 minecraft:log 3
setblock ~32~3~29 minecraft:log 3
setblock ~32~5~29 minecraft:torch 5
fill ~32~6~29 ~32~6~30 minecraft:log 3
setblock ~32~7~29 minecraft:log 3
setblock ~32~9~29 minecraft:torch 5
fill ~32~10~29 ~32~11~30 minecraft:log 3
setblock ~32~17~29 minecraft:log 3
fill ~33~0~29 ~33~0~31 minecraft:glowstone
fill ~33~1~29 ~33~1~31 minecraft:stone_block_slab 1
fill ~33~16~29 ~35~16~30 minecraft:glowstone
fill ~33~17~29 ~33~17~30 minecraft:log 3
setblock ~34~17~29 minecraft:wool 2
fill ~36~12~29 ~36~12~30 minecraft:cobblestone_wall 0
setblock ~52~32~29 minecraft:cobblestone_wall 0
fill ~54~16~29 ~54~16~30 minecraft:log 3
fill ~54~17~29 ~54~17~30 minecraft:birch_stairs 1
fill ~55~15~29 ~55~15~30 minecraft:log 3
fill ~55~16~29 ~55~16~30 minecraft:birch_stairs 1
fill ~56~14~29 ~56~14~30 minecraft:log 3
fill ~56~15~29 ~56~15~30 minecraft:birch_stairs 1
fill ~57~14~29 ~57~14~30 minecraft:birch_stairs 1
fill ~60~1~29 ~60~13~30 minecraft:ladder 4
fill ~60~16~29 ~60~16~30 minecraft:wooden_slab 0
fill ~61~2~29 ~61~4~30 minecraft:log 1
fill ~61~6~29 ~61~8~30 minecraft:log 1
fill ~61~10~29 ~61~12~30 minecraft:log 1
fill ~61~14~29 ~61~16~30 minecraft:log 1
setblock ~11~32~30 minecraft:cobblestone_wall 0
fill ~27~17~30 ~29~17~30 minecraft:wool 4
fill ~30~17~30 ~30~17~31 minecraft:log 3
setblock ~31~3~30 minecraft:log 3
setblock ~31~5~30 minecraft:torch 5
fill ~31~6~30 ~31~7~30 minecraft:log 3
setblock ~31~9~30 minecraft:torch 5
fill ~31~10~30 ~31~11~30 minecraft:log 3
setblock ~32~3~30 minecraft:torch 5
setblock ~32~5~30 minecraft:log 3
setblock ~32~7~30 minecraft:torch 5
setblock ~32~9~30 minecraft:log 3
fill ~32~17~30 ~32~17~31 minecraft:log 3
fill ~34~17~30 ~36~17~30 minecraft:wool 14
fill ~2~2~31 ~2~4~31 minecraft:glass_pane
fill ~2~6~31 ~2~8~31 minecraft:glass_pane
fill ~2~10~31 ~2~12~31 minecraft:glass_pane
fill ~2~14~31 ~2~16~31 minecraft:glass_pane
fill ~3~5~31 ~3~5~36 minecraft:wooden_slab 8
fill ~3~9~31 ~3~9~36 minecraft:wooden_slab 8
fill ~3~13~31 ~3~13~36 minecraft:wooden_slab 8
setblock ~3~14~31 minecraft:cobblestone_wall 1
setblock ~3~15~31 minecraft:wooden_slab 0
setblock ~5~14~31 minecraft:cobblestone_wall 1
setblock ~6~14~31 minecraft:cobblestone_wall 1
setblock ~6~15~31 minecraft:cobblestone_wall 1
setblock ~7~14~31 minecraft:cobblestone_wall 1
setblock ~7~15~31 minecraft:cobblestone_wall 1
setblock ~7~16~31 minecraft:cobblestone_wall 1
setblock ~8~15~31 minecraft:cobblestone_wall 1
setblock ~8~16~31 minecraft:cobblestone_wall 1
setblock ~8~17~31 minecraft:cobblestone_wall 1
setblock ~9~16~31 minecraft:cobblestone_wall 1
setblock ~9~17~31 minecraft:cobblestone_wall 1
setblock ~9~18~31 minecraft:cobblestone_wall 1
setblock ~10~18~31 minecraft:cobblestone_wall 1
setblock ~27~1~31 minecraft:cobblestone_wall 1
setblock ~27~12~31 minecraft:cobblestone_wall 0
fill ~27~17~31 ~28~17~31 minecraft:wool 4
fill ~29~17~31 ~29~17~32 minecraft:log 3
fill ~31~0~31 ~32~0~31 minecraft:glowstone
fill ~31~1~31 ~32~1~31 minecraft:stone_block_slab 1
fill ~31~16~31 ~32~16~34 minecraft:glowstone
setblock ~33~17~31 minecraft:log 3
setblock ~34~17~31 minecraft:log 3
fill ~35~17~31 ~36~17~31 minecraft:wool 14
setblock ~36~1~31 minecraft:cobblestone_wall 1
setblock ~36~12~31 minecraft:cobblestone_wall 0
setblock ~52~32~31 minecraft:cobblestone_wall 0
setblock ~53~18~31 minecraft:cobblestone_wall 1
setblock ~54~16~31 minecraft:cobblestone_wall 1
setblock ~54~17~31 minecraft:cobblestone_wall 1
setblock ~54~18~31 minecraft:cobblestone_wall 1
setblock ~55~15~31 minecraft:cobblestone_wall 1
setblock ~55~16~31 minecraft:cobblestone_wall 1
setblock ~55~17~31 minecraft:cobblestone_wall 1
setblock ~56~14~31 minecraft:cobblestone_wall 1
setblock ~56~15~31 minecraft:cobblestone_wall 1
setblock ~56~16~31 minecraft:cobblestone_wall 1
setblock ~57~14~31 minecraft:cobblestone_wall 1
setblock ~57~15~31 minecraft:cobblestone_wall 1
setblock ~58~14~31 minecraft:cobblestone_wall 1
fill ~60~5~31 ~60~5~36 minecraft:wooden_slab 8
fill ~60~9~31 ~60~9~36 minecraft:wooden_slab 8
fill ~60~13~31 ~60~13~36 minecraft:wooden_slab 8
setblock ~60~14~31 minecraft:cobblestone_wall 1
setblock ~60~15~31 minecraft:wooden_slab 0
fill ~61~2~31 ~61~4~31 minecraft:glass_pane
fill ~61~6~31 ~61~8~31 minecraft:glass_pane
fill ~61~10~31 ~61~12~31 minecraft:glass_pane
fill ~61~14~31 ~61~16~31 minecraft:glass_pane
fill ~2~2~32 ~2~4~33 minecraft:log 1
fill ~2~6~32 ~2~8~33 minecraft:log 1
fill ~2~10~32 ~2~12~33 minecraft:log 1
fill ~2~14~32 ~2~16~33 minecraft:log 1
fill ~5~14~32 ~5~14~36 minecraft:cobblestone_wall 1
fill ~10~18~32 ~10~18~40 minecraft:cobblestone_wall 1
setblock ~11~32~32 minecraft:cobblestone_wall 0
fill ~27~1~32 ~27~1~33 minecraft:cobblestone_wall 1
setblock ~27~17~32 minecraft:wool 4
setblock ~28~12~32 minecraft:cobblestone_wall 0
fill ~28~13~32 ~28~15~32 minecraft:glass
setblock ~28~16~32 minecraft:glowstone
fill ~28~17~32 ~28~17~33 minecraft:log 3
setblock ~30~17~32 minecraft:log 3
fill ~31~17~32 ~31~17~34 minecraft:wool 4
fill ~32~17~32 ~32~17~34 minecraft:wool 14
setblock ~33~17~32 minecraft:log 3
setblock ~34~17~32 minecraft:log 3
setblock ~35~12~32 minecraft:cobblestone_wall 0
fill ~35~13~32 ~35~15~32 minecraft:glass
setblock ~35~16~32 minecraft:glowstone
setblock ~35~17~32 minecraft:log 3
setblock ~36~1~32 minecraft:cobblestone_wall 1
setblock ~36~16~32 minecraft:glass
setblock ~36~17~32 minecraft:wool 14
fill ~53~18~32 ~53~18~40 minecraft:cobblestone_wall 1
fill ~58~14~32 ~58~14~36 minecraft:cobblestone_wall 1
fill ~61~2~32 ~61~4~33 minecraft:log 1
fill ~61~6~32 ~61~8~33 minecraft:log 1
fill ~61~10~32 ~61~12~33 minecraft:log 1
fill ~61~14~32 ~61~16~33 minecraft:log 1
setblock ~26~17~33 minecraft:wool 4
fill ~27~17~33 ~27~17~34 minecraft:log 3
setblock ~29~12~33 minecraft:cobblestone_wall 0
fill ~29~13~33 ~29~15~33 minecraft:glass
setblock ~29~16~33 minecraft:glowstone
setblock ~29~17~33 minecraft:log 3
fill ~30~17~33 ~30~17~34 minecraft:wool 4
fill ~33~17~33 ~33~17~34 minecraft:wool 14
setblock ~34~12~33 minecraft:cobblestone_wall 0
fill ~34~13~33 ~34~15~33 minecraft:glass
setblock ~34~16~33 minecraft:glowstone
setblock ~34~17~33 minecraft:log 3
setblock ~35~1~33 minecraft:waterlily
setblock ~35~17~33 minecraft:log 3
setblock ~36~1~33 minecraft:cobblestone_wall 1
setblock ~36~17~33 minecraft:log 3
setblock ~37~17~33 minecraft:wool 14
setblock ~52~32~33 minecraft:cobblestone_wall 0
fill ~2~2~34 ~2~4~34 minecraft:glass_pane
fill ~2~6~34 ~2~8~34 minecraft:glass_pane
fill ~2~10~34 ~2~12~34 minecraft:glass_pane
fill ~2~14~34 ~2~16~34 minecraft:glass_pane
setblock ~11~32~34 minecraft:cobblestone_wall 0
setblock ~25~17~34 minecraft:wool 4
fill ~26~17~34 ~26~17~35 minecraft:log 3
setblock ~27~0~34 minecraft:wool 4
setblock ~27~1~34 minecraft:cobblestone_wall 1
setblock ~27~2~34 minecraft:torch 5
fill ~28~0~34 ~35~0~59 minecraft:planks 0
fill ~28~1~34 ~29~1~34 minecraft:cobblestone_wall 1
setblock ~28~17~34 minecraft:log 3
setblock ~29~17~34 minecraft:wool 4
setblock ~30~1~34 minecraft:cobblestone_wall 1
setblock ~30~12~34 minecraft:cobblestone_wall 0
fill ~30~13~34 ~33~15~34 minecraft:glass
setblock ~30~16~34 minecraft:glowstone
fill ~31~12~34 ~32~12~34 minecraft:cobblestone_wall 0
setblock ~33~1~34 minecraft:cobblestone_wall 1
setblock ~33~12~34 minecraft:cobblestone_wall 0
setblock ~33~16~34 minecraft:glowstone
setblock ~34~1~34 minecraft:cobblestone_wall 1
setblock ~34~17~34 minecraft:wool 14
setblock ~35~1~34 minecraft:cobblestone_wall 1
setblock ~35~17~34 minecraft:log 3
setblock ~36~0~34 minecraft:wool 14
setblock ~36~1~34 minecraft:cobblestone_wall 1
setblock ~36~2~34 minecraft:torch 5
setblock ~36~17~34 minecraft:log 3
setblock ~37~17~34 minecraft:log 3
setblock ~38~17~34 minecraft:wool 14
fill ~61~2~34 ~61~4~34 minecraft:glass_pane
fill ~61~6~34 ~61~8~34 minecraft:glass_pane
fill ~61~10~34 ~61~12~34 minecraft:glass_pane
fill ~61~14~34 ~61~16~34 minecraft:glass_pane
fill ~2~2~35 ~2~4~36 minecraft:log 1
fill ~2~6~35 ~2~8~36 minecraft:log 1
fill ~2~10~35 ~2~12~36 minecraft:log 1
fill ~2~14~35 ~2~16~36 minecraft:log 1
setblock ~24~17~35 minecraft:wool 4
fill ~25~17~35 ~25~17~36 minecraft:log 3
setblock ~26~0~35 minecraft:wool 4
fill ~27~0~35 ~27~0~59 minecraft:planks 0
setblock ~27~17~35 minecraft:log 3
setblock ~28~17~35 minecraft:wool 4
setblock ~35~17~35 minecraft:wool 14
fill ~36~0~35 ~36~0~59 minecraft:planks 0
setblock ~36~17~35 minecraft:log 3
setblock ~37~0~35 minecraft:wool 14
setblock ~37~17~35 minecraft:log 3
setblock ~38~17~35 minecraft:log 3
setblock ~39~17~35 minecraft:wool 14
setblock ~52~32~35 minecraft:cobblestone_wall 0
fill ~61~2~35 ~61~4~36 minecraft:log 1
fill ~61~6~35 ~61~8~36 minecraft:log 1
fill ~61~10~35 ~61~12~36 minecraft:log 1
fill ~61~14~35 ~61~16~36 minecraft:log 1
setblock ~5~10~36 minecraft:cobblestone_wall 1
fill ~6~9~36 ~6~9~42 minecraft:wooden_slab 8
setblock ~6~10~36 minecraft:cobblestone_wall 1
setblock ~11~32~36 minecraft:cobblestone_wall 0
setblock ~23~17~36 minecraft:wool 4
fill ~24~17~36 ~24~17~37 minecraft:log 3
setblock ~25~0~36 minecraft:wool 4
fill ~26~0~36 ~26~0~59 minecraft:planks 0
setblock ~26~17~36 minecraft:log 3
setblock ~27~17~36 minecraft:wool 4
setblock ~36~17~36 minecraft:wool 14
fill ~37~0~36 ~37~0~59 minecraft:planks 0
setblock ~37~17~36 minecraft:log 3
setblock ~38~0~36 minecraft:wool 14
setblock ~38~17~36 minecraft:log 3
setblock ~39~17~36 minecraft:log 3
setblock ~40~17~36 minecraft:wool 14
fill ~57~5~36 ~57~5~42 minecraft:wooden_slab 8
setblock ~57~6~36 minecraft:cobblestone_wall 1
setblock ~58~6~36 minecraft:cobblestone_wall 1
fill ~3~1~37 ~3~1~39 minecraft:planks 0
fill ~3~2~37 ~3~4~39 minecraft:log 1
fill ~3~5~37 ~3~5~39 minecraft:planks 0
fill ~3~6~37 ~3~8~39 minecraft:log 1
fill ~3~9~37 ~3~9~39 minecraft:planks 0
fill ~3~10~37 ~3~12~39 minecraft:log 1
fill ~3~13~37 ~3~13~39 minecraft:planks 0
fill ~3~14~37 ~3~16~39 minecraft:log 1
fill ~3~17~37 ~3~17~39 minecraft:planks 0
setblock ~5~6~37 minecraft:cobblestone_wall 1
setblock ~5~14~37 minecraft:cobblestone_wall 1
fill ~6~5~37 ~6~5~42 minecraft:wooden_slab 8
setblock ~6~6~37 minecraft:cobblestone_wall 1
fill ~6~10~37 ~6~10~38 minecraft:cobblestone_wall 1
fill ~6~13~37 ~6~13~42 minecraft:wooden_slab 8
setblock ~6~14~37 minecraft:cobblestone_wall 1
setblock ~22~17~37 minecraft:wool 4
fill ~23~17~37 ~23~17~38 minecraft:log 3
setblock ~24~0~37 minecraft:wool 4
fill ~25~0~37 ~25~0~59 minecraft:planks 0
setblock ~25~17~37 minecraft:log 3
setblock ~26~17~37 minecraft:wool 4
setblock ~37~17~37 minecraft:wool 14
fill ~38~0~37 ~38~0~59 minecraft:planks 0
setblock ~38~17~37 minecraft:log 3
setblock ~39~0~37 minecraft:wool 14
setblock ~39~17~37 minecraft:log 3
setblock ~40~17~37 minecraft:log 3
setblock ~41~17~37 minecraft:wool 14
setblock ~52~32~37 minecraft:cobblestone_wall 0
fill ~57~6~37 ~57~6~39 minecraft:cobblestone_wall 1
fill ~57~9~37 ~57~9~42 minecraft:wooden_slab 8
setblock ~57~10~37 minecraft:cobblestone_wall 1
fill ~57~13~37 ~57~13~42 minecraft:wooden_slab 8
setblock ~57~14~37 minecraft:cobblestone_wall 1
setblock ~58~10~37 minecraft:cobblestone_wall 1
setblock ~58~14~37 minecraft:cobblestone_wall 1
fill ~60~1~37 ~60~1~39 minecraft:planks 0
fill ~60~2~37 ~60~4~39 minecraft:log 1
fill ~60~5~37 ~60~5~39 minecraft:planks 0
fill ~60~6~37 ~60~8~39 minecraft:log 1
fill ~60~9~37 ~60~9~39 minecraft:planks 0
fill ~60~10~37 ~60~12~39 minecraft:log 1
fill ~60~13~37 ~60~13~39 minecraft:planks 0
fill ~60~14~37 ~60~16~39 minecraft:log 1
fill ~60~17~37 ~60~17~39 minecraft:planks 0
fill ~2~0~38 ~2~0~65 minecraft:grass
fill ~6~6~38 ~6~6~39 minecraft:cobblestone_wall 1
fill ~6~14~38 ~6~14~39 minecraft:cobblestone_wall 1
setblock ~11~32~38 minecraft:cobblestone_wall 0
setblock ~21~17~38 minecraft:wool 4
fill ~22~17~38 ~22~17~39 minecraft:log 3
setblock ~23~0~38 minecraft:wool 4
fill ~24~0~38 ~24~0~58 minecraft:planks 0
setblock ~24~17~38 minecraft:log 3
setblock ~25~17~38 minecraft:wool 4
setblock ~38~17~38 minecraft:wool 14
fill ~39~0~38 ~39~0~59 minecraft:planks 0
setblock ~39~17~38 minecraft:log 3
setblock ~40~0~38 minecraft:wool 14
setblock ~40~17~38 minecraft:log 3
setblock ~41~17~38 minecraft:log 3
setblock ~42~17~38 minecraft:wool 14
fill ~57~10~38 ~57~10~39 minecraft:cobblestone_wall 1
fill ~57~14~38 ~57~14~39 minecraft:cobblestone_wall 1
setblock ~6~10~39 minecraft:cobblestone_wall 1
fill ~7~9~39 ~7~9~42 minecraft:wooden_slab 8
setblock ~7~10~39 minecraft:cobblestone_wall 1
setblock ~20~17~39 minecraft:wool 4
fill ~21~17~39 ~21~17~40 minecraft:log 3
setblock ~22~0~39 minecraft:wool 4
fill ~23~0~39 ~23~0~58 minecraft:planks 0
setblock ~23~17~39 minecraft:log 3
setblock ~24~17~39 minecraft:wool 4
setblock ~39~17~39 minecraft:wool 14
fill ~40~0~39 ~40~0~59 minecraft:planks 0
setblock ~40~17~39 minecraft:log 3
setblock ~41~0~39 minecraft:wool 14
setblock ~41~17~39 minecraft:log 3
setblock ~42~17~39 minecraft:log 3
setblock ~43~17~39 minecraft:wool 14
setblock ~52~32~39 minecraft:cobblestone_wall 0
fill ~3~0~40 ~3~0~47 minecraft:grass
fill ~4~1~40 ~4~1~41 minecraft:planks 0
fill ~4~2~40 ~4~4~41 minecraft:log 1
fill ~4~5~40 ~4~5~41 minecraft:planks 0
fill ~4~6~40 ~4~8~41 minecraft:log 1
fill ~4~9~40 ~4~9~41 minecraft:planks 0
fill ~4~10~40 ~4~12~41 minecraft:log 1
fill ~4~13~40 ~4~13~41 minecraft:planks 0
fill ~4~14~40 ~4~16~41 minecraft:log 1
fill ~4~17~40 ~4~17~41 minecraft:planks 0
setblock ~6~6~40 minecraft:cobblestone_wall 1
setblock ~6~14~40 minecraft:cobblestone_wall 1
fill ~7~5~40 ~7~5~42 minecraft:wooden_slab 8
setblock ~7~6~40 minecraft:cobblestone_wall 1
setblock ~7~10~40 minecraft:cobblestone_wall 1
fill ~7~13~40 ~7~13~42 minecraft:wooden_slab 8
setblock ~7~14~40 minecraft:cobblestone_wall 1
setblock ~11~32~40 minecraft:cobblestone_wall 0
setblock ~19~17~40 minecraft:wool 4
fill ~20~17~40 ~20~17~41 minecraft:log 3
setblock ~21~0~40 minecraft:wool 4
fill ~22~0~40 ~22~0~58 minecraft:planks 0
setblock ~22~17~40 minecraft:log 3
setblock ~23~17~40 minecraft:wool 4
setblock ~40~17~40 minecraft:wool 14
fill ~41~0~40 ~41~0~59 minecraft:planks 0
setblock ~41~17~40 minecraft:log 3
setblock ~42~0~40 minecraft:wool 14
setblock ~42~17~40 minecraft:log 3
setblock ~43~17~40 minecraft:log 3
setblock ~44~17~40 minecraft:wool 14
fill ~56~5~40 ~56~5~42 minecraft:wooden_slab 8
setblock ~56~6~40 minecraft:cobblestone_wall 1
fill ~56~9~40 ~56~9~42 minecraft:wooden_slab 8
setblock ~56~10~40 minecraft:cobblestone_wall 1
fill ~56~13~40 ~56~13~42 minecraft:wooden_slab 8
setblock ~56~14~40 minecraft:cobblestone_wall 1
setblock ~57~6~40 minecraft:cobblestone_wall 1
setblock ~57~10~40 minecraft:cobblestone_wall 1
setblock ~57~14~40 minecraft:cobblestone_wall 1
fill ~59~1~40 ~59~1~41 minecraft:planks 0
fill ~59~2~40 ~59~4~41 minecraft:log 1
fill ~59~5~40 ~59~5~41 minecraft:planks 0
fill ~59~6~40 ~59~8~41 minecraft:log 1
fill ~59~9~40 ~59~9~41 minecraft:planks 0
fill ~59~10~40 ~59~12~41 minecraft:log 1
setblock ~59~13~40 minecraft:double_wooden_slab 0
fill ~59~14~40 ~59~16~41 minecraft:log 1
fill ~59~17~40 ~59~17~41 minecraft:planks 0
setblock ~7~6~41 minecraft:cobblestone_wall 1
setblock ~7~10~41 minecraft:cobblestone_wall 1
setblock ~7~14~41 minecraft:cobblestone_wall 1
fill ~8~5~41 ~8~5~42 minecraft:wooden_slab 8
setblock ~8~6~41 minecraft:cobblestone_wall 1
fill ~8~9~41 ~8~9~42 minecraft:wooden_slab 8
setblock ~8~10~41 minecraft:cobblestone_wall 1
fill ~8~13~41 ~8~13~42 minecraft:wooden_slab 8
setblock ~8~14~41 minecraft:cobblestone_wall 1
setblock ~10~18~41 minecraft:cobblestone_wall 1
setblock ~11~18~41 minecraft:iron_door 2
setblock ~11~22~41 minecraft:ladder 2
setblock ~11~24~41 minecraft:ladder 2
setblock ~11~26~41 minecraft:ladder 2
setblock ~11~28~41 minecraft:ladder 2
setblock ~11~30~41 minecraft:ladder 2
setblock ~11~32~41 minecraft:ladder 2
setblock ~18~17~41 minecraft:wool 4
fill ~19~17~41 ~19~17~42 minecraft:log 3
setblock ~20~0~41 minecraft:wool 4
fill ~21~0~41 ~21~0~57 minecraft:planks 0
setblock ~21~17~41 minecraft:log 3
setblock ~22~17~41 minecraft:wool 4
setblock ~41~17~41 minecraft:wool 14
fill ~42~0~41 ~42~0~59 minecraft:planks 0
setblock ~42~17~41 minecraft:log 3
setblock ~43~0~41 minecraft:wool 14
setblock ~43~17~41 minecraft:log 3
setblock ~44~17~41 minecraft:log 3
setblock ~45~17~41 minecraft:wool 14
setblock ~52~18~41 minecraft:iron_door 0
setblock ~52~22~41 minecraft:ladder 2
setblock ~52~24~41 minecraft:ladder 2
setblock ~52~26~41 minecraft:ladder 2
setblock ~52~28~41 minecraft:ladder 2
setblock ~52~30~41 minecraft:ladder 2
setblock ~52~32~41 minecraft:ladder 2
setblock ~53~18~41 minecraft:cobblestone_wall 1
fill ~55~5~41 ~55~5~42 minecraft:wooden_slab 8
setblock ~55~6~41 minecraft:cobblestone_wall 1
fill ~55~9~41 ~55~9~42 minecraft:wooden_slab 8
setblock ~55~10~41 minecraft:cobblestone_wall 1
fill ~55~13~41 ~55~13~42 minecraft:wooden_slab 8
setblock ~55~14~41 minecraft:cobblestone_wall 1
setblock ~56~6~41 minecraft:cobblestone_wall 1
setblock ~56~10~41 minecraft:cobblestone_wall 1
setblock ~56~14~41 minecraft:cobblestone_wall 1
setblock ~59~13~41 minecraft:planks 0
fill ~4~0~42 ~4~0~45 minecraft:grass
setblock ~5~1~42 minecraft:planks 0
fill ~5~2~42 ~5~4~42 minecraft:log 1
setblock ~5~5~42 minecraft:planks 0
fill ~5~6~42 ~5~8~42 minecraft:log 1
setblock ~5~9~42 minecraft:planks 0
fill ~5~10~42 ~5~12~42 minecraft:log 1
setblock ~5~13~42 minecraft:planks 0
fill ~5~14~42 ~5~16~42 minecraft:log 1
setblock ~5~17~42 minecraft:planks 0
setblock ~8~6~42 minecraft:cobblestone_wall 1
setblock ~8~10~42 minecraft:cobblestone_wall 1
setblock ~8~14~42 minecraft:cobblestone_wall 1
fill ~9~0~42 ~13~0~47 minecraft:planks 1
fill ~9~1~42 ~9~4~42 minecraft:wool 4
fill ~9~5~42 ~13~16~42 minecraft:log 1
fill ~9~17~42 ~10~17~42 minecraft:log 1
fill ~9~18~42 ~9~27~42 minecraft:log 1
fill ~9~28~42 ~13~32~42 minecraft:planks 0
setblock ~10~1~42 minecraft:iron_door 3
fill ~10~3~42 ~12~3~42 minecraft:cobblestone_wall 1
fill ~10~4~42 ~13~4~42 minecraft:wool 4
fill ~10~18~42 ~10~21~42 minecraft:wool 4
fill ~10~22~42 ~13~27~42 minecraft:log 1
setblock ~11~17~42 minecraft:wool 4
fill ~11~21~42 ~12~21~42 minecraft:wool 4
setblock ~12~1~42 minecraft:iron_door 3
fill ~12~17~42 ~13~17~42 minecraft:log 1
fill ~12~18~42 ~12~20~42 minecraft:wool 4
fill ~13~1~42 ~13~3~42 minecraft:wool 4
fill ~13~18~42 ~13~21~42 minecraft:log 1
setblock ~17~17~42 minecraft:wool 4
fill ~18~17~42 ~18~17~43 minecraft:log 3
setblock ~19~0~42 minecraft:wool 4
fill ~20~0~42 ~20~0~57 minecraft:planks 0
setblock ~20~17~42 minecraft:log 3
setblock ~21~17~42 minecraft:wool 4
setblock ~42~17~42 minecraft:wool 14
fill ~43~0~42 ~43~0~59 minecraft:planks 0
setblock ~43~17~42 minecraft:log 3
setblock ~44~0~42 minecraft:wool 14
fill ~44~17~42 ~45~17~42 minecraft:log 3
setblock ~46~17~42 minecraft:wool 14
fill ~50~0~42 ~54~0~47 minecraft:planks 1
fill ~50~1~42 ~50~4~42 minecraft:wool 14
fill ~50~5~42 ~54~16~42 minecraft:log 1
fill ~50~17~42 ~51~17~42 minecraft:log 1
fill ~50~18~42 ~50~27~42 minecraft:log 1
fill ~50~28~42 ~54~32~42 minecraft:planks 0
setblock ~51~1~42 minecraft:iron_door 3
fill ~51~3~42 ~53~3~42 minecraft:cobblestone_wall 1
fill ~51~4~42 ~54~4~42 minecraft:wool 14
fill ~51~18~42 ~51~21~42 minecraft:wool 14
fill ~51~22~42 ~54~27~42 minecraft:log 1
setblock ~52~17~42 minecraft:wool 14
fill ~52~21~42 ~53~21~42 minecraft:wool 14
setblock ~53~1~42 minecraft:iron_door 3
fill ~53~17~42 ~54~17~42 minecraft:log 1
fill ~53~18~42 ~53~20~42 minecraft:wool 14
fill ~54~1~42 ~54~3~42 minecraft:wool 14
fill ~54~18~42 ~54~21~42 minecraft:log 1
setblock ~55~6~42 minecraft:cobblestone_wall 1
setblock ~55~10~42 minecraft:cobblestone_wall 1
setblock ~55~14~42 minecraft:cobblestone_wall 1
setblock ~58~1~42 minecraft:planks 0
fill ~58~2~42 ~58~4~42 minecraft:log 1
setblock ~58~5~42 minecraft:planks 0
fill ~58~6~42 ~58~8~42 minecraft:log 1
setblock ~58~9~42 minecraft:planks 0
fill ~58~10~42 ~58~12~42 minecraft:log 1
setblock ~58~13~42 minecraft:planks 0
fill ~58~14~42 ~58~16~42 minecraft:log 1
setblock ~58~17~42 minecraft:planks 0
setblock ~5~0~43 minecraft:grass
fill ~6~0~43 ~6~1~43 minecraft:planks 0
fill ~6~2~43 ~8~4~43 minecraft:log 1
setblock ~6~5~43 minecraft:planks 0
fill ~6~6~43 ~6~8~44 minecraft:log 1
setblock ~6~9~43 minecraft:planks 0
fill ~6~10~43 ~6~12~44 minecraft:log 1
setblock ~6~13~43 minecraft:planks 0
fill ~6~14~43 ~6~16~44 minecraft:log 1
setblock ~6~17~43 minecraft:planks 0
fill ~7~0~43 ~8~0~45 minecraft:planks 1
fill ~7~1~43 ~8~1~43 minecraft:log 1
setblock ~7~5~43 minecraft:glowstone
setblock ~7~8~43 minecraft:wool 4
setblock ~7~9~43 minecraft:glowstone
fill ~7~12~43 ~8~12~43 minecraft:log 1
setblock ~7~13~43 minecraft:glowstone
fill ~7~16~43 ~8~26~43 minecraft:log 1
setblock ~7~27~43 minecraft:log 1
fill ~7~28~43 ~8~32~43 minecraft:planks 0
fill ~8~5~43 ~8~11~43 minecraft:log 1
fill ~8~13~43 ~8~15~43 minecraft:log 1
fill ~8~27~43 ~14~27~43 minecraft:planks 0
fill ~8~33~43 ~10~33~43 minecraft:planks 0
fill ~9~16~43 ~13~16~43 minecraft:wool 11
fill ~9~17~43 ~13~17~57 minecraft:cobblestone_wall 0
fill ~9~26~43 ~13~26~43 minecraft:planks 0
fill ~9~34~43 ~10~34~43 minecraft:planks 0
setblock ~11~1~43 minecraft:iron_door 2
fill ~11~28~43 ~11~32~43 minecraft:ladder 3
setblock ~11~35~43 minecraft:wool 4
fill ~12~33~43 ~14~33~43 minecraft:planks 0
fill ~12~34~43 ~13~34~43 minecraft:planks 0
fill ~14~0~43 ~15~0~45 minecraft:planks 1
fill ~14~1~43 ~15~17~43 minecraft:log 1
fill ~14~18~43 ~14~26~43 minecraft:log 1
fill ~14~28~43 ~15~32~43 minecraft:planks 0
fill ~15~18~43 ~15~21~43 minecraft:wool 4
fill ~15~22~43 ~15~27~43 minecraft:log 1
setblock ~16~17~43 minecraft:wool 4
setblock ~17~17~43 minecraft:log 3
setblock ~18~0~43 minecraft:wool 4
fill ~19~0~43 ~19~0~47 minecraft:planks 0
setblock ~19~17~43 minecraft:log 3
setblock ~20~17~43 minecraft:wool 4
setblock ~43~17~43 minecraft:wool 14
fill ~44~0~43 ~44~0~47 minecraft:planks 0
setblock ~44~17~43 minecraft:log 3
setblock ~45~0~43 minecraft:wool 14
fill ~45~17~43 ~46~17~43 minecraft:log 3
setblock ~47~17~43 minecraft:wool 14
fill ~47~21~43 ~48~21~43 minecraft:wool 14
fill ~48~0~43 ~49~0~45 minecraft:planks 1
fill ~48~1~43 ~49~17~43 minecraft:log 1
fill ~48~18~43 ~48~20~43 minecraft:wool 14
fill ~48~22~43 ~49~26~43 minecraft:log 1
setblock ~48~27~43 minecraft:log 1
fill ~48~28~43 ~49~32~43 minecraft:planks 0
fill ~49~18~43 ~49~21~43 minecraft:log 1
fill ~49~27~43 ~55~27~43 minecraft:planks 0
fill ~49~33~43 ~51~33~43 minecraft:planks 0
fill ~50~16~43 ~54~16~43 minecraft:wool 11
fill ~50~17~43 ~54~17~57 minecraft:cobblestone_wall 0
fill ~50~26~43 ~54~26~43 minecraft:planks 0
fill ~50~34~43 ~51~34~43 minecraft:planks 0
setblock ~52~1~43 minecraft:iron_door 2
fill ~52~28~43 ~52~32~43 minecraft:ladder 3
setblock ~52~35~43 minecraft:wool 14
fill ~53~33~43 ~55~33~43 minecraft:planks 0
fill ~53~34~43 ~54~34~43 minecraft:planks 0
fill ~55~0~43 ~56~0~45 minecraft:planks 1
fill ~55~1~43 ~56~4~43 minecraft:log 1
fill ~55~5~43 ~55~26~43 minecraft:log 1
fill ~55~28~43 ~56~32~43 minecraft:planks 0
setblock ~56~5~43 minecraft:glowstone
setblock ~56~8~43 minecraft:wool 14
setblock ~56~9~43 minecraft:glowstone
setblock ~56~12~43 minecraft:wool 14
setblock ~56~13~43 minecraft:glowstone
setblock ~56~16~43 minecraft:wool 14
fill ~56~17~43 ~56~27~43 minecraft:log 1
setblock ~57~1~43 minecraft:planks 0
fill ~57~2~43 ~57~4~44 minecraft:log 1
setblock ~57~5~43 minecraft:planks 0
fill ~57~6~43 ~57~8~44 minecraft:log 1
setblock ~57~9~43 minecraft:planks 0
fill ~57~10~43 ~57~12~44 minecraft:log 1
setblock ~57~13~43 minecraft:planks 0
fill ~57~14~43 ~57~16~44 minecraft:log 1
setblock ~57~17~43 minecraft:planks 0
fill ~5~0~44 ~6~0~44 minecraft:planks 1
fill ~5~1~44 ~6~5~44 minecraft:log 1
fill ~5~6~44 ~5~26~45 minecraft:log 1
fill ~5~27~44 ~5~29~44 minecraft:log 1
fill ~5~30~44 ~6~30~44 minecraft:planks 0
setblock ~6~9~44 minecraft:log 1
setblock ~6~13~44 minecraft:log 1
fill ~6~17~44 ~6~26~44 minecraft:log 1
fill ~6~27~44 ~7~27~44 minecraft:planks 0
fill ~6~28~44 ~6~29~44 minecraft:planks 0
fill ~6~31~44 ~6~33~44 minecraft:planks 0
fill ~7~5~44 ~7~5~45 minecraft:wooden_slab 8
fill ~7~9~44 ~7~9~45 minecraft:wooden_slab 8
fill ~7~13~44 ~7~13~45 minecraft:wooden_slab 8
fill ~7~16~44 ~8~16~44 minecraft:wool 11
fill ~7~17~44 ~8~17~56 minecraft:cobblestone_wall 0
fill ~7~26~44 ~8~26~44 minecraft:planks 0
fill ~7~33~44 ~7~34~44 minecraft:planks 0
fill ~8~25~44 ~14~25~44 minecraft:planks 0
fill ~8~34~44 ~8~35~44 minecraft:planks 0
fill ~9~16~44 ~13~16~44 minecraft:wool 2
fill ~9~35~44 ~14~35~44 minecraft:planks 0
fill ~11~24~44 ~11~24~45 minecraft:planks 0
fill ~11~26~44 ~11~27~44 minecraft:ladder 3
fill ~11~36~44 ~11~36~45 minecraft:planks 0
fill ~14~16~44 ~15~16~44 minecraft:wool 11
fill ~14~17~44 ~15~17~56 minecraft:cobblestone_wall 0
fill ~14~26~44 ~15~26~44 minecraft:planks 0
fill ~14~34~44 ~15~34~44 minecraft:planks 0
fill ~15~27~44 ~16~27~44 minecraft:planks 0
fill ~15~33~44 ~16~33~44 minecraft:planks 0
fill ~16~0~44 ~17~1~44 minecraft:wool 4
fill ~16~2~44 ~17~16~44 minecraft:log 1
fill ~16~17~44 ~17~17~44 minecraft:wool 2
setblock ~16~18~44 minecraft:iron_door 0
fill ~16~21~44 ~17~21~44 minecraft:wool 4
fill ~16~22~44 ~17~26~44 minecraft:log 1
fill ~16~28~44 ~16~32~44 minecraft:planks 0
fill ~17~27~44 ~17~29~44 minecraft:log 1
fill ~17~30~44 ~17~30~45 minecraft:planks 0
fill ~18~0~44 ~18~0~45 minecraft:planks 0
setblock ~18~17~44 minecraft:log 3
setblock ~19~17~44 minecraft:wool 4
setblock ~44~17~44 minecraft:wool 14
fill ~45~0~44 ~45~0~45 minecraft:planks 0
setblock ~45~17~44 minecraft:log 3
fill ~46~0~44 ~47~0~44 minecraft:planks 1
fill ~46~1~44 ~47~1~44 minecraft:wool 14
fill ~46~2~44 ~47~16~44 minecraft:log 1
fill ~46~17~44 ~47~17~44 minecraft:wool 11
fill ~46~21~44 ~46~21~45 minecraft:wool 14
fill ~46~22~44 ~47~26~44 minecraft:log 1
fill ~46~27~44 ~46~29~44 minecraft:log 1
fill ~46~30~44 ~47~30~44 minecraft:planks 0
setblock ~47~18~44 minecraft:iron_door 2
fill ~47~27~44 ~48~27~44 minecraft:planks 0
fill ~47~28~44 ~47~29~44 minecraft:planks 0
fill ~47~31~44 ~47~33~44 minecraft:planks 0
fill ~48~16~44 ~49~16~44 minecraft:wool 11
fill ~48~17~44 ~49~17~56 minecraft:cobblestone_wall 0
fill ~48~26~44 ~49~26~44 minecraft:planks 0
fill ~48~33~44 ~48~34~44 minecraft:planks 0
fill ~49~25~44 ~55~25~44 minecraft:planks 0
fill ~49~34~44 ~49~35~44 minecraft:planks 0
fill ~50~16~44 ~54~16~44 minecraft:wool 2
fill ~50~35~44 ~55~35~44 minecraft:planks 0
fill ~52~24~44 ~52~24~45 minecraft:planks 0
fill ~52~26~44 ~52~27~44 minecraft:ladder 3
fill ~52~36~44 ~52~36~45 minecraft:planks 0
fill ~55~16~44 ~56~16~44 minecraft:wool 11
fill ~55~17~44 ~56~17~56 minecraft:cobblestone_wall 0
fill ~55~26~44 ~56~26~44 minecraft:planks 0
fill ~55~34~44 ~56~34~44 minecraft:planks 0
fill ~56~5~44 ~56~5~45 minecraft:wooden_slab 8
fill ~56~9~44 ~56~9~45 minecraft:wooden_slab 8
fill ~56~13~44 ~56~13~45 minecraft:wooden_slab 8
fill ~56~27~44 ~57~27~44 minecraft:planks 0
fill ~56~33~44 ~57~33~44 minecraft:planks 0
fill ~57~0~44 ~58~0~44 minecraft:planks 1
fill ~57~1~44 ~58~1~44 minecraft:log 1
fill ~57~5~44 ~58~5~44 minecraft:log 1
fill ~57~9~44 ~58~9~44 minecraft:log 1
fill ~57~13~44 ~58~13~44 minecraft:log 1
fill ~57~17~44 ~58~26~44 minecraft:log 1
fill ~57~28~44 ~57~32~44 minecraft:planks 0
fill ~58~2~44 ~58~4~45 minecraft:log 1
fill ~58~6~44 ~58~8~45 minecraft:log 1
