fill ~1~2~0 ~26~2~0 minecraft:border_block
setblock ~27~2~0 minecraft:border_block
fill ~0~2~1 ~0~2~28 minecraft:border_block
fill ~1~0~1 ~26~1~1 minecraft:concrete
fill ~1~2~1 ~26~2~6 minecraft:concrete 7
fill ~27~2~1 ~27~2~26 minecraft:border_block
setblock ~0~12~2 minecraft:glowstone
fill ~0~13~2 ~4~13~2 minecraft:iron_bars
fill ~1~0~2 ~1~1~28 minecraft:concrete
fill ~1~14~2 ~3~14~2 minecraft:lodestone
setblock ~2~3~2 minecraft:crimson_fence
fill ~2~4~2 ~2~12~2 minecraft:iron_bars
setblock ~4~12~2 minecraft:glowstone
setblock ~14~12~2 minecraft:glowstone
fill ~14~13~2 ~18~13~2 minecraft:iron_bars
fill ~15~14~2 ~17~14~2 minecraft:lodestone
setblock ~16~3~2 minecraft:crimson_fence
fill ~16~4~2 ~16~12~2 minecraft:iron_bars
setblock ~18~12~2 minecraft:glowstone
fill ~26~0~2 ~26~1~26 minecraft:concrete
fill ~8~7~5 ~8~7~6 minecraft:quartz_block
fill ~9~7~5 ~9~7~6 minecraft:stained_hardened_clay 14
fill ~10~7~5 ~10~7~6 minecraft:quartz_block
fill ~11~7~5 ~11~7~6 minecraft:stained_hardened_clay 14
fill ~12~7~5 ~12~7~6 minecraft:quartz_block
fill ~13~7~5 ~13~7~6 minecraft:stained_hardened_clay 14
fill ~14~7~5 ~14~7~6 minecraft:quartz_block
fill ~15~7~5 ~15~7~6 minecraft:stained_hardened_clay 14
fill ~16~7~5 ~16~7~6 minecraft:quartz_block
fill ~17~7~5 ~17~7~6 minecraft:stained_hardened_clay 14
fill ~18~7~5 ~18~7~6 minecraft:quartz_block
fill ~19~7~5 ~19~7~6 minecraft:stained_hardened_clay 14
fill ~20~7~5 ~20~7~6 minecraft:quartz_block
fill ~21~7~5 ~21~7~6 minecraft:stained_hardened_clay 14
fill ~22~7~5 ~22~7~6 minecraft:quartz_block
fill ~23~7~5 ~23~7~6 minecraft:stained_hardened_clay 14
fill ~24~7~5 ~24~7~6 minecraft:quartz_block
setblock ~9~8~6 minecraft:stained_hardened_clay 14
fill ~9~9~6 ~11~9~6 minecraft:concrete 5
fill ~9~10~6 ~9~11~6 minecraft:concrete 5
fill ~9~13~6 ~11~13~6 minecraft:concrete 5
setblock ~10~8~6 minecraft:quartz_block
fill ~10~11~6 ~11~11~6 minecraft:concrete 5
setblock ~11~8~6 minecraft:stained_hardened_clay 14
setblock ~11~12~6 minecraft:concrete 5
setblock ~12~8~6 minecraft:quartz_block
setblock ~13~8~6 minecraft:stained_hardened_clay 14
fill ~13~9~6 ~13~13~6 minecraft:concrete 5
setblock ~14~8~6 minecraft:quartz_block
setblock ~14~10~6 minecraft:concrete 5
setblock ~15~8~6 minecraft:stained_hardened_clay 14
fill ~15~11~6 ~16~11~6 minecraft:concrete 5
setblock ~16~8~6 minecraft:quartz_block
fill ~16~9~6 ~16~10~6 minecraft:concrete 5
fill ~16~12~6 ~16~13~6 minecraft:concrete 5
setblock ~17~8~6 minecraft:stained_hardened_clay 14
setblock ~18~8~6 minecraft:quartz_block
fill ~18~9~6 ~20~9~6 minecraft:concrete 5
fill ~18~13~6 ~20~13~6 minecraft:concrete 5
setblock ~19~8~6 minecraft:stained_hardened_clay 14
fill ~19~11~6 ~20~11~6 minecraft:concrete 5
setblock ~20~8~6 minecraft:quartz_block
setblock ~20~10~6 minecraft:concrete 5
setblock ~20~12~6 minecraft:concrete 5
setblock ~21~8~6 minecraft:stained_hardened_clay 14
setblock ~22~8~6 minecraft:quartz_block
fill ~22~9~6 ~24~9~6 minecraft:concrete 5
fill ~22~10~6 ~22~11~6 minecraft:concrete 5
fill ~22~13~6 ~23~13~6 minecraft:concrete 5
setblock ~23~8~6 minecraft:stained_hardened_clay 14
fill ~24~10~6 ~24~12~6 minecraft:concrete 5
fill ~1~2~7 ~7~2~26 minecraft:concrete 7
fill ~8~3~7 ~9~7~7 minecraft:stained_hardened_clay 6
fill ~8~8~7 ~24~8~7 minecraft:stained_hardened_clay
fill ~8~9~7 ~24~9~7 minecraft:stained_hardened_clay 6
fill ~8~10~7 ~9~13~7 minecraft:stained_hardened_clay 6
fill ~8~14~7 ~22~14~7 minecraft:stone_block_slab 4
fill ~10~2~7 ~18~2~7 minecraft:concrete 7
fill ~10~6~7 ~13~7~7 minecraft:stained_hardened_clay 6
fill ~10~10~7 ~11~12~7 minecraft:concrete 3
fill ~10~13~7 ~24~13~7 minecraft:stained_hardened_clay 6
fill ~12~3~7 ~24~3~7 minecraft:stained_hardened_clay 6
fill ~12~4~7 ~13~5~7 minecraft:stained_hardened_clay 6
fill ~12~10~7 ~13~12~7 minecraft:stained_hardened_clay 6
fill ~14~4~7 ~23~6~7 minecraft:stained_glass_pane 9
fill ~14~7~7 ~24~7~7 minecraft:stained_hardened_clay 6
fill ~14~10~7 ~15~12~7 minecraft:concrete 3
fill ~16~10~7 ~17~12~7 minecraft:stained_hardened_clay 6
fill ~18~10~7 ~19~12~7 minecraft:concrete 3
fill ~20~10~7 ~21~12~7 minecraft:stained_hardened_clay 6
fill ~22~10~7 ~23~12~7 minecraft:concrete 3
fill ~24~4~7 ~24~6~8 minecraft:stained_hardened_clay 6
fill ~24~10~7 ~24~12~25 minecraft:stained_hardened_clay 6
fill ~25~2~7 ~26~2~26 minecraft:concrete 7
fill ~8~3~8 ~8~3~25 minecraft:stained_hardened_clay 6
fill ~8~4~8 ~8~7~11 minecraft:stained_hardened_clay 6
fill ~8~8~8 ~8~8~25 minecraft:stained_hardened_clay
fill ~8~9~8 ~8~13~25 minecraft:stained_hardened_clay 6
fill ~8~14~8 ~8~14~25 minecraft:stone_block_slab 4
fill ~9~2~8 ~12~2~9 minecraft:amethyst_block
setblock ~9~8~8 minecraft:sea_lantern
fill ~9~13~8 ~23~13~24 minecraft:concrete 7
setblock ~9~14~8 minecraft:sea_lantern
fill ~10~8~8 ~12~8~24 minecraft:concrete
setblock ~13~2~8 minecraft:concrete
setblock ~13~3~8 minecraft:stained_hardened_clay
fill ~13~4~8 ~13~4~9 minecraft:stained_glass_pane
setblock ~13~8~8 minecraft:sea_lantern
setblock ~14~2~8 minecraft:concrete 7
setblock ~14~3~8 minecraft:stripped_oak_log
fill ~14~8~8 ~15~8~24 minecraft:concrete
setblock ~15~2~8 minecraft:concrete
setblock ~15~3~8 minecraft:stained_hardened_clay
fill ~15~4~8 ~15~4~9 minecraft:stained_glass_pane
setblock ~16~2~8 minecraft:concrete 7
setblock ~16~3~8 minecraft:grass
setblock ~16~8~8 minecraft:sea_lantern
fill ~17~2~8 ~17~2~24 minecraft:concrete 14
setblock ~17~3~8 minecraft:stained_hardened_clay
fill ~17~4~8 ~17~4~9 minecraft:stained_glass_pane
fill ~17~8~8 ~18~8~24 minecraft:concrete
setblock ~18~3~8 minecraft:gold_ore
setblock ~19~2~8 minecraft:concrete
setblock ~19~8~8 minecraft:sea_lantern
setblock ~20~3~8 minecraft:stripped_oak_log
fill ~20~8~8 ~22~8~24 minecraft:concrete
setblock ~21~2~8 minecraft:concrete
setblock ~22~3~8 minecraft:grass
setblock ~23~2~8 minecraft:concrete
setblock ~23~8~8 minecraft:sea_lantern
setblock ~23~14~8 minecraft:sea_lantern
fill ~24~3~8 ~24~3~25 minecraft:stained_hardened_clay 6
fill ~24~7~8 ~24~7~25 minecraft:stained_hardened_clay 6
fill ~24~8~8 ~24~8~25 minecraft:stained_hardened_clay
fill ~24~9~8 ~24~9~25 minecraft:stained_hardened_clay 6
fill ~24~13~8 ~24~13~25 minecraft:stained_hardened_clay 6
fill ~24~14~8 ~24~14~25 minecraft:stone_block_slab 4
fill ~25~7~8 ~26~7~8 minecraft:quartz_block
fill ~1~3~9 ~1~3~27 minecraft:spruce_trapdoor
fill ~9~8~9 ~9~8~12 minecraft:concrete
setblock ~13~2~9 minecraft:concrete 7
setblock ~13~3~9 minecraft:stained_glass_pane
fill ~13~8~9 ~13~8~12 minecraft:concrete
setblock ~14~2~9 minecraft:concrete concrete 4
setblock ~14~3~9 minecraft:light_weighted_pressure_plate
setblock ~15~2~9 minecraft:concrete 7
setblock ~15~3~9 minecraft:stained_glass_pane
setblock ~16~2~9 minecraft:concrete concrete 4
setblock ~16~3~9 minecraft:light_weighted_pressure_plate
fill ~16~8~9 ~16~8~12 minecraft:concrete
setblock ~17~3~9 minecraft:stained_glass_pane
setblock ~18~2~9 minecraft:concrete
setblock ~19~2~9 minecraft:concrete 7
fill ~19~8~9 ~19~8~12 minecraft:concrete
setblock ~20~2~9 minecraft:concrete
setblock ~21~2~9 minecraft:concrete 7
setblock ~22~2~9 minecraft:concrete
setblock ~23~2~9 minecraft:concrete 7
fill ~23~8~9 ~23~8~12 minecraft:concrete
fill ~24~4~9 ~24~6~9 minecraft:stained_hardened_clay 3
fill ~25~7~9 ~26~7~9 minecraft:stained_hardened_clay 14
setblock ~25~8~9 minecraft:stained_hardened_clay 14
fill ~9~2~10 ~9~2~12 minecraft:concrete
setblock ~9~3~10 minecraft:stained_hardened_clay
fill ~9~4~10 ~10~4~10 minecraft:stained_glass_pane
setblock ~10~2~10 minecraft:concrete 7
setblock ~10~3~10 minecraft:stained_glass_pane
setblock ~11~2~10 minecraft:concrete
setblock ~12~2~10 minecraft:concrete 7
setblock ~13~2~10 minecraft:concrete
setblock ~14~2~10 minecraft:concrete 7
setblock ~15~2~10 minecraft:concrete
setblock ~16~2~10 minecraft:concrete 7
setblock ~18~2~10 minecraft:concrete 7
setblock ~19~2~10 minecraft:concrete
setblock ~20~2~10 minecraft:concrete 7
setblock ~21~2~10 minecraft:concrete
setblock ~22~2~10 minecraft:concrete 7
setblock ~23~3~10 minecraft:copper_ore
fill ~24~4~10 ~24~6~10 minecraft:stained_hardened_clay 11
fill ~25~7~10 ~26~7~10 minecraft:quartz_block
setblock ~25~8~10 minecraft:quartz_block
setblock ~9~3~11 minecraft:gold_ore
setblock ~10~2~11 minecraft:concrete concrete 4
setblock ~10~3~11 minecraft:light_weighted_pressure_plate
setblock ~11~2~11 minecraft:concrete 7
setblock ~12~2~11 minecraft:concrete
setblock ~13~2~11 minecraft:concrete 7
setblock ~14~2~11 minecraft:concrete
setblock ~15~2~11 minecraft:concrete 7
setblock ~16~2~11 minecraft:concrete
setblock ~18~2~11 minecraft:concrete
setblock ~19~2~11 minecraft:concrete 7
setblock ~20~2~11 minecraft:concrete
setblock ~21~2~11 minecraft:concrete 7
setblock ~22~2~11 minecraft:concrete
setblock ~23~2~11 minecraft:concrete 7
fill ~24~4~11 ~24~6~11 minecraft:stained_hardened_clay 3
fill ~25~7~11 ~26~7~11 minecraft:stained_hardened_clay 14
setblock ~25~8~11 minecraft:stained_hardened_clay 14
fill ~8~4~12 ~8~6~24 minecraft:stained_glass_pane 9
fill ~8~7~12 ~8~7~25 minecraft:stained_hardened_clay 6
setblock ~9~3~12 minecraft:stained_hardened_clay
fill ~9~4~12 ~10~4~12 minecraft:stained_glass_pane
setblock ~10~2~12 minecraft:concrete 7
setblock ~10~3~12 minecraft:stained_glass_pane
setblock ~11~2~12 minecraft:concrete
setblock ~12~2~12 minecraft:concrete 7
setblock ~13~2~12 minecraft:concrete
setblock ~14~2~12 minecraft:concrete 7
setblock ~15~2~12 minecraft:concrete
setblock ~16~2~12 minecraft:concrete 7
setblock ~18~2~12 minecraft:concrete 7
setblock ~19~2~12 minecraft:concrete
setblock ~20~2~12 minecraft:concrete 7
setblock ~21~2~12 minecraft:concrete
setblock ~22~2~12 minecraft:concrete 7
setblock ~23~2~12 minecraft:concrete
setblock ~23~3~12 minecraft:gravel
fill ~24~4~12 ~24~6~12 minecraft:stained_hardened_clay 11
fill ~25~7~12 ~26~7~12 minecraft:quartz_block
setblock ~25~8~12 minecraft:quartz_block
setblock ~9~2~13 minecraft:concrete 7
setblock ~9~3~13 minecraft:gravel
setblock ~9~8~13 minecraft:sea_lantern
setblock ~10~2~13 minecraft:concrete concrete 4
setblock ~10~3~13 minecraft:light_weighted_pressure_plate
setblock ~11~2~13 minecraft:concrete 7
setblock ~12~2~13 minecraft:concrete
setblock ~13~2~13 minecraft:concrete 7
setblock ~13~8~13 minecraft:sea_lantern
setblock ~14~2~13 minecraft:concrete
setblock ~15~2~13 minecraft:concrete 7
setblock ~16~2~13 minecraft:concrete
setblock ~16~8~13 minecraft:sea_lantern
setblock ~18~2~13 minecraft:concrete
setblock ~19~2~13 minecraft:concrete 7
setblock ~19~8~13 minecraft:sea_lantern
setblock ~20~2~13 minecraft:concrete
setblock ~21~2~13 minecraft:concrete 7
setblock ~22~2~13 minecraft:concrete
setblock ~23~2~13 minecraft:concrete 7
setblock ~23~8~13 minecraft:sea_lantern
fill ~24~4~13 ~24~6~13 minecraft:stained_hardened_clay 3
fill ~25~7~13 ~26~7~13 minecraft:stained_hardened_clay 14
setblock ~25~8~13 minecraft:stained_hardened_clay 14
setblock ~9~2~14 minecraft:concrete
setblock ~9~3~14 minecraft:stained_hardened_clay
fill ~9~4~14 ~10~4~14 minecraft:stained_glass_pane
fill ~9~8~14 ~9~8~15 minecraft:concrete
setblock ~10~2~14 minecraft:concrete 7
setblock ~10~3~14 minecraft:stained_glass_pane
setblock ~11~2~14 minecraft:concrete
setblock ~12~2~14 minecraft:concrete 7
setblock ~13~2~14 minecraft:concrete
fill ~13~8~14 ~13~8~15 minecraft:concrete
setblock ~14~2~14 minecraft:concrete 7
setblock ~15~2~14 minecraft:concrete
setblock ~16~2~14 minecraft:concrete 7
fill ~16~8~14 ~16~8~15 minecraft:concrete
setblock ~18~2~14 minecraft:concrete 7
setblock ~19~2~14 minecraft:concrete
fill ~19~8~14 ~19~8~15 minecraft:concrete
setblock ~20~2~14 minecraft:concrete 7
setblock ~21~2~14 minecraft:concrete
setblock ~22~2~14 minecraft:concrete 7
setblock ~23~3~14 minecraft:sandstone
fill ~23~8~14 ~23~8~15 minecraft:concrete
fill ~24~4~14 ~24~6~14 minecraft:stained_hardened_clay 11
fill ~25~7~14 ~26~7~14 minecraft:quartz_block
setblock ~25~8~14 minecraft:quartz_block
setblock ~9~2~15 minecraft:concrete 7
setblock ~9~3~15 minecraft:sand
setblock ~10~2~15 minecraft:concrete concrete 4
setblock ~10~3~15 minecraft:light_weighted_pressure_plate
setblock ~11~2~15 minecraft:concrete 7
setblock ~12~2~15 minecraft:concrete
setblock ~13~2~15 minecraft:concrete 7
setblock ~14~2~15 minecraft:concrete
setblock ~15~2~15 minecraft:concrete 7
setblock ~16~2~15 minecraft:concrete
setblock ~17~3~15 minecraft:repeating_command_block
fill ~17~4~15 ~17~4~24 minecraft:stained_glass_pane
setblock ~18~2~15 minecraft:concrete
setblock ~19~2~15 minecraft:concrete 7
setblock ~20~2~15 minecraft:concrete
setblock ~21~2~15 minecraft:concrete 7
setblock ~22~2~15 minecraft:concrete
setblock ~23~2~15 minecraft:concrete 7
fill ~24~4~15 ~24~6~15 minecraft:stained_hardened_clay 3
fill ~25~7~15 ~26~7~15 minecraft:stained_hardened_clay 14
setblock ~25~8~15 minecraft:stained_hardened_clay 14
setblock ~9~2~16 minecraft:concrete
setblock ~9~3~16 minecraft:stained_hardened_clay
fill ~9~4~16 ~10~4~16 minecraft:stained_glass_pane
setblock ~9~8~16 minecraft:sea_lantern
setblock ~10~2~16 minecraft:concrete 7
setblock ~10~3~16 minecraft:stained_glass_pane
setblock ~11~2~16 minecraft:concrete
setblock ~12~2~16 minecraft:concrete 7
setblock ~13~2~16 minecraft:concrete
setblock ~13~8~16 minecraft:sea_lantern
setblock ~14~2~16 minecraft:concrete 7
setblock ~15~2~16 minecraft:concrete
setblock ~16~2~16 minecraft:concrete 7
fill ~16~3~16 ~16~4~16 minecraft:stained_glass_pane
setblock ~16~8~16 minecraft:sea_lantern
fill ~17~3~16 ~17~3~18 minecraft:stained_hardened_clay
setblock ~18~2~16 minecraft:concrete 7
fill ~18~3~16 ~18~4~16 minecraft:stained_glass_pane
setblock ~19~2~16 minecraft:concrete
setblock ~19~8~16 minecraft:sea_lantern
setblock ~20~2~16 minecraft:concrete 7
setblock ~21~2~16 minecraft:concrete
setblock ~22~2~16 minecraft:concrete 7
setblock ~23~3~16 minecraft:ancient_debris
setblock ~23~8~16 minecraft:sea_lantern
fill ~24~4~16 ~24~6~16 minecraft:stained_hardened_clay 11
fill ~25~7~16 ~26~7~16 minecraft:quartz_block
setblock ~25~8~16 minecraft:quartz_block
setblock ~9~2~17 minecraft:concrete 7
setblock ~9~3~17 minecraft:ancient_debris
fill ~9~8~17 ~9~8~18 minecraft:concrete
setblock ~10~2~17 minecraft:concrete concrete 4
setblock ~10~3~17 minecraft:light_weighted_pressure_plate
setblock ~11~2~17 minecraft:concrete 7
setblock ~12~2~17 minecraft:concrete
setblock ~13~2~17 minecraft:concrete 7
fill ~13~8~17 ~13~8~18 minecraft:concrete
setblock ~14~2~17 minecraft:concrete
setblock ~15~2~17 minecraft:concrete 7
setblock ~16~2~17 minecraft:concrete concrete 4
setblock ~16~3~17 minecraft:light_weighted_pressure_plate
fill ~16~8~17 ~16~8~18 minecraft:concrete
setblock ~16~14~17 minecraft:sea_lantern
setblock ~18~2~17 minecraft:concrete
setblock ~19~2~17 minecraft:concrete 7
fill ~19~8~17 ~19~8~18 minecraft:concrete
setblock ~20~2~17 minecraft:concrete
setblock ~21~2~17 minecraft:concrete 7
setblock ~22~2~17 minecraft:concrete
setblock ~23~2~17 minecraft:concrete 7
fill ~23~8~17 ~23~8~18 minecraft:concrete
fill ~24~4~17 ~24~6~17 minecraft:stained_hardened_clay 3
fill ~25~7~17 ~26~7~17 minecraft:stained_hardened_clay 14
setblock ~25~8~17 minecraft:stained_hardened_clay 14
setblock ~9~2~18 minecraft:concrete
setblock ~9~3~18 minecraft:stained_hardened_clay
fill ~9~4~18 ~10~4~18 minecraft:stained_glass_pane
setblock ~10~2~18 minecraft:concrete 7
setblock ~10~3~18 minecraft:stained_glass_pane
setblock ~11~2~18 minecraft:concrete
setblock ~12~2~18 minecraft:concrete 7
setblock ~13~2~18 minecraft:concrete
setblock ~14~2~18 minecraft:concrete 7
setblock ~15~2~18 minecraft:concrete
setblock ~16~2~18 minecraft:concrete 7
fill ~16~3~18 ~16~4~18 minecraft:stained_glass_pane
setblock ~18~2~18 minecraft:concrete 7
fill ~18~3~18 ~18~4~18 minecraft:stained_glass_pane
setblock ~19~2~18 minecraft:concrete
setblock ~20~2~18 minecraft:concrete 7
setblock ~21~2~18 minecraft:concrete
setblock ~22~2~18 minecraft:concrete 7
setblock ~23~3~18 minecraft:diamond_ore
fill ~24~4~18 ~24~6~18 minecraft:stained_hardened_clay 11
fill ~25~7~18 ~26~7~18 minecraft:quartz_block
setblock ~25~8~18 minecraft:quartz_block
setblock ~9~2~19 minecraft:concrete 7
setblock ~9~3~19 minecraft:diamond_ore
setblock ~9~8~19 minecraft:sea_lantern
setblock ~10~2~19 minecraft:concrete concrete 4
setblock ~10~3~19 minecraft:light_weighted_pressure_plate
setblock ~11~2~19 minecraft:concrete 7
setblock ~12~2~19 minecraft:concrete
setblock ~13~2~19 minecraft:concrete 7
setblock ~13~8~19 minecraft:sea_lantern
setblock ~14~2~19 minecraft:concrete
setblock ~15~2~19 minecraft:concrete 7
setblock ~16~2~19 minecraft:concrete concrete 4
setblock ~16~3~19 minecraft:light_weighted_pressure_plate
setblock ~16~8~19 minecraft:sea_lantern
fill ~17~3~19 ~18~3~19 minecraft:emerald_ore
setblock ~19~2~19 minecraft:concrete 7
setblock ~19~8~19 minecraft:sea_lantern
setblock ~20~2~19 minecraft:concrete
setblock ~21~2~19 minecraft:concrete 7
setblock ~22~2~19 minecraft:concrete
setblock ~23~2~19 minecraft:concrete 7
setblock ~23~8~19 minecraft:sea_lantern
fill ~24~4~19 ~24~6~19 minecraft:stained_hardened_clay 3
fill ~25~7~19 ~26~7~19 minecraft:stained_hardened_clay 14
setblock ~25~8~19 minecraft:stained_hardened_clay 14
setblock ~9~2~20 minecraft:concrete
setblock ~9~3~20 minecraft:stained_hardened_clay
fill ~9~4~20 ~10~4~20 minecraft:stained_glass_pane
fill ~9~8~20 ~9~8~23 minecraft:concrete
setblock ~10~2~20 minecraft:concrete 7
setblock ~10~3~20 minecraft:stained_glass_pane
setblock ~11~2~20 minecraft:concrete
setblock ~12~2~20 minecraft:concrete 7
setblock ~13~2~20 minecraft:concrete
fill ~13~8~20 ~13~8~23 minecraft:concrete
setblock ~14~2~20 minecraft:concrete 7
setblock ~15~2~20 minecraft:concrete
setblock ~16~2~20 minecraft:concrete 7
fill ~16~3~20 ~16~4~20 minecraft:stained_glass_pane
fill ~16~8~20 ~16~8~23 minecraft:concrete
setblock ~17~3~20 minecraft:stained_hardened_clay
setblock ~18~2~20 minecraft:concrete 7
fill ~18~3~20 ~18~4~20 minecraft:stained_glass_pane
setblock ~19~2~20 minecraft:concrete
fill ~19~8~20 ~19~8~24 minecraft:concrete
setblock ~20~2~20 minecraft:concrete 7
setblock ~21~2~20 minecraft:concrete
setblock ~22~2~20 minecraft:concrete 7
setblock ~23~3~20 minecraft:coal_ore
fill ~23~8~20 ~23~8~23 minecraft:concrete
fill ~24~4~20 ~24~6~20 minecraft:stained_hardened_clay 6
fill ~25~7~20 ~26~7~20 minecraft:quartz_block
setblock ~25~8~20 minecraft:quartz_block
fill ~4~3~21 ~4~6~21 minecraft:iron_bars
setblock ~4~7~21 minecraft:redstone_lamp
setblock ~4~8~21 minecraft:daylight_detector
setblock ~9~2~21 minecraft:concrete 7
setblock ~9~3~21 minecraft:coal_ore
setblock ~10~2~21 minecraft:concrete concrete 4
setblock ~10~3~21 minecraft:light_weighted_pressure_plate
setblock ~11~2~21 minecraft:concrete 7
setblock ~12~2~21 minecraft:concrete
setblock ~13~2~21 minecraft:concrete 7
setblock ~14~2~21 minecraft:concrete
setblock ~15~2~21 minecraft:concrete 7
setblock ~16~2~21 minecraft:concrete concrete 4
setblock ~16~3~21 minecraft:light_weighted_pressure_plate
fill ~17~3~21 ~18~3~21 minecraft:crying_obsidian
setblock ~18~2~21 minecraft:concrete
setblock ~19~2~21 minecraft:concrete 7
setblock ~20~2~21 minecraft:concrete
setblock ~21~2~21 minecraft:concrete 7
setblock ~22~2~21 minecraft:concrete
setblock ~23~2~21 minecraft:concrete 7
fill ~24~4~21 ~24~6~23 minecraft:stained_glass_pane 9
fill ~25~7~21 ~26~7~21 minecraft:stained_hardened_clay 14
setblock ~25~8~21 minecraft:stained_hardened_clay 14
setblock ~9~2~22 minecraft:concrete
setblock ~9~3~22 minecraft:stained_hardened_clay
fill ~9~4~22 ~10~4~22 minecraft:stained_glass_pane
setblock ~10~2~22 minecraft:concrete 7
setblock ~10~3~22 minecraft:stained_glass_pane
setblock ~11~2~22 minecraft:concrete
setblock ~12~2~22 minecraft:concrete 7
setblock ~13~2~22 minecraft:concrete
setblock ~14~2~22 minecraft:concrete 7
setblock ~15~2~22 minecraft:concrete
setblock ~16~2~22 minecraft:concrete 7
fill ~16~3~22 ~16~4~22 minecraft:stained_glass_pane
fill ~17~3~22 ~17~3~24 minecraft:stained_hardened_clay
setblock ~18~2~22 minecraft:concrete 7
fill ~18~3~22 ~18~4~22 minecraft:stained_glass_pane
setblock ~19~2~22 minecraft:concrete
setblock ~20~2~22 minecraft:concrete 7
setblock ~21~2~22 minecraft:concrete
setblock ~22~2~22 minecraft:concrete 7
setblock ~23~3~22 minecraft:stone
fill ~25~7~22 ~26~7~22 minecraft:quartz_block
setblock ~25~8~22 minecraft:quartz_block
setblock ~9~2~23 minecraft:concrete 7
setblock ~9~3~23 minecraft:iron_ore
setblock ~10~2~23 minecraft:concrete concrete 4
setblock ~10~3~23 minecraft:light_weighted_pressure_plate
setblock ~11~2~23 minecraft:concrete 7
fill ~11~3~23 ~11~4~23 minecraft:stained_glass_pane
setblock ~12~2~23 minecraft:concrete concrete 4
setblock ~12~3~23 minecraft:light_weighted_pressure_plate
setblock ~13~2~23 minecraft:concrete 7
fill ~13~3~23 ~13~4~23 minecraft:stained_glass_pane
setblock ~14~2~23 minecraft:concrete concrete 4
setblock ~14~3~23 minecraft:light_weighted_pressure_plate
setblock ~15~2~23 minecraft:concrete 7
fill ~15~3~23 ~15~4~23 minecraft:stained_glass_pane
setblock ~16~2~23 minecraft:concrete concrete 4
setblock ~16~3~23 minecraft:light_weighted_pressure_plate
setblock ~18~2~23 minecraft:concrete
setblock ~19~2~23 minecraft:concrete 7
setblock ~20~2~23 minecraft:concrete
setblock ~21~2~23 minecraft:concrete 7
setblock ~22~2~23 minecraft:concrete
setblock ~23~2~23 minecraft:concrete 7
fill ~25~7~23 ~26~7~23 minecraft:stained_hardened_clay 14
setblock ~25~8~23 minecraft:stained_hardened_clay 14
setblock ~9~2~24 minecraft:concrete
fill ~9~3~24 ~11~3~24 minecraft:stained_hardened_clay
setblock ~9~8~24 minecraft:sea_lantern
setblock ~9~14~24 minecraft:sea_lantern
setblock ~10~2~24 minecraft:concrete 7
setblock ~11~2~24 minecraft:concrete
setblock ~11~4~24 minecraft:stained_glass_pane
setblock ~12~2~24 minecraft:concrete 7
setblock ~12~3~24 minecraft:stone 0
setblock ~12~4~24 minecraft:cobblestone
setblock ~13~2~24 minecraft:concrete
setblock ~13~3~24 minecraft:stained_hardened_clay
setblock ~13~4~24 minecraft:stained_glass_pane
setblock ~13~8~24 minecraft:sea_lantern
setblock ~14~2~24 minecraft:concrete 7
setblock ~14~3~24 minecraft:redstone_ore
setblock ~15~2~24 minecraft:concrete
setblock ~15~3~24 minecraft:stained_hardened_clay
setblock ~15~4~24 minecraft:stained_glass_pane
setblock ~16~2~24 minecraft:concrete 7
setblock ~16~3~24 minecraft:copper_ore
setblock ~16~8~24 minecraft:sea_lantern
setblock ~18~2~24 minecraft:concrete 7
setblock ~19~2~24 minecraft:concrete
setblock ~20~3~24 minecraft:redstone_ore
setblock ~21~2~24 minecraft:concrete
setblock ~22~2~24 minecraft:concrete 7
setblock ~23~3~24 minecraft:iron_ore
setblock ~23~8~24 minecraft:sea_lantern
setblock ~23~14~24 minecraft:sea_lantern
fill ~24~4~24 ~24~6~25 minecraft:stained_hardened_clay 6
fill ~25~7~24 ~26~7~24 minecraft:quartz_block
fill ~8~4~25 ~9~6~25 minecraft:stained_hardened_clay 6
fill ~9~3~25 ~23~3~25 minecraft:stained_hardened_clay 6
fill ~9~7~25 ~23~7~25 minecraft:stained_hardened_clay 6
fill ~9~8~25 ~23~8~25 minecraft:stained_hardened_clay
fill ~9~9~25 ~23~9~25 minecraft:stained_hardened_clay 6
fill ~9~10~25 ~9~13~25 minecraft:stained_hardened_clay 6
fill ~9~14~25 ~23~14~25 minecraft:stone_block_slab 4
fill ~10~4~25 ~22~6~25 minecraft:stained_glass_pane 9
fill ~10~10~25 ~11~12~25 minecraft:concrete 3
fill ~10~13~25 ~23~13~25 minecraft:stained_hardened_clay 6
fill ~12~10~25 ~13~12~25 minecraft:stained_hardened_clay 6
fill ~14~10~25 ~15~12~25 minecraft:concrete 3
fill ~16~10~25 ~17~12~25 minecraft:stained_hardened_clay 6
fill ~18~10~25 ~19~12~25 minecraft:concrete 3
fill ~20~10~25 ~21~12~25 minecraft:stained_hardened_clay 6
fill ~22~10~25 ~23~12~25 minecraft:concrete 3
fill ~23~4~25 ~23~6~25 minecraft:stained_hardened_clay 6
setblock ~7~3~26 minecraft:spruce_trapdoor
fill ~8~2~26 ~24~2~26 minecraft:grass
fill ~8~3~26 ~24~3~26 minecraft:spruce_trapdoor
fill ~1~2~27 ~4~2~27 minecraft:concrete 7
setblock ~5~2~27 minecraft:border_block
fill ~6~2~27 ~26~2~27 minecraft:border_block
setblock ~27~2~27 minecraft:border_block
fill ~1~2~28 ~3~2~28 minecraft:concrete 7
setblock ~4~2~28 minecraft:border_block
setblock ~5~2~28 minecraft:border_block
setblock ~0~2~29 minecraft:border_block