setblock ~17 ~25 ~12 chest 3  
setblock ~18 ~25 ~12 chest 3  
setblock ~19 ~23 ~12 furnace 5  
setblock ~12 ~24 ~13 furnace 5  
setblock ~17 ~25 ~14 chest 2  
setblock ~18 ~25 ~14 chest 2  
setblock ~19 ~23 ~14 furnace 5  
setblock ~21 ~25 ~12 chest 3  
setblock ~22 ~25 ~12 chest 3  
setblock ~24 ~25 ~12 chest 3  
setblock ~25 ~25 ~12 chest 3  
setblock ~32 ~23 ~12 furnace 4  
setblock ~32 ~24 ~12 furnace 3  
setblock ~21 ~25 ~14 chest 2  
setblock ~22 ~25 ~14 chest 2  
setblock ~24 ~25 ~14 chest 2  
setblock ~25 ~25 ~14 chest 2  
setblock ~32 ~23 ~14 furnace 4  
setblock ~32 ~24 ~14 furnace 3  
setblock ~69 ~29 ~5 furnace 3  
setblock ~69 ~29 ~21 furnace 2  
setblock ~74 ~34 ~13 furnace 4  
setblock ~98 ~37 ~13 hopper 0  
setblock ~103 ~39 ~13 hopper 0  
setblock ~105 ~39 ~13 hopper 5  
setblock ~128 ~22 ~5 furnace 2  
setblock ~128 ~22 ~6 hopper 2  
setblock ~128 ~24 ~6 furnace 2  
setblock ~128 ~24 ~7 hopper 2  
setblock ~130 ~22 ~5 furnace 2  
setblock ~130 ~22 ~6 hopper 2  
setblock ~130 ~24 ~6 furnace 2  
setblock ~130 ~24 ~7 hopper 2  
setblock ~128 ~24 ~19 hopper 3  
setblock ~128 ~22 ~20 hopper 3  
setblock ~128 ~24 ~20 furnace 3  
setblock ~128 ~22 ~21 furnace 3  
setblock ~130 ~24 ~19 hopper 3  
setblock ~130 ~22 ~20 hopper 3  
setblock ~130 ~24 ~20 furnace 3  
setblock ~130 ~22 ~21 furnace 3  
setblock ~148 ~36 ~3 furnace 3  
setblock ~148 ~36 ~23 furnace 2  
setblock ~170 ~21 ~13 double_wooden_slab 5  
setblock ~173 ~29 ~13 furnace 4  
setblock ~203 ~22 ~13 double_wooden_slab 0  
setblock ~205 ~25 ~13 furnace 5  
fill ~6 ~-4 ~13 ~8 ~-4 ~13 stained_hardened_clay 14  
fill ~20 ~-4 ~13 ~190 ~-4 ~13 stained_hardened_clay 14  
fill ~31 ~-4 ~12 ~45 ~-4 ~12 stained_hardened_clay 14  
fill ~31 ~-4 ~14 ~45 ~-4 ~14 stained_hardened_clay 14  
fill ~44 ~-4 ~11 ~183 ~-4 ~11 stained_hardened_clay 14  
fill ~44 ~-4 ~15 ~183 ~-4 ~15 stained_hardened_clay 14  
fill ~183 ~-4 ~12 ~190 ~-4 ~12 stained_hardened_clay 14  
fill ~183 ~-4 ~14 ~190 ~-4 ~14 stained_hardened_clay 14  
fill ~6 ~-3 ~13 ~9 ~-3 ~13 stained_hardened_clay 14  
fill ~7 ~-3 ~12 ~7 ~3 ~12 stained_hardened_clay 14  
fill ~7 ~-3 ~14 ~7 ~3 ~14 stained_hardened_clay 14  
fill ~19 ~-3 ~13 ~42 ~-3 ~13 stained_hardened_clay 14  
fill ~28 ~-3 ~12 ~43 ~-3 ~12 stained_hardened_clay 14  
fill ~28 ~-3 ~14 ~43 ~-3 ~14 stained_hardened_clay 14  
fill ~32 ~-3 ~11 ~45 ~-3 ~11 stained_hardened_clay 14  
fill ~32 ~-3 ~15 ~45 ~-3 ~15 stained_hardened_clay 14  
fill ~46 ~-3 ~10 ~183 ~-3 ~10 stained_hardened_clay 14  
fill ~46 ~-3 ~16 ~183 ~-3 ~16 stained_hardened_clay 14  
fill ~183 ~-3 ~11 ~190 ~-3 ~11 stained_hardened_clay 14  
fill ~183 ~-3 ~15 ~190 ~-3 ~15 stained_hardened_clay 14  
fill ~190 ~-3 ~12 ~191 ~-3 ~12 stained_hardened_clay 14  
fill ~190 ~-3 ~13 ~191 ~-3 ~13 stained_hardened_clay 14  
fill ~190 ~-3 ~14 ~191 ~-3 ~14 stained_hardened_clay 14  
fill ~6 ~-2 ~13 ~9 ~-2 ~13 stained_hardened_clay 14  
fill ~8 ~-2 ~12 ~8 ~2 ~12 stained_hardened_clay 14  
fill ~8 ~-2 ~14 ~8 ~2 ~14 stained_hardened_clay 14  
fill ~18 ~-2 ~13 ~42 ~-2 ~13 stained_hardened_clay 14  
fill ~27 ~-2 ~12 ~43 ~-2 ~12 stained_hardened_clay 14  
fill ~27 ~-2 ~14 ~43 ~-2 ~14 stained_hardened_clay 14  
fill ~27 ~-2 ~15 ~28 ~-2 ~15 stained_hardened_clay 14  
fill ~30 ~-2 ~11 ~43 ~-2 ~11 stained_hardened_clay 14  
fill ~30 ~-2 ~15 ~43 ~-2 ~15 stained_hardened_clay 14  
fill ~39 ~-2 ~10 ~52 ~-2 ~10 stained_hardened_clay 14  
fill ~39 ~-2 ~16 ~52 ~-2 ~16 stained_hardened_clay 14  
fill ~52 ~-2 ~9 ~185 ~-2 ~9 stained_hardened_clay 14  
fill ~52 ~-2 ~17 ~185 ~-2 ~17 stained_hardened_clay 14  
fill ~176 ~-2 ~10 ~188 ~-2 ~10 stained_hardened_clay 14  
fill ~176 ~-2 ~16 ~188 ~-2 ~16 stained_hardened_clay 14  
fill ~188 ~-2 ~11 ~190 ~-2 ~11 stained_hardened_clay 14  
fill ~188 ~-2 ~15 ~190 ~-2 ~15 stained_hardened_clay 14  
fill ~191 ~-2 ~12 ~191 ~-1 ~12 stained_hardened_clay 14  
fill ~191 ~-2 ~13 ~192 ~-2 ~13 stained_hardened_clay 14  
fill ~191 ~-2 ~14 ~191 ~-1 ~14 stained_hardened_clay 14  
fill ~6 ~-1 ~13 ~10 ~-1 ~13 stained_hardened_clay 14 
setblock ~13 ~-1 ~14 gold_block 0 
setblock ~13 ~-1 ~15 iron_bars 0 
setblock ~13 ~-1 ~16 gold_block 0  
fill ~16 ~-1 ~15 ~18 ~-1 ~15 iron_bars 0  
fill ~18 ~-1 ~13 ~42 ~-1 ~13 stained_hardened_clay 14  
fill ~24 ~-1 ~15 ~25 ~-1 ~15 cobblestone_wall 0  
fill ~26 ~-1 ~12 ~43 ~-1 ~12 stained_hardened_clay 14  
fill ~26 ~-1 ~14 ~43 ~-1 ~14 stained_hardened_clay 14  
fill ~26 ~-1 ~15 ~45 ~-1 ~15 stained_hardened_clay 14  
fill ~27 ~-1 ~16 ~28 ~-1 ~16 stained_hardened_clay 14  
fill ~29 ~-1 ~11 ~45 ~-1 ~11 stained_hardened_clay 14  
fill ~36 ~-1 ~10 ~183 ~-1 ~10 stained_hardened_clay 14  
fill ~36 ~-1 ~16 ~183 ~-1 ~16 stained_hardened_clay 14  
fill ~45 ~-1 ~9 ~174 ~-1 ~9 stained_hardened_clay 14  
fill ~45 ~-1 ~17 ~174 ~-1 ~17 stained_hardened_clay 14  
fill ~183 ~-1 ~11 ~190 ~-1 ~11 stained_hardened_clay 14  
fill ~183 ~-1 ~15 ~190 ~-1 ~15 stained_hardened_clay 14  
fill ~191 ~-1 ~13 ~191 ~0 ~13 stained_hardened_clay 14  
fill ~6 ~0 ~13 ~10 ~0 ~13 stained_hardened_clay 14  
fill ~9 ~0 ~12 ~9 ~2 ~12 stained_hardened_clay 14  
fill ~9 ~0 ~14 ~9 ~2 ~14 stained_hardened_clay 14 
setblock ~13 ~0 ~14 iron_bars 0 
setblock ~13 ~0 ~15 gold_block 0 
setblock ~13 ~0 ~16 iron_bars 0 
setblock ~14 ~0 ~15 cobblestone_wall 0  
fill ~15 ~0 ~15 ~25 ~0 ~15 stained_hardened_clay 14  
fill ~16 ~0 ~14 ~18 ~0 ~14 iron_bars 0  
fill ~16 ~0 ~16 ~18 ~0 ~16 iron_bars 0  
fill ~17 ~0 ~13 ~41 ~0 ~13 stained_hardened_clay 14  
fill ~24 ~0 ~14 ~25 ~0 ~14 cobblestone_wall 0  
fill ~24 ~0 ~16 ~25 ~0 ~16 cobblestone_wall 0  
fill ~26 ~0 ~12 ~43 ~0 ~12 stained_hardened_clay 14  
fill ~26 ~0 ~15 ~27 ~0 ~15 wool 14  
fill ~26 ~0 ~16 ~29 ~0 ~16 stained_hardened_clay 14  
fill ~27 ~0 ~14 ~43 ~0 ~14 stained_hardened_clay 14  
fill ~28 ~0 ~15 ~43 ~0 ~15 stained_hardened_clay 14  
fill ~29 ~0 ~11 ~43 ~0 ~11 stained_hardened_clay 14  
fill ~35 ~0 ~10 ~53 ~0 ~10 stained_hardened_clay 14  
fill ~35 ~0 ~16 ~53 ~0 ~16 stained_hardened_clay 14  
fill ~39 ~0 ~9 ~172 ~0 ~9 stained_hardened_clay 14  
fill ~39 ~0 ~17 ~172 ~0 ~17 stained_hardened_clay 14  
fill ~147 ~0 ~10 ~175 ~0 ~10 stained_hardened_clay 14  
fill ~147 ~0 ~16 ~175 ~0 ~16 stained_hardened_clay 14  
fill ~163 ~0 ~11 ~183 ~0 ~11 stained_hardened_clay 14  
fill ~163 ~0 ~15 ~183 ~0 ~15 stained_hardened_clay 14  
fill ~182 ~0 ~12 ~190 ~0 ~12 stained_hardened_clay 14  
fill ~182 ~0 ~14 ~190 ~0 ~14 stained_hardened_clay 14  
fill ~188 ~0 ~13 ~188 ~2 ~13 stained_hardened_clay 14  
fill ~6 ~1 ~13 ~11 ~1 ~13 stained_hardened_clay 14 
setblock ~13 ~1 ~14 gold_block 0 
setblock ~13 ~1 ~15 iron_bars 0 
setblock ~13 ~1 ~16 gold_block 0  
fill ~16 ~1 ~13 ~26 ~1 ~13 stained_hardened_clay 14  
fill ~16 ~1 ~15 ~18 ~1 ~15 iron_bars 0  
fill ~24 ~1 ~15 ~25 ~1 ~15 cobblestone_wall 0  
fill ~25 ~1 ~12 ~42 ~1 ~12 stained_hardened_clay 14  
fill ~25 ~1 ~14 ~42 ~1 ~14 stained_hardened_clay 14  
fill ~26 ~1 ~15 ~42 ~1 ~15 stained_hardened_clay 14  
fill ~27 ~1 ~16 ~28 ~1 ~16 stained_hardened_clay 14  
fill ~28 ~1 ~11 ~42 ~1 ~11 stained_hardened_clay 14  
fill ~28 ~1 ~13 ~38 ~1 ~13 stained_hardened_clay 14  
fill ~34 ~1 ~10 ~48 ~1 ~10 stained_hardened_clay 14  
fill ~34 ~1 ~16 ~48 ~1 ~16 stained_hardened_clay 14  
fill ~38 ~1 ~9 ~171 ~1 ~9 stained_hardened_clay 14  
fill ~38 ~1 ~17 ~171 ~1 ~17 stained_hardened_clay 14  
fill ~165 ~1 ~12 ~185 ~1 ~12 stained_hardened_clay 14  
fill ~165 ~1 ~14 ~185 ~1 ~14 stained_hardened_clay 14  
fill ~169 ~1 ~10 ~173 ~1 ~10 stained_hardened_clay 14  
fill ~169 ~1 ~11 ~172 ~1 ~11 stained_hardened_clay 14  
fill ~169 ~1 ~15 ~172 ~1 ~15 stained_hardened_clay 14  
fill ~169 ~1 ~16 ~173 ~1 ~16 stained_hardened_clay 14  
fill ~174 ~1 ~11 ~177 ~1 ~11 stained_hardened_clay 14  
fill ~174 ~1 ~15 ~177 ~1 ~15 stained_hardened_clay 14  
fill ~186 ~1 ~13 ~190 ~1 ~13 stained_hardened_clay 14  
fill ~6 ~2 ~13 ~11 ~2 ~13 stained_hardened_clay 14  
fill ~14 ~2 ~13 ~36 ~2 ~13 stained_hardened_clay 14  
fill ~23 ~2 ~12 ~39 ~2 ~12 stained_hardened_clay 14  
fill ~23 ~2 ~14 ~39 ~2 ~14 stained_hardened_clay 14  
fill ~27 ~2 ~11 ~40 ~2 ~11 stained_hardened_clay 14  
fill ~27 ~2 ~15 ~40 ~2 ~15 stained_hardened_clay 14  
fill ~32 ~2 ~10 ~44 ~2 ~10 stained_hardened_clay 14  
fill ~32 ~2 ~16 ~44 ~2 ~16 stained_hardened_clay 14  
fill ~36 ~2 ~9 ~48 ~2 ~9 stained_hardened_clay 14  
fill ~36 ~2 ~17 ~48 ~2 ~17 stained_hardened_clay 14  
fill ~40 ~2 ~8 ~164 ~2 ~8 stained_hardened_clay 14  
fill ~40 ~2 ~18 ~164 ~2 ~18 stained_hardened_clay 14  
fill ~165 ~2 ~9 ~170 ~2 ~9 stained_hardened_clay 14  
fill ~165 ~2 ~17 ~170 ~2 ~17 stained_hardened_clay 14  
fill ~169 ~2 ~10 ~172 ~2 ~10 stained_hardened_clay 14  
fill ~169 ~2 ~11 ~170 ~2 ~11 stained_hardened_clay 14  
fill ~169 ~2 ~12 ~183 ~2 ~12 stained_hardened_clay 14  
fill ~169 ~2 ~14 ~183 ~2 ~14 stained_hardened_clay 14  
fill ~169 ~2 ~15 ~170 ~2 ~15 stained_hardened_clay 14  
fill ~169 ~2 ~16 ~172 ~2 ~16 stained_hardened_clay 14  
fill ~173 ~2 ~11 ~175 ~2 ~11 stained_hardened_clay 14  
fill ~173 ~2 ~15 ~175 ~2 ~15 stained_hardened_clay 14  
fill ~183 ~2 ~13 ~188 ~2 ~13 stained_hardened_clay 14  
fill ~6 ~3 ~13 ~9 ~3 ~13 stained_hardened_clay 14  
fill ~10 ~3 ~13 ~11 ~3 ~13 anvil 3  
fill ~12 ~3 ~13 ~27 ~3 ~13 stained_hardened_clay 14  
fill ~20 ~3 ~12 ~37 ~3 ~12 stained_hardened_clay 14  
fill ~20 ~3 ~14 ~37 ~3 ~14 stained_hardened_clay 14  
fill ~26 ~3 ~11 ~38 ~3 ~11 stained_hardened_clay 14  
fill ~26 ~3 ~15 ~38 ~3 ~15 stained_hardened_clay 14  
fill ~30 ~3 ~10 ~41 ~3 ~10 stained_hardened_clay 14  
fill ~30 ~3 ~16 ~41 ~3 ~16 stained_hardened_clay 14  
fill ~34 ~3 ~9 ~44 ~3 ~9 stained_hardened_clay 14  
fill ~34 ~3 ~17 ~44 ~3 ~17 stained_hardened_clay 14  
fill ~37 ~3 ~8 ~48 ~3 ~8 stained_hardened_clay 14  
fill ~37 ~3 ~18 ~48 ~3 ~18 stained_hardened_clay 14  
fill ~43 ~3 ~7 ~157 ~3 ~7 stained_hardened_clay 14  
fill ~43 ~3 ~19 ~157 ~3 ~19 stained_hardened_clay 14  
fill ~158 ~3 ~8 ~166 ~3 ~8 stained_hardened_clay 14  
fill ~158 ~3 ~18 ~166 ~3 ~18 stained_hardened_clay 14  
fill ~167 ~3 ~9 ~169 ~3 ~9 stained_hardened_clay 14  
fill ~167 ~3 ~17 ~169 ~3 ~17 stained_hardened_clay 14  
fill ~169 ~3 ~12 ~182 ~3 ~12 stained_hardened_clay 14  
fill ~169 ~3 ~14 ~182 ~3 ~14 stained_hardened_clay 14  
fill ~170 ~3 ~10 ~170 ~5 ~10 stained_hardened_clay 14  
fill ~170 ~3 ~16 ~170 ~5 ~16 stained_hardened_clay 14  
fill ~171 ~3 ~11 ~173 ~3 ~11 stained_hardened_clay 14  
fill ~171 ~3 ~15 ~173 ~3 ~15 stained_hardened_clay 14  
fill ~178 ~3 ~13 ~186 ~3 ~13 stained_hardened_clay 14  
fill ~6 ~4 ~13 ~7 ~4 ~13 stained_hardened_clay 14  
fill ~8 ~4 ~13 ~9 ~4 ~13 anvil 3 
setblock ~10 ~4 ~13 cobblestone_wall 0  
fill ~11 ~4 ~13 ~21 ~4 ~13 stained_hardened_clay 14  
fill ~13 ~4 ~12 ~28 ~4 ~12 stained_hardened_clay 14  
fill ~13 ~4 ~14 ~28 ~4 ~14 stained_hardened_clay 14  
fill ~23 ~4 ~11 ~38 ~4 ~11 stained_hardened_clay 14  
fill ~23 ~4 ~15 ~38 ~4 ~15 stained_hardened_clay 14  
fill ~27 ~4 ~10 ~41 ~4 ~10 stained_hardened_clay 14  
fill ~27 ~4 ~16 ~41 ~4 ~16 stained_hardened_clay 14  
fill ~32 ~4 ~9 ~41 ~4 ~9 stained_hardened_clay 14  
fill ~32 ~4 ~17 ~41 ~4 ~17 stained_hardened_clay 14  
fill ~35 ~4 ~8 ~45 ~4 ~8 stained_hardened_clay 14  
fill ~35 ~4 ~18 ~45 ~4 ~18 stained_hardened_clay 14  
fill ~41 ~4 ~7 ~162 ~4 ~7 stained_hardened_clay 14  
fill ~41 ~4 ~19 ~162 ~4 ~19 stained_hardened_clay 14  
fill ~163 ~4 ~8 ~166 ~4 ~8 stained_hardened_clay 14  
fill ~163 ~4 ~18 ~166 ~4 ~18 stained_hardened_clay 14  
fill ~167 ~4 ~9 ~169 ~4 ~9 stained_hardened_clay 14  
fill ~167 ~4 ~17 ~169 ~4 ~17 stained_hardened_clay 14  
fill ~169 ~4 ~11 ~173 ~4 ~11 stained_hardened_clay 14  
fill ~169 ~4 ~12 ~180 ~4 ~12 stained_hardened_clay 14  
fill ~169 ~4 ~14 ~180 ~4 ~14 stained_hardened_clay 14  
fill ~169 ~4 ~15 ~173 ~4 ~15 stained_hardened_clay 14  
fill ~179 ~4 ~13 ~185 ~4 ~13 stained_hardened_clay 14  
fill ~6 ~5 ~13 ~7 ~5 ~13 cobblestone_wall 0  
fill ~8 ~5 ~12 ~21 ~5 ~12 stained_hardened_clay 14  
fill ~8 ~5 ~13 ~16 ~5 ~13 stained_hardened_clay 14  
fill ~8 ~5 ~14 ~21 ~5 ~14 stained_hardened_clay 14  
fill ~16 ~5 ~11 ~30 ~5 ~11 stained_hardened_clay 14  
fill ~16 ~5 ~15 ~30 ~5 ~15 stained_hardened_clay 14  
fill ~24 ~5 ~10 ~40 ~5 ~10 stained_hardened_clay 14  
fill ~24 ~5 ~16 ~40 ~5 ~16 stained_hardened_clay 14  
fill ~28 ~5 ~12 ~29 ~5 ~12 stained_hardened_clay 14  
fill ~28 ~5 ~14 ~29 ~5 ~14 stained_hardened_clay 14  
fill ~29 ~5 ~9 ~40 ~5 ~9 stained_hardened_clay 14  
fill ~29 ~5 ~17 ~40 ~5 ~17 stained_hardened_clay 14  
fill ~33 ~5 ~8 ~44 ~5 ~8 stained_hardened_clay 14  
fill ~33 ~5 ~18 ~44 ~5 ~18 stained_hardened_clay 14  
fill ~40 ~5 ~7 ~164 ~5 ~7 stained_hardened_clay 14  
fill ~40 ~5 ~19 ~164 ~5 ~19 stained_hardened_clay 14  
fill ~165 ~5 ~8 ~167 ~5 ~8 stained_hardened_clay 14  
fill ~165 ~5 ~18 ~167 ~5 ~18 stained_hardened_clay 14  
fill ~167 ~5 ~9 ~169 ~5 ~9 stained_hardened_clay 14  
fill ~167 ~5 ~17 ~169 ~5 ~17 stained_hardened_clay 14  
fill ~170 ~5 ~11 ~174 ~5 ~11 stained_hardened_clay 14  
fill ~170 ~5 ~15 ~174 ~5 ~15 stained_hardened_clay 14  
fill ~171 ~5 ~10 ~171 ~6 ~10 stained_hardened_clay 14  
fill ~171 ~5 ~16 ~171 ~6 ~16 stained_hardened_clay 14  
fill ~175 ~5 ~12 ~181 ~5 ~12 stained_hardened_clay 14  
fill ~175 ~5 ~14 ~181 ~5 ~14 stained_hardened_clay 14  
fill ~181 ~5 ~13 ~185 ~5 ~13 stained_hardened_clay 14  
fill ~6 ~6 ~13 ~6 ~5 ~13 cobblestone_wall 0  
fill ~7 ~6 ~12 ~8 ~6 ~12 stained_hardened_clay 14  
fill ~7 ~6 ~13 ~8 ~6 ~13 stained_hardened_clay 14  
fill ~7 ~6 ~14 ~8 ~6 ~14 stained_hardened_clay 14  
fill ~8 ~6 ~11 ~15 ~6 ~11 stained_hardened_clay 14  
fill ~8 ~6 ~15 ~15 ~6 ~15 stained_hardened_clay 14  
fill ~11 ~6 ~13 ~14 ~6 ~13 stained_hardened_clay 14  
fill ~14 ~6 ~10 ~30 ~6 ~10 stained_hardened_clay 14  
fill ~14 ~6 ~16 ~30 ~6 ~16 stained_hardened_clay 14  
fill ~25 ~6 ~9 ~43 ~6 ~9 stained_hardened_clay 14  
fill ~25 ~6 ~17 ~43 ~6 ~17 stained_hardened_clay 14  
fill ~31 ~6 ~8 ~44 ~6 ~8 stained_hardened_clay 14  
fill ~31 ~6 ~18 ~44 ~6 ~18 stained_hardened_clay 14  
fill ~38 ~6 ~7 ~164 ~6 ~7 stained_hardened_clay 14  
fill ~38 ~6 ~19 ~164 ~6 ~19 stained_hardened_clay 14  
fill ~164 ~6 ~8 ~167 ~6 ~8 stained_hardened_clay 14  
fill ~164 ~6 ~18 ~167 ~6 ~18 stained_hardened_clay 14  
fill ~168 ~6 ~9 ~170 ~6 ~9 stained_hardened_clay 14  
fill ~168 ~6 ~17 ~170 ~6 ~17 stained_hardened_clay 14  
fill ~171 ~6 ~11 ~175 ~6 ~11 stained_hardened_clay 14  
fill ~171 ~6 ~15 ~175 ~6 ~15 stained_hardened_clay 14  
fill ~172 ~6 ~10 ~172 ~7 ~10 stained_hardened_clay 14  
fill ~172 ~6 ~16 ~172 ~7 ~16 stained_hardened_clay 14  
fill ~176 ~6 ~12 ~182 ~6 ~12 stained_hardened_clay 14  
fill ~176 ~6 ~14 ~182 ~6 ~14 stained_hardened_clay 14  
fill ~181 ~6 ~13 ~186 ~6 ~13 stained_hardened_clay 14  
fill ~6 ~7 ~11 ~7 ~7 ~11 stained_hardened_clay 14  
fill ~6 ~7 ~12 ~6 ~7 ~15 stained_hardened_clay 14  
fill ~7 ~7 ~13 ~10 ~7 ~13 stained_hardened_clay 14 
setblock ~7 ~7 ~15 stained_hardened_clay 14  
fill ~8 ~7 ~10 ~15 ~7 ~10 stained_hardened_clay 14  
fill ~8 ~7 ~16 ~15 ~7 ~16 stained_hardened_clay 14  
fill ~15 ~7 ~9 ~30 ~7 ~9 stained_hardened_clay 14  
fill ~15 ~7 ~17 ~30 ~7 ~17 stained_hardened_clay 14  
fill ~29 ~7 ~8 ~44 ~7 ~8 stained_hardened_clay 14  
fill ~29 ~7 ~18 ~44 ~7 ~18 stained_hardened_clay 14  
fill ~33 ~7 ~7 ~165 ~7 ~7 stained_hardened_clay 14  
fill ~33 ~7 ~19 ~165 ~7 ~19 stained_hardened_clay 14  
fill ~165 ~7 ~8 ~169 ~7 ~8 stained_hardened_clay 14  
fill ~165 ~7 ~18 ~169 ~7 ~18 stained_hardened_clay 14  
fill ~170 ~7 ~9 ~171 ~7 ~9 stained_hardened_clay 14  
fill ~170 ~7 ~17 ~171 ~7 ~17 stained_hardened_clay 14  
fill ~172 ~7 ~11 ~177 ~7 ~11 stained_hardened_clay 14  
fill ~172 ~7 ~15 ~177 ~7 ~15 stained_hardened_clay 14  
fill ~173 ~7 ~10 ~173 ~8 ~10 stained_hardened_clay 14  
fill ~173 ~7 ~16 ~173 ~8 ~16 stained_hardened_clay 14  
fill ~178 ~7 ~12 ~184 ~7 ~12 stained_hardened_clay 14  
fill ~178 ~7 ~14 ~184 ~7 ~14 stained_hardened_clay 14  
fill ~181 ~7 ~13 ~187 ~7 ~13 stained_hardened_clay 14  
fill ~5 ~8 ~11 ~5 ~8 ~15 stained_hardened_clay 14  
fill ~6 ~8 ~10 ~7 ~8 ~10 stained_hardened_clay 14  
fill ~6 ~8 ~16 ~7 ~8 ~16 stained_hardened_clay 14  
fill ~8 ~8 ~9 ~15 ~8 ~9 stained_hardened_clay 14  
fill ~8 ~8 ~17 ~15 ~8 ~17 stained_hardened_clay 14  
fill ~16 ~8 ~8 ~30 ~8 ~8 stained_hardened_clay 14  
fill ~16 ~8 ~18 ~30 ~8 ~18 stained_hardened_clay 14  
fill ~30 ~8 ~7 ~167 ~8 ~7 stained_hardened_clay 14  
fill ~30 ~8 ~19 ~167 ~8 ~19 stained_hardened_clay 14  
fill ~168 ~8 ~8 ~170 ~8 ~8 stained_hardened_clay 14  
fill ~168 ~8 ~18 ~170 ~8 ~18 stained_hardened_clay 14  
fill ~170 ~8 ~9 ~172 ~8 ~9 stained_hardened_clay 14  
fill ~170 ~8 ~17 ~172 ~8 ~17 stained_hardened_clay 14  
fill ~174 ~8 ~10 ~175 ~8 ~10 stained_hardened_clay 14  
fill ~174 ~8 ~16 ~175 ~8 ~16 stained_hardened_clay 14  
fill ~176 ~8 ~11 ~179 ~8 ~11 stained_hardened_clay 14  
fill ~176 ~8 ~15 ~179 ~8 ~15 stained_hardened_clay 14  
fill ~179 ~8 ~12 ~186 ~8 ~12 stained_hardened_clay 14  
fill ~179 ~8 ~14 ~186 ~8 ~14 stained_hardened_clay 14  
fill ~183 ~8 ~13 ~188 ~8 ~13 stained_hardened_clay 14  
fill ~4 ~9 ~11 ~4 ~14 ~11 stone 0  
fill ~4 ~9 ~12 ~4 ~12 ~12 stone 0  
fill ~4 ~9 ~13 ~4 ~12 ~13 stone 0  
fill ~4 ~9 ~14 ~4 ~12 ~14 stone 0  
fill ~4 ~9 ~15 ~4 ~14 ~15 stone 0  
fill ~5 ~9 ~9 ~7 ~9 ~9 stone 0  
fill ~5 ~9 ~10 ~5 ~9 ~9 stone 0  
fill ~5 ~9 ~16 ~5 ~9 ~17 stone 0  
fill ~6 ~9 ~17 ~7 ~9 ~17 stone 0  
fill ~8 ~9 ~8 ~15 ~9 ~8 stone 0  
fill ~8 ~9 ~18 ~15 ~9 ~18 stone 0  
fill ~16 ~9 ~7 ~30 ~9 ~7 stone 0  
fill ~16 ~9 ~19 ~30 ~9 ~19 stone 0  
fill ~31 ~9 ~6 ~167 ~9 ~6 stone 0  
fill ~31 ~9 ~20 ~167 ~9 ~20 stone 0  
fill ~168 ~9 ~7 ~169 ~9 ~7 stone 0  
fill ~168 ~9 ~19 ~169 ~9 ~19 stone 0  
fill ~170 ~9 ~8 ~172 ~9 ~8 stone 0  
fill ~170 ~9 ~18 ~172 ~9 ~18 stone 0  
fill ~173 ~9 ~9 ~175 ~9 ~9 stone 0  
fill ~173 ~9 ~17 ~175 ~9 ~17 stone 0  
fill ~176 ~9 ~10 ~179 ~9 ~10 stone 0  
fill ~176 ~9 ~16 ~179 ~9 ~16 stone 0  
fill ~180 ~9 ~11 ~183 ~9 ~11 stone 0  
fill ~180 ~9 ~15 ~183 ~9 ~15 stone 0  
fill ~183 ~9 ~12 ~188 ~9 ~12 stone 0  
fill ~183 ~9 ~14 ~188 ~9 ~14 stone 0  
fill ~189 ~9 ~13 ~189 ~10 ~13 stone 0  
fill ~4 ~10 ~10 ~4 ~14 ~10 stone 0  
fill ~4 ~10 ~16 ~4 ~14 ~16 stone 0  
fill ~5 ~10 ~9 ~6 ~10 ~9 stone 0  
fill ~5 ~10 ~17 ~6 ~10 ~17 stone 0  
fill ~7 ~10 ~8 ~14 ~10 ~8 stone 0  
fill ~7 ~10 ~18 ~14 ~10 ~18 stone 0  
fill ~15 ~10 ~7 ~29 ~10 ~7 stone 0  
fill ~15 ~10 ~19 ~29 ~10 ~19 stone 0  
fill ~30 ~10 ~6 ~156 ~10 ~6 stone 0  
fill ~30 ~10 ~20 ~168 ~10 ~20 stone 0  
fill ~157 ~10 ~6 ~157 ~12 ~6 quartz_block 0  
fill ~158 ~10 ~6 ~161 ~10 ~6 stone 0  
fill ~162 ~10 ~6 ~164 ~10 ~6 quartz_block 0  
fill ~165 ~10 ~6 ~168 ~10 ~6 stone 0  
fill ~169 ~10 ~7 ~170 ~10 ~7 stone 0  
fill ~169 ~10 ~19 ~170 ~10 ~19 stone 0  
fill ~171 ~10 ~8 ~173 ~10 ~8 stone 0  
fill ~171 ~10 ~18 ~173 ~10 ~18 stone 0  
fill ~174 ~10 ~9 ~176 ~10 ~9 stone 0  
fill ~174 ~10 ~17 ~176 ~10 ~17 stone 0  
fill ~177 ~10 ~10 ~180 ~10 ~10 stone 0  
fill ~177 ~10 ~16 ~180 ~10 ~16 stone 0  
fill ~181 ~10 ~11 ~185 ~10 ~11 stone 0  
fill ~181 ~10 ~15 ~185 ~10 ~15 stone 0  
fill ~184 ~10 ~12 ~189 ~10 ~12 stone 0  
fill ~184 ~10 ~14 ~189 ~10 ~14 stone 0 
setblock ~190 ~10 ~13 stone 0  
fill ~5 ~11 ~8 ~12 ~11 ~8 stone 0  
fill ~5 ~11 ~9 ~5 ~13 ~9 stone 0  
fill ~5 ~11 ~17 ~5 ~13 ~17 stone 0  
fill ~5 ~11 ~18 ~12 ~11 ~18 stone 0  
fill ~13 ~11 ~7 ~27 ~11 ~7 stone 0  
fill ~13 ~11 ~19 ~27 ~11 ~19 stone 0  
fill ~28 ~11 ~6 ~156 ~11 ~6 stone 0  
fill ~28 ~11 ~20 ~170 ~11 ~20 stone 0  
fill ~158 ~11 ~6 ~160 ~11 ~6 stone 0  
fill ~161 ~11 ~6 ~161 ~12 ~6 quartz_block 0  
fill ~162 ~11 ~6 ~170 ~11 ~6 stone 0  
fill ~171 ~11 ~7 ~172 ~11 ~7 stone 0  
fill ~171 ~11 ~19 ~172 ~11 ~19 stone 0  
fill ~173 ~11 ~8 ~175 ~11 ~8 stone 0  
fill ~173 ~11 ~18 ~175 ~11 ~18 stone 0  
fill ~176 ~11 ~9 ~178 ~11 ~9 stone 0  
fill ~176 ~11 ~17 ~178 ~11 ~17 stone 0  
fill ~179 ~11 ~10 ~182 ~11 ~10 stone 0  
fill ~179 ~11 ~16 ~182 ~11 ~16 stone 0  
fill ~183 ~11 ~11 ~187 ~11 ~11 stone 0  
fill ~183 ~11 ~15 ~187 ~11 ~15 stone 0  
fill ~185 ~11 ~12 ~190 ~11 ~12 stone 0  
fill ~185 ~11 ~14 ~190 ~11 ~14 stone 0  
fill ~191 ~11 ~13 ~191 ~12 ~13 stone 0  
fill ~3 ~12 ~13 ~3 ~15 ~13 stone 0  
fill ~4 ~12 ~9 ~4 ~15 ~9 stone 0  
fill ~4 ~12 ~17 ~4 ~15 ~17 stone 0  
fill ~5 ~12 ~8 ~12 ~12 ~8 stone 0  
fill ~5 ~12 ~18 ~12 ~12 ~18 stone 0  
fill ~11 ~12 ~7 ~27 ~12 ~7 stone 0  
fill ~11 ~12 ~19 ~27 ~12 ~19 stone 0  
fill ~25 ~12 ~6 ~156 ~12 ~6 stone 0  
fill ~25 ~12 ~20 ~171 ~12 ~20 stone 0  
fill ~158 ~12 ~6 ~160 ~12 ~6 stone 0  
fill ~162 ~12 ~6 ~171 ~12 ~6 stone 0  
fill ~171 ~12 ~7 ~173 ~12 ~7 stone 0  
fill ~171 ~12 ~19 ~173 ~12 ~19 stone 0  
fill ~173 ~12 ~8 ~176 ~12 ~8 stone 0  
fill ~173 ~12 ~18 ~176 ~12 ~18 stone 0  
fill ~176 ~12 ~9 ~179 ~12 ~9 stone 0  
fill ~176 ~12 ~17 ~179 ~12 ~17 stone 0  
fill ~179 ~12 ~10 ~185 ~12 ~10 stone 0  
fill ~179 ~12 ~16 ~185 ~12 ~16 stone 0  
fill ~183 ~12 ~11 ~189 ~12 ~11 stone 0  
fill ~183 ~12 ~15 ~189 ~12 ~15 stone 0  
fill ~185 ~12 ~12 ~191 ~12 ~12 stone 0  
fill ~185 ~12 ~14 ~191 ~12 ~14 stone 0  
fill ~192 ~12 ~13 ~193 ~12 ~13 stone 0  
fill ~3 ~13 ~11 ~3 ~15 ~11 stone 0  
fill ~3 ~13 ~12 ~3 ~15 ~12 stone 0  
fill ~3 ~13 ~14 ~3 ~15 ~14 stone 0  
fill ~3 ~13 ~15 ~3 ~15 ~15 stone 0  
fill ~4 ~13 ~8 ~6 ~13 ~8 stone 0  
fill ~4 ~13 ~18 ~6 ~13 ~18 stone 0 
setblock ~6 ~13 ~9 stone 0 
setblock ~6 ~13 ~17 stone 0  
fill ~7 ~13 ~7 ~15 ~13 ~7 stone 0  
fill ~7 ~13 ~19 ~15 ~13 ~19 stone 0  
fill ~16 ~13 ~6 ~29 ~13 ~6 stone 0  
fill ~16 ~13 ~20 ~29 ~13 ~20 stone 0  
fill ~30 ~13 ~5 ~156 ~13 ~5 stone 0  
fill ~30 ~13 ~21 ~170 ~13 ~21 stone 0  
fill ~157 ~13 ~5 ~157 ~15 ~5 quartz_block 0  
fill ~158 ~13 ~5 ~160 ~13 ~5 stone 0  
fill ~161 ~13 ~5 ~163 ~13 ~5 quartz_block 0  
fill ~164 ~13 ~5 ~170 ~13 ~5 stone 0  
fill ~171 ~13 ~6 ~172 ~13 ~6 stone 0  
fill ~171 ~13 ~20 ~172 ~13 ~20 stone 0  
fill ~173 ~13 ~7 ~175 ~13 ~7 stone 0  
fill ~173 ~13 ~19 ~175 ~13 ~19 stone 0  
fill ~176 ~13 ~8 ~178 ~13 ~8 stone 0  
fill ~176 ~13 ~18 ~178 ~13 ~18 stone 0  
fill ~179 ~13 ~9 ~182 ~13 ~9 stone 0  
fill ~179 ~13 ~17 ~182 ~13 ~17 stone 0  
fill ~183 ~13 ~10 ~187 ~13 ~10 stone 0  
fill ~183 ~13 ~16 ~187 ~13 ~16 stone 0  
fill ~185 ~13 ~11 ~190 ~13 ~11 stone 0  
fill ~185 ~13 ~15 ~190 ~13 ~15 stone 0  
fill ~191 ~13 ~12 ~193 ~13 ~12 stone 0  
fill ~191 ~13 ~14 ~193 ~13 ~14 stone 0  
fill ~192 ~13 ~13 ~194 ~13 ~13 stone 0  
fill ~3 ~14 ~10 ~3 ~15 ~10 stone 0  
fill ~3 ~14 ~16 ~3 ~15 ~16 stone 0  
fill ~4 ~14 ~8 ~4 ~15 ~8 stone 0  
fill ~4 ~14 ~18 ~4 ~15 ~18 stone 0  
fill ~5 ~14 ~7 ~12 ~14 ~7 stone 0  
fill ~5 ~14 ~19 ~12 ~14 ~19 stone 0  
fill ~13 ~14 ~6 ~27 ~14 ~6 stone 0  
fill ~13 ~14 ~20 ~27 ~14 ~20 stone 0  
fill ~28 ~14 ~5 ~156 ~14 ~5 stone 0  
fill ~28 ~14 ~21 ~172 ~14 ~21 stone 0  
fill ~158 ~14 ~5 ~158 ~13 ~5 stone 0 
setblock ~159 ~14 ~5 quartz_block 0  
fill ~160 ~14 ~5 ~160 ~15 ~5 stone 0  
fill ~161 ~14 ~5 ~161 ~15 ~5 quartz_block 0  
fill ~162 ~14 ~5 ~163 ~14 ~5 stone 0  
fill ~164 ~14 ~5 ~164 ~15 ~5 quartz_block 0  
fill ~165 ~14 ~5 ~172 ~14 ~5 stone 0  
fill ~173 ~14 ~6 ~175 ~14 ~6 stone 0  
fill ~173 ~14 ~20 ~175 ~14 ~20 stone 0  
fill ~176 ~14 ~7 ~178 ~14 ~7 stone 0  
fill ~176 ~14 ~19 ~178 ~14 ~19 stone 0  
fill ~179 ~14 ~8 ~182 ~14 ~8 stone 0  
fill ~179 ~14 ~18 ~182 ~14 ~18 stone 0  
fill ~183 ~14 ~9 ~185 ~14 ~9 stone 0  
fill ~183 ~14 ~17 ~185 ~14 ~17 stone 0  
fill ~185 ~14 ~10 ~190 ~14 ~10 stone 0  
fill ~185 ~14 ~16 ~190 ~14 ~16 stone 0  
fill ~190 ~14 ~11 ~193 ~14 ~11 stone 0  
fill ~190 ~14 ~15 ~193 ~14 ~15 stone 0 
setblock ~194 ~14 ~12 stone 0 
setblock ~194 ~14 ~14 stone 0  
fill ~195 ~14 ~13 ~196 ~14 ~13 stone 0  
fill ~3 ~15 ~9 ~3 ~17 ~9 stone 0  
fill ~3 ~15 ~17 ~3 ~17 ~17 stone 0  
fill ~4 ~15 ~7 ~12 ~15 ~7 stone 0  
fill ~4 ~15 ~19 ~12 ~15 ~19 stone 0  
fill ~11 ~15 ~6 ~27 ~15 ~6 stone 0  
fill ~11 ~15 ~20 ~27 ~15 ~20 stone 0  
fill ~26 ~15 ~5 ~156 ~15 ~5 stone 0  
fill ~26 ~15 ~21 ~175 ~15 ~21 stone 0 
setblock ~158 ~15 ~5 quartz_block 0 
setblock ~159 ~15 ~5 stone 0  
fill ~162 ~15 ~5 ~163 ~15 ~5 stone 0  
fill ~165 ~15 ~5 ~175 ~15 ~5 stone 0  
fill ~176 ~15 ~6 ~178 ~15 ~6 stone 0  
fill ~176 ~15 ~20 ~178 ~15 ~20 stone 0  
fill ~179 ~15 ~7 ~182 ~15 ~7 stone 0  
fill ~179 ~15 ~19 ~182 ~15 ~19 stone 0  
fill ~183 ~15 ~8 ~184 ~15 ~8 stone 0  
fill ~183 ~15 ~18 ~184 ~15 ~18 stone 0  
fill ~185 ~15 ~9 ~191 ~15 ~9 stone 0  
fill ~185 ~15 ~17 ~191 ~15 ~17 stone 0  
fill ~190 ~15 ~10 ~193 ~15 ~10 stone 0  
fill ~190 ~15 ~16 ~193 ~15 ~16 stone 0 
setblock ~194 ~15 ~11 stone 0 
setblock ~194 ~15 ~15 stone 0  
fill ~195 ~15 ~12 ~196 ~15 ~12 stone 0  
fill ~195 ~15 ~14 ~196 ~15 ~14 stone 0 
setblock ~197 ~15 ~13 stone 0  
fill ~2 ~16 ~10 ~2 ~17 ~10 stone 0  
fill ~2 ~16 ~11 ~2 ~17 ~11 stone 0  
fill ~2 ~16 ~12 ~2 ~17 ~12 stone 0  
fill ~2 ~16 ~13 ~2 ~17 ~13 stone 0  
fill ~2 ~16 ~14 ~2 ~17 ~14 stone 0  
fill ~2 ~16 ~15 ~2 ~17 ~15 stone 0  
fill ~2 ~16 ~16 ~2 ~17 ~16 stone 0  
fill ~3 ~16 ~7 ~3 ~17 ~7 stone 0  
fill ~3 ~16 ~8 ~3 ~17 ~8 stone 0  
fill ~3 ~16 ~18 ~3 ~17 ~18 stone 0  
fill ~3 ~16 ~19 ~3 ~17 ~19 stone 0  
fill ~4 ~16 ~6 ~12 ~16 ~6 stone 0  
fill ~4 ~16 ~20 ~12 ~16 ~20 stone 0  
fill ~13 ~16 ~5 ~32 ~16 ~5 stone 0  
fill ~13 ~16 ~21 ~32 ~16 ~21 stone 0  
fill ~33 ~16 ~4 ~156 ~16 ~4 stone 0  
fill ~33 ~16 ~22 ~175 ~16 ~22 stone 0 
setblock ~157 ~16 ~4 quartz_block 0  
fill ~158 ~16 ~4 ~161 ~16 ~4 stone 0  
fill ~162 ~16 ~4 ~163 ~16 ~4 quartz_block 0  
fill ~164 ~16 ~4 ~175 ~16 ~4 stone 0  
fill ~176 ~16 ~5 ~178 ~16 ~5 stone 0  
fill ~176 ~16 ~21 ~178 ~16 ~21 stone 0  
fill ~179 ~16 ~6 ~182 ~16 ~6 stone 0  
fill ~179 ~16 ~20 ~182 ~16 ~20 stone 0  
fill ~183 ~16 ~7 ~185 ~16 ~7 stone 0  
fill ~183 ~16 ~19 ~185 ~16 ~19 stone 0  
fill ~185 ~16 ~8 ~190 ~16 ~8 stone 0  
fill ~185 ~16 ~18 ~190 ~16 ~18 stone 0  
fill ~190 ~16 ~9 ~193 ~16 ~9 stone 0  
fill ~190 ~16 ~17 ~193 ~16 ~17 stone 0  
fill ~193 ~16 ~10 ~194 ~16 ~10 stone 0  
fill ~193 ~16 ~16 ~194 ~16 ~16 stone 0  
fill ~195 ~16 ~11 ~196 ~16 ~11 stone 0  
fill ~195 ~16 ~15 ~196 ~16 ~15 stone 0 
setblock ~197 ~16 ~12 stone 0 
setblock ~197 ~16 ~14 stone 0  
fill ~198 ~16 ~13 ~199 ~16 ~13 stone 0  
fill ~4 ~17 ~6 ~12 ~17 ~6 stone 0  
fill ~4 ~17 ~20 ~12 ~17 ~20 stone 0  
fill ~13 ~17 ~5 ~29 ~17 ~5 stone 0  
fill ~13 ~17 ~21 ~29 ~17 ~21 stone 0  
fill ~30 ~17 ~4 ~178 ~17 ~4 stone 0  
fill ~30 ~17 ~22 ~178 ~17 ~22 stone 0  
fill ~179 ~17 ~5 ~182 ~17 ~5 stone 0  
fill ~179 ~17 ~21 ~182 ~17 ~21 stone 0  
fill ~183 ~17 ~6 ~186 ~17 ~6 stone 0  
fill ~183 ~17 ~20 ~186 ~17 ~20 stone 0  
fill ~185 ~17 ~7 ~191 ~17 ~7 stone 0  
fill ~185 ~17 ~19 ~191 ~17 ~19 stone 0  
fill ~190 ~17 ~8 ~193 ~17 ~8 stone 0  
fill ~190 ~17 ~18 ~193 ~17 ~18 stone 0 
setblock ~194 ~17 ~9 stone 0 
setblock ~194 ~17 ~17 stone 0  
fill ~195 ~17 ~10 ~196 ~17 ~10 stone 0  
fill ~195 ~17 ~16 ~196 ~17 ~16 stone 0 
setblock ~197 ~17 ~11 stone 0 
setblock ~197 ~17 ~15 stone 0  
fill ~198 ~17 ~12 ~199 ~17 ~12 stone 0  
fill ~198 ~17 ~14 ~199 ~17 ~14 stone 0  
fill ~199 ~17 ~13 ~200 ~17 ~13 stone 0  
fill ~1 ~18 ~10 ~1 ~18 ~16 stone 6  
fill ~2 ~18 ~7 ~2 ~18 ~9 stone 6  
fill ~2 ~18 ~17 ~2 ~18 ~19 stone 6 
setblock ~3 ~18 ~6 stone 6 
setblock ~3 ~18 ~20 stone 6  
fill ~4 ~18 ~5 ~12 ~18 ~5 stone 6  
fill ~4 ~18 ~21 ~12 ~18 ~21 stone 6  
fill ~5 ~18 ~6 ~12 ~18 ~6 stone 0  
fill ~5 ~18 ~20 ~12 ~18 ~20 stone 0  
fill ~13 ~18 ~4 ~27 ~18 ~4 stone 6  
fill ~13 ~18 ~5 ~27 ~18 ~5 stone 0  
fill ~13 ~18 ~21 ~27 ~18 ~21 stone 0  
fill ~13 ~18 ~22 ~27 ~18 ~22 stone 6  
fill ~28 ~18 ~3 ~137 ~18 ~3 stone 6  
fill ~28 ~18 ~4 ~181 ~18 ~4 stone 0  
fill ~28 ~18 ~22 ~181 ~18 ~22 stone 0  
fill ~28 ~18 ~23 ~137 ~18 ~23 stone 6  
fill ~182 ~18 ~5 ~184 ~18 ~5 stone 0  
fill ~182 ~18 ~21 ~184 ~18 ~21 stone 0  
fill ~185 ~18 ~6 ~190 ~18 ~6 stone 0  
fill ~185 ~18 ~20 ~190 ~18 ~20 stone 0  
fill ~190 ~18 ~7 ~193 ~18 ~7 stone 0  
fill ~190 ~18 ~19 ~193 ~18 ~19 stone 0  
fill ~194 ~18 ~8 ~194 ~20 ~8 stone 0  
fill ~194 ~18 ~18 ~194 ~20 ~18 stone 0  
fill ~195 ~18 ~9 ~196 ~18 ~9 stone 0  
fill ~195 ~18 ~17 ~196 ~18 ~17 stone 0 
setblock ~197 ~18 ~10 stone 0 
setblock ~197 ~18 ~16 stone 0  
fill ~198 ~18 ~11 ~199 ~18 ~11 stone 0  
fill ~198 ~18 ~15 ~199 ~18 ~15 stone 0  
fill ~199 ~18 ~12 ~200 ~18 ~12 stone 0  
fill ~199 ~18 ~14 ~200 ~18 ~14 stone 0  
fill ~201 ~18 ~13 ~202 ~18 ~13 stone 0  
fill ~1 ~19 ~10 ~1 ~19 ~16 stone_brick_stairs 4  
fill ~2 ~19 ~7 ~2 ~19 ~9 stone_brick_stairs 4  
fill ~2 ~19 ~17 ~2 ~19 ~19 stone_brick_stairs 4 
setblock ~3 ~19 ~6 stone_brick_stairs 4 
setblock ~3 ~19 ~20 stone_brick_stairs 4  
fill ~4 ~19 ~5 ~11 ~19 ~5 stone_brick_stairs 6  
fill ~4 ~19 ~21 ~11 ~19 ~21 stone_brick_stairs 7 
setblock ~12 ~19 ~5 stone_brick_stairs 4 
setblock ~12 ~19 ~21 stone_brick_stairs 4  
fill ~13 ~19 ~4 ~26 ~19 ~4 stone_brick_stairs 6  
fill ~13 ~19 ~22 ~26 ~19 ~22 stone_brick_stairs 7 
setblock ~27 ~19 ~4 stone_brick_stairs 4 
setblock ~27 ~19 ~22 stone_brick_stairs 4  
fill ~28 ~19 ~3 ~104 ~19 ~3 stone_brick_stairs 6  
fill ~28 ~19 ~23 ~104 ~19 ~23 stone_brick_stairs 7  
fill ~88 ~19 ~4 ~142 ~19 ~4 stained_hardened_clay 9  
fill ~88 ~19 ~5 ~142 ~19 ~5 stained_hardened_clay 9  
fill ~88 ~19 ~6 ~142 ~19 ~6 stained_hardened_clay 9  
fill ~88 ~19 ~7 ~142 ~19 ~7 stained_hardened_clay 9  
fill ~88 ~19 ~8 ~142 ~19 ~8 stained_hardened_clay 9  
fill ~88 ~19 ~9 ~142 ~19 ~9 stained_hardened_clay 9  
fill ~88 ~19 ~10 ~142 ~19 ~10 stained_hardened_clay 9  
fill ~88 ~19 ~11 ~142 ~19 ~11 stained_hardened_clay 9  
fill ~88 ~19 ~12 ~142 ~19 ~12 stained_hardened_clay 9  
fill ~88 ~19 ~13 ~123 ~19 ~13 stained_hardened_clay 9  
fill ~88 ~19 ~14 ~142 ~19 ~14 stained_hardened_clay 9  
fill ~88 ~19 ~15 ~142 ~19 ~15 stained_hardened_clay 9  
fill ~88 ~19 ~16 ~142 ~19 ~16 stained_hardened_clay 9  
fill ~88 ~19 ~17 ~142 ~19 ~17 stained_hardened_clay 9  
fill ~88 ~19 ~18 ~142 ~19 ~18 stained_hardened_clay 9  
fill ~88 ~19 ~19 ~142 ~19 ~19 stained_hardened_clay 9  
fill ~88 ~19 ~20 ~142 ~19 ~20 stained_hardened_clay 9  
fill ~88 ~19 ~21 ~142 ~19 ~21 stained_hardened_clay 9  
fill ~88 ~19 ~22 ~142 ~19 ~22 stained_hardened_clay 9 
setblock ~105 ~19 ~3 stone_slab 8 
setblock ~105 ~19 ~23 stone_slab 8  
fill ~106 ~19 ~3 ~108 ~19 ~3 stone 6  
fill ~106 ~19 ~23 ~108 ~19 ~23 stone 6  
fill ~109 ~19 ~3 ~137 ~19 ~3 stone_brick_stairs 6  
fill ~109 ~19 ~23 ~137 ~19 ~23 stone_brick_stairs 7  
fill ~125 ~19 ~13 ~142 ~19 ~13 stained_hardened_clay 9  
fill ~138 ~19 ~3 ~168 ~19 ~3 stone 6  
fill ~138 ~19 ~23 ~168 ~19 ~23 stone 6  
fill ~169 ~19 ~3 ~175 ~19 ~3 stone 0  
fill ~169 ~19 ~23 ~175 ~19 ~23 stone 0  
fill ~172 ~19 ~13 ~172 ~20 ~13 stone_stairs 1  
fill ~176 ~19 ~4 ~182 ~19 ~4 stone 0  
fill ~176 ~19 ~22 ~182 ~19 ~22 stone 0  
fill ~182 ~19 ~5 ~187 ~19 ~5 stone 0  
fill ~182 ~19 ~21 ~187 ~19 ~21 stone 0  
fill ~188 ~19 ~6 ~191 ~19 ~6 stone 0  
fill ~188 ~19 ~20 ~191 ~19 ~20 stone 0  
fill ~191 ~19 ~7 ~194 ~19 ~7 stone 0  
fill ~191 ~19 ~19 ~194 ~19 ~19 stone 0  
fill ~195 ~19 ~8 ~196 ~19 ~8 stone 0  
fill ~195 ~19 ~18 ~196 ~19 ~18 stone 0 
setblock ~197 ~19 ~9 stone 0 
setblock ~197 ~19 ~17 stone 0  
fill ~198 ~19 ~10 ~199 ~19 ~10 stone 0  
fill ~198 ~19 ~16 ~199 ~19 ~16 stone 0  
fill ~199 ~19 ~11 ~200 ~19 ~11 stone 0  
fill ~199 ~19 ~15 ~200 ~19 ~15 stone 0  
fill ~201 ~19 ~12 ~202 ~19 ~12 stone 0  
fill ~201 ~19 ~14 ~202 ~19 ~14 stone 0  
fill ~203 ~19 ~13 ~203 ~20 ~13 stone 0  
fill ~1 ~20 ~10 ~1 ~20 ~16 stone_slab 0  
fill ~2 ~20 ~7 ~2 ~20 ~9 stone_slab 0  
fill ~2 ~20 ~10 ~2 ~20 ~16 stone 0  
fill ~2 ~20 ~17 ~2 ~20 ~19 stone_slab 0 
setblock ~3 ~20 ~6 stone_slab 0  
fill ~3 ~20 ~7 ~3 ~20 ~9 stone 0  
fill ~3 ~20 ~10 ~3 ~20 ~16 stained_hardened_clay 9  
fill ~3 ~20 ~17 ~3 ~20 ~19 stone 0 
setblock ~3 ~20 ~20 stone_slab 0  
fill ~4 ~20 ~5 ~12 ~20 ~5 stone_slab 0  
fill ~4 ~20 ~6 ~12 ~20 ~6 stone 0  
fill ~4 ~20 ~7 ~14 ~20 ~7 stained_hardened_clay 9  
fill ~4 ~20 ~8 ~4 ~20 ~9 stained_hardened_clay 9  
fill ~4 ~20 ~10 ~4 ~20 ~16 quartz_block 0   
fill ~4 ~20 ~17 ~12 ~20 ~17 stained_hardened_clay 9  
fill ~4 ~20 ~18 ~4 ~20 ~19 stained_hardened_clay 9  
fill ~4 ~20 ~20 ~12 ~20 ~20 stone 0  
fill ~4 ~20 ~21 ~12 ~20 ~21 stone_slab 0  
fill ~5 ~20 ~8 ~13 ~20 ~8 quartz_block 0  
fill ~5 ~20 ~9 ~12 ~20 ~9 stained_hardened_clay 9  
fill ~5 ~20 ~10 ~12 ~20 ~10 stained_hardened_clay 9  
fill ~5 ~20 ~11 ~12 ~20 ~11 stained_hardened_clay 9  
fill ~5 ~20 ~12 ~12 ~20 ~12 stained_hardened_clay 9  
fill ~5 ~20 ~13 ~13 ~20 ~13 quartz_block 0  
fill ~5 ~20 ~14 ~12 ~20 ~14 stained_hardened_clay 9  
fill ~5 ~20 ~15 ~12 ~20 ~15 stained_hardened_clay 9  
fill ~5 ~20 ~16 ~12 ~20 ~16 stained_hardened_clay 9  
fill ~5 ~20 ~18 ~13 ~20 ~18 quartz_block 0  
fill ~5 ~20 ~19 ~14 ~20 ~19 stained_hardened_clay 9  
fill ~13 ~20 ~4 ~27 ~20 ~4 stone_slab 0  
fill ~13 ~20 ~5 ~27 ~20 ~5 stone 0  
fill ~13 ~20 ~6 ~26 ~20 ~6 stained_hardened_clay 9  
fill ~13 ~20 ~9 ~13 ~20 ~18 quartz_block 0  
fill ~13 ~20 ~20 ~26 ~20 ~20 stained_hardened_clay 9  
fill ~13 ~20 ~21 ~27 ~20 ~21 stone 0  
fill ~13 ~20 ~22 ~27 ~20 ~22 stone_slab 0  
fill ~14 ~20 ~8 ~25 ~20 ~8 stained_hardened_clay 9  
fill ~14 ~20 ~9 ~25 ~20 ~9 stained_hardened_clay 9  
fill ~14 ~20 ~10 ~25 ~20 ~10 stained_hardened_clay 9  
fill ~14 ~20 ~11 ~25 ~20 ~11 stained_hardened_clay 9  
fill ~14 ~20 ~12 ~25 ~20 ~12 stained_hardened_clay 9  
fill ~14 ~20 ~13 ~25 ~20 ~13 stained_hardened_clay 9  
fill ~14 ~20 ~14 ~25 ~20 ~14 stained_hardened_clay 9  
fill ~14 ~20 ~15 ~25 ~20 ~15 stained_hardened_clay 9  
fill ~14 ~20 ~16 ~25 ~20 ~16 stained_hardened_clay 9  
fill ~14 ~20 ~17 ~25 ~20 ~17 stained_hardened_clay 9  
fill ~14 ~20 ~18 ~25 ~20 ~18 stained_hardened_clay 9  
fill ~15 ~20 ~7 ~27 ~20 ~7 quartz_block 0  
fill ~15 ~20 ~19 ~27 ~20 ~19 quartz_block 0  
fill ~26 ~20 ~8 ~26 ~20 ~19 quartz_block 0  
fill ~27 ~20 ~6 ~39 ~20 ~6 quartz_block 0  
fill ~27 ~20 ~8 ~30 ~20 ~8 stained_hardened_clay 9  
fill ~27 ~20 ~9 ~30 ~20 ~9 stained_hardened_clay 9  
fill ~27 ~20 ~10 ~40 ~20 ~10 quartz_block 0  
fill ~27 ~20 ~11 ~40 ~20 ~11 stained_hardened_clay 9  
fill ~27 ~20 ~12 ~40 ~20 ~12 stained_hardened_clay 9  
fill ~27 ~20 ~13 ~40 ~20 ~13 stained_hardened_clay 9  
fill ~27 ~20 ~14 ~40 ~20 ~14 stained_hardened_clay 9  
fill ~27 ~20 ~15 ~40 ~20 ~15 stained_hardened_clay 9  
fill ~27 ~20 ~16 ~40 ~20 ~16 quartz_block 0  
fill ~27 ~20 ~17 ~30 ~20 ~17 stained_hardened_clay 9  
fill ~27 ~20 ~18 ~30 ~20 ~18 stained_hardened_clay 9  
fill ~27 ~20 ~20 ~39 ~20 ~20 quartz_block 0  
fill ~28 ~20 ~3 ~104 ~20 ~3 stone_slab 0  
fill ~28 ~20 ~4 ~104 ~20 ~4 stone 0  
fill ~28 ~20 ~5 ~41 ~20 ~5 stained_hardened_clay 9  
fill ~28 ~20 ~7 ~30 ~20 ~7 stained_hardened_clay 9  
fill ~28 ~20 ~19 ~30 ~20 ~19 stained_hardened_clay 9  
fill ~28 ~20 ~21 ~41 ~20 ~21 stained_hardened_clay 9  
fill ~28 ~20 ~22 ~104 ~20 ~22 stone 0  
fill ~28 ~20 ~23 ~104 ~20 ~23 stone_slab 0  
fill ~31 ~20 ~7 ~31 ~20 ~10 quartz_block 0  
fill ~31 ~20 ~17 ~31 ~20 ~20 quartz_block 0  
fill ~32 ~20 ~7 ~36 ~20 ~7 stained_hardened_clay 9  
fill ~32 ~20 ~8 ~36 ~20 ~8 stained_hardened_clay 9  
fill ~32 ~20 ~9 ~36 ~20 ~9 stained_hardened_clay 9  
fill ~32 ~20 ~17 ~36 ~20 ~17 stained_hardened_clay 9  
fill ~32 ~20 ~18 ~36 ~20 ~18 stained_hardened_clay 9  
fill ~32 ~20 ~19 ~36 ~20 ~19 stained_hardened_clay 9  
fill ~37 ~20 ~7 ~37 ~20 ~10 quartz_block 0  
fill ~37 ~20 ~17 ~37 ~20 ~20 quartz_block 0  
fill ~38 ~20 ~7 ~40 ~20 ~7 stained_hardened_clay 9  
fill ~38 ~20 ~8 ~40 ~20 ~8 stained_hardened_clay 9  
fill ~38 ~20 ~9 ~40 ~20 ~9 stained_hardened_clay 9  
fill ~38 ~20 ~17 ~40 ~20 ~17 stained_hardened_clay 9  
fill ~38 ~20 ~18 ~40 ~20 ~18 stained_hardened_clay 9  
fill ~38 ~20 ~19 ~40 ~20 ~19 stained_hardened_clay 9 
setblock ~40 ~20 ~6 stained_hardened_clay 9 
setblock ~40 ~20 ~20 stained_hardened_clay 9  
fill ~41 ~20 ~6 ~41 ~20 ~20 iron_block 0  
fill ~54 ~20 ~5 ~56 ~20 ~5 stone 0  
fill ~54 ~20 ~21 ~56 ~20 ~21 stone 0  
fill ~73 ~20 ~5 ~74 ~20 ~5 stone 0  
fill ~73 ~20 ~21 ~74 ~20 ~21 stone 0  
fill ~88 ~20 ~5 ~137 ~20 ~5 stained_hardened_clay 9  
fill ~88 ~20 ~6 ~137 ~20 ~6 stained_hardened_clay 9  
fill ~88 ~20 ~7 ~137 ~20 ~7 stained_hardened_clay 9  
fill ~88 ~20 ~8 ~137 ~20 ~8 stained_hardened_clay 9  
fill ~88 ~20 ~9 ~137 ~20 ~9 stained_hardened_clay 9  
fill ~88 ~20 ~10 ~137 ~20 ~10 stained_hardened_clay 9  
fill ~88 ~20 ~11 ~137 ~20 ~11 stained_hardened_clay 9  
fill ~88 ~20 ~12 ~137 ~20 ~12 stained_hardened_clay 9  
fill ~88 ~20 ~13 ~123 ~20 ~13 stained_hardened_clay 9  
fill ~88 ~20 ~14 ~137 ~20 ~14 stained_hardened_clay 9  
fill ~88 ~20 ~15 ~137 ~20 ~15 stained_hardened_clay 9  
fill ~88 ~20 ~16 ~137 ~20 ~16 stained_hardened_clay 9  
fill ~88 ~20 ~17 ~137 ~20 ~17 stained_hardened_clay 9  
fill ~88 ~20 ~18 ~137 ~20 ~18 stained_hardened_clay 9  
fill ~88 ~20 ~19 ~137 ~20 ~19 stained_hardened_clay 9  
fill ~88 ~20 ~20 ~137 ~20 ~20 stained_hardened_clay 9  
fill ~88 ~20 ~21 ~137 ~20 ~21 stained_hardened_clay 9  
fill ~105 ~20 ~3 ~108 ~20 ~3 stone_slab 13  
fill ~105 ~20 ~4 ~142 ~20 ~4 stained_hardened_clay 9  
fill ~105 ~20 ~22 ~142 ~20 ~22 stained_hardened_clay 9  
fill ~105 ~20 ~23 ~108 ~20 ~23 stone_slab 13  
fill ~109 ~20 ~2 ~136 ~20 ~2 stone_slab 13  
fill ~109 ~20 ~3 ~136 ~20 ~3 stone_slab 0  
fill ~109 ~20 ~23 ~136 ~20 ~23 stone_slab 0  
fill ~109 ~20 ~24 ~136 ~20 ~24 stone_slab 13  
fill ~125 ~20 ~13 ~137 ~20 ~13 stained_hardened_clay 9  
fill ~137 ~20 ~3 ~168 ~20 ~3 stone_brick_stairs 6  
fill ~137 ~20 ~23 ~168 ~20 ~23 stone_brick_stairs 7  
fill ~165 ~20 ~4 ~175 ~20 ~4 stained_hardened_clay 9  
fill ~165 ~20 ~22 ~175 ~20 ~22 stained_hardened_clay 9  
fill ~166 ~20 ~5 ~181 ~20 ~5 stained_hardened_clay 9  
fill ~166 ~20 ~21 ~181 ~20 ~21 stained_hardened_clay 9  
fill ~167 ~20 ~6 ~181 ~20 ~6 stained_hardened_clay 9  
fill ~167 ~20 ~20 ~181 ~20 ~20 stained_hardened_clay 9  
fill ~168 ~20 ~2 ~170 ~20 ~2 stone_slab 13  
fill ~168 ~20 ~7 ~181 ~20 ~7 stained_hardened_clay 9  
fill ~168 ~20 ~19 ~181 ~20 ~19 stained_hardened_clay 9  
fill ~168 ~20 ~24 ~170 ~20 ~24 stone_slab 13  
fill ~169 ~20 ~3 ~171 ~20 ~3 stone 6  
fill ~169 ~20 ~8 ~181 ~20 ~8 stained_hardened_clay 9  
fill ~169 ~20 ~9 ~181 ~20 ~9 stained_hardened_clay 9  
fill ~169 ~20 ~10 ~181 ~20 ~10 stained_hardened_clay 9  
fill ~169 ~20 ~11 ~181 ~20 ~11 stained_hardened_clay 9  
fill ~169 ~20 ~12 ~181 ~20 ~12 stained_hardened_clay 9  
fill ~169 ~20 ~13 ~175 ~20 ~13 stone_stairs 1  
fill ~169 ~20 ~14 ~181 ~20 ~14 stained_hardened_clay 9  
fill ~169 ~20 ~15 ~181 ~20 ~15 stained_hardened_clay 9  
fill ~169 ~20 ~16 ~181 ~20 ~16 stained_hardened_clay 9  
fill ~169 ~20 ~17 ~181 ~20 ~17 stained_hardened_clay 9  
fill ~169 ~20 ~18 ~181 ~20 ~18 stained_hardened_clay 9  
fill ~169 ~20 ~23 ~171 ~20 ~23 stone 6  
fill ~173 ~20 ~3 ~175 ~20 ~3 stone 6  
fill ~173 ~20 ~23 ~175 ~20 ~23 stone 6  
fill ~176 ~20 ~4 ~181 ~20 ~4 stone 6  
fill ~176 ~20 ~13 ~181 ~20 ~13 stained_hardened_clay 9  
fill ~176 ~20 ~22 ~181 ~20 ~22 stone 6  
fill ~182 ~20 ~4 ~184 ~20 ~4 stone 0  
fill ~182 ~20 ~5 ~189 ~20 ~5 stone 0  
fill ~182 ~20 ~21 ~189 ~20 ~21 stone 0  
fill ~182 ~20 ~22 ~184 ~20 ~22 stone 0  
fill ~188 ~20 ~6 ~193 ~20 ~6 stone 0  
fill ~188 ~20 ~20 ~193 ~20 ~20 stone 0  
fill ~191 ~20 ~7 ~196 ~20 ~7 stone 0  
fill ~191 ~20 ~19 ~196 ~20 ~19 stone 0  
fill ~196 ~20 ~8 ~197 ~20 ~8 stone 0  
fill ~196 ~20 ~18 ~197 ~20 ~18 stone 0  
fill ~198 ~20 ~9 ~199 ~20 ~9 stone 0  
fill ~198 ~20 ~17 ~199 ~20 ~17 stone 0  
fill ~199 ~20 ~10 ~200 ~20 ~10 stone 0  
fill ~199 ~20 ~11 ~200 ~20 ~11 stained_hardened_clay 9  
fill ~199 ~20 ~15 ~200 ~20 ~15 stained_hardened_clay 9  
fill ~199 ~20 ~16 ~200 ~20 ~16 stone 0  
fill ~201 ~20 ~11 ~202 ~20 ~11 stone 0  
fill ~201 ~20 ~15 ~202 ~20 ~15 stone 0  
fill ~203 ~20 ~12 ~204 ~20 ~12 stone 0  
fill ~203 ~20 ~14 ~204 ~20 ~14 stone 0  
fill ~204 ~20 ~13 ~205 ~20 ~13 stone 0  
fill ~2 ~21 ~10 ~2 ~21 ~16 stone_slab 13  
fill ~3 ~21 ~8 ~3 ~21 ~9 stone_slab 13 
setblock ~3 ~21 ~10 anvil 0 
setblock ~3 ~21 ~11 stone_brick_stairs 4 
setblock ~3 ~21 ~12 anvil 0 
setblock ~3 ~21 ~13 stone_brick_stairs 4 
setblock ~3 ~21 ~14 anvil 0 
setblock ~3 ~21 ~15 stone_brick_stairs 4 
setblock ~3 ~21 ~16 anvil 0  
fill ~3 ~21 ~17 ~3 ~21 ~18 stone_slab 13 
setblock ~4 ~21 ~7 stone_slab 13 
setblock ~4 ~21 ~8 anvil 0 
setblock ~4 ~21 ~9 stone_brick_stairs 4 
setblock ~4 ~21 ~11 stone_brick_stairs 1 
setblock ~4 ~21 ~13 stone_brick_stairs 1 
setblock ~4 ~21 ~15 stone_brick_stairs 1 
setblock ~4 ~21 ~17 stone_brick_stairs 4 
setblock ~4 ~21 ~18 anvil 0 
setblock ~4 ~21 ~19 stone_slab 13  
fill ~5 ~21 ~6 ~13 ~21 ~6 stone_slab 13 
setblock ~5 ~21 ~7 anvil 1 
setblock ~5 ~21 ~9 stone_brick_stairs 1 
setblock ~5 ~21 ~17 stone_brick_stairs 1 
setblock ~5 ~21 ~19 anvil 1  
fill ~5 ~21 ~20 ~13 ~21 ~20 stone_slab 13 
setblock ~6 ~21 ~7 stone_brick_stairs 6 
setblock ~6 ~21 ~8 stone_brick_stairs 3 
setblock ~6 ~21 ~18 stone_brick_stairs 2 
setblock ~6 ~21 ~19 stone_brick_stairs 7 
setblock ~7 ~21 ~7 anvil 1 
setblock ~7 ~21 ~19 anvil 1 
setblock ~8 ~21 ~7 stone_brick_stairs 6 
setblock ~8 ~21 ~8 stone_brick_stairs 3 
setblock ~8 ~21 ~18 stone_brick_stairs 2 
setblock ~8 ~21 ~19 stone_brick_stairs 7 
setblock ~9 ~21 ~7 anvil 1 
setblock ~9 ~21 ~19 anvil 1 
setblock ~10 ~21 ~7 stone_brick_stairs 6 
setblock ~10 ~21 ~8 stone_brick_stairs 3 
setblock ~10 ~21 ~18 stone_brick_stairs 2 
setblock ~10 ~21 ~19 stone_brick_stairs 7 
setblock ~11 ~21 ~7 anvil 1 
setblock ~11 ~21 ~19 anvil 1 
setblock ~12 ~21 ~7 stone_brick_stairs 6 
setblock ~12 ~21 ~8 stone_brick_stairs 3 
setblock ~12 ~21 ~18 stone_brick_stairs 2 
setblock ~12 ~21 ~19 stone_brick_stairs 7 
setblock ~13 ~21 ~7 anvil 1 
setblock ~13 ~21 ~19 anvil 1  
fill ~14 ~21 ~5 ~27 ~21 ~5 stone_slab 13 
setblock ~14 ~21 ~6 stone_brick_stairs 6 
setblock ~14 ~21 ~7 stone_brick_stairs 3 
setblock ~14 ~21 ~19 stone_brick_stairs 2 
setblock ~14 ~21 ~20 stone_brick_stairs 7  
fill ~14 ~21 ~21 ~27 ~21 ~21 stone_slab 13 
setblock ~15 ~21 ~6 anvil 1 
setblock ~15 ~21 ~20 anvil 1 
setblock ~16 ~21 ~6 stone_brick_stairs 6 
setblock ~16 ~21 ~7 stone_brick_stairs 3 
setblock ~16 ~21 ~19 stone_brick_stairs 2 
setblock ~16 ~21 ~20 stone_brick_stairs 7 
setblock ~17 ~21 ~6 anvil 1 
setblock ~17 ~21 ~20 anvil 1 
setblock ~18 ~21 ~6 stone_brick_stairs 6 
setblock ~18 ~21 ~7 stone_brick_stairs 3 
setblock ~18 ~21 ~19 stone_brick_stairs 2 
setblock ~18 ~21 ~20 stone_brick_stairs 7 
setblock ~19 ~21 ~6 anvil 1 
setblock ~19 ~21 ~10 stone_slab 8 
setblock ~19 ~21 ~16 stone_slab 8 
setblock ~19 ~21 ~20 anvil 1 
setblock ~20 ~21 ~6 stone_brick_stairs 6 
setblock ~20 ~21 ~7 stone_brick_stairs 3 
setblock ~20 ~21 ~9 stone_button 4 
setblock ~20 ~21 ~10 coal_block 0 
setblock ~20 ~21 ~11 stone_slab 8 
setblock ~20 ~21 ~15 stone_slab 8 
setblock ~20 ~21 ~16 coal_block 0 
setblock ~20 ~21 ~17 stone_button 3 
setblock ~20 ~21 ~19 stone_brick_stairs 2 
setblock ~20 ~21 ~20 stone_brick_stairs 7 
setblock ~21 ~21 ~6 anvil 1 
setblock ~21 ~21 ~10 stone_slab 8 
setblock ~21 ~21 ~16 stone_slab 8 
setblock ~21 ~21 ~20 anvil 1 
setblock ~22 ~21 ~6 stone_brick_stairs 6 
setblock ~22 ~21 ~7 stone_brick_stairs 3 
setblock ~22 ~21 ~19 stone_brick_stairs 2 
setblock ~22 ~21 ~20 stone_brick_stairs 7 
setblock ~23 ~21 ~6 anvil 1 
setblock ~23 ~21 ~20 anvil 1 
setblock ~24 ~21 ~6 stone_brick_stairs 6 
setblock ~24 ~21 ~7 stone_brick_stairs 3 
setblock ~24 ~21 ~19 stone_brick_stairs 2 
setblock ~24 ~21 ~20 stone_brick_stairs 7 
setblock ~25 ~21 ~6 anvil 1 
setblock ~25 ~21 ~20 anvil 1 
setblock ~26 ~21 ~6 stone_brick_stairs 6 
setblock ~26 ~21 ~7 stone_brick_stairs 3 
setblock ~26 ~21 ~19 stone_brick_stairs 2 
setblock ~26 ~21 ~20 stone_brick_stairs 7 
setblock ~27 ~21 ~6 anvil 1 
setblock ~27 ~21 ~20 anvil 1  
fill ~28 ~21 ~4 ~42 ~21 ~4 stone_slab 13 
setblock ~28 ~21 ~5 stone_brick_stairs 6 
setblock ~28 ~21 ~6 stone_brick_stairs 3 
setblock ~28 ~21 ~20 stone_brick_stairs 2 
setblock ~28 ~21 ~21 stone_brick_stairs 7  
fill ~28 ~21 ~22 ~42 ~21 ~22 stone_slab 13 
setblock ~29 ~21 ~5 anvil 1 
setblock ~29 ~21 ~21 anvil 1 
setblock ~30 ~21 ~5 stone_brick_stairs 6 
setblock ~30 ~21 ~6 stone_brick_stairs 3 
setblock ~30 ~21 ~13 stone_slab 8 
setblock ~30 ~21 ~20 stone_brick_stairs 2 
setblock ~30 ~21 ~21 stone_brick_stairs 7 
setblock ~31 ~21 ~5 anvil 1 
setblock ~31 ~21 ~12 stone_button 4 
setblock ~31 ~21 ~13 coal_block 0 
setblock ~31 ~21 ~14 stone_button 3 
setblock ~31 ~21 ~21 anvil 1 
setblock ~32 ~21 ~5 stone_brick_stairs 6 
setblock ~32 ~21 ~6 stone_brick_stairs 3 
setblock ~32 ~21 ~13 stone_slab 8 
setblock ~32 ~21 ~20 stone_brick_stairs 2 
setblock ~32 ~21 ~21 stone_brick_stairs 7 
setblock ~33 ~21 ~5 anvil 1 
setblock ~33 ~21 ~21 anvil 1 
setblock ~34 ~21 ~5 stone_brick_stairs 6 
setblock ~34 ~21 ~6 stone_brick_stairs 3 
setblock ~34 ~21 ~20 stone_brick_stairs 2 
setblock ~34 ~21 ~21 stone_brick_stairs 7 
setblock ~35 ~21 ~5 anvil 1 
setblock ~35 ~21 ~21 anvil 1 
setblock ~36 ~21 ~5 stone_brick_stairs 6 
setblock ~36 ~21 ~6 stone_brick_stairs 3 
setblock ~36 ~21 ~20 stone_brick_stairs 2 
setblock ~36 ~21 ~21 stone_brick_stairs 7 
setblock ~37 ~21 ~5 anvil 1 
setblock ~37 ~21 ~21 anvil 1 
setblock ~38 ~21 ~5 stone_brick_stairs 6 
setblock ~38 ~21 ~6 stone_brick_stairs 3 
setblock ~38 ~21 ~20 stone_brick_stairs 2 
setblock ~38 ~21 ~21 stone_brick_stairs 7 
setblock ~39 ~21 ~5 anvil 1 
setblock ~39 ~21 ~21 anvil 1 
setblock ~40 ~21 ~5 stone_brick_stairs 6 
setblock ~40 ~21 ~6 stone_brick_stairs 3  
fill ~40 ~21 ~8 ~40 ~22 ~8 cobblestone_wall 0 
setblock ~40 ~21 ~13 tripwire_hook 1  
fill ~40 ~21 ~18 ~40 ~22 ~18 cobblestone_wall 0 
setblock ~40 ~21 ~20 stone_brick_stairs 2 
setblock ~40 ~21 ~21 stone_brick_stairs 7 
setblock ~41 ~21 ~5 anvil 1  
fill ~41 ~21 ~6 ~41 ~24 ~6 stone 0  
fill ~41 ~21 ~7 ~41 ~24 ~7 stone 0  
fill ~41 ~21 ~8 ~41 ~24 ~8 stone 0  
fill ~41 ~21 ~9 ~41 ~22 ~9 quartz_stairs 0  
fill ~41 ~21 ~10 ~41 ~23 ~10 quartz_stairs 0  
fill ~41 ~21 ~11 ~41 ~23 ~11 quartz_stairs 0  
fill ~41 ~21 ~12 ~41 ~23 ~12 quartz_stairs 0 
setblock ~41 ~21 ~13 stone 6  
fill ~41 ~21 ~14 ~41 ~23 ~14 quartz_stairs 0  
fill ~41 ~21 ~15 ~41 ~23 ~15 quartz_stairs 0  
fill ~41 ~21 ~16 ~41 ~23 ~16 quartz_stairs 0  
fill ~41 ~21 ~17 ~41 ~22 ~17 quartz_stairs 0  
fill ~41 ~21 ~18 ~41 ~24 ~18 stone 0  
fill ~41 ~21 ~19 ~41 ~24 ~19 stone 0  
fill ~41 ~21 ~20 ~41 ~24 ~20 stone 0 
setblock ~41 ~21 ~21 anvil 1  
fill ~42 ~21 ~5 ~42 ~24 ~5 stone 0  
fill ~42 ~21 ~21 ~42 ~24 ~21 stone 0  
fill ~43 ~21 ~4 ~48 ~21 ~4 stone 0  
fill ~43 ~21 ~22 ~48 ~21 ~22 stone 0 
setblock ~49 ~21 ~4 stone_brick_stairs 5 
setblock ~49 ~21 ~5 monster_egg 0 
setblock ~49 ~21 ~21 monster_egg 0 
setblock ~49 ~21 ~22 stone_brick_stairs 5  
fill ~50 ~21 ~6 ~50 ~23 ~6 monster_egg 0  
fill ~50 ~21 ~7 ~50 ~23 ~7 monster_egg 0  
fill ~50 ~21 ~8 ~50 ~23 ~8 monster_egg 0  
fill ~50 ~21 ~9 ~50 ~23 ~9 monster_egg 0  
fill ~50 ~21 ~10 ~50 ~23 ~10 monster_egg 0  
fill ~50 ~21 ~16 ~50 ~23 ~16 monster_egg 0  
fill ~50 ~21 ~17 ~50 ~23 ~17 monster_egg 0  
fill ~50 ~21 ~18 ~50 ~23 ~18 monster_egg 0  
fill ~50 ~21 ~19 ~50 ~23 ~19 monster_egg 0  
fill ~50 ~21 ~20 ~50 ~23 ~20 monster_egg 0  
fill ~51 ~21 ~11 ~51 ~23 ~11 monster_egg 0  
fill ~51 ~21 ~15 ~51 ~23 ~15 monster_egg 0 
setblock ~52 ~21 ~6 stone_brick_stairs 2  
fill ~52 ~21 ~7 ~52 ~21 ~8 stone_brick_stairs 0  
fill ~52 ~21 ~18 ~52 ~21 ~19 stone_brick_stairs 0 
setblock ~52 ~21 ~20 stone_brick_stairs 3 
setblock ~53 ~21 ~5 stone_brick_stairs 2 
setblock ~53 ~21 ~9 stone_brick_stairs 3 
setblock ~53 ~21 ~10 stone_brick_stairs 0 
setblock ~53 ~21 ~16 stone_brick_stairs 0 
setblock ~53 ~21 ~17 stone_brick_stairs 2 
setblock ~53 ~21 ~21 stone_brick_stairs 3 
setblock ~54 ~21 ~5 anvil 1  
fill ~54 ~21 ~10 ~55 ~21 ~10 stone_brick_stairs 3  
fill ~54 ~21 ~16 ~55 ~21 ~16 stone_brick_stairs 2 
setblock ~54 ~21 ~21 anvil 1 
setblock ~55 ~21 ~5 anvil 3  
fill ~55 ~21 ~12 ~56 ~21 ~12 stone 0  
fill ~55 ~21 ~13 ~55 ~21 ~14 stone 0 
setblock ~55 ~21 ~21 anvil 3 
setblock ~56 ~21 ~5 stone_brick_stairs 2 
setblock ~56 ~21 ~9 stone_brick_stairs 3 
setblock ~56 ~21 ~10 stone_brick_stairs 1 
setblock ~56 ~21 ~14 stone 0 
setblock ~56 ~21 ~16 stone_brick_stairs 1 
setblock ~56 ~21 ~17 stone_brick_stairs 2 
setblock ~56 ~21 ~21 stone_brick_stairs 3 
setblock ~57 ~21 ~6 stone_brick_stairs 2  
fill ~57 ~21 ~7 ~57 ~21 ~8 stone_brick_stairs 1  
fill ~57 ~21 ~18 ~57 ~21 ~19 stone_brick_stairs 1 
setblock ~57 ~21 ~20 stone_brick_stairs 3  
fill ~58 ~21 ~11 ~58 ~23 ~11 monster_egg 0  
fill ~58 ~21 ~15 ~58 ~23 ~15 monster_egg 0  
fill ~59 ~21 ~6 ~59 ~23 ~6 monster_egg 0  
fill ~59 ~21 ~7 ~59 ~23 ~7 monster_egg 0  
fill ~59 ~21 ~8 ~59 ~23 ~8 monster_egg 0  
fill ~59 ~21 ~9 ~59 ~23 ~9 monster_egg 0  
fill ~59 ~21 ~10 ~59 ~23 ~10 monster_egg 0  
fill ~59 ~21 ~16 ~59 ~23 ~16 monster_egg 0  
fill ~59 ~21 ~17 ~59 ~23 ~17 monster_egg 0  
fill ~59 ~21 ~18 ~59 ~23 ~18 monster_egg 0  
fill ~59 ~21 ~19 ~59 ~23 ~19 monster_egg 0  
fill ~59 ~21 ~20 ~59 ~23 ~20 monster_egg 0  
fill ~60 ~21 ~5 ~61 ~21 ~5 monster_egg 0  
fill ~60 ~21 ~21 ~61 ~21 ~21 monster_egg 0 
setblock ~61 ~21 ~4 stone_brick_stairs 4 
setblock ~61 ~21 ~22 stone_brick_stairs 4  
fill ~62 ~21 ~4 ~66 ~21 ~4 stone 0  
fill ~62 ~21 ~22 ~66 ~21 ~22 stone 0  
fill ~63 ~21 ~3 ~65 ~21 ~3 stone_brick_stairs 6  
fill ~63 ~21 ~23 ~65 ~21 ~23 stone_brick_stairs 7 
setblock ~67 ~21 ~4 stone_brick_stairs 5  
fill ~67 ~21 ~5 ~68 ~21 ~5 monster_egg 0  
fill ~67 ~21 ~21 ~68 ~21 ~21 monster_egg 0 
setblock ~67 ~21 ~22 stone_brick_stairs 5  
fill ~69 ~21 ~6 ~69 ~23 ~6 monster_egg 0  
fill ~69 ~21 ~7 ~69 ~23 ~7 monster_egg 0  
fill ~69 ~21 ~8 ~69 ~23 ~8 monster_egg 0  
fill ~69 ~21 ~9 ~69 ~23 ~9 monster_egg 0  
fill ~69 ~21 ~10 ~69 ~23 ~10 monster_egg 0  
fill ~69 ~21 ~16 ~69 ~23 ~16 monster_egg 0  
fill ~69 ~21 ~17 ~69 ~23 ~17 monster_egg 0  
fill ~69 ~21 ~18 ~69 ~23 ~18 monster_egg 0  
fill ~69 ~21 ~19 ~69 ~23 ~19 monster_egg 0  
fill ~69 ~21 ~20 ~69 ~23 ~20 monster_egg 0  
fill ~70 ~21 ~11 ~70 ~23 ~11 monster_egg 0  
fill ~70 ~21 ~12 ~70 ~23 ~12 monster_egg 0  
fill ~70 ~21 ~13 ~70 ~23 ~13 monster_egg 0  
fill ~70 ~21 ~14 ~70 ~23 ~14 monster_egg 0  
fill ~70 ~21 ~15 ~70 ~23 ~15 monster_egg 0 
setblock ~71 ~21 ~6 stone_brick_stairs 2  
fill ~71 ~21 ~7 ~71 ~21 ~8 stone_brick_stairs 0  
fill ~71 ~21 ~18 ~71 ~21 ~19 stone_brick_stairs 0 
setblock ~71 ~21 ~20 stone_brick_stairs 3 
setblock ~72 ~21 ~5 stone_brick_stairs 2 
setblock ~72 ~21 ~9 stone_brick_stairs 3 
setblock ~72 ~21 ~10 stone_brick_stairs 0 
setblock ~72 ~21 ~16 stone_brick_stairs 0 
setblock ~72 ~21 ~17 stone_brick_stairs 2 
setblock ~72 ~21 ~21 stone_brick_stairs 3  
fill ~73 ~21 ~5 ~74 ~21 ~5 anvil 3  
fill ~73 ~21 ~10 ~74 ~21 ~10 stone_brick_stairs 3  
fill ~73 ~21 ~16 ~74 ~21 ~16 stone_brick_stairs 2  
fill ~73 ~21 ~21 ~74 ~21 ~21 anvil 3 
setblock ~75 ~21 ~5 stone_brick_stairs 2 
setblock ~75 ~21 ~9 stone_brick_stairs 3 
setblock ~75 ~21 ~10 stone_brick_stairs 1 
setblock ~75 ~21 ~16 stone_brick_stairs 1 
setblock ~75 ~21 ~17 stone_brick_stairs 2 
setblock ~75 ~21 ~21 stone_brick_stairs 3 
setblock ~76 ~21 ~6 stone_brick_stairs 2  
fill ~76 ~21 ~7 ~76 ~21 ~8 stone_brick_stairs 1  
fill ~76 ~21 ~18 ~76 ~21 ~19 stone_brick_stairs 1 
setblock ~76 ~21 ~20 stone_brick_stairs 3  
fill ~77 ~21 ~11 ~77 ~23 ~11 stone 0  
fill ~77 ~21 ~12 ~77 ~23 ~12 stone 0  
fill ~77 ~21 ~13 ~77 ~23 ~13 stone 0  
fill ~77 ~21 ~14 ~77 ~23 ~14 stone 0  
fill ~77 ~21 ~15 ~77 ~23 ~15 stone 0  
fill ~78 ~21 ~6 ~78 ~23 ~6 stone 0  
fill ~78 ~21 ~7 ~78 ~23 ~7 stone 0  
fill ~78 ~21 ~8 ~78 ~23 ~8 stone 0  
fill ~78 ~21 ~9 ~78 ~23 ~9 stone 0  
fill ~78 ~21 ~10 ~78 ~23 ~10 stone 0  
fill ~78 ~21 ~16 ~78 ~23 ~16 stone 0  
fill ~78 ~21 ~17 ~78 ~23 ~17 stone 0  
fill ~78 ~21 ~18 ~78 ~23 ~18 stone 0  
fill ~78 ~21 ~19 ~78 ~23 ~19 stone 0  
fill ~78 ~21 ~20 ~78 ~23 ~20 stone 0  
fill ~79 ~21 ~5 ~80 ~21 ~5 stone 0  
fill ~79 ~21 ~21 ~80 ~21 ~21 stone 0 
setblock ~80 ~21 ~4 stone_brick_stairs 4 
setblock ~80 ~21 ~22 stone_brick_stairs 4  
fill ~81 ~21 ~4 ~85 ~21 ~4 stone 0  
fill ~81 ~21 ~22 ~85 ~21 ~22 stone 0  
fill ~82 ~21 ~3 ~84 ~21 ~3 stone_brick_stairs 6  
fill ~82 ~21 ~23 ~84 ~21 ~23 stone_brick_stairs 7 
setblock ~86 ~21 ~4 stone_brick_stairs 5 
setblock ~86 ~21 ~5 monster_egg 0 
setblock ~86 ~21 ~21 monster_egg 0 
setblock ~86 ~21 ~22 stone_brick_stairs 5 
setblock ~87 ~21 ~5 stone 0 
setblock ~87 ~21 ~21 stone 0  
fill ~88 ~21 ~6 ~88 ~23 ~6 monster_egg 0  
fill ~88 ~21 ~7 ~88 ~23 ~7 monster_egg 0  
fill ~88 ~21 ~8 ~88 ~23 ~8 monster_egg 0  
fill ~88 ~21 ~9 ~88 ~23 ~9 monster_egg 0  
fill ~88 ~21 ~10 ~88 ~23 ~10 monster_egg 0  
fill ~88 ~21 ~16 ~88 ~23 ~16 monster_egg 0  
fill ~88 ~21 ~17 ~88 ~23 ~17 monster_egg 0  
fill ~88 ~21 ~18 ~88 ~23 ~18 monster_egg 0  
fill ~88 ~21 ~19 ~88 ~23 ~19 monster_egg 0  
fill ~88 ~21 ~20 ~88 ~23 ~20 monster_egg 0  
fill ~89 ~21 ~11 ~89 ~23 ~11 monster_egg 0  
fill ~89 ~21 ~12 ~89 ~23 ~12 monster_egg 0  
fill ~89 ~21 ~13 ~89 ~23 ~13 monster_egg 0  
fill ~89 ~21 ~14 ~89 ~23 ~14 monster_egg 0  
fill ~89 ~21 ~15 ~89 ~23 ~15 monster_egg 0 
setblock ~90 ~21 ~6 stone_brick_stairs 2  
fill ~90 ~21 ~7 ~90 ~21 ~8 stone_brick_stairs 0  
fill ~90 ~21 ~18 ~90 ~21 ~19 stone_brick_stairs 0 
setblock ~90 ~21 ~20 stone_brick_stairs 3 
setblock ~91 ~21 ~5 stone_brick_stairs 2 
setblock ~91 ~21 ~9 stone_brick_stairs 3 
setblock ~91 ~21 ~10 stone_brick_stairs 0 
setblock ~91 ~21 ~16 stone_brick_stairs 0 
setblock ~91 ~21 ~17 stone_brick_stairs 2 
setblock ~91 ~21 ~21 stone_brick_stairs 3  
fill ~92 ~21 ~5 ~93 ~21 ~5 anvil 1  
fill ~92 ~21 ~10 ~93 ~21 ~10 stone_brick_stairs 3  
fill ~92 ~21 ~16 ~93 ~21 ~16 stone_brick_stairs 2  
fill ~92 ~21 ~21 ~93 ~21 ~21 anvil 1 
setblock ~94 ~21 ~5 stone_brick_stairs 2 
setblock ~94 ~21 ~9 stone_brick_stairs 3 
setblock ~94 ~21 ~10 stone_brick_stairs 1 
setblock ~94 ~21 ~16 stone_brick_stairs 1 
setblock ~94 ~21 ~17 stone_brick_stairs 2 
setblock ~94 ~21 ~21 stone_brick_stairs 3 
setblock ~95 ~21 ~6 stone_brick_stairs 2  
fill ~95 ~21 ~7 ~95 ~21 ~8 stone_brick_stairs 1  
fill ~95 ~21 ~18 ~95 ~21 ~19 stone_brick_stairs 1 
setblock ~95 ~21 ~20 stone_brick_stairs 3  
fill ~96 ~21 ~11 ~96 ~23 ~11 stone 0  
fill ~96 ~21 ~12 ~96 ~23 ~12 stone 0  
fill ~96 ~21 ~13 ~96 ~23 ~13 stone 0  
fill ~96 ~21 ~14 ~96 ~23 ~14 stone 0  
fill ~96 ~21 ~15 ~96 ~23 ~15 stone 0  
fill ~97 ~21 ~6 ~97 ~23 ~6 stone 0  
fill ~97 ~21 ~7 ~97 ~23 ~7 stone 0  
fill ~97 ~21 ~8 ~97 ~23 ~8 stone 0  
fill ~97 ~21 ~9 ~97 ~23 ~9 stone 0  
fill ~97 ~21 ~10 ~97 ~23 ~10 stone 0  
fill ~97 ~21 ~16 ~97 ~23 ~16 stone 0  
fill ~97 ~21 ~17 ~97 ~23 ~17 stone 0  
fill ~97 ~21 ~18 ~97 ~23 ~18 stone 0  
fill ~97 ~21 ~19 ~97 ~23 ~19 stone 0  
fill ~97 ~21 ~20 ~97 ~23 ~20 stone 0  
fill ~98 ~21 ~5 ~99 ~21 ~5 stone 0  
fill ~98 ~21 ~21 ~99 ~21 ~21 stone 0 
setblock ~99 ~21 ~4 stone_brick_stairs 4 
setblock ~99 ~21 ~22 stone_brick_stairs 4 
setblock ~100 ~21 ~4 stone 0 
setblock ~100 ~21 ~22 stone 0  
fill ~101 ~21 ~4 ~101 ~22 ~4 monster_egg 0  
fill ~101 ~21 ~22 ~101 ~22 ~22 monster_egg 0  
fill ~102 ~21 ~4 ~103 ~21 ~4 stone 0  
fill ~102 ~21 ~22 ~103 ~21 ~22 stone 0  
fill ~103 ~21 ~5 ~104 ~21 ~5 stone 0  
fill ~103 ~21 ~6 ~106 ~21 ~6 stone 0  
fill ~103 ~21 ~20 ~106 ~21 ~20 stone 0  
fill ~103 ~21 ~21 ~104 ~21 ~21 stone 0 
setblock ~104 ~21 ~4 stone_brick_stairs 0 
setblock ~104 ~21 ~22 stone_brick_stairs 0 
setblock ~105 ~21 ~3 stone_brick_stairs 2 
setblock ~105 ~21 ~5 stone_slab 5  
fill ~105 ~21 ~7 ~114 ~21 ~7 stone 0  
fill ~105 ~21 ~19 ~114 ~21 ~19 stone 0 
setblock ~105 ~21 ~21 stone_slab 5 
setblock ~105 ~21 ~23 stone_brick_stairs 3  
fill ~106 ~21 ~3 ~108 ~21 ~3 iron_bars 0  
fill ~106 ~21 ~23 ~108 ~21 ~23 iron_bars 0 
setblock ~109 ~21 ~2 stone_brick_stairs 2 
setblock ~109 ~21 ~24 stone_brick_stairs 3  
fill ~110 ~21 ~2 ~112 ~21 ~2 iron_bars 0  
fill ~110 ~21 ~24 ~112 ~21 ~24 iron_bars 0 
setblock ~113 ~21 ~2 stone_brick_stairs 2 
setblock ~113 ~21 ~24 stone_brick_stairs 3  
fill ~114 ~21 ~2 ~116 ~21 ~2 iron_bars 0  
fill ~114 ~21 ~24 ~116 ~21 ~24 iron_bars 0  
fill ~115 ~21 ~8 ~115 ~27 ~8 stone 0  
fill ~115 ~21 ~9 ~115 ~27 ~9 stone 0  
fill ~115 ~21 ~10 ~115 ~27 ~10 stone 0  
fill ~115 ~21 ~11 ~115 ~27 ~11 stone 0  
fill ~115 ~21 ~12 ~115 ~27 ~12 stone 0  
fill ~115 ~21 ~13 ~123 ~21 ~13 stone 0  
fill ~115 ~21 ~14 ~115 ~27 ~14 stone 0  
fill ~115 ~21 ~15 ~115 ~27 ~15 stone 0  
fill ~115 ~21 ~16 ~115 ~27 ~16 stone 0  
fill ~115 ~21 ~17 ~115 ~27 ~17 stone 0  
fill ~115 ~21 ~18 ~115 ~27 ~18 stone 0  
fill ~116 ~21 ~8 ~116 ~24 ~8 stone_slab 5  
fill ~116 ~21 ~9 ~116 ~24 ~9 stone 6  
fill ~116 ~21 ~17 ~116 ~24 ~17 stone 6  
fill ~116 ~21 ~18 ~116 ~24 ~18 stone_slab 5 
setblock ~117 ~21 ~2 stone_brick_stairs 2 
setblock ~117 ~21 ~7 stone_brick_stairs 2  
fill ~117 ~21 ~8 ~117 ~23 ~8 anvil 1  
fill ~117 ~21 ~18 ~117 ~23 ~18 anvil 1 
setblock ~117 ~21 ~19 stone_brick_stairs 3 
setblock ~117 ~21 ~24 stone_brick_stairs 3  
fill ~118 ~21 ~2 ~120 ~21 ~2 iron_bars 0  
fill ~118 ~21 ~7 ~119 ~21 ~7 stone_slab 5  
fill ~118 ~21 ~8 ~124 ~21 ~8 stone 6  
fill ~118 ~21 ~18 ~124 ~21 ~18 stone 6  
fill ~118 ~21 ~19 ~119 ~21 ~19 stone_slab 5  
fill ~118 ~21 ~24 ~120 ~21 ~24 iron_bars 0 
setblock ~120 ~21 ~7 anvil 1 
setblock ~120 ~21 ~19 anvil 1 
setblock ~121 ~21 ~2 stone_brick_stairs 2 
setblock ~121 ~21 ~7 stone_slab 5 
setblock ~121 ~21 ~19 stone_slab 5 
setblock ~121 ~21 ~24 stone_brick_stairs 3  
fill ~122 ~21 ~2 ~124 ~21 ~2 iron_bars 0 
setblock ~122 ~21 ~7 anvil 1 
setblock ~122 ~21 ~19 anvil 1  
fill ~122 ~21 ~24 ~124 ~21 ~24 iron_bars 0  
fill ~123 ~21 ~7 ~124 ~21 ~7 stone_slab 5  
fill ~123 ~21 ~19 ~124 ~21 ~19 stone_slab 5 
setblock ~125 ~21 ~2 stone_brick_stairs 2 
setblock ~125 ~21 ~7 stone_brick_stairs 2  
fill ~125 ~21 ~8 ~125 ~23 ~8 anvil 1  
fill ~125 ~21 ~9 ~125 ~23 ~9 stone 6  
fill ~125 ~21 ~10 ~125 ~23 ~10 stone 6  
fill ~125 ~21 ~13 ~125 ~29 ~13 stone 0  
fill ~125 ~21 ~16 ~125 ~23 ~16 stone 6  
fill ~125 ~21 ~17 ~125 ~23 ~17 stone 6  
fill ~125 ~21 ~18 ~125 ~23 ~18 anvil 1 
setblock ~125 ~21 ~19 stone_brick_stairs 3 
setblock ~125 ~21 ~24 stone_brick_stairs 3 
setblock ~126 ~21 ~2 iron_bars 0 
setblock ~126 ~21 ~3 stone_brick_stairs 0 
setblock ~126 ~21 ~4 iron_bars 0 
setblock ~126 ~21 ~5 stone_brick_stairs 0 
setblock ~126 ~21 ~6 iron_bars 0 
setblock ~126 ~21 ~7 stone_brick_stairs 0  
fill ~126 ~21 ~11 ~126 ~27 ~11 stone 0  
fill ~126 ~21 ~12 ~127 ~21 ~12 stone 0  
fill ~126 ~21 ~14 ~127 ~21 ~14 stone 0  
fill ~126 ~21 ~15 ~126 ~27 ~15 stone 0 
setblock ~126 ~21 ~19 stone_brick_stairs 0 
setblock ~126 ~21 ~20 iron_bars 0 
setblock ~126 ~21 ~21 stone_brick_stairs 0 
setblock ~126 ~21 ~22 iron_bars 0 
setblock ~126 ~21 ~23 stone_brick_stairs 0 
setblock ~126 ~21 ~24 iron_bars 0  
fill ~127 ~21 ~10 ~132 ~21 ~10 stone 0  
fill ~127 ~21 ~13 ~128 ~21 ~13 stone 0  
fill ~127 ~21 ~16 ~132 ~21 ~16 stone 0 
setblock ~128 ~21 ~4 anvil 0 
setblock ~128 ~21 ~5 cobblestone_wall 0 
setblock ~128 ~21 ~21 cobblestone_wall 0 
setblock ~128 ~21 ~22 anvil 0  
fill ~129 ~21 ~5 ~129 ~21 ~8 stone_slab 8  
fill ~129 ~21 ~12 ~129 ~23 ~12 stone 0  
fill ~129 ~21 ~14 ~129 ~23 ~14 stone 0  
fill ~129 ~21 ~18 ~129 ~21 ~21 stone_slab 8 
setblock ~130 ~21 ~4 anvil 0 
setblock ~130 ~21 ~5 cobblestone_wall 0  
fill ~130 ~21 ~11 ~130 ~23 ~11 stone 0  
fill ~130 ~21 ~15 ~130 ~23 ~15 stone 0 
setblock ~130 ~21 ~21 cobblestone_wall 0 
setblock ~130 ~21 ~22 anvil 0 
setblock ~132 ~21 ~2 iron_bars 0 
setblock ~132 ~21 ~3 stone_brick_stairs 1 
setblock ~132 ~21 ~4 iron_bars 0 
setblock ~132 ~21 ~5 stone_brick_stairs 1 
setblock ~132 ~21 ~6 iron_bars 0 
setblock ~132 ~21 ~7 stone_brick_stairs 1  
fill ~132 ~21 ~9 ~132 ~23 ~9 stone 0  
fill ~132 ~21 ~17 ~132 ~23 ~17 stone 0 
setblock ~132 ~21 ~19 stone_brick_stairs 1 
setblock ~132 ~21 ~20 iron_bars 0 
setblock ~132 ~21 ~21 stone_brick_stairs 1 
setblock ~132 ~21 ~22 iron_bars 0 
setblock ~132 ~21 ~23 stone_brick_stairs 1 
setblock ~132 ~21 ~24 iron_bars 0 
setblock ~133 ~21 ~2 stone_brick_stairs 2  
fill ~133 ~21 ~8 ~133 ~23 ~8 stone 0  
fill ~133 ~21 ~18 ~133 ~23 ~18 stone 0 
setblock ~133 ~21 ~24 stone_brick_stairs 3  
fill ~134 ~21 ~2 ~135 ~21 ~2 iron_bars 0  
fill ~134 ~21 ~7 ~134 ~23 ~7 stone 0  
fill ~134 ~21 ~19 ~134 ~23 ~19 stone 0  
fill ~134 ~21 ~24 ~135 ~21 ~24 iron_bars 0  
fill ~135 ~21 ~6 ~135 ~23 ~6 stone 0  
fill ~135 ~21 ~20 ~135 ~23 ~20 stone 0 
setblock ~136 ~21 ~2 stone_brick_stairs 2 
setblock ~136 ~21 ~3 stone_slab 8  
fill ~136 ~21 ~5 ~142 ~21 ~5 stone 0  
fill ~136 ~21 ~21 ~142 ~21 ~21 stone 0 
setblock ~136 ~21 ~23 stone_slab 8 
setblock ~136 ~21 ~24 stone_brick_stairs 3  
fill ~137 ~21 ~2 ~137 ~21 ~3 stone_slab 13  
fill ~137 ~21 ~23 ~142 ~21 ~23 stone_slab 13  
fill ~137 ~21 ~24 ~137 ~21 ~23 stone_slab 13  
fill ~138 ~21 ~3 ~142 ~21 ~3 stone_slab 13 
setblock ~139 ~21 ~8 stone 0 
setblock ~139 ~21 ~18 stone 0 
setblock ~140 ~21 ~7 stone 0 
setblock ~140 ~21 ~19 stone 0 
setblock ~141 ~21 ~6 stone 0 
setblock ~141 ~21 ~20 stone 0  
fill ~143 ~21 ~3 ~163 ~21 ~3 stone 6 
setblock ~143 ~21 ~4 stone 0 
setblock ~143 ~21 ~22 stone 0  
fill ~143 ~21 ~23 ~163 ~21 ~23 stone 6  
fill ~164 ~21 ~3 ~170 ~21 ~3 stone_slab 8  
fill ~164 ~21 ~4 ~164 ~23 ~4 stone 0  
fill ~164 ~21 ~22 ~164 ~23 ~22 stone 0  
fill ~164 ~21 ~23 ~170 ~21 ~23 stone_slab 8  
fill ~165 ~21 ~5 ~165 ~23 ~5 stone 0  
fill ~165 ~21 ~21 ~165 ~23 ~21 stone 0  
fill ~166 ~21 ~6 ~166 ~23 ~6 stone 0  
fill ~166 ~21 ~20 ~166 ~23 ~20 stone 0  
fill ~167 ~21 ~7 ~167 ~23 ~7 stone 0  
fill ~167 ~21 ~19 ~167 ~23 ~19 stone 0  
fill ~168 ~21 ~8 ~168 ~23 ~8 double_stone_slab 14  
fill ~168 ~21 ~9 ~169 ~21 ~9 stone 0  
fill ~168 ~21 ~10 ~169 ~21 ~10 stone 0  
fill ~168 ~21 ~16 ~169 ~21 ~16 stone 0  
fill ~168 ~21 ~17 ~169 ~21 ~17 stone 0  
fill ~168 ~21 ~18 ~168 ~23 ~18 double_stone_slab 14  
fill ~169 ~21 ~11 ~169 ~22 ~11 stone 0  
fill ~169 ~21 ~15 ~169 ~22 ~15 stone 0 
setblock ~170 ~21 ~9 stone_slab 5 
setblock ~170 ~21 ~10 stone_slab 0 
setblock ~170 ~21 ~11 double_stone_slab 14 
setblock ~170 ~21 ~12 stone_slab 0 
setblock ~170 ~21 ~14 stone_slab 0 
setblock ~170 ~21 ~15 double_stone_slab 14 
setblock ~170 ~21 ~16 stone_slab 0 
setblock ~170 ~21 ~17 stone_slab 5  
fill ~171 ~21 ~2 ~175 ~21 ~2 stone_slab 5  
fill ~171 ~21 ~3 ~175 ~21 ~3 iron_bars 0 
setblock ~171 ~21 ~9 stone_brick_stairs 2 
setblock ~171 ~21 ~10 double_stone_slab 0 
setblock ~171 ~21 ~11 stained_hardened_clay 14 
setblock ~171 ~21 ~12 double_stone_slab 14  
fill ~171 ~21 ~13 ~176 ~21 ~13 anvil 1 
setblock ~171 ~21 ~14 double_stone_slab 14 
setblock ~171 ~21 ~15 stained_hardened_clay 14 
setblock ~171 ~21 ~16 double_stone_slab 0 
setblock ~171 ~21 ~17 stone_brick_stairs 3  
fill ~171 ~21 ~23 ~175 ~21 ~23 iron_bars 0  
fill ~171 ~21 ~24 ~175 ~21 ~24 stone_slab 5 
setblock ~172 ~21 ~9 stone_slab 5 
setblock ~172 ~21 ~10 stone_slab 0 
setblock ~172 ~21 ~11 double_stone_slab 14 
setblock ~172 ~21 ~12 stone_slab 0 
setblock ~172 ~21 ~14 stone_slab 0 
setblock ~172 ~21 ~15 double_stone_slab 14 
setblock ~172 ~21 ~16 stone_slab 0 
setblock ~172 ~21 ~17 stone_slab 5 
setblock ~173 ~21 ~9 stone_brick_stairs 2 
setblock ~173 ~21 ~10 double_stone_slab 14 
setblock ~173 ~21 ~11 stained_hardened_clay 14 
setblock ~173 ~21 ~12 double_stone_slab 14 
setblock ~173 ~21 ~14 double_stone_slab 14 
setblock ~173 ~21 ~15 stained_hardened_clay 14 
setblock ~173 ~21 ~16 double_stone_slab 14 
setblock ~173 ~21 ~17 stone_brick_stairs 3 
setblock ~174 ~21 ~9 stone_slab 5 
setblock ~174 ~21 ~10 stone_slab 0 
setblock ~174 ~21 ~11 double_stone_slab 14 
setblock ~174 ~21 ~12 stone_slab 0 
setblock ~174 ~21 ~14 stone_slab 0 
setblock ~174 ~21 ~15 double_stone_slab 14 
setblock ~174 ~21 ~16 stone_slab 0 
setblock ~174 ~21 ~17 stone_slab 5  
fill ~175 ~21 ~4 ~181 ~21 ~4 iron_bars 0 
setblock ~175 ~21 ~9 stone_brick_stairs 2 
setblock ~175 ~21 ~10 double_stone_slab 14 
setblock ~175 ~21 ~11 stained_hardened_clay 14   

KittysCommands:  
setblock ~175 ~21 ~12 double_stone_slab 14 
setblock ~175 ~21 ~14 double_stone_slab 14 
setblock ~175 ~21 ~15 stained_hardened_clay 14 
setblock ~175 ~21 ~16 double_stone_slab 14 
setblock ~175 ~21 ~17 stone_brick_stairs 3  
fill ~175 ~21 ~22 ~181 ~21 ~22 iron_bars 0  
fill ~176 ~21 ~3 ~181 ~21 ~3 stone_slab 5 
setblock ~176 ~21 ~9 stone_slab 5 
setblock ~176 ~21 ~10 stone_slab 0 
setblock ~176 ~21 ~11 double_stone_slab 14 
setblock ~176 ~21 ~12 stone_slab 0 
setblock ~176 ~21 ~14 stone_slab 0 
setblock ~176 ~21 ~15 double_stone_slab 14 
setblock ~176 ~21 ~16 stone_slab 0 
setblock ~176 ~21 ~17 stone_slab 5  
fill ~176 ~21 ~23 ~181 ~21 ~23 stone_slab 5 
setblock ~177 ~21 ~10 stone_slab 5 
setblock ~177 ~21 ~11 stone_brick_stairs 1 
setblock ~177 ~21 ~12 stone_slab 5 
setblock ~177 ~21 ~13 stone_brick_stairs 1 
setblock ~177 ~21 ~14 stone_slab 5 
setblock ~177 ~21 ~15 stone_brick_stairs 1 
setblock ~177 ~21 ~16 stone_slab 5 
setblock ~178 ~21 ~11 stone_slab 0  
fill ~178 ~21 ~12 ~178 ~21 ~14 stone_slab 8 
setblock ~178 ~21 ~15 stone_slab 0  
fill ~179 ~21 ~10 ~179 ~21 ~11 stone_slab 5  
fill ~179 ~21 ~12 ~180 ~21 ~12 stained_hardened_clay 9  
fill ~179 ~21 ~13 ~180 ~21 ~13 stained_hardened_clay 9  
fill ~179 ~21 ~14 ~180 ~21 ~14 stained_hardened_clay 9  
fill ~179 ~21 ~15 ~179 ~21 ~16 stone_slab 5  
fill ~180 ~21 ~8 ~180 ~21 ~9 stone_slab 5  
fill ~180 ~21 ~10 ~181 ~21 ~10 stained_hardened_clay 9  
fill ~180 ~21 ~11 ~181 ~21 ~11 stained_hardened_clay 9  
fill ~180 ~21 ~15 ~181 ~21 ~15 stained_hardened_clay 9  
fill ~180 ~21 ~16 ~181 ~21 ~16 stained_hardened_clay 9  
fill ~180 ~21 ~17 ~180 ~21 ~18 stone_slab 5 
setblock ~181 ~21 ~5 iron_bars 0  
fill ~181 ~21 ~6 ~181 ~21 ~7 stone_slab 5  
fill ~181 ~21 ~8 ~184 ~21 ~8 stained_hardened_clay 9  
fill ~181 ~21 ~9 ~182 ~21 ~9 stained_hardened_clay 9  
fill ~181 ~21 ~12 ~181 ~21 ~14 stained_hardened_clay 14  
fill ~181 ~21 ~17 ~182 ~21 ~17 stained_hardened_clay 9  
fill ~181 ~21 ~18 ~184 ~21 ~18 stained_hardened_clay 9  
fill ~181 ~21 ~19 ~181 ~21 ~20 stone_slab 5 
setblock ~181 ~21 ~21 iron_bars 0  
fill ~182 ~21 ~4 ~187 ~21 ~4 stone_slab 5  
fill ~182 ~21 ~5 ~187 ~21 ~5 stone 6  
fill ~182 ~21 ~6 ~187 ~21 ~6 stained_hardened_clay 9  
fill ~182 ~21 ~7 ~186 ~21 ~7 stained_hardened_clay 9  
fill ~182 ~21 ~10 ~182 ~21 ~11 stained_hardened_clay 14  
fill ~182 ~21 ~12 ~193 ~21 ~12 stained_hardened_clay 9  
fill ~182 ~21 ~13 ~193 ~21 ~13 stained_hardened_clay 9  
fill ~182 ~21 ~14 ~193 ~21 ~14 stained_hardened_clay 9  
fill ~182 ~21 ~15 ~182 ~21 ~16 stained_hardened_clay 14  
fill ~182 ~21 ~19 ~186 ~21 ~19 stained_hardened_clay 9  
fill ~182 ~21 ~20 ~187 ~21 ~20 stained_hardened_clay 9  
fill ~182 ~21 ~21 ~187 ~21 ~21 stone 6  
fill ~182 ~21 ~22 ~187 ~21 ~22 stone_slab 5  
fill ~183 ~21 ~9 ~184 ~21 ~9 stained_hardened_clay 14  
fill ~183 ~21 ~10 ~192 ~21 ~10 stained_hardened_clay 9  
fill ~183 ~21 ~11 ~192 ~21 ~11 stained_hardened_clay 9  
fill ~183 ~21 ~15 ~192 ~21 ~15 stained_hardened_clay 9  
fill ~183 ~21 ~16 ~192 ~21 ~16 stained_hardened_clay 9  
fill ~183 ~21 ~17 ~184 ~21 ~17 stained_hardened_clay 14  
fill ~185 ~21 ~8 ~186 ~21 ~8 stained_hardened_clay 14  
fill ~185 ~21 ~9 ~189 ~21 ~9 stained_hardened_clay 9  
fill ~185 ~21 ~17 ~189 ~21 ~17 stained_hardened_clay 9  
fill ~185 ~21 ~18 ~186 ~21 ~18 stained_hardened_clay 14 
setblock ~187 ~21 ~7 stained_hardened_clay 14 
setblock ~187 ~21 ~8 stained_hardened_clay 9 
setblock ~187 ~21 ~18 stained_hardened_clay 9 
setblock ~187 ~21 ~19 stained_hardened_clay 14  
fill ~188 ~21 ~5 ~191 ~21 ~5 stone_slab 5  
fill ~188 ~21 ~6 ~191 ~21 ~6 stone 6  
fill ~188 ~21 ~7 ~191 ~21 ~7 stained_hardened_clay 9  
fill ~188 ~21 ~8 ~189 ~21 ~8 stained_hardened_clay 14  
fill ~188 ~21 ~18 ~189 ~21 ~18 stained_hardened_clay 14  
fill ~188 ~21 ~19 ~191 ~21 ~19 stained_hardened_clay 9  
fill ~188 ~21 ~20 ~191 ~21 ~20 stone 6  
fill ~188 ~21 ~21 ~191 ~21 ~21 stone_slab 5  
fill ~190 ~21 ~8 ~195 ~21 ~8 stained_hardened_clay 9  
fill ~190 ~21 ~9 ~192 ~21 ~9 stained_hardened_clay 14  
fill ~190 ~21 ~17 ~192 ~21 ~17 stained_hardened_clay 14  
fill ~190 ~21 ~18 ~195 ~21 ~18 stained_hardened_clay 9 
setblock ~192 ~21 ~6 stone_slab 13  
fill ~192 ~21 ~7 ~197 ~21 ~7 stone 0  
fill ~192 ~21 ~19 ~197 ~21 ~19 stone 0 
setblock ~192 ~21 ~20 stone_slab 13  
fill ~193 ~21 ~9 ~198 ~21 ~9 stained_hardened_clay 9  
fill ~193 ~21 ~10 ~193 ~21 ~11 stained_hardened_clay 14  
fill ~193 ~21 ~15 ~193 ~21 ~16 stained_hardened_clay 14  
fill ~193 ~21 ~17 ~198 ~21 ~17 stained_hardened_clay 9  
fill ~194 ~21 ~10 ~198 ~21 ~10 stained_hardened_clay 9  
fill ~194 ~21 ~11 ~198 ~21 ~11 stained_hardened_clay 9  
fill ~194 ~21 ~12 ~194 ~21 ~14 stained_hardened_clay 14  
fill ~194 ~21 ~15 ~198 ~21 ~15 stained_hardened_clay 9  
fill ~194 ~21 ~16 ~198 ~21 ~16 stained_hardened_clay 9  
fill ~195 ~21 ~12 ~203 ~21 ~12 stained_hardened_clay 9  
fill ~195 ~21 ~13 ~201 ~21 ~13 stained_hardened_clay 9  
fill ~195 ~21 ~14 ~203 ~21 ~14 stained_hardened_clay 9  
fill ~196 ~21 ~8 ~198 ~21 ~8 stone 0  
fill ~196 ~21 ~18 ~198 ~21 ~18 stone 0  
fill ~199 ~21 ~9 ~200 ~21 ~9 stone 0  
fill ~199 ~21 ~10 ~199 ~21 ~11 iron_bars 0  
fill ~199 ~21 ~15 ~201 ~21 ~15 iron_bars 0  
fill ~199 ~21 ~16 ~199 ~21 ~15 iron_bars 0  
fill ~199 ~21 ~17 ~200 ~21 ~17 stone 0 
setblock ~200 ~21 ~10 stained_hardened_clay 9  
fill ~200 ~21 ~11 ~201 ~21 ~11 iron_bars 0 
setblock ~200 ~21 ~16 stained_hardened_clay 9  
fill ~201 ~21 ~10 ~203 ~21 ~10 stone 0  
fill ~201 ~21 ~16 ~203 ~21 ~16 stone 0  
fill ~202 ~21 ~11 ~202 ~22 ~11 stained_hardened_clay 9  
fill ~202 ~21 ~15 ~202 ~22 ~15 stained_hardened_clay 9  
fill ~203 ~21 ~11 ~204 ~21 ~11 stone 0  
fill ~203 ~21 ~15 ~204 ~21 ~15 stone 0  
fill ~204 ~21 ~12 ~205 ~21 ~12 stone 0  
fill ~204 ~21 ~13 ~205 ~21 ~13 stained_hardened_clay 9  
fill ~204 ~21 ~14 ~205 ~21 ~14 stone 0 
setblock ~206 ~21 ~13 stone 0  
fill ~2 ~22 ~10 ~2 ~22 ~16 iron_bars 0  
fill ~3 ~22 ~8 ~3 ~22 ~9 iron_bars 0 
setblock ~3 ~22 ~10 carpet 4 
setblock ~3 ~22 ~11 carpet 15 
setblock ~3 ~22 ~12 carpet 4 
setblock ~3 ~22 ~13 carpet 15 
setblock ~3 ~22 ~14 carpet 4 
setblock ~3 ~22 ~15 carpet 15 
setblock ~3 ~22 ~16 carpet 4  
fill ~3 ~22 ~17 ~3 ~22 ~18 iron_bars 0 
setblock ~4 ~22 ~7 iron_bars 0 
setblock ~4 ~22 ~8 carpet 4 
setblock ~4 ~22 ~9 carpet 15 
setblock ~4 ~22 ~17 carpet 15 
setblock ~4 ~22 ~18 carpet 4 
setblock ~4 ~22 ~19 iron_bars 0  
fill ~5 ~22 ~6 ~13 ~22 ~6 iron_bars 0 
setblock ~5 ~22 ~7 carpet 15 
setblock ~5 ~22 ~19 carpet 15  
fill ~5 ~22 ~20 ~13 ~22 ~20 iron_bars 0 
setblock ~6 ~22 ~7 carpet 4 
setblock ~6 ~22 ~19 carpet 4 
setblock ~7 ~22 ~7 carpet 15 
setblock ~7 ~22 ~19 carpet 15 
setblock ~8 ~22 ~7 carpet 4 
setblock ~8 ~22 ~19 carpet 4 
setblock ~9 ~22 ~7 carpet 15 
setblock ~9 ~22 ~19 carpet 15 
setblock ~10 ~22 ~7 carpet 4 
setblock ~10 ~22 ~19 carpet 4 
setblock ~11 ~22 ~7 carpet 15 
setblock ~11 ~22 ~19 carpet 15 
setblock ~12 ~22 ~7 carpet 4 
setblock ~12 ~22 ~19 carpet 4 
setblock ~13 ~22 ~7 carpet 15 
setblock ~13 ~22 ~13 stone_brick_stairs 4 
setblock ~13 ~22 ~19 carpet 15  
fill ~14 ~22 ~5 ~27 ~22 ~5 iron_bars 0 
setblock ~14 ~22 ~6 carpet 4  
fill ~14 ~22 ~12 ~15 ~22 ~12 stone_slab 8  
fill ~14 ~22 ~13 ~16 ~22 ~13 stained_hardened_clay 9  
fill ~14 ~22 ~14 ~15 ~22 ~14 stone_slab 8 
setblock ~14 ~22 ~20 carpet 4  
fill ~14 ~22 ~21 ~27 ~22 ~21 iron_bars 0 
setblock ~15 ~22 ~6 carpet 15 
setblock ~15 ~22 ~20 carpet 15 
setblock ~16 ~22 ~6 carpet 4 
setblock ~16 ~22 ~12 stone_brick_stairs 4 
setblock ~16 ~22 ~14 stone_brick_stairs 4 
setblock ~16 ~22 ~20 carpet 4 
setblock ~17 ~22 ~6 carpet 15  
fill ~17 ~22 ~12 ~29 ~22 ~12 stained_hardened_clay 9  
fill ~17 ~22 ~13 ~20 ~22 ~13 stonebrick 0  
fill ~17 ~22 ~14 ~29 ~22 ~14 stained_hardened_clay 9 
setblock ~17 ~22 ~20 carpet 15 
setblock ~18 ~22 ~6 carpet 4 
setblock ~18 ~22 ~10 stone_brick_stairs 4 
setblock ~18 ~22 ~16 stone_brick_stairs 4 
setblock ~18 ~22 ~20 carpet 4 
setblock ~19 ~22 ~6 carpet 15 
setblock ~19 ~22 ~9 stone_brick_stairs 6 
setblock ~19 ~22 ~10 stone_brick_stairs 0 
setblock ~19 ~22 ~11 double_stone_slab 0 
setblock ~19 ~22 ~15 double_stone_slab 0 
setblock ~19 ~22 ~16 stone_brick_stairs 0 
setblock ~19 ~22 ~17 stone_brick_stairs 7 
setblock ~19 ~22 ~20 carpet 15 
setblock ~20 ~22 ~6 carpet 4  
fill ~20 ~22 ~9 ~20 ~22 ~10 stone_brick_stairs 2  
fill ~20 ~22 ~11 ~22 ~22 ~11 stone_slab 14  
fill ~20 ~22 ~15 ~22 ~22 ~15 stone_slab 14  
fill ~20 ~22 ~16 ~20 ~22 ~17 stone_brick_stairs 3 
setblock ~20 ~22 ~20 carpet 4 
setblock ~21 ~22 ~6 carpet 15 
setblock ~21 ~22 ~9 stone_slab 13  
fill ~21 ~22 ~10 ~21 ~23 ~10 stone_slab 5  
fill ~21 ~22 ~13 ~32 ~22 ~13 stained_hardened_clay 9  
fill ~21 ~22 ~16 ~21 ~23 ~16 stone_slab 5 
setblock ~21 ~22 ~17 stone_slab 13 
setblock ~21 ~22 ~20 carpet 15 
setblock ~22 ~22 ~6 carpet 4 
setblock ~22 ~22 ~10 stone_brick_stairs 5 
setblock ~22 ~22 ~16 stone_brick_stairs 5 
setblock ~22 ~22 ~20 carpet 4 
setblock ~23 ~22 ~6 carpet 15  
fill ~23 ~22 ~11 ~25 ~22 ~11 stone_slab 13  
fill ~23 ~22 ~15 ~25 ~22 ~15 stone_slab 13 
setblock ~23 ~22 ~20 carpet 15 
setblock ~24 ~22 ~6 carpet 4 
setblock ~24 ~22 ~20 carpet 4 
setblock ~25 ~22 ~6 carpet 15 
setblock ~25 ~22 ~20 carpet 15 
setblock ~26 ~22 ~6 carpet 4  
fill ~26 ~22 ~11 ~27 ~22 ~11 stone_slab 8  
fill ~26 ~22 ~15 ~27 ~22 ~15 stone_slab 8 
setblock ~26 ~22 ~20 carpet 4 
setblock ~27 ~22 ~6 carpet 15 
setblock ~27 ~22 ~20 carpet 15  
fill ~28 ~22 ~4 ~42 ~22 ~4 iron_bars 0 
setblock ~28 ~22 ~5 carpet 4 
setblock ~28 ~22 ~11 stone_slab 13 
setblock ~28 ~22 ~15 stone_slab 13 
setblock ~28 ~22 ~21 carpet 4  
fill ~28 ~22 ~22 ~42 ~22 ~22 iron_bars 0 
setblock ~29 ~22 ~5 carpet 15 
setblock ~29 ~22 ~21 carpet 15 
setblock ~30 ~22 ~5 carpet 4  
fill ~30 ~22 ~12 ~32 ~22 ~12 stone_brick_stairs 6  
fill ~30 ~22 ~14 ~32 ~22 ~14 stone_brick_stairs 7 
setblock ~30 ~22 ~21 carpet 4 
setblock ~31 ~22 ~5 carpet 15 
setblock ~31 ~22 ~21 carpet 15 
setblock ~32 ~22 ~5 carpet 4 
setblock ~32 ~22 ~21 carpet 4 
setblock ~33 ~22 ~5 carpet 15  
fill ~33 ~22 ~12 ~33 ~22 ~14 stone_brick_stairs 5 
setblock ~33 ~22 ~21 carpet 15 
setblock ~34 ~22 ~5 carpet 4 
setblock ~34 ~22 ~21 carpet 4 
setblock ~35 ~22 ~5 carpet 15 
setblock ~35 ~22 ~21 carpet 15 
setblock ~36 ~22 ~5 carpet 4 
setblock ~36 ~22 ~21 carpet 4 
setblock ~37 ~22 ~5 carpet 15 
setblock ~37 ~22 ~21 carpet 15 
setblock ~38 ~22 ~5 carpet 4 
setblock ~38 ~22 ~21 carpet 4 
setblock ~39 ~22 ~5 carpet 15 
setblock ~39 ~22 ~21 carpet 15 
setblock ~40 ~22 ~5 carpet 4 
setblock ~40 ~22 ~21 carpet 4 
setblock ~41 ~22 ~5 carpet 15  
fill ~41 ~22 ~13 ~41 ~23 ~13 quartz_stairs 0 
setblock ~41 ~22 ~21 carpet 15  
fill ~43 ~22 ~4 ~49 ~22 ~4 stone 0  
fill ~43 ~22 ~22 ~49 ~22 ~22 stone 0 
setblock ~49 ~22 ~5 stone 0 
setblock ~49 ~22 ~21 stone 0 
setblock ~50 ~22 ~4 stone_slab 13 
setblock ~50 ~22 ~22 stone_slab 13 
setblock ~52 ~22 ~5 stone_brick_stairs 6  
fill ~52 ~22 ~6 ~57 ~22 ~6 stone 6  
fill ~52 ~22 ~7 ~57 ~22 ~7 stone 6  
fill ~52 ~22 ~8 ~57 ~22 ~8 stone 6 
setblock ~52 ~22 ~9 stone_brick_stairs 7 
setblock ~52 ~22 ~10 stone_slab 13 
setblock ~52 ~22 ~16 stone_slab 13 
setblock ~52 ~22 ~17 stone_brick_stairs 6  
fill ~52 ~22 ~18 ~57 ~22 ~18 stone 6  
fill ~52 ~22 ~19 ~57 ~22 ~19 stone 6  
fill ~52 ~22 ~20 ~57 ~22 ~20 stone 6 
setblock ~52 ~22 ~21 stone_brick_stairs 7  
fill ~53 ~22 ~4 ~56 ~22 ~4 iron_trapdoor 4  
fill ~53 ~22 ~5 ~56 ~22 ~5 stained_hardened_clay 14  
fill ~53 ~22 ~9 ~56 ~22 ~9 stone 6  
fill ~53 ~22 ~10 ~56 ~22 ~10 stone 6  
fill ~53 ~22 ~11 ~56 ~22 ~11 stone_slab 13  
fill ~53 ~22 ~15 ~56 ~22 ~15 stone_slab 13  
fill ~53 ~22 ~16 ~56 ~22 ~16 stone 6  
fill ~53 ~22 ~17 ~56 ~22 ~17 stone 6  
fill ~53 ~22 ~21 ~56 ~22 ~21 stained_hardened_clay 14 
setblock ~57 ~22 ~5 stone_brick_stairs 6 
setblock ~57 ~22 ~9 stone_brick_stairs 7 
setblock ~57 ~22 ~10 stone_slab 13 
setblock ~57 ~22 ~16 stone_slab 13 
setblock ~57 ~22 ~17 stone_brick_stairs 6 
setblock ~57 ~22 ~21 stone_brick_stairs 7 
setblock ~59 ~22 ~4 stone_slab 13 
setblock ~59 ~22 ~22 stone_slab 13 
setblock ~60 ~22 ~4 stone_brick_stairs 4  
fill ~60 ~22 ~5 ~60 ~21 ~5 monster_egg 0  
fill ~60 ~22 ~21 ~60 ~21 ~21 monster_egg 0 
setblock ~60 ~22 ~22 stone_brick_stairs 4  
fill ~61 ~22 ~4 ~67 ~22 ~4 stone 0  
fill ~61 ~22 ~22 ~67 ~22 ~22 stone 0  
fill ~63 ~22 ~3 ~65 ~22 ~3 iron_bars 0  
fill ~63 ~22 ~23 ~65 ~22 ~23 iron_bars 0 
setblock ~68 ~22 ~4 stone_brick_stairs 5 
setblock ~68 ~22 ~5 monster_egg 0 
setblock ~68 ~22 ~21 monster_egg 0 
setblock ~68 ~22 ~22 stone_brick_stairs 5 
setblock ~69 ~22 ~4 stone_slab 13 
setblock ~69 ~22 ~22 stone_slab 13 
setblock ~71 ~22 ~5 stone_brick_stairs 6  
fill ~71 ~22 ~6 ~76 ~22 ~6 stone 6  
fill ~71 ~22 ~7 ~76 ~22 ~7 stone 6  
fill ~71 ~22 ~8 ~76 ~22 ~8 stone 6 
setblock ~71 ~22 ~9 stone_brick_stairs 7 
setblock ~71 ~22 ~10 stone_slab 13 
setblock ~71 ~22 ~16 stone_slab 13 
setblock ~71 ~22 ~17 stone_brick_stairs 6  
fill ~71 ~22 ~18 ~76 ~22 ~18 stone 6  
fill ~71 ~22 ~19 ~76 ~22 ~19 stone 6  
fill ~71 ~22 ~20 ~76 ~22 ~20 stone 6 
setblock ~71 ~22 ~21 stone_brick_stairs 7  
fill ~72 ~22 ~4 ~75 ~22 ~4 iron_trapdoor 4  
fill ~72 ~22 ~5 ~75 ~22 ~5 stained_hardened_clay 14  
fill ~72 ~22 ~9 ~75 ~22 ~9 stone 6  
fill ~72 ~22 ~10 ~75 ~22 ~10 stone 6  
fill ~72 ~22 ~11 ~75 ~22 ~11 stone_slab 13  
fill ~72 ~22 ~15 ~75 ~22 ~15 stone_slab 13  
fill ~72 ~22 ~16 ~75 ~22 ~16 stone 6  
fill ~72 ~22 ~17 ~75 ~22 ~17 stone 6  
fill ~72 ~22 ~21 ~75 ~22 ~21 stained_hardened_clay 14 
setblock ~76 ~22 ~5 stone_brick_stairs 6 
setblock ~76 ~22 ~9 stone_brick_stairs 7 
setblock ~76 ~22 ~10 stone_slab 13 
setblock ~76 ~22 ~16 stone_slab 13 
setblock ~76 ~22 ~17 stone_brick_stairs 6 
setblock ~76 ~22 ~21 stone_brick_stairs 7 
setblock ~78 ~22 ~4 stone_slab 13 
setblock ~78 ~22 ~22 stone_slab 13 
setblock ~79 ~22 ~4 stone_brick_stairs 4  
fill ~79 ~22 ~5 ~79 ~21 ~5 stone 0  
fill ~79 ~22 ~21 ~79 ~21 ~21 stone 0 
setblock ~79 ~22 ~22 stone_brick_stairs 4  
fill ~80 ~22 ~4 ~86 ~22 ~4 stone 0  
fill ~80 ~22 ~22 ~86 ~22 ~22 stone 0  
fill ~82 ~22 ~3 ~84 ~22 ~3 iron_bars 0  
fill ~82 ~22 ~23 ~84 ~22 ~23 iron_bars 0 
setblock ~87 ~22 ~4 stone_brick_stairs 5 
setblock ~87 ~22 ~5 monster_egg 0 
setblock ~87 ~22 ~21 monster_egg 0 
setblock ~87 ~22 ~22 stone_brick_stairs 5 
setblock ~88 ~22 ~4 stone_slab 13 
setblock ~88 ~22 ~22 stone_slab 13 
setblock ~90 ~22 ~5 stone_brick_stairs 6  
fill ~90 ~22 ~6 ~95 ~22 ~6 stone 6  
fill ~90 ~22 ~7 ~95 ~22 ~7 stone 6  
fill ~90 ~22 ~8 ~95 ~22 ~8 stone 6 
setblock ~90 ~22 ~9 stone_brick_stairs 7 
setblock ~90 ~22 ~10 stone_slab 13 
setblock ~90 ~22 ~16 stone_slab 13 
setblock ~90 ~22 ~17 stone_brick_stairs 6  
fill ~90 ~22 ~18 ~95 ~22 ~18 stone 6  
fill ~90 ~22 ~19 ~95 ~22 ~19 stone 6  
fill ~90 ~22 ~20 ~95 ~22 ~20 stone 6 
setblock ~90 ~22 ~21 stone_brick_stairs 7  
fill ~91 ~22 ~4 ~94 ~22 ~4 iron_trapdoor 4  
fill ~91 ~22 ~5 ~94 ~22 ~5 stained_hardened_clay 14  
fill ~91 ~22 ~9 ~94 ~22 ~9 stone 6  
fill ~91 ~22 ~10 ~94 ~22 ~10 stone 6  
fill ~91 ~22 ~11 ~94 ~22 ~11 stone_slab 13  
fill ~91 ~22 ~15 ~94 ~22 ~15 stone_slab 13  
fill ~91 ~22 ~16 ~94 ~22 ~16 stone 6  
fill ~91 ~22 ~17 ~94 ~22 ~17 stone 6  
fill ~91 ~22 ~21 ~94 ~22 ~21 stained_hardened_clay 14 
setblock ~95 ~22 ~5 stone_brick_stairs 6 
setblock ~95 ~22 ~9 stone_brick_stairs 7 
setblock ~95 ~22 ~10 stone_slab 13 
setblock ~95 ~22 ~16 stone_slab 13 
setblock ~95 ~22 ~17 stone_brick_stairs 6 
setblock ~95 ~22 ~21 stone_brick_stairs 7 
setblock ~97 ~22 ~4 stone_slab 13 
setblock ~97 ~22 ~22 stone_slab 13 
setblock ~98 ~22 ~4 stone_brick_stairs 4  
fill ~98 ~22 ~5 ~98 ~21 ~5 stone 0  
fill ~98 ~22 ~21 ~98 ~21 ~21 stone 0 
setblock ~98 ~22 ~22 stone_brick_stairs 4  
fill ~99 ~22 ~4 ~99 ~24 ~4 stone 0  
fill ~99 ~22 ~22 ~99 ~24 ~22 stone 0  
fill ~100 ~22 ~4 ~100 ~23 ~4 monster_egg 0  
fill ~100 ~22 ~22 ~100 ~23 ~22 monster_egg 0  
fill ~102 ~22 ~4 ~103 ~22 ~4 stone 0  
fill ~102 ~22 ~22 ~103 ~22 ~22 stone 0  
fill ~103 ~22 ~5 ~104 ~22 ~5 stone 0  
fill ~103 ~22 ~6 ~106 ~22 ~6 stone 0  
fill ~103 ~22 ~20 ~106 ~22 ~20 stone 0  
fill ~103 ~22 ~21 ~104 ~22 ~21 stone 0 
setblock ~104 ~22 ~4 stone_slab 0 
setblock ~104 ~22 ~22 stone_slab 0  
fill ~105 ~22 ~3 ~108 ~22 ~3 stone_slab 5  
fill ~105 ~22 ~7 ~114 ~22 ~7 stone 0  
fill ~105 ~22 ~19 ~114 ~22 ~19 stone 0  
fill ~105 ~22 ~23 ~108 ~22 ~23 stone_slab 5 
setblock ~109 ~22 ~2 stone_slab 5 
setblock ~109 ~22 ~24 stone_slab 5  
fill ~110 ~22 ~2 ~112 ~22 ~2 stone_slab 0  
fill ~110 ~22 ~24 ~112 ~22 ~24 stone_slab 0  
fill ~113 ~22 ~2 ~117 ~22 ~2 stone_slab 5  
fill ~113 ~22 ~24 ~117 ~22 ~24 stone_slab 5  
fill ~115 ~22 ~13 ~115 ~27 ~13 stone 0  
fill ~118 ~22 ~2 ~120 ~22 ~2 stone_slab 0  
fill ~118 ~22 ~8 ~118 ~23 ~8 stone 6  
fill ~118 ~22 ~18 ~118 ~23 ~18 stone 6  
fill ~118 ~22 ~24 ~120 ~22 ~24 stone_slab 0 
setblock ~119 ~22 ~7 iron_trapdoor 6  
fill ~119 ~22 ~8 ~123 ~22 ~8 stone_brick_stairs 2  
fill ~119 ~22 ~18 ~123 ~22 ~18 stone_brick_stairs 3 
setblock ~119 ~22 ~19 iron_trapdoor 6 
setblock ~120 ~22 ~6 iron_trapdoor 4 
setblock ~120 ~22 ~7 dispenser 2 
setblock ~120 ~22 ~19 dispenser 3 
setblock ~120 ~22 ~20 iron_trapdoor 4  
fill ~121 ~22 ~2 ~126 ~22 ~2 stone_slab 5  
fill ~121 ~22 ~24 ~126 ~22 ~24 stone_slab 5 
setblock ~122 ~22 ~6 iron_trapdoor 4 
setblock ~122 ~22 ~7 dispenser 2 
setblock ~122 ~22 ~19 dispenser 3 
setblock ~122 ~22 ~20 iron_trapdoor 4 
setblock ~123 ~22 ~7 iron_trapdoor 7 
setblock ~123 ~22 ~19 iron_trapdoor 7  
fill ~124 ~22 ~8 ~124 ~23 ~8 stone 6  
fill ~124 ~22 ~18 ~124 ~23 ~18 stone 6  
fill ~126 ~22 ~3 ~126 ~22 ~10 stone_slab 5  
fill ~126 ~22 ~12 ~127 ~22 ~12 stone 0  
fill ~126 ~22 ~14 ~127 ~22 ~14 stone 0  
fill ~126 ~22 ~16 ~126 ~22 ~24 stone_slab 5  
fill ~127 ~22 ~10 ~132 ~22 ~10 stone 0  
fill ~127 ~22 ~16 ~132 ~22 ~16 stone 0  
fill ~128 ~22 ~2 ~128 ~22 ~4 cobblestone_wall 0 
setblock ~128 ~22 ~7 fence_gate 6  
fill ~128 ~22 ~13 ~128 ~23 ~13 stone 0 
setblock ~128 ~22 ~19 fence_gate 4  
fill ~128 ~22 ~22 ~128 ~22 ~24 cobblestone_wall 0 
setblock ~129 ~22 ~6 stone_slab 8  
fill ~129 ~22 ~7 ~129 ~22 ~8 cobblestone_wall 0  
fill ~129 ~22 ~18 ~129 ~22 ~19 cobblestone_wall 0 
setblock ~129 ~22 ~20 stone_slab 8  
fill ~130 ~22 ~2 ~130 ~22 ~4 cobblestone_wall 0 
setblock ~130 ~22 ~7 fence_gate 6 
setblock ~130 ~22 ~19 fence_gate 4  
fill ~130 ~22 ~22 ~130 ~22 ~24 cobblestone_wall 0  
fill ~132 ~22 ~2 ~136 ~22 ~2 stone_slab 5  
fill ~132 ~22 ~3 ~132 ~22 ~8 stone_slab 5  
fill ~132 ~22 ~18 ~132 ~22 ~24 stone_slab 5  
fill ~133 ~22 ~24 ~136 ~22 ~24 stone_slab 5  
fill ~136 ~22 ~5 ~143 ~22 ~5 stone 0  
fill ~136 ~22 ~21 ~143 ~22 ~21 stone 0  
fill ~140 ~22 ~8 ~140 ~23 ~8 stone 0  
fill ~140 ~22 ~18 ~140 ~23 ~18 stone 0  
fill ~141 ~22 ~7 ~141 ~23 ~7 stone 0  
fill ~141 ~22 ~19 ~141 ~23 ~19 stone 0  
fill ~142 ~22 ~6 ~142 ~26 ~6 stone 0  
fill ~142 ~22 ~20 ~142 ~26 ~20 stone 0 
setblock ~143 ~22 ~4 stone_slab 5 
setblock ~143 ~22 ~22 stone_slab 5  
fill ~144 ~22 ~3 ~163 ~22 ~3 stone_slab 5  
fill ~144 ~22 ~4 ~164 ~22 ~4 stone 0  
fill ~144 ~22 ~22 ~164 ~22 ~22 stone 0  
fill ~144 ~22 ~23 ~163 ~22 ~23 stone_slab 5  
fill ~168 ~22 ~9 ~168 ~25 ~9 stone 0  
fill ~168 ~22 ~10 ~168 ~26 ~10 double_stone_slab 14  
fill ~168 ~22 ~11 ~168 ~27 ~11 stone 0  
fill ~168 ~22 ~12 ~168 ~27 ~12 stone 0  
fill ~168 ~22 ~13 ~168 ~27 ~13 stone 0  
fill ~168 ~22 ~14 ~168 ~27 ~14 stone 0  
fill ~168 ~22 ~15 ~168 ~27 ~15 stone 0  
fill ~168 ~22 ~16 ~168 ~26 ~16 double_stone_slab 14  
fill ~168 ~22 ~17 ~168 ~25 ~17 stone 0  
fill ~170 ~22 ~12 ~170 ~22 ~14 stone 0  
fill ~171 ~22 ~3 ~175 ~22 ~3 stone_slab 0 
setblock ~171 ~22 ~11 iron_trapdoor 0 
setblock ~171 ~22 ~15 iron_trapdoor 0  
fill ~171 ~22 ~23 ~175 ~22 ~23 stone_slab 0 
setblock ~173 ~22 ~11 iron_trapdoor 0 
setblock ~173 ~22 ~15 iron_trapdoor 0  
fill ~175 ~22 ~4 ~181 ~22 ~4 stone_slab 0 
setblock ~175 ~22 ~11 iron_trapdoor 0 
setblock ~175 ~22 ~15 iron_trapdoor 0  
fill ~175 ~22 ~22 ~181 ~22 ~22 stone_slab 0 
setblock ~176 ~22 ~12 web 0 
setblock ~176 ~22 ~14 web 0 
setblock ~181 ~22 ~5 stone_slab 0 
setblock ~181 ~22 ~21 stone_slab 0 
setblock ~182 ~22 ~5 stone_brick_stairs 0 
setblock ~182 ~22 ~12 carpet 15 
setblock ~182 ~22 ~13 carpet 4 
setblock ~182 ~22 ~14 carpet 15 
setblock ~182 ~22 ~21 stone_brick_stairs 0  
fill ~183 ~22 ~5 ~187 ~22 ~5 stone_slab 5 
setblock ~183 ~22 ~10 carpet 4 
setblock ~183 ~22 ~11 carpet 15 
setblock ~183 ~22 ~12 carpet 4 
setblock ~183 ~22 ~13 stone_brick_stairs 0 
setblock ~183 ~22 ~14 carpet 4 
setblock ~183 ~22 ~15 carpet 15 
setblock ~183 ~22 ~16 carpet 4  
fill ~183 ~22 ~21 ~187 ~22 ~21 stone_slab 5 
setblock ~184 ~22 ~10 carpet 15 
setblock ~184 ~22 ~11 stone_brick_stairs 0 
setblock ~184 ~22 ~12 stone_slab 0  
fill ~184 ~22 ~13 ~185 ~22 ~13 stone 5 
setblock ~184 ~22 ~14 stone_slab 0 
setblock ~184 ~22 ~15 stone_brick_stairs 0 
setblock ~184 ~22 ~16 carpet 15 
setblock ~185 ~22 ~9 carpet 4 
setblock ~185 ~22 ~10 stone_brick_stairs 2  
fill ~185 ~22 ~11 ~189 ~22 ~11 stone 5  
fill ~185 ~22 ~12 ~185 ~22 ~11 stone 5  
fill ~185 ~22 ~14 ~185 ~22 ~15 stone 5 
setblock ~185 ~22 ~16 stone_brick_stairs 3 
setblock ~185 ~22 ~17 carpet 4 
setblock ~186 ~22 ~9 carpet 15 
setblock ~186 ~22 ~10 stone_slab 0  
fill ~186 ~22 ~12 ~188 ~22 ~12 iron_block 0  
fill ~186 ~22 ~13 ~188 ~22 ~13 iron_block 0  
fill ~186 ~22 ~14 ~188 ~22 ~14 iron_block 0  
fill ~186 ~22 ~15 ~189 ~22 ~15 stone 5 
setblock ~186 ~22 ~16 stone_slab 0 
setblock ~186 ~22 ~17 carpet 15 
setblock ~187 ~22 ~8 carpet 4 
setblock ~187 ~22 ~9 stone_brick_stairs 2 
setblock ~187 ~22 ~10 stone 5 
setblock ~187 ~22 ~16 stone 5 
setblock ~187 ~22 ~17 stone_brick_stairs 3 
setblock ~187 ~22 ~18 carpet 4  
fill ~188 ~22 ~6 ~191 ~22 ~6 stone_slab 5 
setblock ~188 ~22 ~9 carpet 15 
setblock ~188 ~22 ~10 stone_slab 0 
setblock ~188 ~22 ~16 stone_slab 0 
setblock ~188 ~22 ~17 carpet 15  
fill ~188 ~22 ~20 ~191 ~22 ~20 stone_slab 5 
setblock ~189 ~22 ~9 carpet 4 
setblock ~189 ~22 ~10 stone_brick_stairs 2  
fill ~189 ~22 ~12 ~191 ~22 ~12 stone 5  
fill ~189 ~22 ~13 ~190 ~22 ~13 stone 5  
fill ~189 ~22 ~14 ~191 ~22 ~14 stone 5 
setblock ~189 ~22 ~16 stone_brick_stairs 3 
setblock ~189 ~22 ~17 carpet 4 
setblock ~190 ~22 ~10 carpet 15 
setblock ~190 ~22 ~11 stone_brick_stairs 1 
setblock ~190 ~22 ~15 stone_brick_stairs 1 
setblock ~190 ~22 ~16 carpet 15 
setblock ~191 ~22 ~10 carpet 4 
setblock ~191 ~22 ~11 stone_slab 5 
setblock ~191 ~22 ~13 double_stone_slab 5 
setblock ~191 ~22 ~15 stone_slab 5 
setblock ~191 ~22 ~16 carpet 4  
fill ~192 ~22 ~7 ~195 ~22 ~7 stone 6 
setblock ~192 ~22 ~10 carpet 15 
setblock ~192 ~22 ~11 carpet 4 
setblock ~192 ~22 ~12 stone_slab 5 
setblock ~192 ~22 ~13 stone_brick_stairs 1 
setblock ~192 ~22 ~14 stone_slab 5 
setblock ~192 ~22 ~15 carpet 4 
setblock ~192 ~22 ~16 carpet 15  
fill ~192 ~22 ~19 ~195 ~22 ~19 stone 6  
fill ~193 ~22 ~6 ~195 ~22 ~6 stone_slab 5 
setblock ~193 ~22 ~12 carpet 15 
setblock ~193 ~22 ~13 carpet 4 
setblock ~193 ~22 ~14 carpet 15  
fill ~193 ~22 ~20 ~195 ~22 ~20 stone_slab 5 
setblock ~195 ~22 ~11 stone_slab 5 
setblock ~195 ~22 ~13 stone_slab 5 
setblock ~195 ~22 ~15 stone_slab 5  
fill ~196 ~22 ~7 ~198 ~22 ~7 stone_slab 5  
fill ~196 ~22 ~8 ~198 ~22 ~8 stone 6 
setblock ~196 ~22 ~10 stone_brick_stairs 2 
setblock ~196 ~22 ~11 double_stone_slab 5  
fill ~196 ~22 ~13 ~197 ~22 ~13 double_stone_slab 5 
setblock ~196 ~22 ~15 double_stone_slab 5 
setblock ~196 ~22 ~16 stone_brick_stairs 3  
fill ~196 ~22 ~18 ~198 ~22 ~18 stone 6  
fill ~196 ~22 ~19 ~198 ~22 ~19 stone_slab 5 
setblock ~197 ~22 ~11 stone_slab 5 
setblock ~197 ~22 ~12 stone_brick_stairs 1 
setblock ~197 ~22 ~14 stone_brick_stairs 1 
setblock ~197 ~22 ~15 stone_slab 5 
setblock ~198 ~22 ~13 stone_slab 5  
fill ~199 ~22 ~8 ~201 ~22 ~8 stone_slab 5  
fill ~199 ~22 ~9 ~201 ~22 ~9 stone 6  
fill ~199 ~22 ~17 ~201 ~22 ~17 stone 6  
fill ~199 ~22 ~18 ~201 ~22 ~18 stone_slab 5 
setblock ~201 ~22 ~10 stained_hardened_clay 9  
fill ~201 ~22 ~11 ~201 ~22 ~12 iron_bars 0 
setblock ~201 ~22 ~13 stone_brick_stairs 0  
fill ~201 ~22 ~14 ~203 ~22 ~14 iron_bars 0  
fill ~201 ~22 ~15 ~201 ~22 ~14 iron_bars 0 
setblock ~201 ~22 ~16 stained_hardened_clay 9  
fill ~202 ~22 ~9 ~204 ~22 ~9 stone_slab 5  
fill ~202 ~22 ~10 ~204 ~22 ~10 stone 6  
fill ~202 ~22 ~12 ~203 ~22 ~12 iron_bars 0 
setblock ~202 ~22 ~13 double_stone_slab 5  
fill ~202 ~22 ~16 ~204 ~22 ~16 stone 6  
fill ~202 ~22 ~17 ~204 ~22 ~17 stone_slab 5  
fill ~203 ~22 ~11 ~204 ~22 ~11 stained_hardened_clay 9  
fill ~203 ~22 ~15 ~204 ~22 ~15 stained_hardened_clay 9  
fill ~204 ~22 ~12 ~205 ~22 ~12 stained_hardened_clay 9  
fill ~204 ~22 ~13 ~205 ~22 ~13 iron_bars 0  
fill ~204 ~22 ~14 ~205 ~22 ~14 stained_hardened_clay 9  
fill ~205 ~22 ~10 ~205 ~23 ~10 stone_slab 13 
setblock ~205 ~22 ~11 stone 0 
setblock ~205 ~22 ~15 stone 0  
fill ~205 ~22 ~16 ~205 ~23 ~16 stone_slab 13 
setblock ~206 ~22 ~11 stone_slab 13 
setblock ~206 ~22 ~12 stone 0 
setblock ~206 ~22 ~13 stained_hardened_clay 9 
setblock ~206 ~22 ~14 stone 0 
setblock ~206 ~22 ~15 stone_slab 13  
fill ~207 ~22 ~12 ~208 ~22 ~12 stone_slab 13  
fill ~207 ~22 ~13 ~208 ~22 ~13 stone 0  
fill ~207 ~22 ~14 ~208 ~22 ~14 stone_slab 13 
setblock ~209 ~22 ~13 stone_slab 13  
fill ~4 ~23 ~14 ~4 ~24 ~14 stained_glass_pane 15 
setblock ~10 ~23 ~13 stone_brick_stairs 4 
setblock ~11 ~23 ~12 stone_slab 8  
fill ~11 ~23 ~13 ~12 ~23 ~13 stained_hardened_clay 9 
setblock ~11 ~23 ~14 stone_slab 8 
setblock ~12 ~23 ~12 stone_brick_stairs 4 
setblock ~12 ~23 ~14 stone_brick_stairs 4  
fill ~13 ~23 ~11 ~15 ~23 ~11 stone_slab 8  
fill ~13 ~23 ~12 ~15 ~23 ~12 stained_hardened_clay 9 
setblock ~13 ~23 ~13 stonebrick 0  
fill ~13 ~23 ~14 ~15 ~23 ~14 stained_hardened_clay 9  
fill ~13 ~23 ~15 ~15 ~23 ~15 stone_slab 8  
fill ~14 ~23 ~13 ~29 ~23 ~13 carpet 7  
fill ~16 ~23 ~11 ~25 ~23 ~11 stained_hardened_clay 9  
fill ~16 ~23 ~12 ~17 ~23 ~12 anvil 2  
fill ~16 ~23 ~14 ~17 ~23 ~14 anvil 2  
fill ~16 ~23 ~15 ~25 ~23 ~15 stained_hardened_clay 9 
setblock ~18 ~23 ~10 stone_slab 8 
setblock ~18 ~23 ~12 stone_brick_stairs 3 
setblock ~18 ~23 ~14 stone_brick_stairs 2 
setblock ~18 ~23 ~16 stone_slab 8  
fill ~19 ~23 ~10 ~21 ~23 ~10 stone_slab 5  
fill ~19 ~23 ~16 ~21 ~23 ~16 stone_slab 5 
setblock ~20 ~23 ~12 stone_brick_stairs 3 
setblock ~20 ~23 ~14 stone_brick_stairs 2  
fill ~21 ~23 ~12 ~22 ~23 ~12 anvil 2  
fill ~21 ~23 ~14 ~22 ~23 ~14 anvil 2 
setblock ~22 ~23 ~10 stone_slab 8 
setblock ~22 ~23 ~16 stone_slab 8 
setblock ~23 ~23 ~10 iron_trapdoor 7  
fill ~23 ~23 ~12 ~24 ~23 ~12 stone_brick_stairs 3  
fill ~23 ~23 ~14 ~24 ~23 ~14 stone_brick_stairs 2 
setblock ~23 ~23 ~16 iron_trapdoor 7 
setblock ~24 ~23 ~10 wool 0 
setblock ~24 ~23 ~16 wool 0 
setblock ~25 ~23 ~10 stone_slab 8 
setblock ~25 ~23 ~12 anvil 3 
setblock ~25 ~23 ~14 anvil 3 
setblock ~25 ~23 ~16 stone_slab 8  
fill ~26 ~23 ~11 ~26 ~24 ~11 glass 0  
fill ~26 ~23 ~12 ~28 ~23 ~12 carpet 7  
fill ~26 ~23 ~14 ~28 ~23 ~14 carpet 7  
fill ~26 ~23 ~15 ~26 ~24 ~15 glass 0  
fill ~27 ~23 ~11 ~27 ~24 ~11 stained_glass_pane 15  
fill ~27 ~23 ~15 ~27 ~24 ~15 stained_glass_pane 15  
fill ~28 ~23 ~11 ~30 ~23 ~11 stained_hardened_clay 9  
fill ~28 ~23 ~15 ~30 ~23 ~15 stained_hardened_clay 9 
setblock ~29 ~23 ~10 redstone_torch 4 
setblock ~29 ~23 ~12 anvil 0 
setblock ~29 ~23 ~14 anvil 0 
setblock ~29 ~23 ~16 redstone_torch 3 
setblock ~30 ~23 ~12 daylight_detector_inverted 9 
setblock ~30 ~23 ~13 stone_brick_stairs 0 
setblock ~30 ~23 ~14 daylight_detector_inverted 9 
setblock ~31 ~23 ~11 stone_brick_stairs 5 
setblock ~31 ~23 ~12 stone_brick_stairs 0  
fill ~31 ~23 ~13 ~32 ~23 ~13 stone 6 
setblock ~31 ~23 ~14 stone_brick_stairs 0 
setblock ~31 ~23 ~15 stone_brick_stairs 5 
setblock ~32 ~23 ~11 stone_slab 8 
setblock ~32 ~23 ~15 stone_slab 8 
setblock ~33 ~23 ~11 stone_brick_stairs 6 
setblock ~33 ~23 ~13 stone_brick_stairs 1 
setblock ~33 ~23 ~15 stone_brick_stairs 7 
setblock ~34 ~23 ~12 glass 0 
setblock ~34 ~23 ~13 stone_brick_stairs 5 
setblock ~34 ~23 ~14 glass 0 
setblock ~40 ~23 ~8 stone_slab 0 
setblock ~40 ~23 ~9 stone_brick_stairs 7 
setblock ~40 ~23 ~17 stone_brick_stairs 6 
setblock ~40 ~23 ~18 stone_slab 0  
fill ~41 ~23 ~9 ~41 ~24 ~9 stone 0  
fill ~41 ~23 ~17 ~41 ~24 ~17 stone 0  
fill ~43 ~23 ~4 ~50 ~23 ~4 stone 0  
fill ~43 ~23 ~22 ~50 ~23 ~22 stone 0 
setblock ~50 ~23 ~5 monster_egg 0 
setblock ~50 ~23 ~21 monster_egg 0 
setblock ~51 ~23 ~4 stone_brick_stairs 5 
setblock ~51 ~23 ~22 stone_brick_stairs 5  
fill ~52 ~23 ~4 ~57 ~23 ~4 stone_slab 13  
fill ~52 ~23 ~6 ~57 ~23 ~6 stone_slab 5  
fill ~52 ~23 ~7 ~57 ~23 ~7 stone_slab 5  
fill ~52 ~23 ~8 ~57 ~23 ~8 stone_slab 5  
fill ~52 ~23 ~18 ~57 ~23 ~18 stone_slab 5  
fill ~52 ~23 ~19 ~57 ~23 ~19 stone_slab 5  
fill ~52 ~23 ~20 ~57 ~23 ~20 stone_slab 5  
fill ~52 ~23 ~22 ~57 ~23 ~22 stone_slab 13  
fill ~53 ~23 ~5 ~56 ~23 ~5 stone_slab 5  
fill ~53 ~23 ~9 ~56 ~23 ~9 stone_slab 5  
fill ~53 ~23 ~10 ~56 ~23 ~10 stone_slab 5  
fill ~53 ~23 ~16 ~56 ~23 ~16 stone_slab 5  
fill ~53 ~23 ~17 ~56 ~23 ~17 stone_slab 5  
fill ~53 ~23 ~21 ~56 ~23 ~21 stone_slab 5 
setblock ~58 ~23 ~4 stone_brick_stairs 4 
setblock ~58 ~23 ~22 stone_brick_stairs 4  
fill ~59 ~23 ~4 ~69 ~23 ~4 stone 0 
setblock ~59 ~23 ~5 monster_egg 0 
setblock ~59 ~23 ~21 monster_egg 0  
fill ~59 ~23 ~22 ~69 ~23 ~22 stone 0  
fill ~63 ~23 ~3 ~65 ~23 ~3 iron_bars 0  
fill ~63 ~23 ~23 ~65 ~23 ~23 iron_bars 0 
setblock ~69 ~23 ~5 monster_egg 0 
setblock ~69 ~23 ~21 monster_egg 0 
setblock ~70 ~23 ~4 stone_brick_stairs 5 
setblock ~70 ~23 ~22 stone_brick_stairs 5  
fill ~71 ~23 ~4 ~76 ~23 ~4 stone_slab 13  
fill ~71 ~23 ~6 ~76 ~23 ~6 stone_slab 5  
fill ~71 ~23 ~7 ~76 ~23 ~7 stone_slab 5  
fill ~71 ~23 ~8 ~76 ~23 ~8 stone_slab 5  
fill ~71 ~23 ~18 ~76 ~23 ~18 stone_slab 5  
fill ~71 ~23 ~19 ~76 ~23 ~19 stone_slab 5  
fill ~71 ~23 ~20 ~76 ~23 ~20 stone_slab 5  
fill ~71 ~23 ~22 ~76 ~23 ~22 stone_slab 13  
fill ~72 ~23 ~5 ~75 ~23 ~5 stone_slab 5  
fill ~72 ~23 ~9 ~75 ~23 ~9 stone_slab 5  
fill ~72 ~23 ~10 ~75 ~23 ~10 stone_slab 5  
fill ~72 ~23 ~16 ~75 ~23 ~16 stone_slab 5  
fill ~72 ~23 ~17 ~75 ~23 ~17 stone_slab 5  
fill ~72 ~23 ~21 ~75 ~23 ~21 stone_slab 5 
setblock ~77 ~23 ~4 stone_brick_stairs 4 
setblock ~77 ~23 ~22 stone_brick_stairs 4  
fill ~78 ~23 ~4 ~88 ~23 ~4 stone 0  
fill ~78 ~23 ~5 ~78 ~23 ~4 stone 0  
fill ~78 ~23 ~11 ~78 ~25 ~11 wool 0  
fill ~78 ~23 ~15 ~78 ~25 ~15 wool 0  
fill ~78 ~23 ~21 ~78 ~23 ~22 stone 0  
fill ~79 ~23 ~22 ~88 ~23 ~22 stone 0  
fill ~82 ~23 ~3 ~84 ~23 ~3 iron_bars 0  
fill ~82 ~23 ~23 ~84 ~23 ~23 iron_bars 0 
setblock ~88 ~23 ~5 monster_egg 0 
setblock ~88 ~23 ~21 monster_egg 0 
setblock ~89 ~23 ~4 stone_brick_stairs 5 
setblock ~89 ~23 ~22 stone_brick_stairs 5  
fill ~90 ~23 ~4 ~95 ~23 ~4 stone_slab 13  
fill ~90 ~23 ~6 ~95 ~23 ~6 stone_slab 5  
fill ~90 ~23 ~7 ~95 ~23 ~7 stone_slab 5  
fill ~90 ~23 ~8 ~95 ~23 ~8 stone_slab 5  
fill ~90 ~23 ~18 ~95 ~23 ~18 stone_slab 5  
fill ~90 ~23 ~19 ~95 ~23 ~19 stone_slab 5  
fill ~90 ~23 ~20 ~95 ~23 ~20 stone_slab 5  
fill ~90 ~23 ~22 ~95 ~23 ~22 stone_slab 13  
fill ~91 ~23 ~5 ~94 ~23 ~5 stone_slab 5  
fill ~91 ~23 ~9 ~94 ~23 ~9 stone_slab 5  
fill ~91 ~23 ~10 ~94 ~23 ~10 stone_slab 5  
fill ~91 ~23 ~16 ~94 ~23 ~16 stone_slab 5  
fill ~91 ~23 ~17 ~94 ~23 ~17 stone_slab 5  
fill ~91 ~23 ~21 ~94 ~23 ~21 stone_slab 5 
setblock ~96 ~23 ~4 stone_brick_stairs 4 
setblock ~96 ~23 ~22 stone_brick_stairs 4  
fill ~97 ~23 ~4 ~99 ~23 ~4 stone 0  
fill ~97 ~23 ~5 ~97 ~23 ~4 stone 0  
fill ~97 ~23 ~21 ~97 ~23 ~22 stone 0  
fill ~98 ~23 ~22 ~98 ~24 ~22 stone 0  
fill ~101 ~23 ~4 ~103 ~23 ~4 stone 0  
fill ~101 ~23 ~22 ~103 ~23 ~22 stone 0  
fill ~103 ~23 ~5 ~104 ~23 ~5 stone 0  
fill ~103 ~23 ~6 ~106 ~23 ~6 stone 0  
fill ~103 ~23 ~20 ~106 ~23 ~20 stone 0  
fill ~103 ~23 ~21 ~104 ~23 ~21 stone 0  
fill ~105 ~23 ~7 ~114 ~23 ~7 stone 0   
fill ~105 ~23 ~19 ~114 ~23 ~19 stone 0  
fill ~116 ~23 ~12 ~116 ~24 ~12 stone 6  
fill ~116 ~23 ~14 ~116 ~24 ~14 stone 6  
fill ~119 ~23 ~8 ~124 ~23 ~8 stone 6  
fill ~119 ~23 ~18 ~124 ~23 ~18 stone 6 
setblock ~120 ~23 ~7 anvil 1 
setblock ~120 ~23 ~19 anvil 1 
setblock ~122 ~23 ~7 anvil 1 
setblock ~122 ~23 ~19 anvil 1  
fill ~126 ~23 ~12 ~127 ~23 ~12 stone 0  
fill ~126 ~23 ~14 ~127 ~23 ~14 stone 0  
fill ~127 ~23 ~10 ~132 ~23 ~10 stone 0  
fill ~127 ~23 ~16 ~132 ~23 ~16 stone 0 
setblock ~128 ~23 ~4 carpet 7 
setblock ~128 ~23 ~5 anvil 0 
setblock ~128 ~23 ~6 cobblestone_wall 0 
setblock ~128 ~23 ~20 cobblestone_wall 0 
setblock ~128 ~23 ~21 anvil 0 
setblock ~128 ~23 ~22 carpet 7 
setblock ~129 ~23 ~8 stone_brick_stairs 2 
setblock ~129 ~23 ~18 stone_brick_stairs 3 
setblock ~130 ~23 ~4 carpet 7 
setblock ~130 ~23 ~5 anvil 0 
setblock ~130 ~23 ~6 cobblestone_wall 0 
setblock ~130 ~23 ~20 cobblestone_wall 0 
setblock ~130 ~23 ~21 anvil 0 
setblock ~130 ~23 ~22 carpet 7  
fill ~136 ~23 ~5 ~143 ~23 ~5 stone 0  
fill ~136 ~23 ~21 ~143 ~23 ~21 stone 0  
fill ~144 ~23 ~4 ~164 ~23 ~4 stone 0  
fill ~144 ~23 ~22 ~164 ~23 ~22 stone 0  
fill ~162 ~23 ~5 ~164 ~23 ~5 stained_hardened_clay 9  
fill ~162 ~23 ~21 ~164 ~23 ~21 stained_hardened_clay 9  
fill ~163 ~23 ~6 ~165 ~23 ~6 stained_hardened_clay 9  
fill ~163 ~23 ~20 ~165 ~23 ~20 stained_hardened_clay 9  
fill ~164 ~23 ~7 ~166 ~23 ~7 stained_hardened_clay 9  
fill ~164 ~23 ~19 ~166 ~23 ~19 stained_hardened_clay 9  
fill ~165 ~23 ~8 ~167 ~23 ~8 stained_hardened_clay 9  
fill ~165 ~23 ~18 ~167 ~23 ~18 stained_hardened_clay 9  
fill ~169 ~23 ~12 ~169 ~27 ~12 stone 0  
fill ~169 ~23 ~13 ~169 ~27 ~13 stone 0  
fill ~169 ~23 ~14 ~169 ~27 ~14 stone 0  
fill ~175 ~23 ~11 ~175 ~25 ~11 web 0  
fill ~175 ~23 ~15 ~175 ~25 ~15 web 0  
fill ~184 ~23 ~13 ~185 ~23 ~13 stone_slab 5  
fill ~185 ~23 ~11 ~189 ~23 ~11 stone_slab 5  
fill ~185 ~23 ~12 ~185 ~23 ~11 stone_slab 5  
fill ~185 ~23 ~14 ~185 ~23 ~15 stone_slab 5  
fill ~186 ~23 ~12 ~187 ~23 ~12 anvil 3 
setblock ~186 ~23 ~13 stone_slab 13  
fill ~186 ~23 ~14 ~187 ~23 ~14 anvil 3  
fill ~186 ~23 ~15 ~189 ~23 ~15 stone_slab 5 
setblock ~187 ~23 ~10 stone_slab 5  
fill ~187 ~23 ~13 ~190 ~23 ~13 double_stone_slab 5 
setblock ~187 ~23 ~16 stone_slab 5 
setblock ~188 ~23 ~12 stone_stairs 5 
setblock ~188 ~23 ~14 stone_stairs 5  
fill ~189 ~23 ~12 ~190 ~23 ~12 stone_slab 5  
fill ~189 ~23 ~14 ~190 ~23 ~14 stone_slab 5 
setblock ~191 ~23 ~13 stone_slab 5 
setblock ~196 ~23 ~11 stone_slab 5 
setblock ~196 ~23 ~15 stone_slab 5 
setblock ~197 ~23 ~12 stone_slab 5 
setblock ~197 ~23 ~13 stone_brick_stairs 1 
setblock ~197 ~23 ~14 stone_slab 5  
fill ~199 ~23 ~9 ~202 ~23 ~9 stone_slab 5  
fill ~199 ~23 ~17 ~202 ~23 ~17 stone_slab 5  
fill ~202 ~23 ~10 ~204 ~23 ~10 stone_slab 5  
fill ~202 ~23 ~16 ~204 ~23 ~16 stone_slab 5 
setblock ~204 ~23 ~11 stone_brick_stairs 0 
setblock ~204 ~23 ~12 stone_brick_stairs 2  
fill ~204 ~23 ~13 ~205 ~23 ~13 stone_slab 13 
setblock ~204 ~23 ~14 stone_brick_stairs 3 
setblock ~204 ~23 ~15 stone_brick_stairs 0  
fill ~205 ~23 ~11 ~206 ~23 ~11 stone 6 
setblock ~205 ~23 ~12 stone_slab 5 
setblock ~205 ~23 ~14 stone_slab 5  
fill ~205 ~23 ~15 ~206 ~23 ~15 stone 6 
setblock ~206 ~23 ~12 stained_hardened_clay 9 
setblock ~206 ~23 ~13 stone_brick_stairs 1 
setblock ~206 ~23 ~14 stained_hardened_clay 9  
fill ~207 ~23 ~12 ~208 ~23 ~12 stone 6  
fill ~207 ~23 ~13 ~208 ~23 ~13 stained_hardened_clay 9  
fill ~207 ~23 ~14 ~208 ~23 ~14 stone 6  
fill ~209 ~23 ~13 ~210 ~23 ~13 stone 6  
fill ~2 ~24 ~11 ~2 ~24 ~12 wool 0  
fill ~2 ~24 ~14 ~2 ~24 ~15 wool 0  
fill ~3 ~24 ~14 ~3 ~25 ~14 stained_glass_pane 15 
setblock ~6 ~24 ~13 stone_brick_stairs 4 
setblock ~7 ~24 ~12 stone_slab 8  
fill ~7 ~24 ~13 ~8 ~24 ~13 stained_hardened_clay 9 
setblock ~7 ~24 ~14 stone_slab 8 
setblock ~8 ~24 ~12 stone_brick_stairs 4 
setblock ~8 ~24 ~14 stone_brick_stairs 4  
fill ~9 ~24 ~12 ~12 ~24 ~12 stained_hardened_clay 9  
fill ~9 ~24 ~13 ~9 ~25 ~13 stonebrick 0  
fill ~9 ~24 ~14 ~12 ~24 ~14 stained_hardened_clay 9 
setblock ~10 ~24 ~13 stone_brick_stairs 1 
setblock ~11 ~24 ~11 stone_brick_stairs 4 
setblock ~11 ~24 ~15 stone_brick_stairs 4  
fill ~12 ~24 ~11 ~18 ~24 ~11 stained_hardened_clay 9  
fill ~12 ~24 ~15 ~18 ~24 ~15 stained_hardened_clay 9 
setblock ~13 ~24 ~12 beacon 0 
setblock ~13 ~24 ~14 beacon 0 
setblock ~14 ~24 ~12 anvil 2 
setblock ~14 ~24 ~14 anvil 2 
setblock ~15 ~24 ~12 ladder 3 
setblock ~15 ~24 ~14 ladder 2 
setblock ~17 ~24 ~10 iron_trapdoor 7 
setblock ~17 ~24 ~16 iron_trapdoor 7 
setblock ~18 ~24 ~10 cobblestone_wall 0 
setblock ~18 ~24 ~16 cobblestone_wall 0  
fill ~19 ~24 ~11 ~20 ~24 ~11 stained_glass_pane 15 
setblock ~19 ~24 ~12 iron_bars 0 
