setblock ~20~5~0 minecraft:wall_banner 4
setblock ~20~7~0 minecraft:wall_banner 4
setblock ~20~9~0 minecraft:wall_banner 4
setblock ~20~11~0 minecraft:wall_banner 4
setblock ~20~13~0 minecraft:wall_banner 4
setblock ~20~15~0 minecraft:wall_banner 4
setblock ~20~17~0 minecraft:wall_banner 4
fill ~21~4~0 ~21~17~0 minecraft:wool 4
setblock ~22~7~0 minecraft:wall_banner 5
setblock ~22~9~0 minecraft:wall_banner 5
setblock ~22~11~0 minecraft:wall_banner 5
setblock ~22~13~0 minecraft:wall_banner 5
setblock ~22~15~0 minecraft:wall_banner 5
setblock ~22~17~0 minecraft:wall_banner 5
setblock ~21~3~1 minecraft:wool 4
setblock ~21~4~1 minecraft:fence 1
fill ~21~17~1 ~21~17~2 minecraft:fence 1
fill ~16~0~2 ~29~5~5 minecraft:fence 0
fill ~16~6~2 ~29~6~3 minecraft:fence 0
fill ~16~7~2 ~29~15~2 minecraft:fence 0
fill ~20~16~2 ~23~16~3 minecraft:fence 0
fill ~13~5~3 ~15~13~3 minecraft:fence 0
fill ~14~0~3 ~15~4~7 minecraft:fence 0
fill ~15~14~3 ~17~14~3 minecraft:fence 0
fill ~16~7~3 ~16~13~3 minecraft:fence 0
fill ~16~15~3 ~29~15~3 minecraft:fence 0
fill ~17~7~3 ~19~7~3 minecraft:wool 0
fill ~17~8~3 ~19~8~3 minecraft:fence 1
fill ~17~16~3 ~19~16~3 minecraft:wool 0
fill ~17~17~3 ~19~17~3 minecraft:fence 1
fill ~19~9~3 ~26~9~3 minecraft:fence 1
fill ~19~13~3 ~19~14~7 minecraft:fence 0
fill ~19~18~3 ~24~18~3 minecraft:fence 1
fill ~20~7~3 ~25~7~5 minecraft:fence 0
fill ~20~8~3 ~25~8~3 minecraft:wool 0
fill ~20~14~3 ~31~14~3 minecraft:fence 0
fill ~20~17~3 ~23~17~3 minecraft:wool 0
fill ~24~16~3 ~26~16~3 minecraft:wool 0
fill ~24~17~3 ~26~17~3 minecraft:fence 1
fill ~26~7~3 ~28~7~3 minecraft:wool 0
fill ~26~8~3 ~28~8~3 minecraft:fence 1
setblock ~27~9~3 minecraft:fence 0
fill ~29~7~3 ~32~13~3 minecraft:fence 0
fill ~30~0~3 ~32~4~7 minecraft:fence 0
fill ~30~5~3 ~32~6~3 minecraft:fence 0
fill ~11~0~4 ~13~2~8 minecraft:fence 0
fill ~11~3~4 ~13~3~7 minecraft:fence 0
fill ~11~4~4 ~13~4~5 minecraft:fence 0
fill ~11~5~4 ~13~13~4 minecraft:fence 0
fill ~14~5~4 ~14~5~5 minecraft:wool 0
fill ~14~6~4 ~14~6~5 minecraft:fence 1
fill ~14~7~4 ~16~7~4 minecraft:fence 1
setblock ~14~13~4 minecraft:fence 0
fill ~14~14~4 ~14~14~5 minecraft:wool 0
fill ~14~15~4 ~14~15~5 minecraft:fence 1
fill ~14~16~4 ~16~16~4 minecraft:fence 1
fill ~15~5~4 ~15~5~7 minecraft:fence 0
fill ~15~6~4 ~16~6~4 minecraft:wool 0
fill ~15~14~4 ~16~14~4 minecraft:fence 0
fill ~15~15~4 ~16~15~4 minecraft:wool 0
fill ~16~8~4 ~17~8~4 minecraft:fence 1
fill ~16~17~4 ~17~17~4 minecraft:fence 1
fill ~17~6~4 ~28~6~5 minecraft:fence 0
setblock ~17~7~4 minecraft:wool 0
setblock ~17~16~4 minecraft:wool 0
fill ~18~7~4 ~19~7~4 minecraft:planks 0
setblock ~18~8~4 minecraft:rail 6
fill ~18~16~4 ~18~16~5 minecraft:planks 0
setblock ~18~17~4 minecraft:rail 6
setblock ~19~8~4 minecraft:golden_rail 2
fill ~19~15~4 ~26~15~6 minecraft:fence 0
setblock ~19~16~4 minecraft:redstone_block
setblock ~19~17~4 minecraft:golden_rail 2
setblock ~20~8~4 minecraft:redstone_block
fill ~20~9~4 ~21~9~4 minecraft:golden_rail 1
fill ~20~14~4 ~28~14~6 minecraft:fence 0
fill ~20~17~4 ~22~17~4 minecraft:planks 0
setblock ~20~18~4 minecraft:golden_rail 1
fill ~21~8~4 ~24~8~4 minecraft:planks 0
fill ~21~18~4 ~22~18~4 minecraft:rail 1
fill ~22~9~4 ~24~9~4 minecraft:rail 1
setblock ~23~16~4 minecraft:fence 0
setblock ~23~17~4 minecraft:redstone_block
setblock ~23~18~4 minecraft:golden_rail 1
fill ~24~16~4 ~25~16~4 minecraft:planks 0
setblock ~24~17~4 minecraft:golden_rail 3
setblock ~25~8~4 minecraft:redstone_block
setblock ~25~9~4 minecraft:golden_rail 1
setblock ~25~17~4 minecraft:rail 7
fill ~26~7~4 ~27~7~4 minecraft:planks 0
setblock ~26~8~4 minecraft:golden_rail 3
setblock ~26~16~4 minecraft:wool 0
fill ~26~17~4 ~27~17~4 minecraft:fence 1
setblock ~27~8~4 minecraft:rail 7
fill ~27~15~4 ~28~15~4 minecraft:wool 0
fill ~27~16~4 ~29~16~4 minecraft:fence 1
setblock ~28~7~4 minecraft:wool 0
fill ~28~8~4 ~29~8~4 minecraft:fence 1
fill ~28~13~4 ~34~13~5 minecraft:fence 0
fill ~29~6~4 ~30~6~4 minecraft:wool 0
fill ~29~7~4 ~31~7~4 minecraft:fence 1
fill ~29~12~4 ~30~12~8 minecraft:fence 0
fill ~29~14~4 ~29~14~5 minecraft:wool 0
fill ~29~15~4 ~29~15~5 minecraft:fence 1
fill ~30~5~4 ~30~5~9 minecraft:fence 0
fill ~30~14~4 ~31~14~4 minecraft:fence 0
fill ~31~5~4 ~31~5~5 minecraft:wool 0
fill ~31~6~4 ~31~6~5 minecraft:fence 1
fill ~32~5~4 ~34~12~4 minecraft:fence 0
fill ~33~0~4 ~34~3~8 minecraft:fence 0
fill ~33~4~4 ~34~4~5 minecraft:fence 0
fill ~7~0~5 ~9~0~21 minecraft:stone 0
fill ~7~1~5 ~7~1~11 minecraft:iron_bars
fill ~9~1~5 ~9~1~11 minecraft:iron_bars
fill ~9~3~5 ~10~3~8 minecraft:fence 0
fill ~9~4~5 ~10~13~5 minecraft:fence 0
fill ~10~0~5 ~10~2~6 minecraft:fence 0
fill ~11~5~5 ~11~13~5 minecraft:fence 0
fill ~12~5~5 ~13~5~5 minecraft:wool 0
fill ~12~6~5 ~13~6~5 minecraft:fence 1
fill ~12~13~5 ~13~13~6 minecraft:fence 0
fill ~12~14~5 ~13~14~5 minecraft:wool 0
fill ~12~15~5 ~13~15~5 minecraft:fence 1
setblock ~13~7~5 minecraft:fence 0
fill ~15~6~5 ~15~6~6 minecraft:planks 0
setblock ~15~7~5 minecraft:rail 6
fill ~15~15~5 ~15~15~6 minecraft:planks 0
setblock ~15~16~5 minecraft:rail 6
setblock ~16~6~5 minecraft:redstone_block
setblock ~16~7~5 minecraft:golden_rail 2
setblock ~16~15~5 minecraft:redstone_block
setblock ~16~16~5 minecraft:golden_rail 2
fill ~17~7~5 ~18~7~5 minecraft:planks 0
setblock ~17~8~5 minecraft:golden_rail 1
setblock ~17~16~5 minecraft:planks 0
setblock ~17~17~5 minecraft:rail 1
setblock ~18~8~5 minecraft:rail 8
setblock ~18~17~5 minecraft:rail 8
fill ~19~7~5 ~19~7~6 minecraft:wool 0
fill ~19~8~5 ~19~8~6 minecraft:fence 1
fill ~19~9~5 ~26~9~5 minecraft:fence 1
fill ~19~16~5 ~19~16~6 minecraft:wool 0
fill ~19~17~5 ~19~17~6 minecraft:fence 1
fill ~19~18~5 ~24~18~5 minecraft:fence 1
fill ~20~8~5 ~25~8~5 minecraft:wool 0
fill ~20~16~5 ~21~16~6 minecraft:fence 0
fill ~20~17~5 ~23~17~5 minecraft:wool 0
fill ~24~16~5 ~24~16~6 minecraft:wool 0
fill ~24~17~5 ~24~17~6 minecraft:fence 1
fill ~25~16~5 ~26~16~5 minecraft:planks 0
setblock ~25~17~5 minecraft:rail 9
fill ~26~7~5 ~26~7~6 minecraft:wool 0
fill ~26~8~5 ~26~8~6 minecraft:fence 1
setblock ~26~17~5 minecraft:rail 1
fill ~27~7~5 ~28~7~5 minecraft:planks 0
setblock ~27~8~5 minecraft:rail 9
fill ~27~15~5 ~28~15~5 minecraft:planks 0
setblock ~27~16~5 minecraft:rail 3
setblock ~28~8~5 minecraft:rail 1
setblock ~28~16~5 minecraft:rail 7
fill ~29~6~5 ~30~6~5 minecraft:planks 0
setblock ~29~7~5 minecraft:rail 3
setblock ~30~7~5 minecraft:rail 7
fill ~30~14~5 ~31~14~5 minecraft:wool 0
fill ~30~15~5 ~31~15~5 minecraft:fence 1
fill ~32~5~5 ~33~5~5 minecraft:wool 0
fill ~32~6~5 ~33~6~5 minecraft:fence 1
fill ~34~5~5 ~34~12~5 minecraft:fence 0
fill ~8~4~6 ~9~13~6 minecraft:fence 0
fill ~10~4~6 ~11~4~6 minecraft:wool 0
fill ~10~5~6 ~11~5~6 minecraft:fence 1
fill ~10~10~6 ~10~10~13 minecraft:fence 0
fill ~10~11~6 ~10~12~7 minecraft:fence 0
fill ~10~13~6 ~11~13~6 minecraft:wool 0
fill ~10~14~6 ~11~14~6 minecraft:fence 1
fill ~11~6~6 ~12~6~6 minecraft:fence 1
fill ~11~15~6 ~12~15~6 minecraft:fence 1
fill ~12~4~6 ~13~4~6 minecraft:fence 0
setblock ~12~5~6 minecraft:wool 0
setblock ~12~14~6 minecraft:wool 0
fill ~13~5~6 ~13~5~7 minecraft:planks 0
setblock ~13~6~6 minecraft:rail 6
fill ~13~14~6 ~13~14~7 minecraft:planks 0
setblock ~13~15~6 minecraft:rail 6
setblock ~14~5~6 minecraft:redstone_block
setblock ~14~6~6 minecraft:golden_rail 2
setblock ~14~14~6 minecraft:redstone_block
setblock ~14~15~6 minecraft:golden_rail 2
setblock ~15~7~6 minecraft:rail 8
setblock ~15~16~6 minecraft:rail 8
fill ~16~0~6 ~17~5~6 minecraft:fence 0
fill ~16~6~6 ~16~6~7 minecraft:wool 0
fill ~16~7~6 ~16~7~7 minecraft:fence 1
fill ~16~8~6 ~18~8~6 minecraft:fence 1
fill ~16~15~6 ~16~15~7 minecraft:wool 0
fill ~16~16~6 ~16~16~7 minecraft:fence 1
fill ~16~17~6 ~18~17~6 minecraft:fence 1
fill ~17~6~6 ~18~6~6 minecraft:fence 0
fill ~17~7~6 ~18~7~6 minecraft:wool 0
fill ~17~16~6 ~18~16~6 minecraft:wool 0
fill ~18~0~6 ~27~0~6 minecraft:wool 0
fill ~18~1~6 ~18~5~6 minecraft:fence 0
fill ~20~7~6 ~20~13~7 minecraft:fence 0
fill ~21~8~6 ~25~13~6 minecraft:fence 0
fill ~22~16~6 ~23~16~6 minecraft:fence 0
fill ~25~7~6 ~25~7~7 minecraft:fence 0
fill ~25~16~6 ~26~16~6 minecraft:wool 0
fill ~25~17~6 ~27~17~6 minecraft:fence 1
fill ~27~1~6 ~29~5~6 minecraft:fence 0
fill ~27~6~6 ~28~6~6 minecraft:fence 0
fill ~27~7~6 ~28~7~6 minecraft:wool 0
fill ~27~8~6 ~29~8~6 minecraft:fence 1
fill ~27~15~6 ~27~15~7 minecraft:wool 0
fill ~27~16~6 ~27~16~7 minecraft:fence 1
fill ~28~0~6 ~29~0~6 minecraft:fence 0
fill ~28~13~6 ~29~13~8 minecraft:fence 0
setblock ~28~15~6 minecraft:planks 0
setblock ~28~16~6 minecraft:rail 9
fill ~29~6~6 ~29~6~7 minecraft:wool 0
fill ~29~7~6 ~29~7~7 minecraft:fence 1
fill ~29~14~6 ~30~14~6 minecraft:planks 0
setblock ~29~15~6 minecraft:rail 3
setblock ~30~6~6 minecraft:planks 0
setblock ~30~7~6 minecraft:rail 9
setblock ~30~15~6 minecraft:rail 7
fill ~31~5~6 ~32~5~6 minecraft:planks 0
setblock ~31~6~6 minecraft:rail 3
fill ~31~12~6 ~33~12~8 minecraft:fence 0
setblock ~31~13~6 minecraft:fence 0
setblock ~31~14~6 minecraft:wool 0
fill ~31~15~6 ~32~15~6 minecraft:fence 1
setblock ~32~6~6 minecraft:rail 7
fill ~32~13~6 ~33~13~6 minecraft:wool 0
fill ~32~14~6 ~33~14~6 minecraft:fence 1
setblock ~33~4~6 minecraft:fence 0
setblock ~33~5~6 minecraft:wool 0
fill ~33~6~6 ~34~6~6 minecraft:fence 1
fill ~34~4~6 ~35~4~6 minecraft:wool 0
fill ~34~5~6 ~35~5~6 minecraft:fence 1
setblock ~34~13~6 minecraft:fence 0
fill ~7~4~7 ~8~13~7 minecraft:fence 0
fill ~9~4~7 ~10~4~7 minecraft:wool 0
fill ~9~5~7 ~10~5~7 minecraft:fence 1
fill ~9~9~7 ~10~9~7 minecraft:fence 0
fill ~9~10~7 ~9~10~13 minecraft:fence 0
fill ~9~13~7 ~10~13~7 minecraft:wool 0
fill ~9~14~7 ~10~14~7 minecraft:fence 1
fill ~10~1~7 ~10~2~10 minecraft:fence 0
fill ~11~4~7 ~11~4~8 minecraft:planks 0
setblock ~11~5~7 minecraft:rail 6
fill ~11~10~7 ~11~11~10 minecraft:fence 0
fill ~11~12~7 ~11~12~8 minecraft:fence 0
fill ~11~13~7 ~11~13~8 minecraft:planks 0
setblock ~11~14~7 minecraft:rail 6
setblock ~12~4~7 minecraft:redstone_block
setblock ~12~5~7 minecraft:golden_rail 2
setblock ~12~13~7 minecraft:redstone_block
setblock ~12~14~7 minecraft:golden_rail 2
fill ~13~4~7 ~13~4~8 minecraft:fence 0
setblock ~13~6~7 minecraft:rail 8
setblock ~13~15~7 minecraft:rail 8
fill ~14~5~7 ~14~5~8 minecraft:wool 0
fill ~14~6~7 ~14~6~8 minecraft:fence 1
fill ~14~7~7 ~15~7~7 minecraft:fence 1
fill ~14~14~7 ~14~14~8 minecraft:wool 0
fill ~14~15~7 ~14~15~8 minecraft:fence 1
fill ~14~16~7 ~15~16~7 minecraft:fence 1
setblock ~15~6~7 minecraft:wool 0
setblock ~15~15~7 minecraft:wool 0
fill ~16~0~7 ~18~0~7 minecraft:wool 0
fill ~16~1~7 ~16~5~7 minecraft:fence 0
fill ~17~7~7 ~19~12~7 minecraft:fence 0
fill ~17~13~7 ~18~15~7 minecraft:fence 0
fill ~19~0~7 ~22~0~7 minecraft:planks 0
setblock ~19~1~7 minecraft:rail 6
fill ~19~15~7 ~20~15~7 minecraft:fence 0
fill ~20~1~7 ~22~1~7 minecraft:rail 1
setblock ~20~14~7 minecraft:fence 0
setblock ~23~0~7 minecraft:redstone_block
setblock ~23~1~7 minecraft:golden_rail 1
fill ~24~0~7 ~26~0~7 minecraft:planks 0
fill ~24~1~7 ~25~1~7 minecraft:rail 1
fill ~25~8~7 ~28~12~7 minecraft:fence 0
fill ~25~13~7 ~27~14~7 minecraft:fence 0
fill ~25~15~7 ~26~15~7 minecraft:fence 0
setblock ~26~1~7 minecraft:rail 7
fill ~26~7~7 ~28~7~7 minecraft:fence 0
fill ~27~0~7 ~29~0~7 minecraft:wool 0
fill ~28~6~7 ~28~6~8 minecraft:fence 0
fill ~28~14~7 ~28~14~8 minecraft:fence 0
setblock ~28~15~7 minecraft:wool 0
fill ~28~16~7 ~29~16~7 minecraft:fence 1
fill ~29~1~7 ~29~5~7 minecraft:fence 0
fill ~29~14~7 ~29~14~8 minecraft:wool 0
fill ~29~15~7 ~29~15~8 minecraft:fence 1
setblock ~30~6~7 minecraft:wool 0
fill ~30~7~7 ~31~7~7 minecraft:fence 1
fill ~30~13~7 ~30~13~9 minecraft:fence 0
setblock ~30~14~7 minecraft:planks 0
setblock ~30~15~7 minecraft:rail 9
fill ~31~5~7 ~31~5~8 minecraft:wool 0
fill ~31~6~7 ~31~6~8 minecraft:fence 1
fill ~31~13~7 ~32~13~7 minecraft:planks 0
setblock ~31~14~7 minecraft:rail 3
setblock ~32~5~7 minecraft:planks 0
setblock ~32~6~7 minecraft:rail 9
setblock ~32~14~7 minecraft:rail 7
fill ~33~4~7 ~34~4~7 minecraft:planks 0
setblock ~33~5~7 minecraft:rail 3
fill ~33~13~7 ~34~13~7 minecraft:wool 0
fill ~33~14~7 ~34~14~7 minecraft:fence 1
setblock ~34~5~7 minecraft:rail 7
fill ~34~12~7 ~34~12~8 minecraft:fence 0
fill ~35~0~7 ~35~1~12 minecraft:fence 0
fill ~35~2~7 ~35~2~11 minecraft:fence 0
fill ~35~3~7 ~35~3~8 minecraft:fence 0
fill ~35~4~7 ~36~4~7 minecraft:wool 0
fill ~35~5~7 ~36~5~7 minecraft:fence 1
fill ~6~0~8 ~6~3~10 minecraft:fence 0
fill ~6~4~8 ~7~12~8 minecraft:fence 0
fill ~8~4~8 ~9~4~8 minecraft:wool 0
fill ~8~5~8 ~9~5~8 minecraft:fence 1
fill ~8~10~8 ~8~10~13 minecraft:fence 0
setblock ~8~12~8 minecraft:fence 0
setblock ~9~13~8 minecraft:wool 0
fill ~9~14~8 ~9~14~9 minecraft:fence 1
fill ~10~0~8 ~10~0~10 minecraft:fence 0
fill ~10~4~8 ~10~4~9 minecraft:planks 0
setblock ~10~5~8 minecraft:rail 6
fill ~10~9~8 ~11~9~8 minecraft:fence 0
setblock ~10~13~8 minecraft:planks 0
setblock ~10~14~8 minecraft:rail 6
setblock ~11~5~8 minecraft:rail 8
setblock ~11~14~8 minecraft:rail 8
fill ~12~3~8 ~14~3~8 minecraft:fence 0
fill ~12~4~8 ~12~4~9 minecraft:wool 0
fill ~12~5~8 ~12~5~9 minecraft:fence 1
fill ~12~6~8 ~13~6~8 minecraft:fence 1
fill ~12~10~8 ~12~12~10 minecraft:fence 0
fill ~12~13~8 ~12~13~9 minecraft:wool 0
fill ~12~14~8 ~12~14~9 minecraft:fence 1
fill ~12~15~8 ~13~15~8 minecraft:fence 1
setblock ~13~5~8 minecraft:wool 0
setblock ~13~14~8 minecraft:wool 0
fill ~14~0~8 ~16~0~8 minecraft:wool 0
fill ~14~1~8 ~14~2~8 minecraft:fence 0
setblock ~14~4~8 minecraft:fence 0
fill ~15~6~8 ~16~14~8 minecraft:fence 0
fill ~16~15~8 ~17~15~8 minecraft:fence 0
fill ~17~0~8 ~17~0~9 minecraft:planks 0
setblock ~17~1~8 minecraft:rail 6
fill ~17~7~8 ~17~14~8 minecraft:fence 0
setblock ~18~0~8 minecraft:redstone_block
setblock ~18~1~8 minecraft:golden_rail 1
setblock ~19~0~8 minecraft:planks 0
setblock ~19~1~8 minecraft:rail 8
fill ~20~0~8 ~25~0~8 minecraft:wool 0
fill ~20~1~8 ~25~1~8 minecraft:fence 1
fill ~26~0~8 ~28~0~8 minecraft:planks 0
setblock ~26~1~8 minecraft:rail 9
setblock ~27~1~8 minecraft:rail 1
setblock ~28~1~8 minecraft:rail 7
fill ~28~7~8 ~30~11~8 minecraft:fence 0
setblock ~28~12~8 minecraft:fence 0
fill ~29~0~8 ~31~0~8 minecraft:wool 0
fill ~29~6~8 ~30~6~8 minecraft:fence 0
setblock ~30~14~8 minecraft:wool 0
fill ~30~15~8 ~31~15~8 minecraft:fence 1
fill ~31~11~8 ~34~11~9 minecraft:fence 0
fill ~31~13~8 ~31~13~9 minecraft:wool 0
fill ~31~14~8 ~31~14~9 minecraft:fence 1
fill ~32~0~8 ~32~4~8 minecraft:fence 0
setblock ~32~5~8 minecraft:wool 0
fill ~32~6~8 ~33~6~8 minecraft:fence 1
fill ~32~13~8 ~33~13~8 minecraft:planks 0
setblock ~32~14~8 minecraft:rail 9
fill ~33~4~8 ~33~4~9 minecraft:wool 0
fill ~33~5~8 ~33~5~9 minecraft:fence 1
setblock ~33~14~8 minecraft:rail 7
fill ~34~4~8 ~35~4~8 minecraft:planks 0
setblock ~34~5~8 minecraft:rail 9
setblock ~34~13~8 minecraft:wool 0
fill ~34~14~8 ~34~14~9 minecraft:fence 1
setblock ~35~5~8 minecraft:rail 7
fill ~36~0~8 ~36~0~15 minecraft:fence 0
fill ~36~1~8 ~36~2~10 minecraft:fence 0
setblock ~36~3~8 minecraft:fence 0
setblock ~36~4~8 minecraft:wool 0
fill ~36~5~8 ~36~5~9 minecraft:fence 1
fill ~5~0~9 ~5~12~10 minecraft:fence 0
fill ~6~4~9 ~6~12~9 minecraft:fence 0
fill ~7~4~9 ~8~4~9 minecraft:wool 0
fill ~7~5~9 ~8~5~9 minecraft:fence 1
fill ~7~10~9 ~7~10~13 minecraft:fence 0
fill ~7~12~9 ~7~12~10 minecraft:fence 0
fill ~8~12~9 ~9~12~9 minecraft:wool 0
fill ~8~13~9 ~9~13~9 minecraft:fence 1
fill ~9~3~9 ~9~3~10 minecraft:fence 0
fill ~9~4~9 ~9~4~10 minecraft:planks 0
setblock ~9~5~9 minecraft:rail 6
setblock ~10~5~9 minecraft:rail 8
setblock ~10~12~9 minecraft:redstone_block
setblock ~10~13~9 minecraft:golden_rail 4
fill ~11~0~9 ~12~3~9 minecraft:fence 0
fill ~11~4~9 ~11~4~10 minecraft:wool 0
fill ~11~5~9 ~11~5~10 minecraft:fence 1
fill ~11~9~9 ~15~9~9 minecraft:fence 0
fill ~11~12~9 ~11~12~11 minecraft:wool 0
setblock ~11~13~9 minecraft:wool 0
fill ~11~14~9 ~11~14~10 minecraft:fence 1
fill ~13~0~9 ~14~0~9 minecraft:wool 0
fill ~13~5~9 ~14~8~9 minecraft:fence 0
fill ~13~10~9 ~15~13~9 minecraft:fence 0
fill ~14~14~9 ~15~14~9 minecraft:fence 0
fill ~15~0~9 ~15~0~10 minecraft:planks 0
setblock ~15~1~9 minecraft:rail 6
fill ~15~6~9 ~15~8~9 minecraft:fence 0
setblock ~16~0~9 minecraft:redstone_block
setblock ~16~1~9 minecraft:golden_rail 1
setblock ~17~1~9 minecraft:rail 8
fill ~18~0~9 ~20~0~9 minecraft:wool 0
fill ~18~1~9 ~20~1~9 minecraft:fence 1
fill ~25~0~9 ~27~0~9 minecraft:wool 0
fill ~25~1~9 ~27~1~9 minecraft:fence 1
fill ~28~0~9 ~30~0~9 minecraft:planks 0
setblock ~28~1~9 minecraft:rail 9
setblock ~29~1~9 minecraft:rail 1
setblock ~30~1~9 minecraft:rail 7
fill ~30~6~9 ~32~10~9 minecraft:fence 0
fill ~30~11~9 ~30~12~9 minecraft:fence 0
fill ~31~0~9 ~32~0~9 minecraft:wool 0
fill ~31~5~9 ~32~5~9 minecraft:fence 0
fill ~31~12~9 ~32~12~9 minecraft:fence 0
setblock ~32~13~9 minecraft:wool 0
fill ~32~14~9 ~32~14~10 minecraft:fence 1
fill ~33~10~9 ~35~10~12 minecraft:fence 0
fill ~33~12~9 ~33~12~10 minecraft:planks 0
setblock ~33~13~9 minecraft:rail 4
fill ~34~0~9 ~34~2~10 minecraft:fence 0
setblock ~34~3~9 minecraft:fence 0
setblock ~34~4~9 minecraft:wool 0
fill ~34~5~9 ~34~5~10 minecraft:fence 1
fill ~34~12~9 ~35~12~9 minecraft:wool 0
fill ~34~13~9 ~35~13~9 minecraft:fence 1
fill ~35~3~9 ~35~3~10 minecraft:planks 0
setblock ~35~4~9 minecraft:rail 4
fill ~35~11~9 ~35~11~10 minecraft:fence 0
fill ~36~3~9 ~37~3~9 minecraft:wool 0
fill ~36~4~9 ~37~4~9 minecraft:fence 1
fill ~6~4~10 ~7~4~10 minecraft:wool 0
fill ~6~5~10 ~7~5~10 minecraft:fence 1
fill ~6~10~10 ~6~10~13 minecraft:fence 0
setblock ~6~12~10 minecraft:fence 0
fill ~8~4~10 ~8~4~11 minecraft:planks 0
setblock ~8~5~10 minecraft:rail 6
setblock ~8~12~10 minecraft:wool 0
fill ~8~13~10 ~8~13~11 minecraft:fence 1
setblock ~9~5~10 minecraft:rail 8
fill ~9~12~10 ~10~12~10 minecraft:planks 0
setblock ~9~13~10 minecraft:rail 6
fill ~10~3~10 ~11~3~10 minecraft:fence 0
fill ~10~4~10 ~10~4~11 minecraft:wool 0
fill ~10~5~10 ~10~5~11 minecraft:fence 1
setblock ~10~11~10 minecraft:fence 0
setblock ~10~13~10 minecraft:rail 8
fill ~11~0~10 ~11~2~11 minecraft:fence 0
fill ~11~9~10 ~13~9~10 minecraft:fence 0
fill ~11~13~10 ~11~13~11 minecraft:fence 1
fill ~12~4~10 ~12~8~10 minecraft:fence 0
fill ~12~13~10 ~13~13~10 minecraft:fence 0
fill ~13~0~10 ~13~0~11 minecraft:wool 0
fill ~13~5~10 ~13~8~10 minecraft:fence 0
fill ~13~10~10 ~13~12~10 minecraft:fence 0
setblock ~14~0~10 minecraft:planks 0
setblock ~14~1~10 minecraft:rail 6
setblock ~15~1~10 minecraft:rail 8
fill ~16~0~10 ~18~0~10 minecraft:wool 0
fill ~16~1~10 ~18~1~10 minecraft:fence 1
fill ~27~0~10 ~29~0~10 minecraft:wool 0
fill ~27~1~10 ~29~1~10 minecraft:fence 1
fill ~30~0~10 ~31~0~10 minecraft:planks 0
setblock ~30~1~10 minecraft:rail 9
setblock ~31~1~10 minecraft:rail 7
fill ~32~0~10 ~32~0~11 minecraft:wool 0
fill ~32~5~10 ~33~9~10 minecraft:fence 0
fill ~32~10~10 ~32~11~10 minecraft:fence 0
fill ~32~12~10 ~32~12~11 minecraft:wool 0
fill ~32~13~10 ~32~13~11 minecraft:fence 1
fill ~33~3~10 ~33~4~12 minecraft:fence 0
fill ~33~11~10 ~34~11~10 minecraft:fence 0
setblock ~33~13~10 minecraft:rail 9
fill ~34~3~10 ~34~3~11 minecraft:wool 0
fill ~34~4~10 ~34~4~11 minecraft:fence 1
setblock ~34~12~10 minecraft:planks 0
setblock ~34~13~10 minecraft:rail 7
setblock ~35~4~10 minecraft:rail 9
setblock ~35~12~10 minecraft:wool 0
fill ~35~13~10 ~35~13~11 minecraft:fence 1
setblock ~36~3~10 minecraft:planks 0
setblock ~36~4~10 minecraft:rail 7
fill ~37~0~10 ~37~0~15 minecraft:fence 0
fill ~37~1~10 ~37~2~10 minecraft:fence 0
setblock ~37~3~10 minecraft:wool 0
fill ~37~4~10 ~37~4~11 minecraft:fence 1
fill ~4~0~11 ~6~0~13 minecraft:stone 0
fill ~4~1~11 ~6~1~11 minecraft:iron_bars
fill ~5~4~11 ~6~4~11 minecraft:wool 0
fill ~5~5~11 ~6~5~11 minecraft:fence 1
fill ~5~11~11 ~6~11~11 minecraft:fence 0
fill ~7~4~11 ~7~4~12 minecraft:planks 0
setblock ~7~5~11 minecraft:rail 6
fill ~7~11~11 ~8~11~11 minecraft:wool 0
fill ~7~12~11 ~8~12~11 minecraft:fence 1
setblock ~8~5~11 minecraft:rail 8
fill ~9~4~11 ~9~4~12 minecraft:wool 0
fill ~9~5~11 ~9~5~12 minecraft:fence 1
setblock ~9~11~11 minecraft:redstone_block
setblock ~9~12~11 minecraft:golden_rail 4
fill ~10~0~11 ~10~0~22 minecraft:stone 0
fill ~10~1~11 ~10~1~14 minecraft:iron_bars
fill ~10~11~11 ~10~11~13 minecraft:wool 0
setblock ~10~12~11 minecraft:wool 0
fill ~10~13~11 ~10~13~12 minecraft:fence 1
fill ~12~0~11 ~12~0~13 minecraft:wool 0
setblock ~14~0~11 minecraft:redstone_block
setblock ~14~1~11 minecraft:golden_rail 0
fill ~15~0~11 ~16~0~11 minecraft:wool 0
fill ~15~1~11 ~16~1~11 minecraft:fence 1
fill ~29~0~11 ~30~0~11 minecraft:wool 0
fill ~29~1~11 ~30~1~11 minecraft:fence 1
setblock ~31~0~11 minecraft:redstone_block
setblock ~31~1~11 minecraft:golden_rail 0
fill ~33~0~11 ~33~0~13 minecraft:wool 0
fill ~33~5~11 ~33~9~12 minecraft:fence 0
setblock ~33~11~11 minecraft:fence 0
setblock ~33~12~11 minecraft:wool 0
fill ~33~13~11 ~33~13~12 minecraft:fence 1
fill ~34~9~11 ~36~9~14 minecraft:fence 0
fill ~34~11~11 ~34~11~12 minecraft:planks 0
setblock ~34~12~11 minecraft:rail 4
setblock ~35~3~11 minecraft:wool 0
fill ~35~4~11 ~35~4~12 minecraft:fence 1
fill ~35~11~11 ~36~11~11 minecraft:wool 0
fill ~35~12~11 ~36~12~11 minecraft:fence 1
fill ~36~2~11 ~36~2~12 minecraft:planks 0
setblock ~36~3~11 minecraft:rail 4
fill ~36~10~11 ~36~10~13 minecraft:fence 0
fill ~37~2~11 ~38~2~11 minecraft:wool 0
fill ~37~3~11 ~38~3~11 minecraft:fence 1
fill ~4~4~12 ~5~4~12 minecraft:wool 0
fill ~4~5~12 ~5~5~12 minecraft:fence 1
fill ~6~4~12 ~6~4~13 minecraft:planks 0
setblock ~6~5~12 minecraft:rail 6
fill ~6~11~12 ~6~11~13 minecraft:fence 0
setblock ~7~5~12 minecraft:rail 8
fill ~7~11~12 ~7~11~13 minecraft:wool 0
fill ~7~12~12 ~7~12~14 minecraft:fence 1
fill ~8~4~12 ~8~4~13 minecraft:wool 0
fill ~8~5~12 ~8~5~13 minecraft:fence 1
fill ~8~11~12 ~9~11~12 minecraft:planks 0
setblock ~8~12~12 minecraft:rail 6
setblock ~9~12~12 minecraft:rail 8
fill ~10~12~12 ~10~12~13 minecraft:fence 1
fill ~13~0~12 ~14~0~12 minecraft:planks 0
setblock ~13~1~12 minecraft:rail 6
setblock ~14~1~12 minecraft:rail 8
fill ~15~0~12 ~15~0~13 minecraft:wool 0
fill ~15~1~12 ~15~1~13 minecraft:fence 1
fill ~30~0~12 ~30~0~13 minecraft:wool 0
fill ~30~1~12 ~30~1~13 minecraft:fence 1
fill ~31~0~12 ~32~0~12 minecraft:planks 0
setblock ~31~1~12 minecraft:rail 9
setblock ~32~1~12 minecraft:rail 7
fill ~33~11~12 ~33~11~13 minecraft:wool 0
fill ~33~12~12 ~33~12~13 minecraft:fence 1
fill ~34~3~12 ~34~8~14 minecraft:fence 0
setblock ~34~12~12 minecraft:rail 9
fill ~35~2~12 ~35~2~13 minecraft:wool 0
fill ~35~3~12 ~35~3~13 minecraft:fence 1
fill ~35~11~12 ~35~11~13 minecraft:planks 0
setblock ~35~12~12 minecraft:rail 7
setblock ~36~3~12 minecraft:rail 9
fill ~36~11~12 ~36~11~13 minecraft:wool 0
fill ~36~12~12 ~36~12~14 minecraft:fence 1
fill ~37~2~12 ~37~2~13 minecraft:planks 0
setblock ~37~3~12 minecraft:rail 7
fill ~38~2~12 ~38~2~13 minecraft:wool 0
fill ~38~3~12 ~38~3~14 minecraft:fence 1
fill ~4~1~13 ~6~1~13 minecraft:iron_bars
fill ~4~4~13 ~4~4~14 minecraft:wool 0
fill ~4~5~13 ~4~5~15 minecraft:fence 1
fill ~5~4~13 ~5~4~14 minecraft:planks 0
setblock ~5~5~13 minecraft:rail 6
setblock ~6~5~13 minecraft:rail 8
fill ~7~4~13 ~7~4~14 minecraft:wool 0
fill ~7~5~13 ~7~5~14 minecraft:fence 1
setblock ~8~11~13 minecraft:planks 0
setblock ~8~12~13 minecraft:golden_rail 0
setblock ~9~11~13 minecraft:wool 0
fill ~9~12~13 ~9~12~14 minecraft:fence 1
fill ~11~0~13 ~11~0~20 minecraft:wool 0
setblock ~13~0~13 minecraft:redstone_block
setblock ~13~1~13 minecraft:golden_rail 0
fill ~14~0~13 ~14~0~20 minecraft:wool 0
fill ~14~1~13 ~14~1~16 minecraft:fence 1
fill ~31~0~13 ~31~0~15 minecraft:wool 0
fill ~31~1~13 ~31~1~15 minecraft:fence 1
fill ~32~0~13 ~32~0~14 minecraft:planks 0
setblock ~32~1~13 minecraft:rail 0
fill ~34~0~13 ~34~0~18 minecraft:wool 0
fill ~34~2~13 ~34~2~14 minecraft:fence 0
fill ~34~10~13 ~35~10~13 minecraft:fence 0
setblock ~34~11~13 minecraft:wool 0
fill ~34~12~13 ~34~12~14 minecraft:fence 1
fill ~35~8~13 ~36~8~17 minecraft:fence 0
setblock ~35~12~13 minecraft:rail 0
fill ~36~1~13 ~37~1~13 minecraft:fence 0
setblock ~36~2~13 minecraft:wool 0
setblock ~36~3~13 minecraft:fence 1
setblock ~37~3~13 minecraft:rail 0
setblock ~5~5~14 minecraft:golden_rail 0
setblock ~6~0~14 minecraft:stone 0
fill ~6~1~14 ~7~1~14 minecraft:iron_bars
setblock ~6~4~14 minecraft:wool 0
fill ~6~5~14 ~6~5~15 minecraft:fence 1
fill ~7~10~14 ~7~10~15 minecraft:wool 0
fill ~7~11~14 ~7~11~16 minecraft:fence 1
setblock ~8~10~14 minecraft:planks 0
setblock ~8~11~14 minecraft:golden_rail 4
fill ~9~10~14 ~9~10~15 minecraft:wool 0
fill ~9~11~14 ~9~11~16 minecraft:fence 1
fill ~12~0~14 ~13~0~14 minecraft:planks 0
setblock ~12~1~14 minecraft:rail 6
setblock ~13~1~14 minecraft:rail 8
setblock ~32~1~14 minecraft:rail 9
fill ~33~0~14 ~33~0~15 minecraft:planks 0
setblock ~33~1~14 minecraft:rail 7
fill ~34~10~14 ~34~10~15 minecraft:wool 0
fill ~34~11~14 ~34~11~16 minecraft:fence 1
fill ~35~0~14 ~35~7~18 minecraft:fence 0
fill ~35~10~14 ~35~10~15 minecraft:planks 0
setblock ~35~11~14 minecraft:rail 4
fill ~36~1~14 ~36~1~15 minecraft:wool 0
fill ~36~2~14 ~36~2~15 minecraft:fence 1
fill ~36~7~14 ~37~7~18 minecraft:fence 0
fill ~36~10~14 ~37~10~14 minecraft:wool 0
fill ~36~11~14 ~37~11~14 minecraft:fence 1
fill ~37~1~14 ~37~1~15 minecraft:planks 0
setblock ~37~2~14 minecraft:rail 4
fill ~37~8~14 ~37~8~17 minecraft:fence 0
fill ~37~9~14 ~37~9~15 minecraft:fence 0
fill ~38~1~14 ~38~1~15 minecraft:wool 0
fill ~38~2~14 ~38~2~16 minecraft:fence 1
fill ~3~3~15 ~4~3~15 minecraft:wool 0
fill ~3~4~15 ~4~4~15 minecraft:fence 1
fill ~5~0~15 ~5~0~20 minecraft:fence 0
fill ~5~1~15 ~5~1~18 minecraft:fence 0
fill ~5~2~15 ~5~2~16 minecraft:fence 0
setblock ~5~3~15 minecraft:redstone_block
setblock ~5~4~15 minecraft:golden_rail 4
fill ~6~3~15 ~6~3~16 minecraft:wool 0
fill ~6~4~15 ~6~4~17 minecraft:fence 1
fill ~7~1~15 ~7~1~21 minecraft:iron_bars
fill ~7~4~15 ~7~8~17 minecraft:fence 0
fill ~7~9~15 ~8~9~15 minecraft:fence 0
setblock ~8~10~15 minecraft:redstone_block
setblock ~8~11~15 minecraft:golden_rail 0
fill ~12~0~15 ~12~0~19 minecraft:planks 0
fill ~12~1~15 ~12~1~18 minecraft:golden_rail 0
fill ~13~0~15 ~13~0~18 minecraft:wool 0
fill ~32~0~15 ~32~0~18 minecraft:wool 0
fill ~32~1~15 ~32~1~18 minecraft:fence 1
setblock ~33~1~15 minecraft:rail 0
fill ~35~9~15 ~36~9~15 minecraft:fence 0
setblock ~35~11~15 minecraft:rail 9
setblock ~36~10~15 minecraft:planks 0
setblock ~36~11~15 minecraft:rail 7
setblock ~37~2~15 minecraft:rail 0
setblock ~37~10~15 minecraft:wool 0
fill ~37~11~15 ~37~11~16 minecraft:fence 1
fill ~3~0~16 ~4~0~20 minecraft:fence 0
fill ~3~1~16 ~4~1~18 minecraft:fence 0
fill ~3~2~16 ~4~2~16 minecraft:fence 0
setblock ~3~3~16 minecraft:wool 0
fill ~3~4~16 ~3~4~17 minecraft:fence 1
fill ~4~3~16 ~5~3~16 minecraft:planks 0
setblock ~4~4~16 minecraft:rail 6
setblock ~5~4~16 minecraft:rail 8
fill ~6~0~16 ~6~2~16 minecraft:fence 0
fill ~7~3~16 ~7~3~17 minecraft:fence 0
fill ~7~9~16 ~7~9~17 minecraft:wool 0
fill ~7~10~16 ~7~10~18 minecraft:fence 1
fill ~8~7~16 ~9~7~18 minecraft:fence 0
fill ~8~8~16 ~9~8~17 minecraft:fence 0
fill ~8~9~16 ~8~9~17 minecraft:planks 0
setblock ~8~10~16 minecraft:rail 4
fill ~9~9~16 ~9~9~17 minecraft:wool 0
fill ~9~10~16 ~9~10~18 minecraft:fence 1
setblock ~33~0~16 minecraft:redstone_block
setblock ~33~1~16 minecraft:golden_rail 0
fill ~34~9~16 ~35~9~16 minecraft:wool 0
fill ~34~10~16 ~35~10~16 minecraft:fence 1
fill ~36~0~16 ~36~0~46 minecraft:wool 0
fill ~36~1~16 ~36~1~46 minecraft:fence 1
fill ~36~6~16 ~38~6~18 minecraft:fence 0
fill ~36~9~16 ~36~9~17 minecraft:planks 0
setblock ~36~10~16 minecraft:rail 4
fill ~37~0~16 ~37~0~17 minecraft:planks 0
setblock ~37~1~16 minecraft:rail 4
fill ~37~9~16 ~38~9~16 minecraft:wool 0
fill ~37~10~16 ~38~10~16 minecraft:fence 1
fill ~38~0~16 ~38~0~44 minecraft:wool 0
fill ~38~1~16 ~38~1~44 minecraft:fence 1
fill ~38~7~16 ~38~7~18 minecraft:fence 0
fill ~38~8~16 ~38~8~17 minecraft:fence 0
fill ~2~0~17 ~2~0~20 minecraft:fence 0
fill ~2~1~17 ~2~1~18 minecraft:fence 0
fill ~2~2~17 ~3~2~17 minecraft:wool 0
fill ~2~3~17 ~3~3~17 minecraft:fence 1
setblock ~4~2~17 minecraft:redstone_block
setblock ~4~3~17 minecraft:golden_rail 4
fill ~5~2~17 ~6~2~17 minecraft:wool 0
fill ~5~3~17 ~6~3~17 minecraft:fence 1
setblock ~7~2~17 minecraft:fence 0
fill ~8~6~17 ~9~6~18 minecraft:fence 0
setblock ~8~10~17 minecraft:rail 0
fill ~10~1~17 ~10~1~21 minecraft:iron_bars
setblock ~13~1~17 minecraft:wooden_button 4
setblock ~14~1~17 minecraft:wool 0
fill ~33~0~17 ~33~0~18 minecraft:planks 0
setblock ~33~1~17 minecraft:rail 0
setblock ~35~9~17 minecraft:wool 0
fill ~35~10~17 ~35~10~18 minecraft:fence 1
setblock ~36~10~17 minecraft:rail 9
fill ~37~1~17 ~37~1~19 minecraft:golden_rail 0
setblock ~37~9~17 minecraft:planks 0
setblock ~37~10~17 minecraft:rail 7
setblock ~38~9~17 minecraft:wool 0
fill ~38~10~17 ~38~10~18 minecraft:fence 1
setblock ~2~2~18 minecraft:wool 0
fill ~2~3~18 ~2~3~19 minecraft:fence 1
fill ~3~2~18 ~4~2~18 minecraft:planks 0
setblock ~3~3~18 minecraft:rail 6
setblock ~4~3~18 minecraft:rail 8
setblock ~5~2~18 minecraft:wool 0
fill ~5~3~18 ~5~3~19 minecraft:fence 1
fill ~7~5~18 ~9~5~20 minecraft:fence 0
fill ~7~6~18 ~7~6~19 minecraft:fence 0
setblock ~7~7~18 minecraft:fence 0
setblock ~7~8~18 minecraft:wool 0
fill ~7~9~18 ~7~9~19 minecraft:fence 1
setblock ~8~8~18 minecraft:planks 0
setblock ~8~9~18 minecraft:golden_rail 4
setblock ~9~8~18 minecraft:wool 0
fill ~9~9~18 ~9~9~19 minecraft:fence 1
fill ~14~1~18 ~14~1~20 minecraft:fence 1
fill ~32~2~18 ~32~2~19 minecraft:fence 1
setblock ~33~1~18 minecraft:golden_rail 5
fill ~34~1~18 ~34~2~18 minecraft:fence 1
fill ~35~8~18 ~36~8~18 minecraft:wool 0
fill ~35~9~18 ~36~9~18 minecraft:fence 1
setblock ~37~0~18 minecraft:redstone_block
fill ~37~8~18 ~37~8~19 minecraft:planks 0
setblock ~37~9~18 minecraft:rail 4
fill ~38~8~18 ~39~8~18 minecraft:wool 0
fill ~38~9~18 ~39~9~18 minecraft:fence 1
fill ~39~0~18 ~39~3~26 minecraft:fence 0
fill ~39~4~18 ~39~4~25 minecraft:fence 0
fill ~39~5~18 ~39~5~23 minecraft:fence 0
fill ~39~6~18 ~39~6~21 minecraft:fence 0
fill ~39~7~18 ~39~7~19 minecraft:fence 0
fill ~2~1~19 ~2~1~20 minecraft:wool 0
fill ~2~2~19 ~2~2~21 minecraft:fence 1
fill ~3~1~19 ~3~1~20 minecraft:planks 0
setblock ~3~2~19 minecraft:golden_rail 4
fill ~4~1~19 ~5~1~19 minecraft:wool 0
fill ~4~2~19 ~5~2~19 minecraft:fence 1
fill ~7~4~19 ~9~4~21 minecraft:fence 0
setblock ~7~7~19 minecraft:wool 0
fill ~7~8~19 ~7~8~20 minecraft:fence 1
setblock ~8~7~19 minecraft:planks 0
setblock ~8~8~19 minecraft:golden_rail 4
setblock ~9~6~19 minecraft:fence 0
setblock ~9~7~19 minecraft:wool 0
fill ~9~8~19 ~9~8~20 minecraft:fence 1
setblock ~12~1~19 minecraft:rail 9
fill ~13~0~19 ~13~0~21 minecraft:planks 0
setblock ~13~1~19 minecraft:rail 7
fill ~32~0~19 ~32~0~65 minecraft:fence 0
setblock ~32~1~19 minecraft:wool 0
fill ~32~3~19 ~32~3~20 minecraft:fence 1
setblock ~33~1~19 minecraft:redstone_block
setblock ~33~2~19 minecraft:golden_rail 5
fill ~34~0~19 ~34~0~65 minecraft:fence 0
setblock ~34~1~19 minecraft:wool 0
fill ~34~2~19 ~34~3~19 minecraft:fence 1
setblock ~36~8~19 minecraft:wool 0
fill ~36~9~19 ~36~9~20 minecraft:fence 1
fill ~37~0~19 ~37~0~25 minecraft:planks 0
setblock ~37~9~19 minecraft:rail 9
setblock ~38~8~19 minecraft:planks 0
setblock ~38~9~19 minecraft:rail 7
setblock ~39~8~19 minecraft:wool 0
fill ~39~9~19 ~39~9~20 minecraft:fence 1
setblock ~3~2~20 minecraft:golden_rail 0
setblock ~4~1~20 minecraft:wool 0
fill ~4~2~20 ~4~2~21 minecraft:fence 1
setblock ~7~6~20 minecraft:wool 0
fill ~7~7~20 ~7~7~21 minecraft:fence 1
setblock ~8~6~20 minecraft:redstone_block
setblock ~8~7~20 minecraft:golden_rail 4
setblock ~9~6~20 minecraft:wool 0
fill ~9~7~20 ~9~7~21 minecraft:fence 1
fill ~12~0~20 ~12~0~22 minecraft:wool 0
setblock ~13~1~20 minecraft:rail 0
fill ~15~0~20 ~15~0~22 minecraft:wool 0
fill ~15~1~20 ~15~1~22 minecraft:fence 1
fill ~32~1~20 ~34~1~64 minecraft:fence 0
setblock ~32~2~20 minecraft:wool 0
fill ~32~4~20 ~32~4~21 minecraft:fence 1
fill ~33~0~20 ~33~0~65 minecraft:fence 0
setblock ~33~2~20 minecraft:planks 0
setblock ~33~3~20 minecraft:golden_rail 5
setblock ~34~2~20 minecraft:wool 0
fill ~34~3~20 ~34~4~20 minecraft:fence 1
fill ~36~7~20 ~37~7~20 minecraft:wool 0
fill ~36~8~20 ~37~8~20 minecraft:fence 1
fill ~37~1~20 ~37~1~24 minecraft:rail 0
fill ~38~7~20 ~38~7~21 minecraft:planks 0
setblock ~38~8~20 minecraft:rail 4
fill ~39~7~20 ~40~7~20 minecraft:wool 0
fill ~39~8~20 ~40~8~20 minecraft:fence 1
fill ~40~0~20 ~40~0~31 minecraft:fence 0
fill ~40~1~20 ~40~1~30 minecraft:fence 0
fill ~40~2~20 ~40~2~29 minecraft:fence 0
fill ~40~3~20 ~40~3~27 minecraft:fence 0
fill ~40~4~20 ~40~4~25 minecraft:fence 0
fill ~40~5~20 ~40~5~23 minecraft:fence 0
fill ~40~6~20 ~40~6~21 minecraft:fence 0
fill ~2~0~21 ~2~0~23 minecraft:wool 0
fill ~2~1~21 ~2~1~23 minecraft:fence 1
setblock ~3~0~21 minecraft:redstone_block
setblock ~3~1~21 minecraft:golden_rail 4
fill ~4~0~21 ~5~0~21 minecraft:wool 0
fill ~4~1~21 ~5~1~21 minecraft:fence 1
setblock ~7~5~21 minecraft:wool 0
fill ~7~6~21 ~7~6~22 minecraft:fence 1
fill ~8~1~21 ~9~1~21 minecraft:iron_bars
setblock ~8~5~21 minecraft:planks 0
setblock ~8~6~21 minecraft:rail 4
setblock ~9~5~21 minecraft:wool 0
fill ~9~6~21 ~9~6~22 minecraft:fence 1
fill ~11~0~21 ~11~0~22 minecraft:stone 0
setblock ~13~1~21 minecraft:rail 9
setblock ~14~0~21 minecraft:planks 0
setblock ~14~1~21 minecraft:rail 7
fill ~32~2~21 ~34~2~63 minecraft:fence 0
setblock ~32~3~21 minecraft:wool 0
fill ~32~5~21 ~32~5~22 minecraft:fence 1
setblock ~33~3~21 minecraft:redstone_block
setblock ~33~4~21 minecraft:golden_rail 5
setblock ~34~3~21 minecraft:wool 0
fill ~34~4~21 ~34~5~21 minecraft:fence 1
setblock ~37~7~21 minecraft:wool 0
fill ~37~8~21 ~37~8~22 minecraft:fence 1
setblock ~38~8~21 minecraft:rail 9
setblock ~39~7~21 minecraft:planks 0
setblock ~39~8~21 minecraft:rail 7
setblock ~40~7~21 minecraft:wool 0
fill ~40~8~21 ~40~8~22 minecraft:fence 1
fill ~3~0~22 ~4~0~22 minecraft:planks 0
setblock ~3~1~22 minecraft:rail 9
setblock ~4~1~22 minecraft:rail 7
fill ~5~0~22 ~5~0~29 minecraft:wool 0
fill ~5~1~22 ~5~1~29 minecraft:fence 1
fill ~7~0~22 ~8~0~25 minecraft:fence 0
fill ~7~1~22 ~8~1~24 minecraft:fence 0
fill ~7~2~22 ~9~2~23 minecraft:fence 0
fill ~7~3~22 ~9~3~22 minecraft:fence 0
setblock ~7~4~22 minecraft:wool 0
fill ~7~5~22 ~7~5~23 minecraft:fence 1
setblock ~8~4~22 minecraft:planks 0
setblock ~8~5~22 minecraft:rail 4
setblock ~9~0~22 minecraft:stone 0
setblock ~9~4~22 minecraft:wool 0
fill ~9~5~22 ~9~5~23 minecraft:fence 1
fill ~12~1~22 ~13~1~22 minecraft:fence 1
fill ~13~0~22 ~13~0~24 minecraft:wool 0
setblock ~14~0~22 minecraft:redstone_block
setblock ~14~1~22 minecraft:golden_rail 0
fill ~16~0~22 ~16~0~23 minecraft:wool 0
fill ~16~1~22 ~16~1~23 minecraft:fence 1
fill ~32~3~22 ~32~3~62 minecraft:fence 0
setblock ~32~4~22 minecraft:wool 0
fill ~32~6~22 ~32~6~23 minecraft:fence 1
setblock ~33~4~22 minecraft:planks 0
setblock ~33~5~22 minecraft:golden_rail 5
fill ~34~3~22 ~34~3~62 minecraft:fence 0
setblock ~34~4~22 minecraft:wool 0
fill ~34~5~22 ~34~6~22 minecraft:fence 1
fill ~37~6~22 ~38~6~22 minecraft:wool 0
fill ~37~7~22 ~38~7~22 minecraft:fence 1
fill ~39~6~22 ~39~6~23 minecraft:planks 0
setblock ~39~7~22 minecraft:rail 4
fill ~40~6~22 ~41~6~22 minecraft:wool 0
fill ~40~7~22 ~41~7~22 minecraft:fence 1
fill ~41~0~22 ~41~0~31 minecraft:fence 0
fill ~41~1~22 ~41~1~30 minecraft:fence 0
fill ~41~2~22 ~41~2~29 minecraft:fence 0
fill ~41~3~22 ~41~3~27 minecraft:fence 0
fill ~41~4~22 ~41~4~25 minecraft:fence 0
fill ~41~5~22 ~41~5~23 minecraft:fence 0
fill ~3~0~23 ~3~0~29 minecraft:wool 0
fill ~3~1~23 ~3~1~29 minecraft:fence 1
setblock ~4~0~23 minecraft:redstone_block
fill ~4~1~23 ~4~1~24 minecraft:golden_rail 0
setblock ~7~3~23 minecraft:wool 0
fill ~7~4~23 ~7~4~24 minecraft:fence 1
setblock ~8~3~23 minecraft:redstone_block
setblock ~8~4~23 minecraft:golden_rail 4
fill ~9~0~23 ~10~1~23 minecraft:fence 0
setblock ~9~3~23 minecraft:wool 0
fill ~9~4~23 ~9~4~24 minecraft:fence 1
fill ~13~1~23 ~13~1~24 minecraft:fence 1
fill ~14~0~23 ~15~0~23 minecraft:planks 0
setblock ~14~1~23 minecraft:rail 9
setblock ~15~1~23 minecraft:rail 7
fill ~17~0~23 ~18~0~23 minecraft:wool 0
fill ~17~1~23 ~18~1~23 minecraft:fence 1
fill ~32~4~23 ~34~4~62 minecraft:fence 0
setblock ~32~5~23 minecraft:wool 0
fill ~32~7~23 ~32~7~24 minecraft:fence 1
fill ~33~3~23 ~33~3~63 minecraft:fence 0
setblock ~33~5~23 minecraft:planks 0
setblock ~33~6~23 minecraft:rail 5
setblock ~34~5~23 minecraft:wool 0
fill ~34~6~23 ~34~7~23 minecraft:fence 1
setblock ~38~6~23 minecraft:wool 0
fill ~38~7~23 ~38~7~24 minecraft:fence 1
setblock ~39~7~23 minecraft:rail 9
setblock ~40~6~23 minecraft:planks 0
setblock ~40~7~23 minecraft:rail 7
setblock ~41~6~23 minecraft:wool 0
fill ~41~7~23 ~41~7~24 minecraft:fence 1
fill ~4~0~24 ~4~0~29 minecraft:planks 0
setblock ~7~2~24 minecraft:wool 0
fill ~7~3~24 ~7~3~25 minecraft:fence 1
setblock ~8~2~24 minecraft:planks 0
setblock ~8~3~24 minecraft:golden_rail 4
fill ~9~0~24 ~9~0~25 minecraft:fence 0
setblock ~9~1~24 minecraft:fence 0
setblock ~9~2~24 minecraft:wool 0
fill ~9~3~24 ~9~3~25 minecraft:fence 1
fill ~14~0~24 ~14~0~25 minecraft:wool 0
fill ~14~1~24 ~14~1~25 minecraft:fence 1
setblock ~15~0~24 minecraft:planks 0
setblock ~15~1~24 minecraft:rail 9
setblock ~16~0~24 minecraft:redstone_block
setblock ~16~1~24 minecraft:golden_rail 1
fill ~17~0~24 ~17~0~25 minecraft:planks 0
setblock ~17~1~24 minecraft:rail 7
fill ~18~0~24 ~19~0~24 minecraft:wool 0
fill ~18~1~24 ~19~1~24 minecraft:fence 1
fill ~32~5~24 ~34~5~61 minecraft:fence 0
setblock ~32~6~24 minecraft:wool 0
fill ~32~8~24 ~32~8~25 minecraft:fence 1
setblock ~33~6~24 minecraft:planks 0
setblock ~33~7~24 minecraft:golden_rail 5
setblock ~34~6~24 minecraft:wool 0
fill ~34~7~24 ~34~8~24 minecraft:fence 1
fill ~38~5~24 ~39~5~24 minecraft:wool 0
fill ~38~6~24 ~39~6~24 minecraft:fence 1
fill ~40~5~24 ~40~5~25 minecraft:planks 0
setblock ~40~6~24 minecraft:rail 4
fill ~41~5~24 ~42~5~24 minecraft:wool 0
fill ~41~6~24 ~42~6~24 minecraft:fence 1
fill ~42~0~24 ~42~0~31 minecraft:fence 0
fill ~42~1~24 ~42~1~30 minecraft:fence 0
fill ~42~2~24 ~42~2~29 minecraft:fence 0
fill ~42~3~24 ~42~3~27 minecraft:fence 0
fill ~42~4~24 ~42~4~25 minecraft:fence 0
fill ~4~1~25 ~4~1~28 minecraft:rail 0
setblock ~7~1~25 minecraft:wool 0
fill ~7~2~25 ~7~2~26 minecraft:fence 1
setblock ~8~1~25 minecraft:planks 0
setblock ~8~2~25 minecraft:rail 4
setblock ~9~1~25 minecraft:wool 0
setblock ~9~2~25 minecraft:fence 1
fill ~15~0~25 ~16~0~25 minecraft:wool 0
fill ~15~1~25 ~16~1~25 minecraft:fence 1
setblock ~17~1~25 minecraft:rail 9
fill ~18~0~25 ~18~0~26 minecraft:planks 0
setblock ~18~1~25 minecraft:rail 7
fill ~19~0~25 ~20~0~25 minecraft:wool 0
fill ~19~1~25 ~20~1~25 minecraft:fence 1
fill ~32~6~25 ~34~6~61 minecraft:fence 0
setblock ~32~7~25 minecraft:wool 0
fill ~32~9~25 ~32~9~26 minecraft:fence 1
setblock ~33~7~25 minecraft:redstone_block
setblock ~33~8~25 minecraft:golden_rail 5
setblock ~34~7~25 minecraft:wool 0
fill ~34~8~25 ~34~9~25 minecraft:fence 1
fill ~37~1~25 ~37~1~27 minecraft:golden_rail 0
setblock ~39~5~25 minecraft:wool 0
fill ~39~6~25 ~39~6~26 minecraft:fence 1
setblock ~40~6~25 minecraft:rail 9
setblock ~41~5~25 minecraft:planks 0
setblock ~41~6~25 minecraft:rail 7
setblock ~42~5~25 minecraft:wool 0
fill ~42~6~25 ~42~6~26 minecraft:fence 1
fill ~7~0~26 ~7~0~29 minecraft:wool 0
fill ~7~1~26 ~7~1~29 minecraft:fence 1
setblock ~8~0~26 minecraft:planks 0
setblock ~8~1~26 minecraft:golden_rail 4
fill ~9~0~26 ~9~0~27 minecraft:wool 0
fill ~9~1~26 ~9~1~27 minecraft:fence 1
fill ~16~0~26 ~17~0~26 minecraft:wool 0
fill ~16~1~26 ~17~1~26 minecraft:fence 1
setblock ~18~1~26 minecraft:rail 9
fill ~19~0~26 ~19~0~28 minecraft:planks 0
setblock ~19~1~26 minecraft:rail 7
fill ~20~0~26 ~20~0~27 minecraft:wool 0
fill ~20~1~26 ~20~1~27 minecraft:fence 1
fill ~32~7~26 ~34~7~60 minecraft:fence 0
setblock ~32~8~26 minecraft:wool 0
fill ~32~10~26 ~32~10~27 minecraft:fence 1
setblock ~33~8~26 minecraft:planks 0
setblock ~33~9~26 minecraft:rail 5
setblock ~34~8~26 minecraft:wool 0
fill ~34~9~26 ~34~10~26 minecraft:fence 1
setblock ~37~0~26 minecraft:redstone_block
fill ~39~4~26 ~40~4~26 minecraft:wool 0
fill ~39~5~26 ~40~5~26 minecraft:fence 1
fill ~41~4~26 ~41~4~27 minecraft:planks 0
setblock ~41~5~26 minecraft:rail 4
fill ~42~4~26 ~42~4~27 minecraft:wool 0
fill ~42~5~26 ~42~5~28 minecraft:fence 1
setblock ~8~0~27 minecraft:redstone_block
setblock ~8~1~27 minecraft:golden_rail 0
fill ~10~0~27 ~11~0~27 minecraft:wool 0
fill ~10~1~27 ~11~1~27 minecraft:fence 1
fill ~17~0~27 ~18~0~27 minecraft:wool 0
fill ~17~1~27 ~18~1~27 minecraft:fence 1
setblock ~19~1~27 minecraft:rail 0
fill ~21~0~27 ~21~0~28 minecraft:wool 0
fill ~21~1~27 ~21~1~28 minecraft:fence 1
fill ~32~8~27 ~34~8~60 minecraft:fence 0
setblock ~32~9~27 minecraft:wool 0
fill ~32~11~27 ~32~11~28 minecraft:fence 1
setblock ~33~9~27 minecraft:planks 0
setblock ~33~10~27 minecraft:golden_rail 5
setblock ~34~9~27 minecraft:wool 0
fill ~34~10~27 ~34~11~27 minecraft:fence 1
fill ~37~0~27 ~37~0~33 minecraft:planks 0
setblock ~40~4~27 minecraft:wool 0
fill ~40~5~27 ~40~5~28 minecraft:fence 1
setblock ~41~5~27 minecraft:rail 0
fill ~8~0~28 ~10~0~28 minecraft:planks 0
setblock ~8~1~28 minecraft:rail 9
setblock ~9~1~28 minecraft:rail 1
setblock ~10~1~28 minecraft:rail 7
setblock ~11~0~28 minecraft:wool 0
fill ~11~1~28 ~11~2~28 minecraft:fence 1
fill ~18~0~28 ~18~0~29 minecraft:wool 0
fill ~18~1~28 ~18~1~29 minecraft:fence 1
setblock ~19~1~28 minecraft:rail 9
fill ~20~0~28 ~20~0~29 minecraft:planks 0
setblock ~20~1~28 minecraft:rail 7
fill ~22~0~28 ~22~0~29 minecraft:wool 0
fill ~22~1~28 ~22~1~29 minecraft:fence 1
fill ~32~9~28 ~34~9~59 minecraft:fence 0
setblock ~32~10~28 minecraft:wool 0
fill ~32~12~28 ~32~12~29 minecraft:fence 1
setblock ~33~10~28 minecraft:redstone_block
setblock ~33~11~28 minecraft:golden_rail 5
setblock ~34~10~28 minecraft:wool 0
fill ~34~11~28 ~34~12~28 minecraft:fence 1
fill ~37~1~28 ~37~1~32 minecraft:rail 0
fill ~40~3~28 ~40~3~29 minecraft:wool 0
fill ~40~4~28 ~40~4~30 minecraft:fence 1
fill ~41~3~28 ~41~3~29 minecraft:planks 0
setblock ~41~4~28 minecraft:rail 4
fill ~42~3~28 ~42~3~29 minecraft:wool 0
fill ~42~4~28 ~42~4~30 minecraft:fence 1
fill ~3~2~29 ~3~2~31 minecraft:fence 1
setblock ~4~1~29 minecraft:rail 5
fill ~5~2~29 ~5~2~31 minecraft:fence 1
fill ~8~0~29 ~9~0~29 minecraft:wool 0
fill ~8~1~29 ~9~1~29 minecraft:fence 1
fill ~9~2~29 ~9~2~31 minecraft:fence 1
setblock ~10~0~29 minecraft:planks 0
setblock ~10~1~29 minecraft:rail 5
fill ~11~0~29 ~13~0~33 minecraft:fence 0
fill ~11~1~29 ~13~1~29 minecraft:wool 0
fill ~11~2~29 ~13~2~29 minecraft:fence 1
fill ~19~0~29 ~19~0~30 minecraft:wool 0
fill ~19~1~29 ~19~1~30 minecraft:fence 1
setblock ~20~1~29 minecraft:rail 9
fill ~21~0~29 ~21~0~30 minecraft:planks 0
setblock ~21~1~29 minecraft:rail 7
fill ~23~0~29 ~23~0~30 minecraft:wool 0
fill ~23~1~29 ~23~1~30 minecraft:fence 1
fill ~32~10~29 ~34~10~59 minecraft:fence 0
setblock ~32~11~29 minecraft:wool 0
fill ~32~13~29 ~32~13~30 minecraft:fence 1
setblock ~33~11~29 minecraft:planks 0
setblock ~33~12~29 minecraft:rail 5
setblock ~34~11~29 minecraft:wool 0
fill ~34~12~29 ~34~13~29 minecraft:fence 1
setblock ~41~4~29 minecraft:rail 0
fill ~3~0~30 ~5~0~45 minecraft:fence 0
fill ~3~1~30 ~3~1~31 minecraft:wool 0
fill ~4~1~30 ~4~1~31 minecraft:planks 0
setblock ~4~2~30 minecraft:rail 0
fill ~5~1~30 ~5~1~31 minecraft:wool 0
fill ~9~0~30 ~10~0~31 minecraft:fence 0
fill ~9~1~30 ~9~1~31 minecraft:wool 0
fill ~10~1~30 ~12~1~30 minecraft:planks 0
setblock ~10~2~30 minecraft:rail 9
setblock ~11~2~30 minecraft:rail 1
setblock ~12~2~30 minecraft:rail 7
setblock ~13~1~30 minecraft:wool 0
fill ~13~2~30 ~13~3~30 minecraft:fence 1
fill ~20~0~30 ~20~0~31 minecraft:wool 0
fill ~20~1~30 ~20~1~31 minecraft:fence 1
setblock ~21~1~30 minecraft:rail 9
fill ~22~0~30 ~22~0~31 minecraft:planks 0
setblock ~22~1~30 minecraft:rail 7
fill ~24~0~30 ~24~0~31 minecraft:wool 0
fill ~24~1~30 ~24~1~31 minecraft:fence 1
fill ~32~11~30 ~34~11~47 minecraft:fence 0
setblock ~32~12~30 minecraft:wool 0
fill ~32~14~30 ~32~14~31 minecraft:fence 1
setblock ~33~12~30 minecraft:planks 0
setblock ~33~13~30 minecraft:golden_rail 5
setblock ~34~12~30 minecraft:wool 0
fill ~34~13~30 ~34~14~30 minecraft:fence 1
setblock ~40~2~30 minecraft:wool 0
fill ~40~3~30 ~40~3~31 minecraft:fence 1
setblock ~41~2~30 minecraft:planks 0
setblock ~41~3~30 minecraft:rail 4
setblock ~42~2~30 minecraft:wool 0
fill ~42~3~30 ~42~3~31 minecraft:fence 1
fill ~3~3~31 ~3~3~34 minecraft:fence 1
setblock ~4~2~31 minecraft:rail 5
fill ~5~3~31 ~5~3~34 minecraft:fence 1
fill ~10~1~31 ~11~1~31 minecraft:wool 0
fill ~10~2~31 ~11~2~31 minecraft:fence 1
fill ~11~3~31 ~11~3~33 minecraft:fence 1
setblock ~12~1~31 minecraft:planks 0
setblock ~12~2~31 minecraft:rail 5
fill ~13~1~31 ~15~1~35 minecraft:fence 0
fill ~13~2~31 ~15~2~31 minecraft:wool 0
fill ~13~3~31 ~15~3~31 minecraft:fence 1
fill ~14~0~31 ~15~0~35 minecraft:fence 0
fill ~21~0~31 ~21~0~32 minecraft:wool 0
fill ~21~1~31 ~21~1~32 minecraft:fence 1
setblock ~22~1~31 minecraft:rail 9
fill ~23~0~31 ~23~0~32 minecraft:planks 0
setblock ~23~1~31 minecraft:rail 7
fill ~25~0~31 ~25~0~32 minecraft:wool 0
fill ~25~1~31 ~25~1~32 minecraft:fence 1
fill ~32~12~31 ~34~12~48 minecraft:fence 0
setblock ~32~13~31 minecraft:wool 0
fill ~32~15~31 ~32~15~32 minecraft:fence 1
setblock ~33~13~31 minecraft:redstone_block
setblock ~33~14~31 minecraft:golden_rail 5
setblock ~34~13~31 minecraft:wool 0
fill ~34~14~31 ~34~15~31 minecraft:fence 1
setblock ~40~1~31 minecraft:wool 0
fill ~40~2~31 ~40~2~32 minecraft:fence 1
setblock ~41~1~31 minecraft:planks 0
setblock ~41~2~31 minecraft:rail 4
setblock ~42~1~31 minecraft:wool 0
fill ~42~2~31 ~42~2~32 minecraft:fence 1
fill ~3~1~32 ~5~1~43 minecraft:fence 0
fill ~3~2~32 ~3~2~34 minecraft:wool 0
fill ~4~2~32 ~4~2~34 minecraft:planks 0
fill ~4~3~32 ~4~3~33 minecraft:rail 0
fill ~5~2~32 ~5~2~34 minecraft:wool 0
fill ~11~1~32 ~12~1~33 minecraft:fence 0
fill ~11~2~32 ~11~2~33 minecraft:wool 0
fill ~12~2~32 ~14~2~32 minecraft:planks 0
setblock ~12~3~32 minecraft:rail 9
setblock ~13~3~32 minecraft:rail 1
setblock ~14~3~32 minecraft:rail 7
setblock ~15~2~32 minecraft:wool 0
fill ~15~3~32 ~15~4~32 minecraft:fence 1
fill ~22~0~32 ~22~0~33 minecraft:wool 0
fill ~22~1~32 ~22~1~33 minecraft:fence 1
setblock ~23~1~32 minecraft:rail 9
fill ~24~0~32 ~24~0~33 minecraft:planks 0
setblock ~24~1~32 minecraft:rail 7
fill ~26~0~32 ~26~0~33 minecraft:wool 0
fill ~26~1~32 ~26~1~33 minecraft:fence 1
fill ~32~13~32 ~34~13~48 minecraft:fence 0
setblock ~32~14~32 minecraft:wool 0
fill ~32~16~32 ~32~16~33 minecraft:fence 1
setblock ~33~14~32 minecraft:planks 0
setblock ~33~15~32 minecraft:rail 5
setblock ~34~14~32 minecraft:wool 0
fill ~34~15~32 ~34~16~32 minecraft:fence 1
fill ~40~0~32 ~40~0~41 minecraft:wool 0
fill ~40~1~32 ~40~1~41 minecraft:fence 1
fill ~41~0~32 ~41~0~34 minecraft:planks 0
setblock ~41~1~32 minecraft:rail 4
fill ~42~0~32 ~42~0~39 minecraft:wool 0
fill ~42~1~32 ~42~1~39 minecraft:fence 1
fill ~12~2~33 ~13~2~33 minecraft:wool 0
fill ~12~3~33 ~13~3~33 minecraft:fence 1
fill ~13~4~33 ~13~4~35 minecraft:fence 1
setblock ~14~2~33 minecraft:planks 0
setblock ~14~3~33 minecraft:rail 5
fill ~15~2~33 ~17~2~35 minecraft:fence 0
fill ~15~3~33 ~17~3~33 minecraft:wool 0
fill ~15~4~33 ~17~4~33 minecraft:fence 1
fill ~16~0~33 ~17~1~37 minecraft:fence 0
fill ~23~0~33 ~23~0~34 minecraft:wool 0
fill ~23~1~33 ~23~1~34 minecraft:fence 1
setblock ~24~1~33 minecraft:rail 9
fill ~25~0~33 ~25~0~34 minecraft:planks 0
setblock ~25~1~33 minecraft:rail 7
fill ~27~0~33 ~27~0~35 minecraft:wool 0
fill ~27~1~33 ~27~1~35 minecraft:fence 1
fill ~32~14~33 ~34~14~48 minecraft:fence 0
setblock ~32~15~33 minecraft:wool 0
fill ~32~17~33 ~32~17~34 minecraft:fence 1
setblock ~33~15~33 minecraft:planks 0
setblock ~33~16~33 minecraft:golden_rail 5
setblock ~34~15~33 minecraft:wool 0
fill ~34~16~33 ~34~17~33 minecraft:fence 1
fill ~37~1~33 ~37~1~35 minecraft:golden_rail 0
fill ~41~1~33 ~41~1~34 minecraft:rail 0
fill ~3~4~34 ~3~4~41 minecraft:fence 1
setblock ~4~3~34 minecraft:rail 5
fill ~5~4~34 ~5~4~41 minecraft:fence 1
fill ~13~0~34 ~13~0~35 minecraft:fence 0
fill ~13~2~34 ~14~2~35 minecraft:fence 0
fill ~13~3~34 ~13~3~35 minecraft:wool 0
fill ~14~3~34 ~16~3~34 minecraft:planks 0
setblock ~14~4~34 minecraft:rail 9
setblock ~15~4~34 minecraft:rail 1
setblock ~16~4~34 minecraft:rail 7
setblock ~17~3~34 minecraft:wool 0
fill ~17~4~34 ~17~5~34 minecraft:fence 1
fill ~24~0~34 ~24~0~35 minecraft:wool 0
fill ~24~1~34 ~24~1~35 minecraft:fence 1
setblock ~25~1~34 minecraft:rail 9
fill ~26~0~34 ~26~0~35 minecraft:planks 0
setblock ~26~1~34 minecraft:rail 7
fill ~32~15~34 ~34~15~48 minecraft:fence 0
setblock ~32~16~34 minecraft:wool 0
fill ~32~18~34 ~32~18~35 minecraft:fence 1
setblock ~33~16~34 minecraft:redstone_block
setblock ~33~17~34 minecraft:golden_rail 5
setblock ~34~16~34 minecraft:wool 0
fill ~34~17~34 ~34~18~34 minecraft:fence 1
setblock ~37~0~34 minecraft:redstone_block
fill ~3~2~35 ~5~2~40 minecraft:fence 0
fill ~3~3~35 ~3~3~40 minecraft:wool 0
fill ~4~3~35 ~4~3~37 minecraft:planks 0
fill ~4~4~35 ~4~4~36 minecraft:rail 0
fill ~5~3~35 ~5~3~40 minecraft:wool 0
fill ~14~3~35 ~15~3~35 minecraft:wool 0
fill ~14~4~35 ~15~4~35 minecraft:fence 1
fill ~15~5~35 ~15~5~37 minecraft:fence 1
setblock ~16~3~35 minecraft:planks 0
setblock ~16~4~35 minecraft:rail 5
fill ~17~3~35 ~19~3~39 minecraft:fence 0
fill ~17~4~35 ~19~4~35 minecraft:wool 0
fill ~17~5~35 ~19~5~35 minecraft:fence 1
fill ~18~0~35 ~19~2~39 minecraft:fence 0
setblock ~25~0~35 minecraft:wool 0
fill ~25~1~35 ~25~2~35 minecraft:fence 1
setblock ~26~1~35 minecraft:golden_rail 5
fill ~27~2~35 ~27~2~40 minecraft:fence 1
fill ~32~16~35 ~34~16~48 minecraft:fence 0
setblock ~32~17~35 minecraft:wool 0
fill ~32~19~35 ~32~19~36 minecraft:fence 1
setblock ~33~17~35 minecraft:planks 0
setblock ~33~18~35 minecraft:rail 5
setblock ~34~17~35 minecraft:wool 0
fill ~34~18~35 ~34~19~35 minecraft:fence 1
fill ~37~0~35 ~37~0~41 minecraft:planks 0
setblock ~41~0~35 minecraft:redstone_block
fill ~41~1~35 ~41~1~36 minecraft:golden_rail 0
fill ~15~0~36 ~15~1~37 minecraft:fence 0
fill ~15~3~36 ~16~3~37 minecraft:fence 0
fill ~15~4~36 ~15~4~37 minecraft:wool 0
fill ~16~2~36 ~17~2~37 minecraft:fence 0
fill ~16~4~36 ~18~4~36 minecraft:planks 0
setblock ~16~5~36 minecraft:rail 9
setblock ~17~5~36 minecraft:rail 1
setblock ~18~5~36 minecraft:rail 7
setblock ~19~4~36 minecraft:wool 0
fill ~19~5~36 ~19~6~36 minecraft:fence 1
fill ~25~0~36 ~25~0~38 minecraft:fence 0
fill ~25~1~36 ~25~1~38 minecraft:wool 0
fill ~25~2~36 ~25~2~38 minecraft:fence 1
fill ~26~1~36 ~26~1~37 minecraft:planks 0
fill ~26~2~36 ~26~2~38 minecraft:golden_rail 0
fill ~27~0~36 ~27~0~40 minecraft:fence 0
fill ~27~1~36 ~27~1~40 minecraft:wool 0
fill ~32~17~36 ~34~17~55 minecraft:fence 0
setblock ~32~18~36 minecraft:wool 0
fill ~32~20~36 ~32~20~37 minecraft:fence 1
setblock ~33~18~36 minecraft:planks 0
setblock ~33~19~36 minecraft:golden_rail 5
setblock ~34~18~36 minecraft:wool 0
fill ~34~19~36 ~34~20~36 minecraft:fence 1
fill ~37~1~36 ~37~1~40 minecraft:rail 0
fill ~41~0~36 ~41~0~38 minecraft:planks 0
fill ~4~4~37 ~4~4~39 minecraft:golden_rail 0
setblock ~15~2~37 minecraft:fence 0
fill ~16~4~37 ~17~4~37 minecraft:wool 0
fill ~16~5~37 ~17~5~37 minecraft:fence 1
fill ~17~6~37 ~17~6~39 minecraft:fence 1
setblock ~18~4~37 minecraft:planks 0
setblock ~18~5~37 minecraft:rail 5
fill ~19~4~37 ~21~4~39 minecraft:fence 0
fill ~19~5~37 ~21~5~37 minecraft:wool 0
fill ~19~6~37 ~21~6~37 minecraft:fence 1
fill ~20~0~37 ~21~3~39 minecraft:fence 0
fill ~32~18~37 ~34~18~54 minecraft:fence 0
setblock ~32~19~37 minecraft:wool 0
fill ~32~21~37 ~32~21~38 minecraft:fence 1
setblock ~33~19~37 minecraft:redstone_block
setblock ~33~20~37 minecraft:golden_rail 5
setblock ~34~19~37 minecraft:wool 0
fill ~34~20~37 ~34~21~37 minecraft:fence 1
setblock ~41~1~37 minecraft:rail 0
setblock ~4~3~38 minecraft:redstone_block
fill ~17~0~38 ~17~2~39 minecraft:fence 0
fill ~17~4~38 ~18~4~39 minecraft:fence 0
fill ~17~5~38 ~17~5~39 minecraft:wool 0
fill ~18~5~38 ~20~5~38 minecraft:planks 0
setblock ~18~6~38 minecraft:rail 9
setblock ~19~6~38 minecraft:rail 1
setblock ~20~6~38 minecraft:rail 7
setblock ~21~5~38 minecraft:wool 0
fill ~21~6~38 ~21~7~38 minecraft:fence 1
fill ~23~0~38 ~23~5~38 minecraft:wool 0
setblock ~24~0~38 minecraft:fence 0
fill ~24~1~38 ~24~1~39 minecraft:wool 0
fill ~24~2~38 ~24~2~39 minecraft:fence 1
fill ~24~5~38 ~29~5~41 minecraft:wool 0
setblock ~26~0~38 minecraft:fence 0
setblock ~26~1~38 minecraft:redstone_block
fill ~29~0~38 ~29~4~41 minecraft:wool 0
fill ~32~19~38 ~34~19~54 minecraft:fence 0
setblock ~32~20~38 minecraft:wool 0
fill ~32~22~38 ~32~22~39 minecraft:fence 1
setblock ~33~20~38 minecraft:planks 0
setblock ~33~21~38 minecraft:rail 5
setblock ~34~20~38 minecraft:wool 0
fill ~34~21~38 ~34~22~38 minecraft:fence 1
fill ~41~1~38 ~41~1~39 minecraft:golden_rail 0
fill ~4~3~39 ~4~3~40 minecraft:planks 0
fill ~18~5~39 ~19~5~39 minecraft:wool 0
fill ~18~6~39 ~19~6~39 minecraft:fence 1
fill ~19~7~39 ~19~7~41 minecraft:fence 1
setblock ~20~5~39 minecraft:planks 0
setblock ~20~6~39 minecraft:rail 5
setblock ~21~5~39 minecraft:fence 0
fill ~21~6~39 ~23~6~39 minecraft:wool 0
fill ~21~7~39 ~23~7~39 minecraft:fence 1
fill ~22~0~39 ~22~5~39 minecraft:wool 0
fill ~23~1~39 ~23~1~40 minecraft:wool 0
fill ~23~2~39 ~23~2~40 minecraft:fence 1
fill ~23~5~39 ~23~5~50 minecraft:wool 0
fill ~25~1~39 ~26~1~39 minecraft:planks 0
setblock ~25~2~39 minecraft:rail 6
setblock ~26~2~39 minecraft:rail 8
fill ~32~20~39 ~34~20~53 minecraft:fence 0
setblock ~32~21~39 minecraft:wool 0
fill ~32~23~39 ~32~23~40 minecraft:fence 1
setblock ~33~21~39 minecraft:planks 0
setblock ~33~22~39 minecraft:golden_rail 5
setblock ~34~21~39 minecraft:wool 0
fill ~34~22~39 ~34~23~39 minecraft:fence 1
setblock ~41~0~39 minecraft:redstone_block
fill ~43~0~39 ~43~0~41 minecraft:wool 0
fill ~43~1~39 ~43~1~41 minecraft:fence 1
setblock ~4~4~40 minecraft:rail 0
setblock ~12~0~40 minecraft:repeating_command_block 2
fill ~19~6~40 ~19~6~41 minecraft:wool 0
fill ~20~6~40 ~22~6~40 minecraft:planks 0
setblock ~20~7~40 minecraft:rail 9
fill ~21~0~40 ~21~5~42 minecraft:wool 0
setblock ~21~7~40 minecraft:rail 1
fill ~22~1~40 ~22~1~43 minecraft:wool 0
fill ~22~2~40 ~22~2~43 minecraft:fence 1
fill ~22~5~40 ~22~5~50 minecraft:wool 0
setblock ~22~7~40 minecraft:rail 7
setblock ~23~6~40 minecraft:wool 0
fill ~23~7~40 ~23~8~40 minecraft:fence 1
fill ~24~1~40 ~25~1~40 minecraft:planks 0
setblock ~24~2~40 minecraft:rail 6
setblock ~25~2~40 minecraft:rail 8
fill ~26~1~40 ~26~1~41 minecraft:wool 0
fill ~26~2~40 ~26~2~41 minecraft:fence 1
fill ~32~21~40 ~34~21~53 minecraft:fence 0
setblock ~32~22~40 minecraft:wool 0
fill ~32~24~40 ~32~24~41 minecraft:fence 1
setblock ~33~22~40 minecraft:redstone_block
setblock ~33~23~40 minecraft:golden_rail 5
setblock ~34~22~40 minecraft:wool 0
fill ~34~23~40 ~34~24~40 minecraft:fence 1
fill ~41~0~40 ~42~0~40 minecraft:planks 0
setblock ~41~1~40 minecraft:rail 9
setblock ~42~1~40 minecraft:rail 7
fill ~3~2~41 ~3~2~43 minecraft:wool 0
fill ~3~3~41 ~3~3~44 minecraft:fence 1
setblock ~4~2~41 minecraft:planks 0
setblock ~4~3~41 minecraft:rail 4
fill ~5~2~41 ~5~2~43 minecraft:wool 0
fill ~5~3~41 ~5~3~44 minecraft:fence 1
fill ~20~6~41 ~21~6~41 minecraft:wool 0
fill ~20~7~41 ~21~7~41 minecraft:fence 1
fill ~21~8~41 ~21~8~43 minecraft:fence 1
setblock ~22~6~41 minecraft:planks 0
setblock ~22~7~41 minecraft:rail 5
fill ~23~1~41 ~24~1~41 minecraft:planks 0
setblock ~23~2~41 minecraft:rail 6
fill ~23~6~41 ~25~6~41 minecraft:fence 0
fill ~23~7~41 ~25~7~41 minecraft:wool 0
fill ~23~8~41 ~25~8~41 minecraft:fence 1
setblock ~24~2~41 minecraft:rail 8
fill ~25~1~41 ~25~1~42 minecraft:wool 0
fill ~25~2~41 ~25~2~42 minecraft:fence 1
fill ~32~22~41 ~34~22~52 minecraft:fence 0
setblock ~32~23~41 minecraft:wool 0
fill ~32~25~41 ~32~25~42 minecraft:fence 1
setblock ~33~23~41 minecraft:planks 0
setblock ~33~24~41 minecraft:rail 5
setblock ~34~23~41 minecraft:wool 0
fill ~34~24~41 ~34~25~41 minecraft:fence 1
fill ~37~1~41 ~37~1~44 minecraft:golden_rail 0
setblock ~41~0~41 minecraft:wool 0
fill ~41~1~41 ~41~2~41 minecraft:fence 1
setblock ~42~0~41 minecraft:redstone_block
setblock ~42~1~41 minecraft:golden_rail 5
fill ~43~2~41 ~43~2~42 minecraft:fence 1
setblock ~4~2~42 minecraft:redstone_block
setblock ~4~3~42 minecraft:golden_rail 0
fill ~21~6~42 ~23~6~43 minecraft:fence 0
fill ~21~7~42 ~21~7~43 minecraft:wool 0
fill ~22~7~42 ~24~7~42 minecraft:planks 0
setblock ~22~8~42 minecraft:rail 9
setblock ~23~1~42 minecraft:planks 0
fill ~23~2~42 ~23~2~43 minecraft:golden_rail 0
setblock ~23~8~42 minecraft:rail 1
fill ~24~1~42 ~24~1~45 minecraft:wool 0
fill ~24~2~42 ~24~2~45 minecraft:fence 1
fill ~24~5~42 ~28~5~42 minecraft:wool 0
setblock ~24~8~42 minecraft:rail 7
fill ~25~6~42 ~25~6~47 minecraft:fence 0
setblock ~25~7~42 minecraft:wool 0
fill ~25~8~42 ~25~9~42 minecraft:fence 1
fill ~28~0~42 ~28~4~42 minecraft:wool 0
fill ~32~23~42 ~34~23~43 minecraft:fence 0
setblock ~32~24~42 minecraft:wool 0
fill ~32~26~42 ~32~26~43 minecraft:fence 1
setblock ~33~24~42 minecraft:planks 0
setblock ~33~25~42 minecraft:golden_rail 5
setblock ~34~24~42 minecraft:wool 0
fill ~34~25~42 ~34~26~42 minecraft:fence 1
setblock ~37~0~42 minecraft:redstone_block
fill ~41~0~42 ~43~0~45 minecraft:fence 0
setblock ~41~1~42 minecraft:wool 0
fill ~41~2~42 ~41~3~42 minecraft:fence 1
setblock ~42~1~42 minecraft:planks 0
setblock ~42~2~42 minecraft:golden_rail 5
setblock ~43~1~42 minecraft:wool 0
fill ~43~3~42 ~43~3~43 minecraft:fence 1
setblock ~4~2~43 minecraft:planks 0
setblock ~4~3~43 minecraft:rail 0
fill ~20~0~43 ~20~5~43 minecraft:wool 0
fill ~21~1~43 ~21~1~45 minecraft:wool 0
fill ~21~2~43 ~21~2~45 minecraft:fence 1
fill ~21~5~43 ~21~5~50 minecraft:wool 0
fill ~22~7~43 ~23~7~43 minecraft:wool 0
fill ~22~8~43 ~23~8~43 minecraft:fence 1
setblock ~23~0~43 minecraft:fence 0
setblock ~23~1~43 minecraft:redstone_block
fill ~23~9~43 ~23~9~45 minecraft:fence 1
fill ~24~5~43 ~27~5~43 minecraft:wool 0
fill ~24~6~43 ~24~6~45 minecraft:fence 0
setblock ~24~7~43 minecraft:planks 0
setblock ~24~8~43 minecraft:rail 5
fill ~25~7~43 ~27~7~47 minecraft:fence 0
fill ~25~8~43 ~27~8~43 minecraft:wool 0
fill ~25~9~43 ~27~9~43 minecraft:fence 1
fill ~26~6~43 ~27~6~47 minecraft:fence 0
fill ~27~0~43 ~27~4~43 minecraft:wool 0
fill ~32~24~43 ~34~24~43 minecraft:fence 0
setblock ~32~25~43 minecraft:wool 0
fill ~32~27~43 ~32~27~44 minecraft:fence 1
setblock ~33~25~43 minecraft:redstone_block
setblock ~33~26~43 minecraft:golden_rail 5
setblock ~34~25~43 minecraft:wool 0
fill ~34~26~43 ~34~27~43 minecraft:fence 1
fill ~37~0~43 ~37~0~45 minecraft:planks 0
fill ~41~1~43 ~44~1~45 minecraft:fence 0
fill ~41~2~43 ~41~2~45 minecraft:wool 0
fill ~41~3~43 ~41~3~45 minecraft:fence 1
fill ~42~2~43 ~42~2~44 minecraft:planks 0
setblock ~42~3~43 minecraft:rail 0
fill ~43~2~43 ~44~2~43 minecraft:wool 0
fill ~44~0~43 ~44~0~49 minecraft:fence 0
fill ~44~3~43 ~44~3~45 minecraft:fence 1
fill ~3~1~44 ~3~1~45 minecraft:wool 0
fill ~3~2~44 ~3~2~46 minecraft:fence 1
setblock ~4~1~44 minecraft:planks 0
setblock ~4~2~44 minecraft:rail 4
fill ~5~1~44 ~5~1~45 minecraft:wool 0
fill ~5~2~44 ~5~2~46 minecraft:fence 1
fill ~19~0~44 ~19~5~45 minecraft:wool 0
fill ~20~5~44 ~20~5~50 minecraft:wool 0
fill ~22~1~44 ~23~1~44 minecraft:planks 0
setblock ~22~2~44 minecraft:rail 6
setblock ~23~2~44 minecraft:rail 8
fill ~23~6~44 ~23~7~45 minecraft:fence 0
fill ~23~8~44 ~23~8~45 minecraft:wool 0
fill ~24~5~44 ~26~5~46 minecraft:wool 0
fill ~24~7~44 ~24~7~45 minecraft:fence 0
fill ~24~8~44 ~26~8~44 minecraft:planks 0
setblock ~24~9~44 minecraft:rail 9
setblock ~25~9~44 minecraft:rail 1
fill ~26~0~44 ~26~4~46 minecraft:wool 0
setblock ~26~9~44 minecraft:rail 7
fill ~27~0~44 ~27~5~49 minecraft:fence 0
setblock ~27~8~44 minecraft:wool 0
fill ~27~9~44 ~27~10~44 minecraft:fence 1
fill ~32~23~44 ~32~23~50 minecraft:standing_banner 4
fill ~32~25~44 ~34~25~50 minecraft:fence 0
setblock ~32~26~44 minecraft:wool 0
fill ~32~28~44 ~32~28~49 minecraft:fence 1
fill ~32~31~44 ~34~31~44 minecraft:wall_sign 2
setblock ~32~33~44 minecraft:glowstone
fill ~33~23~44 ~33~24~51 minecraft:fence 0
setblock ~33~26~44 minecraft:planks 0
setblock ~33~27~44 minecraft:rail 5
fill ~34~23~44 ~34~23~50 minecraft:standing_banner 12
setblock ~34~26~44 minecraft:wool 0
fill ~34~27~44 ~34~28~44 minecraft:fence 1
setblock ~34~33~44 minecraft:glowstone
fill ~39~0~44 ~39~0~46 minecraft:wool 0
fill ~39~1~44 ~39~1~46 minecraft:fence 1
setblock ~42~3~44 minecraft:rail 9
setblock ~43~2~44 minecraft:planks 0
setblock ~43~3~44 minecraft:rail 7
fill ~44~2~44 ~44~2~45 minecraft:wool 0
setblock ~4~1~45 minecraft:redstone_block
setblock ~4~2~45 minecraft:golden_rail 0
fill ~20~1~45 ~20~1~51 minecraft:wool 0
fill ~20~2~45 ~20~2~51 minecraft:fence 1
fill ~22~1~45 ~22~1~46 minecraft:planks 0
setblock ~22~2~45 minecraft:rail 0
fill ~23~1~45 ~23~1~47 minecraft:wool 0
fill ~23~2~45 ~23~2~47 minecraft:fence 1
fill ~24~8~45 ~25~8~45 minecraft:wool 0
fill ~24~9~45 ~25~9~45 minecraft:fence 1
fill ~25~10~45 ~25~10~47 minecraft:fence 1
setblock ~26~8~45 minecraft:planks 0
setblock ~26~9~45 minecraft:rail 5
fill ~27~8~45 ~29~8~49 minecraft:fence 0
fill ~27~9~45 ~29~9~45 minecraft:wool 0
fill ~27~10~45 ~29~10~45 minecraft:fence 1
fill ~28~0~45 ~29~7~49 minecraft:fence 0
fill ~31~31~45 ~31~31~48 minecraft:wall_sign 4
setblock ~31~33~45 minecraft:wall_banner 4
fill ~32~26~45 ~34~26~48 minecraft:fence 0
fill ~32~27~45 ~32~27~48 minecraft:wool 0
fill ~32~29~45 ~32~33~45 minecraft:fence 1
fill ~33~27~45 ~33~27~46 minecraft:planks 0
setblock ~33~28~45 minecraft:rail 0
fill ~33~31~45 ~34~31~45 minecraft:fence 1
fill ~34~27~45 ~34~27~48 minecraft:wool 0
fill ~34~28~45 ~34~28~48 minecraft:fence 1
fill ~34~29~45 ~34~30~45 minecraft:fence 1
fill ~34~32~45 ~34~33~45 minecraft:fence 1
fill ~35~31~45 ~35~31~48 minecraft:wall_sign 5
setblock ~35~33~45 minecraft:wall_banner 5
setblock ~37~1~45 minecraft:rail 9
fill ~38~0~45 ~38~0~47 minecraft:planks 0
setblock ~38~1~45 minecraft:rail 7
setblock ~42~2~45 minecraft:wool 0
fill ~42~3~45 ~42~4~45 minecraft:fence 1
setblock ~43~2~45 minecraft:redstone_block
setblock ~43~3~45 minecraft:golden_rail 5
fill ~44~4~45 ~44~4~46 minecraft:fence 1
fill ~3~0~46 ~3~0~49 minecraft:wool 0
fill ~3~1~46 ~3~1~49 minecraft:fence 1
fill ~4~0~46 ~4~0~48 minecraft:planks 0
setblock ~4~1~46 minecraft:golden_rail 4
fill ~5~0~46 ~5~0~55 minecraft:wool 0
fill ~5~1~46 ~5~1~51 minecraft:fence 1
fill ~18~0~46 ~18~5~51 minecraft:wool 0
fill ~19~5~46 ~19~5~50 minecraft:wool 0
fill ~21~1~46 ~21~1~48 minecraft:planks 0
setblock ~21~2~46 minecraft:rail 6
setblock ~22~2~46 minecraft:rail 8
fill ~25~8~46 ~26~8~47 minecraft:fence 0
fill ~25~9~46 ~25~9~47 minecraft:wool 0
fill ~26~9~46 ~28~9~46 minecraft:planks 0
setblock ~26~10~46 minecraft:rail 9
setblock ~27~10~46 minecraft:rail 1
setblock ~28~10~46 minecraft:rail 7
setblock ~29~9~46 minecraft:wool 0
fill ~29~10~46 ~29~11~46 minecraft:fence 1
fill ~32~31~46 ~32~31~48 minecraft:fence 1
fill ~33~28~46 ~33~28~48 minecraft:golden_rail 0
fill ~34~31~46 ~34~31~48 minecraft:fence 1
fill ~37~0~46 ~37~0~48 minecraft:wool 0
fill ~37~1~46 ~37~1~48 minecraft:fence 1
setblock ~38~1~46 minecraft:rail 0
fill ~40~0~46 ~40~0~47 minecraft:wool 0
fill ~40~1~46 ~40~1~47 minecraft:fence 1
fill ~42~0~46 ~43~2~47 minecraft:fence 0
setblock ~42~3~46 minecraft:wool 0
fill ~42~4~46 ~42~5~46 minecraft:fence 1
setblock ~43~3~46 minecraft:planks 0
setblock ~43~4~46 minecraft:golden_rail 5
fill ~44~1~46 ~44~2~49 minecraft:fence 0
setblock ~44~3~46 minecraft:wool 0
fill ~44~5~46 ~44~5~47 minecraft:fence 1
fill ~4~1~47 ~4~1~48 minecraft:rail 0
setblock ~21~0~47 minecraft:fence 0
fill ~21~2~47 ~21~2~49 minecraft:golden_rail 0
fill ~22~1~47 ~22~1~51 minecraft:wool 0
fill ~22~2~47 ~22~2~51 minecraft:fence 1
fill ~24~5~47 ~25~5~48 minecraft:wool 0
fill ~25~0~47 ~25~4~48 minecraft:wool 0
fill ~26~0~47 ~26~5~47 minecraft:fence 0
fill ~26~9~47 ~27~9~47 minecraft:wool 0
fill ~26~10~47 ~27~10~47 minecraft:fence 1
fill ~27~11~47 ~27~11~49 minecraft:fence 1
setblock ~28~9~47 minecraft:planks 0
setblock ~28~10~47 minecraft:rail 5
fill ~29~9~47 ~31~9~51 minecraft:fence 0
fill ~29~10~47 ~31~10~47 minecraft:wool 0
fill ~29~11~47 ~31~11~47 minecraft:fence 1
fill ~30~0~47 ~31~8~51 minecraft:fence 0
setblock ~33~27~47 minecraft:redstone_block
setblock ~38~1~47 minecraft:rail 9
fill ~39~0~47 ~39~0~48 minecraft:planks 0
setblock ~39~1~47 minecraft:rail 7
fill ~41~0~47 ~41~0~48 minecraft:wool 0
fill ~41~1~47 ~41~1~48 minecraft:fence 1
fill ~42~3~47 ~45~3~47 minecraft:fence 0
fill ~42~4~47 ~42~4~49 minecraft:wool 0
fill ~42~5~47 ~42~5~49 minecraft:fence 1
fill ~43~4~47 ~43~4~48 minecraft:planks 0
setblock ~43~5~47 minecraft:rail 0
fill ~44~4~47 ~45~4~47 minecraft:wool 0
fill ~45~0~47 ~45~2~50 minecraft:fence 0
fill ~45~5~47 ~45~5~49 minecraft:fence 1
fill ~27~6~48 ~27~7~49 minecraft:fence 0
fill ~27~9~48 ~28~9~49 minecraft:fence 0
fill ~27~10~48 ~27~10~49 minecraft:wool 0
fill ~28~10~48 ~30~10~48 minecraft:planks 0
setblock ~28~11~48 minecraft:rail 9
setblock ~29~11~48 minecraft:rail 1
setblock ~30~11~48 minecraft:rail 7
setblock ~31~10~48 minecraft:wool 0
fill ~31~11~48 ~31~12~48 minecraft:fence 1
setblock ~31~33~48 minecraft:wall_banner 4
fill ~32~11~48 ~33~11~48 minecraft:fence 0
fill ~32~29~48 ~32~30~48 minecraft:fence 1
fill ~32~32~48 ~32~33~48 minecraft:fence 1
setblock ~33~27~48 minecraft:planks 0
setblock ~33~31~48 minecraft:fence 1
fill ~34~29~48 ~34~30~48 minecraft:fence 1
fill ~34~32~48 ~34~33~48 minecraft:fence 1
setblock ~35~33~48 minecraft:wall_banner 5
fill ~38~0~48 ~38~0~49 minecraft:wool 0
fill ~38~1~48 ~38~1~49 minecraft:fence 1
setblock ~39~1~48 minecraft:rail 9
fill ~40~0~48 ~40~0~49 minecraft:planks 0
setblock ~40~1~48 minecraft:rail 7
fill ~42~0~48 ~42~0~49 minecraft:wool 0
fill ~42~1~48 ~42~1~49 minecraft:fence 1
fill ~43~0~48 ~43~3~48 minecraft:fence 0
setblock ~43~5~48 minecraft:rail 9
fill ~44~3~48 ~45~3~50 minecraft:fence 0
setblock ~44~4~48 minecraft:planks 0
setblock ~44~5~48 minecraft:rail 7
fill ~45~4~48 ~45~4~49 minecraft:wool 0
fill ~2~0~49 ~2~0~55 minecraft:wool 0
fill ~2~1~49 ~2~1~55 minecraft:fence 1
setblock ~4~0~49 minecraft:redstone_block
setblock ~4~1~49 minecraft:golden_rail 0
setblock ~21~1~49 minecraft:redstone_block
fill ~24~0~49 ~24~5~53 minecraft:wool 0
fill ~28~10~49 ~29~10~49 minecraft:wool 0
fill ~28~11~49 ~29~11~49 minecraft:fence 1
fill ~29~12~49 ~29~12~51 minecraft:fence 1
setblock ~30~10~49 minecraft:planks 0
setblock ~30~11~49 minecraft:rail 5
fill ~31~11~49 ~33~11~49 minecraft:wool 0
fill ~31~12~49 ~33~12~49 minecraft:fence 1
fill ~32~26~49 ~32~26~50 minecraft:wool 0
fill ~32~27~49 ~32~27~51 minecraft:fence 1
fill ~32~31~49 ~34~31~49 minecraft:wall_sign 3
setblock ~32~33~49 minecraft:glowstone
fill ~33~26~49 ~33~26~50 minecraft:planks 0
setblock ~33~27~49 minecraft:rail 4
fill ~34~11~49 ~34~11~58 minecraft:fence 0
fill ~34~12~49 ~34~16~50 minecraft:fence 0
fill ~34~26~49 ~34~26~50 minecraft:wool 0
fill ~34~27~49 ~34~27~51 minecraft:fence 1
setblock ~34~33~49 minecraft:glowstone
fill ~39~0~49 ~39~0~50 minecraft:wool 0
fill ~39~1~49 ~39~1~50 minecraft:fence 1
setblock ~40~1~49 minecraft:rail 9
fill ~41~0~49 ~41~0~50 minecraft:planks 0
setblock ~41~1~49 minecraft:rail 7
fill ~43~0~49 ~43~0~50 minecraft:wool 0
fill ~43~1~49 ~43~1~50 minecraft:fence 1
fill ~43~2~49 ~43~3~50 minecraft:fence 0
setblock ~43~4~49 minecraft:wool 0
fill ~43~5~49 ~43~6~49 minecraft:fence 1
setblock ~44~4~49 minecraft:redstone_block
setblock ~44~5~49 minecraft:golden_rail 5
fill ~45~6~49 ~45~6~50 minecraft:fence 1
fill ~3~0~50 ~4~0~50 minecraft:planks 0
setblock ~3~1~50 minecraft:rail 6
setblock ~4~1~50 minecraft:rail 8
fill ~21~1~50 ~21~1~51 minecraft:planks 0
setblock ~21~2~50 minecraft:rail 0
fill ~29~0~50 ~29~8~51 minecraft:fence 0
fill ~29~10~50 ~31~10~51 minecraft:fence 0
fill ~29~11~50 ~29~11~51 minecraft:wool 0
fill ~30~11~50 ~32~11~50 minecraft:planks 0
setblock ~30~12~50 minecraft:rail 9
setblock ~31~12~50 minecraft:rail 1
setblock ~32~12~50 minecraft:rail 7
setblock ~33~11~50 minecraft:wool 0
fill ~33~12~50 ~33~13~50 minecraft:fence 1
setblock ~33~27~50 minecraft:rail 0
fill ~40~0~50 ~40~0~51 minecraft:wool 0
fill ~40~1~50 ~40~1~51 minecraft:fence 1
setblock ~41~1~50 minecraft:rail 9
fill ~42~0~50 ~42~0~51 minecraft:planks 0
setblock ~42~1~50 minecraft:rail 7
fill ~43~4~50 ~45~4~53 minecraft:fence 0
setblock ~43~5~50 minecraft:wool 0
fill ~43~6~50 ~43~7~50 minecraft:fence 1
fill ~44~0~50 ~44~0~51 minecraft:wool 0
fill ~44~1~50 ~44~1~51 minecraft:fence 1
setblock ~44~2~50 minecraft:fence 0
setblock ~44~5~50 minecraft:planks 0
setblock ~44~6~50 minecraft:golden_rail 5
setblock ~45~5~50 minecraft:wool 0
fill ~45~7~50 ~45~7~51 minecraft:fence 1
setblock ~3~0~51 minecraft:planks 0
fill ~3~1~51 ~3~1~53 minecraft:golden_rail 0
fill ~4~0~51 ~4~0~53 minecraft:wool 0
fill ~4~1~51 ~4~1~53 minecraft:fence 1
fill ~18~6~51 ~24~6~53 minecraft:wool 0
fill ~20~3~51 ~20~3~52 minecraft:fence 1
setblock ~21~2~51 minecraft:rail 5
fill ~22~3~51 ~22~3~54 minecraft:fence 1
fill ~30~11~51 ~31~11~51 minecraft:wool 0
fill ~30~12~51 ~31~12~51 minecraft:fence 1
fill ~31~13~51 ~31~13~53 minecraft:fence 1
setblock ~32~11~51 minecraft:planks 0
setblock ~32~12~51 minecraft:rail 5
fill ~32~23~51 ~32~24~51 minecraft:fence 0
setblock ~32~25~51 minecraft:wool 0
fill ~32~26~51 ~32~26~52 minecraft:fence 1
fill ~33~11~51 ~33~11~58 minecraft:fence 0
fill ~33~12~51 ~35~12~51 minecraft:wool 0
fill ~33~13~51 ~35~13~51 minecraft:fence 1
setblock ~33~25~51 minecraft:planks 0
setblock ~33~26~51 minecraft:rail 4
fill ~34~23~51 ~34~24~51 minecraft:fence 0
setblock ~34~25~51 minecraft:wool 0
fill ~34~26~51 ~34~26~52 minecraft:fence 1
fill ~35~11~51 ~35~11~55 minecraft:fence 0
fill ~41~0~51 ~41~0~52 minecraft:wool 0
fill ~41~1~51 ~41~1~52 minecraft:fence 1
setblock ~42~1~51 minecraft:rail 9
fill ~43~0~51 ~43~0~52 minecraft:planks 0
setblock ~43~1~51 minecraft:rail 7
fill ~43~5~51 ~45~5~53 minecraft:fence 0
fill ~43~6~51 ~43~6~53 minecraft:wool 0
fill ~43~7~51 ~43~7~53 minecraft:fence 1
fill ~44~6~51 ~44~6~52 minecraft:planks 0
setblock ~44~7~51 minecraft:rail 0
fill ~45~0~51 ~45~0~52 minecraft:wool 0
fill ~45~1~51 ~45~1~52 minecraft:fence 1
fill ~45~6~51 ~46~6~51 minecraft:wool 0
fill ~46~7~51 ~46~7~53 minecraft:fence 1
setblock ~3~0~52 minecraft:redstone_block
fill ~17~0~52 ~17~6~57 minecraft:wool 0
fill ~19~2~52 ~20~2~52 minecraft:wool 0
fill ~19~3~52 ~19~3~58 minecraft:fence 1
fill ~21~2~52 ~21~2~53 minecraft:planks 0
setblock ~21~3~52 minecraft:rail 0
fill ~22~2~52 ~22~2~54 minecraft:wool 0
fill ~31~12~52 ~31~12~53 minecraft:wool 0
fill ~32~11~52 ~32~11~58 minecraft:fence 0
fill ~32~12~52 ~34~12~52 minecraft:planks 0
setblock ~32~13~52 minecraft:rail 9
fill ~32~23~52 ~32~24~52 minecraft:wool 0
fill ~32~25~52 ~32~25~53 minecraft:fence 1
setblock ~33~13~52 minecraft:rail 1
fill ~33~23~52 ~33~24~52 minecraft:planks 0
setblock ~33~25~52 minecraft:rail 4
setblock ~34~13~52 minecraft:rail 7
fill ~34~23~52 ~34~24~52 minecraft:wool 0
fill ~34~25~52 ~34~25~53 minecraft:fence 1
setblock ~35~12~52 minecraft:wool 0
fill ~35~13~52 ~35~14~52 minecraft:fence 1
fill ~42~0~52 ~42~0~53 minecraft:wool 0
fill ~42~1~52 ~42~1~53 minecraft:fence 1
setblock ~43~1~52 minecraft:rail 9
fill ~44~0~52 ~44~0~53 minecraft:planks 0
setblock ~44~1~52 minecraft:rail 7
setblock ~44~7~52 minecraft:rail 9
setblock ~45~6~52 minecraft:planks 0
setblock ~45~7~52 minecraft:rail 7
fill ~46~0~52 ~46~0~53 minecraft:wool 0
fill ~46~1~52 ~46~1~53 minecraft:fence 1
fill ~46~4~52 ~46~5~56 minecraft:fence 0
fill ~46~6~52 ~46~6~53 minecraft:wool 0
fill ~3~0~53 ~3~0~54 minecraft:planks 0
fill ~5~1~53 ~5~1~55 minecraft:fence 1
fill ~19~2~53 ~19~2~58 minecraft:wool 0
fill ~20~2~53 ~20~2~56 minecraft:planks 0
setblock ~20~3~53 minecraft:rail 6
setblock ~21~3~53 minecraft:rail 8
fill ~32~12~53 ~33~12~53 minecraft:wool 0
fill ~32~13~53 ~33~13~53 minecraft:fence 1
setblock ~32~22~53 minecraft:wool 0
fill ~32~23~53 ~32~23~54 minecraft:fence 1
setblock ~32~24~53 minecraft:fence 1
fill ~33~14~53 ~33~14~55 minecraft:fence 1
setblock ~33~22~53 minecraft:redstone_block
setblock ~33~23~53 minecraft:golden_rail 0
setblock ~34~12~53 minecraft:planks 0
setblock ~34~13~53 minecraft:rail 5
setblock ~34~22~53 minecraft:wool 0
fill ~34~23~53 ~34~23~54 minecraft:fence 1
setblock ~34~24~53 minecraft:fence 1
fill ~35~12~53 ~38~12~53 minecraft:fence 0
fill ~35~13~53 ~38~13~53 minecraft:wool 0
fill ~35~14~53 ~38~14~53 minecraft:fence 1
fill ~36~11~53 ~38~11~56 minecraft:fence 0
fill ~37~0~53 ~38~10~56 minecraft:fence 0
fill ~43~0~53 ~43~0~54 minecraft:wool 0
fill ~43~1~53 ~43~1~54 minecraft:fence 1
setblock ~44~1~53 minecraft:rail 9
setblock ~44~6~53 minecraft:wool 0
setblock ~44~7~53 minecraft:fence 1
fill ~45~0~53 ~45~0~54 minecraft:planks 0
setblock ~45~1~53 minecraft:rail 7
setblock ~45~6~53 minecraft:redstone_block
setblock ~45~7~53 minecraft:golden_rail 5
fill ~46~8~53 ~46~8~54 minecraft:fence 1
fill ~47~0~53 ~47~0~54 minecraft:wool 0
fill ~47~1~53 ~47~1~54 minecraft:fence 1
setblock ~3~1~54 minecraft:rail 9
fill ~4~0~54 ~4~0~55 minecraft:planks 0
setblock ~4~1~54 minecraft:rail 7
fill ~18~6~54 ~23~6~60 minecraft:wool 0
fill ~20~3~54 ~20~3~57 minecraft:golden_rail 0
fill ~21~0~54 ~21~1~60 minecraft:fence 0
fill ~21~2~54 ~21~2~60 minecraft:wool 0
fill ~21~3~54 ~21~3~60 minecraft:fence 1
setblock ~22~1~54 minecraft:fence 0
fill ~23~0~54 ~23~5~60 minecraft:wool 0
fill ~32~12~54 ~36~12~55 minecraft:fence 0
fill ~32~20~54 ~32~21~54 minecraft:wool 0
fill ~32~22~54 ~32~22~55 minecraft:fence 1
fill ~33~13~54 ~33~13~55 minecraft:wool 0
fill ~33~20~54 ~33~21~54 minecraft:planks 0
setblock ~33~22~54 minecraft:golden_rail 4
setblock ~34~13~54 minecraft:planks 0
setblock ~34~14~54 minecraft:rail 9
fill ~34~20~54 ~34~21~54 minecraft:wool 0
fill ~34~22~54 ~34~22~55 minecraft:fence 1
setblock ~35~13~54 minecraft:redstone_block
fill ~35~14~54 ~36~14~54 minecraft:golden_rail 1
fill ~36~13~54 ~37~13~54 minecraft:planks 0
fill ~37~12~54 ~37~12~56 minecraft:wool 0
setblock ~37~14~54 minecraft:rail 7
setblock ~38~12~54 minecraft:planks 0
fill ~38~13~54 ~39~13~54 minecraft:wool 0
fill ~38~14~54 ~40~14~54 minecraft:fence 1
fill ~39~0~54 ~40~9~61 minecraft:fence 0
fill ~39~10~54 ~40~10~57 minecraft:fence 0
fill ~39~11~54 ~40~11~55 minecraft:fence 0
fill ~39~12~54 ~40~12~54 minecraft:wool 0
fill ~40~13~54 ~40~13~57 minecraft:fence 1
fill ~44~0~54 ~44~0~55 minecraft:wool 0
fill ~44~1~54 ~44~1~55 minecraft:fence 1
fill ~44~4~54 ~45~6~55 minecraft:fence 0
setblock ~44~7~54 minecraft:wool 0
fill ~44~8~54 ~44~9~54 minecraft:fence 1
setblock ~45~1~54 minecraft:rail 9
setblock ~45~7~54 minecraft:planks 0
setblock ~45~8~54 minecraft:golden_rail 5
fill ~46~0~54 ~46~0~55 minecraft:planks 0
setblock ~46~1~54 minecraft:rail 7
fill ~46~6~54 ~46~6~63 minecraft:fence 0
setblock ~46~7~54 minecraft:wool 0
fill ~46~9~54 ~46~9~55 minecraft:fence 1
fill ~48~0~54 ~48~0~55 minecraft:wool 0
fill ~48~1~54 ~48~1~55 minecraft:fence 1
setblock ~3~0~55 minecraft:wool 0
fill ~3~1~55 ~3~2~55 minecraft:fence 1
setblock ~4~1~55 minecraft:rail 5
fill ~5~2~55 ~6~2~55 minecraft:fence 1
fill ~6~0~55 ~6~0~63 minecraft:fence 0
fill ~6~1~55 ~6~1~57 minecraft:wool 0
fill ~32~13~55 ~32~13~57 minecraft:fence 0
fill ~32~14~55 ~32~15~56 minecraft:fence 0
fill ~32~16~55 ~34~16~55 minecraft:fence 0
fill ~32~18~55 ~32~18~56 minecraft:wool 0
setblock ~32~19~55 minecraft:wool 0
fill ~32~20~55 ~32~20~56 minecraft:fence 1
setblock ~32~21~55 minecraft:fence 1
fill ~33~15~55 ~34~15~56 minecraft:fence 0
setblock ~33~18~55 minecraft:fence 0
setblock ~33~19~55 minecraft:redstone_block
setblock ~33~20~55 minecraft:golden_rail 0
fill ~34~13~55 ~36~13~55 minecraft:wool 0
fill ~34~14~55 ~36~14~55 minecraft:fence 1
fill ~34~18~55 ~34~18~56 minecraft:wool 0
setblock ~34~19~55 minecraft:wool 0
fill ~34~20~55 ~34~20~56 minecraft:fence 1
setblock ~34~21~55 minecraft:fence 1
setblock ~37~13~55 minecraft:planks 0
setblock ~37~14~55 minecraft:rail 9
setblock ~38~12~55 minecraft:redstone_block
setblock ~38~13~55 minecraft:golden_rail 3
fill ~39~12~55 ~39~12~56 minecraft:planks 0
setblock ~39~13~55 minecraft:rail 7
fill ~40~12~55 ~40~12~56 minecraft:wool 0
fill ~44~7~55 ~46~7~57 minecraft:fence 0
fill ~44~8~55 ~44~8~57 minecraft:wool 0
fill ~44~9~55 ~44~9~57 minecraft:fence 1
fill ~45~0~55 ~45~0~56 minecraft:wool 0
fill ~45~1~55 ~45~1~56 minecraft:fence 1
fill ~45~8~55 ~45~8~56 minecraft:planks 0
setblock ~45~9~55 minecraft:rail 0
setblock ~46~1~55 minecraft:rail 9
fill ~46~8~55 ~47~8~55 minecraft:wool 0
fill ~47~0~55 ~47~0~56 minecraft:planks 0
setblock ~47~1~55 minecraft:rail 7
fill ~47~4~55 ~47~6~59 minecraft:fence 0
fill ~47~9~55 ~47~9~57 minecraft:fence 1
fill ~49~0~55 ~49~0~59 minecraft:wool 0
fill ~49~1~55 ~49~1~59 minecraft:fence 1
fill ~3~0~56 ~5~0~57 minecraft:fence 0
setblock ~3~1~56 minecraft:wool 0
fill ~3~2~56 ~3~3~56 minecraft:fence 1
fill ~4~1~56 ~5~1~56 minecraft:planks 0
setblock ~4~2~56 minecraft:rail 9
setblock ~5~2~56 minecraft:rail 7
fill ~6~2~56 ~6~2~57 minecraft:fence 1
fill ~32~12~56 ~34~12~57 minecraft:fence 0
fill ~32~16~56 ~32~17~56 minecraft:wool 0
fill ~32~19~56 ~32~19~57 minecraft:fence 1
fill ~33~13~56 ~34~13~57 minecraft:fence 0
fill ~33~14~56 ~34~14~56 minecraft:fence 0
fill ~33~16~56 ~33~18~56 minecraft:planks 0
setblock ~33~19~56 minecraft:golden_rail 4
fill ~34~16~56 ~34~17~56 minecraft:wool 0
fill ~34~19~56 ~34~19~57 minecraft:fence 1
setblock ~36~12~56 minecraft:wool 0
fill ~36~13~56 ~38~13~56 minecraft:fence 1
setblock ~36~14~56 minecraft:fence 1
setblock ~38~12~56 minecraft:wool 0
setblock ~39~13~56 minecraft:golden_rail 0
setblock ~40~11~56 minecraft:fence 0
fill ~44~0~56 ~44~6~57 minecraft:fence 0
fill ~45~5~56 ~45~6~61 minecraft:fence 0
setblock ~45~9~56 minecraft:rail 9
fill ~46~0~56 ~46~0~57 minecraft:wool 0
fill ~46~1~56 ~46~1~57 minecraft:fence 1
setblock ~46~8~56 minecraft:planks 0
setblock ~46~9~56 minecraft:rail 7
setblock ~47~1~56 minecraft:rail 9
fill ~47~7~56 ~47~7~65 minecraft:fence 0
fill ~47~8~56 ~47~8~57 minecraft:wool 0
fill ~48~0~56 ~48~0~57 minecraft:planks 0
setblock ~48~1~56 minecraft:rail 7
setblock ~3~1~57 minecraft:fence 0
setblock ~3~2~57 minecraft:wool 0
fill ~3~3~57 ~4~3~57 minecraft:fence 1
setblock ~4~1~57 minecraft:wool 0
setblock ~5~1~57 minecraft:planks 0
setblock ~5~2~57 minecraft:rail 5
fill ~6~3~57 ~7~3~57 minecraft:fence 1
fill ~7~0~57 ~7~1~65 minecraft:fence 0
fill ~7~2~57 ~7~2~59 minecraft:wool 0
fill ~20~0~57 ~20~1~57 minecraft:fence 0
setblock ~20~2~57 minecraft:redstone_block
fill ~32~14~57 ~32~14~58 minecraft:wool 0
setblock ~32~15~57 minecraft:wool 0
fill ~32~16~57 ~32~16~58 minecraft:fence 1
fill ~32~17~57 ~32~18~57 minecraft:fence 1
setblock ~33~14~57 minecraft:fence 0
setblock ~33~15~57 minecraft:redstone_block
setblock ~33~16~57 minecraft:golden_rail 0
fill ~34~14~57 ~34~14~58 minecraft:wool 0
setblock ~34~15~57 minecraft:wool 0
fill ~34~16~57 ~34~16~58 minecraft:fence 1
fill ~34~17~57 ~34~18~57 minecraft:fence 1
fill ~38~0~57 ~38~9~59 minecraft:fence 0
fill ~38~10~57 ~38~10~58 minecraft:fence 0
fill ~38~11~57 ~38~11~58 minecraft:wool 0
fill ~38~12~57 ~38~12~58 minecraft:fence 1
setblock ~38~13~57 minecraft:fence 1
setblock ~39~11~57 minecraft:redstone_block
setblock ~39~12~57 minecraft:golden_rail 4
fill ~40~11~57 ~41~11~57 minecraft:wool 0
fill ~40~12~57 ~41~12~57 minecraft:fence 1
fill ~41~0~57 ~41~8~65 minecraft:fence 0
fill ~41~9~57 ~41~9~62 minecraft:fence 0
fill ~41~10~57 ~41~10~58 minecraft:fence 0
fill ~45~0~57 ~45~4~61 minecraft:fence 0
setblock ~45~8~57 minecraft:wool 0
fill ~45~9~57 ~45~10~57 minecraft:fence 1
fill ~46~5~57 ~46~5~63 minecraft:fence 0
setblock ~46~8~57 minecraft:redstone_block
setblock ~46~9~57 minecraft:golden_rail 5
fill ~47~0~57 ~47~0~61 minecraft:wool 0
fill ~47~1~57 ~47~1~61 minecraft:fence 1
fill ~47~10~57 ~47~10~58 minecraft:fence 1
fill ~48~1~57 ~48~1~59 minecraft:golden_rail 0
fill ~4~0~58 ~5~1~60 minecraft:fence 0
fill ~4~2~58 ~4~2~59 minecraft:wool 0
fill ~4~3~58 ~4~3~59 minecraft:fence 1
setblock ~4~4~58 minecraft:fence 1
fill ~5~2~58 ~6~2~58 minecraft:planks 0
setblock ~5~3~58 minecraft:rail 9
fill ~6~1~58 ~6~1~63 minecraft:fence 0
setblock ~6~3~58 minecraft:rail 7
fill ~7~3~58 ~7~3~59 minecraft:fence 1
fill ~16~0~58 ~16~6~62 minecraft:wool 0
fill ~17~6~58 ~17~6~65 minecraft:wool 0
fill ~18~2~58 ~18~2~60 minecraft:wool 0
fill ~18~3~58 ~18~3~60 minecraft:fence 1
fill ~20~2~58 ~20~2~59 minecraft:planks 0
setblock ~20~3~58 minecraft:rail 0
fill ~32~12~58 ~32~13~58 minecraft:wool 0
fill ~32~15~58 ~32~15~59 minecraft:fence 1
fill ~33~12~58 ~33~14~58 minecraft:planks 0
setblock ~33~15~58 minecraft:golden_rail 4
fill ~34~12~58 ~34~13~58 minecraft:wool 0
fill ~34~15~58 ~34~15~59 minecraft:fence 1
setblock ~39~10~58 minecraft:fence 0
fill ~39~11~58 ~40~11~58 minecraft:planks 0
setblock ~39~12~58 minecraft:rail 9
setblock ~40~12~58 minecraft:rail 7
setblock ~41~11~58 minecraft:wool 0
fill ~41~12~58 ~41~12~59 minecraft:fence 1
fill ~45~7~58 ~46~8~61 minecraft:fence 0
setblock ~45~9~58 minecraft:wool 0
fill ~45~10~58 ~45~11~58 minecraft:fence 1
fill ~46~0~58 ~46~4~63 minecraft:fence 0
setblock ~46~9~58 minecraft:planks 0
setblock ~46~10~58 minecraft:golden_rail 5
fill ~47~8~58 ~47~8~64 minecraft:fence 0
setblock ~47~9~58 minecraft:wool 0
fill ~47~11~58 ~47~11~59 minecraft:fence 1
setblock ~48~0~58 minecraft:redstone_block
setblock ~5~2~59 minecraft:wool 0
fill ~5~3~59 ~5~4~59 minecraft:fence 1
setblock ~6~2~59 minecraft:planks 0
setblock ~6~3~59 minecraft:rail 5
fill ~7~4~59 ~8~4~59 minecraft:fence 1
fill ~8~0~59 ~8~2~67 minecraft:fence 0
fill ~8~3~59 ~8~3~61 minecraft:wool 0
setblock ~18~1~59 minecraft:fence 0
setblock ~19~2~59 minecraft:planks 0
setblock ~19~3~59 minecraft:rail 6
fill ~20~1~59 ~20~1~62 minecraft:fence 0
setblock ~20~3~59 minecraft:rail 8
setblock ~32~11~59 minecraft:wool 0
fill ~32~12~59 ~32~12~60 minecraft:fence 1
fill ~32~13~59 ~32~14~59 minecraft:fence 1
setblock ~33~11~59 minecraft:redstone_block
setblock ~33~12~59 minecraft:golden_rail 0
setblock ~34~11~59 minecraft:wool 0
fill ~34~12~59 ~34~12~60 minecraft:fence 1
fill ~34~13~59 ~34~14~59 minecraft:fence 1
fill ~38~10~59 ~39~10~59 minecraft:wool 0
fill ~38~11~59 ~39~11~59 minecraft:fence 1
setblock ~40~10~59 minecraft:redstone_block
setblock ~40~11~59 minecraft:golden_rail 4
fill ~41~10~59 ~42~10~59 minecraft:wool 0
fill ~41~11~59 ~42~11~59 minecraft:fence 1
fill ~42~0~59 ~42~0~78 minecraft:fence 0
fill ~42~1~59 ~42~1~76 minecraft:fence 0
fill ~42~2~59 ~42~2~74 minecraft:fence 0
fill ~42~3~59 ~42~3~72 minecraft:fence 0
fill ~42~4~59 ~42~4~70 minecraft:fence 0
fill ~42~5~59 ~42~5~69 minecraft:fence 0
fill ~42~6~59 ~42~6~68 minecraft:fence 0
fill ~42~7~59 ~42~7~67 minecraft:fence 0
fill ~42~8~59 ~42~8~65 minecraft:fence 0
fill ~42~9~59 ~42~9~62 minecraft:fence 0
fill ~45~9~59 ~48~9~61 minecraft:fence 0
fill ~45~10~59 ~45~10~61 minecraft:wool 0
fill ~45~11~59 ~45~11~61 minecraft:fence 1
fill ~46~10~59 ~46~10~60 minecraft:planks 0
setblock ~46~11~59 minecraft:golden_rail 0
fill ~47~10~59 ~48~10~59 minecraft:wool 0
fill ~48~0~59 ~48~0~60 minecraft:planks 0
fill ~48~4~59 ~48~8~59 minecraft:fence 0
fill ~48~11~59 ~48~11~61 minecraft:fence 1
fill ~50~0~59 ~50~0~62 minecraft:wool 0
fill ~50~1~59 ~50~1~62 minecraft:fence 1
fill ~5~2~60 ~7~2~61 minecraft:fence 0
fill ~5~3~60 ~5~3~61 minecraft:wool 0
fill ~5~4~60 ~5~4~61 minecraft:fence 1
fill ~6~3~60 ~7~3~60 minecraft:planks 0
setblock ~6~4~60 minecraft:rail 9
setblock ~7~4~60 minecraft:rail 7
fill ~8~4~60 ~8~4~61 minecraft:fence 1
fill ~17~2~60 ~17~2~62 minecraft:wool 0
fill ~17~3~60 ~17~3~62 minecraft:fence 1
fill ~19~0~60 ~19~1~60 minecraft:fence 0
setblock ~19~2~60 minecraft:redstone_block
setblock ~19~3~60 minecraft:golden_rail 0
fill ~20~2~60 ~20~2~62 minecraft:wool 0
fill ~20~3~60 ~20~3~62 minecraft:fence 1
fill ~32~9~60 ~32~10~60 minecraft:wool 0
fill ~32~11~60 ~32~11~61 minecraft:fence 1
fill ~33~9~60 ~33~10~60 minecraft:planks 0
setblock ~33~11~60 minecraft:golden_rail 4
fill ~34~9~60 ~34~10~60 minecraft:wool 0
fill ~34~11~60 ~34~11~61 minecraft:fence 1
fill ~39~10~60 ~39~10~61 minecraft:wool 0
fill ~39~11~60 ~39~11~61 minecraft:fence 1
fill ~40~10~60 ~41~10~60 minecraft:planks 0
setblock ~40~11~60 minecraft:rail 9
setblock ~41~11~60 minecraft:rail 7
fill ~42~10~60 ~43~10~60 minecraft:wool 0
fill ~42~11~60 ~43~11~60 minecraft:fence 1
fill ~43~0~60 ~43~0~77 minecraft:fence 0
fill ~43~1~60 ~43~1~76 minecraft:fence 0
fill ~43~2~60 ~43~2~74 minecraft:fence 0
fill ~43~3~60 ~43~3~72 minecraft:fence 0
fill ~43~4~60 ~43~4~70 minecraft:fence 0
fill ~43~5~60 ~43~5~69 minecraft:fence 0
fill ~43~6~60 ~43~6~68 minecraft:fence 0
fill ~43~7~60 ~43~7~67 minecraft:fence 0
fill ~43~8~60 ~43~8~65 minecraft:fence 0
fill ~43~9~60 ~43~9~62 minecraft:fence 0
setblock ~46~11~60 minecraft:rail 9
fill ~47~5~60 ~48~6~65 minecraft:fence 0
fill ~47~10~60 ~47~10~62 minecraft:planks 0
setblock ~47~11~60 minecraft:rail 7
setblock ~48~1~60 minecraft:rail 9
fill ~48~7~60 ~48~7~66 minecraft:fence 0
fill ~48~8~60 ~48~8~64 minecraft:fence 0
fill ~48~10~60 ~48~10~61 minecraft:wool 0
fill ~49~0~60 ~49~0~61 minecraft:planks 0
setblock ~49~1~60 minecraft:rail 7
fill ~5~0~61 ~5~1~61 minecraft:fence 0
setblock ~6~3~61 minecraft:wool 0
fill ~6~4~61 ~6~5~61 minecraft:fence 1
setblock ~7~3~61 minecraft:planks 0
setblock ~7~4~61 minecraft:rail 5
fill ~8~5~61 ~9~5~61 minecraft:fence 1
fill ~9~0~61 ~9~3~69 minecraft:fence 0
fill ~9~4~61 ~9~4~63 minecraft:wool 0
fill ~18~2~61 ~19~2~61 minecraft:planks 0
setblock ~18~3~61 minecraft:rail 6
fill ~18~6~61 ~22~6~62 minecraft:wool 0
fill ~19~1~61 ~19~1~64 minecraft:fence 0
setblock ~19~3~61 minecraft:rail 8
fill ~22~0~61 ~22~5~62 minecraft:wool 0
fill ~32~7~61 ~32~7~62 minecraft:wool 0
setblock ~32~8~61 minecraft:wool 0
fill ~32~9~61 ~32~9~62 minecraft:fence 1
setblock ~32~10~61 minecraft:fence 1
setblock ~33~7~61 minecraft:fence 0
setblock ~33~8~61 minecraft:redstone_block
setblock ~33~9~61 minecraft:golden_rail 0
fill ~34~7~61 ~34~7~62 minecraft:wool 0
setblock ~34~8~61 minecraft:wool 0
fill ~34~9~61 ~34~9~62 minecraft:fence 1
setblock ~34~10~61 minecraft:fence 1
fill ~40~10~61 ~40~10~62 minecraft:wool 0
fill ~40~11~61 ~40~11~62 minecraft:fence 1
fill ~41~10~61 ~42~10~61 minecraft:planks 0
setblock ~41~11~61 minecraft:rail 9
setblock ~42~11~61 minecraft:rail 7
fill ~43~10~61 ~43~10~62 minecraft:wool 0
fill ~43~11~61 ~43~11~63 minecraft:fence 1
fill ~46~10~61 ~46~10~62 minecraft:wool 0
fill ~46~11~61 ~46~11~63 minecraft:fence 1
setblock ~47~11~61 minecraft:rail 0
fill ~48~0~61 ~48~0~62 minecraft:wool 0
fill ~48~1~61 ~48~1~62 minecraft:fence 1
setblock ~49~1~61 minecraft:golden_rail 0
fill ~49~5~61 ~49~5~69 minecraft:fence 0
fill ~49~6~61 ~49~6~68 minecraft:fence 0
fill ~49~7~61 ~49~7~66 minecraft:fence 0
fill ~49~8~61 ~49~8~64 minecraft:fence 0
fill ~49~9~61 ~49~9~62 minecraft:fence 0
fill ~49~10~61 ~49~10~62 minecraft:wool 0
fill ~49~11~61 ~49~11~63 minecraft:fence 1
fill ~6~2~62 ~7~3~63 minecraft:fence 0
fill ~6~4~62 ~6~4~63 minecraft:wool 0
fill ~6~5~62 ~6~5~63 minecraft:fence 1
fill ~7~4~62 ~8~4~62 minecraft:planks 0
setblock ~7~5~62 minecraft:rail 9
fill ~8~3~62 ~8~3~67 minecraft:fence 0
setblock ~8~5~62 minecraft:rail 7
fill ~9~5~62 ~9~5~63 minecraft:fence 1
fill ~17~1~62 ~17~1~64 minecraft:fence 0
fill ~18~2~62 ~18~2~63 minecraft:planks 0
setblock ~18~3~62 minecraft:rail 0
fill ~19~2~62 ~19~2~64 minecraft:wool 0
fill ~19~3~62 ~19~3~64 minecraft:fence 1
fill ~32~5~62 ~32~6~62 minecraft:wool 0
fill ~32~8~62 ~32~8~63 minecraft:fence 1
fill ~33~5~62 ~33~7~62 minecraft:planks 0
setblock ~33~8~62 minecraft:golden_rail 4
fill ~34~5~62 ~34~6~62 minecraft:wool 0
fill ~34~8~62 ~34~8~63 minecraft:fence 1
fill ~40~0~62 ~40~9~62 minecraft:fence 0
setblock ~41~10~62 minecraft:wool 0
fill ~41~11~62 ~41~11~63 minecraft:fence 1
setblock ~42~10~62 minecraft:redstone_block
setblock ~42~11~62 minecraft:golden_rail 0
fill ~46~7~62 ~46~8~63 minecraft:fence 0
fill ~46~9~62 ~48~9~62 minecraft:fence 0
setblock ~47~11~62 minecraft:rail 9
fill ~48~2~62 ~48~2~70 minecraft:fence 1
setblock ~48~10~62 minecraft:planks 0
setblock ~48~11~62 minecraft:rail 7
setblock ~49~0~62 minecraft:redstone_block
setblock ~49~1~62 minecraft:golden_rail 5
fill ~50~2~62 ~50~2~70 minecraft:fence 1
setblock ~7~4~63 minecraft:wool 0
fill ~7~5~63 ~7~6~63 minecraft:fence 1
setblock ~8~4~63 minecraft:planks 0
setblock ~8~5~63 minecraft:rail 5
fill ~9~6~63 ~10~6~63 minecraft:fence 1
fill ~10~0~63 ~10~4~71 minecraft:fence 0
fill ~10~5~63 ~10~5~65 minecraft:wool 0
fill ~15~0~63 ~15~6~63 minecraft:wool 0
fill ~16~1~63 ~16~1~64 minecraft:fence 0
fill ~16~2~63 ~16~2~64 minecraft:wool 0
fill ~16~3~63 ~16~3~65 minecraft:fence 1
fill ~16~6~63 ~16~6~64 minecraft:wool 0
fill ~17~2~63 ~17~2~64 minecraft:planks 0
setblock ~17~3~63 minecraft:rail 6
setblock ~18~3~63 minecraft:rail 8
fill ~18~6~63 ~21~6~65 minecraft:wool 0
fill ~21~0~63 ~21~5~65 minecraft:wool 0
fill ~32~3~63 ~32~3~64 minecraft:wool 0
setblock ~32~4~63 minecraft:wool 0
fill ~32~5~63 ~32~5~64 minecraft:fence 1
fill ~32~6~63 ~32~7~63 minecraft:fence 1
setblock ~33~4~63 minecraft:redstone_block
setblock ~33~5~63 minecraft:golden_rail 0
fill ~34~3~63 ~34~3~64 minecraft:wool 0
setblock ~34~4~63 minecraft:wool 0
fill ~34~5~63 ~34~5~64 minecraft:fence 1
fill ~34~6~63 ~34~7~63 minecraft:fence 1
fill ~41~9~63 ~41~9~65 minecraft:wool 0
fill ~41~10~63 ~41~10~65 minecraft:fence 1
fill ~42~9~63 ~42~9~64 minecraft:planks 0
setblock ~42~10~63 minecraft:golden_rail 4
fill ~43~9~63 ~44~9~63 minecraft:wool 0
fill ~43~10~63 ~44~10~63 minecraft:fence 1
fill ~44~0~63 ~44~0~78 minecraft:fence 0
fill ~44~1~63 ~44~1~76 minecraft:fence 0
fill ~44~2~63 ~44~2~74 minecraft:fence 0
fill ~44~3~63 ~44~3~72 minecraft:fence 0
fill ~44~4~63 ~44~4~70 minecraft:fence 0
fill ~44~5~63 ~44~5~69 minecraft:fence 0
fill ~44~6~63 ~44~6~68 minecraft:fence 0
fill ~44~7~63 ~44~7~67 minecraft:fence 0
fill ~44~8~63 ~44~8~65 minecraft:fence 0
fill ~46~9~63 ~47~9~63 minecraft:wool 0
fill ~46~10~63 ~47~10~63 minecraft:fence 1
fill ~47~0~63 ~50~0~65 minecraft:fence 0
fill ~47~1~63 ~47~4~65 minecraft:fence 0
fill ~48~1~63 ~48~1~70 minecraft:wool 0
fill ~48~9~63 ~48~9~64 minecraft:planks 0
setblock ~48~10~63 minecraft:rail 4
fill ~49~1~63 ~49~1~64 minecraft:planks 0
setblock ~49~2~63 minecraft:rail 0
fill ~49~9~63 ~50~9~63 minecraft:wool 0
fill ~49~10~63 ~50~10~63 minecraft:fence 1
fill ~50~1~63 ~50~1~70 minecraft:wool 0
fill ~50~5~63 ~50~5~69 minecraft:fence 0
fill ~50~6~63 ~50~6~67 minecraft:fence 0
fill ~50~7~63 ~50~7~66 minecraft:fence 0
fill ~50~8~63 ~50~8~64 minecraft:fence 0
fill ~7~2~64 ~7~4~65 minecraft:fence 0
fill ~7~5~64 ~7~5~65 minecraft:wool 0
fill ~7~6~64 ~7~6~65 minecraft:fence 1
fill ~8~4~64 ~9~4~67 minecraft:fence 0
fill ~8~5~64 ~9~5~64 minecraft:planks 0
setblock ~8~6~64 minecraft:rail 9
setblock ~9~6~64 minecraft:rail 7
fill ~10~6~64 ~10~6~65 minecraft:fence 1
fill ~14~0~64 ~14~5~64 minecraft:wool 0
fill ~15~5~64 ~15~5~69 minecraft:wool 0
setblock ~17~3~64 minecraft:golden_rail 0
setblock ~18~1~64 minecraft:fence 0
setblock ~18~2~64 minecraft:wool 0
fill ~18~3~64 ~18~3~65 minecraft:fence 1
setblock ~32~2~64 minecraft:wool 0
fill ~32~4~64 ~32~4~65 minecraft:fence 1
fill ~33~2~64 ~33~3~64 minecraft:planks 0
setblock ~33~4~64 minecraft:golden_rail 4
setblock ~34~2~64 minecraft:wool 0
fill ~34~4~64 ~34~4~65 minecraft:fence 1
setblock ~42~10~64 minecraft:rail 9
setblock ~43~9~64 minecraft:planks 0
setblock ~43~10~64 minecraft:rail 7
fill ~44~9~64 ~44~9~65 minecraft:wool 0
fill ~44~10~64 ~44~10~66 minecraft:fence 1
setblock ~47~9~64 minecraft:wool 0
fill ~47~10~64 ~47~10~65 minecraft:fence 1
setblock ~48~10~64 minecraft:rail 9
fill ~49~2~64 ~49~2~66 minecraft:golden_rail 0
setblock ~49~9~64 minecraft:planks 0
setblock ~49~10~64 minecraft:rail 7
setblock ~50~9~64 minecraft:wool 0
fill ~50~10~64 ~50~10~65 minecraft:fence 1
setblock ~8~5~65 minecraft:wool 0
fill ~8~6~65 ~8~7~65 minecraft:fence 1
setblock ~9~5~65 minecraft:planks 0
setblock ~9~6~65 minecraft:rail 5
fill ~10~7~65 ~11~7~65 minecraft:fence 1
fill ~11~6~65 ~11~6~67 minecraft:wool 0
fill ~13~0~65 ~13~5~65 minecraft:wool 0
fill ~14~5~65 ~14~5~68 minecraft:wool 0
fill ~15~0~65 ~17~0~65 minecraft:fence 0
fill ~15~1~65 ~16~1~65 minecraft:wool 0
fill ~15~2~65 ~16~2~65 minecraft:fence 1
fill ~16~5~65 ~16~5~70 minecraft:wool 0
setblock ~17~1~65 minecraft:redstone_block
setblock ~17~2~65 minecraft:golden_rail 4
fill ~18~1~65 ~18~1~68 minecraft:wool 0
fill ~18~2~65 ~18~2~67 minecraft:fence 1
setblock ~32~1~65 minecraft:wool 0
fill ~32~2~65 ~32~2~66 minecraft:fence 1
setblock ~32~3~65 minecraft:fence 1
setblock ~33~1~65 minecraft:planks 0
setblock ~33~2~65 minecraft:rail 0
setblock ~34~1~65 minecraft:wool 0
fill ~34~2~65 ~34~2~66 minecraft:fence 1
setblock ~34~3~65 minecraft:fence 1
setblock ~42~9~65 minecraft:wool 0
fill ~42~10~65 ~42~10~66 minecraft:fence 1
setblock ~43~9~65 minecraft:redstone_block
setblock ~43~10~65 minecraft:golden_rail 0
fill ~47~8~65 ~48~8~65 minecraft:wool 0
fill ~47~9~65 ~48~9~65 minecraft:fence 1
setblock ~49~1~65 minecraft:redstone_block
fill ~49~8~65 ~49~8~66 minecraft:planks 0
setblock ~49~9~65 minecraft:rail 4
fill ~50~8~65 ~51~8~65 minecraft:wool 0
fill ~50~9~65 ~51~9~65 minecraft:fence 1
fill ~51~0~65 ~51~4~72 minecraft:fence 0
fill ~51~5~65 ~51~5~70 minecraft:fence 0
fill ~51~6~65 ~51~6~68 minecraft:fence 0
fill ~51~7~65 ~51~7~66 minecraft:fence 0
fill ~8~5~66 ~11~5~67 minecraft:fence 0
fill ~8~6~66 ~8~6~67 minecraft:wool 0
fill ~8~7~66 ~8~7~67 minecraft:fence 1
fill ~9~6~66 ~10~6~66 minecraft:planks 0
setblock ~9~7~66 minecraft:rail 9
setblock ~10~7~66 minecraft:rail 7
fill ~11~0~66 ~11~4~71 minecraft:fence 0
fill ~11~7~66 ~11~7~67 minecraft:fence 1
fill ~12~0~66 ~12~5~66 minecraft:wool 0
fill ~13~5~66 ~13~5~67 minecraft:wool 0
fill ~14~1~66 ~15~1~66 minecraft:wool 0
fill ~14~2~66 ~15~2~66 minecraft:fence 1
fill ~16~0~66 ~18~0~67 minecraft:fence 0
fill ~16~1~66 ~17~1~66 minecraft:planks 0
setblock ~16~2~66 minecraft:rail 6
setblock ~17~2~66 minecraft:rail 8
fill ~17~5~66 ~17~5~69 minecraft:wool 0
fill ~18~6~66 ~20~6~66 minecraft:wool 0
fill ~20~0~66 ~20~5~66 minecraft:wool 0
fill ~32~0~66 ~32~0~69 minecraft:wool 0
fill ~32~1~66 ~32~1~69 minecraft:fence 1
setblock ~33~0~66 minecraft:planks 0
setblock ~33~1~66 minecraft:golden_rail 4
fill ~34~0~66 ~34~0~71 minecraft:wool 0
fill ~34~1~66 ~34~1~71 minecraft:fence 1
fill ~42~8~66 ~42~8~67 minecraft:wool 0
fill ~42~9~66 ~42~9~68 minecraft:fence 1
fill ~43~8~66 ~43~8~67 minecraft:planks 0
setblock ~43~9~66 minecraft:golden_rail 4
fill ~44~8~66 ~44~8~67 minecraft:wool 0
fill ~44~9~66 ~44~9~68 minecraft:fence 1
fill ~48~0~66 ~50~0~93 minecraft:fence 0
fill ~48~5~66 ~48~6~66 minecraft:fence 0
setblock ~48~8~66 minecraft:wool 0
fill ~48~9~66 ~48~9~67 minecraft:fence 1
fill ~49~1~66 ~49~1~68 minecraft:planks 0
setblock ~49~9~66 minecraft:rail 9
setblock ~50~8~66 minecraft:planks 0
setblock ~50~9~66 minecraft:rail 7
setblock ~51~8~66 minecraft:wool 0
fill ~51~9~66 ~51~9~67 minecraft:fence 1
setblock ~9~6~67 minecraft:wool 0
fill ~9~7~67 ~9~8~67 minecraft:fence 1
setblock ~10~6~67 minecraft:planks 0
setblock ~10~7~67 minecraft:rail 5
fill ~11~8~67 ~12~8~67 minecraft:fence 1
fill ~12~7~67 ~12~7~69 minecraft:wool 0
fill ~13~1~67 ~14~1~67 minecraft:wool 0
fill ~13~2~67 ~14~2~67 minecraft:fence 1
fill ~15~1~67 ~16~1~67 minecraft:planks 0
setblock ~15~2~67 minecraft:rail 6
setblock ~16~2~67 minecraft:rail 8
fill ~17~1~67 ~17~1~69 minecraft:wool 0
fill ~17~2~67 ~17~2~68 minecraft:fence 1
fill ~18~5~67 ~19~5~67 minecraft:wool 0
fill ~19~0~67 ~19~4~67 minecraft:wool 0
setblock ~19~6~67 minecraft:wool 0
setblock ~33~0~67 minecraft:redstone_block
fill ~33~1~67 ~33~1~68 minecraft:golden_rail 0
setblock ~43~9~67 minecraft:golden_rail 0
fill ~48~7~67 ~49~7~67 minecraft:wool 0
fill ~48~8~67 ~49~8~67 minecraft:fence 1
setblock ~49~2~67 minecraft:rail 0
fill ~50~7~67 ~50~7~68 minecraft:planks 0
setblock ~50~8~67 minecraft:rail 4
fill ~51~7~67 ~53~7~67 minecraft:wool 0
fill ~51~8~67 ~53~8~67 minecraft:fence 1
fill ~52~0~67 ~53~2~75 minecraft:fence 0
fill ~52~3~67 ~53~3~74 minecraft:fence 0
fill ~52~4~67 ~53~4~72 minecraft:fence 0
fill ~52~5~67 ~53~5~70 minecraft:fence 0
fill ~52~6~67 ~53~6~68 minecraft:fence 0
fill ~9~4~68 ~9~6~69 minecraft:fence 0
fill ~9~7~68 ~9~7~69 minecraft:wool 0
fill ~9~8~68 ~9~8~69 minecraft:fence 1
fill ~10~5~68 ~12~6~71 minecraft:fence 0
fill ~10~7~68 ~11~7~68 minecraft:planks 0
setblock ~10~8~68 minecraft:rail 9
setblock ~11~8~68 minecraft:rail 7
fill ~12~0~68 ~12~4~68 minecraft:fence 0
fill ~12~8~68 ~12~8~69 minecraft:fence 1
fill ~13~1~68 ~13~1~69 minecraft:wool 0
fill ~13~2~68 ~13~2~70 minecraft:fence 1
fill ~14~1~68 ~15~1~68 minecraft:planks 0
setblock ~14~2~68 minecraft:rail 6
setblock ~15~2~68 minecraft:rail 8
fill ~16~0~68 ~17~0~68 minecraft:fence 0
fill ~16~1~68 ~16~1~70 minecraft:wool 0
fill ~16~2~68 ~16~2~69 minecraft:fence 1
setblock ~18~0~68 minecraft:wool 0
fill ~18~2~68 ~18~5~68 minecraft:wool 0
fill ~33~0~68 ~33~0~70 minecraft:planks 0
setblock ~42~7~68 minecraft:wool 0
fill ~42~8~68 ~42~8~69 minecraft:fence 1
setblock ~43~7~68 minecraft:planks 0
setblock ~43~8~68 minecraft:rail 4
setblock ~44~7~68 minecraft:wool 0
fill ~44~8~68 ~44~8~69 minecraft:fence 1
fill ~49~2~68 ~49~2~69 minecraft:golden_rail 0
setblock ~49~7~68 minecraft:wool 0
fill ~49~8~68 ~49~8~69 minecraft:fence 1
setblock ~50~8~68 minecraft:rail 9
fill ~51~7~68 ~52~7~68 minecraft:planks 0
setblock ~51~8~68 minecraft:rail 1
setblock ~52~8~68 minecraft:rail 7
setblock ~53~7~68 minecraft:wool 0
setblock ~53~8~68 minecraft:fence 1
fill ~10~7~69 ~10~7~71 minecraft:wool 0
fill ~10~8~69 ~10~8~71 minecraft:fence 1
fill ~11~7~69 ~11~7~70 minecraft:planks 0
setblock ~11~8~69 minecraft:rail 0
fill ~12~1~69 ~12~4~69 minecraft:fence 0
fill ~13~5~69 ~13~5~74 minecraft:fence 0
fill ~13~6~69 ~13~6~71 minecraft:fence 0
fill ~13~7~69 ~13~7~71 minecraft:wool 0
fill ~13~8~69 ~13~8~71 minecraft:fence 1
setblock ~14~1~69 minecraft:planks 0
setblock ~14~2~69 minecraft:golden_rail 0
setblock ~15~1~69 minecraft:wool 0
fill ~15~2~69 ~15~2~70 minecraft:fence 1
setblock ~17~0~69 minecraft:wool 0
fill ~17~2~69 ~17~4~69 minecraft:wool 0
fill ~31~0~69 ~31~0~72 minecraft:wool 0
fill ~31~1~69 ~31~1~72 minecraft:fence 1
setblock ~33~1~69 minecraft:rail 0
setblock ~42~6~69 minecraft:wool 0
fill ~42~7~69 ~42~7~70 minecraft:fence 1
setblock ~43~6~69 minecraft:planks 0
setblock ~43~7~69 minecraft:golden_rail 4
setblock ~44~6~69 minecraft:wool 0
fill ~44~7~69 ~44~7~70 minecraft:fence 1
setblock ~49~1~69 minecraft:redstone_block
fill ~49~6~69 ~51~6~69 minecraft:wool 0
fill ~49~7~69 ~51~7~69 minecraft:fence 1
fill ~52~6~69 ~52~6~70 minecraft:planks 0
setblock ~52~7~69 minecraft:rail 4
fill ~53~6~69 ~53~6~70 minecraft:wool 0
fill ~53~7~69 ~53~7~70 minecraft:fence 1
setblock ~11~8~70 minecraft:rail 9
fill ~12~0~70 ~13~0~70 minecraft:wool 0
fill ~12~1~70 ~13~1~70 minecraft:fence 1
setblock ~12~7~70 minecraft:planks 0
setblock ~12~8~70 minecraft:rail 7
setblock ~14~0~70 minecraft:redstone_block
setblock ~14~1~70 minecraft:golden_rail 4
fill ~15~0~70 ~16~0~70 minecraft:wool 0
fill ~15~1~70 ~15~1~72 minecraft:fence 1
fill ~16~2~70 ~16~4~70 minecraft:wool 0
setblock ~32~0~70 minecraft:planks 0
setblock ~32~1~70 minecraft:rail 6
setblock ~33~1~70 minecraft:rail 8
setblock ~42~5~70 minecraft:wool 0
fill ~42~6~70 ~42~6~71 minecraft:fence 1
setblock ~43~5~70 minecraft:redstone_block
setblock ~43~6~70 minecraft:golden_rail 4
setblock ~44~5~70 minecraft:wool 0
fill ~44~6~70 ~44~6~71 minecraft:fence 1
fill ~48~3~70 ~48~3~76 minecraft:fence 1
setblock ~49~1~70 minecraft:planks 0
setblock ~49~2~70 minecraft:golden_rail 5
fill ~50~3~70 ~50~3~76 minecraft:fence 1
setblock ~51~6~70 minecraft:wool 0
fill ~51~7~70 ~51~7~71 minecraft:fence 1
setblock ~52~7~70 minecraft:rail 0
fill ~11~7~71 ~11~7~72 minecraft:wool 0
