fill ~2~0~0 ~175~0~5 minecraft:grass
fill ~0~0~2 ~1~0~175 minecraft:grass
fill ~77~41~5 ~96~41~7 minecraft:stonebrick 0
fill ~77~42~5 ~96~42~5 minecraft:stonebrick 0
fill ~78~16~5 ~96~16~7 minecraft:stonebrick 0
fill ~78~17~5 ~96~17~5 minecraft:stonebrick 0
fill ~78~30~5 ~96~30~7 minecraft:stonebrick 0
fill ~78~31~5 ~96~31~5 minecraft:stonebrick 0
fill ~78~58~5 ~96~58~9 minecraft:stonebrick 0
fill ~79~15~5 ~81~15~7 minecraft:stonebrick 0
fill ~79~29~5 ~81~29~7 minecraft:stonebrick 0
fill ~79~59~5 ~79~62~5 minecraft:fence 0
setblock ~79~63~5 minecraft:torch 5
fill ~83~59~5 ~83~62~5 minecraft:fence 0
setblock ~83~63~5 minecraft:torch 5
fill ~87~59~5 ~87~62~5 minecraft:fence 0
setblock ~87~63~5 minecraft:torch 5
fill ~91~29~5 ~95~29~6 minecraft:stonebrick 0
fill ~91~59~5 ~91~62~5 minecraft:fence 0
setblock ~91~63~5 minecraft:torch 5
fill ~92~15~5 ~94~15~7 minecraft:stonebrick 0
fill ~92~28~5 ~94~28~6 minecraft:stonebrick 0
fill ~95~59~5 ~95~62~5 minecraft:fence 0
setblock ~95~63~5 minecraft:torch 5
fill ~2~0~6 ~77~0~6 minecraft:grass
fill ~72~16~6 ~77~16~8 minecraft:stonebrick 0
fill ~72~17~6 ~82~17~6 minecraft:stonebrick 0
fill ~72~30~6 ~77~30~8 minecraft:stonebrick 0
fill ~72~31~6 ~77~31~6 minecraft:stonebrick 0
fill ~72~41~6 ~76~41~8 minecraft:stonebrick 0
fill ~72~42~6 ~76~42~6 minecraft:stonebrick 0
fill ~72~58~6 ~77~58~10 minecraft:stonebrick 0
fill ~75~59~6 ~75~62~6 minecraft:fence 0
setblock ~75~63~6 minecraft:torch 5
fill ~78~0~6 ~82~0~6 minecraft:dirt 0
fill ~78~1~6 ~82~1~7 minecraft:stonebrick 0
fill ~78~15~6 ~78~15~12 minecraft:stonebrick 0
fill ~78~29~6 ~78~29~12 minecraft:stonebrick 0
fill ~78~49~6 ~96~49~7 minecraft:stonebrick 0
fill ~78~57~6 ~96~57~8 minecraft:stonebrick 0
fill ~79~14~6 ~81~14~7 minecraft:stonebrick 0
fill ~79~28~6 ~81~28~7 minecraft:stonebrick 0
fill ~82~15~6 ~82~15~12 minecraft:stonebrick 0
fill ~82~29~6 ~82~29~12 minecraft:stonebrick 0
fill ~83~0~6 ~90~0~6 minecraft:grass
fill ~90~17~6 ~102~17~6 minecraft:stonebrick 0
fill ~90~29~6 ~90~29~10 minecraft:stonebrick 0
fill ~91~0~6 ~95~0~6 minecraft:dirt 0
fill ~91~1~6 ~95~1~7 minecraft:stonebrick 0
fill ~91~15~6 ~91~15~12 minecraft:stonebrick 0
fill ~91~28~6 ~91~28~10 minecraft:stonebrick 0
fill ~91~31~6 ~95~31~10 minecraft:stonebrick 0
fill ~91~40~6 ~95~40~10 minecraft:stonebrick 0
fill ~91~42~6 ~95~42~7 minecraft:stonebrick 0
fill ~91~48~6 ~95~48~7 minecraft:stonebrick 0
fill ~92~14~6 ~94~14~7 minecraft:stonebrick 0
fill ~92~18~6 ~94~27~6 minecraft:stonebrick 0
fill ~95~15~6 ~95~15~12 minecraft:stonebrick 0
fill ~95~28~6 ~95~28~10 minecraft:stonebrick 0
fill ~96~0~6 ~175~0~6 minecraft:grass
fill ~96~29~6 ~96~29~10 minecraft:stonebrick 0
fill ~97~16~6 ~102~16~8 minecraft:stonebrick 0
fill ~97~30~6 ~102~30~8 minecraft:stonebrick 0
fill ~97~31~6 ~102~31~6 minecraft:stonebrick 0
fill ~97~41~6 ~102~41~8 minecraft:stonebrick 0
fill ~97~42~6 ~102~42~6 minecraft:stonebrick 0
fill ~97~58~6 ~102~58~10 minecraft:stonebrick 0
fill ~99~59~6 ~99~62~6 minecraft:fence 0
setblock ~99~63~6 minecraft:torch 5
fill ~2~0~7 ~76~0~7 minecraft:grass
fill ~65~41~7 ~71~41~9 minecraft:stonebrick 0
fill ~65~42~7 ~71~42~7 minecraft:stonebrick 0
fill ~67~15~7 ~69~17~9 minecraft:stonebrick 0
fill ~67~29~7 ~69~30~9 minecraft:stonebrick 0
fill ~67~31~7 ~71~31~7 minecraft:stonebrick 0
fill ~67~58~7 ~71~58~11 minecraft:stonebrick 0
fill ~67~59~7 ~67~62~7 minecraft:fence 0
setblock ~67~63~7 minecraft:torch 5
fill ~70~16~7 ~71~16~9 minecraft:stonebrick 0
fill ~70~17~7 ~71~17~7 minecraft:stonebrick 0
fill ~70~30~7 ~71~30~9 minecraft:stonebrick 0
fill ~71~59~7 ~71~62~7 minecraft:fence 0
setblock ~71~63~7 minecraft:torch 5
fill ~72~49~7 ~77~49~8 minecraft:stonebrick 0
fill ~72~57~7 ~77~57~9 minecraft:stonebrick 0
fill ~77~0~7 ~78~0~7 minecraft:dirt 0
fill ~77~1~7 ~77~1~11 minecraft:stonebrick 0
fill ~77~15~7 ~77~15~11 minecraft:stonebrick 0
fill ~77~17~7 ~83~17~7 minecraft:stonebrick 0
fill ~77~29~7 ~77~29~11 minecraft:stonebrick 0
fill ~78~14~7 ~78~14~11 minecraft:stonebrick 0
fill ~78~28~7 ~78~28~11 minecraft:stonebrick 0
fill ~78~31~7 ~82~31~11 minecraft:stonebrick 0
fill ~78~40~7 ~82~40~11 minecraft:stonebrick 0
fill ~78~42~7 ~82~42~8 minecraft:stonebrick 0
fill ~78~48~7 ~82~48~8 minecraft:stonebrick 0
fill ~79~0~7 ~95~0~61 minecraft:cobblestone
fill ~79~2~7 ~81~13~7 minecraft:stonebrick 0
fill ~79~18~7 ~81~27~7 minecraft:stonebrick 0
fill ~79~50~7 ~95~50~7 minecraft:stonebrick 0
fill ~82~14~7 ~82~14~11 minecraft:stonebrick 0
fill ~82~28~7 ~82~28~11 minecraft:stonebrick 0
fill ~82~56~7 ~85~56~7 minecraft:stonebrick 0
fill ~83~1~7 ~83~1~11 minecraft:stonebrick 0
fill ~83~15~7 ~83~15~11 minecraft:stonebrick 0
fill ~83~29~7 ~83~29~11 minecraft:stonebrick 0
fill ~83~51~7 ~84~55~7 minecraft:stonebrick 0
fill ~89~29~7 ~89~29~9 minecraft:stonebrick 0
fill ~89~56~7 ~92~56~7 minecraft:stonebrick 0
fill ~90~1~7 ~90~1~11 minecraft:stonebrick 0
fill ~90~15~7 ~90~15~11 minecraft:stonebrick 0
fill ~90~17~7 ~91~17~10 minecraft:stonebrick 0
fill ~90~28~7 ~90~28~9 minecraft:stonebrick 0
fill ~90~51~7 ~91~55~7 minecraft:stonebrick 0
fill ~91~14~7 ~91~14~11 minecraft:stonebrick 0
fill ~91~18~7 ~91~27~9 minecraft:stonebrick 0
fill ~91~29~7 ~91~29~11 minecraft:stonebrick 0
fill ~92~2~7 ~94~13~7 minecraft:stonebrick 0
fill ~92~32~7 ~94~39~9 minecraft:stonebrick 0
fill ~92~43~7 ~94~47~7 minecraft:stonebrick 0
fill ~95~14~7 ~95~14~11 minecraft:stonebrick 0
fill ~95~17~7 ~96~17~10 minecraft:stonebrick 0
fill ~95~18~7 ~95~27~9 minecraft:stonebrick 0
fill ~95~29~7 ~95~29~11 minecraft:stonebrick 0
setblock ~96~0~7 minecraft:dirt 0
fill ~96~1~7 ~96~1~11 minecraft:stonebrick 0
fill ~96~15~7 ~96~15~11 minecraft:stonebrick 0
fill ~96~28~7 ~96~28~9 minecraft:stonebrick 0
fill ~97~0~7 ~175~0~7 minecraft:grass
fill ~97~29~7 ~97~29~9 minecraft:stonebrick 0
fill ~97~49~7 ~102~49~8 minecraft:stonebrick 0
fill ~97~57~7 ~102~57~9 minecraft:stonebrick 0
fill ~103~16~7 ~107~17~9 minecraft:stonebrick 0
fill ~103~30~7 ~107~30~9 minecraft:stonebrick 0
fill ~103~31~7 ~107~31~7 minecraft:stonebrick 0
fill ~103~41~7 ~108~41~9 minecraft:stonebrick 0
fill ~103~42~7 ~108~42~7 minecraft:stonebrick 0
fill ~103~58~7 ~107~58~11 minecraft:stonebrick 0
fill ~103~59~7 ~103~62~7 minecraft:fence 0
setblock ~103~63~7 minecraft:torch 5
fill ~104~15~7 ~106~15~9 minecraft:stonebrick 0
fill ~104~29~7 ~106~29~9 minecraft:stonebrick 0
fill ~107~59~7 ~107~62~7 minecraft:fence 0
setblock ~107~63~7 minecraft:torch 5
fill ~2~0~8 ~65~0~8 minecraft:grass
fill ~64~16~8 ~66~16~10 minecraft:stonebrick 0
fill ~64~17~8 ~66~17~8 minecraft:stonebrick 0
fill ~64~30~8 ~66~30~10 minecraft:stonebrick 0
fill ~64~31~8 ~66~31~8 minecraft:stonebrick 0
fill ~64~41~8 ~64~41~10 minecraft:stonebrick 0
setblock ~64~42~8 minecraft:stonebrick 0
fill ~64~58~8 ~66~58~12 minecraft:stonebrick 0
fill ~66~0~8 ~70~0~8 minecraft:dirt 0
fill ~66~1~8 ~70~1~9 minecraft:stonebrick 0
fill ~66~15~8 ~66~15~14 minecraft:stonebrick 0
fill ~66~29~8 ~66~29~14 minecraft:stonebrick 0
fill ~67~14~8 ~69~14~9 minecraft:stonebrick 0
fill ~67~28~8 ~69~28~9 minecraft:stonebrick 0
fill ~67~49~8 ~71~49~9 minecraft:stonebrick 0
fill ~67~57~8 ~71~57~10 minecraft:stonebrick 0
fill ~70~15~8 ~70~15~14 minecraft:stonebrick 0
fill ~70~17~8 ~70~17~14 minecraft:stonebrick 0
fill ~70~29~8 ~70~29~14 minecraft:stonebrick 0
setblock ~71~0~8 minecraft:grass
fill ~72~0~8 ~78~0~63 minecraft:cobblestone
fill ~72~50~8 ~78~50~8 minecraft:stonebrick 0
fill ~75~56~8 ~78~56~8 minecraft:stonebrick 0
fill ~76~15~8 ~76~15~10 minecraft:stonebrick 0
fill ~76~29~8 ~76~29~10 minecraft:stonebrick 0
fill ~76~51~8 ~77~55~8 minecraft:stonebrick 0
fill ~77~14~8 ~77~14~10 minecraft:stonebrick 0
fill ~77~17~8 ~78~17~11 minecraft:stonebrick 0
fill ~77~28~8 ~77~28~10 minecraft:stonebrick 0
fill ~77~41~8 ~81~41~8 minecraft:stonebrick 0
fill ~78~1~8 ~78~1~12 minecraft:stonebrick 0
fill ~78~2~8 ~78~13~10 minecraft:stonebrick 0
fill ~78~16~8 ~78~16~10 minecraft:stonebrick 0
fill ~78~18~8 ~78~27~10 minecraft:stonebrick 0
fill ~78~30~8 ~81~30~8 minecraft:stonebrick 0
setblock ~78~49~8 minecraft:stonebrick 0
fill ~79~16~8 ~81~16~8 minecraft:cobblestone
fill ~79~32~8 ~81~39~10 minecraft:stonebrick 0
fill ~79~43~8 ~81~47~8 minecraft:stonebrick 0
fill ~79~49~8 ~95~49~14 minecraft:cobblestone
fill ~80~15~8 ~80~15~9 minecraft:wool 0
fill ~82~1~8 ~82~1~12 minecraft:stonebrick 0
fill ~82~2~8 ~82~13~10 minecraft:stonebrick 0
fill ~82~16~8 ~82~27~10 minecraft:stonebrick 0
fill ~82~30~8 ~91~30~28 minecraft:cobblestone
fill ~82~41~8 ~91~41~22 minecraft:cobblestone
fill ~83~14~8 ~83~14~10 minecraft:stonebrick 0
fill ~83~16~8 ~95~16~8 minecraft:cobblestone
fill ~83~17~8 ~83~17~11 minecraft:stonebrick 0
fill ~83~28~8 ~83~28~10 minecraft:stonebrick 0
fill ~84~15~8 ~84~15~10 minecraft:stonebrick 0
fill ~84~29~8 ~84~29~10 minecraft:stonebrick 0
setblock ~88~31~8 minecraft:cobblestone
fill ~89~15~8 ~89~15~10 minecraft:stonebrick 0
fill ~90~14~8 ~90~14~10 minecraft:stonebrick 0
fill ~91~1~8 ~91~1~12 minecraft:stonebrick 0
fill ~91~2~8 ~91~13~10 minecraft:stonebrick 0
fill ~91~42~8 ~92~42~10 minecraft:stonebrick 0
fill ~91~48~8 ~92~48~10 minecraft:stonebrick 0
fill ~92~29~8 ~93~29~8 minecraft:wool 0
fill ~92~30~8 ~94~30~9 minecraft:stonebrick 0
fill ~92~41~8 ~92~41~11 minecraft:stonebrick 0
fill ~92~43~8 ~92~47~9 minecraft:stonebrick 0
fill ~93~15~8 ~93~15~9 minecraft:wool 0
fill ~94~41~8 ~94~41~11 minecraft:stonebrick 0
fill ~94~42~8 ~95~42~10 minecraft:stonebrick 0
fill ~94~43~8 ~94~48~9 minecraft:stonebrick 0
fill ~95~1~8 ~95~1~12 minecraft:stonebrick 0
fill ~95~2~8 ~95~13~10 minecraft:stonebrick 0
fill ~95~30~8 ~95~30~25 minecraft:cobblestone
fill ~95~41~8 ~95~41~9 minecraft:cobblestone
fill ~95~48~8 ~95~48~10 minecraft:stonebrick 0
fill ~96~0~8 ~102~0~53 minecraft:cobblestone
fill ~96~14~8 ~96~14~10 minecraft:stonebrick 0
setblock ~96~16~8 minecraft:stonebrick 0
setblock ~96~30~8 minecraft:stonebrick 0
setblock ~96~41~8 minecraft:stonebrick 0
fill ~96~49~8 ~96~50~8 minecraft:stonebrick 0
fill ~96~56~8 ~99~56~8 minecraft:stonebrick 0
fill ~97~15~8 ~97~15~10 minecraft:stonebrick 0
fill ~97~50~8 ~102~50~8 minecraft:stonebrick 0
fill ~97~51~8 ~98~55~8 minecraft:stonebrick 0
fill ~103~0~8 ~107~0~8 minecraft:dirt 0
fill ~103~1~8 ~107~1~9 minecraft:stonebrick 0
fill ~103~15~8 ~103~15~14 minecraft:stonebrick 0
fill ~103~29~8 ~103~29~14 minecraft:stonebrick 0
fill ~103~49~8 ~107~49~9 minecraft:stonebrick 0
fill ~103~57~8 ~107~57~10 minecraft:stonebrick 0
fill ~104~14~8 ~106~14~9 minecraft:stonebrick 0
fill ~104~28~8 ~106~28~9 minecraft:stonebrick 0
fill ~107~15~8 ~107~15~14 minecraft:stonebrick 0
fill ~107~29~8 ~107~29~14 minecraft:stonebrick 0
fill ~108~0~8 ~175~0~8 minecraft:grass
fill ~108~16~8 ~110~16~10 minecraft:stonebrick 0
fill ~108~17~8 ~110~17~8 minecraft:stonebrick 0
fill ~108~30~8 ~110~30~10 minecraft:stonebrick 0
fill ~108~31~8 ~110~31~8 minecraft:stonebrick 0
fill ~108~58~8 ~110~58~12 minecraft:stonebrick 0
fill ~109~41~8 ~110~41~10 minecraft:stonebrick 0
fill ~109~42~8 ~110~42~8 minecraft:stonebrick 0
fill ~2~0~9 ~64~0~9 minecraft:grass
fill ~61~16~9 ~63~16~11 minecraft:stonebrick 0
fill ~61~17~9 ~63~17~9 minecraft:stonebrick 0
fill ~61~30~9 ~63~30~11 minecraft:stonebrick 0
fill ~61~31~9 ~63~31~9 minecraft:stonebrick 0
fill ~61~41~9 ~63~41~11 minecraft:stonebrick 0
fill ~61~42~9 ~63~42~9 minecraft:stonebrick 0
fill ~61~58~9 ~63~58~13 minecraft:stonebrick 0
fill ~63~59~9 ~63~62~9 minecraft:fence 0
setblock ~63~63~9 minecraft:torch 5
fill ~64~49~9 ~66~49~10 minecraft:stonebrick 0
fill ~64~57~9 ~66~57~11 minecraft:stonebrick 0
fill ~65~0~9 ~67~0~9 minecraft:dirt 0
fill ~65~1~9 ~65~1~13 minecraft:stonebrick 0
fill ~65~15~9 ~65~15~13 minecraft:stonebrick 0
fill ~65~17~9 ~66~17~13 minecraft:stonebrick 0
fill ~65~29~9 ~65~29~13 minecraft:stonebrick 0
fill ~66~14~9 ~66~14~13 minecraft:stonebrick 0
fill ~66~28~9 ~66~28~13 minecraft:stonebrick 0
fill ~66~31~9 ~70~31~13 minecraft:stonebrick 0
fill ~66~40~9 ~70~40~13 minecraft:stonebrick 0
fill ~66~42~9 ~70~42~10 minecraft:stonebrick 0
fill ~66~48~9 ~70~48~10 minecraft:stonebrick 0
fill ~67~2~9 ~69~13~9 minecraft:stonebrick 0
fill ~67~18~9 ~69~27~9 minecraft:stonebrick 0
fill ~68~0~9 ~71~0~67 minecraft:cobblestone
fill ~68~50~9 ~71~50~9 minecraft:stonebrick 0
fill ~68~56~9 ~71~56~9 minecraft:stonebrick 0
fill ~69~51~9 ~70~55~9 minecraft:stonebrick 0
fill ~70~14~9 ~70~14~13 minecraft:stonebrick 0
fill ~70~28~9 ~70~28~13 minecraft:stonebrick 0
fill ~71~1~9 ~71~1~13 minecraft:stonebrick 0
fill ~71~15~9 ~71~15~13 minecraft:stonebrick 0
fill ~71~17~9 ~71~17~13 minecraft:stonebrick 0
fill ~71~29~9 ~71~29~13 minecraft:stonebrick 0
fill ~72~16~9 ~77~16~34 minecraft:cobblestone
fill ~72~30~9 ~78~30~25 minecraft:cobblestone
fill ~72~41~9 ~78~41~10 minecraft:cobblestone
fill ~72~49~9 ~78~49~18 minecraft:cobblestone
fill ~78~42~9 ~79~42~11 minecraft:stonebrick 0
fill ~78~48~9 ~79~48~11 minecraft:stonebrick 0
setblock ~78~57~9 minecraft:stonebrick 0
setblock ~79~1~9 minecraft:stonebrick 0
fill ~79~16~9 ~79~16~10 minecraft:cobblestone
fill ~79~29~9 ~80~29~9 minecraft:wool 0
fill ~79~30~9 ~81~30~10 minecraft:stonebrick 0
fill ~79~41~9 ~79~41~11 minecraft:stonebrick 0
fill ~79~43~9 ~79~47~10 minecraft:stonebrick 0
setblock ~81~1~9 minecraft:stonebrick 0
fill ~81~16~9 ~81~16~10 minecraft:cobblestone
fill ~81~41~9 ~81~42~11 minecraft:stonebrick 0
fill ~81~43~9 ~81~48~10 minecraft:stonebrick 0
fill ~82~42~9 ~82~42~11 minecraft:stonebrick 0
fill ~82~48~9 ~82~48~11 minecraft:stonebrick 0
fill ~83~16~9 ~92~16~51 minecraft:cobblestone
setblock ~92~1~9 minecraft:stonebrick 0
setblock ~93~16~9 minecraft:wool 0
fill ~93~41~9 ~93~41~11 minecraft:stonebrick 0
fill ~93~42~9 ~93~42~10 minecraft:stonebrick 0
fill ~93~43~9 ~93~48~9 minecraft:stonebrick 0
setblock ~94~1~9 minecraft:stonebrick 0
fill ~94~16~9 ~102~16~34 minecraft:cobblestone
fill ~96~30~9 ~102~30~25 minecraft:cobblestone
fill ~96~41~9 ~102~41~23 minecraft:cobblestone
fill ~96~49~9 ~102~49~18 minecraft:cobblestone
setblock ~96~57~9 minecraft:stonebrick 0
fill ~102~1~9 ~102~1~13 minecraft:stonebrick 0
fill ~102~15~9 ~102~15~13 minecraft:stonebrick 0
fill ~102~17~9 ~102~17~13 minecraft:stonebrick 0
fill ~102~29~9 ~102~29~13 minecraft:stonebrick 0
fill ~103~0~9 ~106~0~67 minecraft:cobblestone
fill ~103~14~9 ~103~14~13 minecraft:stonebrick 0
fill ~103~28~9 ~103~28~13 minecraft:stonebrick 0
fill ~103~31~9 ~107~31~13 minecraft:stonebrick 0
fill ~103~40~9 ~107~40~13 minecraft:stonebrick 0
fill ~103~42~9 ~107~42~10 minecraft:stonebrick 0
fill ~103~48~9 ~107~48~10 minecraft:stonebrick 0
fill ~103~50~9 ~106~50~9 minecraft:stonebrick 0
fill ~103~56~9 ~106~56~9 minecraft:stonebrick 0
fill ~104~2~9 ~106~13~9 minecraft:stonebrick 0
fill ~104~18~9 ~106~27~9 minecraft:stonebrick 0
fill ~104~51~9 ~105~55~9 minecraft:stonebrick 0
fill ~107~0~9 ~108~0~9 minecraft:dirt 0
fill ~107~14~9 ~107~14~13 minecraft:stonebrick 0
fill ~107~28~9 ~107~28~13 minecraft:stonebrick 0
fill ~108~1~9 ~108~1~13 minecraft:stonebrick 0
fill ~108~15~9 ~108~15~13 minecraft:stonebrick 0
fill ~108~17~9 ~108~17~13 minecraft:stonebrick 0
fill ~108~29~9 ~108~29~13 minecraft:stonebrick 0
fill ~108~49~9 ~110~49~10 minecraft:stonebrick 0
fill ~108~57~9 ~110~57~11 minecraft:stonebrick 0
fill ~109~0~9 ~175~0~9 minecraft:grass
fill ~111~16~9 ~113~16~11 minecraft:stonebrick 0
fill ~111~17~9 ~113~17~9 minecraft:stonebrick 0
fill ~111~30~9 ~113~30~11 minecraft:stonebrick 0
fill ~111~31~9 ~113~31~9 minecraft:stonebrick 0
fill ~111~41~9 ~113~41~11 minecraft:stonebrick 0
fill ~111~42~9 ~113~42~9 minecraft:stonebrick 0
fill ~111~58~9 ~113~58~13 minecraft:stonebrick 0
fill ~111~59~9 ~111~62~9 minecraft:fence 0
setblock ~111~63~9 minecraft:torch 5
fill ~2~0~10 ~63~0~10 minecraft:grass
fill ~58~16~10 ~60~16~12 minecraft:stonebrick 0
fill ~58~17~10 ~60~17~10 minecraft:stonebrick 0
fill ~58~30~10 ~60~30~12 minecraft:stonebrick 0
fill ~58~31~10 ~60~31~10 minecraft:stonebrick 0
fill ~58~41~10 ~60~41~12 minecraft:stonebrick 0
fill ~58~42~10 ~60~42~10 minecraft:stonebrick 0
fill ~58~58~10 ~60~58~14 minecraft:stonebrick 0
fill ~59~59~10 ~59~62~10 minecraft:fence 0
setblock ~59~63~10 minecraft:torch 5
fill ~61~49~10 ~63~49~11 minecraft:stonebrick 0
fill ~61~57~10 ~63~57~12 minecraft:stonebrick 0
fill ~64~0~10 ~67~0~71 minecraft:cobblestone
fill ~64~15~10 ~64~15~12 minecraft:stonebrick 0
fill ~64~29~10 ~64~29~12 minecraft:stonebrick 0
fill ~64~50~10 ~67~50~10 minecraft:stonebrick 0
setblock ~64~56~10 minecraft:stonebrick 0
fill ~65~14~10 ~65~14~12 minecraft:stonebrick 0
fill ~65~28~10 ~65~28~12 minecraft:stonebrick 0
fill ~65~41~10 ~69~41~10 minecraft:stonebrick 0
fill ~66~1~10 ~66~1~14 minecraft:stonebrick 0
fill ~66~2~10 ~66~13~12 minecraft:stonebrick 0
fill ~66~18~10 ~66~27~12 minecraft:stonebrick 0
setblock ~67~16~10 minecraft:stonebrick 0
fill ~67~30~10 ~69~30~12 minecraft:stonebrick 0
fill ~67~32~10 ~69~39~12 minecraft:stonebrick 0
fill ~67~43~10 ~69~47~10 minecraft:stonebrick 0
setblock ~67~49~10 minecraft:stonebrick 0
fill ~68~15~10 ~68~15~11 minecraft:wool 0
fill ~68~16~10 ~69~16~10 minecraft:cobblestone
fill ~68~49~10 ~71~49~19 minecraft:cobblestone
fill ~70~1~10 ~70~1~14 minecraft:stonebrick 0
fill ~70~2~10 ~70~13~12 minecraft:stonebrick 0
fill ~70~16~10 ~70~16~12 minecraft:stonebrick 0
fill ~70~18~10 ~70~27~12 minecraft:stonebrick 0
fill ~70~30~10 ~71~30~30 minecraft:cobblestone
fill ~70~41~10 ~71~41~24 minecraft:cobblestone
fill ~71~14~10 ~71~14~12 minecraft:stonebrick 0
fill ~71~16~10 ~71~16~55 minecraft:cobblestone
fill ~71~28~10 ~71~28~12 minecraft:stonebrick 0
fill ~72~15~10 ~72~15~12 minecraft:stonebrick 0
fill ~72~29~10 ~72~29~12 minecraft:stonebrick 0
setblock ~78~58~10 minecraft:stonebrick 0
setblock ~80~16~10 minecraft:cobblestone
fill ~80~41~10 ~80~42~11 minecraft:stonebrick 0
fill ~80~43~10 ~80~48~10 minecraft:stonebrick 0
fill ~92~17~10 ~94~17~11 minecraft:stonebrick 0
fill ~92~18~10 ~94~29~10 minecraft:stonebrick 0
fill ~92~30~10 ~94~30~25 minecraft:cobblestone
setblock ~92~38~10 minecraft:torch 3
fill ~93~16~10 ~93~16~52 minecraft:cobblestone
fill ~93~48~10 ~94~48~10 minecraft:stonebrick 0
fill ~95~41~10 ~95~41~11 minecraft:stonebrick 0
setblock ~96~58~10 minecraft:stonebrick 0
fill ~101~15~10 ~101~15~12 minecraft:stonebrick 0
fill ~101~29~10 ~101~29~12 minecraft:stonebrick 0
fill ~102~14~10 ~102~14~12 minecraft:stonebrick 0
fill ~102~28~10 ~102~28~12 minecraft:stonebrick 0
fill ~103~1~10 ~103~1~14 minecraft:stonebrick 0
fill ~103~2~10 ~103~13~12 minecraft:stonebrick 0
fill ~103~16~10 ~103~27~12 minecraft:stonebrick 0
fill ~103~30~10 ~103~30~30 minecraft:cobblestone
fill ~103~41~10 ~103~41~24 minecraft:cobblestone
fill ~103~49~10 ~106~49~19 minecraft:cobblestone
fill ~104~16~10 ~106~16~10 minecraft:cobblestone
fill ~104~30~10 ~107~30~10 minecraft:stonebrick 0
fill ~104~32~10 ~106~39~12 minecraft:stonebrick 0
fill ~104~41~10 ~108~41~10 minecraft:stonebrick 0
fill ~104~43~10 ~106~47~10 minecraft:stonebrick 0
fill ~105~15~10 ~105~15~11 minecraft:wool 0
fill ~107~0~10 ~110~0~71 minecraft:cobblestone
fill ~107~1~10 ~107~1~14 minecraft:stonebrick 0
fill ~107~2~10 ~107~13~12 minecraft:stonebrick 0
fill ~107~16~10 ~107~27~12 minecraft:stonebrick 0
fill ~107~49~10 ~107~50~10 minecraft:stonebrick 0
fill ~108~14~10 ~108~14~12 minecraft:stonebrick 0
fill ~108~28~10 ~108~28~12 minecraft:stonebrick 0
fill ~108~50~10 ~110~50~10 minecraft:stonebrick 0
fill ~109~15~10 ~109~15~12 minecraft:stonebrick 0
fill ~109~29~10 ~109~29~12 minecraft:stonebrick 0
setblock ~110~56~10 minecraft:stonebrick 0
fill ~111~0~10 ~175~0~10 minecraft:grass
fill ~111~49~10 ~113~49~11 minecraft:stonebrick 0
fill ~111~57~10 ~113~57~12 minecraft:stonebrick 0
fill ~114~16~10 ~116~16~12 minecraft:stonebrick 0
fill ~114~17~10 ~116~17~10 minecraft:stonebrick 0
fill ~114~30~10 ~116~30~12 minecraft:stonebrick 0
fill ~114~31~10 ~116~31~10 minecraft:stonebrick 0
fill ~114~41~10 ~116~41~12 minecraft:stonebrick 0
fill ~114~42~10 ~116~42~10 minecraft:stonebrick 0
fill ~114~58~10 ~116~58~14 minecraft:stonebrick 0
fill ~115~59~10 ~115~62~10 minecraft:fence 0
setblock ~115~63~10 minecraft:torch 5
fill ~2~0~11 ~60~0~11 minecraft:grass
fill ~53~41~11 ~57~41~14 minecraft:stonebrick 0
fill ~53~42~11 ~57~42~11 minecraft:stonebrick 0
fill ~55~15~11 ~57~17~13 minecraft:stonebrick 0
fill ~55~29~11 ~57~30~13 minecraft:stonebrick 0
fill ~55~31~11 ~57~31~11 minecraft:stonebrick 0
fill ~55~58~11 ~57~58~15 minecraft:stonebrick 0
fill ~55~59~11 ~55~62~11 minecraft:fence 0
setblock ~55~63~11 minecraft:torch 5
fill ~58~49~11 ~60~49~12 minecraft:stonebrick 0
fill ~58~57~11 ~60~57~13 minecraft:stonebrick 0
fill ~61~0~11 ~63~0~78 minecraft:cobblestone
fill ~61~50~11 ~63~50~11 minecraft:stonebrick 0
fill ~61~56~11 ~63~56~11 minecraft:stonebrick 0
fill ~62~51~11 ~63~55~11 minecraft:stonebrick 0
fill ~64~16~11 ~65~16~59 minecraft:cobblestone
fill ~64~30~11 ~66~30~32 minecraft:cobblestone
fill ~64~41~11 ~66~41~25 minecraft:cobblestone
fill ~64~49~11 ~67~49~20 minecraft:cobblestone
fill ~66~16~11 ~66~16~12 minecraft:stonebrick 0
fill ~66~42~11 ~67~42~13 minecraft:stonebrick 0
fill ~66~48~11 ~67~48~13 minecraft:stonebrick 0
fill ~67~16~11 ~67~16~12 minecraft:cobblestone
fill ~67~29~11 ~68~29~11 minecraft:wool 0
fill ~67~41~11 ~67~41~12 minecraft:stonebrick 0
fill ~67~43~11 ~67~47~12 minecraft:stonebrick 0
setblock ~67~57~11 minecraft:stonebrick 0
setblock ~69~1~11 minecraft:stonebrick 0
fill ~69~16~11 ~69~16~12 minecraft:cobblestone
fill ~69~41~11 ~69~48~12 minecraft:stonebrick 0
fill ~70~42~11 ~70~42~13 minecraft:stonebrick 0
fill ~70~48~11 ~70~48~13 minecraft:stonebrick 0
fill ~72~41~11 ~77~41~23 minecraft:cobblestone
fill ~78~16~11 ~78~16~34 minecraft:cobblestone
setblock ~78~41~11 minecraft:stonebrick 0
fill ~79~1~11 ~81~1~12 minecraft:stonebrick 0
fill ~79~2~11 ~81~29~11 minecraft:stonebrick 0
fill ~79~30~11 ~81~30~25 minecraft:cobblestone
fill ~80~48~11 ~81~48~11 minecraft:stonebrick 0
setblock ~81~38~11 minecraft:torch 3
fill ~82~16~11 ~82~16~51 minecraft:cobblestone
fill ~82~17~11 ~82~17~12 minecraft:stonebrick 0
fill ~84~34~11 ~89~34~14 minecraft:stonebrick 0
fill ~85~35~11 ~89~35~11 minecraft:stonebrick 0
fill ~86~42~11 ~88~42~11 minecraft:stone_stairs 2
setblock ~87~36~11 minecraft:torch 5
setblock ~91~17~11 minecraft:stonebrick 0
fill ~91~42~11 ~91~42~15 minecraft:fence 0
fill ~92~1~11 ~94~1~12 minecraft:stonebrick 0
fill ~92~2~11 ~94~15~11 minecraft:stonebrick 0
fill ~92~28~11 ~94~29~11 minecraft:stonebrick 0
setblock ~95~17~11 minecraft:stonebrick 0
fill ~103~42~11 ~104~42~13 minecraft:stonebrick 0
fill ~103~48~11 ~104~48~13 minecraft:stonebrick 0
setblock ~104~1~11 minecraft:stonebrick 0
fill ~104~16~11 ~104~16~12 minecraft:cobblestone
fill ~104~29~11 ~105~29~11 minecraft:wool 0
fill ~104~30~11 ~106~30~12 minecraft:stonebrick 0
fill ~104~41~11 ~104~41~12 minecraft:stonebrick 0
fill ~104~43~11 ~104~47~12 minecraft:stonebrick 0
setblock ~106~1~11 minecraft:stonebrick 0
fill ~106~16~11 ~106~16~12 minecraft:cobblestone
fill ~106~41~11 ~106~48~12 minecraft:stonebrick 0
fill ~107~30~11 ~110~30~32 minecraft:cobblestone
fill ~107~41~11 ~110~41~25 minecraft:cobblestone
fill ~107~42~11 ~107~42~13 minecraft:stonebrick 0
fill ~107~48~11 ~107~48~13 minecraft:stonebrick 0
fill ~107~49~11 ~110~49~20 minecraft:cobblestone
setblock ~107~57~11 minecraft:stonebrick 0
fill ~108~16~11 ~110~16~58 minecraft:cobblestone
fill ~111~0~11 ~113~0~78 minecraft:cobblestone
fill ~111~50~11 ~113~50~11 minecraft:stonebrick 0
fill ~111~51~11 ~112~56~11 minecraft:stonebrick 0
setblock ~113~56~11 minecraft:stonebrick 0
fill ~114~0~11 ~175~0~11 minecraft:grass
fill ~114~49~11 ~116~49~12 minecraft:stonebrick 0
fill ~114~57~11 ~116~57~13 minecraft:stonebrick 0
fill ~116~15~11 ~118~15~13 minecraft:stonebrick 0
fill ~116~29~11 ~118~29~13 minecraft:stonebrick 0
fill ~117~16~11 ~119~17~13 minecraft:stonebrick 0
fill ~117~30~11 ~119~30~14 minecraft:stonebrick 0
fill ~117~31~11 ~119~31~11 minecraft:stonebrick 0
fill ~117~41~11 ~120~41~14 minecraft:stonebrick 0
fill ~117~42~11 ~120~42~11 minecraft:stonebrick 0
fill ~117~58~11 ~119~58~15 minecraft:stonebrick 0
fill ~119~59~11 ~119~62~11 minecraft:fence 0
setblock ~119~63~11 minecraft:torch 5
fill ~2~0~12 ~53~0~12 minecraft:grass
fill ~52~41~12 ~52~41~15 minecraft:stonebrick 0
fill ~52~42~12 ~52~42~13 minecraft:stonebrick 0
fill ~53~16~12 ~54~17~15 minecraft:stonebrick 0
fill ~53~30~12 ~54~30~14 minecraft:stonebrick 0
fill ~53~31~12 ~54~31~12 minecraft:stonebrick 0
fill ~53~58~12 ~54~58~16 minecraft:stonebrick 0
fill ~54~0~12 ~57~0~12 minecraft:dirt 0
fill ~54~1~12 ~58~1~13 minecraft:stonebrick 0
fill ~54~15~12 ~54~15~18 minecraft:stonebrick 0
fill ~54~29~12 ~54~29~18 minecraft:stonebrick 0
fill ~55~14~12 ~57~14~13 minecraft:stonebrick 0
fill ~55~28~12 ~57~28~13 minecraft:stonebrick 0
fill ~56~49~12 ~57~49~13 minecraft:stonebrick 0
fill ~56~57~12 ~57~57~14 minecraft:stonebrick 0
fill ~58~0~12 ~60~0~162 minecraft:cobblestone
fill ~58~15~12 ~58~15~18 minecraft:stonebrick 0
fill ~58~17~12 ~58~17~18 minecraft:stonebrick 0
fill ~58~29~12 ~58~29~18 minecraft:stonebrick 0
fill ~58~50~12 ~60~50~12 minecraft:stonebrick 0
fill ~61~16~12 ~63~16~60 minecraft:cobblestone
fill ~61~30~12 ~63~30~33 minecraft:cobblestone
fill ~61~41~12 ~63~41~27 minecraft:cobblestone
fill ~61~49~12 ~63~49~21 minecraft:cobblestone
fill ~67~1~12 ~67~1~14 minecraft:stonebrick 0
setblock ~67~58~12 minecraft:stonebrick 0
setblock ~68~16~12 minecraft:cobblestone
fill ~68~41~12 ~68~48~12 minecraft:stonebrick 0
fill ~78~17~12 ~81~17~12 minecraft:stonebrick 0
fill ~78~39~12 ~79~39~14 minecraft:stonebrick 0
fill ~78~40~12 ~78~40~14 minecraft:stonebrick 0
fill ~78~41~12 ~78~41~14 minecraft:stone_stairs 1
fill ~79~14~12 ~81~15~12 minecraft:stonebrick 0
fill ~79~16~12 ~81~16~34 minecraft:cobblestone
fill ~79~28~12 ~81~29~12 minecraft:stonebrick 0
fill ~79~38~12 ~80~38~14 minecraft:stonebrick 0
fill ~79~40~12 ~79~40~14 minecraft:stone_stairs 1
fill ~80~37~12 ~81~37~14 minecraft:stonebrick 0
fill ~80~39~12 ~80~39~14 minecraft:stone_stairs 1
fill ~81~36~12 ~82~36~14 minecraft:stonebrick 0
fill ~81~38~12 ~81~38~14 minecraft:stone_stairs 1
fill ~82~35~12 ~83~35~14 minecraft:stonebrick 0
fill ~82~37~12 ~82~37~14 minecraft:stone_stairs 1
fill ~82~42~12 ~82~42~15 minecraft:fence 0
fill ~83~34~12 ~83~34~14 minecraft:stonebrick 0
fill ~83~36~12 ~83~36~14 minecraft:stone_stairs 1
fill ~84~35~12 ~84~35~14 minecraft:stone_stairs 1
fill ~86~42~12 ~88~42~15 minecraft:stonebrick 0
fill ~86~43~12 ~88~43~12 minecraft:stone_stairs 2
fill ~89~35~12 ~89~35~14 minecraft:stone_stairs 0
fill ~90~34~12 ~90~35~14 minecraft:stonebrick 0
fill ~90~36~12 ~90~36~14 minecraft:stone_stairs 0
fill ~91~35~12 ~91~36~14 minecraft:stonebrick 0
fill ~91~37~12 ~91~37~14 minecraft:stone_stairs 0
fill ~92~14~12 ~94~15~12 minecraft:stonebrick 0
fill ~92~29~12 ~94~29~12 minecraft:stonebrick 0
fill ~92~36~12 ~92~37~14 minecraft:stonebrick 0
fill ~92~38~12 ~92~38~14 minecraft:stone_stairs 0
fill ~93~37~12 ~93~38~14 minecraft:stonebrick 0
fill ~93~39~12 ~93~39~14 minecraft:stone_stairs 0
fill ~94~38~12 ~94~39~14 minecraft:stonebrick 0
fill ~94~40~12 ~94~40~14 minecraft:stone_stairs 0
fill ~95~39~12 ~95~40~14 minecraft:stonebrick 0
fill ~95~41~12 ~95~41~14 minecraft:stone_stairs 0
setblock ~105~16~12 minecraft:cobblestone
fill ~105~41~12 ~105~48~12 minecraft:stonebrick 0
setblock ~107~58~12 minecraft:stonebrick 0
fill ~111~16~12 ~113~16~60 minecraft:cobblestone
fill ~111~30~12 ~113~30~33 minecraft:cobblestone
fill ~111~41~12 ~113~41~27 minecraft:cobblestone
fill ~111~49~12 ~113~49~21 minecraft:cobblestone
fill ~114~0~12 ~116~0~162 minecraft:cobblestone
fill ~114~50~12 ~116~50~12 minecraft:stonebrick 0
fill ~115~1~12 ~119~1~13 minecraft:stonebrick 0
fill ~115~15~12 ~115~15~18 minecraft:stonebrick 0
fill ~115~17~12 ~116~17~13 minecraft:stonebrick 0
fill ~115~29~12 ~115~29~18 minecraft:stonebrick 0
fill ~116~14~12 ~118~14~13 minecraft:stonebrick 0
fill ~116~28~12 ~118~28~13 minecraft:stonebrick 0
fill ~117~0~12 ~119~0~12 minecraft:dirt 0
fill ~117~49~12 ~118~49~13 minecraft:stonebrick 0
fill ~117~57~12 ~118~57~14 minecraft:stonebrick 0
fill ~119~15~12 ~119~15~18 minecraft:stonebrick 0
fill ~119~29~12 ~119~29~18 minecraft:stonebrick 0
fill ~120~0~12 ~175~0~12 minecraft:grass
fill ~120~16~12 ~121~16~14 minecraft:stonebrick 0
fill ~120~17~12 ~121~17~12 minecraft:stonebrick 0
fill ~120~30~12 ~121~30~14 minecraft:stonebrick 0
fill ~120~31~12 ~121~31~12 minecraft:stonebrick 0
fill ~120~58~12 ~121~58~16 minecraft:stonebrick 0
fill ~121~41~12 ~121~41~15 minecraft:stonebrick 0
setblock ~121~42~12 minecraft:stonebrick 0
fill ~2~0~13 ~52~0~14 minecraft:grass
fill ~51~16~13 ~52~16~15 minecraft:stonebrick 0
fill ~51~17~13 ~52~17~13 minecraft:stonebrick 0
fill ~51~30~13 ~52~30~15 minecraft:stonebrick 0
fill ~51~31~13 ~52~31~13 minecraft:stonebrick 0
fill ~51~41~13 ~51~41~16 minecraft:stonebrick 0
setblock ~51~42~13 minecraft:stonebrick 0
fill ~51~58~13 ~52~58~17 minecraft:stonebrick 0
fill ~51~59~13 ~51~62~13 minecraft:fence 0
setblock ~51~63~13 minecraft:torch 5
fill ~53~0~13 ~55~0~13 minecraft:dirt 0
fill ~53~1~13 ~53~1~17 minecraft:stonebrick 0
fill ~53~15~13 ~53~15~17 minecraft:stonebrick 0
fill ~53~29~13 ~53~29~17 minecraft:stonebrick 0
fill ~53~49~13 ~55~49~14 minecraft:stonebrick 0
fill ~53~57~13 ~55~57~15 minecraft:stonebrick 0
fill ~54~14~13 ~54~14~17 minecraft:stonebrick 0
fill ~54~28~13 ~54~28~17 minecraft:stonebrick 0
fill ~54~31~13 ~58~31~17 minecraft:stonebrick 0
fill ~54~40~13 ~58~40~17 minecraft:stonebrick 0
fill ~54~42~13 ~58~42~14 minecraft:stonebrick 0
fill ~54~48~13 ~58~48~14 minecraft:stonebrick 0
fill ~55~2~13 ~57~13~13 minecraft:stonebrick 0
fill ~55~18~13 ~57~27~13 minecraft:stonebrick 0
fill ~56~0~13 ~57~0~161 minecraft:cobblestone
fill ~56~50~13 ~57~50~13 minecraft:stonebrick 0
fill ~56~51~13 ~56~56~13 minecraft:stonebrick 0
setblock ~57~56~13 minecraft:stonebrick 0
fill ~58~14~13 ~58~14~17 minecraft:stonebrick 0
fill ~58~16~13 ~60~16~13 minecraft:cobblestone
fill ~58~28~13 ~58~28~17 minecraft:stonebrick 0
fill ~58~30~13 ~60~30~35 minecraft:cobblestone
fill ~58~41~13 ~60~41~28 minecraft:cobblestone
fill ~58~49~13 ~60~49~22 minecraft:cobblestone
fill ~59~1~13 ~59~1~17 minecraft:stonebrick 0
fill ~59~15~13 ~59~15~17 minecraft:stonebrick 0
fill ~59~17~13 ~59~17~17 minecraft:stonebrick 0
fill ~59~29~13 ~59~29~17 minecraft:stonebrick 0
fill ~66~16~13 ~66~16~58 minecraft:cobblestone
fill ~67~2~13 ~69~29~13 minecraft:stonebrick 0
fill ~67~30~13 ~69~30~31 minecraft:cobblestone
fill ~67~41~13 ~69~41~25 minecraft:cobblestone
fill ~68~1~13 ~69~1~14 minecraft:stonebrick 0
fill ~68~42~13 ~69~42~13 minecraft:stonebrick 0
fill ~68~48~13 ~69~48~13 minecraft:stonebrick 0
fill ~70~16~13 ~70~16~55 minecraft:cobblestone
fill ~79~15~13 ~81~15~13 minecraft:stonebrick 0
fill ~79~29~13 ~81~29~13 minecraft:stonebrick 0
fill ~86~43~13 ~88~43~15 minecraft:stonebrick 0
fill ~86~44~13 ~88~44~13 minecraft:stone_stairs 2
fill ~92~15~13 ~94~15~13 minecraft:stonebrick 0
fill ~103~16~13 ~103~16~55 minecraft:cobblestone
fill ~103~17~13 ~107~17~14 minecraft:stonebrick 0
fill ~104~1~13 ~106~1~14 minecraft:stonebrick 0
fill ~104~2~13 ~106~16~13 minecraft:stonebrick 0
fill ~104~18~13 ~106~29~13 minecraft:stonebrick 0
fill ~104~30~13 ~106~30~31 minecraft:cobblestone
fill ~104~41~13 ~106~41~24 minecraft:cobblestone
fill ~105~42~13 ~106~42~13 minecraft:stonebrick 0
fill ~105~48~13 ~106~48~13 minecraft:stonebrick 0
fill ~107~16~13 ~107~16~57 minecraft:cobblestone
fill ~114~1~13 ~114~1~17 minecraft:stonebrick 0
fill ~114~15~13 ~114~15~17 minecraft:stonebrick 0
fill ~114~16~13 ~115~16~13 minecraft:cobblestone
fill ~114~17~13 ~114~17~17 minecraft:stonebrick 0
fill ~114~29~13 ~114~29~17 minecraft:stonebrick 0
fill ~114~30~13 ~116~30~13 minecraft:cobblestone
fill ~114~41~13 ~116~41~13 minecraft:cobblestone
fill ~114~49~13 ~116~49~22 minecraft:cobblestone
fill ~115~14~13 ~115~14~17 minecraft:stonebrick 0
fill ~115~28~13 ~115~28~17 minecraft:stonebrick 0
fill ~115~31~13 ~119~31~17 minecraft:stonebrick 0
fill ~115~40~13 ~119~40~17 minecraft:stonebrick 0
fill ~115~42~13 ~119~42~14 minecraft:stonebrick 0
fill ~115~48~13 ~119~48~14 minecraft:stonebrick 0
fill ~116~2~13 ~118~13~13 minecraft:stonebrick 0
setblock ~116~16~13 minecraft:stonebrick 0
fill ~116~18~13 ~118~27~13 minecraft:stonebrick 0
fill ~117~0~13 ~118~0~161 minecraft:cobblestone
fill ~117~50~13 ~118~50~13 minecraft:stonebrick 0
fill ~117~56~13 ~118~56~13 minecraft:stonebrick 0
fill ~118~51~13 ~118~55~13 minecraft:stonebrick 0
fill ~119~0~13 ~120~0~13 minecraft:dirt 0
fill ~119~14~13 ~119~14~17 minecraft:stonebrick 0
fill ~119~28~13 ~119~28~17 minecraft:stonebrick 0
fill ~119~49~13 ~121~49~14 minecraft:stonebrick 0
fill ~119~57~13 ~121~57~15 minecraft:stonebrick 0
fill ~120~1~13 ~120~1~17 minecraft:stonebrick 0
fill ~120~15~13 ~120~15~17 minecraft:stonebrick 0
fill ~120~17~13 ~120~17~17 minecraft:stonebrick 0
fill ~120~29~13 ~120~29~17 minecraft:stonebrick 0
fill ~121~0~13 ~175~0~14 minecraft:grass
fill ~122~16~13 ~123~16~15 minecraft:stonebrick 0
fill ~122~17~13 ~123~17~13 minecraft:stonebrick 0
fill ~122~30~13 ~123~30~15 minecraft:stonebrick 0
fill ~122~31~13 ~123~31~13 minecraft:stonebrick 0
fill ~122~41~13 ~123~41~15 minecraft:stonebrick 0
fill ~122~42~13 ~123~42~13 minecraft:stonebrick 0
fill ~122~58~13 ~123~58~17 minecraft:stonebrick 0
fill ~123~59~13 ~123~62~13 minecraft:fence 0
setblock ~123~63~13 minecraft:torch 5
fill ~49~16~14 ~50~16~16 minecraft:stonebrick 0
fill ~49~17~14 ~50~17~14 minecraft:stonebrick 0
fill ~49~30~14 ~50~30~16 minecraft:stonebrick 0
fill ~49~31~14 ~50~31~14 minecraft:stonebrick 0
fill ~49~41~14 ~50~41~16 minecraft:stonebrick 0
fill ~49~42~14 ~50~42~14 minecraft:stonebrick 0
fill ~49~58~14 ~50~58~18 minecraft:stonebrick 0
fill ~51~49~14 ~52~49~15 minecraft:stonebrick 0
fill ~51~57~14 ~52~57~16 minecraft:stonebrick 0
fill ~52~15~14 ~52~15~16 minecraft:stonebrick 0
fill ~52~29~14 ~52~29~16 minecraft:stonebrick 0
setblock ~53~0~14 minecraft:dirt 0
fill ~53~14~14 ~53~14~16 minecraft:stonebrick 0
fill ~53~28~14 ~53~28~16 minecraft:stonebrick 0
fill ~54~0~14 ~55~0~160 minecraft:cobblestone
fill ~54~1~14 ~54~1~18 minecraft:stonebrick 0
fill ~54~2~14 ~54~13~16 minecraft:stonebrick 0
fill ~54~18~14 ~54~27~16 minecraft:stonebrick 0
fill ~54~50~14 ~55~50~14 minecraft:stonebrick 0
fill ~54~56~14 ~55~56~14 minecraft:stonebrick 0
setblock ~55~16~14 minecraft:stonebrick 0
fill ~55~30~14 ~57~30~16 minecraft:stonebrick 0
fill ~55~32~14 ~57~39~16 minecraft:stonebrick 0
fill ~55~43~14 ~57~47~14 minecraft:stonebrick 0
fill ~55~51~14 ~55~55~14 minecraft:stonebrick 0
fill ~56~15~14 ~56~15~15 minecraft:wool 0
fill ~56~16~14 ~57~16~14 minecraft:cobblestone
fill ~56~49~14 ~57~49~24 minecraft:cobblestone
fill ~58~1~14 ~58~1~18 minecraft:stonebrick 0
fill ~58~2~14 ~58~13~16 minecraft:stonebrick 0
fill ~58~16~14 ~58~16~16 minecraft:stonebrick 0
fill ~58~18~14 ~58~27~16 minecraft:stonebrick 0
fill ~59~14~14 ~59~14~16 minecraft:stonebrick 0
fill ~59~16~14 ~60~16~63 minecraft:cobblestone
fill ~59~28~14 ~59~28~16 minecraft:stonebrick 0
fill ~60~15~14 ~60~15~16 minecraft:stonebrick 0
fill ~60~29~14 ~60~29~16 minecraft:stonebrick 0
fill ~66~17~14 ~69~17~14 minecraft:stonebrick 0
fill ~67~14~14 ~69~15~14 minecraft:stonebrick 0
fill ~67~16~14 ~69~16~56 minecraft:cobblestone
fill ~67~28~14 ~69~29~14 minecraft:stonebrick 0
fill ~82~50~14 ~92~50~14 minecraft:fence 0
setblock ~82~51~14 minecraft:torch 5
fill ~83~31~14 ~90~33~14 minecraft:stonebrick 0
fill ~86~44~14 ~88~44~15 minecraft:stonebrick 0
fill ~86~45~14 ~88~45~14 minecraft:stone_stairs 2
setblock ~92~51~14 minecraft:torch 5
fill ~104~14~14 ~106~15~14 minecraft:stonebrick 0
fill ~104~16~14 ~106~16~55 minecraft:cobblestone
fill ~104~28~14 ~106~29~14 minecraft:stonebrick 0
fill ~113~15~14 ~113~15~16 minecraft:stonebrick 0
fill ~113~29~14 ~113~29~16 minecraft:stonebrick 0
fill ~114~14~14 ~114~14~16 minecraft:stonebrick 0
fill ~114~16~14 ~114~16~63 minecraft:cobblestone
fill ~114~28~14 ~114~28~16 minecraft:stonebrick 0
fill ~114~30~14 ~115~30~35 minecraft:cobblestone
fill ~114~41~14 ~115~41~28 minecraft:cobblestone
fill ~115~1~14 ~115~1~18 minecraft:stonebrick 0
fill ~115~2~14 ~115~13~16 minecraft:stonebrick 0
fill ~115~16~14 ~115~27~16 minecraft:stonebrick 0
fill ~116~16~14 ~118~16~14 minecraft:cobblestone
fill ~116~30~14 ~116~30~16 minecraft:stonebrick 0
fill ~116~32~14 ~118~39~16 minecraft:stonebrick 0
fill ~116~41~14 ~116~41~16 minecraft:stonebrick 0
fill ~116~43~14 ~118~47~14 minecraft:stonebrick 0
fill ~117~15~14 ~117~15~15 minecraft:wool 0
fill ~117~49~14 ~118~49~24 minecraft:cobblestone
fill ~119~0~14 ~120~0~160 minecraft:cobblestone
fill ~119~1~14 ~119~1~18 minecraft:stonebrick 0
fill ~119~2~14 ~119~13~16 minecraft:stonebrick 0
fill ~119~16~14 ~119~27~16 minecraft:stonebrick 0
fill ~119~50~14 ~120~50~14 minecraft:stonebrick 0
fill ~119~51~14 ~119~56~14 minecraft:stonebrick 0
fill ~120~14~14 ~120~14~16 minecraft:stonebrick 0
fill ~120~28~14 ~120~28~16 minecraft:stonebrick 0
setblock ~120~56~14 minecraft:stonebrick 0
fill ~121~15~14 ~121~15~16 minecraft:stonebrick 0
fill ~121~29~14 ~121~29~16 minecraft:stonebrick 0
fill ~122~49~14 ~123~49~15 minecraft:stonebrick 0
fill ~122~57~14 ~123~57~16 minecraft:stonebrick 0
fill ~124~16~14 ~125~16~16 minecraft:stonebrick 0
fill ~124~17~14 ~125~17~14 minecraft:stonebrick 0
fill ~124~30~14 ~125~30~16 minecraft:stonebrick 0
fill ~124~31~14 ~125~31~14 minecraft:stonebrick 0
fill ~124~41~14 ~125~41~16 minecraft:stonebrick 0
fill ~124~42~14 ~125~42~14 minecraft:stonebrick 0
fill ~124~58~14 ~125~58~18 minecraft:stonebrick 0
fill ~2~0~15 ~50~0~15 minecraft:grass
fill ~47~16~15 ~48~16~17 minecraft:stonebrick 0
fill ~47~17~15 ~48~17~15 minecraft:stonebrick 0
fill ~47~30~15 ~48~30~17 minecraft:stonebrick 0
fill ~47~31~15 ~48~31~15 minecraft:stonebrick 0
fill ~47~41~15 ~48~41~17 minecraft:stonebrick 0
fill ~47~42~15 ~48~42~15 minecraft:stonebrick 0
fill ~47~58~15 ~48~58~19 minecraft:stonebrick 0
fill ~47~59~15 ~47~62~15 minecraft:fence 0
setblock ~47~63~15 minecraft:torch 5
fill ~49~49~15 ~50~49~16 minecraft:stonebrick 0
fill ~49~57~15 ~50~57~17 minecraft:stonebrick 0
fill ~51~0~15 ~53~0~159 minecraft:cobblestone
fill ~51~50~15 ~53~50~15 minecraft:stonebrick 0
setblock ~53~30~15 minecraft:stonebrick 0
setblock ~53~41~15 minecraft:stonebrick 0
setblock ~53~49~15 minecraft:stonebrick 0
fill ~54~30~15 ~54~30~38 minecraft:cobblestone
fill ~54~41~15 ~54~41~31 minecraft:cobblestone
fill ~54~42~15 ~55~42~17 minecraft:stonebrick 0
fill ~54~48~15 ~55~48~17 minecraft:stonebrick 0
fill ~54~49~15 ~55~49~25 minecraft:cobblestone
fill ~55~16~15 ~55~16~16 minecraft:cobblestone
fill ~55~29~15 ~56~29~15 minecraft:wool 0
fill ~55~41~15 ~55~41~16 minecraft:stonebrick 0
fill ~55~43~15 ~55~47~16 minecraft:stonebrick 0
setblock ~57~1~15 minecraft:stonebrick 0
fill ~57~16~15 ~57~16~16 minecraft:cobblestone
fill ~57~41~15 ~57~48~16 minecraft:stonebrick 0
fill ~58~42~15 ~58~42~17 minecraft:stonebrick 0
fill ~58~48~15 ~58~48~17 minecraft:stonebrick 0
setblock ~58~58~15 minecraft:stonebrick 0
fill ~67~15~15 ~69~15~15 minecraft:stonebrick 0
fill ~67~29~15 ~69~29~15 minecraft:stonebrick 0
fill ~78~41~15 ~81~41~22 minecraft:cobblestone
fill ~78~42~15 ~81~42~15 minecraft:fence 0
setblock ~78~43~15 minecraft:torch 5
fill ~79~49~15 ~81~49~17 minecraft:cobblestone
setblock ~82~43~15 minecraft:torch 5
fill ~82~48~15 ~82~48~18 minecraft:stonebrick 0
fill ~82~49~15 ~82~49~17 minecraft:stone_stairs 1
fill ~83~47~15 ~83~47~17 minecraft:stonebrick 0
fill ~83~48~15 ~83~48~17 minecraft:stone_stairs 1
fill ~84~31~15 ~89~31~17 minecraft:stonebrick 0
fill ~84~32~15 ~89~32~16 minecraft:stonebrick 0
fill ~84~33~15 ~89~33~15 minecraft:stonebrick 0
fill ~84~34~15 ~89~34~15 minecraft:stone_stairs 3
fill ~84~46~15 ~84~46~18 minecraft:stonebrick 0
fill ~84~47~15 ~84~47~17 minecraft:stone_stairs 1
fill ~85~45~15 ~89~45~23 minecraft:stonebrick 0
fill ~85~46~15 ~85~46~17 minecraft:stone_stairs 1
fill ~89~46~15 ~89~46~17 minecraft:stone_stairs 0
fill ~90~46~15 ~90~46~18 minecraft:stonebrick 0
fill ~90~47~15 ~90~47~17 minecraft:stone_stairs 0
setblock ~91~43~15 minecraft:torch 5
fill ~91~47~15 ~91~47~17 minecraft:stonebrick 0
fill ~91~48~15 ~91~48~17 minecraft:stone_stairs 0
fill ~92~41~15 ~95~41~22 minecraft:cobblestone
fill ~92~42~15 ~95~42~15 minecraft:fence 0
fill ~92~48~15 ~92~48~18 minecraft:stonebrick 0
fill ~92~49~15 ~92~49~17 minecraft:stone_stairs 0
fill ~93~49~15 ~95~49~17 minecraft:cobblestone
setblock ~95~43~15 minecraft:torch 5
fill ~104~15~15 ~106~15~15 minecraft:stonebrick 0
fill ~104~29~15 ~106~29~15 minecraft:stonebrick 0
fill ~115~42~15 ~116~42~17 minecraft:stonebrick 0
fill ~115~48~15 ~116~48~17 minecraft:stonebrick 0
setblock ~116~1~15 minecraft:stonebrick 0
fill ~116~16~15 ~116~16~16 minecraft:cobblestone
fill ~116~29~15 ~117~29~15 minecraft:wool 0
fill ~116~43~15 ~116~47~16 minecraft:stonebrick 0
setblock ~116~58~15 minecraft:stonebrick 0
fill ~117~30~15 ~118~30~16 minecraft:stonebrick 0
setblock ~118~1~15 minecraft:stonebrick 0
fill ~118~16~15 ~118~16~16 minecraft:cobblestone
fill ~118~41~15 ~118~48~16 minecraft:stonebrick 0
fill ~119~30~15 ~120~30~38 minecraft:cobblestone
fill ~119~41~15 ~120~41~30 minecraft:cobblestone
fill ~119~42~15 ~119~42~17 minecraft:stonebrick 0
fill ~119~48~15 ~119~48~17 minecraft:stonebrick 0
fill ~119~49~15 ~120~49~25 minecraft:cobblestone
fill ~120~16~15 ~120~16~73 minecraft:cobblestone
fill ~121~0~15 ~123~0~159 minecraft:cobblestone
setblock ~121~16~15 minecraft:stonebrick 0
setblock ~121~30~15 minecraft:stonebrick 0
fill ~121~49~15 ~121~50~15 minecraft:stonebrick 0
fill ~122~50~15 ~123~50~15 minecraft:stonebrick 0
fill ~124~0~15 ~175~0~15 minecraft:grass
fill ~124~49~15 ~125~49~16 minecraft:stonebrick 0
fill ~124~57~15 ~125~57~15 minecraft:stonebrick 0
fill ~126~16~15 ~127~16~17 minecraft:stonebrick 0
fill ~126~17~15 ~127~17~15 minecraft:stonebrick 0
fill ~126~30~15 ~127~30~17 minecraft:stonebrick 0
fill ~126~31~15 ~127~31~15 minecraft:stonebrick 0
fill ~126~41~15 ~127~41~17 minecraft:stonebrick 0
fill ~126~42~15 ~127~42~15 minecraft:stonebrick 0
fill ~126~58~15 ~127~58~19 minecraft:stonebrick 0
fill ~127~59~15 ~127~62~15 minecraft:fence 0
setblock ~127~63~15 minecraft:torch 5
fill ~2~0~16 ~49~0~16 minecraft:grass
fill ~45~16~16 ~46~16~18 minecraft:stonebrick 0
fill ~45~17~16 ~46~17~16 minecraft:stonebrick 0
fill ~45~30~16 ~46~30~18 minecraft:stonebrick 0
fill ~45~31~16 ~46~31~16 minecraft:stonebrick 0
fill ~45~41~16 ~46~41~18 minecraft:stonebrick 0
fill ~45~42~16 ~46~42~16 minecraft:stonebrick 0
fill ~45~58~16 ~46~58~21 minecraft:stonebrick 0
fill ~47~49~16 ~48~49~17 minecraft:stonebrick 0
fill ~47~57~16 ~48~57~18 minecraft:stonebrick 0
fill ~50~0~16 ~50~0~158 minecraft:cobblestone
setblock ~50~50~16 minecraft:stonebrick 0
setblock ~50~56~16 minecraft:stonebrick 0
setblock ~51~16~16 minecraft:stonebrick 0
setblock ~51~30~16 minecraft:stonebrick 0
fill ~52~16~16 ~53~16~76 minecraft:cobblestone
fill ~52~30~16 ~53~30~39 minecraft:cobblestone
fill ~52~41~16 ~53~41~32 minecraft:cobblestone
fill ~52~49~16 ~53~49~26 minecraft:cobblestone
fill ~53~17~16 ~54~17~17 minecraft:stonebrick 0
setblock ~53~57~16 minecraft:stonebrick 0
setblock ~54~16~16 minecraft:stonebrick 0
fill ~55~1~16 ~55~1~18 minecraft:stonebrick 0
setblock ~55~58~16 minecraft:stonebrick 0
setblock ~56~16~16 minecraft:cobblestone
fill ~56~41~16 ~56~48~16 minecraft:stonebrick 0
fill ~84~33~16 ~89~33~16 minecraft:stone_stairs 3
setblock ~87~43~16 minecraft:torch 3
setblock ~117~16~16 minecraft:cobblestone
fill ~117~41~16 ~117~48~16 minecraft:stonebrick 0
setblock ~119~58~16 minecraft:stonebrick 0
fill ~121~16~16 ~122~16~76 minecraft:cobblestone
fill ~121~30~16 ~122~30~39 minecraft:cobblestone
fill ~121~41~16 ~122~41~32 minecraft:cobblestone
fill ~121~49~16 ~123~49~26 minecraft:cobblestone
setblock ~121~57~16 minecraft:stonebrick 0
setblock ~123~16~16 minecraft:stonebrick 0
setblock ~123~30~16 minecraft:stonebrick 0
setblock ~123~41~16 minecraft:stonebrick 0
fill ~124~0~16 ~124~0~158 minecraft:cobblestone
setblock ~124~50~16 minecraft:stonebrick 0
fill ~124~56~16 ~124~57~16 minecraft:stonebrick 0
fill ~125~0~16 ~175~0~16 minecraft:grass
fill ~126~49~16 ~127~49~17 minecraft:stonebrick 0
fill ~126~57~16 ~127~57~18 minecraft:stonebrick 0
fill ~128~16~16 ~129~16~19 minecraft:stonebrick 0
fill ~128~17~16 ~129~17~16 minecraft:stonebrick 0
fill ~128~30~16 ~129~30~18 minecraft:stonebrick 0
fill ~128~31~16 ~129~31~16 minecraft:stonebrick 0
fill ~128~41~16 ~129~41~18 minecraft:stonebrick 0
fill ~128~42~16 ~129~42~16 minecraft:stonebrick 0
fill ~128~58~16 ~129~58~21 minecraft:stonebrick 0
fill ~2~0~17 ~47~0~17 minecraft:grass
fill ~44~16~17 ~44~16~20 minecraft:stonebrick 0
setblock ~44~17~17 minecraft:stonebrick 0
fill ~44~30~17 ~44~30~23 minecraft:stonebrick 0
setblock ~44~31~17 minecraft:stonebrick 0
fill ~44~41~17 ~44~41~21 minecraft:stonebrick 0
setblock ~44~42~17 minecraft:stonebrick 0
fill ~44~58~17 ~44~58~22 minecraft:stonebrick 0
fill ~46~49~17 ~46~49~18 minecraft:stonebrick 0
fill ~46~57~17 ~46~57~19 minecraft:stonebrick 0
fill ~48~0~17 ~49~0~157 minecraft:cobblestone
fill ~48~50~17 ~49~56~17 minecraft:stonebrick 0
setblock ~49~16~17 minecraft:stonebrick 0
setblock ~49~30~17 minecraft:stonebrick 0
setblock ~49~41~17 minecraft:stonebrick 0
setblock ~49~49~17 minecraft:stonebrick 0
fill ~50~16~17 ~51~16~157 minecraft:cobblestone
fill ~50~30~17 ~51~30~40 minecraft:cobblestone
fill ~50~41~17 ~51~41~33 minecraft:cobblestone
fill ~50~49~17 ~51~49~27 minecraft:cobblestone
setblock ~51~57~17 minecraft:stonebrick 0
setblock ~53~58~17 minecraft:stonebrick 0
fill ~54~16~17 ~54~16~73 minecraft:cobblestone
fill ~55~2~17 ~57~29~17 minecraft:stonebrick 0
fill ~55~30~17 ~57~30~36 minecraft:cobblestone
fill ~55~41~17 ~57~41~29 minecraft:cobblestone
fill ~56~1~17 ~57~1~18 minecraft:stonebrick 0
fill ~56~42~17 ~57~42~17 minecraft:stonebrick 0
fill ~56~48~17 ~57~48~17 minecraft:stonebrick 0
fill ~58~16~17 ~58~16~66 minecraft:cobblestone
setblock ~82~34~17 minecraft:torch 4
fill ~84~32~17 ~89~32~17 minecraft:stone_stairs 3
setblock ~84~43~17 minecraft:torch 4
setblock ~90~43~17 minecraft:torch 4
setblock ~91~34~17 minecraft:torch 4
fill ~115~16~17 ~115~16~65 minecraft:cobblestone
fill ~115~17~17 ~119~17~18 minecraft:stonebrick 0
fill ~116~1~17 ~118~1~18 minecraft:stonebrick 0
fill ~116~2~17 ~118~16~17 minecraft:stonebrick 0
fill ~116~18~17 ~118~29~17 minecraft:stonebrick 0
fill ~116~30~17 ~118~30~36 minecraft:cobblestone
fill ~116~41~17 ~118~41~29 minecraft:cobblestone
fill ~117~42~17 ~118~42~17 minecraft:stonebrick 0
fill ~117~48~17 ~118~48~17 minecraft:stonebrick 0
fill ~119~16~17 ~119~16~71 minecraft:cobblestone
setblock ~121~58~17 minecraft:stonebrick 0
fill ~123~16~17 ~124~16~157 minecraft:cobblestone
fill ~123~30~17 ~124~30~40 minecraft:cobblestone
fill ~123~41~17 ~124~41~33 minecraft:cobblestone
fill ~123~57~17 ~125~57~17 minecraft:stonebrick 0
fill ~124~49~17 ~124~49~28 minecraft:cobblestone
fill ~125~0~17 ~126~0~157 minecraft:cobblestone
setblock ~125~16~17 minecraft:stonebrick 0
setblock ~125~30~17 minecraft:stonebrick 0
setblock ~125~41~17 minecraft:stonebrick 0
fill ~125~49~17 ~125~56~17 minecraft:stonebrick 0
fill ~126~50~17 ~126~56~17 minecraft:stonebrick 0
fill ~127~0~17 ~175~0~17 minecraft:grass
fill ~128~15~17 ~130~15~19 minecraft:stonebrick 0
fill ~128~29~17 ~130~29~19 minecraft:stonebrick 0
fill ~128~49~17 ~128~49~18 minecraft:stonebrick 0
fill ~128~57~17 ~128~57~19 minecraft:stonebrick 0
fill ~130~16~17 ~130~16~20 minecraft:stonebrick 0
fill ~130~17~17 ~130~17~19 minecraft:stonebrick 0
fill ~130~30~17 ~130~30~22 minecraft:stonebrick 0
setblock ~130~31~17 minecraft:stonebrick 0
fill ~130~41~17 ~132~41~20 minecraft:stonebrick 0
fill ~130~42~17 ~132~42~17 minecraft:stonebrick 0
fill ~130~58~17 ~130~58~22 minecraft:stonebrick 0
fill ~2~0~18 ~45~0~18 minecraft:grass
fill ~41~41~18 ~43~41~21 minecraft:stonebrick 0
fill ~41~42~18 ~43~42~18 minecraft:stonebrick 0
fill ~42~16~18 ~43~17~20 minecraft:stonebrick 0
fill ~42~30~18 ~43~30~21 minecraft:stonebrick 0
fill ~42~31~18 ~43~31~18 minecraft:stonebrick 0
fill ~42~58~18 ~43~58~22 minecraft:stonebrick 0
fill ~43~15~18 ~45~15~20 minecraft:stonebrick 0
fill ~43~29~18 ~45~29~20 minecraft:stonebrick 0
fill ~43~59~18 ~43~62~18 minecraft:fence 0
setblock ~43~63~18 minecraft:torch 5
fill ~44~49~18 ~45~49~19 minecraft:stonebrick 0
fill ~44~57~18 ~45~57~20 minecraft:stonebrick 0
fill ~46~0~18 ~47~0~156 minecraft:cobblestone
fill ~46~50~18 ~47~50~18 minecraft:stonebrick 0
setblock ~47~16~18 minecraft:stonebrick 0
setblock ~47~30~18 minecraft:stonebrick 0
setblock ~47~41~18 minecraft:stonebrick 0
setblock ~47~49~18 minecraft:stonebrick 0
setblock ~47~56~18 minecraft:stonebrick 0
fill ~48~16~18 ~49~16~156 minecraft:cobblestone
fill ~48~30~18 ~49~30~42 minecraft:cobblestone
fill ~48~41~18 ~49~41~34 minecraft:cobblestone
fill ~48~49~18 ~49~49~28 minecraft:cobblestone
setblock ~49~57~18 minecraft:stonebrick 0
setblock ~51~58~18 minecraft:stonebrick 0
fill ~54~17~18 ~57~17~18 minecraft:stonebrick 0
fill ~55~14~18 ~57~15~18 minecraft:stonebrick 0
fill ~55~16~18 ~57~16~68 minecraft:cobblestone
fill ~55~28~18 ~57~29~18 minecraft:stonebrick 0
fill ~79~42~18 ~85~42~22 minecraft:stonebrick 0
fill ~79~43~18 ~85~43~21 minecraft:stonebrick 0
fill ~79~44~18 ~85~44~20 minecraft:stonebrick 0
fill ~79~45~18 ~84~45~19 minecraft:stonebrick 0
fill ~79~46~18 ~83~46~18 minecraft:stonebrick 0
fill ~79~49~18 ~95~50~18 minecraft:stonebrick 0
fill ~80~48~18 ~81~48~18 minecraft:stonebrick 0
setblock ~81~34~18 minecraft:torch 2
setblock ~81~47~18 minecraft:stonebrick 0
fill ~82~31~18 ~82~33~18 minecraft:fence 0
setblock ~82~34~18 minecraft:wool 0
setblock ~83~34~18 minecraft:torch 1
fill ~84~31~18 ~89~31~18 minecraft:stone_stairs 3
fill ~84~48~18 ~86~48~18 minecraft:stonebrick 0
fill ~85~46~18 ~89~46~18 minecraft:stonebrick 0
setblock ~85~47~18 minecraft:stonebrick 0
fill ~88~48~18 ~90~48~18 minecraft:stonebrick 0
fill ~89~42~18 ~95~42~22 minecraft:stonebrick 0
fill ~89~43~18 ~95~43~21 minecraft:stonebrick 0
fill ~89~44~18 ~95~44~20 minecraft:stonebrick 0
setblock ~89~47~18 minecraft:stonebrick 0
setblock ~90~34~18 minecraft:torch 2
fill ~90~45~18 ~95~45~19 minecraft:stonebrick 0
fill ~91~31~18 ~91~33~18 minecraft:fence 0
setblock ~91~34~18 minecraft:wool 0
fill ~91~46~18 ~95~46~18 minecraft:stonebrick 0
setblock ~92~34~18 minecraft:torch 1
fill ~93~47~18 ~93~48~18 minecraft:stonebrick 0
setblock ~94~48~18 minecraft:stonebrick 0
fill ~116~14~18 ~118~15~18 minecraft:stonebrick 0
fill ~116~16~18 ~118~16~66 minecraft:cobblestone
fill ~116~28~18 ~118~29~18 minecraft:stonebrick 0
setblock ~123~58~18 minecraft:stonebrick 0
fill ~125~16~18 ~126~16~156 minecraft:cobblestone
fill ~125~30~18 ~126~30~42 minecraft:cobblestone
fill ~125~41~18 ~126~41~34 minecraft:cobblestone
fill ~125~49~18 ~126~49~28 minecraft:cobblestone
setblock ~125~57~18 minecraft:stonebrick 0
fill ~127~0~18 ~128~0~156 minecraft:cobblestone
fill ~127~1~18 ~131~1~19 minecraft:stonebrick 0
fill ~127~15~18 ~127~15~24 minecraft:stonebrick 0
fill ~127~16~18 ~127~17~18 minecraft:stonebrick 0
fill ~127~29~18 ~127~29~24 minecraft:stonebrick 0
setblock ~127~30~18 minecraft:stonebrick 0
setblock ~127~41~18 minecraft:stonebrick 0
fill ~127~49~18 ~127~50~18 minecraft:stonebrick 0
setblock ~127~56~18 minecraft:stonebrick 0
fill ~128~14~18 ~130~14~19 minecraft:stonebrick 0
fill ~128~17~18 ~129~17~19 minecraft:stonebrick 0
fill ~128~28~18 ~130~28~19 minecraft:stonebrick 0
setblock ~128~50~18 minecraft:stonebrick 0
fill ~129~0~18 ~131~0~18 minecraft:dirt 0
fill ~129~49~18 ~130~49~19 minecraft:stonebrick 0
fill ~129~57~18 ~130~57~20 minecraft:stonebrick 0
fill ~131~15~18 ~131~15~24 minecraft:stonebrick 0
fill ~131~16~18 ~132~17~21 minecraft:stonebrick 0
fill ~131~29~18 ~131~29~24 minecraft:stonebrick 0
fill ~131~30~18 ~132~30~20 minecraft:stonebrick 0
fill ~131~31~18 ~132~31~18 minecraft:stonebrick 0
fill ~131~58~18 ~132~58~22 minecraft:stonebrick 0
fill ~131~59~18 ~131~62~18 minecraft:fence 0
setblock ~131~63~18 minecraft:torch 5
fill ~132~0~18 ~175~0~18 minecraft:grass
fill ~133~41~18 ~133~41~22 minecraft:stonebrick 0
fill ~133~42~18 ~133~42~19 minecraft:stonebrick 0
fill ~2~0~19 ~41~0~19 minecraft:grass
fill ~40~41~19 ~40~41~22 minecraft:stonebrick 0
fill ~40~42~19 ~40~42~20 minecraft:stonebrick 0
fill ~41~16~19 ~41~17~22 minecraft:stonebrick 0
fill ~41~30~19 ~41~30~22 minecraft:stonebrick 0
setblock ~41~31~19 minecraft:stonebrick 0
fill ~41~58~19 ~41~58~24 minecraft:stonebrick 0
fill ~42~0~19 ~43~0~19 minecraft:dirt 0
fill ~42~1~19 ~46~1~20 minecraft:stonebrick 0
fill ~42~15~19 ~42~15~25 minecraft:stonebrick 0
fill ~42~29~19 ~42~29~25 minecraft:stonebrick 0
fill ~43~14~19 ~45~14~20 minecraft:stonebrick 0
fill ~43~28~19 ~45~28~20 minecraft:stonebrick 0
fill ~43~49~19 ~43~49~20 minecraft:stonebrick 0
fill ~43~57~19 ~43~57~21 minecraft:stonebrick 0
fill ~44~0~19 ~45~0~155 minecraft:cobblestone
fill ~44~17~19 ~46~17~20 minecraft:stonebrick 0
fill ~44~50~19 ~45~50~19 minecraft:stonebrick 0
fill ~45~16~19 ~45~16~20 minecraft:stonebrick 0
setblock ~45~30~19 minecraft:stonebrick 0
setblock ~45~41~19 minecraft:stonebrick 0
fill ~46~15~19 ~46~15~25 minecraft:stonebrick 0
fill ~46~16~19 ~47~16~20 minecraft:cobblestone
fill ~46~29~19 ~46~29~25 minecraft:stonebrick 0
fill ~46~30~19 ~47~30~44 minecraft:cobblestone
fill ~46~41~19 ~47~41~36 minecraft:cobblestone
fill ~46~49~19 ~47~49~30 minecraft:cobblestone
setblock ~47~57~19 minecraft:stonebrick 0
setblock ~49~58~19 minecraft:stonebrick 0
fill ~55~15~19 ~57~15~19 minecraft:stonebrick 0
fill ~55~29~19 ~57~29~19 minecraft:stonebrick 0
setblock ~72~49~19 minecraft:cobblestone
fill ~73~42~19 ~78~42~23 minecraft:stonebrick 0
fill ~73~43~19 ~78~43~22 minecraft:stonebrick 0
fill ~73~44~19 ~78~44~21 minecraft:stonebrick 0
fill ~73~45~19 ~78~45~20 minecraft:stonebrick 0
fill ~73~46~19 ~78~46~19 minecraft:stonebrick 0
fill ~73~47~19 ~73~50~19 minecraft:stonebrick 0
fill ~74~48~19 ~74~50~19 minecraft:stonebrick 0
fill ~75~49~19 ~78~50~19 minecraft:stonebrick 0
fill ~76~48~19 ~78~48~19 minecraft:stonebrick 0
setblock ~77~47~19 minecraft:stonebrick 0
setblock ~82~34~19 minecraft:torch 3
setblock ~91~34~19 minecraft:torch 3
fill ~96~42~19 ~101~42~23 minecraft:stonebrick 0
fill ~96~43~19 ~101~43~22 minecraft:stonebrick 0
fill ~96~44~19 ~101~44~21 minecraft:stonebrick 0
fill ~96~45~19 ~101~45~20 minecraft:stonebrick 0
fill ~96~46~19 ~101~46~19 minecraft:stonebrick 0
fill ~96~48~19 ~98~50~19 minecraft:stonebrick 0
setblock ~97~47~19 minecraft:stonebrick 0
fill ~99~49~19 ~101~50~19 minecraft:stonebrick 0
fill ~100~48~19 ~101~48~19 minecraft:stonebrick 0
setblock ~101~47~19 minecraft:stonebrick 0
setblock ~102~49~19 minecraft:cobblestone
fill ~116~15~19 ~118~15~19 minecraft:stonebrick 0
fill ~116~29~19 ~118~29~19 minecraft:stonebrick 0
setblock ~125~58~19 minecraft:stonebrick 0
fill ~126~1~19 ~126~1~23 minecraft:stonebrick 0
fill ~126~15~19 ~126~15~23 minecraft:stonebrick 0
fill ~126~17~19 ~127~17~23 minecraft:stonebrick 0
fill ~126~29~19 ~126~29~23 minecraft:stonebrick 0
fill ~127~14~19 ~127~14~23 minecraft:stonebrick 0
setblock ~127~16~19 minecraft:cobblestone
fill ~127~28~19 ~127~28~23 minecraft:stonebrick 0
fill ~127~30~19 ~128~30~19 minecraft:cobblestone
fill ~127~31~19 ~131~31~23 minecraft:stonebrick 0
fill ~127~40~19 ~131~40~23 minecraft:stonebrick 0
fill ~127~41~19 ~128~41~19 minecraft:cobblestone
fill ~127~42~19 ~131~42~20 minecraft:stonebrick 0
fill ~127~48~19 ~131~48~20 minecraft:stonebrick 0
fill ~127~49~19 ~128~49~30 minecraft:cobblestone
setblock ~127~57~19 minecraft:stonebrick 0
fill ~128~2~19 ~130~13~19 minecraft:stonebrick 0
fill ~128~18~19 ~130~27~19 minecraft:stonebrick 0
fill ~129~0~19 ~130~0~155 minecraft:cobblestone
fill ~129~30~19 ~129~30~22 minecraft:stonebrick 0
fill ~129~41~19 ~129~41~20 minecraft:stonebrick 0
fill ~129~50~19 ~130~50~19 minecraft:stonebrick 0
fill ~131~0~19 ~132~0~19 minecraft:dirt 0
fill ~131~14~19 ~131~14~23 minecraft:stonebrick 0
fill ~131~28~19 ~131~28~23 minecraft:stonebrick 0
fill ~131~49~19 ~131~49~20 minecraft:stonebrick 0
fill ~131~57~19 ~131~57~21 minecraft:stonebrick 0
fill ~132~1~19 ~132~1~23 minecraft:stonebrick 0
fill ~132~15~19 ~132~15~23 minecraft:stonebrick 0
fill ~132~29~19 ~132~29~23 minecraft:stonebrick 0
fill ~133~0~19 ~175~0~20 minecraft:grass
fill ~133~16~19 ~133~16~22 minecraft:stonebrick 0
setblock ~133~17~19 minecraft:stonebrick 0
fill ~133~30~19 ~133~30~22 minecraft:stonebrick 0
setblock ~133~31~19 minecraft:stonebrick 0
fill ~133~58~19 ~133~58~24 minecraft:stonebrick 0
fill ~2~0~20 ~40~0~21 minecraft:grass
fill ~39~16~20 ~40~16~22 minecraft:stonebrick 0
fill ~39~17~20 ~40~17~20 minecraft:stonebrick 0
fill ~39~30~20 ~40~30~22 minecraft:stonebrick 0
fill ~39~31~20 ~40~31~20 minecraft:stonebrick 0
fill ~39~41~20 ~39~41~23 minecraft:stonebrick 0
setblock ~39~42~20 minecraft:stonebrick 0
fill ~39~58~20 ~40~58~25 minecraft:stonebrick 0
fill ~39~59~20 ~39~62~20 minecraft:fence 0
setblock ~39~63~20 minecraft:torch 5
fill ~41~0~20 ~42~0~20 minecraft:dirt 0
fill ~41~1~20 ~41~1~24 minecraft:stonebrick 0
fill ~41~15~20 ~41~15~24 minecraft:stonebrick 0
fill ~41~29~20 ~41~29~24 minecraft:stonebrick 0
fill ~41~49~20 ~42~49~21 minecraft:stonebrick 0
fill ~41~57~20 ~42~57~22 minecraft:stonebrick 0
fill ~42~14~20 ~42~14~24 minecraft:stonebrick 0
fill ~42~28~20 ~42~28~24 minecraft:stonebrick 0
fill ~42~31~20 ~46~31~24 minecraft:stonebrick 0
fill ~42~40~20 ~46~40~24 minecraft:stonebrick 0
fill ~42~42~20 ~46~42~21 minecraft:stonebrick 0
fill ~42~48~20 ~46~48~21 minecraft:stonebrick 0
fill ~43~0~20 ~43~0~154 minecraft:cobblestone
fill ~43~2~20 ~45~13~20 minecraft:stonebrick 0
fill ~43~18~20 ~45~27~20 minecraft:stonebrick 0
setblock ~43~50~20 minecraft:stonebrick 0
fill ~43~56~20 ~44~56~20 minecraft:stonebrick 0
fill ~44~49~20 ~45~49~31 minecraft:cobblestone
setblock ~45~30~20 minecraft:cobblestone
setblock ~45~41~20 minecraft:cobblestone
fill ~46~14~20 ~46~14~24 minecraft:stonebrick 0
fill ~46~28~20 ~46~28~24 minecraft:stonebrick 0
fill ~47~1~20 ~47~1~24 minecraft:stonebrick 0
fill ~47~15~20 ~47~15~24 minecraft:stonebrick 0
fill ~47~17~20 ~47~17~24 minecraft:stonebrick 0
fill ~47~29~20 ~47~29~24 minecraft:stonebrick 0
setblock ~47~58~20 minecraft:stonebrick 0
setblock ~68~49~20 minecraft:cobblestone
fill ~69~42~20 ~72~42~24 minecraft:stonebrick 0
fill ~69~43~20 ~72~43~23 minecraft:stonebrick 0
fill ~69~44~20 ~72~44~22 minecraft:stonebrick 0
fill ~69~45~20 ~72~45~21 minecraft:stonebrick 0
fill ~69~46~20 ~72~46~20 minecraft:stonebrick 0
fill ~69~47~20 ~69~50~20 minecraft:stonebrick 0
fill ~70~48~20 ~70~50~20 minecraft:stonebrick 0
fill ~71~49~20 ~72~50~20 minecraft:stonebrick 0
setblock ~72~48~20 minecraft:stonebrick 0
fill ~80~45~20 ~82~45~20 minecraft:stone_stairs 3
setblock ~83~20~20 minecraft:torch 4
setblock ~91~20~20 minecraft:torch 4
fill ~92~45~20 ~94~45~20 minecraft:stone_stairs 3
fill ~102~42~20 ~105~42~24 minecraft:stonebrick 0
fill ~102~43~20 ~105~43~23 minecraft:stonebrick 0
fill ~102~44~20 ~105~44~22 minecraft:stonebrick 0
fill ~102~45~20 ~105~45~21 minecraft:stonebrick 0
fill ~102~46~20 ~105~46~20 minecraft:stonebrick 0
fill ~102~48~20 ~102~50~20 minecraft:stonebrick 0
fill ~103~49~20 ~105~50~20 minecraft:stonebrick 0
fill ~104~48~20 ~105~48~20 minecraft:stonebrick 0
setblock ~105~47~20 minecraft:stonebrick 0
setblock ~106~49~20 minecraft:cobblestone
fill ~125~15~20 ~125~15~22 minecraft:stonebrick 0
fill ~125~29~20 ~125~29~22 minecraft:stonebrick 0
fill ~126~14~20 ~126~14~22 minecraft:stonebrick 0
fill ~126~28~20 ~126~28~22 minecraft:stonebrick 0
fill ~127~1~20 ~127~1~24 minecraft:stonebrick 0
fill ~127~2~20 ~127~13~22 minecraft:stonebrick 0
fill ~127~16~20 ~127~16~22 minecraft:stonebrick 0
fill ~127~18~20 ~127~27~22 minecraft:stonebrick 0
fill ~127~30~20 ~127~30~44 minecraft:cobblestone
fill ~127~41~20 ~127~41~36 minecraft:cobblestone
setblock ~127~58~20 minecraft:stonebrick 0
fill ~128~16~20 ~129~16~20 minecraft:cobblestone
fill ~128~30~20 ~128~30~22 minecraft:stonebrick 0
fill ~128~32~20 ~130~39~22 minecraft:stonebrick 0
fill ~128~41~20 ~128~41~22 minecraft:stonebrick 0
fill ~128~43~20 ~130~47~20 minecraft:stonebrick 0
fill ~129~15~20 ~129~15~21 minecraft:wool 0
fill ~129~49~20 ~130~49~31 minecraft:cobblestone
fill ~131~0~20 ~131~0~154 minecraft:cobblestone
fill ~131~1~20 ~131~1~24 minecraft:stonebrick 0
fill ~131~2~20 ~131~13~22 minecraft:stonebrick 0
fill ~131~18~20 ~131~27~22 minecraft:stonebrick 0
setblock ~131~50~20 minecraft:stonebrick 0
setblock ~131~56~20 minecraft:stonebrick 0
setblock ~132~0~20 minecraft:dirt 0
fill ~132~14~20 ~132~14~22 minecraft:stonebrick 0
fill ~132~28~20 ~132~28~22 minecraft:stonebrick 0
fill ~132~49~20 ~133~49~21 minecraft:stonebrick 0
fill ~132~57~20 ~133~57~22 minecraft:stonebrick 0
fill ~133~15~20 ~133~15~22 minecraft:stonebrick 0
fill ~133~29~20 ~133~29~22 minecraft:stonebrick 0
fill ~134~16~20 ~135~16~22 minecraft:stonebrick 0
fill ~134~17~20 ~135~17~20 minecraft:stonebrick 0
fill ~134~30~20 ~135~30~22 minecraft:stonebrick 0
fill ~134~31~20 ~135~31~20 minecraft:stonebrick 0
fill ~134~41~20 ~135~41~22 minecraft:stonebrick 0
fill ~134~42~20 ~135~42~20 minecraft:stonebrick 0
fill ~134~58~20 ~135~58~25 minecraft:stonebrick 0
fill ~135~59~20 ~135~62~20 minecraft:fence 0
setblock ~135~63~20 minecraft:torch 5
fill ~38~16~21 ~38~16~24 minecraft:stonebrick 0
setblock ~38~17~21 minecraft:stonebrick 0
fill ~38~30~21 ~38~30~24 minecraft:stonebrick 0
setblock ~38~31~21 minecraft:stonebrick 0
fill ~38~41~21 ~38~41~24 minecraft:stonebrick 0
setblock ~38~42~21 minecraft:stonebrick 0
fill ~38~58~21 ~38~58~26 minecraft:stonebrick 0
fill ~40~15~21 ~40~15~23 minecraft:stonebrick 0
fill ~40~29~21 ~40~29~23 minecraft:stonebrick 0
fill ~40~49~21 ~40~49~22 minecraft:stonebrick 0
fill ~40~57~21 ~40~57~23 minecraft:stonebrick 0
fill ~41~0~21 ~42~0~153 minecraft:cobblestone
fill ~41~14~21 ~41~14~23 minecraft:stonebrick 0
fill ~41~28~21 ~41~28~23 minecraft:stonebrick 0
fill ~41~50~21 ~42~56~21 minecraft:stonebrick 0
fill ~42~1~21 ~42~1~25 minecraft:stonebrick 0
fill ~42~2~21 ~42~13~23 minecraft:stonebrick 0
fill ~42~16~21 ~42~27~23 minecraft:stonebrick 0
fill ~43~16~21 ~45~16~21 minecraft:cobblestone
fill ~43~32~21 ~45~39~23 minecraft:stonebrick 0
fill ~43~43~21 ~45~47~21 minecraft:stonebrick 0
fill ~43~49~21 ~43~49~33 minecraft:cobblestone
fill ~44~15~21 ~44~15~22 minecraft:wool 0
setblock ~44~57~21 minecraft:stonebrick 0
fill ~45~1~21 ~46~1~21 minecraft:stonebrick 0
fill ~45~30~21 ~45~30~23 minecraft:stonebrick 0
fill ~45~41~21 ~45~41~23 minecraft:stonebrick 0
fill ~46~2~21 ~46~13~23 minecraft:stonebrick 0
fill ~46~16~21 ~46~27~23 minecraft:stonebrick 0
fill ~47~14~21 ~47~14~23 minecraft:stonebrick 0
fill ~47~16~21 ~47~16~151 minecraft:cobblestone
fill ~47~28~21 ~47~28~23 minecraft:stonebrick 0
fill ~48~15~21 ~48~15~23 minecraft:stonebrick 0
fill ~48~29~21 ~48~29~23 minecraft:stonebrick 0
fill ~64~49~21 ~65~49~21 minecraft:cobblestone
fill ~66~42~21 ~68~42~25 minecraft:stonebrick 0
fill ~66~43~21 ~68~43~24 minecraft:stonebrick 0
fill ~66~44~21 ~68~44~23 minecraft:stonebrick 0
fill ~66~45~21 ~68~45~22 minecraft:stonebrick 0
fill ~66~46~21 ~68~46~21 minecraft:stonebrick 0
fill ~66~48~21 ~66~50~21 minecraft:stonebrick 0
fill ~67~49~21 ~68~50~21 minecraft:stonebrick 0
setblock ~68~48~21 minecraft:stonebrick 0
fill ~80~44~21 ~82~44~21 minecraft:stone_stairs 3
setblock ~82~20~21 minecraft:torch 2
fill ~83~17~21 ~83~19~21 minecraft:fence 0
setblock ~83~20~21 minecraft:wool 0
setblock ~84~20~21 minecraft:torch 1
fill ~85~17~21 ~89~17~21 minecraft:stone_stairs 2
fill ~85~44~21 ~85~44~23 minecraft:stonebrick 0
fill ~89~44~21 ~89~44~23 minecraft:stonebrick 0
setblock ~90~20~21 minecraft:torch 2
fill ~91~17~21 ~91~19~21 minecraft:fence 0
setblock ~91~20~21 minecraft:wool 0
setblock ~92~20~21 minecraft:torch 1
fill ~92~44~21 ~94~44~21 minecraft:stone_stairs 3
fill ~106~42~21 ~108~42~25 minecraft:stonebrick 0
fill ~106~43~21 ~108~43~24 minecraft:stonebrick 0
fill ~106~44~21 ~108~44~23 minecraft:stonebrick 0
fill ~106~45~21 ~108~45~22 minecraft:stonebrick 0
fill ~106~46~21 ~108~46~21 minecraft:stonebrick 0
fill ~106~48~21 ~106~50~21 minecraft:stonebrick 0
fill ~107~49~21 ~108~50~21 minecraft:stonebrick 0
setblock ~108~48~21 minecraft:stonebrick 0
fill ~109~49~21 ~110~49~21 minecraft:cobblestone
fill ~127~42~21 ~128~42~23 minecraft:stonebrick 0
fill ~127~48~21 ~128~48~23 minecraft:stonebrick 0
setblock ~128~1~21 minecraft:stonebrick 0
fill ~128~16~21 ~128~16~22 minecraft:cobblestone
fill ~128~29~21 ~129~29~21 minecraft:wool 0
fill ~128~43~21 ~128~47~22 minecraft:stonebrick 0
fill ~130~16~21 ~130~16~22 minecraft:cobblestone
fill ~130~41~21 ~130~48~22 minecraft:stonebrick 0
setblock ~130~57~21 minecraft:stonebrick 0
fill ~131~30~21 ~131~30~48 minecraft:cobblestone
fill ~131~41~21 ~131~41~39 minecraft:cobblestone
fill ~131~42~21 ~131~42~23 minecraft:stonebrick 0
fill ~131~48~21 ~131~48~23 minecraft:stonebrick 0
fill ~131~49~21 ~131~49~33 minecraft:cobblestone
fill ~132~0~21 ~133~0~153 minecraft:cobblestone
setblock ~132~30~21 minecraft:stonebrick 0
setblock ~132~41~21 minecraft:stonebrick 0
fill ~132~50~21 ~133~56~21 minecraft:stonebrick 0
fill ~134~0~21 ~175~0~21 minecraft:grass
fill ~134~49~21 ~134~49~22 minecraft:stonebrick 0
fill ~134~57~21 ~134~57~23 minecraft:stonebrick 0
fill ~136~16~21 ~136~16~24 minecraft:stonebrick 0
setblock ~136~17~21 minecraft:stonebrick 0
fill ~136~30~21 ~136~30~24 minecraft:stonebrick 0
setblock ~136~31~21 minecraft:stonebrick 0
fill ~136~41~21 ~136~41~24 minecraft:stonebrick 0
setblock ~136~42~21 minecraft:stonebrick 0
fill ~136~58~21 ~136~58~26 minecraft:stonebrick 0
fill ~2~0~22 ~39~0~22 minecraft:grass
fill ~37~16~22 ~37~16~25 minecraft:stonebrick 0
setblock ~37~17~22 minecraft:stonebrick 0
fill ~37~30~22 ~37~30~25 minecraft:stonebrick 0
setblock ~37~31~22 minecraft:stonebrick 0
fill ~37~41~22 ~37~41~25 minecraft:stonebrick 0
setblock ~37~42~22 minecraft:stonebrick 0
fill ~37~58~22 ~37~58~27 minecraft:stonebrick 0
fill ~38~49~22 ~39~49~23 minecraft:stonebrick 0
fill ~38~57~22 ~39~57~24 minecraft:stonebrick 0
fill ~40~0~22 ~40~0~152 minecraft:cobblestone
setblock ~40~50~22 minecraft:stonebrick 0
setblock ~40~56~22 minecraft:stonebrick 0
setblock ~41~41~22 minecraft:stonebrick 0
fill ~41~49~22 ~42~49~34 minecraft:cobblestone
fill ~42~30~22 ~42~30~49 minecraft:cobblestone
fill ~42~41~22 ~42~41~40 minecraft:cobblestone
fill ~42~42~22 ~43~42~24 minecraft:stonebrick 0
fill ~42~48~22 ~43~48~24 minecraft:stonebrick 0
setblock ~43~1~22 minecraft:stonebrick 0
fill ~43~16~22 ~43~16~23 minecraft:cobblestone
fill ~43~29~22 ~44~29~22 minecraft:wool 0
fill ~43~30~22 ~43~30~23 minecraft:stonebrick 0
fill ~43~41~22 ~43~41~23 minecraft:stonebrick 0
fill ~43~43~22 ~43~47~23 minecraft:stonebrick 0
fill ~45~16~22 ~45~16~23 minecraft:cobblestone
fill ~45~42~22 ~46~42~24 minecraft:stonebrick 0
fill ~45~43~22 ~45~48~23 minecraft:stonebrick 0
fill ~46~1~22 ~46~1~25 minecraft:stonebrick 0
fill ~46~48~22 ~46~48~24 minecraft:stonebrick 0
fill ~61~49~22 ~62~49~22 minecraft:cobblestone
fill ~63~42~22 ~65~42~26 minecraft:stonebrick 0
fill ~63~43~22 ~65~43~25 minecraft:stonebrick 0
fill ~63~44~22 ~65~44~24 minecraft:stonebrick 0
fill ~63~45~22 ~65~45~23 minecraft:stonebrick 0
fill ~63~46~22 ~65~46~22 minecraft:stonebrick 0
fill ~63~49~22 ~65~50~22 minecraft:stonebrick 0
fill ~64~48~22 ~65~48~22 minecraft:stonebrick 0
setblock ~65~47~22 minecraft:stonebrick 0
fill ~80~43~22 ~82~43~22 minecraft:stone_stairs 3
setblock ~83~20~22 minecraft:torch 3
fill ~85~17~22 ~89~17~25 minecraft:stonebrick 0
fill ~85~18~22 ~89~18~22 minecraft:stone_stairs 2
fill ~85~43~22 ~85~43~23 minecraft:stonebrick 0
fill ~89~43~22 ~89~43~23 minecraft:stonebrick 0
setblock ~91~20~22 minecraft:torch 3
fill ~92~43~22 ~94~43~22 minecraft:stone_stairs 3
fill ~109~42~22 ~111~42~26 minecraft:stonebrick 0
fill ~109~43~22 ~111~43~25 minecraft:stonebrick 0
fill ~109~44~22 ~111~44~24 minecraft:stonebrick 0
fill ~109~45~22 ~111~45~23 minecraft:stonebrick 0
fill ~109~46~22 ~111~46~22 minecraft:stonebrick 0
fill ~109~47~22 ~109~50~22 minecraft:stonebrick 0
fill ~110~48~22 ~110~50~22 minecraft:stonebrick 0
fill ~111~49~22 ~111~50~22 minecraft:stonebrick 0
fill ~112~49~22 ~113~49~22 minecraft:cobblestone
setblock ~129~16~22 minecraft:cobblestone
fill ~129~41~22 ~129~48~22 minecraft:stonebrick 0
fill ~130~1~22 ~130~1~24 minecraft:stonebrick 0
fill ~131~16~22 ~131~17~22 minecraft:stonebrick 0
fill ~132~16~22 ~132~16~152 minecraft:cobblestone
fill ~132~17~22 ~132~17~23 minecraft:stonebrick 0
fill ~132~30~22 ~132~30~49 minecraft:cobblestone
fill ~132~41~22 ~132~41~40 minecraft:cobblestone
fill ~132~49~22 ~133~49~34 minecraft:cobblestone
fill ~134~0~22 ~134~0~152 minecraft:cobblestone
setblock ~134~50~22 minecraft:stonebrick 0
setblock ~134~56~22 minecraft:stonebrick 0
fill ~135~0~22 ~175~0~22 minecraft:grass
fill ~135~49~22 ~136~49~23 minecraft:stonebrick 0
fill ~135~57~22 ~136~57~24 minecraft:stonebrick 0
fill ~137~16~22 ~137~16~25 minecraft:stonebrick 0
setblock ~137~17~22 minecraft:stonebrick 0
fill ~137~30~22 ~137~30~25 minecraft:stonebrick 0
setblock ~137~31~22 minecraft:stonebrick 0
fill ~137~41~22 ~137~41~25 minecraft:stonebrick 0
setblock ~137~42~22 minecraft:stonebrick 0
fill ~137~58~22 ~137~58~27 minecraft:stonebrick 0
fill ~2~0~23 ~38~0~23 minecraft:grass
fill ~35~16~23 ~36~16~26 minecraft:stonebrick 0
fill ~35~17~23 ~36~17~23 minecraft:stonebrick 0
fill ~35~30~23 ~36~30~26 minecraft:stonebrick 0
fill ~35~31~23 ~36~31~23 minecraft:stonebrick 0
fill ~35~41~23 ~36~41~26 minecraft:stonebrick 0
fill ~35~42~23 ~36~42~23 minecraft:stonebrick 0
fill ~35~58~23 ~36~58~28 minecraft:stonebrick 0
fill ~35~59~23 ~35~62~23 minecraft:fence 0
setblock ~35~63~23 minecraft:torch 5
fill ~37~49~23 ~37~49~24 minecraft:stonebrick 0
fill ~37~57~23 ~37~57~26 minecraft:stonebrick 0
fill ~39~0~23 ~39~0~151 minecraft:cobblestone
setblock ~39~16~23 minecraft:stonebrick 0
setblock ~39~30~23 minecraft:stonebrick 0
setblock ~39~50~23 minecraft:stonebrick 0
fill ~40~16~23 ~41~16~74 minecraft:cobblestone
fill ~40~30~23 ~41~30~50 minecraft:cobblestone
fill ~40~41~23 ~41~41~41 minecraft:cobblestone
fill ~40~49~23 ~40~49~35 minecraft:cobblestone
fill ~41~17~23 ~41~17~24 minecraft:stonebrick 0
setblock ~41~57~23 minecraft:stonebrick 0
setblock ~42~58~23 minecraft:stonebrick 0
setblock ~44~16~23 minecraft:cobblestone
fill ~44~41~23 ~44~48~23 minecraft:stonebrick 0
fill ~58~49~23 ~59~49~23 minecraft:cobblestone
fill ~60~42~23 ~62~46~23 minecraft:stonebrick 0
fill ~60~48~23 ~62~50~23 minecraft:stonebrick 0
setblock ~61~47~23 minecraft:stonebrick 0
setblock ~78~41~23 minecraft:cobblestone
fill ~79~41~23 ~95~41~23 minecraft:stonebrick 0
fill ~80~42~23 ~82~42~23 minecraft:stone_stairs 3
fill ~85~18~23 ~89~18~25 minecraft:stonebrick 0
fill ~85~19~23 ~89~19~23 minecraft:stone_stairs 2
setblock ~85~42~23 minecraft:stonebrick 0
setblock ~89~42~23 minecraft:stonebrick 0
fill ~92~42~23 ~94~42~23 minecraft:stone_stairs 3
fill ~112~42~23 ~114~46~23 minecraft:stonebrick 0
fill ~112~48~23 ~114~50~23 minecraft:stonebrick 0
setblock ~113~47~23 minecraft:stonebrick 0
fill ~115~49~23 ~116~49~23 minecraft:cobblestone
fill ~127~16~23 ~127~16~151 minecraft:cobblestone
fill ~128~1~23 ~129~1~24 minecraft:stonebrick 0
fill ~128~2~23 ~130~29~23 minecraft:stonebrick 0
fill ~128~30~23 ~130~30~45 minecraft:cobblestone
fill ~128~41~23 ~130~41~36 minecraft:cobblestone
fill ~129~42~23 ~130~42~23 minecraft:stonebrick 0
fill ~129~48~23 ~130~48~23 minecraft:stonebrick 0
fill ~131~16~23 ~131~16~151 minecraft:cobblestone
fill ~131~17~23 ~131~17~24 minecraft:stonebrick 0
setblock ~132~58~23 minecraft:stonebrick 0
fill ~133~16~23 ~134~16~74 minecraft:cobblestone
fill ~133~30~23 ~134~30~50 minecraft:cobblestone
fill ~133~41~23 ~134~41~41 minecraft:cobblestone
setblock ~133~57~23 minecraft:stonebrick 0
fill ~134~49~23 ~134~49~35 minecraft:cobblestone
fill ~135~0~23 ~135~0~151 minecraft:cobblestone
setblock ~135~16~23 minecraft:stonebrick 0
setblock ~135~30~23 minecraft:stonebrick 0
setblock ~135~41~23 minecraft:stonebrick 0
setblock ~135~50~23 minecraft:stonebrick 0
fill ~136~0~23 ~175~0~23 minecraft:grass
fill ~137~49~23 ~137~49~24 minecraft:stonebrick 0
fill ~137~57~23 ~137~57~26 minecraft:stonebrick 0
fill ~138~16~23 ~139~16~26 minecraft:stonebrick 0
fill ~138~17~23 ~139~17~23 minecraft:stonebrick 0
fill ~138~30~23 ~139~30~26 minecraft:stonebrick 0
fill ~138~31~23 ~139~31~23 minecraft:stonebrick 0
fill ~138~41~23 ~139~41~26 minecraft:stonebrick 0
fill ~138~42~23 ~139~42~23 minecraft:stonebrick 0
fill ~138~58~23 ~139~58~28 minecraft:stonebrick 0
fill ~139~59~23 ~139~62~23 minecraft:fence 0
setblock ~139~63~23 minecraft:torch 5
fill ~2~0~24 ~36~0~24 minecraft:grass
fill ~34~16~24 ~34~16~27 minecraft:stonebrick 0
setblock ~34~17~24 minecraft:stonebrick 0
fill ~34~30~24 ~34~30~27 minecraft:stonebrick 0
setblock ~34~31~24 minecraft:stonebrick 0
fill ~34~41~24 ~34~41~27 minecraft:stonebrick 0
setblock ~34~42~24 minecraft:stonebrick 0
fill ~34~58~24 ~34~58~30 minecraft:stonebrick 0
fill ~36~49~24 ~36~49~25 minecraft:stonebrick 0
fill ~36~57~24 ~36~57~27 minecraft:stonebrick 0
fill ~37~0~24 ~38~0~150 minecraft:cobblestone
fill ~37~50~24 ~38~50~24 minecraft:stonebrick 0
setblock ~38~49~24 minecraft:stonebrick 0
fill ~39~16~24 ~39~16~74 minecraft:cobblestone
fill ~39~30~24 ~39~30~53 minecraft:cobblestone
fill ~39~41~24 ~39~41~43 minecraft:cobblestone
fill ~39~49~24 ~39~49~36 minecraft:cobblestone
fill ~42~16~24 ~42~16~152 minecraft:cobblestone
fill ~42~17~24 ~46~17~25 minecraft:stonebrick 0
fill ~43~1~24 ~45~1~25 minecraft:stonebrick 0
fill ~43~2~24 ~45~16~24 minecraft:stonebrick 0
fill ~43~18~24 ~45~29~24 minecraft:stonebrick 0
fill ~43~30~24 ~45~30~46 minecraft:cobblestone
fill ~43~41~24 ~45~41~37 minecraft:cobblestone
setblock ~44~42~24 minecraft:stonebrick 0
fill ~44~48~24 ~45~48~24 minecraft:stonebrick 0
fill ~46~16~24 ~46~16~150 minecraft:cobblestone
fill ~58~42~24 ~59~45~25 minecraft:stonebrick 0
fill ~58~46~24 ~59~46~24 minecraft:stonebrick 0
fill ~58~48~24 ~58~50~24 minecraft:stonebrick 0
fill ~59~49~24 ~59~50~24 minecraft:stonebrick 0
fill ~60~45~24 ~62~45~24 minecraft:stonebrick 0
fill ~61~42~24 ~62~42~27 minecraft:stonebrick 0
fill ~61~43~24 ~62~43~26 minecraft:stonebrick 0
fill ~61~44~24 ~62~44~25 minecraft:stonebrick 0
fill ~72~41~24 ~73~41~24 minecraft:cobblestone
setblock ~73~42~24 minecraft:stonebrick 0
fill ~74~41~24 ~79~41~24 minecraft:stonebrick 0
fill ~80~36~24 ~80~40~24 minecraft:stonebrick 0
fill ~80~41~24 ~82~41~24 minecraft:stone_stairs 3
fill ~81~37~24 ~94~40~24 minecraft:stonebrick 0
fill ~82~36~24 ~84~36~24 minecraft:stonebrick 0
fill ~83~31~24 ~83~35~24 minecraft:stonebrick 0
fill ~85~19~24 ~89~19~25 minecraft:stonebrick 0
fill ~85~20~24 ~89~20~24 minecraft:stone_stairs 2
setblock ~85~43~24 minecraft:torch 3
fill ~86~36~24 ~88~36~24 minecraft:stonebrick 0
fill ~86~41~24 ~88~41~24 minecraft:stone_stairs 3
fill ~87~31~24 ~87~35~24 minecraft:stonebrick 0
setblock ~89~43~24 minecraft:torch 3
fill ~90~36~24 ~92~36~24 minecraft:stonebrick 0
fill ~91~31~24 ~91~35~24 minecraft:stonebrick 0
fill ~92~41~24 ~94~41~24 minecraft:stone_stairs 3
setblock ~94~36~24 minecraft:stonebrick 0
fill ~95~41~24 ~100~41~24 minecraft:stonebrick 0
fill ~101~41~24 ~102~41~24 minecraft:cobblestone
setblock ~101~42~24 minecraft:stonebrick 0
fill ~112~42~24 ~113~42~27 minecraft:stonebrick 0
fill ~112~43~24 ~113~43~26 minecraft:stonebrick 0
fill ~112~44~24 ~113~44~25 minecraft:stonebrick 0
fill ~112~45~24 ~116~45~24 minecraft:stonebrick 0
fill ~115~42~24 ~116~44~25 minecraft:stonebrick 0
fill ~115~46~24 ~116~46~24 minecraft:stonebrick 0
fill ~115~49~24 ~116~50~24 minecraft:stonebrick 0
setblock ~116~48~24 minecraft:stonebrick 0
fill ~127~17~24 ~130~17~24 minecraft:stonebrick 0
fill ~128~14~24 ~130~15~24 minecraft:stonebrick 0
fill ~128~16~24 ~130~16~150 minecraft:cobblestone
fill ~128~28~24 ~130~29~24 minecraft:stonebrick 0
fill ~135~16~24 ~135~16~74 minecraft:cobblestone
fill ~135~30~24 ~135~30~53 minecraft:cobblestone
fill ~135~41~24 ~135~41~43 minecraft:cobblestone
fill ~135~49~24 ~135~49~36 minecraft:cobblestone
fill ~136~0~24 ~137~0~150 minecraft:cobblestone
fill ~136~49~24 ~136~50~24 minecraft:stonebrick 0
setblock ~137~50~24 minecraft:stonebrick 0
fill ~138~0~24 ~175~0~24 minecraft:grass
fill ~138~49~24 ~138~49~25 minecraft:stonebrick 0
fill ~138~57~24 ~138~57~27 minecraft:stonebrick 0
fill ~140~16~24 ~140~16~27 minecraft:stonebrick 0
setblock ~140~17~24 minecraft:stonebrick 0
fill ~140~30~24 ~140~30~27 minecraft:stonebrick 0
setblock ~140~31~24 minecraft:stonebrick 0
fill ~140~41~24 ~140~41~27 minecraft:stonebrick 0
setblock ~140~42~24 minecraft:stonebrick 0
fill ~140~58~24 ~140~58~30 minecraft:stonebrick 0
fill ~2~0~25 ~35~0~25 minecraft:grass
fill ~33~16~25 ~33~16~28 minecraft:stonebrick 0
setblock ~33~17~25 minecraft:stonebrick 0
fill ~33~30~25 ~33~30~28 minecraft:stonebrick 0
setblock ~33~31~25 minecraft:stonebrick 0
fill ~33~41~25 ~33~41~28 minecraft:stonebrick 0
setblock ~33~42~25 minecraft:stonebrick 0
fill ~33~58~25 ~33~58~31 minecraft:stonebrick 0
fill ~35~49~25 ~35~49~26 minecraft:stonebrick 0
fill ~35~57~25 ~35~57~27 minecraft:stonebrick 0
fill ~36~0~25 ~36~0~149 minecraft:cobblestone
setblock ~36~50~25 minecraft:stonebrick 0
fill ~37~49~25 ~38~49~37 minecraft:cobblestone
fill ~38~16~25 ~38~16~74 minecraft:cobblestone
fill ~38~30~25 ~38~30~55 minecraft:cobblestone
fill ~38~41~25 ~38~41~44 minecraft:cobblestone
setblock ~38~57~25 minecraft:stonebrick 0
fill ~43~14~25 ~45~15~25 minecraft:stonebrick 0
fill ~43~16~25 ~45~16~150 minecraft:cobblestone
fill ~43~28~25 ~45~29~25 minecraft:stonebrick 0
fill ~56~42~25 ~57~45~26 minecraft:stonebrick 0
fill ~56~46~25 ~57~46~25 minecraft:stonebrick 0
fill ~56~48~25 ~57~50~25 minecraft:stonebrick 0
setblock ~57~47~25 minecraft:stonebrick 0
fill ~60~42~25 ~60~42~28 minecraft:stonebrick 0
fill ~60~43~25 ~60~43~27 minecraft:stonebrick 0
fill ~60~44~25 ~60~44~26 minecraft:stonebrick 0
setblock ~60~45~25 minecraft:stonebrick 0
setblock ~69~42~25 minecraft:stonebrick 0
fill ~70~41~25 ~73~41~25 minecraft:stonebrick 0
fill ~74~36~25 ~76~40~25 minecraft:stonebrick 0
fill ~75~31~25 ~75~35~25 minecraft:stonebrick 0
fill ~77~37~25 ~79~40~25 minecraft:stonebrick 0
fill ~78~36~25 ~79~36~25 minecraft:stonebrick 0
fill ~79~31~25 ~79~35~25 minecraft:stonebrick 0
fill ~80~31~25 ~82~31~25 minecraft:fence 0
fill ~80~38~25 ~100~38~29 minecraft:stonebrick 0
fill ~80~39~25 ~100~39~25 minecraft:stonebrick 0
fill ~80~40~25 ~82~40~25 minecraft:stone_stairs 3
setblock ~82~32~25 minecraft:torch 5
fill ~85~20~25 ~89~20~25 minecraft:stonebrick 0
fill ~85~21~25 ~89~21~25 minecraft:stone_stairs 2
fill ~86~40~25 ~88~40~25 minecraft:stone_stairs 3
fill ~92~31~25 ~94~31~25 minecraft:fence 0
setblock ~92~32~25 minecraft:torch 5
fill ~92~40~25 ~94~40~25 minecraft:stone_stairs 3
fill ~95~31~25 ~95~37~25 minecraft:stonebrick 0
fill ~95~40~25 ~100~40~25 minecraft:stonebrick 0
fill ~96~36~25 ~96~37~25 minecraft:stonebrick 0
fill ~97~37~25 ~100~37~25 minecraft:stonebrick 0
fill ~98~36~25 ~100~36~25 minecraft:stonebrick 0
fill ~99~31~25 ~99~35~25 minecraft:stonebrick 0
fill ~101~41~25 ~104~41~25 minecraft:stonebrick 0
fill ~105~41~25 ~106~41~25 minecraft:cobblestone
setblock ~105~42~25 minecraft:stonebrick 0
fill ~114~42~25 ~114~42~28 minecraft:stonebrick 0
fill ~114~43~25 ~114~43~27 minecraft:stonebrick 0
fill ~114~44~25 ~114~44~26 minecraft:stonebrick 0
fill ~114~45~25 ~118~45~25 minecraft:stonebrick 0
fill ~117~42~25 ~118~44~26 minecraft:stonebrick 0
fill ~117~46~25 ~118~46~25 minecraft:stonebrick 0
fill ~117~47~25 ~117~50~25 minecraft:stonebrick 0
fill ~118~48~25 ~118~50~25 minecraft:stonebrick 0
fill ~128~15~25 ~130~15~25 minecraft:stonebrick 0
fill ~128~29~25 ~130~29~25 minecraft:stonebrick 0
fill ~136~16~25 ~136~16~74 minecraft:cobblestone
fill ~136~30~25 ~136~30~55 minecraft:cobblestone
fill ~136~41~25 ~136~41~44 minecraft:cobblestone
fill ~136~49~25 ~137~49~37 minecraft:cobblestone
setblock ~136~57~25 minecraft:stonebrick 0
fill ~138~0~25 ~138~0~149 minecraft:cobblestone
setblock ~138~50~25 minecraft:stonebrick 0
fill ~139~0~25 ~175~0~25 minecraft:grass
fill ~139~49~25 ~139~49~26 minecraft:stonebrick 0
fill ~139~57~25 ~139~57~27 minecraft:stonebrick 0
fill ~141~16~25 ~141~16~28 minecraft:stonebrick 0
setblock ~141~17~25 minecraft:stonebrick 0
fill ~141~30~25 ~141~30~28 minecraft:stonebrick 0
setblock ~141~31~25 minecraft:stonebrick 0
fill ~141~41~25 ~141~41~28 minecraft:stonebrick 0
setblock ~141~42~25 minecraft:stonebrick 0
fill ~141~58~25 ~141~58~31 minecraft:stonebrick 0
fill ~2~0~26 ~34~0~26 minecraft:grass
fill ~32~16~26 ~32~16~29 minecraft:stonebrick 0
setblock ~32~17~26 minecraft:stonebrick 0
fill ~32~30~26 ~32~30~29 minecraft:stonebrick 0
setblock ~32~31~26 minecraft:stonebrick 0
fill ~32~41~26 ~32~41~29 minecraft:stonebrick 0
setblock ~32~42~26 minecraft:stonebrick 0
fill ~32~58~26 ~32~58~31 minecraft:stonebrick 0
fill ~33~49~26 ~34~49~27 minecraft:stonebrick 0
fill ~33~57~26 ~34~57~28 minecraft:stonebrick 0
fill ~35~0~26 ~35~0~148 minecraft:cobblestone
setblock ~35~50~26 minecraft:stonebrick 0
setblock ~35~56~26 minecraft:stonebrick 0
fill ~36~49~26 ~36~49~39 minecraft:cobblestone
fill ~37~16~26 ~37~16~74 minecraft:cobblestone
fill ~37~30~26 ~37~30~56 minecraft:cobblestone
fill ~37~41~26 ~37~41~45 minecraft:cobblestone
fill ~43~15~26 ~45~15~26 minecraft:stonebrick 0
fill ~43~29~26 ~45~29~26 minecraft:stonebrick 0
fill ~54~42~26 ~55~45~27 minecraft:stonebrick 0
fill ~54~46~26 ~55~46~26 minecraft:stonebrick 0
fill ~54~48~26 ~54~50~26 minecraft:stonebrick 0
fill ~55~49~26 ~55~50~26 minecraft:stonebrick 0
fill ~58~44~26 ~59~44~26 minecraft:stonebrick 0
fill ~59~42~26 ~59~42~28 minecraft:stonebrick 0
fill ~59~43~26 ~59~43~27 minecraft:stonebrick 0
fill ~64~41~26 ~65~41~26 minecraft:cobblestone
fill ~66~41~26 ~69~41~26 minecraft:stonebrick 0
fill ~70~36~26 ~72~40~26 minecraft:stonebrick 0
fill ~71~31~26 ~71~35~26 minecraft:stonebrick 0
fill ~72~30~26 ~76~30~29 minecraft:cobblestone
fill ~73~37~26 ~73~40~26 minecraft:stonebrick 0
fill ~74~38~26 ~79~38~30 minecraft:stonebrick 0
fill ~74~39~26 ~79~39~26 minecraft:stonebrick 0
fill ~77~29~26 ~77~29~34 minecraft:stonebrick 0
fill ~77~30~26 ~77~30~28 minecraft:stone_stairs 1
fill ~78~28~26 ~78~28~35 minecraft:stonebrick 0
fill ~78~29~26 ~78~29~28 minecraft:stone_stairs 1
fill ~79~27~26 ~79~27~36 minecraft:stonebrick 0
fill ~79~28~26 ~79~28~28 minecraft:stone_stairs 1
fill ~80~26~26 ~80~26~36 minecraft:stonebrick 0
fill ~80~27~26 ~80~27~28 minecraft:stone_stairs 1
fill ~80~39~26 ~82~39~26 minecraft:stone_stairs 3
fill ~81~25~26 ~81~25~39 minecraft:stonebrick 0
fill ~81~26~26 ~81~26~28 minecraft:stone_stairs 1
fill ~82~24~26 ~82~24~40 minecraft:stonebrick 0
fill ~82~25~26 ~82~25~28 minecraft:stone_stairs 1
fill ~82~31~26 ~82~31~29 minecraft:fence 0
fill ~83~23~26 ~83~23~41 minecraft:stonebrick 0
fill ~83~24~26 ~83~24~28 minecraft:stone_stairs 1
fill ~84~22~26 ~84~22~42 minecraft:stonebrick 0
fill ~84~23~26 ~84~23~28 minecraft:stone_stairs 1
fill ~85~21~26 ~89~21~43 minecraft:stonebrick 0
fill ~85~22~26 ~85~22~28 minecraft:stone_stairs 1
fill ~86~39~26 ~88~39~26 minecraft:stone_stairs 3
setblock ~87~18~26 minecraft:torch 3
fill ~89~22~26 ~89~22~28 minecraft:stone_stairs 0
fill ~90~22~26 ~90~22~42 minecraft:stonebrick 0
fill ~90~23~26 ~90~23~28 minecraft:stone_stairs 0
fill ~91~23~26 ~91~23~41 minecraft:stonebrick 0
fill ~91~24~26 ~91~24~28 minecraft:stone_stairs 0
fill ~92~24~26 ~92~24~40 minecraft:stonebrick 0
fill ~92~25~26 ~92~25~28 minecraft:stone_stairs 0
fill ~92~30~26 ~92~30~28 minecraft:cobblestone
fill ~92~31~26 ~92~31~29 minecraft:fence 0
fill ~92~39~26 ~94~39~26 minecraft:stone_stairs 3
fill ~93~25~26 ~93~25~39 minecraft:stonebrick 0
fill ~93~26~26 ~93~26~28 minecraft:stone_stairs 0
fill ~94~26~26 ~94~26~36 minecraft:stonebrick 0
fill ~94~27~26 ~94~27~28 minecraft:stone_stairs 0
fill ~95~27~26 ~95~27~36 minecraft:stonebrick 0
fill ~95~28~26 ~95~28~28 minecraft:stone_stairs 0
fill ~95~39~26 ~104~39~26 minecraft:stonebrick 0
fill ~96~28~26 ~96~28~35 minecraft:stonebrick 0
fill ~96~29~26 ~96~29~28 minecraft:stone_stairs 0
fill ~97~29~26 ~97~29~34 minecraft:stonebrick 0
fill ~97~30~26 ~97~30~28 minecraft:stone_stairs 0
fill ~98~30~26 ~102~30~29 minecraft:cobblestone
fill ~101~37~26 ~104~38~26 minecraft:stonebrick 0
fill ~101~40~26 ~104~40~26 minecraft:stonebrick 0
fill ~102~36~26 ~104~36~26 minecraft:stonebrick 0
fill ~103~31~26 ~103~35~26 minecraft:stonebrick 0
fill ~105~41~26 ~108~41~26 minecraft:stonebrick 0
fill ~109~41~26 ~110~41~26 minecraft:cobblestone
fill ~115~42~26 ~115~42~28 minecraft:stonebrick 0
fill ~115~43~26 ~115~43~27 minecraft:stonebrick 0
fill ~115~44~26 ~116~44~26 minecraft:stonebrick 0
fill ~117~45~26 ~120~45~26 minecraft:stonebrick 0
fill ~119~42~26 ~120~44~27 minecraft:stonebrick 0
fill ~119~46~26 ~120~46~26 minecraft:stonebrick 0
fill ~119~49~26 ~120~50~26 minecraft:stonebrick 0
setblock ~120~48~26 minecraft:stonebrick 0
fill ~137~16~26 ~137~16~74 minecraft:cobblestone
fill ~137~30~26 ~137~30~56 minecraft:cobblestone
fill ~137~41~26 ~137~41~45 minecraft:cobblestone
fill ~138~49~26 ~138~49~39 minecraft:cobblestone
fill ~139~0~26 ~139~0~148 minecraft:cobblestone
setblock ~139~50~26 minecraft:stonebrick 0
setblock ~139~56~26 minecraft:stonebrick 0
fill ~140~0~26 ~175~0~26 minecraft:grass
fill ~140~49~26 ~141~49~27 minecraft:stonebrick 0
fill ~140~57~26 ~141~57~28 minecraft:stonebrick 0
fill ~142~16~26 ~142~16~29 minecraft:stonebrick 0
setblock ~142~17~26 minecraft:stonebrick 0
fill ~142~30~26 ~142~30~29 minecraft:stonebrick 0
setblock ~142~31~26 minecraft:stonebrick 0
fill ~142~41~26 ~142~41~29 minecraft:stonebrick 0
setblock ~142~42~26 minecraft:stonebrick 0
fill ~142~58~26 ~142~58~31 minecraft:stonebrick 0
fill ~2~0~27 ~33~0~27 minecraft:grass
fill ~31~16~27 ~31~16~30 minecraft:stonebrick 0
setblock ~31~17~27 minecraft:stonebrick 0
fill ~31~30~27 ~31~30~33 minecraft:stonebrick 0
setblock ~31~31~27 minecraft:stonebrick 0
fill ~31~41~27 ~31~41~33 minecraft:stonebrick 0
setblock ~31~42~27 minecraft:stonebrick 0
fill ~31~58~27 ~31~58~33 minecraft:stonebrick 0
fill ~31~59~27 ~31~62~27 minecraft:fence 0
setblock ~31~63~27 minecraft:torch 5
fill ~32~49~27 ~32~49~29 minecraft:stonebrick 0
fill ~32~57~27 ~32~57~30 minecraft:stonebrick 0
fill ~34~0~27 ~34~0~147 minecraft:cobblestone
fill ~34~50~27 ~34~56~27 minecraft:stonebrick 0
fill ~35~16~27 ~36~16~74 minecraft:cobblestone
fill ~35~30~27 ~36~30~58 minecraft:cobblestone
fill ~35~41~27 ~36~41~47 minecraft:cobblestone
fill ~35~49~27 ~35~49~40 minecraft:cobblestone
fill ~52~42~27 ~53~46~27 minecraft:stonebrick 0
fill ~52~48~27 ~53~50~27 minecraft:stonebrick 0
setblock ~53~47~27 minecraft:stonebrick 0
fill ~56~44~27 ~58~44~27 minecraft:stonebrick 0
fill ~57~42~27 ~58~42~29 minecraft:stonebrick 0
fill ~57~43~27 ~58~43~28 minecraft:stonebrick 0
setblock ~63~42~27 minecraft:stonebrick 0
fill ~64~41~27 ~66~41~27 minecraft:stonebrick 0
fill ~67~31~27 ~67~40~27 minecraft:stonebrick 0
fill ~68~36~27 ~68~40~27 minecraft:stonebrick 0
fill ~69~37~27 ~69~40~27 minecraft:stonebrick 0
fill ~70~38~27 ~73~38~31 minecraft:stonebrick 0
fill ~70~39~27 ~73~39~27 minecraft:stonebrick 0
fill ~101~38~27 ~107~38~31 minecraft:stonebrick 0
fill ~101~39~27 ~107~39~27 minecraft:stonebrick 0
fill ~105~37~27 ~107~37~27 minecraft:stonebrick 0
fill ~105~40~27 ~107~40~27 minecraft:stonebrick 0
fill ~106~36~27 ~107~36~27 minecraft:stonebrick 0
fill ~107~31~27 ~107~35~27 minecraft:stonebrick 0
fill ~108~41~27 ~110~41~27 minecraft:stonebrick 0
setblock ~111~42~27 minecraft:stonebrick 0
fill ~116~42~27 ~117~42~29 minecraft:stonebrick 0
fill ~116~43~27 ~117~43~28 minecraft:stonebrick 0
fill ~116~44~27 ~118~44~27 minecraft:stonebrick 0
fill ~119~45~27 ~122~45~27 minecraft:stonebrick 0
fill ~121~42~27 ~122~44~27 minecraft:stonebrick 0
fill ~121~46~27 ~122~46~27 minecraft:stonebrick 0
fill ~121~47~27 ~121~50~27 minecraft:stonebrick 0
fill ~122~48~27 ~122~50~27 minecraft:stonebrick 0
setblock ~123~49~27 minecraft:cobblestone
fill ~138~16~27 ~139~16~74 minecraft:cobblestone
fill ~138~30~27 ~139~30~58 minecraft:cobblestone
fill ~138~41~27 ~139~41~47 minecraft:cobblestone
fill ~139~49~27 ~139~49~40 minecraft:cobblestone
fill ~140~0~27 ~140~0~147 minecraft:cobblestone
fill ~140~50~27 ~140~56~27 minecraft:stonebrick 0
fill ~141~0~27 ~175~0~27 minecraft:grass
fill ~142~49~27 ~142~49~29 minecraft:stonebrick 0
fill ~142~57~27 ~142~57~30 minecraft:stonebrick 0
fill ~143~16~27 ~143~16~31 minecraft:stonebrick 0
setblock ~143~17~27 minecraft:stonebrick 0
fill ~143~30~27 ~143~30~30 minecraft:stonebrick 0
setblock ~143~31~27 minecraft:stonebrick 0
fill ~143~41~27 ~143~41~30 minecraft:stonebrick 0
setblock ~143~42~27 minecraft:stonebrick 0
fill ~143~58~27 ~143~58~33 minecraft:stonebrick 0
fill ~143~59~27 ~143~62~27 minecraft:fence 0
setblock ~143~63~27 minecraft:torch 5
fill ~2~0~28 ~32~0~28 minecraft:grass
fill ~29~15~28 ~31~15~30 minecraft:stonebrick 0
fill ~29~16~28 ~30~16~31 minecraft:stonebrick 0
fill ~29~17~28 ~30~17~30 minecraft:stonebrick 0
fill ~29~41~28 ~30~41~31 minecraft:stonebrick 0
fill ~29~42~28 ~30~42~28 minecraft:stonebrick 0
fill ~30~29~28 ~31~29~30 minecraft:stonebrick 0
fill ~30~30~28 ~30~30~33 minecraft:stonebrick 0
setblock ~30~31~28 minecraft:stonebrick 0
fill ~30~58~28 ~30~58~34 minecraft:stonebrick 0
fill ~31~49~28 ~31~49~30 minecraft:stonebrick 0
fill ~31~57~28 ~31~57~31 minecraft:stonebrick 0
fill ~33~0~28 ~33~0~146 minecraft:cobblestone
fill ~33~49~28 ~33~56~28 minecraft:stonebrick 0
fill ~34~16~28 ~34~16~140 minecraft:cobblestone
fill ~34~30~28 ~34~30~62 minecraft:cobblestone
fill ~34~41~28 ~34~41~49 minecraft:cobblestone
fill ~34~49~28 ~34~49~42 minecraft:cobblestone
setblock ~50~49~28 minecraft:cobblestone
fill ~51~42~28 ~51~44~30 minecraft:stonebrick 0
fill ~51~45~28 ~53~45~28 minecraft:stonebrick 0
setblock ~51~46~28 minecraft:stonebrick 0
fill ~51~49~28 ~51~50~28 minecraft:stonebrick 0
fill ~53~42~28 ~53~42~32 minecraft:stonebrick 0
fill ~53~43~28 ~53~43~30 minecraft:stonebrick 0
fill ~53~44~28 ~56~44~28 minecraft:stonebrick 0
fill ~55~42~28 ~56~42~30 minecraft:stonebrick 0
fill ~55~43~28 ~56~43~29 minecraft:stonebrick 0
fill ~61~41~28 ~63~41~28 minecraft:stonebrick 0
fill ~64~36~28 ~64~40~28 minecraft:stonebrick 0
fill ~65~37~28 ~66~40~28 minecraft:stonebrick 0
setblock ~66~36~28 minecraft:stonebrick 0
fill ~67~38~28 ~69~38~32 minecraft:stonebrick 0
fill ~67~39~28 ~69~39~28 minecraft:stonebrick 0
setblock ~81~29~28 minecraft:torch 4
setblock ~83~27~28 minecraft:torch 4
setblock ~84~18~28 minecraft:torch 4
setblock ~85~25~28 minecraft:torch 4
setblock ~87~23~28 minecraft:torch 4
setblock ~89~25~28 minecraft:torch 4
setblock ~90~18~28 minecraft:torch 4
setblock ~91~27~28 minecraft:torch 4
setblock ~93~29~28 minecraft:torch 4
fill ~105~39~28 ~110~39~28 minecraft:stonebrick 0
fill ~108~36~28 ~108~38~28 minecraft:stonebrick 0
fill ~108~40~28 ~110~40~28 minecraft:stonebrick 0
fill ~109~37~28 ~110~38~28 minecraft:stonebrick 0
setblock ~110~36~28 minecraft:stonebrick 0
fill ~111~41~28 ~113~41~28 minecraft:stonebrick 0
fill ~118~42~28 ~119~42~30 minecraft:stonebrick 0
fill ~118~43~28 ~119~43~29 minecraft:stonebrick 0
fill ~118~44~28 ~121~44~28 minecraft:stonebrick 0
fill ~121~42~28 ~121~42~32 minecraft:stonebrick 0
fill ~121~43~28 ~121~43~30 minecraft:stonebrick 0
fill ~121~45~28 ~123~45~28 minecraft:stonebrick 0
fill ~123~42~28 ~123~44~30 minecraft:stonebrick 0
setblock ~123~46~28 minecraft:stonebrick 0
fill ~123~49~28 ~123~50~28 minecraft:stonebrick 0
fill ~140~16~28 ~140~16~140 minecraft:cobblestone
fill ~140~30~28 ~140~30~62 minecraft:cobblestone
fill ~140~41~28 ~140~41~49 minecraft:cobblestone
fill ~140~49~28 ~140~49~42 minecraft:cobblestone
fill ~141~0~28 ~141~0~146 minecraft:cobblestone
fill ~141~49~28 ~141~56~28 minecraft:stonebrick 0
fill ~142~0~28 ~175~0~28 minecraft:grass
fill ~143~49~28 ~143~49~30 minecraft:stonebrick 0
fill ~143~57~28 ~143~57~31 minecraft:stonebrick 0
fill ~144~16~28 ~144~16~31 minecraft:stonebrick 0
setblock ~144~17~28 minecraft:stonebrick 0
fill ~144~30~28 ~144~30~34 minecraft:stonebrick 0
setblock ~144~31~28 minecraft:stonebrick 0
fill ~144~41~28 ~144~41~34 minecraft:stonebrick 0
setblock ~144~42~28 minecraft:stonebrick 0
fill ~144~58~28 ~144~58~34 minecraft:stonebrick 0
fill ~2~0~29 ~27~0~29 minecraft:grass
fill ~28~0~29 ~31~0~29 minecraft:dirt 0
fill ~28~1~29 ~32~1~30 minecraft:stonebrick 0
fill ~28~15~29 ~28~15~35 minecraft:stonebrick 0
fill ~28~16~29 ~28~17~33 minecraft:stonebrick 0
fill ~28~41~29 ~28~42~33 minecraft:stonebrick 0
fill ~29~14~29 ~31~14~30 minecraft:stonebrick 0
fill ~29~28~29 ~31~28~30 minecraft:stonebrick 0
fill ~29~29~29 ~29~31~30 minecraft:stonebrick 0
fill ~29~58~29 ~29~58~35 minecraft:stonebrick 0
fill ~30~49~29 ~30~49~31 minecraft:stonebrick 0
fill ~30~57~29 ~30~57~32 minecraft:stonebrick 0
fill ~31~17~29 ~32~17~30 minecraft:stonebrick 0
fill ~32~0~29 ~32~0~145 minecraft:cobblestone
fill ~32~15~29 ~32~15~35 minecraft:stonebrick 0
fill ~32~29~29 ~32~29~35 minecraft:stonebrick 0
setblock ~32~50~29 minecraft:stonebrick 0
setblock ~32~56~29 minecraft:stonebrick 0
fill ~33~16~29 ~33~16~139 minecraft:cobblestone
fill ~33~30~29 ~33~30~64 minecraft:cobblestone
fill ~33~41~29 ~33~41~51 minecraft:cobblestone
fill ~33~49~29 ~33~49~43 minecraft:cobblestone
setblock ~33~57~29 minecraft:stonebrick 0
setblock ~35~58~29 minecraft:stonebrick 0
setblock ~48~49~29 minecraft:cobblestone
fill ~49~42~29 ~50~46~29 minecraft:stonebrick 0
fill ~49~47~29 ~49~50~29 minecraft:stonebrick 0
fill ~50~48~29 ~50~50~29 minecraft:stonebrick 0
fill ~51~45~29 ~52~45~29 minecraft:stonebrick 0
fill ~52~42~29 ~52~42~32 minecraft:stonebrick 0
fill ~52~43~29 ~52~43~31 minecraft:stonebrick 0
fill ~52~44~29 ~54~44~29 minecraft:stonebrick 0
fill ~54~42~29 ~54~42~31 minecraft:stonebrick 0
fill ~54~43~29 ~54~43~30 minecraft:stonebrick 0
setblock ~58~41~29 minecraft:cobblestone
fill ~59~41~29 ~61~41~29 minecraft:stonebrick 0
fill ~62~36~29 ~63~40~29 minecraft:stonebrick 0
fill ~63~31~29 ~63~35~29 minecraft:stonebrick 0
fill ~64~38~29 ~66~38~33 minecraft:stonebrick 0
fill ~64~39~29 ~66~39~29 minecraft:stonebrick 0
fill ~77~30~29 ~79~30~29 minecraft:cobblestone
fill ~78~29~29 ~96~29~33 minecraft:stonebrick 0
fill ~79~28~29 ~95~28~34 minecraft:stonebrick 0
fill ~79~31~29 ~81~31~29 minecraft:fence 0
fill ~80~17~29 ~85~20~29 minecraft:stonebrick 0
fill ~80~21~29 ~84~21~38 minecraft:stonebrick 0
fill ~80~22~29 ~83~22~38 minecraft:stonebrick 0
fill ~80~23~29 ~82~23~38 minecraft:stonebrick 0
fill ~80~24~29 ~81~24~38 minecraft:stonebrick 0
fill ~80~25~29 ~80~25~40 minecraft:stonebrick 0
fill ~80~27~29 ~94~27~35 minecraft:stonebrick 0
fill ~80~30~29 ~94~30~32 minecraft:stonebrick 0
fill ~80~39~29 ~94~39~29 minecraft:stonebrick 0
fill ~81~26~29 ~93~26~36 minecraft:stonebrick 0
setblock ~82~4~29 minecraft:torch 4
fill ~82~25~29 ~92~25~39 minecraft:stonebrick 0
setblock ~82~32~29 minecraft:torch 5
fill ~83~24~29 ~91~24~40 minecraft:stonebrick 0
fill ~84~1~29 ~90~1~29 minecraft:stone_stairs 2
fill ~84~23~29 ~90~23~41 minecraft:stonebrick 0
fill ~85~22~29 ~89~22~42 minecraft:stonebrick 0
fill ~86~20~29 ~94~20~46 minecraft:stonebrick 0
fill ~89~17~29 ~94~19~29 minecraft:stonebrick 0
fill ~90~21~29 ~94~21~38 minecraft:stonebrick 0
fill ~91~22~29 ~94~22~38 minecraft:stonebrick 0
setblock ~92~4~29 minecraft:torch 4
fill ~92~23~29 ~94~23~38 minecraft:stonebrick 0
setblock ~92~32~29 minecraft:torch 5
fill ~93~24~29 ~94~24~38 minecraft:stonebrick 0
fill ~93~31~29 ~95~31~29 minecraft:fence 0
fill ~94~25~29 ~94~25~40 minecraft:stonebrick 0
fill ~95~30~29 ~97~30~29 minecraft:cobblestone
fill ~108~38~29 ~112~38~33 minecraft:stonebrick 0
fill ~108~39~29 ~112~39~29 minecraft:stonebrick 0
fill ~111~31~29 ~111~37~29 minecraft:stonebrick 0
fill ~111~40~29 ~112~40~29 minecraft:stonebrick 0
fill ~112~36~29 ~112~37~29 minecraft:stonebrick 0
fill ~113~41~29 ~115~41~29 minecraft:stonebrick 0
fill ~120~42~29 ~120~42~31 minecraft:stonebrick 0
fill ~120~43~29 ~120~43~30 minecraft:stonebrick 0
fill ~120~44~29 ~122~44~29 minecraft:stonebrick 0
fill ~122~42~29 ~122~42~32 minecraft:stonebrick 0
fill ~122~43~29 ~122~43~31 minecraft:stonebrick 0
fill ~122~45~29 ~125~45~29 minecraft:stonebrick 0
fill ~124~42~29 ~125~44~29 minecraft:stonebrick 0
fill ~124~46~29 ~125~46~29 minecraft:stonebrick 0
fill ~124~48~29 ~125~50~29 minecraft:stonebrick 0
setblock ~125~47~29 minecraft:stonebrick 0
setblock ~126~49~29 minecraft:cobblestone
setblock ~139~58~29 minecraft:stonebrick 0
fill ~141~16~29 ~141~16~31 minecraft:cobblestone
fill ~141~30~29 ~141~30~64 minecraft:cobblestone
fill ~141~41~29 ~141~41~51 minecraft:cobblestone
fill ~141~49~29 ~141~49~43 minecraft:cobblestone
setblock ~141~57~29 minecraft:stonebrick 0
fill ~142~0~29 ~142~0~145 minecraft:cobblestone
fill ~142~15~29 ~144~15~31 minecraft:stonebrick 0
fill ~142~29~29 ~144~29~31 minecraft:stonebrick 0
setblock ~142~50~29 minecraft:stonebrick 0
setblock ~142~56~29 minecraft:stonebrick 0
fill ~143~0~29 ~175~0~29 minecraft:grass
fill ~144~49~29 ~144~49~31 minecraft:stonebrick 0
fill ~144~57~29 ~144~57~32 minecraft:stonebrick 0
fill ~145~16~29 ~145~17~34 minecraft:stonebrick 0
fill ~145~30~29 ~145~30~32 minecraft:stonebrick 0
setblock ~145~31~29 minecraft:stonebrick 0
fill ~145~41~29 ~146~41~32 minecraft:stonebrick 0
fill ~145~42~29 ~146~42~29 minecraft:stonebrick 0
fill ~145~58~29 ~145~58~35 minecraft:stonebrick 0
fill ~2~0~30 ~26~0~34 minecraft:grass
fill ~27~0~30 ~30~0~30 minecraft:dirt 0
fill ~27~1~30 ~27~1~34 minecraft:stonebrick 0
fill ~27~15~30 ~27~17~34 minecraft:stonebrick 0
fill ~27~41~30 ~27~41~34 minecraft:stonebrick 0
setblock ~27~42~30 minecraft:stonebrick 0
fill ~28~14~30 ~28~14~34 minecraft:stonebrick 0
fill ~28~28~30 ~28~29~34 minecraft:stonebrick 0
fill ~28~30~30 ~28~31~33 minecraft:stonebrick 0
fill ~28~40~30 ~32~40~34 minecraft:stonebrick 0
fill ~28~48~30 ~32~48~31 minecraft:stonebrick 0
fill ~28~58~30 ~28~58~36 minecraft:stonebrick 0
fill ~29~2~30 ~31~13~30 minecraft:stonebrick 0
fill ~29~18~30 ~31~27~30 minecraft:stonebrick 0
fill ~29~42~30 ~32~42~31 minecraft:stonebrick 0
fill ~29~49~30 ~29~49~32 minecraft:stonebrick 0
fill ~29~57~30 ~29~57~33 minecraft:stonebrick 0
fill ~30~31~30 ~32~31~34 minecraft:stonebrick 0
fill ~31~0~30 ~31~0~144 minecraft:cobblestone
setblock ~31~50~30 minecraft:stonebrick 0
fill ~32~14~30 ~32~14~34 minecraft:stonebrick 0
setblock ~32~16~30 minecraft:cobblestone
fill ~32~28~30 ~32~28~34 minecraft:stonebrick 0
fill ~32~30~30 ~32~30~67 minecraft:cobblestone
fill ~32~41~30 ~32~41~53 minecraft:cobblestone
fill ~32~49~30 ~32~49~44 minecraft:cobblestone
fill ~33~1~30 ~33~1~34 minecraft:stonebrick 0
fill ~33~15~30 ~33~15~34 minecraft:stonebrick 0
fill ~33~17~30 ~33~17~34 minecraft:stonebrick 0
fill ~33~29~30 ~33~29~34 minecraft:stonebrick 0
fill ~48~42~30 ~48~44~32 minecraft:stonebrick 0
fill ~48~45~30 ~50~45~30 minecraft:stonebrick 0
setblock ~48~46~30 minecraft:stonebrick 0
fill ~48~48~30 ~48~50~30 minecraft:stonebrick 0
fill ~50~42~30 ~50~42~33 minecraft:stonebrick 0
fill ~50~43~30 ~50~43~32 minecraft:stonebrick 0
fill ~50~44~30 ~50~44~31 minecraft:stonebrick 0
setblock ~52~44~30 minecraft:stonebrick 0
fill ~55~41~30 ~56~41~30 minecraft:cobblestone
fill ~57~41~30 ~59~41~30 minecraft:stonebrick 0
fill ~60~36~30 ~60~40~30 minecraft:stonebrick 0
fill ~61~37~30 ~61~40~30 minecraft:stonebrick 0
fill ~62~38~30 ~63~38~34 minecraft:stonebrick 0
fill ~62~39~30 ~63~39~30 minecraft:stonebrick 0
fill ~72~30~30 ~73~30~30 minecraft:cobblestone
fill ~74~17~30 ~79~26~30 minecraft:stonebrick 0
fill ~74~27~30 ~78~27~31 minecraft:stonebrick 0
fill ~74~28~30 ~77~28~31 minecraft:stonebrick 0
fill ~74~29~30 ~76~30~31 minecraft:stonebrick 0
fill ~74~31~30 ~79~31~30 minecraft:stonebrick 0
fill ~74~39~30 ~79~39~30 minecraft:stonebrick 0
fill ~77~30~30 ~79~30~33 minecraft:stonebrick 0
fill ~80~20~30 ~85~20~46 minecraft:stonebrick 0
setblock ~81~4~30 minecraft:torch 2
fill ~82~1~30 ~82~3~30 minecraft:fence 0
