fill ~1 ~0 ~22 ~13 ~0 ~22 sandstone 0  
fill ~1 ~0 ~23 ~13 ~0 ~23 sandstone 0  
fill ~1 ~0 ~24 ~13 ~0 ~24 sandstone 0  
fill ~1 ~0 ~25 ~12 ~0 ~25 sandstone 0  
fill ~1 ~0 ~26 ~12 ~0 ~26 sandstone 0  
fill ~1 ~0 ~27 ~12 ~0 ~27 sandstone 0  
fill ~1 ~0 ~28 ~12 ~0 ~28 sandstone 0  
fill ~1 ~0 ~29 ~1 ~0 ~34 sandstone 0  
fill ~1 ~0 ~35 ~1 ~1 ~35 sand 0  
fill ~1 ~0 ~36 ~1 ~1 ~36 sand 0 
setblock ~1 ~0 ~38 sand 0  
fill ~2 ~0 ~34 ~2 ~1 ~34 sandstone 0  
fill ~2 ~0 ~35 ~2 ~1 ~35 sandstone 0  
fill ~2 ~0 ~36 ~2 ~1 ~36 sandstone 0  
fill ~2 ~0 ~37 ~2 ~1 ~37 sandstone 0  
fill ~2 ~0 ~38 ~3 ~0 ~38 sandstone 0  
fill ~3 ~0 ~21 ~5 ~0 ~21 stone_slab 1  
fill ~3 ~0 ~39 ~3 ~2 ~39 sandstone 0  
fill ~3 ~0 ~40 ~4 ~0 ~40 sandstone 0  
fill ~4 ~0 ~41 ~4 ~2 ~41 sandstone 0  
fill ~4 ~0 ~42 ~5 ~0 ~42 sandstone 0  
fill ~5 ~0 ~29 ~12 ~0 ~29 sandstone 0  
fill ~5 ~0 ~43 ~6 ~0 ~43 sandstone 0  
fill ~6 ~0 ~19 ~7 ~0 ~19 sandstone 0  
fill ~6 ~0 ~30 ~11 ~0 ~30 sandstone 0  
fill ~6 ~0 ~44 ~6 ~2 ~44 sandstone 0  
fill ~6 ~0 ~45 ~7 ~0 ~45 sandstone 0  
fill ~7 ~0 ~17 ~7 ~2 ~17 sandstone 0  
fill ~7 ~0 ~18 ~7 ~0 ~17 sandstone 0  
fill ~7 ~0 ~46 ~8 ~0 ~46 sandstone 0  
fill ~8 ~0 ~31 ~8 ~1 ~31 sandstone 0  
fill ~8 ~0 ~32 ~8 ~1 ~32 sandstone 0  
fill ~8 ~0 ~33 ~8 ~2 ~33 sandstone 0  
fill ~8 ~0 ~34 ~9 ~0 ~34 sandstone 0  
fill ~8 ~0 ~47 ~9 ~0 ~47 sandstone 0  
fill ~9 ~0 ~13 ~10 ~0 ~13 sandstone 0 
setblock ~9 ~0 ~21 sandstone 0  
fill ~9 ~0 ~35 ~9 ~2 ~35 sandstone 0  
fill ~9 ~0 ~36 ~10 ~0 ~36 sandstone 0  
fill ~9 ~0 ~48 ~9 ~1 ~48 sandstone 0  
fill ~10 ~0 ~12 ~11 ~0 ~12 sandstone 0  
fill ~10 ~0 ~37 ~10 ~2 ~37 sandstone 0  
fill ~10 ~0 ~38 ~11 ~0 ~38 sandstone 0  
fill ~10 ~0 ~49 ~10 ~1 ~49 sandstone 0  
fill ~11 ~0 ~11 ~11 ~2 ~11 sandstone 0  
fill ~11 ~0 ~39 ~11 ~2 ~39 sandstone 0  
fill ~11 ~0 ~40 ~12 ~0 ~40 sandstone 0  
fill ~11 ~0 ~50 ~12 ~0 ~50 sandstone 0  
fill ~12 ~0 ~51 ~12 ~2 ~51 planks 2  
fill ~13 ~0 ~20 ~14 ~0 ~20 sandstone 0  
fill ~13 ~0 ~21 ~14 ~0 ~21 sandstone 0  
fill ~13 ~0 ~43 ~13 ~2 ~43 sandstone 0 
setblock ~14 ~0 ~7 sandstone 0  
fill ~14 ~0 ~18 ~15 ~0 ~18 sandstone 0  
fill ~14 ~0 ~19 ~14 ~16 ~19 sandstone 0  
fill ~14 ~0 ~44 ~15 ~0 ~44 sandstone 0 
setblock ~15 ~0 ~7 planks 2  
fill ~15 ~0 ~17 ~16 ~0 ~17 sandstone 0  
fill ~16 ~0 ~6 ~16 ~1 ~6 sandstone 0  
fill ~16 ~0 ~7 ~16 ~8 ~7 sandstone 0  
fill ~16 ~0 ~15 ~17 ~0 ~15 sandstone 0  
fill ~16 ~0 ~16 ~16 ~21 ~16 sandstone 0  
fill ~16 ~0 ~45 ~16 ~3 ~45 sandstone 0  
fill ~16 ~0 ~53 ~16 ~1 ~53 sandstone 0  
fill ~17 ~0 ~14 ~18 ~0 ~14 sandstone 0  
fill ~17 ~0 ~46 ~17 ~3 ~46 sandstone 0  
fill ~17 ~0 ~54 ~18 ~0 ~54 sandstone 0  
fill ~18 ~0 ~13 ~19 ~0 ~13 sandstone 0  
fill ~18 ~0 ~47 ~19 ~0 ~47 sandstone 0  
fill ~19 ~0 ~12 ~21 ~0 ~12 sandstone 0  
fill ~20 ~0 ~4 ~21 ~0 ~4 sandstone 0  
fill ~20 ~0 ~48 ~22 ~0 ~48 sandstone 0  
fill ~21 ~0 ~3 ~22 ~0 ~3 sandstone 0  
fill ~21 ~0 ~11 ~22 ~0 ~11 sandstone 0  
fill ~22 ~0 ~10 ~24 ~0 ~10 sandstone 0  
fill ~22 ~0 ~56 ~24 ~0 ~56 sandstone 0  
fill ~23 ~0 ~49 ~25 ~0 ~49 sandstone 0  
fill ~24 ~0 ~9 ~28 ~0 ~9 sandstone 0  
fill ~26 ~0 ~2 ~28 ~0 ~2 sandstone 0  
fill ~26 ~0 ~50 ~34 ~0 ~50 sandstone 0  
fill ~28 ~0 ~1 ~29 ~0 ~1 sandstone 0  
fill ~28 ~0 ~8 ~35 ~0 ~8 sandstone 0  
fill ~28 ~0 ~57 ~28 ~2 ~57 planks 2  
fill ~29 ~0 ~57 ~30 ~0 ~57 sandstone 0  
fill ~33 ~0 ~1 ~33 ~5 ~1 sandstone 0 
setblock ~34 ~0 ~1 planks 2  
fill ~34 ~0 ~49 ~37 ~0 ~49 sandstone 0  
fill ~34 ~0 ~56 ~36 ~0 ~56 sandstone 0  
fill ~34 ~0 ~57 ~34 ~1 ~57 sandstone 0  
fill ~35 ~0 ~1 ~35 ~1 ~1 sandstone 0  
fill ~35 ~0 ~2 ~35 ~7 ~2 sandstone 0  
fill ~35 ~0 ~9 ~38 ~0 ~9 sandstone 0  
fill ~37 ~0 ~48 ~40 ~0 ~48 sandstone 0  
fill ~38 ~0 ~10 ~41 ~0 ~10 sandstone 0  
fill ~39 ~0 ~2 ~39 ~2 ~2 sandstone 0 
setblock ~40 ~0 ~2 sandstone 2 
setblock ~40 ~0 ~3 sandstone 0  
fill ~40 ~0 ~47 ~41 ~0 ~47 sandstone 0  
fill ~40 ~0 ~55 ~41 ~0 ~55 sandstone 0 
setblock ~41 ~0 ~3 planks 2  
fill ~41 ~0 ~11 ~42 ~0 ~11 sandstone 0  
fill ~41 ~0 ~46 ~43 ~0 ~46 sandstone 0  
fill ~41 ~0 ~54 ~41 ~1 ~54 sandstone 0  
fill ~42 ~0 ~12 ~44 ~0 ~12 sandstone 0  
fill ~42 ~0 ~54 ~42 ~1 ~54 planks 2  
fill ~43 ~0 ~45 ~43 ~8 ~45 sandstone 0  
fill ~44 ~0 ~13 ~45 ~0 ~13 sandstone 0 
setblock ~44 ~0 ~44 sandstone 0  
fill ~44 ~0 ~45 ~44 ~2 ~45 planks 2  
fill ~45 ~0 ~5 ~46 ~0 ~5 sandstone 0  
fill ~45 ~0 ~14 ~46 ~0 ~14 sandstone 0  
fill ~45 ~0 ~43 ~46 ~0 ~43 sandstone 0  
fill ~45 ~0 ~44 ~45 ~3 ~44 planks 2  
fill ~46 ~0 ~6 ~47 ~0 ~6 sandstone 0  
fill ~46 ~0 ~15 ~47 ~0 ~15 sandstone 0  
fill ~46 ~0 ~42 ~47 ~0 ~42 sandstone 0  
fill ~46 ~0 ~47 ~48 ~0 ~47 stone_slab 1  
fill ~46 ~0 ~48 ~47 ~0 ~48 stone_slab 1  
fill ~46 ~0 ~52 ~47 ~0 ~52 sandstone 0  
fill ~47 ~0 ~7 ~47 ~12 ~7 sandstone 0  
fill ~47 ~0 ~16 ~48 ~0 ~16 sandstone 0  
fill ~47 ~0 ~41 ~48 ~0 ~41 sandstone 0  
fill ~47 ~0 ~46 ~48 ~0 ~46 stone_slab 1 
setblock ~47 ~0 ~49 stone_slab 1  
fill ~47 ~0 ~51 ~48 ~0 ~51 sandstone 0  
fill ~48 ~0 ~17 ~48 ~14 ~17 sandstone 0  
fill ~48 ~0 ~18 ~49 ~0 ~18 sandstone 0  
fill ~48 ~0 ~39 ~49 ~0 ~39 sandstone 0  
fill ~48 ~0 ~40 ~48 ~10 ~40 sandstone 0  
fill ~48 ~0 ~50 ~48 ~3 ~50 sandstone 0  
fill ~49 ~0 ~19 ~49 ~14 ~19 sandstone 0  
fill ~49 ~0 ~20 ~50 ~0 ~20 sandstone 0  
fill ~49 ~0 ~38 ~50 ~0 ~38 sandstone 0  
fill ~50 ~0 ~21 ~50 ~4 ~21 sandstone 0  
fill ~50 ~0 ~22 ~51 ~0 ~22 sandstone 0  
fill ~50 ~0 ~35 ~51 ~0 ~35 sandstone 0  
fill ~50 ~0 ~36 ~50 ~1 ~36 sandstone 0  
fill ~50 ~0 ~37 ~50 ~2 ~37 sandstone 0  
fill ~51 ~0 ~9 ~51 ~10 ~9 sandstone 0  
fill ~51 ~0 ~10 ~52 ~0 ~10 sandstone 0  
fill ~51 ~0 ~23 ~51 ~13 ~23 sandstone 0  
fill ~51 ~0 ~24 ~51 ~13 ~24 sandstone 0  
fill ~51 ~0 ~25 ~51 ~13 ~25 sandstone 0  
fill ~51 ~0 ~26 ~51 ~13 ~26 sandstone 0  
fill ~51 ~0 ~27 ~52 ~0 ~27 sandstone 0  
fill ~51 ~0 ~29 ~52 ~0 ~29 sandstone 0  
fill ~51 ~0 ~30 ~51 ~12 ~30 sandstone 0  
fill ~51 ~0 ~31 ~51 ~12 ~31 sandstone 0  
fill ~51 ~0 ~32 ~51 ~12 ~32 sandstone 0  
fill ~51 ~0 ~33 ~51 ~11 ~33 sandstone 0  
fill ~51 ~0 ~34 ~51 ~11 ~34 sandstone 0  
fill ~51 ~0 ~47 ~51 ~5 ~47 sandstone 0  
fill ~52 ~0 ~11 ~53 ~0 ~11 sandstone 0  
fill ~52 ~0 ~28 ~52 ~12 ~28 sandstone 0 
setblock ~52 ~0 ~46 sandstone 0 
setblock ~52 ~0 ~47 sandstone 2  
fill ~53 ~0 ~45 ~53 ~5 ~45 sandstone 0 
setblock ~53 ~0 ~46 planks 2 
setblock ~54 ~0 ~45 planks 2  
fill ~55 ~0 ~15 ~55 ~1 ~15 planks 2  
fill ~55 ~0 ~16 ~56 ~0 ~16 sandstone 0  
fill ~55 ~0 ~41 ~56 ~0 ~41 sandstone 0  
fill ~56 ~0 ~17 ~56 ~1 ~17 sandstone 0  
fill ~56 ~0 ~39 ~56 ~5 ~39 sandstone 0  
fill ~56 ~0 ~40 ~56 ~0 ~39 sandstone 0  
fill ~57 ~0 ~21 ~58 ~0 ~21 sandstone 0 
setblock ~57 ~0 ~39 sandstone 2  
fill ~58 ~0 ~22 ~58 ~0 ~23 sandstone 0  
fill ~58 ~0 ~27 ~59 ~0 ~27 sandstone 0  
fill ~58 ~0 ~28 ~59 ~0 ~28 sandstone 0  
fill ~58 ~0 ~29 ~59 ~0 ~29 sandstone 0  
fill ~58 ~0 ~33 ~58 ~1 ~33 sandstone 0  
fill ~58 ~0 ~34 ~58 ~1 ~34 sandstone 0  
fill ~58 ~0 ~35 ~58 ~1 ~35 sandstone 0  
fill ~1 ~1 ~22 ~1 ~1 ~27 stone_slab 15  
fill ~1 ~1 ~28 ~1 ~1 ~29 double_stone_slab 1  
fill ~1 ~1 ~30 ~13 ~1 ~30 sandstone 0  
fill ~1 ~1 ~31 ~13 ~1 ~31 sandstone 0  
fill ~1 ~1 ~32 ~13 ~1 ~32 sandstone 0  
fill ~1 ~1 ~33 ~13 ~1 ~33 sandstone 0  
fill ~1 ~1 ~34 ~1 ~1 ~30 sandstone 0  
fill ~2 ~1 ~22 ~2 ~1 ~27 stone_slab 1  
fill ~2 ~1 ~28 ~7 ~1 ~28 sandstone 0  
fill ~2 ~1 ~29 ~8 ~1 ~29 sandstone 0  
fill ~2 ~1 ~38 ~3 ~1 ~38 sandstone 0  
fill ~3 ~1 ~23 ~5 ~1 ~23 stone_slab 1  
fill ~3 ~1 ~24 ~4 ~1 ~24 stone_slab 1  
fill ~3 ~1 ~25 ~4 ~1 ~25 stone_slab 1  
fill ~3 ~1 ~26 ~6 ~1 ~26 stone_slab 1  
fill ~3 ~1 ~27 ~3 ~1 ~23 stone_slab 1  
fill ~3 ~1 ~34 ~14 ~1 ~34 sandstone 0  
fill ~3 ~1 ~35 ~3 ~2 ~35 sandstone 0  
fill ~3 ~1 ~40 ~4 ~1 ~40 sandstone 0  
fill ~4 ~1 ~27 ~7 ~1 ~27 sandstone 0  
fill ~4 ~1 ~42 ~5 ~1 ~42 sandstone 0  
fill ~5 ~1 ~24 ~7 ~1 ~24 sandstone 0  
fill ~5 ~1 ~25 ~7 ~1 ~25 sandstone 0  
fill ~5 ~1 ~43 ~6 ~1 ~43 sandstone 0  
fill ~6 ~1 ~19 ~7 ~1 ~19 sandstone 0  
fill ~6 ~1 ~23 ~13 ~1 ~23 sandstone 0  
fill ~6 ~1 ~45 ~6 ~2 ~45 planks 2 
setblock ~7 ~1 ~18 planks 2 
setblock ~7 ~1 ~26 sandstone 0  
fill ~7 ~1 ~35 ~13 ~1 ~35 sandstone 0  
fill ~7 ~1 ~36 ~10 ~1 ~36 sandstone 0  
fill ~7 ~1 ~45 ~7 ~3 ~45 sandstone 0  
fill ~7 ~1 ~46 ~8 ~1 ~46 sandstone 0  
fill ~8 ~1 ~37 ~8 ~12 ~37 sandstone 0  
fill ~8 ~1 ~47 ~9 ~1 ~47 sandstone 0 
setblock ~9 ~1 ~13 sandstone 2  
fill ~10 ~1 ~12 ~10 ~3 ~12 sandstone 2  
fill ~10 ~1 ~13 ~10 ~2 ~13 sandstone 0  
fill ~10 ~1 ~38 ~11 ~1 ~38 sandstone 0  
fill ~10 ~1 ~48 ~10 ~4 ~48 sandstone 0  
fill ~11 ~1 ~12 ~11 ~2 ~12 sandstone 0  
fill ~11 ~1 ~40 ~12 ~1 ~40 sandstone 0  
fill ~11 ~1 ~49 ~11 ~4 ~49 sandstone 0  
fill ~11 ~1 ~50 ~12 ~1 ~50 sandstone 0  
fill ~12 ~1 ~24 ~13 ~1 ~24 sandstone 0  
fill ~12 ~1 ~25 ~12 ~23 ~25 sandstone 0  
fill ~12 ~1 ~26 ~12 ~17 ~26 sandstone 0  
fill ~12 ~1 ~27 ~12 ~16 ~27 sandstone 0  
fill ~12 ~1 ~28 ~12 ~17 ~28 sandstone 0  
fill ~12 ~1 ~29 ~12 ~24 ~29 sandstone 0  
fill ~12 ~1 ~41 ~13 ~1 ~41 sandstone 0  
fill ~13 ~1 ~20 ~14 ~1 ~20 sandstone 0  
fill ~13 ~1 ~21 ~14 ~1 ~21 sandstone 0  
fill ~13 ~1 ~22 ~13 ~22 ~22 sandstone 0  
fill ~13 ~1 ~42 ~14 ~1 ~42 sandstone 0 
setblock ~13 ~1 ~52 sandstone_stairs 5  
fill ~14 ~1 ~7 ~14 ~2 ~7 planks 2  
fill ~14 ~1 ~18 ~15 ~1 ~18 sandstone 0  
fill ~14 ~1 ~43 ~14 ~3 ~43 sandstone 0  
fill ~14 ~1 ~44 ~16 ~1 ~44 sandstone 0 
setblock ~14 ~1 ~52 stone_slab 9  
fill ~15 ~1 ~7 ~15 ~5 ~7 sandstone 0  
fill ~15 ~1 ~17 ~16 ~1 ~17 sandstone 0 
setblock ~15 ~1 ~53 sandstone_stairs 4  
fill ~16 ~1 ~15 ~17 ~1 ~15 sandstone 0  
fill ~17 ~1 ~14 ~18 ~1 ~14 sandstone 0  
fill ~17 ~1 ~45 ~17 ~3 ~45 sandstone 0 
setblock ~17 ~1 ~53 sandstone 0  
fill ~17 ~1 ~54 ~18 ~1 ~54 planks 2  
fill ~18 ~1 ~13 ~19 ~1 ~13 sandstone 0  
fill ~18 ~1 ~46 ~18 ~3 ~46 sandstone 0  
fill ~18 ~1 ~47 ~20 ~1 ~47 sandstone 0  
fill ~19 ~1 ~12 ~21 ~1 ~12 sandstone 0  
fill ~20 ~1 ~4 ~21 ~1 ~4 sandstone 0  
fill ~20 ~1 ~48 ~23 ~1 ~48 sandstone 0  
fill ~21 ~1 ~3 ~22 ~1 ~3 sandstone 0  
fill ~21 ~1 ~11 ~22 ~1 ~11 sandstone 0  
fill ~22 ~1 ~10 ~24 ~1 ~10 sandstone 0  
fill ~22 ~1 ~56 ~22 ~0 ~56 sandstone 0  
fill ~23 ~1 ~49 ~26 ~1 ~49 sandstone 0  
fill ~23 ~1 ~56 ~23 ~2 ~56 sandstone 2  
fill ~24 ~1 ~9 ~28 ~1 ~9 sandstone 0  
fill ~24 ~1 ~56 ~24 ~5 ~56 sandstone 0  
fill ~26 ~1 ~2 ~28 ~1 ~2 sandstone 0  
fill ~26 ~1 ~50 ~34 ~1 ~50 sandstone 0  
fill ~28 ~1 ~1 ~29 ~1 ~1 sandstone 0  
fill ~28 ~1 ~8 ~35 ~1 ~8 sandstone 0 
setblock ~29 ~1 ~57 planks 2  
fill ~30 ~1 ~57 ~30 ~5 ~57 sandstone 0  
fill ~34 ~1 ~1 ~34 ~7 ~1 sandstone 0  
fill ~34 ~1 ~49 ~37 ~1 ~49 sandstone 0  
fill ~34 ~1 ~56 ~36 ~1 ~56 sandstone 0  
fill ~35 ~1 ~9 ~38 ~1 ~9 sandstone 0  
fill ~37 ~1 ~48 ~40 ~1 ~48 sandstone 0  
fill ~38 ~1 ~10 ~41 ~1 ~10 sandstone 0  
fill ~40 ~1 ~2 ~40 ~1 ~3 planks 2  
fill ~40 ~1 ~47 ~41 ~1 ~47 sandstone 0  
fill ~40 ~1 ~55 ~40 ~2 ~55 sandstone 2 
setblock ~41 ~1 ~3 sandstone 0  
fill ~41 ~1 ~11 ~42 ~1 ~11 sandstone 0  
fill ~41 ~1 ~46 ~43 ~1 ~46 sandstone 0  
fill ~41 ~1 ~55 ~41 ~2 ~55 planks 2  
fill ~42 ~1 ~12 ~44 ~1 ~12 sandstone 0  
fill ~44 ~1 ~13 ~45 ~1 ~13 sandstone 0 
setblock ~44 ~1 ~44 planks 2  
fill ~45 ~1 ~5 ~46 ~1 ~5 sandstone 0  
fill ~45 ~1 ~14 ~46 ~1 ~14 sandstone 0  
fill ~45 ~1 ~43 ~45 ~0 ~43 sandstone 0  
fill ~46 ~1 ~6 ~47 ~1 ~6 sandstone 0  
fill ~46 ~1 ~15 ~47 ~1 ~15 sandstone 0  
fill ~46 ~1 ~42 ~47 ~1 ~42 sandstone 0  
fill ~46 ~1 ~43 ~46 ~3 ~43 planks 2  
fill ~46 ~1 ~52 ~46 ~0 ~52 sandstone 0  
fill ~47 ~1 ~16 ~48 ~1 ~16 sandstone 0  
fill ~47 ~1 ~41 ~48 ~1 ~41 sandstone 0  
fill ~47 ~1 ~51 ~48 ~1 ~51 sandstone 0  
fill ~47 ~1 ~52 ~47 ~3 ~52 planks 2  
fill ~48 ~1 ~18 ~49 ~1 ~18 sandstone 0  
fill ~48 ~1 ~39 ~49 ~1 ~39 sandstone 0  
fill ~49 ~1 ~20 ~50 ~1 ~20 sandstone 0  
fill ~49 ~1 ~38 ~50 ~1 ~38 sandstone 0  
fill ~50 ~1 ~22 ~51 ~1 ~22 sandstone 0  
fill ~50 ~1 ~35 ~51 ~1 ~35 sandstone 0  
fill ~51 ~1 ~10 ~51 ~15 ~10 sandstone 0  
fill ~51 ~1 ~27 ~52 ~1 ~27 sandstone 0  
fill ~51 ~1 ~29 ~52 ~1 ~29 sandstone 0 
setblock ~52 ~1 ~10 sandstone 2  
fill ~52 ~1 ~11 ~53 ~1 ~11 sandstone 0  
fill ~52 ~1 ~46 ~52 ~1 ~47 planks 2 
setblock ~53 ~1 ~46 sandstone 2  
fill ~54 ~1 ~45 ~54 ~4 ~45 sandstone 0  
fill ~55 ~1 ~16 ~56 ~1 ~16 sandstone 0  
fill ~55 ~1 ~41 ~55 ~4 ~41 sandstone 0  
fill ~56 ~1 ~40 ~56 ~3 ~40 planks 2 
setblock ~56 ~1 ~41 double_stone_slab 1 
setblock ~57 ~1 ~18 sandstone_stairs 7 
setblock ~57 ~1 ~19 stone_slab 9 
setblock ~57 ~1 ~20 sandstone_stairs 6  
fill ~57 ~1 ~21 ~58 ~1 ~21 sandstone 0  
fill ~57 ~1 ~39 ~57 ~4 ~39 sandstone 0  
fill ~58 ~1 ~22 ~58 ~3 ~22 planks 2  
fill ~58 ~1 ~23 ~58 ~3 ~23 sandstone 0  
fill ~58 ~1 ~27 ~59 ~1 ~27 sandstone 0  
fill ~58 ~1 ~28 ~58 ~12 ~28 sandstone 0  
fill ~58 ~1 ~29 ~58 ~7 ~29 sandstone 0  
fill ~59 ~1 ~28 ~59 ~2 ~28 planks 2  
fill ~59 ~1 ~29 ~59 ~2 ~29 planks 2  
fill ~1 ~2 ~22 ~1 ~2 ~27 stone_slab 7  
fill ~1 ~2 ~28 ~1 ~2 ~29 quartz_block 0 
setblock ~1 ~2 ~30 double_stone_slab 7  
fill ~1 ~2 ~31 ~1 ~2 ~34 stone_slab 15  
fill ~2 ~2 ~31 ~5 ~2 ~31 stone_slab 1  
fill ~2 ~2 ~32 ~5 ~2 ~32 stone_slab 1  
fill ~2 ~2 ~33 ~5 ~2 ~33 stone_slab 1 
setblock ~2 ~2 ~34 double_stone_slab 1  
fill ~2 ~2 ~35 ~2 ~2 ~37 stone_slab 1 
setblock ~2 ~2 ~38 double_stone_slab 1  
fill ~3 ~2 ~34 ~4 ~2 ~34 stone_slab 1  
fill ~3 ~2 ~36 ~15 ~2 ~36 sandstone 0  
fill ~3 ~2 ~37 ~15 ~2 ~37 sandstone 0  
fill ~3 ~2 ~38 ~16 ~2 ~38 sandstone 0  
fill ~3 ~2 ~40 ~15 ~2 ~40 sandstone 0 
setblock ~4 ~2 ~30 stone_slab 1  
fill ~4 ~2 ~35 ~9 ~2 ~35 sandstone 0  
fill ~4 ~2 ~39 ~16 ~2 ~39 sandstone 0  
fill ~4 ~2 ~42 ~5 ~2 ~42 sandstone 0  
fill ~5 ~2 ~24 ~5 ~22 ~24 sandstone 1  
fill ~5 ~2 ~25 ~5 ~0 ~25 sandstone 0  
fill ~5 ~2 ~29 ~5 ~2 ~30 sandstone 0  
fill ~5 ~2 ~34 ~8 ~2 ~34 sandstone 0  
fill ~5 ~2 ~41 ~7 ~2 ~41 sandstone 0  
fill ~5 ~2 ~43 ~6 ~2 ~43 sandstone 0  
fill ~6 ~2 ~19 ~7 ~2 ~19 sandstone 0  
fill ~6 ~2 ~23 ~6 ~8 ~23 sandstone 0  
fill ~6 ~2 ~24 ~6 ~20 ~24 sandstone 0  
fill ~6 ~2 ~30 ~7 ~2 ~30 sandstone 0  
fill ~6 ~2 ~31 ~7 ~2 ~31 sandstone 0  
fill ~6 ~2 ~32 ~7 ~2 ~32 sandstone 0  
fill ~6 ~2 ~33 ~8 ~2 ~33 sandstone 0  
fill ~7 ~2 ~18 ~7 ~3 ~18 sandstone 0 
setblock ~7 ~2 ~29 sandstone 0  
fill ~7 ~2 ~46 ~8 ~2 ~46 planks 2  
fill ~8 ~2 ~47 ~8 ~3 ~47 planks 2 
setblock ~9 ~2 ~13 sandstone 0  
fill ~9 ~2 ~47 ~9 ~3 ~47 sandstone 0 
setblock ~9 ~2 ~48 planks 2  
fill ~10 ~2 ~41 ~15 ~2 ~41 sandstone 0  
fill ~10 ~2 ~42 ~14 ~2 ~42 sandstone 0 
setblock ~10 ~2 ~49 planks 2  
fill ~11 ~2 ~43 ~11 ~4 ~43 sandstone 0  
fill ~11 ~2 ~50 ~12 ~2 ~50 sandstone 0  
fill ~12 ~2 ~24 ~13 ~2 ~24 sandstone 0  
fill ~12 ~2 ~30 ~13 ~2 ~30 sandstone 0  
fill ~12 ~2 ~35 ~14 ~2 ~35 sandstone 0  
fill ~13 ~2 ~20 ~14 ~2 ~20 sandstone 0  
fill ~13 ~2 ~21 ~13 ~22 ~21 sandstone 0  
fill ~13 ~2 ~23 ~13 ~23 ~23 sandstone 0  
fill ~13 ~2 ~31 ~13 ~24 ~31 sandstone 0  
fill ~13 ~2 ~32 ~13 ~16 ~32 sandstone 0  
fill ~13 ~2 ~33 ~13 ~15 ~33 sandstone 0  
fill ~13 ~2 ~34 ~14 ~2 ~34 sandstone 0  
fill ~13 ~2 ~51 ~13 ~2 ~52 planks 2  
fill ~14 ~2 ~18 ~15 ~2 ~18 sandstone 0  
fill ~14 ~2 ~44 ~16 ~2 ~44 sandstone 0  
fill ~14 ~2 ~52 ~14 ~3 ~52 planks 2  
fill ~15 ~2 ~17 ~16 ~2 ~17 sandstone 0  
fill ~15 ~2 ~53 ~17 ~2 ~53 planks 2 
setblock ~16 ~2 ~6 planks 2  
fill ~16 ~2 ~15 ~17 ~2 ~15 sandstone 0  
fill ~17 ~2 ~14 ~18 ~2 ~14 sandstone 0  
fill ~17 ~2 ~54 ~18 ~2 ~54 planks 2  
fill ~18 ~2 ~13 ~19 ~2 ~13 sandstone 0  
fill ~18 ~2 ~47 ~20 ~2 ~47 sandstone 0  
fill ~19 ~2 ~12 ~21 ~2 ~12 sandstone 0 
setblock ~19 ~2 ~55 sandstone_stairs 5  
fill ~20 ~2 ~4 ~21 ~2 ~4 sandstone 0  
fill ~20 ~2 ~48 ~23 ~2 ~48 sandstone 0 
setblock ~20 ~2 ~55 stone_slab 9  
fill ~21 ~2 ~3 ~22 ~2 ~3 planks 2  
fill ~21 ~2 ~11 ~22 ~2 ~11 sandstone 0 
setblock ~21 ~2 ~56 sandstone_stairs 4  
fill ~22 ~2 ~10 ~24 ~2 ~10 sandstone 0  
fill ~22 ~2 ~56 ~22 ~5 ~56 planks 2  
fill ~23 ~2 ~49 ~26 ~2 ~49 sandstone 0  
fill ~24 ~2 ~9 ~28 ~2 ~9 sandstone 0  
fill ~26 ~2 ~2 ~26 ~0 ~2 sandstone 0  
fill ~26 ~2 ~50 ~34 ~2 ~50 sandstone 0  
fill ~27 ~2 ~2 ~27 ~4 ~2 planks 2  
fill ~28 ~2 ~1 ~28 ~4 ~1 planks 2 
setblock ~28 ~2 ~2 sandstone 0  
fill ~28 ~2 ~8 ~30 ~2 ~8 sandstone 0  
fill ~29 ~2 ~1 ~29 ~10 ~1 sandstone 0  
fill ~29 ~2 ~57 ~29 ~3 ~57 sandstone 0  
fill ~31 ~2 ~8 ~31 ~4 ~8 planks 2  
fill ~32 ~2 ~8 ~35 ~2 ~8 sandstone 0  
fill ~34 ~2 ~49 ~37 ~2 ~49 sandstone 0  
fill ~34 ~2 ~56 ~34 ~5 ~56 planks 2  
fill ~34 ~2 ~57 ~34 ~6 ~57 planks 2  
fill ~35 ~2 ~1 ~35 ~4 ~1 planks 2  
fill ~35 ~2 ~9 ~38 ~2 ~9 sandstone 0 
setblock ~35 ~2 ~56 sandstone 2  
fill ~36 ~2 ~56 ~36 ~6 ~56 sandstone 0  
fill ~37 ~2 ~48 ~40 ~2 ~48 sandstone 0  
fill ~38 ~2 ~10 ~41 ~2 ~10 sandstone 0  
fill ~40 ~2 ~2 ~40 ~4 ~2 sandstone 2  
fill ~40 ~2 ~3 ~40 ~5 ~3 sandstone 0  
fill ~40 ~2 ~47 ~41 ~2 ~47 sandstone 0 
setblock ~41 ~2 ~3 planks 2  
fill ~41 ~2 ~11 ~42 ~2 ~11 sandstone 0  
fill ~41 ~2 ~46 ~43 ~2 ~46 sandstone 0 
setblock ~41 ~2 ~54 planks 2  
fill ~42 ~2 ~12 ~44 ~2 ~12 sandstone 0 
setblock ~42 ~2 ~54 sandstone 0  
fill ~44 ~2 ~13 ~45 ~2 ~13 sandstone 0  
fill ~44 ~2 ~44 ~44 ~9 ~44 sandstone 0  
fill ~45 ~2 ~5 ~46 ~2 ~5 sandstone 0  
fill ~45 ~2 ~14 ~46 ~2 ~14 sandstone 0 
setblock ~45 ~2 ~43 planks 2  
fill ~46 ~2 ~6 ~47 ~2 ~6 sandstone 0  
fill ~46 ~2 ~15 ~47 ~2 ~15 sandstone 0  
fill ~46 ~2 ~42 ~47 ~2 ~42 sandstone 0 
setblock ~46 ~2 ~52 planks 2  
fill ~47 ~2 ~16 ~48 ~2 ~16 sandstone 0  
fill ~47 ~2 ~41 ~48 ~2 ~41 sandstone 0  
fill ~47 ~2 ~51 ~47 ~7 ~51 sandstone 0  
fill ~48 ~2 ~18 ~49 ~2 ~18 sandstone 0  
fill ~48 ~2 ~39 ~49 ~2 ~39 sandstone 0  
fill ~48 ~2 ~51 ~48 ~3 ~51 sandstone 2  
fill ~49 ~2 ~20 ~50 ~2 ~20 sandstone 0  
fill ~49 ~2 ~38 ~50 ~2 ~38 sandstone 0  
fill ~50 ~2 ~22 ~51 ~2 ~22 sandstone 0  
fill ~50 ~2 ~35 ~50 ~0 ~35 sandstone 0  
fill ~50 ~2 ~36 ~50 ~4 ~36 planks 2  
fill ~51 ~2 ~27 ~52 ~2 ~27 sandstone 0  
fill ~51 ~2 ~29 ~52 ~2 ~29 sandstone 0  
fill ~51 ~2 ~35 ~51 ~4 ~35 planks 2  
fill ~52 ~2 ~10 ~52 ~3 ~10 sandstone 0 
setblock ~52 ~2 ~11 sandstone 2  
fill ~52 ~2 ~46 ~53 ~2 ~46 sandstone 0  
fill ~52 ~2 ~47 ~52 ~2 ~46 sandstone 0  
fill ~53 ~2 ~11 ~53 ~3 ~11 sandstone 0 
setblock ~53 ~2 ~12 sandstone_stairs 7 
setblock ~54 ~2 ~13 stone_slab 9 
setblock ~55 ~2 ~14 sandstone_stairs 6  
fill ~55 ~2 ~15 ~55 ~4 ~15 sandstone 0  
fill ~55 ~2 ~16 ~55 ~10 ~16 sandstone 0  
fill ~56 ~2 ~16 ~56 ~2 ~17 planks 2 
setblock ~56 ~2 ~41 sandstone 0  
fill ~57 ~2 ~18 ~57 ~2 ~21 sandstone 0 
setblock ~58 ~2 ~21 planks 2  
fill ~58 ~2 ~27 ~58 ~12 ~27 sandstone 0  
fill ~58 ~2 ~33 ~58 ~4 ~33 planks 2  
fill ~58 ~2 ~34 ~58 ~2 ~35 double_stone_slab 1 
setblock ~59 ~2 ~27 planks 2  
fill ~1 ~3 ~31 ~1 ~3 ~34 stone_slab 7  
fill ~2 ~3 ~35 ~2 ~3 ~37 quartz_block 0 
setblock ~2 ~3 ~38 stone_slab 15  
fill ~3 ~3 ~38 ~7 ~3 ~38 stone_slab 1  
fill ~3 ~3 ~39 ~3 ~3 ~40 stone_slab 15  
fill ~4 ~3 ~39 ~7 ~3 ~39 stone_slab 1  
fill ~4 ~3 ~40 ~7 ~3 ~40 stone_slab 1 
setblock ~4 ~3 ~41 stone_slab 15 
setblock ~4 ~3 ~42 stone_slab 1  
fill ~5 ~3 ~25 ~5 ~6 ~25 planks 2 
setblock ~5 ~3 ~29 sandstone 2  
fill ~5 ~3 ~30 ~5 ~23 ~30 sandstone 1  
fill ~5 ~3 ~37 ~6 ~3 ~37 stone_slab 1  
fill ~5 ~3 ~41 ~6 ~3 ~41 stone_slab 1  
fill ~5 ~3 ~42 ~11 ~3 ~42 sandstone 0 
setblock ~5 ~3 ~43 stone_slab 1  
fill ~6 ~3 ~19 ~7 ~3 ~19 sandstone 0  
fill ~6 ~3 ~30 ~6 ~4 ~30 sandstone 0  
fill ~6 ~3 ~31 ~6 ~5 ~31 sandstone 0  
fill ~6 ~3 ~35 ~7 ~3 ~35 sandstone 0 
setblock ~6 ~3 ~36 stone_slab 1  
fill ~6 ~3 ~43 ~12 ~3 ~43 sandstone 0 
setblock ~6 ~3 ~44 stone_slab 1 
setblock ~6 ~3 ~45 sandstone 0 
setblock ~7 ~3 ~17 planks 2  
fill ~7 ~3 ~36 ~7 ~3 ~37 sandstone 0  
fill ~7 ~3 ~41 ~11 ~3 ~41 sandstone 0  
fill ~7 ~3 ~44 ~19 ~3 ~44 sandstone 0  
fill ~7 ~3 ~46 ~7 ~2 ~46 planks 2  
fill ~8 ~3 ~38 ~8 ~3 ~46 sandstone 0  
fill ~9 ~3 ~13 ~10 ~3 ~13 sandstone 2  
fill ~9 ~3 ~39 ~9 ~3 ~48 sandstone 0 
setblock ~10 ~3 ~40 sandstone 0  
fill ~10 ~3 ~45 ~18 ~3 ~45 sandstone 0  
fill ~10 ~3 ~46 ~18 ~3 ~46 sandstone 0  
fill ~10 ~3 ~47 ~11 ~3 ~47 sandstone 0 
setblock ~10 ~3 ~49 sandstone 0  
fill ~11 ~3 ~11 ~11 ~3 ~12 planks 2  
fill ~11 ~3 ~50 ~12 ~3 ~50 sandstone 0  
fill ~12 ~3 ~24 ~13 ~3 ~24 sandstone 0  
fill ~12 ~3 ~30 ~13 ~3 ~30 sandstone 0  
fill ~12 ~3 ~51 ~13 ~3 ~51 sandstone 0  
fill ~13 ~3 ~20 ~14 ~3 ~20 sandstone 0  
fill ~13 ~3 ~34 ~14 ~3 ~34 sandstone 0 
setblock ~13 ~3 ~52 planks 2 
setblock ~14 ~3 ~7 sandstone 0  
fill ~14 ~3 ~18 ~15 ~3 ~18 sandstone 0  
fill ~14 ~3 ~35 ~14 ~25 ~35 sandstone 0  
fill ~14 ~3 ~36 ~15 ~3 ~36 sandstone 0  
fill ~14 ~3 ~42 ~20 ~3 ~42 sandstone 0  
fill ~15 ~3 ~17 ~16 ~3 ~17 sandstone 0  
fill ~15 ~3 ~37 ~16 ~3 ~37 sandstone 0  
fill ~15 ~3 ~41 ~19 ~3 ~41 sandstone 0  
fill ~15 ~3 ~43 ~20 ~3 ~43 sandstone 0  
fill ~15 ~3 ~47 ~20 ~3 ~47 sandstone 0  
fill ~15 ~3 ~52 ~15 ~4 ~52 sandstone 0  
fill ~15 ~3 ~53 ~15 ~4 ~53 sandstone 0  
fill ~16 ~3 ~6 ~16 ~4 ~6 sandstone 0  
fill ~16 ~3 ~15 ~17 ~3 ~15 sandstone 0  
fill ~16 ~3 ~38 ~16 ~26 ~38 sandstone 0  
fill ~16 ~3 ~39 ~17 ~3 ~39 sandstone 0  
fill ~16 ~3 ~40 ~18 ~3 ~40 sandstone 0  
fill ~16 ~3 ~48 ~16 ~8 ~48 sandstone 0  
fill ~16 ~3 ~53 ~17 ~3 ~53 planks 2  
fill ~17 ~3 ~14 ~18 ~3 ~14 sandstone 0  
fill ~17 ~3 ~54 ~19 ~3 ~54 planks 2  
fill ~18 ~3 ~13 ~19 ~3 ~13 sandstone 0  
fill ~19 ~3 ~12 ~21 ~3 ~12 sandstone 0  
fill ~19 ~3 ~55 ~21 ~3 ~55 planks 2  
fill ~20 ~3 ~4 ~21 ~3 ~4 planks 2  
fill ~20 ~3 ~48 ~23 ~3 ~48 sandstone 0  
fill ~21 ~3 ~3 ~21 ~2 ~3 planks 2  
fill ~21 ~3 ~11 ~22 ~3 ~11 sandstone 0  
fill ~21 ~3 ~56 ~21 ~5 ~56 planks 2 
setblock ~22 ~3 ~3 sandstone 2  
fill ~22 ~3 ~10 ~24 ~3 ~10 sandstone 0  
fill ~23 ~3 ~49 ~26 ~3 ~49 sandstone 0  
fill ~23 ~3 ~56 ~23 ~4 ~56 planks 2  
fill ~24 ~3 ~9 ~28 ~3 ~9 sandstone 0 
setblock ~25 ~3 ~56 sandstone_stairs 5 
setblock ~26 ~3 ~2 planks 2  
fill ~26 ~3 ~50 ~34 ~3 ~50 sandstone 0 
setblock ~26 ~3 ~57 stone_slab 9 
setblock ~27 ~3 ~57 sandstone_stairs 4 
setblock ~28 ~3 ~2 planks 2  
fill ~28 ~3 ~8 ~29 ~3 ~8 sandstone 0 
setblock ~28 ~3 ~57 sandstone 2 
setblock ~29 ~3 ~52 sandstone_stairs 5 
setblock ~30 ~3 ~8 planks 2 
setblock ~30 ~3 ~52 stone_slab 9 
setblock ~31 ~3 ~52 sandstone_stairs 4 
setblock ~32 ~3 ~8 planks 2  
fill ~33 ~3 ~8 ~35 ~3 ~8 sandstone 0  
fill ~34 ~3 ~49 ~37 ~3 ~49 sandstone 0  
fill ~35 ~3 ~9 ~38 ~3 ~9 sandstone 0  
fill ~35 ~3 ~56 ~35 ~5 ~56 planks 2  
fill ~37 ~3 ~48 ~40 ~3 ~48 sandstone 0  
fill ~38 ~3 ~10 ~41 ~3 ~10 sandstone 0 
setblock ~39 ~3 ~2 sandstone 2  
fill ~40 ~3 ~47 ~41 ~3 ~47 sandstone 0  
fill ~40 ~3 ~55 ~41 ~3 ~55 sandstone 0  
fill ~41 ~3 ~3 ~41 ~5 ~3 sandstone 0  
fill ~41 ~3 ~11 ~42 ~3 ~11 sandstone 0  
fill ~41 ~3 ~46 ~43 ~3 ~46 sandstone 0  
fill ~41 ~3 ~54 ~41 ~5 ~54 sandstone 2  
fill ~42 ~3 ~12 ~44 ~3 ~12 sandstone 0 
setblock ~42 ~3 ~54 planks 2  
fill ~44 ~3 ~13 ~45 ~3 ~13 sandstone 0  
fill ~44 ~3 ~45 ~44 ~8 ~45 sandstone 0  
fill ~45 ~3 ~5 ~45 ~9 ~5 sandstone 0  
fill ~45 ~3 ~14 ~46 ~3 ~14 sandstone 0  
fill ~45 ~3 ~43 ~45 ~9 ~43 sandstone 0  
fill ~46 ~3 ~5 ~46 ~5 ~5 planks 2  
fill ~46 ~3 ~6 ~46 ~0 ~6 sandstone 0  
fill ~46 ~3 ~15 ~47 ~3 ~15 sandstone 0  
fill ~46 ~3 ~42 ~47 ~3 ~42 sandstone 0  
fill ~46 ~3 ~52 ~46 ~6 ~52 sandstone 0  
fill ~47 ~3 ~6 ~47 ~5 ~6 planks 2  
fill ~47 ~3 ~16 ~48 ~3 ~16 sandstone 0  
fill ~47 ~3 ~41 ~48 ~3 ~41 sandstone 0 
setblock ~48 ~3 ~7 sandstone_stairs 5  
fill ~48 ~3 ~18 ~49 ~3 ~18 sandstone 0  
fill ~48 ~3 ~39 ~49 ~3 ~39 sandstone 0 
setblock ~49 ~3 ~7 stone_slab 9  
fill ~49 ~3 ~20 ~50 ~3 ~20 sandstone 0  
fill ~49 ~3 ~38 ~50 ~3 ~38 sandstone 0 
setblock ~50 ~3 ~8 sandstone_stairs 6  
fill ~50 ~3 ~22 ~51 ~3 ~22 sandstone 0 
setblock ~50 ~3 ~35 planks 2 
setblock ~50 ~3 ~37 planks 2  
fill ~51 ~3 ~27 ~52 ~3 ~27 sandstone 0  
fill ~51 ~3 ~29 ~52 ~3 ~29 sandstone 0  
fill ~52 ~3 ~11 ~52 ~4 ~11 sandstone 0  
fill ~52 ~3 ~46 ~53 ~3 ~46 sandstone 0 
setblock ~52 ~3 ~47 sandstone 2 
setblock ~53 ~3 ~12 sandstone 0 
setblock ~54 ~3 ~13 sandstone 0 
setblock ~55 ~3 ~14 sandstone 0  
fill ~56 ~3 ~16 ~56 ~3 ~17 sandstone 0 
setblock ~56 ~3 ~41 planks 2  
fill ~57 ~3 ~18 ~57 ~3 ~20 glowstone 0  
fill ~57 ~3 ~21 ~58 ~3 ~21 sandstone 0  
fill ~58 ~3 ~34 ~58 ~3 ~35 planks 2  
fill ~59 ~3 ~27 ~59 ~3 ~29 double_stone_slab 1 
setblock ~2 ~4 ~38 stone_slab 7  
fill ~3 ~4 ~39 ~3 ~4 ~40 stone_slab 7 
setblock ~4 ~4 ~41 stone_slab 7 
setblock ~4 ~4 ~42 double_stone_slab 7 
setblock ~5 ~4 ~29 planks 2 
setblock ~5 ~4 ~43 quartz_block 0  
fill ~6 ~4 ~19 ~7 ~4 ~19 sandstone 0  
fill ~6 ~4 ~35 ~7 ~4 ~35 sandstone 0 
setblock ~6 ~4 ~44 quartz_block 0 
setblock ~6 ~4 ~45 stone_slab 15  
fill ~7 ~4 ~17 ~7 ~5 ~17 sandstone 0  
fill ~7 ~4 ~18 ~7 ~6 ~18 planks 2  
fill ~7 ~4 ~36 ~7 ~24 ~36 sandstone 1 
setblock ~7 ~4 ~37 sandstone 0  
fill ~7 ~4 ~45 ~11 ~4 ~45 stone_slab 1 
setblock ~7 ~4 ~46 stone_slab 15  
fill ~8 ~4 ~44 ~10 ~4 ~44 stone_slab 1  
fill ~8 ~4 ~46 ~11 ~4 ~46 stone_slab 1 
setblock ~8 ~4 ~47 stone_slab 15  
fill ~9 ~4 ~13 ~9 ~3 ~13 sandstone 2  
fill ~9 ~4 ~41 ~10 ~4 ~41 sandstone 0 
setblock ~9 ~4 ~43 stone_slab 1  
fill ~9 ~4 ~47 ~10 ~4 ~47 double_stone_slab 1 
setblock ~9 ~4 ~48 stone_slab 1 
setblock ~10 ~4 ~12 planks 2  
fill ~10 ~4 ~13 ~10 ~16 ~13 sandstone 0  
fill ~10 ~4 ~42 ~11 ~4 ~42 sandstone 0  
fill ~10 ~4 ~43 ~10 ~6 ~43 sandstone 0 
setblock ~10 ~4 ~49 stone_slab 1  
fill ~11 ~4 ~11 ~11 ~9 ~11 sandstone 0  
fill ~11 ~4 ~12 ~11 ~11 ~12 sandstone 0  
fill ~11 ~4 ~44 ~15 ~4 ~44 sandstone 0  
fill ~11 ~4 ~47 ~17 ~4 ~47 sandstone 0  
fill ~11 ~4 ~48 ~24 ~4 ~48 sandstone 0 
setblock ~11 ~4 ~50 stone_slab 1  
fill ~12 ~4 ~24 ~13 ~4 ~24 sandstone 0  
fill ~12 ~4 ~30 ~13 ~4 ~30 sandstone 0 
setblock ~12 ~4 ~43 sandstone 0  
fill ~12 ~4 ~45 ~15 ~4 ~45 sandstone 0  
fill ~12 ~4 ~46 ~16 ~4 ~46 sandstone 0  
fill ~12 ~4 ~49 ~26 ~4 ~49 sandstone 0  
fill ~12 ~4 ~50 ~23 ~4 ~50 sandstone 0 
setblock ~12 ~4 ~51 stone_slab 1  
fill ~13 ~4 ~20 ~14 ~4 ~20 sandstone 0  
fill ~13 ~4 ~34 ~14 ~4 ~34 sandstone 0  
fill ~13 ~4 ~51 ~17 ~4 ~51 sandstone 0  
fill ~13 ~4 ~52 ~16 ~4 ~52 sandstone 0  
fill ~14 ~4 ~7 ~14 ~5 ~7 planks 2  
fill ~14 ~4 ~18 ~15 ~4 ~18 sandstone 0  
fill ~14 ~4 ~36 ~15 ~4 ~36 sandstone 0  
fill ~15 ~4 ~17 ~16 ~4 ~17 sandstone 0  
fill ~15 ~4 ~37 ~16 ~4 ~37 sandstone 0  
fill ~16 ~4 ~15 ~17 ~4 ~15 sandstone 0  
fill ~16 ~4 ~39 ~17 ~4 ~39 sandstone 0  
fill ~16 ~4 ~53 ~17 ~4 ~53 planks 2  
fill ~17 ~4 ~14 ~18 ~4 ~14 sandstone 0  
fill ~17 ~4 ~40 ~18 ~4 ~40 sandstone 0  
fill ~17 ~4 ~54 ~19 ~4 ~54 planks 2  
fill ~18 ~4 ~13 ~19 ~4 ~13 sandstone 0  
fill ~18 ~4 ~41 ~19 ~4 ~41 sandstone 0  
fill ~19 ~4 ~12 ~21 ~4 ~12 sandstone 0  
fill ~19 ~4 ~42 ~21 ~4 ~42 sandstone 0  
fill ~19 ~4 ~45 ~25 ~4 ~45 sandstone 0  
fill ~19 ~4 ~46 ~25 ~4 ~46 sandstone 0  
fill ~19 ~4 ~47 ~24 ~4 ~47 sandstone 0 
setblock ~19 ~4 ~55 sandstone 2  
fill ~20 ~4 ~4 ~21 ~4 ~4 sandstone 0  
fill ~20 ~4 ~43 ~22 ~4 ~43 sandstone 0  
fill ~20 ~4 ~44 ~24 ~4 ~44 sandstone 0  
fill ~20 ~4 ~55 ~21 ~4 ~55 planks 2 
setblock ~21 ~4 ~3 sandstone 2  
fill ~21 ~4 ~11 ~22 ~4 ~11 sandstone 0  
fill ~22 ~4 ~3 ~22 ~7 ~3 sandstone 0  
fill ~22 ~4 ~10 ~24 ~4 ~10 sandstone 0  
fill ~22 ~4 ~51 ~23 ~4 ~51 sandstone 0  
fill ~24 ~4 ~9 ~28 ~4 ~9 sandstone 0  
fill ~25 ~4 ~56 ~26 ~4 ~56 planks 2  
fill ~26 ~4 ~2 ~26 ~7 ~2 sandstone 0  
fill ~26 ~4 ~50 ~34 ~4 ~50 sandstone 0  
fill ~26 ~4 ~57 ~26 ~5 ~57 planks 2  
fill ~27 ~4 ~57 ~28 ~4 ~57 sandstone 0  
fill ~28 ~4 ~2 ~28 ~18 ~2 sandstone 0  
fill ~28 ~4 ~8 ~30 ~4 ~8 sandstone 0  
fill ~29 ~4 ~57 ~29 ~6 ~57 planks 2 
setblock ~31 ~4 ~57 sandstone_stairs 5  
fill ~32 ~4 ~8 ~35 ~4 ~8 sandstone 0 
setblock ~32 ~4 ~57 stone_slab 9 
setblock ~33 ~4 ~57 sandstone_stairs 4  
fill ~34 ~4 ~49 ~37 ~4 ~49 sandstone 0  
fill ~35 ~4 ~9 ~38 ~4 ~9 sandstone 0  
fill ~37 ~4 ~48 ~40 ~4 ~48 sandstone 0  
fill ~38 ~4 ~10 ~41 ~4 ~10 sandstone 0  
fill ~39 ~4 ~2 ~39 ~5 ~2 sandstone 0  
fill ~40 ~4 ~47 ~41 ~4 ~47 sandstone 0  
fill ~40 ~4 ~55 ~40 ~3 ~55 sandstone 0  
fill ~41 ~4 ~11 ~42 ~4 ~11 sandstone 0  
fill ~41 ~4 ~46 ~43 ~4 ~46 sandstone 0 
setblock ~41 ~4 ~55 sandstone 2 
setblock ~42 ~4 ~3 sandstone_stairs 5  
fill ~42 ~4 ~12 ~44 ~4 ~12 sandstone 0  
fill ~42 ~4 ~54 ~42 ~6 ~54 sandstone 0 
setblock ~43 ~4 ~4 stone_slab 9 
setblock ~44 ~4 ~4 sandstone_stairs 6  
fill ~44 ~4 ~13 ~45 ~4 ~13 sandstone 0  
fill ~45 ~4 ~14 ~46 ~4 ~14 sandstone 0  
fill ~45 ~4 ~44 ~45 ~9 ~44 sandstone 0 
setblock ~46 ~4 ~6 planks 2  
fill ~46 ~4 ~15 ~47 ~4 ~15 sandstone 0  
fill ~46 ~4 ~42 ~47 ~4 ~42 sandstone 0  
fill ~46 ~4 ~43 ~46 ~10 ~43 sandstone 0  
fill ~47 ~4 ~16 ~48 ~4 ~16 sandstone 0  
fill ~47 ~4 ~41 ~48 ~4 ~41 sandstone 0  
fill ~47 ~4 ~52 ~47 ~5 ~52 sandstone 0 
setblock ~48 ~4 ~7 sandstone 0  
fill ~48 ~4 ~18 ~49 ~4 ~18 sandstone 0  
fill ~48 ~4 ~39 ~49 ~4 ~39 sandstone 0 
setblock ~48 ~4 ~50 sandstone 2  
fill ~48 ~4 ~51 ~48 ~6 ~51 sandstone 0 
setblock ~49 ~4 ~7 planks 2  
fill ~49 ~4 ~20 ~50 ~4 ~20 sandstone 0  
fill ~49 ~4 ~38 ~50 ~4 ~38 sandstone 0 
setblock ~50 ~4 ~8 planks 2  
fill ~50 ~4 ~9 ~50 ~11 ~9 sandstone 0  
fill ~50 ~4 ~22 ~51 ~4 ~22 sandstone 0  
fill ~50 ~4 ~35 ~50 ~10 ~35 sandstone 0  
fill ~50 ~4 ~37 ~50 ~11 ~37 sandstone 0  
fill ~51 ~4 ~27 ~52 ~4 ~27 sandstone 0  
fill ~51 ~4 ~29 ~52 ~4 ~29 sandstone 0  
fill ~52 ~4 ~10 ~52 ~6 ~10 planks 2  
fill ~52 ~4 ~46 ~52 ~2 ~46 sandstone 0  
fill ~52 ~4 ~47 ~52 ~6 ~47 planks 2  
fill ~53 ~4 ~11 ~53 ~7 ~11 planks 2 
setblock ~53 ~4 ~12 glowstone 0  
fill ~53 ~4 ~46 ~53 ~5 ~46 planks 2 
setblock ~54 ~4 ~13 glowstone 0 
setblock ~55 ~4 ~14 glowstone 0 
setblock ~56 ~4 ~16 planks 2  
fill ~56 ~4 ~17 ~56 ~5 ~17 sandstone 0 
setblock ~56 ~4 ~40 sandstone 0 
setblock ~56 ~4 ~41 sandstone 2  
fill ~57 ~4 ~18 ~57 ~4 ~20 double_stone_slab 1 
setblock ~57 ~4 ~21 stone_slab 1  
fill ~58 ~4 ~21 ~58 ~5 ~21 sandstone 0 
setblock ~58 ~4 ~22 sandstone 2 
setblock ~58 ~4 ~23 planks 2  
fill ~58 ~4 ~34 ~58 ~10 ~34 sandstone 0 
setblock ~58 ~4 ~35 planks 2 
setblock ~59 ~4 ~27 planks 2 
setblock ~59 ~4 ~28 sandstone 2 
setblock ~59 ~4 ~29 planks 2 
setblock ~5 ~5 ~29 sandstone 2  
fill ~6 ~5 ~19 ~7 ~5 ~19 sandstone 0 
setblock ~6 ~5 ~30 planks 2  
fill ~6 ~5 ~35 ~7 ~5 ~35 sandstone 0 
setblock ~6 ~5 ~45 stone_slab 7 
setblock ~7 ~5 ~37 planks 2 
setblock ~7 ~5 ~46 stone_slab 7 
setblock ~8 ~5 ~47 stone_slab 7 
setblock ~9 ~5 ~13 sandstone 0  
fill ~9 ~5 ~41 ~10 ~5 ~41 sandstone 0 
setblock ~9 ~5 ~48 double_stone_slab 7 
setblock ~10 ~5 ~12 sandstone 0  
fill ~10 ~5 ~42 ~10 ~25 ~42 sandstone 1 
setblock ~10 ~5 ~49 quartz_block 0 
setblock ~11 ~5 ~50 quartz_block 0  
fill ~12 ~5 ~24 ~13 ~5 ~24 sandstone 0  
fill ~12 ~5 ~30 ~13 ~5 ~30 sandstone 0 
setblock ~12 ~5 ~51 quartz_block 0  
fill ~13 ~5 ~20 ~14 ~5 ~20 sandstone 0  
fill ~13 ~5 ~34 ~14 ~5 ~34 sandstone 0  
fill ~13 ~5 ~50 ~16 ~5 ~50 stone_slab 1  
fill ~13 ~5 ~51 ~16 ~5 ~51 stone_slab 1  
fill ~13 ~5 ~52 ~14 ~5 ~52 stone_slab 15  
fill ~14 ~5 ~18 ~15 ~5 ~18 sandstone 0  
fill ~14 ~5 ~36 ~15 ~5 ~36 sandstone 0  
fill ~14 ~5 ~47 ~14 ~7 ~47 sandstone 0  
fill ~14 ~5 ~49 ~16 ~5 ~49 stone_slab 1  
fill ~15 ~5 ~17 ~16 ~5 ~17 sandstone 0  
fill ~15 ~5 ~37 ~16 ~5 ~37 sandstone 0  
fill ~15 ~5 ~47 ~15 ~25 ~47 sandstone 1 
setblock ~15 ~5 ~48 stone_slab 1 
setblock ~15 ~5 ~52 stone_slab 1 
setblock ~15 ~5 ~53 stone_slab 15 
setblock ~16 ~5 ~6 planks 2  
fill ~16 ~5 ~15 ~17 ~5 ~15 sandstone 0  
fill ~16 ~5 ~39 ~17 ~5 ~39 sandstone 0  
fill ~16 ~5 ~46 ~16 ~5 ~48 sandstone 0  
fill ~16 ~5 ~52 ~17 ~5 ~52 double_stone_slab 1 
setblock ~16 ~5 ~53 stone_slab 1  
fill ~17 ~5 ~14 ~18 ~5 ~14 sandstone 0  
fill ~17 ~5 ~40 ~18 ~5 ~40 sandstone 0  
fill ~17 ~5 ~47 ~17 ~5 ~48 sandstone 0  
fill ~17 ~5 ~49 ~17 ~5 ~52 double_stone_slab 1  
fill ~17 ~5 ~53 ~24 ~5 ~53 sandstone 0  
fill ~17 ~5 ~54 ~18 ~5 ~54 stone_slab 1  
fill ~18 ~5 ~13 ~19 ~5 ~13 sandstone 0  
fill ~18 ~5 ~41 ~19 ~5 ~41 sandstone 0  
fill ~18 ~5 ~48 ~22 ~5 ~48 sandstone 0  
fill ~18 ~5 ~49 ~30 ~5 ~49 sandstone 0  
fill ~18 ~5 ~50 ~34 ~5 ~50 sandstone 0  
fill ~18 ~5 ~51 ~30 ~5 ~51 sandstone 0  
fill ~18 ~5 ~52 ~30 ~5 ~52 sandstone 0   
fill ~19 ~5 ~12 ~21 ~5 ~12 sandstone 0  
fill ~19 ~5 ~42 ~21 ~5 ~42 sandstone 0  
fill ~19 ~5 ~54 ~24 ~5 ~54 sandstone 0  
fill ~19 ~5 ~55 ~19 ~5 ~48 sandstone 0  
fill ~20 ~5 ~4 ~21 ~5 ~4 sandstone 0  
fill ~20 ~5 ~55 ~22 ~5 ~55 planks 2  
fill ~21 ~5 ~3 ~21 ~6 ~3 sandstone 0  
fill ~21 ~5 ~11 ~22 ~5 ~11 sandstone 0  
fill ~21 ~5 ~43 ~23 ~5 ~43 sandstone 0  
fill ~22 ~5 ~10 ~24 ~5 ~10 sandstone 0  
fill ~23 ~5 ~44 ~25 ~5 ~44 sandstone 0  
fill ~23 ~5 ~55 ~23 ~6 ~55 sandstone 0 
setblock ~23 ~5 ~56 sandstone 2  
fill ~24 ~5 ~9 ~28 ~5 ~9 sandstone 0  
fill ~24 ~5 ~47 ~30 ~5 ~47 sandstone 0  
fill ~24 ~5 ~48 ~30 ~5 ~48 sandstone 0  
fill ~25 ~5 ~45 ~30 ~5 ~45 sandstone 0  
fill ~25 ~5 ~46 ~30 ~5 ~46 sandstone 0  
fill ~25 ~5 ~56 ~26 ~5 ~56 planks 2  
fill ~27 ~5 ~2 ~27 ~8 ~2 sandstone 0  
fill ~27 ~5 ~57 ~29 ~5 ~57 planks 2  
fill ~28 ~5 ~1 ~28 ~6 ~1 sandstone 0  
fill ~28 ~5 ~8 ~35 ~5 ~8 sandstone 0  
fill ~31 ~5 ~57 ~32 ~5 ~57 sandstone 0  
fill ~33 ~5 ~57 ~33 ~6 ~57 planks 2  
fill ~34 ~5 ~49 ~37 ~5 ~49 sandstone 0  
fill ~35 ~5 ~1 ~35 ~7 ~1 sandstone 0  
fill ~35 ~5 ~9 ~39 ~5 ~9 sandstone 0 
setblock ~36 ~5 ~2 sandstone_stairs 5 
setblock ~37 ~5 ~2 stone_slab 9  
fill ~37 ~5 ~48 ~40 ~5 ~48 sandstone 0 
setblock ~37 ~5 ~56 sandstone_stairs 5 
setblock ~38 ~5 ~2 sandstone_stairs 4 
setblock ~38 ~5 ~56 stone_slab 9  
fill ~39 ~5 ~10 ~41 ~5 ~10 sandstone 0 
setblock ~39 ~5 ~55 sandstone_stairs 4 
setblock ~40 ~5 ~2 sandstone 0  
fill ~40 ~5 ~47 ~41 ~5 ~47 sandstone 0 
setblock ~40 ~5 ~55 planks 2  
fill ~41 ~5 ~11 ~42 ~5 ~11 sandstone 0  
fill ~41 ~5 ~46 ~43 ~5 ~46 sandstone 0  
fill ~41 ~5 ~55 ~41 ~7 ~55 sandstone 0 
setblock ~42 ~5 ~3 sandstone 0  
fill ~42 ~5 ~12 ~44 ~5 ~12 sandstone 0  
fill ~43 ~5 ~4 ~44 ~5 ~4 sandstone 0  
fill ~44 ~5 ~13 ~45 ~5 ~13 sandstone 0  
fill ~45 ~5 ~14 ~46 ~5 ~14 sandstone 0  
fill ~46 ~5 ~6 ~46 ~9 ~6 sandstone 0  
fill ~46 ~5 ~15 ~47 ~5 ~15 sandstone 0  
fill ~46 ~5 ~42 ~47 ~5 ~42 sandstone 0  
fill ~47 ~5 ~16 ~48 ~5 ~16 sandstone 0  
fill ~47 ~5 ~41 ~48 ~5 ~41 sandstone 0  
fill ~48 ~5 ~7 ~49 ~5 ~7 glowstone 0  
fill ~48 ~5 ~18 ~49 ~5 ~18 sandstone 0  
fill ~48 ~5 ~39 ~49 ~5 ~39 sandstone 0 
setblock ~48 ~5 ~50 sandstone 0  
fill ~49 ~5 ~20 ~50 ~5 ~20 sandstone 0  
fill ~49 ~5 ~38 ~50 ~5 ~38 sandstone 0 
setblock ~50 ~5 ~8 glowstone 0  
fill ~50 ~5 ~21 ~50 ~7 ~21 planks 2  
fill ~50 ~5 ~22 ~50 ~0 ~22 sandstone 0  
fill ~50 ~5 ~36 ~50 ~11 ~36 sandstone 0  
fill ~51 ~5 ~22 ~51 ~7 ~22 planks 2  
fill ~51 ~5 ~27 ~52 ~5 ~27 sandstone 0  
fill ~51 ~5 ~29 ~52 ~5 ~29 sandstone 0  
fill ~51 ~5 ~35 ~51 ~11 ~35 sandstone 0 
setblock ~52 ~5 ~11 planks 2 
setblock ~52 ~5 ~46 planks 2 
setblock ~53 ~5 ~12 sandstone 0 
setblock ~54 ~5 ~13 double_stone_slab 1  
fill ~54 ~5 ~45 ~54 ~6 ~45 planks 2  
fill ~55 ~5 ~14 ~55 ~5 ~15 double_stone_slab 1 
setblock ~55 ~5 ~41 sandstone 2 
setblock ~56 ~5 ~16 sandstone 0  
fill ~56 ~5 ~40 ~56 ~7 ~40 planks 2 
setblock ~56 ~5 ~41 sandstone 0  
fill ~57 ~5 ~18 ~57 ~5 ~20 leaves 6  
fill ~57 ~5 ~21 ~57 ~11 ~21 sandstone 0  
fill ~57 ~5 ~39 ~57 ~7 ~39 planks 2  
fill ~58 ~5 ~22 ~58 ~8 ~22 sandstone 0 
setblock ~58 ~5 ~23 sandstone 2  
fill ~58 ~5 ~33 ~58 ~6 ~33 sandstone 0  
fill ~58 ~5 ~35 ~58 ~6 ~35 sandstone 2  
fill ~59 ~5 ~27 ~59 ~5 ~29 sandstone 0  
fill ~5 ~6 ~29 ~5 ~7 ~29 sandstone 0  
fill ~6 ~6 ~19 ~7 ~6 ~19 sandstone 0 
setblock ~6 ~6 ~30 sandstone 0 
setblock ~6 ~6 ~31 planks 2  
fill ~6 ~6 ~35 ~7 ~6 ~35 planks 2  
fill ~7 ~6 ~17 ~7 ~11 ~17 planks 2 
setblock ~7 ~6 ~37 sandstone 0 
setblock ~8 ~6 ~15 stone_slab 9 
setblock ~8 ~6 ~16 sandstone_stairs 6  
fill ~9 ~6 ~13 ~9 ~8 ~13 sandstone 2 
setblock ~9 ~6 ~14 sandstone_stairs 7  
fill ~9 ~6 ~41 ~9 ~8 ~41 planks 2  
fill ~10 ~6 ~12 ~10 ~8 ~12 planks 2 
setblock ~10 ~6 ~41 sandstone 0 
setblock ~11 ~6 ~10 sandstone_stairs 6 
setblock ~12 ~6 ~9 stone_slab 9  
fill ~12 ~6 ~24 ~13 ~6 ~24 sandstone 0  
fill ~12 ~6 ~30 ~13 ~6 ~30 sandstone 0 
setblock ~13 ~6 ~8 sandstone_stairs 4  
fill ~13 ~6 ~20 ~14 ~6 ~20 sandstone 0  
fill ~13 ~6 ~34 ~14 ~6 ~34 sandstone 0  
fill ~13 ~6 ~52 ~14 ~6 ~52 stone_slab 7  
fill ~14 ~6 ~7 ~14 ~10 ~7 sandstone 0  
fill ~14 ~6 ~18 ~15 ~6 ~18 sandstone 0  
fill ~14 ~6 ~36 ~15 ~6 ~36 sandstone 0  
fill ~15 ~6 ~7 ~15 ~7 ~7 planks 2  
fill ~15 ~6 ~17 ~16 ~6 ~17 sandstone 0  
fill ~15 ~6 ~37 ~16 ~6 ~37 sandstone 0 
setblock ~15 ~6 ~53 stone_slab 7  
fill ~16 ~6 ~6 ~16 ~7 ~6 sandstone 0  
fill ~16 ~6 ~15 ~17 ~6 ~15 sandstone 0  
fill ~16 ~6 ~39 ~17 ~6 ~39 sandstone 0  
fill ~16 ~6 ~47 ~16 ~8 ~47 sandstone 0 
setblock ~16 ~6 ~53 quartz_block 0 
setblock ~17 ~6 ~5 sandstone_stairs 5  
fill ~17 ~6 ~14 ~18 ~6 ~14 sandstone 0  
fill ~17 ~6 ~40 ~18 ~6 ~40 sandstone 0  
fill ~17 ~6 ~54 ~18 ~6 ~54 quartz_block 0 
setblock ~18 ~6 ~5 stone_slab 9  
fill ~18 ~6 ~13 ~19 ~6 ~13 sandstone 0  
fill ~18 ~6 ~41 ~19 ~6 ~41 sandstone 0 
setblock ~19 ~6 ~4 sandstone_stairs 4  
fill ~19 ~6 ~12 ~21 ~6 ~12 sandstone 0  
fill ~19 ~6 ~42 ~21 ~6 ~42 sandstone 0  
fill ~19 ~6 ~54 ~22 ~6 ~54 stone_slab 1  
fill ~19 ~6 ~55 ~20 ~6 ~55 stone_slab 15  
fill ~20 ~6 ~4 ~21 ~6 ~4 sandstone 0  
fill ~20 ~6 ~50 ~21 ~6 ~50 sandstone 0  
fill ~20 ~6 ~51 ~20 ~6 ~54 stone_slab 1  
fill ~21 ~6 ~11 ~22 ~6 ~11 sandstone 0  
fill ~21 ~6 ~43 ~23 ~6 ~43 sandstone 0 
setblock ~21 ~6 ~51 planks 2  
fill ~21 ~6 ~52 ~23 ~6 ~52 stone_slab 1  
fill ~21 ~6 ~53 ~23 ~6 ~53 stone_slab 1  
fill ~21 ~6 ~56 ~22 ~6 ~56 stone_slab 15  
fill ~22 ~6 ~10 ~24 ~6 ~10 sandstone 0  
fill ~22 ~6 ~51 ~37 ~6 ~51 sandstone 0 
setblock ~23 ~6 ~2 sandstone_stairs 5  
fill ~23 ~6 ~44 ~25 ~6 ~44 sandstone 0 
setblock ~23 ~6 ~54 double_stone_slab 1  
fill ~23 ~6 ~56 ~25 ~6 ~56 stone_slab 1 
setblock ~24 ~6 ~2 stone_slab 9  
fill ~24 ~6 ~9 ~28 ~6 ~9 sandstone 0  
fill ~24 ~6 ~52 ~35 ~6 ~52 sandstone 0  
fill ~24 ~6 ~53 ~31 ~6 ~53 sandstone 0  
fill ~24 ~6 ~54 ~31 ~6 ~54 sandstone 0  
fill ~24 ~6 ~55 ~31 ~6 ~55 sandstone 0 
setblock ~25 ~6 ~2 sandstone_stairs 4  
fill ~25 ~6 ~45 ~35 ~6 ~45 sandstone 0  
fill ~25 ~6 ~49 ~26 ~6 ~49 sandstone 0  
fill ~25 ~6 ~50 ~37 ~6 ~50 sandstone 0  
fill ~26 ~6 ~56 ~29 ~6 ~56 planks 2  
fill ~26 ~6 ~57 ~27 ~6 ~57 stone_slab 1  
fill ~28 ~6 ~8 ~35 ~6 ~8 sandstone 0 
setblock ~28 ~6 ~57 planks 2 
setblock ~30 ~6 ~1 sandstone_stairs 5  
fill ~30 ~6 ~46 ~36 ~6 ~46 sandstone 0  
fill ~30 ~6 ~47 ~36 ~6 ~47 sandstone 0  
fill ~30 ~6 ~48 ~36 ~6 ~48 sandstone 0  
fill ~30 ~6 ~49 ~38 ~6 ~49 sandstone 0  
fill ~30 ~6 ~56 ~31 ~6 ~56 sandstone 0 
setblock ~30 ~6 ~57 planks 2 
setblock ~31 ~6 ~1 stone_slab 9  
fill ~31 ~6 ~57 ~31 ~5 ~57 sandstone 0 
setblock ~32 ~6 ~1 sandstone_stairs 4 
setblock ~32 ~6 ~57 planks 2  
fill ~33 ~6 ~1 ~33 ~10 ~1 planks 2  
fill ~34 ~6 ~56 ~38 ~6 ~56 sandstone 0  
fill ~35 ~6 ~9 ~39 ~6 ~9 sandstone 0  
fill ~36 ~6 ~2 ~37 ~6 ~2 sandstone 0 
setblock ~38 ~6 ~2 planks 2  
fill ~38 ~6 ~48 ~40 ~6 ~48 sandstone 0 
setblock ~38 ~6 ~55 sandstone 0  
fill ~39 ~6 ~2 ~40 ~6 ~2 sandstone 2  
fill ~39 ~6 ~10 ~41 ~6 ~10 sandstone 0 
setblock ~39 ~6 ~55 planks 2  
fill ~40 ~6 ~3 ~41 ~6 ~3 sandstone 2  
fill ~40 ~6 ~47 ~41 ~6 ~47 sandstone 0  
fill ~40 ~6 ~55 ~40 ~7 ~55 sandstone 0  
fill ~41 ~6 ~11 ~42 ~6 ~11 sandstone 0  
fill ~41 ~6 ~46 ~43 ~6 ~46 sandstone 0 
setblock ~41 ~6 ~54 planks 2 
setblock ~42 ~6 ~3 glowstone 0  
fill ~42 ~6 ~12 ~44 ~6 ~12 sandstone 0  
fill ~43 ~6 ~4 ~44 ~6 ~4 glowstone 0 
setblock ~43 ~6 ~54 sandstone_stairs 5  
fill ~44 ~6 ~13 ~45 ~6 ~13 sandstone 0 
setblock ~44 ~6 ~53 stone_slab 9  
fill ~45 ~6 ~14 ~46 ~6 ~14 sandstone 0 
setblock ~45 ~6 ~53 sandstone_stairs 7 
setblock ~46 ~6 ~5 sandstone 0  
fill ~46 ~6 ~15 ~47 ~6 ~15 sandstone 0  
fill ~46 ~6 ~42 ~47 ~6 ~42 sandstone 0  
fill ~47 ~6 ~6 ~47 ~7 ~6 sandstone 0  
fill ~47 ~6 ~16 ~48 ~6 ~16 sandstone 0  
fill ~47 ~6 ~41 ~48 ~6 ~41 sandstone 0 
setblock ~47 ~6 ~52 sandstone 2 
setblock ~48 ~6 ~7 sandstone 2  
fill ~48 ~6 ~18 ~49 ~6 ~18 sandstone 0  
fill ~48 ~6 ~39 ~49 ~6 ~39 sandstone 0 
setblock ~48 ~6 ~50 double_stone_slab 1 
setblock ~49 ~6 ~7 planks 2  
fill ~49 ~6 ~20 ~49 ~13 ~20 sandstone 0  
fill ~49 ~6 ~38 ~50 ~6 ~38 sandstone 0 
setblock ~49 ~6 ~50 sandstone_stairs 5 
setblock ~50 ~6 ~8 planks 2 
setblock ~50 ~6 ~20 planks 2 
setblock ~50 ~6 ~22 planks 2 
setblock ~50 ~6 ~49 stone_slab 9  
fill ~51 ~6 ~27 ~52 ~6 ~27 sandstone 0  
fill ~51 ~6 ~29 ~52 ~6 ~29 sandstone 0 
setblock ~51 ~6 ~48 sandstone_stairs 7  
fill ~52 ~6 ~11 ~52 ~10 ~11 sandstone 0  
fill ~52 ~6 ~46 ~53 ~6 ~46 sandstone 0 
setblock ~53 ~6 ~12 leaves 6 
setblock ~53 ~6 ~45 planks 2 
setblock ~54 ~6 ~13 leaves 6 
setblock ~54 ~6 ~44 sandstone_stairs 6 
setblock ~55 ~6 ~14 leaves 6  
fill ~55 ~6 ~15 ~55 ~8 ~15 sandstone 0  
fill ~55 ~6 ~41 ~55 ~10 ~41 sandstone 0 
setblock ~55 ~6 ~42 sandstone_stairs 7 
setblock ~55 ~6 ~43 stone_slab 9  
fill ~56 ~6 ~16 ~56 ~7 ~16 planks 2  
fill ~56 ~6 ~17 ~56 ~6 ~16 planks 2  
fill ~56 ~6 ~18 ~56 ~7 ~18 spruce_fence 0 
setblock ~56 ~6 ~39 planks 2 
setblock ~56 ~6 ~41 planks 2  
fill ~57 ~6 ~20 ~57 ~7 ~20 spruce_fence 0 
setblock ~57 ~6 ~37 stone_slab 9 
setblock ~57 ~6 ~38 sandstone_stairs 6 
setblock ~58 ~6 ~21 planks 2  
fill ~58 ~6 ~23 ~58 ~7 ~23 sandstone 0 
setblock ~58 ~6 ~30 sandstone_stairs 7 
setblock ~58 ~6 ~31 stone_slab 9 
setblock ~58 ~6 ~32 sandstone_stairs 6 
setblock ~58 ~6 ~36 sandstone_stairs 7  
fill ~59 ~6 ~27 ~59 ~6 ~28 planks 2  
fill ~59 ~6 ~29 ~59 ~7 ~29 sandstone 2  
fill ~5 ~7 ~25 ~5 ~8 ~25 sandstone 0 
setblock ~6 ~7 ~19 planks 2 
setblock ~6 ~7 ~20 sandstone_stairs 7 
setblock ~6 ~7 ~21 stone_slab 9 
setblock ~6 ~7 ~22 sandstone_stairs 6 
setblock ~6 ~7 ~30 planks 2  
fill ~6 ~7 ~31 ~6 ~8 ~31 sandstone 0  
fill ~6 ~7 ~35 ~6 ~10 ~35 planks 2  
fill ~7 ~7 ~18 ~7 ~7 ~19 sandstone 0 
setblock ~7 ~7 ~35 sandstone 0 
setblock ~7 ~7 ~37 planks 2  
fill ~8 ~7 ~15 ~8 ~7 ~17 sandstone 0 
setblock ~9 ~7 ~14 sandstone 2 
setblock ~10 ~7 ~41 planks 2 
setblock ~10 ~7 ~43 planks 2  
fill ~11 ~7 ~10 ~11 ~8 ~10 sandstone 0  
fill ~12 ~7 ~9 ~12 ~8 ~9 sandstone 0  
fill ~12 ~7 ~24 ~13 ~7 ~24 sandstone 0  
fill ~12 ~7 ~30 ~13 ~7 ~30 sandstone 0  
fill ~13 ~7 ~8 ~14 ~7 ~8 sandstone 0  
fill ~13 ~7 ~20 ~14 ~7 ~20 sandstone 0  
fill ~13 ~7 ~34 ~14 ~7 ~34 sandstone 0  
fill ~14 ~7 ~18 ~15 ~7 ~18 sandstone 0  
fill ~14 ~7 ~36 ~15 ~7 ~36 sandstone 0  
fill ~15 ~7 ~17 ~16 ~7 ~17 sandstone 0  
fill ~15 ~7 ~37 ~16 ~7 ~37 sandstone 0  
fill ~16 ~7 ~15 ~17 ~7 ~15 sandstone 0  
fill ~16 ~7 ~39 ~17 ~7 ~39 sandstone 0  
fill ~17 ~7 ~5 ~17 ~8 ~5 planks 2  
fill ~17 ~7 ~6 ~17 ~9 ~6 planks 2  
fill ~17 ~7 ~14 ~18 ~7 ~14 sandstone 0  
fill ~17 ~7 ~40 ~18 ~7 ~40 sandstone 0  
fill ~18 ~7 ~5 ~18 ~8 ~5 sandstone 0  
fill ~18 ~7 ~13 ~19 ~7 ~13 sandstone 0  
fill ~18 ~7 ~41 ~19 ~7 ~41 sandstone 0  
fill ~19 ~7 ~4 ~21 ~7 ~4 sandstone 0  
fill ~19 ~7 ~12 ~21 ~7 ~12 sandstone 0  
fill ~19 ~7 ~42 ~21 ~7 ~42 sandstone 0  
fill ~19 ~7 ~54 ~19 ~7 ~55 stone_slab 7  
fill ~20 ~7 ~50 ~20 ~4 ~50 sandstone 0 
setblock ~20 ~7 ~55 stone_slab 7  
fill ~21 ~7 ~3 ~21 ~9 ~3 planks 2  
fill ~21 ~7 ~11 ~22 ~7 ~11 sandstone 0  
fill ~21 ~7 ~43 ~23 ~7 ~43 sandstone 0 
setblock ~21 ~7 ~50 planks 2  
fill ~21 ~7 ~51 ~21 ~27 ~51 sandstone 1  
fill ~21 ~7 ~56 ~22 ~7 ~56 stone_slab 7  
fill ~22 ~7 ~10 ~24 ~7 ~10 sandstone 0  
fill ~22 ~7 ~51 ~22 ~8 ~51 sandstone 0  
fill ~23 ~7 ~2 ~28 ~7 ~2 sandstone 0  
fill ~23 ~7 ~44 ~25 ~7 ~44 sandstone 0  
fill ~23 ~7 ~56 ~25 ~7 ~56 quartz_block 0  
fill ~24 ~7 ~9 ~28 ~7 ~9 sandstone 0  
fill ~25 ~7 ~45 ~41 ~7 ~45 sandstone 0  
fill ~26 ~7 ~52 ~28 ~7 ~52 sandstone 0  
fill ~26 ~7 ~57 ~27 ~7 ~57 quartz_block 0 
setblock ~28 ~7 ~1 planks 2  
fill ~28 ~7 ~8 ~35 ~7 ~8 sandstone 0  
fill ~28 ~7 ~53 ~30 ~7 ~53 stone_slab 1  
fill ~28 ~7 ~54 ~30 ~7 ~54 stone_slab 1  
fill ~28 ~7 ~55 ~30 ~7 ~55 stone_slab 1  
fill ~28 ~7 ~56 ~30 ~7 ~56 stone_slab 1  
fill ~28 ~7 ~57 ~30 ~7 ~57 stone_slab 15 
setblock ~30 ~7 ~1 sandstone 0  
fill ~31 ~7 ~1 ~33 ~7 ~1 planks 2  
fill ~31 ~7 ~50 ~40 ~7 ~50 sandstone 0  
fill ~31 ~7 ~51 ~35 ~7 ~51 sandstone 0  
fill ~31 ~7 ~52 ~34 ~7 ~52 sandstone 0  
fill ~31 ~7 ~53 ~33 ~7 ~53 sandstone 0  
fill ~31 ~7 ~54 ~32 ~7 ~54 sandstone 0  
fill ~31 ~7 ~55 ~31 ~7 ~50 sandstone 0  
fill ~31 ~7 ~56 ~36 ~7 ~56 planks 2  
fill ~31 ~7 ~57 ~34 ~7 ~57 stone_slab 1  
fill ~32 ~7 ~55 ~38 ~7 ~55 planks 2  
fill ~33 ~7 ~54 ~38 ~7 ~54 planks 2  
fill ~34 ~7 ~44 ~41 ~7 ~44 sandstone 0  
fill ~34 ~7 ~49 ~40 ~7 ~49 sandstone 0  
fill ~34 ~7 ~53 ~38 ~7 ~53 planks 2  
fill ~35 ~7 ~9 ~39 ~7 ~9 sandstone 0  
fill ~35 ~7 ~52 ~38 ~7 ~52 planks 2  
fill ~36 ~7 ~2 ~38 ~7 ~2 glowstone 0  
fill ~36 ~7 ~46 ~43 ~7 ~46 sandstone 0  
fill ~36 ~7 ~47 ~41 ~7 ~47 sandstone 0  
fill ~36 ~7 ~48 ~41 ~7 ~48 sandstone 0  
fill ~36 ~7 ~51 ~39 ~7 ~51 planks 2  
fill ~37 ~7 ~43 ~40 ~7 ~43 sandstone 0  
fill ~37 ~7 ~56 ~38 ~7 ~56 sandstone 0 
setblock ~39 ~7 ~2 sandstone 0  
fill ~39 ~7 ~10 ~41 ~7 ~10 sandstone 0 
setblock ~39 ~7 ~55 sandstone 0 
setblock ~40 ~7 ~2 sandstone 2  
fill ~40 ~7 ~3 ~40 ~17 ~3 sandstone 0 
setblock ~41 ~7 ~3 planks 2  
fill ~41 ~7 ~11 ~42 ~7 ~11 sandstone 0  
fill ~41 ~7 ~49 ~42 ~7 ~49 planks 2  
fill ~41 ~7 ~54 ~41 ~8 ~54 sandstone 0 
setblock ~42 ~7 ~3 double_stone_slab 1  
fill ~42 ~7 ~12 ~44 ~7 ~12 sandstone 0  
fill ~42 ~7 ~47 ~42 ~9 ~47 planks 2  
fill ~42 ~7 ~48 ~43 ~7 ~48 planks 2 
setblock ~42 ~7 ~54 planks 2  
fill ~43 ~7 ~4 ~44 ~7 ~4 double_stone_slab 1  
fill ~43 ~7 ~53 ~45 ~7 ~53 sandstone 0  
fill ~43 ~7 ~54 ~43 ~8 ~54 sandstone 0  
fill ~44 ~7 ~13 ~45 ~7 ~13 sandstone 0  
fill ~45 ~7 ~14 ~46 ~7 ~14 sandstone 0 
setblock ~45 ~7 ~52 sandstone 0 
setblock ~46 ~7 ~5 planks 2  
fill ~46 ~7 ~15 ~47 ~7 ~15 sandstone 0  
fill ~46 ~7 ~42 ~47 ~7 ~42 sandstone 0  
fill ~46 ~7 ~52 ~47 ~7 ~52 planks 2  
fill ~47 ~7 ~16 ~48 ~7 ~16 sandstone 0  
fill ~47 ~7 ~41 ~48 ~7 ~41 sandstone 0  
fill ~48 ~7 ~7 ~49 ~7 ~7 leaves 6  
fill ~48 ~7 ~18 ~49 ~7 ~18 sandstone 0  
fill ~48 ~7 ~39 ~49 ~7 ~39 sandstone 0 
setblock ~48 ~7 ~50 sandstone 2  
fill ~48 ~7 ~51 ~48 ~8 ~51 planks 2  
fill ~49 ~7 ~38 ~50 ~7 ~38 sandstone 0  
fill ~49 ~7 ~49 ~49 ~9 ~49 sandstone 0  
fill ~49 ~7 ~50 ~49 ~9 ~50 sandstone 0 
setblock ~50 ~7 ~8 leaves 6  
fill ~50 ~7 ~20 ~50 ~14 ~20 sandstone 0  
fill ~50 ~7 ~22 ~50 ~13 ~22 sandstone 0  
fill ~50 ~7 ~48 ~50 ~9 ~48 sandstone 0 
setblock ~50 ~7 ~49 sandstone 2  
fill ~51 ~7 ~27 ~52 ~7 ~27 sandstone 0  
fill ~51 ~7 ~29 ~52 ~7 ~29 sandstone 0  
fill ~51 ~7 ~47 ~52 ~7 ~47 sandstone 0  
fill ~51 ~7 ~48 ~51 ~9 ~48 planks 2  
fill ~52 ~7 ~10 ~52 ~9 ~10 sandstone 0  
fill ~52 ~7 ~46 ~53 ~7 ~46 sandstone 0  
fill ~53 ~7 ~12 ~53 ~8 ~12 spruce_fence 0  
fill ~53 ~7 ~45 ~54 ~7 ~45 sandstone 0  
fill ~54 ~7 ~43 ~55 ~7 ~43 sandstone 0 
setblock ~54 ~7 ~44 planks 2  
fill ~55 ~7 ~14 ~55 ~8 ~14 spruce_fence 0  
fill ~55 ~7 ~42 ~55 ~10 ~42 sandstone 0  
fill ~56 ~7 ~17 ~56 ~13 ~17 sandstone 0  
fill ~56 ~7 ~39 ~56 ~11 ~39 sandstone 0 
setblock ~56 ~7 ~41 sandstone 0  
fill ~57 ~7 ~36 ~58 ~7 ~36 sandstone 0  
fill ~57 ~7 ~37 ~57 ~7 ~36 sandstone 0 
setblock ~57 ~7 ~38 sandstone 2 
setblock ~58 ~7 ~21 sandstone 2 
setblock ~58 ~7 ~24 sandstone_stairs 7 
setblock ~58 ~7 ~25 stone_slab 9 
setblock ~58 ~7 ~26 sandstone_stairs 6  
fill ~58 ~7 ~30 ~58 ~11 ~30 sandstone 0 
setblock ~58 ~7 ~31 sandstone 2 
setblock ~58 ~7 ~32 sandstone 0 
setblock ~58 ~7 ~33 planks 2 
setblock ~58 ~7 ~35 sandstone 0  
fill ~59 ~7 ~27 ~59 ~8 ~27 sandstone 0  
fill ~59 ~7 ~28 ~59 ~7 ~27 sandstone 0 
setblock ~5 ~8 ~26 sandstone_stairs 7 
setblock ~5 ~8 ~27 stone_slab 9 
setblock ~5 ~8 ~28 sandstone_stairs 6 
setblock ~5 ~8 ~29 planks 2 
setblock ~6 ~8 ~19 sandstone 2  
fill ~6 ~8 ~20 ~6 ~10 ~20 sandstone 0  
fill ~6 ~8 ~21 ~6 ~8 ~24 sandstone 0  
fill ~6 ~8 ~30 ~6 ~9 ~30 sandstone 0 
setblock ~7 ~8 ~18 planks 2  
fill ~7 ~8 ~19 ~7 ~10 ~19 sandstone 0  
fill ~7 ~8 ~35 ~7 ~9 ~35 planks 2 
setblock ~7 ~8 ~37 sandstone 0  
fill ~8 ~8 ~15 ~8 ~9 ~15 sandstone 2  
fill ~8 ~8 ~16 ~8 ~9 ~16 sandstone 0  
fill ~8 ~8 ~17 ~8 ~16 ~17 sandstone 0 
setblock ~9 ~8 ~14 sandstone 0  
fill ~10 ~8 ~41 ~10 ~13 ~41 sandstone 0  
fill ~10 ~8 ~43 ~10 ~10 ~43 sandstone 0  
fill ~12 ~8 ~24 ~13 ~8 ~24 sandstone 0  
fill ~12 ~8 ~30 ~13 ~8 ~30 sandstone 0  
fill ~13 ~8 ~8 ~14 ~8 ~8 sandstone 0  
fill ~13 ~8 ~20 ~14 ~8 ~20 sandstone 0  
fill ~13 ~8 ~34 ~14 ~8 ~34 sandstone 0  
fill ~14 ~8 ~18 ~15 ~8 ~18 sandstone 0  
fill ~14 ~8 ~36 ~14 ~10 ~36 planks 2 
setblock ~14 ~8 ~47 planks 2 
setblock ~15 ~8 ~7 sandstone 0  
fill ~15 ~8 ~17 ~16 ~8 ~17 sandstone 0 
setblock ~15 ~8 ~36 sandstone 0  
fill ~15 ~8 ~37 ~15 ~10 ~37 planks 2 
setblock ~16 ~8 ~6 planks 2  
fill ~16 ~8 ~15 ~17 ~8 ~15 sandstone 0  
fill ~16 ~8 ~37 ~16 ~25 ~37 sandstone 0  
fill ~16 ~8 ~39 ~17 ~8 ~39 sandstone 0  
fill ~17 ~8 ~14 ~18 ~8 ~14 sandstone 0  
fill ~17 ~8 ~40 ~18 ~8 ~40 sandstone 0  
fill ~18 ~8 ~13 ~19 ~8 ~13 sandstone 0  
fill ~18 ~8 ~41 ~19 ~8 ~41 sandstone 0  
fill ~19 ~8 ~4 ~21 ~8 ~4 sandstone 0  
fill ~19 ~8 ~12 ~21 ~8 ~12 sandstone 0  
fill ~19 ~8 ~42 ~21 ~8 ~42 sandstone 0  
fill ~20 ~8 ~50 ~20 ~9 ~50 planks 2  
fill ~21 ~8 ~11 ~22 ~8 ~11 sandstone 0  
fill ~21 ~8 ~43 ~23 ~8 ~43 sandstone 0  
fill ~21 ~8 ~50 ~21 ~14 ~50 sandstone 0 
setblock ~22 ~8 ~3 planks 2  
fill ~22 ~8 ~10 ~24 ~8 ~10 sandstone 0  
fill ~23 ~8 ~2 ~25 ~8 ~2 glowstone 0  
fill ~23 ~8 ~44 ~25 ~8 ~44 sandstone 0  
fill ~24 ~8 ~9 ~28 ~8 ~9 sandstone 0  
fill ~25 ~8 ~45 ~34 ~8 ~45 sandstone 0  
fill ~26 ~8 ~2 ~26 ~10 ~2 planks 2 
setblock ~26 ~8 ~52 planks 2  
fill ~27 ~8 ~52 ~27 ~28 ~52 sandstone 1 
setblock ~28 ~8 ~1 sandstone 0  
fill ~28 ~8 ~8 ~35 ~8 ~8 sandstone 0 
setblock ~28 ~8 ~52 planks 2  
fill ~28 ~8 ~57 ~30 ~8 ~57 stone_slab 7  
fill ~30 ~8 ~1 ~32 ~8 ~1 glowstone 0  
fill ~31 ~8 ~57 ~34 ~8 ~57 quartz_block 0  
fill ~33 ~8 ~52 ~34 ~8 ~52 sandstone 0  
fill ~34 ~8 ~1 ~35 ~8 ~1 double_stone_slab 1  
fill ~34 ~8 ~44 ~37 ~8 ~44 sandstone 0  
fill ~34 ~8 ~53 ~37 ~8 ~53 stone_slab 1  
fill ~34 ~8 ~54 ~37 ~8 ~54 stone_slab 1  
fill ~34 ~8 ~55 ~37 ~8 ~55 stone_slab 1  
fill ~34 ~8 ~56 ~34 ~8 ~53 stone_slab 1  
fill ~35 ~8 ~2 ~36 ~8 ~2 double_stone_slab 1  
fill ~35 ~8 ~9 ~39 ~8 ~9 sandstone 0  
fill ~35 ~8 ~51 ~35 ~16 ~51 sandstone 0  
fill ~35 ~8 ~52 ~35 ~9 ~52 planks 2  
fill ~35 ~8 ~56 ~37 ~8 ~56 stone_slab 15  
fill ~36 ~8 ~51 ~44 ~8 ~51 planks 2  
fill ~36 ~8 ~52 ~37 ~8 ~52 stone_slab 1  
fill ~37 ~8 ~2 ~38 ~8 ~2 sandstone 0  
fill ~37 ~8 ~43 ~48 ~8 ~43 sandstone 0  
fill ~37 ~8 ~49 ~39 ~8 ~49 sandstone 0  
fill ~37 ~8 ~50 ~37 ~8 ~49 sandstone 0  
fill ~38 ~8 ~48 ~40 ~8 ~48 sandstone 0  
fill ~38 ~8 ~50 ~44 ~8 ~50 planks 2  
fill ~38 ~8 ~52 ~43 ~8 ~52 planks 2  
fill ~38 ~8 ~53 ~41 ~8 ~53 planks 2  
fill ~38 ~8 ~54 ~40 ~8 ~54 planks 2  
fill ~38 ~8 ~55 ~38 ~8 ~50 planks 2 
setblock ~38 ~8 ~56 stone_slab 1 
setblock ~39 ~8 ~2 planks 2  
fill ~39 ~8 ~10 ~41 ~8 ~10 sandstone 0  
fill ~39 ~8 ~42 ~47 ~8 ~42 sandstone 0  
fill ~39 ~8 ~55 ~41 ~8 ~55 stone_slab 1  
fill ~40 ~8 ~2 ~40 ~9 ~2 sandstone 0 
setblock ~40 ~8 ~47 sandstone 0  
fill ~40 ~8 ~49 ~43 ~8 ~49 planks 2 
setblock ~41 ~8 ~3 sandstone 0  
fill ~41 ~8 ~11 ~42 ~8 ~11 sandstone 0  
fill ~41 ~8 ~41 ~42 ~8 ~41 sandstone 0  
fill ~41 ~8 ~44 ~48 ~8 ~44 sandstone 0  
fill ~41 ~8 ~45 ~47 ~8 ~45 sandstone 0  
fill ~41 ~8 ~46 ~41 ~8 ~41 sandstone 0  
fill ~41 ~8 ~47 ~41 ~8 ~53 planks 2 
setblock ~42 ~8 ~3 leaves 6  
fill ~42 ~8 ~12 ~44 ~8 ~12 sandstone 0 
setblock ~42 ~8 ~40 sandstone 0  
fill ~42 ~8 ~46 ~44 ~8 ~46 planks 2  
fill ~42 ~8 ~48 ~44 ~8 ~48 planks 2 
setblock ~42 ~8 ~53 sandstone 0 
setblock ~42 ~8 ~54 stone_slab 1  
fill ~43 ~8 ~4 ~44 ~8 ~4 leaves 6  
fill ~43 ~8 ~39 ~43 ~12 ~39 planks 2  
fill ~43 ~8 ~40 ~44 ~8 ~40 planks 2  
fill ~43 ~8 ~41 ~45 ~8 ~41 planks 2  
fill ~43 ~8 ~47 ~45 ~8 ~47 planks 2 
setblock ~43 ~8 ~53 planks 2  
fill ~44 ~8 ~13 ~45 ~8 ~13 sandstone 0  
fill ~44 ~8 ~52 ~44 ~8 ~53 sandstone 0  
fill ~45 ~8 ~14 ~46 ~8 ~14 sandstone 0  
fill ~45 ~8 ~46 ~46 ~8 ~46 sandstone 0  
fill ~45 ~8 ~51 ~45 ~9 ~51 sandstone 0  
fill ~45 ~8 ~52 ~47 ~8 ~52 planks 2  
fill ~45 ~8 ~53 ~45 ~8 ~52 planks 2  
fill ~46 ~8 ~5 ~46 ~9 ~5 sandstone 2  
fill ~46 ~8 ~15 ~47 ~8 ~15 sandstone 0  
fill ~47 ~8 ~6 ~47 ~9 ~6 sandstone 2  
fill ~47 ~8 ~16 ~48 ~8 ~16 sandstone 0  
fill ~47 ~8 ~41 ~48 ~8 ~41 sandstone 0 
setblock ~47 ~8 ~51 planks 2  
fill ~48 ~8 ~7 ~48 ~9 ~7 spruce_fence 0  
fill ~48 ~8 ~18 ~49 ~8 ~18 sandstone 0  
fill ~48 ~8 ~39 ~49 ~8 ~39 sandstone 0  
fill ~48 ~8 ~50 ~48 ~9 ~50 sandstone 0  
fill ~49 ~8 ~38 ~50 ~8 ~38 sandstone 0  
fill ~50 ~8 ~8 ~50 ~9 ~8 spruce_fence 0  
fill ~50 ~8 ~21 ~50 ~14 ~21 sandstone 0  
fill ~50 ~8 ~49 ~50 ~9 ~49 sandstone 0  
fill ~51 ~8 ~22 ~51 ~13 ~22 sandstone 0  
fill ~51 ~8 ~27 ~52 ~8 ~27 sandstone 0  
fill ~51 ~8 ~29 ~52 ~8 ~29 sandstone 0  
fill ~51 ~8 ~47 ~52 ~8 ~47 planks 2  
fill ~52 ~8 ~46 ~53 ~8 ~46 sandstone 0  
fill ~53 ~8 ~11 ~53 ~9 ~11 sandstone 0  
fill ~53 ~8 ~45 ~53 ~10 ~45 sandstone 0  
fill ~54 ~8 ~43 ~54 ~10 ~43 sandstone 0  
fill ~54 ~8 ~44 ~54 ~9 ~44 sandstone 0 
setblock ~54 ~8 ~45 planks 2 
setblock ~55 ~8 ~43 sandstone 2  
fill ~56 ~8 ~16 ~56 ~9 ~16 sandstone 0 
setblock ~56 ~8 ~40 sandstone 0 
setblock ~56 ~8 ~41 planks 2 
setblock ~57 ~8 ~18 sandstone_stairs 7 
setblock ~57 ~8 ~19 stone_slab 9 
setblock ~57 ~8 ~20 sandstone_stairs 6  
fill ~57 ~8 ~36 ~58 ~8 ~36 sandstone 0 
setblock ~57 ~8 ~37 planks 2  
fill ~57 ~8 ~38 ~57 ~8 ~39 sandstone 0 
setblock ~58 ~8 ~21 sandstone 0 
setblock ~58 ~8 ~23 sandstone 2  
fill ~58 ~8 ~24 ~58 ~9 ~24 sandstone 0  
fill ~58 ~8 ~25 ~58 ~12 ~25 sandstone 0  
fill ~58 ~8 ~26 ~58 ~8 ~24 sandstone 0 
setblock ~58 ~8 ~29 sandstone 2 
setblock ~58 ~8 ~31 sandstone 0  
fill ~58 ~8 ~32 ~58 ~10 ~32 planks 2  
fill ~58 ~8 ~33 ~58 ~9 ~33 sandstone 0 
setblock ~58 ~8 ~35 planks 2  
fill ~59 ~8 ~28 ~59 ~10 ~28 planks 2  
fill ~59 ~8 ~29 ~59 ~9 ~29 sandstone 0  
fill ~5 ~9 ~25 ~5 ~10 ~25 sandstone 2  
fill ~5 ~9 ~26 ~5 ~11 ~26 sandstone 0  
fill ~5 ~9 ~27 ~5 ~10 ~27 sandstone 0  
fill ~5 ~9 ~28 ~5 ~9 ~29 sandstone 0 
setblock ~6 ~9 ~19 sandstone 0  
fill ~6 ~9 ~21 ~6 ~9 ~23 planks 2 
setblock ~6 ~9 ~31 sandstone 2 
setblock ~6 ~9 ~32 sandstone_stairs 7 
setblock ~6 ~9 ~33 stone_slab 9 
setblock ~6 ~9 ~34 sandstone_stairs 6 
setblock ~7 ~9 ~18 sandstone 0 
setblock ~7 ~9 ~37 planks 2  
fill ~9 ~9 ~13 ~9 ~10 ~13 sandstone 0 
setblock ~9 ~9 ~14 sandstone 2 
setblock ~9 ~9 ~41 sandstone 0  
fill ~10 ~9 ~12 ~10 ~10 ~12 sandstone 0 
setblock ~11 ~9 ~10 glowstone 0 
setblock ~12 ~9 ~9 glowstone 0  
fill ~12 ~9 ~24 ~13 ~9 ~24 sandstone 0  
fill ~12 ~9 ~30 ~13 ~9 ~30 sandstone 0 
setblock ~13 ~9 ~8 glowstone 0  
fill ~13 ~9 ~20 ~14 ~9 ~20 sandstone 0  
fill ~13 ~9 ~34 ~14 ~9 ~34 sandstone 0  
fill ~14 ~9 ~8 ~14 ~15 ~8 sandstone 0  
fill ~14 ~9 ~18 ~15 ~9 ~18 sandstone 0 
setblock ~14 ~9 ~47 sandstone 0 
setblock ~15 ~9 ~7 planks 2  
fill ~15 ~9 ~17 ~16 ~9 ~17 sandstone 0 
setblock ~15 ~9 ~36 planks 2  
fill ~16 ~9 ~6 ~16 ~9 ~7 sandstone 2  
fill ~16 ~9 ~15 ~17 ~9 ~15 sandstone 0  
fill ~16 ~9 ~39 ~17 ~9 ~39 sandstone 0  
fill ~16 ~9 ~47 ~16 ~9 ~48 sandstone 2  
fill ~17 ~9 ~5 ~18 ~9 ~5 glowstone 0  
fill ~17 ~9 ~14 ~18 ~9 ~14 sandstone 0  
fill ~17 ~9 ~40 ~18 ~9 ~40 sandstone 0  
fill ~18 ~9 ~13 ~19 ~9 ~13 sandstone 0  
fill ~18 ~9 ~41 ~19 ~9 ~41 sandstone 0 
setblock ~19 ~9 ~4 glowstone 0  
fill ~19 ~9 ~12 ~21 ~9 ~12 sandstone 0  
fill ~19 ~9 ~42 ~21 ~9 ~42 sandstone 0  
fill ~20 ~9 ~4 ~21 ~9 ~4 sandstone 0  
fill ~21 ~9 ~11 ~22 ~9 ~11 sandstone 0  
fill ~21 ~9 ~43 ~23 ~9 ~43 sandstone 0 
setblock ~22 ~9 ~3 sandstone 0  
fill ~22 ~9 ~10 ~24 ~9 ~10 sandstone 0 
setblock ~22 ~9 ~51 planks 2  
fill ~23 ~9 ~2 ~24 ~9 ~2 sandstone 0  
fill ~23 ~9 ~44 ~25 ~9 ~44 sandstone 0  
fill ~24 ~9 ~9 ~28 ~9 ~9 sandstone 0 
setblock ~25 ~9 ~2 planks 2  
fill ~25 ~9 ~45 ~34 ~9 ~45 sandstone 0 
setblock ~26 ~9 ~52 sandstone 0 
setblock ~27 ~9 ~2 planks 2  
fill ~28 ~9 ~1 ~28 ~11 ~1 planks 2  
fill ~28 ~9 ~8 ~35 ~9 ~8 sandstone 0 
setblock ~28 ~9 ~52 sandstone 0  
fill ~30 ~9 ~1 ~31 ~9 ~1 sandstone 0 
setblock ~32 ~9 ~1 planks 2  
fill ~33 ~9 ~52 ~33 ~13 ~52 sandstone 0 
setblock ~34 ~9 ~1 planks 2  
fill ~34 ~9 ~44 ~37 ~9 ~44 sandstone 0  
fill ~34 ~9 ~52 ~34 ~29 ~52 sandstone 1  
fill ~35 ~9 ~1 ~35 ~9 ~2 sandstone 0  
fill ~35 ~9 ~9 ~39 ~9 ~9 sandstone 0  
fill ~35 ~9 ~56 ~37 ~9 ~56 stone_slab 7  
fill ~36 ~9 ~2 ~37 ~9 ~2 leaves 14  
fill ~37 ~9 ~43 ~39 ~9 ~43 sandstone 0 
setblock ~38 ~9 ~2 leaves 6 
setblock ~38 ~9 ~56 quartz_block 0  
fill ~39 ~9 ~2 ~39 ~11 ~2 sandstone 0  
fill ~39 ~9 ~10 ~41 ~9 ~10 sandstone 0  
fill ~39 ~9 ~42 ~40 ~9 ~42 sandstone 0  
fill ~39 ~9 ~50 ~41 ~9 ~50 planks 2  
fill ~39 ~9 ~51 ~39 ~11 ~51 planks 2  
fill ~39 ~9 ~55 ~41 ~9 ~55 quartz_block 0  
fill ~40 ~9 ~41 ~41 ~9 ~41 sandstone 0  
fill ~40 ~9 ~51 ~44 ~9 ~51 stone_slab 1  
fill ~40 ~9 ~52 ~44 ~9 ~52 stone_slab 1 
setblock ~41 ~9 ~3 planks 2  
fill ~41 ~9 ~11 ~42 ~9 ~11 sandstone 0  
fill ~41 ~9 ~49 ~46 ~9 ~49 planks 2  
fill ~41 ~9 ~53 ~43 ~9 ~53 stone_slab 1  
fill ~42 ~9 ~3 ~42 ~10 ~3 spruce_fence 0  
fill ~42 ~9 ~12 ~44 ~9 ~12 sandstone 0  
fill ~42 ~9 ~40 ~46 ~9 ~40 planks 2  
fill ~42 ~9 ~41 ~42 ~11 ~41 planks 2  
fill ~42 ~9 ~46 ~45 ~9 ~46 planks 2  
fill ~42 ~9 ~50 ~43 ~9 ~50 stone_slab 1 
setblock ~42 ~9 ~54 quartz_block 0  
fill ~43 ~9 ~38 ~45 ~9 ~38 planks 2  
fill ~43 ~9 ~47 ~46 ~9 ~47 planks 2  
fill ~43 ~9 ~48 ~46 ~9 ~48 planks 2 
setblock ~43 ~9 ~54 stone_slab 15  
fill ~44 ~9 ~4 ~44 ~10 ~4 spruce_fence 0  
fill ~44 ~9 ~5 ~44 ~10 ~5 sandstone 0  
fill ~44 ~9 ~13 ~45 ~9 ~13 sandstone 0  
fill ~44 ~9 ~37 ~51 ~9 ~37 sandstone 0  
fill ~44 ~9 ~39 ~46 ~9 ~39 planks 2 
setblock ~44 ~9 ~45 planks 2  
fill ~44 ~9 ~50 ~45 ~9 ~50 planks 2  
fill ~44 ~9 ~53 ~45 ~9 ~53 stone_slab 15  
fill ~45 ~9 ~14 ~46 ~9 ~14 sandstone 0  
fill ~45 ~9 ~36 ~50 ~9 ~36 sandstone 0  
fill ~45 ~9 ~45 ~49 ~9 ~45 sandstone 0 
setblock ~45 ~9 ~52 double_stone_slab 1  
fill ~46 ~9 ~15 ~47 ~9 ~15 sandstone 0  
fill ~46 ~9 ~35 ~46 ~33 ~35 sandstone 0  
fill ~46 ~9 ~38 ~52 ~9 ~38 sandstone 0 
setblock ~46 ~9 ~41 planks 2  
fill ~46 ~9 ~42 ~50 ~9 ~42 sandstone 0  
fill ~46 ~9 ~44 ~48 ~9 ~44 sandstone 0  
fill ~46 ~9 ~46 ~50 ~9 ~46 sandstone 0  
fill ~46 ~9 ~50 ~49 ~9 ~50 sandstone 0  
fill ~46 ~9 ~51 ~47 ~9 ~51 sandstone 0  
fill ~46 ~9 ~52 ~47 ~9 ~52 stone_slab 1  
fill ~47 ~9 ~16 ~48 ~9 ~16 sandstone 0  
fill ~47 ~9 ~39 ~51 ~9 ~39 sandstone 0  
fill ~47 ~9 ~40 ~47 ~9 ~42 sandstone 0  
fill ~47 ~9 ~47 ~51 ~9 ~47 sandstone 0  
fill ~47 ~9 ~48 ~50 ~9 ~48 sandstone 0  
fill ~47 ~9 ~49 ~50 ~9 ~49 sandstone 0  
fill ~48 ~9 ~18 ~49 ~9 ~18 sandstone 0  
fill ~48 ~9 ~41 ~50 ~9 ~41 sandstone 0  
fill ~48 ~9 ~43 ~49 ~9 ~43 sandstone 0 
setblock ~48 ~9 ~51 stone_slab 1  
fill ~49 ~9 ~40 ~51 ~9 ~40 sandstone 0  
fill ~51 ~9 ~27 ~52 ~9 ~27 sandstone 0  
fill ~51 ~9 ~29 ~52 ~9 ~29 sandstone 0  
fill ~52 ~9 ~46 ~53 ~9 ~46 sandstone 0 
setblock ~52 ~9 ~47 planks 2 
setblock ~53 ~9 ~12 sandstone_stairs 7 
setblock ~54 ~9 ~13 stone_slab 9 
setblock ~54 ~9 ~45 sandstone 0 
setblock ~55 ~9 ~14 sandstone_stairs 6 
setblock ~55 ~9 ~15 sandstone 2  
fill ~55 ~9 ~43 ~55 ~10 ~43 sandstone 0 
setblock ~56 ~9 ~18 sandstone 0 
setblock ~56 ~9 ~40 planks 2 
setblock ~56 ~9 ~41 sandstone 0  
fill ~57 ~9 ~18 ~57 ~11 ~18 planks 2  
fill ~57 ~9 ~19 ~57 ~9 ~18 planks 2 
setblock ~57 ~9 ~20 sandstone 0  
fill ~57 ~9 ~36 ~57 ~11 ~36 sandstone 0  
fill ~57 ~9 ~37 ~57 ~9 ~38 sandstone 2  
fill ~57 ~9 ~39 ~57 ~10 ~39 sandstone 0  
fill ~58 ~9 ~21 ~58 ~11 ~21 sandstone 2  
fill ~58 ~9 ~22 ~58 ~9 ~21 sandstone 2  
fill ~58 ~9 ~23 ~58 ~11 ~23 planks 2 
setblock ~58 ~9 ~26 sandstone 2  
fill ~58 ~9 ~29 ~58 ~12 ~29 sandstone 0  
fill ~58 ~9 ~31 ~58 ~10 ~31 planks 2 
setblock ~58 ~9 ~35 sandstone 0 
setblock ~58 ~9 ~36 planks 2  
fill ~59 ~9 ~27 ~59 ~11 ~27 planks 2 
setblock ~5 ~10 ~28 sandstone 2 
setblock ~5 ~10 ~29 planks 2  
fill ~6 ~10 ~19 ~6 ~11 ~19 planks 2 
setblock ~6 ~10 ~21 sandstone 0 
setblock ~6 ~10 ~22 planks 2  
fill ~6 ~10 ~23 ~6 ~12 ~23 sandstone 0 
setblock ~6 ~10 ~30 sandstone 2  
fill ~6 ~10 ~31 ~6 ~10 ~32 sandstone 0  
fill ~6 ~10 ~33 ~6 ~10 ~35 planks 2  
fill ~7 ~10 ~18 ~7 ~12 ~18 planks 2  
fill ~7 ~10 ~35 ~7 ~12 ~35 sandstone 0  
fill ~7 ~10 ~37 ~7 ~11 ~37 sandstone 0  
fill ~8 ~10 ~15 ~8 ~10 ~16 glowstone 0 
setblock ~8 ~10 ~38 sandstone_stairs 7 
setblock ~8 ~10 ~39 stone_slab 9 
setblock ~9 ~10 ~14 glowstone 0 
setblock ~9 ~10 ~40 sandstone_stairs 6 
setblock ~9 ~10 ~41 sandstone 2 
setblock ~11 ~10 ~10 sandstone 0 
setblock ~11 ~10 ~11 sandstone 2 
setblock ~12 ~10 ~9 sandstone 2  
fill ~12 ~10 ~24 ~13 ~10 ~24 sandstone 0  
fill ~12 ~10 ~30 ~13 ~10 ~30 sandstone 0 
setblock ~13 ~10 ~8 planks 2  
fill ~13 ~10 ~20 ~14 ~10 ~20 sandstone 0  
fill ~13 ~10 ~34 ~14 ~10 ~34 sandstone 0  
fill ~14 ~10 ~18 ~15 ~10 ~18 sandstone 0  
fill ~14 ~10 ~47 ~14 ~11 ~47 planks 2 
setblock ~15 ~10 ~7 sandstone 2  
fill ~15 ~10 ~17 ~15 ~21 ~17 sandstone 0  
fill ~15 ~10 ~36 ~15 ~25 ~36 sandstone 0  
fill ~16 ~10 ~6 ~17 ~10 ~6 sandstone 0  
fill ~16 ~10 ~7 ~16 ~12 ~7 sandstone 0  
fill ~16 ~10 ~15 ~17 ~10 ~15 sandstone 0  
fill ~16 ~10 ~39 ~17 ~10 ~39 sandstone 0  
fill ~16 ~10 ~47 ~16 ~11 ~47 sandstone 0  
fill ~16 ~10 ~48 ~16 ~14 ~48 sandstone 2  
fill ~17 ~10 ~5 ~17 ~11 ~5 planks 2  
fill ~17 ~10 ~14 ~18 ~10 ~14 sandstone 0  
fill ~17 ~10 ~40 ~18 ~10 ~40 sandstone 0  
fill ~18 ~10 ~5 ~18 ~11 ~5 sandstone 0  
fill ~18 ~10 ~13 ~19 ~10 ~13 sandstone 0  
fill ~18 ~10 ~41 ~19 ~10 ~41 sandstone 0  
fill ~19 ~10 ~4 ~19 ~11 ~4 sandstone 0  
fill ~19 ~10 ~12 ~21 ~10 ~12 sandstone 0  
fill ~19 ~10 ~42 ~21 ~10 ~42 sandstone 0 
setblock ~20 ~10 ~4 double_stone_slab 1  
fill ~20 ~10 ~50 ~20 ~13 ~50 sandstone 0 
setblock ~21 ~10 ~3 sandstone 2  
fill ~21 ~10 ~4 ~21 ~19 ~4 sandstone 0  
fill ~21 ~10 ~11 ~22 ~10 ~11 sandstone 0  
fill ~21 ~10 ~43 ~23 ~10 ~43 sandstone 0 
setblock ~22 ~10 ~3 double_stone_slab 1  
fill ~22 ~10 ~10 ~24 ~10 ~10 sandstone 0  
fill ~22 ~10 ~51 ~22 ~16 ~51 sandstone 0 
setblock ~23 ~10 ~2 double_stone_slab 1  
fill ~23 ~10 ~44 ~25 ~10 ~44 sandstone 0  
fill ~24 ~10 ~2 ~25 ~10 ~2 sandstone 0  
fill ~24 ~10 ~9 ~28 ~10 ~9 sandstone 0  
fill ~25 ~10 ~45 ~34 ~10 ~45 sandstone 0 
setblock ~26 ~10 ~52 planks 2 
setblock ~27 ~10 ~2 sandstone 0  
fill ~28 ~10 ~8 ~32 ~10 ~8 sandstone 0 
setblock ~28 ~10 ~52 planks 2  
fill ~30 ~10 ~1 ~32 ~10 ~1 leaves 6  
fill ~33 ~10 ~8 ~34 ~10 ~8 sandstone 2 
setblock ~34 ~10 ~1 sandstone 0  
fill ~34 ~10 ~44 ~37 ~10 ~44 sandstone 0  
fill ~35 ~10 ~1 ~35 ~12 ~1 planks 2  
fill ~35 ~10 ~2 ~35 ~17 ~2 sandstone 0  
fill ~35 ~10 ~8 ~35 ~17 ~8 sandstone 0  
fill ~35 ~10 ~9 ~39 ~10 ~9 sandstone 0  
fill ~35 ~10 ~52 ~35 ~13 ~52 sandstone 0  
fill ~36 ~10 ~2 ~36 ~11 ~2 spruce_fence 0  
fill ~37 ~10 ~43 ~39 ~10 ~43 sandstone 0  
fill ~38 ~10 ~2 ~38 ~11 ~2 spruce_fence 0  
fill ~39 ~10 ~10 ~41 ~10 ~10 sandstone 0  
fill ~39 ~10 ~42 ~40 ~10 ~42 sandstone 0  
fill ~39 ~10 ~50 ~39 ~11 ~50 planks 2 
setblock ~40 ~10 ~2 sandstone 2  
fill ~40 ~10 ~41 ~41 ~10 ~41 sandstone 0  
fill ~40 ~10 ~50 ~40 ~30 ~50 sandstone 1 
setblock ~41 ~10 ~3 sandstone 0  
fill ~41 ~10 ~11 ~42 ~10 ~11 sandstone 0  
fill ~41 ~10 ~49 ~41 ~11 ~49 planks 2  
fill ~41 ~10 ~50 ~41 ~12 ~50 planks 2  
fill ~42 ~10 ~12 ~44 ~10 ~12 sandstone 0  
fill ~42 ~10 ~40 ~43 ~10 ~40 planks 2  
fill ~43 ~10 ~38 ~44 ~10 ~38 planks 2 
setblock ~43 ~10 ~54 stone_slab 7  
fill ~44 ~10 ~13 ~45 ~10 ~13 sandstone 0  
fill ~44 ~10 ~37 ~45 ~10 ~37 sandstone 0  
fill ~44 ~10 ~47 ~45 ~10 ~47 planks 2  
fill ~44 ~10 ~53 ~45 ~10 ~53 stone_slab 7  
fill ~45 ~10 ~5 ~45 ~11 ~5 planks 2  
fill ~45 ~10 ~14 ~46 ~10 ~14 sandstone 0  
fill ~45 ~10 ~35 ~45 ~33 ~35 sandstone 0  
fill ~45 ~10 ~36 ~45 ~33 ~36 sandstone 0  
fill ~45 ~10 ~46 ~46 ~10 ~46 planks 2 
setblock ~46 ~10 ~5 sandstone 0  
fill ~46 ~10 ~6 ~47 ~10 ~6 planks 2  
fill ~46 ~10 ~15 ~47 ~10 ~15 sandstone 0  
fill ~46 ~10 ~32 ~53 ~10 ~32 sandstone 0  
fill ~46 ~10 ~33 ~53 ~10 ~33 sandstone 0   
fill ~46 ~10 ~34 ~53 ~10 ~34 sandstone 0  
fill ~46 ~10 ~45 ~48 ~10 ~45 planks 2  
fill ~46 ~10 ~47 ~50 ~10 ~47 stone_slab 1  
fill ~46 ~10 ~48 ~50 ~10 ~48 stone_slab 1  
fill ~46 ~10 ~52 ~47 ~10 ~52 quartz_block 0  
fill ~47 ~10 ~16 ~48 ~10 ~16 sandstone 0  
fill ~47 ~10 ~30 ~51 ~10 ~30 sandstone 0  
fill ~47 ~10 ~31 ~53 ~10 ~31 sandstone 0  
fill ~47 ~10 ~35 ~53 ~10 ~35 sandstone 0  
fill ~47 ~10 ~41 ~48 ~10 ~41 sandstone 0  
fill ~47 ~10 ~42 ~48 ~10 ~42 sandstone 0  
fill ~47 ~10 ~43 ~48 ~10 ~43 sandstone 0  
fill ~47 ~10 ~46 ~49 ~10 ~46 stone_slab 1  
fill ~47 ~10 ~49 ~49 ~10 ~49 stone_slab 1 
setblock ~48 ~10 ~7 sandstone_stairs 5  
fill ~48 ~10 ~18 ~49 ~10 ~18 sandstone 0  
fill ~48 ~10 ~36 ~53 ~10 ~36 sandstone 0  
fill ~48 ~10 ~44 ~53 ~10 ~44 sandstone 0 
setblock ~48 ~10 ~50 stone_slab 1 
setblock ~48 ~10 ~51 quartz_block 0 
setblock ~49 ~10 ~7 stone_slab 9  
fill ~49 ~10 ~38 ~50 ~10 ~38 sandstone 0  
fill ~49 ~10 ~39 ~52 ~10 ~39 sandstone 0  
fill ~49 ~10 ~40 ~54 ~10 ~40 sandstone 0  
fill ~49 ~10 ~41 ~51 ~10 ~41 planks 2  
fill ~49 ~10 ~42 ~51 ~10 ~42 planks 2  
fill ~49 ~10 ~43 ~51 ~10 ~43 planks 2  
fill ~49 ~10 ~45 ~53 ~10 ~45 sandstone 0 
setblock ~49 ~10 ~50 stone_slab 15 
setblock ~50 ~10 ~8 sandstone_stairs 6  
fill ~50 ~10 ~46 ~52 ~10 ~46 sandstone 0 
setblock ~50 ~10 ~49 stone_slab 15  
fill ~51 ~10 ~27 ~52 ~10 ~27 sandstone 0  
fill ~51 ~10 ~29 ~52 ~10 ~29 sandstone 0  
fill ~51 ~10 ~37 ~52 ~10 ~37 sandstone 0 
setblock ~51 ~10 ~47 sandstone 0 
setblock ~51 ~10 ~48 stone_slab 15  
fill ~52 ~10 ~10 ~52 ~11 ~10 planks 2  
fill ~52 ~10 ~38 ~52 ~11 ~38 sandstone 0  
fill ~52 ~10 ~41 ~55 ~10 ~41 sandstone 0  
fill ~52 ~10 ~42 ~55 ~10 ~42 sandstone 0  
fill ~52 ~10 ~43 ~55 ~10 ~43 sandstone 0 
setblock ~52 ~10 ~47 stone_slab 1  
fill ~53 ~10 ~11 ~53 ~11 ~11 planks 2  
fill ~53 ~10 ~12 ~53 ~14 ~12 sandstone 0  
fill ~53 ~10 ~13 ~53 ~14 ~13 sandstone 0 
setblock ~53 ~10 ~46 stone_slab 1 
setblock ~54 ~10 ~13 planks 2 
setblock ~54 ~10 ~14 sandstone 0  
fill ~54 ~10 ~44 ~54 ~10 ~45 stone_slab 1  
fill ~55 ~10 ~14 ~55 ~10 ~15 planks 2 
setblock ~56 ~10 ~16 planks 2 
setblock ~56 ~10 ~18 planks 2 
setblock ~56 ~10 ~40 sandstone 0 
setblock ~56 ~10 ~41 planks 2  
fill ~57 ~10 ~19 ~57 ~13 ~19 sandstone 0 
setblock ~57 ~10 ~20 planks 2 
setblock ~57 ~10 ~37 planks 2 
setblock ~57 ~10 ~38 sandstone 0 
setblock ~58 ~10 ~22 planks 2 
setblock ~58 ~10 ~24 planks 2  
fill ~58 ~10 ~26 ~58 ~12 ~26 sandstone 0  
fill ~58 ~10 ~33 ~58 ~11 ~33 planks 2 
setblock ~58 ~10 ~35 sandstone 2  
fill ~58 ~10 ~36 ~58 ~11 ~36 sandstone 0 
setblock ~59 ~10 ~29 planks 2  
fill ~5 ~11 ~25 ~5 ~13 ~25 sandstone 0 
setblock ~5 ~11 ~27 sandstone 2 
setblock ~5 ~11 ~28 sandstone 0 
setblock ~5 ~11 ~29 sandstone 2  
fill ~6 ~11 ~20 ~6 ~11 ~22 glowstone 0  
fill ~6 ~11 ~30 ~6 ~14 ~30 sandstone 0 
setblock ~6 ~11 ~31 sandstone 2  
fill ~6 ~11 ~32 ~6 ~11 ~33 sandstone 0 
setblock ~6 ~11 ~34 planks 2 
setblock ~6 ~11 ~35 sandstone 0 
setblock ~7 ~11 ~19 planks 2  
fill ~8 ~11 ~15 ~8 ~12 ~15 sandstone 0  
fill ~8 ~11 ~16 ~8 ~11 ~15 sandstone 0 
setblock ~8 ~11 ~38 sandstone 0  
fill ~8 ~11 ~39 ~8 ~13 ~39 planks 2  
fill ~9 ~11 ~13 ~9 ~11 ~14 sandstone 2  
fill ~9 ~11 ~40 ~9 ~13 ~40 sandstone 0  
fill ~9 ~11 ~41 ~9 ~11 ~40 sandstone 0 
setblock ~10 ~11 ~12 planks 2 
setblock ~10 ~11 ~43 sandstone 2 
setblock ~11 ~11 ~10 sandstone 2 
setblock ~11 ~11 ~11 planks 2 
setblock ~11 ~11 ~44 sandstone_stairs 7  
fill ~12 ~11 ~9 ~12 ~12 ~9 sandstone 0  
fill ~12 ~11 ~24 ~13 ~11 ~24 sandstone 0  
fill ~12 ~11 ~30 ~13 ~11 ~30 sandstone 0 
setblock ~12 ~11 ~45 stone_slab 9 
setblock ~13 ~11 ~8 sandstone 2  
fill ~13 ~11 ~20 ~14 ~11 ~20 sandstone 0  
fill ~13 ~11 ~34 ~14 ~11 ~34 sandstone 0 
setblock ~13 ~11 ~46 sandstone_stairs 4  
fill ~14 ~11 ~7 ~15 ~11 ~7 double_stone_slab 1  
fill ~14 ~11 ~18 ~15 ~11 ~18 sandstone 0  
fill ~14 ~11 ~36 ~14 ~25 ~36 sandstone 0  
fill ~15 ~11 ~37 ~15 ~25 ~37 sandstone 0  
fill ~16 ~11 ~6 ~17 ~11 ~6 sandstone 0  
fill ~16 ~11 ~15 ~17 ~11 ~15 sandstone 0  
fill ~16 ~11 ~39 ~17 ~11 ~39 sandstone 0  
fill ~17 ~11 ~14 ~18 ~11 ~14 sandstone 0  
fill ~17 ~11 ~40 ~18 ~11 ~40 sandstone 0  
fill ~18 ~11 ~13 ~19 ~11 ~13 sandstone 0  
fill ~18 ~11 ~41 ~19 ~11 ~41 sandstone 0  
fill ~19 ~11 ~12 ~21 ~11 ~12 sandstone 0  
fill ~19 ~11 ~42 ~21 ~11 ~42 sandstone 0  
fill ~20 ~11 ~4 ~20 ~16 ~4 sandstone 0  
fill ~21 ~11 ~3 ~21 ~13 ~3 sandstone 0  
fill ~21 ~11 ~11 ~22 ~11 ~11 sandstone 0  
fill ~21 ~11 ~43 ~23 ~11 ~43 sandstone 0 
setblock ~22 ~11 ~3 sandstone 2  
fill ~22 ~11 ~10 ~24 ~11 ~10 sandstone 0 
setblock ~23 ~11 ~2 leaves 6  
fill ~23 ~11 ~44 ~25 ~11 ~44 sandstone 0 
setblock ~24 ~11 ~2 leaves 14  
fill ~24 ~11 ~9 ~28 ~11 ~9 sandstone 0 
setblock ~25 ~11 ~2 leaves 6  
fill ~25 ~11 ~45 ~34 ~11 ~45 sandstone 0 
setblock ~26 ~11 ~2 sandstone 0 
setblock ~26 ~11 ~52 sandstone 0  
fill ~27 ~11 ~2 ~27 ~12 ~2 sandstone 2  
fill ~28 ~11 ~8 ~32 ~11 ~8 sandstone 0  
fill ~28 ~11 ~52 ~28 ~12 ~52 sandstone 0 
setblock ~29 ~11 ~1 planks 2  
fill ~30 ~11 ~1 ~30 ~12 ~1 spruce_fence 0  
fill ~32 ~11 ~1 ~32 ~12 ~1 spruce_fence 0  
fill ~33 ~11 ~1 ~33 ~12 ~1 sandstone 0  
fill ~33 ~11 ~8 ~33 ~10 ~8 sandstone 2 
setblock ~34 ~11 ~1 planks 2  
fill ~34 ~11 ~8 ~34 ~18 ~8 sandstone 0  
fill ~34 ~11 ~44 ~37 ~11 ~44 sandstone 0  
fill ~35 ~11 ~9 ~39 ~11 ~9 sandstone 0  
fill ~37 ~11 ~43 ~39 ~11 ~43 sandstone 0  
fill ~39 ~11 ~10 ~40 ~11 ~10 sandstone 0  
fill ~39 ~11 ~42 ~40 ~11 ~42 sandstone 0  
fill ~40 ~11 ~2 ~40 ~12 ~2 sandstone 0  
fill ~40 ~11 ~41 ~41 ~11 ~41 sandstone 0 
setblock ~41 ~11 ~3 planks 2  
fill ~41 ~11 ~10 ~41 ~13 ~10 planks 2  
fill ~41 ~11 ~11 ~42 ~11 ~11 sandstone 0 
setblock ~42 ~11 ~3 sandstone_stairs 5  
fill ~42 ~11 ~12 ~44 ~11 ~12 sandstone 0  
fill ~42 ~11 ~40 ~43 ~11 ~40 planks 2 
setblock ~43 ~11 ~4 stone_slab 9  
fill ~43 ~11 ~38 ~44 ~11 ~38 planks 2 
setblock ~44 ~11 ~4 sandstone_stairs 6  
fill ~44 ~11 ~13 ~45 ~11 ~13 sandstone 0  
fill ~44 ~11 ~37 ~45 ~11 ~37 sandstone 0  
fill ~44 ~11 ~47 ~45 ~11 ~47 planks 2  
fill ~45 ~11 ~14 ~46 ~11 ~14 sandstone 0  
fill ~45 ~11 ~46 ~45 ~13 ~46 planks 2 
setblock ~46 ~11 ~5 sandstone 2  
fill ~46 ~11 ~6 ~46 ~13 ~6 sandstone 0  
fill ~46 ~11 ~15 ~47 ~11 ~15 sandstone 0  
fill ~46 ~11 ~32 ~47 ~11 ~32 sandstone 0  
fill ~46 ~11 ~33 ~46 ~33 ~33 sandstone 0  
fill ~46 ~11 ~34 ~46 ~33 ~34 sandstone 0  
fill ~46 ~11 ~45 ~47 ~11 ~45 planks 2  
fill ~46 ~11 ~46 ~46 ~31 ~46 sandstone 1 
setblock ~47 ~11 ~6 planks 2  
fill ~47 ~11 ~16 ~48 ~11 ~16 sandstone 0  
fill ~47 ~11 ~25 ~53 ~11 ~25 sandstone 0  
fill ~47 ~11 ~26 ~54 ~11 ~26 sandstone 0  
fill ~47 ~11 ~27 ~54 ~11 ~27 sandstone 0  
fill ~47 ~11 ~28 ~54 ~11 ~28 sandstone 0  
fill ~47 ~11 ~29 ~54 ~11 ~29 sandstone 0  
fill ~47 ~11 ~30 ~54 ~11 ~30 sandstone 0  
fill ~47 ~11 ~31 ~47 ~34 ~31 sandstone 0  
fill ~48 ~11 ~7 ~49 ~11 ~7 sandstone 0  
fill ~48 ~11 ~18 ~49 ~11 ~18 sandstone 0  
fill ~49 ~11 ~8 ~49 ~15 ~8 sandstone 0 
setblock ~49 ~11 ~50 stone_slab 7  
fill ~50 ~11 ~8 ~50 ~12 ~8 planks 2  
fill ~50 ~11 ~38 ~56 ~11 ~38 sandstone 0  
fill ~50 ~11 ~40 ~51 ~11 ~40 planks 2  
fill ~50 ~11 ~41 ~50 ~19 ~41 planks 2 
setblock ~50 ~11 ~49 stone_slab 7  
fill ~51 ~11 ~9 ~51 ~13 ~9 planks 2  
fill ~51 ~11 ~36 ~58 ~11 ~36 sandstone 0  
fill ~51 ~11 ~37 ~56 ~11 ~37 sandstone 0  
fill ~51 ~11 ~39 ~56 ~11 ~39 sandstone 0  
fill ~51 ~11 ~41 ~55 ~11 ~41 stone_slab 1  
fill ~51 ~11 ~42 ~54 ~11 ~42 stone_slab 1  
fill ~51 ~11 ~47 ~52 ~11 ~47 quartz_block 0 
setblock ~51 ~11 ~48 stone_slab 7 
setblock ~52 ~11 ~11 planks 2  
fill ~52 ~11 ~24 ~53 ~11 ~24 sandstone 0  
fill ~52 ~11 ~31 ~54 ~11 ~31 sandstone 0  
fill ~52 ~11 ~32 ~54 ~11 ~32 sandstone 0  
fill ~52 ~11 ~33 ~57 ~11 ~33 sandstone 0  
fill ~52 ~11 ~34 ~57 ~11 ~34 sandstone 0  
fill ~52 ~11 ~35 ~57 ~11 ~35 sandstone 0  
fill ~52 ~11 ~40 ~53 ~11 ~40 stone_slab 1  
fill ~53 ~11 ~43 ~54 ~11 ~43 stone_slab 1 
setblock ~53 ~11 ~46 quartz_block 0 
setblock ~54 ~11 ~13 sandstone 0 
setblock ~54 ~11 ~14 planks 2  
fill ~54 ~11 ~40 ~55 ~11 ~40 sandstone 0  
fill ~54 ~11 ~44 ~54 ~11 ~45 quartz_block 0  
fill ~55 ~11 ~14 ~55 ~11 ~15 sandstone 0 
setblock ~55 ~11 ~16 planks 2  
fill ~55 ~11 ~42 ~55 ~11 ~43 stone_slab 15  
fill ~56 ~11 ~16 ~56 ~14 ~16 sandstone 0 
setblock ~56 ~11 ~18 sandstone 2 
setblock ~56 ~11 ~40 stone_slab 1 
setblock ~56 ~11 ~41 stone_slab 15 
setblock ~57 ~11 ~20 sandstone 0  
fill ~57 ~11 ~37 ~57 ~11 ~39 stone_slab 1  
fill ~58 ~11 ~22 ~58 ~12 ~22 sandstone 0  
fill ~58 ~11 ~24 ~58 ~12 ~24 sandstone 2  
fill ~58 ~11 ~31 ~58 ~11 ~32 sandstone 0  
fill ~58 ~11 ~34 ~58 ~11 ~35 planks 2  
fill ~59 ~11 ~28 ~59 ~12 ~28 sandstone 0  
fill ~59 ~11 ~29 ~59 ~12 ~29 sandstone 0  
fill ~5 ~12 ~26 ~5 ~12 ~28 glowstone 0  
fill ~5 ~12 ~29 ~5 ~15 ~29 planks 2  
fill ~6 ~12 ~19 ~7 ~12 ~19 sandstone 0  
fill ~6 ~12 ~20 ~6 ~12 ~22 planks 2  
fill ~6 ~12 ~31 ~6 ~13 ~31 sandstone 0  
fill ~6 ~12 ~32 ~6 ~12 ~34 sandstone 2  
fill ~6 ~12 ~35 ~6 ~14 ~35 planks 2  
fill ~7 ~12 ~17 ~7 ~14 ~17 sandstone 2  
fill ~7 ~12 ~37 ~7 ~14 ~37 planks 2  
fill ~8 ~12 ~16 ~8 ~13 ~16 sandstone 2  
fill ~8 ~12 ~38 ~8 ~13 ~38 planks 2 
setblock ~9 ~12 ~13 double_stone_slab 1  
fill ~9 ~12 ~14 ~9 ~13 ~14 sandstone 2  
fill ~9 ~12 ~41 ~9 ~15 ~41 sandstone 2 
setblock ~10 ~12 ~12 double_stone_slab 1 
setblock ~10 ~12 ~43 planks 2 
setblock ~11 ~12 ~10 planks 2 
setblock ~11 ~12 ~11 double_stone_slab 1 
setblock ~11 ~12 ~12 planks 2 
setblock ~11 ~12 ~43 sandstone 2 
setblock ~11 ~12 ~44 sandstone 0  
fill ~12 ~12 ~24 ~13 ~12 ~24 sandstone 0  
fill ~12 ~12 ~30 ~13 ~12 ~30 sandstone 0  
fill ~12 ~12 ~45 ~12 ~14 ~45 sandstone 2 
setblock ~13 ~12 ~8 sandstone 0  
fill ~13 ~12 ~20 ~14 ~12 ~20 sandstone 0  
fill ~13 ~12 ~34 ~14 ~12 ~34 sandstone 0  
fill ~13 ~12 ~46 ~13 ~14 ~46 sandstone 2 
setblock ~14 ~12 ~7 planks 2  
fill ~14 ~12 ~18 ~15 ~12 ~18 sandstone 0  
fill ~14 ~12 ~46 ~14 ~14 ~46 sandstone 0  
fill ~14 ~12 ~47 ~14 ~12 ~46 sandstone 0  
fill ~15 ~12 ~7 ~15 ~13 ~7 sandstone 0  
fill ~16 ~12 ~6 ~16 ~14 ~6 sandstone 2  
fill ~16 ~12 ~15 ~17 ~12 ~15 sandstone 0  
fill ~16 ~12 ~17 ~16 ~21 ~17 sandstone 0  
fill ~16 ~12 ~39 ~17 ~12 ~39 sandstone 0 
setblock ~16 ~12 ~47 sandstone 2  
fill ~17 ~12 ~5 ~18 ~12 ~5 leaves 6  
fill ~17 ~12 ~6 ~17 ~16 ~6 sandstone 0  
fill ~17 ~12 ~14 ~18 ~12 ~14 sandstone 0  
fill ~17 ~12 ~40 ~18 ~12 ~40 sandstone 0 
setblock ~17 ~12 ~49 sandstone_stairs 5  
fill ~18 ~12 ~13 ~19 ~12 ~13 sandstone 0  
fill ~18 ~12 ~41 ~19 ~12 ~41 sandstone 0 
setblock ~18 ~12 ~49 stone_slab 9 
setblock ~19 ~12 ~4 leaves 6  
fill ~19 ~12 ~12 ~21 ~12 ~12 sandstone 0  
fill ~19 ~12 ~42 ~21 ~12 ~42 sandstone 0 
setblock ~19 ~12 ~50 sandstone_stairs 4  
fill ~21 ~12 ~11 ~22 ~12 ~11 sandstone 0  
fill ~21 ~12 ~43 ~23 ~12 ~43 sandstone 0 
setblock ~22 ~12 ~3 sandstone 0  
fill ~22 ~12 ~10 ~24 ~12 ~10 sandstone 0  
fill ~23 ~12 ~3 ~23 ~13 ~3 spruce_fence 0  
fill ~23 ~12 ~44 ~25 ~12 ~44 sandstone 0  
fill ~24 ~12 ~9 ~28 ~12 ~9 sandstone 0  
fill ~25 ~12 ~2 ~25 ~13 ~2 spruce_fence 0  
fill ~25 ~12 ~45 ~34 ~12 ~45 sandstone 0  
fill ~26 ~12 ~2 ~26 ~14 ~2 sandstone 2 
setblock ~26 ~12 ~52 planks 2  
fill ~28 ~12 ~1 ~29 ~12 ~1 sandstone 0  
fill ~28 ~12 ~8 ~35 ~12 ~8 sandstone 0 
setblock ~34 ~12 ~1 sandstone 2  
fill ~34 ~12 ~44 ~37 ~12 ~44 sandstone 0  
fill ~35 ~12 ~9 ~39 ~12 ~9 sandstone 0 
setblock ~36 ~12 ~2 sandstone_stairs 5 
setblock ~37 ~12 ~2 stone_slab 9  
fill ~37 ~12 ~43 ~39 ~12 ~43 sandstone 0 
setblock ~38 ~12 ~2 sandstone_stairs 4  
fill ~39 ~12 ~2 ~39 ~15 ~2 planks 2  
fill ~39 ~12 ~10 ~39 ~16 ~10 sandstone 0  
fill ~39 ~12 ~42 ~40 ~12 ~42 sandstone 0  
fill ~39 ~12 ~50 ~39 ~21 ~50 sandstone 0  
fill ~39 ~12 ~51 ~39 ~13 ~51 sandstone 0 
setblock ~40 ~12 ~10 planks 2  
fill ~40 ~12 ~41 ~42 ~12 ~41 sandstone 0  
fill ~41 ~12 ~3 ~42 ~12 ~3 sandstone 0  
fill ~41 ~12 ~11 ~42 ~12 ~11 sandstone 0  
fill ~41 ~12 ~49 ~41 ~24 ~49 sandstone 0  
fill ~42 ~12 ~4 ~43 ~12 ~4 sandstone 0  
fill ~42 ~12 ~12 ~44 ~12 ~12 sandstone 0  
fill ~42 ~12 ~40 ~42 ~31 ~40 sandstone 0  
fill ~43 ~12 ~38 ~44 ~12 ~38 sandstone 0 
setblock ~43 ~12 ~40 planks 2  
fill ~44 ~12 ~4 ~44 ~12 ~5 sandstone 2  
fill ~44 ~12 ~13 ~45 ~12 ~13 sandstone 0  
fill ~44 ~12 ~37 ~45 ~12 ~37 sandstone 0  
fill ~44 ~12 ~47 ~45 ~12 ~47 planks 2 
setblock ~45 ~12 ~5 sandstone 2  
fill ~45 ~12 ~14 ~46 ~12 ~14 sandstone 0  
fill ~45 ~12 ~21 ~53 ~12 ~21 sandstone 0  
fill ~45 ~12 ~22 ~53 ~12 ~22 sandstone 0 
setblock ~46 ~12 ~5 planks 2  
fill ~46 ~12 ~15 ~47 ~12 ~15 sandstone 0  
fill ~46 ~12 ~20 ~52 ~12 ~20 sandstone 0  
fill ~46 ~12 ~23 ~53 ~12 ~23 sandstone 0  
fill ~46 ~12 ~24 ~53 ~12 ~24 sandstone 0  
fill ~46 ~12 ~25 ~49 ~12 ~25 sandstone 0  
fill ~46 ~12 ~32 ~47 ~12 ~32 sandstone 0  
fill ~46 ~12 ~45 ~47 ~12 ~45 planks 2 
setblock ~47 ~12 ~6 sandstone 0  
fill ~47 ~12 ~16 ~48 ~12 ~16 sandstone 0  
fill ~47 ~12 ~26 ~47 ~35 ~26 sandstone 0  
fill ~47 ~12 ~27 ~47 ~35 ~27 sandstone 0  
fill ~47 ~12 ~28 ~47 ~34 ~28 sandstone 0  
fill ~47 ~12 ~29 ~47 ~34 ~29 sandstone 0  
fill ~47 ~12 ~30 ~47 ~34 ~30 sandstone 0  
fill ~48 ~12 ~7 ~48 ~14 ~7 planks 2  
fill ~48 ~12 ~18 ~51 ~12 ~18 sandstone 0  
fill ~48 ~12 ~19 ~48 ~13 ~19 sandstone 0  
fill ~49 ~12 ~7 ~49 ~15 ~7 sandstone 0 
setblock ~50 ~12 ~9 planks 2  
fill ~50 ~12 ~19 ~52 ~12 ~19 sandstone 0  
fill ~50 ~12 ~40 ~50 ~22 ~40 planks 2  
fill ~51 ~12 ~27 ~59 ~12 ~27 sandstone 0  
fill ~51 ~12 ~29 ~59 ~12 ~29 sandstone 0  
fill ~51 ~12 ~39 ~52 ~12 ~39 sandstone 0  
fill ~51 ~12 ~40 ~51 ~32 ~40 sandstone 1  
fill ~52 ~12 ~10 ~52 ~12 ~11 sandstone 0  
fill ~52 ~12 ~30 ~57 ~12 ~30 sandstone 0  
fill ~52 ~12 ~31 ~57 ~12 ~31 sandstone 0  
fill ~52 ~12 ~32 ~57 ~12 ~32 sandstone 0  
fill ~53 ~12 ~11 ~53 ~14 ~11 sandstone 0  
fill ~53 ~12 ~25 ~54 ~12 ~25 sandstone 0  
fill ~53 ~12 ~28 ~59 ~12 ~28 sandstone 0  
fill ~53 ~12 ~33 ~57 ~12 ~33 sandstone 0  
fill ~53 ~12 ~34 ~53 ~18 ~34 sandstone 0  
fill ~53 ~12 ~35 ~53 ~17 ~35 sandstone 0  
fill ~53 ~12 ~37 ~56 ~12 ~37 stone_slab 1 
setblock ~54 ~12 ~13 planks 2 
setblock ~54 ~12 ~14 sandstone 0  
fill ~54 ~12 ~26 ~58 ~12 ~26 sandstone 0  
fill ~54 ~12 ~34 ~54 ~33 ~34 sandstone 1  
fill ~54 ~12 ~35 ~57 ~12 ~35 stone_slab 1  
fill ~54 ~12 ~36 ~57 ~12 ~36 stone_slab 1  
fill ~55 ~12 ~14 ~55 ~12 ~15 planks 2  
fill ~55 ~12 ~16 ~55 ~14 ~16 sandstone 0  
fill ~55 ~12 ~34 ~57 ~12 ~34 stone_slab 1  
fill ~55 ~12 ~42 ~55 ~12 ~43 stone_slab 7  
fill ~56 ~12 ~18 ~57 ~12 ~18 sandstone 0 
setblock ~56 ~12 ~40 quartz_block 0 
setblock ~56 ~12 ~41 stone_slab 7  
fill ~57 ~12 ~20 ~57 ~12 ~21 planks 2  
fill ~57 ~12 ~37 ~57 ~12 ~39 quartz_block 0 
setblock ~58 ~12 ~21 sandstone 0 
setblock ~58 ~12 ~23 sandstone 0  
fill ~58 ~12 ~30 ~58 ~12 ~33 stone_slab 1  
fill ~58 ~12 ~34 ~58 ~12 ~36 stone_slab 15  
fill ~5 ~13 ~26 ~5 ~13 ~29 planks 2  
fill ~6 ~13 ~19 ~6 ~13 ~20 double_stone_slab 1  
fill ~6 ~13 ~21 ~6 ~13 ~23 planks 2  
fill ~6 ~13 ~32 ~6 ~13 ~34 glowstone 0 
setblock ~7 ~13 ~18 double_stone_slab 1  
fill ~7 ~13 ~19 ~7 ~15 ~19 sandstone 0 
setblock ~7 ~13 ~35 planks 2 
setblock ~8 ~13 ~15 sandstone 2 
setblock ~8 ~13 ~37 planks 2 
setblock ~9 ~13 ~13 sandstone 2  
fill ~10 ~13 ~12 ~10 ~18 ~12 planks 2 
setblock ~10 ~13 ~43 sandstone 2 
setblock ~11 ~13 ~10 leaves 6  
fill ~11 ~13 ~11 ~11 ~15 ~11 planks 2 
setblock ~11 ~13 ~12 sandstone 0 
setblock ~11 ~13 ~43 sandstone 0 
setblock ~11 ~13 ~44 planks 2 
setblock ~12 ~13 ~9 leaves 6  
fill ~12 ~13 ~24 ~13 ~13 ~24 sandstone 0  
fill ~12 ~13 ~30 ~13 ~13 ~30 sandstone 0 
setblock ~13 ~13 ~8 leaves 6  
fill ~13 ~13 ~20 ~14 ~13 ~20 sandstone 0  
fill ~13 ~13 ~34 ~14 ~13 ~34 sandstone 0 
setblock ~14 ~13 ~7 sandstone 2  
fill ~14 ~13 ~18 ~15 ~13 ~18 sandstone 0 
setblock ~14 ~13 ~47 planks 2 
setblock ~16 ~13 ~7 sandstone 2  
fill ~16 ~13 ~15 ~17 ~13 ~15 sandstone 0  
fill ~16 ~13 ~39 ~17 ~13 ~39 sandstone 0  
fill ~16 ~13 ~47 ~16 ~17 ~47 sandstone 0  
fill ~17 ~13 ~5 ~17 ~14 ~5 spruce_fence 0  
fill ~17 ~13 ~14 ~18 ~13 ~14 sandstone 0  
fill ~17 ~13 ~40 ~18 ~13 ~40 sandstone 0  
fill ~17 ~13 ~49 ~18 ~13 ~49 sandstone 2  
fill ~18 ~13 ~13 ~19 ~13 ~13 sandstone 0  
fill ~18 ~13 ~41 ~19 ~13 ~41 sandstone 0  
fill ~19 ~13 ~4 ~19 ~14 ~4 spruce_fence 0  
fill ~19 ~13 ~12 ~21 ~13 ~12 sandstone 0  
fill ~19 ~13 ~42 ~21 ~13 ~42 sandstone 0  
fill ~19 ~13 ~50 ~19 ~14 ~50 sandstone 2  
fill ~21 ~13 ~11 ~22 ~13 ~11 sandstone 0  
fill ~21 ~13 ~43 ~23 ~13 ~43 sandstone 0 
setblock ~22 ~13 ~3 planks 2  
fill ~22 ~13 ~10 ~24 ~13 ~10 sandstone 0  
fill ~23 ~13 ~44 ~25 ~13 ~44 sandstone 0 
setblock ~23 ~13 ~51 sandstone_stairs 5  
fill ~24 ~13 ~9 ~28 ~13 ~9 sandstone 0 
setblock ~24 ~13 ~51 stone_slab 9  
fill ~25 ~13 ~45 ~34 ~13 ~45 sandstone 0 
setblock ~25 ~13 ~52 sandstone_stairs 4  
fill ~26 ~13 ~52 ~26 ~14 ~52 sandstone 0  
fill ~27 ~13 ~2 ~27 ~15 ~2 sandstone 0  
fill ~28 ~13 ~1 ~28 ~12 ~1 sandstone 0  
fill ~28 ~13 ~8 ~35 ~13 ~8 sandstone 0  
fill ~28 ~13 ~52 ~28 ~14 ~52 planks 2 
setblock ~29 ~13 ~1 planks 2 
setblock ~30 ~13 ~1 sandstone_stairs 5 
setblock ~31 ~13 ~1 stone_slab 9 
setblock ~32 ~13 ~1 sandstone_stairs 4 
setblock ~33 ~13 ~1 sandstone 2  
fill ~34 ~13 ~1 ~35 ~13 ~1 sandstone 0  
fill ~34 ~13 ~44 ~37 ~13 ~44 sandstone 0  
fill ~35 ~13 ~9 ~39 ~13 ~9 sandstone 0  
fill ~36 ~13 ~2 ~36 ~14 ~2 sandstone 0 
setblock ~37 ~13 ~2 sandstone 2  
fill ~37 ~13 ~43 ~39 ~13 ~43 sandstone 0 
setblock ~38 ~13 ~2 planks 2  
fill ~39 ~13 ~42 ~40 ~13 ~42 sandstone 0  
fill ~40 ~13 ~2 ~40 ~16 ~2 planks 2  
fill ~40 ~13 ~10 ~40 ~16 ~10 sandstone 0  
fill ~40 ~13 ~41 ~42 ~13 ~41 sandstone 0  
fill ~41 ~13 ~3 ~41 ~12 ~3 sandstone 0  
fill ~41 ~13 ~11 ~42 ~13 ~11 sandstone 0 
setblock ~41 ~13 ~50 sandstone 0  
fill ~42 ~13 ~3 ~42 ~15 ~3 planks 2  
fill ~42 ~13 ~4 ~42 ~12 ~4 sandstone 0  
fill ~42 ~13 ~12 ~44 ~13 ~12 sandstone 0  
fill ~42 ~13 ~16 ~50 ~13 ~16 sandstone 0  
fill ~42 ~13 ~17 ~51 ~13 ~17 sandstone 0 
setblock ~43 ~13 ~4 sandstone 2  
fill ~43 ~13 ~18 ~51 ~13 ~18 sandstone 0  
fill ~43 ~13 ~19 ~49 ~13 ~19 sandstone 0  
fill ~43 ~13 ~38 ~44 ~13 ~38 sandstone 0  
fill ~43 ~13 ~39 ~43 ~32 ~39 sandstone 0  
fill ~43 ~13 ~40 ~43 ~31 ~40 sandstone 0  
fill ~44 ~13 ~4 ~44 ~15 ~4 planks 2  
fill ~44 ~13 ~5 ~46 ~13 ~5 sandstone 0  
fill ~44 ~13 ~13 ~48 ~13 ~13 sandstone 0  
fill ~44 ~13 ~15 ~50 ~13 ~15 sandstone 0  
fill ~44 ~13 ~20 ~45 ~13 ~20 sandstone 0  
fill ~44 ~13 ~37 ~45 ~13 ~37 sandstone 0  
fill ~44 ~13 ~47 ~45 ~13 ~47 planks 2  
fill ~45 ~13 ~14 ~49 ~13 ~14 sandstone 0  
fill ~45 ~13 ~21 ~45 ~36 ~21 sandstone 0  
fill ~45 ~13 ~22 ~46 ~13 ~22 sandstone 0  
fill ~46 ~13 ~23 ~46 ~26 ~23 sandstone 0  
fill ~46 ~13 ~24 ~46 ~26 ~24 sandstone 0  
fill ~46 ~13 ~25 ~47 ~13 ~25 sandstone 0  
fill ~46 ~13 ~32 ~47 ~13 ~32 sandstone 0  
fill ~46 ~13 ~45 ~47 ~13 ~45 planks 2  
fill ~47 ~13 ~6 ~47 ~14 ~6 planks 2  
fill ~47 ~13 ~7 ~47 ~13 ~6 planks 2  
fill ~50 ~13 ~8 ~50 ~14 ~8 sandstone 0  
fill ~50 ~13 ~9 ~50 ~15 ~9 sandstone 0  
fill ~51 ~13 ~19 ~52 ~13 ~19 sandstone 0  
fill ~51 ~13 ~21 ~57 ~13 ~21 sandstone 0  
fill ~51 ~13 ~39 ~52 ~13 ~39 sandstone 0  
fill ~52 ~13 ~10 ~52 ~14 ~10 planks 2 
setblock ~52 ~13 ~11 sandstone 0  
fill ~52 ~13 ~20 ~57 ~13 ~20 sandstone 0  
fill ~52 ~13 ~22 ~57 ~13 ~22 sandstone 0  
fill ~52 ~13 ~23 ~57 ~13 ~23 sandstone 0  
fill ~52 ~13 ~24 ~57 ~13 ~24 sandstone 0  
fill ~52 ~13 ~25 ~57 ~13 ~25 sandstone 0  
fill ~52 ~13 ~26 ~57 ~13 ~26 sandstone 0  
fill ~52 ~13 ~27 ~53 ~13 ~27 sandstone 0  
fill ~53 ~13 ~33 ~54 ~13 ~33 sandstone 0  
fill ~54 ~13 ~13 ~54 ~14 ~13 sandstone 0 
setblock ~54 ~13 ~14 planks 2  
fill ~54 ~13 ~28 ~54 ~21 ~28 sandstone 0  
fill ~54 ~13 ~29 ~54 ~16 ~29 sandstone 0  
fill ~55 ~13 ~14 ~55 ~13 ~16 sandstone 0  
fill ~55 ~13 ~27 ~56 ~13 ~27 stone_slab 1  
fill ~55 ~13 ~28 ~58 ~13 ~28 stone_slab 1  
fill ~55 ~13 ~29 ~58 ~13 ~29 stone_slab 1  
fill ~55 ~13 ~30 ~57 ~13 ~30 stone_slab 1  
fill ~56 ~13 ~18 ~57 ~13 ~18 sandstone 0  
fill ~56 ~13 ~19 ~56 ~14 ~19 sandstone 0  
fill ~57 ~13 ~27 ~58 ~13 ~27 double_stone_slab 1  
fill ~58 ~13 ~21 ~58 ~13 ~26 stone_slab 1  
fill ~58 ~13 ~30 ~58 ~13 ~33 quartz_block 0  
fill ~58 ~13 ~34 ~58 ~13 ~36 stone_slab 7  
fill ~59 ~13 ~27 ~59 ~13 ~29 stone_slab 15  
fill ~5 ~14 ~25 ~5 ~15 ~25 planks 2  
fill ~5 ~14 ~26 ~5 ~14 ~28 double_stone_slab 1  
fill ~6 ~14 ~19 ~6 ~14 ~21 sandstone 0 
setblock ~6 ~14 ~22 planks 2  
fill ~6 ~14 ~23 ~6 ~18 ~23 sandstone 0 
setblock ~6 ~14 ~31 planks 2  
fill ~6 ~14 ~32 ~6 ~14 ~33 sandstone 0 
setblock ~6 ~14 ~34 planks 2 
setblock ~7 ~14 ~18 sandstone 0  
fill ~7 ~14 ~35 ~7 ~24 ~35 sandstone 0  
fill ~8 ~14 ~15 ~8 ~14 ~16 leaves 14  
fill ~8 ~14 ~37 ~8 ~22 ~37 sandstone 0  
fill ~8 ~14 ~38 ~8 ~14 ~39 glowstone 0  
fill ~9 ~14 ~13 ~9 ~15 ~13 sandstone 0 
setblock ~9 ~14 ~14 leaves 14 
setblock ~9 ~14 ~40 glowstone 0 
setblock ~10 ~14 ~41 sandstone 2  
fill ~10 ~14 ~43 ~11 ~14 ~43 planks 2  
fill ~11 ~14 ~10 ~11 ~15 ~10 spruce_fence 0 
setblock ~11 ~14 ~12 planks 2 
setblock ~11 ~14 ~44 sandstone 0  
fill ~12 ~14 ~24 ~13 ~14 ~24 sandstone 0  
fill ~12 ~14 ~30 ~13 ~14 ~30 sandstone 0  
fill ~13 ~14 ~8 ~13 ~15 ~8 spruce_fence 0  
fill ~13 ~14 ~20 ~14 ~14 ~20 sandstone 0  
fill ~13 ~14 ~34 ~14 ~14 ~34 sandstone 0  
fill ~14 ~14 ~7 ~14 ~15 ~7 planks 2  
fill ~14 ~14 ~18 ~15 ~14 ~18 sandstone 0 
setblock ~14 ~14 ~47 sandstone 0 
setblock ~15 ~14 ~7 sandstone 2  
fill ~16 ~14 ~7 ~16 ~20 ~7 sandstone 0  
fill ~16 ~14 ~15 ~17 ~14 ~15 sandstone 0  
fill ~16 ~14 ~39 ~17 ~14 ~39 sandstone 0  
fill ~17 ~14 ~14 ~18 ~14 ~14 sandstone 0  
fill ~17 ~14 ~40 ~18 ~14 ~40 sandstone 0  
fill ~17 ~14 ~49 ~18 ~14 ~49 planks 2  
fill ~18 ~14 ~13 ~19 ~14 ~13 sandstone 0  
fill ~18 ~14 ~41 ~19 ~14 ~41 sandstone 0  
fill ~19 ~14 ~12 ~21 ~14 ~12 sandstone 0  
fill ~19 ~14 ~42 ~21 ~14 ~42 sandstone 0  
fill ~20 ~14 ~50 ~20 ~16 ~50 planks 2 
setblock ~21 ~14 ~3 planks 2  
fill ~21 ~14 ~11 ~22 ~14 ~11 sandstone 0  
fill ~21 ~14 ~43 ~23 ~14 ~43 sandstone 0 
setblock ~22 ~14 ~3 sandstone 0  
fill ~22 ~14 ~10 ~24 ~14 ~10 sandstone 0 
setblock ~23 ~14 ~2 sandstone_stairs 5  
fill ~23 ~14 ~44 ~25 ~14 ~44 sandstone 0  
fill ~23 ~14 ~51 ~23 ~15 ~51 sandstone 2 
setblock ~24 ~14 ~2 stone_slab 9  
fill ~24 ~14 ~9 ~28 ~14 ~9 sandstone 0  
fill ~24 ~14 ~51 ~24 ~16 ~51 sandstone 0 
setblock ~25 ~14 ~2 sandstone_stairs 4  
fill ~25 ~14 ~45 ~34 ~14 ~45 sandstone 0 
setblock ~25 ~14 ~52 sandstone 0  
fill ~28 ~14 ~1 ~28 ~15 ~1 planks 2  
fill ~28 ~14 ~8 ~35 ~14 ~8 sandstone 0  
fill ~29 ~14 ~1 ~31 ~14 ~1 sandstone 0 
setblock ~29 ~14 ~52 sandstone_stairs 5  
fill ~30 ~14 ~52 ~31 ~14 ~52 stone_slab 9  
fill ~32 ~14 ~1 ~32 ~15 ~1 planks 2 
setblock ~32 ~14 ~52 sandstone_stairs 4 
setblock ~33 ~14 ~1 sandstone 0 
setblock ~33 ~14 ~52 planks 2 
setblock ~34 ~14 ~1 planks 2  
fill ~34 ~14 ~44 ~37 ~14 ~44 sandstone 0 
setblock ~35 ~14 ~1 sandstone 0  
fill ~35 ~14 ~9 ~39 ~14 ~9 sandstone 0 
setblock ~35 ~14 ~52 planks 2 
setblock ~37 ~14 ~2 planks 2  
fill ~37 ~14 ~43 ~39 ~14 ~43 sandstone 0 
setblock ~38 ~14 ~2 sandstone 2  
fill ~38 ~14 ~14 ~46 ~14 ~14 sandstone 0  
fill ~39 ~14 ~12 ~47 ~14 ~12 sandstone 0  
fill ~39 ~14 ~13 ~45 ~14 ~13 sandstone 0  
fill ~39 ~14 ~15 ~43 ~14 ~15 sandstone 0  
fill ~39 ~14 ~42 ~40 ~14 ~42 sandstone 0 
setblock ~39 ~14 ~51 planks 2  
fill ~40 ~14 ~11 ~46 ~14 ~11 sandstone 0  
fill ~40 ~14 ~16 ~41 ~14 ~16 sandstone 0  
fill ~40 ~14 ~41 ~42 ~14 ~41 sandstone 0 
setblock ~41 ~14 ~3 planks 2  
fill ~41 ~14 ~8 ~41 ~20 ~8 sandstone 0  
fill ~41 ~14 ~9 ~43 ~14 ~9 sandstone 0  
fill ~41 ~14 ~10 ~45 ~14 ~10 sandstone 0  
fill ~41 ~14 ~17 ~42 ~14 ~17 sandstone 0 
setblock ~41 ~14 ~50 planks 2 
setblock ~42 ~14 ~4 sandstone 2  
fill ~42 ~14 ~18 ~43 ~14 ~18 sandstone 0  
fill ~43 ~14 ~4 ~43 ~16 ~4 sandstone 0  
fill ~43 ~14 ~19 ~44 ~14 ~19 sandstone 0  
fill ~43 ~14 ~38 ~44 ~14 ~38 sandstone 0  
fill ~44 ~14 ~5 ~46 ~14 ~5 sandstone 0  
fill ~44 ~14 ~20 ~45 ~14 ~20 sandstone 0  
fill ~44 ~14 ~37 ~45 ~14 ~37 sandstone 0  
fill ~44 ~14 ~47 ~45 ~14 ~47 planks 2  
fill ~45 ~14 ~22 ~46 ~14 ~22 sandstone 0  
fill ~45 ~14 ~46 ~45 ~22 ~46 sandstone 0 
setblock ~46 ~14 ~6 planks 2  
fill ~46 ~14 ~15 ~47 ~14 ~15 sandstone 0  
fill ~46 ~14 ~25 ~47 ~14 ~25 sandstone 0  
fill ~46 ~14 ~32 ~47 ~14 ~32 sandstone 0  
fill ~46 ~14 ~45 ~47 ~14 ~45 planks 2  
fill ~47 ~14 ~7 ~47 ~16 ~7 sandstone 0  
fill ~47 ~14 ~13 ~48 ~14 ~13 sandstone 0  
fill ~47 ~14 ~16 ~56 ~14 ~16 sandstone 0  
fill ~48 ~14 ~14 ~49 ~14 ~14 sandstone 0  
fill ~48 ~14 ~18 ~56 ~14 ~18 sandstone 0  
fill ~49 ~14 ~15 ~55 ~14 ~15 sandstone 0  
fill ~49 ~14 ~17 ~55 ~14 ~17 sandstone 0  
fill ~50 ~14 ~19 ~56 ~14 ~19 sandstone 0 
setblock ~51 ~14 ~9 sandstone 0  
fill ~51 ~14 ~14 ~54 ~14 ~14 sandstone 0  
fill ~51 ~14 ~20 ~54 ~14 ~20 sandstone 0  
fill ~51 ~14 ~21 ~53 ~14 ~21 sandstone 0  
fill ~51 ~14 ~39 ~52 ~14 ~39 sandstone 0 
setblock ~52 ~14 ~11 planks 2  
fill ~52 ~14 ~13 ~52 ~15 ~13 sandstone 0  
fill ~53 ~14 ~22 ~53 ~15 ~22 sandstone 0  
fill ~53 ~14 ~23 ~53 ~15 ~23 sandstone 0  
fill ~53 ~14 ~24 ~54 ~14 ~24 sandstone 0  
fill ~53 ~14 ~33 ~53 ~19 ~33 sandstone 0  
fill ~54 ~14 ~21 ~57 ~14 ~21 stone_slab 1  
fill ~54 ~14 ~22 ~56 ~14 ~22 stone_slab 1  
fill ~54 ~14 ~23 ~54 ~14 ~21 stone_slab 1 
setblock ~54 ~14 ~33 planks 2 
setblock ~55 ~14 ~14 planks 2  
fill ~55 ~14 ~20 ~56 ~14 ~20 stone_slab 1 
setblock ~56 ~14 ~17 stone_slab 1  
fill ~57 ~14 ~18 ~57 ~14 ~20 stone_slab 15  
fill ~58 ~14 ~21 ~58 ~14 ~26 quartz_block 0  
fill ~59 ~14 ~27 ~59 ~14 ~29 stone_slab 7  
fill ~5 ~15 ~26 ~5 ~15 ~27 planks 2 
setblock ~5 ~15 ~28 sandstone 0 
setblock ~6 ~15 ~19 planks 2  
fill ~6 ~15 ~20 ~6 ~15 ~22 leaves 6  
fill ~6 ~15 ~30 ~6 ~16 ~30 planks 2 
setblock ~6 ~15 ~31 sandstone 0  
fill ~6 ~15 ~32 ~6 ~16 ~32 planks 2  
fill ~6 ~15 ~33 ~6 ~15 ~35 double_stone_slab 1  
fill ~7 ~15 ~17 ~7 ~16 ~17 sandstone 0 
setblock ~7 ~15 ~18 planks 2 
setblock ~7 ~15 ~37 sandstone 2  
fill ~8 ~15 ~16 ~8 ~16 ~16 spruce_fence 0 
setblock ~8 ~15 ~38 sandstone 2 
setblock ~8 ~15 ~39 sandstone 0  
fill ~9 ~15 ~14 ~9 ~16 ~14 spruce_fence 0 
setblock ~9 ~15 ~40 sandstone 0  
fill ~10 ~15 ~41 ~10 ~16 ~41 sandstone 0 
setblock ~10 ~15 ~43 sandstone 2  
fill ~11 ~15 ~12 ~11 ~21 ~12 sandstone 0 
setblock ~11 ~15 ~43 sandstone 0 
setblock ~11 ~15 ~44 glowstone 0  
fill ~12 ~15 ~24 ~13 ~15 ~24 sandstone 0  
fill ~12 ~15 ~30 ~13 ~15 ~30 sandstone 0 
setblock ~12 ~15 ~45 glowstone 0  
fill ~13 ~15 ~20 ~14 ~15 ~20 sandstone 0  
fill ~13 ~15 ~34 ~14 ~15 ~34 sandstone 0 
setblock ~13 ~15 ~46 glowstone 0  
fill ~14 ~15 ~18 ~15 ~15 ~18 sandstone 0  
fill ~14 ~15 ~46 ~14 ~15 ~47 sandstone 2  
fill ~15 ~15 ~7 ~15 ~20 ~7 sandstone 0  
fill ~16 ~15 ~6 ~16 ~16 ~6 sandstone 0  
fill ~16 ~15 ~15 ~17 ~15 ~15 sandstone 0  
fill ~16 ~15 ~39 ~17 ~15 ~39 sandstone 0  
fill ~16 ~15 ~48 ~16 ~20 ~48 planks 2 
setblock ~17 ~15 ~5 sandstone_stairs 6  
fill ~17 ~15 ~14 ~18 ~15 ~14 sandstone 0  
fill ~17 ~15 ~40 ~18 ~15 ~40 sandstone 0  
fill ~17 ~15 ~49 ~18 ~15 ~49 planks 2 
setblock ~18 ~15 ~5 stone_slab 9  
fill ~18 ~15 ~13 ~19 ~15 ~13 sandstone 0  
fill ~18 ~15 ~41 ~19 ~15 ~41 sandstone 0 
setblock ~19 ~15 ~4 sandstone_stairs 4  
fill ~19 ~15 ~12 ~21 ~15 ~12 sandstone 0  
fill ~19 ~15 ~42 ~21 ~15 ~42 sandstone 0 
setblock ~19 ~15 ~50 planks 2  
fill ~21 ~15 ~3 ~22 ~15 ~3 sandstone 2  
fill ~21 ~15 ~11 ~22 ~15 ~11 sandstone 0  
fill ~21 ~15 ~43 ~23 ~15 ~43 sandstone 0 
setblock ~21 ~15 ~50 planks 2  
fill ~22 ~15 ~10 ~24 ~15 ~10 sandstone 0  
fill ~23 ~15 ~2 ~23 ~16 ~2 sandstone 0  
fill ~23 ~15 ~3 ~23 ~19 ~3 sandstone 0  
fill ~23 ~15 ~44 ~25 ~15 ~44 sandstone 0  
fill ~24 ~15 ~2 ~25 ~15 ~2 sandstone 2  
fill ~24 ~15 ~9 ~28 ~15 ~9 sandstone 0  
fill ~25 ~15 ~45 ~34 ~15 ~45 sandstone 0  
fill ~25 ~15 ~52 ~25 ~16 ~52 planks 2  
fill ~26 ~15 ~2 ~26 ~17 ~2 planks 2 
setblock ~26 ~15 ~52 sandstone 2  
fill ~28 ~15 ~8 ~42 ~15 ~8 sandstone 0 
setblock ~28 ~15 ~52 sandstone 0  
fill ~29 ~15 ~1 ~31 ~15 ~1 sandstone 0 
setblock ~29 ~15 ~52 planks 2 
setblock ~30 ~15 ~52 sandstone 0 
setblock ~31 ~15 ~52 planks 2  
fill ~32 ~15 ~52 ~32 ~16 ~52 sandstone 2 
setblock ~33 ~15 ~1 planks 2  
fill ~33 ~15 ~12 ~39 ~15 ~12 sandstone 0  
fill ~33 ~15 ~52 ~33 ~19 ~52 sandstone 0  
fill ~34 ~15 ~1 ~34 ~17 ~1 sandstone 0  
fill ~34 ~15 ~7 ~40 ~15 ~7 sandstone 0  
fill ~34 ~15 ~9 ~40 ~15 ~9 sandstone 0  
fill ~34 ~15 ~10 ~41 ~15 ~10 sandstone 0  
fill ~34 ~15 ~11 ~39 ~15 ~11 sandstone 0  
fill ~34 ~15 ~13 ~38 ~15 ~13 sandstone 0  
fill ~34 ~15 ~44 ~37 ~15 ~44 sandstone 0 
setblock ~35 ~15 ~1 planks 2  
fill ~35 ~15 ~6 ~36 ~15 ~6 sandstone 0  
fill ~35 ~15 ~52 ~35 ~17 ~52 sandstone 0 
setblock ~36 ~15 ~2 planks 2  
fill ~36 ~15 ~14 ~38 ~15 ~14 sandstone 0 
setblock ~36 ~15 ~51 sandstone_stairs 5  
fill ~37 ~15 ~2 ~38 ~15 ~2 sandstone 0  
fill ~37 ~15 ~43 ~39 ~15 ~43 sandstone 0 
setblock ~37 ~15 ~51 stone_slab 9  
fill ~38 ~15 ~15 ~40 ~15 ~15 sandstone 0 
setblock ~38 ~15 ~51 sandstone_stairs 4  
fill ~39 ~15 ~42 ~40 ~15 ~42 sandstone 0  
fill ~39 ~15 ~51 ~39 ~17 ~51 sandstone 0  
fill ~40 ~15 ~16 ~41 ~15 ~16 sandstone 0  
fill ~40 ~15 ~41 ~42 ~15 ~41 sandstone 0  
fill ~41 ~15 ~3 ~41 ~16 ~3 sandstone 0  
fill ~41 ~15 ~11 ~42 ~15 ~11 sandstone 0  
fill ~41 ~15 ~17 ~42 ~15 ~17 sandstone 0  
fill ~41 ~15 ~50 ~41 ~16 ~50 sandstone 0  
fill ~42 ~15 ~4 ~42 ~16 ~4 sandstone 0  
fill ~42 ~15 ~9 ~44 ~15 ~9 sandstone 0  
fill ~42 ~15 ~12 ~52 ~15 ~12 sandstone 0  
fill ~42 ~15 ~18 ~43 ~15 ~18 sandstone 0  
fill ~43 ~15 ~19 ~44 ~15 ~19 sandstone 0  
fill ~43 ~15 ~38 ~44 ~15 ~38 sandstone 0  
fill ~44 ~15 ~5 ~45 ~15 ~5 sandstone 0  
fill ~44 ~15 ~10 ~51 ~15 ~10 sandstone 0  
fill ~44 ~15 ~11 ~52 ~15 ~11 sandstone 0  
fill ~44 ~15 ~13 ~52 ~15 ~13 sandstone 0  
fill ~44 ~15 ~20 ~45 ~15 ~20 sandstone 0  
fill ~44 ~15 ~37 ~45 ~15 ~37 sandstone 0  
fill ~44 ~15 ~47 ~45 ~15 ~47 sandstone 0  
fill ~45 ~15 ~14 ~50 ~15 ~14 sandstone 0  
fill ~45 ~15 ~22 ~46 ~15 ~22 sandstone 0 
setblock ~46 ~15 ~5 planks 2  
fill ~46 ~15 ~6 ~46 ~16 ~6 sandstone 0  
fill ~46 ~15 ~9 ~50 ~15 ~9 sandstone 0  
fill ~46 ~15 ~15 ~50 ~15 ~15 sandstone 0  
fill ~46 ~15 ~25 ~47 ~15 ~25 sandstone 0  
fill ~46 ~15 ~32 ~47 ~15 ~32 sandstone 0  
fill ~46 ~15 ~45 ~47 ~15 ~45 sandstone 0 
setblock ~47 ~15 ~6 double_stone_slab 1  
fill ~47 ~15 ~8 ~49 ~15 ~8 sandstone 0  
fill ~47 ~15 ~16 ~48 ~15 ~16 sandstone 0 
setblock ~48 ~15 ~7 sandstone 0 
setblock ~50 ~15 ~8 stone_slab 1  
fill ~50 ~15 ~16 ~50 ~15 ~17 sandstone 0 
setblock ~51 ~15 ~9 stone_slab 1  
fill ~51 ~15 ~14 ~54 ~15 ~14 stone_slab 1  
fill ~51 ~15 ~15 ~54 ~15 ~15 stone_slab 1  
fill ~51 ~15 ~16 ~55 ~15 ~16 stone_slab 1  
fill ~51 ~15 ~17 ~51 ~15 ~18 sandstone 0  
fill ~51 ~15 ~39 ~51 ~23 ~39 planks 2 
setblock ~52 ~15 ~10 stone_slab 1  
fill ~52 ~15 ~17 ~54 ~15 ~17 stone_slab 1  
fill ~52 ~15 ~18 ~52 ~15 ~14 stone_slab 1 
setblock ~52 ~15 ~39 sandstone 0  
fill ~53 ~15 ~11 ~53 ~15 ~12 stone_slab 1 
setblock ~53 ~15 ~13 double_stone_slab 1  
fill ~53 ~15 ~24 ~54 ~15 ~24 sandstone 0 
setblock ~54 ~15 ~13 stone_slab 15 
setblock ~54 ~15 ~33 sandstone 0  
fill ~55 ~15 ~14 ~55 ~15 ~15 stone_slab 15 
setblock ~56 ~15 ~16 stone_slab 15 
setblock ~56 ~15 ~17 quartz_block 0  
fill ~57 ~15 ~18 ~57 ~15 ~20 stone_slab 7  
fill ~5 ~16 ~25 ~5 ~18 ~25 sandstone 0  
fill ~5 ~16 ~26 ~5 ~16 ~27 leaves 6 
setblock ~5 ~16 ~28 leaves 14  
fill ~5 ~16 ~29 ~5 ~20 ~29 sandstone 0 
setblock ~6 ~16 ~19 sandstone 0  
fill ~6 ~16 ~20 ~6 ~17 ~20 spruce_fence 0  
fill ~6 ~16 ~22 ~6 ~17 ~22 spruce_fence 0  
fill ~6 ~16 ~31 ~6 ~17 ~31 planks 2  
fill ~6 ~16 ~33 ~6 ~16 ~34 sandstone 2 
setblock ~6 ~16 ~35 planks 2  
fill ~7 ~16 ~18 ~7 ~19 ~18 sandstone 0 
setblock ~7 ~16 ~19 planks 2 
setblock ~7 ~16 ~37 planks 2 
setblock ~8 ~16 ~38 sandstone 0 
setblock ~8 ~16 ~39 planks 2 
setblock ~9 ~16 ~13 planks 2  
fill ~9 ~16 ~40 ~9 ~16 ~41 double_stone_slab 1 
setblock ~10 ~16 ~43 sandstone 0 
setblock ~11 ~16 ~10 sandstone_stairs 6  
fill ~11 ~16 ~11 ~11 ~20 ~11 sandstone 0   
fill ~11 ~16 ~43 ~11 ~18 ~43 planks 2  
fill ~11 ~16 ~44 ~11 ~18 ~44 planks 2 
setblock ~12 ~16 ~9 stone_slab 9  
fill ~12 ~16 ~24 ~13 ~16 ~24 sandstone 0  
fill ~12 ~16 ~30 ~13 ~16 ~30 sandstone 0 
setblock ~12 ~16 ~45 planks 2 
setblock ~13 ~16 ~8 sandstone_stairs 4  
fill ~13 ~16 ~20 ~14 ~16 ~20 sandstone 0  
fill ~13 ~16 ~33 ~13 ~18 ~33 planks 2  
fill ~13 ~16 ~34 ~14 ~16 ~34 sandstone 0 
setblock ~13 ~16 ~46 planks 2  
fill ~14 ~16 ~7 ~14 ~17 ~7 sandstone 0  
fill ~14 ~16 ~18 ~14 ~18 ~18 planks 2  
fill ~14 ~16 ~46 ~14 ~21 ~46 sandstone 0 
setblock ~14 ~16 ~47 sandstone 2  
fill ~15 ~16 ~18 ~15 ~22 ~18 sandstone 0  
fill ~16 ~16 ~15 ~17 ~16 ~15 sandstone 0  
fill ~16 ~16 ~39 ~17 ~16 ~39 sandstone 0  
fill ~17 ~16 ~5 ~18 ~16 ~5 planks 2  
fill ~17 ~16 ~14 ~18 ~16 ~14 sandstone 0  
fill ~17 ~16 ~40 ~18 ~16 ~40 sandstone 0  
fill ~17 ~16 ~49 ~18 ~16 ~49 glowstone 0  
fill ~18 ~16 ~13 ~19 ~16 ~13 sandstone 0  
fill ~18 ~16 ~41 ~19 ~16 ~41 sandstone 0  
fill ~19 ~16 ~4 ~19 ~18 ~4 planks 2 
setblock ~19 ~16 ~5 sandstone 0  
fill ~19 ~16 ~12 ~21 ~16 ~12 sandstone 0  
fill ~19 ~16 ~42 ~21 ~16 ~42 sandstone 0 
setblock ~19 ~16 ~50 glowstone 0  
fill ~21 ~16 ~3 ~21 ~18 ~3 planks 2  
fill ~21 ~16 ~11 ~22 ~16 ~11 sandstone 0  
fill ~21 ~16 ~43 ~23 ~16 ~43 sandstone 0  
fill ~21 ~16 ~50 ~21 ~28 ~50 sandstone 0 
setblock ~22 ~16 ~3 sandstone 2  
fill ~22 ~16 ~10 ~24 ~16 ~10 sandstone 0  
fill ~23 ~16 ~44 ~25 ~16 ~44 sandstone 0 
setblock ~23 ~16 ~51 planks 2  
fill ~24 ~16 ~2 ~24 ~19 ~2 sandstone 0  
fill ~24 ~16 ~9 ~46 ~16 ~9 sandstone 0 
setblock ~25 ~16 ~2 planks 2  
fill ~25 ~16 ~45 ~34 ~16 ~45 sandstone 0 
setblock ~26 ~16 ~52 planks 2 
setblock ~27 ~16 ~2 planks 2  
fill ~28 ~16 ~1 ~28 ~18 ~1 sandstone 0  
fill ~28 ~16 ~6 ~36 ~16 ~6 sandstone 0  
fill ~28 ~16 ~7 ~34 ~16 ~7 sandstone 0  
fill ~28 ~16 ~8 ~35 ~16 ~8 sandstone 0  
fill ~28 ~16 ~10 ~34 ~16 ~10 sandstone 0  
fill ~28 ~16 ~11 ~34 ~16 ~11 sandstone 0  
fill ~28 ~16 ~52 ~30 ~16 ~52 sandstone 2  
fill ~29 ~16 ~1 ~30 ~16 ~1 planks 2  
fill ~29 ~16 ~12 ~33 ~16 ~12 sandstone 0  
fill ~29 ~16 ~13 ~36 ~16 ~13 sandstone 0  
fill ~31 ~16 ~1 ~32 ~16 ~1 sandstone 0 
setblock ~31 ~16 ~52 sandstone 0  
fill ~33 ~16 ~1 ~33 ~17 ~1 sandstone 2  
fill ~34 ~16 ~44 ~37 ~16 ~44 sandstone 0  
fill ~35 ~16 ~1 ~35 ~17 ~1 sandstone 2  
fill ~36 ~16 ~2 ~37 ~16 ~2 sandstone 0  
fill ~36 ~16 ~7 ~47 ~16 ~7 sandstone 0  
fill ~36 ~16 ~14 ~38 ~16 ~14 sandstone 0  
fill ~36 ~16 ~51 ~39 ~16 ~51 sandstone 0  
fill ~37 ~16 ~43 ~39 ~16 ~43 sandstone 0  
fill ~38 ~16 ~2 ~39 ~16 ~2 sandstone 2  
fill ~38 ~16 ~15 ~40 ~16 ~15 sandstone 0  
fill ~39 ~16 ~8 ~47 ~16 ~8 sandstone 0  
fill ~39 ~16 ~42 ~40 ~16 ~42 sandstone 0  
fill ~40 ~16 ~6 ~46 ~16 ~6 sandstone 0  
fill ~40 ~16 ~16 ~41 ~16 ~16 sandstone 0  
fill ~40 ~16 ~41 ~42 ~16 ~41 sandstone 0  
fill ~41 ~16 ~4 ~41 ~17 ~4 sandstone 0  
fill ~41 ~16 ~5 ~44 ~16 ~5 sandstone 0  
fill ~41 ~16 ~10 ~45 ~16 ~10 sandstone 0  
fill ~41 ~16 ~11 ~46 ~16 ~11 sandstone 0  
fill ~41 ~16 ~17 ~42 ~16 ~17 sandstone 0 
setblock ~42 ~16 ~3 sandstone 0  
fill ~42 ~16 ~18 ~43 ~16 ~18 sandstone 0 
setblock ~42 ~16 ~49 sandstone_stairs 5 
setblock ~43 ~16 ~12 sandstone 0  
fill ~43 ~16 ~19 ~44 ~16 ~19 sandstone 0  
fill ~43 ~16 ~38 ~44 ~16 ~38 sandstone 0 
setblock ~43 ~16 ~49 stone_slab 9 
setblock ~44 ~16 ~4 sandstone 0  
fill ~44 ~16 ~20 ~45 ~16 ~20 sandstone 0  
fill ~44 ~16 ~37 ~45 ~16 ~37 sandstone 0  
fill ~44 ~16 ~47 ~45 ~16 ~47 sandstone 0 
setblock ~44 ~16 ~48 sandstone_stairs 7  
fill ~45 ~16 ~5 ~46 ~16 ~5 stone_slab 1  
fill ~45 ~16 ~22 ~46 ~16 ~22 sandstone 0  
fill ~46 ~16 ~10 ~48 ~16 ~10 stone_slab 1  
fill ~46 ~16 ~12 ~47 ~16 ~12 sandstone 0  
fill ~46 ~16 ~25 ~47 ~16 ~25 sandstone 0  
fill ~46 ~16 ~32 ~47 ~16 ~32 sandstone 0  
fill ~46 ~16 ~45 ~47 ~16 ~45 sandstone 0 
setblock ~47 ~16 ~6 stone_slab 1  
fill ~47 ~16 ~9 ~49 ~16 ~9 stone_slab 1 
setblock ~47 ~16 ~11 stone_slab 1  
fill ~47 ~16 ~13 ~47 ~20 ~13 sandstone 0  
fill ~48 ~16 ~7 ~49 ~16 ~7 stone_slab 15  
fill ~48 ~16 ~8 ~49 ~16 ~8 stone_slab 1 
setblock ~50 ~16 ~8 quartz_block 0  
fill ~50 ~16 ~16 ~50 ~17 ~16 planks 2 
setblock ~50 ~16 ~17 sandstone 0 
setblock ~51 ~16 ~9 quartz_block 0  
fill ~51 ~16 ~17 ~51 ~34 ~17 sandstone 1 
setblock ~51 ~16 ~18 sandstone 0 
setblock ~52 ~16 ~10 quartz_block 0  
fill ~52 ~16 ~39 ~52 ~19 ~39 planks 2  
fill ~53 ~16 ~11 ~53 ~16 ~12 quartz_block 0 
setblock ~53 ~16 ~22 planks 2  
fill ~53 ~16 ~23 ~53 ~34 ~23 sandstone 1  
fill ~53 ~16 ~24 ~54 ~16 ~24 sandstone 0 
setblock ~54 ~16 ~13 stone_slab 7 
setblock ~54 ~16 ~33 planks 2  
fill ~55 ~16 ~14 ~55 ~16 ~15 stone_slab 7 
setblock ~56 ~16 ~16 stone_slab 7  
fill ~5 ~17 ~26 ~5 ~18 ~26 spruce_fence 0  
fill ~5 ~17 ~28 ~5 ~18 ~28 spruce_fence 0  
