fill ~1 ~0 ~71 ~37 ~0 ~71 gravel 0  
fill ~1 ~0 ~72 ~37 ~0 ~72 gravel 0  
fill ~1 ~0 ~73 ~37 ~0 ~73 gravel 0  
fill ~2 ~0 ~70 ~37 ~0 ~70 gravel 0  
fill ~3 ~0 ~69 ~8 ~0 ~69 gravel 0  
fill ~4 ~0 ~68 ~6 ~0 ~68 gravel 0  
fill ~5 ~0 ~67 ~6 ~0 ~67 gravel 0 
setblock ~6 ~0 ~66 gravel 0  
fill ~8 ~0 ~5 ~10 ~0 ~5 stonebrick 3  
fill ~8 ~0 ~26 ~10 ~0 ~26 stonebrick 3  
fill ~8 ~0 ~46 ~10 ~0 ~46 stonebrick 3  
fill ~8 ~0 ~67 ~10 ~0 ~67 stonebrick 3  
fill ~9 ~0 ~4 ~9 ~3 ~4 stonebrick 3  
fill ~9 ~0 ~6 ~9 ~3 ~6 stonebrick 3  
fill ~9 ~0 ~25 ~9 ~5 ~25 stonebrick 3  
fill ~9 ~0 ~27 ~9 ~5 ~27 stonebrick 3  
fill ~9 ~0 ~45 ~9 ~5 ~45 stonebrick 3  
fill ~9 ~0 ~47 ~9 ~5 ~47 stonebrick 3  
fill ~9 ~0 ~66 ~9 ~5 ~66 stonebrick 3  
fill ~9 ~0 ~68 ~9 ~3 ~68 stonebrick 3  
fill ~10 ~0 ~69 ~37 ~0 ~69 gravel 0  
fill ~11 ~0 ~68 ~22 ~0 ~68 gravel 0  
fill ~12 ~0 ~67 ~18 ~0 ~67 gravel 0  
fill ~16 ~0 ~11 ~17 ~0 ~11 stonebrick 3  
fill ~16 ~0 ~12 ~17 ~0 ~12 stonebrick 3  
fill ~16 ~0 ~13 ~17 ~0 ~13 stonebrick 3  
fill ~16 ~0 ~14 ~17 ~0 ~14 stonebrick 3  
fill ~16 ~0 ~15 ~17 ~0 ~15 stonebrick 3  
fill ~16 ~0 ~16 ~17 ~0 ~16 stonebrick 3  
fill ~16 ~0 ~17 ~17 ~0 ~17 stonebrick 3  
fill ~16 ~0 ~18 ~17 ~0 ~18 stonebrick 3  
fill ~16 ~0 ~19 ~17 ~0 ~19 stonebrick 3  
fill ~16 ~0 ~20 ~17 ~0 ~20 stonebrick 3  
fill ~16 ~0 ~21 ~17 ~0 ~21 stonebrick 3  
fill ~16 ~0 ~22 ~17 ~0 ~22 stonebrick 3  
fill ~16 ~0 ~23 ~17 ~0 ~23 stonebrick 3  
fill ~16 ~0 ~24 ~17 ~0 ~24 stonebrick 3  
fill ~16 ~0 ~25 ~17 ~0 ~25 stonebrick 3  
fill ~16 ~0 ~26 ~17 ~0 ~26 stonebrick 3  
fill ~16 ~0 ~27 ~16 ~3 ~27 stonebrick 3  
fill ~16 ~0 ~28 ~16 ~3 ~28 stonebrick 3  
fill ~16 ~0 ~29 ~16 ~7 ~29 stonebrick 3  
fill ~16 ~0 ~30 ~16 ~7 ~30 stonebrick 3  
fill ~16 ~0 ~31 ~16 ~7 ~31 stonebrick 3  
fill ~16 ~0 ~32 ~16 ~7 ~32 stonebrick 3  
fill ~16 ~0 ~33 ~16 ~7 ~33 stonebrick 3  
fill ~16 ~0 ~34 ~16 ~7 ~34 stonebrick 3  
fill ~16 ~0 ~35 ~16 ~7 ~35 stonebrick 3  
fill ~16 ~0 ~36 ~16 ~7 ~36 stonebrick 3  
fill ~16 ~0 ~37 ~16 ~7 ~37 stonebrick 3  
fill ~16 ~0 ~38 ~16 ~7 ~38 stonebrick 3  
fill ~16 ~0 ~39 ~16 ~7 ~39 stonebrick 3  
fill ~16 ~0 ~40 ~16 ~7 ~40 stonebrick 3  
fill ~16 ~0 ~41 ~16 ~7 ~41 stonebrick 3  
fill ~16 ~0 ~42 ~16 ~7 ~42 stonebrick 3  
fill ~16 ~0 ~43 ~16 ~7 ~43 stonebrick 3  
fill ~16 ~0 ~44 ~16 ~6 ~44 stonebrick 3  
fill ~16 ~0 ~45 ~16 ~5 ~45 stonebrick 3  
fill ~16 ~0 ~46 ~16 ~5 ~46 stonebrick 3  
fill ~16 ~0 ~47 ~17 ~0 ~47 stonebrick 3  
fill ~16 ~0 ~48 ~17 ~0 ~48 stonebrick 3  
fill ~16 ~0 ~49 ~17 ~0 ~49 stonebrick 3  
fill ~16 ~0 ~50 ~17 ~0 ~50 stonebrick 3  
fill ~16 ~0 ~51 ~17 ~0 ~51 stonebrick 3  
fill ~16 ~0 ~52 ~17 ~0 ~52 stonebrick 3  
fill ~16 ~0 ~53 ~17 ~0 ~53 stonebrick 3  
fill ~16 ~0 ~54 ~17 ~0 ~54 stonebrick 3  
fill ~16 ~0 ~55 ~17 ~0 ~55 stonebrick 3  
fill ~16 ~0 ~56 ~17 ~0 ~56 stonebrick 3  
fill ~16 ~0 ~57 ~17 ~0 ~57 stonebrick 3  
fill ~16 ~0 ~58 ~17 ~0 ~58 stonebrick 3  
fill ~16 ~0 ~59 ~17 ~0 ~59 stonebrick 3  
fill ~16 ~0 ~60 ~18 ~0 ~60 stonebrick 3  
fill ~16 ~0 ~61 ~18 ~0 ~61 stonebrick 3  
fill ~16 ~0 ~62 ~18 ~0 ~62 stonebrick 3  
fill ~16 ~0 ~63 ~18 ~0 ~63 stonebrick 3  
fill ~16 ~0 ~64 ~18 ~0 ~64 stonebrick 3  
fill ~16 ~0 ~65 ~19 ~0 ~65 stonebrick 3  
fill ~16 ~0 ~66 ~19 ~0 ~66 stonebrick 3  
fill ~17 ~0 ~27 ~18 ~0 ~27 dirt 0  
fill ~17 ~0 ~28 ~18 ~0 ~28 dirt 0  
fill ~17 ~0 ~29 ~17 ~0 ~46 dirt 0  
fill ~18 ~0 ~11 ~36 ~0 ~11 stone 0  
fill ~18 ~0 ~12 ~37 ~0 ~12 stone 0  
fill ~18 ~0 ~13 ~38 ~0 ~13 stone 0  
fill ~18 ~0 ~14 ~24 ~0 ~14 stone 0  
fill ~18 ~0 ~15 ~21 ~0 ~15 stone 0  
fill ~18 ~0 ~16 ~20 ~0 ~16 stone 0  
fill ~18 ~0 ~17 ~20 ~0 ~17 stone 0  
fill ~18 ~0 ~18 ~19 ~0 ~18 stone 0  
fill ~18 ~0 ~19 ~19 ~0 ~19 stone 0  
fill ~18 ~0 ~20 ~18 ~6 ~20 stone 0  
fill ~18 ~0 ~21 ~18 ~6 ~21 stone 0  
fill ~18 ~0 ~22 ~18 ~6 ~22 stone 0  
fill ~18 ~0 ~23 ~18 ~0 ~28 dirt 0  
fill ~18 ~0 ~29 ~19 ~0 ~29 stone 0  
fill ~18 ~0 ~30 ~19 ~0 ~30 stone 0  
fill ~18 ~0 ~31 ~64 ~0 ~31 stone 0  
fill ~18 ~0 ~32 ~64 ~0 ~32 stone 0  
fill ~18 ~0 ~33 ~64 ~0 ~33 stone 0  
fill ~18 ~0 ~34 ~64 ~0 ~34 stone 0  
fill ~18 ~0 ~35 ~18 ~3 ~35 dirt 0  
fill ~18 ~0 ~36 ~18 ~0 ~37 stone 0  
fill ~18 ~0 ~38 ~19 ~0 ~38 coal_ore 0  
fill ~18 ~0 ~39 ~65 ~0 ~39 stone 0  
fill ~18 ~0 ~40 ~18 ~3 ~40 dirt 0  
fill ~18 ~0 ~41 ~18 ~3 ~41 dirt 0  
fill ~18 ~0 ~42 ~18 ~3 ~42 dirt 0  
fill ~18 ~0 ~43 ~18 ~3 ~43 dirt 0  
fill ~18 ~0 ~44 ~18 ~2 ~44 dirt 0  
fill ~18 ~0 ~45 ~18 ~2 ~45 dirt 0  
fill ~18 ~0 ~46 ~19 ~0 ~46 dirt 0  
fill ~18 ~0 ~47 ~19 ~0 ~47 dirt 0  
fill ~18 ~0 ~48 ~19 ~0 ~48 dirt 0  
fill ~18 ~0 ~49 ~20 ~0 ~49 dirt 0  
fill ~18 ~0 ~50 ~20 ~0 ~50 dirt 0  
fill ~18 ~0 ~51 ~19 ~0 ~51 dirt 0  
fill ~18 ~0 ~52 ~20 ~0 ~52 dirt 0  
fill ~18 ~0 ~53 ~20 ~0 ~53 dirt 0  
fill ~18 ~0 ~54 ~20 ~0 ~54 dirt 0  
fill ~18 ~0 ~55 ~20 ~0 ~55 dirt 0  
fill ~18 ~0 ~56 ~20 ~0 ~56 dirt 0  
fill ~18 ~0 ~57 ~20 ~0 ~57 dirt 0  
fill ~18 ~0 ~58 ~20 ~0 ~58 dirt 0  
fill ~18 ~0 ~59 ~20 ~0 ~59 dirt 0  
fill ~19 ~0 ~20 ~20 ~0 ~20 dirt 0  
fill ~19 ~0 ~21 ~19 ~1 ~21 dirt 0  
fill ~19 ~0 ~22 ~19 ~2 ~22 dirt 0  
fill ~19 ~0 ~23 ~21 ~0 ~23 stone 0  
fill ~19 ~0 ~24 ~21 ~0 ~24 stone 0  
fill ~19 ~0 ~25 ~21 ~0 ~25 stone 0  
fill ~19 ~0 ~26 ~21 ~0 ~26 stone 0  
fill ~19 ~0 ~27 ~21 ~0 ~27 stone 0  
fill ~19 ~0 ~28 ~20 ~0 ~28 stone 0  
fill ~19 ~0 ~35 ~65 ~0 ~35 stone 0  
fill ~19 ~0 ~36 ~20 ~0 ~36 coal_ore 0  
fill ~19 ~0 ~37 ~20 ~0 ~37 coal_ore 0  
fill ~19 ~0 ~40 ~64 ~0 ~40 stone 0  
fill ~19 ~0 ~41 ~64 ~0 ~41 stone 0  
fill ~19 ~0 ~42 ~19 ~1 ~42 stone 0  
fill ~19 ~0 ~43 ~19 ~0 ~45 stone 0  
fill ~19 ~0 ~60 ~20 ~0 ~60 dirt 0  
fill ~19 ~0 ~61 ~20 ~0 ~61 dirt 0  
fill ~19 ~0 ~62 ~20 ~0 ~62 dirt 0  
fill ~19 ~0 ~63 ~20 ~0 ~63 dirt 0  
fill ~19 ~0 ~64 ~21 ~0 ~64 dirt 0 
setblock ~19 ~0 ~67 stonebrick 3  
fill ~20 ~0 ~18 ~21 ~0 ~18 dirt 0  
fill ~20 ~0 ~19 ~20 ~1 ~19 dirt 0  
fill ~20 ~0 ~21 ~23 ~0 ~21 stone 0  
fill ~20 ~0 ~22 ~22 ~0 ~22 stone 0  
fill ~20 ~0 ~29 ~28 ~0 ~29 gravel 0  
fill ~20 ~0 ~30 ~26 ~0 ~30 gravel 0  
fill ~20 ~0 ~38 ~66 ~0 ~38 stone 0  
fill ~20 ~0 ~42 ~22 ~0 ~42 coal_ore 0  
fill ~20 ~0 ~43 ~22 ~0 ~43 coal_ore 0  
fill ~20 ~0 ~44 ~20 ~2 ~44 stone 0  
fill ~20 ~0 ~45 ~64 ~0 ~45 stone 0  
fill ~20 ~0 ~46 ~69 ~0 ~46 stone 0  
fill ~20 ~0 ~47 ~41 ~0 ~47 stone 0  
fill ~20 ~0 ~48 ~40 ~0 ~48 stone 0  
fill ~20 ~0 ~51 ~37 ~0 ~51 stone 0  
fill ~20 ~0 ~65 ~21 ~0 ~65 dirt 0  
fill ~20 ~0 ~66 ~21 ~0 ~66 dirt 0  
fill ~20 ~0 ~67 ~21 ~0 ~67 dirt 0  
fill ~21 ~0 ~16 ~21 ~0 ~18 dirt 0  
fill ~21 ~0 ~19 ~41 ~0 ~19 stone 0  
fill ~21 ~0 ~20 ~24 ~0 ~20 stone 0  
fill ~21 ~0 ~28 ~29 ~0 ~28 gravel 0  
fill ~21 ~0 ~36 ~72 ~0 ~36 stone 0  
fill ~21 ~0 ~37 ~69 ~0 ~37 stone 0  
fill ~21 ~0 ~44 ~22 ~0 ~44 coal_ore 0  
fill ~21 ~0 ~49 ~38 ~0 ~49 stone 0  
fill ~21 ~0 ~50 ~37 ~0 ~50 stone 0  
fill ~21 ~0 ~52 ~37 ~0 ~52 stone 0  
fill ~21 ~0 ~53 ~37 ~0 ~53 stone 0  
fill ~21 ~0 ~54 ~63 ~0 ~54 stone 0  
fill ~21 ~0 ~55 ~63 ~0 ~55 stone 0  
fill ~21 ~0 ~56 ~29 ~0 ~56 stone 0  
fill ~21 ~0 ~57 ~29 ~0 ~57 stone 0  
fill ~21 ~0 ~58 ~29 ~0 ~58 stone 0  
fill ~21 ~0 ~59 ~29 ~0 ~59 stone 0  
fill ~21 ~0 ~60 ~30 ~0 ~60 stone 0  
fill ~21 ~0 ~61 ~26 ~0 ~61 stone 0  
fill ~21 ~0 ~62 ~25 ~0 ~62 stone 0  
fill ~21 ~0 ~63 ~34 ~0 ~63 stone 0  
fill ~22 ~0 ~15 ~22 ~0 ~16 clay 0  
fill ~22 ~0 ~17 ~37 ~0 ~17 stone 0  
fill ~22 ~0 ~18 ~39 ~0 ~18 stone 0  
fill ~22 ~0 ~23 ~26 ~0 ~23 gravel 0  
fill ~22 ~0 ~24 ~25 ~0 ~24 gravel 0  
fill ~22 ~0 ~25 ~22 ~0 ~27 coal_ore 0  
fill ~22 ~0 ~64 ~33 ~0 ~64 stone 0  
fill ~22 ~0 ~65 ~33 ~0 ~65 stone 0  
fill ~22 ~0 ~66 ~28 ~0 ~66 stone 0  
fill ~22 ~0 ~67 ~28 ~0 ~67 stone 0  
fill ~23 ~0 ~15 ~31 ~0 ~15 stone 0  
fill ~23 ~0 ~16 ~35 ~0 ~16 stone 0  
fill ~23 ~0 ~22 ~26 ~0 ~22 gravel 0  
fill ~23 ~0 ~25 ~24 ~0 ~25 gravel 0  
fill ~23 ~0 ~26 ~36 ~0 ~26 stone 0  
fill ~23 ~0 ~27 ~29 ~0 ~27 gravel 0  
fill ~23 ~0 ~42 ~64 ~0 ~42 stone 0  
fill ~23 ~0 ~43 ~64 ~0 ~43 stone 0  
fill ~23 ~0 ~44 ~66 ~0 ~44 stone 0  
fill ~23 ~0 ~68 ~27 ~0 ~68 stone 0  
fill ~24 ~0 ~21 ~26 ~0 ~21 gravel 0  
fill ~25 ~0 ~14 ~32 ~0 ~14 dirt 0  
fill ~25 ~0 ~20 ~26 ~0 ~20 gravel 0  
fill ~25 ~0 ~25 ~35 ~0 ~25 stone 0  
fill ~26 ~0 ~24 ~55 ~0 ~24 stone 0 
setblock ~26 ~0 ~62 iron_ore 0  
fill ~27 ~0 ~20 ~42 ~0 ~20 stone 0  
fill ~27 ~0 ~21 ~42 ~0 ~21 stone 0  
fill ~27 ~0 ~22 ~43 ~0 ~22 stone 0  
fill ~27 ~0 ~23 ~43 ~0 ~23 stone 0  
fill ~27 ~0 ~30 ~64 ~0 ~30 stone 0 
setblock ~27 ~0 ~61 iron_ore 0  
fill ~27 ~0 ~62 ~31 ~0 ~62 stone 0  
fill ~28 ~0 ~61 ~30 ~0 ~61 stone 0  
fill ~28 ~0 ~68 ~29 ~0 ~68 coal_ore 0  
fill ~29 ~0 ~29 ~58 ~0 ~29 stone 0  
fill ~29 ~0 ~66 ~30 ~0 ~66 coal_ore 0  
fill ~29 ~0 ~67 ~30 ~0 ~67 coal_ore 0  
fill ~30 ~0 ~27 ~36 ~0 ~27 stone 0  
fill ~30 ~0 ~28 ~53 ~0 ~28 stone 0  
fill ~30 ~0 ~56 ~32 ~0 ~56 dirt 0  
fill ~30 ~0 ~57 ~33 ~0 ~57 dirt 0  
fill ~30 ~0 ~58 ~34 ~0 ~58 dirt 0  
fill ~30 ~0 ~59 ~34 ~0 ~59 dirt 0  
fill ~30 ~0 ~68 ~33 ~0 ~68 stone 0  
fill ~31 ~0 ~60 ~35 ~0 ~60 dirt 0  
fill ~31 ~0 ~61 ~35 ~0 ~61 dirt 0  
fill ~31 ~0 ~66 ~33 ~0 ~66 stone 0  
fill ~31 ~0 ~67 ~33 ~0 ~67 stone 0  
fill ~32 ~0 ~5 ~34 ~0 ~5 stonebrick 3  
fill ~32 ~0 ~15 ~35 ~0 ~15 dirt 0  
fill ~32 ~0 ~62 ~36 ~0 ~62 dirt 0  
fill ~33 ~0 ~4 ~33 ~3 ~4 stonebrick 3  
fill ~33 ~0 ~6 ~33 ~3 ~6 stonebrick 3  
fill ~33 ~0 ~14 ~39 ~0 ~14 stone 0  
fill ~33 ~0 ~56 ~61 ~0 ~56 stone 0  
fill ~34 ~0 ~57 ~60 ~0 ~57 stone 0  
fill ~34 ~0 ~64 ~37 ~0 ~64 dirt 0  
fill ~34 ~0 ~65 ~37 ~0 ~65 dirt 0  
fill ~34 ~0 ~66 ~37 ~0 ~66 dirt 0  
fill ~34 ~0 ~67 ~37 ~0 ~67 dirt 0  
fill ~34 ~0 ~68 ~37 ~0 ~68 dirt 0  
fill ~35 ~0 ~58 ~59 ~0 ~58 stone 0  
fill ~35 ~0 ~59 ~58 ~0 ~59 stone 0  
fill ~35 ~0 ~63 ~36 ~0 ~63 dirt 0  
fill ~36 ~0 ~8 ~53 ~0 ~8 gravel 0  
fill ~36 ~0 ~9 ~54 ~0 ~9 gravel 0  
fill ~36 ~0 ~10 ~55 ~0 ~10 gravel 0  
fill ~36 ~0 ~15 ~40 ~0 ~15 stone 0  
fill ~36 ~0 ~16 ~40 ~0 ~16 dirt 0 
setblock ~36 ~0 ~25 coal_ore 0  
fill ~36 ~0 ~60 ~57 ~0 ~60 stone 0  
fill ~36 ~0 ~61 ~56 ~0 ~61 stone 0  
fill ~37 ~0 ~11 ~56 ~0 ~11 gravel 0  
fill ~37 ~0 ~25 ~56 ~0 ~25 stone 0  
fill ~37 ~0 ~26 ~37 ~0 ~27 coal_ore 0  
fill ~37 ~0 ~62 ~55 ~0 ~62 stone 0  
fill ~37 ~0 ~63 ~54 ~0 ~63 stone 0  
fill ~38 ~0 ~12 ~57 ~0 ~12 gravel 0  
fill ~38 ~0 ~17 ~41 ~0 ~17 dirt 0  
fill ~38 ~0 ~26 ~50 ~0 ~26 stone 0 
setblock ~38 ~0 ~27 coal_ore 0  
fill ~38 ~0 ~50 ~43 ~0 ~50 dirt 0  
fill ~38 ~0 ~51 ~43 ~0 ~51 dirt 0  
fill ~38 ~0 ~52 ~42 ~0 ~52 dirt 0  
fill ~38 ~0 ~53 ~40 ~0 ~53 dirt 0  
fill ~38 ~0 ~64 ~53 ~0 ~64 stone 0  
fill ~38 ~0 ~65 ~52 ~0 ~65 stone 0  
fill ~38 ~0 ~66 ~51 ~0 ~66 stone 0  
fill ~38 ~0 ~67 ~50 ~0 ~67 stone 0  
fill ~38 ~0 ~68 ~49 ~0 ~68 stone 0  
fill ~38 ~0 ~69 ~48 ~0 ~69 stone 0  
fill ~38 ~0 ~70 ~47 ~0 ~70 stone 0  
fill ~38 ~0 ~71 ~39 ~0 ~71 dirt 0  
fill ~38 ~0 ~72 ~38 ~0 ~71 dirt 0  
fill ~38 ~0 ~73 ~42 ~0 ~73 stone 0  
fill ~39 ~0 ~13 ~78 ~0 ~13 gravel 0  
fill ~39 ~0 ~27 ~53 ~0 ~27 stone 0  
fill ~39 ~0 ~49 ~44 ~0 ~49 dirt 0  
fill ~39 ~0 ~72 ~45 ~0 ~72 stone 0  
fill ~40 ~0 ~14 ~78 ~0 ~14 gravel 0  
fill ~40 ~0 ~18 ~42 ~0 ~18 dirt 0  
fill ~40 ~0 ~71 ~46 ~0 ~71 stone 0  
fill ~41 ~0 ~15 ~78 ~0 ~15 gravel 0 
setblock ~41 ~0 ~16 stone 0  
fill ~41 ~0 ~48 ~44 ~0 ~48 dirt 0  
fill ~41 ~0 ~53 ~63 ~0 ~53 stone 0  
fill ~42 ~0 ~16 ~78 ~0 ~16 gravel 0 
setblock ~42 ~0 ~17 stone 0  
fill ~42 ~0 ~19 ~43 ~0 ~19 dirt 0  
fill ~42 ~0 ~47 ~44 ~0 ~47 dirt 0  
fill ~43 ~0 ~17 ~78 ~0 ~17 gravel 0 
setblock ~43 ~0 ~18 stone 0  
fill ~43 ~0 ~20 ~44 ~0 ~20 dirt 0  
fill ~43 ~0 ~21 ~45 ~0 ~21 dirt 0  
fill ~43 ~0 ~52 ~54 ~0 ~52 stone 0 
setblock ~43 ~0 ~73 dirt 0  
fill ~44 ~0 ~18 ~78 ~0 ~18 gravel 0 
setblock ~44 ~0 ~19 stone 0  
fill ~44 ~0 ~22 ~46 ~0 ~22 dirt 0  
fill ~44 ~0 ~23 ~48 ~0 ~23 dirt 0  
fill ~44 ~0 ~50 ~59 ~0 ~50 stone 0  
fill ~44 ~0 ~51 ~59 ~0 ~51 stone 0 
setblock ~44 ~0 ~73 stone 0  
fill ~45 ~0 ~19 ~78 ~0 ~19 gravel 0 
setblock ~45 ~0 ~20 stone 0  
fill ~45 ~0 ~47 ~63 ~0 ~47 stone 0  
fill ~45 ~0 ~48 ~63 ~0 ~48 stone 0  
fill ~45 ~0 ~49 ~59 ~0 ~49 stone 0  
fill ~45 ~0 ~73 ~78 ~0 ~73 gravel 0  
fill ~46 ~0 ~20 ~78 ~0 ~20 gravel 0  
fill ~46 ~0 ~21 ~60 ~0 ~21 stone 0  
fill ~46 ~0 ~72 ~78 ~0 ~72 gravel 0  
fill ~47 ~0 ~22 ~60 ~0 ~22 stone 0  
fill ~47 ~0 ~71 ~78 ~0 ~71 gravel 0  
fill ~48 ~0 ~70 ~78 ~0 ~70 gravel 0  
fill ~49 ~0 ~23 ~67 ~0 ~23 stone 0  
fill ~49 ~0 ~69 ~78 ~0 ~69 gravel 0  
fill ~50 ~0 ~68 ~78 ~0 ~68 gravel 0  
fill ~51 ~0 ~26 ~52 ~0 ~26 stonebrick 3  
fill ~51 ~0 ~67 ~78 ~0 ~67 gravel 0  
fill ~52 ~0 ~66 ~78 ~0 ~66 gravel 0  
fill ~53 ~0 ~26 ~65 ~0 ~26 stone 0  
fill ~53 ~0 ~65 ~78 ~0 ~65 gravel 0  
fill ~54 ~0 ~27 ~54 ~0 ~28 dirt 0  
fill ~54 ~0 ~64 ~78 ~0 ~64 gravel 0  
fill ~55 ~0 ~27 ~58 ~0 ~27 stone 0  
fill ~55 ~0 ~28 ~58 ~0 ~28 stone 0  
fill ~55 ~0 ~52 ~64 ~0 ~52 bedrock 0  
fill ~55 ~0 ~63 ~78 ~0 ~63 gravel 0 
setblock ~56 ~0 ~24 dirt 0  
fill ~56 ~0 ~62 ~78 ~0 ~62 gravel 0  
fill ~57 ~0 ~24 ~65 ~0 ~24 stone 0 
setblock ~57 ~0 ~25 dirt 0  
fill ~57 ~0 ~61 ~78 ~0 ~61 gravel 0  
fill ~58 ~0 ~25 ~64 ~0 ~25 stone 0  
fill ~58 ~0 ~60 ~78 ~0 ~60 gravel 0  
fill ~59 ~0 ~27 ~59 ~0 ~29 dirt 0  
fill ~59 ~0 ~59 ~76 ~0 ~59 gravel 0  
fill ~60 ~0 ~27 ~67 ~0 ~27 stone 0  
fill ~60 ~0 ~28 ~69 ~0 ~28 stone 0  
fill ~60 ~0 ~29 ~72 ~0 ~29 stone 0  
fill ~60 ~0 ~49 ~60 ~1 ~49 bedrock 0  
fill ~60 ~0 ~50 ~60 ~1 ~50 bedrock 0  
fill ~60 ~0 ~51 ~60 ~1 ~51 bedrock 0  
fill ~60 ~0 ~58 ~63 ~0 ~58 gravel 0  
fill ~61 ~0 ~21 ~62 ~0 ~21 stonebrick 3  
fill ~61 ~0 ~22 ~62 ~0 ~22 stonebrick 3  
fill ~61 ~0 ~49 ~63 ~0 ~49 stone 0  
fill ~61 ~0 ~50 ~62 ~0 ~50 stonebrick 3  
fill ~61 ~0 ~51 ~62 ~0 ~51 stonebrick 3  
fill ~61 ~0 ~57 ~63 ~0 ~57 gravel 0  
fill ~62 ~0 ~56 ~63 ~0 ~56 gravel 0  
fill ~63 ~0 ~21 ~70 ~0 ~21 stone 0  
fill ~63 ~0 ~22 ~69 ~0 ~22 stone 0  
fill ~63 ~0 ~50 ~63 ~1 ~50 bedrock 0  
fill ~63 ~0 ~51 ~67 ~0 ~51 bedrock 0  
fill ~64 ~0 ~47 ~76 ~0 ~47 bedrock 0  
fill ~64 ~0 ~48 ~64 ~1 ~48 bedrock 0  
fill ~64 ~0 ~49 ~64 ~0 ~50 glowstone 0  
fill ~64 ~0 ~53 ~65 ~0 ~53 glowstone 0  
fill ~64 ~0 ~54 ~64 ~0 ~58 glowstone 0  
fill ~65 ~0 ~25 ~65 ~1 ~25 bedrock 0  
fill ~65 ~0 ~30 ~65 ~0 ~34 bedrock 0  
fill ~65 ~0 ~40 ~70 ~0 ~40 wool 3  
fill ~65 ~0 ~41 ~66 ~0 ~41 wool 3  
fill ~65 ~0 ~42 ~66 ~0 ~42 wool 3  
fill ~65 ~0 ~43 ~70 ~0 ~43 wool 3  
fill ~65 ~0 ~45 ~68 ~0 ~45 bedrock 0  
fill ~65 ~0 ~48 ~75 ~0 ~48 glass 0  
fill ~65 ~0 ~49 ~66 ~0 ~49 stone 0  
fill ~65 ~0 ~50 ~73 ~0 ~50 glowstone 0  
fill ~65 ~0 ~52 ~68 ~0 ~52 glowstone 0  
fill ~65 ~0 ~54 ~68 ~0 ~54 gravel 0 
setblock ~65 ~0 ~55 bedrock 0  
fill ~65 ~0 ~56 ~75 ~0 ~56 gravel 0  
fill ~65 ~0 ~57 ~75 ~0 ~57 gravel 0  
fill ~65 ~0 ~58 ~76 ~0 ~58 glowstone 0  
fill ~66 ~0 ~24 ~67 ~0 ~24 bedrock 0  
fill ~66 ~0 ~25 ~71 ~0 ~25 stone 0  
fill ~66 ~0 ~26 ~67 ~0 ~26 bedrock 0  
fill ~66 ~0 ~30 ~66 ~1 ~30 wool 3  
fill ~66 ~0 ~31 ~67 ~0 ~31 stone 0  
fill ~66 ~0 ~32 ~67 ~0 ~32 stone 0  
fill ~66 ~0 ~33 ~67 ~0 ~33 stone 0  
fill ~66 ~0 ~34 ~66 ~0 ~35 bedrock 0 
setblock ~66 ~0 ~39 bedrock 0  
fill ~66 ~0 ~53 ~71 ~0 ~53 bedrock 0 
setblock ~66 ~0 ~55 gravel 0  
fill ~67 ~0 ~30 ~68 ~0 ~30 stone 0 
setblock ~67 ~0 ~34 stone 0 
setblock ~67 ~0 ~35 bedrock 0  
fill ~67 ~0 ~38 ~68 ~0 ~38 bedrock 0  
fill ~67 ~0 ~39 ~72 ~0 ~39 wool 3  
fill ~67 ~0 ~41 ~68 ~0 ~41 bedrock 0  
fill ~67 ~0 ~42 ~69 ~0 ~42 bedrock 0  
fill ~67 ~0 ~44 ~73 ~0 ~44 wool 3  
fill ~67 ~0 ~49 ~74 ~0 ~49 bedrock 0  
fill ~67 ~0 ~55 ~76 ~0 ~55 glowstone 0  
fill ~68 ~0 ~23 ~69 ~0 ~23 bedrock 0  
fill ~68 ~0 ~24 ~71 ~0 ~24 stone 0  
fill ~68 ~0 ~26 ~72 ~0 ~26 stone 0  
fill ~68 ~0 ~27 ~69 ~0 ~27 bedrock 0  
fill ~68 ~0 ~31 ~68 ~1 ~31 bedrock 0  
fill ~68 ~0 ~32 ~68 ~1 ~32 bedrock 0  
fill ~68 ~0 ~33 ~68 ~0 ~34 bedrock 0  
fill ~68 ~0 ~35 ~70 ~0 ~35 stone 0  
fill ~68 ~0 ~51 ~71 ~0 ~51 glowstone 0  
fill ~69 ~0 ~30 ~71 ~0 ~30 bedrock 0  
fill ~69 ~0 ~31 ~69 ~0 ~37 stone 0  
fill ~69 ~0 ~38 ~75 ~0 ~38 wool 3  
fill ~69 ~0 ~41 ~72 ~0 ~41 stone 0  
fill ~69 ~0 ~45 ~75 ~0 ~45 wool 3  
fill ~69 ~0 ~52 ~73 ~0 ~52 bedrock 0  
fill ~69 ~0 ~54 ~72 ~0 ~54 glowstone 0  
fill ~70 ~0 ~22 ~74 ~0 ~22 bedrock 0  
fill ~70 ~0 ~23 ~71 ~0 ~23 stone 0  
fill ~70 ~0 ~27 ~72 ~0 ~27 stone 0  
fill ~70 ~0 ~28 ~71 ~0 ~28 bedrock 0  
fill ~70 ~0 ~31 ~71 ~0 ~31 bedrock 0  
fill ~70 ~0 ~32 ~70 ~0 ~36 stone 0  
fill ~70 ~0 ~37 ~71 ~0 ~37 bedrock 0  
fill ~70 ~0 ~42 ~72 ~0 ~42 stone 0  
fill ~70 ~0 ~46 ~71 ~0 ~46 bedrock 0  
fill ~71 ~0 ~21 ~74 ~0 ~21 bedrock 0  
fill ~71 ~0 ~32 ~71 ~1 ~32 bedrock 0  
fill ~71 ~0 ~33 ~71 ~1 ~33 bedrock 0  
fill ~71 ~0 ~34 ~71 ~1 ~34 bedrock 0  
fill ~71 ~0 ~35 ~71 ~1 ~35 bedrock 0  
fill ~71 ~0 ~40 ~72 ~0 ~40 stone 0  
fill ~71 ~0 ~43 ~74 ~0 ~43 bedrock 0  
fill ~72 ~0 ~23 ~74 ~0 ~23 bedrock 0  
fill ~72 ~0 ~24 ~74 ~0 ~24 bedrock 0  
fill ~72 ~0 ~25 ~74 ~0 ~25 bedrock 0 
setblock ~72 ~0 ~28 stone 0  
fill ~72 ~0 ~30 ~72 ~0 ~36 stone 0  
fill ~72 ~0 ~37 ~75 ~0 ~37 wool 3  
fill ~72 ~0 ~46 ~75 ~0 ~46 wool 3  
fill ~72 ~0 ~51 ~73 ~0 ~51 bedrock 0  
fill ~72 ~0 ~53 ~75 ~0 ~53 glowstone 0  
fill ~73 ~0 ~26 ~74 ~0 ~26 bedrock 0  
fill ~73 ~0 ~27 ~74 ~0 ~27 bedrock 0  
fill ~73 ~0 ~28 ~74 ~0 ~28 bedrock 0  
fill ~73 ~0 ~29 ~74 ~0 ~29 bedrock 0  
fill ~73 ~0 ~30 ~74 ~0 ~30 bedrock 0  
fill ~73 ~0 ~31 ~74 ~0 ~31 bedrock 0  
fill ~73 ~0 ~32 ~74 ~0 ~32 bedrock 0  
fill ~73 ~0 ~33 ~74 ~0 ~33 bedrock 0  
fill ~73 ~0 ~34 ~74 ~0 ~34 bedrock 0  
fill ~73 ~0 ~35 ~74 ~0 ~35 bedrock 0  
fill ~73 ~0 ~36 ~74 ~0 ~36 bedrock 0  
fill ~73 ~0 ~39 ~74 ~0 ~39 bedrock 0  
fill ~73 ~0 ~40 ~74 ~0 ~40 bedrock 0  
fill ~73 ~0 ~41 ~74 ~0 ~41 bedrock 0  
fill ~73 ~0 ~42 ~74 ~0 ~42 bedrock 0  
fill ~73 ~0 ~54 ~76 ~0 ~54 bedrock 0  
fill ~74 ~0 ~44 ~75 ~0 ~44 stone 0 
setblock ~74 ~0 ~50 bedrock 0  
fill ~75 ~0 ~21 ~78 ~0 ~21 gravel 0  
fill ~75 ~0 ~22 ~78 ~0 ~22 gravel 0  
fill ~75 ~0 ~23 ~78 ~0 ~23 gravel 0  
fill ~75 ~0 ~24 ~78 ~0 ~24 gravel 0  
fill ~75 ~0 ~25 ~78 ~0 ~25 gravel 0  
fill ~75 ~0 ~26 ~78 ~0 ~26 gravel 0  
fill ~75 ~0 ~27 ~78 ~0 ~27 gravel 0  
fill ~75 ~0 ~28 ~78 ~0 ~28 gravel 0  
fill ~75 ~0 ~29 ~75 ~1 ~29 wool 3  
fill ~75 ~0 ~30 ~78 ~0 ~30 gravel 0  
fill ~75 ~0 ~31 ~75 ~1 ~31 wool 3  
fill ~75 ~0 ~32 ~78 ~0 ~32 gravel 0  
fill ~75 ~0 ~33 ~78 ~0 ~33 gravel 0  
fill ~75 ~0 ~34 ~78 ~0 ~34 gravel 0  
fill ~75 ~0 ~35 ~78 ~0 ~35 gravel 0  
fill ~75 ~0 ~36 ~78 ~0 ~36 gravel 0  
fill ~75 ~0 ~39 ~78 ~0 ~39 gravel 0  
fill ~75 ~0 ~40 ~78 ~0 ~40 gravel 0  
fill ~75 ~0 ~41 ~78 ~0 ~41 gravel 0  
fill ~75 ~0 ~42 ~78 ~0 ~42 gravel 0  
fill ~75 ~0 ~43 ~78 ~0 ~43 gravel 0  
fill ~75 ~0 ~49 ~75 ~0 ~51 glass 0  
fill ~75 ~0 ~52 ~76 ~0 ~52 bedrock 0  
fill ~76 ~0 ~29 ~78 ~0 ~29 gravel 0  
fill ~76 ~0 ~31 ~78 ~0 ~31 gravel 0  
fill ~76 ~0 ~37 ~78 ~0 ~37 gravel 0  
fill ~76 ~0 ~38 ~78 ~0 ~38 gravel 0  
fill ~76 ~0 ~44 ~78 ~0 ~44 gravel 0  
fill ~76 ~0 ~45 ~76 ~0 ~46 stone 0  
fill ~76 ~0 ~48 ~76 ~1 ~48 bedrock 0  
fill ~76 ~0 ~49 ~76 ~1 ~49 bedrock 0  
fill ~76 ~0 ~50 ~76 ~1 ~50 bedrock 0  
fill ~76 ~0 ~51 ~76 ~1 ~51 bedrock 0  
fill ~76 ~0 ~53 ~77 ~0 ~53 gravel 0  
fill ~76 ~0 ~56 ~76 ~0 ~58 glowstone 0  
fill ~77 ~0 ~45 ~78 ~0 ~45 gravel 0  
fill ~77 ~0 ~46 ~78 ~0 ~46 gravel 0  
fill ~77 ~0 ~47 ~78 ~0 ~47 gravel 0  
fill ~77 ~0 ~48 ~78 ~0 ~48 gravel 0  
fill ~77 ~0 ~49 ~78 ~0 ~49 gravel 0  
fill ~77 ~0 ~50 ~78 ~0 ~50 gravel 0  
fill ~77 ~0 ~51 ~78 ~0 ~51 gravel 0  
fill ~77 ~0 ~52 ~78 ~0 ~52 gravel 0  
fill ~77 ~0 ~54 ~77 ~0 ~55 gravel 0  
fill ~77 ~0 ~56 ~78 ~0 ~56 sand 0  
fill ~77 ~0 ~57 ~78 ~0 ~57 sand 0  
fill ~77 ~0 ~58 ~77 ~1 ~58 bedrock 0  
fill ~77 ~0 ~59 ~78 ~0 ~59 sand 0  
fill ~78 ~0 ~53 ~78 ~0 ~59 sand 0  
fill ~8 ~1 ~5 ~10 ~1 ~5 stonebrick 3  
fill ~8 ~1 ~26 ~10 ~1 ~26 stonebrick 3  
fill ~8 ~1 ~46 ~10 ~1 ~46 stonebrick 3  
fill ~8 ~1 ~67 ~10 ~1 ~67 stonebrick 3  
fill ~16 ~1 ~11 ~17 ~1 ~11 stonebrick 3  
fill ~16 ~1 ~12 ~17 ~1 ~12 stonebrick 3  
fill ~16 ~1 ~13 ~17 ~1 ~13 stonebrick 3  
fill ~16 ~1 ~14 ~17 ~1 ~14 stonebrick 3  
fill ~16 ~1 ~15 ~17 ~1 ~15 stonebrick 3  
fill ~16 ~1 ~16 ~17 ~1 ~16 stonebrick 3  
fill ~16 ~1 ~17 ~17 ~1 ~17 stonebrick 3  
fill ~16 ~1 ~18 ~17 ~1 ~18 stonebrick 3  
fill ~16 ~1 ~19 ~17 ~1 ~19 stonebrick 3  
fill ~16 ~1 ~20 ~17 ~1 ~20 stonebrick 3  
fill ~16 ~1 ~21 ~17 ~1 ~21 stonebrick 3  
fill ~16 ~1 ~22 ~17 ~1 ~22 stonebrick 3  
fill ~16 ~1 ~23 ~17 ~1 ~23 stonebrick 3  
fill ~16 ~1 ~24 ~17 ~1 ~24 stonebrick 3  
fill ~16 ~1 ~25 ~17 ~1 ~25 stonebrick 3  
fill ~16 ~1 ~26 ~17 ~1 ~26 stonebrick 3  
fill ~16 ~1 ~47 ~17 ~1 ~47 stonebrick 3  
fill ~16 ~1 ~48 ~18 ~1 ~48 stonebrick 3  
fill ~16 ~1 ~49 ~18 ~1 ~49 stonebrick 3  
fill ~16 ~1 ~50 ~18 ~1 ~50 stonebrick 3  
fill ~16 ~1 ~51 ~18 ~1 ~51 stonebrick 3  
fill ~16 ~1 ~52 ~18 ~1 ~52 stonebrick 3  
fill ~16 ~1 ~53 ~18 ~1 ~53 stonebrick 3  
fill ~16 ~1 ~54 ~18 ~1 ~54 stonebrick 3  
fill ~16 ~1 ~55 ~18 ~1 ~55 stonebrick 3  
fill ~16 ~1 ~56 ~18 ~1 ~56 stonebrick 3  
fill ~16 ~1 ~57 ~18 ~1 ~57 stonebrick 3  
fill ~16 ~1 ~58 ~18 ~1 ~58 stonebrick 3  
fill ~16 ~1 ~59 ~18 ~1 ~59 stonebrick 3  
fill ~16 ~1 ~60 ~18 ~1 ~60 stonebrick 3  
fill ~16 ~1 ~61 ~19 ~1 ~61 stonebrick 3  
fill ~16 ~1 ~62 ~19 ~1 ~62 stonebrick 3  
fill ~16 ~1 ~63 ~19 ~1 ~63 stonebrick 3  
fill ~16 ~1 ~64 ~19 ~1 ~64 stonebrick 3  
fill ~16 ~1 ~65 ~19 ~1 ~65 stonebrick 3  
fill ~16 ~1 ~66 ~20 ~1 ~66 stonebrick 3  
fill ~17 ~1 ~27 ~17 ~1 ~29 stonebrick 3  
fill ~17 ~1 ~30 ~17 ~1 ~33 dirt 0  
fill ~17 ~1 ~34 ~17 ~2 ~34 stonebrick 3  
fill ~17 ~1 ~35 ~17 ~2 ~35 stonebrick 3  
fill ~17 ~1 ~36 ~17 ~2 ~36 stonebrick 3  
fill ~17 ~1 ~37 ~18 ~1 ~37 dirt 0  
fill ~17 ~1 ~38 ~18 ~1 ~38 dirt 0  
fill ~17 ~1 ~39 ~18 ~1 ~39 dirt 0  
fill ~17 ~1 ~40 ~17 ~1 ~43 dirt 0  
fill ~17 ~1 ~44 ~17 ~6 ~44 stonebrick 3  
fill ~17 ~1 ~45 ~17 ~5 ~45 stonebrick 3  
fill ~17 ~1 ~46 ~17 ~5 ~46 stonebrick 3  
fill ~18 ~1 ~11 ~34 ~1 ~11 stone 0  
fill ~18 ~1 ~12 ~35 ~1 ~12 stone 0  
fill ~18 ~1 ~13 ~35 ~1 ~13 stone 0  
fill ~18 ~1 ~14 ~35 ~1 ~14 stone 0  
fill ~18 ~1 ~15 ~21 ~1 ~15 stone 0  
fill ~18 ~1 ~16 ~21 ~1 ~16 stone 0  
fill ~18 ~1 ~17 ~20 ~1 ~17 stone 0  
fill ~18 ~1 ~18 ~20 ~1 ~18 stone 0  
fill ~18 ~1 ~19 ~19 ~1 ~19 stone 0  
fill ~18 ~1 ~23 ~18 ~6 ~23 stone 0  
fill ~18 ~1 ~24 ~18 ~6 ~24 stone 0  
fill ~18 ~1 ~25 ~19 ~1 ~25 dirt 0  
fill ~18 ~1 ~26 ~19 ~1 ~26 dirt 0  
fill ~18 ~1 ~27 ~19 ~1 ~27 dirt 0  
fill ~18 ~1 ~28 ~18 ~2 ~28 dirt 0  
fill ~18 ~1 ~29 ~18 ~3 ~29 dirt 0  
fill ~18 ~1 ~30 ~20 ~1 ~30 stone 0  
fill ~18 ~1 ~31 ~40 ~1 ~31 stone 0  
fill ~18 ~1 ~32 ~40 ~1 ~32 stone 0  
fill ~18 ~1 ~33 ~18 ~4 ~33 dirt 0  
fill ~18 ~1 ~34 ~18 ~4 ~34 dirt 0  
fill ~18 ~1 ~36 ~18 ~3 ~36 dirt 0  
fill ~18 ~1 ~46 ~20 ~1 ~46 dirt 0  
fill ~18 ~1 ~47 ~20 ~1 ~47 dirt 0  
fill ~19 ~1 ~20 ~19 ~6 ~20 stone 0  
fill ~19 ~1 ~23 ~19 ~4 ~23 dirt 0  
fill ~19 ~1 ~24 ~19 ~4 ~24 dirt 0  
fill ~19 ~1 ~28 ~21 ~1 ~28 stone 0  
fill ~19 ~1 ~29 ~20 ~1 ~29 stone 0  
fill ~19 ~1 ~33 ~40 ~1 ~33 stone 0  
fill ~19 ~1 ~34 ~40 ~1 ~34 stone 0  
fill ~19 ~1 ~35 ~40 ~1 ~35 stone 0  
fill ~19 ~1 ~36 ~40 ~1 ~36 stone 0  
fill ~19 ~1 ~37 ~40 ~1 ~37 stone 0  
fill ~19 ~1 ~38 ~40 ~1 ~38 stone 0  
fill ~19 ~1 ~39 ~40 ~1 ~39 stone 0  
fill ~19 ~1 ~40 ~40 ~1 ~40 stone 0  
fill ~19 ~1 ~41 ~40 ~1 ~41 stone 0  
fill ~19 ~1 ~43 ~19 ~4 ~43 dirt 0 
setblock ~19 ~1 ~44 stone 0  
fill ~19 ~1 ~45 ~19 ~4 ~45 dirt 0  
fill ~19 ~1 ~48 ~19 ~4 ~48 dirt 0  
fill ~19 ~1 ~49 ~20 ~1 ~49 dirt 0  
fill ~19 ~1 ~50 ~21 ~1 ~50 dirt 0  
fill ~19 ~1 ~51 ~21 ~1 ~51 dirt 0  
fill ~19 ~1 ~52 ~20 ~1 ~52 dirt 0  
fill ~19 ~1 ~53 ~20 ~1 ~53 dirt 0  
fill ~19 ~1 ~54 ~20 ~1 ~54 dirt 0  
fill ~19 ~1 ~55 ~20 ~1 ~55 dirt 0  
fill ~19 ~1 ~56 ~20 ~1 ~56 dirt 0  
fill ~19 ~1 ~57 ~20 ~1 ~57 dirt 0  
fill ~19 ~1 ~58 ~21 ~1 ~58 dirt 0  
fill ~19 ~1 ~59 ~21 ~1 ~59 dirt 0  
fill ~19 ~1 ~60 ~21 ~1 ~60 dirt 0  
fill ~20 ~1 ~20 ~20 ~1 ~21 dirt 0  
fill ~20 ~1 ~22 ~21 ~1 ~22 stone 0  
fill ~20 ~1 ~23 ~21 ~1 ~23 stone 0  
fill ~20 ~1 ~24 ~21 ~1 ~24 stone 0  
fill ~20 ~1 ~25 ~21 ~1 ~25 stone 0  
fill ~20 ~1 ~26 ~20 ~1 ~45 stone 0  
fill ~20 ~1 ~48 ~39 ~1 ~48 stone 0  
fill ~20 ~1 ~61 ~21 ~1 ~61 dirt 0  
fill ~20 ~1 ~62 ~21 ~1 ~62 dirt 0  
fill ~20 ~1 ~63 ~21 ~1 ~63 dirt 0  
fill ~20 ~1 ~64 ~21 ~1 ~64 dirt 0  
fill ~20 ~1 ~65 ~22 ~1 ~65 dirt 0  
fill ~20 ~1 ~67 ~20 ~7 ~67 stonebrick 3  
fill ~21 ~1 ~17 ~21 ~1 ~18 dirt 0  
fill ~21 ~1 ~19 ~35 ~1 ~19 stone 0  
fill ~21 ~1 ~20 ~24 ~1 ~20 stone 0  
fill ~21 ~1 ~21 ~22 ~1 ~21 stone 0  
fill ~21 ~1 ~26 ~23 ~1 ~26 gravel 0  
fill ~21 ~1 ~27 ~24 ~1 ~27 stone 0  
fill ~21 ~1 ~29 ~27 ~1 ~29 gravel 0  
fill ~21 ~1 ~30 ~21 ~1 ~29 gravel 0  
fill ~21 ~1 ~42 ~21 ~1 ~43 coal_ore 0  
fill ~21 ~1 ~44 ~56 ~1 ~44 stone 0  
fill ~21 ~1 ~45 ~55 ~1 ~45 stone 0  
fill ~21 ~1 ~46 ~40 ~1 ~46 stone 0  
fill ~21 ~1 ~47 ~39 ~1 ~47 stone 0  
fill ~21 ~1 ~49 ~39 ~1 ~49 stone 0  
fill ~21 ~1 ~52 ~39 ~1 ~52 stone 0  
fill ~21 ~1 ~53 ~39 ~1 ~53 stone 0  
fill ~21 ~1 ~54 ~39 ~1 ~54 stone 0  
fill ~21 ~1 ~55 ~39 ~1 ~55 stone 0  
fill ~21 ~1 ~56 ~29 ~1 ~56 stone 0  
fill ~21 ~1 ~57 ~28 ~1 ~57 stone 0  
fill ~21 ~1 ~66 ~22 ~1 ~66 dirt 0  
fill ~21 ~1 ~67 ~22 ~1 ~67 dirt 0  
fill ~22 ~1 ~15 ~23 ~1 ~15 dirt 0  
fill ~22 ~1 ~16 ~22 ~1 ~15 dirt 0  
fill ~22 ~1 ~17 ~35 ~1 ~17 stone 0  
fill ~22 ~1 ~18 ~35 ~1 ~18 stone 0  
fill ~22 ~1 ~22 ~26 ~1 ~22 gravel 0  
fill ~22 ~1 ~23 ~26 ~1 ~23 gravel 0  
fill ~22 ~1 ~24 ~26 ~1 ~24 gravel 0  
fill ~22 ~1 ~25 ~25 ~1 ~25 gravel 0  
fill ~22 ~1 ~28 ~28 ~1 ~28 gravel 0  
fill ~22 ~1 ~30 ~22 ~4 ~30 stone 0  
fill ~22 ~1 ~42 ~40 ~1 ~42 stone 0  
fill ~22 ~1 ~43 ~56 ~1 ~43 stone 0  
fill ~22 ~1 ~50 ~39 ~1 ~50 stone 0  
fill ~22 ~1 ~51 ~39 ~1 ~51 stone 0  
fill ~22 ~1 ~58 ~29 ~1 ~58 stone 0  
fill ~22 ~1 ~59 ~29 ~1 ~59 stone 0  
fill ~22 ~1 ~60 ~30 ~1 ~60 stone 0  
fill ~22 ~1 ~61 ~30 ~1 ~61 stone 0  
fill ~22 ~1 ~62 ~39 ~1 ~62 stone 0  
fill ~22 ~1 ~63 ~39 ~1 ~63 stone 0  
fill ~22 ~1 ~64 ~39 ~1 ~64 stone 0  
fill ~23 ~1 ~16 ~35 ~1 ~16 stone 0  
fill ~23 ~1 ~21 ~27 ~1 ~21 gravel 0 
setblock ~23 ~1 ~30 gravel 0  
fill ~23 ~1 ~65 ~33 ~1 ~65 stone 0  
fill ~23 ~1 ~66 ~33 ~1 ~66 stone 0  
fill ~23 ~1 ~67 ~33 ~1 ~67 stone 0  
fill ~24 ~1 ~15 ~35 ~1 ~15 stone 0  
fill ~24 ~1 ~26 ~35 ~1 ~26 stone 0  
fill ~24 ~1 ~30 ~40 ~1 ~30 stone 0  
fill ~25 ~1 ~20 ~26 ~1 ~20 gravel 0  
fill ~25 ~1 ~27 ~27 ~1 ~27 gravel 0  
fill ~26 ~1 ~25 ~35 ~1 ~25 stone 0  
fill ~27 ~1 ~20 ~35 ~1 ~20 stone 0  
fill ~27 ~1 ~22 ~35 ~1 ~22 stone 0  
fill ~27 ~1 ~23 ~35 ~1 ~23 stone 0  
fill ~27 ~1 ~24 ~35 ~1 ~24 stone 0  
fill ~28 ~1 ~21 ~35 ~1 ~21 stone 0  
fill ~28 ~1 ~27 ~55 ~1 ~27 stone 0  
fill ~28 ~1 ~29 ~49 ~1 ~29 stone 0  
fill ~29 ~1 ~28 ~56 ~1 ~28 stone 0  
fill ~29 ~1 ~57 ~31 ~1 ~57 dirt 0  
fill ~30 ~1 ~56 ~31 ~1 ~56 dirt 0  
fill ~30 ~1 ~58 ~31 ~1 ~58 dirt 0  
fill ~30 ~1 ~59 ~31 ~1 ~59 dirt 0  
fill ~31 ~1 ~60 ~31 ~2 ~60 dirt 0  
fill ~31 ~1 ~61 ~31 ~2 ~61 dirt 0  
fill ~32 ~1 ~5 ~34 ~1 ~5 stonebrick 3  
fill ~32 ~1 ~56 ~39 ~1 ~56 stone 0  
fill ~32 ~1 ~57 ~39 ~1 ~57 stone 0  
fill ~32 ~1 ~58 ~39 ~1 ~58 stone 0  
fill ~32 ~1 ~59 ~39 ~1 ~59 stone 0  
fill ~32 ~1 ~60 ~39 ~1 ~60 stone 0  
fill ~32 ~1 ~61 ~39 ~1 ~61 stone 0  
fill ~34 ~1 ~65 ~37 ~1 ~65 dirt 0  
fill ~34 ~1 ~66 ~37 ~1 ~66 dirt 0  
fill ~34 ~1 ~67 ~36 ~1 ~67 dirt 0  
fill ~35 ~1 ~1 ~46 ~1 ~1 bedrock 0  
fill ~35 ~1 ~2 ~47 ~1 ~2 bedrock 0  
fill ~35 ~1 ~3 ~48 ~1 ~3 bedrock 0  
fill ~35 ~1 ~4 ~49 ~1 ~4 bedrock 0  
fill ~35 ~1 ~5 ~50 ~1 ~5 bedrock 0  
fill ~35 ~1 ~6 ~51 ~1 ~6 bedrock 0  
fill ~35 ~1 ~7 ~52 ~1 ~7 bedrock 0  
fill ~35 ~1 ~8 ~53 ~1 ~8 bedrock 0  
fill ~35 ~1 ~9 ~54 ~1 ~9 bedrock 0  
fill ~35 ~1 ~10 ~55 ~1 ~10 bedrock 0  
fill ~35 ~1 ~11 ~56 ~1 ~11 bedrock 0  
fill ~36 ~1 ~12 ~57 ~1 ~12 bedrock 0  
fill ~36 ~1 ~13 ~78 ~1 ~13 bedrock 0  
fill ~36 ~1 ~14 ~78 ~1 ~14 bedrock 0  
fill ~36 ~1 ~15 ~71 ~1 ~15 bedrock 0  
fill ~36 ~1 ~16 ~68 ~1 ~16 bedrock 0  
fill ~36 ~1 ~17 ~65 ~1 ~17 bedrock 0  
fill ~36 ~1 ~18 ~64 ~1 ~18 bedrock 0  
fill ~36 ~1 ~19 ~64 ~1 ~19 bedrock 0  
fill ~36 ~1 ~20 ~64 ~1 ~20 bedrock 0  
fill ~36 ~1 ~21 ~60 ~1 ~21 bedrock 0  
fill ~36 ~1 ~22 ~60 ~1 ~22 bedrock 0  
fill ~36 ~1 ~23 ~68 ~1 ~23 bedrock 0  
fill ~36 ~1 ~24 ~71 ~1 ~24 bedrock 0  
fill ~36 ~1 ~25 ~78 ~1 ~25 bedrock 0  
fill ~36 ~1 ~26 ~36 ~1 ~1 bedrock 0  
fill ~37 ~1 ~26 ~38 ~1 ~26 stone 0  
fill ~38 ~1 ~65 ~39 ~1 ~65 stone 0  
fill ~38 ~1 ~66 ~39 ~1 ~66 stone 0  
fill ~38 ~1 ~68 ~50 ~1 ~68 bedrock 0  
fill ~38 ~1 ~69 ~49 ~1 ~69 bedrock 0  
fill ~38 ~1 ~70 ~48 ~1 ~70 bedrock 0  
fill ~38 ~1 ~71 ~47 ~1 ~71 bedrock 0  
fill ~38 ~1 ~72 ~46 ~1 ~72 bedrock 0  
fill ~38 ~1 ~73 ~45 ~1 ~73 bedrock 0  
fill ~39 ~1 ~26 ~40 ~1 ~26 stonebrick 3  
fill ~39 ~1 ~67 ~51 ~1 ~67 bedrock 0  
fill ~40 ~1 ~47 ~78 ~1 ~47 bedrock 0  
fill ~40 ~1 ~48 ~64 ~1 ~48 bedrock 0  
fill ~40 ~1 ~49 ~64 ~1 ~49 bedrock 0  
fill ~40 ~1 ~50 ~60 ~1 ~50 bedrock 0  
fill ~40 ~1 ~51 ~60 ~1 ~51 bedrock 0  
fill ~40 ~1 ~52 ~68 ~1 ~52 bedrock 0  
fill ~40 ~1 ~53 ~65 ~1 ~53 bedrock 0  
fill ~40 ~1 ~54 ~64 ~1 ~54 bedrock 0  
fill ~40 ~1 ~55 ~64 ~1 ~55 bedrock 0  
fill ~40 ~1 ~56 ~64 ~1 ~56 bedrock 0  
fill ~40 ~1 ~57 ~64 ~1 ~57 bedrock 0  
fill ~40 ~1 ~58 ~78 ~1 ~58 bedrock 0  
fill ~40 ~1 ~59 ~78 ~1 ~59 bedrock 0  
fill ~40 ~1 ~60 ~58 ~1 ~60 bedrock 0  
fill ~40 ~1 ~61 ~57 ~1 ~61 bedrock 0  
fill ~40 ~1 ~62 ~56 ~1 ~62 bedrock 0  
fill ~40 ~1 ~63 ~55 ~1 ~63 bedrock 0  
fill ~40 ~1 ~64 ~54 ~1 ~64 bedrock 0  
fill ~40 ~1 ~65 ~53 ~1 ~65 bedrock 0  
fill ~40 ~1 ~66 ~52 ~1 ~66 bedrock 0 
setblock ~41 ~1 ~26 bedrock 0 
setblock ~41 ~1 ~46 bedrock 0  
fill ~42 ~1 ~26 ~43 ~1 ~26 stonebrick 3  
fill ~42 ~1 ~31 ~49 ~1 ~31 stone 0  
fill ~42 ~1 ~32 ~49 ~1 ~32 stone 0  
fill ~42 ~1 ~33 ~47 ~1 ~33 stone 0  
fill ~42 ~1 ~34 ~50 ~1 ~34 stone 0  
fill ~42 ~1 ~35 ~50 ~1 ~35 stone 0  
fill ~42 ~1 ~36 ~52 ~1 ~36 stone 0  
fill ~42 ~1 ~37 ~52 ~1 ~37 stone 0  
fill ~42 ~1 ~38 ~52 ~1 ~38 stone 0  
fill ~42 ~1 ~39 ~52 ~1 ~39 stone 0  
fill ~42 ~1 ~40 ~52 ~1 ~40 stone 0  
fill ~42 ~1 ~41 ~52 ~1 ~41 stone 0  
fill ~42 ~1 ~46 ~43 ~1 ~46 stone 0 
setblock ~44 ~1 ~26 bedrock 0 
setblock ~44 ~1 ~46 bedrock 0  
fill ~45 ~1 ~26 ~46 ~1 ~26 stonebrick 3  
fill ~45 ~1 ~46 ~46 ~1 ~46 stone 0 
setblock ~47 ~1 ~26 bedrock 0 
setblock ~47 ~1 ~46 bedrock 0  
fill ~48 ~1 ~26 ~49 ~1 ~26 stonebrick 3  
fill ~48 ~1 ~33 ~48 ~2 ~33 obsidian 0  
fill ~48 ~1 ~46 ~49 ~1 ~46 stone 0 
setblock ~49 ~1 ~33 stone 0 
setblock ~50 ~1 ~26 bedrock 0 
setblock ~50 ~1 ~29 dirt 0  
fill ~50 ~1 ~31 ~50 ~2 ~31 obsidian 0  
fill ~50 ~1 ~32 ~52 ~1 ~32 dirt 0  
fill ~50 ~1 ~33 ~52 ~1 ~33 dirt 0 
setblock ~50 ~1 ~46 bedrock 0  
fill ~51 ~1 ~26 ~52 ~1 ~26 stonebrick 3  
fill ~51 ~1 ~29 ~56 ~1 ~29 stone 0  
fill ~51 ~1 ~31 ~52 ~1 ~31 dirt 0  
fill ~51 ~1 ~34 ~51 ~1 ~35 dirt 0  
fill ~51 ~1 ~46 ~52 ~1 ~46 stonebrick 3 
setblock ~52 ~1 ~34 stone 0 
setblock ~52 ~1 ~35 dirt 0 
setblock ~53 ~1 ~26 bedrock 0 
setblock ~53 ~1 ~46 bedrock 0  
fill ~54 ~1 ~26 ~55 ~1 ~26 stonebrick 3  
fill ~54 ~1 ~30 ~56 ~1 ~30 stone 0  
fill ~54 ~1 ~31 ~56 ~1 ~31 stone 0  
fill ~54 ~1 ~32 ~56 ~1 ~32 stone 0  
fill ~54 ~1 ~33 ~56 ~1 ~33 stone 0  
fill ~54 ~1 ~34 ~56 ~1 ~34 stone 0  
fill ~54 ~1 ~35 ~56 ~1 ~35 stone 0  
fill ~54 ~1 ~36 ~56 ~1 ~36 stone 0  
fill ~54 ~1 ~37 ~56 ~1 ~37 stone 0  
fill ~54 ~1 ~38 ~56 ~1 ~38 stone 0  
fill ~54 ~1 ~39 ~56 ~1 ~39 stone 0  
fill ~54 ~1 ~40 ~56 ~1 ~40 stone 0  
fill ~54 ~1 ~41 ~56 ~1 ~41 stone 0  
fill ~54 ~1 ~42 ~54 ~3 ~42 obsidian 0  
fill ~54 ~1 ~46 ~54 ~7 ~46 stonebrick 3  
fill ~55 ~1 ~42 ~56 ~1 ~42 stone 0  
fill ~55 ~1 ~46 ~71 ~1 ~46 bedrock 0  
fill ~56 ~1 ~26 ~64 ~1 ~26 bedrock 0  
fill ~56 ~1 ~27 ~56 ~7 ~27 stonebrick 3  
fill ~56 ~1 ~45 ~56 ~7 ~45 stonebrick 3  
fill ~57 ~1 ~27 ~64 ~1 ~27 bedrock 0  
fill ~57 ~1 ~28 ~57 ~7 ~28 stonebrick 3  
fill ~57 ~1 ~29 ~57 ~7 ~29 stonebrick 3  
fill ~57 ~1 ~30 ~64 ~1 ~30 bedrock 0  
fill ~57 ~1 ~31 ~57 ~7 ~31 stonebrick 3  
fill ~57 ~1 ~32 ~57 ~7 ~32 stonebrick 3  
fill ~57 ~1 ~33 ~64 ~1 ~33 bedrock 0  
fill ~57 ~1 ~34 ~57 ~7 ~34 stonebrick 3  
fill ~57 ~1 ~35 ~57 ~7 ~35 stonebrick 3  
fill ~57 ~1 ~36 ~61 ~1 ~36 bedrock 0  
fill ~57 ~1 ~37 ~57 ~7 ~37 stonebrick 3  
fill ~57 ~1 ~38 ~57 ~7 ~38 stonebrick 3 
fill ~57 ~1 ~39 ~65 ~1 ~39 bedrock 0  
fill ~57 ~1 ~40 ~57 ~7 ~40 stonebrick 3  
fill ~57 ~1 ~41 ~57 ~7 ~41 stonebrick 3  
fill ~57 ~1 ~42 ~64 ~1 ~42 bedrock 0  
fill ~57 ~1 ~43 ~57 ~7 ~43 stonebrick 3  
fill ~57 ~1 ~44 ~57 ~7 ~44 stonebrick 3  
fill ~57 ~1 ~45 ~68 ~1 ~45 bedrock 0  
fill ~58 ~1 ~28 ~64 ~1 ~28 bedrock 0  
fill ~58 ~1 ~29 ~64 ~1 ~29 bedrock 0  
fill ~58 ~1 ~31 ~64 ~1 ~31 bedrock 0  
fill ~58 ~1 ~32 ~64 ~1 ~32 bedrock 0  
fill ~58 ~1 ~34 ~64 ~1 ~34 bedrock 0  
fill ~58 ~1 ~35 ~65 ~1 ~35 bedrock 0  
fill ~58 ~1 ~37 ~71 ~1 ~37 bedrock 0  
fill ~58 ~1 ~38 ~68 ~1 ~38 bedrock 0  
fill ~58 ~1 ~40 ~64 ~1 ~40 bedrock 0  
fill ~58 ~1 ~41 ~64 ~1 ~41 bedrock 0  
fill ~58 ~1 ~43 ~64 ~1 ~43 bedrock 0  
fill ~58 ~1 ~44 ~65 ~1 ~44 bedrock 0  
fill ~61 ~1 ~21 ~62 ~1 ~21 stonebrick 3  
fill ~61 ~1 ~22 ~62 ~1 ~22 stonebrick 3  
fill ~61 ~1 ~50 ~62 ~1 ~50 stonebrick 3  
fill ~61 ~1 ~51 ~62 ~1 ~51 stonebrick 3  
fill ~62 ~1 ~36 ~62 ~7 ~36 stonebrick 3  
fill ~63 ~1 ~21 ~64 ~1 ~21 bedrock 0  
fill ~63 ~1 ~22 ~65 ~1 ~22 bedrock 0  
fill ~63 ~1 ~36 ~78 ~1 ~36 bedrock 0  
fill ~63 ~1 ~51 ~71 ~1 ~51 bedrock 0  
fill ~64 ~1 ~50 ~73 ~1 ~50 bedrock 0  
fill ~65 ~1 ~18 ~70 ~1 ~18 wool 3  
fill ~65 ~1 ~19 ~66 ~1 ~19 wool 3  
fill ~65 ~1 ~20 ~66 ~1 ~20 wool 3  
fill ~65 ~1 ~21 ~70 ~1 ~21 wool 3  
fill ~65 ~1 ~26 ~66 ~1 ~26 wool 3  
fill ~65 ~1 ~27 ~66 ~1 ~27 wool 3  
fill ~65 ~1 ~28 ~66 ~1 ~28 wool 3  
fill ~65 ~1 ~29 ~66 ~1 ~29 wool 3  
fill ~65 ~1 ~30 ~65 ~1 ~34 wool 3  
fill ~65 ~1 ~40 ~70 ~1 ~40 wool 3  
fill ~65 ~1 ~41 ~66 ~1 ~41 wool 3  
fill ~65 ~1 ~42 ~66 ~1 ~42 wool 3  
fill ~65 ~1 ~43 ~70 ~1 ~43 wool 3  
fill ~65 ~1 ~48 ~75 ~1 ~48 wool 3  
fill ~65 ~1 ~49 ~75 ~1 ~49 wool 3  
fill ~65 ~1 ~54 ~68 ~1 ~54 wool 3  
fill ~65 ~1 ~55 ~66 ~1 ~55 wool 3  
fill ~65 ~1 ~56 ~75 ~1 ~56 wool 3  
fill ~65 ~1 ~57 ~75 ~1 ~57 wool 3  
fill ~66 ~1 ~17 ~73 ~1 ~17 wool 3  
fill ~66 ~1 ~22 ~73 ~1 ~22 wool 3  
fill ~66 ~1 ~31 ~66 ~1 ~35 wool 3  
fill ~66 ~1 ~39 ~73 ~1 ~39 wool 3  
fill ~66 ~1 ~44 ~73 ~1 ~44 wool 3  
fill ~66 ~1 ~53 ~71 ~1 ~53 wool 3  
fill ~67 ~1 ~19 ~78 ~1 ~19 bedrock 0  
fill ~67 ~1 ~20 ~78 ~1 ~20 bedrock 0  
fill ~67 ~1 ~26 ~71 ~1 ~26 bedrock 0  
fill ~67 ~1 ~27 ~70 ~1 ~27 bedrock 0  
fill ~67 ~1 ~28 ~69 ~1 ~28 bedrock 0  
fill ~67 ~1 ~29 ~69 ~1 ~29 bedrock 0  
fill ~67 ~1 ~30 ~68 ~1 ~30 bedrock 0  
fill ~67 ~1 ~31 ~67 ~1 ~32 bedrock 0  
fill ~67 ~1 ~33 ~70 ~1 ~33 wool 3  
fill ~67 ~1 ~34 ~69 ~1 ~34 wool 3  
fill ~67 ~1 ~35 ~68 ~1 ~35 wool 3  
fill ~67 ~1 ~41 ~78 ~1 ~41 bedrock 0  
fill ~67 ~1 ~42 ~78 ~1 ~42 bedrock 0  
fill ~67 ~1 ~55 ~78 ~1 ~55 bedrock 0  
fill ~69 ~1 ~16 ~75 ~1 ~16 wool 3  
fill ~69 ~1 ~23 ~75 ~1 ~23 wool 3  
fill ~69 ~1 ~30 ~71 ~1 ~30 wool 3  
fill ~69 ~1 ~31 ~71 ~1 ~31 wool 3  
fill ~69 ~1 ~32 ~70 ~1 ~32 wool 3  
fill ~69 ~1 ~35 ~73 ~1 ~35 bedrock 0  
fill ~69 ~1 ~38 ~75 ~1 ~38 wool 3  
fill ~69 ~1 ~45 ~75 ~1 ~45 wool 3  
fill ~69 ~1 ~52 ~74 ~1 ~52 wool 3  
fill ~69 ~1 ~54 ~78 ~1 ~54 bedrock 0  
fill ~70 ~1 ~28 ~75 ~1 ~28 wool 3  
fill ~70 ~1 ~29 ~71 ~1 ~29 wool 3 
setblock ~70 ~1 ~34 bedrock 0  
fill ~71 ~1 ~18 ~78 ~1 ~18 bedrock 0  
fill ~71 ~1 ~21 ~78 ~1 ~21 bedrock 0  
fill ~71 ~1 ~27 ~75 ~1 ~27 wool 3  
fill ~71 ~1 ~40 ~78 ~1 ~40 bedrock 0  
fill ~71 ~1 ~43 ~78 ~1 ~43 bedrock 0  
fill ~72 ~1 ~15 ~75 ~1 ~15 wool 3  
fill ~72 ~1 ~24 ~75 ~1 ~24 wool 3  
fill ~72 ~1 ~26 ~74 ~1 ~26 wool 3  
fill ~72 ~1 ~29 ~73 ~1 ~29 bedrock 0  
fill ~72 ~1 ~30 ~73 ~1 ~30 bedrock 0  
fill ~72 ~1 ~31 ~73 ~1 ~31 bedrock 0  
fill ~72 ~1 ~32 ~73 ~1 ~32 bedrock 0  
fill ~72 ~1 ~33 ~73 ~1 ~33 bedrock 0  
fill ~72 ~1 ~34 ~73 ~1 ~34 bedrock 0  
fill ~72 ~1 ~37 ~75 ~1 ~37 wool 3  
fill ~72 ~1 ~46 ~75 ~1 ~46 wool 3  
fill ~72 ~1 ~51 ~75 ~1 ~51 wool 3  
fill ~72 ~1 ~53 ~78 ~1 ~53 bedrock 0  
fill ~74 ~1 ~17 ~78 ~1 ~17 bedrock 0  
fill ~74 ~1 ~22 ~78 ~1 ~22 bedrock 0  
fill ~74 ~1 ~29 ~74 ~1 ~35 wool 3  
fill ~74 ~1 ~39 ~78 ~1 ~39 bedrock 0  
fill ~74 ~1 ~44 ~78 ~1 ~44 bedrock 0  
fill ~74 ~1 ~50 ~75 ~1 ~50 wool 3  
fill ~75 ~1 ~26 ~78 ~1 ~26 bedrock 0 
setblock ~75 ~1 ~30 wool 3  
fill ~75 ~1 ~32 ~75 ~1 ~35 wool 3  
fill ~75 ~1 ~52 ~78 ~1 ~52 bedrock 0  
fill ~76 ~1 ~15 ~78 ~1 ~15 bedrock 0  
fill ~76 ~1 ~16 ~78 ~1 ~16 bedrock 0  
fill ~76 ~1 ~23 ~78 ~1 ~23 bedrock 0  
fill ~76 ~1 ~24 ~78 ~1 ~24 bedrock 0  
fill ~76 ~1 ~27 ~78 ~1 ~27 bedrock 0  
fill ~76 ~1 ~28 ~78 ~1 ~28 bedrock 0  
fill ~76 ~1 ~29 ~78 ~1 ~29 bedrock 0  
fill ~76 ~1 ~30 ~78 ~1 ~30 bedrock 0  
fill ~76 ~1 ~31 ~78 ~1 ~31 bedrock 0  
fill ~76 ~1 ~32 ~78 ~1 ~32 bedrock 0  
fill ~76 ~1 ~33 ~78 ~1 ~33 bedrock 0  
fill ~76 ~1 ~34 ~78 ~1 ~34 bedrock 0  
fill ~76 ~1 ~35 ~78 ~1 ~35 bedrock 0  
fill ~76 ~1 ~37 ~78 ~1 ~37 bedrock 0  
fill ~76 ~1 ~38 ~78 ~1 ~38 bedrock 0  
fill ~76 ~1 ~45 ~78 ~1 ~45 bedrock 0  
fill ~76 ~1 ~46 ~78 ~1 ~46 bedrock 0  
fill ~76 ~1 ~56 ~78 ~1 ~56 bedrock 0  
fill ~76 ~1 ~57 ~78 ~1 ~57 bedrock 0  
fill ~77 ~1 ~48 ~78 ~1 ~48 bedrock 0  
fill ~77 ~1 ~49 ~78 ~1 ~49 bedrock 0  
fill ~77 ~1 ~50 ~78 ~1 ~50 bedrock 0  
fill ~77 ~1 ~51 ~78 ~1 ~51 bedrock 0  
fill ~8 ~2 ~5 ~34 ~2 ~5 stonebrick 3  
fill ~8 ~2 ~26 ~10 ~2 ~26 stonebrick 3  
fill ~8 ~2 ~46 ~10 ~2 ~46 stonebrick 3  
fill ~8 ~2 ~67 ~21 ~2 ~67 stonebrick 3  
fill ~9 ~2 ~7 ~33 ~2 ~7 stonebrick 3  
fill ~9 ~2 ~8 ~33 ~2 ~8 stonebrick 3  
fill ~9 ~2 ~9 ~33 ~2 ~9 stonebrick 3  
fill ~9 ~2 ~10 ~9 ~3 ~10 stonebrick 3  
fill ~9 ~2 ~11 ~9 ~3 ~11 stonebrick 3  
fill ~9 ~2 ~12 ~9 ~3 ~12 stonebrick 3  
fill ~9 ~2 ~13 ~9 ~3 ~13 stonebrick 3  
fill ~9 ~2 ~14 ~9 ~3 ~14 stonebrick 3  
fill ~9 ~2 ~15 ~9 ~7 ~15 stonebrick 3  
fill ~9 ~2 ~16 ~9 ~7 ~16 stonebrick 3  
fill ~9 ~2 ~17 ~9 ~7 ~17 stonebrick 3  
fill ~9 ~2 ~18 ~9 ~7 ~18 stonebrick 3  
fill ~9 ~2 ~19 ~9 ~7 ~19 stonebrick 3  
fill ~9 ~2 ~20 ~9 ~7 ~20 stonebrick 3  
fill ~9 ~2 ~21 ~9 ~5 ~21 stonebrick 3  
fill ~9 ~2 ~22 ~9 ~7 ~22 stonebrick 3  
fill ~9 ~2 ~23 ~9 ~5 ~23 stonebrick 3  
fill ~9 ~2 ~24 ~9 ~5 ~24 stonebrick 3  
fill ~9 ~2 ~28 ~9 ~5 ~28 stonebrick 3  
fill ~9 ~2 ~29 ~9 ~5 ~29 stonebrick 3  
fill ~9 ~2 ~30 ~9 ~6 ~30 stonebrick 3  
fill ~9 ~2 ~31 ~9 ~7 ~31 stonebrick 3  
fill ~9 ~2 ~32 ~9 ~7 ~32 stonebrick 3  
fill ~9 ~2 ~33 ~9 ~7 ~33 stonebrick 3  
fill ~9 ~2 ~34 ~9 ~7 ~34 stonebrick 3  
fill ~9 ~2 ~35 ~9 ~7 ~35 stonebrick 3  
fill ~9 ~2 ~36 ~9 ~7 ~36 stonebrick 3  
fill ~9 ~2 ~37 ~9 ~7 ~37 stonebrick 3  
fill ~9 ~2 ~38 ~9 ~7 ~38 stonebrick 3  
fill ~9 ~2 ~39 ~9 ~7 ~39 stonebrick 3  
fill ~9 ~2 ~40 ~9 ~7 ~40 stonebrick 3  
fill ~9 ~2 ~41 ~9 ~7 ~41 stonebrick 3  
fill ~9 ~2 ~42 ~9 ~6 ~42 stonebrick 3  
fill ~9 ~2 ~43 ~9 ~5 ~43 stonebrick 3  
fill ~9 ~2 ~44 ~9 ~5 ~44 stonebrick 3  
fill ~9 ~2 ~48 ~9 ~5 ~48 stonebrick 3  
fill ~9 ~2 ~49 ~9 ~6 ~49 stonebrick 3  
fill ~9 ~2 ~50 ~9 ~7 ~50 stonebrick 3  
fill ~9 ~2 ~51 ~9 ~7 ~51 stonebrick 3  
fill ~9 ~2 ~52 ~9 ~7 ~52 stonebrick 3  
fill ~9 ~2 ~53 ~9 ~7 ~53 stonebrick 3  
fill ~9 ~2 ~54 ~9 ~7 ~54 stonebrick 3  
fill ~9 ~2 ~55 ~9 ~7 ~55 stonebrick 3  
fill ~9 ~2 ~56 ~9 ~7 ~56 stonebrick 3  
fill ~9 ~2 ~57 ~9 ~7 ~57 stonebrick 3  
fill ~9 ~2 ~58 ~9 ~7 ~58 stonebrick 3  
fill ~9 ~2 ~59 ~9 ~7 ~59 stonebrick 3  
fill ~9 ~2 ~60 ~9 ~7 ~60 stonebrick 3  
fill ~9 ~2 ~61 ~9 ~7 ~61 stonebrick 3  
fill ~9 ~2 ~62 ~9 ~7 ~62 stonebrick 3  
fill ~9 ~2 ~63 ~9 ~6 ~63 stonebrick 3  
fill ~9 ~2 ~64 ~9 ~5 ~64 stonebrick 3  
fill ~9 ~2 ~65 ~9 ~5 ~65 stonebrick 3  
fill ~10 ~2 ~6 ~33 ~2 ~6 stonebrick 3  
fill ~10 ~2 ~66 ~20 ~2 ~66 stonebrick 3  
fill ~15 ~2 ~10 ~17 ~2 ~10 stonebrick 3  
fill ~15 ~2 ~11 ~17 ~2 ~11 stonebrick 3  
fill ~15 ~2 ~12 ~17 ~2 ~12 stonebrick 3  
fill ~15 ~2 ~13 ~17 ~2 ~13 stonebrick 3  
fill ~15 ~2 ~14 ~17 ~2 ~14 stonebrick 3  
fill ~15 ~2 ~15 ~17 ~2 ~15 stonebrick 3  
fill ~15 ~2 ~16 ~17 ~2 ~16 stonebrick 3  
fill ~15 ~2 ~17 ~17 ~2 ~17 stonebrick 3  
fill ~15 ~2 ~18 ~17 ~2 ~18 stonebrick 3  
fill ~15 ~2 ~19 ~17 ~2 ~19 stonebrick 3  
fill ~15 ~2 ~20 ~17 ~2 ~20 stonebrick 3  
fill ~15 ~2 ~21 ~17 ~2 ~21 stonebrick 3  
fill ~15 ~2 ~22 ~17 ~2 ~22 stonebrick 3  
fill ~15 ~2 ~23 ~16 ~2 ~23 stonebrick 3  
fill ~15 ~2 ~24 ~16 ~2 ~24 stonebrick 3  
fill ~15 ~2 ~25 ~16 ~2 ~25 stonebrick 3  
fill ~15 ~2 ~26 ~16 ~2 ~26 stonebrick 3  
fill ~15 ~2 ~27 ~15 ~3 ~27 stonebrick 3  
fill ~15 ~2 ~28 ~15 ~3 ~28 stonebrick 3  
fill ~15 ~2 ~29 ~15 ~5 ~29 stonebrick 3  
fill ~15 ~2 ~30 ~15 ~7 ~30 stonebrick 3  
fill ~15 ~2 ~31 ~15 ~7 ~31 stonebrick 3  
fill ~15 ~2 ~32 ~15 ~7 ~32 stonebrick 3  
fill ~15 ~2 ~33 ~15 ~7 ~33 stonebrick 3  
fill ~15 ~2 ~34 ~15 ~7 ~34 stonebrick 3  
fill ~15 ~2 ~35 ~15 ~7 ~35 stonebrick 3  
fill ~15 ~2 ~36 ~15 ~7 ~36 stonebrick 3  
fill ~15 ~2 ~37 ~15 ~7 ~37 stonebrick 3  
fill ~15 ~2 ~38 ~15 ~7 ~38 stonebrick 3  
fill ~15 ~2 ~39 ~15 ~7 ~39 stonebrick 3  
fill ~15 ~2 ~40 ~15 ~7 ~40 stonebrick 3  
fill ~15 ~2 ~41 ~15 ~7 ~41 stonebrick 3  
fill ~15 ~2 ~42 ~15 ~7 ~42 stonebrick 3  
fill ~15 ~2 ~43 ~15 ~6 ~43 stonebrick 3  
fill ~15 ~2 ~44 ~15 ~5 ~44 stonebrick 3  
fill ~15 ~2 ~45 ~15 ~5 ~45 stonebrick 3  
fill ~15 ~2 ~46 ~15 ~5 ~46 stonebrick 3  
fill ~15 ~2 ~47 ~18 ~2 ~47 stonebrick 3  
fill ~15 ~2 ~48 ~18 ~2 ~48 stonebrick 3  
fill ~15 ~2 ~49 ~18 ~2 ~49 stonebrick 3  
fill ~15 ~2 ~50 ~18 ~2 ~50 stonebrick 3  
fill ~15 ~2 ~51 ~18 ~2 ~51 stonebrick 3  
fill ~15 ~2 ~52 ~18 ~2 ~52 stonebrick 3  
fill ~15 ~2 ~53 ~19 ~2 ~53 stonebrick 3  
fill ~15 ~2 ~54 ~18 ~2 ~54 stonebrick 3  
fill ~15 ~2 ~55 ~18 ~2 ~55 stonebrick 3  
fill ~15 ~2 ~56 ~18 ~2 ~56 stonebrick 3  
fill ~15 ~2 ~57 ~19 ~2 ~57 stonebrick 3  
fill ~15 ~2 ~58 ~19 ~2 ~58 stonebrick 3  
fill ~15 ~2 ~59 ~19 ~2 ~59 stonebrick 3  
fill ~15 ~2 ~60 ~19 ~2 ~60 stonebrick 3  
fill ~15 ~2 ~61 ~19 ~2 ~61 stonebrick 3  
fill ~15 ~2 ~62 ~20 ~2 ~62 stonebrick 3  
fill ~15 ~2 ~63 ~20 ~2 ~63 stonebrick 3  
fill ~15 ~2 ~64 ~20 ~2 ~64 stonebrick 3  
fill ~15 ~2 ~65 ~20 ~2 ~65 stonebrick 3  
fill ~17 ~2 ~23 ~17 ~6 ~23 stone 0  
fill ~17 ~2 ~24 ~17 ~6 ~24 stone 0  
fill ~17 ~2 ~25 ~18 ~2 ~25 stone 0  
fill ~17 ~2 ~26 ~18 ~2 ~26 stone 0  
fill ~17 ~2 ~27 ~18 ~2 ~27 stone 0  
fill ~17 ~2 ~28 ~17 ~6 ~28 stone 0  
fill ~17 ~2 ~29 ~17 ~3 ~29 stone 0  
fill ~17 ~2 ~30 ~17 ~3 ~30 stone 0 
setblock ~17 ~2 ~31 dirt 0  
fill ~17 ~2 ~32 ~17 ~2 ~67 stonebrick 3  
fill ~18 ~2 ~10 ~32 ~2 ~10 stone 0  
fill ~18 ~2 ~11 ~33 ~2 ~11 stone 0  
fill ~18 ~2 ~12 ~34 ~2 ~12 stone 0  
fill ~18 ~2 ~13 ~34 ~2 ~13 stone 0  
fill ~18 ~2 ~14 ~34 ~2 ~14 stone 0  
fill ~18 ~2 ~15 ~34 ~2 ~15 stone 0  
fill ~18 ~2 ~16 ~34 ~2 ~16 stone 0  
fill ~18 ~2 ~17 ~34 ~2 ~17 stone 0  
fill ~18 ~2 ~18 ~34 ~2 ~18 stone 0  
fill ~18 ~2 ~19 ~34 ~2 ~19 stone 0  
fill ~18 ~2 ~30 ~18 ~4 ~30 dirt 0  
fill ~18 ~2 ~31 ~32 ~2 ~31 stone 0  
fill ~18 ~2 ~32 ~18 ~4 ~32 dirt 0  
fill ~18 ~2 ~37 ~18 ~3 ~37 dirt 0  
fill ~18 ~2 ~38 ~19 ~2 ~38 dirt 0  
fill ~18 ~2 ~39 ~18 ~3 ~39 dirt 0 
setblock ~18 ~2 ~46 stonebrick 3  
fill ~19 ~2 ~21 ~19 ~6 ~21 stone 0  
fill ~19 ~2 ~25 ~19 ~4 ~25 dirt 0  
fill ~19 ~2 ~26 ~19 ~4 ~26 dirt 0  
fill ~19 ~2 ~27 ~19 ~4 ~27 dirt 0  
fill ~19 ~2 ~28 ~33 ~2 ~28 stone 0  
fill ~19 ~2 ~29 ~32 ~2 ~29 stone 0  
fill ~19 ~2 ~30 ~32 ~2 ~30 stone 0  
fill ~19 ~2 ~32 ~32 ~2 ~32 stone 0  
fill ~19 ~2 ~33 ~32 ~2 ~33 stone 0  
fill ~19 ~2 ~34 ~32 ~2 ~34 stone 0  
fill ~19 ~2 ~35 ~32 ~2 ~35 stone 0  
fill ~19 ~2 ~36 ~32 ~2 ~36 stone 0  
fill ~19 ~2 ~37 ~32 ~2 ~37 stone 0  
fill ~19 ~2 ~39 ~32 ~2 ~39 stone 0  
fill ~19 ~2 ~40 ~19 ~4 ~40 dirt 0  
fill ~19 ~2 ~41 ~32 ~2 ~41 stone 0  
fill ~19 ~2 ~42 ~19 ~4 ~42 dirt 0  
fill ~19 ~2 ~44 ~19 ~4 ~44 dirt 0  
fill ~19 ~2 ~46 ~20 ~2 ~46 dirt 0  
fill ~19 ~2 ~47 ~20 ~2 ~47 dirt 0  
fill ~19 ~2 ~49 ~20 ~2 ~49 dirt 0  
fill ~19 ~2 ~50 ~21 ~2 ~50 dirt 0  
fill ~19 ~2 ~51 ~21 ~2 ~51 dirt 0  
fill ~19 ~2 ~52 ~21 ~2 ~52 dirt 0  
fill ~19 ~2 ~54 ~21 ~2 ~54 dirt 0  
fill ~19 ~2 ~55 ~21 ~2 ~55 dirt 0  
fill ~19 ~2 ~56 ~21 ~2 ~56 dirt 0  
fill ~20 ~2 ~20 ~34 ~2 ~20 stone 0  
fill ~20 ~2 ~21 ~20 ~4 ~21 dirt 0  
fill ~20 ~2 ~22 ~21 ~2 ~22 stone 0  
fill ~20 ~2 ~23 ~21 ~2 ~23 stone 0  
fill ~20 ~2 ~24 ~20 ~3 ~24 stone 0  
fill ~20 ~2 ~25 ~20 ~3 ~25 stone 0  
fill ~20 ~2 ~26 ~23 ~2 ~26 gravel 0  
fill ~20 ~2 ~27 ~22 ~2 ~27 gravel 0  
fill ~20 ~2 ~38 ~32 ~2 ~38 stone 0  
fill ~20 ~2 ~40 ~32 ~2 ~40 stone 0  
fill ~20 ~2 ~42 ~32 ~2 ~42 stone 0  
fill ~20 ~2 ~43 ~32 ~2 ~43 stone 0  
fill ~20 ~2 ~45 ~20 ~4 ~45 dirt 0  
fill ~20 ~2 ~48 ~21 ~2 ~48 dirt 0  
fill ~20 ~2 ~53 ~22 ~2 ~53 dirt 0  
fill ~20 ~2 ~57 ~21 ~2 ~57 dirt 0  
fill ~20 ~2 ~58 ~21 ~2 ~58 dirt 0  
fill ~20 ~2 ~59 ~21 ~2 ~59 dirt 0  
fill ~20 ~2 ~60 ~21 ~2 ~60 dirt 0  
fill ~20 ~2 ~61 ~22 ~2 ~61 dirt 0  
fill ~21 ~2 ~21 ~22 ~2 ~21 stone 0  
fill ~21 ~2 ~24 ~25 ~2 ~24 gravel 0  
fill ~21 ~2 ~25 ~25 ~2 ~25 gravel 0  
fill ~21 ~2 ~44 ~33 ~2 ~44 stone 0  
fill ~21 ~2 ~45 ~37 ~2 ~45 stone 0  
fill ~21 ~2 ~46 ~38 ~2 ~46 stone 0  
fill ~21 ~2 ~47 ~39 ~2 ~47 stone 0  
fill ~21 ~2 ~49 ~39 ~2 ~49 stone 0  
fill ~21 ~2 ~62 ~22 ~2 ~62 dirt 0  
fill ~21 ~2 ~63 ~22 ~2 ~63 dirt 0  
fill ~21 ~2 ~64 ~22 ~2 ~64 dirt 0  
fill ~21 ~2 ~65 ~22 ~2 ~65 dirt 0  
fill ~21 ~2 ~66 ~23 ~2 ~66 dirt 0  
fill ~22 ~2 ~22 ~26 ~2 ~22 gravel 0  
fill ~22 ~2 ~23 ~26 ~2 ~23 gravel 0  
fill ~22 ~2 ~48 ~39 ~2 ~48 stone 0  
fill ~22 ~2 ~50 ~39 ~2 ~50 stone 0  
fill ~22 ~2 ~51 ~39 ~2 ~51 stone 0  
fill ~22 ~2 ~52 ~39 ~2 ~52 stone 0  
fill ~22 ~2 ~54 ~30 ~2 ~54 stone 0  
fill ~22 ~2 ~55 ~30 ~2 ~55 stone 0  
fill ~22 ~2 ~56 ~29 ~2 ~56 stone 0  
fill ~22 ~2 ~57 ~29 ~2 ~57 stone 0  
fill ~22 ~2 ~58 ~29 ~2 ~58 stone 0  
fill ~22 ~2 ~59 ~29 ~2 ~59 stone 0  
fill ~22 ~2 ~60 ~30 ~2 ~60 stone 0  
fill ~22 ~2 ~67 ~22 ~3 ~67 dirt 0  
fill ~23 ~2 ~21 ~24 ~2 ~21 gravel 0  
fill ~23 ~2 ~27 ~37 ~2 ~27 stone 0  
fill ~23 ~2 ~53 ~39 ~2 ~53 stone 0  
fill ~23 ~2 ~61 ~30 ~2 ~61 stone 0  
fill ~23 ~2 ~62 ~39 ~2 ~62 stone 0  
fill ~23 ~2 ~63 ~34 ~2 ~63 stone 0  
fill ~23 ~2 ~64 ~34 ~2 ~64 stone 0  
fill ~23 ~2 ~65 ~34 ~2 ~65 stone 0  
fill ~23 ~2 ~67 ~23 ~0 ~67 stone 0  
fill ~24 ~2 ~26 ~34 ~2 ~26 stone 0 
setblock ~24 ~2 ~66 stone 0  
fill ~24 ~2 ~67 ~27 ~2 ~67 dirt 0  
fill ~25 ~2 ~66 ~26 ~2 ~66 dirt 0 
setblock ~26 ~2 ~21 gravel 0  
fill ~26 ~2 ~24 ~34 ~2 ~24 stone 0  
fill ~26 ~2 ~25 ~30 ~2 ~25 stone 0  
fill ~27 ~2 ~21 ~34 ~2 ~21 stone 0  
fill ~27 ~2 ~22 ~34 ~2 ~22 stone 0  
fill ~27 ~2 ~23 ~34 ~2 ~23 stone 0  
fill ~27 ~2 ~66 ~34 ~2 ~66 stone 0  
fill ~28 ~2 ~67 ~34 ~2 ~67 stone 0  
fill ~30 ~2 ~56 ~31 ~2 ~56 dirt 0  
fill ~30 ~2 ~57 ~31 ~2 ~57 dirt 0  
fill ~30 ~2 ~58 ~31 ~2 ~58 dirt 0  
fill ~30 ~2 ~59 ~31 ~2 ~59 dirt 0  
fill ~31 ~2 ~54 ~31 ~3 ~54 coal_ore 0  
fill ~31 ~2 ~55 ~31 ~3 ~55 coal_ore 0  
fill ~32 ~2 ~25 ~34 ~2 ~25 stone 0  
fill ~32 ~2 ~54 ~39 ~2 ~54 stone 0  
fill ~32 ~2 ~55 ~39 ~2 ~55 stone 0  
fill ~32 ~2 ~56 ~39 ~2 ~56 stone 0  
fill ~32 ~2 ~57 ~39 ~2 ~57 stone 0  
fill ~32 ~2 ~58 ~39 ~2 ~58 stone 0  
fill ~32 ~2 ~59 ~39 ~2 ~59 stone 0  
fill ~32 ~2 ~60 ~39 ~2 ~60 stone 0  
fill ~32 ~2 ~61 ~39 ~2 ~61 stone 0  
fill ~33 ~2 ~10 ~33 ~3 ~10 stonebrick 3  
fill ~33 ~2 ~69 ~35 ~2 ~69 stonebrick 3  
fill ~34 ~2 ~11 ~34 ~3 ~11 stonebrick 3  
fill ~35 ~2 ~12 ~35 ~4 ~12 stonebrick 3  
fill ~35 ~2 ~13 ~35 ~4 ~13 stonebrick 3  
fill ~35 ~2 ~14 ~35 ~4 ~14 stonebrick 3  
fill ~35 ~2 ~15 ~35 ~4 ~15 stonebrick 3  
fill ~35 ~2 ~16 ~35 ~4 ~16 stonebrick 3  
fill ~35 ~2 ~17 ~35 ~4 ~17 stonebrick 3  
fill ~35 ~2 ~18 ~35 ~4 ~18 stonebrick 3  
fill ~35 ~2 ~19 ~35 ~4 ~19 stonebrick 3  
fill ~35 ~2 ~20 ~35 ~4 ~20 stonebrick 3  
fill ~35 ~2 ~21 ~35 ~4 ~21 stonebrick 3  
fill ~35 ~2 ~22 ~35 ~4 ~22 stonebrick 3  
fill ~35 ~2 ~23 ~35 ~4 ~23 stonebrick 3  
fill ~35 ~2 ~24 ~35 ~4 ~24 stonebrick 3  
fill ~35 ~2 ~25 ~35 ~6 ~25 stonebrick 3  
fill ~35 ~2 ~26 ~40 ~2 ~26 stonebrick 3  
fill ~35 ~2 ~63 ~35 ~4 ~63 stonebrick 3  
fill ~35 ~2 ~64 ~35 ~4 ~64 stonebrick 3  
fill ~35 ~2 ~65 ~35 ~4 ~65 stonebrick 3  
fill ~35 ~2 ~66 ~35 ~4 ~66 stonebrick 3  
fill ~35 ~2 ~67 ~35 ~4 ~67 stonebrick 3  
fill ~35 ~2 ~68 ~35 ~4 ~68 stonebrick 3  
fill ~36 ~2 ~28 ~36 ~6 ~28 stone 0  
fill ~36 ~2 ~63 ~39 ~2 ~63 stone 0  
fill ~36 ~2 ~64 ~39 ~2 ~64 stone 0  
fill ~36 ~2 ~65 ~39 ~2 ~65 stone 0  
fill ~36 ~2 ~66 ~39 ~2 ~66 stone 0  
fill ~36 ~2 ~67 ~36 ~4 ~67 stone 0  
fill ~37 ~2 ~28 ~37 ~7 ~28 stonebrick 3  
fill ~37 ~2 ~29 ~37 ~7 ~29 stonebrick 3  
fill ~37 ~2 ~31 ~37 ~7 ~31 stonebrick 3  
fill ~37 ~2 ~32 ~37 ~7 ~32 stonebrick 3  
fill ~37 ~2 ~34 ~37 ~7 ~34 stonebrick 3  
fill ~37 ~2 ~35 ~37 ~7 ~35 stonebrick 3  
fill ~37 ~2 ~37 ~37 ~7 ~37 stonebrick 3  
fill ~37 ~2 ~38 ~37 ~7 ~38 stonebrick 3  
fill ~37 ~2 ~40 ~37 ~7 ~40 stonebrick 3  
fill ~37 ~2 ~41 ~37 ~7 ~41 stonebrick 3  
fill ~37 ~2 ~43 ~37 ~7 ~43 stonebrick 3  
fill ~37 ~2 ~44 ~37 ~7 ~44 stonebrick 3  
fill ~38 ~2 ~27 ~38 ~7 ~27 stonebrick 3  
fill ~38 ~2 ~28 ~56 ~2 ~28 obsidian 0  
fill ~38 ~2 ~29 ~56 ~2 ~29 obsidian 0  
fill ~38 ~2 ~30 ~56 ~2 ~30 obsidian 0  
fill ~38 ~2 ~31 ~56 ~2 ~31 obsidian 0  
fill ~38 ~2 ~32 ~56 ~2 ~32 obsidian 0  
fill ~38 ~2 ~33 ~56 ~2 ~33 obsidian 0  
fill ~38 ~2 ~34 ~56 ~2 ~34 obsidian 0  
fill ~38 ~2 ~35 ~56 ~2 ~35 obsidian 0  
fill ~38 ~2 ~36 ~56 ~2 ~36 obsidian 0  
fill ~38 ~2 ~37 ~56 ~2 ~37 obsidian 0  
fill ~38 ~2 ~38 ~56 ~2 ~38 obsidian 0  
fill ~38 ~2 ~39 ~56 ~2 ~39 obsidian 0  
fill ~38 ~2 ~40 ~56 ~2 ~40 obsidian 0  
fill ~38 ~2 ~41 ~56 ~2 ~41 obsidian 0  
fill ~38 ~2 ~42 ~56 ~2 ~42 obsidian 0  
fill ~38 ~2 ~43 ~56 ~2 ~43 obsidian 0  
fill ~38 ~2 ~44 ~56 ~2 ~44 obsidian 0  
fill ~38 ~2 ~45 ~38 ~7 ~45 stonebrick 3  
fill ~39 ~2 ~27 ~55 ~2 ~27 obsidian 0  
fill ~39 ~2 ~45 ~55 ~2 ~45 obsidian 0  
fill ~39 ~2 ~46 ~40 ~2 ~46 stonebrick 3  
fill ~39 ~2 ~67 ~40 ~2 ~67 bedrock 0  
fill ~40 ~2 ~47 ~40 ~1 ~47 bedrock 0  
fill ~40 ~2 ~48 ~40 ~1 ~48 bedrock 0  
fill ~40 ~2 ~49 ~40 ~1 ~49 bedrock 0  
fill ~40 ~2 ~50 ~40 ~1 ~50 bedrock 0  
fill ~40 ~2 ~51 ~40 ~1 ~51 bedrock 0  
fill ~40 ~2 ~52 ~40 ~1 ~52 bedrock 0  
fill ~40 ~2 ~53 ~40 ~1 ~53 bedrock 0  
fill ~40 ~2 ~54 ~40 ~1 ~54 bedrock 0  
fill ~40 ~2 ~55 ~40 ~1 ~55 bedrock 0  
fill ~40 ~2 ~56 ~40 ~1 ~56 bedrock 0  
fill ~40 ~2 ~57 ~40 ~1 ~57 bedrock 0  
fill ~40 ~2 ~58 ~40 ~1 ~58 bedrock 0  
fill ~40 ~2 ~59 ~40 ~1 ~59 bedrock 0  
fill ~40 ~2 ~60 ~40 ~1 ~60 bedrock 0  
fill ~40 ~2 ~61 ~40 ~1 ~61 bedrock 0  
fill ~40 ~2 ~62 ~40 ~1 ~62 bedrock 0  
fill ~40 ~2 ~63 ~40 ~1 ~63 bedrock 0  
fill ~40 ~2 ~64 ~40 ~1 ~64 bedrock 0  
fill ~40 ~2 ~65 ~40 ~1 ~65 bedrock 0  
fill ~40 ~2 ~66 ~40 ~1 ~66 bedrock 0  
fill ~42 ~2 ~26 ~43 ~2 ~26 stonebrick 3  
fill ~42 ~2 ~46 ~43 ~2 ~46 stonebrick 3  
fill ~45 ~2 ~26 ~46 ~2 ~26 stonebrick 3  
fill ~45 ~2 ~46 ~46 ~2 ~46 stonebrick 3  
fill ~48 ~2 ~26 ~49 ~2 ~26 stonebrick 3  
fill ~48 ~2 ~46 ~49 ~2 ~46 stonebrick 3  
fill ~51 ~2 ~26 ~52 ~2 ~26 stonebrick 3  
fill ~51 ~2 ~46 ~52 ~2 ~46 stonebrick 3  
fill ~54 ~2 ~26 ~55 ~2 ~26 stonebrick 3  
fill ~55 ~2 ~46 ~55 ~7 ~46 stonebrick 3  
fill ~61 ~2 ~21 ~62 ~2 ~21 stonebrick 3  
fill ~61 ~2 ~22 ~62 ~2 ~22 stonebrick 3  
fill ~61 ~2 ~50 ~62 ~2 ~50 stonebrick 3  
fill ~61 ~2 ~51 ~62 ~2 ~51 stonebrick 3  
fill ~7 ~3 ~3 ~35 ~3 ~3 stonebrick 3  
fill ~7 ~3 ~4 ~7 ~4 ~4 stonebrick 3  
fill ~7 ~3 ~5 ~35 ~3 ~5 stonebrick 3  
fill ~7 ~3 ~6 ~7 ~4 ~6 stonebrick 3  
fill ~7 ~3 ~7 ~7 ~4 ~7 stonebrick 3  
fill ~7 ~3 ~8 ~7 ~4 ~8 stonebrick 3  
fill ~7 ~3 ~9 ~7 ~4 ~9 stonebrick 3  
fill ~7 ~3 ~10 ~7 ~4 ~10 stonebrick 3  
fill ~7 ~3 ~11 ~7 ~4 ~11 stonebrick 3  
fill ~7 ~3 ~12 ~7 ~4 ~12 stonebrick 3  
fill ~7 ~3 ~13 ~7 ~4 ~13 stonebrick 3  
fill ~7 ~3 ~14 ~7 ~4 ~14 stonebrick 3  
fill ~7 ~3 ~15 ~7 ~4 ~15 stonebrick 3  
fill ~7 ~3 ~16 ~7 ~4 ~16 stonebrick 3  
fill ~7 ~3 ~17 ~7 ~4 ~17 stonebrick 3  
fill ~7 ~3 ~18 ~7 ~4 ~18 stonebrick 3  
fill ~7 ~3 ~19 ~7 ~4 ~19 stonebrick 3  
fill ~7 ~3 ~20 ~7 ~4 ~20 stonebrick 3  
fill ~7 ~3 ~21 ~7 ~4 ~21 stonebrick 3  
fill ~7 ~3 ~22 ~7 ~4 ~22 stonebrick 3  
fill ~7 ~3 ~23 ~7 ~4 ~23 stonebrick 3  
fill ~7 ~3 ~24 ~7 ~4 ~24 stonebrick 3  
fill ~7 ~3 ~25 ~7 ~4 ~25 stonebrick 3  
fill ~7 ~3 ~26 ~16 ~3 ~26 stonebrick 3  
fill ~7 ~3 ~27 ~7 ~4 ~27 stonebrick 3  
fill ~7 ~3 ~28 ~7 ~4 ~28 stonebrick 3  
fill ~7 ~3 ~29 ~7 ~4 ~29 stonebrick 3  
fill ~7 ~3 ~30 ~7 ~4 ~30 stonebrick 3  
fill ~7 ~3 ~31 ~7 ~4 ~31 stonebrick 3  
fill ~7 ~3 ~32 ~7 ~4 ~32 stonebrick 3  
fill ~7 ~3 ~33 ~7 ~4 ~33 stonebrick 3  
fill ~7 ~3 ~34 ~7 ~4 ~34 stonebrick 3  
fill ~7 ~3 ~35 ~7 ~4 ~35 stonebrick 3  
fill ~7 ~3 ~36 ~7 ~4 ~36 stonebrick 3  
fill ~7 ~3 ~37 ~7 ~4 ~37 stonebrick 3  
fill ~7 ~3 ~38 ~7 ~4 ~38 stonebrick 3  
fill ~7 ~3 ~39 ~7 ~4 ~39 stonebrick 3  
fill ~7 ~3 ~40 ~7 ~4 ~40 stonebrick 3  
fill ~7 ~3 ~41 ~7 ~4 ~41 stonebrick 3  
fill ~7 ~3 ~42 ~7 ~4 ~42 stonebrick 3  
fill ~7 ~3 ~43 ~7 ~4 ~43 stonebrick 3  
fill ~7 ~3 ~44 ~7 ~4 ~44 stonebrick 3  
fill ~7 ~3 ~45 ~7 ~4 ~45 stonebrick 3  
fill ~7 ~3 ~46 ~17 ~3 ~46 stonebrick 3  
fill ~7 ~3 ~47 ~7 ~4 ~47 stonebrick 3  
fill ~7 ~3 ~48 ~7 ~4 ~48 stonebrick 3  
fill ~7 ~3 ~49 ~7 ~4 ~49 stonebrick 3  
fill ~7 ~3 ~50 ~7 ~4 ~50 stonebrick 3  
fill ~7 ~3 ~51 ~7 ~4 ~51 stonebrick 3  
fill ~7 ~3 ~52 ~7 ~4 ~52 stonebrick 3  
fill ~7 ~3 ~53 ~7 ~4 ~53 stonebrick 3  
fill ~7 ~3 ~54 ~7 ~4 ~54 stonebrick 3  
fill ~7 ~3 ~55 ~7 ~4 ~55 stonebrick 3  
fill ~7 ~3 ~56 ~7 ~4 ~56 stonebrick 3  
fill ~7 ~3 ~57 ~7 ~4 ~57 stonebrick 3  
fill ~7 ~3 ~58 ~7 ~4 ~58 stonebrick 3  
fill ~7 ~3 ~59 ~7 ~4 ~59 stonebrick 3  
fill ~7 ~3 ~60 ~7 ~4 ~60 stonebrick 3  
fill ~7 ~3 ~61 ~7 ~4 ~61 stonebrick 3  
fill ~7 ~3 ~62 ~7 ~4 ~62 stonebrick 3  
fill ~7 ~3 ~63 ~7 ~4 ~63 stonebrick 3  
fill ~7 ~3 ~64 ~7 ~4 ~64 stonebrick 3  
fill ~7 ~3 ~65 ~7 ~4 ~65 stonebrick 3  
fill ~7 ~3 ~66 ~7 ~4 ~66 stonebrick 3  
fill ~7 ~3 ~67 ~20 ~3 ~67 stonebrick 3  
fill ~7 ~3 ~68 ~7 ~4 ~68 stonebrick 3  
fill ~7 ~3 ~69 ~31 ~3 ~69 stonebrick 3  
fill ~9 ~3 ~7 ~33 ~3 ~7 stonebrick 3  
fill ~9 ~3 ~8 ~33 ~3 ~8 stonebrick 3  
fill ~9 ~3 ~9 ~16 ~3 ~9 stonebrick 3  
fill ~10 ~3 ~6 ~33 ~3 ~6 stonebrick 3  
fill ~10 ~3 ~10 ~16 ~3 ~10 stonebrick 3  
fill ~10 ~3 ~11 ~16 ~3 ~11 stonebrick 3  
fill ~10 ~3 ~12 ~16 ~3 ~12 stonebrick 3  
fill ~10 ~3 ~13 ~16 ~3 ~13 stonebrick 3  
fill ~10 ~3 ~14 ~16 ~3 ~14 stonebrick 3  
fill ~10 ~3 ~15 ~16 ~3 ~15 stonebrick 3  
fill ~10 ~3 ~16 ~16 ~3 ~16 stonebrick 3  
fill ~10 ~3 ~17 ~16 ~3 ~17 stonebrick 3  
fill ~10 ~3 ~18 ~16 ~3 ~18 stonebrick 3  
fill ~10 ~3 ~19 ~16 ~3 ~19 stonebrick 3  
fill ~10 ~3 ~20 ~16 ~3 ~20 stonebrick 3  
fill ~10 ~3 ~21 ~16 ~3 ~21 stonebrick 3  
fill ~10 ~3 ~22 ~16 ~3 ~22 stonebrick 3  
fill ~10 ~3 ~23 ~16 ~3 ~23 stonebrick 3  
fill ~10 ~3 ~24 ~16 ~3 ~24 stonebrick 3  
fill ~10 ~3 ~25 ~16 ~3 ~25 stonebrick 3  
fill ~10 ~3 ~27 ~16 ~3 ~27 stonebrick 3  
fill ~10 ~3 ~28 ~16 ~3 ~28 stonebrick 3  
fill ~10 ~3 ~29 ~16 ~3 ~29 stonebrick 3  
fill ~10 ~3 ~30 ~16 ~3 ~30 stonebrick 3  
fill ~10 ~3 ~31 ~16 ~3 ~31 stonebrick 3  
fill ~10 ~3 ~32 ~16 ~3 ~32 stonebrick 3  
fill ~10 ~3 ~33 ~16 ~3 ~33 stonebrick 3  
fill ~10 ~3 ~34 ~16 ~3 ~34 stonebrick 3  
fill ~10 ~3 ~35 ~16 ~3 ~35 stonebrick 3  
fill ~10 ~3 ~36 ~16 ~3 ~36 stonebrick 3  
fill ~10 ~3 ~37 ~16 ~3 ~37 stonebrick 3  
fill ~10 ~3 ~38 ~16 ~3 ~38 stonebrick 3  
fill ~10 ~3 ~39 ~16 ~3 ~39 stonebrick 3  
fill ~10 ~3 ~40 ~16 ~3 ~40 stonebrick 3  
fill ~10 ~3 ~41 ~16 ~3 ~41 stonebrick 3  
fill ~10 ~3 ~42 ~16 ~3 ~42 stonebrick 3  
fill ~10 ~3 ~43 ~16 ~3 ~43 stonebrick 3  
fill ~10 ~3 ~44 ~17 ~3 ~44 stonebrick 3  
fill ~10 ~3 ~45 ~17 ~3 ~45 stonebrick 3  
fill ~10 ~3 ~47 ~17 ~3 ~47 stonebrick 3  
fill ~10 ~3 ~48 ~17 ~3 ~48 stonebrick 3  
fill ~10 ~3 ~49 ~17 ~3 ~49 stonebrick 3  
fill ~10 ~3 ~50 ~17 ~3 ~50 stonebrick 3  
fill ~10 ~3 ~51 ~17 ~3 ~51 stonebrick 3  
fill ~10 ~3 ~52 ~17 ~3 ~52 stonebrick 3  
fill ~10 ~3 ~53 ~18 ~3 ~53 stonebrick 3  
fill ~10 ~3 ~54 ~18 ~3 ~54 stonebrick 3  
fill ~10 ~3 ~55 ~19 ~3 ~55 stonebrick 3  
fill ~10 ~3 ~56 ~19 ~3 ~56 stonebrick 3  
fill ~10 ~3 ~57 ~19 ~3 ~57 stonebrick 3  
fill ~10 ~3 ~58 ~19 ~3 ~58 stonebrick 3  
fill ~10 ~3 ~59 ~19 ~3 ~59 stonebrick 3  
fill ~10 ~3 ~60 ~19 ~3 ~60 stonebrick 3  
fill ~10 ~3 ~61 ~19 ~3 ~61 stonebrick 3  
fill ~10 ~3 ~62 ~19 ~3 ~62 stonebrick 3  
fill ~10 ~3 ~63 ~19 ~3 ~63 stonebrick 3  
fill ~10 ~3 ~64 ~20 ~3 ~64 stonebrick 3  
fill ~10 ~3 ~65 ~20 ~3 ~65 stonebrick 3  
fill ~10 ~3 ~66 ~20 ~3 ~66 stonebrick 3  
fill ~17 ~3 ~9 ~32 ~3 ~9 stone 0  
fill ~17 ~3 ~10 ~32 ~3 ~10 stone 0  
fill ~17 ~3 ~11 ~32 ~3 ~11 stone 0  
fill ~17 ~3 ~12 ~34 ~3 ~12 stone 0  
fill ~17 ~3 ~13 ~34 ~3 ~13 stone 0  
fill ~17 ~3 ~14 ~34 ~3 ~14 stone 0  
fill ~17 ~3 ~15 ~34 ~3 ~15 stone 0  
fill ~17 ~3 ~16 ~34 ~3 ~16 stone 0  
fill ~17 ~3 ~17 ~34 ~3 ~17 stone 0  
fill ~17 ~3 ~18 ~34 ~3 ~18 stone 0  
fill ~17 ~3 ~19 ~34 ~3 ~19 stone 0  
fill ~17 ~3 ~20 ~17 ~6 ~20 stone 0  
fill ~17 ~3 ~21 ~17 ~6 ~21 stone 0  
fill ~17 ~3 ~22 ~17 ~6 ~22 stone 0  
fill ~17 ~3 ~25 ~18 ~3 ~25 stone 0  
fill ~17 ~3 ~26 ~18 ~3 ~26 stone 0  
fill ~17 ~3 ~27 ~18 ~3 ~27 stone 0  
fill ~17 ~3 ~31 ~17 ~3 ~43 stone 0  
fill ~18 ~3 ~28 ~18 ~4 ~28 stone 0  
fill ~18 ~3 ~31 ~18 ~4 ~31 dirt 0  
fill ~18 ~3 ~38 ~19 ~3 ~38 dirt 0  
fill ~18 ~3 ~44 ~18 ~3 ~52 stone 0  
fill ~19 ~3 ~22 ~19 ~6 ~22 stone 0  
fill ~19 ~3 ~28 ~19 ~4 ~28 dirt 0  
fill ~19 ~3 ~29 ~32 ~3 ~29 stone 0  
fill ~19 ~3 ~30 ~32 ~3 ~30 stone 0  
fill ~19 ~3 ~31 ~32 ~3 ~31 stone 0  
fill ~19 ~3 ~32 ~32 ~3 ~32 stone 0  
fill ~19 ~3 ~33 ~32 ~3 ~33 stone 0  
fill ~19 ~3 ~34 ~32 ~3 ~34 stone 0  
fill ~19 ~3 ~35 ~32 ~3 ~35 stone 0  
fill ~19 ~3 ~36 ~19 ~4 ~36 dirt 0  
fill ~19 ~3 ~37 ~19 ~4 ~37 dirt 0  
fill ~19 ~3 ~39 ~19 ~4 ~39 dirt 0  
fill ~19 ~3 ~41 ~19 ~4 ~41 dirt 0  
fill ~19 ~3 ~46 ~21 ~3 ~46 dirt 0  
fill ~19 ~3 ~47 ~21 ~3 ~47 dirt 0  
fill ~19 ~3 ~49 ~21 ~3 ~49 dirt 0  
fill ~19 ~3 ~50 ~22 ~3 ~50 dirt 0  
fill ~19 ~3 ~51 ~22 ~3 ~51 dirt 0  
fill ~19 ~3 ~52 ~22 ~3 ~52 dirt 0  
fill ~19 ~3 ~53 ~19 ~3 ~54 stone 0  
fill ~20 ~3 ~20 ~34 ~3 ~20 stone 0  
fill ~20 ~3 ~22 ~20 ~4 ~22 dirt 0  
fill ~20 ~3 ~23 ~21 ~3 ~23 stone 0  
fill ~20 ~3 ~26 ~22 ~3 ~26 gravel 0  
fill ~20 ~3 ~27 ~22 ~3 ~27 gravel 0  
fill ~20 ~3 ~28 ~33 ~3 ~28 stone 0  
fill ~20 ~3 ~36 ~32 ~3 ~36 stone 0  
fill ~20 ~3 ~37 ~32 ~3 ~37 stone 0  
fill ~20 ~3 ~38 ~32 ~3 ~38 stone 0  
fill ~20 ~3 ~39 ~32 ~3 ~39 stone 0  
fill ~20 ~3 ~40 ~32 ~3 ~40 stone 0  
fill ~20 ~3 ~41 ~32 ~3 ~41 stone 0  
fill ~20 ~3 ~42 ~20 ~4 ~42 dirt 0  
fill ~20 ~3 ~43 ~20 ~4 ~43 dirt 0  
fill ~20 ~3 ~44 ~20 ~4 ~44 dirt 0  
fill ~20 ~3 ~48 ~21 ~3 ~48 dirt 0  
fill ~20 ~3 ~53 ~22 ~3 ~53 dirt 0  
fill ~20 ~3 ~54 ~22 ~3 ~54 dirt 0  
fill ~20 ~3 ~55 ~20 ~3 ~63 stone 0  
fill ~21 ~3 ~21 ~25 ~3 ~21 stone 0  
fill ~21 ~3 ~22 ~22 ~3 ~22 stone 0  
fill ~21 ~3 ~24 ~21 ~6 ~24 stone 0  
fill ~21 ~3 ~25 ~24 ~3 ~25 gravel 0  
fill ~21 ~3 ~42 ~32 ~3 ~42 stone 0  
fill ~21 ~3 ~43 ~32 ~3 ~43 stone 0  
fill ~21 ~3 ~44 ~33 ~3 ~44 stone 0  
fill ~21 ~3 ~45 ~37 ~3 ~45 stone 0  
fill ~21 ~3 ~55 ~22 ~3 ~55 dirt 0  
fill ~21 ~3 ~56 ~22 ~3 ~56 dirt 0  
fill ~21 ~3 ~57 ~22 ~3 ~57 dirt 0  
fill ~21 ~3 ~58 ~22 ~3 ~58 dirt 0  
fill ~21 ~3 ~59 ~22 ~3 ~59 dirt 0  
fill ~21 ~3 ~60 ~22 ~3 ~60 dirt 0  
fill ~21 ~3 ~61 ~22 ~3 ~61 dirt 0  
fill ~21 ~3 ~62 ~22 ~3 ~62 dirt 0  
fill ~21 ~3 ~63 ~26 ~3 ~63 dirt 0  
fill ~21 ~3 ~64 ~21 ~3 ~68 stone 0  
fill ~22 ~3 ~23 ~25 ~3 ~23 gravel 0  
fill ~22 ~3 ~24 ~25 ~3 ~24 gravel 0  
fill ~22 ~3 ~46 ~38 ~3 ~46 stone 0  
fill ~22 ~3 ~47 ~38 ~3 ~47 stone 0  
fill ~22 ~3 ~48 ~38 ~3 ~48 stone 0  
fill ~22 ~3 ~49 ~38 ~3 ~49 stone 0  
fill ~22 ~3 ~64 ~27 ~3 ~64 dirt 0  
fill ~22 ~3 ~65 ~28 ~3 ~65 dirt 0  
fill ~22 ~3 ~66 ~29 ~3 ~66 dirt 0  
fill ~22 ~3 ~68 ~31 ~3 ~68 dirt 0  
fill ~23 ~3 ~22 ~25 ~3 ~22 gravel 0  
fill ~23 ~3 ~26 ~34 ~3 ~26 stone 0  
fill ~23 ~3 ~27 ~37 ~3 ~27 stone 0  
fill ~23 ~3 ~50 ~38 ~3 ~50 stone 0  
fill ~23 ~3 ~51 ~38 ~3 ~51 stone 0  
fill ~23 ~3 ~52 ~38 ~3 ~52 stone 0  
fill ~23 ~3 ~53 ~38 ~3 ~53 stone 0  
fill ~23 ~3 ~54 ~26 ~3 ~54 stone 0  
fill ~23 ~3 ~55 ~27 ~3 ~55 stone 0  
fill ~23 ~3 ~56 ~38 ~3 ~56 stone 0  
fill ~23 ~3 ~57 ~38 ~3 ~57 stone 0  
fill ~23 ~3 ~58 ~38 ~3 ~58 stone 0  
fill ~23 ~3 ~59 ~38 ~3 ~59 stone 0  
fill ~23 ~3 ~60 ~38 ~3 ~60 stone 0  
fill ~23 ~3 ~61 ~38 ~3 ~61 stone 0  
fill ~23 ~3 ~62 ~24 ~3 ~62 coal_ore 0  
fill ~23 ~3 ~67 ~30 ~3 ~67 dirt 0  
fill ~25 ~3 ~25 ~34 ~3 ~25 stone 0  
fill ~25 ~3 ~62 ~38 ~3 ~62 stone 0  
fill ~26 ~3 ~22 ~34 ~3 ~22 stone 0  
fill ~26 ~3 ~23 ~34 ~3 ~23 stone 0  
fill ~26 ~3 ~24 ~34 ~3 ~24 stone 0  
fill ~27 ~3 ~21 ~34 ~3 ~21 stone 0  
fill ~27 ~3 ~54 ~31 ~3 ~54 coal_ore 0  
fill ~27 ~3 ~63 ~34 ~3 ~63 stone 0  
fill ~28 ~3 ~55 ~31 ~3 ~55 coal_ore 0  
fill ~28 ~3 ~64 ~34 ~3 ~64 stone 0  
fill ~29 ~3 ~65 ~34 ~3 ~65 stone 0  
fill ~30 ~3 ~66 ~34 ~3 ~66 stone 0  
fill ~31 ~3 ~67 ~34 ~3 ~67 stone 0  
fill ~32 ~3 ~54 ~38 ~3 ~54 stone 0  
fill ~32 ~3 ~55 ~38 ~3 ~55 stone 0  
fill ~32 ~3 ~68 ~34 ~3 ~68 stone 0 
setblock ~33 ~3 ~9 stonebrick 3 
setblock ~33 ~3 ~11 stonebrick 3  
fill ~33 ~3 ~69 ~35 ~3 ~69 stonebrick 3  
fill ~35 ~3 ~4 ~35 ~4 ~4 stonebrick 3  
fill ~35 ~3 ~6 ~35 ~4 ~6 stonebrick 3  
fill ~35 ~3 ~7 ~35 ~4 ~7 stonebrick 3  
fill ~35 ~3 ~8 ~35 ~4 ~8 stonebrick 3  
fill ~35 ~3 ~9 ~35 ~4 ~9 stonebrick 3  
fill ~35 ~3 ~10 ~35 ~4 ~10 stonebrick 3  
fill ~35 ~3 ~11 ~35 ~4 ~11 stonebrick 3  
fill ~35 ~3 ~26 ~40 ~3 ~26 stonebrick 3  
fill ~36 ~3 ~63 ~38 ~3 ~63 stone 0  
fill ~36 ~3 ~64 ~38 ~3 ~64 stone 0  
fill ~36 ~3 ~65 ~38 ~3 ~65 stone 0  
fill ~36 ~3 ~66 ~38 ~3 ~66 stone 0  
fill ~39 ~3 ~30 ~40 ~3 ~30 obsidian 0  
fill ~39 ~3 ~31 ~39 ~6 ~31 obsidian 0  
fill ~39 ~3 ~34 ~39 ~6 ~34 obsidian 0  
fill ~39 ~3 ~35 ~39 ~6 ~35 obsidian 0  
fill ~39 ~3 ~37 ~39 ~6 ~37 obsidian 0  
fill ~39 ~3 ~38 ~39 ~6 ~38 obsidian 0  
fill ~39 ~3 ~41 ~39 ~6 ~41 obsidian 0  
fill ~39 ~3 ~42 ~40 ~3 ~42 obsidian 0  
fill ~39 ~3 ~46 ~40 ~3 ~46 stonebrick 3  
fill ~39 ~3 ~47 ~39 ~3 ~67 bedrock 0  
fill ~40 ~3 ~29 ~41 ~3 ~29 obsidian 0  
fill ~40 ~3 ~43 ~41 ~3 ~43 obsidian 0  
fill ~41 ~3 ~28 ~42 ~3 ~28 obsidian 0  
fill ~41 ~3 ~44 ~42 ~3 ~44 obsidian 0  
fill ~42 ~3 ~26 ~43 ~3 ~26 stonebrick 3  
fill ~42 ~3 ~46 ~43 ~3 ~46 stonebrick 3  
fill ~45 ~3 ~26 ~46 ~3 ~26 stonebrick 3  
fill ~45 ~3 ~28 ~46 ~3 ~28 obsidian 0  
fill ~45 ~3 ~44 ~46 ~3 ~44 obsidian 0  
fill ~45 ~3 ~46 ~46 ~3 ~46 stonebrick 3  
fill ~48 ~3 ~26 ~49 ~3 ~26 stonebrick 3  
fill ~48 ~3 ~28 ~49 ~3 ~28 obsidian 0  
fill ~48 ~3 ~44 ~49 ~3 ~44 obsidian 0  
fill ~48 ~3 ~46 ~49 ~3 ~46 stonebrick 3  
fill ~51 ~3 ~26 ~52 ~3 ~26 stonebrick 3  
fill ~51 ~3 ~46 ~52 ~3 ~46 stonebrick 3  
fill ~52 ~3 ~28 ~53 ~3 ~28 obsidian 0  
fill ~52 ~3 ~44 ~52 ~6 ~44 obsidian 0 
setblock ~53 ~3 ~29 obsidian 0  
fill ~53 ~3 ~43 ~54 ~3 ~43 obsidian 0  
fill ~54 ~3 ~26 ~55 ~3 ~26 stonebrick 3  
fill ~54 ~3 ~30 ~55 ~3 ~30 obsidian 0  
fill ~55 ~3 ~31 ~55 ~6 ~31 obsidian 0  
fill ~55 ~3 ~34 ~55 ~6 ~34 obsidian 0  
fill ~55 ~3 ~35 ~55 ~6 ~35 obsidian 0  
fill ~55 ~3 ~37 ~55 ~6 ~37 obsidian 0  
fill ~55 ~3 ~38 ~55 ~6 ~38 obsidian 0  
fill ~55 ~3 ~41 ~55 ~6 ~41 obsidian 0  
fill ~61 ~3 ~21 ~62 ~3 ~21 stonebrick 3  
fill ~61 ~3 ~22 ~62 ~3 ~22 stonebrick 3  
fill ~61 ~3 ~50 ~62 ~3 ~50 stonebrick 3  
fill ~61 ~3 ~51 ~62 ~3 ~51 stonebrick 3  
fill ~7 ~4 ~3 ~35 ~4 ~3 stonebrick 3  
fill ~7 ~4 ~5 ~7 ~3 ~5 stonebrick 3  
fill ~7 ~4 ~26 ~7 ~3 ~26 stonebrick 3  
fill ~7 ~4 ~46 ~7 ~3 ~46 stonebrick 3  
fill ~7 ~4 ~67 ~7 ~3 ~67 stonebrick 3  
fill ~7 ~4 ~69 ~35 ~4 ~69 stonebrick 3  
fill ~8 ~4 ~4 ~32 ~4 ~4 glowstone 0  
fill ~8 ~4 ~5 ~8 ~4 ~68 glowstone 0  
fill ~9 ~4 ~5 ~34 ~4 ~5 stone 0  
fill ~9 ~4 ~6 ~33 ~4 ~6 stone 0  
fill ~9 ~4 ~7 ~33 ~4 ~7 stone 0  
fill ~9 ~4 ~8 ~33 ~4 ~8 stone 0  
fill ~9 ~4 ~9 ~33 ~4 ~9 stone 0  
fill ~9 ~4 ~10 ~33 ~4 ~10 stone 0  
fill ~9 ~4 ~11 ~34 ~4 ~11 stone 0  
fill ~9 ~4 ~12 ~34 ~4 ~12 stone 0  
fill ~9 ~4 ~13 ~34 ~4 ~13 stone 0  
fill ~9 ~4 ~14 ~9 ~4 ~5 stone 0  
fill ~9 ~4 ~26 ~13 ~4 ~26 stonebrick 3  
fill ~9 ~4 ~46 ~18 ~4 ~46 stonebrick 3  
fill ~9 ~4 ~67 ~20 ~4 ~67 stonebrick 3  
fill ~9 ~4 ~68 ~20 ~4 ~68 glowstone 0  
fill ~10 ~4 ~14 ~10 ~3 ~14 stonebrick 3  
fill ~10 ~4 ~15 ~13 ~4 ~15 stonebrick 3  
fill ~10 ~4 ~16 ~13 ~4 ~16 stonebrick 3  
fill ~10 ~4 ~17 ~13 ~4 ~17 stonebrick 3  
fill ~10 ~4 ~18 ~13 ~4 ~18 stonebrick 3  
fill ~10 ~4 ~19 ~13 ~4 ~19 stonebrick 3 
fill ~10 ~4 ~20 ~13 ~4 ~20 stonebrick 3  
fill ~10 ~4 ~21 ~13 ~4 ~21 stonebrick 3  
fill ~10 ~4 ~22 ~13 ~4 ~22 stonebrick 3  
fill ~10 ~4 ~23 ~13 ~4 ~23 stonebrick 3  
fill ~10 ~4 ~24 ~13 ~4 ~24 stonebrick 3  
fill ~10 ~4 ~25 ~13 ~4 ~25 stonebrick 3  
fill ~10 ~4 ~27 ~13 ~4 ~27 stonebrick 3  
fill ~10 ~4 ~28 ~14 ~4 ~28 stonebrick 3  
fill ~10 ~4 ~29 ~18 ~4 ~29 stonebrick 3  
fill ~10 ~4 ~30 ~17 ~4 ~30 stonebrick 3  
fill ~10 ~4 ~31 ~17 ~4 ~31 stonebrick 3  
fill ~10 ~4 ~32 ~17 ~4 ~32 stonebrick 3  
fill ~10 ~4 ~33 ~17 ~4 ~33 stonebrick 3  
fill ~10 ~4 ~34 ~17 ~4 ~34 stonebrick 3  
fill ~10 ~4 ~35 ~18 ~4 ~35 stonebrick 3  
fill ~10 ~4 ~36 ~18 ~4 ~36 stonebrick 3  
fill ~10 ~4 ~37 ~18 ~4 ~37 stonebrick 3  
fill ~10 ~4 ~38 ~18 ~4 ~38 stonebrick 3  
fill ~10 ~4 ~39 ~18 ~4 ~39 stonebrick 3  
fill ~10 ~4 ~40 ~18 ~4 ~40 stonebrick 3  
fill ~10 ~4 ~41 ~18 ~4 ~41 stonebrick 3  
fill ~10 ~4 ~42 ~18 ~4 ~42 stonebrick 3  
fill ~10 ~4 ~43 ~18 ~4 ~43 stonebrick 3  
fill ~10 ~4 ~44 ~18 ~4 ~44 stonebrick 3  
fill ~10 ~4 ~45 ~18 ~4 ~45 stonebrick 3  
fill ~10 ~4 ~47 ~18 ~4 ~47 stonebrick 3  
fill ~10 ~4 ~48 ~18 ~4 ~48 stonebrick 3  
fill ~10 ~4 ~49 ~18 ~4 ~49 stonebrick 3  
fill ~10 ~4 ~50 ~18 ~4 ~50 stonebrick 3  
fill ~10 ~4 ~51 ~18 ~4 ~51 stonebrick 3  
fill ~10 ~4 ~52 ~19 ~4 ~52 stonebrick 3  
fill ~10 ~4 ~53 ~19 ~4 ~53 stonebrick 3  
fill ~10 ~4 ~54 ~20 ~4 ~54 stonebrick 3  
fill ~10 ~4 ~55 ~20 ~4 ~55 stonebrick 3  
fill ~10 ~4 ~56 ~20 ~4 ~56 stonebrick 3  
fill ~10 ~4 ~57 ~20 ~4 ~57 stonebrick 3  
fill ~10 ~4 ~58 ~21 ~4 ~58 stonebrick 3  
fill ~10 ~4 ~59 ~21 ~4 ~59 stonebrick 3  
fill ~10 ~4 ~60 ~21 ~4 ~60 stonebrick 3  
fill ~10 ~4 ~61 ~21 ~4 ~61 stonebrick 3  
fill ~10 ~4 ~62 ~21 ~4 ~62 stonebrick 3  
fill ~10 ~4 ~63 ~21 ~4 ~63 stonebrick 3  
fill ~10 ~4 ~64 ~21 ~4 ~64 stonebrick 3  
fill ~10 ~4 ~65 ~21 ~4 ~65 stonebrick 3  
fill ~10 ~4 ~66 ~21 ~4 ~66 stonebrick 3  
fill ~11 ~4 ~14 ~34 ~4 ~14 stone 0  
fill ~14 ~4 ~15 ~34 ~4 ~15 stone 0  
fill ~14 ~4 ~16 ~34 ~4 ~16 stone 0  
fill ~14 ~4 ~17 ~34 ~4 ~17 stone 0  
fill ~14 ~4 ~18 ~34 ~4 ~18 stone 0  
fill ~14 ~4 ~19 ~34 ~4 ~19 stone 0  
fill ~14 ~4 ~20 ~33 ~4 ~20 stone 0  
fill ~14 ~4 ~21 ~19 ~4 ~21 stone 0  
fill ~14 ~4 ~22 ~19 ~4 ~22 stone 0  
fill ~14 ~4 ~23 ~18 ~4 ~23 stone 0  
fill ~14 ~4 ~24 ~18 ~4 ~24 stone 0  
fill ~14 ~4 ~25 ~18 ~4 ~25 stone 0  
fill ~14 ~4 ~26 ~18 ~4 ~26 stone 0  
fill ~14 ~4 ~27 ~18 ~4 ~27 stone 0  
fill ~15 ~4 ~28 ~18 ~4 ~28 stone 0 
setblock ~19 ~4 ~29 dirt 0  
fill ~19 ~4 ~30 ~32 ~4 ~30 stone 0  
fill ~19 ~4 ~31 ~32 ~4 ~31 stone 0  
fill ~19 ~4 ~32 ~32 ~4 ~32 stone 0  
fill ~19 ~4 ~33 ~32 ~4 ~33 stone 0  
fill ~19 ~4 ~34 ~32 ~4 ~34 stone 0 
setblock ~19 ~4 ~35 dirt 0  
fill ~19 ~4 ~38 ~20 ~4 ~38 dirt 0  
fill ~19 ~4 ~46 ~21 ~4 ~46 dirt 0  
fill ~19 ~4 ~47 ~22 ~4 ~47 dirt 0  
fill ~19 ~4 ~49 ~22 ~4 ~49 dirt 0  
fill ~19 ~4 ~50 ~22 ~4 ~50 dirt 0  
fill ~19 ~4 ~51 ~22 ~4 ~51 dirt 0  
fill ~20 ~4 ~23 ~20 ~4 ~26 dirt 0  
fill ~20 ~4 ~27 ~22 ~4 ~27 stone 0  
fill ~20 ~4 ~28 ~33 ~4 ~28 stone 0  
fill ~20 ~4 ~29 ~32 ~4 ~29 stone 0  
fill ~20 ~4 ~35 ~32 ~4 ~35 stone 0  
fill ~20 ~4 ~36 ~32 ~4 ~36 stone 0  
fill ~20 ~4 ~37 ~32 ~4 ~37 stone 0 
setblock ~20 ~4 ~39 dirt 0  
fill ~20 ~4 ~40 ~32 ~4 ~40 stone 0 
setblock ~20 ~4 ~41 dirt 0  
fill ~20 ~4 ~48 ~22 ~4 ~48 dirt 0  
fill ~20 ~4 ~52 ~22 ~4 ~52 dirt 0  
fill ~20 ~4 ~53 ~22 ~4 ~53 dirt 0  
fill ~21 ~4 ~21 ~34 ~4 ~21 stone 0  
fill ~21 ~4 ~22 ~33 ~4 ~22 stone 0  
fill ~21 ~4 ~23 ~33 ~4 ~23 stone 0  
fill ~21 ~4 ~25 ~21 ~6 ~25 stone 0  
fill ~21 ~4 ~26 ~21 ~6 ~26 stone 0  
fill ~21 ~4 ~38 ~32 ~4 ~38 stone 0  
fill ~21 ~4 ~39 ~32 ~4 ~39 stone 0  
fill ~21 ~4 ~41 ~32 ~4 ~41 stone 0  
fill ~21 ~4 ~42 ~32 ~4 ~42 stone 0  
fill ~21 ~4 ~43 ~32 ~4 ~43 stone 0  
fill ~21 ~4 ~44 ~33 ~4 ~44 stone 0 
setblock ~21 ~4 ~45 dirt 0  
fill ~21 ~4 ~54 ~22 ~4 ~54 dirt 0  
fill ~21 ~4 ~55 ~23 ~4 ~55 dirt 0  
fill ~21 ~4 ~56 ~23 ~4 ~56 dirt 0  
fill ~21 ~4 ~57 ~24 ~4 ~57 dirt 0  
fill ~21 ~4 ~67 ~22 ~4 ~67 stone 0  
fill ~21 ~4 ~68 ~22 ~4 ~68 stone 0  
fill ~22 ~4 ~24 ~23 ~4 ~24 coal_ore 0  
fill ~22 ~4 ~25 ~23 ~4 ~25 coal_ore 0  
fill ~22 ~4 ~26 ~23 ~4 ~26 coal_ore 0  
fill ~22 ~4 ~45 ~37 ~4 ~45 stone 0  
fill ~22 ~4 ~46 ~37 ~4 ~46 stone 0  
fill ~22 ~4 ~58 ~24 ~4 ~58 dirt 0  
fill ~22 ~4 ~59 ~25 ~4 ~59 dirt 0  
fill ~22 ~4 ~60 ~26 ~4 ~60 dirt 0  
fill ~22 ~4 ~61 ~28 ~4 ~61 dirt 0  
fill ~22 ~4 ~62 ~29 ~4 ~62 dirt 0  
fill ~22 ~4 ~63 ~29 ~4 ~63 dirt 0  
fill ~22 ~4 ~64 ~31 ~4 ~64 dirt 0  
fill ~22 ~4 ~65 ~22 ~4 ~68 stone 0 
setblock ~23 ~4 ~27 coal_ore 0  
fill ~23 ~4 ~47 ~36 ~4 ~47 stone 0  
fill ~23 ~4 ~48 ~35 ~4 ~48 stone 0  
fill ~23 ~4 ~49 ~35 ~4 ~49 stone 0  
fill ~23 ~4 ~50 ~34 ~4 ~50 stone 0  
fill ~23 ~4 ~51 ~34 ~4 ~51 stone 0  
fill ~23 ~4 ~52 ~34 ~4 ~52 stone 0  
fill ~23 ~4 ~53 ~34 ~4 ~53 stone 0  
fill ~23 ~4 ~54 ~26 ~4 ~54 stone 0  
fill ~23 ~4 ~65 ~31 ~4 ~65 dirt 0  
fill ~23 ~4 ~66 ~31 ~4 ~66 dirt 0  
fill ~23 ~4 ~67 ~31 ~4 ~67 dirt 0  
fill ~23 ~4 ~68 ~31 ~4 ~68 dirt 0  
fill ~24 ~4 ~24 ~33 ~4 ~24 stone 0  
fill ~24 ~4 ~25 ~33 ~4 ~25 stone 0  
fill ~24 ~4 ~26 ~34 ~4 ~26 stone 0  
fill ~24 ~4 ~27 ~37 ~4 ~27 stone 0  
fill ~24 ~4 ~55 ~27 ~4 ~55 stone 0  
fill ~24 ~4 ~56 ~34 ~4 ~56 stone 0  
fill ~25 ~4 ~57 ~34 ~4 ~57 stone 0  
fill ~25 ~4 ~58 ~34 ~4 ~58 stone 0  
fill ~26 ~4 ~59 ~34 ~4 ~59 stone 0  
fill ~27 ~4 ~54 ~29 ~4 ~54 coal_ore 0  
fill ~27 ~4 ~60 ~34 ~4 ~60 stone 0  
fill ~28 ~4 ~55 ~29 ~4 ~55 coal_ore 0  
fill ~29 ~4 ~61 ~34 ~4 ~61 stone 0  
fill ~30 ~4 ~54 ~34 ~4 ~54 stone 0  
fill ~30 ~4 ~55 ~34 ~4 ~55 stone 0  
fill ~30 ~4 ~62 ~34 ~4 ~62 stone 0  
fill ~30 ~4 ~63 ~34 ~4 ~63 stone 0  
fill ~32 ~4 ~64 ~34 ~4 ~64 stone 0  
fill ~32 ~4 ~65 ~34 ~4 ~65 stone 0  
fill ~32 ~4 ~66 ~34 ~4 ~66 stone 0  
fill ~32 ~4 ~67 ~34 ~4 ~67 stone 0  
fill ~32 ~4 ~68 ~34 ~4 ~68 stone 0 
setblock ~33 ~4 ~4 stone 0 
setblock ~34 ~4 ~4 glowstone 0  
fill ~34 ~4 ~6 ~34 ~4 ~10 glowstone 0  
fill ~34 ~4 ~20 ~34 ~6 ~20 stonebrick 3  
fill ~34 ~4 ~22 ~34 ~7 ~22 stonebrick 3  
fill ~34 ~4 ~23 ~34 ~7 ~23 stonebrick 3  
fill ~34 ~4 ~24 ~34 ~6 ~24 stonebrick 3  
fill ~34 ~4 ~25 ~34 ~5 ~25 stonebrick 3 
setblock ~35 ~4 ~5 stonebrick 3  
fill ~35 ~4 ~26 ~40 ~4 ~26 stonebrick 3  
fill ~35 ~4 ~50 ~35 ~7 ~50 stonebrick 3  
fill ~35 ~4 ~51 ~35 ~4 ~69 stonebrick 3  
fill ~36 ~4 ~48 ~37 ~4 ~48 stonebrick 3  
fill ~36 ~4 ~49 ~36 ~7 ~49 stonebrick 3  
fill ~36 ~4 ~50 ~38 ~4 ~50 bedrock 0  
fill ~36 ~4 ~51 ~37 ~4 ~51 stone 0  
fill ~36 ~4 ~52 ~36 ~4 ~67 stone 0  
fill ~37 ~4 ~47 ~37 ~7 ~47 stonebrick 3  
fill ~37 ~4 ~49 ~38 ~4 ~49 bedrock 0  
fill ~37 ~4 ~52 ~38 ~4 ~52 bedrock 0  
fill ~37 ~4 ~53 ~38 ~4 ~53 bedrock 0  
fill ~37 ~4 ~54 ~38 ~4 ~54 bedrock 0  
fill ~37 ~4 ~55 ~38 ~4 ~55 bedrock 0  
fill ~37 ~4 ~56 ~38 ~4 ~56 bedrock 0  
fill ~37 ~4 ~57 ~38 ~4 ~57 bedrock 0  
fill ~37 ~4 ~58 ~38 ~4 ~58 bedrock 0  
fill ~37 ~4 ~59 ~38 ~4 ~59 bedrock 0  
fill ~37 ~4 ~60 ~38 ~4 ~60 bedrock 0  
fill ~37 ~4 ~61 ~38 ~4 ~61 bedrock 0  
fill ~37 ~4 ~62 ~38 ~4 ~62 bedrock 0  
fill ~37 ~4 ~63 ~38 ~4 ~63 bedrock 0  
fill ~37 ~4 ~64 ~38 ~4 ~64 bedrock 0  
fill ~37 ~4 ~65 ~38 ~4 ~65 bedrock 0  
fill ~37 ~4 ~66 ~38 ~4 ~66 bedrock 0  
fill ~37 ~4 ~67 ~37 ~4 ~52 bedrock 0  
fill ~38 ~4 ~46 ~40 ~4 ~46 stonebrick 3  
fill ~38 ~4 ~47 ~38 ~4 ~66 bedrock 0  
fill ~39 ~4 ~30 ~39 ~2 ~30 obsidian 0  
fill ~39 ~4 ~42 ~39 ~2 ~42 obsidian 0  
fill ~40 ~4 ~29 ~40 ~5 ~29 obsidian 0  
fill ~40 ~4 ~43 ~40 ~5 ~43 obsidian 0  
fill ~41 ~4 ~28 ~42 ~4 ~28 obsidian 0  
fill ~41 ~4 ~44 ~42 ~4 ~44 obsidian 0  
fill ~42 ~4 ~26 ~43 ~4 ~26 stonebrick 3  
fill ~42 ~4 ~46 ~43 ~4 ~46 stonebrick 3  
fill ~45 ~4 ~26 ~46 ~4 ~26 stonebrick 3  
fill ~45 ~4 ~28 ~46 ~4 ~28 obsidian 0  
fill ~45 ~4 ~44 ~46 ~4 ~44 obsidian 0  
fill ~45 ~4 ~46 ~46 ~4 ~46 stonebrick 3  
fill ~48 ~4 ~26 ~49 ~4 ~26 stonebrick 3  
fill ~48 ~4 ~28 ~49 ~4 ~28 obsidian 0  
fill ~48 ~4 ~44 ~49 ~4 ~44 obsidian 0  
fill ~48 ~4 ~46 ~49 ~4 ~46 stonebrick 3  
fill ~51 ~4 ~26 ~52 ~4 ~26 stonebrick 3  
fill ~51 ~4 ~46 ~52 ~4 ~46 stonebrick 3  
fill ~52 ~4 ~28 ~53 ~4 ~28 obsidian 0 
setblock ~53 ~4 ~44 obsidian 0  
fill ~54 ~4 ~26 ~55 ~4 ~26 stonebrick 3  
fill ~54 ~4 ~29 ~54 ~5 ~29 obsidian 0  
fill ~54 ~4 ~43 ~54 ~5 ~43 obsidian 0 
setblock ~55 ~4 ~30 obsidian 0 
setblock ~55 ~4 ~42 obsidian 0  
fill ~59 ~4 ~21 ~62 ~4 ~21 stonebrick 3  
fill ~59 ~4 ~51 ~62 ~4 ~51 stonebrick 3  
fill ~61 ~4 ~22 ~62 ~4 ~22 stonebrick 3  
fill ~61 ~4 ~50 ~62 ~4 ~50 stonebrick 3  
fill ~62 ~4 ~23 ~62 ~5 ~23 stonebrick 3  
fill ~62 ~4 ~24 ~62 ~5 ~24 stonebrick 3  
fill ~62 ~4 ~35 ~62 ~5 ~35 stonebrick 3  
fill ~62 ~4 ~37 ~62 ~5 ~37 stonebrick 3  
fill ~62 ~4 ~48 ~62 ~5 ~48 stonebrick 3  
fill ~62 ~4 ~49 ~62 ~5 ~49 stonebrick 3  
fill ~6 ~5 ~2 ~36 ~5 ~2 stonebrick 3  
fill ~6 ~5 ~3 ~7 ~5 ~3 stonebrick 3  
fill ~6 ~5 ~4 ~6 ~5 ~70 stonebrick 3  
fill ~7 ~5 ~70 ~36 ~5 ~70 stonebrick 3  
fill ~8 ~5 ~4 ~34 ~5 ~4 stonebrick 3  
fill ~8 ~5 ~5 ~34 ~5 ~5 stonebrick 3  
fill ~8 ~5 ~6 ~13 ~5 ~6 stonebrick 3  
fill ~8 ~5 ~7 ~13 ~5 ~7 stonebrick 3  
fill ~8 ~5 ~8 ~13 ~5 ~8 stonebrick 3  
fill ~8 ~5 ~9 ~13 ~5 ~9 stonebrick 3  
fill ~8 ~5 ~10 ~9 ~5 ~10 stonebrick 3  
fill ~8 ~5 ~11 ~9 ~5 ~11 stonebrick 3  
fill ~8 ~5 ~12 ~9 ~5 ~12 stonebrick 3  
fill ~8 ~5 ~13 ~9 ~5 ~13 stonebrick 3  
fill ~8 ~5 ~14 ~9 ~5 ~14 stonebrick 3  
fill ~8 ~5 ~15 ~8 ~6 ~15 stonebrick 3  
fill ~8 ~5 ~16 ~8 ~6 ~16 stonebrick 3  
fill ~8 ~5 ~17 ~8 ~6 ~17 stonebrick 3  
fill ~8 ~5 ~18 ~8 ~6 ~18 stonebrick 3  
fill ~8 ~5 ~19 ~8 ~6 ~19 stonebrick 3  
fill ~8 ~5 ~20 ~8 ~6 ~20 stonebrick 3  
fill ~8 ~5 ~21 ~8 ~6 ~21 stonebrick 3  
fill ~8 ~5 ~22 ~8 ~6 ~22 stonebrick 3  
fill ~8 ~5 ~23 ~8 ~6 ~23 stonebrick 3  
fill ~8 ~5 ~24 ~8 ~6 ~24 stonebrick 3  
fill ~8 ~5 ~25 ~8 ~6 ~25 stonebrick 3  
fill ~8 ~5 ~26 ~13 ~5 ~26 stonebrick 3  
fill ~8 ~5 ~27 ~8 ~7 ~27 stonebrick 3  
fill ~8 ~5 ~28 ~8 ~6 ~28 stonebrick 3  
fill ~8 ~5 ~29 ~8 ~6 ~29 stonebrick 3  
fill ~8 ~5 ~30 ~8 ~6 ~30 stonebrick 3  
fill ~8 ~5 ~31 ~8 ~6 ~31 stonebrick 3  
fill ~8 ~5 ~32 ~8 ~6 ~32 stonebrick 3  
fill ~8 ~5 ~33 ~8 ~6 ~33 stonebrick 3  
fill ~8 ~5 ~34 ~8 ~6 ~34 stonebrick 3  
fill ~8 ~5 ~35 ~8 ~6 ~35 stonebrick 3  
fill ~8 ~5 ~36 ~8 ~6 ~36 stonebrick 3  
fill ~8 ~5 ~37 ~8 ~6 ~37 stonebrick 3  
fill ~8 ~5 ~38 ~8 ~6 ~38 stonebrick 3  
fill ~8 ~5 ~39 ~8 ~6 ~39 stonebrick 3  
fill ~8 ~5 ~40 ~8 ~6 ~40 stonebrick 3  
fill ~8 ~5 ~41 ~8 ~6 ~41 stonebrick 3  
fill ~8 ~5 ~42 ~8 ~6 ~42 stonebrick 3  
fill ~8 ~5 ~43 ~8 ~6 ~43 stonebrick 3  
fill ~8 ~5 ~44 ~8 ~6 ~44 stonebrick 3  
fill ~8 ~5 ~45 ~8 ~7 ~45 stonebrick 3  
fill ~8 ~5 ~46 ~17 ~5 ~46 stonebrick 3  
fill ~8 ~5 ~47 ~8 ~6 ~47 stonebrick 3  
fill ~8 ~5 ~48 ~8 ~6 ~48 stonebrick 3  
fill ~8 ~5 ~49 ~8 ~7 ~49 stonebrick 3  
fill ~8 ~5 ~50 ~8 ~7 ~50 stonebrick 3  
fill ~8 ~5 ~51 ~8 ~6 ~51 stonebrick 3  
fill ~8 ~5 ~52 ~8 ~6 ~52 stonebrick 3  
fill ~8 ~5 ~53 ~8 ~6 ~53 stonebrick 3  
fill ~8 ~5 ~54 ~8 ~6 ~54 stonebrick 3  
fill ~8 ~5 ~55 ~8 ~6 ~55 stonebrick 3  
fill ~8 ~5 ~56 ~8 ~6 ~56 stonebrick 3  
fill ~8 ~5 ~57 ~8 ~6 ~57 stonebrick 3  
fill ~8 ~5 ~58 ~8 ~6 ~58 stonebrick 3  
fill ~8 ~5 ~59 ~8 ~6 ~59 stonebrick 3  
fill ~8 ~5 ~60 ~8 ~6 ~60 stonebrick 3  
fill ~8 ~5 ~61 ~8 ~6 ~61 stonebrick 3  
fill ~8 ~5 ~62 ~8 ~6 ~62 stonebrick 3  
fill ~8 ~5 ~63 ~8 ~6 ~63 stonebrick 3  
fill ~8 ~5 ~64 ~8 ~6 ~64 stonebrick 3  
fill ~8 ~5 ~65 ~8 ~6 ~65 stonebrick 3  
fill ~8 ~5 ~66 ~8 ~6 ~66 stonebrick 3  
fill ~8 ~5 ~67 ~28 ~5 ~67 stonebrick 3  
fill ~8 ~5 ~68 ~34 ~5 ~68 stonebrick 3  
fill ~10 ~5 ~10 ~32 ~5 ~10 stone 0  
fill ~10 ~5 ~11 ~32 ~5 ~11 stone 0  
fill ~10 ~5 ~12 ~32 ~5 ~12 stone 0  
fill ~10 ~5 ~13 ~10 ~5 ~24 stone 0  
fill ~10 ~5 ~25 ~13 ~5 ~25 stonebrick 3  
fill ~10 ~5 ~27 ~13 ~5 ~27 stonebrick 3  
fill ~10 ~5 ~28 ~13 ~5 ~28 stonebrick 3  
fill ~10 ~5 ~29 ~28 ~5 ~29 stonebrick 3  
fill ~10 ~5 ~30 ~29 ~5 ~30 stonebrick 3  
fill ~10 ~5 ~31 ~29 ~5 ~31 stonebrick 3  
fill ~10 ~5 ~32 ~29 ~5 ~32 stonebrick 3  
fill ~10 ~5 ~33 ~29 ~5 ~33 stonebrick 3  
fill ~10 ~5 ~34 ~29 ~5 ~34 stonebrick 3  
fill ~10 ~5 ~35 ~29 ~5 ~35 stonebrick 3  
fill ~10 ~5 ~36 ~29 ~5 ~36 stonebrick 3  
fill ~10 ~5 ~37 ~29 ~5 ~37 stonebrick 3  
fill ~10 ~5 ~38 ~29 ~5 ~38 stonebrick 3  
fill ~10 ~5 ~39 ~29 ~5 ~39 stonebrick 3  
fill ~10 ~5 ~40 ~29 ~5 ~40 stonebrick 3  
fill ~10 ~5 ~41 ~29 ~5 ~41 stonebrick 3  
fill ~10 ~5 ~42 ~29 ~5 ~42 stonebrick 3  
fill ~10 ~5 ~43 ~28 ~5 ~43 stonebrick 3  
fill ~10 ~5 ~44 ~28 ~5 ~44 stonebrick 3  
fill ~10 ~5 ~45 ~17 ~5 ~45 stonebrick 3  
fill ~10 ~5 ~47 ~13 ~5 ~47 stonebrick 3  
fill ~10 ~5 ~48 ~13 ~5 ~48 stone 0  
fill ~10 ~5 ~49 ~28 ~5 ~49 stonebrick 3  
fill ~10 ~5 ~50 ~28 ~5 ~50 stonebrick 3  
fill ~10 ~5 ~51 ~28 ~5 ~51 stonebrick 3  
fill ~10 ~5 ~52 ~28 ~5 ~52 stonebrick 3  
fill ~10 ~5 ~53 ~28 ~5 ~53 stonebrick 3  
fill ~10 ~5 ~54 ~28 ~5 ~54 stonebrick 3  
fill ~10 ~5 ~55 ~28 ~5 ~55 stonebrick 3  
fill ~10 ~5 ~56 ~28 ~5 ~56 stonebrick 3  
fill ~10 ~5 ~57 ~28 ~5 ~57 stonebrick 3  
fill ~10 ~5 ~58 ~28 ~5 ~58 stonebrick 3  
fill ~10 ~5 ~59 ~28 ~5 ~59 stonebrick 3  
fill ~10 ~5 ~60 ~28 ~5 ~60 stonebrick 3  
fill ~10 ~5 ~61 ~27 ~5 ~61 stonebrick 3  
fill ~10 ~5 ~62 ~27 ~5 ~62 stonebrick 3  
fill ~10 ~5 ~63 ~27 ~5 ~63 stonebrick 3  
fill ~10 ~5 ~64 ~27 ~5 ~64 stonebrick 3  
fill ~10 ~5 ~65 ~27 ~5 ~65 stonebrick 3  
fill ~10 ~5 ~66 ~28 ~5 ~66 stonebrick 3  
fill ~11 ~5 ~13 ~18 ~5 ~13 stonebrick 3  
fill ~11 ~5 ~14 ~18 ~5 ~14 stonebrick 3  
fill ~11 ~5 ~15 ~13 ~5 ~15 stonebrick 3  
fill ~11 ~5 ~16 ~13 ~5 ~16 stonebrick 3  
fill ~11 ~5 ~17 ~13 ~5 ~17 stonebrick 3  
fill ~11 ~5 ~18 ~13 ~5 ~18 stonebrick 3  
fill ~11 ~5 ~19 ~13 ~5 ~19 stonebrick 3  
fill ~11 ~5 ~20 ~13 ~5 ~20 stonebrick 3  
fill ~11 ~5 ~21 ~13 ~5 ~21 stonebrick 3  
fill ~11 ~5 ~22 ~13 ~5 ~22 stonebrick 3  
fill ~11 ~5 ~23 ~13 ~5 ~23 stonebrick 3  
fill ~11 ~5 ~24 ~11 ~5 ~13 stonebrick 3  
fill ~12 ~5 ~24 ~12 ~6 ~24 stone 0 
setblock ~13 ~5 ~24 stonebrick 3  
fill ~14 ~5 ~6 ~28 ~5 ~6 stone 0  
fill ~14 ~5 ~7 ~28 ~5 ~7 stone 0  
fill ~14 ~5 ~8 ~28 ~5 ~8 stone 0  
fill ~14 ~5 ~9 ~29 ~5 ~9 stone 0  
fill ~14 ~5 ~15 ~33 ~5 ~15 stone 0  
fill ~14 ~5 ~16 ~33 ~5 ~16 stone 0  
fill ~14 ~5 ~17 ~33 ~5 ~17 stone 0  
fill ~14 ~5 ~18 ~33 ~5 ~18 stone 0  
fill ~14 ~5 ~19 ~33 ~5 ~19 stone 0  
fill ~14 ~5 ~20 ~33 ~5 ~20 stone 0  
fill ~14 ~5 ~21 ~33 ~5 ~21 stone 0  
fill ~14 ~5 ~22 ~33 ~5 ~22 stone 0  
fill ~14 ~5 ~23 ~33 ~5 ~23 stone 0  
fill ~14 ~5 ~24 ~33 ~5 ~24 stone 0  
fill ~14 ~5 ~25 ~33 ~5 ~25 stone 0  
fill ~14 ~5 ~26 ~30 ~5 ~26 stone 0  
fill ~14 ~5 ~27 ~36 ~5 ~27 stone 0  
fill ~14 ~5 ~28 ~17 ~5 ~28 stone 0  
fill ~14 ~5 ~47 ~14 ~6 ~47 stone 0  
fill ~14 ~5 ~48 ~28 ~5 ~48 stonebrick 3  
fill ~15 ~5 ~47 ~17 ~5 ~47 stonebrick 3  
fill ~18 ~5 ~28 ~27 ~5 ~28 stonebrick 3  
fill ~18 ~5 ~45 ~18 ~6 ~45 stone 0  
fill ~18 ~5 ~46 ~36 ~5 ~46 stone 0  
fill ~18 ~5 ~47 ~36 ~5 ~47 stone 0  
fill ~19 ~5 ~13 ~33 ~5 ~13 stone 0  
fill ~19 ~5 ~14 ~33 ~5 ~14 stone 0  
fill ~19 ~5 ~45 ~26 ~5 ~45 stonebrick 3  
fill ~27 ~5 ~45 ~36 ~5 ~45 stone 0  
fill ~28 ~5 ~28 ~33 ~5 ~28 stone 0  
fill ~28 ~5 ~61 ~33 ~5 ~61 stone 0  
fill ~28 ~5 ~62 ~33 ~5 ~62 stone 0  
fill ~28 ~5 ~63 ~33 ~5 ~63 stone 0  
fill ~28 ~5 ~64 ~32 ~5 ~64 stone 0  
fill ~28 ~5 ~65 ~31 ~5 ~65 stone 0  
fill ~29 ~5 ~6 ~34 ~5 ~6 stonebrick 3  
fill ~29 ~5 ~7 ~34 ~5 ~7 stonebrick 3  
fill ~29 ~5 ~8 ~34 ~5 ~8 stonebrick 3  
fill ~29 ~5 ~29 ~32 ~5 ~29 stone 0  
fill ~29 ~5 ~43 ~32 ~5 ~43 stone 0  
fill ~29 ~5 ~44 ~33 ~5 ~44 stone 0  
fill ~29 ~5 ~48 ~36 ~5 ~48 stone 0  
fill ~29 ~5 ~49 ~35 ~5 ~49 stone 0  
fill ~29 ~5 ~50 ~34 ~5 ~50 stone 0  
fill ~29 ~5 ~51 ~31 ~5 ~51 stone 0  
fill ~29 ~5 ~52 ~33 ~5 ~52 stone 0  
fill ~29 ~5 ~53 ~33 ~5 ~53 stone 0  
fill ~29 ~5 ~54 ~33 ~5 ~54 stone 0  
fill ~29 ~5 ~55 ~33 ~5 ~55 stone 0  
fill ~29 ~5 ~56 ~33 ~5 ~56 stone 0  
fill ~29 ~5 ~57 ~33 ~5 ~57 stone 0  
fill ~29 ~5 ~58 ~33 ~5 ~58 stone 0  
fill ~29 ~5 ~59 ~33 ~5 ~59 stone 0  
fill ~29 ~5 ~60 ~33 ~5 ~60 stone 0  
fill ~29 ~5 ~66 ~33 ~5 ~66 stone 0  
fill ~29 ~5 ~67 ~32 ~5 ~67 stone 0  
fill ~30 ~5 ~9 ~34 ~5 ~9 stonebrick 3  
fill ~30 ~5 ~30 ~32 ~5 ~30 stone 0  
fill ~30 ~5 ~31 ~32 ~5 ~31 stone 0  
fill ~30 ~5 ~32 ~32 ~5 ~32 stone 0  
fill ~30 ~5 ~33 ~32 ~5 ~33 stone 0  
fill ~30 ~5 ~34 ~32 ~5 ~34 stone 0  
fill ~30 ~5 ~35 ~32 ~5 ~35 stone 0  
fill ~30 ~5 ~36 ~32 ~5 ~36 stone 0  
fill ~30 ~5 ~37 ~32 ~5 ~37 stone 0  
fill ~30 ~5 ~38 ~32 ~5 ~38 stone 0  
fill ~30 ~5 ~39 ~32 ~5 ~39 stone 0  
fill ~30 ~5 ~40 ~32 ~5 ~40 stone 0  
fill ~30 ~5 ~41 ~30 ~6 ~41 stone 0  
fill ~30 ~5 ~42 ~32 ~5 ~42 stone 0 
setblock ~31 ~5 ~26 stonebrick 3  
fill ~31 ~5 ~41 ~31 ~7 ~41 stonebrick 3  
fill ~32 ~5 ~26 ~34 ~5 ~26 stone 0  
fill ~32 ~5 ~41 ~32 ~6 ~41 stone 0  
fill ~32 ~5 ~51 ~32 ~7 ~51 stonebrick 3 
setblock ~32 ~5 ~65 redstone_torch 3  
fill ~33 ~5 ~10 ~34 ~5 ~10 stonebrick 3  
fill ~33 ~5 ~11 ~34 ~5 ~11 stonebrick 3  
fill ~33 ~5 ~12 ~34 ~5 ~12 stonebrick 3  
fill ~33 ~5 ~51 ~33 ~6 ~51 stone 0 
setblock ~33 ~5 ~64 redstone_torch 1 
setblock ~33 ~5 ~65 stone 0  
fill ~33 ~5 ~67 ~34 ~5 ~67 stonebrick 3  
fill ~34 ~5 ~13 ~34 ~6 ~13 stonebrick 3  
fill ~34 ~5 ~14 ~34 ~6 ~14 stonebrick 3  
fill ~34 ~5 ~15 ~34 ~6 ~15 stonebrick 3  
fill ~34 ~5 ~16 ~34 ~6 ~16 stonebrick 3  
fill ~34 ~5 ~17 ~34 ~6 ~17 stonebrick 3  
fill ~34 ~5 ~18 ~34 ~6 ~18 stonebrick 3  
fill ~34 ~5 ~19 ~34 ~6 ~19 stonebrick 3  
fill ~34 ~5 ~21 ~34 ~7 ~21 stonebrick 3  
fill ~34 ~5 ~51 ~34 ~6 ~51 stonebrick 3  
fill ~34 ~5 ~52 ~34 ~6 ~52 stonebrick 3  
fill ~34 ~5 ~53 ~34 ~6 ~53 stonebrick 3  
fill ~34 ~5 ~54 ~34 ~6 ~54 stonebrick 3  
fill ~34 ~5 ~55 ~34 ~6 ~55 stonebrick 3  
fill ~34 ~5 ~56 ~34 ~6 ~56 stonebrick 3  
fill ~34 ~5 ~57 ~34 ~6 ~57 stonebrick 3  
fill ~34 ~5 ~58 ~34 ~6 ~58 stonebrick 3  
fill ~34 ~5 ~59 ~34 ~6 ~59 stonebrick 3  
fill ~34 ~5 ~60 ~34 ~6 ~60 stonebrick 3  
fill ~34 ~5 ~61 ~34 ~6 ~61 stonebrick 3  
fill ~34 ~5 ~62 ~34 ~6 ~62 stonebrick 3  
fill ~34 ~5 ~63 ~34 ~6 ~63 stonebrick 3  
fill ~34 ~5 ~64 ~34 ~6 ~64 stonebrick 3  
fill ~34 ~5 ~65 ~34 ~6 ~65 stonebrick 3  
fill ~34 ~5 ~66 ~34 ~6 ~66 stonebrick 3  
fill ~35 ~5 ~3 ~36 ~5 ~3 stonebrick 3  
fill ~35 ~5 ~26 ~57 ~5 ~26 stonebrick 3  
fill ~36 ~5 ~4 ~36 ~5 ~21 stonebrick 3  
fill ~36 ~5 ~51 ~62 ~5 ~51 stonebrick 3  
fill ~36 ~5 ~52 ~36 ~5 ~70 stonebrick 3  
fill ~37 ~5 ~21 ~62 ~5 ~21 stonebrick 3  
fill ~37 ~5 ~27 ~37 ~7 ~27 stonebrick 3  
fill ~37 ~5 ~30 ~37 ~7 ~30 stonebrick 3  
fill ~37 ~5 ~33 ~37 ~7 ~33 stonebrick 3  
fill ~37 ~5 ~36 ~37 ~7 ~36 stonebrick 3  
fill ~37 ~5 ~39 ~37 ~7 ~39 stonebrick 3  
fill ~37 ~5 ~42 ~37 ~7 ~42 stonebrick 3  
fill ~37 ~5 ~45 ~37 ~7 ~45 stonebrick 3  
fill ~37 ~5 ~46 ~57 ~5 ~46 stonebrick 3  
fill ~37 ~5 ~48 ~37 ~7 ~48 stonebrick 3  
fill ~38 ~5 ~28 ~40 ~5 ~28 obsidian 0  
fill ~38 ~5 ~29 ~40 ~5 ~29 obsidian 0  
fill ~38 ~5 ~30 ~38 ~5 ~44 obsidian 0  
fill ~39 ~5 ~27 ~55 ~5 ~27 obsidian 0 
setblock ~39 ~5 ~30 redstone_torch 4  
fill ~39 ~5 ~32 ~39 ~6 ~32 obsidian 0  
fill ~39 ~5 ~33 ~39 ~6 ~33 obsidian 0  
fill ~39 ~5 ~36 ~39 ~6 ~36 obsidian 0  
fill ~39 ~5 ~39 ~39 ~6 ~39 obsidian 0  
fill ~39 ~5 ~40 ~39 ~6 ~40 obsidian 0 
setblock ~39 ~5 ~42 redstone_torch 3  
fill ~39 ~5 ~43 ~39 ~5 ~45 obsidian 0 
setblock ~40 ~5 ~30 lit_redstone_lamp 0  
fill ~40 ~5 ~31 ~40 ~6 ~31 obsidian 0  
fill ~40 ~5 ~41 ~40 ~6 ~41 obsidian 0 
setblock ~40 ~5 ~42 lit_redstone_lamp 0  
fill ~40 ~5 ~44 ~40 ~5 ~45 obsidian 0 
setblock ~41 ~5 ~28 redstone_torch 2 
setblock ~41 ~5 ~29 lit_redstone_lamp 0  
fill ~41 ~5 ~30 ~41 ~6 ~30 obsidian 0  
fill ~41 ~5 ~42 ~41 ~6 ~42 obsidian 0 
setblock ~41 ~5 ~43 lit_redstone_lamp 0 
setblock ~41 ~5 ~44 redstone_torch 2  
fill ~41 ~5 ~45 ~55 ~5 ~45 obsidian 0  
fill ~42 ~5 ~28 ~52 ~5 ~28 obsidian 0  
fill ~42 ~5 ~29 ~42 ~6 ~29 obsidian 0  
fill ~42 ~5 ~43 ~42 ~6 ~43 obsidian 0  
fill ~42 ~5 ~44 ~52 ~5 ~44 obsidian 0  
fill ~52 ~5 ~29 ~52 ~6 ~29 obsidian 0  
fill ~52 ~5 ~43 ~52 ~6 ~43 obsidian 0 
setblock ~53 ~5 ~28 redstone_torch 1 
setblock ~53 ~5 ~29 lit_redstone_lamp 0  
fill ~53 ~5 ~30 ~53 ~6 ~30 obsidian 0  
fill ~53 ~5 ~42 ~53 ~6 ~42 obsidian 0 
setblock ~53 ~5 ~43 lit_redstone_lamp 0 
setblock ~53 ~5 ~44 redstone_torch 1  
fill ~54 ~5 ~28 ~56 ~5 ~28 obsidian 0 
setblock ~54 ~5 ~30 lit_redstone_lamp 0  
fill ~54 ~5 ~31 ~54 ~6 ~31 obsidian 0  
fill ~54 ~5 ~41 ~54 ~6 ~41 obsidian 0 
setblock ~54 ~5 ~42 lit_redstone_lamp 0  
fill ~54 ~5 ~44 ~56 ~5 ~44 obsidian 0  
fill ~55 ~5 ~29 ~56 ~5 ~29 obsidian 0 
setblock ~55 ~5 ~30 redstone_torch 4  
fill ~55 ~5 ~32 ~56 ~5 ~32 obsidian 0  
fill ~55 ~5 ~33 ~56 ~5 ~33 obsidian 0  
fill ~55 ~5 ~36 ~56 ~5 ~36 obsidian 0  
fill ~55 ~5 ~39 ~56 ~5 ~39 obsidian 0  
fill ~55 ~5 ~40 ~56 ~5 ~40 obsidian 0 
setblock ~55 ~5 ~42 redstone_torch 3  
fill ~55 ~5 ~43 ~56 ~5 ~43 obsidian 0  
fill ~56 ~5 ~30 ~56 ~5 ~44 obsidian 0  
fill ~57 ~5 ~27 ~57 ~7 ~27 stonebrick 3  
fill ~57 ~5 ~30 ~57 ~7 ~30 stonebrick 3  
fill ~57 ~5 ~33 ~57 ~7 ~33 stonebrick 3  
fill ~57 ~5 ~36 ~57 ~7 ~36 stonebrick 3  
fill ~57 ~5 ~39 ~57 ~7 ~39 stonebrick 3  
fill ~57 ~5 ~42 ~57 ~7 ~42 stonebrick 3  
fill ~57 ~5 ~45 ~57 ~7 ~45 stonebrick 3  
fill ~61 ~5 ~22 ~62 ~5 ~22 stonebrick 3  
fill ~61 ~5 ~50 ~62 ~5 ~50 stonebrick 3  
fill ~62 ~5 ~25 ~62 ~5 ~51 stonebrick 3 
setblock ~63 ~5 ~22 glowstone 0 
setblock ~63 ~5 ~28 glowstone 0 
setblock ~63 ~5 ~36 glowstone 0 
setblock ~63 ~5 ~44 glowstone 0 
setblock ~63 ~5 ~51 glowstone 0  
fill ~6 ~6 ~2 ~36 ~6 ~2 nether_brick_fence 0  
fill ~6 ~6 ~3 ~6 ~6 ~70 nether_brick_fence 0 
setblock ~7 ~6 ~3 stonebrick 3  
fill ~7 ~6 ~5 ~7 ~6 ~68 redstone_torch 2  
fill ~7 ~6 ~70 ~36 ~6 ~70 nether_brick_fence 0  
fill ~8 ~6 ~3 ~34 ~6 ~3 redstone_torch 4  
fill ~8 ~6 ~4 ~34 ~6 ~4 stonebrick 3  
fill ~8 ~6 ~5 ~9 ~6 ~5 stonebrick 3  
fill ~8 ~6 ~6 ~8 ~5 ~6 stonebrick 3  
fill ~8 ~6 ~7 ~8 ~5 ~7 stonebrick 3  
fill ~8 ~6 ~8 ~8 ~5 ~8 stonebrick 3  
fill ~8 ~6 ~9 ~9 ~6 ~9 stonebrick 3  
fill ~8 ~6 ~10 ~8 ~5 ~10 stonebrick 3  
fill ~8 ~6 ~11 ~10 ~6 ~11 stonebrick 3  
fill ~8 ~6 ~12 ~10 ~6 ~12 stonebrick 3  
fill ~8 ~6 ~13 ~18 ~6 ~13 stonebrick 3  
fill ~8 ~6 ~14 ~18 ~6 ~14 stonebrick 3  
fill ~8 ~6 ~26 ~8 ~7 ~26 stonebrick 3  
fill ~8 ~6 ~46 ~8 ~7 ~46 stonebrick 3  
fill ~8 ~6 ~67 ~9 ~6 ~67 stonebrick 3  
fill ~8 ~6 ~68 ~34 ~6 ~68 stonebrick 3  
fill ~8 ~6 ~69 ~34 ~6 ~69 redstone_torch 3  
fill ~9 ~6 ~6 ~9 ~6 ~8 lit_redstone_lamp 0 
setblock ~9 ~6 ~10 redstone_torch 3 
setblock ~9 ~6 ~21 redstone_torch 1 
setblock ~9 ~6 ~23 redstone_torch 2  
fill ~9 ~6 ~24 ~14 ~6 ~24 stone 0  
fill ~9 ~6 ~25 ~10 ~6 ~25 stone 0  
fill ~9 ~6 ~26 ~9 ~6 ~28 stone 0 
setblock ~9 ~6 ~29 redstone_torch 3 
setblock ~9 ~6 ~43 redstone_torch 4  
fill ~9 ~6 ~44 ~10 ~6 ~44 stone 0  
fill ~9 ~6 ~45 ~9 ~6 ~46 stone 0 
setblock ~9 ~6 ~47 redstone_torch 3  
fill ~9 ~6 ~48 ~11 ~6 ~48 redstone_torch 5  
fill ~9 ~6 ~64 ~9 ~6 ~66 lit_redstone_lamp 0  
fill ~10 ~6 ~5 ~12 ~6 ~5 lit_redstone_lamp 0  
fill ~10 ~6 ~6 ~12 ~6 ~6 redstone_torch 5  
fill ~10 ~6 ~7 ~12 ~6 ~7 redstone_torch 5  
fill ~10 ~6 ~8 ~12 ~6 ~8 redstone_torch 5  
fill ~10 ~6 ~9 ~12 ~6 ~9 lit_redstone_lamp 0  
fill ~10 ~6 ~10 ~12 ~6 ~10 stonebrick 3  
fill ~10 ~6 ~15 ~18 ~6 ~15 stonebrick 3  
fill ~10 ~6 ~16 ~18 ~6 ~16 stonebrick 3  
fill ~10 ~6 ~17 ~18 ~6 ~17 stonebrick 3  
fill ~10 ~6 ~18 ~13 ~6 ~18 stonebrick 3  
fill ~10 ~6 ~19 ~13 ~6 ~19 stonebrick 3  
fill ~10 ~6 ~20 ~13 ~6 ~20 stonebrick 3  
fill ~10 ~6 ~21 ~13 ~6 ~21 stonebrick 3  
fill ~10 ~6 ~22 ~13 ~6 ~22 redstone_torch 4  
fill ~10 ~6 ~23 ~13 ~6 ~23 stone 0  
fill ~10 ~6 ~26 ~10 ~6 ~27 lit_redstone_lamp 0  
fill ~10 ~6 ~28 ~10 ~6 ~29 stone 0 
setblock ~10 ~6 ~30 redstone_torch 3  
fill ~10 ~6 ~31 ~10 ~3 ~31 stonebrick 3  
fill ~10 ~6 ~32 ~29 ~6 ~32 stonebrick 3  
fill ~10 ~6 ~33 ~20 ~6 ~33 stonebrick 3  
fill ~10 ~6 ~34 ~20 ~6 ~34 stonebrick 3  
fill ~10 ~6 ~35 ~19 ~6 ~35 stonebrick 3  
fill ~10 ~6 ~36 ~17 ~6 ~36 stonebrick 3  
fill ~10 ~6 ~37 ~19 ~6 ~37 stonebrick 3  
fill ~10 ~6 ~38 ~20 ~6 ~38 stonebrick 3  
fill ~10 ~6 ~39 ~20 ~6 ~39 stonebrick 3  
fill ~10 ~6 ~40 ~29 ~6 ~40 stonebrick 3  
fill ~10 ~6 ~41 ~28 ~6 ~41 stonebrick 3 
setblock ~10 ~6 ~42 redstone_torch 4  
fill ~10 ~6 ~43 ~13 ~6 ~43 stone 0  
fill ~10 ~6 ~45 ~10 ~6 ~46 lit_redstone_lamp 0 
setblock ~10 ~6 ~47 redstone_torch 5  
fill ~10 ~6 ~49 ~11 ~6 ~49 stonebrick 3  
fill ~10 ~6 ~50 ~29 ~6 ~50 stonebrick 3  
fill ~10 ~6 ~51 ~29 ~6 ~51 stonebrick 3  
fill ~10 ~6 ~52 ~29 ~6 ~52 stonebrick 3  
fill ~10 ~6 ~53 ~29 ~6 ~53 stonebrick 3  
fill ~10 ~6 ~54 ~29 ~6 ~54 stonebrick 3  
fill ~10 ~6 ~55 ~19 ~6 ~55 stonebrick 3  
fill ~10 ~6 ~56 ~20 ~6 ~56 stonebrick 3  
fill ~10 ~6 ~57 ~19 ~6 ~57 stonebrick 3  
fill ~10 ~6 ~58 ~29 ~6 ~58 stonebrick 3  
fill ~10 ~6 ~59 ~29 ~6 ~59 stonebrick 3  
fill ~10 ~6 ~60 ~29 ~6 ~60 stonebrick 3  
fill ~10 ~6 ~61 ~29 ~6 ~61 stonebrick 3  
fill ~10 ~6 ~62 ~29 ~6 ~62 stonebrick 3  
fill ~10 ~6 ~63 ~12 ~6 ~63 lit_redstone_lamp 0  
fill ~10 ~6 ~64 ~12 ~6 ~64 redstone_torch 5  
fill ~10 ~6 ~65 ~12 ~6 ~65 redstone_torch 5  
fill ~10 ~6 ~66 ~12 ~6 ~66 redstone_torch 5 
setblock ~10 ~6 ~67 lit_redstone_lamp 0  
fill ~11 ~6 ~11 ~33 ~6 ~11 stone 0  
fill ~11 ~6 ~12 ~33 ~6 ~12 stone 0  
fill ~11 ~6 ~25 ~12 ~6 ~25 lit_redstone_lamp 0  
fill ~11 ~6 ~26 ~12 ~6 ~26 redstone_torch 5  
fill ~11 ~6 ~27 ~11 ~6 ~26 redstone_torch 5  
fill ~11 ~6 ~28 ~12 ~6 ~28 lit_redstone_lamp 0  
fill ~11 ~6 ~29 ~14 ~6 ~29 stone 0  
fill ~11 ~6 ~30 ~13 ~6 ~30 stone 0  
fill ~11 ~6 ~31 ~13 ~6 ~31 redstone_torch 3  
fill ~11 ~6 ~44 ~12 ~6 ~44 lit_redstone_lamp 0  
fill ~11 ~6 ~45 ~11 ~6 ~46 redstone_torch 5  
fill ~11 ~6 ~47 ~12 ~6 ~47 lit_redstone_lamp 0  
fill ~12 ~6 ~27 ~13 ~6 ~27 lit_redstone_lamp 0  
fill ~12 ~6 ~42 ~13 ~6 ~42 redstone_torch 4  
fill ~12 ~6 ~45 ~13 ~6 ~45 lit_redstone_lamp 0 
setblock ~12 ~6 ~46 redstone_torch 5 
setblock ~12 ~6 ~48 stone 0  
fill ~12 ~6 ~49 ~13 ~6 ~49 redstone_torch 3 
setblock ~12 ~6 ~67 lit_redstone_lamp 0  
fill ~13 ~6 ~5 ~29 ~6 ~5 stonebrick 3  
fill ~13 ~6 ~6 ~13 ~6 ~8 lit_redstone_lamp 0 
setblock ~13 ~6 ~9 stonebrick 3  
fill ~13 ~6 ~10 ~28 ~6 ~10 stone 0  
fill ~13 ~6 ~25 ~15 ~6 ~25 stone 0 
setblock ~13 ~6 ~26 lit_redstone_lamp 0 
setblock ~13 ~6 ~28 redstone_torch 5 
setblock ~13 ~6 ~44 redstone_torch 5 
setblock ~13 ~6 ~46 lit_redstone_lamp 0  
fill ~13 ~6 ~47 ~13 ~7 ~47 stonebrick 3  
fill ~13 ~6 ~48 ~13 ~6 ~47 stonebrick 3  
fill ~13 ~6 ~63 ~29 ~6 ~63 stonebrick 3  
fill ~13 ~6 ~64 ~13 ~6 ~66 lit_redstone_lamp 0  
fill ~13 ~6 ~67 ~28 ~6 ~67 stonebrick 3  
fill ~14 ~6 ~6 ~14 ~6 ~8 stonebrick 3  
fill ~14 ~6 ~9 ~27 ~6 ~9 stone 0  
fill ~14 ~6 ~18 ~23 ~6 ~18 stone 0  
fill ~14 ~6 ~19 ~22 ~6 ~19 stone 0  
fill ~14 ~6 ~20 ~33 ~6 ~20 stone 0  
fill ~14 ~6 ~21 ~33 ~6 ~21 stone 0  
fill ~14 ~6 ~22 ~29 ~6 ~22 stone 0 
setblock ~14 ~6 ~23 redstone_torch 1  
fill ~14 ~6 ~26 ~15 ~6 ~26 stone 0  
fill ~14 ~6 ~27 ~15 ~6 ~27 stone 0  
fill ~14 ~6 ~28 ~15 ~6 ~28 stone 0 
setblock ~14 ~6 ~30 redstone_torch 3  
fill ~14 ~6 ~31 ~14 ~7 ~31 stonebrick 3 
setblock ~14 ~6 ~42 stonebrick 3 
setblock ~14 ~6 ~43 redstone_torch 4  
fill ~14 ~6 ~44 ~14 ~6 ~47 stone 0 
setblock ~14 ~6 ~48 redstone_torch 3  
fill ~14 ~6 ~49 ~28 ~6 ~49 stonebrick 3  
fill ~14 ~6 ~64 ~28 ~6 ~64 stonebrick 3  
fill ~14 ~6 ~65 ~28 ~6 ~65 stonebrick 3  
fill ~14 ~6 ~66 ~27 ~6 ~66 stonebrick 3  
fill ~15 ~6 ~6 ~27 ~6 ~6 stone 0  
fill ~15 ~6 ~7 ~27 ~6 ~7 stone 0  
fill ~15 ~6 ~8 ~27 ~6 ~8 stone 0  
fill ~15 ~6 ~23 ~27 ~6 ~23 stone 0 
setblock ~15 ~6 ~24 redstone_torch 1 
setblock ~15 ~6 ~29 redstone_torch 3 
setblock ~15 ~6 ~44 redstone_torch 1  
fill ~15 ~6 ~45 ~28 ~6 ~45 stone 0  
fill ~15 ~6 ~46 ~28 ~6 ~46 stone 0 
setblock ~15 ~6 ~47 redstone_torch 3 
setblock ~16 ~6 ~24 stone 0  
fill ~16 ~6 ~25 ~16 ~6 ~28 redstone_torch 1  
fill ~16 ~6 ~47 ~25 ~6 ~47 stone 0 
setblock ~16 ~6 ~48 redstone_torch 3  
fill ~17 ~6 ~25 ~26 ~6 ~25 stone 0  
fill ~17 ~6 ~26 ~28 ~6 ~26 stone 0  
fill ~17 ~6 ~27 ~28 ~6 ~27 stone 0  
fill ~17 ~6 ~29 ~27 ~6 ~29 stonebrick 3  
fill ~17 ~6 ~30 ~28 ~6 ~30 stonebrick 3  
fill ~17 ~6 ~31 ~29 ~6 ~31 stonebrick 3  
fill ~17 ~6 ~42 ~28 ~6 ~42 stonebrick 3  
fill ~17 ~6 ~43 ~28 ~6 ~43 stonebrick 3  
fill ~17 ~6 ~48 ~26 ~6 ~48 stonebrick 3  
fill ~18 ~6 ~28 ~26 ~6 ~28 stonebrick 3  
fill ~18 ~6 ~36 ~18 ~7 ~36 end_stone 0  
fill ~18 ~6 ~44 ~25 ~6 ~44 stonebrick 3  
fill ~19 ~6 ~13 ~23 ~6 ~13 stone 0  
fill ~19 ~6 ~14 ~23 ~6 ~14 stone 0  
fill ~19 ~6 ~15 ~19 ~6 ~27 stone 0 
setblock ~19 ~6 ~36 redstone_torch 5 
setblock ~20 ~6 ~15 redstone_torch 5 
setblock ~20 ~6 ~16 stonebrick 3 
setblock ~20 ~6 ~17 redstone_torch 5 
setblock ~20 ~6 ~24 stone 0 
setblock ~20 ~6 ~35 redstone_torch 5 
setblock ~20 ~6 ~36 stonebrick 3 
setblock ~20 ~6 ~37 redstone_torch 5 
setblock ~20 ~6 ~55 redstone_torch 5 
setblock ~20 ~6 ~57 redstone_torch 5 
setblock ~21 ~6 ~15 stone 0 
setblock ~21 ~6 ~16 redstone_torch 5 
setblock ~21 ~6 ~17 stone 0  
fill ~21 ~6 ~33 ~21 ~7 ~33 end_stone 0 
setblock ~21 ~6 ~34 redstone_torch 5 
setblock ~21 ~6 ~35 stonebrick 3 
setblock ~21 ~6 ~36 redstone_torch 5 
setblock ~21 ~6 ~37 stonebrick 3 
setblock ~21 ~6 ~38 redstone_torch 5  
fill ~21 ~6 ~39 ~21 ~7 ~39 end_stone 0 
setblock ~21 ~6 ~55 stonebrick 3 
setblock ~21 ~6 ~56 redstone_torch 5 
setblock ~21 ~6 ~57 stonebrick 3 
setblock ~22 ~6 ~15 redstone_torch 5  
fill ~22 ~6 ~16 ~23 ~6 ~16 stone 0 
setblock ~22 ~6 ~17 redstone_torch 5  
fill ~22 ~6 ~24 ~27 ~6 ~24 stone 0  
fill ~22 ~6 ~33 ~29 ~6 ~33 stonebrick 3  
fill ~22 ~6 ~34 ~29 ~6 ~34 stonebrick 3 
setblock ~22 ~6 ~35 redstone_torch 5 
setblock ~22 ~6 ~36 stonebrick 3 
setblock ~22 ~6 ~37 redstone_torch 5  
fill ~22 ~6 ~38 ~29 ~6 ~38 stonebrick 3  
fill ~22 ~6 ~39 ~29 ~6 ~39 stonebrick 3 
setblock ~22 ~6 ~55 redstone_torch 5  
fill ~22 ~6 ~56 ~29 ~6 ~56 stonebrick 3 
setblock ~22 ~6 ~57 redstone_torch 5 
setblock ~23 ~6 ~15 stone 0 
setblock ~23 ~6 ~17 stone 0  
fill ~23 ~6 ~19 ~27 ~6 ~19 stonebrick 3  
fill ~23 ~6 ~35 ~29 ~6 ~35 stonebrick 3 
setblock ~23 ~6 ~36 redstone_torch 5  
fill ~23 ~6 ~37 ~29 ~6 ~37 stonebrick 3  
fill ~23 ~6 ~55 ~29 ~6 ~55 stonebrick 3  
fill ~23 ~6 ~57 ~29 ~6 ~57 stonebrick 3  
fill ~24 ~6 ~13 ~27 ~6 ~13 stonebrick 3  
fill ~24 ~6 ~14 ~27 ~6 ~14 stonebrick 3  
fill ~24 ~6 ~15 ~27 ~6 ~15 stonebrick 3  
fill ~24 ~6 ~16 ~27 ~6 ~16 stonebrick 3  
fill ~24 ~6 ~17 ~27 ~6 ~17 stonebrick 3  
fill ~24 ~6 ~18 ~27 ~6 ~18 stonebrick 3  
fill ~24 ~6 ~36 ~24 ~7 ~36 end_stone 0  
fill ~25 ~6 ~36 ~29 ~6 ~36 stonebrick 3  
fill ~26 ~6 ~44 ~28 ~6 ~44 redstone_torch 4 
setblock ~26 ~6 ~47 redstone_torch 3 
setblock ~27 ~6 ~25 redstone_torch 4 
setblock ~27 ~6 ~28 redstone_torch 3  
fill ~27 ~6 ~47 ~29 ~6 ~47 stone 0  
fill ~27 ~6 ~48 ~28 ~6 ~48 redstone_torch 3  
fill ~28 ~6 ~6 ~28 ~6 ~9 stonebrick 3  
fill ~28 ~6 ~13 ~33 ~6 ~13 stone 0  
fill ~28 ~6 ~14 ~33 ~6 ~14 stone 0  
fill ~28 ~6 ~15 ~33 ~6 ~15 stone 0  
fill ~28 ~6 ~16 ~33 ~6 ~16 stone 0  
fill ~28 ~6 ~17 ~33 ~6 ~17 stone 0  
fill ~28 ~6 ~18 ~33 ~6 ~18 stone 0  
fill ~28 ~6 ~19 ~33 ~6 ~19 stone 0  
fill ~28 ~6 ~23 ~28 ~6 ~25 redstone_torch 2  
fill ~28 ~6 ~28 ~28 ~2 ~28 stone 0 
setblock ~28 ~6 ~29 redstone_torch 3 
setblock ~28 ~6 ~66 stone 0  
fill ~29 ~6 ~6 ~29 ~6 ~8 lit_redstone_lamp 0  
fill ~29 ~6 ~9 ~29 ~6 ~10 stonebrick 3  
fill ~29 ~6 ~23 ~31 ~6 ~23 stone 0  
fill ~29 ~6 ~24 ~32 ~6 ~24 stone 0  
fill ~29 ~6 ~25 ~29 ~6 ~11 stone 0  
fill ~29 ~6 ~26 ~29 ~6 ~27 lit_redstone_lamp 0 
setblock ~29 ~6 ~28 redstone_torch 5  
fill ~29 ~6 ~29 ~32 ~6 ~29 stone 0 
setblock ~29 ~6 ~30 redstone_torch 3  
fill ~29 ~6 ~41 ~29 ~6 ~43 redstone_torch 2 
setblock ~29 ~6 ~44 redstone_torch 5  
fill ~29 ~6 ~45 ~30 ~6 ~45 lit_redstone_lamp 0  
fill ~29 ~6 ~46 ~29 ~6 ~45 lit_redstone_lamp 0  
fill ~29 ~6 ~48 ~32 ~6 ~48 stone 0  
fill ~29 ~6 ~49 ~30 ~6 ~49 redstone_torch 3  
fill ~29 ~6 ~64 ~29 ~6 ~66 lit_redstone_lamp 0  
fill ~29 ~6 ~67 ~29 ~5 ~67 stone 0  
fill ~30 ~6 ~5 ~32 ~6 ~5 lit_redstone_lamp 0  
fill ~30 ~6 ~6 ~32 ~6 ~6 redstone_torch 5  
fill ~30 ~6 ~7 ~32 ~6 ~7 redstone_torch 5 
fill ~30 ~6 ~8 ~32 ~6 ~8 redstone_torch 5  
fill ~30 ~6 ~9 ~32 ~6 ~9 lit_redstone_lamp 0  
fill ~30 ~6 ~10 ~34 ~6 ~10 stonebrick 3  
fill ~30 ~6 ~22 ~30 ~7 ~22 stonebrick 3  
fill ~30 ~6 ~25 ~31 ~6 ~25 lit_redstone_lamp 0  
fill ~30 ~6 ~26 ~31 ~6 ~26 redstone_torch 5  
fill ~30 ~6 ~27 ~30 ~6 ~28 lit_redstone_lamp 0  
fill ~30 ~6 ~30 ~32 ~6 ~30 stone 0  
fill ~30 ~6 ~31 ~30 ~0 ~31 stone 0  
fill ~30 ~6 ~32 ~32 ~6 ~32 stone 0  
fill ~30 ~6 ~33 ~32 ~6 ~33 stone 0  
fill ~30 ~6 ~34 ~32 ~6 ~34 stone 0  
fill ~30 ~6 ~35 ~32 ~6 ~35 stone 0  
fill ~30 ~6 ~36 ~32 ~6 ~36 stone 0  
fill ~30 ~6 ~37 ~32 ~6 ~37 stone 0  
fill ~30 ~6 ~38 ~32 ~6 ~38 stone 0  
fill ~30 ~6 ~39 ~32 ~6 ~39 stone 0  
fill ~30 ~6 ~40 ~32 ~6 ~40 stone 0  
fill ~30 ~6 ~42 ~32 ~6 ~42 stone 0  
fill ~30 ~6 ~43 ~32 ~6 ~43 stone 0  
fill ~30 ~6 ~44 ~31 ~6 ~44 lit_redstone_lamp 0  
fill ~30 ~6 ~46 ~31 ~6 ~46 redstone_torch 5  
fill ~30 ~6 ~47 ~31 ~6 ~47 lit_redstone_lamp 0  
fill ~30 ~6 ~50 ~30 ~6 ~62 stone 0  
fill ~30 ~6 ~63 ~32 ~6 ~63 lit_redstone_lamp 0  
fill ~30 ~6 ~64 ~32 ~6 ~64 redstone_torch 5  
fill ~30 ~6 ~65 ~31 ~6 ~65 redstone_torch 5  
fill ~30 ~6 ~66 ~32 ~6 ~66 redstone_torch 5 
setblock ~30 ~6 ~67 lit_redstone_lamp 0  
fill ~31 ~6 ~22 ~33 ~6 ~22 stone 0 
setblock ~31 ~6 ~27 redstone_torch 5 
setblock ~31 ~6 ~28 lit_redstone_lamp 0  
fill ~31 ~6 ~31 ~31 ~7 ~31 stonebrick 3 
setblock ~31 ~6 ~45 redstone_torch 5  
fill ~31 ~6 ~49 ~31 ~7 ~49 stonebrick 3  
fill ~31 ~6 ~50 ~31 ~7 ~50 stonebrick 3  
fill ~31 ~6 ~51 ~31 ~6 ~62 stone 0  
fill ~31 ~6 ~67 ~31 ~7 ~67 stonebrick 3 
setblock ~32 ~6 ~23 redstone_torch 5  
fill ~32 ~6 ~25 ~33 ~6 ~25 stone 0  
fill ~32 ~6 ~26 ~32 ~6 ~27 lit_redstone_lamp 0  
fill ~32 ~6 ~28 ~33 ~6 ~28 stone 0 
setblock ~32 ~6 ~31 stone 0  
fill ~32 ~6 ~44 ~33 ~6 ~44 stone 0  
fill ~32 ~6 ~45 ~32 ~6 ~46 lit_redstone_lamp 0  
fill ~32 ~6 ~47 ~33 ~6 ~47 stone 0 
setblock ~32 ~6 ~49 redstone_torch 3  
fill ~32 ~6 ~50 ~34 ~6 ~50 stone 0  
fill ~32 ~6 ~52 ~33 ~6 ~52 stone 0  
fill ~32 ~6 ~53 ~33 ~6 ~53 stone 0  
fill ~32 ~6 ~54 ~33 ~6 ~54 stone 0  
fill ~32 ~6 ~55 ~33 ~6 ~55 stone 0  
fill ~32 ~6 ~56 ~33 ~6 ~56 stone 0  
fill ~32 ~6 ~57 ~33 ~6 ~57 stone 0  
fill ~32 ~6 ~58 ~33 ~6 ~58 stone 0  
fill ~32 ~6 ~59 ~33 ~6 ~59 stone 0  
fill ~32 ~6 ~60 ~33 ~6 ~60 stone 0  
fill ~32 ~6 ~61 ~33 ~6 ~61 stone 0  
fill ~32 ~6 ~62 ~33 ~6 ~62 stone 0 
setblock ~32 ~6 ~67 lit_redstone_lamp 0  
fill ~33 ~6 ~5 ~34 ~6 ~5 stonebrick 3  
fill ~33 ~6 ~6 ~33 ~6 ~8 lit_redstone_lamp 0  
fill ~33 ~6 ~9 ~34 ~6 ~9 stonebrick 3 
setblock ~33 ~6 ~23 stone 0 
setblock ~33 ~6 ~24 redstone_torch 5  
fill ~33 ~6 ~26 ~36 ~6 ~26 stone 0  
fill ~33 ~6 ~27 ~36 ~6 ~27 stone 0 
setblock ~33 ~6 ~29 redstone_torch 3 
setblock ~33 ~6 ~30 redstone_torch 1 
setblock ~33 ~6 ~42 redstone_torch 1 
setblock ~33 ~6 ~43 redstone_torch 4  
fill ~33 ~6 ~45 ~35 ~6 ~45 stone 0  
fill ~33 ~6 ~46 ~35 ~6 ~46 stone 0 
setblock ~33 ~6 ~48 redstone_torch 1  
fill ~33 ~6 ~49 ~34 ~6 ~49 stone 0 
setblock ~33 ~6 ~63 stone 0  
fill ~33 ~6 ~64 ~33 ~6 ~66 lit_redstone_lamp 0 
setblock ~33 ~6 ~67 stone 0  
fill ~34 ~6 ~6 ~34 ~6 ~24 stonebrick 3 
setblock ~34 ~6 ~25 redstone_torch 3 
setblock ~34 ~6 ~28 redstone_torch 3 
setblock ~34 ~6 ~44 redstone_torch 4 
setblock ~34 ~6 ~47 redstone_torch 1  
fill ~34 ~6 ~48 ~35 ~6 ~48 stone 0 
setblock ~34 ~6 ~67 stonebrick 3  
fill ~35 ~6 ~3 ~35 ~3 ~3 stonebrick 3  
fill ~35 ~6 ~4 ~35 ~6 ~21 redstone_torch 1 
setblock ~35 ~6 ~47 stone 0  
fill ~35 ~6 ~49 ~35 ~7 ~49 stonebrick 3  
fill ~35 ~6 ~51 ~35 ~6 ~68 redstone_torch 1  
fill ~36 ~6 ~3 ~36 ~6 ~21 nether_brick_fence 0  
fill ~36 ~6 ~25 ~39 ~6 ~25 stonebrick 3  
fill ~36 ~6 ~45 ~36 ~7 ~45 stonebrick 3  
fill ~36 ~6 ~46 ~58 ~6 ~46 stonebrick 3  
fill ~36 ~6 ~47 ~36 ~7 ~47 stonebrick 3  
fill ~36 ~6 ~48 ~36 ~7 ~48 stonebrick 3  
fill ~36 ~6 ~51 ~38 ~6 ~51 nether_brick_fence 0  
fill ~36 ~6 ~52 ~36 ~6 ~70 nether_brick_fence 0  
fill ~37 ~6 ~21 ~38 ~6 ~21 nether_brick_fence 0  
fill ~37 ~6 ~26 ~58 ~6 ~26 stonebrick 3 
setblock ~38 ~6 ~24 redstone_torch 4  
fill ~38 ~6 ~28 ~39 ~6 ~28 stonebrick 3  
fill ~38 ~6 ~29 ~38 ~6 ~31 stonebrick 3  
fill ~38 ~6 ~32 ~38 ~6 ~41 redstone_torch 1  
fill ~38 ~6 ~42 ~38 ~6 ~47 stonebrick 3 
setblock ~38 ~6 ~48 redstone_torch 3  
fill ~39 ~6 ~21 ~39 ~7 ~21 stonebrick 3 
setblock ~39 ~6 ~22 redstone_torch 3  
fill ~39 ~6 ~27 ~42 ~6 ~27 stonebrick 3  
fill ~39 ~6 ~29 ~39 ~6 ~30 redstone_torch 1  
fill ~39 ~6 ~42 ~39 ~6 ~43 redstone_torch 1  
fill ~39 ~6 ~44 ~39 ~6 ~47 stonebrick 3 
setblock ~39 ~6 ~50 redstone_torch 4  
fill ~39 ~6 ~51 ~39 ~7 ~51 stonebrick 3  
fill ~40 ~6 ~21 ~46 ~6 ~21 nether_brick_fence 0  
fill ~40 ~6 ~28 ~41 ~6 ~28 redstone_torch 3 
setblock ~40 ~6 ~30 obsidian 0 
setblock ~40 ~6 ~42 obsidian 0  
