fill ~44 ~-4 ~25 ~45 ~-4 ~25 dropper 0  
fill ~46 ~-4 ~25 ~101 ~-4 ~25 stained_hardened_clay 1  
fill ~102 ~-4 ~25 ~102 ~3 ~25 planks 1 
setblock ~103 ~-4 ~25 stained_hardened_clay 1 
setblock ~105 ~-4 ~25 stained_hardened_clay 1  
fill ~106 ~-4 ~25 ~106 ~2 ~25 planks 1  
fill ~107 ~-4 ~25 ~107 ~-1 ~25 stained_hardened_clay 1  
fill ~108 ~-4 ~25 ~108 ~-1 ~25 double_stone_slab 0 
setblock ~42 ~-3 ~25 dropper 0  
fill ~43 ~-3 ~25 ~101 ~-3 ~25 stained_hardened_clay 1  
fill ~49 ~-3 ~24 ~90 ~-3 ~24 stained_hardened_clay 1  
fill ~49 ~-3 ~26 ~90 ~-3 ~26 stained_hardened_clay 1  
fill ~52 ~-3 ~23 ~87 ~-3 ~23 stained_hardened_clay 1  
fill ~52 ~-3 ~27 ~87 ~-3 ~27 stained_hardened_clay 1  
fill ~58 ~-3 ~22 ~83 ~-3 ~22 stained_hardened_clay 1  
fill ~58 ~-3 ~28 ~83 ~-3 ~28 stained_hardened_clay 1 
setblock ~103 ~-3 ~25 planks 1 
setblock ~104 ~-3 ~25 fence 5 
setblock ~105 ~-3 ~25 planks 1  
fill ~41 ~-2 ~25 ~44 ~-2 ~25 stained_hardened_clay 1  
fill ~45 ~-2 ~24 ~48 ~-2 ~24 stained_hardened_clay 1  
fill ~45 ~-2 ~25 ~47 ~-2 ~25 gravel 0  
fill ~45 ~-2 ~26 ~48 ~-2 ~26 stained_hardened_clay 1  
fill ~47 ~-2 ~23 ~51 ~-2 ~23 stained_hardened_clay 1  
fill ~47 ~-2 ~27 ~51 ~-2 ~27 stained_hardened_clay 1 
setblock ~48 ~-2 ~25 concrete 15  
fill ~49 ~-2 ~22 ~57 ~-2 ~22 stained_hardened_clay 1  
fill ~49 ~-2 ~24 ~90 ~-2 ~24 gravel 0  
fill ~49 ~-2 ~25 ~79 ~-2 ~25 gravel 0  
fill ~49 ~-2 ~26 ~90 ~-2 ~26 gravel 0  
fill ~49 ~-2 ~28 ~57 ~-2 ~28 stained_hardened_clay 1  
fill ~52 ~-2 ~21 ~83 ~-2 ~21 stained_hardened_clay 1  
fill ~52 ~-2 ~23 ~85 ~-2 ~23 gravel 0  
fill ~52 ~-2 ~27 ~85 ~-2 ~27 gravel 0  
fill ~52 ~-2 ~29 ~83 ~-2 ~29 stained_hardened_clay 1  
fill ~58 ~-2 ~20 ~78 ~-2 ~20 stained_hardened_clay 1  
fill ~58 ~-2 ~22 ~81 ~-2 ~22 gravel 0  
fill ~58 ~-2 ~28 ~81 ~-2 ~28 gravel 0  
fill ~58 ~-2 ~30 ~78 ~-2 ~30 stained_hardened_clay 1  
fill ~80 ~-2 ~25 ~80 ~-1 ~25 concrete 4  
fill ~81 ~-2 ~25 ~93 ~-2 ~25 gravel 0  
fill ~82 ~-2 ~22 ~87 ~-2 ~22 stained_hardened_clay 1  
fill ~82 ~-2 ~28 ~87 ~-2 ~28 stained_hardened_clay 1  
fill ~86 ~-2 ~23 ~90 ~-2 ~23 stained_hardened_clay 1  
fill ~86 ~-2 ~27 ~90 ~-2 ~27 stained_hardened_clay 1  
fill ~91 ~-2 ~24 ~93 ~-2 ~24 stained_hardened_clay 1  
fill ~91 ~-2 ~26 ~93 ~-2 ~26 stained_hardened_clay 1  
fill ~94 ~-2 ~25 ~101 ~-2 ~25 stained_hardened_clay 1 
setblock ~103 ~-2 ~25 stained_hardened_clay 1 
setblock ~105 ~-2 ~25 stained_hardened_clay 1  
fill ~40 ~-1 ~25 ~42 ~-1 ~25 stained_hardened_clay 1  
fill ~43 ~-1 ~24 ~44 ~-1 ~24 stained_hardened_clay 1  
fill ~43 ~-1 ~25 ~44 ~-1 ~25 gravel 0  
fill ~43 ~-1 ~26 ~44 ~-1 ~26 stained_hardened_clay 1  
fill ~45 ~-1 ~23 ~46 ~-1 ~23 stained_hardened_clay 1  
fill ~45 ~-1 ~24 ~47 ~-1 ~24 gravel 0  
fill ~45 ~-1 ~25 ~47 ~-1 ~25 planks 5  
fill ~45 ~-1 ~26 ~47 ~-1 ~26 gravel 0  
fill ~45 ~-1 ~27 ~46 ~-1 ~27 stained_hardened_clay 1  
fill ~47 ~-1 ~22 ~48 ~-1 ~22 stained_hardened_clay 1  
fill ~47 ~-1 ~23 ~51 ~-1 ~23 gravel 0  
fill ~47 ~-1 ~27 ~51 ~-1 ~27 gravel 0  
fill ~47 ~-1 ~28 ~48 ~-1 ~28 stained_hardened_clay 1  
fill ~48 ~-1 ~24 ~90 ~-1 ~24 planks 1  
fill ~48 ~-1 ~25 ~48 ~0 ~25 concrete 4  
fill ~48 ~-1 ~26 ~55 ~-1 ~26 planks 1  
fill ~49 ~-1 ~21 ~51 ~-1 ~21 stained_hardened_clay 1  
fill ~49 ~-1 ~22 ~56 ~-1 ~22 gravel 0  
fill ~49 ~-1 ~25 ~79 ~-1 ~25 planks 1  
fill ~49 ~-1 ~28 ~56 ~-1 ~28 gravel 0  
fill ~49 ~-1 ~29 ~51 ~-1 ~29 stained_hardened_clay 1  
fill ~52 ~-1 ~20 ~57 ~-1 ~20 stained_hardened_clay 1  
fill ~52 ~-1 ~21 ~83 ~-1 ~21 gravel 0  
fill ~52 ~-1 ~23 ~85 ~-1 ~23 planks 1  
fill ~52 ~-1 ~27 ~85 ~-1 ~27 planks 1  
fill ~52 ~-1 ~29 ~83 ~-1 ~29 gravel 0  
fill ~52 ~-1 ~30 ~57 ~-1 ~30 stained_hardened_clay 1  
fill ~56 ~-1 ~26 ~56 ~2 ~26 lapis_block 0  
fill ~57 ~-1 ~22 ~81 ~-1 ~22 planks 1  
fill ~57 ~-1 ~26 ~90 ~-1 ~26 planks 1  
fill ~57 ~-1 ~28 ~81 ~-1 ~28 planks 1  
fill ~58 ~-1 ~19 ~78 ~-1 ~19 stained_hardened_clay 1  
fill ~58 ~-1 ~20 ~78 ~-1 ~20 gravel 0  
fill ~58 ~-1 ~30 ~78 ~-1 ~30 gravel 0  
fill ~58 ~-1 ~31 ~78 ~-1 ~31 stained_hardened_clay 1  
fill ~79 ~-1 ~20 ~83 ~-1 ~20 stained_hardened_clay 1  
fill ~79 ~-1 ~30 ~83 ~-1 ~30 stained_hardened_clay 1  
fill ~81 ~-1 ~25 ~93 ~-1 ~25 planks 1  
fill ~82 ~-1 ~22 ~87 ~-1 ~22 gravel 0  
fill ~82 ~-1 ~28 ~87 ~-1 ~28 gravel 0  
fill ~84 ~-1 ~21 ~87 ~-1 ~21 stained_hardened_clay 1  
fill ~84 ~-1 ~29 ~87 ~-1 ~29 stained_hardened_clay 1  
fill ~86 ~-1 ~23 ~90 ~-1 ~23 gravel 0  
fill ~86 ~-1 ~27 ~90 ~-1 ~27 gravel 0  
fill ~88 ~-1 ~22 ~90 ~-1 ~22 stained_hardened_clay 1  
fill ~88 ~-1 ~28 ~90 ~-1 ~28 stained_hardened_clay 1  
fill ~91 ~-1 ~23 ~93 ~-1 ~23 stained_hardened_clay 1  
fill ~91 ~-1 ~24 ~93 ~-1 ~24 gravel 0  
fill ~91 ~-1 ~26 ~93 ~-1 ~26 gravel 0  
fill ~91 ~-1 ~27 ~93 ~-1 ~27 stained_hardened_clay 1  
fill ~94 ~-1 ~24 ~95 ~-1 ~24 stained_hardened_clay 1  
fill ~94 ~-1 ~25 ~95 ~-1 ~25 gravel 0  
fill ~94 ~-1 ~26 ~95 ~-1 ~26 stained_hardened_clay 1  
fill ~96 ~-1 ~25 ~101 ~-1 ~25 stained_hardened_clay 1 
setblock ~103 ~-1 ~25 planks 1 
setblock ~104 ~-1 ~25 fence 5 
setblock ~105 ~-1 ~25 planks 1 
setblock ~39 ~0 ~25 dropper 0  
fill ~40 ~0 ~25 ~42 ~0 ~25 stained_hardened_clay 1  
fill ~43 ~0 ~24 ~43 ~-1 ~24 stained_hardened_clay 1 
setblock ~43 ~0 ~25 planks 1  
fill ~43 ~0 ~26 ~43 ~-1 ~26 stained_hardened_clay 1  
fill ~44 ~0 ~23 ~45 ~0 ~23 stained_hardened_clay 1 
setblock ~44 ~0 ~24 planks 5  
fill ~44 ~0 ~25 ~46 ~0 ~25 dropper 0 
setblock ~44 ~0 ~26 planks 5  
fill ~44 ~0 ~27 ~45 ~0 ~27 stained_hardened_clay 1 
setblock ~45 ~0 ~24 planks 1 
setblock ~45 ~0 ~26 planks 1  
fill ~46 ~0 ~22 ~47 ~0 ~22 stained_hardened_clay 1  
fill ~46 ~0 ~23 ~47 ~0 ~23 planks 1  
fill ~46 ~0 ~24 ~47 ~0 ~24 dropper 0  
fill ~46 ~0 ~26 ~47 ~0 ~26 dropper 0  
fill ~46 ~0 ~27 ~47 ~0 ~27 planks 1  
fill ~46 ~0 ~28 ~47 ~0 ~28 stained_hardened_clay 1  
fill ~47 ~0 ~25 ~47 ~3 ~25 fence 5  
fill ~48 ~0 ~21 ~50 ~0 ~21 stained_hardened_clay 1 
setblock ~48 ~0 ~22 planks 1  
fill ~48 ~0 ~23 ~51 ~0 ~23 dropper 0  
fill ~48 ~0 ~24 ~48 ~3 ~24 fence 5  
fill ~48 ~0 ~26 ~48 ~3 ~26 fence 5  
fill ~48 ~0 ~27 ~51 ~0 ~27 dropper 0 
setblock ~48 ~0 ~28 planks 1  
fill ~48 ~0 ~29 ~50 ~0 ~29 stained_hardened_clay 1 
setblock ~49 ~0 ~22 planks 5  
fill ~49 ~0 ~25 ~49 ~3 ~25 fence 5 
setblock ~49 ~0 ~28 planks 5 
setblock ~50 ~0 ~22 planks 1  
fill ~50 ~0 ~24 ~52 ~0 ~24 lapis_block 0  
fill ~50 ~0 ~25 ~52 ~0 ~25 lapis_block 0  
fill ~50 ~0 ~26 ~52 ~0 ~26 lapis_block 0 
setblock ~50 ~0 ~28 planks 1  
fill ~51 ~0 ~20 ~53 ~0 ~20 stained_hardened_clay 1  
fill ~51 ~0 ~21 ~53 ~0 ~21 planks 1  
fill ~51 ~0 ~22 ~56 ~0 ~22 dropper 0  
fill ~51 ~0 ~28 ~56 ~0 ~28 dropper 0  
fill ~51 ~0 ~29 ~53 ~0 ~29 planks 1  
fill ~51 ~0 ~30 ~53 ~0 ~30 stained_hardened_clay 1  
fill ~54 ~0 ~19 ~57 ~0 ~19 stained_hardened_clay 1 
setblock ~54 ~0 ~20 planks 5  
fill ~54 ~0 ~21 ~56 ~0 ~21 activator_rail 0  
fill ~54 ~0 ~24 ~56 ~0 ~24 lapis_block 0  
fill ~54 ~0 ~25 ~55 ~0 ~25 lapis_block 0  
fill ~54 ~0 ~26 ~56 ~0 ~26 lapis_block 0  
fill ~54 ~0 ~29 ~56 ~0 ~29 activator_rail 0 
setblock ~54 ~0 ~30 planks 5  
fill ~54 ~0 ~31 ~57 ~0 ~31 stained_hardened_clay 1  
fill ~55 ~0 ~20 ~56 ~0 ~20 planks 1  
fill ~55 ~0 ~30 ~56 ~0 ~30 planks 1  
fill ~56 ~0 ~25 ~56 ~3 ~25 fence 1  
fill ~57 ~0 ~20 ~57 ~0 ~22 concrete 15 
setblock ~57 ~0 ~23 iron_door 2  
fill ~57 ~0 ~24 ~57 ~0 ~26 concrete 15 
setblock ~57 ~0 ~27 iron_door 2  
fill ~57 ~0 ~28 ~57 ~0 ~30 concrete 15  
fill ~58 ~0 ~18 ~78 ~0 ~18 stained_hardened_clay 1  
fill ~58 ~0 ~19 ~66 ~0 ~19 planks 1  
fill ~58 ~0 ~20 ~66 ~0 ~20 planks 1  
fill ~58 ~0 ~21 ~79 ~0 ~21 dropper 0  
fill ~58 ~0 ~29 ~79 ~0 ~29 dropper 0  
fill ~58 ~0 ~30 ~66 ~0 ~30 planks 1  
fill ~58 ~0 ~31 ~66 ~0 ~31 planks 1  
fill ~58 ~0 ~32 ~78 ~0 ~32 stained_hardened_clay 1  
fill ~61 ~0 ~22 ~61 ~13 ~22 log 1  
fill ~61 ~0 ~28 ~61 ~13 ~28 log 1  
fill ~62 ~0 ~23 ~62 ~2 ~23 fence 0 
setblock ~62 ~0 ~24 dark_oak_stairs 6  
fill ~62 ~0 ~25 ~63 ~0 ~25 planks 5 
setblock ~62 ~0 ~26 dark_oak_stairs 7  
fill ~62 ~0 ~27 ~62 ~2 ~27 fence 0  
fill ~63 ~0 ~24 ~65 ~0 ~24 stone_brick_stairs 6  
fill ~63 ~0 ~26 ~65 ~0 ~26 stone_brick_stairs 7  
fill ~64 ~0 ~25 ~65 ~0 ~25 planks 1  
fill ~66 ~0 ~23 ~66 ~2 ~23 fence 0 
setblock ~66 ~0 ~24 dark_oak_stairs 6 
setblock ~66 ~0 ~25 planks 5 
setblock ~66 ~0 ~26 dark_oak_stairs 7  
fill ~66 ~0 ~27 ~66 ~2 ~27 fence 0 
setblock ~67 ~0 ~19 planks 5 
setblock ~67 ~0 ~20 activator_rail 0 
setblock ~67 ~0 ~30 activator_rail 0 
setblock ~67 ~0 ~31 planks 5  
fill ~68 ~0 ~19 ~71 ~0 ~19 planks 1  
fill ~68 ~0 ~20 ~71 ~0 ~20 planks 1  
fill ~68 ~0 ~23 ~68 ~2 ~23 fence 0 
setblock ~68 ~0 ~24 dark_oak_stairs 6 
setblock ~68 ~0 ~25 planks 5 
setblock ~68 ~0 ~26 dark_oak_stairs 7  
fill ~68 ~0 ~27 ~68 ~2 ~27 fence 0  
fill ~68 ~0 ~30 ~71 ~0 ~30 planks 1  
fill ~68 ~0 ~31 ~71 ~0 ~31 planks 1  
fill ~69 ~0 ~24 ~71 ~0 ~24 stone_brick_stairs 6  
fill ~69 ~0 ~25 ~71 ~0 ~25 planks 1  
fill ~69 ~0 ~26 ~71 ~0 ~26 stone_brick_stairs 7  
fill ~72 ~0 ~19 ~72 ~1 ~19 planks 5 
setblock ~72 ~0 ~20 dropper 0  
fill ~72 ~0 ~23 ~72 ~2 ~23 fence 0 
setblock ~72 ~0 ~24 dark_oak_stairs 6 
setblock ~72 ~0 ~25 planks 5 
setblock ~72 ~0 ~26 dark_oak_stairs 7  
fill ~72 ~0 ~27 ~72 ~2 ~27 fence 0 
setblock ~72 ~0 ~30 dropper 0  
fill ~72 ~0 ~31 ~72 ~1 ~31 planks 5  
fill ~73 ~0 ~19 ~76 ~0 ~19 planks 1  
fill ~73 ~0 ~20 ~76 ~0 ~20 planks 1  
fill ~73 ~0 ~22 ~73 ~7 ~22 log 1  
fill ~73 ~0 ~28 ~73 ~13 ~28 log 1  
fill ~73 ~0 ~30 ~76 ~0 ~30 planks 1  
fill ~73 ~0 ~31 ~76 ~0 ~31 planks 1  
fill ~74 ~0 ~23 ~74 ~2 ~23 fence 0 
setblock ~74 ~0 ~24 dark_oak_stairs 6  
fill ~74 ~0 ~25 ~75 ~0 ~25 planks 5 
setblock ~74 ~0 ~26 dark_oak_stairs 7  
fill ~74 ~0 ~27 ~74 ~2 ~27 fence 0  
fill ~75 ~0 ~24 ~77 ~0 ~24 stone_brick_stairs 6  
fill ~75 ~0 ~26 ~77 ~0 ~26 stone_brick_stairs 7  
fill ~76 ~0 ~25 ~77 ~0 ~25 planks 1 
setblock ~77 ~0 ~19 planks 5 
setblock ~77 ~0 ~20 dropper 0 
setblock ~77 ~0 ~30 dropper 0 
setblock ~77 ~0 ~31 planks 5  
fill ~78 ~0 ~19 ~78 ~0 ~20 planks 1  
fill ~78 ~0 ~23 ~78 ~2 ~23 fence 0 
setblock ~78 ~0 ~24 dark_oak_stairs 6 
setblock ~78 ~0 ~25 planks 5 
setblock ~78 ~0 ~26 dark_oak_stairs 7  
fill ~78 ~0 ~27 ~78 ~2 ~27 fence 0  
fill ~78 ~0 ~30 ~79 ~0 ~30 planks 1  
fill ~78 ~0 ~31 ~78 ~0 ~30 planks 1  
fill ~79 ~0 ~19 ~83 ~0 ~19 stained_hardened_clay 1 
setblock ~79 ~0 ~20 planks 1  
fill ~79 ~0 ~25 ~79 ~3 ~25 fence 5  
fill ~79 ~0 ~31 ~83 ~0 ~31 stained_hardened_clay 1  
fill ~80 ~0 ~20 ~80 ~0 ~21 concrete 15 
setblock ~80 ~0 ~22 spruce_door 2 
setblock ~80 ~0 ~23 concrete 15  
fill ~80 ~0 ~24 ~80 ~3 ~24 fence 5 
setblock ~80 ~0 ~25 coal_block 0  
fill ~80 ~0 ~26 ~80 ~3 ~26 fence 5 
setblock ~80 ~0 ~27 concrete 15 
setblock ~80 ~0 ~28 spruce_door 2  
fill ~80 ~0 ~29 ~80 ~0 ~30 concrete 15  
fill ~81 ~0 ~20 ~81 ~0 ~21 dropper 0  
fill ~81 ~0 ~25 ~81 ~3 ~25 fence 5  
fill ~81 ~0 ~29 ~84 ~0 ~29 dropper 0  
fill ~81 ~0 ~30 ~81 ~0 ~29 dropper 0  
fill ~82 ~0 ~20 ~83 ~0 ~20 planks 1  
fill ~82 ~0 ~21 ~84 ~0 ~21 dropper 0  
fill ~82 ~0 ~22 ~86 ~0 ~22 dropper 0  
fill ~82 ~0 ~24 ~84 ~0 ~24 carrots 0  
fill ~82 ~0 ~25 ~84 ~0 ~25 carrots 0  
fill ~82 ~0 ~26 ~84 ~0 ~26 carrots 0  
fill ~82 ~0 ~28 ~86 ~0 ~28 dropper 0  
fill ~82 ~0 ~30 ~83 ~0 ~30 planks 1  
fill ~84 ~0 ~20 ~87 ~0 ~20 stained_hardened_clay 1  
fill ~84 ~0 ~30 ~87 ~0 ~30 stained_hardened_clay 1  
fill ~85 ~0 ~21 ~86 ~0 ~21 planks 1  
fill ~85 ~0 ~29 ~86 ~0 ~29 planks 1  
fill ~86 ~0 ~23 ~90 ~0 ~23 dropper 0  
fill ~86 ~0 ~24 ~89 ~0 ~24 carrots 0  
fill ~86 ~0 ~25 ~89 ~0 ~25 carrots 0  
fill ~86 ~0 ~26 ~89 ~0 ~26 carrots 0  
fill ~86 ~0 ~27 ~90 ~0 ~27 dropper 0 
setblock ~87 ~0 ~21 planks 5  
fill ~87 ~0 ~22 ~90 ~0 ~22 planks 1  
fill ~87 ~0 ~28 ~90 ~0 ~28 planks 1 
setblock ~87 ~0 ~29 planks 5  
fill ~88 ~0 ~21 ~90 ~0 ~21 stained_hardened_clay 1  
fill ~88 ~0 ~29 ~90 ~0 ~29 stained_hardened_clay 1  
fill ~91 ~0 ~22 ~93 ~0 ~22 stained_hardened_clay 1 
setblock ~91 ~0 ~23 planks 1 
setblock ~91 ~0 ~24 dropper 0 
setblock ~91 ~0 ~26 dropper 0 
setblock ~91 ~0 ~27 planks 1  
fill ~91 ~0 ~28 ~93 ~0 ~28 stained_hardened_clay 1  
fill ~92 ~0 ~23 ~92 ~0 ~27 planks 5  
fill ~93 ~0 ~23 ~93 ~0 ~27 planks 1  
fill ~94 ~0 ~23 ~95 ~0 ~23 stained_hardened_clay 1  
fill ~94 ~0 ~24 ~95 ~0 ~24 planks 1 
setblock ~94 ~0 ~25 wool 0  
fill ~94 ~0 ~26 ~95 ~0 ~26 planks 1  
fill ~94 ~0 ~27 ~95 ~0 ~27 stained_hardened_clay 1 
setblock ~95 ~0 ~25 dropper 0  
fill ~96 ~0 ~24 ~97 ~0 ~24 stained_hardened_clay 1 
setblock ~96 ~0 ~25 planks 1  
fill ~96 ~0 ~26 ~97 ~0 ~26 stained_hardened_clay 1 
setblock ~97 ~0 ~25 planks 5  
fill ~98 ~0 ~25 ~101 ~0 ~25 stained_hardened_clay 1 
setblock ~103 ~0 ~25 stained_hardened_clay 1 
setblock ~105 ~0 ~25 stained_hardened_clay 1  
fill ~107 ~0 ~25 ~107 ~2 ~25 double_stone_slab 0 
setblock ~108 ~0 ~25 stone_slab 0  
fill ~39 ~1 ~25 ~41 ~1 ~25 stained_hardened_clay 1  
fill ~42 ~1 ~24 ~42 ~3 ~24 stained_hardened_clay 1  
fill ~42 ~1 ~25 ~42 ~2 ~25 chest 5  
fill ~42 ~1 ~26 ~42 ~3 ~26 stained_hardened_clay 1  
fill ~43 ~1 ~23 ~43 ~3 ~23 stained_hardened_clay 1  
fill ~43 ~1 ~24 ~44 ~1 ~24 lapis_block 0  
fill ~43 ~1 ~25 ~44 ~1 ~25 lapis_block 0  
fill ~43 ~1 ~26 ~44 ~1 ~26 lapis_block 0  
fill ~43 ~1 ~27 ~43 ~3 ~27 stained_hardened_clay 1  
fill ~44 ~1 ~22 ~45 ~1 ~22 stained_hardened_clay 1  
fill ~44 ~1 ~23 ~44 ~3 ~23 log 1  
fill ~44 ~1 ~27 ~44 ~3 ~27 log 1  
fill ~44 ~1 ~28 ~45 ~1 ~28 stained_hardened_clay 1  
fill ~45 ~1 ~23 ~45 ~2 ~23 chest 3  
fill ~45 ~1 ~27 ~45 ~2 ~27 chest 2  
fill ~46 ~1 ~21 ~47 ~1 ~21 stained_hardened_clay 1  
fill ~46 ~1 ~22 ~48 ~1 ~22 diamond_block 0  
fill ~46 ~1 ~28 ~48 ~1 ~28 gold_block 0  
fill ~46 ~1 ~29 ~47 ~1 ~29 stained_hardened_clay 1  
fill ~48 ~1 ~20 ~51 ~1 ~20 stained_hardened_clay 1  
fill ~48 ~1 ~21 ~48 ~3 ~21 diamond_block 0 
setblock ~48 ~1 ~25 concrete 15  
fill ~48 ~1 ~29 ~48 ~3 ~29 gold_block 0  
fill ~48 ~1 ~30 ~51 ~1 ~30 stained_hardened_clay 1  
fill ~49 ~1 ~21 ~49 ~3 ~21 log 1  
fill ~49 ~1 ~29 ~49 ~3 ~29 planks 5  
fill ~50 ~1 ~21 ~50 ~3 ~21 diamond_block 0  
fill ~50 ~1 ~24 ~52 ~1 ~24 lapis_block 0  
fill ~50 ~1 ~25 ~52 ~1 ~25 lapis_block 0  
fill ~50 ~1 ~26 ~52 ~1 ~26 lapis_block 0  
fill ~50 ~1 ~29 ~50 ~3 ~29 gold_block 0  
fill ~51 ~1 ~19 ~53 ~1 ~19 stained_hardened_clay 1  
fill ~51 ~1 ~31 ~53 ~1 ~31 stained_hardened_clay 1  
fill ~52 ~1 ~20 ~53 ~1 ~20 diamond_block 0  
fill ~52 ~1 ~21 ~53 ~1 ~21 diamond_block 0  
fill ~52 ~1 ~29 ~53 ~1 ~29 gold_block 0  
fill ~52 ~1 ~30 ~53 ~1 ~30 gold_block 0  
fill ~54 ~1 ~18 ~57 ~1 ~18 stained_hardened_clay 1  
fill ~54 ~1 ~19 ~54 ~3 ~19 log 1  
fill ~54 ~1 ~24 ~56 ~1 ~24 lapis_block 0  
fill ~54 ~1 ~25 ~55 ~1 ~25 lapis_block 0  
fill ~54 ~1 ~26 ~56 ~1 ~26 lapis_block 0  
fill ~54 ~1 ~31 ~54 ~3 ~31 log 1  
fill ~54 ~1 ~32 ~57 ~1 ~32 stained_hardened_clay 1  
fill ~55 ~1 ~19 ~56 ~1 ~19 diamond_block 0  
fill ~55 ~1 ~20 ~56 ~1 ~20 diamond_block 0  
fill ~55 ~1 ~21 ~56 ~1 ~21 diamond_block 0  
fill ~55 ~1 ~29 ~56 ~1 ~29 gold_block 0  
fill ~55 ~1 ~30 ~56 ~1 ~30 gold_block 0  
fill ~55 ~1 ~31 ~56 ~1 ~31 gold_block 0  
fill ~57 ~1 ~19 ~57 ~2 ~19 stained_hardened_clay 1  
fill ~57 ~1 ~20 ~57 ~2 ~20 stained_hardened_clay 1  
fill ~57 ~1 ~21 ~57 ~2 ~21 stained_hardened_clay 1  
fill ~57 ~1 ~22 ~57 ~2 ~22 stained_hardened_clay 1 
setblock ~57 ~1 ~23 iron_door 9  
fill ~57 ~1 ~24 ~57 ~2 ~24 stained_hardened_clay 1  
fill ~57 ~1 ~25 ~57 ~3 ~25 concrete 15  
fill ~57 ~1 ~26 ~57 ~2 ~26 stained_hardened_clay 1 
setblock ~57 ~1 ~27 iron_door 9  
fill ~57 ~1 ~28 ~57 ~2 ~28 stained_hardened_clay 1  
fill ~57 ~1 ~29 ~57 ~2 ~29 stained_hardened_clay 1  
fill ~57 ~1 ~30 ~57 ~2 ~30 stained_hardened_clay 1  
fill ~57 ~1 ~31 ~57 ~2 ~31 stained_hardened_clay 1  
fill ~58 ~1 ~17 ~78 ~1 ~17 stained_hardened_clay 1  
fill ~58 ~1 ~18 ~58 ~3 ~18 log 1  
fill ~58 ~1 ~32 ~58 ~3 ~32 log 1  
fill ~58 ~1 ~33 ~78 ~1 ~33 stained_hardened_clay 1  
fill ~59 ~1 ~18 ~60 ~1 ~18 chest 3  
fill ~59 ~1 ~32 ~60 ~1 ~32 chest 2  
fill ~61 ~1 ~18 ~61 ~3 ~18 log 1  
fill ~61 ~1 ~32 ~61 ~3 ~32 log 1 
setblock ~62 ~1 ~18 dark_oak_stairs 6  
fill ~62 ~1 ~19 ~63 ~1 ~19 planks 5 
setblock ~62 ~1 ~20 dark_oak_stairs 7 
setblock ~62 ~1 ~24 planks 5 
setblock ~62 ~1 ~25 concrete 7 
setblock ~62 ~1 ~26 planks 5 
setblock ~62 ~1 ~30 dark_oak_stairs 6  
fill ~62 ~1 ~31 ~63 ~1 ~31 planks 5 
setblock ~62 ~1 ~32 dark_oak_stairs 7  
fill ~63 ~1 ~18 ~65 ~1 ~18 stone_brick_stairs 6  
fill ~63 ~1 ~20 ~65 ~1 ~20 stone_brick_stairs 7  
fill ~63 ~1 ~24 ~65 ~1 ~24 planks 1  
fill ~63 ~1 ~26 ~65 ~1 ~26 planks 1  
fill ~63 ~1 ~30 ~65 ~1 ~30 stone_brick_stairs 6  
fill ~63 ~1 ~32 ~65 ~1 ~32 stone_brick_stairs 7  
fill ~64 ~1 ~19 ~65 ~1 ~19 planks 1  
fill ~64 ~1 ~31 ~65 ~1 ~31 planks 1 
setblock ~66 ~1 ~18 dark_oak_stairs 6 
setblock ~66 ~1 ~19 planks 5 
setblock ~66 ~1 ~20 dark_oak_stairs 7 
setblock ~66 ~1 ~24 planks 5 
setblock ~66 ~1 ~25 concrete 7 
setblock ~66 ~1 ~26 planks 5 
setblock ~66 ~1 ~30 dark_oak_stairs 6 
setblock ~66 ~1 ~31 planks 5 
setblock ~66 ~1 ~32 dark_oak_stairs 7  
fill ~67 ~1 ~18 ~67 ~3 ~18 log 1  
fill ~67 ~1 ~32 ~67 ~3 ~32 log 1 
setblock ~68 ~1 ~18 dark_oak_stairs 6  
fill ~68 ~1 ~19 ~69 ~1 ~19 planks 5 
setblock ~68 ~1 ~20 dark_oak_stairs 7 
setblock ~68 ~1 ~24 planks 5 
setblock ~68 ~1 ~25 concrete 7 
setblock ~68 ~1 ~26 planks 5 
setblock ~68 ~1 ~30 dark_oak_stairs 6  
fill ~68 ~1 ~31 ~69 ~1 ~31 planks 5 
setblock ~68 ~1 ~32 dark_oak_stairs 7  
fill ~69 ~1 ~18 ~71 ~1 ~18 stone_brick_stairs 6  
fill ~69 ~1 ~20 ~71 ~1 ~20 stone_brick_stairs 7  
fill ~69 ~1 ~24 ~71 ~1 ~24 planks 1  
fill ~69 ~1 ~26 ~71 ~1 ~26 planks 1  
fill ~69 ~1 ~30 ~71 ~1 ~30 stone_brick_stairs 6  
fill ~69 ~1 ~32 ~71 ~1 ~32 stone_brick_stairs 7  
fill ~70 ~1 ~19 ~71 ~1 ~19 planks 1  
fill ~70 ~1 ~31 ~71 ~1 ~31 planks 1 
setblock ~72 ~1 ~18 dark_oak_stairs 6 
setblock ~72 ~1 ~20 dark_oak_stairs 7 
setblock ~72 ~1 ~24 planks 5 
setblock ~72 ~1 ~25 concrete 7 
setblock ~72 ~1 ~26 planks 5 
setblock ~72 ~1 ~30 dark_oak_stairs 6 
setblock ~72 ~1 ~32 dark_oak_stairs 7  
fill ~73 ~1 ~18 ~73 ~3 ~18 log 1  
fill ~73 ~1 ~32 ~73 ~3 ~32 log 1 
setblock ~74 ~1 ~18 dark_oak_stairs 6  
fill ~74 ~1 ~19 ~75 ~1 ~19 planks 5 
setblock ~74 ~1 ~20 dark_oak_stairs 7 
setblock ~74 ~1 ~24 planks 5 
setblock ~74 ~1 ~25 concrete 7 
setblock ~74 ~1 ~26 planks 5 
setblock ~74 ~1 ~30 dark_oak_stairs 6  
fill ~74 ~1 ~31 ~75 ~1 ~31 planks 5 
setblock ~74 ~1 ~32 dark_oak_stairs 7  
fill ~75 ~1 ~18 ~77 ~1 ~18 stone_brick_stairs 6  
fill ~75 ~1 ~20 ~77 ~1 ~20 stone_brick_stairs 7  
fill ~75 ~1 ~24 ~77 ~1 ~24 planks 1  
fill ~75 ~1 ~26 ~77 ~1 ~26 planks 1  
fill ~75 ~1 ~30 ~77 ~1 ~30 stone_brick_stairs 6  
fill ~75 ~1 ~32 ~77 ~1 ~32 stone_brick_stairs 7  
fill ~76 ~1 ~19 ~77 ~1 ~19 planks 1  
fill ~76 ~1 ~31 ~77 ~1 ~31 planks 1 
setblock ~78 ~1 ~18 dark_oak_stairs 6 
setblock ~78 ~1 ~19 planks 5 
setblock ~78 ~1 ~20 dark_oak_stairs 7 
setblock ~78 ~1 ~24 planks 5 
setblock ~78 ~1 ~25 concrete 7 
setblock ~78 ~1 ~26 planks 5 
setblock ~78 ~1 ~30 dark_oak_stairs 6 
setblock ~78 ~1 ~31 planks 5 
setblock ~78 ~1 ~32 dark_oak_stairs 7  
fill ~79 ~1 ~18 ~83 ~1 ~18 stained_hardened_clay 1  
fill ~79 ~1 ~32 ~83 ~1 ~32 stained_hardened_clay 1  
fill ~80 ~1 ~19 ~80 ~2 ~19 stained_hardened_clay 1  
fill ~80 ~1 ~20 ~80 ~2 ~20 stained_hardened_clay 1  
fill ~80 ~1 ~21 ~80 ~2 ~21 stained_hardened_clay 1 
setblock ~80 ~1 ~22 spruce_door 8  
fill ~80 ~1 ~23 ~80 ~2 ~23 stained_hardened_clay 1  
fill ~80 ~1 ~25 ~80 ~2 ~25 concrete 4  
fill ~80 ~1 ~27 ~80 ~2 ~27 stained_hardened_clay 1 
setblock ~80 ~1 ~28 spruce_door 8  
fill ~80 ~1 ~29 ~80 ~2 ~29 stained_hardened_clay 1  
fill ~80 ~1 ~30 ~80 ~2 ~30 stained_hardened_clay 1  
fill ~80 ~1 ~31 ~80 ~2 ~31 stained_hardened_clay 1  
fill ~81 ~1 ~19 ~81 ~2 ~19 chest 3  
fill ~81 ~1 ~31 ~81 ~2 ~31 chest 2  
fill ~82 ~1 ~24 ~84 ~1 ~24 carrots 0  
fill ~82 ~1 ~25 ~84 ~1 ~25 carrots 0  
fill ~82 ~1 ~26 ~84 ~1 ~26 carrots 0  
fill ~83 ~1 ~19 ~87 ~1 ~19 stained_hardened_clay 1  
fill ~83 ~1 ~31 ~87 ~1 ~31 stained_hardened_clay 1  
fill ~85 ~1 ~20 ~86 ~1 ~20 chest 3  
fill ~85 ~1 ~30 ~86 ~1 ~30 chest 2  
fill ~86 ~1 ~24 ~89 ~1 ~24 carrots 0  
fill ~86 ~1 ~25 ~89 ~1 ~25 carrots 0  
fill ~86 ~1 ~26 ~89 ~1 ~26 carrots 0  
fill ~87 ~1 ~20 ~87 ~3 ~20 log 1  
fill ~87 ~1 ~30 ~87 ~3 ~30 log 1  
fill ~88 ~1 ~20 ~90 ~1 ~20 stained_hardened_clay 1 
setblock ~88 ~1 ~21 dark_oak_stairs 0  
fill ~88 ~1 ~22 ~89 ~1 ~22 fence 0  
fill ~88 ~1 ~28 ~89 ~1 ~28 fence 0 
setblock ~88 ~1 ~29 dark_oak_stairs 0  
fill ~88 ~1 ~30 ~90 ~1 ~30 stained_hardened_clay 1 
setblock ~89 ~1 ~21 dark_oak_stairs 5 
setblock ~89 ~1 ~29 dark_oak_stairs 5 
setblock ~90 ~1 ~21 fence 1 
setblock ~90 ~1 ~29 fence 1  
fill ~91 ~1 ~21 ~93 ~1 ~21 stained_hardened_clay 1  
fill ~91 ~1 ~22 ~91 ~3 ~22 chest 3  
fill ~91 ~1 ~28 ~91 ~3 ~28 chest 2  
fill ~91 ~1 ~29 ~93 ~1 ~29 stained_hardened_clay 1  
fill ~92 ~1 ~22 ~92 ~3 ~22 log 1  
fill ~92 ~1 ~28 ~92 ~3 ~28 log 1  
fill ~93 ~1 ~22 ~93 ~3 ~22 chest 3  
fill ~93 ~1 ~28 ~93 ~3 ~28 chest 2  
fill ~94 ~1 ~22 ~95 ~1 ~22 stained_hardened_clay 1  
fill ~94 ~1 ~24 ~96 ~1 ~24 wool 0  
fill ~94 ~1 ~26 ~96 ~1 ~26 wool 0  
fill ~94 ~1 ~28 ~95 ~1 ~28 stained_hardened_clay 1  
fill ~95 ~1 ~23 ~95 ~3 ~23 wool 0  
fill ~95 ~1 ~25 ~97 ~1 ~25 wool 0  
fill ~95 ~1 ~27 ~95 ~3 ~27 wool 0  
fill ~96 ~1 ~23 ~97 ~1 ~23 stained_hardened_clay 1  
fill ~96 ~1 ~27 ~97 ~1 ~27 stained_hardened_clay 1  
fill ~97 ~1 ~24 ~97 ~3 ~24 planks 5  
fill ~97 ~1 ~26 ~97 ~3 ~26 planks 5  
fill ~98 ~1 ~24 ~98 ~2 ~24 stained_hardened_clay 1  
fill ~98 ~1 ~25 ~98 ~3 ~25 fence 5  
fill ~98 ~1 ~26 ~98 ~2 ~26 stained_hardened_clay 1  
fill ~99 ~1 ~25 ~101 ~1 ~25 stained_hardened_clay 1 
setblock ~103 ~1 ~25 planks 1 
setblock ~104 ~1 ~25 fence 5 
setblock ~105 ~1 ~25 planks 1  
fill ~39 ~2 ~25 ~41 ~2 ~25 stained_hardened_clay 1  
fill ~41 ~2 ~24 ~41 ~3 ~24 stained_hardened_clay 1  
fill ~41 ~2 ~26 ~41 ~3 ~26 stained_hardened_clay 1  
fill ~42 ~2 ~23 ~42 ~3 ~23 stained_hardened_clay 1  
fill ~42 ~2 ~27 ~42 ~3 ~27 stained_hardened_clay 1  
fill ~43 ~2 ~22 ~45 ~2 ~22 stained_hardened_clay 1  
fill ~43 ~2 ~24 ~44 ~2 ~24 lapis_block 0  
fill ~43 ~2 ~25 ~44 ~2 ~25 lapis_block 0  
fill ~43 ~2 ~26 ~44 ~2 ~26 lapis_block 0  
fill ~43 ~2 ~28 ~45 ~2 ~28 stained_hardened_clay 1  
fill ~45 ~2 ~21 ~47 ~2 ~21 stained_hardened_clay 1  
fill ~45 ~2 ~29 ~47 ~2 ~29 stained_hardened_clay 1  
fill ~46 ~2 ~22 ~48 ~2 ~22 diamond_block 0  
fill ~46 ~2 ~28 ~48 ~2 ~28 gold_block 0  
fill ~47 ~2 ~20 ~51 ~2 ~20 stained_hardened_clay 1  
fill ~47 ~2 ~30 ~51 ~2 ~30 stained_hardened_clay 1  
fill ~48 ~2 ~25 ~48 ~3 ~25 concrete 4  
fill ~50 ~2 ~19 ~53 ~2 ~19 stained_hardened_clay 1  
fill ~50 ~2 ~24 ~52 ~2 ~24 lapis_block 0  
fill ~50 ~2 ~25 ~52 ~2 ~25 lapis_block 0  
fill ~50 ~2 ~26 ~52 ~2 ~26 lapis_block 0  
fill ~50 ~2 ~31 ~53 ~2 ~31 stained_hardened_clay 1  
fill ~52 ~2 ~20 ~53 ~2 ~20 diamond_block 0  
fill ~52 ~2 ~21 ~53 ~2 ~21 diamond_block 0  
fill ~52 ~2 ~29 ~53 ~2 ~29 gold_block 0  
fill ~52 ~2 ~30 ~53 ~2 ~30 gold_block 0  
fill ~53 ~2 ~18 ~57 ~2 ~18 stained_hardened_clay 1  
fill ~53 ~2 ~32 ~56 ~2 ~32 stained_hardened_clay 1  
fill ~54 ~2 ~24 ~56 ~2 ~24 lapis_block 0  
fill ~54 ~2 ~25 ~55 ~2 ~25 lapis_block 0  
fill ~54 ~2 ~26 ~56 ~2 ~26 lapis_block 0  
fill ~55 ~2 ~19 ~56 ~2 ~19 diamond_block 0  
fill ~55 ~2 ~20 ~56 ~2 ~20 diamond_block 0  
fill ~55 ~2 ~21 ~56 ~2 ~21 diamond_block 0  
fill ~55 ~2 ~29 ~56 ~2 ~29 gold_block 0  
fill ~55 ~2 ~30 ~56 ~2 ~30 gold_block 0  
fill ~55 ~2 ~31 ~56 ~2 ~31 gold_block 0  
fill ~56 ~2 ~17 ~81 ~2 ~17 stained_hardened_clay 1  
fill ~56 ~2 ~33 ~82 ~2 ~33 stained_hardened_clay 1 
setblock ~57 ~2 ~23 stained_hardened_clay 1 
setblock ~57 ~2 ~27 stained_hardened_clay 1  
fill ~57 ~2 ~32 ~57 ~3 ~32 concrete 15  
fill ~59 ~2 ~18 ~60 ~2 ~18 chest 3  
fill ~59 ~2 ~32 ~60 ~2 ~32 chest 2 
setblock ~62 ~2 ~18 planks 5 
setblock ~62 ~2 ~19 concrete 7 
setblock ~62 ~2 ~20 planks 5 
setblock ~62 ~2 ~24 dark_oak_stairs 2 
setblock ~62 ~2 ~25 planks 5 
setblock ~62 ~2 ~26 dark_oak_stairs 3 
setblock ~62 ~2 ~30 planks 5 
setblock ~62 ~2 ~31 concrete 7 
setblock ~62 ~2 ~32 planks 5  
fill ~63 ~2 ~18 ~65 ~2 ~18 planks 1  
fill ~63 ~2 ~20 ~65 ~2 ~20 planks 1  
fill ~63 ~2 ~24 ~65 ~2 ~24 stone_brick_stairs 2  
fill ~63 ~2 ~25 ~65 ~2 ~25 planks 1  
fill ~63 ~2 ~26 ~65 ~2 ~26 stone_brick_stairs 3  
fill ~63 ~2 ~30 ~65 ~2 ~30 planks 1  
fill ~63 ~2 ~32 ~65 ~2 ~32 planks 1 
setblock ~66 ~2 ~18 planks 5 
setblock ~66 ~2 ~19 concrete 7 
setblock ~66 ~2 ~20 planks 5 
setblock ~66 ~2 ~24 dark_oak_stairs 2 
setblock ~66 ~2 ~25 planks 5 
setblock ~66 ~2 ~26 dark_oak_stairs 3 
setblock ~66 ~2 ~30 planks 5 
setblock ~66 ~2 ~31 concrete 7 
setblock ~66 ~2 ~32 planks 5 
setblock ~68 ~2 ~18 planks 5 
setblock ~68 ~2 ~19 concrete 7 
setblock ~68 ~2 ~20 planks 5 
setblock ~68 ~2 ~24 dark_oak_stairs 2 
setblock ~68 ~2 ~25 planks 5 
setblock ~68 ~2 ~26 dark_oak_stairs 3 
setblock ~68 ~2 ~30 planks 5 
setblock ~68 ~2 ~31 concrete 7 
setblock ~68 ~2 ~32 planks 5  
fill ~69 ~2 ~18 ~71 ~2 ~18 planks 1  
fill ~69 ~2 ~20 ~71 ~2 ~20 planks 1  
fill ~69 ~2 ~24 ~71 ~2 ~24 stone_brick_stairs 2  
fill ~69 ~2 ~25 ~71 ~2 ~25 planks 1  
fill ~69 ~2 ~26 ~71 ~2 ~26 stone_brick_stairs 3  
fill ~69 ~2 ~30 ~71 ~2 ~30 planks 1  
fill ~69 ~2 ~32 ~71 ~2 ~32 planks 1 
setblock ~72 ~2 ~18 planks 5 
setblock ~72 ~2 ~19 concrete 7 
setblock ~72 ~2 ~20 planks 5 
setblock ~72 ~2 ~24 dark_oak_stairs 2 
setblock ~72 ~2 ~25 planks 5 
setblock ~72 ~2 ~26 dark_oak_stairs 3 
setblock ~72 ~2 ~30 planks 5 
setblock ~72 ~2 ~31 concrete 7 
setblock ~72 ~2 ~32 planks 5 
setblock ~74 ~2 ~18 planks 5 
setblock ~74 ~2 ~19 concrete 7 
setblock ~74 ~2 ~20 planks 5 
setblock ~74 ~2 ~24 dark_oak_stairs 2 
setblock ~74 ~2 ~25 planks 5 
setblock ~74 ~2 ~26 dark_oak_stairs 3 
setblock ~74 ~2 ~30 planks 5 
setblock ~74 ~2 ~31 concrete 7 
setblock ~74 ~2 ~32 planks 5  
fill ~75 ~2 ~18 ~77 ~2 ~18 planks 1  
fill ~75 ~2 ~20 ~77 ~2 ~20 planks 1  
fill ~75 ~2 ~24 ~77 ~2 ~24 stone_brick_stairs 2  
fill ~75 ~2 ~25 ~77 ~2 ~25 planks 1  
fill ~75 ~2 ~26 ~77 ~2 ~26 stone_brick_stairs 3  
fill ~75 ~2 ~30 ~77 ~2 ~30 planks 1  
fill ~75 ~2 ~32 ~77 ~2 ~32 planks 1 
setblock ~78 ~2 ~18 planks 5 
setblock ~78 ~2 ~19 concrete 7 
setblock ~78 ~2 ~20 planks 5 
setblock ~78 ~2 ~24 dark_oak_stairs 2 
setblock ~78 ~2 ~25 planks 5 
setblock ~78 ~2 ~26 dark_oak_stairs 3 
setblock ~78 ~2 ~30 planks 5 
setblock ~78 ~2 ~31 concrete 7 
setblock ~78 ~2 ~32 planks 5  
fill ~79 ~2 ~18 ~79 ~3 ~18 log 1  
fill ~79 ~2 ~32 ~79 ~3 ~32 log 1 
setblock ~80 ~2 ~18 stained_hardened_clay 1 
setblock ~80 ~2 ~22 stained_hardened_clay 1 
setblock ~80 ~2 ~28 stained_hardened_clay 1 
setblock ~80 ~2 ~32 stained_hardened_clay 1  
fill ~81 ~2 ~18 ~81 ~3 ~18 log 1  
fill ~81 ~2 ~32 ~81 ~3 ~32 log 1  
fill ~82 ~2 ~18 ~85 ~2 ~18 stained_hardened_clay 1  
fill ~82 ~2 ~24 ~84 ~2 ~24 carrots 0  
fill ~82 ~2 ~25 ~84 ~2 ~25 carrots 0  
fill ~82 ~2 ~26 ~84 ~2 ~26 carrots 0  
fill ~82 ~2 ~32 ~85 ~2 ~32 stained_hardened_clay 1  
fill ~83 ~2 ~19 ~84 ~2 ~19 chest 3  
fill ~83 ~2 ~31 ~84 ~2 ~31 chest 2  
fill ~85 ~2 ~19 ~90 ~2 ~19 stained_hardened_clay 1  
fill ~85 ~2 ~20 ~86 ~2 ~20 chest 3  
fill ~85 ~2 ~30 ~86 ~2 ~30 chest 2  
fill ~85 ~2 ~31 ~90 ~2 ~31 stained_hardened_clay 1  
fill ~86 ~2 ~24 ~89 ~2 ~24 carrots 0  
fill ~86 ~2 ~25 ~89 ~2 ~25 carrots 0  
fill ~86 ~2 ~26 ~89 ~2 ~26 carrots 0  
fill ~88 ~2 ~20 ~92 ~2 ~20 stained_hardened_clay 1  
fill ~88 ~2 ~30 ~92 ~2 ~30 stained_hardened_clay 1 
setblock ~89 ~2 ~21 dark_oak_stairs 0  
fill ~89 ~2 ~22 ~90 ~2 ~22 fence 0  
fill ~89 ~2 ~28 ~90 ~2 ~28 fence 0 
setblock ~89 ~2 ~29 dark_oak_stairs 0 
setblock ~90 ~2 ~21 dark_oak_stairs 5 
setblock ~90 ~2 ~29 dark_oak_stairs 5  
fill ~91 ~2 ~21 ~94 ~2 ~21 stained_hardened_clay 1  
fill ~91 ~2 ~29 ~94 ~2 ~29 stained_hardened_clay 1  
fill ~94 ~2 ~22 ~97 ~2 ~22 stained_hardened_clay 1  
fill ~94 ~2 ~28 ~97 ~2 ~28 stained_hardened_clay 1  
fill ~95 ~2 ~24 ~96 ~2 ~24 wool 0  
fill ~95 ~2 ~26 ~96 ~2 ~26 wool 0  
fill ~96 ~2 ~23 ~98 ~2 ~23 stained_hardened_clay 1  
fill ~96 ~2 ~25 ~97 ~2 ~25 wool 0  
fill ~96 ~2 ~27 ~98 ~2 ~27 stained_hardened_clay 1 
setblock ~99 ~2 ~24 stained_hardened_clay 1 
setblock ~99 ~2 ~25 concrete 4 
setblock ~99 ~2 ~26 stained_hardened_clay 1  
fill ~100 ~2 ~25 ~101 ~2 ~25 stained_hardened_clay 1 
setblock ~103 ~2 ~25 stained_hardened_clay 1 
setblock ~105 ~2 ~25 stained_hardened_clay 1 
setblock ~38 ~3 ~25 dropper 0  
fill ~39 ~3 ~25 ~41 ~3 ~25 stained_hardened_clay 1  
fill ~41 ~3 ~23 ~41 ~4 ~23 stained_hardened_clay 1  
fill ~41 ~3 ~27 ~41 ~4 ~27 stained_hardened_clay 1  
fill ~42 ~3 ~22 ~45 ~3 ~22 stained_hardened_clay 1  
fill ~42 ~3 ~28 ~45 ~3 ~28 stained_hardened_clay 1  
fill ~43 ~3 ~21 ~47 ~3 ~21 stained_hardened_clay 1  
fill ~43 ~3 ~29 ~47 ~3 ~29 stained_hardened_clay 1  
fill ~45 ~3 ~20 ~51 ~3 ~20 stained_hardened_clay 1  
fill ~45 ~3 ~30 ~51 ~3 ~30 stained_hardened_clay 1  
fill ~46 ~3 ~22 ~48 ~3 ~22 diamond_block 0  
fill ~46 ~3 ~28 ~48 ~3 ~28 gold_block 0  
fill ~47 ~3 ~19 ~53 ~3 ~19 stained_hardened_clay 1  
fill ~47 ~3 ~31 ~53 ~3 ~31 stained_hardened_clay 1  
fill ~50 ~3 ~18 ~56 ~3 ~18 stained_hardened_clay 1  
fill ~50 ~3 ~32 ~56 ~3 ~32 stained_hardened_clay 1  
fill ~52 ~3 ~20 ~53 ~3 ~20 diamond_block 0  
fill ~52 ~3 ~21 ~53 ~3 ~21 diamond_block 0  
fill ~52 ~3 ~29 ~53 ~3 ~29 gold_block 0  
fill ~52 ~3 ~30 ~53 ~3 ~30 gold_block 0  
fill ~53 ~3 ~17 ~85 ~3 ~17 stained_hardened_clay 1  
fill ~53 ~3 ~33 ~85 ~3 ~33 stained_hardened_clay 1  
fill ~55 ~3 ~19 ~56 ~3 ~19 pumpkin 0  
fill ~55 ~3 ~20 ~56 ~3 ~20 diamond_block 0  
fill ~55 ~3 ~21 ~56 ~3 ~21 diamond_block 0  
fill ~55 ~3 ~29 ~56 ~3 ~29 gold_block 0  
fill ~55 ~3 ~30 ~56 ~3 ~30 gold_block 0  
fill ~55 ~3 ~31 ~56 ~3 ~31 gold_block 0  
fill ~57 ~3 ~18 ~57 ~3 ~32 concrete 15  
fill ~58 ~3 ~16 ~78 ~3 ~16 stained_hardened_clay 1  
fill ~58 ~3 ~34 ~78 ~3 ~34 stained_hardened_clay 1  
fill ~59 ~3 ~18 ~60 ~3 ~18 chest 3  
fill ~59 ~3 ~32 ~60 ~3 ~32 chest 2 
setblock ~62 ~3 ~18 dark_oak_stairs 2 
setblock ~62 ~3 ~19 planks 5 
setblock ~62 ~3 ~20 dark_oak_stairs 3 
setblock ~62 ~3 ~30 dark_oak_stairs 2 
setblock ~62 ~3 ~31 planks 5 
setblock ~62 ~3 ~32 dark_oak_stairs 3  
fill ~63 ~3 ~18 ~65 ~3 ~18 stone_brick_stairs 2  
fill ~63 ~3 ~19 ~65 ~3 ~19 planks 1  
fill ~63 ~3 ~20 ~65 ~3 ~20 stone_brick_stairs 3  
fill ~63 ~3 ~30 ~65 ~3 ~30 stone_brick_stairs 2  
fill ~63 ~3 ~31 ~65 ~3 ~31 planks 1  
fill ~63 ~3 ~32 ~65 ~3 ~32 stone_brick_stairs 3 
setblock ~66 ~3 ~18 dark_oak_stairs 2 
setblock ~66 ~3 ~19 planks 5 
setblock ~66 ~3 ~20 dark_oak_stairs 3 
setblock ~66 ~3 ~30 dark_oak_stairs 2 
setblock ~66 ~3 ~31 planks 5 
setblock ~66 ~3 ~32 dark_oak_stairs 3 
setblock ~68 ~3 ~18 dark_oak_stairs 2 
setblock ~68 ~3 ~19 planks 5 
setblock ~68 ~3 ~20 dark_oak_stairs 3 
setblock ~68 ~3 ~30 dark_oak_stairs 2 
setblock ~68 ~3 ~31 planks 5 
setblock ~68 ~3 ~32 dark_oak_stairs 3  
fill ~69 ~3 ~18 ~71 ~3 ~18 stone_brick_stairs 2  
fill ~69 ~3 ~19 ~71 ~3 ~19 planks 1  
fill ~69 ~3 ~20 ~71 ~3 ~20 stone_brick_stairs 3  
fill ~69 ~3 ~30 ~71 ~3 ~30 stone_brick_stairs 2  
fill ~69 ~3 ~31 ~71 ~3 ~31 planks 1  
fill ~69 ~3 ~32 ~71 ~3 ~32 stone_brick_stairs 3 
setblock ~72 ~3 ~18 dark_oak_stairs 2 
setblock ~72 ~3 ~19 planks 5 
setblock ~72 ~3 ~20 dark_oak_stairs 3 
setblock ~72 ~3 ~30 dark_oak_stairs 2 
setblock ~72 ~3 ~31 planks 5 
setblock ~72 ~3 ~32 dark_oak_stairs 3 
setblock ~74 ~3 ~18 dark_oak_stairs 2 
setblock ~74 ~3 ~19 planks 5 
setblock ~74 ~3 ~20 dark_oak_stairs 3 
setblock ~74 ~3 ~30 dark_oak_stairs 2 
setblock ~74 ~3 ~31 planks 5 
setblock ~74 ~3 ~32 dark_oak_stairs 3  
fill ~75 ~3 ~18 ~77 ~3 ~18 stone_brick_stairs 2  
fill ~75 ~3 ~19 ~77 ~3 ~19 planks 1  
fill ~75 ~3 ~20 ~77 ~3 ~20 stone_brick_stairs 3  
fill ~75 ~3 ~30 ~77 ~3 ~30 stone_brick_stairs 2  
fill ~75 ~3 ~31 ~77 ~3 ~31 planks 1  
fill ~75 ~3 ~32 ~77 ~3 ~32 stone_brick_stairs 3 
setblock ~78 ~3 ~18 dark_oak_stairs 2 KittysCommands: summon minecraft:item ~44.8670428738 ~2.875 ~22.8007714931 summon minecraft:item ~45.4341837876 ~1.0 ~25.9050805879 summon minecraft:item ~48.625 ~1.0 ~27.8122558594 summon minecraft:item ~48.625 ~1.0 ~21.625 summon minecraft:item ~58.625 ~5.0 ~16.7551269531 summon minecraft:item ~58.625 ~5.0 ~15.9768066406 summon minecraft:item ~61.625 ~0.0 ~28.375 summon minecraft:item ~61.5056152344 ~0.0 ~22.625 summon minecraft:item ~60.6625976562 ~1.0 ~19.0004882812 summon minecraft:item ~58.4597167969 ~0.0 ~27.1809082031 summon minecraft:item ~57.7895507812 ~1.0 ~18.625 summon minecraft:item ~57.7814941406 ~0.0 ~23.3244628906 summon minecraft:item ~57.625 ~0.0 ~23.8059082031 summon minecraft:item ~55.451171875 ~5.0 ~18.0673828125 summon minecraft:item ~55.4526367188 ~0.0 ~23.0612792969 summon minecraft:item ~56.375 ~0.5 ~28.375 summon minecraft:item ~54.625 ~5.0 ~18.0588378906 summon minecraft:item ~54.375 ~1.0 ~19.625 summon minecraft:item ~61.375 ~1.0 ~31.375 summon minecraft:item ~57.625 ~1.0 ~31.375 summon minecraft:item ~57.1909179688 ~5.0 ~31.0705566406 summon minecraft:item ~56.8208007812 ~5.0 ~31.4108886719 summon minecraft:item ~53.7033691406 ~1.0 ~30.375 summon minecraft:bat ~53.9137175505 ~1.1769684277 ~30.021582031 summon minecraft:item ~77.625 ~5.0 ~15.625 summon minecraft:item ~79.9438476562 ~5.0 ~17.3115234375 summon minecraft:item ~67.375 ~1.0 ~18.625 summon minecraft:item ~71.501953125 ~0.0 ~27.7653808594 summon minecraft:item ~71.375 ~5.0 ~17.6975097656 summon minecraft:item ~71.375 ~5.0 ~18.0258789062 summon minecraft:item ~70.7241210938 ~0.0 ~23.158203125 summon minecraft:item ~72.625 ~1.0 ~18.625 summon minecraft:item ~77.625 ~5.0 ~18.3330078125 summon minecraft:item ~78.625 ~1.0 ~18.625 summon minecraft:item ~67.375 ~1.0 ~31.375 summon minecraft:item ~72.625 ~1.0 ~31.375 summon minecraft:item ~79.375 ~1.0 ~31.375 summon minecraft:item ~77.625 ~5.0 ~32.2790527344 summon minecraft:item ~80.7749023438 ~2.875 ~18.625 summon minecraft:item ~80.7854003906 ~5.0 ~33.375 summon minecraft:item ~77.625 ~5.0 ~34.375 summon minecraft:item ~87.375 ~1.0 ~28.6711425781 summon minecraft:item ~87.5009765625 ~1.5 ~20.625 summon minecraft:item ~92.8354492188 ~1.0 ~26.07421875 summon minecraft:item ~92.6696777344 ~1.0 ~24.2392578125 summon minecraft:item ~81.8227539062 ~1.0 ~31.375  

KittysCommands:  
setblock ~78 ~3 ~19 planks 5 
setblock ~78 ~3 ~20 dark_oak_stairs 3 
setblock ~78 ~3 ~30 dark_oak_stairs 2 
setblock ~78 ~3 ~31 planks 5 
setblock ~78 ~3 ~32 dark_oak_stairs 3  
fill ~80 ~3 ~18 ~80 ~3 ~23 concrete 15 
setblock ~80 ~3 ~25 coal_block 0  
fill ~80 ~3 ~27 ~80 ~3 ~32 concrete 15  
fill ~82 ~3 ~18 ~90 ~3 ~18 stained_hardened_clay 1  
fill ~82 ~3 ~32 ~90 ~3 ~32 stained_hardened_clay 1  
fill ~83 ~3 ~19 ~84 ~3 ~19 chest 3  
fill ~83 ~3 ~31 ~84 ~3 ~31 chest 2  
fill ~85 ~3 ~19 ~92 ~3 ~19 stained_hardened_clay 1  
fill ~85 ~3 ~20 ~86 ~3 ~20 chest 3  
fill ~85 ~3 ~30 ~86 ~3 ~30 chest 2  
fill ~85 ~3 ~31 ~92 ~3 ~31 stained_hardened_clay 1  
fill ~88 ~3 ~20 ~94 ~3 ~20 stained_hardened_clay 1  
fill ~88 ~3 ~30 ~94 ~3 ~30 stained_hardened_clay 1 
setblock ~90 ~3 ~21 dark_oak_stairs 0 
setblock ~90 ~3 ~22 fence 0 
setblock ~90 ~3 ~28 fence 0 
setblock ~90 ~3 ~29 dark_oak_stairs 0  
fill ~91 ~3 ~21 ~96 ~3 ~21 stained_hardened_clay 1  
fill ~91 ~3 ~29 ~96 ~3 ~29 stained_hardened_clay 1  
fill ~94 ~3 ~22 ~98 ~3 ~22 stained_hardened_clay 1  
fill ~94 ~3 ~28 ~98 ~3 ~28 stained_hardened_clay 1  
fill ~96 ~3 ~23 ~99 ~3 ~23 stained_hardened_clay 1 
setblock ~96 ~3 ~24 wool 0 
setblock ~96 ~3 ~26 wool 0  
fill ~96 ~3 ~27 ~99 ~3 ~27 stained_hardened_clay 1 
setblock ~97 ~3 ~25 wool 0 
setblock ~99 ~3 ~24 fence 5 
setblock ~99 ~3 ~25 concrete 15 
setblock ~99 ~3 ~26 fence 5 
setblock ~100 ~3 ~24 stained_hardened_clay 1 
setblock ~100 ~3 ~26 stained_hardened_clay 1 
setblock ~101 ~3 ~25 stained_hardened_clay 1 
setblock ~103 ~3 ~25 planks 1 
setblock ~104 ~3 ~25 fence 5 
setblock ~105 ~3 ~25 planks 1  
fill ~106 ~3 ~25 ~106 ~5 ~25 double_stone_slab 0 
setblock ~107 ~3 ~25 stone_slab 0  
fill ~38 ~4 ~25 ~40 ~4 ~25 stained_hardened_clay 1  
fill ~40 ~4 ~24 ~40 ~6 ~24 stained_hardened_clay 1  
fill ~40 ~4 ~26 ~40 ~6 ~26 stained_hardened_clay 1  
fill ~41 ~4 ~24 ~46 ~4 ~24 planks 0  
fill ~41 ~4 ~25 ~46 ~4 ~25 planks 0  
fill ~41 ~4 ~26 ~46 ~4 ~26 planks 0  
fill ~42 ~4 ~22 ~42 ~3 ~22 stained_hardened_clay 1  
fill ~42 ~4 ~23 ~50 ~4 ~23 planks 0  
fill ~42 ~4 ~27 ~50 ~4 ~27 planks 0  
fill ~42 ~4 ~28 ~42 ~3 ~28 stained_hardened_clay 1  
fill ~43 ~4 ~21 ~43 ~3 ~21 stained_hardened_clay 1  
fill ~43 ~4 ~22 ~60 ~4 ~22 planks 0  
fill ~43 ~4 ~28 ~60 ~4 ~28 planks 0  
fill ~43 ~4 ~29 ~43 ~3 ~29 stained_hardened_clay 1  
fill ~44 ~4 ~20 ~45 ~4 ~20 stained_hardened_clay 1 
setblock ~44 ~4 ~21 planks 5 
setblock ~44 ~4 ~29 planks 5  
fill ~44 ~4 ~30 ~45 ~4 ~30 stained_hardened_clay 1  
fill ~45 ~4 ~21 ~86 ~4 ~21 planks 0  
fill ~45 ~4 ~29 ~86 ~4 ~29 planks 0  
fill ~46 ~4 ~19 ~48 ~4 ~19 stained_hardened_clay 1  
fill ~46 ~4 ~20 ~94 ~4 ~20 planks 0  
fill ~46 ~4 ~30 ~94 ~4 ~30 planks 0  
fill ~46 ~4 ~31 ~48 ~4 ~31 stained_hardened_clay 1  
fill ~47 ~4 ~24 ~49 ~4 ~24 planks 1  
fill ~47 ~4 ~25 ~47 ~4 ~26 planks 1 
setblock ~48 ~4 ~25 concrete 15  
fill ~48 ~4 ~26 ~49 ~4 ~26 planks 1  
fill ~49 ~4 ~18 ~51 ~4 ~18 stained_hardened_clay 1 
setblock ~49 ~4 ~19 planks 5 
setblock ~49 ~4 ~25 planks 1 
setblock ~49 ~4 ~31 planks 5  
fill ~49 ~4 ~32 ~51 ~4 ~32 stained_hardened_clay 1  
fill ~50 ~4 ~19 ~91 ~4 ~19 planks 0  
fill ~50 ~4 ~24 ~50 ~4 ~31 planks 0  
fill ~51 ~4 ~23 ~56 ~4 ~23 planks 1  
fill ~51 ~4 ~24 ~51 ~4 ~27 planks 1  
fill ~51 ~4 ~31 ~91 ~4 ~31 planks 0  
fill ~52 ~4 ~17 ~56 ~4 ~17 stained_hardened_clay 1  
fill ~52 ~4 ~18 ~53 ~4 ~18 planks 0  
fill ~52 ~4 ~27 ~56 ~4 ~27 planks 1  
fill ~52 ~4 ~32 ~53 ~4 ~32 planks 0  
fill ~52 ~4 ~33 ~56 ~4 ~33 stained_hardened_clay 1 
setblock ~54 ~4 ~18 planks 5 
setblock ~54 ~4 ~32 planks 5  
fill ~55 ~4 ~18 ~86 ~4 ~18 planks 0  
fill ~55 ~4 ~32 ~86 ~4 ~32 planks 0  
fill ~56 ~4 ~24 ~56 ~4 ~27 planks 1  
fill ~57 ~4 ~16 ~83 ~4 ~16 stained_hardened_clay 1  
fill ~57 ~4 ~17 ~66 ~4 ~17 planks 0  
fill ~57 ~4 ~23 ~60 ~4 ~23 planks 0  
fill ~57 ~4 ~24 ~60 ~4 ~24 planks 0  
fill ~57 ~4 ~25 ~60 ~4 ~25 planks 0  
fill ~57 ~4 ~26 ~60 ~4 ~26 planks 0  
fill ~57 ~4 ~27 ~60 ~4 ~27 planks 0  
fill ~57 ~4 ~33 ~66 ~4 ~33 planks 0  
fill ~57 ~4 ~34 ~82 ~4 ~34 stained_hardened_clay 1  
fill ~61 ~4 ~23 ~61 ~4 ~27 planks 1  
fill ~62 ~4 ~22 ~72 ~4 ~22 planks 5  
fill ~62 ~4 ~23 ~65 ~4 ~23 trapdoor 9  
fill ~62 ~4 ~24 ~65 ~4 ~24 trapdoor 8  
fill ~62 ~4 ~25 ~65 ~4 ~25 trapdoor 8  
fill ~62 ~4 ~26 ~65 ~4 ~26 trapdoor 8  
fill ~62 ~4 ~27 ~65 ~4 ~27 trapdoor 8  
fill ~62 ~4 ~28 ~72 ~4 ~28 planks 5  
fill ~66 ~4 ~23 ~66 ~4 ~27 trapdoor 10 
setblock ~67 ~4 ~17 planks 5  
fill ~67 ~4 ~23 ~67 ~4 ~27 dropper 9 
setblock ~67 ~4 ~33 planks 5  
fill ~68 ~4 ~17 ~71 ~4 ~17 planks 0  
fill ~68 ~4 ~23 ~68 ~4 ~27 trapdoor 8  
fill ~68 ~4 ~33 ~71 ~4 ~33 planks 0  
fill ~69 ~4 ~23 ~70 ~4 ~23 trapdoor 11  
fill ~69 ~4 ~24 ~70 ~4 ~24 trapdoor 11  
fill ~69 ~4 ~25 ~70 ~4 ~25 trapdoor 11  
fill ~69 ~4 ~26 ~70 ~4 ~26 trapdoor 11  
fill ~69 ~4 ~27 ~70 ~4 ~27 trapdoor 11  
fill ~71 ~4 ~23 ~71 ~4 ~27 trapdoor 10 
setblock ~72 ~4 ~17 planks 5  
fill ~72 ~4 ~23 ~72 ~4 ~27 trapdoor 11 
setblock ~72 ~4 ~33 planks 5  
fill ~73 ~4 ~17 ~76 ~4 ~17 planks 0  
fill ~73 ~4 ~23 ~73 ~4 ~27 planks 1  
fill ~73 ~4 ~33 ~76 ~4 ~33 planks 0  
fill ~74 ~4 ~22 ~98 ~4 ~22 planks 0  
fill ~74 ~4 ~23 ~84 ~4 ~23 planks 0  
fill ~74 ~4 ~24 ~78 ~4 ~24 planks 0  
fill ~74 ~4 ~25 ~78 ~4 ~25 planks 0  
fill ~74 ~4 ~26 ~78 ~4 ~26 planks 0  
fill ~74 ~4 ~27 ~84 ~4 ~27 planks 0  
fill ~74 ~4 ~28 ~98 ~4 ~28 planks 0 
setblock ~77 ~4 ~17 planks 5 
setblock ~77 ~4 ~33 planks 5  
fill ~78 ~4 ~17 ~81 ~4 ~17 planks 0  
fill ~78 ~4 ~33 ~81 ~4 ~33 planks 0  
fill ~79 ~4 ~24 ~81 ~4 ~24 planks 1  
fill ~79 ~4 ~25 ~81 ~4 ~25 planks 1  
fill ~79 ~4 ~26 ~81 ~4 ~26 planks 1 
setblock ~82 ~4 ~17 planks 5  
fill ~82 ~4 ~24 ~84 ~4 ~24 planks 0  
fill ~82 ~4 ~25 ~84 ~4 ~25 planks 0  
fill ~82 ~4 ~26 ~84 ~4 ~26 planks 0 
setblock ~82 ~4 ~33 planks 5  
fill ~83 ~4 ~17 ~89 ~4 ~17 stained_hardened_clay 1  
fill ~83 ~4 ~33 ~88 ~4 ~33 stained_hardened_clay 1  
fill ~85 ~4 ~23 ~89 ~4 ~23 planks 1  
fill ~85 ~4 ~24 ~85 ~4 ~27 planks 1  
fill ~86 ~4 ~27 ~89 ~4 ~27 planks 1 
setblock ~87 ~4 ~18 planks 5 
setblock ~87 ~4 ~21 oak_stairs 5 
setblock ~87 ~4 ~29 oak_stairs 5 
setblock ~87 ~4 ~32 planks 5  
fill ~88 ~4 ~18 ~89 ~4 ~18 planks 0 
setblock ~88 ~4 ~32 planks 0  
fill ~89 ~4 ~24 ~89 ~4 ~27 planks 1  
fill ~89 ~4 ~32 ~92 ~4 ~32 stained_hardened_clay 1  
fill ~90 ~4 ~18 ~92 ~4 ~18 stained_hardened_clay 1  
fill ~90 ~4 ~23 ~99 ~4 ~23 planks 0  
fill ~90 ~4 ~24 ~97 ~4 ~24 planks 0  
fill ~90 ~4 ~25 ~97 ~4 ~25 planks 0  
fill ~90 ~4 ~26 ~97 ~4 ~26 planks 0  
fill ~90 ~4 ~27 ~99 ~4 ~27 planks 0 
setblock ~91 ~4 ~21 dark_oak_stairs 0 
setblock ~91 ~4 ~29 dark_oak_stairs 0 
setblock ~92 ~4 ~19 planks 5  
fill ~92 ~4 ~21 ~96 ~4 ~21 planks 0  
fill ~92 ~4 ~29 ~96 ~4 ~29 planks 0 
setblock ~92 ~4 ~31 planks 5  
fill ~93 ~4 ~19 ~94 ~4 ~19 stained_hardened_clay 1  
fill ~93 ~4 ~31 ~94 ~4 ~31 stained_hardened_clay 1  
fill ~95 ~4 ~20 ~96 ~4 ~20 stained_hardened_clay 1  
fill ~95 ~4 ~30 ~96 ~4 ~30 stained_hardened_clay 1  
fill ~97 ~4 ~21 ~98 ~4 ~21 stained_hardened_clay 1  
fill ~97 ~4 ~29 ~98 ~4 ~29 stained_hardened_clay 1  
fill ~98 ~4 ~24 ~100 ~4 ~24 planks 1  
fill ~98 ~4 ~25 ~98 ~4 ~26 planks 1 
setblock ~99 ~4 ~22 stained_hardened_clay 1  
fill ~99 ~4 ~25 ~99 ~5 ~25 concrete 4  
fill ~99 ~4 ~26 ~100 ~4 ~26 planks 1 
setblock ~99 ~4 ~28 stained_hardened_clay 1 
setblock ~100 ~4 ~23 stained_hardened_clay 1 
setblock ~100 ~4 ~25 planks 1 
setblock ~100 ~4 ~27 stained_hardened_clay 1 
setblock ~101 ~4 ~24 stained_hardened_clay 1 
setblock ~101 ~4 ~25 planks 0 
setblock ~101 ~4 ~26 stained_hardened_clay 1  
fill ~102 ~4 ~25 ~103 ~4 ~25 stained_hardened_clay 1 
setblock ~105 ~4 ~25 stained_hardened_clay 1  
fill ~38 ~5 ~25 ~40 ~5 ~25 stained_hardened_clay 1  
fill ~40 ~5 ~23 ~40 ~6 ~23 stained_hardened_clay 1  
fill ~40 ~5 ~27 ~40 ~6 ~27 stained_hardened_clay 1  
fill ~41 ~5 ~22 ~41 ~6 ~22 stained_hardened_clay 1 
setblock ~41 ~5 ~23 activator_rail 0 
setblock ~41 ~5 ~24 dropper 9 
setblock ~41 ~5 ~25 activator_rail 0  
fill ~41 ~5 ~26 ~41 ~5 ~27 cobblestone 0  
fill ~41 ~5 ~28 ~41 ~6 ~28 stained_hardened_clay 1  
fill ~42 ~5 ~21 ~42 ~6 ~21 stained_hardened_clay 1  
fill ~42 ~5 ~28 ~42 ~6 ~28 chest 5  
fill ~42 ~5 ~29 ~42 ~6 ~29 stained_hardened_clay 1  
fill ~43 ~5 ~20 ~43 ~6 ~20 stained_hardened_clay 1  
fill ~43 ~5 ~21 ~44 ~5 ~21 bookshelf 0  
fill ~43 ~5 ~28 ~44 ~5 ~28 spruce_door 3  
fill ~43 ~5 ~29 ~44 ~5 ~29 dropper 9  
fill ~43 ~5 ~30 ~43 ~6 ~30 stained_hardened_clay 1  
fill ~44 ~5 ~19 ~45 ~5 ~19 stained_hardened_clay 1  
fill ~44 ~5 ~20 ~45 ~5 ~20 planks 5  
fill ~44 ~5 ~30 ~45 ~5 ~30 planks 5  
fill ~44 ~5 ~31 ~45 ~5 ~31 stained_hardened_clay 1  
fill ~45 ~5 ~21 ~45 ~6 ~21 stained_hardened_clay 1  
fill ~45 ~5 ~22 ~45 ~5 ~25 stained_hardened_clay 1  
fill ~45 ~5 ~26 ~45 ~6 ~26 planks 5 
setblock ~45 ~5 ~27 spruce_door 2  
fill ~45 ~5 ~28 ~45 ~6 ~28 planks 5  
fill ~45 ~5 ~29 ~45 ~6 ~29 stained_hardened_clay 1  
fill ~46 ~5 ~18 ~48 ~5 ~18 stained_hardened_clay 1  
fill ~46 ~5 ~19 ~47 ~5 ~19 chest 3  
fill ~46 ~5 ~31 ~47 ~5 ~31 chest 2  
fill ~46 ~5 ~32 ~48 ~5 ~32 stained_hardened_clay 1  
fill ~48 ~5 ~19 ~48 ~6 ~19 stained_hardened_clay 1  
fill ~48 ~5 ~20 ~48 ~6 ~20 stained_hardened_clay 1  
fill ~48 ~5 ~21 ~48 ~6 ~21 stained_hardened_clay 1 
setblock ~48 ~5 ~22 spruce_door 2  
fill ~48 ~5 ~23 ~48 ~7 ~23 planks 5  
fill ~48 ~5 ~24 ~48 ~7 ~24 fence 5  
fill ~48 ~5 ~25 ~48 ~6 ~25 concrete 4  
fill ~48 ~5 ~26 ~48 ~7 ~26 fence 5  
fill ~48 ~5 ~27 ~48 ~7 ~27 planks 5 
setblock ~48 ~5 ~28 spruce_door 2  
fill ~48 ~5 ~29 ~48 ~6 ~29 stained_hardened_clay 1  
fill ~48 ~5 ~30 ~48 ~6 ~30 stained_hardened_clay 1  
fill ~48 ~5 ~31 ~48 ~6 ~31 stained_hardened_clay 1  
fill ~49 ~5 ~17 ~51 ~5 ~17 stained_hardened_clay 1  
fill ~49 ~5 ~18 ~49 ~7 ~18 planks 5  
fill ~49 ~5 ~19 ~51 ~5 ~19 pumpkin 3  
fill ~49 ~5 ~20 ~49 ~7 ~20 pumpkin 1  
fill ~49 ~5 ~21 ~49 ~7 ~21 planks 5  
fill ~49 ~5 ~29 ~49 ~7 ~29 planks 5  
fill ~49 ~5 ~30 ~50 ~5 ~30 melon_block 0  
fill ~49 ~5 ~31 ~53 ~5 ~31 melon_block 0  
fill ~49 ~5 ~32 ~49 ~7 ~32 planks 5  
fill ~49 ~5 ~33 ~51 ~5 ~33 stained_hardened_clay 1 
setblock ~50 ~5 ~18 hay_block 0  
fill ~50 ~5 ~21 ~50 ~7 ~21 fence 1  
fill ~50 ~5 ~29 ~50 ~7 ~29 fence 1  
fill ~50 ~5 ~32 ~53 ~5 ~32 melon_block 0  
fill ~51 ~5 ~18 ~51 ~7 ~18 pumpkin 2  
fill ~51 ~5 ~23 ~56 ~5 ~23 fence 5  
fill ~51 ~5 ~24 ~51 ~5 ~27 fence 5  
fill ~52 ~5 ~16 ~56 ~5 ~16 stained_hardened_clay 1 
setblock ~52 ~5 ~17 hay_block 8 
setblock ~52 ~5 ~18 hay_block 0  
fill ~52 ~5 ~19 ~53 ~5 ~19 hay_block 8  
fill ~52 ~5 ~20 ~53 ~5 ~20 pumpkin 2  
fill ~52 ~5 ~21 ~53 ~5 ~21 fence 1  
fill ~52 ~5 ~27 ~56 ~5 ~27 fence 5  
fill ~52 ~5 ~29 ~53 ~5 ~29 fence 1  
fill ~52 ~5 ~30 ~53 ~5 ~30 melon_block 0  
fill ~52 ~5 ~33 ~53 ~5 ~33 melon_block 0  
fill ~52 ~5 ~34 ~56 ~5 ~34 stained_hardened_clay 1 
setblock ~53 ~5 ~17 hay_block 0 
setblock ~53 ~5 ~18 hay_block 4  
fill ~54 ~5 ~17 ~54 ~7 ~17 planks 5  
fill ~54 ~5 ~18 ~54 ~6 ~18 planks 0  
fill ~54 ~5 ~19 ~54 ~6 ~19 planks 0  
fill ~54 ~5 ~20 ~54 ~6 ~20 planks 0  
fill ~54 ~5 ~21 ~54 ~7 ~21 planks 5  
fill ~54 ~5 ~29 ~54 ~7 ~29 planks 5  
fill ~54 ~5 ~30 ~54 ~6 ~30 planks 0  
fill ~54 ~5 ~31 ~54 ~6 ~31 planks 0  
fill ~54 ~5 ~32 ~54 ~6 ~32 planks 0  
fill ~54 ~5 ~33 ~54 ~7 ~33 planks 5  
fill ~55 ~5 ~17 ~55 ~6 ~17 chest 5  
fill ~55 ~5 ~20 ~55 ~6 ~20 planks 1  
fill ~55 ~5 ~30 ~55 ~6 ~30 planks 1 
setblock ~55 ~5 ~31 dispenser 0 
setblock ~55 ~5 ~32 glass 0 
setblock ~55 ~5 ~33 dispenser 0 
setblock ~56 ~5 ~20 dark_oak_door 2  
fill ~56 ~5 ~24 ~56 ~5 ~27 fence 5 
setblock ~56 ~5 ~30 dark_oak_door 3  
fill ~57 ~5 ~15 ~79 ~5 ~15 stained_hardened_clay 1  
fill ~57 ~5 ~16 ~57 ~7 ~16 bookshelf 0 
setblock ~57 ~5 ~17 dispenser 2 
setblock ~57 ~5 ~18 glass 0 
setblock ~57 ~5 ~19 dispenser 0  
fill ~57 ~5 ~20 ~57 ~6 ~20 planks 1  
fill ~57 ~5 ~30 ~57 ~6 ~30 planks 1  
fill ~57 ~5 ~33 ~57 ~6 ~33 chest 4  
fill ~57 ~5 ~34 ~57 ~7 ~34 bookshelf 0  
fill ~57 ~5 ~35 ~79 ~5 ~35 stained_hardened_clay 1  
fill ~58 ~5 ~16 ~58 ~6 ~16 planks 0  
fill ~58 ~5 ~17 ~58 ~6 ~17 planks 0  
fill ~58 ~5 ~18 ~58 ~6 ~18 planks 0  
fill ~58 ~5 ~19 ~58 ~6 ~19 planks 0  
fill ~58 ~5 ~20 ~58 ~6 ~20 planks 0  
fill ~58 ~5 ~30 ~58 ~6 ~30 planks 0  
fill ~58 ~5 ~31 ~58 ~6 ~31 planks 0  
fill ~58 ~5 ~32 ~58 ~6 ~32 planks 0  
fill ~58 ~5 ~33 ~58 ~6 ~33 planks 0  
fill ~58 ~5 ~34 ~58 ~6 ~34 planks 0  
fill ~59 ~5 ~19 ~59 ~6 ~19 chest 5  
fill ~59 ~5 ~20 ~59 ~6 ~20 planks 1  
fill ~59 ~5 ~30 ~59 ~6 ~30 planks 1 
setblock ~59 ~5 ~31 dispenser 2 
setblock ~59 ~5 ~32 glass 0 
setblock ~59 ~5 ~33 dispenser 0  
fill ~59 ~5 ~34 ~59 ~6 ~34 bookshelf 0 
setblock ~60 ~5 ~20 dark_oak_door 2 
setblock ~60 ~5 ~30 dark_oak_door 3  
fill ~60 ~5 ~34 ~60 ~6 ~34 bed 0  
fill ~61 ~5 ~16 ~61 ~6 ~16 bookshelf 0 
setblock ~61 ~5 ~17 dispenser 2 
setblock ~61 ~5 ~18 glass 0 
setblock ~61 ~5 ~19 dispenser 0  
fill ~61 ~5 ~20 ~61 ~6 ~20 planks 1  
fill ~61 ~5 ~30 ~61 ~6 ~30 planks 1  
fill ~61 ~5 ~31 ~61 ~6 ~31 chest 4  
fill ~61 ~5 ~34 ~61 ~6 ~34 bed 8  
fill ~62 ~5 ~16 ~62 ~7 ~16 planks 5  
fill ~62 ~5 ~17 ~62 ~6 ~17 planks 0  
fill ~62 ~5 ~18 ~62 ~6 ~18 planks 0  
fill ~62 ~5 ~19 ~62 ~6 ~19 planks 0  
fill ~62 ~5 ~20 ~62 ~6 ~20 planks 0  
fill ~62 ~5 ~30 ~62 ~6 ~30 planks 0  
fill ~62 ~5 ~31 ~62 ~6 ~31 planks 0  
fill ~62 ~5 ~32 ~62 ~6 ~32 planks 0  
fill ~62 ~5 ~33 ~62 ~6 ~33 planks 0  
fill ~62 ~5 ~34 ~62 ~6 ~34 planks 0 
setblock ~63 ~5 ~16 dispenser 1  
fill ~63 ~5 ~20 ~63 ~6 ~20 planks 1  
fill ~63 ~5 ~30 ~63 ~6 ~30 planks 1  
fill ~63 ~5 ~31 ~63 ~6 ~31 bookshelf 0 
setblock ~63 ~5 ~32 dispenser 2 
setblock ~63 ~5 ~33 glass 0 
setblock ~63 ~5 ~34 dispenser 0 
setblock ~64 ~5 ~16 glass 0 
setblock ~64 ~5 ~20 dark_oak_door 1 
setblock ~64 ~5 ~30 dark_oak_door 3 
setblock ~65 ~5 ~16 dispenser 3  
fill ~65 ~5 ~19 ~65 ~6 ~19 bed 0  
fill ~65 ~5 ~20 ~65 ~6 ~20 planks 1  
fill ~65 ~5 ~30 ~65 ~6 ~30 planks 1  
fill ~65 ~5 ~31 ~65 ~6 ~31 bed 0  
fill ~66 ~5 ~16 ~66 ~6 ~16 bookshelf 0  
fill ~66 ~5 ~17 ~66 ~6 ~17 bookshelf 0  
fill ~66 ~5 ~18 ~66 ~6 ~18 chest 4  
fill ~66 ~5 ~19 ~66 ~6 ~19 bed 8  
fill ~66 ~5 ~20 ~67 ~5 ~20 planks 0  
fill ~66 ~5 ~30 ~67 ~5 ~30 planks 0  
fill ~66 ~5 ~31 ~66 ~6 ~31 bed 8  
fill ~66 ~5 ~32 ~66 ~6 ~32 chest 4  
fill ~67 ~5 ~16 ~67 ~7 ~16 planks 5  
fill ~67 ~5 ~17 ~67 ~6 ~17 planks 0  
fill ~67 ~5 ~18 ~67 ~6 ~18 planks 0  
fill ~67 ~5 ~19 ~67 ~6 ~19 planks 0  
fill ~67 ~5 ~31 ~67 ~8 ~31 planks 0  
fill ~67 ~5 ~32 ~67 ~8 ~32 planks 0  
fill ~67 ~5 ~33 ~67 ~8 ~33 planks 0  
fill ~67 ~5 ~34 ~67 ~7 ~34 planks 5  
fill ~68 ~5 ~16 ~68 ~6 ~16 bookshelf 0 
setblock ~68 ~5 ~17 dispenser 0 
setblock ~68 ~5 ~18 glass 0 
setblock ~68 ~5 ~19 dispenser 0  
fill ~68 ~5 ~20 ~68 ~6 ~20 planks 1  
fill ~68 ~5 ~30 ~68 ~6 ~30 planks 1 
setblock ~68 ~5 ~31 dispenser 0 
setblock ~68 ~5 ~32 glass 0 
setblock ~68 ~5 ~33 dispenser 0 
setblock ~69 ~5 ~20 dark_oak_door 1 
setblock ~69 ~5 ~30 dark_oak_door 3  
fill ~70 ~5 ~20 ~70 ~6 ~20 planks 1  
fill ~70 ~5 ~30 ~70 ~6 ~30 planks 1  
fill ~70 ~5 ~31 ~70 ~6 ~31 bed 0  
fill ~71 ~5 ~16 ~71 ~6 ~16 bookshelf 0  
fill ~71 ~5 ~17 ~71 ~6 ~17 chest 4  
fill ~71 ~5 ~20 ~72 ~5 ~20 planks 0  
fill ~71 ~5 ~30 ~72 ~5 ~30 planks 0  
fill ~71 ~5 ~31 ~71 ~6 ~31 bed 8  
fill ~71 ~5 ~32 ~71 ~6 ~32 chest 4  
fill ~71 ~5 ~33 ~71 ~6 ~33 bookshelf 0  
fill ~71 ~5 ~34 ~71 ~6 ~34 bookshelf 0  
fill ~72 ~5 ~16 ~72 ~7 ~16 planks 5  
fill ~72 ~5 ~17 ~72 ~6 ~17 planks 0  
fill ~72 ~5 ~18 ~72 ~6 ~18 planks 0  
fill ~72 ~5 ~19 ~72 ~6 ~19 planks 0  
fill ~72 ~5 ~31 ~72 ~8 ~31 planks 0  
fill ~72 ~5 ~32 ~72 ~8 ~32 planks 0  
fill ~72 ~5 ~33 ~72 ~8 ~33 planks 0  
fill ~72 ~5 ~34 ~72 ~7 ~34 planks 5 
setblock ~73 ~5 ~17 dispenser 0 
setblock ~73 ~5 ~18 glass 0 
setblock ~73 ~5 ~19 dispenser 0  
fill ~73 ~5 ~20 ~73 ~6 ~20 planks 1  
fill ~73 ~5 ~30 ~73 ~6 ~30 planks 1 
setblock ~73 ~5 ~31 dispenser 0 
setblock ~73 ~5 ~32 glass 0 
setblock ~73 ~5 ~33 dispenser 0 
setblock ~74 ~5 ~20 dark_oak_door 1 
setblock ~74 ~5 ~30 dark_oak_door 3  
fill ~75 ~5 ~16 ~76 ~5 ~16 bookshelf 0  
fill ~75 ~5 ~20 ~75 ~6 ~20 planks 1  
fill ~75 ~5 ~30 ~75 ~6 ~30 planks 1  
fill ~75 ~5 ~34 ~76 ~5 ~34 bookshelf 0  
fill ~76 ~5 ~17 ~76 ~6 ~17 chest 4  
fill ~76 ~5 ~20 ~76 ~6 ~20 planks 0  
fill ~76 ~5 ~30 ~76 ~6 ~30 planks 0  
fill ~76 ~5 ~33 ~76 ~6 ~33 chest 4  
fill ~77 ~5 ~16 ~77 ~7 ~16 planks 5  
fill ~77 ~5 ~17 ~77 ~6 ~17 planks 0  
fill ~77 ~5 ~18 ~77 ~6 ~18 planks 0  
fill ~77 ~5 ~19 ~77 ~6 ~19 planks 0  
fill ~77 ~5 ~20 ~77 ~7 ~20 planks 5  
fill ~77 ~5 ~30 ~77 ~7 ~30 planks 5  
fill ~77 ~5 ~31 ~77 ~6 ~31 planks 0  
fill ~77 ~5 ~32 ~77 ~6 ~32 planks 0  
fill ~77 ~5 ~33 ~77 ~6 ~33 planks 0  
fill ~77 ~5 ~34 ~77 ~7 ~34 planks 5  
fill ~78 ~5 ~19 ~79 ~5 ~19 fence 1  
fill ~78 ~5 ~31 ~79 ~5 ~31 fence 1  
fill ~79 ~5 ~21 ~82 ~5 ~21 fence 0 
setblock ~79 ~5 ~22 dark_oak_stairs 0  
fill ~79 ~5 ~23 ~82 ~5 ~23 fence 0  
fill ~79 ~5 ~27 ~82 ~5 ~27 fence 0 
setblock ~79 ~5 ~28 dark_oak_stairs 0  
fill ~79 ~5 ~29 ~82 ~5 ~29 fence 0  
fill ~80 ~5 ~16 ~86 ~5 ~16 stained_hardened_clay 1 
setblock ~80 ~5 ~22 dark_oak_stairs 5  
fill ~80 ~5 ~24 ~80 ~7 ~24 fence 5 
setblock ~80 ~5 ~25 concrete 4  
fill ~80 ~5 ~26 ~80 ~7 ~26 fence 5 
setblock ~80 ~5 ~28 dark_oak_stairs 5  
fill ~80 ~5 ~34 ~86 ~5 ~34 stained_hardened_clay 1  
fill ~81 ~5 ~19 ~81 ~7 ~19 fence 1  
fill ~81 ~5 ~31 ~81 ~7 ~31 fence 1  
fill ~82 ~5 ~17 ~82 ~7 ~17 fence 1  
fill ~82 ~5 ~18 ~82 ~7 ~18 fence 1  
fill ~82 ~5 ~19 ~82 ~7 ~19 planks 5  
fill ~82 ~5 ~22 ~82 ~6 ~22 fence 1  
fill ~82 ~5 ~28 ~82 ~6 ~28 fence 1  
fill ~82 ~5 ~31 ~82 ~7 ~31 planks 5  
fill ~82 ~5 ~32 ~82 ~7 ~32 fence 1  
fill ~82 ~5 ~33 ~82 ~7 ~33 fence 1  
fill ~83 ~5 ~17 ~86 ~5 ~17 wool 0  
fill ~83 ~5 ~18 ~84 ~5 ~18 wool 0  
fill ~83 ~5 ~19 ~84 ~5 ~19 fence 1  
fill ~83 ~5 ~31 ~84 ~5 ~31 fence 1  
fill ~83 ~5 ~32 ~84 ~5 ~32 wool 0  
fill ~83 ~5 ~33 ~86 ~5 ~33 wool 0  
fill ~85 ~5 ~23 ~89 ~5 ~23 fence 5  
fill ~85 ~5 ~24 ~85 ~5 ~27 fence 5  
fill ~86 ~5 ~18 ~86 ~6 ~18 wool 0  
fill ~86 ~5 ~19 ~86 ~7 ~19 fence 1  
fill ~86 ~5 ~27 ~89 ~5 ~27 fence 5  
fill ~86 ~5 ~31 ~86 ~7 ~31 fence 1  
fill ~86 ~5 ~32 ~86 ~6 ~32 wool 0  
fill ~87 ~5 ~17 ~92 ~5 ~17 stained_hardened_clay 1  
fill ~87 ~5 ~18 ~87 ~7 ~18 fence 1  
fill ~87 ~5 ~19 ~87 ~7 ~19 planks 5  
fill ~87 ~5 ~31 ~87 ~7 ~31 planks 5  
fill ~87 ~5 ~32 ~87 ~7 ~32 fence 1  
fill ~87 ~5 ~33 ~92 ~5 ~33 stained_hardened_clay 1  
fill ~89 ~5 ~24 ~89 ~5 ~27 fence 5  
fill ~92 ~5 ~18 ~92 ~7 ~18 planks 5  
fill ~92 ~5 ~32 ~92 ~7 ~32 planks 5  
fill ~93 ~5 ~18 ~94 ~5 ~18 stained_hardened_clay 1  
fill ~93 ~5 ~19 ~96 ~5 ~19 stained_hardened_clay 1  
fill ~93 ~5 ~20 ~93 ~6 ~20 stained_hardened_clay 1  
fill ~93 ~5 ~21 ~93 ~6 ~21 stained_hardened_clay 1  
fill ~93 ~5 ~22 ~93 ~6 ~22 stained_hardened_clay 1  
fill ~93 ~5 ~23 ~93 ~6 ~23 stained_hardened_clay 1  
fill ~93 ~5 ~24 ~93 ~6 ~24 planks 5 
setblock ~93 ~5 ~25 spruce_door 0  
fill ~93 ~5 ~26 ~93 ~6 ~26 planks 5  
fill ~93 ~5 ~27 ~93 ~6 ~27 stained_hardened_clay 1  
fill ~93 ~5 ~28 ~93 ~6 ~28 stained_hardened_clay 1  
fill ~93 ~5 ~29 ~93 ~6 ~29 stained_hardened_clay 1  
fill ~93 ~5 ~30 ~93 ~6 ~30 stained_hardened_clay 1  
fill ~93 ~5 ~31 ~96 ~5 ~31 stained_hardened_clay 1  
fill ~93 ~5 ~32 ~94 ~5 ~32 stained_hardened_clay 1 
setblock ~94 ~5 ~23 iron_door 3 
setblock ~94 ~5 ~27 iron_door 1  
fill ~95 ~5 ~23 ~95 ~7 ~23 planks 5  
fill ~95 ~5 ~27 ~95 ~7 ~27 planks 5  
fill ~96 ~5 ~23 ~99 ~5 ~23 iron_bars 0  
fill ~96 ~5 ~27 ~99 ~5 ~27 iron_bars 0  
fill ~97 ~5 ~20 ~98 ~5 ~20 stained_hardened_clay 1  
fill ~97 ~5 ~21 ~97 ~7 ~21 planks 5  
fill ~97 ~5 ~29 ~97 ~7 ~29 planks 5  
fill ~97 ~5 ~30 ~98 ~5 ~30 stained_hardened_clay 1  
fill ~99 ~5 ~21 ~99 ~6 ~21 stained_hardened_clay 1  
fill ~99 ~5 ~24 ~99 ~7 ~24 fence 5  
fill ~99 ~5 ~26 ~99 ~7 ~26 fence 5  
fill ~99 ~5 ~29 ~99 ~6 ~29 stained_hardened_clay 1  
fill ~100 ~5 ~22 ~100 ~6 ~22 stained_hardened_clay 1  
fill ~100 ~5 ~23 ~100 ~7 ~23 planks 5  
fill ~100 ~5 ~27 ~100 ~7 ~27 planks 5  
fill ~100 ~5 ~28 ~100 ~6 ~28 stained_hardened_clay 1  
fill ~101 ~5 ~23 ~101 ~6 ~23 stained_hardened_clay 1  
fill ~101 ~5 ~27 ~101 ~6 ~27 stained_hardened_clay 1  
fill ~102 ~5 ~24 ~102 ~6 ~24 stained_hardened_clay 1  
fill ~102 ~5 ~25 ~102 ~4 ~25 stained_hardened_clay 1  
fill ~102 ~5 ~26 ~102 ~6 ~26 stained_hardened_clay 1 
setblock ~103 ~5 ~25 planks 1 
setblock ~104 ~5 ~25 fence 5 
setblock ~105 ~5 ~25 planks 1  
fill ~38 ~6 ~25 ~40 ~6 ~25 stained_hardened_clay 1 
setblock ~41 ~6 ~21 stained_hardened_clay 1  
fill ~41 ~6 ~26 ~41 ~6 ~27 furnace 5 
setblock ~41 ~6 ~29 stained_hardened_clay 1 
setblock ~42 ~6 ~20 stained_hardened_clay 1 
setblock ~42 ~6 ~30 stained_hardened_clay 1  
fill ~43 ~6 ~19 ~45 ~6 ~19 stained_hardened_clay 1  
fill ~43 ~6 ~21 ~44 ~6 ~21 bookshelf 0 
setblock ~43 ~6 ~28 spruce_door 8  
fill ~43 ~6 ~29 ~44 ~6 ~29 skull 1  
fill ~43 ~6 ~31 ~45 ~6 ~31 stained_hardened_clay 1  
fill ~44 ~6 ~20 ~45 ~6 ~20 planks 5 
setblock ~44 ~6 ~28 spruce_door 9  
fill ~44 ~6 ~30 ~45 ~6 ~30 planks 5  
fill ~45 ~6 ~18 ~48 ~6 ~18 stained_hardened_clay 1  
fill ~45 ~6 ~24 ~45 ~6 ~25 stained_hardened_clay 1 
setblock ~45 ~6 ~27 spruce_door 8  
fill ~45 ~6 ~32 ~48 ~6 ~32 stained_hardened_clay 1  
fill ~46 ~6 ~19 ~47 ~6 ~19 chest 3  
fill ~46 ~6 ~22 ~46 ~6 ~23 trapdoor 15  
fill ~46 ~6 ~31 ~47 ~6 ~31 chest 2  
fill ~48 ~6 ~17 ~50 ~6 ~17 stained_hardened_clay 1 
setblock ~48 ~6 ~22 spruce_door 8 
setblock ~48 ~6 ~28 spruce_door 9  
fill ~48 ~6 ~33 ~51 ~6 ~33 stained_hardened_clay 1  
fill ~49 ~6 ~19 ~49 ~5 ~19 pumpkin 3  
fill ~49 ~6 ~30 ~50 ~6 ~30 melon_block 0  
fill ~49 ~6 ~31 ~53 ~6 ~31 melon_block 0 
setblock ~50 ~6 ~18 pumpkin 0 
setblock ~50 ~6 ~19 pumpkin 2  
fill ~50 ~6 ~32 ~53 ~6 ~32 melon_block 0  
fill ~51 ~6 ~16 ~56 ~6 ~16 stained_hardened_clay 1  
fill ~51 ~6 ~17 ~51 ~7 ~17 pumpkin 2  
fill ~51 ~6 ~23 ~51 ~7 ~23 fence 5  
fill ~51 ~6 ~27 ~51 ~7 ~27 fence 5  
fill ~51 ~6 ~34 ~56 ~6 ~34 stained_hardened_clay 1  
fill ~52 ~6 ~17 ~52 ~7 ~17 pumpkin 0  
fill ~52 ~6 ~18 ~53 ~6 ~18 pumpkin 2  
fill ~52 ~6 ~19 ~53 ~6 ~19 pumpkin 2  
fill ~52 ~6 ~21 ~53 ~6 ~21 fence 1  
fill ~52 ~6 ~29 ~53 ~6 ~29 fence 1  
fill ~52 ~6 ~33 ~53 ~6 ~33 melon_block 0  
fill ~53 ~6 ~17 ~53 ~7 ~17 pumpkin 1 
setblock ~53 ~6 ~20 pumpkin 2 
setblock ~53 ~6 ~30 melon_block 0  
fill ~56 ~6 ~15 ~80 ~6 ~15 stained_hardened_clay 1 
setblock ~56 ~6 ~20 dark_oak_door 9  
fill ~56 ~6 ~23 ~56 ~7 ~23 fence 5  
fill ~56 ~6 ~27 ~56 ~7 ~27 fence 5 
setblock ~56 ~6 ~30 dark_oak_door 8  
fill ~56 ~6 ~35 ~80 ~6 ~35 stained_hardened_clay 1 
setblock ~60 ~6 ~20 dark_oak_door 9 
setblock ~60 ~6 ~30 dark_oak_door 8 
setblock ~64 ~6 ~20 dark_oak_door 8 
setblock ~64 ~6 ~30 dark_oak_door 8  
fill ~66 ~6 ~20 ~67 ~6 ~20 planks 0  
fill ~66 ~6 ~30 ~67 ~6 ~30 planks 0 
setblock ~69 ~6 ~20 dark_oak_door 8 
setblock ~69 ~6 ~30 dark_oak_door 8  
fill ~71 ~6 ~20 ~72 ~6 ~20 planks 0  
fill ~71 ~6 ~30 ~72 ~6 ~30 planks 0 
setblock ~74 ~6 ~20 dark_oak_door 8 
setblock ~74 ~6 ~30 dark_oak_door 8  
fill ~75 ~6 ~16 ~76 ~6 ~16 bookshelf 0  
fill ~75 ~6 ~34 ~76 ~6 ~34 bookshelf 0  
fill ~78 ~6 ~16 ~80 ~6 ~16 dropper 9  
fill ~78 ~6 ~17 ~78 ~6 ~18 dropper 9  
fill ~78 ~6 ~19 ~79 ~6 ~19 fence 1  
fill ~78 ~6 ~31 ~79 ~6 ~31 fence 1  
fill ~78 ~6 ~32 ~78 ~6 ~34 dropper 9  
fill ~79 ~6 ~34 ~80 ~6 ~34 dropper 9  
fill ~80 ~6 ~21 ~82 ~6 ~21 fence 0 
setblock ~80 ~6 ~22 dark_oak_stairs 0  
fill ~80 ~6 ~23 ~82 ~6 ~23 fence 0 
setblock ~80 ~6 ~25 coal_block 0  
fill ~80 ~6 ~27 ~82 ~6 ~27 fence 0 
setblock ~80 ~6 ~28 dark_oak_stairs 0  
fill ~80 ~6 ~29 ~82 ~6 ~29 fence 0  
fill ~81 ~6 ~16 ~87 ~6 ~16 stained_hardened_clay 1 
setblock ~81 ~6 ~22 dark_oak_stairs 5 
setblock ~81 ~6 ~28 dark_oak_stairs 5  
fill ~81 ~6 ~34 ~87 ~6 ~34 stained_hardened_clay 1  
fill ~83 ~6 ~17 ~86 ~6 ~17 wool 0  
fill ~83 ~6 ~18 ~83 ~7 ~18 wool 0  
fill ~83 ~6 ~19 ~84 ~6 ~19 fence 1  
fill ~83 ~6 ~31 ~84 ~6 ~31 fence 1  
fill ~83 ~6 ~32 ~83 ~7 ~32 wool 0  
fill ~83 ~6 ~33 ~86 ~6 ~33 wool 0  
fill ~85 ~6 ~23 ~85 ~7 ~23 fence 5  
fill ~85 ~6 ~27 ~85 ~7 ~27 fence 5  
fill ~87 ~6 ~17 ~87 ~7 ~17 planks 5  
fill ~87 ~6 ~33 ~87 ~7 ~33 planks 5  
fill ~88 ~6 ~17 ~93 ~6 ~17 stained_hardened_clay 1  
fill ~88 ~6 ~33 ~93 ~6 ~33 stained_hardened_clay 1  
fill ~89 ~6 ~23 ~89 ~7 ~23 fence 5  
fill ~89 ~6 ~27 ~89 ~7 ~27 fence 5  
fill ~93 ~6 ~18 ~96 ~6 ~18 stained_hardened_clay 1  
fill ~93 ~6 ~19 ~98 ~6 ~19 stained_hardened_clay 1 
setblock ~93 ~6 ~25 spruce_door 8  
fill ~93 ~6 ~31 ~98 ~6 ~31 stained_hardened_clay 1  
fill ~93 ~6 ~32 ~96 ~6 ~32 stained_hardened_clay 1 
setblock ~94 ~6 ~23 iron_door 8 
setblock ~94 ~6 ~27 iron_door 8  
fill ~96 ~6 ~23 ~99 ~6 ~23 iron_bars 0  
fill ~96 ~6 ~27 ~99 ~6 ~27 iron_bars 0  
fill ~97 ~6 ~20 ~99 ~6 ~20 stained_hardened_clay 1  
fill ~97 ~6 ~30 ~99 ~6 ~30 stained_hardened_clay 1 
setblock ~99 ~6 ~25 concrete 15 
setblock ~100 ~6 ~21 stained_hardened_clay 1 
setblock ~100 ~6 ~29 stained_hardened_clay 1 
setblock ~101 ~6 ~22 stained_hardened_clay 1 
setblock ~101 ~6 ~28 stained_hardened_clay 1 
setblock ~102 ~6 ~23 stained_hardened_clay 1 
setblock ~102 ~6 ~27 stained_hardened_clay 1  
fill ~103 ~6 ~24 ~103 ~6 ~26 stained_hardened_clay 1 
setblock ~105 ~6 ~25 double_stone_slab 0 
setblock ~106 ~6 ~25 stone_slab 0  
fill ~37 ~7 ~25 ~40 ~7 ~25 concrete 15  
fill ~40 ~7 ~23 ~40 ~8 ~23 concrete 15  
fill ~40 ~7 ~24 ~40 ~8 ~24 concrete 15  
fill ~40 ~7 ~26 ~40 ~8 ~26 concrete 15  
fill ~40 ~7 ~27 ~40 ~8 ~27 concrete 15  
fill ~41 ~7 ~21 ~42 ~7 ~21 concrete 15  
fill ~41 ~7 ~22 ~41 ~8 ~22 concrete 15  
fill ~41 ~7 ~26 ~41 ~7 ~27 cobblestone_wall 0  
fill ~41 ~7 ~28 ~41 ~8 ~28 concrete 15  
fill ~41 ~7 ~29 ~42 ~7 ~29 concrete 15  
fill ~42 ~7 ~20 ~43 ~7 ~20 concrete 15 
setblock ~42 ~7 ~22 torch 3 
setblock ~42 ~7 ~28 torch 4  
fill ~42 ~7 ~30 ~43 ~7 ~30 concrete 15  
fill ~43 ~7 ~19 ~45 ~7 ~19 concrete 15  
fill ~43 ~7 ~21 ~44 ~7 ~21 bookshelf 0  
fill ~43 ~7 ~29 ~44 ~7 ~29 dropper 0  
fill ~43 ~7 ~31 ~45 ~7 ~31 concrete 15  
fill ~44 ~7 ~18 ~48 ~7 ~18 concrete 15  
fill ~44 ~7 ~20 ~45 ~7 ~20 planks 5  
fill ~44 ~7 ~30 ~45 ~7 ~30 planks 5  
fill ~44 ~7 ~32 ~48 ~7 ~32 concrete 15  
fill ~45 ~7 ~21 ~45 ~7 ~29 concrete 15 
setblock ~46 ~7 ~19 torch 1 
setblock ~46 ~7 ~31 torch 1  
fill ~47 ~7 ~17 ~50 ~7 ~17 concrete 15 
setblock ~47 ~7 ~25 torch 2  
fill ~47 ~7 ~33 ~51 ~7 ~33 concrete 15  
fill ~48 ~7 ~19 ~48 ~7 ~22 concrete 15 
setblock ~48 ~7 ~25 concrete 15  
fill ~48 ~7 ~28 ~48 ~7 ~33 concrete 15 
setblock ~49 ~7 ~19 pumpkin 1 
setblock ~49 ~7 ~25 torch 1  
fill ~49 ~7 ~30 ~49 ~5 ~30 melon_block 0  
fill ~49 ~7 ~31 ~50 ~7 ~31 melon_block 0  
fill ~50 ~7 ~16 ~56 ~7 ~16 concrete 15 
setblock ~50 ~7 ~18 pumpkin 1  
fill ~50 ~7 ~32 ~51 ~7 ~32 melon_block 0  
fill ~50 ~7 ~34 ~56 ~7 ~34 concrete 15  
fill ~51 ~7 ~21 ~53 ~7 ~21 fence 1  
fill ~51 ~7 ~29 ~53 ~7 ~29 fence 1 
setblock ~52 ~7 ~18 pumpkin 0  
fill ~52 ~7 ~19 ~53 ~7 ~19 pumpkin 2  
fill ~52 ~7 ~33 ~53 ~7 ~33 melon_block 0 
setblock ~53 ~7 ~18 pumpkin 2  
fill ~53 ~7 ~31 ~53 ~7 ~33 melon_block 0  
fill ~54 ~7 ~18 ~54 ~7 ~20 concrete 15 
setblock ~54 ~7 ~30 planks 5  
fill ~54 ~7 ~31 ~54 ~7 ~32 concrete 15  
fill ~55 ~7 ~15 ~81 ~7 ~15 concrete 15 
setblock ~55 ~7 ~17 torch 1  
fill ~55 ~7 ~20 ~76 ~7 ~20 concrete 15 
setblock ~55 ~7 ~21 torch 1 
setblock ~55 ~7 ~29 torch 1  
fill ~55 ~7 ~30 ~76 ~7 ~30 concrete 15 
setblock ~55 ~7 ~33 torch 1  
fill ~55 ~7 ~35 ~81 ~7 ~35 concrete 15  
fill ~58 ~7 ~16 ~58 ~7 ~20 concrete 15  
fill ~58 ~7 ~31 ~58 ~7 ~35 concrete 15 
setblock ~59 ~7 ~16 torch 1 
setblock ~59 ~7 ~34 torch 1 
setblock ~61 ~7 ~16 torch 2 
setblock ~61 ~7 ~23 torch 3 
setblock ~61 ~7 ~27 torch 4 
setblock ~61 ~7 ~34 torch 2  
fill ~62 ~7 ~17 ~62 ~7 ~20 concrete 15 
setblock ~62 ~7 ~22 torch 1 
setblock ~62 ~7 ~28 torch 1  
fill ~62 ~7 ~31 ~62 ~7 ~35 concrete 15 
setblock ~63 ~7 ~16 torch 1 
setblock ~63 ~7 ~34 torch 1 
setblock ~66 ~7 ~16 torch 2 
setblock ~66 ~7 ~34 torch 2  
fill ~67 ~7 ~17 ~67 ~7 ~20 concrete 15 
setblock ~68 ~7 ~16 torch 1 
setblock ~68 ~7 ~34 torch 1 
setblock ~71 ~7 ~16 torch 2 
setblock ~71 ~7 ~34 torch 2  
fill ~72 ~7 ~17 ~72 ~7 ~20 concrete 15 
setblock ~72 ~7 ~22 torch 2 
setblock ~72 ~7 ~28 torch 2 
setblock ~73 ~7 ~16 torch 1 
setblock ~73 ~7 ~23 torch 3 
setblock ~73 ~7 ~27 torch 4 
setblock ~73 ~7 ~34 torch 1 
setblock ~76 ~7 ~16 torch 2 
setblock ~76 ~7 ~34 torch 2  
fill ~77 ~7 ~17 ~77 ~7 ~19 concrete 15 
setblock ~77 ~7 ~21 torch 3 
setblock ~77 ~7 ~29 torch 4  
fill ~77 ~7 ~31 ~77 ~7 ~33 concrete 15  
fill ~78 ~7 ~16 ~81 ~7 ~16 skull 1  
fill ~78 ~7 ~17 ~78 ~7 ~18 skull 1  
fill ~78 ~7 ~19 ~81 ~7 ~19 fence 1 
setblock ~78 ~7 ~20 torch 1 
setblock ~78 ~7 ~30 torch 1  
fill ~78 ~7 ~31 ~81 ~7 ~31 fence 1  
fill ~78 ~7 ~32 ~78 ~7 ~34 skull 1 
setblock ~79 ~7 ~25 torch 2  
fill ~79 ~7 ~34 ~81 ~7 ~34 skull 1  
fill ~80 ~7 ~25 ~80 ~8 ~25 concrete 4  
fill ~81 ~7 ~21 ~82 ~7 ~21 fence 0 
setblock ~81 ~7 ~22 dark_oak_stairs 0  
fill ~81 ~7 ~23 ~82 ~7 ~23 fence 0 
setblock ~81 ~7 ~25 torch 1  
fill ~81 ~7 ~27 ~82 ~7 ~27 fence 0 
setblock ~81 ~7 ~28 dark_oak_stairs 0  
fill ~81 ~7 ~29 ~82 ~7 ~29 fence 0  
fill ~82 ~7 ~16 ~88 ~7 ~16 concrete 15 
setblock ~82 ~7 ~22 dark_oak_stairs 5 
setblock ~82 ~7 ~28 dark_oak_stairs 5  
fill ~82 ~7 ~34 ~88 ~7 ~34 concrete 15  
fill ~83 ~7 ~17 ~85 ~7 ~17 wool 0  
fill ~83 ~7 ~19 ~86 ~7 ~19 fence 1  
fill ~83 ~7 ~31 ~86 ~7 ~31 fence 1  
fill ~83 ~7 ~33 ~85 ~7 ~33 wool 0 
setblock ~86 ~7 ~17 torch 2 
setblock ~86 ~7 ~33 torch 2  
fill ~88 ~7 ~17 ~94 ~7 ~17 concrete 15  
fill ~88 ~7 ~33 ~94 ~7 ~33 concrete 15 
setblock ~92 ~7 ~19 torch 3 
setblock ~92 ~7 ~31 torch 4  
fill ~93 ~7 ~18 ~97 ~7 ~18 concrete 15  
fill ~93 ~7 ~19 ~100 ~7 ~19 concrete 15  
fill ~93 ~7 ~20 ~93 ~7 ~33 concrete 15 
setblock ~94 ~7 ~23 planks 5 
setblock ~94 ~7 ~27 planks 5  
fill ~94 ~7 ~31 ~100 ~7 ~31 concrete 15  
fill ~94 ~7 ~32 ~97 ~7 ~32 concrete 15 
setblock ~95 ~7 ~20 torch 3 
setblock ~95 ~7 ~30 torch 4  
fill ~96 ~7 ~23 ~99 ~7 ~23 iron_bars 0  
fill ~96 ~7 ~27 ~99 ~7 ~27 iron_bars 0  
fill ~97 ~7 ~20 ~98 ~7 ~20 concrete 15  
fill ~97 ~7 ~30 ~98 ~7 ~30 concrete 15 
setblock ~98 ~7 ~25 torch 2  
fill ~99 ~7 ~20 ~100 ~7 ~20 stained_hardened_clay 1  
fill ~99 ~7 ~21 ~100 ~7 ~21 concrete 15  
fill ~99 ~7 ~25 ~99 ~8 ~25 concrete 4  
fill ~99 ~7 ~29 ~100 ~7 ~29 concrete 15  
fill ~99 ~7 ~30 ~100 ~7 ~30 stained_hardened_clay 1  
fill ~100 ~7 ~22 ~101 ~7 ~22 concrete 15 
setblock ~100 ~7 ~25 torch 1  
fill ~100 ~7 ~28 ~101 ~7 ~28 concrete 15  
fill ~101 ~7 ~20 ~102 ~7 ~20 concrete 15  
fill ~101 ~7 ~21 ~102 ~7 ~21 stained_hardened_clay 1  
fill ~101 ~7 ~23 ~102 ~7 ~23 concrete 15  
fill ~101 ~7 ~27 ~102 ~7 ~27 concrete 15  
fill ~101 ~7 ~29 ~102 ~7 ~29 stained_hardened_clay 1  
fill ~101 ~7 ~30 ~102 ~7 ~30 concrete 15  
fill ~102 ~7 ~22 ~103 ~7 ~22 stained_hardened_clay 1  
fill ~102 ~7 ~24 ~105 ~7 ~24 concrete 15  
fill ~102 ~7 ~26 ~105 ~7 ~26 concrete 15  
fill ~102 ~7 ~28 ~103 ~7 ~28 stained_hardened_clay 1 
setblock ~103 ~7 ~21 concrete 15 
setblock ~103 ~7 ~23 stained_hardened_clay 1  
fill ~103 ~7 ~25 ~105 ~7 ~25 concrete 15 
setblock ~103 ~7 ~27 stained_hardened_clay 1 
setblock ~103 ~7 ~29 concrete 15  
fill ~104 ~7 ~22 ~104 ~7 ~28 concrete 15 
setblock ~105 ~7 ~23 concrete 15 
setblock ~105 ~7 ~27 concrete 15 
setblock ~106 ~7 ~23 dropper 0 
setblock ~106 ~7 ~27 dropper 0  
fill ~36 ~8 ~25 ~39 ~8 ~25 concrete 15  
fill ~40 ~8 ~25 ~46 ~8 ~25 planks 0  
fill ~41 ~8 ~21 ~41 ~7 ~21 concrete 15  
fill ~41 ~8 ~23 ~50 ~8 ~23 planks 0  
fill ~41 ~8 ~24 ~46 ~8 ~24 planks 0  
fill ~41 ~8 ~26 ~46 ~8 ~26 planks 0  
fill ~41 ~8 ~27 ~50 ~8 ~27 planks 0  
fill ~41 ~8 ~29 ~41 ~7 ~29 concrete 15  
fill ~42 ~8 ~19 ~43 ~8 ~19 concrete 15  
fill ~42 ~8 ~20 ~42 ~7 ~20 concrete 15  
fill ~42 ~8 ~21 ~103 ~8 ~21 planks 0  
fill ~42 ~8 ~22 ~60 ~8 ~22 planks 0  
fill ~42 ~8 ~28 ~60 ~8 ~28 planks 0  
fill ~42 ~8 ~29 ~103 ~8 ~29 planks 0
fill ~42 ~8 ~30 ~42 ~7 ~30 concrete 15  
fill ~42 ~8 ~31 ~43 ~8 ~31 concrete 15  
fill ~43 ~8 ~20 ~100 ~8 ~20 planks 0  
fill ~43 ~8 ~30 ~100 ~8 ~30 planks 0  
fill ~44 ~8 ~18 ~46 ~8 ~18 concrete 15  
fill ~44 ~8 ~19 ~97 ~8 ~19 planks 0  
fill ~44 ~8 ~31 ~97 ~8 ~31 planks 0  
fill ~44 ~8 ~32 ~46 ~8 ~32 concrete 15  
fill ~47 ~8 ~17 ~49 ~8 ~17 concrete 15  
fill ~47 ~8 ~18 ~94 ~8 ~18 planks 0  
fill ~47 ~8 ~24 ~49 ~8 ~24 planks 1  
fill ~47 ~8 ~25 ~47 ~8 ~26 planks 1  
fill ~47 ~8 ~32 ~94 ~8 ~32 planks 0  
fill ~47 ~8 ~33 ~49 ~8 ~33 concrete 15  
fill ~48 ~8 ~25 ~48 ~9 ~25 concrete 4  
fill ~48 ~8 ~26 ~49 ~8 ~26 planks 1 
setblock ~49 ~8 ~25 planks 1  
fill ~50 ~8 ~16 ~54 ~8 ~16 concrete 15  
fill ~50 ~8 ~17 ~88 ~8 ~17 planks 0  
fill ~50 ~8 ~24 ~50 ~8 ~33 planks 0  
fill ~50 ~8 ~34 ~54 ~8 ~34 concrete 15  
fill ~51 ~8 ~23 ~56 ~8 ~23 planks 1  
fill ~51 ~8 ~24 ~51 ~8 ~27 planks 1  
fill ~51 ~8 ~33 ~88 ~8 ~33 planks 0  
fill ~52 ~8 ~27 ~56 ~8 ~27 planks 1  
fill ~55 ~8 ~15 ~81 ~8 ~15 concrete 15  
fill ~55 ~8 ~16 ~81 ~8 ~16 planks 0  
fill ~55 ~8 ~34 ~81 ~8 ~34 planks 0  
fill ~55 ~8 ~35 ~81 ~8 ~35 concrete 15  
fill ~56 ~8 ~24 ~56 ~8 ~27 planks 1  
fill ~57 ~8 ~23 ~61 ~8 ~23 planks 0  
fill ~57 ~8 ~24 ~61 ~8 ~24 planks 0  
fill ~57 ~8 ~25 ~61 ~8 ~25 planks 0  
fill ~57 ~8 ~26 ~61 ~8 ~26 planks 0  
fill ~57 ~8 ~27 ~61 ~8 ~27 planks 0  
fill ~62 ~8 ~22 ~72 ~8 ~22 planks 0  
fill ~62 ~8 ~23 ~63 ~8 ~23 trapdoor 11  
fill ~62 ~8 ~24 ~63 ~8 ~24 trapdoor 11  
fill ~62 ~8 ~25 ~63 ~8 ~25 trapdoor 11  
fill ~62 ~8 ~26 ~63 ~8 ~26 trapdoor 11  
fill ~62 ~8 ~27 ~65 ~8 ~27 trapdoor 8  
fill ~62 ~8 ~28 ~72 ~8 ~28 planks 0  
fill ~64 ~8 ~23 ~65 ~8 ~23 trapdoor 8  
fill ~64 ~8 ~24 ~65 ~8 ~24 trapdoor 8  
fill ~64 ~8 ~25 ~65 ~8 ~25 trapdoor 8  
fill ~64 ~8 ~26 ~65 ~8 ~26 trapdoor 8  
fill ~66 ~8 ~23 ~66 ~8 ~27 trapdoor 11  
fill ~67 ~8 ~23 ~67 ~8 ~27 dropper 9  
fill ~68 ~8 ~23 ~69 ~8 ~23 trapdoor 10  
fill ~68 ~8 ~24 ~70 ~8 ~24 trapdoor 10  
fill ~68 ~8 ~25 ~70 ~8 ~25 trapdoor 10  
fill ~68 ~8 ~26 ~70 ~8 ~26 trapdoor 10  
fill ~68 ~8 ~27 ~70 ~8 ~27 trapdoor 10  
fill ~70 ~8 ~23 ~71 ~8 ~23 trapdoor 11  
fill ~71 ~8 ~24 ~71 ~8 ~26 trapdoor 11 
setblock ~71 ~8 ~27 trapdoor 8  
fill ~72 ~8 ~23 ~72 ~8 ~27 trapdoor 10 
setblock ~73 ~8 ~22 log 9  
fill ~73 ~8 ~23 ~84 ~8 ~23 planks 0  
fill ~73 ~8 ~24 ~78 ~8 ~24 planks 0  
fill ~73 ~8 ~25 ~78 ~8 ~25 planks 0  
fill ~73 ~8 ~26 ~78 ~8 ~26 planks 0  
fill ~73 ~8 ~27 ~84 ~8 ~27 planks 0  
fill ~74 ~8 ~22 ~77 ~8 ~22 planks 0  
fill ~74 ~8 ~28 ~77 ~8 ~28 planks 0 
setblock ~78 ~8 ~22 oak_stairs 5 
setblock ~78 ~8 ~28 oak_stairs 5  
fill ~79 ~8 ~24 ~81 ~8 ~24 planks 1  
fill ~79 ~8 ~25 ~79 ~8 ~26 planks 1  
fill ~80 ~8 ~26 ~81 ~8 ~26 planks 1 
setblock ~81 ~8 ~25 planks 1  
fill ~82 ~8 ~16 ~88 ~8 ~16 concrete 15 
setblock ~82 ~8 ~22 dark_oak_stairs 0  
fill ~82 ~8 ~24 ~84 ~8 ~24 planks 0  
fill ~82 ~8 ~25 ~84 ~8 ~25 planks 0  
fill ~82 ~8 ~26 ~84 ~8 ~26 planks 0 
setblock ~82 ~8 ~28 dark_oak_stairs 0  
fill ~82 ~8 ~34 ~88 ~8 ~34 concrete 15  
fill ~83 ~8 ~22 ~104 ~8 ~22 planks 0  
fill ~83 ~8 ~28 ~104 ~8 ~28 planks 0  
fill ~85 ~8 ~23 ~89 ~8 ~23 planks 1  
fill ~85 ~8 ~24 ~85 ~8 ~27 planks 1  
fill ~86 ~8 ~27 ~89 ~8 ~27 planks 1  
fill ~89 ~8 ~17 ~94 ~8 ~17 concrete 15  
fill ~89 ~8 ~24 ~89 ~8 ~27 planks 1  
fill ~89 ~8 ~33 ~94 ~8 ~33 concrete 15  
fill ~90 ~8 ~23 ~101 ~8 ~23 planks 0  
fill ~90 ~8 ~24 ~97 ~8 ~24 planks 0  
fill ~90 ~8 ~25 ~97 ~8 ~25 planks 0  
fill ~90 ~8 ~26 ~97 ~8 ~26 planks 0  
fill ~90 ~8 ~27 ~101 ~8 ~27 planks 0  
fill ~95 ~8 ~18 ~97 ~8 ~18 concrete 15  
fill ~95 ~8 ~32 ~97 ~8 ~32 concrete 15  
fill ~98 ~8 ~19 ~100 ~8 ~19 concrete 15  
fill ~98 ~8 ~24 ~100 ~8 ~24 planks 1  
fill ~98 ~8 ~25 ~98 ~8 ~26 planks 1  
fill ~98 ~8 ~31 ~100 ~8 ~31 concrete 15  
fill ~99 ~8 ~26 ~100 ~8 ~26 planks 1 
setblock ~100 ~8 ~25 planks 1  
fill ~101 ~8 ~20 ~103 ~8 ~20 concrete 15  
fill ~101 ~8 ~24 ~104 ~8 ~24 planks 0  
fill ~101 ~8 ~25 ~104 ~8 ~25 planks 0  
fill ~101 ~8 ~26 ~104 ~8 ~26 planks 0  
fill ~101 ~8 ~30 ~103 ~8 ~30 concrete 15  
fill ~104 ~8 ~21 ~105 ~8 ~21 concrete 15 
setblock ~104 ~8 ~23 dispenser 5 
setblock ~104 ~8 ~27 dispenser 5  
fill ~104 ~8 ~29 ~105 ~8 ~29 concrete 15  
fill ~105 ~8 ~22 ~106 ~8 ~22 concrete 15  
fill ~105 ~8 ~24 ~106 ~8 ~24 concrete 15  
fill ~105 ~8 ~25 ~106 ~8 ~25 concrete 15  
fill ~105 ~8 ~26 ~106 ~8 ~26 concrete 15  
fill ~105 ~8 ~28 ~106 ~8 ~28 concrete 15 
setblock ~107 ~8 ~23 trapdoor 15  
fill ~107 ~8 ~24 ~107 ~8 ~26 wall_sign 5 
setblock ~107 ~8 ~27 trapdoor 15  
fill ~36 ~9 ~25 ~37 ~9 ~25 concrete 15  
fill ~38 ~9 ~24 ~39 ~9 ~24 gold_block 0  
fill ~38 ~9 ~26 ~39 ~9 ~26 gold_block 0 
setblock ~39 ~9 ~23 gold_block 0 
setblock ~39 ~9 ~25 concrete 4 
setblock ~39 ~9 ~27 gold_block 0  
fill ~40 ~9 ~22 ~41 ~9 ~22 wool 4  
fill ~40 ~9 ~23 ~40 ~9 ~22 wool 4  
fill ~40 ~9 ~27 ~40 ~9 ~28 wool 4  
fill ~41 ~9 ~20 ~42 ~9 ~20 wool 4  
fill ~41 ~9 ~21 ~41 ~9 ~20 wool 4  
fill ~41 ~9 ~28 ~41 ~9 ~30 wool 4 
setblock ~42 ~9 ~19 wool 4  
fill ~42 ~9 ~21 ~42 ~8 ~21 planks 0  
fill ~42 ~9 ~25 ~42 ~10 ~25 fence 0  
fill ~42 ~9 ~29 ~42 ~8 ~29 planks 0  
fill ~42 ~9 ~30 ~42 ~9 ~31 wool 4  
fill ~43 ~9 ~18 ~45 ~9 ~18 wool 4 
setblock ~43 ~9 ~19 skull 1 
setblock ~43 ~9 ~21 skull 1 
setblock ~43 ~9 ~23 fence 1 
setblock ~43 ~9 ~24 dark_oak_stairs 6 
setblock ~43 ~9 ~25 dark_oak_stairs 3 
setblock ~43 ~9 ~29 skull 1 
setblock ~43 ~9 ~31 skull 1  
fill ~43 ~9 ~32 ~45 ~9 ~32 wool 4  
fill ~44 ~9 ~19 ~44 ~9 ~21 planks 1 
setblock ~44 ~9 ~22 spruce_stairs 3  
fill ~44 ~9 ~25 ~44 ~10 ~25 fence 0 
setblock ~44 ~9 ~28 spruce_stairs 2  
fill ~44 ~9 ~29 ~44 ~9 ~31 planks 1 
setblock ~45 ~9 ~19 skull 1 
setblock ~45 ~9 ~21 skull 1 
setblock ~45 ~9 ~29 skull 1 
setblock ~45 ~9 ~31 skull 1  
fill ~46 ~9 ~17 ~48 ~9 ~17 wool 4  
fill ~46 ~9 ~33 ~48 ~9 ~33 wool 4 
setblock ~47 ~9 ~18 skull 1 
setblock ~47 ~9 ~20 skull 1 
setblock ~47 ~9 ~30 skull 1 
setblock ~47 ~9 ~32 skull 1  
fill ~48 ~9 ~18 ~48 ~9 ~20 planks 1 
setblock ~48 ~9 ~21 spruce_stairs 3  
fill ~48 ~9 ~24 ~48 ~10 ~24 fence 5  
fill ~48 ~9 ~26 ~48 ~10 ~26 fence 5 
setblock ~48 ~9 ~29 spruce_stairs 2  
fill ~48 ~9 ~30 ~48 ~9 ~32 planks 1  
fill ~49 ~9 ~16 ~53 ~9 ~16 wool 4  
fill ~49 ~9 ~17 ~49 ~10 ~17 concrete 4 
setblock ~49 ~9 ~18 skull 1 
setblock ~49 ~9 ~20 skull 1 
setblock ~49 ~9 ~25 skull 1 
setblock ~49 ~9 ~30 skull 1 
setblock ~49 ~9 ~32 skull 1  
fill ~49 ~9 ~33 ~49 ~10 ~33 concrete 4  
fill ~49 ~9 ~34 ~53 ~9 ~34 wool 4 
setblock ~51 ~9 ~17 skull 1 
setblock ~51 ~9 ~19 skull 1  
fill ~51 ~9 ~23 ~56 ~9 ~23 fence 5  
fill ~51 ~9 ~24 ~51 ~9 ~27 fence 5 
setblock ~51 ~9 ~31 skull 1 
setblock ~51 ~9 ~33 skull 1  
fill ~52 ~9 ~17 ~52 ~9 ~19 planks 1 
setblock ~52 ~9 ~20 spruce_stairs 3  
fill ~52 ~9 ~27 ~56 ~9 ~27 fence 5 
setblock ~52 ~9 ~30 spruce_stairs 2  
fill ~52 ~9 ~31 ~52 ~9 ~33 planks 1 
setblock ~53 ~9 ~17 skull 1 
setblock ~53 ~9 ~19 skull 1 
setblock ~53 ~9 ~31 skull 1 
setblock ~53 ~9 ~33 skull 1  
fill ~54 ~9 ~15 ~82 ~9 ~15 wool 4  
fill ~54 ~9 ~35 ~82 ~9 ~35 wool 4 
setblock ~55 ~9 ~16 skull 1 
setblock ~55 ~9 ~18 skull 1 
setblock ~55 ~9 ~32 skull 1 
setblock ~55 ~9 ~34 skull 1  
fill ~56 ~9 ~16 ~56 ~9 ~18 planks 1 
setblock ~56 ~9 ~19 spruce_stairs 3  
fill ~56 ~9 ~24 ~56 ~9 ~27 fence 5 
setblock ~56 ~9 ~31 spruce_stairs 2  
fill ~56 ~9 ~32 ~56 ~9 ~34 planks 1 
setblock ~57 ~9 ~16 skull 1 
setblock ~57 ~9 ~18 skull 1 
setblock ~57 ~9 ~32 skull 1 
setblock ~57 ~9 ~34 skull 1 
setblock ~59 ~9 ~16 skull 1 
setblock ~59 ~9 ~18 skull 1 
setblock ~59 ~9 ~32 skull 1 
setblock ~59 ~9 ~34 skull 1  
fill ~60 ~9 ~16 ~60 ~9 ~18 planks 1 
setblock ~60 ~9 ~19 spruce_stairs 3 
setblock ~60 ~9 ~31 spruce_stairs 2  
fill ~60 ~9 ~32 ~60 ~9 ~34 planks 1 
setblock ~61 ~9 ~16 skull 1 
setblock ~61 ~9 ~18 skull 1  
fill ~61 ~9 ~23 ~61 ~9 ~27 dropper 0 
setblock ~61 ~9 ~32 skull 1 
setblock ~61 ~9 ~34 skull 1  
fill ~62 ~9 ~22 ~72 ~9 ~22 dropper 0  
fill ~62 ~9 ~28 ~72 ~9 ~28 dropper 0 
setblock ~63 ~9 ~16 skull 1 
setblock ~63 ~9 ~18 skull 1 
setblock ~63 ~9 ~32 skull 1 
setblock ~63 ~9 ~34 skull 1  
fill ~64 ~9 ~16 ~64 ~9 ~18 planks 1 
setblock ~64 ~9 ~19 spruce_stairs 3 
setblock ~64 ~9 ~31 spruce_stairs 2  
fill ~64 ~9 ~32 ~64 ~9 ~34 planks 1 
setblock ~65 ~9 ~16 skull 1 
setblock ~65 ~9 ~18 skull 1 
setblock ~65 ~9 ~32 skull 1 
setblock ~65 ~9 ~34 skull 1 
setblock ~67 ~9 ~16 skull 1 
setblock ~67 ~9 ~18 skull 1 
setblock ~67 ~9 ~32 skull 1 
setblock ~67 ~9 ~34 skull 1  
fill ~68 ~9 ~16 ~68 ~9 ~18 planks 1 
setblock ~68 ~9 ~19 spruce_stairs 3 
setblock ~68 ~9 ~31 spruce_stairs 2  
fill ~68 ~9 ~32 ~68 ~9 ~34 planks 1 
setblock ~69 ~9 ~16 skull 1 
setblock ~69 ~9 ~18 skull 1 
setblock ~69 ~9 ~32 skull 1 
setblock ~69 ~9 ~34 skull 1 
setblock ~71 ~9 ~16 skull 1 
setblock ~71 ~9 ~18 skull 1 
setblock ~71 ~9 ~32 skull 1 
setblock ~71 ~9 ~34 skull 1  
fill ~72 ~9 ~16 ~72 ~9 ~18 planks 1 
setblock ~72 ~9 ~19 spruce_stairs 3 
setblock ~72 ~9 ~31 spruce_stairs 2  
fill ~72 ~9 ~32 ~72 ~9 ~34 planks 1 
setblock ~73 ~9 ~16 skull 1 
setblock ~73 ~9 ~18 skull 1  
fill ~73 ~9 ~22 ~73 ~13 ~22 log 1  
fill ~73 ~9 ~23 ~73 ~9 ~27 dropper 0 
setblock ~73 ~9 ~32 skull 1 
setblock ~73 ~9 ~34 skull 1  
fill ~75 ~9 ~14 ~75 ~13 ~14 ladder 2 
setblock ~75 ~9 ~16 skull 1 
setblock ~75 ~9 ~18 skull 1 
setblock ~75 ~9 ~32 skull 1 
setblock ~75 ~9 ~34 skull 1  
fill ~75 ~9 ~36 ~75 ~13 ~36 ladder 3  
fill ~76 ~9 ~16 ~76 ~9 ~18 planks 1 
setblock ~76 ~9 ~19 spruce_stairs 3 
setblock ~76 ~9 ~31 spruce_stairs 2  
fill ~76 ~9 ~32 ~76 ~9 ~34 planks 1 
setblock ~77 ~9 ~16 skull 1 
setblock ~77 ~9 ~18 skull 1 
setblock ~77 ~9 ~32 skull 1 
setblock ~77 ~9 ~34 skull 1  
fill ~78 ~9 ~21 ~82 ~9 ~21 fence 1  
fill ~78 ~9 ~22 ~78 ~9 ~23 fence 1  
fill ~78 ~9 ~27 ~82 ~9 ~27 fence 1  
fill ~78 ~9 ~28 ~78 ~9 ~29 fence 1 
setblock ~79 ~9 ~16 skull 1 
setblock ~79 ~9 ~18 skull 1  
fill ~79 ~9 ~23 ~82 ~9 ~23 fence 1 
setblock ~79 ~9 ~25 skull 1  
fill ~79 ~9 ~29 ~82 ~9 ~29 fence 1 
setblock ~79 ~9 ~32 skull 1 
setblock ~79 ~9 ~34 skull 1  
fill ~80 ~9 ~16 ~80 ~9 ~18 planks 1 
setblock ~80 ~9 ~19 spruce_stairs 3  
fill ~80 ~9 ~24 ~80 ~10 ~24 fence 5 
setblock ~80 ~9 ~25 coal_block 0  
fill ~80 ~9 ~26 ~80 ~10 ~26 fence 5 
setblock ~80 ~9 ~31 spruce_stairs 2  
fill ~80 ~9 ~32 ~80 ~9 ~34 planks 1 
setblock ~81 ~9 ~16 skull 1 
setblock ~81 ~9 ~18 skull 1 
setblock ~81 ~9 ~25 skull 1 
setblock ~81 ~9 ~32 skull 1 
setblock ~81 ~9 ~34 skull 1  
fill ~83 ~9 ~16 ~89 ~9 ~16 wool 4 
setblock ~83 ~9 ~17 skull 1 
setblock ~83 ~9 ~19 skull 1 
setblock ~83 ~9 ~31 skull 1 
setblock ~83 ~9 ~33 skull 1  
fill ~83 ~9 ~34 ~89 ~9 ~34 wool 4  
fill ~84 ~9 ~17 ~84 ~9 ~19 planks 1 
setblock ~84 ~9 ~20 spruce_stairs 3 
setblock ~84 ~9 ~30 spruce_stairs 2  
fill ~84 ~9 ~31 ~84 ~9 ~33 planks 1 
setblock ~85 ~9 ~17 skull 1 
setblock ~85 ~9 ~19 skull 1  
fill ~85 ~9 ~23 ~89 ~9 ~23 fence 5  
fill ~85 ~9 ~24 ~85 ~9 ~27 fence 5 
setblock ~85 ~9 ~31 skull 1 
setblock ~85 ~9 ~33 skull 1  
fill ~86 ~9 ~27 ~89 ~9 ~27 fence 5 
setblock ~87 ~9 ~17 skull 1 
setblock ~87 ~9 ~19 skull 1 
setblock ~87 ~9 ~31 skull 1 
setblock ~87 ~9 ~33 skull 1  
fill ~88 ~9 ~17 ~88 ~9 ~19 planks 1 
setblock ~88 ~9 ~20 spruce_stairs 3 
setblock ~88 ~9 ~30 spruce_stairs 2  
fill ~88 ~9 ~31 ~88 ~9 ~33 planks 1 
setblock ~89 ~9 ~17 skull 1 
setblock ~89 ~9 ~19 skull 1  
fill ~89 ~9 ~24 ~89 ~9 ~27 fence 5 
setblock ~89 ~9 ~31 skull 1 
setblock ~89 ~9 ~33 skull 1  
fill ~90 ~9 ~17 ~95 ~9 ~17 wool 4  
fill ~90 ~9 ~33 ~95 ~9 ~33 wool 4 
setblock ~91 ~9 ~18 skull 1 
setblock ~91 ~9 ~20 skull 1 
setblock ~91 ~9 ~25 fence 1 
setblock ~91 ~9 ~30 skull 1 
setblock ~91 ~9 ~32 skull 1  
fill ~92 ~9 ~18 ~92 ~9 ~20 planks 1 
setblock ~92 ~9 ~21 spruce_stairs 3 
setblock ~92 ~9 ~25 dark_oak_stairs 4 
setblock ~92 ~9 ~29 spruce_stairs 2  
fill ~92 ~9 ~30 ~92 ~9 ~32 planks 1 
setblock ~93 ~9 ~18 skull 1 
setblock ~93 ~9 ~20 skull 1  
fill ~93 ~9 ~24 ~93 ~10 ~24 fence 0 
setblock ~93 ~9 ~25 dark_oak_stairs 1  
fill ~93 ~9 ~26 ~93 ~10 ~26 fence 0 
setblock ~93 ~9 ~30 skull 1 
setblock ~93 ~9 ~32 skull 1  
fill ~95 ~9 ~18 ~95 ~10 ~18 concrete 4 
setblock ~95 ~9 ~19 skull 1 
setblock ~95 ~9 ~21 skull 1 
setblock ~95 ~9 ~29 skull 1 
setblock ~95 ~9 ~31 skull 1  
fill ~95 ~9 ~32 ~95 ~10 ~32 concrete 4  
fill ~96 ~9 ~18 ~98 ~9 ~18 wool 4  
fill ~96 ~9 ~19 ~96 ~9 ~21 planks 1 
setblock ~96 ~9 ~22 spruce_stairs 3 
setblock ~96 ~9 ~28 spruce_stairs 2  
fill ~96 ~9 ~29 ~96 ~9 ~31 planks 1  
fill ~96 ~9 ~32 ~98 ~9 ~32 wool 4 
setblock ~97 ~9 ~19 skull 1 
setblock ~97 ~9 ~21 skull 1 
setblock ~97 ~9 ~29 skull 1 
setblock ~97 ~9 ~31 skull 1 
setblock ~98 ~9 ~25 skull 1  
fill ~99 ~9 ~19 ~101 ~9 ~19 wool 4 
setblock ~99 ~9 ~20 skull 1 
setblock ~99 ~9 ~22 skull 1  
fill ~99 ~9 ~24 ~99 ~10 ~24 fence 5 
setblock ~99 ~9 ~25 concrete 15  
fill ~99 ~9 ~26 ~99 ~10 ~26 fence 5 
setblock ~99 ~9 ~28 skull 1 
setblock ~99 ~9 ~30 skull 1  
fill ~99 ~9 ~31 ~101 ~9 ~31 wool 4  
fill ~100 ~9 ~20 ~100 ~9 ~22 planks 1 
setblock ~100 ~9 ~23 spruce_stairs 3 
setblock ~100 ~9 ~27 spruce_stairs 2  
fill ~100 ~9 ~28 ~100 ~9 ~30 planks 1 
setblock ~101 ~9 ~20 skull 1 
setblock ~101 ~9 ~22 skull 1 
setblock ~101 ~9 ~28 skull 1 
setblock ~101 ~9 ~30 skull 1  
fill ~102 ~9 ~19 ~103 ~9 ~19 concrete 15  
fill ~102 ~9 ~20 ~102 ~12 ~20 log 1  
fill ~102 ~9 ~21 ~102 ~9 ~22 concrete 15  
fill ~102 ~9 ~23 ~102 ~13 ~23 log 1  
fill ~102 ~9 ~24 ~102 ~9 ~26 concrete 15  
fill ~102 ~9 ~27 ~102 ~13 ~27 log 1  
fill ~102 ~9 ~28 ~102 ~9 ~29 concrete 15  
fill ~102 ~9 ~30 ~102 ~12 ~30 log 1  
fill ~102 ~9 ~31 ~103 ~9 ~31 concrete 15  
fill ~103 ~9 ~20 ~103 ~10 ~20 planks 0  
fill ~103 ~9 ~21 ~105 ~9 ~21 planks 0  
fill ~103 ~9 ~22 ~105 ~9 ~22 planks 0  
fill ~103 ~9 ~23 ~105 ~9 ~23 planks 0  
fill ~103 ~9 ~24 ~105 ~9 ~24 planks 0  
fill ~103 ~9 ~25 ~105 ~9 ~25 planks 0  
fill ~103 ~9 ~26 ~105 ~9 ~26 planks 0  
fill ~103 ~9 ~27 ~105 ~9 ~27 planks 0  
fill ~103 ~9 ~28 ~105 ~9 ~28 planks 0  
fill ~103 ~9 ~29 ~105 ~9 ~29 planks 0  
fill ~103 ~9 ~30 ~103 ~10 ~30 planks 0  
fill ~104 ~9 ~19 ~105 ~9 ~19 dropper 0  
fill ~104 ~9 ~20 ~105 ~9 ~20 concrete 15  
fill ~104 ~9 ~30 ~105 ~9 ~30 concrete 15  
fill ~104 ~9 ~31 ~105 ~9 ~31 dropper 0 
setblock ~106 ~9 ~20 dropper 0  
fill ~106 ~9 ~21 ~106 ~9 ~29 concrete 15 
setblock ~106 ~9 ~30 dropper 0 
setblock ~107 ~9 ~22 dropper 0  
fill ~107 ~9 ~23 ~107 ~9 ~27 dark_oak_stairs 5 
setblock ~107 ~9 ~28 dropper 0  
fill ~35 ~10 ~25 ~36 ~10 ~25 concrete 15 
setblock ~37 ~10 ~24 gold_block 0 
setblock ~37 ~10 ~26 gold_block 0  
fill ~38 ~10 ~24 ~39 ~10 ~24 concrete 15  
fill ~38 ~10 ~26 ~39 ~10 ~26 concrete 15  
fill ~39 ~10 ~23 ~40 ~10 ~23 concrete 15  
fill ~39 ~10 ~25 ~39 ~11 ~25 concrete 15  
fill ~39 ~10 ~27 ~40 ~10 ~27 concrete 15  
fill ~40 ~10 ~22 ~41 ~10 ~22 concrete 15 
setblock ~40 ~10 ~25 torch 1  
fill ~40 ~10 ~28 ~41 ~10 ~28 concrete 15 
setblock ~41 ~10 ~20 concrete 15 
setblock ~41 ~10 ~30 concrete 15 
setblock ~42 ~10 ~19 concrete 4 
setblock ~42 ~10 ~20 torch 3 
setblock ~42 ~10 ~21 dispenser 4 
setblock ~42 ~10 ~24 fence 0 
setblock ~42 ~10 ~29 dispenser 12 
setblock ~42 ~10 ~30 torch 4 
setblock ~42 ~10 ~31 concrete 4 
setblock ~43 ~10 ~18 concrete 4 
setblock ~43 ~10 ~21 lever 1 
setblock ~43 ~10 ~23 dark_oak_stairs 6 
setblock ~43 ~10 ~24 dark_oak_stairs 3 
setblock ~43 ~10 ~29 lever 9 
setblock ~43 ~10 ~32 concrete 4 
setblock ~44 ~10 ~17 trapdoor 8 
setblock ~44 ~10 ~19 dispenser 2  
fill ~44 ~10 ~20 ~44 ~10 ~21 stone 6 
setblock ~44 ~10 ~22 skull 3 
setblock ~44 ~10 ~24 fence 0 
setblock ~44 ~10 ~28 skull 2  
fill ~44 ~10 ~29 ~44 ~10 ~30 stone 6 
setblock ~44 ~10 ~31 dispenser 3 
setblock ~44 ~10 ~33 trapdoor 9 
setblock ~45 ~10 ~18 concrete 4 
setblock ~45 ~10 ~32 concrete 4  
fill ~46 ~10 ~17 ~47 ~10 ~17 concrete 4 
setblock ~46 ~10 ~18 torch 3 
setblock ~46 ~10 ~32 torch 4  
fill ~46 ~10 ~33 ~47 ~10 ~33 concrete 4 
setblock ~47 ~10 ~25 torch 2 
setblock ~48 ~10 ~16 trapdoor 8 
setblock ~48 ~10 ~18 dispenser 2  
fill ~48 ~10 ~19 ~48 ~10 ~20 stone 6 
setblock ~48 ~10 ~21 skull 3 
setblock ~48 ~10 ~25 concrete 15 
setblock ~48 ~10 ~29 skull 2  
fill ~48 ~10 ~30 ~48 ~10 ~31 stone 6 
setblock ~48 ~10 ~32 dispenser 3 
setblock ~48 ~10 ~34 trapdoor 9  
fill ~49 ~10 ~16 ~51 ~10 ~16 concrete 4 
setblock ~49 ~10 ~25 torch 1  
fill ~49 ~10 ~34 ~51 ~10 ~34 concrete 4 
setblock ~50 ~10 ~17 torch 3 
setblock ~50 ~10 ~33 torch 4  
fill ~51 ~10 ~23 ~51 ~9 ~23 fence 5 
setblock ~51 ~10 ~27 fence 5 
setblock ~52 ~10 ~15 trapdoor 8 
setblock ~52 ~10 ~17 dispenser 2  
fill ~52 ~10 ~18 ~52 ~10 ~19 stone 6 
setblock ~52 ~10 ~20 skull 3 
setblock ~52 ~10 ~30 skull 2  
fill ~52 ~10 ~31 ~52 ~10 ~32 stone 6 
setblock ~52 ~10 ~33 dispenser 3 
setblock ~52 ~10 ~35 trapdoor 9 
setblock ~53 ~10 ~16 concrete 4 
setblock ~53 ~10 ~34 concrete 4  
fill ~54 ~10 ~15 ~55 ~10 ~15 concrete 4 
setblock ~54 ~10 ~16 torch 3 
setblock ~54 ~10 ~34 torch 4  
fill ~54 ~10 ~35 ~55 ~10 ~35 concrete 4 
setblock ~56 ~10 ~14 trapdoor 8 
setblock ~56 ~10 ~16 dispenser 2  
fill ~56 ~10 ~17 ~56 ~10 ~18 stone 6 
setblock ~56 ~10 ~19 skull 3 
setblock ~56 ~10 ~23 fence 5 
setblock ~56 ~10 ~27 fence 5 
setblock ~56 ~10 ~31 skull 2  
fill ~56 ~10 ~32 ~56 ~10 ~33 stone 6 
setblock ~56 ~10 ~34 dispenser 3 
setblock ~56 ~10 ~36 trapdoor 9  
fill ~57 ~10 ~15 ~59 ~10 ~15 concrete 4  
fill ~57 ~10 ~35 ~59 ~10 ~35 concrete 4 
setblock ~58 ~10 ~16 torch 3 
setblock ~58 ~10 ~34 torch 4 
setblock ~60 ~10 ~14 trapdoor 8 
setblock ~60 ~10 ~16 dispenser 2  
fill ~60 ~10 ~17 ~60 ~10 ~18 stone 6 
setblock ~60 ~10 ~19 skull 3 
setblock ~60 ~10 ~31 skull 2  
fill ~60 ~10 ~32 ~60 ~10 ~33 stone 6 
setblock ~60 ~10 ~34 dispenser 3 
setblock ~60 ~10 ~36 trapdoor 9  
fill ~61 ~10 ~15 ~63 ~10 ~15 concrete 4  
fill ~61 ~10 ~35 ~63 ~10 ~35 concrete 4 
setblock ~62 ~10 ~16 torch 3 
setblock ~62 ~10 ~34 torch 4 
setblock ~64 ~10 ~14 trapdoor 8 
setblock ~64 ~10 ~16 dispenser 2  
fill ~64 ~10 ~17 ~64 ~10 ~18 stone 6 
setblock ~64 ~10 ~19 skull 3 
setblock ~64 ~10 ~31 skull 2  
fill ~64 ~10 ~32 ~64 ~10 ~33 stone 6 
setblock ~64 ~10 ~34 dispenser 3 
setblock ~64 ~10 ~36 trapdoor 9  
fill ~65 ~10 ~15 ~67 ~10 ~15 concrete 4  
fill ~65 ~10 ~35 ~67 ~10 ~35 concrete 4 
setblock ~66 ~10 ~16 torch 3 
setblock ~66 ~10 ~34 torch 4 
setblock ~68 ~10 ~14 trapdoor 8 
setblock ~68 ~10 ~16 dispenser 2  
fill ~68 ~10 ~17 ~68 ~10 ~18 stone 6 
setblock ~68 ~10 ~19 skull 3 
setblock ~68 ~10 ~31 skull 2  
fill ~68 ~10 ~32 ~68 ~10 ~33 stone 6 
setblock ~68 ~10 ~34 dispenser 3 
setblock ~68 ~10 ~36 trapdoor 9  
fill ~69 ~10 ~15 ~71 ~10 ~15 concrete 4  
fill ~69 ~10 ~35 ~71 ~10 ~35 concrete 4 
setblock ~70 ~10 ~16 torch 3 
setblock ~70 ~10 ~34 torch 4 
setblock ~72 ~10 ~14 trapdoor 8 
setblock ~72 ~10 ~16 dispenser 2  
fill ~72 ~10 ~17 ~72 ~10 ~18 stone 6 
setblock ~72 ~10 ~19 skull 3 
setblock ~72 ~10 ~31 skull 2  
fill ~72 ~10 ~32 ~72 ~10 ~33 stone 6 
setblock ~72 ~10 ~34 dispenser 3 
setblock ~72 ~10 ~36 trapdoor 9  
fill ~73 ~10 ~15 ~75 ~10 ~15 concrete 4  
fill ~73 ~10 ~35 ~75 ~10 ~35 concrete 4 
setblock ~74 ~10 ~16 torch 3 
setblock ~74 ~10 ~34 torch 4 
setblock ~76 ~10 ~14 trapdoor 8 
setblock ~76 ~10 ~16 dispenser 2  
fill ~76 ~10 ~17 ~76 ~10 ~18 stone 6 
setblock ~76 ~10 ~19 skull 3 
setblock ~76 ~10 ~31 skull 2  
fill ~76 ~10 ~32 ~76 ~10 ~33 stone 6 
setblock ~76 ~10 ~34 dispenser 3 
setblock ~76 ~10 ~36 trapdoor 9  
fill ~77 ~10 ~15 ~79 ~10 ~15 concrete 4  
fill ~77 ~10 ~35 ~79 ~10 ~35 concrete 4 
setblock ~78 ~10 ~16 torch 3 
setblock ~78 ~10 ~34 torch 4 
setblock ~79 ~10 ~25 torch 2 
setblock ~80 ~10 ~14 trapdoor 8 
setblock ~80 ~10 ~16 dispenser 2  
fill ~80 ~10 ~17 ~80 ~10 ~18 stone 6 
setblock ~80 ~10 ~19 skull 3  
fill ~80 ~10 ~25 ~80 ~11 ~25 concrete 4 
setblock ~80 ~10 ~31 skull 2  
fill ~80 ~10 ~32 ~80 ~10 ~33 stone 6 
setblock ~80 ~10 ~34 dispenser 3 
setblock ~80 ~10 ~36 trapdoor 9  
fill ~81 ~10 ~15 ~82 ~10 ~15 concrete 4 
setblock ~81 ~10 ~25 torch 1  
fill ~81 ~10 ~35 ~82 ~10 ~35 concrete 4 
setblock ~82 ~10 ~16 torch 3 
setblock ~82 ~10 ~34 torch 4 
setblock ~83 ~10 ~16 concrete 4 
setblock ~83 ~10 ~34 concrete 4 
setblock ~84 ~10 ~15 trapdoor 8  
fill ~84 ~10 ~17 ~84 ~10 ~19 stone 6 
setblock ~84 ~10 ~20 skull 3 
setblock ~84 ~10 ~30 skull 2  
fill ~84 ~10 ~31 ~84 ~10 ~33 stone 6 
setblock ~84 ~10 ~35 trapdoor 9  
fill ~85 ~10 ~16 ~87 ~10 ~16 concrete 4  
fill ~85 ~10 ~23 ~85 ~9 ~23 fence 5 
setblock ~85 ~10 ~27 fence 5  
fill ~85 ~10 ~34 ~87 ~10 ~34 concrete 4 
setblock ~86 ~10 ~17 torch 3 
setblock ~86 ~10 ~33 torch 4 
setblock ~88 ~10 ~15 trapdoor 8 
setblock ~88 ~10 ~17 dispenser 2  
fill ~88 ~10 ~18 ~88 ~10 ~19 stone 6 
setblock ~88 ~10 ~20 skull 3 
setblock ~88 ~10 ~30 skull 2  
fill ~88 ~10 ~31 ~88 ~10 ~32 stone 6 
setblock ~88 ~10 ~33 dispenser 3 
setblock ~88 ~10 ~35 trapdoor 9 
setblock ~89 ~10 ~16 concrete 4 
setblock ~89 ~10 ~23 fence 5 
setblock ~89 ~10 ~27 fence 5 
setblock ~89 ~10 ~34 concrete 4  
fill ~90 ~10 ~17 ~91 ~10 ~17 concrete 4  
fill ~90 ~10 ~33 ~91 ~10 ~33 concrete 4 
setblock ~91 ~10 ~25 dark_oak_stairs 4 
setblock ~92 ~10 ~16 trapdoor 8 
setblock ~92 ~10 ~18 dispenser 2  
fill ~92 ~10 ~19 ~92 ~10 ~20 stone 6 
setblock ~92 ~10 ~21 skull 3 
setblock ~92 ~10 ~24 fence 0 
setblock ~92 ~10 ~25 dark_oak_stairs 1 
setblock ~92 ~10 ~26 fence 0 
setblock ~92 ~10 ~29 skull 2  
fill ~92 ~10 ~30 ~92 ~10 ~31 stone 6 
setblock ~92 ~10 ~32 dispenser 3 
setblock ~92 ~10 ~34 trapdoor 9  
fill ~93 ~10 ~17 ~95 ~10 ~17 concrete 4  
fill ~93 ~10 ~33 ~95 ~10 ~33 concrete 4 
setblock ~94 ~10 ~18 torch 3 
setblock ~94 ~10 ~32 torch 4 
setblock ~96 ~10 ~17 trapdoor 8 
setblock ~96 ~10 ~19 dispenser 2  
fill ~96 ~10 ~20 ~96 ~10 ~21 stone 6 
setblock ~96 ~10 ~22 skull 3 
setblock ~96 ~10 ~28 skull 2  
fill ~96 ~10 ~29 ~96 ~10 ~30 stone 6 
setblock ~96 ~10 ~31 dispenser 3 
setblock ~96 ~10 ~33 trapdoor 9  
fill ~97 ~10 ~18 ~98 ~10 ~18 concrete 4  
fill ~97 ~10 ~32 ~98 ~10 ~32 concrete 4 
setblock ~98 ~10 ~19 torch 3 
setblock ~98 ~10 ~25 torch 2 
setblock ~98 ~10 ~31 torch 4 
setblock ~99 ~10 ~19 concrete 4  
fill ~99 ~10 ~25 ~99 ~11 ~25 concrete 4 
setblock ~99 ~10 ~31 concrete 4 
setblock ~100 ~10 ~18 trapdoor 8 
setblock ~100 ~10 ~20 dispenser 2  
fill ~100 ~10 ~21 ~100 ~10 ~22 stone 6 
setblock ~100 ~10 ~23 skull 3  
fill ~100 ~10 ~24 ~101 ~10 ~24 dropper 8 
setblock ~100 ~10 ~25 dropper 9  
fill ~100 ~10 ~26 ~101 ~10 ~26 dropper 8 
setblock ~100 ~10 ~27 skull 2  
fill ~100 ~10 ~28 ~100 ~10 ~29 stone 6 
setblock ~100 ~10 ~30 dispenser 3 
setblock ~100 ~10 ~32 trapdoor 9 
setblock ~101 ~10 ~19 concrete 4 
setblock ~101 ~10 ~25 dropper 8 
setblock ~101 ~10 ~31 concrete 4  
fill ~102 ~10 ~19 ~106 ~10 ~19 concrete 11  
fill ~102 ~10 ~21 ~102 ~10 ~22 concrete 4  
fill ~102 ~10 ~24 ~102 ~10 ~26 concrete 4  
fill ~102 ~10 ~28 ~102 ~10 ~29 concrete 4  
fill ~102 ~10 ~31 ~106 ~10 ~31 concrete 11  
fill ~103 ~10 ~21 ~105 ~10 ~21 planks 0  
fill ~103 ~10 ~22 ~106 ~10 ~22 planks 0  
fill ~103 ~10 ~23 ~106 ~10 ~23 planks 0  
fill ~103 ~10 ~24 ~106 ~10 ~24 planks 0  
fill ~103 ~10 ~25 ~106 ~10 ~25 planks 0  
fill ~103 ~10 ~26 ~106 ~10 ~26 planks 0  
fill ~103 ~10 ~27 ~106 ~10 ~27 planks 0  
fill ~103 ~10 ~28 ~106 ~10 ~28 planks 0  
fill ~103 ~10 ~29 ~105 ~10 ~29 planks 0  
fill ~104 ~10 ~18 ~105 ~10 ~18 concrete 11  
fill ~104 ~10 ~20 ~106 ~10 ~20 concrete 11  
fill ~104 ~10 ~30 ~106 ~10 ~30 concrete 11  
fill ~104 ~10 ~32 ~105 ~10 ~32 concrete 11 
setblock ~106 ~10 ~18 spruce_stairs 5  
fill ~106 ~10 ~21 ~107 ~10 ~21 concrete 11  
fill ~106 ~10 ~29 ~107 ~10 ~29 concrete 11 
setblock ~106 ~10 ~32 spruce_stairs 5 
setblock ~107 ~10 ~20 spruce_stairs 5  
fill ~107 ~10 ~22 ~107 ~10 ~29 concrete 11 
setblock ~107 ~10 ~30 spruce_stairs 5 
setblock ~108 ~10 ~22 spruce_stairs 5  
fill ~108 ~10 ~23 ~108 ~10 ~27 concrete 11 
setblock ~108 ~10 ~28 spruce_stairs 5  
fill ~35 ~11 ~25 ~35 ~15 ~25 concrete 15  
fill ~36 ~11 ~24 ~36 ~12 ~24 gold_block 0  
fill ~36 ~11 ~26 ~36 ~12 ~26 gold_block 0  
fill ~37 ~11 ~24 ~39 ~11 ~24 concrete 15  
fill ~37 ~11 ~25 ~39 ~11 ~25 concrete 15  
fill ~37 ~11 ~26 ~39 ~11 ~26 concrete 15 
setblock ~38 ~11 ~22 fence 2  
fill ~38 ~11 ~23 ~39 ~11 ~23 concrete 15  
fill ~38 ~11 ~27 ~39 ~11 ~27 concrete 15 
setblock ~38 ~11 ~28 fence 2  
fill ~39 ~11 ~22 ~40 ~11 ~22 concrete 15  
fill ~39 ~11 ~28 ~40 ~11 ~28 concrete 15  
fill ~40 ~11 ~21 ~40 ~12 ~21 gold_block 0  
fill ~40 ~11 ~23 ~41 ~11 ~23 planks 0  
fill ~40 ~11 ~24 ~41 ~11 ~24 planks 0  
fill ~40 ~11 ~25 ~41 ~11 ~25 planks 0  
fill ~40 ~11 ~26 ~41 ~11 ~26 planks 0  
fill ~40 ~11 ~27 ~41 ~11 ~27 planks 0  
fill ~40 ~11 ~29 ~40 ~12 ~29 gold_block 0  
fill ~41 ~11 ~20 ~41 ~12 ~20 gold_block 0  
fill ~41 ~11 ~21 ~41 ~12 ~21 planks 0  
fill ~41 ~11 ~22 ~41 ~12 ~22 planks 0  
fill ~41 ~11 ~28 ~41 ~11 ~29 planks 0  
fill ~41 ~11 ~30 ~41 ~12 ~30 gold_block 0  
fill ~42 ~11 ~19 ~42 ~11 ~31 concrete 15  
fill ~43 ~11 ~18 ~44 ~11 ~18 concrete 15  
fill ~43 ~11 ~19 ~99 ~11 ~19 planks 0  
fill ~43 ~11 ~20 ~101 ~11 ~20 planks 0  
fill ~43 ~11 ~21 ~101 ~11 ~21 planks 0  
fill ~43 ~11 ~22 ~60 ~11 ~22 planks 0 
setblock ~43 ~11 ~23 dark_oak_stairs 3 
setblock ~43 ~11 ~27 oak_stairs 6  
fill ~43 ~11 ~28 ~60 ~11 ~28 planks 0  
fill ~43 ~11 ~29 ~101 ~11 ~29 planks 0  
fill ~43 ~11 ~30 ~101 ~11 ~30 planks 0  
fill ~43 ~11 ~31 ~99 ~11 ~31 planks 0  
fill ~43 ~11 ~32 ~44 ~11 ~32 concrete 15 
setblock ~44 ~11 ~17 carpet 15  
fill ~44 ~11 ~23 ~50 ~11 ~23 planks 0  
fill ~44 ~11 ~24 ~46 ~11 ~24 planks 0  
fill ~44 ~11 ~25 ~46 ~11 ~25 planks 0  
fill ~44 ~11 ~26 ~46 ~11 ~26 planks 0  
fill ~44 ~11 ~27 ~50 ~11 ~27 planks 0 
setblock ~44 ~11 ~33 carpet 15  
fill ~45 ~11 ~17 ~47 ~11 ~17 concrete 15  
fill ~45 ~11 ~18 ~96 ~11 ~18 planks 0  
fill ~45 ~11 ~32 ~96 ~11 ~32 planks 0  
fill ~45 ~11 ~33 ~47 ~11 ~33 concrete 15  
fill ~47 ~11 ~24 ~49 ~11 ~24 planks 1  
fill ~47 ~11 ~25 ~47 ~11 ~26 planks 1  
fill ~48 ~11 ~16 ~52 ~11 ~16 concrete 15  
fill ~48 ~11 ~17 ~90 ~11 ~17 planks 0  
fill ~48 ~11 ~25 ~48 ~12 ~25 concrete 4  
fill ~48 ~11 ~26 ~49 ~11 ~26 planks 1  
fill ~48 ~11 ~33 ~90 ~11 ~33 planks 0  
fill ~48 ~11 ~34 ~52 ~11 ~34 concrete 15 
setblock ~49 ~11 ~25 planks 1  
fill ~50 ~11 ~24 ~50 ~11 ~33 planks 0  
fill ~51 ~11 ~23 ~56 ~11 ~23 planks 1  
fill ~51 ~11 ~24 ~51 ~11 ~27 planks 1 
setblock ~52 ~11 ~15 carpet 15  
fill ~52 ~11 ~27 ~56 ~11 ~27 planks 1 
setblock ~52 ~11 ~35 carpet 15  
fill ~53 ~11 ~15 ~82 ~11 ~15 concrete 15  
fill ~53 ~11 ~16 ~82 ~11 ~16 planks 0  
fill ~53 ~11 ~34 ~82 ~11 ~34 planks 0  
fill ~53 ~11 ~35 ~82 ~11 ~35 concrete 15 
setblock ~56 ~11 ~14 carpet 15  
fill ~56 ~11 ~24 ~56 ~11 ~27 planks 1 
setblock ~56 ~11 ~36 carpet 15  
fill ~57 ~11 ~23 ~61 ~11 ~23 planks 0  
fill ~57 ~11 ~24 ~61 ~11 ~24 planks 0  
fill ~57 ~11 ~25 ~61 ~11 ~25 planks 0  
fill ~57 ~11 ~26 ~61 ~11 ~26 planks 0  
fill ~57 ~11 ~27 ~61 ~11 ~27 planks 0 
setblock ~60 ~11 ~14 carpet 15 
setblock ~60 ~11 ~36 carpet 15  
fill ~62 ~11 ~22 ~72 ~11 ~22 planks 0  
fill ~62 ~11 ~23 ~64 ~11 ~23 trapdoor 11  
fill ~62 ~11 ~24 ~64 ~11 ~24 trapdoor 11  
fill ~62 ~11 ~25 ~64 ~11 ~25 trapdoor 11  
fill ~62 ~11 ~26 ~64 ~11 ~26 trapdoor 11  
fill ~62 ~11 ~27 ~65 ~11 ~27 trapdoor 8  
fill ~62 ~11 ~28 ~72 ~11 ~28 planks 0 
setblock ~64 ~11 ~14 carpet 15 
setblock ~64 ~11 ~36 carpet 15  
fill ~65 ~11 ~23 ~65 ~11 ~26 trapdoor 9  
fill ~66 ~11 ~23 ~66 ~11 ~27 trapdoor 11  
fill ~67 ~11 ~23 ~67 ~11 ~27 dropper 9 
setblock ~68 ~11 ~14 carpet 15  
fill ~68 ~11 ~23 ~72 ~11 ~23 trapdoor 11  
fill ~68 ~11 ~24 ~72 ~11 ~24 trapdoor 11  
fill ~68 ~11 ~25 ~72 ~11 ~25 trapdoor 11  
fill ~68 ~11 ~26 ~70 ~11 ~26 trapdoor 11  
fill ~68 ~11 ~27 ~72 ~11 ~27 trapdoor 11 
setblock ~68 ~11 ~36 carpet 15 
setblock ~71 ~11 ~26 trapdoor 15 
setblock ~72 ~11 ~14 carpet 15 
setblock ~72 ~11 ~26 trapdoor 11 
setblock ~72 ~11 ~36 carpet 15  
fill ~73 ~11 ~23 ~84 ~11 ~23 planks 0  
fill ~73 ~11 ~24 ~78 ~11 ~24 planks 0  
fill ~73 ~11 ~25 ~78 ~11 ~25 planks 0  
fill ~73 ~11 ~26 ~78 ~11 ~26 planks 0  
fill ~73 ~11 ~27 ~84 ~11 ~27 planks 0  
fill ~74 ~11 ~22 ~101 ~11 ~22 planks 0  
fill ~74 ~11 ~28 ~101 ~11 ~28 planks 0 
setblock ~76 ~11 ~14 carpet 15 
setblock ~76 ~11 ~36 carpet 15  
fill ~79 ~11 ~24 ~81 ~11 ~24 planks 1  
fill ~79 ~11 ~25 ~79 ~11 ~26 planks 1 
setblock ~80 ~11 ~14 carpet 15  
fill ~80 ~11 ~26 ~81 ~11 ~26 planks 1 
setblock ~80 ~11 ~36 carpet 15 
setblock ~81 ~11 ~25 planks 1  
fill ~82 ~11 ~24 ~84 ~11 ~24 planks 0  
fill ~82 ~11 ~25 ~84 ~11 ~25 planks 0  
fill ~82 ~11 ~26 ~84 ~11 ~26 planks 0  
fill ~83 ~11 ~16 ~90 ~11 ~16 concrete 15  
fill ~83 ~11 ~34 ~90 ~11 ~34 concrete 15 
setblock ~84 ~11 ~15 carpet 15 
setblock ~84 ~11 ~35 carpet 15  
fill ~85 ~11 ~23 ~89 ~11 ~23 planks 1  
fill ~85 ~11 ~24 ~85 ~11 ~27 planks 1  
fill ~86 ~11 ~27 ~89 ~11 ~27 planks 1 
setblock ~88 ~11 ~15 carpet 15 
setblock ~88 ~11 ~35 carpet 15  
fill ~89 ~11 ~24 ~89 ~11 ~27 planks 1  
fill ~90 ~11 ~23 ~101 ~11 ~23 planks 0  
fill ~90 ~11 ~24 ~97 ~11 ~24 planks 0  
fill ~90 ~11 ~25 ~90 ~11 ~33 planks 0  
fill ~91 ~11 ~17 ~96 ~11 ~17 concrete 15 
setblock ~91 ~11 ~25 dark_oak_stairs 1  
fill ~91 ~11 ~26 ~97 ~11 ~26 planks 0  
fill ~91 ~11 ~27 ~101 ~11 ~27 planks 0  
fill ~91 ~11 ~33 ~96 ~11 ~33 concrete 15 
setblock ~92 ~11 ~16 carpet 15 
setblock ~92 ~11 ~34 carpet 15 
setblock ~95 ~11 ~25 dropper 8  
fill ~96 ~11 ~25 ~97 ~11 ~25 planks 0  
fill ~97 ~11 ~18 ~99 ~11 ~18 concrete 15  
fill ~97 ~11 ~32 ~99 ~11 ~32 concrete 15  
fill ~98 ~11 ~24 ~99 ~11 ~24 planks 1  
fill ~98 ~11 ~25 ~98 ~11 ~26 planks 1 
setblock ~99 ~11 ~26 planks 1 
setblock ~100 ~11 ~18 carpet 15  
fill ~100 ~11 ~19 ~101 ~11 ~19 concrete 15  
fill ~100 ~11 ~24 ~101 ~11 ~24 dropper 0  
fill ~100 ~11 ~26 ~101 ~11 ~26 dropper 0  
fill ~100 ~11 ~31 ~101 ~11 ~31 concrete 15 
setblock ~100 ~11 ~32 carpet 15  
fill ~102 ~11 ~19 ~102 ~12 ~19 planks 5 
setblock ~102 ~11 ~22 concrete 15 
setblock ~102 ~11 ~24 concrete 15 
setblock ~102 ~11 ~25 dark_oak_door 0 
setblock ~102 ~11 ~26 concrete 15 
setblock ~102 ~11 ~28 concrete 15  
fill ~102 ~11 ~31 ~102 ~12 ~31 planks 5 
setblock ~103 ~11 ~19 glass 0 
setblock ~103 ~11 ~20 chest 5 
setblock ~103 ~11 ~21 birch_door 0  
fill ~103 ~11 ~22 ~103 ~12 ~22 planks 5 
setblock ~103 ~11 ~31 glass 0  
fill ~104 ~11 ~18 ~104 ~12 ~18 planks 5  
fill ~104 ~11 ~19 ~104 ~12 ~19 planks 5 
setblock ~104 ~11 ~22 wooden_door 3  
fill ~104 ~11 ~31 ~104 ~12 ~31 planks 5  
fill ~104 ~11 ~32 ~104 ~12 ~32 planks 5 
setblock ~105 ~11 ~18 glass 0 
setblock ~105 ~11 ~19 bed 0  
fill ~105 ~11 ~22 ~108 ~11 ~22 planks 5  
fill ~105 ~11 ~24 ~106 ~11 ~24 glass 0  
fill ~105 ~11 ~25 ~106 ~11 ~25 glass 0  
fill ~105 ~11 ~26 ~106 ~11 ~26 glass 0 
setblock ~105 ~11 ~29 emerald_block 2 
setblock ~105 ~11 ~32 glass 0  
fill ~106 ~11 ~18 ~106 ~12 ~18 planks 5 
setblock ~106 ~11 ~20 bookshelf 0  
fill ~106 ~11 ~32 ~106 ~12 ~32 planks 5  
fill ~107 ~11 ~19 ~107 ~13 ~19 concrete 11  
fill ~107 ~11 ~20 ~107 ~12 ~20 planks 5 
setblock ~107 ~11 ~21 glass 0 
setblock ~107 ~11 ~25 dispenser 3  
fill ~107 ~11 ~28 ~108 ~11 ~28 planks 5 
setblock ~107 ~11 ~29 glass 0  
fill ~107 ~11 ~30 ~107 ~12 ~30 planks 5  
fill ~107 ~11 ~31 ~107 ~13 ~31 concrete 11 
setblock ~108 ~11 ~23 glass 0  
fill ~108 ~11 ~24 ~108 ~12 ~24 planks 5 
setblock ~108 ~11 ~25 glass 0  
fill ~108 ~11 ~26 ~108 ~12 ~26 planks 5 
setblock ~108 ~11 ~27 glass 0 
setblock ~34 ~12 ~25 fence 0 
setblock ~37 ~12 ~23 fence 2  
fill ~37 ~12 ~24 ~37 ~11 ~24 concrete 15  
fill ~37 ~12 ~25 ~37 ~11 ~25 concrete 15  
fill ~37 ~12 ~26 ~37 ~11 ~26 concrete 15 
setblock ~37 ~12 ~27 fence 2 
setblock ~38 ~12 ~22 gold_block 0  
fill ~38 ~12 ~23 ~38 ~11 ~23 concrete 15  
fill ~38 ~12 ~24 ~41 ~12 ~24 planks 0  
fill ~38 ~12 ~25 ~41 ~12 ~25 planks 0  
fill ~38 ~12 ~26 ~41 ~12 ~26 planks 0  
fill ~38 ~12 ~27 ~38 ~11 ~27 concrete 15 
setblock ~38 ~12 ~28 gold_block 0 
setblock ~39 ~12 ~21 gold_block 0  
fill ~39 ~12 ~22 ~39 ~11 ~22 concrete 15
fill ~39 ~12 ~23 ~41 ~12 ~23 planks 0  
fill ~39 ~12 ~27 ~41 ~12 ~27 planks 0  
fill ~39 ~12 ~28 ~39 ~11 ~28 concrete 15 
setblock ~39 ~12 ~29 gold_block 0 
setblock ~40 ~12 ~22 planks 0 
setblock ~40 ~12 ~28 oak_stairs 1 
setblock ~41 ~12 ~19 fence 2 
setblock ~41 ~12 ~29 planks 0 
setblock ~41 ~12 ~31 fence 2  
fill ~42 ~12 ~18 ~42 ~13 ~18 fence 2 
setblock ~42 ~12 ~19 planks 1  
fill ~42 ~12 ~20 ~42 ~12 ~30 concrete 4 
setblock ~42 ~12 ~31 planks 1  
fill ~42 ~12 ~32 ~42 ~13 ~32 fence 2 
setblock ~43 ~12 ~18 wool 4  
fill ~43 ~12 ~27 ~45 ~12 ~27 fence 1 
setblock ~43 ~12 ~32 wool 4  
fill ~44 ~12 ~17 ~46 ~12 ~17 wool 4 
setblock ~44 ~12 ~18 skull 1 
setblock ~44 ~12 ~20 skull 1  
fill ~44 ~12 ~23 ~44 ~12 ~27 fence 1 
setblock ~44 ~12 ~30 skull 1 
setblock ~44 ~12 ~32 skull 1  
fill ~44 ~12 ~33 ~46 ~12 ~33 wool 4  
fill ~45 ~12 ~18 ~45 ~12 ~20 planks 1 
setblock ~45 ~12 ~21 spruce_stairs 3 
setblock ~45 ~12 ~25 dark_oak_stairs 2 
setblock ~45 ~12 ~26 dark_oak_stairs 7 
setblock ~45 ~12 ~29 spruce_stairs 2  
fill ~45 ~12 ~30 ~45 ~12 ~32 planks 1 
setblock ~46 ~12 ~18 skull 1 
setblock ~46 ~12 ~20 skull 1  
fill ~46 ~12 ~25 ~46 ~13 ~25 fence 0 
setblock ~46 ~12 ~30 skull 1 
setblock ~46 ~12 ~32 skull 1  
fill ~47 ~12 ~16 ~51 ~12 ~16 wool 4  
fill ~47 ~12 ~34 ~51 ~12 ~34 wool 4 
setblock ~48 ~12 ~17 skull 1 
setblock ~48 ~12 ~19 skull 1  
fill ~48 ~12 ~24 ~48 ~13 ~24 fence 5  
fill ~48 ~12 ~26 ~48 ~13 ~26 fence 5 
setblock ~48 ~12 ~31 skull 1 
setblock ~48 ~12 ~33 skull 1  
fill ~49 ~12 ~17 ~49 ~12 ~19 planks 1 
setblock ~49 ~12 ~20 spruce_stairs 3 
setblock ~49 ~12 ~25 skull 1 
setblock ~49 ~12 ~30 spruce_stairs 2  
fill ~49 ~12 ~31 ~49 ~12 ~33 planks 1 
setblock ~50 ~12 ~17 skull 1 
setblock ~50 ~12 ~19 skull 1 
setblock ~50 ~12 ~31 skull 1 
setblock ~50 ~12 ~33 skull 1  
fill ~51 ~12 ~23 ~56 ~12 ~23 fence 5  
fill ~51 ~12 ~24 ~51 ~12 ~27 fence 5  
fill ~52 ~12 ~15 ~83 ~12 ~15 wool 4 
setblock ~52 ~12 ~16 skull 1 
setblock ~52 ~12 ~18 skull 1  
fill ~52 ~12 ~27 ~56 ~12 ~27 fence 5 
setblock ~52 ~12 ~32 skull 1 
setblock ~52 ~12 ~34 skull 1  
fill ~52 ~12 ~35 ~83 ~12 ~35 wool 4  
fill ~53 ~12 ~16 ~53 ~12 ~18 planks 1 
setblock ~53 ~12 ~19 spruce_stairs 3 
setblock ~53 ~12 ~31 spruce_stairs 2  
fill ~53 ~12 ~32 ~53 ~12 ~34 planks 1 
setblock ~54 ~12 ~16 skull 1 
setblock ~54 ~12 ~18 skull 1 
setblock ~54 ~12 ~32 skull 1 
setblock ~54 ~12 ~34 skull 1 
