setblock ~-14 ~87 ~26 chest 3  
setblock ~-16 ~87 ~28 furnace 5  
setblock ~1 ~78 ~11 chest 5  
setblock ~1 ~78 ~10 chest 5  
setblock ~4 ~79 ~17 furnace 3  
setblock ~4 ~78 ~17 furnace 3  
setblock ~1 ~78 ~40 chest 5  
setblock ~1 ~78 ~39 chest 5  
setblock ~4 ~79 ~33 furnace 2  
setblock ~4 ~78 ~33 furnace 2  
setblock ~9 ~78 ~3 chest 3  
setblock ~9 ~79 ~9 furnace 2  
setblock ~7 ~79 ~11 furnace 4  
setblock ~10 ~79 ~9 furnace 2  
setblock ~9 ~78 ~9 furnace 2  
setblock ~7 ~78 ~11 furnace 4  
setblock ~8 ~78 ~3 chest 3  
setblock ~10 ~78 ~9 furnace 2  
setblock ~7 ~79 ~12 furnace 4  
setblock ~7 ~78 ~12 furnace 4  
setblock ~15 ~79 ~8 furnace 5  
setblock ~16 ~78 ~0 chest 3  
setblock ~15 ~78 ~4 chest 5  
setblock ~15 ~78 ~5 chest 5  
setblock ~15 ~78 ~8 furnace 5  
setblock ~15 ~78 ~7 furnace 5  
setblock ~16 ~78 ~9 furnace 2  
setblock ~17 ~78 ~0 chest 3  
setblock ~16 ~79 ~9 furnace 2  
setblock ~17 ~78 ~9 furnace 2  
setblock ~19 ~78 ~9 chest 2  
setblock ~20 ~78 ~9 chest 2  
setblock ~7 ~78 ~18 chest 4  
setblock ~7 ~78 ~23 chest 4  
setblock ~7 ~78 ~27 chest 4  
setblock ~17 ~79 ~19 furnace 5  
setblock ~15 ~78 ~20 furnace 4  
setblock ~15 ~78 ~19 furnace 4  
setblock ~17 ~79 ~20 furnace 5  
setblock ~15 ~79 ~20 furnace 4  
setblock ~17 ~78 ~19 furnace 5  
setblock ~15 ~79 ~19 furnace 4  
setblock ~17 ~78 ~20 furnace 5  
setblock ~9 ~79 ~41 furnace 3  
setblock ~7 ~78 ~42 chest 5  
setblock ~9 ~78 ~41 furnace 3  
setblock ~10 ~78 ~41 furnace 3  
setblock ~7 ~78 ~39 furnace 4  
setblock ~7 ~78 ~38 furnace 4  
setblock ~7 ~78 ~32 chest 4  
setblock ~10 ~79 ~41 furnace 3  
setblock ~7 ~79 ~39 furnace 4  
setblock ~7 ~79 ~38 furnace 4  
setblock ~15 ~79 ~42 furnace 5  
setblock ~15 ~79 ~30 furnace 4  
setblock ~15 ~79 ~31 furnace 4  
setblock ~16 ~78 ~41 furnace 3  
setblock ~17 ~79 ~31 furnace 5  
setblock ~17 ~79 ~30 furnace 5  
setblock ~16 ~79 ~41 furnace 3  
setblock ~17 ~78 ~41 furnace 3  
setblock ~17 ~78 ~30 furnace 5  
setblock ~17 ~78 ~31 furnace 5  
setblock ~15 ~78 ~30 furnace 4  
setblock ~15 ~78 ~31 furnace 4  
setblock ~15 ~78 ~42 furnace 5  
setblock ~15 ~78 ~43 furnace 5  
setblock ~20 ~78 ~41 chest 3  
setblock ~19 ~78 ~41 chest 3  
setblock ~15 ~78 ~45 chest 5  
setblock ~9 ~78 ~47 chest 2  
setblock ~8 ~78 ~47 chest 2  
setblock ~16 ~78 ~50 chest 2  
setblock ~15 ~78 ~46 chest 5  
setblock ~17 ~78 ~50 chest 2  
setblock ~26 ~78 ~41 chest 3  
setblock ~27 ~78 ~41 chest 3  
setblock ~31 ~79 ~42 furnace 4  
setblock ~31 ~79 ~30 furnace 5  
setblock ~31 ~79 ~31 furnace 5  
setblock ~29 ~79 ~30 furnace 4  
setblock ~29 ~79 ~31 furnace 4  
setblock ~29 ~78 ~30 furnace 4  
setblock ~29 ~78 ~31 furnace 4  
setblock ~30 ~78 ~41 furnace 3  
setblock ~30 ~79 ~41 furnace 3  
setblock ~29 ~78 ~41 furnace 3  
setblock ~31 ~78 ~30 furnace 5  
setblock ~31 ~78 ~31 furnace 5  
setblock ~31 ~78 ~42 furnace 4  
setblock ~31 ~78 ~43 furnace 4  
setblock ~36 ~78 ~41 furnace 3  
setblock ~36 ~79 ~41 furnace 3  
setblock ~31 ~78 ~45 chest 4  
setblock ~30 ~78 ~50 chest 2  
setblock ~29 ~78 ~50 chest 2  
setblock ~31 ~78 ~46 chest 4  
setblock ~39 ~78 ~27 chest 5  
setblock ~39 ~78 ~39 furnace 5  
setblock ~39 ~78 ~38 furnace 5  
setblock ~37 ~78 ~41 furnace 3  
setblock ~39 ~78 ~32 chest 5  
setblock ~37 ~79 ~41 furnace 3  
setblock ~39 ~79 ~39 furnace 5  
setblock ~39 ~79 ~38 furnace 5  
setblock ~42 ~78 ~33 furnace 2  
setblock ~39 ~78 ~42 chest 4  
setblock ~42 ~79 ~33 furnace 2  
setblock ~45 ~78 ~39 chest 4  
setblock ~45 ~78 ~40 chest 4  
setblock ~38 ~78 ~47 chest 2  
setblock ~37 ~78 ~47 chest 2  
fill ~23 ~1 ~25 ~24 ~1 ~25 fence 0 
setblock ~23 ~2 ~25 redstone_torch 5  
fill ~24 ~2 ~25 ~24 ~9 ~25 fence 0  
fill ~22 ~5 ~24 ~23 ~5 ~24 fence 0  
fill ~22 ~6 ~23 ~22 ~10 ~23 fence 0 
setblock ~22 ~6 ~24 redstone_torch 5  
fill ~23 ~6 ~24 ~23 ~9 ~24 fence 0  
fill ~23 ~6 ~26 ~23 ~9 ~26 fence 0 
setblock ~22 ~7 ~22 fence 0 
setblock ~23 ~7 ~27 fence 0 
setblock ~25 ~7 ~25 fence 0 
setblock ~22 ~8 ~22 redstone_torch 5 
setblock ~23 ~8 ~27 redstone_torch 5 
setblock ~25 ~8 ~25 redstone_torch 5 
setblock ~21 ~10 ~25 redstone_torch 2  
fill ~22 ~10 ~24 ~24 ~10 ~24 iron_block 0  
fill ~22 ~10 ~25 ~22 ~10 ~26 iron_block 0 
setblock ~23 ~10 ~23 redstone_torch 4 
setblock ~23 ~10 ~25 glass 0  
fill ~23 ~10 ~26 ~24 ~10 ~26 iron_block 0 
setblock ~23 ~10 ~27 redstone_torch 3 
setblock ~24 ~10 ~25 iron_block 0 
setblock ~25 ~10 ~25 redstone_torch 1 
setblock ~21 ~11 ~24 iron_block 0 
setblock ~21 ~11 ~25 glowstone 0 
setblock ~21 ~11 ~26 iron_block 0 
setblock ~22 ~11 ~23 iron_block 0  
fill ~22 ~11 ~24 ~23 ~11 ~24 spruce_stairs 3 
setblock ~22 ~11 ~25 spruce_stairs 1  
fill ~22 ~11 ~26 ~24 ~11 ~26 spruce_stairs 2 
setblock ~22 ~11 ~27 iron_block 0 
setblock ~23 ~11 ~23 glowstone 0 
setblock ~23 ~11 ~27 glowstone 0 
setblock ~24 ~11 ~23 iron_block 0  
fill ~24 ~11 ~24 ~24 ~11 ~25 spruce_stairs 0 
setblock ~24 ~11 ~27 iron_block 0 
setblock ~25 ~11 ~24 iron_block 0 
setblock ~25 ~11 ~25 glowstone 0 
setblock ~25 ~11 ~26 iron_block 0  
fill ~20 ~12 ~24 ~20 ~15 ~24 iron_block 0  
fill ~20 ~12 ~25 ~20 ~18 ~25 iron_block 0  
fill ~20 ~12 ~26 ~20 ~15 ~26 iron_block 0  
fill ~21 ~12 ~23 ~21 ~15 ~23 iron_block 0  
fill ~21 ~12 ~24 ~21 ~14 ~24 fence 0  
fill ~21 ~12 ~25 ~21 ~17 ~25 ladder 5  
fill ~21 ~12 ~26 ~21 ~14 ~26 fence 0  
fill ~21 ~12 ~27 ~21 ~15 ~27 iron_block 0  
fill ~22 ~12 ~22 ~24 ~12 ~22 iron_block 0  
fill ~22 ~12 ~23 ~22 ~14 ~23 fence 0  
fill ~22 ~12 ~27 ~22 ~14 ~27 fence 0  
fill ~22 ~12 ~28 ~24 ~12 ~28 iron_block 0  
fill ~24 ~12 ~23 ~24 ~14 ~23 fence 0  
fill ~24 ~12 ~27 ~24 ~14 ~27 fence 0  
fill ~25 ~12 ~23 ~25 ~15 ~23 iron_block 0  
fill ~25 ~12 ~24 ~25 ~14 ~24 fence 0  
fill ~25 ~12 ~25 ~25 ~17 ~25 ladder 4  
fill ~25 ~12 ~26 ~25 ~14 ~26 fence 0  
fill ~25 ~12 ~27 ~25 ~15 ~27 iron_block 0  
fill ~26 ~12 ~24 ~26 ~15 ~24 iron_block 0  
fill ~26 ~12 ~25 ~26 ~18 ~25 iron_block 0  
fill ~26 ~12 ~26 ~26 ~15 ~26 iron_block 0  
fill ~19 ~13 ~24 ~19 ~15 ~24 iron_block 0  
fill ~19 ~13 ~25 ~19 ~18 ~25 iron_block 0  
fill ~19 ~13 ~26 ~19 ~15 ~26 iron_block 0  
fill ~20 ~13 ~22 ~22 ~13 ~22 iron_block 0  
fill ~20 ~13 ~23 ~20 ~15 ~23 iron_block 0  
fill ~20 ~13 ~27 ~20 ~15 ~27 iron_block 0  
fill ~20 ~13 ~28 ~22 ~13 ~28 iron_block 0  
fill ~22 ~13 ~21 ~24 ~13 ~21 iron_block 0  
fill ~22 ~13 ~29 ~24 ~13 ~29 iron_block 0 
setblock ~23 ~13 ~22 glowstone 0 
setblock ~23 ~13 ~28 glowstone 0  
fill ~24 ~13 ~22 ~26 ~13 ~22 iron_block 0  
fill ~24 ~13 ~28 ~26 ~13 ~28 iron_block 0  
fill ~26 ~13 ~23 ~26 ~15 ~23 iron_block 0  
fill ~26 ~13 ~27 ~26 ~15 ~27 iron_block 0  
fill ~27 ~13 ~24 ~27 ~15 ~24 iron_block 0  
fill ~27 ~13 ~25 ~27 ~18 ~25 iron_block 0  
fill ~27 ~13 ~26 ~27 ~15 ~26 iron_block 0  
fill ~18 ~14 ~24 ~18 ~15 ~24 iron_block 0  
fill ~18 ~14 ~25 ~18 ~18 ~25 iron_block 0  
fill ~18 ~14 ~26 ~18 ~15 ~26 iron_block 0  
fill ~19 ~14 ~22 ~27 ~14 ~22 iron_block 0  
fill ~19 ~14 ~23 ~19 ~15 ~23 iron_block 0  
fill ~19 ~14 ~27 ~19 ~15 ~27 iron_block 0  
fill ~19 ~14 ~28 ~27 ~14 ~28 iron_block 0  
fill ~20 ~14 ~21 ~26 ~14 ~21 iron_block 0  
fill ~20 ~14 ~29 ~26 ~14 ~29 iron_block 0  
fill ~22 ~14 ~20 ~24 ~14 ~20 iron_block 0  
fill ~22 ~14 ~30 ~24 ~14 ~30 iron_block 0  
fill ~27 ~14 ~23 ~27 ~15 ~23 iron_block 0  
fill ~27 ~14 ~27 ~27 ~15 ~27 iron_block 0  
fill ~28 ~14 ~24 ~28 ~15 ~24 iron_block 0  
fill ~28 ~14 ~25 ~28 ~18 ~25 iron_block 0  
fill ~28 ~14 ~26 ~28 ~15 ~26 iron_block 0  
fill ~17 ~15 ~24 ~17 ~19 ~24 iron_block 0 
setblock ~17 ~15 ~25 glowstone 0  
fill ~17 ~15 ~26 ~17 ~19 ~26 iron_block 0  
fill ~18 ~15 ~22 ~28 ~15 ~22 iron_block 0  
fill ~18 ~15 ~23 ~18 ~19 ~23 iron_block 0  
fill ~18 ~15 ~27 ~18 ~19 ~27 iron_block 0  
fill ~18 ~15 ~28 ~28 ~15 ~28 iron_block 0  
fill ~19 ~15 ~21 ~27 ~15 ~21 iron_block 0  
fill ~19 ~15 ~29 ~27 ~15 ~29 iron_block 0  
fill ~20 ~15 ~20 ~26 ~15 ~20 iron_block 0  
fill ~20 ~15 ~30 ~26 ~15 ~30 iron_block 0  
fill ~21 ~15 ~24 ~29 ~15 ~24 iron_block 0  
fill ~21 ~15 ~26 ~29 ~15 ~26 iron_block 0  
fill ~22 ~15 ~19 ~22 ~19 ~19 iron_block 0 
setblock ~22 ~15 ~23 iron_block 0  
fill ~22 ~15 ~25 ~24 ~15 ~25 iron_block 0 
setblock ~22 ~15 ~27 iron_block 0  
fill ~22 ~15 ~31 ~22 ~19 ~31 iron_block 0 
setblock ~23 ~15 ~19 glowstone 0 
setblock ~23 ~15 ~23 glowstone 0 
setblock ~23 ~15 ~27 glowstone 0 
setblock ~23 ~15 ~31 glowstone 0  
fill ~24 ~15 ~19 ~24 ~19 ~19 iron_block 0 
setblock ~24 ~15 ~23 iron_block 0 
setblock ~24 ~15 ~27 iron_block 0  
fill ~24 ~15 ~31 ~24 ~19 ~31 iron_block 0  
fill ~28 ~15 ~23 ~28 ~19 ~23 iron_block 0  
fill ~28 ~15 ~27 ~28 ~19 ~27 iron_block 0 
setblock ~29 ~15 ~25 glowstone 0 
setblock ~16 ~16 ~25 redstone_torch 2  
fill ~17 ~16 ~25 ~17 ~19 ~25 iron_block 0 
setblock ~18 ~16 ~21 redstone_torch 2  
fill ~18 ~16 ~22 ~18 ~19 ~22 iron_block 0  
fill ~18 ~16 ~28 ~18 ~19 ~28 iron_block 0 
setblock ~18 ~16 ~29 redstone_torch 2 
setblock ~19 ~16 ~20 redstone_torch 4  
fill ~19 ~16 ~21 ~19 ~18 ~21 iron_block 0  
fill ~19 ~16 ~23 ~19 ~17 ~23 glass 0  
fill ~19 ~16 ~27 ~19 ~17 ~27 glass 0  
fill ~19 ~16 ~29 ~19 ~18 ~29 iron_block 0 
setblock ~19 ~16 ~30 redstone_torch 3  
fill ~20 ~16 ~20 ~21 ~16 ~20 iron_block 0  
fill ~20 ~16 ~22 ~20 ~17 ~22 glass 0  
fill ~20 ~16 ~23 ~20 ~17 ~23 stained_hardened_clay 14  
fill ~20 ~16 ~24 ~20 ~17 ~24 glass 0  
fill ~20 ~16 ~26 ~20 ~17 ~26 glass 0  
fill ~20 ~16 ~27 ~20 ~17 ~27 stained_hardened_clay 14  
fill ~20 ~16 ~28 ~20 ~17 ~28 glass 0  
fill ~20 ~16 ~30 ~21 ~16 ~30 iron_block 0 
setblock ~21 ~16 ~21 oak_stairs 1  
fill ~21 ~16 ~23 ~21 ~17 ~23 glass 0  
fill ~21 ~16 ~27 ~21 ~17 ~27 glass 0 
setblock ~21 ~16 ~29 oak_stairs 1 
setblock ~22 ~16 ~20 trapdoor 9 
setblock ~22 ~16 ~21 oak_stairs 2  
fill ~22 ~16 ~25 ~22 ~44 ~25 iron_block 0 
setblock ~22 ~16 ~29 oak_stairs 3 
setblock ~22 ~16 ~30 trapdoor 8 
setblock ~23 ~16 ~18 redstone_torch 4  
fill ~23 ~16 ~19 ~23 ~19 ~19 iron_block 0  
fill ~23 ~16 ~25 ~23 ~42 ~25 ladder 5  
fill ~23 ~16 ~31 ~23 ~19 ~31 iron_block 0 
setblock ~23 ~16 ~32 redstone_torch 3 
setblock ~24 ~16 ~20 trapdoor 9 
setblock ~24 ~16 ~21 oak_stairs 2  
fill ~24 ~16 ~25 ~24 ~24 ~25 iron_block 0 
setblock ~24 ~16 ~29 oak_stairs 3 
setblock ~24 ~16 ~30 trapdoor 8  
fill ~25 ~16 ~20 ~26 ~16 ~20 iron_block 0 
setblock ~25 ~16 ~21 oak_stairs 0  
fill ~25 ~16 ~23 ~25 ~17 ~23 glass 0  
fill ~25 ~16 ~27 ~25 ~17 ~27 glass 0 
setblock ~25 ~16 ~29 oak_stairs 0  
fill ~25 ~16 ~30 ~26 ~16 ~30 iron_block 0  
fill ~26 ~16 ~22 ~26 ~17 ~22 glass 0  
fill ~26 ~16 ~23 ~26 ~17 ~23 stained_hardened_clay 14  
fill ~26 ~16 ~24 ~26 ~17 ~24 glass 0  
fill ~26 ~16 ~26 ~26 ~17 ~26 glass 0  
fill ~26 ~16 ~27 ~26 ~17 ~27 stained_hardened_clay 14  
fill ~26 ~16 ~28 ~26 ~17 ~28 glass 0 
setblock ~27 ~16 ~20 redstone_torch 4  
fill ~27 ~16 ~21 ~27 ~18 ~21 iron_block 0  
fill ~27 ~16 ~23 ~27 ~17 ~23 glass 0  
fill ~27 ~16 ~27 ~27 ~17 ~27 glass 0  
fill ~27 ~16 ~29 ~27 ~18 ~29 iron_block 0 
setblock ~27 ~16 ~30 redstone_torch 3 
setblock ~28 ~16 ~21 redstone_torch 1  
fill ~28 ~16 ~22 ~28 ~19 ~22 iron_block 0  
fill ~28 ~16 ~28 ~28 ~19 ~28 iron_block 0 
setblock ~28 ~16 ~29 redstone_torch 1  
fill ~29 ~16 ~24 ~29 ~19 ~24 iron_block 0  
fill ~29 ~16 ~25 ~29 ~19 ~25 iron_block 0  
fill ~29 ~16 ~26 ~29 ~19 ~26 iron_block 0 
setblock ~30 ~16 ~25 redstone_torch 1  
fill ~16 ~17 ~24 ~16 ~18 ~24 iron_block 0  
fill ~16 ~17 ~25 ~16 ~17 ~26 iron_block 0  
fill ~17 ~17 ~22 ~17 ~18 ~22 iron_block 0  
fill ~17 ~17 ~23 ~17 ~18 ~23 iron_block 0  
fill ~17 ~17 ~27 ~17 ~18 ~27 iron_block 0  
fill ~17 ~17 ~28 ~17 ~18 ~28 iron_block 0  
fill ~18 ~17 ~21 ~18 ~18 ~21 iron_block 0  
fill ~18 ~17 ~29 ~18 ~18 ~29 iron_block 0  
fill ~19 ~17 ~20 ~21 ~17 ~20 iron_block 0  
fill ~19 ~17 ~30 ~21 ~17 ~30 iron_block 0  
fill ~20 ~17 ~19 ~26 ~17 ~19 iron_block 0  
fill ~20 ~17 ~31 ~26 ~17 ~31 iron_block 0  
fill ~22 ~17 ~18 ~24 ~17 ~18 iron_block 0  
fill ~22 ~17 ~32 ~24 ~17 ~32 iron_block 0  
fill ~25 ~17 ~20 ~27 ~17 ~20 iron_block 0  
fill ~25 ~17 ~30 ~27 ~17 ~30 iron_block 0  
fill ~28 ~17 ~21 ~28 ~18 ~21 iron_block 0  
fill ~28 ~17 ~29 ~28 ~18 ~29 iron_block 0  
fill ~29 ~17 ~22 ~29 ~18 ~22 iron_block 0  
fill ~29 ~17 ~23 ~29 ~18 ~23 iron_block 0  
fill ~29 ~17 ~27 ~29 ~18 ~27 iron_block 0  
fill ~29 ~17 ~28 ~29 ~18 ~28 iron_block 0  
fill ~30 ~17 ~24 ~30 ~18 ~24 iron_block 0  
fill ~30 ~17 ~25 ~30 ~17 ~26 iron_block 0 
setblock ~16 ~18 ~25 glowstone 0 
setblock ~16 ~18 ~26 iron_block 0  
fill ~18 ~18 ~24 ~30 ~18 ~24 iron_block 0  
fill ~18 ~18 ~26 ~30 ~18 ~26 iron_block 0  
fill ~19 ~18 ~20 ~27 ~18 ~20 iron_block 0  
fill ~19 ~18 ~22 ~29 ~18 ~22 iron_block 0  
fill ~19 ~18 ~23 ~22 ~18 ~23 iron_block 0  
fill ~19 ~18 ~27 ~22 ~18 ~27 iron_block 0  
fill ~19 ~18 ~28 ~29 ~18 ~28 iron_block 0  
fill ~19 ~18 ~30 ~27 ~18 ~30 iron_block 0  
fill ~20 ~18 ~19 ~26 ~18 ~19 iron_block 0  
fill ~20 ~18 ~21 ~28 ~18 ~21 iron_block 0  
fill ~20 ~18 ~29 ~28 ~18 ~29 iron_block 0  
fill ~20 ~18 ~31 ~26 ~18 ~31 iron_block 0 
setblock ~21 ~18 ~25 iron_block 0  
fill ~22 ~18 ~18 ~22 ~17 ~18 iron_block 0  
fill ~22 ~18 ~32 ~22 ~17 ~32 iron_block 0 
setblock ~23 ~18 ~18 glowstone 0 
setblock ~23 ~18 ~23 glowstone 0 
setblock ~23 ~18 ~27 glowstone 0 
setblock ~23 ~18 ~32 glowstone 0 
setblock ~24 ~18 ~18 iron_block 0  
fill ~24 ~18 ~23 ~29 ~18 ~23 iron_block 0  
fill ~24 ~18 ~27 ~29 ~18 ~27 iron_block 0 
setblock ~24 ~18 ~32 iron_block 0 
setblock ~25 ~18 ~25 iron_block 0 
setblock ~30 ~18 ~25 glowstone 0 
setblock ~19 ~19 ~21 glowstone 0 
setblock ~19 ~19 ~29 glowstone 0  
fill ~20 ~19 ~20 ~21 ~19 ~20 iron_block 0  
fill ~20 ~19 ~23 ~21 ~19 ~23 fence 0  
fill ~20 ~19 ~24 ~20 ~19 ~23 fence 0  
fill ~20 ~19 ~26 ~20 ~19 ~27 fence 0  
fill ~20 ~19 ~30 ~21 ~19 ~30 iron_block 0  
fill ~21 ~19 ~24 ~22 ~19 ~24 oak_stairs 2  
fill ~21 ~19 ~25 ~21 ~19 ~26 oak_stairs 0 
setblock ~21 ~19 ~27 fence 0 
setblock ~22 ~19 ~26 oak_stairs 3 
setblock ~24 ~19 ~24 oak_stairs 2  
fill ~24 ~19 ~26 ~25 ~19 ~26 oak_stairs 3  
fill ~25 ~19 ~20 ~26 ~19 ~20 iron_block 0  
fill ~25 ~19 ~23 ~26 ~19 ~23 fence 0  
fill ~25 ~19 ~24 ~25 ~19 ~25 oak_stairs 1  
fill ~25 ~19 ~27 ~26 ~19 ~27 fence 0  
fill ~25 ~19 ~30 ~26 ~19 ~30 iron_block 0 
setblock ~26 ~19 ~24 fence 0 
setblock ~26 ~19 ~26 fence 0 
setblock ~27 ~19 ~21 glowstone 0 
setblock ~27 ~19 ~29 glowstone 0 
setblock ~17 ~20 ~24 glass 0 
setblock ~17 ~20 ~25 planks 1 
setblock ~17 ~20 ~26 glass 0  
fill ~18 ~20 ~22 ~18 ~20 ~23 glass 0  
fill ~18 ~20 ~27 ~18 ~20 ~28 glass 0 
setblock ~19 ~20 ~21 planks 1 
setblock ~19 ~20 ~29 planks 1  
fill ~20 ~20 ~20 ~21 ~20 ~20 glass 0  
fill ~20 ~20 ~23 ~21 ~20 ~23 wooden_pressure_plate 0  
fill ~20 ~20 ~24 ~20 ~20 ~23 wooden_pressure_plate 0  
fill ~20 ~20 ~30 ~21 ~20 ~30 glass 0 
setblock ~22 ~20 ~19 glass 0 
setblock ~22 ~20 ~31 glass 0 
setblock ~23 ~20 ~19 planks 1 
setblock ~23 ~20 ~31 planks 1 
setblock ~24 ~20 ~19 glass 0 
setblock ~24 ~20 ~31 glass 0  
fill ~25 ~20 ~20 ~26 ~20 ~20 glass 0  
fill ~25 ~20 ~23 ~26 ~20 ~23 wooden_pressure_plate 0  
fill ~25 ~20 ~27 ~26 ~20 ~27 wooden_pressure_plate 0  
fill ~25 ~20 ~30 ~26 ~20 ~30 glass 0 
setblock ~26 ~20 ~24 wooden_pressure_plate 0 
setblock ~26 ~20 ~26 wooden_pressure_plate 0 
setblock ~27 ~20 ~21 planks 1 
setblock ~27 ~20 ~29 planks 1  
fill ~28 ~20 ~22 ~28 ~20 ~23 glass 0  
fill ~28 ~20 ~27 ~28 ~20 ~28 glass 0 
setblock ~29 ~20 ~24 glass 0 
setblock ~29 ~20 ~25 planks 1 
setblock ~29 ~20 ~26 glass 0  
fill ~18 ~21 ~24 ~28 ~21 ~24 iron_block 0  
fill ~18 ~21 ~25 ~22 ~21 ~25 iron_block 0  
fill ~18 ~21 ~26 ~28 ~21 ~26 iron_block 0  
fill ~19 ~21 ~22 ~27 ~21 ~22 iron_block 0  
fill ~19 ~21 ~23 ~27 ~21 ~23 iron_block 0  
fill ~19 ~21 ~27 ~27 ~21 ~27 iron_block 0  
fill ~19 ~21 ~28 ~27 ~21 ~28 iron_block 0  
fill ~20 ~21 ~21 ~26 ~21 ~21 iron_block 0  
fill ~20 ~21 ~29 ~26 ~21 ~29 iron_block 0  
fill ~22 ~21 ~20 ~24 ~21 ~20 iron_block 0  
fill ~22 ~21 ~30 ~24 ~21 ~30 iron_block 0  
fill ~25 ~21 ~25 ~28 ~21 ~25 iron_block 0  
fill ~19 ~22 ~24 ~19 ~22 ~26 iron_block 0  
fill ~20 ~22 ~22 ~21 ~22 ~22 iron_block 0  
fill ~20 ~22 ~23 ~20 ~22 ~22 iron_block 0  
fill ~20 ~22 ~27 ~20 ~22 ~28 iron_block 0 
setblock ~21 ~22 ~28 iron_block 0  
fill ~22 ~22 ~21 ~24 ~22 ~21 iron_block 0  
fill ~22 ~22 ~29 ~24 ~22 ~29 iron_block 0  
fill ~23 ~22 ~24 ~23 ~40 ~24 iron_block 0  
fill ~23 ~22 ~26 ~23 ~40 ~26 iron_block 0  
fill ~25 ~22 ~22 ~26 ~22 ~22 iron_block 0  
fill ~25 ~22 ~28 ~26 ~22 ~28 iron_block 0 
setblock ~26 ~22 ~23 iron_block 0 
setblock ~26 ~22 ~27 iron_block 0  
fill ~27 ~22 ~24 ~27 ~22 ~26 iron_block 0  
fill ~20 ~23 ~24 ~20 ~28 ~24 iron_block 0  
fill ~20 ~23 ~25 ~20 ~23 ~26 iron_block 0  
fill ~21 ~23 ~23 ~21 ~41 ~23 iron_block 0  
fill ~21 ~23 ~27 ~21 ~41 ~27 iron_block 0  
fill ~22 ~23 ~22 ~24 ~23 ~22 iron_block 0  
fill ~22 ~23 ~28 ~24 ~23 ~28 iron_block 0  
fill ~25 ~23 ~23 ~25 ~41 ~23 iron_block 0  
fill ~25 ~23 ~27 ~25 ~41 ~27 iron_block 0  
fill ~26 ~23 ~24 ~26 ~28 ~24 iron_block 0  
fill ~26 ~23 ~25 ~26 ~23 ~26 iron_block 0  
fill ~20 ~24 ~25 ~21 ~24 ~25 glowstone 0  
fill ~20 ~24 ~26 ~26 ~24 ~26 iron_block 0  
fill ~21 ~24 ~24 ~26 ~24 ~24 iron_block 0  
fill ~22 ~24 ~22 ~22 ~28 ~22 iron_block 0  
fill ~22 ~24 ~23 ~22 ~34 ~23 iron_block 0  
fill ~22 ~24 ~27 ~22 ~34 ~27 iron_block 0  
fill ~22 ~24 ~28 ~22 ~28 ~28 iron_block 0  
fill ~23 ~24 ~22 ~23 ~24 ~23 glowstone 0  
fill ~23 ~24 ~27 ~23 ~24 ~28 glowstone 0  
fill ~24 ~24 ~22 ~24 ~28 ~22 iron_block 0  
fill ~24 ~24 ~23 ~24 ~34 ~23 iron_block 0  
fill ~24 ~24 ~27 ~24 ~34 ~27 iron_block 0  
fill ~24 ~24 ~28 ~24 ~28 ~28 iron_block 0  
fill ~25 ~24 ~25 ~26 ~24 ~25 glowstone 0 
setblock ~20 ~25 ~23 redstone_torch 2  
fill ~20 ~25 ~25 ~20 ~26 ~25 fence 0  
fill ~20 ~25 ~26 ~21 ~25 ~26 iron_block 0 
setblock ~20 ~25 ~27 redstone_torch 2 
setblock ~21 ~25 ~22 redstone_torch 4  
fill ~21 ~25 ~24 ~21 ~34 ~24 iron_block 0  
fill ~21 ~25 ~25 ~21 ~27 ~25 iron_block 0 
setblock ~21 ~25 ~28 redstone_torch 3  
fill ~23 ~25 ~22 ~23 ~26 ~22 fence 0  
fill ~23 ~25 ~23 ~23 ~27 ~23 iron_block 0  
fill ~23 ~25 ~27 ~23 ~27 ~27 iron_block 0  
fill ~23 ~25 ~28 ~23 ~26 ~28 fence 0 
setblock ~24 ~25 ~25 glowstone 0 
setblock ~25 ~25 ~22 redstone_torch 4  
fill ~25 ~25 ~24 ~25 ~34 ~24 iron_block 0  
fill ~25 ~25 ~25 ~25 ~27 ~25 iron_block 0  
fill ~25 ~25 ~26 ~26 ~25 ~26 iron_block 0 
setblock ~25 ~25 ~28 redstone_torch 3 
setblock ~26 ~25 ~23 redstone_torch 1  
fill ~26 ~25 ~25 ~26 ~26 ~25 fence 0 
setblock ~26 ~25 ~27 redstone_torch 1  
fill ~20 ~26 ~26 ~21 ~26 ~26 iron_block 0  
fill ~24 ~26 ~25 ~24 ~31 ~25 iron_block 0  
fill ~25 ~26 ~26 ~26 ~26 ~26 iron_block 0  
fill ~20 ~27 ~25 ~20 ~28 ~25 iron_block 0  
fill ~20 ~27 ~26 ~21 ~27 ~26 iron_block 0  
fill ~23 ~27 ~22 ~23 ~28 ~22 iron_block 0  
fill ~23 ~27 ~28 ~23 ~28 ~28 iron_block 0  
fill ~25 ~27 ~26 ~26 ~27 ~26 iron_block 0  
fill ~26 ~27 ~25 ~26 ~28 ~25 iron_block 0  
fill ~19 ~28 ~24 ~19 ~28 ~26 iron_block 0 
setblock ~20 ~28 ~23 iron_block 0  
fill ~20 ~28 ~26 ~21 ~28 ~26 iron_block 0  
fill ~20 ~28 ~27 ~20 ~28 ~23 iron_block 0 
setblock ~21 ~28 ~22 iron_block 0 
setblock ~21 ~28 ~25 glowstone 0 
setblock ~21 ~28 ~28 iron_block 0  
fill ~22 ~28 ~21 ~24 ~28 ~21 iron_block 0  
fill ~22 ~28 ~29 ~24 ~28 ~29 iron_block 0 
setblock ~23 ~28 ~23 glowstone 0 
setblock ~23 ~28 ~27 glowstone 0 
setblock ~25 ~28 ~22 iron_block 0 
setblock ~25 ~28 ~25 glowstone 0  
fill ~25 ~28 ~26 ~27 ~28 ~26 iron_block 0 
setblock ~25 ~28 ~28 iron_block 0 
setblock ~26 ~28 ~23 iron_block 0 
setblock ~26 ~28 ~27 iron_block 0  
fill ~27 ~28 ~24 ~27 ~28 ~26 iron_block 0  
fill ~18 ~29 ~24 ~18 ~30 ~24 iron_block 0  
fill ~18 ~29 ~25 ~18 ~29 ~26 iron_block 0  
fill ~19 ~29 ~23 ~19 ~30 ~23 iron_block 0  
fill ~19 ~29 ~27 ~19 ~30 ~27 iron_block 0 
setblock ~20 ~29 ~22 glowstone 0 
setblock ~20 ~29 ~25 glowstone 0 
setblock ~20 ~29 ~28 glowstone 0  
fill ~21 ~29 ~21 ~21 ~30 ~21 iron_block 0  
fill ~21 ~29 ~25 ~21 ~31 ~25 iron_block 0  
fill ~21 ~29 ~26 ~21 ~34 ~26 iron_block 0  
fill ~21 ~29 ~29 ~21 ~30 ~29 iron_block 0  
fill ~22 ~29 ~20 ~24 ~29 ~20 iron_block 0  
fill ~22 ~29 ~30 ~24 ~29 ~30 iron_block 0 
setblock ~23 ~29 ~22 glowstone 0  
fill ~23 ~29 ~23 ~23 ~31 ~23 iron_block 0  
fill ~23 ~29 ~27 ~23 ~31 ~27 iron_block 0 
setblock ~23 ~29 ~28 glowstone 0  
fill ~25 ~29 ~21 ~25 ~30 ~21 iron_block 0  
fill ~25 ~29 ~25 ~25 ~31 ~25 iron_block 0  
fill ~25 ~29 ~26 ~25 ~34 ~26 iron_block 0  
fill ~25 ~29 ~29 ~25 ~30 ~29 iron_block 0 
setblock ~26 ~29 ~22 glowstone 0 
setblock ~26 ~29 ~25 glowstone 0 
setblock ~26 ~29 ~28 glowstone 0  
fill ~27 ~29 ~23 ~27 ~30 ~23 iron_block 0  
fill ~27 ~29 ~27 ~27 ~30 ~27 iron_block 0  
fill ~28 ~29 ~24 ~28 ~30 ~24 iron_block 0  
fill ~28 ~29 ~25 ~28 ~29 ~26 iron_block 0 
setblock ~18 ~30 ~25 glowstone 0 
setblock ~18 ~30 ~26 iron_block 0 
setblock ~20 ~30 ~22 iron_block 0  
fill ~20 ~30 ~25 ~20 ~31 ~25 iron_block 0 
setblock ~20 ~30 ~28 iron_block 0  
fill ~22 ~30 ~20 ~22 ~29 ~20 iron_block 0  
fill ~22 ~30 ~30 ~22 ~29 ~30 iron_block 0 
setblock ~23 ~30 ~20 glowstone 0  
fill ~23 ~30 ~22 ~23 ~31 ~22 iron_block 0  
fill ~23 ~30 ~28 ~23 ~31 ~28 iron_block 0 
setblock ~23 ~30 ~30 glowstone 0 
setblock ~24 ~30 ~20 iron_block 0 
setblock ~24 ~30 ~30 iron_block 0 
setblock ~26 ~30 ~22 iron_block 0  
fill ~26 ~30 ~25 ~26 ~31 ~25 iron_block 0 
setblock ~26 ~30 ~28 iron_block 0 
setblock ~28 ~30 ~25 glowstone 0 
setblock ~28 ~30 ~26 iron_block 0 
setblock ~16 ~31 ~25 redstone_torch 2  
fill ~17 ~31 ~24 ~17 ~32 ~24 iron_block 0  
fill ~17 ~31 ~25 ~17 ~32 ~25 iron_block 0  
fill ~17 ~31 ~26 ~17 ~32 ~26 iron_block 0  
fill ~18 ~31 ~23 ~18 ~32 ~23 iron_block 0  
fill ~18 ~31 ~27 ~18 ~32 ~27 iron_block 0  
fill ~19 ~31 ~22 ~19 ~32 ~22 iron_block 0  
fill ~19 ~31 ~28 ~19 ~32 ~28 iron_block 0  
fill ~20 ~31 ~21 ~20 ~32 ~21 iron_block 0  
fill ~20 ~31 ~29 ~20 ~32 ~29 iron_block 0  
fill ~21 ~31 ~20 ~21 ~32 ~20 iron_block 0  
fill ~21 ~31 ~30 ~21 ~32 ~30 iron_block 0  
fill ~22 ~31 ~19 ~24 ~31 ~19 iron_block 0  
fill ~22 ~31 ~31 ~24 ~31 ~31 iron_block 0 
setblock ~23 ~31 ~18 redstone_torch 4 
setblock ~23 ~31 ~32 redstone_torch 3  
fill ~25 ~31 ~20 ~25 ~32 ~20 iron_block 0  
fill ~25 ~31 ~30 ~25 ~32 ~30 iron_block 0  
fill ~26 ~31 ~21 ~26 ~32 ~21 iron_block 0  
fill ~26 ~31 ~29 ~26 ~32 ~29 iron_block 0  
fill ~27 ~31 ~22 ~27 ~32 ~22 iron_block 0  
fill ~27 ~31 ~28 ~27 ~32 ~28 iron_block 0  
fill ~28 ~31 ~23 ~28 ~32 ~23 iron_block 0  
fill ~28 ~31 ~27 ~28 ~32 ~27 iron_block 0  
fill ~29 ~31 ~24 ~29 ~32 ~24 iron_block 0  
fill ~29 ~31 ~25 ~29 ~32 ~25 iron_block 0  
fill ~29 ~31 ~26 ~29 ~32 ~26 iron_block 0 
setblock ~30 ~31 ~25 redstone_torch 1 
setblock ~20 ~32 ~25 glowstone 0  
fill ~22 ~32 ~19 ~24 ~32 ~19 iron_block 0  
fill ~22 ~32 ~31 ~24 ~32 ~31 iron_block 0 
setblock ~23 ~32 ~22 glowstone 0 
setblock ~23 ~32 ~28 glowstone 0 
setblock ~24 ~32 ~25 glowstone 0 
setblock ~26 ~32 ~25 glowstone 0  
fill ~18 ~33 ~24 ~18 ~34 ~24 iron_block 0 
setblock ~18 ~33 ~25 glowstone 0  
fill ~18 ~33 ~26 ~18 ~34 ~26 iron_block 0  
fill ~19 ~33 ~23 ~19 ~34 ~23 iron_block 0  
fill ~19 ~33 ~27 ~19 ~34 ~27 iron_block 0 
setblock ~20 ~33 ~22 iron_block 0  
fill ~20 ~33 ~25 ~20 ~35 ~25 iron_block 0 
setblock ~20 ~33 ~28 iron_block 0  
fill ~21 ~33 ~21 ~21 ~34 ~21 iron_block 0  
fill ~21 ~33 ~29 ~21 ~34 ~29 iron_block 0  
fill ~22 ~33 ~20 ~22 ~34 ~20 iron_block 0  
fill ~22 ~33 ~30 ~22 ~34 ~30 iron_block 0 
setblock ~23 ~33 ~20 glowstone 0  
fill ~23 ~33 ~22 ~23 ~35 ~22 iron_block 0  
fill ~23 ~33 ~28 ~23 ~35 ~28 iron_block 0 
setblock ~23 ~33 ~30 glowstone 0  
fill ~24 ~33 ~20 ~24 ~34 ~20 iron_block 0  
fill ~24 ~33 ~25 ~24 ~37 ~25 iron_block 0  
fill ~24 ~33 ~30 ~24 ~34 ~30 iron_block 0  
fill ~25 ~33 ~21 ~25 ~34 ~21 iron_block 0  
fill ~25 ~33 ~29 ~25 ~34 ~29 iron_block 0 
setblock ~26 ~33 ~22 iron_block 0  
fill ~26 ~33 ~25 ~26 ~35 ~25 iron_block 0 
setblock ~26 ~33 ~28 iron_block 0  
fill ~27 ~33 ~23 ~27 ~34 ~23 iron_block 0  
fill ~27 ~33 ~27 ~27 ~34 ~27 iron_block 0  
fill ~28 ~33 ~24 ~28 ~34 ~24 iron_block 0 
setblock ~28 ~33 ~25 glowstone 0  
fill ~28 ~33 ~26 ~28 ~34 ~26 iron_block 0 
setblock ~18 ~34 ~25 iron_block 0 
setblock ~20 ~34 ~22 glowstone 0 
setblock ~20 ~34 ~28 glowstone 0 
setblock ~23 ~34 ~20 iron_block 0 
setblock ~23 ~34 ~30 iron_block 0 
setblock ~26 ~34 ~22 glowstone 0 
setblock ~26 ~34 ~28 glowstone 0 
setblock ~28 ~34 ~25 iron_block 0  
fill ~19 ~35 ~24 ~20 ~35 ~24 iron_block 0  
fill ~19 ~35 ~25 ~19 ~35 ~26 iron_block 0 
setblock ~20 ~35 ~23 iron_block 0  
fill ~20 ~35 ~26 ~20 ~41 ~26 iron_block 0  
fill ~20 ~35 ~27 ~20 ~35 ~23 iron_block 0  
fill ~21 ~35 ~22 ~25 ~35 ~22 iron_block 0  
fill ~21 ~35 ~28 ~25 ~35 ~28 iron_block 0  
fill ~22 ~35 ~21 ~24 ~35 ~21 iron_block 0  
fill ~22 ~35 ~29 ~24 ~35 ~29 iron_block 0  
fill ~26 ~35 ~23 ~26 ~35 ~27 iron_block 0  
fill ~27 ~35 ~24 ~27 ~35 ~26 iron_block 0  
fill ~20 ~36 ~24 ~20 ~41 ~24 iron_block 0 
setblock ~20 ~36 ~25 glowstone 0  
fill ~21 ~36 ~25 ~21 ~39 ~25 iron_block 0  
fill ~22 ~36 ~22 ~22 ~43 ~22 iron_block 0  
fill ~22 ~36 ~28 ~22 ~43 ~28 iron_block 0 
setblock ~23 ~36 ~22 glowstone 0  
fill ~23 ~36 ~23 ~23 ~39 ~23 iron_block 0 
setblock ~23 ~36 ~28 glowstone 0  
fill ~24 ~36 ~22 ~24 ~43 ~22 iron_block 0  
fill ~24 ~36 ~28 ~24 ~43 ~28 iron_block 0  
fill ~25 ~36 ~25 ~25 ~39 ~25 iron_block 0  
fill ~26 ~36 ~24 ~26 ~41 ~24 iron_block 0 
setblock ~26 ~36 ~25 glowstone 0  
fill ~26 ~36 ~26 ~26 ~41 ~26 iron_block 0  
fill ~20 ~37 ~25 ~20 ~39 ~25 fence 0  
fill ~23 ~37 ~22 ~23 ~39 ~22 fence 0  
fill ~23 ~37 ~27 ~23 ~39 ~27 iron_block 0  
fill ~23 ~37 ~28 ~23 ~39 ~28 fence 0  
fill ~26 ~37 ~25 ~26 ~39 ~25 fence 0 
setblock ~20 ~38 ~23 redstone_torch 2 
setblock ~20 ~38 ~27 redstone_torch 2 
setblock ~21 ~38 ~22 redstone_torch 4 
setblock ~21 ~38 ~28 redstone_torch 3 
setblock ~24 ~38 ~25 glowstone 0 
setblock ~25 ~38 ~22 redstone_torch 4 
setblock ~25 ~38 ~28 redstone_torch 3 
setblock ~26 ~38 ~23 redstone_torch 1 
setblock ~26 ~38 ~27 redstone_torch 1  
fill ~24 ~39 ~25 ~24 ~43 ~25 iron_block 0 
setblock ~20 ~40 ~25 glowstone 0  
fill ~23 ~40 ~22 ~23 ~40 ~23 glowstone 0  
fill ~23 ~40 ~27 ~23 ~40 ~28 glowstone 0 
setblock ~26 ~40 ~25 glowstone 0 
setblock ~19 ~41 ~24 stone_slab 8 
setblock ~19 ~41 ~26 stone_slab 8 
setblock ~20 ~41 ~23 stone_slab 8 
setblock ~20 ~41 ~25 iron_block 0 
setblock ~20 ~41 ~27 stone_slab 8 
setblock ~21 ~41 ~22 stone_slab 8 
setblock ~21 ~41 ~28 stone_slab 8  
fill ~22 ~41 ~21 ~24 ~41 ~21 stone_slab 8  
fill ~22 ~41 ~23 ~22 ~43 ~23 iron_block 0  
fill ~22 ~41 ~24 ~22 ~43 ~24 iron_block 0  
fill ~22 ~41 ~26 ~22 ~43 ~26 iron_block 0  
fill ~22 ~41 ~27 ~22 ~43 ~27 iron_block 0 
setblock ~22 ~41 ~29 stone_slab 8  
fill ~23 ~41 ~22 ~23 ~45 ~22 iron_block 0  
fill ~23 ~41 ~23 ~23 ~45 ~23 ladder 3  
fill ~23 ~41 ~27 ~23 ~45 ~27 ladder 2  
fill ~23 ~41 ~28 ~23 ~45 ~28 iron_block 0  
fill ~24 ~41 ~23 ~24 ~43 ~23 iron_block 0  
fill ~24 ~41 ~24 ~24 ~43 ~24 iron_block 0  
fill ~24 ~41 ~26 ~24 ~43 ~26 iron_block 0  
fill ~24 ~41 ~27 ~24 ~43 ~27 iron_block 0 
setblock ~24 ~41 ~29 stone_slab 8 
setblock ~25 ~41 ~22 stone_slab 8 
setblock ~25 ~41 ~28 stone_slab 8 
setblock ~26 ~41 ~23 stone_slab 8 
setblock ~26 ~41 ~25 iron_block 0 
setblock ~26 ~41 ~27 stone_slab 8 
setblock ~27 ~41 ~24 stone_slab 8 
setblock ~27 ~41 ~26 stone_slab 8  
fill ~18 ~42 ~24 ~19 ~42 ~24 iron_block 0  
fill ~18 ~42 ~25 ~19 ~42 ~25 iron_block 0  
fill ~18 ~42 ~26 ~19 ~42 ~26 iron_block 0  
fill ~19 ~42 ~22 ~27 ~42 ~22 iron_block 0  
fill ~19 ~42 ~23 ~20 ~42 ~23 iron_block 0  
fill ~19 ~42 ~27 ~20 ~42 ~27 iron_block 0  
fill ~19 ~42 ~28 ~27 ~42 ~28 iron_block 0  
fill ~20 ~42 ~21 ~26 ~42 ~21 iron_block 0  
fill ~20 ~42 ~29 ~26 ~42 ~29 iron_block 0  
fill ~22 ~42 ~20 ~24 ~42 ~20 iron_block 0  
fill ~22 ~42 ~30 ~24 ~42 ~30 iron_block 0  
fill ~26 ~42 ~23 ~27 ~42 ~23 iron_block 0  
fill ~26 ~42 ~27 ~27 ~42 ~27 iron_block 0  
fill ~27 ~42 ~24 ~28 ~42 ~24 iron_block 0  
fill ~27 ~42 ~25 ~28 ~42 ~25 iron_block 0  
fill ~27 ~42 ~26 ~28 ~42 ~26 iron_block 0  
fill ~16 ~43 ~24 ~30 ~43 ~24 iron_block 0  
fill ~16 ~43 ~25 ~30 ~43 ~25 iron_block 0  
fill ~16 ~43 ~26 ~30 ~43 ~26 iron_block 0 
setblock ~17 ~43 ~20 redstone_torch 4  
fill ~17 ~43 ~21 ~18 ~43 ~21 iron_block 0  
fill ~17 ~43 ~22 ~29 ~43 ~22 iron_block 0  
fill ~17 ~43 ~23 ~22 ~43 ~23 iron_block 0  
fill ~17 ~43 ~27 ~22 ~43 ~27 iron_block 0  
fill ~17 ~43 ~28 ~29 ~43 ~28 iron_block 0  
fill ~17 ~43 ~29 ~18 ~43 ~29 iron_block 0 
setblock ~17 ~43 ~30 redstone_torch 3 
setblock ~18 ~43 ~19 redstone_torch 2  
fill ~18 ~43 ~20 ~28 ~43 ~20 iron_block 0  
fill ~18 ~43 ~30 ~28 ~43 ~30 iron_block 0 
setblock ~18 ~43 ~31 redstone_torch 2  
fill ~19 ~43 ~19 ~27 ~43 ~19 iron_block 0 
setblock ~19 ~43 ~21 glowstone 0 
setblock ~19 ~43 ~29 glowstone 0  
fill ~19 ~43 ~31 ~27 ~43 ~31 iron_block 0  
fill ~20 ~43 ~21 ~26 ~43 ~21 iron_block 0  
fill ~20 ~43 ~29 ~26 ~43 ~29 iron_block 0  
fill ~22 ~43 ~18 ~24 ~43 ~18 iron_block 0  
fill ~22 ~43 ~32 ~24 ~43 ~32 iron_block 0  
fill ~25 ~43 ~23 ~29 ~43 ~23 iron_block 0  
fill ~25 ~43 ~27 ~29 ~43 ~27 iron_block 0 
setblock ~27 ~43 ~21 glowstone 0 
setblock ~27 ~43 ~29 glowstone 0 
setblock ~28 ~43 ~19 redstone_torch 1  
fill ~28 ~43 ~21 ~29 ~43 ~21 iron_block 0  
fill ~28 ~43 ~29 ~29 ~43 ~29 iron_block 0 
setblock ~28 ~43 ~31 redstone_torch 1 
setblock ~29 ~43 ~20 redstone_torch 4 
setblock ~29 ~43 ~30 redstone_torch 3  
fill ~15 ~44 ~24 ~15 ~55 ~24 iron_block 0 
setblock ~15 ~44 ~25 glowstone 0  
fill ~15 ~44 ~26 ~15 ~55 ~26 iron_block 0  
fill ~16 ~44 ~21 ~16 ~55 ~21 iron_block 0  
fill ~16 ~44 ~22 ~16 ~51 ~22 iron_block 0  
fill ~16 ~44 ~23 ~16 ~55 ~23 iron_block 0  
fill ~16 ~44 ~27 ~16 ~55 ~27 iron_block 0  
fill ~16 ~44 ~28 ~16 ~51 ~28 iron_block 0  
fill ~16 ~44 ~29 ~16 ~55 ~29 iron_block 0  
fill ~17 ~44 ~19 ~18 ~44 ~19 iron_block 0  
fill ~17 ~44 ~20 ~17 ~55 ~20 iron_block 0 
setblock ~17 ~44 ~21 oak_stairs 3  
fill ~17 ~44 ~22 ~17 ~44 ~23 oak_stairs 1 
setblock ~17 ~44 ~24 oak_stairs 2 
setblock ~17 ~44 ~26 oak_stairs 3  
fill ~17 ~44 ~27 ~17 ~44 ~28 oak_stairs 1 
setblock ~17 ~44 ~29 oak_stairs 2  
fill ~17 ~44 ~30 ~17 ~55 ~30 iron_block 0  
fill ~17 ~44 ~31 ~18 ~44 ~31 iron_block 0  
fill ~18 ~44 ~20 ~18 ~55 ~20 fence 0  
fill ~18 ~44 ~22 ~18 ~44 ~23 fence 0  
fill ~18 ~44 ~27 ~18 ~44 ~28 fence 0  
fill ~19 ~44 ~18 ~21 ~44 ~18 iron_block 0  
fill ~19 ~44 ~32 ~21 ~44 ~32 iron_block 0 
setblock ~20 ~44 ~19 trapdoor 9 
setblock ~20 ~44 ~20 oak_stairs 2 
setblock ~20 ~44 ~25 oak_stairs 1 
setblock ~20 ~44 ~30 oak_stairs 3 
setblock ~20 ~44 ~31 trapdoor 8  
fill ~21 ~44 ~19 ~21 ~45 ~19 iron_block 0 
setblock ~21 ~44 ~25 trapdoor 10  
fill ~21 ~44 ~31 ~21 ~45 ~31 iron_block 0  
fill ~22 ~44 ~17 ~22 ~55 ~17 iron_block 0  
fill ~22 ~44 ~24 ~22 ~71 ~24 fence 0  
fill ~22 ~44 ~26 ~22 ~71 ~26 fence 0  
fill ~22 ~44 ~33 ~22 ~55 ~33 iron_block 0 
setblock ~23 ~44 ~17 glowstone 0  
fill ~23 ~44 ~18 ~23 ~53 ~18 ladder 2  
fill ~23 ~44 ~19 ~23 ~53 ~19 iron_block 0 
setblock ~23 ~44 ~24 iron_block 0  
fill ~23 ~44 ~25 ~23 ~47 ~25 stained_hardened_clay 14 
setblock ~23 ~44 ~26 iron_block 0  
fill ~23 ~44 ~31 ~23 ~53 ~31 iron_block 0  
fill ~23 ~44 ~32 ~23 ~53 ~32 ladder 3 
setblock ~23 ~44 ~33 glowstone 0  
fill ~24 ~44 ~17 ~24 ~55 ~17 iron_block 0  
fill ~24 ~44 ~24 ~24 ~71 ~24 fence 0 
setblock ~24 ~44 ~25 glowstone 0  
fill ~24 ~44 ~26 ~24 ~71 ~26 fence 0  
fill ~24 ~44 ~33 ~24 ~55 ~33 iron_block 0  
fill ~25 ~44 ~18 ~27 ~44 ~18 iron_block 0  
fill ~25 ~44 ~19 ~25 ~45 ~19 iron_block 0 
setblock ~25 ~44 ~25 trapdoor 11  
fill ~25 ~44 ~31 ~25 ~45 ~31 iron_block 0  
fill ~25 ~44 ~32 ~27 ~44 ~32 iron_block 0 
setblock ~26 ~44 ~19 trapdoor 9 
setblock ~26 ~44 ~20 oak_stairs 2 
setblock ~26 ~44 ~25 oak_stairs 0 
setblock ~26 ~44 ~30 oak_stairs 3 
setblock ~26 ~44 ~31 trapdoor 8  
fill ~28 ~44 ~19 ~29 ~44 ~19 iron_block 0  
fill ~28 ~44 ~20 ~28 ~55 ~20 fence 0  
fill ~28 ~44 ~22 ~28 ~44 ~23 fence 0  
summon Painting ~-15.9375 ~88.5 ~32.5 
summon Painting ~-14.9375 ~88.5 ~35.5 
summon Painting ~-11.0625 ~88.5 ~32.5 
summon Painting ~-12.0625 ~88.5 ~35.5 
summon Painting ~20.5 ~45.5 ~19.0625 
summon Painting ~20.5 ~45.5 ~31.9375 
summon Painting ~22.5 ~17.5 ~20.0625 
summon Painting ~24.5 ~17.5 ~20.0625 
summon Painting ~26.5 ~45.5 ~19.0625 
summon Painting ~21.9375 ~45.5 ~25.5 
summon Painting ~25.0625 ~45.5 ~25.5 
summon Painting ~30.5 ~82.5 ~21.0625 
summon Painting ~32.5 ~82.5 ~21.0625 
summon Painting ~30.9375 ~82.5 ~25.5 
summon Painting ~34.5 ~82.5 ~21.0625 
summon Painting ~30.5 ~82.5 ~29.9375 
summon Painting ~32.5 ~82.5 ~29.9375 
summon Painting ~34.5 ~82.5 ~29.9375 
summon Painting ~24.5 ~17.5 ~30.9375 
summon Painting ~22.5 ~17.5 ~30.9375 
summon Painting ~26.5 ~45.5 ~31.9375  
fill ~28 ~44 ~27 ~28 ~44 ~28 fence 0  
fill ~28 ~44 ~30 ~28 ~55 ~30 fence 0  
fill ~28 ~44 ~31 ~29 ~44 ~31 iron_block 0  
fill ~29 ~44 ~20 ~29 ~55 ~20 iron_block 0 
setblock ~29 ~44 ~21 oak_stairs 3  
fill ~29 ~44 ~22 ~29 ~44 ~23 oak_stairs 0 
setblock ~29 ~44 ~24 oak_stairs 2 
setblock ~29 ~44 ~26 oak_stairs 3  
fill ~29 ~44 ~27 ~29 ~44 ~28 oak_stairs 0 
setblock ~29 ~44 ~29 oak_stairs 2  
fill ~29 ~44 ~30 ~29 ~55 ~30 iron_block 0  
fill ~30 ~44 ~21 ~30 ~55 ~21 iron_block 0  
fill ~30 ~44 ~22 ~30 ~51 ~22 iron_block 0  
fill ~30 ~44 ~23 ~30 ~55 ~23 iron_block 0  
fill ~30 ~44 ~27 ~30 ~55 ~27 iron_block 0  
fill ~30 ~44 ~28 ~30 ~51 ~28 iron_block 0  
fill ~30 ~44 ~29 ~30 ~55 ~29 iron_block 0  
fill ~31 ~44 ~24 ~31 ~55 ~24 iron_block 0 
setblock ~31 ~44 ~25 glowstone 0  
fill ~31 ~44 ~26 ~31 ~55 ~26 iron_block 0  
fill ~14 ~45 ~24 ~14 ~45 ~26 iron_block 0  
fill ~15 ~45 ~21 ~15 ~45 ~29 iron_block 0  
fill ~16 ~45 ~19 ~16 ~45 ~23 iron_block 0  
fill ~16 ~45 ~30 ~16 ~46 ~30 iron_block 0  
fill ~16 ~45 ~31 ~16 ~45 ~27 iron_block 0  
fill ~17 ~45 ~18 ~21 ~45 ~18 iron_block 0  
fill ~17 ~45 ~32 ~21 ~45 ~32 iron_block 0  
fill ~18 ~45 ~19 ~18 ~55 ~19 iron_block 0  
fill ~18 ~45 ~22 ~18 ~45 ~23 wooden_pressure_plate 0  
fill ~18 ~45 ~27 ~18 ~45 ~28 wooden_pressure_plate 0  
fill ~18 ~45 ~31 ~18 ~55 ~31 iron_block 0  
fill ~19 ~45 ~17 ~27 ~45 ~17 iron_block 0  
fill ~19 ~45 ~33 ~27 ~45 ~33 iron_block 0  
fill ~22 ~45 ~16 ~24 ~45 ~16 iron_block 0 
setblock ~22 ~45 ~25 glass 0  
fill ~22 ~45 ~34 ~24 ~45 ~34 iron_block 0  
fill ~23 ~45 ~24 ~23 ~46 ~24 glass 0 
setblock ~23 ~45 ~26 glowstone 0  
fill ~24 ~45 ~25 ~24 ~47 ~25 glass 0  
fill ~25 ~45 ~18 ~29 ~45 ~18 iron_block 0  
fill ~25 ~45 ~32 ~29 ~45 ~32 iron_block 0  
fill ~28 ~45 ~19 ~28 ~55 ~19 iron_block 0  
fill ~28 ~45 ~22 ~28 ~45 ~23 wooden_pressure_plate 0  
fill ~28 ~45 ~27 ~28 ~45 ~28 wooden_pressure_plate 0  
fill ~28 ~45 ~31 ~28 ~55 ~31 iron_block 0  
fill ~30 ~45 ~19 ~30 ~45 ~23 iron_block 0  
fill ~30 ~45 ~30 ~30 ~45 ~31 iron_block 0  
fill ~31 ~45 ~21 ~31 ~45 ~29 iron_block 0  
fill ~32 ~45 ~24 ~32 ~45 ~26 iron_block 0  
fill ~13 ~46 ~24 ~13 ~48 ~24 iron_block 0  
fill ~13 ~46 ~25 ~13 ~46 ~26 iron_block 0  
fill ~14 ~46 ~21 ~14 ~48 ~21 iron_block 0  
fill ~14 ~46 ~22 ~14 ~48 ~22 iron_block 0  
fill ~14 ~46 ~23 ~14 ~48 ~23 iron_block 0  
fill ~14 ~46 ~27 ~14 ~48 ~27 iron_block 0  
fill ~14 ~46 ~28 ~14 ~48 ~28 iron_block 0  
fill ~14 ~46 ~29 ~16 ~46 ~29 iron_block 0  
fill ~15 ~46 ~19 ~15 ~48 ~19 iron_block 0  
fill ~15 ~46 ~20 ~15 ~46 ~19 iron_block 0  
fill ~15 ~46 ~25 ~15 ~47 ~25 iron_block 0  
fill ~15 ~46 ~30 ~15 ~46 ~31 iron_block 0  
fill ~16 ~46 ~18 ~16 ~48 ~18 iron_block 0  
fill ~16 ~46 ~25 ~21 ~46 ~25 stone_slab 8  
fill ~16 ~46 ~32 ~16 ~48 ~32 iron_block 0  
fill ~17 ~46 ~17 ~18 ~46 ~17 iron_block 0  
fill ~17 ~46 ~33 ~18 ~46 ~33 iron_block 0  
fill ~19 ~46 ~16 ~21 ~46 ~16 iron_block 0  
fill ~19 ~46 ~18 ~22 ~46 ~18 iron_block 0  
fill ~19 ~46 ~32 ~22 ~46 ~32 iron_block 0  
fill ~19 ~46 ~34 ~21 ~46 ~34 iron_block 0  
fill ~22 ~46 ~15 ~24 ~46 ~15 iron_block 0 
setblock ~22 ~46 ~19 iron_block 0 
setblock ~22 ~46 ~25 glowstone 0 
setblock ~22 ~46 ~31 iron_block 0  
fill ~22 ~46 ~35 ~24 ~46 ~35 iron_block 0  
fill ~23 ~46 ~17 ~23 ~47 ~17 iron_block 0  
fill ~23 ~46 ~26 ~23 ~48 ~26 glass 0  
fill ~23 ~46 ~33 ~23 ~47 ~33 iron_block 0  
fill ~24 ~46 ~18 ~27 ~46 ~18 iron_block 0  
fill ~24 ~46 ~19 ~24 ~46 ~17 iron_block 0  
fill ~24 ~46 ~31 ~24 ~46 ~33 iron_block 0  
fill ~25 ~46 ~16 ~27 ~46 ~16 iron_block 0  
fill ~25 ~46 ~32 ~27 ~46 ~32 iron_block 0  
fill ~25 ~46 ~34 ~27 ~46 ~34 iron_block 0  
fill ~28 ~46 ~17 ~29 ~46 ~17 iron_block 0  
fill ~28 ~46 ~33 ~29 ~46 ~33 iron_block 0  
fill ~30 ~46 ~18 ~30 ~48 ~18 iron_block 0  
fill ~30 ~46 ~32 ~30 ~48 ~32 iron_block 0  
fill ~31 ~46 ~19 ~31 ~48 ~19 iron_block 0  
fill ~31 ~46 ~20 ~31 ~46 ~19 iron_block 0  
fill ~31 ~46 ~25 ~31 ~47 ~25 iron_block 0  
fill ~31 ~46 ~30 ~31 ~46 ~31 iron_block 0  
fill ~32 ~46 ~21 ~32 ~48 ~21 iron_block 0  
fill ~32 ~46 ~22 ~32 ~48 ~22 iron_block 0  
fill ~32 ~46 ~23 ~32 ~48 ~23 iron_block 0  
fill ~32 ~46 ~27 ~32 ~48 ~27 iron_block 0  
fill ~32 ~46 ~28 ~32 ~48 ~28 iron_block 0  
fill ~32 ~46 ~29 ~32 ~48 ~29 iron_block 0  
fill ~33 ~46 ~24 ~33 ~48 ~24 iron_block 0  
fill ~33 ~46 ~25 ~33 ~46 ~26 iron_block 0 
setblock ~13 ~47 ~23 redstone_torch 4 
setblock ~13 ~47 ~25 glowstone 0  
fill ~13 ~47 ~26 ~13 ~48 ~26 iron_block 0 
setblock ~13 ~47 ~27 redstone_torch 3  
fill ~14 ~47 ~29 ~14 ~48 ~29 iron_block 0 
setblock ~15 ~47 ~18 redstone_torch 2 
setblock ~15 ~47 ~20 glowstone 0 
setblock ~15 ~47 ~30 glowstone 0  
fill ~15 ~47 ~31 ~15 ~48 ~31 iron_block 0 
setblock ~15 ~47 ~32 redstone_torch 2 
setblock ~16 ~47 ~17 redstone_torch 4 
setblock ~16 ~47 ~33 redstone_torch 3  
fill ~17 ~47 ~17 ~17 ~48 ~17 iron_block 0  
fill ~17 ~47 ~33 ~17 ~48 ~33 iron_block 0 
setblock ~18 ~47 ~17 glowstone 0 
setblock ~18 ~47 ~33 glowstone 0  
fill ~19 ~47 ~16 ~21 ~47 ~16 iron_block 0  
fill ~19 ~47 ~18 ~22 ~47 ~18 iron_block 0  
fill ~19 ~47 ~32 ~22 ~47 ~32 iron_block 0  
fill ~19 ~47 ~34 ~21 ~47 ~34 iron_block 0 
setblock ~21 ~47 ~15 redstone_torch 2 
setblock ~21 ~47 ~35 redstone_torch 2  
fill ~22 ~47 ~15 ~22 ~48 ~15 iron_block 0  
fill ~22 ~47 ~19 ~22 ~52 ~19 fence 0  
fill ~22 ~47 ~25 ~22 ~49 ~25 glass 0  
fill ~22 ~47 ~31 ~22 ~52 ~31 fence 0  
fill ~22 ~47 ~35 ~22 ~48 ~35 iron_block 0 
setblock ~23 ~47 ~15 glowstone 0  
fill ~23 ~47 ~20 ~23 ~47 ~23 stone_slab 8 
setblock ~23 ~47 ~24 glowstone 0 
setblock ~23 ~47 ~35 glowstone 0  
fill ~24 ~47 ~15 ~24 ~48 ~15 iron_block 0  
fill ~24 ~47 ~18 ~27 ~47 ~18 iron_block 0  
fill ~24 ~47 ~19 ~24 ~52 ~19 fence 0  
fill ~24 ~47 ~31 ~24 ~52 ~31 fence 0  
fill ~24 ~47 ~32 ~27 ~47 ~32 iron_block 0  
fill ~24 ~47 ~35 ~24 ~48 ~35 iron_block 0 
setblock ~25 ~47 ~15 redstone_torch 1  
fill ~25 ~47 ~16 ~27 ~47 ~16 iron_block 0  
fill ~25 ~47 ~34 ~27 ~47 ~34 iron_block 0 
setblock ~25 ~47 ~35 redstone_torch 1 
setblock ~28 ~47 ~17 glowstone 0 
setblock ~28 ~47 ~33 glowstone 0  
fill ~29 ~47 ~17 ~29 ~48 ~17 iron_block 0  
fill ~29 ~47 ~33 ~29 ~48 ~33 iron_block 0 
setblock ~30 ~47 ~17 redstone_torch 4 
setblock ~30 ~47 ~33 redstone_torch 3 
setblock ~31 ~47 ~18 redstone_torch 1 
setblock ~31 ~47 ~20 glowstone 0 
setblock ~31 ~47 ~30 glowstone 0  
fill ~31 ~47 ~31 ~31 ~48 ~31 iron_block 0 
setblock ~31 ~47 ~32 redstone_torch 1 
setblock ~33 ~47 ~23 redstone_torch 4 
setblock ~33 ~47 ~25 glowstone 0  
fill ~33 ~47 ~26 ~33 ~48 ~26 iron_block 0 
setblock ~33 ~47 ~27 redstone_torch 3 
setblock ~13 ~48 ~25 iron_block 0 
setblock ~15 ~48 ~20 iron_block 0 
setblock ~15 ~48 ~25 glowstone 0 
setblock ~15 ~48 ~30 iron_block 0 
setblock ~18 ~48 ~17 iron_block 0 
setblock ~18 ~48 ~33 iron_block 0  
fill ~19 ~48 ~16 ~21 ~48 ~16 iron_block 0  
fill ~19 ~48 ~18 ~22 ~48 ~18 iron_block 0  
fill ~19 ~48 ~32 ~22 ~48 ~32 iron_block 0  
fill ~19 ~48 ~34 ~21 ~48 ~34 iron_block 0 
setblock ~23 ~48 ~15 iron_block 0 
setblock ~23 ~48 ~17 glowstone 0  
fill ~23 ~48 ~24 ~23 ~50 ~24 glass 0  
fill ~23 ~48 ~25 ~23 ~49 ~25 stained_hardened_clay 6 
setblock ~23 ~48 ~33 glowstone 0 
setblock ~23 ~48 ~35 iron_block 0  
fill ~24 ~48 ~18 ~27 ~48 ~18 iron_block 0 
setblock ~24 ~48 ~25 glowstone 0  
fill ~24 ~48 ~32 ~27 ~48 ~32 iron_block 0  
fill ~25 ~48 ~16 ~27 ~48 ~16 iron_block 0  
fill ~25 ~48 ~25 ~30 ~48 ~25 stone_slab 8  
fill ~25 ~48 ~34 ~27 ~48 ~34 iron_block 0 
setblock ~28 ~48 ~17 iron_block 0 
setblock ~28 ~48 ~33 iron_block 0 
setblock ~31 ~48 ~20 iron_block 0 
setblock ~31 ~48 ~25 glowstone 0 
setblock ~31 ~48 ~30 iron_block 0 
setblock ~33 ~48 ~25 iron_block 0  
fill ~14 ~49 ~24 ~14 ~49 ~26 iron_block 0  
fill ~15 ~49 ~21 ~15 ~49 ~29 iron_block 0  
fill ~16 ~49 ~19 ~18 ~49 ~19 iron_block 0  
fill ~16 ~49 ~20 ~16 ~49 ~19 iron_block 0  
fill ~16 ~49 ~30 ~16 ~49 ~31 iron_block 0  
fill ~17 ~49 ~18 ~22 ~49 ~18 iron_block 0  
fill ~17 ~49 ~31 ~17 ~51 ~31 iron_block 0  
fill ~17 ~49 ~32 ~22 ~49 ~32 iron_block 0  
fill ~19 ~49 ~17 ~27 ~49 ~17 iron_block 0  
fill ~19 ~49 ~33 ~27 ~49 ~33 iron_block 0  
fill ~22 ~49 ~16 ~24 ~49 ~16 iron_block 0  
fill ~22 ~49 ~34 ~24 ~49 ~34 iron_block 0 
setblock ~23 ~49 ~26 glowstone 0  
fill ~23 ~49 ~27 ~23 ~49 ~30 stone_slab 8  
fill ~24 ~49 ~18 ~29 ~49 ~18 iron_block 0  
fill ~24 ~49 ~25 ~24 ~51 ~25 glass 0  
fill ~24 ~49 ~32 ~29 ~49 ~32 iron_block 0  
fill ~29 ~49 ~19 ~30 ~49 ~19 iron_block 0  
fill ~29 ~49 ~31 ~30 ~49 ~31 iron_block 0 
setblock ~30 ~49 ~20 iron_block 0 
setblock ~30 ~49 ~30 iron_block 0  
fill ~31 ~49 ~21 ~31 ~49 ~29 iron_block 0  
fill ~32 ~49 ~24 ~32 ~49 ~26 iron_block 0 
setblock ~15 ~50 ~25 iron_block 0  
fill ~16 ~50 ~25 ~21 ~50 ~25 stone_slab 8  
fill ~17 ~50 ~19 ~17 ~51 ~19 iron_block 0  
fill ~19 ~50 ~18 ~22 ~50 ~18 iron_block 0  
fill ~19 ~50 ~32 ~22 ~50 ~32 iron_block 0 
setblock ~22 ~50 ~25 glowstone 0 
setblock ~23 ~50 ~17 iron_block 0  
fill ~23 ~50 ~25 ~23 ~52 ~25 stained_hardened_clay 14  
fill ~23 ~50 ~26 ~23 ~52 ~26 glass 0 
setblock ~23 ~50 ~33 iron_block 0  
fill ~24 ~50 ~18 ~27 ~50 ~18 iron_block 0  
fill ~24 ~50 ~32 ~27 ~50 ~32 iron_block 0  
fill ~29 ~50 ~19 ~29 ~51 ~19 iron_block 0  
fill ~29 ~50 ~31 ~29 ~51 ~31 iron_block 0 
setblock ~31 ~50 ~25 iron_block 0 
setblock ~15 ~51 ~25 quartz_block 0  
fill ~19 ~51 ~18 ~22 ~51 ~18 iron_block 0  
fill ~19 ~51 ~32 ~22 ~51 ~32 iron_block 0  
fill ~22 ~51 ~25 ~22 ~53 ~25 glass 0 
setblock ~23 ~51 ~17 quartz_block 0  
fill ~23 ~51 ~20 ~23 ~51 ~23 stone_slab 8 
setblock ~23 ~51 ~24 glowstone 0 
setblock ~23 ~51 ~33 quartz_block 0  
fill ~24 ~51 ~18 ~27 ~51 ~18 iron_block 0  
fill ~24 ~51 ~32 ~27 ~51 ~32 iron_block 0 
setblock ~31 ~51 ~25 quartz_block 0 
setblock ~15 ~52 ~23 redstone_torch 4 
setblock ~15 ~52 ~25 glowstone 0 
setblock ~15 ~52 ~27 redstone_torch 3 
setblock ~16 ~52 ~22 glowstone 0 
setblock ~16 ~52 ~28 glowstone 0 
setblock ~17 ~52 ~19 glowstone 0 
setblock ~17 ~52 ~31 glowstone 0  
fill ~19 ~52 ~18 ~19 ~55 ~18 iron_block 0  
fill ~19 ~52 ~32 ~19 ~55 ~32 iron_block 0 
setblock ~20 ~52 ~18 glowstone 0 
setblock ~20 ~52 ~32 glowstone 0 
setblock ~21 ~52 ~17 redstone_torch 2  
fill ~21 ~52 ~18 ~22 ~52 ~18 iron_block 0  
fill ~21 ~52 ~32 ~22 ~52 ~32 iron_block 0 
setblock ~21 ~52 ~33 redstone_torch 2 
setblock ~23 ~52 ~17 glowstone 0  
fill ~23 ~52 ~24 ~23 ~54 ~24 glass 0 
setblock ~23 ~52 ~33 glowstone 0  
fill ~24 ~52 ~18 ~25 ~52 ~18 iron_block 0 
setblock ~24 ~52 ~25 glowstone 0  
fill ~24 ~52 ~32 ~25 ~52 ~32 iron_block 0 
setblock ~25 ~52 ~17 redstone_torch 1  
fill ~25 ~52 ~25 ~30 ~52 ~25 stone_slab 8 
setblock ~25 ~52 ~33 redstone_torch 1 
setblock ~26 ~52 ~18 glowstone 0 
setblock ~26 ~52 ~32 glowstone 0  
fill ~27 ~52 ~18 ~27 ~55 ~18 iron_block 0  
fill ~27 ~52 ~32 ~27 ~55 ~32 iron_block 0 
setblock ~29 ~52 ~19 glowstone 0 
setblock ~29 ~52 ~31 glowstone 0 
setblock ~30 ~52 ~22 glowstone 0 
setblock ~30 ~52 ~28 glowstone 0 
setblock ~31 ~52 ~23 redstone_torch 4 
setblock ~31 ~52 ~25 glowstone 0 
setblock ~31 ~52 ~27 redstone_torch 3  
fill ~15 ~53 ~25 ~15 ~54 ~25 quartz_block 0  
fill ~16 ~53 ~22 ~16 ~55 ~22 glass 0  
fill ~16 ~53 ~28 ~16 ~55 ~28 glass 0  
fill ~17 ~53 ~19 ~17 ~54 ~19 fence 0  
fill ~17 ~53 ~31 ~17 ~54 ~31 fence 0  
fill ~20 ~53 ~18 ~20 ~55 ~18 glass 0  
fill ~20 ~53 ~32 ~20 ~55 ~32 glass 0  
fill ~21 ~53 ~18 ~22 ~53 ~18 iron_block 0  
fill ~21 ~53 ~32 ~22 ~53 ~32 iron_block 0 
setblock ~22 ~53 ~19 spruce_stairs 4 
setblock ~22 ~53 ~20 spruce_stairs 7 
setblock ~22 ~53 ~30 spruce_stairs 6 
setblock ~22 ~53 ~31 spruce_stairs 4  
fill ~23 ~53 ~17 ~23 ~54 ~17 quartz_block 0  
fill ~23 ~53 ~20 ~23 ~53 ~21 iron_block 0 
setblock ~23 ~53 ~25 stained_hardened_clay 6 
setblock ~23 ~53 ~26 glowstone 0  
fill ~23 ~53 ~27 ~23 ~53 ~28 stone_slab 8  
fill ~23 ~53 ~29 ~23 ~63 ~29 iron_block 0  
fill ~23 ~53 ~30 ~23 ~53 ~29 iron_block 0  
fill ~23 ~53 ~33 ~23 ~54 ~33 quartz_block 0  
fill ~24 ~53 ~18 ~25 ~53 ~18 iron_block 0 
setblock ~24 ~53 ~19 spruce_stairs 5 
setblock ~24 ~53 ~20 spruce_stairs 7  
fill ~24 ~53 ~25 ~24 ~55 ~25 glass 0 
setblock ~24 ~53 ~30 spruce_stairs 6 
setblock ~24 ~53 ~31 spruce_stairs 5  
fill ~24 ~53 ~32 ~25 ~53 ~32 iron_block 0  
fill ~26 ~53 ~18 ~26 ~55 ~18 glass 0  
fill ~26 ~53 ~32 ~26 ~55 ~32 glass 0  
fill ~29 ~53 ~19 ~29 ~54 ~19 fence 0  
fill ~29 ~53 ~31 ~29 ~54 ~31 fence 0  
fill ~30 ~53 ~22 ~30 ~55 ~22 glass 0  
fill ~30 ~53 ~28 ~30 ~55 ~28 glass 0  
fill ~31 ~53 ~25 ~31 ~54 ~25 quartz_block 0  
fill ~16 ~54 ~25 ~21 ~54 ~25 stone_slab 8  
fill ~21 ~54 ~18 ~22 ~54 ~18 iron_block 0  
fill ~21 ~54 ~32 ~22 ~54 ~32 iron_block 0  
fill ~22 ~54 ~19 ~22 ~62 ~19 iron_block 0  
fill ~22 ~54 ~20 ~22 ~54 ~17 iron_block 0 
setblock ~22 ~54 ~25 glowstone 0  
fill ~22 ~54 ~30 ~22 ~54 ~33 iron_block 0  
fill ~23 ~54 ~20 ~23 ~62 ~20 ladder 2  
fill ~23 ~54 ~21 ~23 ~63 ~21 iron_block 0 
setblock ~23 ~54 ~25 stained_hardened_clay 14  
fill ~23 ~54 ~26 ~23 ~56 ~26 glass 0  
fill ~23 ~54 ~30 ~23 ~62 ~30 ladder 3  
fill ~24 ~54 ~18 ~25 ~54 ~18 iron_block 0  
fill ~24 ~54 ~19 ~24 ~62 ~19 iron_block 0  
fill ~24 ~54 ~20 ~24 ~54 ~17 iron_block 0  
fill ~24 ~54 ~30 ~24 ~54 ~33 iron_block 0  
fill ~25 ~54 ~32 ~25 ~55 ~32 iron_block 0 
setblock ~15 ~55 ~25 iron_block 0 
setblock ~17 ~55 ~19 iron_block 0 
setblock ~17 ~55 ~31 iron_block 0  
fill ~21 ~55 ~18 ~22 ~55 ~18 iron_block 0  
fill ~21 ~55 ~32 ~22 ~55 ~32 iron_block 0  
fill ~22 ~55 ~20 ~22 ~57 ~20 glass 0  
fill ~22 ~55 ~25 ~22 ~57 ~25 glass 0  
fill ~22 ~55 ~30 ~22 ~57 ~30 glass 0  
fill ~22 ~55 ~31 ~22 ~63 ~31 iron_block 0 
setblock ~23 ~55 ~17 iron_block 0 
setblock ~23 ~55 ~18 ladder 3  
fill ~23 ~55 ~22 ~23 ~55 ~23 stone_slab 8 
setblock ~23 ~55 ~24 glowstone 0 
setblock ~23 ~55 ~25 stained_hardened_clay 6 
setblock ~23 ~55 ~32 ladder 2 
setblock ~23 ~55 ~33 iron_block 0  
fill ~24 ~55 ~18 ~25 ~55 ~18 iron_block 0  
fill ~24 ~55 ~20 ~24 ~57 ~20 glass 0  
fill ~24 ~55 ~30 ~24 ~57 ~30 glass 0  
fill ~24 ~55 ~31 ~24 ~63 ~31 iron_block 0  
fill ~24 ~55 ~32 ~24 ~57 ~32 iron_block 0 
setblock ~29 ~55 ~19 iron_block 0 
setblock ~29 ~55 ~31 iron_block 0 
setblock ~31 ~55 ~25 iron_block 0  
fill ~16 ~56 ~24 ~16 ~57 ~24 iron_block 0  
fill ~16 ~56 ~25 ~16 ~57 ~25 iron_block 0  
fill ~16 ~56 ~26 ~16 ~57 ~26 iron_block 0  
fill ~17 ~56 ~21 ~17 ~57 ~21 iron_block 0  
fill ~17 ~56 ~22 ~17 ~57 ~22 iron_block 0  
fill ~17 ~56 ~23 ~17 ~57 ~23 iron_block 0  
fill ~17 ~56 ~27 ~17 ~57 ~27 iron_block 0  
fill ~17 ~56 ~28 ~17 ~57 ~28 iron_block 0  
fill ~17 ~56 ~29 ~17 ~57 ~29 iron_block 0 
setblock ~18 ~56 ~20 glowstone 0 
setblock ~18 ~56 ~30 glowstone 0  
fill ~19 ~56 ~19 ~27 ~56 ~19 iron_block 0  
fill ~19 ~56 ~31 ~22 ~56 ~31 iron_block 0  
fill ~22 ~56 ~18 ~24 ~56 ~18 iron_block 0  
fill ~22 ~56 ~32 ~24 ~56 ~32 iron_block 0  
fill ~23 ~56 ~24 ~23 ~58 ~24 glass 0  
fill ~23 ~56 ~25 ~23 ~61 ~25 stained_hardened_clay 14 
setblock ~24 ~56 ~25 glowstone 0  
fill ~25 ~56 ~25 ~29 ~56 ~25 stone_slab 8  
fill ~25 ~56 ~31 ~27 ~56 ~31 iron_block 0 
setblock ~28 ~56 ~20 glowstone 0 
setblock ~28 ~56 ~30 glowstone 0  
fill ~29 ~56 ~21 ~29 ~57 ~21 iron_block 0  
fill ~29 ~56 ~22 ~29 ~57 ~22 iron_block 0  
fill ~29 ~56 ~23 ~29 ~57 ~23 iron_block 0  
fill ~29 ~56 ~27 ~29 ~57 ~27 iron_block 0  
fill ~29 ~56 ~28 ~29 ~57 ~28 iron_block 0  
fill ~29 ~56 ~29 ~29 ~57 ~29 iron_block 0  
fill ~30 ~56 ~24 ~30 ~57 ~24 iron_block 0  
fill ~30 ~56 ~25 ~30 ~57 ~25 iron_block 0  
fill ~30 ~56 ~26 ~30 ~57 ~26 iron_block 0 
setblock ~18 ~57 ~20 iron_block 0 
setblock ~18 ~57 ~30 iron_block 0  
fill ~19 ~57 ~19 ~27 ~57 ~19 iron_block 0  
fill ~19 ~57 ~31 ~22 ~57 ~31 iron_block 0  
fill ~22 ~57 ~18 ~24 ~57 ~18 iron_block 0  
fill ~22 ~57 ~32 ~24 ~57 ~32 iron_block 0 
setblock ~23 ~57 ~26 glowstone 0  
fill ~23 ~57 ~27 ~23 ~57 ~28 stone_slab 8  
fill ~24 ~57 ~25 ~24 ~59 ~25 glass 0  
fill ~25 ~57 ~31 ~27 ~57 ~31 iron_block 0 
setblock ~28 ~57 ~20 iron_block 0 
setblock ~28 ~57 ~30 iron_block 0 
setblock ~16 ~58 ~24 redstone_torch 2 
setblock ~16 ~58 ~25 fence 0 
setblock ~16 ~58 ~26 redstone_torch 2 
setblock ~17 ~58 ~21 redstone_torch 2 
setblock ~17 ~58 ~24 iron_block 0 
setblock ~17 ~58 ~25 glowstone 0 
setblock ~17 ~58 ~26 iron_block 0 
setblock ~17 ~58 ~29 redstone_torch 2  
fill ~18 ~58 ~21 ~18 ~58 ~23 iron_block 0  
fill ~18 ~58 ~27 ~18 ~58 ~29 iron_block 0 
setblock ~19 ~58 ~19 redstone_torch 4  
fill ~19 ~58 ~20 ~22 ~58 ~20 iron_block 0  
fill ~19 ~58 ~25 ~21 ~58 ~25 stone_slab 8  
fill ~19 ~58 ~30 ~22 ~58 ~30 iron_block 0 
setblock ~19 ~58 ~31 redstone_torch 3 
setblock ~22 ~58 ~18 redstone_torch 4 
setblock ~22 ~58 ~25 glowstone 0 
setblock ~22 ~58 ~32 redstone_torch 3 
setblock ~23 ~58 ~18 fence 0 
setblock ~23 ~58 ~19 glowstone 0  
fill ~23 ~58 ~26 ~23 ~60 ~26 glass 0 
setblock ~23 ~58 ~31 glowstone 0 
setblock ~23 ~58 ~32 fence 0 
setblock ~24 ~58 ~18 redstone_torch 4  
fill ~24 ~58 ~20 ~27 ~58 ~20 iron_block 0  
fill ~24 ~58 ~30 ~27 ~58 ~30 iron_block 0 
setblock ~24 ~58 ~32 redstone_torch 3 
setblock ~27 ~58 ~19 redstone_torch 4 
setblock ~27 ~58 ~31 redstone_torch 3  
fill ~28 ~58 ~21 ~28 ~58 ~23 iron_block 0  
fill ~28 ~58 ~27 ~28 ~58 ~29 iron_block 0 
setblock ~29 ~58 ~21 redstone_torch 1 
setblock ~29 ~58 ~24 iron_block 0 
setblock ~29 ~58 ~25 glowstone 0 
setblock ~29 ~58 ~26 iron_block 0 
setblock ~29 ~58 ~29 redstone_torch 1 
setblock ~30 ~58 ~24 redstone_torch 1 
setblock ~30 ~58 ~25 fence 0 
setblock ~30 ~58 ~26 redstone_torch 1  
fill ~38 ~58 ~21 ~38 ~58 ~30 lever 15 
setblock ~42 ~58 ~25 stone_slab 8  
fill ~43 ~58 ~24 ~45 ~58 ~24 stone_slab 8  
fill ~43 ~58 ~25 ~45 ~58 ~25 iron_block 0  
fill ~43 ~58 ~26 ~45 ~58 ~26 stone_slab 8  
fill ~46 ~58 ~25 ~50 ~58 ~25 stone_slab 8  
fill ~46 ~58 ~26 ~47 ~58 ~26 iron_block 0 
setblock ~46 ~58 ~27 stone_slab 8 
setblock ~47 ~58 ~27 ladder 3 
setblock ~48 ~58 ~26 glowstone 0  
fill ~48 ~58 ~27 ~49 ~58 ~27 stone_slab 8 
setblock ~48 ~58 ~39 stone_slab 8  
fill ~49 ~58 ~26 ~53 ~58 ~26 iron_block 0 
setblock ~49 ~58 ~38 stone_slab 8  
fill ~49 ~58 ~39 ~50 ~58 ~39 iron_block 0  
fill ~49 ~58 ~40 ~49 ~58 ~41 stone_slab 8  
fill ~50 ~58 ~27 ~50 ~59 ~27 iron_block 0  
fill ~50 ~58 ~28 ~50 ~58 ~29 stone_slab 8 
setblock ~50 ~58 ~37 stone_slab 8  
fill ~50 ~58 ~38 ~52 ~58 ~38 iron_block 0  
fill ~50 ~58 ~40 ~52 ~58 ~40 iron_block 0  
fill ~50 ~58 ~41 ~52 ~58 ~41 iron_block 0  
fill ~50 ~58 ~42 ~50 ~58 ~47 stone_slab 8  
fill ~51 ~58 ~23 ~51 ~58 ~24 stone_slab 8  
fill ~51 ~58 ~25 ~51 ~59 ~25 iron_block 0 
setblock ~51 ~58 ~27 glowstone 0  
fill ~51 ~58 ~28 ~51 ~59 ~28 iron_block 0  
fill ~51 ~58 ~29 ~51 ~59 ~29 iron_block 0  
fill ~51 ~58 ~30 ~51 ~58 ~36 stone_slab 8  
fill ~51 ~58 ~37 ~51 ~59 ~37 iron_block 0 
setblock ~51 ~58 ~39 glowstone 0  
fill ~51 ~58 ~42 ~51 ~63 ~42 iron_block 0  
fill ~51 ~58 ~43 ~51 ~59 ~43 iron_block 0  
fill ~51 ~58 ~44 ~51 ~59 ~44 iron_block 0 
setblock ~51 ~58 ~45 glowstone 0  
fill ~51 ~58 ~46 ~51 ~59 ~46 iron_block 0  
fill ~51 ~58 ~47 ~51 ~59 ~47 iron_block 0  
fill ~51 ~58 ~48 ~51 ~58 ~50 stone_slab 8  
fill ~52 ~58 ~25 ~56 ~58 ~25 stone_slab 8  
fill ~52 ~58 ~27 ~52 ~59 ~27 iron_block 0  
fill ~52 ~58 ~28 ~52 ~58 ~29 stone_slab 8 
setblock ~52 ~58 ~37 stone_slab 8  
fill ~52 ~58 ~39 ~53 ~58 ~39 iron_block 0  
fill ~52 ~58 ~42 ~52 ~58 ~47 stone_slab 8  
fill ~53 ~58 ~27 ~54 ~58 ~27 stone_slab 8 
setblock ~53 ~58 ~38 stone_slab 8  
fill ~53 ~58 ~40 ~53 ~58 ~41 stone_slab 8 
setblock ~54 ~58 ~26 glowstone 0 
setblock ~54 ~58 ~39 stone_slab 8  
fill ~55 ~58 ~26 ~56 ~58 ~26 iron_block 0 
setblock ~55 ~58 ~27 ladder 3 
setblock ~56 ~58 ~27 stone_slab 8  
fill ~57 ~58 ~24 ~59 ~58 ~24 stone_slab 8  
fill ~57 ~58 ~25 ~59 ~58 ~25 iron_block 0  
fill ~57 ~58 ~26 ~59 ~58 ~26 stone_slab 8 
setblock ~60 ~58 ~25 stone_slab 8  
fill ~64 ~58 ~21 ~64 ~58 ~30 lever 15  
fill ~10 ~59 ~5 ~10 ~59 ~8 lever 7  
fill ~10 ~59 ~11 ~10 ~59 ~14 lever 7 
setblock ~14 ~59 ~10 stone_slab 8  
fill ~15 ~59 ~9 ~17 ~59 ~9 stone_slab 8  
fill ~16 ~59 ~24 ~16 ~60 ~24 iron_block 0  
fill ~16 ~59 ~25 ~16 ~60 ~25 iron_block 0  
fill ~16 ~59 ~26 ~16 ~60 ~26 iron_block 0  
fill ~17 ~59 ~21 ~17 ~60 ~21 iron_block 0  
fill ~17 ~59 ~22 ~17 ~60 ~22 iron_block 0  
fill ~17 ~59 ~23 ~17 ~60 ~23 iron_block 0  
fill ~17 ~59 ~27 ~17 ~60 ~27 iron_block 0  
fill ~17 ~59 ~28 ~17 ~60 ~28 iron_block 0  
fill ~17 ~59 ~29 ~17 ~60 ~29 iron_block 0  
fill ~18 ~59 ~8 ~21 ~59 ~8 stone_slab 8 
setblock ~18 ~59 ~20 iron_block 0 
setblock ~18 ~59 ~30 iron_block 0  
fill ~19 ~59 ~19 ~27 ~59 ~19 iron_block 0  
fill ~19 ~59 ~31 ~27 ~59 ~31 iron_block 0  
fill ~21 ~59 ~-11 ~21 ~59 ~-7 stone_slab 8  
fill ~22 ~59 ~-14 ~22 ~59 ~-12 stone_slab 8  
fill ~22 ~59 ~-11 ~24 ~59 ~-11 iron_block 0  
fill ~22 ~59 ~-10 ~24 ~59 ~-10 iron_block 0  
fill ~22 ~59 ~-9 ~22 ~60 ~-9 iron_block 0  
fill ~22 ~59 ~-8 ~24 ~59 ~-8 iron_block 0  
fill ~22 ~59 ~-7 ~24 ~59 ~-7 iron_block 0  
fill ~22 ~59 ~-6 ~22 ~59 ~-5 stone_slab 8  
fill ~22 ~59 ~6 ~22 ~59 ~7 stone_slab 8  
fill ~22 ~59 ~8 ~22 ~60 ~8 iron_block 0 
setblock ~22 ~59 ~9 stone_slab 8  
fill ~22 ~59 ~18 ~24 ~59 ~18 iron_block 0  
fill ~22 ~59 ~20 ~22 ~61 ~20 glass 0  
fill ~22 ~59 ~25 ~22 ~61 ~25 glass 0  
fill ~22 ~59 ~30 ~22 ~61 ~30 glass 0  
fill ~22 ~59 ~32 ~24 ~59 ~32 iron_block 0  
fill ~23 ~59 ~-16 ~23 ~59 ~-15 stone_slab 8  
fill ~23 ~59 ~-14 ~23 ~60 ~-14 iron_block 0  
fill ~23 ~59 ~-13 ~23 ~60 ~-13 iron_block 0  
fill ~23 ~59 ~-12 ~23 ~59 ~-14 iron_block 0 
setblock ~23 ~59 ~-9 glowstone 0  
fill ~23 ~59 ~-6 ~23 ~64 ~-6 iron_block 0  
fill ~23 ~59 ~-5 ~23 ~60 ~-5 iron_block 0  
fill ~23 ~59 ~-4 ~23 ~59 ~5 stone_slab 8  
fill ~23 ~59 ~6 ~23 ~60 ~6 iron_block 0  
fill ~23 ~59 ~7 ~23 ~60 ~7 iron_block 0 
setblock ~23 ~59 ~8 glowstone 0  
fill ~23 ~59 ~9 ~23 ~60 ~9 iron_block 0  
fill ~23 ~59 ~10 ~23 ~59 ~11 stone_slab 8  
fill ~23 ~59 ~22 ~23 ~59 ~23 stone_slab 8 
setblock ~23 ~59 ~24 glowstone 0  
fill ~24 ~59 ~-14 ~24 ~59 ~-12 stone_slab 8  
fill ~24 ~59 ~-9 ~24 ~60 ~-9 iron_block 0  
fill ~24 ~59 ~-6 ~24 ~59 ~-5 stone_slab 8  
fill ~24 ~59 ~6 ~24 ~59 ~7 stone_slab 8  
fill ~24 ~59 ~8 ~24 ~60 ~8 iron_block 0 
setblock ~24 ~59 ~9 stone_slab 8  
fill ~24 ~59 ~20 ~24 ~61 ~20 glass 0  
fill ~24 ~59 ~30 ~24 ~61 ~30 glass 0  
fill ~25 ~59 ~-11 ~25 ~59 ~-7 stone_slab 8  
fill ~25 ~59 ~8 ~28 ~59 ~8 stone_slab 8 
setblock ~28 ~59 ~20 iron_block 0 
setblock ~28 ~59 ~30 iron_block 0  
fill ~29 ~59 ~9 ~31 ~59 ~9 stone_slab 8  
fill ~29 ~59 ~21 ~29 ~60 ~21 iron_block 0  
fill ~29 ~59 ~22 ~29 ~60 ~22 iron_block 0  
fill ~29 ~59 ~23 ~29 ~60 ~23 iron_block 0  
fill ~29 ~59 ~27 ~29 ~60 ~27 iron_block 0  
fill ~29 ~59 ~28 ~29 ~60 ~28 iron_block 0  
fill ~29 ~59 ~29 ~29 ~60 ~29 iron_block 0  
fill ~30 ~59 ~24 ~30 ~60 ~24 iron_block 0  
fill ~30 ~59 ~25 ~30 ~60 ~25 iron_block 0  
fill ~30 ~59 ~26 ~30 ~60 ~26 iron_block 0 
setblock ~32 ~59 ~10 stone_slab 8  
fill ~36 ~59 ~5 ~36 ~59 ~8 lever 7  
fill ~36 ~59 ~11 ~36 ~59 ~14 lever 7 
setblock ~38 ~59 ~20 iron_block 0  
fill ~38 ~59 ~21 ~38 ~59 ~30 wool 11 
setblock ~38 ~59 ~31 iron_block 0  
fill ~39 ~59 ~24 ~63 ~59 ~24 iron_block 0 
setblock ~39 ~59 ~25 glowstone 0  
fill ~40 ~59 ~25 ~62 ~59 ~25 iron_block 0  
fill ~40 ~59 ~26 ~62 ~59 ~26 iron_block 0  
fill ~41 ~59 ~23 ~61 ~59 ~23 iron_block 0  
fill ~42 ~59 ~27 ~46 ~59 ~27 iron_block 0  
fill ~44 ~59 ~28 ~58 ~59 ~28 iron_block 0  
fill ~46 ~59 ~22 ~50 ~59 ~22 iron_block 0  
fill ~46 ~59 ~29 ~56 ~59 ~29 iron_block 0  
fill ~46 ~59 ~38 ~56 ~59 ~38 iron_block 0  
fill ~46 ~59 ~39 ~46 ~59 ~40 iron_block 0 
setblock ~47 ~59 ~27 trapdoor 3  
fill ~47 ~59 ~37 ~55 ~59 ~37 iron_block 0 
setblock ~47 ~59 ~39 glowstone 0  
fill ~47 ~59 ~40 ~56 ~59 ~40 iron_block 0  
fill ~47 ~59 ~41 ~55 ~59 ~41 iron_block 0  
fill ~47 ~59 ~42 ~55 ~59 ~42 iron_block 0  
fill ~47 ~59 ~43 ~55 ~59 ~43 iron_block 0  
fill ~48 ~59 ~30 ~54 ~59 ~30 iron_block 0  
fill ~48 ~59 ~36 ~54 ~59 ~36 iron_block 0  
fill ~48 ~59 ~39 ~54 ~59 ~39 iron_block 0  
fill ~48 ~59 ~44 ~54 ~59 ~44 iron_block 0  
fill ~48 ~59 ~45 ~54 ~59 ~45 iron_block 0  
fill ~48 ~59 ~46 ~54 ~59 ~46 iron_block 0 
setblock ~49 ~59 ~27 oak_stairs 0  
fill ~49 ~59 ~31 ~53 ~59 ~31 iron_block 0  
fill ~49 ~59 ~35 ~53 ~59 ~35 iron_block 0  
fill ~49 ~59 ~47 ~53 ~59 ~47 iron_block 0  
fill ~49 ~59 ~48 ~53 ~59 ~48 iron_block 0  
fill ~49 ~59 ~49 ~53 ~59 ~49 iron_block 0  
fill ~50 ~59 ~32 ~52 ~59 ~32 iron_block 0 
setblock ~50 ~59 ~33 glowstone 0  
fill ~50 ~59 ~34 ~52 ~59 ~34 iron_block 0  
fill ~50 ~59 ~50 ~52 ~59 ~50 iron_block 0  
fill ~50 ~59 ~51 ~52 ~59 ~51 iron_block 0  
fill ~50 ~59 ~52 ~50 ~59 ~34 iron_block 0 
setblock ~51 ~59 ~21 iron_block 0 
setblock ~51 ~59 ~22 glowstone 0 
setblock ~51 ~59 ~27 iron_block 0 
setblock ~51 ~59 ~33 iron_block 0 
setblock ~51 ~59 ~52 glowstone 0  
fill ~51 ~59 ~53 ~51 ~59 ~54 iron_block 0  
fill ~52 ~59 ~22 ~56 ~59 ~22 iron_block 0 
setblock ~52 ~59 ~33 glowstone 0 
setblock ~52 ~59 ~52 iron_block 0 
setblock ~53 ~59 ~27 oak_stairs 1 
setblock ~55 ~59 ~27 trapdoor 1 
setblock ~55 ~59 ~39 glowstone 0  
fill ~56 ~59 ~27 ~60 ~59 ~27 iron_block 0 
setblock ~56 ~59 ~39 iron_block 0 
setblock ~63 ~59 ~25 glowstone 0 
setblock ~64 ~59 ~20 iron_block 0  
fill ~64 ~59 ~21 ~64 ~59 ~30 wool 11 
setblock ~64 ~59 ~31 iron_block 0 
setblock ~9 ~60 ~4 stone_button 2  
fill ~9 ~60 ~9 ~9 ~60 ~10 stone_button 2 
setblock ~9 ~60 ~15 stone_button 2 
setblock ~10 ~60 ~3 stone_button 4 
setblock ~10 ~60 ~4 iron_block 0  
fill ~10 ~60 ~5 ~10 ~60 ~8 wool 11  
fill ~10 ~60 ~9 ~36 ~60 ~9 iron_block 0  
fill ~10 ~60 ~10 ~10 ~60 ~9 iron_block 0  
fill ~10 ~60 ~11 ~10 ~60 ~14 wool 11 
setblock ~10 ~60 ~15 iron_block 0 
setblock ~10 ~60 ~16 stone_button 3 
setblock ~11 ~60 ~4 stone_button 1 
setblock ~11 ~60 ~10 glowstone 0 
setblock ~11 ~60 ~15 stone_button 1  
fill ~12 ~60 ~8 ~34 ~60 ~8 iron_block 0  
fill ~12 ~60 ~10 ~14 ~60 ~10 iron_block 0 
setblock ~13 ~60 ~11 iron_block 0  
fill ~14 ~60 ~7 ~32 ~60 ~7 iron_block 0 
setblock ~14 ~60 ~11 wool 14 
setblock ~15 ~60 ~10 glowstone 0 
setblock ~15 ~60 ~11 iron_block 0  
fill ~16 ~60 ~6 ~30 ~60 ~6 iron_block 0  
fill ~16 ~60 ~10 ~20 ~60 ~10 iron_block 0 
setblock ~16 ~60 ~11 wool 14  
fill ~17 ~60 ~11 ~29 ~60 ~11 iron_block 0  
fill ~18 ~60 ~-6 ~28 ~60 ~-6 iron_block 0  
fill ~18 ~60 ~-5 ~28 ~60 ~-5 iron_block 0  
fill ~18 ~60 ~-4 ~19 ~60 ~-4 iron_block 0  
fill ~18 ~60 ~5 ~20 ~60 ~5 iron_block 0 
setblock ~18 ~60 ~20 glowstone 0 
setblock ~18 ~60 ~30 glowstone 0  
fill ~19 ~60 ~-9 ~20 ~60 ~-9 iron_block 0  
fill ~19 ~60 ~-8 ~27 ~60 ~-8 iron_block 0  
fill ~19 ~60 ~-7 ~27 ~60 ~-7 iron_block 0  
fill ~19 ~60 ~-3 ~27 ~60 ~-3 iron_block 0  
fill ~19 ~60 ~12 ~27 ~60 ~12 iron_block 0  
fill ~19 ~60 ~19 ~27 ~60 ~19 iron_block 0  
fill ~19 ~60 ~31 ~27 ~60 ~31 iron_block 0  
fill ~20 ~60 ~-12 ~22 ~60 ~-12 iron_block 0  
fill ~20 ~60 ~-11 ~26 ~60 ~-11 iron_block 0  
fill ~20 ~60 ~-10 ~26 ~60 ~-10 iron_block 0 
setblock ~20 ~60 ~-4 glowstone 0  
fill ~20 ~60 ~-2 ~22 ~60 ~-2 iron_block 0  
fill ~20 ~60 ~4 ~26 ~60 ~4 iron_block 0  
fill ~21 ~60 ~-15 ~25 ~60 ~-15 iron_block 0  
fill ~21 ~60 ~-14 ~25 ~60 ~-14 iron_block 0  
fill ~21 ~60 ~-13 ~25 ~60 ~-13 iron_block 0 
setblock ~21 ~60 ~-9 glowstone 0  
fill ~21 ~60 ~-4 ~25 ~60 ~-4 iron_block 0  
fill ~21 ~60 ~-1 ~25 ~60 ~-1 iron_block 0  
fill ~21 ~60 ~3 ~25 ~60 ~3 iron_block 0 
setblock ~21 ~60 ~5 glowstone 0 
setblock ~21 ~60 ~10 glowstone 0  
fill ~22 ~60 ~-17 ~22 ~60 ~12 iron_block 0  
fill ~22 ~60 ~16 ~22 ~60 ~17 quartz_stairs 4  
fill ~22 ~60 ~18 ~24 ~60 ~18 iron_block 0  
fill ~22 ~60 ~32 ~24 ~60 ~32 iron_block 0 
setblock ~22 ~60 ~33 quartz_stairs 4  
fill ~22 ~60 ~34 ~24 ~60 ~34 quartz_stairs 7  
fill ~23 ~60 ~-19 ~23 ~60 ~-18 iron_block 0 
setblock ~23 ~60 ~-17 glowstone 0  
fill ~23 ~60 ~-16 ~24 ~60 ~-16 iron_block 0 
setblock ~23 ~60 ~-12 glowstone 0  
fill ~23 ~60 ~-9 ~23 ~64 ~-9 iron_block 0 
setblock ~23 ~60 ~-2 glowstone 0  
fill ~23 ~60 ~0 ~24 ~60 ~0 iron_block 0 
setblock ~23 ~60 ~1 glowstone 0  
fill ~23 ~60 ~2 ~24 ~60 ~2 iron_block 0  
fill ~23 ~60 ~5 ~24 ~60 ~5 iron_block 0  
fill ~23 ~60 ~10 ~24 ~60 ~10 iron_block 0 
setblock ~23 ~60 ~13 iron_block 0  
fill ~23 ~60 ~14 ~23 ~60 ~15 stone_slab 8  
fill ~23 ~60 ~16 ~24 ~60 ~16 quartz_stairs 6 
setblock ~23 ~60 ~17 glowstone 0  
fill ~23 ~60 ~24 ~23 ~62 ~24 glass 0 
setblock ~23 ~60 ~33 glowstone 0 
setblock ~24 ~60 ~-17 iron_block 0  
fill ~24 ~60 ~-12 ~26 ~60 ~-12 iron_block 0  
fill ~24 ~60 ~-2 ~26 ~60 ~-2 iron_block 0 
setblock ~24 ~60 ~1 iron_block 0 
setblock ~24 ~60 ~17 quartz_stairs 5 
setblock ~24 ~60 ~25 glowstone 0 
setblock ~24 ~60 ~33 quartz_stairs 5 
setblock ~25 ~60 ~-9 glowstone 0 
setblock ~25 ~60 ~5 glowstone 0 
setblock ~25 ~60 ~10 glowstone 0  
fill ~25 ~60 ~25 ~28 ~60 ~25 stone_slab 8  
fill ~26 ~60 ~-9 ~27 ~60 ~-9 iron_block 0 
setblock ~26 ~60 ~-4 glowstone 0  
fill ~26 ~60 ~5 ~28 ~60 ~5 iron_block 0  
fill ~26 ~60 ~10 ~30 ~60 ~10 iron_block 0  
fill ~27 ~60 ~-4 ~28 ~60 ~-4 iron_block 0 
setblock ~28 ~60 ~20 glowstone 0 
setblock ~28 ~60 ~30 glowstone 0 
setblock ~30 ~60 ~11 wool 14 
setblock ~31 ~60 ~10 glowstone 0 
setblock ~31 ~60 ~11 iron_block 0  
fill ~32 ~60 ~10 ~34 ~60 ~10 iron_block 0 
setblock ~32 ~60 ~11 wool 14 
setblock ~33 ~60 ~11 iron_block 0 
setblock ~35 ~60 ~4 stone_button 2 
setblock ~35 ~60 ~10 glowstone 0 
setblock ~35 ~60 ~15 stone_button 2 
setblock ~36 ~60 ~3 stone_button 4 
setblock ~36 ~60 ~4 iron_block 0  
fill ~36 ~60 ~5 ~36 ~60 ~8 wool 11 
setblock ~36 ~60 ~10 iron_block 0  
fill ~36 ~60 ~11 ~36 ~60 ~14 wool 11 
setblock ~36 ~60 ~15 iron_block 0 
setblock ~36 ~60 ~16 stone_button 3 
setblock ~37 ~60 ~4 stone_button 1  
fill ~37 ~60 ~9 ~37 ~60 ~10 stone_button 1 
setblock ~37 ~60 ~15 stone_button 1  
fill ~38 ~60 ~21 ~38 ~60 ~30 lever 13  
fill ~41 ~60 ~25 ~44 ~60 ~25 stone_slab 0  
fill ~43 ~60 ~24 ~46 ~60 ~24 stone_slab 0  
fill ~44 ~60 ~26 ~46 ~60 ~26 stone_slab 0 
setblock ~45 ~60 ~25 glowstone 0  
fill ~45 ~60 ~38 ~45 ~60 ~40 iron_block 0  
fill ~46 ~60 ~25 ~50 ~60 ~25 iron_block 0 
setblock ~46 ~60 ~27 iron_block 0  
fill ~46 ~60 ~37 ~47 ~60 ~37 iron_block 0  
fill ~46 ~60 ~41 ~46 ~60 ~43 iron_block 0  
fill ~47 ~60 ~22 ~47 ~60 ~26 iron_block 0  
fill ~47 ~60 ~28 ~47 ~60 ~30 iron_block 0 
setblock ~47 ~60 ~36 iron_block 0  
fill ~47 ~60 ~44 ~47 ~60 ~46 iron_block 0  
fill ~48 ~60 ~21 ~50 ~60 ~21 iron_block 0 
setblock ~48 ~60 ~24 iron_block 0 
setblock ~48 ~60 ~31 iron_block 0 
setblock ~48 ~60 ~35 iron_block 0 
setblock ~48 ~60 ~37 wooden_door 3  
fill ~48 ~60 ~46 ~50 ~60 ~46 iron_block 0  
fill ~48 ~60 ~47 ~48 ~60 ~49 iron_block 0  
fill ~49 ~60 ~32 ~50 ~60 ~32 iron_block 0  
fill ~49 ~60 ~33 ~49 ~60 ~34 iron_block 0  
fill ~49 ~60 ~37 ~49 ~62 ~37 iron_block 0  
fill ~49 ~60 ~38 ~53 ~60 ~38 iron_block 0  
fill ~49 ~60 ~50 ~49 ~60 ~52 iron_block 0 
setblock ~50 ~60 ~47 oak_stairs 0 
setblock ~50 ~60 ~49 oak_stairs 0  
fill ~50 ~60 ~53 ~50 ~60 ~54 iron_block 0 
setblock ~51 ~60 ~20 iron_block 0 
setblock ~51 ~60 ~25 wooden_door 1 
setblock ~51 ~60 ~32 wooden_door 3  
fill ~51 ~60 ~39 ~51 ~62 ~39 iron_block 0  
fill ~51 ~60 ~40 ~51 ~63 ~40 iron_block 0  
fill ~51 ~60 ~41 ~51 ~63 ~41 iron_block 0  
fill ~51 ~60 ~43 ~51 ~61 ~43 fence 0 
setblock ~51 ~60 ~46 wooden_door 1 
setblock ~51 ~60 ~51 oak_stairs 3 
setblock ~51 ~60 ~55 iron_block 0  
fill ~52 ~60 ~21 ~54 ~60 ~21 iron_block 0  
fill ~52 ~60 ~25 ~56 ~60 ~25 iron_block 0  
fill ~52 ~60 ~32 ~53 ~60 ~32 iron_block 0  
fill ~52 ~60 ~46 ~55 ~60 ~46 iron_block 0 
setblock ~52 ~60 ~47 oak_stairs 1 
setblock ~52 ~60 ~49 oak_stairs 1  
fill ~52 ~60 ~53 ~52 ~60 ~54 iron_block 0  
fill ~53 ~60 ~33 ~53 ~60 ~34 iron_block 0  
fill ~53 ~60 ~37 ~53 ~62 ~37 iron_block 0  
fill ~53 ~60 ~50 ~53 ~60 ~52 iron_block 0  
fill ~54 ~60 ~24 ~55 ~60 ~24 iron_block 0  
fill ~54 ~60 ~26 ~55 ~60 ~26 iron_block 0 
setblock ~54 ~60 ~31 iron_block 0 
setblock ~54 ~60 ~35 iron_block 0 
setblock ~54 ~60 ~37 wooden_door 3  
fill ~54 ~60 ~47 ~54 ~60 ~49 iron_block 0   
fill ~55 ~60 ~22 ~55 ~60 ~26 iron_block 0  
fill ~55 ~60 ~28 ~55 ~60 ~30 iron_block 0  
fill ~55 ~60 ~36 ~55 ~60 ~37 iron_block 0  
fill ~55 ~60 ~44 ~55 ~60 ~46 iron_block 0  
fill ~56 ~60 ~24 ~59 ~60 ~24 stone_slab 0  
fill ~56 ~60 ~26 ~58 ~60 ~26 stone_slab 0  
fill ~56 ~60 ~27 ~56 ~59 ~27 iron_block 0 
setblock ~56 ~60 ~37 iron_block 0  
fill ~56 ~60 ~41 ~56 ~60 ~43 iron_block 0 
setblock ~57 ~60 ~25 glowstone 0  
fill ~57 ~60 ~38 ~57 ~60 ~40 iron_block 0  
fill ~58 ~60 ~25 ~61 ~60 ~25 stone_slab 0  
fill ~64 ~60 ~21 ~64 ~60 ~30 lever 13  
fill ~10 ~61 ~5 ~10 ~61 ~8 lever 5  
fill ~10 ~61 ~11 ~10 ~61 ~14 lever 5  
fill ~13 ~61 ~9 ~16 ~61 ~9 stone_slab 0  
fill ~15 ~61 ~8 ~18 ~61 ~8 stone_slab 0  
fill ~15 ~61 ~24 ~15 ~68 ~24 iron_block 0  
fill ~15 ~61 ~25 ~15 ~61 ~26 iron_block 0  
fill ~16 ~61 ~10 ~18 ~61 ~10 stone_slab 0 
setblock ~16 ~61 ~19 redstone_torch 2  
fill ~16 ~61 ~21 ~16 ~68 ~21 iron_block 0  
fill ~16 ~61 ~22 ~16 ~63 ~22 glass 0  
fill ~16 ~61 ~23 ~16 ~68 ~23 iron_block 0  
fill ~16 ~61 ~27 ~16 ~68 ~27 iron_block 0  
fill ~16 ~61 ~28 ~16 ~63 ~28 glass 0  
fill ~16 ~61 ~29 ~16 ~68 ~29 iron_block 0 
setblock ~16 ~61 ~31 redstone_torch 2  
fill ~17 ~61 ~-6 ~17 ~61 ~-4 iron_block 0 
setblock ~17 ~61 ~9 iron_block 0 
setblock ~17 ~61 ~18 redstone_torch 4  
fill ~17 ~61 ~19 ~18 ~61 ~19 iron_block 0  
fill ~17 ~61 ~20 ~17 ~68 ~20 iron_block 0  
fill ~17 ~61 ~30 ~17 ~68 ~30 iron_block 0  
fill ~17 ~61 ~31 ~18 ~61 ~31 iron_block 0 
setblock ~17 ~61 ~32 redstone_torch 3  
fill ~18 ~61 ~-9 ~18 ~61 ~-7 iron_block 0  
fill ~18 ~61 ~-4 ~20 ~61 ~-4 iron_block 0  
fill ~18 ~61 ~-3 ~18 ~61 ~-4 iron_block 0 
setblock ~18 ~61 ~7 stone_slab 0 
setblock ~18 ~61 ~9 glowstone 0  
fill ~18 ~61 ~11 ~18 ~61 ~12 iron_block 0  
fill ~18 ~61 ~20 ~18 ~68 ~20 fence 0  
fill ~19 ~61 ~-12 ~21 ~61 ~-12 iron_block 0  
fill ~19 ~61 ~-11 ~19 ~61 ~-10 iron_block 0 
setblock ~19 ~61 ~-2 iron_block 0  
fill ~19 ~61 ~4 ~19 ~61 ~5 iron_block 0  
fill ~19 ~61 ~6 ~19 ~61 ~7 quartz_stairs 0  
fill ~19 ~61 ~8 ~19 ~61 ~10 iron_block 0  
fill ~19 ~61 ~13 ~22 ~61 ~13 iron_block 0  
fill ~19 ~61 ~18 ~19 ~68 ~18 iron_block 0  
fill ~19 ~61 ~32 ~19 ~68 ~32 iron_block 0  
fill ~20 ~61 ~-15 ~20 ~61 ~-12 iron_block 0 
setblock ~20 ~61 ~-1 iron_block 0 
setblock ~20 ~61 ~3 iron_block 0  
fill ~20 ~61 ~6 ~20 ~61 ~7 iron_block 0  
fill ~20 ~61 ~18 ~20 ~63 ~18 glass 0  
fill ~20 ~61 ~32 ~20 ~63 ~32 glass 0  
fill ~21 ~61 ~-17 ~21 ~61 ~-16 iron_block 0  
fill ~21 ~61 ~0 ~22 ~61 ~0 iron_block 0  
fill ~21 ~61 ~1 ~21 ~61 ~2 iron_block 0  
fill ~21 ~61 ~7 ~22 ~61 ~7 iron_block 0  
fill ~21 ~61 ~17 ~21 ~61 ~18 iron_block 0  
fill ~21 ~61 ~31 ~21 ~62 ~31 iron_block 0  
fill ~21 ~61 ~32 ~22 ~61 ~32 iron_block 0  
fill ~21 ~61 ~33 ~21 ~61 ~31 iron_block 0  
fill ~22 ~61 ~-19 ~22 ~61 ~-18 iron_block 0  
fill ~22 ~61 ~-13 ~22 ~63 ~-13 iron_block 0  
fill ~22 ~61 ~-4 ~24 ~61 ~-4 iron_block 0 
setblock ~22 ~61 ~12 stone_button 4  
fill ~22 ~61 ~14 ~22 ~62 ~14 double_stone_slab 0  
fill ~22 ~61 ~15 ~22 ~62 ~15 double_stone_slab 0 
setblock ~22 ~61 ~16 iron_block 0 
setblock ~22 ~61 ~17 lever 11  
fill ~22 ~61 ~18 ~22 ~68 ~18 iron_block 0 
setblock ~22 ~61 ~33 stone_button 4 
setblock ~22 ~61 ~34 iron_block 0 
setblock ~22 ~61 ~35 redstone_torch 3 
setblock ~23 ~61 ~-20 iron_block 0 
setblock ~23 ~61 ~-13 wooden_door 1  
fill ~23 ~61 ~-8 ~23 ~64 ~-8 iron_block 0  
fill ~23 ~61 ~-7 ~23 ~63 ~-7 iron_block 0 
setblock ~23 ~61 ~-5 glowstone 0 
setblock ~23 ~61 ~0 wooden_door 1 
setblock ~23 ~61 ~7 wooden_door 1 
setblock ~23 ~61 ~13 iron_door 7 
setblock ~23 ~61 ~16 iron_door 5  
fill ~23 ~61 ~18 ~23 ~62 ~18 ladder 4 
setblock ~23 ~61 ~26 glowstone 0  
fill ~23 ~61 ~27 ~23 ~61 ~28 stone_slab 8  
fill ~23 ~61 ~32 ~23 ~62 ~32 ladder 5 
setblock ~23 ~61 ~34 iron_door 3  
fill ~24 ~61 ~-19 ~24 ~61 ~-18 iron_block 0  
fill ~24 ~61 ~-13 ~24 ~63 ~-13 iron_block 0  
fill ~24 ~61 ~0 ~25 ~61 ~0 iron_block 0  
fill ~24 ~61 ~7 ~26 ~61 ~7 iron_block 0 
setblock ~24 ~61 ~12 lever 12  
fill ~24 ~61 ~13 ~27 ~61 ~13 iron_block 0  
fill ~24 ~61 ~14 ~24 ~62 ~14 double_stone_slab 0  
fill ~24 ~61 ~15 ~24 ~62 ~15 double_stone_slab 0 
setblock ~24 ~61 ~16 iron_block 0 
setblock ~24 ~61 ~17 stone_button 3  
fill ~24 ~61 ~18 ~25 ~61 ~18 iron_block 0  
fill ~24 ~61 ~25 ~24 ~63 ~25 glass 0  
fill ~24 ~61 ~32 ~25 ~61 ~32 iron_block 0 
setblock ~24 ~61 ~33 lever 4 
setblock ~24 ~61 ~34 iron_block 0 
setblock ~24 ~61 ~35 redstone_torch 3  
fill ~25 ~61 ~-17 ~25 ~61 ~-16 iron_block 0  
fill ~25 ~61 ~-12 ~27 ~61 ~-12 iron_block 0 
setblock ~25 ~61 ~-4 wooden_door 1  
fill ~25 ~61 ~1 ~25 ~61 ~2 iron_block 0 
setblock ~25 ~61 ~17 iron_block 0  
fill ~25 ~61 ~31 ~25 ~62 ~31 iron_block 0 
setblock ~25 ~61 ~33 iron_block 0  
fill ~26 ~61 ~-15 ~26 ~61 ~-12 iron_block 0  
fill ~26 ~61 ~-4 ~29 ~61 ~-4 iron_block 0 
setblock ~26 ~61 ~-1 iron_block 0 
setblock ~26 ~61 ~3 iron_block 0 
setblock ~26 ~61 ~6 iron_block 0  
fill ~26 ~61 ~18 ~26 ~63 ~18 glass 0  
fill ~26 ~61 ~32 ~26 ~63 ~32 glass 0  
fill ~27 ~61 ~-11 ~27 ~61 ~-10 iron_block 0 
setblock ~27 ~61 ~-2 iron_block 0  
fill ~27 ~61 ~4 ~27 ~61 ~5 iron_block 0  
fill ~27 ~61 ~6 ~27 ~61 ~7 quartz_stairs 1  
fill ~27 ~61 ~8 ~27 ~61 ~10 iron_block 0  
fill ~27 ~61 ~18 ~27 ~68 ~18 iron_block 0  
fill ~27 ~61 ~32 ~27 ~68 ~32 iron_block 0  
fill ~28 ~61 ~-9 ~28 ~61 ~-7 iron_block 0 
setblock ~28 ~61 ~-3 iron_block 0  
fill ~28 ~61 ~7 ~28 ~61 ~8 stone_slab 0 
setblock ~28 ~61 ~9 glowstone 0  
fill ~28 ~61 ~10 ~30 ~61 ~10 stone_slab 0  
fill ~28 ~61 ~11 ~28 ~61 ~12 iron_block 0  
fill ~28 ~61 ~19 ~29 ~61 ~19 iron_block 0  
fill ~28 ~61 ~20 ~28 ~68 ~20 fence 0  
fill ~28 ~61 ~30 ~28 ~68 ~30 fence 0  
fill ~28 ~61 ~31 ~29 ~61 ~31 iron_block 0  
fill ~29 ~61 ~-6 ~29 ~61 ~-4 iron_block 0  
fill ~29 ~61 ~8 ~31 ~61 ~8 stone_slab 0 
setblock ~29 ~61 ~9 iron_block 0 
setblock ~29 ~61 ~18 redstone_torch 4  
fill ~29 ~61 ~20 ~29 ~68 ~20 iron_block 0  
fill ~29 ~61 ~30 ~29 ~68 ~30 iron_block 0 
setblock ~29 ~61 ~32 redstone_torch 3  
fill ~30 ~61 ~9 ~33 ~61 ~9 stone_slab 0 
setblock ~30 ~61 ~19 redstone_torch 1  
fill ~30 ~61 ~21 ~30 ~68 ~21 iron_block 0  
fill ~30 ~61 ~22 ~30 ~63 ~22 glass 0  
fill ~30 ~61 ~23 ~30 ~68 ~23 iron_block 0  
fill ~30 ~61 ~27 ~30 ~68 ~27 iron_block 0  
fill ~30 ~61 ~28 ~30 ~63 ~28 glass 0  
fill ~30 ~61 ~29 ~30 ~68 ~29 iron_block 0 
setblock ~30 ~61 ~31 redstone_torch 1  
fill ~31 ~61 ~24 ~31 ~68 ~24 iron_block 0  
fill ~31 ~61 ~25 ~31 ~61 ~26 iron_block 0  
fill ~36 ~61 ~5 ~36 ~61 ~8 lever 5  
fill ~36 ~61 ~11 ~36 ~61 ~14 lever 5 
setblock ~45 ~61 ~38 glass 0  
fill ~45 ~61 ~39 ~45 ~61 ~40 planks 1 
setblock ~46 ~61 ~27 glass 0 
setblock ~46 ~61 ~37 planks 1 
setblock ~46 ~61 ~38 torch 3 
setblock ~46 ~61 ~41 glass 0  
fill ~46 ~61 ~42 ~46 ~61 ~43 planks 1 
setblock ~47 ~61 ~22 planks 1 
setblock ~47 ~61 ~23 glass 0 
setblock ~47 ~61 ~26 glass 0  
fill ~47 ~61 ~28 ~47 ~61 ~29 planks 1 
setblock ~47 ~61 ~30 glass 0 
setblock ~47 ~61 ~36 glass 0 
setblock ~47 ~61 ~37 iron_block 0 
setblock ~47 ~61 ~44 glass 0  
fill ~47 ~61 ~45 ~47 ~61 ~46 planks 1  
fill ~48 ~61 ~21 ~49 ~61 ~21 planks 1 
setblock ~48 ~61 ~22 torch 1  
fill ~48 ~61 ~24 ~48 ~61 ~25 planks 1 
setblock ~48 ~61 ~31 planks 1 
setblock ~48 ~61 ~35 planks 1 
setblock ~48 ~61 ~37 wooden_door 8  
fill ~48 ~61 ~46 ~50 ~61 ~46 iron_block 0 
setblock ~48 ~61 ~47 glass 0 
setblock ~48 ~61 ~48 planks 1 
setblock ~48 ~61 ~49 glass 0  
fill ~49 ~61 ~25 ~50 ~61 ~25 iron_block 0 
setblock ~49 ~61 ~26 torch 3 
setblock ~49 ~61 ~32 planks 1 
setblock ~49 ~61 ~33 glass 0 
setblock ~49 ~61 ~34 planks 1  
fill ~49 ~61 ~38 ~53 ~61 ~38 iron_block 0  
fill ~49 ~61 ~50 ~49 ~61 ~51 planks 1 
setblock ~49 ~61 ~52 glass 0 
setblock ~50 ~61 ~21 glass 0 
setblock ~50 ~61 ~24 torch 4 
setblock ~50 ~61 ~31 torch 4  
fill ~50 ~61 ~32 ~50 ~62 ~32 iron_block 0 
setblock ~50 ~61 ~33 torch 3 
setblock ~50 ~61 ~37 torch 1 
setblock ~50 ~61 ~42 torch 2 
setblock ~50 ~61 ~47 torch 3  
fill ~50 ~61 ~53 ~50 ~61 ~54 glass 0 
setblock ~51 ~61 ~20 glass 0 
setblock ~51 ~61 ~25 wooden_door 8 
setblock ~51 ~61 ~32 wooden_door 8 
setblock ~51 ~61 ~46 wooden_door 8 
setblock ~51 ~61 ~55 glass 0 
setblock ~52 ~61 ~21 glass 0 
setblock ~52 ~61 ~24 torch 4  
fill ~52 ~61 ~25 ~53 ~61 ~25 iron_block 0 
setblock ~52 ~61 ~31 torch 4  
fill ~52 ~61 ~32 ~52 ~62 ~32 iron_block 0 
setblock ~52 ~61 ~33 torch 3 
setblock ~52 ~61 ~37 torch 2 
setblock ~52 ~61 ~42 torch 1  
fill ~52 ~61 ~46 ~54 ~61 ~46 iron_block 0 
setblock ~52 ~61 ~47 torch 3  
fill ~52 ~61 ~53 ~52 ~61 ~54 glass 0  
fill ~53 ~61 ~21 ~54 ~61 ~21 planks 1 
setblock ~53 ~61 ~26 torch 3 
setblock ~53 ~61 ~32 planks 1 
setblock ~53 ~61 ~33 glass 0 
setblock ~53 ~61 ~34 planks 1  
fill ~53 ~61 ~50 ~53 ~61 ~51 planks 1 
setblock ~53 ~61 ~52 glass 0 
setblock ~54 ~61 ~22 torch 2  
fill ~54 ~61 ~24 ~54 ~61 ~26 planks 1 
setblock ~54 ~61 ~31 planks 1 
setblock ~54 ~61 ~35 planks 1 
setblock ~54 ~61 ~37 wooden_door 8 
setblock ~54 ~61 ~47 glass 0 
setblock ~54 ~61 ~48 planks 1 
setblock ~54 ~61 ~49 glass 0 
setblock ~55 ~61 ~22 planks 1 
setblock ~55 ~61 ~23 glass 0 
setblock ~55 ~61 ~26 glass 0  
fill ~55 ~61 ~28 ~55 ~61 ~29 planks 1 
setblock ~55 ~61 ~30 glass 0 
setblock ~55 ~61 ~36 glass 0  
fill ~55 ~61 ~37 ~55 ~62 ~37 iron_block 0 
setblock ~55 ~61 ~44 glass 0  
fill ~55 ~61 ~45 ~55 ~61 ~46 planks 1 
setblock ~56 ~61 ~27 glass 0 
setblock ~56 ~61 ~37 planks 1 
setblock ~56 ~61 ~38 torch 3 
setblock ~56 ~61 ~41 glass 0  
fill ~56 ~61 ~42 ~56 ~61 ~43 planks 1 
setblock ~57 ~61 ~38 glass 0  
fill ~57 ~61 ~39 ~57 ~61 ~40 planks 1  
fill ~15 ~62 ~25 ~15 ~63 ~25 quartz_block 0  
fill ~15 ~62 ~26 ~15 ~68 ~26 iron_block 0  
fill ~16 ~62 ~25 ~21 ~62 ~25 stone_slab 8 
setblock ~17 ~62 ~-6 planks 1 
setblock ~17 ~62 ~-5 glass 0 
setblock ~17 ~62 ~-4 planks 1  
fill ~17 ~62 ~19 ~17 ~63 ~19 fence 0  
fill ~17 ~62 ~31 ~17 ~63 ~31 fence 0 
setblock ~18 ~62 ~-9 glass 0 
setblock ~18 ~62 ~-8 planks 1 
setblock ~18 ~62 ~-7 glass 0  
fill ~18 ~62 ~-4 ~20 ~62 ~-4 iron_block 0 
setblock ~18 ~62 ~-3 glass 0  
fill ~18 ~62 ~11 ~18 ~62 ~12 planks 1  
fill ~18 ~62 ~19 ~18 ~68 ~19 iron_block 0  
fill ~18 ~62 ~31 ~18 ~68 ~31 iron_block 0 
setblock ~19 ~62 ~-12 planks 1 
setblock ~19 ~62 ~-11 glass 0 
setblock ~19 ~62 ~-10 planks 1 
setblock ~19 ~62 ~-2 planks 1 
setblock ~19 ~62 ~4 planks 1 
setblock ~19 ~62 ~5 glass 0 
setblock ~19 ~62 ~8 glass 0 
setblock ~19 ~62 ~9 planks 1 
setblock ~19 ~62 ~10 glass 0 
setblock ~19 ~62 ~13 glass 0 
setblock ~20 ~62 ~-15 glass 0 
setblock ~20 ~62 ~-14 planks 1 
setblock ~20 ~62 ~-13 glass 0  
fill ~20 ~62 ~-12 ~21 ~62 ~-12 iron_block 0 
setblock ~20 ~62 ~-1 glass 0 
setblock ~20 ~62 ~3 glass 0  
fill ~20 ~62 ~6 ~20 ~62 ~7 planks 1 
setblock ~20 ~62 ~13 planks 1  
fill ~21 ~62 ~-17 ~21 ~62 ~-16 planks 1 
setblock ~21 ~62 ~0 planks 1 
setblock ~21 ~62 ~1 glass 0 
setblock ~21 ~62 ~2 planks 1  
fill ~21 ~62 ~7 ~22 ~62 ~7 iron_block 0 
setblock ~21 ~62 ~13 glass 0 
setblock ~21 ~62 ~17 planks 1  
fill ~21 ~62 ~18 ~21 ~68 ~18 iron_block 0  
fill ~21 ~62 ~32 ~22 ~62 ~32 iron_block 0 
setblock ~21 ~62 ~33 planks 1  
fill ~22 ~62 ~-19 ~22 ~62 ~-18 glass 0  
fill ~22 ~62 ~-4 ~24 ~62 ~-4 iron_block 0  
fill ~22 ~62 ~0 ~22 ~63 ~0 iron_block 0 
setblock ~22 ~62 ~13 planks 1 
setblock ~22 ~62 ~16 glass 0 
setblock ~22 ~62 ~20 iron_block 0 
setblock ~22 ~62 ~25 glowstone 0 
setblock ~22 ~62 ~30 iron_block 0 
setblock ~22 ~62 ~34 glass 0 
setblock ~23 ~62 ~-20 glass 0 
setblock ~23 ~62 ~-13 wooden_door 8  
fill ~23 ~62 ~-5 ~23 ~64 ~-5 iron_block 0 
setblock ~23 ~62 ~0 wooden_door 8 
setblock ~23 ~62 ~7 wooden_door 8 
setblock ~23 ~62 ~13 iron_door 8 
setblock ~23 ~62 ~16 iron_door 8 
setblock ~23 ~62 ~25 stained_hardened_clay 6  
fill ~23 ~62 ~26 ~23 ~64 ~26 glass 0 
setblock ~23 ~62 ~34 iron_door 8  
fill ~24 ~62 ~-19 ~24 ~62 ~-18 glass 0  
fill ~24 ~62 ~0 ~24 ~63 ~0 iron_block 0  
fill ~24 ~62 ~7 ~25 ~62 ~7 iron_block 0 
setblock ~24 ~62 ~13 planks 1 
setblock ~24 ~62 ~16 glass 0  
fill ~24 ~62 ~18 ~25 ~62 ~18 iron_block 0 
setblock ~24 ~62 ~20 iron_block 0 
setblock ~24 ~62 ~30 iron_block 0  
fill ~24 ~62 ~32 ~25 ~62 ~32 iron_block 0 
setblock ~24 ~62 ~34 glass 0  
fill ~25 ~62 ~-17 ~25 ~62 ~-16 planks 1  
fill ~25 ~62 ~-12 ~26 ~62 ~-12 iron_block 0 
setblock ~25 ~62 ~-4 wooden_door 8 
setblock ~25 ~62 ~0 planks 1 
setblock ~25 ~62 ~1 glass 0 
setblock ~25 ~62 ~2 planks 1 
setblock ~25 ~62 ~13 glass 0 
setblock ~25 ~62 ~17 planks 1 
setblock ~25 ~62 ~33 planks 1 
setblock ~26 ~62 ~-15 glass 0 
setblock ~26 ~62 ~-14 planks 1 
setblock ~26 ~62 ~-13 glass 0  
fill ~26 ~62 ~-4 ~28 ~62 ~-4 iron_block 0 
setblock ~26 ~62 ~-1 glass 0 
setblock ~26 ~62 ~3 glass 0  
fill ~26 ~62 ~6 ~26 ~62 ~7 planks 1 
setblock ~26 ~62 ~13 planks 1 
setblock ~27 ~62 ~-12 planks 1 
setblock ~27 ~62 ~-11 glass 0 
setblock ~27 ~62 ~-10 planks 1 
setblock ~27 ~62 ~-2 planks 1 
setblock ~27 ~62 ~4 planks 1 
setblock ~27 ~62 ~5 glass 0 
setblock ~27 ~62 ~8 glass 0 
setblock ~27 ~62 ~9 planks 1 
setblock ~27 ~62 ~10 glass 0 
setblock ~27 ~62 ~13 glass 0 
setblock ~28 ~62 ~-9 glass 0 
setblock ~28 ~62 ~-8 planks 1 
setblock ~28 ~62 ~-7 glass 0 
setblock ~28 ~62 ~-3 glass 0  
fill ~28 ~62 ~11 ~28 ~62 ~12 planks 1  
fill ~28 ~62 ~19 ~28 ~68 ~19 iron_block 0  
fill ~28 ~62 ~31 ~28 ~68 ~31 iron_block 0 
setblock ~29 ~62 ~-6 planks 1 
setblock ~29 ~62 ~-5 glass 0 
setblock ~29 ~62 ~-4 planks 1  
fill ~29 ~62 ~19 ~29 ~63 ~19 fence 0  
fill ~29 ~62 ~31 ~29 ~63 ~31 fence 0  
fill ~31 ~62 ~25 ~31 ~63 ~25 quartz_block 0  
fill ~31 ~62 ~26 ~31 ~68 ~26 iron_block 0  
fill ~46 ~62 ~38 ~56 ~62 ~38 iron_block 0  
fill ~46 ~62 ~39 ~56 ~62 ~39 iron_block 0  
fill ~46 ~62 ~40 ~56 ~62 ~40 iron_block 0  
fill ~47 ~62 ~27 ~55 ~62 ~27 iron_block 0  
fill ~47 ~62 ~41 ~55 ~62 ~41 iron_block 0  
fill ~47 ~62 ~42 ~55 ~62 ~42 iron_block 0  
fill ~47 ~62 ~43 ~55 ~62 ~43 iron_block 0  
fill ~48 ~62 ~22 ~50 ~62 ~22 iron_block 0  
fill ~48 ~62 ~23 ~54 ~62 ~23 iron_block 0  
fill ~48 ~62 ~26 ~54 ~62 ~26 iron_block 0  
fill ~48 ~62 ~28 ~54 ~62 ~28 iron_block 0  
fill ~48 ~62 ~29 ~54 ~62 ~29 iron_block 0  
fill ~48 ~62 ~30 ~54 ~62 ~30 iron_block 0  
fill ~48 ~62 ~36 ~54 ~62 ~36 iron_block 0  
fill ~48 ~62 ~37 ~48 ~62 ~36 iron_block 0  
fill ~48 ~62 ~44 ~54 ~62 ~44 iron_block 0  
fill ~48 ~62 ~45 ~54 ~62 ~45 iron_block 0  
fill ~48 ~62 ~46 ~54 ~62 ~46 iron_block 0  
fill ~49 ~62 ~24 ~53 ~62 ~24 iron_block 0  
fill ~49 ~62 ~25 ~53 ~62 ~25 iron_block 0  
fill ~49 ~62 ~31 ~53 ~62 ~31 iron_block 0  
fill ~49 ~62 ~35 ~53 ~62 ~35 iron_block 0  
fill ~49 ~62 ~47 ~53 ~62 ~47 iron_block 0  
fill ~49 ~62 ~48 ~53 ~62 ~48 iron_block 0  
fill ~49 ~62 ~49 ~53 ~62 ~49 iron_block 0 
setblock ~50 ~62 ~33 glowstone 0  
fill ~50 ~62 ~34 ~52 ~62 ~34 iron_block 0  
fill ~50 ~62 ~37 ~55 ~62 ~37 iron_block 0  
fill ~50 ~62 ~50 ~52 ~62 ~50 iron_block 0  
fill ~50 ~62 ~51 ~52 ~62 ~51 iron_block 0  
fill ~50 ~62 ~52 ~50 ~62 ~34 iron_block 0 
setblock ~51 ~62 ~21 iron_block 0 
setblock ~51 ~62 ~22 glowstone 0  
fill ~51 ~62 ~32 ~51 ~62 ~51 iron_block 0 
setblock ~51 ~62 ~52 glowstone 0  
fill ~51 ~62 ~53 ~51 ~62 ~54 iron_block 0  
fill ~52 ~62 ~22 ~54 ~62 ~22 iron_block 0 
setblock ~52 ~62 ~33 glowstone 0 
setblock ~52 ~62 ~52 iron_block 0  
fill ~18 ~63 ~-6 ~28 ~63 ~-6 iron_block 0  
fill ~18 ~63 ~-5 ~28 ~63 ~-5 iron_block 0  
fill ~18 ~63 ~-4 ~19 ~63 ~-4 iron_block 0  
fill ~19 ~63 ~-9 ~27 ~63 ~-9 iron_block 0  
fill ~19 ~63 ~-8 ~27 ~63 ~-8 iron_block 0  
fill ~19 ~63 ~-7 ~27 ~63 ~-7 iron_block 0  
fill ~19 ~63 ~-3 ~27 ~63 ~-3 iron_block 0  
fill ~19 ~63 ~11 ~27 ~63 ~11 iron_block 0 
setblock ~19 ~63 ~12 glowstone 0  
fill ~20 ~63 ~-12 ~26 ~63 ~-12 iron_block 0  
fill ~20 ~63 ~-11 ~26 ~63 ~-11 iron_block 0  
fill ~20 ~63 ~-10 ~26 ~63 ~-10 iron_block 0 
setblock ~20 ~63 ~-4 glowstone 0  
fill ~20 ~63 ~-2 ~26 ~63 ~-2 iron_block 0  
fill ~20 ~63 ~4 ~20 ~63 ~5 iron_block 0  
fill ~20 ~63 ~8 ~26 ~63 ~8 iron_block 0  
fill ~20 ~63 ~9 ~26 ~63 ~9 iron_block 0  
fill ~20 ~63 ~10 ~26 ~63 ~10 iron_block 0  
fill ~20 ~63 ~12 ~26 ~63 ~12 iron_block 0  
fill ~21 ~63 ~-15 ~25 ~63 ~-15 iron_block 0  
fill ~21 ~63 ~-14 ~25 ~63 ~-14 iron_block 0  
fill ~21 ~63 ~-13 ~21 ~63 ~-15 iron_block 0  
fill ~21 ~63 ~-4 ~25 ~63 ~-4 iron_block 0  
fill ~21 ~63 ~-1 ~25 ~63 ~-1 iron_block 0  
fill ~21 ~63 ~3 ~25 ~63 ~3 iron_block 0 
setblock ~21 ~63 ~4 glowstone 0  
fill ~21 ~63 ~5 ~26 ~63 ~5 iron_block 0  
fill ~21 ~63 ~6 ~25 ~63 ~6 iron_block 0  
fill ~21 ~63 ~7 ~25 ~63 ~7 iron_block 0  
fill ~21 ~63 ~32 ~22 ~63 ~32 iron_block 0  
fill ~22 ~63 ~-17 ~24 ~63 ~-17 iron_block 0  
fill ~22 ~63 ~-16 ~24 ~63 ~-16 iron_block 0  
fill ~22 ~63 ~1 ~24 ~63 ~1 iron_block 0  
fill ~22 ~63 ~2 ~24 ~63 ~2 iron_block 0  
fill ~22 ~63 ~4 ~24 ~63 ~4 iron_block 0 
setblock ~22 ~63 ~16 quartz_stairs 0  
fill ~22 ~63 ~17 ~22 ~68 ~17 iron_block 0  
fill ~22 ~63 ~19 ~22 ~71 ~19 fence 0  
fill ~22 ~63 ~25 ~22 ~65 ~25 glass 0  
fill ~22 ~63 ~33 ~22 ~68 ~33 iron_block 0 
setblock ~22 ~63 ~34 quartz_stairs 0  
fill ~23 ~63 ~-19 ~23 ~63 ~13 iron_block 0  
fill ~23 ~63 ~14 ~23 ~63 ~15 stone_slab 0 
setblock ~23 ~63 ~16 quartz_stairs 2 
setblock ~23 ~63 ~17 quartz_block 0  
fill ~23 ~63 ~18 ~23 ~73 ~18 ladder 2  
fill ~23 ~63 ~19 ~23 ~73 ~19 iron_block 0  
fill ~23 ~63 ~20 ~23 ~63 ~19 iron_block 0  
fill ~23 ~63 ~22 ~23 ~63 ~23 stone_slab 8 
setblock ~23 ~63 ~24 glowstone 0  
fill ~23 ~63 ~25 ~23 ~64 ~25 stained_hardened_clay 14  
fill ~23 ~63 ~30 ~23 ~63 ~31 iron_block 0  
fill ~23 ~63 ~32 ~23 ~73 ~32 ladder 3 
setblock ~23 ~63 ~33 quartz_block 0 
setblock ~23 ~63 ~34 quartz_stairs 3 
setblock ~24 ~63 ~16 quartz_stairs 1  
fill ~24 ~63 ~17 ~24 ~68 ~17 iron_block 0  
fill ~24 ~63 ~18 ~25 ~63 ~18 iron_block 0  
fill ~24 ~63 ~19 ~24 ~71 ~19 fence 0  
fill ~24 ~63 ~32 ~25 ~63 ~32 iron_block 0  
fill ~24 ~63 ~33 ~24 ~68 ~33 iron_block 0 
setblock ~24 ~63 ~34 quartz_stairs 1 
setblock ~25 ~63 ~-13 iron_block 0 
setblock ~25 ~63 ~4 glowstone 0 
setblock ~26 ~63 ~-4 glowstone 0 
setblock ~26 ~63 ~4 iron_block 0  
fill ~27 ~63 ~-4 ~28 ~63 ~-4 iron_block 0 
setblock ~27 ~63 ~12 glowstone 0 
setblock ~48 ~63 ~39 stone_slab 0 
setblock ~49 ~63 ~28 stone_slab 0 
setblock ~49 ~63 ~38 stone_slab 0  
fill ~49 ~63 ~39 ~50 ~63 ~39 iron_block 0  
fill ~49 ~63 ~40 ~49 ~63 ~41 stone_slab 0  
fill ~50 ~63 ~25 ~50 ~63 ~27 stone_slab 0 
setblock ~50 ~63 ~28 iron_block 0 
setblock ~50 ~63 ~29 stone_slab 0 
setblock ~50 ~63 ~37 stone_slab 0  
fill ~50 ~63 ~38 ~52 ~63 ~38 iron_block 0  
fill ~50 ~63 ~40 ~50 ~63 ~41 iron_block 0  
fill ~50 ~63 ~42 ~50 ~63 ~47 stone_slab 0  
fill ~51 ~63 ~23 ~51 ~63 ~24 stone_slab 0  
fill ~51 ~63 ~25 ~51 ~63 ~27 iron_block 0 
setblock ~51 ~63 ~28 glowstone 0 
setblock ~51 ~63 ~29 iron_block 0  
fill ~51 ~63 ~30 ~51 ~63 ~36 stone_slab 0 
setblock ~51 ~63 ~37 iron_block 0 
setblock ~51 ~63 ~39 glowstone 0  
fill ~51 ~63 ~43 ~51 ~63 ~44 iron_block 0 
setblock ~51 ~63 ~45 glowstone 0  
fill ~51 ~63 ~46 ~51 ~63 ~47 iron_block 0  
fill ~51 ~63 ~48 ~51 ~63 ~50 stone_slab 0  
fill ~52 ~63 ~25 ~52 ~63 ~27 stone_slab 0 
setblock ~52 ~63 ~28 iron_block 0 
setblock ~52 ~63 ~29 stone_slab 0 
setblock ~52 ~63 ~37 stone_slab 0  
fill ~52 ~63 ~39 ~53 ~63 ~39 iron_block 0  
fill ~52 ~63 ~40 ~52 ~63 ~41 iron_block 0  
fill ~52 ~63 ~42 ~52 ~63 ~47 stone_slab 0 
setblock ~53 ~63 ~28 stone_slab 0 
setblock ~53 ~63 ~38 stone_slab 0  
fill ~53 ~63 ~40 ~53 ~63 ~41 stone_slab 0 
setblock ~54 ~63 ~39 stone_slab 0 
setblock ~15 ~64 ~23 redstone_torch 4 
setblock ~15 ~64 ~25 glowstone 0 
setblock ~15 ~64 ~27 redstone_torch 3 
setblock ~16 ~64 ~22 glowstone 0 
setblock ~16 ~64 ~28 glowstone 0 
setblock ~17 ~64 ~19 glowstone 0 
setblock ~17 ~64 ~31 glowstone 0 
setblock ~20 ~64 ~18 glowstone 0 
setblock ~20 ~64 ~32 glowstone 0  
fill ~21 ~64 ~-10 ~21 ~64 ~-6 stone_slab 0  
fill ~21 ~64 ~11 ~22 ~64 ~11 stone_slab 0 
setblock ~21 ~64 ~17 redstone_torch 2  
fill ~21 ~64 ~32 ~22 ~64 ~32 iron_block 0 
setblock ~21 ~64 ~33 redstone_torch 2  
fill ~22 ~64 ~-13 ~22 ~64 ~-11 stone_slab 0  
fill ~22 ~64 ~-10 ~24 ~64 ~-10 iron_block 0  
fill ~22 ~64 ~-9 ~22 ~64 ~-6 iron_block 0  
fill ~22 ~64 ~-5 ~22 ~64 ~-4 stone_slab 0  
fill ~22 ~64 ~6 ~22 ~64 ~9 stone_slab 0  
fill ~22 ~64 ~31 ~22 ~71 ~31 fence 0  
fill ~23 ~64 ~-16 ~23 ~64 ~-14 stone_slab 0 
setblock ~23 ~64 ~-13 glowstone 0  
fill ~23 ~64 ~-12 ~23 ~64 ~-8 iron_block 0 
setblock ~23 ~64 ~-7 glowstone 0 
setblock ~23 ~64 ~-4 iron_block 0  
fill ~23 ~64 ~-3 ~23 ~64 ~5 stone_slab 0  
fill ~23 ~64 ~6 ~23 ~64 ~7 iron_block 0 
setblock ~23 ~64 ~8 glowstone 0 
setblock ~23 ~64 ~9 iron_block 0 
setblock ~23 ~64 ~10 stone_slab 0 
setblock ~23 ~64 ~17 glowstone 0  
fill ~23 ~64 ~24 ~23 ~66 ~24 glass 0  
fill ~23 ~64 ~31 ~23 ~73 ~31 iron_block 0 
setblock ~23 ~64 ~33 glowstone 0  
fill ~24 ~64 ~-13 ~24 ~64 ~-11 stone_slab 0  
fill ~24 ~64 ~-9 ~24 ~64 ~-6 iron_block 0  
fill ~24 ~64 ~-5 ~24 ~64 ~-4 stone_slab 0  
fill ~24 ~64 ~6 ~24 ~64 ~9 stone_slab 0  
fill ~24 ~64 ~11 ~25 ~64 ~11 stone_slab 0  
fill ~24 ~64 ~18 ~25 ~64 ~18 iron_block 0 
setblock ~24 ~64 ~25 glowstone 0  
fill ~24 ~64 ~31 ~24 ~71 ~31 fence 0  
fill ~24 ~64 ~32 ~25 ~64 ~32 iron_block 0  
fill ~25 ~64 ~-10 ~25 ~64 ~-6 stone_slab 0 
setblock ~25 ~64 ~17 redstone_torch 1  
fill ~25 ~64 ~25 ~30 ~64 ~25 stone_slab 8 
setblock ~25 ~64 ~33 redstone_torch 1 
setblock ~26 ~64 ~18 glowstone 0 
setblock ~26 ~64 ~32 glowstone 0 
setblock ~29 ~64 ~19 glowstone 0 
setblock ~29 ~64 ~31 glowstone 0 
setblock ~30 ~64 ~22 glowstone 0 
setblock ~30 ~64 ~28 glowstone 0 
setblock ~31 ~64 ~23 redstone_torch 4 
setblock ~31 ~64 ~25 glowstone 0 
setblock ~31 ~64 ~27 redstone_torch 3  
fill ~15 ~65 ~25 ~15 ~66 ~25 quartz_block 0  
fill ~16 ~65 ~22 ~16 ~66 ~22 quartz_block 0  
fill ~16 ~65 ~28 ~16 ~66 ~28 quartz_block 0  
fill ~17 ~65 ~19 ~17 ~66 ~19 quartz_block 0  
fill ~17 ~65 ~31 ~17 ~66 ~31 quartz_block 0  
fill ~20 ~65 ~18 ~20 ~66 ~18 quartz_block 0  
fill ~20 ~65 ~32 ~20 ~66 ~32 quartz_block 0  
fill ~21 ~65 ~32 ~22 ~65 ~32 iron_block 0  
fill ~23 ~65 ~17 ~23 ~66 ~17 quartz_block 0  
fill ~23 ~65 ~25 ~23 ~68 ~25 stained_hardened_clay 6 
setblock ~23 ~65 ~26 glowstone 0  
fill ~23 ~65 ~27 ~23 ~65 ~30 stone_slab 8  
fill ~23 ~65 ~33 ~23 ~66 ~33 quartz_block 0  
fill ~24 ~65 ~18 ~25 ~65 ~18 iron_block 0  
fill ~24 ~65 ~25 ~24 ~67 ~25 glass 0  
fill ~24 ~65 ~32 ~25 ~65 ~32 iron_block 0  
fill ~26 ~65 ~18 ~26 ~66 ~18 quartz_block 0  
fill ~26 ~65 ~32 ~26 ~66 ~32 quartz_block 0  
fill ~29 ~65 ~19 ~29 ~67 ~19 iron_block 0  
fill ~29 ~65 ~31 ~29 ~66 ~31 quartz_block 0  
fill ~30 ~65 ~22 ~30 ~66 ~22 quartz_block 0  
fill ~30 ~65 ~28 ~30 ~66 ~28 quartz_block 0  
fill ~31 ~65 ~25 ~31 ~66 ~25 quartz_block 0  
fill ~16 ~66 ~25 ~21 ~66 ~25 stone_slab 8  
fill ~21 ~66 ~32 ~22 ~66 ~32 iron_block 0 
setblock ~22 ~66 ~25 glowstone 0  
fill ~23 ~66 ~26 ~23 ~68 ~26 glass 0  
fill ~24 ~66 ~18 ~25 ~66 ~18 iron_block 0  
fill ~24 ~66 ~32 ~25 ~66 ~32 iron_block 0  
fill ~14 ~67 ~24 ~14 ~67 ~26 stone_slab 8  
fill ~15 ~67 ~21 ~15 ~67 ~23 stone_slab 8  
fill ~15 ~67 ~25 ~15 ~68 ~25 iron_block 0  
fill ~15 ~67 ~27 ~15 ~67 ~29 stone_slab 8  
fill ~16 ~67 ~19 ~16 ~67 ~20 stone_slab 8  
fill ~16 ~67 ~22 ~16 ~68 ~22 iron_block 0  
fill ~16 ~67 ~28 ~16 ~68 ~28 iron_block 0  
fill ~16 ~67 ~30 ~16 ~67 ~31 stone_slab 8  
fill ~17 ~67 ~18 ~18 ~67 ~18 stone_slab 8 
setblock ~17 ~67 ~19 iron_block 0 
setblock ~17 ~67 ~31 iron_block 0  
fill ~17 ~67 ~32 ~18 ~67 ~32 stone_slab 8  
fill ~19 ~67 ~17 ~21 ~67 ~17 stone_slab 8  
fill ~19 ~67 ~33 ~21 ~67 ~33 stone_slab 8  
fill ~20 ~67 ~18 ~20 ~68 ~18 iron_block 0  
fill ~20 ~67 ~32 ~22 ~67 ~32 iron_block 0  
fill ~22 ~67 ~16 ~24 ~67 ~16 stone_slab 8  
fill ~22 ~67 ~25 ~22 ~69 ~25 glass 0  
fill ~22 ~67 ~34 ~24 ~67 ~34 stone_slab 8  
fill ~23 ~67 ~17 ~23 ~72 ~17 iron_block 0  
fill ~23 ~67 ~20 ~23 ~67 ~23 stone_slab 8 
setblock ~23 ~67 ~24 glowstone 0  
fill ~23 ~67 ~33 ~23 ~72 ~33 iron_block 0  
fill ~24 ~67 ~18 ~27 ~67 ~18 iron_block 0  
fill ~24 ~67 ~32 ~27 ~67 ~32 iron_block 0  
fill ~25 ~67 ~17 ~27 ~67 ~17 stone_slab 8  
fill ~25 ~67 ~33 ~27 ~67 ~33 stone_slab 8  
fill ~28 ~67 ~18 ~29 ~67 ~18 stone_slab 8  
fill ~28 ~67 ~32 ~29 ~67 ~32 stone_slab 8 
setblock ~29 ~67 ~31 iron_block 0  
fill ~30 ~67 ~19 ~30 ~67 ~20 stone_slab 8  
fill ~30 ~67 ~22 ~30 ~68 ~22 iron_block 0  
fill ~30 ~67 ~28 ~30 ~68 ~28 iron_block 0  
fill ~30 ~67 ~30 ~30 ~67 ~31 stone_slab 8  
fill ~31 ~67 ~21 ~31 ~67 ~23 stone_slab 8  
fill ~31 ~67 ~25 ~31 ~68 ~25 iron_block 0  
fill ~31 ~67 ~27 ~31 ~67 ~29 stone_slab 8  
fill ~32 ~67 ~24 ~32 ~67 ~26 stone_slab 8  
fill ~13 ~68 ~24 ~15 ~68 ~24 iron_block 0  
fill ~13 ~68 ~25 ~15 ~68 ~25 iron_block 0  
fill ~13 ~68 ~26 ~15 ~68 ~26 iron_block 0  
fill ~14 ~68 ~21 ~16 ~68 ~21 iron_block 0  
fill ~14 ~68 ~22 ~16 ~68 ~22 iron_block 0  
fill ~14 ~68 ~23 ~16 ~68 ~23 iron_block 0  
fill ~14 ~68 ~27 ~16 ~68 ~27 iron_block 0  
fill ~14 ~68 ~28 ~16 ~68 ~28 iron_block 0  
fill ~14 ~68 ~29 ~16 ~68 ~29 iron_block 0  
fill ~15 ~68 ~19 ~16 ~68 ~19 iron_block 0  
fill ~15 ~68 ~20 ~17 ~68 ~20 iron_block 0  
fill ~15 ~68 ~30 ~17 ~68 ~30 iron_block 0  
fill ~15 ~68 ~31 ~16 ~68 ~31 iron_block 0  
fill ~16 ~68 ~18 ~22 ~68 ~18 iron_block 0  
fill ~16 ~68 ~32 ~22 ~68 ~32 iron_block 0  
fill ~17 ~68 ~17 ~29 ~68 ~17 iron_block 0 
setblock ~17 ~68 ~19 glowstone 0 
setblock ~17 ~68 ~31 glowstone 0  
fill ~17 ~68 ~33 ~29 ~68 ~33 iron_block 0  
fill ~19 ~68 ~16 ~27 ~68 ~16 iron_block 0  
fill ~19 ~68 ~34 ~27 ~68 ~34 iron_block 0  
fill ~22 ~68 ~15 ~24 ~68 ~15 iron_block 0  
fill ~22 ~68 ~35 ~24 ~68 ~35 iron_block 0  
fill ~23 ~68 ~24 ~23 ~70 ~24 glass 0  
fill ~24 ~68 ~18 ~30 ~68 ~18 iron_block 0 
setblock ~24 ~68 ~25 glowstone 0  
fill ~24 ~68 ~32 ~30 ~68 ~32 iron_block 0  
fill ~25 ~68 ~25 ~30 ~68 ~25 stone_slab 8 
setblock ~29 ~68 ~19 glowstone 0 
setblock ~29 ~68 ~31 glowstone 0  
fill ~30 ~68 ~19 ~31 ~68 ~19 iron_block 0  
fill ~30 ~68 ~20 ~31 ~68 ~20 iron_block 0  
fill ~30 ~68 ~30 ~31 ~68 ~30 iron_block 0  
fill ~30 ~68 ~31 ~31 ~68 ~31 iron_block 0  
fill ~31 ~68 ~21 ~32 ~68 ~21 iron_block 0  
fill ~31 ~68 ~22 ~32 ~68 ~22 iron_block 0  
fill ~31 ~68 ~23 ~32 ~68 ~23 iron_block 0  
fill ~31 ~68 ~27 ~32 ~68 ~27 iron_block 0  
fill ~31 ~68 ~28 ~32 ~68 ~28 iron_block 0  
fill ~31 ~68 ~29 ~32 ~68 ~29 iron_block 0  
fill ~32 ~68 ~24 ~33 ~68 ~24 iron_block 0  
fill ~32 ~68 ~25 ~33 ~68 ~25 iron_block 0  
fill ~32 ~68 ~26 ~33 ~68 ~26 iron_block 0 
setblock ~12 ~69 ~22 redstone_torch 2  
fill ~12 ~69 ~24 ~12 ~72 ~24 iron_block 0  
fill ~12 ~69 ~25 ~13 ~69 ~25 iron_block 0  
fill ~12 ~69 ~26 ~12 ~72 ~26 iron_block 0 
setblock ~12 ~69 ~28 redstone_torch 2  
fill ~13 ~69 ~21 ~13 ~72 ~21 iron_block 0  
fill ~13 ~69 ~22 ~13 ~72 ~22 iron_block 0  
fill ~13 ~69 ~23 ~13 ~72 ~23 iron_block 0  
fill ~13 ~69 ~27 ~13 ~72 ~27 iron_block 0  
fill ~13 ~69 ~28 ~13 ~72 ~28 iron_block 0  
fill ~13 ~69 ~29 ~13 ~72 ~29 iron_block 0  
fill ~14 ~69 ~19 ~14 ~72 ~19 iron_block 0  
fill ~14 ~69 ~20 ~14 ~72 ~20 iron_block 0 
setblock ~14 ~69 ~24 iron_block 0 
setblock ~14 ~69 ~25 glowstone 0 
setblock ~14 ~69 ~26 iron_block 0  
fill ~14 ~69 ~30 ~14 ~72 ~30 iron_block 0  
fill ~14 ~69 ~31 ~14 ~72 ~31 iron_block 0 
setblock ~15 ~69 ~17 glowstone 0  
fill ~15 ~69 ~18 ~15 ~72 ~18 iron_block 0  
fill ~15 ~69 ~21 ~15 ~69 ~23 iron_block 0  
fill ~15 ~69 ~27 ~15 ~69 ~29 iron_block 0  
fill ~15 ~69 ~32 ~15 ~72 ~32 iron_block 0 
setblock ~15 ~69 ~33 glowstone 0  
fill ~16 ~69 ~17 ~16 ~72 ~17 iron_block 0  
fill ~16 ~69 ~19 ~16 ~69 ~20 iron_block 0  
fill ~16 ~69 ~30 ~16 ~69 ~31 iron_block 0  
fill ~16 ~69 ~33 ~16 ~72 ~33 iron_block 0  
fill ~17 ~69 ~16 ~18 ~69 ~16 iron_block 0  
fill ~17 ~69 ~18 ~18 ~69 ~18 iron_block 0  
fill ~17 ~69 ~32 ~18 ~69 ~32 iron_block 0  
fill ~17 ~69 ~34 ~18 ~69 ~34 iron_block 0  
fill ~19 ~69 ~15 ~21 ~69 ~15 iron_block 0  
fill ~19 ~69 ~17 ~21 ~69 ~17 iron_block 0  
fill ~19 ~69 ~33 ~21 ~69 ~33 iron_block 0  
fill ~19 ~69 ~35 ~21 ~69 ~35 iron_block 0 
setblock ~20 ~69 ~14 redstone_torch 4 
setblock ~20 ~69 ~36 redstone_torch 3  
fill ~22 ~69 ~14 ~24 ~69 ~14 iron_block 0 
setblock ~22 ~69 ~16 iron_block 0  
fill ~22 ~69 ~17 ~22 ~71 ~17 fence 0  
fill ~22 ~69 ~18 ~22 ~70 ~18 glass 0  
fill ~22 ~69 ~32 ~22 ~70 ~32 glass 0  
fill ~22 ~69 ~33 ~22 ~71 ~33 fence 0 
setblock ~22 ~69 ~34 iron_block 0  
fill ~22 ~69 ~36 ~24 ~69 ~36 iron_block 0  
fill ~23 ~69 ~15 ~23 ~70 ~15 iron_block 0 
setblock ~23 ~69 ~16 glowstone 0  
fill ~23 ~69 ~25 ~23 ~71 ~25 stained_hardened_clay 14 
setblock ~23 ~69 ~26 glowstone 0  
fill ~23 ~69 ~27 ~23 ~69 ~30 stone_slab 8 
setblock ~23 ~69 ~34 glowstone 0  
fill ~23 ~69 ~35 ~23 ~70 ~35 iron_block 0 
setblock ~24 ~69 ~16 iron_block 0  
fill ~24 ~69 ~17 ~24 ~71 ~17 fence 0  
fill ~24 ~69 ~18 ~24 ~70 ~18 glass 0  
fill ~24 ~69 ~25 ~24 ~71 ~25 glass 0  
fill ~24 ~69 ~32 ~24 ~70 ~32 glass 0  
fill ~24 ~69 ~33 ~24 ~71 ~33 fence 0 
setblock ~24 ~69 ~34 iron_block 0  
fill ~25 ~69 ~15 ~27 ~69 ~15 iron_block 0  
fill ~25 ~69 ~17 ~27 ~69 ~17 iron_block 0  
fill ~25 ~69 ~33 ~27 ~69 ~33 iron_block 0  
fill ~25 ~69 ~35 ~27 ~69 ~35 iron_block 0 
setblock ~26 ~69 ~14 redstone_torch 4 
setblock ~26 ~69 ~36 redstone_torch 3  
fill ~28 ~69 ~16 ~29 ~69 ~16 iron_block 0  
fill ~28 ~69 ~18 ~29 ~69 ~18 iron_block 0  
fill ~28 ~69 ~32 ~29 ~69 ~32 iron_block 0  
fill ~28 ~69 ~34 ~29 ~69 ~34 iron_block 0  
fill ~30 ~69 ~17 ~30 ~72 ~17 iron_block 0  
fill ~30 ~69 ~19 ~30 ~68 ~19 iron_block 0  
fill ~30 ~69 ~20 ~30 ~68 ~20 iron_block 0  
fill ~30 ~69 ~30 ~30 ~68 ~30 iron_block 0  
fill ~30 ~69 ~31 ~30 ~68 ~31 iron_block 0  
fill ~30 ~69 ~33 ~30 ~72 ~33 iron_block 0 
setblock ~31 ~69 ~17 glowstone 0  
fill ~31 ~69 ~18 ~31 ~72 ~18 iron_block 0  
fill ~31 ~69 ~21 ~31 ~68 ~21 iron_block 0  
fill ~31 ~69 ~22 ~31 ~68 ~22 iron_block 0  
fill ~31 ~69 ~23 ~31 ~68 ~23 iron_block 0  
fill ~31 ~69 ~27 ~31 ~68 ~27 iron_block 0  
fill ~31 ~69 ~28 ~31 ~68 ~28 iron_block 0  
fill ~31 ~69 ~29 ~31 ~68 ~29 iron_block 0  
fill ~31 ~69 ~32 ~31 ~72 ~32 iron_block 0 
setblock ~31 ~69 ~33 glowstone 0  
fill ~32 ~69 ~19 ~32 ~72 ~19 iron_block 0  
fill ~32 ~69 ~20 ~32 ~72 ~20 iron_block 0  
fill ~32 ~69 ~24 ~32 ~68 ~24 iron_block 0 
setblock ~32 ~69 ~25 glowstone 0  
fill ~32 ~69 ~26 ~32 ~68 ~26 iron_block 0  
fill ~32 ~69 ~30 ~32 ~72 ~30 iron_block 0  
fill ~32 ~69 ~31 ~32 ~72 ~31 iron_block 0  
fill ~33 ~69 ~21 ~33 ~72 ~21 iron_block 0  
fill ~33 ~69 ~22 ~33 ~72 ~22 iron_block 0  
fill ~33 ~69 ~23 ~33 ~72 ~23 iron_block 0  
fill ~33 ~69 ~25 ~34 ~69 ~25 iron_block 0  
fill ~33 ~69 ~27 ~33 ~72 ~27 iron_block 0  
fill ~33 ~69 ~28 ~33 ~72 ~28 iron_block 0  
fill ~33 ~69 ~29 ~33 ~72 ~29 iron_block 0 
setblock ~34 ~69 ~22 redstone_torch 1  
fill ~34 ~69 ~24 ~34 ~72 ~24 iron_block 0  
fill ~34 ~69 ~26 ~34 ~72 ~26 iron_block 0 
setblock ~34 ~69 ~28 redstone_torch 1  
fill ~11 ~70 ~24 ~11 ~70 ~26 iron_block 0  
fill ~12 ~70 ~21 ~12 ~70 ~29 iron_block 0  
fill ~13 ~70 ~19 ~13 ~70 ~31 iron_block 0  
fill ~14 ~70 ~17 ~18 ~70 ~17 iron_block 0  
fill ~14 ~70 ~18 ~14 ~70 ~17 iron_block 0  
fill ~14 ~70 ~21 ~14 ~70 ~23 iron_block 0  
fill ~14 ~70 ~25 ~21 ~70 ~25 stone_slab 8  
fill ~14 ~70 ~27 ~14 ~70 ~33 iron_block 0  
fill ~15 ~70 ~16 ~21 ~70 ~16 iron_block 0  
fill ~15 ~70 ~19 ~15 ~70 ~20 iron_block 0  
fill ~15 ~70 ~30 ~15 ~70 ~34 iron_block 0 
setblock ~16 ~70 ~18 iron_block 0 
setblock ~16 ~70 ~32 iron_block 0  
fill ~16 ~70 ~34 ~21 ~70 ~34 iron_block 0  
fill ~17 ~70 ~15 ~29 ~70 ~15 iron_block 0  
fill ~17 ~70 ~33 ~18 ~70 ~33 iron_block 0  
fill ~17 ~70 ~35 ~29 ~70 ~35 iron_block 0  
fill ~19 ~70 ~14 ~27 ~70 ~14 iron_block 0  
fill ~19 ~70 ~36 ~27 ~70 ~36 iron_block 0  
fill ~22 ~70 ~13 ~24 ~70 ~13 iron_block 0 
setblock ~22 ~70 ~25 glowstone 0  
fill ~22 ~70 ~37 ~24 ~70 ~37 iron_block 0  
fill ~23 ~70 ~26 ~23 ~71 ~26 glass 0  
fill ~25 ~70 ~16 ~31 ~70 ~16 iron_block 0  
fill ~25 ~70 ~34 ~31 ~70 ~34 iron_block 0  
fill ~28 ~70 ~17 ~32 ~70 ~17 iron_block 0   
fill ~28 ~70 ~33 ~32 ~70 ~33 iron_block 0 
setblock ~30 ~70 ~18 iron_block 0 
setblock ~30 ~70 ~32 iron_block 0  
fill ~31 ~70 ~19 ~31 ~70 ~20 iron_block 0  
fill ~31 ~70 ~30 ~31 ~70 ~34 iron_block 0 
setblock ~32 ~70 ~18 iron_block 0  
fill ~32 ~70 ~21 ~32 ~70 ~23 iron_block 0  
fill ~32 ~70 ~27 ~32 ~70 ~33 iron_block 0  
fill ~33 ~70 ~19 ~33 ~70 ~31 iron_block 0  
fill ~34 ~70 ~21 ~34 ~70 ~29 iron_block 0  
fill ~35 ~70 ~24 ~35 ~70 ~26 iron_block 0  
fill ~10 ~71 ~24 ~10 ~72 ~24 iron_block 0 
setblock ~10 ~71 ~25 glowstone 0  
fill ~10 ~71 ~26 ~10 ~72 ~26 iron_block 0  
fill ~11 ~71 ~21 ~11 ~72 ~21 iron_block 0  
fill ~11 ~71 ~22 ~11 ~72 ~22 iron_block 0  
fill ~11 ~71 ~23 ~11 ~72 ~23 iron_block 0  
fill ~11 ~71 ~27 ~11 ~72 ~27 iron_block 0  
fill ~11 ~71 ~28 ~11 ~72 ~28 iron_block 0  
fill ~11 ~71 ~29 ~11 ~72 ~29 iron_block 0  
fill ~12 ~71 ~19 ~12 ~72 ~19 iron_block 0  
fill ~12 ~71 ~20 ~12 ~71 ~19 iron_block 0  
fill ~12 ~71 ~25 ~12 ~72 ~25 iron_block 0  
fill ~12 ~71 ~30 ~12 ~71 ~31 iron_block 0  
fill ~13 ~71 ~17 ~13 ~72 ~17 iron_block 0  
fill ~13 ~71 ~18 ~13 ~72 ~18 iron_block 0  
fill ~13 ~71 ~32 ~13 ~72 ~32 iron_block 0  
fill ~13 ~71 ~33 ~13 ~72 ~33 iron_block 0  
fill ~14 ~71 ~16 ~14 ~72 ~16 iron_block 0  
fill ~14 ~71 ~34 ~14 ~72 ~34 iron_block 0  
fill ~15 ~71 ~15 ~16 ~71 ~15 iron_block 0  
fill ~15 ~71 ~35 ~16 ~71 ~35 iron_block 0  
fill ~17 ~71 ~14 ~18 ~71 ~14 iron_block 0  
fill ~17 ~71 ~16 ~18 ~71 ~16 iron_block 0  
fill ~17 ~71 ~34 ~18 ~71 ~34 iron_block 0  
fill ~17 ~71 ~36 ~18 ~71 ~36 iron_block 0  
fill ~19 ~71 ~13 ~21 ~71 ~13 iron_block 0  
fill ~19 ~71 ~15 ~21 ~71 ~15 iron_block 0  
fill ~19 ~71 ~35 ~21 ~71 ~35 iron_block 0  
fill ~19 ~71 ~37 ~21 ~71 ~37 iron_block 0  
fill ~22 ~71 ~12 ~22 ~72 ~12 iron_block 0  
fill ~22 ~71 ~14 ~24 ~71 ~14 iron_block 0  
fill ~22 ~71 ~18 ~22 ~72 ~18 iron_block 0 
setblock ~22 ~71 ~25 glass 0  
fill ~22 ~71 ~32 ~22 ~72 ~32 iron_block 0  
fill ~22 ~71 ~36 ~24 ~71 ~36 iron_block 0  
fill ~22 ~71 ~38 ~22 ~72 ~38 iron_block 0 
setblock ~23 ~71 ~12 glowstone 0  
fill ~23 ~71 ~20 ~23 ~71 ~23 stone_slab 8 
setblock ~23 ~71 ~24 glowstone 0 
setblock ~23 ~71 ~38 glowstone 0  
fill ~24 ~71 ~12 ~24 ~72 ~12 iron_block 0  
fill ~24 ~71 ~18 ~24 ~72 ~18 iron_block 0  
fill ~24 ~71 ~32 ~24 ~72 ~32 iron_block 0  
fill ~24 ~71 ~38 ~24 ~72 ~38 iron_block 0  
fill ~25 ~71 ~13 ~27 ~71 ~13 iron_block 0  
fill ~25 ~71 ~15 ~27 ~71 ~15 iron_block 0  
fill ~25 ~71 ~35 ~27 ~71 ~35 iron_block 0  
fill ~25 ~71 ~37 ~27 ~71 ~37 iron_block 0  
fill ~28 ~71 ~14 ~29 ~71 ~14 iron_block 0  
fill ~28 ~71 ~16 ~29 ~71 ~16 iron_block 0  
fill ~28 ~71 ~34 ~29 ~71 ~34 iron_block 0  
fill ~28 ~71 ~36 ~29 ~71 ~36 iron_block 0  
fill ~30 ~71 ~15 ~31 ~71 ~15 iron_block 0  
fill ~30 ~71 ~35 ~31 ~71 ~35 iron_block 0  
fill ~32 ~71 ~16 ~32 ~72 ~16 iron_block 0  
fill ~32 ~71 ~34 ~32 ~72 ~34 iron_block 0  
fill ~33 ~71 ~17 ~33 ~72 ~17 iron_block 0  
fill ~33 ~71 ~18 ~33 ~72 ~18 iron_block 0  
fill ~33 ~71 ~32 ~33 ~72 ~32 iron_block 0  
fill ~33 ~71 ~33 ~33 ~72 ~33 iron_block 0  
fill ~34 ~71 ~19 ~34 ~72 ~19 iron_block 0  
fill ~34 ~71 ~20 ~34 ~71 ~19 iron_block 0  
fill ~34 ~71 ~25 ~34 ~72 ~25 iron_block 0  
fill ~34 ~71 ~30 ~34 ~71 ~31 iron_block 0  
fill ~35 ~71 ~21 ~35 ~72 ~21 iron_block 0  
fill ~35 ~71 ~22 ~35 ~72 ~22 iron_block 0  
fill ~35 ~71 ~23 ~35 ~72 ~23 iron_block 0  
fill ~35 ~71 ~27 ~35 ~72 ~27 iron_block 0  
fill ~35 ~71 ~28 ~35 ~72 ~28 iron_block 0  
fill ~35 ~71 ~29 ~35 ~72 ~29 iron_block 0  
fill ~36 ~71 ~24 ~36 ~72 ~24 iron_block 0 
setblock ~36 ~71 ~25 glowstone 0  
fill ~36 ~71 ~26 ~36 ~72 ~26 iron_block 0 
setblock ~10 ~72 ~25 iron_block 0 
setblock ~11 ~72 ~24 iron_block 0 
setblock ~11 ~72 ~25 glowstone 0 
setblock ~11 ~72 ~26 iron_block 0 
setblock ~12 ~72 ~17 redstone_torch 2 
setblock ~12 ~72 ~20 glowstone 0  
fill ~12 ~72 ~21 ~12 ~72 ~29 iron_block 0 
setblock ~12 ~72 ~30 glowstone 0 
setblock ~12 ~72 ~31 iron_block 0 
