setblock ~8~15~2 minecraft:wall_banner 2
fill ~10~7~2 ~10~7~10 minecraft:stained_hardened_clay 14
fill ~10~8~2 ~10~12~2 minecraft:stained_hardened_clay 14
fill ~11~7~2 ~12~9~2 minecraft:stone 0
fill ~11~10~2 ~11~11~2 minecraft:stone 0
setblock ~12~10~2 minecraft:wool 8
fill ~12~11~2 ~13~11~2 minecraft:stone 0
fill ~13~7~2 ~13~7~10 minecraft:wool 8
fill ~13~8~2 ~14~8~2 minecraft:stone 0
fill ~13~9~2 ~16~9~2 minecraft:wool 8
fill ~13~10~2 ~15~10~2 minecraft:stone 0
fill ~14~7~2 ~15~7~2 minecraft:stone 0
fill ~14~11~2 ~16~11~2 minecraft:wool 8
fill ~15~8~2 ~16~8~2 minecraft:wool 8
setblock ~16~7~2 minecraft:wool 8
setblock ~16~10~2 minecraft:wool 8
fill ~6~8~3 ~7~8~3 minecraft:stained_hardened_clay 8
fill ~6~9~3 ~6~9~4 minecraft:stained_hardened_clay 12
fill ~6~10~3 ~6~10~4 minecraft:stained_hardened_clay 8
setblock ~6~11~3 minecraft:wool 0
fill ~6~12~3 ~7~13~3 minecraft:wool 8
setblock ~7~9~3 minecraft:stained_hardened_clay 0
fill ~7~10~3 ~9~10~3 minecraft:wool 8
fill ~7~11~3 ~8~11~3 minecraft:wool 8
fill ~8~0~3 ~8~0~4 minecraft:stone 0
fill ~8~1~3 ~9~1~3 minecraft:wool 8
fill ~8~2~3 ~8~2~4 minecraft:wool 8
setblock ~8~8~3 minecraft:stained_hardened_clay 0
fill ~8~9~3 ~9~9~3 minecraft:wool 8
fill ~8~12~3 ~9~12~3 minecraft:stone 0
fill ~8~13~3 ~9~13~4 minecraft:wool 8
fill ~8~14~3 ~8~15~4 minecraft:wool 8
fill ~8~16~3 ~8~16~4 minecraft:carpet 7
fill ~9~0~3 ~9~0~4 minecraft:wool 8
setblock ~9~2~3 minecraft:stone 0
fill ~9~3~3 ~10~3~3 minecraft:wool 8
fill ~9~4~3 ~10~4~3 minecraft:stone 0
fill ~9~8~3 ~9~8~9 minecraft:wool 8
setblock ~9~11~3 minecraft:stone 0
fill ~9~15~3 ~9~15~4 minecraft:wall_banner 5
fill ~10~2~3 ~10~2~4 minecraft:wool 8
fill ~10~5~3 ~11~5~3 minecraft:wool 8
setblock ~10~6~3 minecraft:wool 8
fill ~10~12~3 ~10~12~10 minecraft:stained_hardened_clay 14
fill ~11~4~3 ~11~4~4 minecraft:wool 8
setblock ~11~6~3 minecraft:stone 0
fill ~11~7~3 ~12~7~9 minecraft:wool 8
setblock ~11~12~3 minecraft:wool 8
fill ~12~6~3 ~12~6~4 minecraft:wool 8
setblock ~12~9~3 minecraft:torch 3
fill ~12~12~3 ~13~12~3 minecraft:stone 0
fill ~14~6~3 ~22~6~3 minecraft:wool 8
fill ~14~12~3 ~14~12~4 minecraft:wool 8
fill ~15~11~3 ~15~11~4 minecraft:stone 0
setblock ~16~5~3 minecraft:stone 0
setblock ~16~11~3 minecraft:wool 8
fill ~17~4~3 ~17~5~3 minecraft:wool 8
fill ~17~7~3 ~17~8~3 minecraft:wool 8
setblock ~17~9~3 minecraft:stone 0
fill ~17~10~3 ~18~10~3 minecraft:wool 8
fill ~18~3~3 ~22~3~3 minecraft:wool 8
setblock ~18~4~3 minecraft:stone 0
fill ~18~5~3 ~19~5~3 minecraft:wool 8
setblock ~18~7~3 minecraft:stone 0
fill ~18~8~3 ~18~9~3 minecraft:wool 8
fill ~19~2~3 ~20~2~3 minecraft:wool 8
fill ~19~4~3 ~23~4~3 minecraft:wool 8
fill ~19~7~3 ~20~7~3 minecraft:wool 8
fill ~19~8~3 ~19~9~3 minecraft:stone 0
fill ~20~1~3 ~23~1~3 minecraft:wool 8
fill ~20~5~3 ~21~5~3 minecraft:stone 0
setblock ~20~8~3 minecraft:wool 8
fill ~21~0~3 ~22~0~9 minecraft:wool 8
setblock ~21~2~3 minecraft:stone 0
setblock ~21~7~3 minecraft:stone 0
fill ~22~2~3 ~24~2~3 minecraft:wool 8
fill ~22~5~3 ~23~5~3 minecraft:wool 8
setblock ~23~3~3 minecraft:stone 0
fill ~24~3~3 ~24~3~9 minecraft:wool 8
setblock ~24~4~3 minecraft:stone 0
setblock ~6~8~4 minecraft:stained_hardened_clay 12
setblock ~6~11~4 minecraft:wool 15
setblock ~6~12~4 minecraft:wool 0
setblock ~6~13~4 minecraft:stone 0
fill ~7~8~4 ~8~8~8 minecraft:wool 8
fill ~7~13~4 ~7~13~5 minecraft:wool 8
setblock ~8~1~4 minecraft:wool 8
setblock ~8~11~4 minecraft:torch 3
setblock ~9~1~4 minecraft:stone 0
setblock ~9~2~4 minecraft:wool 8
fill ~9~3~4 ~10~3~4 minecraft:stone 0
fill ~9~4~4 ~10~4~4 minecraft:wool 8
fill ~10~5~4 ~11~5~4 minecraft:stone 0
setblock ~10~6~4 minecraft:stone 0
setblock ~11~6~4 minecraft:wool 8
fill ~11~12~4 ~12~12~6 minecraft:stone 0
setblock ~13~12~4 minecraft:wool 8
fill ~14~6~4 ~15~6~4 minecraft:wool 8
fill ~15~0~4 ~17~0~5 minecraft:wool 8
setblock ~16~1~4 minecraft:stone 0
fill ~16~5~4 ~16~5~9 minecraft:wool 8
setblock ~16~11~4 minecraft:stone 0
fill ~17~1~4 ~17~1~5 minecraft:wool 8
fill ~17~4~4 ~17~4~5 minecraft:stone 0
setblock ~17~10~4 minecraft:wool 8
fill ~18~0~4 ~18~1~4 minecraft:stone 0
setblock ~18~3~4 minecraft:wool 8
setblock ~18~7~4 minecraft:torch 3
setblock ~18~10~4 minecraft:stone 0
fill ~19~0~4 ~20~0~5 minecraft:wool 8
setblock ~19~1~4 minecraft:stone 0
fill ~19~2~4 ~19~2~9 minecraft:wool 8
fill ~19~9~4 ~19~9~5 minecraft:wool 8
fill ~20~1~4 ~20~1~9 minecraft:wool 8
setblock ~20~8~4 minecraft:stone 0
setblock ~21~4~4 minecraft:torch 3
fill ~21~7~4 ~21~7~8 minecraft:wool 8
fill ~22~6~4 ~22~6~5 minecraft:stone 0
fill ~23~1~4 ~23~1~9 minecraft:wool 8
fill ~23~5~4 ~23~5~5 minecraft:wool 8
fill ~24~2~4 ~24~2~9 minecraft:wool 8
fill ~24~4~4 ~24~4~8 minecraft:wool 8
fill ~30~7~4 ~31~7~4 minecraft:wool 8
fill ~30~8~4 ~30~8~5 minecraft:wool 8
setblock ~31~8~4 minecraft:stone 0
fill ~3~8~5 ~4~8~7 minecraft:wool 7
fill ~3~9~5 ~3~9~7 minecraft:wool 0
setblock ~3~10~5 minecraft:stained_hardened_clay 0
setblock ~4~9~5 minecraft:stained_hardened_clay 0
fill ~4~10~5 ~5~10~7 minecraft:stained_hardened_clay 8
setblock ~5~8~5 minecraft:stained_hardened_clay 0
setblock ~5~9~5 minecraft:stained_hardened_clay 8
fill ~6~8~5 ~6~10~7 minecraft:wool 8
fill ~6~11~5 ~6~11~7 minecraft:stained_hardened_clay 8
fill ~6~12~5 ~6~13~6 minecraft:wool 8
fill ~8~13~5 ~8~13~9 minecraft:wool 8
setblock ~8~15~5 minecraft:wall_banner 3
setblock ~9~13~5 minecraft:stone 0
fill ~13~12~5 ~14~12~5 minecraft:stone 0
fill ~14~6~5 ~14~7~7 minecraft:wool 8
fill ~15~6~5 ~15~6~6 minecraft:stone 0
fill ~15~11~5 ~16~11~5 minecraft:wool 8
setblock ~16~1~5 minecraft:wool 8
fill ~17~10~5 ~17~10~6 minecraft:stone 0
setblock ~18~0~5 minecraft:wool 8
setblock ~18~1~5 minecraft:stone 0
setblock ~18~3~5 minecraft:stone 0
fill ~18~10~5 ~18~10~7 minecraft:wool 8
setblock ~19~1~5 minecraft:wool 8
fill ~20~8~5 ~20~8~6 minecraft:wool 8
setblock ~24~5~5 minecraft:wool 8
fill ~25~4~5 ~25~4~7 minecraft:wool 8
setblock ~25~5~5 minecraft:stone 0
fill ~25~6~5 ~25~6~7 minecraft:wool 8
fill ~26~5~5 ~26~5~6 minecraft:wool 8
fill ~26~6~5 ~27~6~5 minecraft:stone 0
setblock ~27~5~5 minecraft:stone 0
setblock ~27~7~5 minecraft:wool 8
fill ~28~6~5 ~29~6~5 minecraft:wool 8
fill ~28~7~5 ~28~7~7 minecraft:stone 0
fill ~29~7~5 ~30~7~7 minecraft:wool 8
setblock ~29~8~5 minecraft:stone 0
setblock ~31~7~5 minecraft:stone 0
fill ~31~8~5 ~31~8~6 minecraft:wool 8
setblock ~3~10~6 minecraft:wool 7
setblock ~5~8~6 minecraft:wool 7
setblock ~7~11~6 minecraft:torch 1
fill ~7~13~6 ~7~13~7 minecraft:stone 0
fill ~9~13~6 ~9~13~8 minecraft:wool 8
setblock ~13~12~6 minecraft:stone 0
setblock ~14~8~6 minecraft:torch 5
setblock ~14~12~6 minecraft:wool 8
fill ~15~11~6 ~16~11~6 minecraft:stone 0
fill ~17~4~6 ~17~4~7 minecraft:wool 8
fill ~18~3~6 ~18~3~9 minecraft:wool 8
setblock ~18~4~6 minecraft:torch 5
setblock ~19~9~6 minecraft:stone 0
fill ~22~6~6 ~22~6~9 minecraft:wool 8
setblock ~23~3~6 minecraft:torch 2
fill ~23~5~6 ~24~5~6 minecraft:stone 0
fill ~25~5~6 ~25~5~7 minecraft:wool 8
fill ~26~6~6 ~27~6~6 minecraft:wool 8
setblock ~27~5~6 minecraft:wool 8
setblock ~27~7~6 minecraft:stone 0
fill ~28~6~6 ~29~6~6 minecraft:stone 0
fill ~29~8~6 ~29~8~7 minecraft:wool 8
fill ~30~8~6 ~30~8~7 minecraft:stone 0
setblock ~3~10~7 minecraft:stained_hardened_clay 0
setblock ~4~9~7 minecraft:stained_hardened_clay 0
setblock ~5~8~7 minecraft:stained_hardened_clay 0
setblock ~5~9~7 minecraft:stained_hardened_clay 8
fill ~6~12~7 ~6~13~7 minecraft:stone 0
setblock ~8~15~7 minecraft:wall_banner 2
fill ~11~12~7 ~11~12~10 minecraft:stone 0
fill ~12~12~7 ~13~12~7 minecraft:wool 8
setblock ~14~12~7 minecraft:stone 0
fill ~15~0~7 ~20~0~7 minecraft:wool 8
fill ~15~6~7 ~15~6~9 minecraft:wool 8
setblock ~15~11~7 minecraft:stone 0
fill ~16~1~7 ~17~1~7 minecraft:wool 8
setblock ~16~11~7 minecraft:wool 8
fill ~17~10~7 ~17~10~9 minecraft:wool 8
setblock ~18~1~7 minecraft:stone 0
fill ~19~1~7 ~19~1~8 minecraft:wool 8
fill ~19~9~7 ~19~9~9 minecraft:wool 8
setblock ~20~8~7 minecraft:stone 0
fill ~23~5~7 ~24~5~7 minecraft:wool 8
fill ~26~5~7 ~27~5~7 minecraft:stone 0
setblock ~26~6~7 minecraft:stone 0
fill ~27~6~7 ~29~6~7 minecraft:wool 8
setblock ~27~7~7 minecraft:wool 8
fill ~6~8~8 ~6~9~8 minecraft:stained_hardened_clay 12
fill ~6~10~8 ~6~10~9 minecraft:stained_hardened_clay 8
setblock ~6~11~8 minecraft:wool 15
setblock ~6~12~8 minecraft:wool 0
fill ~6~13~8 ~7~13~8 minecraft:wool 8
fill ~8~0~8 ~8~0~9 minecraft:stone 0
fill ~8~1~8 ~9~2~9 minecraft:wool 8
setblock ~8~11~8 minecraft:torch 4
fill ~8~14~8 ~8~15~9 minecraft:wool 8
fill ~8~16~8 ~8~16~9 minecraft:carpet 7
fill ~9~0~8 ~9~0~9 minecraft:wool 8
fill ~9~3~8 ~10~3~8 minecraft:wool 8
setblock ~9~4~8 minecraft:stone 0
fill ~9~15~8 ~9~15~9 minecraft:wall_banner 5
setblock ~10~2~8 minecraft:stone 0
fill ~10~4~8 ~10~6~8 minecraft:wool 8
fill ~11~4~8 ~11~5~8 minecraft:stone 0
fill ~11~6~8 ~12~6~8 minecraft:wool 8
fill ~12~12~8 ~13~12~8 minecraft:stone 0
setblock ~14~6~8 minecraft:stone 0
fill ~14~7~8 ~14~7~10 minecraft:wool 8
setblock ~14~12~8 minecraft:wool 8
fill ~15~0~8 ~17~0~8 minecraft:wool 8
setblock ~15~11~8 minecraft:wool 8
setblock ~16~1~8 minecraft:stone 0
fill ~16~11~8 ~16~11~9 minecraft:stone 0
fill ~17~1~8 ~18~1~8 minecraft:wool 8
setblock ~17~4~8 minecraft:stone 0
setblock ~18~0~8 minecraft:stone 0
setblock ~18~7~8 minecraft:torch 4
setblock ~18~10~8 minecraft:stone 0
fill ~19~0~8 ~20~0~8 minecraft:wool 8
fill ~20~8~8 ~20~8~9 minecraft:wool 8
setblock ~21~4~8 minecraft:torch 4
setblock ~23~5~8 minecraft:stone 0
fill ~6~8~9 ~7~8~9 minecraft:stained_hardened_clay 8
setblock ~6~9~9 minecraft:stained_hardened_clay 12
setblock ~6~11~9 minecraft:wool 0
fill ~6~12~9 ~9~12~9 minecraft:wool 8
setblock ~6~13~9 minecraft:stone 0
setblock ~7~9~9 minecraft:stained_hardened_clay 0
fill ~7~10~9 ~8~10~9 minecraft:wool 8
setblock ~7~11~9 minecraft:wool 8
setblock ~7~13~9 minecraft:wool 8
setblock ~8~8~9 minecraft:stained_hardened_clay 0
fill ~8~9~9 ~9~9~9 minecraft:wool 8
setblock ~8~11~9 minecraft:stone 0
setblock ~9~3~9 minecraft:stone 0
setblock ~9~4~9 minecraft:wool 8
setblock ~9~10~9 minecraft:stone 0
setblock ~9~11~9 minecraft:wool 8
setblock ~9~13~9 minecraft:stone 0
fill ~10~2~9 ~10~3~9 minecraft:wool 8
setblock ~10~4~9 minecraft:stone 0
fill ~10~5~9 ~10~6~9 minecraft:wool 8
setblock ~11~4~9 minecraft:wool 8
fill ~11~5~9 ~11~6~9 minecraft:stone 0
setblock ~12~6~9 minecraft:wool 8
setblock ~12~9~9 minecraft:torch 4
setblock ~12~12~9 minecraft:wool 8
fill ~13~12~9 ~14~12~9 minecraft:stone 0
setblock ~14~6~9 minecraft:wool 8
setblock ~15~11~9 minecraft:stone 0
fill ~16~6~9 ~17~6~9 minecraft:wool 8
fill ~17~4~9 ~21~4~9 minecraft:wool 8
fill ~17~5~9 ~19~5~9 minecraft:wool 8
fill ~17~7~9 ~18~7~9 minecraft:stone 0
fill ~17~8~9 ~19~8~9 minecraft:wool 8
setblock ~17~9~9 minecraft:wool 8
setblock ~18~6~9 minecraft:stone 0
setblock ~18~9~9 minecraft:stone 0
setblock ~18~10~9 minecraft:wool 8
setblock ~19~3~9 minecraft:stone 0
fill ~19~6~9 ~21~6~9 minecraft:wool 8
fill ~19~7~9 ~20~7~9 minecraft:wool 8
fill ~20~2~9 ~20~3~9 minecraft:wool 8
setblock ~20~5~9 minecraft:stone 0
fill ~21~1~9 ~22~1~9 minecraft:wool 8
setblock ~21~2~9 minecraft:stone 0
fill ~21~3~9 ~23~3~9 minecraft:wool 8
setblock ~21~5~9 minecraft:wool 8
setblock ~21~7~9 minecraft:stone 0
fill ~22~2~9 ~23~2~9 minecraft:wool 8
fill ~22~4~9 ~22~5~9 minecraft:stone 0
fill ~23~4~9 ~23~5~9 minecraft:wool 8
setblock ~24~4~9 minecraft:stone 0
setblock ~8~15~10 minecraft:wall_banner 3
fill ~10~8~10 ~10~11~10 minecraft:stained_hardened_clay 14
fill ~11~7~10 ~12~8~10 minecraft:stone 0
fill ~11~9~10 ~11~11~10 minecraft:stone 0
fill ~12~9~10 ~12~10~10 minecraft:wool 8
fill ~12~11~10 ~14~11~10 minecraft:stone 0
fill ~12~12~10 ~13~12~10 minecraft:stone 0
fill ~13~8~10 ~14~8~10 minecraft:stone 0
fill ~13~9~10 ~13~10~10 minecraft:stone 0
setblock ~14~9~10 minecraft:wool 8
setblock ~14~10~10 minecraft:stone 0
setblock ~14~12~10 minecraft:wool 8
fill ~15~7~10 ~15~8~10 minecraft:wool 8
fill ~15~9~10 ~16~9~10 minecraft:stone 0
fill ~15~10~10 ~15~11~10 minecraft:wool 8
setblock ~16~7~10 minecraft:stone 0
setblock ~16~8~10 minecraft:wool 8
setblock ~16~10~10 minecraft:stone 0
setblock ~16~11~10 minecraft:wool 8