fill ~65~21~0 ~73~21~0 minecraft:stone_block_slab 13
fill ~65~22~0 ~73~22~0 minecraft:stained_hardened_clay 14
fill ~65~23~0 ~73~23~0 minecraft:stone_block_slab 5
fill ~62~21~1 ~64~21~1 minecraft:stone_block_slab 13
fill ~62~22~1 ~64~22~1 minecraft:stained_hardened_clay 14
fill ~62~23~1 ~64~23~1 minecraft:stone_block_slab 5
fill ~65~1~1 ~73~1~1 minecraft:stone_block_slab 13
fill ~65~2~1 ~73~2~1 minecraft:stained_hardened_clay 14
fill ~65~3~1 ~73~3~1 minecraft:stone_block_slab 5
fill ~69~23~1 ~69~23~15 minecraft:stone_block_slab 5
fill ~74~21~1 ~76~21~1 minecraft:stone_block_slab 13
fill ~74~22~1 ~76~22~1 minecraft:stained_hardened_clay 14
fill ~74~23~1 ~76~23~1 minecraft:stone_block_slab 5
fill ~60~21~2 ~61~21~2 minecraft:stone_block_slab 13
fill ~60~22~2 ~61~22~2 minecraft:stained_hardened_clay 14
fill ~60~23~2 ~61~23~2 minecraft:stone_block_slab 5
fill ~62~1~2 ~64~1~2 minecraft:stone_block_slab 13
fill ~62~2~2 ~64~2~2 minecraft:stained_hardened_clay 14
fill ~62~3~2 ~64~3~2 minecraft:stone_block_slab 5
fill ~69~3~2 ~69~3~16 minecraft:stone_block_slab 5
fill ~74~1~2 ~76~1~2 minecraft:stone_block_slab 13
fill ~74~2~2 ~76~2~2 minecraft:stained_hardened_clay 14
fill ~74~3~2 ~76~3~2 minecraft:stone_block_slab 5
fill ~77~21~2 ~78~21~2 minecraft:stone_block_slab 13
fill ~77~22~2 ~78~22~2 minecraft:stained_hardened_clay 14
fill ~77~23~2 ~78~23~2 minecraft:stone_block_slab 5
setblock ~59~21~3 minecraft:stone_block_slab 13
setblock ~59~22~3 minecraft:stained_hardened_clay 14
setblock ~59~23~3 minecraft:stone_block_slab 5
fill ~60~1~3 ~61~1~3 minecraft:stone_block_slab 13
fill ~60~2~3 ~61~2~3 minecraft:stained_hardened_clay 14
fill ~60~3~3 ~61~3~3 minecraft:stone_block_slab 5
fill ~77~1~3 ~78~1~3 minecraft:stone_block_slab 13
fill ~77~2~3 ~78~2~3 minecraft:stained_hardened_clay 14
fill ~77~3~3 ~78~3~3 minecraft:stone_block_slab 5
setblock ~79~21~3 minecraft:stone_block_slab 13
setblock ~79~22~3 minecraft:stained_hardened_clay 14
setblock ~79~23~3 minecraft:stone_block_slab 5
setblock ~58~21~4 minecraft:stone_block_slab 13
setblock ~58~22~4 minecraft:stained_hardened_clay 14
setblock ~58~23~4 minecraft:stone_block_slab 5
setblock ~59~1~4 minecraft:stone_block_slab 13
setblock ~59~2~4 minecraft:stained_hardened_clay 14
setblock ~59~3~4 minecraft:stone_block_slab 5
setblock ~79~1~4 minecraft:stone_block_slab 13
setblock ~79~2~4 minecraft:stained_hardened_clay 14
setblock ~79~3~4 minecraft:stone_block_slab 5
setblock ~80~21~4 minecraft:stone_block_slab 13
setblock ~80~22~4 minecraft:stained_hardened_clay 14
setblock ~80~23~4 minecraft:stone_block_slab 5
setblock ~57~21~5 minecraft:stone_block_slab 13
setblock ~57~22~5 minecraft:stained_hardened_clay 14
setblock ~57~23~5 minecraft:stone_block_slab 5
setblock ~58~1~5 minecraft:stone_block_slab 13
setblock ~58~2~5 minecraft:stained_hardened_clay 14
setblock ~58~3~5 minecraft:stone_block_slab 5
setblock ~80~1~5 minecraft:stone_block_slab 13
setblock ~80~2~5 minecraft:stained_hardened_clay 14
setblock ~80~3~5 minecraft:stone_block_slab 5
setblock ~81~21~5 minecraft:stone_block_slab 13
setblock ~81~22~5 minecraft:stained_hardened_clay 14
setblock ~81~23~5 minecraft:stone_block_slab 5
setblock ~56~21~6 minecraft:stone_block_slab 13
setblock ~56~22~6 minecraft:stained_hardened_clay 14
setblock ~56~23~6 minecraft:stone_block_slab 5
setblock ~57~1~6 minecraft:stone_block_slab 13
setblock ~57~2~6 minecraft:stained_hardened_clay 14
setblock ~57~3~6 minecraft:stone_block_slab 5
fill ~59~21~6 ~59~21~8 minecraft:stone_block_slab 8
fill ~59~22~6 ~59~22~8 minecraft:stone_block_slab 0
fill ~65~9~6 ~73~9~6 minecraft:wooden_slab 10
fill ~65~10~6 ~73~10~6 minecraft:sandstone 2
fill ~65~11~6 ~67~12~6 minecraft:glass
setblock ~65~13~6 minecraft:glass
fill ~65~14~6 ~73~14~6 minecraft:sandstone 2
fill ~65~15~6 ~73~15~6 minecraft:wooden_slab 2
fill ~65~29~6 ~73~29~6 minecraft:wooden_slab 10
fill ~65~30~6 ~73~30~6 minecraft:sandstone 2
fill ~65~31~6 ~73~33~6 minecraft:glass
fill ~65~34~6 ~73~34~6 minecraft:sandstone 2
fill ~65~35~6 ~73~35~6 minecraft:wooden_slab 2
fill ~67~13~6 ~73~13~6 minecraft:glass
fill ~68~12~6 ~73~12~6 minecraft:glass
fill ~69~11~6 ~73~11~6 minecraft:glass
setblock ~81~1~6 minecraft:stone_block_slab 13
setblock ~81~2~6 minecraft:stained_hardened_clay 14
setblock ~81~3~6 minecraft:stone_block_slab 5
setblock ~82~21~6 minecraft:stone_block_slab 13
setblock ~82~22~6 minecraft:stained_hardened_clay 14
setblock ~82~23~6 minecraft:stone_block_slab 5
setblock ~55~21~7 minecraft:stone_block_slab 13
setblock ~55~22~7 minecraft:stained_hardened_clay 14
setblock ~55~23~7 minecraft:stone_block_slab 5
setblock ~56~1~7 minecraft:stone_block_slab 13
setblock ~56~2~7 minecraft:stained_hardened_clay 14
setblock ~56~3~7 minecraft:stone_block_slab 5
fill ~59~1~7 ~59~1~9 minecraft:stone_block_slab 8
fill ~59~2~7 ~59~2~9 minecraft:stone_block_slab 0
fill ~60~21~7 ~60~21~9 minecraft:stone_block_slab 8
fill ~60~22~7 ~60~22~9 minecraft:stone_block_slab 0
fill ~63~9~7 ~64~9~7 minecraft:wooden_slab 10
fill ~63~10~7 ~64~10~7 minecraft:sandstone 2
fill ~63~11~7 ~64~13~7 minecraft:glass
fill ~63~14~7 ~64~14~7 minecraft:sandstone 2
fill ~63~15~7 ~64~15~7 minecraft:wooden_slab 2
fill ~63~29~7 ~64~29~7 minecraft:wooden_slab 10
fill ~63~30~7 ~64~30~7 minecraft:sandstone 2
fill ~63~31~7 ~64~33~7 minecraft:glass
fill ~63~34~7 ~64~34~7 minecraft:sandstone 2
fill ~63~35~7 ~64~35~7 minecraft:wooden_slab 2
fill ~65~10~7 ~73~10~9 minecraft:stained_glass 14
fill ~65~15~7 ~73~15~7 minecraft:stained_hardened_clay 14
fill ~65~30~7 ~73~30~7 minecraft:stained_glass 14
fill ~65~35~7 ~73~35~7 minecraft:stained_hardened_clay 14
fill ~74~9~7 ~75~9~7 minecraft:wooden_slab 10
fill ~74~10~7 ~75~10~7 minecraft:sandstone 2
fill ~74~11~7 ~75~13~7 minecraft:glass
fill ~74~14~7 ~75~14~7 minecraft:sandstone 2
fill ~74~15~7 ~75~15~7 minecraft:wooden_slab 2
fill ~74~29~7 ~75~29~7 minecraft:wooden_slab 10
fill ~74~30~7 ~75~30~7 minecraft:sandstone 2
fill ~74~31~7 ~75~33~7 minecraft:glass
fill ~74~34~7 ~75~34~7 minecraft:sandstone 2
fill ~74~35~7 ~75~35~7 minecraft:wooden_slab 2
setblock ~82~1~7 minecraft:stone_block_slab 13
setblock ~82~2~7 minecraft:stained_hardened_clay 14
setblock ~82~3~7 minecraft:stone_block_slab 5
setblock ~83~21~7 minecraft:stone_block_slab 13
setblock ~83~22~7 minecraft:stained_hardened_clay 14
setblock ~83~23~7 minecraft:stone_block_slab 5
fill ~54~21~8 ~54~21~9 minecraft:stone_block_slab 13
fill ~54~22~8 ~54~22~9 minecraft:stained_hardened_clay 14
fill ~54~23~8 ~54~23~9 minecraft:stone_block_slab 5
setblock ~55~1~8 minecraft:stone_block_slab 13
setblock ~55~2~8 minecraft:stained_hardened_clay 14
setblock ~55~3~8 minecraft:stone_block_slab 5
fill ~60~1~8 ~60~1~10 minecraft:stone_block_slab 8
fill ~60~2~8 ~60~2~10 minecraft:stone_block_slab 0
fill ~61~9~8 ~62~9~8 minecraft:wooden_slab 10
fill ~61~10~8 ~62~10~8 minecraft:sandstone 2
fill ~61~11~8 ~62~13~8 minecraft:glass
fill ~61~14~8 ~62~14~8 minecraft:sandstone 2
fill ~61~15~8 ~62~15~8 minecraft:wooden_slab 2
fill ~61~21~8 ~61~21~10 minecraft:stone_block_slab 8
fill ~61~22~8 ~61~22~10 minecraft:stone_block_slab 0
fill ~61~29~8 ~62~29~8 minecraft:wooden_slab 10
fill ~61~30~8 ~62~30~8 minecraft:sandstone 2
fill ~61~31~8 ~62~33~8 minecraft:glass
fill ~61~34~8 ~62~34~8 minecraft:sandstone 2
fill ~61~35~8 ~62~35~8 minecraft:wooden_slab 2
fill ~63~10~8 ~64~10~10 minecraft:stained_glass 14
fill ~63~15~8 ~64~15~8 minecraft:stained_hardened_clay 14
fill ~63~30~8 ~64~30~10 minecraft:stained_glass 14
fill ~63~35~8 ~64~35~8 minecraft:stained_hardened_clay 14
fill ~65~16~8 ~73~16~8 minecraft:wooden_slab 1
fill ~65~36~8 ~73~36~8 minecraft:wooden_slab 1
fill ~66~30~8 ~75~30~9 minecraft:stained_glass 14
fill ~74~10~8 ~75~10~10 minecraft:stained_glass 14
fill ~74~15~8 ~75~15~8 minecraft:stained_hardened_clay 14
fill ~74~35~8 ~75~35~8 minecraft:stained_hardened_clay 14
fill ~76~9~8 ~77~9~8 minecraft:wooden_slab 10
fill ~76~10~8 ~77~10~8 minecraft:sandstone 2
fill ~76~11~8 ~77~13~8 minecraft:glass
fill ~76~14~8 ~77~14~8 minecraft:sandstone 2
fill ~76~15~8 ~77~15~8 minecraft:wooden_slab 2
fill ~76~29~8 ~77~29~8 minecraft:wooden_slab 10
fill ~76~30~8 ~77~30~8 minecraft:sandstone 2
fill ~76~31~8 ~77~33~8 minecraft:glass
fill ~76~34~8 ~77~34~8 minecraft:sandstone 2
fill ~76~35~8 ~77~35~8 minecraft:wooden_slab 2
setblock ~83~1~8 minecraft:stone_block_slab 13
setblock ~83~2~8 minecraft:stained_hardened_clay 14
setblock ~83~3~8 minecraft:stone_block_slab 5
fill ~84~21~8 ~84~21~9 minecraft:stone_block_slab 13
fill ~84~22~8 ~84~22~9 minecraft:stained_hardened_clay 14
fill ~84~23~8 ~84~23~9 minecraft:stone_block_slab 5
fill ~54~1~9 ~54~1~10 minecraft:stone_block_slab 13
fill ~54~2~9 ~54~2~10 minecraft:stained_hardened_clay 14
fill ~54~3~9 ~54~3~10 minecraft:stone_block_slab 5
fill ~59~9~9 ~60~9~9 minecraft:wooden_slab 10
fill ~59~10~9 ~60~10~9 minecraft:sandstone 2
fill ~59~11~9 ~60~13~9 minecraft:glass
fill ~59~14~9 ~60~14~9 minecraft:sandstone 2
fill ~59~15~9 ~60~15~9 minecraft:wooden_slab 2
fill ~59~29~9 ~60~29~9 minecraft:wooden_slab 10
fill ~59~30~9 ~60~30~9 minecraft:sandstone 2
fill ~59~31~9 ~60~33~9 minecraft:glass
fill ~59~34~9 ~60~34~9 minecraft:sandstone 2
fill ~59~35~9 ~60~35~9 minecraft:wooden_slab 2
fill ~61~1~9 ~61~1~11 minecraft:stone_block_slab 8
fill ~61~2~9 ~61~2~11 minecraft:stone_block_slab 0
fill ~61~10~9 ~62~10~11 minecraft:stained_glass 14
fill ~61~15~9 ~62~15~9 minecraft:stained_hardened_clay 14
fill ~61~30~9 ~62~30~11 minecraft:stained_glass 14
fill ~61~35~9 ~62~35~9 minecraft:stained_hardened_clay 14
fill ~62~21~9 ~62~21~11 minecraft:stone_block_slab 8
fill ~62~22~9 ~62~22~11 minecraft:stone_block_slab 0
fill ~63~16~9 ~64~16~9 minecraft:wooden_slab 1
fill ~63~36~9 ~64~36~9 minecraft:wooden_slab 1
fill ~65~16~9 ~73~16~9 minecraft:sea_lantern
setblock ~65~30~9 minecraft:stained_glass 14
fill ~65~36~9 ~73~36~9 minecraft:sea_lantern
fill ~74~16~9 ~75~16~9 minecraft:wooden_slab 1
fill ~74~36~9 ~75~36~9 minecraft:wooden_slab 1
fill ~76~10~9 ~77~10~11 minecraft:stained_glass 14
fill ~76~15~9 ~77~15~9 minecraft:stained_hardened_clay 14
fill ~76~30~9 ~77~30~11 minecraft:stained_glass 14
fill ~76~35~9 ~77~35~9 minecraft:stained_hardened_clay 14
fill ~78~9~9 ~79~9~9 minecraft:wooden_slab 10
fill ~78~10~9 ~79~10~9 minecraft:sandstone 2
fill ~78~11~9 ~79~13~9 minecraft:glass
fill ~78~14~9 ~79~14~9 minecraft:sandstone 2
fill ~78~15~9 ~79~15~9 minecraft:wooden_slab 2
fill ~78~29~9 ~79~29~9 minecraft:wooden_slab 10
fill ~78~30~9 ~79~30~9 minecraft:sandstone 2
fill ~78~31~9 ~79~33~9 minecraft:glass
fill ~78~34~9 ~79~34~9 minecraft:sandstone 2
fill ~78~35~9 ~79~35~9 minecraft:wooden_slab 2
fill ~84~1~9 ~84~1~10 minecraft:stone_block_slab 13
fill ~84~2~9 ~84~2~10 minecraft:stained_hardened_clay 14
fill ~84~3~9 ~84~3~10 minecraft:stone_block_slab 5
fill ~53~21~10 ~53~21~12 minecraft:stone_block_slab 13
fill ~53~22~10 ~53~22~12 minecraft:stained_hardened_clay 14
fill ~53~23~10 ~53~23~12 minecraft:stone_block_slab 5
setblock ~58~9~10 minecraft:wooden_slab 10
setblock ~58~10~10 minecraft:sandstone 2
fill ~58~11~10 ~58~13~10 minecraft:glass
setblock ~58~14~10 minecraft:sandstone 2
setblock ~58~15~10 minecraft:wooden_slab 2
setblock ~58~29~10 minecraft:wooden_slab 10
setblock ~58~30~10 minecraft:sandstone 2
fill ~58~31~10 ~58~33~10 minecraft:glass
setblock ~58~34~10 minecraft:sandstone 2
setblock ~58~35~10 minecraft:wooden_slab 2
fill ~59~10~10 ~60~10~12 minecraft:stained_glass 14
fill ~59~15~10 ~60~15~10 minecraft:stained_hardened_clay 14
fill ~59~30~10 ~60~30~12 minecraft:stained_glass 14
fill ~59~35~10 ~60~35~10 minecraft:stained_hardened_clay 14
fill ~61~16~10 ~62~16~10 minecraft:wooden_slab 1
fill ~61~36~10 ~62~36~10 minecraft:wooden_slab 1
fill ~62~1~10 ~62~1~12 minecraft:stone_block_slab 8
fill ~62~2~10 ~62~2~12 minecraft:stone_block_slab 0
fill ~63~16~10 ~64~16~10 minecraft:sea_lantern
fill ~63~21~10 ~63~21~12 minecraft:stone_block_slab 8
fill ~63~22~10 ~63~22~12 minecraft:stone_block_slab 0
fill ~63~36~10 ~64~36~10 minecraft:sea_lantern
fill ~65~9~10 ~73~9~10 minecraft:wooden_slab 10
fill ~65~10~10 ~73~10~10 minecraft:sea_lantern
fill ~65~11~10 ~73~11~10 minecraft:wooden_slab 2
fill ~65~16~10 ~73~16~14 minecraft:wooden_slab 1
fill ~65~29~10 ~73~29~10 minecraft:wooden_slab 10
fill ~65~30~10 ~73~30~10 minecraft:sea_lantern
fill ~65~31~10 ~73~31~10 minecraft:wooden_slab 2
fill ~65~36~10 ~73~36~14 minecraft:wooden_slab 1
fill ~74~16~10 ~75~16~10 minecraft:sea_lantern
fill ~74~30~10 ~75~30~10 minecraft:stained_glass 14
fill ~74~36~10 ~75~36~10 minecraft:sea_lantern
fill ~76~16~10 ~77~16~10 minecraft:wooden_slab 1
fill ~76~36~10 ~77~36~10 minecraft:wooden_slab 1
fill ~78~10~10 ~79~10~12 minecraft:stained_glass 14
fill ~78~15~10 ~79~15~10 minecraft:stained_hardened_clay 14
fill ~78~30~10 ~79~30~12 minecraft:stained_glass 14
fill ~78~35~10 ~79~35~10 minecraft:stained_hardened_clay 14
setblock ~80~9~10 minecraft:wooden_slab 10
setblock ~80~10~10 minecraft:sandstone 2
fill ~80~11~10 ~80~13~10 minecraft:glass
setblock ~80~14~10 minecraft:sandstone 2
setblock ~80~15~10 minecraft:wooden_slab 2
setblock ~80~29~10 minecraft:wooden_slab 10
setblock ~80~30~10 minecraft:sandstone 2
fill ~80~31~10 ~80~33~10 minecraft:glass
setblock ~80~34~10 minecraft:sandstone 2
setblock ~80~35~10 minecraft:wooden_slab 2
fill ~85~21~10 ~85~21~12 minecraft:stone_block_slab 13
fill ~85~22~10 ~85~22~12 minecraft:stained_hardened_clay 14
fill ~85~23~10 ~85~23~12 minecraft:stone_block_slab 5
fill ~53~1~11 ~53~1~13 minecraft:stone_block_slab 13
fill ~53~2~11 ~53~2~13 minecraft:stained_hardened_clay 14
fill ~53~3~11 ~53~3~13 minecraft:stone_block_slab 5
setblock ~57~9~11 minecraft:wooden_slab 10
setblock ~57~10~11 minecraft:sandstone 2
fill ~57~11~11 ~57~13~11 minecraft:glass
setblock ~57~14~11 minecraft:sandstone 2
setblock ~57~15~11 minecraft:wooden_slab 2
setblock ~57~29~11 minecraft:wooden_slab 10
setblock ~57~30~11 minecraft:sandstone 2
fill ~57~31~11 ~57~33~11 minecraft:glass
setblock ~57~34~11 minecraft:sandstone 2
setblock ~57~35~11 minecraft:wooden_slab 2
fill ~58~10~11 ~58~10~15 minecraft:stained_glass 14
setblock ~58~15~11 minecraft:stained_hardened_clay 14
fill ~58~30~11 ~58~30~15 minecraft:stained_glass 14
setblock ~58~35~11 minecraft:stained_hardened_clay 14
fill ~59~16~11 ~60~16~11 minecraft:wooden_slab 1
fill ~59~36~11 ~60~36~11 minecraft:wooden_slab 1
fill ~61~16~11 ~62~16~11 minecraft:sea_lantern
fill ~61~36~11 ~62~36~11 minecraft:sea_lantern
fill ~63~1~11 ~63~1~13 minecraft:stone_block_slab 8
fill ~63~2~11 ~63~2~13 minecraft:stone_block_slab 0
fill ~63~9~11 ~64~9~11 minecraft:wooden_slab 10
fill ~63~10~11 ~64~10~11 minecraft:sea_lantern
fill ~63~11~11 ~64~11~11 minecraft:wooden_slab 2
fill ~63~16~11 ~64~16~16 minecraft:wooden_slab 1
fill ~63~29~11 ~64~29~11 minecraft:wooden_slab 10
fill ~63~30~11 ~64~30~11 minecraft:sea_lantern
fill ~63~31~11 ~64~31~11 minecraft:wooden_slab 2
fill ~63~36~11 ~64~36~16 minecraft:wooden_slab 1
fill ~64~21~11 ~64~21~13 minecraft:stone_block_slab 8
fill ~64~22~11 ~64~22~13 minecraft:stone_block_slab 0
fill ~65~9~11 ~73~9~13 minecraft:wooden_slab 9
setblock ~65~10~11 minecraft:farmland 5
fill ~65~11~11 ~68~11~14 minecraft:wheat 7
fill ~65~29~11 ~73~29~14 minecraft:wooden_slab 9
fill ~65~30~11 ~73~30~14 minecraft:stonebrick 0
setblock ~66~10~11 minecraft:farmland 6
fill ~67~10~11 ~68~10~11 minecraft:farmland 5
fill ~69~10~11 ~69~10~14 minecraft:planks 1
fill ~70~10~11 ~70~10~12 minecraft:farmland 5
fill ~70~11~11 ~73~11~12 minecraft:wheat 7
fill ~71~10~11 ~71~10~12 minecraft:farmland 6
setblock ~72~10~11 minecraft:farmland 5
fill ~73~10~11 ~73~10~12 minecraft:farmland 6
fill ~74~9~11 ~75~9~11 minecraft:wooden_slab 10
fill ~74~10~11 ~75~10~11 minecraft:sea_lantern
fill ~74~11~11 ~75~11~11 minecraft:wooden_slab 2
fill ~74~16~11 ~75~16~16 minecraft:wooden_slab 1
fill ~74~29~11 ~75~29~11 minecraft:wooden_slab 10
fill ~74~30~11 ~75~30~11 minecraft:sea_lantern
fill ~74~31~11 ~75~31~11 minecraft:wooden_slab 2
fill ~74~36~11 ~75~36~16 minecraft:wooden_slab 1
fill ~76~16~11 ~77~16~11 minecraft:sea_lantern
fill ~76~36~11 ~77~36~11 minecraft:sea_lantern
fill ~78~16~11 ~79~16~11 minecraft:wooden_slab 1
fill ~78~36~11 ~79~36~11 minecraft:wooden_slab 1
fill ~80~10~11 ~80~10~15 minecraft:stained_glass 14
setblock ~80~15~11 minecraft:stained_hardened_clay 14
fill ~80~30~11 ~80~30~15 minecraft:stained_glass 14
setblock ~80~35~11 minecraft:stained_hardened_clay 14
setblock ~81~9~11 minecraft:wooden_slab 10
setblock ~81~10~11 minecraft:sandstone 2
fill ~81~11~11 ~81~13~11 minecraft:glass
setblock ~81~14~11 minecraft:sandstone 2
setblock ~81~15~11 minecraft:wooden_slab 2
setblock ~81~29~11 minecraft:wooden_slab 10
setblock ~81~30~11 minecraft:sandstone 2
fill ~81~31~11 ~81~33~11 minecraft:glass
setblock ~81~34~11 minecraft:sandstone 2
setblock ~81~35~11 minecraft:wooden_slab 2
fill ~85~1~11 ~85~1~13 minecraft:stone_block_slab 13
fill ~85~2~11 ~85~2~13 minecraft:stained_hardened_clay 14
fill ~85~3~11 ~85~3~13 minecraft:stone_block_slab 5
fill ~56~9~12 ~56~9~13 minecraft:wooden_slab 10
fill ~56~10~12 ~56~10~13 minecraft:sandstone 2
fill ~56~11~12 ~56~13~13 minecraft:glass
fill ~56~14~12 ~56~14~13 minecraft:sandstone 2
fill ~56~15~12 ~56~15~13 minecraft:wooden_slab 2
fill ~56~29~12 ~56~29~13 minecraft:wooden_slab 10
fill ~56~30~12 ~56~30~13 minecraft:sandstone 2
fill ~56~31~12 ~56~33~13 minecraft:glass
fill ~56~34~12 ~56~34~13 minecraft:sandstone 2
fill ~56~35~12 ~56~35~13 minecraft:wooden_slab 2
fill ~57~10~12 ~57~10~17 minecraft:stained_glass 14
fill ~57~15~12 ~57~15~13 minecraft:stained_hardened_clay 14
fill ~57~30~12 ~57~30~17 minecraft:stained_glass 14
fill ~57~35~12 ~57~35~13 minecraft:stained_hardened_clay 14
fill ~58~16~12 ~58~16~13 minecraft:wooden_slab 1
fill ~58~36~12 ~58~36~13 minecraft:wooden_slab 1
fill ~59~16~12 ~60~16~12 minecraft:sea_lantern
fill ~59~36~12 ~60~36~12 minecraft:sea_lantern
fill ~61~9~12 ~62~9~12 minecraft:wooden_slab 10
fill ~61~10~12 ~62~10~12 minecraft:sea_lantern
fill ~61~11~12 ~62~11~12 minecraft:wooden_slab 2
fill ~61~16~12 ~62~16~18 minecraft:wooden_slab 1
fill ~61~29~12 ~62~29~12 minecraft:wooden_slab 10
fill ~61~30~12 ~62~30~12 minecraft:sea_lantern
fill ~61~31~12 ~62~31~12 minecraft:wooden_slab 2
fill ~61~36~12 ~62~36~18 minecraft:wooden_slab 1
fill ~63~9~12 ~64~9~15 minecraft:wooden_slab 9
setblock ~63~10~12 minecraft:farmland 5
fill ~63~11~12 ~64~11~16 minecraft:wheat 7
fill ~63~29~12 ~64~29~16 minecraft:wooden_slab 9
fill ~63~30~12 ~64~30~16 minecraft:stonebrick 0
fill ~64~1~12 ~64~1~14 minecraft:stone_block_slab 8
fill ~64~2~12 ~64~2~14 minecraft:stone_block_slab 0
fill ~64~10~12 ~65~10~12 minecraft:farmland 4
fill ~65~21~12 ~65~21~14 minecraft:stone_block_slab 8
fill ~65~22~12 ~65~22~14 minecraft:stone_block_slab 0
setblock ~66~10~12 minecraft:farmland 3
setblock ~67~10~12 minecraft:farmland 7
setblock ~68~10~12 minecraft:farmland 3
setblock ~72~10~12 minecraft:farmland 6
fill ~74~9~12 ~75~9~15 minecraft:wooden_slab 9
setblock ~74~10~12 minecraft:farmland 7
fill ~74~11~12 ~75~11~16 minecraft:wheat 7
fill ~74~29~12 ~75~29~16 minecraft:wooden_slab 9
fill ~74~30~12 ~75~30~16 minecraft:stonebrick 0
fill ~75~10~12 ~75~10~14 minecraft:farmland 6
fill ~76~9~12 ~77~9~12 minecraft:wooden_slab 10
fill ~76~10~12 ~77~10~12 minecraft:sea_lantern
fill ~76~11~12 ~77~11~12 minecraft:wooden_slab 2
fill ~76~16~12 ~77~16~18 minecraft:wooden_slab 1
fill ~76~29~12 ~77~29~12 minecraft:wooden_slab 10
fill ~76~30~12 ~77~30~12 minecraft:sea_lantern
fill ~76~31~12 ~77~31~12 minecraft:wooden_slab 2
fill ~76~36~12 ~77~36~18 minecraft:wooden_slab 1
fill ~78~16~12 ~79~16~12 minecraft:sea_lantern
fill ~78~36~12 ~79~36~12 minecraft:sea_lantern
fill ~80~16~12 ~80~16~13 minecraft:wooden_slab 1
fill ~80~36~12 ~80~36~13 minecraft:wooden_slab 1
fill ~81~10~12 ~81~10~17 minecraft:stained_glass 14
fill ~81~15~12 ~81~15~13 minecraft:stained_hardened_clay 14
fill ~81~30~12 ~81~30~17 minecraft:stained_glass 14
fill ~81~35~12 ~81~35~13 minecraft:stained_hardened_clay 14
fill ~82~9~12 ~82~9~13 minecraft:wooden_slab 10
fill ~82~10~12 ~82~10~13 minecraft:sandstone 2
fill ~82~11~12 ~82~13~13 minecraft:glass
fill ~82~14~12 ~82~14~13 minecraft:sandstone 2
fill ~82~15~12 ~82~15~13 minecraft:wooden_slab 2
fill ~82~29~12 ~82~29~13 minecraft:wooden_slab 10
fill ~82~30~12 ~82~30~13 minecraft:sandstone 2
fill ~82~31~12 ~82~33~13 minecraft:glass
fill ~82~34~12 ~82~34~13 minecraft:sandstone 2
fill ~82~35~12 ~82~35~13 minecraft:wooden_slab 2
fill ~52~21~13 ~52~21~21 minecraft:stone_block_slab 13
fill ~52~22~13 ~52~22~21 minecraft:stained_hardened_clay 14
fill ~52~23~13 ~52~23~21 minecraft:stone_block_slab 5
setblock ~59~10~13 minecraft:stained_glass 14
setblock ~59~16~13 minecraft:sea_lantern
setblock ~59~30~13 minecraft:stained_glass 14
setblock ~59~36~13 minecraft:sea_lantern
setblock ~60~9~13 minecraft:wooden_slab 10
setblock ~60~10~13 minecraft:sea_lantern
setblock ~60~11~13 minecraft:wooden_slab 2
fill ~60~16~13 ~60~16~31 minecraft:wooden_slab 1
setblock ~60~29~13 minecraft:wooden_slab 10
setblock ~60~30~13 minecraft:sea_lantern
setblock ~60~31~13 minecraft:wooden_slab 2
fill ~60~36~13 ~60~36~31 minecraft:wooden_slab 1
fill ~61~9~13 ~62~9~17 minecraft:wooden_slab 9
setblock ~61~10~13 minecraft:farmland 4
fill ~61~11~13 ~62~11~18 minecraft:wheat 7
fill ~61~29~13 ~62~29~18 minecraft:wooden_slab 9
fill ~61~30~13 ~62~30~18 minecraft:stonebrick 0
setblock ~62~10~13 minecraft:farmland 7
setblock ~63~10~13 minecraft:farmland 2
setblock ~64~10~13 minecraft:farmland 6
fill ~65~1~13 ~65~1~15 minecraft:stone_block_slab 8
fill ~65~2~13 ~65~2~15 minecraft:stone_block_slab 0
setblock ~65~10~13 minecraft:farmland 2
fill ~66~10~13 ~66~10~14 minecraft:farmland 5
setblock ~66~14~13 minecraft:sea_lantern
setblock ~66~15~13 minecraft:fence 2
fill ~66~21~13 ~66~21~15 minecraft:stone_block_slab 8
fill ~66~22~13 ~66~22~15 minecraft:stone_block_slab 0
setblock ~67~10~13 minecraft:farmland 4
setblock ~68~10~13 minecraft:farmland 7
fill ~70~10~13 ~70~10~14 minecraft:farmland 6
fill ~70~11~13 ~72~11~13 minecraft:wheat 7
fill ~71~10~13 ~72~10~13 minecraft:farmland 4
setblock ~72~14~13 minecraft:sea_lantern
setblock ~72~15~13 minecraft:fence 2
setblock ~73~10~13 minecraft:farmland 2
setblock ~74~10~13 minecraft:farmland 5
fill ~76~9~13 ~77~9~17 minecraft:wooden_slab 9
fill ~76~10~13 ~76~10~14 minecraft:farmland 5
fill ~76~11~13 ~77~11~18 minecraft:wheat 7
fill ~76~29~13 ~77~29~18 minecraft:wooden_slab 9
fill ~76~30~13 ~77~30~18 minecraft:stonebrick 0
setblock ~77~10~13 minecraft:farmland 4
setblock ~78~9~13 minecraft:wooden_slab 10
setblock ~78~10~13 minecraft:sea_lantern
setblock ~78~11~13 minecraft:wooden_slab 2
fill ~78~16~13 ~78~16~31 minecraft:wooden_slab 1
setblock ~78~29~13 minecraft:wooden_slab 10
setblock ~78~30~13 minecraft:sea_lantern
setblock ~78~31~13 minecraft:wooden_slab 2
fill ~78~36~13 ~78~36~31 minecraft:wooden_slab 1
setblock ~79~10~13 minecraft:stained_glass 14
setblock ~79~16~13 minecraft:sea_lantern
setblock ~79~30~13 minecraft:stained_glass 14
setblock ~79~36~13 minecraft:sea_lantern
fill ~86~21~13 ~86~21~21 minecraft:stone_block_slab 13
fill ~86~22~13 ~86~22~21 minecraft:stained_hardened_clay 14
fill ~86~23~13 ~86~23~21 minecraft:stone_block_slab 5
fill ~52~1~14 ~52~1~22 minecraft:stone_block_slab 13
fill ~52~2~14 ~52~2~22 minecraft:stained_hardened_clay 14
fill ~52~3~14 ~52~3~22 minecraft:stone_block_slab 5
fill ~55~9~14 ~55~9~15 minecraft:wooden_slab 10
fill ~55~10~14 ~55~10~15 minecraft:sandstone 2
fill ~55~11~14 ~55~13~15 minecraft:glass
fill ~55~14~14 ~55~14~15 minecraft:sandstone 2
fill ~55~15~14 ~55~15~15 minecraft:wooden_slab 2
fill ~55~29~14 ~55~29~15 minecraft:wooden_slab 10
fill ~55~30~14 ~55~30~15 minecraft:sandstone 2
fill ~55~31~14 ~55~33~15 minecraft:glass
fill ~55~34~14 ~55~34~15 minecraft:sandstone 2
fill ~55~35~14 ~55~35~15 minecraft:wooden_slab 2
fill ~56~10~14 ~56~10~30 minecraft:stained_glass 14
fill ~56~15~14 ~56~15~15 minecraft:stained_hardened_clay 14
fill ~56~30~14 ~56~30~30 minecraft:stained_glass 14
fill ~56~35~14 ~56~35~15 minecraft:stained_hardened_clay 14
fill ~57~16~14 ~57~16~15 minecraft:wooden_slab 1
fill ~57~36~14 ~57~36~15 minecraft:wooden_slab 1
fill ~58~16~14 ~58~16~15 minecraft:sea_lantern
fill ~58~36~14 ~58~36~15 minecraft:sea_lantern
fill ~59~9~14 ~59~9~15 minecraft:wooden_slab 10
fill ~59~10~14 ~59~10~15 minecraft:sea_lantern
fill ~59~11~14 ~59~11~15 minecraft:wooden_slab 2
fill ~59~16~14 ~59~16~30 minecraft:wooden_slab 1
fill ~59~29~14 ~59~29~15 minecraft:wooden_slab 10
fill ~59~30~14 ~59~30~15 minecraft:sea_lantern
fill ~59~31~14 ~59~31~15 minecraft:wooden_slab 2
fill ~59~36~14 ~59~36~30 minecraft:wooden_slab 1
fill ~60~9~14 ~60~9~30 minecraft:wooden_slab 9
setblock ~60~10~14 minecraft:farmland 5
fill ~60~11~14 ~60~11~21 minecraft:wheat 7
fill ~60~29~14 ~60~29~30 minecraft:wooden_slab 9
fill ~60~30~14 ~60~30~30 minecraft:stonebrick 0
setblock ~61~10~14 minecraft:farmland 3
setblock ~62~10~14 minecraft:farmland 4
fill ~63~10~14 ~64~10~14 minecraft:farmland 3
setblock ~65~9~14 minecraft:wooden_slab 9
setblock ~65~10~14 minecraft:farmland 7
fill ~66~1~14 ~66~1~16 minecraft:stone_block_slab 8
fill ~66~2~14 ~66~2~16 minecraft:stone_block_slab 0
fill ~66~9~14 ~72~9~14 minecraft:sea_lantern
fill ~67~10~14 ~68~10~14 minecraft:farmland 5
fill ~67~21~14 ~67~21~16 minecraft:stone_block_slab 8
fill ~67~22~14 ~67~22~16 minecraft:stone_block_slab 0
setblock ~70~11~14 minecraft:wheat 6
setblock ~71~10~14 minecraft:farmland 5
fill ~71~11~14 ~73~11~14 minecraft:wheat 7
setblock ~72~10~14 minecraft:farmland 7
setblock ~73~9~14 minecraft:wooden_slab 9
setblock ~73~10~14 minecraft:farmland 4
setblock ~74~10~14 minecraft:farmland 6
setblock ~77~10~14 minecraft:farmland 3
fill ~78~9~14 ~78~9~30 minecraft:wooden_slab 9
setblock ~78~10~14 minecraft:farmland 2
fill ~78~11~14 ~78~11~17 minecraft:wheat 7
fill ~78~29~14 ~78~29~30 minecraft:wooden_slab 9
fill ~78~30~14 ~78~30~30 minecraft:stonebrick 0
fill ~79~9~14 ~79~9~15 minecraft:wooden_slab 10
fill ~79~10~14 ~79~10~15 minecraft:sea_lantern
fill ~79~11~14 ~79~11~15 minecraft:wooden_slab 2
fill ~79~16~14 ~79~16~30 minecraft:wooden_slab 1
fill ~79~29~14 ~79~29~15 minecraft:wooden_slab 10
fill ~79~30~14 ~79~30~15 minecraft:sea_lantern
fill ~79~31~14 ~79~31~15 minecraft:wooden_slab 2
fill ~79~36~14 ~79~36~30 minecraft:wooden_slab 1
fill ~80~16~14 ~80~16~15 minecraft:sea_lantern
fill ~80~36~14 ~80~36~15 minecraft:sea_lantern
fill ~81~16~14 ~81~16~15 minecraft:wooden_slab 1
fill ~81~36~14 ~81~36~15 minecraft:wooden_slab 1
fill ~82~10~14 ~82~10~30 minecraft:stained_glass 14
fill ~82~15~14 ~82~15~15 minecraft:stained_hardened_clay 14
fill ~82~30~14 ~82~30~30 minecraft:stained_glass 14
fill ~82~35~14 ~82~35~15 minecraft:stained_hardened_clay 14
fill ~83~9~14 ~83~9~15 minecraft:wooden_slab 10
fill ~83~10~14 ~83~10~15 minecraft:sandstone 2
fill ~83~11~14 ~83~13~15 minecraft:glass
fill ~83~14~14 ~83~14~15 minecraft:sandstone 2
fill ~83~15~14 ~83~15~15 minecraft:wooden_slab 2
fill ~83~29~14 ~83~29~15 minecraft:wooden_slab 10
fill ~83~30~14 ~83~30~15 minecraft:sandstone 2
fill ~83~31~14 ~83~33~15 minecraft:glass
fill ~83~34~14 ~83~34~15 minecraft:sandstone 2
fill ~83~35~14 ~83~35~15 minecraft:wooden_slab 2
fill ~86~1~14 ~86~1~22 minecraft:stone_block_slab 13
fill ~86~2~14 ~86~2~22 minecraft:stained_hardened_clay 14
fill ~86~3~14 ~86~3~22 minecraft:stone_block_slab 5
setblock ~60~10~15 minecraft:farmland 6
setblock ~61~10~15 minecraft:farmland 5
setblock ~62~10~15 minecraft:farmland 1
setblock ~62~14~15 minecraft:sea_lantern
setblock ~62~15~15 minecraft:fence 2
setblock ~62~34~15 minecraft:sea_lantern
setblock ~62~35~15 minecraft:fence 2
setblock ~63~10~15 minecraft:farmland 7
setblock ~64~10~15 minecraft:farmland 3
setblock ~65~9~15 minecraft:sea_lantern
setblock ~65~10~15 minecraft:farmland 5
setblock ~65~11~15 minecraft:wheat 7
setblock ~65~16~15 minecraft:wooden_slab 1
setblock ~65~29~15 minecraft:wooden_slab 9
setblock ~65~30~15 minecraft:stonebrick 0
setblock ~65~36~15 minecraft:wooden_slab 1
fill ~66~9~15 ~72~9~15 minecraft:stained_glass 11
fill ~66~11~15 ~68~11~15 minecraft:carpet 12
fill ~66~16~15 ~72~16~15 minecraft:sea_lantern
fill ~66~29~15 ~72~29~15 minecraft:stained_glass 3
fill ~66~30~15 ~72~30~15 minecraft:sea_lantern
fill ~67~1~15 ~67~1~17 minecraft:stone_block_slab 8
fill ~67~2~15 ~67~2~17 minecraft:stone_block_slab 0
fill ~68~21~15 ~68~21~17 minecraft:stone_block_slab 8
fill ~68~22~15 ~68~22~17 minecraft:stone_block_slab 0
setblock ~69~11~15 minecraft:wooden_slab 1
setblock ~73~9~15 minecraft:sea_lantern
setblock ~73~10~15 minecraft:farmland 5
setblock ~73~11~15 minecraft:wheat 7
setblock ~73~16~15 minecraft:wooden_slab 1
setblock ~73~29~15 minecraft:wooden_slab 9
setblock ~73~30~15 minecraft:stonebrick 0
setblock ~73~36~15 minecraft:wooden_slab 1
setblock ~74~10~15 minecraft:farmland 7
setblock ~75~10~15 minecraft:farmland 3
setblock ~76~10~15 minecraft:farmland 4
setblock ~76~14~15 minecraft:sea_lantern
setblock ~76~15~15 minecraft:fence 2
setblock ~76~34~15 minecraft:sea_lantern
setblock ~76~35~15 minecraft:fence 2
fill ~77~10~15 ~78~10~15 minecraft:farmland 6
fill ~54~9~16 ~54~9~17 minecraft:wooden_slab 10
fill ~54~10~16 ~54~10~17 minecraft:sandstone 2
fill ~54~11~16 ~54~13~17 minecraft:glass
fill ~54~14~16 ~54~14~17 minecraft:sandstone 2
fill ~54~15~16 ~54~15~17 minecraft:wooden_slab 2
fill ~54~29~16 ~54~29~17 minecraft:wooden_slab 10
fill ~54~30~16 ~54~30~17 minecraft:sandstone 2
fill ~54~31~16 ~54~33~17 minecraft:glass
fill ~54~34~16 ~54~34~17 minecraft:sandstone 2
fill ~54~35~16 ~54~35~17 minecraft:wooden_slab 2
fill ~55~10~16 ~55~10~28 minecraft:stained_glass 14
fill ~55~15~16 ~55~15~17 minecraft:stained_hardened_clay 14
fill ~55~30~16 ~55~30~28 minecraft:stained_glass 14
fill ~55~35~16 ~55~35~17 minecraft:stained_hardened_clay 14
fill ~56~16~16 ~56~16~17 minecraft:wooden_slab 1
fill ~56~36~16 ~56~36~17 minecraft:wooden_slab 1
fill ~57~16~16 ~57~16~17 minecraft:sea_lantern
fill ~57~36~16 ~57~36~17 minecraft:sea_lantern
fill ~58~9~16 ~58~9~17 minecraft:wooden_slab 10
fill ~58~10~16 ~58~10~17 minecraft:sea_lantern
fill ~58~11~16 ~58~11~17 minecraft:wooden_slab 2
fill ~58~16~16 ~58~16~28 minecraft:wooden_slab 1
fill ~58~29~16 ~58~29~17 minecraft:wooden_slab 10
fill ~58~30~16 ~58~30~17 minecraft:sea_lantern
fill ~58~31~16 ~58~31~17 minecraft:wooden_slab 2
fill ~58~36~16 ~58~36~28 minecraft:wooden_slab 1
fill ~59~9~16 ~59~9~28 minecraft:wooden_slab 9
setblock ~59~10~16 minecraft:farmland 3
fill ~59~11~16 ~59~11~21 minecraft:wheat 7
fill ~59~29~16 ~59~29~28 minecraft:wooden_slab 9
fill ~59~30~16 ~59~30~28 minecraft:stonebrick 0
setblock ~60~10~16 minecraft:farmland 4
setblock ~61~10~16 minecraft:farmland 2
setblock ~62~10~16 minecraft:farmland 4
setblock ~63~9~16 minecraft:wooden_slab 9
setblock ~63~10~16 minecraft:farmland 3
setblock ~64~9~16 minecraft:sea_lantern
setblock ~64~10~16 minecraft:farmland 5
setblock ~65~9~16 minecraft:stained_glass 11
setblock ~65~11~16 minecraft:carpet 12
setblock ~65~16~16 minecraft:sea_lantern
setblock ~65~29~16 minecraft:stained_glass 3
setblock ~65~30~16 minecraft:sea_lantern
fill ~66~9~16 ~72~9~16 minecraft:sea_lantern
fill ~66~10~16 ~67~10~16 minecraft:farmland 5
fill ~66~11~16 ~68~11~20 minecraft:wheat 7
fill ~66~16~16 ~72~16~16 minecraft:wooden_slab 1
fill ~66~29~16 ~72~29~28 minecraft:wooden_slab 9
fill ~66~30~16 ~72~30~18 minecraft:stonebrick 0
fill ~68~1~16 ~68~1~18 minecraft:stone_block_slab 8
fill ~68~2~16 ~68~2~18 minecraft:stone_block_slab 0
setblock ~68~10~16 minecraft:farmland 6
setblock ~68~23~16 minecraft:iron_bars
fill ~69~10~16 ~69~10~20 minecraft:planks 1
setblock ~69~23~16 minecraft:sea_lantern
setblock ~69~24~16 minecraft:anvil 1
setblock ~69~25~16 minecraft:skull 1
setblock ~70~10~16 minecraft:farmland 6
fill ~70~11~16 ~72~11~20 minecraft:wheat 7
setblock ~70~23~16 minecraft:iron_bars
fill ~71~10~16 ~72~10~16 minecraft:farmland 5
setblock ~73~9~16 minecraft:stained_glass 11
setblock ~73~11~16 minecraft:carpet 12
setblock ~73~16~16 minecraft:sea_lantern
setblock ~73~29~16 minecraft:stained_glass 3
setblock ~73~30~16 minecraft:sea_lantern
setblock ~74~9~16 minecraft:sea_lantern
setblock ~74~10~16 minecraft:farmland 5
setblock ~75~9~16 minecraft:wooden_slab 9
setblock ~75~10~16 minecraft:farmland 4
setblock ~76~10~16 minecraft:farmland 3
setblock ~77~10~16 minecraft:farmland 4
fill ~78~10~16 ~79~10~16 minecraft:farmland 5
fill ~79~9~16 ~79~9~28 minecraft:wooden_slab 9
fill ~79~11~16 ~79~11~21 minecraft:wheat 7
fill ~79~29~16 ~79~29~28 minecraft:wooden_slab 9
fill ~79~30~16 ~79~30~28 minecraft:stonebrick 0
fill ~80~9~16 ~80~9~17 minecraft:wooden_slab 10
fill ~80~10~16 ~80~10~17 minecraft:sea_lantern
fill ~80~11~16 ~80~11~17 minecraft:wooden_slab 2
fill ~80~16~16 ~80~16~28 minecraft:wooden_slab 1
fill ~80~29~16 ~80~29~17 minecraft:wooden_slab 10
fill ~80~30~16 ~80~30~17 minecraft:sea_lantern
fill ~80~31~16 ~80~31~17 minecraft:wooden_slab 2
fill ~80~36~16 ~80~36~28 minecraft:wooden_slab 1
fill ~81~16~16 ~81~16~17 minecraft:sea_lantern
fill ~81~36~16 ~81~36~17 minecraft:sea_lantern
fill ~82~16~16 ~82~16~17 minecraft:wooden_slab 1
fill ~82~36~16 ~82~36~17 minecraft:wooden_slab 1
fill ~83~10~16 ~83~10~17 minecraft:stained_glass 14
fill ~83~15~16 ~83~15~17 minecraft:stained_hardened_clay 14
fill ~83~30~16 ~83~30~28 minecraft:stained_glass 14
fill ~83~35~16 ~83~35~17 minecraft:stained_hardened_clay 14
fill ~84~9~16 ~84~9~17 minecraft:wooden_slab 10
fill ~84~10~16 ~84~10~17 minecraft:sandstone 2
fill ~84~11~16 ~84~13~17 minecraft:glass
fill ~84~14~16 ~84~14~17 minecraft:sandstone 2
fill ~84~15~16 ~84~15~17 minecraft:wooden_slab 2
fill ~84~29~16 ~84~29~17 minecraft:wooden_slab 10
fill ~84~30~16 ~84~30~17 minecraft:sandstone 2
fill ~84~31~16 ~84~33~17 minecraft:glass
fill ~84~34~16 ~84~34~17 minecraft:sandstone 2
fill ~84~35~16 ~84~35~17 minecraft:wooden_slab 2
fill ~53~23~17 ~67~23~17 minecraft:stone_block_slab 5
setblock ~59~10~17 minecraft:farmland 4
setblock ~60~10~17 minecraft:farmland 5
setblock ~61~10~17 minecraft:farmland 6
setblock ~62~10~17 minecraft:farmland 7
setblock ~63~9~17 minecraft:sea_lantern
setblock ~63~10~17 minecraft:farmland 6
setblock ~63~11~17 minecraft:wheat 7
setblock ~63~16~17 minecraft:wooden_slab 1
setblock ~63~29~17 minecraft:wooden_slab 9
setblock ~63~30~17 minecraft:stonebrick 0
setblock ~63~36~17 minecraft:wooden_slab 1
setblock ~64~9~17 minecraft:stained_glass 11
setblock ~64~11~17 minecraft:carpet 12
setblock ~64~14~17 minecraft:sea_lantern
setblock ~64~15~17 minecraft:fence 2
setblock ~64~16~17 minecraft:sea_lantern
setblock ~64~29~17 minecraft:stained_glass 3
setblock ~64~30~17 minecraft:sea_lantern
setblock ~65~9~17 minecraft:sea_lantern
fill ~65~10~17 ~65~10~18 minecraft:farmland 5
fill ~65~11~17 ~65~11~21 minecraft:wheat 7
setblock ~65~16~17 minecraft:wooden_slab 1
fill ~65~29~17 ~65~29~27 minecraft:wooden_slab 9
fill ~65~30~17 ~65~30~27 minecraft:stonebrick 0
fill ~66~9~17 ~72~9~27 minecraft:wooden_slab 9
setblock ~66~10~17 minecraft:farmland 4
fill ~66~16~17 ~72~16~27 minecraft:glass
setblock ~67~10~17 minecraft:farmland 6
setblock ~68~3~17 minecraft:iron_bars
fill ~68~10~17 ~68~10~18 minecraft:farmland 4
setblock ~68~23~17 minecraft:sea_lantern
setblock ~68~24~17 minecraft:anvil 0
setblock ~68~25~17 minecraft:skull 1
setblock ~69~3~17 minecraft:sea_lantern
setblock ~69~4~17 minecraft:anvil 1
setblock ~69~5~17 minecraft:skull 1
fill ~69~21~17 ~69~23~17 minecraft:iron_block
setblock ~69~24~17 minecraft:dispenser 1
setblock ~69~25~17 minecraft:cobblestone_wall 0
setblock ~69~26~17 minecraft:skull 1
setblock ~70~3~17 minecraft:iron_bars
setblock ~70~10~17 minecraft:farmland 4
fill ~70~21~17 ~70~21~19 minecraft:stone_block_slab 8
fill ~70~22~17 ~70~22~19 minecraft:stone_block_slab 0
setblock ~70~23~17 minecraft:sea_lantern
setblock ~70~24~17 minecraft:anvil 2
setblock ~70~25~17 minecraft:skull 1
setblock ~71~10~17 minecraft:farmland 6
fill ~71~23~17 ~85~23~17 minecraft:stone_block_slab 5
fill ~72~10~17 ~73~10~17 minecraft:farmland 5
setblock ~73~9~17 minecraft:sea_lantern
fill ~73~11~17 ~73~11~21 minecraft:wheat 7
setblock ~73~16~17 minecraft:wooden_slab 1
fill ~73~29~17 ~73~29~27 minecraft:wooden_slab 9
fill ~73~30~17 ~73~30~27 minecraft:stonebrick 0
setblock ~74~9~17 minecraft:stained_glass 11
setblock ~74~11~17 minecraft:carpet 12
setblock ~74~14~17 minecraft:sea_lantern
setblock ~74~15~17 minecraft:fence 2
setblock ~74~16~17 minecraft:sea_lantern
setblock ~74~29~17 minecraft:stained_glass 3
setblock ~74~30~17 minecraft:sea_lantern
setblock ~75~9~17 minecraft:sea_lantern
fill ~75~10~17 ~76~10~17 minecraft:farmland 5
setblock ~75~11~17 minecraft:wheat 7
setblock ~75~16~17 minecraft:wooden_slab 1
setblock ~75~29~17 minecraft:wooden_slab 9
setblock ~75~30~17 minecraft:stonebrick 0
setblock ~75~36~17 minecraft:wooden_slab 1
setblock ~77~10~17 minecraft:farmland 3
setblock ~78~10~17 minecraft:farmland 7
setblock ~79~10~17 minecraft:farmland 4
fill ~53~3~18 ~67~3~18 minecraft:stone_block_slab 5
fill ~53~9~18 ~53~9~26 minecraft:wooden_slab 10
fill ~53~10~18 ~53~10~26 minecraft:sandstone 2
fill ~53~11~18 ~53~13~20 minecraft:glass
fill ~53~14~18 ~53~14~26 minecraft:sandstone 2
fill ~53~15~18 ~53~15~26 minecraft:wooden_slab 2
fill ~53~29~18 ~53~29~26 minecraft:wooden_slab 10
fill ~53~30~18 ~53~30~26 minecraft:sandstone 2
fill ~53~31~18 ~53~33~22 minecraft:glass
fill ~53~34~18 ~53~34~26 minecraft:sandstone 2
fill ~53~35~18 ~53~35~26 minecraft:wooden_slab 2
fill ~54~10~18 ~54~10~26 minecraft:stained_glass 14
fill ~54~15~18 ~54~15~26 minecraft:stained_hardened_clay 14
fill ~54~30~18 ~54~30~26 minecraft:stained_glass 14
fill ~54~35~18 ~54~35~26 minecraft:stained_hardened_clay 14
fill ~55~16~18 ~55~16~26 minecraft:wooden_slab 1
fill ~55~36~18 ~55~36~26 minecraft:wooden_slab 1
fill ~56~16~18 ~56~16~26 minecraft:sea_lantern
fill ~56~36~18 ~56~36~26 minecraft:sea_lantern
fill ~57~9~18 ~57~9~26 minecraft:wooden_slab 10
fill ~57~10~18 ~57~10~26 minecraft:sea_lantern
fill ~57~11~18 ~57~11~26 minecraft:wooden_slab 2
fill ~57~16~18 ~57~16~26 minecraft:wooden_slab 1
fill ~57~29~18 ~57~29~26 minecraft:wooden_slab 10
fill ~57~30~18 ~57~30~26 minecraft:sea_lantern
fill ~57~31~18 ~57~31~26 minecraft:wooden_slab 2
fill ~57~36~18 ~57~36~26 minecraft:wooden_slab 1
fill ~58~9~18 ~58~9~26 minecraft:wooden_slab 9
setblock ~58~10~18 minecraft:farmland 4
fill ~58~11~18 ~58~11~21 minecraft:wheat 7
fill ~58~29~18 ~58~29~26 minecraft:wooden_slab 9
fill ~58~30~18 ~58~30~26 minecraft:stonebrick 0
setblock ~59~10~18 minecraft:farmland 5
setblock ~60~10~18 minecraft:farmland 3
setblock ~61~9~18 minecraft:wooden_slab 9
setblock ~61~10~18 minecraft:farmland 7
setblock ~62~9~18 minecraft:sea_lantern
setblock ~62~10~18 minecraft:farmland 6
setblock ~63~9~18 minecraft:stained_glass 11
setblock ~63~11~18 minecraft:carpet 12
setblock ~63~16~18 minecraft:sea_lantern
setblock ~63~29~18 minecraft:stained_glass 3
setblock ~63~30~18 minecraft:sea_lantern
setblock ~64~9~18 minecraft:sea_lantern
setblock ~64~10~18 minecraft:farmland 5
fill ~64~11~18 ~64~11~21 minecraft:wheat 7
setblock ~64~16~18 minecraft:wooden_slab 1
fill ~64~29~18 ~64~29~26 minecraft:wooden_slab 9
fill ~64~30~18 ~64~30~26 minecraft:stonebrick 0
fill ~65~9~18 ~65~9~26 minecraft:wooden_slab 9
fill ~65~16~18 ~65~16~26 minecraft:glass
fill ~66~10~18 ~67~10~18 minecraft:farmland 7
setblock ~68~3~18 minecraft:sea_lantern
setblock ~68~4~18 minecraft:anvil 0
setblock ~68~5~18 minecraft:skull 1
setblock ~68~23~18 minecraft:iron_bars
fill ~69~1~18 ~69~3~18 minecraft:iron_block
setblock ~69~4~18 minecraft:dispenser 1
setblock ~69~5~18 minecraft:cobblestone_wall 0
setblock ~69~6~18 minecraft:skull 1
setblock ~69~23~18 minecraft:sea_lantern
setblock ~69~24~18 minecraft:anvil 3
setblock ~69~25~18 minecraft:skull 1
fill ~70~1~18 ~70~1~20 minecraft:stone_block_slab 8
fill ~70~2~18 ~70~2~20 minecraft:stone_block_slab 0
setblock ~70~3~18 minecraft:sea_lantern
setblock ~70~4~18 minecraft:anvil 2
setblock ~70~5~18 minecraft:skull 1
fill ~70~10~18 ~72~10~18 minecraft:farmland 5
fill ~71~3~18 ~85~3~18 minecraft:stone_block_slab 5
fill ~71~21~18 ~71~21~20 minecraft:stone_block_slab 8
fill ~71~22~18 ~71~22~20 minecraft:stone_block_slab 0
fill ~73~9~18 ~73~9~26 minecraft:wooden_slab 9
setblock ~73~10~18 minecraft:farmland 7
fill ~73~16~18 ~73~16~26 minecraft:glass
setblock ~74~9~18 minecraft:sea_lantern
setblock ~74~10~18 minecraft:farmland 4
fill ~74~11~18 ~74~11~21 minecraft:wheat 7
setblock ~74~16~18 minecraft:wooden_slab 1
fill ~74~29~18 ~74~29~26 minecraft:wooden_slab 9
fill ~74~30~18 ~74~30~26 minecraft:stonebrick 0
setblock ~75~9~18 minecraft:stained_glass 11
setblock ~75~11~18 minecraft:carpet 12
setblock ~75~16~18 minecraft:sea_lantern
setblock ~75~29~18 minecraft:stained_glass 3
setblock ~75~30~18 minecraft:sea_lantern
setblock ~76~9~18 minecraft:sea_lantern
fill ~76~10~18 ~77~10~18 minecraft:farmland 5
setblock ~77~9~18 minecraft:wooden_slab 9
fill ~78~10~18 ~78~10~19 minecraft:farmland 6
fill ~79~10~18 ~79~10~19 minecraft:farmland 7
fill ~80~9~18 ~80~9~26 minecraft:wooden_slab 9
setblock ~80~10~18 minecraft:farmland 6
fill ~80~11~18 ~80~11~21 minecraft:wheat 7
fill ~80~29~18 ~80~29~26 minecraft:wooden_slab 9
fill ~80~30~18 ~80~30~26 minecraft:stonebrick 0
fill ~81~9~18 ~81~9~26 minecraft:wooden_slab 10
fill ~81~10~18 ~81~10~26 minecraft:sea_lantern
fill ~81~11~18 ~81~11~26 minecraft:wooden_slab 2
fill ~81~16~18 ~81~16~26 minecraft:wooden_slab 1
fill ~81~29~18 ~81~29~26 minecraft:wooden_slab 10
fill ~81~30~18 ~81~30~26 minecraft:sea_lantern
fill ~81~31~18 ~81~31~26 minecraft:wooden_slab 2
fill ~81~36~18 ~81~36~26 minecraft:wooden_slab 1
fill ~82~16~18 ~82~16~26 minecraft:sea_lantern
fill ~82~36~18 ~82~36~26 minecraft:sea_lantern
fill ~83~16~18 ~83~16~26 minecraft:wooden_slab 1
fill ~83~36~18 ~83~36~26 minecraft:wooden_slab 1
fill ~84~10~18 ~84~10~26 minecraft:stained_glass 14
fill ~84~15~18 ~84~15~26 minecraft:stained_hardened_clay 14
fill ~84~30~18 ~84~30~26 minecraft:stained_glass 14
fill ~84~35~18 ~84~35~26 minecraft:stained_hardened_clay 14
fill ~85~9~18 ~85~9~26 minecraft:wooden_slab 10
fill ~85~10~18 ~85~10~26 minecraft:sandstone 2
fill ~85~11~18 ~85~13~26 minecraft:glass
fill ~85~14~18 ~85~14~26 minecraft:sandstone 2
fill ~85~15~18 ~85~15~26 minecraft:wooden_slab 2
fill ~85~29~18 ~85~29~26 minecraft:wooden_slab 10
fill ~85~30~18 ~85~30~26 minecraft:sandstone 2
fill ~85~31~18 ~85~33~26 minecraft:glass
fill ~85~34~18 ~85~34~26 minecraft:sandstone 2
fill ~85~35~18 ~85~35~26 minecraft:wooden_slab 2
setblock ~58~10~19 minecraft:farmland 1
setblock ~59~10~19 minecraft:farmland 7
fill ~60~10~19 ~60~10~20 minecraft:farmland 6
setblock ~60~14~19 minecraft:sea_lantern
setblock ~60~15~19 minecraft:fence 2
fill ~61~9~19 ~61~9~25 minecraft:sea_lantern
fill ~61~10~19 ~61~10~20 minecraft:farmland 2
fill ~61~11~19 ~61~11~21 minecraft:wheat 7
fill ~61~16~19 ~61~16~32 minecraft:wooden_slab 1
fill ~61~29~19 ~61~29~31 minecraft:wooden_slab 9
fill ~61~30~19 ~61~30~31 minecraft:stonebrick 0
fill ~61~36~19 ~61~36~32 minecraft:wooden_slab 1
fill ~62~9~19 ~62~9~25 minecraft:stained_glass 11
fill ~62~11~19 ~62~11~21 minecraft:carpet 12
fill ~62~16~19 ~62~16~25 minecraft:sea_lantern
fill ~62~29~19 ~62~29~25 minecraft:stained_glass 3
fill ~62~30~19 ~62~30~25 minecraft:sea_lantern
fill ~63~9~19 ~63~9~25 minecraft:sea_lantern
fill ~63~10~19 ~63~10~20 minecraft:farmland 5
fill ~63~11~19 ~63~11~21 minecraft:wheat 7
fill ~63~16~19 ~63~16~25 minecraft:wooden_slab 1
fill ~63~29~19 ~63~29~25 minecraft:wooden_slab 9
fill ~63~30~19 ~63~30~25 minecraft:stonebrick 0
fill ~64~9~19 ~64~9~25 minecraft:wooden_slab 9
fill ~64~10~19 ~64~10~20 minecraft:farmland 3
fill ~64~16~19 ~64~16~25 minecraft:glass
setblock ~65~10~19 minecraft:farmland 6
setblock ~66~10~19 minecraft:farmland 3
fill ~66~30~19 ~66~30~28 minecraft:stonebrick 0
fill ~67~10~19 ~67~10~20 minecraft:farmland 5
fill ~67~30~19 ~67~30~25 minecraft:planks 2
setblock ~68~3~19 minecraft:iron_bars
setblock ~68~10~19 minecraft:farmland 6
fill ~68~30~19 ~70~30~21 minecraft:stonebrick 0
setblock ~69~3~19 minecraft:sea_lantern
setblock ~69~4~19 minecraft:anvil 3
setblock ~69~5~19 minecraft:skull 1
fill ~69~23~19 ~69~23~34 minecraft:stone_block_slab 5
setblock ~70~3~19 minecraft:iron_bars
setblock ~70~10~19 minecraft:farmland 4
fill ~71~1~19 ~71~1~21 minecraft:stone_block_slab 8
fill ~71~2~19 ~71~2~21 minecraft:stone_block_slab 0
setblock ~71~10~19 minecraft:farmland 3
fill ~71~30~19 ~71~30~25 minecraft:planks 2
fill ~72~10~19 ~73~10~19 minecraft:farmland 6
fill ~72~21~19 ~72~21~21 minecraft:stone_block_slab 8
fill ~72~22~19 ~72~22~21 minecraft:stone_block_slab 0
fill ~72~30~19 ~72~30~28 minecraft:stonebrick 0
fill ~74~9~19 ~74~9~25 minecraft:wooden_slab 9
setblock ~74~10~19 minecraft:farmland 3
fill ~74~16~19 ~74~16~25 minecraft:glass
fill ~75~9~19 ~75~9~25 minecraft:sea_lantern
setblock ~75~10~19 minecraft:farmland 7
fill ~75~11~19 ~75~11~21 minecraft:wheat 7
fill ~75~16~19 ~75~16~25 minecraft:wooden_slab 1
fill ~75~29~19 ~75~29~25 minecraft:wooden_slab 9
fill ~75~30~19 ~75~30~25 minecraft:stonebrick 0
fill ~76~9~19 ~76~9~25 minecraft:stained_glass 11
fill ~76~11~19 ~76~11~21 minecraft:carpet 12
fill ~76~16~19 ~76~16~25 minecraft:sea_lantern
fill ~76~29~19 ~76~29~25 minecraft:stained_glass 3
fill ~76~30~19 ~76~30~25 minecraft:sea_lantern
fill ~77~9~19 ~77~9~25 minecraft:sea_lantern
setblock ~77~10~19 minecraft:farmland 6
fill ~77~11~19 ~78~11~21 minecraft:wheat 7
fill ~77~16~19 ~77~16~32 minecraft:wooden_slab 1
fill ~77~29~19 ~77~29~31 minecraft:wooden_slab 9
fill ~77~30~19 ~77~30~31 minecraft:stonebrick 0
fill ~77~36~19 ~77~36~32 minecraft:wooden_slab 1
setblock ~78~14~19 minecraft:sea_lantern
setblock ~78~15~19 minecraft:fence 2
setblock ~80~10~19 minecraft:farmland 7
fill ~83~10~19 ~83~10~28 minecraft:stained_glass 14
setblock ~58~10~20 minecraft:farmland 7
setblock ~59~10~20 minecraft:farmland 5
setblock ~65~10~20 minecraft:farmland 4
setblock ~66~10~20 minecraft:farmland 5
setblock ~68~10~20 minecraft:farmland 4
fill ~69~3~20 ~69~3~35 minecraft:stone_block_slab 5
fill ~70~10~20 ~71~10~20 minecraft:farmland 6
fill ~72~1~20 ~72~1~22 minecraft:stone_block_slab 8
fill ~72~2~20 ~72~2~22 minecraft:stone_block_slab 0
fill ~72~10~20 ~73~10~20 minecraft:farmland 3
fill ~73~21~20 ~73~21~22 minecraft:stone_block_slab 8
fill ~73~22~20 ~73~22~22 minecraft:stone_block_slab 0
fill ~74~10~20 ~75~10~20 minecraft:farmland 5
setblock ~77~10~20 minecraft:farmland 7
setblock ~78~10~20 minecraft:farmland 5
fill ~79~10~20 ~79~10~21 minecraft:farmland 6
setblock ~80~10~20 minecraft:farmland 4
fill ~58~10~21 ~59~10~21 minecraft:farmland 6
setblock ~60~10~21 minecraft:farmland 5
setblock ~61~10~21 minecraft:farmland 4
setblock ~63~10~21 minecraft:farmland 6
setblock ~64~10~21 minecraft:farmland 5
setblock ~65~10~21 minecraft:farmland 6
setblock ~66~10~21 minecraft:farmland 7
fill ~66~11~21 ~67~11~21 minecraft:wheat 7
setblock ~67~10~21 minecraft:farmland 4
fill ~68~10~21 ~69~10~21 minecraft:farmland 5
fill ~68~11~21 ~70~11~21 minecraft:carpet 12
setblock ~70~10~21 minecraft:farmland 3
setblock ~71~10~21 minecraft:farmland 5
fill ~71~11~21 ~72~11~21 minecraft:wheat 7
setblock ~72~10~21 minecraft:farmland 3
fill ~73~1~21 ~73~1~23 minecraft:stone_block_slab 8
fill ~73~2~21 ~73~2~23 minecraft:stone_block_slab 0
setblock ~73~10~21 minecraft:farmland 6
setblock ~74~10~21 minecraft:farmland 7
fill ~74~21~21 ~74~21~23 minecraft:stone_block_slab 8
fill ~74~22~21 ~74~22~23 minecraft:stone_block_slab 0
setblock ~75~10~21 minecraft:farmland 6
setblock ~77~10~21 minecraft:farmland 5
setblock ~78~10~21 minecraft:farmland 7
setblock ~80~10~21 minecraft:farmland 6
fill ~53~21~22 ~53~21~24 minecraft:stone_block_slab 13
fill ~53~22~22 ~53~22~24 minecraft:stained_hardened_clay 14
fill ~53~23~22 ~53~23~24 minecraft:stone_block_slab 5
fill ~58~10~22 ~61~10~22 minecraft:planks 1
setblock ~62~11~22 minecraft:wooden_slab 1
setblock ~62~14~22 minecraft:sea_lantern
setblock ~62~15~22 minecraft:fence 2
fill ~63~10~22 ~67~10~22 minecraft:planks 1
setblock ~68~10~22 minecraft:farmland 5
fill ~68~11~22 ~68~11~23 minecraft:carpet 12
fill ~68~30~22 ~70~30~22 minecraft:planks 2
setblock ~69~11~22 minecraft:stained_glass 11
setblock ~69~12~22 minecraft:sea_lantern
setblock ~69~13~22 minecraft:stained_glass 11
setblock ~69~14~22 minecraft:sea_lantern
setblock ~69~15~22 minecraft:stained_glass 11
setblock ~70~10~22 minecraft:farmland 2
fill ~70~11~22 ~70~11~23 minecraft:carpet 12
fill ~71~10~22 ~75~10~22 minecraft:planks 1
fill ~74~1~22 ~74~1~24 minecraft:stone_block_slab 8
fill ~74~2~22 ~74~2~24 minecraft:stone_block_slab 0
fill ~75~21~22 ~75~21~24 minecraft:stone_block_slab 8
fill ~75~22~22 ~75~22~24 minecraft:stone_block_slab 0
setblock ~76~11~22 minecraft:wooden_slab 1
setblock ~76~14~22 minecraft:sea_lantern
setblock ~76~15~22 minecraft:fence 2
fill ~77~10~22 ~80~10~22 minecraft:planks 1
fill ~85~21~22 ~85~21~24 minecraft:stone_block_slab 13
fill ~85~22~22 ~85~22~24 minecraft:stained_hardened_clay 14
fill ~85~23~22 ~85~23~24 minecraft:stone_block_slab 5
fill ~53~1~23 ~53~1~25 minecraft:stone_block_slab 13
fill ~53~2~23 ~53~2~25 minecraft:stained_hardened_clay 14
fill ~53~3~23 ~53~3~25 minecraft:stone_block_slab 5
fill ~53~32~23 ~53~32~26 minecraft:glass
fill ~53~33~23 ~53~33~24 minecraft:glass
fill ~58~10~23 ~58~10~24 minecraft:farmland 6
fill ~58~11~23 ~61~11~26 minecraft:wheat 7
setblock ~59~10~23 minecraft:farmland 4
setblock ~60~10~23 minecraft:farmland 6
setblock ~61~10~23 minecraft:farmland 7
fill ~62~11~23 ~62~11~25 minecraft:carpet 12
setblock ~63~10~23 minecraft:farmland 5
fill ~63~11~23 ~67~11~25 minecraft:wheat 7
fill ~64~10~23 ~67~10~23 minecraft:farmland 4
setblock ~68~10~23 minecraft:farmland 7
fill ~68~30~23 ~70~30~28 minecraft:stonebrick 0
setblock ~69~10~23 minecraft:farmland 5
setblock ~69~11~23 minecraft:carpet 12
fill ~70~10~23 ~70~10~24 minecraft:farmland 6
fill ~71~10~23 ~72~10~23 minecraft:farmland 7
fill ~71~11~23 ~75~11~25 minecraft:wheat 7
fill ~73~10~23 ~73~10~27 minecraft:farmland 6
setblock ~74~10~23 minecraft:farmland 5
fill ~75~1~23 ~75~1~25 minecraft:stone_block_slab 8
fill ~75~2~23 ~75~2~25 minecraft:stone_block_slab 0
setblock ~75~10~23 minecraft:farmland 6
fill ~76~11~23 ~76~11~25 minecraft:carpet 12
fill ~76~21~23 ~76~21~25 minecraft:stone_block_slab 8
fill ~76~22~23 ~76~22~25 minecraft:stone_block_slab 0
setblock ~77~10~23 minecraft:farmland 5
fill ~77~11~23 ~80~11~26 minecraft:wheat 7
setblock ~78~10~23 minecraft:farmland 4
setblock ~79~10~23 minecraft:farmland 7
setblock ~80~10~23 minecraft:farmland 4
fill ~85~1~23 ~85~1~25 minecraft:stone_block_slab 13
fill ~85~2~23 ~85~2~25 minecraft:stained_hardened_clay 14
fill ~85~3~23 ~85~3~25 minecraft:stone_block_slab 5
fill ~53~11~24 ~53~13~26 minecraft:glass
fill ~53~31~24 ~53~31~26 minecraft:glass
setblock ~59~10~24 minecraft:farmland 2
setblock ~60~10~24 minecraft:farmland 3
fill ~61~10~24 ~61~10~25 minecraft:farmland 4
setblock ~63~10~24 minecraft:farmland 7
setblock ~64~10~24 minecraft:farmland 4
fill ~65~10~24 ~66~10~24 minecraft:farmland 5
fill ~67~10~24 ~67~10~25 minecraft:farmland 6
setblock ~68~10~24 minecraft:farmland 4
fill ~68~11~24 ~68~11~28 minecraft:wheat 7
fill ~69~10~24 ~69~10~28 minecraft:planks 1
fill ~70~11~24 ~70~11~28 minecraft:wheat 7
fill ~71~10~24 ~71~10~26 minecraft:farmland 5
setblock ~72~10~24 minecraft:farmland 7
fill ~74~10~24 ~75~10~24 minecraft:farmland 7
fill ~76~1~24 ~76~1~26 minecraft:stone_block_slab 8
fill ~76~2~24 ~76~2~26 minecraft:stone_block_slab 0
setblock ~77~10~24 minecraft:farmland 7
fill ~77~21~24 ~77~21~26 minecraft:stone_block_slab 8
fill ~77~22~24 ~77~22~26 minecraft:stone_block_slab 0
setblock ~78~10~24 minecraft:farmland 5
setblock ~79~10~24 minecraft:farmland 3
setblock ~80~10~24 minecraft:farmland 6
fill ~54~21~25 ~54~21~26 minecraft:stone_block_slab 13
fill ~54~22~25 ~54~22~26 minecraft:stained_hardened_clay 14
fill ~54~23~25 ~54~23~26 minecraft:stone_block_slab 5
fill ~58~10~25 ~58~10~26 minecraft:farmland 5
setblock ~59~10~25 minecraft:farmland 4
setblock ~60~10~25 minecraft:farmland 7
setblock ~60~14~25 minecraft:sea_lantern
setblock ~60~15~25 minecraft:fence 2
setblock ~63~10~25 minecraft:farmland 6
fill ~64~10~25 ~64~10~26 minecraft:farmland 5
fill ~65~10~25 ~65~10~27 minecraft:farmland 6
setblock ~66~10~25 minecraft:farmland 5
setblock ~68~10~25 minecraft:farmland 6
setblock ~70~10~25 minecraft:farmland 7
setblock ~72~10~25 minecraft:farmland 5
setblock ~74~10~25 minecraft:farmland 7
setblock ~75~10~25 minecraft:farmland 3
fill ~77~1~25 ~77~1~27 minecraft:stone_block_slab 8
fill ~77~2~25 ~77~2~27 minecraft:stone_block_slab 0
setblock ~77~10~25 minecraft:farmland 3
fill ~78~10~25 ~79~10~25 minecraft:farmland 6
setblock ~78~14~25 minecraft:sea_lantern
setblock ~78~15~25 minecraft:fence 2
fill ~78~21~25 ~78~21~27 minecraft:stone_block_slab 8
fill ~78~22~25 ~78~22~27 minecraft:stone_block_slab 0
setblock ~80~10~25 minecraft:farmland 7
fill ~84~21~25 ~84~21~26 minecraft:stone_block_slab 13
fill ~84~22~25 ~84~22~26 minecraft:stained_hardened_clay 14
fill ~84~23~25 ~84~23~26 minecraft:stone_block_slab 5
setblock ~53~33~26 minecraft:glass
fill ~54~1~26 ~54~1~27 minecraft:stone_block_slab 13
fill ~54~2~26 ~54~2~27 minecraft:stained_hardened_clay 14
fill ~54~3~26 ~54~3~27 minecraft:stone_block_slab 5
setblock ~59~10~26 minecraft:farmland 6
setblock ~60~10~26 minecraft:farmland 3
fill ~61~9~26 ~61~9~31 minecraft:wooden_slab 9
setblock ~61~10~26 minecraft:farmland 6
setblock ~62~9~26 minecraft:sea_lantern
setblock ~62~10~26 minecraft:farmland 2
fill ~62~11~26 ~62~11~31 minecraft:wheat 7
fill ~62~16~26 ~62~16~32 minecraft:wooden_slab 1
fill ~62~29~26 ~62~29~31 minecraft:wooden_slab 9
fill ~62~30~26 ~62~30~31 minecraft:stonebrick 0
fill ~62~36~26 ~62~36~32 minecraft:wooden_slab 1
setblock ~63~9~26 minecraft:stained_glass 11
setblock ~63~11~26 minecraft:carpet 12
setblock ~63~16~26 minecraft:sea_lantern
setblock ~63~29~26 minecraft:stained_glass 3
setblock ~63~30~26 minecraft:sea_lantern
setblock ~64~9~26 minecraft:sea_lantern
fill ~64~11~26 ~67~11~26 minecraft:wheat 7
setblock ~64~16~26 minecraft:wooden_slab 1
setblock ~66~10~26 minecraft:farmland 4
fill ~67~10~26 ~67~10~28 minecraft:farmland 7
fill ~67~30~26 ~67~30~28 minecraft:stonebrick 0
setblock ~68~10~26 minecraft:farmland 5
setblock ~70~10~26 minecraft:farmland 5
fill ~71~11~26 ~74~11~26 minecraft:wheat 7
fill ~71~30~26 ~71~30~28 minecraft:stonebrick 0
setblock ~72~10~26 minecraft:farmland 6
setblock ~74~9~26 minecraft:sea_lantern
setblock ~74~10~26 minecraft:farmland 5
setblock ~74~16~26 minecraft:wooden_slab 1
setblock ~75~9~26 minecraft:stained_glass 11
setblock ~75~11~26 minecraft:carpet 12
setblock ~75~16~26 minecraft:sea_lantern
setblock ~75~29~26 minecraft:stained_glass 3
setblock ~75~30~26 minecraft:sea_lantern
setblock ~76~9~26 minecraft:sea_lantern
fill ~76~10~26 ~78~10~26 minecraft:farmland 7
fill ~76~11~26 ~76~11~31 minecraft:wheat 7
fill ~76~16~26 ~76~16~32 minecraft:wooden_slab 1
fill ~76~30~26 ~76~30~31 minecraft:stonebrick 0
fill ~76~36~26 ~76~36~32 minecraft:wooden_slab 1
fill ~77~9~26 ~77~9~31 minecraft:wooden_slab 9
fill ~78~1~26 ~78~1~28 minecraft:stone_block_slab 8
fill ~78~2~26 ~78~2~28 minecraft:stone_block_slab 0
setblock ~79~10~26 minecraft:farmland 5
fill ~79~21~26 ~79~21~28 minecraft:stone_block_slab 8
fill ~79~22~26 ~79~22~28 minecraft:stone_block_slab 0
setblock ~80~10~26 minecraft:farmland 6
fill ~84~1~26 ~84~1~27 minecraft:stone_block_slab 13
fill ~84~2~26 ~84~2~27 minecraft:stained_hardened_clay 14
fill ~84~3~26 ~84~3~27 minecraft:stone_block_slab 5
fill ~54~9~27 ~54~9~28 minecraft:wooden_slab 10
fill ~54~10~27 ~54~10~28 minecraft:sandstone 2
fill ~54~11~27 ~54~13~28 minecraft:glass
fill ~54~14~27 ~54~14~28 minecraft:sandstone 2
fill ~54~15~27 ~54~15~28 minecraft:wooden_slab 2
fill ~54~29~27 ~54~29~28 minecraft:wooden_slab 10
fill ~54~30~27 ~54~30~28 minecraft:sandstone 2
fill ~54~31~27 ~54~33~28 minecraft:glass
fill ~54~34~27 ~54~34~28 minecraft:sandstone 2
fill ~54~35~27 ~54~35~28 minecraft:wooden_slab 2
fill ~55~15~27 ~55~15~28 minecraft:stained_hardened_clay 14
setblock ~55~21~27 minecraft:stone_block_slab 13
setblock ~55~22~27 minecraft:stained_hardened_clay 14
setblock ~55~23~27 minecraft:stone_block_slab 5
fill ~55~35~27 ~55~35~28 minecraft:stained_hardened_clay 14
fill ~56~16~27 ~56~16~28 minecraft:wooden_slab 1
fill ~56~36~27 ~56~36~28 minecraft:wooden_slab 1
fill ~57~10~27 ~57~10~32 minecraft:stained_glass 14
fill ~57~16~27 ~57~16~28 minecraft:sea_lantern
fill ~57~30~27 ~57~30~32 minecraft:stained_glass 14
fill ~57~36~27 ~57~36~28 minecraft:sea_lantern
fill ~58~9~27 ~58~9~28 minecraft:wooden_slab 10
fill ~58~10~27 ~58~10~28 minecraft:sea_lantern
fill ~58~11~27 ~58~11~28 minecraft:wooden_slab 2
fill ~58~29~27 ~58~29~28 minecraft:wooden_slab 10
fill ~58~30~27 ~58~30~28 minecraft:sea_lantern
fill ~58~31~27 ~58~31~28 minecraft:wooden_slab 2
setblock ~59~10~27 minecraft:farmland 7
fill ~59~11~27 ~61~11~28 minecraft:wheat 7
setblock ~60~10~27 minecraft:farmland 1
fill ~61~10~27 ~61~10~28 minecraft:farmland 7
fill ~62~9~27 ~62~9~31 minecraft:wooden_slab 9
setblock ~62~10~27 minecraft:farmland 4
setblock ~63~9~27 minecraft:sea_lantern
fill ~63~10~27 ~63~10~28 minecraft:farmland 5
fill ~63~11~27 ~63~11~32 minecraft:wheat 7
fill ~63~16~27 ~63~16~33 minecraft:wooden_slab 1
fill ~63~29~27 ~63~29~32 minecraft:wooden_slab 9
fill ~63~30~27 ~63~30~32 minecraft:stonebrick 0
fill ~63~36~27 ~63~36~33 minecraft:wooden_slab 1
setblock ~64~9~27 minecraft:stained_glass 11
setblock ~64~11~27 minecraft:carpet 12
setblock ~64~14~27 minecraft:sea_lantern
setblock ~64~15~27 minecraft:fence 2
setblock ~64~16~27 minecraft:sea_lantern
setblock ~64~29~27 minecraft:stained_glass 3
setblock ~64~30~27 minecraft:sea_lantern
setblock ~65~9~27 minecraft:sea_lantern
fill ~65~11~27 ~67~11~27 minecraft:wheat 7
setblock ~65~16~27 minecraft:wooden_slab 1
setblock ~66~10~27 minecraft:farmland 7
setblock ~68~10~27 minecraft:farmland 2
fill ~70~10~27 ~71~10~27 minecraft:farmland 6
fill ~71~11~27 ~73~11~27 minecraft:wheat 7
setblock ~72~10~27 minecraft:farmland 7
setblock ~73~9~27 minecraft:sea_lantern
setblock ~73~16~27 minecraft:wooden_slab 1
setblock ~74~9~27 minecraft:stained_glass 11
setblock ~74~11~27 minecraft:carpet 12
setblock ~74~14~27 minecraft:sea_lantern
setblock ~74~15~27 minecraft:fence 2
setblock ~74~16~27 minecraft:sea_lantern
setblock ~74~29~27 minecraft:stained_glass 3
setblock ~74~30~27 minecraft:sea_lantern
setblock ~75~9~27 minecraft:sea_lantern
fill ~75~10~27 ~77~10~27 minecraft:farmland 5
fill ~75~11~27 ~75~11~32 minecraft:wheat 7
fill ~75~16~27 ~75~16~33 minecraft:wooden_slab 1
fill ~75~30~27 ~75~30~32 minecraft:stonebrick 0
fill ~75~36~27 ~75~36~33 minecraft:wooden_slab 1
fill ~76~9~27 ~76~9~31 minecraft:wooden_slab 9
fill ~76~29~27 ~76~29~31 minecraft:wooden_slab 9
fill ~77~11~27 ~79~11~28 minecraft:wheat 7
fill ~78~10~27 ~79~10~27 minecraft:farmland 6
fill ~79~1~27 ~79~1~29 minecraft:stone_block_slab 8
fill ~79~2~27 ~79~2~29 minecraft:stone_block_slab 0
fill ~80~9~27 ~80~9~28 minecraft:wooden_slab 10
fill ~80~10~27 ~80~10~28 minecraft:sea_lantern
fill ~80~11~27 ~80~11~28 minecraft:wooden_slab 2
fill ~80~29~27 ~80~29~28 minecraft:wooden_slab 10
fill ~80~30~27 ~80~30~28 minecraft:sea_lantern
fill ~80~31~27 ~80~31~28 minecraft:wooden_slab 2
fill ~81~10~27 ~81~10~32 minecraft:stained_glass 14
fill ~81~16~27 ~81~16~28 minecraft:sea_lantern
fill ~81~30~27 ~81~30~32 minecraft:stained_glass 14
fill ~81~36~27 ~81~36~28 minecraft:sea_lantern
fill ~82~16~27 ~82~16~28 minecraft:wooden_slab 1
fill ~82~36~27 ~82~36~28 minecraft:wooden_slab 1
fill ~83~15~27 ~83~15~28 minecraft:stained_hardened_clay 14
setblock ~83~21~27 minecraft:stone_block_slab 13
setblock ~83~22~27 minecraft:stained_hardened_clay 14
setblock ~83~23~27 minecraft:stone_block_slab 5
fill ~83~35~27 ~83~35~28 minecraft:stained_hardened_clay 14
fill ~84~9~27 ~84~9~28 minecraft:wooden_slab 10
fill ~84~10~27 ~84~10~28 minecraft:sandstone 2
fill ~84~11~27 ~84~13~28 minecraft:glass
fill ~84~14~27 ~84~14~28 minecraft:sandstone 2
fill ~84~15~27 ~84~15~28 minecraft:wooden_slab 2
fill ~84~29~27 ~84~29~28 minecraft:wooden_slab 10
fill ~84~30~27 ~84~30~28 minecraft:sandstone 2
fill ~84~31~27 ~84~33~28 minecraft:glass
fill ~84~34~27 ~84~34~28 minecraft:sandstone 2
fill ~84~35~27 ~84~35~28 minecraft:wooden_slab 2
setblock ~55~1~28 minecraft:stone_block_slab 13
setblock ~55~2~28 minecraft:stained_hardened_clay 14
setblock ~55~3~28 minecraft:stone_block_slab 5
setblock ~56~21~28 minecraft:stone_block_slab 13
setblock ~56~22~28 minecraft:stained_hardened_clay 14
setblock ~56~23~28 minecraft:stone_block_slab 5
setblock ~59~10~28 minecraft:farmland 2
setblock ~60~10~28 minecraft:farmland 4
setblock ~62~10~28 minecraft:farmland 6
fill ~63~9~28 ~63~9~32 minecraft:wooden_slab 9
setblock ~64~9~28 minecraft:sea_lantern
setblock ~64~10~28 minecraft:farmland 5
fill ~64~11~28 ~64~11~32 minecraft:wheat 7
fill ~64~16~28 ~64~16~33 minecraft:wooden_slab 1
fill ~64~29~28 ~64~29~32 minecraft:wooden_slab 9
fill ~64~30~28 ~64~30~32 minecraft:stonebrick 0
fill ~64~36~28 ~64~36~33 minecraft:wooden_slab 1
setblock ~65~9~28 minecraft:stained_glass 11
setblock ~65~11~28 minecraft:carpet 12
setblock ~65~16~28 minecraft:sea_lantern
setblock ~65~29~28 minecraft:stained_glass 3
setblock ~65~30~28 minecraft:sea_lantern
fill ~66~9~28 ~72~9~28 minecraft:sea_lantern
setblock ~66~10~28 minecraft:farmland 6
fill ~66~11~28 ~67~11~28 minecraft:wheat 7
fill ~66~16~28 ~72~16~28 minecraft:wooden_slab 1
setblock ~68~10~28 minecraft:farmland 4
setblock ~70~10~28 minecraft:farmland 1
setblock ~71~10~28 minecraft:farmland 5
fill ~71~11~28 ~72~11~28 minecraft:wheat 7
setblock ~72~10~28 minecraft:farmland 4
setblock ~73~9~28 minecraft:stained_glass 11
setblock ~73~11~28 minecraft:carpet 12
setblock ~73~16~28 minecraft:sea_lantern
setblock ~73~29~28 minecraft:stained_glass 3
setblock ~73~30~28 minecraft:sea_lantern
setblock ~74~9~28 minecraft:sea_lantern
setblock ~74~10~28 minecraft:farmland 4
fill ~74~11~28 ~74~11~32 minecraft:wheat 7
fill ~74~16~28 ~74~16~33 minecraft:wooden_slab 1
fill ~74~30~28 ~74~30~32 minecraft:stonebrick 0
fill ~74~36~28 ~74~36~33 minecraft:wooden_slab 1
fill ~75~9~28 ~75~9~32 minecraft:wooden_slab 9
fill ~75~10~28 ~77~10~28 minecraft:farmland 6
fill ~75~29~28 ~75~29~32 minecraft:wooden_slab 9
setblock ~78~10~28 minecraft:farmland 3
setblock ~79~10~28 minecraft:farmland 6
setblock ~82~21~28 minecraft:stone_block_slab 13
setblock ~82~22~28 minecraft:stained_hardened_clay 14
setblock ~82~23~28 minecraft:stone_block_slab 5
setblock ~83~1~28 minecraft:stone_block_slab 13
setblock ~83~2~28 minecraft:stained_hardened_clay 14
setblock ~83~3~28 minecraft:stone_block_slab 5
fill ~55~9~29 ~55~9~30 minecraft:wooden_slab 10
fill ~55~10~29 ~55~10~30 minecraft:sandstone 2
fill ~55~11~29 ~55~13~30 minecraft:glass
fill ~55~14~29 ~55~14~30 minecraft:sandstone 2
fill ~55~15~29 ~55~15~30 minecraft:wooden_slab 2
fill ~55~29~29 ~55~29~30 minecraft:wooden_slab 10
fill ~55~30~29 ~55~30~30 minecraft:sandstone 2
fill ~55~31~29 ~55~33~30 minecraft:glass
fill ~55~34~29 ~55~34~30 minecraft:sandstone 2
fill ~55~35~29 ~55~35~30 minecraft:wooden_slab 2
setblock ~56~1~29 minecraft:stone_block_slab 13
setblock ~56~2~29 minecraft:stained_hardened_clay 14
setblock ~56~3~29 minecraft:stone_block_slab 5
fill ~56~15~29 ~56~15~30 minecraft:stained_hardened_clay 14
fill ~56~35~29 ~56~35~30 minecraft:stained_hardened_clay 14
fill ~57~16~29 ~57~16~30 minecraft:wooden_slab 1
setblock ~57~21~29 minecraft:stone_block_slab 13
setblock ~57~22~29 minecraft:stained_hardened_clay 14
setblock ~57~23~29 minecraft:stone_block_slab 5
fill ~57~36~29 ~57~36~30 minecraft:wooden_slab 1
fill ~58~10~29 ~58~10~33 minecraft:stained_glass 14
fill ~58~16~29 ~58~16~30 minecraft:sea_lantern
fill ~58~30~29 ~58~30~33 minecraft:stained_glass 14
fill ~58~36~29 ~58~36~30 minecraft:sea_lantern
fill ~59~9~29 ~59~9~30 minecraft:wooden_slab 10
fill ~59~10~29 ~59~10~30 minecraft:sea_lantern
fill ~59~11~29 ~59~11~30 minecraft:wooden_slab 2
fill ~59~29~29 ~59~29~30 minecraft:wooden_slab 10
fill ~59~30~29 ~59~30~30 minecraft:sea_lantern
fill ~59~31~29 ~59~31~30 minecraft:wooden_slab 2
setblock ~60~10~29 minecraft:farmland 5
fill ~60~11~29 ~61~11~30 minecraft:wheat 7
setblock ~61~10~29 minecraft:farmland 4
setblock ~62~10~29 minecraft:farmland 3
setblock ~62~14~29 minecraft:sea_lantern
setblock ~62~15~29 minecraft:fence 2
setblock ~62~34~29 minecraft:sea_lantern
setblock ~62~35~29 minecraft:fence 2
fill ~63~10~29 ~63~10~30 minecraft:farmland 4
fill ~64~9~29 ~64~9~32 minecraft:wooden_slab 9
fill ~64~10~29 ~64~10~30 minecraft:farmland 6
setblock ~65~9~29 minecraft:sea_lantern
setblock ~65~10~29 minecraft:farmland 5
fill ~65~11~29 ~65~11~33 minecraft:wheat 7
fill ~65~16~29 ~65~16~34 minecraft:wooden_slab 1
fill ~65~29~29 ~65~29~33 minecraft:wooden_slab 9
fill ~65~30~29 ~65~30~33 minecraft:stonebrick 0
fill ~65~36~29 ~65~36~34 minecraft:wooden_slab 1
fill ~66~9~29 ~72~9~29 minecraft:stained_glass 11
fill ~66~11~29 ~68~11~29 minecraft:carpet 12
fill ~66~16~29 ~72~16~29 minecraft:sea_lantern
fill ~66~29~29 ~72~29~29 minecraft:stained_glass 3
fill ~66~30~29 ~72~30~29 minecraft:sea_lantern
setblock ~69~11~29 minecraft:wooden_slab 1
setblock ~69~14~29 minecraft:sea_lantern
setblock ~69~15~29 minecraft:fence 2
fill ~70~11~29 ~72~11~29 minecraft:carpet 12
setblock ~73~9~29 minecraft:sea_lantern
fill ~73~10~29 ~73~10~30 minecraft:farmland 4
fill ~73~11~29 ~73~11~33 minecraft:wheat 7
fill ~73~16~29 ~73~16~34 minecraft:wooden_slab 1
fill ~73~30~29 ~73~30~33 minecraft:stonebrick 0
fill ~73~36~29 ~73~36~34 minecraft:wooden_slab 1
fill ~74~9~29 ~74~9~32 minecraft:wooden_slab 9
setblock ~74~10~29 minecraft:farmland 6
fill ~74~29~29 ~74~29~32 minecraft:wooden_slab 9
fill ~75~10~29 ~76~10~29 minecraft:farmland 7
setblock ~76~14~29 minecraft:sea_lantern
setblock ~76~15~29 minecraft:fence 2
setblock ~76~34~29 minecraft:sea_lantern
setblock ~76~35~29 minecraft:fence 2
fill ~77~10~29 ~78~10~30 minecraft:farmland 5
fill ~77~11~29 ~78~11~30 minecraft:wheat 7
fill ~79~9~29 ~79~9~30 minecraft:wooden_slab 10
fill ~79~10~29 ~79~10~30 minecraft:sea_lantern
fill ~79~11~29 ~79~11~30 minecraft:wooden_slab 2
fill ~79~29~29 ~79~29~30 minecraft:wooden_slab 10
fill ~79~30~29 ~79~30~30 minecraft:sea_lantern
fill ~79~31~29 ~79~31~30 minecraft:wooden_slab 2
fill ~80~10~29 ~80~10~33 minecraft:stained_glass 14
fill ~80~16~29 ~80~16~30 minecraft:sea_lantern
fill ~80~30~29 ~80~30~33 minecraft:stained_glass 14
fill ~80~36~29 ~80~36~30 minecraft:sea_lantern
fill ~81~16~29 ~81~16~30 minecraft:wooden_slab 1
setblock ~81~21~29 minecraft:stone_block_slab 13
setblock ~81~22~29 minecraft:stained_hardened_clay 14
setblock ~81~23~29 minecraft:stone_block_slab 5
fill ~81~36~29 ~81~36~30 minecraft:wooden_slab 1
setblock ~82~1~29 minecraft:stone_block_slab 13
setblock ~82~2~29 minecraft:stained_hardened_clay 14
setblock ~82~3~29 minecraft:stone_block_slab 5
fill ~82~15~29 ~82~15~30 minecraft:stained_hardened_clay 14
fill ~82~35~29 ~82~35~30 minecraft:stained_hardened_clay 14
fill ~83~9~29 ~83~9~30 minecraft:wooden_slab 10
fill ~83~10~29 ~83~10~30 minecraft:sandstone 2
fill ~83~11~29 ~83~13~30 minecraft:glass
fill ~83~14~29 ~83~14~30 minecraft:sandstone 2
fill ~83~15~29 ~83~15~30 minecraft:wooden_slab 2
fill ~83~29~29 ~83~29~30 minecraft:wooden_slab 10
fill ~83~30~29 ~83~30~30 minecraft:sandstone 2
fill ~83~31~29 ~83~33~30 minecraft:glass
fill ~83~34~29 ~83~34~30 minecraft:sandstone 2
fill ~83~35~29 ~83~35~30 minecraft:wooden_slab 2
setblock ~57~1~30 minecraft:stone_block_slab 13
setblock ~57~2~30 minecraft:stained_hardened_clay 14
setblock ~57~3~30 minecraft:stone_block_slab 5
setblock ~58~21~30 minecraft:stone_block_slab 13
setblock ~58~22~30 minecraft:stained_hardened_clay 14
setblock ~58~23~30 minecraft:stone_block_slab 5
setblock ~60~10~30 minecraft:farmland 3
fill ~61~10~30 ~62~10~30 minecraft:farmland 5
fill ~65~9~30 ~65~9~33 minecraft:wooden_slab 9
setblock ~65~10~30 minecraft:farmland 2
fill ~66~9~30 ~72~9~30 minecraft:sea_lantern
setblock ~66~10~30 minecraft:farmland 5
fill ~66~11~30 ~68~11~33 minecraft:wheat 7
fill ~66~16~30 ~72~16~34 minecraft:wooden_slab 1
fill ~66~29~30 ~73~29~33 minecraft:wooden_slab 9
fill ~66~30~30 ~72~30~33 minecraft:stonebrick 0
fill ~66~36~30 ~72~36~34 minecraft:wooden_slab 1
fill ~67~10~30 ~68~10~30 minecraft:farmland 6
fill ~69~10~30 ~69~10~33 minecraft:planks 1
setblock ~70~10~30 minecraft:farmland 4
fill ~70~11~30 ~72~11~33 minecraft:wheat 7
setblock ~71~10~30 minecraft:farmland 6
setblock ~72~10~30 minecraft:farmland 4
fill ~73~9~30 ~73~9~33 minecraft:wooden_slab 9
setblock ~74~10~30 minecraft:farmland 7
setblock ~75~10~30 minecraft:farmland 6
fill ~76~10~30 ~76~10~31 minecraft:farmland 5
setblock ~80~21~30 minecraft:stone_block_slab 13
setblock ~80~22~30 minecraft:stained_hardened_clay 14
setblock ~80~23~30 minecraft:stone_block_slab 5
setblock ~81~1~30 minecraft:stone_block_slab 13
setblock ~81~2~30 minecraft:stained_hardened_clay 14
setblock ~81~3~30 minecraft:stone_block_slab 5
fill ~56~9~31 ~56~9~32 minecraft:wooden_slab 10
fill ~56~10~31 ~56~10~32 minecraft:sandstone 2
fill ~56~11~31 ~56~13~32 minecraft:glass
fill ~56~14~31 ~56~14~32 minecraft:sandstone 2
fill ~56~15~31 ~56~15~32 minecraft:wooden_slab 2
fill ~56~29~31 ~56~29~32 minecraft:wooden_slab 10
fill ~56~30~31 ~56~30~32 minecraft:sandstone 2
fill ~56~31~31 ~56~33~32 minecraft:glass
fill ~56~34~31 ~56~34~32 minecraft:sandstone 2
fill ~56~35~31 ~56~35~32 minecraft:wooden_slab 2
fill ~57~15~31 ~57~15~32 minecraft:stained_hardened_clay 14
fill ~57~35~31 ~57~35~32 minecraft:stained_hardened_clay 14
setblock ~58~1~31 minecraft:stone_block_slab 13
setblock ~58~2~31 minecraft:stained_hardened_clay 14
setblock ~58~3~31 minecraft:stone_block_slab 5
fill ~58~16~31 ~58~16~32 minecraft:wooden_slab 1
fill ~58~36~31 ~58~36~32 minecraft:wooden_slab 1
fill ~59~10~31 ~59~10~34 minecraft:stained_glass 14
fill ~59~16~31 ~59~16~32 minecraft:sea_lantern
setblock ~59~21~31 minecraft:stone_block_slab 13
setblock ~59~22~31 minecraft:stained_hardened_clay 14
setblock ~59~23~31 minecraft:stone_block_slab 5
fill ~59~30~31 ~59~30~34 minecraft:stained_glass 14
fill ~59~36~31 ~59~36~32 minecraft:sea_lantern
setblock ~60~9~31 minecraft:wooden_slab 10
setblock ~60~10~31 minecraft:sea_lantern
setblock ~60~11~31 minecraft:wooden_slab 2
setblock ~60~29~31 minecraft:wooden_slab 10
setblock ~60~30~31 minecraft:sea_lantern
setblock ~60~31~31 minecraft:wooden_slab 2
setblock ~61~10~31 minecraft:farmland 6
setblock ~61~11~31 minecraft:wheat 7
fill ~62~10~31 ~64~10~31 minecraft:farmland 3
setblock ~65~10~31 minecraft:farmland 6
fill ~66~9~31 ~72~9~33 minecraft:wooden_slab 9
setblock ~66~10~31 minecraft:farmland 4
setblock ~66~14~31 minecraft:sea_lantern
setblock ~66~15~31 minecraft:fence 2
setblock ~67~10~31 minecraft:farmland 6
setblock ~68~10~31 minecraft:farmland 7
setblock ~70~10~31 minecraft:farmland 5
fill ~71~10~31 ~71~10~32 minecraft:farmland 4
setblock ~72~10~31 minecraft:farmland 6
setblock ~72~14~31 minecraft:sea_lantern
setblock ~72~15~31 minecraft:fence 2
setblock ~73~10~31 minecraft:farmland 7
setblock ~74~10~31 minecraft:farmland 6
setblock ~75~10~31 minecraft:farmland 4
setblock ~77~10~31 minecraft:farmland 7
setblock ~77~11~31 minecraft:wheat 7
setblock ~78~9~31 minecraft:wooden_slab 10
setblock ~78~10~31 minecraft:sea_lantern
setblock ~78~11~31 minecraft:wooden_slab 2
setblock ~78~29~31 minecraft:wooden_slab 10
setblock ~78~30~31 minecraft:sea_lantern
setblock ~78~31~31 minecraft:wooden_slab 2
fill ~79~10~31 ~79~10~34 minecraft:stained_glass 14
fill ~79~16~31 ~79~16~32 minecraft:sea_lantern
setblock ~79~21~31 minecraft:stone_block_slab 13
setblock ~79~22~31 minecraft:stained_hardened_clay 14
setblock ~79~23~31 minecraft:stone_block_slab 5
fill ~79~30~31 ~79~30~34 minecraft:stained_glass 14
fill ~79~36~31 ~79~36~32 minecraft:sea_lantern
setblock ~80~1~31 minecraft:stone_block_slab 13
setblock ~80~2~31 minecraft:stained_hardened_clay 14
setblock ~80~3~31 minecraft:stone_block_slab 5
fill ~80~16~31 ~80~16~32 minecraft:wooden_slab 1
fill ~80~36~31 ~80~36~32 minecraft:wooden_slab 1
fill ~81~15~31 ~81~15~32 minecraft:stained_hardened_clay 14
fill ~81~35~31 ~81~35~32 minecraft:stained_hardened_clay 14
fill ~82~9~31 ~82~9~32 minecraft:wooden_slab 10
fill ~82~10~31 ~82~10~32 minecraft:sandstone 2
fill ~82~11~31 ~82~13~32 minecraft:glass
fill ~82~14~31 ~82~14~32 minecraft:sandstone 2
fill ~82~15~31 ~82~15~32 minecraft:wooden_slab 2
fill ~82~29~31 ~82~29~32 minecraft:wooden_slab 10
fill ~82~30~31 ~82~30~32 minecraft:sandstone 2
fill ~82~31~31 ~82~33~32 minecraft:glass
fill ~82~34~31 ~82~34~32 minecraft:sandstone 2
fill ~82~35~31 ~82~35~32 minecraft:wooden_slab 2
setblock ~59~1~32 minecraft:stone_block_slab 13
setblock ~59~2~32 minecraft:stained_hardened_clay 14
setblock ~59~3~32 minecraft:stone_block_slab 5
fill ~60~10~32 ~60~10~34 minecraft:stained_glass 14
setblock ~60~16~32 minecraft:sea_lantern
fill ~60~21~32 ~61~21~32 minecraft:stone_block_slab 13
fill ~60~22~32 ~61~22~32 minecraft:stained_hardened_clay 14
fill ~60~23~32 ~61~23~32 minecraft:stone_block_slab 5
fill ~60~30~32 ~60~30~34 minecraft:stained_glass 14
setblock ~60~36~32 minecraft:sea_lantern
fill ~61~9~32 ~62~9~32 minecraft:wooden_slab 10
fill ~61~10~32 ~62~10~32 minecraft:sea_lantern
fill ~61~11~32 ~62~11~32 minecraft:wooden_slab 2
fill ~61~29~32 ~62~29~32 minecraft:wooden_slab 10
fill ~61~30~32 ~62~30~32 minecraft:sea_lantern
fill ~61~31~32 ~62~31~32 minecraft:wooden_slab 2
setblock ~63~10~32 minecraft:farmland 5
fill ~64~10~32 ~65~10~32 minecraft:farmland 4
fill ~66~10~32 ~67~10~32 minecraft:farmland 3
setblock ~68~10~32 minecraft:farmland 5
setblock ~70~10~32 minecraft:farmland 6
setblock ~72~10~32 minecraft:farmland 5
fill ~73~10~32 ~73~10~33 minecraft:farmland 6
setblock ~74~10~32 minecraft:farmland 5
setblock ~75~10~32 minecraft:farmland 7
fill ~76~9~32 ~77~9~32 minecraft:wooden_slab 10
fill ~76~10~32 ~77~10~32 minecraft:sea_lantern
fill ~76~11~32 ~77~11~32 minecraft:wooden_slab 2
fill ~76~29~32 ~77~29~32 minecraft:wooden_slab 10
fill ~76~30~32 ~77~30~32 minecraft:sea_lantern
fill ~76~31~32 ~77~31~32 minecraft:wooden_slab 2
fill ~77~21~32 ~78~21~32 minecraft:stone_block_slab 13
fill ~77~22~32 ~78~22~32 minecraft:stained_hardened_clay 14
fill ~77~23~32 ~78~23~32 minecraft:stone_block_slab 5
fill ~78~10~32 ~78~10~34 minecraft:stained_glass 14
setblock ~78~16~32 minecraft:sea_lantern
fill ~78~30~32 ~78~30~34 minecraft:stained_glass 14
setblock ~78~36~32 minecraft:sea_lantern
setblock ~79~1~32 minecraft:stone_block_slab 13
setblock ~79~2~32 minecraft:stained_hardened_clay 14
setblock ~79~3~32 minecraft:stone_block_slab 5
setblock ~57~9~33 minecraft:wooden_slab 10
setblock ~57~10~33 minecraft:sandstone 2
fill ~57~11~33 ~57~13~33 minecraft:glass
setblock ~57~14~33 minecraft:sandstone 2
setblock ~57~15~33 minecraft:wooden_slab 2
setblock ~57~29~33 minecraft:wooden_slab 10
setblock ~57~30~33 minecraft:sandstone 2
fill ~57~31~33 ~57~33~33 minecraft:glass
setblock ~57~34~33 minecraft:sandstone 2
setblock ~57~35~33 minecraft:wooden_slab 2
setblock ~58~15~33 minecraft:stained_hardened_clay 14
setblock ~58~35~33 minecraft:stained_hardened_clay 14
fill ~59~16~33 ~60~16~33 minecraft:wooden_slab 1
fill ~59~36~33 ~60~36~33 minecraft:wooden_slab 1
fill ~60~1~33 ~61~1~33 minecraft:stone_block_slab 13
fill ~60~2~33 ~61~2~33 minecraft:stained_hardened_clay 14
fill ~60~3~33 ~61~3~33 minecraft:stone_block_slab 5
fill ~61~10~33 ~62~10~35 minecraft:stained_glass 14
fill ~61~16~33 ~62~16~33 minecraft:sea_lantern
fill ~61~30~33 ~62~30~35 minecraft:stained_glass 14
fill ~61~36~33 ~62~36~33 minecraft:sea_lantern
fill ~62~21~33 ~64~21~33 minecraft:stone_block_slab 13
fill ~62~22~33 ~64~22~33 minecraft:stained_hardened_clay 14
fill ~62~23~33 ~64~23~33 minecraft:stone_block_slab 5
fill ~63~9~33 ~64~9~33 minecraft:wooden_slab 10
fill ~63~10~33 ~64~10~33 minecraft:sea_lantern
fill ~63~11~33 ~64~11~33 minecraft:wooden_slab 2
fill ~63~29~33 ~64~29~33 minecraft:wooden_slab 10
fill ~63~30~33 ~64~30~33 minecraft:sea_lantern
fill ~63~31~33 ~64~31~33 minecraft:wooden_slab 2
setblock ~65~10~33 minecraft:farmland 7
setblock ~66~10~33 minecraft:farmland 6
fill ~67~10~33 ~68~10~33 minecraft:farmland 7
setblock ~70~10~33 minecraft:farmland 4
setblock ~71~10~33 minecraft:farmland 7
setblock ~72~10~33 minecraft:farmland 6
fill ~74~9~33 ~75~9~33 minecraft:wooden_slab 10
fill ~74~10~33 ~75~10~33 minecraft:sea_lantern
fill ~74~11~33 ~75~11~33 minecraft:wooden_slab 2
fill ~74~21~33 ~76~21~33 minecraft:stone_block_slab 13
fill ~74~22~33 ~76~22~33 minecraft:stained_hardened_clay 14
fill ~74~23~33 ~76~23~33 minecraft:stone_block_slab 5
fill ~74~29~33 ~75~29~33 minecraft:wooden_slab 10
fill ~74~30~33 ~75~30~33 minecraft:sea_lantern
fill ~74~31~33 ~75~31~33 minecraft:wooden_slab 2
fill ~76~10~33 ~77~10~35 minecraft:stained_glass 14
fill ~76~16~33 ~77~16~33 minecraft:sea_lantern
fill ~76~30~33 ~77~30~35 minecraft:stained_glass 14
fill ~76~36~33 ~77~36~33 minecraft:sea_lantern
fill ~77~1~33 ~78~1~33 minecraft:stone_block_slab 13
fill ~77~2~33 ~78~2~33 minecraft:stained_hardened_clay 14
fill ~77~3~33 ~78~3~33 minecraft:stone_block_slab 5
fill ~78~16~33 ~79~16~33 minecraft:wooden_slab 1
fill ~78~36~33 ~79~36~33 minecraft:wooden_slab 1
setblock ~80~15~33 minecraft:stained_hardened_clay 14
setblock ~80~35~33 minecraft:stained_hardened_clay 14
setblock ~81~9~33 minecraft:wooden_slab 10
setblock ~81~10~33 minecraft:sandstone 2
fill ~81~11~33 ~81~13~33 minecraft:glass
setblock ~81~14~33 minecraft:sandstone 2
setblock ~81~15~33 minecraft:wooden_slab 2
setblock ~81~29~33 minecraft:wooden_slab 10
setblock ~81~30~33 minecraft:sandstone 2
fill ~81~31~33 ~81~33~33 minecraft:glass
setblock ~81~34~33 minecraft:sandstone 2
setblock ~81~35~33 minecraft:wooden_slab 2
setblock ~58~9~34 minecraft:wooden_slab 10
setblock ~58~10~34 minecraft:sandstone 2
fill ~58~11~34 ~58~13~34 minecraft:glass
setblock ~58~14~34 minecraft:sandstone 2
setblock ~58~15~34 minecraft:wooden_slab 2
setblock ~58~29~34 minecraft:wooden_slab 10
setblock ~58~30~34 minecraft:sandstone 2
fill ~58~31~34 ~58~33~34 minecraft:glass
setblock ~58~34~34 minecraft:sandstone 2
setblock ~58~35~34 minecraft:wooden_slab 2
fill ~59~15~34 ~60~15~34 minecraft:stained_hardened_clay 14
fill ~59~35~34 ~60~35~34 minecraft:stained_hardened_clay 14
fill ~61~16~34 ~62~16~34 minecraft:wooden_slab 1
fill ~61~36~34 ~62~36~34 minecraft:wooden_slab 1
fill ~62~1~34 ~64~1~34 minecraft:stone_block_slab 13
fill ~62~2~34 ~64~2~34 minecraft:stained_hardened_clay 14
fill ~62~3~34 ~64~3~34 minecraft:stone_block_slab 5
fill ~63~10~34 ~64~10~36 minecraft:stained_glass 14
fill ~63~16~34 ~64~16~34 minecraft:sea_lantern
fill ~63~30~34 ~64~30~36 minecraft:stained_glass 14
fill ~63~36~34 ~64~36~34 minecraft:sea_lantern
fill ~65~9~34 ~73~9~34 minecraft:wooden_slab 10
fill ~65~10~34 ~73~10~34 minecraft:sea_lantern
fill ~65~11~34 ~73~11~34 minecraft:wooden_slab 2
fill ~65~21~34 ~73~21~34 minecraft:stone_block_slab 13
fill ~65~22~34 ~73~22~34 minecraft:stained_hardened_clay 14
fill ~65~23~34 ~68~23~34 minecraft:stone_block_slab 5
fill ~65~29~34 ~73~29~34 minecraft:wooden_slab 10
fill ~65~30~34 ~73~30~34 minecraft:sea_lantern
fill ~65~31~34 ~73~31~34 minecraft:wooden_slab 2
fill ~70~23~34 ~73~23~34 minecraft:stone_block_slab 5
fill ~74~1~34 ~76~1~34 minecraft:stone_block_slab 13
fill ~74~2~34 ~76~2~34 minecraft:stained_hardened_clay 14
fill ~74~3~34 ~76~3~34 minecraft:stone_block_slab 5
fill ~74~10~34 ~75~10~36 minecraft:stained_glass 14
fill ~74~16~34 ~75~16~34 minecraft:sea_lantern
fill ~74~30~34 ~75~30~36 minecraft:stained_glass 14
fill ~74~36~34 ~75~36~34 minecraft:sea_lantern
fill ~76~16~34 ~77~16~34 minecraft:wooden_slab 1
fill ~76~36~34 ~77~36~34 minecraft:wooden_slab 1
fill ~78~15~34 ~79~15~34 minecraft:stained_hardened_clay 14
fill ~78~35~34 ~79~35~34 minecraft:stained_hardened_clay 14
setblock ~80~9~34 minecraft:wooden_slab 10
setblock ~80~10~34 minecraft:sandstone 2
fill ~80~11~34 ~80~13~34 minecraft:glass
setblock ~80~14~34 minecraft:sandstone 2
setblock ~80~15~34 minecraft:wooden_slab 2
setblock ~80~29~34 minecraft:wooden_slab 10
setblock ~80~30~34 minecraft:sandstone 2
fill ~80~31~34 ~80~33~34 minecraft:glass
setblock ~80~34~34 minecraft:sandstone 2
setblock ~80~35~34 minecraft:wooden_slab 2
fill ~59~9~35 ~60~9~35 minecraft:wooden_slab 10
fill ~59~10~35 ~60~10~35 minecraft:sandstone 2
fill ~59~11~35 ~60~13~35 minecraft:glass
fill ~59~14~35 ~60~14~35 minecraft:sandstone 2
fill ~59~15~35 ~60~15~35 minecraft:wooden_slab 2
fill ~59~29~35 ~60~29~35 minecraft:wooden_slab 10
fill ~59~30~35 ~60~30~35 minecraft:sandstone 2
fill ~59~31~35 ~60~33~35 minecraft:glass
fill ~59~34~35 ~60~34~35 minecraft:sandstone 2
fill ~59~35~35 ~60~35~35 minecraft:wooden_slab 2
fill ~61~15~35 ~62~15~35 minecraft:stained_hardened_clay 14
fill ~61~35~35 ~62~35~35 minecraft:stained_hardened_clay 14
fill ~63~16~35 ~64~16~35 minecraft:wooden_slab 1
fill ~63~36~35 ~64~36~35 minecraft:wooden_slab 1
fill ~65~1~35 ~73~1~35 minecraft:stone_block_slab 13
fill ~65~2~35 ~73~2~35 minecraft:stained_hardened_clay 14
fill ~65~3~35 ~68~3~35 minecraft:stone_block_slab 5
fill ~65~10~35 ~73~10~36 minecraft:stained_glass 14
fill ~65~16~35 ~73~16~35 minecraft:sea_lantern
fill ~65~30~35 ~73~30~37 minecraft:stained_glass 14
fill ~65~36~35 ~73~36~35 minecraft:sea_lantern
fill ~68~22~35 ~70~22~35 minecraft:stone_brick_stairs 7
fill ~68~23~35 ~70~23~35 minecraft:stone_brick_stairs 2
fill ~70~3~35 ~73~3~35 minecraft:stone_block_slab 5
fill ~74~16~35 ~75~16~35 minecraft:wooden_slab 1
fill ~74~36~35 ~75~36~35 minecraft:wooden_slab 1
fill ~76~15~35 ~77~15~35 minecraft:stained_hardened_clay 14
fill ~76~35~35 ~77~35~35 minecraft:stained_hardened_clay 14
fill ~78~9~35 ~79~9~35 minecraft:wooden_slab 10
fill ~78~10~35 ~79~10~35 minecraft:sandstone 2
fill ~78~11~35 ~79~13~35 minecraft:glass
fill ~78~14~35 ~79~14~35 minecraft:sandstone 2
fill ~78~15~35 ~79~15~35 minecraft:wooden_slab 2
fill ~78~29~35 ~79~29~35 minecraft:wooden_slab 10
fill ~78~30~35 ~79~30~35 minecraft:sandstone 2
fill ~78~31~35 ~79~33~35 minecraft:glass
fill ~78~34~35 ~79~34~35 minecraft:sandstone 2
fill ~78~35~35 ~79~35~35 minecraft:wooden_slab 2
fill ~61~9~36 ~62~9~36 minecraft:wooden_slab 10
fill ~61~10~36 ~62~10~36 minecraft:sandstone 2
fill ~61~11~36 ~62~13~36 minecraft:glass
fill ~61~14~36 ~62~14~36 minecraft:sandstone 2
fill ~61~15~36 ~62~15~36 minecraft:wooden_slab 2
fill ~61~29~36 ~62~29~36 minecraft:wooden_slab 10
fill ~61~30~36 ~62~30~36 minecraft:sandstone 2
fill ~61~31~36 ~62~33~36 minecraft:glass
fill ~61~34~36 ~62~34~36 minecraft:sandstone 2
fill ~61~35~36 ~62~35~36 minecraft:wooden_slab 2
fill ~63~15~36 ~64~15~36 minecraft:stained_hardened_clay 14
fill ~63~35~36 ~64~35~36 minecraft:stained_hardened_clay 14
fill ~65~16~36 ~73~16~36 minecraft:wooden_slab 1
fill ~65~36~36 ~73~36~36 minecraft:wooden_slab 1
fill ~68~3~36 ~70~3~36 minecraft:stonebrick 0
fill ~68~23~36 ~70~23~36 minecraft:stonebrick 0
fill ~74~15~36 ~75~15~36 minecraft:stained_hardened_clay 14
fill ~74~35~36 ~75~35~36 minecraft:stained_hardened_clay 14
fill ~76~9~36 ~77~9~36 minecraft:wooden_slab 10
fill ~76~10~36 ~77~10~36 minecraft:sandstone 2
fill ~76~11~36 ~77~13~36 minecraft:glass
fill ~76~14~36 ~77~14~36 minecraft:sandstone 2
fill ~76~15~36 ~77~15~36 minecraft:wooden_slab 2
fill ~76~29~36 ~77~29~36 minecraft:wooden_slab 10
fill ~76~30~36 ~77~30~36 minecraft:sandstone 2
fill ~76~31~36 ~77~33~36 minecraft:glass
fill ~76~34~36 ~77~34~36 minecraft:sandstone 2
fill ~76~35~36 ~77~35~36 minecraft:wooden_slab 2
fill ~63~9~37 ~64~9~37 minecraft:wooden_slab 10
fill ~63~10~37 ~64~10~37 minecraft:sandstone 2
fill ~63~11~37 ~64~13~37 minecraft:glass
fill ~63~14~37 ~64~14~37 minecraft:sandstone 2
fill ~63~15~37 ~64~15~37 minecraft:wooden_slab 2
fill ~63~29~37 ~64~29~37 minecraft:wooden_slab 10
fill ~63~30~37 ~64~30~37 minecraft:sandstone 2
fill ~63~31~37 ~64~33~37 minecraft:glass
fill ~63~34~37 ~64~34~37 minecraft:sandstone 2
fill ~63~35~37 ~64~35~37 minecraft:wooden_slab 2
fill ~65~10~37 ~68~10~37 minecraft:stained_glass 14
fill ~65~15~37 ~73~15~37 minecraft:stained_hardened_clay 14
fill ~65~35~37 ~73~35~37 minecraft:stained_hardened_clay 14
fill ~68~3~37 ~70~3~37 minecraft:stone_brick_stairs 7
fill ~68~4~37 ~70~4~37 minecraft:stone_brick_stairs 2
fill ~68~23~37 ~70~23~37 minecraft:stone_brick_stairs 7
fill ~68~24~37 ~70~24~37 minecraft:stone_brick_stairs 2
setblock ~69~10~37 minecraft:redstone_lamp
setblock ~69~11~37 minecraft:wooden_pressure_plate 0
fill ~70~10~37 ~73~10~37 minecraft:stained_glass 14
fill ~74~9~37 ~75~9~37 minecraft:wooden_slab 10
fill ~74~10~37 ~75~10~37 minecraft:sandstone 2
fill ~74~11~37 ~75~13~37 minecraft:glass
fill ~74~14~37 ~75~14~37 minecraft:sandstone 2
fill ~74~15~37 ~75~15~37 minecraft:wooden_slab 2
fill ~74~29~37 ~75~29~37 minecraft:wooden_slab 10
fill ~74~30~37 ~75~30~37 minecraft:sandstone 2
fill ~74~31~37 ~75~33~37 minecraft:glass
fill ~74~34~37 ~75~34~37 minecraft:sandstone 2
fill ~74~35~37 ~75~35~37 minecraft:wooden_slab 2
fill ~65~9~38 ~73~9~38 minecraft:wooden_slab 10
fill ~65~10~38 ~73~10~38 minecraft:sandstone 2
fill ~65~11~38 ~67~13~38 minecraft:glass
fill ~65~14~38 ~73~14~38 minecraft:sandstone 2
fill ~65~15~38 ~73~15~38 minecraft:wooden_slab 2
fill ~65~29~38 ~73~29~38 minecraft:wooden_slab 10
fill ~65~30~38 ~73~30~38 minecraft:sandstone 2
fill ~65~31~38 ~67~33~38 minecraft:glass
fill ~65~34~38 ~73~34~38 minecraft:sandstone 2
fill ~65~35~38 ~73~35~38 minecraft:wooden_slab 2
fill ~68~4~38 ~70~4~38 minecraft:stonebrick 0
fill ~68~11~38 ~68~13~38 minecraft:stained_glass 15
fill ~68~24~38 ~70~24~38 minecraft:stonebrick 0
fill ~68~31~38 ~68~33~38 minecraft:stained_glass 14
setblock ~69~11~38 minecraft:dark_oak_door 3
fill ~69~13~38 ~70~13~38 minecraft:stained_glass 15
setblock ~69~31~38 minecraft:dark_oak_door 3
fill ~69~33~38 ~70~33~38 minecraft:stained_glass 14
fill ~70~11~38 ~70~12~38 minecraft:stained_glass 15
fill ~70~31~38 ~70~32~38 minecraft:stained_glass 14
fill ~71~11~38 ~73~13~38 minecraft:glass
fill ~71~31~38 ~73~33~38 minecraft:glass
fill ~68~4~39 ~70~4~39 minecraft:stone_brick_stairs 7
fill ~68~5~39 ~70~5~39 minecraft:stone_brick_stairs 2
fill ~68~9~39 ~70~9~39 minecraft:stone_brick_stairs 6
fill ~68~10~39 ~70~10~39 minecraft:stone_brick_stairs 3
fill ~68~24~39 ~70~24~39 minecraft:stone_brick_stairs 7
fill ~68~25~39 ~70~25~39 minecraft:stone_brick_stairs 2
fill ~68~29~39 ~70~29~39 minecraft:stone_brick_stairs 6
fill ~68~30~39 ~70~30~39 minecraft:stone_brick_stairs 3
fill ~68~5~40 ~70~5~40 minecraft:stonebrick 0
fill ~68~9~40 ~70~9~40 minecraft:stonebrick 0
fill ~68~25~40 ~70~25~40 minecraft:stonebrick 0
fill ~68~29~40 ~70~29~40 minecraft:stonebrick 0
fill ~68~5~41 ~70~5~41 minecraft:stone_brick_stairs 7
fill ~68~6~41 ~70~6~41 minecraft:stone_brick_stairs 2
fill ~68~8~41 ~70~8~41 minecraft:stone_brick_stairs 6
fill ~68~9~41 ~70~9~41 minecraft:stone_brick_stairs 3
fill ~68~25~41 ~70~25~41 minecraft:stone_brick_stairs 7
fill ~68~26~41 ~70~26~41 minecraft:stone_brick_stairs 2
fill ~68~28~41 ~70~28~41 minecraft:stone_brick_stairs 6
fill ~68~29~41 ~70~29~41 minecraft:stone_brick_stairs 3
fill ~68~6~42 ~70~8~42 minecraft:stonebrick 0
fill ~68~26~42 ~70~28~42 minecraft:stonebrick 0
fill ~64~6~43 ~67~6~43 minecraft:wooden_slab 10
fill ~64~7~43 ~74~7~44 minecraft:sandstone 2
fill ~64~8~43 ~67~8~43 minecraft:wooden_slab 2
fill ~64~26~43 ~67~26~43 minecraft:wooden_slab 10
fill ~64~27~43 ~74~27~43 minecraft:sandstone 2
fill ~64~28~43 ~67~28~43 minecraft:wooden_slab 2
fill ~68~6~43 ~70~6~43 minecraft:stone_brick_stairs 7
fill ~68~8~43 ~70~8~43 minecraft:stone_brick_stairs 3
fill ~68~26~43 ~70~26~43 minecraft:stone_brick_stairs 7
fill ~68~28~43 ~70~28~43 minecraft:stone_brick_stairs 3
fill ~71~6~43 ~74~6~43 minecraft:wooden_slab 10
fill ~71~8~43 ~74~8~43 minecraft:wooden_slab 2
fill ~71~26~43 ~74~26~43 minecraft:wooden_slab 10
fill ~71~28~43 ~74~28~43 minecraft:wooden_slab 2
fill ~61~6~44 ~63~6~44 minecraft:wooden_slab 10
fill ~61~7~44 ~63~7~45 minecraft:sandstone 2
fill ~61~8~44 ~63~8~44 minecraft:wooden_slab 2
fill ~61~26~44 ~63~26~44 minecraft:wooden_slab 10
fill ~61~27~44 ~63~27~44 minecraft:sandstone 2
fill ~61~28~44 ~63~28~44 minecraft:wooden_slab 2
fill ~64~27~44 ~74~27~44 minecraft:stained_glass 11
fill ~75~6~44 ~77~6~44 minecraft:wooden_slab 10
fill ~75~7~44 ~77~7~45 minecraft:sandstone 2
fill ~75~8~44 ~77~8~44 minecraft:wooden_slab 2
fill ~75~26~44 ~77~26~44 minecraft:wooden_slab 10
fill ~75~27~44 ~77~27~44 minecraft:sandstone 2
fill ~75~28~44 ~77~28~44 minecraft:wooden_slab 2
fill ~58~6~45 ~60~6~45 minecraft:wooden_slab 10
fill ~58~7~45 ~60~7~46 minecraft:sandstone 2
fill ~58~8~45 ~60~8~45 minecraft:wooden_slab 2
fill ~58~26~45 ~60~26~45 minecraft:wooden_slab 10
fill ~58~27~45 ~60~27~45 minecraft:sandstone 2
fill ~58~28~45 ~60~28~45 minecraft:wooden_slab 2
fill ~61~27~45 ~63~27~45 minecraft:stained_glass 11
fill ~64~7~45 ~74~7~45 minecraft:sea_lantern
fill ~64~27~45 ~74~27~45 minecraft:sea_lantern
fill ~75~27~45 ~77~27~45 minecraft:stained_glass 11
fill ~78~6~45 ~80~6~45 minecraft:wooden_slab 10
fill ~78~7~45 ~80~7~46 minecraft:sandstone 2
fill ~78~8~45 ~80~8~45 minecraft:wooden_slab 2
fill ~78~26~45 ~80~26~45 minecraft:wooden_slab 10
fill ~78~27~45 ~80~27~45 minecraft:sandstone 2
fill ~78~28~45 ~80~28~45 minecraft:wooden_slab 2
fill ~56~6~46 ~57~6~46 minecraft:wooden_slab 10
fill ~56~7~46 ~57~7~47 minecraft:sandstone 2
fill ~56~8~46 ~57~8~46 minecraft:wooden_slab 2
fill ~56~26~46 ~57~26~46 minecraft:wooden_slab 10
fill ~56~27~46 ~57~27~46 minecraft:sandstone 2
fill ~56~28~46 ~57~28~46 minecraft:wooden_slab 2
fill ~58~27~46 ~60~27~46 minecraft:stained_glass 11
fill ~61~7~46 ~63~7~46 minecraft:sea_lantern
fill ~61~27~46 ~63~27~46 minecraft:sea_lantern
fill ~64~7~46 ~74~7~47 minecraft:sandstone 2
fill ~64~27~46 ~74~27~46 minecraft:stained_glass 11
fill ~75~7~46 ~77~7~46 minecraft:sea_lantern
fill ~75~27~46 ~77~27~46 minecraft:sea_lantern
fill ~78~27~46 ~80~27~46 minecraft:stained_glass 11
fill ~81~6~46 ~82~6~46 minecraft:wooden_slab 10
fill ~81~7~46 ~82~7~47 minecraft:sandstone 2
fill ~81~8~46 ~82~8~46 minecraft:wooden_slab 2
fill ~81~26~46 ~82~26~46 minecraft:wooden_slab 10
fill ~81~27~46 ~82~27~46 minecraft:sandstone 2
fill ~81~28~46 ~82~28~46 minecraft:wooden_slab 2
setblock ~55~6~47 minecraft:wooden_slab 10
fill ~55~7~47 ~55~7~48 minecraft:sandstone 2
setblock ~55~8~47 minecraft:wooden_slab 2
setblock ~55~26~47 minecraft:wooden_slab 10
setblock ~55~27~47 minecraft:sandstone 2
setblock ~55~28~47 minecraft:wooden_slab 2
fill ~56~27~47 ~57~27~47 minecraft:stained_glass 11
fill ~58~7~47 ~60~7~47 minecraft:sea_lantern
fill ~58~27~47 ~60~27~47 minecraft:sea_lantern
fill ~61~7~47 ~63~7~48 minecraft:sandstone 2
fill ~61~27~47 ~63~27~47 minecraft:stained_glass 11
fill ~64~6~47 ~74~6~47 minecraft:wooden_slab 10
fill ~64~8~47 ~67~8~47 minecraft:wooden_slab 2
fill ~64~26~47 ~74~26~47 minecraft:wooden_slab 10
fill ~64~27~47 ~74~27~47 minecraft:sandstone 2
fill ~64~28~47 ~67~28~47 minecraft:wooden_slab 2
fill ~71~8~47 ~74~8~47 minecraft:wooden_slab 2
fill ~71~28~47 ~74~28~47 minecraft:wooden_slab 2
fill ~75~7~47 ~77~7~48 minecraft:sandstone 2
fill ~75~27~47 ~77~27~47 minecraft:stained_glass 11
fill ~78~7~47 ~80~7~47 minecraft:sea_lantern
fill ~78~27~47 ~80~27~47 minecraft:sea_lantern
fill ~81~27~47 ~82~27~47 minecraft:stained_glass 11
setblock ~83~6~47 minecraft:wooden_slab 10
fill ~83~7~47 ~83~7~48 minecraft:sandstone 2
setblock ~83~8~47 minecraft:wooden_slab 2
setblock ~83~26~47 minecraft:wooden_slab 10
setblock ~83~27~47 minecraft:sandstone 2
setblock ~83~28~47 minecraft:wooden_slab 2
fill ~53~6~48 ~54~6~48 minecraft:wooden_slab 10
fill ~53~7~48 ~54~7~49 minecraft:sandstone 2
fill ~53~8~48 ~54~8~48 minecraft:wooden_slab 2
fill ~53~26~48 ~54~26~48 minecraft:wooden_slab 10
fill ~53~27~48 ~54~27~48 minecraft:sandstone 2
fill ~53~28~48 ~54~28~48 minecraft:wooden_slab 2
setblock ~55~27~48 minecraft:stained_glass 11
fill ~56~7~48 ~57~7~48 minecraft:sea_lantern
fill ~56~27~48 ~57~27~48 minecraft:sea_lantern
fill ~58~7~48 ~60~7~49 minecraft:sandstone 2
fill ~58~27~48 ~60~27~48 minecraft:stained_glass 11
fill ~61~6~48 ~63~6~48 minecraft:wooden_slab 10
fill ~61~8~48 ~63~8~48 minecraft:wooden_slab 2
fill ~61~26~48 ~63~26~48 minecraft:wooden_slab 10
fill ~61~27~48 ~63~27~48 minecraft:sandstone 2
fill ~61~28~48 ~63~28~48 minecraft:wooden_slab 2
fill ~67~7~48 ~67~7~52 minecraft:wooden_slab 10
fill ~67~8~48 ~67~8~52 minecraft:fence 2
fill ~67~27~48 ~67~27~55 minecraft:wooden_slab 10
fill ~67~28~48 ~67~28~55 minecraft:fence 2
fill ~68~7~48 ~70~7~52 minecraft:stained_glass 3
fill ~68~27~48 ~70~27~56 minecraft:stained_glass 3
fill ~71~7~48 ~71~7~52 minecraft:wooden_slab 10
fill ~71~8~48 ~71~8~52 minecraft:fence 2
fill ~71~27~48 ~71~27~55 minecraft:wooden_slab 10
fill ~71~28~48 ~71~28~55 minecraft:fence 2
fill ~75~6~48 ~77~6~48 minecraft:wooden_slab 10
fill ~75~8~48 ~77~8~48 minecraft:wooden_slab 2
fill ~75~26~48 ~77~26~48 minecraft:wooden_slab 10
fill ~75~27~48 ~77~27~48 minecraft:sandstone 2
fill ~75~28~48 ~77~28~48 minecraft:wooden_slab 2
fill ~78~7~48 ~80~7~49 minecraft:sandstone 2
fill ~78~27~48 ~80~27~48 minecraft:stained_glass 11
fill ~81~7~48 ~82~7~48 minecraft:sea_lantern
fill ~81~27~48 ~82~27~48 minecraft:sea_lantern
setblock ~83~27~48 minecraft:stained_glass 11
fill ~84~6~48 ~85~6~48 minecraft:wooden_slab 10
fill ~84~7~48 ~85~7~49 minecraft:sandstone 2
fill ~84~8~48 ~85~8~48 minecraft:wooden_slab 2
fill ~84~26~48 ~85~26~48 minecraft:wooden_slab 10
fill ~84~27~48 ~85~27~48 minecraft:sandstone 2
fill ~84~28~48 ~85~28~48 minecraft:wooden_slab 2
setblock ~52~6~49 minecraft:wooden_slab 10
fill ~52~7~49 ~52~7~50 minecraft:sandstone 2
setblock ~52~8~49 minecraft:wooden_slab 2
setblock ~52~26~49 minecraft:wooden_slab 10
setblock ~52~27~49 minecraft:sandstone 2
setblock ~52~28~49 minecraft:wooden_slab 2
fill ~53~27~49 ~54~27~49 minecraft:stained_glass 11
setblock ~55~7~49 minecraft:sea_lantern
setblock ~55~27~49 minecraft:sea_lantern
fill ~56~7~49 ~57~7~50 minecraft:sandstone 2
fill ~56~27~49 ~57~27~49 minecraft:stained_glass 11
fill ~58~6~49 ~60~6~49 minecraft:wooden_slab 10
fill ~58~8~49 ~60~8~49 minecraft:wooden_slab 2
fill ~58~26~49 ~60~26~49 minecraft:wooden_slab 10
fill ~58~27~49 ~60~27~49 minecraft:sandstone 2
fill ~58~28~49 ~60~28~49 minecraft:wooden_slab 2
fill ~78~6~49 ~80~6~49 minecraft:wooden_slab 10
fill ~78~8~49 ~80~8~49 minecraft:wooden_slab 2
fill ~78~26~49 ~80~26~49 minecraft:wooden_slab 10
fill ~78~27~49 ~80~27~49 minecraft:sandstone 2
fill ~78~28~49 ~80~28~49 minecraft:wooden_slab 2
fill ~81~7~49 ~82~7~50 minecraft:sandstone 2
fill ~81~27~49 ~82~27~49 minecraft:stained_glass 11
setblock ~83~7~49 minecraft:sea_lantern
setblock ~83~27~49 minecraft:sea_lantern
fill ~84~27~49 ~85~27~49 minecraft:stained_glass 11
setblock ~86~6~49 minecraft:wooden_slab 10
fill ~86~7~49 ~86~7~50 minecraft:sandstone 2
setblock ~86~8~49 minecraft:wooden_slab 2
setblock ~86~26~49 minecraft:wooden_slab 10
setblock ~86~27~49 minecraft:sandstone 2
setblock ~86~28~49 minecraft:wooden_slab 2
setblock ~51~6~50 minecraft:wooden_slab 10
fill ~51~7~50 ~51~7~51 minecraft:sandstone 2
setblock ~51~8~50 minecraft:wooden_slab 2
setblock ~51~26~50 minecraft:wooden_slab 10
setblock ~51~27~50 minecraft:sandstone 2
setblock ~51~28~50 minecraft:wooden_slab 2
setblock ~52~27~50 minecraft:stained_glass 11
fill ~53~7~50 ~54~7~50 minecraft:sea_lantern
fill ~53~27~50 ~54~27~50 minecraft:sea_lantern
fill ~55~7~50 ~55~7~51 minecraft:sandstone 2
setblock ~55~27~50 minecraft:stained_glass 11
fill ~56~6~50 ~57~6~50 minecraft:wooden_slab 10
fill ~56~8~50 ~57~8~50 minecraft:wooden_slab 2
fill ~56~26~50 ~57~26~50 minecraft:wooden_slab 10
fill ~56~27~50 ~57~27~50 minecraft:sandstone 2
fill ~56~28~50 ~57~28~50 minecraft:wooden_slab 2
fill ~81~6~50 ~82~6~50 minecraft:wooden_slab 10
fill ~81~8~50 ~82~8~50 minecraft:wooden_slab 2
fill ~81~26~50 ~82~26~50 minecraft:wooden_slab 10
fill ~81~27~50 ~82~27~50 minecraft:sandstone 2
fill ~81~28~50 ~82~28~50 minecraft:wooden_slab 2
fill ~83~7~50 ~83~7~51 minecraft:sandstone 2
setblock ~83~27~50 minecraft:stained_glass 11
fill ~84~7~50 ~85~7~50 minecraft:sea_lantern
fill ~84~27~50 ~85~27~50 minecraft:sea_lantern
setblock ~86~27~50 minecraft:stained_glass 11
setblock ~87~6~50 minecraft:wooden_slab 10
fill ~87~7~50 ~87~7~51 minecraft:sandstone 2
setblock ~87~8~50 minecraft:wooden_slab 2
setblock ~87~26~50 minecraft:wooden_slab 10
setblock ~87~27~50 minecraft:sandstone 2
setblock ~87~28~50 minecraft:wooden_slab 2
setblock ~50~6~51 minecraft:wooden_slab 10
fill ~50~7~51 ~50~7~52 minecraft:sandstone 2
setblock ~50~8~51 minecraft:wooden_slab 2
setblock ~50~26~51 minecraft:wooden_slab 10
setblock ~50~27~51 minecraft:sandstone 2
setblock ~50~28~51 minecraft:wooden_slab 2
setblock ~51~27~51 minecraft:stained_glass 11
setblock ~52~7~51 minecraft:sea_lantern
setblock ~52~27~51 minecraft:sea_lantern
fill ~53~7~51 ~54~7~52 minecraft:sandstone 2
fill ~53~27~51 ~54~27~51 minecraft:stained_glass 11
setblock ~55~6~51 minecraft:wooden_slab 10
setblock ~55~8~51 minecraft:wooden_slab 2
setblock ~55~26~51 minecraft:wooden_slab 10
setblock ~55~27~51 minecraft:sandstone 2
setblock ~55~28~51 minecraft:wooden_slab 2
setblock ~83~6~51 minecraft:wooden_slab 10
setblock ~83~8~51 minecraft:wooden_slab 2
setblock ~83~26~51 minecraft:wooden_slab 10
setblock ~83~27~51 minecraft:sandstone 2
setblock ~83~28~51 minecraft:wooden_slab 2
fill ~84~7~51 ~85~7~52 minecraft:sandstone 2
fill ~84~27~51 ~85~27~51 minecraft:stained_glass 11
setblock ~86~7~51 minecraft:sea_lantern
setblock ~86~27~51 minecraft:sea_lantern
setblock ~87~27~51 minecraft:stained_glass 11
setblock ~88~6~51 minecraft:wooden_slab 10
fill ~88~7~51 ~88~7~52 minecraft:sandstone 2
setblock ~88~8~51 minecraft:wooden_slab 2
setblock ~88~26~51 minecraft:wooden_slab 10
setblock ~88~27~51 minecraft:sandstone 2
setblock ~88~28~51 minecraft:wooden_slab 2
fill ~13~21~52 ~21~21~52 minecraft:stone_block_slab 13
fill ~13~22~52 ~21~22~52 minecraft:stained_hardened_clay 14
fill ~13~23~52 ~21~23~52 minecraft:stone_block_slab 5
fill ~14~1~52 ~22~1~52 minecraft:stone_block_slab 13
fill ~14~2~52 ~22~2~52 minecraft:stained_hardened_clay 14
fill ~14~3~52 ~22~3~52 minecraft:stone_block_slab 5
setblock ~49~6~52 minecraft:wooden_slab 10
fill ~49~7~52 ~49~7~54 minecraft:sandstone 2
setblock ~49~8~52 minecraft:wooden_slab 2
setblock ~49~26~52 minecraft:wooden_slab 10
setblock ~49~27~52 minecraft:sandstone 2
setblock ~49~28~52 minecraft:wooden_slab 2
setblock ~50~27~52 minecraft:stained_glass 11
setblock ~51~7~52 minecraft:sea_lantern
setblock ~51~27~52 minecraft:sea_lantern
fill ~52~7~52 ~52~7~54 minecraft:sandstone 2
setblock ~52~27~52 minecraft:stained_glass 11
fill ~53~6~52 ~54~6~52 minecraft:wooden_slab 10
fill ~53~8~52 ~54~8~52 minecraft:wooden_slab 2
fill ~53~26~52 ~54~26~52 minecraft:wooden_slab 10
fill ~53~27~52 ~54~27~52 minecraft:sandstone 2
fill ~53~28~52 ~54~28~52 minecraft:wooden_slab 2
fill ~84~6~52 ~85~6~52 minecraft:wooden_slab 10
fill ~84~8~52 ~85~8~52 minecraft:wooden_slab 2
fill ~84~26~52 ~85~26~52 minecraft:wooden_slab 10
fill ~84~27~52 ~85~27~52 minecraft:sandstone 2
fill ~84~28~52 ~85~28~52 minecraft:wooden_slab 2
fill ~86~7~52 ~86~7~54 minecraft:sandstone 2
setblock ~86~27~52 minecraft:stained_glass 11
setblock ~87~7~52 minecraft:sea_lantern
setblock ~87~27~52 minecraft:sea_lantern
setblock ~88~27~52 minecraft:stained_glass 11
setblock ~89~6~52 minecraft:wooden_slab 10
fill ~89~7~52 ~89~7~54 minecraft:sandstone 2
setblock ~89~8~52 minecraft:wooden_slab 2
setblock ~89~26~52 minecraft:wooden_slab 10
setblock ~89~27~52 minecraft:sandstone 2
setblock ~89~28~52 minecraft:wooden_slab 2
fill ~117~1~52 ~125~1~52 minecraft:stone_block_slab 13
fill ~117~2~52 ~125~2~52 minecraft:stained_hardened_clay 14
fill ~117~3~52 ~125~3~52 minecraft:stone_block_slab 5
fill ~117~21~52 ~125~21~52 minecraft:stone_block_slab 13
