fill ~35~1~1 ~35~2~1 minecraft:coal_block
fill ~33~1~2 ~33~3~2 minecraft:coal_block
setblock ~35~0~2 minecraft:coal_block
fill ~35~1~2 ~36~1~6 minecraft:wool 7
fill ~35~2~2 ~36~2~3 minecraft:wool 7
fill ~36~0~2 ~36~0~9 minecraft:wool 7
setblock ~34~0~3 minecraft:coal_block
fill ~34~1~3 ~34~2~7 minecraft:wool 7
fill ~35~0~3 ~35~0~8 minecraft:wool 7
setblock ~35~3~3 minecraft:wool 7
fill ~36~3~3 ~38~3~9 minecraft:stained_hardened_clay 12
fill ~37~0~3 ~37~1~10 minecraft:wool 7
fill ~37~2~3 ~38~2~9 minecraft:stained_hardened_clay 12
setblock ~38~1~3 minecraft:stained_hardened_clay 12
fill ~32~1~4 ~32~3~4 minecraft:coal_block
setblock ~33~0~4 minecraft:coal_block
fill ~33~1~4 ~33~1~7 minecraft:wool 7
fill ~33~2~4 ~33~2~6 minecraft:wool 7
fill ~34~0~4 ~34~0~8 minecraft:wool 7
fill ~34~3~4 ~35~3~5 minecraft:stained_hardened_clay 12
setblock ~35~2~4 minecraft:wool 7
fill ~36~2~4 ~36~2~8 minecraft:stained_hardened_clay 12
fill ~38~0~4 ~38~1~11 minecraft:wool 7
fill ~39~1~4 ~39~1~7 minecraft:wool 7
fill ~39~2~4 ~39~2~11 minecraft:stained_hardened_clay 12
fill ~33~3~5 ~33~3~6 minecraft:wool 7
fill ~35~2~5 ~35~2~9 minecraft:stained_hardened_clay 12
fill ~39~0~5 ~39~0~12 minecraft:wool 7
fill ~39~3~5 ~40~3~10 minecraft:stained_hardened_clay 12
fill ~40~1~5 ~40~1~8 minecraft:wool 7
fill ~40~2~5 ~41~2~10 minecraft:stained_hardened_clay 12
fill ~41~1~5 ~41~1~6 minecraft:stained_hardened_clay 12
fill ~32~1~6 ~32~2~6 minecraft:coal_block
setblock ~33~0~6 minecraft:coal_block
setblock ~34~3~6 minecraft:wool 7
fill ~35~3~6 ~35~3~8 minecraft:stained_hardened_clay 12
fill ~38~4~6 ~38~4~9 minecraft:stained_hardened_clay 12
fill ~40~0~6 ~41~0~8 minecraft:wool 7
fill ~41~3~6 ~41~3~10 minecraft:stained_hardened_clay 12
fill ~42~1~6 ~42~1~16 minecraft:stained_hardened_clay 12
fill ~34~3~7 ~34~3~8 minecraft:stained_hardened_clay 12
setblock ~35~1~7 minecraft:stained_hardened_clay 12
fill ~36~1~7 ~36~1~10 minecraft:wool 7
setblock ~37~4~7 minecraft:stained_hardened_clay 12
fill ~39~4~7 ~39~4~10 minecraft:stained_hardened_clay 12
setblock ~41~1~7 minecraft:wool 7
fill ~42~2~7 ~42~3~10 minecraft:stained_hardened_clay 12
setblock ~34~2~8 minecraft:wool 7
fill ~35~1~8 ~35~1~9 minecraft:wool 7
setblock ~39~1~8 minecraft:stained_hardened_clay 12
fill ~40~4~8 ~40~4~10 minecraft:stained_hardened_clay 12
fill ~41~1~8 ~41~1~12 minecraft:stained_hardened_clay 12
fill ~42~0~8 ~42~0~15 minecraft:stained_hardened_clay 12
fill ~43~1~8 ~43~1~13 minecraft:stained_hardened_clay 12
fill ~43~2~8 ~43~2~11 minecraft:stained_hardened_clay 12
fill ~43~3~8 ~43~3~10 minecraft:stained_hardened_clay 12
fill ~36~2~9 ~36~2~10 minecraft:wool 7
setblock ~39~1~9 minecraft:wool 7
fill ~40~0~9 ~41~0~13 minecraft:stained_hardened_clay 12
fill ~40~1~9 ~40~1~14 minecraft:stained_hardened_clay 12
setblock ~41~4~9 minecraft:stained_hardened_clay 12
fill ~43~0~9 ~43~0~15 minecraft:stained_hardened_clay 12
fill ~44~1~9 ~44~1~18 minecraft:stained_hardened_clay 12
fill ~44~2~9 ~44~2~11 minecraft:stained_hardened_clay 12
fill ~28~2~10 ~28~3~10 minecraft:coal_block
fill ~30~1~10 ~30~2~10 minecraft:coal_block
fill ~37~2~10 ~37~2~11 minecraft:wool 7
fill ~37~3~10 ~38~3~10 minecraft:stained_hardened_clay 12
setblock ~38~2~10 minecraft:stained_hardened_clay 12
setblock ~39~1~10 minecraft:stained_hardened_clay 12
fill ~41~4~10 ~41~4~14 minecraft:wool 12
setblock ~42~4~10 minecraft:stained_hardened_clay 12
fill ~44~0~10 ~44~0~17 minecraft:stained_hardened_clay 12
fill ~44~3~10 ~44~3~11 minecraft:stained_hardened_clay 12
fill ~45~2~10 ~45~2~12 minecraft:stained_hardened_clay 12
fill ~27~2~11 ~27~2~17 minecraft:wool 7
fill ~28~0~11 ~28~1~11 minecraft:coal_block
fill ~28~2~11 ~31~2~11 minecraft:stained_hardened_clay 12
fill ~28~3~11 ~30~3~16 minecraft:stained_hardened_clay 12
fill ~29~1~11 ~30~1~14 minecraft:wool 7
fill ~29~4~11 ~29~4~17 minecraft:stained_hardened_clay 12
setblock ~30~0~11 minecraft:coal_block
setblock ~37~1~11 minecraft:wool 7
setblock ~38~2~11 minecraft:wool 7
setblock ~38~3~11 minecraft:stained_hardened_clay 12
setblock ~39~1~11 minecraft:wool 7
fill ~39~3~11 ~43~3~13 minecraft:wool 12
fill ~39~4~11 ~40~4~11 minecraft:wool 12
fill ~40~2~11 ~42~2~14 minecraft:wool 12
fill ~42~4~11 ~44~4~15 minecraft:wool 12
fill ~45~0~11 ~45~0~18 minecraft:stained_hardened_clay 12
fill ~45~1~11 ~45~1~15 minecraft:stained_hardened_clay 12
fill ~45~3~11 ~46~3~11 minecraft:stained_hardened_clay 12
fill ~46~2~11 ~46~2~13 minecraft:stained_hardened_clay 12
fill ~25~2~12 ~26~2~12 minecraft:coal_block
setblock ~25~3~12 minecraft:coal_block
fill ~26~1~12 ~26~1~13 minecraft:coal_block
fill ~27~1~12 ~28~1~17 minecraft:wool 7
fill ~27~3~12 ~27~4~16 minecraft:stained_hardened_clay 12
fill ~28~0~12 ~30~0~17 minecraft:wool 7
setblock ~28~2~12 minecraft:wool 7
fill ~28~4~12 ~28~4~16 minecraft:stained_hardened_clay 12
fill ~29~2~12 ~32~2~17 minecraft:stained_hardened_clay 12
fill ~29~5~12 ~29~5~15 minecraft:stained_hardened_clay 12
fill ~30~4~12 ~31~4~15 minecraft:stained_hardened_clay 12
fill ~31~1~12 ~31~1~17 minecraft:wool 7
fill ~31~3~12 ~31~3~16 minecraft:stained_hardened_clay 12
setblock ~38~1~12 minecraft:wool 7
setblock ~38~2~12 minecraft:stained_hardened_clay 12
fill ~39~1~12 ~39~1~14 minecraft:stained_hardened_clay 12
fill ~39~2~12 ~39~2~13 minecraft:wool 12
setblock ~40~4~12 minecraft:wool 12
fill ~42~5~12 ~43~5~14 minecraft:wool 12
fill ~43~2~12 ~44~2~16 minecraft:wool 12
fill ~44~3~12 ~45~3~18 minecraft:wool 12
fill ~45~4~12 ~45~4~18 minecraft:wool 12
fill ~46~0~12 ~46~1~18 minecraft:stained_hardened_clay 12
fill ~46~3~12 ~47~3~13 minecraft:stained_hardened_clay 12
fill ~47~1~12 ~47~1~16 minecraft:stained_hardened_clay 12
fill ~47~2~12 ~47~2~14 minecraft:stained_hardened_clay 12
fill ~26~2~13 ~26~2~14 minecraft:wool 7
fill ~26~3~13 ~26~3~15 minecraft:stained_hardened_clay 12
setblock ~27~0~13 minecraft:coal_block
setblock ~28~2~13 minecraft:stained_hardened_clay 12
fill ~28~5~13 ~28~5~15 minecraft:stained_hardened_clay 12
fill ~30~5~13 ~30~5~16 minecraft:stained_hardened_clay 12
fill ~31~0~13 ~31~0~17 minecraft:wool 7
fill ~32~1~13 ~32~1~16 minecraft:wool 7
fill ~32~3~13 ~32~3~15 minecraft:stained_hardened_clay 12
setblock ~38~1~13 minecraft:stained_hardened_clay 12
setblock ~39~0~13 minecraft:stained_hardened_clay 12
setblock ~41~1~13 minecraft:wool 12
fill ~44~5~13 ~44~5~16 minecraft:wool 12
fill ~45~2~13 ~45~2~18 minecraft:wool 12
fill ~46~4~13 ~47~4~18 minecraft:wool 12
fill ~48~2~13 ~48~3~14 minecraft:stained_hardened_clay 12
fill ~26~1~14 ~26~1~15 minecraft:wool 7
setblock ~26~4~14 minecraft:stained_hardened_clay 12
setblock ~27~0~14 minecraft:wool 7
setblock ~27~5~14 minecraft:stained_hardened_clay 12
setblock ~28~2~14 minecraft:wool 7
setblock ~31~5~14 minecraft:stained_hardened_clay 12
fill ~32~0~14 ~32~0~17 minecraft:wool 7
fill ~32~4~14 ~32~4~15 minecraft:stained_hardened_clay 12
setblock ~33~1~14 minecraft:wool 7
fill ~33~2~14 ~33~2~16 minecraft:stained_hardened_clay 12
fill ~40~3~14 ~43~3~14 minecraft:wool 12
fill ~41~0~14 ~41~1~14 minecraft:stained_hardened_clay 12
setblock ~43~1~14 minecraft:wool 12
fill ~45~5~14 ~46~5~18 minecraft:wool 12
fill ~46~2~14 ~46~3~19 minecraft:wool 12
fill ~47~0~14 ~47~0~19 minecraft:stained_hardened_clay 12
fill ~47~3~14 ~47~3~21 minecraft:wool 12
fill ~48~1~14 ~49~1~16 minecraft:stained_hardened_clay 12
setblock ~49~2~14 minecraft:stained_hardened_clay 12
fill ~25~1~15 ~25~3~15 minecraft:coal_block
fill ~26~0~15 ~27~0~15 minecraft:coal_block
setblock ~26~2~15 minecraft:stained_hardened_clay 12
setblock ~28~2~15 minecraft:stained_hardened_clay 12
fill ~29~1~15 ~29~1~18 minecraft:wool 7
setblock ~30~1~15 minecraft:stained_hardened_clay 12
setblock ~33~0~15 minecraft:wool 7
fill ~33~1~15 ~34~1~25 minecraft:stained_hardened_clay 12
setblock ~33~3~15 minecraft:stained_hardened_clay 12
setblock ~41~1~15 minecraft:stained_hardened_clay 12
fill ~41~2~15 ~42~2~15 minecraft:wool 12
fill ~42~3~15 ~43~3~15 minecraft:wool 12
fill ~43~1~15 ~43~1~17 minecraft:stained_hardened_clay 12
setblock ~43~5~15 minecraft:wool 12
fill ~47~2~15 ~49~2~19 minecraft:wool 12
fill ~48~0~15 ~48~0~20 minecraft:stained_hardened_clay 12
fill ~48~3~15 ~49~3~22 minecraft:wool 12
fill ~50~1~15 ~50~1~25 minecraft:stained_hardened_clay 12
setblock ~50~2~15 minecraft:stained_hardened_clay 12
setblock ~26~2~16 minecraft:wool 7
setblock ~28~2~16 minecraft:wool 7
fill ~30~1~16 ~30~1~17 minecraft:wool 7
setblock ~30~4~16 minecraft:stained_hardened_clay 12
fill ~31~4~16 ~32~4~19 minecraft:wool 12
fill ~32~3~16 ~33~3~23 minecraft:wool 12
fill ~33~0~16 ~33~0~24 minecraft:stained_hardened_clay 12
fill ~34~2~16 ~34~2~18 minecraft:stained_hardened_clay 12
setblock ~42~2~16 minecraft:wool 12
setblock ~43~3~16 minecraft:wool 12
fill ~44~4~16 ~44~4~17 minecraft:wool 12
setblock ~45~1~16 minecraft:wool 12
fill ~47~5~16 ~48~5~18 minecraft:wool 12
fill ~48~4~16 ~48~4~20 minecraft:wool 12
fill ~49~0~16 ~50~0~22 minecraft:stained_hardened_clay 12
fill ~50~2~16 ~50~3~18 minecraft:wool 12
fill ~51~1~16 ~51~1~26 minecraft:stained_hardened_clay 12
fill ~51~2~16 ~51~2~19 minecraft:stained_hardened_clay 12
fill ~28~2~17 ~28~3~17 minecraft:stained_hardened_clay 12
fill ~29~3~17 ~29~3~18 minecraft:stained_hardened_clay 12
fill ~30~3~17 ~31~3~20 minecraft:wool 12
fill ~30~4~17 ~30~4~18 minecraft:wool 12
fill ~32~1~17 ~32~1~20 minecraft:stained_hardened_clay 12
fill ~33~2~17 ~33~2~27 minecraft:wool 12
fill ~33~4~17 ~33~4~24 minecraft:wool 12
fill ~34~0~17 ~34~0~24 minecraft:stained_hardened_clay 12
fill ~34~3~17 ~34~3~27 minecraft:wool 12
fill ~35~1~17 ~35~1~29 minecraft:stained_hardened_clay 12
fill ~35~2~17 ~35~2~20 minecraft:stained_hardened_clay 12
fill ~44~2~17 ~44~2~18 minecraft:wool 12
fill ~45~1~17 ~45~1~19 minecraft:stained_hardened_clay 12
fill ~47~1~17 ~48~1~17 minecraft:wool 12
fill ~49~1~17 ~49~1~24 minecraft:stained_hardened_clay 12
fill ~49~4~17 ~50~4~23 minecraft:wool 12
fill ~49~5~17 ~49~5~19 minecraft:wool 12
fill ~51~0~17 ~51~0~24 minecraft:stained_hardened_clay 12
fill ~51~3~17 ~51~3~18 minecraft:stained_hardened_clay 12
fill ~52~1~17 ~52~2~27 minecraft:stained_hardened_clay 12
setblock ~28~1~18 minecraft:stained_hardened_clay 12
fill ~29~0~18 ~30~0~18 minecraft:wool 7
fill ~29~2~18 ~30~2~19 minecraft:stained_hardened_clay 12
fill ~30~1~18 ~31~1~20 minecraft:stained_hardened_clay 12
fill ~31~0~18 ~32~0~21 minecraft:stained_hardened_clay 12
fill ~31~2~18 ~32~2~23 minecraft:wool 12
fill ~32~5~18 ~33~5~20 minecraft:wool 12
fill ~34~4~18 ~34~4~27 minecraft:wool 12
fill ~35~0~18 ~35~0~29 minecraft:stained_hardened_clay 12
fill ~35~3~18 ~35~3~26 minecraft:wool 12
fill ~36~1~18 ~36~1~32 minecraft:stained_hardened_clay 12
fill ~47~1~18 ~48~1~21 minecraft:stained_hardened_clay 12
fill ~51~4~18 ~51~4~24 minecraft:wool 12
fill ~52~0~18 ~52~0~25 minecraft:stained_hardened_clay 12
fill ~52~3~18 ~53~3~18 minecraft:stained_hardened_clay 12
fill ~53~1~18 ~54~2~28 minecraft:stained_hardened_clay 12
setblock ~30~0~19 minecraft:stained_hardened_clay 12
fill ~34~2~19 ~34~2~20 minecraft:wool 12
fill ~34~5~19 ~34~5~23 minecraft:wool 12
fill ~35~4~19 ~35~4~27 minecraft:wool 12
fill ~36~2~19 ~36~2~21 minecraft:stained_hardened_clay 12
setblock ~45~2~19 minecraft:stained_hardened_clay 12
fill ~46~1~19 ~46~1~20 minecraft:stained_hardened_clay 12
fill ~47~4~19 ~47~4~20 minecraft:wool 12
setblock ~48~5~19 minecraft:wool 12
fill ~50~2~19 ~50~2~20 minecraft:stained_hardened_clay 12
fill ~50~3~19 ~52~3~22 minecraft:wool 12
fill ~52~4~19 ~52~4~24 minecraft:wool 12
fill ~53~0~19 ~54~0~27 minecraft:stained_hardened_clay 12
fill ~53~3~19 ~55~3~102 minecraft:stained_hardened_clay 12
setblock ~53~4~19 minecraft:stained_hardened_clay 12
fill ~55~1~19 ~55~2~102 minecraft:stained_hardened_clay 12
fill ~30~2~20 ~30~2~21 minecraft:stained_hardened_clay 12
fill ~32~4~20 ~32~4~21 minecraft:wool 12
fill ~36~0~20 ~36~0~30 minecraft:stained_hardened_clay 12
fill ~36~3~20 ~36~3~26 minecraft:wool 12
fill ~37~1~20 ~37~1~38 minecraft:stained_hardened_clay 12
fill ~37~2~20 ~37~2~23 minecraft:stained_hardened_clay 12
fill ~38~28~20 ~39~28~20 minecraft:stained_hardened_clay 12
fill ~38~29~20 ~38~29~21 minecraft:stained_hardened_clay 12
fill ~39~27~20 ~40~27~21 minecraft:wool 12
fill ~40~25~20 ~40~26~21 minecraft:wool 12
fill ~46~2~20 ~49~2~20 minecraft:stained_hardened_clay 12
setblock ~46~3~20 minecraft:wool 12
setblock ~51~2~20 minecraft:wool 12
fill ~53~4~20 ~53~5~23 minecraft:wool 12
fill ~54~4~20 ~55~4~103 minecraft:stained_hardened_clay 12
fill ~55~0~20 ~55~0~29 minecraft:stained_hardened_clay 12
fill ~56~1~20 ~57~2~98 minecraft:stained_hardened_clay 12
fill ~56~3~20 ~56~3~101 minecraft:stained_hardened_clay 12
fill ~31~1~21 ~31~1~24 minecraft:stained_hardened_clay 12
setblock ~31~3~21 minecraft:wool 12
setblock ~32~1~21 minecraft:wool 12
fill ~33~5~21 ~33~5~22 minecraft:wool 12
setblock ~34~2~21 minecraft:stained_hardened_clay 12
setblock ~35~2~21 minecraft:wool 12
fill ~35~5~21 ~35~5~23 minecraft:wool 12
fill ~36~4~21 ~36~4~26 minecraft:wool 12
fill ~37~0~21 ~37~0~33 minecraft:stained_hardened_clay 12
fill ~38~1~21 ~38~1~38 minecraft:stained_hardened_clay 12
fill ~39~28~21 ~39~29~21 minecraft:stained_hardened_clay 12
fill ~40~23~21 ~42~23~22 minecraft:wool 12
fill ~40~24~21 ~42~24~21 minecraft:wool 12
setblock ~40~28~21 minecraft:wool 12
fill ~41~25~21 ~42~26~21 minecraft:wool 12
setblock ~41~27~21 minecraft:wool 12
fill ~41~28~21 ~41~28~23 minecraft:stained_hardened_clay 12
fill ~42~27~21 ~42~27~23 minecraft:stained_hardened_clay 12
fill ~47~2~21 ~49~2~21 minecraft:stained_hardened_clay 12
setblock ~50~2~21 minecraft:wool 12
fill ~50~5~21 ~52~5~24 minecraft:wool 12
fill ~51~2~21 ~51~2~26 minecraft:stained_hardened_clay 12
fill ~53~6~21 ~53~6~24 minecraft:wool 12
fill ~54~5~21 ~55~5~102 minecraft:stained_hardened_clay 12
fill ~56~0~21 ~56~0~94 minecraft:stained_hardened_clay 12
fill ~56~4~21 ~57~4~101 minecraft:stained_hardened_clay 12
fill ~57~3~21 ~58~3~100 minecraft:stained_hardened_clay 12
fill ~58~2~21 ~58~2~99 minecraft:stained_hardened_clay 12
fill ~32~0~22 ~32~0~23 minecraft:stained_hardened_clay 12
setblock ~32~1~22 minecraft:stained_hardened_clay 12
setblock ~34~2~22 minecraft:wool 12
fill ~35~2~22 ~35~2~24 minecraft:stained_hardened_clay 12
setblock ~36~2~22 minecraft:wool 12
fill ~36~5~22 ~36~5~23 minecraft:wool 12
fill ~37~3~22 ~37~3~26 minecraft:wool 12
fill ~38~2~22 ~38~2~38 minecraft:stained_hardened_clay 12
fill ~39~28~22 ~39~28~24 minecraft:wool 7
setblock ~39~29~22 minecraft:stained_hardened_clay 12
fill ~40~20~22 ~42~20~22 minecraft:stained_hardened_clay 12
fill ~40~21~22 ~41~22~23 minecraft:wool 12
setblock ~40~28~22 minecraft:stained_hardened_clay 12
fill ~41~24~22 ~43~24~22 minecraft:wool 12
setblock ~42~21~22 minecraft:stained_hardened_clay 12
fill ~42~22~22 ~42~22~27 minecraft:wool 12
fill ~42~25~22 ~42~25~23 minecraft:wool 12
fill ~42~26~22 ~43~26~22 minecraft:stained_hardened_clay 12
fill ~43~23~22 ~43~23~26 minecraft:wool 12
fill ~43~25~22 ~43~25~24 minecraft:stained_hardened_clay 12
fill ~48~1~22 ~48~2~22 minecraft:stained_hardened_clay 12
fill ~49~2~22 ~50~2~24 minecraft:stained_hardened_clay 12
fill ~51~6~22 ~52~6~25 minecraft:wool 12
fill ~51~8~22 ~51~8~26 minecraft:wool 12
setblock ~54~6~22 minecraft:wool 12
fill ~55~6~22 ~55~6~102 minecraft:stained_hardened_clay 12
fill ~56~5~22 ~59~5~97 minecraft:stained_hardened_clay 12
fill ~57~0~22 ~57~0~94 minecraft:stained_hardened_clay 12
fill ~58~1~22 ~58~1~97 minecraft:stained_hardened_clay 12
fill ~58~4~22 ~59~4~98 minecraft:stained_hardened_clay 12
fill ~58~6~22 ~59~6~95 minecraft:stained_hardened_clay 12
fill ~58~7~22 ~58~7~94 minecraft:stained_hardened_clay 12
fill ~59~2~22 ~59~3~98 minecraft:stained_hardened_clay 12
setblock ~32~1~23 minecraft:wool 12
fill ~34~2~23 ~34~2~24 minecraft:stained_hardened_clay 12
setblock ~36~2~23 minecraft:stained_hardened_clay 12
fill ~38~0~23 ~38~0~37 minecraft:stained_hardened_clay 12
fill ~38~3~23 ~38~3~26 minecraft:wool 12
setblock ~38~28~23 minecraft:wool 7
fill ~39~1~23 ~39~2~38 minecraft:stained_hardened_clay 12
setblock ~39~20~23 minecraft:stained_hardened_clay 12
setblock ~39~21~23 minecraft:wool 12
setblock ~39~27~23 minecraft:stained_hardened_clay 12
setblock ~39~29~23 minecraft:wool 7
fill ~40~18~23 ~40~20~28 minecraft:wool 12
fill ~40~27~23 ~40~27~24 minecraft:wool 7
setblock ~40~28~23 minecraft:wool 7
setblock ~40~29~23 minecraft:stained_hardened_clay 12
fill ~41~17~23 ~41~17~45 minecraft:stained_hardened_clay 12
fill ~41~18~23 ~41~20~23 minecraft:stained_hardened_clay 12
fill ~41~27~23 ~41~27~25 minecraft:stained_hardened_clay 12
fill ~42~19~23 ~43~19~24 minecraft:stained_hardened_clay 12
fill ~42~20~23 ~43~20~23 minecraft:stained_hardened_clay 12
fill ~42~21~23 ~43~21~26 minecraft:wool 12
fill ~42~23~23 ~42~23~27 minecraft:wool 12
fill ~42~24~23 ~43~24~24 minecraft:wool 12
fill ~42~26~23 ~42~26~24 minecraft:stained_hardened_clay 12
fill ~43~22~23 ~43~22~26 minecraft:wool 12
fill ~46~19~23 ~46~19~42 minecraft:stained_hardened_clay 12
setblock ~48~19~23 minecraft:stained_hardened_clay 12
fill ~49~3~23 ~51~3~23 minecraft:wool 12
setblock ~50~0~23 minecraft:stained_hardened_clay 12
fill ~51~7~23 ~54~7~24 minecraft:wool 12
fill ~52~3~23 ~52~3~27 minecraft:stained_hardened_clay 12
fill ~52~8~23 ~54~8~24 minecraft:wool 12
fill ~52~9~23 ~52~10~27 minecraft:wool 12
fill ~54~6~23 ~54~6~102 minecraft:stained_hardened_clay 12
fill ~55~7~23 ~57~7~99 minecraft:stained_hardened_clay 12
fill ~56~6~23 ~57~6~99 minecraft:stained_hardened_clay 12
fill ~56~8~23 ~60~8~90 minecraft:stained_hardened_clay 12
fill ~57~9~23 ~57~9~93 minecraft:stained_hardened_clay 12
fill ~58~0~23 ~58~0~94 minecraft:stained_hardened_clay 12
fill ~59~1~23 ~59~1~96 minecraft:stained_hardened_clay 12
fill ~59~7~23 ~60~7~91 minecraft:stained_hardened_clay 12
fill ~60~2~23 ~60~5~97 minecraft:stained_hardened_clay 12
fill ~60~6~23 ~61~6~92 minecraft:stained_hardened_clay 12
fill ~61~3~23 ~61~5~97 minecraft:stained_hardened_clay 12
setblock ~32~2~24 minecraft:wool 12
setblock ~33~3~24 minecraft:wool 12
fill ~36~2~24 ~37~2~24 minecraft:wool 12
fill ~36~7~24 ~41~8~25 minecraft:wool 12
fill ~37~4~24 ~37~4~27 minecraft:wool 12
fill ~37~6~24 ~41~6~25 minecraft:wool 12
fill ~37~9~24 ~42~9~25 minecraft:wool 12
fill ~38~27~24 ~39~27~24 minecraft:wool 7
fill ~39~0~24 ~39~0~37 minecraft:stained_hardened_clay 12
fill ~39~5~24 ~40~5~25 minecraft:wool 12
fill ~39~10~24 ~42~10~24 minecraft:wool 12
fill ~39~11~24 ~39~11~25 minecraft:wool 7
fill ~39~16~24 ~39~18~27 minecraft:wool 12
fill ~39~19~24 ~39~19~25 minecraft:wool 12
setblock ~39~20~24 minecraft:wool 12
fill ~39~26~24 ~39~26~27 minecraft:wool 7
fill ~40~1~24 ~40~1~38 minecraft:stained_hardened_clay 12
fill ~40~11~24 ~40~11~47 minecraft:stained_hardened_clay 12
fill ~40~12~24 ~41~12~25 minecraft:wool 7
fill ~40~13~24 ~41~13~24 minecraft:wool 7
fill ~40~16~24 ~41~16~45 minecraft:stained_hardened_clay 12
fill ~40~17~24 ~40~17~28 minecraft:wool 12
fill ~40~26~24 ~41~26~24 minecraft:stained_hardened_clay 12
setblock ~40~28~24 minecraft:stained_hardened_clay 12
fill ~41~11~24 ~42~11~25 minecraft:wool 12
fill ~41~14~24 ~41~14~46 minecraft:stained_hardened_clay 12
fill ~41~18~24 ~41~20~27 minecraft:wool 12
setblock ~41~21~24 minecraft:wool 12
fill ~42~8~24 ~42~8~26 minecraft:wool 12
setblock ~42~12~24 minecraft:wool 12
fill ~42~18~24 ~43~18~44 minecraft:stained_hardened_clay 12
fill ~42~20~24 ~43~20~26 minecraft:wool 12
fill ~42~25~24 ~42~25~26 minecraft:stained_hardened_clay 12
fill ~44~20~24 ~44~20~42 minecraft:stained_hardened_clay 12
setblock ~45~17~24 minecraft:stained_hardened_clay 12
fill ~45~21~24 ~46~21~24 minecraft:stained_hardened_clay 12
fill ~47~17~24 ~49~17~24 minecraft:stained_hardened_clay 12
setblock ~48~16~24 minecraft:stained_hardened_clay 12
fill ~48~21~24 ~49~21~24 minecraft:stained_hardened_clay 12
fill ~49~3~24 ~51~3~24 minecraft:stained_hardened_clay 12
setblock ~49~15~24 minecraft:stained_hardened_clay 12
setblock ~50~4~24 minecraft:wool 12
fill ~52~11~24 ~57~11~27 minecraft:wool 12
fill ~53~4~24 ~53~4~106 minecraft:stained_hardened_clay 12
setblock ~53~5~24 minecraft:wool 12
fill ~53~9~24 ~54~10~25 minecraft:wool 12
fill ~55~8~24 ~55~8~101 minecraft:stained_hardened_clay 12
fill ~55~9~24 ~56~9~25 minecraft:stained_hardened_clay 12
fill ~55~10~24 ~56~10~28 minecraft:wool 12
fill ~57~10~24 ~60~10~24 minecraft:stained_hardened_clay 12
fill ~58~9~24 ~61~9~89 minecraft:stained_hardened_clay 12
fill ~58~11~24 ~58~11~26 minecraft:stained_hardened_clay 12
fill ~59~0~24 ~59~0~94 minecraft:stained_hardened_clay 12
fill ~60~1~24 ~61~1~94 minecraft:stained_hardened_clay 12
fill ~61~2~24 ~61~2~96 minecraft:stained_hardened_clay 12
fill ~61~7~24 ~63~7~90 minecraft:stained_hardened_clay 12
fill ~61~8~24 ~62~8~89 minecraft:stained_hardened_clay 12
fill ~62~3~24 ~62~5~93 minecraft:stained_hardened_clay 12
fill ~62~6~24 ~63~6~92 minecraft:stained_hardened_clay 12
fill ~34~2~25 ~35~2~25 minecraft:wool 12
fill ~34~6~25 ~36~6~25 minecraft:wool 12
fill ~34~7~25 ~35~8~26 minecraft:wool 12
fill ~35~9~25 ~36~9~25 minecraft:wool 12
fill ~36~2~25 ~36~2~40 minecraft:stained_hardened_clay 12
fill ~36~10~25 ~38~10~25 minecraft:wool 12
setblock ~37~2~25 minecraft:wool 12
fill ~37~11~25 ~38~11~25 minecraft:wool 7
fill ~37~12~25 ~39~12~46 minecraft:stained_hardened_clay 12
fill ~37~13~25 ~40~13~25 minecraft:stained_hardened_clay 12
fill ~37~14~25 ~38~14~25 minecraft:wool 12
fill ~38~4~25 ~38~4~26 minecraft:wool 12
fill ~38~15~25 ~38~17~26 minecraft:wool 12
fill ~38~18~25 ~38~19~25 minecraft:wool 12
setblock ~38~26~25 minecraft:wool 7
fill ~39~3~25 ~39~3~40 minecraft:stained_hardened_clay 12
setblock ~39~10~25 minecraft:wool 7
fill ~39~14~25 ~40~14~45 minecraft:stained_hardened_clay 12
fill ~39~15~25 ~42~15~25 minecraft:stained_hardened_clay 12
setblock ~39~25~25 minecraft:wool 7
setblock ~39~27~25 minecraft:wool 7
fill ~40~0~25 ~40~0~38 minecraft:stained_hardened_clay 12
fill ~40~2~25 ~40~2~38 minecraft:stained_hardened_clay 12
fill ~40~10~25 ~43~10~25 minecraft:wool 12
fill ~40~25~25 ~41~25~25 minecraft:stained_hardened_clay 12
setblock ~40~26~25 minecraft:wool 7
setblock ~40~27~25 minecraft:stained_hardened_clay 12
setblock ~41~5~25 minecraft:wool 12
fill ~41~13~25 ~44~13~25 minecraft:wool 7
fill ~41~23~25 ~41~23~27 minecraft:wool 12
setblock ~41~24~25 minecraft:stained_hardened_clay 12
fill ~41~26~25 ~41~26~27 minecraft:stained_hardened_clay 12
fill ~42~5~25 ~42~5~28 minecraft:stained_hardened_clay 12
fill ~42~6~25 ~42~7~25 minecraft:wool 12
setblock ~42~12~25 minecraft:wool 7
fill ~42~14~25 ~42~14~46 minecraft:stained_hardened_clay 12
fill ~42~16~25 ~42~16~45 minecraft:stained_hardened_clay 12
fill ~42~17~25 ~43~17~44 minecraft:stained_hardened_clay 12
fill ~42~19~25 ~42~19~26 minecraft:wool 12
setblock ~42~24~25 minecraft:wool 12
fill ~43~6~25 ~43~6~28 minecraft:stained_hardened_clay 12
fill ~43~7~25 ~43~9~25 minecraft:wool 12
fill ~43~11~25 ~43~11~27 minecraft:wool 12
setblock ~43~12~25 minecraft:wool 12
fill ~43~14~25 ~44~14~26 minecraft:wool 7
setblock ~43~15~25 minecraft:wool 7
fill ~43~19~25 ~45~19~42 minecraft:stained_hardened_clay 12
setblock ~43~24~25 minecraft:stained_hardened_clay 12
fill ~44~18~25 ~47~18~43 minecraft:stained_hardened_clay 12
setblock ~44~21~25 minecraft:wool 12
fill ~46~14~25 ~48~14~25 minecraft:stained_hardened_clay 12
fill ~46~16~25 ~47~16~46 minecraft:stained_hardened_clay 12
setblock ~48~15~25 minecraft:stained_hardened_clay 12
setblock ~48~22~25 minecraft:stained_hardened_clay 12
fill ~49~20~25 ~50~20~25 minecraft:stained_hardened_clay 12
setblock ~49~21~25 minecraft:stained_hardened_clay 12
fill ~50~2~25 ~50~4~25 minecraft:stained_hardened_clay 12
setblock ~50~5~25 minecraft:wool 12
fill ~51~3~25 ~51~5~26 minecraft:stained_hardened_clay 12
fill ~51~7~25 ~53~7~25 minecraft:wool 12
fill ~51~9~25 ~51~9~27 minecraft:wool 12
fill ~52~4~25 ~52~5~107 minecraft:stained_hardened_clay 12
fill ~52~8~25 ~53~8~25 minecraft:wool 12
fill ~53~5~25 ~53~5~103 minecraft:stained_hardened_clay 12
fill ~53~6~25 ~53~6~102 minecraft:stained_hardened_clay 12
fill ~53~12~25 ~57~12~30 minecraft:wool 12
fill ~54~7~25 ~54~7~102 minecraft:stained_hardened_clay 12
fill ~54~8~25 ~54~8~101 minecraft:stained_hardened_clay 12
fill ~57~10~25 ~57~10~27 minecraft:wool 12
fill ~58~10~25 ~62~10~87 minecraft:stained_hardened_clay 12
fill ~58~12~25 ~60~12~25 minecraft:stained_hardened_clay 12
fill ~58~13~25 ~59~13~25 minecraft:stained_hardened_clay 12
fill ~59~11~25 ~61~11~88 minecraft:stained_hardened_clay 12
fill ~62~2~25 ~62~2~95 minecraft:stained_hardened_clay 12
fill ~62~9~25 ~62~9~88 minecraft:stained_hardened_clay 12
fill ~63~3~25 ~63~5~92 minecraft:stained_hardened_clay 12
fill ~63~8~25 ~63~8~88 minecraft:stained_hardened_clay 12
setblock ~33~1~26 minecraft:wool 12
fill ~33~3~26 ~33~4~28 minecraft:wool 12
fill ~33~6~26 ~35~6~26 minecraft:wool 12
fill ~33~7~26 ~33~7~28 minecraft:wool 12
fill ~34~1~26 ~34~1~28 minecraft:stained_hardened_clay 12
fill ~34~2~26 ~34~2~27 minecraft:wool 12
fill ~34~5~26 ~38~5~26 minecraft:wool 12
fill ~34~9~26 ~35~9~26 minecraft:wool 12
fill ~34~10~26 ~37~10~42 minecraft:stained_hardened_clay 12
fill ~34~11~26 ~36~11~26 minecraft:stained_hardened_clay 12
fill ~35~2~26 ~35~2~33 minecraft:stained_hardened_clay 12
fill ~35~12~26 ~36~12~26 minecraft:stained_hardened_clay 12
fill ~36~6~26 ~39~6~43 minecraft:stained_hardened_clay 12
setblock ~36~7~26 minecraft:wool 12
fill ~36~8~26 ~37~8~46 minecraft:stained_hardened_clay 12
fill ~36~9~26 ~36~9~46 minecraft:stained_hardened_clay 12
fill ~37~2~26 ~37~2~39 minecraft:stained_hardened_clay 12
fill ~37~7~26 ~38~7~43 minecraft:stained_hardened_clay 12
setblock ~37~9~26 minecraft:wool 12
setblock ~37~11~26 minecraft:wool 7
setblock ~37~13~26 minecraft:wool 12
fill ~37~15~26 ~37~16~26 minecraft:wool 12
fill ~38~8~26 ~39~8~26 minecraft:wool 12
fill ~38~9~26 ~40~9~45 minecraft:stained_hardened_clay 12
setblock ~38~10~26 minecraft:wool 7
fill ~38~11~26 ~39~11~46 minecraft:stained_hardened_clay 12
fill ~38~13~26 ~43~13~46 minecraft:stained_hardened_clay 12
setblock ~38~14~26 minecraft:coal_block
fill ~38~24~26 ~41~24~26 minecraft:wool 12
setblock ~38~25~26 minecraft:wool 7
fill ~39~4~26 ~41~5~43 minecraft:stained_hardened_clay 12
setblock ~39~7~26 minecraft:wool 12
fill ~39~10~26 ~41~10~46 minecraft:stained_hardened_clay 12
setblock ~39~15~26 minecraft:wool 12
fill ~39~23~26 ~40~23~29 minecraft:wool 12
setblock ~39~25~26 minecraft:wool 12
fill ~40~3~26 ~40~3~41 minecraft:stained_hardened_clay 12
setblock ~40~6~26 minecraft:wool 12
fill ~40~7~26 ~40~8~43 minecraft:stained_hardened_clay 12
fill ~40~12~26 ~43~12~46 minecraft:stained_hardened_clay 12
fill ~40~15~26 ~43~15~45 minecraft:stained_hardened_clay 12
fill ~40~25~26 ~40~25~28 minecraft:wool 7
fill ~40~26~26 ~40~26~27 minecraft:stained_hardened_clay 12
fill ~41~0~26 ~41~2~38 minecraft:stained_hardened_clay 12
fill ~41~6~26 ~42~6~28 minecraft:stained_hardened_clay 12
setblock ~41~7~26 minecraft:wool 12
fill ~41~8~26 ~41~8~43 minecraft:stained_hardened_clay 12
fill ~41~9~26 ~44~9~26 minecraft:wool 12
fill ~41~11~26 ~41~11~47 minecraft:stained_hardened_clay 12
fill ~41~21~26 ~41~22~28 minecraft:wool 12
fill ~41~25~26 ~41~25~28 minecraft:stained_hardened_clay 12
fill ~42~7~26 ~43~7~28 minecraft:stained_hardened_clay 12
fill ~42~10~26 ~44~10~26 minecraft:wool 12
setblock ~42~11~26 minecraft:wool 12
fill ~42~24~26 ~42~24~29 minecraft:stained_hardened_clay 12
fill ~43~5~26 ~43~5~27 minecraft:stained_hardened_clay 12
fill ~43~8~26 ~44~8~27 minecraft:wool 12
fill ~43~16~26 ~45~16~45 minecraft:stained_hardened_clay 12
fill ~44~11~26 ~44~11~27 minecraft:wool 12
setblock ~44~12~26 minecraft:wool 12
setblock ~44~13~26 minecraft:wool 7
setblock ~44~15~26 minecraft:wool 7
fill ~44~17~26 ~48~17~44 minecraft:stained_hardened_clay 12
fill ~44~21~26 ~45~21~32 minecraft:stained_hardened_clay 12
fill ~44~22~26 ~44~22~30 minecraft:stained_hardened_clay 12
setblock ~45~14~26 minecraft:wool 7
fill ~45~15~26 ~47~15~47 minecraft:stained_hardened_clay 12
fill ~45~20~26 ~47~20~40 minecraft:stained_hardened_clay 12
setblock ~47~13~26 minecraft:stained_hardened_clay 12
fill ~47~19~26 ~47~19~41 minecraft:stained_hardened_clay 12
setblock ~47~22~26 minecraft:stained_hardened_clay 12
setblock ~48~11~26 minecraft:stained_hardened_clay 12
fill ~48~18~26 ~50~18~26 minecraft:stained_hardened_clay 12
setblock ~49~13~26 minecraft:stained_hardened_clay 12
fill ~50~14~26 ~50~15~26 minecraft:stained_hardened_clay 12
fill ~50~17~26 ~51~17~26 minecraft:stained_hardened_clay 12
fill ~50~19~26 ~50~19~27 minecraft:stained_hardened_clay 12
fill ~51~6~26 ~52~6~106 minecraft:stained_hardened_clay 12
setblock ~51~7~26 minecraft:wool 12
fill ~51~16~26 ~51~16~28 minecraft:stained_hardened_clay 12
fill ~52~7~26 ~53~7~103 minecraft:stained_hardened_clay 12
setblock ~52~8~26 minecraft:wool 12
fill ~53~8~26 ~53~8~104 minecraft:stained_hardened_clay 12
fill ~53~9~26 ~53~10~27 minecraft:wool 12
fill ~54~9~26 ~54~9~102 minecraft:stained_hardened_clay 12
fill ~54~10~26 ~54~10~28 minecraft:wool 12
setblock ~55~9~26 minecraft:wool 12
fill ~56~9~26 ~56~9~95 minecraft:stained_hardened_clay 12
fill ~56~13~26 ~58~13~36 minecraft:wool 12
fill ~57~14~26 ~58~14~37 minecraft:wool 12
fill ~58~12~26 ~58~12~35 minecraft:wool 12
fill ~59~12~26 ~62~12~28 minecraft:stained_hardened_clay 12
fill ~59~13~26 ~61~13~27 minecraft:stained_hardened_clay 12
fill ~59~14~26 ~60~14~28 minecraft:stained_hardened_clay 12
fill ~60~0~26 ~60~0~93 minecraft:stained_hardened_clay 12
fill ~62~1~26 ~62~1~94 minecraft:stained_hardened_clay 12
fill ~62~11~26 ~63~11~86 minecraft:stained_hardened_clay 12
fill ~63~2~26 ~63~2~92 minecraft:stained_hardened_clay 12
fill ~63~9~26 ~63~9~87 minecraft:stained_hardened_clay 12
fill ~63~10~26 ~63~10~86 minecraft:stained_hardened_clay 12
fill ~64~4~26 ~64~6~92 minecraft:stained_hardened_clay 12
fill ~64~7~26 ~64~7~89 minecraft:stained_hardened_clay 12
fill ~64~8~26 ~64~8~87 minecraft:stained_hardened_clay 12
fill ~29~4~27 ~31~5~29 minecraft:wool 12
fill ~29~6~27 ~34~6~27 minecraft:wool 12
fill ~30~7~27 ~32~8~28 minecraft:wool 12
fill ~31~3~27 ~32~3~29 minecraft:wool 12
fill ~32~2~27 ~32~2~35 minecraft:wool 12
fill ~32~5~27 ~34~5~27 minecraft:wool 12
fill ~32~9~27 ~33~9~28 minecraft:wool 12
setblock ~33~1~27 minecraft:stained_hardened_clay 12
fill ~33~8~27 ~34~8~27 minecraft:wool 12
setblock ~33~10~27 minecraft:stained_hardened_clay 12
setblock ~34~7~27 minecraft:wool 12
fill ~34~9~27 ~35~9~45 minecraft:stained_hardened_clay 12
fill ~34~11~27 ~34~12~28 minecraft:wool 12
fill ~35~3~27 ~38~3~40 minecraft:stained_hardened_clay 12
fill ~35~5~27 ~38~5~41 minecraft:stained_hardened_clay 12
fill ~35~6~27 ~35~8~42 minecraft:stained_hardened_clay 12
fill ~35~11~27 ~37~11~45 minecraft:stained_hardened_clay 12
setblock ~35~12~27 minecraft:wool 12
fill ~36~4~27 ~36~4~41 minecraft:stained_hardened_clay 12
fill ~36~7~27 ~36~7~43 minecraft:stained_hardened_clay 12
fill ~36~12~27 ~36~12~43 minecraft:stained_hardened_clay 12
fill ~36~16~27 ~38~16~28 minecraft:wool 12
fill ~37~9~27 ~37~9~46 minecraft:stained_hardened_clay 12
fill ~37~13~27 ~37~14~28 minecraft:coal_block
fill ~37~17~27 ~38~17~29 minecraft:wool 12
fill ~38~4~27 ~38~4~43 minecraft:stained_hardened_clay 12
fill ~38~8~27 ~39~8~43 minecraft:stained_hardened_clay 12
fill ~38~10~27 ~38~10~46 minecraft:stained_hardened_clay 12
setblock ~38~14~27 minecraft:wool 12
setblock ~38~15~27 minecraft:coal_block
fill ~38~23~27 ~38~23~28 minecraft:wool 12
fill ~38~24~27 ~40~24~27 minecraft:wool 12
fill ~39~7~27 ~39~7~29 minecraft:stained_hardened_clay 12
fill ~39~15~27 ~39~15~45 minecraft:stained_hardened_clay 12
fill ~39~22~27 ~40~22~29 minecraft:wool 12
fill ~39~25~27 ~39~25~28 minecraft:wool 7
fill ~40~6~27 ~40~6~42 minecraft:stained_hardened_clay 12
fill ~41~3~27 ~41~3~42 minecraft:stained_hardened_clay 12
fill ~41~7~27 ~41~7~43 minecraft:stained_hardened_clay 12
fill ~41~9~27 ~42~9~47 minecraft:stained_hardened_clay 12
fill ~41~24~27 ~41~24~30 minecraft:stained_hardened_clay 12
fill ~42~0~27 ~42~2~40 minecraft:stained_hardened_clay 12
fill ~42~8~27 ~42~8~44 minecraft:stained_hardened_clay 12
fill ~42~10~27 ~42~11~47 minecraft:stained_hardened_clay 12
fill ~42~19~27 ~42~19~44 minecraft:stained_hardened_clay 12
fill ~42~20~27 ~42~21~27 minecraft:wool 12
fill ~43~9~27 ~45~10~27 minecraft:wool 12
fill ~43~14~27 ~48~14~46 minecraft:stained_hardened_clay 12
fill ~43~20~27 ~43~20~43 minecraft:stained_hardened_clay 12
fill ~43~21~27 ~43~21~42 minecraft:stained_hardened_clay 12
fill ~43~22~27 ~43~22~32 minecraft:stained_hardened_clay 12
fill ~43~23~27 ~43~23~29 minecraft:stained_hardened_clay 12
fill ~44~12~27 ~45~13~47 minecraft:stained_hardened_clay 12
fill ~44~15~27 ~44~15~46 minecraft:stained_hardened_clay 12
setblock ~45~11~27 minecraft:wool 12
fill ~46~11~27 ~47~11~51 minecraft:stained_hardened_clay 12
fill ~46~13~27 ~46~13~54 minecraft:stained_hardened_clay 12
fill ~46~21~27 ~47~21~30 minecraft:stained_hardened_clay 12
setblock ~46~22~27 minecraft:stained_hardened_clay 12
fill ~47~10~27 ~47~10~108 minecraft:stained_hardened_clay 12
setblock ~48~13~27 minecraft:stained_hardened_clay 12
fill ~48~16~27 ~49~16~97 minecraft:stained_hardened_clay 12
fill ~48~18~27 ~48~18~44 minecraft:stained_hardened_clay 12
fill ~48~19~27 ~49~20~27 minecraft:stained_hardened_clay 12
setblock ~48~22~27 minecraft:stained_hardened_clay 12
fill ~49~17~27 ~50~17~97 minecraft:stained_hardened_clay 12
fill ~50~5~27 ~51~5~27 minecraft:stained_hardened_clay 12
fill ~50~6~27 ~50~9~28 minecraft:stained_hardened_clay 12
fill ~50~12~27 ~50~12~106 minecraft:stained_hardened_clay 12
fill ~51~7~27 ~51~8~106 minecraft:stained_hardened_clay 12
fill ~51~10~27 ~51~12~27 minecraft:wool 12
setblock ~51~15~27 minecraft:stained_hardened_clay 12
fill ~52~8~27 ~52~8~106 minecraft:stained_hardened_clay 12
setblock ~52~12~27 minecraft:wool 12
fill ~55~9~27 ~55~9~101 minecraft:stained_hardened_clay 12
fill ~55~13~27 ~55~13~31 minecraft:wool 12
fill ~56~14~27 ~56~14~29 minecraft:wool 12
fill ~58~11~27 ~58~11~29 minecraft:wool 12
fill ~58~15~27 ~58~15~29 minecraft:wool 12
fill ~59~15~27 ~59~15~28 minecraft:stained_hardened_clay 12
fill ~61~14~27 ~62~14~30 minecraft:stained_hardened_clay 12
fill ~62~13~27 ~63~13~86 minecraft:stained_hardened_clay 12
fill ~63~12~27 ~63~12~86 minecraft:stained_hardened_clay 12
fill ~64~3~27 ~64~3~91 minecraft:stained_hardened_clay 12
fill ~64~9~27 ~64~9~86 minecraft:stained_hardened_clay 12
fill ~64~10~27 ~64~10~83 minecraft:stained_hardened_clay 12
fill ~64~11~27 ~64~11~82 minecraft:stained_hardened_clay 12
fill ~65~4~27 ~65~6~92 minecraft:stained_hardened_clay 12
fill ~65~7~27 ~65~7~88 minecraft:stained_hardened_clay 12
fill ~65~8~27 ~65~8~87 minecraft:stained_hardened_clay 12
fill ~28~5~28 ~28~5~30 minecraft:wool 12
fill ~28~6~28 ~33~6~28 minecraft:wool 12
fill ~28~7~28 ~29~8~29 minecraft:wool 12
fill ~29~9~28 ~31~9~28 minecraft:wool 12
fill ~30~10~28 ~33~10~28 minecraft:wool 12
fill ~32~4~28 ~32~5~29 minecraft:wool 12
fill ~32~11~28 ~33~11~29 minecraft:wool 12
fill ~33~1~28 ~33~1~35 minecraft:wool 12
fill ~33~2~28 ~34~2~28 minecraft:stained_hardened_clay 12
setblock ~33~5~28 minecraft:wool 12
setblock ~33~8~28 minecraft:wool 12
fill ~33~12~28 ~33~12~30 minecraft:wool 12
fill ~34~3~28 ~34~8~40 minecraft:stained_hardened_clay 12
fill ~35~4~28 ~35~4~40 minecraft:stained_hardened_clay 12
fill ~35~12~28 ~35~12~39 minecraft:stained_hardened_clay 12
fill ~35~17~28 ~36~17~29 minecraft:wool 12
fill ~36~13~28 ~36~13~29 minecraft:coal_block
fill ~37~4~28 ~37~4~42 minecraft:stained_hardened_clay 12
setblock ~37~15~28 minecraft:coal_block
fill ~38~14~28 ~38~15~45 minecraft:stained_hardened_clay 12
fill ~38~18~28 ~39~18~29 minecraft:wool 12
setblock ~38~24~28 minecraft:wool 7
fill ~39~16~28 ~39~16~45 minecraft:stained_hardened_clay 12
fill ~39~17~28 ~39~17~29 minecraft:wool 12
fill ~39~21~28 ~40~21~29 minecraft:wool 12
setblock ~39~24~28 minecraft:wool 12
fill ~40~24~28 ~40~24~30 minecraft:wool 7
fill ~41~18~28 ~41~20~44 minecraft:stained_hardened_clay 12
fill ~41~23~28 ~42~23~30 minecraft:stained_hardened_clay 12
fill ~42~3~28 ~42~3~45 minecraft:stained_hardened_clay 12
fill ~42~4~28 ~42~4~44 minecraft:stained_hardened_clay 12
fill ~42~20~28 ~42~21~44 minecraft:stained_hardened_clay 12
fill ~42~22~28 ~42~22~33 minecraft:stained_hardened_clay 12
fill ~43~0~28 ~43~2~41 minecraft:stained_hardened_clay 12
fill ~43~8~28 ~45~8~28 minecraft:stained_hardened_clay 12
fill ~43~9~28 ~43~9~49 minecraft:stained_hardened_clay 12
fill ~43~10~28 ~43~11~47 minecraft:stained_hardened_clay 12
fill ~44~1~28 ~45~1~41 minecraft:stained_hardened_clay 12
fill ~44~2~28 ~44~2~41 minecraft:stained_hardened_clay 12
setblock ~44~7~28 minecraft:stained_hardened_clay 12
fill ~44~9~28 ~44~10~28 minecraft:wool 12
fill ~44~11~28 ~45~11~47 minecraft:stained_hardened_clay 12
fill ~45~9~28 ~48~9~28 minecraft:stained_hardened_clay 12
fill ~45~10~28 ~46~10~49 minecraft:stained_hardened_clay 12
fill ~46~12~28 ~47~12~59 minecraft:stained_hardened_clay 12
fill ~46~23~28 ~48~23~28 minecraft:stained_hardened_clay 12
fill ~48~15~28 ~48~15~98 minecraft:stained_hardened_clay 12
fill ~48~19~28 ~48~19~40 minecraft:stained_hardened_clay 12
fill ~48~20~28 ~49~20~28 minecraft:stained_hardened_clay 12
fill ~49~13~28 ~49~13~100 minecraft:stained_hardened_clay 12
fill ~49~14~28 ~50~14~98 minecraft:stained_hardened_clay 12
fill ~49~18~28 ~50~18~28 minecraft:stained_hardened_clay 12
fill ~49~21~28 ~49~22~28 minecraft:stained_hardened_clay 12
fill ~50~10~28 ~51~10~103 minecraft:stained_hardened_clay 12
fill ~50~11~28 ~52~11~102 minecraft:stained_hardened_clay 12
fill ~50~15~28 ~50~15~97 minecraft:stained_hardened_clay 12
setblock ~51~5~28 minecraft:stained_hardened_clay 12
fill ~51~9~28 ~53~9~103 minecraft:stained_hardened_clay 12
fill ~51~12~28 ~52~12~101 minecraft:stained_hardened_clay 12
setblock ~52~10~28 minecraft:wool 12
fill ~53~10~28 ~53~10~102 minecraft:stained_hardened_clay 12
fill ~53~11~28 ~57~11~29 minecraft:wool 12
setblock ~54~0~28 minecraft:stained_hardened_clay 12
fill ~57~10~28 ~57~10~92 minecraft:stained_hardened_clay 12
fill ~59~13~28 ~59~13~37 minecraft:wool 12
fill ~60~13~28 ~61~13~28 minecraft:stained_hardened_clay 12
fill ~60~15~28 ~61~15~28 minecraft:stained_hardened_clay 12
fill ~61~0~28 ~61~0~93 minecraft:stained_hardened_clay 12
fill ~63~1~28 ~63~1~93 minecraft:stained_hardened_clay 12
fill ~63~14~28 ~63~14~86 minecraft:stained_hardened_clay 12
fill ~64~2~28 ~64~2~91 minecraft:stained_hardened_clay 12
fill ~64~12~28 ~65~12~81 minecraft:stained_hardened_clay 12
fill ~64~13~28 ~64~13~82 minecraft:stained_hardened_clay 12
fill ~65~3~28 ~65~3~91 minecraft:stained_hardened_clay 12
fill ~65~9~28 ~66~9~81 minecraft:stained_hardened_clay 12
fill ~65~10~28 ~66~10~80 minecraft:stained_hardened_clay 12
fill ~65~11~28 ~65~11~81 minecraft:stained_hardened_clay 12
fill ~66~5~28 ~66~8~31 minecraft:stained_hardened_clay 12
fill ~24~6~29 ~27~7~30 minecraft:wool 12
fill ~25~4~29 ~28~4~30 minecraft:wool 12
fill ~25~5~29 ~27~5~30 minecraft:wool 12
fill ~25~8~29 ~27~8~30 minecraft:wool 12
fill ~26~9~29 ~30~9~29 minecraft:wool 12
fill ~27~3~29 ~30~3~31 minecraft:wool 12
fill ~28~6~29 ~29~6~36 minecraft:stained_hardened_clay 12
fill ~28~10~29 ~29~10~37 minecraft:stained_hardened_clay 12
fill ~30~6~29 ~30~8~29 minecraft:wool 12
setblock ~30~10~29 minecraft:wool 12
fill ~30~11~29 ~31~11~34 minecraft:stained_hardened_clay 12
fill ~31~6~29 ~33~7~38 minecraft:stained_hardened_clay 12
fill ~31~8~29 ~31~9~38 minecraft:stained_hardened_clay 12
fill ~31~10~29 ~31~10~35 minecraft:stained_hardened_clay 12
setblock ~32~8~29 minecraft:wool 12
fill ~32~9~29 ~33~9~39 minecraft:stained_hardened_clay 12
setblock ~32~10~29 minecraft:wool 12
fill ~32~12~29 ~32~12~30 minecraft:wool 12
fill ~33~2~29 ~34~2~32 minecraft:wool 12
fill ~33~3~29 ~33~5~29 minecraft:stained_hardened_clay 12
fill ~33~8~29 ~33~8~41 minecraft:stained_hardened_clay 12
fill ~33~10~29 ~33~10~39 minecraft:stained_hardened_clay 12
fill ~34~1~29 ~34~1~35 minecraft:wool 12
fill ~34~11~29 ~34~11~38 minecraft:stained_hardened_clay 12
setblock ~34~12~29 minecraft:wool 12
fill ~34~16~29 ~36~16~30 minecraft:wool 12
fill ~35~13~29 ~35~13~30 minecraft:coal_block
setblock ~35~14~29 minecraft:skull 4
fill ~35~15~29 ~36~15~29 minecraft:coal_block
setblock ~36~14~29 minecraft:coal_block
fill ~37~13~29 ~37~15~45 minecraft:stained_hardened_clay 12
fill ~37~16~29 ~38~16~31 minecraft:stained_hardened_clay 12
setblock ~37~18~29 minecraft:wool 12
fill ~38~19~29 ~39~19~29 minecraft:wool 12
setblock ~38~22~29 minecraft:wool 12
fill ~39~20~29 ~40~20~29 minecraft:wool 12
setblock ~39~24~29 minecraft:wool 7
fill ~40~17~29 ~40~19~45 minecraft:stained_hardened_clay 12
fill ~41~6~29 ~41~6~43 minecraft:stained_hardened_clay 12
fill ~41~21~29 ~41~21~34 minecraft:stained_hardened_clay 12
fill ~41~22~29 ~41~22~33 minecraft:stained_hardened_clay 12
fill ~42~7~29 ~42~7~43 minecraft:stained_hardened_clay 12
fill ~43~3~29 ~45~3~43 minecraft:stained_hardened_clay 12
fill ~43~4~29 ~43~4~57 minecraft:stained_hardened_clay 12
fill ~43~8~29 ~43~8~51 minecraft:stained_hardened_clay 12
fill ~44~0~29 ~45~0~40 minecraft:stained_hardened_clay 12
fill ~44~9~29 ~47~9~29 minecraft:stained_hardened_clay 12
fill ~44~10~29 ~44~10~48 minecraft:stained_hardened_clay 12
fill ~45~2~29 ~46~2~41 minecraft:stained_hardened_clay 12
fill ~47~13~29 ~48~13~100 minecraft:stained_hardened_clay 12
fill ~48~8~29 ~50~8~29 minecraft:stained_hardened_clay 12
fill ~48~10~29 ~49~12~106 minecraft:stained_hardened_clay 12
fill ~48~20~29 ~48~20~39 minecraft:stained_hardened_clay 12
fill ~48~22~29 ~48~23~29 minecraft:stained_hardened_clay 12
fill ~49~7~29 ~50~7~29 minecraft:stained_hardened_clay 12
fill ~49~9~29 ~50~9~106 minecraft:stained_hardened_clay 12
fill ~49~15~29 ~49~15~98 minecraft:stained_hardened_clay 12
fill ~49~18~29 ~49~18~42 minecraft:stained_hardened_clay 12
fill ~49~19~29 ~49~19~38 minecraft:stained_hardened_clay 12
fill ~50~13~29 ~52~13~99 minecraft:stained_hardened_clay 12
fill ~50~16~29 ~50~16~97 minecraft:stained_hardened_clay 12
fill ~51~18~29 ~51~19~29 minecraft:stained_hardened_clay 12
fill ~52~10~29 ~52~10~102 minecraft:stained_hardened_clay 12
setblock ~52~17~29 minecraft:stained_hardened_clay 12
fill ~53~2~29 ~54~2~103 minecraft:stained_hardened_clay 12
fill ~53~13~29 ~54~13~30 minecraft:wool 12
fill ~54~1~29 ~54~1~102 minecraft:stained_hardened_clay 12
fill ~54~10~29 ~56~10~94 minecraft:stained_hardened_clay 12
fill ~59~12~29 ~59~12~33 minecraft:wool 12
fill ~59~14~29 ~60~15~37 minecraft:wool 12
fill ~60~12~29 ~62~12~29 minecraft:stained_hardened_clay 12
fill ~60~13~29 ~60~13~36 minecraft:wool 12
fill ~61~13~29 ~61~13~88 minecraft:stained_hardened_clay 12
fill ~61~15~29 ~63~15~32 minecraft:stained_hardened_clay 12
fill ~64~14~29 ~65~14~81 minecraft:stained_hardened_clay 12
fill ~65~13~29 ~65~13~81 minecraft:stained_hardened_clay 12
fill ~66~4~29 ~66~4~32 minecraft:stained_hardened_clay 12
fill ~66~11~29 ~67~11~79 minecraft:stained_hardened_clay 12
fill ~66~12~29 ~66~12~80 minecraft:stained_hardened_clay 12
fill ~67~6~29 ~67~10~30 minecraft:stained_hardened_clay 12
fill ~68~9~29 ~68~9~80 minecraft:stained_hardened_clay 12
fill ~22~5~30 ~24~5~32 minecraft:coal_block
fill ~22~6~30 ~23~7~30 minecraft:stained_hardened_clay 12
fill ~23~4~30 ~24~4~33 minecraft:coal_block
fill ~23~8~30 ~24~8~35 minecraft:stained_hardened_clay 12
fill ~24~3~30 ~24~3~33 minecraft:coal_block
fill ~24~9~30 ~30~9~35 minecraft:stained_hardened_clay 12
fill ~25~2~30 ~25~2~31 minecraft:wool 12
fill ~25~3~30 ~26~3~30 minecraft:wool 12
fill ~25~10~30 ~27~10~35 minecraft:stained_hardened_clay 12
fill ~28~7~30 ~30~7~36 minecraft:stained_hardened_clay 12
fill ~28~8~30 ~29~8~30 minecraft:wool 12
fill ~28~11~30 ~29~11~36 minecraft:stained_hardened_clay 12
fill ~29~4~30 ~29~5~30 minecraft:stained_hardened_clay 12
fill ~30~2~30 ~31~2~33 minecraft:wool 12
setblock ~30~4~30 minecraft:wool 12
fill ~30~5~30 ~33~5~36 minecraft:stained_hardened_clay 12
fill ~30~6~30 ~30~6~38 minecraft:stained_hardened_clay 12
fill ~30~8~30 ~30~8~38 minecraft:stained_hardened_clay 12
fill ~30~10~30 ~30~10~38 minecraft:stained_hardened_clay 12
fill ~30~12~30 ~31~12~33 minecraft:stained_hardened_clay 12
fill ~31~3~30 ~31~3~33 minecraft:wool 12
fill ~31~4~30 ~33~4~31 minecraft:stained_hardened_clay 12
setblock ~32~3~30 minecraft:stained_hardened_clay 12
fill ~32~8~30 ~32~8~40 minecraft:stained_hardened_clay 12
fill ~32~10~30 ~32~10~40 minecraft:stained_hardened_clay 12
fill ~32~11~30 ~33~11~34 minecraft:stained_hardened_clay 12
fill ~32~13~30 ~32~13~34 minecraft:stained_hardened_clay 12
setblock ~33~3~30 minecraft:wool 12
fill ~33~13~30 ~34~13~30 minecraft:coal_block
fill ~33~15~30 ~34~15~31 minecraft:wool 12
fill ~34~0~30 ~35~0~33 minecraft:wool 12
fill ~34~12~30 ~34~12~38 minecraft:stained_hardened_clay 12
fill ~34~14~30 ~35~14~30 minecraft:coal_block
fill ~35~1~30 ~35~1~35 minecraft:wool 12
fill ~36~13~30 ~36~14~43 minecraft:stained_hardened_clay 12
fill ~36~15~30 ~36~15~41 minecraft:stained_hardened_clay 12
setblock ~36~17~30 minecraft:wool 12
fill ~37~17~30 ~39~17~31 minecraft:stained_hardened_clay 12
fill ~37~18~30 ~37~18~32 minecraft:stained_hardened_clay 12
setblock ~38~18~30 minecraft:wool 12
fill ~38~19~30 ~39~19~30 minecraft:stained_hardened_clay 12
fill ~38~20~30 ~39~20~33 minecraft:wool 7
fill ~38~21~30 ~38~21~31 minecraft:wool 7
setblock ~38~22~30 minecraft:wool 7
fill ~39~18~30 ~39~18~41 minecraft:stained_hardened_clay 12
fill ~39~21~30 ~39~22~30 minecraft:wool 12
fill ~39~23~30 ~40~23~30 minecraft:wool 7
fill ~40~20~30 ~40~20~45 minecraft:stained_hardened_clay 12
setblock ~40~21~30 minecraft:stained_hardened_clay 12
fill ~40~22~30 ~40~22~32 minecraft:wool 7
fill ~43~5~30 ~44~5~58 minecraft:stained_hardened_clay 12
fill ~43~7~30 ~43~7~58 minecraft:stained_hardened_clay 12
fill ~44~4~30 ~45~4~57 minecraft:stained_hardened_clay 12
fill ~44~9~30 ~44~9~49 minecraft:stained_hardened_clay 12
fill ~46~1~30 ~47~1~41 minecraft:stained_hardened_clay 12
fill ~46~3~30 ~46~3~46 minecraft:stained_hardened_clay 12
fill ~46~22~30 ~46~22~32 minecraft:stained_hardened_clay 12
setblock ~46~24~30 minecraft:stained_hardened_clay 12
fill ~47~2~30 ~47~2~42 minecraft:stained_hardened_clay 12
fill ~47~9~30 ~48~9~107 minecraft:stained_hardened_clay 12
fill ~48~21~30 ~50~21~30 minecraft:stained_hardened_clay 12
setblock ~49~22~30 minecraft:stained_hardened_clay 12
fill ~50~5~30 ~51~5~106 minecraft:stained_hardened_clay 12
fill ~50~7~30 ~50~8~106 minecraft:stained_hardened_clay 12
fill ~50~18~30 ~50~18~39 minecraft:stained_hardened_clay 12
fill ~50~19~30 ~50~19~37 minecraft:stained_hardened_clay 12
fill ~51~14~30 ~52~15~30 minecraft:stained_hardened_clay 12
fill ~52~3~30 ~52~3~106 minecraft:stained_hardened_clay 12
setblock ~52~18~30 minecraft:stained_hardened_clay 12
fill ~53~11~30 ~53~11~101 minecraft:stained_hardened_clay 12
fill ~54~11~30 ~57~11~30 minecraft:wool 12
setblock ~58~11~30 minecraft:stained_hardened_clay 12
fill ~60~12~30 ~60~12~32 minecraft:wool 12
fill ~61~12~30 ~62~12~87 minecraft:stained_hardened_clay 12
fill ~62~0~30 ~62~0~93 minecraft:stained_hardened_clay 12
fill ~65~2~30 ~65~2~90 minecraft:stained_hardened_clay 12
fill ~66~13~30 ~67~13~79 minecraft:stained_hardened_clay 12
setblock ~67~5~30 minecraft:stained_hardened_clay 12
fill ~67~12~30 ~67~12~79 minecraft:stained_hardened_clay 12
fill ~68~8~30 ~68~8~81 minecraft:stained_hardened_clay 12
fill ~68~10~30 ~68~11~79 minecraft:stained_hardened_clay 12
fill ~19~5~31 ~19~6~31 minecraft:wool 7
fill ~20~3~31 ~23~3~35 minecraft:coal_block
fill ~20~4~31 ~22~4~35 minecraft:coal_block
fill ~20~5~31 ~21~6~35 minecraft:coal_block
fill ~21~7~31 ~21~7~35 minecraft:coal_block
fill ~22~6~31 ~22~6~35 minecraft:coal_block
fill ~22~7~31 ~25~7~32 minecraft:stained_hardened_clay 12
fill ~22~8~31 ~22~8~35 minecraft:stained_hardened_clay 12
fill ~22~9~31 ~23~9~34 minecraft:stained_hardened_clay 12
fill ~23~6~31 ~24~6~33 minecraft:stained_hardened_clay 12
fill ~24~2~31 ~24~2~33 minecraft:coal_block
fill ~24~10~31 ~24~10~35 minecraft:stained_hardened_clay 12
setblock ~25~3~31 minecraft:coal_block
fill ~25~4~31 ~27~4~31 minecraft:wool 12
fill ~25~5~31 ~25~6~31 minecraft:wool 12
fill ~25~8~31 ~29~8~35 minecraft:stained_hardened_clay 12
fill ~26~2~31 ~29~2~31 minecraft:wool 12
fill ~26~3~31 ~26~3~32 minecraft:wool 12
fill ~26~5~31 ~29~5~35 minecraft:stained_hardened_clay 12
fill ~26~6~31 ~27~6~35 minecraft:stained_hardened_clay 12
setblock ~26~7~31 minecraft:wool 12
fill ~26~11~31 ~27~11~35 minecraft:stained_hardened_clay 12
fill ~27~7~31 ~27~7~35 minecraft:stained_hardened_clay 12
fill ~28~4~31 ~28~4~36 minecraft:stained_hardened_clay 12
setblock ~29~4~31 minecraft:wool 12
fill ~29~12~31 ~29~12~35 minecraft:stained_hardened_clay 12
fill ~30~4~31 ~30~4~36 minecraft:stained_hardened_clay 12
fill ~31~13~31 ~31~13~33 minecraft:stained_hardened_clay 12
fill ~32~1~31 ~32~1~35 minecraft:wool 12
fill ~32~3~31 ~32~3~34 minecraft:wool 12
fill ~32~12~31 ~33~12~34 minecraft:stained_hardened_clay 12
fill ~32~14~31 ~34~14~31 minecraft:wool 12
fill ~33~3~31 ~33~3~38 minecraft:stained_hardened_clay 12
fill ~33~13~31 ~35~13~34 minecraft:stained_hardened_clay 12
fill ~33~16~31 ~34~16~31 minecraft:wool 12
setblock ~34~17~31 minecraft:stained_hardened_clay 12
fill ~35~14~31 ~35~14~43 minecraft:stained_hardened_clay 12
fill ~35~15~31 ~35~15~42 minecraft:stained_hardened_clay 12
setblock ~35~16~31 minecraft:stained_hardened_clay 12
setblock ~35~17~31 minecraft:wool 12
fill ~36~0~31 ~36~0~35 minecraft:wool 12
fill ~36~16~31 ~36~16~34 minecraft:wool 7
setblock ~36~17~31 minecraft:stained_hardened_clay 12
fill ~37~19~31 ~38~19~31 minecraft:stained_hardened_clay 12
setblock ~38~18~31 minecraft:stained_hardened_clay 12
fill ~39~7~31 ~39~7~43 minecraft:stained_hardened_clay 12
fill ~39~19~31 ~39~19~32 minecraft:wool 7
fill ~39~21~31 ~40~21~31 minecraft:wool 7
fill ~39~22~31 ~39~22~32 minecraft:wool 7
setblock ~41~23~31 minecraft:stained_hardened_clay 12
fill ~42~5~31 ~42~5~43 minecraft:stained_hardened_clay 12
fill ~44~6~31 ~44~6~58 minecraft:stained_hardened_clay 12
fill ~44~7~31 ~45~8~57 minecraft:stained_hardened_clay 12
fill ~45~5~31 ~46~5~58 minecraft:stained_hardened_clay 12
fill ~45~9~31 ~46~9~50 minecraft:stained_hardened_clay 12
setblock ~45~23~31 minecraft:stained_hardened_clay 12
fill ~46~0~31 ~46~0~41 minecraft:stained_hardened_clay 12
fill ~46~4~31 ~47~4~58 minecraft:stained_hardened_clay 12
fill ~46~21~31 ~46~21~32 minecraft:stained_hardened_clay 12
fill ~47~3~31 ~48~3~58 minecraft:stained_hardened_clay 12
fill ~47~22~31 ~48~22~31 minecraft:stained_hardened_clay 12
fill ~48~1~31 ~48~2~44 minecraft:stained_hardened_clay 12
fill ~48~5~31 ~49~5~110 minecraft:stained_hardened_clay 12
fill ~48~21~31 ~49~21~31 minecraft:stained_hardened_clay 12
setblock ~48~24~31 minecraft:stained_hardened_clay 12
fill ~49~4~31 ~51~4~108 minecraft:stained_hardened_clay 12
fill ~49~6~31 ~50~6~106 minecraft:stained_hardened_clay 12
fill ~49~7~31 ~49~7~107 minecraft:stained_hardened_clay 12
fill ~50~20~31 ~51~20~31 minecraft:stained_hardened_clay 12
setblock ~50~22~31 minecraft:stained_hardened_clay 12
fill ~51~14~31 ~51~15~98 minecraft:stained_hardened_clay 12
fill ~51~16~31 ~51~16~97 minecraft:stained_hardened_clay 12
setblock ~51~18~31 minecraft:stained_hardened_clay 12
fill ~52~2~31 ~52~2~105 minecraft:stained_hardened_clay 12
fill ~52~14~31 ~53~14~32 minecraft:wool 7
setblock ~52~15~31 minecraft:wool 7
setblock ~52~19~31 minecraft:stained_hardened_clay 12
fill ~53~12~31 ~55~12~99 minecraft:stained_hardened_clay 12
fill ~53~13~31 ~53~13~33 minecraft:wool 7
fill ~54~11~31 ~57~11~92 minecraft:stained_hardened_clay 12
setblock ~54~13~31 minecraft:stained_hardened_clay 12
fill ~55~0~31 ~55~0~94 minecraft:stained_hardened_clay 12
fill ~56~12~31 ~57~12~32 minecraft:wool 12
setblock ~58~11~31 minecraft:wool 12
setblock ~61~14~31 minecraft:wool 12
fill ~62~14~31 ~62~14~33 minecraft:stained_hardened_clay 12
fill ~64~1~31 ~64~1~91 minecraft:stained_hardened_clay 12
fill ~66~3~31 ~66~3~33 minecraft:stained_hardened_clay 12
fill ~66~14~31 ~66~14~80 minecraft:stained_hardened_clay 12
fill ~67~4~31 ~67~4~35 minecraft:wool 12
fill ~67~5~31 ~67~5~34 minecraft:wool 12
fill ~67~6~31 ~68~6~33 minecraft:wool 12
fill ~67~7~31 ~68~7~31 minecraft:stained_hardened_clay 12
fill ~67~8~31 ~67~8~81 minecraft:stained_hardened_clay 12
fill ~67~9~31 ~67~10~80 minecraft:stained_hardened_clay 12
fill ~68~12~31 ~68~12~79 minecraft:stained_hardened_clay 12
fill ~69~9~31 ~69~9~80 minecraft:stained_hardened_clay 12
fill ~69~10~31 ~69~10~35 minecraft:stained_hardened_clay 12
fill ~69~11~31 ~69~11~34 minecraft:stained_hardened_clay 12
fill ~19~6~32 ~19~6~35 minecraft:wool 7
fill ~19~7~32 ~19~7~34 minecraft:wool 7
fill ~20~7~32 ~20~7~34 minecraft:coal_block
fill ~20~8~32 ~21~8~33 minecraft:stained_hardened_clay 12
fill ~21~2~32 ~23~2~34 minecraft:coal_block
fill ~23~10~32 ~23~10~34 minecraft:stained_hardened_clay 12
fill ~25~1~32 ~25~2~34 minecraft:stained_hardened_clay 12
setblock ~25~3~32 minecraft:wool 12
fill ~25~4~32 ~27~4~35 minecraft:stained_hardened_clay 12
fill ~25~5~32 ~25~5~35 minecraft:stained_hardened_clay 12
fill ~25~6~32 ~25~6~34 minecraft:stained_hardened_clay 12
fill ~25~11~32 ~25~11~34 minecraft:stained_hardened_clay 12
fill ~26~2~32 ~27~2~35 minecraft:stained_hardened_clay 12
fill ~26~7~32 ~26~7~34 minecraft:stained_hardened_clay 12
fill ~27~3~32 ~27~3~36 minecraft:stained_hardened_clay 12
fill ~28~2~32 ~29~3~32 minecraft:wool 12
fill ~28~12~32 ~28~12~35 minecraft:stained_hardened_clay 12
fill ~29~4~32 ~29~4~35 minecraft:stained_hardened_clay 12
fill ~29~13~32 ~30~13~34 minecraft:stained_hardened_clay 12
fill ~30~3~32 ~30~3~33 minecraft:wool 12
setblock ~31~4~32 minecraft:wool 12
fill ~31~14~32 ~31~14~34 minecraft:stained_hardened_clay 12
fill ~32~4~32 ~33~4~37 minecraft:stained_hardened_clay 12
fill ~32~14~32 ~34~14~32 minecraft:wool 7
fill ~32~15~32 ~32~15~33 minecraft:wool 7
setblock ~33~15~32 minecraft:wool 12
fill ~33~16~32 ~33~16~34 minecraft:wool 7
fill ~34~15~32 ~34~15~35 minecraft:wool 7
fill ~34~16~32 ~34~16~33 minecraft:stained_hardened_clay 12
fill ~34~17~32 ~37~17~32 minecraft:wool 7
fill ~35~16~32 ~35~16~33 minecraft:wool 7
fill ~36~18~32 ~36~18~36 minecraft:wool 7
fill ~37~16~32 ~37~16~33 minecraft:wool 7
fill ~37~19~32 ~38~19~32 minecraft:wool 7
fill ~38~16~32 ~38~16~45 minecraft:stained_hardened_clay 12
fill ~38~17~32 ~39~17~40 minecraft:stained_hardened_clay 12
setblock ~38~18~32 minecraft:wool 7
setblock ~39~21~32 minecraft:wool 7
fill ~40~21~32 ~40~21~34 minecraft:stained_hardened_clay 12
fill ~42~6~32 ~43~6~43 minecraft:stained_hardened_clay 12
fill ~45~6~32 ~48~6~58 minecraft:stained_hardened_clay 12
fill ~46~8~32 ~47~8~32 minecraft:stained_hardened_clay 12
fill ~47~0~32 ~48~0~41 minecraft:stained_hardened_clay 12
fill ~47~5~32 ~47~5~111 minecraft:stained_hardened_clay 12
fill ~47~21~32 ~48~21~32 minecraft:stained_hardened_clay 12
setblock ~47~23~32 minecraft:stained_hardened_clay 12
fill ~48~4~32 ~48~4~111 minecraft:stained_hardened_clay 12
fill ~48~7~32 ~48~7~108 minecraft:stained_hardened_clay 12
fill ~49~1~32 ~53~1~103 minecraft:stained_hardened_clay 12
fill ~49~2~32 ~51~3~106 minecraft:stained_hardened_clay 12
fill ~49~8~32 ~49~8~107 minecraft:stained_hardened_clay 12
fill ~51~17~32 ~53~17~32 minecraft:stained_hardened_clay 12
fill ~52~15~32 ~52~16~97 minecraft:stained_hardened_clay 12
setblock ~53~18~32 minecraft:stained_hardened_clay 12
fill ~54~13~32 ~54~14~34 minecraft:wool 7
setblock ~55~13~32 minecraft:stained_hardened_clay 12
fill ~56~14~32 ~56~14~37 minecraft:wool 12
fill ~58~11~32 ~58~11~91 minecraft:stained_hardened_clay 12
setblock ~61~14~32 minecraft:stained_hardened_clay 12
fill ~63~0~32 ~63~0~93 minecraft:stained_hardened_clay 12
fill ~64~15~32 ~64~15~86 minecraft:stained_hardened_clay 12
setblock ~66~5~32 minecraft:wool 12
fill ~66~6~32 ~66~7~93 minecraft:stained_hardened_clay 12
fill ~66~8~32 ~66~8~82 minecraft:stained_hardened_clay 12
fill ~67~7~32 ~67~7~83 minecraft:stained_hardened_clay 12
fill ~68~5~32 ~68~5~36 minecraft:wool 12
setblock ~68~7~32 minecraft:wool 12
fill ~68~13~32 ~68~13~78 minecraft:stained_hardened_clay 12
fill ~69~7~32 ~69~8~33 minecraft:stained_hardened_clay 12
fill ~19~4~33 ~19~5~33 minecraft:wool 7
setblock ~20~2~33 minecraft:coal_block
fill ~22~5~33 ~23~5~36 minecraft:coal_block
fill ~22~7~33 ~22~7~35 minecraft:coal_block
fill ~23~7~33 ~25~7~35 minecraft:stained_hardened_clay 12
fill ~24~1~33 ~24~1~34 minecraft:stained_hardened_clay 12
fill ~24~5~33 ~24~5~35 minecraft:stained_hardened_clay 12
fill ~25~3~33 ~26~3~36 minecraft:stained_hardened_clay 12
setblock ~26~1~33 minecraft:stained_hardened_clay 12
fill ~27~12~33 ~27~12~35 minecraft:stained_hardened_clay 12
fill ~28~2~33 ~28~3~34 minecraft:stained_hardened_clay 12
fill ~29~3~33 ~29~3~36 minecraft:stained_hardened_clay 12
setblock ~31~1~33 minecraft:wool 12
fill ~31~4~33 ~31~4~36 minecraft:stained_hardened_clay 12
setblock ~32~14~33 minecraft:stained_hardened_clay 12
fill ~33~2~33 ~33~2~35 minecraft:wool 12
fill ~33~14~33 ~33~15~34 minecraft:wool 7
fill ~34~2~33 ~34~2~39 minecraft:stained_hardened_clay 12
fill ~34~14~33 ~34~14~34 minecraft:stained_hardened_clay 12
fill ~34~17~33 ~34~17~34 minecraft:stained_hardened_clay 12
fill ~35~17~33 ~37~17~34 minecraft:wool 7
setblock ~35~18~33 minecraft:wool 7
fill ~36~1~33 ~36~1~35 minecraft:wool 12
setblock ~37~18~33 minecraft:wool 7
fill ~37~19~33 ~37~19~37 minecraft:stained_hardened_clay 12
fill ~38~18~33 ~38~18~40 minecraft:stained_hardened_clay 12
setblock ~38~19~33 minecraft:wool 7
fill ~39~19~33 ~39~19~45 minecraft:stained_hardened_clay 12
setblock ~39~21~33 minecraft:stained_hardened_clay 12
fill ~40~22~33 ~40~22~34 minecraft:stained_hardened_clay 12
setblock ~45~21~33 minecraft:stained_hardened_clay 12
fill ~46~7~33 ~47~7~58 minecraft:stained_hardened_clay 12
fill ~46~8~33 ~46~8~58 minecraft:stained_hardened_clay 12
fill ~47~21~33 ~47~22~34 minecraft:stained_hardened_clay 12
fill ~48~8~33 ~48~8~107 minecraft:stained_hardened_clay 12
fill ~49~0~33 ~54~0~46 minecraft:stained_hardened_clay 12
fill ~49~20~33 ~50~20~33 minecraft:stained_hardened_clay 12
fill ~51~17~33 ~52~17~34 minecraft:stained_hardened_clay 12
fill ~51~18~33 ~51~18~38 minecraft:stained_hardened_clay 12
fill ~52~14~33 ~52~14~99 minecraft:stained_hardened_clay 12
fill ~53~14~33 ~53~14~34 minecraft:wool 7
fill ~53~15~33 ~54~15~33 minecraft:wool 7
fill ~53~16~33 ~53~16~34 minecraft:stained_hardened_clay 12
fill ~55~13~33 ~55~14~33 minecraft:wool 7
fill ~56~12~33 ~56~12~94 minecraft:stained_hardened_clay 12
setblock ~57~12~33 minecraft:wool 12
fill ~58~15~33 ~58~15~40 minecraft:wool 12
fill ~60~12~33 ~60~12~89 minecraft:stained_hardened_clay 12
fill ~61~14~33 ~61~14~36 minecraft:wool 7
setblock ~61~15~33 minecraft:wool 7
fill ~62~15~33 ~63~15~33 minecraft:stained_hardened_clay 12
fill ~65~1~33 ~65~1~91 minecraft:stained_hardened_clay 12
fill ~66~2~33 ~66~2~91 minecraft:stained_hardened_clay 12
setblock ~66~4~33 minecraft:wool 12
fill ~66~5~33 ~66~5~93 minecraft:stained_hardened_clay 12
fill ~67~3~33 ~67~3~35 minecraft:wool 12
fill ~67~14~33 ~67~14~80 minecraft:stained_hardened_clay 12
fill ~68~4~33 ~68~4~37 minecraft:wool 12
setblock ~68~7~33 minecraft:stained_hardened_clay 12
fill ~69~6~33 ~69~6~37 minecraft:wool 12
fill ~69~12~33 ~69~12~36 minecraft:stained_hardened_clay 12
fill ~70~9~33 ~70~9~35 minecraft:stained_hardened_clay 12
setblock ~21~8~34 minecraft:stained_hardened_clay 12
fill ~23~4~34 ~23~4~36 minecraft:coal_block
fill ~23~6~34 ~23~6~36 minecraft:coal_block
fill ~24~2~34 ~24~3~36 minecraft:stained_hardened_clay 12
setblock ~24~4~34 minecraft:stained_hardened_clay 12
fill ~24~6~34 ~24~6~35 minecraft:stained_hardened_clay 12
fill ~30~2~34 ~30~3~35 minecraft:stained_hardened_clay 12
setblock ~30~12~34 minecraft:stained_hardened_clay 12
fill ~31~2~34 ~31~2~35 minecraft:wool 12
fill ~31~3~34 ~31~3~36 minecraft:stained_hardened_clay 12
fill ~31~12~34 ~31~12~39 minecraft:wool 12
fill ~31~13~34 ~31~13~36 minecraft:wool 12
fill ~32~14~34 ~32~15~36 minecraft:wool 12
fill ~34~16~34 ~34~16~35 minecraft:wool 7
setblock ~35~0~34 minecraft:wool 12
setblock ~35~2~34 minecraft:wool 12
fill ~35~16~34 ~35~16~36 minecraft:stained_hardened_clay 12
setblock ~35~18~34 minecraft:stained_hardened_clay 12
fill ~36~19~34 ~36~19~35 minecraft:stained_hardened_clay 12
setblock ~37~0~34 minecraft:wool 12
fill ~37~16~34 ~37~16~40 minecraft:stained_hardened_clay 12
fill ~37~18~34 ~37~18~39 minecraft:stained_hardened_clay 12
fill ~38~19~34 ~38~19~38 minecraft:stained_hardened_clay 12
fill ~38~20~34 ~39~20~37 minecraft:stained_hardened_clay 12
setblock ~39~22~34 minecraft:stained_hardened_clay 12
fill ~44~21~34 ~44~21~42 minecraft:stained_hardened_clay 12
fill ~45~22~34 ~45~23~34 minecraft:stained_hardened_clay 12
fill ~47~8~34 ~47~8~60 minecraft:stained_hardened_clay 12
setblock ~48~21~34 minecraft:stained_hardened_clay 12
fill ~49~20~34 ~49~20~36 minecraft:stained_hardened_clay 12
fill ~49~22~34 ~49~22~35 minecraft:stained_hardened_clay 12
setblock ~51~20~34 minecraft:stained_hardened_clay 12
fill ~51~22~34 ~51~22~35 minecraft:stained_hardened_clay 12
fill ~53~13~34 ~53~13~99 minecraft:stained_hardened_clay 12
fill ~53~15~34 ~53~15~38 minecraft:stained_hardened_clay 12
fill ~54~15~34 ~54~15~35 minecraft:wool 7
setblock ~54~16~34 minecraft:wool 7
fill ~55~13~34 ~55~13~98 minecraft:stained_hardened_clay 12
fill ~55~14~34 ~55~14~35 minecraft:wool 7
fill ~55~15~34 ~57~15~35 minecraft:wool 12
fill ~57~12~34 ~57~12~92 minecraft:stained_hardened_clay 12
fill ~59~12~34 ~59~12~90 minecraft:stained_hardened_clay 12
fill ~61~15~34 ~61~15~35 minecraft:wool 12
fill ~62~14~34 ~62~15~35 minecraft:wool 7
fill ~63~15~34 ~63~15~36 minecraft:stained_hardened_clay 12
fill ~65~15~34 ~65~15~82 minecraft:stained_hardened_clay 12
fill ~66~1~34 ~66~1~91 minecraft:stained_hardened_clay 12
setblock ~66~3~34 minecraft:wool 12
fill ~66~4~34 ~66~4~93 minecraft:stained_hardened_clay 12
fill ~67~2~34 ~67~2~35 minecraft:wool 12
setblock ~67~6~34 minecraft:stained_hardened_clay 12
fill ~68~3~34 ~68~3~36 minecraft:wool 12
fill ~68~6~34 ~68~7~36 minecraft:wool 12
fill ~69~5~34 ~69~5~38 minecraft:wool 12
fill ~69~7~34 ~69~7~36 minecraft:wool 12
setblock ~69~8~34 minecraft:stained_hardened_clay 12
setblock ~70~10~34 minecraft:stained_hardened_clay 12
setblock ~19~5~35 minecraft:wool 7
setblock ~23~2~35 minecraft:coal_block
setblock ~23~9~35 minecraft:stained_hardened_clay 12
setblock ~24~4~35 minecraft:coal_block
fill ~25~2~35 ~25~2~36 minecraft:stained_hardened_clay 12
fill ~25~6~35 ~25~6~37 minecraft:wool 12
fill ~26~7~35 ~26~7~37 minecraft:wool 12
fill ~28~3~35 ~28~3~36 minecraft:stained_hardened_clay 12
fill ~30~11~35 ~32~11~38 minecraft:wool 12
fill ~30~12~35 ~30~12~37 minecraft:wool 12
setblock ~30~13~35 minecraft:wool 12
setblock ~31~14~35 minecraft:wool 12
fill ~32~3~35 ~32~3~37 minecraft:stained_hardened_clay 12
fill ~32~12~35 ~32~12~36 minecraft:wool 12
fill ~32~13~35 ~33~13~35 minecraft:wool 12
fill ~33~11~35 ~33~11~38 minecraft:stained_hardened_clay 12
setblock ~33~12~35 minecraft:stained_hardened_clay 12
fill ~33~14~35 ~33~16~35 minecraft:wool 12
fill ~34~13~35 ~35~13~38 minecraft:stained_hardened_clay 12
setblock ~34~14~35 minecraft:wool 7
fill ~34~17~35 ~35~17~35 minecraft:wool 7
fill ~35~2~35 ~35~2~38 minecraft:stained_hardened_clay 12
fill ~35~18~35 ~35~18~36 minecraft:wool 7
fill ~36~16~35 ~36~16~40 minecraft:stained_hardened_clay 12
fill ~36~17~35 ~37~17~35 minecraft:stained_hardened_clay 12
fill ~37~0~35 ~37~0~36 minecraft:stained_hardened_clay 12
fill ~43~22~35 ~44~22~35 minecraft:stained_hardened_clay 12
fill ~46~22~35 ~48~22~35 minecraft:stained_hardened_clay 12
fill ~46~23~35 ~46~24~35 minecraft:stained_hardened_clay 12
setblock ~47~24~35 minecraft:stained_hardened_clay 12
fill ~48~23~35 ~49~23~35 minecraft:stained_hardened_clay 12
setblock ~50~22~35 minecraft:stained_hardened_clay 12
fill ~51~17~35 ~51~17~98 minecraft:stained_hardened_clay 12
setblock ~51~21~35 minecraft:stained_hardened_clay 12
setblock ~52~17~35 minecraft:wool 7
fill ~52~20~35 ~52~20~37 minecraft:stained_hardened_clay 12
fill ~53~14~35 ~54~14~98 minecraft:stained_hardened_clay 12
setblock ~53~16~35 minecraft:wool 7
fill ~54~13~35 ~54~13~98 minecraft:stained_hardened_clay 12
fill ~54~16~35 ~54~16~37 minecraft:stained_hardened_clay 12
setblock ~55~16~35 minecraft:wool 7
fill ~64~0~35 ~64~0~92 minecraft:stained_hardened_clay 12
fill ~66~3~35 ~66~3~91 minecraft:stained_hardened_clay 12
fill ~66~15~35 ~66~15~81 minecraft:stained_hardened_clay 12
fill ~67~5~35 ~67~5~93 minecraft:stained_hardened_clay 12
setblock ~67~6~35 minecraft:wool 12
setblock ~68~2~35 minecraft:wool 12
fill ~69~3~35 ~69~3~39 minecraft:wool 12
fill ~69~4~35 ~69~4~38 minecraft:wool 12
setblock ~69~8~35 minecraft:wool 12
fill ~69~11~35 ~70~11~38 minecraft:wool 7
fill ~70~7~35 ~70~7~38 minecraft:wool 12
setblock ~70~8~35 minecraft:stained_hardened_clay 12
fill ~70~10~35 ~70~10~37 minecraft:wool 7
setblock ~70~12~35 minecraft:stained_hardened_clay 12
setblock ~23~3~36 minecraft:coal_block
fill ~24~4~36 ~25~4~36 minecraft:stained_hardened_clay 12
fill ~24~5~36 ~27~5~36 minecraft:wool 12
fill ~24~6~36 ~24~7~36 minecraft:wool 12
setblock ~24~8~36 minecraft:stained_hardened_clay 12
fill ~25~7~36 ~25~7~37 minecraft:wool 12
fill ~25~8~36 ~27~8~36 minecraft:wool 12
fill ~25~9~36 ~30~9~36 minecraft:stained_hardened_clay 12
fill ~26~2~36 ~26~2~37 minecraft:stained_hardened_clay 12
fill ~26~4~36 ~26~4~38 minecraft:wool 12
fill ~26~6~36 ~27~6~38 minecraft:wool 12
fill ~26~10~36 ~27~10~36 minecraft:stained_hardened_clay 12
setblock ~27~4~36 minecraft:stained_hardened_clay 12
fill ~27~7~36 ~27~7~38 minecraft:wool 12
setblock ~27~11~36 minecraft:stained_hardened_clay 12
fill ~28~5~36 ~29~5~36 minecraft:stained_hardened_clay 12
fill ~28~8~36 ~29~8~36 minecraft:stained_hardened_clay 12
fill ~29~4~36 ~29~4~38 minecraft:wool 12
setblock ~29~12~36 minecraft:wool 12
setblock ~30~3~36 minecraft:stained_hardened_clay 12
fill ~31~2~36 ~33~2~36 minecraft:stained_hardened_clay 12
setblock ~31~10~36 minecraft:wool 12
fill ~32~13~36 ~33~13~38 minecraft:coal_block
fill ~33~1~36 ~36~1~36 minecraft:stained_hardened_clay 12
fill ~33~12~36 ~33~12~39 minecraft:coal_block
fill ~33~14~36 ~33~14~38 minecraft:coal_block
fill ~33~15~36 ~34~16~37 minecraft:wool 12
setblock ~34~14~36 minecraft:wool 12
fill ~34~17~36 ~34~17~40 minecraft:wool 12
fill ~35~17~36 ~35~17~38 minecraft:stained_hardened_clay 12
setblock ~36~0~36 minecraft:stained_hardened_clay 12
setblock ~36~17~36 minecraft:wool 7
fill ~36~19~36 ~36~19~40 minecraft:wool 7
fill ~37~17~36 ~37~17~40 minecraft:stained_hardened_clay 12
fill ~39~21~36 ~40~21~36 minecraft:stained_hardened_clay 12
fill ~40~22~36 ~41~22~37 minecraft:stained_hardened_clay 12
fill ~43~22~36 ~43~22~37 minecraft:stained_hardened_clay 12
fill ~44~23~36 ~45~23~36 minecraft:stained_hardened_clay 12
fill ~45~21~36 ~48~21~36 minecraft:stained_hardened_clay 12
fill ~45~22~36 ~47~22~36 minecraft:stained_hardened_clay 12
setblock ~49~23~36 minecraft:stained_hardened_clay 12
setblock ~51~19~36 minecraft:stained_hardened_clay 12
fill ~52~17~36 ~53~17~37 minecraft:stained_hardened_clay 12
fill ~53~16~36 ~53~16~37 minecraft:stained_hardened_clay 12
fill ~54~15~36 ~55~15~36 minecraft:stained_hardened_clay 12
fill ~55~14~36 ~55~14~39 minecraft:stained_hardened_clay 12
fill ~55~16~36 ~60~16~37 minecraft:wool 12
fill ~56~15~36 ~57~15~41 minecraft:wool 12
fill ~58~12~36 ~58~12~91 minecraft:stained_hardened_clay 12
fill ~61~15~36 ~62~15~37 minecraft:wool 7
fill ~61~16~36 ~63~16~36 minecraft:wool 7
fill ~62~14~36 ~62~14~87 minecraft:stained_hardened_clay 12
fill ~65~0~36 ~66~0~91 minecraft:stained_hardened_clay 12
fill ~66~16~36 ~66~16~82 minecraft:stained_hardened_clay 12
fill ~67~1~36 ~68~1~85 minecraft:stained_hardened_clay 12
fill ~67~2~36 ~69~2~36 minecraft:stained_hardened_clay 12
fill ~67~3~36 ~67~4~93 minecraft:stained_hardened_clay 12
fill ~67~6~36 ~67~6~92 minecraft:stained_hardened_clay 12
fill ~68~14~36 ~68~14~79 minecraft:stained_hardened_clay 12
setblock ~69~8~36 minecraft:stained_hardened_clay 12
fill ~69~10~36 ~69~10~37 minecraft:wool 7
fill ~69~13~36 ~69~13~77 minecraft:stained_hardened_clay 12
fill ~70~4~36 ~70~4~40 minecraft:wool 12
fill ~70~5~36 ~70~6~39 minecraft:wool 12
fill ~70~8~36 ~70~9~38 minecraft:wool 12
setblock ~24~4~37 minecraft:stained_hardened_clay 12
fill ~25~3~37 ~30~3~37 minecraft:wool 12
fill ~25~4~37 ~25~5~37 minecraft:wool 12
fill ~26~5~37 ~30~5~38 minecraft:wool 12
fill ~26~8~37 ~28~8~37 minecraft:wool 12
fill ~27~4~37 ~28~4~38 minecraft:wool 12
fill ~27~9~37 ~30~9~37 minecraft:stained_hardened_clay 12
fill ~28~6~37 ~28~7~39 minecraft:wool 12
fill ~29~6~37 ~29~8~37 minecraft:stained_hardened_clay 12
setblock ~29~11~37 minecraft:stained_hardened_clay 12
fill ~30~4~37 ~31~4~39 minecraft:wool 12
fill ~30~7~37 ~30~7~38 minecraft:stained_hardened_clay 12
fill ~31~5~37 ~33~5~37 minecraft:stained_hardened_clay 12
setblock ~31~10~37 minecraft:stained_hardened_clay 12
setblock ~32~12~37 minecraft:coal_block
fill ~33~1~37 ~35~1~37 minecraft:stained_hardened_clay 12
fill ~33~2~37 ~33~2~38 minecraft:stained_hardened_clay 12
fill ~34~14~37 ~34~14~38 minecraft:stained_hardened_clay 12
fill ~35~16~37 ~35~16~38 minecraft:wool 12
fill ~35~18~37 ~36~18~40 minecraft:stained_hardened_clay 12
fill ~36~17~37 ~36~17~39 minecraft:stained_hardened_clay 12
setblock ~37~20~37 minecraft:stained_hardened_clay 12
fill ~41~21~37 ~41~21~45 minecraft:stained_hardened_clay 12
fill ~44~23~37 ~44~24~37 minecraft:stained_hardened_clay 12
fill ~45~21~37 ~47~21~39 minecraft:stained_hardened_clay 12
setblock ~45~24~37 minecraft:stained_hardened_clay 12
fill ~46~22~37 ~49~22~37 minecraft:stained_hardened_clay 12
fill ~50~21~37 ~51~21~37 minecraft:stained_hardened_clay 12
setblock ~50~23~37 minecraft:stained_hardened_clay 12
setblock ~54~15~37 minecraft:stained_hardened_clay 12
setblock ~54~17~37 minecraft:stained_hardened_clay 12
fill ~55~15~37 ~55~15~42 minecraft:wool 12
fill ~56~13~37 ~56~13~97 minecraft:stained_hardened_clay 12
setblock ~56~17~37 minecraft:stained_hardened_clay 12
fill ~57~13~37 ~58~13~37 minecraft:wool 12
fill ~60~13~37 ~60~13~89 minecraft:stained_hardened_clay 12
fill ~61~14~37 ~61~14~95 minecraft:stained_hardened_clay 12
setblock ~61~16~37 minecraft:stained_hardened_clay 12
fill ~62~16~37 ~63~16~38 minecraft:wool 7
setblock ~63~15~37 minecraft:wool 7
fill ~64~16~37 ~65~16~84 minecraft:stained_hardened_clay 12
fill ~67~0~37 ~67~0~90 minecraft:stained_hardened_clay 12
fill ~67~2~37 ~68~2~37 minecraft:stained_hardened_clay 12
fill ~67~15~37 ~67~15~80 minecraft:stained_hardened_clay 12
fill ~68~3~37 ~68~3~88 minecraft:stained_hardened_clay 12
fill ~68~5~37 ~68~5~92 minecraft:stained_hardened_clay 12
fill ~68~6~37 ~68~6~91 minecraft:stained_hardened_clay 12
fill ~68~7~37 ~69~7~82 minecraft:stained_hardened_clay 12
fill ~69~2~37 ~69~2~39 minecraft:wool 12
setblock ~69~8~37 minecraft:wool 12
fill ~69~12~37 ~70~12~37 minecraft:wool 7
fill ~70~3~37 ~70~3~39 minecraft:wool 12
fill ~70~13~37 ~70~13~38 minecraft:stained_hardened_clay 12
fill ~71~6~37 ~71~6~44 minecraft:wool 12
fill ~71~7~37 ~71~9~38 minecraft:wool 12
fill ~27~8~38 ~29~8~38 minecraft:wool 12
fill ~28~9~38 ~30~9~38 minecraft:wool 12
fill ~29~6~38 ~29~7~38 minecraft:wool 12
setblock ~29~10~38 minecraft:stained_hardened_clay 12
fill ~31~5~38 ~32~5~40 minecraft:wool 12
fill ~31~10~38 ~31~10~41 minecraft:wool 12
fill ~32~3~38 ~32~4~38 minecraft:wool 12
fill ~32~12~38 ~32~12~42 minecraft:wool 12
setblock ~32~14~38 minecraft:skull 4
fill ~33~4~38 ~33~5~38 minecraft:stained_hardened_clay 12
setblock ~33~15~38 minecraft:coal_block
fill ~33~16~38 ~34~16~42 minecraft:wool 12
fill ~33~17~38 ~33~17~39 minecraft:wool 12
setblock ~34~15~38 minecraft:wool 12
fill ~37~19~38 ~37~20~39 minecraft:wool 7
fill ~38~20~38 ~38~20~40 minecraft:wool 7
fill ~39~20~38 ~39~20~45 minecraft:stained_hardened_clay 12
fill ~41~22~38 ~42~22~38 minecraft:stained_hardened_clay 12
fill ~43~23~38 ~43~23~40 minecraft:stained_hardened_clay 12
fill ~44~22~38 ~45~22~38 minecraft:stained_hardened_clay 12
setblock ~44~24~38 minecraft:stained_hardened_clay 12
setblock ~45~23~38 minecraft:stained_hardened_clay 12
fill ~47~22~38 ~47~22~39 minecraft:stained_hardened_clay 12
setblock ~48~23~38 minecraft:stained_hardened_clay 12
fill ~49~22~38 ~50~22~38 minecraft:stained_hardened_clay 12
setblock ~50~21~38 minecraft:stained_hardened_clay 12
setblock ~51~20~38 minecraft:stained_hardened_clay 12
fill ~52~17~38 ~52~17~39 minecraft:stained_hardened_clay 12
fill ~53~16~38 ~59~17~40 minecraft:wool 12
fill ~53~19~38 ~53~19~39 minecraft:stained_hardened_clay 12
fill ~54~15~38 ~54~15~42 minecraft:wool 12
fill ~56~14~38 ~56~14~96 minecraft:stained_hardened_clay 12
fill ~57~13~38 ~59~13~90 minecraft:stained_hardened_clay 12
setblock ~57~14~38 minecraft:wool 12
fill ~58~14~38 ~60~14~96 minecraft:stained_hardened_clay 12
fill ~59~15~38 ~59~15~39 minecraft:wool 12
fill ~60~15~38 ~61~15~94 minecraft:stained_hardened_clay 12
fill ~60~16~38 ~60~16~93 minecraft:stained_hardened_clay 12
setblock ~60~17~38 minecraft:wool 12
setblock ~61~16~38 minecraft:wool 7
setblock ~61~17~38 minecraft:stained_hardened_clay 12
setblock ~62~15~38 minecraft:wool 7
setblock ~62~17~38 minecraft:wool 7
fill ~63~15~38 ~63~15~88 minecraft:stained_hardened_clay 12
fill ~63~17~38 ~65~17~83 minecraft:stained_hardened_clay 12
fill ~67~2~38 ~67~2~89 minecraft:stained_hardened_clay 12
fill ~67~16~38 ~67~16~81 minecraft:stained_hardened_clay 12
setblock ~68~2~38 minecraft:wool 12
fill ~68~4~38 ~68~4~92 minecraft:stained_hardened_clay 12
fill ~68~15~38 ~68~15~79 minecraft:stained_hardened_clay 12
fill ~69~1~38 ~69~1~39 minecraft:wool 12
fill ~69~6~38 ~69~6~90 minecraft:stained_hardened_clay 12
fill ~69~8~38 ~69~8~81 minecraft:stained_hardened_clay 12
fill ~69~10~38 ~70~10~41 minecraft:stained_hardened_clay 12
fill ~69~12~38 ~69~12~77 minecraft:stained_hardened_clay 12
fill ~69~14~38 ~69~14~45 minecraft:stained_hardened_clay 12
fill ~70~2~38 ~70~2~40 minecraft:wool 12
fill ~70~12~38 ~70~12~40 minecraft:wool 7
fill ~71~4~38 ~71~5~44 minecraft:wool 12
fill ~71~10~38 ~71~10~51 minecraft:wool 12
fill ~71~11~38 ~71~11~40 minecraft:wool 7
fill ~28~5~39 ~30~5~39 minecraft:wool 12
fill ~28~8~39 ~31~8~39 minecraft:wool 12
setblock ~29~6~39 minecraft:stained_hardened_clay 12
fill ~29~7~39 ~30~7~40 minecraft:wool 12
fill ~29~9~39 ~31~9~39 minecraft:wool 12
fill ~30~6~39 ~31~6~41 minecraft:wool 12
setblock ~30~10~39 minecraft:wool 12
fill ~31~7~39 ~33~7~39 minecraft:stained_hardened_clay 12
fill ~31~11~39 ~34~11~39 minecraft:wool 12
fill ~32~4~39 ~33~4~40 minecraft:wool 12
fill ~32~6~39 ~33~6~40 minecraft:stained_hardened_clay 12
fill ~33~5~39 ~33~5~40 minecraft:stained_hardened_clay 12
setblock ~33~13~39 minecraft:coal_block
fill ~34~12~39 ~34~12~42 minecraft:wool 12
setblock ~34~13~39 minecraft:wool 12
fill ~34~14~39 ~34~15~41 minecraft:coal_block
fill ~35~13~39 ~35~13~40 minecraft:stained_hardened_clay 12
fill ~35~16~39 ~35~16~40 minecraft:stained_hardened_clay 12
setblock ~35~17~39 minecraft:wool 12
fill ~35~19~39 ~35~19~40 minecraft:wool 7
fill ~36~20~39 ~36~20~40 minecraft:wool 7
fill ~37~1~39 ~41~1~40 minecraft:wool 12
fill ~37~21~39 ~37~21~40 minecraft:wool 7
fill ~38~2~39 ~40~2~42 minecraft:wool 12
setblock ~38~19~39 minecraft:wool 7
fill ~39~21~39 ~39~21~44 minecraft:stained_hardened_clay 12
fill ~41~0~39 ~41~0~48 minecraft:wool 12
setblock ~41~2~39 minecraft:stained_hardened_clay 12
fill ~41~22~39 ~41~22~40 minecraft:stained_hardened_clay 12
setblock ~42~24~39 minecraft:stained_hardened_clay 12
fill ~45~22~39 ~46~22~39 minecraft:stained_hardened_clay 12
setblock ~48~21~39 minecraft:stained_hardened_clay 12
setblock ~50~19~39 minecraft:stained_hardened_clay 12
fill ~53~15~39 ~53~15~41 minecraft:wool 12
fill ~53~18~39 ~53~18~41 minecraft:stained_hardened_clay 12
setblock ~53~20~39 minecraft:stained_hardened_clay 12
fill ~55~18~39 ~55~19~39 minecraft:stained_hardened_clay 12
fill ~56~19~39 ~56~19~40 minecraft:stained_hardened_clay 12
setblock ~56~20~39 minecraft:stained_hardened_clay 12
fill ~57~14~39 ~57~14~96 minecraft:stained_hardened_clay 12
setblock ~57~18~39 minecraft:stained_hardened_clay 12
fill ~58~18~39 ~59~18~40 minecraft:wool 12
setblock ~60~17~39 minecraft:stained_hardened_clay 12
fill ~60~18~39 ~61~18~40 minecraft:wool 7
fill ~61~16~39 ~63~16~87 minecraft:stained_hardened_clay 12
setblock ~61~17~39 minecraft:wool 7
fill ~62~15~39 ~62~15~89 minecraft:stained_hardened_clay 12
fill ~62~17~39 ~62~17~90 minecraft:stained_hardened_clay 12
fill ~62~18~39 ~64~18~41 minecraft:stained_hardened_clay 12
fill ~66~17~39 ~66~17~81 minecraft:stained_hardened_clay 12
fill ~68~0~39 ~68~0~88 minecraft:stained_hardened_clay 12
fill ~68~2~39 ~68~2~88 minecraft:stained_hardened_clay 12
fill ~68~16~39 ~68~16~47 minecraft:stained_hardened_clay 12
fill ~69~4~39 ~69~5~86 minecraft:stained_hardened_clay 12
fill ~69~11~39 ~69~11~80 minecraft:stained_hardened_clay 12
fill ~69~15~39 ~69~15~45 minecraft:stained_hardened_clay 12
fill ~70~7~39 ~71~7~41 minecraft:stained_hardened_clay 12
fill ~70~8~39 ~70~8~43 minecraft:stained_hardened_clay 12
fill ~70~9~39 ~72~9~39 minecraft:wool 12
setblock ~70~11~39 minecraft:wool 7
setblock ~70~13~39 minecraft:wool 7
fill ~71~3~39 ~71~3~45 minecraft:wool 12
fill ~71~8~39 ~72~8~40 minecraft:wool 12
fill ~71~12~39 ~71~12~40 minecraft:wool 7
fill ~72~6~39 ~72~6~45 minecraft:wool 12
setblock ~72~7~39 minecraft:wool 12
setblock ~29~6~40 minecraft:wool 12
fill ~29~8~40 ~31~8~40 minecraft:wool 12
setblock ~30~5~40 minecraft:wool 12
fill ~30~9~40 ~32~9~40 minecraft:wool 12
fill ~31~7~40 ~31~7~42 minecraft:wool 12
setblock ~31~11~40 minecraft:stained_hardened_clay 12
fill ~32~7~40 ~33~7~40 minecraft:stained_hardened_clay 12
fill ~32~11~40 ~34~11~41 minecraft:wool 12
setblock ~33~3~40 minecraft:stained_hardened_clay 12
fill ~33~9~40 ~33~9~41 minecraft:stained_hardened_clay 12
setblock ~33~10~40 minecraft:wool 12
fill ~33~12~40 ~33~12~42 minecraft:wool 12
setblock ~34~13~40 minecraft:coal_block
setblock ~34~18~40 minecraft:wool 12
setblock ~35~12~40 minecraft:wool 12
setblock ~35~17~40 minecraft:stained_hardened_clay 12
fill ~35~20~40 ~35~20~41 minecraft:wool 7
fill ~36~17~40 ~36~17~45 minecraft:wool 12
fill ~36~21~40 ~36~21~41 minecraft:wool 7
fill ~37~2~40 ~37~2~41 minecraft:wool 12
fill ~37~18~40 ~37~18~46 minecraft:wool 12
fill ~37~19~40 ~38~19~40 minecraft:stained_hardened_clay 12
setblock ~37~20~40 minecraft:wool 7
fill ~38~21~40 ~38~21~43 minecraft:stained_hardened_clay 12
fill ~38~22~40 ~39~22~40 minecraft:stained_hardened_clay 12
fill ~39~0~40 ~40~0~44 minecraft:wool 12
fill ~40~21~40 ~40~21~45 minecraft:stained_hardened_clay 12
fill ~40~24~40 ~41~24~40 minecraft:stained_hardened_clay 12
fill ~41~2~40 ~41~2~48 minecraft:wool 12
fill ~41~23~40 ~41~23~43 minecraft:stained_hardened_clay 12
setblock ~45~21~40 minecraft:stained_hardened_clay 12
setblock ~52~17~40 minecraft:wool 12
fill ~52~18~40 ~52~18~97 minecraft:stained_hardened_clay 12
fill ~54~19~40 ~55~19~40 minecraft:stained_hardened_clay 12
setblock ~55~14~40 minecraft:wool 12
fill ~55~18~40 ~57~18~42 minecraft:wool 12
setblock ~56~21~40 minecraft:stained_hardened_clay 12
setblock ~58~19~40 minecraft:stained_hardened_clay 12
fill ~59~15~40 ~59~15~93 minecraft:stained_hardened_clay 12
fill ~59~19~40 ~61~19~40 minecraft:wool 7
setblock ~60~17~40 minecraft:wool 7
fill ~61~17~40 ~61~17~92 minecraft:stained_hardened_clay 12
fill ~62~19~40 ~63~19~40 minecraft:stained_hardened_clay 12
fill ~65~18~40 ~67~18~50 minecraft:stained_hardened_clay 12
fill ~67~17~40 ~67~17~74 minecraft:stained_hardened_clay 12
fill ~69~1~40 ~70~1~83 minecraft:stained_hardened_clay 12
fill ~69~2~40 ~69~3~84 minecraft:stained_hardened_clay 12
fill ~70~3~40 ~70~3~85 minecraft:stained_hardened_clay 12
fill ~70~5~40 ~70~6~40 minecraft:stained_hardened_clay 12
fill ~70~9~40 ~70~9~80 minecraft:stained_hardened_clay 12
fill ~70~11~40 ~70~11~42 minecraft:stained_hardened_clay 12
fill ~70~13~40 ~70~14~41 minecraft:stained_hardened_clay 12
fill ~71~2~40 ~71~2~41 minecraft:stained_hardened_clay 12
fill ~71~9~40 ~72~9~50 minecraft:wool 12
fill ~72~4~40 ~72~4~50 minecraft:wool 12
fill ~72~5~40 ~72~5~44 minecraft:wool 12
setblock ~72~7~40 minecraft:stained_hardened_clay 12
fill ~72~10~40 ~72~10~51 minecraft:wool 12
fill ~30~7~41 ~30~8~41 minecraft:wool 12
fill ~31~8~41 ~32~9~42 minecraft:wool 12
fill ~32~5~41 ~34~5~42 minecraft:wool 12
fill ~32~6~41 ~32~7~43 minecraft:wool 12
fill ~32~10~41 ~32~10~43 minecraft:wool 12
fill ~32~13~41 ~35~13~41 minecraft:wool 12
setblock ~32~15~41 minecraft:wool 12
fill ~33~3~41 ~33~4~41 minecraft:wool 12
fill ~33~6~41 ~34~7~41 minecraft:stained_hardened_clay 12
fill ~33~10~41 ~33~10~42 minecraft:stained_hardened_clay 12
setblock ~33~15~41 minecraft:coal_block
fill ~34~4~41 ~35~4~44 minecraft:wool 12
fill ~34~8~41 ~34~8~43 minecraft:stained_hardened_clay 12
fill ~35~12~41 ~35~12~43 minecraft:stained_hardened_clay 12
fill ~35~16~41 ~37~16~43 minecraft:wool 12
setblock ~35~17~41 minecraft:wool 12
fill ~35~21~41 ~35~22~42 minecraft:wool 7
fill ~36~3~41 ~38~3~41 minecraft:stained_hardened_clay 12
fill ~36~18~41 ~36~19~41 minecraft:wool 12
fill ~36~20~41 ~38~20~41 minecraft:stained_hardened_clay 12
fill ~36~22~41 ~36~22~43 minecraft:wool 7
fill ~37~17~41 ~38~17~44 minecraft:wool 12
fill ~37~19~41 ~38~19~45 minecraft:wool 12
fill ~37~21~41 ~37~22~42 minecraft:stained_hardened_clay 12
fill ~38~1~41 ~41~1~41 minecraft:wool 12
fill ~38~18~41 ~38~18~44 minecraft:wool 12
fill ~39~3~41 ~39~3~50 minecraft:wool 12
fill ~39~17~41 ~39~17~45 minecraft:stained_hardened_clay 12
fill ~39~22~41 ~40~22~41 minecraft:stained_hardened_clay 12
fill ~40~24~41 ~40~24~42 minecraft:stained_hardened_clay 12
setblock ~42~0~41 minecraft:wool 12
fill ~42~1~41 ~42~2~43 minecraft:stained_hardened_clay 12
fill ~42~22~41 ~43~22~41 minecraft:stained_hardened_clay 12
fill ~42~23~41 ~42~24~41 minecraft:stained_hardened_clay 12
setblock ~44~0~41 minecraft:stained_hardened_clay 12
fill ~45~0~41 ~45~0~55 minecraft:wool 12
fill ~45~20~41 ~46~20~41 minecraft:stained_hardened_clay 12
fill ~50~19~41 ~50~19~42 minecraft:stained_hardened_clay 12
fill ~52~17~41 ~52~17~98 minecraft:stained_hardened_clay 12
fill ~52~19~41 ~53~19~42 minecraft:stained_hardened_clay 12
fill ~53~16~41 ~57~17~42 minecraft:wool 12
fill ~54~18~41 ~54~18~42 minecraft:wool 12
fill ~55~14~41 ~55~14~97 minecraft:stained_hardened_clay 12
fill ~56~19~41 ~57~19~41 minecraft:wool 12
fill ~58~15~41 ~58~15~94 minecraft:stained_hardened_clay 12
fill ~58~16~41 ~59~16~93 minecraft:stained_hardened_clay 12
fill ~58~17~41 ~60~17~91 minecraft:stained_hardened_clay 12
fill ~58~18~41 ~60~19~41 minecraft:wool 7
fill ~61~18~41 ~61~18~90 minecraft:stained_hardened_clay 12
fill ~61~19~41 ~63~19~43 minecraft:wool 12
fill ~64~19~41 ~65~19~47 minecraft:stained_hardened_clay 12
fill ~68~17~41 ~68~18~46 minecraft:stained_hardened_clay 12
fill ~69~0~41 ~69~0~84 minecraft:stained_hardened_clay 12
fill ~69~16~41 ~69~16~44 minecraft:stained_hardened_clay 12
fill ~70~2~41 ~70~2~42 minecraft:stained_hardened_clay 12
fill ~70~4~41 ~70~4~42 minecraft:stained_hardened_clay 12
fill ~70~5~41 ~70~5~42 minecraft:wool 12
fill ~70~6~41 ~70~6~42 minecraft:stained_hardened_clay 12
fill ~70~12~41 ~71~12~41 minecraft:stained_hardened_clay 12
fill ~71~8~41 ~72~8~41 minecraft:stained_hardened_clay 12
fill ~71~11~41 ~72~11~51 minecraft:wool 12
setblock ~71~13~41 minecraft:stained_hardened_clay 12
fill ~72~3~41 ~72~3~50 minecraft:wool 12
fill ~72~7~41 ~72~7~45 minecraft:wool 12
fill ~31~5~42 ~31~6~42 minecraft:wool 12
fill ~32~11~42 ~34~11~42 minecraft:stained_hardened_clay 12
fill ~32~13~42 ~34~14~42 minecraft:wool 12
setblock ~33~4~42 minecraft:wool 12
fill ~33~6~42 ~33~8~44 minecraft:wool 12
setblock ~33~9~42 minecraft:wool 12
fill ~33~15~42 ~34~15~44 minecraft:wool 12
fill ~34~6~42 ~34~7~42 minecraft:stained_hardened_clay 12
fill ~35~5~42 ~36~5~45 minecraft:wool 12
fill ~35~13~42 ~35~13~43 minecraft:stained_hardened_clay 12
fill ~35~23~42 ~36~23~42 minecraft:wool 7
fill ~36~4~42 ~36~4~44 minecraft:wool 12
setblock ~36~15~42 minecraft:wool 12
setblock ~36~21~42 minecraft:stained_hardened_clay 12
setblock ~37~3~42 minecraft:stained_hardened_clay 12
fill ~37~5~42 ~38~5~42 minecraft:stained_hardened_clay 12
fill ~37~20~42 ~37~20~47 minecraft:wool 12
fill ~38~3~42 ~38~3~43 minecraft:wool 12
fill ~38~20~42 ~38~20~43 minecraft:stained_hardened_clay 12
fill ~38~22~42 ~38~22~43 minecraft:stained_hardened_clay 12
fill ~39~1~42 ~41~1~46 minecraft:wool 12
fill ~39~18~42 ~39~18~43 minecraft:wool 12
fill ~40~3~42 ~40~3~49 minecraft:wool 12
fill ~42~0~42 ~42~0~43 minecraft:stained_hardened_clay 12
setblock ~42~24~42 minecraft:stained_hardened_clay 12
fill ~43~0~42 ~44~1~54 minecraft:wool 12
setblock ~43~2~42 minecraft:stained_hardened_clay 12
fill ~44~2~42 ~46~2~54 minecraft:wool 12
setblock ~44~22~42 minecraft:stained_hardened_clay 12
fill ~45~1~42 ~47~1~51 minecraft:wool 12
fill ~46~0~42 ~47~0~51 minecraft:wool 12
fill ~48~0~42 ~48~0~43 minecraft:stained_hardened_clay 12
setblock ~49~19~42 minecraft:stained_hardened_clay 12
fill ~51~18~42 ~51~18~96 minecraft:stained_hardened_clay 12
fill ~52~20~42 ~54~20~42 minecraft:stained_hardened_clay 12
fill ~53~15~42 ~53~15~99 minecraft:stained_hardened_clay 12
setblock ~53~18~42 minecraft:wool 12
setblock ~53~21~42 minecraft:stained_hardened_clay 12
fill ~54~19~42 ~54~19~76 minecraft:stained_hardened_clay 12
fill ~55~19~42 ~56~19~42 minecraft:wool 12
setblock ~56~15~42 minecraft:wool 12
setblock ~56~21~42 minecraft:stained_hardened_clay 12
fill ~57~15~42 ~57~15~95 minecraft:stained_hardened_clay 12
fill ~57~19~42 ~59~19~42 minecraft:wool 7
setblock ~58~18~42 minecraft:wool 7
fill ~58~20~42 ~59~20~43 minecraft:wool 7
fill ~59~18~42 ~60~18~91 minecraft:stained_hardened_clay 12
fill ~60~19~42 ~60~19~90 minecraft:stained_hardened_clay 12
fill ~60~20~42 ~63~20~42 minecraft:wool 12
setblock ~62~18~42 minecraft:wool 12
fill ~63~18~42 ~64~18~80 minecraft:stained_hardened_clay 12
fill ~69~10~42 ~69~10~79 minecraft:stained_hardened_clay 12
fill ~70~0~42 ~70~0~84 minecraft:stained_hardened_clay 12
fill ~70~7~42 ~70~7~82 minecraft:stained_hardened_clay 12
setblock ~70~10~42 minecraft:wool 12
fill ~70~12~42 ~70~12~77 minecraft:stained_hardened_clay 12
fill ~70~13~42 ~71~13~42 minecraft:wool 7
fill ~70~14~42 ~70~15~42 minecraft:stained_hardened_clay 12
fill ~71~1~42 ~71~2~44 minecraft:wool 12
fill ~71~7~42 ~71~7~45 minecraft:wool 12
setblock ~71~8~42 minecraft:stained_hardened_clay 12
fill ~71~12~42 ~71~12~44 minecraft:wool 12
fill ~72~2~42 ~72~2~46 minecraft:wool 12
fill ~72~8~42 ~72~8~46 minecraft:wool 12
fill ~32~8~43 ~32~8~44 minecraft:wool 12
setblock ~32~9~43 minecraft:wool 12
fill ~32~11~43 ~32~12~43 minecraft:stained_hardened_clay 12
fill ~33~5~43 ~34~5~44 minecraft:wool 12
setblock ~33~9~43 minecraft:stained_hardened_clay 12
fill ~33~10~43 ~34~10~43 minecraft:wool 7
fill ~33~11~43 ~33~11~44 minecraft:wool 7
fill ~33~12~43 ~34~12~43 minecraft:stained_hardened_clay 12
fill ~33~13~43 ~33~14~43 minecraft:wool 12
fill ~34~6~43 ~35~6~45 minecraft:wool 12
fill ~34~7~43 ~34~7~45 minecraft:wool 12
setblock ~34~11~43 minecraft:stained_hardened_clay 12
setblock ~34~13~43 minecraft:stained_hardened_clay 12
fill ~34~14~43 ~34~14~44 minecraft:wool 12
fill ~34~16~43 ~34~16~44 minecraft:wool 12
fill ~34~23~43 ~35~24~43 minecraft:wool 7
fill ~35~7~43 ~35~8~43 minecraft:stained_hardened_clay 12
fill ~35~10~43 ~37~10~45 minecraft:stained_hardened_clay 12
setblock ~35~15~43 minecraft:wool 12
fill ~36~15~43 ~36~15~44 minecraft:stained_hardened_clay 12
fill ~36~23~43 ~37~23~44 minecraft:stained_hardened_clay 12
fill ~37~4~43 ~37~5~44 minecraft:wool 12
fill ~37~21~43 ~37~21~47 minecraft:wool 12
setblock ~37~22~43 minecraft:stained_hardened_clay 12
setblock ~38~5~43 minecraft:stained_hardened_clay 12
fill ~39~2~43 ~40~2~48 minecraft:wool 12
fill ~39~22~43 ~39~22~46 minecraft:stained_hardened_clay 12
setblock ~39~23~43 minecraft:stained_hardened_clay 12
fill ~40~6~43 ~40~6~51 minecraft:wool 12
fill ~41~3~43 ~41~3~48 minecraft:wool 12
setblock ~42~22~43 minecraft:stained_hardened_clay 12
fill ~43~2~43 ~43~2~45 minecraft:wool 12
fill ~43~19~43 ~43~19~44 minecraft:stained_hardened_clay 12
setblock ~43~23~43 minecraft:stained_hardened_clay 12
fill ~47~2~43 ~47~2~50 minecraft:wool 12
fill ~48~19~43 ~48~19~44 minecraft:stained_hardened_clay 12
fill ~49~20~43 ~50~20~43 minecraft:stained_hardened_clay 12
setblock ~51~19~43 minecraft:stained_hardened_clay 12
setblock ~52~20~43 minecraft:stained_hardened_clay 12
fill ~53~16~43 ~57~16~94 minecraft:stained_hardened_clay 12
fill ~53~17~43 ~54~17~97 minecraft:stained_hardened_clay 12
fill ~53~18~43 ~58~18~91 minecraft:stained_hardened_clay 12
fill ~53~19~43 ~53~19~95 minecraft:stained_hardened_clay 12
fill ~54~15~43 ~56~15~94 minecraft:stained_hardened_clay 12
fill ~54~22~43 ~55~22~43 minecraft:stained_hardened_clay 12
setblock ~55~17~43 minecraft:wool 12
fill ~55~19~43 ~57~19~93 minecraft:stained_hardened_clay 12
fill ~55~20~43 ~55~20~75 minecraft:stained_hardened_clay 12
fill ~56~17~43 ~57~17~94 minecraft:stained_hardened_clay 12
fill ~57~20~43 ~57~20~78 minecraft:stained_hardened_clay 12
fill ~57~21~43 ~57~21~52 minecraft:stained_hardened_clay 12
setblock ~58~19~43 minecraft:wool 7
fill ~59~19~43 ~59~19~91 minecraft:stained_hardened_clay 12
fill ~60~20~43 ~60~20~48 minecraft:stained_hardened_clay 12
fill ~60~21~43 ~60~21~47 minecraft:stained_hardened_clay 12
fill ~61~20~43 ~64~20~43 minecraft:wool 12
fill ~62~18~43 ~62~18~89 minecraft:stained_hardened_clay 12
fill ~66~19~43 ~66~19~49 minecraft:stained_hardened_clay 12
setblock ~70~2~43 minecraft:wool 12
setblock ~70~4~43 minecraft:wool 12
fill ~70~5~43 ~70~5~85 minecraft:stained_hardened_clay 12
setblock ~70~6~43 minecraft:wool 12
fill ~70~10~43 ~70~10~45 minecraft:stained_hardened_clay 12
setblock ~70~11~43 minecraft:wool 12
fill ~70~13~43 ~71~13~44 minecraft:stained_hardened_clay 12
setblock ~70~14~43 minecraft:wool 7
fill ~70~15~43 ~70~15~44 minecraft:stained_hardened_clay 12
fill ~71~0~43 ~71~0~82 minecraft:stained_hardened_clay 12
fill ~71~8~43 ~71~8~45 minecraft:wool 12
setblock ~71~14~43 minecraft:stained_hardened_clay 12
fill ~72~1~43 ~72~1~46 minecraft:wool 12
fill ~72~12~43 ~72~12~44 minecraft:wool 12
fill ~32~9~44 ~33~10~44 minecraft:wool 7
setblock ~32~11~44 minecraft:wool 7
setblock ~33~12~44 minecraft:stained_hardened_clay 12
fill ~34~8~44 ~34~8~45 minecraft:wool 12
fill ~34~10~44 ~34~10~45 minecraft:stained_hardened_clay 12
fill ~34~11~44 ~34~13~44 minecraft:wool 7
fill ~34~17~44 ~35~17~44 minecraft:wool 12
fill ~34~24~44 ~34~26~44 minecraft:wool 7
fill ~35~7~44 ~36~7~45 minecraft:wool 12
setblock ~35~8~44 minecraft:stained_hardened_clay 12
fill ~35~12~44 ~36~13~45 minecraft:wool 7
setblock ~35~14~44 minecraft:wool 7
setblock ~35~15~44 minecraft:stained_hardened_clay 12
fill ~35~16~44 ~36~16~44 minecraft:wool 12
fill ~35~23~44 ~35~25~44 minecraft:stained_hardened_clay 12
fill ~36~6~44 ~39~6~44 minecraft:wool 12
setblock ~36~14~44 minecraft:stained_hardened_clay 12
fill ~36~18~44 ~36~18~46 minecraft:wool 12
fill ~36~24~44 ~37~24~44 minecraft:stained_hardened_clay 12
fill ~37~7~44 ~37~7~45 minecraft:stained_hardened_clay 12
fill ~37~16~44 ~37~16~45 minecraft:stained_hardened_clay 12
fill ~37~22~44 ~38~22~46 minecraft:wool 12
fill ~38~4~44 ~41~5~44 minecraft:wool 12
fill ~38~7~44 ~42~7~46 minecraft:wool 12
setblock ~38~8~44 minecraft:stained_hardened_clay 12
fill ~38~20~44 ~38~21~46 minecraft:wool 12
fill ~38~23~44 ~38~23~47 minecraft:stained_hardened_clay 12
fill ~39~8~44 ~41~8~46 minecraft:wool 12
fill ~39~18~44 ~39~18~45 minecraft:stained_hardened_clay 12
fill ~41~6~44 ~42~6~48 minecraft:wool 12
fill ~42~0~44 ~42~1~44 minecraft:wool 12
fill ~42~2~44 ~42~2~51 minecraft:stained_hardened_clay 12
fill ~42~5~44 ~42~5~48 minecraft:wool 12
fill ~43~3~44 ~44~3~52 minecraft:stained_hardened_clay 12
fill ~43~6~44 ~43~6~45 minecraft:stained_hardened_clay 12
setblock ~45~3~44 minecraft:wool 12
fill ~48~0~44 ~48~0~49 minecraft:wool 12
fill ~49~18~44 ~50~19~44 minecraft:stained_hardened_clay 12
fill ~51~20~44 ~51~20~46 minecraft:stained_hardened_clay 12
fill ~52~19~44 ~52~19~58 minecraft:stained_hardened_clay 12
fill ~52~21~44 ~52~21~46 minecraft:stained_hardened_clay 12
fill ~53~20~44 ~53~20~45 minecraft:stained_hardened_clay 12
fill ~54~22~44 ~54~22~45 minecraft:stained_hardened_clay 12
fill ~55~17~44 ~55~17~95 minecraft:stained_hardened_clay 12
setblock ~55~21~44 minecraft:stained_hardened_clay 12
fill ~56~20~44 ~56~20~92 minecraft:stained_hardened_clay 12
fill ~58~19~44 ~58~19~92 minecraft:stained_hardened_clay 12
fill ~58~20~44 ~59~20~89 minecraft:stained_hardened_clay 12
fill ~58~21~44 ~59~21~47 minecraft:stained_hardened_clay 12
fill ~61~19~44 ~62~19~87 minecraft:stained_hardened_clay 12
fill ~61~20~44 ~61~20~87 minecraft:stained_hardened_clay 12
fill ~61~21~44 ~63~21~49 minecraft:wool 12
fill ~62~20~44 ~64~20~45 minecraft:wool 12
setblock ~63~19~44 minecraft:wool 12
fill ~65~20~44 ~65~20~46 minecraft:stained_hardened_clay 12
fill ~67~19~44 ~67~19~49 minecraft:stained_hardened_clay 12
fill ~69~17~44 ~69~17~45 minecraft:stained_hardened_clay 12
fill ~70~2~44 ~70~2~84 minecraft:stained_hardened_clay 12
fill ~70~4~44 ~70~4~85 minecraft:stained_hardened_clay 12
fill ~70~6~44 ~70~6~88 minecraft:stained_hardened_clay 12
setblock ~70~8~44 minecraft:wool 12
fill ~70~11~44 ~70~11~49 minecraft:stained_hardened_clay 12
setblock ~70~14~44 minecraft:stained_hardened_clay 12
fill ~71~14~44 ~71~14~48 minecraft:wool 12
setblock ~72~13~44 minecraft:stained_hardened_clay 12
fill ~73~2~44 ~73~2~51 minecraft:wool 12
fill ~73~3~44 ~73~3~50 minecraft:wool 12
fill ~33~7~45 ~33~9~45 minecraft:wool 12
setblock ~34~5~45 minecraft:wool 12
setblock ~34~11~45 minecraft:stained_hardened_clay 12
fill ~34~18~45 ~35~18~46 minecraft:wool 12
fill ~34~26~45 ~34~26~47 minecraft:stained_hardened_clay 12
fill ~34~27~45 ~34~27~46 minecraft:wool 7
setblock ~35~8~45 minecraft:wool 12
fill ~35~16~45 ~35~17~45 minecraft:wool 12
fill ~35~24~45 ~35~25~45 minecraft:stained_hardened_clay 12
fill ~36~6~45 ~37~6~45 minecraft:wool 12
setblock ~36~14~45 minecraft:wool 7
fill ~36~16~45 ~36~16~46 minecraft:stained_hardened_clay 12
fill ~36~19~45 ~36~20~47 minecraft:wool 12
setblock ~36~23~45 minecraft:stained_hardened_clay 12
fill ~36~24~45 ~36~24~47 minecraft:wool 12
fill ~36~25~45 ~37~25~45 minecraft:stained_hardened_clay 12
setblock ~36~26~45 minecraft:stained_hardened_clay 12
setblock ~37~5~45 minecraft:wool 12
setblock ~37~17~45 minecraft:wool 12
fill ~37~23~45 ~37~23~47 minecraft:wool 12
fill ~37~24~45 ~38~24~45 minecraft:stained_hardened_clay 12
fill ~38~8~45 ~38~8~46 minecraft:wool 12
fill ~38~17~45 ~38~18~45 minecraft:stained_hardened_clay 12
fill ~39~4~45 ~42~4~47 minecraft:wool 12
fill ~39~5~45 ~41~5~48 minecraft:wool 12
fill ~39~6~45 ~39~6~46 minecraft:wool 12
setblock ~39~21~45 minecraft:wool 12
fill ~40~0~45 ~40~0~48 minecraft:wool 12
setblock ~41~20~45 minecraft:stained_hardened_clay 12
fill ~42~0~45 ~42~0~48 minecraft:stained_hardened_clay 12
setblock ~42~1~45 minecraft:stained_hardened_clay 12
fill ~42~8~45 ~42~8~47 minecraft:wool 12
fill ~45~3~45 ~45~3~48 minecraft:stained_hardened_clay 12
setblock ~45~17~45 minecraft:stained_hardened_clay 12
setblock ~47~20~45 minecraft:stained_hardened_clay 12
fill ~48~1~45 ~48~1~49 minecraft:wool 12
setblock ~48~2~45 minecraft:stained_hardened_clay 12
fill ~48~17~45 ~48~17~98 minecraft:stained_hardened_clay 12
setblock ~49~20~45 minecraft:stained_hardened_clay 12
fill ~50~18~45 ~50~18~96 minecraft:stained_hardened_clay 12
fill ~50~19~45 ~51~19~45 minecraft:stained_hardened_clay 12
fill ~54~20~45 ~54~20~52 minecraft:stained_hardened_clay 12
setblock ~60~22~45 minecraft:stained_hardened_clay 12
fill ~61~22~45 ~61~22~66 minecraft:wool 12
fill ~63~19~45 ~63~19~80 minecraft:stained_hardened_clay 12
fill ~66~20~45 ~66~20~46 minecraft:stained_hardened_clay 12
setblock ~68~19~45 minecraft:stained_hardened_clay 12
fill ~69~16~45 ~70~16~45 minecraft:wool 7
fill ~70~8~45 ~70~8~81 minecraft:stained_hardened_clay 12
fill ~70~13~45 ~71~13~47 minecraft:wool 12
fill ~70~14~45 ~70~15~48 minecraft:wool 12
fill ~71~1~45 ~71~1~82 minecraft:stained_hardened_clay 12
setblock ~71~2~45 minecraft:wool 12
fill ~71~4~45 ~71~6~46 minecraft:stained_hardened_clay 12
fill ~71~12~45 ~72~12~45 minecraft:stained_hardened_clay 12
setblock ~72~5~45 minecraft:stained_hardened_clay 12
fill ~73~4~45 ~73~4~50 minecraft:wool 12
fill ~32~28~46 ~32~28~47 minecraft:stained_hardened_clay 12
setblock ~33~28~46 minecraft:wool 7
fill ~34~19~46 ~35~19~47 minecraft:wool 12
fill ~35~8~46 ~35~9~46 minecraft:stained_hardened_clay 12
fill ~35~20~46 ~35~20~48 minecraft:wool 12
fill ~35~25~46 ~37~25~46 minecraft:wool 12
fill ~35~26~46 ~35~27~46 minecraft:stained_hardened_clay 12
fill ~36~7~46 ~37~7~46 minecraft:wool 12
fill ~36~10~46 ~37~11~46 minecraft:stained_hardened_clay 12
setblock ~36~12~46 minecraft:stained_hardened_clay 12
fill ~36~17~46 ~37~17~46 minecraft:stained_hardened_clay 12
fill ~36~21~46 ~36~21~48 minecraft:wool 12
setblock ~37~19~46 minecraft:wool 12
fill ~37~24~46 ~37~24~47 minecraft:wool 12
fill ~38~9~46 ~39~9~46 minecraft:stained_hardened_clay 12
setblock ~38~19~46 minecraft:stained_hardened_clay 12
setblock ~38~24~46 minecraft:stained_hardened_clay 12
setblock ~39~23~46 minecraft:stained_hardened_clay 12
setblock ~40~9~46 minecraft:wool 12
setblock ~40~14~46 minecraft:stained_hardened_clay 12
setblock ~42~1~46 minecraft:wool 12
setblock ~42~3~46 minecraft:wool 12
fill ~43~2~46 ~43~2~47 minecraft:stained_hardened_clay 12
setblock ~43~6~46 minecraft:wool 12
setblock ~43~15~46 minecraft:stained_hardened_clay 12
setblock ~45~16~46 minecraft:stained_hardened_clay 12
fill ~45~18~46 ~45~18~47 minecraft:stained_hardened_clay 12
fill ~46~17~46 ~47~17~46 minecraft:stained_hardened_clay 12
fill ~47~18~46 ~48~19~46 minecraft:stained_hardened_clay 12
fill ~48~2~46 ~48~2~48 minecraft:wool 12
setblock ~48~20~46 minecraft:stained_hardened_clay 12
fill ~50~20~46 ~50~20~48 minecraft:stained_hardened_clay 12
setblock ~52~20~46 minecraft:stained_hardened_clay 12
fill ~56~21~46 ~56~21~51 minecraft:stained_hardened_clay 12
fill ~58~22~46 ~59~22~47 minecraft:stained_hardened_clay 12
fill ~60~22~46 ~60~22~62 minecraft:wool 12
setblock ~62~20~46 minecraft:wool 12
fill ~62~22~46 ~62~22~66 minecraft:wool 12
fill ~63~20~46 ~64~20~46 minecraft:stained_hardened_clay 12
setblock ~64~21~46 minecraft:stained_hardened_clay 12
setblock ~69~14~46 minecraft:wool 12
fill ~69~15~46 ~69~17~46 minecraft:wool 7
setblock ~70~10~46 minecraft:wool 12
fill ~70~16~46 ~70~16~48 minecraft:wool 12
fill ~71~2~46 ~71~3~48 minecraft:stained_hardened_clay 12
fill ~71~7~46 ~72~7~46 minecraft:stained_hardened_clay 12
setblock ~71~8~46 minecraft:stained_hardened_clay 12
fill ~71~12~46 ~72~12~46 minecraft:wool 12
fill ~71~15~46 ~71~15~49 minecraft:wool 12
fill ~72~0~46 ~72~0~82 minecraft:stained_hardened_clay 12
fill ~72~5~46 ~73~5~50 minecraft:wool 12
setblock ~72~6~46 minecraft:wool 7
fill ~72~13~46 ~72~13~47 minecraft:wool 12
setblock ~73~1~46 minecraft:wool 12
fill ~32~25~47 ~32~27~47 minecraft:wool 12
setblock ~33~27~47 minecraft:stained_hardened_clay 12
fill ~34~20~47 ~34~22~47 minecraft:wool 12
setblock ~35~18~47 minecraft:wool 12
fill ~35~21~47 ~35~23~48 minecraft:wool 12
fill ~35~25~47 ~36~25~47 minecraft:wool 12
setblock ~36~18~47 minecraft:stained_hardened_clay 12
fill ~36~22~47 ~37~22~47 minecraft:wool 12
fill ~36~23~47 ~36~23~48 minecraft:wool 12
setblock ~37~19~47 minecraft:stained_hardened_clay 12
fill ~38~21~47 ~38~22~47 minecraft:stained_hardened_clay 12
fill ~40~1~47 ~41~1~48 minecraft:wool 12
fill ~40~7~47 ~42~7~48 minecraft:wool 12
fill ~40~9~47 ~40~10~47 minecraft:stained_hardened_clay 12
fill ~40~12~47 ~41~12~47 minecraft:stained_hardened_clay 12
fill ~41~8~47 ~41~8~55 minecraft:wool 12
