setblock ~2~0~1 minecraft:gravel
setblock ~3~0~1 minecraft:grass
setblock ~4~0~1 minecraft:gravel
fill ~5~0~1 ~6~0~1 minecraft:grass
setblock ~7~0~1 minecraft:gravel
fill ~8~0~1 ~9~0~1 minecraft:grass
fill ~10~0~1 ~11~0~1 minecraft:gravel
setblock ~12~0~1 minecraft:grass
setblock ~13~0~1 minecraft:gravel
fill ~14~0~1 ~14~0~2 minecraft:grass
fill ~22~0~1 ~23~0~1 minecraft:grass
fill ~24~0~1 ~29~0~1 minecraft:gravel
fill ~30~0~1 ~31~0~1 minecraft:grass
fill ~32~0~1 ~33~0~1 minecraft:gravel
fill ~34~0~1 ~35~0~1 minecraft:grass
fill ~36~0~1 ~37~0~1 minecraft:gravel
setblock ~38~0~1 minecraft:grass
setblock ~39~0~1 minecraft:gravel
fill ~40~0~1 ~42~0~1 minecraft:grass
fill ~2~0~2 ~2~0~3 minecraft:grass
fill ~3~0~2 ~13~0~4 minecraft:dirt 0
fill ~3~1~2 ~5~1~2 minecraft:grass
setblock ~6~1~2 minecraft:gravel
setblock ~7~1~2 minecraft:grass
fill ~8~1~2 ~10~1~2 minecraft:gravel
setblock ~11~1~2 minecraft:grass
setblock ~12~1~2 minecraft:gravel
fill ~13~1~2 ~13~1~3 minecraft:grass
fill ~15~0~2 ~19~0~2 minecraft:gravel
setblock ~20~0~2 minecraft:grass
setblock ~21~0~2 minecraft:gravel
setblock ~22~0~2 minecraft:grass
fill ~23~0~2 ~41~0~4 minecraft:dirt 0
setblock ~23~1~2 minecraft:grass
fill ~23~24~2 ~24~24~2 minecraft:stone_brick_stairs 2
fill ~24~1~2 ~28~1~2 minecraft:gravel
setblock ~27~22~2 minecraft:torch 4
setblock ~27~24~2 minecraft:stone_brick_stairs 6
fill ~27~25~2 ~27~25~3 minecraft:stone_brick_stairs 0
setblock ~28~25~2 minecraft:stone_brick_stairs 6
fill ~28~26~2 ~28~26~3 minecraft:stone_block_slab 5
fill ~29~1~2 ~30~1~2 minecraft:grass
setblock ~29~22~2 minecraft:torch 4
setblock ~29~24~2 minecraft:stone_brick_stairs 6
fill ~29~25~2 ~29~25~3 minecraft:stone_brick_stairs 1
fill ~31~1~2 ~32~1~2 minecraft:gravel
setblock ~31~22~2 minecraft:torch 4
setblock ~31~24~2 minecraft:stone_brick_stairs 6
fill ~31~25~2 ~31~25~3 minecraft:stone_brick_stairs 0
setblock ~32~25~2 minecraft:stone_brick_stairs 6
fill ~32~26~2 ~32~26~3 minecraft:stone_block_slab 5
fill ~33~1~2 ~34~1~2 minecraft:grass
setblock ~33~22~2 minecraft:torch 4
setblock ~33~24~2 minecraft:stone_brick_stairs 6
fill ~33~25~2 ~33~25~3 minecraft:stone_brick_stairs 1
fill ~35~1~2 ~36~1~2 minecraft:gravel
setblock ~35~22~2 minecraft:torch 4
setblock ~35~24~2 minecraft:stone_brick_stairs 6
fill ~35~25~2 ~35~25~3 minecraft:stone_brick_stairs 0
setblock ~36~25~2 minecraft:stone_brick_stairs 6
fill ~36~26~2 ~36~26~3 minecraft:stone_block_slab 5
fill ~37~1~2 ~40~1~2 minecraft:grass
setblock ~37~22~2 minecraft:torch 4
setblock ~37~24~2 minecraft:stone_brick_stairs 6
fill ~37~25~2 ~37~25~3 minecraft:stone_brick_stairs 1
fill ~40~24~2 ~41~24~2 minecraft:stone_brick_stairs 2
fill ~41~1~2 ~41~1~3 minecraft:gravel
setblock ~42~0~2 minecraft:grass
fill ~3~1~3 ~3~1~4 minecraft:gravel
fill ~4~1~3 ~12~3~3 minecraft:stonebrick 0
fill ~4~4~3 ~4~4~10 minecraft:stone_brick_stairs 0
fill ~4~12~3 ~12~12~3 minecraft:stonebrick 0
setblock ~4~13~3 minecraft:stonebrick 0
setblock ~4~14~3 minecraft:stone_block_slab 0
fill ~5~4~3 ~11~4~3 minecraft:stone_brick_stairs 2
setblock ~5~11~3 minecraft:stone_brick_stairs 6
setblock ~5~13~3 minecraft:stone_block_slab 5
setblock ~6~13~3 minecraft:double_stone_block_slab 5
setblock ~6~14~3 minecraft:stone_block_slab 0
setblock ~7~11~3 minecraft:stone_brick_stairs 6
setblock ~7~13~3 minecraft:stone_block_slab 5
setblock ~8~13~3 minecraft:double_stone_block_slab 5
setblock ~8~14~3 minecraft:stone_block_slab 0
setblock ~9~11~3 minecraft:stone_brick_stairs 6
setblock ~9~13~3 minecraft:stone_block_slab 5
setblock ~10~13~3 minecraft:double_stone_block_slab 5
setblock ~10~14~3 minecraft:stone_block_slab 0
setblock ~11~11~3 minecraft:stone_brick_stairs 6
setblock ~11~13~3 minecraft:stone_block_slab 5
fill ~12~4~3 ~12~4~4 minecraft:stone_brick_stairs 1
setblock ~12~13~3 minecraft:stonebrick 0
setblock ~12~14~3 minecraft:stone_block_slab 0
fill ~14~0~3 ~22~0~5 minecraft:dirt 0
fill ~14~1~3 ~18~1~3 minecraft:gravel
fill ~19~1~3 ~21~1~3 minecraft:grass
fill ~22~1~3 ~23~1~3 minecraft:gravel
fill ~23~25~3 ~24~25~3 minecraft:stone_brick_stairs 2
fill ~24~1~3 ~40~3~3 minecraft:stonebrick 0
fill ~24~4~3 ~24~4~4 minecraft:stone_brick_stairs 0
fill ~24~20~3 ~40~20~3 minecraft:stonebrick 0
fill ~24~21~3 ~24~24~3 minecraft:stonebrick 0
fill ~25~4~3 ~39~4~3 minecraft:stone_brick_stairs 2
setblock ~25~19~3 minecraft:stone_brick_stairs 6
fill ~25~21~3 ~26~23~3 minecraft:stained_hardened_clay 15
fill ~25~24~3 ~26~24~3 minecraft:stone_stairs 2
setblock ~27~14~3 minecraft:torch 4
setblock ~27~19~3 minecraft:stone_brick_stairs 6
fill ~27~21~3 ~27~24~3 minecraft:stonebrick 0
fill ~28~21~3 ~28~23~3 minecraft:stained_glass_pane 2
fill ~28~24~3 ~29~24~3 minecraft:stonebrick 0
setblock ~28~25~3 minecraft:stonebrick 0
setblock ~29~14~3 minecraft:torch 4
setblock ~29~19~3 minecraft:stone_brick_stairs 6
fill ~29~21~3 ~29~23~3 minecraft:stonebrick 0
fill ~30~21~3 ~30~23~3 minecraft:stained_hardened_clay 15
setblock ~30~24~3 minecraft:stone_stairs 2
setblock ~31~14~3 minecraft:torch 4
setblock ~31~19~3 minecraft:stone_brick_stairs 6
fill ~31~21~3 ~31~24~3 minecraft:stonebrick 0
fill ~32~21~3 ~32~23~3 minecraft:stained_glass_pane 2
fill ~32~24~3 ~33~24~3 minecraft:stonebrick 0
setblock ~32~25~3 minecraft:stonebrick 0
setblock ~33~14~3 minecraft:torch 4
setblock ~33~19~3 minecraft:stone_brick_stairs 6
fill ~33~21~3 ~33~23~3 minecraft:stonebrick 0
fill ~34~21~3 ~34~23~3 minecraft:stained_hardened_clay 15
setblock ~34~24~3 minecraft:stone_stairs 2
setblock ~35~14~3 minecraft:torch 4
setblock ~35~19~3 minecraft:stone_brick_stairs 6
fill ~35~21~3 ~35~24~3 minecraft:stonebrick 0
fill ~36~21~3 ~36~23~3 minecraft:stained_glass_pane 2
fill ~36~24~3 ~37~24~3 minecraft:stonebrick 0
setblock ~36~25~3 minecraft:stonebrick 0
setblock ~37~14~3 minecraft:torch 4
setblock ~37~19~3 minecraft:stone_brick_stairs 6
fill ~37~21~3 ~37~23~3 minecraft:stonebrick 0
fill ~38~21~3 ~39~23~3 minecraft:stained_hardened_clay 15
fill ~38~24~3 ~39~24~3 minecraft:stone_stairs 2
setblock ~39~19~3 minecraft:stone_brick_stairs 6
fill ~40~4~3 ~40~4~10 minecraft:stone_brick_stairs 1
fill ~40~21~3 ~40~24~3 minecraft:stonebrick 0
fill ~40~25~3 ~41~25~3 minecraft:stone_brick_stairs 2
fill ~42~0~3 ~42~0~4 minecraft:gravel
setblock ~2~0~4 minecraft:gravel
fill ~4~1~4 ~5~3~4 minecraft:stonebrick 0
setblock ~4~11~4 minecraft:stone_brick_stairs 4
fill ~4~12~4 ~4~12~11 minecraft:stonebrick 0
setblock ~4~13~4 minecraft:stone_block_slab 5
fill ~5~4~4 ~5~11~4 minecraft:stonebrick 0
fill ~5~12~4 ~11~12~4 minecraft:cobblestone
fill ~6~1~4 ~10~9~4 minecraft:stained_hardened_clay 15
fill ~6~10~4 ~11~11~4 minecraft:stonebrick 0
setblock ~6~13~4 minecraft:torch 3
setblock ~10~13~4 minecraft:torch 3
fill ~11~1~4 ~25~3~4 minecraft:stonebrick 0
fill ~11~4~4 ~11~9~4 minecraft:stonebrick 0
setblock ~12~11~4 minecraft:stone_brick_stairs 5
fill ~12~12~4 ~12~12~5 minecraft:stonebrick 0
setblock ~12~13~4 minecraft:stone_block_slab 5
fill ~13~4~4 ~23~4~4 minecraft:stone_brick_stairs 2
fill ~21~20~4 ~21~20~10 minecraft:stone_brick_stairs 4
setblock ~21~21~4 minecraft:stonebrick 0
setblock ~21~22~4 minecraft:stone_block_slab 0
fill ~22~19~4 ~23~19~4 minecraft:stone_block_slab 13
fill ~22~20~4 ~24~20~4 minecraft:stonebrick 0
setblock ~22~21~4 minecraft:stone_block_slab 5
setblock ~23~21~4 minecraft:stonebrick 0
setblock ~23~22~4 minecraft:stone_block_slab 0
fill ~23~26~4 ~24~26~4 minecraft:stone_brick_stairs 2
setblock ~24~19~4 minecraft:stone_brick_stairs 4
fill ~24~21~4 ~24~24~4 minecraft:stained_hardened_clay 15
setblock ~24~25~4 minecraft:stonebrick 0
fill ~25~4~4 ~25~19~4 minecraft:stonebrick 0
fill ~25~20~4 ~39~20~4 minecraft:stained_hardened_clay 15
fill ~25~21~4 ~26~21~4 minecraft:shulker_box 12
fill ~25~22~4 ~26~22~4 minecraft:shulker_box 4
fill ~25~23~4 ~26~23~4 minecraft:shulker_box 12
fill ~25~24~4 ~26~24~4 minecraft:stone_stairs 7
fill ~25~25~4 ~39~25~4 minecraft:stone_stairs 2
fill ~26~1~4 ~38~11~4 minecraft:stained_hardened_clay 15
fill ~26~12~4 ~26~12~10 minecraft:stained_hardened_clay 15
fill ~26~13~4 ~26~17~4 minecraft:stained_hardened_clay 15
fill ~26~18~4 ~39~18~4 minecraft:stonebrick 0
fill ~26~19~4 ~35~19~4 minecraft:stonebrick 0
fill ~27~12~4 ~29~12~4 minecraft:stonebrick 0
fill ~27~13~4 ~27~16~4 minecraft:stonebrick 0
fill ~27~17~4 ~38~17~4 minecraft:stained_hardened_clay 15
fill ~27~24~4 ~29~24~4 minecraft:stone_block_slab2 5
fill ~28~13~4 ~28~15~4 minecraft:stained_glass_pane 2
fill ~28~16~4 ~29~16~4 minecraft:stonebrick 0
fill ~29~13~4 ~29~15~4 minecraft:stonebrick 0
fill ~30~12~4 ~30~12~5 minecraft:stained_hardened_clay 15
fill ~30~13~4 ~30~16~4 minecraft:stained_hardened_clay 15
setblock ~30~24~4 minecraft:stone_stairs 7
fill ~31~12~4 ~33~12~4 minecraft:stonebrick 0
fill ~31~13~4 ~31~16~4 minecraft:stonebrick 0
fill ~31~24~4 ~33~24~4 minecraft:stone_block_slab2 5
fill ~32~13~4 ~32~15~4 minecraft:stained_glass_pane 2
fill ~32~16~4 ~33~16~4 minecraft:stonebrick 0
fill ~33~13~4 ~33~15~4 minecraft:stonebrick 0
fill ~34~12~4 ~34~12~5 minecraft:stained_hardened_clay 15
fill ~34~13~4 ~34~16~4 minecraft:stained_hardened_clay 15
setblock ~34~24~4 minecraft:stone_stairs 7
fill ~35~12~4 ~37~12~4 minecraft:stonebrick 0
fill ~35~13~4 ~35~16~4 minecraft:stonebrick 0
fill ~35~24~4 ~37~24~4 minecraft:stone_block_slab2 5
fill ~36~13~4 ~36~15~4 minecraft:stained_glass_pane 2
fill ~36~16~4 ~37~16~4 minecraft:stonebrick 0
setblock ~36~19~4 minecraft:double_stone_block_slab 5
fill ~37~13~4 ~37~15~4 minecraft:stonebrick 0
fill ~37~19~4 ~39~19~4 minecraft:stonebrick 0
fill ~38~12~4 ~38~12~10 minecraft:stained_hardened_clay 15
fill ~38~13~4 ~38~16~4 minecraft:stained_hardened_clay 15
setblock ~38~21~4 minecraft:trapdoor 1
fill ~38~24~4 ~39~24~4 minecraft:stone_stairs 7
fill ~39~1~4 ~40~3~4 minecraft:stonebrick 0
fill ~39~4~4 ~39~17~4 minecraft:stonebrick 0
setblock ~39~21~4 minecraft:grass
fill ~39~22~4 ~39~23~4 minecraft:leaves 1
setblock ~40~19~4 minecraft:stone_brick_stairs 5
fill ~40~20~4 ~40~20~11 minecraft:stonebrick 0
fill ~40~21~4 ~40~24~4 minecraft:stained_hardened_clay 15
setblock ~40~25~4 minecraft:stonebrick 0
fill ~40~26~4 ~41~26~4 minecraft:stone_brick_stairs 2
setblock ~41~1~4 minecraft:grass
setblock ~2~0~5 minecraft:grass
fill ~3~0~5 ~5~0~15 minecraft:dirt 0
setblock ~3~1~5 minecraft:grass
fill ~4~1~5 ~4~3~11 minecraft:stonebrick 0
setblock ~4~13~5 minecraft:double_stone_block_slab 5
setblock ~4~14~5 minecraft:stone_block_slab 0
fill ~5~1~5 ~5~9~9 minecraft:stained_hardened_clay 15
fill ~5~10~5 ~5~11~10 minecraft:stonebrick 0
fill ~5~12~5 ~6~12~10 minecraft:cobblestone
setblock ~5~13~5 minecraft:torch 1
fill ~6~0~5 ~11~0~9 minecraft:cobblestone
fill ~6~4~5 ~6~4~8 minecraft:stone 0
setblock ~6~8~5 minecraft:acacia_stairs 3
setblock ~7~1~5 minecraft:acacia_stairs 0
fill ~7~5~5 ~7~7~6 minecraft:stonebrick 0
setblock ~7~8~5 minecraft:stonebrick 0
setblock ~7~9~5 minecraft:acacia_stairs 0
setblock ~8~2~5 minecraft:acacia_stairs 0
fill ~8~9~5 ~8~9~6 minecraft:stone_brick_stairs 5
setblock ~8~10~5 minecraft:acacia_stairs 0
setblock ~9~3~5 minecraft:acacia_stairs 0
setblock ~9~7~5 minecraft:torch 3
fill ~9~9~5 ~9~9~6 minecraft:stone_block_slab 13
fill ~9~10~5 ~12~10~6 minecraft:stonebrick 0
setblock ~9~11~5 minecraft:acacia_stairs 0
setblock ~10~4~5 minecraft:acacia_stairs 0
fill ~10~9~5 ~10~9~6 minecraft:stone_brick_stairs 4
fill ~10~11~5 ~11~12~9 minecraft:cobblestone
fill ~11~4~5 ~11~4~9 minecraft:stone 0
fill ~11~5~5 ~12~9~5 minecraft:stonebrick 0
setblock ~11~13~5 minecraft:torch 2
fill ~12~0~5 ~13~0~5 minecraft:dirt 0
fill ~12~1~5 ~12~4~5 minecraft:stonebrick 0
setblock ~12~11~5 minecraft:stonebrick 0
setblock ~12~13~5 minecraft:stonebrick 0
setblock ~12~14~5 minecraft:stone_block_slab 0
fill ~13~1~5 ~23~11~5 minecraft:stained_hardened_clay 15
fill ~13~12~5 ~24~12~5 minecraft:stonebrick 0
setblock ~13~13~5 minecraft:stone_block_slab 5
setblock ~14~13~5 minecraft:double_stone_block_slab 5
setblock ~14~14~5 minecraft:stone_block_slab 0
setblock ~15~13~5 minecraft:stone_block_slab 5
setblock ~16~13~5 minecraft:double_stone_block_slab 5
setblock ~16~14~5 minecraft:stone_block_slab 0
setblock ~17~13~5 minecraft:stone_block_slab 5
setblock ~18~13~5 minecraft:double_stone_block_slab 5
setblock ~18~14~5 minecraft:stone_block_slab 0
setblock ~19~13~5 minecraft:stone_block_slab 5
setblock ~20~13~5 minecraft:double_stone_block_slab 5
setblock ~20~14~5 minecraft:stone_block_slab 0
setblock ~21~13~5 minecraft:stone_block_slab 5
setblock ~21~21~5 minecraft:stone_block_slab 5
setblock ~22~13~5 minecraft:double_stone_block_slab 5
setblock ~22~14~5 minecraft:stone_block_slab 0
fill ~22~20~5 ~23~20~6 minecraft:double_stone_block_slab 5
fill ~23~0~5 ~24~0~5 minecraft:dirt 0
setblock ~23~13~5 minecraft:stone_block_slab 5
fill ~23~27~5 ~24~27~5 minecraft:stone_brick_stairs 2
fill ~24~1~5 ~24~11~5 minecraft:stonebrick 0
setblock ~24~13~5 minecraft:stonebrick 0
setblock ~24~14~5 minecraft:stone_block_slab 0
fill ~24~20~5 ~24~20~11 minecraft:stonebrick 0
fill ~24~21~5 ~24~24~6 minecraft:stonebrick 0
setblock ~24~25~5 minecraft:stained_hardened_clay 15
setblock ~24~26~5 minecraft:stonebrick 0
fill ~25~0~5 ~38~0~9 minecraft:cobblestone
setblock ~25~2~5 minecraft:torch 1
fill ~25~4~5 ~38~4~9 minecraft:stone 0
fill ~25~5~5 ~25~10~5 minecraft:stonebrick 0
fill ~25~11~5 ~36~11~9 minecraft:cobblestone
fill ~25~12~5 ~25~17~5 minecraft:stained_hardened_clay 15
fill ~25~18~5 ~25~19~10 minecraft:stonebrick 0
fill ~25~20~5 ~25~20~10 minecraft:stained_hardened_clay 15
fill ~25~25~5 ~39~25~5 minecraft:stone_stairs 7
fill ~25~26~5 ~39~26~5 minecraft:stone_stairs 2
fill ~26~5~5 ~27~5~5 minecraft:chest 3
fill ~26~6~5 ~27~6~5 minecraft:brewing_stand 0
setblock ~26~8~5 minecraft:torch 3
fill ~26~10~5 ~38~10~5 minecraft:stone_stairs 7
setblock ~26~13~5 minecraft:grass
fill ~26~14~5 ~26~15~5 minecraft:leaves 1
fill ~26~18~5 ~35~18~5 minecraft:stained_hardened_clay 15
fill ~26~19~5 ~34~19~5 minecraft:stained_hardened_clay 15
fill ~26~20~5 ~33~20~9 minecraft:planks 4
fill ~27~12~5 ~29~12~5 minecraft:stained_hardened_clay 15
setblock ~27~13~5 minecraft:trapdoor 0
setblock ~27~15~5 minecraft:torch 3
fill ~28~5~5 ~29~5~5 minecraft:anvil 3
setblock ~29~15~5 minecraft:torch 3
fill ~30~5~5 ~31~5~5 minecraft:chest 3
fill ~30~6~5 ~31~6~5 minecraft:brewing_stand 0
setblock ~30~8~5 minecraft:torch 3
fill ~31~12~5 ~33~12~5 minecraft:stained_hardened_clay 15
setblock ~31~15~5 minecraft:torch 3
setblock ~32~2~5 minecraft:torch 3
setblock ~32~5~5 minecraft:smithing_table
setblock ~33~5~5 minecraft:grindstone 0
setblock ~33~15~5 minecraft:torch 3
fill ~34~5~5 ~35~5~5 minecraft:chest 3
fill ~34~6~5 ~35~6~5 minecraft:brewing_stand 0
setblock ~34~8~5 minecraft:torch 3
setblock ~34~13~5 minecraft:ender_chest 3
setblock ~34~20~5 minecraft:acacia_stairs 1
fill ~35~12~5 ~37~12~5 minecraft:stained_hardened_clay 15
setblock ~35~15~5 minecraft:torch 3
setblock ~35~19~5 minecraft:acacia_stairs 1
fill ~36~5~5 ~38~5~5 minecraft:cauldron 6
setblock ~36~18~5 minecraft:acacia_stairs 1
fill ~37~11~5 ~39~11~5 minecraft:stained_hardened_clay 15
setblock ~37~15~5 minecraft:torch 3
setblock ~37~17~5 minecraft:acacia_stairs 1
setblock ~38~7~5 minecraft:torch 3
setblock ~38~16~5 minecraft:acacia_stairs 3
setblock ~38~20~5 minecraft:wooden_slab 12
fill ~39~0~5 ~41~0~12 minecraft:dirt 0
fill ~39~1~5 ~39~10~9 minecraft:stained_hardened_clay 15
fill ~39~12~5 ~39~17~5 minecraft:stained_hardened_clay 15
fill ~39~18~5 ~39~19~10 minecraft:stonebrick 0
fill ~39~20~5 ~39~20~10 minecraft:stained_hardened_clay 15
setblock ~39~21~5 minecraft:trapdoor 2
fill ~40~1~5 ~40~3~11 minecraft:stonebrick 0
fill ~40~21~5 ~40~24~5 minecraft:stonebrick 0
setblock ~40~25~5 minecraft:stained_hardened_clay 15
setblock ~40~26~5 minecraft:stonebrick 0
fill ~40~27~5 ~41~27~5 minecraft:stone_brick_stairs 2
setblock ~41~1~5 minecraft:gravel
setblock ~41~22~5 minecraft:torch 1
setblock ~42~0~5 minecraft:grass
fill ~2~0~6 ~2~0~9 minecraft:gravel
fill ~3~1~6 ~3~1~10 minecraft:gravel
setblock ~4~11~6 minecraft:stone_brick_stairs 4
setblock ~4~13~6 minecraft:stone_block_slab 5
setblock ~6~5~6 minecraft:stone_block_slab 13
setblock ~6~6~6 minecraft:double_stone_block_slab 5
setblock ~6~7~6 minecraft:acacia_stairs 3
setblock ~6~9~6 minecraft:torch 1
fill ~6~11~6 ~9~11~10 minecraft:cobblestone
fill ~7~4~6 ~10~4~8 minecraft:stone 0
setblock ~7~8~6 minecraft:double_stone_block_slab 5
setblock ~7~9~6 minecraft:stonebrick 0
setblock ~7~10~6 minecraft:double_stone_block_slab 5
fill ~7~12~6 ~8~12~15 minecraft:cobblestone
fill ~8~5~6 ~9~5~6 minecraft:fence 4
setblock ~8~10~6 minecraft:stonebrick 0
setblock ~9~12~6 minecraft:acacia_stairs 2
fill ~11~8~6 ~12~8~6 minecraft:stone_brick_stairs 7
fill ~11~9~6 ~12~9~9 minecraft:stonebrick 0
fill ~12~0~6 ~24~0~8 minecraft:cobblestone
fill ~12~4~6 ~24~4~8 minecraft:stone 0
fill ~12~11~6 ~24~12~8 minecraft:cobblestone
setblock ~12~13~6 minecraft:torch 3
setblock ~13~2~6 minecraft:torch 3
fill ~13~6~6 ~23~7~6 minecraft:wall_banner 3
setblock ~13~8~6 minecraft:torch 3
fill ~13~10~6 ~23~10~6 minecraft:stone_stairs 7
setblock ~18~2~6 minecraft:torch 3
setblock ~18~8~6 minecraft:torch 3
setblock ~18~13~6 minecraft:torch 3
setblock ~21~21~6 minecraft:double_stone_block_slab 5
setblock ~21~22~6 minecraft:stone_block_slab 0
fill ~22~19~6 ~23~19~6 minecraft:stone_block_slab 13
setblock ~23~8~6 minecraft:torch 3
setblock ~23~22~6 minecraft:torch 2
fill ~23~24~6 ~23~24~8 minecraft:stone_stairs 0
fill ~23~28~6 ~24~28~6 minecraft:stone_brick_stairs 2
setblock ~24~2~6 minecraft:torch 3
fill ~24~8~6 ~25~8~6 minecraft:stone_brick_stairs 7
fill ~24~9~6 ~25~10~9 minecraft:stonebrick 0
setblock ~24~14~6 minecraft:torch 2
fill ~24~16~6 ~24~16~8 minecraft:stone_stairs 0
setblock ~24~19~6 minecraft:stone_brick_stairs 4
fill ~24~25~6 ~24~25~8 minecraft:stonebrick 0
setblock ~24~26~6 minecraft:stained_hardened_clay 15
setblock ~24~27~6 minecraft:stonebrick 0
fill ~25~12~6 ~25~12~8 minecraft:stonebrick 0
fill ~25~13~6 ~25~16~6 minecraft:stonebrick 0
fill ~25~17~6 ~25~17~9 minecraft:stained_hardened_clay 15
setblock ~25~22~6 minecraft:torch 1
fill ~25~26~6 ~39~26~6 minecraft:stone_stairs 7
fill ~25~27~6 ~39~27~6 minecraft:stone_stairs 2
setblock ~26~13~6 minecraft:trapdoor 2
setblock ~26~14~6 minecraft:torch 1
fill ~26~18~6 ~26~18~9 minecraft:stained_hardened_clay 15
fill ~26~19~6 ~26~19~8 minecraft:stained_hardened_clay 15
fill ~27~12~6 ~37~12~8 minecraft:planks 4
fill ~27~13~6 ~37~13~6 minecraft:carpet 14
fill ~27~18~6 ~37~19~8 minecraft:planks 4
fill ~28~21~6 ~32~21~6 minecraft:wooden_slab 1
fill ~34~20~6 ~38~20~9 minecraft:planks 4
fill ~35~21~6 ~37~21~6 minecraft:fence 4
fill ~37~11~6 ~37~11~37 minecraft:cobblestone
fill ~38~5~6 ~38~5~9 minecraft:cauldron 6
fill ~38~10~6 ~38~10~9 minecraft:stone_stairs 4
fill ~38~11~6 ~39~11~8 minecraft:stained_hardened_clay 15
setblock ~38~15~6 minecraft:acacia_stairs 3
fill ~38~19~6 ~38~19~9 minecraft:stained_hardened_clay 15
setblock ~38~21~6 minecraft:spruce_wall_sign 2
fill ~39~12~6 ~39~12~8 minecraft:stonebrick 0
fill ~39~13~6 ~39~16~6 minecraft:stonebrick 0
fill ~39~17~6 ~39~17~9 minecraft:stained_hardened_clay 15
setblock ~40~14~6 minecraft:torch 1
setblock ~40~19~6 minecraft:stone_brick_stairs 5
fill ~40~21~6 ~40~23~6 minecraft:stained_glass_pane 2
fill ~40~24~6 ~40~24~9 minecraft:stonebrick 0
fill ~40~25~6 ~40~25~8 minecraft:stonebrick 0
setblock ~40~26~6 minecraft:stained_hardened_clay 15
setblock ~40~27~6 minecraft:stonebrick 0
fill ~40~28~6 ~41~28~6 minecraft:stone_brick_stairs 2
fill ~41~1~6 ~41~1~7 minecraft:grass
setblock ~42~0~6 minecraft:gravel
setblock ~4~13~7 minecraft:double_stone_block_slab 5
setblock ~4~14~7 minecraft:stone_block_slab 0
setblock ~6~2~7 minecraft:torch 1
setblock ~6~6~7 minecraft:acacia_stairs 1
fill ~6~10~7 ~10~10~7 minecraft:stone_stairs 7
setblock ~7~5~7 minecraft:acacia_stairs 1
setblock ~7~13~7 minecraft:chest 5
fill ~9~12~7 ~9~12~15 minecraft:cobblestone
fill ~11~8~7 ~12~8~7 minecraft:stone_block_slab 13
fill ~11~10~7 ~12~10~9 minecraft:stonebrick 0
fill ~13~10~7 ~23~10~7 minecraft:stone_block_slab2 5
setblock ~21~21~7 minecraft:stone_block_slab 5
fill ~22~20~7 ~23~20~7 minecraft:stonebrick 0
setblock ~23~28~7 minecraft:stone_block_slab 13
fill ~23~29~7 ~24~29~7 minecraft:stone_block_slab 5
fill ~24~8~7 ~25~8~7 minecraft:stone_block_slab 13
setblock ~24~21~7 minecraft:spruce_door 0
fill ~24~23~7 ~24~24~9 minecraft:stonebrick 0
setblock ~24~26~7 minecraft:stonebrick 0
setblock ~24~27~7 minecraft:stained_hardened_clay 15
setblock ~24~28~7 minecraft:stonebrick 0
setblock ~25~13~7 minecraft:spruce_door 0
setblock ~25~15~7 minecraft:stone_brick_stairs 5
fill ~25~16~7 ~25~16~8 minecraft:stonebrick 0
fill ~25~27~7 ~39~27~7 minecraft:stone_block_slab2 5
fill ~25~28~7 ~39~28~7 minecraft:stone_block_slab2 5
fill ~27~13~7 ~28~13~8 minecraft:carpet 14
fill ~28~21~7 ~28~21~9 minecraft:wooden_slab 1
fill ~29~13~7 ~29~13~8 minecraft:quartz_stairs 1
fill ~29~21~7 ~31~21~10 minecraft:wool 14
fill ~29~22~7 ~31~22~8 minecraft:carpet 14
fill ~30~13~7 ~31~13~7 minecraft:quartz_stairs 3
fill ~32~13~7 ~37~13~7 minecraft:carpet 14
fill ~32~21~7 ~32~21~9 minecraft:wooden_slab 1
setblock ~38~2~7 minecraft:torch 2
setblock ~38~7~7 minecraft:torch 2
setblock ~38~14~7 minecraft:acacia_stairs 3
fill ~38~18~7 ~38~18~9 minecraft:stained_hardened_clay 15
setblock ~38~21~7 minecraft:spruce_stairs 1
fill ~39~13~7 ~39~15~7 minecraft:stained_glass_pane 2
fill ~39~16~7 ~39~16~8 minecraft:stonebrick 0
setblock ~39~21~7 minecraft:lectern 1
setblock ~39~23~7 minecraft:torch 2
fill ~40~21~7 ~40~23~7 minecraft:stonebrick 0
setblock ~40~26~7 minecraft:stonebrick 0
setblock ~40~27~7 minecraft:stained_hardened_clay 15
setblock ~40~28~7 minecraft:stonebrick 0
fill ~40~29~7 ~41~29~7 minecraft:stone_block_slab 5
setblock ~41~22~7 minecraft:torch 1
setblock ~41~28~7 minecraft:stone_block_slab 13
fill ~42~0~7 ~42~0~8 minecraft:grass
setblock ~4~11~8 minecraft:stone_brick_stairs 4
setblock ~4~13~8 minecraft:stone_block_slab 5
fill ~6~5~8 ~7~5~8 minecraft:stonebrick 0
setblock ~6~6~8 minecraft:stonebrick 0
setblock ~6~7~8 minecraft:stone_block_slab 5
fill ~6~10~8 ~10~10~8 minecraft:stone_block_slab2 5
setblock ~7~6~8 minecraft:stone_block_slab 5
fill ~11~8~8 ~12~8~8 minecraft:stone_brick_stairs 6
setblock ~12~13~8 minecraft:torch 4
fill ~13~6~8 ~16~7~8 minecraft:wall_banner 2
setblock ~13~8~8 minecraft:torch 4
fill ~13~10~8 ~23~10~8 minecraft:stone_stairs 6
setblock ~18~8~8 minecraft:torch 4
setblock ~18~13~8 minecraft:torch 4
fill ~20~6~8 ~23~7~8 minecraft:wall_banner 2
setblock ~21~21~8 minecraft:stonebrick 0
setblock ~21~22~8 minecraft:stone_block_slab 0
fill ~22~19~8 ~23~19~8 minecraft:stone_block_slab 13
fill ~22~20~8 ~23~20~9 minecraft:double_stone_block_slab 5
setblock ~23~8~8 minecraft:torch 4
setblock ~23~22~8 minecraft:torch 2
fill ~23~28~8 ~24~28~8 minecraft:stone_brick_stairs 3
setblock ~24~2~8 minecraft:torch 4
fill ~24~8~8 ~25~8~8 minecraft:stone_brick_stairs 6
setblock ~24~14~8 minecraft:torch 2
setblock ~24~19~8 minecraft:stone_brick_stairs 4
fill ~24~21~8 ~24~22~9 minecraft:stonebrick 0
setblock ~24~26~8 minecraft:stained_hardened_clay 15
setblock ~24~27~8 minecraft:stonebrick 0
fill ~25~13~8 ~25~15~8 minecraft:stonebrick 0
setblock ~25~22~8 minecraft:torch 1
fill ~25~26~8 ~39~26~8 minecraft:stone_stairs 6
fill ~25~27~8 ~39~27~8 minecraft:stone_stairs 3
setblock ~26~13~8 minecraft:trapdoor 3
setblock ~26~14~8 minecraft:torch 1
setblock ~30~13~8 minecraft:stone_block_slab 6
setblock ~31~13~8 minecraft:quartz_stairs 0
fill ~32~13~8 ~32~13~9 minecraft:stone_block_slab 6
fill ~33~13~8 ~37~13~8 minecraft:carpet 14
setblock ~38~13~8 minecraft:acacia_stairs 3
setblock ~38~15~8 minecraft:torch 2
setblock ~38~21~8 minecraft:spruce_wall_sign 3
fill ~39~13~8 ~39~15~8 minecraft:stonebrick 0
setblock ~40~14~8 minecraft:torch 1
setblock ~40~19~8 minecraft:stone_brick_stairs 5
fill ~40~21~8 ~40~23~8 minecraft:stained_glass_pane 2
setblock ~40~26~8 minecraft:stained_hardened_clay 15
setblock ~40~27~8 minecraft:stonebrick 0
fill ~40~28~8 ~41~28~8 minecraft:stone_brick_stairs 3
fill ~41~1~8 ~41~1~9 minecraft:gravel
setblock ~4~13~9 minecraft:double_stone_block_slab 5
setblock ~4~14~9 minecraft:stone_block_slab 0
setblock ~5~13~9 minecraft:torch 1
fill ~6~4~9 ~7~4~9 minecraft:double_stone_block_slab4 2
setblock ~6~5~9 minecraft:chest 5
setblock ~6~8~9 minecraft:torch 4
fill ~6~10~9 ~10~10~9 minecraft:stone_stairs 6
fill ~8~4~9 ~10~4~10 minecraft:stone 0
setblock ~10~8~9 minecraft:torch 4
setblock ~11~2~9 minecraft:torch 4
fill ~11~5~9 ~12~8~9 minecraft:stonebrick 0
setblock ~11~13~9 minecraft:torch 2
fill ~12~0~9 ~24~0~9 minecraft:dirt 0
fill ~12~1~9 ~12~4~9 minecraft:stonebrick 0
fill ~12~11~9 ~12~13~9 minecraft:stonebrick 0
setblock ~12~14~9 minecraft:stone_block_slab 0
fill ~13~1~9 ~23~4~9 minecraft:stained_hardened_clay 15
fill ~13~5~9 ~16~11~9 minecraft:stained_hardened_clay 15
fill ~13~12~9 ~24~12~9 minecraft:stonebrick 0
setblock ~13~13~9 minecraft:stone_block_slab 5
setblock ~14~13~9 minecraft:stonebrick 0
setblock ~14~14~9 minecraft:stone_block_slab 0
setblock ~15~13~9 minecraft:stone_block_slab 5
setblock ~16~13~9 minecraft:stonebrick 0
setblock ~16~14~9 minecraft:stone_block_slab 0
fill ~17~5~9 ~17~7~9 minecraft:stonebrick 0
fill ~17~8~9 ~23~11~9 minecraft:stained_hardened_clay 15
setblock ~17~13~9 minecraft:stone_block_slab 5
setblock ~18~5~9 minecraft:spruce_door 3
fill ~18~7~9 ~19~7~9 minecraft:stonebrick 0
setblock ~18~13~9 minecraft:stonebrick 0
setblock ~18~14~9 minecraft:stone_block_slab 0
fill ~19~5~9 ~19~6~9 minecraft:stonebrick 0
setblock ~19~13~9 minecraft:stone_block_slab 5
fill ~20~5~9 ~23~7~9 minecraft:stained_hardened_clay 15
setblock ~20~13~9 minecraft:stonebrick 0
setblock ~20~14~9 minecraft:stone_block_slab 0
setblock ~21~13~9 minecraft:stone_block_slab 5
setblock ~21~21~9 minecraft:stone_block_slab 5
setblock ~22~13~9 minecraft:stonebrick 0
setblock ~22~14~9 minecraft:stone_block_slab 0
setblock ~23~13~9 minecraft:stone_block_slab 5
fill ~23~27~9 ~24~27~9 minecraft:stone_brick_stairs 3
fill ~24~1~9 ~24~8~9 minecraft:stonebrick 0
setblock ~24~11~9 minecraft:stonebrick 0
setblock ~24~13~9 minecraft:stonebrick 0
setblock ~24~14~9 minecraft:stone_block_slab 0
setblock ~24~25~9 minecraft:stained_hardened_clay 15
setblock ~24~26~9 minecraft:stonebrick 0
setblock ~25~2~9 minecraft:torch 1
fill ~25~5~9 ~25~8~10 minecraft:stonebrick 0
fill ~25~12~9 ~25~16~9 minecraft:stained_hardened_clay 15
setblock ~25~21~9 minecraft:trapdoor 3
fill ~25~25~9 ~39~25~9 minecraft:stone_stairs 6
fill ~25~26~9 ~39~26~9 minecraft:stone_stairs 3
fill ~26~5~9 ~27~5~9 minecraft:chest 2
fill ~26~6~9 ~27~6~9 minecraft:brewing_stand 0
setblock ~26~8~9 minecraft:torch 4
fill ~26~10~9 ~37~10~9 minecraft:stone_stairs 6
setblock ~26~13~9 minecraft:grass
fill ~26~14~9 ~26~15~9 minecraft:leaves 1
fill ~26~19~9 ~28~19~9 minecraft:planks 4
fill ~27~12~9 ~34~12~10 minecraft:stained_hardened_clay 15
setblock ~27~13~9 minecraft:trapdoor 0
fill ~27~18~9 ~35~18~9 minecraft:stained_hardened_clay 15
fill ~28~5~9 ~29~5~9 minecraft:blast_furnace 2
fill ~28~6~9 ~29~6~9 minecraft:furnace 2
fill ~29~13~9 ~31~13~9 minecraft:quartz_stairs 2
setblock ~29~15~9 minecraft:torch 4
setblock ~30~2~9 minecraft:torch 4
setblock ~30~5~9 minecraft:crafting_table
setblock ~30~8~9 minecraft:torch 4
fill ~30~19~9 ~37~19~9 minecraft:stained_hardened_clay 15
fill ~31~5~9 ~32~5~9 minecraft:blast_furnace 2
fill ~31~6~9 ~32~6~9 minecraft:furnace 2
setblock ~33~6~9 minecraft:torch 4
setblock ~35~6~9 minecraft:torch 4
fill ~35~12~9 ~36~12~13 minecraft:planks 4
fill ~35~13~9 ~38~13~9 minecraft:carpet 14
fill ~36~5~9 ~37~5~9 minecraft:cauldron 6
fill ~36~18~9 ~36~18~36 minecraft:planks 4
fill ~37~12~9 ~37~12~13 minecraft:stained_hardened_clay 15
fill ~37~18~9 ~37~18~25 minecraft:stained_hardened_clay 15
fill ~38~11~9 ~38~11~10 minecraft:cobblestone
fill ~39~11~9 ~39~16~9 minecraft:stained_hardened_clay 15
fill ~40~21~9 ~40~23~9 minecraft:stonebrick 0
setblock ~40~25~9 minecraft:stained_hardened_clay 15
setblock ~40~26~9 minecraft:stonebrick 0
fill ~40~27~9 ~41~27~9 minecraft:stone_brick_stairs 3
setblock ~41~22~9 minecraft:torch 1
fill ~42~0~9 ~42~0~10 minecraft:gravel
fill ~2~0~10 ~2~0~11 minecraft:grass
setblock ~4~11~10 minecraft:stone_brick_stairs 4
setblock ~4~13~10 minecraft:stone_block_slab 5
fill ~5~1~10 ~5~3~16 minecraft:stonebrick 0
fill ~5~4~10 ~5~9~10 minecraft:stonebrick 0
fill ~6~0~10 ~10~0~10 minecraft:cobblestone
fill ~6~4~10 ~7~4~10 minecraft:stone 0
fill ~6~5~10 ~6~10~11 minecraft:stonebrick 0
setblock ~6~13~10 minecraft:torch 4
fill ~7~8~10 ~7~8~11 minecraft:stone_brick_stairs 5
fill ~7~9~10 ~11~10~10 minecraft:stonebrick 0
fill ~8~8~10 ~8~8~11 minecraft:stone_block_slab 13
fill ~9~8~10 ~9~8~11 minecraft:stone_brick_stairs 4
setblock ~10~2~10 minecraft:torch 2
fill ~10~5~10 ~11~8~10 minecraft:stonebrick 0
fill ~10~11~10 ~10~12~10 minecraft:cobblestone
setblock ~10~13~10 minecraft:torch 4
setblock ~11~0~10 minecraft:dirt 0
fill ~11~1~10 ~11~4~10 minecraft:stonebrick 0
setblock ~11~11~10 minecraft:stonebrick 0
setblock ~11~12~10 minecraft:cobblestone
fill ~12~0~10 ~24~0~32 minecraft:cobblestone
setblock ~12~2~10 minecraft:torch 1
fill ~12~4~10 ~16~4~10 minecraft:double_stone_block_slab 0
setblock ~12~5~10 minecraft:crafting_table
setblock ~12~8~10 minecraft:torch 1
setblock ~12~11~10 minecraft:stone_brick_stairs 5
fill ~12~12~10 ~12~12~11 minecraft:stonebrick 0
setblock ~12~13~10 minecraft:stone_block_slab 5
setblock ~13~5~10 minecraft:smithing_table
setblock ~14~5~10 minecraft:blast_furnace 3
setblock ~15~5~10 minecraft:grindstone 0
fill ~17~4~10 ~19~4~32 minecraft:stone 0
setblock ~17~6~10 minecraft:torch 3
fill ~17~8~10 ~19~8~10 minecraft:stone_stairs 3
setblock ~18~2~10 minecraft:torch 3
setblock ~19~6~10 minecraft:torch 3
fill ~20~4~10 ~24~4~10 minecraft:double_stone_block_slab 0
setblock ~21~21~10 minecraft:stonebrick 0
setblock ~21~22~10 minecraft:stone_block_slab 0
fill ~22~19~10 ~23~19~10 minecraft:stone_block_slab 13
fill ~22~20~10 ~23~20~10 minecraft:stonebrick 0
setblock ~22~21~10 minecraft:stone_block_slab 5
setblock ~23~21~10 minecraft:stonebrick 0
setblock ~23~22~10 minecraft:stone_block_slab 0
fill ~23~26~10 ~24~26~10 minecraft:stone_brick_stairs 3
setblock ~24~2~10 minecraft:torch 2
setblock ~24~8~10 minecraft:torch 2
setblock ~24~19~10 minecraft:stone_brick_stairs 4
fill ~24~21~10 ~24~24~10 minecraft:stained_hardened_clay 15
setblock ~24~25~10 minecraft:stonebrick 0
fill ~25~0~10 ~29~0~10 minecraft:dirt 0
fill ~25~1~10 ~25~4~10 minecraft:stonebrick 0
fill ~25~9~10 ~25~17~10 minecraft:stonebrick 0
setblock ~25~21~10 minecraft:grass
fill ~25~22~10 ~25~23~10 minecraft:leaves 1
fill ~25~24~10 ~26~24~10 minecraft:stone_stairs 6
fill ~25~25~10 ~39~25~10 minecraft:stone_stairs 3
fill ~26~1~10 ~29~11~10 minecraft:stained_hardened_clay 15
fill ~26~13~10 ~33~17~10 minecraft:stained_hardened_clay 15
fill ~26~18~10 ~34~19~10 minecraft:stonebrick 0
fill ~26~20~10 ~38~20~10 minecraft:stained_hardened_clay 15
setblock ~26~21~10 minecraft:trapdoor 0
fill ~27~24~10 ~29~24~10 minecraft:stone_block_slab2 5
setblock ~28~21~10 minecraft:shulker_box 4
setblock ~28~22~10 minecraft:red_candle 0
fill ~29~22~10 ~31~22~10 minecraft:carpet 4
fill ~30~0~10 ~30~3~10 minecraft:stonebrick 0
fill ~30~4~10 ~38~4~10 minecraft:stone 0
fill ~30~5~10 ~30~10~11 minecraft:stonebrick 0
setblock ~30~11~10 minecraft:stained_hardened_clay 15
setblock ~30~24~10 minecraft:stone_stairs 6
fill ~31~0~10 ~38~0~10 minecraft:cobblestone
setblock ~31~2~10 minecraft:torch 1
fill ~31~5~10 ~32~10~10 minecraft:stained_hardened_clay 15
fill ~31~11~10 ~36~11~37 minecraft:cobblestone
fill ~31~24~10 ~33~24~10 minecraft:stone_block_slab2 5
setblock ~32~21~10 minecraft:shulker_box 4
setblock ~32~22~10 minecraft:red_candle 0
fill ~33~5~10 ~33~7~10 minecraft:stonebrick 0
fill ~33~8~10 ~38~10~10 minecraft:stained_hardened_clay 15
setblock ~34~5~10 minecraft:spruce_door 3
fill ~34~7~10 ~35~7~10 minecraft:stonebrick 0
fill ~34~13~10 ~34~17~10 minecraft:log 1
setblock ~34~24~10 minecraft:stone_stairs 6
fill ~35~5~10 ~35~6~10 minecraft:stonebrick 0
fill ~35~13~10 ~36~13~10 minecraft:birch_door 1
fill ~35~15~10 ~36~15~10 minecraft:log 1
fill ~35~16~10 ~36~17~10 minecraft:planks 4
fill ~35~18~10 ~35~18~25 minecraft:stained_hardened_clay 15
fill ~35~19~10 ~38~19~10 minecraft:stonebrick 0
fill ~35~24~10 ~37~24~10 minecraft:stone_block_slab2 5
fill ~36~5~10 ~38~7~10 minecraft:stained_hardened_clay 15
fill ~37~13~10 ~37~17~10 minecraft:log 1
fill ~38~13~10 ~38~17~10 minecraft:stained_hardened_clay 15
fill ~38~18~10 ~38~18~11 minecraft:stonebrick 0
fill ~38~21~10 ~39~21~10 minecraft:shulker_box 14
fill ~38~22~10 ~39~22~10 minecraft:shulker_box 4
fill ~38~23~10 ~39~23~10 minecraft:shulker_box 14
fill ~38~24~10 ~39~24~10 minecraft:stone_stairs 6
fill ~39~1~10 ~39~3~24 minecraft:stonebrick 0
fill ~39~4~10 ~39~17~10 minecraft:stonebrick 0
setblock ~40~19~10 minecraft:stone_brick_stairs 5
fill ~40~21~10 ~40~24~10 minecraft:stained_hardened_clay 15
setblock ~40~25~10 minecraft:stonebrick 0
fill ~40~26~10 ~41~26~10 minecraft:stone_brick_stairs 3
fill ~41~1~10 ~41~1~11 minecraft:grass
fill ~3~1~11 ~3~1~13 minecraft:grass
fill ~4~4~11 ~5~4~11 minecraft:stone_brick_stairs 3
setblock ~4~13~11 minecraft:stonebrick 0
setblock ~4~14~11 minecraft:stone_block_slab 0
setblock ~5~11~11 minecraft:stone_brick_stairs 7
fill ~5~12~11 ~6~12~11 minecraft:stonebrick 0
setblock ~5~13~11 minecraft:stone_block_slab 5
fill ~6~0~11 ~6~0~15 minecraft:double_stone_block_slab 5
fill ~6~1~11 ~6~4~11 minecraft:stonebrick 0
setblock ~6~11~11 minecraft:stonebrick 0
setblock ~6~13~11 minecraft:stonebrick 0
setblock ~6~14~11 minecraft:stone_block_slab 0
fill ~7~0~11 ~9~0~11 minecraft:stone_block_slab 3
fill ~7~4~11 ~8~4~11 minecraft:stone 0
fill ~7~9~11 ~10~10~11 minecraft:stonebrick 0
fill ~7~11~11 ~9~11~15 minecraft:cobblestone
setblock ~7~13~11 minecraft:torch 1
fill ~9~4~11 ~9~4~12 minecraft:double_stone_block_slab4 2
setblock ~9~13~11 minecraft:torch 2
setblock ~10~0~11 minecraft:double_stone_block_slab 5
fill ~10~1~11 ~10~8~11 minecraft:stonebrick 0
fill ~10~11~11 ~10~13~11 minecraft:stonebrick 0
setblock ~10~14~11 minecraft:stone_block_slab 0
fill ~11~0~11 ~11~0~15 minecraft:cobblestone
setblock ~11~2~11 minecraft:torch 3
fill ~11~4~11 ~12~4~11 minecraft:double_stone_block_slab 0
setblock ~11~5~11 minecraft:lodestone
setblock ~11~8~11 minecraft:torch 3
setblock ~11~11~11 minecraft:stone_brick_stairs 7
setblock ~11~12~11 minecraft:stonebrick 0
setblock ~11~13~11 minecraft:double_stone_block_slab 5
setblock ~12~13~11 minecraft:stonebrick 0
setblock ~12~14~11 minecraft:stone_block_slab 0
setblock ~13~4~11 minecraft:stone 0
setblock ~14~4~11 minecraft:double_stone_block_slab 0
setblock ~15~4~11 minecraft:stone 0
setblock ~16~4~11 minecraft:double_stone_block_slab 0
fill ~20~4~11 ~21~4~15 minecraft:stone 0
setblock ~22~4~11 minecraft:double_stone_block_slab 0
fill ~23~4~11 ~23~4~15 minecraft:stone 0
fill ~23~25~11 ~24~25~11 minecraft:stone_brick_stairs 3
fill ~24~4~11 ~28~4~11 minecraft:double_stone_block_slab 0
fill ~24~21~11 ~24~24~11 minecraft:stonebrick 0
fill ~25~0~11 ~29~0~23 minecraft:cobblestone
setblock ~25~2~11 minecraft:torch 3
setblock ~25~8~11 minecraft:torch 3
setblock ~25~19~11 minecraft:stone_brick_stairs 7
fill ~25~20~11 ~39~20~11 minecraft:stonebrick 0
fill ~25~21~11 ~26~23~11 minecraft:stained_hardened_clay 15
fill ~25~24~11 ~26~24~11 minecraft:stone_stairs 3
setblock ~27~19~11 minecraft:stone_brick_stairs 7
fill ~27~21~11 ~27~24~11 minecraft:stonebrick 0
fill ~27~25~11 ~27~25~12 minecraft:stone_brick_stairs 0
fill ~28~3~11 ~29~3~11 minecraft:stone_block_slab 13
fill ~28~21~11 ~28~23~11 minecraft:stained_glass_pane 2
fill ~28~24~11 ~29~24~11 minecraft:stonebrick 0
setblock ~28~25~11 minecraft:stonebrick 0
fill ~28~26~11 ~28~26~12 minecraft:stone_block_slab 5
setblock ~29~4~11 minecraft:log 2
fill ~29~5~11 ~29~7~11 minecraft:leaves 2
setblock ~29~8~11 minecraft:torch 2
setblock ~29~19~11 minecraft:stone_brick_stairs 7
fill ~29~21~11 ~29~23~11 minecraft:stonebrick 0
fill ~29~25~11 ~29~25~12 minecraft:stone_brick_stairs 1
fill ~30~0~11 ~30~0~15 minecraft:dirt 0
fill ~30~1~11 ~30~3~14 minecraft:stained_hardened_clay 15
setblock ~30~4~11 minecraft:double_stone_block_slab 0
fill ~30~11~11 ~30~11~23 minecraft:stonebrick 0
setblock ~30~12~11 minecraft:stonebrick 0
setblock ~30~13~11 minecraft:stone_brick_stairs 0
fill ~30~21~11 ~30~23~11 minecraft:stained_hardened_clay 15
setblock ~30~24~11 minecraft:stone_stairs 3
fill ~31~0~11 ~37~0~37 minecraft:cobblestone
fill ~31~4~11 ~31~4~15 minecraft:stone 0
setblock ~31~8~11 minecraft:torch 1
setblock ~31~12~11 minecraft:stained_hardened_clay 15
setblock ~31~13~11 minecraft:stonebrick 0
setblock ~31~14~11 minecraft:stone_brick_stairs 0
setblock ~31~19~11 minecraft:stone_brick_stairs 7
fill ~31~21~11 ~31~24~11 minecraft:stonebrick 0
fill ~31~25~11 ~31~25~12 minecraft:stone_brick_stairs 0
setblock ~32~4~11 minecraft:double_stone_block_slab 0
fill ~32~12~11 ~32~13~23 minecraft:planks 4
setblock ~32~14~11 minecraft:stonebrick 0
setblock ~32~15~11 minecraft:stone_brick_stairs 0
fill ~32~21~11 ~32~23~11 minecraft:stained_glass_pane 2
fill ~32~24~11 ~33~24~11 minecraft:stonebrick 0
setblock ~32~25~11 minecraft:stonebrick 0
fill ~32~26~11 ~32~26~12 minecraft:stone_block_slab 5
fill ~33~4~11 ~37~4~11 minecraft:stone 0
fill ~33~12~11 ~33~12~25 minecraft:stained_hardened_clay 15
fill ~33~14~11 ~33~14~15 minecraft:acacia_stairs 5
setblock ~33~15~11 minecraft:stonebrick 0
setblock ~33~16~11 minecraft:stone_brick_stairs 0
setblock ~33~19~11 minecraft:stone_brick_stairs 7
fill ~33~21~11 ~33~23~11 minecraft:stonebrick 0
fill ~33~25~11 ~33~25~12 minecraft:stone_brick_stairs 1
fill ~34~12~11 ~34~12~36 minecraft:planks 4
fill ~34~15~11 ~34~15~15 minecraft:acacia_stairs 5
fill ~34~16~11 ~34~16~23 minecraft:stonebrick 0
fill ~34~17~11 ~34~19~11 minecraft:stonebrick 0
fill ~34~21~11 ~34~23~11 minecraft:stained_hardened_clay 15
setblock ~34~24~11 minecraft:stone_stairs 3
setblock ~35~16~11 minecraft:torch 1
setblock ~35~19~11 minecraft:stone_brick_stairs 7
fill ~35~21~11 ~35~24~11 minecraft:stonebrick 0
setblock ~35~25~11 minecraft:stone_brick_stairs 0
setblock ~36~21~11 minecraft:wooden_door 3
fill ~36~23~11 ~37~24~11 minecraft:stonebrick 0
setblock ~36~25~11 minecraft:stonebrick 0
setblock ~36~26~11 minecraft:stone_block_slab 5
setblock ~37~2~11 minecraft:torch 2
fill ~37~10~11 ~37~10~23 minecraft:stone_stairs 4
setblock ~37~13~11 minecraft:cauldron 0
setblock ~37~14~11 minecraft:wall_banner 3
setblock ~37~19~11 minecraft:stone_brick_stairs 7
fill ~37~21~11 ~37~22~11 minecraft:stonebrick 0
setblock ~37~25~11 minecraft:stone_brick_stairs 1
fill ~38~0~11 ~38~0~23 minecraft:dirt 0
fill ~38~1~11 ~38~17~11 minecraft:stonebrick 0
setblock ~38~19~11 minecraft:stonebrick 0
fill ~38~21~11 ~39~23~11 minecraft:stained_hardened_clay 15
fill ~38~24~11 ~39~24~11 minecraft:stone_stairs 3
fill ~39~4~11 ~40~4~11 minecraft:stone_brick_stairs 3
setblock ~39~19~11 minecraft:stone_brick_stairs 7
fill ~40~21~11 ~40~24~11 minecraft:stonebrick 0
fill ~40~25~11 ~41~25~11 minecraft:stone_brick_stairs 3
setblock ~42~0~11 minecraft:grass
setblock ~2~0~12 minecraft:gravel
fill ~4~1~12 ~4~2~12 minecraft:gravel
fill ~5~4~12 ~5~4~14 minecraft:stone_brick_stairs 0
fill ~6~1~12 ~6~11~14 minecraft:stained_hardened_clay 15
fill ~6~12~12 ~6~12~15 minecraft:stonebrick 0
setblock ~6~13~12 minecraft:stone_block_slab 5
fill ~7~4~12 ~7~4~17 minecraft:stone 0
fill ~7~10~12 ~7~10~14 minecraft:stone_stairs 5
setblock ~8~4~12 minecraft:double_stone_block_slab4 2
fill ~8~10~12 ~8~10~15 minecraft:stone_block_slab2 5
fill ~9~10~12 ~9~10~15 minecraft:stone_stairs 4
fill ~10~0~12 ~10~0~14 minecraft:stone_block_slab 3
fill ~10~4~12 ~10~11~14 minecraft:stained_hardened_clay 15
fill ~10~12~12 ~10~12~15 minecraft:stonebrick 0
setblock ~10~13~12 minecraft:stone_block_slab 5
fill ~11~4~12 ~11~4~15 minecraft:double_stone_block_slab 0
setblock ~11~5~12 minecraft:anvil 2
setblock ~12~4~12 minecraft:stone 0
setblock ~13~4~12 minecraft:double_stone_block_slab 0
setblock ~14~4~12 minecraft:stone 0
setblock ~15~4~12 minecraft:double_stone_block_slab 0
setblock ~16~4~12 minecraft:stone 0
fill ~22~4~12 ~22~4~14 minecraft:stone 0
fill ~23~24~12 ~24~24~12 minecraft:stone_brick_stairs 3
fill ~24~4~12 ~30~4~14 minecraft:stone 0
setblock ~27~22~12 minecraft:torch 3
setblock ~27~24~12 minecraft:stone_brick_stairs 7
setblock ~28~25~12 minecraft:stone_brick_stairs 7
setblock ~29~22~12 minecraft:torch 3
setblock ~29~24~12 minecraft:stone_brick_stairs 7
setblock ~30~5~12 minecraft:acacia_fence_gate 3
setblock ~30~9~12 minecraft:stone_brick_stairs 7
fill ~30~10~12 ~30~10~24 minecraft:stonebrick 0
fill ~30~12~12 ~30~12~22 minecraft:stone_stairs 0
fill ~31~12~12 ~31~12~22 minecraft:planks 4
fill ~31~13~12 ~31~13~22 minecraft:stone_stairs 0
setblock ~31~22~12 minecraft:torch 3
setblock ~31~24~12 minecraft:stone_brick_stairs 7
fill ~32~4~12 ~34~4~14 minecraft:stone 0
fill ~32~14~12 ~32~14~22 minecraft:stone_stairs 0
setblock ~32~25~12 minecraft:stone_brick_stairs 7
fill ~33~15~12 ~33~15~22 minecraft:stone_stairs 0
setblock ~33~22~12 minecraft:torch 3
setblock ~33~24~12 minecraft:stone_brick_stairs 7
fill ~34~17~12 ~34~19~22 minecraft:stained_hardened_clay 15
fill ~34~20~12 ~34~20~23 minecraft:stonebrick 0
setblock ~34~21~12 minecraft:double_stone_block_slab 5
setblock ~34~22~12 minecraft:stone_block_slab 0
fill ~35~1~12 ~37~3~22 minecraft:stone 0
setblock ~35~4~12 minecraft:double_stone_block_slab 0
fill ~35~5~12 ~37~5~12 minecraft:fence 4
fill ~35~20~12 ~37~20~23 minecraft:cobblestone
setblock ~35~22~12 minecraft:torch 3
fill ~35~24~12 ~37~24~12 minecraft:stone_stairs 3
setblock ~36~4~12 minecraft:stone 0
setblock ~37~4~12 minecraft:double_stone_block_slab 0
setblock ~37~6~12 minecraft:fence 4
setblock ~37~13~12 minecraft:cauldron 6
setblock ~37~15~12 minecraft:torch 2
setblock ~37~22~12 minecraft:torch 3
fill ~38~1~12 ~38~19~22 minecraft:stained_hardened_clay 15
fill ~38~20~12 ~38~20~23 minecraft:stonebrick 0
setblock ~38~21~12 minecraft:double_stone_block_slab 5
setblock ~38~22~12 minecraft:stone_block_slab 0
fill ~39~4~12 ~39~4~22 minecraft:stone_brick_stairs 1
setblock ~40~1~12 minecraft:grass
fill ~40~24~12 ~41~24~12 minecraft:stone_brick_stairs 3
setblock ~41~1~12 minecraft:gravel
setblock ~42~0~12 minecraft:gravel
setblock ~2~0~13 minecraft:grass
setblock ~4~1~13 minecraft:dirt 0
setblock ~4~2~13 minecraft:grass
setblock ~6~13~13 minecraft:double_stone_block_slab 5
setblock ~6~14~13 minecraft:stone_block_slab 0
setblock ~7~2~13 minecraft:torch 1
setblock ~7~5~13 minecraft:acacia_stairs 2
setblock ~7~8~13 minecraft:torch 1
fill ~8~4~13 ~9~4~13 minecraft:stone 0
setblock ~9~8~13 minecraft:torch 2
setblock ~10~13~13 minecraft:stonebrick 0
setblock ~10~14~13 minecraft:stone_block_slab 0
setblock ~11~5~13 minecraft:chest 5
setblock ~12~4~13 minecraft:double_stone_block_slab 0
setblock ~13~4~13 minecraft:stone 0
setblock ~14~4~13 minecraft:double_stone_block_slab 0
setblock ~15~4~13 minecraft:stone 0
setblock ~16~4~13 minecraft:double_stone_block_slab 0
setblock ~30~5~13 minecraft:acacia_fence_gate 3
setblock ~34~21~13 minecraft:stone_block_slab 5
fill ~35~4~13 ~37~4~13 minecraft:hay_block 0
setblock ~37~5~13 minecraft:hopper 5
setblock ~38~21~13 minecraft:stone_block_slab 5
fill ~39~0~13 ~40~0~40 minecraft:dirt 0
fill ~40~1~13 ~40~1~14 minecraft:gravel
fill ~41~0~13 ~42~0~13 minecraft:grass
setblock ~2~0~14 minecraft:gravel
fill ~3~1~14 ~4~1~14 minecraft:gravel
setblock ~4~2~14 minecraft:gravel
setblock ~6~13~14 minecraft:stone_block_slab 5
fill ~7~5~14 ~7~5~15 minecraft:double_stone_block_slab 5
setblock ~7~6~14 minecraft:acacia_stairs 2
setblock ~8~4~14 minecraft:double_stone_block_slab4 2
setblock ~8~5~14 minecraft:stonebrick 0
fill ~8~6~14 ~9~6~14 minecraft:redstone_wire 0
fill ~9~4~14 ~9~4~15 minecraft:stone 0
setblock ~9~5~14 minecraft:stone 0
setblock ~10~13~14 minecraft:stone_block_slab 5
setblock ~11~6~14 minecraft:lever 1
setblock ~12~4~14 minecraft:stone 0
setblock ~13~4~14 minecraft:double_stone_block_slab 0
setblock ~14~4~14 minecraft:stone 0
setblock ~15~4~14 minecraft:double_stone_block_slab 0
setblock ~16~4~14 minecraft:stone 0
setblock ~30~5~14 minecraft:acacia_fence_gate 3
setblock ~30~9~14 minecraft:stone_brick_stairs 6
setblock ~34~21~14 minecraft:double_stone_block_slab 5
setblock ~34~22~14 minecraft:stone_block_slab 0
fill ~35~4~14 ~36~4~21 minecraft:hay_block 0
fill ~35~5~14 ~37~5~14 minecraft:fence 4
fill ~35~12~14 ~35~12~36 minecraft:planks 4
setblock ~36~12~14 minecraft:quartz_stairs 0
setblock ~37~4~14 minecraft:double_stone_block_slab 0
setblock ~37~6~14 minecraft:fence 4
setblock ~37~12~14 minecraft:hopper 0
setblock ~37~13~14 minecraft:spruce_trapdoor 1
setblock ~38~21~14 minecraft:double_stone_block_slab 5
setblock ~38~22~14 minecraft:stone_block_slab 0
setblock ~41~0~14 minecraft:grass
setblock ~2~0~15 minecraft:grass
setblock ~3~1~15 minecraft:grass
fill ~4~1~15 ~4~3~27 minecraft:stonebrick 0
fill ~4~4~15 ~4~4~17 minecraft:stone_brick_stairs 0
fill ~4~20~15 ~12~20~15 minecraft:stonebrick 0
setblock ~4~21~15 minecraft:stonebrick 0
setblock ~4~22~15 minecraft:stone_block_slab 0
setblock ~5~4~15 minecraft:stone_brick_stairs 2
setblock ~5~19~15 minecraft:stone_brick_stairs 6
setblock ~5~21~15 minecraft:stone_block_slab 5
fill ~6~1~15 ~6~11~15 minecraft:stonebrick 0
setblock ~6~13~15 minecraft:stonebrick 0
setblock ~6~14~15 minecraft:stone_block_slab 0
setblock ~6~21~15 minecraft:double_stone_block_slab 5
setblock ~6~22~15 minecraft:stone_block_slab 0
fill ~7~3~15 ~10~3~15 minecraft:stonebrick 0
setblock ~7~7~15 minecraft:acacia_stairs 2
setblock ~7~14~15 minecraft:torch 4
fill ~7~16~15 ~9~16~15 minecraft:stone_stairs 2
setblock ~7~19~15 minecraft:stone_brick_stairs 6
setblock ~7~21~15 minecraft:stone_block_slab 5
setblock ~8~4~15 minecraft:redstone_wire 0
setblock ~8~5~15 minecraft:stone_block_slab 13
setblock ~8~6~15 minecraft:redstone_wire 0
setblock ~8~21~15 minecraft:double_stone_block_slab 5
setblock ~8~22~15 minecraft:stone_block_slab 0
setblock ~9~5~15 minecraft:redstone_wire 0
setblock ~9~6~15 minecraft:stonebrick 0
setblock ~9~14~15 minecraft:torch 4
setblock ~9~19~15 minecraft:stone_brick_stairs 6
setblock ~9~21~15 minecraft:stone_block_slab 5
setblock ~10~0~15 minecraft:double_stone_block_slab 5
fill ~10~1~15 ~10~2~15 minecraft:stonebrick 0
setblock ~10~4~15 minecraft:stonebrick 0
fill ~10~5~15 ~10~6~15 minecraft:double_stone_block_slab 5
fill ~10~7~15 ~10~11~15 minecraft:stonebrick 0
setblock ~10~13~15 minecraft:stonebrick 0
setblock ~10~14~15 minecraft:stone_block_slab 0
setblock ~10~21~15 minecraft:double_stone_block_slab 5
setblock ~10~22~15 minecraft:stone_block_slab 0
setblock ~11~2~15 minecraft:torch 4
setblock ~11~5~15 minecraft:crimson_button 5
setblock ~11~6~15 minecraft:wall_sign 5
setblock ~11~19~15 minecraft:stone_brick_stairs 6
setblock ~11~21~15 minecraft:stone_block_slab 5
fill ~12~4~15 ~12~4~19 minecraft:double_stone_block_slab 0
setblock ~12~21~15 minecraft:stonebrick 0
setblock ~12~22~15 minecraft:stone_block_slab 0
setblock ~13~4~15 minecraft:stone 0
setblock ~14~4~15 minecraft:double_stone_block_slab 0
setblock ~15~4~15 minecraft:stone 0
setblock ~16~4~15 minecraft:double_stone_block_slab 0
setblock ~22~4~15 minecraft:double_stone_block_slab 0
setblock ~22~5~15 minecraft:leaves 2
setblock ~24~4~15 minecraft:double_stone_block_slab 0
setblock ~24~5~15 minecraft:leaves 2
setblock ~25~4~15 minecraft:stone 0
setblock ~26~4~15 minecraft:double_stone_block_slab 0
setblock ~26~5~15 minecraft:leaves 2
setblock ~27~4~15 minecraft:stone 0
fill ~28~4~15 ~28~4~23 minecraft:double_stone_block_slab 0
fill ~28~5~15 ~29~5~15 minecraft:leaves 2
setblock ~29~2~15 minecraft:torch 2
fill ~29~4~15 ~29~4~22 minecraft:stone 0
fill ~29~6~15 ~29~6~16 minecraft:leaves 2
setblock ~29~7~15 minecraft:leaves 2
setblock ~29~8~15 minecraft:torch 2
fill ~30~1~15 ~30~3~15 minecraft:stonebrick 0
setblock ~30~4~15 minecraft:double_stone_block_slab 0
fill ~30~5~15 ~30~9~15 minecraft:stonebrick 0
setblock ~31~2~15 minecraft:torch 1
setblock ~31~8~15 minecraft:torch 1
setblock ~32~4~15 minecraft:double_stone_block_slab 0
fill ~33~4~15 ~34~4~37 minecraft:stone 0
setblock ~34~21~15 minecraft:stone_block_slab 5
fill ~36~12~15 ~36~12~36 minecraft:planks 4
setblock ~37~4~15 minecraft:hay_block 0
setblock ~37~5~15 minecraft:hopper 5
setblock ~37~8~15 minecraft:torch 2
fill ~37~12~15 ~37~12~25 minecraft:stained_hardened_clay 15
setblock ~37~14~15 minecraft:wall_banner 4
setblock ~38~21~15 minecraft:stone_block_slab 5
fill ~40~1~15 ~40~1~16 minecraft:grass
setblock ~41~0~15 minecraft:gravel
setblock ~2~0~16 minecraft:gravel
fill ~3~0~16 ~4~0~18 minecraft:dirt 0
setblock ~3~1~16 minecraft:gravel
setblock ~4~19~16 minecraft:stone_brick_stairs 4
fill ~4~20~16 ~4~20~27 minecraft:stonebrick 0
setblock ~4~21~16 minecraft:stone_block_slab 5
fill ~5~0~16 ~5~0~18 minecraft:stonebrick 0
fill ~5~4~16 ~6~4~16 minecraft:stonebrick 0
fill ~5~5~16 ~5~19~16 minecraft:stonebrick 0
fill ~5~20~16 ~11~20~22 minecraft:cobblestone
fill ~6~3~16 ~8~3~17 minecraft:bedrock 0
fill ~6~5~16 ~6~7~17 minecraft:stained_hardened_clay 15
fill ~6~8~16 ~6~17~16 minecraft:stained_hardened_clay 15
fill ~6~18~16 ~11~19~16 minecraft:stonebrick 0
setblock ~6~21~16 minecraft:torch 3
setblock ~7~5~16 minecraft:stonebrick 0
setblock ~7~6~16 minecraft:redstone_wire 0
setblock ~7~7~16 minecraft:stonebrick 0
setblock ~7~8~16 minecraft:acacia_stairs 2
fill ~7~12~16 ~7~16~16 minecraft:stonebrick 0
fill ~7~17~16 ~10~17~16 minecraft:stained_hardened_clay 15
fill ~8~4~16 ~8~4~17 minecraft:stone 0
setblock ~8~5~16 minecraft:redstone_wire 0
setblock ~8~6~16 minecraft:stonebrick 0
setblock ~8~7~16 minecraft:redstone_torch 5
setblock ~8~8~16 minecraft:stonebrick 0
setblock ~8~9~16 minecraft:unlit_redstone_torch 5
setblock ~8~10~16 minecraft:stonebrick 0
setblock ~8~11~16 minecraft:redstone_wire 0
fill ~8~12~16 ~8~12~17 minecraft:stone_block_slab 13
setblock ~8~13~16 minecraft:spruce_door 1
setblock ~8~15~16 minecraft:stone_brick_stairs 7
fill ~8~16~16 ~9~16~16 minecraft:stonebrick 0
setblock ~8~21~16 minecraft:torch 3
setblock ~9~2~16 minecraft:stone 0
setblock ~9~3~16 minecraft:redstone_wire 15
setblock ~9~4~16 minecraft:redstone_torch 1
fill ~9~9~16 ~9~9~18 minecraft:stonebrick 0
fill ~9~10~16 ~9~10~17 minecraft:redstone_wire 0
setblock ~9~11~16 minecraft:double_stone_block_slab 5
fill ~9~12~16 ~9~12~17 minecraft:redstone_wire 0
fill ~9~13~16 ~9~15~16 minecraft:stonebrick 0
setblock ~10~0~16 minecraft:stone 0
setblock ~10~1~16 minecraft:redstone_wire 0
setblock ~10~2~16 minecraft:unlit_redstone_torch 1
fill ~10~4~16 ~10~5~16 minecraft:stone 0
fill ~10~8~16 ~10~16~16 minecraft:stained_hardened_clay 15
setblock ~10~21~16 minecraft:torch 3
setblock ~11~0~16 minecraft:dirt 0
fill ~11~1~16 ~11~17~16 minecraft:stonebrick 0
setblock ~12~2~16 minecraft:torch 1
setblock ~12~19~16 minecraft:stone_brick_stairs 5
fill ~12~20~16 ~12~20~27 minecraft:stonebrick 0
setblock ~12~21~16 minecraft:stone_block_slab 5
setblock ~13~4~16 minecraft:double_stone_block_slab 0
setblock ~14~4~16 minecraft:stone 0
setblock ~15~4~16 minecraft:double_stone_block_slab 0
setblock ~16~4~16 minecraft:stone 0
setblock ~20~4~16 minecraft:stone 0
setblock ~21~4~16 minecraft:double_stone_block_slab 0
setblock ~22~4~16 minecraft:stone 0
setblock ~23~4~16 minecraft:double_stone_block_slab 0
setblock ~24~4~16 minecraft:stone 0
setblock ~25~4~16 minecraft:double_stone_block_slab 0
setblock ~26~4~16 minecraft:stone 0
setblock ~27~4~16 minecraft:double_stone_block_slab 0
fill ~29~5~16 ~29~5~23 minecraft:leaves 2
fill ~30~0~16 ~30~0~18 minecraft:cobblestone
setblock ~30~4~16 minecraft:stone 0
fill ~30~5~16 ~30~5~18 minecraft:fence 4
setblock ~30~9~16 minecraft:stone_brick_stairs 7
setblock ~31~4~16 minecraft:double_stone_block_slab 0
setblock ~32~4~16 minecraft:stone 0
fill ~33~13~16 ~37~14~16 minecraft:planks 4
fill ~34~15~16 ~37~15~16 minecraft:planks 4
setblock ~34~21~16 minecraft:double_stone_block_slab 5
setblock ~34~22~16 minecraft:stone_block_slab 0
fill ~35~5~16 ~37~5~16 minecraft:fence 4
fill ~35~16~16 ~37~17~16 minecraft:planks 4
setblock ~35~21~16 minecraft:torch 1
setblock ~37~4~16 minecraft:double_stone_block_slab 0
setblock ~37~6~16 minecraft:fence 4
setblock ~37~21~16 minecraft:torch 2
setblock ~38~21~16 minecraft:double_stone_block_slab 5
setblock ~38~22~16 minecraft:stone_block_slab 0
setblock ~41~0~16 minecraft:grass
setblock ~2~0~17 minecraft:grass
setblock ~3~1~17 minecraft:grass
setblock ~4~21~17 minecraft:double_stone_block_slab 5
setblock ~4~22~17 minecraft:stone_block_slab 0
fill ~5~1~17 ~5~17~17 minecraft:stained_hardened_clay 15
fill ~5~18~17 ~5~19~26 minecraft:stonebrick 0
setblock ~5~21~17 minecraft:torch 1
setblock ~6~4~17 minecraft:stone 0
fill ~6~8~17 ~7~8~17 minecraft:stonebrick 0
fill ~6~9~17 ~6~9~18 minecraft:stonebrick 0
setblock ~6~10~17 minecraft:double_stone_block_slab 5
fill ~6~11~17 ~6~12~26 minecraft:stained_hardened_clay 15
setblock ~6~13~17 minecraft:grass
fill ~6~14~17 ~6~15~17 minecraft:leaves 1
fill ~6~18~17 ~10~18~17 minecraft:stained_hardened_clay 15
fill ~6~19~17 ~11~19~23 minecraft:stonebrick 0
fill ~7~5~17 ~11~7~17 minecraft:stained_hardened_clay 15
setblock ~7~9~17 minecraft:acacia_stairs 2
setblock ~7~13~17 minecraft:trapdoor 0
setblock ~7~15~17 minecraft:torch 3
fill ~8~8~17 ~9~8~17 minecraft:stained_hardened_clay 15
setblock ~8~9~17 minecraft:stonebrick 0
setblock ~9~4~17 minecraft:stone 0
setblock ~9~11~17 minecraft:stone_block_slab 13
setblock ~9~15~17 minecraft:torch 3
setblock ~10~0~17 minecraft:unpowered_repeater 2
setblock ~10~1~17 minecraft:stone 0
setblock ~10~2~17 minecraft:redstone_wire 0
setblock ~10~3~17 minecraft:torch 2
fill ~10~8~17 ~10~11~17 minecraft:stonebrick 0
fill ~10~12~17 ~11~12~17 minecraft:stained_hardened_clay 15
fill ~11~0~17 ~11~0~26 minecraft:stonebrick 0
fill ~11~1~17 ~11~4~17 minecraft:stained_hardened_clay 15
fill ~11~8~17 ~11~11~17 minecraft:stained_hardened_clay 15
fill ~11~13~17 ~11~17~17 minecraft:stained_hardened_clay 15
fill ~11~18~17 ~11~18~26 minecraft:stonebrick 0
setblock ~11~21~17 minecraft:torch 2
setblock ~12~21~17 minecraft:double_stone_block_slab 5
setblock ~12~22~17 minecraft:stone_block_slab 0
setblock ~13~4~17 minecraft:stone 0
setblock ~14~4~17 minecraft:double_stone_block_slab 0
setblock ~15~4~17 minecraft:stone 0
setblock ~16~4~17 minecraft:double_stone_block_slab 0
setblock ~20~4~17 minecraft:double_stone_block_slab 0
setblock ~20~5~17 minecraft:leaves 2
setblock ~21~4~17 minecraft:stone 0
setblock ~22~4~17 minecraft:double_stone_block_slab 0
setblock ~23~4~17 minecraft:stone 0
setblock ~24~4~17 minecraft:double_stone_block_slab 0
setblock ~25~4~17 minecraft:stone 0
setblock ~26~4~17 minecraft:double_stone_block_slab 0
setblock ~27~4~17 minecraft:stone 0
setblock ~30~4~17 minecraft:double_stone_block_slab 0
setblock ~31~4~17 minecraft:stone 0
setblock ~32~4~17 minecraft:double_stone_block_slab 0
setblock ~33~13~17 minecraft:crafting_table
fill ~33~14~17 ~33~14~23 minecraft:acacia_stairs 5
fill ~34~15~17 ~34~15~23 minecraft:acacia_stairs 5
fill ~34~21~17 ~34~21~18 minecraft:stone_block_slab 5
setblock ~35~16~17 minecraft:torch 1
setblock ~37~4~17 minecraft:hay_block 0
setblock ~37~5~17 minecraft:hopper 5
fill ~37~13~17 ~37~15~21 minecraft:bookshelf
fill ~38~21~17 ~38~21~18 minecraft:stone_block_slab 5
setblock ~40~1~17 minecraft:gravel
fill ~41~0~17 ~41~0~18 minecraft:gravel
fill ~0~0~18 ~1~0~24 minecraft:stonebrick 0
setblock ~0~1~18 minecraft:stone_brick_stairs 0
fill ~1~1~18 ~3~1~18 minecraft:stonebrick 0
setblock ~1~2~18 minecraft:stone_brick_stairs 0
fill ~2~0~18 ~2~0~24 minecraft:dirt 0
fill ~2~2~18 ~3~2~18 minecraft:stonebrick 0
setblock ~2~3~18 minecraft:stone_brick_stairs 0
setblock ~3~3~18 minecraft:stonebrick 0
setblock ~3~4~18 minecraft:stone_brick_stairs 0
fill ~4~4~18 ~5~4~18 minecraft:stonebrick 0
setblock ~4~5~18 minecraft:stone_brick_stairs 0
setblock ~4~8~18 minecraft:torch 2
setblock ~4~14~18 minecraft:torch 2
setblock ~4~19~18 minecraft:stone_brick_stairs 4
setblock ~4~21~18 minecraft:stone_block_slab 5
fill ~5~1~18 ~5~3~18 minecraft:stonebrick 0
fill ~5~5~18 ~5~10~18 minecraft:stonebrick 0
fill ~5~11~18 ~5~11~25 minecraft:stained_hardened_clay 15
fill ~5~12~18 ~5~12~24 minecraft:stonebrick 0
fill ~5~13~18 ~5~16~18 minecraft:stonebrick 0
fill ~5~17~18 ~5~17~25 minecraft:stained_hardened_clay 15
setblock ~6~1~18 minecraft:torch 1
fill ~6~3~18 ~7~3~26 minecraft:bedrock 0
fill ~6~4~18 ~7~4~18 minecraft:double_stone_block_slab 0
setblock ~6~7~18 minecraft:torch 3
fill ~6~8~18 ~7~8~18 minecraft:stone_brick_stairs 7
fill ~6~10~18 ~6~10~24 minecraft:stonebrick 0
setblock ~6~13~18 minecraft:trapdoor 2
setblock ~6~15~18 minecraft:torch 1
fill ~6~18~18 ~6~18~25 minecraft:stained_hardened_clay 15
setblock ~7~9~18 minecraft:stone_block_slab 13
setblock ~7~10~18 minecraft:acacia_stairs 2
fill ~7~18~18 ~9~18~24 minecraft:planks 4
fill ~8~0~18 ~8~0~24 minecraft:sticky_piston 1
fill ~8~1~18 ~8~1~24 minecraft:piston 1
fill ~8~2~18 ~8~3~24 minecraft:sand 0
fill ~8~4~18 ~8~4~24 minecraft:gravel
fill ~8~7~18 ~8~9~24 minecraft:fence 4
fill ~8~10~18 ~8~10~24 minecraft:log2 0
fill ~8~11~18 ~8~12~24 minecraft:piston 0
fill ~9~0~18 ~9~0~24 minecraft:unpowered_repeater 3
fill ~9~2~18 ~10~2~24 minecraft:stone 0
fill ~9~3~18 ~9~3~24 minecraft:unpowered_repeater 3
fill ~9~4~18 ~11~4~18 minecraft:double_stone_block_slab 0
fill ~9~8~18 ~10~8~18 minecraft:stone_brick_stairs 7
fill ~9~10~18 ~9~10~19 minecraft:red_sandstone 3
fill ~9~11~18 ~9~11~24 minecraft:redstone_wire 0
fill ~9~12~18 ~9~12~20 minecraft:stonebrick 0
fill ~9~13~18 ~9~13~24 minecraft:redstone_wire 0
fill ~10~0~18 ~10~0~24 minecraft:redstone_wire 0
fill ~10~3~18 ~10~3~24 minecraft:redstone_wire 0
fill ~10~9~18 ~11~10~18 minecraft:stonebrick 0
fill ~10~11~18 ~10~11~22 minecraft:stonebrick 0
fill ~10~12~18 ~10~12~26 minecraft:stained_hardened_clay 15
setblock ~10~15~18 minecraft:torch 2
fill ~10~18~18 ~10~18~24 minecraft:stained_hardened_clay 15
fill ~11~1~18 ~11~3~18 minecraft:stonebrick 0
fill ~11~5~18 ~11~8~18 minecraft:stonebrick 0
fill ~11~11~18 ~11~11~25 minecraft:stained_hardened_clay 15
fill ~11~12~18 ~11~12~24 minecraft:stonebrick 0
fill ~11~13~18 ~11~16~18 minecraft:stonebrick 0
fill ~11~17~18 ~11~17~25 minecraft:stained_hardened_clay 15
setblock ~12~8~18 minecraft:torch 1
setblock ~12~14~18 minecraft:torch 1
setblock ~12~19~18 minecraft:stone_brick_stairs 5
setblock ~12~21~18 minecraft:stone_block_slab 5
setblock ~13~4~18 minecraft:double_stone_block_slab 0
setblock ~14~4~18 minecraft:stone 0
setblock ~15~4~18 minecraft:double_stone_block_slab 0
fill ~16~4~18 ~16~4~24 minecraft:stone 0
setblock ~20~4~18 minecraft:stone 0
setblock ~21~4~18 minecraft:double_stone_block_slab 0
setblock ~22~4~18 minecraft:stone 0
setblock ~23~4~18 minecraft:double_stone_block_slab 0
setblock ~23~5~18 minecraft:stone_block_slab 0
setblock ~24~4~18 minecraft:stone 0
setblock ~25~4~18 minecraft:double_stone_block_slab 0
setblock ~25~5~18 minecraft:stone_block_slab 0
setblock ~26~4~18 minecraft:stone 0
setblock ~27~4~18 minecraft:double_stone_block_slab 0
fill ~29~6~18 ~29~6~20 minecraft:leaves 2
setblock ~30~4~18 minecraft:stone 0
setblock ~30~9~18 minecraft:stone_brick_stairs 6
setblock ~31~4~18 minecraft:double_stone_block_slab 0
setblock ~32~4~18 minecraft:stone 0
fill ~33~13~18 ~33~13~19 minecraft:trapped_chest 5
fill ~35~5~18 ~37~5~18 minecraft:fence 4
setblock ~37~4~18 minecraft:double_stone_block_slab 0
setblock ~37~6~18 minecraft:fence 4
setblock ~40~1~18 minecraft:grass
fill ~1~1~19 ~1~1~23 minecraft:stone_brick_stairs 0
fill ~2~1~19 ~3~1~24 minecraft:stonebrick 0
fill ~2~2~19 ~2~2~23 minecraft:stone_brick_stairs 0
fill ~3~0~19 ~3~0~40 minecraft:dirt 0
fill ~3~2~19 ~3~2~24 minecraft:stonebrick 0
fill ~3~3~19 ~3~3~23 minecraft:stone_brick_stairs 0
fill ~4~0~19 ~4~0~23 minecraft:stonebrick 0
fill ~4~4~19 ~4~4~23 minecraft:stone_brick_stairs 0
setblock ~4~21~19 minecraft:double_stone_block_slab 5
setblock ~4~22~19 minecraft:stone_block_slab 0
fill ~5~3~19 ~5~3~23 minecraft:bedrock 0
fill ~5~4~19 ~5~4~23 minecraft:double_stone_block_slab 5
fill ~5~9~19 ~7~9~19 minecraft:stone_brick_stairs 7
fill ~5~10~19 ~5~10~24 minecraft:stonebrick 0
fill ~5~13~19 ~5~15~19 minecraft:stained_glass_pane 2
fill ~5~16~19 ~5~16~24 minecraft:stonebrick 0
fill ~6~4~19 ~6~4~23 minecraft:stone 0
setblock ~7~4~19 minecraft:double_stone_block_slab4 2
fill ~7~10~19 ~7~10~23 minecraft:stone_block_slab 5
setblock ~7~11~19 minecraft:acacia_stairs 2
fill ~9~4~19 ~9~4~23 minecraft:stone 0
fill ~9~9~19 ~11~9~19 minecraft:stone_brick_stairs 7
fill ~10~4~19 ~11~4~19 minecraft:double_stone_block_slab 0
fill ~10~10~19 ~11~10~19 minecraft:stonebrick 0
fill ~11~1~19 ~11~3~23 minecraft:stained_hardened_clay 15
fill ~11~13~19 ~11~15~19 minecraft:stained_glass_pane 2
fill ~11~16~19 ~11~16~24 minecraft:stonebrick 0
setblock ~12~21~19 minecraft:double_stone_block_slab 5
setblock ~12~22~19 minecraft:stone_block_slab 0
fill ~13~4~19 ~13~4~23 minecraft:stone 0
setblock ~14~4~19 minecraft:double_stone_block_slab 0
fill ~15~4~19 ~15~4~23 minecraft:stone 0
fill ~17~1~19 ~17~3~19 minecraft:stonebrick 0
setblock ~18~2~19 minecraft:torch 1
setblock ~20~4~19 minecraft:double_stone_block_slab 0
setblock ~20~5~19 minecraft:leaves 2
setblock ~21~4~19 minecraft:stone 0
setblock ~22~4~19 minecraft:double_stone_block_slab 0
setblock ~23~4~19 minecraft:stone 0
setblock ~24~4~19 minecraft:double_stone_block_slab 0
setblock ~25~4~19 minecraft:stone 0
setblock ~26~4~19 minecraft:double_stone_block_slab 0
setblock ~27~4~19 minecraft:stone 0
setblock ~29~2~19 minecraft:torch 2
setblock ~29~7~19 minecraft:leaves 2
setblock ~29~8~19 minecraft:torch 2
fill ~30~0~19 ~30~0~23 minecraft:dirt 0
fill ~30~1~19 ~30~3~19 minecraft:stonebrick 0
setblock ~30~4~19 minecraft:double_stone_block_slab 0
fill ~30~5~19 ~30~9~19 minecraft:stonebrick 0
setblock ~31~2~19 minecraft:torch 1
setblock ~31~4~19 minecraft:stone 0
setblock ~31~8~19 minecraft:torch 1
setblock ~32~4~19 minecraft:double_stone_block_slab 0
setblock ~34~21~19 minecraft:double_stone_block_slab 5
setblock ~34~22~19 minecraft:stone_block_slab 0
setblock ~35~21~19 minecraft:torch 1
setblock ~37~4~19 minecraft:hay_block 0
setblock ~37~5~19 minecraft:hopper 5
setblock ~37~8~19 minecraft:torch 2
setblock ~37~21~19 minecraft:torch 2
setblock ~38~21~19 minecraft:stonebrick 0
setblock ~38~22~19 minecraft:stone_block_slab 0
setblock ~40~1~19 minecraft:gravel
setblock ~41~0~19 minecraft:grass
setblock ~4~14~20 minecraft:torch 2
setblock ~4~19~20 minecraft:stone_brick_stairs 4
setblock ~4~21~20 minecraft:stone_block_slab 5
fill ~5~13~20 ~5~15~20 minecraft:stonebrick 0
setblock ~6~15~20 minecraft:torch 1
fill ~7~4~20 ~7~4~23 minecraft:stone 0
setblock ~7~12~20 minecraft:acacia_stairs 2
fill ~9~10~20 ~9~10~22 minecraft:double_stone_block_slab 5
fill ~10~4~20 ~12~4~22 minecraft:stone 0
fill ~10~10~20 ~10~10~23 minecraft:stonebrick 0
setblock ~10~13~20 minecraft:chest 4
setblock ~10~15~20 minecraft:torch 2
setblock ~11~10~20 minecraft:double_stone_block_slab 5
fill ~11~13~20 ~11~15~20 minecraft:stonebrick 0
setblock ~12~14~20 minecraft:torch 1
setblock ~12~19~20 minecraft:stone_brick_stairs 5
setblock ~12~21~20 minecraft:stone_block_slab 5
fill ~14~4~20 ~14~4~22 minecraft:stone 0
setblock ~17~2~20 minecraft:torch 3
setblock ~20~4~20 minecraft:stone 0
setblock ~21~4~20 minecraft:double_stone_block_slab 0
setblock ~22~4~20 minecraft:stone 0
setblock ~22~5~20 minecraft:stone_block_slab 0
setblock ~23~4~20 minecraft:double_stone_block_slab 0
setblock ~24~4~20 minecraft:stone 0
setblock ~24~5~20 minecraft:campfire 1
setblock ~25~4~20 minecraft:double_stone_block_slab 0
setblock ~26~4~20 minecraft:stone 0
setblock ~26~5~20 minecraft:stone_block_slab 0
setblock ~27~4~20 minecraft:double_stone_block_slab 0
fill ~30~1~20 ~30~3~23 minecraft:stained_hardened_clay 15
setblock ~30~4~20 minecraft:stone 0
fill ~30~5~20 ~30~5~22 minecraft:fence 4
setblock ~30~9~20 minecraft:stone_brick_stairs 7
setblock ~31~4~20 minecraft:double_stone_block_slab 0
setblock ~32~4~20 minecraft:stone 0
setblock ~33~13~20 minecraft:crafting_table
setblock ~34~21~20 minecraft:stone_block_slab 5
fill ~35~5~20 ~37~5~20 minecraft:fence 4
setblock ~37~4~20 minecraft:double_stone_block_slab 0
setblock ~37~6~20 minecraft:fence 4
setblock ~38~21~20 minecraft:stone_block_slab 5
setblock ~40~1~20 minecraft:grass
setblock ~41~0~20 minecraft:gravel
setblock ~4~21~21 minecraft:double_stone_block_slab 5
setblock ~4~22~21 minecraft:stone_block_slab 0
setblock ~5~1~21 minecraft:torch 1
fill ~5~13~21 ~5~15~21 minecraft:stained_glass_pane 2
setblock ~5~21~21 minecraft:torch 1
setblock ~7~12~21 minecraft:stone_block_slab 13
setblock ~8~15~21 minecraft:bell 2
fill ~8~16~21 ~8~17~21 minecraft:chain 0
setblock ~9~12~21 minecraft:double_stone_block_slab 5
setblock ~10~9~21 minecraft:bell 1
setblock ~10~13~21 minecraft:crafting_table
fill ~11~10~21 ~11~10~24 minecraft:stonebrick 0
fill ~11~13~21 ~11~15~21 minecraft:stained_glass_pane 2
setblock ~11~21~21 minecraft:torch 2
setblock ~12~2~21 minecraft:torch 1
setblock ~12~21~21 minecraft:double_stone_block_slab 5
setblock ~12~22~21 minecraft:stone_block_slab 0
setblock ~20~4~21 minecraft:double_stone_block_slab 0
setblock ~20~5~21 minecraft:leaves 2
setblock ~21~4~21 minecraft:stone 0
setblock ~22~4~21 minecraft:double_stone_block_slab 0
setblock ~23~4~21 minecraft:stone 0
setblock ~24~4~21 minecraft:double_stone_block_slab 0
setblock ~25~4~21 minecraft:stone 0
setblock ~26~4~21 minecraft:double_stone_block_slab 0
setblock ~27~4~21 minecraft:stone 0
setblock ~30~4~21 minecraft:double_stone_block_slab 0
setblock ~31~4~21 minecraft:stone 0
setblock ~32~4~21 minecraft:double_stone_block_slab 0
fill ~33~13~21 ~33~13~22 minecraft:trapped_chest 5
setblock ~34~21~21 minecraft:double_stone_block_slab 5
setblock ~34~22~21 minecraft:stone_block_slab 0
setblock ~37~4~21 minecraft:hay_block 0
setblock ~37~5~21 minecraft:hopper 5
setblock ~38~21~21 minecraft:stonebrick 0
setblock ~38~22~21 minecraft:stone_block_slab 0
setblock ~40~1~21 minecraft:gravel
fill ~41~0~21 ~42~0~21 minecraft:grass
setblock ~4~14~22 minecraft:torch 2
setblock ~4~19~22 minecraft:stone_brick_stairs 4
setblock ~4~21~22 minecraft:stone_block_slab 5
fill ~5~13~22 ~5~15~22 minecraft:stonebrick 0
setblock ~6~15~22 minecraft:torch 1
setblock ~7~12~22 minecraft:acacia_stairs 3
fill ~9~12~22 ~9~12~24 minecraft:stonebrick 0
setblock ~10~13~22 minecraft:anvil 0
setblock ~10~15~22 minecraft:torch 2
fill ~11~13~22 ~11~15~22 minecraft:stonebrick 0
setblock ~12~14~22 minecraft:torch 1
setblock ~12~19~22 minecraft:stone_brick_stairs 5
setblock ~12~21~22 minecraft:stone_block_slab 5
setblock ~20~4~22 minecraft:stone 0
setblock ~21~4~22 minecraft:double_stone_block_slab 0
setblock ~22~4~22 minecraft:stone 0
setblock ~23~4~22 minecraft:double_stone_block_slab 0
setblock ~23~5~22 minecraft:stone_block_slab 0
setblock ~24~4~22 minecraft:stone 0
fill ~25~4~22 ~25~4~23 minecraft:double_stone_block_slab 0
setblock ~25~5~22 minecraft:stone_block_slab 0
setblock ~26~4~22 minecraft:stone 0
fill ~27~4~22 ~27~4~23 minecraft:double_stone_block_slab 0
fill ~29~6~22 ~29~6~23 minecraft:leaves 2
setblock ~30~4~22 minecraft:stone 0
setblock ~30~9~22 minecraft:stone_brick_stairs 6
setblock ~31~4~22 minecraft:double_stone_block_slab 0
setblock ~32~4~22 minecraft:stone 0
setblock ~34~21~22 minecraft:stone_block_slab 5
setblock ~35~4~22 minecraft:double_stone_block_slab 0
fill ~35~5~22 ~37~5~22 minecraft:fence 4
setblock ~36~4~22 minecraft:stone 0
setblock ~37~4~22 minecraft:double_stone_block_slab 0
setblock ~37~6~22 minecraft:fence 4
setblock ~37~15~22 minecraft:torch 2
setblock ~38~21~22 minecraft:stone_block_slab 5
fill ~40~1~22 ~41~1~22 minecraft:grass
fill ~41~0~22 ~41~0~40 minecraft:dirt 0
setblock ~42~0~22 minecraft:gravel
setblock ~4~21~23 minecraft:double_stone_block_slab 5
setblock ~4~22~23 minecraft:stone_block_slab 0
fill ~5~9~23 ~7~9~23 minecraft:stone_brick_stairs 6
fill ~5~13~23 ~5~15~23 minecraft:stained_glass_pane 2
fill ~5~20~23 ~9~20~24 minecraft:cobblestone
setblock ~7~11~23 minecraft:acacia_stairs 3
setblock ~7~21~23 minecraft:chest 5
fill ~9~9~23 ~11~9~23 minecraft:stone_brick_stairs 6
fill ~9~10~23 ~9~10~24 minecraft:red_sandstone 3
fill ~10~4~23 ~12~4~24 minecraft:double_stone_block_slab 0
setblock ~10~20~23 minecraft:acacia_stairs 3
fill ~11~13~23 ~11~15~23 minecraft:stained_glass_pane 2
fill ~11~20~23 ~11~20~26 minecraft:cobblestone
setblock ~12~21~23 minecraft:double_stone_block_slab 5
setblock ~12~22~23 minecraft:stone_block_slab 0
setblock ~14~4~23 minecraft:double_stone_block_slab 0
setblock ~20~4~23 minecraft:double_stone_block_slab 0
setblock ~20~5~23 minecraft:leaves 2
setblock ~21~4~23 minecraft:stone 0
setblock ~22~4~23 minecraft:double_stone_block_slab 0
setblock ~23~4~23 minecraft:stone 0
fill ~24~4~23 ~24~4~25 minecraft:double_stone_block_slab 0
fill ~24~28~23 ~40~28~23 minecraft:stonebrick 0
setblock ~24~29~23 minecraft:stonebrick 0
setblock ~24~30~23 minecraft:stone_block_slab 0
setblock ~25~2~23 minecraft:torch 4
setblock ~25~27~23 minecraft:stone_brick_stairs 6
setblock ~25~29~23 minecraft:stone_block_slab 5
setblock ~26~4~23 minecraft:double_stone_block_slab 0
setblock ~26~29~23 minecraft:stonebrick 0
setblock ~26~30~23 minecraft:stone_block_slab 0
setblock ~27~22~23 minecraft:torch 4
setblock ~27~27~23 minecraft:stone_brick_stairs 6
setblock ~27~29~23 minecraft:stone_block_slab 5
setblock ~28~5~23 minecraft:chest 2
setblock ~28~29~23 minecraft:stonebrick 0
setblock ~28~30~23 minecraft:stone_block_slab 0
fill ~29~4~23 ~30~4~23 minecraft:double_stone_block_slab 0
setblock ~29~7~23 minecraft:leaves 2
setblock ~29~8~23 minecraft:torch 2
setblock ~29~22~23 minecraft:torch 4
setblock ~29~27~23 minecraft:stone_brick_stairs 6
setblock ~29~29~23 minecraft:stone_block_slab 5
setblock ~30~5~23 minecraft:double_stone_block_slab 5
fill ~30~6~23 ~30~9~24 minecraft:stonebrick 0
setblock ~30~12~23 minecraft:stonebrick 0
setblock ~30~13~23 minecraft:stone_brick_stairs 0
setblock ~30~29~23 minecraft:stonebrick 0
setblock ~30~30~23 minecraft:stone_block_slab 0
fill ~31~4~23 ~31~4~37 minecraft:stone 0
setblock ~31~5~23 minecraft:cauldron 6
setblock ~31~8~23 minecraft:torch 1
fill ~31~12~23 ~31~12~25 minecraft:stained_hardened_clay 15
setblock ~31~13~23 minecraft:stonebrick 0
setblock ~31~14~23 minecraft:stone_brick_stairs 0
setblock ~31~22~23 minecraft:torch 4
setblock ~31~27~23 minecraft:stone_brick_stairs 6
setblock ~31~29~23 minecraft:stone_block_slab 5
setblock ~32~4~23 minecraft:double_stone_block_slab 0
setblock ~32~5~23 minecraft:chest 2
setblock ~32~14~23 minecraft:stonebrick 0
setblock ~32~15~23 minecraft:stone_brick_stairs 0
setblock ~32~29~23 minecraft:stonebrick 0
setblock ~32~30~23 minecraft:stone_block_slab 0
setblock ~33~6~23 minecraft:torch 4
setblock ~33~13~23 minecraft:crafting_table
setblock ~33~15~23 minecraft:stonebrick 0
setblock ~33~16~23 minecraft:stone_brick_stairs 0
setblock ~33~22~23 minecraft:torch 4
setblock ~33~27~23 minecraft:stone_brick_stairs 6
setblock ~33~29~23 minecraft:stone_block_slab 5
fill ~34~17~23 ~34~19~23 minecraft:stonebrick 0
setblock ~34~21~23 minecraft:stonebrick 0
setblock ~34~22~23 minecraft:stone_block_slab 0
setblock ~34~29~23 minecraft:stonebrick 0
setblock ~34~30~23 minecraft:stone_block_slab 0
fill ~35~4~23 ~35~4~37 minecraft:stone 0
setblock ~35~6~23 minecraft:torch 4
setblock ~35~16~23 minecraft:torch 1
setblock ~35~22~23 minecraft:torch 4
fill ~35~24~23 ~37~24~23 minecraft:stone_stairs 2
setblock ~35~27~23 minecraft:stone_brick_stairs 6
setblock ~35~29~23 minecraft:stone_block_slab 5
setblock ~36~4~23 minecraft:double_stone_block_slab 0
setblock ~36~29~23 minecraft:stonebrick 0
setblock ~36~30~23 minecraft:stone_block_slab 0
setblock ~37~2~23 minecraft:torch 2
fill ~37~4~23 ~37~4~37 minecraft:stone 0
setblock ~37~22~23 minecraft:torch 4
setblock ~37~27~23 minecraft:stone_brick_stairs 6
setblock ~37~29~23 minecraft:stone_block_slab 5
fill ~38~1~23 ~38~19~23 minecraft:stonebrick 0
setblock ~38~21~23 minecraft:stonebrick 0
setblock ~38~22~23 minecraft:stone_block_slab 0
setblock ~38~29~23 minecraft:stonebrick 0
setblock ~38~30~23 minecraft:stone_block_slab 0
fill ~39~4~23 ~40~4~23 minecraft:stone_brick_stairs 2
setblock ~39~27~23 minecraft:stone_brick_stairs 6
setblock ~39~29~23 minecraft:stone_block_slab 5
fill ~40~1~23 ~40~3~39 minecraft:stonebrick 0
setblock ~40~29~23 minecraft:stonebrick 0
setblock ~40~30~23 minecraft:stone_block_slab 0
fill ~41~1~23 ~41~1~24 minecraft:gravel
fill ~42~0~23 ~42~0~24 minecraft:grass
setblock ~0~1~24 minecraft:stone_brick_stairs 0
setblock ~1~1~24 minecraft:stonebrick 0
setblock ~1~2~24 minecraft:stone_brick_stairs 0
setblock ~2~2~24 minecraft:stonebrick 0
setblock ~2~3~24 minecraft:stone_brick_stairs 0
setblock ~3~3~24 minecraft:stonebrick 0
setblock ~3~4~24 minecraft:stone_brick_stairs 0
fill ~4~0~24 ~4~0~40 minecraft:dirt 0
fill ~4~4~24 ~5~4~24 minecraft:stonebrick 0
setblock ~4~5~24 minecraft:stone_brick_stairs 0
setblock ~4~8~24 minecraft:torch 2
setblock ~4~14~24 minecraft:torch 2
setblock ~4~19~24 minecraft:stone_brick_stairs 4
setblock ~4~21~24 minecraft:stone_block_slab 5
fill ~5~0~24 ~5~0~26 minecraft:stonebrick 0
fill ~5~1~24 ~5~3~24 minecraft:stonebrick 0
fill ~5~5~24 ~5~9~24 minecraft:stonebrick 0
fill ~5~13~24 ~5~15~24 minecraft:stonebrick 0
setblock ~6~1~24 minecraft:torch 1
fill ~6~4~24 ~7~4~24 minecraft:double_stone_block_slab 0
setblock ~6~7~24 minecraft:torch 4
fill ~6~8~24 ~7~8~24 minecraft:stone_brick_stairs 6
fill ~6~9~24 ~6~9~25 minecraft:stonebrick 0
setblock ~6~13~24 minecraft:acacia_stairs 2
setblock ~6~15~24 minecraft:torch 1
fill ~6~19~24 ~6~19~26 minecraft:stonebrick 0
setblock ~7~9~24 minecraft:double_stone_block_slab 5
setblock ~7~10~24 minecraft:acacia_stairs 3
fill ~7~19~24 ~9~19~24 minecraft:planks 4
setblock ~9~4~24 minecraft:double_stone_block_slab 0
fill ~9~8~24 ~10~8~24 minecraft:stone_brick_stairs 6
fill ~9~9~24 ~11~9~24 minecraft:stonebrick 0
setblock ~10~7~24 minecraft:torch 4
fill ~10~11~24 ~10~11~26 minecraft:stained_hardened_clay 15
setblock ~10~15~24 minecraft:torch 2
setblock ~10~19~24 minecraft:acacia_stairs 3
fill ~11~1~24 ~11~3~24 minecraft:stonebrick 0
fill ~11~5~24 ~11~8~24 minecraft:stonebrick 0
fill ~11~13~24 ~11~15~24 minecraft:stonebrick 0
fill ~11~19~24 ~11~19~26 minecraft:stonebrick 0
setblock ~12~8~24 minecraft:torch 1
setblock ~12~14~24 minecraft:torch 1
setblock ~12~19~24 minecraft:stone_brick_stairs 5
setblock ~12~21~24 minecraft:stone_block_slab 5
setblock ~13~4~24 minecraft:double_stone_block_slab 0
setblock ~14~4~24 minecraft:stone 0
setblock ~15~4~24 minecraft:double_stone_block_slab 0
setblock ~20~4~24 minecraft:stone 0
setblock ~21~4~24 minecraft:double_stone_block_slab 0
setblock ~22~4~24 minecraft:stone 0
setblock ~23~4~24 minecraft:double_stone_block_slab 0
setblock ~24~2~24 minecraft:torch 2
setblock ~24~27~24 minecraft:stone_brick_stairs 4
fill ~24~28~24 ~24~28~33 minecraft:stonebrick 0
setblock ~24~29~24 minecraft:stone_block_slab 5
fill ~25~0~24 ~29~0~24 minecraft:dirt 0
fill ~25~1~24 ~25~27~24 minecraft:stonebrick 0
fill ~25~28~24 ~39~28~25 minecraft:cobblestone
fill ~26~1~24 ~29~19~24 minecraft:stained_hardened_clay 15
fill ~26~20~24 ~26~25~24 minecraft:stained_hardened_clay 15
fill ~26~26~24 ~39~27~24 minecraft:stonebrick 0
setblock ~26~29~24 minecraft:torch 3
fill ~27~20~24 ~29~20~24 minecraft:stonebrick 0
fill ~27~21~24 ~27~24~24 minecraft:stonebrick 0
fill ~27~25~24 ~38~25~24 minecraft:stained_hardened_clay 15
fill ~28~21~24 ~28~23~24 minecraft:stained_glass_pane 2
fill ~28~24~24 ~29~24~24 minecraft:stonebrick 0
fill ~29~21~24 ~29~23~24 minecraft:stonebrick 0
fill ~30~0~24 ~30~3~24 minecraft:stonebrick 0
fill ~30~4~24 ~30~4~37 minecraft:stone 0
setblock ~30~5~24 minecraft:stonebrick 0
fill ~30~11~24 ~30~24~24 minecraft:stained_hardened_clay 15
setblock ~31~2~24 minecraft:torch 1
fill ~31~5~24 ~32~10~24 minecraft:stained_hardened_clay 15
fill ~31~13~24 ~32~19~24 minecraft:stained_hardened_clay 15
fill ~31~20~24 ~33~20~24 minecraft:stonebrick 0
fill ~31~21~24 ~31~24~24 minecraft:stonebrick 0
fill ~32~4~24 ~32~4~37 minecraft:stone 0
fill ~32~12~24 ~32~12~25 minecraft:stained_hardened_clay 15
fill ~32~21~24 ~32~23~24 minecraft:stained_glass_pane 2
fill ~32~24~24 ~33~24~24 minecraft:stonebrick 0
fill ~33~5~24 ~33~7~24 minecraft:stonebrick 0
fill ~33~8~24 ~38~10~24 minecraft:stained_hardened_clay 15
fill ~33~14~24 ~33~19~24 minecraft:stained_hardened_clay 15
fill ~33~21~24 ~33~23~24 minecraft:stonebrick 0
setblock ~34~5~24 minecraft:spruce_door 1
fill ~34~7~24 ~35~7~24 minecraft:stonebrick 0
fill ~34~13~24 ~34~17~24 minecraft:log 1
fill ~34~18~24 ~34~19~25 minecraft:stained_hardened_clay 15
fill ~34~20~24 ~34~24~24 minecraft:stained_hardened_clay 15
fill ~35~5~24 ~35~6~24 minecraft:stonebrick 0
fill ~35~13~24 ~36~13~24 minecraft:iron_door 3
fill ~35~15~24 ~36~15~24 minecraft:log 1
fill ~35~16~24 ~36~17~24 minecraft:planks 4
fill ~35~19~24 ~38~19~25 minecraft:stained_hardened_clay 15
fill ~35~20~24 ~37~20~24 minecraft:stonebrick 0
fill ~35~21~24 ~35~24~24 minecraft:stonebrick 0
fill ~36~4~24 ~36~4~37 minecraft:stone 0
fill ~36~5~24 ~38~7~24 minecraft:stained_hardened_clay 15
setblock ~36~21~24 minecraft:spruce_door 1
fill ~36~23~24 ~37~24~24 minecraft:stonebrick 0
fill ~37~13~24 ~37~17~24 minecraft:log 1
fill ~37~21~24 ~37~22~24 minecraft:stonebrick 0
fill ~38~0~24 ~38~0~37 minecraft:cobblestone
fill ~38~4~24 ~38~4~37 minecraft:stone 0
fill ~38~11~24 ~38~11~37 minecraft:cobblestone
fill ~38~12~24 ~38~12~38 minecraft:stained_hardened_clay 15
fill ~38~13~24 ~38~18~24 minecraft:stained_hardened_clay 15
fill ~38~20~24 ~38~24~24 minecraft:stained_hardened_clay 15
setblock ~38~29~24 minecraft:torch 3
fill ~39~4~24 ~39~25~24 minecraft:stonebrick 0
fill ~40~4~24 ~40~4~39 minecraft:stone_brick_stairs 1
setblock ~40~27~24 minecraft:stone_brick_stairs 5
fill ~40~28~24 ~40~28~39 minecraft:stonebrick 0
setblock ~40~29~24 minecraft:stone_block_slab 5
setblock ~2~0~25 minecraft:grass
fill ~3~1~25 ~3~1~28 minecraft:gravel
fill ~4~4~25 ~4~4~26 minecraft:stone_brick_stairs 0
setblock ~4~21~25 minecraft:double_stone_block_slab 5
setblock ~4~22~25 minecraft:stone_block_slab 0
fill ~5~1~25 ~5~10~25 minecraft:stained_hardened_clay 15
fill ~5~12~25 ~5~16~25 minecraft:stained_hardened_clay 15
fill ~5~20~25 ~8~20~26 minecraft:cobblestone
setblock ~5~21~25 minecraft:torch 1
fill ~6~4~25 ~10~4~26 minecraft:stone 0
fill ~6~5~25 ~11~7~25 minecraft:stained_hardened_clay 15
setblock ~6~8~25 minecraft:stonebrick 0
setblock ~6~10~25 minecraft:double_stone_block_slab 5
setblock ~6~14~25 minecraft:acacia_stairs 2
setblock ~7~8~25 minecraft:double_stone_block_slab 5
setblock ~7~9~25 minecraft:acacia_stairs 3
setblock ~7~15~25 minecraft:acacia_stairs 0
setblock ~7~19~25 minecraft:stained_hardened_clay 15
fill ~8~3~25 ~10~3~26 minecraft:bedrock 0
setblock ~8~8~25 minecraft:stained_hardened_clay 15
fill ~8~9~25 ~10~9~25 minecraft:stonebrick 0
setblock ~8~10~25 minecraft:double_stone_block_slab 5
fill ~8~11~25 ~9~11~26 minecraft:stained_hardened_clay 15
fill ~8~12~25 ~9~12~25 minecraft:stained_hardened_clay 15
setblock ~8~16~25 minecraft:acacia_stairs 0
fill ~9~8~25 ~10~8~25 minecraft:stonebrick 0
setblock ~9~15~25 minecraft:torch 4
setblock ~9~17~25 minecraft:acacia_stairs 0
setblock ~10~18~25 minecraft:acacia_stairs 0
fill ~11~1~25 ~11~4~25 minecraft:stained_hardened_clay 15
fill ~11~8~25 ~11~10~25 minecraft:stained_hardened_clay 15
fill ~11~12~25 ~11~16~25 minecraft:stained_hardened_clay 15
setblock ~11~21~25 minecraft:torch 2
fill ~12~4~25 ~12~4~27 minecraft:double_stone_block_slab 0
setblock ~12~21~25 minecraft:double_stone_block_slab 5
setblock ~12~22~25 minecraft:stone_block_slab 0
setblock ~13~4~25 minecraft:stone 0
setblock ~14~4~25 minecraft:double_stone_block_slab 0
setblock ~15~4~25 minecraft:stone 0
setblock ~16~4~25 minecraft:double_stone_block_slab 0
setblock ~20~4~25 minecraft:double_stone_block_slab 0
setblock ~20~5~25 minecraft:leaves 2
fill ~21~4~25 ~21~4~29 minecraft:stone 0
setblock ~22~4~25 minecraft:double_stone_block_slab 0
setblock ~22~5~25 minecraft:leaves 2
fill ~23~4~25 ~23~4~29 minecraft:stone 0
setblock ~24~5~25 minecraft:leaves 2
setblock ~24~29~25 minecraft:stonebrick 0
setblock ~24~30~25 minecraft:stone_block_slab 0
fill ~25~0~25 ~25~0~32 minecraft:dirt 0
fill ~25~1~25 ~25~3~31 minecraft:stained_hardened_clay 15
fill ~25~4~25 ~25~25~25 minecraft:stained_hardened_clay 15
fill ~25~26~25 ~25~27~38 minecraft:stonebrick 0
setblock ~25~29~25 minecraft:torch 1
fill ~26~0~25 ~30~0~37 minecraft:cobblestone
fill ~26~4~25 ~29~4~37 minecraft:stone 0
setblock ~26~5~25 minecraft:grass
fill ~26~6~25 ~26~7~25 minecraft:leaves 1
fill ~26~10~25 ~26~10~26 minecraft:planks 4
fill ~26~18~25 ~33~19~25 minecraft:stained_hardened_clay 15
setblock ~26~20~25 minecraft:grass
fill ~26~21~25 ~26~22~25 minecraft:leaves 1
fill ~26~26~25 ~38~27~25 minecraft:stained_hardened_clay 15
fill ~26~44~25 ~38~44~25 minecraft:stonebrick 0
setblock ~26~45~25 minecraft:stonebrick 0
setblock ~26~46~25 minecraft:stone_block_slab 0
setblock ~27~5~25 minecraft:trapdoor 0
fill ~27~6~25 ~30~6~25 minecraft:wall_banner 3
setblock ~27~8~25 minecraft:torch 3
setblock ~27~10~25 minecraft:acacia_stairs 1
setblock ~27~20~25 minecraft:trapdoor 1
setblock ~27~23~25 minecraft:torch 3
setblock ~27~43~25 minecraft:stone_brick_stairs 6
setblock ~27~45~25 minecraft:stone_block_slab 5
setblock ~28~5~25 minecraft:crafting_table
setblock ~28~9~25 minecraft:acacia_stairs 1
setblock ~28~45~25 minecraft:stonebrick 0
setblock ~28~46~25 minecraft:stone_block_slab 0
setblock ~29~8~25 minecraft:acacia_stairs 1
fill ~29~12~25 ~30~12~25 minecraft:stained_hardened_clay 15
fill ~29~13~25 ~33~15~25 minecraft:bookshelf
setblock ~29~23~25 minecraft:torch 3
setblock ~29~43~25 minecraft:stone_brick_stairs 6
setblock ~29~45~25 minecraft:stone_block_slab 5
setblock ~30~2~25 minecraft:torch 3
setblock ~30~5~25 minecraft:ender_chest 3
setblock ~30~7~25 minecraft:acacia_stairs 1
fill ~30~11~25 ~30~11~37 minecraft:cobblestone
setblock ~30~45~25 minecraft:stonebrick 0
setblock ~30~46~25 minecraft:stone_block_slab 0
setblock ~31~6~25 minecraft:acacia_stairs 1
setblock ~31~8~25 minecraft:torch 3
fill ~31~10~25 ~37~10~25 minecraft:stone_stairs 7
setblock ~31~23~25 minecraft:torch 3
setblock ~31~30~25 minecraft:torch 4
setblock ~31~38~25 minecraft:torch 4
setblock ~31~43~25 minecraft:stone_brick_stairs 6
setblock ~31~45~25 minecraft:stone_block_slab 5
setblock ~32~5~25 minecraft:acacia_stairs 1
setblock ~32~45~25 minecraft:stonebrick 0
setblock ~32~46~25 minecraft:stone_block_slab 0
setblock ~33~6~25 minecraft:torch 3
setblock ~33~23~25 minecraft:torch 3
setblock ~33~30~25 minecraft:torch 4
setblock ~33~38~25 minecraft:torch 4
setblock ~33~43~25 minecraft:stone_brick_stairs 6
setblock ~33~45~25 minecraft:stone_block_slab 5
setblock ~34~14~25 minecraft:stone_button 3
setblock ~34~45~25 minecraft:stonebrick 0
setblock ~34~46~25 minecraft:stone_block_slab 0
setblock ~35~6~25 minecraft:torch 3
fill ~35~20~25 ~37~20~25 minecraft:acacia_stairs 3
setblock ~35~23~25 minecraft:torch 3
setblock ~35~43~25 minecraft:stone_brick_stairs 6
setblock ~35~45~25 minecraft:stone_block_slab 5
setblock ~36~8~25 minecraft:torch 3
setblock ~36~45~25 minecraft:stonebrick 0
setblock ~36~46~25 minecraft:stone_block_slab 0
setblock ~37~5~25 minecraft:trapdoor 1
setblock ~37~13~25 minecraft:trapdoor 1
setblock ~37~23~25 minecraft:torch 3
setblock ~37~43~25 minecraft:stone_brick_stairs 6
setblock ~37~45~25 minecraft:stone_block_slab 5
setblock ~38~5~25 minecraft:grass
fill ~38~6~25 ~38~7~25 minecraft:leaves 1
setblock ~38~8~25 minecraft:torch 2
fill ~38~10~25 ~38~10~36 minecraft:stone_stairs 4
setblock ~38~13~25 minecraft:grass
fill ~38~14~25 ~38~15~25 minecraft:leaves 1
fill ~38~18~25 ~39~18~37 minecraft:stained_hardened_clay 15
setblock ~38~20~25 minecraft:grass
fill ~38~21~25 ~38~22~25 minecraft:leaves 1
setblock ~38~45~25 minecraft:stonebrick 0
setblock ~38~46~25 minecraft:stone_block_slab 0
fill ~39~1~25 ~39~11~37 minecraft:stained_hardened_clay 15
fill ~39~12~25 ~39~17~25 minecraft:stained_hardened_clay 15
fill ~39~19~25 ~39~19~37 minecraft:stained_hardened_clay 15
fill ~39~20~25 ~39~25~25 minecraft:stained_hardened_clay 15
fill ~39~26~25 ~39~27~38 minecraft:stonebrick 0
setblock ~39~29~25 minecraft:torch 2
setblock ~40~29~25 minecraft:stonebrick 0
setblock ~40~30~25 minecraft:stone_block_slab 0
fill ~41~1~25 ~41~1~27 minecraft:grass
fill ~42~0~25 ~42~0~26 minecraft:gravel
setblock ~2~0~26 minecraft:gravel
setblock ~4~19~26 minecraft:stone_brick_stairs 4
setblock ~4~21~26 minecraft:stone_block_slab 5
fill ~5~1~26 ~5~3~32 minecraft:stonebrick 0
fill ~5~4~26 ~5~17~26 minecraft:stonebrick 0
fill ~6~5~26 ~6~10~26 minecraft:stained_hardened_clay 15
fill ~6~13~26 ~6~17~26 minecraft:stained_hardened_clay 15
fill ~6~18~26 ~10~18~26 minecraft:stonebrick 0
setblock ~6~21~26 minecraft:torch 4
setblock ~7~5~26 minecraft:stonebrick 0
fill ~7~6~26 ~7~7~26 minecraft:double_stone_block_slab 5
setblock ~7~8~26 minecraft:acacia_stairs 3
setblock ~7~11~26 minecraft:torch 2
fill ~7~12~26 ~9~12~26 minecraft:stonebrick 0
fill ~7~13~26 ~7~16~26 minecraft:stonebrick 0
fill ~7~17~26 ~10~17~26 minecraft:stained_hardened_clay 15
fill ~7~19~26 ~10~19~26 minecraft:stonebrick 0
setblock ~8~5~26 minecraft:stained_hardened_clay 15
fill ~8~6~26 ~9~10~26 minecraft:stonebrick 0
setblock ~8~13~26 minecraft:spruce_door 3
setblock ~8~15~26 minecraft:stone_brick_stairs 6
fill ~8~16~26 ~9~16~26 minecraft:stonebrick 0
setblock ~9~5~26 minecraft:stonebrick 0
fill ~9~13~26 ~9~15~26 minecraft:stonebrick 0
fill ~9~20~26 ~10~20~26 minecraft:cobblestone
setblock ~10~1~26 minecraft:torch 2
fill ~10~5~26 ~10~10~26 minecraft:stained_hardened_clay 15
fill ~10~13~26 ~10~16~26 minecraft:stained_hardened_clay 15
setblock ~10~21~26 minecraft:torch 4
fill ~11~1~26 ~11~17~26 minecraft:stonebrick 0
setblock ~12~2~26 minecraft:torch 1
setblock ~12~19~26 minecraft:stone_brick_stairs 5
setblock ~12~21~26 minecraft:stone_block_slab 5
setblock ~13~4~26 minecraft:double_stone_block_slab 0
setblock ~14~4~26 minecraft:stone 0
setblock ~15~4~26 minecraft:double_stone_block_slab 0
setblock ~16~4~26 minecraft:stone 0
fill ~20~4~26 ~20~4~28 minecraft:stone 0
fill ~22~4~26 ~22~4~28 minecraft:stone 0
fill ~24~4~26 ~24~4~28 minecraft:stone 0
setblock ~24~6~26 minecraft:torch 2
fill ~24~8~26 ~24~8~28 minecraft:stone_stairs 0
setblock ~24~14~26 minecraft:torch 2
setblock ~24~22~26 minecraft:torch 2
setblock ~24~27~26 minecraft:stone_brick_stairs 4
setblock ~24~29~26 minecraft:stone_block_slab 5
fill ~25~4~26 ~25~4~28 minecraft:stonebrick 0
fill ~25~5~26 ~25~8~26 minecraft:stonebrick 0
fill ~25~9~26 ~25~9~37 minecraft:stained_hardened_clay 15
fill ~25~10~26 ~25~11~32 minecraft:stained_hardened_clay 15
fill ~25~12~26 ~25~12~28 minecraft:stonebrick 0
fill ~25~13~26 ~25~16~26 minecraft:stonebrick 0
fill ~25~17~26 ~25~19~37 minecraft:stained_hardened_clay 15
fill ~25~20~26 ~25~20~28 minecraft:stonebrick 0
fill ~25~21~26 ~25~24~26 minecraft:stonebrick 0
fill ~25~25~26 ~25~25~37 minecraft:stained_hardened_clay 15
fill ~25~28~26 ~26~28~38 minecraft:cobblestone
setblock ~26~5~26 minecraft:trapdoor 2
setblock ~26~8~26 minecraft:torch 1
setblock ~26~15~26 minecraft:torch 1
fill ~26~18~26 ~35~18~26 minecraft:planks 4
setblock ~26~20~26 minecraft:trapdoor 2
setblock ~26~23~26 minecraft:torch 1
fill ~26~26~26 ~26~27~37 minecraft:stained_hardened_clay 15
setblock ~26~43~26 minecraft:stone_brick_stairs 4
fill ~26~44~26 ~26~44~37 minecraft:stonebrick 0
setblock ~26~45~26 minecraft:stone_block_slab 5
setblock ~27~10~26 minecraft:acacia_stairs 2
fill ~27~26~26 ~37~26~31 minecraft:planks 4
fill ~27~27~26 ~37~27~28 minecraft:planks 4
fill ~27~28~26 ~27~43~26 minecraft:stonebrick 0
fill ~27~44~26 ~37~44~29 minecraft:cobblestone
setblock ~28~9~26 minecraft:acacia_stairs 2
setblock ~28~19~26 minecraft:acacia_stairs 0
fill ~28~28~26 ~30~28~27 minecraft:stained_hardened_clay 15
fill ~28~29~26 ~30~41~26 minecraft:stained_hardened_clay 15
fill ~28~42~26 ~37~43~26 minecraft:stonebrick 0
setblock ~28~45~26 minecraft:torch 3
setblock ~29~8~26 minecraft:acacia_stairs 2
setblock ~29~11~26 minecraft:torch 4
fill ~29~12~26 ~33~12~36 minecraft:planks 4
fill ~29~13~26 ~29~15~28 minecraft:bookshelf
fill ~29~19~26 ~37~19~36 minecraft:planks 4
setblock ~30~7~26 minecraft:acacia_stairs 2
setblock ~31~6~26 minecraft:acacia_stairs 2
fill ~31~10~26 ~31~10~27 minecraft:stone_stairs 5
fill ~31~28~26 ~33~28~26 minecraft:stonebrick 0
fill ~31~29~26 ~31~32~26 minecraft:stonebrick 0
fill ~31~33~26 ~36~35~26 minecraft:stained_hardened_clay 15
fill ~31~36~26 ~33~36~26 minecraft:stonebrick 0
fill ~31~37~26 ~31~40~26 minecraft:stonebrick 0
fill ~31~41~26 ~36~41~26 minecraft:stained_hardened_clay 15
setblock ~32~5~26 minecraft:acacia_stairs 2
fill ~32~29~26 ~32~31~26 minecraft:stained_glass_pane 2
fill ~32~32~26 ~33~32~26 minecraft:stonebrick 0
fill ~32~37~26 ~32~39~26 minecraft:stained_glass_pane 2
fill ~32~40~26 ~33~40~26 minecraft:stonebrick 0
setblock ~32~45~26 minecraft:torch 3
fill ~33~13~26 ~33~15~28 minecraft:bookshelf
fill ~33~29~26 ~33~31~26 minecraft:stonebrick 0
fill ~33~37~26 ~33~39~26 minecraft:stonebrick 0
fill ~34~28~26 ~36~28~27 minecraft:stained_hardened_clay 15
fill ~34~29~26 ~36~32~26 minecraft:stained_hardened_clay 15
fill ~34~36~26 ~36~40~26 minecraft:stained_hardened_clay 15
setblock ~36~45~26 minecraft:torch 3
fill ~37~12~26 ~37~12~36 minecraft:planks 4
fill ~37~18~26 ~37~18~36 minecraft:planks 4
fill ~37~28~26 ~37~41~26 minecraft:stonebrick 0
setblock ~38~5~26 minecraft:trapdoor 2
setblock ~38~13~26 minecraft:trapdoor 2
setblock ~38~15~26 minecraft:torch 2
fill ~38~19~26 ~38~19~38 minecraft:stained_hardened_clay 15
setblock ~38~20~26 minecraft:trapdoor 2
setblock ~38~23~26 minecraft:torch 2
fill ~38~26~26 ~38~27~37 minecraft:stained_hardened_clay 15
fill ~38~28~26 ~39~28~38 minecraft:cobblestone
setblock ~38~43~26 minecraft:stone_brick_stairs 5
fill ~38~44~26 ~38~44~37 minecraft:stonebrick 0
setblock ~38~45~26 minecraft:stone_block_slab 5
fill ~39~12~26 ~39~12~28 minecraft:stonebrick 0
fill ~39~13~26 ~39~16~26 minecraft:stonebrick 0
fill ~39~17~26 ~39~17~37 minecraft:stained_hardened_clay 15
fill ~39~20~26 ~39~20~28 minecraft:stonebrick 0
fill ~39~21~26 ~39~24~26 minecraft:stonebrick 0
fill ~39~25~26 ~39~25~37 minecraft:stained_hardened_clay 15
setblock ~40~14~26 minecraft:torch 1
setblock ~40~22~26 minecraft:torch 1
setblock ~40~27~26 minecraft:stone_brick_stairs 5
setblock ~40~29~26 minecraft:stone_block_slab 5
setblock ~2~0~27 minecraft:grass
fill ~4~4~27 ~5~4~27 minecraft:stone_brick_stairs 3
setblock ~4~21~27 minecraft:stonebrick 0
setblock ~4~22~27 minecraft:stone_block_slab 0
fill ~5~0~27 ~5~0~31 minecraft:dirt 0
setblock ~5~19~27 minecraft:stone_brick_stairs 7
fill ~5~20~27 ~11~20~27 minecraft:stonebrick 0
setblock ~5~21~27 minecraft:stone_block_slab 5
fill ~6~0~27 ~6~0~31 minecraft:stonebrick 0
fill ~6~1~27 ~6~13~27 minecraft:stonebrick 0
setblock ~6~14~27 minecraft:stone_block_slab 0
setblock ~6~21~27 minecraft:double_stone_block_slab 5
setblock ~6~22~27 minecraft:stone_block_slab 0
fill ~7~3~27 ~10~3~27 minecraft:stonebrick 0
fill ~7~4~27 ~9~4~36 minecraft:stone 0
setblock ~7~5~27 minecraft:stone_block_slab 5
setblock ~7~7~27 minecraft:acacia_stairs 1
fill ~7~11~27 ~9~11~36 minecraft:cobblestone
fill ~7~12~27 ~9~12~31 minecraft:cobblestone
setblock ~7~14~27 minecraft:torch 3
fill ~7~16~27 ~9~16~27 minecraft:stone_stairs 3
setblock ~7~19~27 minecraft:stone_brick_stairs 7
setblock ~7~21~27 minecraft:stone_block_slab 5
fill ~8~5~27 ~8~5~28 minecraft:double_stone_block_slab 5
setblock ~8~6~27 minecraft:acacia_stairs 1
setblock ~8~21~27 minecraft:double_stone_block_slab 5
setblock ~8~22~27 minecraft:stone_block_slab 0
setblock ~9~5~27 minecraft:acacia_stairs 3
setblock ~9~14~27 minecraft:torch 3
setblock ~9~19~27 minecraft:stone_brick_stairs 7
setblock ~9~21~27 minecraft:stone_block_slab 5
fill ~10~0~27 ~10~0~31 minecraft:stonebrick 0
fill ~10~1~27 ~10~2~27 minecraft:stonebrick 0
fill ~10~4~27 ~10~13~27 minecraft:stonebrick 0
setblock ~10~14~27 minecraft:stone_block_slab 0
setblock ~10~21~27 minecraft:double_stone_block_slab 5
setblock ~10~22~27 minecraft:stone_block_slab 0
fill ~11~0~27 ~11~0~31 minecraft:cobblestone
setblock ~11~2~27 minecraft:torch 3
fill ~11~4~27 ~11~4~31 minecraft:double_stone_block_slab 0
setblock ~11~5~27 minecraft:chest 5
setblock ~11~19~27 minecraft:stone_brick_stairs 7
setblock ~11~21~27 minecraft:stone_block_slab 5
setblock ~12~21~27 minecraft:stonebrick 0
setblock ~12~22~27 minecraft:stone_block_slab 0
setblock ~13~4~27 minecraft:stone 0
setblock ~14~4~27 minecraft:double_stone_block_slab 0
setblock ~15~4~27 minecraft:stone 0
setblock ~16~4~27 minecraft:double_stone_block_slab 0
setblock ~24~29~27 minecraft:stonebrick 0
setblock ~24~30~27 minecraft:stone_block_slab 0
setblock ~25~5~27 minecraft:spruce_door 0
fill ~25~7~27 ~25~8~28 minecraft:stonebrick 0
fill ~25~13~27 ~25~15~27 minecraft:stained_glass_pane 2
fill ~25~16~27 ~25~16~28 minecraft:stonebrick 0
fill ~25~21~27 ~25~23~27 minecraft:stained_glass_pane 2
fill ~25~24~27 ~25~24~28 minecraft:stonebrick 0
fill ~26~10~27 ~26~10~37 minecraft:stone_stairs 5
setblock ~26~11~27 minecraft:acacia_stairs 2
setblock ~26~18~27 minecraft:acacia_stairs 3
setblock ~26~45~27 minecraft:stonebrick 0
setblock ~26~46~27 minecraft:stone_block_slab 0
fill ~27~10~27 ~30~10~27 minecraft:stone_stairs 7
setblock ~27~11~27 minecraft:acacia_stairs 0
setblock ~27~18~27 minecraft:acacia_stairs 0
fill ~27~28~27 ~27~41~29 minecraft:stained_hardened_clay 15
fill ~27~42~27 ~27~43~36 minecraft:stonebrick 0
setblock ~27~45~27 minecraft:torch 1
fill ~28~11~27 ~29~11~37 minecraft:cobblestone
fill ~28~12~27 ~28~12~36 minecraft:planks 4
setblock ~28~13~27 minecraft:fence 4
fill ~28~18~27 ~35~18~36 minecraft:planks 4
setblock ~28~19~27 minecraft:acacia_stairs 2
setblock ~28~29~27 minecraft:grass
fill ~28~30~27 ~28~31~27 minecraft:leaves 1
fill ~28~34~27 ~37~35~27 minecraft:stained_hardened_clay 15
setblock ~28~38~27 minecraft:acacia_stairs 1
fill ~28~42~27 ~36~43~27 minecraft:stained_hardened_clay 15
setblock ~29~29~27 minecraft:trapdoor 1
setblock ~29~37~27 minecraft:acacia_stairs 1
fill ~30~29~27 ~30~30~27 minecraft:bookshelf
setblock ~30~36~27 minecraft:acacia_stairs 1
setblock ~31~13~27 minecraft:enchanting_table
setblock ~31~16~27 minecraft:lantern 1
setblock ~31~17~27 minecraft:chain 0
setblock ~31~20~27 minecraft:darkoak_wall_sign 4
fill ~31~28~27 ~33~28~27 minecraft:stained_hardened_clay 15
setblock ~31~31~27 minecraft:torch 3
setblock ~31~39~27 minecraft:torch 3
setblock ~32~20~27 minecraft:dark_oak_stairs 3
setblock ~33~20~27 minecraft:darkoak_wall_sign 5
setblock ~33~31~27 minecraft:torch 3
setblock ~33~39~27 minecraft:torch 3
fill ~34~29~27 ~34~30~27 minecraft:bookshelf
setblock ~35~29~27 minecraft:trapdoor 1
setblock ~35~36~27 minecraft:trapdoor 1
setblock ~36~29~27 minecraft:grass
fill ~36~30~27 ~36~31~27 minecraft:leaves 1
setblock ~36~36~27 minecraft:grass
fill ~36~37~27 ~36~38~27 minecraft:leaves 1
fill ~37~28~27 ~37~33~29 minecraft:stained_hardened_clay 15
fill ~37~36~27 ~37~41~29 minecraft:stained_hardened_clay 15
fill ~37~42~27 ~37~43~36 minecraft:stonebrick 0
setblock ~37~45~27 minecraft:torch 2
fill ~38~5~27 ~38~7~29 minecraft:bookshelf
setblock ~38~45~27 minecraft:stonebrick 0
setblock ~38~46~27 minecraft:stone_block_slab 0
fill ~39~13~27 ~39~15~27 minecraft:stained_glass_pane 2
fill ~39~16~27 ~39~16~28 minecraft:stonebrick 0
fill ~39~21~27 ~39~23~27 minecraft:stained_glass_pane 2
fill ~39~24~27 ~39~24~28 minecraft:stonebrick 0
setblock ~40~29~27 minecraft:stonebrick 0
setblock ~40~30~27 minecraft:stone_block_slab 0
setblock ~42~0~27 minecraft:grass
setblock ~2~0~28 minecraft:gravel
fill ~4~1~28 ~4~1~30 minecraft:dirt 0
setblock ~4~2~28 minecraft:grass
fill ~5~4~28 ~5~4~31 minecraft:stone_brick_stairs 0
fill ~6~1~28 ~6~11~30 minecraft:stained_hardened_clay 15
fill ~6~12~28 ~6~12~31 minecraft:stonebrick 0
setblock ~6~13~28 minecraft:stone_block_slab 5
fill ~7~5~28 ~7~7~28 minecraft:double_stone_block_slab 5
setblock ~7~8~28 minecraft:stone_block_slab 5
setblock ~8~6~28 minecraft:double_stone_block_slab 5
setblock ~8~7~28 minecraft:stone_block_slab 5
fill ~10~1~28 ~10~11~30 minecraft:stained_hardened_clay 15
fill ~10~12~28 ~10~12~31 minecraft:stonebrick 0
setblock ~10~13~28 minecraft:stone_block_slab 5
fill ~11~1~28 ~13~3~28 minecraft:cobblestone
fill ~11~5~28 ~12~5~28 minecraft:leaves 3
setblock ~12~4~28 minecraft:stone 0
setblock ~13~4~28 minecraft:double_stone_block_slab 0
setblock ~14~4~28 minecraft:stone 0
setblock ~15~4~28 minecraft:double_stone_block_slab 0
setblock ~16~4~28 minecraft:stone 0
setblock ~24~6~28 minecraft:torch 2
setblock ~24~14~28 minecraft:torch 2
setblock ~24~22~28 minecraft:torch 2
setblock ~24~27~28 minecraft:stone_brick_stairs 4
setblock ~24~29~28 minecraft:stone_block_slab 5
fill ~25~5~28 ~25~6~28 minecraft:stonebrick 0
fill ~25~13~28 ~25~15~28 minecraft:stonebrick 0
fill ~25~21~28 ~25~23~28 minecraft:stonebrick 0
fill ~26~11~28 ~27~11~37 minecraft:cobblestone
setblock ~26~12~28 minecraft:acacia_stairs 2
setblock ~26~15~28 minecraft:torch 1
setblock ~26~17~28 minecraft:acacia_stairs 3
setblock ~26~23~28 minecraft:torch 1
setblock ~26~43~28 minecraft:stone_brick_stairs 4
setblock ~26~45~28 minecraft:stone_block_slab 5
setblock ~27~12~28 minecraft:acacia_stairs 0
setblock ~27~17~28 minecraft:acacia_stairs 0
fill ~28~19~28 ~28~19~36 minecraft:planks 4
fill ~28~28~28 ~28~28~36 minecraft:stained_hardened_clay 15
setblock ~28~29~28 minecraft:trapdoor 2
fill ~28~34~28 ~28~35~34 minecraft:stained_hardened_clay 15
setblock ~28~39~28 minecraft:acacia_stairs 2
setblock ~28~43~28 minecraft:stained_hardened_clay 15
fill ~29~28~28 ~30~28~29 minecraft:double_wooden_slab 4
fill ~29~34~28 ~35~35~34 minecraft:planks 4
fill ~29~42~28 ~35~43~34 minecraft:planks 4
fill ~31~20~28 ~33~20~29 minecraft:wooden_slab 9
setblock ~31~21~28 minecraft:air
fill ~31~28~28 ~35~28~32 minecraft:planks 4
setblock ~32~21~28 minecraft:carpet 14
fill ~36~28~28 ~36~28~32 minecraft:stained_hardened_clay 15
setblock ~36~29~28 minecraft:trapdoor 2
fill ~36~34~28 ~37~35~35 minecraft:stained_hardened_clay 15
setblock ~36~36~28 minecraft:trapdoor 2
fill ~36~42~28 ~36~43~35 minecraft:stained_hardened_clay 15
setblock ~38~15~28 minecraft:torch 2
setblock ~38~23~28 minecraft:torch 2
setblock ~38~43~28 minecraft:stone_brick_stairs 5
setblock ~38~45~28 minecraft:stone_block_slab 5
fill ~39~13~28 ~39~15~28 minecraft:stonebrick 0
fill ~39~21~28 ~39~23~28 minecraft:stonebrick 0
setblock ~40~14~28 minecraft:torch 1
setblock ~40~22~28 minecraft:torch 1
setblock ~40~27~28 minecraft:stone_brick_stairs 5
setblock ~40~29~28 minecraft:stone_block_slab 5
fill ~41~1~28 ~41~1~31 minecraft:gravel
setblock ~42~0~28 minecraft:gravel
fill ~2~0~29 ~2~0~30 minecraft:grass
setblock ~3~1~29 minecraft:grass
setblock ~4~2~29 minecraft:gravel
setblock ~6~13~29 minecraft:stonebrick 0
setblock ~6~14~29 minecraft:stone_block_slab 0
setblock ~7~5~29 minecraft:crafting_table
setblock ~7~8~29 minecraft:torch 1
setblock ~9~8~29 minecraft:torch 2
setblock ~10~13~29 minecraft:stonebrick 0
setblock ~10~14~29 minecraft:stone_block_slab 0
fill ~11~2~29 ~14~2~31 minecraft:cobblestone
fill ~11~3~29 ~11~3~31 minecraft:stone 0
fill ~11~5~29 ~11~5~31 minecraft:leaves 3
fill ~12~3~29 ~13~3~30 minecraft:stone_block_slab 0
fill ~12~4~29 ~13~4~30 minecraft:water 0
setblock ~14~1~29 minecraft:cobblestone
setblock ~14~3~29 minecraft:cobblestone
setblock ~14~4~29 minecraft:double_stone_block_slab 0
setblock ~15~4~29 minecraft:stone 0
setblock ~16~4~29 minecraft:double_stone_block_slab 0
setblock ~20~4~29 minecraft:double_stone_block_slab 0
setblock ~22~4~29 minecraft:double_stone_block_slab 0
