fill ~0~6~0 ~0~6~3 minecraft:quartz_stairs 0
fill ~1~6~0 ~1~6~1 minecraft:quartz_stairs 5
fill ~1~7~0 ~1~7~1 minecraft:quartz_stairs 0
setblock ~2~7~0 minecraft:quartz_stairs 5
setblock ~2~8~0 minecraft:quartz_stairs 0
fill ~3~8~0 ~3~8~1 minecraft:quartz_stairs 5
fill ~3~9~0 ~3~9~2 minecraft:quartz_stairs 0
fill ~4~0~0 ~6~0~0 minecraft:snow
fill ~4~1~0 ~6~1~0 minecraft:trapdoor 3
fill ~4~9~0 ~4~9~1 minecraft:quartz_stairs 5
setblock ~4~10~0 minecraft:quartz_stairs 0
fill ~5~10~0 ~5~10~2 minecraft:quartz_block 0
setblock ~5~11~0 minecraft:quartz_stairs 2
fill ~6~9~0 ~6~9~1 minecraft:quartz_stairs 4
setblock ~6~10~0 minecraft:quartz_stairs 1
fill ~7~8~0 ~7~8~1 minecraft:quartz_stairs 4
fill ~7~9~0 ~7~9~2 minecraft:quartz_stairs 1
setblock ~8~7~0 minecraft:quartz_stairs 4
fill ~8~8~0 ~8~8~2 minecraft:quartz_stairs 1
fill ~9~6~0 ~9~6~1 minecraft:quartz_stairs 4
fill ~9~7~0 ~9~7~1 minecraft:quartz_stairs 1
fill ~10~6~0 ~10~6~3 minecraft:quartz_stairs 1
fill ~2~0~1 ~3~0~1 minecraft:snow
setblock ~2~1~1 minecraft:fence 2
setblock ~2~4~1 minecraft:quartz_stairs 6
setblock ~2~5~1 minecraft:wool 14
setblock ~2~6~1 minecraft:wool 0
setblock ~2~7~1 minecraft:wool 14
setblock ~2~8~1 minecraft:stone_block_slab 6
setblock ~3~1~1 minecraft:trapdoor 1
setblock ~3~4~1 minecraft:fence 2
fill ~3~5~1 ~7~5~1 minecraft:quartz_stairs 6
setblock ~3~6~1 minecraft:fence 2
fill ~4~1~1 ~6~1~1 minecraft:grass
fill ~4~2~1 ~6~2~1 minecraft:tallgrass 2
setblock ~4~8~1 minecraft:stone_block_slab 14
setblock ~4~10~1 minecraft:stone_block_slab 6
setblock ~5~4~1 minecraft:fence 2
fill ~5~6~1 ~5~7~1 minecraft:fence 2
setblock ~5~8~1 minecraft:stone_block_slab 6
fill ~5~11~1 ~5~11~3 minecraft:stone_block_slab 6
setblock ~6~8~1 minecraft:stone_block_slab 14
setblock ~6~10~1 minecraft:stone_block_slab 6
fill ~7~0~1 ~8~0~1 minecraft:snow
setblock ~7~1~1 minecraft:trapdoor 1
setblock ~7~4~1 minecraft:fence 2
setblock ~7~6~1 minecraft:fence 2
setblock ~8~1~1 minecraft:fence 2
setblock ~8~4~1 minecraft:quartz_stairs 6
setblock ~8~5~1 minecraft:wool 14
setblock ~8~6~1 minecraft:wool 0
setblock ~8~7~1 minecraft:wool 14
fill ~1~0~2 ~1~0~3 minecraft:snow
setblock ~1~1~2 minecraft:fence 2
setblock ~1~4~2 minecraft:quartz_stairs 4
setblock ~1~5~2 minecraft:wool 14
fill ~1~6~2 ~1~6~3 minecraft:quartz_block 0
setblock ~1~7~2 minecraft:stone_block_slab 6
setblock ~2~1~2 minecraft:wool 14
setblock ~2~2~2 minecraft:wool 0
setblock ~2~3~2 minecraft:wool 14
setblock ~2~4~2 minecraft:wool 0
fill ~2~5~2 ~8~5~2 minecraft:stained_hardened_clay 12
fill ~2~6~2 ~3~6~2 minecraft:stained_hardened_clay 12
setblock ~2~7~2 minecraft:stone_block_slab 14
setblock ~2~8~2 minecraft:quartz_stairs 0
fill ~3~1~2 ~7~1~14 minecraft:stained_hardened_clay 12
fill ~3~2~2 ~3~4~2 minecraft:stained_hardened_clay 12
fill ~3~7~2 ~3~8~2 minecraft:stained_hardened_clay 12
setblock ~4~2~2 minecraft:quartz_stairs 2
setblock ~4~3~2 minecraft:stained_glass_pane 0
fill ~4~4~2 ~7~4~2 minecraft:stained_hardened_clay 12
setblock ~4~6~2 minecraft:quartz_stairs 2
setblock ~4~7~2 minecraft:stained_glass_pane 0
fill ~4~8~2 ~7~8~2 minecraft:stained_hardened_clay 12
fill ~4~9~2 ~6~9~2 minecraft:stained_hardened_clay 12
setblock ~4~10~2 minecraft:quartz_stairs 0
fill ~5~2~2 ~5~3~2 minecraft:stained_hardened_clay 12
fill ~5~6~2 ~5~7~2 minecraft:stained_hardened_clay 12
setblock ~6~2~2 minecraft:quartz_stairs 2
setblock ~6~3~2 minecraft:stained_glass_pane 0
setblock ~6~6~2 minecraft:quartz_stairs 2
setblock ~6~7~2 minecraft:stained_glass_pane 0
setblock ~6~10~2 minecraft:quartz_stairs 1
fill ~7~2~2 ~7~3~2 minecraft:stained_hardened_clay 12
fill ~7~6~2 ~8~6~2 minecraft:stained_hardened_clay 12
setblock ~7~7~2 minecraft:stained_hardened_clay 12
setblock ~8~1~2 minecraft:wool 14
setblock ~8~2~2 minecraft:wool 0
setblock ~8~3~2 minecraft:wool 14
setblock ~8~4~2 minecraft:wool 0
setblock ~8~7~2 minecraft:quartz_block 0
fill ~9~0~2 ~9~0~3 minecraft:snow
setblock ~9~1~2 minecraft:fence 2
setblock ~9~4~2 minecraft:quartz_stairs 5
setblock ~9~5~2 minecraft:wool 14
setblock ~9~6~2 minecraft:wool 0
setblock ~9~7~2 minecraft:stone_block_slab 6
fill ~0~9~3 ~0~9~13 minecraft:quartz_stairs 0
setblock ~1~1~3 minecraft:trapdoor 3
setblock ~1~5~3 minecraft:quartz_stairs 4
setblock ~1~7~3 minecraft:quartz_stairs 0
setblock ~1~9~3 minecraft:quartz_stairs 5
fill ~1~10~3 ~1~10~4 minecraft:quartz_stairs 0
setblock ~2~1~3 minecraft:stained_hardened_clay 12
setblock ~2~2~3 minecraft:quartz_stairs 0
setblock ~2~3~3 minecraft:stained_glass_pane 0
fill ~2~4~3 ~2~7~3 minecraft:stained_hardened_clay 12
setblock ~2~8~3 minecraft:stone_block_slab 6
setblock ~2~10~3 minecraft:quartz_stairs 5
fill ~2~11~3 ~2~11~4 minecraft:quartz_stairs 0
fill ~3~5~3 ~7~5~6 minecraft:stone_block_slab 14
fill ~3~8~3 ~3~8~4 minecraft:quartz_stairs 5
setblock ~3~9~3 minecraft:stone_block_slab 6
setblock ~3~11~3 minecraft:quartz_stairs 5
fill ~3~12~3 ~3~12~4 minecraft:quartz_stairs 0
fill ~4~9~3 ~4~9~4 minecraft:quartz_stairs 5
setblock ~4~10~3 minecraft:stone_block_slab 6
setblock ~4~12~3 minecraft:quartz_stairs 5
setblock ~4~13~3 minecraft:quartz_stairs 0
setblock ~5~7~3 minecraft:torch 3
fill ~5~9~3 ~5~9~12 minecraft:stone_block_slab 14
setblock ~5~10~3 minecraft:double_stone_block_slab 6
setblock ~5~13~3 minecraft:quartz_block 0
setblock ~5~14~3 minecraft:quartz_stairs 2
fill ~6~9~3 ~6~9~4 minecraft:quartz_stairs 4
setblock ~6~10~3 minecraft:stone_block_slab 6
setblock ~6~12~3 minecraft:quartz_stairs 4
setblock ~6~13~3 minecraft:quartz_stairs 1
fill ~7~8~3 ~7~8~4 minecraft:quartz_stairs 4
setblock ~7~9~3 minecraft:stone_block_slab 6
setblock ~7~11~3 minecraft:quartz_stairs 4
setblock ~7~12~3 minecraft:quartz_stairs 1
setblock ~8~1~3 minecraft:stained_hardened_clay 12
setblock ~8~2~3 minecraft:quartz_stairs 1
setblock ~8~3~3 minecraft:stained_glass_pane 0
fill ~8~4~3 ~8~7~3 minecraft:stained_hardened_clay 12
setblock ~8~8~3 minecraft:quartz_block 0
setblock ~8~10~3 minecraft:quartz_stairs 4
fill ~8~11~3 ~8~11~6 minecraft:quartz_stairs 1
setblock ~9~1~3 minecraft:trapdoor 3
setblock ~9~5~3 minecraft:quartz_stairs 5
setblock ~9~6~3 minecraft:quartz_block 0
setblock ~9~7~3 minecraft:double_stone_block_slab 6
setblock ~9~9~3 minecraft:quartz_stairs 4
setblock ~9~10~3 minecraft:quartz_stairs 1
fill ~10~9~3 ~10~9~13 minecraft:quartz_stairs 1
fill ~0~0~4 ~0~0~6 minecraft:snow
fill ~0~1~4 ~0~1~6 minecraft:trapdoor 1
fill ~1~1~4 ~1~1~6 minecraft:grass
fill ~1~2~4 ~1~2~5 minecraft:tallgrass 2
setblock ~1~4~4 minecraft:quartz_stairs 4
fill ~1~5~4 ~2~5~4 minecraft:wool 14
setblock ~1~6~4 minecraft:wool 0
setblock ~1~7~4 minecraft:wool 14
setblock ~1~8~4 minecraft:wool 0
setblock ~1~9~4 minecraft:wool 14
setblock ~2~1~4 minecraft:wool 14
setblock ~2~2~4 minecraft:wool 0
setblock ~2~3~4 minecraft:wool 14
setblock ~2~4~4 minecraft:wool 0
fill ~2~6~4 ~2~10~5 minecraft:stained_hardened_clay 12
setblock ~3~3~4 minecraft:torch 1
fill ~3~9~4 ~3~11~4 minecraft:stained_hardened_clay 12
fill ~4~10~4 ~8~10~4 minecraft:stained_hardened_clay 12
fill ~4~11~4 ~7~11~4 minecraft:stained_hardened_clay 12
fill ~4~12~4 ~6~12~4 minecraft:stained_hardened_clay 12
setblock ~4~13~4 minecraft:quartz_block 0
setblock ~5~13~4 minecraft:stained_hardened_clay 12
fill ~5~14~4 ~5~14~5 minecraft:stone_block_slab 6
fill ~6~13~4 ~6~13~6 minecraft:double_stone_block_slab 6
setblock ~7~3~4 minecraft:torch 2
fill ~7~9~4 ~8~9~4 minecraft:stained_hardened_clay 12
fill ~7~12~4 ~7~12~7 minecraft:double_stone_block_slab 6
setblock ~8~1~4 minecraft:wool 14
setblock ~8~2~4 minecraft:wool 0
setblock ~8~3~4 minecraft:wool 14
setblock ~8~4~4 minecraft:wool 0
fill ~8~5~4 ~9~5~4 minecraft:wool 14
fill ~8~6~4 ~8~8~5 minecraft:stained_hardened_clay 12
fill ~9~1~4 ~9~1~6 minecraft:grass
fill ~9~2~4 ~9~2~5 minecraft:tallgrass 2
setblock ~9~4~4 minecraft:quartz_stairs 5
setblock ~9~6~4 minecraft:wool 0
setblock ~9~7~4 minecraft:wool 14
setblock ~9~8~4 minecraft:wool 0
setblock ~9~9~4 minecraft:wool 14
fill ~9~10~4 ~9~10~5 minecraft:double_stone_block_slab 6
fill ~10~0~4 ~10~0~6 minecraft:snow
setblock ~10~1~4 minecraft:trapdoor 1
fill ~1~5~5 ~1~5~7 minecraft:quartz_stairs 4
fill ~1~6~5 ~1~7~5 minecraft:fence 2
setblock ~1~8~5 minecraft:stone_block_slab 6
setblock ~1~9~5 minecraft:wool 0
setblock ~1~10~5 minecraft:double_stone_block_slab 6
fill ~2~1~5 ~2~1~7 minecraft:stained_hardened_clay 12
fill ~2~2~5 ~2~5~5 minecraft:stained_hardened_clay 12
fill ~2~11~5 ~2~11~6 minecraft:double_stone_block_slab 6
setblock ~3~9~5 minecraft:double_stone_block_slab 6
setblock ~3~11~5 minecraft:quartz_stairs 5
fill ~3~12~5 ~3~12~6 minecraft:stone_block_slab 6
fill ~4~9~5 ~4~9~11 minecraft:stone_block_slab 14
fill ~4~12~5 ~4~12~7 minecraft:quartz_stairs 5
setblock ~4~13~5 minecraft:double_stone_block_slab 6
setblock ~5~11~5 minecraft:torch 3
fill ~5~13~5 ~5~13~11 minecraft:stone_block_slab 14
fill ~6~9~5 ~6~9~11 minecraft:stone_block_slab 14
fill ~6~12~5 ~6~12~11 minecraft:quartz_stairs 4
setblock ~7~9~5 minecraft:double_stone_block_slab 6
fill ~7~11~5 ~7~11~11 minecraft:quartz_stairs 4
fill ~8~1~5 ~8~1~7 minecraft:stained_hardened_clay 12
fill ~8~2~5 ~8~5~5 minecraft:stained_hardened_clay 12
fill ~8~9~5 ~8~10~7 minecraft:stained_hardened_clay 12
fill ~9~5~5 ~9~5~7 minecraft:quartz_stairs 5
fill ~9~6~5 ~9~7~5 minecraft:fence 2
setblock ~9~8~5 minecraft:stone_block_slab 6
setblock ~9~9~5 minecraft:wool 0
fill ~10~1~5 ~10~1~6 minecraft:trapdoor 0
setblock ~0~10~6 minecraft:stone_block_slab 14
fill ~0~11~6 ~1~11~6 minecraft:quartz_stairs 2
setblock ~1~8~6 minecraft:stone_block_slab 14
setblock ~1~9~6 minecraft:wool 14
setblock ~1~10~6 minecraft:quartz_block 0
setblock ~2~2~6 minecraft:quartz_stairs 0
setblock ~2~3~6 minecraft:stained_glass_pane 0
fill ~2~4~6 ~2~5~7 minecraft:stained_hardened_clay 12
setblock ~2~6~6 minecraft:quartz_stairs 0
setblock ~2~7~6 minecraft:stained_glass_pane 0
fill ~2~8~6 ~2~9~7 minecraft:stained_hardened_clay 12
setblock ~2~10~6 minecraft:stained_hardened_clay 12
setblock ~3~9~6 minecraft:stone_block_slab 14
setblock ~3~11~6 minecraft:quartz_stairs 7
fill ~4~13~6 ~4~13~8 minecraft:stone_block_slab 6
setblock ~5~14~6 minecraft:quartz_stairs 2
fill ~7~9~6 ~7~9~10 minecraft:stone_block_slab 14
setblock ~8~2~6 minecraft:quartz_stairs 1
setblock ~8~3~6 minecraft:stained_glass_pane 0
fill ~8~4~6 ~8~5~7 minecraft:stained_hardened_clay 12
setblock ~8~6~6 minecraft:quartz_stairs 1
setblock ~8~7~6 minecraft:stained_glass_pane 0
fill ~8~8~6 ~8~8~7 minecraft:stained_hardened_clay 12
setblock ~9~8~6 minecraft:stone_block_slab 14
setblock ~9~9~6 minecraft:wool 14
setblock ~9~10~6 minecraft:quartz_stairs 1
setblock ~0~11~7 minecraft:quartz_stairs 7
fill ~0~12~7 ~1~12~7 minecraft:quartz_stairs 2
setblock ~1~0~7 minecraft:snow
setblock ~1~1~7 minecraft:trapdoor 2
fill ~1~6~7 ~1~7~7 minecraft:fence 2
setblock ~1~8~7 minecraft:stone_block_slab 6
setblock ~1~9~7 minecraft:wool 0
setblock ~1~10~7 minecraft:wool 14
setblock ~1~11~7 minecraft:wool 0
fill ~2~2~7 ~2~3~7 minecraft:stained_hardened_clay 12
fill ~2~6~7 ~2~7~7 minecraft:stained_hardened_clay 12
setblock ~2~10~7 minecraft:quartz_stairs 3
setblock ~2~11~7 minecraft:torch 1
fill ~2~12~7 ~3~12~7 minecraft:double_stone_block_slab 6
fill ~3~2~7 ~3~9~7 minecraft:ladder 5
fill ~4~5~7 ~7~5~13 minecraft:stone_block_slab 14
setblock ~5~14~7 minecraft:stone_block_slab 6
fill ~6~13~7 ~6~13~10 minecraft:stone_block_slab 6
fill ~8~2~7 ~8~3~7 minecraft:stained_hardened_clay 12
fill ~8~6~7 ~8~7~7 minecraft:stained_hardened_clay 12
fill ~8~11~7 ~8~11~11 minecraft:stone_block_slab 6
fill ~9~0~7 ~9~0~9 minecraft:snow
setblock ~9~1~7 minecraft:trapdoor 2
fill ~9~6~7 ~9~7~7 minecraft:fence 2
setblock ~9~8~7 minecraft:stone_block_slab 6
setblock ~9~9~7 minecraft:wool 0
setblock ~9~10~7 minecraft:quartz_stairs 2
setblock ~0~1~8 minecraft:wool 14
setblock ~0~12~8 minecraft:double_stone_block_slab 6
setblock ~0~13~8 minecraft:quartz_stairs 0
setblock ~1~1~8 minecraft:wool 0
setblock ~1~2~8 minecraft:fence 2
setblock ~1~4~8 minecraft:quartz_stairs 4
fill ~1~5~8 ~2~5~8 minecraft:wool 14
fill ~1~6~8 ~2~6~8 minecraft:wool 0
fill ~1~7~8 ~2~7~8 minecraft:wool 14
fill ~1~8~8 ~2~8~8 minecraft:wool 0
fill ~1~9~8 ~2~9~8 minecraft:wool 14
setblock ~1~10~8 minecraft:quartz_stairs 0
setblock ~1~11~8 minecraft:stained_glass_pane 0
setblock ~1~12~8 minecraft:wool 14
fill ~1~13~8 ~3~13~8 minecraft:stone_block_slab 6
setblock ~2~1~8 minecraft:wool 14
setblock ~2~2~8 minecraft:wool 0
setblock ~2~3~8 minecraft:wool 14
setblock ~2~4~8 minecraft:wool 0
fill ~2~12~8 ~4~12~8 minecraft:stone_block_slab 14
setblock ~3~3~8 minecraft:torch 1
fill ~3~5~8 ~3~5~13 minecraft:stone_block_slab 14
setblock ~3~7~8 minecraft:torch 1
fill ~3~9~8 ~3~9~10 minecraft:stone_block_slab 14
setblock ~7~3~8 minecraft:torch 2
setblock ~7~7~8 minecraft:torch 2
fill ~7~12~8 ~7~12~9 minecraft:quartz_stairs 1
setblock ~8~1~8 minecraft:wool 14
setblock ~8~2~8 minecraft:wool 0
setblock ~8~3~8 minecraft:wool 14
setblock ~8~4~8 minecraft:wool 0
fill ~8~5~8 ~9~5~8 minecraft:wool 14
fill ~8~6~8 ~9~6~8 minecraft:wool 0
fill ~8~7~8 ~9~7~8 minecraft:wool 14
fill ~8~8~8 ~9~8~8 minecraft:wool 0
fill ~8~9~8 ~9~9~8 minecraft:wool 14
fill ~8~10~8 ~8~10~12 minecraft:stained_hardened_clay 12
setblock ~9~1~8 minecraft:fence 2
setblock ~9~4~8 minecraft:quartz_stairs 5
setblock ~9~10~8 minecraft:double_stone_block_slab 6
fill ~0~1~9 ~0~1~11 minecraft:quartz_stairs 0
setblock ~0~11~9 minecraft:quartz_stairs 6
fill ~0~12~9 ~1~12~9 minecraft:quartz_stairs 3
fill ~1~1~9 ~1~1~11 minecraft:quartz_block 0
fill ~1~5~9 ~1~5~11 minecraft:quartz_stairs 4
fill ~1~6~9 ~1~7~9 minecraft:fence 2
setblock ~1~8~9 minecraft:stone_block_slab 6
setblock ~1~9~9 minecraft:wool 0
setblock ~1~10~9 minecraft:wool 14
setblock ~1~11~9 minecraft:wool 0
fill ~2~1~9 ~2~1~11 minecraft:stained_hardened_clay 12
fill ~2~2~9 ~2~9~9 minecraft:stained_hardened_clay 12
setblock ~2~10~9 minecraft:quartz_stairs 2
setblock ~2~11~9 minecraft:torch 1
setblock ~2~12~9 minecraft:stone_block_slab 6
setblock ~3~12~9 minecraft:double_stone_block_slab 6
fill ~4~12~9 ~4~12~11 minecraft:quartz_stairs 5
setblock ~4~13~9 minecraft:double_stone_block_slab 6
fill ~8~1~9 ~8~1~11 minecraft:stained_hardened_clay 12
fill ~8~2~9 ~8~9~9 minecraft:stained_hardened_clay 12
setblock ~9~1~9 minecraft:trapdoor 3
fill ~9~5~9 ~9~5~11 minecraft:quartz_stairs 5
fill ~9~6~9 ~9~7~9 minecraft:fence 2
setblock ~9~8~9 minecraft:stone_block_slab 6
setblock ~9~9~9 minecraft:wool 0
fill ~9~10~9 ~9~10~13 minecraft:quartz_stairs 1
fill ~10~0~9 ~10~0~12 minecraft:snow
setblock ~0~0~10 minecraft:snow
setblock ~0~10~10 minecraft:stone_block_slab 14
fill ~0~11~10 ~1~11~10 minecraft:quartz_stairs 3
setblock ~1~8~10 minecraft:stone_block_slab 14
setblock ~1~9~10 minecraft:wool 14
setblock ~1~10~10 minecraft:quartz_block 0
setblock ~2~2~10 minecraft:spruce_door 2
fill ~2~4~10 ~2~5~11 minecraft:stained_hardened_clay 12
setblock ~2~6~10 minecraft:quartz_stairs 0
setblock ~2~7~10 minecraft:stained_glass_pane 0
fill ~2~8~10 ~2~10~12 minecraft:stained_hardened_clay 12
setblock ~2~11~10 minecraft:double_stone_block_slab 6
setblock ~3~11~10 minecraft:quartz_stairs 6
fill ~3~12~10 ~3~12~11 minecraft:stone_block_slab 6
fill ~4~13~10 ~4~13~11 minecraft:stone_block_slab 6
fill ~7~12~10 ~7~12~11 minecraft:stone_block_slab 6
setblock ~8~2~10 minecraft:quartz_stairs 1
setblock ~8~3~10 minecraft:stained_glass_pane 0
fill ~8~4~10 ~8~5~11 minecraft:stained_hardened_clay 12
setblock ~8~6~10 minecraft:quartz_stairs 1
setblock ~8~7~10 minecraft:stained_glass_pane 0
fill ~8~8~10 ~8~9~12 minecraft:stained_hardened_clay 12
fill ~9~1~10 ~9~1~12 minecraft:grass
setblock ~9~8~10 minecraft:stone_block_slab 14
setblock ~9~9~10 minecraft:wool 14
fill ~10~1~10 ~10~1~12 minecraft:trapdoor 1
fill ~1~6~11 ~1~7~11 minecraft:fence 2
setblock ~1~8~11 minecraft:stone_block_slab 6
setblock ~1~9~11 minecraft:wool 0
setblock ~1~10~11 minecraft:quartz_stairs 0
fill ~2~2~11 ~2~3~11 minecraft:stained_hardened_clay 12
fill ~2~6~11 ~2~6~14 minecraft:stained_hardened_clay 12
fill ~2~7~11 ~2~7~13 minecraft:stained_hardened_clay 12
setblock ~2~11~11 minecraft:stone_block_slab 6
setblock ~3~9~11 minecraft:double_stone_block_slab 6
setblock ~3~11~11 minecraft:quartz_stairs 5
setblock ~5~11~11 minecraft:torch 4
fill ~6~13~11 ~6~13~12 minecraft:double_stone_block_slab 6
fill ~7~9~11 ~7~9~12 minecraft:double_stone_block_slab 6
fill ~8~2~11 ~8~3~11 minecraft:stained_hardened_clay 12
fill ~8~6~11 ~8~6~14 minecraft:stained_hardened_clay 12
fill ~8~7~11 ~8~7~13 minecraft:stained_hardened_clay 12
setblock ~9~2~11 minecraft:tallgrass 2
fill ~9~6~11 ~9~7~11 minecraft:fence 2
setblock ~9~8~11 minecraft:stone_block_slab 6
setblock ~9~9~11 minecraft:wool 0
setblock ~0~1~12 minecraft:wool 14
setblock ~1~1~12 minecraft:wool 0
setblock ~1~2~12 minecraft:fence 2
setblock ~1~4~12 minecraft:quartz_stairs 4
fill ~1~5~12 ~2~5~12 minecraft:wool 14
setblock ~1~6~12 minecraft:wool 0
setblock ~1~7~12 minecraft:wool 14
setblock ~1~8~12 minecraft:wool 0
setblock ~1~9~12 minecraft:wool 14
setblock ~1~10~12 minecraft:double_stone_block_slab 6
setblock ~2~1~12 minecraft:wool 14
setblock ~2~2~12 minecraft:wool 0
setblock ~2~3~12 minecraft:wool 14
setblock ~2~4~12 minecraft:wool 0
setblock ~2~11~12 minecraft:double_stone_block_slab 6
setblock ~3~3~12 minecraft:torch 1
fill ~3~8~12 ~3~8~13 minecraft:quartz_stairs 5
fill ~3~9~12 ~3~11~12 minecraft:stained_hardened_clay 12
fill ~3~12~12 ~3~12~13 minecraft:quartz_stairs 0
fill ~4~9~12 ~4~9~13 minecraft:double_stone_block_slab 6
fill ~4~10~12 ~7~11~12 minecraft:stained_hardened_clay 12
fill ~4~12~12 ~6~12~12 minecraft:stained_hardened_clay 12
setblock ~4~13~12 minecraft:double_stone_block_slab 6
setblock ~5~13~12 minecraft:stained_hardened_clay 12
setblock ~5~14~12 minecraft:stone_block_slab 6
fill ~6~9~12 ~6~9~13 minecraft:double_stone_block_slab 6
setblock ~7~3~12 minecraft:torch 2
fill ~7~8~12 ~7~8~13 minecraft:quartz_stairs 4
setblock ~7~12~12 minecraft:double_stone_block_slab 6
setblock ~8~1~12 minecraft:wool 14
setblock ~8~2~12 minecraft:wool 0
setblock ~8~3~12 minecraft:wool 14
setblock ~8~4~12 minecraft:wool 0
fill ~8~5~12 ~9~5~12 minecraft:wool 14
fill ~8~11~12 ~8~11~13 minecraft:quartz_stairs 1
setblock ~9~4~12 minecraft:quartz_stairs 5
setblock ~9~6~12 minecraft:wool 0
setblock ~9~7~12 minecraft:wool 14
setblock ~9~8~12 minecraft:wool 0
setblock ~9~9~12 minecraft:wool 14
fill ~0~6~13 ~0~6~16 minecraft:quartz_stairs 0
setblock ~1~5~13 minecraft:quartz_stairs 4
fill ~1~6~13 ~1~6~14 minecraft:quartz_block 0
fill ~1~7~13 ~1~7~16 minecraft:quartz_stairs 0
setblock ~1~9~13 minecraft:quartz_stairs 5
setblock ~1~10~13 minecraft:quartz_stairs 0
setblock ~2~1~13 minecraft:stained_hardened_clay 12
setblock ~2~2~13 minecraft:quartz_stairs 0
setblock ~2~3~13 minecraft:stained_glass_pane 0
fill ~2~4~13 ~2~5~13 minecraft:stained_hardened_clay 12
setblock ~2~8~13 minecraft:stone_block_slab 6
setblock ~2~10~13 minecraft:quartz_stairs 5
setblock ~2~11~13 minecraft:quartz_stairs 0
setblock ~3~9~13 minecraft:stone_block_slab 6
setblock ~3~11~13 minecraft:quartz_stairs 5
fill ~4~10~13 ~4~10~15 minecraft:stone_block_slab 6
setblock ~4~12~13 minecraft:quartz_stairs 5
setblock ~4~13~13 minecraft:quartz_stairs 0
setblock ~5~7~13 minecraft:torch 4
fill ~5~10~13 ~5~10~16 minecraft:double_stone_block_slab 6
setblock ~5~13~13 minecraft:quartz_block 0
setblock ~5~14~13 minecraft:quartz_stairs 2
fill ~6~10~13 ~6~10~15 minecraft:stone_block_slab 6
setblock ~6~12~13 minecraft:quartz_stairs 4
setblock ~6~13~13 minecraft:quartz_stairs 1
setblock ~7~9~13 minecraft:stone_block_slab 6
setblock ~7~11~13 minecraft:quartz_stairs 4
setblock ~7~12~13 minecraft:quartz_stairs 1
setblock ~8~1~13 minecraft:stained_hardened_clay 12
setblock ~8~2~13 minecraft:quartz_stairs 1
setblock ~8~3~13 minecraft:stained_glass_pane 0
fill ~8~4~13 ~8~5~13 minecraft:stained_hardened_clay 12
setblock ~8~8~13 minecraft:stone_block_slab 6
setblock ~8~10~13 minecraft:quartz_stairs 4
fill ~9~0~13 ~9~0~14 minecraft:snow
setblock ~9~1~13 minecraft:trapdoor 2
setblock ~9~5~13 minecraft:quartz_stairs 5
fill ~9~6~13 ~9~7~13 minecraft:quartz_block 0
setblock ~9~9~13 minecraft:quartz_stairs 4
fill ~10~6~13 ~10~6~16 minecraft:quartz_stairs 1
setblock ~1~0~14 minecraft:snow
setblock ~1~1~14 minecraft:fence 2
setblock ~1~4~14 minecraft:quartz_stairs 4
setblock ~1~5~14 minecraft:wool 14
setblock ~2~1~14 minecraft:wool 14
setblock ~2~2~14 minecraft:wool 0
setblock ~2~3~14 minecraft:wool 14
setblock ~2~4~14 minecraft:wool 0
fill ~2~5~14 ~8~5~14 minecraft:stained_hardened_clay 12
setblock ~2~7~14 minecraft:quartz_block 0
fill ~2~8~14 ~2~8~16 minecraft:quartz_stairs 0
fill ~3~2~14 ~3~4~14 minecraft:stained_hardened_clay 12
fill ~3~6~14 ~3~8~14 minecraft:stained_hardened_clay 12
setblock ~3~9~14 minecraft:quartz_stairs 0
setblock ~4~2~14 minecraft:quartz_stairs 3
setblock ~4~3~14 minecraft:stained_glass_pane 0
fill ~4~4~14 ~7~4~14 minecraft:stained_hardened_clay 12
setblock ~4~6~14 minecraft:quartz_stairs 3
setblock ~4~7~14 minecraft:stained_glass_pane 0
fill ~4~8~14 ~7~8~14 minecraft:stained_hardened_clay 12
fill ~4~9~14 ~6~9~14 minecraft:stained_hardened_clay 12
fill ~5~2~14 ~5~3~14 minecraft:stained_hardened_clay 12
fill ~5~6~14 ~5~7~14 minecraft:stained_hardened_clay 12
setblock ~6~2~14 minecraft:quartz_stairs 3
setblock ~6~3~14 minecraft:stained_glass_pane 0
setblock ~6~6~14 minecraft:quartz_stairs 3
setblock ~6~7~14 minecraft:stained_glass_pane 0
fill ~7~2~14 ~7~3~14 minecraft:stained_hardened_clay 12
fill ~7~6~14 ~7~7~14 minecraft:stained_hardened_clay 12
setblock ~7~9~14 minecraft:quartz_stairs 1
setblock ~8~1~14 minecraft:wool 14
setblock ~8~2~14 minecraft:wool 0
setblock ~8~3~14 minecraft:wool 14
setblock ~8~4~14 minecraft:wool 0
setblock ~8~7~14 minecraft:stone_block_slab 14
setblock ~8~8~14 minecraft:quartz_stairs 1
setblock ~9~1~14 minecraft:fence 2
setblock ~9~4~14 minecraft:quartz_stairs 5
setblock ~9~5~14 minecraft:wool 14
setblock ~9~6~14 minecraft:wool 0
fill ~9~7~14 ~9~7~16 minecraft:quartz_stairs 1
fill ~1~6~15 ~1~6~16 minecraft:quartz_stairs 5
fill ~2~0~15 ~3~0~15 minecraft:snow
setblock ~2~1~15 minecraft:fence 2
setblock ~2~4~15 minecraft:quartz_stairs 7
setblock ~2~5~15 minecraft:wool 14
setblock ~2~6~15 minecraft:wool 0
setblock ~2~7~15 minecraft:wool 14
setblock ~3~1~15 minecraft:trapdoor 1
setblock ~3~4~15 minecraft:fence 2
fill ~3~5~15 ~7~5~15 minecraft:quartz_stairs 7
setblock ~3~6~15 minecraft:fence 2
fill ~3~8~15 ~3~8~16 minecraft:quartz_stairs 5
setblock ~3~9~15 minecraft:stone_block_slab 6
fill ~4~1~15 ~6~1~15 minecraft:grass
setblock ~4~2~15 minecraft:tallgrass 2
setblock ~4~8~15 minecraft:stone_block_slab 14
fill ~4~9~15 ~4~9~16 minecraft:quartz_stairs 5
setblock ~5~4~15 minecraft:fence 2
fill ~5~6~15 ~5~7~15 minecraft:fence 2
setblock ~5~8~15 minecraft:stone_block_slab 6
setblock ~5~11~15 minecraft:stone_block_slab 6
setblock ~6~2~15 minecraft:tallgrass 2
setblock ~6~8~15 minecraft:stone_block_slab 14
fill ~6~9~15 ~6~9~16 minecraft:quartz_stairs 4
fill ~7~0~15 ~8~0~15 minecraft:snow
setblock ~7~1~15 minecraft:trapdoor 1
setblock ~7~4~15 minecraft:fence 2
setblock ~7~6~15 minecraft:fence 2
fill ~7~8~15 ~7~8~16 minecraft:quartz_stairs 4
setblock ~7~9~15 minecraft:stone_block_slab 6
setblock ~8~1~15 minecraft:fence 2
setblock ~8~4~15 minecraft:quartz_stairs 7
setblock ~8~5~15 minecraft:wool 14
setblock ~8~6~15 minecraft:wool 0
setblock ~8~7~15 minecraft:wool 14
setblock ~8~8~15 minecraft:stone_block_slab 6
fill ~9~6~15 ~9~6~16 minecraft:quartz_stairs 4
setblock ~2~7~16 minecraft:quartz_stairs 5
setblock ~3~9~16 minecraft:quartz_stairs 0
fill ~4~0~16 ~6~0~16 minecraft:snow
fill ~4~1~16 ~6~1~16 minecraft:trapdoor 2
setblock ~4~10~16 minecraft:quartz_stairs 0
setblock ~5~11~16 minecraft:quartz_stairs 3
setblock ~6~10~16 minecraft:quartz_stairs 1
setblock ~7~9~16 minecraft:quartz_stairs 1
setblock ~8~7~16 minecraft:quartz_stairs 4
setblock ~8~8~16 minecraft:quartz_stairs 1